{"op":"mcm","clk":"992350394","pt":1580520342496,"mc":[{"id":"1.168179121","marketDefinition":{"bspMarket":false,"turnInPlayEnabled":true,"persistenceEnabled":true,"marketBaseRate":5.0,"eventId":"29680182","eventTypeId":"2","numberOfWinners":1,"bettingType":"ODDS","marketType":"SET_BETTING","marketTime":"2020-02-02T00:00:00.000Z","suspendTime":"2020-02-02T00:00:00.000Z","bspReconciled":false,"complete":true,"inPlay":false,"crossMatching":false,"runnersVoidable":false,"numberOfActiveRunners":4,"betDelay":0,"status":"OPEN","runners":[{"status":"ACTIVE","sortPriority":1,"id":20912771,"name":"Meligeni Rodrigues Alve 2-0"},{"status":"ACTIVE","sortPriority":2,"id":20912772,"name":"Meligeni Rodrigues Alve 2-1"},{"status":"ACTIVE","sortPriority":3,"id":14904498,"name":"T Monteiro 2-0"},{"status":"ACTIVE","sortPriority":4,"id":14904499,"name":"T Monteiro 2-1"}],"regulators":["MR_INT"],"countryCode":"UY","discountAllowed":false,"timezone":"UTC","openDate":"2020-02-02T00:00:00.000Z","version":3144293965,"name":"Set Betting","eventName":"Meligeni Rodrigues Alve v T Monteiro"}}]}
{"op":"mcm","clk":"992350445","pt":1580520343901,"mc":[{"id":"1.168179121","marketDefinition":{"bspMarket":false,"turnInPlayEnabled":true,"persistenceEnabled":true,"marketBaseRate":5.0,"eventId":"29680182","eventTypeId":"2","numberOfWinners":1,"bettingType":"ODDS","marketType":"SET_BETTING","marketTime":"2020-02-02T00:00:00.000Z","suspendTime":"2020-02-02T00:00:00.000Z","bspReconciled":false,"complete":true,"inPlay":false,"crossMatching":false,"runnersVoidable":false,"numberOfActiveRunners":4,"betDelay":0,"status":"OPEN","runners":[{"status":"ACTIVE","sortPriority":1,"id":20912771,"name":"Meligeni Rodrigues Alve 2-0"},{"status":"ACTIVE","sortPriority":2,"id":20912772,"name":"Meligeni Rodrigues Alve 2-1"},{"status":"ACTIVE","sortPriority":3,"id":14904498,"name":"T Monteiro 2-0"},{"status":"ACTIVE","sortPriority":4,"id":14904499,"name":"T Monteiro 2-1"}],"regulators":["MR_INT"],"countryCode":"UY","discountAllowed":true,"timezone":"UTC","openDate":"2020-02-02T00:00:00.000Z","version":3144293965,"name":"Set Betting","eventName":"Meligeni Rodrigues Alve v T Monteiro"}}]}
{"op":"mcm","clk":"992450057","pt":1580523140351,"mc":[{"id":"1.168179121","rc":[{"batb":[[0,1.02,2]],"ltp":0.0,"tv":0.0,"id":14904499},{"batb":[[0,1.02,2]],"ltp":0.0,"tv":0.0,"id":14904498},{"batb":[[0,1.02,2]],"ltp":0.0,"tv":0.0,"id":20912772},{"batb":[[0,1.02,2]],"ltp":0.0,"tv":0.0,"id":20912771}]}]}
{"op":"mcm","clk":"993468469","pt":1580542707934,"mc":[{"id":"1.168179121","rc":[{"batl":[[0,5,9.09]],"ltp":0.0,"tv":0.0,"id":14904498}]}]}
{"op":"mcm","clk":"993796878","pt":1580546407728,"mc":[{"id":"1.168179121","rc":[{"batb":[[0,1.33,30.29],[1,1.02,2]],"ltp":0.0,"tv":0.0,"id":14904498}]}]}
{"op":"mcm","clk":"993829743","pt":1580546773037,"mc":[{"id":"1.168179121","rc":[{"batb":[[0,1.36,30.29]],"ltp":0.0,"tv":0.0,"id":14904498}]}]}
{"op":"mcm","clk":"993859214","pt":1580547138106,"mc":[{"id":"1.168179121","rc":[{"batb":[[0,1.35,30.29]],"ltp":0.0,"tv":0.0,"id":14904498}]}]}
{"op":"mcm","clk":"996287080","pt":1580561382843,"mc":[{"id":"1.168179121","rc":[{"batb":[[0,1.02,2],[1,1.02,0]],"ltp":0.0,"tv":0.0,"id":14904498}]}]}
{"op":"mcm","clk":"996287098","pt":1580561382950,"mc":[{"id":"1.168179121","rc":[{"batb":[[0,1.34,30.29],[1,1.02,2]],"ltp":0.0,"tv":0.0,"id":14904498}]}]}
{"op":"mcm","clk":"997867847","pt":1580568565781,"mc":[{"id":"1.168179121","rc":[{"batb":[[0,1.31,30.29]],"ltp":0.0,"tv":0.0,"id":14904498}]}]}
{"op":"mcm","clk":"998032296","pt":1580569295958,"mc":[{"id":"1.168179121","rc":[{"batb":[[0,1.33,30.29]],"ltp":0.0,"tv":0.0,"id":14904498}]}]}
{"op":"mcm","clk":"999461501","pt":1580574898119,"mc":[{"id":"1.168179121","rc":[{"batb":[[0,1.32,30.29]],"ltp":0.0,"tv":0.0,"id":14904498}]}]}
{"op":"mcm","clk":"1002081028","pt":1580590336309,"mc":[{"id":"1.168179121","rc":[{"batl":[[0,38,21.11]],"ltp":0.0,"tv":0.0,"id":20912771}]}]}
{"op":"mcm","clk":"1002083136","pt":1580590352019,"mc":[{"id":"1.168179121","rc":[{"batb":[[0,1.36,84.44],[1,1.32,30.29],[2,1.02,2]],"ltp":0.0,"tv":0.0,"id":14904498}]}]}
{"op":"mcm","clk":"1002083265","pt":1580590353070,"mc":[{"id":"1.168179121","marketDefinition":{"bspMarket":false,"turnInPlayEnabled":true,"persistenceEnabled":true,"marketBaseRate":5.0,"eventId":"29680182","eventTypeId":"2","numberOfWinners":1,"bettingType":"ODDS","marketType":"SET_BETTING","marketTime":"2020-02-02T00:00:00.000Z","suspendTime":"2020-02-02T00:00:00.000Z","bspReconciled":false,"complete":true,"inPlay":false,"crossMatching":true,"runnersVoidable":false,"numberOfActiveRunners":4,"betDelay":0,"status":"OPEN","runners":[{"status":"ACTIVE","sortPriority":1,"id":20912771,"name":"Meligeni Rodrigues Alve 2-0"},{"status":"ACTIVE","sortPriority":2,"id":20912772,"name":"Meligeni Rodrigues Alve 2-1"},{"status":"ACTIVE","sortPriority":3,"id":14904498,"name":"T Monteiro 2-0"},{"status":"ACTIVE","sortPriority":4,"id":14904499,"name":"T Monteiro 2-1"}],"regulators":["MR_INT"],"countryCode":"UY","discountAllowed":true,"timezone":"UTC","openDate":"2020-02-02T00:00:00.000Z","version":3144293965,"name":"Set Betting","eventName":"Meligeni Rodrigues Alve v T Monteiro"}}]}
{"op":"mcm","clk":"1002085117","pt":1580590368033,"mc":[{"id":"1.168179121","rc":[{"batl":[[0,1.62,54.89],[1,5,9.09]],"ltp":0.0,"tv":0.0,"id":14904498}]}]}
{"op":"mcm","clk":"1002091494","pt":1580590420583,"mc":[{"id":"1.168179121","rc":[{"batb":[[0,1.37,30.29],[1,1.36,84.44]],"ltp":0.0,"tv":0.0,"id":14904498}]}]}
{"op":"mcm","clk":"1002635524","pt":1580596400136,"mc":[{"id":"1.168179121","rc":[{"batb":[[0,1.36,84.44],[1,1.02,2],[2,1.02,0]],"ltp":0.0,"tv":0.0,"id":14904498}]}]}
{"op":"mcm","clk":"1002647382","pt":1580596576462,"mc":[{"id":"1.168179121","rc":[{"batb":[[0,1.37,30.29],[1,1.36,84.44],[2,1.02,2]],"ltp":0.0,"tv":0.0,"id":14904498}]}]}
{"op":"mcm","clk":"1002683413","pt":1580597184990,"mc":[{"id":"1.168179121","rc":[{"batb":[[0,1.36,84.44],[1,1.02,2],[2,1.02,0]],"ltp":0.0,"tv":0.0,"id":14904498}]}]}
{"op":"mcm","clk":"1002702389","pt":1580597513023,"mc":[{"id":"1.168179121","rc":[{"trd":[[1.36,5.07]],"batb":[[0,1.36,81.91]],"ltp":1.36,"tv":5.06,"id":14904498}],"tv":5.06}]}
{"op":"mcm","clk":"1002763642","pt":1580598440927,"mc":[{"id":"1.168179121","rc":[{"batb":[[0,1.03,137],[1,1.02,2]],"ltp":0.0,"tv":0.0,"id":14904499},{"batb":[[0,1.37,14],[1,1.36,81.91],[2,1.02,2]],"ltp":1.36,"tv":5.06,"id":14904498},{"batb":[[0,1.03,137],[1,1.02,2]],"ltp":0.0,"tv":0.0,"id":20912772},{"batb":[[0,1.03,137],[1,1.02,2]],"ltp":0.0,"tv":0.0,"id":20912771}]}]}
{"op":"mcm","clk":"1002778122","pt":1580598643462,"mc":[{"id":"1.168179121","rc":[{"batb":[[0,1.38,2],[1,1.37,14],[2,1.36,81.91]],"ltp":1.36,"tv":5.06,"id":14904498},{"batb":[[0,2.62,2],[1,1.03,137],[2,1.02,2]],"ltp":0.0,"tv":0.0,"id":20912771}]}]}
{"op":"mcm","clk":"1002807150","pt":1580599027993,"mc":[{"id":"1.168179121","rc":[{"batb":[[0,1.4,5.91],[1,1.38,2],[2,1.37,14]],"ltp":1.36,"tv":5.06,"id":14904498}]}]}
{"op":"mcm","clk":"1002821730","pt":1580599230223,"mc":[{"id":"1.168179121","rc":[{"batb":[[0,1.41,2.02],[1,1.4,5.91],[2,1.38,2]],"ltp":1.36,"tv":5.06,"id":14904498},{"batb":[[0,2.64,2.02],[1,2.62,2],[2,1.03,137]],"ltp":0.0,"tv":0.0,"id":20912771}]}]}
{"op":"mcm","clk":"1002822603","pt":1580599242679,"mc":[{"id":"1.168179121","rc":[{"batb":[[1,1.03,137],[2,1.02,2]],"ltp":0.0,"tv":0.0,"id":20912771}]}]}
{"op":"mcm","clk":"1002822627","pt":1580599242945,"mc":[{"id":"1.168179121","rc":[{"batb":[[2,1.37,14]],"ltp":1.36,"tv":5.06,"id":14904498}]}]}
{"op":"mcm","clk":"1002900865","pt":1580600315850,"mc":[{"id":"1.168179121","rc":[{"batb":[[2,1.36,81.91]],"ltp":1.36,"tv":5.06,"id":14904498},{"batb":[[0,1.02,2],[1,1.02,0]],"ltp":0.0,"tv":0.0,"id":20912772},{"batb":[[1,1.02,2],[2,1.02,0]],"ltp":0.0,"tv":0.0,"id":20912771}]}]}
{"op":"mcm","clk":"1002900874","pt":1580600316053,"mc":[{"id":"1.168179121","rc":[{"batb":[[0,1.02,2],[1,1.02,0]],"ltp":0.0,"tv":0.0,"id":14904499}]}]}
{"op":"mcm","clk":"1002901036","pt":1580600319459,"mc":[{"id":"1.168179121","rc":[{"batb":[[0,1.03,137],[1,1.02,2]],"ltp":0.0,"tv":0.0,"id":14904499},{"batb":[[0,1.42,13],[1,1.41,2.02],[2,1.4,5.91]],"ltp":1.36,"tv":5.06,"id":14904498},{"batb":[[0,1.03,137],[1,1.02,2]],"ltp":0.0,"tv":0.0,"id":20912772},{"batb":[[0,2.66,6],[1,2.64,2.02],[2,1.02,2]],"ltp":0.0,"tv":0.0,"id":20912771}]}]}
{"op":"mcm","clk":"1002912776","pt":1580600497387,"mc":[{"id":"1.168179121","rc":[{"batb":[[0,1.43,4.02],[1,1.42,13],[2,1.41,2.02]],"ltp":1.36,"tv":5.06,"id":14904498},{"batb":[[0,2.68,4.02],[1,2.66,6],[2,2.64,2.02]],"ltp":0.0,"tv":0.0,"id":20912771}]}]}
{"op":"mcm","clk":"1002952251","pt":1580601096627,"mc":[{"id":"1.168179121","rc":[{"batb":[[0,1.43,2.02]],"ltp":1.36,"tv":5.06,"id":14904498}]}]}
{"op":"mcm","clk":"1002952272","pt":1580601096938,"mc":[{"id":"1.168179121","rc":[{"batb":[[0,2.68,2.02]],"ltp":0.0,"tv":0.0,"id":20912771}]}]}
{"op":"mcm","clk":"1002978671","pt":1580601469629,"mc":[{"id":"1.168179121","rc":[{"batb":[[1,2.64,2.02],[2,1.02,2]],"ltp":0.0,"tv":0.0,"id":20912771}]}]}
{"op":"mcm","clk":"1002978752","pt":1580601470815,"mc":[{"id":"1.168179121","rc":[{"batb":[[0,1.44,13],[1,1.43,2.02]],"ltp":1.36,"tv":5.06,"id":14904498},{"batb":[[0,2.7,6],[1,2.68,2.02],[2,2.64,2.02]],"ltp":0.0,"tv":0.0,"id":20912771}]}]}
{"op":"mcm","clk":"1002983191","pt":1580601531719,"mc":[{"id":"1.168179121","rc":[{"trd":[[4.7,10]],"ltp":4.7,"tv":9.99,"id":14904499},{"trd":[[1.62,29.02]],"batl":[[0,1.62,40.38],[1,2.3,7],[2,5,9.09]],"ltp":1.62,"tv":34.08,"id":14904498},{"batl":[[0,12.5,6]],"ltp":0.0,"tv":0.0,"id":20912772},{"batl":[[0,36,6],[1,38,21.11]],"ltp":0.0,"tv":0.0,"id":20912771}],"tv":44.08}]}
{"op":"mcm","clk":"1002986643","pt":1580601577534,"mc":[{"id":"1.168179121","rc":[{"batb":[[0,2.82,2],[1,1.03,137],[2,1.02,2]],"ltp":0.0,"tv":0.0,"id":20912772}]}]}
{"op":"mcm","clk":"1002987529","pt":1580601589478,"mc":[{"id":"1.168179121","rc":[{"batb":[[0,2.84,2.02],[1,2.82,2],[2,1.03,137]],"ltp":0.0,"tv":0.0,"id":20912772}]}]}
{"op":"mcm","clk":"1002994722","pt":1580601699793,"mc":[{"id":"1.168179121","marketDefinition":{"bspMarket":false,"turnInPlayEnabled":true,"persistenceEnabled":true,"marketBaseRate":5.0,"eventId":"29680182","eventTypeId":"2","numberOfWinners":1,"bettingType":"ODDS","marketType":"SET_BETTING","marketTime":"2020-02-02T00:15:00.000Z","suspendTime":"2020-02-02T00:15:00.000Z","bspReconciled":false,"complete":true,"inPlay":false,"crossMatching":true,"runnersVoidable":false,"numberOfActiveRunners":4,"betDelay":0,"status":"OPEN","runners":[{"status":"ACTIVE","sortPriority":1,"id":20912771,"name":"Meligeni Rodrigues Alve 2-0"},{"status":"ACTIVE","sortPriority":2,"id":20912772,"name":"Meligeni Rodrigues Alve 2-1"},{"status":"ACTIVE","sortPriority":3,"id":14904498,"name":"T Monteiro 2-0"},{"status":"ACTIVE","sortPriority":4,"id":14904499,"name":"T Monteiro 2-1"}],"regulators":["MR_INT"],"countryCode":"UY","discountAllowed":true,"timezone":"UTC","openDate":"2020-02-02T00:00:00.000Z","version":3147888954,"name":"Set Betting","eventName":"Meligeni Rodrigues Alve v T Monteiro"}}]}
{"op":"mcm","clk":"1002995013","pt":1580601703802,"mc":[{"id":"1.168179121","marketDefinition":{"bspMarket":false,"turnInPlayEnabled":true,"persistenceEnabled":true,"marketBaseRate":5.0,"eventId":"29680182","eventTypeId":"2","numberOfWinners":1,"bettingType":"ODDS","marketType":"SET_BETTING","marketTime":"2020-02-02T00:15:00.000Z","suspendTime":"2020-02-02T00:15:00.000Z","bspReconciled":false,"complete":true,"inPlay":false,"crossMatching":true,"runnersVoidable":false,"numberOfActiveRunners":4,"betDelay":0,"status":"OPEN","runners":[{"status":"ACTIVE","sortPriority":1,"id":20912771,"name":"Meligeni Rodrigues Alve 2-0"},{"status":"ACTIVE","sortPriority":2,"id":20912772,"name":"Meligeni Rodrigues Alve 2-1"},{"status":"ACTIVE","sortPriority":3,"id":14904498,"name":"T Monteiro 2-0"},{"status":"ACTIVE","sortPriority":4,"id":14904499,"name":"T Monteiro 2-1"}],"regulators":["MR_INT"],"countryCode":"UY","discountAllowed":true,"timezone":"UTC","openDate":"2020-02-02T00:15:00.000Z","version":3147888954,"name":"Set Betting","eventName":"Meligeni Rodrigues Alve v T Monteiro"}}]}
{"op":"mcm","clk":"1002995451","pt":1580601710442,"mc":[{"id":"1.168179121","rc":[{"batb":[[0,3.75,106.99],[1,1.03,137],[2,1.02,2]],"ltp":4.7,"tv":9.99,"id":14904499},{"batb":[[0,1.45,279.61],[1,1.44,13],[2,1.43,2.02]],"ltp":1.62,"tv":34.08,"id":14904498},{"batb":[[0,7,57.31],[1,2.84,2.02],[2,2.82,2]],"ltp":0.0,"tv":0.0,"id":20912772},{"batb":[[0,5.9,67.86],[1,2.7,6],[2,2.68,2.02]],"batl":[[0,34,103.98],[1,36,6],[2,38,21.11]],"ltp":0.0,"tv":0.0,"id":20912771}]}]}
{"op":"mcm","clk":"1002996992","pt":1580601734731,"mc":[{"id":"1.168179121","rc":[{"batb":[[2,1.03,137]],"ltp":0.0,"tv":0.0,"id":20912772}]}]}
{"op":"mcm","clk":"1003013495","pt":1580601983673,"mc":[{"id":"1.168179121","rc":[{"batl":[[0,1.72,40.38]],"ltp":1.62,"tv":34.08,"id":14904498}]}]}
{"op":"mcm","clk":"1003015720","pt":1580602008412,"mc":[{"id":"1.168179121","rc":[{"batb":[[0,1.5,13.37],[1,1.45,279.61],[2,1.44,13]],"ltp":1.62,"tv":34.08,"id":14904498}]}]}
{"op":"mcm","clk":"1003067632","pt":1580602567852,"mc":[{"id":"1.168179121","rc":[{"batb":[[1,1.44,13],[2,1.43,2.02]],"ltp":1.62,"tv":34.08,"id":14904498}]}]}
{"op":"mcm","clk":"1003067727","pt":1580602568735,"mc":[{"id":"1.168179121","rc":[{"batl":[[0,1.71,96.62],[1,1.72,40.38],[2,2.3,7]],"ltp":1.62,"tv":34.08,"id":14904498}]}]}
{"op":"mcm","clk":"1003070584","pt":1580602600982,"mc":[{"id":"1.168179121","marketDefinition":{"bspMarket":false,"turnInPlayEnabled":true,"persistenceEnabled":true,"marketBaseRate":5.0,"eventId":"29680182","eventTypeId":"2","numberOfWinners":1,"bettingType":"ODDS","marketType":"SET_BETTING","marketTime":"2020-02-02T00:30:00.000Z","suspendTime":"2020-02-02T00:30:00.000Z","bspReconciled":false,"complete":true,"inPlay":false,"crossMatching":true,"runnersVoidable":false,"numberOfActiveRunners":4,"betDelay":0,"status":"OPEN","runners":[{"status":"ACTIVE","sortPriority":1,"id":20912771,"name":"Meligeni Rodrigues Alve 2-0"},{"status":"ACTIVE","sortPriority":2,"id":20912772,"name":"Meligeni Rodrigues Alve 2-1"},{"status":"ACTIVE","sortPriority":3,"id":14904498,"name":"T Monteiro 2-0"},{"status":"ACTIVE","sortPriority":4,"id":14904499,"name":"T Monteiro 2-1"}],"regulators":["MR_INT"],"countryCode":"UY","discountAllowed":true,"timezone":"UTC","openDate":"2020-02-02T00:15:00.000Z","version":3147905059,"name":"Set Betting","eventName":"Meligeni Rodrigues Alve v T Monteiro"}}]}
{"op":"mcm","clk":"1003070979","pt":1580602604992,"mc":[{"id":"1.168179121","marketDefinition":{"bspMarket":false,"turnInPlayEnabled":true,"persistenceEnabled":true,"marketBaseRate":5.0,"eventId":"29680182","eventTypeId":"2","numberOfWinners":1,"bettingType":"ODDS","marketType":"SET_BETTING","marketTime":"2020-02-02T00:30:00.000Z","suspendTime":"2020-02-02T00:30:00.000Z","bspReconciled":false,"complete":true,"inPlay":false,"crossMatching":true,"runnersVoidable":false,"numberOfActiveRunners":4,"betDelay":0,"status":"OPEN","runners":[{"status":"ACTIVE","sortPriority":1,"id":20912771,"name":"Meligeni Rodrigues Alve 2-0"},{"status":"ACTIVE","sortPriority":2,"id":20912772,"name":"Meligeni Rodrigues Alve 2-1"},{"status":"ACTIVE","sortPriority":3,"id":14904498,"name":"T Monteiro 2-0"},{"status":"ACTIVE","sortPriority":4,"id":14904499,"name":"T Monteiro 2-1"}],"regulators":["MR_INT"],"countryCode":"UY","discountAllowed":true,"timezone":"UTC","openDate":"2020-02-02T00:30:00.000Z","version":3147905149,"name":"Set Betting","eventName":"Meligeni Rodrigues Alve v T Monteiro"}}]}
{"op":"mcm","clk":"1003071542","pt":1580602610716,"mc":[{"id":"1.168179121","rc":[{"batb":[[0,7.6,52.54]],"ltp":0.0,"tv":0.0,"id":20912772},{"batb":[[0,7,57.3]],"batl":[[0,23,153.66]],"ltp":0.0,"tv":0.0,"id":20912771}]}]}
{"op":"mcm","clk":"1003078114","pt":1580602682837,"mc":[{"id":"1.168179121","rc":[{"batb":[[1,1.02,2],[2,1.01,0.51]],"ltp":4.7,"tv":9.99,"id":14904499},{"batb":[[1,1.43,2.02],[2,1.41,2.02]],"ltp":1.62,"tv":34.08,"id":14904498},{"batb":[[2,1.02,2]],"ltp":0.0,"tv":0.0,"id":20912772},{"batb":[[1,2.68,2.02],[2,2.64,2.02]],"ltp":0.0,"tv":0.0,"id":20912771}]}]}
{"op":"mcm","clk":"1003078143","pt":1580602683249,"mc":[{"id":"1.168179121","rc":[{"batb":[[0,3.8,5],[1,3.75,106.99],[2,1.02,2]],"ltp":4.7,"tv":9.99,"id":14904499},{"batb":[[0,1.51,11],[1,1.5,13.37],[2,1.43,2.02]],"ltp":1.62,"tv":34.08,"id":14904498},{"batb":[[0,7.8,6],[1,7.6,52.54],[2,2.84,2.02]],"ltp":0.0,"tv":0.0,"id":20912772},{"batb":[[0,7.2,6],[1,7,57.3],[2,2.68,2.02]],"ltp":0.0,"tv":0.0,"id":20912771}]}]}
{"op":"mcm","clk":"1003085328","pt":1580602775715,"mc":[{"id":"1.168179121","rc":[{"batl":[[0,1.7,40.38],[1,1.71,96.62]],"ltp":1.62,"tv":34.08,"id":14904498}]}]}
{"op":"mcm","clk":"1003127403","pt":1580603335732,"mc":[{"id":"1.168179121","rc":[{"batb":[[0,4.2,95.47],[1,3.8,5]],"batl":[[0,8.8,447.07]],"ltp":4.7,"tv":9.99,"id":14904499},{"batl":[[0,1.68,98.14],[1,1.7,40.38]],"ltp":1.62,"tv":34.08,"id":14904498},{"batb":[[0,8,50.13],[1,7.8,6]],"ltp":0.0,"tv":0.0,"id":20912772},{"batb":[[0,8.4,47.51],[1,7.2,6]],"ltp":0.0,"tv":0.0,"id":20912771}]}]}
{"op":"mcm","clk":"1003141084","pt":1580603501489,"mc":[{"id":"1.168179121","marketDefinition":{"bspMarket":false,"turnInPlayEnabled":true,"persistenceEnabled":true,"marketBaseRate":5.0,"eventId":"29680182","eventTypeId":"2","numberOfWinners":1,"bettingType":"ODDS","marketType":"SET_BETTING","marketTime":"2020-02-02T00:45:00.000Z","suspendTime":"2020-02-02T00:45:00.000Z","bspReconciled":false,"complete":true,"inPlay":false,"crossMatching":true,"runnersVoidable":false,"numberOfActiveRunners":4,"betDelay":0,"status":"OPEN","runners":[{"status":"ACTIVE","sortPriority":1,"id":20912771,"name":"Meligeni Rodrigues Alve 2-0"},{"status":"ACTIVE","sortPriority":2,"id":20912772,"name":"Meligeni Rodrigues Alve 2-1"},{"status":"ACTIVE","sortPriority":3,"id":14904498,"name":"T Monteiro 2-0"},{"status":"ACTIVE","sortPriority":4,"id":14904499,"name":"T Monteiro 2-1"}],"regulators":["MR_INT"],"countryCode":"UY","discountAllowed":true,"timezone":"UTC","openDate":"2020-02-02T00:30:00.000Z","version":3147932330,"name":"Set Betting","eventName":"Meligeni Rodrigues Alve v T Monteiro"},"rc":[{"batb":[[1,1.43,2.02],[2,1.41,2.02]],"ltp":1.62,"tv":34.08,"id":14904498}]}]}
{"op":"mcm","clk":"1003141344","pt":1580603504503,"mc":[{"id":"1.168179121","marketDefinition":{"bspMarket":false,"turnInPlayEnabled":true,"persistenceEnabled":true,"marketBaseRate":5.0,"eventId":"29680182","eventTypeId":"2","numberOfWinners":1,"bettingType":"ODDS","marketType":"SET_BETTING","marketTime":"2020-02-02T00:45:00.000Z","suspendTime":"2020-02-02T00:45:00.000Z","bspReconciled":false,"complete":true,"inPlay":false,"crossMatching":true,"runnersVoidable":false,"numberOfActiveRunners":4,"betDelay":0,"status":"OPEN","runners":[{"status":"ACTIVE","sortPriority":1,"id":20912771,"name":"Meligeni Rodrigues Alve 2-0"},{"status":"ACTIVE","sortPriority":2,"id":20912772,"name":"Meligeni Rodrigues Alve 2-1"},{"status":"ACTIVE","sortPriority":3,"id":14904498,"name":"T Monteiro 2-0"},{"status":"ACTIVE","sortPriority":4,"id":14904499,"name":"T Monteiro 2-1"}],"regulators":["MR_INT"],"countryCode":"UY","discountAllowed":true,"timezone":"UTC","openDate":"2020-02-02T00:45:00.000Z","version":3147932330,"name":"Set Betting","eventName":"Meligeni Rodrigues Alve v T Monteiro"}}]}
{"op":"mcm","clk":"1003141821","pt":1580603510274,"mc":[{"id":"1.168179121","rc":[{"batb":[[0,1.52,13.2],[1,1.51,11],[2,1.43,2.02]],"ltp":1.62,"tv":34.08,"id":14904498}]}]}
{"op":"mcm","clk":"1003142558","pt":1580603518772,"mc":[{"id":"1.168179121","rc":[{"batb":[[0,4.3,93.28]],"batl":[[0,9,437.41]],"ltp":4.7,"tv":9.99,"id":14904499},{"batl":[[0,1.67,98.65]],"ltp":1.62,"tv":34.08,"id":14904498},{"batb":[[0,7.8,6],[1,2.84,2.02],[2,1.02,2]],"ltp":0.0,"tv":0.0,"id":20912772},{"batb":[[0,8.6,46.39]],"batl":[[0,18,196.3]],"ltp":0.0,"tv":0.0,"id":20912771}]}]}
{"op":"mcm","clk":"1003144869","pt":1580603544495,"mc":[{"id":"1.168179121","rc":[{"batl":[[0,9,45.25]],"ltp":4.7,"tv":9.99,"id":14904499},{"batl":[[0,1.67,241.46]],"ltp":1.62,"tv":34.08,"id":14904498},{"batb":[[0,8.2,48.67],[1,7.8,6],[2,2.84,2.02]],"ltp":0.0,"tv":0.0,"id":20912772},{"batl":[[0,18,195.7]],"ltp":0.0,"tv":0.0,"id":20912771}]}]}
{"op":"mcm","clk":"1003151903","pt":1580603629814,"mc":[{"id":"1.168179121","rc":[{"batb":[[0,4.6,32.5],[1,4.3,93.28],[2,3.8,5]],"batl":[[0,5.4,31.08],[1,9,45.25]],"ltp":4.7,"tv":9.99,"id":14904499},{"batb":[[0,1.54,70.11],[1,1.52,13.2],[2,1.51,11]],"batl":[[0,1.62,68.45],[1,1.67,241.46],[2,1.7,40.38]],"ltp":1.62,"tv":34.08,"id":14904498},{"batb":[[0,10.5,23.76],[1,8.2,48.67],[2,7.8,6]],"batl":[[1,14.5,21.79]],"ltp":0.0,"tv":0.0,"id":20912772},{"batb":[[0,10,25.81],[1,8.6,46.39],[2,7.2,6]],"batl":[[0,13.5,23.6],[1,18,195.7],[2,36,6]],"ltp":0.0,"tv":0.0,"id":20912771}]}]}
{"op":"mcm","clk":"1003152019","pt":1580603631315,"mc":[{"id":"1.168179121","rc":[{"trd":[[12.5,0.16]],"batl":[[0,12.5,5.92]],"ltp":12.5,"tv":0.16,"id":20912772}],"tv":44.24}]}
{"op":"mcm","clk":"1003152581","pt":1580603637535,"mc":[{"id":"1.168179121","rc":[{"batl":[[0,5.3,31.55]],"ltp":4.7,"tv":9.99,"id":14904499},{"batb":[[0,1.55,68.77]],"batl":[[0,1.63,67.19]],"ltp":1.62,"tv":34.08,"id":14904498},{"batl":[[1,14,22.03]],"ltp":12.5,"tv":0.16,"id":20912772}]}]}
{"op":"mcm","clk":"1003154177","pt":1580603655060,"mc":[{"id":"1.168179121","rc":[{"batb":[[1,1.51,11],[2,1.43,2.02]],"ltp":1.62,"tv":34.08,"id":14904498}]}]}
{"op":"mcm","clk":"1003154925","pt":1580603663055,"mc":[{"id":"1.168179121","rc":[{"batb":[[0,1.56,12.85],[1,1.55,68.77],[2,1.51,11]],"ltp":1.62,"tv":34.08,"id":14904498}]}]}
{"op":"mcm","clk":"1003158029","pt":1580603699411,"mc":[{"id":"1.168179121","rc":[{"batb":[[0,1.55,68.77],[1,1.51,11],[2,1.43,2.02]],"ltp":1.62,"tv":34.08,"id":14904498}]}]}
{"op":"mcm","clk":"1003158728","pt":1580603706699,"mc":[{"id":"1.168179121","rc":[{"trd":[[1.63,24.61]],"batb":[[0,1.55,68.45]],"batl":[[0,1.63,54.89]],"ltp":1.63,"tv":58.68,"id":14904498}],"tv":68.85}]}
{"op":"mcm","clk":"1003159677","pt":1580603717637,"mc":[{"id":"1.168179121","rc":[{"batl":[[1,1.7,40.38],[2,2.3,7]],"ltp":1.63,"tv":58.68,"id":14904498},{"batb":[[1,7.2,6],[2,2.68,2.02]],"batl":[[1,36,6],[2,36,0]],"ltp":0.0,"tv":0.0,"id":20912771}]}]}
{"op":"mcm","clk":"1003159840","pt":1580603719405,"mc":[{"id":"1.168179121","rc":[{"batl":[[1,2.3,7],[2,5,9.09]],"ltp":1.63,"tv":58.68,"id":14904498}]}]}
{"op":"mcm","clk":"1003162186","pt":1580603747760,"mc":[{"id":"1.168179121","rc":[{"batb":[[1,3.8,5],[2,1.02,2]],"batl":[[1,9,0]],"ltp":4.7,"tv":9.99,"id":14904499},{"batb":[[1,7.8,6],[2,2.84,2.02]],"ltp":12.5,"tv":0.16,"id":20912772}]}]}
{"op":"mcm","clk":"1003166663","pt":1580603799332,"mc":[{"id":"1.168179121","marketDefinition":{"bspMarket":false,"turnInPlayEnabled":true,"persistenceEnabled":true,"marketBaseRate":5.0,"eventId":"29680182","eventTypeId":"2","numberOfWinners":1,"bettingType":"ODDS","marketType":"SET_BETTING","marketTime":"2020-02-02T00:32:00.000Z","suspendTime":"2020-02-02T00:32:00.000Z","bspReconciled":false,"complete":true,"inPlay":false,"crossMatching":true,"runnersVoidable":false,"numberOfActiveRunners":4,"betDelay":0,"status":"OPEN","runners":[{"status":"ACTIVE","sortPriority":1,"id":20912771,"name":"Meligeni Rodrigues Alve 2-0"},{"status":"ACTIVE","sortPriority":2,"id":20912772,"name":"Meligeni Rodrigues Alve 2-1"},{"status":"ACTIVE","sortPriority":3,"id":14904498,"name":"T Monteiro 2-0"},{"status":"ACTIVE","sortPriority":4,"id":14904499,"name":"T Monteiro 2-1"}],"regulators":["MR_INT"],"countryCode":"UY","discountAllowed":true,"timezone":"UTC","openDate":"2020-02-02T00:45:00.000Z","version":3147936781,"name":"Set Betting","eventName":"Meligeni Rodrigues Alve v T Monteiro"}}]}
{"op":"mcm","clk":"1003167020","pt":1580603803341,"mc":[{"id":"1.168179121","marketDefinition":{"bspMarket":false,"turnInPlayEnabled":true,"persistenceEnabled":true,"marketBaseRate":5.0,"eventId":"29680182","eventTypeId":"2","numberOfWinners":1,"bettingType":"ODDS","marketType":"SET_BETTING","marketTime":"2020-02-02T00:32:00.000Z","suspendTime":"2020-02-02T00:32:00.000Z","bspReconciled":false,"complete":true,"inPlay":false,"crossMatching":true,"runnersVoidable":false,"numberOfActiveRunners":4,"betDelay":0,"status":"OPEN","runners":[{"status":"ACTIVE","sortPriority":1,"id":20912771,"name":"Meligeni Rodrigues Alve 2-0"},{"status":"ACTIVE","sortPriority":2,"id":20912772,"name":"Meligeni Rodrigues Alve 2-1"},{"status":"ACTIVE","sortPriority":3,"id":14904498,"name":"T Monteiro 2-0"},{"status":"ACTIVE","sortPriority":4,"id":14904499,"name":"T Monteiro 2-1"}],"regulators":["MR_INT"],"countryCode":"UY","discountAllowed":true,"timezone":"UTC","openDate":"2020-02-02T00:32:00.000Z","version":3147936871,"name":"Set Betting","eventName":"Meligeni Rodrigues Alve v T Monteiro"}}]}
{"op":"mcm","clk":"1003169448","pt":1580603833795,"mc":[{"id":"1.168179121","rc":[{"batb":[[1,1.43,2.02],[2,1.41,2.02]],"ltp":1.63,"tv":58.68,"id":14904498},{"batb":[[1,2.84,2.02],[2,1.02,2]],"ltp":12.5,"tv":0.16,"id":20912772},{"batb":[[1,2.68,2.02],[2,2.64,2.02]],"ltp":0.0,"tv":0.0,"id":20912771}]}]}
{"op":"mcm","clk":"1003169492","pt":1580603834476,"mc":[{"id":"1.168179121","rc":[{"batb":[[0,4.6,37.5],[1,1.02,2],[2,1.01,1.01]],"ltp":4.7,"tv":9.99,"id":14904499},{"batb":[[0,1.56,11],[1,1.55,68.45],[2,1.43,2.02]],"ltp":1.63,"tv":58.68,"id":14904498},{"batb":[[0,11,6],[1,10.5,23.76],[2,2.84,2.02]],"ltp":12.5,"tv":0.16,"id":20912772},{"batb":[[1,9.4,6],[2,2.68,2.02]],"ltp":0.0,"tv":0.0,"id":20912771}]}]}
{"op":"mcm","clk":"1003173573","pt":1580603895634,"mc":[{"id":"1.168179121","rc":[{"batl":[[1,5,9.09],[2,5,0]],"ltp":1.63,"tv":58.68,"id":14904498},{"batl":[[0,14,22.03],[1,14,0]],"ltp":12.5,"tv":0.16,"id":20912772},{"batl":[[1,36,0]],"ltp":0.0,"tv":0.0,"id":20912771}]}]}
{"op":"mcm","clk":"1003179304","pt":1580603988440,"mc":[{"id":"1.168179121","rc":[{"batb":[[0,1.56,78.59],[1,1.43,2.02],[2,1.41,2.02]],"ltp":1.63,"tv":58.68,"id":14904498},{"batl":[[0,13,25.41]],"ltp":0.0,"tv":0.0,"id":20912771}]}]}
{"op":"mcm","clk":"1003179967","pt":1580603998856,"mc":[{"id":"1.168179121","rc":[{"batl":[[0,5.3,31.24]],"ltp":4.7,"tv":9.99,"id":14904499},{"batb":[[0,1.56,77.8]],"batl":[[0,1.64,65.23]],"ltp":1.63,"tv":58.68,"id":14904498},{"batl":[[0,13.5,23.6]],"ltp":12.5,"tv":0.16,"id":20912772}]}]}
{"op":"mcm","clk":"1003180809","pt":1580604011579,"mc":[{"id":"1.168179121","rc":[{"batb":[[0,4.7,32.42],[1,4.6,5],[2,1.02,2]],"batl":[[0,5.3,31]],"ltp":4.7,"tv":9.99,"id":14904499},{"batb":[[0,1.57,65.86],[1,1.56,11],[2,1.43,2.02]],"batl":[[0,1.65,64.44]],"ltp":1.63,"tv":58.68,"id":14904498},{"batb":[[1,10,26.75]],"ltp":12.5,"tv":0.16,"id":20912772},{"batb":[[0,9.8,29.9]],"batl":[[0,12.5,27.15]],"ltp":0.0,"tv":0.0,"id":20912771}]}]}
{"op":"mcm","clk":"1003181896","pt":1580604028638,"mc":[{"id":"1.168179121","rc":[{"batb":[[0,4.7,32.18]],"batl":[[0,5.4,30.76]],"ltp":4.7,"tv":9.99,"id":14904499},{"batb":[[0,1.58,64.99]],"batl":[[0,1.65,63.57]],"ltp":1.63,"tv":58.68,"id":14904498},{"batl":[[0,13,25.34]],"ltp":12.5,"tv":0.16,"id":20912772},{"batb":[[0,9.6,31]],"ltp":0.0,"tv":0.0,"id":20912771}]}]}
{"op":"mcm","clk":"1003182536","pt":1580604038831,"mc":[{"id":"1.168179121","rc":[{"batb":[[0,4.7,31.87]],"batl":[[0,5.4,30.45]],"ltp":4.7,"tv":9.99,"id":14904499},{"batb":[[0,1.58,64.05]],"batl":[[0,1.66,62.63]],"ltp":1.63,"tv":58.68,"id":14904498},{"batb":[[0,9.4,38.18],[1,2.68,2.02],[2,2.64,2.02]],"batl":[[0,12,29.19]],"ltp":0.0,"tv":0.0,"id":20912771}]}]}
{"op":"mcm","clk":"1003182551","pt":1580604039037,"mc":[{"id":"1.168179121","rc":[{"trd":[[1.58,4]],"batb":[[0,1.58,62.05]],"ltp":1.58,"tv":62.69,"id":14904498}],"tv":72.85}]}
{"op":"mcm","clk":"1003183203","pt":1580604048654,"mc":[{"id":"1.168179121","rc":[{"batl":[[0,12.5,29.19]],"ltp":0.0,"tv":0.0,"id":20912771}]}]}
{"op":"mcm","clk":"1003188972","pt":1580604144873,"mc":[{"id":"1.168179121","rc":[{"batb":[[0,4.7,31.71]],"batl":[[0,5.4,30.29]],"ltp":4.7,"tv":9.99,"id":14904499},{"batb":[[0,9.4,37.87]],"batl":[[0,12.5,28.88]],"ltp":0.0,"tv":0.0,"id":20912771}]}]}
{"op":"mcm","clk":"1003199590","pt":1580604319848,"mc":[{"id":"1.168179121","marketDefinition":{"bspMarket":false,"turnInPlayEnabled":true,"persistenceEnabled":true,"marketBaseRate":5.0,"eventId":"29680182","eventTypeId":"2","numberOfWinners":1,"bettingType":"ODDS","marketType":"SET_BETTING","marketTime":"2020-02-02T00:32:00.000Z","suspendTime":"2020-02-02T00:32:00.000Z","bspReconciled":false,"complete":true,"inPlay":true,"crossMatching":true,"runnersVoidable":false,"numberOfActiveRunners":4,"betDelay":3,"status":"OPEN","runners":[{"status":"ACTIVE","sortPriority":1,"id":20912771,"name":"Meligeni Rodrigues Alve 2-0"},{"status":"ACTIVE","sortPriority":2,"id":20912772,"name":"Meligeni Rodrigues Alve 2-1"},{"status":"ACTIVE","sortPriority":3,"id":14904498,"name":"T Monteiro 2-0"},{"status":"ACTIVE","sortPriority":4,"id":14904499,"name":"T Monteiro 2-1"}],"regulators":["MR_INT"],"countryCode":"UY","discountAllowed":true,"timezone":"UTC","openDate":"2020-02-02T00:32:00.000Z","version":3147941752,"name":"Set Betting","eventName":"Meligeni Rodrigues Alve v T Monteiro"},"rc":[{"batb":[[0,1.01,0.51],[1,4.6,0],[2,1.02,0]],"ltp":4.7,"tv":9.99,"id":14904499},{"batb":[[0,1.01,0.51],[1,1.56,0],[2,1.43,0]],"ltp":1.58,"tv":62.69,"id":14904498},{"batb":[[0,1.01,0.51],[1,10,0],[2,2.84,0]],"ltp":12.5,"tv":0.16,"id":20912772},{"batb":[[0,1.01,0.51],[1,2.68,0],[2,2.64,0]],"ltp":0.0,"tv":0.0,"id":20912771}]}]}
{"op":"mcm","clk":"1003200280","pt":1580604330575,"mc":[{"id":"1.168179121","rc":[{"batb":[[0,4.3,38.4],[1,3.95,48.78],[2,1.01,0.51]],"batl":[[0,5,36.59],[1,5.3,32.18]],"ltp":4.7,"tv":9.99,"id":14904499},{"batb":[[0,1.68,51.38],[1,1.61,60.19],[2,1.01,0.51]],"batl":[[0,1.77,50.36],[1,1.96,36.35]],"ltp":1.58,"tv":62.69,"id":14904498},{"batb":[[0,9.6,31.63],[1,8.8,14.79],[2,1.01,0.51]],"batl":[[0,12.5,28.72],[1,13,26.99]],"ltp":12.5,"tv":0.16,"id":20912772},{"batb":[[0,8.2,17.86],[1,6.6,27.93],[2,1.01,0.51]],"batl":[[0,10,17],[1,11.5,32.18]],"ltp":0.0,"tv":0.0,"id":20912771}]}]}
{"op":"mcm","clk":"1003201454","pt":1580604349490,"mc":[{"id":"1.168179121","rc":[{"batb":[[0,3.95,48.78],[1,1.01,0.51],[2,1.01,0]],"batl":[[0,5.3,32.18],[1,5.3,0]],"ltp":4.7,"tv":9.99,"id":14904499},{"batb":[[0,1.61,60.19],[1,1.01,0.51],[2,1.01,0]],"batl":[[0,1.96,36.35],[1,1.96,0]],"ltp":1.58,"tv":62.69,"id":14904498},{"batb":[[0,8.8,14.79],[1,1.01,0.51],[2,1.01,0]],"batl":[[0,13,26.99],[1,13,0]],"ltp":12.5,"tv":0.16,"id":20912772},{"batb":[[0,6.6,27.93],[1,1.01,0.51],[2,1.01,0]],"batl":[[0,11.5,32.18],[1,11.5,0]],"ltp":0.0,"tv":0.0,"id":20912771}]}]}
{"op":"mcm","clk":"1003201653","pt":1580604352787,"mc":[{"id":"1.168179121","rc":[{"batb":[[1,1.6,60.9],[2,1.01,0.51]],"batl":[[0,1.95,37.14],[1,1.96,36.35]],"ltp":1.58,"tv":62.69,"id":14904498},{"batb":[[0,9,14.16],[1,8.8,14.79],[2,1.01,0.51]],"ltp":12.5,"tv":0.16,"id":20912772},{"batb":[[0,6.8,27.7],[1,6.6,27.93],[2,1.01,0.51]],"batl":[[1,12,31.71]],"ltp":0.0,"tv":0.0,"id":20912771}]}]}
{"op":"mcm","clk":"1003201678","pt":1580604353098,"mc":[{"id":"1.168179121","rc":[{"batb":[[0,3.95,48.31]],"batl":[[0,5.3,31.94]],"ltp":4.7,"tv":9.99,"id":14904499},{"batb":[[0,1.6,60.9],[1,1.01,0.51],[2,1.01,0]],"batl":[[1,1.96,0]],"ltp":1.58,"tv":62.69,"id":14904498},{"batb":[[1,1.01,0.51],[2,1.01,0]],"batl":[[0,13,26.67]],"ltp":12.5,"tv":0.16,"id":20912772},{"batb":[[1,1.01,0.51],[2,1.01,0]],"batl":[[0,12,31.71],[1,12,0]],"ltp":0.0,"tv":0.0,"id":20912771}]}]}
{"op":"mcm","clk":"1003202839","pt":1580604372793,"mc":[{"id":"1.168179121","rc":[{"batb":[[1,3.55,31.16],[2,1.01,0.51]],"batl":[[0,4.5,45.71],[1,4.8,39.42]],"ltp":4.7,"tv":9.99,"id":14904499},{"batb":[[0,1.85,37.77],[1,1.73,46.34],[2,1.01,0.51]],"batl":[[1,2.24,50.28]],"ltp":1.58,"tv":62.69,"id":14904498},{"batb":[[1,8.6,15.74],[2,1.01,0.51]],"batl":[[0,11.5,31.87],[1,12,29.66]],"ltp":12.5,"tv":0.16,"id":20912772},{"batb":[[1,5.6,21.17],[2,1.01,0.51]],"batl":[[0,8,26.12],[1,9.2,19.99]],"ltp":0.0,"tv":0.0,"id":20912771}]}]}
{"op":"mcm","clk":"1003203652","pt":1580604388716,"mc":[{"id":"1.168179121","rc":[{"batb":[[0,3.55,31.16],[1,1.01,0.51],[2,1.01,0]],"batl":[[0,4.8,39.42],[1,4.8,0]],"ltp":4.7,"tv":9.99,"id":14904499},{"batb":[[0,1.73,46.34],[1,1.01,0.51],[2,1.01,0]],"batl":[[0,2.24,50.28],[1,2.24,0]],"ltp":1.58,"tv":62.69,"id":14904498},{"batb":[[0,8.6,15.74],[1,1.01,0.51],[2,1.01,0]],"batl":[[0,12,29.66],[1,12,0]],"ltp":12.5,"tv":0.16,"id":20912772},{"batb":[[0,5.6,21.17],[1,1.01,0.51],[2,1.01,0]],"batl":[[0,9.2,19.99],[1,9.2,0]],"ltp":0.0,"tv":0.0,"id":20912771}]}]}
{"op":"mcm","clk":"1003204105","pt":1580604396767,"mc":[{"id":"1.168179121","rc":[{"batb":[[0,4.2,41.47],[1,3.75,27.77],[2,1.01,0.51]],"batl":[[1,5.1,33.91]],"ltp":4.7,"tv":9.99,"id":14904499},{"batb":[[1,1.63,56.73],[2,1.01,0.51]],"batl":[[0,1.82,45.48],[1,2.1,59.64]],"ltp":1.58,"tv":62.69,"id":14904498},{"batb":[[0,9.4,32.81],[1,8.8,15.11],[2,1.01,0.51]],"batl":[[1,12.5,27.3]],"ltp":12.5,"tv":0.16,"id":20912772},{"batb":[[0,7.6,21.01],[1,6,34.93],[2,1.01,0.51]],"batl":[[1,11,14.63]],"ltp":0.0,"tv":0.0,"id":20912771}]}]}
{"op":"mcm","clk":"1003204817","pt":1580604409861,"mc":[{"id":"1.168179121","rc":[{"batb":[[0,3.75,27.77],[1,1.01,0.51],[2,1.01,0]],"batl":[[0,5.1,33.91],[1,5.1,0]],"ltp":4.7,"tv":9.99,"id":14904499},{"batb":[[0,1.63,56.73],[1,1.01,0.51],[2,1.01,0]],"batl":[[0,2.1,59.64],[1,2.1,0]],"ltp":1.58,"tv":62.69,"id":14904498},{"batb":[[0,8.8,15.11],[1,1.01,0.51],[2,1.01,0]],"batl":[[0,12.5,27.3],[1,12.5,0]],"ltp":12.5,"tv":0.16,"id":20912772},{"batb":[[0,6,34.93],[1,1.01,0.51],[2,1.01,0]],"batl":[[0,11,14.63],[1,11,0]],"ltp":0.0,"tv":0.0,"id":20912771}]}]}
{"op":"mcm","clk":"1003205659","pt":1580604423894,"mc":[{"id":"1.168179121","rc":[{"batb":[[0,1.01,0.51],[1,1.01,0]],"ltp":4.7,"tv":9.99,"id":14904499}]}]}
{"op":"mcm","clk":"1003205822","pt":1580604426784,"mc":[{"id":"1.168179121","rc":[{"batb":[[0,3.7,28.33],[1,3.3,37.85],[2,1.01,0.51]],"batl":[[0,4.1,27.54],[1,4.5,45.32],[2,5.1,33.91]],"ltp":4.7,"tv":9.99,"id":14904499},{"batb":[[0,1.95,63.1],[1,1.81,40.36],[2,1.63,56.73]],"batl":[[0,2.08,61.21],[1,2.1,59.64],[2,2.46,38.63]],"ltp":1.58,"tv":62.69,"id":14904498},{"batb":[[0,9,14.71],[1,8.8,15.11],[2,8.6,16.44]],"batl":[[0,11.5,33.2],[1,12,30.06],[2,12.5,27.3]],"ltp":12.5,"tv":0.16,"id":20912772},{"batb":[[0,6.2,32.97],[1,6,34.93],[2,5.1,26.04]],"batl":[[0,7.4,30.92],[1,8.6,23.21],[2,11,14.63]],"ltp":0.0,"tv":0.0,"id":20912771}]}]}
{"op":"mcm","clk":"1003205867","pt":1580604427402,"mc":[{"id":"1.168179121","rc":[{"batl":[[2,5.1,0]],"ltp":4.7,"tv":9.99,"id":14904499},{"batb":[[2,1.01,0.51]],"batl":[[1,2.46,38.63],[2,2.46,0]],"ltp":1.58,"tv":62.69,"id":14904498},{"batb":[[1,8.6,16.44],[2,1.01,0.51]],"batl":[[2,12.5,0]],"ltp":12.5,"tv":0.16,"id":20912772},{"batb":[[1,5.1,26.04],[2,1.01,0.51]],"batl":[[2,11,0]],"ltp":0.0,"tv":0.0,"id":20912771}]}]}
{"op":"mcm","clk":"1003206721","pt":1580604443725,"mc":[{"id":"1.168179121","rc":[{"batb":[[0,3.3,37.85],[1,1.01,0.51],[2,1.01,0]],"batl":[[0,4.5,45.32],[1,4.5,0]],"ltp":4.7,"tv":9.99,"id":14904499},{"batb":[[0,1.81,40.36],[1,1.01,0.51],[2,1.01,0]],"batl":[[0,2.46,38.63],[1,2.46,0]],"ltp":1.58,"tv":62.69,"id":14904498},{"batb":[[0,8.6,16.44],[1,1.01,0.51],[2,1.01,0]],"batl":[[0,12,30.06],[1,12,0]],"ltp":12.5,"tv":0.16,"id":20912772},{"batb":[[0,5.1,26.04],[1,1.01,0.51],[2,1.01,0]],"batl":[[0,8.6,23.21],[1,8.6,0]],"ltp":0.0,"tv":0.0,"id":20912771}]}]}
{"op":"mcm","clk":"1003208942","pt":1580604484668,"mc":[{"id":"1.168179121","rc":[{"batb":[[0,3.95,47.84],[1,3.3,37.69],[2,1.01,0.51]],"batl":[[1,5.1,34.93]],"ltp":4.7,"tv":9.99,"id":14904499},{"batb":[[1,1.64,56.18],[2,1.01,0.51]],"batl":[[0,1.91,39.66],[1,2.42,40.6]],"ltp":1.58,"tv":62.69,"id":14904498},{"batb":[[0,9.4,33.2],[1,8.6,16.21],[2,1.01,0.51]],"batl":[[1,13,26.83]],"ltp":12.5,"tv":0.16,"id":20912772},{"batb":[[0,7,24.47],[1,5.3,24],[2,1.01,0.51]],"batl":[[1,11,14.56]],"ltp":0.0,"tv":0.0,"id":20912771}]}]}
{"op":"mcm","clk":"1003210088","pt":1580604505569,"mc":[{"id":"1.168179121","rc":[{"batb":[[0,3.3,37.69],[1,1.01,0.51],[2,1.01,0]],"batl":[[0,5.1,34.93],[1,5.1,0]],"ltp":4.7,"tv":9.99,"id":14904499},{"batb":[[0,1.64,56.18],[1,1.01,0.51],[2,1.01,0]],"batl":[[0,2.42,40.6],[1,2.42,0]],"ltp":1.58,"tv":62.69,"id":14904498},{"batb":[[0,8.6,16.21],[1,1.01,0.51],[2,1.01,0]],"batl":[[0,13,26.83],[1,13,0]],"ltp":12.5,"tv":0.16,"id":20912772},{"batb":[[0,5.3,24],[1,1.01,0.51],[2,1.01,0]],"batl":[[0,11,14.56],[1,11,0]],"ltp":0.0,"tv":0.0,"id":20912771}]}]}
{"op":"mcm","clk":"1003211933","pt":1580604536642,"mc":[{"id":"1.168179121","rc":[{"batb":[[1,3.15,42.65],[2,1.01,0.51]],"batl":[[0,3.65,36.43],[1,3.95,30.06]],"ltp":4.7,"tv":9.99,"id":14904499},{"batb":[[0,2.26,41.62],[1,2.02,56.73],[2,1.01,0.51]],"batl":[[1,2.64,31.87]],"ltp":1.58,"tv":62.69,"id":14904498},{"batb":[[1,8.2,17.39],[2,1.01,0.51]],"batl":[[0,11,34.78]],"ltp":12.5,"tv":0.16,"id":20912772},{"batb":[[1,4.8,30.06],[2,1.01,0.51]],"batl":[[0,6.2,23.05],[1,7.2,33.91]],"ltp":0.0,"tv":0.0,"id":20912771}]}]}
{"op":"mcm","clk":"1003215314","pt":1580604587090,"mc":[{"id":"1.168179121","rc":[{"batb":[[0,3.15,42.65],[1,1.01,0.51],[2,1.01,0]],"batl":[[0,3.95,30.06],[1,3.95,0]],"ltp":4.7,"tv":9.99,"id":14904499},{"batb":[[0,2.02,56.73],[1,1.01,0.51],[2,1.01,0]],"batl":[[0,2.64,31.87],[1,2.64,0]],"ltp":1.58,"tv":62.69,"id":14904498},{"batb":[[0,8.2,17.39],[1,1.01,0.51],[2,1.01,0]],"ltp":12.5,"tv":0.16,"id":20912772},{"batb":[[0,4.8,30.06],[1,1.01,0.51],[2,1.01,0]],"batl":[[0,7.2,33.91],[1,7.2,0]],"ltp":0.0,"tv":0.0,"id":20912771}]}]}
{"op":"mcm","clk":"1003215553","pt":1580604590286,"mc":[{"id":"1.168179121","rc":[{"batb":[[0,2.04,54.68]],"batl":[[0,2.68,30.61]],"ltp":1.58,"tv":62.69,"id":14904498},{"batl":[[0,11,14.48]],"ltp":12.5,"tv":0.16,"id":20912772},{"batb":[[0,4.7,31.63]],"batl":[[0,7,35.8]],"ltp":0.0,"tv":0.0,"id":20912771}]}]}
{"op":"mcm","clk":"1003217060","pt":1580604611836,"mc":[{"id":"1.168179121","rc":[{"batb":[[0,3.55,31.08],[1,3.3,36.67],[2,1.01,0.51]],"batl":[[1,4.4,47.13]],"ltp":4.7,"tv":9.99,"id":14904499},{"batb":[[1,1.84,38.48],[2,1.01,0.51]],"batl":[[0,2.18,53.19],[1,2.4,40.76]],"ltp":1.58,"tv":62.69,"id":14904498},{"batb":[[0,8.8,15.11],[1,8.4,16.68],[2,1.01,0.51]],"batl":[[1,12,30.37]],"ltp":12.5,"tv":0.16,"id":20912772},{"batb":[[0,5.9,38.32],[1,5.3,24.23],[2,1.01,0.51]],"batl":[[1,8.4,24.55]],"ltp":0.0,"tv":0.0,"id":20912771}]}]}
{"op":"mcm","clk":"1003218072","pt":1580604626731,"mc":[{"id":"1.168179121","rc":[{"batb":[[0,3.3,36.67],[1,1.01,0.51],[2,1.01,0]],"batl":[[0,4.4,47.13],[1,4.4,0]],"ltp":4.7,"tv":9.99,"id":14904499},{"batb":[[0,1.84,38.48],[1,1.01,0.51],[2,1.01,0]],"batl":[[0,2.4,40.76],[1,2.4,0]],"ltp":1.58,"tv":62.69,"id":14904498},{"batb":[[0,8.4,16.68],[1,1.01,0.51],[2,1.01,0]],"batl":[[0,12,30.37],[1,12,0]],"ltp":12.5,"tv":0.16,"id":20912772},{"batb":[[0,5.3,24.23],[1,1.01,0.51],[2,1.01,0]],"batl":[[0,8.4,24.55],[1,8.4,0]],"ltp":0.0,"tv":0.0,"id":20912771}]}]}
{"op":"mcm","clk":"1003218972","pt":1580604640765,"mc":[{"id":"1.168179121","rc":[{"batb":[[1,3.1,43.12],[2,1.01,0.51]],"batl":[[0,3.7,35.49],[1,4.1,28.33]],"ltp":4.7,"tv":9.99,"id":14904499},{"batb":[[0,2.24,41.78],[1,1.99,59.8],[2,1.01,0.51]],"batl":[[1,2.68,30.69]],"ltp":1.58,"tv":62.69,"id":14904498},{"batb":[[1,8.2,17.86],[2,1.01,0.51]],"batl":[[0,10.5,15.97],[1,11,14.08]],"ltp":12.5,"tv":0.16,"id":20912772},{"batb":[[1,4.7,31.08],[2,1.01,0.51]],"batl":[[0,6.2,23.37],[1,7.2,32.97]],"ltp":0.0,"tv":0.0,"id":20912771}]}]}
{"op":"mcm","clk":"1003219920","pt":1580604655294,"mc":[{"id":"1.168179121","rc":[{"batb":[[0,3.1,43.12],[1,1.01,0.51],[2,1.01,0]],"batl":[[0,4.1,28.33],[1,4.1,0]],"ltp":4.7,"tv":9.99,"id":14904499},{"batb":[[0,1.99,59.8],[1,1.01,0.51],[2,1.01,0]],"batl":[[0,2.68,30.69],[1,2.68,0]],"ltp":1.58,"tv":62.69,"id":14904498},{"batb":[[0,8.2,17.86],[1,1.01,0.51],[2,1.01,0]],"batl":[[0,11,14.08],[1,11,0]],"ltp":12.5,"tv":0.16,"id":20912772},{"batb":[[0,4.7,31.08],[1,1.01,0.51],[2,1.01,0]],"batl":[[0,7.2,32.97],[1,7.2,0]],"ltp":0.0,"tv":0.0,"id":20912771}]}]}
{"op":"mcm","clk":"1003220500","pt":1580604664791,"mc":[{"id":"1.168179121","rc":[{"batb":[[0,3.65,29.19],[1,3.35,36.04],[2,1.01,0.51]],"batl":[[1,4.7,42.02]],"ltp":4.7,"tv":9.99,"id":14904499},{"batb":[[1,1.76,43.9],[2,1.01,0.51]],"batl":[[0,2.12,58.07],[1,2.38,42.49]],"ltp":1.58,"tv":62.69,"id":14904498},{"batb":[[0,9,14.63],[1,8.6,16.21],[2,1.01,0.51]],"batl":[[1,12,29.66]],"ltp":12.5,"tv":0.16,"id":20912772},{"batb":[[0,6,35.17],[1,5.4,23.37],[2,1.01,0.51]],"batl":[[1,9,20.93]],"ltp":0.0,"tv":0.0,"id":20912771}]}]}
{"op":"mcm","clk":"1003221635","pt":1580604682803,"mc":[{"id":"1.168179121","rc":[{"batb":[[0,3.35,36.04],[1,1.01,0.51],[2,1.01,0]],"batl":[[0,4.7,42.02],[1,4.7,0]],"ltp":4.7,"tv":9.99,"id":14904499},{"batb":[[0,1.76,43.9],[1,1.01,0.51],[2,1.01,0]],"batl":[[0,2.38,42.49],[1,2.38,0]],"ltp":1.58,"tv":62.69,"id":14904498},{"batb":[[0,8.6,16.21],[1,1.01,0.51],[2,1.01,0]],"batl":[[0,12,29.66],[1,12,0]],"ltp":12.5,"tv":0.16,"id":20912772},{"batb":[[0,5.4,23.37],[1,1.01,0.51],[2,1.01,0]],"batl":[[0,9,20.93],[1,9,0]],"ltp":0.0,"tv":0.0,"id":20912771}]}]}
{"op":"mcm","clk":"1003223070","pt":1580604701204,"mc":[{"id":"1.168179121","rc":[{"batb":[[0,4.1,44.22],[1,3.8,26.91],[2,1.01,0.51]],"batl":[[1,5.2,32.57]],"ltp":4.7,"tv":9.99,"id":14904499},{"batb":[[1,1.6,61.21],[2,1.01,0.51]],"batl":[[0,1.85,43.12],[1,2.02,33.28]],"ltp":1.58,"tv":62.69,"id":14904498},{"batb":[[0,9.4,32.73],[1,9,14.48],[2,1.01,0.51]],"batl":[[1,13,25.81]],"ltp":12.5,"tv":0.16,"id":20912772},{"batb":[[0,7.4,22.03],[1,6.4,29.82],[2,1.01,0.51]],"batl":[[1,12,30.84]],"ltp":0.0,"tv":0.0,"id":20912771}]}]}
{"op":"mcm","clk":"1003224381","pt":1580604721545,"mc":[{"id":"1.168179121","rc":[{"batb":[[0,3.8,26.91],[1,1.01,0.51],[2,1.01,0]],"batl":[[0,5.2,32.57],[1,5.2,0]],"ltp":4.7,"tv":9.99,"id":14904499},{"batb":[[0,1.6,61.21],[1,1.01,0.51],[2,1.01,0]],"batl":[[0,2.02,33.28],[1,2.02,0]],"ltp":1.58,"tv":62.69,"id":14904498},{"batb":[[0,9,14.48],[1,1.01,0.51],[2,1.01,0]],"batl":[[0,13,25.81],[1,13,0]],"ltp":12.5,"tv":0.16,"id":20912772},{"batb":[[0,6.4,29.82],[1,1.01,0.51],[2,1.01,0]],"batl":[[0,12,30.84],[1,12,0]],"ltp":0.0,"tv":0.0,"id":20912771}]}]}
{"op":"mcm","clk":"1003224578","pt":1580604724742,"mc":[{"id":"1.168179121","rc":[{"batb":[[0,3.75,27.54]],"ltp":4.7,"tv":9.99,"id":14904499},{"batb":[[0,1.59,62.79]],"batl":[[0,2,34.15]],"ltp":1.58,"tv":62.69,"id":14904498},{"batb":[[0,9.2,34.07]],"batl":[[0,13.5,24.23]],"ltp":12.5,"tv":0.16,"id":20912772},{"batb":[[0,6.6,28.01]],"batl":[[0,12.5,28.95]],"ltp":0.0,"tv":0.0,"id":20912771}]}]}
{"op":"mcm","clk":"1003224979","pt":1580604730580,"mc":[{"id":"1.168179121","rc":[{"batb":[[0,4.5,34.62],[1,4.2,42.33],[2,1.01,0.51]],"batl":[[1,5.5,29.51]],"ltp":4.7,"tv":9.99,"id":14904499},{"batb":[[1,1.53,72.23],[2,1.01,0.51]],"batl":[[0,1.67,61.37],[1,1.8,47.84]],"ltp":1.58,"tv":62.69,"id":14904498},{"batb":[[0,10,26.52],[1,9.8,29.51],[2,1.01,0.51]],"batl":[[1,14,22.11]],"ltp":12.5,"tv":0.16,"id":20912772},{"batb":[[0,9.4,31.94],[1,8,18.73],[2,1.01,0.51]],"batl":[[1,14,23.13]],"ltp":0.0,"tv":0.0,"id":20912771}]}]}
{"op":"mcm","clk":"1003226586","pt":1580604755814,"mc":[{"id":"1.168179121","rc":[{"batb":[[0,4.2,42.33],[1,1.01,0.51],[2,1.01,0]],"batl":[[0,5.5,29.51],[1,5.5,0]],"ltp":4.7,"tv":9.99,"id":14904499},{"batb":[[0,1.53,72.23],[1,1.01,0.51],[2,1.01,0]],"batl":[[0,1.8,47.84],[1,1.8,0]],"ltp":1.58,"tv":62.69,"id":14904498},{"batb":[[0,9.8,29.51],[1,1.01,0.51],[2,1.01,0]],"batl":[[0,14,22.11],[1,14,0]],"ltp":12.5,"tv":0.16,"id":20912772},{"batb":[[0,8,18.73],[1,1.01,0.51],[2,1.01,0]],"batl":[[0,14,23.13],[1,14,0]],"ltp":0.0,"tv":0.0,"id":20912771}]}]}
{"op":"mcm","clk":"1003226803","pt":1580604759421,"mc":[{"id":"1.168179121","rc":[{"batb":[[0,4.1,42.41]],"ltp":4.7,"tv":9.99,"id":14904499},{"batb":[[0,1.53,72.07]],"ltp":1.58,"tv":62.69,"id":14904498}]}]}
{"op":"mcm","clk":"1003228286","pt":1580604780348,"mc":[{"id":"1.168179121","rc":[{"batb":[[0,4.2,42.33],[1,3.8,26.83],[2,1.01,0.51]],"batl":[[0,4.8,40.21],[1,5.1,35.01]],"ltp":4.7,"tv":9.99,"id":14904499},{"batb":[[0,1.71,48.63],[1,1.62,58.85],[2,1.01,0.51]],"batl":[[0,1.8,47.68],[1,2,34.23]],"ltp":1.58,"tv":62.69,"id":14904498},{"batb":[[1,9.2,34.31],[2,1.01,0.51]],"batl":[[0,13,26.99],[1,13.5,24.86]],"ltp":12.5,"tv":0.16,"id":20912772},{"batb":[[1,6.6,28.88],[2,1.01,0.51]],"batl":[[0,9.8,17.94],[1,11.5,31.87]],"ltp":0.0,"tv":0.0,"id":20912771}]}]}
{"op":"mcm","clk":"1003229656","pt":1580604801332,"mc":[{"id":"1.168179121","rc":[{"batb":[[0,3.8,26.83],[1,1.01,0.51],[2,1.01,0]],"batl":[[0,5.1,35.01],[1,5.1,0]],"ltp":4.7,"tv":9.99,"id":14904499},{"batb":[[0,1.62,58.85],[1,1.01,0.51],[2,1.01,0]],"batl":[[0,2,34.23],[1,2,0]],"ltp":1.58,"tv":62.69,"id":14904498},{"batb":[[0,9.2,34.31],[1,1.01,0.51],[2,1.01,0]],"batl":[[0,13.5,24.86],[1,13.5,0]],"ltp":12.5,"tv":0.16,"id":20912772},{"batb":[[0,6.6,28.88],[1,1.01,0.51],[2,1.01,0]],"batl":[[0,11.5,31.87],[1,11.5,0]],"ltp":0.0,"tv":0.0,"id":20912771}]}]}
{"op":"mcm","clk":"1003230814","pt":1580604819799,"mc":[{"id":"1.168179121","rc":[{"batb":[[0,4.4,36.74],[1,4,46.34],[2,1.01,0.51]],"batl":[[1,5.4,30.14]],"ltp":4.7,"tv":9.99,"id":14904499},{"batb":[[1,1.55,69.71],[2,1.01,0.51]],"batl":[[0,1.7,57.6],[1,1.86,42.57]],"ltp":1.58,"tv":62.69,"id":14904498},{"batb":[[0,10,27.3],[1,9.6,31.24],[2,1.01,0.51]],"batl":[[1,14,22.66]],"ltp":12.5,"tv":0.16,"id":20912772},{"batb":[[0,9,14.16],[1,7.4,21.95],[2,1.01,0.51]],"batl":[[1,13.5,24.86]],"ltp":0.0,"tv":0.0,"id":20912771}]}]}
{"op":"mcm","clk":"1003231978","pt":1580604838638,"mc":[{"id":"1.168179121","rc":[{"batb":[[0,4,46.34],[1,1.01,0.51],[2,1.01,0]],"batl":[[0,5.4,30.14],[1,5.4,0]],"ltp":4.7,"tv":9.99,"id":14904499},{"batb":[[0,1.55,69.71],[1,1.01,0.51],[2,1.01,0]],"batl":[[0,1.86,42.57],[1,1.86,0]],"ltp":1.58,"tv":62.69,"id":14904498},{"batb":[[0,9.6,31.24],[1,1.01,0.51],[2,1.01,0]],"batl":[[0,14,22.66],[1,14,0]],"ltp":12.5,"tv":0.16,"id":20912772},{"batb":[[0,7.4,21.95],[1,1.01,0.51],[2,1.01,0]],"batl":[[0,13.5,24.86],[1,13.5,0]],"ltp":0.0,"tv":0.0,"id":20912771}]}]}
{"op":"mcm","clk":"1003233201","pt":1580604859850,"mc":[{"id":"1.168179121","rc":[{"batb":[[0,4.7,31.55],[1,4.3,38.16],[2,4,46.34]],"batl":[[1,5.7,26.91]],"ltp":4.7,"tv":9.99,"id":14904499},{"batb":[[1,1.49,79.86],[2,1.01,0.51]],"batl":[[0,1.62,68.06],[1,1.73,53.98],[2,1.86,42.57]],"ltp":1.58,"tv":62.69,"id":14904498},{"batb":[[0,10.5,24.71],[1,10,28.56],[2,9.6,31.24]],"batl":[[1,14.5,21.4]],"ltp":12.5,"tv":0.16,"id":20912772},{"batb":[[0,10,27.22],[1,8.8,15.42],[2,7.4,21.95]],"batl":[[1,15,19.04]],"ltp":0.0,"tv":0.0,"id":20912771}]}]}
{"op":"mcm","clk":"1003233251","pt":1580604860834,"mc":[{"id":"1.168179121","rc":[{"batb":[[2,1.01,0.51]],"ltp":4.7,"tv":9.99,"id":14904499},{"batl":[[2,1.86,0]],"ltp":1.58,"tv":62.69,"id":14904498},{"batb":[[2,1.01,0.51]],"ltp":12.5,"tv":0.16,"id":20912772},{"batb":[[2,1.01,0.51]],"ltp":0.0,"tv":0.0,"id":20912771}]}]}
{"op":"mcm","clk":"1003234334","pt":1580604880371,"mc":[{"id":"1.168179121","rc":[{"batb":[[0,4.3,38.16],[1,1.01,0.51],[2,1.01,0]],"batl":[[0,5.7,26.91],[1,5.7,0]],"ltp":4.7,"tv":9.99,"id":14904499},{"batb":[[0,1.49,79.86],[1,1.01,0.51],[2,1.01,0]],"batl":[[0,1.73,53.98],[1,1.73,0]],"ltp":1.58,"tv":62.69,"id":14904498},{"batb":[[0,10,28.56],[1,1.01,0.51],[2,1.01,0]],"batl":[[0,14.5,21.4],[1,14.5,0]],"ltp":12.5,"tv":0.16,"id":20912772},{"batb":[[0,8.8,15.42],[1,1.01,0.51],[2,1.01,0]],"batl":[[0,15,19.04],[1,15,0]],"ltp":0.0,"tv":0.0,"id":20912771}]}]}
{"op":"mcm","clk":"1003234547","pt":1580604883872,"mc":[{"id":"1.168179121","rc":[{"batb":[[0,4.4,37.85]],"batl":[[0,5.7,26.75]],"ltp":4.7,"tv":9.99,"id":14904499},{"batb":[[0,1.5,78.92]],"batl":[[0,1.74,53.27]],"ltp":1.58,"tv":62.69,"id":14904498},{"batb":[[0,9.8,29.58]],"ltp":12.5,"tv":0.16,"id":20912772},{"batb":[[0,8.6,15.97]],"ltp":0.0,"tv":0.0,"id":20912771}]}]}
{"op":"mcm","clk":"1003235375","pt":1580604899722,"mc":[{"id":"1.168179121","rc":[{"batb":[[0,5,27.85],[1,4.7,31.24],[2,1.01,0.51]],"batl":[[1,5.8,25.49]],"ltp":4.7,"tv":9.99,"id":14904499},{"batb":[[1,1.47,84.66],[2,1.01,0.51]],"batl":[[0,1.57,76.87],[1,1.63,66.49]],"ltp":1.58,"tv":62.69,"id":14904498},{"batb":[[0,10.5,24.08],[1,10,26.2],[2,1.01,0.51]],"batl":[[0,14,22.11],[1,14.5,20.77]],"ltp":12.5,"tv":0.16,"id":20912772},{"batb":[[0,11,21.32],[1,10,28.88],[2,1.01,0.51]],"batl":[[1,16,17.07]],"ltp":0.0,"tv":0.0,"id":20912771}]}]}
{"op":"mcm","clk":"1003236647","pt":1580604924806,"mc":[{"id":"1.168179121","rc":[{"batb":[[0,4.7,31.24],[1,1.01,0.51],[2,1.01,0]],"batl":[[0,5.8,25.49],[1,5.8,0]],"ltp":4.7,"tv":9.99,"id":14904499},{"batb":[[0,1.47,84.66],[1,1.01,0.51],[2,1.01,0]],"batl":[[0,1.63,66.49],[1,1.63,0]],"ltp":1.58,"tv":62.69,"id":14904498},{"batb":[[0,10,26.2],[1,1.01,0.51],[2,1.01,0]],"batl":[[0,14.5,20.77],[1,14.5,0]],"ltp":12.5,"tv":0.16,"id":20912772},{"batb":[[0,10,28.88],[1,1.01,0.51],[2,1.01,0]],"batl":[[0,16,17.07],[1,16,0]],"ltp":0.0,"tv":0.0,"id":20912771}]}]}
{"op":"mcm","clk":"1003236999","pt":1580604932858,"mc":[{"id":"1.168179121","rc":[{"batb":[[0,5.1,26.52],[1,4.8,30.69],[2,1.01,0.51]],"batl":[[1,6.6,40.21]],"ltp":4.7,"tv":9.99,"id":14904499},{"batb":[[1,1.4,104.88],[2,1.01,0.51]],"batl":[[0,1.54,82.46],[1,1.61,69.71]],"ltp":1.58,"tv":62.69,"id":14904498},{"batb":[[0,11,22.58],[1,10.5,25.41],[2,1.01,0.51]],"batl":[[1,15.5,18.73]],"ltp":12.5,"tv":0.16,"id":20912772},{"batb":[[0,12,18.41],[1,10.5,25.41],[2,1.01,0.51]],"batl":[[1,20,11.17]],"ltp":0.0,"tv":0.0,"id":20912771}]}]}
{"op":"mcm","clk":"1003238162","pt":1580604958803,"mc":[{"id":"1.168179121","rc":[{"batl":[[1,5.9,25.18],[2,6.6,40.21]],"ltp":4.7,"tv":9.99,"id":14904499},{"batb":[[0,1.48,82.85],[1,1.47,84.66],[2,1.4,104.88]],"batl":[[1,1.55,80.73],[2,1.61,69.71]],"ltp":1.58,"tv":62.69,"id":14904498},{"batb":[[2,10,27.07]],"batl":[[0,14,22.11],[1,14.5,20.77],[2,15,19.91]],"ltp":12.5,"tv":0.16,"id":20912772},{"batb":[[1,11.5,19.59],[2,10.5,25.41]],"batl":[[0,15.5,18.1],[1,16,17.07],[2,19.5,11.88]],"ltp":0.0,"tv":0.0,"id":20912771}]}]}
{"op":"mcm","clk":"1003238205","pt":1580604959791,"mc":[{"id":"1.168179121","rc":[{"batb":[[0,5.1,26.2],[1,4.8,30.29]],"batl":[[0,5.9,25.18],[1,6.6,39.81],[2,6.6,0]],"ltp":4.7,"tv":9.99,"id":14904499},{"batb":[[1,1.4,102.68],[2,1.01,0.51]],"batl":[[0,1.55,80.73],[1,1.62,68.14],[2,1.61,0]],"ltp":1.58,"tv":62.69,"id":14904498},{"batb":[[0,10.5,24.08],[1,10,27.07],[2,1.01,0.51]],"batl":[[1,15,19.91],[2,15,0]],"ltp":12.5,"tv":0.16,"id":20912772},{"batb":[[0,11.5,19.59],[1,10,27.07],[2,1.01,0.51]],"batl":[[1,19.5,11.88],[2,19.5,0]],"ltp":0.0,"tv":0.0,"id":20912771}]}]}
{"op":"mcm","clk":"1003238325","pt":1580604962094,"mc":[{"id":"1.168179121","rc":[{"batb":[[0,1.48,356.61]],"ltp":1.58,"tv":62.69,"id":14904498}]}]}
{"op":"mcm","clk":"1003241178","pt":1580605007643,"mc":[{"id":"1.168179121","rc":[{"batb":[[0,4.8,30.29],[1,1.01,0.51],[2,1.01,0]],"batl":[[0,6.6,39.81],[1,6.6,0]],"ltp":4.7,"tv":9.99,"id":14904499},{"batb":[[0,1.4,102.68],[1,1.01,0.51],[2,1.01,0]],"batl":[[0,1.62,68.14],[1,1.62,0]],"ltp":1.58,"tv":62.69,"id":14904498},{"batb":[[0,10,27.07],[1,1.01,0.51],[2,1.01,0]],"batl":[[0,15,19.91],[1,15,0]],"ltp":12.5,"tv":0.16,"id":20912772},{"batb":[[0,10,27.07],[1,1.01,0.51],[2,1.01,0]],"batl":[[0,19.5,11.88],[1,19.5,0]],"ltp":0.0,"tv":0.0,"id":20912771}]}]}
{"op":"mcm","clk":"1003241913","pt":1580605018792,"mc":[{"id":"1.168179121","rc":[{"batb":[[1,4.5,34.23],[2,1.01,0.51]],"batl":[[0,5.5,28.95],[1,6,24.39]],"ltp":4.7,"tv":9.99,"id":14904499},{"batb":[[0,1.54,69.79],[1,1.47,85.13],[2,1.01,0.51]],"batl":[[1,1.69,58.85]],"ltp":1.58,"tv":62.69,"id":14904498},{"batb":[[1,9.8,29.58],[2,1.01,0.51]],"batl":[[0,13.5,24.71],[1,14,22.19]],"ltp":12.5,"tv":0.16,"id":20912772},{"batb":[[1,9.2,34.86],[2,1.01,0.51]],"batl":[[0,13.5,24.71],[1,16,17.07]],"ltp":0.0,"tv":0.0,"id":20912771}]}]}
{"op":"mcm","clk":"1003242654","pt":1580605030799,"mc":[{"id":"1.168179121","rc":[{"batb":[[0,4.5,34.23],[1,1.01,0.51],[2,1.01,0]],"batl":[[0,6,24.39],[1,6,0]],"ltp":4.7,"tv":9.99,"id":14904499},{"batb":[[0,1.47,85.13],[1,1.01,0.51],[2,1.01,0]],"batl":[[0,1.69,58.85],[1,1.69,0]],"ltp":1.58,"tv":62.69,"id":14904498},{"batb":[[0,9.8,29.58],[1,1.01,0.51],[2,1.01,0]],"batl":[[0,14,22.19],[1,14,0]],"ltp":12.5,"tv":0.16,"id":20912772},{"batb":[[0,9.2,34.86],[1,1.01,0.51],[2,1.01,0]],"batl":[[0,16,17.07],[1,16,0]],"ltp":0.0,"tv":0.0,"id":20912771}]}]}
{"op":"mcm","clk":"1003243167","pt":1580605039719,"mc":[{"id":"1.168179121","rc":[{"batb":[[1,4.4,37.92],[2,1.01,0.51]],"batl":[[0,5.2,32.73],[1,5.5,28.72],[2,6,24.39]],"ltp":4.7,"tv":9.99,"id":14904499},{"batb":[[0,1.61,60.11],[1,1.54,70.26],[2,1.47,85.13]],"batl":[[1,1.75,51.77]],"ltp":1.58,"tv":62.69,"id":14904498},{"batb":[[1,9.4,31.79],[2,1.01,0.51]],"batl":[[0,13,26.91],[1,13.5,24.71],[2,14,22.19]],"ltp":12.5,"tv":0.16,"id":20912772},{"batb":[[1,8.4,16.52],[2,1.01,0.51]],"batl":[[0,12,31.47],[1,13.5,24.39],[2,16,17.07]],"ltp":0.0,"tv":0.0,"id":20912771}]}]}
{"op":"mcm","clk":"1003243205","pt":1580605040485,"mc":[{"id":"1.168179121","rc":[{"batl":[[2,6,0]],"ltp":4.7,"tv":9.99,"id":14904499},{"batb":[[2,1.01,0.51]],"ltp":1.58,"tv":62.69,"id":14904498},{"batl":[[2,14,0]],"ltp":12.5,"tv":0.16,"id":20912772},{"batl":[[2,16,0]],"ltp":0.0,"tv":0.0,"id":20912771}]}]}
{"op":"mcm","clk":"1003243826","pt":1580605052547,"mc":[{"id":"1.168179121","rc":[{"batb":[[0,4.4,37.92],[1,1.01,0.51],[2,1.01,0]],"batl":[[0,5.5,28.72],[1,5.5,0]],"ltp":4.7,"tv":9.99,"id":14904499},{"batb":[[0,1.54,70.26],[1,1.01,0.51],[2,1.01,0]],"batl":[[0,1.75,51.77],[1,1.75,0]],"ltp":1.58,"tv":62.69,"id":14904498},{"batb":[[0,9.4,31.79],[1,1.01,0.51],[2,1.01,0]],"batl":[[0,13.5,24.71],[1,13.5,0]],"ltp":12.5,"tv":0.16,"id":20912772},{"batb":[[0,8.4,16.52],[1,1.01,0.51],[2,1.01,0]],"batl":[[0,13.5,24.39],[1,13.5,0]],"ltp":0.0,"tv":0.0,"id":20912771}]}]}
{"op":"mcm","clk":"1003244397","pt":1580605061639,"mc":[{"id":"1.168179121","rc":[{"batb":[[1,4.2,40.36],[2,1.01,0.51]],"batl":[[0,5,36.12],[1,5.2,33.2]],"ltp":4.7,"tv":9.99,"id":14904499},{"batb":[[0,1.67,52.87],[1,1.61,59.64],[2,1.01,0.51]],"batl":[[1,1.8,47.52]],"ltp":1.58,"tv":62.69,"id":14904498},{"batb":[[1,9.2,33.52],[2,1.01,0.51]],"batl":[[0,12.5,28.8],[1,13,26.52]],"ltp":12.5,"tv":0.16,"id":20912772},{"batb":[[1,8,18.88],[2,1.01,0.51]],"batl":[[0,10.5,15.82],[1,12,31.71]],"ltp":0.0,"tv":0.0,"id":20912771}]}]}
{"op":"mcm","clk":"1003244914","pt":1580605072463,"mc":[{"id":"1.168179121","rc":[{"batb":[[0,4.2,40.36],[1,1.01,0.51],[2,1.01,0]],"batl":[[0,5.2,33.2],[1,5.2,0]],"ltp":4.7,"tv":9.99,"id":14904499},{"batb":[[0,1.61,59.64],[1,1.01,0.51],[2,1.01,0]],"batl":[[0,1.8,47.52],[1,1.8,0]],"ltp":1.58,"tv":62.69,"id":14904498},{"batb":[[0,9.2,33.52],[1,1.01,0.51],[2,1.01,0]],"batl":[[0,13,26.52],[1,13,0]],"ltp":12.5,"tv":0.16,"id":20912772},{"batb":[[0,8,18.88],[1,1.01,0.51],[2,1.01,0]],"batl":[[0,12,31.71],[1,12,0]],"ltp":0.0,"tv":0.0,"id":20912771}]}]}
{"op":"mcm","clk":"1003248391","pt":1580605135627,"mc":[{"id":"1.168179121","rc":[{"batb":[[0,4.5,34.86],[1,4.3,38],[2,4.2,40.36]],"batl":[[1,5.5,29.66]],"ltp":4.7,"tv":9.99,"id":14904499},{"batb":[[1,1.55,69.48],[2,1.01,0.51]],"batl":[[0,1.69,58.46],[1,1.75,51.85],[2,1.8,47.52]],"ltp":1.58,"tv":62.69,"id":14904498},{"batb":[[0,9.8,29.03],[1,9.4,31.87],[2,9.2,33.52]],"batl":[[1,13.5,24.23]],"ltp":12.5,"tv":0.16,"id":20912772},{"batb":[[0,9,35.01],[1,8.6,16.37],[2,8,18.88]],"batl":[[1,13.5,24.39]],"ltp":0.0,"tv":0.0,"id":20912771}]}]}
{"op":"mcm","clk":"1003248418","pt":1580605136140,"mc":[{"id":"1.168179121","rc":[{"batb":[[2,1.01,0.51]],"ltp":4.7,"tv":9.99,"id":14904499},{"batl":[[2,1.8,0]],"ltp":1.58,"tv":62.69,"id":14904498},{"batb":[[2,1.01,0.51]],"ltp":12.5,"tv":0.16,"id":20912772},{"batb":[[2,1.01,0.51]],"ltp":0.0,"tv":0.0,"id":20912771}]}]}
{"op":"mcm","clk":"1003249299","pt":1580605152383,"mc":[{"id":"1.168179121","rc":[{"batb":[[0,4.3,38],[1,1.01,0.51],[2,1.01,0]],"batl":[[0,5.5,29.66],[1,5.5,0]],"ltp":4.7,"tv":9.99,"id":14904499},{"batb":[[0,1.55,69.48],[1,1.01,0.51],[2,1.01,0]],"batl":[[0,1.75,51.85],[1,1.75,0]],"ltp":1.58,"tv":62.69,"id":14904498},{"batb":[[0,9.4,31.87],[1,1.01,0.51],[2,1.01,0]],"batl":[[0,13.5,24.23],[1,13.5,0]],"ltp":12.5,"tv":0.16,"id":20912772},{"batb":[[0,8.6,16.37],[1,1.01,0.51],[2,1.01,0]],"batl":[[0,13.5,24.39],[1,13.5,0]],"ltp":0.0,"tv":0.0,"id":20912771}]}]}
{"op":"mcm","clk":"1003249455","pt":1580605154858,"mc":[{"id":"1.168179121","rc":[{"batb":[[1,1.53,72.94],[2,1.01,0.51]],"batl":[[0,1.73,54.68],[1,1.75,51.85]],"ltp":1.58,"tv":62.69,"id":14904498},{"batl":[[1,14,22.27]],"ltp":12.5,"tv":0.16,"id":20912772},{"batl":[[1,14,21.79]],"ltp":0.0,"tv":0.0,"id":20912771}]}]}
{"op":"mcm","clk":"1003249503","pt":1580605155680,"mc":[{"id":"1.168179121","rc":[{"batb":[[0,1.53,72.94],[1,1.01,0.51],[2,1.01,0]],"batl":[[1,1.75,0]],"ltp":1.58,"tv":62.69,"id":14904498},{"batb":[[0,1.01,0.51],[1,1.01,0]],"batl":[[0,14,22.27],[1,14,0]],"ltp":12.5,"tv":0.16,"id":20912772},{"batb":[[0,1.01,0.51],[1,1.01,0]],"batl":[[0,14,21.79],[1,14,0]],"ltp":0.0,"tv":0.0,"id":20912771}]}]}
{"op":"mcm","clk":"1003250384","pt":1580605172507,"mc":[{"id":"1.168179121","rc":[{"batb":[[1,3.95,48.15],[2,1.01,0.51]],"batl":[[0,5,36.35],[1,5.2,32.65]],"ltp":4.7,"tv":9.99,"id":14904499},{"batb":[[0,1.65,55.55],[1,1.58,64.44],[2,1.01,0.51]],"batl":[[0,1.73,54.37],[1,1.89,40.91]],"ltp":1.58,"tv":62.69,"id":14904498},{"batb":[[0,9.8,29.27],[1,9.4,32.89],[2,1.01,0.51]],"batl":[[0,13,26.67],[1,13.5,24.47]],"ltp":12.5,"tv":0.16,"id":20912772},{"batb":[[0,9,14.71],[1,7.4,22.35],[2,1.01,0.51]],"batl":[[0,11,14.08],[1,13,26.59]],"ltp":0.0,"tv":0.0,"id":20912771}]}]}
{"op":"mcm","clk":"1003251507","pt":1580605193745,"mc":[{"id":"1.168179121","rc":[{"batb":[[0,3.95,48.15],[1,1.01,0.51],[2,1.01,0]],"batl":[[0,5.2,32.65],[1,5.2,0]],"ltp":4.7,"tv":9.99,"id":14904499},{"batb":[[0,1.58,63.89],[1,1.01,0.51],[2,1.01,0]],"batl":[[0,1.89,40.44],[1,1.89,0]],"ltp":1.58,"tv":62.69,"id":14904498},{"batb":[[0,9.4,32.89],[1,1.01,0.51],[2,1.01,0]],"batl":[[0,13.5,24.47],[1,13.5,0]],"ltp":12.5,"tv":0.16,"id":20912772},{"batb":[[0,7.4,22.35],[1,1.01,0.51],[2,1.01,0]],"batl":[[0,13,26.59],[1,13,0]],"ltp":0.0,"tv":0.0,"id":20912771}]}]}
{"op":"mcm","clk":"1003253780","pt":1580605228817,"mc":[{"id":"1.168179121","rc":[{"batb":[[0,4.5,34.46],[1,4.2,41.07],[2,3.95,48.15]],"batl":[[1,5.4,30.29]],"ltp":4.7,"tv":9.99,"id":14904499},{"batb":[[1,1.54,71.21],[2,1.01,0.51]],"batl":[[0,1.66,62.47],[1,1.78,49.65],[2,1.89,40.44]],"ltp":1.58,"tv":62.69,"id":14904498},{"batb":[[0,10,26.83],[1,9.6,30.76],[2,9.4,32.89]],"batl":[[1,14,23.21]],"ltp":12.5,"tv":0.16,"id":20912772},{"batb":[[0,9.8,29.66],[1,8.4,16.84],[2,7.4,22.35]],"batl":[[1,14,22.11]],"ltp":0.0,"tv":0.0,"id":20912771}]}]}
{"op":"mcm","clk":"1003253789","pt":1580605228917,"mc":[{"id":"1.168179121","rc":[{"batb":[[2,1.01,0.51]],"ltp":4.7,"tv":9.99,"id":14904499},{"batl":[[2,1.89,0]],"ltp":1.58,"tv":62.69,"id":14904498},{"batb":[[2,1.01,0.51]],"ltp":12.5,"tv":0.16,"id":20912772},{"batb":[[2,1.01,0.51]],"ltp":0.0,"tv":0.0,"id":20912771}]}]}
{"op":"mcm","clk":"1003254748","pt":1580605243442,"mc":[{"id":"1.168179121","rc":[{"batb":[[0,4.2,41.07],[1,1.01,0.51],[2,1.01,0]],"batl":[[0,5.4,30.29],[1,5.4,0]],"ltp":4.7,"tv":9.99,"id":14904499},{"batb":[[0,1.54,71.21],[1,1.01,0.51],[2,1.01,0]],"batl":[[0,1.78,49.65],[1,1.78,0]],"ltp":1.58,"tv":62.69,"id":14904498},{"batb":[[0,9.6,30.76],[1,1.01,0.51],[2,1.01,0]],"batl":[[0,14,23.21],[1,14,0]],"ltp":12.5,"tv":0.16,"id":20912772},{"batb":[[0,8.4,16.84],[1,1.01,0.51],[2,1.01,0]],"batl":[[0,14,22.11],[1,14,0]],"ltp":0.0,"tv":0.0,"id":20912771}]}]}
{"op":"mcm","clk":"1003256291","pt":1580605264777,"mc":[{"id":"1.168179121","rc":[{"batb":[[0,4.7,31.63],[1,4.5,35.49],[2,1.01,0.51]],"batl":[[1,5.6,27.93]],"ltp":4.7,"tv":9.99,"id":14904499},{"batb":[[1,1.5,78.05],[2,1.01,0.51]],"batl":[[0,1.61,69.55],[1,1.68,59.56]],"ltp":1.58,"tv":62.69,"id":14904498},{"batb":[[0,10,28.17]],"batl":[[0,14,22.19]],"ltp":12.5,"tv":0.16,"id":20912772},{"batb":[[0,10.5,24.08],[1,9.4,32.42],[2,1.01,0.51]],"batl":[[1,15.5,18.65]],"ltp":0.0,"tv":0.0,"id":20912771}]}]}
{"op":"mcm","clk":"1003257656","pt":1580605285894,"mc":[{"id":"1.168179121","rc":[{"batb":[[0,4.5,35.49],[1,1.01,0.51],[2,1.01,0]],"batl":[[0,5.6,27.93],[1,5.6,0]],"ltp":4.7,"tv":9.99,"id":14904499},{"batb":[[0,1.5,78.05],[1,1.01,0.51],[2,1.01,0]],"batl":[[0,1.68,59.56],[1,1.68,0]],"ltp":1.58,"tv":62.69,"id":14904498},{"batb":[[0,9.4,32.42],[1,1.01,0.51],[2,1.01,0]],"batl":[[0,15.5,18.65],[1,15.5,0]],"ltp":0.0,"tv":0.0,"id":20912771}]}]}
{"op":"mcm","clk":"1003257812","pt":1580605288622,"mc":[{"id":"1.168179121","rc":[{"batl":[[1,1.69,59.09]],"ltp":1.58,"tv":62.69,"id":14904498}]}]}
{"op":"mcm","clk":"1003257837","pt":1580605288922,"mc":[{"id":"1.168179121","rc":[{"batb":[[0,1.5,77.5]],"batl":[[0,1.69,59.09],[1,1.69,0]],"ltp":1.58,"tv":62.69,"id":14904498}]}]}
{"op":"mcm","clk":"1003258868","pt":1580605303794,"mc":[{"id":"1.168179121","rc":[{"batb":[[0,4.9,29.35],[1,4.7,32.1],[2,1.01,0.51]],"batl":[[1,5.7,26.91]],"ltp":4.7,"tv":9.99,"id":14904499},{"batb":[[1,1.48,82.46],[2,1.01,0.51]],"batl":[[0,1.58,75.53],[1,1.63,67.19]],"ltp":1.58,"tv":62.69,"id":14904498},{"batb":[[0,10.5,24.23],[1,10,26.59],[2,1.01,0.51]],"batl":[[1,14.5,20.69]],"ltp":12.5,"tv":0.16,"id":20912772},{"batb":[[0,11.5,20.46],[1,10.5,25.73],[2,1.01,0.51]],"batl":[[1,16,17.07]],"ltp":0.0,"tv":0.0,"id":20912771}]}]}
{"op":"mcm","clk":"1003259862","pt":1580605316726,"mc":[{"id":"1.168179121","rc":[{"batb":[[0,4.7,32.1],[1,1.01,0.51],[2,1.01,0]],"batl":[[0,5.7,26.91],[1,5.7,0]],"ltp":4.7,"tv":9.99,"id":14904499},{"batb":[[0,1.48,82.46],[1,1.01,0.51],[2,1.01,0]],"batl":[[0,1.63,67.19],[1,1.63,0]],"ltp":1.58,"tv":62.69,"id":14904498},{"batb":[[0,10,26.59],[1,1.01,0.51],[2,1.01,0]],"batl":[[0,14.5,20.69],[1,14.5,0]],"ltp":12.5,"tv":0.16,"id":20912772},{"batb":[[0,10.5,25.73],[1,1.01,0.51],[2,1.01,0]],"batl":[[0,16,17.07],[1,16,0]],"ltp":0.0,"tv":0.0,"id":20912771}]}]}
{"op":"mcm","clk":"1003260449","pt":1580605323756,"mc":[{"id":"1.168179121","rc":[{"batb":[[0,5,28.01],[1,4.7,32.1],[2,4.6,33.6]],"batl":[[1,6.4,21.79]],"ltp":4.7,"tv":9.99,"id":14904499},{"batb":[[1,1.4,104.1],[2,1.01,0.51]],"batl":[[0,1.55,80.33],[1,1.63,67.19]],"ltp":1.58,"tv":62.69,"id":14904498},{"batb":[[0,11,22.42],[1,10.5,25.1],[2,10,26.59]],"batl":[[1,15.5,18.1]],"ltp":12.5,"tv":0.16,"id":20912772},{"batb":[[0,12,18.41],[1,10.5,25.73],[2,1.01,0.51]],"batl":[[1,21,10.31]],"ltp":0.0,"tv":0.0,"id":20912771}]}]}
{"op":"mcm","clk":"1003260480","pt":1580605324165,"mc":[{"id":"1.168179121","rc":[{"batb":[[1,4.6,33.6],[2,1.01,0.51]],"ltp":4.7,"tv":9.99,"id":14904499},{"batl":[[1,1.63,66.88]],"ltp":1.58,"tv":62.69,"id":14904498},{"batb":[[2,1.01,0.51]],"ltp":12.5,"tv":0.16,"id":20912772},{"batb":[[1,10.5,25.02]],"ltp":0.0,"tv":0.0,"id":20912771}]}]}
{"op":"mcm","clk":"1003261846","pt":1580605343702,"mc":[{"id":"1.168179121","rc":[{"batb":[[0,1.48,82.3],[1,1.4,103.86]],"batl":[[0,1.55,80.18]],"ltp":1.58,"tv":62.69,"id":14904498}]}]}
{"op":"mcm","clk":"1003262572","pt":1580605353816,"mc":[{"id":"1.168179121","rc":[{"batb":[[0,1.48,81.99],[1,1.4,103.55]],"batl":[[0,1.55,79.94],[1,1.63,66.56]],"ltp":1.58,"tv":62.69,"id":14904498}]}]}
{"op":"mcm","clk":"1003265370","pt":1580605396878,"mc":[{"id":"1.168179121","rc":[{"batb":[[0,4.6,33.6],[1,1.01,0.51],[2,1.01,0]],"batl":[[0,6.4,21.79],[1,6.4,0]],"ltp":4.7,"tv":9.99,"id":14904499},{"batb":[[0,1.4,103.55],[1,1.01,0.51],[2,1.01,0]],"batl":[[0,1.63,66.56],[1,1.63,0]],"ltp":1.58,"tv":62.69,"id":14904498},{"batb":[[0,10.5,25.1],[1,1.01,0.51],[2,1.01,0]],"batl":[[0,15.5,18.1],[1,15.5,0]],"ltp":12.5,"tv":0.16,"id":20912772},{"batb":[[0,10.5,25.02],[1,1.01,0.51],[2,1.01,0]],"batl":[[0,21,10.31],[1,21,0]],"ltp":0.0,"tv":0.0,"id":20912771}]}]}
{"op":"mcm","clk":"1003266197","pt":1580605408864,"mc":[{"id":"1.168179121","rc":[{"batb":[[1,4.4,37.92],[2,1.01,0.51]],"batl":[[0,5.3,32.1],[1,5.8,26.2]],"ltp":4.7,"tv":9.99,"id":14904499},{"batb":[[0,1.55,68.14],[1,1.47,84.74],[2,1.01,0.51]],"batl":[[1,1.71,56.89]],"ltp":1.58,"tv":62.69,"id":14904498},{"batb":[[1,10,28.17],[2,1.01,0.51]],"batl":[[0,13.5,23.29],[1,14.5,20.77]],"ltp":12.5,"tv":0.16,"id":20912772},{"batb":[[1,9.2,33.75],[2,1.01,0.51]],"batl":[[0,14,23.21],[1,16.5,15.89]],"ltp":0.0,"tv":0.0,"id":20912771}]}]}
{"op":"mcm","clk":"1003266906","pt":1580605418687,"mc":[{"id":"1.168179121","rc":[{"batb":[[0,4.4,37.92],[1,1.01,0.51],[2,1.01,0]],"batl":[[0,5.8,26.2],[1,5.8,0]],"ltp":4.7,"tv":9.99,"id":14904499},{"batb":[[0,1.47,84.74],[1,1.01,0.51],[2,1.01,0]],"batl":[[0,1.71,56.89],[1,1.71,0]],"ltp":1.58,"tv":62.69,"id":14904498},{"batb":[[0,10,28.17],[1,1.01,0.51],[2,1.01,0]],"batl":[[0,14.5,20.77],[1,14.5,0]],"ltp":12.5,"tv":0.16,"id":20912772},{"batb":[[0,9.2,33.75],[1,1.01,0.51],[2,1.01,0]],"batl":[[0,16.5,15.89],[1,16.5,0]],"ltp":0.0,"tv":0.0,"id":20912771}]}]}
{"op":"mcm","clk":"1003268921","pt":1580605448740,"mc":[{"id":"1.168179121","rc":[{"batb":[[1,4.2,41.47],[2,1.01,0.51]],"batl":[[0,5,36.12],[1,5.3,31.79],[2,5.8,26.2]],"ltp":4.7,"tv":9.99,"id":14904499},{"batb":[[0,1.62,58.07],[1,1.55,68.77],[2,1.47,84.74]],"batl":[[1,1.76,50.67]],"ltp":1.58,"tv":62.69,"id":14904498},{"batb":[[1,9.8,30.06],[2,1.01,0.51]],"batl":[[0,13,25.73],[1,14,22.82],[2,14.5,20.77]],"ltp":12.5,"tv":0.16,"id":20912772},{"batb":[[1,8.6,15.74],[2,1.01,0.51]],"batl":[[0,12,30.53],[1,14,23.21],[2,16.5,15.89]],"ltp":0.0,"tv":0.0,"id":20912771}]}]}
{"op":"mcm","clk":"1003268937","pt":1580605448941,"mc":[{"id":"1.168179121","rc":[{"batl":[[2,5.8,0]],"ltp":4.7,"tv":9.99,"id":14904499},{"batb":[[2,1.01,0.51]],"ltp":1.58,"tv":62.69,"id":14904498},{"batl":[[2,14.5,0]],"ltp":12.5,"tv":0.16,"id":20912772},{"batl":[[2,16.5,0]],"ltp":0.0,"tv":0.0,"id":20912771}]}]}
{"op":"mcm","clk":"1003270450","pt":1580605469552,"mc":[{"id":"1.168179121","rc":[{"batb":[[0,4.2,41.47],[1,1.01,0.51],[2,1.01,0]],"batl":[[0,5.3,31.79],[1,5.3,0]],"ltp":4.7,"tv":9.99,"id":14904499},{"batb":[[0,1.55,68.77],[1,1.01,0.51],[2,1.01,0]],"batl":[[0,1.76,50.67],[1,1.76,0]],"ltp":1.58,"tv":62.69,"id":14904498},{"batb":[[0,9.8,30.06],[1,1.01,0.51],[2,1.01,0]],"batl":[[0,14,22.82],[1,14,0]],"ltp":12.5,"tv":0.16,"id":20912772},{"batb":[[0,8.6,15.74],[1,1.01,0.51],[2,1.01,0]],"batl":[[0,14,23.21],[1,14,0]],"ltp":0.0,"tv":0.0,"id":20912771}]}]}
{"op":"mcm","clk":"1003271620","pt":1580605484393,"mc":[{"id":"1.168179121","rc":[{"batb":[[1,4.1,44.53],[2,1.01,0.51]],"batl":[[0,4.8,39.34],[1,5,36.51]],"ltp":4.7,"tv":9.99,"id":14904499},{"batb":[[0,1.68,51.69],[1,1.62,58.46],[2,1.01,0.51]],"batl":[[1,1.82,45.95]],"ltp":1.58,"tv":62.69,"id":14904498},{"batb":[[1,9.4,32.57],[2,1.01,0.51]],"batl":[[0,12.5,27.38],[1,13,25.1]],"ltp":12.5,"tv":0.16,"id":20912772},{"batb":[[1,8.2,17.94],[2,1.01,0.51]],"batl":[[0,11,15.03],[1,12,29.74]],"ltp":0.0,"tv":0.0,"id":20912771}]}]}
{"op":"mcm","clk":"1003272439","pt":1580605495791,"mc":[{"id":"1.168179121","rc":[{"batb":[[0,4.1,44.53],[1,1.01,0.51],[2,1.01,0]],"batl":[[0,5,36.51],[1,5,0]],"ltp":4.7,"tv":9.99,"id":14904499},{"batb":[[0,1.62,58.46],[1,1.01,0.51],[2,1.01,0]],"batl":[[0,1.82,45.95],[1,1.82,0]],"ltp":1.58,"tv":62.69,"id":14904498},{"batb":[[0,9.4,32.57],[1,1.01,0.51],[2,1.01,0]],"batl":[[0,13,25.1],[1,13,0]],"ltp":12.5,"tv":0.16,"id":20912772},{"batb":[[0,8.2,17.94],[1,1.01,0.51],[2,1.01,0]],"batl":[[0,12,29.74],[1,12,0]],"ltp":0.0,"tv":0.0,"id":20912771}]}]}
{"op":"mcm","clk":"1003273657","pt":1580605511703,"mc":[{"id":"1.168179121","rc":[{"batb":[[0,4.3,38.32],[1,4.1,42.49],[2,1.01,0.51]],"batl":[[1,5.3,31.94]],"ltp":4.7,"tv":9.99,"id":14904499},{"batb":[[1,1.55,68.61],[2,1.01,0.51]],"batl":[[0,1.7,57.2],[1,1.77,50.36]],"ltp":1.58,"tv":62.69,"id":14904498},{"batb":[[0,10,27.54],[1,9.8,29.66],[2,1.01,0.51]],"batl":[[0,14,22.98]],"ltp":12.5,"tv":0.16,"id":20912772},{"batb":[[0,9.4,32.89],[1,8.8,15.5],[2,1.01,0.51]],"batl":[[1,14,23.05]],"ltp":0.0,"tv":0.0,"id":20912771}]}]}
{"op":"mcm","clk":"1003274686","pt":1580605525620,"mc":[{"id":"1.168179121","rc":[{"batb":[[0,4.1,42.49],[1,1.01,0.51],[2,1.01,0]],"batl":[[0,5.3,31.94],[1,5.3,0]],"ltp":4.7,"tv":9.99,"id":14904499},{"batb":[[0,1.55,68.61],[1,1.01,0.51],[2,1.01,0]],"batl":[[0,1.77,50.36],[1,1.77,0]],"ltp":1.58,"tv":62.69,"id":14904498},{"batb":[[0,9.8,29.66],[1,1.01,0.51],[2,1.01,0]],"ltp":12.5,"tv":0.16,"id":20912772},{"batb":[[0,8.8,15.5],[1,1.01,0.51],[2,1.01,0]],"batl":[[0,14,23.05],[1,14,0]],"ltp":0.0,"tv":0.0,"id":20912771}]}]}
{"op":"mcm","clk":"1003275468","pt":1580605536645,"mc":[{"id":"1.168179121","rc":[{"batb":[[0,4.6,33.44],[1,4.3,39.89],[2,4.1,42.49]],"batl":[[1,5.9,24.94]],"ltp":4.7,"tv":9.99,"id":14904499},{"batb":[[1,1.45,90.64],[2,1.01,0.51]],"batl":[[0,1.63,67.04],[1,1.72,55.16],[2,1.77,50.36]],"ltp":1.58,"tv":62.69,"id":14904498},{"batb":[[0,10.5,25.1],[1,10,27.85],[2,9.8,29.66]],"batl":[[1,15,19.59]],"ltp":12.5,"tv":0.16,"id":20912772},{"batb":[[0,10.5,25.18],[1,9.2,34.46],[2,8.8,15.5]],"batl":[[1,18,13.69]],"ltp":0.0,"tv":0.0,"id":20912771}]}]}
{"op":"mcm","clk":"1003275525","pt":1580605537422,"mc":[{"id":"1.168179121","rc":[{"batb":[[2,1.01,0.51]],"ltp":4.7,"tv":9.99,"id":14904499},{"batl":[[2,1.77,0]],"ltp":1.58,"tv":62.69,"id":14904498},{"batb":[[2,1.01,0.51]],"ltp":12.5,"tv":0.16,"id":20912772},{"batb":[[2,1.01,0.51]],"ltp":0.0,"tv":0.0,"id":20912771}]}]}
{"op":"mcm","clk":"1003276939","pt":1580605557580,"mc":[{"id":"1.168179121","rc":[{"batb":[[0,4.3,39.89],[1,1.01,0.51],[2,1.01,0]],"batl":[[0,5.9,24.94],[1,5.9,0]],"ltp":4.7,"tv":9.99,"id":14904499},{"batb":[[0,1.45,90.64],[1,1.01,0.51],[2,1.01,0]],"batl":[[0,1.72,55.16],[1,1.72,0]],"ltp":1.58,"tv":62.69,"id":14904498},{"batb":[[0,10,27.85],[1,1.01,0.51],[2,1.01,0]],"batl":[[0,15,19.59],[1,15,0]],"ltp":12.5,"tv":0.16,"id":20912772},{"batb":[[0,9.2,34.46],[1,1.01,0.51],[2,1.01,0]],"batl":[[0,18,13.69],[1,18,0]],"ltp":0.0,"tv":0.0,"id":20912771}]}]}
{"op":"mcm","clk":"1003279390","pt":1580605590818,"mc":[{"id":"1.168179121","rc":[{"batb":[[1,3.85,51.85],[2,1.01,0.51]],"batl":[[0,4.9,37.92],[1,5.2,33.2],[2,5.9,24.94]],"ltp":4.7,"tv":9.99,"id":14904499},{"batb":[[0,1.64,56.26],[1,1.57,65.7],[2,1.45,90.64]],"batl":[[1,1.91,39.5]],"ltp":1.58,"tv":62.69,"id":14904498},{"batb":[[1,9.4,32.65],[2,1.01,0.51]],"batl":[[0,13,25.41],[1,13.5,23.6],[2,15,19.59]],"ltp":12.5,"tv":0.16,"id":20912772},{"batb":[[1,7.4,21.79],[2,1.01,0.51]],"batl":[[0,12,31.16],[1,13.5,24.63],[2,18,13.69]],"ltp":0.0,"tv":0.0,"id":20912771}]}]}
{"op":"mcm","clk":"1003279440","pt":1580605591385,"mc":[{"id":"1.168179121","rc":[{"batl":[[2,5.9,0]],"ltp":4.7,"tv":9.99,"id":14904499},{"batb":[[2,1.01,0.51]],"ltp":1.58,"tv":62.69,"id":14904498},{"batl":[[2,15,0]],"ltp":12.5,"tv":0.16,"id":20912772},{"batl":[[2,18,0]],"ltp":0.0,"tv":0.0,"id":20912771}]}]}
{"op":"mcm","clk":"1003280442","pt":1580605604861,"mc":[{"id":"1.168179121","rc":[{"batb":[[0,3.85,51.69],[1,1.01,0.51],[2,1.01,0]],"batl":[[0,5.2,33.2],[1,5.2,0]],"ltp":4.7,"tv":9.99,"id":14904499},{"batb":[[0,1.57,65.46],[1,1.01,0.51],[2,1.01,0]],"batl":[[0,1.91,39.34],[1,1.91,0]],"ltp":1.58,"tv":62.69,"id":14904498},{"batb":[[0,9.4,32.65],[1,1.01,0.51],[2,1.01,0]],"batl":[[0,13.5,23.6],[1,13.5,0]],"ltp":12.5,"tv":0.16,"id":20912772},{"batb":[[0,7.4,21.79],[1,1.01,0.51],[2,1.01,0]],"batl":[[0,13.5,24.63],[1,13.5,0]],"ltp":0.0,"tv":0.0,"id":20912771}]}]}
{"op":"mcm","clk":"1003282042","pt":1580605627866,"mc":[{"id":"1.168179121","rc":[{"batb":[[0,4.5,34.7],[1,4.1,43.12],[2,3.85,51.69]],"batl":[[1,5.4,29.98]],"ltp":4.7,"tv":9.99,"id":14904499},{"batb":[[1,1.52,74.43],[2,1.01,0.51]],"batl":[[0,1.65,63.97],[1,1.78,49.41],[2,1.91,39.34]],"ltp":1.58,"tv":62.69,"id":14904498},{"batb":[[0,10,26.12],[1,9.8,29.9],[2,9.4,32.65]],"batl":[[1,14,21.72]],"ltp":12.5,"tv":0.16,"id":20912772},{"batb":[[0,10,27.22],[1,8.6,15.97],[2,7.4,21.79]],"batl":[[1,15,19.91]],"ltp":0.0,"tv":0.0,"id":20912771}]}]}
{"op":"mcm","clk":"1003282072","pt":1580605628274,"mc":[{"id":"1.168179121","rc":[{"batb":[[2,1.01,0.51]],"ltp":4.7,"tv":9.99,"id":14904499},{"batl":[[2,1.91,0]],"ltp":1.58,"tv":62.69,"id":14904498},{"batb":[[2,1.01,0.51]],"ltp":12.5,"tv":0.16,"id":20912772},{"batb":[[2,1.01,0.51]],"ltp":0.0,"tv":0.0,"id":20912771}]}]}
{"op":"mcm","clk":"1003283545","pt":1580605650676,"mc":[{"id":"1.168179121","rc":[{"batb":[[0,4.1,43.12],[1,1.01,0.51],[2,1.01,0]],"batl":[[0,5.4,29.98],[1,5.4,0]],"ltp":4.7,"tv":9.99,"id":14904499},{"batb":[[0,1.52,74.43],[1,1.01,0.51],[2,1.01,0]],"batl":[[0,1.78,49.41],[1,1.78,0]],"ltp":1.58,"tv":62.69,"id":14904498},{"batb":[[0,9.8,29.9],[1,1.01,0.51],[2,1.01,0]],"batl":[[0,14,21.72],[1,14,0]],"ltp":12.5,"tv":0.16,"id":20912772},{"batb":[[0,8.6,15.97],[1,1.01,0.51],[2,1.01,0]],"batl":[[0,15,19.91],[1,15,0]],"ltp":0.0,"tv":0.0,"id":20912771}]}]}
{"op":"mcm","clk":"1003284877","pt":1580605669797,"mc":[{"id":"1.168179121","rc":[{"batb":[[0,4.7,31.39],[1,4.4,36.19],[2,1.01,0.51]],"batl":[[1,5.6,28.4]],"ltp":4.7,"tv":9.99,"id":14904499},{"batb":[[1,1.49,80.49],[2,1.01,0.51]],"batl":[[0,1.59,72.62],[1,1.68,60.19]],"ltp":1.58,"tv":62.69,"id":14904498},{"batb":[[0,10.5,23.6],[1,10,27.54],[2,1.01,0.51]],"batl":[[1,14.5,20.93]],"ltp":12.5,"tv":0.16,"id":20912772},{"batb":[[0,11,21.56],[1,9.6,30.37],[2,1.01,0.51]],"batl":[[1,16.5,16.6]],"ltp":0.0,"tv":0.0,"id":20912771}]}]}
{"op":"mcm","clk":"1003286228","pt":1580605688759,"mc":[{"id":"1.168179121","rc":[{"batb":[[0,4.4,36.19],[1,1.01,0.51],[2,1.01,0]],"batl":[[0,5.6,28.4],[1,5.6,0]],"ltp":4.7,"tv":9.99,"id":14904499},{"batb":[[0,1.49,80.49],[1,1.01,0.51],[2,1.01,0]],"batl":[[0,1.68,60.19],[1,1.68,0]],"ltp":1.58,"tv":62.69,"id":14904498},{"batb":[[0,10,27.54],[1,1.01,0.51],[2,1.01,0]],"batl":[[0,14.5,20.93],[1,14.5,0]],"ltp":12.5,"tv":0.16,"id":20912772},{"batb":[[0,9.6,30.37],[1,1.01,0.51],[2,1.01,0]],"batl":[[0,16.5,16.6],[1,16.5,0]],"ltp":0.0,"tv":0.0,"id":20912771}]}]}
{"op":"mcm","clk":"1003287577","pt":1580605710791,"mc":[{"id":"1.168179121","rc":[{"batb":[[0,4.8,29.58],[1,4.7,32.1],[2,1.01,0.51]],"batl":[[1,5.7,26.99]],"ltp":4.7,"tv":9.99,"id":14904499},{"batb":[[1,1.47,85.29],[2,1.01,0.51]],"batl":[[0,1.56,78.45],[1,1.61,69.71]],"ltp":1.58,"tv":62.69,"id":14904498},{"batb":[[0,10.5,25.49]],"batl":[[1,15,19.67]],"ltp":12.5,"tv":0.16,"id":20912772},{"batb":[[0,12,17.86],[1,11,22.82],[2,1.01,0.51]],"batl":[[1,17,15.19]],"ltp":0.0,"tv":0.0,"id":20912771}]}]}
{"op":"mcm","clk":"1003288400","pt":1580605722890,"mc":[{"id":"1.168179121","rc":[{"batb":[[0,4.7,32.1],[1,1.01,0.51],[2,1.01,0]],"batl":[[0,5.7,26.99],[1,5.7,0]],"ltp":4.7,"tv":9.99,"id":14904499},{"batb":[[0,1.47,85.29],[1,1.01,0.51],[2,1.01,0]],"batl":[[0,1.61,69.71],[1,1.61,0]],"ltp":1.58,"tv":62.69,"id":14904498},{"batl":[[0,15,19.67],[1,15,0]],"ltp":12.5,"tv":0.16,"id":20912772},{"batb":[[0,11,22.82],[1,1.01,0.51],[2,1.01,0]],"batl":[[0,17,15.19],[1,17,0]],"ltp":0.0,"tv":0.0,"id":20912771}]}]}
{"op":"mcm","clk":"1003289193","pt":1580605734731,"mc":[{"id":"1.168179121","rc":[{"batb":[[0,4.9,28.17],[1,4.6,33.75],[2,1.01,0.51]],"batl":[[1,6.4,41.54]],"ltp":4.7,"tv":9.99,"id":14904499},{"batb":[[1,1.38,111.65],[2,1.01,0.51]],"batl":[[0,1.54,83.01],[1,1.62,68.69]],"ltp":1.58,"tv":62.69,"id":14904498},{"batb":[[0,11,21.32],[1,10.5,24.16],[2,1.01,0.51]],"batl":[[1,16.5,16.6]],"ltp":12.5,"tv":0.16,"id":20912772},{"batb":[[0,12.5,16.29],[1,11,22.82],[2,1.01,0.51]],"batl":[[1,23,8.73]],"ltp":0.0,"tv":0.0,"id":20912771}]}]}
{"op":"mcm","clk":"1003289532","pt":1580605739514,"mc":[{"id":"1.168179121","rc":[{"batb":[[0,1.47,85.13],[1,1.38,111.49]],"batl":[[1,1.62,68.53]],"ltp":1.58,"tv":62.69,"id":14904498}]}]}
{"op":"mcm","clk":"1003290095","pt":1580605747753,"mc":[{"id":"1.168179121","rc":[{"batb":[[0,1.47,84.82],[1,1.38,111.1]],"batl":[[0,1.54,82.62],[1,1.62,68.3]],"ltp":1.58,"tv":62.69,"id":14904498}]}]}
{"op":"mcm","clk":"1003294585","pt":1580605810030,"mc":[{"id":"1.168179121","rc":[{"batb":[[0,4.6,33.75],[1,1.01,0.51],[2,1.01,0]],"batl":[[0,6.4,41.54],[1,6.4,0]],"ltp":4.7,"tv":9.99,"id":14904499},{"batb":[[0,1.38,111.1],[1,1.01,0.51],[2,1.01,0]],"batl":[[0,1.62,68.3],[1,1.62,0]],"ltp":1.58,"tv":62.69,"id":14904498},{"batb":[[0,10.5,24.16],[1,1.01,0.51],[2,1.01,0]],"batl":[[0,16.5,16.6],[1,16.5,0]],"ltp":12.5,"tv":0.16,"id":20912772},{"batb":[[0,11,22.82],[1,1.01,0.51],[2,1.01,0]],"batl":[[0,23,8.73],[1,23,0]],"ltp":0.0,"tv":0.0,"id":20912771}]}]}
{"op":"mcm","clk":"1003295820","pt":1580605826849,"mc":[{"id":"1.168179121","rc":[{"batb":[[1,4.3,39.34],[2,1.01,0.51]],"batl":[[0,5.2,32.34],[1,5.8,25.97],[2,6.4,41.54]],"ltp":4.7,"tv":9.99,"id":14904499},{"batb":[[0,1.54,69.95],[1,1.45,88.99],[2,1.38,111.1]],"batl":[[1,1.7,57.44]],"ltp":1.58,"tv":62.69,"id":14904498},{"batb":[[1,10,27.3],[2,1.01,0.51]],"batl":[[0,14,22.35],[1,15,19.2],[2,16.5,16.6]],"ltp":12.5,"tv":0.16,"id":20912772},{"batb":[[1,9.6,30.84],[2,1.01,0.51]],"batl":[[0,14.5,21.32],[1,18,14.01],[2,23,8.73]],"ltp":0.0,"tv":0.0,"id":20912771}]}]}
{"op":"mcm","clk":"1003295844","pt":1580605827108,"mc":[{"id":"1.168179121","rc":[{"batl":[[2,6.4,0]],"ltp":4.7,"tv":9.99,"id":14904499},{"batb":[[2,1.01,0.51]],"ltp":1.58,"tv":62.69,"id":14904498},{"batl":[[2,16.5,0]],"ltp":12.5,"tv":0.16,"id":20912772},{"batl":[[2,23,0]],"ltp":0.0,"tv":0.0,"id":20912771}]}]}
{"op":"mcm","clk":"1003296988","pt":1580605844654,"mc":[{"id":"1.168179121","rc":[{"batb":[[0,4.3,39.34],[1,1.01,0.51],[2,1.01,0]],"batl":[[0,5.8,25.97],[1,5.8,0]],"ltp":4.7,"tv":9.99,"id":14904499},{"batb":[[0,1.45,88.99],[1,1.01,0.51],[2,1.01,0]],"batl":[[0,1.7,57.44],[1,1.7,0]],"ltp":1.58,"tv":62.69,"id":14904498},{"batb":[[0,10,27.3],[1,1.01,0.51],[2,1.01,0]],"batl":[[0,15,19.2],[1,15,0]],"ltp":12.5,"tv":0.16,"id":20912772},{"batb":[[0,9.6,30.84],[1,1.01,0.51],[2,1.01,0]],"batl":[[0,18,14.01],[1,18,0]],"ltp":0.0,"tv":0.0,"id":20912771}]}]}
{"op":"mcm","clk":"1003299641","pt":1580605882421,"mc":[{"id":"1.168179121","rc":[{"batb":[[0,5,27.07],[1,4.6,33.52],[2,1.01,0.51]],"batl":[[1,6.8,37.61]],"ltp":4.7,"tv":9.99,"id":14904499},{"batb":[[1,1.35,121.96],[2,1.01,0.51]],"batl":[[0,1.52,86.55],[1,1.61,69.63]],"ltp":1.58,"tv":62.69,"id":14904498},{"batb":[[0,11.5,20.77],[1,10.5,23.6],[2,1.01,0.51]],"batl":[[1,17,15.74]],"ltp":12.5,"tv":0.16,"id":20912772},{"batb":[[0,13,14.95],[1,11,22.42],[2,1.01,0.51]],"batl":[[1,27,13.38]],"ltp":0.0,"tv":0.0,"id":20912771}]}]}
{"op":"mcm","clk":"1003300781","pt":1580605897564,"mc":[{"id":"1.168179121","rc":[{"batb":[[0,4.6,33.52],[1,1.01,0.51],[2,1.01,0]],"batl":[[0,6.8,37.61],[1,6.8,0]],"ltp":4.7,"tv":9.99,"id":14904499},{"batb":[[0,1.35,121.96],[1,1.01,0.51],[2,1.01,0]],"batl":[[0,1.61,69.63],[1,1.61,0]],"ltp":1.58,"tv":62.69,"id":14904498},{"batb":[[0,10.5,23.6],[1,1.01,0.51],[2,1.01,0]],"batl":[[0,17,15.74],[1,17,0]],"ltp":12.5,"tv":0.16,"id":20912772},{"batb":[[0,11,22.42],[1,1.01,0.51],[2,1.01,0]],"batl":[[0,27,13.38],[1,27,0]],"ltp":0.0,"tv":0.0,"id":20912771}]}]}
{"op":"mcm","clk":"1003302171","pt":1580605919577,"mc":[{"id":"1.168179121","rc":[{"batb":[[0,5.7,40.36],[1,5.1,26.28],[2,1.01,0.51]],"batl":[[1,8.4,24.63]],"ltp":4.7,"tv":9.99,"id":14904499},{"batb":[[1,1.25,179.79],[2,1.01,0.51]],"batl":[[0,1.41,117.94],[1,1.51,89.46]],"ltp":1.58,"tv":62.69,"id":14904498},{"batb":[[0,12.5,16.92],[1,11.5,20.85],[2,1.01,0.51]],"batl":[[1,19,12.59]],"ltp":12.5,"tv":0.16,"id":20912772},{"batb":[[0,18,14.71],[1,14,13.45],[2,1.01,0.51]],"ltp":0.0,"tv":0.0,"id":20912771}]}]}
{"op":"mcm","clk":"1003304008","pt":1580605946823,"mc":[{"id":"1.168179121","rc":[{"batb":[[0,5.1,26.28],[1,1.01,0.51],[2,1.01,0]],"batl":[[0,8.4,24.63],[1,8.4,0]],"ltp":4.7,"tv":9.99,"id":14904499},{"batb":[[0,1.25,179.79],[1,1.01,0.51],[2,1.01,0]],"batl":[[0,1.51,89.46],[1,1.51,0]],"ltp":1.58,"tv":62.69,"id":14904498},{"batb":[[0,11.5,20.85],[1,1.01,0.51],[2,1.01,0]],"batl":[[0,19,12.59],[1,19,0]],"ltp":12.5,"tv":0.16,"id":20912772},{"batb":[[0,14,13.45],[1,1.01,0.51],[2,1.01,0]],"ltp":0.0,"tv":0.0,"id":20912771}]}]}
{"op":"mcm","clk":"1003304230","pt":1580605949818,"mc":[{"id":"1.168179121","rc":[{"batl":[[0,8.2,25.1]],"ltp":4.7,"tv":9.99,"id":14904499},{"batb":[[0,1.26,175.62]],"batl":[[0,1.52,87.65]],"ltp":1.58,"tv":62.69,"id":14904498},{"batb":[[0,11,21.56]],"batl":[[0,18.5,13.14]],"ltp":12.5,"tv":0.16,"id":20912772},{"batb":[[0,13.5,14.16]],"ltp":0.0,"tv":0.0,"id":20912771}]}]}
{"op":"mcm","clk":"1003304524","pt":1580605953737,"mc":[{"id":"1.168179121","rc":[{"batb":[[1,4.5,34.93],[2,1.01,0.51]],"batl":[[0,5.8,25.41],[1,7.2,33.05],[2,8.2,25.1]],"ltp":4.7,"tv":9.99,"id":14904499},{"batb":[[0,1.45,90.09],[1,1.32,136.28],[2,1.26,175.62]],"batl":[[1,1.63,66.09]],"ltp":1.58,"tv":62.69,"id":14904498},{"batb":[[1,10.5,24.86],[2,1.01,0.51]],"batl":[[0,15,19.91],[1,17,15.34],[2,18.5,13.14]],"ltp":12.5,"tv":0.16,"id":20912772},{"batb":[[1,10.5,24.55],[2,1.01,0.51]],"batl":[[0,18.5,13.22]],"ltp":0.0,"tv":0.0,"id":20912771}]}]}
{"op":"mcm","clk":"1003304548","pt":1580605954044,"mc":[{"id":"1.168179121","rc":[{"batl":[[2,8.2,0]],"ltp":4.7,"tv":9.99,"id":14904499},{"batb":[[2,1.01,0.51]],"ltp":1.58,"tv":62.69,"id":14904498},{"batl":[[2,18.5,0]],"ltp":12.5,"tv":0.16,"id":20912772}]}]}
{"op":"mcm","clk":"1003305663","pt":1580605971449,"mc":[{"id":"1.168179121","rc":[{"batb":[[0,4.5,34.93],[1,1.01,0.51],[2,1.01,0]],"batl":[[0,7.2,33.05],[1,7.2,0]],"ltp":4.7,"tv":9.99,"id":14904499},{"batb":[[0,1.32,136.28],[1,1.01,0.51],[2,1.01,0]],"batl":[[0,1.63,66.09],[1,1.63,0]],"ltp":1.58,"tv":62.69,"id":14904498},{"batb":[[0,10.5,24.86],[1,1.01,0.51],[2,1.01,0]],"batl":[[0,17,15.34],[1,17,0]],"ltp":12.5,"tv":0.16,"id":20912772},{"batb":[[0,10.5,24.55],[1,1.01,0.51],[2,1.01,0]],"ltp":0.0,"tv":0.0,"id":20912771}]}]}
{"op":"mcm","clk":"1003306849","pt":1580605990864,"mc":[{"id":"1.168179121","rc":[{"batb":[[1,4.1,42.49],[2,1.01,0.51]],"batl":[[0,5.2,33.28],[1,5.9,24.94],[2,7.2,33.05]],"ltp":4.7,"tv":9.99,"id":14904499},{"batb":[[0,1.56,67.59],[1,1.44,92.77],[2,1.32,136.28]],"batl":[[1,1.74,53.35]],"ltp":1.58,"tv":62.69,"id":14904498},{"batb":[[1,10,27.77],[2,1.01,0.51]],"batl":[[0,14,22.74],[1,15.5,18.88],[2,17,15.34]],"ltp":12.5,"tv":0.16,"id":20912772},{"batb":[[1,9.2,34.38],[2,1.01,0.51]],"batl":[[0,14,22.5],[1,19,12.75]],"ltp":0.0,"tv":0.0,"id":20912771}]}]}
{"op":"mcm","clk":"1003306892","pt":1580605991486,"mc":[{"id":"1.168179121","rc":[{"batl":[[2,7.2,0]],"ltp":4.7,"tv":9.99,"id":14904499},{"batb":[[2,1.01,0.51]],"ltp":1.58,"tv":62.69,"id":14904498},{"batl":[[2,17,0]],"ltp":12.5,"tv":0.16,"id":20912772}]}]}
{"op":"mcm","clk":"1003308234","pt":1580606010898,"mc":[{"id":"1.168179121","rc":[{"batb":[[0,4.1,42.49],[1,1.01,0.51],[2,1.01,0]],"batl":[[0,5.9,24.94],[1,5.9,0]],"ltp":4.7,"tv":9.99,"id":14904499},{"batb":[[0,1.44,92.77],[1,1.01,0.51],[2,1.01,0]],"batl":[[0,1.74,53.35],[1,1.74,0]],"ltp":1.58,"tv":62.69,"id":14904498},{"batb":[[0,10,27.77],[1,1.01,0.51],[2,1.01,0]],"batl":[[0,15.5,18.88],[1,15.5,0]],"ltp":12.5,"tv":0.16,"id":20912772},{"batb":[[0,9.2,34.38],[1,1.01,0.51],[2,1.01,0]],"batl":[[0,19,12.75],[1,19,0]],"ltp":0.0,"tv":0.0,"id":20912771}]}]}
{"op":"mcm","clk":"1003308452","pt":1580606013893,"mc":[{"id":"1.168179121","rc":[{"batb":[[0,4.2,42.09]],"batl":[[0,5.9,24.78]],"ltp":4.7,"tv":9.99,"id":14904499},{"batb":[[0,1.44,91.66]],"batl":[[0,1.74,52.64]],"ltp":1.58,"tv":62.69,"id":14904498},{"batl":[[0,15,19.51]],"ltp":12.5,"tv":0.16,"id":20912772},{"batb":[[0,9,14.24]],"batl":[[0,18.5,13.14]],"ltp":0.0,"tv":0.0,"id":20912771}]}]}
{"op":"mcm","clk":"1003308913","pt":1580606020596,"mc":[{"id":"1.168179121","rc":[{"batb":[[0,5.1,25.81],[1,4.6,34.15],[2,1.01,0.51]],"batl":[[1,7.4,32.34]],"ltp":4.7,"tv":9.99,"id":14904499},{"batb":[[1,1.32,138.32],[2,1.01,0.51]],"batl":[[0,1.51,89.15],[1,1.63,66.8]],"ltp":1.58,"tv":62.69,"id":14904498},{"batb":[[0,11,21.17],[1,10.5,25.1],[2,1.01,0.51]],"batl":[[1,17,15.26]],"ltp":12.5,"tv":0.16,"id":20912772},{"batb":[[0,13.5,14.08],[1,10.5,24.39],[2,1.01,0.51]],"ltp":0.0,"tv":0.0,"id":20912771}]}]}
{"op":"mcm","clk":"1003310212","pt":1580606039049,"mc":[{"id":"1.168179121","rc":[{"batb":[[0,4.6,34.15],[1,1.01,0.51],[2,1.01,0]],"batl":[[0,7.4,32.34],[1,7.4,0]],"ltp":4.7,"tv":9.99,"id":14904499},{"batb":[[0,1.32,138.32],[1,1.01,0.51],[2,1.01,0]],"batl":[[0,1.63,66.8],[1,1.63,0]],"ltp":1.58,"tv":62.69,"id":14904498},{"batb":[[0,10.5,25.1],[1,1.01,0.51],[2,1.01,0]],"batl":[[0,17,15.26],[1,17,0]],"ltp":12.5,"tv":0.16,"id":20912772},{"batb":[[0,10.5,24.39],[1,1.01,0.51],[2,1.01,0]],"ltp":0.0,"tv":0.0,"id":20912771}]}]}
{"op":"mcm","clk":"1003311876","pt":1580606062286,"mc":[{"id":"1.168179121","rc":[{"batb":[[0,6,34.54],[1,5.2,25.49],[2,1.01,0.51]],"batl":[[1,10,17.15]],"ltp":4.7,"tv":9.99,"id":14904499},{"batb":[[1,1.19,244.46],[2,1.01,0.51]],"batl":[[0,1.38,133.29],[1,1.5,90.41]],"ltp":1.58,"tv":62.69,"id":14904498},{"batb":[[0,12.5,16.37],[1,11.5,20.93],[2,1.01,0.51]],"batl":[[1,20,11.25]],"ltp":12.5,"tv":0.16,"id":20912772},{"batb":[[0,21,9.87],[1,13.5,13.69],[2,1.01,0.51]],"ltp":0.0,"tv":0.0,"id":20912771}]}]}
{"op":"mcm","clk":"1003313429","pt":1580606083807,"mc":[{"id":"1.168179121","rc":[{"batb":[[0,5.2,25.49],[1,1.01,0.51],[2,1.01,0]],"batl":[[0,10,17.15],[1,10,0]],"ltp":4.7,"tv":9.99,"id":14904499},{"batb":[[0,1.19,244.46],[1,1.01,0.51],[2,1.01,0]],"batl":[[0,1.5,90.41],[1,1.5,0]],"ltp":1.58,"tv":62.69,"id":14904498},{"batb":[[0,11.5,20.93],[1,1.01,0.51],[2,1.01,0]],"batl":[[0,20,11.25],[1,20,0]],"ltp":12.5,"tv":0.16,"id":20912772},{"batb":[[0,13.5,13.69],[1,1.01,0.51],[2,1.01,0]],"ltp":0.0,"tv":0.0,"id":20912771}]}]}
{"op":"mcm","clk":"1003314332","pt":1580606097740,"mc":[{"id":"1.168179121","rc":[{"batb":[[0,8.2,18.02],[1,7.2,24],[2,1.01,0.51]],"batl":[[1,10.5,15.26]],"ltp":4.7,"tv":9.99,"id":14904499},{"batb":[[1,1.18,273.81],[2,1.01,0.51]],"batl":[[0,1.24,231.56],[1,1.29,182.46]],"ltp":1.58,"tv":62.69,"id":14904498},{"batb":[[0,14.5,11.96],[1,13,14.71],[2,1.01,0.51]],"batl":[[1,22,9.99]],"ltp":12.5,"tv":0.16,"id":20912772},{"batb":[[0,30,2.6]],"ltp":0.0,"tv":0.0,"id":20912771}]}]}
{"op":"mcm","clk":"1003316171","pt":1580606123365,"mc":[{"id":"1.168179121","rc":[{"batb":[[0,7.2,24],[1,1.01,0.51],[2,1.01,0]],"batl":[[0,10.5,15.26],[1,10.5,0]],"ltp":4.7,"tv":9.99,"id":14904499},{"batb":[[0,1.18,273.81],[1,1.01,0.51],[2,1.01,0]],"batl":[[0,1.29,182.46],[1,1.29,0]],"ltp":1.58,"tv":62.69,"id":14904498},{"batb":[[0,13,14.71],[1,1.01,0.51],[2,1.01,0]],"batl":[[0,22,9.99],[1,22,0]],"ltp":12.5,"tv":0.16,"id":20912772}]}]}
{"op":"mcm","clk":"1003316402","pt":1580606126848,"mc":[{"id":"1.168179121","rc":[{"batb":[[0,7,25.57]],"ltp":4.7,"tv":9.99,"id":14904499},{"batb":[[0,1.18,259.57]],"batl":[[0,1.31,174.04]],"ltp":1.58,"tv":62.69,"id":14904498},{"batl":[[0,21,10.78]],"ltp":12.5,"tv":0.16,"id":20912772}]}]}
{"op":"mcm","clk":"1003316911","pt":1580606133761,"mc":[{"id":"1.168179121","rc":[{"batb":[[0,8.2,17.31],[1,7.4,21.79],[2,1.01,0.51]],"batl":[[1,11,14.56]],"ltp":4.7,"tv":9.99,"id":14904499},{"batb":[[1,1.17,287.03],[2,1.01,0.51]],"batl":[[0,1.23,245.25],[1,1.27,202.13]],"ltp":1.58,"tv":62.69,"id":14904498},{"batb":[[0,14.5,11.49],[1,13.5,14.01],[2,1.01,0.51]],"batl":[[1,22,9.99]],"ltp":12.5,"tv":0.16,"id":20912772},{"batb":[[0,1.01,0.51],[1,1.01,0]],"ltp":0.0,"tv":0.0,"id":20912771}]}]}
{"op":"mcm","clk":"1003317821","pt":1580606146405,"mc":[{"id":"1.168179121","rc":[{"batb":[[0,7.4,21.79],[1,1.01,0.51],[2,1.01,0]],"batl":[[0,11,14.56],[1,11,0]],"ltp":4.7,"tv":9.99,"id":14904499},{"batb":[[0,1.17,286.87],[1,1.01,0.51],[2,1.01,0]],"batl":[[0,1.27,201.98],[1,1.27,0]],"ltp":1.58,"tv":62.69,"id":14904498},{"batb":[[0,13.5,14.01],[1,1.01,0.51],[2,1.01,0]],"batl":[[0,22,9.99],[1,22,0]],"ltp":12.5,"tv":0.16,"id":20912772}]}]}
{"op":"mcm","clk":"1003318504","pt":1580606155796,"mc":[{"id":"1.168179121","rc":[{"batb":[[0,8,18.65],[1,7.4,21.79],[2,1.01,0.51]],"batl":[[1,11.5,33.05]],"ltp":4.7,"tv":9.99,"id":14904499},{"batb":[[1,1.16,306.15],[2,1.01,0.51]],"batl":[[0,1.22,269.96],[1,1.24,230.07],[2,1.27,201.98]],"ltp":1.58,"tv":62.69,"id":14904498},{"batb":[[0,15,10.62],[1,14,12.98],[2,13.5,14.01]],"batl":[[1,23,9.13]],"ltp":12.5,"tv":0.16,"id":20912772}]}]}
{"op":"mcm","clk":"1003318582","pt":1580606156726,"mc":[{"id":"1.168179121","rc":[{"batb":[[1,1.01,0.51],[2,1.01,0]],"ltp":4.7,"tv":9.99,"id":14904499},{"batl":[[2,1.27,0]],"ltp":1.58,"tv":62.69,"id":14904498},{"batb":[[2,1.01,0.51]],"ltp":12.5,"tv":0.16,"id":20912772}]}]}
{"op":"mcm","clk":"1003319572","pt":1580606170206,"mc":[{"id":"1.168179121","rc":[{"batl":[[0,11.5,33.05],[1,11.5,0]],"ltp":4.7,"tv":9.99,"id":14904499},{"batb":[[0,1.16,306.15],[1,1.01,0.51],[2,1.01,0]],"batl":[[0,1.24,230.07],[1,1.24,0]],"ltp":1.58,"tv":62.69,"id":14904498},{"batb":[[0,14,12.98],[1,1.01,0.51],[2,1.01,0]],"batl":[[0,23,9.13],[1,23,0]],"ltp":12.5,"tv":0.16,"id":20912772}]}]}
{"op":"mcm","clk":"1003321444","pt":1580606194844,"mc":[{"id":"1.168179121","rc":[{"batb":[[1,7,24.55],[2,1.01,0.51]],"batl":[[0,9.6,18.02],[1,10.5,16.21]],"ltp":4.7,"tv":9.99,"id":14904499},{"batb":[[0,1.2,240.29],[1,1.18,266.89],[2,1.01,0.51]],"batl":[[0,1.25,227.78],[1,1.29,182.46]],"ltp":1.58,"tv":62.69,"id":14904498},{"batb":[[1,13,15.82],[2,1.01,0.51]],"batl":[[0,19,12.35],[1,20,11.33]],"ltp":12.5,"tv":0.16,"id":20912772}]}]}
{"op":"mcm","clk":"1003323349","pt":1580606219086,"mc":[{"id":"1.168179121","rc":[{"batb":[[0,7,24.55],[1,1.01,0.51],[2,1.01,0]],"batl":[[0,10.5,16.21],[1,10.5,0]],"ltp":4.7,"tv":9.99,"id":14904499},{"batb":[[0,1.18,266.89],[1,1.01,0.51],[2,1.01,0]],"batl":[[0,1.29,182.46],[1,1.29,0]],"ltp":1.58,"tv":62.69,"id":14904498},{"batb":[[0,13,15.82],[1,1.01,0.51],[2,1.01,0]],"batl":[[0,20,11.33],[1,20,0]],"ltp":12.5,"tv":0.16,"id":20912772}]}]}
{"op":"mcm","clk":"1003324998","pt":1580606239651,"mc":[{"id":"1.168179121","rc":[{"batb":[[0,8.4,16.92],[1,7.8,20.14],[2,1.01,0.51]],"batl":[[1,11,14.71]],"ltp":4.7,"tv":9.99,"id":14904499},{"batb":[[1,1.17,288.76],[2,1.01,0.51]],"batl":[[0,1.23,251.94],[1,1.25,219.05]],"ltp":1.58,"tv":62.69,"id":14904498},{"batb":[[0,14.5,12.04],[1,13.5,14.32],[2,1.01,0.51]],"batl":[[1,21,10.31]],"ltp":12.5,"tv":0.16,"id":20912772}]}]}
{"op":"mcm","clk":"1003326202","pt":1580606254540,"mc":[{"id":"1.168179121","rc":[{"batb":[[0,7.8,20.14],[1,1.01,0.51],[2,1.01,0]],"batl":[[0,11,14.71],[1,11,0]],"ltp":4.7,"tv":9.99,"id":14904499},{"batb":[[0,1.17,288.76],[1,1.01,0.51],[2,1.01,0]],"batl":[[0,1.25,219.05],[1,1.25,0]],"ltp":1.58,"tv":62.69,"id":14904498},{"batb":[[0,13.5,14.32],[1,1.01,0.51],[2,1.01,0]],"batl":[[0,21,10.31],[1,21,0]],"ltp":12.5,"tv":0.16,"id":20912772}]}]}
{"op":"mcm","clk":"1003327757","pt":1580606274188,"mc":[{"id":"1.168179121","rc":[{"batb":[[0,8.8,15.34],[1,7.6,21.09],[2,1.01,0.51]],"batl":[[1,14,23.05]],"ltp":4.7,"tv":9.99,"id":14904499},{"batb":[[1,1.13,385.54],[2,1.01,0.51]],"batl":[[0,1.21,271.69],[1,1.25,219.05]],"ltp":1.58,"tv":62.69,"id":14904498},{"batb":[[0,15,10.94],[1,13,14.63],[2,1.01,0.51]],"batl":[[1,27,13.22]],"ltp":12.5,"tv":0.16,"id":20912772}]}]}
{"op":"mcm","clk":"1003328489","pt":1580606282891,"mc":[{"id":"1.168179121","rc":[{"batb":[[0,8.4,16.37],[1,7.4,22.5]],"batl":[[0,10.5,15.66],[1,13.5,24.63]],"ltp":4.7,"tv":9.99,"id":14904499},{"batb":[[0,1.17,276.41],[1,1.13,369.25]],"batl":[[0,1.22,260.52],[1,1.26,212.99]],"ltp":1.58,"tv":62.69,"id":14904498},{"batb":[[0,14.5,11.64]],"batl":[[1,26,14.08]],"ltp":12.5,"tv":0.16,"id":20912772}]}]}
{"op":"mcm","clk":"1003328673","pt":1580606284869,"mc":[{"id":"1.168179121","rc":[{"batb":[[0,1000,4],[1,1.01,0.51]],"ltp":0.0,"tv":0.0,"id":20912771}]}]}
{"op":"mcm","clk":"1003328714","pt":1580606285282,"mc":[{"id":"1.168179121","rc":[{"batb":[[0,1.19,341.71],[1,1.17,276.41],[2,1.13,369.25]],"ltp":1.58,"tv":62.69,"id":14904498}]}]}
{"op":"mcm","clk":"1003330440","pt":1580606305501,"mc":[{"id":"1.168179121","rc":[{"batb":[[1,1.17,274.84],[2,1.13,367.29]],"batl":[[0,1.22,259.18],[1,1.26,211.81]],"ltp":1.58,"tv":62.69,"id":14904498},{"batb":[[1,12.5,15.97]],"batl":[[0,20,11.25]],"ltp":12.5,"tv":0.16,"id":20912772}]}]}
{"op":"mcm","clk":"1003330704","pt":1580606308594,"mc":[{"id":"1.168179121","rc":[{"batb":[[0,14.5,39.26]],"ltp":12.5,"tv":0.16,"id":20912772}]}]}
{"op":"mcm","clk":"1003331124","pt":1580606313732,"mc":[{"id":"1.168179121","rc":[{"batb":[[1,1.18,274.13],[2,1.13,366.34]],"batl":[[0,1.22,258.47],[1,1.26,211.26]],"ltp":1.58,"tv":62.69,"id":14904498}]}]}
{"op":"mcm","clk":"1003332734","pt":1580606333554,"mc":[{"id":"1.168179121","rc":[{"batb":[[1,1.18,273.73],[2,1.13,365.79]],"batl":[[0,1.22,258.16],[1,1.26,211.02]],"ltp":1.58,"tv":62.69,"id":14904498}]}]}
{"op":"mcm","clk":"1003333322","pt":1580606341548,"mc":[{"id":"1.168179121","rc":[{"batb":[[1,1.18,273.5],[2,1.13,365.48]],"batl":[[0,1.22,257.92],[1,1.26,210.79]],"ltp":1.58,"tv":62.69,"id":14904498}]}]}
{"op":"mcm","clk":"1003334778","pt":1580606360674,"mc":[{"id":"1.168179121","rc":[{"batb":[[0,1.18,273.5],[1,1.13,365.48],[2,1.01,0.51]],"ltp":1.58,"tv":62.69,"id":14904498}]}]}
{"op":"mcm","clk":"1003339896","pt":1580606430862,"mc":[{"id":"1.168179121","rc":[{"batb":[[0,7.4,22.5],[1,1.01,0.51],[2,1.01,0]],"batl":[[0,13.5,24.63],[1,13.5,0]],"ltp":4.7,"tv":9.99,"id":14904499},{"batb":[[0,1.13,365.16],[1,1.01,0.51],[2,1.01,0]],"batl":[[0,1.26,210.63],[1,1.26,0]],"ltp":1.58,"tv":62.69,"id":14904498},{"batb":[[0,12.5,15.97],[1,1.01,0.51],[2,1.01,0]],"batl":[[0,26,14.08],[1,26,0]],"ltp":12.5,"tv":0.16,"id":20912772}]}]}
{"op":"mcm","clk":"1003340763","pt":1580606442813,"mc":[{"id":"1.168179121","rc":[{"batb":[[1,6.6,28.56],[2,1.01,0.51]],"batl":[[0,9,21.24],[1,11,14.95]],"ltp":4.7,"tv":9.99,"id":14904499},{"batb":[[0,1.21,221.49],[1,1.17,282.78],[2,1.01,0.51]],"batl":[[1,1.3,177.19]],"ltp":1.58,"tv":62.69,"id":14904498},{"batb":[[1,11,21.48],[2,1.01,0.51]],"batl":[[0,17,15.26],[1,21,10.86]],"ltp":12.5,"tv":0.16,"id":20912772}]}]}
{"op":"mcm","clk":"1003341754","pt":1580606457417,"mc":[{"id":"1.168179121","rc":[{"batb":[[0,6.6,28.56],[1,1.01,0.51],[2,1.01,0]],"batl":[[0,11,14.95],[1,11,0]],"ltp":4.7,"tv":9.99,"id":14904499},{"batb":[[0,1.17,282.78],[1,1.01,0.51],[2,1.01,0]],"batl":[[0,1.3,177.19],[1,1.3,0]],"ltp":1.58,"tv":62.69,"id":14904498},{"batb":[[0,11,21.48],[1,1.01,0.51],[2,1.01,0]],"batl":[[0,21,10.86],[1,21,0]],"ltp":12.5,"tv":0.16,"id":20912772}]}]}
{"op":"mcm","clk":"1003342867","pt":1580606473652,"mc":[{"id":"1.168179121","rc":[{"batb":[[0,8.6,15.66],[1,7.4,22.42],[2,1.01,0.51]],"batl":[[1,14.5,21.4]],"ltp":4.7,"tv":9.99,"id":14904499},{"batb":[[1,1.12,401.51],[2,1.01,0.51]],"batl":[[0,1.22,266.26],[1,1.26,210.95]],"ltp":1.58,"tv":62.69,"id":14904498},{"batb":[[0,14.5,11.57],[1,12.5,16.29],[2,1.01,0.51]],"batl":[[1,28,12.67]],"ltp":12.5,"tv":0.16,"id":20912772}]}]}
{"op":"mcm","clk":"1003343903","pt":1580606490346,"mc":[{"id":"1.168179121","rc":[{"batb":[[0,7.4,22.42],[1,1.01,0.51],[2,1.01,0]],"batl":[[0,14.5,21.4],[1,14.5,0]],"ltp":4.7,"tv":9.99,"id":14904499},{"batb":[[0,1.12,401.51],[1,1.01,0.51],[2,1.01,0]],"batl":[[0,1.26,210.95],[1,1.26,0]],"ltp":1.58,"tv":62.69,"id":14904498},{"batb":[[0,12.5,16.29],[1,1.01,0.51],[2,1.01,0]],"batl":[[0,28,12.67],[1,28,0]],"ltp":12.5,"tv":0.16,"id":20912772}]}]}
{"op":"mcm","clk":"1003345386","pt":1580606512564,"mc":[{"id":"1.168179121","rc":[{"batb":[[1,6.4,29.66],[2,1.01,0.51]],"batl":[[0,9,21.32],[1,11,14.24]],"ltp":4.7,"tv":9.99,"id":14904499},{"batb":[[0,1.21,221.88],[1,1.16,293.64],[2,1.01,0.51]],"batl":[[1,1.31,173.41]],"ltp":1.58,"tv":62.69,"id":14904498},{"batb":[[1,11,21.79],[2,1.01,0.51]],"batl":[[0,17,15.19],[1,21,10.23]],"ltp":12.5,"tv":0.16,"id":20912772}]}]}
{"op":"mcm","clk":"1003346712","pt":1580606532001,"mc":[{"id":"1.168179121","rc":[{"batb":[[0,6.4,29.66],[1,1.01,0.51],[2,1.01,0]],"batl":[[0,11,14.24],[1,11,0]],"ltp":4.7,"tv":9.99,"id":14904499},{"batb":[[0,1.16,293.64],[1,1.01,0.51],[2,1.01,0]],"batl":[[0,1.31,173.41],[1,1.31,0]],"ltp":1.58,"tv":62.69,"id":14904498},{"batb":[[0,11,21.79],[1,1.01,0.51],[2,1.01,0]],"batl":[[0,21,10.23],[1,21,0]],"ltp":12.5,"tv":0.16,"id":20912772}]}]}
{"op":"mcm","clk":"1003347889","pt":1580606549755,"mc":[{"id":"1.168179121","rc":[{"batb":[[1,6,35.49],[2,1.01,0.51]],"batl":[[0,7.8,27.93],[1,8.8,22.42]],"ltp":4.7,"tv":9.99,"id":14904499},{"batb":[[0,1.25,181.2],[1,1.22,215.51],[2,1.01,0.51]],"batl":[[1,1.34,152.64]],"ltp":1.58,"tv":62.69,"id":14904498},{"batb":[[1,10,25.97],[2,1.01,0.51]],"batl":[[0,15,20.06],[1,17,15.42]],"ltp":12.5,"tv":0.16,"id":20912772}]}]}
{"op":"mcm","clk":"1003348808","pt":1580606565274,"mc":[{"id":"1.168179121","rc":[{"batb":[[0,6,35.49],[1,1.01,0.51],[2,1.01,0]],"batl":[[0,8.8,22.42],[1,8.8,0]],"ltp":4.7,"tv":9.99,"id":14904499},{"batb":[[0,1.22,215.51],[1,1.01,0.51],[2,1.01,0]],"batl":[[0,1.34,152.64],[1,1.34,0]],"ltp":1.58,"tv":62.69,"id":14904498},{"batb":[[0,10,25.97],[1,1.01,0.51],[2,1.01,0]],"batl":[[0,17,15.42],[1,17,0]],"ltp":12.5,"tv":0.16,"id":20912772}]}]}
{"op":"mcm","clk":"1003349597","pt":1580606578680,"mc":[{"id":"1.168179121","rc":[{"batb":[[0,7.2,23.68],[1,6.2,32.73],[2,1.01,0.51]],"batl":[[1,11,34.7]],"ltp":4.7,"tv":9.99,"id":14904499},{"batb":[[1,1.16,297.97],[2,1.01,0.51]],"batl":[[0,1.27,205.2],[1,1.32,164.84]],"ltp":1.58,"tv":62.69,"id":14904498},{"batb":[[0,12.5,16.52],[1,11,22.35],[2,1.01,0.51]],"batl":[[1,22,9.99]],"ltp":12.5,"tv":0.16,"id":20912772}]}]}
{"op":"mcm","clk":"1003350791","pt":1580606596998,"mc":[{"id":"1.168179121","rc":[{"batb":[[0,6.2,32.73],[1,1.01,0.51],[2,1.01,0]],"batl":[[0,11,34.7],[1,11,0]],"ltp":4.7,"tv":9.99,"id":14904499},{"batb":[[0,1.16,297.97],[1,1.01,0.51],[2,1.01,0]],"batl":[[0,1.32,164.84],[1,1.32,0]],"ltp":1.58,"tv":62.69,"id":14904498},{"batb":[[0,11,22.35],[1,1.01,0.51],[2,1.01,0]],"batl":[[0,22,9.99],[1,22,0]],"ltp":12.5,"tv":0.16,"id":20912772}]}]}
{"op":"mcm","clk":"1003351914","pt":1580606613421,"mc":[{"id":"1.168179121","rc":[{"batb":[[0,9,14.48],[1,7.2,23.29],[2,1.01,0.51]],"batl":[[1,16,17.07]],"ltp":4.7,"tv":9.99,"id":14904499},{"batb":[[1,1.11,464.14],[2,1.01,0.51]],"batl":[[0,1.21,279.87],[1,1.27,207.01]],"ltp":1.58,"tv":62.69,"id":14904498},{"batb":[[0,15,10.62],[1,12.5,16.52],[2,1.01,0.51]],"ltp":12.5,"tv":0.16,"id":20912772}]}]}
{"op":"mcm","clk":"1003353237","pt":1580606632845,"mc":[{"id":"1.168179121","rc":[{"batb":[[0,7.2,23.29],[1,1.01,0.51],[2,1.01,0]],"batl":[[0,16,17.07],[1,16,0]],"ltp":4.7,"tv":9.99,"id":14904499},{"batb":[[0,1.11,464.14],[1,1.01,0.51],[2,1.01,0]],"batl":[[0,1.27,207.01],[1,1.27,0]],"ltp":1.58,"tv":62.69,"id":14904498},{"batb":[[0,12.5,16.52],[1,1.01,0.51],[2,1.01,0]],"ltp":12.5,"tv":0.16,"id":20912772}]}]}
{"op":"mcm","clk":"1003354156","pt":1580606645763,"mc":[{"id":"1.168179121","rc":[{"batb":[[1,6.2,32.73],[2,1.01,0.51]],"batl":[[0,8.8,22.03],[1,11.5,32.81]],"ltp":4.7,"tv":9.99,"id":14904499},{"batb":[[0,1.22,217.56],[1,1.16,302.22],[2,1.01,0.51]],"batl":[[1,1.32,165.39]],"ltp":1.58,"tv":62.69,"id":14904498},{"batb":[[1,11,22.03],[2,1.01,0.51]],"batl":[[0,17,15.34],[1,22,9.91]],"ltp":12.5,"tv":0.16,"id":20912772}]}]}
{"op":"mcm","clk":"1003355103","pt":1580606660463,"mc":[{"id":"1.168179121","rc":[{"batb":[[0,6.2,32.73],[1,1.01,0.51],[2,1.01,0]],"batl":[[0,11.5,32.81],[1,11.5,0]],"ltp":4.7,"tv":9.99,"id":14904499},{"batb":[[0,1.16,302.22],[1,1.01,0.51],[2,1.01,0]],"batl":[[0,1.32,165.39],[1,1.32,0]],"ltp":1.58,"tv":62.69,"id":14904498},{"batb":[[0,11,22.03],[1,1.01,0.51],[2,1.01,0]],"batl":[[0,22,9.91],[1,22,0]],"ltp":12.5,"tv":0.16,"id":20912772}]}]}
{"op":"mcm","clk":"1003357344","pt":1580606691815,"mc":[{"id":"1.168179121","rc":[{"batl":[[0,15.5,83.38],[1,22,9.91]],"ltp":12.5,"tv":0.16,"id":20912772}]}]}
{"op":"mcm","clk":"1003357412","pt":1580606692745,"mc":[{"id":"1.168179121","rc":[{"batb":[[1,5.3,24],[2,1.01,0.51]],"batl":[[0,7.4,30.76],[1,8.4,24.71],[2,11.5,32.81]],"ltp":4.7,"tv":9.99,"id":14904499},{"batb":[[0,1.26,172.47],[1,1.23,200.32],[2,1.16,302.22]],"batl":[[1,1.4,121.72]],"ltp":1.58,"tv":62.69,"id":14904498},{"batb":[[1,9.2,33.83],[2,1.01,0.51]],"batl":[[0,14.5,20.3],[1,16,17.15],[2,22,9.91]],"ltp":12.5,"tv":0.16,"id":20912772}]}]}
{"op":"mcm","clk":"1003357429","pt":1580606693003,"mc":[{"id":"1.168179121","rc":[{"batl":[[2,11.5,0]],"ltp":4.7,"tv":9.99,"id":14904499},{"batb":[[2,1.01,0.51]],"ltp":1.58,"tv":62.69,"id":14904498},{"batl":[[2,22,0]],"ltp":12.5,"tv":0.16,"id":20912772}]}]}
{"op":"mcm","clk":"1003361004","pt":1580606740394,"mc":[{"id":"1.168179121","rc":[{"batb":[[0,5.3,24],[1,1.01,0.51],[2,1.01,0]],"batl":[[0,8.4,24.71],[1,8.4,0]],"ltp":4.7,"tv":9.99,"id":14904499},{"batb":[[0,1.23,200.32],[1,1.01,0.51],[2,1.01,0]],"batl":[[0,1.4,121.72],[1,1.4,0]],"ltp":1.58,"tv":62.69,"id":14904498},{"batb":[[0,9.2,33.83],[1,1.01,0.51],[2,1.01,0]],"batl":[[0,16,17.15],[1,16,0]],"ltp":12.5,"tv":0.16,"id":20912772}]}]}
{"op":"mcm","clk":"1003361787","pt":1580606750401,"mc":[{"id":"1.168179121","rc":[{"batb":[[0,6.8,26.12],[1,5.9,37.37],[2,1.01,0.51]],"batl":[[1,8.8,21.56]],"ltp":4.7,"tv":9.99,"id":14904499},{"batb":[[1,1.21,222.83],[2,1.01,0.51]],"batl":[[0,1.28,191.12],[1,1.35,148.32]],"ltp":1.58,"tv":62.69,"id":14904498},{"batb":[[0,12,18.57],[1,10,26.44],[2,1.01,0.51]],"batl":[[1,17.5,14.63]],"ltp":12.5,"tv":0.16,"id":20912772}]}]}
{"op":"mcm","clk":"1003362245","pt":1580606755875,"mc":[{"id":"1.168179121","rc":[{"batb":[[0,5.9,37.37],[1,1.01,0.51],[2,1.01,0]],"batl":[[0,8.8,21.56],[1,8.8,0]],"ltp":4.7,"tv":9.99,"id":14904499},{"batb":[[0,1.21,222.83],[1,1.01,0.51],[2,1.01,0]],"batl":[[0,1.35,148.32],[1,1.35,0]],"ltp":1.58,"tv":62.69,"id":14904498},{"batb":[[0,10,26.44],[1,1.01,0.51],[2,1.01,0]],"batl":[[0,17.5,14.63],[1,17.5,0]],"ltp":12.5,"tv":0.16,"id":20912772}]}]}
{"op":"mcm","clk":"1003363116","pt":1580606766886,"mc":[{"id":"1.168179121","rc":[{"batb":[[0,7.4,22.66],[1,6.6,28.88],[2,1.01,0.51]],"batl":[[1,9.2,19.75]],"ltp":4.7,"tv":9.99,"id":14904499},{"batb":[[1,1.2,240.77],[2,1.01,0.51]],"batl":[[0,1.26,211.81],[1,1.3,176.8]],"ltp":1.58,"tv":62.69,"id":14904498},{"batb":[[0,13,15.66],[1,11,21.24],[2,1.01,0.51]],"batl":[[1,19,12.59]],"ltp":12.5,"tv":0.16,"id":20912772}]}]}
{"op":"mcm","clk":"1003364397","pt":1580606782852,"mc":[{"id":"1.168179121","rc":[{"batb":[[0,6.6,28.88],[1,1.01,0.51],[2,1.01,0]],"batl":[[0,9.2,19.75],[1,9.2,0]],"ltp":4.7,"tv":9.99,"id":14904499},{"batb":[[0,1.2,240.77],[1,1.01,0.51],[2,1.01,0]],"batl":[[0,1.3,176.8],[1,1.3,0]],"ltp":1.58,"tv":62.69,"id":14904498},{"batb":[[0,11,21.24],[1,1.01,0.51],[2,1.01,0]],"batl":[[0,19,12.59],[1,19,0]],"ltp":12.5,"tv":0.16,"id":20912772}]}]}
{"op":"mcm","clk":"1003365006","pt":1580606790660,"mc":[{"id":"1.168179121","rc":[{"batb":[[0,7.6,20.77],[1,7.2,24.16],[2,1.01,0.51]],"batl":[[1,9.6,18.65]],"ltp":4.7,"tv":9.99,"id":14904499},{"batb":[[1,1.19,253.12],[2,1.01,0.51]],"batl":[[0,1.25,228.26],[1,1.27,201.66]],"ltp":1.58,"tv":62.69,"id":14904498},{"batb":[[0,14,13.38],[1,12.5,17.23],[2,1.01,0.51]],"batl":[[1,20,11.49]],"ltp":12.5,"tv":0.16,"id":20912772}]}]}
{"op":"mcm","clk":"1003365723","pt":1580606800262,"mc":[{"id":"1.168179121","rc":[{"batb":[[0,7.2,24.16],[1,1.01,0.51],[2,1.01,0]],"batl":[[0,9.6,18.65],[1,9.6,0]],"ltp":4.7,"tv":9.99,"id":14904499},{"batb":[[0,1.19,253.12],[1,1.01,0.51],[2,1.01,0]],"batl":[[0,1.27,201.66],[1,1.27,0]],"ltp":1.58,"tv":62.69,"id":14904498},{"batb":[[0,12.5,17.23],[1,1.01,0.51],[2,1.01,0]],"batl":[[0,20,11.49],[1,20,0]],"ltp":12.5,"tv":0.16,"id":20912772}]}]}
{"op":"mcm","clk":"1003367518","pt":1580606820896,"mc":[{"id":"1.168179121","rc":[{"batb":[[0,7.8,19.59],[1,6.8,26.2],[2,1.01,0.51]],"batl":[[1,12.5,27.54]],"ltp":4.7,"tv":9.99,"id":14904499},{"batb":[[1,1.14,348.4],[2,1.01,0.51]],"batl":[[0,1.24,239.43],[1,1.28,196.23]],"ltp":1.58,"tv":62.69,"id":14904498},{"batb":[[0,14.5,12.2],[1,12.5,16.52],[2,1.01,0.51]],"batl":[[1,26,14.63]],"ltp":12.5,"tv":0.16,"id":20912772}]}]}
{"op":"mcm","clk":"1003369721","pt":1580606847836,"mc":[{"id":"1.168179121","rc":[{"batb":[[0,6.8,26.2],[1,1.01,0.51],[2,1.01,0]],"batl":[[0,12.5,27.54],[1,12.5,0]],"ltp":4.7,"tv":9.99,"id":14904499},{"batb":[[0,1.14,348.4],[1,1.01,0.51],[2,1.01,0]],"batl":[[0,1.28,196.23],[1,1.28,0]],"ltp":1.58,"tv":62.69,"id":14904498},{"batb":[[0,12.5,16.52],[1,1.01,0.51],[2,1.01,0]],"batl":[[0,26,14.63],[1,26,0]],"ltp":12.5,"tv":0.16,"id":20912772}]}]}
{"op":"mcm","clk":"1003369964","pt":1580606850745,"mc":[{"id":"1.168179121","rc":[{"batl":[[0,25,15.26],[1,26,14.63]],"ltp":12.5,"tv":0.16,"id":20912772}]}]}
{"op":"mcm","clk":"1003369991","pt":1580606851054,"mc":[{"id":"1.168179121","rc":[{"batb":[[0,1.14,345.26]],"batl":[[0,1.28,194.5]],"ltp":1.58,"tv":62.69,"id":14904498},{"batl":[[1,26,0]],"ltp":12.5,"tv":0.16,"id":20912772}]}]}
{"op":"mcm","clk":"1003371214","pt":1580606866841,"mc":[{"id":"1.168179121","rc":[{"batb":[[0,9.6,30.21],[1,8,18.18],[2,1.01,0.51]],"batl":[[1,17.5,14.32]],"ltp":4.7,"tv":9.99,"id":14904499},{"batb":[[1,1.09,526.62],[2,1.01,0.51]],"batl":[[0,1.19,303.55],[1,1.23,245.88]],"ltp":1.58,"tv":62.69,"id":14904498},{"batb":[[0,17,8.5],[1,14,12.43],[2,1.01,0.51]],"ltp":12.5,"tv":0.16,"id":20912772}]}]}
{"op":"mcm","clk":"1003372554","pt":1580606882779,"mc":[{"id":"1.168179121","rc":[{"batb":[[0,8,18.18],[1,1.01,0.51],[2,1.01,0]],"batl":[[0,17.5,14.32],[1,17.5,0]],"ltp":4.7,"tv":9.99,"id":14904499},{"batb":[[0,1.09,526.46],[1,1.01,0.51],[2,1.01,0]],"batl":[[0,1.23,245.88],[1,1.23,0]],"ltp":1.58,"tv":62.69,"id":14904498},{"batb":[[0,14,12.43],[1,1.01,0.51],[2,1.01,0]],"ltp":12.5,"tv":0.16,"id":20912772}]}]}
{"op":"mcm","clk":"1003374410","pt":1580606903573,"mc":[{"id":"1.168179121","rc":[{"batb":[[0,13,15.34],[1,10,26.28],[2,1.01,0.51]],"batl":[[1,28,12.35]],"ltp":4.7,"tv":9.99,"id":14904499},{"batb":[[1,1.05,866.76],[2,1.01,0.51]],"batl":[[0,1.13,286.64],[1,1.17,292.15]],"ltp":1.58,"tv":62.69,"id":14904498},{"batb":[[0,22,7.72],[1,18,14.24],[2,1.01,0.51]],"ltp":12.5,"tv":0.16,"id":20912772}]}]}
{"op":"mcm","clk":"1003376846","pt":1580606931656,"mc":[{"id":"1.168179121","rc":[{"batb":[[0,10,26.28],[1,1.01,0.51],[2,1.01,0]],"batl":[[0,28,12.35],[1,28,0]],"ltp":4.7,"tv":9.99,"id":14904499},{"batb":[[0,1.05,866.76],[1,1.01,0.51],[2,1.01,0]],"batl":[[0,1.17,292.15],[1,1.17,0]],"ltp":1.58,"tv":62.69,"id":14904498},{"batb":[[0,18,14.24],[1,1.01,0.51],[2,1.01,0]],"ltp":12.5,"tv":0.16,"id":20912772}]}]}
{"op":"mcm","clk":"1003377977","pt":1580606944773,"mc":[{"id":"1.168179121","rc":[{"batb":[[1,8.4,17.07],[2,1.01,0.51]],"batl":[[0,13.5,24.08],[1,21,10.23],[2,28,12.35]],"ltp":4.7,"tv":9.99,"id":14904499},{"batb":[[0,1.13,380.11],[1,1.07,648.1],[2,1.05,866.76]],"batl":[[1,1.22,258.16]],"ltp":1.58,"tv":62.69,"id":14904498},{"batb":[[1,15,11.25],[2,1.01,0.51]],"batl":[[0,28,12.98]],"ltp":12.5,"tv":0.16,"id":20912772}]}]}
{"op":"mcm","clk":"1003377996","pt":1580606944982,"mc":[{"id":"1.168179121","rc":[{"batl":[[2,28,0]],"ltp":4.7,"tv":9.99,"id":14904499},{"batb":[[2,1.01,0.51]],"ltp":1.58,"tv":62.69,"id":14904498}]}]}
{"op":"mcm","clk":"1003379438","pt":1580606962358,"mc":[{"id":"1.168179121","rc":[{"batb":[[0,8.4,17.07],[1,1.01,0.51],[2,1.01,0]],"batl":[[0,21,10.23],[1,21,0]],"ltp":4.7,"tv":9.99,"id":14904499},{"batb":[[0,1.07,648.1],[1,1.01,0.51],[2,1.01,0]],"batl":[[0,1.22,258.16],[1,1.22,0]],"ltp":1.58,"tv":62.69,"id":14904498},{"batb":[[0,15,11.25],[1,1.01,0.51],[2,1.01,0]],"ltp":12.5,"tv":0.16,"id":20912772}]}]}
{"op":"mcm","clk":"1003380955","pt":1580606982595,"mc":[{"id":"1.168179121","rc":[{"batb":[[1,6.6,28.25],[2,1.01,0.51]],"batl":[[0,10.5,16.37],[1,15.5,18.18]],"ltp":4.7,"tv":9.99,"id":14904499},{"batb":[[0,1.18,273.73],[1,1.11,451.71],[2,1.01,0.51]],"batl":[[1,1.29,184.75]],"ltp":1.58,"tv":62.69,"id":14904498},{"batb":[[1,12,18.49],[2,1.01,0.51]],"batl":[[0,21,10.62]],"ltp":12.5,"tv":0.16,"id":20912772}]}]}
{"op":"mcm","clk":"1003382452","pt":1580607002111,"mc":[{"id":"1.168179121","rc":[{"batb":[[0,6.6,28.25],[1,1.01,0.51],[2,1.01,0]],"batl":[[0,15.5,18.18],[1,15.5,0]],"ltp":4.7,"tv":9.99,"id":14904499},{"batb":[[0,1.11,451.71],[1,1.01,0.51],[2,1.01,0]],"batl":[[0,1.29,184.75],[1,1.29,0]],"ltp":1.58,"tv":62.69,"id":14904498},{"batb":[[0,12,18.49],[1,1.01,0.51],[2,1.01,0]],"ltp":12.5,"tv":0.16,"id":20912772}]}]}
{"op":"mcm","clk":"1003382722","pt":1580607005212,"mc":[{"id":"1.168179121","rc":[{"batb":[[0,1.11,441.72]],"batl":[[0,1.3,180.58]],"ltp":1.58,"tv":62.69,"id":14904498},{"batb":[[0,11.5,19.12]],"ltp":12.5,"tv":0.16,"id":20912772}]}]}
{"op":"mcm","clk":"1003383196","pt":1580607010854,"mc":[{"id":"1.168179121","rc":[{"batb":[[1,5.7,39.81],[2,1.01,0.51]],"batl":[[0,7.8,27.46],[1,10,17],[2,15.5,18.18]],"ltp":4.7,"tv":9.99,"id":14904499},{"batb":[[0,1.24,188.84],[1,1.18,267.83],[2,1.11,441.72]],"batl":[[1,1.35,144.54]],"ltp":1.58,"tv":62.69,"id":14904498},{"batb":[[1,10,26.04],[2,1.01,0.51]],"batl":[[0,16,17.7],[1,21,10.78]],"ltp":12.5,"tv":0.16,"id":20912772}]}]}
{"op":"mcm","clk":"1003383229","pt":1580607011111,"mc":[{"id":"1.168179121","rc":[{"batl":[[2,15.5,0]],"ltp":4.7,"tv":9.99,"id":14904499},{"batb":[[2,1.01,0.51]],"ltp":1.58,"tv":62.69,"id":14904498}]}]}
{"op":"mcm","clk":"1003384415","pt":1580607025842,"mc":[{"id":"1.168179121","rc":[{"batb":[[0,5.7,39.81],[1,1.01,0.51],[2,1.01,0]],"batl":[[0,10,17],[1,10,0]],"ltp":4.7,"tv":9.99,"id":14904499},{"batb":[[0,1.18,267.83],[1,1.01,0.51],[2,1.01,0]],"batl":[[0,1.35,144.54],[1,1.35,0]],"ltp":1.58,"tv":62.69,"id":14904498},{"batb":[[0,10,26.04],[1,1.01,0.51],[2,1.01,0]],"batl":[[0,21,10.78],[1,21,0]],"ltp":12.5,"tv":0.16,"id":20912772}]}]}
{"op":"mcm","clk":"1003384655","pt":1580607028839,"mc":[{"id":"1.168179121","rc":[{"batb":[[0,10.5,25.81],[1,10,26.04],[2,1.01,0.51]],"ltp":12.5,"tv":0.16,"id":20912772}]}]}
{"op":"mcm","clk":"1003384670","pt":1580607029046,"mc":[{"id":"1.168179121","rc":[{"batb":[[1,1.01,0.51],[2,1.01,0]],"ltp":12.5,"tv":0.16,"id":20912772}]}]}
{"op":"mcm","clk":"1003385186","pt":1580607035854,"mc":[{"id":"1.168179121","rc":[{"batb":[[0,8.2,17.86],[1,6.6,28.33],[2,1.01,0.51]],"batl":[[1,15.5,18.8]],"ltp":4.7,"tv":9.99,"id":14904499},{"batb":[[1,1.11,444.47],[2,1.01,0.51]],"batl":[[0,1.23,253.12],[1,1.29,184.82]],"ltp":1.58,"tv":62.69,"id":14904498},{"batb":[[0,15,11.33],[1,12,18.41],[2,1.01,0.51]],"ltp":12.5,"tv":0.16,"id":20912772}]}]}
{"op":"mcm","clk":"1003386598","pt":1580607053398,"mc":[{"id":"1.168179121","rc":[{"batb":[[0,6.6,28.33],[1,1.01,0.51],[2,1.01,0]],"batl":[[0,15.5,18.8],[1,15.5,0]],"ltp":4.7,"tv":9.99,"id":14904499},{"batb":[[0,1.11,444.47],[1,1.01,0.51],[2,1.01,0]],"batl":[[0,1.29,184.82],[1,1.29,0]],"ltp":1.58,"tv":62.69,"id":14904498},{"batb":[[0,12,18.41],[1,1.01,0.51],[2,1.01,0]],"ltp":12.5,"tv":0.16,"id":20912772}]}]}
{"op":"mcm","clk":"1003388377","pt":1580607075724,"mc":[{"id":"1.168179121","rc":[{"batl":[[0,17,79.84]],"ltp":12.5,"tv":0.16,"id":20912772}]}]}
{"op":"mcm","clk":"1003388480","pt":1580607076818,"mc":[{"id":"1.168179121","rc":[{"batb":[[1,5.8,39.81],[2,1.01,0.51]],"batl":[[0,8,26.75],[1,10.5,16.44]],"ltp":4.7,"tv":9.99,"id":14904499},{"batb":[[0,1.24,193.48],[1,1.18,272.08],[2,1.01,0.51]],"batl":[[1,1.35,146.51]],"ltp":1.58,"tv":62.69,"id":14904498},{"batb":[[1,10.5,24.71],[2,1.01,0.51]],"batl":[[0,16,17.07],[1,21,10.7]],"ltp":12.5,"tv":0.16,"id":20912772}]}]}
{"op":"mcm","clk":"1003390064","pt":1580607096736,"mc":[{"id":"1.168179121","rc":[{"batb":[[0,5.8,39.81],[1,1.01,0.51],[2,1.01,0]],"batl":[[0,10.5,16.44],[1,10.5,0]],"ltp":4.7,"tv":9.99,"id":14904499},{"batb":[[0,1.18,272.08],[1,1.01,0.51],[2,1.01,0]],"batl":[[0,1.35,146.51],[1,1.35,0]],"ltp":1.58,"tv":62.69,"id":14904498},{"batb":[[0,10.5,24.71],[1,1.01,0.51],[2,1.01,0]],"batl":[[0,21,10.7],[1,21,0]],"ltp":12.5,"tv":0.16,"id":20912772}]}]}
{"op":"mcm","clk":"1003390321","pt":1580607099840,"mc":[{"id":"1.168179121","rc":[{"batb":[[0,6,36.67],[1,5.8,39.81],[2,1.01,0.51]],"ltp":4.7,"tv":9.99,"id":14904499},{"batb":[[1,1.17,288.29],[2,1.01,0.51]],"batl":[[0,1.33,155.48],[1,1.35,146.51]],"ltp":1.58,"tv":62.69,"id":14904498},{"batb":[[0,11,22.9],[1,10.5,24.71],[2,1.01,0.51]],"batl":[[1,22,9.91]],"ltp":12.5,"tv":0.16,"id":20912772}]}]}
{"op":"mcm","clk":"1003390352","pt":1580607100252,"mc":[{"id":"1.168179121","rc":[{"batb":[[1,1.01,0.51],[2,1.01,0]],"batl":[[0,10.5,15.11]],"ltp":4.7,"tv":9.99,"id":14904499},{"batb":[[0,1.17,288.29],[1,1.01,0.51],[2,1.01,0]],"batl":[[1,1.35,0]],"ltp":1.58,"tv":62.69,"id":14904498},{"batb":[[1,1.01,0.51],[2,1.01,0]],"batl":[[0,22,9.91],[1,22,0]],"ltp":12.5,"tv":0.16,"id":20912772}]}]}
{"op":"mcm","clk":"1003391432","pt":1580607113557,"mc":[{"id":"1.168179121","rc":[{"batb":[[1,5,27.46],[2,1.01,0.51]],"batl":[[0,7.2,34.31],[1,7.8,28.25]],"ltp":4.7,"tv":9.99,"id":14904499},{"batb":[[0,1.28,161.93],[1,1.25,186.48],[2,1.01,0.51]],"batl":[[1,1.43,111.65]],"ltp":1.58,"tv":62.69,"id":14904498},{"batb":[[1,9,14.4],[2,1.01,0.51]],"batl":[[0,14.5,21.01],[1,16,17.7]],"ltp":12.5,"tv":0.16,"id":20912772}]}]}
{"op":"mcm","clk":"1003397243","pt":1580607193783,"mc":[{"id":"1.168179121","rc":[{"batb":[[0,5,27.46],[1,1.01,0.51],[2,1.01,0]],"batl":[[0,7.8,28.25],[1,7.8,0]],"ltp":4.7,"tv":9.99,"id":14904499},{"batb":[[0,1.25,186.48],[1,1.01,0.51],[2,1.01,0]],"batl":[[0,1.43,111.65],[1,1.43,0]],"ltp":1.58,"tv":62.69,"id":14904498},{"batb":[[0,9,14.4],[1,1.01,0.51],[2,1.01,0]],"batl":[[0,16,17.7],[1,16,0]],"ltp":12.5,"tv":0.16,"id":20912772}]}]}
{"op":"mcm","clk":"1003397453","pt":1580607196688,"mc":[{"id":"1.168179121","rc":[{"batl":[[0,15.5,17.94],[1,16,17.7]],"ltp":12.5,"tv":0.16,"id":20912772}]}]}
{"op":"mcm","clk":"1003397470","pt":1580607196997,"mc":[{"id":"1.168179121","rc":[{"batb":[[0,1.25,184.9]],"batl":[[0,1.43,110.71]],"ltp":1.58,"tv":62.69,"id":14904498},{"batl":[[1,16,0]],"ltp":12.5,"tv":0.16,"id":20912772}]}]}
{"op":"mcm","clk":"1003397747","pt":1580607200775,"mc":[{"id":"1.168179121","rc":[{"batb":[[0,6.4,30.37],[1,5.5,21.79],[2,1.01,0.51]],"batl":[[1,8.2,25.02]],"ltp":4.7,"tv":9.99,"id":14904499},{"batb":[[1,1.23,205.52],[2,1.01,0.51]],"batl":[[0,1.3,176.88],[1,1.37,135.49]],"ltp":1.58,"tv":62.69,"id":14904498},{"batb":[[0,11.5,19.36],[1,10,28.17],[2,1.01,0.51]],"batl":[[1,17,15.19]],"ltp":12.5,"tv":0.16,"id":20912772}]}]}
{"op":"mcm","clk":"1003398484","pt":1580607211717,"mc":[{"id":"1.168179121","rc":[{"batb":[[0,5.5,21.79],[1,1.01,0.51],[2,1.01,0]],"batl":[[0,8.2,25.02],[1,8.2,0]],"ltp":4.7,"tv":9.99,"id":14904499},{"batb":[[0,1.23,205.52],[1,1.01,0.51],[2,1.01,0]],"batl":[[0,1.37,135.49],[1,1.37,0]],"ltp":1.58,"tv":62.69,"id":14904498},{"batb":[[0,10,28.17],[1,1.01,0.51],[2,1.01,0]],"batl":[[0,17,15.19],[1,17,0]],"ltp":12.5,"tv":0.16,"id":20912772}]}]}
{"op":"mcm","clk":"1003399334","pt":1580607223703,"mc":[{"id":"1.168179121","rc":[{"batb":[[1,4.4,36.43],[2,1.01,0.51]],"batl":[[0,6.6,40.52],[1,7.4,31.63],[2,8.2,25.02]],"ltp":4.7,"tv":9.99,"id":14904499},{"batb":[[0,1.31,140.53],[1,1.27,170.9],[2,1.23,205.52]],"batl":[[1,1.51,89.23]],"ltp":1.58,"tv":62.69,"id":14904498},{"batb":[[1,8.2,17.94],[2,1.01,0.51]],"batl":[[0,13,25.65],[1,15,19.91],[2,17,15.19]],"ltp":12.5,"tv":0.16,"id":20912772}]}]}
{"op":"mcm","clk":"1003399351","pt":1580607224008,"mc":[{"id":"1.168179121","rc":[{"batl":[[2,8.2,0]],"ltp":4.7,"tv":9.99,"id":14904499},{"batb":[[2,1.01,0.51]],"ltp":1.58,"tv":62.69,"id":14904498},{"batl":[[2,17,0]],"ltp":12.5,"tv":0.16,"id":20912772}]}]}
{"op":"mcm","clk":"1003400126","pt":1580607234717,"mc":[{"id":"1.168179121","rc":[{"batb":[[0,4.4,36.43],[1,1.01,0.51],[2,1.01,0]],"batl":[[0,7.4,31.63],[1,7.4,0]],"ltp":4.7,"tv":9.99,"id":14904499},{"batb":[[0,1.27,170.9],[1,1.01,0.51],[2,1.01,0]],"batl":[[0,1.51,89.23],[1,1.51,0]],"ltp":1.58,"tv":62.69,"id":14904498},{"batb":[[0,8.2,17.94],[1,1.01,0.51],[2,1.01,0]],"batl":[[0,15,19.91],[1,15,0]],"ltp":12.5,"tv":0.16,"id":20912772}]}]}
{"op":"mcm","clk":"1003402532","pt":1580607265389,"mc":[{"id":"1.168179121","rc":[{"batb":[[0,6.2,33.75],[1,5.2,25.02],[2,1.01,0.51]],"batl":[[1,8.2,26.04]],"ltp":4.7,"tv":9.99,"id":14904499},{"batb":[[1,1.23,198.2],[2,1.01,0.51]],"batl":[[0,1.32,163.82],[1,1.41,119.6]],"ltp":1.58,"tv":62.69,"id":14904498},{"batb":[[0,11,21.64],[1,9.2,33.44],[2,1.01,0.51]],"batl":[[1,16.5,16.29]],"ltp":12.5,"tv":0.16,"id":20912772}]}]}
{"op":"mcm","clk":"1003404328","pt":1580607291524,"mc":[{"id":"1.168179121","rc":[{"batb":[[0,5.2,25.02],[1,1.01,0.51],[2,1.01,0]],"batl":[[0,8.2,26.04],[1,8.2,0]],"ltp":4.7,"tv":9.99,"id":14904499},{"batb":[[0,1.23,198.2],[1,1.01,0.51],[2,1.01,0]],"batl":[[0,1.41,119.6],[1,1.41,0]],"ltp":1.58,"tv":62.69,"id":14904498},{"batb":[[0,9.2,33.44],[1,1.01,0.51],[2,1.01,0]],"batl":[[0,16.5,16.29],[1,16.5,0]],"ltp":12.5,"tv":0.16,"id":20912772}]}]}
{"op":"mcm","clk":"1003405675","pt":1580607309632,"mc":[{"id":"1.168179121","rc":[{"batb":[[0,6.8,27.62],[1,6,35.64],[2,1.01,0.51]],"batl":[[1,8.6,23.53]],"ltp":4.7,"tv":9.99,"id":14904499},{"batb":[[1,1.22,214.49],[2,1.01,0.51]],"batl":[[0,1.29,189.23],[1,1.33,155.4]],"ltp":1.58,"tv":62.69,"id":14904498},{"batb":[[0,12,17.55],[1,10.5,24.08],[2,1.01,0.51]],"batl":[[1,17.5,14.4]],"ltp":12.5,"tv":0.16,"id":20912772}]}]}
{"op":"mcm","clk":"1003406647","pt":1580607321820,"mc":[{"id":"1.168179121","rc":[{"batb":[[0,6,35.64],[1,1.01,0.51],[2,1.01,0]],"batl":[[0,8.6,23.53],[1,8.6,0]],"ltp":4.7,"tv":9.99,"id":14904499},{"batb":[[0,1.22,214.49],[1,1.01,0.51],[2,1.01,0]],"batl":[[0,1.33,155.4],[1,1.33,0]],"ltp":1.58,"tv":62.69,"id":14904498},{"batb":[[0,10.5,24.08],[1,1.01,0.51],[2,1.01,0]],"batl":[[0,17.5,14.4],[1,17.5,0]],"ltp":12.5,"tv":0.16,"id":20912772}]}]}
{"op":"mcm","clk":"1003407596","pt":1580607332897,"mc":[{"id":"1.168179121","rc":[{"batb":[[0,7,24.86],[1,6,34.46],[2,1.01,0.51]],"batl":[[1,11,14.48]],"ltp":4.7,"tv":9.99,"id":14904499},{"batb":[[1,1.16,299.78],[2,1.01,0.51]],"batl":[[0,1.27,204.18],[1,1.32,163.03]],"ltp":1.58,"tv":62.69,"id":14904498},{"batb":[[0,13,15.42],[1,11,21.32],[2,1.01,0.51]],"batl":[[1,23,9.05]],"ltp":12.5,"tv":0.16,"id":20912772}]}]}
{"op":"mcm","clk":"1003410021","pt":1580607365310,"mc":[{"id":"1.168179121","rc":[{"batb":[[0,6,34.46],[1,1.01,0.51],[2,1.01,0]],"batl":[[0,11,14.48],[1,11,0]],"ltp":4.7,"tv":9.99,"id":14904499},{"batb":[[0,1.16,299.78],[1,1.01,0.51],[2,1.01,0]],"batl":[[0,1.32,163.03],[1,1.32,0]],"ltp":1.58,"tv":62.69,"id":14904498},{"batb":[[0,11,21.32],[1,1.01,0.51],[2,1.01,0]],"batl":[[0,23,9.05],[1,23,0]],"ltp":12.5,"tv":0.16,"id":20912772}]}]}
{"op":"mcm","clk":"1003410891","pt":1580607377144,"mc":[{"id":"1.168179121","rc":[{"batb":[[0,8.8,15.11],[1,7.2,23.6],[2,1.01,0.51]],"batl":[[1,16,17.55]],"ltp":4.7,"tv":9.99,"id":14904499},{"batb":[[1,1.1,471.86],[2,1.01,0.51]],"batl":[[0,1.21,281.52],[1,1.26,210.95]],"ltp":1.58,"tv":62.69,"id":14904498},{"batb":[[0,16,9.6],[1,13,14.87],[2,1.01,0.51]],"ltp":12.5,"tv":0.16,"id":20912772}]}]}
{"op":"mcm","clk":"1003412042","pt":1580607392340,"mc":[{"id":"1.168179121","rc":[{"batb":[[0,7.2,23.6],[1,1.01,0.51],[2,1.01,0]],"batl":[[0,16,17.55],[1,16,0]],"ltp":4.7,"tv":9.99,"id":14904499},{"batb":[[0,1.1,471.86],[1,1.01,0.51],[2,1.01,0]],"batl":[[0,1.26,210.95],[1,1.26,0]],"ltp":1.58,"tv":62.69,"id":14904498},{"batb":[[0,13,14.87],[1,1.01,0.51],[2,1.01,0]],"ltp":12.5,"tv":0.16,"id":20912772}]}]}
{"op":"mcm","clk":"1003413373","pt":1580607410891,"mc":[{"id":"1.168179121","rc":[{"batb":[[1,6,34.62],[2,1.01,0.51]],"batl":[[0,8.8,22.35],[1,12,30.14]],"ltp":4.7,"tv":9.99,"id":14904499},{"batb":[[0,1.21,221.88],[1,1.15,334.4],[2,1.01,0.51]],"batl":[[1,1.32,162.71]],"ltp":1.58,"tv":62.69,"id":14904498},{"batb":[[1,11,21.24],[2,1.01,0.51]],"batl":[[0,18,13.85],[1,26,14.79]],"ltp":12.5,"tv":0.16,"id":20912772}]}]}
{"op":"mcm","clk":"1003414637","pt":1580607428118,"mc":[{"id":"1.168179121","rc":[{"batb":[[0,6,34.62],[1,1.01,0.51],[2,1.01,0]],"batl":[[0,12,30.14],[1,12,0]],"ltp":4.7,"tv":9.99,"id":14904499},{"batb":[[0,1.15,334.4],[1,1.01,0.51],[2,1.01,0]],"batl":[[0,1.32,162.71],[1,1.32,0]],"ltp":1.58,"tv":62.69,"id":14904498},{"batb":[[0,11,21.24],[1,1.01,0.51],[2,1.01,0]],"batl":[[0,26,14.79],[1,26,0]],"ltp":12.5,"tv":0.16,"id":20912772}]}]}
{"op":"mcm","clk":"1003415280","pt":1580607437807,"mc":[{"id":"1.168179121","rc":[{"batb":[[1,5.4,22.58],[2,1.01,0.51]],"batl":[[0,7.2,32.42],[1,9,20.93]],"ltp":4.7,"tv":9.99,"id":14904499},{"batb":[[0,1.27,169.64],[1,1.2,234.31],[2,1.01,0.51]],"batl":[[1,1.38,132.11]],"ltp":1.58,"tv":62.69,"id":14904498},{"batb":[[1,10,28.01],[2,1.01,0.51]],"batl":[[0,15,19.59],[1,19,12.67]],"ltp":12.5,"tv":0.16,"id":20912772}]}]}
{"op":"mcm","clk":"1003416129","pt":1580607450231,"mc":[{"id":"1.168179121","rc":[{"batb":[[0,5.4,22.58],[1,1.01,0.51],[2,1.01,0]],"batl":[[0,9,20.93],[1,9,0]],"ltp":4.7,"tv":9.99,"id":14904499},{"batb":[[0,1.2,234.31],[1,1.01,0.51],[2,1.01,0]],"batl":[[0,1.38,132.11],[1,1.38,0]],"ltp":1.58,"tv":62.69,"id":14904498},{"batb":[[0,10,28.01],[1,1.01,0.51],[2,1.01,0]],"batl":[[0,19,12.67],[1,19,0]],"ltp":12.5,"tv":0.16,"id":20912772}]}]}
{"op":"mcm","clk":"1003417267","pt":1580607465668,"mc":[{"id":"1.168179121","rc":[{"batb":[[0,7.4,22.03],[1,6,36.67],[2,1.01,0.51]],"batl":[[1,14,22.35]],"ltp":4.7,"tv":9.99,"id":14904499},{"batb":[[1,1.12,407.89],[2,1.01,0.51]],"batl":[[0,1.25,222.36],[1,1.33,157.91]],"ltp":1.58,"tv":62.69,"id":14904498},{"batb":[[0,13.5,13.45],[1,11,21.4],[2,1.01,0.51]],"batl":[[1,30,10.94]],"ltp":12.5,"tv":0.16,"id":20912772}]}]}
{"op":"mcm","clk":"1003419162","pt":1580607489890,"mc":[{"id":"1.168179121","rc":[{"batb":[[0,6,36.67],[1,1.01,0.51],[2,1.01,0]],"batl":[[0,14,22.35],[1,14,0]],"ltp":4.7,"tv":9.99,"id":14904499},{"batb":[[0,1.12,407.89],[1,1.01,0.51],[2,1.01,0]],"batl":[[0,1.33,157.91],[1,1.33,0]],"ltp":1.58,"tv":62.69,"id":14904498},{"batb":[[0,11,21.4],[1,1.01,0.51],[2,1.01,0]],"batl":[[0,30,10.94],[1,30,0]],"ltp":12.5,"tv":0.16,"id":20912772}]}]}
{"op":"mcm","clk":"1003420288","pt":1580607506214,"mc":[{"id":"1.168179121","rc":[{"batb":[[1,5.2,24.78],[2,1.01,0.51]],"batl":[[0,7.2,34.31],[1,9.2,20.38]],"ltp":4.7,"tv":9.99,"id":14904499},{"batb":[[0,1.27,164.52],[1,1.2,239.9],[2,1.01,0.51]],"batl":[[1,1.4,124.4]],"ltp":1.58,"tv":62.69,"id":14904498},{"batb":[[1,9.8,29.43],[2,1.01,0.51]],"batl":[[0,15,19.75],[1,19.5,12.04]],"ltp":12.5,"tv":0.16,"id":20912772}]}]}
{"op":"mcm","clk":"1003421810","pt":1580607527725,"mc":[{"id":"1.168179121","rc":[{"batb":[[0,5.2,24.78],[1,1.01,0.51],[2,1.01,0]],"batl":[[0,9.2,20.38],[1,9.2,0]],"ltp":4.7,"tv":9.99,"id":14904499},{"batb":[[0,1.2,239.9],[1,1.01,0.51],[2,1.01,0]],"batl":[[0,1.4,124.4],[1,1.4,0]],"ltp":1.58,"tv":62.69,"id":14904498},{"batb":[[0,9.8,29.43],[1,1.01,0.51],[2,1.01,0]],"batl":[[0,19.5,12.04],[1,19.5,0]],"ltp":12.5,"tv":0.16,"id":20912772}]}]}
{"op":"mcm","clk":"1003422528","pt":1580607538422,"mc":[{"id":"1.168179121","rc":[{"batb":[[1,4.3,39.97],[2,1.01,0.51]],"batl":[[0,6,23.84],[1,6.8,38.55]],"ltp":4.7,"tv":9.99,"id":14904499},{"batb":[[0,1.34,128.72],[1,1.3,150.05],[2,1.01,0.51]],"batl":[[1,1.53,84.82]],"ltp":1.58,"tv":62.69,"id":14904498},{"batb":[[1,8.2,17.78],[2,1.01,0.51]],"batl":[[0,13,26.75],[1,14,22.27]],"ltp":12.5,"tv":0.16,"id":20912772}]}]}
{"op":"mcm","clk":"1003423096","pt":1580607546844,"mc":[{"id":"1.168179121","rc":[{"batb":[[1,4.2,40.29]],"ltp":4.7,"tv":9.99,"id":14904499},{"batb":[[0,1.33,130.69],[1,1.29,152.25]],"batl":[[0,1.39,126.21],[1,1.52,86.16]],"ltp":1.58,"tv":62.69,"id":14904498},{"batb":[[0,10,27.54],[1,8.4,16.68]],"batl":[[0,13,25.1],[1,14.5,20.85]],"ltp":12.5,"tv":0.16,"id":20912772}]}]}
{"op":"mcm","clk":"1003423301","pt":1580607549740,"mc":[{"id":"1.168179121","rc":[{"batb":[[0,1.35,323.87],[1,1.33,130.69],[2,1.29,152.25]],"ltp":1.58,"tv":62.69,"id":14904498},{"batb":[[0,10,67.62]],"ltp":12.5,"tv":0.16,"id":20912772}]}]}
{"op":"mcm","clk":"1003424024","pt":1580607559765,"mc":[{"id":"1.168179121","rc":[{"batl":[[1,6.6,38.95]],"ltp":4.7,"tv":9.99,"id":14904499},{"batb":[[1,1.33,130.22],[2,1.29,151.78]],"batl":[[0,1.39,125.73],[1,1.52,85.84]],"ltp":1.58,"tv":62.69,"id":14904498}]}]}
{"op":"mcm","clk":"1003425379","pt":1580607575880,"mc":[{"id":"1.168179121","rc":[{"batb":[[1,1.34,129.35],[2,1.33,130.22]],"batl":[[1,1.4,124.95],[2,1.52,85.84]],"ltp":1.58,"tv":62.69,"id":14904498}]}]}
{"op":"mcm","clk":"1003425393","pt":1580607576085,"mc":[{"id":"1.168179121","rc":[{"batb":[[2,1.3,150.75]],"batl":[[0,1.4,124.95],[1,1.53,85.29],[2,1.52,0]],"ltp":1.58,"tv":62.69,"id":14904498}]}]}
{"op":"mcm","clk":"1003429470","pt":1580607629123,"mc":[{"id":"1.168179121","rc":[{"batb":[[0,4.2,40.29],[1,1.01,0.51],[2,1.01,0]],"batl":[[0,6.6,38.95],[1,6.6,0]],"ltp":4.7,"tv":9.99,"id":14904499},{"batb":[[0,1.3,150.75],[1,1.01,0.51],[2,1.3,0]],"batl":[[0,1.53,85.29],[1,1.53,0]],"ltp":1.58,"tv":62.69,"id":14904498},{"batb":[[0,8.4,16.68],[1,1.01,0.51],[2,1.01,0]],"batl":[[0,14.5,20.85],[1,14.5,0]],"ltp":12.5,"tv":0.16,"id":20912772}]}]}
{"op":"mcm","clk":"1003430376","pt":1580607640254,"mc":[{"id":"1.168179121","rc":[{"batb":[[0,5.6,21.09],[1,4.8,29.66],[2,1.01,0.51]],"batl":[[1,7.2,33.91]],"ltp":4.7,"tv":9.99,"id":14904499},{"batb":[[1,1.27,170.19],[2,1.01,0.51]],"batl":[[0,1.35,145.09],[1,1.44,109.29]],"ltp":1.58,"tv":62.69,"id":14904498},{"batb":[[0,11,22.98],[1,9.2,33.83],[2,1.01,0.51]],"batl":[[1,16,17.78]],"ltp":12.5,"tv":0.16,"id":20912772}]}]}
{"op":"mcm","clk":"1003431691","pt":1580607656886,"mc":[{"id":"1.168179121","rc":[{"batb":[[0,4.8,29.66],[1,1.01,0.51],[2,1.01,0]],"batl":[[0,7.2,33.91],[1,7.2,0]],"ltp":4.7,"tv":9.99,"id":14904499},{"batb":[[0,1.27,170.19],[1,1.01,0.51],[2,1.01,0]],"batl":[[0,1.44,109.29],[1,1.44,0]],"ltp":1.58,"tv":62.69,"id":14904498},{"batb":[[0,9.2,33.83],[1,1.01,0.51],[2,1.01,0]],"batl":[[0,16,17.78],[1,16,0]],"ltp":12.5,"tv":0.16,"id":20912772}]}]}
{"op":"mcm","clk":"1003432261","pt":1580607664775,"mc":[{"id":"1.168179121","rc":[{"batb":[[0,6,36.19],[1,5.4,22.74],[2,1.01,0.51]],"batl":[[1,7.6,30.45]],"ltp":4.7,"tv":9.99,"id":14904499},{"batb":[[1,1.25,185.85],[2,1.01,0.51]],"batl":[[0,1.32,163.19],[1,1.38,133.68]],"ltp":1.58,"tv":62.69,"id":14904498},{"batb":[[0,11.5,19.2],[1,10,26.44],[2,1.01,0.51]],"batl":[[1,17,15.5]],"ltp":12.5,"tv":0.16,"id":20912772}]}]}
{"op":"mcm","clk":"1003433286","pt":1580607677395,"mc":[{"id":"1.168179121","rc":[{"batb":[[0,5.4,22.74],[1,1.01,0.51],[2,1.01,0]],"batl":[[0,7.6,30.45],[1,7.6,0]],"ltp":4.7,"tv":9.99,"id":14904499},{"batb":[[0,1.25,185.85],[1,1.01,0.51],[2,1.01,0]],"batl":[[0,1.38,133.68],[1,1.38,0]],"ltp":1.58,"tv":62.69,"id":14904498},{"batb":[[0,10,26.44],[1,1.01,0.51],[2,1.01,0]],"batl":[[0,17,15.5],[1,17,0]],"ltp":12.5,"tv":0.16,"id":20912772}]}]}
{"op":"mcm","clk":"1003433726","pt":1580607683525,"mc":[{"id":"1.168179121","rc":[{"batb":[[0,6.2,32.42],[1,5.8,38.48],[2,1.01,0.51]],"batl":[[0,7.6,29.43]],"ltp":4.7,"tv":9.99,"id":14904499},{"batb":[[1,1.24,192.69],[2,1.01,0.51]],"batl":[[0,1.3,177.74],[1,1.34,154.77]],"ltp":1.58,"tv":62.69,"id":14904498},{"batb":[[0,12.5,16.68],[1,11,21.24],[2,1.01,0.51]],"batl":[[1,17.5,14.32]],"ltp":12.5,"tv":0.16,"id":20912772}]}]}
{"op":"mcm","clk":"1003434704","pt":1580607696504,"mc":[{"id":"1.168179121","rc":[{"batb":[[0,5.8,38.48],[1,1.01,0.51],[2,1.01,0]],"ltp":4.7,"tv":9.99,"id":14904499},{"batb":[[0,1.24,192.69],[1,1.01,0.51],[2,1.01,0]],"batl":[[0,1.34,154.77],[1,1.34,0]],"ltp":1.58,"tv":62.69,"id":14904498},{"batb":[[0,11,21.24],[1,1.01,0.51],[2,1.01,0]],"batl":[[0,17.5,14.32],[1,17.5,0]],"ltp":12.5,"tv":0.16,"id":20912772}]}]}
{"op":"mcm","clk":"1003436165","pt":1580607715644,"mc":[{"id":"1.168179121","rc":[{"batb":[[0,6.4,31.32],[1,5.6,21.56],[2,1.01,0.51]],"batl":[[1,10,17.07]],"ltp":4.7,"tv":9.99,"id":14904499},{"batb":[[1,1.17,282.63],[2,1.01,0.51]],"batl":[[0,1.29,184.12],[1,1.35,145.8]],"ltp":1.58,"tv":62.69,"id":14904498},{"batb":[[0,13,15.34],[1,11,21.24],[2,1.01,0.51]],"batl":[[1,24,8.42]],"ltp":12.5,"tv":0.16,"id":20912772}]}]}
{"op":"mcm","clk":"1003438740","pt":1580607747513,"mc":[{"id":"1.168179121","rc":[{"batb":[[0,5.6,21.56],[1,1.01,0.51],[2,1.01,0]],"batl":[[0,10,17.07],[1,10,0]],"ltp":4.7,"tv":9.99,"id":14904499},{"batb":[[0,1.17,282.63],[1,1.01,0.51],[2,1.01,0]],"batl":[[0,1.35,145.8],[1,1.35,0]],"ltp":1.58,"tv":62.69,"id":14904498},{"batb":[[0,11,21.24],[1,1.01,0.51],[2,1.01,0]],"batl":[[0,24,8.42],[1,24,0]],"ltp":12.5,"tv":0.16,"id":20912772}]}]}
{"op":"mcm","clk":"1003441008","pt":1580607776558,"mc":[{"id":"1.168179121","rc":[{"batb":[[0,8.2,17.94],[1,6.6,28.95],[2,1.01,0.51]],"batl":[[1,15.5,18.8]],"ltp":4.7,"tv":9.99,"id":14904499},{"batb":[[1,1.1,474.77],[2,1.01,0.51]],"batl":[[0,1.22,266.1],[1,1.28,194.42]],"ltp":1.58,"tv":62.69,"id":14904498},{"batb":[[0,16.5,8.89],[1,13.5,14.16],[2,1.01,0.51]],"ltp":12.5,"tv":0.16,"id":20912772}]}]}
{"op":"mcm","clk":"1003442781","pt":1580607800695,"mc":[{"id":"1.168179121","rc":[{"batb":[[0,6.6,28.95],[1,1.01,0.51],[2,1.01,0]],"batl":[[0,15.5,18.8],[1,15.5,0]],"ltp":4.7,"tv":9.99,"id":14904499},{"batb":[[0,1.1,474.77],[1,1.01,0.51],[2,1.01,0]],"batl":[[0,1.28,194.42],[1,1.28,0]],"ltp":1.58,"tv":62.69,"id":14904498},{"batb":[[0,13.5,14.16],[1,1.01,0.51],[2,1.01,0]],"ltp":12.5,"tv":0.16,"id":20912772}]}]}
{"op":"mcm","clk":"1003443874","pt":1580607816798,"mc":[{"id":"1.168179121","rc":[{"batb":[[0,11.5,20.38],[1,8.8,14.87],[2,6.6,28.95]],"batl":[[1,30,11.33]],"ltp":4.7,"tv":9.99,"id":14904499},{"batb":[[1,1.05,975.73],[2,1.01,0.51]],"batl":[[0,1.15,310.09],[1,1.2,301.98],[2,1.28,194.42]],"ltp":1.58,"tv":62.69,"id":14904498},{"batb":[[0,23,6.89],[1,18,14.48],[2,13.5,14.16]],"ltp":12.5,"tv":0.16,"id":20912772}]}]}
{"op":"mcm","clk":"1003443891","pt":1580607817004,"mc":[{"id":"1.168179121","rc":[{"batb":[[2,1.01,0.51]],"ltp":4.7,"tv":9.99,"id":14904499},{"batl":[[2,1.28,0]],"ltp":1.58,"tv":62.69,"id":14904498},{"batb":[[2,1.01,0.51]],"ltp":12.5,"tv":0.16,"id":20912772}]}]}
{"op":"mcm","clk":"1003446018","pt":1580607844611,"mc":[{"id":"1.168179121","rc":[{"batb":[[0,8.8,14.87],[1,1.01,0.51],[2,1.01,0]],"batl":[[0,30,11.33],[1,30,0]],"ltp":4.7,"tv":9.99,"id":14904499},{"batb":[[0,1.05,975.73],[1,1.01,0.51],[2,1.01,0]],"batl":[[0,1.2,301.98],[1,1.2,0]],"ltp":1.58,"tv":62.69,"id":14904498},{"batb":[[0,18,14.48],[1,1.01,0.51],[2,1.01,0]],"ltp":12.5,"tv":0.16,"id":20912772}]}]}
{"op":"mcm","clk":"1003446600","pt":1580607851723,"mc":[{"id":"1.168179121","rc":[{"batb":[[1,6.8,27.07],[2,1.01,0.51]],"batl":[[0,11,14.24],[1,21,10.78]],"ltp":4.7,"tv":9.99,"id":14904499},{"batb":[[0,1.15,322.75],[1,1.07,661.01],[2,1.01,0.51]],"batl":[[1,1.27,203.79]],"ltp":1.58,"tv":62.69,"id":14904498},{"batb":[[1,14,13.14],[2,1.01,0.51]],"batl":[[0,27,13.14]],"ltp":12.5,"tv":0.16,"id":20912772}]}]}
{"op":"mcm","clk":"1003447564","pt":1580607864547,"mc":[{"id":"1.168179121","rc":[{"batb":[[0,6.8,27.07],[1,1.01,0.51],[2,1.01,0]],"batl":[[0,21,10.78],[1,21,0]],"ltp":4.7,"tv":9.99,"id":14904499},{"batb":[[0,1.07,661.01],[1,1.01,0.51],[2,1.01,0]],"batl":[[0,1.27,203.79],[1,1.27,0]],"ltp":1.58,"tv":62.69,"id":14904498},{"batb":[[0,14,13.14],[1,1.01,0.51],[2,1.01,0]],"ltp":12.5,"tv":0.16,"id":20912772}]}]}
{"op":"mcm","clk":"1003449316","pt":1580607889276,"mc":[{"id":"1.168179121","rc":[{"batb":[[0,14.5,11.49],[1,10,26.75],[2,1.01,0.51]],"ltp":4.7,"tv":9.99,"id":14904499},{"batb":[[1,1.02,2000.25],[2,1.01,0.51]],"batl":[[0,1.11,285.62],[1,1.17,306.15]],"ltp":1.58,"tv":62.69,"id":14904498},{"batb":[[0,27,6.7],[1,20,10.86],[2,1.01,0.51]],"ltp":12.5,"tv":0.16,"id":20912772}]}]}
{"op":"mcm","clk":"1003451033","pt":1580607911328,"mc":[{"id":"1.168179121","rc":[{"batb":[[0,10,26.75],[1,1.01,0.51],[2,1.01,0]],"ltp":4.7,"tv":9.99,"id":14904499},{"batb":[[0,1.02,2000.25],[1,1.01,0.51],[2,1.01,0]],"batl":[[0,1.17,306.15],[1,1.17,0]],"ltp":1.58,"tv":62.69,"id":14904498},{"batb":[[0,20,10.86],[1,1.01,0.51],[2,1.01,0]],"ltp":12.5,"tv":0.16,"id":20912772}]}]}
{"op":"mcm","clk":"1003452669","pt":1580607932538,"mc":[{"id":"1.168179121","rc":[{"batb":[[0,30,3.58],[1,19.5,11.72],[2,1.01,0.51]],"ltp":4.7,"tv":9.99,"id":14904499},{"batl":[[0,1.09,311.58]],"ltp":1.58,"tv":62.69,"id":14904498},{"batb":[[0,30,2.71]],"ltp":12.5,"tv":0.16,"id":20912772}]}]}
{"op":"mcm","clk":"1003458293","pt":1580608011531,"mc":[{"id":"1.168179121","rc":[{"batb":[[0,19.5,11.72],[1,1.01,0.51],[2,1.01,0]],"ltp":4.7,"tv":9.99,"id":14904499},{"batb":[[0,1.01,0.51],[1,1.01,0]],"ltp":1.58,"tv":62.69,"id":14904498}]}]}
{"op":"mcm","clk":"1003460795","pt":1580608044475,"mc":[{"id":"1.168179121","rc":[{"batb":[[0,26,7.99]],"ltp":4.7,"tv":9.99,"id":14904499},{"batl":[[0,1.06,245.02]],"ltp":1.58,"tv":62.69,"id":14904498},{"batb":[[0,1.01,0.51],[1,1.01,0]],"ltp":12.5,"tv":0.16,"id":20912772}]}]}
{"op":"mcm","clk":"1003462517","pt":1580608069728,"mc":[{"id":"1.168179121","rc":[{"batb":[[0,30,6.29]],"ltp":4.7,"tv":9.99,"id":14904499},{"batl":[[0,1.06,795.08]],"ltp":1.58,"tv":62.69,"id":14904498}]}]}
{"op":"mcm","clk":"1003465604","pt":1580608111379,"mc":[{"id":"1.168179121","rc":[{"batb":[[0,1.01,0.51],[1,1.01,0]],"ltp":4.7,"tv":9.99,"id":14904499}]}]}
{"op":"mcm","clk":"1003477287","pt":1580608275882,"mc":[{"id":"1.168179121","marketDefinition":{"bspMarket":false,"turnInPlayEnabled":true,"persistenceEnabled":true,"marketBaseRate":5.0,"eventId":"29680182","eventTypeId":"2","numberOfWinners":1,"bettingType":"ODDS","marketType":"SET_BETTING","marketTime":"2020-02-02T00:32:00.000Z","suspendTime":"2020-02-02T00:32:00.000Z","bspReconciled":false,"complete":true,"inPlay":true,"crossMatching":true,"runnersVoidable":false,"numberOfActiveRunners":4,"betDelay":3,"status":"SUSPENDED","runners":[{"status":"ACTIVE","sortPriority":1,"id":20912771,"name":"Meligeni Rodrigues Alve 2-0"},{"status":"ACTIVE","sortPriority":2,"id":20912772,"name":"Meligeni Rodrigues Alve 2-1"},{"status":"ACTIVE","sortPriority":3,"id":14904498,"name":"T Monteiro 2-0"},{"status":"ACTIVE","sortPriority":4,"id":14904499,"name":"T Monteiro 2-1"}],"regulators":["MR_INT"],"countryCode":"UY","discountAllowed":true,"timezone":"UTC","openDate":"2020-02-02T00:32:00.000Z","version":3148025539,"name":"Set Betting","eventName":"Meligeni Rodrigues Alve v T Monteiro"}}]}
{"op":"mcm","clk":"1003479445","pt":1580608309319,"mc":[{"id":"1.168179121","tv":0.0}]}
{"op":"mcm","clk":"1003479482","pt":1580608310056,"mc":[{"id":"1.168179121","marketDefinition":{"bspMarket":false,"turnInPlayEnabled":true,"persistenceEnabled":true,"marketBaseRate":5.0,"eventId":"29680182","eventTypeId":"2","numberOfWinners":1,"bettingType":"ODDS","marketType":"SET_BETTING","marketTime":"2020-02-02T00:32:00.000Z","suspendTime":"2020-02-02T00:32:00.000Z","bspReconciled":false,"complete":true,"inPlay":true,"crossMatching":false,"runnersVoidable":false,"numberOfActiveRunners":0,"betDelay":3,"status":"CLOSED","settledTime":"2020-02-02T01:51:48.000Z","runners":[{"status":"LOSER","sortPriority":1,"id":20912771,"name":"Meligeni Rodrigues Alve 2-0"},{"status":"LOSER","sortPriority":2,"id":20912772,"name":"Meligeni Rodrigues Alve 2-1"},{"status":"WINNER","sortPriority":3,"id":14904498,"name":"T Monteiro 2-0"},{"status":"LOSER","sortPriority":4,"id":14904499,"name":"T Monteiro 2-1"}],"regulators":["MR_INT"],"countryCode":"UY","discountAllowed":true,"timezone":"UTC","openDate":"2020-02-02T00:32:00.000Z","version":3148026043,"name":"Set Betting","eventName":"Meligeni Rodrigues Alve v T Monteiro"}}]}
