{"op":"mcm","clk":"992350394","pt":1580520342496,"mc":[{"id":"1.168179120","marketDefinition":{"bspMarket":false,"turnInPlayEnabled":true,"persistenceEnabled":true,"marketBaseRate":5.0,"eventId":"29680182","eventTypeId":"2","numberOfWinners":1,"bettingType":"ODDS","marketType":"MATCH_ODDS","marketTime":"2020-02-02T00:00:00.000Z","suspendTime":"2020-02-02T00:00:00.000Z","bspReconciled":false,"complete":true,"inPlay":false,"crossMatching":false,"runnersVoidable":false,"numberOfActiveRunners":2,"betDelay":0,"status":"OPEN","runners":[{"status":"ACTIVE","sortPriority":1,"id":9712909,"name":"Felipe Meligeni Rodrigu"},{"status":"ACTIVE","sortPriority":2,"id":8326656,"name":"Thiago Monteiro"}],"regulators":["MR_INT"],"countryCode":"UY","discountAllowed":false,"timezone":"UTC","openDate":"2020-02-02T00:00:00.000Z","version":3144293949,"name":"Match Odds","eventName":"Meligeni Rodrigues Alve v T Monteiro"},"rc":[{"batb":[[0,1.03,190.07],[1,1.02,217.33],[2,1.01,282.92]],"ltp":0.0,"tv":0.0,"id":8326656},{"batb":[[0,1.01,282.92]],"ltp":0.0,"tv":0.0,"id":9712909}]}]}
{"op":"mcm","clk":"992350445","pt":1580520343901,"mc":[{"id":"1.168179120","marketDefinition":{"bspMarket":false,"turnInPlayEnabled":true,"persistenceEnabled":true,"marketBaseRate":5.0,"eventId":"29680182","eventTypeId":"2","numberOfWinners":1,"bettingType":"ODDS","marketType":"MATCH_ODDS","marketTime":"2020-02-02T00:00:00.000Z","suspendTime":"2020-02-02T00:00:00.000Z","bspReconciled":false,"complete":true,"inPlay":false,"crossMatching":false,"runnersVoidable":false,"numberOfActiveRunners":2,"betDelay":0,"status":"OPEN","runners":[{"status":"ACTIVE","sortPriority":1,"id":9712909,"name":"Felipe Meligeni Rodrigu"},{"status":"ACTIVE","sortPriority":2,"id":8326656,"name":"Thiago Monteiro"}],"regulators":["MR_INT"],"countryCode":"UY","discountAllowed":true,"timezone":"UTC","openDate":"2020-02-02T00:00:00.000Z","version":3144293949,"name":"Match Odds","eventName":"Meligeni Rodrigues Alve v T Monteiro"}}]}
{"op":"mcm","clk":"992351704","pt":1580520393080,"mc":[{"id":"1.168179120","rc":[{"batb":[[0,1.01,582.92]],"ltp":0.0,"tv":0.0,"id":9712909}]}]}
{"op":"mcm","clk":"992351749","pt":1580520394574,"mc":[{"id":"1.168179120","rc":[{"batb":[[2,1.01,582.92]],"ltp":0.0,"tv":0.0,"id":8326656}]}]}
{"op":"mcm","clk":"992351814","pt":1580520397417,"mc":[{"id":"1.168179120","rc":[{"batb":[[0,1.01,282.92]],"ltp":0.0,"tv":0.0,"id":9712909}]}]}
{"op":"mcm","clk":"992351841","pt":1580520398924,"mc":[{"id":"1.168179120","rc":[{"batb":[[2,1.01,282.92]],"ltp":0.0,"tv":0.0,"id":8326656}]}]}
{"op":"mcm","clk":"992357859","pt":1580520615740,"mc":[{"id":"1.168179120","rc":[{"batb":[[2,1.01,272.92]],"ltp":0.0,"tv":0.0,"id":8326656},{"batb":[[0,1.01,272.92]],"ltp":0.0,"tv":0.0,"id":9712909}]}]}
{"op":"mcm","clk":"992365782","pt":1580520912460,"mc":[{"id":"1.168179120","rc":[{"batl":[[0,990,1.51]],"ltp":0.0,"tv":0.0,"id":8326656},{"batl":[[0,990,1.51]],"ltp":0.0,"tv":0.0,"id":9712909}]}]}
{"op":"mcm","clk":"992366223","pt":1580520929573,"mc":[{"id":"1.168179120","rc":[{"batb":[[0,1.03,237.77],[1,1.02,271.85],[2,1.01,336.52]],"ltp":0.0,"tv":0.0,"id":8326656},{"batb":[[0,1.01,336.52]],"ltp":0.0,"tv":0.0,"id":9712909}]}]}
{"op":"mcm","clk":"992366849","pt":1580520958367,"mc":[{"id":"1.168179120","marketDefinition":{"bspMarket":false,"turnInPlayEnabled":true,"persistenceEnabled":true,"marketBaseRate":5.0,"eventId":"29680182","eventTypeId":"2","numberOfWinners":1,"bettingType":"ODDS","marketType":"MATCH_ODDS","marketTime":"2020-02-02T00:00:00.000Z","suspendTime":"2020-02-02T00:00:00.000Z","bspReconciled":false,"complete":true,"inPlay":false,"crossMatching":true,"runnersVoidable":false,"numberOfActiveRunners":2,"betDelay":0,"status":"OPEN","runners":[{"status":"ACTIVE","sortPriority":1,"id":9712909,"name":"Felipe Meligeni Rodrigu"},{"status":"ACTIVE","sortPriority":2,"id":8326656,"name":"Thiago Monteiro"}],"regulators":["MR_INT"],"countryCode":"UY","discountAllowed":true,"timezone":"UTC","openDate":"2020-02-02T00:00:00.000Z","version":3144293949,"name":"Match Odds","eventName":"Meligeni Rodrigues Alve v T Monteiro"}}]}
{"op":"mcm","clk":"992379535","pt":1580521090812,"mc":[{"id":"1.168179120","rc":[{"batb":[[0,1.04,75.72],[1,1.03,237.77],[2,1.02,271.85]],"ltp":0.0,"tv":0.0,"id":8326656},{"batb":[[0,1.02,151.45],[1,1.01,336.52]],"ltp":0.0,"tv":0.0,"id":9712909}]}]}
{"op":"mcm","clk":"992421961","pt":1580522445766,"mc":[{"id":"1.168179120","rc":[{"batb":[[2,1.02,297.05]],"ltp":0.0,"tv":0.0,"id":8326656},{"batb":[[0,1.03,8.4],[1,1.02,176.65],[2,1.01,336.52]],"ltp":0.0,"tv":0.0,"id":9712909}]}]}
{"op":"mcm","clk":"992421966","pt":1580522445971,"mc":[{"id":"1.168179120","rc":[{"batb":[[1,1.03,246.17]],"ltp":0.0,"tv":0.0,"id":8326656}]}]}
{"op":"mcm","clk":"992424979","pt":1580522532662,"mc":[{"id":"1.168179120","rc":[{"batb":[[0,1.04,75.72],[1,1.03,8.4],[2,1.02,25.21]],"ltp":0.0,"tv":0.0,"id":9712909}]}]}
{"op":"mcm","clk":"992450057","pt":1580523140351,"mc":[{"id":"1.168179120","rc":[{"batl":[[0,990,3.71]],"ltp":0.0,"tv":0.0,"id":8326656},{"batl":[[0,990,3.71]],"ltp":0.0,"tv":0.0,"id":9712909}]}]}
{"op":"mcm","clk":"992905850","pt":1580532862256,"mc":[{"id":"1.168179120","rc":[{"batl":[[0,25,3.43],[1,990,3.71]],"ltp":0.0,"tv":0.0,"id":8326656}]}]}
{"op":"mcm","clk":"993024511","pt":1580535201673,"mc":[{"id":"1.168179120","rc":[{"batb":[[0,1.09,75.72],[1,1.04,75.72],[2,1.03,246.17]],"ltp":0.0,"tv":0.0,"id":8326656},{"batb":[[0,1.13,75.72],[1,1.04,75.72],[2,1.03,8.4]],"ltp":0.0,"tv":0.0,"id":9712909}]}]}
{"op":"mcm","clk":"993028934","pt":1580535301537,"mc":[{"id":"1.168179120","rc":[{"batb":[[0,1.09,75.92]],"ltp":0.0,"tv":0.0,"id":8326656},{"batb":[[1,1.04,75.92]],"ltp":0.0,"tv":0.0,"id":9712909}]}]}
{"op":"mcm","clk":"993029350","pt":1580535310753,"mc":[{"id":"1.168179120","rc":[{"batl":[[2,1000,0.02]],"ltp":0.0,"tv":0.0,"id":8326656},{"batl":[[1,1000,0.02]],"ltp":0.0,"tv":0.0,"id":9712909}]}]}
{"op":"mcm","clk":"993029362","pt":1580535311017,"mc":[{"id":"1.168179120","rc":[{"batb":[[0,1.09,76.02],[1,1.04,76.22]],"ltp":0.0,"tv":0.0,"id":8326656},{"batb":[[0,1.13,75.82],[1,1.04,76.42]],"ltp":0.0,"tv":0.0,"id":9712909}]}]}
{"op":"mcm","clk":"993029408","pt":1580535311936,"mc":[{"id":"1.168179120","rc":[{"batb":[[0,1.15,182.64],[1,1.09,75.92],[2,1.04,76.22]],"ltp":0.0,"tv":0.0,"id":8326656},{"batb":[[0,4.5,10],[1,1.13,75.82],[2,1.04,76.42]],"ltp":0.0,"tv":0.0,"id":9712909}]}]}
{"op":"mcm","clk":"993033019","pt":1580535397163,"mc":[{"id":"1.168179120","rc":[{"batb":[[0,1.13,210.72]],"ltp":0.0,"tv":0.0,"id":8326656},{"batb":[[0,5,10]],"ltp":0.0,"tv":0.0,"id":9712909}]}]}
{"op":"mcm","clk":"993034364","pt":1580535432171,"mc":[{"id":"1.168179120","rc":[{"batl":[[0,1.75,3.03],[1,25,3.43],[2,990,3.71]],"ltp":0.0,"tv":0.0,"id":8326656}]}]}
{"op":"mcm","clk":"993052333","pt":1580535607364,"mc":[{"id":"1.168179120","rc":[{"batb":[[1,1.99,4],[2,1.13,75.82]],"ltp":0.0,"tv":0.0,"id":9712909}]}]}
{"op":"mcm","clk":"993052510","pt":1580535610973,"mc":[{"id":"1.168179120","rc":[{"batb":[[2,1.05,4]],"ltp":0.0,"tv":0.0,"id":8326656}]}]}
{"op":"mcm","clk":"993075260","pt":1580536089221,"mc":[{"id":"1.168179120","rc":[{"batb":[[0,1.1,274.11],[1,1.09,75.72]],"ltp":0.0,"tv":0.0,"id":8326656},{"batb":[[0,5.5,10]],"ltp":0.0,"tv":0.0,"id":9712909}]}]}
{"op":"mcm","clk":"993111697","pt":1580536704146,"mc":[{"id":"1.168179120","rc":[{"batb":[[0,1.11,75.82],[1,1.1,274.01]],"ltp":0.0,"tv":0.0,"id":8326656}]}]}
{"op":"mcm","clk":"993151545","pt":1580537436855,"mc":[{"id":"1.168179120","rc":[{"batl":[[1,10,3.43]],"ltp":0.0,"tv":0.0,"id":8326656}]}]}
{"op":"mcm","clk":"993176824","pt":1580538004792,"mc":[{"id":"1.168179120","rc":[{"batb":[[0,1.11,82.11]],"ltp":0.0,"tv":0.0,"id":8326656}]}]}
{"op":"mcm","clk":"993215849","pt":1580538703538,"mc":[{"id":"1.168179120","rc":[{"batb":[[2,1.08,213.5]],"ltp":0.0,"tv":0.0,"id":8326656},{"batb":[[1,4.1,213.5],[2,1.99,4]],"ltp":0.0,"tv":0.0,"id":9712909}]}]}
{"op":"mcm","clk":"993215975","pt":1580538707644,"mc":[{"id":"1.168179120","rc":[{"batb":[[1,4.1,216.82]],"ltp":0.0,"tv":0.0,"id":9712909}]}]}
{"op":"mcm","clk":"993222673","pt":1580538870110,"mc":[{"id":"1.168179120","rc":[{"batb":[[1,1.1,320.96]],"ltp":0.0,"tv":0.0,"id":8326656},{"batb":[[1,4.7,11.36],[2,4.1,216.82]],"ltp":0.0,"tv":0.0,"id":9712909}]}]}
{"op":"mcm","clk":"993222816","pt":1580538873507,"mc":[{"id":"1.168179120","rc":[{"batb":[[2,4.1,223.86]],"ltp":0.0,"tv":0.0,"id":9712909}]}]}
{"op":"mcm","clk":"993247499","pt":1580539253350,"mc":[{"id":"1.168179120","rc":[{"batb":[[0,1.11,6.39]],"ltp":0.0,"tv":0.0,"id":8326656}]}]}
{"op":"mcm","clk":"993253065","pt":1580539377030,"mc":[{"id":"1.168179120","rc":[{"trd":[[1.2,0.1]],"batb":[[0,1.11,6.29],[1,1.1,47.15],[2,1.08,555.76]],"ltp":1.2,"tv":0.1,"id":8326656},{"trd":[[6,0.02]],"batb":[[0,6,9.98]],"ltp":6.0,"tv":0.02,"id":9712909}],"tv":0.12}]}
{"op":"mcm","clk":"993253203","pt":1580539380221,"mc":[{"id":"1.168179120","rc":[{"batb":[[2,4.1,227.06]],"ltp":6.0,"tv":0.02,"id":9712909}]}]}
{"op":"mcm","clk":"993253300","pt":1580539382030,"mc":[{"id":"1.168179120","rc":[{"batb":[[0,6,10]],"ltp":6.0,"tv":0.02,"id":9712909}]}]}
{"op":"mcm","clk":"993255225","pt":1580539428579,"mc":[{"id":"1.168179120","rc":[{"batb":[[1,4.8,11.36]],"ltp":6.0,"tv":0.02,"id":9712909}]}]}
{"op":"mcm","clk":"993256110","pt":1580539447169,"mc":[{"id":"1.168179120","rc":[{"batb":[[1,1.1,320.96],[2,1.08,213.5]],"ltp":1.2,"tv":0.1,"id":8326656},{"batb":[[0,5.5,10]],"ltp":6.0,"tv":0.02,"id":9712909}]}]}
{"op":"mcm","clk":"993258578","pt":1580539502270,"mc":[{"id":"1.168179120","rc":[{"batb":[[1,1.1,47.15],[2,1.08,555.76]],"ltp":1.2,"tv":0.1,"id":8326656},{"batb":[[0,6,10]],"ltp":6.0,"tv":0.02,"id":9712909}]}]}
{"op":"mcm","clk":"993261968","pt":1580539580689,"mc":[{"id":"1.168179120","rc":[{"batb":[[1,4.8,15.14]],"ltp":6.0,"tv":0.02,"id":9712909}]}]}
{"op":"mcm","clk":"993261994","pt":1580539581158,"mc":[{"id":"1.168179120","rc":[{"batb":[[1,1.1,62.29]],"ltp":1.2,"tv":0.1,"id":8326656}]}]}
{"op":"mcm","clk":"993271296","pt":1580539762277,"mc":[{"id":"1.168179120","rc":[{"batb":[[1,1.1,28.22]],"ltp":1.2,"tv":0.1,"id":8326656},{"batb":[[1,4.8,6.82]],"ltp":6.0,"tv":0.02,"id":9712909}]}]}
{"op":"mcm","clk":"993279437","pt":1580539944623,"mc":[{"id":"1.168179120","rc":[{"batb":[[1,4.8,15.14]],"ltp":6.0,"tv":0.02,"id":9712909}]}]}
{"op":"mcm","clk":"993279457","pt":1580539945135,"mc":[{"id":"1.168179120","rc":[{"batb":[[1,1.1,62.29]],"ltp":1.2,"tv":0.1,"id":8326656}]}]}
{"op":"mcm","clk":"993325098","pt":1580540666753,"mc":[{"id":"1.168179120","rc":[{"batb":[[1,1.1,28.22]],"ltp":1.2,"tv":0.1,"id":8326656},{"batb":[[1,4.8,6.82]],"ltp":6.0,"tv":0.02,"id":9712909}]}]}
{"op":"mcm","clk":"993325343","pt":1580540673384,"mc":[{"id":"1.168179120","rc":[{"batb":[[1,4.9,6.82]],"ltp":6.0,"tv":0.02,"id":9712909}]}]}
{"op":"mcm","clk":"993332649","pt":1580540848770,"mc":[{"id":"1.168179120","rc":[{"batb":[[1,1.1,62.29]],"ltp":1.2,"tv":0.1,"id":8326656},{"batb":[[1,4.9,13.63]],"ltp":6.0,"tv":0.02,"id":9712909}]}]}
{"op":"mcm","clk":"993359305","pt":1580541230851,"mc":[{"id":"1.168179120","rc":[{"batb":[[1,5,13.63]],"ltp":6.0,"tv":0.02,"id":9712909}]}]}
{"op":"mcm","clk":"993367525","pt":1580541388745,"mc":[{"id":"1.168179120","rc":[{"batb":[[1,4.9,13.63]],"ltp":6.0,"tv":0.02,"id":9712909}]}]}
{"op":"mcm","clk":"993369549","pt":1580541422281,"mc":[{"id":"1.168179120","rc":[{"batb":[[0,1.1,62.29],[1,1.08,555.76],[2,1.05,4]],"ltp":1.2,"tv":0.1,"id":8326656}]}]}
{"op":"mcm","clk":"993415037","pt":1580542070248,"mc":[{"id":"1.168179120","rc":[{"batb":[[1,5.1,13.63]],"ltp":6.0,"tv":0.02,"id":9712909}]}]}
{"op":"mcm","clk":"993421788","pt":1580542180412,"mc":[{"id":"1.168179120","rc":[{"batl":[[0,1.17,2],[1,1.75,3.03],[2,10,3.43]],"ltp":1.2,"tv":0.1,"id":8326656}]}]}
{"op":"mcm","clk":"993465641","pt":1580542660591,"mc":[{"id":"1.168179120","rc":[{"batb":[[0,1.12,16.66],[1,1.08,555.96]],"ltp":1.2,"tv":0.1,"id":8326656},{"batb":[[1,5.9,13.63]],"ltp":6.0,"tv":0.02,"id":9712909}]}]}
{"op":"mcm","clk":"993475582","pt":1580542829811,"mc":[{"id":"1.168179120","rc":[{"batb":[[0,1.12,35.59]],"ltp":1.2,"tv":0.1,"id":8326656},{"batb":[[1,5.9,16.66]],"ltp":6.0,"tv":0.02,"id":9712909}]}]}
{"op":"mcm","clk":"993655112","pt":1580544980115,"mc":[{"id":"1.168179120","rc":[{"batl":[[1,1.7,3.03]],"ltp":1.2,"tv":0.1,"id":8326656}]}]}
{"op":"mcm","clk":"993825344","pt":1580546720937,"mc":[{"id":"1.168179120","rc":[{"batb":[[1,4.1,227.06],[2,1.99,4]],"ltp":6.0,"tv":0.02,"id":9712909}]}]}
{"op":"mcm","clk":"993849683","pt":1580547020624,"mc":[{"id":"1.168179120","rc":[{"batb":[[0,1.08,555.96],[1,1.05,4],[2,1.04,76.22]],"ltp":1.2,"tv":0.1,"id":8326656}]}]}
{"op":"mcm","clk":"993911837","pt":1580547628844,"mc":[{"id":"1.168179120","rc":[{"batb":[[1,5.7,18.17],[2,4.1,227.06]],"ltp":6.0,"tv":0.02,"id":9712909}]}]}
{"op":"mcm","clk":"993911850","pt":1580547629052,"mc":[{"id":"1.168179120","rc":[{"batb":[[0,1.12,44.68],[1,1.08,555.96],[2,1.05,4]],"ltp":1.2,"tv":0.1,"id":8326656}]}]}
{"op":"mcm","clk":"994249634","pt":1580550573919,"mc":[{"id":"1.168179120","rc":[{"batl":[[0,95,15.9],[1,990,3.71],[2,1000,0.02]],"ltp":6.0,"tv":0.02,"id":9712909}]}]}
{"op":"mcm","clk":"994302834","pt":1580550939701,"mc":[{"id":"1.168179120","rc":[{"batb":[[0,1.08,555.96],[1,1.05,4],[2,1.04,76.22]],"ltp":1.2,"tv":0.1,"id":8326656}]}]}
{"op":"mcm","clk":"994302861","pt":1580550939915,"mc":[{"id":"1.168179120","rc":[{"batb":[[0,1.12,90.87],[1,1.08,555.96],[2,1.05,4]],"ltp":1.2,"tv":0.1,"id":8326656}]}]}
{"op":"mcm","clk":"994426378","pt":1580551765744,"mc":[{"id":"1.168179120","rc":[{"batb":[[0,1.13,6.09],[1,1.12,90.87],[2,1.08,555.96]],"ltp":1.2,"tv":0.1,"id":8326656}]}]}
{"op":"mcm","clk":"995229162","pt":1580555984254,"mc":[{"id":"1.168179120","rc":[{"batl":[[2,95,15.9]],"ltp":1.2,"tv":0.1,"id":8326656}]}]}
{"op":"mcm","clk":"995597060","pt":1580557693206,"mc":[{"id":"1.168179120","rc":[{"trd":[[1.13,5.07]],"batb":[[0,1.13,3.55]],"ltp":1.13,"tv":5.16,"id":8326656}],"tv":5.18}]}
{"op":"mcm","clk":"995707462","pt":1580558341818,"mc":[{"id":"1.168179120","rc":[{"batl":[[2,95,15.95]],"ltp":1.13,"tv":5.16,"id":8326656}]}]}
{"op":"mcm","clk":"996270604","pt":1580561292822,"mc":[{"id":"1.168179120","rc":[{"batb":[[1,1.08,555.96],[2,1.05,4]],"ltp":1.13,"tv":5.16,"id":8326656}]}]}
{"op":"mcm","clk":"996413633","pt":1580562047798,"mc":[{"id":"1.168179120","rc":[{"batb":[[1,1.12,90.87],[2,1.08,555.96]],"ltp":1.13,"tv":5.16,"id":8326656},{"batb":[[0,6,28.17],[1,4.1,227.06],[2,1.99,4]],"ltp":6.0,"tv":0.02,"id":9712909}]}]}
{"op":"mcm","clk":"996414092","pt":1580562049972,"mc":[{"id":"1.168179120","rc":[{"batb":[[1,4.1,213.5]],"ltp":6.0,"tv":0.02,"id":9712909}]}]}
{"op":"mcm","clk":"996940719","pt":1580564447351,"mc":[{"id":"1.168179120","rc":[{"batl":[[1,990,2.2]],"ltp":6.0,"tv":0.02,"id":9712909}]}]}
{"op":"mcm","clk":"997041043","pt":1580564948383,"mc":[{"id":"1.168179120","rc":[{"batb":[[0,1.14,128],[1,1.13,3.55],[2,1.12,90.87]],"ltp":1.13,"tv":5.16,"id":8326656}]}]}
{"op":"mcm","clk":"997041274","pt":1580564949795,"mc":[{"id":"1.168179120","rc":[{"batb":[[0,6,31.76]],"ltp":6.0,"tv":0.02,"id":9712909}]}]}
{"op":"mcm","clk":"997251581","pt":1580566110372,"mc":[{"id":"1.168179120","rc":[{"batb":[[0,1.15,3.55],[1,1.14,128]],"ltp":1.13,"tv":5.16,"id":8326656}]}]}
{"op":"mcm","clk":"997592853","pt":1580567453894,"mc":[{"id":"1.168179120","rc":[{"trd":[[1.15,3.36]],"batb":[[0,1.15,1.87]],"ltp":1.15,"tv":8.53,"id":8326656}],"tv":8.55}]}
{"op":"mcm","clk":"997842307","pt":1580568458177,"mc":[{"id":"1.168179120","rc":[{"batb":[[2,1.08,555.96]],"ltp":1.15,"tv":8.53,"id":8326656}]}]}
{"op":"mcm","clk":"997911950","pt":1580568765690,"mc":[{"id":"1.168179120","rc":[{"batb":[[2,1.08,213.7]],"ltp":1.15,"tv":8.53,"id":8326656},{"batb":[[0,6.4,10],[1,6,21.76],[2,4.1,213.5]],"ltp":6.0,"tv":0.02,"id":9712909}]}]}
{"op":"mcm","clk":"998022207","pt":1580569251563,"mc":[{"id":"1.168179120","rc":[{"batb":[[2,1.1,93.34]],"ltp":1.15,"tv":8.53,"id":8326656},{"batb":[[1,6.2,18.17],[2,6,3.59]],"ltp":6.0,"tv":0.02,"id":9712909}]}]}
{"op":"mcm","clk":"998023313","pt":1580569256754,"mc":[{"id":"1.168179120","rc":[{"batb":[[2,1.11,93.14]],"ltp":1.15,"tv":8.53,"id":8326656},{"batb":[[1,6,3.59],[2,4.1,213.5]],"ltp":6.0,"tv":0.02,"id":9712909}]}]}
{"op":"mcm","clk":"998023973","pt":1580569259711,"mc":[{"id":"1.168179120","rc":[{"batb":[[2,1.11,15.9]],"ltp":1.15,"tv":8.53,"id":8326656}]}]}
{"op":"mcm","clk":"998024156","pt":1580569260300,"mc":[{"id":"1.168179120","rc":[{"batb":[[2,1.1,16.1]],"ltp":1.15,"tv":8.53,"id":8326656},{"batb":[[1,6.2,15.9],[2,6,3.59]],"ltp":6.0,"tv":0.02,"id":9712909}]}]}
{"op":"mcm","clk":"998037490","pt":1580569317671,"mc":[{"id":"1.168179120","rc":[{"batb":[[2,1.1,186.48]],"ltp":1.15,"tv":8.53,"id":8326656}]}]}
{"op":"mcm","clk":"998037695","pt":1580569318609,"mc":[{"id":"1.168179120","rc":[{"batb":[[2,1.1,93.34]],"ltp":1.15,"tv":8.53,"id":8326656}]}]}
{"op":"mcm","clk":"998331657","pt":1580570446956,"mc":[{"id":"1.168179120","rc":[{"batb":[[0,1.14,128],[1,1.1,93.34],[2,1.08,213.5]],"ltp":1.15,"tv":8.53,"id":8326656}]}]}
{"op":"mcm","clk":"998918084","pt":1580572816464,"mc":[{"id":"1.168179120","rc":[{"batb":[[1,1.1,367.15]],"ltp":1.15,"tv":8.53,"id":8326656}]}]}
{"op":"mcm","clk":"998924532","pt":1580572847489,"mc":[{"id":"1.168179120","rc":[{"batb":[[0,6.4,25.9],[1,6,3.59],[2,4.1,213.5]],"ltp":6.0,"tv":0.02,"id":9712909}]}]}
{"op":"mcm","clk":"998924959","pt":1580572849614,"mc":[{"id":"1.168179120","rc":[{"batb":[[1,4.1,213.5],[2,1.99,4]],"ltp":6.0,"tv":0.02,"id":9712909}]}]}
{"op":"mcm","clk":"998926007","pt":1580572855028,"mc":[{"id":"1.168179120","rc":[{"batb":[[0,6.4,32.7]],"ltp":6.0,"tv":0.02,"id":9712909}]}]}
{"op":"mcm","clk":"998946124","pt":1580572947748,"mc":[{"id":"1.168179120","rc":[{"batb":[[0,6.4,16.8],[1,6.2,15.9],[2,4.1,213.5]],"ltp":6.0,"tv":0.02,"id":9712909}]}]}
{"op":"mcm","clk":"998946520","pt":1580572949740,"mc":[{"id":"1.168179120","rc":[{"batb":[[0,6.4,10]],"ltp":6.0,"tv":0.02,"id":9712909}]}]}
{"op":"mcm","clk":"998988931","pt":1580573128828,"mc":[{"id":"1.168179120","rc":[{"batb":[[2,1.05,4]],"ltp":1.15,"tv":8.53,"id":8326656},{"batb":[[2,1.99,4]],"ltp":6.0,"tv":0.02,"id":9712909}]}]}
{"op":"mcm","clk":"999003338","pt":1580573185196,"mc":[{"id":"1.168179120","rc":[{"batb":[[1,1.1,580.68]],"ltp":1.15,"tv":8.53,"id":8326656},{"batb":[[2,4.8,213.53]],"ltp":6.0,"tv":0.02,"id":9712909}]}]}
{"op":"mcm","clk":"999078684","pt":1580573467562,"mc":[{"id":"1.168179120","rc":[{"batb":[[0,6.4,25.9],[1,4.8,213.53],[2,1.99,4]],"ltp":6.0,"tv":0.02,"id":9712909}]}]}
{"op":"mcm","clk":"999079307","pt":1580573469534,"mc":[{"id":"1.168179120","rc":[{"batb":[[0,6.4,30.81]],"ltp":6.0,"tv":0.02,"id":9712909}]}]}
{"op":"mcm","clk":"999440939","pt":1580574819753,"mc":[{"id":"1.168179120","rc":[{"batb":[[1,1.11,15.9],[2,1.1,487.54]],"ltp":1.15,"tv":8.53,"id":8326656},{"batb":[[0,6.4,14.91],[1,6.2,15.9],[2,4.8,213.53]],"ltp":6.0,"tv":0.02,"id":9712909}]}]}
{"op":"mcm","clk":"999442302","pt":1580574824864,"mc":[{"id":"1.168179120","rc":[{"batb":[[0,6.4,10]],"ltp":6.0,"tv":0.02,"id":9712909}]}]}
{"op":"mcm","clk":"999464024","pt":1580574907732,"mc":[{"id":"1.168179120","rc":[{"batb":[[1,1.11,92.38]],"ltp":1.15,"tv":8.53,"id":8326656}]}]}
{"op":"mcm","clk":"999918668","pt":1580577540815,"mc":[{"id":"1.168179120","rc":[{"batb":[[1,4.8,213.53],[2,1.99,4]],"ltp":6.0,"tv":0.02,"id":9712909}]}]}
{"op":"mcm","clk":"999918683","pt":1580577540921,"mc":[{"id":"1.168179120","rc":[{"batb":[[0,6.4,25.9]],"ltp":6.0,"tv":0.02,"id":9712909}]}]}
{"op":"mcm","clk":"999919441","pt":1580577546036,"mc":[{"id":"1.168179120","rc":[{"batb":[[0,6.4,34.93]],"ltp":6.0,"tv":0.02,"id":9712909}]}]}
{"op":"mcm","clk":"999949372","pt":1580577741633,"mc":[{"id":"1.168179120","rc":[{"batb":[[0,6.4,19.03],[1,6.2,15.9],[2,4.8,213.53]],"ltp":6.0,"tv":0.02,"id":9712909}]}]}
{"op":"mcm","clk":"999949926","pt":1580577745045,"mc":[{"id":"1.168179120","rc":[{"batb":[[0,6.4,10]],"ltp":6.0,"tv":0.02,"id":9712909}]}]}
{"op":"mcm","clk":"1000294832","pt":1580580000455,"mc":[{"id":"1.168179120","rc":[{"batb":[[2,1.1,624.44]],"ltp":1.15,"tv":8.53,"id":8326656}]}]}
{"op":"mcm","clk":"1000346375","pt":1580580361341,"mc":[{"id":"1.168179120","rc":[{"batb":[[1,6,15.9]],"ltp":6.0,"tv":0.02,"id":9712909}]}]}
{"op":"mcm","clk":"1000353253","pt":1580580408098,"mc":[{"id":"1.168179120","rc":[{"batb":[[1,6.2,15.9]],"ltp":6.0,"tv":0.02,"id":9712909}]}]}
{"op":"mcm","clk":"1000713277","pt":1580582758767,"mc":[{"id":"1.168179120","rc":[{"batl":[[0,1.16,10.6],[1,1.17,2],[2,1.7,3.03]],"ltp":1.15,"tv":8.53,"id":8326656}]}]}
{"op":"mcm","clk":"1000931219","pt":1580584012535,"mc":[{"id":"1.168179120","rc":[{"batl":[[2,1.5,90.87]],"ltp":1.15,"tv":8.53,"id":8326656}]}]}
{"op":"mcm","clk":"1000949709","pt":1580584101409,"mc":[{"id":"1.168179120","rc":[{"batb":[[0,1.14,130]],"ltp":1.15,"tv":8.53,"id":8326656}]}]}
{"op":"mcm","clk":"1001024278","pt":1580584474471,"mc":[{"id":"1.168179120","rc":[{"batb":[[1,6,15.9]],"ltp":6.0,"tv":0.02,"id":9712909}]}]}
{"op":"mcm","clk":"1001032024","pt":1580584515426,"mc":[{"id":"1.168179120","rc":[{"batb":[[1,6.2,15.9]],"ltp":6.0,"tv":0.02,"id":9712909}]}]}
{"op":"mcm","clk":"1001114398","pt":1580584957123,"mc":[{"id":"1.168179120","rc":[{"batb":[[1,1.12,136.8],[2,1.11,92.38]],"ltp":1.15,"tv":8.53,"id":8326656},{"batb":[[0,6.8,21.32],[1,6.4,10],[2,6.2,15.9]],"ltp":6.0,"tv":0.02,"id":9712909}]}]}
{"op":"mcm","clk":"1001114690","pt":1580584958729,"mc":[{"id":"1.168179120","rc":[{"batb":[[0,6.8,24.46]],"ltp":6.0,"tv":0.02,"id":9712909}]}]}
{"op":"mcm","clk":"1001240855","pt":1580585608821,"mc":[{"id":"1.168179120","rc":[{"batl":[[0,1.17,2],[1,1.5,90.87],[2,1.7,113.58]],"ltp":1.15,"tv":8.53,"id":8326656}]}]}
{"op":"mcm","clk":"1001242888","pt":1580585618551,"mc":[{"id":"1.168179120","rc":[{"batl":[[0,1.15,10.6],[1,1.17,2],[2,1.5,90.87]],"ltp":1.15,"tv":8.53,"id":8326656}]}]}
{"op":"mcm","clk":"1001387667","pt":1580586370899,"mc":[{"id":"1.168179120","rc":[{"trd":[[1.14,260]],"batb":[[0,1.12,136.8],[1,1.11,92.38],[2,1.1,624.44]],"batl":[[0,1.14,19.93],[1,1.15,10.6],[2,1.17,2]],"ltp":1.14,"tv":268.53,"id":8326656}],"tv":268.55}]}
{"op":"mcm","clk":"1001388897","pt":1580586378309,"mc":[{"id":"1.168179120","rc":[{"batb":[[0,1.13,149.93],[1,1.12,136.8],[2,1.11,92.38]],"ltp":1.14,"tv":268.53,"id":8326656}]}]}
{"op":"mcm","clk":"1001391742","pt":1580586396770,"mc":[{"id":"1.168179120","rc":[{"trd":[[1.14,299.86]],"batl":[[0,1.15,10.6],[1,1.17,2],[2,1.5,90.87]],"ltp":1.14,"tv":308.39,"id":8326656}],"tv":308.41}]}
{"op":"mcm","clk":"1001391849","pt":1580586397463,"mc":[{"id":"1.168179120","rc":[{"batl":[[1,1.17,606.27]],"ltp":1.14,"tv":308.39,"id":8326656}]}]}
{"op":"mcm","clk":"1001392089","pt":1580586399065,"mc":[{"id":"1.168179120","rc":[{"batb":[[1,1.12,116.71]],"ltp":1.14,"tv":308.39,"id":8326656},{"batb":[[0,7,3.09],[1,6.8,24.46],[2,6.4,10]],"ltp":6.0,"tv":0.02,"id":9712909}]}]}
{"op":"mcm","clk":"1001700412","pt":1580588116890,"mc":[{"id":"1.168179120","rc":[{"trd":[[1.15,3.4]],"batl":[[0,1.15,10.58]],"ltp":1.15,"tv":308.43,"id":8326656}],"tv":308.45}]}
{"op":"mcm","clk":"1001905601","pt":1580589244927,"mc":[{"id":"1.168179120","rc":[{"batl":[[0,1.14,6.08],[1,1.15,10.58],[2,1.17,606.27]],"ltp":1.15,"tv":308.43,"id":8326656}]}]}
{"op":"mcm","clk":"1001991517","pt":1580589766053,"mc":[{"id":"1.168179120","rc":[{"batl":[[1,1.15,138.58]],"ltp":1.15,"tv":308.43,"id":8326656}]}]}
{"op":"mcm","clk":"1001992397","pt":1580589771387,"mc":[{"id":"1.168179120","rc":[{"batb":[[1,6.8,21.32]],"ltp":6.0,"tv":0.02,"id":9712909}]}]}
{"op":"mcm","clk":"1001993081","pt":1580589775418,"mc":[{"id":"1.168179120","rc":[{"batb":[[0,1.13,277.93]],"ltp":1.15,"tv":308.43,"id":8326656}]}]}
{"op":"mcm","clk":"1001993315","pt":1580589776792,"mc":[{"id":"1.168179120","rc":[{"batb":[[0,7.6,3.15],[1,7,3.09],[2,6.8,21.32]],"ltp":6.0,"tv":0.02,"id":9712909}]}]}
{"op":"mcm","clk":"1002003924","pt":1580589842402,"mc":[{"id":"1.168179120","rc":[{"batb":[[0,7.8,5.02],[1,7.6,3.15],[2,6.4,10]],"ltp":6.0,"tv":0.02,"id":9712909}]}]}
{"op":"mcm","clk":"1002075206","pt":1580590293278,"mc":[{"id":"1.168179120","rc":[{"batb":[[2,1.11,176.82]],"ltp":1.15,"tv":308.43,"id":8326656},{"batb":[[2,6.6,8.44]],"ltp":6.0,"tv":0.02,"id":9712909}]}]}
{"op":"mcm","clk":"1002159555","pt":1580591025360,"mc":[{"id":"1.168179120","rc":[{"trd":[[1.14,300.86]],"batl":[[0,1.14,5.58]],"ltp":1.14,"tv":309.43,"id":8326656}],"tv":309.45}]}
{"op":"mcm","clk":"1002171320","pt":1580591128693,"mc":[{"id":"1.168179120","rc":[{"trd":[[1.14,312.02]],"batb":[[0,1.14,24.42],[1,1.13,277.93],[2,1.12,116.71]],"batl":[[0,1.15,138.58],[1,1.17,606.27],[2,1.5,90.87]],"ltp":1.14,"tv":320.59,"id":8326656}],"tv":320.61}]}
{"op":"mcm","clk":"1002171599","pt":1580591130890,"mc":[{"id":"1.168179120","rc":[{"batb":[[1,7.6,5.18]],"ltp":6.0,"tv":0.02,"id":9712909}]}]}
{"op":"mcm","clk":"1002362327","pt":1580592886506,"mc":[{"id":"1.168179120","rc":[{"batl":[[1,1.17,227.66]],"ltp":1.14,"tv":320.59,"id":8326656}]}]}
{"op":"mcm","clk":"1002372499","pt":1580592984875,"mc":[{"id":"1.168179120","rc":[{"trd":[[1.15,314.58]],"batb":[[0,1.15,1126.4],[1,1.14,24.42],[2,1.13,277.93]],"batl":[[0,1.17,227.66],[1,1.5,90.87],[2,1.7,113.58]],"ltp":1.15,"tv":631.77,"id":8326656},{"trd":[[7.8,5.02]],"batb":[[0,7.6,5.18],[1,6.6,8.44],[2,6.4,10]],"ltp":7.8,"tv":5.03,"id":9712909}],"tv":636.8}]}
{"op":"mcm","clk":"1002372562","pt":1580592985558,"mc":[{"id":"1.168179120","rc":[{"batb":[[1,1.14,61.27]],"ltp":1.15,"tv":631.77,"id":8326656},{"batb":[[1,7,14.53],[2,6.6,8.44]],"ltp":7.8,"tv":5.03,"id":9712909}]}]}
{"op":"mcm","clk":"1002372704","pt":1580592986977,"mc":[{"id":"1.168179120","rc":[{"batb":[[0,7,14.53],[1,6.6,8.44],[2,6.4,10]],"ltp":7.8,"tv":5.03,"id":9712909}]}]}
{"op":"mcm","clk":"1002373225","pt":1580592992354,"mc":[{"id":"1.168179120","rc":[{"batb":[[1,6.8,9.23],[2,6.6,8.44]],"ltp":7.8,"tv":5.03,"id":9712909}]}]}
{"op":"mcm","clk":"1002377105","pt":1580593032324,"mc":[{"id":"1.168179120","rc":[{"batl":[[0,1.16,74.21],[1,1.17,227.66],[2,1.5,90.87]],"ltp":1.15,"tv":631.77,"id":8326656}]}]}
{"op":"mcm","clk":"1002386248","pt":1580593121851,"mc":[{"id":"1.168179120","rc":[{"batb":[[0,7.4,6.7]],"ltp":7.8,"tv":5.03,"id":9712909}]}]}
{"op":"mcm","clk":"1002388168","pt":1580593141891,"mc":[{"id":"1.168179120","rc":[{"trd":[[1.15,765.9]],"batb":[[0,1.15,900.74]],"ltp":1.15,"tv":1083.08,"id":8326656}],"tv":1088.12}]}
{"op":"mcm","clk":"1002388359","pt":1580593143568,"mc":[{"id":"1.168179120","rc":[{"batb":[[0,1.15,910.52]],"batl":[[0,1.16,84.23]],"ltp":1.15,"tv":1083.08,"id":8326656},{"batb":[[1,7,1.6],[2,6.8,9.23]],"ltp":7.8,"tv":5.03,"id":9712909}]}]}
{"op":"mcm","clk":"1002399698","pt":1580593258153,"mc":[{"id":"1.168179120","rc":[{"batb":[[2,1.13,280.12]],"batl":[[2,1.18,2.03]],"ltp":1.15,"tv":1083.08,"id":8326656},{"batb":[[1,7,3.6],[2,6.8,11.23]],"batl":[[0,8.2,2.03],[1,8.4,2.04],[2,95,15.9]],"ltp":7.8,"tv":5.03,"id":9712909}]}]}
{"op":"mcm","clk":"1002400942","pt":1580593271868,"mc":[{"id":"1.168179120","rc":[{"batb":[[0,7.4,8.3],[1,7,2],[2,6.8,11.26]],"ltp":7.8,"tv":5.03,"id":9712909}]}]}
{"op":"mcm","clk":"1002408288","pt":1580593347843,"mc":[{"id":"1.168179120","rc":[{"trd":[[1.15,854.91]],"batb":[[0,1.15,866.01],[1,1.14,74.56]],"ltp":1.15,"tv":1172.1,"id":8326656},{"batb":[[0,7.4,1.6],[1,7,14.46]],"ltp":7.8,"tv":5.03,"id":9712909}],"tv":1177.13}]}
{"op":"mcm","clk":"1002408345","pt":1580593348376,"mc":[{"id":"1.168179120","rc":[{"batb":[[0,7,12.46],[1,6.8,11.26],[2,6.6,10.48]],"ltp":7.8,"tv":5.03,"id":9712909}]}]}
{"op":"mcm","clk":"1002409773","pt":1580593361784,"mc":[{"id":"1.168179120","rc":[{"batb":[[2,1.13,507.29]],"ltp":1.15,"tv":1172.1,"id":8326656},{"batb":[[2,6.6,12.52]],"batl":[[1,8.4,4.08]],"ltp":7.8,"tv":5.03,"id":9712909}]}]}
{"op":"mcm","clk":"1002409925","pt":1580593363483,"mc":[{"id":"1.168179120","rc":[{"batb":[[1,6.8,14.42]],"ltp":7.8,"tv":5.03,"id":9712909}]}]}
{"op":"mcm","clk":"1002413363","pt":1580593397823,"mc":[{"id":"1.168179120","rc":[{"batl":[[0,1.16,10.02],[1,1.17,301.86]],"ltp":1.15,"tv":1172.1,"id":8326656},{"batb":[[2,6.6,8.44]],"batl":[[1,95,15.9],[2,990,2.2]],"ltp":7.8,"tv":5.03,"id":9712909}]}]}
{"op":"mcm","clk":"1002413396","pt":1580593398142,"mc":[{"id":"1.168179120","rc":[{"batb":[[1,6.8,12.39],[2,6.6,10.48]],"batl":[[1,8.4,2.04],[2,95,15.9]],"ltp":7.8,"tv":5.03,"id":9712909}]}]}
{"op":"mcm","clk":"1002413642","pt":1580593400634,"mc":[{"id":"1.168179120","rc":[{"batl":[[0,1.17,301.86],[1,1.19,2.08],[2,1.2,2.03]],"ltp":1.15,"tv":1172.1,"id":8326656}]}]}
{"op":"mcm","clk":"1002413693","pt":1580593401012,"mc":[{"id":"1.168179120","rc":[{"batb":[[0,7,14.06]],"ltp":7.8,"tv":5.03,"id":9712909}]}]}
{"op":"mcm","clk":"1002414532","pt":1580593409753,"mc":[{"id":"1.168179120","rc":[{"batb":[[0,1.15,856.23]],"ltp":1.15,"tv":1172.1,"id":8326656}]}]}
{"op":"mcm","clk":"1002462426","pt":1580594006390,"mc":[{"id":"1.168179120","rc":[{"batl":[[2,1.2,2]],"ltp":1.15,"tv":1172.1,"id":8326656},{"batb":[[0,7,12.46]],"ltp":7.8,"tv":5.03,"id":9712909}]}]}
{"op":"mcm","clk":"1002463415","pt":1580594018623,"mc":[{"id":"1.168179120","rc":[{"batl":[[1,1.18,15.2],[2,1.19,2.08]],"ltp":1.15,"tv":1172.1,"id":8326656},{"batb":[[0,7,14.06]],"ltp":7.8,"tv":5.03,"id":9712909}]}]}
{"op":"mcm","clk":"1002492046","pt":1580594403373,"mc":[{"id":"1.168179120","rc":[{"batl":[[1,8.4,2.02]],"ltp":7.8,"tv":5.03,"id":9712909}]}]}
{"op":"mcm","clk":"1002496228","pt":1580594458847,"mc":[{"id":"1.168179120","rc":[{"batl":[[1,95,15.9],[2,990,2.2]],"ltp":7.8,"tv":5.03,"id":9712909}]}]}
{"op":"mcm","clk":"1002496257","pt":1580594459164,"mc":[{"id":"1.168179120","rc":[{"batl":[[1,8.4,2.04],[2,95,15.9]],"ltp":7.8,"tv":5.03,"id":9712909}]}]}
{"op":"mcm","clk":"1002500542","pt":1580594518837,"mc":[{"id":"1.168179120","rc":[{"batl":[[1,95,15.9],[2,990,2.2]],"ltp":7.8,"tv":5.03,"id":9712909}]}]}
{"op":"mcm","clk":"1002500555","pt":1580594519044,"mc":[{"id":"1.168179120","rc":[{"batl":[[1,8.4,2.04],[2,95,15.9]],"ltp":7.8,"tv":5.03,"id":9712909}]}]}
{"op":"mcm","clk":"1002516084","pt":1580594756857,"mc":[{"id":"1.168179120","rc":[{"trd":[[1.17,6]],"batl":[[0,1.17,298.86]],"ltp":1.17,"tv":1178.1,"id":8326656},{"batl":[[1,95,15.9],[2,990,2.2]],"ltp":7.8,"tv":5.03,"id":9712909}],"tv":1183.13}]}
{"op":"mcm","clk":"1002516091","pt":1580594757060,"mc":[{"id":"1.168179120","rc":[{"batl":[[1,8.4,2.04],[2,95,15.9]],"ltp":7.8,"tv":5.03,"id":9712909}]}]}
{"op":"mcm","clk":"1002531202","pt":1580594986865,"mc":[{"id":"1.168179120","rc":[{"batl":[[0,1.17,501.73]],"ltp":1.17,"tv":1178.1,"id":8326656}]}]}
{"op":"mcm","clk":"1002531351","pt":1580594988997,"mc":[{"id":"1.168179120","rc":[{"batb":[[0,7,12.46]],"ltp":7.8,"tv":5.03,"id":9712909}]}]}
{"op":"mcm","clk":"1002531687","pt":1580594993406,"mc":[{"id":"1.168179120","rc":[{"batb":[[0,7,14.06]],"ltp":7.8,"tv":5.03,"id":9712909}]}]}
{"op":"mcm","clk":"1002542595","pt":1580595132722,"mc":[{"id":"1.168179120","rc":[{"batb":[[0,7,12.46]],"ltp":7.8,"tv":5.03,"id":9712909}]}]}
{"op":"mcm","clk":"1002543444","pt":1580595142628,"mc":[{"id":"1.168179120","rc":[{"batb":[[0,7,14.06]],"ltp":7.8,"tv":5.03,"id":9712909}]}]}
{"op":"mcm","clk":"1002552431","pt":1580595247740,"mc":[{"id":"1.168179120","rc":[{"batb":[[0,1.16,3.78],[1,1.15,856.23],[2,1.14,74.56]],"ltp":1.17,"tv":1178.1,"id":8326656}]}]}
{"op":"mcm","clk":"1002552495","pt":1580595248326,"mc":[{"id":"1.168179120","rc":[{"batb":[[2,1.14,76.56]],"ltp":1.17,"tv":1178.1,"id":8326656},{"batl":[[1,8.4,2]],"ltp":7.8,"tv":5.03,"id":9712909}]}]}
{"op":"mcm","clk":"1002552598","pt":1580595249428,"mc":[{"id":"1.168179120","rc":[{"trd":[[1.16,7.56]],"batb":[[0,1.15,856.23],[1,1.14,78.39],[2,1.13,507.1]],"ltp":1.16,"tv":1185.66,"id":8326656},{"batb":[[0,7,13.46]],"ltp":7.8,"tv":5.03,"id":9712909}],"tv":1190.69}]}
{"op":"mcm","clk":"1002557953","pt":1580595311725,"mc":[{"id":"1.168179120","rc":[{"batl":[[1,1.18,18.91]],"ltp":1.16,"tv":1185.66,"id":8326656},{"batl":[[1,8.4,2.04]],"ltp":7.8,"tv":5.03,"id":9712909}]}]}
{"op":"mcm","clk":"1002564660","pt":1580595396802,"mc":[{"id":"1.168179120","rc":[{"batb":[[0,7,11.86]],"ltp":7.8,"tv":5.03,"id":9712909}]}]}
{"op":"mcm","clk":"1002565685","pt":1580595408636,"mc":[{"id":"1.168179120","rc":[{"batl":[[1,95,15.9],[2,990,2.2]],"ltp":7.8,"tv":5.03,"id":9712909}]}]}
{"op":"mcm","clk":"1002565708","pt":1580595408948,"mc":[{"id":"1.168179120","rc":[{"batb":[[0,7,13.46]],"batl":[[1,8.4,2.04],[2,95,15.9]],"ltp":7.8,"tv":5.03,"id":9712909}]}]}
{"op":"mcm","clk":"1002569946","pt":1580595458726,"mc":[{"id":"1.168179120","rc":[{"trd":[[1.17,14.4]],"batl":[[0,1.17,497.52]],"ltp":1.17,"tv":1194.06,"id":8326656}],"tv":1199.1}]}
{"op":"mcm","clk":"1002576241","pt":1580595543882,"mc":[{"id":"1.168179120","rc":[{"batb":[[0,1.16,16.89],[1,1.15,856.23],[2,1.14,80.42]],"ltp":1.17,"tv":1194.06,"id":8326656},{"batl":[[0,7.8,2.02],[1,8,2.3]],"ltp":7.8,"tv":5.03,"id":9712909}]}]}
{"op":"mcm","clk":"1002576285","pt":1580595544565,"mc":[{"id":"1.168179120","rc":[{"trd":[[1.16,34.16]],"batb":[[0,1.16,3.59]],"ltp":1.16,"tv":1220.66,"id":8326656},{"batl":[[0,8.2,2.03],[1,8.4,2.04],[2,8.6,2.01]],"ltp":7.8,"tv":5.03,"id":9712909}],"tv":1225.7}]}
{"op":"mcm","clk":"1002583921","pt":1580595653715,"mc":[{"id":"1.168179120","rc":[{"trd":[[1.16,41.32]],"batb":[[0,1.15,856.24],[1,1.14,80.42],[2,1.13,507.29]],"ltp":1.16,"tv":1227.82,"id":8326656}],"tv":1232.86}]}
{"op":"mcm","clk":"1002583969","pt":1580595654336,"mc":[{"id":"1.168179120","rc":[{"batb":[[1,1.14,82.02]],"ltp":1.16,"tv":1227.82,"id":8326656},{"batb":[[0,7,12.89]],"batl":[[2,95,15.9]],"ltp":7.8,"tv":5.03,"id":9712909}]}]}
{"op":"mcm","clk":"1002584656","pt":1580595665660,"mc":[{"id":"1.168179120","rc":[{"trd":[[1.17,24.4]],"batl":[[0,1.17,492.53]],"ltp":1.17,"tv":1237.82,"id":8326656}],"tv":1242.85}]}
{"op":"mcm","clk":"1002584823","pt":1580595667838,"mc":[{"id":"1.168179120","rc":[{"batb":[[0,7,11.29]],"ltp":7.8,"tv":5.03,"id":9712909}]}]}
{"op":"mcm","clk":"1002584846","pt":1580595668148,"mc":[{"id":"1.168179120","rc":[{"batb":[[0,7,12.89]],"ltp":7.8,"tv":5.03,"id":9712909}]}]}
{"op":"mcm","clk":"1002605633","pt":1580595973793,"mc":[{"id":"1.168179120","rc":[{"trd":[[1.15,1054.89],[1.16,41.34]],"batb":[[0,1.15,756.24]],"ltp":1.15,"tv":1437.82,"id":8326656}],"tv":1442.85}]}
{"op":"mcm","clk":"1002607885","pt":1580596008875,"mc":[{"id":"1.168179120","rc":[{"batl":[[0,1.17,289.66]],"ltp":1.15,"tv":1437.82,"id":8326656}]}]}
{"op":"mcm","clk":"1002607937","pt":1580596009858,"mc":[{"id":"1.168179120","rc":[{"batl":[[0,1.16,202.86],[1,1.17,289.66],[2,1.18,20.94]],"ltp":1.15,"tv":1437.82,"id":8326656},{"batb":[[1,6.8,14.42],[2,6.6,12.52]],"ltp":7.8,"tv":5.03,"id":9712909}]}]}
{"op":"mcm","clk":"1002608001","pt":1580596011057,"mc":[{"id":"1.168179120","rc":[{"batl":[[0,1.16,212.52]],"ltp":1.15,"tv":1437.82,"id":8326656}]}]}
{"op":"mcm","clk":"1002608645","pt":1580596022270,"mc":[{"id":"1.168179120","rc":[{"batb":[[0,7,11.29],[2,6.6,10.48]],"ltp":7.8,"tv":5.03,"id":9712909}]}]}
{"op":"mcm","clk":"1002622042","pt":1580596205686,"mc":[{"id":"1.168179120","rc":[{"batb":[[1,6.8,2.03]],"ltp":7.8,"tv":5.03,"id":9712909}]}]}
{"op":"mcm","clk":"1002622400","pt":1580596211108,"mc":[{"id":"1.168179120","rc":[{"batb":[[0,7.2,10.93],[1,7,11.29],[2,6.8,2.03]],"ltp":7.8,"tv":5.03,"id":9712909}]}]}
{"op":"mcm","clk":"1002649179","pt":1580596609325,"mc":[{"id":"1.168179120","rc":[{"trd":[[1.16,177.24]],"batl":[[0,1.16,144.56]],"ltp":1.16,"tv":1573.72,"id":8326656}],"tv":1578.76}]}
{"op":"mcm","clk":"1002649241","pt":1580596610626,"mc":[{"id":"1.168179120","rc":[{"trd":[[1.16,230.58]],"batb":[[1,1.14,122.45]],"batl":[[0,1.16,117.89]],"ltp":1.16,"tv":1627.06,"id":8326656},{"batb":[[1,6.8,11.11],[2,6.6,10.48]],"ltp":7.8,"tv":5.03,"id":9712909}],"tv":1632.09}]}
{"op":"mcm","clk":"1002649297","pt":1580596611812,"mc":[{"id":"1.168179120","rc":[{"trd":[[1.16,466.37]],"batb":[[1,1.14,214.84]],"batl":[[0,1.17,289.66],[1,1.18,18.91],[2,1.19,2.08]],"ltp":1.16,"tv":1862.85,"id":8326656},{"trd":[[7.2,21.82]],"batb":[[0,6.8,9.06],[1,6.6,8.44],[2,6.4,2.01]],"ltp":7.2,"tv":26.86,"id":9712909}],"tv":1889.71}]}
{"op":"mcm","clk":"1002649425","pt":1580596613833,"mc":[{"id":"1.168179120","rc":[{"trd":[[1.17,646.53]],"batl":[[0,1.17,268.44]],"ltp":1.17,"tv":2484.98,"id":8326656},{"trd":[[7.2,21.84]],"batb":[[0,6.6,8.44],[1,6.2,2.02],[2,6,12.99]],"ltp":7.2,"tv":26.88,"id":9712909}],"tv":2511.86}]}
{"op":"mcm","clk":"1002649480","pt":1580596614814,"mc":[{"id":"1.168179120","rc":[{"batb":[[0,1.16,43.84],[1,1.15,756.24],[2,1.14,118.83]],"batl":[[0,1.17,284.69]],"ltp":1.17,"tv":2484.98,"id":8326656},{"batb":[[1,6.4,13.04],[2,6.2,2.02]],"batl":[[0,7.8,2.02],[1,8,2.01],[2,8.4,2.04]],"ltp":7.2,"tv":26.88,"id":9712909}]}]}
{"op":"mcm","clk":"1002649491","pt":1580596615020,"mc":[{"id":"1.168179120","rc":[{"batb":[[1,1.15,765.89]],"ltp":1.17,"tv":2484.98,"id":8326656},{"batl":[[2,95,15.9]],"ltp":7.2,"tv":26.88,"id":9712909}]}]}
{"op":"mcm","clk":"1002649667","pt":1580596618440,"mc":[{"id":"1.168179120","rc":[{"trd":[[1.17,679.04]],"batl":[[0,1.18,18.91],[1,1.2,2.03],[2,1.21,2.12]],"ltp":1.17,"tv":2517.49,"id":8326656},{"batb":[[1,6.4,11.03]],"ltp":7.2,"tv":26.88,"id":9712909}],"tv":2544.37}]}
{"op":"mcm","clk":"1002650348","pt":1580596630179,"mc":[{"id":"1.168179120","rc":[{"batb":[[0,6.6,10.16]],"batl":[[1,8,2]],"ltp":7.2,"tv":26.88,"id":9712909}]}]}
{"op":"mcm","clk":"1002651902","pt":1580596657799,"mc":[{"id":"1.168179120","rc":[{"batb":[[0,1.16,69.89],[1,1.15,756.24]],"ltp":1.17,"tv":2517.49,"id":8326656}]}]}
{"op":"mcm","clk":"1002651962","pt":1580596658886,"mc":[{"id":"1.168179120","rc":[{"trd":[[1.16,554.05]],"batb":[[0,1.15,756.24],[1,1.14,116.8],[2,1.13,507.29]],"ltp":1.16,"tv":2605.17,"id":8326656},{"batl":[[0,8.2,2.03],[1,8.4,2.04]],"ltp":7.2,"tv":26.88,"id":9712909}],"tv":2632.05}]}
{"op":"mcm","clk":"1002652006","pt":1580596659709,"mc":[{"id":"1.168179120","rc":[{"batb":[[0,1.15,803.38]],"ltp":1.16,"tv":2605.17,"id":8326656},{"batb":[[0,6.8,9.07],[1,6.6,10.16],[2,6.4,2.01]],"batl":[[2,8.6,2.01]],"ltp":7.2,"tv":26.88,"id":9712909}]}]}
{"op":"mcm","clk":"1002652187","pt":1580596662827,"mc":[{"id":"1.168179120","rc":[{"batl":[[0,1.17,74.21],[1,1.18,18.91],[2,1.19,2.03]],"ltp":1.16,"tv":2605.17,"id":8326656}]}]}
{"op":"mcm","clk":"1002652237","pt":1580596663507,"mc":[{"id":"1.168179120","rc":[{"batb":[[2,1.13,928.53]],"ltp":1.16,"tv":2605.17,"id":8326656}]}]}
{"op":"mcm","clk":"1002652385","pt":1580596666302,"mc":[{"id":"1.168179120","rc":[{"batb":[[0,6.8,14.2]],"batl":[[2,95,15.9]],"ltp":7.2,"tv":26.88,"id":9712909}]}]}
{"op":"mcm","clk":"1002653482","pt":1580596684742,"mc":[{"id":"1.168179120","rc":[{"trd":[[1.15,2714.23]],"batb":[[0,1.14,116.8],[1,1.13,928.53],[2,1.12,2.04]],"batl":[[0,1.15,850.71],[1,1.17,74.21],[2,1.18,18.91]],"ltp":1.15,"tv":4264.51,"id":8326656}],"tv":4291.39}]}
{"op":"mcm","clk":"1002653574","pt":1580596685885,"mc":[{"id":"1.168179120","rc":[{"trd":[[1.15,4415.64],[1.17,856.52],[1.18,180.56],[1.19,14.88],[1.2,14.6]],"batb":[[0,1.15,68.01],[1,1.14,116.8],[2,1.13,930.76]],"batl":[[0,1.5,90.87],[1,1.7,113.58],[2,2,249.89]],"ltp":1.2,"tv":6353.33,"id":8326656},{"trd":[[6.2,2.02],[6.4,2.01],[6.6,10.16],[6.8,14.2],[7,2.1],[7.2,23.86]],"batb":[[0,6.2,20.36],[1,5.5,12.16],[2,5.1,20.45]],"batl":[[0,8.2,4.13],[1,8.4,4.14],[2,8.6,2.01]],"ltp":6.2,"tv":59.39,"id":9712909}],"tv":6412.72}]}
{"op":"mcm","clk":"1002653623","pt":1580596686873,"mc":[{"id":"1.168179120","rc":[{"batl":[[0,1.19,25.54],[1,1.5,90.87],[2,1.7,113.58]],"ltp":1.2,"tv":6353.33,"id":8326656}]}]}
{"op":"mcm","clk":"1002653662","pt":1580596687446,"mc":[{"id":"1.168179120","rc":[{"batb":[[1,1.14,24.42]],"ltp":1.2,"tv":6353.33,"id":8326656},{"batb":[[0,6.2,26.26],[2,5.3,20.45]],"batl":[[0,8,1.41],[1,8.2,4.13],[2,8.4,4.14]],"ltp":6.2,"tv":59.39,"id":9712909}]}]}
{"op":"mcm","clk":"1002654016","pt":1580596693351,"mc":[{"id":"1.168179120","rc":[{"batb":[[1,1.14,415.57],[2,1.13,509.52]],"ltp":1.2,"tv":6353.33,"id":8326656},{"batb":[[1,5.3,20.45],[2,5,13.69]],"batl":[[2,8.4,4.69]],"ltp":6.2,"tv":59.39,"id":9712909}]}]}
{"op":"mcm","clk":"1002654150","pt":1580596695778,"mc":[{"id":"1.168179120","rc":[{"batb":[[1,1.14,504.92]],"ltp":1.2,"tv":6353.33,"id":8326656},{"batb":[[1,5.2,20.45]],"ltp":6.2,"tv":59.39,"id":9712909}]}]}
{"op":"mcm","clk":"1002654231","pt":1580596697592,"mc":[{"id":"1.168179120","rc":[{"batb":[[0,6.2,30.9]],"ltp":6.2,"tv":59.39,"id":9712909}]}]}
{"op":"mcm","clk":"1002654312","pt":1580596698894,"mc":[{"id":"1.168179120","rc":[{"batb":[[1,5.3,5.29],[2,5.2,20.45]],"ltp":6.2,"tv":59.39,"id":9712909}]}]}
{"op":"mcm","clk":"1002654359","pt":1580596699779,"mc":[{"id":"1.168179120","rc":[{"batb":[[2,1.13,132.42]],"ltp":1.2,"tv":6353.33,"id":8326656},{"batb":[[0,6.4,2.98],[1,6.2,30.9],[2,5.3,10.57]],"batl":[[2,8.4,4.29]],"ltp":6.2,"tv":59.39,"id":9712909}]}]}
{"op":"mcm","clk":"1002654516","pt":1580596702988,"mc":[{"id":"1.168179120","rc":[{"batb":[[0,1.15,168.97]],"ltp":1.2,"tv":6353.33,"id":8326656}]}]}
{"op":"mcm","clk":"1002654788","pt":1580596707893,"mc":[{"id":"1.168179120","rc":[{"trd":[[1.16,635.27]],"batb":[[0,1.16,6.72],[1,1.15,168.97],[2,1.14,509.81]],"ltp":1.16,"tv":6434.55,"id":8326656},{"batl":[[0,7.8,4.77],[1,8,6],[2,8.4,4.54]],"ltp":6.2,"tv":59.39,"id":9712909}],"tv":6493.94}]}
{"op":"mcm","clk":"1002654814","pt":1580596708305,"mc":[{"id":"1.168179120","rc":[{"batb":[[1,1.15,1121.56]],"ltp":1.16,"tv":6434.55,"id":8326656},{"batl":[[0,8,1.41],[1,8.2,4.38],[2,8.4,4.79]],"ltp":6.2,"tv":59.39,"id":9712909}]}]}
{"op":"mcm","clk":"1002654863","pt":1580596709192,"mc":[{"id":"1.168179120","rc":[{"batl":[[0,1.18,39.92],[1,1.19,25.54],[2,1.5,90.87]],"ltp":1.16,"tv":6434.55,"id":8326656}]}]}
{"op":"mcm","clk":"1002655024","pt":1580596711893,"mc":[{"id":"1.168179120","rc":[{"batl":[[2,1.2,15.14]],"ltp":1.16,"tv":6434.55,"id":8326656}]}]}
{"op":"mcm","clk":"1002655248","pt":1580596715588,"mc":[{"id":"1.168179120","rc":[{"batb":[[2,1.14,440.15]],"ltp":1.16,"tv":6434.55,"id":8326656}]}]}
{"op":"mcm","clk":"1002655275","pt":1580596716001,"mc":[{"id":"1.168179120","rc":[{"batb":[[1,1.15,1141.25],[2,1.14,420.46]],"ltp":1.16,"tv":6434.55,"id":8326656},{"batl":[[2,8.4,4.44]],"ltp":6.2,"tv":59.39,"id":9712909}]}]}
{"op":"mcm","clk":"1002655686","pt":1580596723800,"mc":[{"id":"1.168179120","rc":[{"trd":[[1.16,645.63]],"batb":[[0,1.16,1.54]],"ltp":1.16,"tv":6444.91,"id":8326656},{"batl":[[0,7.6,1.41],[2,8.4,4.89]],"ltp":6.2,"tv":59.39,"id":9712909}],"tv":6504.3}]}
{"op":"mcm","clk":"1002655689","pt":1580596723903,"mc":[{"id":"1.168179120","rc":[{"batb":[[2,1.14,415.57]],"ltp":1.16,"tv":6444.91,"id":8326656}]}]}
{"op":"mcm","clk":"1002655856","pt":1580596726393,"mc":[{"id":"1.168179120","rc":[{"batb":[[1,1.15,1210.16]],"ltp":1.16,"tv":6444.91,"id":8326656}]}]}
{"op":"mcm","clk":"1002655927","pt":1580596727732,"mc":[{"id":"1.168179120","rc":[{"batl":[[0,1.18,55.07]],"ltp":1.16,"tv":6444.91,"id":8326656}]}]}
{"op":"mcm","clk":"1002656189","pt":1580596732338,"mc":[{"id":"1.168179120","rc":[{"batb":[[0,1.15,1210.16],[1,1.14,415.57],[2,1.13,132.42]],"ltp":1.16,"tv":6444.91,"id":8326656},{"batl":[[2,8.4,4.84]],"ltp":6.2,"tv":59.39,"id":9712909}]}]}
{"op":"mcm","clk":"1002656769","pt":1580596742844,"mc":[{"id":"1.168179120","rc":[{"batb":[[0,1.16,4.35],[1,1.15,1210.16],[2,1.14,415.57]],"ltp":1.16,"tv":6444.91,"id":8326656}]}]}
{"op":"mcm","clk":"1002656817","pt":1580596743718,"mc":[{"id":"1.168179120","rc":[{"batb":[[2,1.14,420.39]],"ltp":1.16,"tv":6444.91,"id":8326656},{"batl":[[1,8,5.06],[2,8.2,4.88]],"ltp":6.2,"tv":59.39,"id":9712909}]}]}
{"op":"mcm","clk":"1002657011","pt":1580596746822,"mc":[{"id":"1.168179120","rc":[{"batb":[[0,1.16,30.39]],"batl":[[1,1.2,15.14],[2,1.23,30.29]],"ltp":1.16,"tv":6444.91,"id":8326656}]}]}
{"op":"mcm","clk":"1002657076","pt":1580596747857,"mc":[{"id":"1.168179120","rc":[{"trd":[[1.16,697.5]],"batb":[[0,1.16,4.47]],"batl":[[0,1.17,25.54],[1,1.18,55.07],[2,1.2,15.14]],"ltp":1.16,"tv":6496.77,"id":8326656}],"tv":6556.16}]}
{"op":"mcm","clk":"1002657216","pt":1580596750733,"mc":[{"id":"1.168179120","rc":[{"batl":[[0,7.6,1.49],[1,8,4.81],[2,8.2,4.28]],"ltp":6.2,"tv":59.39,"id":9712909}]}]}
{"op":"mcm","clk":"1002657280","pt":1580596751823,"mc":[{"id":"1.168179120","rc":[{"batl":[[0,1.19,44.64],[1,1.2,15.14],[2,1.23,30.29]],"ltp":1.16,"tv":6496.77,"id":8326656}]}]}
{"op":"mcm","clk":"1002657288","pt":1580596751927,"mc":[{"id":"1.168179120","rc":[{"batl":[[0,1.19,70.18]],"ltp":1.16,"tv":6496.77,"id":8326656}]}]}
{"op":"mcm","clk":"1002657442","pt":1580596754367,"mc":[{"id":"1.168179120","rc":[{"batl":[[0,1.19,85.32]],"ltp":1.16,"tv":6496.77,"id":8326656}]}]}
{"op":"mcm","clk":"1002657531","pt":1580596755863,"mc":[{"id":"1.168179120","rc":[{"batb":[[0,1.15,1210.16],[1,1.14,420.39],[2,1.13,132.73]],"ltp":1.16,"tv":6496.77,"id":8326656}]}]}
{"op":"mcm","clk":"1002657556","pt":1580596756437,"mc":[{"id":"1.168179120","rc":[{"batb":[[1,1.14,415.57]],"ltp":1.16,"tv":6496.77,"id":8326656},{"batl":[[1,8.2,4.48],[2,8.4,4.44]],"ltp":6.2,"tv":59.39,"id":9712909}]}]}
{"op":"mcm","clk":"1002658470","pt":1580596774856,"mc":[{"id":"1.168179120","rc":[{"batl":[[0,1.18,78.68],[1,1.19,85.32],[2,1.2,15.14]],"ltp":1.16,"tv":6496.77,"id":8326656},{"batl":[[2,95,15.9]],"ltp":6.2,"tv":59.39,"id":9712909}]}]}
{"op":"mcm","clk":"1002658479","pt":1580596774970,"mc":[{"id":"1.168179120","rc":[{"batl":[[2,8.4,4.84]],"ltp":6.2,"tv":59.39,"id":9712909}]}]}
{"op":"mcm","clk":"1002658549","pt":1580596776878,"mc":[{"id":"1.168179120","rc":[{"batb":[[0,6.4,4.75]],"ltp":6.2,"tv":59.39,"id":9712909}]}]}
{"op":"mcm","clk":"1002658885","pt":1580596782867,"mc":[{"id":"1.168179120","rc":[{"batb":[[0,6.6,4.6]],"ltp":6.2,"tv":59.39,"id":9712909}]}]}
{"op":"mcm","clk":"1002658906","pt":1580596783177,"mc":[{"id":"1.168179120","rc":[{"batl":[[2,8.4,4.79]],"ltp":6.2,"tv":59.39,"id":9712909}]}]}
{"op":"mcm","clk":"1002659481","pt":1580596794864,"mc":[{"id":"1.168179120","rc":[{"batl":[[1,1.19,59.78]],"ltp":1.16,"tv":6496.77,"id":8326656}]}]}
{"op":"mcm","clk":"1002659503","pt":1580596795380,"mc":[{"id":"1.168179120","rc":[{"batl":[[0,1.17,25.54],[1,1.18,78.68],[2,1.19,59.78]],"ltp":1.16,"tv":6496.77,"id":8326656},{"batl":[[2,8.4,4.74]],"ltp":6.2,"tv":59.39,"id":9712909}]}]}
{"op":"mcm","clk":"1002660122","pt":1580596805884,"mc":[{"id":"1.168179120","rc":[{"trd":[[1.17,882.06]],"batb":[[0,1.15,1214.59],[1,1.14,420.39]],"batl":[[0,1.18,78.68],[1,1.19,59.78],[2,1.2,15.14]],"ltp":1.17,"tv":6522.31,"id":8326656},{"trd":[[6.8,150.53]],"batl":[[0,6.8,200.7],[1,7.2,4.13],[2,7.4,4.34]],"ltp":6.8,"tv":195.71,"id":9712909}],"tv":6718.03}]}
{"op":"mcm","clk":"1002660134","pt":1580596805991,"mc":[{"id":"1.168179120","rc":[{"batb":[[2,1.13,128]],"ltp":1.17,"tv":6522.31,"id":8326656}]}]}
{"op":"mcm","clk":"1002660470","pt":1580596810287,"mc":[{"id":"1.168179120","rc":[{"batl":[[0,1.18,79.11]],"ltp":1.17,"tv":6522.31,"id":8326656},{"batb":[[0,6.2,30.9],[1,5.3,10.57],[2,5.2,20.45]],"ltp":6.8,"tv":195.71,"id":9712909}]}]}
{"op":"mcm","clk":"1002660573","pt":1580596811589,"mc":[{"id":"1.168179120","rc":[{"batb":[[1,1.14,419.96]],"batl":[[1,1.2,15.14],[2,1.23,30.29]],"ltp":1.17,"tv":6522.31,"id":8326656},{"batl":[[2,7.4,4.94]],"ltp":6.8,"tv":195.71,"id":9712909}]}]}
{"op":"mcm","clk":"1002660618","pt":1580596812116,"mc":[{"id":"1.168179120","rc":[{"batl":[[0,1.19,45.07]],"ltp":1.17,"tv":6522.31,"id":8326656}]}]}
{"op":"mcm","clk":"1002660682","pt":1580596813409,"mc":[{"id":"1.168179120","rc":[{"batb":[[1,1.14,28.81],[2,1.13,549.24]],"ltp":1.17,"tv":6522.31,"id":8326656},{"batb":[[1,5.5,12.16],[2,5.3,10.57]],"ltp":6.8,"tv":195.71,"id":9712909}]}]}
{"op":"mcm","clk":"1002661048","pt":1580596817890,"mc":[{"id":"1.168179120","rc":[{"batb":[[0,1.17,30.39],[1,1.15,1214.59],[2,1.14,28.81]],"batl":[[1,1.2,93.83]],"ltp":1.17,"tv":6522.31,"id":8326656}]}]}
{"op":"mcm","clk":"1002661070","pt":1580596818257,"mc":[{"id":"1.168179120","rc":[{"batb":[[2,1.14,29.24]],"ltp":1.17,"tv":6522.31,"id":8326656},{"batl":[[0,6.8,202.19],[2,7.4,4.39]],"ltp":6.8,"tv":195.71,"id":9712909}]}]}
{"op":"mcm","clk":"1002661819","pt":1580596828750,"mc":[{"id":"1.168179120","rc":[{"batb":[[2,1.14,29.74]],"ltp":1.17,"tv":6522.31,"id":8326656},{"trd":[[6.8,254.53]],"batl":[[0,6.8,150.18],[2,7.4,4.94]],"ltp":6.8,"tv":299.71,"id":9712909}],"tv":6822.03}]}
{"op":"mcm","clk":"1002661973","pt":1580596831250,"mc":[{"id":"1.168179120","rc":[{"batb":[[0,1.15,1214.99],[1,1.14,29.74],[2,1.13,553.66]],"ltp":1.17,"tv":6522.31,"id":8326656}]}]}
{"op":"mcm","clk":"1002662959","pt":1580596844746,"mc":[{"id":"1.168179120","rc":[{"trd":[[6.8,368.53]],"batl":[[0,6.8,93.18]],"ltp":6.8,"tv":413.71,"id":9712909}],"tv":6936.03}]}
{"op":"mcm","clk":"1002662989","pt":1580596845264,"mc":[{"id":"1.168179120","rc":[{"batb":[[1,1.14,29.24],[2,1.13,549.24]],"ltp":1.17,"tv":6522.31,"id":8326656},{"batl":[[2,7.4,4.74]],"ltp":6.8,"tv":413.71,"id":9712909}]}]}
{"op":"mcm","clk":"1002663737","pt":1580596859258,"mc":[{"id":"1.168179120","rc":[{"batb":[[1,1.14,29.31]],"ltp":1.17,"tv":6522.31,"id":8326656},{"batl":[[2,7.4,5.04]],"ltp":6.8,"tv":413.71,"id":9712909}]}]}
{"op":"mcm","clk":"1002664058","pt":1580596863794,"mc":[{"id":"1.168179120","rc":[{"batb":[[0,1.16,32.93],[1,1.15,1214.99],[2,1.14,29.31]],"ltp":1.17,"tv":6522.31,"id":8326656},{"trd":[[6.8,379.76]],"batb":[[0,6.2,25.07]],"batl":[[0,6.8,87.57]],"ltp":6.8,"tv":424.94,"id":9712909}],"tv":6947.26}]}
{"op":"mcm","clk":"1002664239","pt":1580596865669,"mc":[{"id":"1.168179120","rc":[{"batb":[[2,1.14,29.24]],"ltp":1.17,"tv":6522.31,"id":8326656},{"trd":[[6.8,505.76]],"batl":[[0,6.8,24.56],[2,7.4,4.89]],"ltp":6.8,"tv":550.94,"id":9712909}],"tv":7073.26}]}
{"op":"mcm","clk":"1002664559","pt":1580596869076,"mc":[{"id":"1.168179120","rc":[{"batl":[[0,6.6,1.49],[1,6.8,23.07],[2,7.2,4.13]],"ltp":6.8,"tv":550.94,"id":9712909}]}]}
{"op":"mcm","clk":"1002664856","pt":1580596872309,"mc":[{"id":"1.168179120","rc":[{"batb":[[2,1.14,24.42]],"batl":[[0,1.19,44.64]],"ltp":1.17,"tv":6522.31,"id":8326656}]}]}
{"op":"mcm","clk":"1002664919","pt":1580596873090,"mc":[{"id":"1.168179120","rc":[{"batb":[[2,1.14,29.74]],"ltp":1.17,"tv":6522.31,"id":8326656}]}]}
{"op":"mcm","clk":"1002666537","pt":1580596898830,"mc":[{"id":"1.168179120","rc":[{"batb":[[2,1.14,28.74]],"ltp":1.17,"tv":6522.31,"id":8326656},{"trd":[[6.6,13.58],[6.8,542.32]],"batl":[[0,6.8,4.79],[1,7.2,4.13],[2,7.4,4.59]],"ltp":6.8,"tv":590.93,"id":9712909}],"tv":7113.24}]}
{"op":"mcm","clk":"1002667685","pt":1580596919236,"mc":[{"id":"1.168179120","rc":[{"batl":[[2,7.4,4.69]],"ltp":6.8,"tv":590.93,"id":9712909}]}]}
{"op":"mcm","clk":"1002668282","pt":1580596930778,"mc":[{"id":"1.168179120","rc":[{"batl":[[0,1.18,25.76],[1,1.19,44.64],[2,1.2,93.83]],"ltp":1.17,"tv":6522.31,"id":8326656},{"trd":[[6.8,549.28]],"batl":[[0,6.8,1.31],[2,7.4,4.99]],"ltp":6.8,"tv":597.89,"id":9712909}],"tv":7120.2}]}
{"op":"mcm","clk":"1002668297","pt":1580596931037,"mc":[{"id":"1.168179120","rc":[{"batl":[[1,7.4,4.99],[2,7.6,4.56]],"ltp":6.8,"tv":597.89,"id":9712909}]}]}
{"op":"mcm","clk":"1002668661","pt":1580596937362,"mc":[{"id":"1.168179120","rc":[{"batb":[[0,1.16,63.32],[2,1.14,28.81]],"ltp":1.17,"tv":6522.31,"id":8326656}]}]}
{"op":"mcm","clk":"1002669607","pt":1580596952878,"mc":[{"id":"1.168179120","rc":[{"trd":[[1.16,791.96],[1.17,889.68]],"batb":[[0,1.16,16.1],[2,1.14,29.24]],"ltp":1.16,"tv":6624.39,"id":8326656},{"trd":[[6.8,550.6]],"batb":[[2,5.3,31.02]],"batl":[[0,7.4,4.99],[1,7.6,4.76],[2,7.8,4.47]],"ltp":6.8,"tv":599.2,"id":9712909}],"tv":7223.6}]}
{"op":"mcm","clk":"1002669665","pt":1580596953760,"mc":[{"id":"1.168179120","rc":[{"batb":[[0,1.16,6.57],[1,1.15,1210.14]],"batl":[[0,1.18,14.21]],"ltp":1.16,"tv":6624.39,"id":8326656},{"batb":[[0,6.6,10.14],[1,6.2,10.54],[2,5.5,12.16]],"batl":[[0,8.2,4.18],[1,8.4,4.59],[2,8.6,4.66]],"ltp":6.8,"tv":599.2,"id":9712909}]}]}
{"op":"mcm","clk":"1002670168","pt":1580596961608,"mc":[{"id":"1.168179120","rc":[{"batb":[[0,1.16,85.25]],"ltp":1.16,"tv":6624.39,"id":8326656},{"batl":[[0,7.8,4.92],[1,8,4.84],[2,95,15.9]],"ltp":6.8,"tv":599.2,"id":9712909}]}]}
{"op":"mcm","clk":"1002670717","pt":1580596969573,"mc":[{"id":"1.168179120","rc":[{"batb":[[1,1.15,257.54],[2,1.14,981.84]],"ltp":1.16,"tv":6624.39,"id":8326656},{"batl":[[1,8,5.06]],"ltp":6.8,"tv":599.2,"id":9712909}]}]}
{"op":"mcm","clk":"1002671175","pt":1580596976818,"mc":[{"id":"1.168179120","rc":[{"trd":[[1.16,802.4]],"batb":[[0,1.16,1.35]],"batl":[[2,1.2,15.14]],"ltp":1.16,"tv":6634.83,"id":8326656},{"batl":[[1,8.2,5.03],[2,8.4,4.54]],"ltp":6.8,"tv":599.2,"id":9712909}],"tv":7234.03}]}
{"op":"mcm","clk":"1002671195","pt":1580596977129,"mc":[{"id":"1.168179120","rc":[{"batb":[[2,1.14,977.02]],"ltp":1.16,"tv":6634.83,"id":8326656},{"batl":[[0,8.2,5.03],[1,8.4,4.54],[2,95,15.9]],"ltp":6.8,"tv":599.2,"id":9712909}]}]}
{"op":"mcm","clk":"1002671300","pt":1580596979091,"mc":[{"id":"1.168179120","rc":[{"batl":[[0,1.18,19.33]],"ltp":1.16,"tv":6634.83,"id":8326656}]}]}
{"op":"mcm","clk":"1002671410","pt":1580596980698,"mc":[{"id":"1.168179120","rc":[{"batb":[[1,1.15,414.9]],"ltp":1.16,"tv":6634.83,"id":8326656}]}]}
{"op":"mcm","clk":"1002672502","pt":1580596999543,"mc":[{"id":"1.168179120","rc":[{"batl":[[1,8.4,4.44]],"ltp":6.8,"tv":599.2,"id":9712909}]}]}
{"op":"mcm","clk":"1002673471","pt":1580597017857,"mc":[{"id":"1.168179120","rc":[{"batl":[[1,1.19,202]],"ltp":1.16,"tv":6634.83,"id":8326656},{"batl":[[1,95,15.9],[2,990,2.2]],"ltp":6.8,"tv":599.2,"id":9712909}]}]}
{"op":"mcm","clk":"1002673479","pt":1580597018062,"mc":[{"id":"1.168179120","rc":[{"batl":[[1,8.4,4.29],[2,95,15.9]],"ltp":6.8,"tv":599.2,"id":9712909}]}]}
{"op":"mcm","clk":"1002673541","pt":1580597019150,"mc":[{"id":"1.168179120","rc":[{"batb":[[0,1.15,414.9],[1,1.14,977.02],[2,1.13,553.66]],"batl":[[0,1.19,202],[1,1.2,15.14],[2,1.23,30.29]],"ltp":1.16,"tv":6634.83,"id":8326656}]}]}
{"op":"mcm","clk":"1002674306","pt":1580597032490,"mc":[{"id":"1.168179120","rc":[{"batl":[[0,1.18,19.33],[1,1.19,202],[2,1.2,15.14]],"ltp":1.16,"tv":6634.83,"id":8326656},{"batl":[[1,8.4,4.99]],"ltp":6.8,"tv":599.2,"id":9712909}]}]}
{"op":"mcm","clk":"1002674395","pt":1580597033681,"mc":[{"id":"1.168179120","rc":[{"batb":[[0,1.16,48.04],[1,1.15,414.9],[2,1.14,982.34]],"ltp":1.16,"tv":6634.83,"id":8326656},{"trd":[[6.6,30.47]],"batb":[[0,6.4,6.63]],"batl":[[0,7.8,4.72],[1,8,4.59],[2,8.2,5.03]],"ltp":6.6,"tv":616.09,"id":9712909}],"tv":7250.92}]}
{"op":"mcm","clk":"1002674422","pt":1580597034096,"mc":[{"id":"1.168179120","rc":[{"batl":[[2,8.4,4.99]],"ltp":6.6,"tv":616.09,"id":9712909}]}]}
{"op":"mcm","clk":"1002674582","pt":1580597036684,"mc":[{"id":"1.168179120","rc":[{"batl":[[0,7.6,2.39],[1,7.8,4.72],[2,8,4.59]],"ltp":6.6,"tv":616.09,"id":9712909}]}]}
{"op":"mcm","clk":"1002675583","pt":1580597053831,"mc":[{"id":"1.168179120","rc":[{"trd":[[1.16,903.74]],"batb":[[0,1.16,7.93]],"ltp":1.16,"tv":6736.17,"id":8326656}],"tv":7352.26}]}
{"op":"mcm","clk":"1002675608","pt":1580597054299,"mc":[{"id":"1.168179120","rc":[{"batb":[[0,6.6,8.41],[1,6.4,6.63],[2,6.2,10.54]],"batl":[[1,8,4.59],[2,8.2,4.48]],"ltp":6.6,"tv":616.09,"id":9712909}]}]}
{"op":"mcm","clk":"1002675905","pt":1580597059836,"mc":[{"id":"1.168179120","rc":[{"batl":[[0,1.18,21.92]],"ltp":1.16,"tv":6736.17,"id":8326656},{"batl":[[0,8.2,4.48],[1,8.4,4.74],[2,95,15.9]],"ltp":6.6,"tv":616.09,"id":9712909}]}]}
{"op":"mcm","clk":"1002676962","pt":1580597077826,"mc":[{"id":"1.168179120","rc":[{"trd":[[1.16,915.97]],"batb":[[0,1.16,1.81]],"ltp":1.16,"tv":6748.4,"id":8326656},{"batl":[[1,8.4,4.14]],"ltp":6.6,"tv":616.09,"id":9712909}],"tv":7364.5}]}
{"op":"mcm","clk":"1002676975","pt":1580597078027,"mc":[{"id":"1.168179120","rc":[{"batb":[[2,1.14,977.02]],"ltp":1.16,"tv":6748.4,"id":8326656}]}]}
{"op":"mcm","clk":"1002677037","pt":1580597079316,"mc":[{"id":"1.168179120","rc":[{"batb":[[0,1.16,4.44],[2,1.14,981.41]],"ltp":1.16,"tv":6748.4,"id":8326656}]}]}
{"op":"mcm","clk":"1002677496","pt":1580597086749,"mc":[{"id":"1.168179120","rc":[{"batb":[[0,1.15,414.9],[1,1.14,977.02],[2,1.13,554.43]],"batl":[[0,1.18,25.76]],"ltp":1.16,"tv":6748.4,"id":8326656},{"batl":[[1,8.4,4.94]],"ltp":6.6,"tv":616.09,"id":9712909}]}]}
{"op":"mcm","clk":"1002679050","pt":1580597109477,"mc":[{"id":"1.168179120","rc":[{"batl":[[1,8.4,4.59]],"ltp":6.6,"tv":616.09,"id":9712909}]}]}
{"op":"mcm","clk":"1002679861","pt":1580597122508,"mc":[{"id":"1.168179120","rc":[{"batb":[[0,1.15,499.34]],"ltp":1.16,"tv":6748.4,"id":8326656},{"batl":[[1,8.4,4.29]],"ltp":6.6,"tv":616.09,"id":9712909}]}]}
{"op":"mcm","clk":"1002681436","pt":1580597150743,"mc":[{"id":"1.168179120","rc":[{"batl":[[0,1.19,202],[1,1.2,15.14],[2,1.23,30.29]],"ltp":1.16,"tv":6748.4,"id":8326656},{"batl":[[1,8.4,4.59]],"ltp":6.6,"tv":616.09,"id":9712909}]}]}
{"op":"mcm","clk":"1002682583","pt":1580597170764,"mc":[{"id":"1.168179120","rc":[{"batl":[[0,1.18,25.76],[1,1.19,202],[2,1.2,15.14]],"ltp":1.16,"tv":6748.4,"id":8326656},{"batl":[[1,8.4,4.19]],"ltp":6.6,"tv":616.09,"id":9712909}]}]}
{"op":"mcm","clk":"1002683712","pt":1580597190893,"mc":[{"id":"1.168179120","rc":[{"batb":[[0,1.16,4.45],[1,1.15,499.34],[2,1.14,981.84]],"ltp":1.16,"tv":6748.4,"id":8326656},{"batl":[[1,8.4,4.59]],"ltp":6.6,"tv":616.09,"id":9712909}]}]}
{"op":"mcm","clk":"1002688702","pt":1580597283832,"mc":[{"id":"1.168179120","rc":[{"batb":[[0,1.15,499.34],[1,1.14,977.02],[2,1.13,553.97]],"batl":[[0,1.19,202],[1,1.2,15.14],[2,1.23,30.29]],"ltp":1.16,"tv":6748.4,"id":8326656},{"batl":[[1,8.4,4.84]],"ltp":6.6,"tv":616.09,"id":9712909}]}]}
{"op":"mcm","clk":"1002689429","pt":1580597295747,"mc":[{"id":"1.168179120","rc":[{"batb":[[0,1.16,7.34],[1,1.15,499.34],[2,1.14,982.34]],"batl":[[0,1.18,25.76],[1,1.19,202],[2,1.2,15.14]],"ltp":1.16,"tv":6748.4,"id":8326656},{"batl":[[1,95,15.9],[2,990,2.2]],"ltp":6.6,"tv":616.09,"id":9712909}]}]}
{"op":"mcm","clk":"1002689450","pt":1580597296110,"mc":[{"id":"1.168179120","rc":[{"batl":[[1,8.4,4.89],[2,95,15.9]],"ltp":6.6,"tv":616.09,"id":9712909}]}]}
{"op":"mcm","clk":"1002701888","pt":1580597505399,"mc":[{"id":"1.168179120","rc":[{"batl":[[1,8.4,4.24]],"ltp":6.6,"tv":616.09,"id":9712909}]}]}
{"op":"mcm","clk":"1002709019","pt":1580597616565,"mc":[{"id":"1.168179120","rc":[{"trd":[[1.16,928.41]],"batb":[[0,1.16,1.12],[2,1.14,977.02]],"ltp":1.16,"tv":6760.84,"id":8326656},{"batl":[[1,8.4,4.64]],"ltp":6.6,"tv":616.09,"id":9712909}],"tv":7376.93}]}
{"op":"mcm","clk":"1002709831","pt":1580597629877,"mc":[{"id":"1.168179120","rc":[{"batb":[[0,1.15,499.34],[1,1.14,977.02],[2,1.13,132.73]],"ltp":1.16,"tv":6760.84,"id":8326656}]}]}
{"op":"mcm","clk":"1002709847","pt":1580597630134,"mc":[{"id":"1.168179120","rc":[{"batl":[[1,8.4,4.84]],"ltp":6.6,"tv":616.09,"id":9712909}]}]}
{"op":"mcm","clk":"1002709921","pt":1580597631471,"mc":[{"id":"1.168179120","rc":[{"batb":[[1,1.14,24.42],[2,1.13,1085.33]],"ltp":1.16,"tv":6760.84,"id":8326656}]}]}
{"op":"mcm","clk":"1002716446","pt":1580597736482,"mc":[{"id":"1.168179120","rc":[{"batb":[[0,1.16,1.68],[1,1.15,499.34],[2,1.14,24.42]],"ltp":1.16,"tv":6760.84,"id":8326656},{"batl":[[1,8.4,4.44]],"ltp":6.6,"tv":616.09,"id":9712909}]}]}
{"op":"mcm","clk":"1002721148","pt":1580597802056,"mc":[{"id":"1.168179120","rc":[{"batl":[[1,8.4,4.69]],"ltp":6.6,"tv":616.09,"id":9712909}]}]}
{"op":"mcm","clk":"1002723445","pt":1580597842312,"mc":[{"id":"1.168179120","rc":[{"batl":[[1,8.4,5.04]],"ltp":6.6,"tv":616.09,"id":9712909}]}]}
{"op":"mcm","clk":"1002723796","pt":1580597848438,"mc":[{"id":"1.168179120","rc":[{"batb":[[0,6.6,13.01]],"batl":[[1,8.4,4.89]],"ltp":6.6,"tv":616.09,"id":9712909}]}]}
{"op":"mcm","clk":"1002727466","pt":1580597903798,"mc":[{"id":"1.168179120","rc":[{"batl":[[1,95,15.9],[2,990,2.2]],"ltp":6.6,"tv":616.09,"id":9712909}]}]}
{"op":"mcm","clk":"1002727494","pt":1580597904161,"mc":[{"id":"1.168179120","rc":[{"batl":[[1,8.4,9.53],[2,95,15.9]],"ltp":6.6,"tv":616.09,"id":9712909}]}]}
{"op":"mcm","clk":"1002727813","pt":1580597908857,"mc":[{"id":"1.168179120","rc":[{"batb":[[0,1.16,75.89],[2,1.14,28.74]],"ltp":1.16,"tv":6760.84,"id":8326656},{"batl":[[0,7.8,5.02],[1,8,4.81],[2,8.2,4.48]],"ltp":6.6,"tv":616.09,"id":9712909}]}]}
{"op":"mcm","clk":"1002727840","pt":1580597909268,"mc":[{"id":"1.168179120","rc":[{"batl":[[2,8.4,4.89]],"ltp":6.6,"tv":616.09,"id":9712909}]}]}
{"op":"mcm","clk":"1002731952","pt":1580597974849,"mc":[{"id":"1.168179120","rc":[{"batl":[[0,1.18,104.44]],"ltp":1.16,"tv":6760.84,"id":8326656},{"batl":[[1,8,5.06],[2,95,15.9]],"ltp":6.6,"tv":616.09,"id":9712909}]}]}
{"op":"mcm","clk":"1002732016","pt":1580597975831,"mc":[{"id":"1.168179120","rc":[{"trd":[[1.16,1063.29]],"batb":[[0,1.16,8.45]],"ltp":1.16,"tv":6895.72,"id":8326656},{"batl":[[0,8.2,4.78],[1,8.4,4.84],[2,8.6,4.91]],"ltp":6.6,"tv":616.09,"id":9712909}],"tv":7511.81}]}
{"op":"mcm","clk":"1002732056","pt":1580597976146,"mc":[{"id":"1.168179120","rc":[{"batl":[[0,8.2,4.48],[1,8.4,4.59]],"ltp":6.6,"tv":616.09,"id":9712909}]}]}
{"op":"mcm","clk":"1002732230","pt":1580597978329,"mc":[{"id":"1.168179120","rc":[{"batb":[[2,6,10.95]],"ltp":6.6,"tv":616.09,"id":9712909}]}]}
{"op":"mcm","clk":"1002732629","pt":1580597983769,"mc":[{"id":"1.168179120","rc":[{"batb":[[1,6.4,15]],"ltp":6.6,"tv":616.09,"id":9712909}]}]}
{"op":"mcm","clk":"1002732679","pt":1580597984336,"mc":[{"id":"1.168179120","rc":[{"batl":[[1,8.4,4.14],[2,95,15.9]],"ltp":6.6,"tv":616.09,"id":9712909}]}]}
{"op":"mcm","clk":"1002733034","pt":1580597989150,"mc":[{"id":"1.168179120","rc":[{"batb":[[1,6.4,16.58]],"ltp":6.6,"tv":616.09,"id":9712909}]}]}
{"op":"mcm","clk":"1002733266","pt":1580597992675,"mc":[{"id":"1.168179120","rc":[{"batl":[[0,1.18,78.68]],"ltp":1.16,"tv":6895.72,"id":8326656},{"batb":[[0,6.6,8.41]],"ltp":6.6,"tv":616.09,"id":9712909}]}]}
{"op":"mcm","clk":"1002734195","pt":1580598002882,"mc":[{"id":"1.168179120","rc":[{"trd":[[1.16,1133.49]],"batb":[[0,1.16,4.6]],"ltp":1.16,"tv":6965.92,"id":8326656},{"batl":[[1,8.4,3.49],[2,8.6,3.56]],"ltp":6.6,"tv":616.09,"id":9712909}],"tv":7582.01}]}
{"op":"mcm","clk":"1002734241","pt":1580598003297,"mc":[{"id":"1.168179120","rc":[{"batl":[[0,8.2,4.03],[1,8.4,3.89]],"ltp":6.6,"tv":616.09,"id":9712909}]}]}
{"op":"mcm","clk":"1002734375","pt":1580598004703,"mc":[{"id":"1.168179120","rc":[{"batl":[[0,1.17,65.12],[1,1.18,78.68],[2,1.19,202]],"ltp":1.16,"tv":6965.92,"id":8326656},{"batb":[[1,6.4,21.25]],"ltp":6.6,"tv":616.09,"id":9712909}]}]}
{"op":"mcm","clk":"1002734774","pt":1580598011272,"mc":[{"id":"1.168179120","rc":[{"batl":[[0,1.17,74.21]],"ltp":1.16,"tv":6965.92,"id":8326656},{"batl":[[1,8.4,3.59],[2,95,15.9]],"ltp":6.6,"tv":616.09,"id":9712909}]}]}
{"op":"mcm","clk":"1002734835","pt":1580598012298,"mc":[{"id":"1.168179120","rc":[{"batl":[[1,1.18,104.44]],"ltp":1.16,"tv":6965.92,"id":8326656},{"batb":[[0,6.6,13.01]],"ltp":6.6,"tv":616.09,"id":9712909}]}]}
{"op":"mcm","clk":"1002735868","pt":1580598027818,"mc":[{"id":"1.168179120","rc":[{"batb":[[1,1.15,410.75]],"ltp":1.16,"tv":6965.92,"id":8326656},{"batl":[[1,8.4,3.49]],"ltp":6.6,"tv":616.09,"id":9712909}]}]}
{"op":"mcm","clk":"1002736018","pt":1580598030699,"mc":[{"id":"1.168179120","rc":[{"trd":[[1.17,963.89]],"batl":[[0,1.18,104.44],[1,1.19,202],[2,1.2,15.14]],"ltp":1.17,"tv":7040.13,"id":8326656},{"trd":[[6.8,563.37]],"batl":[[0,6.8,110.45],[1,8.2,4.03],[2,8.4,3.49]],"ltp":6.8,"tv":628.86,"id":9712909}],"tv":7668.99}]}
{"op":"mcm","clk":"1002736093","pt":1580598031728,"mc":[{"id":"1.168179120","rc":[{"batb":[[1,1.15,417.38],[2,1.14,30.74]],"ltp":1.17,"tv":7040.13,"id":8326656},{"batb":[[0,6.6,8.41],[1,6.4,16.58],[2,6.2,4.85]],"batl":[[1,7.2,3.53],[2,7.4,3.79]],"ltp":6.8,"tv":628.86,"id":9712909}]}]}
{"op":"mcm","clk":"1002738082","pt":1580598059531,"mc":[{"id":"1.168179120","rc":[{"batb":[[2,1.14,30.24]],"ltp":1.17,"tv":7040.13,"id":8326656},{"batl":[[2,7.4,3.39]],"ltp":6.8,"tv":628.86,"id":9712909}]}]}
{"op":"mcm","clk":"1002738171","pt":1580598060458,"mc":[{"id":"1.168179120","rc":[{"trd":[[6.8,707.37]],"batl":[[0,6.8,38.44]],"ltp":6.8,"tv":772.86,"id":9712909}],"tv":7812.99}]}
{"op":"mcm","clk":"1002738234","pt":1580598061234,"mc":[{"id":"1.168179120","rc":[{"batb":[[0,6.6,13.01]],"ltp":6.8,"tv":772.86,"id":9712909}]}]}
{"op":"mcm","clk":"1002738765","pt":1580598068743,"mc":[{"id":"1.168179120","rc":[{"batb":[[2,1.14,30.74]],"ltp":1.17,"tv":7040.13,"id":8326656}]}]}
{"op":"mcm","clk":"1002739099","pt":1580598073564,"mc":[{"id":"1.168179120","rc":[{"batb":[[0,1.16,111.94]],"ltp":1.17,"tv":7040.13,"id":8326656},{"trd":[[6.8,729.85]],"batb":[[0,6.6,4.6],[1,6.4,28.54]],"batl":[[0,6.8,27.2]],"ltp":6.8,"tv":795.34,"id":9712909}],"tv":7835.48}]}
{"op":"mcm","clk":"1002739474","pt":1580598077755,"mc":[{"id":"1.168179120","rc":[{"batb":[[2,1.14,31.24]],"ltp":1.17,"tv":7040.13,"id":8326656},{"batb":[[0,6.4,28.54],[1,6,15.99],[2,5.6,12.67]],"batl":[[2,7.4,3.49]],"ltp":6.8,"tv":795.34,"id":9712909}]}]}
{"op":"mcm","clk":"1002739507","pt":1580598078073,"mc":[{"id":"1.168179120","rc":[{"batb":[[0,6.4,32.09]],"ltp":6.8,"tv":795.34,"id":9712909}]}]}
{"op":"mcm","clk":"1002742353","pt":1580598119576,"mc":[{"id":"1.168179120","rc":[{"batl":[[2,7.4,3.74]],"ltp":6.8,"tv":795.34,"id":9712909}]}]}
{"op":"mcm","clk":"1002742425","pt":1580598120460,"mc":[{"id":"1.168179120","rc":[{"trd":[[6.8,778.64]],"batl":[[0,6.8,2.81]],"ltp":6.8,"tv":844.13,"id":9712909}],"tv":7884.26}]}
{"op":"mcm","clk":"1002742848","pt":1580598127850,"mc":[{"id":"1.168179120","rc":[{"batb":[[0,1.16,112.44],[2,1.14,30.81]],"ltp":1.17,"tv":7040.13,"id":8326656},{"batl":[[2,7.4,3.99]],"ltp":6.8,"tv":844.13,"id":9712909}]}]}
{"op":"mcm","clk":"1002742879","pt":1580598128468,"mc":[{"id":"1.168179120","rc":[{"batb":[[0,1.16,111.94],[1,1.15,422.61]],"ltp":1.17,"tv":7040.13,"id":8326656}]}]}
{"op":"mcm","clk":"1002743019","pt":1580598130757,"mc":[{"id":"1.168179120","rc":[{"batb":[[0,6.6,4.6],[1,6.4,32.09],[2,6.2,4.85]],"ltp":6.8,"tv":844.13,"id":9712909}]}]}
{"op":"mcm","clk":"1002744334","pt":1580598150595,"mc":[{"id":"1.168179120","rc":[{"batb":[[0,1.16,186.15]],"ltp":1.17,"tv":7040.13,"id":8326656}]}]}
{"op":"mcm","clk":"1002744408","pt":1580598151786,"mc":[{"id":"1.168179120","rc":[{"trd":[[1.16,1437.21],[1.17,980.21]],"batb":[[0,1.16,34.29],[1,1.15,410.75],[2,1.14,30.24]],"ltp":1.16,"tv":7360.17,"id":8326656},{"trd":[[6.8,781.44]],"batl":[[0,7.6,4.01],[1,7.8,3.62],[2,95,15.9]],"ltp":6.8,"tv":846.93,"id":9712909}],"tv":8207.11}]}
{"op":"mcm","clk":"1002744471","pt":1580598152774,"mc":[{"id":"1.168179120","rc":[{"batb":[[1,1.15,437.15]],"ltp":1.16,"tv":7360.17,"id":8326656},{"batb":[[0,6.6,23.2]],"batl":[[0,7.8,4.02],[1,8,3.53],[2,8.2,3.68]],"ltp":6.8,"tv":846.93,"id":9712909}]}]}
{"op":"mcm","clk":"1002744514","pt":1580598153498,"mc":[{"id":"1.168179120","rc":[{"batl":[[0,1.17,25.76],[1,1.18,78.68],[2,1.19,202]],"ltp":1.16,"tv":7360.17,"id":8326656}]}]}
{"op":"mcm","clk":"1002744606","pt":1580598154685,"mc":[{"id":"1.168179120","rc":[{"batb":[[1,6.4,36.76]],"ltp":6.8,"tv":846.93,"id":9712909}]}]}
{"op":"mcm","clk":"1002744718","pt":1580598156719,"mc":[{"id":"1.168179120","rc":[{"batb":[[1,6.4,23.26]],"ltp":6.8,"tv":846.93,"id":9712909}]}]}
{"op":"mcm","clk":"1002745018","pt":1580598161608,"mc":[{"id":"1.168179120","rc":[{"batl":[[0,1.17,65.13]],"ltp":1.16,"tv":7360.17,"id":8326656}]}]}
{"op":"mcm","clk":"1002745038","pt":1580598162123,"mc":[{"id":"1.168179120","rc":[{"batb":[[0,6.6,29.91]],"batl":[[1,8,3.67],[2,95,15.9]],"ltp":6.8,"tv":846.93,"id":9712909}]}]}
{"op":"mcm","clk":"1002746103","pt":1580598177731,"mc":[{"id":"1.168179120","rc":[{"batl":[[0,1.17,65.35]],"ltp":1.16,"tv":7360.17,"id":8326656},{"batl":[[1,95,15.9],[2,990,2.2]],"ltp":6.8,"tv":846.93,"id":9712909}]}]}
{"op":"mcm","clk":"1002746163","pt":1580598178717,"mc":[{"id":"1.168179120","rc":[{"trd":[[1.16,1498.73]],"batb":[[0,1.16,3.53]],"ltp":1.16,"tv":7421.69,"id":8326656},{"batl":[[0,8.2,3.58],[1,8.4,3.39],[2,95,15.9]],"ltp":6.8,"tv":846.93,"id":9712909}],"tv":8268.63}]}
{"op":"mcm","clk":"1002746191","pt":1580598179132,"mc":[{"id":"1.168179120","rc":[{"batl":[[0,8.2,3.53],[1,8.4,3.79],[2,8.6,3.46]],"ltp":6.8,"tv":846.93,"id":9712909}]}]}
{"op":"mcm","clk":"1002746458","pt":1580598183644,"mc":[{"id":"1.168179120","rc":[{"batb":[[0,6.6,33.14]],"ltp":6.8,"tv":846.93,"id":9712909}]}]}
{"op":"mcm","clk":"1002746977","pt":1580598189814,"mc":[{"id":"1.168179120","rc":[{"trd":[[1.17,1064.38]],"batl":[[0,1.17,23.28]],"ltp":1.17,"tv":7505.87,"id":8326656},{"batb":[[0,7,4.6],[1,6.6,14.97],[2,6.4,23.26]],"batl":[[1,95,15.9],[2,990,2.2]],"ltp":6.8,"tv":846.93,"id":9712909}],"tv":8352.81}]}
{"op":"mcm","clk":"1002747066","pt":1580598190848,"mc":[{"id":"1.168179120","rc":[{"batb":[[0,1.16,91.21]],"ltp":1.17,"tv":7505.87,"id":8326656},{"batb":[[1,6.6,13.4]],"batl":[[0,7.8,3.37],[1,8,4.59],[2,8.4,3.34]],"ltp":6.8,"tv":846.93,"id":9712909}]}]}
{"op":"mcm","clk":"1002747137","pt":1580598191729,"mc":[{"id":"1.168179120","rc":[{"batb":[[1,6.6,17.91]],"ltp":6.8,"tv":846.93,"id":9712909}]}]}
{"op":"mcm","clk":"1002747918","pt":1580598203765,"mc":[{"id":"1.168179120","rc":[{"trd":[[1.16,1663.18]],"batb":[[0,1.16,8.98]],"ltp":1.16,"tv":7670.32,"id":8326656},{"batl":[[0,8,4.59],[1,8.2,3.63],[2,8.4,3.54]],"ltp":6.8,"tv":846.93,"id":9712909}],"tv":8517.26}]}
{"op":"mcm","clk":"1002747999","pt":1580598204753,"mc":[{"id":"1.168179120","rc":[{"batb":[[0,1.15,342.76],[1,1.14,229.66],[2,1.13,134.96]],"ltp":1.16,"tv":7670.32,"id":8326656},{"batb":[[1,6.8,16.66],[2,6.6,27.85]],"batl":[[0,8.2,3.63],[1,8.4,3.54],[2,95,15.9]],"ltp":6.8,"tv":846.93,"id":9712909}]}]}
{"op":"mcm","clk":"1002748078","pt":1580598205740,"mc":[{"id":"1.168179120","rc":[{"trd":[[1.17,1110.93]],"batb":[[0,1.17,44.09],[1,1.15,342.76],[2,1.14,229.66]],"batl":[[0,1.18,78.68],[1,1.19,202],[2,1.2,15.14]],"ltp":1.17,"tv":7716.87,"id":8326656},{"trd":[[7,11.32]],"batb":[[0,6.8,16.66],[1,6.6,23.35],[2,6.4,4.67]],"ltp":7.0,"tv":856.15,"id":9712909}],"tv":8573.03}]}
{"op":"mcm","clk":"1002748146","pt":1580598206732,"mc":[{"id":"1.168179120","rc":[{"batb":[[0,1.15,342.76],[1,1.14,229.66],[2,1.13,134.96]],"ltp":1.17,"tv":7716.87,"id":8326656}]}]}
{"op":"mcm","clk":"1002748393","pt":1580598209848,"mc":[{"id":"1.168179120","rc":[{"batb":[[1,6.6,13.41]],"batl":[[0,7.6,4],[1,8,3.78]],"ltp":7.0,"tv":856.15,"id":9712909}]}]}
{"op":"mcm","clk":"1002748428","pt":1580598210264,"mc":[{"id":"1.168179120","rc":[{"batl":[[2,8.2,3.43]],"ltp":7.0,"tv":856.15,"id":9712909}]}]}
{"op":"mcm","clk":"1002749317","pt":1580598221856,"mc":[{"id":"1.168179120","rc":[{"batl":[[0,1.17,34.83],[1,1.18,78.68],[2,1.19,202]],"ltp":1.17,"tv":7716.87,"id":8326656}]}]}
{"op":"mcm","clk":"1002749351","pt":1580598222272,"mc":[{"id":"1.168179120","rc":[{"batl":[[2,8.2,3.38]],"ltp":7.0,"tv":856.15,"id":9712909}]}]}
{"op":"mcm","clk":"1002749602","pt":1580598225373,"mc":[{"id":"1.168179120","rc":[{"batb":[[0,6.8,24.11]],"ltp":7.0,"tv":856.15,"id":9712909}]}]}
{"op":"mcm","clk":"1002750248","pt":1580598234777,"mc":[{"id":"1.168179120","rc":[{"trd":[[1.16,1726.79]],"batl":[[0,1.16,31.51],[1,1.17,34.83],[2,1.18,78.68]],"ltp":1.16,"tv":7780.47,"id":8326656},{"batb":[[0,6.8,28.45]],"batl":[[2,8.2,3.73]],"ltp":7.0,"tv":856.15,"id":9712909}],"tv":8636.63}]}
{"op":"mcm","clk":"1002750614","pt":1580598240800,"mc":[{"id":"1.168179120","rc":[{"trd":[[1.16,1789.8],[1.17,1180.6]],"batb":[[0,1.17,1.47],[1,1.15,342.76],[2,1.14,229.66]],"batl":[[0,1.18,78.68],[1,1.19,202],[2,1.2,15.14]],"ltp":1.17,"tv":7913.16,"id":8326656}],"tv":8769.31}]}
{"op":"mcm","clk":"1002750683","pt":1580598241792,"mc":[{"id":"1.168179120","rc":[{"trd":[[1.17,1183.54]],"batb":[[0,1.15,342.76],[1,1.14,229.66],[2,1.13,134.96]],"ltp":1.17,"tv":7916.1,"id":8326656},{"trd":[[6.8,828.13]],"batb":[[0,6.6,14.18],[1,6.4,4.67],[2,6.2,4.85]],"batl":[[2,8.2,3.78]],"ltp":6.8,"tv":902.83,"id":9712909}],"tv":8818.93}]}
{"op":"mcm","clk":"1002750745","pt":1580598242881,"mc":[{"id":"1.168179120","rc":[{"batb":[[0,1.16,106.56],[1,1.15,342.76],[2,1.14,30.31]],"ltp":1.17,"tv":7916.1,"id":8326656},{"batb":[[0,6.6,10.72],[1,6.4,18.74]],"batl":[[1,7.8,3.72],[2,8,3.78]],"ltp":6.8,"tv":902.83,"id":9712909}]}]}
{"op":"mcm","clk":"1002750797","pt":1580598243503,"mc":[{"id":"1.168179120","rc":[{"batl":[[2,8,3.55]],"ltp":6.8,"tv":902.83,"id":9712909}]}]}
{"op":"mcm","clk":"1002750936","pt":1580598245495,"mc":[{"id":"1.168179120","rc":[{"batb":[[0,1.16,132.76]],"batl":[[0,1.17,10.02],[1,1.18,78.68],[2,1.19,202]],"ltp":1.17,"tv":7916.1,"id":8326656}]}]}
{"op":"mcm","clk":"1002751015","pt":1580598246588,"mc":[{"id":"1.168179120","rc":[{"trd":[[1.16,1937.44]],"batb":[[0,1.16,58.94]],"ltp":1.16,"tv":8063.74,"id":8326656},{"batb":[[0,6.6,9.95]],"ltp":6.8,"tv":902.83,"id":9712909}],"tv":8966.57}]}
{"op":"mcm","clk":"1002751122","pt":1580598247793,"mc":[{"id":"1.168179120","rc":[{"trd":[[1.17,1193.56]],"batb":[[0,1.16,26.2],[1,1.15,470]],"batl":[[0,1.18,78.68],[1,1.19,202],[2,1.2,15.14]],"ltp":1.17,"tv":8073.76,"id":8326656},{"trd":[[6.8,855.24]],"batb":[[1,6.2,4.85],[2,6,10.95]],"batl":[[0,7.2,4],[1,7.6,3.66],[2,7.8,3.72]],"ltp":6.8,"tv":929.95,"id":9712909}],"tv":9003.71}]}
{"op":"mcm","clk":"1002751158","pt":1580598248205,"mc":[{"id":"1.168179120","rc":[{"batl":[[2,7.8,3.92]],"ltp":6.8,"tv":929.95,"id":9712909}]}]}
{"op":"mcm","clk":"1002751248","pt":1580598249805,"mc":[{"id":"1.168179120","rc":[{"batb":[[0,1.16,100.68]],"ltp":1.17,"tv":8073.76,"id":8326656},{"batb":[[1,6.4,18.63],[2,6.2,4.85]],"ltp":6.8,"tv":929.95,"id":9712909}]}]}
{"op":"mcm","clk":"1002751345","pt":1580598251925,"mc":[{"id":"1.168179120","rc":[{"batb":[[1,6.4,25.04]],"ltp":6.8,"tv":929.95,"id":9712909}]}]}
{"op":"mcm","clk":"1002751473","pt":1580598253789,"mc":[{"id":"1.168179120","rc":[{"batl":[[0,1.17,31.8],[1,1.18,78.68],[2,1.19,202]],"ltp":1.17,"tv":8073.76,"id":8326656},{"batb":[[1,6.4,29.71]],"ltp":6.8,"tv":929.95,"id":9712909}]}]}
{"op":"mcm","clk":"1002751496","pt":1580598254308,"mc":[{"id":"1.168179120","rc":[{"batl":[[2,7.8,3.37]],"ltp":6.8,"tv":929.95,"id":9712909}]}]}
{"op":"mcm","clk":"1002752314","pt":1580598267534,"mc":[{"id":"1.168179120","rc":[{"batb":[[0,1.16,174.89]],"ltp":1.17,"tv":8073.76,"id":8326656},{"batl":[[2,7.8,3.57]],"ltp":6.8,"tv":929.95,"id":9712909}]}]}
{"op":"mcm","clk":"1002752376","pt":1580598268524,"mc":[{"id":"1.168179120","rc":[{"batl":[[0,7.2,4.22]],"ltp":6.8,"tv":929.95,"id":9712909}]}]}
{"op":"mcm","clk":"1002754272","pt":1580598301760,"mc":[{"id":"1.168179120","rc":[{"batb":[[2,1.14,421.46]],"ltp":1.17,"tv":8073.76,"id":8326656}]}]}
{"op":"mcm","clk":"1002754299","pt":1580598302175,"mc":[{"id":"1.168179120","rc":[{"batl":[[2,7.8,3.77]],"ltp":6.8,"tv":929.95,"id":9712909}]}]}
{"op":"mcm","clk":"1002754545","pt":1580598305590,"mc":[{"id":"1.168179120","rc":[{"trd":[[1.17,1257.17]],"batl":[[0,1.18,78.68],[1,1.19,202],[2,1.2,15.14]],"ltp":1.17,"tv":8137.37,"id":8326656}],"tv":9067.32}]}
{"op":"mcm","clk":"1002754614","pt":1580598306796,"mc":[{"id":"1.168179120","rc":[{"batb":[[1,6.4,25.04]],"ltp":6.8,"tv":929.95,"id":9712909}]}]}
{"op":"mcm","clk":"1002754896","pt":1580598311860,"mc":[{"id":"1.168179120","rc":[{"batb":[[0,1.16,249.1]],"ltp":1.17,"tv":8137.37,"id":8326656}]}]}
{"op":"mcm","clk":"1002755062","pt":1580598313887,"mc":[{"id":"1.168179120","rc":[{"batb":[[0,6.6,11.72]],"ltp":6.8,"tv":929.95,"id":9712909}]}]}
{"op":"mcm","clk":"1002756747","pt":1580598341823,"mc":[{"id":"1.168179120","rc":[{"batb":[[0,1.16,296.42]],"ltp":1.17,"tv":8137.37,"id":8326656}]}]}
{"op":"mcm","clk":"1002756781","pt":1580598342191,"mc":[{"id":"1.168179120","rc":[{"batl":[[2,7.8,3.47]],"ltp":6.8,"tv":929.95,"id":9712909}]}]}
{"op":"mcm","clk":"1002761511","pt":1580598411784,"mc":[{"id":"1.168179120","rc":[{"batb":[[0,1.16,270.23]],"ltp":1.17,"tv":8137.37,"id":8326656},{"batb":[[0,6.6,9.95]],"batl":[[0,7.6,3.66],[1,7.8,3.47],[2,95,15.9]],"ltp":6.8,"tv":929.95,"id":9712909}]}]}
{"op":"mcm","clk":"1002761620","pt":1580598412870,"mc":[{"id":"1.168179120","rc":[{"batl":[[0,7.8,3.47],[1,8,3.53]],"ltp":6.8,"tv":929.95,"id":9712909}]}]}
{"op":"mcm","clk":"1002761949","pt":1580598417883,"mc":[{"id":"1.168179120","rc":[{"batl":[[0,7.2,4.22],[1,7.6,3.56],[2,7.8,3.47]],"ltp":6.8,"tv":929.95,"id":9712909}]}]}
{"op":"mcm","clk":"1002762023","pt":1580598418818,"mc":[{"id":"1.168179120","rc":[{"batb":[[0,6.6,11.76]],"batl":[[2,7.8,3.52]],"ltp":6.8,"tv":929.95,"id":9712909}]}]}
{"op":"mcm","clk":"1002778908","pt":1580598653870,"mc":[{"id":"1.168179120","rc":[{"batb":[[0,1.17,844.55],[1,1.16,270.23],[2,1.15,475.83]],"ltp":1.17,"tv":8137.37,"id":8326656},{"batl":[[2,95,15.9]],"ltp":6.8,"tv":929.95,"id":9712909}]}]}
{"op":"mcm","clk":"1002778940","pt":1580598654398,"mc":[{"id":"1.168179120","rc":[{"batb":[[0,1.17,874.94]],"ltp":1.17,"tv":8137.37,"id":8326656},{"batl":[[1,7.4,3.64],[2,7.6,3.51]],"ltp":6.8,"tv":929.95,"id":9712909}]}]}
{"op":"mcm","clk":"1002779716","pt":1580598664399,"mc":[{"id":"1.168179120","rc":[{"batl":[[2,7.6,3.41]],"ltp":6.8,"tv":929.95,"id":9712909}]}]}
{"op":"mcm","clk":"1002780230","pt":1580598671725,"mc":[{"id":"1.168179120","rc":[{"batl":[[0,6.8,4.22],[1,7.2,3.83],[2,95,15.9]],"ltp":6.8,"tv":929.95,"id":9712909}]}]}
{"op":"mcm","clk":"1002780246","pt":1580598671933,"mc":[{"id":"1.168179120","rc":[{"batl":[[2,7.4,3.74]],"ltp":6.8,"tv":929.95,"id":9712909}]}]}
{"op":"mcm","clk":"1002781151","pt":1580598683432,"mc":[{"id":"1.168179120","rc":[{"batb":[[0,1.17,844.55]],"ltp":1.17,"tv":8137.37,"id":8326656},{"batb":[[0,6.6,9.95]],"batl":[[0,7.4,3.74],[1,7.6,3.96],[2,95,15.9]],"ltp":6.8,"tv":929.95,"id":9712909}]}]}
{"op":"mcm","clk":"1002783872","pt":1580598719890,"mc":[{"id":"1.168179120","rc":[{"batl":[[1,7.6,3.66]],"ltp":6.8,"tv":929.95,"id":9712909}]}]}
{"op":"mcm","clk":"1002786401","pt":1580598750895,"mc":[{"id":"1.168179120","rc":[{"trd":[[6.6,48.94]],"batb":[[0,6.4,25.75],[1,6.2,4.85],[2,5.6,12.67]],"batl":[[1,95,15.9],[2,990,2.2]],"ltp":6.6,"tv":948.42,"id":9712909}],"tv":9085.79}]}
{"op":"mcm","clk":"1002786500","pt":1580598751881,"mc":[{"id":"1.168179120","rc":[{"batb":[[1,6,5.04]],"batl":[[1,7.6,3.81],[2,95,15.9]],"ltp":6.6,"tv":948.42,"id":9712909}]}]}
{"op":"mcm","clk":"1002788350","pt":1580598776261,"mc":[{"id":"1.168179120","rc":[{"batl":[[1,7.6,4.06]],"ltp":6.6,"tv":948.42,"id":9712909}]}]}
{"op":"mcm","clk":"1002789406","pt":1580598789854,"mc":[{"id":"1.168179120","rc":[{"batb":[[0,1.17,874.94]],"ltp":1.17,"tv":8137.37,"id":8326656},{"batb":[[0,6.6,2.56],[1,6.4,25.04],[2,6,5.04]],"batl":[[0,6.8,4.47],[1,7.2,7.66],[2,7.4,3.34]],"ltp":6.6,"tv":948.42,"id":9712909}]}]}
{"op":"mcm","clk":"1002790001","pt":1580598797657,"mc":[{"id":"1.168179120","rc":[{"batb":[[0,1.17,844.55]],"ltp":1.17,"tv":8137.37,"id":8326656},{"batb":[[0,6.4,25.75],[1,6,5.04],[2,5.6,12.67]],"batl":[[0,7.4,3.34],[1,7.6,3.76],[2,95,15.9]],"ltp":6.6,"tv":948.42,"id":9712909}]}]}
{"op":"mcm","clk":"1002790163","pt":1580598799542,"mc":[{"id":"1.168179120","rc":[{"batb":[[0,6.6,2.56],[1,6.4,25.04],[2,6,5.04]],"ltp":6.6,"tv":948.42,"id":9712909}]}]}
{"op":"mcm","clk":"1002791228","pt":1580598812688,"mc":[{"id":"1.168179120","rc":[{"batl":[[0,6.8,4.47],[1,7.2,3.58],[2,7.4,3.79]],"ltp":6.6,"tv":948.42,"id":9712909}]}]}
{"op":"mcm","clk":"1002791355","pt":1580598814154,"mc":[{"id":"1.168179120","rc":[{"batb":[[0,1.17,874.94]],"ltp":1.17,"tv":8137.37,"id":8326656}]}]}
{"op":"mcm","clk":"1002798163","pt":1580598901781,"mc":[{"id":"1.168179120","rc":[{"batl":[[2,95,15.9]],"ltp":6.6,"tv":948.42,"id":9712909}]}]}
{"op":"mcm","clk":"1002798179","pt":1580598901991,"mc":[{"id":"1.168179120","rc":[{"batl":[[2,7.4,3.84]],"ltp":6.6,"tv":948.42,"id":9712909}]}]}
{"op":"mcm","clk":"1002802732","pt":1580598963823,"mc":[{"id":"1.168179120","rc":[{"batb":[[0,1.17,844.55]],"ltp":1.17,"tv":8137.37,"id":8326656},{"batb":[[0,6.4,25.75],[1,6,5.04],[2,5.6,12.67]],"batl":[[0,7.4,3.84],[1,7.6,4.01],[2,95,15.9]],"ltp":6.6,"tv":948.42,"id":9712909}]}]}
{"op":"mcm","clk":"1002803284","pt":1580598970844,"mc":[{"id":"1.168179120","rc":[{"batb":[[0,1.17,874.94]],"ltp":1.17,"tv":8137.37,"id":8326656},{"batb":[[0,6.6,2.56],[1,6.4,25.04],[2,6,5.04]],"batl":[[0,6.8,4.47],[1,7.2,3.38],[2,7.4,3.84]],"ltp":6.6,"tv":948.42,"id":9712909}]}]}
{"op":"mcm","clk":"1002803332","pt":1580598971214,"mc":[{"id":"1.168179120","rc":[{"batl":[[2,7.4,3.44]],"ltp":6.6,"tv":948.42,"id":9712909}]}]}
{"op":"mcm","clk":"1002817841","pt":1580599179516,"mc":[{"id":"1.168179120","rc":[{"batl":[[0,1.18,95.32]],"ltp":1.17,"tv":8137.37,"id":8326656},{"batl":[[2,7.4,4.04]],"ltp":6.6,"tv":948.42,"id":9712909}]}]}
{"op":"mcm","clk":"1002825877","pt":1580599285616,"mc":[{"id":"1.168179120","rc":[{"batl":[[2,1.23,30.29]],"ltp":1.17,"tv":8137.37,"id":8326656},{"batl":[[2,7.4,3.74]],"ltp":6.6,"tv":948.42,"id":9712909}]}]}
{"op":"mcm","clk":"1002826296","pt":1580599290795,"mc":[{"id":"1.168179120","rc":[{"batb":[[0,1.17,844.55]],"batl":[[1,1.19,157.36]],"ltp":1.17,"tv":8137.37,"id":8326656},{"batb":[[0,6.4,25.75],[1,6,5.04],[2,5.6,12.67]],"batl":[[0,7.2,3.38],[1,7.4,3.74],[2,95,15.9]],"ltp":6.6,"tv":948.42,"id":9712909}]}]}
{"op":"mcm","clk":"1002826342","pt":1580599291325,"mc":[{"id":"1.168179120","rc":[{"batl":[[0,1.18,140.33]],"ltp":1.17,"tv":8137.37,"id":8326656},{"batl":[[0,7.4,3.74],[1,7.6,3.41]],"ltp":6.6,"tv":948.42,"id":9712909}]}]}
{"op":"mcm","clk":"1002826910","pt":1580599298821,"mc":[{"id":"1.168179120","rc":[{"batb":[[0,1.17,874.94]],"ltp":1.17,"tv":8137.37,"id":8326656},{"batl":[[0,6.8,4.47],[1,7.2,3.33],[2,7.4,3.74]],"ltp":6.6,"tv":948.42,"id":9712909}]}]}
{"op":"mcm","clk":"1002826956","pt":1580599299352,"mc":[{"id":"1.168179120","rc":[{"batb":[[0,6.6,2.56],[1,6.4,25.04],[2,6,5.04]],"batl":[[2,7.4,3.49]],"ltp":6.6,"tv":948.42,"id":9712909}]}]}
{"op":"mcm","clk":"1002832042","pt":1580599366407,"mc":[{"id":"1.168179120","rc":[{"batl":[[2,7.4,3.89]],"ltp":6.6,"tv":948.42,"id":9712909}]}]}
{"op":"mcm","clk":"1002834079","pt":1580599398655,"mc":[{"id":"1.168179120","rc":[{"batb":[[2,1.15,318.47]],"batl":[[0,1.18,61.65],[1,1.23,30.29],[2,1.5,90.87]],"ltp":1.17,"tv":8137.37,"id":8326656},{"batl":[[2,7.4,3.74]],"ltp":6.6,"tv":948.42,"id":9712909}]}]}
{"op":"mcm","clk":"1002836405","pt":1580599433261,"mc":[{"id":"1.168179120","rc":[{"batb":[[0,6.6,4.29]],"batl":[[2,7.4,3.64]],"ltp":6.6,"tv":948.42,"id":9712909}]}]}
{"op":"mcm","clk":"1002836456","pt":1580599434189,"mc":[{"id":"1.168179120","rc":[{"batb":[[2,6.2,4.85]],"ltp":6.6,"tv":948.42,"id":9712909}]}]}
{"op":"mcm","clk":"1002839687","pt":1580599479826,"mc":[{"id":"1.168179120","rc":[{"batb":[[1,1.16,222.9]],"ltp":1.17,"tv":8137.37,"id":8326656},{"batl":[[2,95,15.9]],"ltp":6.6,"tv":948.42,"id":9712909}]}]}
{"op":"mcm","clk":"1002839710","pt":1580599480033,"mc":[{"id":"1.168179120","rc":[{"batl":[[2,7.4,3.59]],"ltp":6.6,"tv":948.42,"id":9712909}]}]}
{"op":"mcm","clk":"1002840085","pt":1580599485031,"mc":[{"id":"1.168179120","rc":[{"batb":[[2,1.15,217.51]],"ltp":1.17,"tv":8137.37,"id":8326656}]}]}
{"op":"mcm","clk":"1002840918","pt":1580599496729,"mc":[{"id":"1.168179120","rc":[{"batb":[[1,6.4,6.41],[2,6.2,33.93]],"batl":[[2,95,15.9]],"ltp":6.6,"tv":948.42,"id":9712909}]}]}
{"op":"mcm","clk":"1002840934","pt":1580599496933,"mc":[{"id":"1.168179120","rc":[{"batl":[[2,7.4,3.79]],"ltp":6.6,"tv":948.42,"id":9712909}]}]}
{"op":"mcm","clk":"1002841155","pt":1580599500063,"mc":[{"id":"1.168179120","rc":[{"batb":[[1,6.2,33.93],[2,6,5.04]],"ltp":6.6,"tv":948.42,"id":9712909}]}]}
{"op":"mcm","clk":"1002841473","pt":1580599504756,"mc":[{"id":"1.168179120","rc":[{"batb":[[0,1.17,882.14],[1,1.16,230.17]],"batl":[[0,1.18,68.79],[1,1.19,7.08],[2,1.23,30.29]],"ltp":1.17,"tv":8137.37,"id":8326656},{"batb":[[0,6.6,5.97],[1,6.4,1.68],[2,6.2,33.93]],"batl":[[0,6.8,6.15],[1,7,1.68],[2,7.2,3.33]],"ltp":6.6,"tv":948.42,"id":9712909}]}]}
{"op":"mcm","clk":"1002841523","pt":1580599505444,"mc":[{"id":"1.168179120","rc":[{"batb":[[2,6.2,40.55]],"ltp":6.6,"tv":948.42,"id":9712909}]}]}
{"op":"mcm","clk":"1002843218","pt":1580599529801,"mc":[{"id":"1.168179120","rc":[{"batb":[[1,1.16,81.75]],"ltp":1.17,"tv":8137.37,"id":8326656}]}]}
{"op":"mcm","clk":"1002846787","pt":1580599580466,"mc":[{"id":"1.168179120","rc":[{"trd":[[1.18,183.92]],"batl":[[0,1.18,67.11]],"ltp":1.18,"tv":8140.73,"id":8326656}],"tv":9089.16}]}
{"op":"mcm","clk":"1002854398","pt":1580599677692,"mc":[{"id":"1.168179120","rc":[{"batl":[[0,1.18,22.1]],"ltp":1.18,"tv":8140.73,"id":8326656}]}]}
{"op":"mcm","clk":"1002854447","pt":1580599678264,"mc":[{"id":"1.168179120","rc":[{"batb":[[0,6.6,2.45],[2,6.2,42.23]],"ltp":6.6,"tv":948.42,"id":9712909}]}]}
{"op":"mcm","clk":"1002854523","pt":1580599679380,"mc":[{"id":"1.168179120","rc":[{"batl":[[1,1.19,51.72]],"ltp":1.18,"tv":8140.73,"id":8326656},{"batb":[[2,6.2,37.38]],"ltp":6.6,"tv":948.42,"id":9712909}]}]}
{"op":"mcm","clk":"1002860846","pt":1580599758855,"mc":[{"id":"1.168179120","rc":[{"batl":[[1,1.19,7.08]],"ltp":1.18,"tv":8140.73,"id":8326656}]}]}
{"op":"mcm","clk":"1002860961","pt":1580599760158,"mc":[{"id":"1.168179120","rc":[{"trd":[[1.17,1347.97]],"batb":[[0,1.17,836.73]],"ltp":1.17,"tv":8231.53,"id":8326656}],"tv":9179.96}]}
{"op":"mcm","clk":"1002861153","pt":1580599762774,"mc":[{"id":"1.168179120","rc":[{"batl":[[2,1.54,5.07]],"ltp":1.17,"tv":8231.53,"id":8326656}]}]}
{"op":"mcm","clk":"1002862293","pt":1580599777786,"mc":[{"id":"1.168179120","rc":[{"batl":[[0,1.18,122.1]],"ltp":1.17,"tv":8231.53,"id":8326656}]}]}
{"op":"mcm","clk":"1002862351","pt":1580599778622,"mc":[{"id":"1.168179120","rc":[{"batb":[[0,6.6,4.13]],"ltp":6.6,"tv":948.42,"id":9712909}]}]}
{"op":"mcm","clk":"1002862406","pt":1580599779317,"mc":[{"id":"1.168179120","rc":[{"batb":[[2,6.2,42.23]],"ltp":6.6,"tv":948.42,"id":9712909}]}]}
{"op":"mcm","clk":"1002862664","pt":1580599782520,"mc":[{"id":"1.168179120","rc":[{"batb":[[2,6.2,35.61]],"ltp":6.6,"tv":948.42,"id":9712909}]}]}
{"op":"mcm","clk":"1002862756","pt":1580599783714,"mc":[{"id":"1.168179120","rc":[{"batl":[[0,1.18,133.36]],"ltp":1.17,"tv":8231.53,"id":8326656},{"batb":[[0,6.6,5.97]],"ltp":6.6,"tv":948.42,"id":9712909}]}]}
{"op":"mcm","clk":"1002863159","pt":1580599788415,"mc":[{"id":"1.168179120","rc":[{"batb":[[1,6.4,8.1]],"ltp":6.6,"tv":948.42,"id":9712909}]}]}
{"op":"mcm","clk":"1002865004","pt":1580599808729,"mc":[{"id":"1.168179120","rc":[{"trd":[[6.6,60.89]],"batb":[[0,6.4,8.1],[1,6.2,35.61],[2,6,5.04]],"batl":[[0,6.6,9.18],[1,6.8,6.15],[2,7,5.95]],"ltp":6.6,"tv":960.37,"id":9712909}],"tv":9191.9}]}
{"op":"mcm","clk":"1002865089","pt":1580599809562,"mc":[{"id":"1.168179120","rc":[{"batl":[[0,1.18,114.95],[2,1.2,7.11]],"ltp":1.17,"tv":8231.53,"id":8326656},{"batb":[[1,6.2,30.76]],"ltp":6.6,"tv":960.37,"id":9712909}]}]}
{"op":"mcm","clk":"1002871176","pt":1580599879822,"mc":[{"id":"1.168179120","rc":[{"trd":[[6.6,78.9]],"batl":[[0,6.8,6.32],[1,7,5.95],[2,7.2,3.88]],"ltp":6.6,"tv":978.38,"id":9712909}],"tv":9209.92}]}
{"op":"mcm","clk":"1002871237","pt":1580599880500,"mc":[{"id":"1.168179120","rc":[{"batb":[[0,1.17,906.87],[2,1.15,90.27]],"batl":[[0,1.18,122.2]],"ltp":1.17,"tv":8231.53,"id":8326656},{"batb":[[1,6.2,1.68]],"batl":[[1,7,1.68]],"ltp":6.6,"tv":978.38,"id":9712909}]}]}
{"op":"mcm","clk":"1002871713","pt":1580599886746,"mc":[{"id":"1.168179120","rc":[{"batl":[[0,1.18,123.1]],"ltp":1.17,"tv":8231.53,"id":8326656}]}]}
{"op":"mcm","clk":"1002883631","pt":1580600052759,"mc":[{"id":"1.168179120","rc":[{"trd":[[1.18,419.42]],"batl":[[0,1.18,5.35]],"ltp":1.18,"tv":8467.03,"id":8326656}],"tv":9445.42}]}
{"op":"mcm","clk":"1002883678","pt":1580600053482,"mc":[{"id":"1.168179120","rc":[{"trd":[[1.18,430.12]],"batb":[[0,1.18,25.15],[1,1.17,906.87],[2,1.16,88.53]],"batl":[[0,1.19,7.08],[1,1.2,7.11],[2,1.54,5.07]],"ltp":1.18,"tv":8477.74,"id":8326656},{"batl":[[1,7,5.09],[2,7.2,3.53]],"ltp":6.6,"tv":978.38,"id":9712909}],"tv":9456.12}]}
{"op":"mcm","clk":"1002883781","pt":1580600054785,"mc":[{"id":"1.168179120","rc":[{"batb":[[0,1.18,32.46]],"ltp":1.18,"tv":8477.74,"id":8326656},{"batb":[[0,6.2,1.68],[1,6,6.72],[2,5.7,49.93]],"ltp":6.6,"tv":978.38,"id":9712909}]}]}
{"op":"mcm","clk":"1002883823","pt":1580600055352,"mc":[{"id":"1.168179120","rc":[{"batb":[[0,1.18,25.15]],"ltp":1.18,"tv":8477.74,"id":8326656},{"batb":[[1,6,1.68],[2,5.7,55.29]],"ltp":6.6,"tv":978.38,"id":9712909}]}]}
{"op":"mcm","clk":"1002884053","pt":1580600058661,"mc":[{"id":"1.168179120","rc":[{"batb":[[0,1.18,33.37],[1,1.17,876.47]],"ltp":1.18,"tv":8477.74,"id":8326656},{"batl":[[0,6.6,1.85],[1,6.8,6.15],[2,7,5.95]],"ltp":6.6,"tv":978.38,"id":9712909}]}]}
{"op":"mcm","clk":"1002884194","pt":1580600060702,"mc":[{"id":"1.168179120","rc":[{"batb":[[2,5.7,60.28]],"ltp":6.6,"tv":978.38,"id":9712909}]}]}
{"op":"mcm","clk":"1002884597","pt":1580600066799,"mc":[{"id":"1.168179120","rc":[{"batl":[[1,6.8,1.68]],"ltp":6.6,"tv":978.38,"id":9712909}]}]}
{"op":"mcm","clk":"1002884654","pt":1580600067677,"mc":[{"id":"1.168179120","rc":[{"batl":[[0,1.2,7.11],[1,1.21,7.13]],"ltp":1.18,"tv":8477.74,"id":8326656},{"batl":[[0,6.4,4.47],[1,6.6,1.85],[2,6.8,5.05]],"ltp":6.6,"tv":978.38,"id":9712909}]}]}
{"op":"mcm","clk":"1002884690","pt":1580600068399,"mc":[{"id":"1.168179120","rc":[{"batb":[[0,6,1.68],[1,5.9,1.68]],"ltp":6.6,"tv":978.38,"id":9712909}]}]}
{"op":"mcm","clk":"1002885194","pt":1580600076689,"mc":[{"id":"1.168179120","rc":[{"batl":[[0,6.4,4.75]],"ltp":6.6,"tv":978.38,"id":9712909}]}]}
{"op":"mcm","clk":"1002889004","pt":1580600133893,"mc":[{"id":"1.168179120","rc":[{"trd":[[6.4,11.52]],"batb":[[2,5.7,10.35]],"batl":[[0,6.6,1.85],[1,6.8,1.68],[2,7,5.95]],"ltp":6.4,"tv":987.89,"id":9712909}],"tv":9465.63}]}
{"op":"mcm","clk":"1002889024","pt":1580600134192,"mc":[{"id":"1.168179120","rc":[{"batb":[[1,1.17,902.37]],"ltp":1.18,"tv":8477.74,"id":8326656},{"batb":[[0,6,27.9]],"ltp":6.4,"tv":987.89,"id":9712909}]}]}
{"op":"mcm","clk":"1002889120","pt":1580600135481,"mc":[{"id":"1.168179120","rc":[{"batb":[[0,6.2,1.68],[1,6,27.9],[2,5.9,1.68]],"ltp":6.4,"tv":987.89,"id":9712909}]}]}
{"op":"mcm","clk":"1002889465","pt":1580600140798,"mc":[{"id":"1.168179120","rc":[{"batb":[[1,6,31.56]],"ltp":6.4,"tv":987.89,"id":9712909}]}]}
{"op":"mcm","clk":"1002890039","pt":1580600148809,"mc":[{"id":"1.168179120","rc":[{"batl":[[0,6.4,3.87],[1,6.6,1.85],[2,6.8,5.05]],"ltp":6.4,"tv":987.89,"id":9712909}]}]}
{"op":"mcm","clk":"1002904369","pt":1580600373813,"mc":[{"id":"1.168179120","rc":[{"trd":[[1.2,22.6]],"batl":[[0,1.2,3.11]],"ltp":1.2,"tv":8485.73,"id":8326656},{"batb":[[0,6,31.56],[1,5.9,1.68],[2,5.7,5.36]],"ltp":6.4,"tv":987.89,"id":9712909}],"tv":9473.63}]}
{"op":"mcm","clk":"1002904435","pt":1580600374706,"mc":[{"id":"1.168179120","rc":[{"batb":[[1,1.17,910.34],[2,1.16,89.53]],"batl":[[0,1.21,7.13],[1,1.22,7.18]],"ltp":1.2,"tv":8485.73,"id":8326656},{"batb":[[0,6,29.88],[2,5.8,1.68]],"ltp":6.4,"tv":987.89,"id":9712909}]}]}
{"op":"mcm","clk":"1002904472","pt":1580600375320,"mc":[{"id":"1.168179120","rc":[{"batb":[[1,1.17,902.37]],"ltp":1.2,"tv":8485.73,"id":8326656},{"batb":[[0,6,31.56]],"ltp":6.4,"tv":987.89,"id":9712909}]}]}
{"op":"mcm","clk":"1002904541","pt":1580600376311,"mc":[{"id":"1.168179120","rc":[{"batb":[[0,1.19,7.37],[1,1.18,33.37],[2,1.17,917.78]],"ltp":1.2,"tv":8485.73,"id":8326656}]}]}
{"op":"mcm","clk":"1002905374","pt":1580600390858,"mc":[{"id":"1.168179120","rc":[{"trd":[[1.19,29.61]],"batb":[[0,1.18,33.37],[1,1.17,902.37],[2,1.16,89.53]],"ltp":1.19,"tv":8500.47,"id":8326656},{"batb":[[0,6,30.16]],"ltp":6.4,"tv":987.89,"id":9712909}],"tv":9488.37}]}
{"op":"mcm","clk":"1002905381","pt":1580600390960,"mc":[{"id":"1.168179120","rc":[{"batb":[[1,1.17,909.83]],"ltp":1.19,"tv":8500.47,"id":8326656},{"batb":[[0,6.2,1.68],[1,6,30.16],[2,5.9,1.68]],"ltp":6.4,"tv":987.89,"id":9712909}]}]}
{"op":"mcm","clk":"1002911233","pt":1580600473817,"mc":[{"id":"1.168179120","rc":[{"batl":[[2,6.8,5.5]],"ltp":6.4,"tv":987.89,"id":9712909}]}]}
{"op":"mcm","clk":"1002925279","pt":1580600693799,"mc":[{"id":"1.168179120","rc":[{"batb":[[0,1.19,10],[1,1.18,33.37],[2,1.17,909.83]],"ltp":1.19,"tv":8500.47,"id":8326656}]}]}
{"op":"mcm","clk":"1002925328","pt":1580600694476,"mc":[{"id":"1.168179120","rc":[{"batb":[[2,1.17,917.8]],"ltp":1.19,"tv":8500.47,"id":8326656}]}]}
{"op":"mcm","clk":"1002925390","pt":1580600695498,"mc":[{"id":"1.168179120","rc":[{"batb":[[0,1.19,17.52]],"ltp":1.19,"tv":8500.47,"id":8326656},{"batb":[[0,6,30.16],[1,5.9,1.68],[2,5.8,1.68]],"ltp":6.4,"tv":987.89,"id":9712909}]}]}
{"op":"mcm","clk":"1002930266","pt":1580600774691,"mc":[{"id":"1.168179120","rc":[{"trd":[[1.19,64.65]],"batb":[[0,1.18,33.37],[1,1.17,909.83],[2,1.16,88.53]],"ltp":1.19,"tv":8535.51,"id":8326656},{"batb":[[0,6.2,1.68],[1,6,30.16],[2,5.9,1.68]],"ltp":6.4,"tv":987.89,"id":9712909}],"tv":9523.4}]}
{"op":"mcm","clk":"1002930369","pt":1580600776572,"mc":[{"id":"1.168179120","rc":[{"batb":[[0,1.18,51.08],[2,1.16,14.05]],"ltp":1.19,"tv":8535.51,"id":8326656},{"batb":[[1,6,26.8]],"ltp":6.4,"tv":987.89,"id":9712909}]}]}
{"op":"mcm","clk":"1002931065","pt":1580600786708,"mc":[{"id":"1.168179120","rc":[{"batl":[[0,1.19,49.21],[1,1.21,7.13],[2,1.22,7.18]],"ltp":1.19,"tv":8535.51,"id":8326656}]}]}
{"op":"mcm","clk":"1002931135","pt":1580600787698,"mc":[{"id":"1.168179120","rc":[{"batl":[[0,1.19,56.78],[1,1.2,7.51],[2,1.21,7.13]],"ltp":1.19,"tv":8535.51,"id":8326656},{"batb":[[2,5.9,6.82]],"ltp":6.4,"tv":987.89,"id":9712909}]}]}
{"op":"mcm","clk":"1002931171","pt":1580600788425,"mc":[{"id":"1.168179120","rc":[{"batb":[[1,6,29.97]],"batl":[[0,6.4,2.19]],"ltp":6.4,"tv":987.89,"id":9712909}]}]}
{"op":"mcm","clk":"1002931684","pt":1580600794842,"mc":[{"id":"1.168179120","rc":[{"batl":[[0,6.6,3.98],[1,6.8,5.5],[2,7,1.68]],"ltp":6.4,"tv":987.89,"id":9712909}]}]}
{"op":"mcm","clk":"1002931708","pt":1580600794995,"mc":[{"id":"1.168179120","rc":[{"batl":[[1,6.8,1.68],[2,7,4.99]],"ltp":6.4,"tv":987.89,"id":9712909}]}]}
{"op":"mcm","clk":"1002945707","pt":1580601002617,"mc":[{"id":"1.168179120","rc":[{"batb":[[0,1.18,25.93]],"ltp":1.19,"tv":8535.51,"id":8326656}]}]}
{"op":"mcm","clk":"1002945918","pt":1580601005844,"mc":[{"id":"1.168179120","rc":[{"batb":[[0,1.18,25.02],[1,1.17,910.74]],"ltp":1.19,"tv":8535.51,"id":8326656}]}]}
{"op":"mcm","clk":"1002945970","pt":1580601006446,"mc":[{"id":"1.168179120","rc":[{"batl":[[0,6.6,1.85],[1,6.8,3.74],[2,7,5.95]],"ltp":6.4,"tv":987.89,"id":9712909}]}]}
{"op":"mcm","clk":"1002947182","pt":1580601023850,"mc":[{"id":"1.168179120","rc":[{"trd":[[1.18,430.15]],"batb":[[0,1.18,25]],"ltp":1.18,"tv":8535.54,"id":8326656}],"tv":9523.44}]}
{"op":"mcm","clk":"1002947829","pt":1580601033878,"mc":[{"id":"1.168179120","rc":[{"batl":[[0,1.19,7.57]],"ltp":1.18,"tv":8535.54,"id":8326656}]}]}
{"op":"mcm","clk":"1002947896","pt":1580601034860,"mc":[{"id":"1.168179120","rc":[{"trd":[[1.17,1396.47],[1.18,480.14]],"batb":[[0,1.17,886.47],[1,1.16,7.27],[2,1.15,93.07]],"ltp":1.17,"tv":8634.02,"id":8326656},{"batb":[[2,5.9,1.68]],"batl":[[0,6.6,3.91],[1,6.8,1.68],[2,7,1.68]],"ltp":6.4,"tv":987.89,"id":9712909}],"tv":9621.91}]}
{"op":"mcm","clk":"1002947972","pt":1580601035846,"mc":[{"id":"1.168179120","rc":[{"batb":[[0,1.17,886.43]],"ltp":1.17,"tv":8634.02,"id":8326656},{"batb":[[0,6.2,5.05],[2,5.9,6.82]],"batl":[[0,6.6,2.23],[2,7,5.95]],"ltp":6.4,"tv":987.89,"id":9712909}]}]}
{"op":"mcm","clk":"1002947986","pt":1580601036050,"mc":[{"id":"1.168179120","rc":[{"batb":[[0,6.4,1.68],[1,6.2,5.05],[2,6,29.97]],"ltp":6.4,"tv":987.89,"id":9712909}]}]}
{"op":"mcm","clk":"1002948659","pt":1580601046384,"mc":[{"id":"1.168179120","rc":[{"batl":[[0,6.6,2.3]],"ltp":6.4,"tv":987.89,"id":9712909}]}]}
{"op":"mcm","clk":"1002948736","pt":1580601047469,"mc":[{"id":"1.168179120","rc":[{"batl":[[0,6.6,3.98]],"ltp":6.4,"tv":987.89,"id":9712909}]}]}
{"op":"mcm","clk":"1002948927","pt":1580601050176,"mc":[{"id":"1.168179120","rc":[{"batb":[[0,1.17,886.45]],"ltp":1.17,"tv":8634.02,"id":8326656}]}]}
{"op":"mcm","clk":"1002949166","pt":1580601053849,"mc":[{"id":"1.168179120","rc":[{"batb":[[0,1.18,8.76],[1,1.17,885.53],[2,1.16,15.8]],"ltp":1.17,"tv":8634.02,"id":8326656}]}]}
{"op":"mcm","clk":"1002949391","pt":1580601057690,"mc":[{"id":"1.168179120","rc":[{"batb":[[0,6.2,5.05],[1,6,29.97],[2,5.9,6.82]],"ltp":6.4,"tv":987.89,"id":9712909}]}]}
{"op":"mcm","clk":"1002958053","pt":1580601176775,"mc":[{"id":"1.168179120","rc":[{"trd":[[1.19,69.19]],"batl":[[0,1.19,5.3]],"ltp":1.19,"tv":8638.56,"id":8326656}],"tv":9626.45}]}
{"op":"mcm","clk":"1002958123","pt":1580601177783,"mc":[{"id":"1.168179120","rc":[{"batl":[[0,1.2,7.51],[1,1.21,7.13],[2,1.22,7.18]],"ltp":1.19,"tv":8638.56,"id":8326656}]}]}
{"op":"mcm","clk":"1002964503","pt":1580601272860,"mc":[{"id":"1.168179120","rc":[{"trd":[[1.2,37.08]],"batl":[[0,1.21,7.4],[1,1.22,7.18],[2,1.54,5.07]],"ltp":1.2,"tv":8653.04,"id":8326656}],"tv":9640.93}]}
{"op":"mcm","clk":"1002964557","pt":1580601273685,"mc":[{"id":"1.168179120","rc":[{"trd":[[1.2,106.18]],"batl":[[0,1.21,7.13]],"ltp":1.2,"tv":8722.14,"id":8326656},{"trd":[[6,10.35],[6.2,5.39]],"batb":[[0,6,19.63],[1,5.9,6.82],[2,5.7,5.36]],"ltp":6.0,"tv":1001.59,"id":9712909}],"tv":9723.73}]}
{"op":"mcm","clk":"1002964634","pt":1580601274776,"mc":[{"id":"1.168179120","rc":[{"trd":[[1.2,126.26],[1.21,55.59]],"batb":[[0,1.21,20.64],[1,1.18,149.96],[2,1.17,885.53]],"batl":[[0,1.22,7.18],[1,1.54,5.07],[2,95,15.95]],"ltp":1.21,"tv":8797.8,"id":8326656},{"trd":[[5.8,1.68],[5.9,6.82],[6,42.25]],"batb":[[0,5.7,15.44],[1,5.6,12.67],[2,5.5,5.6]],"ltp":5.8,"tv":1041.99,"id":9712909}],"tv":9839.8}]}
{"op":"mcm","clk":"1002964743","pt":1580601275874,"mc":[{"id":"1.168179120","rc":[{"trd":[[1.22,75.7]],"batb":[[0,1.19,8.71],[1,1.18,158.82],[2,1.17,894.5]],"batl":[[0,1.23,7.78]],"ltp":1.22,"tv":8873.5,"id":8326656},{"trd":[[5.6,15.38],[5.7,44.26]],"batb":[[0,5.5,1.74],[1,5.3,5.92],[2,5,13.69]],"batl":[[0,5.6,21.51],[1,5.9,17.75],[2,6,3.82]],"ltp":5.6,"tv":1101.63,"id":9712909}],"tv":9975.14}]}
{"op":"mcm","clk":"1002964803","pt":1580601276800,"mc":[{"id":"1.168179120","rc":[{"trd":[[1.23,23.34]],"batb":[[0,1.22,46.95],[1,1.2,8.72],[2,1.19,149.63]],"batl":[[0,1.54,11.28],[1,1.55,6.18]],"ltp":1.23,"tv":8896.84,"id":8326656},{"trd":[[5.3,24],[5.5,1.74]],"batb":[[0,5.2,1.84],[1,5.1,1.88]],"batl":[[0,5.5,3.95],[1,5.6,21.51],[2,5.8,3.67]],"ltp":5.3,"tv":1127.38,"id":9712909}],"tv":10024.23}]}
{"op":"mcm","clk":"1002964836","pt":1580601277212,"mc":[{"id":"1.168179120","rc":[{"batb":[[0,5.1,1.88],[1,5,15.61],[2,4.8,30.31]],"batl":[[0,5.6,21.51],[1,5.8,3.67],[2,5.9,17.95]],"ltp":5.3,"tv":1127.38,"id":9712909}]}]}
{"op":"mcm","clk":"1002964941","pt":1580601278811,"mc":[{"id":"1.168179120","rc":[{"trd":[[1.22,169.64]],"batb":[[0,1.21,47.86],[1,1.19,16.97],[2,1.18,157.66]],"ltp":1.22,"tv":8990.78,"id":8326656},{"trd":[[5.6,26.82]],"batb":[[0,5.2,28.89],[1,5.1,1.88],[2,5,15.61]],"batl":[[0,5.6,15.79]],"ltp":5.6,"tv":1138.82,"id":9712909}],"tv":10129.61}]}
{"op":"mcm","clk":"1002965002","pt":1580601279692,"mc":[{"id":"1.168179120","rc":[{"batb":[[0,5.2,30.74],[1,5.1,3.88]],"ltp":5.6,"tv":1138.82,"id":9712909}]}]}
{"op":"mcm","clk":"1002965064","pt":1580601280783,"mc":[{"id":"1.168179120","rc":[{"batb":[[2,5,21.91]],"ltp":5.6,"tv":1138.82,"id":9712909}]}]}
{"op":"mcm","clk":"1002965140","pt":1580601281889,"mc":[{"id":"1.168179120","rc":[{"batb":[[1,1.2,150.63],[2,1.19,16.97]],"ltp":1.22,"tv":8990.78,"id":8326656}]}]}
{"op":"mcm","clk":"1002965168","pt":1580601282302,"mc":[{"id":"1.168179120","rc":[{"batl":[[2,5.9,17.35]],"ltp":5.6,"tv":1138.82,"id":9712909}]}]}
{"op":"mcm","clk":"1002965238","pt":1580601283483,"mc":[{"id":"1.168179120","rc":[{"batl":[[2,5.9,19.03]],"ltp":5.6,"tv":1138.82,"id":9712909}]}]}
{"op":"mcm","clk":"1002965339","pt":1580601284727,"mc":[{"id":"1.168179120","rc":[{"batb":[[0,1.21,48.76],[1,1.2,158.75],[2,1.19,16.76]],"ltp":1.22,"tv":8990.78,"id":8326656},{"batl":[[0,5.5,2.55],[1,5.6,15.79],[2,5.7,3.95]],"ltp":5.6,"tv":1138.82,"id":9712909}]}]}
{"op":"mcm","clk":"1002965732","pt":1580601290834,"mc":[{"id":"1.168179120","rc":[{"batb":[[0,1.21,56.71]],"ltp":1.22,"tv":8990.78,"id":8326656}]}]}
{"op":"mcm","clk":"1002965753","pt":1580601291146,"mc":[{"id":"1.168179120","rc":[{"batb":[[2,1.19,15.97]],"ltp":1.22,"tv":8990.78,"id":8326656}]}]}
{"op":"mcm","clk":"1002966412","pt":1580601300836,"mc":[{"id":"1.168179120","rc":[{"trd":[[1.22,172.55]],"batb":[[0,1.21,47.86],[1,1.2,142.63],[2,1.19,8.71]],"batl":[[0,1.54,5.07],[1,95,15.95],[2,990,2.2]],"ltp":1.22,"tv":8993.69,"id":8326656},{"trd":[[5.2,28.94],[5.5,1.98]],"batb":[[0,5.2,14.43],[1,5.1,2],[2,5,19.99]],"batl":[[0,5.5,2.3]],"ltp":5.5,"tv":1168.0,"id":9712909}],"tv":10161.69}]}
{"op":"mcm","clk":"1002966493","pt":1580601301718,"mc":[{"id":"1.168179120","rc":[{"batb":[[0,1.21,109.72]],"ltp":1.22,"tv":8993.69,"id":8326656},{"batb":[[0,5.1,24.86],[1,5,19.99],[2,4.9,8.52]],"batl":[[0,5.5,2.06],[2,5.8,3.87]],"ltp":5.5,"tv":1168.0,"id":9712909}]}]}
{"op":"mcm","clk":"1002966537","pt":1580601302231,"mc":[{"id":"1.168179120","rc":[{"batb":[[1,1.2,150.6]],"ltp":1.22,"tv":8993.69,"id":8326656},{"batb":[[1,5,13.69]],"batl":[[2,5.7,3.85]],"ltp":5.5,"tv":1168.0,"id":9712909}]}]}
{"op":"mcm","clk":"1002966638","pt":1580601304042,"mc":[{"id":"1.168179120","rc":[{"trd":[[1.25,0.05]],"ltp":1.25,"tv":8993.74,"id":8326656},{"trd":[[5.1,0.01]],"batb":[[0,5.1,24.85]],"ltp":5.1,"tv":1168.01,"id":9712909}],"tv":10161.75}]}
{"op":"mcm","clk":"1002966756","pt":1580601305808,"mc":[{"id":"1.168179120","rc":[{"batl":[[0,5.5,2.3],[2,5.7,4.05]],"ltp":5.1,"tv":1168.01,"id":9712909}]}]}
{"op":"mcm","clk":"1002967433","pt":1580601315534,"mc":[{"id":"1.168179120","rc":[{"trd":[[1.25,1.05]],"ltp":1.25,"tv":8994.74,"id":8326656},{"trd":[[5.1,0.26]],"batb":[[0,5.1,24.6]],"ltp":5.1,"tv":1168.26,"id":9712909}],"tv":10163.0}]}
{"op":"mcm","clk":"1002969531","pt":1580601345760,"mc":[{"id":"1.168179120","rc":[{"trd":[[1.22,182.95]],"batb":[[1,1.2,142.63]],"batl":[[0,1.22,121.75],[1,1.54,5.07],[2,95,15.95]],"ltp":1.22,"tv":9005.14,"id":8326656},{"trd":[[5.5,4.29]],"batb":[[0,5.3,2.08],[1,5.2,8.02],[2,5.1,24.6]],"batl":[[0,5.6,15.79],[1,5.8,3.87],[2,5.9,17.55]],"ltp":5.5,"tv":1170.56,"id":9712909}],"tv":10175.71}]}
{"op":"mcm","clk":"1002969699","pt":1580601348091,"mc":[{"id":"1.168179120","rc":[{"trd":[[5.6,27.26]],"batl":[[0,5.6,15.57]],"ltp":5.6,"tv":1171.0,"id":9712909}],"tv":10176.15}]}
{"op":"mcm","clk":"1002973610","pt":1580601402856,"mc":[{"id":"1.168179120","rc":[{"batl":[[0,1.54,5.07],[1,95,15.95],[2,990,2.2]],"ltp":1.22,"tv":9005.14,"id":8326656},{"batb":[[0,5.2,6],[1,5.1,24.6],[2,5,15.69]],"batl":[[2,5.9,17.75]],"ltp":5.6,"tv":1171.0,"id":9712909}]}]}
{"op":"mcm","clk":"1002973679","pt":1580601403840,"mc":[{"id":"1.168179120","rc":[{"batb":[[0,5.1,24.6],[1,5,13.69],[2,4.9,8.52]],"ltp":5.6,"tv":1171.0,"id":9712909}]}]}
{"op":"mcm","clk":"1002974176","pt":1580601410863,"mc":[{"id":"1.168179120","rc":[{"trd":[[1.21,288.21]],"batb":[[0,1.2,142.63],[1,1.19,8.71],[2,1.18,149.41]],"ltp":1.21,"tv":9237.76,"id":8326656},{"trd":[[5.6,50.57]],"batb":[[1,5,19.99]],"batl":[[0,5.6,2.49],[2,5.9,17.45]],"ltp":5.6,"tv":1194.31,"id":9712909}],"tv":10432.08}]}
{"op":"mcm","clk":"1002974248","pt":1580601411776,"mc":[{"id":"1.168179120","rc":[{"batb":[[0,1.2,258.64]],"ltp":1.21,"tv":9237.76,"id":8326656},{"batb":[[0,5.2,14.27],[1,5.1,24.6],[2,5,21.99]],"ltp":5.6,"tv":1194.31,"id":9712909}]}]}
{"op":"mcm","clk":"1002974916","pt":1580601420542,"mc":[{"id":"1.168179120","rc":[{"batb":[[2,1.18,148.41]],"ltp":1.21,"tv":9237.76,"id":8326656},{"batl":[[0,5.6,15.16],[2,5.9,17.55]],"ltp":5.6,"tv":1194.31,"id":9712909}]}]}
{"op":"mcm","clk":"1002976299","pt":1580601437877,"mc":[{"id":"1.168179120","rc":[{"trd":[[1.24,59.83]],"batb":[[0,1.24,13.84],[1,1.2,258.64],[2,1.19,8.71]],"ltp":1.24,"tv":9297.59,"id":8326656},{"trd":[[5.2,43.21]],"batb":[[0,5.1,24.6],[1,5,21.99],[2,4.9,8.52]],"ltp":5.2,"tv":1208.58,"id":9712909}],"tv":10506.18}]}
{"op":"mcm","clk":"1002976368","pt":1580601438803,"mc":[{"id":"1.168179120","rc":[{"batb":[[1,1.22,8.84],[2,1.21,9.07]],"ltp":1.24,"tv":9297.59,"id":8326656},{"batb":[[1,5,6.3]],"batl":[[0,5.4,3.84],[1,5.5,3.99],[2,5.6,15.16]],"ltp":5.2,"tv":1208.58,"id":9712909}]}]}
{"op":"mcm","clk":"1002976450","pt":1580601439890,"mc":[{"id":"1.168179120","rc":[{"batb":[[1,4.9,8.52],[2,4.8,25.71]],"ltp":5.2,"tv":1208.58,"id":9712909}]}]}
{"op":"mcm","clk":"1002976471","pt":1580601440200,"mc":[{"id":"1.168179120","rc":[{"batb":[[2,1.21,70.37]],"ltp":1.24,"tv":9297.59,"id":8326656}]}]}
{"op":"mcm","clk":"1002977727","pt":1580601456694,"mc":[{"id":"1.168179120","rc":[{"trd":[[5.1,6.9]],"batb":[[0,5.1,21.28]],"ltp":5.1,"tv":1215.22,"id":9712909}],"tv":10512.82}]}
{"op":"mcm","clk":"1002977772","pt":1580601457314,"mc":[{"id":"1.168179120","rc":[{"batb":[[1,1.22,59.44]],"ltp":1.24,"tv":9297.59,"id":8326656},{"batl":[[1,5.5,3.43]],"ltp":5.1,"tv":1215.22,"id":9712909}]}]}
{"op":"mcm","clk":"1002979532","pt":1580601481840,"mc":[{"id":"1.168179120","rc":[{"batb":[[2,1.21,61.3]],"ltp":1.24,"tv":9297.59,"id":8326656},{"batb":[[1,5,10.4],[2,4.9,8.52]],"batl":[[1,5.6,15.16],[2,5.9,14]],"ltp":5.1,"tv":1215.22,"id":9712909}]}]}
{"op":"mcm","clk":"1002979549","pt":1580601482045,"mc":[{"id":"1.168179120","rc":[{"batb":[[2,1.21,69.99]],"ltp":1.24,"tv":9297.59,"id":8326656},{"batl":[[1,5.5,3.41],[2,5.6,15.16]],"ltp":5.1,"tv":1215.22,"id":9712909}]}]}
{"op":"mcm","clk":"1002983056","pt":1580601529877,"mc":[{"id":"1.168179120","rc":[{"batb":[[2,1.21,61.3]],"batl":[[0,1.25,3.26],[1,1.54,5.07],[2,95,15.95]],"ltp":1.24,"tv":9297.59,"id":8326656},{"batl":[[1,5.6,15.16],[2,5.9,14]],"ltp":5.1,"tv":1215.22,"id":9712909}]}]}
{"op":"mcm","clk":"1002983071","pt":1580601530083,"mc":[{"id":"1.168179120","rc":[{"batb":[[2,1.21,69.37]],"ltp":1.24,"tv":9297.59,"id":8326656},{"batl":[[1,5.5,3.61],[2,5.6,15.16]],"ltp":5.1,"tv":1215.22,"id":9712909}]}]}
{"op":"mcm","clk":"1002983191","pt":1580601531719,"mc":[{"id":"1.168179120","rc":[{"trd":[[1.24,87.51]],"batb":[[0,1.22,59.44],[1,1.21,69.37],[2,1.2,142.63]],"ltp":1.24,"tv":9325.27,"id":8326656}],"tv":10540.5}]}
{"op":"mcm","clk":"1002983264","pt":1580601532598,"mc":[{"id":"1.168179120","rc":[{"batb":[[0,1.22,50.6],[1,1.21,61.3],[2,1.2,151.35]],"ltp":1.24,"tv":9325.27,"id":8326656},{"batb":[[0,5.4,1.13],[1,5.1,21.28],[2,5,10.4]],"batl":[[0,5.6,15.16],[1,5.8,3.52],[2,5.9,17.75]],"ltp":5.1,"tv":1215.22,"id":9712909}]}]}
{"op":"mcm","clk":"1002983358","pt":1580601533922,"mc":[{"id":"1.168179120","rc":[{"batb":[[2,5,24.09]],"ltp":5.1,"tv":1215.22,"id":9712909}]}]}
{"op":"mcm","clk":"1002984455","pt":1580601549734,"mc":[{"id":"1.168179120","rc":[{"batl":[[2,5.9,17.55]],"ltp":5.1,"tv":1215.22,"id":9712909}]}]}
{"op":"mcm","clk":"1002984877","pt":1580601555501,"mc":[{"id":"1.168179120","rc":[{"batb":[[2,1.2,8.72]],"ltp":1.24,"tv":9325.27,"id":8326656},{"batl":[[2,5.9,17.95]],"ltp":5.1,"tv":1215.22,"id":9712909}]}]}
{"op":"mcm","clk":"1002984978","pt":1580601556852,"mc":[{"id":"1.168179120","rc":[{"trd":[[1.23,28.29]],"ltp":1.23,"tv":9330.22,"id":8326656},{"trd":[[5.1,37.44],[5.4,1.13]],"batb":[[0,5,24.09],[1,4.9,8.52],[2,4.8,25.71]],"ltp":5.1,"tv":1246.89,"id":9712909}],"tv":10577.11}]}
{"op":"mcm","clk":"1002985057","pt":1580601557832,"mc":[{"id":"1.168179120","rc":[{"batb":[[0,1.22,114.07]],"ltp":1.23,"tv":9330.22,"id":8326656},{"batb":[[1,4.9,23.69],[2,4.8,32.34]],"ltp":5.1,"tv":1246.89,"id":9712909}]}]}
{"op":"mcm","clk":"1002986288","pt":1580601572824,"mc":[{"id":"1.168179120","rc":[{"trd":[[1.25,103.91]],"batb":[[0,1.25,31.04],[1,1.22,114.07],[2,1.21,61.3]],"batl":[[0,1.54,5.07],[1,95,15.95],[2,990,2.2]],"ltp":1.25,"tv":9433.08,"id":8326656},{"trd":[[5,24.09]],"batb":[[0,4.9,23.69],[1,4.8,32.34],[2,4.7,2.02]],"ltp":5.0,"tv":1270.98,"id":9712909}],"tv":10704.06}]}
{"op":"mcm","clk":"1002986366","pt":1580601573860,"mc":[{"id":"1.168179120","rc":[{"batb":[[1,1.23,8.02],[2,1.22,122]],"ltp":1.25,"tv":9433.08,"id":8326656},{"batb":[[1,4.8,23.68],[2,4.7,8.83]],"batl":[[0,5.2,3.66],[1,5.3,3.95],[2,5.6,15.16]],"ltp":5.0,"tv":1270.98,"id":9712909}]}]}
{"op":"mcm","clk":"1002986738","pt":1580601578874,"mc":[{"id":"1.168179120","rc":[{"trd":[[1.25,116.2],[1.26,19.54]],"batb":[[0,1.22,122],[1,1.21,69.99],[2,1.2,133.85]],"ltp":1.26,"tv":9464.91,"id":8326656},{"trd":[[4.9,5.02],[5,27.16]],"batb":[[0,4.9,18.66]],"batl":[[0,5.2,3.48],[1,5.4,3.74],[2,5.5,3.97]],"ltp":4.9,"tv":1279.07,"id":9712909}],"tv":10743.99}]}
{"op":"mcm","clk":"1002986774","pt":1580601579345,"mc":[{"id":"1.168179120","rc":[{"batb":[[0,1.22,134.08],[1,1.21,61.3]],"ltp":1.26,"tv":9464.91,"id":8326656},{"trd":[[4.9,5.38]],"batb":[[0,4.9,18.48]],"batl":[[0,5.6,15.16],[1,5.8,3.67],[2,5.9,17.85]],"ltp":4.9,"tv":1279.43,"id":9712909}],"tv":10744.34}]}
{"op":"mcm","clk":"1002986823","pt":1580601579965,"mc":[{"id":"1.168179120","rc":[{"batb":[[2,1.2,7.82]],"ltp":1.26,"tv":9464.91,"id":8326656}]}]}
{"op":"mcm","clk":"1002987243","pt":1580601585349,"mc":[{"id":"1.168179120","rc":[{"trd":[[1.26,19.94]],"ltp":1.26,"tv":9465.31,"id":8326656},{"trd":[[4.9,5.48]],"batb":[[0,4.9,18.38]],"batl":[[2,5.9,17.55]],"ltp":4.9,"tv":1279.53,"id":9712909}],"tv":10744.84}]}
{"op":"mcm","clk":"1002988200","pt":1580601599886,"mc":[{"id":"1.168179120","rc":[{"batl":[[2,5.9,14]],"ltp":4.9,"tv":1279.53,"id":9712909}]}]}
{"op":"mcm","clk":"1002988212","pt":1580601600092,"mc":[{"id":"1.168179120","rc":[{"trd":[[1.22,183.29]],"batb":[[0,1.22,133.91]],"ltp":1.22,"tv":9465.65,"id":8326656},{"batl":[[2,5.9,18.05]],"ltp":4.9,"tv":1279.53,"id":9712909}],"tv":10745.18}]}
{"op":"mcm","clk":"1002989333","pt":1580601615087,"mc":[{"id":"1.168179120","rc":[{"trd":[[1.22,183.37]],"batb":[[0,1.22,133.87]],"ltp":1.22,"tv":9465.73,"id":8326656}],"tv":10745.26}]}
{"op":"mcm","clk":"1002991349","pt":1580601645646,"mc":[{"id":"1.168179120","rc":[{"batb":[[1,4.8,38.82]],"ltp":4.9,"tv":1279.53,"id":9712909}]}]}
{"op":"mcm","clk":"1002991581","pt":1580601649332,"mc":[{"id":"1.168179120","rc":[{"trd":[[1.22,210.39]],"batb":[[0,1.22,120.36]],"ltp":1.22,"tv":9492.75,"id":8326656},{"batb":[[0,4.9,21.85]],"ltp":4.9,"tv":1279.53,"id":9712909}],"tv":10772.28}]}
{"op":"mcm","clk":"1002993655","pt":1580601682374,"mc":[{"id":"1.168179120","rc":[{"batb":[[2,1.19,132.66]],"ltp":1.22,"tv":9492.75,"id":8326656},{"batb":[[2,4.7,6.81]],"batl":[[1,5.9,14],[2,95,16.07]],"ltp":4.9,"tv":1279.53,"id":9712909}]}]}
{"op":"mcm","clk":"1002994601","pt":1580601697631,"mc":[{"id":"1.168179120","rc":[{"batb":[[1,4.8,23.68]],"ltp":4.9,"tv":1279.53,"id":9712909}]}]}
{"op":"mcm","clk":"1002994722","pt":1580601699793,"mc":[{"id":"1.168179120","marketDefinition":{"bspMarket":false,"turnInPlayEnabled":true,"persistenceEnabled":true,"marketBaseRate":5.0,"eventId":"29680182","eventTypeId":"2","numberOfWinners":1,"bettingType":"ODDS","marketType":"MATCH_ODDS","marketTime":"2020-02-02T00:15:00.000Z","suspendTime":"2020-02-02T00:15:00.000Z","bspReconciled":false,"complete":true,"inPlay":false,"crossMatching":true,"runnersVoidable":false,"numberOfActiveRunners":2,"betDelay":0,"status":"OPEN","runners":[{"status":"ACTIVE","sortPriority":1,"id":9712909,"name":"Felipe Meligeni Rodrigu"},{"status":"ACTIVE","sortPriority":2,"id":8326656,"name":"Thiago Monteiro"}],"regulators":["MR_INT"],"countryCode":"UY","discountAllowed":true,"timezone":"UTC","openDate":"2020-02-02T00:00:00.000Z","version":3147888952,"name":"Match Odds","eventName":"Meligeni Rodrigues Alve v T Monteiro"}}]}
{"op":"mcm","clk":"1002994865","pt":1580601701836,"mc":[{"id":"1.168179120","rc":[{"batb":[[1,4.8,38.82]],"ltp":4.9,"tv":1279.53,"id":9712909}]}]}
{"op":"mcm","clk":"1002995013","pt":1580601703802,"mc":[{"id":"1.168179120","marketDefinition":{"bspMarket":false,"turnInPlayEnabled":true,"persistenceEnabled":true,"marketBaseRate":5.0,"eventId":"29680182","eventTypeId":"2","numberOfWinners":1,"bettingType":"ODDS","marketType":"MATCH_ODDS","marketTime":"2020-02-02T00:15:00.000Z","suspendTime":"2020-02-02T00:15:00.000Z","bspReconciled":false,"complete":true,"inPlay":false,"crossMatching":true,"runnersVoidable":false,"numberOfActiveRunners":2,"betDelay":0,"status":"OPEN","runners":[{"status":"ACTIVE","sortPriority":1,"id":9712909,"name":"Felipe Meligeni Rodrigu"},{"status":"ACTIVE","sortPriority":2,"id":8326656,"name":"Thiago Monteiro"}],"regulators":["MR_INT"],"countryCode":"UY","discountAllowed":true,"timezone":"UTC","openDate":"2020-02-02T00:15:00.000Z","version":3147888952,"name":"Match Odds","eventName":"Meligeni Rodrigues Alve v T Monteiro"}}]}
{"op":"mcm","clk":"1002998552","pt":1580601758285,"mc":[{"id":"1.168179120","rc":[{"batb":[[1,4.8,23.68]],"ltp":4.9,"tv":1279.53,"id":9712909}]}]}
{"op":"mcm","clk":"1003002353","pt":1580601814770,"mc":[{"id":"1.168179120","rc":[{"batb":[[0,1.23,20],[1,1.22,120.36],[2,1.21,61.3]],"ltp":1.22,"tv":9492.75,"id":8326656}]}]}
{"op":"mcm","clk":"1003003255","pt":1580601827106,"mc":[{"id":"1.168179120","rc":[{"batb":[[0,1.22,120.36],[1,1.21,61.3],[2,1.19,132.66]],"ltp":1.22,"tv":9492.75,"id":8326656}]}]}
{"op":"mcm","clk":"1003016691","pt":1580602019505,"mc":[{"id":"1.168179120","rc":[{"trd":[[1.22,363.45]],"batb":[[0,1.22,43.82]],"ltp":1.22,"tv":9645.81,"id":8326656}],"tv":10925.35}]}
{"op":"mcm","clk":"1003016740","pt":1580602020024,"mc":[{"id":"1.168179120","rc":[{"batb":[[2,4.5,15.64]],"ltp":4.9,"tv":1279.53,"id":9712909}]}]}
{"op":"mcm","clk":"1003016839","pt":1580602021007,"mc":[{"id":"1.168179120","rc":[{"batb":[[0,1.21,110.14],[1,1.19,132.66],[2,1.18,140.05]],"ltp":1.22,"tv":9645.81,"id":8326656},{"batb":[[0,4.9,40.22],[1,4.8,30.31]],"ltp":4.9,"tv":1279.53,"id":9712909}]}]}
{"op":"mcm","clk":"1003019487","pt":1580602048374,"mc":[{"id":"1.168179120","rc":[{"batb":[[0,1.22,2.07],[1,1.21,110.14],[2,1.19,132.66]],"ltp":1.22,"tv":9645.81,"id":8326656},{"batb":[[0,4.9,40.72]],"ltp":4.9,"tv":1279.53,"id":9712909}]}]}
{"op":"mcm","clk":"1003051222","pt":1580602391422,"mc":[{"id":"1.168179120","rc":[{"batb":[[0,5,14.19],[1,4.9,40.22],[2,4.8,30.31]],"ltp":4.9,"tv":1279.53,"id":9712909}]}]}
{"op":"mcm","clk":"1003051353","pt":1580602392621,"mc":[{"id":"1.168179120","rc":[{"trd":[[1.25,117.07]],"ltp":1.25,"tv":9646.69,"id":8326656},{"trd":[[5,27.38]],"batb":[[0,5,13.98]],"ltp":5.0,"tv":1279.75,"id":9712909}],"tv":10926.44}]}
{"op":"mcm","clk":"1003053761","pt":1580602418187,"mc":[{"id":"1.168179120","rc":[{"trd":[[5.6,50.77]],"batl":[[0,5.6,15.06]],"ltp":5.6,"tv":1279.95,"id":9712909}],"tv":10926.64}]}
{"op":"mcm","clk":"1003058034","pt":1580602462252,"mc":[{"id":"1.168179120","rc":[{"batb":[[0,5.1,22.77],[1,5,13.98]],"ltp":5.6,"tv":1279.95,"id":9712909}]}]}
{"op":"mcm","clk":"1003058131","pt":1580602463251,"mc":[{"id":"1.168179120","rc":[{"batb":[[2,1.18,140.05]],"ltp":1.25,"tv":9646.69,"id":8326656},{"batb":[[2,4.9,6.46]],"ltp":5.6,"tv":1279.95,"id":9712909}]}]}
{"op":"mcm","clk":"1003062485","pt":1580602510061,"mc":[{"id":"1.168179120","rc":[{"trd":[[1.22,363.47]],"batb":[[0,1.22,2.06]],"ltp":1.22,"tv":9646.71,"id":8326656}],"tv":10926.66}]}
{"op":"mcm","clk":"1003070584","pt":1580602600982,"mc":[{"id":"1.168179120","marketDefinition":{"bspMarket":false,"turnInPlayEnabled":true,"persistenceEnabled":true,"marketBaseRate":5.0,"eventId":"29680182","eventTypeId":"2","numberOfWinners":1,"bettingType":"ODDS","marketType":"MATCH_ODDS","marketTime":"2020-02-02T00:30:00.000Z","suspendTime":"2020-02-02T00:30:00.000Z","bspReconciled":false,"complete":true,"inPlay":false,"crossMatching":true,"runnersVoidable":false,"numberOfActiveRunners":2,"betDelay":0,"status":"OPEN","runners":[{"status":"ACTIVE","sortPriority":1,"id":9712909,"name":"Felipe Meligeni Rodrigu"},{"status":"ACTIVE","sortPriority":2,"id":8326656,"name":"Thiago Monteiro"}],"regulators":["MR_INT"],"countryCode":"UY","discountAllowed":true,"timezone":"UTC","openDate":"2020-02-02T00:15:00.000Z","version":3147905057,"name":"Match Odds","eventName":"Meligeni Rodrigues Alve v T Monteiro"}}]}
{"op":"mcm","clk":"1003070874","pt":1580602603932,"mc":[{"id":"1.168179120","rc":[{"batb":[[0,1.22,2.5]],"ltp":1.22,"tv":9646.71,"id":8326656}]}]}
{"op":"mcm","clk":"1003070979","pt":1580602604992,"mc":[{"id":"1.168179120","marketDefinition":{"bspMarket":false,"turnInPlayEnabled":true,"persistenceEnabled":true,"marketBaseRate":5.0,"eventId":"29680182","eventTypeId":"2","numberOfWinners":1,"bettingType":"ODDS","marketType":"MATCH_ODDS","marketTime":"2020-02-02T00:30:00.000Z","suspendTime":"2020-02-02T00:30:00.000Z","bspReconciled":false,"complete":true,"inPlay":false,"crossMatching":true,"runnersVoidable":false,"numberOfActiveRunners":2,"betDelay":0,"status":"OPEN","runners":[{"status":"ACTIVE","sortPriority":1,"id":9712909,"name":"Felipe Meligeni Rodrigu"},{"status":"ACTIVE","sortPriority":2,"id":8326656,"name":"Thiago Monteiro"}],"regulators":["MR_INT"],"countryCode":"UY","discountAllowed":true,"timezone":"UTC","openDate":"2020-02-02T00:30:00.000Z","version":3147905147,"name":"Match Odds","eventName":"Meligeni Rodrigues Alve v T Monteiro"}}]}
{"op":"mcm","clk":"1003072308","pt":1580602618733,"mc":[{"id":"1.168179120","rc":[{"batb":[[0,1.22,2.06]],"ltp":1.22,"tv":9646.71,"id":8326656}]}]}
{"op":"mcm","clk":"1003075919","pt":1580602657921,"mc":[{"id":"1.168179120","rc":[{"batl":[[0,1.24,200],[1,1.54,5.07],[2,95,15.95]],"ltp":1.22,"tv":9646.71,"id":8326656}]}]}
{"op":"mcm","clk":"1003079457","pt":1580602699779,"mc":[{"id":"1.168179120","rc":[{"trd":[[1.24,88.39]],"batl":[[0,1.24,199.56]],"ltp":1.24,"tv":9647.59,"id":8326656}],"tv":10927.54}]}
{"op":"mcm","clk":"1003080104","pt":1580602707667,"mc":[{"id":"1.168179120","rc":[{"batl":[[0,5.6,31.86]],"ltp":5.6,"tv":1279.95,"id":9712909}]}]}
{"op":"mcm","clk":"1003091105","pt":1580602858143,"mc":[{"id":"1.168179120","rc":[{"batb":[[2,1.2,2]],"batl":[[1,1.26,2.02],[2,1.27,2.13]],"ltp":1.24,"tv":9647.59,"id":8326656},{"batb":[[2,4.9,8.52]],"batl":[[1,5.8,2.02],[2,5.9,16]],"ltp":5.6,"tv":1279.95,"id":9712909}]}]}
{"op":"mcm","clk":"1003125986","pt":1580603319631,"mc":[{"id":"1.168179120","rc":[{"trd":[[1.21,509.88],[1.22,367.59]],"batb":[[0,1.19,2.02],[1,1.18,142.13],[2,1.17,923.15]],"batl":[[2,1.27,2.02]],"ltp":1.21,"tv":9873.37,"id":8326656},{"trd":[[5.6,71.52]],"batl":[[0,5.6,21.34],[2,5.9,16.05]],"ltp":5.6,"tv":1300.7,"id":9712909}],"tv":11174.08}]}
{"op":"mcm","clk":"1003126175","pt":1580603321591,"mc":[{"id":"1.168179120","rc":[{"batb":[[0,1.19,190.81]],"ltp":1.21,"tv":9873.37,"id":8326656},{"batb":[[0,5.2,14.36],[1,5.1,22.77],[2,5,13.98]],"ltp":5.6,"tv":1300.7,"id":9712909}]}]}
{"op":"mcm","clk":"1003126359","pt":1580603323498,"mc":[{"id":"1.168179120","rc":[{"batb":[[2,5,20.28]],"ltp":5.6,"tv":1300.7,"id":9712909}]}]}
{"op":"mcm","clk":"1003128494","pt":1580603349856,"mc":[{"id":"1.168179120","rc":[{"trd":[[5.6,75.76]],"batl":[[0,5.6,19.22]],"ltp":5.6,"tv":1304.94,"id":9712909}],"tv":11178.32}]}
{"op":"mcm","clk":"1003128536","pt":1580603350373,"mc":[{"id":"1.168179120","rc":[{"batl":[[2,5.9,16]],"ltp":5.6,"tv":1304.94,"id":9712909}]}]}
{"op":"mcm","clk":"1003132373","pt":1580603397827,"mc":[{"id":"1.168179120","rc":[{"batb":[[1,1.18,310.17]],"batl":[[2,1.27,2]],"ltp":1.21,"tv":9873.37,"id":8326656},{"batl":[[2,5.9,16.05]],"ltp":5.6,"tv":1304.94,"id":9712909}]}]}
{"op":"mcm","clk":"1003132643","pt":1580603400627,"mc":[{"id":"1.168179120","rc":[{"batb":[[1,1.18,170.13],[2,1.17,774.88]],"ltp":1.21,"tv":9873.37,"id":8326656},{"batb":[[2,5,13.98]],"ltp":5.6,"tv":1304.94,"id":9712909}]}]}
{"op":"mcm","clk":"1003135024","pt":1580603431160,"mc":[{"id":"1.168179120","rc":[{"trd":[[1.24,89.03]],"batl":[[0,1.24,199.24]],"ltp":1.24,"tv":9874.02,"id":8326656}],"tv":11178.96}]}
{"op":"mcm","clk":"1003137763","pt":1580603463617,"mc":[{"id":"1.168179120","rc":[{"trd":[[1.24,90.21]],"batl":[[0,1.24,198.65]],"ltp":1.24,"tv":9875.19,"id":8326656}],"tv":11180.14}]}
{"op":"mcm","clk":"1003137788","pt":1580603463926,"mc":[{"id":"1.168179120","rc":[{"batb":[[0,1.19,188.79],[1,1.18,168.05]],"batl":[[1,1.54,5.07],[2,95,15.95]],"ltp":1.24,"tv":9875.19,"id":8326656},{"batl":[[1,5.9,14],[2,95,16.07]],"ltp":5.6,"tv":1304.94,"id":9712909}]}]}
{"op":"mcm","clk":"1003141084","pt":1580603501489,"mc":[{"id":"1.168179120","marketDefinition":{"bspMarket":false,"turnInPlayEnabled":true,"persistenceEnabled":true,"marketBaseRate":5.0,"eventId":"29680182","eventTypeId":"2","numberOfWinners":1,"bettingType":"ODDS","marketType":"MATCH_ODDS","marketTime":"2020-02-02T00:45:00.000Z","suspendTime":"2020-02-02T00:45:00.000Z","bspReconciled":false,"complete":true,"inPlay":false,"crossMatching":true,"runnersVoidable":false,"numberOfActiveRunners":2,"betDelay":0,"status":"OPEN","runners":[{"status":"ACTIVE","sortPriority":1,"id":9712909,"name":"Felipe Meligeni Rodrigu"},{"status":"ACTIVE","sortPriority":2,"id":8326656,"name":"Thiago Monteiro"}],"regulators":["MR_INT"],"countryCode":"UY","discountAllowed":true,"timezone":"UTC","openDate":"2020-02-02T00:30:00.000Z","version":3147932328,"name":"Match Odds","eventName":"Meligeni Rodrigues Alve v T Monteiro"}}]}
{"op":"mcm","clk":"1003141344","pt":1580603504503,"mc":[{"id":"1.168179120","marketDefinition":{"bspMarket":false,"turnInPlayEnabled":true,"persistenceEnabled":true,"marketBaseRate":5.0,"eventId":"29680182","eventTypeId":"2","numberOfWinners":1,"bettingType":"ODDS","marketType":"MATCH_ODDS","marketTime":"2020-02-02T00:45:00.000Z","suspendTime":"2020-02-02T00:45:00.000Z","bspReconciled":false,"complete":true,"inPlay":false,"crossMatching":true,"runnersVoidable":false,"numberOfActiveRunners":2,"betDelay":0,"status":"OPEN","runners":[{"status":"ACTIVE","sortPriority":1,"id":9712909,"name":"Felipe Meligeni Rodrigu"},{"status":"ACTIVE","sortPriority":2,"id":8326656,"name":"Thiago Monteiro"}],"regulators":["MR_INT"],"countryCode":"UY","discountAllowed":true,"timezone":"UTC","openDate":"2020-02-02T00:45:00.000Z","version":3147932328,"name":"Match Odds","eventName":"Meligeni Rodrigues Alve v T Monteiro"},"rc":[{"batl":[[0,1.23,84.02],[1,1.24,198.65],[2,1.54,5.07]],"ltp":1.24,"tv":9875.19,"id":8326656}]}]}
{"op":"mcm","clk":"1003141821","pt":1580603510274,"mc":[{"id":"1.168179120","rc":[{"trd":[[1.21,578.55]],"ltp":1.21,"tv":9943.87,"id":8326656},{"trd":[[5.6,90.6]],"batl":[[0,5.6,4.38]],"ltp":5.6,"tv":1319.78,"id":9712909}],"tv":11263.65}]}
{"op":"mcm","clk":"1003141920","pt":1580603511466,"mc":[{"id":"1.168179120","rc":[{"trd":[[1.2,190.02],[1.21,598.81]],"ltp":1.2,"tv":10027.89,"id":8326656},{"trd":[[5.6,94.97],[5.9,19.79]],"batl":[[0,5.9,1.03],[1,95,16.07],[2,990,2.2]],"ltp":5.9,"tv":1337.12,"id":9712909}],"tv":11365.02}]}
{"op":"mcm","clk":"1003143616","pt":1580603530396,"mc":[{"id":"1.168179120","rc":[{"batb":[[0,1.19,750.13]],"ltp":1.2,"tv":10027.89,"id":8326656}]}]}
{"op":"mcm","clk":"1003144094","pt":1580603536290,"mc":[{"id":"1.168179120","rc":[{"trd":[[1.2,195.08]],"batl":[[0,1.2,19.07],[1,1.23,84.02],[2,1.24,198.65]],"ltp":1.2,"tv":10032.95,"id":8326656},{"trd":[[5.9,20.82]],"batl":[[0,95,16.07],[1,990,2.2],[2,1000,0.02]],"ltp":5.9,"tv":1338.15,"id":9712909}],"tv":11371.11}]}
{"op":"mcm","clk":"1003144447","pt":1580603539803,"mc":[{"id":"1.168179120","rc":[{"trd":[[1.2,214.15]],"batl":[[0,1.23,84.02],[1,1.24,198.65],[2,1.54,5.07]],"ltp":1.2,"tv":10052.02,"id":8326656},{"trd":[[6,46.06]],"ltp":6.0,"tv":1341.97,"id":9712909}],"tv":11394.0}]}
{"op":"mcm","clk":"1003144502","pt":1580603540370,"mc":[{"id":"1.168179120","rc":[{"batb":[[0,1.19,731.1]],"batl":[[0,1.2,560],[1,1.23,84.02],[2,1.24,198.65]],"ltp":1.2,"tv":10052.02,"id":8326656},{"batb":[[0,5.4,17.93],[1,5,13.98],[2,4.8,23.68]],"ltp":6.0,"tv":1341.97,"id":9712909}]}]}
{"op":"mcm","clk":"1003147215","pt":1580603573723,"mc":[{"id":"1.168179120","rc":[{"trd":[[1.2,215.76]],"batl":[[0,1.2,559.2]],"ltp":1.2,"tv":10053.63,"id":8326656}],"tv":11395.6}]}
{"op":"mcm","clk":"1003147871","pt":1580603581743,"mc":[{"id":"1.168179120","rc":[{"trd":[[1.2,722.78]],"batl":[[0,1.2,52.18]],"ltp":1.2,"tv":10560.65,"id":8326656},{"trd":[[6,147.36]],"ltp":6.0,"tv":1443.27,"id":9712909}],"tv":12003.92}]}
{"op":"mcm","clk":"1003149242","pt":1580603597776,"mc":[{"id":"1.168179120","rc":[{"trd":[[1.2,808.38]],"batl":[[0,1.2,9.38]],"ltp":1.2,"tv":10646.25,"id":8326656}],"tv":12089.52}]}
{"op":"mcm","clk":"1003149959","pt":1580603607258,"mc":[{"id":"1.168179120","rc":[{"batl":[[0,1.23,84.02],[1,1.24,198.65],[2,1.54,5.07]],"ltp":1.2,"tv":10646.25,"id":8326656}]}]}
{"op":"mcm","clk":"1003151903","pt":1580603629814,"mc":[{"id":"1.168179120","rc":[{"batb":[[1,1.18,1260.16]],"ltp":1.2,"tv":10646.25,"id":8326656},{"batb":[[0,5.6,86.55],[1,5.4,17.93],[2,5,13.98]],"ltp":6.0,"tv":1443.27,"id":9712909}]}]}
{"op":"mcm","clk":"1003151911","pt":1580603629917,"mc":[{"id":"1.168179120","rc":[{"batl":[[0,1.23,283.45]],"ltp":1.2,"tv":10646.25,"id":8326656}]}]}
{"op":"mcm","clk":"1003152581","pt":1580603637535,"mc":[{"id":"1.168179120","rc":[{"batb":[[1,1.18,1243.79]],"ltp":1.2,"tv":10646.25,"id":8326656}]}]}
{"op":"mcm","clk":"1003152711","pt":1580603638831,"mc":[{"id":"1.168179120","rc":[{"trd":[[1.19,880.02]],"batb":[[0,1.19,556.71]],"batl":[[0,1.23,84.02]],"ltp":1.19,"tv":11457.08,"id":8326656}],"tv":12900.35}]}
{"op":"mcm","clk":"1003152798","pt":1580603639817,"mc":[{"id":"1.168179120","rc":[{"batb":[[0,1.19,499.66]],"batl":[[0,1.23,87.13]],"ltp":1.19,"tv":11457.08,"id":8326656},{"batb":[[0,5.7,18.17],[1,5.6,86.55]],"ltp":6.0,"tv":1443.27,"id":9712909}]}]}
{"op":"mcm","clk":"1003152844","pt":1580603640403,"mc":[{"id":"1.168179120","rc":[{"batb":[[0,1.19,849.66]],"ltp":1.19,"tv":11457.08,"id":8326656}]}]}
{"op":"mcm","clk":"1003153299","pt":1580603645526,"mc":[{"id":"1.168179120","rc":[{"batl":[[0,1.22,171.29],[1,1.23,84.02],[2,1.24,198.65]],"ltp":1.19,"tv":11457.08,"id":8326656}]}]}
{"op":"mcm","clk":"1003153936","pt":1580603652356,"mc":[{"id":"1.168179120","rc":[{"batl":[[1,1.23,252.06]],"ltp":1.19,"tv":11457.08,"id":8326656}]}]}
{"op":"mcm","clk":"1003154177","pt":1580603655060,"mc":[{"id":"1.168179120","rc":[{"trd":[[1.22,377.59]],"batl":[[0,1.22,166.29]],"ltp":1.22,"tv":11467.07,"id":8326656}],"tv":12910.35}]}
{"op":"mcm","clk":"1003154560","pt":1580603659424,"mc":[{"id":"1.168179120","rc":[{"batl":[[2,1.24,254.94]],"ltp":1.22,"tv":11467.07,"id":8326656}]}]}
{"op":"mcm","clk":"1003155636","pt":1580603670743,"mc":[{"id":"1.168179120","rc":[{"batb":[[0,1.2,84.02],[1,1.19,849.66],[2,1.18,1243.79]],"ltp":1.22,"tv":11467.07,"id":8326656}]}]}
{"op":"mcm","clk":"1003155664","pt":1580603671053,"mc":[{"id":"1.168179120","rc":[{"batb":[[1,1.19,421.53]],"ltp":1.22,"tv":11467.07,"id":8326656}]}]}
{"op":"mcm","clk":"1003155992","pt":1580603674358,"mc":[{"id":"1.168179120","rc":[{"batb":[[2,4.8,23.97]],"ltp":6.0,"tv":1443.27,"id":9712909}]}]}
{"op":"mcm","clk":"1003158728","pt":1580603706699,"mc":[{"id":"1.168179120","rc":[{"batb":[[2,1.18,1240.65]],"ltp":1.22,"tv":11467.07,"id":8326656}]}]}
{"op":"mcm","clk":"1003159198","pt":1580603711622,"mc":[{"id":"1.168179120","rc":[{"batb":[[0,1.21,315.79],[1,1.2,84.02],[2,1.19,421.53]],"ltp":1.22,"tv":11467.07,"id":8326656}]}]}
{"op":"mcm","clk":"1003159313","pt":1580603712921,"mc":[{"id":"1.168179120","rc":[{"batb":[[0,1.21,320.83]],"ltp":1.22,"tv":11467.07,"id":8326656}]}]}
{"op":"mcm","clk":"1003159760","pt":1580603718523,"mc":[{"id":"1.168179120","rc":[{"trd":[[1.21,788.81]],"batb":[[0,1.21,225.83]],"ltp":1.21,"tv":11657.07,"id":8326656}],"tv":13100.35}]}
{"op":"mcm","clk":"1003160728","pt":1580603730535,"mc":[{"id":"1.168179120","rc":[{"trd":[[1.21,988.81]],"batb":[[0,1.21,125.83]],"ltp":1.21,"tv":11857.07,"id":8326656}],"tv":13300.35}]}
{"op":"mcm","clk":"1003162186","pt":1580603747760,"mc":[{"id":"1.168179120","rc":[{"batb":[[2,1.19,71.53]],"ltp":1.21,"tv":11857.07,"id":8326656}]}]}
{"op":"mcm","clk":"1003162322","pt":1580603749774,"mc":[{"id":"1.168179120","rc":[{"batb":[[1,1.2,86.03]],"ltp":1.21,"tv":11857.07,"id":8326656}]}]}
{"op":"mcm","clk":"1003162804","pt":1580603755684,"mc":[{"id":"1.168179120","rc":[{"batb":[[2,1.19,155.55]],"ltp":1.21,"tv":11857.07,"id":8326656}]}]}
{"op":"mcm","clk":"1003166663","pt":1580603799332,"mc":[{"id":"1.168179120","marketDefinition":{"bspMarket":false,"turnInPlayEnabled":true,"persistenceEnabled":true,"marketBaseRate":5.0,"eventId":"29680182","eventTypeId":"2","numberOfWinners":1,"bettingType":"ODDS","marketType":"MATCH_ODDS","marketTime":"2020-02-02T00:32:00.000Z","suspendTime":"2020-02-02T00:32:00.000Z","bspReconciled":false,"complete":true,"inPlay":false,"crossMatching":true,"runnersVoidable":false,"numberOfActiveRunners":2,"betDelay":0,"status":"OPEN","runners":[{"status":"ACTIVE","sortPriority":1,"id":9712909,"name":"Felipe Meligeni Rodrigu"},{"status":"ACTIVE","sortPriority":2,"id":8326656,"name":"Thiago Monteiro"}],"regulators":["MR_INT"],"countryCode":"UY","discountAllowed":true,"timezone":"UTC","openDate":"2020-02-02T00:45:00.000Z","version":3147936779,"name":"Match Odds","eventName":"Meligeni Rodrigues Alve v T Monteiro"}}]}
{"op":"mcm","clk":"1003167020","pt":1580603803341,"mc":[{"id":"1.168179120","marketDefinition":{"bspMarket":false,"turnInPlayEnabled":true,"persistenceEnabled":true,"marketBaseRate":5.0,"eventId":"29680182","eventTypeId":"2","numberOfWinners":1,"bettingType":"ODDS","marketType":"MATCH_ODDS","marketTime":"2020-02-02T00:32:00.000Z","suspendTime":"2020-02-02T00:32:00.000Z","bspReconciled":false,"complete":true,"inPlay":false,"crossMatching":true,"runnersVoidable":false,"numberOfActiveRunners":2,"betDelay":0,"status":"OPEN","runners":[{"status":"ACTIVE","sortPriority":1,"id":9712909,"name":"Felipe Meligeni Rodrigu"},{"status":"ACTIVE","sortPriority":2,"id":8326656,"name":"Thiago Monteiro"}],"regulators":["MR_INT"],"countryCode":"UY","discountAllowed":true,"timezone":"UTC","openDate":"2020-02-02T00:32:00.000Z","version":3147936869,"name":"Match Odds","eventName":"Meligeni Rodrigues Alve v T Monteiro"}}]}
{"op":"mcm","clk":"1003167699","pt":1580603811763,"mc":[{"id":"1.168179120","rc":[{"trd":[[1.21,1124.41]],"batb":[[0,1.21,58.03]],"batl":[[0,1.22,163.04]],"ltp":1.21,"tv":11992.68,"id":8326656}],"tv":13435.95}]}
{"op":"mcm","clk":"1003167750","pt":1580603812339,"mc":[{"id":"1.168179120","rc":[{"batb":[[1,1.2,153.51]],"ltp":1.21,"tv":11992.68,"id":8326656},{"batb":[[0,5.6,97],[1,4.8,23.97],[2,4.2,46.88]],"ltp":6.0,"tv":1443.27,"id":9712909}]}]}
{"op":"mcm","clk":"1003168249","pt":1580603818350,"mc":[{"id":"1.168179120","rc":[{"trd":[[1.21,1175.74]],"batb":[[0,1.21,32.37]],"ltp":1.21,"tv":12044.0,"id":8326656}],"tv":13487.28}]}
{"op":"mcm","clk":"1003168464","pt":1580603820878,"mc":[{"id":"1.168179120","rc":[{"trd":[[1.22,432.25]],"batb":[[0,1.21,5.04]],"batl":[[0,1.22,135.71]],"ltp":1.22,"tv":12098.66,"id":8326656}],"tv":13541.94}]}
{"op":"mcm","clk":"1003168792","pt":1580603824565,"mc":[{"id":"1.168179120","rc":[{"batb":[[1,5,13.98],[2,4.8,23.68]],"ltp":6.0,"tv":1443.27,"id":9712909}]}]}
{"op":"mcm","clk":"1003170460","pt":1580603849698,"mc":[{"id":"1.168179120","rc":[{"batb":[[0,1.21,33.61]],"ltp":1.22,"tv":12098.66,"id":8326656},{"batb":[[1,4.8,23.97],[2,4.2,46.88]],"ltp":6.0,"tv":1443.27,"id":9712909}]}]}
{"op":"mcm","clk":"1003176213","pt":1580603935199,"mc":[{"id":"1.168179120","rc":[{"trd":[[1.22,433.06]],"batl":[[0,1.22,135.3]],"ltp":1.22,"tv":12099.47,"id":8326656}],"tv":13542.74}]}
{"op":"mcm","clk":"1003176399","pt":1580603938387,"mc":[{"id":"1.168179120","rc":[{"batb":[[0,1.21,109.33]],"ltp":1.22,"tv":12099.47,"id":8326656}]}]}
{"op":"mcm","clk":"1003179248","pt":1580603987462,"mc":[{"id":"1.168179120","rc":[{"trd":[[5.6,288.97]],"batb":[[0,4.8,23.97],[1,4.2,46.88],[2,3.3,28.52]],"batl":[[0,5.6,660.24],[1,95,16.07],[2,990,2.2]],"ltp":5.6,"tv":1637.27,"id":9712909}],"tv":13736.74}]}
{"op":"mcm","clk":"1003179304","pt":1580603988440,"mc":[{"id":"1.168179120","rc":[{"batb":[[1,1.2,202.02],[2,1.19,1203.44]],"ltp":1.22,"tv":12099.47,"id":8326656},{"batb":[[0,5.5,90.56],[1,5.4,13.79],[2,4.8,23.97]],"ltp":5.6,"tv":1637.27,"id":9712909}]}]}
{"op":"mcm","clk":"1003179347","pt":1580603989058,"mc":[{"id":"1.168179120","rc":[{"trd":[[1.21,1176.98]],"batb":[[0,1.21,108.71]],"ltp":1.21,"tv":12100.71,"id":8326656}],"tv":13737.98}]}
{"op":"mcm","clk":"1003179773","pt":1580603995663,"mc":[{"id":"1.168179120","rc":[{"batl":[[1,1.23,168.04]],"ltp":1.21,"tv":12100.71,"id":8326656}]}]}
{"op":"mcm","clk":"1003179815","pt":1580603996384,"mc":[{"id":"1.168179120","rc":[{"trd":[[1.22,437.44]],"batl":[[0,1.22,133.11]],"ltp":1.22,"tv":12105.1,"id":8326656}],"tv":13742.37}]}
{"op":"mcm","clk":"1003179905","pt":1580603997874,"mc":[{"id":"1.168179120","rc":[{"batl":[[0,95,16.07],[1,990,2.2],[2,1000,0.02]],"ltp":5.6,"tv":1637.27,"id":9712909}]}]}
{"op":"mcm","clk":"1003179967","pt":1580603998856,"mc":[{"id":"1.168179120","rc":[{"trd":[[1.22,570.56]],"batb":[[0,1.21,147.59],[1,1.2,1225.12],[2,1.19,155.55]],"batl":[[0,1.23,168.04],[1,1.24,254.94],[2,1.54,5.07]],"ltp":1.22,"tv":12238.21,"id":8326656},{"trd":[[5.5,214.93]],"batb":[[0,5.4,107.81],[1,4.8,23.97],[2,4.2,46.88]],"batl":[[0,5.5,540.16],[1,95,16.07],[2,990,2.2]],"ltp":5.5,"tv":1847.91,"id":9712909}],"tv":14086.13}]}
{"op":"mcm","clk":"1003180049","pt":1580603999985,"mc":[{"id":"1.168179120","rc":[{"batb":[[1,5,13.98],[2,4.8,23.68]],"ltp":5.5,"tv":1847.91,"id":9712909}]}]}
{"op":"mcm","clk":"1003180752","pt":1580604010698,"mc":[{"id":"1.168179120","rc":[{"trd":[[5.4,220.75]],"batb":[[0,5,13.98],[1,4.8,23.68],[2,4.2,46.88]],"batl":[[0,5.4,430.35]],"ltp":5.4,"tv":2067.53,"id":9712909}],"tv":14305.74}]}
{"op":"mcm","clk":"1003180809","pt":1580604011579,"mc":[{"id":"1.168179120","rc":[{"batb":[[0,1.21,170.19],[1,1.2,1200.41],[2,1.19,84.02]],"ltp":1.22,"tv":12238.21,"id":8326656},{"batb":[[0,5.3,97.57],[1,5.2,15.02],[2,5,13.98]],"ltp":5.4,"tv":2067.53,"id":9712909}]}]}
{"op":"mcm","clk":"1003180974","pt":1580604014305,"mc":[{"id":"1.168179120","rc":[{"batl":[[0,1.24,254.94],[1,1.25,168.04]],"ltp":1.22,"tv":12238.21,"id":8326656}]}]}
{"op":"mcm","clk":"1003181209","pt":1580604018013,"mc":[{"id":"1.168179120","rc":[{"batb":[[1,1.2,1198.4]],"ltp":1.22,"tv":12238.21,"id":8326656}]}]}
{"op":"mcm","clk":"1003181842","pt":1580604027813,"mc":[{"id":"1.168179120","rc":[{"trd":[[5.3,219.13]],"batb":[[0,5.2,15.02],[1,5,13.98],[2,4.8,23.68]],"batl":[[0,5.3,332.79]],"ltp":5.3,"tv":2262.66,"id":9712909}],"tv":14500.87}]}
{"op":"mcm","clk":"1003181896","pt":1580604028638,"mc":[{"id":"1.168179120","rc":[{"batb":[[0,1.21,1143.96],[1,1.2,200.01]],"ltp":1.22,"tv":12238.21,"id":8326656},{"trd":[[5.3,565.85]],"batl":[[0,5.3,159.44]],"ltp":5.3,"tv":2609.37,"id":9712909}],"tv":14847.59}]}
{"op":"mcm","clk":"1003182043","pt":1580604031218,"mc":[{"id":"1.168179120","rc":[{"batl":[[0,1.24,376.51]],"ltp":1.22,"tv":12238.21,"id":8326656}]}]}
{"op":"mcm","clk":"1003182400","pt":1580604036826,"mc":[{"id":"1.168179120","rc":[{"batb":[[0,1.22,42.02],[1,1.21,1143.96],[2,1.2,200.01]],"ltp":1.22,"tv":12238.21,"id":8326656},{"batl":[[0,95,16.07],[1,990,2.2],[2,1000,0.02]],"ltp":5.3,"tv":2609.37,"id":9712909}]}]}
{"op":"mcm","clk":"1003182412","pt":1580604037032,"mc":[{"id":"1.168179120","rc":[{"batb":[[0,1.21,1143.96],[1,1.2,200.01],[2,1.19,84.02]],"ltp":1.22,"tv":12238.21,"id":8326656}]}]}
{"op":"mcm","clk":"1003182536","pt":1580604038831,"mc":[{"id":"1.168179120","rc":[{"batb":[[0,1.21,1118.94]],"batl":[[0,1.23,40.82],[1,1.24,376.51],[2,1.25,168.04]],"ltp":1.22,"tv":12238.21,"id":8326656},{"batb":[[0,5.2,120.54]],"ltp":5.3,"tv":2609.37,"id":9712909}]}]}
{"op":"mcm","clk":"1003183246","pt":1580604049424,"mc":[{"id":"1.168179120","rc":[{"batb":[[1,1.2,115.99],[2,1.17,774.9]],"ltp":1.22,"tv":12238.21,"id":8326656}]}]}
{"op":"mcm","clk":"1003184174","pt":1580604063653,"mc":[{"id":"1.168179120","rc":[{"batl":[[0,1.23,97.11],[1,1.24,320.21]],"ltp":1.22,"tv":12238.21,"id":8326656},{"batb":[[0,5.3,11.05],[1,5.2,120.54],[2,5,13.98]],"ltp":5.3,"tv":2609.37,"id":9712909}]}]}
{"op":"mcm","clk":"1003184237","pt":1580604064640,"mc":[{"id":"1.168179120","rc":[{"trd":[[1.23,109.94]],"batl":[[0,1.23,15.46]],"ltp":1.23,"tv":12319.86,"id":8326656},{"trd":[[5.3,606.89]],"batb":[[0,5.2,120.54],[1,5,13.98],[2,4.8,23.68]],"ltp":5.3,"tv":2650.42,"id":9712909}],"tv":14970.29}]}
{"op":"mcm","clk":"1003185119","pt":1580604078874,"mc":[{"id":"1.168179120","rc":[{"batl":[[1,1.24,488.25],[2,1.54,5.07]],"ltp":1.23,"tv":12319.86,"id":8326656}]}]}
{"op":"mcm","clk":"1003185352","pt":1580604082759,"mc":[{"id":"1.168179120","rc":[{"batb":[[0,1.22,44.18],[1,1.21,1118.94]],"ltp":1.23,"tv":12319.86,"id":8326656}]}]}
{"op":"mcm","clk":"1003185929","pt":1580604092085,"mc":[{"id":"1.168179120","rc":[{"batb":[[0,1.22,172.18]],"ltp":1.23,"tv":12319.86,"id":8326656}]}]}
{"op":"mcm","clk":"1003186125","pt":1580604095585,"mc":[{"id":"1.168179120","rc":[{"trd":[[1.23,140.86]],"batb":[[0,1.23,29.17],[1,1.22,172.18],[2,1.21,1138.63]],"batl":[[0,1.24,488.25],[1,1.54,5.07],[2,1.55,10.08]],"ltp":1.23,"tv":12350.78,"id":8326656}],"tv":15001.21}]}
{"op":"mcm","clk":"1003186231","pt":1580604097801,"mc":[{"id":"1.168179120","rc":[{"batb":[[0,1.23,32.2]],"ltp":1.23,"tv":12350.78,"id":8326656}]}]}
{"op":"mcm","clk":"1003186362","pt":1580604100268,"mc":[{"id":"1.168179120","rc":[{"batb":[[1,4.8,23.97],[2,4.2,46.88]],"ltp":5.3,"tv":2650.42,"id":9712909}]}]}
{"op":"mcm","clk":"1003186818","pt":1580604107920,"mc":[{"id":"1.168179120","rc":[{"batb":[[0,1.23,45.24]],"ltp":1.23,"tv":12350.78,"id":8326656}]}]}
{"op":"mcm","clk":"1003187299","pt":1580604116104,"mc":[{"id":"1.168179120","rc":[{"batb":[[1,1.22,228.47]],"ltp":1.23,"tv":12350.78,"id":8326656}]}]}
{"op":"mcm","clk":"1003187453","pt":1580604119129,"mc":[{"id":"1.168179120","rc":[{"trd":[[1.23,216.59]],"batb":[[0,1.23,7.38]],"ltp":1.23,"tv":12426.51,"id":8326656}],"tv":15076.93}]}
{"op":"mcm","clk":"1003187522","pt":1580604120211,"mc":[{"id":"1.168179120","rc":[{"batb":[[1,5,13.98],[2,4.8,23.68]],"ltp":5.3,"tv":2650.42,"id":9712909}]}]}
{"op":"mcm","clk":"1003188972","pt":1580604144873,"mc":[{"id":"1.168179120","rc":[{"batb":[[0,5.2,119.83]],"ltp":5.3,"tv":2650.42,"id":9712909}]}]}
{"op":"mcm","clk":"1003189011","pt":1580604145543,"mc":[{"id":"1.168179120","rc":[{"batb":[[2,1.21,1118.94]],"ltp":1.23,"tv":12426.51,"id":8326656}]}]}
{"op":"mcm","clk":"1003191620","pt":1580604189480,"mc":[{"id":"1.168179120","rc":[{"trd":[[5.2,73.5]],"batb":[[0,5.2,104.68]],"ltp":5.2,"tv":2680.71,"id":9712909}],"tv":15107.22}]}
{"op":"mcm","clk":"1003191750","pt":1580604191691,"mc":[{"id":"1.168179120","rc":[{"batb":[[0,1.23,53.97],[2,1.21,1057.46]],"ltp":1.23,"tv":12426.51,"id":8326656},{"batb":[[2,4.9,25.19]],"ltp":5.2,"tv":2680.71,"id":9712909}]}]}
{"op":"mcm","clk":"1003191972","pt":1580604195496,"mc":[{"id":"1.168179120","rc":[{"batb":[[1,4.9,25.47],[2,4.8,23.68]],"ltp":5.2,"tv":2680.71,"id":9712909}]}]}
{"op":"mcm","clk":"1003192074","pt":1580604197296,"mc":[{"id":"1.168179120","rc":[{"trd":[[1.24,97.78]],"batl":[[0,1.24,484.46]],"ltp":1.24,"tv":12434.08,"id":8326656}],"tv":15114.8}]}
{"op":"mcm","clk":"1003192175","pt":1580604198793,"mc":[{"id":"1.168179120","rc":[{"trd":[[1.23,321.46]],"batb":[[0,1.22,228.47],[1,1.21,1057.46],[2,1.17,774.9]],"ltp":1.23,"tv":12538.96,"id":8326656}],"tv":15219.67}]}
{"op":"mcm","clk":"1003192207","pt":1580604199208,"mc":[{"id":"1.168179120","rc":[{"batb":[[0,1.22,247.01]],"ltp":1.23,"tv":12538.96,"id":8326656},{"batb":[[0,5.2,115.41],[1,4.8,23.97],[2,4.2,46.88]],"ltp":5.2,"tv":2680.71,"id":9712909}]}]}
{"op":"mcm","clk":"1003192293","pt":1580604200803,"mc":[{"id":"1.168179120","rc":[{"batl":[[1,1.25,12.83],[2,1.54,5.07]],"ltp":1.23,"tv":12538.96,"id":8326656},{"batb":[[1,5,13.98],[2,4.8,23.68]],"ltp":5.2,"tv":2680.71,"id":9712909}]}]}
{"op":"mcm","clk":"1003194386","pt":1580604236507,"mc":[{"id":"1.168179120","rc":[{"batl":[[0,1.23,506.76],[1,1.24,484.46],[2,1.25,12.83]],"ltp":1.23,"tv":12538.96,"id":8326656}]}]}
{"op":"mcm","clk":"1003194570","pt":1580604239639,"mc":[{"id":"1.168179120","rc":[{"trd":[[1.23,361.45]],"batl":[[0,1.23,486.78]],"ltp":1.23,"tv":12578.94,"id":8326656}],"tv":15259.65}]}
{"op":"mcm","clk":"1003195160","pt":1580604248743,"mc":[{"id":"1.168179120","rc":[{"trd":[[1.22,605.92],[1.23,362.33]],"batb":[[0,1.22,229.32]],"batl":[[0,1.23,486.34]],"ltp":1.23,"tv":12615.19,"id":8326656},{"batb":[[0,5.2,119.5]],"ltp":5.2,"tv":2680.71,"id":9712909}],"tv":15295.9}]}
{"op":"mcm","clk":"1003195263","pt":1580604250335,"mc":[{"id":"1.168179120","rc":[{"trd":[[1.22,646.24]],"batb":[[0,1.22,209.16]],"ltp":1.22,"tv":12655.5,"id":8326656}],"tv":15336.22}]}
{"op":"mcm","clk":"1003195317","pt":1580604251368,"mc":[{"id":"1.168179120","rc":[{"batb":[[0,1.22,184.29],[2,1.19,231.06]],"ltp":1.22,"tv":12655.5,"id":8326656},{"batb":[[0,5.3,4.63],[1,5.2,119.5],[2,5,13.98]],"ltp":5.2,"tv":2680.71,"id":9712909}]}]}
{"op":"mcm","clk":"1003196294","pt":1580604267084,"mc":[{"id":"1.168179120","rc":[{"trd":[[1.22,654.8]],"batb":[[0,1.22,180.01]],"ltp":1.22,"tv":12664.06,"id":8326656}],"tv":15344.78}]}
{"op":"mcm","clk":"1003196819","pt":1580604276053,"mc":[{"id":"1.168179120","rc":[{"batl":[[0,1.23,1060.01]],"ltp":1.22,"tv":12664.06,"id":8326656}]}]}
{"op":"mcm","clk":"1003196900","pt":1580604277185,"mc":[{"id":"1.168179120","rc":[{"trd":[[1.22,704.3]],"batb":[[0,1.22,155.26]],"batl":[[0,1.23,1089.04],[1,1.24,316.42]],"ltp":1.22,"tv":12713.56,"id":8326656}],"tv":15394.28}]}
{"op":"mcm","clk":"1003198643","pt":1580604306310,"mc":[{"id":"1.168179120","rc":[{"trd":[[1.23,513.7]],"batb":[[1,1.21,981.73]],"batl":[[0,1.23,1013.39]],"ltp":1.23,"tv":12864.93,"id":8326656}],"tv":15545.65}]}
{"op":"mcm","clk":"1003199590","pt":1580604319848,"mc":[{"id":"1.168179120","marketDefinition":{"bspMarket":false,"turnInPlayEnabled":true,"persistenceEnabled":true,"marketBaseRate":5.0,"eventId":"29680182","eventTypeId":"2","numberOfWinners":1,"bettingType":"ODDS","marketType":"MATCH_ODDS","marketTime":"2020-02-02T00:32:00.000Z","suspendTime":"2020-02-02T00:32:00.000Z","bspReconciled":false,"complete":true,"inPlay":true,"crossMatching":true,"runnersVoidable":false,"numberOfActiveRunners":2,"betDelay":3,"status":"OPEN","runners":[{"status":"ACTIVE","sortPriority":1,"id":9712909,"name":"Felipe Meligeni Rodrigu"},{"status":"ACTIVE","sortPriority":2,"id":8326656,"name":"Thiago Monteiro"}],"regulators":["MR_INT"],"countryCode":"UY","discountAllowed":true,"timezone":"UTC","openDate":"2020-02-02T00:32:00.000Z","version":3147941745,"name":"Match Odds","eventName":"Meligeni Rodrigues Alve v T Monteiro"},"rc":[{"batb":[[0,1.17,774.9],[1,1.12,952.6],[2,1.03,246.87]],"batl":[[0,1.23,573.67],[1,1.24,121.56]],"ltp":1.23,"tv":12864.93,"id":8326656},{"batb":[[0,3.3,28.52],[1,2.58,66.59],[2,1.03,9.21]],"batl":[[0,1000,0.02],[1,990,0],[2,1000,0]],"ltp":5.2,"tv":2680.71,"id":9712909}]}]}
{"op":"mcm","clk":"1003199616","pt":1580604320259,"mc":[{"id":"1.168179120","rc":[{"batl":[[0,1.24,121.56],[1,1.25,12.83],[2,1.54,5.07]],"ltp":1.23,"tv":12864.93,"id":8326656}]}]}
{"op":"mcm","clk":"1003199807","pt":1580604323356,"mc":[{"id":"1.168179120","rc":[{"batl":[[2,1.27,573.67]],"ltp":1.23,"tv":12864.93,"id":8326656}]}]}
{"op":"mcm","clk":"1003199918","pt":1580604325062,"mc":[{"id":"1.168179120","rc":[{"batl":[[1,1.27,573.67],[2,1.54,5.07]],"ltp":1.23,"tv":12864.93,"id":8326656}]}]}
{"op":"mcm","clk":"1003200151","pt":1580604328564,"mc":[{"id":"1.168179120","rc":[{"batl":[[0,1.23,13.04],[1,1.24,121.56],[2,1.27,573.67]],"ltp":1.23,"tv":12864.93,"id":8326656}]}]}
{"op":"mcm","clk":"1003200218","pt":1580604329441,"mc":[{"id":"1.168179120","rc":[{"trd":[[1.23,526.74],[1.24,219.34]],"batb":[[0,1.25,336.51],[1,1.17,774.9],[2,1.12,952.6]],"batl":[[0,1.27,590.34],[1,1.28,816.84],[2,1.54,5.07]],"ltp":1.24,"tv":12999.53,"id":8326656},{"trd":[[5.1,67.03],[5.3,609.92]],"batl":[[0,5,84.13],[1,1000,0.02]],"ltp":5.1,"tv":2713.33,"id":9712909}],"tv":15712.87}]}
{"op":"mcm","clk":"1003200280","pt":1580604330575,"mc":[{"id":"1.168179120","rc":[{"batb":[[1,1.24,806.17],[2,1.22,906.18]],"ltp":1.24,"tv":12999.53,"id":8326656},{"batb":[[0,4.6,134.78],[1,4,189.54],[2,3.3,28.52]],"ltp":5.1,"tv":2713.33,"id":9712909}]}]}
{"op":"mcm","clk":"1003200485","pt":1580604333664,"mc":[{"id":"1.168179120","rc":[{"trd":[[1.25,118.28]],"batb":[[0,1.25,1345.36],[1,1.24,2228.33]],"batl":[[1,1.28,2383.23],[2,1.29,1076.15]],"ltp":1.25,"tv":13000.74,"id":8326656}],"tv":15714.07}]}
{"op":"mcm","clk":"1003200521","pt":1580604334385,"mc":[{"id":"1.168179120","rc":[{"trd":[[1.25,130.1]],"batb":[[0,1.25,1339.45]],"ltp":1.25,"tv":13012.56,"id":8326656}],"tv":15725.89}]}
{"op":"mcm","clk":"1003200745","pt":1580604338046,"mc":[{"id":"1.168179120","rc":[{"trd":[[1.25,951.9]],"batb":[[0,1.25,928.34]],"ltp":1.25,"tv":13834.36,"id":8326656}],"tv":16547.69}]}
{"op":"mcm","clk":"1003200905","pt":1580604340646,"mc":[{"id":"1.168179120","rc":[{"batb":[[0,1.26,500],[1,1.25,928.34],[2,1.24,2228.33]],"ltp":1.25,"tv":13834.36,"id":8326656}]}]}
{"op":"mcm","clk":"1003201183","pt":1580604344865,"mc":[{"id":"1.168179120","rc":[{"trd":[[1.26,38.12]],"batb":[[0,1.26,490.91]],"batl":[[0,1.27,16.67]],"ltp":1.26,"tv":13852.54,"id":8326656}],"tv":16565.87}]}
{"op":"mcm","clk":"1003201381","pt":1580604348310,"mc":[{"id":"1.168179120","rc":[{"trd":[[1.26,1019.94]],"batb":[[0,1.25,928.34],[1,1.24,2228.33],[2,1.22,906.18]],"batl":[[0,1.26,82.76]],"ltp":1.26,"tv":14834.36,"id":8326656},{"batl":[[0,5,79.78]],"ltp":5.1,"tv":2713.33,"id":9712909}],"tv":17547.69}]}
{"op":"mcm","clk":"1003201454","pt":1580604349490,"mc":[{"id":"1.168179120","rc":[{"batb":[[0,1.22,906.18],[1,1.18,168.05],[2,1.17,774.88]],"batl":[[1,1.54,5.07],[2,1.55,10.08]],"ltp":1.26,"tv":14834.36,"id":8326656},{"batb":[[0,4,189.54],[1,3.3,28.52],[2,2.58,66.59]],"batl":[[0,1000,0.02],[1,1000,0]],"ltp":5.1,"tv":2713.33,"id":9712909}]}]}
{"op":"mcm","clk":"1003201481","pt":1580604349901,"mc":[{"id":"1.168179120","rc":[{"batb":[[0,4,184.75]],"ltp":5.1,"tv":2713.33,"id":9712909}]}]}
{"op":"mcm","clk":"1003201653","pt":1580604352787,"mc":[{"id":"1.168179120","rc":[{"batl":[[0,1.54,5.07],[1,1.55,10.08],[2,1000,0.07]],"ltp":1.26,"tv":14834.36,"id":8326656}]}]}
{"op":"mcm","clk":"1003201852","pt":1580604355776,"mc":[{"id":"1.168179120","rc":[{"batb":[[0,1.26,866.73],[1,1.25,1351.64],[2,1.23,20]],"batl":[[0,1.29,1553.1],[1,1.3,1034],[2,1.31,82.76]],"ltp":1.26,"tv":14834.36,"id":8326656}]}]}
{"op":"mcm","clk":"1003201912","pt":1580604356803,"mc":[{"id":"1.168179120","rc":[{"batl":[[0,1.27,250],[1,1.29,1553.1],[2,1.3,1034]],"ltp":1.26,"tv":14834.36,"id":8326656}]}]}
{"op":"mcm","clk":"1003201971","pt":1580604357780,"mc":[{"id":"1.168179120","rc":[{"batb":[[0,1.26,868.4]],"ltp":1.26,"tv":14834.36,"id":8326656}]}]}
{"op":"mcm","clk":"1003202066","pt":1580604359320,"mc":[{"id":"1.168179120","rc":[{"batb":[[0,1.26,1.67],[1,1.23,20],[2,1.22,906.18]],"batl":[[1,1.31,82.76],[2,1.54,5.07]],"ltp":1.26,"tv":14834.36,"id":8326656}]}]}
{"op":"mcm","clk":"1003202143","pt":1580604360400,"mc":[{"id":"1.168179120","rc":[{"batl":[[1,1.28,250]],"ltp":1.26,"tv":14834.36,"id":8326656}]}]}
{"op":"mcm","clk":"1003202249","pt":1580604362207,"mc":[{"id":"1.168179120","rc":[{"batb":[[2,1.22,2976.16]],"batl":[[2,1.33,1188.19]],"ltp":1.26,"tv":14834.36,"id":8326656}]}]}
{"op":"mcm","clk":"1003202314","pt":1580604363492,"mc":[{"id":"1.168179120","rc":[{"batl":[[2,1.33,1270.95]],"ltp":1.26,"tv":14834.36,"id":8326656}]}]}
{"op":"mcm","clk":"1003202373","pt":1580604364624,"mc":[{"id":"1.168179120","rc":[{"batb":[[0,1.23,20],[1,1.22,2976.16],[2,1.21,1341.81]],"ltp":1.26,"tv":14834.36,"id":8326656}]}]}
{"op":"mcm","clk":"1003202564","pt":1580604368732,"mc":[{"id":"1.168179120","rc":[{"batb":[[0,1.23,29.31],[1,1.22,906.18],[2,1.18,168.05]],"ltp":1.26,"tv":14834.36,"id":8326656}]}]}
{"op":"mcm","clk":"1003202592","pt":1580604369298,"mc":[{"id":"1.168179120","rc":[{"batl":[[0,1.33,1270.95],[1,1.34,892.53],[2,1.54,5.07]],"ltp":1.26,"tv":14834.36,"id":8326656}]}]}
{"op":"mcm","clk":"1003202752","pt":1580604371818,"mc":[{"id":"1.168179120","rc":[{"batb":[[0,1.3,4193.31],[1,1.29,1124.99],[2,1.23,29.31]],"batl":[[0,1.32,22.58],[1,1.33,4654.41],[2,1.34,1879.26]],"ltp":1.26,"tv":14834.36,"id":8326656},{"batl":[[0,4.3,3.74],[1,5.1,1119.87],[2,1000,0.02]],"ltp":5.1,"tv":2713.33,"id":9712909}]}]}
{"op":"mcm","clk":"1003202839","pt":1580604372793,"mc":[{"id":"1.168179120","rc":[{"batb":[[1,1.29,1774.27],[2,1.27,4.3]],"ltp":1.26,"tv":14834.36,"id":8326656},{"batb":[[1,3.55,126.91],[2,3.3,28.52]],"ltp":5.1,"tv":2713.33,"id":9712909}]}]}
{"op":"mcm","clk":"1003202946","pt":1580604375003,"mc":[{"id":"1.168179120","rc":[{"trd":[[1.3,0.32]],"batb":[[0,1.3,4193.15]],"ltp":1.3,"tv":14834.67,"id":8326656}],"tv":17548.01}]}
{"op":"mcm","clk":"1003203143","pt":1580604379723,"mc":[{"id":"1.168179120","rc":[{"batb":[[2,1.27,1.76]],"ltp":1.3,"tv":14834.67,"id":8326656}]}]}
{"op":"mcm","clk":"1003203200","pt":1580604380700,"mc":[{"id":"1.168179120","rc":[{"trd":[[1.3,210.32]],"batb":[[0,1.3,4088.15]],"batl":[[1,1.33,4571.65]],"ltp":1.3,"tv":15044.67,"id":8326656}],"tv":17758.01}]}
{"op":"mcm","clk":"1003203306","pt":1580604382860,"mc":[{"id":"1.168179120","rc":[{"trd":[[1.3,213.53]],"batb":[[0,1.3,4086.54]],"ltp":1.3,"tv":15047.89,"id":8326656}],"tv":17761.22}]}
{"op":"mcm","clk":"1003203337","pt":1580604383428,"mc":[{"id":"1.168179120","rc":[{"batl":[[0,1.32,355.34]],"ltp":1.3,"tv":15047.89,"id":8326656}]}]}
{"op":"mcm","clk":"1003203515","pt":1580604386712,"mc":[{"id":"1.168179120","rc":[{"trd":[[1.32,4.02]],"batl":[[0,1.32,353.33]],"ltp":1.32,"tv":15051.91,"id":8326656}],"tv":17765.24}]}
{"op":"mcm","clk":"1003203585","pt":1580604387842,"mc":[{"id":"1.168179120","rc":[{"batl":[[0,1.31,20],[1,1.32,353.33],[2,1.33,4571.65]],"ltp":1.32,"tv":15051.91,"id":8326656},{"batb":[[2,3.3,28.63]],"ltp":5.1,"tv":2713.33,"id":9712909}]}]}
{"op":"mcm","clk":"1003203652","pt":1580604388716,"mc":[{"id":"1.168179120","rc":[{"batb":[[0,1.27,1.76],[1,1.26,746.53],[2,1.23,9.31]],"batl":[[1,1.32,332.76],[2,1.54,5.07]],"ltp":1.32,"tv":15051.91,"id":8326656},{"batb":[[0,3.55,126.91],[1,3.3,28.63],[2,2.58,66.59]],"batl":[[0,1000,0.02],[1,5.1,0],[2,1000,0]],"ltp":5.1,"tv":2713.33,"id":9712909}]}]}
{"op":"mcm","clk":"1003203696","pt":1580604389436,"mc":[{"id":"1.168179120","rc":[{"batl":[[1,1.32,250]],"ltp":1.32,"tv":15051.91,"id":8326656}]}]}
{"op":"mcm","clk":"1003203769","pt":1580604390825,"mc":[{"id":"1.168179120","rc":[{"trd":[[1.31,3.34],[1.32,36.02]],"batl":[[0,1.32,234],[1,1.54,5.07],[2,1.55,10.08]],"ltp":1.32,"tv":15087.25,"id":8326656}],"tv":17800.59}]}
{"op":"mcm","clk":"1003203811","pt":1580604391441,"mc":[{"id":"1.168179120","rc":[{"trd":[[1.32,38.24]],"batb":[[0,1.27,578.09],[1,1.26,2029.1]],"batl":[[0,1.32,232.89],[1,1.4,1074.76],[2,1.41,706.65]],"ltp":1.32,"tv":15089.47,"id":8326656}],"tv":17802.81}]}
{"op":"mcm","clk":"1003203875","pt":1580604392522,"mc":[{"id":"1.168179120","rc":[{"batl":[[0,1.31,82.76],[1,1.32,232.89],[2,1.4,1074.76]],"ltp":1.32,"tv":15089.47,"id":8326656}]}]}
{"op":"mcm","clk":"1003203898","pt":1580604392932,"mc":[{"id":"1.168179120","rc":[{"batl":[[2,1.54,5.07]],"ltp":1.32,"tv":15089.47,"id":8326656}]}]}
{"op":"mcm","clk":"1003204051","pt":1580604395837,"mc":[{"id":"1.168179120","rc":[{"batb":[[0,1.27,4134.66],[2,1.25,770.34]],"batl":[[0,1.29,637.91],[1,1.3,4512.77],[2,1.31,82.76]],"ltp":1.32,"tv":15089.47,"id":8326656},{"batb":[[0,4.5,6.83],[1,3.55,126.91],[2,3.3,28.63]],"batl":[[0,5,192.58],[1,1000,0.02]],"ltp":5.1,"tv":2713.33,"id":9712909}]}]}
{"op":"mcm","clk":"1003204105","pt":1580604396767,"mc":[{"id":"1.168179120","rc":[{"batb":[[0,1.27,4121.4]],"ltp":1.32,"tv":15089.47,"id":8326656},{"batb":[[0,4.4,150.91],[1,3.8,110]],"ltp":5.1,"tv":2713.33,"id":9712909}]}]}
{"op":"mcm","clk":"1003204210","pt":1580604398718,"mc":[{"id":"1.168179120","rc":[{"batl":[[0,1.29,887.91]],"ltp":1.32,"tv":15089.47,"id":8326656}]}]}
{"op":"mcm","clk":"1003204231","pt":1580604399129,"mc":[{"id":"1.168179120","rc":[{"batb":[[0,1.27,4134.66]],"ltp":1.32,"tv":15089.47,"id":8326656},{"batb":[[0,4.5,6.83],[1,4.4,150.91],[2,3.8,110]],"ltp":5.1,"tv":2713.33,"id":9712909}]}]}
{"op":"mcm","clk":"1003204316","pt":1580604400771,"mc":[{"id":"1.168179120","rc":[{"batl":[[0,1.28,250],[1,1.29,887.91],[2,1.3,4512.77]],"ltp":1.32,"tv":15089.47,"id":8326656}]}]}
{"op":"mcm","clk":"1003204397","pt":1580604402362,"mc":[{"id":"1.168179120","rc":[{"trd":[[1.28,28]],"batl":[[0,1.28,236]],"ltp":1.28,"tv":15117.47,"id":8326656}],"tv":17830.81}]}
{"op":"mcm","clk":"1003204618","pt":1580604406368,"mc":[{"id":"1.168179120","rc":[{"trd":[[1.28,68]],"batl":[[0,1.28,216]],"ltp":1.28,"tv":15157.47,"id":8326656}],"tv":17870.81}]}
{"op":"mcm","clk":"1003204817","pt":1580604409861,"mc":[{"id":"1.168179120","rc":[{"batb":[[0,1.27,1.76],[1,1.23,879.06],[2,1.18,168.05]],"batl":[[1,1.29,250],[2,1.54,5.07]],"ltp":1.28,"tv":15157.47,"id":8326656},{"batb":[[0,3.8,110],[1,3.3,28.63],[2,2.58,66.59]],"batl":[[0,1000,0.02],[1,1000,0]],"ltp":5.1,"tv":2713.33,"id":9712909}]}]}
{"op":"mcm","clk":"1003204829","pt":1580604410171,"mc":[{"id":"1.168179120","rc":[{"batl":[[2,1.35,82.76]],"ltp":1.28,"tv":15157.47,"id":8326656}]}]}
{"op":"mcm","clk":"1003204978","pt":1580604412789,"mc":[{"id":"1.168179120","rc":[{"batb":[[1,1.23,2729.25],[2,1.22,1535.42]],"ltp":1.28,"tv":15157.47,"id":8326656}]}]}
{"op":"mcm","clk":"1003205083","pt":1580604414484,"mc":[{"id":"1.168179120","rc":[{"batb":[[0,1.23,2729.25],[1,1.22,1535.42],[2,1.18,168.05]],"ltp":1.28,"tv":15157.47,"id":8326656}]}]}
{"op":"mcm","clk":"1003205119","pt":1580604415049,"mc":[{"id":"1.168179120","rc":[{"trd":[[1.27,3.36],[1.28,74.82]],"batl":[[0,1.28,212.59]],"ltp":1.28,"tv":15167.66,"id":8326656}],"tv":17880.99}]}
{"op":"mcm","clk":"1003205329","pt":1580604418793,"mc":[{"id":"1.168179120","rc":[{"trd":[[1.23,1958.78]],"batb":[[0,1.23,2013.21]],"batl":[[0,1.27,45.97],[1,1.28,212.59],[2,1.29,250]],"ltp":1.23,"tv":16599.7,"id":8326656}],"tv":19313.03}]}
{"op":"mcm","clk":"1003205481","pt":1580604421161,"mc":[{"id":"1.168179120","rc":[{"batl":[[0,1.28,212.59],[1,1.29,250],[2,1.35,82.76]],"ltp":1.23,"tv":16599.7,"id":8326656}]}]}
{"op":"mcm","clk":"1003205659","pt":1580604423894,"mc":[{"id":"1.168179120","rc":[{"trd":[[1.28,287.41]],"batb":[[0,1.23,163.02],[1,1.18,168.05],[2,1.17,774.88]],"batl":[[0,1.35,82.76],[1,1.36,523.19],[2,1.37,811.9]],"ltp":1.28,"tv":16812.29,"id":8326656},{"trd":[[4.5,60.47]],"batl":[[0,4.5,123.17],[1,1000,0.02]],"ltp":4.5,"tv":2773.8,"id":9712909}],"tv":19586.1}]}
{"op":"mcm","clk":"1003205685","pt":1580604424363,"mc":[{"id":"1.168179120","rc":[{"trd":[[1.28,333.38]],"ltp":1.28,"tv":16858.26,"id":8326656},{"trd":[[4.5,73.55]],"batl":[[0,4.5,110.09]],"ltp":4.5,"tv":2786.88,"id":9712909}],"tv":19645.14}]}
{"op":"mcm","clk":"1003205759","pt":1580604425757,"mc":[{"id":"1.168179120","rc":[{"batb":[[0,1.33,3383.46],[1,1.23,163.02],[2,1.18,168.05]],"batl":[[1,1.36,3832.01]],"ltp":1.28,"tv":16858.26,"id":8326656},{"batl":[[0,4,1715.6],[1,4.5,113.8],[2,1000,0.02]],"ltp":4.5,"tv":2786.88,"id":9712909}]}]}
{"op":"mcm","clk":"1003205822","pt":1580604426784,"mc":[{"id":"1.168179120","rc":[{"batb":[[0,1.33,4517.21],[1,1.32,1595.2],[2,1.28,698.14]],"batl":[[0,1.35,96.35]],"ltp":1.28,"tv":16858.26,"id":8326656},{"batb":[[0,3.85,209.84],[1,3.8,110],[2,3.3,178.83]],"batl":[[0,4,5.72],[1,4.2,384.38],[2,4.5,110.09]],"ltp":4.5,"tv":2786.88,"id":9712909}]}]}
{"op":"mcm","clk":"1003205867","pt":1580604427402,"mc":[{"id":"1.168179120","rc":[{"batb":[[1,3.3,178.83],[2,2.58,66.59]],"ltp":4.5,"tv":2786.88,"id":9712909}]}]}
{"op":"mcm","clk":"1003205913","pt":1580604428175,"mc":[{"id":"1.168179120","rc":[{"batl":[[2,1000,0.02]],"ltp":4.5,"tv":2786.88,"id":9712909}]}]}
{"op":"mcm","clk":"1003206267","pt":1580604434472,"mc":[{"id":"1.168179120","rc":[{"batl":[[0,1.34,125],[1,1.35,96.35],[2,1.36,3832.01]],"ltp":1.28,"tv":16858.26,"id":8326656}]}]}
{"op":"mcm","clk":"1003206426","pt":1580604436993,"mc":[{"id":"1.168179120","rc":[{"batl":[[1,1.35,13.59]],"ltp":1.28,"tv":16858.26,"id":8326656}]}]}
{"op":"mcm","clk":"1003206507","pt":1580604438686,"mc":[{"id":"1.168179120","rc":[{"trd":[[1.34,3.16]],"batl":[[0,1.34,123.42]],"ltp":1.34,"tv":16861.42,"id":8326656}],"tv":19648.3}]}
{"op":"mcm","clk":"1003206518","pt":1580604438995,"mc":[{"id":"1.168179120","rc":[{"trd":[[1.34,15.88]],"batl":[[0,1.34,117.06]],"ltp":1.34,"tv":16874.14,"id":8326656}],"tv":19661.03}]}
{"op":"mcm","clk":"1003206596","pt":1580604440792,"mc":[{"id":"1.168179120","rc":[{"trd":[[1.33,42.8]],"batb":[[0,1.33,4495.81]],"batl":[[0,1.34,199.82]],"ltp":1.33,"tv":16916.95,"id":8326656}],"tv":19703.83}]}
{"op":"mcm","clk":"1003206721","pt":1580604443725,"mc":[{"id":"1.168179120","rc":[{"batb":[[0,1.28,698.14],[1,1.18,168.05],[2,1.17,774.88]],"batl":[[1,1.54,5.07],[2,1.55,10.08]],"ltp":1.33,"tv":16916.95,"id":8326656},{"batb":[[0,3.3,178.83],[1,2.58,66.59],[2,1.03,9.21]],"batl":[[0,1000,0.02],[1,4.2,0],[2,1000,0]],"ltp":4.5,"tv":2786.88,"id":9712909}]}]}
{"op":"mcm","clk":"1003206817","pt":1580604445734,"mc":[{"id":"1.168179120","rc":[{"batl":[[0,1.33,2.52],[1,1.34,117.06],[2,1.54,5.07]],"ltp":1.33,"tv":16916.95,"id":8326656}]}]}
{"op":"mcm","clk":"1003206842","pt":1580604446404,"mc":[{"id":"1.168179120","rc":[{"batb":[[0,1.29,1225.97],[1,1.28,1882.27],[2,1.18,168.05]],"batl":[[2,1.45,578.38]],"ltp":1.33,"tv":16916.95,"id":8326656}]}]}
{"op":"mcm","clk":"1003206874","pt":1580604447126,"mc":[{"id":"1.168179120","rc":[{"batb":[[0,1.28,698.14],[1,1.18,168.05],[2,1.17,774.88]],"batl":[[2,1.54,5.07]],"ltp":1.33,"tv":16916.95,"id":8326656}]}]}
{"op":"mcm","clk":"1003206948","pt":1580604448822,"mc":[{"id":"1.168179120","rc":[{"trd":[[1.33,43.42]],"batl":[[0,1.33,84.97],[1,1.54,5.07],[2,1.55,10.08]],"ltp":1.33,"tv":16917.57,"id":8326656}],"tv":19704.45}]}
{"op":"mcm","clk":"1003207052","pt":1580604450632,"mc":[{"id":"1.168179120","rc":[{"trd":[[1.33,213.36]],"batb":[[0,1.35,618.77],[1,1.34,921.99],[2,1.28,698.14]],"batl":[[0,1.38,764.75],[1,1.39,756.81],[2,1.54,5.07]],"ltp":1.33,"tv":17087.51,"id":8326656}],"tv":19874.39}]}
{"op":"mcm","clk":"1003207141","pt":1580604452328,"mc":[{"id":"1.168179120","rc":[{"batb":[[2,1.32,30]],"ltp":1.33,"tv":17087.51,"id":8326656}]}]}
{"op":"mcm","clk":"1003207268","pt":1580604454538,"mc":[{"id":"1.168179120","rc":[{"batb":[[0,1.28,698.14],[1,1.18,168.05],[2,1.17,774.88]],"batl":[[0,1.54,5.07],[1,1.55,10.08],[2,1000,0.07]],"ltp":1.33,"tv":17087.51,"id":8326656}]}]}
{"op":"mcm","clk":"1003207330","pt":1580604455514,"mc":[{"id":"1.168179120","rc":[{"batl":[[0,1.36,50],[1,1.54,5.07],[2,1.55,10.08]],"ltp":1.33,"tv":17087.51,"id":8326656}]}]}
{"op":"mcm","clk":"1003207375","pt":1580604456439,"mc":[{"id":"1.168179120","rc":[{"batl":[[1,1.37,50],[2,1.54,5.07]],"ltp":1.33,"tv":17087.51,"id":8326656}]}]}
{"op":"mcm","clk":"1003207432","pt":1580604457418,"mc":[{"id":"1.168179120","rc":[{"batb":[[0,1.29,1167.12],[1,1.28,1882.24],[2,1.18,168.05]],"batl":[[2,1.45,631.05]],"ltp":1.33,"tv":17087.51,"id":8326656}]}]}
{"op":"mcm","clk":"1003207750","pt":1580604464257,"mc":[{"id":"1.168179120","rc":[{"batl":[[0,1.45,631.05],[1,1.46,613.73],[2,1.54,5.07]],"ltp":1.33,"tv":17087.51,"id":8326656}]}]}
{"op":"mcm","clk":"1003207834","pt":1580604465647,"mc":[{"id":"1.168179120","rc":[{"batl":[[0,1.45,631.06]],"ltp":1.33,"tv":17087.51,"id":8326656}]}]}
{"op":"mcm","clk":"1003208684","pt":1580604480688,"mc":[{"id":"1.168179120","rc":[{"batl":[[0,1.54,5.07],[1,1.55,10.08],[2,1000,0.07]],"ltp":1.33,"tv":17087.51,"id":8326656}]}]}
{"op":"mcm","clk":"1003208869","pt":1580604483682,"mc":[{"id":"1.168179120","rc":[{"batb":[[0,1.29,4655.49],[1,1.28,2876.5]],"batl":[[0,1.31,18.83],[1,1.32,4306.05],[2,1.33,1976.23]],"ltp":1.33,"tv":17087.51,"id":8326656},{"batl":[[0,4.4,4.47],[1,1000,0.02]],"ltp":4.5,"tv":2786.88,"id":9712909}]}]}
{"op":"mcm","clk":"1003208942","pt":1580604484668,"mc":[{"id":"1.168179120","rc":[{"batb":[[2,1.23,876.28]],"ltp":1.33,"tv":17087.51,"id":8326656},{"batb":[[0,4.2,166.41],[1,3.4,141.26],[2,3.3,28.52]],"ltp":4.5,"tv":2786.88,"id":9712909}]}]}
{"op":"mcm","clk":"1003209160","pt":1580604488172,"mc":[{"id":"1.168179120","rc":[{"batl":[[0,1.3,125],[1,1.31,18.83],[2,1.32,4306.05]],"ltp":1.33,"tv":17087.51,"id":8326656}]}]}
{"op":"mcm","clk":"1003209338","pt":1580604491463,"mc":[{"id":"1.168179120","rc":[{"batl":[[1,5.4,2],[2,1000,0.02]],"ltp":4.5,"tv":2786.88,"id":9712909}]}]}
{"op":"mcm","clk":"1003209383","pt":1580604492285,"mc":[{"id":"1.168179120","rc":[{"trd":[[1.3,281.02]],"batl":[[0,1.3,91.26]],"ltp":1.3,"tv":17154.99,"id":8326656}],"tv":19941.88}]}
{"op":"mcm","clk":"1003209506","pt":1580604494596,"mc":[{"id":"1.168179120","rc":[{"batb":[[2,1.23,949.91]],"ltp":1.3,"tv":17154.99,"id":8326656}]}]}
{"op":"mcm","clk":"1003209519","pt":1580604494903,"mc":[{"id":"1.168179120","rc":[{"batb":[[2,1.23,876.28]],"ltp":1.3,"tv":17154.99,"id":8326656}]}]}
{"op":"mcm","clk":"1003209600","pt":1580604496703,"mc":[{"id":"1.168179120","rc":[{"trd":[[1.29,2000]],"batb":[[0,1.29,3655.49]],"ltp":1.29,"tv":19154.99,"id":8326656}],"tv":21941.88}]}
{"op":"mcm","clk":"1003209656","pt":1580604497787,"mc":[{"id":"1.168179120","rc":[{"batb":[[1,3.5,2.23],[2,3.4,141.16]],"ltp":4.5,"tv":2786.88,"id":9712909}]}]}
{"op":"mcm","clk":"1003209676","pt":1580604498197,"mc":[{"id":"1.168179120","rc":[{"batb":[[1,3.4,141.26],[2,3.3,28.52]],"ltp":4.5,"tv":2786.88,"id":9712909}]}]}
{"op":"mcm","clk":"1003209746","pt":1580604499587,"mc":[{"id":"1.168179120","rc":[{"batb":[[0,1.29,4062.78]],"batl":[[1,1.31,514.67],[2,1.32,4393.5]],"ltp":1.29,"tv":19154.99,"id":8326656}]}]}
{"op":"mcm","clk":"1003209916","pt":1580604502474,"mc":[{"id":"1.168179120","rc":[{"trd":[[1.3,357.89]],"batl":[[0,1.3,52.82]],"ltp":1.3,"tv":19231.87,"id":8326656}],"tv":22018.75}]}
{"op":"mcm","clk":"1003210049","pt":1580604504692,"mc":[{"id":"1.168179120","rc":[{"batb":[[0,1.28,698.14],[1,1.23,943.91],[2,1.18,168.05]],"batl":[[1,1.4,41.5],[2,1.41,39.5]],"ltp":1.3,"tv":19231.87,"id":8326656},{"batb":[[1,3.5,2.75],[2,3.4,141.16]],"batl":[[0,1000,0.02],[1,5.4,0],[2,1000,0]],"ltp":4.5,"tv":2786.88,"id":9712909}]}]}
{"op":"mcm","clk":"1003210088","pt":1580604505569,"mc":[{"id":"1.168179120","rc":[{"batb":[[0,1.23,943.91],[1,1.18,168.05],[2,1.17,774.88]],"ltp":1.3,"tv":19231.87,"id":8326656},{"batb":[[0,3.5,2.75],[1,3.4,141.16],[2,3.3,28.52]],"ltp":4.5,"tv":2786.88,"id":9712909}]}]}
{"op":"mcm","clk":"1003210110","pt":1580604506082,"mc":[{"id":"1.168179120","rc":[{"trd":[[1.3,448.42]],"batl":[[0,1.3,7.56]],"ltp":1.3,"tv":19322.39,"id":8326656}],"tv":22109.28}]}
{"op":"mcm","clk":"1003210193","pt":1580604507676,"mc":[{"id":"1.168179120","rc":[{"batb":[[0,1.23,2758.27],[1,1.22,1571.55],[2,1.18,168.05]],"ltp":1.3,"tv":19322.39,"id":8326656},{"batl":[[0,5.4,2],[1,1000,0.02]],"ltp":4.5,"tv":2786.88,"id":9712909}]}]}
{"op":"mcm","clk":"1003210292","pt":1580604509377,"mc":[{"id":"1.168179120","rc":[{"batl":[[0,1.29,17.12]],"ltp":1.3,"tv":19322.39,"id":8326656}]}]}
{"op":"mcm","clk":"1003210326","pt":1580604510097,"mc":[{"id":"1.168179120","rc":[{"trd":[[1.29,2006.03]],"batl":[[0,1.29,11.09]],"ltp":1.29,"tv":19328.43,"id":8326656},{"trd":[[4.4,1.77]],"ltp":4.4,"tv":2788.65,"id":9712909}],"tv":22117.08}]}
{"op":"mcm","clk":"1003210452","pt":1580604512306,"mc":[{"id":"1.168179120","rc":[{"trd":[[1.29,2028.21]],"batb":[[0,1.3,93.15],[1,1.23,2758.27],[2,1.22,1571.55]],"batl":[[0,1.44,1088.86],[1,1.45,672.38],[2,1.54,5.07]],"ltp":1.29,"tv":19350.6,"id":8326656},{"batb":[[0,3.4,141.26],[1,3.3,28.52],[2,3.25,2.25]],"ltp":4.4,"tv":2788.65,"id":9712909}],"tv":22139.25}]}
{"op":"mcm","clk":"1003210676","pt":1580604516110,"mc":[{"id":"1.168179120","rc":[{"batl":[[0,4.3,20],[1,5.4,2],[2,1000,0.02]],"ltp":4.4,"tv":2788.65,"id":9712909}]}]}
{"op":"mcm","clk":"1003211448","pt":1580604528724,"mc":[{"id":"1.168179120","rc":[{"batl":[[0,1.4,44.8],[1,1.44,1088.85],[2,1.45,672.38]],"ltp":1.29,"tv":19350.6,"id":8326656},{"batb":[[0,3.5,2.23],[1,3.4,141.16],[2,3.3,28.52]],"ltp":4.4,"tv":2788.65,"id":9712909}]}]}
{"op":"mcm","clk":"1003211503","pt":1580604529599,"mc":[{"id":"1.168179120","rc":[{"trd":[[1.32,38.26],[1.4,0.27],[1.42,0.03]],"batl":[[0,1.44,1088.85],[1,1.45,672.38],[2,1.54,5.07]],"ltp":1.42,"tv":19350.92,"id":8326656},{"trd":[[3.4,0.01],[3.5,0.11]],"batb":[[0,3.4,141.14],[1,3.3,28.52],[2,3.25,2.25]],"ltp":3.4,"tv":2788.77,"id":9712909}],"tv":22139.69}]}
{"op":"mcm","clk":"1003211572","pt":1580604530832,"mc":[{"id":"1.168179120","rc":[{"batl":[[0,1.42,5.21],[1,1.44,1088.85],[2,1.45,672.38]],"ltp":1.42,"tv":19350.92,"id":8326656}]}]}
{"op":"mcm","clk":"1003211682","pt":1580604532735,"mc":[{"id":"1.168179120","rc":[{"batb":[[1,1.23,943.91],[2,1.18,168.05]],"batl":[[2,1.45,633.48]],"ltp":1.42,"tv":19350.92,"id":8326656}]}]}
{"op":"mcm","clk":"1003211868","pt":1580604535611,"mc":[{"id":"1.168179120","rc":[{"batb":[[0,1.4,3973.96],[1,1.39,781.44],[2,1.3,93.15]],"batl":[[1,1.44,4213.85],[2,1.45,1542.62]],"ltp":1.42,"tv":19350.92,"id":8326656},{"batb":[[0,3.4,146.93]],"batl":[[0,3.55,8.9],[1,3.7,415.09],[2,4.3,20]],"ltp":3.4,"tv":2788.77,"id":9712909}]}]}
{"op":"mcm","clk":"1003211933","pt":1580604536642,"mc":[{"id":"1.168179120","rc":[{"batb":[[2,1.38,472.96]],"ltp":1.42,"tv":19350.92,"id":8326656}]}]}
{"op":"mcm","clk":"1003212464","pt":1580604544517,"mc":[{"id":"1.168179120","rc":[{"batl":[[0,1.42,4.96]],"ltp":1.42,"tv":19350.92,"id":8326656}]}]}
{"op":"mcm","clk":"1003212560","pt":1580604545855,"mc":[{"id":"1.168179120","rc":[{"trd":[[1.42,26.39]],"batl":[[0,1.44,4213.85],[1,1.45,1542.62],[2,1.54,5.07]],"ltp":1.42,"tv":19377.28,"id":8326656},{"trd":[[3.4,39.13]],"batb":[[0,3.4,123.94]],"ltp":3.4,"tv":2827.88,"id":9712909}],"tv":22205.17}]}
{"op":"mcm","clk":"1003212646","pt":1580604546938,"mc":[{"id":"1.168179120","rc":[{"trd":[[1.4,0.89]],"batb":[[0,1.4,3973.65]],"ltp":1.4,"tv":19377.9,"id":8326656}],"tv":22205.79}]}
{"op":"mcm","clk":"1003212785","pt":1580604548840,"mc":[{"id":"1.168179120","rc":[{"trd":[[1.4,12.42]],"batb":[[0,1.4,3967.89]],"ltp":1.4,"tv":19389.42,"id":8326656},{"batl":[[0,3.45,21],[1,3.55,8.9],[2,3.7,415.09]],"ltp":3.4,"tv":2827.88,"id":9712909}],"tv":22217.31}]}
{"op":"mcm","clk":"1003212835","pt":1580604549557,"mc":[{"id":"1.168179120","rc":[{"trd":[[1.4,212.42]],"batb":[[0,1.4,3867.89]],"ltp":1.4,"tv":19589.42,"id":8326656}],"tv":22417.31}]}
{"op":"mcm","clk":"1003212887","pt":1580604550433,"mc":[{"id":"1.168179120","rc":[{"trd":[[1.4,243.89]],"batb":[[0,1.4,3852.15]],"ltp":1.4,"tv":19620.9,"id":8326656}],"tv":22448.79}]}
{"op":"mcm","clk":"1003212962","pt":1580604551721,"mc":[{"id":"1.168179120","rc":[{"trd":[[1.4,399.33]],"batb":[[0,1.4,3774.43]],"ltp":1.4,"tv":19776.34,"id":8326656}],"tv":22604.23}]}
{"op":"mcm","clk":"1003213062","pt":1580604553567,"mc":[{"id":"1.168179120","rc":[{"trd":[[1.4,402.36]],"batb":[[0,1.4,3772.92]],"ltp":1.4,"tv":19779.37,"id":8326656}],"tv":22607.25}]}
{"op":"mcm","clk":"1003213156","pt":1580604554753,"mc":[{"id":"1.168179120","rc":[{"trd":[[1.4,3987.36]],"batb":[[0,1.4,1980.42]],"ltp":1.4,"tv":23364.37,"id":8326656},{"trd":[[3.4,45.18]],"batb":[[0,3.4,120.91]],"ltp":3.4,"tv":2833.94,"id":9712909}],"tv":26198.31}]}
{"op":"mcm","clk":"1003213193","pt":1580604555267,"mc":[{"id":"1.168179120","rc":[{"trd":[[1.4,3991.36],[1.42,29.35]],"batb":[[0,1.4,1978.42]],"ltp":1.4,"tv":23371.33,"id":8326656},{"trd":[[3.4,46.42]],"batb":[[0,3.4,119.68]],"ltp":3.4,"tv":2835.18,"id":9712909}],"tv":26206.51}]}
{"op":"mcm","clk":"1003213271","pt":1580604556454,"mc":[{"id":"1.168179120","rc":[{"trd":[[3.45,2.68]],"batl":[[0,3.55,8.9],[1,3.7,415.09],[2,4.3,20]],"ltp":3.45,"tv":2837.86,"id":9712909}],"tv":26209.19}]}
{"op":"mcm","clk":"1003213466","pt":1580604559543,"mc":[{"id":"1.168179120","rc":[{"trd":[[1.4,3992.24]],"batb":[[0,1.4,1977.98]],"ltp":1.4,"tv":23372.2,"id":8326656},{"trd":[[3.4,85.74]],"batb":[[0,3.4,100.02]],"ltp":3.4,"tv":2877.18,"id":9712909}],"tv":26249.39}]}
{"op":"mcm","clk":"1003213760","pt":1580604564950,"mc":[{"id":"1.168179120","rc":[{"trd":[[1.4,3993.04]],"batb":[[0,1.4,1977.58]],"ltp":1.4,"tv":23373.01,"id":8326656}],"tv":26250.2}]}
{"op":"mcm","clk":"1003213990","pt":1580604568759,"mc":[{"id":"1.168179120","rc":[{"trd":[[1.42,29.79]],"ltp":1.42,"tv":23373.45,"id":8326656},{"trd":[[3.4,85.93]],"batb":[[0,3.4,99.83]],"ltp":3.4,"tv":2877.37,"id":9712909}],"tv":26250.82}]}
{"op":"mcm","clk":"1003214047","pt":1580604569548,"mc":[{"id":"1.168179120","rc":[{"trd":[[1.44,1414.27]],"batl":[[0,1.44,2799.58]],"ltp":1.44,"tv":24787.72,"id":8326656},{"trd":[[3.25,631.13],[3.3,57.03],[3.4,285.59]],"batb":[[0,3.15,169.8],[1,2.58,66.59],[2,1.03,9.21]],"ltp":3.25,"tv":3765.2,"id":9712909}],"tv":28552.92}]}
{"op":"mcm","clk":"1003214107","pt":1580604570371,"mc":[{"id":"1.168179120","rc":[{"trd":[[1.4,4146],[1.43,0.52]],"batb":[[0,1.4,1901.1],[1,1.38,472.96],[2,1.33,564.78]],"ltp":1.4,"tv":24941.2,"id":8326656},{"trd":[[3.3,57.26]],"ltp":3.3,"tv":3765.42,"id":9712909}],"tv":28706.62}]}
{"op":"mcm","clk":"1003214212","pt":1580604571762,"mc":[{"id":"1.168179120","rc":[{"trd":[[1.4,4149.29]],"batb":[[0,1.4,1897.81]],"ltp":1.4,"tv":24944.49,"id":8326656},{"trd":[[3.5,1.43]],"ltp":3.5,"tv":3766.74,"id":9712909}],"tv":28711.23}]}
{"op":"mcm","clk":"1003214286","pt":1580604572892,"mc":[{"id":"1.168179120","rc":[{"trd":[[1.4,4302.98]],"batb":[[0,1.4,1061.28]],"batl":[[1,1.45,909.14]],"ltp":1.4,"tv":25098.18,"id":8326656}],"tv":28864.92}]}
{"op":"mcm","clk":"1003214314","pt":1580604573256,"mc":[{"id":"1.168179120","rc":[{"batl":[[0,1.44,2968.66]],"ltp":1.4,"tv":25098.18,"id":8326656}]}]}
{"op":"mcm","clk":"1003214601","pt":1580604577377,"mc":[{"id":"1.168179120","rc":[{"trd":[[1.4,4307.02]],"batb":[[0,1.4,1059.24],[2,1.35,1301.65]],"batl":[[2,1.49,838.72]],"ltp":1.4,"tv":25102.22,"id":8326656},{"trd":[[3.5,1.44]],"ltp":3.5,"tv":3766.75,"id":9712909}],"tv":28868.97}]}
{"op":"mcm","clk":"1003214766","pt":1580604579795,"mc":[{"id":"1.168179120","rc":[{"batl":[[0,3.7,415.09],[1,4.3,20],[2,5.4,2]],"ltp":3.5,"tv":3766.75,"id":9712909}]}]}
{"op":"mcm","clk":"1003214971","pt":1580604582662,"mc":[{"id":"1.168179120","rc":[{"batb":[[0,1.4,1071.52]],"ltp":1.4,"tv":25102.22,"id":8326656},{"batb":[[0,3.35,5.23],[1,3.15,169.8],[2,2.58,66.59]],"batl":[[0,3.5,4.91],[1,3.7,415.09],[2,4.3,20]],"ltp":3.5,"tv":3766.75,"id":9712909}]}]}
{"op":"mcm","clk":"1003214992","pt":1580604582971,"mc":[{"id":"1.168179120","rc":[{"batb":[[0,1.42,28.42],[1,1.4,1071.52],[2,1.38,472.96]],"ltp":1.4,"tv":25102.22,"id":8326656}]}]}
{"op":"mcm","clk":"1003215098","pt":1580604584670,"mc":[{"id":"1.168179120","rc":[{"batl":[[0,1.44,2799.58]],"ltp":1.4,"tv":25102.22,"id":8326656}]}]}
{"op":"mcm","clk":"1003215286","pt":1580604586784,"mc":[{"id":"1.168179120","rc":[{"batb":[[1,1.35,1301.65],[2,1.34,931.05]],"batl":[[0,1.49,838.72],[1,1.5,549.05],[2,1.54,5.07]],"ltp":1.4,"tv":25102.22,"id":8326656},{"trd":[[3.35,3.36]],"batb":[[0,3.15,169.8],[1,2.58,66.59],[2,1.03,9.21]],"batl":[[0,4.3,20],[1,5.4,2],[2,1000,0.02]],"ltp":3.35,"tv":3770.11,"id":9712909}],"tv":28872.33}]}
{"op":"mcm","clk":"1003215524","pt":1580604589875,"mc":[{"id":"1.168179120","rc":[{"batb":[[2,1.34,1521.62]],"batl":[[0,1.48,33.99],[1,1.49,838.72],[2,1.5,549.05]],"ltp":1.4,"tv":25102.22,"id":8326656},{"batb":[[0,3.1,178.45],[1,3.05,2.89],[2,2.58,66.59]],"batl":[[0,3.95,3.1],[1,4.3,22.75]],"ltp":3.35,"tv":3770.11,"id":9712909}]}]}
{"op":"mcm","clk":"1003215553","pt":1580604590286,"mc":[{"id":"1.168179120","rc":[{"batl":[[0,1.45,39.5],[1,1.47,34.5],[2,1.48,33.99]],"ltp":1.4,"tv":25102.22,"id":8326656},{"batb":[[0,3.2,2.22],[1,3.1,180.99],[2,3.05,2.89]],"ltp":3.35,"tv":3770.11,"id":9712909}]}]}
{"op":"mcm","clk":"1003215790","pt":1580604593603,"mc":[{"id":"1.168179120","rc":[{"batb":[[0,1.35,1301.65],[1,1.34,1521.62],[2,1.31,64.79]],"ltp":1.4,"tv":25102.22,"id":8326656}]}]}
{"op":"mcm","clk":"1003215813","pt":1580604593912,"mc":[{"id":"1.168179120","rc":[{"batb":[[0,1.43,78.18],[1,1.35,1301.65],[2,1.34,1521.62]],"ltp":1.4,"tv":25102.22,"id":8326656}]}]}
{"op":"mcm","clk":"1003215949","pt":1580604596290,"mc":[{"id":"1.168179120","rc":[{"batl":[[2,4.8,2.32]],"ltp":3.35,"tv":3770.11,"id":9712909}]}]}
{"op":"mcm","clk":"1003216150","pt":1580604599382,"mc":[{"id":"1.168179120","rc":[{"trd":[[1.45,0.42]],"batb":[[2,1.34,1474.9]],"batl":[[0,1.49,838.72],[1,1.5,583.6],[2,1.52,34.26]],"ltp":1.45,"tv":25102.64,"id":8326656},{"batb":[[0,3.1,178.45],[1,3,2.97],[2,2.92,2.94]],"batl":[[0,4.3,20],[1,4.8,2.32],[2,5.8,2.02]],"ltp":3.35,"tv":3770.11,"id":9712909}],"tv":28872.75}]}
{"op":"mcm","clk":"1003216256","pt":1580604600924,"mc":[{"id":"1.168179120","rc":[{"batb":[[0,1.35,1301.65],[1,1.34,1474.9],[2,1.27,71.87]],"ltp":1.45,"tv":25102.64,"id":8326656}]}]}
{"op":"mcm","clk":"1003216517","pt":1580604604593,"mc":[{"id":"1.168179120","rc":[{"batl":[[0,1.43,1.11],[1,1.49,838.72],[2,1.5,583.6]],"ltp":1.45,"tv":25102.64,"id":8326656}]}]}
{"op":"mcm","clk":"1003216743","pt":1580604607918,"mc":[{"id":"1.168179120","rc":[{"batl":[[1,1.5,34.55],[2,1.52,34.26]],"ltp":1.45,"tv":25102.64,"id":8326656}]}]}
{"op":"mcm","clk":"1003216986","pt":1580604610809,"mc":[{"id":"1.168179120","rc":[{"batl":[[0,1.37,18.92],[1,1.38,912.71],[2,1.39,1046.74]],"ltp":1.45,"tv":25102.64,"id":8326656},{"batb":[[0,3.45,68.44],[1,3.1,178.45],[2,3,2.97]],"batl":[[0,3.85,4.72],[1,4.1,320.05],[2,4.3,20]],"ltp":3.35,"tv":3770.11,"id":9712909}]}]}
{"op":"mcm","clk":"1003217060","pt":1580604611836,"mc":[{"id":"1.168179120","rc":[{"batb":[[2,1.28,678.71]],"ltp":1.45,"tv":25102.64,"id":8326656},{"batb":[[0,3.7,116.76],[1,3.45,68.44],[2,3.4,144.22]],"ltp":3.35,"tv":3770.11,"id":9712909}]}]}
{"op":"mcm","clk":"1003217396","pt":1580604616534,"mc":[{"id":"1.168179120","rc":[{"trd":[[1.37,2.24]],"batl":[[0,1.37,17.8]],"ltp":1.37,"tv":25104.87,"id":8326656}],"tv":28874.99}]}
{"op":"mcm","clk":"1003217484","pt":1580604617818,"mc":[{"id":"1.168179120","rc":[{"trd":[[3.7,2.63]],"batb":[[0,3.7,115.45]],"ltp":3.7,"tv":3772.75,"id":9712909}],"tv":28877.62}]}
{"op":"mcm","clk":"1003217598","pt":1580604619721,"mc":[{"id":"1.168179120","rc":[{"batb":[[2,1.28,737.62]],"ltp":1.37,"tv":25104.87,"id":8326656}]}]}
{"op":"mcm","clk":"1003217668","pt":1580604620752,"mc":[{"id":"1.168179120","rc":[{"trd":[[1.35,75.72]],"batb":[[0,1.35,1263.79],[2,1.28,678.71]],"ltp":1.35,"tv":25180.59,"id":8326656}],"tv":28953.34}]}
{"op":"mcm","clk":"1003217682","pt":1580604620909,"mc":[{"id":"1.168179120","rc":[{"trd":[[1.37,37.84]],"batb":[[0,1.37,3.6],[1,1.35,1263.79],[2,1.34,1474.9]],"batl":[[0,1.38,912.71],[1,1.39,1046.74],[2,1.4,911.25]],"ltp":1.37,"tv":25216.19,"id":8326656}],"tv":28988.95}]}
{"op":"mcm","clk":"1003217923","pt":1580604624523,"mc":[{"id":"1.168179120","rc":[{"trd":[[1.37,38.24]],"batb":[[0,1.37,3.4]],"ltp":1.37,"tv":25216.6,"id":8326656}],"tv":28989.35}]}
{"op":"mcm","clk":"1003217978","pt":1580604625240,"mc":[{"id":"1.168179120","rc":[{"trd":[[1.35,89.77],[1.37,45.04]],"batb":[[0,1.35,1256.77],[1,1.34,1474.9],[2,1.28,678.71]],"ltp":1.35,"tv":25237.44,"id":8326656}],"tv":29010.19}]}
{"op":"mcm","clk":"1003218072","pt":1580604626731,"mc":[{"id":"1.168179120","rc":[{"batb":[[0,1.28,678.55],[1,1.27,71.87],[2,1.21,89.69]],"batl":[[0,1.39,88],[1,1.43,1.11],[2,1.48,40.24]],"ltp":1.35,"tv":25237.44,"id":8326656},{"batb":[[0,3.4,144.22],[1,3.05,2.89],[2,3,2.97]],"batl":[[0,4.3,20],[1,4.6,136.05],[2,4.8,2.32]],"ltp":3.7,"tv":3772.75,"id":9712909}]}]}
{"op":"mcm","clk":"1003218160","pt":1580604628119,"mc":[{"id":"1.168179120","rc":[{"batl":[[0,1.37,88],[1,1.39,88],[2,1.43,1.11]],"ltp":1.35,"tv":25237.44,"id":8326656}]}]}
{"op":"mcm","clk":"1003218241","pt":1580604629656,"mc":[{"id":"1.168179120","rc":[{"batb":[[0,1.3,829.1],[1,1.29,1127.9],[2,1.28,737.71]],"batl":[[2,1.43,475.47]],"ltp":1.35,"tv":25237.44,"id":8326656},{"batb":[[1,3.2,2.57],[2,3.05,2.89]],"batl":[[1,4.6,138.66]],"ltp":3.7,"tv":3772.75,"id":9712909}]}]}
{"op":"mcm","clk":"1003218256","pt":1580604629915,"mc":[{"id":"1.168179120","rc":[{"batb":[[1,1.29,1188.71]],"ltp":1.35,"tv":25237.44,"id":8326656},{"batl":[[1,4.5,2.65],[2,4.6,138.66]],"ltp":3.7,"tv":3772.75,"id":9712909}]}]}
{"op":"mcm","clk":"1003218703","pt":1580604636446,"mc":[{"id":"1.168179120","rc":[{"batb":[[0,1.29,60.81],[1,1.28,737.71],[2,1.27,71.87]],"batl":[[0,1.43,475.47],[1,1.44,652.18],[2,1.48,40.24]],"ltp":1.35,"tv":25237.44,"id":8326656},{"batb":[[1,3.05,2.89],[2,3,2.97]],"ltp":3.7,"tv":3772.75,"id":9712909}]}]}
{"op":"mcm","clk":"1003218808","pt":1580604638039,"mc":[{"id":"1.168179120","rc":[{"batl":[[2,4.6,2.61]],"ltp":3.7,"tv":3772.75,"id":9712909}]}]}
{"op":"mcm","clk":"1003218877","pt":1580604639229,"mc":[{"id":"1.168179120","rc":[{"batb":[[0,1.41,17.51],[1,1.4,659.04],[2,1.39,4039.71]],"batl":[[0,1.43,4408.75]],"ltp":1.35,"tv":25237.44,"id":8326656},{"batl":[[0,3.6,3.56],[1,3.7,335.03],[2,4.3,20]],"ltp":3.7,"tv":3772.75,"id":9712909}]}]}
{"op":"mcm","clk":"1003218972","pt":1580604640765,"mc":[{"id":"1.168179120","rc":[{"batb":[[2,1.39,4504.96]],"ltp":1.35,"tv":25237.44,"id":8326656},{"batb":[[1,3.1,175.85],[2,3.05,2.89]],"ltp":3.7,"tv":3772.75,"id":9712909}]}]}
{"op":"mcm","clk":"1003219035","pt":1580604641745,"mc":[{"id":"1.168179120","rc":[{"batl":[[2,4.2,148.03]],"ltp":3.7,"tv":3772.75,"id":9712909}]}]}
{"op":"mcm","clk":"1003219459","pt":1580604648673,"mc":[{"id":"1.168179120","rc":[{"trd":[[1.41,35.01]],"batb":[[0,1.4,659.04],[1,1.39,4504.96],[2,1.38,88]],"batl":[[0,1.41,7.75],[1,1.43,4408.75],[2,1.44,652.18]],"ltp":1.41,"tv":25272.45,"id":8326656},{"batl":[[2,3.9,3.15]],"ltp":3.7,"tv":3772.75,"id":9712909}],"tv":29045.2}]}
{"op":"mcm","clk":"1003219501","pt":1580604649448,"mc":[{"id":"1.168179120","rc":[{"batl":[[0,1.41,8.86]],"ltp":1.41,"tv":25272.45,"id":8326656}]}]}
{"op":"mcm","clk":"1003219614","pt":1580604650841,"mc":[{"id":"1.168179120","rc":[{"trd":[[1.41,52.73]],"batb":[[0,1.41,116.14],[1,1.4,659.04],[2,1.39,4504.96]],"batl":[[0,1.43,4408.75],[1,1.44,652.18],[2,1.48,40.24]],"ltp":1.41,"tv":25290.17,"id":8326656}],"tv":29062.92}]}
{"op":"mcm","clk":"1003219704","pt":1580604651869,"mc":[{"id":"1.168179120","rc":[{"trd":[[1.42,32.81]],"batl":[[0,1.42,123.49],[1,1.43,4408.75],[2,1.44,652.18]],"ltp":1.42,"tv":25293.19,"id":8326656}],"tv":29065.94}]}
{"op":"mcm","clk":"1003219796","pt":1580604653566,"mc":[{"id":"1.168179120","rc":[{"trd":[[1.4,5074.74],[1.41,285.01]],"batb":[[0,1.4,275.18],[1,1.39,4504.96],[2,1.38,88]],"ltp":1.4,"tv":26293.19,"id":8326656}],"tv":30065.94}]}
{"op":"mcm","clk":"1003219834","pt":1580604654147,"mc":[{"id":"1.168179120","rc":[{"batb":[[0,1.39,4504.96],[1,1.38,88],[2,1.35,46.87]],"ltp":1.4,"tv":26293.19,"id":8326656}]}]}
{"op":"mcm","clk":"1003219920","pt":1580604655294,"mc":[{"id":"1.168179120","rc":[{"batb":[[0,1.38,88],[1,1.34,51.72],[2,1.33,571.23]],"batl":[[1,1.43,1.11],[2,1.48,40.24]],"ltp":1.4,"tv":26293.19,"id":8326656},{"batb":[[0,3.1,175.85],[1,3.05,2.89],[2,3,2.97]],"batl":[[0,3.95,3.1],[1,4.2,150.86],[2,4.3,20]],"ltp":3.7,"tv":3772.75,"id":9712909}]}]}
{"op":"mcm","clk":"1003220090","pt":1580604658357,"mc":[{"id":"1.168179120","rc":[{"batb":[[1,1.35,45.67],[2,1.34,51.72]],"batl":[[1,1.48,729.83],[2,1.49,566.92]],"ltp":1.4,"tv":26293.19,"id":8326656},{"batl":[[0,3.9,3.15],[1,3.95,3.1],[2,4.1,2.95]],"ltp":3.7,"tv":3772.75,"id":9712909}]}]}
{"op":"mcm","clk":"1003220219","pt":1580604660768,"mc":[{"id":"1.168179120","rc":[{"batb":[[0,1.35,45.67],[1,1.34,51.72],[2,1.33,2024.73]],"batl":[[0,1.42,123.69],[1,1.48,40.24],[2,1.5,34.55]],"ltp":1.4,"tv":26293.19,"id":8326656}]}]}
{"op":"mcm","clk":"1003220276","pt":1580604661596,"mc":[{"id":"1.168179120","rc":[{"batb":[[0,1.33,2024.73],[1,1.32,1063.87],[2,1.18,168.05]],"batl":[[0,1.4,162],[1,1.42,123.69],[2,1.48,40.24]],"ltp":1.4,"tv":26293.19,"id":8326656},{"batl":[[0,4.1,2.95],[1,4.2,150.86],[2,4.3,20]],"ltp":3.7,"tv":3772.75,"id":9712909}]}]}
{"op":"mcm","clk":"1003220319","pt":1580604662164,"mc":[{"id":"1.168179120","rc":[{"trd":[[1.4,5075.54]],"batl":[[0,1.4,161.6]],"ltp":1.4,"tv":26293.99,"id":8326656},{"batl":[[1,4.2,2.83]],"ltp":3.7,"tv":3772.75,"id":9712909}],"tv":30066.74}]}
{"op":"mcm","clk":"1003220435","pt":1580604663864,"mc":[{"id":"1.168179120","rc":[{"batb":[[0,1.33,5408.19],[2,1.31,873.41]],"batl":[[0,1.35,11.48],[1,1.36,3396.82],[2,1.37,1101.24]],"ltp":1.4,"tv":26293.99,"id":8326656},{"batb":[[0,3.35,1485.54],[1,3.1,175.85],[2,3.05,2.89]],"batl":[[0,4,6.3],[1,4.1,2.95],[2,4.2,2.83]],"ltp":3.7,"tv":3772.75,"id":9712909}]}]}
{"op":"mcm","clk":"1003220500","pt":1580604664791,"mc":[{"id":"1.168179120","rc":[{"batb":[[0,3.8,109.13],[1,3.45,138.87],[2,3.35,1485.54]],"ltp":3.7,"tv":3772.75,"id":9712909}]}]}
{"op":"mcm","clk":"1003220909","pt":1580604671480,"mc":[{"id":"1.168179120","rc":[{"batb":[[0,1.34,125],[1,1.33,5408.19],[2,1.32,1063.87]],"ltp":1.4,"tv":26293.99,"id":8326656}]}]}
{"op":"mcm","clk":"1003220974","pt":1580604672768,"mc":[{"id":"1.168179120","rc":[{"batl":[[0,1.35,136.48]],"ltp":1.4,"tv":26293.99,"id":8326656}]}]}
{"op":"mcm","clk":"1003220984","pt":1580604672973,"mc":[{"id":"1.168179120","rc":[{"batl":[[0,1.35,261.48]],"ltp":1.4,"tv":26293.99,"id":8326656}]}]}
{"op":"mcm","clk":"1003221146","pt":1580604675797,"mc":[{"id":"1.168179120","rc":[{"trd":[[1.35,90.39]],"batl":[[0,1.35,261.17]],"ltp":1.35,"tv":26294.61,"id":8326656}],"tv":30067.36}]}
{"op":"mcm","clk":"1003221440","pt":1580604679403,"mc":[{"id":"1.168179120","rc":[{"trd":[[1.34,21.94],[1.35,91.5]],"batb":[[0,1.34,121.97]],"batl":[[0,1.35,260.61]],"ltp":1.35,"tv":26301.78,"id":8326656}],"tv":30074.54}]}
{"op":"mcm","clk":"1003221500","pt":1580604680281,"mc":[{"id":"1.168179120","rc":[{"batb":[[0,1.33,5408.19],[1,1.32,1063.87],[2,1.31,873.41]],"ltp":1.35,"tv":26301.78,"id":8326656}]}]}
{"op":"mcm","clk":"1003221563","pt":1580604681717,"mc":[{"id":"1.168179120","rc":[{"trd":[[1.33,223.5],[1.35,95.02]],"batb":[[0,1.33,5403.12]],"batl":[[0,1.35,258.85]],"ltp":1.35,"tv":26315.43,"id":8326656}],"tv":30088.19}]}
{"op":"mcm","clk":"1003221635","pt":1580604682803,"mc":[{"id":"1.168179120","rc":[{"batb":[[0,1.27,805.93],[1,1.24,68.02],[2,1.18,168.05]],"batl":[[0,1.35,250],[1,1.36,88],[2,1.4,161.6]],"ltp":1.35,"tv":26315.43,"id":8326656},{"batb":[[0,3.45,138.87],[1,3.3,2.68],[2,3.15,3.03]],"batl":[[0,4.3,20],[1,4.8,2.52],[2,5.2,2.28]],"ltp":3.7,"tv":3772.75,"id":9712909}]}]}
{"op":"mcm","clk":"1003221848","pt":1580604686117,"mc":[{"id":"1.168179120","rc":[{"trd":[[1.35,178.32]],"batl":[[0,1.35,208.35]],"ltp":1.35,"tv":26398.73,"id":8326656}],"tv":30171.48}]}
{"op":"mcm","clk":"1003222090","pt":1580604688701,"mc":[{"id":"1.168179120","rc":[{"trd":[[1.35,234.47]],"batb":[[0,1.32,1127.13],[1,1.31,1046.7],[2,1.27,805.93]],"batl":[[0,1.35,804.68],[1,1.36,930.85]],"ltp":1.35,"tv":26454.88,"id":8326656},{"trd":[[3.85,19.69]],"batb":[[0,3.9,10.86],[1,3.45,138.87],[2,3.3,2.68]],"batl":[[0,4.1,10.35],[1,4.3,20],[2,4.8,2.52]],"ltp":3.85,"tv":3792.43,"id":9712909}],"tv":30247.32}]}
{"op":"mcm","clk":"1003222106","pt":1580604688911,"mc":[{"id":"1.168179120","rc":[{"batb":[[0,1.32,1116.99]],"batl":[[0,1.35,794.78]],"ltp":1.35,"tv":26454.88,"id":8326656},{"batb":[[0,3.45,138.87],[1,3.3,2.68],[2,3.15,3.03]],"batl":[[0,4.3,20],[1,4.8,2.52],[2,5.2,2.28]],"ltp":3.85,"tv":3792.43,"id":9712909}]}]}
{"op":"mcm","clk":"1003222338","pt":1580604691601,"mc":[{"id":"1.168179120","rc":[{"trd":[[1.35,277.27]],"batl":[[0,1.35,773.38]],"ltp":1.35,"tv":26497.68,"id":8326656}],"tv":30290.12}]}
{"op":"mcm","clk":"1003222405","pt":1580604692425,"mc":[{"id":"1.168179120","rc":[{"trd":[[1.3,465.97],[1.35,279.46]],"batb":[[0,1.27,805.93],[1,1.24,68.02],[2,1.18,168.05]],"batl":[[0,1.35,129.7],[1,1.36,88]],"ltp":1.3,"tv":26517.43,"id":8326656},{"trd":[[4.3,5.31]],"batl":[[0,4.3,14.69]],"ltp":4.3,"tv":3797.74,"id":9712909}],"tv":30315.18}]}
{"op":"mcm","clk":"1003222667","pt":1580604695527,"mc":[{"id":"1.168179120","rc":[{"batb":[[0,1.27,2030.37],[1,1.26,1302.31],[2,1.24,68.02]],"ltp":1.3,"tv":26517.43,"id":8326656}]}]}
{"op":"mcm","clk":"1003222825","pt":1580604697537,"mc":[{"id":"1.168179120","rc":[{"batl":[[0,1.32,500],[1,1.35,129.7],[2,1.36,88]],"ltp":1.3,"tv":26517.43,"id":8326656}]}]}
{"op":"mcm","clk":"1003222937","pt":1580604699341,"mc":[{"id":"1.168179120","rc":[{"trd":[[1.3,503.83]],"ltp":1.3,"tv":26555.29,"id":8326656},{"trd":[[4.3,16.76]],"batl":[[0,4.3,3.24]],"ltp":4.3,"tv":3809.19,"id":9712909}],"tv":30364.49}]}
{"op":"mcm","clk":"1003223047","pt":1580604700844,"mc":[{"id":"1.168179120","rc":[{"trd":[[1.3,514.55]],"batb":[[0,1.27,5573.68]],"batl":[[0,1.28,88],[1,1.3,5759.45],[2,1.31,1006.38]],"ltp":1.3,"tv":26566.01,"id":8326656},{"trd":[[4.3,20],[4.7,5.29]],"batb":[[0,4.5,4.01],[1,3.45,138.87],[2,3.3,2.68]],"batl":[[0,4.7,3.35],[2,5.1,355.18]],"ltp":4.7,"tv":3817.73,"id":9712909}],"tv":30383.75}]}
{"op":"mcm","clk":"1003223070","pt":1580604701204,"mc":[{"id":"1.168179120","rc":[{"batb":[[1,4.4,155.24],[2,3.95,195.68]],"ltp":4.7,"tv":3817.73,"id":9712909}]}]}
{"op":"mcm","clk":"1003223519","pt":1580604707829,"mc":[{"id":"1.168179120","rc":[{"trd":[[1.27,1003.39],[1.28,335.6]],"batb":[[0,1.27,5073.65]],"batl":[[0,1.28,86.89]],"ltp":1.28,"tv":27568.27,"id":8326656}],"tv":31386.0}]}
{"op":"mcm","clk":"1003223606","pt":1580604709322,"mc":[{"id":"1.168179120","rc":[{"batl":[[0,1.28,196.89]],"ltp":1.28,"tv":27568.27,"id":8326656}]}]}
{"op":"mcm","clk":"1003223680","pt":1580604710557,"mc":[{"id":"1.168179120","rc":[{"trd":[[1.27,1009.45]],"batb":[[0,1.27,5070.62]],"ltp":1.27,"tv":27574.32,"id":8326656}],"tv":31392.06}]}
{"op":"mcm","clk":"1003223730","pt":1580604711329,"mc":[{"id":"1.168179120","rc":[{"trd":[[1.27,1026.95]],"batb":[[0,1.27,5061.87]],"ltp":1.27,"tv":27591.82,"id":8326656},{"batb":[[0,4.4,155.24],[1,3.95,195.68],[2,3.75,2.11]],"batl":[[0,4.8,2.52],[1,5.1,355.18],[2,5.2,2.28]],"ltp":4.7,"tv":3817.73,"id":9712909}],"tv":31409.56}]}
{"op":"mcm","clk":"1003223825","pt":1580604712827,"mc":[{"id":"1.168179120","rc":[{"trd":[[1.27,1033.01],[1.28,423.03]],"batb":[[0,1.27,5058.84]],"batl":[[0,1.28,110.58]],"ltp":1.28,"tv":27685.31,"id":8326656},{"trd":[[4.5,97.78]],"ltp":4.5,"tv":3841.96,"id":9712909}],"tv":31527.27}]}
{"op":"mcm","clk":"1003223921","pt":1580604714223,"mc":[{"id":"1.168179120","rc":[{"trd":[[1.27,1039.07]],"batb":[[0,1.27,5068.87]],"ltp":1.27,"tv":27691.37,"id":8326656},{"batb":[[0,4.5,6.78],[1,4.4,155.24],[2,3.95,195.68]],"ltp":4.5,"tv":3841.96,"id":9712909}],"tv":31533.33}]}
{"op":"mcm","clk":"1003224016","pt":1580604715821,"mc":[{"id":"1.168179120","rc":[{"trd":[[1.27,1124.67]],"batb":[[0,1.27,5026.06]],"ltp":1.27,"tv":27776.97,"id":8326656}],"tv":31618.93}]}
{"op":"mcm","clk":"1003224177","pt":1580604718549,"mc":[{"id":"1.168179120","rc":[{"trd":[[1.27,5216.02]],"batb":[[0,1.27,2980.45]],"ltp":1.27,"tv":31868.31,"id":8326656}],"tv":35710.28}]}
{"op":"mcm","clk":"1003224264","pt":1580604719837,"mc":[{"id":"1.168179120","rc":[{"batl":[[2,1.35,129.7]],"ltp":1.27,"tv":31868.31,"id":8326656},{"trd":[[4.5,101.78]],"batb":[[0,4.5,4.78]],"ltp":4.5,"tv":3845.96,"id":9712909}],"tv":35714.28}]}
{"op":"mcm","clk":"1003224381","pt":1580604721545,"mc":[{"id":"1.168179120","rc":[{"batb":[[0,1.23,2.64],[1,1.21,935.53],[2,1.2,88.97]],"batl":[[0,1.27,3.03],[1,1.28,110.58]],"ltp":1.27,"tv":31868.31,"id":8326656},{"batb":[[0,3.95,195.68],[1,3.75,2.11],[2,3.55,2.59]],"batl":[[0,6,108.19],[1,1000,0.02],[2,5.2,0]],"ltp":4.5,"tv":3845.96,"id":9712909}]}]}
{"op":"mcm","clk":"1003224422","pt":1580604722266,"mc":[{"id":"1.168179120","rc":[{"trd":[[1.27,5228.13]],"batl":[[0,1.28,110.58],[1,1.35,129.7],[2,1.36,131.57]],"ltp":1.27,"tv":31880.43,"id":8326656}],"tv":35726.4}]}
{"op":"mcm","clk":"1003224578","pt":1580604724742,"mc":[{"id":"1.168179120","rc":[{"batb":[[1,1.22,739.92],[2,1.21,2624.21]],"batl":[[1,1.33,504.91],[2,1.34,918.34]],"ltp":1.27,"tv":31880.43,"id":8326656},{"batb":[[0,4.1,183.09]],"batl":[[0,5.6,2],[1,6,108.19],[2,1000,0.02]],"ltp":4.5,"tv":3845.96,"id":9712909}]}]}
{"op":"mcm","clk":"1003224787","pt":1580604727742,"mc":[{"id":"1.168179120","rc":[{"batb":[[0,1.22,739.92],[1,1.21,2624.21],[2,1.2,88.97]],"batl":[[1,1.35,129.7],[2,1.36,131.57]],"ltp":1.27,"tv":31880.43,"id":8326656}]}]}
{"op":"mcm","clk":"1003224858","pt":1580604728775,"mc":[{"id":"1.168179120","rc":[{"trd":[[1.28,423.83]],"batl":[[0,1.28,110.18]],"ltp":1.28,"tv":31881.23,"id":8326656},{"batl":[[1,6,2.01]],"ltp":4.5,"tv":3845.96,"id":9712909}],"tv":35727.2}]}
{"op":"mcm","clk":"1003224927","pt":1580604729860,"mc":[{"id":"1.168179120","rc":[{"trd":[[1.22,880.3]],"batb":[[0,1.22,4340.44],[2,1.2,865.12]],"batl":[[0,1.24,4826.93],[1,1.25,1320.62],[2,1.27,15.5]],"ltp":1.22,"tv":32057.23,"id":8326656},{"batb":[[0,5.1,257],[1,4.7,2],[2,4.1,183.09]],"batl":[[0,5.5,4.37],[1,5.6,2],[2,6,157.24]],"ltp":4.5,"tv":3845.96,"id":9712909}],"tv":35903.2}]}
{"op":"mcm","clk":"1003224979","pt":1580604730580,"mc":[{"id":"1.168179120","rc":[{"batl":[[0,1.24,4795.04]],"ltp":1.22,"tv":32057.23,"id":8326656},{"batb":[[0,5.3,100.63],[1,5.1,257],[2,4.7,136]],"batl":[[0,5.6,2],[1,6,157.24],[2,1000,0.02]],"ltp":4.5,"tv":3845.96,"id":9712909}]}]}
{"op":"mcm","clk":"1003225011","pt":1580604730940,"mc":[{"id":"1.168179120","rc":[{"trd":[[1.24,224.68]],"batl":[[0,1.24,4792.37]],"ltp":1.24,"tv":32062.57,"id":8326656}],"tv":35908.53}]}
{"op":"mcm","clk":"1003225083","pt":1580604732077,"mc":[{"id":"1.168179120","rc":[{"batl":[[2,7.2,92.18]],"ltp":4.5,"tv":3845.96,"id":9712909}]}]}
{"op":"mcm","clk":"1003225144","pt":1580604732953,"mc":[{"id":"1.168179120","rc":[{"batl":[[0,1.24,4824.26]],"ltp":1.24,"tv":32062.57,"id":8326656},{"batl":[[0,5.5,4.37],[1,5.6,2],[2,6,157.24]],"ltp":4.5,"tv":3845.96,"id":9712909}]}]}
{"op":"mcm","clk":"1003225247","pt":1580604734858,"mc":[{"id":"1.168179120","rc":[{"batl":[[0,1.24,4666.97]],"ltp":1.24,"tv":32062.57,"id":8326656}]}]}
{"op":"mcm","clk":"1003225344","pt":1580604736355,"mc":[{"id":"1.168179120","rc":[{"trd":[[1.22,885.3]],"batb":[[0,1.22,4337.94]],"ltp":1.22,"tv":32067.57,"id":8326656}],"tv":35913.53}]}
{"op":"mcm","clk":"1003225438","pt":1580604737765,"mc":[{"id":"1.168179120","rc":[{"batb":[[0,1.22,4581.59]],"ltp":1.22,"tv":32067.57,"id":8326656}]}]}
{"op":"mcm","clk":"1003225451","pt":1580604737971,"mc":[{"id":"1.168179120","rc":[{"batb":[[1,1.21,2704.9]],"ltp":1.22,"tv":32067.57,"id":8326656},{"batl":[[2,5.8,2]],"ltp":4.5,"tv":3845.96,"id":9712909}]}]}
{"op":"mcm","clk":"1003225518","pt":1580604739154,"mc":[{"id":"1.168179120","rc":[{"trd":[[1.22,887.54],[1.24,267.48]],"batb":[[0,1.22,4580.47]],"batl":[[0,1.24,4645.57]],"ltp":1.24,"tv":32112.61,"id":8326656},{"trd":[[5.5,216.29]],"batl":[[0,5.5,3.69]],"ltp":5.5,"tv":3847.32,"id":9712909}],"tv":35959.94}]}
{"op":"mcm","clk":"1003225743","pt":1580604742860,"mc":[{"id":"1.168179120","rc":[{"batb":[[0,1.22,4780.47]],"batl":[[0,1.23,27.73],[1,1.24,4645.57],[2,1.25,1320.62]],"ltp":1.24,"tv":32112.61,"id":8326656}]}]}
{"op":"mcm","clk":"1003225799","pt":1580604743785,"mc":[{"id":"1.168179120","rc":[{"trd":[[1.23,1959.65]],"batl":[[0,1.23,27.29]],"ltp":1.23,"tv":32113.49,"id":8326656}],"tv":35960.82}]}
{"op":"mcm","clk":"1003225833","pt":1580604744353,"mc":[{"id":"1.168179120","rc":[{"trd":[[5.3,611.26]],"batb":[[0,5.3,99.96]],"ltp":5.3,"tv":3848.66,"id":9712909}],"tv":35962.16}]}
{"op":"mcm","clk":"1003225898","pt":1580604745280,"mc":[{"id":"1.168179120","rc":[{"trd":[[1.22,893.6]],"batb":[[0,1.22,4777.44]],"ltp":1.22,"tv":32119.55,"id":8326656}],"tv":35968.21}]}
{"op":"mcm","clk":"1003225960","pt":1580604746053,"mc":[{"id":"1.168179120","rc":[{"trd":[[1.22,899.66]],"batb":[[0,1.22,4774.41]],"ltp":1.22,"tv":32125.61,"id":8326656},{"trd":[[5.5,216.32]],"batl":[[0,5.5,3.68]],"ltp":5.5,"tv":3848.69,"id":9712909}],"tv":35974.3}]}
{"op":"mcm","clk":"1003226062","pt":1580604747604,"mc":[{"id":"1.168179120","rc":[{"trd":[[1.22,905.72],[1.23,2003.65]],"batb":[[0,1.22,4771.38]],"batl":[[0,1.23,5.29]],"ltp":1.22,"tv":32175.66,"id":8326656}],"tv":36024.35}]}
{"op":"mcm","clk":"1003226097","pt":1580604748074,"mc":[{"id":"1.168179120","rc":[{"trd":[[1.22,911.78]],"batb":[[0,1.22,4768.35]],"ltp":1.22,"tv":32181.72,"id":8326656}],"tv":36030.41}]}
{"op":"mcm","clk":"1003226165","pt":1580604749100,"mc":[{"id":"1.168179120","rc":[{"batl":[[1,1.24,4613.68]],"ltp":1.22,"tv":32181.72,"id":8326656},{"batl":[[0,5.6,2],[1,5.8,2],[2,6,157.24]],"ltp":5.5,"tv":3848.69,"id":9712909}]}]}
{"op":"mcm","clk":"1003226357","pt":1580604752102,"mc":[{"id":"1.168179120","rc":[{"batb":[[0,5.3,103.3]],"batl":[[0,5.5,3.68],[1,5.6,2],[2,5.8,2]],"ltp":5.5,"tv":3848.69,"id":9712909}]}]}
{"op":"mcm","clk":"1003226421","pt":1580604753082,"mc":[{"id":"1.168179120","rc":[{"trd":[[1.23,2007.16]],"batl":[[0,1.23,3.54]],"ltp":1.23,"tv":32185.23,"id":8326656},{"trd":[[5.3,615.81]],"batb":[[0,5.3,101.03]],"ltp":5.3,"tv":3853.23,"id":9712909}],"tv":36038.47}]}
{"op":"mcm","clk":"1003226528","pt":1580604754884,"mc":[{"id":"1.168179120","rc":[{"batb":[[2,1.2,88.97]],"ltp":1.23,"tv":32185.23,"id":8326656},{"batb":[[0,5.3,97.69],[1,4.7,136],[2,4.2,2.02]],"batl":[[0,5.6,2],[1,5.8,2],[2,6,2.01]],"ltp":5.3,"tv":3853.23,"id":9712909}]}]}
{"op":"mcm","clk":"1003226586","pt":1580604755814,"mc":[{"id":"1.168179120","rc":[{"batb":[[0,1.22,200],[1,1.21,80.69]],"batl":[[1,1.28,110.18],[2,1.31,55.5]],"ltp":1.23,"tv":32185.23,"id":8326656},{"trd":[[5.3,621.87]],"batb":[[0,4.7,134],[1,4.2,2.02],[2,3.9,2.06]],"batl":[[0,5.8,2],[1,6,2.01],[2,6.6,98.95]],"ltp":5.3,"tv":3859.29,"id":9712909}],"tv":36044.53}]}
{"op":"mcm","clk":"1003226607","pt":1580604756177,"mc":[{"id":"1.168179120","rc":[{"trd":[[1.23,2014.24]],"batb":[[0,1.24,18.46],[1,1.22,200],[2,1.21,80.69]],"batl":[[0,1.28,110.18],[1,1.31,55.5],[2,1.34,55.25]],"ltp":1.23,"tv":32192.31,"id":8326656}],"tv":36051.6}]}
{"op":"mcm","clk":"1003226657","pt":1580604757100,"mc":[{"id":"1.168179120","rc":[{"trd":[[1.24,280.86]],"batb":[[0,1.24,11.77]],"ltp":1.24,"tv":32205.69,"id":8326656}],"tv":36064.99}]}
{"op":"mcm","clk":"1003226761","pt":1580604758804,"mc":[{"id":"1.168179120","rc":[{"batb":[[1,1.21,80.69],[2,1.2,88.97]],"ltp":1.24,"tv":32205.69,"id":8326656}]}]}
{"op":"mcm","clk":"1003226803","pt":1580604759421,"mc":[{"id":"1.168179120","rc":[{"batb":[[1,1.23,100]],"ltp":1.24,"tv":32205.69,"id":8326656},{"batb":[[0,4.6,134.31]],"batl":[[0,6,2.01],[1,1000,0.02],[2,6.6,0]],"ltp":5.3,"tv":3859.29,"id":9712909}]}]}
{"op":"mcm","clk":"1003226954","pt":1580604761895,"mc":[{"id":"1.168179120","rc":[{"trd":[[1.24,304.4],[1.28,668.44]],"batb":[[0,1.23,361.36],[1,1.22,1903.42],[2,1.21,1506.12]],"batl":[[0,1.25,1343.75],[1,1.26,1252.3],[2,1.31,55.5]],"ltp":1.24,"tv":32473.85,"id":8326656},{"trd":[[4.6,6.75]],"batb":[[0,4.6,127.56]],"ltp":4.6,"tv":3866.04,"id":9712909}],"tv":36339.89}]}
{"op":"mcm","clk":"1003226973","pt":1580604762205,"mc":[{"id":"1.168179120","rc":[{"batb":[[2,1.21,1580.81]],"ltp":1.24,"tv":32473.85,"id":8326656},{"batl":[[0,5.8,2],[1,6,2.01],[2,1000,0.02]],"ltp":4.6,"tv":3866.04,"id":9712909}]}]}
{"op":"mcm","clk":"1003227065","pt":1580604763609,"mc":[{"id":"1.168179120","rc":[{"batl":[[0,1.25,1393.75]],"ltp":1.24,"tv":32473.85,"id":8326656},{"batl":[[1,6,107.79]],"ltp":4.6,"tv":3866.04,"id":9712909}]}]}
{"op":"mcm","clk":"1003227139","pt":1580604764794,"mc":[{"id":"1.168179120","rc":[{"batb":[[0,1.23,350.66]],"batl":[[0,1.24,100],[1,1.25,1393.75],[2,1.26,1252.3]],"ltp":1.24,"tv":32473.85,"id":8326656}]}]}
{"op":"mcm","clk":"1003227166","pt":1580604765204,"mc":[{"id":"1.168179120","rc":[{"batb":[[0,1.23,300],[1,1.21,74.69],[2,1.2,88.97]],"batl":[[1,1.25,50],[2,1.31,55.5]],"ltp":1.24,"tv":32473.85,"id":8326656}]}]}
{"op":"mcm","clk":"1003227278","pt":1580604766800,"mc":[{"id":"1.168179120","rc":[{"batl":[[0,1.24,150]],"ltp":1.24,"tv":32473.85,"id":8326656}]}]}
{"op":"mcm","clk":"1003227358","pt":1580604768088,"mc":[{"id":"1.168179120","rc":[{"batb":[[2,1.2,1360.39]],"batl":[[2,1.28,1193.83]],"ltp":1.24,"tv":32473.85,"id":8326656}]}]}
{"op":"mcm","clk":"1003227566","pt":1580604771027,"mc":[{"id":"1.168179120","rc":[{"batb":[[0,1.23,100]],"ltp":1.24,"tv":32473.85,"id":8326656},{"batl":[[0,5.3,5.3],[1,5.8,2],[2,6,107.79]],"ltp":4.6,"tv":3866.04,"id":9712909}]}]}
{"op":"mcm","clk":"1003227717","pt":1580604772616,"mc":[{"id":"1.168179120","rc":[{"trd":[[1.24,347.2]],"batl":[[0,1.24,128.6]],"ltp":1.24,"tv":32516.65,"id":8326656}],"tv":36382.69}]}
{"op":"mcm","clk":"1003227742","pt":1580604772934,"mc":[{"id":"1.168179120","rc":[{"trd":[[1.24,355.43]],"batl":[[0,1.24,120.37]],"ltp":1.24,"tv":32524.88,"id":8326656},{"trd":[[5.1,69.03]],"ltp":5.1,"tv":3868.04,"id":9712909}],"tv":36392.92}]}
{"op":"mcm","clk":"1003227905","pt":1580604774838,"mc":[{"id":"1.168179120","rc":[{"trd":[[1.24,596.17],[1.25,952.48]],"batb":[[0,1.24,79.63],[1,1.23,100],[2,1.21,74.69]],"batl":[[0,1.25,49.71],[1,1.28,1193.83],[2,1.29,1100.03]],"ltp":1.25,"tv":32766.2,"id":8326656}],"tv":36634.24}]}
{"op":"mcm","clk":"1003228035","pt":1580604776742,"mc":[{"id":"1.168179120","rc":[{"batl":[[0,1.28,1193.83],[1,1.29,1100.03],[2,1.31,55.5]],"ltp":1.25,"tv":32766.2,"id":8326656}]}]}
{"op":"mcm","clk":"1003228161","pt":1580604778698,"mc":[{"id":"1.168179120","rc":[{"batb":[[0,1.24,90.63],[2,1.21,103.26]],"ltp":1.25,"tv":32766.2,"id":8326656},{"batl":[[2,6,2.01]],"ltp":5.1,"tv":3868.04,"id":9712909}]}]}
{"op":"mcm","clk":"1003228251","pt":1580604779832,"mc":[{"id":"1.168179120","rc":[{"batb":[[0,1.26,88],[1,1.25,5074.62],[2,1.24,1543.93]],"batl":[[0,1.28,4736.16]],"ltp":1.25,"tv":32766.2,"id":8326656},{"batb":[[1,4.5,274.89],[2,4.2,2.02]],"batl":[[0,4.8,3.59],[1,5.1,217.9],[2,5.3,5.3]],"ltp":5.1,"tv":3868.04,"id":9712909}]}]}
{"op":"mcm","clk":"1003228286","pt":1580604780348,"mc":[{"id":"1.168179120","rc":[{"batb":[[2,1.24,2371.35]],"ltp":1.25,"tv":32766.2,"id":8326656}]}]}
{"op":"mcm","clk":"1003228721","pt":1580604786528,"mc":[{"id":"1.168179120","rc":[{"batb":[[0,1.26,146.28]],"batl":[[0,1.27,135.49],[1,1.28,4809.61],[2,1.29,1173.17]],"ltp":1.25,"tv":32766.2,"id":8326656}]}]}
{"op":"mcm","clk":"1003228747","pt":1580604786931,"mc":[{"id":"1.168179120","rc":[{"batb":[[1,1.25,5150.96]],"ltp":1.25,"tv":32766.2,"id":8326656}]}]}
{"op":"mcm","clk":"1003228881","pt":1580604788851,"mc":[{"id":"1.168179120","rc":[{"trd":[[1.27,5374.75]],"batl":[[0,1.27,71.27]],"ltp":1.27,"tv":32912.81,"id":8326656}],"tv":36780.85}]}
{"op":"mcm","clk":"1003228938","pt":1580604789569,"mc":[{"id":"1.168179120","rc":[{"trd":[[1.27,5517.28]],"batb":[[0,1.27,78.73],[1,1.26,146.28],[2,1.25,5150.96]],"batl":[[0,1.28,4809.61],[1,1.29,1173.17],[2,1.31,55.5]],"ltp":1.27,"tv":33055.35,"id":8326656},{"batl":[[2,5.2,2]],"ltp":5.1,"tv":3868.04,"id":9712909}],"tv":36923.39}]}
{"op":"mcm","clk":"1003229062","pt":1580604791635,"mc":[{"id":"1.168179120","rc":[{"trd":[[1.27,5523.34]],"batb":[[0,1.27,75.7],[2,1.25,5074.62]],"batl":[[1,1.29,1100.03]],"ltp":1.27,"tv":33061.41,"id":8326656}],"tv":36929.45}]}
{"op":"mcm","clk":"1003229117","pt":1580604792565,"mc":[{"id":"1.168179120","rc":[{"trd":[[1.27,5578.79]],"batb":[[0,1.27,47.98]],"ltp":1.27,"tv":33116.86,"id":8326656}],"tv":36984.9}]}
{"op":"mcm","clk":"1003229158","pt":1580604793136,"mc":[{"id":"1.168179120","rc":[{"batb":[[0,1.27,172.98]],"ltp":1.27,"tv":33116.86,"id":8326656}]}]}
{"op":"mcm","clk":"1003229239","pt":1580604794737,"mc":[{"id":"1.168179120","rc":[{"trd":[[1.27,5584.85]],"batb":[[0,1.27,169.95],[1,1.26,521.28],[2,1.25,5151.31]],"ltp":1.27,"tv":33122.92,"id":8326656},{"batl":[[1,5,2],[2,5.1,217.9]],"ltp":5.1,"tv":3868.04,"id":9712909}],"tv":36990.96}]}
{"op":"mcm","clk":"1003229269","pt":1580604795248,"mc":[{"id":"1.168179120","rc":[{"batb":[[1,1.26,646.28]],"ltp":1.27,"tv":33122.92,"id":8326656}]}]}
{"op":"mcm","clk":"1003229357","pt":1580604796639,"mc":[{"id":"1.168179120","rc":[{"trd":[[1.27,5585.19]],"batb":[[0,1.27,419.78],[1,1.26,771.28]],"ltp":1.27,"tv":33123.26,"id":8326656}],"tv":36991.3}]}
{"op":"mcm","clk":"1003229382","pt":1580604797053,"mc":[{"id":"1.168179120","rc":[{"batb":[[1,1.26,896.28]],"ltp":1.27,"tv":33123.26,"id":8326656}]}]}
{"op":"mcm","clk":"1003229618","pt":1580604800762,"mc":[{"id":"1.168179120","rc":[{"batl":[[0,1.28,4782.9]],"ltp":1.27,"tv":33123.26,"id":8326656},{"batb":[[1,4.2,2.02],[2,4,187.03]],"batl":[[0,5,2],[1,5.2,2],[2,5.4,2]],"ltp":5.1,"tv":3868.04,"id":9712909}]}]}
{"op":"mcm","clk":"1003229656","pt":1580604801332,"mc":[{"id":"1.168179120","rc":[{"trd":[[1.28,672.46]],"batb":[[2,1.25,76.69]],"batl":[[0,1.28,73.45],[1,1.36,50.32],[2,1.39,44.5]],"ltp":1.28,"tv":33127.27,"id":8326656},{"batb":[[0,4,187.03],[1,3.75,2.03],[2,3.55,2.39]],"ltp":5.1,"tv":3868.04,"id":9712909}],"tv":36995.32}]}
{"op":"mcm","clk":"1003229716","pt":1580604802462,"mc":[{"id":"1.168179120","rc":[{"trd":[[1.28,682.64]],"batl":[[0,1.28,68.36]],"ltp":1.28,"tv":33137.46,"id":8326656},{"batl":[[0,4.9,5.3],[1,5,2],[2,5.2,2]],"ltp":5.1,"tv":3868.04,"id":9712909}],"tv":37005.5}]}
