{"op":"mcm","clk":"992350394","pt":1580520342496,"mc":[{"id":"1.168179122","marketDefinition":{"bspMarket":false,"turnInPlayEnabled":true,"persistenceEnabled":true,"marketBaseRate":5.0,"eventId":"29680182","eventTypeId":"2","numberOfWinners":1,"bettingType":"ODDS","marketType":"SET_WINNER","marketTime":"2020-02-02T00:00:00.000Z","suspendTime":"2020-02-02T00:00:00.000Z","bspReconciled":false,"complete":true,"inPlay":false,"crossMatching":false,"runnersVoidable":false,"numberOfActiveRunners":2,"betDelay":0,"status":"OPEN","runners":[{"status":"ACTIVE","sortPriority":1,"id":9712909,"name":"Felipe Meligeni Rodrigu"},{"status":"ACTIVE","sortPriority":2,"id":8326656,"name":"Thiago Monteiro"}],"regulators":["MR_INT"],"countryCode":"UY","discountAllowed":false,"timezone":"UTC","openDate":"2020-02-02T00:00:00.000Z","version":3144293969,"name":"Set 1 Winner","eventName":"Meligeni Rodrigues Alve v T Monteiro"},"rc":[{"batb":[[0,1.01,20]],"ltp":0.0,"tv":0.0,"id":8326656},{"batb":[[0,1.01,20]],"ltp":0.0,"tv":0.0,"id":9712909}]}]}
{"op":"mcm","clk":"992350445","pt":1580520343901,"mc":[{"id":"1.168179122","marketDefinition":{"bspMarket":false,"turnInPlayEnabled":true,"persistenceEnabled":true,"marketBaseRate":5.0,"eventId":"29680182","eventTypeId":"2","numberOfWinners":1,"bettingType":"ODDS","marketType":"SET_WINNER","marketTime":"2020-02-02T00:00:00.000Z","suspendTime":"2020-02-02T00:00:00.000Z","bspReconciled":false,"complete":true,"inPlay":false,"crossMatching":false,"runnersVoidable":false,"numberOfActiveRunners":2,"betDelay":0,"status":"OPEN","runners":[{"status":"ACTIVE","sortPriority":1,"id":9712909,"name":"Felipe Meligeni Rodrigu"},{"status":"ACTIVE","sortPriority":2,"id":8326656,"name":"Thiago Monteiro"}],"regulators":["MR_INT"],"countryCode":"UY","discountAllowed":true,"timezone":"UTC","openDate":"2020-02-02T00:00:00.000Z","version":3144293969,"name":"Set 1 Winner","eventName":"Meligeni Rodrigues Alve v T Monteiro"}}]}
{"op":"mcm","clk":"992357859","pt":1580520615740,"mc":[{"id":"1.168179122","rc":[{"batb":[[0,1.01,15]],"ltp":0.0,"tv":0.0,"id":8326656},{"batb":[[0,1.01,15]],"ltp":0.0,"tv":0.0,"id":9712909}]}]}
{"op":"mcm","clk":"993028681","pt":1580535296011,"mc":[{"id":"1.168179122","rc":[{"batb":[[0,1.29,93.72],[1,1.01,15]],"ltp":0.0,"tv":0.0,"id":8326656},{"batb":[[0,3.25,12.07],[1,1.01,15]],"ltp":0.0,"tv":0.0,"id":9712909}]}]}
{"op":"mcm","clk":"993029211","pt":1580535307443,"mc":[{"id":"1.168179122","marketDefinition":{"bspMarket":false,"turnInPlayEnabled":true,"persistenceEnabled":true,"marketBaseRate":5.0,"eventId":"29680182","eventTypeId":"2","numberOfWinners":1,"bettingType":"ODDS","marketType":"SET_WINNER","marketTime":"2020-02-02T00:00:00.000Z","suspendTime":"2020-02-02T00:00:00.000Z","bspReconciled":false,"complete":true,"inPlay":false,"crossMatching":true,"runnersVoidable":false,"numberOfActiveRunners":2,"betDelay":0,"status":"OPEN","runners":[{"status":"ACTIVE","sortPriority":1,"id":9712909,"name":"Felipe Meligeni Rodrigu"},{"status":"ACTIVE","sortPriority":2,"id":8326656,"name":"Thiago Monteiro"}],"regulators":["MR_INT"],"countryCode":"UY","discountAllowed":true,"timezone":"UTC","openDate":"2020-02-02T00:00:00.000Z","version":3144293969,"name":"Set 1 Winner","eventName":"Meligeni Rodrigues Alve v T Monteiro"}}]}
{"op":"mcm","clk":"993032998","pt":1580535396698,"mc":[{"id":"1.168179122","rc":[{"batb":[[0,1.22,123.54]],"ltp":0.0,"tv":0.0,"id":8326656},{"batb":[[0,3.75,10]],"ltp":0.0,"tv":0.0,"id":9712909}]}]}
{"op":"mcm","clk":"993075334","pt":1580536091026,"mc":[{"id":"1.168179122","rc":[{"batb":[[0,1.2,135.89]],"ltp":0.0,"tv":0.0,"id":8326656},{"batb":[[0,4,10]],"ltp":0.0,"tv":0.0,"id":9712909}]}]}
{"op":"mcm","clk":"997867189","pt":1580568563053,"mc":[{"id":"1.168179122","rc":[{"batb":[[0,1.17,159.87]],"ltp":0.0,"tv":0.0,"id":8326656},{"batb":[[0,4.5,10]],"ltp":0.0,"tv":0.0,"id":9712909}]}]}
{"op":"mcm","clk":"999575113","pt":1580575364280,"mc":[{"id":"1.168179122","rc":[{"batb":[[0,4,10]],"ltp":0.0,"tv":0.0,"id":9712909}]}]}
{"op":"mcm","clk":"1000293156","pt":1580579986742,"mc":[{"id":"1.168179122","rc":[{"batb":[[0,1.17,173.67]],"ltp":0.0,"tv":0.0,"id":8326656}]}]}
{"op":"mcm","clk":"1000295082","pt":1580580001832,"mc":[{"id":"1.168179122","rc":[{"batb":[[0,1.17,434.18]],"ltp":0.0,"tv":0.0,"id":8326656},{"batb":[[0,4,24.76]],"ltp":0.0,"tv":0.0,"id":9712909}]}]}
{"op":"mcm","clk":"1000295102","pt":1580580001937,"mc":[{"id":"1.168179122","rc":[{"batb":[[0,1.17,260.51]],"ltp":0.0,"tv":0.0,"id":8326656},{"batb":[[0,4,14.76]],"ltp":0.0,"tv":0.0,"id":9712909}]}]}
{"op":"mcm","clk":"1000295940","pt":1580580006968,"mc":[{"id":"1.168179122","rc":[{"batb":[[0,4.5,12.65]],"ltp":0.0,"tv":0.0,"id":9712909}]}]}
{"op":"mcm","clk":"1002491901","pt":1580594401787,"mc":[{"id":"1.168179122","rc":[{"batb":[[0,1.17,347.35]],"ltp":0.0,"tv":0.0,"id":8326656},{"batb":[[0,4.5,16.87]],"ltp":0.0,"tv":0.0,"id":9712909}]}]}
{"op":"mcm","clk":"1002519194","pt":1580594810730,"mc":[{"id":"1.168179122","rc":[{"batb":[[1,1.01,17]],"ltp":0.0,"tv":0.0,"id":8326656},{"batb":[[1,1.01,17]],"ltp":0.0,"tv":0.0,"id":9712909}]}]}
{"op":"mcm","clk":"1002519230","pt":1580594811304,"mc":[{"id":"1.168179122","rc":[{"trd":[[1.29,0.01]],"batb":[[1,1.01,15]],"ltp":1.29,"tv":0.01,"id":8326656},{"batb":[[1,1.01,15.01]],"ltp":0.0,"tv":0.0,"id":9712909}],"tv":0.01}]}
{"op":"mcm","clk":"1002652237","pt":1580596663507,"mc":[{"id":"1.168179122","rc":[{"batb":[[0,1.22,268.4]],"ltp":1.29,"tv":0.01,"id":8326656},{"batb":[[0,3.75,21.47]],"ltp":0.0,"tv":0.0,"id":9712909}]}]}
{"op":"mcm","clk":"1002701649","pt":1580597501620,"mc":[{"id":"1.168179122","rc":[{"batb":[[0,1.2,295.24]],"ltp":1.29,"tv":0.01,"id":8326656},{"batb":[[0,4,19.68]],"ltp":0.0,"tv":0.0,"id":9712909}]}]}
{"op":"mcm","clk":"1002754420","pt":1580598303860,"mc":[{"id":"1.168179122","rc":[{"batb":[[0,1.22,268.4]],"ltp":1.29,"tv":0.01,"id":8326656},{"batb":[[0,3.75,21.47]],"ltp":0.0,"tv":0.0,"id":9712909}]}]}
{"op":"mcm","clk":"1002778028","pt":1580598642467,"mc":[{"id":"1.168179122","rc":[{"batb":[[0,1.23,2],[1,1.22,268.4],[2,1.01,15]],"ltp":1.29,"tv":0.01,"id":8326656},{"batb":[[0,3.8,2],[1,3.75,21.47],[2,1.01,15.01]],"ltp":0.0,"tv":0.0,"id":9712909}]}]}
{"op":"mcm","clk":"1002783558","pt":1580598715771,"mc":[{"id":"1.168179122","rc":[{"batb":[[0,1.24,2.03],[1,1.23,2],[2,1.22,268.4]],"ltp":1.29,"tv":0.01,"id":8326656},{"batb":[[2,1.01,15.67]],"ltp":0.0,"tv":0.0,"id":9712909}]}]}
{"op":"mcm","clk":"1002783581","pt":1580598716080,"mc":[{"id":"1.168179122","rc":[{"batb":[[0,3.8,2.66],[2,1.01,15.01]],"ltp":0.0,"tv":0.0,"id":9712909}]}]}
{"op":"mcm","clk":"1002822549","pt":1580599241843,"mc":[{"id":"1.168179122","rc":[{"batb":[[1,1.22,268.4],[2,1.01,15]],"ltp":1.29,"tv":0.01,"id":8326656},{"batb":[[0,3.75,22.13],[1,1.01,15.01],[2,1.01,0]],"ltp":0.0,"tv":0.0,"id":9712909}]}]}
{"op":"mcm","clk":"1002823367","pt":1580599252352,"mc":[{"id":"1.168179122","rc":[{"batb":[[0,1.25,2],[1,1.24,2.03],[2,1.22,268.4]],"ltp":1.29,"tv":0.01,"id":8326656},{"batb":[[0,3.8,2.66],[1,3.75,21.47],[2,1.01,15.01]],"ltp":0.0,"tv":0.0,"id":9712909}]}]}
{"op":"mcm","clk":"1002823698","pt":1580599256495,"mc":[{"id":"1.168179122","rc":[{"batb":[[0,1.26,2],[1,1.25,2]],"ltp":1.29,"tv":0.01,"id":8326656}]}]}
{"op":"mcm","clk":"1002868867","pt":1580599851696,"mc":[{"id":"1.168179122","rc":[{"batb":[[1,1.22,268.4],[2,1.01,15]],"ltp":1.29,"tv":0.01,"id":8326656},{"batb":[[0,3.75,22.13],[1,1.01,15.01],[2,1.01,0]],"ltp":0.0,"tv":0.0,"id":9712909}]}]}
{"op":"mcm","clk":"1002868948","pt":1580599852588,"mc":[{"id":"1.168179122","rc":[{"batb":[[0,1.27,2],[1,1.26,2],[2,1.22,268.4]],"ltp":1.29,"tv":0.01,"id":8326656},{"batb":[[0,3.8,2.66],[1,3.75,21.47],[2,1.01,15.01]],"ltp":0.0,"tv":0.0,"id":9712909}]}]}
{"op":"mcm","clk":"1002869222","pt":1580599856219,"mc":[{"id":"1.168179122","rc":[{"batb":[[0,1.28,1.97],[1,1.27,2]],"ltp":1.29,"tv":0.01,"id":8326656}]}]}
{"op":"mcm","clk":"1002909711","pt":1580600452116,"mc":[{"id":"1.168179122","rc":[{"batb":[[1,1.22,268.4],[2,1.01,15]],"ltp":1.29,"tv":0.01,"id":8326656},{"batb":[[0,3.75,22.13],[1,1.01,15.01],[2,1.01,0]],"ltp":0.0,"tv":0.0,"id":9712909}]}]}
{"op":"mcm","clk":"1002910430","pt":1580600461715,"mc":[{"id":"1.168179122","rc":[{"batb":[[1,1.23,2],[2,1.22,268.4]],"ltp":1.29,"tv":0.01,"id":8326656},{"batb":[[0,3.8,2.66],[1,3.75,21.47],[2,1.01,15.01]],"ltp":0.0,"tv":0.0,"id":9712909}]}]}
{"op":"mcm","clk":"1002949649","pt":1580601061314,"mc":[{"id":"1.168179122","rc":[{"batb":[[1,1.22,268.4],[2,1.01,15]],"ltp":1.29,"tv":0.01,"id":8326656},{"batb":[[0,3.75,22.13],[1,1.01,15.01],[2,1.01,0]],"ltp":0.0,"tv":0.0,"id":9712909}]}]}
{"op":"mcm","clk":"1002949791","pt":1580601063287,"mc":[{"id":"1.168179122","rc":[{"batb":[[1,1.23,2],[2,1.22,268.4]],"ltp":1.29,"tv":0.01,"id":8326656},{"batb":[[0,3.8,2.66],[1,3.75,21.47],[2,1.01,15.01]],"ltp":0.0,"tv":0.0,"id":9712909}]}]}
{"op":"mcm","clk":"1002962569","pt":1580601242648,"mc":[{"id":"1.168179122","rc":[{"batb":[[1,1.22,268.4],[2,1.01,15]],"ltp":1.29,"tv":0.01,"id":8326656},{"batb":[[0,3.75,22.13],[1,1.01,15.01],[2,1.01,0]],"ltp":0.0,"tv":0.0,"id":9712909}]}]}
{"op":"mcm","clk":"1002962741","pt":1580601245536,"mc":[{"id":"1.168179122","rc":[{"batb":[[1,1.23,2],[2,1.22,268.4]],"ltp":1.29,"tv":0.01,"id":8326656},{"batb":[[0,3.8,2.66],[1,3.75,21.47],[2,1.01,15.01]],"ltp":0.0,"tv":0.0,"id":9712909}]}]}
{"op":"mcm","clk":"1002975327","pt":1580601424772,"mc":[{"id":"1.168179122","rc":[{"batb":[[1,1.22,268.4],[2,1.01,15]],"ltp":1.29,"tv":0.01,"id":8326656}]}]}
{"op":"mcm","clk":"1002975351","pt":1580601425081,"mc":[{"id":"1.168179122","rc":[{"batb":[[0,3.75,22.13],[1,1.01,15.01],[2,1.01,0]],"ltp":0.0,"tv":0.0,"id":9712909}]}]}
{"op":"mcm","clk":"1002975513","pt":1580601427358,"mc":[{"id":"1.168179122","rc":[{"batb":[[1,1.23,2],[2,1.22,268.4]],"ltp":1.29,"tv":0.01,"id":8326656},{"batb":[[0,3.8,2.66],[1,3.75,21.47],[2,1.01,15.01]],"ltp":0.0,"tv":0.0,"id":9712909}]}]}
{"op":"mcm","clk":"1002979915","pt":1580601486721,"mc":[{"id":"1.168179122","rc":[{"batb":[[1,1.22,268.4],[2,1.01,15]],"ltp":1.29,"tv":0.01,"id":8326656},{"batb":[[0,3.75,22.13],[1,1.01,15.01],[2,1.01,0]],"ltp":0.0,"tv":0.0,"id":9712909}]}]}
{"op":"mcm","clk":"1002979986","pt":1580601487647,"mc":[{"id":"1.168179122","rc":[{"batb":[[1,1.25,236.19]],"ltp":1.29,"tv":0.01,"id":8326656},{"batb":[[0,3.5,24.27]],"ltp":0.0,"tv":0.0,"id":9712909}]}]}
{"op":"mcm","clk":"1002980609","pt":1580601496161,"mc":[{"id":"1.168179122","rc":[{"batb":[[1,1.26,2],[2,1.25,236.19]],"ltp":1.29,"tv":0.01,"id":8326656},{"batb":[[0,3.55,2.66],[1,3.5,23.61],[2,1.01,15.01]],"ltp":0.0,"tv":0.0,"id":9712909}]}]}
{"op":"mcm","clk":"1002983948","pt":1580601543123,"mc":[{"id":"1.168179122","rc":[{"batb":[[2,3.45,61.22]],"ltp":0.0,"tv":0.0,"id":9712909}]}]}
{"op":"mcm","clk":"1002984877","pt":1580601555501,"mc":[{"id":"1.168179122","rc":[{"batb":[[1,1.25,236.19],[2,1.24,625]],"ltp":1.29,"tv":0.01,"id":8326656},{"batb":[[0,3.5,24.27],[1,3.45,61.22],[2,1.01,15.01]],"ltp":0.0,"tv":0.0,"id":9712909}]}]}
{"op":"mcm","clk":"1002985661","pt":1580601565129,"mc":[{"id":"1.168179122","rc":[{"batb":[[1,1.26,2],[2,1.25,236.19]],"ltp":1.29,"tv":0.01,"id":8326656},{"batb":[[0,3.55,2.66],[1,3.5,23.61],[2,3.45,61.22]],"ltp":0.0,"tv":0.0,"id":9712909}]}]}
{"op":"mcm","clk":"1002994722","pt":1580601699793,"mc":[{"id":"1.168179122","marketDefinition":{"bspMarket":false,"turnInPlayEnabled":true,"persistenceEnabled":true,"marketBaseRate":5.0,"eventId":"29680182","eventTypeId":"2","numberOfWinners":1,"bettingType":"ODDS","marketType":"SET_WINNER","marketTime":"2020-02-02T00:15:00.000Z","suspendTime":"2020-02-02T00:15:00.000Z","bspReconciled":false,"complete":true,"inPlay":false,"crossMatching":true,"runnersVoidable":false,"numberOfActiveRunners":2,"betDelay":0,"status":"OPEN","runners":[{"status":"ACTIVE","sortPriority":1,"id":9712909,"name":"Felipe Meligeni Rodrigu"},{"status":"ACTIVE","sortPriority":2,"id":8326656,"name":"Thiago Monteiro"}],"regulators":["MR_INT"],"countryCode":"UY","discountAllowed":true,"timezone":"UTC","openDate":"2020-02-02T00:00:00.000Z","version":3147888956,"name":"Set 1 Winner","eventName":"Meligeni Rodrigues Alve v T Monteiro"}}]}
{"op":"mcm","clk":"1002995013","pt":1580601703802,"mc":[{"id":"1.168179122","marketDefinition":{"bspMarket":false,"turnInPlayEnabled":true,"persistenceEnabled":true,"marketBaseRate":5.0,"eventId":"29680182","eventTypeId":"2","numberOfWinners":1,"bettingType":"ODDS","marketType":"SET_WINNER","marketTime":"2020-02-02T00:15:00.000Z","suspendTime":"2020-02-02T00:15:00.000Z","bspReconciled":false,"complete":true,"inPlay":false,"crossMatching":true,"runnersVoidable":false,"numberOfActiveRunners":2,"betDelay":0,"status":"OPEN","runners":[{"status":"ACTIVE","sortPriority":1,"id":9712909,"name":"Felipe Meligeni Rodrigu"},{"status":"ACTIVE","sortPriority":2,"id":8326656,"name":"Thiago Monteiro"}],"regulators":["MR_INT"],"countryCode":"UY","discountAllowed":true,"timezone":"UTC","openDate":"2020-02-02T00:15:00.000Z","version":3147888956,"name":"Set 1 Winner","eventName":"Meligeni Rodrigues Alve v T Monteiro"}}]}
{"op":"mcm","clk":"1002997027","pt":1580601735147,"mc":[{"id":"1.168179122","rc":[{"batb":[[1,1.25,236.19],[2,1.24,625]],"ltp":1.29,"tv":0.01,"id":8326656},{"batb":[[0,3.5,24.27],[1,3.45,61.22],[2,1.01,15.01]],"ltp":0.0,"tv":0.0,"id":9712909}]}]}
{"op":"mcm","clk":"1002997661","pt":1580601745188,"mc":[{"id":"1.168179122","rc":[{"batb":[[1,1.26,2],[2,1.25,236.19]],"ltp":1.29,"tv":0.01,"id":8326656},{"batb":[[0,3.55,2.66],[1,3.5,23.61],[2,3.45,61.22]],"ltp":0.0,"tv":0.0,"id":9712909}]}]}
{"op":"mcm","clk":"1003001642","pt":1580601804695,"mc":[{"id":"1.168179122","rc":[{"batb":[[1,1.25,236.19],[2,1.24,625]],"ltp":1.29,"tv":0.01,"id":8326656},{"batb":[[0,3.5,24.27],[1,3.45,61.22],[2,1.01,15.01]],"ltp":0.0,"tv":0.0,"id":9712909}]}]}
{"op":"mcm","clk":"1003002216","pt":1580601812995,"mc":[{"id":"1.168179122","rc":[{"batb":[[1,1.26,2],[2,1.25,236.19]],"ltp":1.29,"tv":0.01,"id":8326656},{"batb":[[0,3.55,2.66],[1,3.5,23.61],[2,3.45,61.22]],"ltp":0.0,"tv":0.0,"id":9712909}]}]}
{"op":"mcm","clk":"1003006269","pt":1580601872508,"mc":[{"id":"1.168179122","rc":[{"batb":[[1,1.25,236.19],[2,1.24,625]],"ltp":1.29,"tv":0.01,"id":8326656},{"batb":[[0,3.5,24.27],[1,3.45,61.22],[2,1.01,15.01]],"ltp":0.0,"tv":0.0,"id":9712909}]}]}
{"op":"mcm","clk":"1003006813","pt":1580601881070,"mc":[{"id":"1.168179122","rc":[{"batb":[[1,1.26,2],[2,1.25,236.19]],"ltp":1.29,"tv":0.01,"id":8326656},{"batb":[[0,3.55,2.66],[1,3.5,23.61],[2,3.45,61.22]],"ltp":0.0,"tv":0.0,"id":9712909}]}]}
{"op":"mcm","clk":"1003010305","pt":1580601940573,"mc":[{"id":"1.168179122","rc":[{"batb":[[1,1.25,236.19],[2,1.24,625]],"ltp":1.29,"tv":0.01,"id":8326656},{"batb":[[0,3.5,24.27],[1,3.45,61.22],[2,1.01,15.01]],"ltp":0.0,"tv":0.0,"id":9712909}]}]}
{"op":"mcm","clk":"1003067727","pt":1580602568735,"mc":[{"id":"1.168179122","rc":[{"batb":[[2,1.01,17.54]],"ltp":0.0,"tv":0.0,"id":9712909}]}]}
{"op":"mcm","clk":"1003067806","pt":1580602569562,"mc":[{"id":"1.168179122","rc":[{"batb":[[2,1.01,15.52]],"ltp":0.0,"tv":0.0,"id":9712909}]}]}
{"op":"mcm","clk":"1003070584","pt":1580602600982,"mc":[{"id":"1.168179122","marketDefinition":{"bspMarket":false,"turnInPlayEnabled":true,"persistenceEnabled":true,"marketBaseRate":5.0,"eventId":"29680182","eventTypeId":"2","numberOfWinners":1,"bettingType":"ODDS","marketType":"SET_WINNER","marketTime":"2020-02-02T00:30:00.000Z","suspendTime":"2020-02-02T00:30:00.000Z","bspReconciled":false,"complete":true,"inPlay":false,"crossMatching":true,"runnersVoidable":false,"numberOfActiveRunners":2,"betDelay":0,"status":"OPEN","runners":[{"status":"ACTIVE","sortPriority":1,"id":9712909,"name":"Felipe Meligeni Rodrigu"},{"status":"ACTIVE","sortPriority":2,"id":8326656,"name":"Thiago Monteiro"}],"regulators":["MR_INT"],"countryCode":"UY","discountAllowed":true,"timezone":"UTC","openDate":"2020-02-02T00:15:00.000Z","version":3147905061,"name":"Set 1 Winner","eventName":"Meligeni Rodrigues Alve v T Monteiro"}}]}
{"op":"mcm","clk":"1003070979","pt":1580602604992,"mc":[{"id":"1.168179122","marketDefinition":{"bspMarket":false,"turnInPlayEnabled":true,"persistenceEnabled":true,"marketBaseRate":5.0,"eventId":"29680182","eventTypeId":"2","numberOfWinners":1,"bettingType":"ODDS","marketType":"SET_WINNER","marketTime":"2020-02-02T00:30:00.000Z","suspendTime":"2020-02-02T00:30:00.000Z","bspReconciled":false,"complete":true,"inPlay":false,"crossMatching":true,"runnersVoidable":false,"numberOfActiveRunners":2,"betDelay":0,"status":"OPEN","runners":[{"status":"ACTIVE","sortPriority":1,"id":9712909,"name":"Felipe Meligeni Rodrigu"},{"status":"ACTIVE","sortPriority":2,"id":8326656,"name":"Thiago Monteiro"}],"regulators":["MR_INT"],"countryCode":"UY","discountAllowed":true,"timezone":"UTC","openDate":"2020-02-02T00:30:00.000Z","version":3147905151,"name":"Set 1 Winner","eventName":"Meligeni Rodrigues Alve v T Monteiro"}}]}
{"op":"mcm","clk":"1003127403","pt":1580603335732,"mc":[{"id":"1.168179122","rc":[{"batb":[[2,1.01,18.05]],"ltp":0.0,"tv":0.0,"id":9712909}]}]}
{"op":"mcm","clk":"1003127480","pt":1580603336710,"mc":[{"id":"1.168179122","rc":[{"batb":[[2,1.01,16.02]],"ltp":0.0,"tv":0.0,"id":9712909}]}]}
{"op":"mcm","clk":"1003141084","pt":1580603501489,"mc":[{"id":"1.168179122","marketDefinition":{"bspMarket":false,"turnInPlayEnabled":true,"persistenceEnabled":true,"marketBaseRate":5.0,"eventId":"29680182","eventTypeId":"2","numberOfWinners":1,"bettingType":"ODDS","marketType":"SET_WINNER","marketTime":"2020-02-02T00:45:00.000Z","suspendTime":"2020-02-02T00:45:00.000Z","bspReconciled":false,"complete":true,"inPlay":false,"crossMatching":true,"runnersVoidable":false,"numberOfActiveRunners":2,"betDelay":0,"status":"OPEN","runners":[{"status":"ACTIVE","sortPriority":1,"id":9712909,"name":"Felipe Meligeni Rodrigu"},{"status":"ACTIVE","sortPriority":2,"id":8326656,"name":"Thiago Monteiro"}],"regulators":["MR_INT"],"countryCode":"UY","discountAllowed":true,"timezone":"UTC","openDate":"2020-02-02T00:30:00.000Z","version":3147932332,"name":"Set 1 Winner","eventName":"Meligeni Rodrigues Alve v T Monteiro"}}]}
{"op":"mcm","clk":"1003141344","pt":1580603504503,"mc":[{"id":"1.168179122","marketDefinition":{"bspMarket":false,"turnInPlayEnabled":true,"persistenceEnabled":true,"marketBaseRate":5.0,"eventId":"29680182","eventTypeId":"2","numberOfWinners":1,"bettingType":"ODDS","marketType":"SET_WINNER","marketTime":"2020-02-02T00:45:00.000Z","suspendTime":"2020-02-02T00:45:00.000Z","bspReconciled":false,"complete":true,"inPlay":false,"crossMatching":true,"runnersVoidable":false,"numberOfActiveRunners":2,"betDelay":0,"status":"OPEN","runners":[{"status":"ACTIVE","sortPriority":1,"id":9712909,"name":"Felipe Meligeni Rodrigu"},{"status":"ACTIVE","sortPriority":2,"id":8326656,"name":"Thiago Monteiro"}],"regulators":["MR_INT"],"countryCode":"UY","discountAllowed":true,"timezone":"UTC","openDate":"2020-02-02T00:45:00.000Z","version":3147932332,"name":"Set 1 Winner","eventName":"Meligeni Rodrigues Alve v T Monteiro"}}]}
{"op":"mcm","clk":"1003149823","pt":1580603605552,"mc":[{"id":"1.168179122","rc":[{"batb":[[0,1.35,157.89],[1,1.28,1.97],[2,1.25,236.19]],"ltp":1.29,"tv":0.01,"id":8326656}]}]}
{"op":"mcm","clk":"1003151457","pt":1580603624369,"mc":[{"id":"1.168179122","rc":[{"trd":[[1.36,1.86],[1.4,59.03]],"batb":[[0,1.4,97]],"ltp":1.4,"tv":60.9,"id":8326656},{"trd":[[3.5,23.61],[3.85,0.66]],"batb":[[0,3.45,61.22],[1,1.01,16.02],[2,1.01,0]],"ltp":3.5,"tv":24.26,"id":9712909}],"tv":85.16}]}
{"op":"mcm","clk":"1003151903","pt":1580603629814,"mc":[{"id":"1.168179122","rc":[{"trd":[[1.4,156.03]],"batb":[[0,1.28,1.97],[1,1.27,165.15],[2,1.24,625]],"ltp":1.4,"tv":157.9,"id":8326656},{"trd":[[3.5,62.41]],"batb":[[0,4,6.28],[1,3.45,61.22],[2,1.01,16.02]],"ltp":3.5,"tv":63.06,"id":9712909}],"tv":220.96}]}
{"op":"mcm","clk":"1003152287","pt":1580603634211,"mc":[{"id":"1.168179122","rc":[{"batb":[[2,1.25,236.19]],"ltp":1.4,"tv":157.9,"id":8326656},{"batb":[[2,3.05,28.8]],"ltp":3.5,"tv":63.06,"id":9712909}]}]}
{"op":"mcm","clk":"1003152581","pt":1580603637535,"mc":[{"id":"1.168179122","rc":[{"batb":[[0,1.29,160.75],[1,1.28,1.97]],"ltp":1.4,"tv":157.9,"id":8326656},{"batb":[[0,4,46.88]],"ltp":3.5,"tv":63.06,"id":9712909}]}]}
{"op":"mcm","clk":"1003158728","pt":1580603706699,"mc":[{"id":"1.168179122","rc":[{"batb":[[0,1.29,160.2]],"ltp":1.4,"tv":157.9,"id":8326656}]}]}
{"op":"mcm","clk":"1003166663","pt":1580603799332,"mc":[{"id":"1.168179122","marketDefinition":{"bspMarket":false,"turnInPlayEnabled":true,"persistenceEnabled":true,"marketBaseRate":5.0,"eventId":"29680182","eventTypeId":"2","numberOfWinners":1,"bettingType":"ODDS","marketType":"SET_WINNER","marketTime":"2020-02-02T00:32:00.000Z","suspendTime":"2020-02-02T00:32:00.000Z","bspReconciled":false,"complete":true,"inPlay":false,"crossMatching":true,"runnersVoidable":false,"numberOfActiveRunners":2,"betDelay":0,"status":"OPEN","runners":[{"status":"ACTIVE","sortPriority":1,"id":9712909,"name":"Felipe Meligeni Rodrigu"},{"status":"ACTIVE","sortPriority":2,"id":8326656,"name":"Thiago Monteiro"}],"regulators":["MR_INT"],"countryCode":"UY","discountAllowed":true,"timezone":"UTC","openDate":"2020-02-02T00:45:00.000Z","version":3147936783,"name":"Set 1 Winner","eventName":"Meligeni Rodrigues Alve v T Monteiro"}}]}
{"op":"mcm","clk":"1003167020","pt":1580603803341,"mc":[{"id":"1.168179122","marketDefinition":{"bspMarket":false,"turnInPlayEnabled":true,"persistenceEnabled":true,"marketBaseRate":5.0,"eventId":"29680182","eventTypeId":"2","numberOfWinners":1,"bettingType":"ODDS","marketType":"SET_WINNER","marketTime":"2020-02-02T00:32:00.000Z","suspendTime":"2020-02-02T00:32:00.000Z","bspReconciled":false,"complete":true,"inPlay":false,"crossMatching":true,"runnersVoidable":false,"numberOfActiveRunners":2,"betDelay":0,"status":"OPEN","runners":[{"status":"ACTIVE","sortPriority":1,"id":9712909,"name":"Felipe Meligeni Rodrigu"},{"status":"ACTIVE","sortPriority":2,"id":8326656,"name":"Thiago Monteiro"}],"regulators":["MR_INT"],"countryCode":"UY","discountAllowed":true,"timezone":"UTC","openDate":"2020-02-02T00:32:00.000Z","version":3147936873,"name":"Set 1 Winner","eventName":"Meligeni Rodrigues Alve v T Monteiro"}}]}
{"op":"mcm","clk":"1003179304","pt":1580603988440,"mc":[{"id":"1.168179122","rc":[{"batb":[[0,1.29,158.39]],"ltp":1.4,"tv":157.9,"id":8326656},{"batb":[[0,3.95,47.84]],"ltp":3.5,"tv":63.06,"id":9712909}]}]}
{"op":"mcm","clk":"1003179773","pt":1580603995663,"mc":[{"id":"1.168179122","rc":[{"batb":[[2,1.24,625]],"ltp":1.4,"tv":157.9,"id":8326656},{"batb":[[1,3.75,21.47],[2,3.45,61.22]],"ltp":3.5,"tv":63.06,"id":9712909}]}]}
{"op":"mcm","clk":"1003179967","pt":1580603998856,"mc":[{"id":"1.168179122","rc":[{"batb":[[0,1.29,156.58]],"ltp":1.4,"tv":157.9,"id":8326656}]}]}
{"op":"mcm","clk":"1003180809","pt":1580604011579,"mc":[{"id":"1.168179122","rc":[{"batb":[[0,1.3,154.77]],"ltp":1.4,"tv":157.9,"id":8326656},{"batb":[[0,3.9,49.41]],"ltp":3.5,"tv":63.06,"id":9712909}]}]}
{"op":"mcm","clk":"1003181896","pt":1580604028638,"mc":[{"id":"1.168179122","rc":[{"batb":[[0,1.3,152.88]],"ltp":1.4,"tv":157.9,"id":8326656}]}]}
{"op":"mcm","clk":"1003182536","pt":1580604038831,"mc":[{"id":"1.168179122","rc":[{"batb":[[0,1.3,150.99]],"ltp":1.4,"tv":157.9,"id":8326656},{"batb":[[0,3.85,51.22]],"ltp":3.5,"tv":63.06,"id":9712909}]}]}
{"op":"mcm","clk":"1003188972","pt":1580604144873,"mc":[{"id":"1.168179122","rc":[{"trd":[[1.3,54.95]],"batb":[[0,1.3,123.51]],"ltp":1.3,"tv":212.85,"id":8326656},{"batb":[[0,3.85,50.67]],"ltp":3.5,"tv":63.06,"id":9712909}],"tv":275.92}]}
{"op":"mcm","clk":"1003199590","pt":1580604319848,"mc":[{"id":"1.168179122","marketDefinition":{"bspMarket":false,"turnInPlayEnabled":true,"persistenceEnabled":true,"marketBaseRate":5.0,"eventId":"29680182","eventTypeId":"2","numberOfWinners":1,"bettingType":"ODDS","marketType":"SET_WINNER","marketTime":"2020-02-02T00:32:00.000Z","suspendTime":"2020-02-02T00:32:00.000Z","bspReconciled":false,"complete":true,"inPlay":true,"crossMatching":true,"runnersVoidable":false,"numberOfActiveRunners":2,"betDelay":3,"status":"OPEN","runners":[{"status":"ACTIVE","sortPriority":1,"id":9712909,"name":"Felipe Meligeni Rodrigu"},{"status":"ACTIVE","sortPriority":2,"id":8326656,"name":"Thiago Monteiro"}],"regulators":["MR_INT"],"countryCode":"UY","discountAllowed":true,"timezone":"UTC","openDate":"2020-02-02T00:32:00.000Z","version":3147941767,"name":"Set 1 Winner","eventName":"Meligeni Rodrigues Alve v T Monteiro"},"rc":[{"batb":[[0,1.01,15.51],[1,1.28,0],[2,1.24,0]],"ltp":1.3,"tv":212.85,"id":8326656},{"batb":[[0,1.83,63.08],[1,1.01,15.52],[2,3.45,0]],"ltp":3.5,"tv":63.06,"id":9712909}]}]}
{"op":"mcm","clk":"1003200280","pt":1580604330575,"mc":[{"id":"1.168179122","rc":[{"batb":[[0,1.38,112.83],[1,1.32,139.42],[2,1.01,15.51]],"ltp":1.3,"tv":212.85,"id":8326656},{"batb":[[0,3.3,37.53],[1,2.7,24.94],[2,1.83,63.08]],"ltp":3.5,"tv":63.06,"id":9712909}]}]}
{"op":"mcm","clk":"1003200485","pt":1580604333664,"mc":[{"id":"1.168179122","rc":[{"batb":[[0,1.4,428.6],[1,1.39,513.62],[2,1.38,112.83]],"batl":[[0,1.44,448.16],[1,1.45,416.25]],"ltp":1.3,"tv":212.85,"id":8326656}]}]}
{"op":"mcm","clk":"1003201454","pt":1580604349490,"mc":[{"id":"1.168179122","rc":[{"batb":[[0,1.32,139.42],[1,1.01,15.51],[2,1.38,0]],"ltp":1.3,"tv":212.85,"id":8326656},{"batb":[[0,2.7,24.94],[1,1.83,63.08],[2,1.01,15.52]],"ltp":3.5,"tv":63.06,"id":9712909}]}]}
{"op":"mcm","clk":"1003201653","pt":1580604352787,"mc":[{"id":"1.168179122","rc":[{"batb":[[0,2.72,24.47],[1,2.7,24.94],[2,1.83,63.08]],"ltp":3.5,"tv":63.06,"id":9712909}]}]}
{"op":"mcm","clk":"1003201678","pt":1580604353098,"mc":[{"id":"1.168179122","rc":[{"batb":[[1,1.83,63.08],[2,1.01,15.52]],"ltp":3.5,"tv":63.06,"id":9712909}]}]}
{"op":"mcm","clk":"1003201852","pt":1580604355776,"mc":[{"id":"1.168179122","rc":[{"batb":[[0,1.42,680.59],[1,1.41,483.83],[2,1.32,139.42]],"batl":[[0,1.47,515.4],[1,1.48,382.31]],"ltp":1.3,"tv":212.85,"id":8326656}]}]}
{"op":"mcm","clk":"1003202066","pt":1580604359320,"mc":[{"id":"1.168179122","rc":[{"batb":[[0,1.32,139.42],[1,1.01,15.51],[2,1.32,0]],"ltp":1.3,"tv":212.85,"id":8326656}]}]}
{"op":"mcm","clk":"1003202249","pt":1580604362207,"mc":[{"id":"1.168179122","rc":[{"batb":[[0,1.34,330.88],[1,1.33,634.57],[2,1.32,139.42]],"batl":[[0,1.59,308.62],[1,1.6,285.06]],"ltp":1.3,"tv":212.85,"id":8326656}]}]}
{"op":"mcm","clk":"1003202564","pt":1580604368732,"mc":[{"id":"1.168179122","rc":[{"batb":[[0,1.32,139.42],[1,1.01,15.51],[2,1.32,0]],"ltp":1.3,"tv":212.85,"id":8326656}]}]}
{"op":"mcm","clk":"1003202752","pt":1580604371818,"mc":[{"id":"1.168179122","rc":[{"batb":[[0,1.54,371.09],[1,1.53,341.51],[2,1.32,139.42]],"ltp":1.3,"tv":212.85,"id":8326656}]}]}
{"op":"mcm","clk":"1003202839","pt":1580604372793,"mc":[{"id":"1.168179122","rc":[{"batb":[[1,1.53,417.6],[2,1.43,98.27]],"ltp":1.3,"tv":212.85,"id":8326656},{"batb":[[1,2.24,41.7],[2,1.83,63.08]],"ltp":3.5,"tv":63.06,"id":9712909}]}]}
{"op":"mcm","clk":"1003203652","pt":1580604388716,"mc":[{"id":"1.168179122","rc":[{"batb":[[0,1.43,98.27],[1,1.01,15.51],[2,1.43,0]],"ltp":1.3,"tv":212.85,"id":8326656},{"batb":[[0,2.24,41.7],[1,1.83,63.08],[2,1.01,15.52]],"ltp":3.5,"tv":63.06,"id":9712909}]}]}
{"op":"mcm","clk":"1003203811","pt":1580604391441,"mc":[{"id":"1.168179122","rc":[{"batb":[[0,1.44,688.41],[1,1.43,552.81],[2,1.01,15.51]],"batl":[[0,1.83,325.72],[1,1.85,352.01]],"ltp":1.3,"tv":212.85,"id":8326656}]}]}
{"op":"mcm","clk":"1003204051","pt":1580604395837,"mc":[{"id":"1.168179122","rc":[{"batl":[[0,1.49,404.38],[1,1.5,363.18]],"ltp":1.3,"tv":212.85,"id":8326656}]}]}
{"op":"mcm","clk":"1003204105","pt":1580604396767,"mc":[{"id":"1.168179122","rc":[{"batb":[[2,1.34,128.57]],"ltp":1.3,"tv":212.85,"id":8326656},{"batb":[[0,3.05,45.01],[1,2.44,33.05],[2,1.83,63.08]],"ltp":3.5,"tv":63.06,"id":9712909}]}]}
{"op":"mcm","clk":"1003204817","pt":1580604409861,"mc":[{"id":"1.168179122","rc":[{"batb":[[0,1.34,128.57],[1,1.01,15.51],[2,1.34,0]],"ltp":1.3,"tv":212.85,"id":8326656},{"batb":[[0,2.44,33.05],[1,1.83,63.08],[2,1.01,15.52]],"ltp":3.5,"tv":63.06,"id":9712909}]}]}
{"op":"mcm","clk":"1003204978","pt":1580604412789,"mc":[{"id":"1.168179122","rc":[{"batb":[[0,1.36,374.6],[1,1.35,589.61],[2,1.34,128.57]],"batl":[[0,1.72,415.5],[1,1.74,428.47]],"ltp":1.3,"tv":212.85,"id":8326656}]}]}
{"op":"mcm","clk":"1003205659","pt":1580604423894,"mc":[{"id":"1.168179122","rc":[{"batb":[[0,1.34,128.57],[1,1.01,15.51],[2,1.34,0]],"ltp":1.3,"tv":212.85,"id":8326656}]}]}
{"op":"mcm","clk":"1003205822","pt":1580604426784,"mc":[{"id":"1.168179122","rc":[{"batb":[[0,1.65,439.08],[1,1.64,263.19],[2,1.63,60.43]],"ltp":1.3,"tv":212.85,"id":8326656},{"batb":[[0,2.46,32.18],[1,2.44,33.05],[2,2,58.54]],"ltp":3.5,"tv":63.06,"id":9712909}]}]}
{"op":"mcm","clk":"1003205867","pt":1580604427402,"mc":[{"id":"1.168179122","rc":[{"batb":[[1,2,58.54],[2,1.83,63.08]],"ltp":3.5,"tv":63.06,"id":9712909}]}]}
{"op":"mcm","clk":"1003206721","pt":1580604443725,"mc":[{"id":"1.168179122","rc":[{"batb":[[0,1.5,82.07],[1,1.01,15.51],[2,1.63,0]],"ltp":1.3,"tv":212.85,"id":8326656},{"batb":[[0,2,58.54],[1,1.83,63.08],[2,1.01,15.52]],"ltp":3.5,"tv":63.06,"id":9712909}]}]}
{"op":"mcm","clk":"1003206842","pt":1580604446404,"mc":[{"id":"1.168179122","rc":[{"batb":[[0,1.52,491.93],[1,1.51,360.53],[2,1.5,82.07]],"batl":[[0,2.06,203.84],[1,2.08,247.48]],"ltp":1.3,"tv":212.85,"id":8326656}]}]}
{"op":"mcm","clk":"1003206874","pt":1580604447126,"mc":[{"id":"1.168179122","rc":[{"batb":[[0,1.5,82.07],[1,1.01,15.51],[2,1.5,0]],"ltp":1.3,"tv":212.85,"id":8326656}]}]}
{"op":"mcm","clk":"1003207052","pt":1580604450632,"mc":[{"id":"1.168179122","rc":[{"batb":[[0,1.71,296.77],[1,1.69,469.6],[2,1.5,82.07]],"batl":[[0,1.78,395.13],[1,1.8,383.79]],"ltp":1.3,"tv":212.85,"id":8326656}]}]}
{"op":"mcm","clk":"1003207268","pt":1580604454538,"mc":[{"id":"1.168179122","rc":[{"batb":[[0,1.5,82.07],[1,1.01,15.51],[2,1.5,0]],"ltp":1.3,"tv":212.85,"id":8326656}]}]}
{"op":"mcm","clk":"1003207432","pt":1580604457418,"mc":[{"id":"1.168179122","rc":[{"batb":[[0,1.52,470.86],[1,1.51,360.52],[2,1.5,82.07]],"batl":[[0,2.06,220.05],[1,2.08,247.51]],"ltp":1.3,"tv":212.85,"id":8326656}]}]}
{"op":"mcm","clk":"1003208869","pt":1580604483682,"mc":[{"id":"1.168179122","rc":[{"batl":[[0,1.57,280],[1,1.58,298.71]],"ltp":1.3,"tv":212.85,"id":8326656}]}]}
{"op":"mcm","clk":"1003208942","pt":1580604484668,"mc":[{"id":"1.168179122","rc":[{"batb":[[0,2.82,22.35],[1,2.04,1004.43],[2,1.83,63.08]],"ltp":3.5,"tv":63.06,"id":9712909}]}]}
{"op":"mcm","clk":"1003209600","pt":1580604496703,"mc":[{"id":"1.168179122","rc":[{"batb":[[0,1.52,311.24]],"ltp":1.3,"tv":212.85,"id":8326656}]}]}
{"op":"mcm","clk":"1003209746","pt":1580604499587,"mc":[{"id":"1.168179122","rc":[{"batl":[[0,1.57,434.58]],"ltp":1.3,"tv":212.85,"id":8326656}]}]}
{"op":"mcm","clk":"1003210049","pt":1580604504692,"mc":[{"id":"1.168179122","rc":[{"batb":[[0,1.5,82.07],[1,1.35,126.84],[2,1.01,15.51]],"ltp":1.3,"tv":212.85,"id":8326656},{"batb":[[1,2.04,55.31]],"ltp":3.5,"tv":63.06,"id":9712909}]}]}
{"op":"mcm","clk":"1003210088","pt":1580604505569,"mc":[{"id":"1.168179122","rc":[{"batb":[[0,1.35,126.84],[1,1.01,15.51],[2,1.01,0]],"ltp":1.3,"tv":212.85,"id":8326656},{"batb":[[0,2.04,55.31],[1,1.83,63.08],[2,1.01,15.52]],"ltp":3.5,"tv":63.06,"id":9712909}]}]}
{"op":"mcm","clk":"1003210193","pt":1580604507676,"mc":[{"id":"1.168179122","rc":[{"batb":[[0,1.36,591.75],[1,1.35,721.46],[2,1.01,15.51]],"batl":[[0,2.04,313.69],[1,2.06,254.89]],"ltp":1.3,"tv":212.85,"id":8326656}]}]}
{"op":"mcm","clk":"1003211682","pt":1580604532735,"mc":[{"id":"1.168179122","rc":[{"batb":[[0,1.35,126.84],[1,1.01,15.51],[2,1.01,0]],"ltp":1.3,"tv":212.85,"id":8326656}]}]}
{"op":"mcm","clk":"1003211868","pt":1580604535611,"mc":[{"id":"1.168179122","rc":[{"batb":[[0,1.95,245.37],[1,1.93,303.97],[2,1.35,126.84]],"ltp":1.3,"tv":212.85,"id":8326656}]}]}
{"op":"mcm","clk":"1003211933","pt":1580604536642,"mc":[{"id":"1.168179122","rc":[{"batb":[[2,1.89,36.82]],"ltp":1.3,"tv":212.85,"id":8326656},{"batb":[[1,1.87,36.12],[2,1.83,63.08]],"ltp":3.5,"tv":63.06,"id":9712909}]}]}
{"op":"mcm","clk":"1003213062","pt":1580604553567,"mc":[{"id":"1.168179122","rc":[{"trd":[[2.04,30]],"batb":[[0,2.04,40.31]],"ltp":2.04,"tv":93.06,"id":9712909}],"tv":305.92}]}
{"op":"mcm","clk":"1003214107","pt":1580604570371,"mc":[{"id":"1.168179122","rc":[{"batb":[[0,1.89,36.82],[1,1.69,52.24],[2,1.41,1269.45]],"ltp":1.3,"tv":212.85,"id":8326656}]}]}
{"op":"mcm","clk":"1003214314","pt":1580604573256,"mc":[{"id":"1.168179122","rc":[{"trd":[[2.04,110.62]],"batb":[[0,1.87,36.12],[1,1.83,63.08],[2,1.01,15.52]],"ltp":2.04,"tv":173.69,"id":9712909}],"tv":386.54}]}
{"op":"mcm","clk":"1003214601","pt":1580604577377,"mc":[{"id":"1.168179122","rc":[{"batb":[[2,1.81,252.55]],"batl":[[0,2.34,330.29],[1,2.38,343.69]],"ltp":2.04,"tv":173.69,"id":9712909}]}]}
{"op":"mcm","clk":"1003215286","pt":1580604586784,"mc":[{"id":"1.168179122","rc":[{"batb":[[0,1.69,52.24],[1,1.01,15.51],[2,1.41,0]],"ltp":1.3,"tv":212.85,"id":8326656}]}]}
{"op":"mcm","clk":"1003215524","pt":1580604589875,"mc":[{"id":"1.168179122","rc":[{"batb":[[0,1.72,50.28]],"ltp":1.3,"tv":212.85,"id":8326656},{"batb":[[0,1.84,37.53]],"ltp":2.04,"tv":173.69,"id":9712909}]}]}
{"op":"mcm","clk":"1003216743","pt":1580604607918,"mc":[{"id":"1.168179122","rc":[{"batb":[[2,1.01,15.52]],"ltp":2.04,"tv":173.69,"id":9712909}]}]}
{"op":"mcm","clk":"1003216986","pt":1580604610809,"mc":[{"id":"1.168179122","rc":[{"batb":[[0,1.75,368.08],[1,1.73,434.06],[2,1.72,50.28]],"batl":[[0,1.82,241.93],[1,1.84,358.81]],"ltp":1.3,"tv":212.85,"id":8326656}]}]}
{"op":"mcm","clk":"1003217060","pt":1580604611836,"mc":[{"id":"1.168179122","rc":[{"batb":[[0,2.28,39.58],[1,2.04,55.16],[2,1.83,63.08]],"ltp":2.04,"tv":173.69,"id":9712909}]}]}
{"op":"mcm","clk":"1003218072","pt":1580604626731,"mc":[{"id":"1.168179122","rc":[{"batb":[[0,1.53,75.69],[1,1.5,426.9],[2,1.01,15.51]],"ltp":1.3,"tv":212.85,"id":8326656},{"batb":[[0,2.04,55.16],[1,1.83,63.08],[2,1.77,402.27]],"ltp":2.04,"tv":173.69,"id":9712909}]}]}
{"op":"mcm","clk":"1003218241","pt":1580604629656,"mc":[{"id":"1.168179122","rc":[{"batb":[[0,1.56,413.99],[1,1.55,325.25],[2,1.53,75.69]],"batl":[[0,2.02,418.08],[1,2.04,262.29]],"ltp":1.3,"tv":212.85,"id":8326656}]}]}
{"op":"mcm","clk":"1003218518","pt":1580604633621,"mc":[{"id":"1.168179122","rc":[{"batl":[[0,1.75,2.27],[1,2.02,418.08],[2,2.04,262.29]],"ltp":1.3,"tv":212.85,"id":8326656}]}]}
{"op":"mcm","clk":"1003218703","pt":1580604636446,"mc":[{"id":"1.168179122","rc":[{"batb":[[0,1.53,75.69],[1,1.5,426.9],[2,1.01,15.51]],"ltp":1.3,"tv":212.85,"id":8326656}]}]}
{"op":"mcm","clk":"1003218808","pt":1580604638039,"mc":[{"id":"1.168179122","rc":[{"batb":[[1,1.01,15.51],[2,1.01,0]],"ltp":1.3,"tv":212.85,"id":8326656}]}]}
{"op":"mcm","clk":"1003218877","pt":1580604639229,"mc":[{"id":"1.168179122","rc":[{"trd":[[1.75,4.54]],"batb":[[0,1.92,322.69],[1,1.9,319.39],[2,1.53,75.69]],"batl":[[0,2.02,418.08],[1,2.04,262.29],[2,2.04,0]],"ltp":1.75,"tv":217.39,"id":8326656}],"tv":391.08}]}
{"op":"mcm","clk":"1003218972","pt":1580604640765,"mc":[{"id":"1.168179122","rc":[{"batb":[[2,1.89,36.9]],"ltp":1.75,"tv":217.39,"id":8326656},{"batb":[[1,1.84,37.53],[2,1.83,63.08]],"ltp":2.04,"tv":173.69,"id":9712909}]}]}
{"op":"mcm","clk":"1003219614","pt":1580604650841,"mc":[{"id":"1.168179122","rc":[{"trd":[[1.92,4.54]],"batb":[[0,1.92,320.42]],"ltp":1.92,"tv":221.93,"id":8326656}],"tv":395.62}]}
{"op":"mcm","clk":"1003219834","pt":1580604654147,"mc":[{"id":"1.168179122","rc":[{"batb":[[0,1.92,271.07]],"ltp":1.92,"tv":221.93,"id":8326656}]}]}
{"op":"mcm","clk":"1003219920","pt":1580604655294,"mc":[{"id":"1.168179122","rc":[{"batb":[[0,1.66,55.94],[1,1.58,416.47],[2,1.01,15.51]],"ltp":1.92,"tv":221.93,"id":8326656},{"batb":[[0,1.84,37.53],[1,1.83,63.08],[2,1.77,402.27]],"ltp":2.04,"tv":173.69,"id":9712909}]}]}
{"op":"mcm","clk":"1003220090","pt":1580604658357,"mc":[{"id":"1.168179122","rc":[{"batb":[[0,1.69,332.09],[1,1.67,490.61],[2,1.66,55.94]],"batl":[[0,2.24,338.33],[1,2.26,196.24]],"ltp":1.92,"tv":221.93,"id":8326656}]}]}
{"op":"mcm","clk":"1003220319","pt":1580604662164,"mc":[{"id":"1.168179122","rc":[{"batb":[[2,1.01,15.52]],"ltp":2.04,"tv":173.69,"id":9712909}]}]}
{"op":"mcm","clk":"1003220435","pt":1580604663864,"mc":[{"id":"1.168179122","rc":[{"batl":[[0,1.76,412.33],[1,1.78,398.5]],"ltp":1.92,"tv":221.93,"id":8326656}]}]}
{"op":"mcm","clk":"1003220500","pt":1580604664791,"mc":[{"id":"1.168179122","rc":[{"batb":[[0,2.38,35.09],[1,2.06,52.24],[2,1.83,63.08]],"ltp":2.04,"tv":173.69,"id":9712909}]}]}
{"op":"mcm","clk":"1003220568","pt":1580604665769,"mc":[{"id":"1.168179122","rc":[{"batb":[[2,1.86,398.62]],"ltp":2.04,"tv":173.69,"id":9712909}]}]}
{"op":"mcm","clk":"1003221635","pt":1580604682803,"mc":[{"id":"1.168179122","rc":[{"batb":[[0,1.47,89.93],[1,1.44,436.18],[2,1.01,15.51]],"ltp":1.92,"tv":221.93,"id":8326656},{"batb":[[0,2.06,52.24],[1,1.86,398.62],[2,1.83,63.08]],"ltp":2.04,"tv":173.69,"id":9712909}]}]}
{"op":"mcm","clk":"1003222090","pt":1580604688701,"mc":[{"id":"1.168179122","rc":[{"batb":[[0,1.64,429.7],[1,1.63,269.53],[2,1.47,89.93]],"batl":[[0,1.71,456.43],[1,1.73,437.33]],"ltp":1.92,"tv":221.93,"id":8326656}]}]}
{"op":"mcm","clk":"1003222405","pt":1580604692425,"mc":[{"id":"1.168179122","rc":[{"batb":[[0,1.47,89.93],[1,1.44,436.18],[2,1.01,15.51]],"ltp":1.92,"tv":221.93,"id":8326656}]}]}
{"op":"mcm","clk":"1003222667","pt":1580604695527,"mc":[{"id":"1.168179122","rc":[{"batb":[[0,1.48,395.97],[1,1.47,492.38],[2,1.44,436.18]],"batl":[[0,1.97,283.21],[1,1.99,282.27]],"ltp":1.92,"tv":221.93,"id":8326656}]}]}
{"op":"mcm","clk":"1003222937","pt":1580604699341,"mc":[{"id":"1.168179122","rc":[{"batb":[[2,1.01,15.51]],"ltp":1.92,"tv":221.93,"id":8326656},{"batb":[[1,1.83,63.08],[2,1.01,15.52]],"ltp":2.04,"tv":173.69,"id":9712909}]}]}
{"op":"mcm","clk":"1003223047","pt":1580604700844,"mc":[{"id":"1.168179122","rc":[{"batl":[[0,1.53,501.34],[1,1.54,327.98]],"ltp":1.92,"tv":221.93,"id":8326656},{"batb":[[0,2.18,938.86],[1,2.06,52.24],[2,1.83,63.08]],"ltp":2.04,"tv":173.69,"id":9712909}]}]}
{"op":"mcm","clk":"1003223070","pt":1580604701204,"mc":[{"id":"1.168179122","rc":[{"batb":[[2,1.33,138.64]],"ltp":1.92,"tv":221.93,"id":8326656},{"batb":[[0,2.94,50.44],[1,2.56,29.11]],"ltp":2.04,"tv":173.69,"id":9712909}]}]}
{"op":"mcm","clk":"1003223208","pt":1580604703217,"mc":[{"id":"1.168179122","rc":[{"batb":[[2,2.12,388.65]],"ltp":2.04,"tv":173.69,"id":9712909}]}]}
{"op":"mcm","clk":"1003224264","pt":1580604719837,"mc":[{"id":"1.168179122","rc":[{"batb":[[0,1.47,492.38],[1,1.33,138.64],[2,1.31,477.51]],"batl":[[0,1.53,338.38],[1,1.54,0]],"ltp":1.92,"tv":221.93,"id":8326656}]}]}
{"op":"mcm","clk":"1003224381","pt":1580604721545,"mc":[{"id":"1.168179122","rc":[{"batb":[[0,1.33,138.64],[1,1.31,477.51],[2,1.01,15.51]],"ltp":1.92,"tv":221.93,"id":8326656},{"batb":[[0,2.56,29.11],[1,2.12,388.65],[2,1.83,63.08]],"ltp":2.04,"tv":173.69,"id":9712909}]}]}
{"op":"mcm","clk":"1003224578","pt":1580604724742,"mc":[{"id":"1.168179122","rc":[{"batb":[[0,1.33,827.81],[1,1.32,813.32],[2,1.31,477.51]],"batl":[[0,1.66,378.46],[1,1.68,484.78]],"ltp":1.92,"tv":221.93,"id":8326656},{"batb":[[0,2.58,28.33]],"ltp":2.04,"tv":173.69,"id":9712909}]}]}
{"op":"mcm","clk":"1003224858","pt":1580604728775,"mc":[{"id":"1.168179122","rc":[{"batb":[[2,1.01,15.51]],"ltp":1.92,"tv":221.93,"id":8326656},{"batb":[[1,1.83,63.08],[2,1.01,15.52]],"ltp":2.04,"tv":173.69,"id":9712909}]}]}
{"op":"mcm","clk":"1003224927","pt":1580604729860,"mc":[{"id":"1.168179122","rc":[{"batl":[[0,1.37,514.65],[1,1.38,519.13]],"ltp":1.92,"tv":221.93,"id":8326656}]}]}
{"op":"mcm","clk":"1003224979","pt":1580604730580,"mc":[{"id":"1.168179122","rc":[{"batb":[[2,1.28,170.27]],"ltp":1.92,"tv":221.93,"id":8326656},{"batb":[[0,3.75,27.54],[1,3.1,42.65],[2,1.83,63.08]],"ltp":2.04,"tv":173.69,"id":9712909}]}]}
{"op":"mcm","clk":"1003225083","pt":1580604732077,"mc":[{"id":"1.168179122","rc":[{"batb":[[2,2.3,385.09]],"ltp":2.04,"tv":173.69,"id":9712909}]}]}
{"op":"mcm","clk":"1003225247","pt":1580604734858,"mc":[{"id":"1.168179122","rc":[{"trd":[[1.37,1035.94]],"batb":[[0,1.33,636.26],[1,1.32,141.71]],"batl":[[0,1.38,519.13],[1,1.38,0]],"ltp":1.37,"tv":1257.87,"id":8326656},{"trd":[[3.75,2.42]],"batb":[[0,3.75,25.11]],"ltp":3.75,"tv":176.11,"id":9712909}],"tv":1433.99}]}
{"op":"mcm","clk":"1003225438","pt":1580604737765,"mc":[{"id":"1.168179122","rc":[{"batb":[[0,1.34,380.13],[1,1.33,636.26],[2,1.32,141.71]],"batl":[[0,1.37,327.09],[1,1.38,519.13]],"ltp":1.37,"tv":1257.87,"id":8326656}]}]}
{"op":"mcm","clk":"1003226586","pt":1580604755814,"mc":[{"id":"1.168179122","rc":[{"batb":[[0,1.28,170.27],[1,1.25,505.09],[2,1.01,15.51]],"ltp":1.37,"tv":1257.87,"id":8326656},{"batb":[[0,3.1,42.65],[1,2.3,385.09],[2,1.83,63.08]],"ltp":3.75,"tv":176.11,"id":9712909}]}]}
{"op":"mcm","clk":"1003226607","pt":1580604756177,"mc":[{"id":"1.168179122","rc":[{"batb":[[0,1.28,169.87]],"ltp":1.37,"tv":1257.87,"id":8326656}]}]}
{"op":"mcm","clk":"1003226954","pt":1580604761895,"mc":[{"id":"1.168179122","rc":[{"batb":[[0,1.35,832.4],[1,1.34,618.85],[2,1.28,169.87]],"batl":[[0,1.39,359.58],[1,1.4,486.05]],"ltp":1.37,"tv":1257.87,"id":8326656}]}]}
{"op":"mcm","clk":"1003227166","pt":1580604765204,"mc":[{"id":"1.168179122","rc":[{"batb":[[0,1.28,169.87],[1,1.25,505.09],[2,1.01,15.51]],"ltp":1.37,"tv":1257.87,"id":8326656}]}]}
{"op":"mcm","clk":"1003227358","pt":1580604768088,"mc":[{"id":"1.168179122","rc":[{"batb":[[0,1.29,824.12],[1,1.28,959.27],[2,1.25,505.09]],"batl":[[0,1.48,606.91],[1,1.49,371.87]],"ltp":1.37,"tv":1257.87,"id":8326656}]}]}
{"op":"mcm","clk":"1003228035","pt":1580604776742,"mc":[{"id":"1.168179122","rc":[{"batb":[[0,1.28,169.87],[1,1.25,505.09],[2,1.01,15.51]],"ltp":1.37,"tv":1257.87,"id":8326656}]}]}
{"op":"mcm","clk":"1003228161","pt":1580604778698,"mc":[{"id":"1.168179122","rc":[{"batb":[[1,1.01,15.51],[2,1.01,0]],"ltp":1.37,"tv":1257.87,"id":8326656},{"batb":[[1,1.83,63.08],[2,1.01,15.52]],"ltp":3.75,"tv":176.11,"id":9712909}]}]}
{"op":"mcm","clk":"1003228251","pt":1580604779832,"mc":[{"id":"1.168179122","rc":[{"batb":[[0,1.43,527.94],[1,1.42,467.88],[2,1.28,169.87]],"ltp":1.37,"tv":1257.87,"id":8326656}]}]}
{"op":"mcm","clk":"1003228286","pt":1580604780348,"mc":[{"id":"1.168179122","rc":[{"batb":[[1,1.42,569.93],[2,1.34,131.79]],"ltp":1.37,"tv":1257.87,"id":8326656},{"batb":[[1,2.58,28.17],[2,1.83,63.08]],"ltp":3.75,"tv":176.11,"id":9712909}]}]}
{"op":"mcm","clk":"1003228438","pt":1580604782648,"mc":[{"id":"1.168179122","rc":[{"batb":[[2,1.34,595.48]],"ltp":1.37,"tv":1257.87,"id":8326656},{"batb":[[2,2.04,395.32]],"ltp":3.75,"tv":176.11,"id":9712909}]}]}
{"op":"mcm","clk":"1003229656","pt":1580604801332,"mc":[{"id":"1.168179122","rc":[{"batb":[[0,1.34,595.48],[1,1.01,15.51],[2,1.34,0]],"ltp":1.37,"tv":1257.87,"id":8326656},{"batb":[[0,2.58,28.17],[1,2.04,395.32],[2,1.83,63.08]],"ltp":3.75,"tv":176.11,"id":9712909}]}]}
{"op":"mcm","clk":"1003229865","pt":1580604804480,"mc":[{"id":"1.168179122","rc":[{"batb":[[0,1.36,392.29],[1,1.35,590.73],[2,1.34,595.48]],"batl":[[0,1.65,338.07],[1,1.66,250.16]],"ltp":1.37,"tv":1257.87,"id":8326656}]}]}
{"op":"mcm","clk":"1003230001","pt":1580604806656,"mc":[{"id":"1.168179122","rc":[{"batl":[[0,1.42,279.78],[1,1.65,338.07],[2,1.66,250.16]],"ltp":1.37,"tv":1257.87,"id":8326656}]}]}
{"op":"mcm","clk":"1003230448","pt":1580604813677,"mc":[{"id":"1.168179122","rc":[{"batl":[[0,1.65,338.07],[1,1.66,250.16],[2,1.66,0]],"ltp":1.37,"tv":1257.87,"id":8326656}]}]}
{"op":"mcm","clk":"1003230637","pt":1580604816769,"mc":[{"id":"1.168179122","rc":[{"trd":[[1.36,561.42]],"batb":[[0,1.36,112.51]],"ltp":1.36,"tv":1817.44,"id":8326656}],"tv":1993.55}]}
{"op":"mcm","clk":"1003230679","pt":1580604817592,"mc":[{"id":"1.168179122","rc":[{"batb":[[0,1.35,590.73],[1,1.34,131.79],[2,1.01,15.51]],"ltp":1.36,"tv":1817.44,"id":8326656},{"batb":[[1,1.83,63.08],[2,1.01,15.52]],"ltp":3.75,"tv":176.11,"id":9712909}]}]}
{"op":"mcm","clk":"1003230757","pt":1580604818879,"mc":[{"id":"1.168179122","rc":[{"batl":[[0,1.4,487.7]],"ltp":1.36,"tv":1817.44,"id":8326656}]}]}
{"op":"mcm","clk":"1003230814","pt":1580604819799,"mc":[{"id":"1.168179122","rc":[{"batb":[[2,1.29,163.42]],"ltp":1.36,"tv":1817.44,"id":8326656},{"batb":[[0,3.6,30.45],[1,2.92,50.75],[2,1.83,63.08]],"ltp":3.75,"tv":176.11,"id":9712909}]}]}
{"op":"mcm","clk":"1003230831","pt":1580604820108,"mc":[{"id":"1.168179122","rc":[{"batb":[[0,1.35,875.33],[1,1.34,752.71]],"batl":[[0,1.39,325.19],[1,1.4,487.7]],"ltp":1.36,"tv":1817.44,"id":8326656}]}]}
{"op":"mcm","clk":"1003230938","pt":1580604821905,"mc":[{"id":"1.168179122","rc":[{"batb":[[2,2.22,385.54]],"ltp":3.75,"tv":176.11,"id":9712909}]}]}
{"op":"mcm","clk":"1003231978","pt":1580604838638,"mc":[{"id":"1.168179122","rc":[{"batb":[[0,1.29,163.42],[1,1.28,484.09],[2,1.01,15.51]],"ltp":1.36,"tv":1817.44,"id":8326656},{"batb":[[0,2.92,50.75],[1,2.22,385.54],[2,1.83,63.08]],"ltp":3.75,"tv":176.11,"id":9712909}]}]}
{"op":"mcm","clk":"1003232217","pt":1580604842616,"mc":[{"id":"1.168179122","rc":[{"batb":[[1,1.01,15.51],[2,1.01,0]],"ltp":1.36,"tv":1817.44,"id":8326656}]}]}
{"op":"mcm","clk":"1003232295","pt":1580604843849,"mc":[{"id":"1.168179122","rc":[{"batb":[[0,1.38,453.94],[1,1.37,552.18],[2,1.29,163.42]],"batl":[[0,1.42,535.93],[1,1.43,442.41]],"ltp":1.36,"tv":1817.44,"id":8326656}]}]}
{"op":"mcm","clk":"1003232440","pt":1580604846015,"mc":[{"id":"1.168179122","rc":[{"batb":[[2,1.31,475.73]],"ltp":1.36,"tv":1817.44,"id":8326656}]}]}
{"op":"mcm","clk":"1003232648","pt":1580604848843,"mc":[{"id":"1.168179122","rc":[{"batb":[[0,1.31,475.73],[1,1.29,163.42],[2,1.01,15.51]],"ltp":1.36,"tv":1817.44,"id":8326656}]}]}
{"op":"mcm","clk":"1003232797","pt":1580604851621,"mc":[{"id":"1.168179122","rc":[{"batb":[[1,1.3,442.04],[2,1.29,914.37]],"batl":[[0,1.53,437.3],[1,1.54,328.78]],"ltp":1.36,"tv":1817.44,"id":8326656}]}]}
{"op":"mcm","clk":"1003233152","pt":1580604858767,"mc":[{"id":"1.168179122","rc":[{"batb":[[0,1.3,442.04],[1,1.29,914.37],[2,1.01,15.51]],"ltp":1.36,"tv":1817.44,"id":8326656}]}]}
{"op":"mcm","clk":"1003233201","pt":1580604859850,"mc":[{"id":"1.168179122","rc":[{"batb":[[2,1.24,197.41]],"batl":[[0,1.33,513.75],[1,1.34,595.8],[2,1.37,195.77]],"ltp":1.36,"tv":1817.44,"id":8326656},{"batb":[[0,4,45.71],[1,3.4,34.15],[2,2.92,50.75]],"ltp":3.75,"tv":176.11,"id":9712909}]}]}
{"op":"mcm","clk":"1003233251","pt":1580604860834,"mc":[{"id":"1.168179122","rc":[{"batb":[[2,1.83,63.08]],"ltp":3.75,"tv":176.11,"id":9712909}]}]}
{"op":"mcm","clk":"1003233351","pt":1580604863150,"mc":[{"id":"1.168179122","rc":[{"batb":[[2,2.42,382.58]],"ltp":3.75,"tv":176.11,"id":9712909}]}]}
{"op":"mcm","clk":"1003233821","pt":1580604872179,"mc":[{"id":"1.168179122","rc":[{"batl":[[2,1.37,0]],"ltp":1.36,"tv":1817.44,"id":8326656}]}]}
{"op":"mcm","clk":"1003234025","pt":1580604875792,"mc":[{"id":"1.168179122","rc":[{"trd":[[1.3,446.49]],"batb":[[0,1.3,246.27]],"ltp":1.3,"tv":2208.97,"id":8326656}],"tv":2385.09}]}
{"op":"mcm","clk":"1003234219","pt":1580604878676,"mc":[{"id":"1.168179122","rc":[{"batb":[[0,1.3,365.14]],"batl":[[0,1.33,588.97]],"ltp":1.3,"tv":2208.97,"id":8326656}]}]}
{"op":"mcm","clk":"1003234334","pt":1580604880371,"mc":[{"id":"1.168179122","rc":[{"batb":[[0,1.24,195.21],[1,1.22,521.26],[2,1.01,15.51]],"ltp":1.3,"tv":2208.97,"id":8326656},{"batb":[[0,3.4,34.15],[1,2.42,382.58],[2,1.83,63.08]],"ltp":3.75,"tv":176.11,"id":9712909}]}]}
{"op":"mcm","clk":"1003234547","pt":1580604883872,"mc":[{"id":"1.168179122","rc":[{"batb":[[0,1.26,545.38],[1,1.25,904.96],[2,1.24,195.21]],"batl":[[0,1.42,631.01],[1,1.43,442.3]],"ltp":1.3,"tv":2208.97,"id":8326656}]}]}
{"op":"mcm","clk":"1003235315","pt":1580604898792,"mc":[{"id":"1.168179122","rc":[{"batl":[[0,1.29,741.31],[1,1.3,692.38]],"ltp":1.3,"tv":2208.97,"id":8326656}]}]}
{"op":"mcm","clk":"1003235375","pt":1580604899722,"mc":[{"id":"1.168179122","rc":[{"batb":[[0,4.5,35.33],[1,4,46.26],[2,2.42,382.58]],"ltp":3.75,"tv":176.11,"id":9712909}]}]}
{"op":"mcm","clk":"1003236647","pt":1580604924806,"mc":[{"id":"1.168179122","rc":[{"batb":[[0,1.22,736.92],[1,1.01,15.51],[2,1.24,0]],"ltp":1.3,"tv":2208.97,"id":8326656},{"batb":[[0,4,46.26],[1,2.42,382.58],[2,1.83,63.08]],"ltp":3.75,"tv":176.11,"id":9712909}]}]}
{"op":"mcm","clk":"1003236785","pt":1580604927831,"mc":[{"id":"1.168179122","rc":[{"batb":[[0,1.24,758.02],[1,1.23,1005.97],[2,1.22,736.92]],"batl":[[0,1.33,751.56],[1,1.34,593.47]],"ltp":1.3,"tv":2208.97,"id":8326656}]}]}
{"op":"mcm","clk":"1003236926","pt":1580604930854,"mc":[{"id":"1.168179122","rc":[{"batb":[[2,1.22,215.67]],"ltp":1.3,"tv":2208.97,"id":8326656},{"batb":[[1,1.83,63.08],[2,1.01,15.52]],"ltp":3.75,"tv":176.11,"id":9712909}]}]}
{"op":"mcm","clk":"1003236999","pt":1580604932858,"mc":[{"id":"1.168179122","rc":[{"batl":[[0,1.27,747.43],[1,1.28,752.7]],"ltp":1.3,"tv":2208.97,"id":8326656},{"batb":[[0,4.8,30.45],[1,4.1,42.88],[2,1.83,63.08]],"ltp":3.75,"tv":176.11,"id":9712909}]}]}
{"op":"mcm","clk":"1003237050","pt":1580604934558,"mc":[{"id":"1.168179122","rc":[{"batb":[[2,2.62,378.35]],"ltp":3.75,"tv":176.11,"id":9712909}]}]}
{"op":"mcm","clk":"1003238162","pt":1580604958803,"mc":[{"id":"1.168179122","rc":[{"batb":[[1,1.23,1217.47]],"ltp":1.3,"tv":2208.97,"id":8326656},{"batb":[[1,4.7,31.39],[2,4.1,42.88]],"ltp":3.75,"tv":176.11,"id":9712909}]}]}
{"op":"mcm","clk":"1003238205","pt":1580604959791,"mc":[{"id":"1.168179122","rc":[{"batb":[[2,1.18,547.68]],"ltp":1.3,"tv":2208.97,"id":8326656},{"batb":[[0,4.7,31.39],[1,4.1,42.88],[2,2.62,378.35]],"ltp":3.75,"tv":176.11,"id":9712909}]}]}
{"op":"mcm","clk":"1003241178","pt":1580605007643,"mc":[{"id":"1.168179122","rc":[{"batb":[[0,1.18,547.68],[1,1.17,288.45],[2,1.01,15.51]],"ltp":1.3,"tv":2208.97,"id":8326656},{"batb":[[0,4.1,42.88],[1,2.62,378.35],[2,1.83,63.08]],"ltp":3.75,"tv":176.11,"id":9712909}]}]}
{"op":"mcm","clk":"1003241368","pt":1580605010884,"mc":[{"id":"1.168179122","rc":[{"batb":[[0,1.18,2171.06],[1,1.17,999.48]],"batl":[[0,1.32,697],[1,1.33,616.73]],"ltp":1.3,"tv":2208.97,"id":8326656}]}]}
{"op":"mcm","clk":"1003241686","pt":1580605015255,"mc":[{"id":"1.168179122","rc":[{"batb":[[0,1.18,547.68],[1,1.17,288.45]],"ltp":1.3,"tv":2208.97,"id":8326656}]}]}
{"op":"mcm","clk":"1003241791","pt":1580605016689,"mc":[{"id":"1.168179122","rc":[{"batb":[[0,1.17,288.45],[1,1.01,15.51],[2,1.01,0]],"ltp":1.3,"tv":2208.97,"id":8326656}]}]}
{"op":"mcm","clk":"1003241859","pt":1580605017868,"mc":[{"id":"1.168179122","rc":[{"batb":[[0,1.29,325.32],[1,1.28,783.65],[2,1.17,288.45]],"ltp":1.3,"tv":2208.97,"id":8326656}]}]}
{"op":"mcm","clk":"1003241913","pt":1580605018792,"mc":[{"id":"1.168179122","rc":[{"batb":[[1,1.28,951.09],[2,1.22,219.05]],"ltp":1.3,"tv":2208.97,"id":8326656},{"batb":[[1,3.7,28.56],[2,2.62,378.35]],"ltp":3.75,"tv":176.11,"id":9712909}]}]}
{"op":"mcm","clk":"1003242017","pt":1580605020481,"mc":[{"id":"1.168179122","rc":[{"batb":[[2,1.22,742.05]],"ltp":1.3,"tv":2208.97,"id":8326656}]}]}
{"op":"mcm","clk":"1003242654","pt":1580605030799,"mc":[{"id":"1.168179122","rc":[{"batb":[[0,1.22,742.05],[1,1.01,15.51],[2,1.22,0]],"ltp":1.3,"tv":2208.97,"id":8326656},{"batb":[[0,3.7,28.56],[1,2.62,378.35],[2,1.83,63.08]],"ltp":3.75,"tv":176.11,"id":9712909}]}]}
{"op":"mcm","clk":"1003242893","pt":1580605034694,"mc":[{"id":"1.168179122","rc":[{"batb":[[0,1.23,1033.37],[1,1.22,1810.94],[2,1.01,15.51]],"batl":[[0,1.37,812.08],[1,1.38,515.76]],"ltp":1.3,"tv":2208.97,"id":8326656}]}]}
{"op":"mcm","clk":"1003242983","pt":1580605036381,"mc":[{"id":"1.168179122","rc":[{"batb":[[0,1.22,742.05],[1,1.01,15.51],[2,1.01,0]],"ltp":1.3,"tv":2208.97,"id":8326656}]}]}
{"op":"mcm","clk":"1003243025","pt":1580605037201,"mc":[{"id":"1.168179122","rc":[{"batb":[[0,1.22,219.05]],"ltp":1.3,"tv":2208.97,"id":8326656}]}]}
{"op":"mcm","clk":"1003243113","pt":1580605038790,"mc":[{"id":"1.168179122","rc":[{"batb":[[0,1.33,503.38],[1,1.32,666.46],[2,1.22,219.05]],"ltp":1.3,"tv":2208.97,"id":8326656}]}]}
{"op":"mcm","clk":"1003243167","pt":1580605039719,"mc":[{"id":"1.168179122","rc":[{"batb":[[0,1.33,641.39],[2,1.28,167.75]],"ltp":1.3,"tv":2208.97,"id":8326656},{"batb":[[1,3.4,35.17],[2,2.62,378.35]],"ltp":3.75,"tv":176.11,"id":9712909}]}]}
{"op":"mcm","clk":"1003243826","pt":1580605052547,"mc":[{"id":"1.168179122","rc":[{"batb":[[0,1.28,167.75],[1,1.25,505.09],[2,1.01,15.51]],"ltp":1.3,"tv":2208.97,"id":8326656},{"batb":[[0,3.4,35.17],[1,2.62,378.35],[2,1.83,63.08]],"ltp":3.75,"tv":176.11,"id":9712909}]}]}
{"op":"mcm","clk":"1003244040","pt":1580605055732,"mc":[{"id":"1.168179122","rc":[{"batb":[[0,1.29,343.63],[1,1.28,951.71],[2,1.25,505.09]],"batl":[[0,1.4,456.33],[1,1.41,472.28]],"ltp":1.3,"tv":2208.97,"id":8326656}]}]}
{"op":"mcm","clk":"1003244160","pt":1580605057736,"mc":[{"id":"1.168179122","rc":[{"batb":[[0,1.28,167.75],[1,1.25,505.09],[2,1.01,15.51]],"ltp":1.3,"tv":2208.97,"id":8326656}]}]}
{"op":"mcm","clk":"1003244261","pt":1580605059534,"mc":[{"id":"1.168179122","rc":[{"batb":[[1,1.01,15.51],[2,1.01,0]],"ltp":1.3,"tv":2208.97,"id":8326656},{"batb":[[1,1.83,63.08],[2,1.01,15.52]],"ltp":3.75,"tv":176.11,"id":9712909}]}]}
{"op":"mcm","clk":"1003244305","pt":1580605060353,"mc":[{"id":"1.168179122","rc":[{"batb":[[0,1.36,669.52],[1,1.35,597.07],[2,1.28,167.75]],"ltp":1.3,"tv":2208.97,"id":8326656}]}]}
{"op":"mcm","clk":"1003244397","pt":1580605061639,"mc":[{"id":"1.168179122","rc":[{"batb":[[0,1.37,118.57],[1,1.36,669.52],[2,1.35,597.07]],"ltp":1.3,"tv":2208.97,"id":8326656},{"batb":[[1,3.2,39.97],[2,1.83,63.08]],"ltp":3.75,"tv":176.11,"id":9712909}]}]}
{"op":"mcm","clk":"1003244438","pt":1580605062513,"mc":[{"id":"1.168179122","rc":[{"batb":[[2,2.22,384.52]],"ltp":3.75,"tv":176.11,"id":9712909}]}]}
{"op":"mcm","clk":"1003244914","pt":1580605072463,"mc":[{"id":"1.168179122","rc":[{"batb":[[0,1.34,134.94],[1,1.28,485.89],[2,1.01,15.51]],"ltp":1.3,"tv":2208.97,"id":8326656},{"batb":[[0,3.2,39.97],[1,2.22,384.52],[2,1.83,63.08]],"ltp":3.75,"tv":176.11,"id":9712909}]}]}
{"op":"mcm","clk":"1003245086","pt":1580605075176,"mc":[{"id":"1.168179122","rc":[{"batb":[[0,1.34,454.42],[1,1.33,638.4],[2,1.28,485.89]],"batl":[[0,1.42,356.84],[1,1.43,445.28]],"ltp":1.3,"tv":2208.97,"id":8326656}]}]}
{"op":"mcm","clk":"1003246331","pt":1580605097684,"mc":[{"id":"1.168179122","rc":[{"batb":[[0,1.34,134.94],[1,1.28,485.89],[2,1.01,15.51]],"ltp":1.3,"tv":2208.97,"id":8326656}]}]}
{"op":"mcm","clk":"1003248391","pt":1580605135627,"mc":[{"id":"1.168179122","rc":[{"batb":[[1,1.29,163.58],[2,1.28,485.89]],"ltp":1.3,"tv":2208.97,"id":8326656},{"batb":[[0,3.65,29.51],[1,3.35,35.56],[2,3.2,39.97]],"ltp":3.75,"tv":176.11,"id":9712909}]}]}
{"op":"mcm","clk":"1003248418","pt":1580605136140,"mc":[{"id":"1.168179122","rc":[{"batb":[[2,2.22,384.52]],"ltp":3.75,"tv":176.11,"id":9712909}]}]}
{"op":"mcm","clk":"1003248663","pt":1580605140547,"mc":[{"id":"1.168179122","rc":[{"trd":[[1.34,223.5]],"batb":[[0,1.34,23.19]],"ltp":1.34,"tv":2432.47,"id":8326656}],"tv":2608.59}]}
{"op":"mcm","clk":"1003248908","pt":1580605144870,"mc":[{"id":"1.168179122","rc":[{"batb":[[0,1.34,352.85],[1,1.33,638.42],[2,1.29,163.58]],"batl":[[0,1.37,381.94],[1,1.38,520.93]],"ltp":1.34,"tv":2432.47,"id":8326656}]}]}
{"op":"mcm","clk":"1003249299","pt":1580605152383,"mc":[{"id":"1.168179122","rc":[{"batb":[[0,1.29,163.58],[1,1.28,485.89],[2,1.01,15.51]],"ltp":1.34,"tv":2432.47,"id":8326656},{"batb":[[0,3.35,35.56],[1,2.22,384.52],[2,1.83,63.08]],"ltp":3.75,"tv":176.11,"id":9712909}]}]}
{"op":"mcm","clk":"1003249331","pt":1580605152945,"mc":[{"id":"1.168179122","rc":[{"batl":[[0,3.7,10]],"ltp":3.75,"tv":176.11,"id":9712909}]}]}
{"op":"mcm","clk":"1003249455","pt":1580605154858,"mc":[{"id":"1.168179122","rc":[{"batb":[[0,1.29,1158.2],[1,1.28,1281.93],[2,1.27,172.79]],"batl":[[0,1.41,565.55],[1,1.42,456.7]],"ltp":1.34,"tv":2432.47,"id":8326656},{"batb":[[0,3.45,32.89],[1,3.35,35.56],[2,2.22,384.52]],"ltp":3.75,"tv":176.11,"id":9712909}]}]}
{"op":"mcm","clk":"1003249503","pt":1580605155680,"mc":[{"id":"1.168179122","rc":[{"batb":[[0,1.29,994.62]],"ltp":1.34,"tv":2432.47,"id":8326656},{"batb":[[1,2.22,384.52],[2,1.83,63.08]],"ltp":3.75,"tv":176.11,"id":9712909}]}]}
{"op":"mcm","clk":"1003249852","pt":1580605162662,"mc":[{"id":"1.168179122","rc":[{"trd":[[3.45,20]],"batb":[[0,3.45,22.89]],"ltp":3.45,"tv":196.11,"id":9712909}],"tv":2628.59}]}
{"op":"mcm","clk":"1003250163","pt":1580605168763,"mc":[{"id":"1.168179122","rc":[{"batb":[[0,1.28,485.89],[1,1.27,172.79],[2,1.01,15.51]],"ltp":1.34,"tv":2432.47,"id":8326656}]}]}
{"op":"mcm","clk":"1003250325","pt":1580605171586,"mc":[{"id":"1.168179122","rc":[{"batb":[[0,1.37,486.73],[1,1.36,573.54],[2,1.28,485.89]],"batl":[[0,1.41,565.54],[1,1.42,456.69]],"ltp":1.34,"tv":2432.47,"id":8326656}]}]}
{"op":"mcm","clk":"1003250384","pt":1580605172507,"mc":[{"id":"1.168179122","rc":[{"batb":[[1,1.36,697.15],[2,1.3,150.2]],"ltp":1.34,"tv":2432.47,"id":8326656},{"batb":[[1,2.88,21.24],[2,2.22,384.52]],"ltp":3.45,"tv":196.11,"id":9712909}]}]}
{"op":"mcm","clk":"1003250642","pt":1580605177084,"mc":[{"id":"1.168179122","rc":[{"trd":[[3.45,55.37]],"batb":[[0,3.45,5.2]],"ltp":3.45,"tv":231.48,"id":9712909}],"tv":2663.96}]}
{"op":"mcm","clk":"1003251507","pt":1580605193745,"mc":[{"id":"1.168179122","rc":[{"batb":[[0,1.3,150.2],[1,1.28,485.89],[2,1.01,15.51]],"ltp":1.34,"tv":2432.47,"id":8326656},{"batb":[[0,2.88,21.24],[1,2.22,384.52],[2,1.83,63.08]],"ltp":3.45,"tv":231.48,"id":9712909}]}]}
{"op":"mcm","clk":"1003251605","pt":1580605195897,"mc":[{"id":"1.168179122","rc":[{"batb":[[0,1.31,148.32],[1,1.3,150.2],[2,1.28,485.89]],"ltp":1.34,"tv":2432.47,"id":8326656}]}]}
{"op":"mcm","clk":"1003251652","pt":1580605196822,"mc":[{"id":"1.168179122","rc":[{"batb":[[0,1.32,454.43],[1,1.31,840.85]],"batl":[[0,1.53,326.94],[1,1.54,329.85]],"ltp":1.34,"tv":2432.47,"id":8326656}]}]}
{"op":"mcm","clk":"1003252661","pt":1580605211478,"mc":[{"id":"1.168179122","rc":[{"batb":[[0,1.31,148.32],[1,1.28,485.89],[2,1.01,15.51]],"ltp":1.34,"tv":2432.47,"id":8326656}]}]}
{"op":"mcm","clk":"1003252735","pt":1580605212769,"mc":[{"id":"1.168179122","rc":[{"batb":[[1,1.01,15.51],[2,1.01,0]],"ltp":1.34,"tv":2432.47,"id":8326656}]}]}
{"op":"mcm","clk":"1003252864","pt":1580605214672,"mc":[{"id":"1.168179122","rc":[{"batb":[[0,1.39,562.24],[1,1.38,535.5],[2,1.31,148.32]],"batl":[[0,1.43,384.25],[1,1.44,431.57]],"ltp":1.34,"tv":2432.47,"id":8326656}]}]}
{"op":"mcm","clk":"1003252979","pt":1580605216897,"mc":[{"id":"1.168179122","rc":[{"batb":[[0,1.31,622.6],[1,1.01,15.51],[2,1.31,0]],"ltp":1.34,"tv":2432.47,"id":8326656}]}]}
{"op":"mcm","clk":"1003253146","pt":1580605219785,"mc":[{"id":"1.168179122","rc":[{"batb":[[0,1.32,455.91],[1,1.31,1315.13],[2,1.01,15.51]],"batl":[[0,1.53,325.66],[1,1.54,329.85]],"ltp":1.34,"tv":2432.47,"id":8326656}]}]}
{"op":"mcm","clk":"1003253661","pt":1580605226800,"mc":[{"id":"1.168179122","rc":[{"batb":[[1,1.31,840.85]],"ltp":1.34,"tv":2432.47,"id":8326656},{"batb":[[1,1.83,63.08],[2,1.01,15.52]],"ltp":3.45,"tv":231.48,"id":9712909}]}]}
{"op":"mcm","clk":"1003253780","pt":1580605228817,"mc":[{"id":"1.168179122","rc":[{"batb":[[2,1.27,172.31]],"batl":[[0,1.35,375.56],[1,1.36,557.68]],"ltp":1.34,"tv":2432.47,"id":8326656},{"batb":[[0,3.8,52.48],[1,3.25,38.32],[2,1.83,63.08]],"ltp":3.45,"tv":231.48,"id":9712909}]}]}
{"op":"mcm","clk":"1003253933","pt":1580605230920,"mc":[{"id":"1.168179122","rc":[{"batb":[[2,2.38,383.94]],"ltp":3.45,"tv":231.48,"id":9712909}]}]}
{"op":"mcm","clk":"1003254197","pt":1580605234631,"mc":[{"id":"1.168179122","rc":[{"batl":[[2,1.5,67.89]],"ltp":1.34,"tv":2432.47,"id":8326656}]}]}
{"op":"mcm","clk":"1003254748","pt":1580605243442,"mc":[{"id":"1.168179122","rc":[{"batb":[[0,1.27,172.31],[1,1.23,513.22],[2,1.01,15.51]],"ltp":1.34,"tv":2432.47,"id":8326656},{"batb":[[0,3.25,38.32],[1,2.38,383.94],[2,1.83,63.08]],"ltp":3.45,"tv":231.48,"id":9712909}]}]}
{"op":"mcm","clk":"1003255061","pt":1580605247725,"mc":[{"id":"1.168179122","rc":[{"batb":[[1,1.01,15.51],[2,1.01,0]],"ltp":1.34,"tv":2432.47,"id":8326656}]}]}
{"op":"mcm","clk":"1003255184","pt":1580605249732,"mc":[{"id":"1.168179122","rc":[{"batb":[[0,1.33,743.24],[1,1.32,669.75],[2,1.27,172.31]],"batl":[[0,1.37,590.56],[1,1.38,518.25]],"ltp":1.34,"tv":2432.47,"id":8326656}]}]}
{"op":"mcm","clk":"1003255483","pt":1580605253653,"mc":[{"id":"1.168179122","rc":[{"batb":[[0,1.27,172.31],[1,1.25,501.85],[2,1.01,15.51]],"ltp":1.34,"tv":2432.47,"id":8326656}]}]}
{"op":"mcm","clk":"1003255741","pt":1580605256847,"mc":[{"id":"1.168179122","rc":[{"batb":[[0,1.28,855.61],[1,1.27,1002.35],[2,1.25,501.85]],"batl":[[0,1.44,634.93],[1,1.45,416.96]],"ltp":1.34,"tv":2432.47,"id":8326656}]}]}
{"op":"mcm","clk":"1003256130","pt":1580605262864,"mc":[{"id":"1.168179122","rc":[{"batb":[[2,1.01,15.51]],"ltp":1.34,"tv":2432.47,"id":8326656}]}]}
{"op":"mcm","clk":"1003256217","pt":1580605263850,"mc":[{"id":"1.168179122","rc":[{"batl":[[0,1.32,927.92],[1,1.33,612.97]],"ltp":1.34,"tv":2432.47,"id":8326656}]}]}
{"op":"mcm","clk":"1003256291","pt":1580605264777,"mc":[{"id":"1.168179122","rc":[{"batb":[[2,1.25,193.95]],"ltp":1.34,"tv":2432.47,"id":8326656},{"batb":[[0,4.1,42.41],[1,3.75,27.38],[2,2.38,383.94]],"ltp":3.45,"tv":231.48,"id":9712909}]}]}
{"op":"mcm","clk":"1003256684","pt":1580605270795,"mc":[{"id":"1.168179122","rc":[{"batl":[[2,1.51,73.68]],"ltp":1.34,"tv":2432.47,"id":8326656}]}]}
{"op":"mcm","clk":"1003256940","pt":1580605274579,"mc":[{"id":"1.168179122","rc":[{"trd":[[4.1,5.11]],"batb":[[0,4.1,39.86]],"ltp":4.1,"tv":236.59,"id":9712909}],"tv":2669.07}]}
{"op":"mcm","clk":"1003257656","pt":1580605285894,"mc":[{"id":"1.168179122","rc":[{"batb":[[0,1.25,193.95],[1,1.22,519.89],[2,1.01,15.51]],"ltp":1.34,"tv":2432.47,"id":8326656},{"batb":[[0,3.75,27.38],[1,2.38,383.94],[2,1.83,63.08]],"ltp":4.1,"tv":236.59,"id":9712909}]}]}
{"op":"mcm","clk":"1003257812","pt":1580605288622,"mc":[{"id":"1.168179122","rc":[{"batb":[[0,1.26,857.19],[1,1.25,1106.35],[2,1.22,519.89]],"batl":[[0,1.36,441.34],[1,1.37,538.12]],"ltp":1.34,"tv":2432.47,"id":8326656},{"batb":[[1,3.7,27.85],[2,2.38,383.94]],"ltp":4.1,"tv":236.59,"id":9712909}]}]}
{"op":"mcm","clk":"1003257837","pt":1580605288922,"mc":[{"id":"1.168179122","rc":[{"batb":[[1,1.25,1104.31]],"ltp":1.34,"tv":2432.47,"id":8326656},{"batb":[[0,3.7,27.85],[1,2.38,383.94],[2,1.83,63.08]],"ltp":4.1,"tv":236.59,"id":9712909}]}]}
{"op":"mcm","clk":"1003258669","pt":1580605301021,"mc":[{"id":"1.168179122","rc":[{"batb":[[1,1.83,63.08],[2,1.01,15.52]],"ltp":4.1,"tv":236.59,"id":9712909}]}]}
{"op":"mcm","clk":"1003258782","pt":1580605302614,"mc":[{"id":"1.168179122","rc":[{"batl":[[0,1.29,455.62],[1,1.3,697.98]],"ltp":1.34,"tv":2432.47,"id":8326656}]}]}
{"op":"mcm","clk":"1003258868","pt":1580605303794,"mc":[{"id":"1.168179122","rc":[{"batb":[[2,1.23,204.02]],"ltp":1.34,"tv":2432.47,"id":8326656},{"batb":[[0,4.4,36.27],[1,4.1,44.3],[2,1.83,63.08]],"ltp":4.1,"tv":236.59,"id":9712909}]}]}
{"op":"mcm","clk":"1003258941","pt":1580605305126,"mc":[{"id":"1.168179122","rc":[{"batb":[[2,2.52,382.89]],"ltp":4.1,"tv":236.59,"id":9712909}]}]}
{"op":"mcm","clk":"1003259299","pt":1580605309761,"mc":[{"id":"1.168179122","rc":[{"batl":[[2,1.46,2537.62]],"ltp":1.34,"tv":2432.47,"id":8326656}]}]}
{"op":"mcm","clk":"1003259862","pt":1580605316726,"mc":[{"id":"1.168179122","rc":[{"batb":[[0,1.25,912.4],[1,1.23,204.02],[2,1.22,519.89]],"ltp":1.34,"tv":2432.47,"id":8326656},{"batb":[[0,4.1,44.3],[1,2.52,382.89],[2,1.83,63.08]],"ltp":4.1,"tv":236.59,"id":9712909}]}]}
{"op":"mcm","clk":"1003260100","pt":1580605319356,"mc":[{"id":"1.168179122","rc":[{"batb":[[1,1.24,959.64],[2,1.23,204.02]],"batl":[[0,1.31,331.87],[1,1.32,646.91]],"ltp":1.34,"tv":2432.47,"id":8326656}]}]}
{"op":"mcm","clk":"1003260449","pt":1580605323756,"mc":[{"id":"1.168179122","rc":[{"batl":[[0,1.28,495.19],[1,1.29,726.63]],"ltp":1.34,"tv":2432.47,"id":8326656},{"batb":[[0,4.6,33.05],[1,4.1,44.3],[2,4,47.21]],"ltp":4.1,"tv":236.59,"id":9712909}]}]}
{"op":"mcm","clk":"1003261846","pt":1580605343702,"mc":[{"id":"1.168179122","rc":[{"batb":[[1,4,47.21],[2,2.52,382.89]],"ltp":4.1,"tv":236.59,"id":9712909}]}]}
{"op":"mcm","clk":"1003262143","pt":1580605347673,"mc":[{"id":"1.168179122","rc":[{"batl":[[2,1.43,54.13]],"ltp":1.34,"tv":2432.47,"id":8326656}]}]}
{"op":"mcm","clk":"1003262780","pt":1580605356821,"mc":[{"id":"1.168179122","rc":[{"batb":[[1,1.24,1162.88],[2,1.18,545.77]],"ltp":1.34,"tv":2432.47,"id":8326656},{"batb":[[1,3.95,47.52]],"ltp":4.1,"tv":236.59,"id":9712909}]}]}
{"op":"mcm","clk":"1003265370","pt":1580605396878,"mc":[{"id":"1.168179122","rc":[{"trd":[[1.25,10.61]],"batb":[[0,1.18,545.77],[1,1.17,286.24],[2,1.01,15.51]],"ltp":1.25,"tv":2443.08,"id":8326656},{"batb":[[0,3.95,47.52],[1,2.52,382.89],[2,1.83,63.08]],"ltp":4.1,"tv":236.59,"id":9712909}],"tv":2679.68}]}
{"op":"mcm","clk":"1003265542","pt":1580605399254,"mc":[{"id":"1.168179122","rc":[{"batb":[[0,1.19,883.54],[1,1.18,1895.3],[2,1.17,286.24]],"batl":[[0,1.34,760.57],[1,1.35,572.67]],"ltp":1.25,"tv":2443.08,"id":8326656}]}]}
{"op":"mcm","clk":"1003265898","pt":1580605405074,"mc":[{"id":"1.168179122","rc":[{"batb":[[0,1.18,545.77],[1,1.17,286.24],[2,1.01,15.51]],"ltp":1.25,"tv":2443.08,"id":8326656}]}]}
{"op":"mcm","clk":"1003266127","pt":1580605407873,"mc":[{"id":"1.168179122","rc":[{"batb":[[0,1.17,286.24],[1,1.01,15.51],[2,1.01,0]],"ltp":1.25,"tv":2443.08,"id":8326656}]}]}
{"op":"mcm","clk":"1003266197","pt":1580605408864,"mc":[{"id":"1.168179122","rc":[{"batb":[[0,1.3,825.8],[1,1.29,918.93],[2,1.23,211.89]],"ltp":1.25,"tv":2443.08,"id":8326656},{"batb":[[1,3.55,31.08],[2,2.52,382.89]],"ltp":4.1,"tv":236.59,"id":9712909}]}]}
{"op":"mcm","clk":"1003266906","pt":1580605418687,"mc":[{"id":"1.168179122","rc":[{"batb":[[0,1.23,211.89],[1,1.22,523],[2,1.01,15.51]],"ltp":1.25,"tv":2443.08,"id":8326656},{"batb":[[0,3.55,31.08],[1,2.52,382.89],[2,1.83,63.08]],"ltp":4.1,"tv":236.59,"id":9712909}]}]}
{"op":"mcm","clk":"1003267326","pt":1580605424406,"mc":[{"id":"1.168179122","rc":[{"batb":[[0,1.29,671.37],[1,1.28,790.6],[2,1.23,211.89]],"batl":[[0,1.32,376.37],[1,1.33,622.12]],"ltp":1.25,"tv":2443.08,"id":8326656}]}]}
{"op":"mcm","clk":"1003267429","pt":1580605426311,"mc":[{"id":"1.168179122","rc":[{"batb":[[0,1.23,211.89],[1,1.22,523],[2,1.01,15.51]],"ltp":1.25,"tv":2443.08,"id":8326656}]}]}
{"op":"mcm","clk":"1003267638","pt":1580605429615,"mc":[{"id":"1.168179122","rc":[{"batb":[[0,1.24,1032.73],[1,1.23,1225.74],[2,1.22,523]],"batl":[[0,1.39,635.04],[1,1.4,485.74]],"ltp":1.25,"tv":2443.08,"id":8326656}]}]}
{"op":"mcm","clk":"1003268679","pt":1580605445149,"mc":[{"id":"1.168179122","rc":[{"batb":[[0,1.23,211.89],[1,1.22,523],[2,1.01,15.51]],"ltp":1.25,"tv":2443.08,"id":8326656}]}]}
{"op":"mcm","clk":"1003268854","pt":1580605447810,"mc":[{"id":"1.168179122","rc":[{"batb":[[1,1.01,15.51],[2,1.01,0]],"ltp":1.25,"tv":2443.08,"id":8326656}]}]}
{"op":"mcm","clk":"1003268921","pt":1580605448740,"mc":[{"id":"1.168179122","rc":[{"batb":[[0,1.35,676.03],[1,1.34,618.3],[2,1.29,159.17]],"ltp":1.25,"tv":2443.08,"id":8326656},{"batb":[[1,3.3,37.3],[2,2.52,382.89]],"ltp":4.1,"tv":236.59,"id":9712909}]}]}
{"op":"mcm","clk":"1003270450","pt":1580605469552,"mc":[{"id":"1.168179122","rc":[{"batb":[[0,1.29,159.17],[1,1.25,505.09],[2,1.01,15.51]],"ltp":1.25,"tv":2443.08,"id":8326656},{"batb":[[0,3.3,37.3],[1,2.52,382.89],[2,1.83,63.08]],"ltp":4.1,"tv":236.59,"id":9712909}]}]}
{"op":"mcm","clk":"1003270649","pt":1580605472131,"mc":[{"id":"1.168179122","rc":[{"batb":[[0,1.3,814.14],[1,1.29,918.78],[2,1.25,505.09]],"batl":[[0,1.43,638.21],[1,1.44,429.94]],"ltp":1.25,"tv":2443.08,"id":8326656}]}]}
{"op":"mcm","clk":"1003271333","pt":1580605480568,"mc":[{"id":"1.168179122","rc":[{"batb":[[0,1.29,159.17],[1,1.25,505.09],[2,1.01,15.51]],"ltp":1.25,"tv":2443.08,"id":8326656}]}]}
{"op":"mcm","clk":"1003271486","pt":1580605482683,"mc":[{"id":"1.168179122","rc":[{"batb":[[1,1.01,15.51],[2,1.01,0]],"ltp":1.25,"tv":2443.08,"id":8326656},{"batb":[[1,1.83,63.08],[2,1.01,15.52]],"ltp":4.1,"tv":236.59,"id":9712909}]}]}
{"op":"mcm","clk":"1003271559","pt":1580605483667,"mc":[{"id":"1.168179122","rc":[{"batb":[[0,1.38,828.47],[1,1.37,558.21],[2,1.29,159.17]],"ltp":1.25,"tv":2443.08,"id":8326656}]}]}
{"op":"mcm","clk":"1003271620","pt":1580605484393,"mc":[{"id":"1.168179122","rc":[{"batb":[[0,1.39,113.38],[1,1.38,828.47],[2,1.37,558.21]],"ltp":1.25,"tv":2443.08,"id":8326656},{"batb":[[1,3.15,42.41],[2,1.83,63.08]],"ltp":4.1,"tv":236.59,"id":9712909}]}]}
{"op":"mcm","clk":"1003271779","pt":1580605486565,"mc":[{"id":"1.168179122","rc":[{"batb":[[2,2.12,388.65]],"ltp":4.1,"tv":236.59,"id":9712909}]}]}
{"op":"mcm","clk":"1003272439","pt":1580605495791,"mc":[{"id":"1.168179122","rc":[{"batb":[[0,1.35,129.67],[1,1.31,477.51],[2,1.01,15.51]],"ltp":1.25,"tv":2443.08,"id":8326656},{"batb":[[0,3.15,42.41],[1,2.12,388.65],[2,1.83,63.08]],"ltp":4.1,"tv":236.59,"id":9712909}]}]}
{"op":"mcm","clk":"1003272817","pt":1580605500682,"mc":[{"id":"1.168179122","rc":[{"batb":[[0,1.38,525.55],[1,1.37,554.72],[2,1.35,129.67]],"batl":[[0,1.42,474.39],[1,1.43,444.45]],"ltp":1.25,"tv":2443.08,"id":8326656}]}]}
{"op":"mcm","clk":"1003272970","pt":1580605502718,"mc":[{"id":"1.168179122","rc":[{"batb":[[0,1.35,129.67],[1,1.31,477.51],[2,1.01,15.51]],"ltp":1.25,"tv":2443.08,"id":8326656}]}]}
{"op":"mcm","clk":"1003273178","pt":1580605505614,"mc":[{"id":"1.168179122","rc":[{"batb":[[0,1.36,425.39],[1,1.35,723.87],[2,1.31,477.51]],"batl":[[0,1.45,515.37],[1,1.46,406.68]],"ltp":1.25,"tv":2443.08,"id":8326656}]}]}
{"op":"mcm","clk":"1003273585","pt":1580605510723,"mc":[{"id":"1.168179122","rc":[{"batl":[[0,1.4,683.87],[1,1.41,470.06]],"ltp":1.25,"tv":2443.08,"id":8326656}]}]}
{"op":"mcm","clk":"1003273657","pt":1580605511703,"mc":[{"id":"1.168179122","rc":[{"batb":[[0,3.55,31.16],[1,3.25,38],[2,3.2,27.62]],"ltp":4.1,"tv":236.59,"id":9712909}]}]}
{"op":"mcm","clk":"1003273667","pt":1580605511907,"mc":[{"id":"1.168179122","rc":[{"batb":[[2,2.12,388.65]],"ltp":4.1,"tv":236.59,"id":9712909}]}]}
{"op":"mcm","clk":"1003274686","pt":1580605525620,"mc":[{"id":"1.168179122","rc":[{"batb":[[0,1.31,477.51],[1,1.3,156.34],[2,1.01,15.51]],"ltp":1.25,"tv":2443.08,"id":8326656},{"batb":[[0,3.25,38],[1,2.12,388.65],[2,1.83,63.08]],"ltp":4.1,"tv":236.59,"id":9712909}]}]}
{"op":"mcm","clk":"1003274886","pt":1580605528402,"mc":[{"id":"1.168179122","rc":[{"batb":[[0,1.31,1263.02],[1,1.3,883.65]],"batl":[[0,1.44,713.53],[1,1.45,416.5]],"ltp":1.25,"tv":2443.08,"id":8326656}]}]}
{"op":"mcm","clk":"1003275318","pt":1580605534635,"mc":[{"id":"1.168179122","rc":[{"batb":[[0,1.31,785.51]],"ltp":1.25,"tv":2443.08,"id":8326656},{"batb":[[1,1.83,63.08],[2,1.01,15.52]],"ltp":4.1,"tv":236.59,"id":9712909}]}]}
{"op":"mcm","clk":"1003275468","pt":1580605536645,"mc":[{"id":"1.168179122","rc":[{"batb":[[2,1.21,231.56]],"batl":[[0,1.35,710.71],[1,1.36,553.33]],"ltp":1.25,"tv":2443.08,"id":8326656},{"batb":[[0,3.95,48.7],[1,3.4,33.99],[2,3.25,38]],"ltp":4.1,"tv":236.59,"id":9712909}]}]}
{"op":"mcm","clk":"1003275525","pt":1580605537422,"mc":[{"id":"1.168179122","rc":[{"batb":[[2,1.83,63.08]],"ltp":4.1,"tv":236.59,"id":9712909}]}]}
{"op":"mcm","clk":"1003275586","pt":1580605538245,"mc":[{"id":"1.168179122","rc":[{"batb":[[2,1.23,516.48]],"ltp":1.25,"tv":2443.08,"id":8326656},{"batb":[[2,2.38,382.3]],"ltp":4.1,"tv":236.59,"id":9712909}]}]}
{"op":"mcm","clk":"1003276939","pt":1580605557580,"mc":[{"id":"1.168179122","rc":[{"batb":[[0,1.23,516.48],[1,1.21,231.56],[2,1.01,15.51]],"ltp":1.25,"tv":2443.08,"id":8326656},{"batb":[[0,3.4,33.99],[1,2.38,382.3],[2,1.83,63.08]],"ltp":4.1,"tv":236.59,"id":9712909}]}]}
{"op":"mcm","clk":"1003277122","pt":1580605560358,"mc":[{"id":"1.168179122","rc":[{"batb":[[0,1.23,1387.62],[1,1.22,1064.28],[2,1.21,231.56]],"batl":[[0,1.42,468.95],[1,1.43,443.96]],"ltp":1.25,"tv":2443.08,"id":8326656}]}]}
{"op":"mcm","clk":"1003277941","pt":1580605571652,"mc":[{"id":"1.168179122","rc":[{"trd":[[3.4,4]],"batb":[[0,3.4,31.99]],"ltp":3.4,"tv":240.59,"id":9712909}],"tv":2683.68}]}
{"op":"mcm","clk":"1003278971","pt":1580605585301,"mc":[{"id":"1.168179122","rc":[{"batb":[[0,1.23,516.48],[1,1.21,231.56],[2,1.01,15.51]],"ltp":1.25,"tv":2443.08,"id":8326656}]}]}
{"op":"mcm","clk":"1003279319","pt":1580605589891,"mc":[{"id":"1.168179122","rc":[{"batb":[[0,1.21,231.56],[1,1.01,15.51],[2,1.01,0]],"ltp":1.25,"tv":2443.08,"id":8326656}]}]}
{"op":"mcm","clk":"1003279390","pt":1580605590818,"mc":[{"id":"1.168179122","rc":[{"batb":[[0,1.37,121.33],[1,1.31,148.24],[2,1.21,231.56]],"ltp":1.25,"tv":2443.08,"id":8326656},{"batb":[[1,2.8,22.9],[2,2.38,382.3]],"ltp":3.4,"tv":240.59,"id":9712909}]}]}
{"op":"mcm","clk":"1003279440","pt":1580605591385,"mc":[{"id":"1.168179122","rc":[{"batb":[[0,1.38,529.28],[1,1.37,675.75],[2,1.31,148.24]],"batl":[[0,1.42,469.2],[1,1.43,444.2]],"ltp":1.25,"tv":2443.08,"id":8326656}]}]}
{"op":"mcm","clk":"1003280187","pt":1580605601333,"mc":[{"id":"1.168179122","rc":[{"trd":[[1.38,200]],"batb":[[0,1.38,429.28]],"ltp":1.38,"tv":2643.08,"id":8326656}],"tv":2883.68}]}
{"op":"mcm","clk":"1003280442","pt":1580605604861,"mc":[{"id":"1.168179122","rc":[{"batb":[[0,1.31,147.76],[1,1.28,485.89],[2,1.01,15.51]],"ltp":1.38,"tv":2643.08,"id":8326656},{"batb":[[0,2.8,22.9],[1,2.38,382.3],[2,1.83,63.08]],"ltp":3.4,"tv":240.59,"id":9712909}]}]}
{"op":"mcm","clk":"1003280741","pt":1580605608909,"mc":[{"id":"1.168179122","rc":[{"batb":[[1,1.01,15.51],[2,1.01,0]],"ltp":1.38,"tv":2643.08,"id":8326656}]}]}
{"op":"mcm","clk":"1003280873","pt":1580605610810,"mc":[{"id":"1.168179122","rc":[{"batb":[[0,1.4,720.18],[1,1.39,520.36],[2,1.31,147.76]],"batl":[[0,1.45,608.74],[1,1.46,406.25]],"ltp":1.38,"tv":2643.08,"id":8326656}]}]}
{"op":"mcm","clk":"1003280997","pt":1580605612713,"mc":[{"id":"1.168179122","rc":[{"batb":[[2,1.31,625.27]],"ltp":1.38,"tv":2643.08,"id":8326656}]}]}
{"op":"mcm","clk":"1003281068","pt":1580605613740,"mc":[{"id":"1.168179122","rc":[{"batb":[[0,1.31,625.27],[1,1.01,15.51],[2,1.31,0]],"ltp":1.38,"tv":2643.08,"id":8326656}]}]}
{"op":"mcm","clk":"1003281280","pt":1580605617246,"mc":[{"id":"1.168179122","rc":[{"batb":[[0,1.32,707.98],[1,1.31,1322.71],[2,1.01,15.51]],"batl":[[0,1.57,526.26],[1,1.58,299.35]],"ltp":1.38,"tv":2643.08,"id":8326656}]}]}
{"op":"mcm","clk":"1003281973","pt":1580605626834,"mc":[{"id":"1.168179122","rc":[{"batb":[[1,1.31,845.2]],"ltp":1.38,"tv":2643.08,"id":8326656}]}]}
{"op":"mcm","clk":"1003282042","pt":1580605627866,"mc":[{"id":"1.168179122","rc":[{"batb":[[2,1.27,174.12]],"batl":[[0,1.36,701.57],[1,1.37,535.28]],"ltp":1.38,"tv":2643.08,"id":8326656},{"batb":[[0,3.8,26.36],[1,3.2,40.13],[2,2.84,954.97]],"ltp":3.4,"tv":240.59,"id":9712909}]}]}
{"op":"mcm","clk":"1003282072","pt":1580605628274,"mc":[{"id":"1.168179122","rc":[{"batb":[[2,2.38,382.3]],"ltp":3.4,"tv":240.59,"id":9712909}]}]}
{"op":"mcm","clk":"1003283545","pt":1580605650676,"mc":[{"id":"1.168179122","rc":[{"batb":[[0,1.27,174.12],[1,1.23,516.48],[2,1.01,15.51]],"ltp":1.38,"tv":2643.08,"id":8326656},{"batb":[[0,3.2,40.13],[1,2.38,382.3],[2,1.83,63.08]],"ltp":3.4,"tv":240.59,"id":9712909}]}]}
{"op":"mcm","clk":"1003283768","pt":1580605653874,"mc":[{"id":"1.168179122","rc":[{"batb":[[0,1.28,920.03],[1,1.27,1006.16],[2,1.23,516.48]],"batl":[[0,1.45,385.79],[1,1.46,408.15]],"ltp":1.38,"tv":2643.08,"id":8326656}]}]}
{"op":"mcm","clk":"1003283816","pt":1580605654705,"mc":[{"id":"1.168179122","rc":[{"batb":[[0,1.27,174.12],[1,1.23,516.48],[2,1.01,15.51]],"ltp":1.38,"tv":2643.08,"id":8326656}]}]}
{"op":"mcm","clk":"1003283844","pt":1580605655067,"mc":[{"id":"1.168179122","rc":[{"batb":[[1,1.01,15.51],[2,1.01,0]],"ltp":1.38,"tv":2643.08,"id":8326656}]}]}
{"op":"mcm","clk":"1003283994","pt":1580605657287,"mc":[{"id":"1.168179122","rc":[{"batb":[[0,1.34,461.77],[1,1.33,641.1],[2,1.27,174.12]],"batl":[[0,1.38,780.05],[1,1.39,500]],"ltp":1.38,"tv":2643.08,"id":8326656}]}]}
{"op":"mcm","clk":"1003284208","pt":1580605660580,"mc":[{"id":"1.168179122","rc":[{"batb":[[0,1.27,174.12],[1,1.25,505.09],[2,1.01,15.51]],"ltp":1.38,"tv":2643.08,"id":8326656}]}]}
{"op":"mcm","clk":"1003284405","pt":1580605663599,"mc":[{"id":"1.168179122","rc":[{"batb":[[0,1.28,920.03],[1,1.27,1006.16],[2,1.25,505.09]],"batl":[[0,1.45,385.79],[1,1.46,408.15]],"ltp":1.38,"tv":2643.08,"id":8326656}]}]}
{"op":"mcm","clk":"1003284675","pt":1580605667118,"mc":[{"id":"1.168179122","rc":[{"batb":[[2,1.01,15.51]],"ltp":1.38,"tv":2643.08,"id":8326656},{"batb":[[1,1.83,63.08],[2,1.01,15.52]],"ltp":3.4,"tv":240.59,"id":9712909}]}]}
{"op":"mcm","clk":"1003284800","pt":1580605668819,"mc":[{"id":"1.168179122","rc":[{"batl":[[0,1.32,871.01],[1,1.33,614.44]],"ltp":1.38,"tv":2643.08,"id":8326656}]}]}
{"op":"mcm","clk":"1003284877","pt":1580605669797,"mc":[{"id":"1.168179122","rc":[{"batb":[[2,1.25,192.53]],"ltp":1.38,"tv":2643.08,"id":8326656},{"batb":[[0,4.2,41.78],[1,3.7,28.17],[2,1.83,63.08]],"ltp":3.4,"tv":240.59,"id":9712909}]}]}
{"op":"mcm","clk":"1003284987","pt":1580605671336,"mc":[{"id":"1.168179122","rc":[{"batb":[[2,2.52,381.46]],"ltp":3.4,"tv":240.59,"id":9712909}]}]}
{"op":"mcm","clk":"1003286228","pt":1580605688759,"mc":[{"id":"1.168179122","rc":[{"batb":[[0,1.25,192.53],[1,1.2,530.86],[2,1.01,15.51]],"ltp":1.38,"tv":2643.08,"id":8326656},{"batb":[[0,3.7,28.17],[1,2.52,381.46],[2,1.83,63.08]],"ltp":3.4,"tv":240.59,"id":9712909}]}]}
{"op":"mcm","clk":"1003286405","pt":1580605691546,"mc":[{"id":"1.168179122","rc":[{"batb":[[0,1.26,858.84],[1,1.25,1105.26],[2,1.2,530.86]],"batl":[[0,1.37,685.66],[1,1.38,517.86]],"ltp":1.38,"tv":2643.08,"id":8326656}]}]}
{"op":"mcm","clk":"1003287500","pt":1580605709762,"mc":[{"id":"1.168179122","rc":[{"batl":[[0,1.29,453.62],[1,1.3,698.24]],"ltp":1.38,"tv":2643.08,"id":8326656}]}]}
{"op":"mcm","clk":"1003287577","pt":1580605710791,"mc":[{"id":"1.168179122","rc":[{"batb":[[2,1.23,203.71]],"ltp":1.38,"tv":2643.08,"id":8326656},{"batb":[[0,4.4,36.04],[1,4.1,43.04],[2,2.52,381.46]],"ltp":3.4,"tv":240.59,"id":9712909}]}]}
{"op":"mcm","clk":"1003288400","pt":1580605722890,"mc":[{"id":"1.168179122","rc":[{"batb":[[0,1.25,912.73],[1,1.23,203.71],[2,1.2,530.86]],"ltp":1.38,"tv":2643.08,"id":8326656},{"batb":[[0,4.1,43.04],[1,2.52,381.46],[2,1.83,63.08]],"ltp":3.4,"tv":240.59,"id":9712909}]}]}
{"op":"mcm","clk":"1003288563","pt":1580605725577,"mc":[{"id":"1.168179122","rc":[{"batb":[[1,1.24,961.69],[2,1.23,203.71]],"batl":[[0,1.32,949.27],[1,1.33,613.23]],"ltp":1.38,"tv":2643.08,"id":8326656}]}]}
{"op":"mcm","clk":"1003289113","pt":1580605733703,"mc":[{"id":"1.168179122","rc":[{"batl":[[0,1.28,453.33],[1,1.29,727.62]],"ltp":1.38,"tv":2643.08,"id":8326656}]}]}
{"op":"mcm","clk":"1003289193","pt":1580605734731,"mc":[{"id":"1.168179122","rc":[{"batb":[[0,4.6,33.13],[1,3.95,47.52],[2,2.52,381.46]],"ltp":3.4,"tv":240.59,"id":9712909}]}]}
{"op":"mcm","clk":"1003289742","pt":1580605742702,"mc":[{"id":"1.168179122","rc":[{"batb":[[1,1.24,1165.32],[2,1.2,530.86]],"ltp":1.38,"tv":2643.08,"id":8326656}]}]}
{"op":"mcm","clk":"1003290324","pt":1580605750854,"mc":[{"id":"1.168179122","rc":[{"batb":[[1,1.24,1165]],"ltp":1.38,"tv":2643.08,"id":8326656}]}]}
{"op":"mcm","clk":"1003290395","pt":1580605751833,"mc":[{"id":"1.168179122","rc":[{"trd":[[1.28,378.62]],"batl":[[0,1.28,264.02]],"ltp":1.28,"tv":3021.7,"id":8326656}],"tv":3262.3}]}
{"op":"mcm","clk":"1003290616","pt":1580605754720,"mc":[{"id":"1.168179122","rc":[{"batb":[[0,1.25,1041.76]],"batl":[[0,1.28,378.97]],"ltp":1.28,"tv":3021.7,"id":8326656}]}]}
{"op":"mcm","clk":"1003292251","pt":1580605777169,"mc":[{"id":"1.168179122","rc":[{"trd":[[1.28,404.36]],"batl":[[0,1.28,366.1]],"ltp":1.28,"tv":3047.45,"id":8326656}],"tv":3288.04}]}
{"op":"mcm","clk":"1003294560","pt":1580605809756,"mc":[{"id":"1.168179122","rc":[{"batb":[[0,1.24,203.31],[1,1.2,530.86],[2,1.17,299.94]],"ltp":1.28,"tv":3047.45,"id":8326656}]}]}
{"op":"mcm","clk":"1003294585","pt":1580605810030,"mc":[{"id":"1.168179122","rc":[{"batb":[[0,1.2,530.86],[1,1.17,299.94],[2,1.01,15.51]],"ltp":1.28,"tv":3047.45,"id":8326656},{"batb":[[0,3.95,47.52],[1,2.52,381.46],[2,1.83,63.08]],"ltp":3.4,"tv":240.59,"id":9712909}]}]}
{"op":"mcm","clk":"1003294787","pt":1580605812728,"mc":[{"id":"1.168179122","rc":[{"batb":[[1,1.18,1560.25],[2,1.17,1076.92]],"batl":[[0,1.34,313.92],[1,1.35,577.84]],"ltp":1.28,"tv":3047.45,"id":8326656}]}]}
{"op":"mcm","clk":"1003294867","pt":1580605813815,"mc":[{"id":"1.168179122","rc":[{"batb":[[1,1.17,299.94],[2,1.01,15.51]],"ltp":1.28,"tv":3047.45,"id":8326656}]}]}
{"op":"mcm","clk":"1003295149","pt":1580605817714,"mc":[{"id":"1.168179122","rc":[{"batb":[[0,1.24,676.12],[1,1.23,1002.51],[2,1.2,530.86]],"batl":[[0,1.27,816.85],[1,1.28,749.84]],"ltp":1.28,"tv":3047.45,"id":8326656}]}]}
{"op":"mcm","clk":"1003295303","pt":1580605819724,"mc":[{"id":"1.168179122","rc":[{"batb":[[0,1.2,530.86],[1,1.17,299.94],[2,1.01,15.51]],"ltp":1.28,"tv":3047.45,"id":8326656}]}]}
{"op":"mcm","clk":"1003295514","pt":1580605822612,"mc":[{"id":"1.168179122","rc":[{"batb":[[1,1.18,1560.25],[2,1.17,1076.92]],"batl":[[0,1.34,313.92],[1,1.35,577.83]],"ltp":1.28,"tv":3047.45,"id":8326656}]}]}
{"op":"mcm","clk":"1003295564","pt":1580605823228,"mc":[{"id":"1.168179122","rc":[{"batb":[[1,1.17,299.94],[2,1.01,15.51]],"ltp":1.28,"tv":3047.45,"id":8326656}]}]}
{"op":"mcm","clk":"1003295740","pt":1580605825707,"mc":[{"id":"1.168179122","rc":[{"batb":[[0,1.17,299.94],[1,1.01,15.51],[2,1.01,0]],"ltp":1.28,"tv":3047.45,"id":8326656}]}]}
{"op":"mcm","clk":"1003295820","pt":1580605826849,"mc":[{"id":"1.168179122","rc":[{"batb":[[0,1.31,584.91],[1,1.3,722.79],[2,1.29,158.78]],"ltp":1.28,"tv":3047.45,"id":8326656},{"batb":[[1,3.5,31.71],[2,2.52,381.46]],"ltp":3.4,"tv":240.59,"id":9712909}]}]}
{"op":"mcm","clk":"1003296988","pt":1580605844654,"mc":[{"id":"1.168179122","rc":[{"batb":[[0,1.22,739.84],[1,1.01,15.51],[2,1.29,0]],"ltp":1.28,"tv":3047.45,"id":8326656},{"batb":[[0,3.5,31.71],[1,2.52,381.46],[2,1.83,63.08]],"ltp":3.4,"tv":240.59,"id":9712909}]}]}
{"op":"mcm","clk":"1003297191","pt":1580605847667,"mc":[{"id":"1.168179122","rc":[{"batb":[[0,1.24,1085.67],[1,1.23,1013.12],[2,1.22,739.84]],"batl":[[0,1.4,490.78],[1,1.41,471.18]],"ltp":1.28,"tv":3047.45,"id":8326656}]}]}
{"op":"mcm","clk":"1003299494","pt":1580605880612,"mc":[{"id":"1.168179122","rc":[{"batb":[[2,1.22,216.85]],"ltp":1.28,"tv":3047.45,"id":8326656}]}]}
{"op":"mcm","clk":"1003299575","pt":1580605881747,"mc":[{"id":"1.168179122","rc":[{"batl":[[0,1.27,444.04],[1,1.28,757.67]],"ltp":1.28,"tv":3047.45,"id":8326656}]}]}
{"op":"mcm","clk":"1003299641","pt":1580605882421,"mc":[{"id":"1.168179122","rc":[{"batb":[[0,4.8,30.21],[1,4,47.37],[2,2.52,381.46]],"ltp":3.4,"tv":240.59,"id":9712909}]}]}
{"op":"mcm","clk":"1003299899","pt":1580605885417,"mc":[{"id":"1.168179122","rc":[{"batl":[[2,1.38,2837.75]],"ltp":1.28,"tv":3047.45,"id":8326656}]}]}
{"op":"mcm","clk":"1003300733","pt":1580605896847,"mc":[{"id":"1.168179122","rc":[{"batl":[[2,1.38,0]],"ltp":1.28,"tv":3047.45,"id":8326656}]}]}
{"op":"mcm","clk":"1003300781","pt":1580605897564,"mc":[{"id":"1.168179122","rc":[{"batb":[[0,1.18,549.72],[1,1.14,352.73],[2,1.01,15.51]],"ltp":1.28,"tv":3047.45,"id":8326656},{"batb":[[0,4,47.37],[1,2.52,381.46],[2,1.83,63.08]],"ltp":3.4,"tv":240.59,"id":9712909}]}]}
{"op":"mcm","clk":"1003301036","pt":1580605901643,"mc":[{"id":"1.168179122","rc":[{"batb":[[1,1.83,63.08],[2,1.01,15.52]],"ltp":3.4,"tv":240.59,"id":9712909}]}]}
{"op":"mcm","clk":"1003301179","pt":1580605903861,"mc":[{"id":"1.168179122","rc":[{"batb":[[0,1.23,440.51],[1,1.22,1050.81],[2,1.18,549.72]],"batl":[[0,1.26,1143.84],[1,1.27,776.12]],"ltp":1.28,"tv":3047.45,"id":8326656}]}]}
{"op":"mcm","clk":"1003301323","pt":1580605905764,"mc":[{"id":"1.168179122","rc":[{"batb":[[1,2.72,378.25],[2,1.83,63.08]],"ltp":3.4,"tv":240.59,"id":9712909}]}]}
{"op":"mcm","clk":"1003301387","pt":1580605906948,"mc":[{"id":"1.168179122","rc":[{"batb":[[0,1.18,549.72],[1,1.14,352.73],[2,1.01,15.51]],"ltp":1.28,"tv":3047.45,"id":8326656}]}]}
{"op":"mcm","clk":"1003301614","pt":1580605910352,"mc":[{"id":"1.168179122","rc":[{"batb":[[1,1.16,1560.67],[2,1.15,817.2]],"batl":[[0,1.35,854.28],[1,1.36,550.42]],"ltp":1.28,"tv":3047.45,"id":8326656}]}]}
{"op":"mcm","clk":"1003301927","pt":1580605915664,"mc":[{"id":"1.168179122","rc":[{"batb":[[1,1.14,352.73],[2,1.01,15.51]],"ltp":1.28,"tv":3047.45,"id":8326656}]}]}
{"op":"mcm","clk":"1003302049","pt":1580605917772,"mc":[{"id":"1.168179122","rc":[{"batb":[[0,1.14,352.73],[1,1.01,15.51],[2,1.01,0]],"ltp":1.28,"tv":3047.45,"id":8326656},{"batb":[[1,1.83,63.08],[2,1.01,15.52]],"ltp":3.4,"tv":240.59,"id":9712909}]}]}
{"op":"mcm","clk":"1003302171","pt":1580605919577,"mc":[{"id":"1.168179122","rc":[{"batb":[[0,1.16,1560.67],[1,1.15,817.2],[2,1.14,352.73]],"batl":[[0,1.19,1329.95],[1,1.2,972.93]],"ltp":1.28,"tv":3047.45,"id":8326656},{"batb":[[0,6.6,28.8],[1,4.9,28.09],[2,1.83,63.08]],"ltp":3.4,"tv":240.59,"id":9712909}]}]}
{"op":"mcm","clk":"1003302332","pt":1580605922298,"mc":[{"id":"1.168179122","rc":[{"batb":[[2,2.98,374.28]],"ltp":3.4,"tv":240.59,"id":9712909}]}]}
{"op":"mcm","clk":"1003304008","pt":1580605946823,"mc":[{"id":"1.168179122","rc":[{"batb":[[0,1.12,650.34],[1,1.06,762.43],[2,1.01,15.51]],"ltp":1.28,"tv":3047.45,"id":8326656},{"batb":[[0,4.9,28.09],[1,2.98,374.28],[2,1.83,63.08]],"ltp":3.4,"tv":240.59,"id":9712909}]}]}
{"op":"mcm","clk":"1003304144","pt":1580605948833,"mc":[{"id":"1.168179122","rc":[{"batb":[[0,1.06,762.43],[1,1.01,15.51],[2,1.01,0]],"ltp":1.28,"tv":3047.45,"id":8326656},{"batb":[[1,1.83,63.08],[2,1.01,15.52]],"ltp":3.4,"tv":240.59,"id":9712909}]}]}
{"op":"mcm","clk":"1003304230","pt":1580605949818,"mc":[{"id":"1.168179122","rc":[{"batb":[[0,1.08,2368.72],[1,1.06,762.43],[2,1.01,15.51]],"batl":[[0,1.26,484.31],[1,1.27,790.87]],"ltp":1.28,"tv":3047.45,"id":8326656}]}]}
{"op":"mcm","clk":"1003304298","pt":1580605950742,"mc":[{"id":"1.168179122","rc":[{"batb":[[0,1.06,762.43],[1,1.01,15.51],[2,1.01,0]],"ltp":1.28,"tv":3047.45,"id":8326656}]}]}
{"op":"mcm","clk":"1003304524","pt":1580605953737,"mc":[{"id":"1.168179122","rc":[{"batb":[[0,1.23,1168.5],[1,1.22,1071.04],[2,1.21,225.58]],"batl":[[0,1.26,484.31],[1,1.27,790.87]],"ltp":1.28,"tv":3047.45,"id":8326656},{"batb":[[1,3.85,51.22],[2,1.83,63.08]],"ltp":3.4,"tv":240.59,"id":9712909}]}]}
{"op":"mcm","clk":"1003304616","pt":1580605955028,"mc":[{"id":"1.168179122","rc":[{"batb":[[2,2.72,378.25]],"ltp":3.4,"tv":240.59,"id":9712909}]}]}
{"op":"mcm","clk":"1003305663","pt":1580605971449,"mc":[{"id":"1.168179122","rc":[{"batb":[[0,1.16,576.13],[1,1.11,443.53],[2,1.01,15.51]],"ltp":1.28,"tv":3047.45,"id":8326656},{"batb":[[0,3.85,51.22],[1,2.72,378.25],[2,1.83,63.08]],"ltp":3.4,"tv":240.59,"id":9712909}]}]}
{"op":"mcm","clk":"1003305843","pt":1580605974377,"mc":[{"id":"1.168179122","rc":[{"batb":[[1,1.13,1611.87],[2,1.12,829.24]],"batl":[[0,1.36,646.26],[1,1.37,534.65]],"ltp":1.28,"tv":3047.45,"id":8326656}]}]}
{"op":"mcm","clk":"1003306616","pt":1580605987189,"mc":[{"id":"1.168179122","rc":[{"batb":[[1,1.11,443.53],[2,1.01,15.51]],"ltp":1.28,"tv":3047.45,"id":8326656}]}]}
{"op":"mcm","clk":"1003306783","pt":1580605989863,"mc":[{"id":"1.168179122","rc":[{"batb":[[0,1.11,443.53],[1,1.01,15.51],[2,1.01,0]],"ltp":1.28,"tv":3047.45,"id":8326656}]}]}
{"op":"mcm","clk":"1003306849","pt":1580605990864,"mc":[{"id":"1.168179122","rc":[{"batb":[[0,1.32,762.35],[1,1.31,696.67],[2,1.3,150.99]],"ltp":1.28,"tv":3047.45,"id":8326656},{"batb":[[1,3.35,36.35],[2,2.72,378.25]],"ltp":3.4,"tv":240.59,"id":9712909}]}]}
{"op":"mcm","clk":"1003308218","pt":1580606010686,"mc":[{"id":"1.168179122","rc":[{"batb":[[0,1.3,150.99],[1,1.23,516.48],[2,1.21,231.95]],"ltp":1.28,"tv":3047.45,"id":8326656}]}]}
{"op":"mcm","clk":"1003308234","pt":1580606010898,"mc":[{"id":"1.168179122","rc":[{"batb":[[0,1.23,516.48],[1,1.21,231.95],[2,1.01,15.51]],"ltp":1.28,"tv":3047.45,"id":8326656},{"batb":[[0,3.35,36.35],[1,2.72,378.25],[2,1.83,63.08]],"ltp":3.4,"tv":240.59,"id":9712909}]}]}
{"op":"mcm","clk":"1003308452","pt":1580606013893,"mc":[{"id":"1.168179122","rc":[{"batb":[[0,1.23,1447.42],[1,1.22,1064.49],[2,1.21,229.52]],"batl":[[0,1.44,515.21],[1,1.45,417.9]],"ltp":1.28,"tv":3047.45,"id":8326656},{"batb":[[0,3.3,36.82]],"ltp":3.4,"tv":240.59,"id":9712909}]}]}
{"op":"mcm","clk":"1003308856","pt":1580606019823,"mc":[{"id":"1.168179122","rc":[{"batb":[[0,1.23,930.94]],"batl":[[0,1.26,699.56],[1,1.27,786.1]],"ltp":1.28,"tv":3047.45,"id":8326656}]}]}
{"op":"mcm","clk":"1003308913","pt":1580606020596,"mc":[{"id":"1.168179122","rc":[{"batb":[[0,5,27.7],[1,3.85,50.59],[2,2.72,378.25]],"ltp":3.4,"tv":240.59,"id":9712909}]}]}
{"op":"mcm","clk":"1003309131","pt":1580606023733,"mc":[{"id":"1.168179122","rc":[{"batb":[[1,4.4,8.84],[2,3.85,50.59]],"ltp":3.4,"tv":240.59,"id":9712909}]}]}
{"op":"mcm","clk":"1003309343","pt":1580606026832,"mc":[{"id":"1.168179122","rc":[{"batb":[[1,3.85,50.59],[2,2.72,378.25]],"ltp":3.4,"tv":240.59,"id":9712909}]}]}
{"op":"mcm","clk":"1003310212","pt":1580606039049,"mc":[{"id":"1.168179122","rc":[{"batb":[[0,1.16,576.13],[1,1.11,450.53],[2,1.01,15.51]],"ltp":1.28,"tv":3047.45,"id":8326656},{"batb":[[0,3.85,50.59],[1,2.72,378.25],[2,1.83,63.08]],"ltp":3.4,"tv":240.59,"id":9712909}]}]}
{"op":"mcm","clk":"1003310301","pt":1580606040164,"mc":[{"id":"1.168179122","rc":[{"batl":[[0,1.23,75.62]],"ltp":1.28,"tv":3047.45,"id":8326656}]}]}
{"op":"mcm","clk":"1003311000","pt":1580606049851,"mc":[{"id":"1.168179122","rc":[{"batb":[[0,1.11,450.53],[1,1.01,15.51],[2,1.01,0]],"ltp":1.28,"tv":3047.45,"id":8326656},{"batb":[[1,1.83,63.08],[2,1.01,15.52]],"ltp":3.4,"tv":240.59,"id":9712909}]}]}
{"op":"mcm","clk":"1003311100","pt":1580606051361,"mc":[{"id":"1.168179122","rc":[{"batb":[[0,1.13,1324.18],[1,1.12,1119.5],[2,1.11,450.53]],"batl":[[0,1.36,813.68],[1,1.37,532.46]],"ltp":1.28,"tv":3047.45,"id":8326656}]}]}
{"op":"mcm","clk":"1003311846","pt":1580606061871,"mc":[{"id":"1.168179122","rc":[{"batl":[[0,1.15,965.98],[1,1.16,1413.19]],"ltp":1.28,"tv":3047.45,"id":8326656},{"batb":[[0,4,1000],[1,3.85,50.59],[2,1.83,63.08]],"ltp":3.4,"tv":240.59,"id":9712909}]}]}
{"op":"mcm","clk":"1003311876","pt":1580606062286,"mc":[{"id":"1.168179122","rc":[{"batb":[[0,7.8,19.28],[1,5,27.3]],"ltp":3.4,"tv":240.59,"id":9712909}]}]}
{"op":"mcm","clk":"1003312001","pt":1580606063995,"mc":[{"id":"1.168179122","rc":[{"batb":[[2,3.2,374.33]],"ltp":3.4,"tv":240.59,"id":9712909}]}]}
{"op":"mcm","clk":"1003312625","pt":1580606071795,"mc":[{"id":"1.168179122","rc":[{"trd":[[1.13,336.08]],"batb":[[0,1.13,1156.14]],"batl":[[1,1.16,1348.83]],"ltp":1.13,"tv":3383.52,"id":8326656}],"tv":3624.12}]}
{"op":"mcm","clk":"1003312858","pt":1580606074685,"mc":[{"id":"1.168179122","rc":[{"batb":[[0,1.13,1258.17],[1,1.12,1186.1]],"batl":[[0,1.15,1030.89]],"ltp":1.13,"tv":3383.52,"id":8326656}]}]}
{"op":"mcm","clk":"1003313429","pt":1580606083807,"mc":[{"id":"1.168179122","rc":[{"batb":[[0,1.09,753.06],[1,1.01,15.51],[2,1.11,0]],"ltp":1.13,"tv":3383.52,"id":8326656},{"batb":[[0,5,27.3],[1,3.2,374.33],[2,1.83,63.08]],"ltp":3.4,"tv":240.59,"id":9712909}]}]}
{"op":"mcm","clk":"1003313449","pt":1580606084118,"mc":[{"id":"1.168179122","rc":[{"batb":[[0,1.01,15.51],[1,1.01,0]],"ltp":1.13,"tv":3383.52,"id":8326656},{"batb":[[1,1.83,63.08],[2,1.01,15.52]],"ltp":3.4,"tv":240.59,"id":9712909}]}]}
{"op":"mcm","clk":"1003313596","pt":1580606086498,"mc":[{"id":"1.168179122","rc":[{"batb":[[0,1.02,2696.25],[1,1.01,15.51]],"batl":[[0,1.26,938.17],[1,1.27,782.33]],"ltp":1.13,"tv":3383.52,"id":8326656}]}]}
{"op":"mcm","clk":"1003314065","pt":1580606093814,"mc":[{"id":"1.168179122","rc":[{"batb":[[0,1.01,15.51],[1,1.01,0]],"ltp":1.13,"tv":3383.52,"id":8326656}]}]}
{"op":"mcm","clk":"1003314332","pt":1580606097740,"mc":[{"id":"1.168179122","rc":[{"batb":[[0,1.02,2698.43],[1,1.01,15.51]],"batl":[[0,1.03,899.84],[1,1.04,1755.35]],"ltp":1.13,"tv":3383.52,"id":8326656},{"batb":[[0,29,4.93],[1,16,9.76],[2,1.83,63.08]],"ltp":3.4,"tv":240.59,"id":9712909}]}]}
{"op":"mcm","clk":"1003314428","pt":1580606099237,"mc":[{"id":"1.168179122","rc":[{"batb":[[1,1.01,4112.75]],"ltp":1.13,"tv":3383.52,"id":8326656},{"batb":[[2,4.1,372.42]],"ltp":3.4,"tv":240.59,"id":9712909}]}]}
{"op":"mcm","clk":"1003315829","pt":1580606118559,"mc":[{"id":"1.168179122","rc":[{"trd":[[1.02,1011.52]],"batb":[[0,1.02,2192.67]],"ltp":1.02,"tv":4395.04,"id":8326656}],"tv":4635.64}]}
{"op":"mcm","clk":"1003315903","pt":1580606119743,"mc":[{"id":"1.168179122","rc":[{"batl":[[1,1.04,1559.73]],"ltp":1.02,"tv":4395.04,"id":8326656}]}]}
{"op":"mcm","clk":"1003316060","pt":1580606121861,"mc":[{"id":"1.168179122","rc":[{"batb":[[0,1.02,2698.43]],"batl":[[0,1.03,1097.35]],"ltp":1.02,"tv":4395.04,"id":8326656}]}]}
{"op":"mcm","clk":"1003316171","pt":1580606123365,"mc":[{"id":"1.168179122","rc":[{"batb":[[0,1.01,4112.75],[1,1.01,0]],"ltp":1.02,"tv":4395.04,"id":8326656},{"batb":[[0,16,9.76],[1,4.1,372.42],[2,1.83,63.08]],"ltp":3.4,"tv":240.59,"id":9712909}]}]}
{"op":"mcm","clk":"1003316237","pt":1580606124321,"mc":[{"id":"1.168179122","rc":[{"batb":[[0,1.01,15.51]],"ltp":1.02,"tv":4395.04,"id":8326656},{"batb":[[1,1.83,63.08],[2,1.01,15.52]],"ltp":3.4,"tv":240.59,"id":9712909}]}]}
{"op":"mcm","clk":"1003316402","pt":1580606126848,"mc":[{"id":"1.168179122","rc":[{"batb":[[0,1.01,2740.66]],"batl":[[0,1.07,2572.34]],"ltp":1.02,"tv":4395.04,"id":8326656},{"batb":[[0,15.5,9.91]],"ltp":3.4,"tv":240.59,"id":9712909}]}]}
{"op":"mcm","clk":"1003316840","pt":1580606132875,"mc":[{"id":"1.168179122","rc":[{"batl":[[0,1.02,2698.43]],"ltp":1.02,"tv":4395.04,"id":8326656}]}]}
{"op":"mcm","clk":"1003316911","pt":1580606133761,"mc":[{"id":"1.168179122","rc":[{"batb":[[0,24,5.85]],"ltp":3.4,"tv":240.59,"id":9712909}]}]}
{"op":"mcm","clk":"1003316976","pt":1580606134687,"mc":[{"id":"1.168179122","rc":[{"batb":[[1,4.4,373.53],[2,1.83,63.08]],"ltp":3.4,"tv":240.59,"id":9712909}]}]}
{"op":"mcm","clk":"1003317821","pt":1580606146405,"mc":[{"id":"1.168179122","rc":[{"batb":[[0,1.01,15.51]],"ltp":1.02,"tv":4395.04,"id":8326656}]}]}
{"op":"mcm","clk":"1003317892","pt":1580606147392,"mc":[{"id":"1.168179122","rc":[{"batb":[[1,1.83,63.08],[2,1.01,15.52]],"ltp":3.4,"tv":240.59,"id":9712909}]}]}
{"op":"mcm","clk":"1003317960","pt":1580606148500,"mc":[{"id":"1.168179122","rc":[{"trd":[[1.01,31.01]],"batl":[[0,1.01,491.14]],"ltp":1.01,"tv":4426.05,"id":8326656}],"tv":4666.65}]}
{"op":"mcm","clk":"1003317998","pt":1580606148966,"mc":[{"id":"1.168179122","rc":[{"batl":[[1,1.04,2646.54]],"ltp":1.01,"tv":4426.05,"id":8326656}]}]}
{"op":"mcm","clk":"1003318341","pt":1580606153681,"mc":[{"id":"1.168179122","rc":[{"batb":[[0,1.83,63.08],[1,1.01,15.52],[2,1.01,0]],"ltp":3.4,"tv":240.59,"id":9712909}]}]}
{"op":"mcm","clk":"1003318504","pt":1580606155796,"mc":[{"id":"1.168179122","rc":[{"batl":[[0,1.01,2725.15]],"ltp":1.01,"tv":4426.05,"id":8326656}]}]}
{"op":"mcm","clk":"1003318582","pt":1580606156726,"mc":[{"id":"1.168179122","rc":[{"batb":[[0,4.7,371.58],[1,1.83,63.08],[2,1.01,15.52]],"ltp":3.4,"tv":240.59,"id":9712909}]}]}
{"op":"mcm","clk":"1003319649","pt":1580606171440,"mc":[{"id":"1.168179122","rc":[{"batb":[[0,1.83,63.08],[1,1.01,15.52],[2,1.01,0]],"ltp":3.4,"tv":240.59,"id":9712909}]}]}
{"op":"mcm","clk":"1003319766","pt":1580606172831,"mc":[{"id":"1.168179122","rc":[{"batl":[[0,1.02,2698.43]],"ltp":1.01,"tv":4426.05,"id":8326656}]}]}
{"op":"mcm","clk":"1003321361","pt":1580606193866,"mc":[{"id":"1.168179122","rc":[{"batb":[[0,1.01,2725.15]],"ltp":1.01,"tv":4426.05,"id":8326656}]}]}
{"op":"mcm","clk":"1003321444","pt":1580606194844,"mc":[{"id":"1.168179122","rc":[{"batb":[[0,20,11.33],[1,1.83,63.08],[2,1.01,15.52]],"ltp":3.4,"tv":240.59,"id":9712909}]}]}
{"op":"mcm","clk":"1003321519","pt":1580606195871,"mc":[{"id":"1.168179122","rc":[{"batb":[[1,4.4,373.53],[2,1.83,63.08]],"ltp":3.4,"tv":240.59,"id":9712909}]}]}
{"op":"mcm","clk":"1003323448","pt":1580606220581,"mc":[{"id":"1.168179122","rc":[{"batb":[[1,1.83,63.08],[2,1.01,15.52]],"ltp":3.4,"tv":240.59,"id":9712909}]}]}
{"op":"mcm","clk":"1003323551","pt":1580606221818,"mc":[{"id":"1.168179122","rc":[{"batl":[[0,1.05,2621.34]],"ltp":1.01,"tv":4426.05,"id":8326656}]}]}
{"op":"mcm","clk":"1003323832","pt":1580606225328,"mc":[{"id":"1.168179122","rc":[{"batb":[[0,1.02,1007.62],[1,1.01,1707.55]],"batl":[[0,1.03,2672.24]],"ltp":1.01,"tv":4426.05,"id":8326656}]}]}
{"op":"mcm","clk":"1003323913","pt":1580606226312,"mc":[{"id":"1.168179122","rc":[{"batb":[[1,4.3,383.85],[2,1.83,63.08]],"batl":[[0,170,36.71]],"ltp":3.4,"tv":240.59,"id":9712909}]}]}
{"op":"mcm","clk":"1003324178","pt":1580606229622,"mc":[{"id":"1.168179122","rc":[{"batb":[[1,1.83,63.08],[2,1.01,15.52]],"ltp":3.4,"tv":240.59,"id":9712909}]}]}
{"op":"mcm","clk":"1003324310","pt":1580606231117,"mc":[{"id":"1.168179122","rc":[{"batl":[[0,1.05,2621.34]],"ltp":1.01,"tv":4426.05,"id":8326656}]}]}
{"op":"mcm","clk":"1003324736","pt":1580606236328,"mc":[{"id":"1.168179122","rc":[{"batb":[[0,1.83,63.08],[1,1.01,15.52],[2,1.01,0]],"ltp":3.4,"tv":240.59,"id":9712909}]}]}
{"op":"mcm","clk":"1003324908","pt":1580606238454,"mc":[{"id":"1.168179122","rc":[{"batl":[[0,1.01,2725.15]],"ltp":1.01,"tv":4426.05,"id":8326656}]}]}
{"op":"mcm","clk":"1003325056","pt":1580606240314,"mc":[{"id":"1.168179122","rc":[{"batb":[[0,4.7,381.98],[1,1.83,63.08],[2,1.01,15.52]],"ltp":3.4,"tv":240.59,"id":9712909}]}]}
{"op":"mcm","clk":"1003326290","pt":1580606255634,"mc":[{"id":"1.168179122","rc":[{"batb":[[0,1.83,63.08],[1,1.01,15.52],[2,1.01,0]],"ltp":3.4,"tv":240.59,"id":9712909}]}]}
{"op":"mcm","clk":"1003326381","pt":1580606256769,"mc":[{"id":"1.168179122","rc":[{"batl":[[0,1.02,2698.43]],"ltp":1.01,"tv":4426.05,"id":8326656}]}]}
{"op":"mcm","clk":"1003327530","pt":1580606271256,"mc":[{"id":"1.168179122","marketDefinition":{"bspMarket":false,"turnInPlayEnabled":true,"persistenceEnabled":true,"marketBaseRate":5.0,"eventId":"29680182","eventTypeId":"2","numberOfWinners":1,"bettingType":"ODDS","marketType":"SET_WINNER","marketTime":"2020-02-02T00:32:00.000Z","suspendTime":"2020-02-02T00:32:00.000Z","bspReconciled":false,"complete":true,"inPlay":true,"crossMatching":true,"runnersVoidable":false,"numberOfActiveRunners":2,"betDelay":3,"status":"SUSPENDED","runners":[{"status":"ACTIVE","sortPriority":1,"id":9712909,"name":"Felipe Meligeni Rodrigu"},{"status":"ACTIVE","sortPriority":2,"id":8326656,"name":"Thiago Monteiro"}],"regulators":["MR_INT"],"countryCode":"UY","discountAllowed":true,"timezone":"UTC","openDate":"2020-02-02T00:32:00.000Z","version":3147992368,"name":"Set 1 Winner","eventName":"Meligeni Rodrigues Alve v T Monteiro"}}]}
{"op":"mcm","clk":"1003330139","pt":1580606301641,"mc":[{"id":"1.168179122","tv":0.0}]}
{"op":"mcm","clk":"1003330192","pt":1580606302336,"mc":[{"id":"1.168179122","marketDefinition":{"bspMarket":false,"turnInPlayEnabled":true,"persistenceEnabled":true,"marketBaseRate":5.0,"eventId":"29680182","eventTypeId":"2","numberOfWinners":1,"bettingType":"ODDS","marketType":"SET_WINNER","marketTime":"2020-02-02T00:32:00.000Z","suspendTime":"2020-02-02T00:32:00.000Z","bspReconciled":false,"complete":true,"inPlay":true,"crossMatching":false,"runnersVoidable":false,"numberOfActiveRunners":0,"betDelay":3,"status":"CLOSED","settledTime":"2020-02-02T01:18:20.000Z","runners":[{"status":"LOSER","sortPriority":1,"id":9712909,"name":"Felipe Meligeni Rodrigu"},{"status":"WINNER","sortPriority":2,"id":8326656,"name":"Thiago Monteiro"}],"regulators":["MR_INT"],"countryCode":"UY","discountAllowed":true,"timezone":"UTC","openDate":"2020-02-02T00:32:00.000Z","version":3147992414,"name":"Set 1 Winner","eventName":"Meligeni Rodrigues Alve v T Monteiro"}}]}
