{"op":"mcm","clk":"992350394","pt":1580520342496,"mc":[{"id":"1.168179123","marketDefinition":{"bspMarket":false,"turnInPlayEnabled":true,"persistenceEnabled":true,"marketBaseRate":5.0,"eventId":"29680182","eventTypeId":"2","numberOfWinners":1,"bettingType":"ODDS","marketType":"SET_WINNER","marketTime":"2020-02-02T00:00:00.000Z","suspendTime":"2020-02-02T00:00:00.000Z","bspReconciled":false,"complete":true,"inPlay":false,"crossMatching":false,"runnersVoidable":false,"numberOfActiveRunners":2,"betDelay":0,"status":"OPEN","runners":[{"status":"ACTIVE","sortPriority":1,"id":9712909,"name":"Felipe Meligeni Rodrigu"},{"status":"ACTIVE","sortPriority":2,"id":8326656,"name":"Thiago Monteiro"}],"regulators":["MR_INT"],"countryCode":"UY","discountAllowed":false,"timezone":"UTC","openDate":"2020-02-02T00:00:00.000Z","version":3144293963,"name":"Set 2 Winner","eventName":"Meligeni Rodrigues Alve v T Monteiro"},"rc":[{"batb":[[0,1.01,20]],"ltp":0.0,"tv":0.0,"id":8326656},{"batb":[[0,1.01,20]],"ltp":0.0,"tv":0.0,"id":9712909}]}]}
{"op":"mcm","clk":"992350445","pt":1580520343901,"mc":[{"id":"1.168179123","marketDefinition":{"bspMarket":false,"turnInPlayEnabled":true,"persistenceEnabled":true,"marketBaseRate":5.0,"eventId":"29680182","eventTypeId":"2","numberOfWinners":1,"bettingType":"ODDS","marketType":"SET_WINNER","marketTime":"2020-02-02T00:00:00.000Z","suspendTime":"2020-02-02T00:00:00.000Z","bspReconciled":false,"complete":true,"inPlay":false,"crossMatching":false,"runnersVoidable":false,"numberOfActiveRunners":2,"betDelay":0,"status":"OPEN","runners":[{"status":"ACTIVE","sortPriority":1,"id":9712909,"name":"Felipe Meligeni Rodrigu"},{"status":"ACTIVE","sortPriority":2,"id":8326656,"name":"Thiago Monteiro"}],"regulators":["MR_INT"],"countryCode":"UY","discountAllowed":true,"timezone":"UTC","openDate":"2020-02-02T00:00:00.000Z","version":3144293963,"name":"Set 2 Winner","eventName":"Meligeni Rodrigues Alve v T Monteiro"}}]}
{"op":"mcm","clk":"992357868","pt":1580520615946,"mc":[{"id":"1.168179123","rc":[{"batb":[[0,1.01,15]],"ltp":0.0,"tv":0.0,"id":8326656},{"batb":[[0,1.01,15]],"ltp":0.0,"tv":0.0,"id":9712909}]}]}
{"op":"mcm","clk":"993440117","pt":1580542436760,"mc":[{"id":"1.168179123","rc":[{"batl":[[0,3.5,18.93]],"ltp":0.0,"tv":0.0,"id":8326656}]}]}
{"op":"mcm","clk":"1002519194","pt":1580594810730,"mc":[{"id":"1.168179123","rc":[{"batb":[[0,1.01,17]],"ltp":0.0,"tv":0.0,"id":8326656},{"batb":[[0,1.01,15.01]],"ltp":0.0,"tv":0.0,"id":9712909}]}]}
{"op":"mcm","clk":"1002519230","pt":1580594811304,"mc":[{"id":"1.168179123","rc":[{"batb":[[0,1.01,15.01]],"ltp":0.0,"tv":0.0,"id":8326656}]}]}
{"op":"mcm","clk":"1002778122","pt":1580598643462,"mc":[{"id":"1.168179123","rc":[{"batb":[[0,1.02,2.01],[1,1.01,15]],"ltp":0.0,"tv":0.0,"id":8326656}]}]}
{"op":"mcm","clk":"1002780473","pt":1580598675081,"mc":[{"id":"1.168179123","marketDefinition":{"bspMarket":false,"turnInPlayEnabled":true,"persistenceEnabled":true,"marketBaseRate":5.0,"eventId":"29680182","eventTypeId":"2","numberOfWinners":1,"bettingType":"ODDS","marketType":"SET_WINNER","marketTime":"2020-02-02T00:00:00.000Z","suspendTime":"2020-02-02T00:00:00.000Z","bspReconciled":false,"complete":true,"inPlay":false,"crossMatching":true,"runnersVoidable":false,"numberOfActiveRunners":2,"betDelay":0,"status":"OPEN","runners":[{"status":"ACTIVE","sortPriority":1,"id":9712909,"name":"Felipe Meligeni Rodrigu"},{"status":"ACTIVE","sortPriority":2,"id":8326656,"name":"Thiago Monteiro"}],"regulators":["MR_INT"],"countryCode":"UY","discountAllowed":true,"timezone":"UTC","openDate":"2020-02-02T00:00:00.000Z","version":3144293963,"name":"Set 2 Winner","eventName":"Meligeni Rodrigues Alve v T Monteiro"}}]}
{"op":"mcm","clk":"1002799517","pt":1580598920061,"mc":[{"id":"1.168179123","rc":[{"batb":[[0,1.03,2.03],[1,1.02,2],[2,1.01,15]],"ltp":0.0,"tv":0.0,"id":8326656}]}]}
{"op":"mcm","clk":"1002822603","pt":1580599242679,"mc":[{"id":"1.168179123","rc":[{"batb":[[1,1.01,15],[2,1.01,0]],"ltp":0.0,"tv":0.0,"id":8326656}]}]}
{"op":"mcm","clk":"1002994722","pt":1580601699793,"mc":[{"id":"1.168179123","marketDefinition":{"bspMarket":false,"turnInPlayEnabled":true,"persistenceEnabled":true,"marketBaseRate":5.0,"eventId":"29680182","eventTypeId":"2","numberOfWinners":1,"bettingType":"ODDS","marketType":"SET_WINNER","marketTime":"2020-02-02T00:15:00.000Z","suspendTime":"2020-02-02T00:15:00.000Z","bspReconciled":false,"complete":true,"inPlay":false,"crossMatching":true,"runnersVoidable":false,"numberOfActiveRunners":2,"betDelay":0,"status":"OPEN","runners":[{"status":"ACTIVE","sortPriority":1,"id":9712909,"name":"Felipe Meligeni Rodrigu"},{"status":"ACTIVE","sortPriority":2,"id":8326656,"name":"Thiago Monteiro"}],"regulators":["MR_INT"],"countryCode":"UY","discountAllowed":true,"timezone":"UTC","openDate":"2020-02-02T00:00:00.000Z","version":3147888958,"name":"Set 2 Winner","eventName":"Meligeni Rodrigues Alve v T Monteiro"}}]}
{"op":"mcm","clk":"1002995013","pt":1580601703802,"mc":[{"id":"1.168179123","marketDefinition":{"bspMarket":false,"turnInPlayEnabled":true,"persistenceEnabled":true,"marketBaseRate":5.0,"eventId":"29680182","eventTypeId":"2","numberOfWinners":1,"bettingType":"ODDS","marketType":"SET_WINNER","marketTime":"2020-02-02T00:15:00.000Z","suspendTime":"2020-02-02T00:15:00.000Z","bspReconciled":false,"complete":true,"inPlay":false,"crossMatching":true,"runnersVoidable":false,"numberOfActiveRunners":2,"betDelay":0,"status":"OPEN","runners":[{"status":"ACTIVE","sortPriority":1,"id":9712909,"name":"Felipe Meligeni Rodrigu"},{"status":"ACTIVE","sortPriority":2,"id":8326656,"name":"Thiago Monteiro"}],"regulators":["MR_INT"],"countryCode":"UY","discountAllowed":true,"timezone":"UTC","openDate":"2020-02-02T00:15:00.000Z","version":3147888958,"name":"Set 2 Winner","eventName":"Meligeni Rodrigues Alve v T Monteiro"}}]}
{"op":"mcm","clk":"1002996992","pt":1580601734731,"mc":[{"id":"1.168179123","rc":[{"batb":[[0,1.04,4.03],[1,1.03,2.02],[2,1.01,15]],"ltp":0.0,"tv":0.0,"id":8326656}]}]}
{"op":"mcm","clk":"1003000960","pt":1580601795119,"mc":[{"id":"1.168179123","rc":[{"batb":[[0,1.04,2.03]],"ltp":0.0,"tv":0.0,"id":8326656}]}]}
{"op":"mcm","clk":"1003067632","pt":1580602567852,"mc":[{"id":"1.168179123","rc":[{"batb":[[2,1.01,17.53]],"ltp":0.0,"tv":0.0,"id":8326656},{"batb":[[0,1.01,17.54]],"ltp":0.0,"tv":0.0,"id":9712909}]}]}
{"op":"mcm","clk":"1003067727","pt":1580602568735,"mc":[{"id":"1.168179123","rc":[{"batb":[[2,1.01,15.51]],"ltp":0.0,"tv":0.0,"id":8326656},{"batb":[[0,1.01,15.52]],"ltp":0.0,"tv":0.0,"id":9712909}]}]}
{"op":"mcm","clk":"1003070584","pt":1580602600982,"mc":[{"id":"1.168179123","marketDefinition":{"bspMarket":false,"turnInPlayEnabled":true,"persistenceEnabled":true,"marketBaseRate":5.0,"eventId":"29680182","eventTypeId":"2","numberOfWinners":1,"bettingType":"ODDS","marketType":"SET_WINNER","marketTime":"2020-02-02T00:30:00.000Z","suspendTime":"2020-02-02T00:30:00.000Z","bspReconciled":false,"complete":true,"inPlay":false,"crossMatching":true,"runnersVoidable":false,"numberOfActiveRunners":2,"betDelay":0,"status":"OPEN","runners":[{"status":"ACTIVE","sortPriority":1,"id":9712909,"name":"Felipe Meligeni Rodrigu"},{"status":"ACTIVE","sortPriority":2,"id":8326656,"name":"Thiago Monteiro"}],"regulators":["MR_INT"],"countryCode":"UY","discountAllowed":true,"timezone":"UTC","openDate":"2020-02-02T00:15:00.000Z","version":3147905063,"name":"Set 2 Winner","eventName":"Meligeni Rodrigues Alve v T Monteiro"}}]}
{"op":"mcm","clk":"1003070979","pt":1580602604992,"mc":[{"id":"1.168179123","marketDefinition":{"bspMarket":false,"turnInPlayEnabled":true,"persistenceEnabled":true,"marketBaseRate":5.0,"eventId":"29680182","eventTypeId":"2","numberOfWinners":1,"bettingType":"ODDS","marketType":"SET_WINNER","marketTime":"2020-02-02T00:30:00.000Z","suspendTime":"2020-02-02T00:30:00.000Z","bspReconciled":false,"complete":true,"inPlay":false,"crossMatching":true,"runnersVoidable":false,"numberOfActiveRunners":2,"betDelay":0,"status":"OPEN","runners":[{"status":"ACTIVE","sortPriority":1,"id":9712909,"name":"Felipe Meligeni Rodrigu"},{"status":"ACTIVE","sortPriority":2,"id":8326656,"name":"Thiago Monteiro"}],"regulators":["MR_INT"],"countryCode":"UY","discountAllowed":true,"timezone":"UTC","openDate":"2020-02-02T00:30:00.000Z","version":3147905153,"name":"Set 2 Winner","eventName":"Meligeni Rodrigues Alve v T Monteiro"}}]}
{"op":"mcm","clk":"1003127311","pt":1580603334600,"mc":[{"id":"1.168179123","rc":[{"batb":[[2,1.01,18.04]],"ltp":0.0,"tv":0.0,"id":8326656},{"batb":[[0,1.01,18.05]],"ltp":0.0,"tv":0.0,"id":9712909}]}]}
{"op":"mcm","clk":"1003127403","pt":1580603335732,"mc":[{"id":"1.168179123","rc":[{"batb":[[2,1.01,16.01]],"ltp":0.0,"tv":0.0,"id":8326656},{"batb":[[0,1.01,16.02]],"ltp":0.0,"tv":0.0,"id":9712909}]}]}
{"op":"mcm","clk":"1003141084","pt":1580603501489,"mc":[{"id":"1.168179123","marketDefinition":{"bspMarket":false,"turnInPlayEnabled":true,"persistenceEnabled":true,"marketBaseRate":5.0,"eventId":"29680182","eventTypeId":"2","numberOfWinners":1,"bettingType":"ODDS","marketType":"SET_WINNER","marketTime":"2020-02-02T00:45:00.000Z","suspendTime":"2020-02-02T00:45:00.000Z","bspReconciled":false,"complete":true,"inPlay":false,"crossMatching":true,"runnersVoidable":false,"numberOfActiveRunners":2,"betDelay":0,"status":"OPEN","runners":[{"status":"ACTIVE","sortPriority":1,"id":9712909,"name":"Felipe Meligeni Rodrigu"},{"status":"ACTIVE","sortPriority":2,"id":8326656,"name":"Thiago Monteiro"}],"regulators":["MR_INT"],"countryCode":"UY","discountAllowed":true,"timezone":"UTC","openDate":"2020-02-02T00:30:00.000Z","version":3147932334,"name":"Set 2 Winner","eventName":"Meligeni Rodrigues Alve v T Monteiro"}}]}
{"op":"mcm","clk":"1003141344","pt":1580603504503,"mc":[{"id":"1.168179123","marketDefinition":{"bspMarket":false,"turnInPlayEnabled":true,"persistenceEnabled":true,"marketBaseRate":5.0,"eventId":"29680182","eventTypeId":"2","numberOfWinners":1,"bettingType":"ODDS","marketType":"SET_WINNER","marketTime":"2020-02-02T00:45:00.000Z","suspendTime":"2020-02-02T00:45:00.000Z","bspReconciled":false,"complete":true,"inPlay":false,"crossMatching":true,"runnersVoidable":false,"numberOfActiveRunners":2,"betDelay":0,"status":"OPEN","runners":[{"status":"ACTIVE","sortPriority":1,"id":9712909,"name":"Felipe Meligeni Rodrigu"},{"status":"ACTIVE","sortPriority":2,"id":8326656,"name":"Thiago Monteiro"}],"regulators":["MR_INT"],"countryCode":"UY","discountAllowed":true,"timezone":"UTC","openDate":"2020-02-02T00:45:00.000Z","version":3147932334,"name":"Set 2 Winner","eventName":"Meligeni Rodrigues Alve v T Monteiro"}}]}
{"op":"mcm","clk":"1003151903","pt":1580603629814,"mc":[{"id":"1.168179123","rc":[{"trd":[[1.48,0.01]],"batb":[[0,1.25,178.77],[1,1.04,2.02],[2,1.03,2.02]],"ltp":1.48,"tv":0.01,"id":8326656},{"trd":[[3.1,0]],"batb":[[0,4.2,40.2],[1,1.01,16.02]],"ltp":3.1,"tv":0.0,"id":9712909}],"tv":0.01}]}
{"op":"mcm","clk":"1003152581","pt":1580603637535,"mc":[{"id":"1.168179123","rc":[{"batb":[[0,1.26,177.82]],"ltp":1.48,"tv":0.01,"id":8326656}]}]}
{"op":"mcm","clk":"1003158728","pt":1580603706699,"mc":[{"id":"1.168179123","rc":[{"batb":[[0,1.26,177.19]],"ltp":1.48,"tv":0.01,"id":8326656}]}]}
{"op":"mcm","clk":"1003166663","pt":1580603799332,"mc":[{"id":"1.168179123","marketDefinition":{"bspMarket":false,"turnInPlayEnabled":true,"persistenceEnabled":true,"marketBaseRate":5.0,"eventId":"29680182","eventTypeId":"2","numberOfWinners":1,"bettingType":"ODDS","marketType":"SET_WINNER","marketTime":"2020-02-02T00:32:00.000Z","suspendTime":"2020-02-02T00:32:00.000Z","bspReconciled":false,"complete":true,"inPlay":false,"crossMatching":true,"runnersVoidable":false,"numberOfActiveRunners":2,"betDelay":0,"status":"OPEN","runners":[{"status":"ACTIVE","sortPriority":1,"id":9712909,"name":"Felipe Meligeni Rodrigu"},{"status":"ACTIVE","sortPriority":2,"id":8326656,"name":"Thiago Monteiro"}],"regulators":["MR_INT"],"countryCode":"UY","discountAllowed":true,"timezone":"UTC","openDate":"2020-02-02T00:45:00.000Z","version":3147936785,"name":"Set 2 Winner","eventName":"Meligeni Rodrigues Alve v T Monteiro"}}]}
{"op":"mcm","clk":"1003167020","pt":1580603803341,"mc":[{"id":"1.168179123","marketDefinition":{"bspMarket":false,"turnInPlayEnabled":true,"persistenceEnabled":true,"marketBaseRate":5.0,"eventId":"29680182","eventTypeId":"2","numberOfWinners":1,"bettingType":"ODDS","marketType":"SET_WINNER","marketTime":"2020-02-02T00:32:00.000Z","suspendTime":"2020-02-02T00:32:00.000Z","bspReconciled":false,"complete":true,"inPlay":false,"crossMatching":true,"runnersVoidable":false,"numberOfActiveRunners":2,"betDelay":0,"status":"OPEN","runners":[{"status":"ACTIVE","sortPriority":1,"id":9712909,"name":"Felipe Meligeni Rodrigu"},{"status":"ACTIVE","sortPriority":2,"id":8326656,"name":"Thiago Monteiro"}],"regulators":["MR_INT"],"countryCode":"UY","discountAllowed":true,"timezone":"UTC","openDate":"2020-02-02T00:32:00.000Z","version":3147936875,"name":"Set 2 Winner","eventName":"Meligeni Rodrigues Alve v T Monteiro"}}]}
{"op":"mcm","clk":"1003179304","pt":1580603988440,"mc":[{"id":"1.168179123","rc":[{"batb":[[0,1.26,174.83]],"ltp":1.48,"tv":0.01,"id":8326656}]}]}
{"op":"mcm","clk":"1003179967","pt":1580603998856,"mc":[{"id":"1.168179123","rc":[{"batb":[[0,1.26,172.39]],"ltp":1.48,"tv":0.01,"id":8326656},{"batb":[[0,4.1,42.33]],"ltp":3.1,"tv":0.0,"id":9712909}]}]}
{"op":"mcm","clk":"1003180809","pt":1580604011579,"mc":[{"id":"1.168179123","rc":[{"batb":[[0,1.27,169.95]],"ltp":1.48,"tv":0.01,"id":8326656}]}]}
{"op":"mcm","clk":"1003181789","pt":1580604026895,"mc":[{"id":"1.168179123","rc":[{"batb":[[0,1.28,1.97],[1,1.27,169.95],[2,1.04,2.02]],"ltp":1.48,"tv":0.01,"id":8326656},{"batb":[[1,1.01,16.62]],"ltp":3.1,"tv":0.0,"id":9712909}]}]}
{"op":"mcm","clk":"1003181842","pt":1580604027813,"mc":[{"id":"1.168179123","rc":[{"batb":[[0,4.1,42.93],[1,1.01,16.02]],"ltp":3.1,"tv":0.0,"id":9712909}]}]}
{"op":"mcm","clk":"1003181896","pt":1580604028638,"mc":[{"id":"1.168179123","rc":[{"batb":[[1,1.27,167.44]],"ltp":1.48,"tv":0.01,"id":8326656}]}]}
{"op":"mcm","clk":"1003182536","pt":1580604038831,"mc":[{"id":"1.168179123","rc":[{"batb":[[1,1.27,164.84]],"ltp":1.48,"tv":0.01,"id":8326656},{"batb":[[0,4,45.76]],"ltp":3.1,"tv":0.0,"id":9712909}]}]}
{"op":"mcm","clk":"1003199590","pt":1580604319848,"mc":[{"id":"1.168179123","marketDefinition":{"bspMarket":false,"turnInPlayEnabled":true,"persistenceEnabled":true,"marketBaseRate":5.0,"eventId":"29680182","eventTypeId":"2","numberOfWinners":1,"bettingType":"ODDS","marketType":"SET_WINNER","marketTime":"2020-02-02T00:32:00.000Z","suspendTime":"2020-02-02T00:32:00.000Z","bspReconciled":false,"complete":true,"inPlay":false,"crossMatching":true,"runnersVoidable":false,"numberOfActiveRunners":2,"betDelay":0,"status":"SUSPENDED","runners":[{"status":"ACTIVE","sortPriority":1,"id":9712909,"name":"Felipe Meligeni Rodrigu"},{"status":"ACTIVE","sortPriority":2,"id":8326656,"name":"Thiago Monteiro"}],"regulators":["MR_INT"],"countryCode":"UY","discountAllowed":true,"timezone":"UTC","openDate":"2020-02-02T00:32:00.000Z","version":3147941533,"name":"Set 2 Winner","eventName":"Meligeni Rodrigues Alve v T Monteiro"},"rc":[{"batb":[[1,1.04,2.02],[2,1.03,2.02]],"ltp":1.48,"tv":0.01,"id":8326656},{"batb":[[0,1.01,16.62],[1,1.01,0]],"ltp":3.1,"tv":0.0,"id":9712909}]}]}
{"op":"mcm","clk":"1003199616","pt":1580604320259,"mc":[{"id":"1.168179123","marketDefinition":{"bspMarket":false,"turnInPlayEnabled":true,"persistenceEnabled":true,"marketBaseRate":5.0,"eventId":"29680182","eventTypeId":"2","numberOfWinners":1,"bettingType":"ODDS","marketType":"SET_WINNER","marketTime":"2020-02-02T00:32:00.000Z","suspendTime":"2020-02-02T00:32:00.000Z","bspReconciled":false,"complete":true,"inPlay":true,"crossMatching":true,"runnersVoidable":false,"numberOfActiveRunners":2,"betDelay":3,"status":"OPEN","runners":[{"status":"ACTIVE","sortPriority":1,"id":9712909,"name":"Felipe Meligeni Rodrigu"},{"status":"ACTIVE","sortPriority":2,"id":8326656,"name":"Thiago Monteiro"}],"regulators":["MR_INT"],"countryCode":"UY","discountAllowed":true,"timezone":"UTC","openDate":"2020-02-02T00:32:00.000Z","version":3147941799,"name":"Set 2 Winner","eventName":"Meligeni Rodrigues Alve v T Monteiro"},"rc":[{"batb":[[0,1.01,15.51],[1,1.04,0],[2,1.03,0]],"ltp":1.48,"tv":0.01,"id":8326656},{"batb":[[0,1.01,15.52]],"ltp":3.1,"tv":0.0,"id":9712909}]}]}
{"op":"mcm","clk":"1003200280","pt":1580604330575,"mc":[{"id":"1.168179123","rc":[{"batb":[[0,1.29,153.43],[1,1.28,160.83],[2,1.01,15.51]],"ltp":1.48,"tv":0.01,"id":8326656},{"batb":[[0,3.9,50.04],[1,3.7,28.25],[2,1.01,15.52]],"ltp":3.1,"tv":0.0,"id":9712909}]}]}
{"op":"mcm","clk":"1003201454","pt":1580604349490,"mc":[{"id":"1.168179123","rc":[{"batb":[[0,1.28,160.83],[1,1.01,15.51],[2,1.01,0]],"ltp":1.48,"tv":0.01,"id":8326656},{"batb":[[0,3.7,28.25],[1,1.01,15.52],[2,1.01,0]],"ltp":3.1,"tv":0.0,"id":9712909}]}]}
{"op":"mcm","clk":"1003201481","pt":1580604349901,"mc":[{"id":"1.168179123","rc":[{"batb":[[0,3.7,27.93]],"ltp":3.1,"tv":0.0,"id":9712909}]}]}
{"op":"mcm","clk":"1003202839","pt":1580604372793,"mc":[{"id":"1.168179123","rc":[{"batb":[[0,1.31,140.53],[1,1.3,148.94],[2,1.29,2519.67]],"ltp":1.48,"tv":0.01,"id":8326656},{"batb":[[1,3.5,31.79],[2,1.01,15.52]],"ltp":3.1,"tv":0.0,"id":9712909}]}]}
{"op":"mcm","clk":"1003203652","pt":1580604388716,"mc":[{"id":"1.168179123","rc":[{"batb":[[0,1.3,148.94],[1,1.01,15.51],[2,1.29,0]],"ltp":1.48,"tv":0.01,"id":8326656},{"batb":[[0,3.5,31.79],[1,1.01,15.52],[2,1.01,0]],"ltp":3.1,"tv":0.0,"id":9712909}]}]}
{"op":"mcm","clk":"1003204105","pt":1580604396767,"mc":[{"id":"1.168179123","rc":[{"batb":[[1,1.28,158.31],[2,1.01,15.51]],"ltp":1.48,"tv":0.01,"id":8326656},{"batb":[[0,3.8,52.17],[1,3.6,29.98],[2,3.5,114.94]],"ltp":3.1,"tv":0.0,"id":9712909}]}]}
{"op":"mcm","clk":"1003204117","pt":1580604397024,"mc":[{"id":"1.168179123","rc":[{"batb":[[2,1.01,15.52]],"ltp":3.1,"tv":0.0,"id":9712909}]}]}
{"op":"mcm","clk":"1003204817","pt":1580604409861,"mc":[{"id":"1.168179123","rc":[{"batb":[[0,1.28,158.31],[1,1.01,15.51],[2,1.01,0]],"ltp":1.48,"tv":0.01,"id":8326656},{"batb":[[0,3.6,29.98],[1,1.01,15.52],[2,1.01,0]],"ltp":3.1,"tv":0.0,"id":9712909}]}]}
{"op":"mcm","clk":"1003205822","pt":1580604426784,"mc":[{"id":"1.168179123","rc":[{"batb":[[0,1.32,137.38],[1,1.3,146.43],[2,1.29,2541.36]],"ltp":1.48,"tv":0.01,"id":8326656},{"batb":[[0,3.65,28.8],[1,3.6,29.98],[2,3.45,33.36]],"ltp":3.1,"tv":0.0,"id":9712909}]}]}
{"op":"mcm","clk":"1003205867","pt":1580604427402,"mc":[{"id":"1.168179123","rc":[{"batb":[[2,1.01,15.51]],"ltp":1.48,"tv":0.01,"id":8326656},{"batb":[[1,3.45,33.36],[2,1.01,15.52]],"ltp":3.1,"tv":0.0,"id":9712909}]}]}
{"op":"mcm","clk":"1003206200","pt":1580604433394,"mc":[{"id":"1.168179123","rc":[{"batb":[[0,1.32,2620.02]],"ltp":1.48,"tv":0.01,"id":8326656}]}]}
{"op":"mcm","clk":"1003206721","pt":1580604443725,"mc":[{"id":"1.168179123","rc":[{"batb":[[0,1.3,146.43],[1,1.01,15.51],[2,1.01,0]],"ltp":1.48,"tv":0.01,"id":8326656},{"batb":[[0,3.45,33.36],[1,1.01,15.52],[2,1.01,0]],"ltp":3.1,"tv":0.0,"id":9712909}]}]}
{"op":"mcm","clk":"1003208942","pt":1580604484668,"mc":[{"id":"1.168179123","rc":[{"batb":[[1,1.28,158.62],[2,1.01,15.51]],"ltp":1.48,"tv":0.01,"id":8326656},{"batb":[[0,3.8,26.75],[1,3.5,31.87],[2,1.01,15.52]],"ltp":3.1,"tv":0.0,"id":9712909}]}]}
{"op":"mcm","clk":"1003210088","pt":1580604505569,"mc":[{"id":"1.168179123","rc":[{"batb":[[0,1.28,158.62],[1,1.01,15.51],[2,1.01,0]],"ltp":1.48,"tv":0.01,"id":8326656},{"batb":[[0,3.5,31.87],[1,1.01,15.52],[2,1.01,0]],"ltp":3.1,"tv":0.0,"id":9712909}]}]}
{"op":"mcm","clk":"1003211933","pt":1580604536642,"mc":[{"id":"1.168179123","rc":[{"batb":[[0,1.34,127.62],[1,1.32,138.09],[2,1.3,2362.98]],"ltp":1.48,"tv":0.01,"id":8326656},{"batb":[[1,3.4,34.93],[2,1.01,15.52]],"ltp":3.1,"tv":0.0,"id":9712909}]}]}
{"op":"mcm","clk":"1003214314","pt":1580604573256,"mc":[{"id":"1.168179123","rc":[{"batb":[[2,1.01,15.51]],"ltp":1.48,"tv":0.01,"id":8326656}]}]}
{"op":"mcm","clk":"1003214522","pt":1580604576246,"mc":[{"id":"1.168179123","rc":[{"batb":[[2,1.3,312.28]],"ltp":1.48,"tv":0.01,"id":8326656}]}]}
{"op":"mcm","clk":"1003215286","pt":1580604586784,"mc":[{"id":"1.168179123","rc":[{"batb":[[0,1.32,138.09],[1,1.01,15.51],[2,1.3,0]],"ltp":1.48,"tv":0.01,"id":8326656},{"batb":[[0,3.4,34.93],[1,1.01,15.52],[2,1.01,0]],"ltp":3.1,"tv":0.0,"id":9712909}]}]}
{"op":"mcm","clk":"1003215524","pt":1580604589875,"mc":[{"id":"1.168179123","rc":[{"batb":[[0,1.32,135.1]],"ltp":1.48,"tv":0.01,"id":8326656},{"batb":[[0,3.35,36.04]],"ltp":3.1,"tv":0.0,"id":9712909}]}]}
{"op":"mcm","clk":"1003216517","pt":1580604604593,"mc":[{"id":"1.168179123","rc":[{"batl":[[0,1.89,435.28]],"ltp":1.48,"tv":0.01,"id":8326656},{"batl":[[0,4.2,148.03]],"ltp":3.1,"tv":0.0,"id":9712909}]}]}
{"op":"mcm","clk":"1003217060","pt":1580604611836,"mc":[{"id":"1.168179123","rc":[{"batb":[[1,1.3,148.39],[2,1.01,15.51]],"ltp":1.48,"tv":0.01,"id":8326656},{"batb":[[0,3.65,29.43],[1,3.5,47.6],[2,1.01,15.52]],"ltp":3.1,"tv":0.0,"id":9712909}]}]}
{"op":"mcm","clk":"1003218072","pt":1580604626731,"mc":[{"id":"1.168179123","rc":[{"batb":[[0,1.3,148.39],[1,1.01,15.51],[2,1.01,0]],"ltp":1.48,"tv":0.01,"id":8326656},{"batb":[[0,3.5,32.02],[1,1.01,15.52],[2,1.01,0]],"ltp":3.1,"tv":0.0,"id":9712909}]}]}
{"op":"mcm","clk":"1003218972","pt":1580604640765,"mc":[{"id":"1.168179123","rc":[{"batb":[[0,1.34,126.99],[1,1.32,137.14],[2,1.01,15.51]],"ltp":1.48,"tv":0.01,"id":8326656},{"batb":[[1,3.35,35.49],[2,1.01,15.52]],"batl":[[0,4.1,98.85],[1,4.2,148.03]],"ltp":3.1,"tv":0.0,"id":9712909}]}]}
{"op":"mcm","clk":"1003219920","pt":1580604655294,"mc":[{"id":"1.168179123","rc":[{"batb":[[0,1.32,137.14],[1,1.01,15.51],[2,1.01,0]],"ltp":1.48,"tv":0.01,"id":8326656},{"batb":[[0,3.35,35.49],[1,1.01,15.52],[2,1.01,0]],"batl":[[0,4.2,148.03],[1,4.2,0]],"ltp":3.1,"tv":0.0,"id":9712909}]}]}
{"op":"mcm","clk":"1003220500","pt":1580604664791,"mc":[{"id":"1.168179123","rc":[{"batb":[[1,1.29,151.78],[2,1.01,15.51]],"ltp":1.48,"tv":0.01,"id":8326656},{"batb":[[0,3.65,28.88],[1,3.5,31.87],[2,3.35,19.07]],"ltp":3.1,"tv":0.0,"id":9712909}]}]}
{"op":"mcm","clk":"1003221635","pt":1580604682803,"mc":[{"id":"1.168179123","rc":[{"batb":[[0,1.29,151.78],[1,1.01,15.51],[2,1.01,0]],"ltp":1.48,"tv":0.01,"id":8326656},{"batb":[[0,3.5,31.87],[1,1.01,15.52],[2,3.35,0]],"ltp":3.1,"tv":0.0,"id":9712909}]}]}
{"op":"mcm","clk":"1003223070","pt":1580604701204,"mc":[{"id":"1.168179123","rc":[{"batb":[[1,1.27,167.59],[2,1.01,15.51]],"ltp":1.48,"tv":0.01,"id":8326656},{"batb":[[0,3.85,50.83],[1,3.75,27.62],[2,3.5,114.94]],"ltp":3.1,"tv":0.0,"id":9712909}]}]}
{"op":"mcm","clk":"1003223208","pt":1580604703217,"mc":[{"id":"1.168179123","rc":[{"batl":[[0,1.77,500.61]],"ltp":1.48,"tv":0.01,"id":8326656},{"batb":[[2,1.01,15.52]],"batl":[[0,4.9,126.27]],"ltp":3.1,"tv":0.0,"id":9712909}]}]}
{"op":"mcm","clk":"1003224381","pt":1580604721545,"mc":[{"id":"1.168179123","rc":[{"batb":[[0,1.27,167.59],[1,1.01,15.51],[2,1.01,0]],"ltp":1.48,"tv":0.01,"id":8326656},{"batb":[[0,3.75,27.62],[1,1.01,15.52],[2,1.01,0]],"ltp":3.1,"tv":0.0,"id":9712909}]}]}
{"op":"mcm","clk":"1003224578","pt":1580604724742,"mc":[{"id":"1.168179123","rc":[{"batb":[[0,1.26,172.16]],"ltp":1.48,"tv":0.01,"id":8326656},{"batb":[[0,3.75,26.91]],"ltp":3.1,"tv":0.0,"id":9712909}]}]}
{"op":"mcm","clk":"1003224979","pt":1580604730580,"mc":[{"id":"1.168179123","rc":[{"batb":[[1,1.25,180.81],[2,1.01,15.51]],"ltp":1.48,"tv":0.01,"id":8326656},{"batb":[[0,4.1,42.41],[1,3.95,48],[2,3.75,883.99]],"ltp":3.1,"tv":0.0,"id":9712909}]}]}
{"op":"mcm","clk":"1003226586","pt":1580604755814,"mc":[{"id":"1.168179123","rc":[{"batb":[[0,1.25,180.81],[1,1.01,15.51],[2,1.01,0]],"ltp":1.48,"tv":0.01,"id":8326656},{"batb":[[0,3.95,48],[1,1.01,15.52],[2,3.75,0]],"ltp":3.1,"tv":0.0,"id":9712909}]}]}
{"op":"mcm","clk":"1003228286","pt":1580604780348,"mc":[{"id":"1.168179123","rc":[{"batb":[[0,1.28,157.6],[1,1.27,166.81],[2,1.01,15.51]],"ltp":1.48,"tv":0.01,"id":8326656},{"batb":[[1,3.75,27.07],[2,1.01,15.52]],"batl":[[0,4.6,695.46]],"ltp":3.1,"tv":0.0,"id":9712909}]}]}
{"op":"mcm","clk":"1003228438","pt":1580604782648,"mc":[{"id":"1.168179123","rc":[{"batl":[[0,4.6,135.57]],"ltp":3.1,"tv":0.0,"id":9712909}]}]}
{"op":"mcm","clk":"1003228666","pt":1580604785746,"mc":[{"id":"1.168179123","rc":[{"batb":[[0,1.29,2480.12],[1,1.28,157.6],[2,1.27,166.81]],"ltp":1.48,"tv":0.01,"id":8326656}]}]}
{"op":"mcm","clk":"1003229656","pt":1580604801332,"mc":[{"id":"1.168179123","rc":[{"batb":[[0,1.27,166.81],[1,1.01,15.51],[2,1.27,0]],"ltp":1.48,"tv":0.01,"id":8326656},{"batb":[[0,3.75,27.07],[1,1.01,15.52],[2,1.01,0]],"ltp":3.1,"tv":0.0,"id":9712909}]}]}
{"op":"mcm","clk":"1003230814","pt":1580604819799,"mc":[{"id":"1.168179123","rc":[{"batb":[[1,1.26,176.72],[2,1.01,15.51]],"ltp":1.48,"tv":0.01,"id":8326656},{"batb":[[0,4.1,44.46],[1,3.85,51.3],[2,1.01,15.52]],"ltp":3.1,"tv":0.0,"id":9712909}]}]}
{"op":"mcm","clk":"1003231978","pt":1580604838638,"mc":[{"id":"1.168179123","rc":[{"batb":[[0,1.26,176.72],[1,1.01,15.51],[2,1.01,0]],"ltp":1.48,"tv":0.01,"id":8326656},{"batb":[[0,3.85,51.3],[1,1.01,15.52],[2,1.01,0]],"ltp":3.1,"tv":0.0,"id":9712909}]}]}
{"op":"mcm","clk":"1003233201","pt":1580604859850,"mc":[{"id":"1.168179123","rc":[{"batb":[[1,1.25,186.48],[2,1.01,15.51]],"ltp":1.48,"tv":0.01,"id":8326656},{"batb":[[0,4.2,40.84],[1,4,46.19],[2,3.85,51.3]],"ltp":3.1,"tv":0.0,"id":9712909}]}]}
{"op":"mcm","clk":"1003233251","pt":1580604860834,"mc":[{"id":"1.168179123","rc":[{"batb":[[2,3.95,28.31]],"ltp":3.1,"tv":0.0,"id":9712909}]}]}
{"op":"mcm","clk":"1003234301","pt":1580604879859,"mc":[{"id":"1.168179123","rc":[{"batb":[[2,1.01,15.52]],"ltp":3.1,"tv":0.0,"id":9712909}]}]}
{"op":"mcm","clk":"1003234334","pt":1580604880371,"mc":[{"id":"1.168179123","rc":[{"batb":[[0,1.25,183.96],[1,1.01,15.51],[2,1.01,0]],"ltp":1.48,"tv":0.01,"id":8326656},{"batb":[[0,4,46.19],[1,1.01,15.52],[2,1.01,0]],"ltp":3.1,"tv":0.0,"id":9712909}]}]}
{"op":"mcm","clk":"1003235375","pt":1580604899722,"mc":[{"id":"1.168179123","rc":[{"batb":[[1,1.24,189.23],[2,1.01,15.51]],"ltp":1.48,"tv":0.01,"id":8326656},{"batb":[[0,4.3,38.55],[1,4.1,43.12],[2,1.01,15.52]],"ltp":3.1,"tv":0.0,"id":9712909}]}]}
{"op":"mcm","clk":"1003235396","pt":1580604899975,"mc":[{"id":"1.168179123","rc":[{"batb":[[1,4.1,63.46]],"ltp":3.1,"tv":0.0,"id":9712909}]}]}
{"op":"mcm","clk":"1003235485","pt":1580604901525,"mc":[{"id":"1.168179123","rc":[{"batb":[[1,4.1,43.12]],"batl":[[0,5.3,118.43]],"ltp":3.1,"tv":0.0,"id":9712909}]}]}
{"op":"mcm","clk":"1003236647","pt":1580604924806,"mc":[{"id":"1.168179123","rc":[{"batb":[[0,1.24,189.23],[1,1.01,15.51],[2,1.01,0]],"ltp":1.48,"tv":0.01,"id":8326656},{"batb":[[0,4.1,43.12],[1,1.01,15.52],[2,1.01,0]],"ltp":3.1,"tv":0.0,"id":9712909}]}]}
{"op":"mcm","clk":"1003236999","pt":1580604932858,"mc":[{"id":"1.168179123","rc":[{"batb":[[1,1.23,205.52],[2,1.01,15.51]],"ltp":1.48,"tv":0.01,"id":8326656},{"batb":[[0,4.4,36.98],[1,4.2,40.68],[2,1.01,15.52]],"ltp":3.1,"tv":0.0,"id":9712909}]}]}
{"op":"mcm","clk":"1003237026","pt":1580604933840,"mc":[{"id":"1.168179123","rc":[{"batb":[[1,4.2,60.1]],"ltp":3.1,"tv":0.0,"id":9712909}]}]}
{"op":"mcm","clk":"1003237515","pt":1580604945634,"mc":[{"id":"1.168179123","rc":[{"batb":[[1,4.2,40.68]],"ltp":3.1,"tv":0.0,"id":9712909}]}]}
{"op":"mcm","clk":"1003238162","pt":1580604958803,"mc":[{"id":"1.168179123","rc":[{"batb":[[0,1.25,184.82],[1,1.24,189.23],[2,1.23,205.52]],"ltp":1.48,"tv":0.01,"id":8326656},{"batb":[[1,4.3,38.32],[2,4.2,40.68]],"ltp":3.1,"tv":0.0,"id":9712909}]}]}
{"op":"mcm","clk":"1003238205","pt":1580604959791,"mc":[{"id":"1.168179123","rc":[{"batb":[[1,1.23,200.95],[2,1.01,15.51]],"ltp":1.48,"tv":0.01,"id":8326656},{"batb":[[0,4.3,38.32],[1,4.2,40.68],[2,1.01,15.52]],"ltp":3.1,"tv":0.0,"id":9712909}]}]}
{"op":"mcm","clk":"1003241178","pt":1580605007643,"mc":[{"id":"1.168179123","rc":[{"batb":[[0,1.23,200.95],[1,1.01,15.51],[2,1.01,0]],"ltp":1.48,"tv":0.01,"id":8326656},{"batb":[[0,4.2,40.68],[1,1.01,15.52],[2,1.01,0]],"ltp":3.1,"tv":0.0,"id":9712909}]}]}
{"op":"mcm","clk":"1003241913","pt":1580605018792,"mc":[{"id":"1.168179123","rc":[{"batb":[[0,1.26,173.02],[1,1.24,187.74],[2,1.01,15.51]],"ltp":1.48,"tv":0.01,"id":8326656},{"batb":[[1,4,45.71],[2,1.01,15.52]],"ltp":3.1,"tv":0.0,"id":9712909}]}]}
{"op":"mcm","clk":"1003242126","pt":1580605021973,"mc":[{"id":"1.168179123","rc":[{"batb":[[0,1.26,2674.73]],"ltp":1.48,"tv":0.01,"id":8326656}]}]}
{"op":"mcm","clk":"1003242654","pt":1580605030799,"mc":[{"id":"1.168179123","rc":[{"batb":[[0,1.24,187.74],[1,1.01,15.51],[2,1.01,0]],"ltp":1.48,"tv":0.01,"id":8326656},{"batb":[[0,4,45.71],[1,1.01,15.52],[2,1.01,0]],"ltp":3.1,"tv":0.0,"id":9712909}]}]}
{"op":"mcm","clk":"1003243167","pt":1580605039719,"mc":[{"id":"1.168179123","rc":[{"batb":[[0,1.28,163.58],[1,1.26,174.75],[2,1.24,187.74]],"ltp":1.48,"tv":0.01,"id":8326656},{"batb":[[1,3.9,49.57],[2,1.01,15.52]],"ltp":3.1,"tv":0.0,"id":9712909}]}]}
{"op":"mcm","clk":"1003243205","pt":1580605040485,"mc":[{"id":"1.168179123","rc":[{"batb":[[2,1.01,15.51]],"ltp":1.48,"tv":0.01,"id":8326656},{"batl":[[0,4.9,126.27]],"ltp":3.1,"tv":0.0,"id":9712909}]}]}
{"op":"mcm","clk":"1003243826","pt":1580605052547,"mc":[{"id":"1.168179123","rc":[{"batb":[[0,1.26,174.75],[1,1.01,15.51],[2,1.01,0]],"ltp":1.48,"tv":0.01,"id":8326656},{"batb":[[0,3.9,49.57],[1,1.01,15.52],[2,1.01,0]],"ltp":3.1,"tv":0.0,"id":9712909}]}]}
{"op":"mcm","clk":"1003244397","pt":1580605061639,"mc":[{"id":"1.168179123","rc":[{"batb":[[0,1.29,154.53],[1,1.27,165.7],[2,1.01,15.51]],"ltp":1.48,"tv":0.01,"id":8326656},{"batb":[[1,3.8,26.44],[2,1.01,15.52]],"ltp":3.1,"tv":0.0,"id":9712909}]}]}
{"op":"mcm","clk":"1003244438","pt":1580605062513,"mc":[{"id":"1.168179123","rc":[{"batl":[[0,4.6,136.05]],"ltp":3.1,"tv":0.0,"id":9712909}]}]}
{"op":"mcm","clk":"1003244914","pt":1580605072463,"mc":[{"id":"1.168179123","rc":[{"batb":[[0,1.27,165.7],[1,1.01,15.51],[2,1.01,0]],"ltp":1.48,"tv":0.01,"id":8326656},{"batb":[[0,3.8,26.44],[1,1.01,15.52],[2,1.01,0]],"ltp":3.1,"tv":0.0,"id":9712909}]}]}
{"op":"mcm","clk":"1003248391","pt":1580605135627,"mc":[{"id":"1.168179123","rc":[{"batb":[[1,1.26,176.96],[2,1.01,15.51]],"ltp":1.48,"tv":0.01,"id":8326656},{"batb":[[0,4,44.77],[1,3.95,48.55],[2,3.8,26.44]],"ltp":3.1,"tv":0.0,"id":9712909}]}]}
{"op":"mcm","clk":"1003248418","pt":1580605136140,"mc":[{"id":"1.168179123","rc":[{"batb":[[2,1.01,15.52]],"ltp":3.1,"tv":0.0,"id":9712909}]}]}
{"op":"mcm","clk":"1003249299","pt":1580605152383,"mc":[{"id":"1.168179123","rc":[{"batb":[[0,1.26,176.96],[1,1.01,15.51],[2,1.01,0]],"ltp":1.48,"tv":0.01,"id":8326656},{"batb":[[0,3.95,48.55],[1,1.01,15.52],[2,1.01,0]],"ltp":3.1,"tv":0.0,"id":9712909}]}]}
{"op":"mcm","clk":"1003249455","pt":1580605154858,"mc":[{"id":"1.168179123","rc":[{"batb":[[1,1.25,183.56],[2,1.01,15.51]],"ltp":1.48,"tv":0.01,"id":8326656}]}]}
{"op":"mcm","clk":"1003249503","pt":1580605155680,"mc":[{"id":"1.168179123","rc":[{"batb":[[0,1.25,183.56],[1,1.01,15.51],[2,1.01,0]],"ltp":1.48,"tv":0.01,"id":8326656},{"batb":[[0,1.01,15.52],[1,1.01,0]],"ltp":3.1,"tv":0.0,"id":9712909}]}]}
{"op":"mcm","clk":"1003250384","pt":1580605172507,"mc":[{"id":"1.168179123","rc":[{"batb":[[0,1.28,162.87],[1,1.26,171.92],[2,1.01,15.51]],"ltp":1.48,"tv":0.01,"id":8326656},{"batb":[[0,4,45.95],[1,3.8,52.4],[2,1.01,15.52]],"batl":[[0,4.5,705.69],[1,4.6,136.05]],"ltp":3.1,"tv":0.0,"id":9712909}]}]}
{"op":"mcm","clk":"1003251507","pt":1580605193745,"mc":[{"id":"1.168179123","rc":[{"batb":[[0,1.26,171.53],[1,1.01,15.51],[2,1.01,0]],"ltp":1.48,"tv":0.01,"id":8326656},{"batb":[[0,3.8,52.4],[1,1.01,15.52],[2,1.01,0]],"batl":[[0,4.6,136.05],[1,4.6,0]],"ltp":3.1,"tv":0.0,"id":9712909}]}]}
{"op":"mcm","clk":"1003253780","pt":1580605228817,"mc":[{"id":"1.168179123","rc":[{"batb":[[0,4.1,42.65],[1,3.95,48.7],[2,1.01,15.52]],"ltp":3.1,"tv":0.0,"id":9712909}]}]}
{"op":"mcm","clk":"1003254748","pt":1580605243442,"mc":[{"id":"1.168179123","rc":[{"batb":[[0,3.95,48.7],[1,1.01,15.52],[2,1.01,0]],"ltp":3.1,"tv":0.0,"id":9712909}]}]}
{"op":"mcm","clk":"1003256291","pt":1580605264777,"mc":[{"id":"1.168179123","rc":[{"batb":[[1,1.25,185.45],[2,1.01,15.51]],"ltp":1.48,"tv":0.01,"id":8326656},{"batb":[[0,4.2,40.44],[1,4,73.62],[2,1.01,15.52]],"ltp":3.1,"tv":0.0,"id":9712909}]}]}
{"op":"mcm","clk":"1003256449","pt":1580605267290,"mc":[{"id":"1.168179123","rc":[{"batb":[[1,4,45.32]],"batl":[[0,5.3,118.09]],"ltp":3.1,"tv":0.0,"id":9712909}]}]}
{"op":"mcm","clk":"1003257656","pt":1580605285894,"mc":[{"id":"1.168179123","rc":[{"batb":[[0,1.25,185.06],[1,1.01,15.51],[2,1.01,0]],"ltp":1.48,"tv":0.01,"id":8326656},{"batb":[[0,4,45.32],[1,1.01,15.52],[2,1.01,0]],"ltp":3.1,"tv":0.0,"id":9712909}]}]}
{"op":"mcm","clk":"1003258868","pt":1580605303794,"mc":[{"id":"1.168179123","rc":[{"batb":[[1,1.24,193.16],[2,1.01,15.51]],"ltp":1.48,"tv":0.01,"id":8326656},{"batb":[[0,4.3,38.24],[1,4.1,70.49],[2,1.01,15.52]],"ltp":3.1,"tv":0.0,"id":9712909}]}]}
{"op":"mcm","clk":"1003259862","pt":1580605316726,"mc":[{"id":"1.168179123","rc":[{"batb":[[0,1.24,193.16],[1,1.01,15.51],[2,1.01,0]],"ltp":1.48,"tv":0.01,"id":8326656},{"batb":[[0,4.1,42.25],[1,1.01,15.52],[2,1.01,0]],"ltp":3.1,"tv":0.0,"id":9712909}]}]}
{"op":"mcm","clk":"1003260449","pt":1580605323756,"mc":[{"id":"1.168179123","rc":[{"batb":[[1,1.22,211.58],[2,1.01,15.51]],"ltp":1.48,"tv":0.01,"id":8326656},{"batb":[[0,4.5,35.88],[1,4.3,39.34],[2,4.1,42.25]],"ltp":3.1,"tv":0.0,"id":9712909}]}]}
{"op":"mcm","clk":"1003260480","pt":1580605324165,"mc":[{"id":"1.168179123","rc":[{"batb":[[1,4.3,58.12],[2,1.01,15.52]],"ltp":3.1,"tv":0.0,"id":9712909}]}]}
{"op":"mcm","clk":"1003261784","pt":1580605342773,"mc":[{"id":"1.168179123","rc":[{"batb":[[1,4.3,39.34]],"ltp":3.1,"tv":0.0,"id":9712909}]}]}
{"op":"mcm","clk":"1003262077","pt":1580605346798,"mc":[{"id":"1.168179123","rc":[{"batb":[[0,1.24,192.69],[1,1.22,211.02]],"ltp":1.48,"tv":0.01,"id":8326656},{"batb":[[0,4.4,35.96]],"ltp":3.1,"tv":0.0,"id":9712909}]}]}
{"op":"mcm","clk":"1003262572","pt":1580605353816,"mc":[{"id":"1.168179123","rc":[{"batb":[[0,1.24,191.91],[1,1.22,210.24]],"ltp":1.48,"tv":0.01,"id":8326656}]}]}
{"op":"mcm","clk":"1003265370","pt":1580605396878,"mc":[{"id":"1.168179123","rc":[{"batb":[[0,1.22,210.24],[1,1.01,15.51],[2,1.01,0]],"ltp":1.48,"tv":0.01,"id":8326656},{"batb":[[0,4.3,39.34],[1,1.01,15.52],[2,1.01,0]],"ltp":3.1,"tv":0.0,"id":9712909}]}]}
{"op":"mcm","clk":"1003266197","pt":1580605408864,"mc":[{"id":"1.168179123","rc":[{"batb":[[0,1.25,180.18],[1,1.24,196.31],[2,1.01,15.51]],"ltp":1.48,"tv":0.01,"id":8326656},{"batb":[[1,4.1,43.51],[2,1.01,15.52]],"ltp":3.1,"tv":0.0,"id":9712909}]}]}
{"op":"mcm","clk":"1003266389","pt":1580605411904,"mc":[{"id":"1.168179123","rc":[{"batb":[[0,1.26,2501.71],[1,1.25,180.18],[2,1.24,196.31]],"ltp":1.48,"tv":0.01,"id":8326656}]}]}
{"op":"mcm","clk":"1003266906","pt":1580605418687,"mc":[{"id":"1.168179123","rc":[{"batb":[[0,1.24,196.31],[1,1.01,15.51],[2,1.24,0]],"ltp":1.48,"tv":0.01,"id":8326656},{"batb":[[0,4.1,43.51],[1,1.01,15.52],[2,1.01,0]],"ltp":3.1,"tv":0.0,"id":9712909}]}]}
{"op":"mcm","clk":"1003268921","pt":1580605448740,"mc":[{"id":"1.168179123","rc":[{"batb":[[0,1.27,169.17],[1,1.26,2504.71],[2,1.25,182.54]],"ltp":1.48,"tv":0.01,"id":8326656},{"batb":[[1,4,46.82],[2,1.01,15.52]],"ltp":3.1,"tv":0.0,"id":9712909}]}]}
{"op":"mcm","clk":"1003269131","pt":1580605451638,"mc":[{"id":"1.168179123","rc":[{"batl":[[0,4.9,126.27]],"ltp":3.1,"tv":0.0,"id":9712909}]}]}
{"op":"mcm","clk":"1003270450","pt":1580605469552,"mc":[{"id":"1.168179123","rc":[{"batb":[[0,1.25,182.54],[1,1.01,15.51],[2,1.25,0]],"ltp":1.48,"tv":0.01,"id":8326656},{"batb":[[0,4,46.82],[1,1.01,15.52],[2,1.01,0]],"ltp":3.1,"tv":0.0,"id":9712909}]}]}
{"op":"mcm","clk":"1003271620","pt":1580605484393,"mc":[{"id":"1.168179123","rc":[{"batb":[[0,1.28,160.75],[1,1.26,172.23],[2,1.01,15.51]],"ltp":1.48,"tv":0.01,"id":8326656},{"batb":[[1,3.85,50.75],[2,1.01,15.52]],"batl":[[0,4.8,661.92],[1,4.9,126.27]],"ltp":3.1,"tv":0.0,"id":9712909}]}]}
{"op":"mcm","clk":"1003272439","pt":1580605495791,"mc":[{"id":"1.168179123","rc":[{"batb":[[0,1.26,172.23],[1,1.01,15.51],[2,1.01,0]],"ltp":1.48,"tv":0.01,"id":8326656},{"batb":[[0,3.85,50.75],[1,1.01,15.52],[2,1.01,0]],"batl":[[0,4.9,126.27],[1,4.9,0]],"ltp":3.1,"tv":0.0,"id":9712909}]}]}
{"op":"mcm","clk":"1003273657","pt":1580605511703,"mc":[{"id":"1.168179123","rc":[{"batb":[[1,1.25,185.69],[2,1.01,15.51]],"ltp":1.48,"tv":0.01,"id":8326656},{"batb":[[0,4.1,42.41],[1,4,46.03],[2,3.9,28.16]],"ltp":3.1,"tv":0.0,"id":9712909}]}]}
{"op":"mcm","clk":"1003274686","pt":1580605525620,"mc":[{"id":"1.168179123","rc":[{"batb":[[0,1.25,185.69],[1,1.01,15.51],[2,1.01,0]],"ltp":1.48,"tv":0.01,"id":8326656},{"batb":[[0,4,46.03],[1,1.01,15.52],[2,3.9,0]],"ltp":3.1,"tv":0.0,"id":9712909}]}]}
{"op":"mcm","clk":"1003275468","pt":1580605536645,"mc":[{"id":"1.168179123","rc":[{"batb":[[1,1.23,203.24],[2,1.01,15.51]],"ltp":1.48,"tv":0.01,"id":8326656},{"batb":[[0,4.3,38],[1,4.2,41.7],[2,4,46.03]],"ltp":3.1,"tv":0.0,"id":9712909}]}]}
{"op":"mcm","clk":"1003275525","pt":1580605537422,"mc":[{"id":"1.168179123","rc":[{"batb":[[2,4.1,28.34]],"ltp":3.1,"tv":0.0,"id":9712909}]}]}
{"op":"mcm","clk":"1003276939","pt":1580605557580,"mc":[{"id":"1.168179123","rc":[{"batb":[[0,1.23,203.24],[1,1.01,15.51],[2,1.01,0]],"ltp":1.48,"tv":0.01,"id":8326656},{"batb":[[0,4.2,41.7],[1,1.01,15.52],[2,4.1,0]],"ltp":3.1,"tv":0.0,"id":9712909}]}]}
{"op":"mcm","clk":"1003279390","pt":1580605590818,"mc":[{"id":"1.168179123","rc":[{"batb":[[0,1.26,174.28],[1,1.25,182.46],[2,1.23,203.24]],"ltp":1.48,"tv":0.01,"id":8326656},{"batb":[[1,3.95,48.86],[2,1.01,15.52]],"ltp":3.1,"tv":0.0,"id":9712909}]}]}
{"op":"mcm","clk":"1003279440","pt":1580605591385,"mc":[{"id":"1.168179123","rc":[{"batb":[[2,1.01,15.51]],"ltp":1.48,"tv":0.01,"id":8326656}]}]}
{"op":"mcm","clk":"1003279759","pt":1580605595817,"mc":[{"id":"1.168179123","rc":[{"batb":[[0,1.27,2484.61],[1,1.26,174.28],[2,1.25,182.46]],"ltp":1.48,"tv":0.01,"id":8326656}]}]}
{"op":"mcm","clk":"1003280442","pt":1580605604861,"mc":[{"id":"1.168179123","rc":[{"batb":[[0,1.25,182.46],[1,1.01,15.51],[2,1.25,0]],"ltp":1.48,"tv":0.01,"id":8326656},{"batb":[[0,3.95,48.86],[1,1.01,15.52],[2,1.01,0]],"ltp":3.1,"tv":0.0,"id":9712909}]}]}
{"op":"mcm","clk":"1003280658","pt":1580605607826,"mc":[{"id":"1.168179123","rc":[{"batb":[[0,1.25,181.76]],"ltp":1.48,"tv":0.01,"id":8326656},{"batb":[[0,3.9,49.18]],"ltp":3.1,"tv":0.0,"id":9712909}]}]}
{"op":"mcm","clk":"1003282042","pt":1580605627866,"mc":[{"id":"1.168179123","rc":[{"batb":[[1,1.24,191.59],[2,1.01,15.51]],"ltp":1.48,"tv":0.01,"id":8326656},{"batb":[[0,4.3,39.26],[1,4,45.24],[2,3.9,49.18]],"ltp":3.1,"tv":0.0,"id":9712909}]}]}
{"op":"mcm","clk":"1003282072","pt":1580605628274,"mc":[{"id":"1.168179123","rc":[{"batb":[[2,3.95,21.51]],"ltp":3.1,"tv":0.0,"id":9712909}]}]}
{"op":"mcm","clk":"1003283545","pt":1580605650676,"mc":[{"id":"1.168179123","rc":[{"batb":[[0,1.24,191.59],[1,1.01,15.51],[2,1.01,0]],"ltp":1.48,"tv":0.01,"id":8326656},{"batb":[[0,4,45.24],[1,1.01,15.52],[2,3.95,0]],"ltp":3.1,"tv":0.0,"id":9712909}]}]}
{"op":"mcm","clk":"1003284877","pt":1580605669797,"mc":[{"id":"1.168179123","rc":[{"batb":[[1,1.23,200.25],[2,1.01,15.51]],"ltp":1.48,"tv":0.01,"id":8326656},{"batb":[[0,4.4,36.35],[1,4.2,41.94],[2,4.1,28.94]],"ltp":3.1,"tv":0.0,"id":9712909}]}]}
{"op":"mcm","clk":"1003284987","pt":1580605671336,"mc":[{"id":"1.168179123","rc":[{"batb":[[2,1.01,15.52]],"batl":[[0,5.5,115.06]],"ltp":3.1,"tv":0.0,"id":9712909}]}]}
{"op":"mcm","clk":"1003286228","pt":1580605688759,"mc":[{"id":"1.168179123","rc":[{"batb":[[0,1.23,200.25],[1,1.01,15.51],[2,1.01,0]],"ltp":1.48,"tv":0.01,"id":8326656},{"batb":[[0,4.2,41.94],[1,1.01,15.52],[2,1.01,0]],"ltp":3.1,"tv":0.0,"id":9712909}]}]}
{"op":"mcm","clk":"1003287577","pt":1580605710791,"mc":[{"id":"1.168179123","rc":[{"batb":[[1,1.22,208.03],[2,1.01,15.51]],"ltp":1.48,"tv":0.01,"id":8326656},{"batb":[[0,4.6,33.99],[1,4.3,57.05],[2,1.01,15.52]],"ltp":3.1,"tv":0.0,"id":9712909}]}]}
{"op":"mcm","clk":"1003288400","pt":1580605722890,"mc":[{"id":"1.168179123","rc":[{"batb":[[0,1.22,208.03],[1,1.01,15.51],[2,1.01,0]],"ltp":1.48,"tv":0.01,"id":8326656},{"batb":[[0,4.3,38.87],[1,1.01,15.52],[2,1.01,0]],"ltp":3.1,"tv":0.0,"id":9712909}]}]}
{"op":"mcm","clk":"1003288563","pt":1580605725577,"mc":[{"id":"1.168179123","rc":[{"batl":[[0,4.6,5.88],[1,5.5,115.06]],"ltp":3.1,"tv":0.0,"id":9712909}]}]}
{"op":"mcm","clk":"1003289034","pt":1580605732524,"mc":[{"id":"1.168179123","rc":[{"batl":[[0,5.5,115.06],[1,5.5,0]],"ltp":3.1,"tv":0.0,"id":9712909}]}]}
{"op":"mcm","clk":"1003289193","pt":1580605734731,"mc":[{"id":"1.168179123","rc":[{"batb":[[1,1.2,229.75],[2,1.01,15.51]],"ltp":1.48,"tv":0.01,"id":8326656},{"batb":[[0,4.7,32.1],[1,4.4,35.96],[2,1.01,15.52]],"ltp":3.1,"tv":0.0,"id":9712909}]}]}
{"op":"mcm","clk":"1003289345","pt":1580605736688,"mc":[{"id":"1.168179123","rc":[{"batl":[[0,1.66,579.81]],"ltp":1.48,"tv":0.01,"id":8326656}]}]}
{"op":"mcm","clk":"1003289742","pt":1580605742702,"mc":[{"id":"1.168179123","rc":[{"batb":[[0,1.22,207.56],[1,1.21,229.28]],"ltp":1.48,"tv":0.01,"id":8326656},{"trd":[[4.7,8.4]],"batb":[[0,4.7,27.9]],"ltp":4.7,"tv":8.4,"id":9712909}],"tv":8.41}]}
{"op":"mcm","clk":"1003290324","pt":1580605750854,"mc":[{"id":"1.168179123","rc":[{"batb":[[0,1.23,206.54],[1,1.21,228.1]],"ltp":1.48,"tv":0.01,"id":8326656},{"batb":[[0,4.6,32.5]],"ltp":4.7,"tv":8.4,"id":9712909}]}]}
{"op":"mcm","clk":"1003290395","pt":1580605751833,"mc":[{"id":"1.168179123","rc":[{"batl":[[0,5.1,608.15],[1,5.5,115.06]],"ltp":4.7,"tv":8.4,"id":9712909}]}]}
{"op":"mcm","clk":"1003294560","pt":1580605809756,"mc":[{"id":"1.168179123","rc":[{"batl":[[0,5.5,115.06],[1,5.5,0]],"ltp":4.7,"tv":8.4,"id":9712909}]}]}
{"op":"mcm","clk":"1003294585","pt":1580605810030,"mc":[{"id":"1.168179123","rc":[{"batb":[[0,1.21,228.1],[1,1.01,15.51],[2,1.01,0]],"ltp":1.48,"tv":0.01,"id":8326656},{"batb":[[0,4.4,35.96],[1,1.01,15.52],[2,1.01,0]],"ltp":4.7,"tv":8.4,"id":9712909}]}]}
{"op":"mcm","clk":"1003295820","pt":1580605826849,"mc":[{"id":"1.168179123","rc":[{"batb":[[0,1.24,191.43],[1,1.22,210.63],[2,1.21,228.1]],"ltp":1.48,"tv":0.01,"id":8326656},{"batb":[[1,4.2,40.21],[2,1.01,15.52]],"ltp":4.7,"tv":8.4,"id":9712909}]}]}
{"op":"mcm","clk":"1003295844","pt":1580605827108,"mc":[{"id":"1.168179123","rc":[{"batb":[[2,1.01,15.51]],"ltp":1.48,"tv":0.01,"id":8326656}]}]}
{"op":"mcm","clk":"1003296066","pt":1580605830310,"mc":[{"id":"1.168179123","rc":[{"batl":[[0,5.1,613.35],[1,5.5,115.06]],"ltp":4.7,"tv":8.4,"id":9712909}]}]}
{"op":"mcm","clk":"1003296988","pt":1580605844654,"mc":[{"id":"1.168179123","rc":[{"batb":[[0,1.22,210.63],[1,1.01,15.51],[2,1.01,0]],"ltp":1.48,"tv":0.01,"id":8326656},{"batb":[[0,4.2,40.21],[1,1.01,15.52],[2,1.01,0]],"batl":[[0,5.5,115.06],[1,5.5,0]],"ltp":4.7,"tv":8.4,"id":9712909}]}]}
{"op":"mcm","clk":"1003299641","pt":1580605882421,"mc":[{"id":"1.168179123","rc":[{"batb":[[1,1.2,234.63],[2,1.01,15.51]],"ltp":1.48,"tv":0.01,"id":8326656},{"batb":[[0,4.7,31.55],[1,4.5,34.78],[2,4.3,29.78]],"ltp":4.7,"tv":8.4,"id":9712909}]}]}
{"op":"mcm","clk":"1003300733","pt":1580605896847,"mc":[{"id":"1.168179123","rc":[{"batb":[[2,1.01,15.52]],"ltp":4.7,"tv":8.4,"id":9712909}]}]}
{"op":"mcm","clk":"1003300781","pt":1580605897564,"mc":[{"id":"1.168179123","rc":[{"batb":[[0,1.2,234.63],[1,1.01,15.51],[2,1.01,0]],"ltp":1.48,"tv":0.01,"id":8326656},{"batb":[[0,4.5,34.78],[1,1.01,15.52],[2,1.01,0]],"ltp":4.7,"tv":8.4,"id":9712909}]}]}
{"op":"mcm","clk":"1003302171","pt":1580605919577,"mc":[{"id":"1.168179123","rc":[{"batb":[[1,1.18,265.79],[2,1.01,15.51]],"ltp":1.48,"tv":0.01,"id":8326656},{"trd":[[5,8.4]],"batb":[[0,5,22.63],[1,4.8,30.61],[2,4.6,30.44]],"ltp":5.0,"tv":16.8,"id":9712909}],"tv":16.81}]}
{"op":"mcm","clk":"1003302332","pt":1580605922298,"mc":[{"id":"1.168179123","rc":[{"batb":[[2,1.01,15.52]],"batl":[[0,6.6,98.95]],"ltp":5.0,"tv":16.8,"id":9712909}]}]}
{"op":"mcm","clk":"1003304008","pt":1580605946823,"mc":[{"id":"1.168179123","rc":[{"batb":[[0,1.18,265.79],[1,1.01,15.51],[2,1.01,0]],"ltp":1.48,"tv":0.01,"id":8326656},{"batb":[[0,4.8,30.61],[1,1.01,15.52],[2,1.01,0]],"ltp":5.0,"tv":16.8,"id":9712909}]}]}
{"op":"mcm","clk":"1003304230","pt":1580605949818,"mc":[{"id":"1.168179123","rc":[{"batb":[[0,1.19,258.39]],"ltp":1.48,"tv":0.01,"id":8326656},{"batb":[[0,4.7,32.02]],"batl":[[0,5,6.72],[1,6.6,98.95]],"ltp":5.0,"tv":16.8,"id":9712909}]}]}
{"op":"mcm","clk":"1003304395","pt":1580605951828,"mc":[{"id":"1.168179123","rc":[{"batl":[[1,6.6,0]],"ltp":5.0,"tv":16.8,"id":9712909}]}]}
{"op":"mcm","clk":"1003304524","pt":1580605953737,"mc":[{"id":"1.168179123","rc":[{"batb":[[0,1.22,208.51],[1,1.2,238.17],[2,1.19,258.39]],"ltp":1.48,"tv":0.01,"id":8326656},{"batb":[[1,4.4,36.51],[2,1.01,15.52]],"ltp":5.0,"tv":16.8,"id":9712909}]}]}
{"op":"mcm","clk":"1003304548","pt":1580605954044,"mc":[{"id":"1.168179123","rc":[{"batb":[[2,1.01,15.51]],"ltp":1.48,"tv":0.01,"id":8326656}]}]}
{"op":"mcm","clk":"1003304616","pt":1580605955028,"mc":[{"id":"1.168179123","rc":[{"batl":[[1,6,106.18]],"ltp":5.0,"tv":16.8,"id":9712909}]}]}
{"op":"mcm","clk":"1003305072","pt":1580605961740,"mc":[{"id":"1.168179123","rc":[{"batl":[[0,6,106.18],[1,6,0]],"ltp":5.0,"tv":16.8,"id":9712909}]}]}
{"op":"mcm","clk":"1003305283","pt":1580605964848,"mc":[{"id":"1.168179123","rc":[{"batl":[[0,5,617.34],[1,6,106.18]],"ltp":5.0,"tv":16.8,"id":9712909}]}]}
{"op":"mcm","clk":"1003305663","pt":1580605971449,"mc":[{"id":"1.168179123","rc":[{"batb":[[0,1.2,238.17],[1,1.01,15.51],[2,1.01,0]],"ltp":1.48,"tv":0.01,"id":8326656},{"batb":[[0,4.4,36.51],[1,1.01,15.52],[2,1.01,0]],"batl":[[0,6,106.18],[1,6,0]],"ltp":5.0,"tv":16.8,"id":9712909}]}]}
{"op":"mcm","clk":"1003306849","pt":1580605990864,"mc":[{"id":"1.168179123","rc":[{"batb":[[0,1.24,190.8],[1,1.22,212.68],[2,1.2,238.17]],"ltp":1.48,"tv":0.01,"id":8326656},{"batb":[[1,4.2,40.91],[2,1.01,15.52]],"batl":[[0,4.9,632.05],[1,6,106.18]],"ltp":5.0,"tv":16.8,"id":9712909}]}]}
{"op":"mcm","clk":"1003306892","pt":1580605991486,"mc":[{"id":"1.168179123","rc":[{"batb":[[2,1.01,15.51]],"ltp":1.48,"tv":0.01,"id":8326656}]}]}
{"op":"mcm","clk":"1003308218","pt":1580606010686,"mc":[{"id":"1.168179123","rc":[{"batb":[[1,1.22,210]],"ltp":1.48,"tv":0.01,"id":8326656},{"batl":[[0,6,106.18],[1,6,0]],"ltp":5.0,"tv":16.8,"id":9712909}]}]}
{"op":"mcm","clk":"1003308234","pt":1580606010898,"mc":[{"id":"1.168179123","rc":[{"batb":[[0,1.22,210],[1,1.01,15.51],[2,1.01,0]],"ltp":1.48,"tv":0.01,"id":8326656},{"batb":[[0,4.2,40.91],[1,1.01,15.52],[2,1.01,0]],"ltp":5.0,"tv":16.8,"id":9712909}]}]}
{"op":"mcm","clk":"1003308913","pt":1580606020596,"mc":[{"id":"1.168179123","rc":[{"batb":[[1,1.2,240.45],[2,1.01,15.51]],"ltp":1.48,"tv":0.01,"id":8326656},{"batb":[[0,4.7,31.71],[1,4.4,36.19],[2,1.01,15.52]],"ltp":5.0,"tv":16.8,"id":9712909}]}]}
{"op":"mcm","clk":"1003310212","pt":1580606039049,"mc":[{"id":"1.168179123","rc":[{"batb":[[0,1.2,240.45],[1,1.01,15.51],[2,1.01,0]],"ltp":1.48,"tv":0.01,"id":8326656},{"batb":[[0,4.4,36.19],[1,1.01,15.52],[2,1.01,0]],"ltp":5.0,"tv":16.8,"id":9712909}]}]}
{"op":"mcm","clk":"1003311876","pt":1580606062286,"mc":[{"id":"1.168179123","rc":[{"batb":[[1,1.17,280.97],[2,1.01,15.51]],"ltp":1.48,"tv":0.01,"id":8326656},{"batb":[[0,5.1,25.89],[1,4.7,31.08],[2,1.01,15.52]],"ltp":5.0,"tv":16.8,"id":9712909}]}]}
{"op":"mcm","clk":"1003313429","pt":1580606083807,"mc":[{"id":"1.168179123","rc":[{"batb":[[0,1.17,280.97],[1,1.01,15.51],[2,1.01,0]],"ltp":1.48,"tv":0.01,"id":8326656},{"batb":[[0,4.7,31.08],[1,1.01,15.52],[2,1.01,0]],"ltp":5.0,"tv":16.8,"id":9712909}]}]}
{"op":"mcm","clk":"1003314332","pt":1580606097740,"mc":[{"id":"1.168179123","rc":[{"batb":[[1,1.16,295.21],[2,1.01,15.51]],"ltp":1.48,"tv":0.01,"id":8326656},{"batb":[[0,5.7,41.39],[1,5.3,24.47],[2,1.01,15.52]],"ltp":5.0,"tv":16.8,"id":9712909}]}]}
{"op":"mcm","clk":"1003314529","pt":1580606100320,"mc":[{"id":"1.168179123","rc":[{"batl":[[0,1.58,650.58]],"ltp":1.48,"tv":0.01,"id":8326656},{"batl":[[0,7.2,92.18]],"ltp":5.0,"tv":16.8,"id":9712909}]}]}
{"op":"mcm","clk":"1003315903","pt":1580606119743,"mc":[{"id":"1.168179123","rc":[{"trd":[[5.7,82.3]],"batb":[[0,5.3,24.7],[1,1.01,15.52],[2,1.01,0]],"ltp":5.7,"tv":99.11,"id":9712909}],"tv":99.12}]}
{"op":"mcm","clk":"1003316171","pt":1580606123365,"mc":[{"id":"1.168179123","rc":[{"batb":[[0,1.16,295.21],[1,1.01,15.51],[2,1.01,0]],"ltp":1.48,"tv":0.01,"id":8326656},{"batb":[[0,5.3,24.47]],"ltp":5.7,"tv":99.11,"id":9712909}]}]}
{"op":"mcm","clk":"1003316402","pt":1580606126848,"mc":[{"id":"1.168179123","rc":[{"batb":[[0,1.18,279.16]],"ltp":1.48,"tv":0.01,"id":8326656},{"batb":[[0,5.1,26.67]],"ltp":5.7,"tv":99.11,"id":9712909}]}]}
{"op":"mcm","clk":"1003316911","pt":1580606133761,"mc":[{"id":"1.168179123","rc":[{"batb":[[1,1.17,295.92],[2,1.01,15.51]],"ltp":1.48,"tv":0.01,"id":8326656},{"batb":[[0,5.6,41.78],[1,5.3,24.39],[2,5.2,31.02]],"ltp":5.7,"tv":99.11,"id":9712909}]}]}
{"op":"mcm","clk":"1003316976","pt":1580606134687,"mc":[{"id":"1.168179123","rc":[{"batb":[[2,1.01,15.52]],"ltp":5.7,"tv":99.11,"id":9712909}]}]}
{"op":"mcm","clk":"1003317821","pt":1580606146405,"mc":[{"id":"1.168179123","rc":[{"batb":[[0,1.17,295.77],[1,1.01,15.51],[2,1.01,0]],"ltp":1.48,"tv":0.01,"id":8326656},{"batb":[[0,5.3,24.39],[1,1.01,15.52],[2,1.01,0]],"ltp":5.7,"tv":99.11,"id":9712909}]}]}
{"op":"mcm","clk":"1003318504","pt":1580606155796,"mc":[{"id":"1.168179123","rc":[{"batb":[[1,1.16,308.35],[2,1.01,15.51]],"ltp":1.48,"tv":0.01,"id":8326656},{"batb":[[0,5.9,38.16],[1,5.4,22.58],[2,5.3,24.39]],"ltp":5.7,"tv":99.11,"id":9712909}]}]}
{"op":"mcm","clk":"1003318582","pt":1580606156726,"mc":[{"id":"1.168179123","rc":[{"batb":[[2,1.01,15.52]],"ltp":5.7,"tv":99.11,"id":9712909}]}]}
{"op":"mcm","clk":"1003318692","pt":1580606157720,"mc":[{"id":"1.168179123","rc":[{"batl":[[0,8.2,85.46]],"ltp":5.7,"tv":99.11,"id":9712909}]}]}
{"op":"mcm","clk":"1003319572","pt":1580606170206,"mc":[{"id":"1.168179123","rc":[{"batb":[[0,1.16,308.35],[1,1.01,15.51],[2,1.01,0]],"ltp":1.48,"tv":0.01,"id":8326656},{"batb":[[0,5.4,22.58],[1,1.01,15.52],[2,1.01,0]],"ltp":5.7,"tv":99.11,"id":9712909}]}]}
{"op":"mcm","clk":"1003321444","pt":1580606194844,"mc":[{"id":"1.168179123","rc":[{"batb":[[0,1.19,259.97],[1,1.18,273.1],[2,1.01,15.51]],"ltp":1.48,"tv":0.01,"id":8326656},{"batb":[[1,5,27.38],[2,1.01,15.52]],"ltp":5.7,"tv":99.11,"id":9712909}]}]}
{"op":"mcm","clk":"1003321596","pt":1580606196852,"mc":[{"id":"1.168179123","rc":[{"batl":[[0,7.2,92.18]],"ltp":5.7,"tv":99.11,"id":9712909}]}]}
{"op":"mcm","clk":"1003321684","pt":1580606197984,"mc":[{"id":"1.168179123","rc":[{"batb":[[0,1.2,2485.67],[1,1.19,259.97],[2,1.18,273.1]],"ltp":1.48,"tv":0.01,"id":8326656}]}]}
{"op":"mcm","clk":"1003323334","pt":1580606218882,"mc":[{"id":"1.168179123","rc":[{"batb":[[0,1.19,259.97],[1,1.18,273.1],[2,1.01,15.51]],"ltp":1.48,"tv":0.01,"id":8326656}]}]}
{"op":"mcm","clk":"1003323349","pt":1580606219086,"mc":[{"id":"1.168179123","rc":[{"batb":[[0,1.18,273.1],[1,1.01,15.51],[2,1.01,0]],"ltp":1.48,"tv":0.01,"id":8326656},{"batb":[[0,5,27.38],[1,1.01,15.52],[2,1.01,0]],"ltp":5.7,"tv":99.11,"id":9712909}]}]}
{"op":"mcm","clk":"1003324998","pt":1580606239651,"mc":[{"id":"1.168179123","rc":[{"batb":[[1,1.17,288.76],[2,1.01,15.51]],"ltp":1.48,"tv":0.01,"id":8326656},{"batb":[[0,5.5,21.64],[1,5.2,24.86],[2,1.01,15.52]],"ltp":5.7,"tv":99.11,"id":9712909}]}]}
{"op":"mcm","clk":"1003326202","pt":1580606254540,"mc":[{"id":"1.168179123","rc":[{"batb":[[0,1.17,288.76],[1,1.01,15.51],[2,1.01,0]],"ltp":1.48,"tv":0.01,"id":8326656},{"batb":[[0,5.2,24.86],[1,1.01,15.52],[2,1.01,0]],"ltp":5.7,"tv":99.11,"id":9712909}]}]}
{"op":"mcm","clk":"1003327728","pt":1580606273774,"mc":[{"id":"1.168179123","rc":[{"batb":[[0,1.21,1105.04],[1,1.17,288.76],[2,1.01,15.51]],"batl":[[0,1.24,434.63],[1,1.25,864.89],[2,1.58,650.58]],"ltp":1.48,"tv":0.01,"id":8326656}]}]}
{"op":"mcm","clk":"1003327757","pt":1580606274188,"mc":[{"id":"1.168179123","rc":[{"trd":[[1.21,190.07]],"batb":[[0,1.21,914.97],[2,1.13,385.54]],"ltp":1.21,"tv":190.07,"id":8326656},{"trd":[[5.8,39.66]],"batb":[[0,5,26.91]],"ltp":5.8,"tv":138.76,"id":9712909}],"tv":328.84}]}
{"op":"mcm","clk":"1003327973","pt":1580606276675,"mc":[{"id":"1.168179123","rc":[{"batb":[[0,1.21,1241.82],[1,1.2,848.63],[2,1.17,288.76]],"batl":[[0,1.24,504.59]],"ltp":1.21,"tv":190.07,"id":8326656}]}]}
{"op":"mcm","clk":"1003328018","pt":1580606277293,"mc":[{"id":"1.168179123","rc":[{"batb":[[0,1.21,1339.29],[1,1.2,942]],"batl":[[0,1.24,594.96]],"ltp":1.21,"tv":190.07,"id":8326656}]}]}
{"op":"mcm","clk":"1003328489","pt":1580606282891,"mc":[{"id":"1.168179123","rc":[{"batb":[[2,1.18,276.41]],"ltp":1.21,"tv":190.07,"id":8326656},{"batb":[[0,5.6,21.24],[1,4.9,28.72],[2,1.01,15.52]],"ltp":5.8,"tv":138.76,"id":9712909}]}]}
{"op":"mcm","clk":"1003330192","pt":1580606302336,"mc":[{"id":"1.168179123","rc":[{"batb":[[2,1.18,274.84]],"ltp":1.21,"tv":190.07,"id":8326656}]}]}
{"op":"mcm","clk":"1003330870","pt":1580606310531,"mc":[{"id":"1.168179123","rc":[{"batb":[[2,1.18,274.13]],"ltp":1.21,"tv":190.07,"id":8326656}]}]}
{"op":"mcm","clk":"1003332734","pt":1580606333554,"mc":[{"id":"1.168179123","rc":[{"batb":[[2,1.18,273.73]],"ltp":1.21,"tv":190.07,"id":8326656}]}]}
{"op":"mcm","clk":"1003333548","pt":1580606344744,"mc":[{"id":"1.168179123","rc":[{"batb":[[2,1.18,273.5]],"ltp":1.21,"tv":190.07,"id":8326656},{"batb":[[0,5.5,21.56]],"ltp":5.8,"tv":138.76,"id":9712909}]}]}
{"op":"mcm","clk":"1003339896","pt":1580606430862,"mc":[{"id":"1.168179123","rc":[{"batb":[[0,1.14,365.16],[1,1.01,15.51],[2,1.18,0]],"batl":[[0,1.58,650.58],[1,1.25,0],[2,1.58,0]],"ltp":1.21,"tv":190.07,"id":8326656},{"batb":[[0,4.9,28.72],[1,1.01,15.52],[2,1.01,0]],"ltp":5.8,"tv":138.76,"id":9712909}]}]}
{"op":"mcm","clk":"1003340063","pt":1580606433290,"mc":[{"id":"1.168179123","rc":[{"batb":[[0,1.17,817.08],[1,1.16,1541.77],[2,1.14,365.16]],"batl":[[0,1.28,423.01],[1,1.29,726.91],[2,1.58,650.58]],"ltp":1.21,"tv":190.07,"id":8326656}]}]}
{"op":"mcm","clk":"1003340477","pt":1580606438784,"mc":[{"id":"1.168179123","rc":[{"batb":[[0,1.14,365.16],[1,1.01,15.51],[2,1.14,0]],"ltp":1.21,"tv":190.07,"id":8326656}]}]}
{"op":"mcm","clk":"1003340692","pt":1580606441886,"mc":[{"id":"1.168179123","rc":[{"batb":[[0,1.25,993.82],[1,1.24,960.61],[2,1.14,365.16]],"ltp":1.21,"tv":190.07,"id":8326656}]}]}
{"op":"mcm","clk":"1003340763","pt":1580606442813,"mc":[{"id":"1.168179123","rc":[{"batb":[[2,1.22,221.49]],"ltp":1.21,"tv":190.07,"id":8326656},{"batb":[[1,4.3,38.16],[2,1.01,15.52]],"ltp":5.8,"tv":138.76,"id":9712909}]}]}
{"op":"mcm","clk":"1003340840","pt":1580606443791,"mc":[{"id":"1.168179123","rc":[{"batl":[[0,6.6,98.95]],"ltp":5.8,"tv":138.76,"id":9712909}]}]}
{"op":"mcm","clk":"1003341712","pt":1580606456801,"mc":[{"id":"1.168179123","rc":[{"batb":[[0,1.22,221.49],[1,1.18,282.78],[2,1.01,15.51]],"batl":[[0,1.58,650.58],[1,1.29,0],[2,1.58,0]],"ltp":1.21,"tv":190.07,"id":8326656}]}]}
{"op":"mcm","clk":"1003341754","pt":1580606457417,"mc":[{"id":"1.168179123","rc":[{"batb":[[0,1.18,282.78],[1,1.01,15.51],[2,1.01,0]],"ltp":1.21,"tv":190.07,"id":8326656},{"batb":[[0,4.3,38.16],[1,1.01,15.52],[2,1.01,0]],"ltp":5.8,"tv":138.76,"id":9712909}]}]}
{"op":"mcm","clk":"1003341913","pt":1580606459732,"mc":[{"id":"1.168179123","rc":[{"batb":[[0,1.21,699.91],[1,1.2,1185.27],[2,1.18,282.78]],"batl":[[0,1.32,459.16],[1,1.33,619.76],[2,1.58,650.58]],"ltp":1.21,"tv":190.07,"id":8326656}]}]}
{"op":"mcm","clk":"1003342571","pt":1580606469556,"mc":[{"id":"1.168179123","rc":[{"batl":[[0,1.58,650.58],[1,1.33,0],[2,1.58,0]],"ltp":1.21,"tv":190.07,"id":8326656}]}]}
{"op":"mcm","clk":"1003342792","pt":1580606472725,"mc":[{"id":"1.168179123","rc":[{"batl":[[0,1.24,1171.79],[1,1.25,850.54],[2,1.58,650.58]],"ltp":1.21,"tv":190.07,"id":8326656}]}]}
{"op":"mcm","clk":"1003342867","pt":1580606473652,"mc":[{"id":"1.168179123","rc":[{"batb":[[0,5.7,40.99],[1,4.9,29.19],[2,1.01,15.52]],"ltp":5.8,"tv":138.76,"id":9712909}]}]}
{"op":"mcm","clk":"1003342993","pt":1580606475154,"mc":[{"id":"1.168179123","rc":[{"batl":[[0,8.2,85.46]],"ltp":5.8,"tv":138.76,"id":9712909}]}]}
{"op":"mcm","clk":"1003343903","pt":1580606490346,"mc":[{"id":"1.168179123","rc":[{"batb":[[0,1.13,401.51],[1,1.01,15.51],[2,1.18,0]],"batl":[[0,1.58,650.58],[1,1.25,0],[2,1.58,0]],"ltp":1.21,"tv":190.07,"id":8326656},{"batb":[[0,4.9,29.19],[1,1.01,15.52],[2,1.01,0]],"ltp":5.8,"tv":138.76,"id":9712909}]}]}
{"op":"mcm","clk":"1003344317","pt":1580606496662,"mc":[{"id":"1.168179123","rc":[{"batb":[[0,1.2,605.95],[1,1.19,1255.86],[2,1.13,401.51]],"batl":[[0,1.22,444.44],[1,1.23,958.95],[2,1.58,650.58]],"ltp":1.21,"tv":190.07,"id":8326656}]}]}
{"op":"mcm","clk":"1003344474","pt":1580606499245,"mc":[{"id":"1.168179123","rc":[{"batb":[[0,1.13,401.51],[1,1.01,15.51],[2,1.13,0]],"batl":[[0,1.58,650.58],[1,1.23,0],[2,1.58,0]],"ltp":1.21,"tv":190.07,"id":8326656}]}]}
{"op":"mcm","clk":"1003344691","pt":1580606502593,"mc":[{"id":"1.168179123","rc":[{"batb":[[0,1.16,407.54],[1,1.15,1640.79],[2,1.13,401.51]],"batl":[[0,1.28,357.3],[1,1.29,728.24],[2,1.58,650.58]],"ltp":1.21,"tv":190.07,"id":8326656}]}]}
{"op":"mcm","clk":"1003345097","pt":1580606508579,"mc":[{"id":"1.168179123","rc":[{"batb":[[0,1.13,401.51],[1,1.01,15.51],[2,1.13,0]],"ltp":1.21,"tv":190.07,"id":8326656}]}]}
{"op":"mcm","clk":"1003345325","pt":1580606511888,"mc":[{"id":"1.168179123","rc":[{"batb":[[0,1.25,1065.8],[1,1.24,962.39],[2,1.13,401.51]],"ltp":1.21,"tv":190.07,"id":8326656}]}]}
{"op":"mcm","clk":"1003345386","pt":1580606512564,"mc":[{"id":"1.168179123","rc":[{"batb":[[2,1.22,221.88]],"ltp":1.21,"tv":190.07,"id":8326656},{"batb":[[1,4.3,39.42],[2,1.01,15.52]],"ltp":5.8,"tv":138.76,"id":9712909}]}]}
{"op":"mcm","clk":"1003345464","pt":1580606513797,"mc":[{"id":"1.168179123","rc":[{"batl":[[0,6.6,98.95]],"ltp":5.8,"tv":138.76,"id":9712909}]}]}
{"op":"mcm","clk":"1003346696","pt":1580606531844,"mc":[{"id":"1.168179123","rc":[{"batb":[[0,1.22,221.88],[1,1.17,293.64],[2,1.01,15.51]],"batl":[[0,1.58,650.58],[1,1.29,0],[2,1.58,0]],"ltp":1.21,"tv":190.07,"id":8326656}]}]}
{"op":"mcm","clk":"1003346712","pt":1580606532001,"mc":[{"id":"1.168179123","rc":[{"batb":[[0,1.17,293.64],[1,1.01,15.51],[2,1.01,0]],"ltp":1.21,"tv":190.07,"id":8326656},{"batb":[[0,4.3,39.42],[1,1.01,15.52],[2,1.01,0]],"ltp":5.8,"tv":138.76,"id":9712909}]}]}
{"op":"mcm","clk":"1003347121","pt":1580606537519,"mc":[{"id":"1.168179123","rc":[{"batb":[[0,1.24,1061.2],[1,1.23,1013.03],[2,1.17,293.64]],"batl":[[0,1.27,467.48],[1,1.28,757.65],[2,1.58,650.58]],"ltp":1.21,"tv":190.07,"id":8326656}]}]}
{"op":"mcm","clk":"1003347423","pt":1580606541754,"mc":[{"id":"1.168179123","rc":[{"batb":[[0,1.17,293.64],[1,1.01,15.51],[2,1.17,0]],"batl":[[0,1.58,650.58],[1,1.28,0],[2,1.58,0]],"ltp":1.21,"tv":190.07,"id":8326656}]}]}
{"op":"mcm","clk":"1003347564","pt":1580606544127,"mc":[{"id":"1.168179123","rc":[{"batb":[[0,1.2,1231.13],[1,1.19,1070.24],[2,1.17,293.64]],"batl":[[0,1.33,621.6],[1,1.34,594.8],[2,1.58,650.58]],"ltp":1.21,"tv":190.07,"id":8326656}]}]}
{"op":"mcm","clk":"1003347717","pt":1580606546654,"mc":[{"id":"1.168179123","rc":[{"batb":[[0,1.17,293.64],[1,1.01,15.51],[2,1.17,0]],"ltp":1.21,"tv":190.07,"id":8326656}]}]}
{"op":"mcm","clk":"1003347836","pt":1580606548829,"mc":[{"id":"1.168179123","rc":[{"batb":[[0,1.3,326.52],[1,1.29,749.63],[2,1.17,293.64]],"ltp":1.21,"tv":190.07,"id":8326656}]}]}
{"op":"mcm","clk":"1003347889","pt":1580606549755,"mc":[{"id":"1.168179123","rc":[{"batb":[[2,1.26,181.2]],"ltp":1.21,"tv":190.07,"id":8326656},{"batb":[[1,3.95,47.6],[2,1.01,15.52]],"ltp":5.8,"tv":138.76,"id":9712909}]}]}
{"op":"mcm","clk":"1003347956","pt":1580606551145,"mc":[{"id":"1.168179123","rc":[{"batl":[[0,5.5,115.06]],"ltp":5.8,"tv":138.76,"id":9712909}]}]}
{"op":"mcm","clk":"1003348808","pt":1580606565274,"mc":[{"id":"1.168179123","rc":[{"batb":[[0,1.23,215.51],[1,1.01,15.51],[2,1.26,0]],"batl":[[0,1.58,650.58],[1,1.34,0],[2,1.58,0]],"ltp":1.21,"tv":190.07,"id":8326656},{"batb":[[0,3.95,47.6],[1,1.01,15.52],[2,1.01,0]],"ltp":5.8,"tv":138.76,"id":9712909}]}]}
{"op":"mcm","clk":"1003348941","pt":1580606567863,"mc":[{"id":"1.168179123","rc":[{"batb":[[0,1.26,822.88],[1,1.25,910.29],[2,1.23,215.51]],"batl":[[0,1.36,610.99],[1,1.37,535.42],[2,1.58,650.58]],"ltp":1.21,"tv":190.07,"id":8326656}]}]}
{"op":"mcm","clk":"1003349335","pt":1580606574687,"mc":[{"id":"1.168179123","rc":[{"batb":[[0,1.23,215.51],[1,1.01,15.51],[2,1.23,0]],"batl":[[0,1.58,650.58],[1,1.37,0],[2,1.58,0]],"ltp":1.21,"tv":190.07,"id":8326656}]}]}
{"op":"mcm","clk":"1003349531","pt":1580606577690,"mc":[{"id":"1.168179123","rc":[{"batb":[[0,1.26,822.88],[1,1.25,910.29],[2,1.23,215.51]],"batl":[[0,1.29,482.33],[1,1.3,696.38],[2,1.58,650.58]],"ltp":1.21,"tv":190.07,"id":8326656}]}]}
{"op":"mcm","clk":"1003349597","pt":1580606578680,"mc":[{"id":"1.168179123","rc":[{"batb":[[0,4.8,30.45],[1,4.1,42.49],[2,1.01,15.52]],"ltp":5.8,"tv":138.76,"id":9712909}]}]}
{"op":"mcm","clk":"1003349739","pt":1580606580893,"mc":[{"id":"1.168179123","rc":[{"batl":[[0,6.6,98.95]],"ltp":5.8,"tv":138.76,"id":9712909}]}]}
{"op":"mcm","clk":"1003350783","pt":1580606596895,"mc":[{"id":"1.168179123","rc":[{"batb":[[0,1.23,215.51],[1,1.17,297.97],[2,1.01,15.51]],"batl":[[0,1.58,650.58],[1,1.3,0],[2,1.58,0]],"ltp":1.21,"tv":190.07,"id":8326656}]}]}
{"op":"mcm","clk":"1003350791","pt":1580606596998,"mc":[{"id":"1.168179123","rc":[{"batb":[[0,1.17,297.97],[1,1.01,15.51],[2,1.01,0]],"ltp":1.21,"tv":190.07,"id":8326656},{"batb":[[0,4.1,42.49],[1,1.01,15.52],[2,1.01,0]],"ltp":5.8,"tv":138.76,"id":9712909}]}]}
{"op":"mcm","clk":"1003350953","pt":1580606599601,"mc":[{"id":"1.168179123","rc":[{"batb":[[0,1.2,1049.02],[1,1.19,1253.88],[2,1.17,297.97]],"batl":[[0,1.35,742.95],[1,1.36,552.27],[2,1.58,650.58]],"ltp":1.21,"tv":190.07,"id":8326656}]}]}
{"op":"mcm","clk":"1003351624","pt":1580606609502,"mc":[{"id":"1.168179123","rc":[{"batl":[[0,1.58,650.58],[1,1.36,0],[2,1.58,0]],"ltp":1.21,"tv":190.07,"id":8326656}]}]}
{"op":"mcm","clk":"1003351818","pt":1580606612396,"mc":[{"id":"1.168179123","rc":[{"batl":[[0,1.23,1004.79],[1,1.24,897.01],[2,1.58,650.58]],"ltp":1.21,"tv":190.07,"id":8326656}]}]}
{"op":"mcm","clk":"1003351914","pt":1580606613421,"mc":[{"id":"1.168179123","rc":[{"batb":[[0,5.9,37.69],[1,4.8,30.06],[2,1.01,15.52]],"ltp":5.8,"tv":138.76,"id":9712909}]}]}
{"op":"mcm","clk":"1003352038","pt":1580606615232,"mc":[{"id":"1.168179123","rc":[{"batl":[[0,8.2,85.46]],"ltp":5.8,"tv":138.76,"id":9712909}]}]}
{"op":"mcm","clk":"1003353152","pt":1580606631859,"mc":[{"id":"1.168179123","rc":[{"batb":[[0,1.17,297.97],[1,1.11,464.14],[2,1.01,15.51]],"batl":[[0,1.58,650.58],[1,1.24,0],[2,1.58,0]],"ltp":1.21,"tv":190.07,"id":8326656}]}]}
{"op":"mcm","clk":"1003353237","pt":1580606632845,"mc":[{"id":"1.168179123","rc":[{"batb":[[0,1.11,464.14],[1,1.01,15.51],[2,1.01,0]],"ltp":1.21,"tv":190.07,"id":8326656},{"batb":[[0,4.8,30.06],[1,1.01,15.52],[2,1.01,0]],"ltp":5.8,"tv":138.76,"id":9712909}]}]}
{"op":"mcm","clk":"1003353362","pt":1580606634738,"mc":[{"id":"1.168179123","rc":[{"batb":[[0,1.13,2211.52],[1,1.11,464.14],[2,1.01,15.51]],"batl":[[0,1.29,594.23],[1,1.3,694.3],[2,1.58,650.58]],"ltp":1.21,"tv":190.07,"id":8326656}]}]}
{"op":"mcm","clk":"1003353864","pt":1580606641549,"mc":[{"id":"1.168179123","rc":[{"batb":[[0,1.11,464.14],[1,1.01,15.51],[2,1.01,0]],"ltp":1.21,"tv":190.07,"id":8326656}]}]}
{"op":"mcm","clk":"1003354090","pt":1580606644865,"mc":[{"id":"1.168179123","rc":[{"batb":[[0,1.26,701],[1,1.25,907.53],[2,1.11,464.14]],"ltp":1.21,"tv":190.07,"id":8326656}]}]}
{"op":"mcm","clk":"1003354156","pt":1580606645763,"mc":[{"id":"1.168179123","rc":[{"batb":[[2,1.22,217.56]],"ltp":1.21,"tv":190.07,"id":8326656},{"batb":[[1,4.1,42.33],[2,1.01,15.52]],"ltp":5.8,"tv":138.76,"id":9712909}]}]}
{"op":"mcm","clk":"1003354248","pt":1580606647360,"mc":[{"id":"1.168179123","rc":[{"batl":[[0,6.6,98.95]],"ltp":5.8,"tv":138.76,"id":9712909}]}]}
{"op":"mcm","clk":"1003355059","pt":1580606659890,"mc":[{"id":"1.168179123","rc":[{"batb":[[0,1.22,217.56],[1,1.17,302.22],[2,1.01,15.51]],"batl":[[0,1.58,650.58],[1,1.3,0],[2,1.58,0]],"ltp":1.21,"tv":190.07,"id":8326656}]}]}
{"op":"mcm","clk":"1003355103","pt":1580606660463,"mc":[{"id":"1.168179123","rc":[{"batb":[[0,1.17,302.22],[1,1.01,15.51],[2,1.01,0]],"ltp":1.21,"tv":190.07,"id":8326656},{"batb":[[0,4.1,42.33],[1,1.01,15.52],[2,1.01,0]],"ltp":5.8,"tv":138.76,"id":9712909}]}]}
{"op":"mcm","clk":"1003355254","pt":1580606662790,"mc":[{"id":"1.168179123","rc":[{"batb":[[0,1.2,884.14],[1,1.19,1266.04],[2,1.17,302.22]],"batl":[[0,1.35,853.09],[1,1.36,551.07],[2,1.58,650.58]],"ltp":1.21,"tv":190.07,"id":8326656}]}]}
{"op":"mcm","clk":"1003356364","pt":1580606677903,"mc":[{"id":"1.168179123","rc":[{"trd":[[1.2,42.01]],"batb":[[0,1.2,842.13]],"ltp":1.2,"tv":232.08,"id":8326656},{"trd":[[6,8.4]],"ltp":6.0,"tv":147.16,"id":9712909}],"tv":379.25}]}
{"op":"mcm","clk":"1003357168","pt":1580606689394,"mc":[{"id":"1.168179123","rc":[{"batb":[[0,1.17,302.22],[1,1.01,15.51],[2,1.17,0]],"ltp":1.2,"tv":232.08,"id":8326656}]}]}
{"op":"mcm","clk":"1003357412","pt":1580606692745,"mc":[{"id":"1.168179123","rc":[{"batb":[[0,1.31,611.27],[1,1.3,724.19],[2,1.27,172.47]],"ltp":1.2,"tv":232.08,"id":8326656},{"batb":[[1,3.5,32.42],[2,1.01,15.52]],"ltp":6.0,"tv":147.16,"id":9712909}]}]}
{"op":"mcm","clk":"1003357622","pt":1580606695835,"mc":[{"id":"1.168179123","rc":[{"batl":[[0,5.5,115.06]],"ltp":6.0,"tv":147.16,"id":9712909}]}]}
{"op":"mcm","clk":"1003358110","pt":1580606701716,"mc":[{"id":"1.168179123","rc":[{"trd":[[1.31,200]],"batb":[[0,1.31,511.27]],"ltp":1.31,"tv":432.09,"id":8326656}],"tv":579.25}]}
{"op":"mcm","clk":"1003358140","pt":1580606702124,"mc":[{"id":"1.168179123","rc":[{"batl":[[0,1.35,578.99],[1,1.58,650.58],[2,1.58,0]],"ltp":1.31,"tv":432.09,"id":8326656}]}]}
{"op":"mcm","clk":"1003358334","pt":1580606705054,"mc":[{"id":"1.168179123","rc":[{"batb":[[0,1.31,571.98]],"batl":[[0,1.34,330.2],[1,1.35,578.99],[2,1.58,650.58]],"ltp":1.31,"tv":432.09,"id":8326656},{"batl":[[1,5.8,550.12]],"ltp":6.0,"tv":147.16,"id":9712909}]}]}
{"op":"mcm","clk":"1003358568","pt":1580606708246,"mc":[{"id":"1.168179123","rc":[{"trd":[[1.31,260.58]],"batb":[[0,1.31,541.69]],"ltp":1.31,"tv":492.66,"id":8326656}],"tv":639.83}]}
{"op":"mcm","clk":"1003359827","pt":1580606724174,"mc":[{"id":"1.168179123","rc":[{"trd":[[1.31,460.58]],"batb":[[0,1.31,441.69]],"ltp":1.31,"tv":692.66,"id":8326656}],"tv":839.83}]}
{"op":"mcm","clk":"1003360090","pt":1580606727545,"mc":[{"id":"1.168179123","rc":[{"batb":[[0,1.31,529.74]],"ltp":1.31,"tv":692.66,"id":8326656}]}]}
{"op":"mcm","clk":"1003360202","pt":1580606729262,"mc":[{"id":"1.168179123","rc":[{"batb":[[0,1.27,172.47],[1,1.24,200.32],[2,1.01,15.51]],"batl":[[0,1.58,650.58],[1,1.35,0],[2,1.58,0]],"ltp":1.31,"tv":692.66,"id":8326656}]}]}
{"op":"mcm","clk":"1003360397","pt":1580606731948,"mc":[{"id":"1.168179123","rc":[{"batb":[[0,1.27,1201.23],[1,1.26,874.7],[2,1.24,200.32]],"batl":[[0,1.43,341.56],[1,1.44,432.94],[2,1.58,650.58]],"ltp":1.31,"tv":692.66,"id":8326656}]}]}
{"op":"mcm","clk":"1003361004","pt":1580606740394,"mc":[{"id":"1.168179123","rc":[{"batb":[[0,1.27,1028.76]],"ltp":1.31,"tv":692.66,"id":8326656},{"batb":[[0,3.5,32.42],[1,1.01,15.52],[2,1.01,0]],"batl":[[1,5.8,0]],"ltp":6.0,"tv":147.16,"id":9712909}]}]}
{"op":"mcm","clk":"1003361453","pt":1580606746427,"mc":[{"id":"1.168179123","rc":[{"batl":[[0,1.58,650.58],[1,1.44,0],[2,1.58,0]],"ltp":1.31,"tv":692.66,"id":8326656}]}]}
{"op":"mcm","clk":"1003361734","pt":1580606749783,"mc":[{"id":"1.168179123","rc":[{"batl":[[0,1.31,884.7],[1,1.32,638.71],[2,1.58,650.58]],"ltp":1.31,"tv":692.66,"id":8326656},{"batb":[[0,3.65,894.33],[1,3.5,32.42],[2,1.01,15.52]],"ltp":6.0,"tv":147.16,"id":9712909}]}]}
{"op":"mcm","clk":"1003361787","pt":1580606750401,"mc":[{"id":"1.168179123","rc":[{"batb":[[0,4.6,33.99],[1,3.9,49.73]],"ltp":6.0,"tv":147.16,"id":9712909}]}]}
{"op":"mcm","clk":"1003362245","pt":1580606755875,"mc":[{"id":"1.168179123","rc":[{"batb":[[0,1.22,222.83],[1,1.01,15.51],[2,1.24,0]],"batl":[[0,1.58,650.58],[1,1.32,0],[2,1.58,0]],"ltp":1.31,"tv":692.66,"id":8326656},{"batb":[[0,3.9,49.73],[1,1.01,15.52],[2,1.01,0]],"ltp":6.0,"tv":147.16,"id":9712909}]}]}
{"op":"mcm","clk":"1003362470","pt":1580606758506,"mc":[{"id":"1.168179123","rc":[{"batb":[[0,1.25,765.23],[1,1.24,958.05],[2,1.22,222.83]],"batl":[[0,1.37,691.11],[1,1.38,518.18],[2,1.58,650.58]],"ltp":1.31,"tv":692.66,"id":8326656}]}]}
{"op":"mcm","clk":"1003362815","pt":1580606763103,"mc":[{"id":"1.168179123","rc":[{"batl":[[0,1.58,650.58],[1,1.38,0],[2,1.58,0]],"ltp":1.31,"tv":692.66,"id":8326656}]}]}
{"op":"mcm","clk":"1003363116","pt":1580606766886,"mc":[{"id":"1.168179123","rc":[{"batl":[[0,1.28,639.88],[1,1.29,725.08],[2,1.58,650.58]],"ltp":1.31,"tv":692.66,"id":8326656},{"batb":[[0,4.9,29.03],[1,4.3,38.32],[2,1.01,15.52]],"ltp":6.0,"tv":147.16,"id":9712909}]}]}
{"op":"mcm","clk":"1003363271","pt":1580606768795,"mc":[{"id":"1.168179123","rc":[{"batl":[[0,6.6,98.95]],"ltp":6.0,"tv":147.16,"id":9712909}]}]}
{"op":"mcm","clk":"1003364397","pt":1580606782852,"mc":[{"id":"1.168179123","rc":[{"batb":[[0,1.24,392.47],[1,1.2,240.77],[2,1.01,15.51]],"batl":[[0,1.58,650.58],[1,1.29,0],[2,1.58,0]],"ltp":1.31,"tv":692.66,"id":8326656},{"batb":[[0,4.3,38.32],[1,1.01,15.52],[2,1.01,0]],"ltp":6.0,"tv":147.16,"id":9712909}]}]}
{"op":"mcm","clk":"1003364611","pt":1580606785536,"mc":[{"id":"1.168179123","rc":[{"batb":[[1,1.23,998.86],[2,1.2,240.77]],"batl":[[0,1.32,834.58],[1,1.33,615.83],[2,1.58,650.58]],"ltp":1.31,"tv":692.66,"id":8326656}]}]}
{"op":"mcm","clk":"1003364704","pt":1580606786727,"mc":[{"id":"1.168179123","rc":[{"batl":[[0,1.58,650.58],[1,1.33,0],[2,1.58,0]],"ltp":1.31,"tv":692.66,"id":8326656}]}]}
{"op":"mcm","clk":"1003364933","pt":1580606789732,"mc":[{"id":"1.168179123","rc":[{"batl":[[0,1.27,1084.55],[1,1.28,747.26],[2,1.58,650.58]],"ltp":1.31,"tv":692.66,"id":8326656}]}]}
{"op":"mcm","clk":"1003365006","pt":1580606790660,"mc":[{"id":"1.168179123","rc":[{"batb":[[0,5.1,25.81],[1,4.7,31.32],[2,1.01,15.52]],"ltp":6.0,"tv":147.16,"id":9712909}]}]}
{"op":"mcm","clk":"1003365723","pt":1580606800262,"mc":[{"id":"1.168179123","rc":[{"batb":[[0,1.23,682.84],[1,1.2,240.77],[2,1.01,15.51]],"batl":[[0,1.28,382.47],[1,1.58,650.58],[2,1.58,0]],"ltp":1.31,"tv":692.66,"id":8326656},{"batb":[[0,4.7,31.32],[1,1.01,15.52],[2,1.01,0]],"ltp":6.0,"tv":147.16,"id":9712909}]}]}
{"op":"mcm","clk":"1003365918","pt":1580606802841,"mc":[{"id":"1.168179123","rc":[{"batb":[[1,1.22,1061.19],[2,1.2,240.77]],"batl":[[1,1.29,730.22],[2,1.58,650.58]],"ltp":1.31,"tv":692.66,"id":8326656}]}]}
{"op":"mcm","clk":"1003365962","pt":1580606803357,"mc":[{"id":"1.168179123","rc":[{"batb":[[1,1.2,240.77],[2,1.01,15.51]],"batl":[[1,1.58,650.58],[2,1.58,0]],"ltp":1.31,"tv":692.66,"id":8326656}]}]}
{"op":"mcm","clk":"1003366167","pt":1580606805684,"mc":[{"id":"1.168179123","rc":[{"batb":[[0,1.24,716.04],[1,1.23,1007.25],[2,1.2,240.77]],"batl":[[0,1.27,789.93],[1,1.28,753.46],[2,1.58,650.58]],"ltp":1.31,"tv":692.66,"id":8326656}]}]}
{"op":"mcm","clk":"1003366533","pt":1580606809561,"mc":[{"id":"1.168179123","rc":[{"batb":[[0,1.23,682.84],[1,1.2,240.77],[2,1.01,15.51]],"batl":[[0,1.28,382.47],[1,1.58,650.58],[2,1.58,0]],"ltp":1.31,"tv":692.66,"id":8326656}]}]}
{"op":"mcm","clk":"1003366837","pt":1580606812864,"mc":[{"id":"1.168179123","rc":[{"batb":[[1,1.22,1061.19],[2,1.2,240.77]],"batl":[[1,1.29,730.22],[2,1.58,650.58]],"ltp":1.31,"tv":692.66,"id":8326656}]}]}
{"op":"mcm","clk":"1003367213","pt":1580606817269,"mc":[{"id":"1.168179123","rc":[{"batl":[[0,1.58,650.58],[1,1.29,0],[2,1.58,0]],"ltp":1.31,"tv":692.66,"id":8326656}]}]}
{"op":"mcm","clk":"1003367518","pt":1580606820896,"mc":[{"id":"1.168179123","rc":[{"batl":[[0,1.26,933.57],[1,1.27,783.93],[2,1.58,650.58]],"ltp":1.31,"tv":692.66,"id":8326656},{"batb":[[0,5.3,23.92],[1,4.8,31.08],[2,4.6,32.65]],"ltp":6.0,"tv":147.16,"id":9712909}]}]}
{"op":"mcm","clk":"1003367537","pt":1580606821106,"mc":[{"id":"1.168179123","rc":[{"batb":[[1,4.6,32.65],[2,1.01,15.52]],"ltp":6.0,"tv":147.16,"id":9712909}]}]}
{"op":"mcm","clk":"1003369721","pt":1580606847836,"mc":[{"id":"1.168179123","rc":[{"batb":[[0,1.15,345.26],[1,1.01,15.51],[2,1.2,0]],"batl":[[0,1.58,650.58],[1,1.27,0],[2,1.58,0]],"ltp":1.31,"tv":692.66,"id":8326656},{"batb":[[0,4.6,32.65],[1,1.01,15.52],[2,1.01,0]],"ltp":6.0,"tv":147.16,"id":9712909}]}]}
{"op":"mcm","clk":"1003369964","pt":1580606850745,"mc":[{"id":"1.168179123","rc":[{"batb":[[0,1.18,605.2],[1,1.17,1433.8],[2,1.15,345.26]],"batl":[[0,1.3,385.93],[1,1.31,672.81],[2,1.58,650.58]],"ltp":1.31,"tv":692.66,"id":8326656}]}]}
{"op":"mcm","clk":"1003370913","pt":1580606863264,"mc":[{"id":"1.168179123","rc":[{"batl":[[0,1.58,650.58],[1,1.31,0],[2,1.58,0]],"ltp":1.31,"tv":692.66,"id":8326656}]}]}
{"op":"mcm","clk":"1003371214","pt":1580606866841,"mc":[{"id":"1.168179123","rc":[{"batl":[[0,1.2,694.58],[1,1.21,1062.55]],"ltp":1.31,"tv":692.66,"id":8326656},{"batb":[[0,6.4,29.82],[1,5.4,22.9],[2,1.01,15.52]],"ltp":6.0,"tv":147.16,"id":9712909}]}]}
{"op":"mcm","clk":"1003371332","pt":1580606868338,"mc":[{"id":"1.168179123","rc":[{"batl":[[2,1.51,741.08]],"ltp":1.31,"tv":692.66,"id":8326656},{"batl":[[0,9.4,78.04]],"ltp":6.0,"tv":147.16,"id":9712909}]}]}
{"op":"mcm","clk":"1003372554","pt":1580606882779,"mc":[{"id":"1.168179123","rc":[{"batb":[[0,1.1,526.46],[1,1.01,15.51],[2,1.15,0]],"batl":[[0,1.51,741.08],[1,1.21,0],[2,1.51,0]],"ltp":1.31,"tv":692.66,"id":8326656},{"batb":[[0,5.4,22.9],[1,1.01,15.52],[2,1.01,0]],"ltp":6.0,"tv":147.16,"id":9712909}]}]}
{"op":"mcm","clk":"1003373080","pt":1580606888779,"mc":[{"id":"1.168179123","rc":[{"batb":[[0,1.17,479.86],[1,1.16,1532.3],[2,1.1,526.46]],"batl":[[0,1.19,951.4],[1,1.2,1115.85],[2,1.51,741.08]],"ltp":1.31,"tv":692.66,"id":8326656}]}]}
{"op":"mcm","clk":"1003373263","pt":1580606890896,"mc":[{"id":"1.168179123","rc":[{"batb":[[0,1.1,526.46],[1,1.01,15.51],[2,1.1,0]],"batl":[[0,1.51,741.08],[1,1.2,0],[2,1.51,0]],"ltp":1.31,"tv":692.66,"id":8326656}]}]}
{"op":"mcm","clk":"1003373495","pt":1580606893787,"mc":[{"id":"1.168179123","rc":[{"batb":[[0,1.12,2269.55],[1,1.1,526.46],[2,1.01,15.51]],"batl":[[0,1.25,703.44],[1,1.26,825.62],[2,1.51,741.08]],"ltp":1.31,"tv":692.66,"id":8326656}]}]}
{"op":"mcm","clk":"1003374106","pt":1580606900469,"mc":[{"id":"1.168179123","rc":[{"batl":[[0,1.51,741.08],[1,1.26,0],[2,1.51,0]],"ltp":1.31,"tv":692.66,"id":8326656}]}]}
{"op":"mcm","clk":"1003374410","pt":1580606903573,"mc":[{"id":"1.168179123","rc":[{"batb":[[2,1.06,866.76]],"batl":[[0,1.14,429.19],[1,1.15,1575.12]],"ltp":1.31,"tv":692.66,"id":8326656},{"batb":[[0,8.8,14.87],[1,7,25.49],[2,1.01,15.52]],"ltp":6.0,"tv":147.16,"id":9712909}]}]}
{"op":"mcm","clk":"1003374587","pt":1580606905502,"mc":[{"id":"1.168179123","rc":[{"batl":[[2,1.44,857.74]],"ltp":1.31,"tv":692.66,"id":8326656},{"batl":[[0,13.5,64.07]],"ltp":6.0,"tv":147.16,"id":9712909}]}]}
{"op":"mcm","clk":"1003376846","pt":1580606931656,"mc":[{"id":"1.168179123","rc":[{"batb":[[0,1.06,866.76],[1,1.01,15.51],[2,1.06,0]],"batl":[[0,1.44,857.74],[1,1.15,0],[2,1.44,0]],"ltp":1.31,"tv":692.66,"id":8326656},{"batb":[[0,7,25.49],[1,1.01,15.52],[2,1.01,0]],"ltp":6.0,"tv":147.16,"id":9712909}]}]}
{"op":"mcm","clk":"1003377058","pt":1580606934140,"mc":[{"id":"1.168179123","rc":[{"batb":[[0,1.08,1846.64],[1,1.07,707.08],[2,1.06,866.76]],"batl":[[0,1.19,1396.04],[1,1.2,908.05],[2,1.44,857.74]],"ltp":1.31,"tv":692.66,"id":8326656}]}]}
{"op":"mcm","clk":"1003377666","pt":1580606941261,"mc":[{"id":"1.168179123","rc":[{"batb":[[0,1.06,866.76],[1,1.01,15.51],[2,1.06,0]],"ltp":1.31,"tv":692.66,"id":8326656}]}]}
{"op":"mcm","clk":"1003377977","pt":1580606944773,"mc":[{"id":"1.168179123","rc":[{"batb":[[0,1.16,1502.36],[1,1.15,876.71],[2,1.13,380.11]],"ltp":1.31,"tv":692.66,"id":8326656},{"batb":[[1,5.6,21.56],[2,1.01,15.52]],"ltp":6.0,"tv":147.16,"id":9712909}]}]}
{"op":"mcm","clk":"1003378142","pt":1580606946581,"mc":[{"id":"1.168179123","rc":[{"batl":[[0,9.4,78.04]],"ltp":6.0,"tv":147.16,"id":9712909}]}]}
{"op":"mcm","clk":"1003379438","pt":1580606962358,"mc":[{"id":"1.168179123","rc":[{"batb":[[0,1.08,648.1],[1,1.01,15.51],[2,1.13,0]],"batl":[[0,1.44,857.74],[1,1.2,0],[2,1.44,0]],"ltp":1.31,"tv":692.66,"id":8326656},{"batb":[[0,5.6,21.56],[1,1.01,15.52],[2,1.01,0]],"ltp":6.0,"tv":147.16,"id":9712909}]}]}
{"op":"mcm","clk":"1003379618","pt":1580606964886,"mc":[{"id":"1.168179123","rc":[{"batb":[[0,1.1,1931.77],[1,1.09,574.32],[2,1.08,648.1]],"batl":[[0,1.24,404.48],[1,1.25,872.56],[2,1.44,857.74]],"ltp":1.31,"tv":692.66,"id":8326656}]}]}
{"op":"mcm","clk":"1003380615","pt":1580606978718,"mc":[{"id":"1.168179123","rc":[{"batb":[[0,1.08,648.1],[1,1.01,15.51],[2,1.08,0]],"ltp":1.31,"tv":692.66,"id":8326656}]}]}
{"op":"mcm","clk":"1003380879","pt":1580606981713,"mc":[{"id":"1.168179123","rc":[{"trd":[[1.22,98.95]],"batb":[[0,1.22,344.22],[1,1.21,1114.77],[2,1.08,648.1]],"ltp":1.22,"tv":791.61,"id":8326656},{"trd":[[5.6,21.56]],"batb":[[0,1.01,15.52],[1,1.01,0]],"ltp":5.6,"tv":168.72,"id":9712909}],"tv":960.34}]}
{"op":"mcm","clk":"1003380955","pt":1580606982595,"mc":[{"id":"1.168179123","rc":[{"batb":[[2,1.18,273.73]],"ltp":1.22,"tv":791.61,"id":8326656},{"batb":[[0,4.5,35.8],[1,1.01,15.52]],"ltp":5.6,"tv":168.72,"id":9712909}]}]}
{"op":"mcm","clk":"1003381110","pt":1580606984820,"mc":[{"id":"1.168179123","rc":[{"batb":[[0,1.22,404.31]],"ltp":1.22,"tv":791.61,"id":8326656},{"batl":[[0,8.2,85.46]],"ltp":5.6,"tv":168.72,"id":9712909}]}]}
{"op":"mcm","clk":"1003382428","pt":1580607001799,"mc":[{"id":"1.168179123","rc":[{"batb":[[0,1.11,451.71],[1,1.01,15.51],[2,1.18,0]],"batl":[[0,1.44,857.74],[1,1.25,0],[2,1.44,0]],"ltp":1.22,"tv":791.61,"id":8326656}]}]}
{"op":"mcm","clk":"1003382676","pt":1580607004746,"mc":[{"id":"1.168179123","rc":[{"batb":[[0,1.14,1215.36],[1,1.13,1208.35],[2,1.12,441.72]],"batl":[[0,1.32,943.76],[1,1.33,614.64],[2,1.44,857.74]],"ltp":1.22,"tv":791.61,"id":8326656},{"batb":[[1,4.4,37.06],[2,1.01,15.52]],"ltp":5.6,"tv":168.72,"id":9712909}]}]}
{"op":"mcm","clk":"1003382722","pt":1580607005212,"mc":[{"id":"1.168179123","rc":[{"batb":[[0,4.4,37.06],[1,1.01,15.52],[2,1.01,0]],"ltp":5.6,"tv":168.72,"id":9712909}]}]}
{"op":"mcm","clk":"1003382904","pt":1580607007432,"mc":[{"id":"1.168179123","rc":[{"batb":[[0,1.12,441.72],[1,1.01,15.51],[2,1.12,0]],"ltp":1.22,"tv":791.61,"id":8326656}]}]}
{"op":"mcm","clk":"1003383051","pt":1580607009144,"mc":[{"id":"1.168179123","rc":[{"batl":[[2,1.44,0]],"ltp":1.22,"tv":791.61,"id":8326656}]}]}
{"op":"mcm","clk":"1003383196","pt":1580607010854,"mc":[{"id":"1.168179123","rc":[{"batb":[[0,1.28,845.56],[1,1.27,832.19],[2,1.25,188.84]],"ltp":1.22,"tv":791.61,"id":8326656},{"batb":[[1,3.85,51.62],[2,1.01,15.52]],"ltp":5.6,"tv":168.72,"id":9712909}]}]}
{"op":"mcm","clk":"1003383358","pt":1580607012710,"mc":[{"id":"1.168179123","rc":[{"batl":[[2,1.66,579.81]],"ltp":1.22,"tv":791.61,"id":8326656},{"batl":[[0,6,106.18]],"ltp":5.6,"tv":168.72,"id":9712909}]}]}
{"op":"mcm","clk":"1003384415","pt":1580607025842,"mc":[{"id":"1.168179123","rc":[{"batb":[[0,1.19,267.83],[1,1.01,15.51],[2,1.25,0]],"batl":[[0,1.66,579.81],[1,1.33,0],[2,1.66,0]],"ltp":1.22,"tv":791.61,"id":8326656},{"batb":[[0,3.85,51.46],[1,1.01,15.52],[2,1.01,0]],"ltp":5.6,"tv":168.72,"id":9712909}]}]}
{"op":"mcm","clk":"1003384556","pt":1580607027547,"mc":[{"id":"1.168179123","rc":[{"batl":[[1,1000,3.04]],"ltp":1.22,"tv":791.61,"id":8326656}]}]}
{"op":"mcm","clk":"1003384655","pt":1580607028839,"mc":[{"id":"1.168179123","rc":[{"batb":[[0,1.21,1369.7],[1,1.2,911.35],[2,1.19,267.83]],"batl":[[0,1.38,778.68],[1,1.39,500.9],[2,1.66,579.81]],"ltp":1.22,"tv":791.61,"id":8326656}]}]}
{"op":"mcm","clk":"1003384850","pt":1580607031457,"mc":[{"id":"1.168179123","rc":[{"batl":[[0,1.38,778.7]],"ltp":1.22,"tv":791.61,"id":8326656}]}]}
{"op":"mcm","clk":"1003384893","pt":1580607032077,"mc":[{"id":"1.168179123","rc":[{"batl":[[0,1.66,579.83],[1,1.39,0],[2,1.66,0]],"ltp":1.22,"tv":791.61,"id":8326656}]}]}
{"op":"mcm","clk":"1003385103","pt":1580607034873,"mc":[{"id":"1.168179123","rc":[{"batl":[[0,1.28,0.02]],"ltp":1.22,"tv":791.61,"id":8326656}]}]}
{"op":"mcm","clk":"1003385186","pt":1580607035854,"mc":[{"id":"1.168179123","rc":[{"batl":[[0,1.24,581.24],[1,1.25,869.18],[2,1.28,0.02]],"ltp":1.22,"tv":791.61,"id":8326656},{"batb":[[0,5.5,21.87],[1,4.5,35.8],[2,1.01,15.52]],"ltp":5.6,"tv":168.72,"id":9712909}]}]}
{"op":"mcm","clk":"1003385360","pt":1580607038075,"mc":[{"id":"1.168179123","rc":[{"batl":[[2,1.55,690.77]],"ltp":1.22,"tv":791.61,"id":8326656},{"batl":[[0,8.2,85.46]],"ltp":5.6,"tv":168.72,"id":9712909}]}]}
{"op":"mcm","clk":"1003386556","pt":1580607052876,"mc":[{"id":"1.168179123","rc":[{"batb":[[0,1.19,267.83],[1,1.11,444.47],[2,1.01,15.51]],"batl":[[0,1.55,690.77],[1,1.25,0],[2,1.55,0]],"ltp":1.22,"tv":791.61,"id":8326656}]}]}
{"op":"mcm","clk":"1003386598","pt":1580607053398,"mc":[{"id":"1.168179123","rc":[{"batb":[[0,1.11,444.47],[1,1.01,15.51],[2,1.01,0]],"ltp":1.22,"tv":791.61,"id":8326656},{"batb":[[0,4.5,35.8],[1,1.01,15.52],[2,1.01,0]],"ltp":5.6,"tv":168.72,"id":9712909}]}]}
{"op":"mcm","clk":"1003386777","pt":1580607055892,"mc":[{"id":"1.168179123","rc":[{"batb":[[0,1.14,1046.98],[1,1.13,1378.22],[2,1.11,444.47]],"batl":[[0,1.31,409.23],[1,1.32,647.31],[2,1.55,690.76]],"ltp":1.22,"tv":791.61,"id":8326656}]}]}
{"op":"mcm","clk":"1003386899","pt":1580607057396,"mc":[{"id":"1.168179123","rc":[{"batb":[[0,1.11,444.47],[1,1.01,15.51],[2,1.11,0]],"batl":[[0,1.55,690.77],[1,1.32,0],[2,1.55,0]],"ltp":1.22,"tv":791.61,"id":8326656}]}]}
{"op":"mcm","clk":"1003387144","pt":1580607060590,"mc":[{"id":"1.168179123","rc":[{"batb":[[0,1.2,737.23],[1,1.19,1265.68],[2,1.11,444.47]],"batl":[[0,1.23,1296.22],[1,1.24,893.48],[2,1.55,690.77]],"ltp":1.22,"tv":791.61,"id":8326656}]}]}
{"op":"mcm","clk":"1003387300","pt":1580607061888,"mc":[{"id":"1.168179123","rc":[{"batb":[[0,1.11,444.47],[1,1.01,15.51],[2,1.11,0]],"batl":[[0,1.55,690.77],[1,1.24,0],[2,1.55,0]],"ltp":1.22,"tv":791.61,"id":8326656}]}]}
{"op":"mcm","clk":"1003387514","pt":1580607064791,"mc":[{"id":"1.168179123","rc":[{"batb":[[0,1.14,1047.28],[1,1.13,1377.92],[2,1.11,444.47]],"batl":[[0,1.31,408.98],[1,1.32,647.3],[2,1.55,690.76]],"ltp":1.22,"tv":791.61,"id":8326656}]}]}
{"op":"mcm","clk":"1003388170","pt":1580607073128,"mc":[{"id":"1.168179123","rc":[{"batb":[[0,1.11,444.47],[1,1.01,15.51],[2,1.11,0]],"ltp":1.22,"tv":791.61,"id":8326656}]}]}
{"op":"mcm","clk":"1003388480","pt":1580607076818,"mc":[{"id":"1.168179123","rc":[{"trd":[[1.28,0.04]],"batb":[[0,1.28,724.24],[1,1.27,829.78],[2,1.25,193.48]],"batl":[[0,1.31,408.96]],"ltp":1.28,"tv":791.65,"id":8326656},{"batb":[[1,3.85,50.59],[2,1.01,15.52]],"ltp":5.6,"tv":168.72,"id":9712909}],"tv":960.38}]}
{"op":"mcm","clk":"1003388707","pt":1580607079607,"mc":[{"id":"1.168179123","rc":[{"batl":[[0,6,106.18]],"ltp":5.6,"tv":168.72,"id":9712909}]}]}
{"op":"mcm","clk":"1003389574","pt":1580607091019,"mc":[{"id":"1.168179123","rc":[{"batl":[[1,7.4,420.59]],"ltp":5.6,"tv":168.72,"id":9712909}]}]}
{"op":"mcm","clk":"1003389675","pt":1580607092336,"mc":[{"id":"1.168179123","rc":[{"trd":[[1.25,386.94],[1.27,1659.56],[1.28,1448.51]],"batb":[[0,1.18,272.08],[1,1.01,15.51],[2,1.25,0]],"batl":[[1,1.55,690.76],[2,1.55,0]],"ltp":1.25,"tv":4286.63,"id":8326656}],"tv":4455.36}]}
{"op":"mcm","clk":"1003389883","pt":1580607094819,"mc":[{"id":"1.168179123","rc":[{"batb":[[0,1.18,272.1]],"ltp":1.25,"tv":4286.63,"id":8326656}]}]}
{"op":"mcm","clk":"1003389946","pt":1580607095542,"mc":[{"id":"1.168179123","rc":[{"batb":[[0,1.27,947.37],[1,1.26,886.55],[2,1.18,272.08]],"batl":[[0,1.3,320.36],[1,1.31,685.29],[2,1.55,690.76]],"ltp":1.25,"tv":4286.63,"id":8326656}]}]}
{"op":"mcm","clk":"1003390064","pt":1580607096736,"mc":[{"id":"1.168179123","rc":[{"batb":[[0,1.18,272.1],[1,1.01,15.51],[2,1.18,0]],"batl":[[0,1.55,690.76],[1,1.31,0],[2,1.55,0]],"ltp":1.25,"tv":4286.63,"id":8326656},{"batb":[[0,3.85,50.59],[1,1.01,15.52],[2,1.01,0]],"batl":[[1,7.4,0]],"ltp":5.6,"tv":168.72,"id":9712909}]}]}
{"op":"mcm","clk":"1003390321","pt":1580607099840,"mc":[{"id":"1.168179123","rc":[{"batb":[[0,1.21,576],[1,1.2,1205.33],[2,1.17,288.29]],"batl":[[0,1.36,365.93],[1,1.37,548.61],[2,1.55,690.76]],"ltp":1.25,"tv":4286.63,"id":8326656},{"batb":[[0,4,46.34]],"ltp":5.6,"tv":168.72,"id":9712909}]}]}
{"op":"mcm","clk":"1003391124","pt":1580607109835,"mc":[{"id":"1.168179123","rc":[{"trd":[[1.34,0.79]],"batb":[[0,1.17,288.31],[1,1.01,15.51],[2,1.17,0]],"ltp":1.34,"tv":4287.41,"id":8326656},{"trd":[[4,0.26]],"batb":[[0,4,46.08]],"ltp":4.0,"tv":168.99,"id":9712909}],"tv":4456.41}]}
{"op":"mcm","clk":"1003391377","pt":1580607112885,"mc":[{"id":"1.168179123","rc":[{"batb":[[0,1.33,435.32],[1,1.32,676.48],[2,1.17,288.31]],"batl":[[2,1.55,0]],"ltp":1.34,"tv":4287.41,"id":8326656}]}]}
{"op":"mcm","clk":"1003391432","pt":1580607113557,"mc":[{"id":"1.168179123","rc":[{"batb":[[2,1.29,161.93]],"ltp":1.34,"tv":4287.41,"id":8326656},{"batb":[[1,3.35,36.51],[2,1.01,15.52]],"ltp":4.0,"tv":168.99,"id":9712909}]}]}
{"op":"mcm","clk":"1003391585","pt":1580607115777,"mc":[{"id":"1.168179123","rc":[{"batl":[[2,1000,0.16]],"ltp":1.34,"tv":4287.41,"id":8326656}]}]}
{"op":"mcm","clk":"1003391674","pt":1580607116863,"mc":[{"id":"1.168179123","rc":[{"batl":[[2,1.73,527.57]],"ltp":1.34,"tv":4287.41,"id":8326656},{"batl":[[0,5.3,118.79],[1,7.8,414.67]],"ltp":4.0,"tv":168.99,"id":9712909}]}]}
{"op":"mcm","clk":"1003391875","pt":1580607119547,"mc":[{"id":"1.168179123","rc":[{"trd":[[1.33,0.32]],"batb":[[0,1.33,435.16]],"ltp":1.33,"tv":4287.73,"id":8326656}],"tv":4456.72}]}
{"op":"mcm","clk":"1003392115","pt":1580607122694,"mc":[{"id":"1.168179123","rc":[{"trd":[[1.33,401.93]],"batb":[[0,1.33,234.35]],"ltp":1.33,"tv":4689.35,"id":8326656}],"tv":4858.34}]}
{"op":"mcm","clk":"1003392345","pt":1580607125878,"mc":[{"id":"1.168179123","rc":[{"batb":[[0,1.33,356.37]],"batl":[[0,1.36,443.13]],"ltp":1.33,"tv":4689.35,"id":8326656}]}]}
{"op":"mcm","clk":"1003393493","pt":1580607141777,"mc":[{"id":"1.168179123","rc":[{"trd":[[1.33,601.93]],"batb":[[0,1.33,256.37]],"ltp":1.33,"tv":4889.35,"id":8326656}],"tv":5058.34}]}
{"op":"mcm","clk":"1003393720","pt":1580607145022,"mc":[{"id":"1.168179123","rc":[{"batb":[[0,1.33,317.08]],"ltp":1.33,"tv":4889.35,"id":8326656}]}]}
{"op":"mcm","clk":"1003395376","pt":1580607167347,"mc":[{"id":"1.168179123","rc":[{"trd":[[1.33,609.51]],"batb":[[0,1.33,313.29]],"ltp":1.33,"tv":4896.92,"id":8326656}],"tv":5065.92}]}
{"op":"mcm","clk":"1003397156","pt":1580607192445,"mc":[{"id":"1.168179123","rc":[{"trd":[[4,20.26]],"batb":[[0,4,36.08]],"ltp":4.0,"tv":188.99,"id":9712909}],"tv":5085.92}]}
{"op":"mcm","clk":"1003397243","pt":1580607193783,"mc":[{"id":"1.168179123","rc":[{"batb":[[0,1.26,186.49],[1,1.01,15.51],[2,1.29,0]],"batl":[[0,1.73,527.57],[1,1.37,0],[2,1.73,0]],"ltp":1.33,"tv":4896.92,"id":8326656},{"batb":[[0,3.35,36.51],[1,1.01,15.52],[2,1.01,0]],"batl":[[1,7.8,0]],"ltp":4.0,"tv":188.99,"id":9712909}]}]}
{"op":"mcm","clk":"1003397453","pt":1580607196688,"mc":[{"id":"1.168179123","rc":[{"batb":[[0,1.29,497.08],[1,1.28,802.68],[2,1.26,186.48]],"batl":[[0,1.46,293.02],[1,1.47,404.32],[2,1.73,527.57]],"ltp":1.33,"tv":4896.92,"id":8326656},{"batb":[[1,3.3,36.9],[2,1.01,15.52]],"ltp":4.0,"tv":188.99,"id":9712909}]}]}
{"op":"mcm","clk":"1003397470","pt":1580607196997,"mc":[{"id":"1.168179123","rc":[{"batb":[[2,1.26,184.9]],"batl":[[0,1.73,527.57],[1,1.47,0],[2,1.73,0]],"ltp":1.33,"tv":4896.92,"id":8326656},{"batb":[[0,3.3,36.9],[1,1.01,15.52],[2,1.01,0]],"ltp":4.0,"tv":188.99,"id":9712909}]}]}
{"op":"mcm","clk":"1003397674","pt":1580607199894,"mc":[{"id":"1.168179123","rc":[{"batl":[[0,1.32,578.04],[1,1.33,631.89]],"ltp":1.33,"tv":4896.92,"id":8326656}]}]}
{"op":"mcm","clk":"1003397747","pt":1580607200775,"mc":[{"id":"1.168179123","rc":[{"batb":[[0,4.3,38.24],[1,3.7,27.85],[2,1.01,15.52]],"ltp":4.0,"tv":188.99,"id":9712909}]}]}
{"op":"mcm","clk":"1003397905","pt":1580607203100,"mc":[{"id":"1.168179123","rc":[{"batl":[[2,1.66,579.81]],"ltp":1.33,"tv":4896.92,"id":8326656},{"batl":[[0,6,106.18]],"ltp":4.0,"tv":188.99,"id":9712909}]}]}
{"op":"mcm","clk":"1003398484","pt":1580607211717,"mc":[{"id":"1.168179123","rc":[{"batb":[[0,1.24,205.53],[1,1.01,15.51],[2,1.26,0]],"batl":[[0,1.66,579.81],[1,1.33,0],[2,1.66,0]],"ltp":1.33,"tv":4896.92,"id":8326656},{"batb":[[0,3.7,27.85],[1,1.01,15.52],[2,1.01,0]],"ltp":4.0,"tv":188.99,"id":9712909}]}]}
{"op":"mcm","clk":"1003398653","pt":1580607214301,"mc":[{"id":"1.168179123","rc":[{"batb":[[0,1.26,919.86],[1,1.25,932.02],[2,1.24,205.52]],"batl":[[0,1.39,590.57],[1,1.4,495.57],[2,1.66,579.81]],"ltp":1.33,"tv":4896.92,"id":8326656}]}]}
{"op":"mcm","clk":"1003399035","pt":1580607219931,"mc":[{"id":"1.168179123","rc":[{"batb":[[0,1.24,205.53],[1,1.01,15.51],[2,1.24,0]],"ltp":1.33,"tv":4896.92,"id":8326656}]}]}
{"op":"mcm","clk":"1003399266","pt":1580607222823,"mc":[{"id":"1.168179123","rc":[{"batb":[[0,1.35,635.53],[1,1.34,630.52],[2,1.24,205.53]],"ltp":1.33,"tv":4896.92,"id":8326656}]}]}
{"op":"mcm","clk":"1003399334","pt":1580607223703,"mc":[{"id":"1.168179123","rc":[{"batb":[[2,1.33,140.53]],"ltp":1.33,"tv":4896.92,"id":8326656},{"batb":[[1,2.96,49.18],[2,1.01,15.52]],"ltp":4.0,"tv":188.99,"id":9712909}]}]}
{"op":"mcm","clk":"1003399537","pt":1580607226637,"mc":[{"id":"1.168179123","rc":[{"batl":[[0,4.9,126.27]],"ltp":4.0,"tv":188.99,"id":9712909}]}]}
{"op":"mcm","clk":"1003400126","pt":1580607234717,"mc":[{"id":"1.168179123","rc":[{"batb":[[0,1.28,170.91],[1,1.01,15.51],[2,1.33,0]],"batl":[[0,1.66,579.81],[1,1.4,0],[2,1.66,0]],"ltp":1.33,"tv":4896.92,"id":8326656},{"batb":[[0,2.96,49.18],[1,1.01,15.52],[2,1.01,0]],"ltp":4.0,"tv":188.99,"id":9712909}]}]}
{"op":"mcm","clk":"1003400302","pt":1580607237042,"mc":[{"id":"1.168179123","rc":[{"batb":[[0,1.3,510.01],[1,1.29,768.7],[2,1.28,170.91]],"batl":[[0,1.54,591.79],[1,1.55,326.17],[2,1.66,579.81]],"ltp":1.33,"tv":4896.92,"id":8326656}]}]}
{"op":"mcm","clk":"1003400414","pt":1580607238643,"mc":[{"id":"1.168179123","rc":[{"batb":[[0,1.28,170.91],[1,1.01,15.51],[2,1.28,0]],"batl":[[0,1.66,579.81],[1,1.55,0],[2,1.66,0]],"ltp":1.33,"tv":4896.92,"id":8326656}]}]}
{"op":"mcm","clk":"1003400664","pt":1580607241751,"mc":[{"id":"1.168179123","rc":[{"batb":[[0,1.38,316.25],[1,1.37,561.89],[2,1.28,170.91]],"batl":[[0,1.42,702.74],[1,1.43,450.43],[2,1.66,579.81]],"ltp":1.33,"tv":4896.92,"id":8326656}]}]}
{"op":"mcm","clk":"1003400898","pt":1580607244855,"mc":[{"id":"1.168179123","rc":[{"batb":[[0,1.28,170.91],[1,1.01,15.51],[2,1.28,0]],"batl":[[0,1.66,579.81],[1,1.43,0],[2,1.66,0]],"ltp":1.33,"tv":4896.92,"id":8326656}]}]}
{"op":"mcm","clk":"1003401119","pt":1580607247651,"mc":[{"id":"1.168179123","rc":[{"batb":[[0,1.3,510.01],[1,1.29,768.7],[2,1.28,170.91]],"batl":[[0,1.54,591.79],[1,1.55,326.17],[2,1.66,579.81]],"ltp":1.33,"tv":4896.92,"id":8326656}]}]}
{"op":"mcm","clk":"1003402263","pt":1580607261864,"mc":[{"id":"1.168179123","rc":[{"batl":[[0,1.66,579.81],[1,1.55,0],[2,1.66,0]],"ltp":1.33,"tv":4896.92,"id":8326656}]}]}
{"op":"mcm","clk":"1003402471","pt":1580607264555,"mc":[{"id":"1.168179123","rc":[{"batl":[[0,1.33,492.8],[1,1.34,610.11],[2,1.66,579.81]],"ltp":1.33,"tv":4896.92,"id":8326656}]}]}
{"op":"mcm","clk":"1003402532","pt":1580607265389,"mc":[{"id":"1.168179123","rc":[{"batb":[[0,4.1,42.88],[1,3.45,33.2],[2,1.01,15.52]],"ltp":4.0,"tv":188.99,"id":9712909}]}]}
{"op":"mcm","clk":"1003402675","pt":1580607267472,"mc":[{"id":"1.168179123","rc":[{"batl":[[0,6,106.18]],"ltp":4.0,"tv":188.99,"id":9712909}]}]}
{"op":"mcm","clk":"1003404328","pt":1580607291524,"mc":[{"id":"1.168179123","rc":[{"batb":[[0,1.24,198.21],[1,1.01,15.51],[2,1.28,0]],"batl":[[0,1.66,579.81],[1,1.34,0],[2,1.66,0]],"ltp":1.33,"tv":4896.92,"id":8326656},{"batb":[[0,3.45,33.2],[1,1.01,15.52],[2,1.01,0]],"ltp":4.0,"tv":188.99,"id":9712909}]}]}
{"op":"mcm","clk":"1003404565","pt":1580607294725,"mc":[{"id":"1.168179123","rc":[{"batb":[[0,1.26,1153.55],[1,1.25,937.22],[2,1.24,198.2]],"batl":[[0,1.42,488.65],[1,1.43,452.46],[2,1.66,579.81]],"ltp":1.33,"tv":4896.92,"id":8326656}]}]}
{"op":"mcm","clk":"1003405368","pt":1580607305797,"mc":[{"id":"1.168179123","rc":[{"batl":[[0,1.66,579.81],[1,1.43,0],[2,1.66,0]],"ltp":1.33,"tv":4896.92,"id":8326656}]}]}
{"op":"mcm","clk":"1003405593","pt":1580607308819,"mc":[{"id":"1.168179123","rc":[{"batl":[[0,1.3,945.36],[1,1.31,676.47],[2,1.66,579.81]],"ltp":1.33,"tv":4896.92,"id":8326656}]}]}
{"op":"mcm","clk":"1003405675","pt":1580607309632,"mc":[{"id":"1.168179123","rc":[{"batb":[[0,4.5,34.54],[1,4,46.42],[2,1.01,15.52]],"ltp":4.0,"tv":188.99,"id":9712909}]}]}
{"op":"mcm","clk":"1003406647","pt":1580607321820,"mc":[{"id":"1.168179123","rc":[{"batb":[[0,1.25,826.47],[1,1.23,214.49],[2,1.01,15.51]],"batl":[[0,1.66,579.81],[1,1.31,0],[2,1.66,0]],"ltp":1.33,"tv":4896.92,"id":8326656},{"batb":[[0,4,46.42],[1,1.01,15.52],[2,1.01,0]],"ltp":4.0,"tv":188.99,"id":9712909}]}]}
{"op":"mcm","clk":"1003406867","pt":1580607324487,"mc":[{"id":"1.168179123","rc":[{"batb":[[1,1.24,977.37],[2,1.23,214.49]],"batl":[[0,1.33,398.07],[1,1.34,611.54],[2,1.66,579.81]],"ltp":1.33,"tv":4896.92,"id":8326656}]}]}
{"op":"mcm","clk":"1003407267","pt":1580607329182,"mc":[{"id":"1.168179123","rc":[{"batl":[[0,1.66,579.81],[1,1.34,0],[2,1.66,0]],"ltp":1.33,"tv":4896.92,"id":8326656}]}]}
{"op":"mcm","clk":"1003407596","pt":1580607332897,"mc":[{"id":"1.168179123","rc":[{"trd":[[1.28,1448.55]],"batb":[[0,1.25,826.45]],"batl":[[0,1.28,630.11],[1,1.29,740],[2,1.66,579.81]],"ltp":1.28,"tv":4896.96,"id":8326656},{"batb":[[0,4.8,30.69],[1,4.1,43.2],[2,1.01,15.52]],"ltp":4.0,"tv":188.99,"id":9712909}],"tv":5085.95}]}
{"op":"mcm","clk":"1003409557","pt":1580607358905,"mc":[{"id":"1.168179123","rc":[{"trd":[[1.25,387.28]],"batb":[[0,1.25,826.28]],"ltp":1.25,"tv":4897.3,"id":8326656}],"tv":5086.29}]}
{"op":"mcm","clk":"1003410021","pt":1580607365310,"mc":[{"id":"1.168179123","rc":[{"batb":[[0,1.17,299.78],[1,1.01,15.51],[2,1.23,0]],"batl":[[0,1.66,579.81],[1,1.29,0],[2,1.66,0]],"ltp":1.25,"tv":4897.3,"id":8326656},{"batb":[[0,4.1,43.2],[1,1.01,15.52],[2,1.01,0]],"ltp":4.0,"tv":188.99,"id":9712909}]}]}
{"op":"mcm","clk":"1003410207","pt":1580607367903,"mc":[{"id":"1.168179123","rc":[{"batb":[[0,1.19,1048.18],[1,1.18,1274.34],[2,1.17,299.78]],"batl":[[0,1.33,339.86],[1,1.34,612.26],[2,1.66,579.81]],"ltp":1.25,"tv":4897.3,"id":8326656}]}]}
{"op":"mcm","clk":"1003410610","pt":1580607373421,"mc":[{"id":"1.168179123","rc":[{"batl":[[0,1.66,579.81],[1,1.34,0],[2,1.66,0]],"ltp":1.25,"tv":4897.3,"id":8326656}]}]}
{"op":"mcm","clk":"1003410842","pt":1580607376526,"mc":[{"id":"1.168179123","rc":[{"batl":[[0,1.22,1247.48],[1,1.23,960.69]],"ltp":1.25,"tv":4897.3,"id":8326656}]}]}
{"op":"mcm","clk":"1003410891","pt":1580607377144,"mc":[{"id":"1.168179123","rc":[{"batb":[[0,5.9,37.37],[1,4.9,29.19],[2,1.01,15.52]],"ltp":4.0,"tv":188.99,"id":9712909}]}]}
{"op":"mcm","clk":"1003410986","pt":1580607378328,"mc":[{"id":"1.168179123","rc":[{"batl":[[2,1.55,690.76]],"ltp":1.25,"tv":4897.3,"id":8326656},{"batl":[[0,8.2,85.46]],"ltp":4.0,"tv":188.99,"id":9712909}]}]}
{"op":"mcm","clk":"1003411996","pt":1580607391823,"mc":[{"id":"1.168179123","rc":[{"batb":[[0,1.17,299.78],[1,1.11,471.86],[2,1.01,15.51]],"batl":[[0,1.55,690.76],[1,1.23,0],[2,1.55,0]],"ltp":1.25,"tv":4897.3,"id":8326656}]}]}
{"op":"mcm","clk":"1003412042","pt":1580607392340,"mc":[{"id":"1.168179123","rc":[{"batb":[[0,1.11,471.86],[1,1.01,15.51],[2,1.01,0]],"ltp":1.25,"tv":4897.3,"id":8326656},{"batb":[[0,4.9,29.19],[1,1.01,15.52],[2,1.01,0]],"ltp":4.0,"tv":188.99,"id":9712909}]}]}
{"op":"mcm","clk":"1003412228","pt":1580607394869,"mc":[{"id":"1.168179123","rc":[{"batb":[[0,1.13,1176.22],[1,1.12,1269.58],[2,1.11,471.86]],"batl":[[0,1.27,536.45],[1,1.28,774.64],[2,1.55,690.76]],"ltp":1.25,"tv":4897.3,"id":8326656}]}]}
{"op":"mcm","clk":"1003413096","pt":1580607407285,"mc":[{"id":"1.168179123","rc":[{"batb":[[0,1.11,471.86],[1,1.01,15.51],[2,1.11,0]],"ltp":1.25,"tv":4897.3,"id":8326656}]}]}
{"op":"mcm","clk":"1003413373","pt":1580607410891,"mc":[{"id":"1.168179123","rc":[{"batb":[[0,1.24,1049.57],[1,1.23,1035.25],[2,1.22,221.88]],"ltp":1.25,"tv":4897.3,"id":8326656},{"batb":[[1,4.1,43.35],[2,1.01,15.52]],"ltp":4.0,"tv":188.99,"id":9712909}]}]}
{"op":"mcm","clk":"1003413522","pt":1580607412799,"mc":[{"id":"1.168179123","rc":[{"batl":[[0,7.2,93.09]],"ltp":4.0,"tv":188.99,"id":9712909}]}]}
{"op":"mcm","clk":"1003414619","pt":1580607427809,"mc":[{"id":"1.168179123","rc":[{"batb":[[0,1.22,221.88],[1,1.15,334.4],[2,1.01,15.51]],"batl":[[0,1.55,690.76],[1,1.28,0],[2,1.55,0]],"ltp":1.25,"tv":4897.3,"id":8326656}]}]}
{"op":"mcm","clk":"1003414637","pt":1580607428118,"mc":[{"id":"1.168179123","rc":[{"batb":[[0,1.15,334.4],[1,1.01,15.51],[2,1.01,0]],"ltp":1.25,"tv":4897.3,"id":8326656},{"batb":[[0,4.1,43.35],[1,1.01,15.52],[2,1.01,0]],"ltp":4.0,"tv":188.99,"id":9712909}]}]}
{"op":"mcm","clk":"1003414807","pt":1580607430592,"mc":[{"id":"1.168179123","rc":[{"batb":[[0,1.17,1507.2],[1,1.16,851.41],[2,1.15,334.4]],"batl":[[0,1.34,877.74],[1,1.35,583.22],[2,1.55,690.76]],"ltp":1.25,"tv":4897.3,"id":8326656}]}]}
{"op":"mcm","clk":"1003415044","pt":1580607434198,"mc":[{"id":"1.168179123","rc":[{"batb":[[0,1.15,334.4],[1,1.01,15.51],[2,1.15,0]],"ltp":1.25,"tv":4897.3,"id":8326656}]}]}
{"op":"mcm","clk":"1003415280","pt":1580607437807,"mc":[{"id":"1.168179123","rc":[{"batb":[[0,1.3,754.43],[1,1.29,773.25],[2,1.28,169.64]],"ltp":1.25,"tv":4897.3,"id":8326656},{"batb":[[1,3.65,28.88],[2,1.01,15.52]],"ltp":4.0,"tv":188.99,"id":9712909}]}]}
{"op":"mcm","clk":"1003415430","pt":1580607440026,"mc":[{"id":"1.168179123","rc":[{"batl":[[0,6,107.01]],"ltp":4.0,"tv":188.99,"id":9712909}]}]}
{"op":"mcm","clk":"1003416099","pt":1580607449819,"mc":[{"id":"1.168179123","rc":[{"batb":[[0,1.28,169.64],[1,1.21,234.31],[2,1.01,15.51]],"batl":[[0,1.55,690.76],[1,1.35,0],[2,1.55,0]],"ltp":1.25,"tv":4897.3,"id":8326656}]}]}
{"op":"mcm","clk":"1003416129","pt":1580607450231,"mc":[{"id":"1.168179123","rc":[{"batb":[[0,1.21,234.31],[1,1.01,15.51],[2,1.01,0]],"ltp":1.25,"tv":4897.3,"id":8326656},{"batb":[[0,3.65,28.88],[1,1.01,15.52],[2,1.01,0]],"ltp":4.0,"tv":188.99,"id":9712909}]}]}
{"op":"mcm","clk":"1003416293","pt":1580607452513,"mc":[{"id":"1.168179123","rc":[{"batb":[[0,1.23,1299.5],[1,1.22,944.81],[2,1.21,234.31]],"batl":[[0,1.39,319.42],[1,1.4,498.69],[2,1.55,690.76]],"ltp":1.25,"tv":4897.3,"id":8326656}]}]}
{"op":"mcm","clk":"1003416972","pt":1580607461734,"mc":[{"id":"1.168179123","rc":[{"batl":[[0,1.55,690.76],[1,1.4,0],[2,1.55,0]],"ltp":1.25,"tv":4897.3,"id":8326656}]}]}
{"op":"mcm","clk":"1003417199","pt":1580607464839,"mc":[{"id":"1.168179123","rc":[{"batl":[[0,1.26,428.17],[1,1.27,811.95],[2,1.55,690.76]],"ltp":1.25,"tv":4897.3,"id":8326656}]}]}
{"op":"mcm","clk":"1003417267","pt":1580607465668,"mc":[{"id":"1.168179123","rc":[{"batb":[[0,5,26.91],[1,4,45.32],[2,1.01,15.52]],"ltp":4.0,"tv":188.99,"id":9712909}]}]}
{"op":"mcm","clk":"1003417458","pt":1580607468139,"mc":[{"id":"1.168179123","rc":[{"batl":[[0,7.2,93.12]],"ltp":4.0,"tv":188.99,"id":9712909}]}]}
{"op":"mcm","clk":"1003419162","pt":1580607489890,"mc":[{"id":"1.168179123","rc":[{"batb":[[0,1.12,407.89],[1,1.01,15.51],[2,1.21,0]],"batl":[[0,1.55,690.76],[1,1.27,0],[2,1.55,0]],"ltp":1.25,"tv":4897.3,"id":8326656},{"batb":[[0,4,45.32],[1,1.01,15.52],[2,1.01,0]],"ltp":4.0,"tv":188.99,"id":9712909}]}]}
{"op":"mcm","clk":"1003419343","pt":1580607492775,"mc":[{"id":"1.168179123","rc":[{"batb":[[0,1.15,575.57],[1,1.14,1828.58],[2,1.12,407.89]],"batl":[[0,1.35,752.66],[1,1.36,564.6],[2,1.55,690.76]],"ltp":1.25,"tv":4897.3,"id":8326656}]}]}
{"op":"mcm","clk":"1003420031","pt":1580607502501,"mc":[{"id":"1.168179123","rc":[{"batb":[[0,1.12,407.89],[1,1.01,15.51],[2,1.12,0]],"ltp":1.25,"tv":4897.3,"id":8326656}]}]}
{"op":"mcm","clk":"1003420167","pt":1580607504413,"mc":[{"id":"1.168179123","rc":[{"batl":[[2,1.55,0]],"ltp":1.25,"tv":4897.3,"id":8326656}]}]}
{"op":"mcm","clk":"1003420255","pt":1580607505701,"mc":[{"id":"1.168179123","rc":[{"batb":[[0,1.31,793.03],[1,1.3,741.67],[2,1.12,407.89]],"ltp":1.25,"tv":4897.3,"id":8326656}]}]}
{"op":"mcm","clk":"1003420288","pt":1580607506214,"mc":[{"id":"1.168179123","rc":[{"batb":[[2,1.29,164.52]],"ltp":1.25,"tv":4897.3,"id":8326656},{"batb":[[1,3.55,31.47],[2,1.01,15.52]],"ltp":4.0,"tv":188.99,"id":9712909}]}]}
{"op":"mcm","clk":"1003420444","pt":1580607508282,"mc":[{"id":"1.168179123","rc":[{"batl":[[2,1.71,539.26]],"ltp":1.25,"tv":4897.3,"id":8326656},{"batl":[[0,5.5,115.94]],"ltp":4.0,"tv":188.99,"id":9712909}]}]}
{"op":"mcm","clk":"1003421810","pt":1580607527725,"mc":[{"id":"1.168179123","rc":[{"batb":[[0,1.21,239.9],[1,1.01,15.51],[2,1.29,0]],"batl":[[0,1.71,539.26],[1,1.36,0],[2,1.71,0]],"ltp":1.25,"tv":4897.3,"id":8326656},{"batb":[[0,3.55,31.47],[1,1.01,15.52],[2,1.01,0]],"ltp":4.0,"tv":188.99,"id":9712909}]}]}
{"op":"mcm","clk":"1003422000","pt":1580607530207,"mc":[{"id":"1.168179123","rc":[{"batb":[[0,1.23,1132.39],[1,1.22,1094.52],[2,1.21,239.9]],"batl":[[0,1.42,610.39],[1,1.43,451.48],[2,1.71,539.26]],"ltp":1.25,"tv":4897.3,"id":8326656}]}]}
{"op":"mcm","clk":"1003422285","pt":1580607534711,"mc":[{"id":"1.168179123","rc":[{"batb":[[0,1.21,239.9],[1,1.01,15.51],[2,1.21,0]],"ltp":1.25,"tv":4897.3,"id":8326656}]}]}
{"op":"mcm","clk":"1003422488","pt":1580607537803,"mc":[{"id":"1.168179123","rc":[{"batb":[[0,1.38,416.09],[1,1.37,563.17],[2,1.21,239.9]],"ltp":1.25,"tv":4897.3,"id":8326656}]}]}
{"op":"mcm","clk":"1003422528","pt":1580607538422,"mc":[{"id":"1.168179123","rc":[{"batb":[[2,1.35,128.72]],"batl":[[0,1.42,548.26]],"ltp":1.25,"tv":4897.3,"id":8326656},{"batb":[[1,2.9,52.4],[2,1.01,15.52]],"ltp":4.0,"tv":188.99,"id":9712909}]}]}
{"op":"mcm","clk":"1003422694","pt":1580607540752,"mc":[{"id":"1.168179123","rc":[{"batl":[[0,4.9,123.9]],"ltp":4.0,"tv":188.99,"id":9712909}]}]}
{"op":"mcm","clk":"1003422745","pt":1580607541429,"mc":[{"id":"1.168179123","rc":[{"batb":[[0,1.38,480.13]],"ltp":1.25,"tv":4897.3,"id":8326656}]}]}
{"op":"mcm","clk":"1003423096","pt":1580607546844,"mc":[{"id":"1.168179123","rc":[{"batb":[[0,3.55,30.84],[1,2.92,51.38]],"ltp":4.0,"tv":188.99,"id":9712909}]}]}
{"op":"mcm","clk":"1003423794","pt":1580607556877,"mc":[{"id":"1.168179123","rc":[{"trd":[[1.38,200]],"batb":[[0,1.38,380.13]],"ltp":1.38,"tv":5097.3,"id":8326656},{"trd":[[3.55,9.65]],"batb":[[0,3.55,26.02]],"ltp":3.55,"tv":198.64,"id":9712909}],"tv":5295.94}]}
{"op":"mcm","clk":"1003424024","pt":1580607559765,"mc":[{"id":"1.168179123","rc":[{"batb":[[0,1.38,445.46]],"ltp":1.38,"tv":5097.3,"id":8326656}]}]}
{"op":"mcm","clk":"1003425100","pt":1580607572363,"mc":[{"id":"1.168179123","rc":[{"trd":[[1.4,23]],"ltp":1.4,"tv":5120.3,"id":8326656},{"trd":[[3.55,18.72]],"batb":[[0,3.55,16.95]],"ltp":3.55,"tv":207.71,"id":9712909}],"tv":5328.01}]}
{"op":"mcm","clk":"1003425379","pt":1580607575880,"mc":[{"id":"1.168179123","rc":[{"batb":[[2,2.9,52.09]],"ltp":3.55,"tv":207.71,"id":9712909}]}]}
{"op":"mcm","clk":"1003425393","pt":1580607576085,"mc":[{"id":"1.168179123","rc":[{"batb":[[1,2.9,52.09],[2,1.01,15.52]],"ltp":3.55,"tv":207.71,"id":9712909}]}]}
{"op":"mcm","clk":"1003429430","pt":1580607628761,"mc":[{"id":"1.168179123","rc":[{"batb":[[0,1.35,128.72],[1,1.31,150.75],[2,1.01,15.51]],"batl":[[0,1.71,539.26],[1,1.43,0],[2,1.71,0]],"ltp":1.4,"tv":5120.3,"id":8326656}]}]}
{"op":"mcm","clk":"1003429470","pt":1580607629123,"mc":[{"id":"1.168179123","rc":[{"batb":[[0,1.31,150.75],[1,1.01,15.51],[2,1.01,0]],"ltp":1.4,"tv":5120.3,"id":8326656},{"batb":[[0,2.9,52.09],[1,1.01,15.52],[2,1.01,0]],"ltp":3.55,"tv":207.71,"id":9712909}]}]}
{"op":"mcm","clk":"1003429666","pt":1580607631645,"mc":[{"id":"1.168179123","rc":[{"batb":[[0,1.33,655.53],[1,1.32,681.21],[2,1.31,150.75]],"batl":[[0,1.55,365.8],[1,1.56,319.31],[2,1.71,539.26]],"ltp":1.4,"tv":5120.3,"id":8326656}]}]}
{"op":"mcm","clk":"1003430044","pt":1580607636443,"mc":[{"id":"1.168179123","rc":[{"batl":[[0,1.71,539.26],[1,1.56,0],[2,1.71,0]],"ltp":1.4,"tv":5120.3,"id":8326656}]}]}
{"op":"mcm","clk":"1003430301","pt":1580607639480,"mc":[{"id":"1.168179123","rc":[{"batl":[[0,1.37,714.65],[1,1.38,527.42],[2,1.71,539.26]],"ltp":1.4,"tv":5120.3,"id":8326656}]}]}
{"op":"mcm","clk":"1003430376","pt":1580607640254,"mc":[{"id":"1.168179123","rc":[{"batb":[[0,3.85,51.3],[1,3.3,37.53],[2,1.01,15.52]],"ltp":3.55,"tv":207.71,"id":9712909}]}]}
{"op":"mcm","clk":"1003430557","pt":1580607642569,"mc":[{"id":"1.168179123","rc":[{"batl":[[0,5.5,115.06]],"ltp":3.55,"tv":207.71,"id":9712909}]}]}
{"op":"mcm","clk":"1003431691","pt":1580607656886,"mc":[{"id":"1.168179123","rc":[{"batb":[[0,1.28,170.19],[1,1.01,15.51],[2,1.31,0]],"batl":[[0,1.71,539.26],[1,1.38,0],[2,1.71,0]],"ltp":1.4,"tv":5120.3,"id":8326656},{"batb":[[0,3.3,37.53],[1,1.01,15.52],[2,1.01,0]],"ltp":3.55,"tv":207.71,"id":9712909}]}]}
{"op":"mcm","clk":"1003431871","pt":1580607659507,"mc":[{"id":"1.168179123","rc":[{"batb":[[0,1.3,598.75],[1,1.29,770.05],[2,1.28,170.19]],"batl":[[0,1.33,18.93],[1,1.45,359.26],[2,1.46,415.24]],"ltp":1.4,"tv":5120.3,"id":8326656}]}]}
{"op":"mcm","clk":"1003431919","pt":1580607660075,"mc":[{"id":"1.168179123","rc":[{"batl":[[1,1.71,539.26],[2,1.46,0]],"ltp":1.4,"tv":5120.3,"id":8326656}]}]}
{"op":"mcm","clk":"1003432102","pt":1580607662806,"mc":[{"id":"1.168179123","rc":[{"batl":[[0,1.71,539.26],[1,1.71,0]],"ltp":1.4,"tv":5120.3,"id":8326656}]}]}
{"op":"mcm","clk":"1003432157","pt":1580607663484,"mc":[{"id":"1.168179123","rc":[{"batl":[[0,1.33,409.7],[1,1.34,611.15],[2,1.71,539.26]],"ltp":1.4,"tv":5120.3,"id":8326656}]}]}
{"op":"mcm","clk":"1003432261","pt":1580607664775,"mc":[{"id":"1.168179123","rc":[{"batb":[[0,4.1,43.12],[1,3.7,28.4],[2,1.01,15.52]],"ltp":3.55,"tv":207.71,"id":9712909}]}]}
{"op":"mcm","clk":"1003433159","pt":1580607675694,"mc":[{"id":"1.168179123","rc":[{"trd":[[1.3,37.86]],"batb":[[0,1.3,579.82]],"ltp":1.3,"tv":5158.16,"id":8326656}],"tv":5365.87}]}
{"op":"mcm","clk":"1003433238","pt":1580607676827,"mc":[{"id":"1.168179123","rc":[{"batb":[[0,1.28,170.19],[1,1.26,185.85],[2,1.01,15.51]],"batl":[[0,1.71,539.26],[1,1.34,0],[2,1.71,0]],"ltp":1.3,"tv":5158.16,"id":8326656}]}]}
{"op":"mcm","clk":"1003433286","pt":1580607677395,"mc":[{"id":"1.168179123","rc":[{"batb":[[0,1.26,185.85],[1,1.01,15.51],[2,1.01,0]],"ltp":1.3,"tv":5158.16,"id":8326656},{"batb":[[0,3.7,28.4],[1,1.01,15.52],[2,1.01,0]],"ltp":3.55,"tv":207.71,"id":9712909}]}]}
{"op":"mcm","clk":"1003433455","pt":1580607679812,"mc":[{"id":"1.168179123","rc":[{"batb":[[0,1.28,791.73],[1,1.27,845.35],[2,1.26,185.85]],"batl":[[0,1.38,521.11],[1,1.39,512.61],[2,1.71,539.26]],"ltp":1.3,"tv":5158.16,"id":8326656}]}]}
{"op":"mcm","clk":"1003433469","pt":1580607680019,"mc":[{"id":"1.168179123","rc":[{"batl":[[0,1.71,539.26],[1,1.39,0],[2,1.71,0]],"ltp":1.3,"tv":5158.16,"id":8326656}]}]}
{"op":"mcm","clk":"1003433680","pt":1580607682805,"mc":[{"id":"1.168179123","rc":[{"batl":[[0,1.31,384.21],[1,1.32,659.65],[2,1.71,539.26]],"ltp":1.3,"tv":5158.16,"id":8326656}]}]}
{"op":"mcm","clk":"1003433726","pt":1580607683525,"mc":[{"id":"1.168179123","rc":[{"batb":[[0,4.3,38],[1,4,46.66],[2,1.01,15.52]],"ltp":3.55,"tv":207.71,"id":9712909}]}]}
{"op":"mcm","clk":"1003434639","pt":1580607695834,"mc":[{"id":"1.168179123","rc":[{"batb":[[0,1.27,845.35],[1,1.26,185.85],[2,1.25,192.69]],"batl":[[0,1.71,539.26],[1,1.32,0],[2,1.71,0]],"ltp":1.3,"tv":5158.16,"id":8326656}]}]}
{"op":"mcm","clk":"1003434704","pt":1580607696504,"mc":[{"id":"1.168179123","rc":[{"batb":[[1,1.25,192.69],[2,1.01,15.51]],"ltp":1.3,"tv":5158.16,"id":8326656},{"batb":[[0,4,46.66],[1,1.01,15.52],[2,1.01,0]],"ltp":3.55,"tv":207.71,"id":9712909}]}]}
{"op":"mcm","clk":"1003434878","pt":1580607698716,"mc":[{"id":"1.168179123","rc":[{"batb":[[0,1.27,992.06],[1,1.26,889.7],[2,1.25,192.69]],"batl":[[0,1.34,837.54],[1,1.35,583.68],[2,1.71,539.26]],"ltp":1.3,"tv":5158.16,"id":8326656}]}]}
{"op":"mcm","clk":"1003434899","pt":1580607698921,"mc":[{"id":"1.168179123","rc":[{"batb":[[0,1.27,851.68],[1,1.25,192.69],[2,1.01,15.51]],"batl":[[0,1.71,539.26],[1,1.35,0],[2,1.71,0]],"ltp":1.3,"tv":5158.16,"id":8326656}]}]}
{"op":"mcm","clk":"1003435113","pt":1580607701810,"mc":[{"id":"1.168179123","rc":[{"batb":[[0,1.28,1107.38],[1,1.27,851.68],[2,1.25,192.69]],"batl":[[0,1.32,756.49],[1,1.33,629.3],[2,1.71,539.26]],"ltp":1.3,"tv":5158.16,"id":8326656}]}]}
{"op":"mcm","clk":"1003435334","pt":1580607705042,"mc":[{"id":"1.168179123","rc":[{"batb":[[0,1.27,851.68],[1,1.25,192.69],[2,1.01,15.51]],"batl":[[0,1.71,539.26],[1,1.33,0],[2,1.71,0]],"ltp":1.3,"tv":5158.16,"id":8326656}]}]}
{"op":"mcm","clk":"1003435541","pt":1580607707918,"mc":[{"id":"1.168179123","rc":[{"batb":[[0,1.27,990.89],[1,1.26,889.71],[2,1.25,192.69]],"batl":[[0,1.34,838.64],[1,1.35,583.69],[2,1.71,539.26]],"ltp":1.3,"tv":5158.16,"id":8326656}]}]}
{"op":"mcm","clk":"1003435846","pt":1580607711627,"mc":[{"id":"1.168179123","rc":[{"batl":[[0,1.71,539.26],[1,1.35,0],[2,1.71,0]],"ltp":1.3,"tv":5158.16,"id":8326656}]}]}
{"op":"mcm","clk":"1003436098","pt":1580607714767,"mc":[{"id":"1.168179123","rc":[{"batl":[[0,1.31,972.01],[1,1.32,650.19]],"ltp":1.3,"tv":5158.16,"id":8326656}]}]}
{"op":"mcm","clk":"1003436165","pt":1580607715644,"mc":[{"id":"1.168179123","rc":[{"batb":[[0,4.4,36.04],[1,3.85,50.91],[2,1.01,15.52]],"ltp":3.55,"tv":207.71,"id":9712909}]}]}
{"op":"mcm","clk":"1003436406","pt":1580607718738,"mc":[{"id":"1.168179123","rc":[{"batl":[[0,1.31,1063.77],[2,1.62,614.4]],"ltp":1.3,"tv":5158.16,"id":8326656},{"batl":[[0,6.6,98.95]],"ltp":3.55,"tv":207.71,"id":9712909}]}]}
{"op":"mcm","clk":"1003436424","pt":1580607718945,"mc":[{"id":"1.168179123","rc":[{"batl":[[0,1.31,972.01]],"ltp":1.3,"tv":5158.16,"id":8326656}]}]}
{"op":"mcm","clk":"1003438740","pt":1580607747513,"mc":[{"id":"1.168179123","rc":[{"batb":[[0,1.18,282.63],[1,1.01,15.51],[2,1.25,0]],"batl":[[0,1.62,614.4],[1,1.32,0],[2,1.62,0]],"ltp":1.3,"tv":5158.16,"id":8326656},{"batb":[[0,3.85,50.91],[1,1.01,15.52],[2,1.01,0]],"ltp":3.55,"tv":207.71,"id":9712909}]}]}
{"op":"mcm","clk":"1003438939","pt":1580607749989,"mc":[{"id":"1.168179123","rc":[{"batb":[[0,1.2,1251.5],[1,1.19,1050.14],[2,1.18,282.63]],"batl":[[0,1.37,662.46],[1,1.38,528.24],[2,1.62,614.4]],"ltp":1.3,"tv":5158.16,"id":8326656}]}]}
{"op":"mcm","clk":"1003440672","pt":1580607772630,"mc":[{"id":"1.168179123","rc":[{"batl":[[0,1.62,614.4],[1,1.38,0],[2,1.62,0]],"ltp":1.3,"tv":5158.16,"id":8326656}]}]}
{"op":"mcm","clk":"1003440931","pt":1580607775734,"mc":[{"id":"1.168179123","rc":[{"batl":[[0,1.23,897.08],[1,1.24,922.85]],"ltp":1.3,"tv":5158.16,"id":8326656}]}]}
{"op":"mcm","clk":"1003441008","pt":1580607776558,"mc":[{"id":"1.168179123","rc":[{"batb":[[0,5.7,40.99],[1,4.6,33.13],[2,1.01,15.52]],"ltp":3.55,"tv":207.71,"id":9712909}]}]}
{"op":"mcm","clk":"1003441158","pt":1580607778615,"mc":[{"id":"1.168179123","rc":[{"batl":[[2,1.55,690.76]],"ltp":1.3,"tv":5158.16,"id":8326656},{"batl":[[0,8.2,85.46]],"ltp":3.55,"tv":207.71,"id":9712909}]}]}
{"op":"mcm","clk":"1003442720","pt":1580607799864,"mc":[{"id":"1.168179123","rc":[{"batb":[[0,1.18,282.63],[1,1.11,474.77],[2,1.01,15.51]],"batl":[[0,1.55,690.76],[1,1.24,0],[2,1.55,0]],"ltp":1.3,"tv":5158.16,"id":8326656}]}]}
{"op":"mcm","clk":"1003442781","pt":1580607800695,"mc":[{"id":"1.168179123","rc":[{"batb":[[0,1.11,474.77],[1,1.01,15.51],[2,1.01,0]],"ltp":1.3,"tv":5158.16,"id":8326656},{"batb":[[0,4.6,33.13],[1,1.01,15.52],[2,1.01,0]],"ltp":3.55,"tv":207.71,"id":9712909}]}]}
{"op":"mcm","clk":"1003442919","pt":1580607802756,"mc":[{"id":"1.168179123","rc":[{"batb":[[0,1.13,1515.84],[1,1.12,927.29],[2,1.11,474.77]],"batl":[[0,1.3,998.65],[1,1.31,675.58],[2,1.55,690.76]],"ltp":1.3,"tv":5158.16,"id":8326656}]}]}
{"op":"mcm","clk":"1003443628","pt":1580607813392,"mc":[{"id":"1.168179123","rc":[{"batl":[[0,1.55,690.76],[1,1.31,0],[2,1.55,0]],"ltp":1.3,"tv":5158.16,"id":8326656}]}]}
{"op":"mcm","clk":"1003443874","pt":1580607816798,"mc":[{"id":"1.168179123","rc":[{"batl":[[0,1.15,884.75],[1,1.16,1477.87]],"ltp":1.3,"tv":5158.16,"id":8326656},{"batb":[[0,8.2,17.7],[1,6.2,33.2],[2,4.6,33.13]],"ltp":3.55,"tv":207.71,"id":9712909}]}]}
{"op":"mcm","clk":"1003443891","pt":1580607817004,"mc":[{"id":"1.168179123","rc":[{"batb":[[2,1.01,15.52]],"ltp":3.55,"tv":207.71,"id":9712909}]}]}
{"op":"mcm","clk":"1003444030","pt":1580607818906,"mc":[{"id":"1.168179123","rc":[{"batl":[[2,1.46,823.53]],"ltp":1.3,"tv":5158.16,"id":8326656},{"batl":[[0,12,67.78]],"ltp":3.55,"tv":207.71,"id":9712909}]}]}
{"op":"mcm","clk":"1003446018","pt":1580607844611,"mc":[{"id":"1.168179123","rc":[{"batb":[[0,1.05,975.73],[1,1.01,15.51],[2,1.11,0]],"batl":[[0,1.46,823.53],[1,1.16,0],[2,1.46,0]],"ltp":1.3,"tv":5158.16,"id":8326656},{"batb":[[0,6.2,33.2],[1,1.01,15.52],[2,1.01,0]],"ltp":3.55,"tv":207.71,"id":9712909}]}]}
{"op":"mcm","clk":"1003446252","pt":1580607847644,"mc":[{"id":"1.168179123","rc":[{"batl":[[0,1.21,1201.57],[1,1.22,1013.88],[2,1.46,823.53]],"ltp":1.3,"tv":5158.16,"id":8326656}]}]}
{"op":"mcm","clk":"1003446527","pt":1580607850845,"mc":[{"id":"1.168179123","rc":[{"batb":[[0,1.18,1313.31],[1,1.17,1027.14],[2,1.05,975.73]],"ltp":1.3,"tv":5158.16,"id":8326656}]}]}
{"op":"mcm","clk":"1003446600","pt":1580607851723,"mc":[{"id":"1.168179123","rc":[{"batb":[[2,1.16,322.75]],"ltp":1.3,"tv":5158.16,"id":8326656},{"batb":[[1,4.8,30.76],[2,1.01,15.52]],"ltp":3.55,"tv":207.71,"id":9712909}]}]}
{"op":"mcm","clk":"1003446751","pt":1580607853736,"mc":[{"id":"1.168179123","rc":[{"batl":[[0,9.4,78.04]],"ltp":3.55,"tv":207.71,"id":9712909}]}]}
{"op":"mcm","clk":"1003447564","pt":1580607864547,"mc":[{"id":"1.168179123","rc":[{"batb":[[0,1.08,661.01],[1,1.01,15.51],[2,1.16,0]],"batl":[[0,1.46,823.53],[1,1.22,0],[2,1.46,0]],"ltp":1.3,"tv":5158.16,"id":8326656},{"batb":[[0,4.8,30.76],[1,1.01,15.52],[2,1.01,0]],"ltp":3.55,"tv":207.71,"id":9712909}]}]}
{"op":"mcm","clk":"1003448022","pt":1580607870643,"mc":[{"id":"1.168179123","rc":[{"batb":[[0,1.16,1819.65],[1,1.15,557.11],[2,1.08,661.01]],"batl":[[0,1.19,1204.66],[1,1.2,1098.27]],"ltp":1.3,"tv":5158.16,"id":8326656}]}]}
{"op":"mcm","clk":"1003448186","pt":1580607872867,"mc":[{"id":"1.168179123","rc":[{"batb":[[0,1.08,661.01],[1,1.01,15.51],[2,1.08,0]],"ltp":1.3,"tv":5158.16,"id":8326656}]}]}
{"op":"mcm","clk":"1003448397","pt":1580607875760,"mc":[{"id":"1.168179123","rc":[{"batb":[[0,1.1,1432.05],[1,1.09,1079.09],[2,1.08,661.01]],"batl":[[0,1.29,993.18],[1,1.3,703.42]],"ltp":1.3,"tv":5158.16,"id":8326656}]}]}
{"op":"mcm","clk":"1003449262","pt":1580607888553,"mc":[{"id":"1.168179123","rc":[{"batl":[[0,1.12,1958.04],[1,1.13,494.21]],"ltp":1.3,"tv":5158.16,"id":8326656}]}]}
{"op":"mcm","clk":"1003449316","pt":1580607889276,"mc":[{"id":"1.168179123","rc":[{"batb":[[0,10,26.12],[1,7.2,23.53],[2,1.01,15.52]],"ltp":3.55,"tv":207.71,"id":9712909}]}]}
{"op":"mcm","clk":"1003449498","pt":1580607891763,"mc":[{"id":"1.168179123","rc":[{"batl":[[2,1.41,902.65]],"ltp":1.3,"tv":5158.16,"id":8326656},{"batl":[[0,15.5,59.64]],"ltp":3.55,"tv":207.71,"id":9712909}]}]}
{"op":"mcm","clk":"1003450480","pt":1580607904201,"mc":[{"id":"1.168179123","rc":[{"trd":[[1.1,15.56]],"batb":[[0,1.1,1416.49]],"ltp":1.1,"tv":5173.72,"id":8326656},{"trd":[[11,1.56]],"ltp":11.0,"tv":209.26,"id":9712909}],"tv":5382.99}]}
{"op":"mcm","clk":"1003450842","pt":1580607908800,"mc":[{"id":"1.168179123","rc":[{"trd":[[1.1,32.36]],"batb":[[0,1.1,1408.09]],"ltp":1.1,"tv":5190.52,"id":8326656}],"tv":5399.79}]}
{"op":"mcm","clk":"1003451033","pt":1580607911328,"mc":[{"id":"1.168179123","rc":[{"batb":[[0,1.02,2000.25],[1,1.01,15.51],[2,1.08,0]],"batl":[[0,1.41,902.65],[1,1.13,0],[2,1.41,0]],"ltp":1.1,"tv":5190.52,"id":8326656},{"batb":[[0,7.2,23.53],[1,1.01,15.52],[2,1.01,0]],"ltp":11.0,"tv":209.26,"id":9712909}]}]}
{"op":"mcm","clk":"1003451237","pt":1580607913803,"mc":[{"id":"1.168179123","rc":[{"batb":[[0,1.04,2645.64],[1,1.02,2000.25],[2,1.01,15.51]],"batl":[[0,1.17,594.23],[1,1.18,1303.85]],"ltp":1.1,"tv":5190.52,"id":8326656}]}]}
{"op":"mcm","clk":"1003451337","pt":1580607915039,"mc":[{"id":"1.168179123","rc":[{"batb":[[0,1.02,2000.25],[1,1.01,15.51],[2,1.01,0]],"ltp":1.1,"tv":5190.52,"id":8326656}]}]}
{"op":"mcm","clk":"1003451577","pt":1580607917824,"mc":[{"id":"1.168179123","rc":[{"batb":[[0,1.09,804.15],[1,1.08,1736.06],[2,1.02,2000.25]],"batl":[[0,1.1,688.11],[1,1.11,1796.88]],"ltp":1.1,"tv":5190.52,"id":8326656}]}]}
{"op":"mcm","clk":"1003451727","pt":1580607919733,"mc":[{"id":"1.168179123","rc":[{"batb":[[0,1.02,2000.25],[1,1.01,15.51],[2,1.02,0]],"batl":[[0,1.4,940.51],[1,1.11,0]],"ltp":1.1,"tv":5190.52,"id":8326656},{"batl":[[0,18,56.21]],"ltp":11.0,"tv":209.26,"id":9712909}]}]}
{"op":"mcm","clk":"1003451912","pt":1580607922107,"mc":[{"id":"1.168179123","rc":[{"batb":[[0,1.04,2645.64],[1,1.02,2000.25],[2,1.01,15.51]],"batl":[[0,1.17,592.62],[1,1.18,1303.85]],"ltp":1.1,"tv":5190.52,"id":8326656}]}]}
{"op":"mcm","clk":"1003452617","pt":1580607931813,"mc":[{"id":"1.168179123","rc":[{"batl":[[0,1.05,1630.15],[1,1.06,981.55]],"ltp":1.1,"tv":5190.52,"id":8326656}]}]}
{"op":"mcm","clk":"1003452669","pt":1580607932538,"mc":[{"id":"1.168179123","rc":[{"batb":[[0,23,6.82],[1,14,13.06],[2,1.01,15.52]],"ltp":11.0,"tv":209.26,"id":9712909}]}]}
{"op":"mcm","clk":"1003452767","pt":1580607933830,"mc":[{"id":"1.168179123","rc":[{"batl":[[2,1.33,1121.38]],"ltp":1.1,"tv":5190.52,"id":8326656},{"batl":[[0,46,42.96]],"ltp":11.0,"tv":209.26,"id":9712909}]}]}
{"op":"mcm","clk":"1003452974","pt":1580607937037,"mc":[{"id":"1.168179123","rc":[{"batl":[[2,1.18,1.54]],"ltp":1.1,"tv":5190.52,"id":8326656}]}]}
{"op":"mcm","clk":"1003453405","pt":1580607943341,"mc":[{"id":"1.168179123","rc":[{"batl":[[2,1.33,1121.38]],"ltp":1.1,"tv":5190.52,"id":8326656}]}]}
{"op":"mcm","clk":"1003453642","pt":1580607946548,"mc":[{"id":"1.168179123","rc":[{"trd":[[1.04,3.08]],"batb":[[0,1.04,2644.1]],"ltp":1.04,"tv":5193.61,"id":8326656}],"tv":5402.87}]}
{"op":"mcm","clk":"1003454341","pt":1580607956673,"mc":[{"id":"1.168179123","rc":[{"batl":[[0,1.05,1552.89]],"ltp":1.04,"tv":5193.61,"id":8326656}]}]}
{"op":"mcm","clk":"1003454537","pt":1580607959577,"mc":[{"id":"1.168179123","rc":[{"batl":[[1,1.06,1058.09]],"ltp":1.04,"tv":5193.61,"id":8326656}]}]}
{"op":"mcm","clk":"1003456789","pt":1580607989489,"mc":[{"id":"1.168179123","rc":[{"trd":[[1.05,7.58]],"batl":[[0,1.05,1549.1]],"ltp":1.05,"tv":5201.18,"id":8326656}],"tv":5410.45}]}
{"op":"mcm","clk":"1003458293","pt":1580608011531,"mc":[{"id":"1.168179123","rc":[{"batb":[[0,1.01,15.51],[1,1.02,0],[2,1.01,0]],"batl":[[0,1.33,1121.38],[1,1.06,0],[2,1.33,0]],"ltp":1.05,"tv":5201.18,"id":8326656},{"batb":[[0,14,13.06],[1,1.01,15.52],[2,1.01,0]],"ltp":11.0,"tv":209.26,"id":9712909}]}]}
{"op":"mcm","clk":"1003458756","pt":1580608017557,"mc":[{"id":"1.168179123","rc":[{"batb":[[0,1.05,580.58],[1,1.04,2060.1],[2,1.01,15.51]],"batl":[[0,1.06,2596.33],[1,1.33,1121.38]],"ltp":1.05,"tv":5201.18,"id":8326656}]}]}
{"op":"mcm","clk":"1003458907","pt":1580608019567,"mc":[{"id":"1.168179123","rc":[{"batl":[[0,34,46.08]],"ltp":11.0,"tv":209.26,"id":9712909}]}]}
{"op":"mcm","clk":"1003459098","pt":1580608021841,"mc":[{"id":"1.168179123","rc":[{"batb":[[0,1.01,15.51],[1,1.04,0],[2,1.01,0]],"batl":[[0,1.33,1121.38],[1,1.33,0]],"ltp":1.05,"tv":5201.18,"id":8326656}]}]}
{"op":"mcm","clk":"1003459321","pt":1580608024740,"mc":[{"id":"1.168179123","rc":[{"batb":[[0,1.03,2212.25],[1,1.02,464.2],[2,1.01,15.51]],"batl":[[0,1.09,2524.87],[1,1.33,1121.38]],"ltp":1.05,"tv":5201.18,"id":8326656}]}]}
{"op":"mcm","clk":"1003460483","pt":1580608040559,"mc":[{"id":"1.168179123","rc":[{"batl":[[0,1.33,1121.38],[1,1.33,0]],"ltp":1.05,"tv":5201.18,"id":8326656}]}]}
{"op":"mcm","clk":"1003460712","pt":1580608043499,"mc":[{"id":"1.168179123","rc":[{"batl":[[0,1.04,2646.26],[1,1.33,1121.38]],"ltp":1.05,"tv":5201.18,"id":8326656}]}]}
{"op":"mcm","clk":"1003460795","pt":1580608044475,"mc":[{"id":"1.168179123","rc":[{"batb":[[0,19,12.35]],"ltp":11.0,"tv":209.26,"id":9712909}]}]}
{"op":"mcm","clk":"1003460953","pt":1580608046498,"mc":[{"id":"1.168179123","rc":[{"batl":[[0,85,39.13]],"ltp":11.0,"tv":209.26,"id":9712909}]}]}
{"op":"mcm","clk":"1003461317","pt":1580608051970,"mc":[{"id":"1.168179123","rc":[{"batb":[[0,1.03,2114.95]],"ltp":1.05,"tv":5201.18,"id":8326656}]}]}
{"op":"mcm","clk":"1003461517","pt":1580608055311,"mc":[{"id":"1.168179123","rc":[{"batb":[[1,1.02,562.45]],"ltp":1.05,"tv":5201.18,"id":8326656},{"batb":[[1,17.5,169.36],[2,1.01,15.52]],"ltp":11.0,"tv":209.26,"id":9712909}]}]}
{"op":"mcm","clk":"1003461697","pt":1580608057888,"mc":[{"id":"1.168179123","rc":[{"batb":[[0,1.02,562.45],[1,1.01,15.51],[2,1.01,0]],"batl":[[0,1.33,1121.38],[1,1.33,0]],"ltp":1.05,"tv":5201.18,"id":8326656}]}]}
{"op":"mcm","clk":"1003461711","pt":1580608058093,"mc":[{"id":"1.168179123","rc":[{"batb":[[1,1.01,15.52],[2,1.01,0]],"ltp":11.0,"tv":209.26,"id":9712909}]}]}
{"op":"mcm","clk":"1003461903","pt":1580608060819,"mc":[{"id":"1.168179123","rc":[{"batb":[[0,1.02,2698.15]],"batl":[[0,1.06,1998.95],[1,1.07,591.79],[2,1.33,1121.38]],"ltp":1.05,"tv":5201.18,"id":8326656}]}]}
{"op":"mcm","clk":"1003462231","pt":1580608065805,"mc":[{"id":"1.168179123","rc":[{"batl":[[0,1.33,1121.38],[1,1.07,0],[2,1.33,0]],"ltp":1.05,"tv":5201.18,"id":8326656}]}]}
{"op":"mcm","clk":"1003462442","pt":1580608068802,"mc":[{"id":"1.168179123","rc":[{"batl":[[0,1.03,2671.95],[1,1.33,1121.38]],"ltp":1.05,"tv":5201.18,"id":8326656}]}]}
{"op":"mcm","clk":"1003462517","pt":1580608069728,"mc":[{"id":"1.168179123","rc":[{"batb":[[0,30,5.47],[1,27,7.11],[2,1.01,15.52]],"ltp":11.0,"tv":209.26,"id":9712909}]}]}
{"op":"mcm","clk":"1003462686","pt":1580608071735,"mc":[{"id":"1.168179123","rc":[{"batl":[[0,170,36.98]],"ltp":11.0,"tv":209.26,"id":9712909}]}]}
{"op":"mcm","clk":"1003463995","pt":1580608088320,"mc":[{"id":"1.168179123","rc":[{"batb":[[0,1.01,15.51],[1,1.01,0]],"batl":[[0,1.33,1121.38],[1,1.33,0]],"ltp":1.05,"tv":5201.18,"id":8326656},{"batb":[[0,27,7.11],[1,1.01,15.52],[2,1.01,0]],"ltp":11.0,"tv":209.26,"id":9712909}]}]}
{"op":"mcm","clk":"1003464429","pt":1580608094533,"mc":[{"id":"1.168179123","rc":[{"batb":[[0,1.02,2698.15],[1,1.01,15.51]],"batl":[[0,1.03,2282.54],[1,1.33,1121.38]],"ltp":1.05,"tv":5201.18,"id":8326656}]}]}
{"op":"mcm","clk":"1003464720","pt":1580608098618,"mc":[{"id":"1.168179123","rc":[{"batb":[[0,1.01,15.51],[1,1.01,0]],"batl":[[0,1.33,1121.38],[1,1.33,0]],"ltp":1.05,"tv":5201.18,"id":8326656}]}]}
{"op":"mcm","clk":"1003464945","pt":1580608101645,"mc":[{"id":"1.168179123","rc":[{"batb":[[0,1.01,2740.37]],"batl":[[0,1.04,2248.82],[1,1.05,393.64],[2,1.33,1121.38]],"ltp":1.05,"tv":5201.18,"id":8326656}]}]}
{"op":"mcm","clk":"1003465564","pt":1580608110558,"mc":[{"id":"1.168179123","rc":[{"batl":[[0,1.33,1121.38],[1,1.05,0],[2,1.33,0]],"ltp":1.05,"tv":5201.18,"id":8326656}]}]}
{"op":"mcm","clk":"1003465759","pt":1580608113645,"mc":[{"id":"1.168179123","rc":[{"batl":[[0,1.03,2671.95],[1,1.33,1121.38]],"ltp":1.05,"tv":5201.18,"id":8326656}]}]}
{"op":"mcm","clk":"1003465814","pt":1580608114674,"mc":[{"id":"1.168179123","rc":[{"batb":[[0,30,6.33]],"ltp":11.0,"tv":209.26,"id":9712909}]}]}
{"op":"mcm","clk":"1003465974","pt":1580608117247,"mc":[{"id":"1.168179123","rc":[{"batl":[[0,340,35.88]],"ltp":11.0,"tv":209.26,"id":9712909}]}]}
{"op":"mcm","clk":"1003466666","pt":1580608127966,"mc":[{"id":"1.168179123","rc":[{"trd":[[1.01,3.36]],"batb":[[0,1.01,2738.69]],"ltp":1.01,"tv":5204.54,"id":8326656}],"tv":5413.81}]}
{"op":"mcm","clk":"1003467053","pt":1580608133576,"mc":[{"id":"1.168179123","rc":[{"batl":[[0,1.03,1340.86]],"ltp":1.01,"tv":5204.54,"id":8326656},{"batb":[[0,1.01,15.52],[1,1.01,0]],"ltp":11.0,"tv":209.26,"id":9712909}]}]}
{"op":"mcm","clk":"1003467227","pt":1580608136093,"mc":[{"id":"1.168179123","rc":[{"batl":[[0,1.02,1343.94],[1,1.03,1340.86],[2,1.33,1121.38]],"ltp":1.01,"tv":5204.54,"id":8326656}]}]}
{"op":"mcm","clk":"1003469763","pt":1580608170237,"mc":[{"id":"1.168179123","rc":[{"batl":[[0,1.03,1340.86],[1,1.33,1121.38],[2,1.33,0]],"ltp":1.01,"tv":5204.54,"id":8326656}]}]}
{"op":"mcm","clk":"1003470051","pt":1580608173616,"mc":[{"id":"1.168179123","rc":[{"batl":[[0,1.03,2671.75]],"ltp":1.01,"tv":5204.54,"id":8326656}]}]}
{"op":"mcm","clk":"1003470619","pt":1580608181325,"mc":[{"id":"1.168179123","rc":[{"batl":[[0,1.33,1121.38],[1,1.33,0]],"ltp":1.01,"tv":5204.54,"id":8326656}]}]}
{"op":"mcm","clk":"1003470829","pt":1580608184230,"mc":[{"id":"1.168179123","rc":[{"batl":[[0,1.02,2697.95],[1,1.33,1121.38]],"ltp":1.01,"tv":5204.54,"id":8326656}]}]}
{"op":"mcm","clk":"1003472046","pt":1580608200782,"mc":[{"id":"1.168179123","rc":[{"batb":[[0,1.01,13.83]],"batl":[[0,1.02,1999.45]],"ltp":1.01,"tv":5204.54,"id":8326656}]}]}
{"op":"mcm","clk":"1003472252","pt":1580608203578,"mc":[{"id":"1.168179123","rc":[{"batl":[[1,1.03,691.71]],"ltp":1.01,"tv":5204.54,"id":8326656}]}]}
{"op":"mcm","clk":"1003472806","pt":1580608211385,"mc":[{"id":"1.168179123","rc":[{"trd":[[1.01,31.02]],"batl":[[0,1.01,2710.83],[1,1.03,0]],"ltp":1.01,"tv":5232.2,"id":8326656}],"tv":5441.47}]}
{"op":"mcm","clk":"1003472943","pt":1580608213085,"mc":[{"id":"1.168179123","rc":[{"batl":[[1,1.28,1347.87]],"ltp":1.01,"tv":5232.2,"id":8326656}]}]}
{"op":"mcm","clk":"1003474530","pt":1580608233221,"mc":[{"id":"1.168179123","rc":[{"batl":[[0,1.28,1347.87],[1,1.28,0]],"ltp":1.01,"tv":5232.2,"id":8326656}]}]}
{"op":"mcm","clk":"1003474740","pt":1580608235907,"mc":[{"id":"1.168179123","rc":[{"batl":[[0,1.02,2697.95]],"ltp":1.01,"tv":5232.2,"id":8326656}]}]}
{"op":"mcm","clk":"1003475483","pt":1580608246624,"mc":[{"id":"1.168179123","rc":[{"batl":[[0,1.01,2724.66]],"ltp":1.01,"tv":5232.2,"id":8326656}]}]}
{"op":"mcm","clk":"1003475635","pt":1580608249353,"mc":[{"id":"1.168179123","rc":[{"batl":[[1,1.27,1393.68]],"ltp":1.01,"tv":5232.2,"id":8326656}]}]}
{"op":"mcm","clk":"1003476672","pt":1580608265769,"mc":[{"id":"1.168179123","rc":[{"batl":[[1,1.27,0]],"ltp":1.01,"tv":5232.2,"id":8326656}]}]}
{"op":"mcm","clk":"1003477287","pt":1580608275882,"mc":[{"id":"1.168179123","marketDefinition":{"bspMarket":false,"turnInPlayEnabled":true,"persistenceEnabled":true,"marketBaseRate":5.0,"eventId":"29680182","eventTypeId":"2","numberOfWinners":1,"bettingType":"ODDS","marketType":"SET_WINNER","marketTime":"2020-02-02T00:32:00.000Z","suspendTime":"2020-02-02T00:32:00.000Z","bspReconciled":false,"complete":true,"inPlay":true,"crossMatching":true,"runnersVoidable":false,"numberOfActiveRunners":2,"betDelay":3,"status":"SUSPENDED","runners":[{"status":"ACTIVE","sortPriority":1,"id":9712909,"name":"Felipe Meligeni Rodrigu"},{"status":"ACTIVE","sortPriority":2,"id":8326656,"name":"Thiago Monteiro"}],"regulators":["MR_INT"],"countryCode":"UY","discountAllowed":true,"timezone":"UTC","openDate":"2020-02-02T00:32:00.000Z","version":3148025549,"name":"Set 2 Winner","eventName":"Meligeni Rodrigues Alve v T Monteiro"}}]}
{"op":"mcm","clk":"1003479296","pt":1580608306599,"mc":[{"id":"1.168179123","tv":0.0}]}
{"op":"mcm","clk":"1003479378","pt":1580608308052,"mc":[{"id":"1.168179123","marketDefinition":{"bspMarket":false,"turnInPlayEnabled":true,"persistenceEnabled":true,"marketBaseRate":5.0,"eventId":"29680182","eventTypeId":"2","numberOfWinners":1,"bettingType":"ODDS","marketType":"SET_WINNER","marketTime":"2020-02-02T00:32:00.000Z","suspendTime":"2020-02-02T00:32:00.000Z","bspReconciled":false,"complete":true,"inPlay":true,"crossMatching":false,"runnersVoidable":false,"numberOfActiveRunners":0,"betDelay":3,"status":"CLOSED","settledTime":"2020-02-02T01:51:45.000Z","runners":[{"status":"LOSER","sortPriority":1,"id":9712909,"name":"Felipe Meligeni Rodrigu"},{"status":"WINNER","sortPriority":2,"id":8326656,"name":"Thiago Monteiro"}],"regulators":["MR_INT"],"countryCode":"UY","discountAllowed":true,"timezone":"UTC","openDate":"2020-02-02T00:32:00.000Z","version":3148026025,"name":"Set 2 Winner","eventName":"Meligeni Rodrigues Alve v T Monteiro"}}]}
