{"op":"mcm","clk":"1012056248","pt":1580659270815,"mc":[{"id":"1.168223929","rc":[{"batb":[[0,1.33,135.43],[1,1.01,15.51],[2,1.01,0]],"ltp":1.99,"tv":1630.72,"id":8444055},{"batb":[[0,1.48,81.67],[1,1.01,15.51],[2,1.01,0]],"ltp":2.0,"tv":4130.59,"id":8257852}]}]}
{"op":"mcm","clk":"1012056464","pt":1580659272215,"mc":[{"id":"1.168223929","rc":[{"batb":[[0,1.35,968.09],[1,1.34,691.03],[2,1.33,135.41]],"batl":[[0,3.1,175.22],[1,3.15,239.52]],"ltp":1.99,"tv":1630.72,"id":8444055}]}]}
{"op":"mcm","clk":"1012058258","pt":1580659284232,"mc":[{"id":"1.168223929","rc":[{"trd":[[1.49,68.21]],"batb":[[0,1.35,968.07]],"batl":[[0,1.39,349.84],[1,1.4,542.33]],"ltp":1.49,"tv":1630.75,"id":8444055}],"tv":5761.35}]}
{"op":"mcm","clk":"1012058400","pt":1580659285237,"mc":[{"id":"1.168223929","rc":[{"batb":[[0,3.65,29.35],[1,1.83,38.32],[2,1.48,81.67]],"ltp":2.0,"tv":4130.59,"id":8257852}]}]}
{"op":"mcm","clk":"1012058518","pt":1580659286039,"mc":[{"id":"1.168223929","rc":[{"batb":[[2,1.01,15.51]],"ltp":2.0,"tv":4130.59,"id":8257852}]}]}
{"op":"mcm","clk":"1012058691","pt":1580659287238,"mc":[{"id":"1.168223929","rc":[{"batb":[[1,2.38,381.97],[2,1.83,38.32]],"batl":[[0,4.1,13.44]],"ltp":2.0,"tv":4130.59,"id":8257852}]}]}
{"op":"mcm","clk":"1012058761","pt":1580659287762,"mc":[{"id":"1.168223929","rc":[{"batl":[[1,1.4,584.34]],"ltp":1.49,"tv":1630.75,"id":8444055},{"batb":[[1,3.5,16.8],[2,2.38,381.97]],"ltp":2.0,"tv":4130.59,"id":8257852}]}]}
{"op":"mcm","clk":"1012059736","pt":1580659294141,"mc":[{"id":"1.168223929","rc":[{"trd":[[3.65,22.72]],"batb":[[0,3.65,17.99]],"ltp":3.65,"tv":4153.31,"id":8257852}],"tv":5784.07}]}
{"op":"mcm","clk":"1012060321","pt":1580659298266,"mc":[{"id":"1.168223929","rc":[{"batb":[[0,1.35,657.31],[1,1.33,135.41],[2,1.32,131.07]],"batl":[[0,1.4,584.34],[1,1.4,0]],"ltp":1.49,"tv":1630.75,"id":8444055}]}]}
{"op":"mcm","clk":"1012060784","pt":1580659301230,"mc":[{"id":"1.168223929","rc":[{"batb":[[0,1.36,511.97],[1,1.35,657.31],[2,1.33,135.41]],"batl":[[0,1.4,734.54],[1,1.41,519.52]],"ltp":1.49,"tv":1630.75,"id":8444055}]}]}
{"op":"mcm","clk":"1012062400","pt":1580659311173,"mc":[{"id":"1.168223929","rc":[{"batb":[[0,1.33,135.41],[1,1.32,131.07],[2,1.23,517.12]],"batl":[[0,1.4,42.01],[1,1.41,0]],"ltp":1.49,"tv":1630.75,"id":8444055},{"trd":[[3.65,56.33]],"batb":[[0,3.65,1.18]],"ltp":3.65,"tv":4186.92,"id":8257852}],"tv":5817.67}]}
{"op":"mcm","clk":"1012062542","pt":1580659312155,"mc":[{"id":"1.168223929","rc":[{"batb":[[0,1.23,517.12],[1,1.12,416.86],[2,1.01,15.51]],"ltp":1.49,"tv":1630.75,"id":8444055},{"batb":[[0,2.38,381.97],[1,1.83,38.32],[2,1.01,15.51]],"ltp":3.65,"tv":4186.92,"id":8257852}]}]}
{"op":"mcm","clk":"1012062650","pt":1580659312957,"mc":[{"id":"1.168223929","rc":[{"batb":[[0,1.12,416.86],[1,1.01,15.51],[2,1.01,0]],"batl":[[0,1.35,21.84]],"ltp":1.49,"tv":1630.75,"id":8444055},{"batb":[[0,1.83,38.32],[1,1.01,15.51],[2,1.01,0]],"ltp":3.65,"tv":4186.92,"id":8257852}]}]}
{"op":"mcm","clk":"1012062841","pt":1580659314186,"mc":[{"id":"1.168223929","rc":[{"batb":[[0,1.14,422.75],[1,1.13,2107.49],[2,1.12,416.86]],"batl":[[1,2.22,290.5],[2,2.24,227.31]],"ltp":1.49,"tv":1630.75,"id":8444055}]}]}
{"op":"mcm","clk":"1012063012","pt":1580659315181,"mc":[{"id":"1.168223929","rc":[{"batb":[[0,1.12,416.86],[1,1.01,15.51],[2,1.12,0]],"batl":[[1,2.22,0],[2,2.24,0]],"ltp":1.49,"tv":1630.75,"id":8444055}]}]}
{"op":"mcm","clk":"1012063289","pt":1580659316971,"mc":[{"id":"1.168223929","rc":[{"trd":[[1.35,43.68]],"batb":[[0,1.46,676.93],[1,1.45,477.53],[2,1.12,416.86]],"batl":[[0,1.51,400.75],[1,1.52,385.18]],"ltp":1.35,"tv":1674.43,"id":8444055}],"tv":5861.35}]}
{"op":"mcm","clk":"1012063485","pt":1580659318272,"mc":[{"id":"1.168223929","rc":[{"batl":[[0,3.45,18.93]],"ltp":3.65,"tv":4186.92,"id":8257852}]}]}
{"op":"mcm","clk":"1012063596","pt":1580659319068,"mc":[{"id":"1.168223929","rc":[{"batb":[[2,1.31,478.11]],"ltp":1.35,"tv":1674.43,"id":8444055},{"batb":[[0,2.12,388.28],[1,1.83,38.32],[2,1.01,15.51]],"ltp":3.65,"tv":4186.92,"id":8257852}]}]}
{"op":"mcm","clk":"1012064108","pt":1580659322182,"mc":[{"id":"1.168223929","rc":[{"batb":[[0,1.31,478.11],[1,1.12,416.86],[2,1.01,15.51]],"ltp":1.35,"tv":1674.43,"id":8444055}]}]}
{"op":"mcm","clk":"1012064267","pt":1580659323168,"mc":[{"id":"1.168223929","rc":[{"batb":[[0,1.12,416.86],[1,1.01,15.51],[2,1.01,0]],"ltp":1.35,"tv":1674.43,"id":8444055},{"batb":[[0,1.83,38.32],[1,1.01,15.51],[2,1.01,0]],"ltp":3.65,"tv":4186.92,"id":8257852}]}]}
{"op":"mcm","clk":"1012064408","pt":1580659324083,"mc":[{"id":"1.168223929","rc":[{"batb":[[0,1.01,15.51],[1,1.01,0]],"ltp":3.65,"tv":4186.92,"id":8257852}]}]}
{"op":"mcm","clk":"1012064718","pt":1580659325985,"mc":[{"id":"1.168223929","rc":[{"batb":[[0,1.82,356.45],[1,1.8,429.84],[2,1.01,15.51]],"batl":[[0,1.9,369.56],[1,1.92,355.79]],"ltp":3.65,"tv":4186.92,"id":8257852}]}]}
{"op":"mcm","clk":"1012064924","pt":1580659327252,"mc":[{"id":"1.168223929","rc":[{"batb":[[0,2.12,51.93],[1,1.67,410.23],[2,1.56,70.58]],"ltp":1.35,"tv":1674.43,"id":8444055},{"batb":[[0,1.82,395.55],[2,1.58,415.96]],"ltp":3.65,"tv":4186.92,"id":8257852}]}]}
{"op":"mcm","clk":"1012065237","pt":1580659329072,"mc":[{"id":"1.168223929","rc":[{"batb":[[1,2.02,41.17],[2,1.67,410.23]],"ltp":1.35,"tv":1674.43,"id":8444055},{"batl":[[2,1.99,42.01]],"ltp":3.65,"tv":4186.92,"id":8257852}]}]}
{"op":"mcm","clk":"1012065399","pt":1580659330196,"mc":[{"id":"1.168223929","rc":[{"batl":[[0,2.24,33.61]],"ltp":1.35,"tv":1674.43,"id":8444055},{"batb":[[0,1.82,445.97]],"ltp":3.65,"tv":4186.92,"id":8257852}]}]}
{"op":"mcm","clk":"1012066677","pt":1580659338206,"mc":[{"id":"1.168223929","rc":[{"trd":[[2.12,53.84]],"batb":[[0,2.12,47.73]],"ltp":2.12,"tv":1682.83,"id":8444055}],"tv":5869.75}]}
{"op":"mcm","clk":"1012067442","pt":1580659343204,"mc":[{"id":"1.168223929","rc":[{"trd":[[2.1,2.75],[2.12,149.29]],"batb":[[0,2.02,41.17],[1,1.67,410.23],[2,1.56,70.58]],"ltp":2.1,"tv":1781.04,"id":8444055},{"trd":[[1.9,29.56]],"batl":[[0,1.9,353.26]],"ltp":1.9,"tv":4216.48,"id":8257852}],"tv":5997.52}]}
{"op":"mcm","clk":"1012068150","pt":1580659348196,"mc":[{"id":"1.168223929","rc":[{"trd":[[1.82,614.88]],"batb":[[0,1.82,443.97]],"ltp":1.82,"tv":4220.48,"id":8257852}],"tv":6001.52}]}
{"op":"mcm","clk":"1012068284","pt":1580659349106,"mc":[{"id":"1.168223929","rc":[{"batb":[[0,1.82,50.41],[1,1.58,415.96],[2,1.15,318.58]],"batl":[[0,1.99,42.01],[1,1.92,0],[2,1.99,0]],"ltp":1.82,"tv":4220.48,"id":8257852}]}]}
{"op":"mcm","clk":"1012068445","pt":1580659350226,"mc":[{"id":"1.168223929","rc":[{"batb":[[0,1.67,410.23],[1,1.56,70.58],[2,1.01,15.51]],"ltp":2.1,"tv":1781.04,"id":8444055},{"batb":[[0,1.58,415.96],[1,1.15,318.58],[2,1.01,15.51]],"ltp":1.82,"tv":4220.48,"id":8257852}]}]}
{"op":"mcm","clk":"1012068586","pt":1580659351209,"mc":[{"id":"1.168223929","rc":[{"batb":[[0,1.56,70.58],[1,1.01,15.51],[2,1.01,0]],"ltp":2.1,"tv":1781.04,"id":8444055},{"batb":[[0,1.15,318.58],[1,1.01,15.51],[2,1.01,0]],"ltp":1.82,"tv":4220.48,"id":8257852}]}]}
{"op":"mcm","clk":"1012068738","pt":1580659352216,"mc":[{"id":"1.168223929","rc":[{"batb":[[1,1.55,72.78],[2,1.01,15.51]],"ltp":2.1,"tv":1781.04,"id":8444055},{"batb":[[0,1.17,778.34],[1,1.16,2076.81],[2,1.15,318.58]],"batl":[[0,2.86,216.92],[1,2.9,229.71]],"ltp":1.82,"tv":4220.48,"id":8257852}]}]}
{"op":"mcm","clk":"1012068893","pt":1580659353236,"mc":[{"id":"1.168223929","rc":[{"batb":[[0,1.55,72.78],[1,1.01,15.51],[2,1.01,0]],"ltp":2.1,"tv":1781.04,"id":8444055},{"batb":[[2,1.01,15.51]],"ltp":1.82,"tv":4220.48,"id":8257852}]}]}
{"op":"mcm","clk":"1012070821","pt":1580659365119,"mc":[{"id":"1.168223929","rc":[{"batl":[[0,1.19,903.8],[1,1.2,1286.32]],"ltp":1.82,"tv":4220.48,"id":8257852}]}]}
{"op":"mcm","clk":"1012071014","pt":1580659366243,"mc":[{"id":"1.168223929","rc":[{"batb":[[0,6.2,35.25],[1,2.1,53.19],[2,1.01,15.51]],"ltp":2.1,"tv":1781.04,"id":8444055}]}]}
{"op":"mcm","clk":"1012071171","pt":1580659367211,"mc":[{"id":"1.168223929","rc":[{"batb":[[1,2.98,374.54],[2,2.1,53.19]],"batl":[[0,7.2,6.72]],"ltp":2.1,"tv":1781.04,"id":8444055},{"batb":[[1,1.16,2244.85],[2,1.12,649.61]],"batl":[[1,1.2,1328.33]],"ltp":1.82,"tv":4220.48,"id":8257852}]}]}
{"op":"mcm","clk":"1012071318","pt":1580659368234,"mc":[{"id":"1.168223929","rc":[{"batb":[[1,6,8.4],[2,2.98,374.54]],"ltp":2.1,"tv":1781.04,"id":8444055}]}]}
{"op":"mcm","clk":"1012071422","pt":1580659369023,"mc":[{"id":"1.168223929","rc":[{"batb":[[1,1.16,2076.81]],"ltp":1.82,"tv":4220.48,"id":8257852}]}]}
{"op":"mcm","clk":"1012071765","pt":1580659371221,"mc":[{"id":"1.168223929","rc":[{"trd":[[1.17,42.22]],"batb":[[0,1.17,757.23]],"ltp":1.17,"tv":4262.7,"id":8257852}],"tv":6043.74}]}
{"op":"mcm","clk":"1012071912","pt":1580659372131,"mc":[{"id":"1.168223929","rc":[{"batb":[[1,1.16,2244.85]],"ltp":1.17,"tv":4262.7,"id":8257852}]}]}
{"op":"mcm","clk":"1012072373","pt":1580659375230,"mc":[{"id":"1.168223929","rc":[{"trd":[[1.19,100]],"batl":[[0,1.19,853.8]],"ltp":1.19,"tv":4362.7,"id":8257852}],"tv":6143.74}]}
{"op":"mcm","clk":"1012072679","pt":1580659377142,"mc":[{"id":"1.168223929","rc":[{"trd":[[6.2,16.8]],"batb":[[0,6.2,26.85]],"ltp":6.2,"tv":1797.84,"id":8444055}],"tv":6160.55}]}
{"op":"mcm","clk":"1012072871","pt":1580659378252,"mc":[{"id":"1.168223929","rc":[{"trd":[[7,0.13]],"ltp":7.0,"tv":1797.97,"id":8444055},{"trd":[[1.17,57.53]],"batb":[[0,1.17,749.19]],"ltp":1.17,"tv":4378.01,"id":8257852}],"tv":6175.98}]}
{"op":"mcm","clk":"1012074650","pt":1580659388042,"mc":[{"id":"1.168223929","rc":[{"batb":[[0,1.16,479.07],[1,1.12,649.61],[2,1.01,15.51]],"batl":[[0,1.2,42.01],[1,1.2,0]],"ltp":1.17,"tv":4378.01,"id":8257852}]}]}
{"op":"mcm","clk":"1012074857","pt":1580659389152,"mc":[{"id":"1.168223929","rc":[{"batb":[[0,6,8.4],[1,2.98,374.54],[2,2.1,52.87]],"ltp":7.0,"tv":1797.97,"id":8444055},{"batb":[[0,1.16,168.04]],"ltp":1.17,"tv":4378.01,"id":8257852}]}]}
{"op":"mcm","clk":"1012075001","pt":1580659390047,"mc":[{"id":"1.168223929","rc":[{"batb":[[0,2.1,52.87],[1,1.01,15.51],[2,2.1,0]],"ltp":7.0,"tv":1797.97,"id":8444055},{"batb":[[0,1.01,15.51],[1,1.12,0],[2,1.01,0]],"ltp":1.17,"tv":4378.01,"id":8257852}]}]}
{"op":"mcm","clk":"1012075148","pt":1580659391167,"mc":[{"id":"1.168223929","rc":[{"batl":[[0,1.9,326.48],[1,1.92,355.78]],"ltp":1.17,"tv":4378.01,"id":8257852}]}]}
{"op":"mcm","clk":"1012075977","pt":1580659396271,"mc":[{"id":"1.168223929","rc":[{"batb":[[0,1.82,401.52],[1,1.8,429.86],[2,1.01,15.51]],"ltp":1.17,"tv":4378.01,"id":8257852}]}]}
{"op":"mcm","clk":"1012076111","pt":1580659397188,"mc":[{"id":"1.168223929","rc":[{"batb":[[1,2.04,40.33],[2,1.22,221.57]],"batl":[[0,2.26,32.77]],"ltp":7.0,"tv":1797.97,"id":8444055},{"batb":[[0,1.83,38.48],[1,1.82,401.52],[2,1.8,429.86]],"ltp":1.17,"tv":4378.01,"id":8257852}]}]}
{"op":"mcm","clk":"1012076247","pt":1580659398067,"mc":[{"id":"1.168223929","rc":[{"batb":[[2,1.67,410.23]],"ltp":7.0,"tv":1797.97,"id":8444055}]}]}
{"op":"mcm","clk":"1012076541","pt":1580659401255,"mc":[{"id":"1.168223929","rc":[{"batl":[[2,1.96,42.01]],"ltp":1.17,"tv":4378.01,"id":8257852}]}]}
{"op":"mcm","clk":"1012077488","pt":1580659406197,"mc":[{"id":"1.168223929","rc":[{"trd":[[1.83,274.15]],"batb":[[0,1.83,18.16]],"ltp":1.83,"tv":4418.01,"id":8257852}],"tv":6215.99}]}
{"op":"mcm","clk":"1012078563","pt":1580659413193,"mc":[{"id":"1.168223929","rc":[{"batb":[[0,1.83,38.54]],"ltp":1.83,"tv":4418.01,"id":8257852}]}]}
{"op":"mcm","clk":"1012078737","pt":1580659414178,"mc":[{"id":"1.168223929","rc":[{"trd":[[1.83,304.44]],"batb":[[0,1.83,23.39]],"ltp":1.83,"tv":4448.3,"id":8257852}],"tv":6246.28}]}
{"op":"mcm","clk":"1012079951","pt":1580659421209,"mc":[{"id":"1.168223929","rc":[{"trd":[[1.83,321.1]],"batb":[[0,1.83,15.06]],"ltp":1.83,"tv":4464.96,"id":8257852}],"tv":6262.93}]}
{"op":"mcm","clk":"1012081927","pt":1580659434090,"mc":[{"id":"1.168223929","rc":[{"trd":[[1.83,325.1]],"batb":[[0,1.83,13.06],[1,1.79,52.93],[2,1.58,415.96]],"batl":[[0,1.96,42.01],[1,1.92,0],[2,1.96,0]],"ltp":1.83,"tv":4468.96,"id":8257852}],"tv":6266.93}]}
{"op":"mcm","clk":"1012082052","pt":1580659435050,"mc":[{"id":"1.168223929","rc":[{"trd":[[2.22,145.1]],"ltp":2.22,"tv":1807.97,"id":8444055},{"trd":[[1.83,337.23]],"batb":[[0,1.79,53.86],[1,1.58,415.96],[2,1.4,103.7]],"ltp":1.83,"tv":4481.09,"id":8257852}],"tv":6289.07}]}
{"op":"mcm","clk":"1012082253","pt":1580659436453,"mc":[{"id":"1.168223929","rc":[{"batl":[[1,5.3,180.79],[2,5.4,135.18]],"ltp":1.83,"tv":4481.09,"id":8257852}]}]}
{"op":"mcm","clk":"1012083915","pt":1580659446144,"mc":[{"id":"1.168223929","rc":[{"batb":[[0,1.67,410.23],[1,1.22,221.17],[2,1.01,15.51]],"ltp":2.22,"tv":1807.97,"id":8444055},{"batb":[[0,1.58,415.96],[1,1.4,103.7],[2,1.39,680.95]],"batl":[[0,5.3,180.79],[1,5.4,135.18],[2,5.4,0]],"ltp":1.83,"tv":4481.09,"id":8257852}]}]}
{"op":"mcm","clk":"1012084129","pt":1580659447254,"mc":[{"id":"1.168223929","rc":[{"batb":[[0,1.22,221.17],[1,1.01,15.51],[2,1.01,0]],"ltp":2.22,"tv":1807.97,"id":8444055},{"batb":[[0,1.4,103.7],[1,1.39,680.95],[2,1.38,611.03]],"ltp":1.83,"tv":4481.09,"id":8257852}]}]}
{"op":"mcm","clk":"1012084455","pt":1580659449061,"mc":[{"id":"1.168223929","rc":[{"batb":[[0,1.22,218.26]],"ltp":2.22,"tv":1807.97,"id":8444055},{"batb":[[0,1.39,786.93],[1,1.38,611.03],[2,1.01,15.51]],"ltp":1.83,"tv":4481.09,"id":8257852}]}]}
{"op":"mcm","clk":"1012085468","pt":1580659455175,"mc":[{"id":"1.168223929","rc":[{"batb":[[0,1.39,105.98],[1,1.01,15.51],[2,1.01,0]],"ltp":1.83,"tv":4481.09,"id":8257852}]}]}
{"op":"mcm","clk":"1012085968","pt":1580659457965,"mc":[{"id":"1.168223929","rc":[{"batb":[[0,1.23,1063.5],[1,1.22,1391.59],[2,1.01,15.51]],"batl":[[0,1.26,704.96],[1,1.27,865.7]],"ltp":2.22,"tv":1807.97,"id":8444055}]}]}
{"op":"mcm","clk":"1012086196","pt":1580659459251,"mc":[{"id":"1.168223929","rc":[{"batl":[[0,1.26,746.97]],"ltp":2.22,"tv":1807.97,"id":8444055},{"batb":[[0,4.8,40.82],[1,1.83,38.71],[2,1.01,15.51]],"batl":[[0,5.8,8.4]],"ltp":1.83,"tv":4481.09,"id":8257852}]}]}
{"op":"mcm","clk":"1012086338","pt":1580659460169,"mc":[{"id":"1.168223929","rc":[{"batb":[[2,1.16,576.81]],"ltp":2.22,"tv":1807.97,"id":8444055},{"batb":[[1,2.72,377.96],[2,1.83,38.71]],"ltp":1.83,"tv":4481.09,"id":8257852}]}]}
{"op":"mcm","clk":"1012087321","pt":1580659466257,"mc":[{"id":"1.168223929","rc":[{"batb":[[2,1.21,168.04]],"ltp":2.22,"tv":1807.97,"id":8444055}]}]}
{"op":"mcm","clk":"1012087429","pt":1580659466965,"mc":[{"id":"1.168223929","rc":[{"trd":[[1.26,18.48]],"batl":[[0,1.26,737.73]],"ltp":1.26,"tv":1826.45,"id":8444055}],"tv":6307.55}]}
{"op":"mcm","clk":"1012087641","pt":1580659468262,"mc":[{"id":"1.168223929","rc":[{"trd":[[1.23,87.8]],"batb":[[0,1.23,975.7]],"ltp":1.23,"tv":1914.25,"id":8444055},{"trd":[[5.4,20]],"ltp":5.4,"tv":4501.09,"id":8257852}],"tv":6415.35}]}
{"op":"mcm","clk":"1012088184","pt":1580659471263,"mc":[{"id":"1.168223929","rc":[{"batb":[[0,1.23,1081.22]],"ltp":1.23,"tv":1914.25,"id":8444055}]}]}
{"op":"mcm","clk":"1012088630","pt":1580659474003,"mc":[{"id":"1.168223929","rc":[{"batl":[[0,1.26,611.84]],"ltp":1.23,"tv":1914.25,"id":8444055}]}]}
{"op":"mcm","clk":"1012088804","pt":1580659475178,"mc":[{"id":"1.168223929","rc":[{"trd":[[1.23,161.74],[1.26,33.62]],"batb":[[0,1.23,1044.25]],"batl":[[0,1.26,604.27]],"ltp":1.26,"tv":2003.34,"id":8444055}],"tv":6504.43}]}
{"op":"mcm","clk":"1012089108","pt":1580659477095,"mc":[{"id":"1.168223929","rc":[{"batb":[[0,1.23,1165.34]],"ltp":1.26,"tv":2003.34,"id":8444055},{"trd":[[4.8,4]],"batb":[[0,4.8,38.82]],"ltp":4.8,"tv":4505.09,"id":8257852}],"tv":6508.43}]}
{"op":"mcm","clk":"1012089652","pt":1580659480255,"mc":[{"id":"1.168223929","rc":[{"batb":[[0,1.23,1242.05]],"ltp":1.26,"tv":2003.34,"id":8444055}]}]}
{"op":"mcm","clk":"1012089974","pt":1580659482178,"mc":[{"id":"1.168223929","rc":[{"trd":[[4.8,19.15]],"batb":[[0,4.8,31.25]],"ltp":4.8,"tv":4520.24,"id":8257852}],"tv":6523.58}]}
{"op":"mcm","clk":"1012090125","pt":1580659483195,"mc":[{"id":"1.168223929","rc":[{"batb":[[0,1.21,168.04],[1,1.16,576.81],[2,1.01,15.51]],"batl":[[0,1.26,42.01],[1,1.27,0]],"ltp":1.26,"tv":2003.34,"id":8444055},{"batb":[[0,4.8,10.92]],"ltp":4.8,"tv":4520.24,"id":8257852}]}]}
{"op":"mcm","clk":"1012090272","pt":1580659484106,"mc":[{"id":"1.168223929","rc":[{"batb":[[0,1.16,576.81],[1,1.01,15.51],[2,1.01,0]],"ltp":1.26,"tv":2003.34,"id":8444055},{"batb":[[0,2.72,377.96],[1,1.83,38.71],[2,1.01,15.51]],"ltp":4.8,"tv":4520.24,"id":8257852}]}]}
{"op":"mcm","clk":"1012090430","pt":1580659485080,"mc":[{"id":"1.168223929","rc":[{"batb":[[0,1.01,15.51],[1,1.01,0]],"ltp":1.26,"tv":2003.34,"id":8444055},{"batb":[[0,1.83,38.71],[1,1.01,15.51],[2,1.01,0]],"ltp":4.8,"tv":4520.24,"id":8257852}]}]}
{"op":"mcm","clk":"1012090915","pt":1580659488185,"mc":[{"id":"1.168223929","rc":[{"batb":[[0,1.35,458.11],[1,1.34,678.67],[2,1.01,15.51]],"batl":[[0,1.39,802.95],[1,1.4,532.66]],"ltp":1.26,"tv":2003.34,"id":8444055}]}]}
{"op":"mcm","clk":"1012091082","pt":1580659489200,"mc":[{"id":"1.168223929","rc":[{"batb":[[0,1.35,351.53]],"batl":[[0,1.39,556.94],[1,1.4,0]],"ltp":1.26,"tv":2003.34,"id":8444055}]}]}
{"op":"mcm","clk":"1012091256","pt":1580659490228,"mc":[{"id":"1.168223929","rc":[{"batb":[[2,1.22,523.64]],"ltp":1.26,"tv":2003.34,"id":8444055},{"batb":[[0,2.42,381.41],[1,1.83,38.71],[2,1.01,15.51]],"ltp":4.8,"tv":4520.24,"id":8257852}]}]}
{"op":"mcm","clk":"1012091427","pt":1580659491112,"mc":[{"id":"1.168223929","rc":[{"batb":[[0,1.22,523.64],[1,1.01,15.51],[2,1.22,0]],"ltp":1.26,"tv":2003.34,"id":8444055}]}]}
{"op":"mcm","clk":"1012091752","pt":1580659493202,"mc":[{"id":"1.168223929","rc":[{"batb":[[0,1.01,15.51],[1,1.01,0]],"ltp":1.26,"tv":2003.34,"id":8444055},{"batb":[[0,1.83,38.71],[1,1.01,15.51],[2,1.01,0]],"ltp":4.8,"tv":4520.24,"id":8257852}]}]}
{"op":"mcm","clk":"1012091924","pt":1580659494213,"mc":[{"id":"1.168223929","rc":[{"batl":[[0,2.22,313.41],[1,2.24,227.21]],"ltp":1.26,"tv":2003.34,"id":8444055}]}]}
{"op":"mcm","clk":"1012093460","pt":1580659503024,"mc":[{"id":"1.168223929","marketDefinition":{"bspMarket":false,"turnInPlayEnabled":true,"persistenceEnabled":true,"marketBaseRate":5.0,"eventId":"29681623","eventTypeId":"2","numberOfWinners":1,"bettingType":"ODDS","marketType":"SET_WINNER","marketTime":"2020-02-02T14:50:00.000Z","suspendTime":"2020-02-02T14:50:00.000Z","bspReconciled":false,"complete":true,"inPlay":true,"crossMatching":true,"runnersVoidable":false,"numberOfActiveRunners":2,"betDelay":3,"status":"SUSPENDED","runners":[{"status":"ACTIVE","sortPriority":1,"id":8257852,"name":"Maxime Janvier"},{"status":"ACTIVE","sortPriority":2,"id":8444055,"name":"Cem Ilkel"}],"regulators":["MR_INT"],"countryCode":"FR","discountAllowed":true,"timezone":"UTC","openDate":"2020-02-02T14:50:00.000Z","version":3149700248,"name":"Set 1 Winner","eventName":"Janvier v Ilkel"},"rc":[{"batb":[[0,1.01,15.51],[1,1.01,0]],"ltp":4.8,"tv":4520.24,"id":8257852}]}]}
{"op":"mcm","clk":"1012099642","pt":1580659538272,"mc":[{"id":"1.168223929","tv":0.0}]}
{"op":"mcm","clk":"1012099809","pt":1580659539225,"mc":[{"id":"1.168223929","marketDefinition":{"bspMarket":false,"turnInPlayEnabled":true,"persistenceEnabled":true,"marketBaseRate":5.0,"eventId":"29681623","eventTypeId":"2","numberOfWinners":1,"bettingType":"ODDS","marketType":"SET_WINNER","marketTime":"2020-02-02T14:50:00.000Z","suspendTime":"2020-02-02T14:50:00.000Z","bspReconciled":false,"complete":true,"inPlay":true,"crossMatching":false,"runnersVoidable":false,"numberOfActiveRunners":0,"betDelay":3,"status":"CLOSED","settledTime":"2020-02-02T16:05:35.000Z","runners":[{"status":"LOSER","sortPriority":1,"id":8257852,"name":"Maxime Janvier"},{"status":"WINNER","sortPriority":2,"id":8444055,"name":"Cem Ilkel"}],"regulators":["MR_INT"],"countryCode":"FR","discountAllowed":true,"timezone":"UTC","openDate":"2020-02-02T14:50:00.000Z","version":3149703533,"name":"Set 1 Winner","eventName":"Janvier v Ilkel"}}]}
