{"op":"mcm","clk":"1004323371","pt":1580581675727,"mc":[{"id":"1.168223929","marketDefinition":{"bspMarket":false,"turnInPlayEnabled":true,"persistenceEnabled":true,"marketBaseRate":5.0,"eventId":"29681623","eventTypeId":"2","numberOfWinners":1,"bettingType":"ODDS","marketType":"SET_WINNER","marketTime":"2020-02-02T15:00:00.000Z","suspendTime":"2020-02-02T15:00:00.000Z","bspReconciled":false,"complete":true,"inPlay":false,"crossMatching":false,"runnersVoidable":false,"numberOfActiveRunners":2,"betDelay":0,"status":"OPEN","runners":[{"status":"ACTIVE","sortPriority":1,"id":8257852,"name":"Maxime Janvier"},{"status":"ACTIVE","sortPriority":2,"id":8444055,"name":"Cem Ilkel"}],"regulators":["MR_INT"],"countryCode":"FR","discountAllowed":false,"timezone":"UTC","openDate":"2020-02-02T15:00:00.000Z","version":3146826523,"name":"Set 1 Winner","eventName":"Janvier v Ilkel"},"rc":[{"batb":[[0,1.01,20]],"ltp":0.0,"tv":0.0,"id":8444055},{"batb":[[0,1.01,20]],"ltp":0.0,"tv":0.0,"id":8257852}]}]}
{"op":"mcm","clk":"1004323649","pt":1580581677280,"mc":[{"id":"1.168223929","marketDefinition":{"bspMarket":false,"turnInPlayEnabled":true,"persistenceEnabled":true,"marketBaseRate":5.0,"eventId":"29681623","eventTypeId":"2","numberOfWinners":1,"bettingType":"ODDS","marketType":"SET_WINNER","marketTime":"2020-02-02T15:00:00.000Z","suspendTime":"2020-02-02T15:00:00.000Z","bspReconciled":false,"complete":true,"inPlay":false,"crossMatching":false,"runnersVoidable":false,"numberOfActiveRunners":2,"betDelay":0,"status":"OPEN","runners":[{"status":"ACTIVE","sortPriority":1,"id":8257852,"name":"Maxime Janvier"},{"status":"ACTIVE","sortPriority":2,"id":8444055,"name":"Cem Ilkel"}],"regulators":["MR_INT"],"countryCode":"FR","discountAllowed":true,"timezone":"UTC","openDate":"2020-02-02T15:00:00.000Z","version":3146826523,"name":"Set 1 Winner","eventName":"Janvier v Ilkel"}}]}
{"op":"mcm","clk":"1004346957","pt":1580581820655,"mc":[{"id":"1.168223929","rc":[{"batb":[[0,1.01,15]],"ltp":0.0,"tv":0.0,"id":8444055},{"batb":[[0,1.01,15]],"ltp":0.0,"tv":0.0,"id":8257852}]}]}
{"op":"mcm","clk":"1006958545","pt":1580602585241,"mc":[{"id":"1.168223929","rc":[{"batb":[[0,1.01,17.53]],"ltp":0.0,"tv":0.0,"id":8444055},{"batb":[[0,1.01,17.53]],"ltp":0.0,"tv":0.0,"id":8257852}]}]}
{"op":"mcm","clk":"1006958585","pt":1580602585817,"mc":[{"id":"1.168223929","rc":[{"batb":[[0,1.01,15.51]],"ltp":0.0,"tv":0.0,"id":8444055},{"batb":[[0,1.01,15.51]],"ltp":0.0,"tv":0.0,"id":8257852}]}]}
{"op":"mcm","clk":"1007018766","pt":1580603351976,"mc":[{"id":"1.168223929","rc":[{"batb":[[0,1.01,16.01]],"ltp":0.0,"tv":0.0,"id":8444055},{"batb":[[0,1.01,16.01]],"ltp":0.0,"tv":0.0,"id":8257852}]}]}
{"op":"mcm","clk":"1007163891","pt":1580606173296,"mc":[{"id":"1.168223929","rc":[{"batb":[[0,2.1,21.14],[1,1.01,16.01]],"ltp":0.0,"tv":0.0,"id":8444055},{"batb":[[0,1.57,31.57],[1,1.01,16.01]],"ltp":0.0,"tv":0.0,"id":8257852}]}]}
{"op":"mcm","clk":"1007298971","pt":1580609773604,"mc":[{"id":"1.168223929","rc":[{"batb":[[0,1.89,23.69]],"ltp":0.0,"tv":0.0,"id":8444055},{"batb":[[0,1.37,36.31]],"ltp":0.0,"tv":0.0,"id":8257852}]}]}
{"op":"mcm","clk":"1007376417","pt":1580612101736,"mc":[{"id":"1.168223929","rc":[{"batb":[[0,1.89,40.05]],"ltp":0.0,"tv":0.0,"id":8444055},{"batb":[[0,1.37,61.31]],"ltp":0.0,"tv":0.0,"id":8257852}]}]}
{"op":"mcm","clk":"1007414658","pt":1580613374552,"mc":[{"id":"1.168223929","rc":[{"batb":[[0,1.88,40.46]],"ltp":0.0,"tv":0.0,"id":8444055},{"batb":[[0,1.51,55.83]],"ltp":0.0,"tv":0.0,"id":8257852}]}]}
{"op":"mcm","clk":"1007435009","pt":1580613970228,"mc":[{"id":"1.168223929","rc":[{"batb":[[0,1.88,57.46]],"ltp":0.0,"tv":0.0,"id":8444055},{"batb":[[0,1.51,79.4]],"ltp":0.0,"tv":0.0,"id":8257852}]}]}
{"op":"mcm","clk":"1007533449","pt":1580616975161,"mc":[{"id":"1.168223929","rc":[{"batb":[[0,1.01,16.01],[1,1.01,0]],"ltp":0.0,"tv":0.0,"id":8444055},{"batb":[[0,1.01,16.01],[1,1.01,0]],"ltp":0.0,"tv":0.0,"id":8257852}]}]}
{"op":"mcm","clk":"1007533454","pt":1580616975468,"mc":[{"id":"1.168223929","rc":[{"batb":[[0,2.04,53.12],[1,1.01,16.01]],"ltp":0.0,"tv":0.0,"id":8444055},{"batb":[[0,1.51,79.77],[1,1.01,16.01]],"ltp":0.0,"tv":0.0,"id":8257852}]}]}
{"op":"mcm","clk":"1007680211","pt":1580620575638,"mc":[{"id":"1.168223929","rc":[{"batb":[[0,1.01,16.01],[1,1.01,0]],"ltp":0.0,"tv":0.0,"id":8444055},{"batb":[[0,1.01,16.01],[1,1.01,0]],"ltp":0.0,"tv":0.0,"id":8257852}]}]}
{"op":"mcm","clk":"1007714430","pt":1580621401613,"mc":[{"id":"1.168223929","rc":[{"batb":[[0,1.76,62.23],[1,1.01,16.01]],"ltp":0.0,"tv":0.0,"id":8444055},{"batb":[[0,1.43,85.29],[1,1.01,16.01]],"ltp":0.0,"tv":0.0,"id":8257852}]}]}
{"op":"mcm","clk":"1007714645","pt":1580621404981,"mc":[{"id":"1.168223929","rc":[{"batb":[[0,2.1,52.04],[1,1.97,9.84],[2,1.01,16.01]],"ltp":0.0,"tv":0.0,"id":8444055},{"batb":[[0,1.58,77.06],[1,1.55,17.35],[2,1.01,16.01]],"ltp":0.0,"tv":0.0,"id":8257852}]}]}
{"op":"mcm","clk":"1007715778","pt":1580621431104,"mc":[{"id":"1.168223929","marketDefinition":{"bspMarket":false,"turnInPlayEnabled":true,"persistenceEnabled":true,"marketBaseRate":5.0,"eventId":"29681623","eventTypeId":"2","numberOfWinners":1,"bettingType":"ODDS","marketType":"SET_WINNER","marketTime":"2020-02-02T15:00:00.000Z","suspendTime":"2020-02-02T15:00:00.000Z","bspReconciled":false,"complete":true,"inPlay":false,"crossMatching":true,"runnersVoidable":false,"numberOfActiveRunners":2,"betDelay":0,"status":"OPEN","runners":[{"status":"ACTIVE","sortPriority":1,"id":8257852,"name":"Maxime Janvier"},{"status":"ACTIVE","sortPriority":2,"id":8444055,"name":"Cem Ilkel"}],"regulators":["MR_INT"],"countryCode":"FR","discountAllowed":true,"timezone":"UTC","openDate":"2020-02-02T15:00:00.000Z","version":3146844616,"name":"Set 1 Winner","eventName":"Janvier v Ilkel"}}]}
{"op":"mcm","clk":"1007804338","pt":1580623314747,"mc":[{"id":"1.168223929","rc":[{"batb":[[0,2.1,77.84]],"ltp":0.0,"tv":0.0,"id":8444055},{"batb":[[0,1.58,115.06]],"ltp":0.0,"tv":0.0,"id":8257852}]}]}
{"op":"mcm","clk":"1007804952","pt":1580623330805,"mc":[{"id":"1.168223929","rc":[{"batb":[[1,1.01,16.01],[2,1.01,0]],"ltp":0.0,"tv":0.0,"id":8444055},{"batb":[[1,1.01,16.01],[2,1.01,0]],"ltp":0.0,"tv":0.0,"id":8257852}]}]}
{"op":"mcm","clk":"1007804976","pt":1580623331366,"mc":[{"id":"1.168223929","rc":[{"batb":[[1,2.02,13.96],[2,1.01,16.01]],"ltp":0.0,"tv":0.0,"id":8444055},{"batb":[[1,1.57,24.97],[2,1.01,16.01]],"ltp":0.0,"tv":0.0,"id":8257852}]}]}
{"op":"mcm","clk":"1007878526","pt":1580625001865,"mc":[{"id":"1.168223929","rc":[{"batb":[[0,2.04,80.62]],"ltp":0.0,"tv":0.0,"id":8444055},{"batb":[[0,1.58,115.56]],"ltp":0.0,"tv":0.0,"id":8257852}]}]}
{"op":"mcm","clk":"1008061104","pt":1580628602268,"mc":[{"id":"1.168223929","rc":[{"batb":[[0,2.14,76.82]],"ltp":0.0,"tv":0.0,"id":8444055},{"batb":[[0,1.61,113.27]],"ltp":0.0,"tv":0.0,"id":8257852}]}]}
{"op":"mcm","clk":"1008061913","pt":1580628616881,"mc":[{"id":"1.168223929","rc":[{"batb":[[1,1.58,24.54]],"ltp":0.0,"tv":0.0,"id":8257852}]}]}
{"op":"mcm","clk":"1008264978","pt":1580632202249,"mc":[{"id":"1.168223929","rc":[{"batb":[[0,2.02,13.96],[1,1.01,16.01],[2,1.01,0]],"ltp":0.0,"tv":0.0,"id":8444055},{"batb":[[0,1.58,24.54],[1,1.01,16.01],[2,1.01,0]],"ltp":0.0,"tv":0.0,"id":8257852}]}]}
{"op":"mcm","clk":"1008327452","pt":1580633266270,"mc":[{"id":"1.168223929","rc":[{"batb":[[0,2.12,77.04],[1,2.02,13.96],[2,1.01,16.01]],"ltp":0.0,"tv":0.0,"id":8444055},{"batb":[[0,1.6,112.09],[1,1.58,24.54],[2,1.01,16.01]],"ltp":0.0,"tv":0.0,"id":8257852}]}]}
{"op":"mcm","clk":"1008378671","pt":1580634233898,"mc":[{"id":"1.168223929","rc":[{"batb":[[0,2.12,102.79]],"ltp":0.0,"tv":0.0,"id":8444055},{"batb":[[0,1.6,149.54]],"ltp":0.0,"tv":0.0,"id":8257852}]}]}
{"op":"mcm","clk":"1008546324","pt":1580636867214,"mc":[{"id":"1.168223929","rc":[{"batb":[[0,2.04,106.87]],"ltp":0.0,"tv":0.0,"id":8444055}]}]}
{"op":"mcm","clk":"1008885949","pt":1580640467136,"mc":[{"id":"1.168223929","rc":[{"batb":[[0,2.02,13.96],[1,1.01,16.01],[2,1.01,0]],"ltp":0.0,"tv":0.0,"id":8444055},{"batb":[[0,1.58,24.54],[1,1.01,16.01],[2,1.01,0]],"ltp":0.0,"tv":0.0,"id":8257852}]}]}
{"op":"mcm","clk":"1008885981","pt":1580640467440,"mc":[{"id":"1.168223929","rc":[{"batb":[[0,2.08,104.81],[1,2.02,13.96],[2,1.01,16.01]],"ltp":0.0,"tv":0.0,"id":8444055},{"batb":[[0,1.62,147.83],[1,1.58,24.54],[2,1.01,16.01]],"ltp":0.0,"tv":0.0,"id":8257852}]}]}
{"op":"mcm","clk":"1009407129","pt":1580644068045,"mc":[{"id":"1.168223929","rc":[{"batb":[[0,2.1,103.84]],"ltp":0.0,"tv":0.0,"id":8444055},{"batb":[[0,1.59,150.55]],"ltp":0.0,"tv":0.0,"id":8257852}]}]}
{"op":"mcm","clk":"1009484415","pt":1580644771199,"mc":[{"id":"1.168223929","rc":[{"batb":[[1,2,18.93]],"ltp":0.0,"tv":0.0,"id":8444055},{"batb":[[0,1.59,182.63],[1,1.01,16.01],[2,1.01,0]],"ltp":0.0,"tv":0.0,"id":8257852}]}]}
{"op":"mcm","clk":"1009674284","pt":1580646117948,"mc":[{"id":"1.168223929","rc":[{"batb":[[0,2,18.93],[1,1.01,16.01],[2,1.01,0]],"batl":[[0,2.56,92.67],[1,2.68,3.79]],"ltp":0.0,"tv":0.0,"id":8444055},{"batb":[[0,1.59,32.08]],"batl":[[0,1.89,114.5],[1,1.9,7.57]],"ltp":0.0,"tv":0.0,"id":8257852}]}]}
{"op":"mcm","clk":"1009676450","pt":1580646133194,"mc":[{"id":"1.168223929","rc":[{"batl":[[0,2.54,3.79],[1,2.56,92.67]],"ltp":0.0,"tv":0.0,"id":8444055},{"batl":[[0,1.88,7.57],[1,1.89,114.5]],"ltp":0.0,"tv":0.0,"id":8257852}]}]}
{"op":"mcm","clk":"1009676492","pt":1580646133501,"mc":[{"id":"1.168223929","rc":[{"batl":[[0,2.52,94.01],[1,2.54,3.79]],"ltp":0.0,"tv":0.0,"id":8444055},{"batl":[[0,1.87,115.73],[1,1.88,7.57]],"ltp":0.0,"tv":0.0,"id":8257852}]}]}
{"op":"mcm","clk":"1009678032","pt":1580646144224,"mc":[{"id":"1.168223929","rc":[{"batl":[[0,2.5,3.79],[1,2.52,94.01]],"ltp":0.0,"tv":0.0,"id":8444055},{"batl":[[0,1.86,7.57],[1,1.88,0]],"ltp":0.0,"tv":0.0,"id":8257852}]}]}
{"op":"mcm","clk":"1009678071","pt":1580646144435,"mc":[{"id":"1.168223929","rc":[{"batl":[[0,2.5,98.56],[1,2.52,0]],"ltp":0.0,"tv":0.0,"id":8444055},{"batl":[[0,1.85,116.9],[1,1.86,7.57]],"ltp":0.0,"tv":0.0,"id":8257852}]}]}
{"op":"mcm","clk":"1009679356","pt":1580646153206,"mc":[{"id":"1.168223929","rc":[{"batl":[[0,1.84,7.57],[1,1.86,0]],"ltp":0.0,"tv":0.0,"id":8257852}]}]}
{"op":"mcm","clk":"1009680065","pt":1580646158847,"mc":[{"id":"1.168223929","rc":[{"batl":[[0,1.85,124.47]],"ltp":0.0,"tv":0.0,"id":8257852}]}]}
{"op":"mcm","clk":"1009890950","pt":1580647668963,"mc":[{"id":"1.168223929","rc":[{"batl":[[0,2.5,3.79]],"ltp":0.0,"tv":0.0,"id":8444055}]}]}
{"op":"mcm","clk":"1009891007","pt":1580647669356,"mc":[{"id":"1.168223929","rc":[{"batb":[[0,1.67,142.23],[1,1.59,32.08],[2,1.01,16.01]],"ltp":0.0,"tv":0.0,"id":8257852}]}]}
{"op":"mcm","clk":"1009965873","pt":1580648314887,"mc":[{"id":"1.168223929","rc":[{"batb":[[0,1.01,16.01],[1,1.01,0]],"ltp":0.0,"tv":0.0,"id":8444055},{"batb":[[1,1.01,16.01],[2,1.01,0]],"ltp":0.0,"tv":0.0,"id":8257852}]}]}
{"op":"mcm","clk":"1009965950","pt":1580648315466,"mc":[{"id":"1.168223929","rc":[{"batb":[[0,2,18.93],[1,1.01,16.01]],"ltp":0.0,"tv":0.0,"id":8444055},{"batb":[[1,1.59,32.08],[2,1.01,16.01]],"ltp":0.0,"tv":0.0,"id":8257852}]}]}
{"op":"mcm","clk":"1010195979","pt":1580649758739,"mc":[{"id":"1.168223929","rc":[{"batl":[[0,1.85,7.57]],"ltp":0.0,"tv":0.0,"id":8257852}]}]}
{"op":"mcm","clk":"1010206230","pt":1580649832635,"mc":[{"id":"1.168223929","rc":[{"batl":[[0,1.85,124.47]],"ltp":0.0,"tv":0.0,"id":8257852}]}]}
{"op":"mcm","clk":"1010206629","pt":1580649835086,"mc":[{"id":"1.168223929","rc":[{"batb":[[0,1.01,16.01],[1,1.01,0]],"ltp":0.0,"tv":0.0,"id":8444055},{"batb":[[1,1.01,16.01],[2,1.01,0]],"ltp":0.0,"tv":0.0,"id":8257852}]}]}
{"op":"mcm","clk":"1010206724","pt":1580649835691,"mc":[{"id":"1.168223929","rc":[{"batb":[[0,2,18.93],[1,1.01,16.01]],"ltp":0.0,"tv":0.0,"id":8444055},{"batb":[[1,1.59,32.08],[2,1.01,16.01]],"ltp":0.0,"tv":0.0,"id":8257852}]}]}
{"op":"mcm","clk":"1010328629","pt":1580650591074,"mc":[{"id":"1.168223929","rc":[{"batl":[[0,1.85,7.57]],"ltp":0.0,"tv":0.0,"id":8257852}]}]}
{"op":"mcm","clk":"1010329143","pt":1580650594156,"mc":[{"id":"1.168223929","rc":[{"batb":[[0,1.96,19.72]],"ltp":0.0,"tv":0.0,"id":8444055},{"batb":[[1,1.62,30.53]],"ltp":0.0,"tv":0.0,"id":8257852}]}]}
{"op":"mcm","clk":"1010330272","pt":1580650601239,"mc":[{"id":"1.168223929","rc":[{"batb":[[0,1.01,16.01],[1,1.01,0]],"ltp":0.0,"tv":0.0,"id":8444055},{"batb":[[1,1.01,16.01],[2,1.01,0]],"ltp":0.0,"tv":0.0,"id":8257852}]}]}
{"op":"mcm","clk":"1010330330","pt":1580650601680,"mc":[{"id":"1.168223929","rc":[{"batb":[[0,1.94,20.14],[1,1.01,16.01]],"ltp":0.0,"tv":0.0,"id":8444055},{"batb":[[1,1.63,30.05],[2,1.01,16.01]],"ltp":0.0,"tv":0.0,"id":8257852}]}]}
{"op":"mcm","clk":"1010391287","pt":1580650975816,"mc":[{"id":"1.168223929","rc":[{"batb":[[0,1.01,16.01],[1,1.01,0]],"ltp":0.0,"tv":0.0,"id":8444055},{"batb":[[1,1.01,16.01],[2,1.01,0]],"ltp":0.0,"tv":0.0,"id":8257852}]}]}
{"op":"mcm","clk":"1010391383","pt":1580650976410,"mc":[{"id":"1.168223929","rc":[{"batb":[[0,1.93,20.35],[1,1.01,16.01]],"ltp":0.0,"tv":0.0,"id":8444055},{"batb":[[1,1.65,29.12],[2,1.01,16.01]],"ltp":0.0,"tv":0.0,"id":8257852}]}]}
{"op":"mcm","clk":"1010400786","pt":1580651032268,"mc":[{"id":"1.168223929","rc":[{"batb":[[0,1.65,29.12],[1,1.01,16.01],[2,1.01,0]],"ltp":0.0,"tv":0.0,"id":8257852}]}]}
{"op":"mcm","clk":"1010400928","pt":1580651033083,"mc":[{"id":"1.168223929","rc":[{"batb":[[0,1.67,132.87],[1,1.65,29.12],[2,1.01,16.01]],"ltp":0.0,"tv":0.0,"id":8257852}]}]}
{"op":"mcm","clk":"1010401378","pt":1580651035793,"mc":[{"id":"1.168223929","rc":[{"batb":[[0,1.01,16.01],[1,1.01,0]],"ltp":0.0,"tv":0.0,"id":8444055},{"batb":[[1,1.01,16.01],[2,1.01,0]],"ltp":0.0,"tv":0.0,"id":8257852}]}]}
{"op":"mcm","clk":"1010401561","pt":1580651036780,"mc":[{"id":"1.168223929","rc":[{"batb":[[0,1.92,20.57],[1,1.01,16.01]],"ltp":0.0,"tv":0.0,"id":8444055},{"batb":[[1,1.66,28.68],[2,1.01,16.01]],"ltp":0.0,"tv":0.0,"id":8257852}]}]}
{"op":"mcm","clk":"1010403680","pt":1580651049908,"mc":[{"id":"1.168223929","rc":[{"batb":[[0,1.01,16.01],[1,1.01,0]],"ltp":0.0,"tv":0.0,"id":8444055},{"batb":[[1,1.01,16.01],[2,1.01,0]],"ltp":0.0,"tv":0.0,"id":8257852}]}]}
{"op":"mcm","clk":"1010403891","pt":1580651051231,"mc":[{"id":"1.168223929","rc":[{"batb":[[0,1.89,21.27],[1,1.01,16.01]],"ltp":0.0,"tv":0.0,"id":8444055},{"batb":[[0,1.71,130.64],[1,1.68,27.84],[2,1.01,16.01]],"ltp":0.0,"tv":0.0,"id":8257852}]}]}
{"op":"mcm","clk":"1010404266","pt":1580651053589,"mc":[{"id":"1.168223929","rc":[{"batb":[[0,1.01,16.01],[1,1.01,0]],"ltp":0.0,"tv":0.0,"id":8444055},{"batb":[[1,1.01,16.01],[2,1.01,0]],"ltp":0.0,"tv":0.0,"id":8257852}]}]}
{"op":"mcm","clk":"1010404413","pt":1580651054711,"mc":[{"id":"1.168223929","rc":[{"batb":[[0,1.92,20.57],[1,1.01,16.01]],"ltp":0.0,"tv":0.0,"id":8444055},{"batb":[[1,1.66,28.68],[2,1.01,16.01]],"ltp":0.0,"tv":0.0,"id":8257852}]}]}
{"op":"mcm","clk":"1010405660","pt":1580651062225,"mc":[{"id":"1.168223929","rc":[{"batb":[[0,1.01,16.01],[1,1.01,0]],"ltp":0.0,"tv":0.0,"id":8444055},{"batb":[[1,1.01,16.01],[2,1.01,0]],"ltp":0.0,"tv":0.0,"id":8257852}]}]}
{"op":"mcm","clk":"1010405761","pt":1580651062815,"mc":[{"id":"1.168223929","rc":[{"batb":[[0,1.9,21.04],[1,1.01,16.01]],"ltp":0.0,"tv":0.0,"id":8444055},{"batb":[[1,1.67,28.25],[2,1.01,16.01]],"ltp":0.0,"tv":0.0,"id":8257852}]}]}
{"op":"mcm","clk":"1010409347","pt":1580651083860,"mc":[{"id":"1.168223929","rc":[{"batb":[[0,1.01,16.01],[1,1.01,0]],"ltp":0.0,"tv":0.0,"id":8444055},{"batb":[[1,1.01,16.01],[2,1.01,0]],"ltp":0.0,"tv":0.0,"id":8257852}]}]}
{"op":"mcm","clk":"1010409578","pt":1580651085248,"mc":[{"id":"1.168223929","rc":[{"batb":[[0,1.88,21.51],[1,1.01,16.01]],"ltp":0.0,"tv":0.0,"id":8444055},{"batb":[[1,1.69,27.43],[2,1.01,16.01]],"ltp":0.0,"tv":0.0,"id":8257852}]}]}
{"op":"mcm","clk":"1010410054","pt":1580651088065,"mc":[{"id":"1.168223929","rc":[{"batb":[[0,1.9,21.04]],"ltp":0.0,"tv":0.0,"id":8444055},{"batb":[[1,1.67,28.25]],"ltp":0.0,"tv":0.0,"id":8257852}]}]}
{"op":"mcm","clk":"1010412844","pt":1580651103697,"mc":[{"id":"1.168223929","rc":[{"batb":[[0,1.01,16.01],[1,1.01,0]],"ltp":0.0,"tv":0.0,"id":8444055},{"batb":[[1,1.01,16.01],[2,1.01,0]],"ltp":0.0,"tv":0.0,"id":8257852}]}]}
{"op":"mcm","clk":"1010413009","pt":1580651104409,"mc":[{"id":"1.168223929","rc":[{"batb":[[0,1.93,20.35],[1,1.01,16.01]],"ltp":0.0,"tv":0.0,"id":8444055},{"batb":[[1,1.64,29.58],[2,1.01,16.01]],"ltp":0.0,"tv":0.0,"id":8257852}]}]}
{"op":"mcm","clk":"1010415370","pt":1580651116916,"mc":[{"id":"1.168223929","rc":[{"batb":[[0,1.01,16.01],[1,1.01,0]],"ltp":0.0,"tv":0.0,"id":8444055},{"batb":[[1,1.01,16.01],[2,1.01,0]],"ltp":0.0,"tv":0.0,"id":8257852}]}]}
{"op":"mcm","clk":"1010415519","pt":1580651117607,"mc":[{"id":"1.168223929","rc":[{"batb":[[0,1.92,20.57],[1,1.01,16.01]],"ltp":0.0,"tv":0.0,"id":8444055},{"batb":[[1,1.65,29.12],[2,1.01,16.01]],"ltp":0.0,"tv":0.0,"id":8257852}]}]}
{"op":"mcm","clk":"1010417034","pt":1580651126629,"mc":[{"id":"1.168223929","rc":[{"batb":[[0,1.01,16.01],[1,1.01,0]],"ltp":0.0,"tv":0.0,"id":8444055},{"batb":[[1,1.01,16.01],[2,1.01,0]],"ltp":0.0,"tv":0.0,"id":8257852}]}]}
{"op":"mcm","clk":"1010417135","pt":1580651127280,"mc":[{"id":"1.168223929","rc":[{"batb":[[0,1.9,21.04],[1,1.01,16.01]],"ltp":0.0,"tv":0.0,"id":8444055},{"batb":[[1,1.67,28.25],[2,1.01,16.01]],"ltp":0.0,"tv":0.0,"id":8257852}]}]}
{"op":"mcm","clk":"1010419808","pt":1580651142940,"mc":[{"id":"1.168223929","rc":[{"batb":[[0,1.88,21.51]],"ltp":0.0,"tv":0.0,"id":8444055},{"batb":[[1,1.68,27.84]],"ltp":0.0,"tv":0.0,"id":8257852}]}]}
{"op":"mcm","clk":"1010421373","pt":1580651151181,"mc":[{"id":"1.168223929","rc":[{"batb":[[0,1.01,16.01],[1,1.01,0]],"ltp":0.0,"tv":0.0,"id":8444055},{"batb":[[1,1.01,16.01],[2,1.01,0]],"ltp":0.0,"tv":0.0,"id":8257852}]}]}
{"op":"mcm","clk":"1010421551","pt":1580651152090,"mc":[{"id":"1.168223929","rc":[{"batb":[[0,1.9,21.04],[1,1.01,16.01]],"ltp":0.0,"tv":0.0,"id":8444055},{"batb":[[1,1.67,28.25],[2,1.01,16.01]],"ltp":0.0,"tv":0.0,"id":8257852}]}]}
{"op":"mcm","clk":"1010424072","pt":1580651165893,"mc":[{"id":"1.168223929","rc":[{"batb":[[0,1.89,21.27]],"ltp":0.0,"tv":0.0,"id":8444055},{"batb":[[1,1.68,27.84]],"ltp":0.0,"tv":0.0,"id":8257852}]}]}
{"op":"mcm","clk":"1010425677","pt":1580651174005,"mc":[{"id":"1.168223929","rc":[{"batb":[[0,1.01,16.01],[1,1.01,0]],"ltp":0.0,"tv":0.0,"id":8444055},{"batb":[[1,1.01,16.01],[2,1.01,0]],"ltp":0.0,"tv":0.0,"id":8257852}]}]}
{"op":"mcm","clk":"1010425831","pt":1580651174610,"mc":[{"id":"1.168223929","rc":[{"batb":[[0,1.89,21.27],[1,1.01,16.01]],"ltp":0.0,"tv":0.0,"id":8444055},{"batb":[[1,1.68,27.84],[2,1.01,16.01]],"ltp":0.0,"tv":0.0,"id":8257852}]}]}
{"op":"mcm","clk":"1010427446","pt":1580651182087,"mc":[{"id":"1.168223929","rc":[{"batb":[[0,1.88,21.51]],"ltp":0.0,"tv":0.0,"id":8444055},{"batb":[[1,1.69,27.43]],"ltp":0.0,"tv":0.0,"id":8257852}]}]}
{"op":"mcm","clk":"1010429561","pt":1580651193060,"mc":[{"id":"1.168223929","rc":[{"batb":[[0,1.01,16.01],[1,1.01,0]],"ltp":0.0,"tv":0.0,"id":8444055},{"batb":[[1,1.01,16.01],[2,1.01,0]],"ltp":0.0,"tv":0.0,"id":8257852}]}]}
{"op":"mcm","clk":"1010429684","pt":1580651193652,"mc":[{"id":"1.168223929","rc":[{"batb":[[0,1.88,21.51],[1,1.01,16.01]],"ltp":0.0,"tv":0.0,"id":8444055},{"batb":[[1,1.68,27.84],[2,1.01,16.01]],"ltp":0.0,"tv":0.0,"id":8257852}]}]}
{"op":"mcm","clk":"1010434801","pt":1580651220087,"mc":[{"id":"1.168223929","rc":[{"batb":[[0,1.01,16.01],[1,1.01,0]],"ltp":0.0,"tv":0.0,"id":8444055},{"batb":[[1,1.01,16.01],[2,1.01,0]],"ltp":0.0,"tv":0.0,"id":8257852}]}]}
{"op":"mcm","clk":"1010434920","pt":1580651220681,"mc":[{"id":"1.168223929","rc":[{"batb":[[0,1.89,21.27],[1,1.01,16.01]],"ltp":0.0,"tv":0.0,"id":8444055},{"batb":[[1,1.68,27.84],[2,1.01,16.01]],"ltp":0.0,"tv":0.0,"id":8257852}]}]}
{"op":"mcm","clk":"1010444400","pt":1580651273179,"mc":[{"id":"1.168223929","rc":[{"batb":[[0,1.7,129.12]],"ltp":0.0,"tv":0.0,"id":8257852}]}]}
{"op":"mcm","clk":"1010452229","pt":1580651319270,"mc":[{"id":"1.168223929","rc":[{"batb":[[0,1.01,16.01],[1,1.01,0]],"ltp":0.0,"tv":0.0,"id":8444055},{"batb":[[1,1.01,16.01],[2,1.01,0]],"ltp":0.0,"tv":0.0,"id":8257852}]}]}
{"op":"mcm","clk":"1010452388","pt":1580651320176,"mc":[{"id":"1.168223929","rc":[{"batb":[[0,1.9,21.04],[1,1.01,16.01]],"ltp":0.0,"tv":0.0,"id":8444055},{"batb":[[1,1.67,28.25],[2,1.01,16.01]],"ltp":0.0,"tv":0.0,"id":8257852}]}]}
{"op":"mcm","clk":"1010456382","pt":1580651345106,"mc":[{"id":"1.168223929","rc":[{"batb":[[0,1.01,16.01],[1,1.01,0]],"ltp":0.0,"tv":0.0,"id":8444055},{"batb":[[1,1.01,16.01],[2,1.01,0]],"ltp":0.0,"tv":0.0,"id":8257852}]}]}
{"op":"mcm","clk":"1010456472","pt":1580651345699,"mc":[{"id":"1.168223929","rc":[{"batb":[[0,1.9,21.04],[1,1.01,16.01]],"ltp":0.0,"tv":0.0,"id":8444055},{"batb":[[1,1.67,28.25],[2,1.01,16.01]],"ltp":0.0,"tv":0.0,"id":8257852}]}]}
{"op":"mcm","clk":"1010460362","pt":1580651370240,"mc":[{"id":"1.168223929","rc":[{"batb":[[0,1.93,20.35]],"ltp":0.0,"tv":0.0,"id":8444055},{"batb":[[1,1.65,29.12]],"ltp":0.0,"tv":0.0,"id":8257852}]}]}
{"op":"mcm","clk":"1010465570","pt":1580651403186,"mc":[{"id":"1.168223929","rc":[{"batb":[[1,1.64,29.58]],"ltp":0.0,"tv":0.0,"id":8257852}]}]}
{"op":"mcm","clk":"1010479125","pt":1580651491952,"mc":[{"id":"1.168223929","rc":[{"batb":[[0,1.01,16.01],[1,1.01,0]],"ltp":0.0,"tv":0.0,"id":8444055},{"batb":[[1,1.01,16.01],[2,1.01,0]],"ltp":0.0,"tv":0.0,"id":8257852}]}]}
{"op":"mcm","clk":"1010479217","pt":1580651492538,"mc":[{"id":"1.168223929","rc":[{"batb":[[0,1.93,20.35],[1,1.01,16.01]],"ltp":0.0,"tv":0.0,"id":8444055},{"batb":[[1,1.64,29.58],[2,1.01,16.01]],"ltp":0.0,"tv":0.0,"id":8257852}]}]}
{"op":"mcm","clk":"1010556715","pt":1580652006215,"mc":[{"id":"1.168223929","rc":[{"batb":[[0,1.01,16.01],[1,1.01,0]],"ltp":0.0,"tv":0.0,"id":8444055},{"batb":[[1,1.01,16.01],[2,1.01,0]],"ltp":0.0,"tv":0.0,"id":8257852}]}]}
{"op":"mcm","clk":"1010561358","pt":1580652031161,"mc":[{"id":"1.168223929","rc":[{"batb":[[0,2.18,2],[1,1.01,16.01]],"ltp":0.0,"tv":0.0,"id":8444055},{"batb":[[0,1.71,2]],"ltp":0.0,"tv":0.0,"id":8257852}]}]}
{"op":"mcm","clk":"1010561478","pt":1580652031868,"mc":[{"id":"1.168223929","rc":[{"batb":[[0,1.72,132.34],[1,1.71,2],[2,1.01,16.01]],"ltp":0.0,"tv":0.0,"id":8257852}]}]}
{"op":"mcm","clk":"1010692860","pt":1580652630192,"mc":[{"id":"1.168223929","rc":[{"batb":[[1,1.01,16.01],[2,1.01,0]],"ltp":0.0,"tv":0.0,"id":8257852}]}]}
{"op":"mcm","clk":"1010693009","pt":1580652630897,"mc":[{"id":"1.168223929","rc":[{"batb":[[0,1.01,16.01],[1,1.01,0]],"ltp":0.0,"tv":0.0,"id":8444055}]}]}
{"op":"mcm","clk":"1010832946","pt":1580653267017,"mc":[{"id":"1.168223929","rc":[{"batb":[[0,2.18,2],[1,1.01,16.01]],"ltp":0.0,"tv":0.0,"id":8444055},{"batb":[[0,1.73,2]],"ltp":0.0,"tv":0.0,"id":8257852}]}]}
{"op":"mcm","clk":"1010957244","pt":1580653866189,"mc":[{"id":"1.168223929","rc":[{"batb":[[0,1.01,16.01],[1,1.01,0]],"ltp":0.0,"tv":0.0,"id":8444055},{"batb":[[0,1.01,16.01],[1,1.01,0]],"ltp":0.0,"tv":0.0,"id":8257852}]}]}
{"op":"mcm","clk":"1010958224","pt":1580653871060,"mc":[{"id":"1.168223929","rc":[{"batb":[[0,2.18,2],[1,1.01,16.01]],"ltp":0.0,"tv":0.0,"id":8444055},{"batb":[[0,1.67,2],[1,1.01,16.01]],"ltp":0.0,"tv":0.0,"id":8257852}]}]}
{"op":"mcm","clk":"1010959464","pt":1580653876267,"mc":[{"id":"1.168223929","rc":[{"batb":[[0,1.68,1.5],[1,1.67,2],[2,1.01,16.01]],"ltp":0.0,"tv":0.0,"id":8257852}]}]}
{"op":"mcm","clk":"1010959702","pt":1580653877143,"mc":[{"id":"1.168223929","rc":[{"batb":[[0,2.2,1.14],[1,2.18,2],[2,1.01,16.01]],"ltp":0.0,"tv":0.0,"id":8444055}]}]}
{"op":"mcm","clk":"1011092842","pt":1580654470125,"mc":[{"id":"1.168223929","rc":[{"batb":[[1,1.01,16.01],[2,1.01,0]],"ltp":0.0,"tv":0.0,"id":8257852}]}]}
{"op":"mcm","clk":"1011093038","pt":1580654471095,"mc":[{"id":"1.168223929","rc":[{"batb":[[1,1.01,16.01],[2,1.01,0]],"ltp":0.0,"tv":0.0,"id":8444055},{"batb":[[0,1.69,83.92],[1,1.68,1.5],[2,1.01,16.01]],"ltp":0.0,"tv":0.0,"id":8257852}]}]}
{"op":"mcm","clk":"1011093423","pt":1580654472929,"mc":[{"id":"1.168223929","rc":[{"batb":[[1,1.01,17.69],[2,1.01,0]],"ltp":0.0,"tv":0.0,"id":8257852}]}]}
{"op":"mcm","clk":"1011093683","pt":1580654474120,"mc":[{"id":"1.168223929","rc":[{"batb":[[1,1.01,17.49]],"ltp":0.0,"tv":0.0,"id":8257852}]}]}
{"op":"mcm","clk":"1011093889","pt":1580654474993,"mc":[{"id":"1.168223929","rc":[{"batb":[[0,1.71,82.88],[1,1.7,1.48],[2,1.01,16.01]],"ltp":0.0,"tv":0.0,"id":8257852}]}]}
{"op":"mcm","clk":"1011095002","pt":1580654480002,"mc":[{"id":"1.168223929","rc":[{"batb":[[1,2.18,2],[2,1.01,16.01]],"ltp":0.0,"tv":0.0,"id":8444055},{"batb":[[0,1.72,2],[1,1.71,82.88],[2,1.7,1.48]],"ltp":0.0,"tv":0.0,"id":8257852}]}]}
{"op":"mcm","clk":"1011095125","pt":1580654480552,"mc":[{"id":"1.168223929","rc":[{"batb":[[0,1.72,84.34],[1,1.7,1.48],[2,1.01,16.01]],"ltp":0.0,"tv":0.0,"id":8257852}]}]}
{"op":"mcm","clk":"1011100333","pt":1580654504040,"mc":[{"id":"1.168223929","rc":[{"batb":[[0,1.73,1.45],[1,1.72,84.34]],"ltp":0.0,"tv":0.0,"id":8257852}]}]}
{"op":"mcm","clk":"1011101119","pt":1580654507730,"mc":[{"id":"1.168223929","rc":[{"batb":[[1,1.72,2]],"ltp":0.0,"tv":0.0,"id":8257852}]}]}
{"op":"mcm","clk":"1011200173","pt":1580654989878,"mc":[{"id":"1.168223929","rc":[{"batb":[[0,1.74,129.02],[1,1.73,1.45],[2,1.72,2]],"ltp":0.0,"tv":0.0,"id":8257852}]}]}
{"op":"mcm","clk":"1011204115","pt":1580655014197,"mc":[{"id":"1.168223929","rc":[{"batb":[[0,1.73,131.84],[1,1.72,2],[2,1.01,16.01]],"ltp":0.0,"tv":0.0,"id":8257852}]}]}
{"op":"mcm","clk":"1011214434","pt":1580655079143,"mc":[{"id":"1.168223929","rc":[{"batb":[[1,1.01,16.01],[2,1.01,0]],"ltp":0.0,"tv":0.0,"id":8444055}]}]}
{"op":"mcm","clk":"1011214567","pt":1580655080038,"mc":[{"id":"1.168223929","rc":[{"batb":[[1,1.01,16.01],[2,1.01,0]],"ltp":0.0,"tv":0.0,"id":8257852}]}]}
{"op":"mcm","clk":"1011219631","pt":1580655112527,"mc":[{"id":"1.168223929","marketDefinition":{"bspMarket":false,"turnInPlayEnabled":true,"persistenceEnabled":true,"marketBaseRate":5.0,"eventId":"29681623","eventTypeId":"2","numberOfWinners":1,"bettingType":"ODDS","marketType":"SET_WINNER","marketTime":"2020-02-02T14:50:00.000Z","suspendTime":"2020-02-02T14:50:00.000Z","bspReconciled":false,"complete":true,"inPlay":false,"crossMatching":true,"runnersVoidable":false,"numberOfActiveRunners":2,"betDelay":0,"status":"OPEN","runners":[{"status":"ACTIVE","sortPriority":1,"id":8257852,"name":"Maxime Janvier"},{"status":"ACTIVE","sortPriority":2,"id":8444055,"name":"Cem Ilkel"}],"regulators":["MR_INT"],"countryCode":"FR","discountAllowed":true,"timezone":"UTC","openDate":"2020-02-02T15:00:00.000Z","version":3149299568,"name":"Set 1 Winner","eventName":"Janvier v Ilkel"}}]}
{"op":"mcm","clk":"1011220310","pt":1580655116547,"mc":[{"id":"1.168223929","marketDefinition":{"bspMarket":false,"turnInPlayEnabled":true,"persistenceEnabled":true,"marketBaseRate":5.0,"eventId":"29681623","eventTypeId":"2","numberOfWinners":1,"bettingType":"ODDS","marketType":"SET_WINNER","marketTime":"2020-02-02T14:50:00.000Z","suspendTime":"2020-02-02T14:50:00.000Z","bspReconciled":false,"complete":true,"inPlay":false,"crossMatching":true,"runnersVoidable":false,"numberOfActiveRunners":2,"betDelay":0,"status":"OPEN","runners":[{"status":"ACTIVE","sortPriority":1,"id":8257852,"name":"Maxime Janvier"},{"status":"ACTIVE","sortPriority":2,"id":8444055,"name":"Cem Ilkel"}],"regulators":["MR_INT"],"countryCode":"FR","discountAllowed":true,"timezone":"UTC","openDate":"2020-02-02T14:50:00.000Z","version":3149299568,"name":"Set 1 Winner","eventName":"Janvier v Ilkel"}}]}
{"op":"mcm","clk":"1011226539","pt":1580655155656,"mc":[{"id":"1.168223929","rc":[{"batb":[[1,2.12,48.39],[2,1.01,16.01]],"ltp":0.0,"tv":0.0,"id":8444055},{"batb":[[0,1.78,41.78],[1,1.73,1.45],[2,1.01,16.01]],"ltp":0.0,"tv":0.0,"id":8257852}]}]}
{"op":"mcm","clk":"1011270700","pt":1580655427788,"mc":[{"id":"1.168223929","rc":[{"batb":[[1,2.14,47.92]],"ltp":0.0,"tv":0.0,"id":8444055}]}]}
{"op":"mcm","clk":"1011296747","pt":1580655598853,"mc":[{"id":"1.168223929","rc":[{"batb":[[1,2.14,47.45]],"ltp":0.0,"tv":0.0,"id":8444055},{"batb":[[0,1.77,42.57]],"ltp":0.0,"tv":0.0,"id":8257852}]}]}
{"op":"mcm","clk":"1011300484","pt":1580655618962,"mc":[{"id":"1.168223929","rc":[{"batb":[[1,2.14,46.97]],"ltp":0.0,"tv":0.0,"id":8444055}]}]}
{"op":"mcm","clk":"1011302159","pt":1580655629112,"mc":[{"id":"1.168223929","rc":[{"batb":[[1,2.18,2],[2,2.16,46.5]],"ltp":0.0,"tv":0.0,"id":8444055},{"batb":[[0,1.78,2],[1,1.76,43.43],[2,1.73,1.45]],"ltp":0.0,"tv":0.0,"id":8257852}]}]}
{"op":"mcm","clk":"1011304370","pt":1580655642342,"mc":[{"id":"1.168223929","rc":[{"batb":[[1,1.77,855.08],[2,1.76,43.43]],"ltp":0.0,"tv":0.0,"id":8257852}]}]}
{"op":"mcm","clk":"1011312560","pt":1580655687902,"mc":[{"id":"1.168223929","rc":[{"batb":[[1,2.16,46.5],[2,1.01,16.01]],"ltp":0.0,"tv":0.0,"id":8444055},{"batb":[[0,1.77,855.08],[1,1.76,43.43],[2,1.73,1.45]],"ltp":0.0,"tv":0.0,"id":8257852}]}]}
{"op":"mcm","clk":"1011374489","pt":1580655981284,"mc":[{"id":"1.168223929","rc":[{"batb":[[1,2.16,46.34]],"ltp":0.0,"tv":0.0,"id":8444055}]}]}
{"op":"mcm","clk":"1011394799","pt":1580656066141,"mc":[{"id":"1.168223929","rc":[{"trd":[[1.77,106.11]],"batb":[[0,1.77,802.01]],"ltp":1.77,"tv":106.11,"id":8257852}],"tv":106.11}]}
{"op":"mcm","clk":"1011433624","pt":1580656222882,"mc":[{"id":"1.168223929","rc":[{"batb":[[1,2.16,45.64]],"ltp":0.0,"tv":0.0,"id":8444055},{"batb":[[2,1.75,44.14]],"ltp":1.77,"tv":106.11,"id":8257852}]}]}
{"op":"mcm","clk":"1011451804","pt":1580656295291,"mc":[{"id":"1.168223929","rc":[{"batl":[[0,1.97,7.57]],"ltp":1.77,"tv":106.11,"id":8257852}]}]}
{"op":"mcm","clk":"1011453649","pt":1580656302995,"mc":[{"id":"1.168223929","rc":[{"batl":[[0,1.99,7.57]],"ltp":1.77,"tv":106.11,"id":8257852}]}]}
{"op":"mcm","clk":"1011453879","pt":1580656303983,"mc":[{"id":"1.168223929","rc":[{"batb":[[1,2.14,46.89]],"ltp":0.0,"tv":0.0,"id":8444055},{"batb":[[0,1.77,845.05],[1,1.73,1.45],[2,1.01,16.01]],"ltp":1.77,"tv":106.11,"id":8257852}]}]}
{"op":"mcm","clk":"1011456012","pt":1580656313104,"mc":[{"id":"1.168223929","rc":[{"batl":[[0,2.58,3.79]],"ltp":0.0,"tv":0.0,"id":8444055}]}]}
{"op":"mcm","clk":"1011457746","pt":1580656320007,"mc":[{"id":"1.168223929","rc":[{"batb":[[1,1.01,16.01],[2,1.01,0]],"ltp":0.0,"tv":0.0,"id":8444055},{"batb":[[0,1.77,802.01]],"ltp":1.77,"tv":106.11,"id":8257852}]}]}
{"op":"mcm","clk":"1011457918","pt":1580656320833,"mc":[{"id":"1.168223929","marketDefinition":{"bspMarket":false,"turnInPlayEnabled":true,"persistenceEnabled":true,"marketBaseRate":5.0,"eventId":"29681623","eventTypeId":"2","numberOfWinners":1,"bettingType":"ODDS","marketType":"SET_WINNER","marketTime":"2020-02-02T14:50:00.000Z","suspendTime":"2020-02-02T14:50:00.000Z","bspReconciled":false,"complete":true,"inPlay":true,"crossMatching":true,"runnersVoidable":false,"numberOfActiveRunners":2,"betDelay":3,"status":"OPEN","runners":[{"status":"ACTIVE","sortPriority":1,"id":8257852,"name":"Maxime Janvier"},{"status":"ACTIVE","sortPriority":2,"id":8444055,"name":"Cem Ilkel"}],"regulators":["MR_INT"],"countryCode":"FR","discountAllowed":true,"timezone":"UTC","openDate":"2020-02-02T14:50:00.000Z","version":3149418451,"name":"Set 1 Winner","eventName":"Janvier v Ilkel"},"rc":[{"batb":[[0,1.01,15.51],[1,1.01,0]],"ltp":0.0,"tv":0.0,"id":8444055},{"batb":[[1,1.01,15.51],[2,1.01,0]],"ltp":1.77,"tv":106.11,"id":8257852}]}]}
{"op":"mcm","clk":"1011463066","pt":1580656340969,"mc":[{"id":"1.168223929","rc":[{"batb":[[0,2.28,39.34],[1,2.08,51.54],[2,1.01,15.51]],"ltp":0.0,"tv":0.0,"id":8444055},{"batb":[[1,1.68,50.59],[2,1.61,58.78]],"ltp":1.77,"tv":106.11,"id":8257852}]}]}
{"op":"mcm","clk":"1011466762","pt":1580656355815,"mc":[{"id":"1.168223929","rc":[{"batb":[[0,2.08,51.54],[1,1.01,15.51],[2,1.01,0]],"ltp":0.0,"tv":0.0,"id":8444055},{"batb":[[1,1.61,58.78],[2,1.01,15.51]],"ltp":1.77,"tv":106.11,"id":8257852}]}]}
{"op":"mcm","clk":"1011467593","pt":1580656358986,"mc":[{"id":"1.168223929","rc":[{"batb":[[1,1.62,58.7]],"ltp":1.77,"tv":106.11,"id":8257852}]}]}
{"op":"mcm","clk":"1011468828","pt":1580656364088,"mc":[{"id":"1.168223929","rc":[{"trd":[[2.3,33.28]],"batb":[[0,2.24,74.99]],"batl":[[0,2.56,26.89]],"ltp":2.3,"tv":33.28,"id":8444055},{"trd":[[1.77,819.41]],"batb":[[0,1.77,423.73],[1,1.65,63.85],[2,1.62,58.7]],"batl":[[0,1.8,42.01]],"ltp":1.77,"tv":819.41,"id":8257852}],"tv":852.69}]}
{"op":"mcm","clk":"1011468918","pt":1580656364459,"mc":[{"id":"1.168223929","rc":[{"batb":[[0,2.24,41.39]],"ltp":2.3,"tv":33.28,"id":8444055}]}]}
{"op":"mcm","clk":"1011469618","pt":1580656367272,"mc":[{"id":"1.168223929","rc":[{"batb":[[0,2.26,32.77],[1,2.24,41.39],[2,1.01,15.51]],"ltp":2.3,"tv":33.28,"id":8444055}]}]}
{"op":"mcm","clk":"1011471294","pt":1580656373933,"mc":[{"id":"1.168223929","rc":[{"trd":[[1.77,876.41]],"batb":[[0,1.77,395.23]],"ltp":1.77,"tv":876.41,"id":8257852}],"tv":909.69}]}
{"op":"mcm","clk":"1011471440","pt":1580656374512,"mc":[{"id":"1.168223929","rc":[{"batb":[[2,1.58,64.28]],"ltp":1.77,"tv":876.41,"id":8257852}]}]}
{"op":"mcm","clk":"1011471903","pt":1580656376374,"mc":[{"id":"1.168223929","rc":[{"batb":[[0,2.24,41.39],[1,1.01,15.51],[2,1.01,0]],"ltp":2.3,"tv":33.28,"id":8444055},{"batb":[[1,1.58,64.28],[2,1.01,15.51]],"ltp":1.77,"tv":876.41,"id":8257852}]}]}
{"op":"mcm","clk":"1011472250","pt":1580656377809,"mc":[{"id":"1.168223929","rc":[{"batb":[[0,2.22,42.8]],"ltp":2.3,"tv":33.28,"id":8444055},{"batb":[[1,1.61,62.32]],"ltp":1.77,"tv":876.41,"id":8257852}]}]}
{"op":"mcm","clk":"1011475509","pt":1580656391212,"mc":[{"id":"1.168223929","rc":[{"trd":[[2.3,100]],"batb":[[0,1.01,15.51],[1,1.01,0]],"ltp":2.3,"tv":100.0,"id":8444055},{"trd":[[1.77,1578.13]],"batb":[[0,1.77,1.02],[2,1.58,66.8]],"ltp":1.77,"tv":1578.12,"id":8257852}],"tv":1678.13}]}
{"op":"mcm","clk":"1011475652","pt":1580656391800,"mc":[{"id":"1.168223929","rc":[{"trd":[[1.77,1580.16]],"batb":[[0,1.61,62.32],[1,1.58,66.8],[2,1.01,15.51]],"ltp":1.77,"tv":1580.15,"id":8257852}],"tv":1680.16}]}
{"op":"mcm","clk":"1011476414","pt":1580656395139,"mc":[{"id":"1.168223929","rc":[{"batb":[[0,2.32,31.09],[1,1.01,15.51]],"batl":[[0,2.66,25.21]],"ltp":2.3,"tv":100.0,"id":8444055},{"batb":[[0,1.61,130.37]],"batl":[[0,1.76,42.01]],"ltp":1.77,"tv":1580.15,"id":8257852}]}]}
{"op":"mcm","clk":"1011477001","pt":1580656397616,"mc":[{"id":"1.168223929","rc":[{"batb":[[0,1.61,611.01],[1,1.6,268.83],[2,1.58,66.8]],"batl":[[0,1.68,435.04],[1,1.7,431.43],[2,1.76,42.01]],"ltp":1.77,"tv":1580.15,"id":8257852}]}]}
{"op":"mcm","clk":"1011478298","pt":1580656403249,"mc":[{"id":"1.168223929","rc":[{"batb":[[0,1.61,68.06]],"batl":[[0,1.76,42.01],[1,1.7,0],[2,1.76,0]],"ltp":1.77,"tv":1580.15,"id":8257852}]}]}
{"op":"mcm","clk":"1011478754","pt":1580656405099,"mc":[{"id":"1.168223929","rc":[{"batb":[[0,1.01,15.51],[1,1.01,0]],"ltp":2.3,"tv":100.0,"id":8444055},{"batb":[[0,1.58,66.8],[1,1.01,15.51],[2,1.58,0]],"ltp":1.77,"tv":1580.15,"id":8257852}]}]}
{"op":"mcm","clk":"1011479011","pt":1580656406131,"mc":[{"id":"1.168223929","rc":[{"batb":[[0,2.32,37.45],[1,1.01,15.51]],"ltp":2.3,"tv":100.0,"id":8444055},{"batb":[[0,1.6,64.2],[1,1.58,66.8],[2,1.01,15.51]],"ltp":1.77,"tv":1580.15,"id":8257852}]}]}
{"op":"mcm","clk":"1011479077","pt":1580656406395,"mc":[{"id":"1.168223929","rc":[{"batb":[[1,1.01,15.51],[2,1.01,0]],"ltp":1.77,"tv":1580.15,"id":8257852}]}]}
{"op":"mcm","clk":"1011479449","pt":1580656408132,"mc":[{"id":"1.168223929","rc":[{"batb":[[0,1.62,404.06],[1,1.61,262.42],[2,1.6,64.2]],"batl":[[0,1.68,258.63],[1,1.7,432.47]],"ltp":1.77,"tv":1580.15,"id":8257852}]}]}
{"op":"mcm","clk":"1011480089","pt":1580656410836,"mc":[{"id":"1.168223929","rc":[{"batb":[[0,1.6,64.2],[1,1.01,15.51],[2,1.6,0]],"ltp":1.77,"tv":1580.15,"id":8257852}]}]}
{"op":"mcm","clk":"1011480904","pt":1580656414043,"mc":[{"id":"1.168223929","rc":[{"batb":[[0,1.6,346.94],[1,1.59,274.42],[2,1.01,15.51]],"ltp":1.77,"tv":1580.15,"id":8257852}]}]}
{"op":"mcm","clk":"1011481661","pt":1580656417235,"mc":[{"id":"1.168223929","rc":[{"batb":[[0,2.38,30.25],[1,2.32,37.45],[2,1.01,15.51]],"batl":[[0,2.74,23.53]],"ltp":2.3,"tv":100.0,"id":8444055},{"batb":[[2,1.58,72.26]],"batl":[[0,1.66,425.97],[1,1.68,449.22],[2,1.71,42.01]],"ltp":1.77,"tv":1580.15,"id":8257852}]}]}
{"op":"mcm","clk":"1011481869","pt":1580656418148,"mc":[{"id":"1.168223929","rc":[{"batb":[[0,2.52,29.98],[1,2.38,30.25],[2,2.34,36.9]],"ltp":2.3,"tv":100.0,"id":8444055}]}]}
{"op":"mcm","clk":"1011482371","pt":1580656420258,"mc":[{"id":"1.168223929","rc":[{"batb":[[2,2.36,10.18]],"ltp":2.3,"tv":100.0,"id":8444055}]}]}
{"op":"mcm","clk":"1011489302","pt":1580656449080,"mc":[{"id":"1.168223929","rc":[{"trd":[[1.66,53.22]],"batl":[[0,1.66,399.36]],"ltp":1.66,"tv":1633.37,"id":8257852}],"tv":1733.38}]}
{"op":"mcm","clk":"1011490590","pt":1580656453765,"mc":[{"id":"1.168223929","rc":[{"batb":[[0,1.6,64.2],[1,1.58,72.26],[2,1.47,87.97]],"batl":[[0,1.71,42.01],[1,1.68,0],[2,1.71,0]],"ltp":1.66,"tv":1633.37,"id":8257852}]}]}
{"op":"mcm","clk":"1011491670","pt":1580656458209,"mc":[{"id":"1.168223929","rc":[{"batb":[[2,1.48,436.33]],"batl":[[1,1.74,374.42],[2,1.76,384.67]],"ltp":1.66,"tv":1633.37,"id":8257852}]}]}
{"op":"mcm","clk":"1011493142","pt":1580656464002,"mc":[{"id":"1.168223929","rc":[{"batb":[[0,2.38,30.25],[1,2.34,36.9],[2,1.01,15.51]],"ltp":2.3,"tv":100.0,"id":8444055},{"batb":[[0,1.58,72.26],[1,1.48,436.33],[2,1.47,462.86]],"ltp":1.66,"tv":1633.37,"id":8257852}]}]}
{"op":"mcm","clk":"1011493222","pt":1580656464376,"mc":[{"id":"1.168223929","rc":[{"batb":[[0,2.34,36.9],[1,1.01,15.51],[2,1.01,0]],"ltp":2.3,"tv":100.0,"id":8444055},{"batb":[[0,1.48,436.33],[1,1.47,462.86],[2,1.01,15.51]],"batl":[[0,1.74,374.42],[1,1.76,384.67],[2,1.76,0]],"ltp":1.66,"tv":1633.37,"id":8257852}]}]}
{"op":"mcm","clk":"1011493952","pt":1580656467034,"mc":[{"id":"1.168223929","rc":[{"batb":[[1,2.32,37.37],[2,1.01,15.51]],"ltp":2.3,"tv":100.0,"id":8444055},{"batb":[[0,1.48,523.51]],"ltp":1.66,"tv":1633.37,"id":8257852}]}]}
{"op":"mcm","clk":"1011494138","pt":1580656467697,"mc":[{"id":"1.168223929","rc":[{"batb":[[0,2.32,37.37],[1,1.01,15.51],[2,1.01,0]],"ltp":2.3,"tv":100.0,"id":8444055},{"batb":[[0,1.48,87.18],[1,1.01,15.51],[2,1.01,0]],"ltp":1.66,"tv":1633.37,"id":8257852}]}]}
{"op":"mcm","clk":"1011494829","pt":1580656470634,"mc":[{"id":"1.168223929","rc":[{"batb":[[0,1.57,447.14],[1,1.56,295.64],[2,1.48,87.18]],"batl":[[0,1.63,358.18],[1,1.64,242.98]],"ltp":1.66,"tv":1633.37,"id":8257852}]}]}
{"op":"mcm","clk":"1011495369","pt":1580656472815,"mc":[{"id":"1.168223929","rc":[{"batb":[[0,1.48,87.18],[1,1.01,15.51],[2,1.48,0]],"ltp":1.66,"tv":1633.37,"id":8257852}]}]}
{"op":"mcm","clk":"1011496083","pt":1580656475726,"mc":[{"id":"1.168223929","rc":[{"batb":[[0,1.48,523.51],[1,1.47,374.89],[2,1.01,15.51]],"batl":[[0,1.74,374.42],[1,1.76,384.67]],"ltp":1.66,"tv":1633.37,"id":8257852}]}]}
{"op":"mcm","clk":"1011497961","pt":1580656483128,"mc":[{"id":"1.168223929","rc":[{"batb":[[0,1.48,87.18],[1,1.01,15.51],[2,1.01,0]],"ltp":1.66,"tv":1633.37,"id":8257852}]}]}
{"op":"mcm","clk":"1011498699","pt":1580656486227,"mc":[{"id":"1.168223929","rc":[{"batb":[[0,1.67,367.98],[1,1.66,234.76],[2,1.48,87.18]],"batl":[[0,1.74,374.42],[1,1.76,384.67]],"ltp":1.66,"tv":1633.37,"id":8257852}]}]}
{"op":"mcm","clk":"1011498935","pt":1580656487248,"mc":[{"id":"1.168223929","rc":[{"batb":[[1,2.2,43.83],[2,1.01,15.51]],"ltp":2.3,"tv":100.0,"id":8444055},{"batb":[[0,1.69,53.03],[1,1.67,367.98],[2,1.66,234.76]],"ltp":1.66,"tv":1633.37,"id":8257852}]}]}
{"op":"mcm","clk":"1011499372","pt":1580656489037,"mc":[{"id":"1.168223929","rc":[{"batb":[[1,2.26,32.77],[2,2.2,43.83]],"batl":[[0,2.56,26.89]],"ltp":2.3,"tv":100.0,"id":8444055},{"batl":[[2,1.79,42.01]],"ltp":1.66,"tv":1633.37,"id":8257852}]}]}
{"op":"mcm","clk":"1011500381","pt":1580656493076,"mc":[{"id":"1.168223929","rc":[{"batl":[[0,2.56,38.06]],"ltp":2.3,"tv":100.0,"id":8444055}]}]}
{"op":"mcm","clk":"1011501848","pt":1580656499059,"mc":[{"id":"1.168223929","rc":[{"batl":[[0,2.56,26.89]],"ltp":2.3,"tv":100.0,"id":8444055}]}]}
{"op":"mcm","clk":"1011502053","pt":1580656499863,"mc":[{"id":"1.168223929","rc":[{"batb":[[0,2.26,32.77],[1,2.2,43.83],[2,1.01,15.51]],"ltp":2.3,"tv":100.0,"id":8444055},{"batb":[[0,1.64,65.54],[1,1.57,68.61],[2,1.01,15.51]],"batl":[[0,1.79,42.01],[1,1.76,0],[2,1.79,0]],"ltp":1.66,"tv":1633.37,"id":8257852}]}]}
{"op":"mcm","clk":"1011502443","pt":1580656501253,"mc":[{"id":"1.168223929","rc":[{"batb":[[0,2.2,43.83],[1,1.01,15.51],[2,1.01,0]],"ltp":2.3,"tv":100.0,"id":8444055},{"batb":[[0,1.57,68.61],[1,1.01,15.51],[2,1.01,0]],"ltp":1.66,"tv":1633.37,"id":8257852}]}]}
{"op":"mcm","clk":"1011502706","pt":1580656502266,"mc":[{"id":"1.168223929","rc":[{"batb":[[0,1.57,414.26],[1,1.56,295.18],[2,1.01,15.51]],"batl":[[0,1.8,217.5],[1,1.82,345.77]],"ltp":1.66,"tv":1633.37,"id":8257852}]}]}
{"op":"mcm","clk":"1011502766","pt":1580656502434,"mc":[{"id":"1.168223929","rc":[{"batb":[[0,1.57,68.61],[1,1.01,15.51],[2,1.01,0]],"ltp":1.66,"tv":1633.37,"id":8257852}]}]}
{"op":"mcm","clk":"1011503764","pt":1580656506261,"mc":[{"id":"1.168223929","rc":[{"batb":[[0,1.65,339.75],[1,1.64,245.1],[2,1.57,68.61]],"batl":[[0,1.71,247.13],[1,1.73,407.77]],"ltp":1.66,"tv":1633.37,"id":8257852}]}]}
{"op":"mcm","clk":"1011504532","pt":1580656509354,"mc":[{"id":"1.168223929","rc":[{"batb":[[0,1.57,68.61],[1,1.01,15.51],[2,1.57,0]],"ltp":1.66,"tv":1633.37,"id":8257852}]}]}
{"op":"mcm","clk":"1011505177","pt":1580656512317,"mc":[{"id":"1.168223929","rc":[{"batb":[[0,1.57,414.26],[1,1.56,295.18],[2,1.01,15.51]],"batl":[[0,1.8,217.5],[1,1.82,345.77]],"ltp":1.66,"tv":1633.37,"id":8257852}]}]}
{"op":"mcm","clk":"1011505560","pt":1580656513870,"mc":[{"id":"1.168223929","rc":[{"batb":[[0,1.57,68.61],[1,1.01,15.51],[2,1.01,0]],"ltp":1.66,"tv":1633.37,"id":8257852}]}]}
{"op":"mcm","clk":"1011506369","pt":1580656517266,"mc":[{"id":"1.168223929","rc":[{"batb":[[1,2.16,36.13],[2,1.01,15.51]],"batl":[[0,2.44,28.57]],"ltp":2.3,"tv":100.0,"id":8444055},{"batb":[[0,1.73,390.97],[1,1.71,420.64],[2,1.7,59.65]],"batl":[[2,1.86,42.01]],"ltp":1.66,"tv":1633.37,"id":8257852}]}]}
{"op":"mcm","clk":"1011506527","pt":1580656517865,"mc":[{"id":"1.168223929","rc":[{"batb":[[2,2.12,49.1]],"ltp":2.3,"tv":100.0,"id":8444055},{"batb":[[0,1.76,45.87],[1,1.73,390.97],[2,1.71,420.64]],"ltp":1.66,"tv":1633.37,"id":8257852}]}]}
{"op":"mcm","clk":"1011508771","pt":1580656526807,"mc":[{"id":"1.168223929","rc":[{"trd":[[2.32,8.84]],"ltp":2.32,"tv":108.84,"id":8444055},{"trd":[[1.76,11.66]],"batb":[[0,1.76,34.21]],"ltp":1.76,"tv":1645.03,"id":8257852}],"tv":1753.88}]}
{"op":"mcm","clk":"1011509830","pt":1580656530986,"mc":[{"id":"1.168223929","rc":[{"batb":[[0,2.16,36.13],[1,2.12,49.1],[2,1.01,15.51]],"ltp":2.32,"tv":108.84,"id":8444055},{"batb":[[0,1.7,59.65],[1,1.67,55.55],[2,1.01,15.51]],"batl":[[0,1.86,42.01],[1,1.82,0],[2,1.86,0]],"ltp":1.76,"tv":1645.03,"id":8257852}]}]}
{"op":"mcm","clk":"1011510441","pt":1580656533090,"mc":[{"id":"1.168223929","rc":[{"batb":[[0,2.12,49.1],[1,1.01,15.51],[2,1.01,0]],"ltp":2.32,"tv":108.84,"id":8444055},{"batb":[[0,1.67,55.55],[1,1.01,15.51],[2,1.01,0]],"ltp":1.76,"tv":1645.03,"id":8257852}]}]}
{"op":"mcm","clk":"1011510694","pt":1580656534096,"mc":[{"id":"1.168223929","rc":[{"batb":[[0,2.12,48.78]],"ltp":2.32,"tv":108.84,"id":8444055},{"batb":[[0,1.66,55.94]],"ltp":1.76,"tv":1645.03,"id":8257852}]}]}
{"op":"mcm","clk":"1011511329","pt":1580656536700,"mc":[{"id":"1.168223929","rc":[{"batb":[[0,1.72,280.96],[1,1.7,428.81],[2,1.66,55.94]],"batl":[[0,1.79,342.57],[1,1.81,351.49]],"ltp":1.76,"tv":1645.03,"id":8257852}]}]}
{"op":"mcm","clk":"1011512562","pt":1580656541620,"mc":[{"id":"1.168223929","rc":[{"batb":[[0,1.66,55.94],[1,1.01,15.51],[2,1.66,0]],"ltp":1.76,"tv":1645.03,"id":8257852}]}]}
{"op":"mcm","clk":"1011513412","pt":1580656545122,"mc":[{"id":"1.168223929","rc":[{"batb":[[0,1.66,365.78],[1,1.65,239.71],[2,1.01,15.51]],"ltp":1.76,"tv":1645.03,"id":8257852}]}]}
{"op":"mcm","clk":"1011514122","pt":1580656547992,"mc":[{"id":"1.168223929","rc":[{"batl":[[0,1.72,253.17],[1,1.74,400]],"ltp":1.76,"tv":1645.03,"id":8257852}]}]}
{"op":"mcm","clk":"1011514375","pt":1580656549021,"mc":[{"id":"1.168223929","rc":[{"batb":[[0,2.38,35.17],[1,2.22,42.33],[2,1.01,15.51]],"ltp":2.32,"tv":108.84,"id":8444055},{"batb":[[2,1.53,75.06]],"ltp":1.76,"tv":1645.03,"id":8257852}]}]}
{"op":"mcm","clk":"1011514689","pt":1580656550228,"mc":[{"id":"1.168223929","rc":[{"batb":[[1,2.28,32.77],[2,2.22,42.33]],"batl":[[0,2.58,26.05]],"ltp":2.32,"tv":108.84,"id":8444055},{"batb":[[2,1.63,66.38]],"batl":[[2,1.77,42.01]],"ltp":1.76,"tv":1645.03,"id":8257852}]}]}
{"op":"mcm","clk":"1011518018","pt":1580656563133,"mc":[{"id":"1.168223929","rc":[{"batb":[[0,2.28,32.77],[1,2.22,42.33],[2,1.01,15.51]],"ltp":2.32,"tv":108.84,"id":8444055},{"batb":[[0,1.63,66.38],[1,1.53,75.06],[2,1.01,15.51]],"batl":[[0,1.77,42.01],[1,1.74,0],[2,1.77,0]],"ltp":1.76,"tv":1645.03,"id":8257852}]}]}
{"op":"mcm","clk":"1011518501","pt":1580656565062,"mc":[{"id":"1.168223929","rc":[{"batb":[[0,2.22,42.33],[1,1.01,15.51],[2,1.01,0]],"ltp":2.32,"tv":108.84,"id":8444055},{"batb":[[0,1.53,75.06],[1,1.01,15.51],[2,1.01,0]],"ltp":1.76,"tv":1645.03,"id":8257852}]}]}
{"op":"mcm","clk":"1011518598","pt":1580656565444,"mc":[{"id":"1.168223929","rc":[{"batb":[[0,1.54,389.37],[1,1.53,393.57],[2,1.01,15.51]],"batl":[[0,1.8,224.76],[1,1.82,345.74]],"ltp":1.76,"tv":1645.03,"id":8257852}]}]}
{"op":"mcm","clk":"1011519143","pt":1580656567576,"mc":[{"id":"1.168223929","rc":[{"batb":[[0,1.53,75.06],[1,1.01,15.51],[2,1.01,0]],"ltp":1.76,"tv":1645.03,"id":8257852}]}]}
{"op":"mcm","clk":"1011520039","pt":1580656571243,"mc":[{"id":"1.168223929","rc":[{"batb":[[0,1.63,438.88],[1,1.62,256.61],[2,1.53,75.06]],"batl":[[0,1.7,414.5],[1,1.72,414.86]],"ltp":1.76,"tv":1645.03,"id":8257852}]}]}
{"op":"mcm","clk":"1011520515","pt":1580656573159,"mc":[{"id":"1.168223929","rc":[{"batb":[[1,1.86,398.62],[2,1.01,15.51]],"ltp":2.32,"tv":108.84,"id":8444055},{"batb":[[0,1.53,75.06],[1,1.44,436.18],[2,1.01,15.51]],"ltp":1.76,"tv":1645.03,"id":8257852}]}]}
{"op":"mcm","clk":"1011521181","pt":1580656575870,"mc":[{"id":"1.168223929","rc":[{"batb":[[0,1.54,389.37],[1,1.53,393.57],[2,1.44,436.18]],"batl":[[0,1.8,224.76],[1,1.82,345.74]],"ltp":1.76,"tv":1645.03,"id":8257852}]}]}
{"op":"mcm","clk":"1011524981","pt":1580656591894,"mc":[{"id":"1.168223929","rc":[{"batb":[[0,1.53,75.06],[1,1.44,436.18],[2,1.01,15.51]],"ltp":1.76,"tv":1645.03,"id":8257852}]}]}
{"op":"mcm","clk":"1011525309","pt":1580656593243,"mc":[{"id":"1.168223929","rc":[{"batb":[[1,1.01,15.51],[2,1.01,0]],"ltp":1.76,"tv":1645.03,"id":8257852}]}]}
{"op":"mcm","clk":"1011525753","pt":1580656595268,"mc":[{"id":"1.168223929","rc":[{"batb":[[1,2.14,47.68],[2,1.86,398.62]],"ltp":2.32,"tv":108.84,"id":8444055},{"batb":[[0,1.75,47.37],[1,1.73,383.51],[2,1.71,420.62]],"ltp":1.76,"tv":1645.03,"id":8257852}]}]}
{"op":"mcm","clk":"1011525966","pt":1580656596175,"mc":[{"id":"1.168223929","rc":[{"batb":[[1,2.18,35.29],[2,2.14,47.68]],"batl":[[0,2.44,28.57]],"ltp":2.32,"tv":108.84,"id":8444055},{"batl":[[2,1.85,42.01]],"ltp":1.76,"tv":1645.03,"id":8257852}]}]}
{"op":"mcm","clk":"1011529826","pt":1580656613247,"mc":[{"id":"1.168223929","rc":[{"batb":[[0,2.14,47.68],[1,1.86,398.62],[2,1.01,15.51]],"ltp":2.32,"tv":108.84,"id":8444055},{"batb":[[0,1.65,57.36],[1,1.52,425.49],[2,1.01,15.51]],"ltp":1.76,"tv":1645.03,"id":8257852}]}]}
{"op":"mcm","clk":"1011530542","pt":1580656616246,"mc":[{"id":"1.168223929","rc":[{"batb":[[0,1.66,400.93],[1,1.65,297.33],[2,1.52,425.49]],"batl":[[0,1.85,307.49],[1,1.87,317.25]],"ltp":1.76,"tv":1645.03,"id":8257852}]}]}
{"op":"mcm","clk":"1011533233","pt":1580656628047,"mc":[{"id":"1.168223929","rc":[{"batb":[[0,1.65,57.36],[1,1.52,425.49],[2,1.01,15.51]],"ltp":1.76,"tv":1645.03,"id":8257852}]}]}
{"op":"mcm","clk":"1011533343","pt":1580656628539,"mc":[{"id":"1.168223929","rc":[{"batb":[[1,1.01,15.51],[2,1.01,0]],"ltp":2.32,"tv":108.84,"id":8444055}]}]}
{"op":"mcm","clk":"1011533705","pt":1580656630255,"mc":[{"id":"1.168223929","rc":[{"batb":[[0,1.77,386.8],[1,1.75,388.71],[2,1.65,57.36]],"ltp":1.76,"tv":1645.03,"id":8257852}]}]}
{"op":"mcm","clk":"1011533950","pt":1580656631226,"mc":[{"id":"1.168223929","rc":[{"batb":[[1,1.9,34.15],[2,1.01,15.51]],"ltp":2.32,"tv":108.84,"id":8444055},{"batb":[[0,1.81,42.41],[1,1.77,386.8],[2,1.75,388.71]],"ltp":1.76,"tv":1645.03,"id":8257852}]}]}
{"op":"mcm","clk":"1011534113","pt":1580656631924,"mc":[{"id":"1.168223929","rc":[{"batb":[[1,2.1,37.81],[2,1.9,34.15]],"batl":[[0,2.34,31.09]],"ltp":2.32,"tv":108.84,"id":8444055},{"batl":[[2,1.91,42.01]],"ltp":1.76,"tv":1645.03,"id":8257852}]}]}
{"op":"mcm","clk":"1011540673","pt":1580656660078,"mc":[{"id":"1.168223929","rc":[{"batb":[[0,2.1,37.81],[1,1.9,34.15],[2,1.7,409.32]],"ltp":2.32,"tv":108.84,"id":8444055},{"batb":[[0,1.74,56.29],[1,1.71,50.67],[2,1.52,425.49]],"batl":[[0,1.91,42.01],[1,1.87,0],[2,1.91,0]],"ltp":1.76,"tv":1645.03,"id":8257852}]}]}
{"op":"mcm","clk":"1011540847","pt":1580656660785,"mc":[{"id":"1.168223929","rc":[{"batb":[[0,1.9,34.15],[1,1.7,409.32],[2,1.01,15.51]],"ltp":2.32,"tv":108.84,"id":8444055},{"batb":[[0,1.71,50.67],[1,1.52,425.49],[2,1.01,15.51]],"ltp":1.76,"tv":1645.03,"id":8257852}]}]}
{"op":"mcm","clk":"1011541482","pt":1580656663231,"mc":[{"id":"1.168223929","rc":[{"batb":[[0,1.91,33.75]],"ltp":2.32,"tv":108.84,"id":8444055},{"batb":[[1,1.69,354.8],[2,1.67,456.72]],"ltp":1.76,"tv":1645.03,"id":8257852}]}]}
{"op":"mcm","clk":"1011541918","pt":1580656665208,"mc":[{"id":"1.168223929","rc":[{"batb":[[1,1.01,15.51],[2,1.01,0]],"ltp":2.32,"tv":108.84,"id":8444055}]}]}
{"op":"mcm","clk":"1011542077","pt":1580656666016,"mc":[{"id":"1.168223929","rc":[{"batl":[[0,1.76,338.8],[1,1.78,370.93]],"ltp":1.76,"tv":1645.03,"id":8257852}]}]}
{"op":"mcm","clk":"1011542312","pt":1580656667064,"mc":[{"id":"1.168223929","rc":[{"batb":[[0,2.3,38.79],[1,2.06,52.72],[2,1.01,15.51]],"ltp":2.32,"tv":108.84,"id":8444055}]}]}
{"op":"mcm","clk":"1011542491","pt":1580656667877,"mc":[{"id":"1.168223929","rc":[{"batb":[[1,2.2,34.45],[2,2.06,52.72]],"batl":[[0,2.5,27.73]],"ltp":2.32,"tv":108.84,"id":8444055},{"batb":[[2,1.68,61.33]],"batl":[[2,1.82,42.01]],"ltp":1.76,"tv":1645.03,"id":8257852}]}]}
{"op":"mcm","clk":"1011545558","pt":1580656681136,"mc":[{"id":"1.168223929","rc":[{"batb":[[0,2.06,52.72],[1,1.77,402.27],[2,1.01,15.51]],"ltp":2.32,"tv":108.84,"id":8444055},{"batb":[[0,1.64,58.22],[1,1.52,425.49],[2,1.01,15.51]],"ltp":1.76,"tv":1645.03,"id":8257852}]}]}
{"op":"mcm","clk":"1011546182","pt":1580656683803,"mc":[{"id":"1.168223929","rc":[{"batb":[[1,1.63,465.42],[2,1.62,256.7]],"ltp":1.76,"tv":1645.03,"id":8257852}]}]}
{"op":"mcm","clk":"1011546480","pt":1580656685037,"mc":[{"id":"1.168223929","rc":[{"batb":[[1,1.01,15.51],[2,1.01,0]],"ltp":2.32,"tv":108.84,"id":8444055}]}]}
{"op":"mcm","clk":"1011546684","pt":1580656686032,"mc":[{"id":"1.168223929","rc":[{"batl":[[0,1.7,389.59],[1,1.72,415]],"ltp":1.76,"tv":1645.03,"id":8257852}]}]}
{"op":"mcm","clk":"1011546906","pt":1580656686950,"mc":[{"id":"1.168223929","rc":[{"batb":[[0,2.42,33.6],[1,2.24,41.78],[2,1.01,15.51]],"ltp":2.32,"tv":108.84,"id":8444055}]}]}
{"op":"mcm","clk":"1011547115","pt":1580656687752,"mc":[{"id":"1.168223929","rc":[{"batb":[[1,2.3,31.93],[2,2.24,41.78]],"batl":[[0,2.62,25.21]],"ltp":2.32,"tv":108.84,"id":8444055},{"batb":[[1,1.63,531.8]],"batl":[[2,1.76,42.01]],"ltp":1.76,"tv":1645.03,"id":8257852}]}]}
{"op":"mcm","clk":"1011550116","pt":1580656700059,"mc":[{"id":"1.168223929","rc":[{"batb":[[0,2.3,31.93],[1,2.24,41.78],[2,1.86,398.62]],"ltp":2.32,"tv":108.84,"id":8444055},{"batb":[[0,1.63,66.38],[1,1.6,63.97],[2,1.44,436.18]],"batl":[[0,1.76,42.01],[1,1.72,0],[2,1.76,0]],"ltp":1.76,"tv":1645.03,"id":8257852}]}]}
{"op":"mcm","clk":"1011550332","pt":1580656700867,"mc":[{"id":"1.168223929","rc":[{"batb":[[0,2.24,41.78],[1,1.86,398.62],[2,1.01,15.51]],"ltp":2.32,"tv":108.84,"id":8444055},{"batb":[[0,1.6,63.97],[1,1.44,436.18],[2,1.01,15.51]],"ltp":1.76,"tv":1645.03,"id":8257852}]}]}
{"op":"mcm","clk":"1011550893","pt":1580656703237,"mc":[{"id":"1.168223929","rc":[{"batb":[[0,1.6,457.4],[1,1.59,274.83],[2,1.44,436.18]],"batl":[[0,1.78,360.97],[1,1.8,357.72]],"ltp":1.76,"tv":1645.03,"id":8257852}]}]}
{"op":"mcm","clk":"1011551512","pt":1580656706080,"mc":[{"id":"1.168223929","rc":[{"batb":[[0,1.6,63.97],[1,1.44,436.18],[2,1.01,15.51]],"ltp":1.76,"tv":1645.03,"id":8257852}]}]}
{"op":"mcm","clk":"1011552221","pt":1580656709104,"mc":[{"id":"1.168223929","rc":[{"batb":[[0,1.6,457.4],[1,1.59,274.83],[2,1.44,436.18]],"batl":[[0,1.66,321.4],[1,1.68,449.86]],"ltp":1.76,"tv":1645.03,"id":8257852}]}]}
{"op":"mcm","clk":"1011552434","pt":1580656710220,"mc":[{"id":"1.168223929","rc":[{"batb":[[0,2.52,30.14],[1,2.38,34.78],[2,2.36,30.25]],"batl":[[0,2.72,24.37]],"ltp":2.32,"tv":108.84,"id":8444055},{"batb":[[1,1.59,345.41],[2,1.58,67.82]],"batl":[[2,1.72,42.01]],"ltp":1.76,"tv":1645.03,"id":8257852}]}]}
{"op":"mcm","clk":"1011555965","pt":1580656725961,"mc":[{"id":"1.168223929","rc":[{"batb":[[0,2.38,34.78],[1,2.36,30.25],[2,1.86,398.62]],"ltp":2.32,"tv":108.84,"id":8444055},{"batb":[[0,1.59,70.58],[1,1.58,67.04],[2,1.44,436.18]],"batl":[[0,1.72,42.01],[1,1.68,0],[2,1.72,0]],"ltp":1.76,"tv":1645.03,"id":8257852}]}]}
{"op":"mcm","clk":"1011556241","pt":1580656727184,"mc":[{"id":"1.168223929","rc":[{"batb":[[1,1.86,398.62],[2,1.01,15.51]],"ltp":2.32,"tv":108.84,"id":8444055},{"batb":[[0,1.58,67.04],[1,1.44,436.18],[2,1.01,15.51]],"ltp":1.76,"tv":1645.03,"id":8257852}]}]}
{"op":"mcm","clk":"1011557174","pt":1580656731127,"mc":[{"id":"1.168223929","rc":[{"batb":[[0,1.61,301.08],[1,1.6,268.18],[2,1.58,67.04]],"batl":[[0,1.67,381.94],[1,1.69,440.52]],"ltp":1.76,"tv":1645.03,"id":8257852}]}]}
{"op":"mcm","clk":"1011557639","pt":1580656733117,"mc":[{"id":"1.168223929","rc":[{"batb":[[0,1.58,67.04],[1,1.44,436.18],[2,1.01,15.51]],"ltp":1.76,"tv":1645.03,"id":8257852}]}]}
{"op":"mcm","clk":"1011558332","pt":1580656736121,"mc":[{"id":"1.168223929","rc":[{"batb":[[0,1.58,564.05],[1,1.57,288.78],[2,1.44,436.18]],"batl":[[0,1.7,331.91],[1,1.72,415.39]],"ltp":1.76,"tv":1645.03,"id":8257852}]}]}
{"op":"mcm","clk":"1011558605","pt":1580656737237,"mc":[{"id":"1.168223929","rc":[{"batb":[[0,1.58,67.04],[1,1.44,436.18],[2,1.01,15.51]],"ltp":1.76,"tv":1645.03,"id":8257852}]}]}
{"op":"mcm","clk":"1011559322","pt":1580656740214,"mc":[{"id":"1.168223929","rc":[{"batb":[[0,1.64,275],[1,1.63,250.42],[2,1.58,67.04]],"ltp":1.76,"tv":1645.03,"id":8257852}]}]}
{"op":"mcm","clk":"1011559541","pt":1580656741212,"mc":[{"id":"1.168223929","rc":[{"batb":[[1,2.2,43.43],[2,1.86,398.62]],"ltp":2.32,"tv":108.84,"id":8444055},{"batb":[[0,1.67,55.71],[1,1.64,275],[2,1.63,250.42]],"ltp":1.76,"tv":1645.03,"id":8257852}]}]}
{"op":"mcm","clk":"1011559650","pt":1580656741750,"mc":[{"id":"1.168223929","rc":[{"batb":[[1,2.32,31.09],[2,2.2,43.43]],"batl":[[0,2.62,25.21]],"ltp":2.32,"tv":108.84,"id":8444055},{"batb":[[2,1.63,316.8]],"batl":[[2,1.76,42.01]],"ltp":1.76,"tv":1645.03,"id":8257852}]}]}
{"op":"mcm","clk":"1011563068","pt":1580656757183,"mc":[{"id":"1.168223929","rc":[{"batb":[[1,1.63,66.38],[2,1.62,60.82]],"batl":[[0,1.76,42.01],[1,1.72,0],[2,1.76,0]],"ltp":1.76,"tv":1645.03,"id":8257852}]}]}
{"op":"mcm","clk":"1011563130","pt":1580656757476,"mc":[{"id":"1.168223929","rc":[{"batb":[[0,2.32,31.09],[1,2.2,43.43],[2,1.86,398.62]],"ltp":2.32,"tv":108.84,"id":8444055},{"batb":[[0,1.63,66.38],[1,1.62,60.82],[2,1.44,436.18]],"ltp":1.76,"tv":1645.03,"id":8257852}]}]}
{"op":"mcm","clk":"1011563442","pt":1580656758800,"mc":[{"id":"1.168223929","rc":[{"batb":[[0,2.2,43.43],[1,1.86,398.62],[2,1.01,15.51]],"ltp":2.32,"tv":108.84,"id":8444055},{"batb":[[0,1.62,60.82],[1,1.44,436.18],[2,1.01,15.51]],"ltp":1.76,"tv":1645.03,"id":8257852}]}]}
{"op":"mcm","clk":"1011563775","pt":1580656760268,"mc":[{"id":"1.168223929","rc":[{"batb":[[1,1.61,240.23],[2,1.6,267.95]],"batl":[[0,1.78,393.97],[1,1.8,357.66]],"ltp":1.76,"tv":1645.03,"id":8257852}]}]}
{"op":"mcm","clk":"1011564315","pt":1580656762703,"mc":[{"id":"1.168223929","rc":[{"batl":[[0,1.67,439.41],[1,1.69,440.16]],"ltp":1.76,"tv":1645.03,"id":8257852}]}]}
{"op":"mcm","clk":"1011564657","pt":1580656764186,"mc":[{"id":"1.168223929","rc":[{"batb":[[0,2.46,31.94],[1,2.4,29.41],[2,2.28,39.42]],"batl":[[0,2.72,24.37]],"ltp":2.32,"tv":108.84,"id":8444055},{"batl":[[2,1.71,42.01]],"ltp":1.76,"tv":1645.03,"id":8257852}]}]}
{"op":"mcm","clk":"1011571458","pt":1580656794242,"mc":[{"id":"1.168223929","rc":[{"batb":[[1,1.6,267.95],[2,1.59,70.58]],"batl":[[0,1.71,42.01],[1,1.69,0],[2,1.71,0]],"ltp":1.76,"tv":1645.03,"id":8257852}]}]}
{"op":"mcm","clk":"1011572080","pt":1580656797222,"mc":[{"id":"1.168223929","rc":[{"batb":[[1,1.6,429.35],[2,1.59,345.91]],"batl":[[0,1.66,289.49],[1,1.68,450.69],[2,1.71,42.01]],"ltp":1.76,"tv":1645.03,"id":8257852}]}]}
{"op":"mcm","clk":"1011572214","pt":1580656797860,"mc":[{"id":"1.168223929","rc":[{"batb":[[1,1.6,335.8]],"ltp":1.76,"tv":1645.03,"id":8257852}]}]}
{"op":"mcm","clk":"1011572968","pt":1580656801257,"mc":[{"id":"1.168223929","rc":[{"batb":[[0,2.48,31.47],[2,2.3,38.87]],"ltp":2.32,"tv":108.84,"id":8444055},{"batl":[[0,1.66,379.74]],"ltp":1.76,"tv":1645.03,"id":8257852}]}]}
{"op":"mcm","clk":"1011577762","pt":1580656822327,"mc":[{"id":"1.168223929","rc":[{"batb":[[1,1.59,345.91],[2,1.48,85.37]],"batl":[[0,1.66,234.34],[1,1.71,42.01],[2,1.71,0]],"ltp":1.76,"tv":1645.03,"id":8257852}]}]}
{"op":"mcm","clk":"1011578420","pt":1580656825171,"mc":[{"id":"1.168223929","rc":[{"batb":[[1,1.59,536.65],[2,1.58,283.06]],"batl":[[0,1.65,288.28],[1,1.66,234.34],[2,1.71,42.01]],"ltp":1.76,"tv":1645.03,"id":8257852}]}]}
{"op":"mcm","clk":"1011582784","pt":1580656844204,"mc":[{"id":"1.168223929","rc":[{"batb":[[1,1.59,70.58],[2,1.48,85.37]],"batl":[[0,1.71,42.01],[1,1.66,0],[2,1.71,0]],"ltp":1.76,"tv":1645.03,"id":8257852}]}]}
{"op":"mcm","clk":"1011582935","pt":1580656844817,"mc":[{"id":"1.168223929","rc":[{"batb":[[0,2.3,38.4],[1,1.86,398.62],[2,1.01,15.51]],"ltp":2.32,"tv":108.84,"id":8444055},{"batb":[[0,1.48,85.37],[1,1.44,436.18],[2,1.01,15.51]],"ltp":1.76,"tv":1645.03,"id":8257852}]}]}
{"op":"mcm","clk":"1011583491","pt":1580656847234,"mc":[{"id":"1.168223929","rc":[{"batb":[[1,1.47,432.56],[2,1.46,388.02]],"batl":[[0,1.74,393],[1,1.76,386.34]],"ltp":1.76,"tv":1645.03,"id":8257852}]}]}
{"op":"mcm","clk":"1011583609","pt":1580656847736,"mc":[{"id":"1.168223929","rc":[{"batb":[[1,1.44,436.18],[2,1.01,15.51]],"ltp":1.76,"tv":1645.03,"id":8257852}]}]}
{"op":"mcm","clk":"1011584110","pt":1580656849915,"mc":[{"id":"1.168223929","rc":[{"batb":[[0,1.57,294.66],[1,1.56,296.42],[2,1.48,85.37]],"batl":[[0,1.62,260.98],[1,1.63,249.99]],"ltp":1.76,"tv":1645.03,"id":8257852}]}]}
{"op":"mcm","clk":"1011585128","pt":1580656854210,"mc":[{"id":"1.168223929","rc":[{"batb":[[0,1.48,85.37],[1,1.44,436.18],[2,1.01,15.51]],"ltp":1.76,"tv":1645.03,"id":8257852}]}]}
{"op":"mcm","clk":"1011585721","pt":1580656856926,"mc":[{"id":"1.168223929","rc":[{"batb":[[1,1.47,432.56],[2,1.46,388.02]],"batl":[[0,1.74,393],[1,1.76,386.34]],"ltp":1.76,"tv":1645.03,"id":8257852}]}]}
{"op":"mcm","clk":"1011586873","pt":1580656862168,"mc":[{"id":"1.168223929","rc":[{"batb":[[1,1.44,436.18],[2,1.01,15.51]],"ltp":1.76,"tv":1645.03,"id":8257852}]}]}
{"op":"mcm","clk":"1011587649","pt":1580656865257,"mc":[{"id":"1.168223929","rc":[{"batb":[[0,1.67,354.96],[1,1.66,235.7],[2,1.48,85.37]],"ltp":1.76,"tv":1645.03,"id":8257852}]}]}
{"op":"mcm","clk":"1011587786","pt":1580656865813,"mc":[{"id":"1.168223929","rc":[{"batb":[[1,2.26,32.77],[2,2.18,45.16]],"batl":[[0,2.54,26.89]],"ltp":2.32,"tv":108.84,"id":8444055},{"batb":[[0,1.7,51.77],[1,1.67,354.96],[2,1.66,235.7]],"batl":[[2,1.8,42.01]],"ltp":1.76,"tv":1645.03,"id":8257852}]}]}
{"op":"mcm","clk":"1011591154","pt":1580656880066,"mc":[{"id":"1.168223929","rc":[{"batb":[[0,2.26,32.77],[1,2.18,45.16],[2,1.86,398.62]],"ltp":2.32,"tv":108.84,"id":8444055},{"batb":[[0,1.65,63.85],[1,1.58,67.9],[2,1.44,436.18]],"batl":[[0,1.8,42.01],[1,1.76,0],[2,1.8,0]],"ltp":1.76,"tv":1645.03,"id":8257852}]}]}
{"op":"mcm","clk":"1011591345","pt":1580656881016,"mc":[{"id":"1.168223929","rc":[{"batb":[[0,2.18,45.16],[1,1.86,398.62],[2,1.01,15.51]],"ltp":2.32,"tv":108.84,"id":8444055},{"batb":[[0,1.58,67.9],[1,1.44,436.18],[2,1.01,15.51]],"ltp":1.76,"tv":1645.03,"id":8257852}]}]}
{"op":"mcm","clk":"1011591791","pt":1580656882977,"mc":[{"id":"1.168223929","rc":[{"batb":[[1,1.56,475.39],[2,1.55,304.7]],"batl":[[0,1.81,364.59],[1,1.83,340.75]],"ltp":1.76,"tv":1645.03,"id":8257852}]}]}
{"op":"mcm","clk":"1011593024","pt":1580656888168,"mc":[{"id":"1.168223929","rc":[{"batb":[[1,1.44,436.18],[2,1.01,15.51]],"ltp":1.76,"tv":1645.03,"id":8257852}]}]}
{"op":"mcm","clk":"1011593424","pt":1580656889872,"mc":[{"id":"1.168223929","rc":[{"batb":[[1,1.01,15.51],[2,1.01,0]],"ltp":1.76,"tv":1645.03,"id":8257852}]}]}
{"op":"mcm","clk":"1011593743","pt":1580656891272,"mc":[{"id":"1.168223929","rc":[{"batb":[[0,1.73,425.41],[1,1.71,422.36],[2,1.58,67.9]],"ltp":1.76,"tv":1645.03,"id":8257852}]}]}
{"op":"mcm","clk":"1011593943","pt":1580656892191,"mc":[{"id":"1.168223929","rc":[{"batb":[[1,2.14,36.13],[2,2.1,50.67]],"batl":[[0,2.42,29.41]],"ltp":2.32,"tv":108.84,"id":8444055},{"batb":[[0,1.78,44.53],[1,1.73,425.41],[2,1.71,481.17]],"batl":[[2,1.87,42.01]],"ltp":1.76,"tv":1645.03,"id":8257852}]}]}
{"op":"mcm","clk":"1011597250","pt":1580656906923,"mc":[{"id":"1.168223929","rc":[{"batb":[[0,2.1,50.67],[1,1.86,398.62],[2,1.01,15.51]],"ltp":2.32,"tv":108.84,"id":8444055},{"batb":[[0,1.67,55.16],[1,1.52,425.49],[2,1.01,15.51]],"ltp":1.76,"tv":1645.03,"id":8257852}]}]}
{"op":"mcm","clk":"1011597927","pt":1580656909825,"mc":[{"id":"1.168223929","rc":[{"batb":[[1,1.66,281.32],[2,1.65,240.65]],"batl":[[0,1.85,214.2],[1,1.87,318.67]],"ltp":1.76,"tv":1645.03,"id":8257852}]}]}
{"op":"mcm","clk":"1011598160","pt":1580656910802,"mc":[{"id":"1.168223929","rc":[{"batb":[[1,1.52,425.49],[2,1.01,15.51]],"ltp":1.76,"tv":1645.03,"id":8257852}]}]}
{"op":"mcm","clk":"1011599114","pt":1580656915060,"mc":[{"id":"1.168223929","rc":[{"batb":[[0,1.72,302.79],[1,1.7,430.57],[2,1.67,55.16]],"batl":[[0,1.79,327.15],[1,1.81,353.01]],"ltp":1.76,"tv":1645.03,"id":8257852}]}]}
{"op":"mcm","clk":"1011599365","pt":1580656916190,"mc":[{"id":"1.168223929","rc":[{"batb":[[0,1.67,55.16],[1,1.52,425.49],[2,1.01,15.51]],"ltp":1.76,"tv":1645.03,"id":8257852}]}]}
{"op":"mcm","clk":"1011600128","pt":1580656919266,"mc":[{"id":"1.168223929","rc":[{"batb":[[1,1.66,284.21],[2,1.65,240.65]],"batl":[[0,1.85,211.61],[1,1.87,318.66]],"ltp":1.76,"tv":1645.03,"id":8257852}]}]}
{"op":"mcm","clk":"1011600338","pt":1580656920062,"mc":[{"id":"1.168223929","rc":[{"batb":[[1,1.01,15.51],[2,1.01,0]],"ltp":2.32,"tv":108.84,"id":8444055},{"batb":[[1,1.52,425.49],[2,1.01,15.51]],"ltp":1.76,"tv":1645.03,"id":8257852}]}]}
{"op":"mcm","clk":"1011600813","pt":1580656922051,"mc":[{"id":"1.168223929","rc":[{"batb":[[1,2.08,38.65],[2,1.01,15.51]],"batl":[[0,2.34,31.09]],"ltp":2.32,"tv":108.84,"id":8444055},{"batb":[[0,1.78,302.84],[1,1.76,437.04],[2,1.67,55.16]],"batl":[[2,1.92,42.01]],"ltp":1.76,"tv":1645.03,"id":8257852}]}]}
{"op":"mcm","clk":"1011601019","pt":1580656922958,"mc":[{"id":"1.168223929","rc":[{"batb":[[2,2.04,54.29]],"ltp":2.32,"tv":108.84,"id":8444055},{"batb":[[0,1.84,40.05],[1,1.78,302.84],[2,1.76,483.15]],"ltp":1.76,"tv":1645.03,"id":8257852}]}]}
{"op":"mcm","clk":"1011604067","pt":1580656936073,"mc":[{"id":"1.168223929","rc":[{"batb":[[0,2.08,38.65],[1,2.04,54.29],[2,1.7,409.32]],"ltp":2.32,"tv":108.84,"id":8444055},{"batb":[[0,1.76,100.72],[1,1.52,425.49],[2,1.01,15.51]],"batl":[[0,1.92,42.01],[1,1.87,0],[2,1.92,0]],"ltp":1.76,"tv":1645.03,"id":8257852}]}]}
{"op":"mcm","clk":"1011604256","pt":1580656936878,"mc":[{"id":"1.168223929","rc":[{"batb":[[0,2.04,54.29],[1,1.7,409.32],[2,1.01,15.51]],"ltp":2.32,"tv":108.84,"id":8444055},{"batb":[[0,1.76,46.11]],"ltp":1.76,"tv":1645.03,"id":8257852}]}]}
{"op":"mcm","clk":"1011604778","pt":1580656939089,"mc":[{"id":"1.168223929","rc":[{"batb":[[1,1.73,413.86],[2,1.71,422.28]],"batl":[[0,1.88,277.72],[1,1.9,303.19]],"ltp":1.76,"tv":1645.03,"id":8257852}]}]}
{"op":"mcm","clk":"1011606238","pt":1580656945205,"mc":[{"id":"1.168223929","rc":[{"batb":[[1,1.52,425.49],[2,1.01,15.51]],"ltp":1.76,"tv":1645.03,"id":8257852}]}]}
{"op":"mcm","clk":"1011606444","pt":1580656946179,"mc":[{"id":"1.168223929","rc":[{"batb":[[1,1.01,15.51],[2,1.01,0]],"ltp":1.76,"tv":1645.03,"id":8257852}]}]}
{"op":"mcm","clk":"1011606814","pt":1580656948024,"mc":[{"id":"1.168223929","rc":[{"batb":[[1,2.02,41.17],[2,1.7,409.32]],"batl":[[0,2.26,32.77]],"ltp":2.32,"tv":108.84,"id":8444055},{"batb":[[0,1.8,52.09],[1,1.76,46.11],[2,1.01,15.51]],"batl":[[0,1.88,233.2],[2,1.96,42.01]],"ltp":1.76,"tv":1645.03,"id":8257852}]}]}
{"op":"mcm","clk":"1011607109","pt":1580656949217,"mc":[{"id":"1.168223929","rc":[{"batb":[[2,1.81,39.66]],"ltp":2.32,"tv":108.84,"id":8444055},{"trd":[[1.88,75.06]],"batb":[[1,1.78,44.77]],"batl":[[0,1.88,195.67]],"ltp":1.88,"tv":1720.09,"id":8257852}],"tv":1828.94}]}
{"op":"mcm","clk":"1011607193","pt":1580656949591,"mc":[{"id":"1.168223929","rc":[{"batb":[[2,1.58,416.47]],"ltp":1.88,"tv":1720.09,"id":8257852}]}]}
{"op":"mcm","clk":"1011607479","pt":1580656950854,"mc":[{"id":"1.168223929","rc":[{"batb":[[0,1.81,227.66],[1,1.8,52.09],[2,1.79,361.25]],"ltp":1.88,"tv":1720.09,"id":8257852}]}]}
{"op":"mcm","clk":"1011607806","pt":1580656952166,"mc":[{"id":"1.168223929","rc":[{"batb":[[0,1.81,240.32]],"ltp":1.88,"tv":1720.09,"id":8257852}]}]}
{"op":"mcm","clk":"1011612473","pt":1580656972842,"mc":[{"id":"1.168223929","rc":[{"batb":[[0,1.81,39.66],[1,1.7,409.32],[2,1.01,15.51]],"ltp":2.32,"tv":108.84,"id":8444055},{"batb":[[0,1.78,44.77],[1,1.58,416.47],[2,1.01,15.51]],"ltp":1.88,"tv":1720.09,"id":8257852}]}]}
{"op":"mcm","clk":"1011613201","pt":1580656976242,"mc":[{"id":"1.168223929","rc":[{"batb":[[0,1.83,38.63]],"ltp":2.32,"tv":108.84,"id":8444055},{"batb":[[0,1.76,45.95],[1,1.71,433.65],[2,1.69,439.97]],"batl":[[0,2.12,199.13],[1,2.14,213.12]],"ltp":1.88,"tv":1720.09,"id":8257852}]}]}
{"op":"mcm","clk":"1011614994","pt":1580656984473,"mc":[{"id":"1.168223929","rc":[{"batb":[[1,1.58,416.47],[2,1.01,15.51]],"ltp":1.88,"tv":1720.09,"id":8257852}]}]}
{"op":"mcm","clk":"1011615244","pt":1580656985660,"mc":[{"id":"1.168223929","rc":[{"batb":[[1,1.01,15.51],[2,1.01,0]],"ltp":2.32,"tv":108.84,"id":8444055},{"batb":[[1,1.01,15.51],[2,1.01,0]],"ltp":1.88,"tv":1720.09,"id":8257852}]}]}
{"op":"mcm","clk":"1011615757","pt":1580656988109,"mc":[{"id":"1.168223929","rc":[{"batb":[[0,1.89,267.04],[1,1.87,313.32],[2,1.83,89.04]],"batl":[[0,1.97,216.13],[1,1.99,263.28]],"ltp":2.32,"tv":108.84,"id":8444055},{"batb":[[0,2.1,52.64],[1,1.93,34.54],[2,1.76,45.95]],"batl":[[0,2.2,34.45]],"ltp":1.88,"tv":1720.09,"id":8257852}]}]}
{"op":"mcm","clk":"1011615939","pt":1580656988913,"mc":[{"id":"1.168223929","rc":[{"batb":[[2,1.01,15.51]],"ltp":1.88,"tv":1720.09,"id":8257852}]}]}
{"op":"mcm","clk":"1011616107","pt":1580656989814,"mc":[{"id":"1.168223929","rc":[{"batb":[[2,1.7,409.32]],"ltp":1.88,"tv":1720.09,"id":8257852}]}]}
{"op":"mcm","clk":"1011618866","pt":1580657001217,"mc":[{"id":"1.168223929","rc":[{"batb":[[0,1.83,50.41],[1,1.57,65.15],[2,1.55,420.5]],"ltp":2.32,"tv":108.84,"id":8444055},{"batb":[[0,1.93,34.54],[1,1.7,409.32],[2,1.01,15.51]],"ltp":1.88,"tv":1720.09,"id":8257852}]}]}
{"op":"mcm","clk":"1011619305","pt":1580657002953,"mc":[{"id":"1.168223929","rc":[{"batb":[[0,1.57,65.15],[1,1.55,420.5],[2,1.01,15.51]],"ltp":2.32,"tv":108.84,"id":8444055}]}]}
{"op":"mcm","clk":"1011619557","pt":1580657004133,"mc":[{"id":"1.168223929","rc":[{"batb":[[1,1.92,34.86],[2,1.7,409.32]],"ltp":1.88,"tv":1720.09,"id":8257852}]}]}
{"op":"mcm","clk":"1011619763","pt":1580657005019,"mc":[{"id":"1.168223929","rc":[{"batb":[[0,1.57,64.52]],"ltp":2.32,"tv":108.84,"id":8444055},{"batb":[[0,1.92,34.86],[1,1.7,409.32],[2,1.01,15.51]],"ltp":1.88,"tv":1720.09,"id":8257852}]}]}
{"op":"mcm","clk":"1011620238","pt":1580657007227,"mc":[{"id":"1.168223929","rc":[{"batb":[[0,1.83,247.79],[1,1.81,347.94],[2,1.57,64.52]],"batl":[[0,1.91,329.08],[1,1.93,288.45]],"ltp":2.32,"tv":108.84,"id":8444055}]}]}
{"op":"mcm","clk":"1011620674","pt":1580657009120,"mc":[{"id":"1.168223929","rc":[{"batb":[[0,1.57,64.52],[1,1.55,420.5],[2,1.01,15.51]],"ltp":2.32,"tv":108.84,"id":8444055}]}]}
{"op":"mcm","clk":"1011620824","pt":1580657009728,"mc":[{"id":"1.168223929","rc":[{"trd":[[1.92,69.69]],"batb":[[0,1.7,409.32],[1,1.01,15.51],[2,1.01,0]],"batl":[[0,1.92,9.37]],"ltp":1.92,"tv":1789.78,"id":8257852}],"tv":1898.63}]}
{"op":"mcm","clk":"1011621377","pt":1580657012147,"mc":[{"id":"1.168223929","rc":[{"batb":[[0,1.62,252.53],[1,1.61,262.1],[2,1.57,64.52]],"batl":[[0,2.18,362.57],[1,2.2,197.39]],"ltp":2.32,"tv":108.84,"id":8444055}]}]}
{"op":"mcm","clk":"1011621949","pt":1580657014729,"mc":[{"id":"1.168223929","rc":[{"trd":[[2.08,8.33]],"ltp":2.08,"tv":117.17,"id":8444055},{"trd":[[1.92,78.71]],"batl":[[0,1.92,0.35]],"ltp":1.92,"tv":1798.8,"id":8257852}],"tv":1915.98}]}
{"op":"mcm","clk":"1011622229","pt":1580657015914,"mc":[{"id":"1.168223929","rc":[{"trd":[[2.08,8.65]],"ltp":2.08,"tv":117.49,"id":8444055},{"trd":[[1.92,79.06]],"ltp":1.92,"tv":1799.15,"id":8257852}],"tv":1916.64}]}
{"op":"mcm","clk":"1011625031","pt":1580657028852,"mc":[{"id":"1.168223929","rc":[{"batb":[[0,1.01,15.51],[1,1.01,0]],"ltp":1.92,"tv":1799.15,"id":8257852}]}]}
{"op":"mcm","clk":"1011625297","pt":1580657030143,"mc":[{"id":"1.168223929","rc":[{"batl":[[0,1.68,402.98],[1,1.7,431.93]],"ltp":2.08,"tv":117.49,"id":8444055}]}]}
{"op":"mcm","clk":"1011625510","pt":1580657031144,"mc":[{"id":"1.168223929","rc":[{"batb":[[2,1.58,63.57]],"ltp":2.08,"tv":117.49,"id":8444055},{"batb":[[0,2.56,30.37],[1,2.24,44.14],[2,1.01,15.51]],"ltp":1.92,"tv":1799.15,"id":8257852}]}]}
{"op":"mcm","clk":"1011625728","pt":1580657032056,"mc":[{"id":"1.168223929","rc":[{"batb":[[2,1.59,70.58]],"batl":[[2,1.73,42.01]],"ltp":2.08,"tv":117.49,"id":8444055},{"batb":[[1,2.38,30.25],[2,2.24,44.14]],"batl":[[0,2.72,24.37]],"ltp":1.92,"tv":1799.15,"id":8257852}]}]}
{"op":"mcm","clk":"1011629456","pt":1580657049065,"mc":[{"id":"1.168223929","rc":[{"batb":[[0,1.38,448.45],[1,1.35,124.4],[2,1.01,15.51]],"ltp":2.08,"tv":117.49,"id":8444055},{"batb":[[0,2.24,44.14],[1,1.97,394.86],[2,1.01,15.51]],"ltp":1.92,"tv":1799.15,"id":8257852}]}]}
{"op":"mcm","clk":"1011630328","pt":1580657053174,"mc":[{"id":"1.168223929","rc":[{"batb":[[1,1.35,122.82]],"ltp":2.08,"tv":117.49,"id":8444055},{"batb":[[0,2.22,44.53]],"ltp":1.92,"tv":1799.15,"id":8257852}]}]}
{"op":"mcm","clk":"1011630755","pt":1580657055167,"mc":[{"id":"1.168223929","rc":[{"batb":[[0,1.56,397.37],[1,1.55,303.01],[2,1.38,448.45]],"batl":[[0,1.62,437.2],[1,1.63,248.08]],"ltp":2.08,"tv":117.49,"id":8444055}]}]}
{"op":"mcm","clk":"1011631404","pt":1580657057996,"mc":[{"id":"1.168223929","rc":[{"batb":[[0,1.38,448.45],[1,1.35,122.82],[2,1.01,15.51]],"ltp":2.08,"tv":117.49,"id":8444055}]}]}
{"op":"mcm","clk":"1011632079","pt":1580657061190,"mc":[{"id":"1.168223929","rc":[{"batb":[[1,1.37,640.08],[2,1.36,533.26]],"batl":[[0,1.86,336.31],[1,1.88,312.53]],"ltp":2.08,"tv":117.49,"id":8444055}]}]}
{"op":"mcm","clk":"1011633865","pt":1580657069231,"mc":[{"id":"1.168223929","rc":[{"batb":[[0,1.37,640.08],[1,1.36,533.26],[2,1.35,122.82]],"ltp":2.08,"tv":117.49,"id":8444055},{"batb":[[1,1.01,15.51],[2,1.01,0]],"ltp":1.92,"tv":1799.15,"id":8257852}]}]}
{"op":"mcm","clk":"1011634256","pt":1580657071094,"mc":[{"id":"1.168223929","rc":[{"batl":[[0,1.41,339.96],[1,1.42,424.44]],"ltp":2.08,"tv":117.49,"id":8444055},{"batb":[[0,3.5,33.52],[1,3,49.25],[2,2.22,44.53]],"ltp":1.92,"tv":1799.15,"id":8257852}]}]}
{"op":"mcm","clk":"1011634515","pt":1580657072140,"mc":[{"id":"1.168223929","rc":[{"batb":[[1,1.36,649.21]],"batl":[[2,1.45,42.01]],"ltp":2.08,"tv":117.49,"id":8444055},{"batb":[[1,3.2,18.48],[2,3,49.25]],"batl":[[0,3.75,15.12]],"ltp":1.92,"tv":1799.15,"id":8257852}]}]}
{"op":"mcm","clk":"1011637514","pt":1580657085034,"mc":[{"id":"1.168223929","rc":[{"batb":[[0,1.36,115.95],[1,1.35,122.82],[2,1.25,505.09]],"batl":[[0,1.45,42.01],[1,1.42,0],[2,1.45,0]],"ltp":2.08,"tv":117.49,"id":8444055}]}]}
{"op":"mcm","clk":"1011637686","pt":1580657085845,"mc":[{"id":"1.168223929","rc":[{"batb":[[1,1.25,505.09],[2,1.21,226.53]],"ltp":2.08,"tv":117.49,"id":8444055},{"batb":[[0,3.2,18.48],[1,3,49.25],[2,2.38,382.3]],"ltp":1.92,"tv":1799.15,"id":8257852}]}]}
{"op":"mcm","clk":"1011637934","pt":1580657086947,"mc":[{"id":"1.168223929","rc":[{"batb":[[0,1.25,505.09],[1,1.21,226.53],[2,1.01,15.51]],"ltp":2.08,"tv":117.49,"id":8444055},{"batb":[[0,3,49.25],[1,2.38,382.3],[2,1.01,15.51]],"ltp":1.92,"tv":1799.15,"id":8257852}]}]}
{"op":"mcm","clk":"1011638244","pt":1580657088245,"mc":[{"id":"1.168223929","rc":[{"batb":[[1,1.22,1079.75],[2,1.21,1256.55]],"batl":[[0,1.52,495.22],[1,1.53,312.54]],"ltp":2.08,"tv":117.49,"id":8444055}]}]}
{"op":"mcm","clk":"1011638696","pt":1580657090165,"mc":[{"id":"1.168223929","rc":[{"batb":[[1,1.21,226.53],[2,1.01,15.51]],"ltp":2.08,"tv":117.49,"id":8444055}]}]}
{"op":"mcm","clk":"1011639406","pt":1580657093255,"mc":[{"id":"1.168223929","rc":[{"batb":[[0,1.47,376.6],[1,1.46,385.35],[2,1.21,226.53]],"ltp":2.08,"tv":117.49,"id":8444055}]}]}
{"op":"mcm","clk":"1011639630","pt":1580657094261,"mc":[{"id":"1.168223929","rc":[{"batb":[[2,1.45,93.26]],"batl":[[2,1.55,42.01]],"ltp":2.08,"tv":117.49,"id":8444055},{"batb":[[1,2.82,22.69],[2,2.5,32.18]],"batl":[[0,3.25,18.48]],"ltp":1.92,"tv":1799.15,"id":8257852}]}]}
{"op":"mcm","clk":"1011643028","pt":1580657108942,"mc":[{"id":"1.168223929","rc":[{"batb":[[0,1.31,477.51],[1,1.21,218.26],[2,1.01,15.51]],"ltp":2.08,"tv":117.49,"id":8444055},{"batb":[[0,2.5,32.18],[1,2.38,382.3],[2,1.01,15.51]],"ltp":1.92,"tv":1799.15,"id":8257852}]}]}
{"op":"mcm","clk":"1011643657","pt":1580657111952,"mc":[{"id":"1.168223929","rc":[{"batl":[[0,1.7,265.67],[1,1.72,416.07]],"ltp":2.08,"tv":117.49,"id":8444055},{"batb":[[0,2.52,31.79]],"ltp":1.92,"tv":1799.15,"id":8257852}]}]}
{"op":"mcm","clk":"1011644121","pt":1580657113757,"mc":[{"id":"1.168223929","rc":[{"batb":[[0,1.21,218.26],[1,1.01,15.51],[2,1.01,0]],"ltp":2.08,"tv":117.49,"id":8444055},{"batb":[[1,1.01,15.51],[2,1.01,0]],"ltp":1.92,"tv":1799.15,"id":8257852}]}]}
{"op":"mcm","clk":"1011644450","pt":1580657115069,"mc":[{"id":"1.168223929","rc":[{"batb":[[0,1.64,346.1],[1,1.63,250.89],[2,1.21,218.26]],"ltp":2.08,"tv":117.49,"id":8444055}]}]}
{"op":"mcm","clk":"1011644713","pt":1580657116204,"mc":[{"id":"1.168223929","rc":[{"batb":[[2,1.6,130.79]],"batl":[[2,1.73,42.01]],"ltp":2.08,"tv":117.49,"id":8444055},{"batb":[[1,2.36,30.25],[2,1.99,61.06]],"batl":[[0,2.68,24.37]],"ltp":1.92,"tv":1799.15,"id":8257852}]}]}
{"op":"mcm","clk":"1011647103","pt":1580657127011,"mc":[{"id":"1.168223929","rc":[{"batb":[[0,1.44,436.18],[1,1.22,215.2],[2,1.01,15.51]],"ltp":2.08,"tv":117.49,"id":8444055},{"batb":[[0,1.99,61.06],[1,1.86,398.62],[2,1.01,15.51]],"ltp":1.92,"tv":1799.15,"id":8257852}]}]}
{"op":"mcm","clk":"1011647479","pt":1580657128770,"mc":[{"id":"1.168223929","rc":[{"batb":[[0,1.22,215.2],[1,1.01,15.51],[2,1.01,0]],"ltp":2.08,"tv":117.49,"id":8444055},{"batb":[[1,1.01,15.51],[2,1.01,0]],"ltp":1.92,"tv":1799.15,"id":8257852}]}]}
{"op":"mcm","clk":"1011648194","pt":1580657131992,"mc":[{"id":"1.168223929","rc":[{"batb":[[0,1.54,306.23],[1,1.53,318.21],[2,1.22,215.2]],"batl":[[0,1.59,325.25],[1,1.6,265.59]],"ltp":2.08,"tv":117.49,"id":8444055}]}]}
{"op":"mcm","clk":"1011648447","pt":1580657133178,"mc":[{"id":"1.168223929","rc":[{"batb":[[2,1.34,465.43]],"ltp":2.08,"tv":117.49,"id":8444055},{"batb":[[0,2.04,394.09],[1,1.99,61.06],[2,1.01,15.51]],"ltp":1.92,"tv":1799.15,"id":8257852}]}]}
{"op":"mcm","clk":"1011649015","pt":1580657136069,"mc":[{"id":"1.168223929","rc":[{"batb":[[0,1.34,465.43],[1,1.22,215.2],[2,1.01,15.51]],"ltp":2.08,"tv":117.49,"id":8444055}]}]}
{"op":"mcm","clk":"1011649172","pt":1580657136796,"mc":[{"id":"1.168223929","rc":[{"batb":[[0,1.22,215.2],[1,1.01,15.51],[2,1.01,0]],"ltp":2.08,"tv":117.49,"id":8444055},{"batb":[[0,1.99,61.06],[1,1.01,15.51],[2,1.01,0]],"ltp":1.92,"tv":1799.15,"id":8257852}]}]}
{"op":"mcm","clk":"1011650138","pt":1580657141226,"mc":[{"id":"1.168223929","rc":[{"batb":[[1,1.93,213.12],[2,1.91,293.13]],"batl":[[0,2.02,337.64],[1,2.04,244.81]],"ltp":1.92,"tv":1799.15,"id":8257852}]}]}
{"op":"mcm","clk":"1011650374","pt":1580657142065,"mc":[{"id":"1.168223929","rc":[{"batb":[[0,1.91,33.44],[1,1.89,47.05],[2,1.58,64.13]],"batl":[[0,2.1,37.81]],"ltp":2.08,"tv":117.49,"id":8444055},{"batb":[[2,1.91,338.5]],"batl":[[2,2.12,36.97]],"ltp":1.92,"tv":1799.15,"id":8257852}]}]}
{"op":"mcm","clk":"1011650585","pt":1580657143083,"mc":[{"id":"1.168223929","rc":[{"batb":[[2,1.62,415.43]],"ltp":2.08,"tv":117.49,"id":8444055}]}]}
{"op":"mcm","clk":"1011653329","pt":1580657156077,"mc":[{"id":"1.168223929","rc":[{"batb":[[0,1.89,47.05],[1,1.62,415.43],[2,1.58,64.13]],"ltp":2.08,"tv":117.49,"id":8444055},{"batb":[[0,1.91,45.37],[1,1.8,42.57],[2,1.62,415.43]],"batl":[[0,2.12,36.97],[1,2.04,0],[2,2.12,0]],"ltp":1.92,"tv":1799.15,"id":8257852}]}]}
{"op":"mcm","clk":"1011653530","pt":1580657156950,"mc":[{"id":"1.168223929","rc":[{"batb":[[0,1.62,415.43],[1,1.58,64.13],[2,1.01,15.51]],"ltp":2.08,"tv":117.49,"id":8444055},{"batb":[[0,1.8,42.57],[1,1.62,415.43],[2,1.01,15.51]],"ltp":1.92,"tv":1799.15,"id":8257852}]}]}
{"op":"mcm","clk":"1011653920","pt":1580657159044,"mc":[{"id":"1.168223929","rc":[{"batb":[[1,1.74,238.31],[2,1.72,413.27]],"batl":[[0,2.58,150.6],[1,2.62,247.77]],"ltp":1.92,"tv":1799.15,"id":8257852}]}]}
{"op":"mcm","clk":"1011654879","pt":1580657163841,"mc":[{"id":"1.168223929","rc":[{"batb":[[0,1.58,64.13],[1,1.01,15.51],[2,1.01,0]],"ltp":2.08,"tv":117.49,"id":8444055}]}]}
{"op":"mcm","clk":"1011655373","pt":1580657166257,"mc":[{"id":"1.168223929","rc":[{"batb":[[0,2.14,47.52],[1,2.1,37.81],[2,1.88,35.25]],"batl":[[0,2.38,30.25]],"ltp":2.08,"tv":117.49,"id":8444055},{"batb":[[1,1.74,294.6]],"batl":[[0,1.81,347.36],[1,1.83,340.76],[2,1.91,42.01]],"ltp":1.92,"tv":1799.15,"id":8257852}]}]}
{"op":"mcm","clk":"1011657819","pt":1580657176636,"mc":[{"id":"1.168223929","rc":[{"batb":[[1,1.74,238.31]],"ltp":1.92,"tv":1799.15,"id":8257852}]}]}
{"op":"mcm","clk":"1011658147","pt":1580657178153,"mc":[{"id":"1.168223929","rc":[{"batb":[[0,2.1,37.81],[1,1.88,35.25],[2,1.74,404.28]],"ltp":2.08,"tv":117.49,"id":8444055},{"batb":[[0,1.7,51.85],[1,1.52,425.49],[2,1.01,15.51]],"batl":[[0,1.91,42.01],[1,1.83,0],[2,1.91,0]],"ltp":1.92,"tv":1799.15,"id":8257852}]}]}
{"op":"mcm","clk":"1011658290","pt":1580657178872,"mc":[{"id":"1.168223929","rc":[{"batb":[[0,1.88,35.25],[1,1.74,404.28],[2,1.01,15.51]],"ltp":2.08,"tv":117.49,"id":8444055}]}]}
{"op":"mcm","clk":"1011658695","pt":1580657180773,"mc":[{"id":"1.168223929","rc":[{"batb":[[1,1.65,312.42],[2,1.64,246.05]],"batl":[[0,2.04,338.71],[1,2.06,237.96]],"ltp":1.92,"tv":1799.15,"id":8257852}]}]}
{"op":"mcm","clk":"1011659279","pt":1580657183262,"mc":[{"id":"1.168223929","rc":[{"batb":[[1,1.52,425.49],[2,1.01,15.51]],"ltp":1.92,"tv":1799.15,"id":8257852}]}]}
{"op":"mcm","clk":"1011659752","pt":1580657185619,"mc":[{"id":"1.168223929","rc":[{"batb":[[0,1.77,381.59],[1,1.75,390.06],[2,1.7,51.85]],"batl":[[0,1.85,317.36],[1,1.87,318.42]],"ltp":1.92,"tv":1799.15,"id":8257852}]}]}
{"op":"mcm","clk":"1011660089","pt":1580657187196,"mc":[{"id":"1.168223929","rc":[{"batb":[[0,1.7,51.85],[1,1.52,425.49],[2,1.01,15.51]],"ltp":1.92,"tv":1799.15,"id":8257852}]}]}
{"op":"mcm","clk":"1011660674","pt":1580657189787,"mc":[{"id":"1.168223929","rc":[{"batb":[[1,1.65,312.42],[2,1.64,246.05]],"batl":[[0,2.04,338.71],[1,2.06,237.96]],"ltp":1.92,"tv":1799.15,"id":8257852}]}]}
{"op":"mcm","clk":"1011662193","pt":1580657196922,"mc":[{"id":"1.168223929","rc":[{"batb":[[1,1.52,425.49],[2,1.01,15.51]],"ltp":1.92,"tv":1799.15,"id":8257852}]}]}
{"op":"mcm","clk":"1011662482","pt":1580657198177,"mc":[{"id":"1.168223929","rc":[{"batb":[[1,1.01,15.51],[2,1.01,0]],"ltp":2.08,"tv":117.49,"id":8444055},{"batb":[[1,1.01,15.51],[2,1.01,0]],"ltp":1.92,"tv":1799.15,"id":8257852}]}]}
{"op":"mcm","clk":"1011662930","pt":1580657200195,"mc":[{"id":"1.168223929","rc":[{"batb":[[0,1.89,47.05],[1,1.88,35.25],[2,1.01,15.51]],"ltp":2.08,"tv":117.49,"id":8444055},{"batb":[[0,1.94,323.19],[1,1.92,288.4],[2,1.7,51.85]],"batl":[[2,2.12,36.97]],"ltp":1.92,"tv":1799.15,"id":8257852}]}]}
{"op":"mcm","clk":"1011663146","pt":1580657201218,"mc":[{"id":"1.168223929","rc":[{"batb":[[2,1.56,67.27]],"batl":[[0,2.1,37.81]],"ltp":2.08,"tv":117.49,"id":8444055},{"batb":[[0,2.02,57.91],[1,1.94,323.19],[2,1.92,288.4]],"ltp":1.92,"tv":1799.15,"id":8257852}]}]}
{"op":"mcm","clk":"1011663231","pt":1580657201604,"mc":[{"id":"1.168223929","rc":[{"batb":[[2,1.58,416.47]],"ltp":2.08,"tv":117.49,"id":8444055}]}]}
{"op":"mcm","clk":"1011666432","pt":1580657216253,"mc":[{"id":"1.168223929","rc":[{"batb":[[1,1.58,416.47],[2,1.56,67.27]],"ltp":2.08,"tv":117.49,"id":8444055},{"batb":[[0,1.91,45.37],[1,1.83,40.36],[2,1.67,409.76]],"batl":[[0,2.12,36.97],[1,2.06,0],[2,2.12,0]],"ltp":1.92,"tv":1799.15,"id":8257852}]}]}
{"op":"mcm","clk":"1011666694","pt":1580657217271,"mc":[{"id":"1.168223929","rc":[{"batb":[[0,1.58,416.47],[1,1.56,67.27],[2,1.01,15.51]],"ltp":2.08,"tv":117.49,"id":8444055},{"batb":[[0,1.83,40.36],[1,1.67,409.76],[2,1.01,15.51]],"ltp":1.92,"tv":1799.15,"id":8257852}]}]}
{"op":"mcm","clk":"1011667081","pt":1580657219089,"mc":[{"id":"1.168223929","rc":[{"batb":[[1,1.75,287.76],[2,1.73,405.34]],"batl":[[0,2.62,210.03],[1,2.66,238.55]],"ltp":1.92,"tv":1799.15,"id":8257852}]}]}
{"op":"mcm","clk":"1011672146","pt":1580657241577,"mc":[{"id":"1.168223929","rc":[{"batb":[[0,1.56,67.27],[1,1.01,15.51],[2,1.01,0]],"ltp":2.08,"tv":117.49,"id":8444055}]}]}
{"op":"mcm","clk":"1011672456","pt":1580657243120,"mc":[{"id":"1.168223929","rc":[{"trd":[[1.83,80.72]],"batb":[[0,1.75,287.76],[1,1.73,405.34],[2,1.01,15.51]],"batl":[[0,1.82,240.56],[1,1.84,335.12]],"ltp":1.83,"tv":1879.87,"id":8257852}],"tv":1997.37}]}
{"op":"mcm","clk":"1011672680","pt":1580657244179,"mc":[{"id":"1.168223929","rc":[{"batb":[[0,2.1,50.2],[1,2.08,38.65],[2,1.85,37.14]],"batl":[[0,2.36,30.25]],"ltp":2.08,"tv":117.49,"id":8444055},{"batb":[[0,1.75,343.21],[2,1.72,49.18]],"batl":[[2,1.92,42.01]],"ltp":1.83,"tv":1879.87,"id":8257852}]}]}
{"op":"mcm","clk":"1011678530","pt":1580657270927,"mc":[{"id":"1.168223929","rc":[{"batb":[[1,1.85,37.14],[2,1.7,409.32]],"ltp":2.08,"tv":117.49,"id":8444055},{"batb":[[0,1.75,287.76]],"batl":[[2,1.92,0]],"ltp":1.83,"tv":1879.87,"id":8257852}]}]}
{"op":"mcm","clk":"1011678786","pt":1580657272124,"mc":[{"id":"1.168223929","rc":[{"batb":[[0,1.72,49.18],[1,1.55,420.5],[2,1.01,15.51]],"ltp":1.83,"tv":1879.87,"id":8257852}]}]}
{"op":"mcm","clk":"1011678978","pt":1580657272944,"mc":[{"id":"1.168223929","rc":[{"batb":[[0,1.85,37.14],[1,1.7,409.32],[2,1.01,15.51]],"ltp":2.08,"tv":117.49,"id":8444055}]}]}
{"op":"mcm","clk":"1011679492","pt":1580657275130,"mc":[{"id":"1.168223929","rc":[{"batb":[[1,1.66,315],[2,1.65,240.7]],"batl":[[0,2.06,329.96],[1,2.08,231.38]],"ltp":1.83,"tv":1879.87,"id":8257852}]}]}
{"op":"mcm","clk":"1011679737","pt":1580657276226,"mc":[{"id":"1.168223929","rc":[{"batb":[[0,1.86,36.43]],"ltp":2.08,"tv":117.49,"id":8444055},{"batb":[[0,1.69,49.96],[1,1.55,420.5],[2,1.01,15.51]],"ltp":1.83,"tv":1879.87,"id":8257852}]}]}
{"op":"mcm","clk":"1011680411","pt":1580657279077,"mc":[{"id":"1.168223929","rc":[{"batb":[[0,1.79,269.47],[1,1.77,375.13],[2,1.69,49.96]],"batl":[[0,1.86,226.12],[1,1.88,313.35]],"ltp":1.83,"tv":1879.87,"id":8257852}]}]}
{"op":"mcm","clk":"1011680937","pt":1580657281272,"mc":[{"id":"1.168223929","rc":[{"batb":[[0,1.69,49.96],[1,1.55,420.5],[2,1.01,15.51]],"ltp":1.83,"tv":1879.87,"id":8257852}]}]}
{"op":"mcm","clk":"1011681532","pt":1580657284198,"mc":[{"id":"1.168223929","rc":[{"batb":[[1,1.66,315],[2,1.65,240.7]],"batl":[[0,2.06,329.96],[1,2.08,231.38]],"ltp":1.83,"tv":1879.87,"id":8257852}]}]}
{"op":"mcm","clk":"1011685158","pt":1580657300926,"mc":[{"id":"1.168223929","rc":[{"batb":[[1,1.55,420.5],[2,1.01,15.51]],"ltp":1.83,"tv":1879.87,"id":8257852}]}]}
{"op":"mcm","clk":"1011685387","pt":1580657302028,"mc":[{"id":"1.168223929","rc":[{"batb":[[1,1.01,15.51],[2,1.01,0]],"ltp":2.08,"tv":117.49,"id":8444055},{"batb":[[1,1.01,15.51],[2,1.01,0]],"ltp":1.83,"tv":1879.87,"id":8257852}]}]}
{"op":"mcm","clk":"1011685882","pt":1580657304221,"mc":[{"id":"1.168223929","rc":[{"batb":[[0,2.28,39.89],[1,2.26,32.77],[2,2.12,49.02]],"batl":[[0,2.56,26.89]],"ltp":2.08,"tv":117.49,"id":8444055},{"batb":[[1,1.66,315.02],[2,1.65,304.57]],"batl":[[0,1.72,253.61],[1,1.74,401.74],[2,1.8,42.01]],"ltp":1.83,"tv":1879.87,"id":8257852}]}]}
{"op":"mcm","clk":"1011695892","pt":1580657348703,"mc":[{"id":"1.168223929","rc":[{"batb":[[0,2.28,39.42],[2,2.12,48.47]],"ltp":2.08,"tv":117.49,"id":8444055}]}]}
{"op":"mcm","clk":"1011705830","pt":1580657394993,"mc":[{"id":"1.168223929","rc":[{"batb":[[0,2.12,48.47],[1,1.82,401.24],[2,1.01,15.51]],"ltp":2.08,"tv":117.49,"id":8444055},{"batb":[[0,1.52,73.41],[1,1.46,435.7],[2,1.01,15.51]],"ltp":1.83,"tv":1879.87,"id":8257852}]}]}
{"op":"mcm","clk":"1011706768","pt":1580657399444,"mc":[{"id":"1.168223929","rc":[{"batb":[[0,1.63,286.58],[1,1.62,257.19],[2,1.52,73.41]],"batl":[[0,1.69,350.62],[1,1.71,425.33]],"ltp":1.83,"tv":1879.87,"id":8257852}]}]}
{"op":"mcm","clk":"1011707328","pt":1580657401703,"mc":[{"id":"1.168223929","rc":[{"batl":[[0,1.69,253.34]],"ltp":1.83,"tv":1879.87,"id":8257852}]}]}
{"op":"mcm","clk":"1011708053","pt":1580657404882,"mc":[{"id":"1.168223929","rc":[{"batb":[[0,1.52,73.41],[1,1.46,435.7],[2,1.01,15.51]],"ltp":1.83,"tv":1879.87,"id":8257852}]}]}
{"op":"mcm","clk":"1011708839","pt":1580657408067,"mc":[{"id":"1.168223929","rc":[{"batb":[[0,1.52,327.05],[1,1.51,336.03],[2,1.46,435.7]],"batl":[[0,1.83,351.53],[1,1.85,328.91]],"ltp":1.83,"tv":1879.87,"id":8257852}]}]}
{"op":"mcm","clk":"1011709865","pt":1580657412791,"mc":[{"id":"1.168223929","rc":[{"batb":[[0,1.52,73.41],[1,1.46,435.7],[2,1.01,15.51]],"ltp":1.83,"tv":1879.87,"id":8257852}]}]}
{"op":"mcm","clk":"1011710433","pt":1580657415256,"mc":[{"id":"1.168223929","rc":[{"batb":[[1,1.01,15.51],[2,1.01,0]],"ltp":2.08,"tv":117.49,"id":8444055},{"batb":[[1,1.01,15.51],[2,1.01,0]],"ltp":1.83,"tv":1879.87,"id":8257852}]}]}
{"op":"mcm","clk":"1011710570","pt":1580657415962,"mc":[{"id":"1.168223929","rc":[{"batb":[[0,2.58,26.05],[1,2.12,48.47],[2,1.01,15.51]],"batl":[[0,2.98,21]],"ltp":2.08,"tv":117.49,"id":8444055},{"batb":[[0,1.52,327.1],[1,1.51,418.37],[2,1.01,15.51]],"batl":[[0,1.57,440.02],[1,1.58,278.46],[2,1.63,42.01]],"ltp":1.83,"tv":1879.87,"id":8257852}]}]}
{"op":"mcm","clk":"1011710751","pt":1580657416765,"mc":[{"id":"1.168223929","rc":[{"batb":[[0,2.7,25.57],[1,2.58,26.05],[2,2.4,34.7]],"ltp":2.08,"tv":117.49,"id":8444055},{"batb":[[2,1.34,124.87]],"ltp":1.83,"tv":1879.87,"id":8257852}]}]}
{"op":"mcm","clk":"1011711098","pt":1580657418176,"mc":[{"id":"1.168223929","rc":[{"batb":[[2,1.34,590.29]],"ltp":1.83,"tv":1879.87,"id":8257852}]}]}
{"op":"mcm","clk":"1011711739","pt":1580657421206,"mc":[{"id":"1.168223929","rc":[{"batb":[[0,1.52,73.41]],"batl":[[0,1.57,286.57],[1,1.63,42.01],[2,1.63,0]],"ltp":1.83,"tv":1879.87,"id":8257852}]}]}
{"op":"mcm","clk":"1011711875","pt":1580657421813,"mc":[{"id":"1.168223929","rc":[{"batb":[[1,2.4,34.7],[2,2.04,394.09]],"ltp":2.08,"tv":117.49,"id":8444055},{"batb":[[1,1.51,336.03]],"batl":[[1,1.63,0]],"ltp":1.83,"tv":1879.87,"id":8257852}]}]}
{"op":"mcm","clk":"1011712405","pt":1580657424198,"mc":[{"id":"1.168223929","rc":[{"batb":[[1,2.6,26.05],[2,2.4,34.7]],"ltp":2.08,"tv":117.49,"id":8444055},{"batb":[[1,1.51,470.68],[2,1.5,431.21]],"batl":[[0,1.56,271.41],[1,1.57,286.57],[2,1.62,42.01]],"ltp":1.83,"tv":1879.87,"id":8257852}]}]}
{"op":"mcm","clk":"1011713926","pt":1580657431204,"mc":[{"id":"1.168223929","rc":[{"trd":[[1.52,53.06]],"batb":[[0,1.52,46.87]],"ltp":1.52,"tv":1932.93,"id":8257852}],"tv":2050.42}]}
{"op":"mcm","clk":"1011714170","pt":1580657432235,"mc":[{"id":"1.168223929","rc":[{"batb":[[1,1.5,84.02],[2,1.34,590.29]],"batl":[[0,1.62,42.01],[1,1.57,0],[2,1.62,0]],"ltp":1.52,"tv":1932.93,"id":8257852}]}]}
{"op":"mcm","clk":"1011714346","pt":1580657432997,"mc":[{"id":"1.168223929","rc":[{"batb":[[0,2.4,34.7],[1,2.04,394.09],[2,1.01,15.51]],"ltp":2.08,"tv":117.49,"id":8444055},{"batb":[[0,1.34,590.29],[1,1.01,15.51],[2,1.34,0]],"ltp":1.52,"tv":1932.93,"id":8257852}]}]}
{"op":"mcm","clk":"1011714818","pt":1580657435214,"mc":[{"id":"1.168223929","rc":[{"batb":[[0,1.34,1386.09],[1,1.33,602.62],[2,1.01,15.51]],"batl":[[0,1.68,264.71],[1,1.7,434.63]],"ltp":1.52,"tv":1932.93,"id":8257852}]}]}
{"op":"mcm","clk":"1011714920","pt":1580657435693,"mc":[{"id":"1.168223929","rc":[{"batb":[[0,2.44,33.91]],"ltp":2.08,"tv":117.49,"id":8444055}]}]}
{"op":"mcm","clk":"1011717079","pt":1580657445246,"mc":[{"id":"1.168223929","rc":[{"batb":[[1,1.01,15.51],[2,1.01,0]],"ltp":2.08,"tv":117.49,"id":8444055},{"batb":[[0,1.34,920.67]],"batl":[[0,1.38,389.78],[1,1.39,469.9]],"ltp":1.52,"tv":1932.93,"id":8257852}]}]}
{"op":"mcm","clk":"1011717278","pt":1580657446221,"mc":[{"id":"1.168223929","rc":[{"batb":[[0,3.55,31.94],[1,3.3,17.64],[2,2.98,49.88]],"batl":[[0,3.9,14.28]],"ltp":2.08,"tv":117.49,"id":8444055},{"batb":[[0,1.34,1044.18],[2,1.19,254.77]],"batl":[[2,1.43,42.01]],"ltp":1.52,"tv":1932.93,"id":8257852}]}]}
{"op":"mcm","clk":"1011717803","pt":1580657448627,"mc":[{"id":"1.168223929","rc":[{"batb":[[2,1.23,516.48]],"ltp":1.52,"tv":1932.93,"id":8257852}]}]}
{"op":"mcm","clk":"1011720957","pt":1580657463078,"mc":[{"id":"1.168223929","rc":[{"batb":[[0,2.98,49.88],[1,2.38,382.3],[2,1.01,15.51]],"ltp":2.08,"tv":117.49,"id":8444055},{"batb":[[0,1.23,516.48],[1,1.19,254.77],[2,1.01,15.51]],"ltp":1.52,"tv":1932.93,"id":8257852}]}]}
{"op":"mcm","clk":"1011721553","pt":1580657465991,"mc":[{"id":"1.168223929","rc":[{"batb":[[1,1.19,1256.84],[2,1.18,1162.13]],"batl":[[0,1.5,567.76],[1,1.51,330.61]],"ltp":1.52,"tv":1932.93,"id":8257852}]}]}
{"op":"mcm","clk":"1011721773","pt":1580657466975,"mc":[{"id":"1.168223929","rc":[{"batb":[[1,1.19,254.77],[2,1.01,15.51]],"ltp":1.52,"tv":1932.93,"id":8257852}]}]}
{"op":"mcm","clk":"1011722248","pt":1580657469179,"mc":[{"id":"1.168223929","rc":[{"batb":[[0,1.19,254.77],[1,1.01,15.51],[2,1.01,0]],"ltp":1.52,"tv":1932.93,"id":8257852}]}]}
{"op":"mcm","clk":"1011722488","pt":1580657470183,"mc":[{"id":"1.168223929","rc":[{"batb":[[1,2.84,22.69],[2,2.54,30.29]],"batl":[[0,3.25,18.48]],"ltp":2.08,"tv":117.49,"id":8444055},{"batb":[[0,1.45,399.92],[1,1.44,597.15],[2,1.25,184.75]],"batl":[[2,1.54,42.01]],"ltp":1.52,"tv":1932.93,"id":8257852}]}]}
{"op":"mcm","clk":"1011722886","pt":1580657472079,"mc":[{"id":"1.168223929","rc":[{"batb":[[2,1.31,477.51]],"ltp":1.52,"tv":1932.93,"id":8257852}]}]}
{"op":"mcm","clk":"1011724700","pt":1580657480094,"mc":[{"id":"1.168223929","rc":[{"batb":[[2,1.25,184.75]],"ltp":1.52,"tv":1932.93,"id":8257852}]}]}
{"op":"mcm","clk":"1011725577","pt":1580657483823,"mc":[{"id":"1.168223929","rc":[{"batb":[[0,2.84,22.69],[1,2.54,30.29],[2,1.01,15.51]],"ltp":2.08,"tv":117.49,"id":8444055},{"batb":[[0,1.44,94.94],[1,1.25,184.51],[2,1.01,15.51]],"batl":[[0,1.54,42.01],[1,1.51,0],[2,1.54,0]],"ltp":1.52,"tv":1932.93,"id":8257852}]}]}
{"op":"mcm","clk":"1011725848","pt":1580657485105,"mc":[{"id":"1.168223929","rc":[{"batb":[[0,2.54,30.29],[1,1.01,15.51],[2,1.01,0]],"ltp":2.08,"tv":117.49,"id":8444055},{"batb":[[0,1.25,184.51],[1,1.01,15.51],[2,1.01,0]],"ltp":1.52,"tv":1932.93,"id":8257852}]}]}
{"op":"mcm","clk":"1011726130","pt":1580657486400,"mc":[{"id":"1.168223929","rc":[{"batb":[[0,1.25,1152.69],[1,1.24,898.14],[2,1.01,15.51]],"batl":[[0,1.64,258.95],[1,1.65,239.52]],"ltp":1.52,"tv":1932.93,"id":8257852}]}]}
{"op":"mcm","clk":"1011728889","pt":1580657499141,"mc":[{"id":"1.168223929","rc":[{"batl":[[0,1.28,360.65],[1,1.29,679.62]],"ltp":1.52,"tv":1932.93,"id":8257852}]}]}
{"op":"mcm","clk":"1011729174","pt":1580657500243,"mc":[{"id":"1.168223929","rc":[{"batb":[[0,4.4,38.4],[1,4.1,13.44],[2,3.45,34.7]],"batl":[[0,4.9,10.08]],"ltp":2.08,"tv":117.49,"id":8444055},{"batb":[[0,1.26,161.32],[1,1.25,1152.69],[2,1.24,898.14]],"ltp":1.52,"tv":1932.93,"id":8257852}]}]}
{"op":"mcm","clk":"1011729867","pt":1580657503241,"mc":[{"id":"1.168223929","rc":[{"batl":[[2,1.32,42.01]],"ltp":1.52,"tv":1932.93,"id":8257852}]}]}
{"op":"mcm","clk":"1011730899","pt":1580657508047,"mc":[{"id":"1.168223929","rc":[{"batb":[[0,1.25,1152.69],[1,1.24,898.14],[2,1.18,549.72]],"ltp":1.52,"tv":1932.93,"id":8257852}]}]}
{"op":"mcm","clk":"1011731685","pt":1580657511264,"mc":[{"id":"1.168223929","rc":[{"batb":[[0,1.25,1320.73]],"ltp":1.52,"tv":1932.93,"id":8257852}]}]}
{"op":"mcm","clk":"1011732893","pt":1580657516210,"mc":[{"id":"1.168223929","rc":[{"batl":[[0,1.26,30.29],[1,1.28,360.65],[2,1.29,679.62]],"ltp":1.52,"tv":1932.93,"id":8257852}]}]}
{"op":"mcm","clk":"1011733115","pt":1580657517010,"mc":[{"id":"1.168223929","rc":[{"batb":[[1,3.45,34.7],[2,2.62,379.26]],"ltp":2.08,"tv":117.49,"id":8444055}]}]}
{"op":"mcm","clk":"1011733715","pt":1580657519613,"mc":[{"id":"1.168223929","rc":[{"batb":[[1,4.2,12.6],[2,3.45,34.7]],"ltp":2.08,"tv":117.49,"id":8444055},{"trd":[[1.26,57.14]],"batl":[[0,1.26,1.72]],"ltp":1.26,"tv":1990.07,"id":8257852}],"tv":2107.56}]}
{"op":"mcm","clk":"1011734299","pt":1580657522104,"mc":[{"id":"1.168223929","rc":[{"batb":[[0,4.2,12.6],[1,3.45,34.7],[2,2.62,379.26]],"ltp":2.08,"tv":117.49,"id":8444055},{"batb":[[0,1.25,168.04],[1,1.18,549.72],[2,1.09,515.84]],"batl":[[1,1.31,42.01],[2,1.29,0]],"ltp":1.26,"tv":1990.07,"id":8257852}]}]}
{"op":"mcm","clk":"1011734571","pt":1580657523235,"mc":[{"id":"1.168223929","rc":[{"batb":[[0,3.45,34.7],[1,2.62,379.26],[2,1.01,15.51]],"ltp":2.08,"tv":117.49,"id":8444055},{"batb":[[0,1.18,549.72],[1,1.09,515.84],[2,1.01,15.51]],"ltp":1.26,"tv":1990.07,"id":8257852}]}]}
{"op":"mcm","clk":"1011734803","pt":1580657524191,"mc":[{"id":"1.168223929","rc":[{"batb":[[1,1.01,15.51],[2,1.01,0]],"ltp":2.08,"tv":117.49,"id":8444055},{"batb":[[0,1.09,515.84],[1,1.01,15.51],[2,1.01,0]],"ltp":1.26,"tv":1990.07,"id":8257852}]}]}
{"op":"mcm","clk":"1011734986","pt":1580657525014,"mc":[{"id":"1.168223929","rc":[{"batb":[[0,1.1,884.52],[1,1.09,1975.29],[2,1.01,15.51]],"batl":[[0,1.4,371.01],[1,1.41,441.06]],"ltp":1.26,"tv":1990.07,"id":8257852}]}]}
{"op":"mcm","clk":"1011737764","pt":1580657537722,"mc":[{"id":"1.168223929","rc":[{"batb":[[0,1.09,515.84],[1,1.01,15.51],[2,1.01,0]],"ltp":1.26,"tv":1990.07,"id":8257852}]}]}
{"op":"mcm","clk":"1011738573","pt":1580657541228,"mc":[{"id":"1.168223929","rc":[{"batb":[[1,2.6,29.11],[2,1.01,15.51]],"ltp":2.08,"tv":117.49,"id":8444055},{"batb":[[0,1.36,802.57],[1,1.35,557.63],[2,1.1,499.55]],"ltp":1.26,"tv":1990.07,"id":8257852}]}]}
{"op":"mcm","clk":"1011738735","pt":1580657541997,"mc":[{"id":"1.168223929","rc":[{"batb":[[1,3.35,17.64],[2,2.6,29.11]],"batl":[[0,3.85,14.28]],"ltp":2.08,"tv":117.49,"id":8444055},{"batb":[[1,1.35,676.94]],"batl":[[2,1.43,42.01]],"ltp":1.26,"tv":1990.07,"id":8257852}]}]}
{"op":"mcm","clk":"1011738827","pt":1580657542429,"mc":[{"id":"1.168223929","rc":[{"batb":[[2,1.25,505.09]],"ltp":1.26,"tv":1990.07,"id":8257852}]}]}
{"op":"mcm","clk":"1011742825","pt":1580657560230,"mc":[{"id":"1.168223929","rc":[{"trd":[[3.5,50]],"ltp":3.5,"tv":167.49,"id":8444055},{"trd":[[1.4,125]],"batl":[[0,1.4,246.01]],"ltp":1.4,"tv":2115.07,"id":8257852}],"tv":2282.56}]}
{"op":"mcm","clk":"1011743023","pt":1580657561162,"mc":[{"id":"1.168223929","rc":[{"batb":[[0,1.36,119.68],[1,1.35,119.31]],"batl":[[0,1.43,42.01],[1,1.41,0],[2,1.43,0]],"ltp":1.4,"tv":2115.07,"id":8257852}]}]}
{"op":"mcm","clk":"1011743151","pt":1580657561750,"mc":[{"id":"1.168223929","rc":[{"batb":[[0,3.35,17.64],[1,2.6,29.11],[2,2.3,385.09]],"ltp":3.5,"tv":167.49,"id":8444055},{"batb":[[0,1.35,119.31],[1,1.25,505.09],[2,1.1,499.55]],"ltp":1.4,"tv":2115.07,"id":8257852}]}]}
{"op":"mcm","clk":"1011743438","pt":1580657563041,"mc":[{"id":"1.168223929","rc":[{"batb":[[0,2.6,29.11],[1,1.01,15.51],[2,2.3,0]],"ltp":3.5,"tv":167.49,"id":8444055},{"batb":[[0,1.1,499.55],[1,1.01,15.51],[2,1.1,0]],"ltp":1.4,"tv":2115.07,"id":8257852}]}]}
{"op":"mcm","clk":"1011743660","pt":1580657564171,"mc":[{"id":"1.168223929","rc":[{"batb":[[0,1.1,1834.6],[1,1.09,1004.79],[2,1.01,15.51]],"batl":[[0,1.63,256.31],[1,1.64,244.49]],"ltp":1.4,"tv":2115.07,"id":8257852}]}]}
{"op":"mcm","clk":"1011745280","pt":1580657571777,"mc":[{"id":"1.168223929","rc":[{"batb":[[0,1.1,499.55],[1,1.01,15.51],[2,1.01,0]],"ltp":1.4,"tv":2115.07,"id":8257852}]}]}
{"op":"mcm","clk":"1011746043","pt":1580657575270,"mc":[{"id":"1.168223929","rc":[{"batb":[[0,1.58,272.08],[1,1.57,289],[2,1.1,499.55]],"ltp":1.4,"tv":2115.07,"id":8257852}]}]}
{"op":"mcm","clk":"1011746275","pt":1580657576267,"mc":[{"id":"1.168223929","rc":[{"batb":[[1,2.54,26.89],[2,2.26,42.25]],"batl":[[0,2.88,21.85]],"ltp":3.5,"tv":167.49,"id":8444055},{"batb":[[1,1.57,354.86],[2,1.53,78.98]],"batl":[[2,1.65,42.01]],"ltp":1.4,"tv":2115.07,"id":8257852}]}]}
{"op":"mcm","clk":"1011746491","pt":1580657577180,"mc":[{"id":"1.168223929","rc":[{"batb":[[2,1.4,451]],"ltp":1.4,"tv":2115.07,"id":8257852}]}]}
{"op":"mcm","clk":"1011746735","pt":1580657578167,"mc":[{"id":"1.168223929","rc":[{"batl":[[0,2.86,21.85]],"ltp":3.5,"tv":167.49,"id":8444055},{"batb":[[2,1.54,77.3]],"ltp":1.4,"tv":2115.07,"id":8257852}]}]}
{"op":"mcm","clk":"1011747750","pt":1580657582671,"mc":[{"id":"1.168223929","rc":[{"trd":[[1.58,31.83]],"batb":[[0,1.58,256.16]],"ltp":1.58,"tv":2146.9,"id":8257852}],"tv":2314.39}]}
{"op":"mcm","clk":"1011750185","pt":1580657593195,"mc":[{"id":"1.168223929","rc":[{"batb":[[0,2.26,42.25],[1,1.92,394.91],[2,1.01,15.51]],"ltp":3.5,"tv":167.49,"id":8444055},{"batb":[[0,1.4,451],[1,1.34,125.1],[2,1.01,15.51]],"ltp":1.58,"tv":2146.9,"id":8257852}]}]}
{"op":"mcm","clk":"1011750873","pt":1580657596219,"mc":[{"id":"1.168223929","rc":[{"batb":[[1,1.36,343.86],[2,1.35,552.73]],"batl":[[0,1.8,280.45],[1,1.82,346.84]],"ltp":1.58,"tv":2146.9,"id":8257852}]}]}
{"op":"mcm","clk":"1011751658","pt":1580657599539,"mc":[{"id":"1.168223929","rc":[{"batb":[[1,1.34,125.1],[2,1.01,15.51]],"ltp":1.58,"tv":2146.9,"id":8257852}]}]}
{"op":"mcm","clk":"1011752076","pt":1580657601211,"mc":[{"id":"1.168223929","rc":[{"batb":[[1,1.01,15.51],[2,1.01,0]],"ltp":3.5,"tv":167.49,"id":8444055},{"batb":[[0,1.34,125.1],[1,1.01,15.51],[2,1.01,0]],"ltp":1.58,"tv":2146.9,"id":8257852}]}]}
{"op":"mcm","clk":"1011752537","pt":1580657603168,"mc":[{"id":"1.168223929","rc":[{"batb":[[1,2.08,53.19],[2,1.01,15.51]],"ltp":3.5,"tv":167.49,"id":8444055},{"batb":[[0,1.73,329.47],[1,1.72,47.45],[2,1.71,421.88]],"ltp":1.58,"tv":2146.9,"id":8257852}]}]}
{"op":"mcm","clk":"1011752802","pt":1580657604182,"mc":[{"id":"1.168223929","rc":[{"batb":[[1,2.24,33.61],[2,2.08,53.19]],"batl":[[0,2.48,27.73]],"ltp":3.5,"tv":167.49,"id":8444055},{"batl":[[1,1.81,42.01],[2,1.82,346.84]],"ltp":1.58,"tv":2146.9,"id":8257852}]}]}
{"op":"mcm","clk":"1011752998","pt":1580657605106,"mc":[{"id":"1.168223929","rc":[{"batb":[[1,2.22,33.61]],"ltp":3.5,"tv":167.49,"id":8444055}]}]}
{"op":"mcm","clk":"1011754893","pt":1580657613134,"mc":[{"id":"1.168223929","rc":[{"batb":[[0,1.72,47.45],[1,1.67,62.17],[2,1.54,69.48]],"batl":[[0,1.81,42.01],[1,1.81,0],[2,1.82,0]],"ltp":1.58,"tv":2146.9,"id":8257852}]}]}
{"op":"mcm","clk":"1011755145","pt":1580657614206,"mc":[{"id":"1.168223929","rc":[{"batb":[[0,2.22,33.61],[1,2.08,53.19],[2,1.74,404.28]],"ltp":3.5,"tv":167.49,"id":8444055},{"batb":[[0,1.67,62.17],[1,1.54,69.48],[2,1.52,425.49]],"ltp":1.58,"tv":2146.9,"id":8257852}]}]}
{"op":"mcm","clk":"1011755333","pt":1580657615014,"mc":[{"id":"1.168223929","rc":[{"batb":[[0,2.08,53.19],[1,1.74,404.28],[2,1.01,15.51]],"ltp":3.5,"tv":167.49,"id":8444055},{"batb":[[0,1.54,69.48],[1,1.52,425.49],[2,1.01,15.51]],"ltp":1.58,"tv":2146.9,"id":8257852}]}]}
{"op":"mcm","clk":"1011755862","pt":1580657617220,"mc":[{"id":"1.168223929","rc":[{"batl":[[0,1.91,225.96],[1,1.93,288.99]],"ltp":1.58,"tv":2146.9,"id":8257852}]}]}
{"op":"mcm","clk":"1011756145","pt":1580657618205,"mc":[{"id":"1.168223929","rc":[{"batb":[[1,1.01,15.51],[2,1.01,0]],"ltp":1.58,"tv":2146.9,"id":8257852}]}]}
{"op":"mcm","clk":"1011756610","pt":1580657620220,"mc":[{"id":"1.168223929","rc":[{"batb":[[0,2.08,91.84],[1,1.83,40.13],[2,1.74,404.28]],"batl":[[0,2.3,31.93]],"ltp":3.5,"tv":167.49,"id":8444055},{"batb":[[0,1.83,395.81],[1,1.81,348.45],[2,1.76,54.61]],"batl":[[1,1.92,42.01],[2,1.93,288.99]],"ltp":1.58,"tv":2146.9,"id":8257852}]}]}
{"op":"mcm","clk":"1011756816","pt":1580657621147,"mc":[{"id":"1.168223929","rc":[{"batb":[[0,2.08,53.19]],"ltp":3.5,"tv":167.49,"id":8444055},{"batb":[[2,1.77,53.77]],"batl":[[1,1.93,331],[2,1.93,0]],"ltp":1.58,"tv":2146.9,"id":8257852}]}]}
{"op":"mcm","clk":"1011757068","pt":1580657622222,"mc":[{"id":"1.168223929","rc":[{"batb":[[1,2.06,39.49],[2,1.83,40.13]],"ltp":3.5,"tv":167.49,"id":8444055}]}]}
{"op":"mcm","clk":"1011761815","pt":1580657642189,"mc":[{"id":"1.168223929","rc":[{"batb":[[0,2.06,39.49],[1,1.83,40.13],[2,1.74,404.28]],"ltp":3.5,"tv":167.49,"id":8444055},{"trd":[[1.83,157.2]],"batb":[[0,1.77,53.77],[1,1.72,47.52],[2,1.58,416.47]],"batl":[[0,1.83,37.48],[1,1.93,42.01]],"ltp":1.83,"tv":2223.38,"id":8257852}],"tv":2390.87}]}
{"op":"mcm","clk":"1011762024","pt":1580657643073,"mc":[{"id":"1.168223929","rc":[{"batb":[[0,1.83,40.13],[1,1.74,404.28],[2,1.01,15.51]],"ltp":3.5,"tv":167.49,"id":8444055},{"batb":[[0,1.72,47.52],[1,1.58,416.47],[2,1.01,15.51]],"batl":[[1,1.93,0]],"ltp":1.83,"tv":2223.38,"id":8257852}]}]}
{"op":"mcm","clk":"1011762506","pt":1580657645252,"mc":[{"id":"1.168223929","rc":[{"batb":[[0,1.73,257.23],[1,1.71,421.57],[2,1.58,416.47]],"ltp":1.83,"tv":2223.38,"id":8257852}]}]}
{"op":"mcm","clk":"1011762944","pt":1580657647053,"mc":[{"id":"1.168223929","rc":[{"batl":[[0,1.8,349.11],[1,1.82,346.62],[2,1.83,37.48]],"ltp":1.83,"tv":2223.38,"id":8257852}]}]}
{"op":"mcm","clk":"1011763151","pt":1580657648061,"mc":[{"id":"1.168223929","rc":[{"batb":[[0,2.3,41.47],[1,2.2,34.45],[2,2.04,58.46]],"batl":[[0,2.46,28.57]],"ltp":3.5,"tv":167.49,"id":8444055},{"batb":[[1,1.71,469.88],[2,1.69,60.49]],"batl":[[2,1.83,79.49]],"ltp":1.83,"tv":2223.38,"id":8257852}]}]}
{"op":"mcm","clk":"1011763590","pt":1580657650185,"mc":[{"id":"1.168223929","rc":[{"trd":[[1.73,88.43]],"batb":[[0,1.73,213]],"ltp":1.73,"tv":2311.81,"id":8257852}],"tv":2479.3}]}
{"op":"mcm","clk":"1011765056","pt":1580657656583,"mc":[{"id":"1.168223929","rc":[{"batl":[[2,1.83,42.01]],"ltp":1.73,"tv":2311.81,"id":8257852}]}]}
{"op":"mcm","clk":"1011765712","pt":1580657659268,"mc":[{"id":"1.168223929","rc":[{"batb":[[0,2.2,34.45],[1,2.04,58.46],[2,1.74,404.28]],"ltp":3.5,"tv":167.49,"id":8444055},{"batb":[[0,1.69,60.49],[1,1.63,56.65],[2,1.58,416.47]],"batl":[[0,1.83,42.01],[1,1.82,0],[2,1.83,0]],"ltp":1.73,"tv":2311.81,"id":8257852}]}]}
{"op":"mcm","clk":"1011766088","pt":1580657661062,"mc":[{"id":"1.168223929","rc":[{"batb":[[0,2.04,58.46],[1,1.74,404.28],[2,1.01,15.51]],"ltp":3.5,"tv":167.49,"id":8444055},{"batb":[[0,1.63,56.65],[1,1.58,416.47],[2,1.01,15.51]],"ltp":1.73,"tv":2311.81,"id":8257852}]}]}
{"op":"mcm","clk":"1011766336","pt":1580657662149,"mc":[{"id":"1.168223929","rc":[{"batb":[[0,1.66,247.65],[1,1.65,240.48],[2,1.63,56.65]],"batl":[[0,1.97,238.42],[1,1.99,263.47]],"ltp":1.73,"tv":2311.81,"id":8257852}]}]}
{"op":"mcm","clk":"1011768049","pt":1580657669962,"mc":[{"id":"1.168223929","rc":[{"batb":[[1,1.01,15.51],[2,1.01,0]],"ltp":3.5,"tv":167.49,"id":8444055}]}]}
{"op":"mcm","clk":"1011768240","pt":1580657670797,"mc":[{"id":"1.168223929","rc":[{"batl":[[0,1.72,317.5],[1,1.74,401.36]],"ltp":1.73,"tv":2311.81,"id":8257852}]}]}
{"op":"mcm","clk":"1011768540","pt":1580657672166,"mc":[{"id":"1.168223929","rc":[{"batb":[[0,2.46,34.62],[1,2.32,31.09],[2,2.24,44.06]],"batl":[[0,2.62,25.21]],"ltp":3.5,"tv":167.49,"id":8444055},{"batb":[[2,1.63,123.03]],"batl":[[2,1.76,42.01]],"ltp":1.73,"tv":2311.81,"id":8257852}]}]}
{"op":"mcm","clk":"1011771596","pt":1580657686161,"mc":[{"id":"1.168223929","rc":[{"batb":[[0,2.32,31.09],[1,2.24,44.06],[2,1.82,401.24]],"ltp":3.5,"tv":167.49,"id":8444055},{"batb":[[0,1.63,66.38],[1,1.59,62.32],[2,1.46,435.7]],"batl":[[0,1.76,42.01],[1,1.74,0],[2,1.76,0]],"ltp":1.73,"tv":2311.81,"id":8257852}]}]}
{"op":"mcm","clk":"1011771780","pt":1580657687090,"mc":[{"id":"1.168223929","rc":[{"batb":[[0,2.24,44.06],[1,1.82,401.24],[2,1.01,15.51]],"ltp":3.5,"tv":167.49,"id":8444055},{"batb":[[0,1.59,61.69],[1,1.46,435.7],[2,1.01,15.51]],"ltp":1.73,"tv":2311.81,"id":8257852}]}]}
{"op":"mcm","clk":"1011772655","pt":1580657691015,"mc":[{"id":"1.168223929","rc":[{"batb":[[0,1.67,390.41],[1,1.66,235.74],[2,1.59,61.69]],"batl":[[0,1.74,359.25],[1,1.76,386.36]],"ltp":1.73,"tv":2311.81,"id":8257852}]}]}
{"op":"mcm","clk":"1011773393","pt":1580657694340,"mc":[{"id":"1.168223929","rc":[{"batb":[[0,1.59,61.69],[1,1.46,435.7],[2,1.01,15.51]],"ltp":1.73,"tv":2311.81,"id":8257852}]}]}
{"op":"mcm","clk":"1011774167","pt":1580657698036,"mc":[{"id":"1.168223929","rc":[{"batb":[[0,1.62,258.67],[1,1.61,262.99],[2,1.59,61.69]],"batl":[[0,1.81,227.15],[1,1.83,341.08]],"ltp":1.73,"tv":2311.81,"id":8257852}]}]}
{"op":"mcm","clk":"1011775417","pt":1580657703250,"mc":[{"id":"1.168223929","rc":[{"batb":[[0,1.59,61.69],[1,1.46,435.7],[2,1.01,15.51]],"ltp":1.73,"tv":2311.81,"id":8257852}]}]}
{"op":"mcm","clk":"1011775717","pt":1580657704745,"mc":[{"id":"1.168223929","rc":[{"batb":[[1,1.01,15.51],[2,1.01,0]],"ltp":1.73,"tv":2311.81,"id":8257852}]}]}
{"op":"mcm","clk":"1011776017","pt":1580657706130,"mc":[{"id":"1.168223929","rc":[{"batb":[[0,1.74,364.82],[1,1.72,413.7],[2,1.59,61.69]],"ltp":1.73,"tv":2311.81,"id":8257852}]}]}
{"op":"mcm","clk":"1011776186","pt":1580657706958,"mc":[{"id":"1.168223929","rc":[{"batb":[[1,1.95,33.28],[2,1.82,401.24]],"ltp":3.5,"tv":167.49,"id":8444055},{"batb":[[0,1.74,409.98],[2,1.65,54.29]],"ltp":1.73,"tv":2311.81,"id":8257852}]}]}
{"op":"mcm","clk":"1011776435","pt":1580657708110,"mc":[{"id":"1.168223929","rc":[{"batb":[[1,2.2,34.45],[2,1.95,33.28]],"batl":[[0,2.44,28.57]],"ltp":3.5,"tv":167.49,"id":8444055},{"batb":[[2,1.69,60.49]],"batl":[[2,1.84,42.01]],"ltp":1.73,"tv":2311.81,"id":8257852}]}]}
{"op":"mcm","clk":"1011779283","pt":1580657721236,"mc":[{"id":"1.168223929","rc":[{"trd":[[2.24,63.05]],"batb":[[0,2.2,34.45],[1,1.95,33.28],[2,1.82,401.24]],"ltp":2.24,"tv":230.54,"id":8444055},{"batb":[[0,1.69,60.49],[1,1.65,54.29],[2,1.52,425.49]],"batl":[[0,1.84,42.01],[1,1.83,0],[2,1.84,0]],"ltp":1.73,"tv":2311.81,"id":8257852}],"tv":2542.35}]}
{"op":"mcm","clk":"1011779640","pt":1580657723009,"mc":[{"id":"1.168223929","rc":[{"batb":[[0,1.95,33.28],[1,1.82,401.24],[2,1.01,15.51]],"ltp":2.24,"tv":230.54,"id":8444055},{"batb":[[0,1.65,54.29],[1,1.52,425.49],[2,1.01,15.51]],"ltp":1.73,"tv":2311.81,"id":8257852}]}]}
{"op":"mcm","clk":"1011779871","pt":1580657724032,"mc":[{"id":"1.168223929","rc":[{"batb":[[0,1.65,488.43],[1,1.64,246.4],[2,1.52,425.49]],"batl":[[0,2.04,248.72],[1,2.06,237.96]],"ltp":1.73,"tv":2311.81,"id":8257852}]}]}
{"op":"mcm","clk":"1011780118","pt":1580657725231,"mc":[{"id":"1.168223929","rc":[{"batb":[[0,1.65,54.29],[1,1.52,425.49],[2,1.01,15.51]],"ltp":1.73,"tv":2311.81,"id":8257852}]}]}
{"op":"mcm","clk":"1011780755","pt":1580657728251,"mc":[{"id":"1.168223929","rc":[{"batb":[[0,1.78,311.07],[1,1.76,382.44],[2,1.65,54.29]],"batl":[[0,1.86,363.84],[1,1.88,313.09]],"ltp":1.73,"tv":2311.81,"id":8257852}]}]}
{"op":"mcm","clk":"1011781111","pt":1580657729843,"mc":[{"id":"1.168223929","rc":[{"trd":[[2.3,100.22]],"ltp":2.3,"tv":230.75,"id":8444055},{"trd":[[1.78,0.27]],"batb":[[0,1.78,310.8]],"ltp":1.78,"tv":2312.08,"id":8257852}],"tv":2542.83}]}
{"op":"mcm","clk":"1011781326","pt":1580657730905,"mc":[{"id":"1.168223929","rc":[{"batb":[[0,1.65,54.29],[1,1.52,425.49],[2,1.01,15.51]],"ltp":1.78,"tv":2312.08,"id":8257852}]}]}
{"op":"mcm","clk":"1011782186","pt":1580657735014,"mc":[{"id":"1.168223929","rc":[{"batb":[[0,1.65,488.33],[1,1.64,246.39],[2,1.52,425.49]],"batl":[[0,2.04,248.81],[1,2.06,237.96]],"ltp":1.78,"tv":2312.08,"id":8257852}]}]}
{"op":"mcm","clk":"1011782970","pt":1580657738846,"mc":[{"id":"1.168223929","rc":[{"batl":[[0,1.72,370.21],[1,1.74,401.19]],"ltp":1.78,"tv":2312.08,"id":8257852}]}]}
{"op":"mcm","clk":"1011783210","pt":1580657740035,"mc":[{"id":"1.168223929","rc":[{"batb":[[0,2.36,37.06],[1,2.32,31.09],[2,2.18,45.71]],"batl":[[0,2.62,25.21]],"ltp":2.3,"tv":230.75,"id":8444055},{"batb":[[0,1.66,53.43],[1,1.65,434.04],[2,1.64,246.39]],"batl":[[2,1.76,42.01]],"ltp":1.78,"tv":2312.08,"id":8257852}]}]}
{"op":"mcm","clk":"1011784716","pt":1580657747383,"mc":[{"id":"1.168223929","rc":[{"trd":[[2.52,0.05]],"ltp":2.52,"tv":230.8,"id":8444055},{"trd":[[1.66,53.3]],"batb":[[0,1.66,53.34]],"ltp":1.66,"tv":2312.16,"id":8257852}],"tv":2542.97}]}
{"op":"mcm","clk":"1011786255","pt":1580657755186,"mc":[{"id":"1.168223929","rc":[{"batb":[[1,1.62,67.22],[2,1.61,59.72]],"batl":[[0,1.76,42.01],[1,1.74,0],[2,1.76,0]],"ltp":1.66,"tv":2312.16,"id":8257852}]}]}
{"op":"mcm","clk":"1011786415","pt":1580657756085,"mc":[{"id":"1.168223929","rc":[{"batb":[[0,2.32,31.09],[1,2.18,45.71],[2,1.82,401.24]],"ltp":2.52,"tv":230.8,"id":8444055},{"batb":[[0,1.62,67.22],[1,1.61,59.72],[2,1.52,425.49]],"ltp":1.66,"tv":2312.16,"id":8257852}]}]}
{"op":"mcm","clk":"1011786683","pt":1580657757078,"mc":[{"id":"1.168223929","rc":[{"batb":[[0,2.18,45.71],[1,1.82,401.24],[2,1.01,15.51]],"ltp":2.52,"tv":230.8,"id":8444055},{"batb":[[0,1.61,59.72],[1,1.52,425.49],[2,1.01,15.51]],"ltp":1.66,"tv":2312.16,"id":8257852}]}]}
{"op":"mcm","clk":"1011786883","pt":1580657758085,"mc":[{"id":"1.168223929","rc":[{"batb":[[0,1.62,301.52],[1,1.61,322.87],[2,1.52,425.49]],"batl":[[0,1.81,382.21],[1,1.83,340.68]],"ltp":1.66,"tv":2312.16,"id":8257852}]}]}
{"op":"mcm","clk":"1011787829","pt":1580657762993,"mc":[{"id":"1.168223929","rc":[{"batb":[[2,1.01,15.51]],"batl":[[0,1.68,361.65],[1,1.7,433.79]],"ltp":1.66,"tv":2312.16,"id":8257852}]}]}
{"op":"mcm","clk":"1011788116","pt":1580657764195,"mc":[{"id":"1.168223929","rc":[{"batb":[[0,2.48,32.57],[1,2.42,29.41],[2,2.26,41.47]],"batl":[[0,2.74,23.53]],"ltp":2.52,"tv":230.8,"id":8444055},{"batb":[[0,1.61,322.87],[1,1.58,72.26],[2,1.45,89.93]],"batl":[[1,1.7,475.8]],"ltp":1.66,"tv":2312.16,"id":8257852}]}]}
{"op":"mcm","clk":"1011788542","pt":1580657766259,"mc":[{"id":"1.168223929","rc":[{"trd":[[1.61,0.36]],"batb":[[0,1.61,550.51],[1,1.6,270.26],[2,1.58,72.26]],"batl":[[0,1.68,434.2]],"ltp":1.61,"tv":2312.52,"id":8257852}],"tv":2543.33}]}
{"op":"mcm","clk":"1011794874","pt":1580657796109,"mc":[{"id":"1.168223929","rc":[{"trd":[[1.61,18.05]],"batb":[[0,1.61,541.66]],"ltp":1.61,"tv":2330.2,"id":8257852}],"tv":2561.01}]}
{"op":"mcm","clk":"1011796008","pt":1580657801131,"mc":[{"id":"1.168223929","rc":[{"batb":[[0,2.5,32.5],[1,2.48,32.57],[2,2.42,29.41]],"ltp":2.52,"tv":230.8,"id":8444055}]}]}
{"op":"mcm","clk":"1011796166","pt":1580657801952,"mc":[{"id":"1.168223929","rc":[{"batb":[[1,2.42,29.41],[2,2.28,41.31]],"ltp":2.52,"tv":230.8,"id":8444055}]}]}
{"op":"mcm","clk":"1011801490","pt":1580657826149,"mc":[{"id":"1.168223929","rc":[{"trd":[[2.5,8.16]],"batb":[[0,2.5,24.34]],"ltp":2.5,"tv":238.96,"id":8444055},{"trd":[[1.67,12.21]],"ltp":1.67,"tv":2342.41,"id":8257852}],"tv":2581.38}]}
{"op":"mcm","clk":"1011803408","pt":1580657834746,"mc":[{"id":"1.168223929","rc":[{"trd":[[2.5,8.21]],"batb":[[0,2.5,24.29]],"ltp":2.5,"tv":239.01,"id":8444055},{"trd":[[1.67,12.28]],"ltp":1.67,"tv":2342.48,"id":8257852}],"tv":2581.5}]}
{"op":"mcm","clk":"1011807910","pt":1580657855194,"mc":[{"id":"1.168223929","rc":[{"batb":[[0,2.28,41.31],[1,1.82,401.24],[2,1.01,15.51]],"ltp":2.5,"tv":239.01,"id":8444055},{"batb":[[0,1.45,89.93],[1,1.44,436.18],[2,1.01,15.51]],"ltp":1.67,"tv":2342.48,"id":8257852}]}]}
{"op":"mcm","clk":"1011808583","pt":1580657858228,"mc":[{"id":"1.168223929","rc":[{"batb":[[1,2.26,41.62],[2,1.82,401.24]],"ltp":2.5,"tv":239.01,"id":8444055}]}]}
{"op":"mcm","clk":"1011808809","pt":1580657859127,"mc":[{"id":"1.168223929","rc":[{"batb":[[0,2.26,41.62],[1,1.01,15.51],[2,1.82,0]],"ltp":2.5,"tv":239.01,"id":8444055},{"batb":[[0,1.45,89.62]],"ltp":1.67,"tv":2342.48,"id":8257852}]}]}
{"op":"mcm","clk":"1011809218","pt":1580657861112,"mc":[{"id":"1.168223929","rc":[{"batb":[[0,1.58,436.47],[1,1.57,290.06],[2,1.45,89.62]],"batl":[[0,1.64,346.72],[1,1.65,239.32]],"ltp":1.67,"tv":2342.48,"id":8257852}]}]}
{"op":"mcm","clk":"1011809646","pt":1580657863092,"mc":[{"id":"1.168223929","rc":[{"batb":[[1,1.92,394.91],[2,1.01,15.51]],"ltp":2.5,"tv":239.01,"id":8444055}]}]}
{"op":"mcm","clk":"1011810076","pt":1580657865002,"mc":[{"id":"1.168223929","rc":[{"batb":[[0,1.45,89.62],[1,1.44,436.18],[2,1.01,15.51]],"ltp":1.67,"tv":2342.48,"id":8257852}]}]}
{"op":"mcm","clk":"1011810813","pt":1580657868132,"mc":[{"id":"1.168223929","rc":[{"batb":[[0,1.46,596.93],[1,1.45,490.7],[2,1.44,436.18]],"batl":[[0,1.78,339.39],[1,1.8,359.57]],"ltp":1.67,"tv":2342.48,"id":8257852}]}]}
{"op":"mcm","clk":"1011811719","pt":1580657872137,"mc":[{"id":"1.168223929","rc":[{"batb":[[0,2.96,50.59],[1,2.6,28.95],[2,2.26,41.62]],"batl":[[0,3.25,18.48]],"ltp":2.5,"tv":239.01,"id":8444055},{"batb":[[1,1.45,583.96],[2,1.28,161.14]],"batl":[[0,1.51,342.02],[1,1.52,323.83]],"ltp":1.67,"tv":2342.48,"id":8257852}]}]}
{"op":"mcm","clk":"1011811750","pt":1580657872299,"mc":[{"id":"1.168223929","rc":[{"batb":[[2,1.01,15.51]],"ltp":2.5,"tv":239.01,"id":8444055}]}]}
{"op":"mcm","clk":"1011812504","pt":1580657875539,"mc":[{"id":"1.168223929","rc":[{"batb":[[2,2.12,388.65]],"ltp":2.5,"tv":239.01,"id":8444055},{"batb":[[2,1.31,477.51]],"ltp":1.67,"tv":2342.48,"id":8257852}]}]}
{"op":"mcm","clk":"1011814746","pt":1580657885167,"mc":[{"id":"1.168223929","rc":[{"batb":[[0,2.6,28.95],[1,2.12,388.65],[2,1.01,15.51]],"ltp":2.5,"tv":239.01,"id":8444055},{"batb":[[0,1.31,477.51],[1,1.28,161.14],[2,1.01,15.51]],"ltp":1.67,"tv":2342.48,"id":8257852}]}]}
{"op":"mcm","clk":"1011815463","pt":1580657888240,"mc":[{"id":"1.168223929","rc":[{"batb":[[0,2.58,29.27]],"ltp":2.5,"tv":239.01,"id":8444055},{"batb":[[1,1.29,906.26],[2,1.28,902.66]],"batl":[[0,1.64,448.86],[1,1.65,238.95]],"ltp":1.67,"tv":2342.48,"id":8257852}]}]}
{"op":"mcm","clk":"1011816613","pt":1580657893272,"mc":[{"id":"1.168223929","rc":[{"batb":[[1,1.28,159.8],[2,1.01,15.51]],"ltp":1.67,"tv":2342.48,"id":8257852}]}]}
{"op":"mcm","clk":"1011816772","pt":1580657893932,"mc":[{"id":"1.168223929","rc":[{"batb":[[1,1.01,15.51],[2,1.01,0]],"ltp":2.5,"tv":239.01,"id":8444055},{"batb":[[0,1.28,159.8],[1,1.01,15.51],[2,1.01,0]],"ltp":1.67,"tv":2342.48,"id":8257852}]}]}
{"op":"mcm","clk":"1011817310","pt":1580657896249,"mc":[{"id":"1.168223929","rc":[{"batb":[[1,2.52,26.89],[2,2.3,39.73]],"batl":[[0,2.84,22.69]],"ltp":2.5,"tv":239.01,"id":8444055},{"batb":[[0,1.58,327.85],[1,1.57,355.21],[2,1.54,77.3]],"batl":[[2,1.66,42.01]],"ltp":1.67,"tv":2342.48,"id":8257852}]}]}
{"op":"mcm","clk":"1011820066","pt":1580657908049,"mc":[{"id":"1.168223929","rc":[{"batb":[[0,2.52,26.89],[1,2.3,39.73],[2,1.92,394.91]],"ltp":2.5,"tv":239.01,"id":8444055},{"batb":[[0,1.54,77.3],[1,1.4,451],[2,1.39,108.35]],"batl":[[0,1.66,42.01],[1,1.65,0],[2,1.66,0]],"ltp":1.67,"tv":2342.48,"id":8257852}]}]}
{"op":"mcm","clk":"1011820291","pt":1580657909060,"mc":[{"id":"1.168223929","rc":[{"batb":[[0,2.3,39.73],[1,1.92,394.91],[2,1.01,15.51]],"ltp":2.5,"tv":239.01,"id":8444055},{"batb":[[0,1.4,451],[1,1.39,108.35],[2,1.01,15.51]],"ltp":1.67,"tv":2342.48,"id":8257852}]}]}
{"op":"mcm","clk":"1011820620","pt":1580657910470,"mc":[{"id":"1.168223929","rc":[{"batb":[[0,1.4,939.6],[1,1.39,591.5]],"batl":[[0,1.76,243.43],[1,1.78,373.13]],"ltp":1.67,"tv":2342.48,"id":8257852}]}]}
{"op":"mcm","clk":"1011821089","pt":1580657912666,"mc":[{"id":"1.168223929","rc":[{"batb":[[0,1.4,451],[1,1.39,108.35]],"ltp":1.67,"tv":2342.48,"id":8257852}]}]}
{"op":"mcm","clk":"1011821740","pt":1580657915685,"mc":[{"id":"1.168223929","rc":[{"batb":[[0,1.54,362.8],[1,1.53,320.25],[2,1.4,451]],"batl":[[0,1.59,279.89],[1,1.6,267.36]],"ltp":1.67,"tv":2342.48,"id":8257852}]}]}
{"op":"mcm","clk":"1011822010","pt":1580657916866,"mc":[{"id":"1.168223929","rc":[{"batb":[[0,1.4,451],[1,1.39,108.35],[2,1.01,15.51]],"ltp":1.67,"tv":2342.48,"id":8257852}]}]}
{"op":"mcm","clk":"1011822708","pt":1580657920089,"mc":[{"id":"1.168223929","rc":[{"batb":[[0,1.4,939.6],[1,1.39,591.5]],"batl":[[0,1.76,243.43],[1,1.78,373.13]],"ltp":1.67,"tv":2342.48,"id":8257852}]}]}
{"op":"mcm","clk":"1011823972","pt":1580657926092,"mc":[{"id":"1.168223929","rc":[{"batb":[[0,1.4,451],[1,1.39,108.35]],"ltp":1.67,"tv":2342.48,"id":8257852}]}]}
{"op":"mcm","clk":"1011824224","pt":1580657927186,"mc":[{"id":"1.168223929","rc":[{"batb":[[1,1.01,15.51],[2,1.01,0]],"ltp":2.5,"tv":239.01,"id":8444055},{"batb":[[0,1.39,108.35],[1,1.01,15.51],[2,1.01,0]],"ltp":1.67,"tv":2342.48,"id":8257852}]}]}
{"op":"mcm","clk":"1011824683","pt":1580657929193,"mc":[{"id":"1.168223929","rc":[{"batb":[[1,2.12,49.41],[2,1.01,15.51]],"ltp":2.5,"tv":239.01,"id":8444055},{"batb":[[0,1.7,240.23],[1,1.69,50.12],[2,1.68,448.78]],"ltp":1.67,"tv":2342.48,"id":8257852}]}]}
{"op":"mcm","clk":"1011824890","pt":1580657930115,"mc":[{"id":"1.168223929","rc":[{"batb":[[1,2.28,32.77],[2,2.12,49.41]],"batl":[[0,2.54,26.89]],"ltp":2.5,"tv":239.01,"id":8444055},{"batl":[[1,1.78,415.14]],"ltp":1.67,"tv":2342.48,"id":8257852}]}]}
{"op":"mcm","clk":"1011828526","pt":1580657946210,"mc":[{"id":"1.168223929","rc":[{"batb":[[0,2.28,32.77],[1,2.12,49.41],[2,1.77,402.27]],"ltp":2.5,"tv":239.01,"id":8444055},{"batb":[[0,1.64,65.54],[1,1.52,73.41],[2,1.5,426.9]],"batl":[[0,1.78,42.01],[1,1.78,0]],"ltp":1.67,"tv":2342.48,"id":8257852}]}]}
{"op":"mcm","clk":"1011828725","pt":1580657947134,"mc":[{"id":"1.168223929","rc":[{"batb":[[0,2.12,49.41],[1,1.77,402.27],[2,1.01,15.51]],"ltp":2.5,"tv":239.01,"id":8444055},{"batb":[[0,1.52,73.41],[1,1.5,426.9],[2,1.01,15.51]],"ltp":1.67,"tv":2342.48,"id":8257852}]}]}
{"op":"mcm","clk":"1011829055","pt":1580657948652,"mc":[{"id":"1.168223929","rc":[{"batb":[[0,1.54,422.65],[1,1.53,320.54],[2,1.52,73.41]],"batl":[[0,1.87,311.9],[1,1.89,308.3]],"ltp":1.67,"tv":2342.48,"id":8257852}]}]}
{"op":"mcm","clk":"1011833836","pt":1580657970245,"mc":[{"id":"1.168223929","rc":[{"batb":[[0,1.52,73.41],[1,1.5,426.9],[2,1.01,15.51]],"ltp":1.67,"tv":2342.48,"id":8257852}]}]}
{"op":"mcm","clk":"1011834265","pt":1580657972267,"mc":[{"id":"1.168223929","rc":[{"batb":[[0,1.66,399.45],[1,1.65,241.14],[2,1.52,73.41]],"batl":[[0,1.73,377.56],[1,1.75,393.97]],"ltp":1.67,"tv":2342.48,"id":8257852}]}]}
{"op":"mcm","clk":"1011835351","pt":1580657977179,"mc":[{"id":"1.168223929","rc":[{"batb":[[0,1.52,73.41],[1,1.5,426.9],[2,1.01,15.51]],"ltp":1.67,"tv":2342.48,"id":8257852}]}]}
{"op":"mcm","clk":"1011836022","pt":1580657980180,"mc":[{"id":"1.168223929","rc":[{"batb":[[0,1.54,422.65],[1,1.53,320.54],[2,1.52,73.41]],"batl":[[0,1.87,311.9],[1,1.89,308.3]],"ltp":1.67,"tv":2342.48,"id":8257852}]}]}
{"op":"mcm","clk":"1011836463","pt":1580657982206,"mc":[{"id":"1.168223929","rc":[{"batb":[[1,1.01,15.51],[2,1.01,0]],"ltp":2.5,"tv":239.01,"id":8444055}]}]}
{"op":"mcm","clk":"1011836678","pt":1580657983038,"mc":[{"id":"1.168223929","rc":[{"batb":[[0,2.72,25.57],[1,2.3,39.34],[2,2.12,49.41]],"ltp":2.5,"tv":239.01,"id":8444055},{"batl":[[0,1.6,489.45],[1,1.61,260.49]],"ltp":1.67,"tv":2342.48,"id":8257852}]}]}
{"op":"mcm","clk":"1011836937","pt":1580657984074,"mc":[{"id":"1.168223929","rc":[{"batb":[[1,2.58,26.05],[2,2.3,39.34]],"batl":[[0,2.96,21]],"ltp":2.5,"tv":239.01,"id":8444055},{"batb":[[2,1.52,154.07]],"batl":[[2,1.63,42.01]],"ltp":1.67,"tv":2342.48,"id":8257852}]}]}
{"op":"mcm","clk":"1011838501","pt":1580657990989,"mc":[{"id":"1.168223929","rc":[{"batl":[[0,1.6,267.59],[1,1.63,42.01],[2,1.63,0]],"ltp":1.67,"tv":2342.48,"id":8257852}]}]}
{"op":"mcm","clk":"1011839140","pt":1580657994002,"mc":[{"id":"1.168223929","rc":[{"batl":[[0,1.59,245.44],[1,1.6,267.59],[2,1.63,42.01]],"ltp":1.67,"tv":2342.48,"id":8257852}]}]}
{"op":"mcm","clk":"1011841728","pt":1580658005927,"mc":[{"id":"1.168223929","rc":[{"batb":[[0,2.58,26.05],[1,2.3,39.34],[2,2.12,49.41]],"ltp":2.5,"tv":239.01,"id":8444055},{"batb":[[0,1.52,80.66],[1,1.38,448.45],[2,1.29,150.68]],"batl":[[0,1.63,42.01],[1,1.6,0],[2,1.63,0]],"ltp":1.67,"tv":2342.48,"id":8257852}]}]}
{"op":"mcm","clk":"1011842033","pt":1580658007195,"mc":[{"id":"1.168223929","rc":[{"batb":[[0,2.3,39.34],[1,2.12,49.41],[2,1.97,394.86]],"ltp":2.5,"tv":239.01,"id":8444055},{"batb":[[0,1.38,448.45],[1,1.29,150.68],[2,1.01,15.51]],"ltp":1.67,"tv":2342.48,"id":8257852}]}]}
{"op":"mcm","clk":"1011842459","pt":1580658009112,"mc":[{"id":"1.168223929","rc":[{"batb":[[1,1.97,394.86],[2,1.01,15.51]],"ltp":2.5,"tv":239.01,"id":8444055},{"batb":[[1,1.31,734.46],[2,1.3,828.52]],"batl":[[0,1.77,270.14],[1,1.79,366.38]],"ltp":1.67,"tv":2342.48,"id":8257852}]}]}
{"op":"mcm","clk":"1011842632","pt":1580658010028,"mc":[{"id":"1.168223929","rc":[{"batb":[[1,1.3,149.34],[2,1.01,15.51]],"ltp":1.67,"tv":2342.48,"id":8257852}]}]}
{"op":"mcm","clk":"1011843295","pt":1580658013211,"mc":[{"id":"1.168223929","rc":[{"batb":[[1,1.01,15.51],[2,1.01,0]],"ltp":2.5,"tv":239.01,"id":8444055},{"batb":[[0,1.7,410.45],[1,1.68,449.61],[2,1.3,149.34]],"ltp":1.67,"tv":2342.48,"id":8257852}]}]}
{"op":"mcm","clk":"1011843493","pt":1580658014136,"mc":[{"id":"1.168223929","rc":[{"batb":[[1,2.26,32.77],[2,2.1,51.14]],"batl":[[0,2.52,26.89]],"ltp":2.5,"tv":239.01,"id":8444055},{"batb":[[1,1.69,50.12],[2,1.68,449.61]],"batl":[[1,1.79,408.39]],"ltp":1.67,"tv":2342.48,"id":8257852}]}]}
{"op":"mcm","clk":"1011845560","pt":1580658024146,"mc":[{"id":"1.168223929","rc":[{"batb":[[0,1.69,50.12],[1,1.65,63.85],[2,1.51,76.16]],"batl":[[0,1.79,42.01],[1,1.79,0]],"ltp":1.67,"tv":2342.48,"id":8257852}]}]}
{"op":"mcm","clk":"1011845819","pt":1580658025235,"mc":[{"id":"1.168223929","rc":[{"batb":[[0,2.1,51.14],[1,1.77,402.27],[2,1.01,15.51]],"ltp":2.5,"tv":239.01,"id":8444055},{"batb":[[0,1.51,76.16],[1,1.5,426.9],[2,1.01,15.51]],"ltp":1.67,"tv":2342.48,"id":8257852}]}]}
{"op":"mcm","clk":"1011846260","pt":1580658027254,"mc":[{"id":"1.168223929","rc":[{"batb":[[0,1.53,394.75],[1,1.52,328.94],[2,1.51,76.16]],"batl":[[0,1.89,262.67],[1,1.91,298.56]],"ltp":1.67,"tv":2342.48,"id":8257852}]}]}
{"op":"mcm","clk":"1011850106","pt":1580658046180,"mc":[{"id":"1.168223929","rc":[{"batb":[[1,1.01,15.51],[2,1.01,0]],"ltp":2.5,"tv":239.01,"id":8444055}]}]}
{"op":"mcm","clk":"1011850323","pt":1580658047167,"mc":[{"id":"1.168223929","rc":[{"batl":[[0,1.59,273.62]],"ltp":1.67,"tv":2342.48,"id":8257852}]}]}
{"op":"mcm","clk":"1011850546","pt":1580658048146,"mc":[{"id":"1.168223929","rc":[{"batb":[[0,2.76,24.47],[1,2.62,25.21],[2,2.34,37.92]],"batl":[[0,3,21]],"ltp":2.5,"tv":239.01,"id":8444055},{"batb":[[2,1.51,158.5]],"batl":[[1,1.62,42.01]],"ltp":1.67,"tv":2342.48,"id":8257852}]}]}
{"op":"mcm","clk":"1011850999","pt":1580658050259,"mc":[{"id":"1.168223929","rc":[{"batl":[[0,1.59,513.79],[1,1.6,266.22],[2,1.62,42.01]],"ltp":1.67,"tv":2342.48,"id":8257852}]}]}
{"op":"mcm","clk":"1011854605","pt":1580658067877,"mc":[{"id":"1.168223929","rc":[{"batb":[[0,2.62,25.21],[1,2.34,37.92],[2,1.97,394.86]],"ltp":2.5,"tv":239.01,"id":8444055},{"batb":[[0,1.51,82.34],[1,1.38,448.45],[2,1.28,156.89]],"batl":[[0,1.62,42.01],[1,1.6,0],[2,1.62,0]],"ltp":1.67,"tv":2342.48,"id":8257852}]}]}
{"op":"mcm","clk":"1011854885","pt":1580658069218,"mc":[{"id":"1.168223929","rc":[{"batb":[[0,2.34,37.92],[1,1.97,394.86],[2,1.01,15.51]],"ltp":2.5,"tv":239.01,"id":8444055},{"batb":[[0,1.38,448.45],[1,1.28,156.89],[2,1.01,15.51]],"ltp":1.67,"tv":2342.48,"id":8257852}]}]}
{"op":"mcm","clk":"1011855271","pt":1580658071104,"mc":[{"id":"1.168223929","rc":[{"batb":[[0,2.32,38.32]],"ltp":2.5,"tv":239.01,"id":8444055},{"batb":[[1,1.29,155.63]],"ltp":1.67,"tv":2342.48,"id":8257852}]}]}
{"op":"mcm","clk":"1011855988","pt":1580658074801,"mc":[{"id":"1.168223929","rc":[{"batb":[[0,1.48,429.46],[1,1.47,377.11],[2,1.38,448.45]],"batl":[[0,1.53,417.6],[1,1.54,307.37]],"ltp":1.67,"tv":2342.48,"id":8257852}]}]}
{"op":"mcm","clk":"1011856926","pt":1580658079243,"mc":[{"id":"1.168223929","rc":[{"batb":[[0,1.38,448.45],[1,1.29,155.63],[2,1.01,15.51]],"ltp":1.67,"tv":2342.48,"id":8257852}]}]}
{"op":"mcm","clk":"1011857040","pt":1580658079835,"mc":[{"id":"1.168223929","rc":[{"batb":[[1,1.01,15.51],[2,1.01,0]],"ltp":2.5,"tv":239.01,"id":8444055},{"batb":[[0,1.29,155.63],[1,1.01,15.51],[2,1.01,0]],"ltp":1.67,"tv":2342.48,"id":8257852}]}]}
{"op":"mcm","clk":"1011857475","pt":1580658082040,"mc":[{"id":"1.168223929","rc":[{"batb":[[0,1.31,380.45],[1,1.3,672.55],[2,1.29,155.63]],"batl":[[0,1.76,283.85],[1,1.78,372.84]],"ltp":1.67,"tv":2342.48,"id":8257852}]}]}
{"op":"mcm","clk":"1011857595","pt":1580658082805,"mc":[{"id":"1.168223929","rc":[{"batb":[[0,1.29,155.63],[1,1.01,15.51],[2,1.29,0]],"ltp":1.67,"tv":2342.48,"id":8257852}]}]}
{"op":"mcm","clk":"1011858018","pt":1580658085102,"mc":[{"id":"1.168223929","rc":[{"batb":[[0,1.69,419.56],[1,1.67,459],[2,1.29,155.63]],"ltp":1.67,"tv":2342.48,"id":8257852}]}]}
{"op":"mcm","clk":"1011858215","pt":1580658086087,"mc":[{"id":"1.168223929","rc":[{"batb":[[1,2.28,32.77],[2,2.12,49.18]],"batl":[[0,2.56,26.89]],"ltp":2.5,"tv":239.01,"id":8444055},{"batb":[[1,1.67,510.77],[2,1.64,65.54]],"batl":[[1,1.78,414.85]],"ltp":1.67,"tv":2342.48,"id":8257852}]}]}
{"op":"mcm","clk":"1011861501","pt":1580658102207,"mc":[{"id":"1.168223929","rc":[{"batb":[[0,2.28,32.77],[1,2.12,49.18],[2,1.77,402.27]],"ltp":2.5,"tv":239.01,"id":8444055},{"batb":[[0,1.64,65.54],[1,1.5,426.9],[2,1.49,80.49]],"batl":[[0,1.78,42.01],[1,1.78,0]],"ltp":1.67,"tv":2342.48,"id":8257852}]}]}
{"op":"mcm","clk":"1011861686","pt":1580658103140,"mc":[{"id":"1.168223929","rc":[{"batb":[[0,2.12,49.18],[1,1.77,402.27],[2,1.01,15.51]],"ltp":2.5,"tv":239.01,"id":8444055},{"batb":[[0,1.5,426.9],[1,1.49,80.49],[2,1.01,15.51]],"ltp":1.67,"tv":2342.48,"id":8257852}]}]}
{"op":"mcm","clk":"1011862138","pt":1580658105270,"mc":[{"id":"1.168223929","rc":[{"batb":[[0,1.52,452.41],[1,1.51,337.82],[2,1.5,426.9]],"batl":[[0,1.88,264.08],[1,1.9,303.27]],"ltp":1.67,"tv":2342.48,"id":8257852}]}]}
{"op":"mcm","clk":"1011862363","pt":1580658106272,"mc":[{"id":"1.168223929","rc":[{"batb":[[0,1.5,426.9],[1,1.49,80.49],[2,1.01,15.51]],"ltp":1.67,"tv":2342.48,"id":8257852}]}]}
{"op":"mcm","clk":"1011863025","pt":1580658109253,"mc":[{"id":"1.168223929","rc":[{"batb":[[0,1.66,255.45],[1,1.65,240.65],[2,1.5,426.9]],"batl":[[0,1.72,310.92],[1,1.74,401.66]],"ltp":1.67,"tv":2342.48,"id":8257852}]}]}
{"op":"mcm","clk":"1011863661","pt":1580658112250,"mc":[{"id":"1.168223929","rc":[{"batb":[[0,1.5,426.9],[1,1.49,80.49],[2,1.01,15.51]],"ltp":1.67,"tv":2342.48,"id":8257852}]}]}
{"op":"mcm","clk":"1011864111","pt":1580658114522,"mc":[{"id":"1.168223929","rc":[{"batb":[[0,1.52,452.41],[1,1.51,337.82],[2,1.5,426.9]],"batl":[[0,1.88,264.08],[1,1.9,303.27]],"ltp":1.67,"tv":2342.48,"id":8257852}]}]}
{"op":"mcm","clk":"1011866879","pt":1580658127135,"mc":[{"id":"1.168223929","rc":[{"batb":[[1,1.01,15.51],[2,1.01,0]],"ltp":2.5,"tv":239.01,"id":8444055},{"batb":[[2,1.49,80.49]],"ltp":1.67,"tv":2342.48,"id":8257852}]}]}
{"op":"mcm","clk":"1011867095","pt":1580658128122,"mc":[{"id":"1.168223929","rc":[{"batl":[[0,3,21]],"ltp":2.5,"tv":239.01,"id":8444055},{"batb":[[2,1.5,84.02]],"batl":[[0,1.57,255.86],[1,1.58,279.94]],"ltp":1.67,"tv":2342.48,"id":8257852}]}]}
{"op":"mcm","clk":"1011867276","pt":1580658128927,"mc":[{"id":"1.168223929","rc":[{"batb":[[0,2.84,22.9],[1,2.64,25.21],[2,2.38,36.12]],"ltp":2.5,"tv":239.01,"id":8444055},{"batl":[[2,1.61,42.01]],"ltp":1.67,"tv":2342.48,"id":8257852}]}]}
{"op":"mcm","clk":"1011871820","pt":1580658150262,"mc":[{"id":"1.168223929","rc":[{"batb":[[0,2.64,25.21],[1,2.38,36.12],[2,2.04,394.09]],"ltp":2.5,"tv":239.01,"id":8444055},{"batb":[[0,1.5,84.02],[1,1.34,465.43],[2,1.27,163.66]],"batl":[[0,1.61,42.01],[1,1.58,0],[2,1.61,0]],"ltp":1.67,"tv":2342.48,"id":8257852}]}]}
{"op":"mcm","clk":"1011872026","pt":1580658151251,"mc":[{"id":"1.168223929","rc":[{"batb":[[0,2.38,36.12],[1,2.04,394.09],[2,1.01,15.51]],"ltp":2.5,"tv":239.01,"id":8444055},{"batb":[[0,1.34,465.43],[1,1.27,163.66],[2,1.01,15.51]],"ltp":1.67,"tv":2342.48,"id":8257852}]}]}
{"op":"mcm","clk":"1011872417","pt":1580658153141,"mc":[{"id":"1.168223929","rc":[{"batb":[[1,1.3,661.02],[2,1.29,706.44]],"batl":[[0,1.75,323.39],[1,1.77,379.57]],"ltp":1.67,"tv":2342.48,"id":8257852}]}]}
{"op":"mcm","clk":"1011872643","pt":1580658154232,"mc":[{"id":"1.168223929","rc":[{"batb":[[1,1.28,163.58],[2,1.01,15.51]],"ltp":1.67,"tv":2342.48,"id":8257852}]}]}
{"op":"mcm","clk":"1011873087","pt":1580658156245,"mc":[{"id":"1.168223929","rc":[{"batb":[[1,1.01,15.51],[2,1.01,0]],"ltp":2.5,"tv":239.01,"id":8444055},{"batb":[[0,1.28,163.58],[1,1.01,15.51],[2,1.01,0]],"ltp":1.67,"tv":2342.48,"id":8257852}]}]}
{"op":"mcm","clk":"1011873338","pt":1580658157253,"mc":[{"id":"1.168223929","rc":[{"batb":[[0,1.68,402.89],[1,1.67,230.88],[2,1.28,163.58]],"ltp":1.67,"tv":2342.48,"id":8257852}]}]}
{"op":"mcm","clk":"1011873533","pt":1580658158156,"mc":[{"id":"1.168223929","rc":[{"batb":[[1,2.32,31.09],[2,2.16,46.82]],"batl":[[0,2.58,26.05]],"ltp":2.5,"tv":239.01,"id":8444055},{"batb":[[2,1.65,54.61]],"batl":[[1,1.76,42.01],[2,1.77,379.57]],"ltp":1.67,"tv":2342.48,"id":8257852}]}]}
{"op":"mcm","clk":"1011873610","pt":1580658158569,"mc":[{"id":"1.168223929","rc":[{"batb":[[1,2.16,46.82],[2,1.01,15.51]],"ltp":2.5,"tv":239.01,"id":8444055},{"batl":[[1,1.77,379.57],[2,1.77,0]],"ltp":1.67,"tv":2342.48,"id":8257852}]}]}
{"op":"mcm","clk":"1011873937","pt":1580658160162,"mc":[{"id":"1.168223929","rc":[{"batb":[[1,2.3,31.93],[2,2.16,46.82]],"ltp":2.5,"tv":239.01,"id":8444055},{"batl":[[1,1.77,421.58]],"ltp":1.67,"tv":2342.48,"id":8257852}]}]}
{"op":"mcm","clk":"1011875611","pt":1580658168158,"mc":[{"id":"1.168223929","rc":[{"trd":[[1.68,391.54]],"batb":[[0,1.68,207.12]],"ltp":1.68,"tv":2734.02,"id":8257852}],"tv":2973.03}]}
{"op":"mcm","clk":"1011876036","pt":1580658170186,"mc":[{"id":"1.168223929","rc":[{"batb":[[0,2.3,31.93],[1,2.16,46.82],[2,1.82,401.24]],"ltp":2.5,"tv":239.01,"id":8444055},{"batb":[[0,1.63,66.38],[1,1.47,83.32],[2,1.46,435.7]],"batl":[[0,1.77,42.01],[1,1.77,0]],"ltp":1.68,"tv":2734.02,"id":8257852}]}]}
{"op":"mcm","clk":"1011876272","pt":1580658171266,"mc":[{"id":"1.168223929","rc":[{"batb":[[0,2.16,46.82],[1,1.82,401.24],[2,1.01,15.51]],"ltp":2.5,"tv":239.01,"id":8444055},{"batb":[[0,1.47,83.32],[1,1.46,435.7],[2,1.01,15.51]],"ltp":1.68,"tv":2734.02,"id":8257852}]}]}
{"op":"mcm","clk":"1011876769","pt":1580658173691,"mc":[{"id":"1.168223929","rc":[{"batb":[[0,1.51,402.8],[1,1.5,347.08],[2,1.47,83.32]],"batl":[[0,1.87,358.33],[1,1.89,308.28]],"ltp":1.68,"tv":2734.02,"id":8257852}]}]}
{"op":"mcm","clk":"1011877821","pt":1580658178491,"mc":[{"id":"1.168223929","rc":[{"batb":[[0,1.47,83.32],[1,1.46,435.7],[2,1.01,15.51]],"ltp":1.68,"tv":2734.02,"id":8257852}]}]}
{"op":"mcm","clk":"1011878638","pt":1580658182197,"mc":[{"id":"1.168223929","rc":[{"batb":[[0,1.64,415.57],[1,1.63,252.18],[2,1.47,83.32]],"batl":[[0,1.71,416.92],[1,1.73,409.28]],"ltp":1.68,"tv":2734.02,"id":8257852}]}]}
{"op":"mcm","clk":"1011878817","pt":1580658182967,"mc":[{"id":"1.168223929","rc":[{"batb":[[0,1.47,83.32],[1,1.46,435.7],[2,1.01,15.51]],"ltp":1.68,"tv":2734.02,"id":8257852}]}]}
{"op":"mcm","clk":"1011879737","pt":1580658187173,"mc":[{"id":"1.168223929","rc":[{"batb":[[1,1.01,15.51],[2,1.01,0]],"ltp":2.5,"tv":239.01,"id":8444055},{"batb":[[0,1.51,402.8],[1,1.5,347.08],[2,1.47,83.32]],"batl":[[0,1.56,336.86],[1,1.57,286.52]],"ltp":1.68,"tv":2734.02,"id":8257852}]}]}
{"op":"mcm","clk":"1011879964","pt":1580658188269,"mc":[{"id":"1.168223929","rc":[{"batb":[[0,2.9,21.87],[1,2.66,25.21],[2,2.42,34.46]],"batl":[[0,3.05,20.16]],"ltp":2.5,"tv":239.01,"id":8444055},{"batb":[[2,1.49,85.7]],"batl":[[2,1.6,42.01]],"ltp":1.68,"tv":2734.02,"id":8257852}]}]}
{"op":"mcm","clk":"1011884432","pt":1580658208098,"mc":[{"id":"1.168223929","rc":[{"batb":[[0,2.66,25.21],[1,2.42,34.46],[2,2.04,394.09]],"ltp":2.5,"tv":239.01,"id":8444055},{"batb":[[0,1.49,85.7],[1,1.34,465.43],[2,1.27,168.46]],"batl":[[0,1.6,42.01],[1,1.57,0],[2,1.6,0]],"ltp":1.68,"tv":2734.02,"id":8257852}]}]}
{"op":"mcm","clk":"1011884828","pt":1580658209896,"mc":[{"id":"1.168223929","rc":[{"batb":[[0,2.42,34.46],[1,2.04,394.09],[2,1.01,15.51]],"ltp":2.5,"tv":239.01,"id":8444055},{"batb":[[0,1.34,465.43],[1,1.27,168.46],[2,1.01,15.51]],"ltp":1.68,"tv":2734.02,"id":8257852}]}]}
{"op":"mcm","clk":"1011885468","pt":1580658212818,"mc":[{"id":"1.168223929","rc":[{"batb":[[0,1.46,375.17],[1,1.45,400.31],[2,1.34,465.43]],"batl":[[0,1.51,553.13],[1,1.52,323.3]],"ltp":1.68,"tv":2734.02,"id":8257852}]}]}
{"op":"mcm","clk":"1011886364","pt":1580658216819,"mc":[{"id":"1.168223929","rc":[{"batb":[[0,1.34,465.43],[1,1.27,168.46],[2,1.01,15.51]],"ltp":1.68,"tv":2734.02,"id":8257852}]}]}
{"op":"mcm","clk":"1011886818","pt":1580658218938,"mc":[{"id":"1.168223929","rc":[{"batb":[[1,1.01,15.51],[2,1.01,0]],"ltp":2.5,"tv":239.01,"id":8444055},{"batb":[[0,1.27,168.46],[1,1.01,15.51],[2,1.01,0]],"ltp":1.68,"tv":2734.02,"id":8257852}]}]}
{"op":"mcm","clk":"1011886997","pt":1580658219729,"mc":[{"id":"1.168223929","rc":[{"batb":[[0,1.29,778.37],[1,1.28,742.75],[2,1.27,168.46]],"batl":[[0,1.73,305.88],[1,1.75,394.93]],"ltp":1.68,"tv":2734.02,"id":8257852}]}]}
{"op":"mcm","clk":"1011887924","pt":1580658223895,"mc":[{"id":"1.168223929","rc":[{"batl":[[0,1.33,799.8],[1,1.34,554.46]],"ltp":1.68,"tv":2734.02,"id":8257852}]}]}
{"op":"mcm","clk":"1011888235","pt":1580658225231,"mc":[{"id":"1.168223929","rc":[{"batb":[[0,4.1,43.83],[1,2.92,21.32],[2,1.01,15.51]],"batl":[[0,4.4,11.76]],"ltp":2.5,"tv":239.01,"id":8444055},{"batb":[[0,1.29,922.88]],"batl":[[2,1.36,42.01]],"ltp":1.68,"tv":2734.02,"id":8257852}]}]}
{"op":"mcm","clk":"1011888323","pt":1580658225614,"mc":[{"id":"1.168223929","rc":[{"batb":[[2,2.52,381.46]],"ltp":2.5,"tv":239.01,"id":8444055}]}]}
{"op":"mcm","clk":"1011888926","pt":1580658228215,"mc":[{"id":"1.168223929","rc":[{"batb":[[1,3.8,14.28],[2,2.92,21.32]],"ltp":2.5,"tv":239.01,"id":8444055}]}]}
{"op":"mcm","clk":"1011891090","pt":1580658238158,"mc":[{"id":"1.168223929","rc":[{"trd":[[1.29,223.5]],"batb":[[0,1.29,811.13]],"ltp":1.29,"tv":2957.51,"id":8257852}],"tv":3196.53}]}
{"op":"mcm","clk":"1011891729","pt":1580658241135,"mc":[{"id":"1.168223929","rc":[{"batb":[[0,1.29,881.94]],"ltp":1.29,"tv":2957.51,"id":8257852}]}]}
{"op":"mcm","clk":"1011892654","pt":1580658245563,"mc":[{"id":"1.168223929","rc":[{"batb":[[0,3.8,14.28],[1,2.92,21.32],[2,2.52,381.46]],"ltp":2.5,"tv":239.01,"id":8444055},{"batb":[[0,1.29,144.51],[1,1.2,530.86],[2,1.04,1128.69]],"batl":[[0,1.36,42.01],[1,1.34,0],[2,1.36,0]],"ltp":1.29,"tv":2957.51,"id":8257852}]}]}
{"op":"mcm","clk":"1011892985","pt":1580658247107,"mc":[{"id":"1.168223929","rc":[{"batb":[[2,1.01,15.51]],"ltp":2.5,"tv":239.01,"id":8444055},{"batb":[[1,1.04,1128.69],[2,1.01,15.51]],"ltp":1.29,"tv":2957.51,"id":8257852}]}]}
{"op":"mcm","clk":"1011893175","pt":1580658247977,"mc":[{"id":"1.168223929","rc":[{"batb":[[0,2.92,21.32],[1,1.01,15.51],[2,1.01,0]],"ltp":2.5,"tv":239.01,"id":8444055},{"batb":[[0,1.04,1128.69],[1,1.01,15.51],[2,1.01,0]],"ltp":1.29,"tv":2957.51,"id":8257852}]}]}
{"op":"mcm","clk":"1011893513","pt":1580658249268,"mc":[{"id":"1.168223929","rc":[{"batb":[[0,1.05,1619.8],[1,1.04,1958.06],[2,1.01,15.51]],"batl":[[0,1.55,429.73],[1,1.56,293.69]],"ltp":1.29,"tv":2957.51,"id":8257852}]}]}
{"op":"mcm","clk":"1011893659","pt":1580658249985,"mc":[{"id":"1.168223929","rc":[{"batb":[[0,1.04,1128.69],[1,1.01,15.51],[2,1.01,0]],"ltp":1.29,"tv":2957.51,"id":8257852}]}]}
{"op":"mcm","clk":"1011894146","pt":1580658252241,"mc":[{"id":"1.168223929","rc":[{"batl":[[2,1.57,42.01]],"ltp":1.29,"tv":2957.51,"id":8257852}]}]}
{"op":"mcm","clk":"1011894343","pt":1580658253256,"mc":[{"id":"1.168223929","rc":[{"batb":[[1,2.74,23.53],[2,2.44,33.75]],"batl":[[0,3.1,19.32]],"ltp":2.5,"tv":239.01,"id":8444055},{"batb":[[0,1.5,344.4],[1,1.49,357.17],[2,1.48,87.38]],"batl":[[2,1.58,42.01]],"ltp":1.29,"tv":2957.51,"id":8257852}]}]}
{"op":"mcm","clk":"1011896565","pt":1580658264195,"mc":[{"id":"1.168223929","rc":[{"batb":[[0,1.48,87.38],[1,1.47,85.13],[2,1.34,465.43]],"batl":[[0,1.58,42.01],[1,1.56,0],[2,1.58,0]],"ltp":1.29,"tv":2957.51,"id":8257852}]}]}
{"op":"mcm","clk":"1011896783","pt":1580658265267,"mc":[{"id":"1.168223929","rc":[{"batb":[[0,2.44,33.75],[1,2.04,394.09],[2,1.01,15.51]],"ltp":2.5,"tv":239.01,"id":8444055},{"batb":[[0,1.34,465.43],[1,1.26,172.94],[2,1.01,15.51]],"ltp":1.29,"tv":2957.51,"id":8257852}]}]}
{"op":"mcm","clk":"1011897161","pt":1580658267191,"mc":[{"id":"1.168223929","rc":[{"batl":[[0,1.72,338.78],[1,1.74,402.63]],"ltp":1.29,"tv":2957.51,"id":8257852}]}]}
{"op":"mcm","clk":"1011897571","pt":1580658269190,"mc":[{"id":"1.168223929","rc":[{"batb":[[1,1.01,15.51],[2,1.01,0]],"ltp":2.5,"tv":239.01,"id":8444055},{"batb":[[0,1.26,172.94],[1,1.01,15.51],[2,1.01,0]],"ltp":1.29,"tv":2957.51,"id":8257852}]}]}
{"op":"mcm","clk":"1011897774","pt":1580658270163,"mc":[{"id":"1.168223929","rc":[{"batb":[[0,1.65,472.41],[1,1.64,247.24],[2,1.26,172.94]],"ltp":1.29,"tv":2957.51,"id":8257852}]}]}
{"op":"mcm","clk":"1011898057","pt":1580658271177,"mc":[{"id":"1.168223929","rc":[{"batb":[[1,2.2,44.3],[2,1.01,15.51]],"ltp":2.5,"tv":239.01,"id":8444055},{"batb":[[2,1.62,57.99]],"ltp":1.29,"tv":2957.51,"id":8257852}]}]}
{"op":"mcm","clk":"1011898250","pt":1580658272202,"mc":[{"id":"1.168223929","rc":[{"batb":[[1,2.36,30.25],[2,2.2,44.3]],"batl":[[0,2.64,25.21]],"ltp":2.5,"tv":239.01,"id":8444055},{"batl":[[1,1.74,444.64]],"ltp":1.29,"tv":2957.51,"id":8257852}]}]}
{"op":"mcm","clk":"1011900315","pt":1580658282194,"mc":[{"id":"1.168223929","rc":[{"batb":[[0,1.62,57.99],[1,1.61,68.06],[2,1.46,435.7]],"batl":[[0,1.74,42.01],[1,1.74,0]],"ltp":1.29,"tv":2957.51,"id":8257852}]}]}
{"op":"mcm","clk":"1011900537","pt":1580658283221,"mc":[{"id":"1.168223929","rc":[{"batb":[[0,2.2,44.3],[1,1.82,401.24],[2,1.01,15.51]],"ltp":2.5,"tv":239.01,"id":8444055},{"batb":[[0,1.46,435.7],[1,1.45,89.3],[2,1.01,15.51]],"ltp":1.29,"tv":2957.51,"id":8257852}]}]}
{"op":"mcm","clk":"1011900922","pt":1580658285207,"mc":[{"id":"1.168223929","rc":[{"batl":[[0,1.84,324.25],[1,1.86,324.62]],"ltp":1.29,"tv":2957.51,"id":8257852}]}]}
{"op":"mcm","clk":"1011901328","pt":1580658287218,"mc":[{"id":"1.168223929","rc":[{"batb":[[0,1.45,89.3],[1,1.01,15.51],[2,1.01,0]],"ltp":1.29,"tv":2957.51,"id":8257852}]}]}
{"op":"mcm","clk":"1011901555","pt":1580658288206,"mc":[{"id":"1.168223929","rc":[{"batb":[[1,2.16,36.13],[2,1.82,401.24]],"batl":[[0,2.4,29.41]],"ltp":2.5,"tv":239.01,"id":8444055},{"batb":[[0,1.76,400.35],[1,1.74,398.73],[2,1.71,58.81]],"batl":[[2,1.88,42.01]],"ltp":1.29,"tv":2957.51,"id":8257852}]}]}
{"op":"mcm","clk":"1011901783","pt":1580658289255,"mc":[{"id":"1.168223929","rc":[{"batb":[[2,1.89,36.04]],"ltp":2.5,"tv":239.01,"id":8444055},{"batb":[[1,1.74,444.13]],"ltp":1.29,"tv":2957.51,"id":8257852}]}]}
{"op":"mcm","clk":"1011905511","pt":1580658306164,"mc":[{"id":"1.168223929","rc":[{"trd":[[2.2,33.02]],"batb":[[0,2.2,27.79]],"ltp":2.2,"tv":272.03,"id":8444055}],"tv":3229.55}]}
{"op":"mcm","clk":"1011906592","pt":1580658311272,"mc":[{"id":"1.168223929","rc":[{"batb":[[0,1.89,36.04],[1,1.82,401.24],[2,1.01,15.51]],"ltp":2.2,"tv":272.03,"id":8444055},{"batb":[[0,1.62,57.6],[1,1.52,425.49],[2,1.01,15.51]],"ltp":1.29,"tv":2957.51,"id":8257852}]}]}
{"op":"mcm","clk":"1011907178","pt":1580658314191,"mc":[{"id":"1.168223929","rc":[{"batb":[[1,1.86,36.35],[2,1.82,401.24]],"ltp":2.2,"tv":272.03,"id":8444055},{"batb":[[0,1.65,426.43],[1,1.64,247.13],[2,1.63,57.12]],"batl":[[0,2.14,231.48],[1,2.16,207.9]],"ltp":1.29,"tv":2957.51,"id":8257852}]}]}
{"op":"mcm","clk":"1011907390","pt":1580658315171,"mc":[{"id":"1.168223929","rc":[{"batb":[[0,1.86,36.35],[1,1.82,401.24],[2,1.01,15.51]],"ltp":2.2,"tv":272.03,"id":8444055}]}]}
{"op":"mcm","clk":"1011908180","pt":1580658318998,"mc":[{"id":"1.168223929","rc":[{"batl":[[0,1.72,382.18],[1,1.74,402.47]],"ltp":1.29,"tv":2957.51,"id":8257852}]}]}
{"op":"mcm","clk":"1011908422","pt":1580658320170,"mc":[{"id":"1.168223929","rc":[{"batb":[[0,2.4,34.31],[1,2.32,31.09],[2,2.1,50.75]],"batl":[[0,2.62,25.21]],"ltp":2.2,"tv":272.03,"id":8444055},{"batb":[[2,1.63,123.5]],"batl":[[2,1.76,42.01]],"ltp":1.29,"tv":2957.51,"id":8257852}]}]}
{"op":"mcm","clk":"1011909834","pt":1580658327270,"mc":[{"id":"1.168223929","rc":[{"batb":[[0,2.1,50.75],[1,1.82,401.24],[2,1.01,15.51]],"ltp":2.2,"tv":272.03,"id":8444055},{"batb":[[0,1.55,67.98],[1,1.52,425.49],[2,1.01,15.51]],"ltp":1.29,"tv":2957.51,"id":8257852}]}]}
{"op":"mcm","clk":"1011910428","pt":1580658330221,"mc":[{"id":"1.168223929","rc":[{"batb":[[0,1.58,423.64],[1,1.57,290.74],[2,1.55,67.98]],"ltp":1.29,"tv":2957.51,"id":8257852}]}]}
{"op":"mcm","clk":"1011910819","pt":1580658332246,"mc":[{"id":"1.168223929","rc":[{"batb":[[1,1.01,15.51],[2,1.01,0]],"ltp":2.2,"tv":272.03,"id":8444055}]}]}
{"op":"mcm","clk":"1011911023","pt":1580658333229,"mc":[{"id":"1.168223929","rc":[{"batb":[[0,2.18,580.86],[1,2.1,50.75],[2,1.01,15.51]],"ltp":2.2,"tv":272.03,"id":8444055},{"batl":[[0,1.64,362.77],[1,1.65,239.91]],"ltp":1.29,"tv":2957.51,"id":8257852}]}]}
{"op":"mcm","clk":"1011911225","pt":1580658334242,"mc":[{"id":"1.168223929","rc":[{"batb":[[0,2.6,28.09],[1,2.46,28.57],[2,2.34,36.74]],"batl":[[0,2.8,22.69]],"ltp":2.2,"tv":272.03,"id":8444055},{"batb":[[2,1.56,74.78]],"batl":[[2,1.67,42.01]],"ltp":1.29,"tv":2957.51,"id":8257852}]}]}
{"op":"mcm","clk":"1011913246","pt":1580658344192,"mc":[{"id":"1.168223929","rc":[{"batb":[[0,1.56,74.78],[1,1.55,67.98],[2,1.51,74.98]],"batl":[[0,1.67,42.01],[1,1.65,0],[2,1.67,0]],"ltp":1.29,"tv":2957.51,"id":8257852}]}]}
{"op":"mcm","clk":"1011913460","pt":1580658345251,"mc":[{"id":"1.168223929","rc":[{"batb":[[0,2.34,36.74],[1,1.92,394.91],[2,1.01,15.51]],"ltp":2.2,"tv":272.03,"id":8444055},{"batb":[[0,1.51,74.98],[1,1.4,451],[2,1.01,15.51]],"ltp":1.29,"tv":2957.51,"id":8257852}]}]}
{"op":"mcm","clk":"1011914042","pt":1580658348248,"mc":[{"id":"1.168223929","rc":[{"batb":[[0,1.54,479.77],[1,1.53,321.71],[2,1.51,74.98]],"batl":[[0,1.73,237.12],[1,1.75,395.55]],"ltp":1.29,"tv":2957.51,"id":8257852}]}]}
{"op":"mcm","clk":"1011914138","pt":1580658348636,"mc":[{"id":"1.168223929","rc":[{"batb":[[0,1.51,74.98],[1,1.4,451],[2,1.01,15.51]],"ltp":1.29,"tv":2957.51,"id":8257852}]}]}
{"op":"mcm","clk":"1011915773","pt":1580658356887,"mc":[{"id":"1.168223929","rc":[{"batb":[[0,1.54,479.77],[1,1.53,321.71],[2,1.51,74.98]],"batl":[[0,1.73,237.12],[1,1.75,395.55]],"ltp":1.29,"tv":2957.51,"id":8257852}]}]}
{"op":"mcm","clk":"1011916872","pt":1580658362268,"mc":[{"id":"1.168223929","rc":[{"batb":[[0,2.7,24.94],[1,2.58,28.64],[2,2.56,26.89]],"batl":[[0,2.92,21.85]],"ltp":2.2,"tv":272.03,"id":8444055},{"batb":[[2,1.52,80.66]],"batl":[[0,1.6,440.8],[1,1.61,261.48],[2,1.63,42.01]],"ltp":1.29,"tv":2957.51,"id":8257852}]}]}
{"op":"mcm","clk":"1011919045","pt":1580658373061,"mc":[{"id":"1.168223929","rc":[{"trd":[[2.7,4.54]],"batb":[[0,2.7,22.67]],"ltp":2.7,"tv":276.57,"id":8444055}],"tv":3234.09}]}
{"op":"mcm","clk":"1011919522","pt":1580658375262,"mc":[{"id":"1.168223929","rc":[{"batb":[[0,2.58,28.64],[1,1.92,394.91],[2,1.01,15.51]],"ltp":2.7,"tv":276.57,"id":8444055},{"batb":[[0,1.53,321.71],[1,1.49,80.65],[2,1.4,451]],"ltp":1.29,"tv":2957.51,"id":8257852}]}]}
{"op":"mcm","clk":"1011920139","pt":1580658378266,"mc":[{"id":"1.168223929","rc":[{"batb":[[1,2.56,28.64],[2,1.92,394.91]],"ltp":2.7,"tv":276.57,"id":8444055},{"batb":[[1,1.52,329.38],[2,1.49,80.65]],"batl":[[0,1.64,466.31],[1,1.65,239.59]],"ltp":1.29,"tv":2957.51,"id":8257852}]}]}
{"op":"mcm","clk":"1011920323","pt":1580658378983,"mc":[{"id":"1.168223929","rc":[{"batb":[[0,2.56,28.64],[1,1.92,394.91],[2,1.01,15.51]],"ltp":2.7,"tv":276.57,"id":8444055},{"batb":[[1,1.49,80.49],[2,1.4,451]],"ltp":1.29,"tv":2957.51,"id":8257852}]}]}
{"op":"mcm","clk":"1011920736","pt":1580658381068,"mc":[{"id":"1.168223929","rc":[{"batb":[[1,1.01,15.51],[2,1.01,0]],"ltp":2.7,"tv":276.57,"id":8444055},{"batb":[[2,1.01,15.51]],"ltp":1.29,"tv":2957.51,"id":8257852}]}]}
{"op":"mcm","clk":"1011920961","pt":1580658382191,"mc":[{"id":"1.168223929","rc":[{"batb":[[1,1.52,329.42],[2,1.49,80.49]],"batl":[[0,1.58,338.25],[1,1.59,274.06]],"ltp":1.29,"tv":2957.51,"id":8257852}]}]}
{"op":"mcm","clk":"1011921185","pt":1580658383220,"mc":[{"id":"1.168223929","rc":[{"batb":[[0,2.8,22.82],[1,2.5,30.69],[2,1.01,15.51]],"ltp":2.7,"tv":276.57,"id":8444055},{"batl":[[2,3,3.86]],"ltp":1.29,"tv":2957.51,"id":8257852}]}]}
{"op":"mcm","clk":"1011921387","pt":1580658384192,"mc":[{"id":"1.168223929","rc":[{"batb":[[1,2.62,25.21],[2,2.5,30.69]],"batl":[[0,3,21]],"ltp":2.7,"tv":276.57,"id":8444055},{"batb":[[0,1.52,329.42],[1,1.51,82.34]],"batl":[[2,1.61,42.01]],"ltp":1.29,"tv":2957.51,"id":8257852}]}]}
{"op":"mcm","clk":"1011921873","pt":1580658386590,"mc":[{"id":"1.168223929","rc":[{"batb":[[0,1.52,556.29],[1,1.51,422.42]],"batl":[[0,1.58,446.27]],"ltp":1.29,"tv":2957.51,"id":8257852}]}]}
{"op":"mcm","clk":"1011922741","pt":1580658391114,"mc":[{"id":"1.168223929","rc":[{"batb":[[0,2.78,23.37],[2,2.48,31.32]],"ltp":2.7,"tv":276.57,"id":8444055},{"batb":[[0,1.52,416.07],[2,1.49,79.15]],"batl":[[0,1.58,281.9],[1,1.61,42.01],[2,3,3.86]],"ltp":1.29,"tv":2957.51,"id":8257852}]}]}
{"op":"mcm","clk":"1011923372","pt":1580658394130,"mc":[{"id":"1.168223929","rc":[{"batl":[[0,1.57,301.2],[1,1.58,281.9],[2,1.61,42.01]],"ltp":1.29,"tv":2957.51,"id":8257852}]}]}
{"op":"mcm","clk":"1011924908","pt":1580658402214,"mc":[{"id":"1.168223929","rc":[{"trd":[[1.52,194.54]],"batb":[[0,1.52,345.31]],"ltp":1.52,"tv":3098.99,"id":8257852}],"tv":3375.57}]}
{"op":"mcm","clk":"1011925642","pt":1580658406234,"mc":[{"id":"1.168223929","rc":[{"batl":[[0,1.57,386.65]],"ltp":1.52,"tv":3098.99,"id":8257852}]}]}
{"op":"mcm","clk":"1011937789","pt":1580658470252,"mc":[{"id":"1.168223929","rc":[{"batb":[[0,1.51,82.34],[1,1.49,79.15],[2,1.35,122.59]],"batl":[[0,1.61,42.01],[1,3,3.86],[2,1.61,0]],"ltp":1.52,"tv":3098.99,"id":8257852}]}]}
{"op":"mcm","clk":"1011937981","pt":1580658471218,"mc":[{"id":"1.168223929","rc":[{"batb":[[0,2.48,31.32],[1,2.04,394.09],[2,1.01,15.51]],"ltp":2.7,"tv":276.57,"id":8444055},{"batb":[[0,1.35,122.59],[1,1.34,465.43],[2,1.01,15.51]],"batl":[[0,3,3.86],[1,3,0]],"ltp":1.52,"tv":3098.99,"id":8257852}]}]}
{"op":"mcm","clk":"1011938357","pt":1580658473116,"mc":[{"id":"1.168223929","rc":[{"batl":[[0,1.67,294.94],[1,1.69,446.93],[2,3,3.86]],"ltp":1.52,"tv":3098.99,"id":8257852}]}]}
{"op":"mcm","clk":"1011938567","pt":1580658474135,"mc":[{"id":"1.168223929","rc":[{"batb":[[1,1.01,15.51],[2,1.01,0]],"ltp":2.7,"tv":276.57,"id":8444055},{"batb":[[1,1.01,15.51],[2,1.01,0]],"ltp":1.52,"tv":3098.99,"id":8257852}]}]}
{"op":"mcm","clk":"1011938763","pt":1580658475128,"mc":[{"id":"1.168223929","rc":[{"batb":[[0,1.61,412.68],[1,1.6,271.96],[2,1.35,122.59]],"ltp":1.52,"tv":3098.99,"id":8257852}]}]}
{"op":"mcm","clk":"1011938978","pt":1580658476239,"mc":[{"id":"1.168223929","rc":[{"batb":[[1,2.42,29.41],[2,2.3,38.87]],"batl":[[0,2.72,24.37]],"ltp":2.7,"tv":276.57,"id":8444055},{"batb":[[2,1.59,61.84]],"batl":[[2,1.71,42.01]],"ltp":1.52,"tv":3098.99,"id":8257852}]}]}
{"op":"mcm","clk":"1011940899","pt":1580658486028,"mc":[{"id":"1.168223929","rc":[{"batb":[[0,2.42,29.41],[1,2.3,38.87],[2,1.86,398.62]],"ltp":2.7,"tv":276.57,"id":8444055},{"batb":[[0,1.58,72.26],[1,1.46,87.1],[2,1.44,436.18]],"batl":[[0,1.71,42.01],[1,3,3.86],[2,1.71,0]],"ltp":1.52,"tv":3098.99,"id":8257852}]}]}
{"op":"mcm","clk":"1011941157","pt":1580658487247,"mc":[{"id":"1.168223929","rc":[{"batb":[[0,2.3,38.87],[1,1.86,398.62],[2,1.01,15.51]],"ltp":2.7,"tv":276.57,"id":8444055},{"batb":[[0,1.46,87.1],[1,1.44,436.18],[2,1.01,15.51]],"batl":[[0,3,3.86],[1,3,0]],"ltp":1.52,"tv":3098.99,"id":8257852}]}]}
{"op":"mcm","clk":"1011942301","pt":1580658492948,"mc":[{"id":"1.168223929","rc":[{"batb":[[0,1.58,505.79],[1,1.57,292.55],[2,1.46,87.1]],"batl":[[0,1.64,293.42],[1,1.65,241.45],[2,3,3.86]],"ltp":1.52,"tv":3098.99,"id":8257852}]}]}
{"op":"mcm","clk":"1011942700","pt":1580658495131,"mc":[{"id":"1.168223929","rc":[{"batb":[[0,1.46,87.1],[1,1.44,436.18],[2,1.01,15.51]],"batl":[[0,3,3.86],[1,1.65,0],[2,3,0]],"ltp":1.52,"tv":3098.99,"id":8257852}]}]}
{"op":"mcm","clk":"1011943224","pt":1580658498163,"mc":[{"id":"1.168223929","rc":[{"batb":[[0,1.48,589.39],[1,1.47,381.64],[2,1.46,87.1]],"batl":[[0,1.76,334.88],[1,1.78,375.44],[2,3,3.86]],"ltp":1.52,"tv":3098.99,"id":8257852}]}]}
{"op":"mcm","clk":"1011944054","pt":1580658503173,"mc":[{"id":"1.168223929","rc":[{"batb":[[0,1.46,87.1],[1,1.44,436.18],[2,1.01,15.51]],"ltp":1.52,"tv":3098.99,"id":8257852}]}]}
{"op":"mcm","clk":"1011944451","pt":1580658505134,"mc":[{"id":"1.168223929","rc":[{"batb":[[1,1.01,15.51],[2,1.01,0]],"ltp":1.52,"tv":3098.99,"id":8257852}]}]}
{"op":"mcm","clk":"1011944635","pt":1580658506152,"mc":[{"id":"1.168223929","rc":[{"batb":[[1,2.2,44.22],[2,1.86,398.62]],"ltp":2.7,"tv":276.57,"id":8444055},{"batb":[[0,1.69,376.24],[1,1.68,51.22],[2,1.67,462.01]],"ltp":1.52,"tv":3098.99,"id":8257852}]}]}
{"op":"mcm","clk":"1011944663","pt":1580658506299,"mc":[{"id":"1.168223929","rc":[{"batb":[[1,2.26,32.77],[2,2.2,44.22]],"batl":[[0,2.52,26.89]],"ltp":2.7,"tv":276.57,"id":8444055},{"batl":[[2,1.8,42.01]],"ltp":1.52,"tv":3098.99,"id":8257852}]}]}
{"op":"mcm","clk":"1011946952","pt":1580658518242,"mc":[{"id":"1.168223929","rc":[{"batb":[[0,2.26,32.77],[1,2.2,44.22],[2,1.86,398.62]],"ltp":2.7,"tv":276.57,"id":8444055},{"batb":[[0,1.65,63.85],[1,1.57,65.31],[2,1.5,426.9]],"batl":[[0,1.8,42.01],[1,3,3.86],[2,1.8,0]],"ltp":1.52,"tv":3098.99,"id":8257852}]}]}
{"op":"mcm","clk":"1011947135","pt":1580658519204,"mc":[{"id":"1.168223929","rc":[{"batb":[[0,2.2,44.22],[1,1.86,398.62],[2,1.01,15.51]],"ltp":2.7,"tv":276.57,"id":8444055},{"batb":[[0,1.57,65.31],[1,1.5,426.9],[2,1.01,15.51]],"batl":[[0,3,3.86],[1,3,0]],"ltp":1.52,"tv":3098.99,"id":8257852}]}]}
{"op":"mcm","clk":"1011947934","pt":1580658524020,"mc":[{"id":"1.168223929","rc":[{"batb":[[0,1.67,406.37],[1,1.66,237.59],[2,1.57,65.31]],"batl":[[0,1.74,355.59],[1,1.76,389.55],[2,3,3.86]],"ltp":1.52,"tv":3098.99,"id":8257852}]}]}
{"op":"mcm","clk":"1011948504","pt":1580658527237,"mc":[{"id":"1.168223929","rc":[{"batb":[[0,1.57,65.31],[1,1.5,426.9],[2,1.01,15.51]],"batl":[[0,3,3.86],[1,1.76,0],[2,3,0]],"ltp":1.52,"tv":3098.99,"id":8257852}]}]}
{"op":"mcm","clk":"1011949068","pt":1580658530260,"mc":[{"id":"1.168223929","rc":[{"batb":[[0,1.6,388.65],[1,1.59,278.32],[2,1.57,65.31]],"batl":[[0,1.82,346.22],[1,1.84,337.43],[2,3,3.86]],"ltp":1.52,"tv":3098.99,"id":8257852}]}]}
{"op":"mcm","clk":"1011949908","pt":1580658535250,"mc":[{"id":"1.168223929","rc":[{"batb":[[0,1.57,65.31],[1,1.5,426.9],[2,1.01,15.51]],"ltp":1.52,"tv":3098.99,"id":8257852}]}]}
{"op":"mcm","clk":"1011950422","pt":1580658538233,"mc":[{"id":"1.168223929","rc":[{"batb":[[1,2.16,36.13],[2,1.86,398.62]],"batl":[[0,2.42,29.41]],"ltp":2.7,"tv":276.57,"id":8444055},{"batb":[[0,1.75,228.51],[1,1.73,407.97],[2,1.7,59.65]],"batl":[[2,1.86,42.01]],"ltp":1.52,"tv":3098.99,"id":8257852}]}]}
{"op":"mcm","clk":"1011950570","pt":1580658539143,"mc":[{"id":"1.168223929","rc":[{"batb":[[2,2.14,47.84]],"ltp":2.7,"tv":276.57,"id":8444055},{"batb":[[1,1.74,45.48],[2,1.73,407.97]],"ltp":1.52,"tv":3098.99,"id":8257852}]}]}
{"op":"mcm","clk":"1011952518","pt":1580658550259,"mc":[{"id":"1.168223929","rc":[{"batb":[[0,2.16,36.13],[1,2.14,47.84],[2,1.86,398.62]],"ltp":2.7,"tv":276.57,"id":8444055},{"batb":[[0,1.7,59.65],[1,1.67,52.32],[2,1.5,426.9]],"batl":[[0,1.84,237.71],[1,1.86,42.01],[2,3,3.86]],"ltp":1.52,"tv":3098.99,"id":8257852}]}]}
{"op":"mcm","clk":"1011952707","pt":1580658551239,"mc":[{"id":"1.168223929","rc":[{"batb":[[0,2.14,47.84],[1,1.86,398.62],[2,1.01,15.51]],"ltp":2.7,"tv":276.57,"id":8444055},{"batb":[[0,1.67,52.32],[1,1.5,426.9],[2,1.01,15.51]],"batl":[[1,3,3.86],[2,3,0]],"ltp":1.52,"tv":3098.99,"id":8257852}]}]}
{"op":"mcm","clk":"1011953036","pt":1580658553264,"mc":[{"id":"1.168223929","rc":[{"batb":[[0,1.7,293.45],[1,1.68,451.9],[2,1.67,52.32]],"batl":[[1,1.86,326.27],[2,3,3.86]],"ltp":1.52,"tv":3098.99,"id":8257852}]}]}
{"op":"mcm","clk":"1011954123","pt":1580658559264,"mc":[{"id":"1.168223929","rc":[{"batb":[[0,1.67,52.32],[1,1.5,426.9],[2,1.01,15.51]],"ltp":1.52,"tv":3098.99,"id":8257852}]}]}
{"op":"mcm","clk":"1011954185","pt":1580658559568,"mc":[{"id":"1.168223929","rc":[{"batb":[[1,1.01,15.51],[2,1.01,0]],"ltp":2.7,"tv":276.57,"id":8444055},{"batb":[[1,1.01,15.51],[2,1.01,0]],"ltp":1.52,"tv":3098.99,"id":8257852}]}]}
{"op":"mcm","clk":"1011954663","pt":1580658562180,"mc":[{"id":"1.168223929","rc":[{"batb":[[1,1.83,38.08],[2,1.01,15.51]],"ltp":2.7,"tv":276.57,"id":8444055},{"batb":[[0,1.78,42.33],[1,1.77,302.78],[2,1.75,392.54]],"ltp":1.52,"tv":3098.99,"id":8257852}]}]}
{"op":"mcm","clk":"1011954856","pt":1580658563262,"mc":[{"id":"1.168223929","rc":[{"batb":[[1,2.12,36.97],[2,1.83,38.08]],"batl":[[0,2.36,30.25]],"ltp":2.7,"tv":276.57,"id":8444055},{"batl":[[2,1.9,42.01]],"ltp":1.52,"tv":3098.99,"id":8257852}]}]}
{"op":"mcm","clk":"1011958732","pt":1580658584992,"mc":[{"id":"1.168223929","rc":[{"batb":[[0,2.12,36.97],[1,1.83,38.08],[2,1.7,409.32]],"ltp":2.7,"tv":276.57,"id":8444055},{"batb":[[0,1.73,57.13],[1,1.68,51.46],[2,1.55,420.5]],"batl":[[0,1.9,42.01],[1,3,3.86],[2,1.9,0]],"ltp":1.52,"tv":3098.99,"id":8257852}]}]}
{"op":"mcm","clk":"1011958937","pt":1580658586101,"mc":[{"id":"1.168223929","rc":[{"batb":[[0,1.83,38.08],[1,1.7,409.32],[2,1.01,15.51]],"ltp":2.7,"tv":276.57,"id":8444055},{"batb":[[0,1.68,51.46],[1,1.55,420.5],[2,1.01,15.51]],"batl":[[0,3,3.86],[1,3,0]],"ltp":1.52,"tv":3098.99,"id":8257852}]}]}
{"op":"mcm","clk":"1011959278","pt":1580658588181,"mc":[{"id":"1.168223929","rc":[{"batb":[[1,1.66,451.08],[2,1.65,243.05]],"ltp":1.52,"tv":3098.99,"id":8257852}]}]}
{"op":"mcm","clk":"1011959379","pt":1580658588768,"mc":[{"id":"1.168223929","rc":[{"batb":[[0,1.84,37.53]],"ltp":2.7,"tv":276.57,"id":8444055},{"batb":[[0,1.67,52.72]],"ltp":1.52,"tv":3098.99,"id":8257852}]}]}
{"op":"mcm","clk":"1011959611","pt":1580658590254,"mc":[{"id":"1.168223929","rc":[{"batb":[[1,1.01,15.51],[2,1.01,0]],"ltp":2.7,"tv":276.57,"id":8444055}]}]}
{"op":"mcm","clk":"1011959748","pt":1580658591156,"mc":[{"id":"1.168223929","rc":[{"batl":[[0,1.73,339.91],[1,1.75,397.22],[2,3,3.86]],"ltp":1.52,"tv":3098.99,"id":8257852}]}]}
{"op":"mcm","clk":"1011959920","pt":1580658592181,"mc":[{"id":"1.168223929","rc":[{"batb":[[0,2.32,37.61],[1,2.04,54.61],[2,1.01,15.51]],"ltp":2.7,"tv":276.57,"id":8444055}]}]}
{"op":"mcm","clk":"1011960002","pt":1580658592558,"mc":[{"id":"1.168223929","rc":[{"batl":[[0,2.56,26.89]],"ltp":2.7,"tv":276.57,"id":8444055},{"batb":[[2,1.65,306.9]],"ltp":1.52,"tv":3098.99,"id":8257852}]}]}
{"op":"mcm","clk":"1011960256","pt":1580658594054,"mc":[{"id":"1.168223929","rc":[{"batb":[[1,2.28,32.77],[2,2.04,54.61]],"ltp":2.7,"tv":276.57,"id":8444055},{"batl":[[2,1.78,42.01]],"ltp":1.52,"tv":3098.99,"id":8257852}]}]}
{"op":"mcm","clk":"1011961422","pt":1580658601192,"mc":[{"id":"1.168223929","rc":[{"batb":[[1,1.66,237.26],[2,1.65,63.85]],"ltp":1.52,"tv":3098.99,"id":8257852}]}]}
{"op":"mcm","clk":"1011961909","pt":1580658604207,"mc":[{"id":"1.168223929","rc":[{"batb":[[0,2.28,32.77],[1,2.04,54.61],[2,1.82,401.24]],"ltp":2.7,"tv":276.57,"id":8444055},{"batb":[[0,1.67,253.79],[1,1.65,63.85],[2,1.6,60.66]],"batl":[[0,1.78,42.01],[1,3,3.86],[2,1.78,0]],"ltp":1.52,"tv":3098.99,"id":8257852}]}]}
{"op":"mcm","clk":"1011961954","pt":1580658604479,"mc":[{"id":"1.168223929","rc":[{"batb":[[0,1.65,63.85],[1,1.6,60.66],[2,1.46,435.7]],"ltp":1.52,"tv":3098.99,"id":8257852}]}]}
{"op":"mcm","clk":"1011962192","pt":1580658606012,"mc":[{"id":"1.168223929","rc":[{"batb":[[0,2.04,54.61],[1,1.82,401.24],[2,1.01,15.51]],"ltp":2.7,"tv":276.57,"id":8444055},{"batb":[[0,1.6,60.66],[1,1.46,435.7],[2,1.01,15.51]],"batl":[[0,3,3.86],[1,3,0]],"ltp":1.52,"tv":3098.99,"id":8257852}]}]}
{"op":"mcm","clk":"1011962294","pt":1580658606604,"mc":[{"id":"1.168223929","rc":[{"batb":[[0,1.6,400.14],[1,1.59,278.21],[2,1.46,435.7]],"batl":[[0,1.91,309.42],[1,1.93,290.82],[2,3,3.86]],"ltp":1.52,"tv":3098.99,"id":8257852}]}]}
{"op":"mcm","clk":"1011964698","pt":1580658622011,"mc":[{"id":"1.168223929","rc":[{"batb":[[0,1.6,60.66],[1,1.46,435.7],[2,1.01,15.51]],"batl":[[0,3,3.86],[1,1.93,0],[2,3,0]],"ltp":1.52,"tv":3098.99,"id":8257852}]}]}
{"op":"mcm","clk":"1011965026","pt":1580658624220,"mc":[{"id":"1.168223929","rc":[{"batb":[[1,1.01,15.51],[2,1.01,0]],"ltp":1.52,"tv":3098.99,"id":8257852}]}]}
{"op":"mcm","clk":"1011965131","pt":1580658624812,"mc":[{"id":"1.168223929","rc":[{"batb":[[0,1.7,250.11],[1,1.68,451.86],[2,1.6,60.66]],"batl":[[0,1.76,242.01],[1,1.78,375.78],[2,3,3.86]],"ltp":1.52,"tv":3098.99,"id":8257852}]}]}
{"op":"mcm","clk":"1011965593","pt":1580658627193,"mc":[{"id":"1.168223929","rc":[{"batb":[[0,1.6,60.66],[1,1.01,15.51],[2,1.6,0]],"batl":[[0,3,3.86],[1,1.78,0],[2,3,0]],"ltp":1.52,"tv":3098.99,"id":8257852}]}]}
{"op":"mcm","clk":"1011965834","pt":1580658628918,"mc":[{"id":"1.168223929","rc":[{"batb":[[1,1.5,426.9],[2,1.01,15.51]],"ltp":1.52,"tv":3098.99,"id":8257852}]}]}
{"op":"mcm","clk":"1011966067","pt":1580658630233,"mc":[{"id":"1.168223929","rc":[{"batb":[[0,1.6,400.14],[1,1.59,278.21],[2,1.5,426.9]],"batl":[[0,1.91,309.42],[1,1.93,290.82],[2,3,3.86]],"ltp":1.52,"tv":3098.99,"id":8257852}]}]}
{"op":"mcm","clk":"1011966689","pt":1580658634024,"mc":[{"id":"1.168223929","rc":[{"batl":[[0,3,3.86],[1,1.93,0],[2,3,0]],"ltp":1.52,"tv":3098.99,"id":8257852}]}]}
{"op":"mcm","clk":"1011967037","pt":1580658636269,"mc":[{"id":"1.168223929","rc":[{"batl":[[0,1.66,391.64],[1,1.67,231.2],[2,3,3.86]],"ltp":1.52,"tv":3098.99,"id":8257852}]}]}
{"op":"mcm","clk":"1011967359","pt":1580658638241,"mc":[{"id":"1.168223929","rc":[{"batb":[[0,2.46,32.02],[1,2.4,29.41],[2,2.26,40.44]],"batl":[[0,2.74,23.53]],"ltp":2.7,"tv":276.57,"id":8444055},{"batb":[[2,1.58,72.26]],"batl":[[2,1.71,42.01]],"ltp":1.52,"tv":3098.99,"id":8257852}]}]}
{"op":"mcm","clk":"1011969555","pt":1580658652227,"mc":[{"id":"1.168223929","rc":[{"batb":[[0,2.4,29.41],[1,2.26,40.44],[2,1.82,401.24]],"ltp":2.7,"tv":276.57,"id":8444055},{"batb":[[0,1.58,72.26],[1,1.56,66.96],[2,1.5,426.9]],"batl":[[0,1.71,42.01],[1,3,3.86],[2,1.71,0]],"ltp":1.52,"tv":3098.99,"id":8257852}]}]}
{"op":"mcm","clk":"1011969874","pt":1580658654061,"mc":[{"id":"1.168223929","rc":[{"batb":[[0,2.26,40.44],[1,1.82,401.24],[2,1.01,15.51]],"ltp":2.7,"tv":276.57,"id":8444055},{"batb":[[0,1.56,66.96],[1,1.5,426.9],[2,1.01,15.51]],"batl":[[0,3,3.86],[1,3,0]],"ltp":1.52,"tv":3098.99,"id":8257852}]}]}
{"op":"mcm","clk":"1011969999","pt":1580658654762,"mc":[{"id":"1.168223929","rc":[{"batb":[[0,1.56,532.78],[1,1.55,307.26],[2,1.5,426.9]],"batl":[[0,1.75,347.77],[1,1.77,382.5],[2,3,3.86]],"ltp":1.52,"tv":3098.99,"id":8257852}]}]}
{"op":"mcm","clk":"1011972300","pt":1580658670158,"mc":[{"id":"1.168223929","rc":[{"batb":[[0,1.56,66.96],[1,1.5,426.9],[2,1.01,15.51]],"batl":[[0,3,3.86],[1,1.77,0],[2,3,0]],"ltp":1.52,"tv":3098.99,"id":8257852}]}]}
{"op":"mcm","clk":"1011972712","pt":1580658672971,"mc":[{"id":"1.168223929","rc":[{"batb":[[0,1.61,493.74],[1,1.6,272.27],[2,1.56,66.96]],"batl":[[0,1.68,444.01],[1,1.7,437.25],[2,3,3.86]],"ltp":1.52,"tv":3098.99,"id":8257852}]}]}
{"op":"mcm","clk":"1011973156","pt":1580658676090,"mc":[{"id":"1.168223929","rc":[{"batb":[[0,1.56,66.96],[1,1.5,426.9],[2,1.01,15.51]],"batl":[[0,3,3.86],[1,1.7,0],[2,3,0]],"ltp":1.52,"tv":3098.99,"id":8257852}]}]}
{"op":"mcm","clk":"1011973583","pt":1580658679225,"mc":[{"id":"1.168223929","rc":[{"batb":[[0,1.56,532.78],[1,1.55,307.26],[2,1.5,426.9]],"batl":[[0,1.75,347.77],[1,1.77,382.5],[2,3,3.86]],"ltp":1.52,"tv":3098.99,"id":8257852}]}]}
{"op":"mcm","clk":"1011973710","pt":1580658680044,"mc":[{"id":"1.168223929","rc":[{"trd":[[1.56,133.91]],"batb":[[0,1.5,426.9],[1,1.01,15.51],[2,1.5,0]],"batl":[[0,1.56,6.98],[1,3,3.86],[2,3,0]],"ltp":1.56,"tv":3232.91,"id":8257852}],"tv":3509.48}]}
{"op":"mcm","clk":"1011974041","pt":1580658682209,"mc":[{"id":"1.168223929","rc":[{"batb":[[1,1.01,15.51],[2,1.01,0]],"ltp":2.7,"tv":276.57,"id":8444055},{"batb":[[0,1.01,15.51],[1,1.01,0]],"ltp":1.56,"tv":3232.91,"id":8257852}]}]}
{"op":"mcm","clk":"1011974207","pt":1580658683197,"mc":[{"id":"1.168223929","rc":[{"batb":[[0,2.58,28.56],[1,2.44,32.81],[2,2.26,40.44]],"ltp":2.7,"tv":276.57,"id":8444055},{"trd":[[1.56,147.88]],"batb":[[0,1.56,525.8],[1,1.55,307.26],[2,1.54,70.11]],"batl":[[0,1.62,394.25],[1,1.63,251.75],[2,3,3.86]],"ltp":1.56,"tv":3246.87,"id":8257852}],"tv":3523.45}]}
{"op":"mcm","clk":"1011974352","pt":1580658684208,"mc":[{"id":"1.168223929","rc":[{"batb":[[2,1.01,15.51]],"ltp":2.7,"tv":276.57,"id":8444055}]}]}
{"op":"mcm","clk":"1011974407","pt":1580658684582,"mc":[{"id":"1.168223929","rc":[{"batb":[[1,2.5,27.73],[2,2.44,32.81]],"batl":[[0,2.84,22.69]],"ltp":2.7,"tv":276.57,"id":8444055},{"batb":[[2,1.54,147.4]],"batl":[[2,1.66,42.01]],"ltp":1.56,"tv":3246.87,"id":8257852}]}]}
{"op":"mcm","clk":"1011975757","pt":1580658694901,"mc":[{"id":"1.168223929","rc":[{"batb":[[0,2.5,27.73],[1,2.44,32.81],[2,1.92,394.91]],"ltp":2.7,"tv":276.57,"id":8444055},{"batb":[[0,1.55,307.26],[1,1.54,147.4],[2,1.4,451]],"batl":[[0,1.66,42.01],[1,3,3.86],[2,1.66,0]],"ltp":1.56,"tv":3246.87,"id":8257852}]}]}
{"op":"mcm","clk":"1011975809","pt":1580658695328,"mc":[{"id":"1.168223929","rc":[{"batb":[[0,2.44,32.81],[1,1.92,394.91],[2,1.01,15.51]],"ltp":2.7,"tv":276.57,"id":8444055},{"batb":[[1,1.54,70.11]],"batl":[[0,3,3.86],[1,3,0]],"ltp":1.56,"tv":3246.87,"id":8257852}]}]}
{"op":"mcm","clk":"1011976202","pt":1580658698082,"mc":[{"id":"1.168223929","rc":[{"batb":[[0,2.54,31.79]],"ltp":2.7,"tv":276.57,"id":8444055},{"batb":[[0,1.55,371.82],[1,1.54,314.66],[2,1.53,72.07]],"batl":[[0,1.65,240.95],[1,1.66,236.63],[2,3,3.86]],"ltp":1.56,"tv":3246.87,"id":8257852}]}]}
{"op":"mcm","clk":"1011976509","pt":1580658700207,"mc":[{"id":"1.168223929","rc":[{"batl":[[0,3,3.86],[1,1.66,0],[2,3,0]],"ltp":1.56,"tv":3246.87,"id":8257852}]}]}
{"op":"mcm","clk":"1011976928","pt":1580658703254,"mc":[{"id":"1.168223929","rc":[{"batl":[[0,1.6,253.63],[1,1.61,263.69],[2,3,3.86]],"ltp":1.56,"tv":3246.87,"id":8257852}]}]}
{"op":"mcm","clk":"1011977064","pt":1580658704224,"mc":[{"id":"1.168223929","rc":[{"batb":[[0,2.72,26.12],[1,2.48,33.44],[2,1.92,394.91]],"ltp":2.7,"tv":276.57,"id":8444055}]}]}
{"op":"mcm","clk":"1011977192","pt":1580658705120,"mc":[{"id":"1.168223929","rc":[{"batb":[[1,2.54,26.89],[2,2.48,33.44]],"batl":[[0,2.9,21.85]],"ltp":2.7,"tv":276.57,"id":8444055},{"batb":[[2,1.53,151.05]],"batl":[[2,1.65,42.01]],"ltp":1.56,"tv":3246.87,"id":8257852}]}]}
{"op":"mcm","clk":"1011978328","pt":1580658712933,"mc":[{"id":"1.168223929","rc":[{"batb":[[2,1.53,150.66]],"ltp":1.56,"tv":3246.87,"id":8257852}]}]}
{"op":"mcm","clk":"1011982816","pt":1580658744248,"mc":[{"id":"1.168223929","rc":[{"trd":[[1.55,35.37]],"batb":[[0,1.55,354.13]],"ltp":1.55,"tv":3282.24,"id":8257852}],"tv":3558.82}]}
{"op":"mcm","clk":"1011988847","pt":1580658787249,"mc":[{"id":"1.168223929","rc":[{"batb":[[0,2.54,26.89],[1,2.48,33.44],[2,1.92,394.91]],"ltp":2.7,"tv":276.57,"id":8444055},{"batb":[[0,1.53,78.98],[1,1.4,451],[2,1.38,111.73]],"batl":[[0,1.65,42.01],[1,3,3.86],[2,1.65,0]],"ltp":1.55,"tv":3282.24,"id":8257852}]}]}
{"op":"mcm","clk":"1011988948","pt":1580658787849,"mc":[{"id":"1.168223929","rc":[{"batb":[[0,2.48,33.44],[1,1.92,394.91],[2,1.01,15.51]],"ltp":2.7,"tv":276.57,"id":8444055},{"batb":[[0,1.4,451],[1,1.38,111.73],[2,1.01,15.51]],"batl":[[0,3,3.86],[1,3,0]],"ltp":1.55,"tv":3282.24,"id":8257852}]}]}
{"op":"mcm","clk":"1011989284","pt":1580658790155,"mc":[{"id":"1.168223929","rc":[{"batl":[[0,1.71,395.65],[1,1.73,412.28],[2,3,3.86]],"ltp":1.55,"tv":3282.24,"id":8257852}]}]}
{"op":"mcm","clk":"1011989378","pt":1580658790766,"mc":[{"id":"1.168223929","rc":[{"batb":[[0,1.38,111.73],[1,1.01,15.51],[2,1.01,0]],"ltp":1.55,"tv":3282.24,"id":8257852}]}]}
{"op":"mcm","clk":"1011989749","pt":1580658793269,"mc":[{"id":"1.168223929","rc":[{"batb":[[1,2.32,40.44],[2,1.92,394.91]],"ltp":2.7,"tv":276.57,"id":8444055},{"batb":[[0,1.64,449.15],[1,1.63,253.96],[2,1.62,58.15]],"ltp":1.55,"tv":3282.24,"id":8257852}]}]}
{"op":"mcm","clk":"1011989966","pt":1580658794843,"mc":[{"id":"1.168223929","rc":[{"batb":[[1,2.34,31.09],[2,2.32,40.44]],"batl":[[0,2.64,25.21]],"ltp":2.7,"tv":276.57,"id":8444055},{"batl":[[2,1.74,42.01]],"ltp":1.55,"tv":3282.24,"id":8257852}]}]}
{"op":"mcm","clk":"1011991210","pt":1580658803192,"mc":[{"id":"1.168223929","rc":[{"batb":[[0,1.64,247.73],[1,1.62,58.15],[2,1.61,68.06]],"batl":[[0,1.71,262.52]],"ltp":1.55,"tv":3282.24,"id":8257852}]}]}
{"op":"mcm","clk":"1011991342","pt":1580658803926,"mc":[{"id":"1.168223929","rc":[{"batb":[[0,2.34,31.09],[1,2.32,40.44],[2,1.92,394.91]],"ltp":2.7,"tv":276.57,"id":8444055},{"batb":[[0,1.61,68.06],[1,1.48,81.36],[2,1.46,435.7]],"batl":[[0,1.74,42.01],[1,3,3.86],[2,1.74,0]],"ltp":1.55,"tv":3282.24,"id":8257852}]}]}
{"op":"mcm","clk":"1011991685","pt":1580658806242,"mc":[{"id":"1.168223929","rc":[{"batb":[[0,2.32,40.44],[1,1.92,394.91],[2,1.01,15.51]],"ltp":2.7,"tv":276.57,"id":8444055},{"batb":[[0,1.48,81.36],[1,1.46,435.7],[2,1.01,15.51]],"batl":[[0,3,3.86],[1,3,0]],"ltp":1.55,"tv":3282.24,"id":8257852}]}]}
{"op":"mcm","clk":"1011991822","pt":1580658807139,"mc":[{"id":"1.168223929","rc":[{"batb":[[0,2.3,40.84]],"ltp":2.7,"tv":276.57,"id":8444055},{"batb":[[0,1.52,348.46],[1,1.51,339.61],[2,1.49,80.65]],"batl":[[0,1.8,315.92],[1,1.82,349.01],[2,3,3.86]],"ltp":1.55,"tv":3282.24,"id":8257852}]}]}
{"op":"mcm","clk":"1011991942","pt":1580658807975,"mc":[{"id":"1.168223929","rc":[{"batb":[[0,1.49,80.65],[1,1.46,435.7],[2,1.01,15.51]],"batl":[[0,3,3.86],[1,1.82,0],[2,3,0]],"ltp":1.55,"tv":3282.24,"id":8257852}]}]}
{"op":"mcm","clk":"1011992113","pt":1580658808973,"mc":[{"id":"1.168223929","rc":[{"batb":[[0,1.62,258.52],[1,1.49,80.65],[2,1.46,435.7]],"ltp":1.55,"tv":3282.24,"id":8257852}]}]}
{"op":"mcm","clk":"1011992584","pt":1580658812167,"mc":[{"id":"1.168223929","rc":[{"batb":[[0,1.49,80.65],[1,1.46,435.7],[2,1.01,15.51]],"ltp":1.55,"tv":3282.24,"id":8257852}]}]}
{"op":"mcm","clk":"1011993033","pt":1580658815176,"mc":[{"id":"1.168223929","rc":[{"batb":[[0,1.52,480.02],[1,1.51,339.81],[2,1.49,80.65]],"batl":[[0,1.81,381.37],[1,1.83,342.4],[2,3,3.86]],"ltp":1.55,"tv":3282.24,"id":8257852}]}]}
{"op":"mcm","clk":"1011993548","pt":1580658818264,"mc":[{"id":"1.168223929","rc":[{"batb":[[0,1.49,80.65],[1,1.46,435.7],[2,1.01,15.51]],"batl":[[0,3,3.86],[1,1.83,0],[2,3,0]],"ltp":1.55,"tv":3282.24,"id":8257852}]}]}
{"op":"mcm","clk":"1011993651","pt":1580658818949,"mc":[{"id":"1.168223929","rc":[{"batb":[[1,1.01,15.51],[2,1.01,0]],"ltp":2.7,"tv":276.57,"id":8444055},{"batb":[[1,1.01,15.51],[2,1.01,0]],"ltp":1.55,"tv":3282.24,"id":8257852}]}]}
{"op":"mcm","clk":"1011993992","pt":1580658821173,"mc":[{"id":"1.168223929","rc":[{"batb":[[1,2.2,46.26],[2,1.01,15.51]],"ltp":2.7,"tv":276.57,"id":8444055},{"batb":[[0,1.73,414.97],[1,1.71,424.34],[2,1.7,48.86]],"batl":[[0,1.81,381.37],[1,1.83,342.4],[2,3,3.86]],"ltp":1.55,"tv":3282.24,"id":8257852}]}]}
{"op":"mcm","clk":"1011994168","pt":1580658822392,"mc":[{"id":"1.168223929","rc":[{"batb":[[1,2.22,33.61],[2,2.2,46.26]],"batl":[[0,2.46,28.57]],"ltp":2.7,"tv":276.57,"id":8444055},{"batl":[[2,1.84,42.01]],"ltp":1.55,"tv":3282.24,"id":8257852}]}]}
{"op":"mcm","clk":"1011995874","pt":1580658834101,"mc":[{"id":"1.168223929","rc":[{"batb":[[0,2.22,33.61],[1,2.2,46.26],[2,1.77,402.27]],"ltp":2.7,"tv":276.57,"id":8444055},{"batb":[[0,1.68,61.33],[1,1.6,60.98],[2,1.5,426.9]],"batl":[[0,1.84,42.01],[1,3,3.86],[2,1.84,0]],"ltp":1.55,"tv":3282.24,"id":8257852}]}]}
{"op":"mcm","clk":"1011996127","pt":1580658835902,"mc":[{"id":"1.168223929","rc":[{"batb":[[0,2.2,46.26],[1,1.77,402.27],[2,1.01,15.51]],"ltp":2.7,"tv":276.57,"id":8444055},{"batb":[[0,1.6,60.98],[1,1.5,426.9],[2,1.01,15.51]],"batl":[[0,3,3.86],[1,3,0]],"ltp":1.55,"tv":3282.24,"id":8257852}]}]}
{"op":"mcm","clk":"1011996640","pt":1580658839988,"mc":[{"id":"1.168223929","rc":[{"batb":[[0,1.72,224.01],[1,1.7,432.37],[2,1.6,60.98]],"batl":[[0,1.78,226.43],[1,1.8,361.48],[2,3,3.86]],"ltp":1.55,"tv":3282.24,"id":8257852}]}]}
{"op":"mcm","clk":"1011997086","pt":1580658843202,"mc":[{"id":"1.168223929","rc":[{"batb":[[0,1.6,60.98],[1,1.5,426.9],[2,1.01,15.51]],"batl":[[0,3,3.86],[1,1.8,0],[2,3,0]],"ltp":1.55,"tv":3282.24,"id":8257852}]}]}
{"op":"mcm","clk":"1011997506","pt":1580658846233,"mc":[{"id":"1.168223929","rc":[{"batb":[[0,1.64,403.03],[1,1.63,253.15],[2,1.6,60.98]],"batl":[[0,1.86,246.74],[1,1.88,314.85],[2,3,3.86]],"ltp":1.55,"tv":3282.24,"id":8257852}]}]}
{"op":"mcm","clk":"1011998451","pt":1580658852930,"mc":[{"id":"1.168223929","rc":[{"batb":[[0,1.6,60.98],[1,1.5,426.9],[2,1.01,15.51]],"ltp":1.55,"tv":3282.24,"id":8257852}]}]}
{"op":"mcm","clk":"1011998619","pt":1580658854200,"mc":[{"id":"1.168223929","rc":[{"batb":[[1,1.01,15.51],[2,1.01,0]],"ltp":1.55,"tv":3282.24,"id":8257852}]}]}
{"op":"mcm","clk":"1011998943","pt":1580658856231,"mc":[{"id":"1.168223929","rc":[{"batb":[[1,2.16,49.25],[2,1.77,402.27]],"ltp":2.7,"tv":276.57,"id":8444055},{"batb":[[0,1.79,253.57],[1,1.77,376.87],[2,1.76,43.59]],"ltp":1.55,"tv":3282.24,"id":8257852}]}]}
{"op":"mcm","clk":"1011999090","pt":1580658857233,"mc":[{"id":"1.168223929","rc":[{"batb":[[2,2.14,36.13]],"batl":[[0,2.38,30.25]],"ltp":2.7,"tv":276.57,"id":8444055},{"batl":[[2,1.9,42.01]],"ltp":1.55,"tv":3282.24,"id":8257852}]}]}
{"op":"mcm","clk":"1012000887","pt":1580658869949,"mc":[{"id":"1.168223929","rc":[{"batb":[[0,2.16,49.25],[1,2.14,36.13],[2,1.77,402.27]],"ltp":2.7,"tv":276.57,"id":8444055},{"batb":[[0,1.73,57.13],[1,1.69,50.2],[2,1.55,420.5]],"batl":[[0,1.9,42.01],[1,3,3.86],[2,1.9,0]],"ltp":1.55,"tv":3282.24,"id":8257852}]}]}
{"op":"mcm","clk":"1012001160","pt":1580658872066,"mc":[{"id":"1.168223929","rc":[{"batb":[[1,1.77,402.27],[2,1.01,15.51]],"ltp":2.7,"tv":276.57,"id":8444055},{"batb":[[0,1.69,50.2],[1,1.55,420.5],[2,1.01,15.51]],"batl":[[0,3,3.86],[1,3,0]],"ltp":1.55,"tv":3282.24,"id":8257852}]}]}
{"op":"mcm","clk":"1012001615","pt":1580658874957,"mc":[{"id":"1.168223929","rc":[{"batb":[[0,1.78,263.22],[1,1.76,384.12],[2,1.69,50.2]],"batl":[[0,1.85,254.8],[1,1.87,320.11],[2,3,3.86]],"ltp":1.55,"tv":3282.24,"id":8257852}]}]}
{"op":"mcm","clk":"1012002157","pt":1580658879077,"mc":[{"id":"1.168223929","rc":[{"batb":[[0,1.69,50.2],[1,1.55,420.5],[2,1.01,15.51]],"batl":[[0,3,3.86],[1,1.87,0],[2,3,0]],"ltp":1.55,"tv":3282.24,"id":8257852}]}]}
{"op":"mcm","clk":"1012002537","pt":1580658882155,"mc":[{"id":"1.168223929","rc":[{"batl":[[0,1.89,324.97],[1,1.91,299.71],[2,3,3.86]],"ltp":1.55,"tv":3282.24,"id":8257852}]}]}
{"op":"mcm","clk":"1012002892","pt":1580658884236,"mc":[{"id":"1.168223929","rc":[{"batb":[[0,1.81,297.49],[1,1.79,363.14],[2,1.69,50.2]],"ltp":1.55,"tv":3282.24,"id":8257852}]}]}
{"op":"mcm","clk":"1012003031","pt":1580658885248,"mc":[{"id":"1.168223929","rc":[{"batb":[[1,2.1,37.81],[2,1.77,402.27]],"batl":[[0,2.32,31.09]],"ltp":2.7,"tv":276.57,"id":8444055},{"batb":[[1,1.79,404.29],[2,1.77,53.77]],"batl":[[2,1.93,42.01]],"ltp":1.55,"tv":3282.24,"id":8257852}]}]}
{"op":"mcm","clk":"1012007153","pt":1580658913213,"mc":[{"id":"1.168223929","rc":[{"batb":[[0,2.1,37.81],[1,1.77,402.27],[2,1.56,69.71]],"ltp":2.7,"tv":276.57,"id":8444055},{"batb":[[0,1.77,53.77],[1,1.58,63.81],[2,1.55,420.5]],"batl":[[0,1.93,42.01],[1,3,3.86],[2,1.93,0]],"ltp":1.55,"tv":3282.24,"id":8257852}]}]}
{"op":"mcm","clk":"1012007252","pt":1580658913911,"mc":[{"id":"1.168223929","rc":[{"batb":[[0,1.56,69.71],[1,1.01,15.51],[2,1.56,0]],"ltp":2.7,"tv":276.57,"id":8444055},{"batb":[[0,1.58,63.81],[1,1.01,15.51],[2,1.55,0]],"batl":[[0,3,3.86],[1,3,0]],"ltp":1.55,"tv":3282.24,"id":8257852}]}]}
{"op":"mcm","clk":"1012007611","pt":1580658916208,"mc":[{"id":"1.168223929","rc":[{"batb":[[0,1.58,571.51],[1,1.57,352.59],[2,1.01,15.51]],"batl":[[0,2.74,219.09],[1,2.78,258.09],[2,3,3.86]],"ltp":1.55,"tv":3282.24,"id":8257852}]}]}
{"op":"mcm","clk":"1012009465","pt":1580658929124,"mc":[{"id":"1.168223929","rc":[{"batl":[[0,3,3.86],[1,2.78,0],[2,3,0]],"ltp":1.55,"tv":3282.24,"id":8257852}]}]}
{"op":"mcm","clk":"1012009860","pt":1580658932229,"mc":[{"id":"1.168223929","rc":[{"batl":[[0,1.64,447.81],[1,1.65,290.96],[2,3,3.86]],"ltp":1.55,"tv":3282.24,"id":8257852}]}]}
{"op":"mcm","clk":"1012009999","pt":1580658933239,"mc":[{"id":"1.168223929","rc":[{"batb":[[0,2.58,29.98],[1,2.48,27.73],[2,2.14,49.73]],"batl":[[0,2.8,22.69]],"ltp":2.7,"tv":276.57,"id":8444055},{"batb":[[2,1.56,74.78]],"batl":[[2,1.68,42.01]],"ltp":1.55,"tv":3282.24,"id":8257852}]}]}
{"op":"mcm","clk":"1012013093","pt":1580658956178,"mc":[{"id":"1.168223929","rc":[{"trd":[[2.58,4.24]],"batb":[[0,2.58,27.85]],"ltp":2.58,"tv":280.82,"id":8444055}],"tv":3563.06}]}
{"op":"mcm","clk":"1012013256","pt":1580658957180,"mc":[{"id":"1.168223929","rc":[{"batb":[[0,1.58,63.81],[1,1.56,74.78],[2,1.4,451]],"batl":[[0,1.68,42.01],[1,3,3.86],[2,1.68,0]],"ltp":1.55,"tv":3282.24,"id":8257852}]}]}
{"op":"mcm","clk":"1012013348","pt":1580658957878,"mc":[{"id":"1.168223929","rc":[{"batb":[[0,2.14,49.73],[1,1.92,394.91],[2,1.01,15.51]],"ltp":2.58,"tv":280.82,"id":8444055},{"batb":[[0,1.4,451],[1,1.25,179.71],[2,1.01,15.51]],"batl":[[0,3,3.86],[1,3,0]],"ltp":1.55,"tv":3282.24,"id":8257852}]}]}
{"op":"mcm","clk":"1012013515","pt":1580658959068,"mc":[{"id":"1.168223929","rc":[{"batb":[[1,1.01,15.51],[2,1.01,0]],"ltp":2.58,"tv":280.82,"id":8444055},{"batb":[[0,1.25,179.71],[1,1.01,15.51],[2,1.01,0]],"ltp":1.55,"tv":3282.24,"id":8257852}]}]}
{"op":"mcm","clk":"1012013975","pt":1580658962042,"mc":[{"id":"1.168223929","rc":[{"batb":[[0,1.51,450.57],[1,1.5,421.77],[2,1.25,179.71]],"batl":[[0,1.56,451.13],[1,1.57,348.21],[2,3,3.86]],"ltp":1.55,"tv":3282.24,"id":8257852}]}]}
{"op":"mcm","clk":"1012014333","pt":1580658964056,"mc":[{"id":"1.168223929","rc":[{"batb":[[1,2.04,394.09],[2,1.01,15.51]],"ltp":2.58,"tv":280.82,"id":8444055},{"batb":[[2,1.34,465.43]],"ltp":1.55,"tv":3282.24,"id":8257852}]}]}
{"op":"mcm","clk":"1012014494","pt":1580658965186,"mc":[{"id":"1.168223929","rc":[{"trd":[[2.78,37.86]],"ltp":2.78,"tv":318.68,"id":8444055},{"trd":[[1.56,215.35]],"batl":[[0,1.56,383.66]],"ltp":1.56,"tv":3349.71,"id":8257852}],"tv":3668.39}]}
{"op":"mcm","clk":"1012014776","pt":1580658966983,"mc":[{"id":"1.168223929","rc":[{"batb":[[0,1.34,465.43],[1,1.25,179.71],[2,1.01,15.51]],"batl":[[0,3,3.86],[1,1.57,0],[2,3,0]],"ltp":1.56,"tv":3349.71,"id":8257852}]}]}
{"op":"mcm","clk":"1012015208","pt":1580658970269,"mc":[{"id":"1.168223929","rc":[{"batb":[[1,1.01,15.51],[2,1.01,0]],"ltp":2.78,"tv":318.68,"id":8444055},{"batb":[[0,1.25,179.71],[1,1.01,15.51],[2,1.01,0]],"batl":[[0,1.9,394.27],[1,1.92,356.69],[2,3,3.86]],"ltp":1.56,"tv":3349.71,"id":8257852}]}]}
{"op":"mcm","clk":"1012015721","pt":1580658974179,"mc":[{"id":"1.168223929","rc":[{"batb":[[1,1.81,41.78],[2,1.01,15.51]],"ltp":2.78,"tv":318.68,"id":8444055},{"batb":[[0,1.82,335.06],[1,1.8,471.63],[2,1.36,119.44]],"ltp":1.56,"tv":3349.71,"id":8257852}]}]}
{"op":"mcm","clk":"1012015812","pt":1580658974968,"mc":[{"id":"1.168223929","rc":[{"batb":[[1,2.08,38.65],[2,1.81,41.78]],"batl":[[0,2.3,31.93]],"ltp":2.78,"tv":318.68,"id":8444055},{"batb":[[2,1.76,54.61]],"batl":[[1,1.92,398.7]],"ltp":1.56,"tv":3349.71,"id":8257852}]}]}
{"op":"mcm","clk":"1012016532","pt":1580658980171,"mc":[{"id":"1.168223929","rc":[{"trd":[[1.82,6.08]],"batb":[[0,1.82,332.02]],"ltp":1.82,"tv":3355.79,"id":8257852}],"tv":3674.47}]}
{"op":"mcm","clk":"1012016805","pt":1580658982077,"mc":[{"id":"1.168223929","rc":[{"trd":[[1.82,206.08]],"batb":[[0,1.82,232.02]],"ltp":1.82,"tv":3555.79,"id":8257852}],"tv":3874.47}]}
{"op":"mcm","clk":"1012016931","pt":1580658982963,"mc":[{"id":"1.168223929","rc":[{"batl":[[0,1.92,42.01],[1,3,3.86],[2,3,0]],"ltp":1.82,"tv":3555.79,"id":8257852}]}]}
{"op":"mcm","clk":"1012017323","pt":1580658986077,"mc":[{"id":"1.168223929","rc":[{"batb":[[0,1.82,289.41]],"batl":[[0,1.89,255.99],[1,1.91,362.71],[2,1.92,42.01]],"ltp":1.82,"tv":3555.79,"id":8257852}]}]}
{"op":"mcm","clk":"1012017710","pt":1580658989157,"mc":[{"id":"1.168223929","rc":[{"trd":[[2.14,0.06]],"batb":[[0,2.14,49.7]],"ltp":2.14,"tv":318.73,"id":8444055}],"tv":3874.53}]}
{"op":"mcm","clk":"1012017845","pt":1580658990265,"mc":[{"id":"1.168223929","rc":[{"batb":[[0,1.8,40.52],[1,1.76,54.61],[2,1.55,420.5]],"batl":[[0,1.92,42.01],[1,3,3.86],[2,1.92,0]],"ltp":1.82,"tv":3555.79,"id":8257852}]}]}
{"op":"mcm","clk":"1012017986","pt":1580658991266,"mc":[{"id":"1.168223929","rc":[{"batb":[[0,2.08,38.65],[1,1.81,41.78],[2,1.7,409.32]],"ltp":2.14,"tv":318.73,"id":8444055},{"batb":[[0,1.76,54.61],[1,1.55,420.5],[2,1.36,119.44]],"ltp":1.82,"tv":3555.79,"id":8257852}]}]}
{"op":"mcm","clk":"1012018117","pt":1580658992212,"mc":[{"id":"1.168223929","rc":[{"batb":[[0,1.81,41.78],[1,1.01,15.51],[2,1.7,0]],"ltp":2.14,"tv":318.73,"id":8444055},{"batb":[[0,1.36,119.44],[1,1.01,15.51],[2,1.36,0]],"batl":[[0,3,3.86],[1,3,0]],"ltp":1.82,"tv":3555.79,"id":8257852}]}]}
{"op":"mcm","clk":"1012018256","pt":1580658993218,"mc":[{"id":"1.168223929","rc":[{"batb":[[0,1.39,544.81],[1,1.38,607.89],[2,1.36,119.44]],"batl":[[0,2.3,409.87],[1,2.32,206.77],[2,3,3.86]],"ltp":1.82,"tv":3555.79,"id":8257852}]}]}
{"op":"mcm","clk":"1012018522","pt":1580658995271,"mc":[{"id":"1.168223929","rc":[{"batb":[[0,1.36,119.44],[1,1.01,15.51],[2,1.36,0]],"batl":[[0,3,3.86],[1,2.32,0],[2,3,0]],"ltp":1.82,"tv":3555.79,"id":8257852}]}]}
{"op":"mcm","clk":"1012018923","pt":1580658998114,"mc":[{"id":"1.168223929","rc":[{"batb":[[0,1.71,406.94],[1,1.69,534.61],[2,1.36,119.44]],"batl":[[0,1.78,391.52],[1,1.8,437.05],[2,3,3.86]],"ltp":1.82,"tv":3555.79,"id":8257852}]}]}
{"op":"mcm","clk":"1012019049","pt":1580658999236,"mc":[{"id":"1.168223929","rc":[{"batb":[[1,1.77,402.27],[2,1.01,15.51]],"ltp":2.14,"tv":318.73,"id":8444055},{"batb":[[2,1.5,426.9]],"ltp":1.82,"tv":3555.79,"id":8257852}]}]}
{"op":"mcm","clk":"1012019162","pt":1580659000175,"mc":[{"id":"1.168223929","rc":[{"batb":[[0,1.5,426.9],[1,1.36,119.44],[2,1.01,15.51]],"batl":[[0,3,3.86],[1,1.8,0],[2,3,0]],"ltp":1.82,"tv":3555.79,"id":8257852}]}]}
{"op":"mcm","clk":"1012019341","pt":1580659001821,"mc":[{"id":"1.168223929","rc":[{"batb":[[1,1.01,15.51],[2,1.01,0]],"ltp":2.14,"tv":318.73,"id":8444055},{"batb":[[0,1.36,119.44],[1,1.01,15.51],[2,1.01,0]],"ltp":1.82,"tv":3555.79,"id":8257852}]}]}
{"op":"mcm","clk":"1012019476","pt":1580659003034,"mc":[{"id":"1.168223929","rc":[{"batb":[[0,1.39,544.81],[1,1.38,607.89],[2,1.36,119.44]],"batl":[[0,2.3,409.87],[1,2.32,206.77],[2,3,3.86]],"ltp":1.82,"tv":3555.79,"id":8257852}]}]}
{"op":"mcm","clk":"1012020635","pt":1580659012127,"mc":[{"id":"1.168223929","rc":[{"batl":[[0,3,3.86],[1,2.32,0],[2,3,0]],"ltp":1.82,"tv":3555.79,"id":8257852}]}]}
{"op":"mcm","clk":"1012021054","pt":1580659015266,"mc":[{"id":"1.168223929","rc":[{"batb":[[0,3.5,34.78],[1,2.12,51.69],[2,1.81,41.78]],"ltp":2.14,"tv":318.73,"id":8444055},{"batl":[[0,1.43,533.08],[1,1.44,490.03],[2,3,3.86]],"ltp":1.82,"tv":3555.79,"id":8257852}]}]}
{"op":"mcm","clk":"1012021083","pt":1580659015461,"mc":[{"id":"1.168223929","rc":[{"batb":[[2,1.01,15.51]],"ltp":2.14,"tv":318.73,"id":8444055}]}]}
{"op":"mcm","clk":"1012021322","pt":1580659017171,"mc":[{"id":"1.168223929","rc":[{"batb":[[1,3.2,18.48],[2,2.22,384.52]],"batl":[[0,3.7,15.12]],"ltp":2.14,"tv":318.73,"id":8444055},{"batb":[[2,1.37,113.43]],"batl":[[2,1.45,42.01]],"ltp":1.82,"tv":3555.79,"id":8257852}]}]}
{"op":"mcm","clk":"1012023051","pt":1580659029166,"mc":[{"id":"1.168223929","rc":[{"trd":[[1.39,30.28]],"batb":[[0,1.39,529.67]],"ltp":1.39,"tv":3586.08,"id":8257852}],"tv":3904.81}]}
{"op":"mcm","clk":"1012023986","pt":1580659036178,"mc":[{"id":"1.168223929","rc":[{"batb":[[0,3.2,18.48],[1,2.22,384.52],[2,2.12,51.69]],"ltp":2.14,"tv":318.73,"id":8444055},{"batb":[[0,1.37,113.43],[1,1.28,485.89],[2,1.23,203.55]],"batl":[[0,1.45,42.01],[1,3,3.86],[2,1.45,0]],"ltp":1.39,"tv":3586.08,"id":8257852}]}]}
{"op":"mcm","clk":"1012024123","pt":1580659037185,"mc":[{"id":"1.168223929","rc":[{"batb":[[2,1.23,202.92]],"ltp":1.39,"tv":3586.08,"id":8257852}]}]}
{"op":"mcm","clk":"1012024288","pt":1580659038196,"mc":[{"id":"1.168223929","rc":[{"batb":[[0,2.12,51.69],[1,1.01,15.51],[2,2.12,0]],"ltp":2.14,"tv":318.73,"id":8444055},{"batb":[[0,1.23,202.92],[1,1.01,15.51],[2,1.23,0]],"batl":[[0,3,3.86],[1,3,0]],"ltp":1.39,"tv":3586.08,"id":8257852}]}]}
{"op":"mcm","clk":"1012024681","pt":1580659040985,"mc":[{"id":"1.168223929","rc":[{"batb":[[0,1.46,437.65],[1,1.45,485.95],[2,1.23,202.92]],"batl":[[0,1.51,691.84],[1,1.52,392.48],[2,3,3.86]],"ltp":1.39,"tv":3586.08,"id":8257852}]}]}
{"op":"mcm","clk":"1012024953","pt":1580659042891,"mc":[{"id":"1.168223929","rc":[{"batb":[[0,2.12,440.34]],"ltp":2.14,"tv":318.73,"id":8444055},{"batb":[[2,1.31,477.51]],"ltp":1.39,"tv":3586.08,"id":8257852}]}]}
{"op":"mcm","clk":"1012025105","pt":1580659044110,"mc":[{"id":"1.168223929","rc":[{"batb":[[0,1.31,477.51],[1,1.23,202.92],[2,1.01,15.51]],"batl":[[0,3,3.86],[1,1.52,0],[2,3,0]],"ltp":1.39,"tv":3586.08,"id":8257852}]}]}
{"op":"mcm","clk":"1012025367","pt":1580659045896,"mc":[{"id":"1.168223929","rc":[{"batb":[[0,2.12,51.69]],"ltp":2.14,"tv":318.73,"id":8444055},{"batb":[[0,1.23,202.92],[1,1.01,15.51],[2,1.01,0]],"ltp":1.39,"tv":3586.08,"id":8257852}]}]}
{"op":"mcm","clk":"1012025524","pt":1580659047212,"mc":[{"id":"1.168223929","rc":[{"batl":[[0,1.9,275.23],[1,1.92,356.92],[2,3,3.86]],"ltp":1.39,"tv":3586.08,"id":8257852}]}]}
{"op":"mcm","clk":"1012025799","pt":1580659049112,"mc":[{"id":"1.168223929","rc":[{"batb":[[0,1.82,460.53],[1,1.8,431.42],[2,1.23,202.92]],"ltp":1.39,"tv":3586.08,"id":8257852}]}]}
{"op":"mcm","clk":"1012025957","pt":1580659050204,"mc":[{"id":"1.168223929","rc":[{"batb":[[1,1.47,87.57],[2,1.01,15.51]],"ltp":2.14,"tv":318.73,"id":8444055},{"batb":[[0,1.82,499.71],[2,1.56,66.96]],"ltp":1.39,"tv":3586.08,"id":8257852}]}]}
{"op":"mcm","clk":"1012026102","pt":1580659051203,"mc":[{"id":"1.168223929","rc":[{"batb":[[1,2.08,38.65],[2,1.47,87.57]],"batl":[[0,2.3,31.93]],"ltp":2.14,"tv":318.73,"id":8444055},{"batb":[[2,1.76,54.61]],"batl":[[1,1.92,398.93]],"ltp":1.39,"tv":3586.08,"id":8257852}]}]}
{"op":"mcm","clk":"1012026234","pt":1580659052185,"mc":[{"id":"1.168223929","rc":[{"batb":[[2,1.67,409.76]],"ltp":2.14,"tv":318.73,"id":8444055}]}]}
{"op":"mcm","clk":"1012027568","pt":1580659061111,"mc":[{"id":"1.168223929","rc":[{"trd":[[1.82,323.02]],"batb":[[0,1.82,441.24],[2,1.58,416.47]],"ltp":1.82,"tv":3703.02,"id":8257852}],"tv":4021.76}]}
{"op":"mcm","clk":"1012027966","pt":1580659063882,"mc":[{"id":"1.168223929","rc":[{"batb":[[2,1.77,53.77]],"ltp":1.82,"tv":3703.02,"id":8257852}]}]}
{"op":"mcm","clk":"1012028277","pt":1580659066102,"mc":[{"id":"1.168223929","rc":[{"batb":[[0,2.08,38.65],[1,1.67,409.76],[2,1.47,87.57]],"ltp":2.14,"tv":318.73,"id":8444055},{"batb":[[0,1.77,53.77],[1,1.58,416.47],[2,1.56,66.96]],"batl":[[0,1.92,42.01],[1,3,3.86],[2,3,0]],"ltp":1.82,"tv":3703.02,"id":8257852}]}]}
{"op":"mcm","clk":"1012028503","pt":1580659068195,"mc":[{"id":"1.168223929","rc":[{"batb":[[0,1.47,87.57],[1,1.01,15.51],[2,1.47,0]],"ltp":2.14,"tv":318.73,"id":8444055},{"batb":[[0,1.56,66.96],[1,1.01,15.51],[2,1.56,0]],"batl":[[0,3,3.86],[1,3,0]],"ltp":1.82,"tv":3703.02,"id":8257852}]}]}
{"op":"mcm","clk":"1012028567","pt":1580659068712,"mc":[{"id":"1.168223929","rc":[{"batb":[[1,1.55,521.79],[2,1.54,380.17]],"batl":[[1,3.05,273.67],[2,3.1,246.67]],"ltp":1.82,"tv":3703.02,"id":8257852}]}]}
{"op":"mcm","clk":"1012030504","pt":1580659084645,"mc":[{"id":"1.168223929","rc":[{"batb":[[1,1.01,15.51],[2,1.54,0]],"batl":[[1,3.05,0],[2,3.1,0]],"ltp":1.82,"tv":3703.02,"id":8257852}]}]}
{"op":"mcm","clk":"1012030965","pt":1580659088115,"mc":[{"id":"1.168223929","rc":[{"batb":[[0,1.95,277.2],[1,1.93,344.72],[2,1.47,87.57]],"batl":[[0,2.04,360.36],[1,2.06,288.92]],"ltp":2.14,"tv":318.73,"id":8444055}]}]}
{"op":"mcm","clk":"1012031169","pt":1580659089946,"mc":[{"id":"1.168223929","rc":[{"batb":[[2,1.62,415.43]],"ltp":2.14,"tv":318.73,"id":8444055},{"batb":[[0,1.62,415.43],[1,1.56,66.96],[2,1.01,15.51]],"ltp":1.82,"tv":3703.02,"id":8257852}]}]}
{"op":"mcm","clk":"1012031281","pt":1580659091117,"mc":[{"id":"1.168223929","rc":[{"batb":[[0,1.62,415.43],[1,1.47,87.57],[2,1.01,15.51]],"ltp":2.14,"tv":318.73,"id":8444055}]}]}
{"op":"mcm","clk":"1012031452","pt":1580659092762,"mc":[{"id":"1.168223929","rc":[{"batb":[[0,1.47,87.57],[1,1.01,15.51],[2,1.01,0]],"ltp":2.14,"tv":318.73,"id":8444055},{"batb":[[0,1.56,66.96],[1,1.01,15.51],[2,1.01,0]],"ltp":1.82,"tv":3703.02,"id":8257852}]}]}
{"op":"mcm","clk":"1012031581","pt":1580659093822,"mc":[{"id":"1.168223929","rc":[{"batb":[[0,1.49,465.06],[1,1.48,441.1],[2,1.47,87.57]],"batl":[[0,2.8,174.76],[1,2.84,246.35]],"ltp":2.14,"tv":318.73,"id":8444055}]}]}
{"op":"mcm","clk":"1012032422","pt":1580659100128,"mc":[{"id":"1.168223929","rc":[{"batl":[[0,1.54,501.2],[1,1.55,360.92]],"ltp":2.14,"tv":318.73,"id":8444055},{"batb":[[0,2.9,52.09],[1,1.83,38.48],[2,1.56,66.96]],"ltp":1.82,"tv":3703.02,"id":8257852}]}]}
{"op":"mcm","clk":"1012032567","pt":1580659101141,"mc":[{"id":"1.168223929","rc":[{"batl":[[2,1.58,42.01]],"ltp":2.14,"tv":318.73,"id":8444055},{"batb":[[1,2.04,394.09],[2,1.83,38.48]],"ltp":1.82,"tv":3703.02,"id":8257852}]}]}
{"op":"mcm","clk":"1012032813","pt":1580659103170,"mc":[{"id":"1.168223929","rc":[{"batb":[[2,1.47,176.63]],"ltp":2.14,"tv":318.73,"id":8444055},{"batb":[[1,2.72,24.37],[2,2.04,394.09]],"batl":[[1,3.1,19.32]],"ltp":1.82,"tv":3703.02,"id":8257852}]}]}
{"op":"mcm","clk":"1012033347","pt":1580659107137,"mc":[{"id":"1.168223929","rc":[{"batb":[[2,1.47,87.57]],"batl":[[2,1.58,0]],"ltp":2.14,"tv":318.73,"id":8444055},{"batb":[[1,2.04,394.09],[2,1.83,38.48]],"ltp":1.82,"tv":3703.02,"id":8257852}]}]}
{"op":"mcm","clk":"1012033595","pt":1580659109207,"mc":[{"id":"1.168223929","rc":[{"trd":[[1.49,12.98],[1.5,7.72]],"batb":[[0,1.49,458.57]],"ltp":1.49,"tv":339.44,"id":8444055},{"trd":[[3,3.86]],"batl":[[0,3.1,19.32],[1,3.1,0]],"ltp":3.0,"tv":3706.88,"id":8257852}],"tv":4046.32}]}
{"op":"mcm","clk":"1012033705","pt":1580659110034,"mc":[{"id":"1.168223929","rc":[{"batl":[[2,1.56,42.01]],"ltp":1.49,"tv":339.44,"id":8444055},{"batb":[[1,2.74,23.53],[2,2.04,394.09]],"ltp":3.0,"tv":3706.88,"id":8257852}]}]}
{"op":"mcm","clk":"1012033856","pt":1580659111181,"mc":[{"id":"1.168223929","rc":[{"batb":[[1,2.04,394.09],[2,1.83,38.48]],"ltp":3.0,"tv":3706.88,"id":8257852}]}]}
{"op":"mcm","clk":"1012033973","pt":1580659112076,"mc":[{"id":"1.168223929","rc":[{"trd":[[2.9,5.04]],"batb":[[0,2.9,49.57]],"ltp":2.9,"tv":3711.92,"id":8257852}],"tv":4051.36}]}
{"op":"mcm","clk":"1012034265","pt":1580659114173,"mc":[{"id":"1.168223929","rc":[{"batb":[[1,2.76,23.53],[2,2.04,394.09]],"batl":[[0,3.15,19.32]],"ltp":2.9,"tv":3711.92,"id":8257852}]}]}
{"op":"mcm","clk":"1012034545","pt":1580659116189,"mc":[{"id":"1.168223929","rc":[{"trd":[[1.49,55.2]],"batb":[[0,1.49,437.46]],"ltp":1.49,"tv":381.66,"id":8444055}],"tv":4093.58}]}
{"op":"mcm","clk":"1012034688","pt":1580659117262,"mc":[{"id":"1.168223929","rc":[{"batb":[[2,1.46,90.74]],"ltp":1.49,"tv":381.66,"id":8444055},{"batb":[[0,2.76,23.53],[1,2.04,394.09],[2,1.83,38.48]],"ltp":2.9,"tv":3711.92,"id":8257852}]}]}
{"op":"mcm","clk":"1012034917","pt":1580659119179,"mc":[{"id":"1.168223929","rc":[{"trd":[[1.54,0.14]],"batl":[[0,1.54,501.06]],"ltp":1.54,"tv":381.8,"id":8444055},{"trd":[[2.84,0.08]],"ltp":2.84,"tv":3712.0,"id":8257852}],"tv":4093.8}]}
{"op":"mcm","clk":"1012035047","pt":1580659120243,"mc":[{"id":"1.168223929","rc":[{"batl":[[0,1.5,6.47],[1,1.54,501.06],[2,1.55,360.92]],"ltp":1.54,"tv":381.8,"id":8444055}]}]}
{"op":"mcm","clk":"1012035136","pt":1580659121044,"mc":[{"id":"1.168223929","rc":[{"trd":[[1.49,55.23]],"batb":[[0,1.49,437.44]],"ltp":1.49,"tv":381.83,"id":8444055}],"tv":4093.84}]}
{"op":"mcm","clk":"1012035387","pt":1580659123271,"mc":[{"id":"1.168223929","rc":[{"batl":[[0,1.54,501.06],[1,1.55,360.92],[2,1.56,42.01]],"ltp":1.49,"tv":381.83,"id":8444055}]}]}
{"op":"mcm","clk":"1012035962","pt":1580659127188,"mc":[{"id":"1.168223929","rc":[{"trd":[[1.49,68.17],[1.54,1002.28]],"batb":[[0,1.54,39.33],[1,1.49,430.97],[2,1.48,441.1]],"batl":[[0,1.55,360.92],[1,1.56,42.01],[2,1.56,0]],"ltp":1.54,"tv":1396.91,"id":8444055}],"tv":5108.91}]}
{"op":"mcm","clk":"1012036097","pt":1580659128210,"mc":[{"id":"1.168223929","rc":[{"batb":[[1,1.46,90.74],[2,1.34,465.43]],"batl":[[0,1.56,42.01],[1,1.56,0]],"ltp":1.54,"tv":1396.91,"id":8444055}]}]}
{"op":"mcm","clk":"1012036223","pt":1580659129197,"mc":[{"id":"1.168223929","rc":[{"batb":[[2,1.28,167.83]],"ltp":1.54,"tv":1396.91,"id":8444055},{"batb":[[1,1.83,38.48],[2,1.01,15.51]],"ltp":2.84,"tv":3712.0,"id":8257852}]}]}
{"op":"mcm","clk":"1012036329","pt":1580659130095,"mc":[{"id":"1.168223929","rc":[{"batb":[[1,1.28,167.83],[2,1.01,15.51]],"ltp":1.54,"tv":1396.91,"id":8444055},{"batb":[[0,1.83,38.48],[1,1.01,15.51],[2,1.01,0]],"ltp":2.84,"tv":3712.0,"id":8257852}]}]}
{"op":"mcm","clk":"1012036753","pt":1580659133170,"mc":[{"id":"1.168223929","rc":[{"batb":[[0,1.59,375.01],[1,1.58,339.86],[2,1.54,39.33]],"batl":[[0,1.65,516.07],[1,1.66,281.19]],"ltp":1.54,"tv":1396.91,"id":8444055},{"batl":[[0,2.78,50],[1,1000,2.36]],"ltp":2.84,"tv":3712.0,"id":8257852}]}]}
{"op":"mcm","clk":"1012036878","pt":1580659134191,"mc":[{"id":"1.168223929","rc":[{"batb":[[0,1.97,394.86],[1,1.83,38.48],[2,1.01,15.51]],"ltp":2.84,"tv":3712.0,"id":8257852}]}]}
{"op":"mcm","clk":"1012037089","pt":1580659136001,"mc":[{"id":"1.168223929","rc":[{"batb":[[0,1.54,39.33],[1,1.38,448.45],[2,1.28,167.83]],"ltp":1.54,"tv":1396.91,"id":8444055}]}]}
{"op":"mcm","clk":"1012037218","pt":1580659137011,"mc":[{"id":"1.168223929","rc":[{"batb":[[1,1.28,167.83],[2,1.01,15.51]],"ltp":1.54,"tv":1396.91,"id":8444055},{"trd":[[1.97,0.79]],"batb":[[0,1.83,38.48],[1,1.01,15.51],[2,1.01,0]],"ltp":1.97,"tv":3712.79,"id":8257852}],"tv":5109.7}]}
{"op":"mcm","clk":"1012037365","pt":1580659138135,"mc":[{"id":"1.168223929","rc":[{"batb":[[0,1.54,174.44]],"ltp":1.54,"tv":1396.91,"id":8444055}]}]}
{"op":"mcm","clk":"1012037508","pt":1580659139200,"mc":[{"id":"1.168223929","rc":[{"batb":[[1,1.29,933.02],[2,1.28,1049.92]],"batl":[[0,2.22,332.3],[1,2.24,227.77]],"ltp":1.54,"tv":1396.91,"id":8444055}]}]}
{"op":"mcm","clk":"1012037914","pt":1580659142087,"mc":[{"id":"1.168223929","rc":[{"batl":[[0,2.52,50]],"ltp":1.97,"tv":3712.79,"id":8257852}]}]}
{"op":"mcm","clk":"1012038491","pt":1580659146224,"mc":[{"id":"1.168223929","rc":[{"batb":[[1,1.28,167.83],[2,1.01,15.51]],"ltp":1.54,"tv":1396.91,"id":8444055}]}]}
{"op":"mcm","clk":"1012038925","pt":1580659149195,"mc":[{"id":"1.168223929","rc":[{"batb":[[0,2.1,52.48],[1,1.71,50.91],[2,1.54,174.44]],"ltp":1.54,"tv":1396.91,"id":8444055},{"batb":[[1,1.82,398.45],[2,1.8,430.65]],"batl":[[0,1.9,332.07],[1,1.92,356.36]],"ltp":1.97,"tv":3712.79,"id":8257852}]}]}
{"op":"mcm","clk":"1012039039","pt":1580659150202,"mc":[{"id":"1.168223929","rc":[{"batb":[[2,1.67,410.23]],"ltp":1.54,"tv":1396.91,"id":8444055}]}]}
{"op":"mcm","clk":"1012039090","pt":1580659150729,"mc":[{"id":"1.168223929","rc":[{"batb":[[1,2.02,41.17],[2,1.71,50.91]],"batl":[[0,2.26,32.77]],"ltp":1.54,"tv":1396.91,"id":8444055},{"batb":[[2,1.81,51.25]],"batl":[[2,1.98,42.01]],"ltp":1.97,"tv":3712.79,"id":8257852}]}]}
{"op":"mcm","clk":"1012040184","pt":1580659158934,"mc":[{"id":"1.168223929","rc":[{"trd":[[1.82,446.08],[1.83,234.15]],"batb":[[0,1.82,336.92],[1,1.81,51.25],[2,1.8,430.65]],"ltp":1.82,"tv":3912.79,"id":8257852}],"tv":5309.71}]}
{"op":"mcm","clk":"1012040728","pt":1580659163140,"mc":[{"id":"1.168223929","rc":[{"batb":[[0,2.12,51.62],[2,1.72,50.04]],"ltp":1.54,"tv":1396.91,"id":8444055},{"batb":[[0,1.82,376.26]],"ltp":1.82,"tv":3912.79,"id":8257852}]}]}
{"op":"mcm","clk":"1012042556","pt":1580659177268,"mc":[{"id":"1.168223929","rc":[{"trd":[[2.12,45.44]],"batb":[[0,2.12,28.9]],"ltp":2.12,"tv":1442.34,"id":8444055}],"tv":5355.14}]}
{"op":"mcm","clk":"1012043740","pt":1580659186270,"mc":[{"id":"1.168223929","rc":[{"batb":[[0,1.82,39.34],[2,1.58,415.96]],"batl":[[0,1.98,42.01],[1,1.92,0],[2,1.98,0]],"ltp":1.82,"tv":3912.79,"id":8257852}]}]}
{"op":"mcm","clk":"1012044126","pt":1580659188953,"mc":[{"id":"1.168223929","rc":[{"batl":[[1,2.44,307.29],[2,2.48,346.92]],"ltp":1.82,"tv":3912.79,"id":8257852}]}]}
{"op":"mcm","clk":"1012044998","pt":1580659196087,"mc":[{"id":"1.168223929","rc":[{"batb":[[0,2.02,41.17],[1,1.72,50.04],[2,1.67,410.23]],"ltp":2.12,"tv":1442.34,"id":8444055},{"batb":[[0,1.81,51.25],[1,1.58,415.96],[2,1.32,911.25]],"ltp":1.82,"tv":3912.79,"id":8257852}]}]}
{"op":"mcm","clk":"1012045223","pt":1580659197978,"mc":[{"id":"1.168223929","rc":[{"batb":[[0,1.72,50.04],[1,1.54,39.33],[2,1.01,15.51]],"ltp":2.12,"tv":1442.34,"id":8444055},{"batb":[[0,1.32,911.25],[1,1.31,795.34],[2,1.3,145.17]],"batl":[[0,2.44,307.29],[1,2.48,346.92],[2,2.48,0]],"ltp":1.82,"tv":3912.79,"id":8257852}]}]}
{"op":"mcm","clk":"1012047718","pt":1580659213922,"mc":[{"id":"1.168223929","rc":[{"batb":[[2,1.01,15.52]],"ltp":2.12,"tv":1442.34,"id":8444055}]}]}
{"op":"mcm","clk":"1012047856","pt":1580659214820,"mc":[{"id":"1.168223929","rc":[{"batb":[[2,1.01,15.51]],"ltp":2.12,"tv":1442.34,"id":8444055}]}]}
{"op":"mcm","clk":"1012048026","pt":1580659216111,"mc":[{"id":"1.168223929","rc":[{"batb":[[0,1.3,145.17],[1,1.01,15.51],[2,1.3,0]],"ltp":1.82,"tv":3912.79,"id":8257852}]}]}
{"op":"mcm","clk":"1012048280","pt":1580659218116,"mc":[{"id":"1.168223929","rc":[{"batb":[[2,1.01,15.52]],"ltp":2.12,"tv":1442.34,"id":8444055}]}]}
{"op":"mcm","clk":"1012048459","pt":1580659219223,"mc":[{"id":"1.168223929","rc":[{"batb":[[1,1.7,294.38],[2,1.68,541.04]],"batl":[[0,1.76,285.1],[1,1.78,449.6]],"ltp":2.12,"tv":1442.34,"id":8444055},{"batb":[[0,2.28,39.81],[1,1.82,38.71],[2,1.3,145.17]],"ltp":1.82,"tv":3912.79,"id":8257852}]}]}
{"op":"mcm","clk":"1012048609","pt":1580659220210,"mc":[{"id":"1.168223929","rc":[{"batb":[[1,1.82,439.51],[2,1.01,15.51]],"ltp":1.82,"tv":3912.79,"id":8257852}]}]}
{"op":"mcm","clk":"1012048746","pt":1580659221226,"mc":[{"id":"1.168223929","rc":[{"batl":[[2,1.81,42.01]],"ltp":2.12,"tv":1442.34,"id":8444055},{"batb":[[1,2.22,33.61],[2,1.82,439.51]],"batl":[[0,2.5,27.73]],"ltp":1.82,"tv":3912.79,"id":8257852}]}]}
{"op":"mcm","clk":"1012048829","pt":1580659221823,"mc":[{"id":"1.168223929","rc":[{"batb":[[1,1.82,439.51],[2,1.01,15.51]],"ltp":1.82,"tv":3912.79,"id":8257852}]}]}
{"op":"mcm","clk":"1012049233","pt":1580659225250,"mc":[{"id":"1.168223929","rc":[{"batb":[[1,2.24,33.61],[2,1.82,439.51]],"ltp":1.82,"tv":3912.79,"id":8257852}]}]}
{"op":"mcm","clk":"1012049452","pt":1580659226855,"mc":[{"id":"1.168223929","rc":[{"batl":[[0,1.81,42.01],[1,1.78,0],[2,1.81,0]],"ltp":2.12,"tv":1442.34,"id":8444055}]}]}
{"op":"mcm","clk":"1012049927","pt":1580659230169,"mc":[{"id":"1.168223929","rc":[{"batb":[[1,1.7,418.55]],"batl":[[0,1.77,392.02],[1,1.79,440.59],[2,1.81,42.01]],"ltp":2.12,"tv":1442.34,"id":8444055}]}]}
{"op":"mcm","clk":"1012050287","pt":1580659232254,"mc":[{"id":"1.168223929","rc":[{"batb":[[0,1.76,135.1],[1,1.72,50.04],[2,1.7,418.55]],"ltp":2.12,"tv":1442.34,"id":8444055}]}]}
{"op":"mcm","clk":"1012050864","pt":1580659236156,"mc":[{"id":"1.168223929","rc":[{"batb":[[1,1.67,62.17],[2,1.54,39.33]],"batl":[[0,1.81,42.01],[1,1.79,0],[2,1.81,0]],"ltp":2.12,"tv":1442.34,"id":8444055},{"batb":[[0,2.24,33.61],[1,1.82,439.51],[2,1.01,15.51]],"ltp":1.82,"tv":3912.79,"id":8257852}]}]}
{"op":"mcm","clk":"1012051182","pt":1580659238264,"mc":[{"id":"1.168223929","rc":[{"batb":[[1,1.54,39.33],[2,1.21,227.48]],"ltp":2.12,"tv":1442.34,"id":8444055},{"batb":[[0,1.82,38.71],[1,1.01,15.51],[2,1.01,0]],"ltp":1.82,"tv":3912.79,"id":8257852}]}]}
{"op":"mcm","clk":"1012051340","pt":1580659239268,"mc":[{"id":"1.168223929","rc":[{"batb":[[2,1.23,565.6]],"batl":[[0,2.22,351.57],[1,2.24,227.73]],"ltp":2.12,"tv":1442.34,"id":8444055},{"batl":[[0,2.28,37.86]],"ltp":1.82,"tv":3912.79,"id":8257852}]}]}
{"op":"mcm","clk":"1012051529","pt":1580659240236,"mc":[{"id":"1.168223929","rc":[{"batl":[[1,2.3,33.61]],"ltp":1.82,"tv":3912.79,"id":8257852}]}]}
{"op":"mcm","clk":"1012051835","pt":1580659242166,"mc":[{"id":"1.168223929","rc":[{"batb":[[2,1.21,227.48]],"ltp":2.12,"tv":1442.34,"id":8444055},{"batl":[[0,2.3,33.61],[1,2.3,0]],"ltp":1.82,"tv":3912.79,"id":8257852}]}]}
{"op":"mcm","clk":"1012052279","pt":1580659245262,"mc":[{"id":"1.168223929","rc":[{"batb":[[0,1.82,460.66],[1,1.8,430.57],[2,1.01,15.51]],"batl":[[0,1.9,309.38],[1,1.92,356.32],[2,2.3,33.61]],"ltp":1.82,"tv":3912.79,"id":8257852}]}]}
{"op":"mcm","clk":"1012052460","pt":1580659246265,"mc":[{"id":"1.168223929","rc":[{"batb":[[0,2.12,52.48],[1,1.76,135.1],[2,1.54,39.33]],"ltp":2.12,"tv":1442.34,"id":8444055},{"batb":[[2,1.49,80.49]],"batl":[[2,2.06,535.75]],"ltp":1.82,"tv":3912.79,"id":8257852}]}]}
{"op":"mcm","clk":"1012052614","pt":1580659246996,"mc":[{"id":"1.168223929","rc":[{"batb":[[1,2.02,41.17],[2,1.76,135.1]],"batl":[[0,2.24,33.61]],"ltp":2.12,"tv":1442.34,"id":8444055},{"batb":[[1,1.81,51.25],[2,1.8,430.57]],"batl":[[2,1.99,42.01]],"ltp":1.82,"tv":3912.79,"id":8257852}]}]}
{"op":"mcm","clk":"1012053096","pt":1580659250167,"mc":[{"id":"1.168223929","rc":[{"batb":[[2,1.67,410.23]],"ltp":2.12,"tv":1442.34,"id":8444055}]}]}
{"op":"mcm","clk":"1012053547","pt":1580659253188,"mc":[{"id":"1.168223929","rc":[{"trd":[[2.22,135.1]],"ltp":2.22,"tv":1577.45,"id":8444055},{"trd":[[1.82,610.88]],"batb":[[0,1.82,295.87]],"ltp":1.82,"tv":4077.58,"id":8257852}],"tv":5655.04}]}
{"op":"mcm","clk":"1012054018","pt":1580659256223,"mc":[{"id":"1.168223929","rc":[{"batb":[[0,1.82,366.08]],"batl":[[0,1.9,362.88]],"ltp":1.82,"tv":4077.58,"id":8257852}]}]}
{"op":"mcm","clk":"1012054735","pt":1580659261085,"mc":[{"id":"1.168223929","rc":[{"batb":[[0,2.02,41.17],[1,1.67,410.23],[2,1.33,137.32]],"ltp":2.22,"tv":1577.45,"id":8444055},{"batb":[[0,1.81,51.25],[1,1.58,415.96],[2,1.49,80.49]],"batl":[[0,1.99,42.01],[1,1.92,0],[2,1.99,0]],"ltp":1.82,"tv":4077.58,"id":8257852}]}]}
{"op":"mcm","clk":"1012054891","pt":1580659261896,"mc":[{"id":"1.168223929","rc":[{"batb":[[0,1.67,410.23],[1,1.33,137.32],[2,1.01,15.51]],"ltp":2.22,"tv":1577.45,"id":8444055},{"batb":[[0,1.58,415.96],[1,1.49,80.49],[2,1.01,15.51]],"ltp":1.82,"tv":4077.58,"id":8257852}]}]}
{"op":"mcm","clk":"1012055056","pt":1580659263188,"mc":[{"id":"1.168223929","rc":[{"batb":[[0,1.33,137.32],[1,1.01,15.51],[2,1.01,0]],"ltp":2.22,"tv":1577.45,"id":8444055},{"batb":[[0,1.49,80.49],[1,1.01,15.51],[2,1.01,0]],"ltp":1.82,"tv":4077.58,"id":8257852}]}]}
{"op":"mcm","clk":"1012055195","pt":1580659264224,"mc":[{"id":"1.168223929","rc":[{"batb":[[0,1.33,135.43]],"ltp":2.22,"tv":1577.45,"id":8444055},{"batb":[[0,1.48,81.67]],"ltp":1.82,"tv":4077.58,"id":8257852}]}]}
{"op":"mcm","clk":"1012055532","pt":1580659266116,"mc":[{"id":"1.168223929","rc":[{"trd":[[1.99,53.27]],"batb":[[0,1.9,365.18],[1,1.88,373.22],[2,1.33,135.43]],"batl":[[0,1.99,309.51],[1,2.02,459.6]],"ltp":1.99,"tv":1630.72,"id":8444055},{"trd":[[2,53.01]],"ltp":2.0,"tv":4130.59,"id":8257852}],"tv":5761.31}]}
{"op":"mcm","clk":"1012055729","pt":1580659267422,"mc":[{"id":"1.168223929","rc":[{"batb":[[2,1.58,416.96]],"ltp":1.99,"tv":1630.72,"id":8444055},{"batb":[[0,1.67,409.28],[1,1.48,81.67],[2,1.01,15.51]],"ltp":2.0,"tv":4130.59,"id":8257852}]}]}
{"op":"mcm","clk":"1012056011","pt":1580659269200,"mc":[{"id":"1.168223929","rc":[{"batb":[[0,1.58,416.96],[1,1.33,135.43],[2,1.01,15.51]],"ltp":1.99,"tv":1630.72,"id":8444055}]}]}
