{"op":"mcm","clk":"1012359817","pt":1580660958177,"mc":[{"id":"1.168223930","rc":[{"batb":[[0,6.8,26.83],[1,4.8,30.84],[2,3.3,38.71]],"ltp":4.0,"tv":1971.48,"id":8444055},{"batb":[[0,1.14,1231.86],[2,1.09,514.82]],"batl":[[0,1.16,900.43],[1,1.17,1323.09],[2,1.19,532.68]],"ltp":1.24,"tv":4476.91,"id":8257852}]}]}
{"op":"mcm","clk":"1012359978","pt":1580660959078,"mc":[{"id":"1.168223930","rc":[{"batb":[[0,7,6.72],[1,6.8,26.83],[2,4.8,30.84]],"batl":[[0,8.4,5.04]],"ltp":4.0,"tv":1971.48,"id":8444055},{"batb":[[1,1.13,1587.79]],"batl":[[1,1.17,1365.1]],"ltp":1.24,"tv":4476.91,"id":8257852}]}]}
{"op":"mcm","clk":"1012360322","pt":1580660961167,"mc":[{"id":"1.168223930","rc":[{"batl":[[1,13.5,11.21]],"ltp":4.0,"tv":1971.48,"id":8444055},{"batl":[[2,1.19,1588.66]],"ltp":1.24,"tv":4476.91,"id":8257852}]}]}
{"op":"mcm","clk":"1012360520","pt":1580660962246,"mc":[{"id":"1.168223930","rc":[{"batl":[[2,1.44,1324.94]],"ltp":1.24,"tv":4476.91,"id":8257852}]}]}
{"op":"mcm","clk":"1012361218","pt":1580660966080,"mc":[{"id":"1.168223930","rc":[{"trd":[[1.16,100]],"batl":[[0,1.16,850.43]],"ltp":1.16,"tv":4576.91,"id":8257852}],"tv":6548.4}]}
{"op":"mcm","clk":"1012361872","pt":1580660970085,"mc":[{"id":"1.168223930","rc":[{"batb":[[0,1.13,536.29],[1,1.09,514.82],[2,1.01,15.51]],"batl":[[0,1.17,42.01],[1,1.44,1324.94],[2,2.88,0.31]],"ltp":1.16,"tv":4576.91,"id":8257852}]}]}
{"op":"mcm","clk":"1012362101","pt":1580660971271,"mc":[{"id":"1.168223930","rc":[{"batb":[[1,4.8,30.61],[2,1.01,15.51]],"ltp":4.0,"tv":1971.48,"id":8444055},{"batb":[[0,1.13,168.05],[1,1.09,513.95]],"ltp":1.16,"tv":4576.91,"id":8257852}]}]}
{"op":"mcm","clk":"1012362241","pt":1580660972107,"mc":[{"id":"1.168223930","rc":[{"batb":[[0,4.8,30.61],[1,1.01,15.51],[2,1.01,0]],"batl":[[0,13.5,11.21],[1,13.5,0]],"ltp":4.0,"tv":1971.48,"id":8444055},{"batb":[[0,1.09,513.97],[1,1.01,15.51],[2,1.01,0]],"batl":[[0,1.44,1324.94],[1,2.88,0.31],[2,2.88,0]],"ltp":1.16,"tv":4576.91,"id":8257852}]}]}
{"op":"mcm","clk":"1012362405","pt":1580660973074,"mc":[{"id":"1.168223930","rc":[{"batb":[[0,1.1,2356.85],[1,1.09,513.95],[2,1.01,15.51]],"batl":[[0,1.24,382.42],[1,1.25,871.55],[2,1.44,1324.94]],"ltp":1.16,"tv":4576.91,"id":8257852}]}]}
{"op":"mcm","clk":"1012364312","pt":1580660984222,"mc":[{"id":"1.168223930","rc":[{"batl":[[0,1.44,1324.94],[1,2.88,0.31],[2,1.44,0]],"ltp":1.16,"tv":4576.91,"id":8257852}]}]}
{"op":"mcm","clk":"1012364645","pt":1580660986201,"mc":[{"id":"1.168223930","rc":[{"batl":[[0,1.15,532.68],[1,1.44,1324.94],[2,2.88,0.31]],"ltp":1.16,"tv":4576.91,"id":8257852}]}]}
{"op":"mcm","clk":"1012364797","pt":1580660987111,"mc":[{"id":"1.168223930","rc":[{"batb":[[0,8.8,15.5],[1,7.8,19.67],[2,4.8,30.61]],"batl":[[0,11,4.2]],"ltp":4.0,"tv":1971.48,"id":8444055},{"trd":[[1.14,0.07]],"batb":[[0,1.1,2356.83],[2,1.07,680.05]],"batl":[[0,1.12,701.79],[1,1.13,1598.75],[2,1.15,532.68]],"ltp":1.14,"tv":4576.95,"id":8257852}],"tv":6548.43}]}
{"op":"mcm","clk":"1012364872","pt":1580660987540,"mc":[{"id":"1.168223930","rc":[{"batb":[[2,1.01,15.51]],"ltp":4.0,"tv":1971.48,"id":8444055}]}]}
{"op":"mcm","clk":"1012365178","pt":1580660989217,"mc":[{"id":"1.168223930","rc":[{"batl":[[2,1.23,1957.26]],"ltp":1.14,"tv":4576.95,"id":8257852}]}]}
{"op":"mcm","clk":"1012365265","pt":1580660989802,"mc":[{"id":"1.168223930","rc":[{"batb":[[0,8.8,20.54]],"batl":[[1,18,15.97]],"ltp":4.0,"tv":1971.48,"id":8444055},{"batl":[[1,1.13,1640.76]],"ltp":1.14,"tv":4576.95,"id":8257852}]}]}
{"op":"mcm","clk":"1012366168","pt":1580660995222,"mc":[{"id":"1.168223930","rc":[{"batb":[[0,1.1,1643.73]],"batl":[[0,1.13,1640.76],[1,1.23,1957.26],[2,1.44,1324.94]],"ltp":1.14,"tv":4576.95,"id":8257852}]}]}
{"op":"mcm","clk":"1012366332","pt":1580660996234,"mc":[{"id":"1.168223930","rc":[{"trd":[[1.1,8.77]],"batb":[[0,1.1,1639.35]],"ltp":1.1,"tv":4585.71,"id":8257852}],"tv":6557.2}]}
{"op":"mcm","clk":"1012366663","pt":1580660998260,"mc":[{"id":"1.168223930","rc":[{"batb":[[0,1.11,706.77],[1,1.1,1639.35],[2,1.09,513.95]],"batl":[[0,1.13,2193.8]],"ltp":1.1,"tv":4585.71,"id":8257852}]}]}
{"op":"mcm","clk":"1012370342","pt":1580661018265,"mc":[{"id":"1.168223930","rc":[{"batb":[[0,7.8,19.67],[1,1.01,15.51],[2,1.01,0]],"batl":[[0,18,15.97],[1,18,0]],"ltp":4.0,"tv":1971.48,"id":8444055},{"batb":[[0,1.07,663.68],[1,1.01,15.51],[2,1.09,0]],"batl":[[0,1.44,1324.94],[1,2.88,0.31],[2,1.44,0]],"ltp":1.1,"tv":4585.71,"id":8257852}]}]}
{"op":"mcm","clk":"1012370638","pt":1580661019977,"mc":[{"id":"1.168223930","rc":[{"batl":[[0,1.1,7.65],[1,1.44,1324.94],[2,2.88,0.31]],"ltp":1.1,"tv":4585.71,"id":8257852}]}]}
{"op":"mcm","clk":"1012371000","pt":1580661022177,"mc":[{"id":"1.168223930","rc":[{"batl":[[0,1.1,207.65]],"ltp":1.1,"tv":4585.71,"id":8257852}]}]}
{"op":"mcm","clk":"1012371163","pt":1580661023163,"mc":[{"id":"1.168223930","rc":[{"trd":[[1.1,424.06]],"batb":[[0,1.1,1967.17],[1,1.07,663.68],[2,1.01,15.51]],"batl":[[0,1.12,1272.81],[1,1.13,958.81],[2,1.44,1324.94]],"ltp":1.1,"tv":5001.01,"id":8257852}],"tv":6972.5}]}
{"op":"mcm","clk":"1012371633","pt":1580661026089,"mc":[{"id":"1.168223930","rc":[{"batb":[[0,1.1,2098.75]],"batl":[[0,1.12,1347.47]],"ltp":1.1,"tv":5001.01,"id":8257852}]}]}
{"op":"mcm","clk":"1012371785","pt":1580661026991,"mc":[{"id":"1.168223930","rc":[{"batb":[[0,1.07,663.68],[1,1.01,15.51],[2,1.01,0]],"batl":[[0,1.44,1324.94],[1,2.88,0.31],[2,1.44,0]],"ltp":1.1,"tv":5001.01,"id":8257852}]}]}
{"op":"mcm","clk":"1012372339","pt":1580661030179,"mc":[{"id":"1.168223930","rc":[{"batb":[[0,1.08,2400.58],[1,1.07,663.68],[2,1.01,15.51]],"batl":[[0,1.14,1472.22],[1,1.15,795.04],[2,1.44,1324.94]],"ltp":1.1,"tv":5001.01,"id":8257852}]}]}
{"op":"mcm","clk":"1012374916","pt":1580661043346,"mc":[{"id":"1.168223930","rc":[{"batl":[[0,1.44,1324.94],[1,2.88,0.31],[2,1.44,0]],"ltp":1.1,"tv":5001.01,"id":8257852}]}]}
{"op":"mcm","clk":"1012375487","pt":1580661046259,"mc":[{"id":"1.168223930","rc":[{"batl":[[0,1.11,532.68],[1,1.44,1324.94],[2,2.88,0.31]],"ltp":1.1,"tv":5001.01,"id":8257852}]}]}
{"op":"mcm","clk":"1012375665","pt":1580661047143,"mc":[{"id":"1.168223930","rc":[{"batb":[[0,10.5,30.09],[1,9,14.79],[2,7.8,19.67]],"batl":[[0,13.5,3.36]],"ltp":4.0,"tv":1971.48,"id":8444055},{"batb":[[0,1.08,2568.62],[2,1.04,1039.23]],"batl":[[0,1.1,1259.77],[1,1.11,1619.95],[2,1.44,1324.94]],"ltp":1.1,"tv":5001.01,"id":8257852}]}]}
{"op":"mcm","clk":"1012375807","pt":1580661048012,"mc":[{"id":"1.168223930","rc":[{"batb":[[2,1.01,15.51]],"ltp":4.0,"tv":1971.48,"id":8444055}]}]}
{"op":"mcm","clk":"1012376121","pt":1580661049650,"mc":[{"id":"1.168223930","rc":[{"batl":[[1,21,18.36]],"ltp":4.0,"tv":1971.48,"id":8444055},{"batl":[[1,1.11,1087.27]],"ltp":1.1,"tv":5001.01,"id":8257852}]}]}
{"op":"mcm","clk":"1012378923","pt":1580661064187,"mc":[{"id":"1.168223930","rc":[{"batb":[[0,1.08,168.04]],"batl":[[0,1.44,1324.94],[1,2.88,0.31],[2,1.44,0]],"ltp":1.1,"tv":5001.01,"id":8257852}]}]}
{"op":"mcm","clk":"1012379125","pt":1580661065263,"mc":[{"id":"1.168223930","rc":[{"batb":[[0,10.5,4.2]],"batl":[[0,11,16.8],[1,13.5,3.36],[2,21,18.36]],"ltp":4.0,"tv":1971.48,"id":8444055},{"batb":[[1,1.04,1039.23],[2,1.01,15.51]],"ltp":1.1,"tv":5001.01,"id":8257852}]}]}
{"op":"mcm","clk":"1012379317","pt":1580661066168,"mc":[{"id":"1.168223930","rc":[{"batb":[[0,9,14.79],[1,1.01,15.51],[2,1.01,0]],"batl":[[1,21,18.36],[2,21,0]],"ltp":4.0,"tv":1971.48,"id":8444055},{"batb":[[0,1.04,1039.23],[1,1.01,15.51],[2,1.01,0]],"ltp":1.1,"tv":5001.01,"id":8257852}]}]}
{"op":"mcm","clk":"1012379527","pt":1580661067184,"mc":[{"id":"1.168223930","rc":[{"batb":[[1,8.8,15.03],[2,1.01,15.51]],"ltp":4.0,"tv":1971.48,"id":8444055}]}]}
{"op":"mcm","clk":"1012379748","pt":1580661068270,"mc":[{"id":"1.168223930","rc":[{"batb":[[0,8.8,15.03],[1,1.01,15.51],[2,1.01,0]],"ltp":4.0,"tv":1971.48,"id":8444055},{"batb":[[0,1.04,1029]],"ltp":1.1,"tv":5001.01,"id":8257852}]}]}
{"op":"mcm","clk":"1012379913","pt":1580661069176,"mc":[{"id":"1.168223930","rc":[{"trd":[[11,16.8]],"batl":[[0,21,18.36],[1,21,0]],"ltp":11.0,"tv":1988.28,"id":8444055},{"trd":[[1.1,592.1]],"batb":[[0,1.08,1533.89],[1,1.07,874.79],[2,1.04,1029]],"batl":[[0,1.1,2188.89]],"ltp":1.1,"tv":5169.05,"id":8257852}],"tv":7157.34}]}
{"op":"mcm","clk":"1012380446","pt":1580661072194,"mc":[{"id":"1.168223930","rc":[{"batb":[[0,1.04,1029],[1,1.01,15.51],[2,1.04,0]],"batl":[[0,1.1,168.04]],"ltp":1.1,"tv":5169.05,"id":8257852}]}]}
{"op":"mcm","clk":"1012380615","pt":1580661073069,"mc":[{"id":"1.168223930","rc":[{"batl":[[0,1.37,1493.45]],"ltp":1.1,"tv":5169.05,"id":8257852}]}]}
{"op":"mcm","clk":"1012380976","pt":1580661075080,"mc":[{"id":"1.168223930","rc":[{"batb":[[0,1.06,817.73],[1,1.05,1643.64],[2,1.04,1029]],"batl":[[0,1.12,1362.18],[1,1.13,944.23],[2,1.37,1493.45]],"ltp":1.1,"tv":5169.05,"id":8257852}]}]}
{"op":"mcm","clk":"1012382432","pt":1580661083225,"mc":[{"id":"1.168223930","rc":[{"trd":[[1.06,8]],"batb":[[0,1.06,813.73]],"ltp":1.06,"tv":5177.05,"id":8257852}],"tv":7165.34}]}
{"op":"mcm","clk":"1012384546","pt":1580661095052,"mc":[{"id":"1.168223930","rc":[{"batb":[[0,1.04,1029],[1,1.01,15.51],[2,1.04,0]],"batl":[[0,1.37,1493.45],[1,2.88,0.31],[2,1.37,0]],"ltp":1.06,"tv":5177.05,"id":8257852}]}]}
{"op":"mcm","clk":"1012384737","pt":1580661096136,"mc":[{"id":"1.168223930","rc":[{"batl":[[0,1.22,1283.25],[1,1.37,1493.45],[2,2.88,0.31]],"ltp":1.06,"tv":5177.05,"id":8257852}]}]}
{"op":"mcm","clk":"1012385109","pt":1580661098145,"mc":[{"id":"1.168223930","rc":[{"batb":[[0,1.08,2400.58],[1,1.04,1029],[2,1.01,15.51]],"batl":[[0,1.1,1199.62],[1,1.11,1146.88],[2,1.37,1493.45]],"ltp":1.06,"tv":5177.05,"id":8257852}]}]}
{"op":"mcm","clk":"1012385823","pt":1580661101893,"mc":[{"id":"1.168223930","rc":[{"batl":[[2,1.22,1205.57]],"ltp":1.06,"tv":5177.05,"id":8257852}]}]}
{"op":"mcm","clk":"1012386104","pt":1580661103258,"mc":[{"id":"1.168223930","rc":[{"batb":[[0,1.04,1029],[1,1.01,15.51],[2,1.01,0]],"batl":[[0,1.22,1205.57],[1,1.37,1493.45],[2,2.88,0.31]],"ltp":1.06,"tv":5177.05,"id":8257852}]}]}
{"op":"mcm","clk":"1012386157","pt":1580661103582,"mc":[{"id":"1.168223930","rc":[{"batl":[[0,1.37,1493.45],[1,2.88,0.31],[2,2.88,0]],"ltp":1.06,"tv":5177.05,"id":8257852}]}]}
{"op":"mcm","clk":"1012386666","pt":1580661106190,"mc":[{"id":"1.168223930","rc":[{"batb":[[0,1.06,816.27],[1,1.05,1645.12],[2,1.04,1029]],"batl":[[0,1.12,1363.56],[1,1.13,942.86],[2,1.37,1493.45]],"ltp":1.06,"tv":5177.05,"id":8257852}]}]}
{"op":"mcm","clk":"1012386715","pt":1580661106411,"mc":[{"id":"1.168223930","rc":[{"batb":[[0,1.04,1029],[1,1.01,15.51],[2,1.04,0]],"batl":[[0,1.37,1493.45],[1,2.88,0.31],[2,1.37,0]],"ltp":1.06,"tv":5177.05,"id":8257852}]}]}
{"op":"mcm","clk":"1012387229","pt":1580661109095,"mc":[{"id":"1.168223930","rc":[{"batb":[[0,1.08,1595.39],[1,1.07,812.71],[2,1.04,1029]],"batl":[[0,1.1,2356.93],[1,1.37,1493.45],[2,2.88,0.31]],"ltp":1.06,"tv":5177.05,"id":8257852}]}]}
{"op":"mcm","clk":"1012387692","pt":1580661111779,"mc":[{"id":"1.168223930","rc":[{"batb":[[0,1.04,1029],[1,1.01,15.51],[2,1.04,0]],"batl":[[0,1.37,1493.45],[1,2.88,0.31],[2,2.88,0]],"ltp":1.06,"tv":5177.05,"id":8257852}]}]}
{"op":"mcm","clk":"1012388366","pt":1580661115160,"mc":[{"id":"1.168223930","rc":[{"batb":[[0,1.06,818.14],[1,1.05,1643.23],[2,1.04,1029]],"batl":[[0,1.12,1361.85],[1,1.13,944.56],[2,1.37,1493.45]],"ltp":1.06,"tv":5177.05,"id":8257852}]}]}
{"op":"mcm","clk":"1012388801","pt":1580661117179,"mc":[{"id":"1.168223930","rc":[{"batb":[[0,1.04,1029],[1,1.01,15.51],[2,1.04,0]],"ltp":1.06,"tv":5177.05,"id":8257852}]}]}
{"op":"mcm","clk":"1012389438","pt":1580661120120,"mc":[{"id":"1.168223930","rc":[{"batb":[[0,1.1,2072.15],[1,1.09,5918.7],[2,1.04,1029]],"ltp":1.06,"tv":5177.05,"id":8257852}]}]}
{"op":"mcm","clk":"1012389633","pt":1580661121116,"mc":[{"id":"1.168223930","rc":[{"batb":[[0,9,5.04],[1,8.8,15.03],[2,7.8,20.22]],"ltp":11.0,"tv":1988.28,"id":8444055},{"batb":[[1,1.09,6442.88],[2,1.06,749.84]],"batl":[[0,1.12,1403.86]],"ltp":1.06,"tv":5177.05,"id":8257852}]}]}
{"op":"mcm","clk":"1012389686","pt":1580661121398,"mc":[{"id":"1.168223930","rc":[{"batl":[[0,11.5,3.36]],"ltp":11.0,"tv":1988.28,"id":8444055}]}]}
{"op":"mcm","clk":"1012390037","pt":1580661123210,"mc":[{"id":"1.168223930","rc":[{"batl":[[1,18,15.97]],"ltp":11.0,"tv":1988.28,"id":8444055},{"batb":[[1,1.09,524.18]],"ltp":1.06,"tv":5177.05,"id":8257852}]}]}
{"op":"mcm","clk":"1012390943","pt":1580661128212,"mc":[{"id":"1.168223930","rc":[{"trd":[[1.1,601.55]],"batb":[[0,1.1,2067.43]],"ltp":1.1,"tv":5186.49,"id":8257852}],"tv":7174.78}]}
{"op":"mcm","clk":"1012391701","pt":1580661132203,"mc":[{"id":"1.168223930","rc":[{"batl":[[2,1.18,2121.53]],"ltp":1.1,"tv":5186.49,"id":8257852}]}]}
{"op":"mcm","clk":"1012392654","pt":1580661137202,"mc":[{"id":"1.168223930","rc":[{"batb":[[0,1.09,524.18],[1,1.06,749.84],[2,1.01,15.51]],"batl":[[0,1.12,42.01],[1,1.37,1493.45],[2,2.88,0.31]],"ltp":1.1,"tv":5186.49,"id":8257852}]}]}
{"op":"mcm","clk":"1012392848","pt":1580661138231,"mc":[{"id":"1.168223930","rc":[{"batb":[[0,7.8,20.22],[1,1.01,15.51],[2,7.8,0]],"batl":[[0,18,15.97],[1,18,0]],"ltp":11.0,"tv":1988.28,"id":8444055},{"batb":[[0,1.06,749.84],[1,1.01,15.51],[2,1.01,0]],"batl":[[0,1.37,1493.45],[1,2.88,0.31],[2,2.88,0]],"ltp":1.1,"tv":5186.49,"id":8257852}]}]}
{"op":"mcm","clk":"1012393218","pt":1580661140134,"mc":[{"id":"1.168223930","rc":[{"batb":[[0,1.07,2423.02],[1,1.06,749.84],[2,1.01,15.51]],"batl":[[0,1.14,1698.82],[1,1.15,570.4],[2,1.37,1493.45]],"ltp":1.1,"tv":5186.49,"id":8257852}]}]}
{"op":"mcm","clk":"1012394093","pt":1580661144235,"mc":[{"id":"1.168223930","rc":[{"batl":[[0,1.37,1493.45],[1,2.88,0.31],[2,1.37,0]],"ltp":1.1,"tv":5186.49,"id":8257852}]}]}
{"op":"mcm","clk":"1012394707","pt":1580661147240,"mc":[{"id":"1.168223930","rc":[{"batl":[[0,1.09,2035.05],[1,1.1,868.21],[2,1.37,1493.45]],"ltp":1.1,"tv":5186.49,"id":8257852}]}]}
{"op":"mcm","clk":"1012394891","pt":1580661148225,"mc":[{"id":"1.168223930","rc":[{"batb":[[0,11.5,21.01],[1,9.2,14.16],[2,1.01,15.51]],"ltp":11.0,"tv":1988.28,"id":8444055},{"batb":[[2,1.03,1482.92]],"ltp":1.1,"tv":5186.49,"id":8257852}]}]}
{"op":"mcm","clk":"1012395049","pt":1580661149015,"mc":[{"id":"1.168223930","rc":[{"batb":[[0,11.5,24.37]],"ltp":11.0,"tv":1988.28,"id":8444055},{"batb":[[0,1.07,2591.06]],"ltp":1.1,"tv":5186.49,"id":8257852}]}]}
{"op":"mcm","clk":"1012395226","pt":1580661149942,"mc":[{"id":"1.168223930","rc":[{"batl":[[0,1.09,1502.37]],"ltp":1.1,"tv":5186.49,"id":8257852}]}]}
{"op":"mcm","clk":"1012395438","pt":1580661151156,"mc":[{"id":"1.168223930","rc":[{"batl":[[0,26,21.44]],"ltp":11.0,"tv":1988.28,"id":8444055},{"batl":[[2,1.19,1375.5]],"ltp":1.1,"tv":5186.49,"id":8257852}]}]}
{"op":"mcm","clk":"1012396327","pt":1580661155222,"mc":[{"id":"1.168223930","rc":[{"trd":[[1.07,41.8]],"batb":[[0,1.07,2570.16]],"ltp":1.07,"tv":5228.29,"id":8257852}],"tv":7216.58}]}
{"op":"mcm","clk":"1012397296","pt":1580661160131,"mc":[{"id":"1.168223930","rc":[{"trd":[[1.07,45.16]],"batb":[[0,1.07,2568.48]],"ltp":1.07,"tv":5231.66,"id":8257852}],"tv":7219.94}]}
{"op":"mcm","clk":"1012398118","pt":1580661164256,"mc":[{"id":"1.168223930","rc":[{"batb":[[0,1.07,168.04]],"batl":[[0,1.37,1493.45],[1,2.88,0.31],[2,1.19,0]],"ltp":1.07,"tv":5231.66,"id":8257852}]}]}
{"op":"mcm","clk":"1012398263","pt":1580661164980,"mc":[{"id":"1.168223930","rc":[{"batb":[[0,11.5,3.36]],"ltp":11.0,"tv":1988.28,"id":8444055},{"batb":[[1,1.03,1482.92],[2,1.01,15.51]],"ltp":1.07,"tv":5231.66,"id":8257852}]}]}
{"op":"mcm","clk":"1012398474","pt":1580661166234,"mc":[{"id":"1.168223930","rc":[{"batb":[[0,9.2,14.16],[1,1.01,15.51],[2,1.01,0]],"ltp":11.0,"tv":1988.28,"id":8444055},{"batb":[[0,1.03,1482.92],[1,1.01,15.51],[2,1.01,0]],"ltp":1.07,"tv":5231.66,"id":8257852}]}]}
{"op":"mcm","clk":"1012398641","pt":1580661167159,"mc":[{"id":"1.168223930","rc":[{"batl":[[0,2.88,0.31],[1,2.88,0]],"ltp":1.07,"tv":5231.66,"id":8257852}]}]}
{"op":"mcm","clk":"1012399058","pt":1580661169254,"mc":[{"id":"1.168223930","rc":[{"batb":[[0,1.07,1207.43],[1,1.06,1227.05],[2,1.03,1482.92]],"batl":[[0,1.08,1048.71],[1,1.09,1339.46],[2,2.88,0.31]],"ltp":1.07,"tv":5231.66,"id":8257852}]}]}
{"op":"mcm","clk":"1012399621","pt":1580661172157,"mc":[{"id":"1.168223930","rc":[{"batb":[[0,1.03,1482.92],[1,1.01,15.51],[2,1.03,0]],"batl":[[0,2.88,0.31],[1,1.09,0],[2,2.88,0]],"ltp":1.07,"tv":5231.66,"id":8257852}]}]}
{"op":"mcm","clk":"1012400231","pt":1580661175068,"mc":[{"id":"1.168223930","rc":[{"batb":[[0,1.04,2492.91],[1,1.03,1482.92],[2,1.01,15.51]],"batl":[[0,1.11,447.89],[1,1.12,1870.95],[2,2.88,0.31]],"ltp":1.07,"tv":5231.66,"id":8257852}]}]}
{"op":"mcm","clk":"1012400615","pt":1580661176934,"mc":[{"id":"1.168223930","rc":[{"batl":[[0,2.88,0.31],[1,1.12,0],[2,2.88,0]],"ltp":1.07,"tv":5231.66,"id":8257852}]}]}
{"op":"mcm","clk":"1012401083","pt":1580661179262,"mc":[{"id":"1.168223930","rc":[{"batl":[[0,1.07,532.68],[1,2.88,0.31]],"ltp":1.07,"tv":5231.66,"id":8257852}]}]}
{"op":"mcm","clk":"1012401235","pt":1580661180054,"mc":[{"id":"1.168223930","rc":[{"batb":[[0,18.5,13.38],[1,13.5,14.48],[2,9.2,14.16]],"ltp":11.0,"tv":1988.28,"id":8444055},{"batl":[[0,1.05,1921.89],[1,1.06,542.11],[2,1.07,532.68]],"ltp":1.07,"tv":5231.66,"id":8257852}]}]}
{"op":"mcm","clk":"1012401515","pt":1580661181265,"mc":[{"id":"1.168223930","rc":[{"batb":[[2,1.01,15.51]],"ltp":11.0,"tv":1988.28,"id":8444055},{"batb":[[0,1.04,2660.95]],"ltp":1.07,"tv":5231.66,"id":8257852}]}]}
{"op":"mcm","clk":"1012401705","pt":1580661182264,"mc":[{"id":"1.168223930","rc":[{"batl":[[0,60,28.18]],"ltp":11.0,"tv":1988.28,"id":8444055},{"batl":[[2,1.32,1665.42]],"ltp":1.07,"tv":5231.66,"id":8257852}]}]}
{"op":"mcm","clk":"1012404624","pt":1580661198186,"mc":[{"id":"1.168223930","rc":[{"batb":[[0,1.03,1482.92],[1,1.01,15.51],[2,1.01,0]],"batl":[[0,1.32,1665.42],[1,2.88,0.31],[2,1.32,0]],"ltp":1.07,"tv":5231.66,"id":8257852}]}]}
{"op":"mcm","clk":"1012404748","pt":1580661199069,"mc":[{"id":"1.168223930","rc":[{"batb":[[0,13.5,14.48],[1,1.01,15.51],[2,1.01,0]],"ltp":11.0,"tv":1988.28,"id":8444055},{"batb":[[0,1.01,15.51],[1,1.01,0]],"ltp":1.07,"tv":5231.66,"id":8257852}]}]}
{"op":"mcm","clk":"1012404891","pt":1580661199982,"mc":[{"id":"1.168223930","rc":[{"trd":[[60,8.4]],"ltp":60.0,"tv":1996.69,"id":8444055},{"trd":[[1.01,530.31]],"batl":[[0,2.88,0.31],[1,2.88,0]],"ltp":1.01,"tv":5761.96,"id":8257852}],"tv":7758.65}]}
{"op":"mcm","clk":"1012405107","pt":1580661201172,"mc":[{"id":"1.168223930","rc":[{"batb":[[1,13,14.71],[2,1.01,15.51]],"ltp":60.0,"tv":1996.69,"id":8444055},{"batl":[[0,1.08,2400.58],[1,2.88,0.31]],"ltp":1.01,"tv":5761.96,"id":8257852}]}]}
{"op":"mcm","clk":"1012405262","pt":1580661202011,"mc":[{"id":"1.168223930","rc":[{"batb":[[0,13,14.71],[1,1.01,15.51],[2,1.01,0]],"ltp":60.0,"tv":1996.69,"id":8444055}]}]}
{"op":"mcm","clk":"1012405660","pt":1580661204173,"mc":[{"id":"1.168223930","rc":[{"batb":[[0,1.06,2445.87],[1,1.05,10653.66]],"ltp":1.01,"tv":5761.96,"id":8257852}]}]}
{"op":"mcm","clk":"1012405810","pt":1580661205072,"mc":[{"id":"1.168223930","rc":[{"batb":[[0,13.5,3.36],[1,13,14.71],[2,9.2,34.86]],"ltp":60.0,"tv":1996.69,"id":8444055},{"batb":[[1,1.05,11575.11]],"batl":[[0,1.08,2442.59]],"ltp":1.01,"tv":5761.96,"id":8257852}]}]}
{"op":"mcm","clk":"1012405981","pt":1580661206102,"mc":[{"id":"1.168223930","rc":[{"batl":[[0,34,23.82]],"ltp":60.0,"tv":1996.69,"id":8444055},{"batl":[[1,1.35,1575.86],[2,2.88,0.31]],"ltp":1.01,"tv":5761.96,"id":8257852}]}]}
{"op":"mcm","clk":"1012406159","pt":1580661207091,"mc":[{"id":"1.168223930","rc":[{"batb":[[1,1.05,921.44]],"ltp":1.01,"tv":5761.96,"id":8257852}]}]}
{"op":"mcm","clk":"1012407228","pt":1580661213191,"mc":[{"id":"1.168223930","rc":[{"batb":[[0,1.05,921.44],[1,1.05,0]],"batl":[[0,1.08,42.01]],"ltp":1.01,"tv":5761.96,"id":8257852}]}]}
{"op":"mcm","clk":"1012407416","pt":1580661214266,"mc":[{"id":"1.168223930","rc":[{"batb":[[0,9.2,34.86],[1,1.01,15.51],[2,9.2,0]],"ltp":60.0,"tv":1996.69,"id":8444055},{"batl":[[0,1.35,1575.86],[1,2.88,0.31],[2,2.88,0]],"ltp":1.01,"tv":5761.96,"id":8257852}]}]}
{"op":"mcm","clk":"1012407711","pt":1580661216177,"mc":[{"id":"1.168223930","rc":[{"batl":[[0,1.11,722.83],[1,1.12,1598.47],[2,2.88,0.31]],"ltp":1.01,"tv":5761.96,"id":8257852}]}]}
{"op":"mcm","clk":"1012410395","pt":1580661231229,"mc":[{"id":"1.168223930","rc":[{"batb":[[0,1.1,484.98],[1,1.09,1889.12],[2,1.07,7609.76]],"ltp":1.01,"tv":5761.96,"id":8257852}]}]}
{"op":"mcm","clk":"1012410571","pt":1580661232200,"mc":[{"id":"1.168223930","rc":[{"batb":[[1,7.8,20.22],[2,1.01,15.51]],"ltp":60.0,"tv":1996.69,"id":8444055},{"batb":[[1,1.09,2447.29]],"ltp":1.01,"tv":5761.96,"id":8257852}]}]}
{"op":"mcm","clk":"1012410716","pt":1580661233119,"mc":[{"id":"1.168223930","rc":[{"batb":[[0,9.4,4.2],[1,9.2,34.86],[2,7.8,20.22]],"batl":[[0,12.5,3.36]],"ltp":60.0,"tv":1996.69,"id":8444055}]}]}
{"op":"mcm","clk":"1012410942","pt":1580661234208,"mc":[{"id":"1.168223930","rc":[{"batb":[[2,1.05,937.42]],"batl":[[2,1.4,1773.83]],"ltp":1.01,"tv":5761.96,"id":8257852}]}]}
{"op":"mcm","clk":"1012413072","pt":1580661245223,"mc":[{"id":"1.168223930","rc":[{"batb":[[1,7.8,20.22],[2,1.01,15.51]],"ltp":60.0,"tv":1996.69,"id":8444055},{"batb":[[0,1.05,937.42],[1,1.09,0],[2,1.05,0]],"batl":[[0,1.4,1773.83],[1,2.88,0.31],[2,1.4,0]],"ltp":1.01,"tv":5761.96,"id":8257852}]}]}
{"op":"mcm","clk":"1012413257","pt":1580661246194,"mc":[{"id":"1.168223930","rc":[{"batb":[[0,7.8,20.22],[1,1.01,15.51],[2,1.01,0]],"ltp":60.0,"tv":1996.69,"id":8444055}]}]}
{"op":"mcm","clk":"1012413632","pt":1580661248242,"mc":[{"id":"1.168223930","rc":[{"batl":[[0,1.14,1672.75],[1,1.15,596.25],[2,1.4,1773.83]],"ltp":1.01,"tv":5761.96,"id":8257852}]}]}
{"op":"mcm","clk":"1012414180","pt":1580661251167,"mc":[{"id":"1.168223930","rc":[{"batb":[[0,8.2,5.04],[1,7.8,20.22],[2,1.01,15.51]],"batl":[[0,10.5,4.2]],"ltp":60.0,"tv":1996.69,"id":8444055},{"batb":[[0,1.12,898.08],[1,1.11,1353.4],[2,1.05,937.42]],"batl":[[0,1.14,1640.9]],"ltp":1.01,"tv":5761.96,"id":8257852}]}]}
{"op":"mcm","clk":"1012414344","pt":1580661252070,"mc":[{"id":"1.168223930","rc":[{"batb":[[2,7,25.73]],"ltp":60.0,"tv":1996.69,"id":8444055},{"batb":[[1,1.11,1791.58],[2,1.08,572.33]],"ltp":1.01,"tv":5761.96,"id":8257852}]}]}
{"op":"mcm","clk":"1012414726","pt":1580661254176,"mc":[{"id":"1.168223930","rc":[{"batb":[[0,1.12,973.52]],"batl":[[1,1.15,669.47]],"ltp":1.01,"tv":5761.96,"id":8257852}]}]}
{"op":"mcm","clk":"1012416030","pt":1580661261262,"mc":[{"id":"1.168223930","rc":[{"batb":[[1,7,25.73],[2,1.01,15.51]],"ltp":60.0,"tv":1996.69,"id":8444055},{"batb":[[0,1.08,572.33],[1,1.11,0],[2,1.08,0]],"batl":[[0,1.14,42.01]],"ltp":1.01,"tv":5761.96,"id":8257852}]}]}
{"op":"mcm","clk":"1012416177","pt":1580661262200,"mc":[{"id":"1.168223930","rc":[{"batb":[[0,7,25.73],[1,1.01,15.51],[2,1.01,0]],"ltp":60.0,"tv":1996.69,"id":8444055},{"batl":[[0,1.15,669.47],[1,1.4,1773.83],[2,2.88,0.31]],"ltp":1.01,"tv":5761.96,"id":8257852}]}]}
{"op":"mcm","clk":"1012416543","pt":1580661264101,"mc":[{"id":"1.168223930","rc":[{"batb":[[0,1.09,2378.56],[1,1.08,572.33]],"batl":[[0,1.15,786.68],[1,1.16,1436.83],[2,1.4,1773.83]],"ltp":1.01,"tv":5761.96,"id":8257852}]}]}
{"op":"mcm","clk":"1012416925","pt":1580661266081,"mc":[{"id":"1.168223930","rc":[{"batb":[[0,1.08,572.33],[1,1.08,0]],"ltp":1.01,"tv":5761.96,"id":8257852}]}]}
{"op":"mcm","clk":"1012417474","pt":1580661269088,"mc":[{"id":"1.168223930","rc":[{"batb":[[0,7.6,5.88],[1,7,25.73],[2,1.01,15.51]],"batl":[[0,9.4,4.2]],"ltp":60.0,"tv":1996.69,"id":8444055},{"batb":[[0,1.13,1584.33],[1,1.12,5155.39],[2,1.08,572.33]],"batl":[[0,1.15,828.69]],"ltp":1.01,"tv":5761.96,"id":8257852}]}]}
{"op":"mcm","clk":"1012417681","pt":1580661270177,"mc":[{"id":"1.168223930","rc":[{"batb":[[2,4.7,31.47]],"ltp":60.0,"tv":1996.69,"id":8444055},{"batb":[[0,1.13,1962.4],[1,1.12,5028.79],[2,1.09,547.55]],"batl":[[0,1.15,711.48]],"ltp":1.01,"tv":5761.96,"id":8257852}]}]}
{"op":"mcm","clk":"1012418093","pt":1580661272215,"mc":[{"id":"1.168223930","rc":[{"batb":[[1,1.12,589.76]],"ltp":1.01,"tv":5761.96,"id":8257852}]}]}
{"op":"mcm","clk":"1012418302","pt":1580661273197,"mc":[{"id":"1.168223930","rc":[{"batb":[[0,1.13,2087.88]],"ltp":1.01,"tv":5761.96,"id":8257852}]}]}
{"op":"mcm","clk":"1012419171","pt":1580661278015,"mc":[{"id":"1.168223930","rc":[{"batb":[[1,7,25.34],[2,4.8,31]],"ltp":60.0,"tv":1996.69,"id":8444055}]}]}
{"op":"mcm","clk":"1012421280","pt":1580661290191,"mc":[{"id":"1.168223930","rc":[{"batb":[[1,7,25.18],[2,4.8,30.84]],"ltp":60.0,"tv":1996.69,"id":8444055}]}]}
{"op":"mcm","clk":"1012422752","pt":1580661298248,"mc":[{"id":"1.168223930","rc":[{"batb":[[1,7,25.02],[2,4.8,30.69]],"ltp":60.0,"tv":1996.69,"id":8444055}]}]}
{"op":"mcm","clk":"1012424317","pt":1580661306653,"mc":[{"id":"1.168223930","rc":[{"batb":[[1,7,24.71],[2,4.8,30.29]],"ltp":60.0,"tv":1996.69,"id":8444055}]}]}
{"op":"mcm","clk":"1012424753","pt":1580661309245,"mc":[{"id":"1.168223930","rc":[{"trd":[[7.6,36.17]],"batb":[[0,7,24.71],[1,4.8,30.29],[2,1.01,15.51]],"ltp":7.6,"tv":2032.86,"id":8444055},{"trd":[[1.15,161.29]],"batl":[[0,1.15,550.19]],"ltp":1.15,"tv":5923.25,"id":8257852}],"tv":7956.11}]}
{"op":"mcm","clk":"1012425176","pt":1580661311952,"mc":[{"id":"1.168223930","rc":[{"batb":[[0,7.6,5.88],[1,7,24.71],[2,4.8,30.29]],"ltp":7.6,"tv":2032.86,"id":8444055},{"batb":[[1,1.12,757.8]],"batl":[[0,1.15,692.54]],"ltp":1.15,"tv":5923.25,"id":8257852}]}]}
{"op":"mcm","clk":"1012427676","pt":1580661326264,"mc":[{"id":"1.168223930","rc":[{"batb":[[1,7.2,24.63],[2,7,24.71]],"ltp":7.6,"tv":2032.86,"id":8444055}]}]}
{"op":"mcm","clk":"1012427748","pt":1580661326693,"mc":[{"id":"1.168223930","rc":[{"batb":[[2,4.8,30.14]],"ltp":7.6,"tv":2032.86,"id":8444055}]}]}
{"op":"mcm","clk":"1012431604","pt":1580661349176,"mc":[{"id":"1.168223930","rc":[{"trd":[[1.15,169.29]],"batl":[[0,1.15,688.54]],"ltp":1.15,"tv":5931.25,"id":8257852}],"tv":7964.11}]}
{"op":"mcm","clk":"1012432647","pt":1580661355103,"mc":[{"id":"1.168223930","rc":[{"batb":[[0,1.13,378.07],[1,1.12,168.04]],"batl":[[0,1.15,42.01],[1,1.4,1773.83],[2,2.88,0.31]],"ltp":1.15,"tv":5931.25,"id":8257852}]}]}
{"op":"mcm","clk":"1012432855","pt":1580661356209,"mc":[{"id":"1.168223930","rc":[{"batb":[[0,4.8,29.98],[1,1.01,15.51],[2,4.8,0]],"ltp":7.6,"tv":2032.86,"id":8444055},{"batb":[[0,1.09,547.55],[1,1.12,0],[2,1.09,0]],"batl":[[0,1.4,1773.83],[1,2.88,0.31],[2,2.88,0]],"ltp":1.15,"tv":5931.25,"id":8257852}]}]}
{"op":"mcm","clk":"1012433180","pt":1580661358119,"mc":[{"id":"1.168223930","rc":[{"batb":[[0,1.1,424.87],[1,1.09,2497.34]],"batl":[[0,1.24,674.06],[1,1.25,850.85],[2,1.4,1773.83]],"ltp":1.15,"tv":5931.25,"id":8257852}]}]}
{"op":"mcm","clk":"1012433560","pt":1580661360222,"mc":[{"id":"1.168223930","rc":[{"batl":[[0,1.4,1773.83],[1,2.88,0.31],[2,1.4,0]],"ltp":1.15,"tv":5931.25,"id":8257852}]}]}
{"op":"mcm","clk":"1012434135","pt":1580661363248,"mc":[{"id":"1.168223930","rc":[{"batl":[[0,1.11,763.13],[1,1.12,1558.52],[2,1.13,532.68]],"ltp":1.15,"tv":5931.25,"id":8257852}]}]}
{"op":"mcm","clk":"1012434308","pt":1580661364226,"mc":[{"id":"1.168223930","rc":[{"batb":[[0,9.2,34.15],[1,6.4,31.32],[2,1.01,15.51]],"ltp":7.6,"tv":2032.86,"id":8444055},{"batb":[[2,1.06,800.9]],"ltp":1.15,"tv":5931.25,"id":8257852}]}]}
{"op":"mcm","clk":"1012434497","pt":1580661365249,"mc":[{"id":"1.168223930","rc":[{"batb":[[0,9.6,4.2],[1,9.2,34.15],[2,6.4,31.32]],"batl":[[0,12.5,3.36]],"ltp":7.6,"tv":2032.86,"id":8444055}]}]}
{"op":"mcm","clk":"1012434654","pt":1580661366228,"mc":[{"id":"1.168223930","rc":[{"batl":[[2,1.4,1773.83]],"ltp":1.15,"tv":5931.25,"id":8257852}]}]}
{"op":"mcm","clk":"1012436873","pt":1580661378251,"mc":[{"id":"1.168223930","rc":[{"batb":[[1,6.4,31.32],[2,1.01,15.51]],"ltp":7.6,"tv":2032.86,"id":8444055},{"batb":[[0,1.06,800.9],[1,1.09,0],[2,1.06,0]],"batl":[[0,1.4,1773.83],[1,2.88,0.31],[2,1.4,0]],"ltp":1.15,"tv":5931.25,"id":8257852}]}]}
{"op":"mcm","clk":"1012437022","pt":1580661379035,"mc":[{"id":"1.168223930","rc":[{"batb":[[0,6.4,31.32],[1,1.01,15.51],[2,1.01,0]],"ltp":7.6,"tv":2032.86,"id":8444055}]}]}
{"op":"mcm","clk":"1012437439","pt":1580661381149,"mc":[{"id":"1.168223930","rc":[{"batb":[[0,1.11,15.14],[1,1.06,800.9]],"ltp":1.15,"tv":5931.25,"id":8257852}]}]}
{"op":"mcm","clk":"1012437816","pt":1580661383241,"mc":[{"id":"1.168223930","rc":[{"batb":[[0,1.11,494],[1,1.1,1873.71],[2,1.06,800.9]],"batl":[[0,1.12,505.01],[1,1.13,1793.81],[2,1.4,1773.83]],"ltp":1.15,"tv":5931.25,"id":8257852}]}]}
{"op":"mcm","clk":"1012438269","pt":1580661386098,"mc":[{"id":"1.168223930","rc":[{"batb":[[0,1.11,15.14],[1,1.06,800.9],[2,1.06,0]],"batl":[[0,1.4,1773.83],[1,2.88,0.31],[2,1.4,0]],"ltp":1.15,"tv":5931.25,"id":8257852}]}]}
{"op":"mcm","clk":"1012438790","pt":1580661389066,"mc":[{"id":"1.168223930","rc":[{"batb":[[1,1.07,2391.66],[2,1.06,800.9]],"batl":[[0,1.17,866.08],[1,1.18,1247.51],[2,1.4,1773.83]],"ltp":1.15,"tv":5931.25,"id":8257852}]}]}
{"op":"mcm","clk":"1012438974","pt":1580661390261,"mc":[{"id":"1.168223930","rc":[{"batb":[[1,1.06,800.9],[2,1.06,0]],"ltp":1.15,"tv":5931.25,"id":8257852}]}]}
{"op":"mcm","clk":"1012439537","pt":1580661393264,"mc":[{"id":"1.168223930","rc":[{"batb":[[0,7,6.72],[1,6.4,31.32],[2,1.01,15.51]],"ltp":7.6,"tv":2032.86,"id":8444055},{"batb":[[0,1.15,981.58],[1,1.14,1284.04],[2,1.12,4439.03]],"batl":[[0,1.17,908.09]],"ltp":1.15,"tv":5931.25,"id":8257852}]}]}
{"op":"mcm","clk":"1012439710","pt":1580661394249,"mc":[{"id":"1.168223930","rc":[{"batb":[[2,4.1,43.75]],"batl":[[0,8.6,5.04]],"ltp":7.6,"tv":2032.86,"id":8444055},{"batb":[[1,1.14,1619.07],[2,1.13,168.04]],"ltp":1.15,"tv":5931.25,"id":8257852}]}]}
{"op":"mcm","clk":"1012442114","pt":1580661407189,"mc":[{"id":"1.168223930","rc":[{"batb":[[1,4.1,43.2],[2,1.01,15.51]],"ltp":7.6,"tv":2032.86,"id":8444055},{"batb":[[0,1.13,168.04],[1,1.09,531.18],[2,1.13,0]],"batl":[[0,1.17,42.01],[1,1.4,1773.83],[2,2.88,0.31]],"ltp":1.15,"tv":5931.25,"id":8257852}]}]}
{"op":"mcm","clk":"1012442324","pt":1580661408263,"mc":[{"id":"1.168223930","rc":[{"batb":[[0,4.1,43.2],[1,1.01,15.51],[2,1.01,0]],"ltp":7.6,"tv":2032.86,"id":8444055},{"batb":[[0,1.09,531.18],[1,1.09,0]],"batl":[[0,1.4,1773.83],[1,2.88,0.31],[2,2.88,0]],"ltp":1.15,"tv":5931.25,"id":8257852}]}]}
{"op":"mcm","clk":"1012442680","pt":1580661410233,"mc":[{"id":"1.168223930","rc":[{"batb":[[0,1.1,1419.4],[1,1.09,1477.31]],"batl":[[0,1.29,474.81],[1,1.3,685.09],[2,1.4,1773.83]],"ltp":1.15,"tv":5931.25,"id":8257852}]}]}
{"op":"mcm","clk":"1012444091","pt":1580661418195,"mc":[{"id":"1.168223930","rc":[{"batb":[[0,1.09,531.18],[1,1.09,0]],"ltp":1.15,"tv":5931.25,"id":8257852}]}]}
{"op":"mcm","clk":"1012444638","pt":1580661421207,"mc":[{"id":"1.168223930","rc":[{"batb":[[0,1.26,853.47],[1,1.25,894.61],[2,1.23,2316.01]],"batl":[[2,2.88,0.31]],"ltp":1.15,"tv":5931.25,"id":8257852}]}]}
{"op":"mcm","clk":"1012444790","pt":1580661422121,"mc":[{"id":"1.168223930","rc":[{"batb":[[1,2.78,24.16],[2,1.01,15.51]],"ltp":7.6,"tv":2032.86,"id":8444055},{"batb":[[0,1.27,170.03],[1,1.26,853.47],[2,1.25,894.61]],"ltp":1.15,"tv":5931.25,"id":8257852}]}]}
{"op":"mcm","clk":"1012444982","pt":1580661423192,"mc":[{"id":"1.168223930","rc":[{"batb":[[0,4.5,11.76],[1,4.1,43.2],[2,2.78,24.16]],"batl":[[0,5.3,9.24]],"ltp":7.6,"tv":2032.86,"id":8444055},{"batl":[[0,1.28,42.01],[1,1.29,474.81],[2,1.3,685.09]],"ltp":1.15,"tv":5931.25,"id":8257852}]}]}
{"op":"mcm","clk":"1012447479","pt":1580661436197,"mc":[{"id":"1.168223930","rc":[{"batb":[[1,2.78,24],[2,1.01,15.51]],"ltp":7.6,"tv":2032.86,"id":8444055},{"batb":[[0,1.23,168.04],[1,1.17,289.16],[2,1.25,0]],"batl":[[1,1.58,1379.62],[2,2.88,0.31]],"ltp":1.15,"tv":5931.25,"id":8257852}]}]}
{"op":"mcm","clk":"1012447654","pt":1580661437218,"mc":[{"id":"1.168223930","rc":[{"batb":[[0,2.78,24],[1,1.01,15.51],[2,1.01,0]],"ltp":7.6,"tv":2032.86,"id":8444055},{"batb":[[0,1.17,289.16],[1,1.17,0]],"batl":[[0,1.58,1379.62],[1,2.88,0.31],[2,2.88,0]],"ltp":1.15,"tv":5931.25,"id":8257852}]}]}
{"op":"mcm","clk":"1012448424","pt":1580661441119,"mc":[{"id":"1.168223930","rc":[{"batb":[[0,1.3,748.97],[1,1.29,741.77],[2,1.17,289.16]],"batl":[[0,1.34,835.78],[1,1.35,559.92],[2,1.58,1379.62]],"ltp":1.15,"tv":5931.25,"id":8257852}]}]}
{"op":"mcm","clk":"1012448832","pt":1580661443133,"mc":[{"id":"1.168223930","rc":[{"batb":[[0,1.3,674.58]],"batl":[[0,1.34,589.03],[1,1.58,1379.62],[2,2.88,0.31]],"ltp":1.15,"tv":5931.25,"id":8257852}]}]}
{"op":"mcm","clk":"1012449184","pt":1580661445030,"mc":[{"id":"1.168223930","rc":[{"batb":[[0,1.17,289.16],[1,1.29,0],[2,1.17,0]],"batl":[[0,1.58,1379.62],[1,2.88,0.31],[2,2.88,0]],"ltp":1.15,"tv":5931.25,"id":8257852}]}]}
{"op":"mcm","clk":"1012449381","pt":1580661446117,"mc":[{"id":"1.168223930","rc":[{"batl":[[0,1.33,321.4],[1,1.58,1379.62],[2,2.88,0.31]],"ltp":1.15,"tv":5931.25,"id":8257852}]}]}
{"op":"mcm","clk":"1012449417","pt":1580661446319,"mc":[{"id":"1.168223930","rc":[{"batl":[[0,1.58,1379.62],[1,2.88,0.31],[2,2.88,0]],"ltp":1.15,"tv":5931.25,"id":8257852}]}]}
{"op":"mcm","clk":"1012449893","pt":1580661448838,"mc":[{"id":"1.168223930","rc":[{"batl":[[0,1.54,351.85],[1,1.55,312.99],[2,2.88,0.31]],"ltp":1.15,"tv":5931.25,"id":8257852}]}]}
{"op":"mcm","clk":"1012450150","pt":1580661450244,"mc":[{"id":"1.168223930","rc":[{"batb":[[0,1.49,520.42],[1,1.48,381.94],[2,1.41,1299.23]],"ltp":1.15,"tv":5931.25,"id":8257852}]}]}
{"op":"mcm","clk":"1012450355","pt":1580661451221,"mc":[{"id":"1.168223930","rc":[{"batb":[[0,2.9,21.85],[1,2.78,23.84],[2,2.02,58.22]],"batl":[[0,3.3,17.64]],"ltp":7.6,"tv":2032.86,"id":8444055},{"batb":[[0,1.5,77.74],[1,1.49,520.42],[2,1.48,381.94]],"batl":[[0,1.52,42.01],[1,1.54,351.85],[2,1.55,312.99]],"ltp":1.15,"tv":5931.25,"id":8257852}]}]}
{"op":"mcm","clk":"1012450536","pt":1580661452134,"mc":[{"id":"1.168223930","rc":[{"batl":[[0,3.25,18.48]],"ltp":7.6,"tv":2032.86,"id":8444055}]}]}
{"op":"mcm","clk":"1012451912","pt":1580661459230,"mc":[{"id":"1.168223930","rc":[{"trd":[[2.92,6.42]],"ltp":2.92,"tv":2039.27,"id":8444055},{"trd":[[1.52,12.33]],"batl":[[0,1.52,29.68]],"ltp":1.52,"tv":5943.58,"id":8257852}],"tv":7982.86}]}
{"op":"mcm","clk":"1012452097","pt":1580661460250,"mc":[{"id":"1.168223930","rc":[{"batl":[[0,1.54,351.85],[1,1.55,312.99],[2,1.82,1088.22]],"ltp":1.52,"tv":5943.58,"id":8257852}]}]}
{"op":"mcm","clk":"1012452471","pt":1580661462149,"mc":[{"id":"1.168223930","rc":[{"batb":[[0,2.78,23.84],[1,2.02,58.22],[2,1.01,15.51]],"ltp":2.92,"tv":2039.27,"id":8444055}]}]}
{"op":"mcm","clk":"1012452630","pt":1580661462953,"mc":[{"id":"1.168223930","rc":[{"batl":[[0,1.53,42.01],[1,1.54,351.85],[2,1.55,312.99]],"ltp":1.52,"tv":5943.58,"id":8257852}]}]}
{"op":"mcm","clk":"1012452891","pt":1580661464257,"mc":[{"id":"1.168223930","rc":[{"batb":[[0,2.84,22.69],[1,2.78,23.84],[2,2.02,58.22]],"batl":[[0,3.2,18.48]],"ltp":2.92,"tv":2039.27,"id":8444055},{"trd":[[1.53,84.02],[1.54,572.88]],"batl":[[0,1.54,65.41],[1,1.55,312.99],[2,1.82,1088.22]],"ltp":1.54,"tv":6600.48,"id":8257852}],"tv":8639.76}]}
{"op":"mcm","clk":"1012453077","pt":1580661465238,"mc":[{"id":"1.168223930","rc":[{"batb":[[1,1.49,369.32],[2,1.35,122.74]],"batl":[[0,1.55,312.99],[1,1.82,1088.22],[2,2.88,0.31]],"ltp":1.54,"tv":6600.48,"id":8257852}]}]}
{"op":"mcm","clk":"1012453287","pt":1580661466248,"mc":[{"id":"1.168223930","rc":[{"trd":[[1.49,153.52],[1.5,155.47]],"batb":[[0,1.35,122.74],[1,1.49,0],[2,1.35,0]],"batl":[[0,1.82,1088.22],[1,2.88,0.31],[2,2.88,0]],"ltp":1.49,"tv":6909.47,"id":8257852}],"tv":8948.74}]}
{"op":"mcm","clk":"1012453476","pt":1580661467230,"mc":[{"id":"1.168223930","rc":[{"batb":[[1,2.02,58.22],[2,1.01,15.51]],"ltp":2.92,"tv":2039.27,"id":8444055}]}]}
{"op":"mcm","clk":"1012453679","pt":1580661468254,"mc":[{"id":"1.168223930","rc":[{"batb":[[0,1.46,90.74],[1,1.35,122.74]],"batl":[[0,1.54,42.01],[1,1.82,1088.22],[2,2.88,0.31]],"ltp":1.49,"tv":6909.47,"id":8257852}]}]}
{"op":"mcm","clk":"1012453854","pt":1580661469130,"mc":[{"id":"1.168223930","rc":[{"batb":[[0,2.02,58.22],[1,1.01,15.51],[2,1.01,0]],"ltp":2.92,"tv":2039.27,"id":8444055},{"batb":[[0,1.35,122.74],[1,1.34,862.51],[2,1.33,630.61]],"batl":[[0,1.82,1088.22],[1,1.98,259.39],[2,2,266.6]],"ltp":1.49,"tv":6909.47,"id":8257852}]}]}
{"op":"mcm","clk":"1012454072","pt":1580661470253,"mc":[{"id":"1.168223930","rc":[{"batb":[[0,2.06,55.71]],"ltp":2.92,"tv":2039.27,"id":8444055},{"batb":[[0,1.34,128.41],[1,1.34,0],[2,1.33,0]],"batl":[[1,2.88,0.31],[2,2,0]],"ltp":1.49,"tv":6909.47,"id":8257852}]}]}
{"op":"mcm","clk":"1012454270","pt":1580661471242,"mc":[{"id":"1.168223930","rc":[{"batl":[[0,3.15,19.32]],"ltp":2.92,"tv":2039.27,"id":8444055}]}]}
{"op":"mcm","clk":"1012454621","pt":1580661473265,"mc":[{"id":"1.168223930","rc":[{"trd":[[1.82,14.7]],"batb":[[0,1.56,422.85],[1,1.55,315.45],[2,1.34,128.41]],"batl":[[0,1.62,471.04],[1,1.63,258.66],[2,1.82,1080.87]],"ltp":1.82,"tv":6924.17,"id":8257852}],"tv":8963.45}]}
{"op":"mcm","clk":"1012454834","pt":1580661474258,"mc":[{"id":"1.168223930","rc":[{"batb":[[0,1.34,128.41],[1,1.55,0],[2,1.34,0]],"batl":[[0,1.82,1080.87],[1,2.88,0.31],[2,1.82,0]],"ltp":1.82,"tv":6924.17,"id":8257852}]}]}
{"op":"mcm","clk":"1012455406","pt":1580661477250,"mc":[{"id":"1.168223930","rc":[{"batb":[[0,1.34,1017.78],[1,1.33,630.72]],"batl":[[1,1.98,241.58],[2,2,266.57]],"ltp":1.82,"tv":6924.17,"id":8257852}]}]}
{"op":"mcm","clk":"1012455583","pt":1580661478241,"mc":[{"id":"1.168223930","rc":[{"trd":[[1.82,15.9]],"batl":[[0,1.82,1080.27]],"ltp":1.82,"tv":6925.36,"id":8257852}],"tv":8964.64}]}
{"op":"mcm","clk":"1012455770","pt":1580661479165,"mc":[{"id":"1.168223930","rc":[{"batb":[[0,1.34,128.41],[1,1.33,0]],"ltp":1.82,"tv":6925.36,"id":8257852}]}]}
{"op":"mcm","clk":"1012456350","pt":1580661482148,"mc":[{"id":"1.168223930","rc":[{"batb":[[0,1.9,249.15],[1,1.88,316.22],[2,1.79,674.28]],"batl":[[0,1.98,241.58],[1,2,266.57],[2,2.88,0.31]],"ltp":1.82,"tv":6925.36,"id":8257852}]}]}
{"op":"mcm","clk":"1012456584","pt":1580661483271,"mc":[{"id":"1.168223930","rc":[{"batb":[[1,1.96,43.69],[2,1.88,37.22]],"ltp":2.92,"tv":2039.27,"id":8444055},{"batb":[[2,1.86,36.59]],"batl":[[2,2.04,40.33]],"ltp":1.82,"tv":6925.36,"id":8257852}]}]}
{"op":"mcm","clk":"1012456785","pt":1580661484264,"mc":[{"id":"1.168223930","rc":[{"trd":[[2.06,56.11]],"batb":[[0,2.06,55.67],[1,1.88,37.22],[2,1.01,15.51]],"ltp":2.06,"tv":2039.31,"id":8444055},{"trd":[[1.95,583]],"batl":[[2,2.88,0.31]],"ltp":1.95,"tv":6925.4,"id":8257852}],"tv":8964.72}]}
{"op":"mcm","clk":"1012456930","pt":1580661484971,"mc":[{"id":"1.168223930","rc":[{"batl":[[0,2.12,36.97]],"ltp":2.06,"tv":2039.31,"id":8444055},{"batb":[[1,1.89,47.05],[2,1.88,316.22]],"ltp":1.95,"tv":6925.4,"id":8257852}]}]}
{"op":"mcm","clk":"1012457165","pt":1580661486258,"mc":[{"id":"1.168223930","rc":[{"batb":[[1,1.95,43.69],[2,1.88,37.22]],"ltp":2.06,"tv":2039.31,"id":8444055},{"batl":[[2,2.06,39.49]],"ltp":1.95,"tv":6925.4,"id":8257852}]}]}
{"op":"mcm","clk":"1012459066","pt":1580661496263,"mc":[{"id":"1.168223930","rc":[{"trd":[[2.06,62.44]],"batb":[[0,2.06,49.34]],"ltp":2.06,"tv":2045.64,"id":8444055},{"trd":[[1.95,589.68]],"ltp":1.95,"tv":6932.09,"id":8257852}],"tv":8977.73}]}
{"op":"mcm","clk":"1012460837","pt":1580661505208,"mc":[{"id":"1.168223930","rc":[{"trd":[[2.06,111.78]],"batb":[[0,1.95,43.69],[1,1.88,37.22],[2,1.01,15.51]],"ltp":2.06,"tv":2094.98,"id":8444055},{"trd":[[1.95,641.81]],"batb":[[0,1.95,15.09],[1,1.9,249.15],[2,1.89,47.05]],"ltp":1.95,"tv":6984.21,"id":8257852}],"tv":9079.2}]}
{"op":"mcm","clk":"1012461425","pt":1580661508222,"mc":[{"id":"1.168223930","rc":[{"batb":[[0,1.89,47.05],[1,1.61,58.85],[2,1.89,0]],"batl":[[0,2.06,39.49],[1,2.36,758.65],[2,2.88,0.31]],"ltp":1.95,"tv":6984.21,"id":8257852}]}]}
{"op":"mcm","clk":"1012461560","pt":1580661508882,"mc":[{"id":"1.168223930","rc":[{"batb":[[0,1.88,37.22],[1,1.01,15.51],[2,1.01,0]],"ltp":2.06,"tv":2094.98,"id":8444055},{"batb":[[0,1.61,58.85],[1,1.61,0]],"batl":[[0,2.36,758.65],[1,2.88,0.31],[2,2.88,0]],"ltp":1.95,"tv":6984.21,"id":8257852}]}]}
{"op":"mcm","clk":"1012462014","pt":1580661511207,"mc":[{"id":"1.168223930","rc":[{"batb":[[0,1.01,15.51],[1,1.01,0]],"ltp":2.06,"tv":2094.98,"id":8444055}]}]}
{"op":"mcm","clk":"1012462179","pt":1580661512017,"mc":[{"id":"1.168223930","rc":[{"batb":[[0,1.85,38.48],[1,1.01,15.51]],"ltp":2.06,"tv":2094.98,"id":8444055},{"batb":[[0,1.63,56.97]],"ltp":1.95,"tv":6984.21,"id":8257852}]}]}
{"op":"mcm","clk":"1012462389","pt":1580661513211,"mc":[{"id":"1.168223930","rc":[{"batb":[[0,1.86,216.83],[1,1.85,38.48],[2,1.84,337.46]],"batl":[[0,1.94,328.6],[1,1.96,281.48]],"ltp":2.06,"tv":2094.98,"id":8444055},{"batb":[[0,2,532.68],[1,1.63,56.97]],"batl":[[0,2.24,33.61],[1,2.36,758.65],[2,2.88,0.31]],"ltp":1.95,"tv":6984.21,"id":8257852}]}]}
{"op":"mcm","clk":"1012462559","pt":1580661514119,"mc":[{"id":"1.168223930","rc":[{"batl":[[1,1.96,323.49]],"ltp":2.06,"tv":2094.98,"id":8444055},{"batb":[[0,2.04,40.33],[1,2,532.68],[2,1.63,56.97]],"ltp":1.95,"tv":6984.21,"id":8257852}]}]}
{"op":"mcm","clk":"1012462771","pt":1580661515210,"mc":[{"id":"1.168223930","rc":[{"batl":[[0,1.94,289.07]],"ltp":2.06,"tv":2094.98,"id":8444055},{"batb":[[0,2.06,52.87],[1,2.04,40.33],[2,2,532.68]],"ltp":1.95,"tv":6984.21,"id":8257852}]}]}
{"op":"mcm","clk":"1012462959","pt":1580661516225,"mc":[{"id":"1.168223930","rc":[{"batb":[[2,1.83,38.79]],"ltp":1.95,"tv":6984.21,"id":8257852}]}]}
{"op":"mcm","clk":"1012463349","pt":1580661518219,"mc":[{"id":"1.168223930","rc":[{"batb":[[0,1.86,258.02]],"ltp":2.06,"tv":2094.98,"id":8444055}]}]}
{"op":"mcm","clk":"1012464710","pt":1580661525145,"mc":[{"id":"1.168223930","rc":[{"batb":[[0,1.82,50.41],[1,1.72,48],[2,1.01,15.51]],"batl":[[0,1.96,42.01],[1,1.96,0]],"ltp":2.06,"tv":2094.98,"id":8444055},{"batb":[[0,2.04,40.33],[1,1.83,38.79],[2,1.83,0]],"ltp":1.95,"tv":6984.21,"id":8257852}]}]}
{"op":"mcm","clk":"1012464927","pt":1580661526263,"mc":[{"id":"1.168223930","rc":[{"batb":[[0,1.72,48],[1,1.01,15.51],[2,1.01,0]],"ltp":2.06,"tv":2094.98,"id":8444055},{"batb":[[0,1.83,38.79],[1,1.83,0]],"batl":[[0,2.36,758.65],[1,2.88,0.31],[2,2.88,0]],"ltp":1.95,"tv":6984.21,"id":8257852}]}]}
{"op":"mcm","clk":"1012465303","pt":1580661528172,"mc":[{"id":"1.168223930","rc":[{"batb":[[0,1.75,357.9],[1,1.73,460.85],[2,1.01,15.51]],"batl":[[0,2.2,302.33],[1,2.22,197.68]],"ltp":2.06,"tv":2094.98,"id":8444055}]}]}
{"op":"mcm","clk":"1012465728","pt":1580661530262,"mc":[{"id":"1.168223930","rc":[{"batl":[[0,1.79,8.4],[1,2.2,302.33],[2,2.22,197.68]],"ltp":2.06,"tv":2094.98,"id":8444055}]}]}
{"op":"mcm","clk":"1012466644","pt":1580661534932,"mc":[{"id":"1.168223930","rc":[{"trd":[[1.79,8.9]],"batl":[[0,2.2,302.33],[1,2.22,197.68],[2,2.22,0]],"ltp":1.79,"tv":2103.38,"id":8444055},{"trd":[[2.26,6.66]],"batl":[[0,2.36,758.8]],"ltp":2.26,"tv":6990.87,"id":8257852}],"tv":9094.26}]}
{"op":"mcm","clk":"1012467096","pt":1580661537256,"mc":[{"id":"1.168223930","rc":[{"batb":[[0,1.73,47.92],[1,1.01,15.51],[2,1.01,0]],"ltp":1.79,"tv":2103.38,"id":8444055}]}]}
{"op":"mcm","clk":"1012467654","pt":1580661540245,"mc":[{"id":"1.168223930","rc":[{"batb":[[0,1.97,549.15],[1,1.73,47.92],[2,1.01,15.51]],"ltp":1.79,"tv":2103.38,"id":8444055},{"batb":[[0,1.84,246.55],[1,1.83,38.79],[2,1.82,351.48]],"batl":[[0,1.92,341.11],[1,1.94,292.47],[2,2.36,758.8]],"ltp":2.26,"tv":6990.87,"id":8257852}]}]}
{"op":"mcm","clk":"1012467844","pt":1580661541268,"mc":[{"id":"1.168223930","rc":[{"batb":[[0,2.1,52.24],[1,1.99,42.01],[2,1.97,549.15]],"batl":[[0,2.18,35.29]],"ltp":1.79,"tv":2103.38,"id":8444055},{"batb":[[0,1.84,296.12]],"batl":[[2,2,42.01]],"ltp":2.26,"tv":6990.87,"id":8257852}]}]}
{"op":"mcm","clk":"1012468236","pt":1580661543063,"mc":[{"id":"1.168223930","rc":[{"batb":[[2,1.87,37.22]],"ltp":1.79,"tv":2103.38,"id":8444055}]}]}
{"op":"mcm","clk":"1012470435","pt":1580661554253,"mc":[{"id":"1.168223930","rc":[{"batb":[[1,1.87,37.22],[2,1.01,15.51]],"ltp":1.79,"tv":2103.38,"id":8444055}]}]}
{"op":"mcm","clk":"1012471030","pt":1580661557173,"mc":[{"id":"1.168223930","rc":[{"batb":[[1,2,42.01],[2,1.87,37.22]],"ltp":1.79,"tv":2103.38,"id":8444055}]}]}
{"op":"mcm","clk":"1012471438","pt":1580661559261,"mc":[{"id":"1.168223930","rc":[{"batb":[[0,1.84,49.57],[2,1.54,70.58]],"batl":[[0,2,42.01],[1,2.36,758.8],[2,2.88,0.31]],"ltp":2.26,"tv":6990.87,"id":8257852}]}]}
{"op":"mcm","clk":"1012471573","pt":1580661559867,"mc":[{"id":"1.168223930","rc":[{"batb":[[0,2,42.01],[1,1.87,36.9],[2,1.01,15.51]],"ltp":1.79,"tv":2103.38,"id":8444055},{"batb":[[1,1.54,70.58],[2,1.54,0]],"ltp":2.26,"tv":6990.87,"id":8257852}]}]}
{"op":"mcm","clk":"1012471820","pt":1580661561169,"mc":[{"id":"1.168223930","rc":[{"batb":[[0,1.87,36.9],[1,1.01,15.51],[2,1.01,0]],"ltp":1.79,"tv":2103.38,"id":8444055},{"batb":[[0,1.54,70.58],[1,1.54,0]],"batl":[[0,2.36,758.8],[1,2.88,0.31],[2,2.88,0]],"ltp":2.26,"tv":6990.87,"id":8257852}]}]}
{"op":"mcm","clk":"1012472554","pt":1580661565264,"mc":[{"id":"1.168223930","rc":[{"batb":[[0,1.87,372.55],[1,1.85,331.87],[2,1.01,15.51]],"batl":[[0,1.96,338.43],[1,1.98,273.05]],"ltp":1.79,"tv":2103.38,"id":8444055},{"batb":[[0,1.94,566.68],[1,1.54,70.58]],"ltp":2.26,"tv":6990.87,"id":8257852}]}]}
{"op":"mcm","clk":"1012472670","pt":1580661565944,"mc":[{"id":"1.168223930","rc":[{"batb":[[2,1.72,48.63]],"ltp":1.79,"tv":2103.38,"id":8444055},{"batb":[[0,2.04,55.16],[1,1.94,566.68],[2,1.77,43.83]],"ltp":2.26,"tv":6990.87,"id":8257852}]}]}
{"op":"mcm","clk":"1012473093","pt":1580661568206,"mc":[{"id":"1.168223930","rc":[{"batb":[[2,1.83,50.41]],"batl":[[1,1.98,315.06]],"ltp":1.79,"tv":2103.38,"id":8444055},{"batb":[[1,2.02,41.17]],"batl":[[0,2.22,33.61],[1,2.36,758.8],[2,2.88,0.31]],"ltp":2.26,"tv":6990.87,"id":8257852}]}]}
{"op":"mcm","clk":"1012474953","pt":1580661578202,"mc":[{"id":"1.168223930","rc":[{"batb":[[0,1.83,50.41],[1,1.72,48.63],[2,1.01,15.51]],"batl":[[0,1.98,42.01],[1,1.98,0]],"ltp":1.79,"tv":2103.38,"id":8444055},{"batb":[[0,2.02,41.17],[1,1.77,43.83],[2,1.77,0]],"ltp":2.26,"tv":6990.87,"id":8257852}]}]}
{"op":"mcm","clk":"1012475096","pt":1580661578971,"mc":[{"id":"1.168223930","rc":[{"batb":[[0,1.72,48.63],[1,1.01,15.51],[2,1.01,0]],"ltp":1.79,"tv":2103.38,"id":8444055},{"batb":[[0,1.77,43.83],[1,1.77,0]],"batl":[[0,2.36,758.8],[1,2.88,0.31],[2,2.88,0]],"ltp":2.26,"tv":6990.87,"id":8257852}]}]}
{"op":"mcm","clk":"1012475306","pt":1580661580205,"mc":[{"id":"1.168223930","rc":[{"batb":[[0,1.74,342.31],[1,1.72,469.47],[2,1.01,15.51]],"batl":[[0,2.28,221.03],[1,2.3,179.52]],"ltp":1.79,"tv":2103.38,"id":8444055}]}]}
{"op":"mcm","clk":"1012475844","pt":1580661583198,"mc":[{"id":"1.168223930","rc":[{"batl":[[0,2.88,0.47],[1,2.88,0]],"ltp":2.26,"tv":6990.87,"id":8257852}]}]}
{"op":"mcm","clk":"1012476032","pt":1580661584199,"mc":[{"id":"1.168223930","rc":[{"batl":[[0,1.81,794.64],[1,1.83,346.54]],"ltp":1.79,"tv":2103.38,"id":8444055}]}]}
{"op":"mcm","clk":"1012476175","pt":1580661585078,"mc":[{"id":"1.168223930","rc":[{"batb":[[2,1.66,55.23]],"ltp":1.79,"tv":2103.38,"id":8444055},{"trd":[[2.26,6.97]],"batb":[[0,2.26,40.91],[1,2.06,53.5]],"batl":[[0,2.88,0.31]],"ltp":2.26,"tv":6991.19,"id":8257852}],"tv":9094.57}]}
{"op":"mcm","clk":"1012476275","pt":1580661585712,"mc":[{"id":"1.168223930","rc":[{"batl":[[0,2.38,30.25],[1,2.88,0.31]],"ltp":2.26,"tv":6991.19,"id":8257852}]}]}
{"op":"mcm","clk":"1012476495","pt":1580661587137,"mc":[{"id":"1.168223930","rc":[{"batb":[[1,1.72,527.44]],"batl":[[0,1.81,261.96],[2,1.84,42.01]],"ltp":1.79,"tv":2103.38,"id":8444055},{"batb":[[1,2.18,35.29],[2,2.06,53.5]],"batl":[[1,2.72,631.54],[2,2.88,0.31]],"ltp":2.26,"tv":6991.19,"id":8257852}]}]}
{"op":"mcm","clk":"1012477368","pt":1580661592106,"mc":[{"id":"1.168223930","rc":[{"trd":[[1.8,51.37],[1.81,708.52]],"batl":[[0,1.81,124.18]],"ltp":1.81,"tv":2430.32,"id":8444055},{"trd":[[2.26,47.89]],"batb":[[0,2.18,35.29],[1,2.06,53.5],[2,2.06,0]],"ltp":2.26,"tv":7032.1,"id":8257852}],"tv":9462.42}]}
{"op":"mcm","clk":"1012477539","pt":1580661593079,"mc":[{"id":"1.168223930","rc":[{"batl":[[0,1.84,42.01],[1,1.83,0],[2,1.84,0]],"ltp":1.81,"tv":2430.32,"id":8444055}]}]}
{"op":"mcm","clk":"1012478102","pt":1580661596257,"mc":[{"id":"1.168223930","rc":[{"batb":[[0,1.74,394.82]],"batl":[[0,1.82,385.72],[1,1.84,382.02]],"ltp":1.81,"tv":2430.32,"id":8444055}]}]}
{"op":"mcm","clk":"1012478410","pt":1580661598161,"mc":[{"id":"1.168223930","rc":[{"batb":[[0,1.72,106.6],[1,1.66,55.23],[2,1.01,15.51]],"batl":[[0,1.84,42.01],[1,1.84,0]],"ltp":1.81,"tv":2430.32,"id":8444055}]}]}
{"op":"mcm","clk":"1012478575","pt":1580661599078,"mc":[{"id":"1.168223930","rc":[{"batb":[[0,1.72,57.97]],"ltp":1.81,"tv":2430.32,"id":8444055}]}]}
{"op":"mcm","clk":"1012478962","pt":1580661601260,"mc":[{"id":"1.168223930","rc":[{"batb":[[0,1.69,317.73],[1,1.67,465.14],[2,1.66,55.23]],"ltp":1.81,"tv":2430.32,"id":8444055},{"batb":[[0,2.06,53.5],[1,2.06,0]],"batl":[[0,2.72,631.54],[1,2.88,0.31],[2,2.88,0]],"ltp":2.26,"tv":7032.1,"id":8257852}]}]}
{"op":"mcm","clk":"1012479131","pt":1580661602192,"mc":[{"id":"1.168223930","rc":[{"batb":[[1,1.68,53.98],[2,1.67,465.14]],"ltp":1.81,"tv":2430.32,"id":8444055},{"batb":[[0,2.04,54.84]],"ltp":2.26,"tv":7032.1,"id":8257852}]}]}
{"op":"mcm","clk":"1012479479","pt":1580661604170,"mc":[{"id":"1.168223930","rc":[{"batl":[[0,1.76,923.98],[1,1.78,377.29]],"ltp":1.81,"tv":2430.32,"id":8444055}]}]}
{"op":"mcm","clk":"1012479694","pt":1580661605190,"mc":[{"id":"1.168223930","rc":[{"batb":[[0,2.34,36.59],[1,2.14,120.1],[2,2.1,49.73]],"ltp":2.26,"tv":7032.1,"id":8257852}]}]}
{"op":"mcm","clk":"1012479830","pt":1580661605992,"mc":[{"id":"1.168223930","rc":[{"batb":[[2,1.67,527.31]],"batl":[[1,1.78,419.3]],"ltp":1.81,"tv":2430.32,"id":8444055},{"batb":[[1,2.26,32.77],[2,2.14,120.1]],"batl":[[0,2.52,26.89],[1,2.72,631.54],[2,2.88,0.31]],"ltp":2.26,"tv":7032.1,"id":8257852}]}]}
{"op":"mcm","clk":"1012480042","pt":1580661607079,"mc":[{"id":"1.168223930","rc":[{"batl":[[0,1.76,391.3]],"ltp":1.81,"tv":2430.32,"id":8444055}]}]}
{"op":"mcm","clk":"1012480414","pt":1580661609184,"mc":[{"id":"1.168223930","rc":[{"batb":[[2,2.1,49.73]],"ltp":2.26,"tv":7032.1,"id":8257852}]}]}
{"op":"mcm","clk":"1012481004","pt":1580661612175,"mc":[{"id":"1.168223930","rc":[{"trd":[[1.75,48.92],[1.76,782.62],[1.78,212.85]],"batl":[[0,1.78,312.88],[1,1.78,0]],"ltp":1.78,"tv":3474.7,"id":8444055},{"trd":[[2.34,36.59]],"batb":[[0,2.26,32.77],[1,2.1,49.73],[2,2.1,0]],"ltp":2.34,"tv":7068.69,"id":8257852}],"tv":10543.39}]}
{"op":"mcm","clk":"1012481174","pt":1580661613206,"mc":[{"id":"1.168223930","rc":[{"batb":[[0,1.68,53.98],[1,1.67,62.17],[2,1.46,90.17]],"batl":[[0,1.78,42.01]],"ltp":1.78,"tv":3474.7,"id":8444055}]}]}
{"op":"mcm","clk":"1012481711","pt":1580661616200,"mc":[{"id":"1.168223930","rc":[{"batb":[[0,1.7,282.62],[1,1.68,508.29],[2,1.67,62.17]],"batl":[[0,1.77,398.27],[1,1.78,42.01],[2,1.79,369.65]],"ltp":1.78,"tv":3474.7,"id":8444055}]}]}
{"op":"mcm","clk":"1012481885","pt":1580661617185,"mc":[{"id":"1.168223930","rc":[{"batl":[[0,1.78,42.01],[1,1.78,0],[2,1.79,0]],"ltp":1.78,"tv":3474.7,"id":8444055}]}]}
{"op":"mcm","clk":"1012482405","pt":1580661620204,"mc":[{"id":"1.168223930","rc":[{"batl":[[0,1.76,230.19],[1,1.78,419.31]],"ltp":1.78,"tv":3474.7,"id":8444055}]}]}
{"op":"mcm","clk":"1012482590","pt":1580661621264,"mc":[{"id":"1.168223930","rc":[{"batb":[[1,1.69,52.87],[2,1.68,454.31]],"ltp":1.78,"tv":3474.7,"id":8444055},{"batb":[[0,2.32,37.45],[1,2.26,32.77],[2,2.08,50.83]],"ltp":2.34,"tv":7068.69,"id":8257852}]}]}
{"op":"mcm","clk":"1012485502","pt":1580661637233,"mc":[{"id":"1.168223930","rc":[{"trd":[[1.76,786.6]],"batl":[[0,1.76,226.21]],"ltp":1.76,"tv":3478.68,"id":8444055},{"trd":[[2.3,3.04],[2.32,74.9]],"batb":[[0,2.26,32.77],[1,2.08,50.83],[2,2.08,0]],"ltp":2.3,"tv":7146.63,"id":8257852}],"tv":10625.32}]}
{"op":"mcm","clk":"1012485662","pt":1580661638214,"mc":[{"id":"1.168223930","rc":[{"batb":[[0,1.69,52.87],[1,1.67,62.17],[2,1.47,88.52]],"ltp":1.76,"tv":3478.68,"id":8444055}]}]}
{"op":"mcm","clk":"1012486125","pt":1580661640755,"mc":[{"id":"1.168223930","rc":[{"batb":[[0,1.69,495.95],[1,1.67,527.44]],"batl":[[0,1.76,270.9]],"ltp":1.76,"tv":3478.68,"id":8444055}]}]}
{"op":"mcm","clk":"1012486861","pt":1580661645060,"mc":[{"id":"1.168223930","rc":[{"batb":[[0,1.7,51.85],[1,1.69,495.95],[2,1.67,527.44]],"ltp":1.76,"tv":3478.68,"id":8444055},{"batb":[[0,2.3,38.32],[1,2.26,32.77],[2,2.08,50.83]],"ltp":2.3,"tv":7146.63,"id":8257852}]}]}
{"op":"mcm","clk":"1012487022","pt":1580661645897,"mc":[{"id":"1.168223930","rc":[{"batb":[[1,1.69,443.08]],"ltp":1.76,"tv":3478.68,"id":8444055}]}]}
{"op":"mcm","clk":"1012487566","pt":1580661649192,"mc":[{"id":"1.168223930","rc":[{"trd":[[2.3,36.79]],"batb":[[0,2.3,21.45]],"ltp":2.3,"tv":7180.38,"id":8257852}],"tv":10659.06}]}
{"op":"mcm","clk":"1012488236","pt":1580661653050,"mc":[{"id":"1.168223930","rc":[{"trd":[[1.7,16.01]],"batb":[[0,1.71,51.3],[1,1.7,43.84],[2,1.69,443.08]],"ltp":1.7,"tv":3494.69,"id":8444055}],"tv":10675.08}]}
{"op":"mcm","clk":"1012488345","pt":1580661653592,"mc":[{"id":"1.168223930","rc":[{"batb":[[1,1.69,443.08],[2,1.67,527.44]],"ltp":1.7,"tv":3494.69,"id":8444055},{"batb":[[2,2.06,52.56]],"ltp":2.3,"tv":7180.38,"id":8257852}]}]}
{"op":"mcm","clk":"1012489356","pt":1580661659212,"mc":[{"id":"1.168223930","rc":[{"batb":[[2,2.06,52.4]],"ltp":2.3,"tv":7180.38,"id":8257852}]}]}
{"op":"mcm","clk":"1012490407","pt":1580661665097,"mc":[{"id":"1.168223930","rc":[{"trd":[[1.67,346.84],[1.69,886.16],[1.71,102.6]],"batb":[[0,1.67,354.02],[1,1.48,86],[2,1.01,15.51]],"batl":[[0,1.78,42.01],[1,1.78,0]],"ltp":1.67,"tv":4830.3,"id":8444055},{"batb":[[1,2.06,52.4],[2,2.06,0]],"ltp":2.3,"tv":7180.38,"id":8257852}],"tv":12010.68}]}
{"op":"mcm","clk":"1012490885","pt":1580661667910,"mc":[{"id":"1.168223930","rc":[{"batb":[[0,1.69,233.32],[1,1.67,465.28],[2,1.66,63.01]],"batl":[[0,1.75,279.36],[1,1.77,385.36],[2,1.78,42.01]],"ltp":1.67,"tv":4830.3,"id":8444055},{"batb":[[1,2.28,32.77],[2,2.06,52.4]],"ltp":2.3,"tv":7180.38,"id":8257852}]}]}
{"op":"mcm","clk":"1012491266","pt":1580661670142,"mc":[{"id":"1.168223930","rc":[{"trd":[[1.69,899.34]],"batb":[[0,1.69,220.14]],"ltp":1.69,"tv":4843.48,"id":8444055},{"trd":[[2.46,9.06]],"ltp":2.46,"tv":7189.44,"id":8257852}],"tv":12032.92}]}
{"op":"mcm","clk":"1012491430","pt":1580661671062,"mc":[{"id":"1.168223930","rc":[{"batb":[[0,1.67,234.75],[1,1.66,63.01],[2,1.48,86]],"batl":[[0,1.7,3.54],[1,1.75,279.36],[2,1.77,385.36]],"ltp":1.69,"tv":4843.48,"id":8444055}]}]}
{"op":"mcm","clk":"1012491965","pt":1580661673757,"mc":[{"id":"1.168223930","rc":[{"batb":[[0,1.68,459],[1,1.67,234.75],[2,1.66,63.01]],"ltp":1.69,"tv":4843.48,"id":8444055}]}]}
{"op":"mcm","clk":"1012493953","pt":1580661684173,"mc":[{"id":"1.168223930","rc":[{"batb":[[0,1.66,63.01],[1,1.48,86],[2,1.01,15.51]],"batl":[[1,1.78,42.01],[2,1.77,0]],"ltp":1.69,"tv":4843.48,"id":8444055}]}]}
{"op":"mcm","clk":"1012494004","pt":1580661684487,"mc":[{"id":"1.168223930","rc":[{"batb":[[0,2.28,32.77],[1,2.06,52.4],[2,2.06,0]],"ltp":2.46,"tv":7189.44,"id":8257852}]}]}
{"op":"mcm","clk":"1012494467","pt":1580661687090,"mc":[{"id":"1.168223930","rc":[{"batb":[[0,1.48,636.97],[1,1.47,380.33]],"batl":[[1,1.9,207.31],[2,1.92,299.76]],"ltp":1.69,"tv":4843.48,"id":8444055},{"batb":[[0,2.06,52.4],[1,2.06,0]],"batl":[[0,2.72,631.54],[1,2.88,0.31],[2,2.88,0]],"ltp":2.46,"tv":7189.44,"id":8257852}]}]}
{"op":"mcm","clk":"1012494681","pt":1580661688174,"mc":[{"id":"1.168223930","rc":[{"batb":[[0,1.48,550.97],[1,1.47,468.69]],"ltp":1.69,"tv":4843.48,"id":8444055},{"batb":[[0,2.08,50.91]],"ltp":2.46,"tv":7189.44,"id":8257852}]}]}
{"op":"mcm","clk":"1012495031","pt":1580661690103,"mc":[{"id":"1.168223930","rc":[{"batb":[[0,1.47,88.36],[1,1.01,15.51],[2,1.01,0]],"batl":[[1,1.9,0],[2,1.92,0]],"ltp":1.69,"tv":4843.48,"id":8444055}]}]}
{"op":"mcm","clk":"1012495642","pt":1580661693265,"mc":[{"id":"1.168223930","rc":[{"trd":[[1.7,23.09]],"batb":[[0,1.83,238.89],[1,1.81,355.9],[2,1.79,670.74]],"batl":[[0,1.88,42.01],[1,1.9,207.31],[2,1.92,299.76]],"ltp":1.7,"tv":4850.55,"id":8444055},{"batb":[[0,2.12,36.97],[1,2.08,50.91]],"batl":[[0,2.88,0.31],[1,2.88,0]],"ltp":2.46,"tv":7189.44,"id":8257852}],"tv":12039.99}]}
{"op":"mcm","clk":"1012495782","pt":1580661694079,"mc":[{"id":"1.168223930","rc":[{"batb":[[0,1.84,39.89],[1,1.83,238.89],[2,1.81,355.9]],"ltp":1.7,"tv":4850.55,"id":8444055},{"batb":[[2,1.94,32.02]],"batl":[[0,2.3,3.03],[1,2.88,0.31]],"ltp":2.46,"tv":7189.44,"id":8257852}]}]}
{"op":"mcm","clk":"1012495894","pt":1580661694710,"mc":[{"id":"1.168223930","rc":[{"batl":[[0,2.88,0.31],[1,2.88,0]],"ltp":2.46,"tv":7189.44,"id":8257852}]}]}
{"op":"mcm","clk":"1012496145","pt":1580661696097,"mc":[{"id":"1.168223930","rc":[{"trd":[[1.01,351.07],[1.53,0.59],[1.64,118.34],[1.81,1420.32],[1.83,477.97],[1.84,79.78]],"batb":[[0,1.75,55.45],[1,1.83,0],[2,1.81,0]],"batl":[[1,1.9,0],[2,1.92,0]],"ltp":1.01,"tv":6589.91,"id":8444055},{"trd":[[2.88,0.31],[100,3.23]],"batb":[[0,2.08,50.91],[1,1.94,32.02],[2,1.94,0]],"batl":[[0,2.34,27.85],[1,2.6,671.4]],"ltp":100.0,"tv":7192.98,"id":8257852}],"tv":13782.89}]}
{"op":"mcm","clk":"1012496250","pt":1580661696797,"mc":[{"id":"1.168223930","rc":[{"batl":[[0,2.6,671.4],[1,2.6,0]],"ltp":100.0,"tv":7192.98,"id":8257852}]}]}
{"op":"mcm","clk":"1012496469","pt":1580661698090,"mc":[{"id":"1.168223930","rc":[{"batl":[[0,1.83,3.29],[1,1.88,42.01]],"ltp":1.01,"tv":6589.91,"id":8444055}]}]}
{"op":"mcm","clk":"1012496679","pt":1580661699209,"mc":[{"id":"1.168223930","rc":[{"batb":[[0,1.81,378.23],[1,1.79,370.11]],"batl":[[2,1.89,263.9]],"ltp":1.01,"tv":6589.91,"id":8444055},{"batb":[[0,2.14,36.13],[1,2.08,50.91],[2,1.94,32.02]],"ltp":100.0,"tv":7192.98,"id":8257852}]}]}
{"op":"mcm","clk":"1012496863","pt":1580661700133,"mc":[{"id":"1.168223930","rc":[{"batb":[[2,1.73,57.13]],"ltp":1.01,"tv":6589.91,"id":8444055},{"batb":[[0,2.16,36.13]],"batl":[[0,2.38,30.25],[1,2.6,671.4]],"ltp":100.0,"tv":7192.98,"id":8257852}]}]}
{"op":"mcm","clk":"1012497979","pt":1580661706230,"mc":[{"id":"1.168223930","rc":[{"batb":[[0,1.73,57.13],[1,1.79,0],[2,1.73,0]],"batl":[[2,1.89,0]],"ltp":1.01,"tv":6589.91,"id":8444055},{"batb":[[1,1.94,32.02],[2,1.94,0]],"ltp":100.0,"tv":7192.98,"id":8257852}]}]}
{"op":"mcm","clk":"1012498121","pt":1580661707039,"mc":[{"id":"1.168223930","rc":[{"batl":[[1,1.88,0]],"ltp":1.01,"tv":6589.91,"id":8444055},{"batb":[[0,1.94,32.02],[1,1.94,0]],"batl":[[0,2.6,671.4],[1,2.6,0]],"ltp":100.0,"tv":7192.98,"id":8257852}]}]}
{"op":"mcm","clk":"1012498491","pt":1580661709235,"mc":[{"id":"1.168223930","rc":[{"batb":[[0,1.63,377.28],[1,1.62,261.91],[2,1.6,61.77]],"batl":[[1,2.02,212.03],[2,2.04,251.23]],"ltp":1.01,"tv":6589.91,"id":8444055},{"batb":[[0,1.97,61.61]],"ltp":100.0,"tv":7192.98,"id":8257852}]}]}
{"op":"mcm","clk":"1012499419","pt":1580661714211,"mc":[{"id":"1.168223930","rc":[{"batl":[[1,2.02,0],[2,2.04,0]],"ltp":1.01,"tv":6589.91,"id":8444055}]}]}
{"op":"mcm","clk":"1012499969","pt":1580661717139,"mc":[{"id":"1.168223930","rc":[{"batl":[[0,1.69,811.86],[1,1.71,432.66],[2,1.83,3.29]],"ltp":1.01,"tv":6589.91,"id":8444055}]}]}
{"op":"mcm","clk":"1012500126","pt":1580661718152,"mc":[{"id":"1.168223930","rc":[{"batl":[[1,1.7,42.01],[2,1.71,432.66]],"ltp":1.01,"tv":6589.91,"id":8444055},{"batb":[[0,2.48,31.39],[1,2.16,46.66]],"batl":[[0,2.68,24.37]],"ltp":100.0,"tv":7192.98,"id":8257852}]}]}
{"op":"mcm","clk":"1012500287","pt":1580661719021,"mc":[{"id":"1.168223930","rc":[{"batl":[[0,1.69,279.18]],"ltp":1.01,"tv":6589.91,"id":8444055}]}]}
{"op":"mcm","clk":"1012500483","pt":1580661720236,"mc":[{"id":"1.168223930","rc":[{"batb":[[1,2.44,28.57],[2,2.16,46.66]],"ltp":100.0,"tv":7192.98,"id":8257852}]}]}
{"op":"mcm","clk":"1012500645","pt":1580661721136,"mc":[{"id":"1.168223930","rc":[{"batl":[[1,3,567.72]],"ltp":100.0,"tv":7192.98,"id":8257852}]}]}
{"op":"mcm","clk":"1012500861","pt":1580661722267,"mc":[{"id":"1.168223930","rc":[{"trd":[[1.63,7.38]],"batb":[[0,1.63,373.59]],"ltp":1.63,"tv":6597.29,"id":8444055}],"tv":13790.27}]}
{"op":"mcm","clk":"1012502614","pt":1580661732258,"mc":[{"id":"1.168223930","rc":[{"trd":[[1.68,46.34]],"batb":[[0,1.68,53.66],[1,1.63,373.59],[2,1.62,261.91]],"ltp":1.68,"tv":6643.63,"id":8444055},{"trd":[[2.48,31.39]],"batb":[[0,2.44,28.57],[1,2.16,46.66],[2,2.16,0]],"ltp":2.48,"tv":7224.38,"id":8257852}],"tv":13868.01}]}
{"op":"mcm","clk":"1012503155","pt":1580661735257,"mc":[{"id":"1.168223930","rc":[{"batb":[[1,1.59,70.58],[2,1.37,117.47]],"batl":[[0,1.7,42.01],[1,1.7,0],[2,1.71,0]],"ltp":1.68,"tv":6643.63,"id":8444055}]}]}
{"op":"mcm","clk":"1012503310","pt":1580661736065,"mc":[{"id":"1.168223930","rc":[{"batb":[[0,1.59,70.58],[1,1.37,117.47],[2,1.37,0]],"ltp":1.68,"tv":6643.63,"id":8444055}]}]}
{"op":"mcm","clk":"1012503489","pt":1580661737216,"mc":[{"id":"1.168223930","rc":[{"batb":[[0,1.37,117.47],[1,1.37,0]],"ltp":1.68,"tv":6643.63,"id":8444055},{"batb":[[0,2.16,46.66],[1,2.16,0]],"batl":[[0,3,567.72],[1,3,0]],"ltp":2.48,"tv":7224.38,"id":8257852}]}]}
{"op":"mcm","clk":"1012503649","pt":1580661738204,"mc":[{"id":"1.168223930","rc":[{"batb":[[0,1.38,114.95],[1,1.37,117.47]],"ltp":1.68,"tv":6643.63,"id":8444055},{"batb":[[1,2.14,47.92]],"ltp":2.48,"tv":7224.38,"id":8257852}]}]}
{"op":"mcm","clk":"1012503804","pt":1580661739096,"mc":[{"id":"1.168223930","rc":[{"batb":[[1,1.37,0]],"ltp":1.68,"tv":6643.63,"id":8444055},{"batb":[[0,2.14,47.92],[1,2.14,0]],"ltp":2.48,"tv":7224.38,"id":8257852}]}]}
{"op":"mcm","clk":"1012504005","pt":1580661740230,"mc":[{"id":"1.168223930","rc":[{"batb":[[0,1.58,345.82],[1,1.57,293.73],[2,1.38,114.95]],"batl":[[0,1.64,443.9],[1,1.65,242.06]],"ltp":1.68,"tv":6643.63,"id":8444055}]}]}
{"op":"mcm","clk":"1012504190","pt":1580661741234,"mc":[{"id":"1.168223930","rc":[{"batl":[[2,1.68,1.22]],"ltp":1.68,"tv":6643.63,"id":8444055}]}]}
{"op":"mcm","clk":"1012504542","pt":1580661743245,"mc":[{"id":"1.168223930","rc":[{"batb":[[0,1.38,114.95],[1,1.57,0],[2,1.38,0]],"batl":[[0,1.68,1.22],[1,1.65,0],[2,1.68,0]],"ltp":1.68,"tv":6643.63,"id":8444055}]}]}
{"op":"mcm","clk":"1012505027","pt":1580661746161,"mc":[{"id":"1.168223930","rc":[{"batb":[[0,1.4,483.31],[1,1.39,485.73],[2,1.38,114.95]],"batl":[[0,1.88,324.76],[1,1.9,309.82]],"ltp":1.68,"tv":6643.63,"id":8444055}]}]}
{"op":"mcm","clk":"1012509351","pt":1580661770127,"mc":[{"id":"1.168223930","rc":[{"batb":[[0,1.38,114.95],[1,1.39,0],[2,1.38,0]],"ltp":1.68,"tv":6643.63,"id":8444055}]}]}
{"op":"mcm","clk":"1012509911","pt":1580661773248,"mc":[{"id":"1.168223930","rc":[{"batb":[[0,1.8,334.14],[1,1.78,376.89],[2,1.73,729.7]],"ltp":1.68,"tv":6643.63,"id":8444055}]}]}
{"op":"mcm","clk":"1012510091","pt":1580661774215,"mc":[{"id":"1.168223930","rc":[{"batb":[[0,1.81,42.25],[1,1.8,334.14],[2,1.78,376.89]],"ltp":1.68,"tv":6643.63,"id":8444055},{"batb":[[1,1.94,31.87]],"ltp":2.48,"tv":7224.38,"id":8257852}]}]}
{"op":"mcm","clk":"1012510444","pt":1580661776241,"mc":[{"id":"1.168223930","rc":[{"batl":[[0,1.85,42.01],[1,1.88,324.76],[2,1.9,309.82]],"ltp":1.68,"tv":6643.63,"id":8444055},{"batb":[[0,2.18,35.29],[1,2.14,47.92],[2,1.94,31.87]],"batl":[[0,2.4,29.41],[1,2.6,671.4]],"ltp":2.48,"tv":7224.38,"id":8257852}]}]}
{"op":"mcm","clk":"1012510620","pt":1580661777161,"mc":[{"id":"1.168223930","rc":[{"batl":[[2,2.98,421.23]],"ltp":2.48,"tv":7224.38,"id":8257852}]}]}
{"op":"mcm","clk":"1012512852","pt":1580661789240,"mc":[{"id":"1.168223930","rc":[{"trd":[[1.81,1422.76]],"batb":[[0,1.81,41.03]],"ltp":1.81,"tv":6646.06,"id":8444055}],"tv":13870.44}]}
{"op":"mcm","clk":"1012514118","pt":1580661796178,"mc":[{"id":"1.168223930","rc":[{"batb":[[0,1.72,57.97],[1,1.57,67.51],[2,1.78,0]],"batl":[[1,1.88,0],[2,1.9,0]],"ltp":1.81,"tv":6646.06,"id":8444055},{"batb":[[1,1.94,31.87],[2,1.94,0]],"batl":[[2,2.98,0]],"ltp":2.48,"tv":7224.38,"id":8257852}]}]}
{"op":"mcm","clk":"1012514293","pt":1580661797097,"mc":[{"id":"1.168223930","rc":[{"batb":[[0,1.57,67.51],[1,1.57,0]],"ltp":1.81,"tv":6646.06,"id":8444055},{"batb":[[0,1.94,31.87],[1,1.94,0]],"batl":[[0,2.6,671.4],[1,2.6,0]],"ltp":2.48,"tv":7224.38,"id":8257852}]}]}
{"op":"mcm","clk":"1012514690","pt":1580661799258,"mc":[{"id":"1.168223930","rc":[{"batb":[[0,1.58,66.56]],"ltp":1.81,"tv":6646.06,"id":8444055}]}]}
{"op":"mcm","clk":"1012515210","pt":1580661802164,"mc":[{"id":"1.168223930","rc":[{"batb":[[0,1.75,405.69],[1,1.73,414.55],[2,1.58,66.56]],"batl":[[0,1.83,359.62],[1,1.85,336.02]],"ltp":1.81,"tv":6646.06,"id":8444055}]}]}
{"op":"mcm","clk":"1012515807","pt":1580661805365,"mc":[{"id":"1.168223930","rc":[{"batb":[[0,1.58,66.56],[1,1.73,0],[2,1.58,0]],"ltp":1.81,"tv":6646.06,"id":8444055}]}]}
{"op":"mcm","clk":"1012516440","pt":1580661809021,"mc":[{"id":"1.168223930","rc":[{"batb":[[0,1.59,291.71],[1,1.58,353.21]],"batl":[[0,2.04,262.66],[1,2.06,244.3]],"ltp":1.81,"tv":6646.06,"id":8444055}]}]}
{"op":"mcm","clk":"1012518565","pt":1580661822216,"mc":[{"id":"1.168223930","rc":[{"batb":[[2,1.28,165.39]],"batl":[[0,1.65,466.04],[1,1.66,237.06],[2,1.7,532.68]],"ltp":1.81,"tv":6646.06,"id":8444055},{"batb":[[0,2.56,28.8],[1,2.1,50.2],[2,1.94,31.87]],"ltp":2.48,"tv":7224.38,"id":8257852}]}]}
{"op":"mcm","clk":"1012518616","pt":1580661822543,"mc":[{"id":"1.168223930","rc":[{"batb":[[2,1.94,0]],"ltp":2.48,"tv":7224.38,"id":8257852}]}]}
{"op":"mcm","clk":"1012518769","pt":1580661823349,"mc":[{"id":"1.168223930","rc":[{"batb":[[2,1.55,75.62]],"batl":[[0,1.65,508.05]],"ltp":1.81,"tv":6646.06,"id":8444055},{"batb":[[1,2.52,26.89],[2,2.1,50.2]],"batl":[[0,2.8,22.69]],"ltp":2.48,"tv":7224.38,"id":8257852}]}]}
{"op":"mcm","clk":"1012519096","pt":1580661825085,"mc":[{"id":"1.168223930","rc":[{"batl":[[2,1.7,0]],"ltp":1.81,"tv":6646.06,"id":8444055},{"batl":[[1,3.15,534.7]],"ltp":2.48,"tv":7224.38,"id":8257852}]}]}
{"op":"mcm","clk":"1012522658","pt":1580661844250,"mc":[{"id":"1.168223930","rc":[{"batb":[[0,1.58,66.56],[1,1.55,75.62],[2,1.28,165.39]],"batl":[[0,1.65,42.01],[1,1.66,0]],"ltp":1.81,"tv":6646.06,"id":8444055}]}]}
{"op":"mcm","clk":"1012522820","pt":1580661845239,"mc":[{"id":"1.168223930","rc":[{"batb":[[0,1.55,75.62],[1,1.28,164.6],[2,1.28,0]],"ltp":1.81,"tv":6646.06,"id":8444055},{"batb":[[0,2.52,26.89],[1,2.1,50.2],[2,2.1,0]],"ltp":2.48,"tv":7224.38,"id":8257852}]}]}
{"op":"mcm","clk":"1012523140","pt":1580661847244,"mc":[{"id":"1.168223930","rc":[{"batb":[[0,1.3,393.35],[1,1.29,701.65],[2,1.28,164.6]],"batl":[[0,1.9,271.67],[1,1.92,300.42]],"ltp":1.81,"tv":6646.06,"id":8444055},{"batb":[[0,2.1,50.2],[1,2.1,0]],"batl":[[0,3.15,534.7],[1,3.15,0]],"ltp":2.48,"tv":7224.38,"id":8257852}]}]}
{"op":"mcm","clk":"1012523483","pt":1580661849159,"mc":[{"id":"1.168223930","rc":[{"batb":[[0,1.28,164.6],[1,1.29,0],[2,1.28,0]],"ltp":1.81,"tv":6646.06,"id":8444055}]}]}
{"op":"mcm","clk":"1012524059","pt":1580661852155,"mc":[{"id":"1.168223930","rc":[{"batb":[[0,1.52,391.32],[1,1.51,341.55],[2,1.28,164.6]],"batl":[[0,1.57,321.47],[1,1.58,282.75]],"ltp":1.81,"tv":6646.06,"id":8444055}]}]}
{"op":"mcm","clk":"1012524543","pt":1580661855057,"mc":[{"id":"1.168223930","rc":[{"batb":[[0,1.28,164.6],[1,1.51,0],[2,1.28,0]],"ltp":1.81,"tv":6646.06,"id":8444055}]}]}
{"op":"mcm","clk":"1012525048","pt":1580661857861,"mc":[{"id":"1.168223930","rc":[{"batb":[[0,1.3,405.07],[1,1.29,701.71],[2,1.28,164.6]],"batl":[[0,1.9,263.47],[1,1.92,300.4]],"ltp":1.81,"tv":6646.06,"id":8444055}]}]}
{"op":"mcm","clk":"1012525568","pt":1580661860687,"mc":[{"id":"1.168223930","rc":[{"batb":[[0,1.28,164.6],[1,1.29,0],[2,1.28,0]],"ltp":1.81,"tv":6646.06,"id":8444055}]}]}
{"op":"mcm","clk":"1012525999","pt":1580661863183,"mc":[{"id":"1.168223930","rc":[{"batb":[[0,1.82,360.16],[1,1.8,363.58],[2,1.72,739.83]],"ltp":1.81,"tv":6646.06,"id":8444055}]}]}
{"op":"mcm","clk":"1012526178","pt":1580661864158,"mc":[{"id":"1.168223930","rc":[{"batb":[[0,1.84,40.21],[1,1.82,360.16],[2,1.8,363.58]],"ltp":1.81,"tv":6646.06,"id":8444055},{"batb":[[1,1.9,33.99]],"ltp":2.48,"tv":7224.38,"id":8257852}]}]}
{"op":"mcm","clk":"1012526361","pt":1580661865179,"mc":[{"id":"1.168223930","rc":[{"batl":[[0,2.72,636.58]],"ltp":2.48,"tv":7224.38,"id":8257852}]}]}
{"op":"mcm","clk":"1012526535","pt":1580661866163,"mc":[{"id":"1.168223930","rc":[{"batl":[[0,1.87,42.01],[1,1.9,263.47],[2,1.92,300.4]],"ltp":1.81,"tv":6646.06,"id":8444055},{"batb":[[0,2.14,36.13],[1,2.1,50.2],[2,1.9,33.99]],"batl":[[0,2.36,30.25],[1,2.72,636.58]],"ltp":2.48,"tv":7224.38,"id":8257852}]}]}
{"op":"mcm","clk":"1012527900","pt":1580661874189,"mc":[{"id":"1.168223930","rc":[{"batl":[[0,2.72,636.58],[1,2.72,0]],"ltp":2.48,"tv":7224.38,"id":8257852}]}]}
{"op":"mcm","clk":"1012528386","pt":1580661877167,"mc":[{"id":"1.168223930","rc":[{"batl":[[0,2.34,31.09],[1,2.72,636.58]],"ltp":2.48,"tv":7224.38,"id":8257852}]}]}
{"op":"mcm","clk":"1012528542","pt":1580661878186,"mc":[{"id":"1.168223930","rc":[{"batb":[[0,1.74,56.29],[1,1.57,68.3],[2,1.8,0]],"batl":[[1,1.9,0],[2,1.92,0]],"ltp":1.81,"tv":6646.06,"id":8444055},{"batb":[[1,1.9,33.99],[2,1.9,0]],"ltp":2.48,"tv":7224.38,"id":8257852}]}]}
{"op":"mcm","clk":"1012528711","pt":1580661879175,"mc":[{"id":"1.168223930","rc":[{"batb":[[0,1.57,68.3],[1,1.57,0]],"ltp":1.81,"tv":6646.06,"id":8444055},{"batb":[[0,1.9,33.99],[1,1.9,0]],"batl":[[0,2.72,636.58],[1,2.72,0]],"ltp":2.48,"tv":7224.38,"id":8257852}]}]}
{"op":"mcm","clk":"1012528898","pt":1580661880271,"mc":[{"id":"1.168223930","rc":[{"batb":[[0,1.58,309.61],[1,1.57,361.94]],"batl":[[0,2.1,323.01],[1,2.12,225.21]],"ltp":1.81,"tv":6646.06,"id":8444055}]}]}
{"op":"mcm","clk":"1012529057","pt":1580661881192,"mc":[{"id":"1.168223930","rc":[{"batb":[[0,1.57,68.3],[1,1.57,0]],"ltp":1.81,"tv":6646.06,"id":8444055}]}]}
{"op":"mcm","clk":"1012529399","pt":1580661883185,"mc":[{"id":"1.168223930","rc":[{"batb":[[0,1.77,284.88],[1,1.75,398.49],[2,1.57,68.3]],"batl":[[0,1.84,265.07],[1,1.86,330.87]],"ltp":1.81,"tv":6646.06,"id":8444055}]}]}
{"op":"mcm","clk":"1012529882","pt":1580661886197,"mc":[{"id":"1.168223930","rc":[{"batb":[[0,1.57,68.3],[1,1.75,0],[2,1.57,0]],"ltp":1.81,"tv":6646.06,"id":8444055}]}]}
{"op":"mcm","clk":"1012530344","pt":1580661889105,"mc":[{"id":"1.168223930","rc":[{"batb":[[0,1.58,339.23],[1,1.57,361.98]],"batl":[[0,2.1,300.24],[1,2.12,225.18]],"ltp":1.81,"tv":6646.06,"id":8444055}]}]}
{"op":"mcm","clk":"1012531821","pt":1580661898229,"mc":[{"id":"1.168223930","rc":[{"batb":[[0,1.57,68.3],[1,1.57,0]],"ltp":1.81,"tv":6646.06,"id":8444055}]}]}
{"op":"mcm","clk":"1012532134","pt":1580661900224,"mc":[{"id":"1.168223930","rc":[{"batb":[[0,1.95,560.71],[1,1.57,68.3]],"ltp":1.81,"tv":6646.06,"id":8444055}]}]}
{"op":"mcm","clk":"1012532296","pt":1580661901115,"mc":[{"id":"1.168223930","rc":[{"batb":[[0,2,60.11],[1,1.95,560.71],[2,1.86,39.03]],"ltp":1.81,"tv":6646.06,"id":8444055},{"batb":[[0,1.91,316.24],[1,1.9,33.99],[2,1.89,311.56]],"batl":[[0,2,297.1],[1,2.02,259.31]],"ltp":2.48,"tv":7224.38,"id":8257852}]}]}
{"op":"mcm","clk":"1012532457","pt":1580661902128,"mc":[{"id":"1.168223930","rc":[{"batl":[[0,2.04,40.33]],"ltp":1.81,"tv":6646.06,"id":8444055},{"batb":[[0,1.96,43.69],[1,1.91,316.24],[2,1.9,33.99]],"ltp":2.48,"tv":7224.38,"id":8257852}]}]}
{"op":"mcm","clk":"1012532847","pt":1580661904204,"mc":[{"id":"1.168223930","rc":[{"batb":[[1,1.88,47.05]],"ltp":1.81,"tv":6646.06,"id":8444055},{"batl":[[2,2.5,706.25]],"ltp":2.48,"tv":7224.38,"id":8257852}]}]}
{"op":"mcm","clk":"1012532998","pt":1580661905105,"mc":[{"id":"1.168223930","rc":[{"batb":[[1,1.89,47.05]],"ltp":1.81,"tv":6646.06,"id":8444055},{"batl":[[2,2.12,36.97]],"ltp":2.48,"tv":7224.38,"id":8257852}]}]}
{"op":"mcm","clk":"1012534640","pt":1580661915193,"mc":[{"id":"1.168223930","rc":[{"batb":[[1,1.86,39.03],[2,1.86,0]],"ltp":1.81,"tv":6646.06,"id":8444055},{"batb":[[0,1.91,316.24],[1,1.9,33.99],[2,1.89,311.56]],"batl":[[2,2.5,706.25]],"ltp":2.48,"tv":7224.38,"id":8257852}]}]}
{"op":"mcm","clk":"1012535132","pt":1580661918201,"mc":[{"id":"1.168223930","rc":[{"batb":[[1,1.9,46.21],[2,1.86,39.03]],"batl":[[0,2.08,38.65]],"ltp":1.81,"tv":6646.06,"id":8444055},{"batb":[[0,1.93,44.53],[1,1.91,316.24],[2,1.9,33.99]],"batl":[[2,2.1,37.81]],"ltp":2.48,"tv":7224.38,"id":8257852}]}]}
{"op":"mcm","clk":"1012537723","pt":1580661933198,"mc":[{"id":"1.168223930","rc":[{"batb":[[0,1.9,46.21],[1,1.86,39.03],[2,1.86,0]],"ltp":1.81,"tv":6646.06,"id":8444055},{"batb":[[1,1.64,55.31],[2,1.9,0]],"batl":[[0,2.1,37.81],[1,2.5,706.25],[2,2.1,0]],"ltp":2.48,"tv":7224.38,"id":8257852}]}]}
{"op":"mcm","clk":"1012538042","pt":1580661934925,"mc":[{"id":"1.168223930","rc":[{"batb":[[0,1.86,39.03],[1,1.86,0]],"ltp":1.81,"tv":6646.06,"id":8444055},{"batb":[[0,1.64,55.31],[1,1.64,0]],"batl":[[0,2.5,706.25],[1,2.5,0]],"ltp":2.48,"tv":7224.38,"id":8257852}]}]}
{"op":"mcm","clk":"1012538230","pt":1580661936203,"mc":[{"id":"1.168223930","rc":[{"batb":[[0,1.67,255.71],[1,1.66,243.41],[2,1.65,54.84]],"batl":[[0,2.18,248.92],[1,2.2,202.21],[2,2.5,706.25]],"ltp":2.48,"tv":7224.38,"id":8257852}]}]}
{"op":"mcm","clk":"1012538400","pt":1580661937211,"mc":[{"id":"1.168223930","rc":[{"batl":[[0,2.5,706.25],[1,2.2,0],[2,2.5,0]],"ltp":2.48,"tv":7224.38,"id":8257852}]}]}
{"op":"mcm","clk":"1012538896","pt":1580661940198,"mc":[{"id":"1.168223930","rc":[{"batl":[[0,1.73,323.74],[1,1.75,407.71],[2,1.8,532.68]],"ltp":2.48,"tv":7224.38,"id":8257852}]}]}
{"op":"mcm","clk":"1012539078","pt":1580661941100,"mc":[{"id":"1.168223930","rc":[{"batb":[[0,2.42,35.96],[1,2.1,53.5]],"ltp":1.81,"tv":6646.06,"id":8444055}]}]}
{"op":"mcm","clk":"1012539249","pt":1580661942111,"mc":[{"id":"1.168223930","rc":[{"trd":[[2.42,58.82]],"batb":[[0,2.42,6.55]],"ltp":2.42,"tv":6704.88,"id":8444055},{"batb":[[0,1.7,59.65],[1,1.67,255.71],[2,1.66,243.41]],"ltp":2.48,"tv":7224.38,"id":8257852}],"tv":13929.26}]}
{"op":"mcm","clk":"1012539429","pt":1580661943235,"mc":[{"id":"1.168223930","rc":[{"batl":[[2,2.16,849.68]],"ltp":2.48,"tv":7224.38,"id":8257852}]}]}
{"op":"mcm","clk":"1012539585","pt":1580661944138,"mc":[{"id":"1.168223930","rc":[{"batl":[[0,2.44,28.57]],"ltp":2.42,"tv":6704.88,"id":8444055},{"batl":[[2,1.83,42.01]],"ltp":2.48,"tv":7224.38,"id":8257852}]}]}
{"op":"mcm","clk":"1012539767","pt":1580661945210,"mc":[{"id":"1.168223930","rc":[{"trd":[[2.42,71.91]],"batb":[[0,2.22,33.61]],"ltp":2.42,"tv":6717.97,"id":8444055}],"tv":13942.35}]}
{"op":"mcm","clk":"1012539895","pt":1580661946013,"mc":[{"id":"1.168223930","rc":[{"batl":[[2,2.16,849.68]],"ltp":2.48,"tv":7224.38,"id":8257852}]}]}
{"op":"mcm","clk":"1012540248","pt":1580661948204,"mc":[{"id":"1.168223930","rc":[{"batl":[[2,1.82,42.01]],"ltp":2.48,"tv":7224.38,"id":8257852}]}]}
{"op":"mcm","clk":"1012541270","pt":1580661954149,"mc":[{"id":"1.168223930","rc":[{"batb":[[1,1.39,105.83],[2,1.66,0]],"batl":[[0,1.82,42.01],[1,2.16,849.68],[2,1.82,0]],"ltp":2.48,"tv":7224.38,"id":8257852}]}]}
{"op":"mcm","clk":"1012541445","pt":1580661955127,"mc":[{"id":"1.168223930","rc":[{"batb":[[0,2.1,53.5],[1,2.1,0]],"ltp":2.42,"tv":6717.97,"id":8444055},{"batb":[[0,1.39,105.83],[1,1.39,0]],"batl":[[0,2.16,849.68],[1,2.16,0]],"ltp":2.48,"tv":7224.38,"id":8257852}]}]}
{"op":"mcm","clk":"1012541807","pt":1580661957270,"mc":[{"id":"1.168223930","rc":[{"batb":[[0,2.06,55.31]],"ltp":2.42,"tv":6717.97,"id":8444055},{"batb":[[0,1.41,537.84],[1,1.4,590.03]],"batl":[[0,1.93,216.11],[1,1.95,288.48],[2,2.16,849.68]],"ltp":2.48,"tv":7224.38,"id":8257852}]}]}
{"op":"mcm","clk":"1012541946","pt":1580661958187,"mc":[{"id":"1.168223930","rc":[{"batl":[[0,2.16,849.68],[1,1.95,0],[2,2.16,0]],"ltp":2.48,"tv":7224.38,"id":8257852}]}]}
{"op":"mcm","clk":"1012542497","pt":1580661961248,"mc":[{"id":"1.168223930","rc":[{"batb":[[0,3.15,42.41],[1,2.6,28.95],[2,2.06,55.31]],"ltp":2.42,"tv":6717.97,"id":8444055},{"batb":[[2,1.2,239.27]],"batl":[[0,1.45,314.47],[1,1.46,397.21],[2,1.6,532.68]],"ltp":2.48,"tv":7224.38,"id":8257852}]}]}
{"op":"mcm","clk":"1012542653","pt":1580661962253,"mc":[{"id":"1.168223930","rc":[{"batb":[[1,2.9,21.85],[2,2.6,28.95]],"batl":[[0,3.3,17.64]],"ltp":2.42,"tv":6717.97,"id":8444055},{"batb":[[0,1.44,94.94],[1,1.41,537.84],[2,1.4,590.03]],"batl":[[2,1.52,42.01]],"ltp":2.48,"tv":7224.38,"id":8257852}]}]}
{"op":"mcm","clk":"1012542819","pt":1580661963217,"mc":[{"id":"1.168223930","rc":[{"batb":[[1,2.6,28.95],[2,2.6,0]],"ltp":2.42,"tv":6717.97,"id":8444055},{"batb":[[0,1.41,537.84],[1,1.4,590.03],[2,1.2,239.27]],"ltp":2.48,"tv":7224.38,"id":8257852}]}]}
{"op":"mcm","clk":"1012543305","pt":1580661966168,"mc":[{"id":"1.168223930","rc":[{"batb":[[1,2.94,21],[2,2.6,28.95]],"ltp":2.42,"tv":6717.97,"id":8444055},{"batb":[[0,1.43,97.46],[1,1.41,537.84],[2,1.4,590.03]],"ltp":2.48,"tv":7224.38,"id":8257852}]}]}
{"op":"mcm","clk":"1012545266","pt":1580661978201,"mc":[{"id":"1.168223930","rc":[{"trd":[[3.3,28.32]],"batl":[[0,3.3,3.49]],"ltp":3.3,"tv":6746.29,"id":8444055}],"tv":13970.67}]}
{"op":"mcm","clk":"1012545420","pt":1580661978960,"mc":[{"id":"1.168223930","rc":[{"batl":[[2,1.77,1138.51]],"ltp":2.48,"tv":7224.38,"id":8257852}]}]}
{"op":"mcm","clk":"1012545792","pt":1580661981204,"mc":[{"id":"1.168223930","rc":[{"batb":[[1,1.4,102.92],[2,1.2,239.27]],"batl":[[0,1.77,1138.51],[1,1.46,0],[2,1.77,0]],"ltp":2.48,"tv":7224.38,"id":8257852}]}]}
{"op":"mcm","clk":"1012545962","pt":1580661982270,"mc":[{"id":"1.168223930","rc":[{"batb":[[0,2.94,21],[1,2.6,28.95],[2,2.6,0]],"batl":[[0,3.3,16.93]],"ltp":3.3,"tv":6746.29,"id":8444055},{"batb":[[1,1.2,239.27],[2,1.2,0]],"batl":[[0,1.51,42.01],[1,1.77,1138.51]],"ltp":2.48,"tv":7224.38,"id":8257852}]}]}
{"op":"mcm","clk":"1012546111","pt":1580661983186,"mc":[{"id":"1.168223930","rc":[{"batb":[[0,2.6,28.95],[1,2.6,0]],"ltp":3.3,"tv":6746.29,"id":8444055},{"batb":[[0,1.2,239.27],[1,1.2,0]],"batl":[[0,1.77,1138.51],[1,1.77,0]],"ltp":2.48,"tv":7224.38,"id":8257852}]}]}
{"op":"mcm","clk":"1012546314","pt":1580661984219,"mc":[{"id":"1.168223930","rc":[{"batb":[[0,1.2,1274.17],[1,1.19,1135.07]],"batl":[[0,1.63,496.37],[1,1.64,253.07]],"ltp":2.48,"tv":7224.38,"id":8257852}]}]}
{"op":"mcm","clk":"1012546498","pt":1580661985181,"mc":[{"id":"1.168223930","rc":[{"batb":[[0,2.58,29.19]],"ltp":3.3,"tv":6746.29,"id":8444055},{"batb":[[0,1.2,1272.68]],"ltp":2.48,"tv":7224.38,"id":8257852}]}]}
{"op":"mcm","clk":"1012547128","pt":1580661989102,"mc":[{"id":"1.168223930","rc":[{"batb":[[0,1.2,237.78],[1,1.19,0]],"ltp":2.48,"tv":7224.38,"id":8257852}]}]}
{"op":"mcm","clk":"1012547618","pt":1580661992118,"mc":[{"id":"1.168223930","rc":[{"batb":[[1,2.12,50.51]],"ltp":3.3,"tv":6746.29,"id":8444055},{"batb":[[0,1.57,426.67],[1,1.56,307.53],[2,1.5,1065.37]],"ltp":2.48,"tv":7224.38,"id":8257852}]}]}
{"op":"mcm","clk":"1012547899","pt":1580661993852,"mc":[{"id":"1.168223930","rc":[{"batb":[[0,1.58,72.26],[1,1.57,426.67],[2,1.56,307.53]],"batl":[[2,1.68,42.01]],"ltp":2.48,"tv":7224.38,"id":8257852}]}]}
{"op":"mcm","clk":"1012548168","pt":1580661995237,"mc":[{"id":"1.168223930","rc":[{"batb":[[1,2.46,28.57],[2,2.12,50.51]],"batl":[[0,2.72,24.37]],"ltp":3.3,"tv":6746.29,"id":8444055}]}]}
{"op":"mcm","clk":"1012550341","pt":1580662009073,"mc":[{"id":"1.168223930","rc":[{"batb":[[0,2.46,28.57],[1,2.12,50.28],[2,2.12,0]],"ltp":3.3,"tv":6746.29,"id":8444055},{"batb":[[1,1.28,158.23],[2,1.56,0]],"batl":[[0,1.68,42.01],[1,2.04,929.31],[2,1.68,0]],"ltp":2.48,"tv":7224.38,"id":8257852}]}]}
{"op":"mcm","clk":"1012550687","pt":1580662011163,"mc":[{"id":"1.168223930","rc":[{"batb":[[0,2.12,50.28],[1,2.12,0]],"ltp":3.3,"tv":6746.29,"id":8444055},{"batb":[[0,1.28,158.23],[1,1.28,0]],"ltp":2.48,"tv":7224.38,"id":8257852}]}]}
{"op":"mcm","clk":"1012550873","pt":1580662012249,"mc":[{"id":"1.168223930","rc":[{"batl":[[0,1.87,259.66],[1,1.89,317.82]],"ltp":2.48,"tv":7224.38,"id":8257852}]}]}
{"op":"mcm","clk":"1012551153","pt":1580662014245,"mc":[{"id":"1.168223930","rc":[{"batb":[[0,1.8,246],[1,1.78,379.3],[2,1.7,760.97]],"ltp":2.48,"tv":7224.38,"id":8257852}]}]}
{"op":"mcm","clk":"1012551322","pt":1580662015248,"mc":[{"id":"1.168223930","rc":[{"batb":[[1,1.82,40.68]],"ltp":3.3,"tv":6746.29,"id":8444055},{"batb":[[0,1.8,286.36]],"ltp":2.48,"tv":7224.38,"id":8257852}]}]}
{"op":"mcm","clk":"1012551458","pt":1580662016071,"mc":[{"id":"1.168223930","rc":[{"batb":[[1,2.08,38.65],[2,1.82,40.68]],"batl":[[0,2.26,32.77]],"ltp":3.3,"tv":6746.29,"id":8444055},{"batb":[[1,1.79,52.93],[2,1.78,379.3]],"batl":[[2,1.93,42.01]],"ltp":2.48,"tv":7224.38,"id":8257852}]}]}
{"op":"mcm","clk":"1012553555","pt":1580662030241,"mc":[{"id":"1.168223930","rc":[{"batb":[[0,1.8,40.36],[2,1.44,91.59]],"batl":[[0,1.93,42.01],[1,2.36,758.65],[2,1.93,0]],"ltp":2.48,"tv":7224.38,"id":8257852}]}]}
{"op":"mcm","clk":"1012553702","pt":1580662031261,"mc":[{"id":"1.168223930","rc":[{"batb":[[0,1.82,40.68],[1,2.08,0],[2,1.82,0]],"ltp":3.3,"tv":6746.29,"id":8444055},{"batb":[[0,1.44,91.59],[1,1.79,0],[2,1.44,0]],"batl":[[0,2.36,758.65],[1,2.36,0]],"ltp":2.48,"tv":7224.38,"id":8257852}]}]}
{"op":"mcm","clk":"1012554273","pt":1580662035246,"mc":[{"id":"1.168223930","rc":[{"batb":[[0,1.71,350.03],[1,1.69,453.97],[2,1.44,91.59]],"batl":[[0,1.78,340.39],[1,1.8,371.39]],"ltp":2.48,"tv":7224.38,"id":8257852}]}]}
{"op":"mcm","clk":"1012554855","pt":1580662039247,"mc":[{"id":"1.168223930","rc":[{"batb":[[0,1.44,91.59],[1,1.69,0],[2,1.44,0]],"batl":[[0,2.22,826.13],[1,1.8,0]],"ltp":2.48,"tv":7224.38,"id":8257852}]}]}
{"op":"mcm","clk":"1012555280","pt":1580662042272,"mc":[{"id":"1.168223930","rc":[{"batb":[[0,1.44,560.08],[1,1.43,441.95]],"batl":[[0,2.2,351.91],[1,2.22,197.17]],"ltp":2.48,"tv":7224.38,"id":8257852}]}]}
{"op":"mcm","clk":"1012555885","pt":1580662046268,"mc":[{"id":"1.168223930","rc":[{"batl":[[0,1.49,615.47],[1,1.5,353.6],[2,1.59,532.68]],"ltp":2.48,"tv":7224.38,"id":8257852}]}]}
{"op":"mcm","clk":"1012556024","pt":1580662047177,"mc":[{"id":"1.168223930","rc":[{"batb":[[0,3,49.25],[1,2.14,48.63]],"ltp":3.3,"tv":6746.29,"id":8444055},{"batb":[[2,1.09,542.12]],"ltp":2.48,"tv":7224.38,"id":8257852}]}]}
{"op":"mcm","clk":"1012556164","pt":1580662048166,"mc":[{"id":"1.168223930","rc":[{"batb":[[1,2.84,22.69],[2,2.14,48.63]],"batl":[[0,3.2,18.48]],"ltp":3.3,"tv":6746.29,"id":8444055},{"batb":[[0,1.45,93.26],[1,1.44,560.08],[2,1.43,441.95]],"batl":[[2,1.54,42.01]],"ltp":2.48,"tv":7224.38,"id":8257852}]}]}
{"op":"mcm","clk":"1012558794","pt":1580662065188,"mc":[{"id":"1.168223930","rc":[{"batb":[[0,2.84,22.69],[1,2.14,48.63],[2,2.14,0]],"ltp":3.3,"tv":6746.29,"id":8444055},{"batb":[[1,1.09,542.12],[2,1.43,0]],"batl":[[0,1.54,42.01],[1,1.82,1087.58],[2,1.54,0]],"ltp":2.48,"tv":7224.38,"id":8257852}]}]}
{"op":"mcm","clk":"1012559085","pt":1580662067179,"mc":[{"id":"1.168223930","rc":[{"batb":[[0,2.14,48.63],[1,2.14,0]],"ltp":3.3,"tv":6746.29,"id":8444055},{"batb":[[0,1.09,542.12],[1,1.08,2400.58]],"batl":[[0,1.86,300.17],[1,1.88,322.92]],"ltp":2.48,"tv":7224.38,"id":8257852}]}]}
{"op":"mcm","clk":"1012559554","pt":1580662070225,"mc":[{"id":"1.168223930","rc":[{"batb":[[1,1.08,0]],"ltp":2.48,"tv":7224.38,"id":8257852}]}]}
{"op":"mcm","clk":"1012559869","pt":1580662072221,"mc":[{"id":"1.168223930","rc":[{"batb":[[0,1.79,221.15],[1,1.77,386.29],[2,1.64,832.31]],"ltp":2.48,"tv":7224.38,"id":8257852}]}]}
{"op":"mcm","clk":"1012560001","pt":1580662073195,"mc":[{"id":"1.168223930","rc":[{"batb":[[1,1.84,39.26]],"ltp":3.3,"tv":6746.29,"id":8444055},{"batb":[[1,1.78,41.7],[2,1.77,386.29]],"ltp":2.48,"tv":7224.38,"id":8257852}]}]}
{"op":"mcm","clk":"1012560091","pt":1580662073682,"mc":[{"id":"1.168223930","rc":[{"batl":[[0,2.28,32.77]],"ltp":3.3,"tv":6746.29,"id":8444055},{"batb":[[1,1.78,95.47]],"ltp":2.48,"tv":7224.38,"id":8257852}]}]}
{"op":"mcm","clk":"1012560293","pt":1580662075120,"mc":[{"id":"1.168223930","rc":[{"batl":[[2,2.3,782.84]],"ltp":2.48,"tv":7224.38,"id":8257852}]}]}
{"op":"mcm","clk":"1012560337","pt":1580662075388,"mc":[{"id":"1.168223930","rc":[{"batb":[[1,2.08,38.65],[2,1.84,39.26]],"ltp":3.3,"tv":6746.29,"id":8444055},{"batl":[[2,1.92,42.01]],"ltp":2.48,"tv":7224.38,"id":8257852}]}]}
{"op":"mcm","clk":"1012562502","pt":1580662089225,"mc":[{"id":"1.168223930","rc":[{"batb":[[0,2.08,38.65],[1,1.84,39.26],[2,1.84,0]],"ltp":3.3,"tv":6746.29,"id":8444055},{"batb":[[0,1.78,53.77],[1,1.43,95.13],[2,1.77,0]],"batl":[[0,1.92,42.01],[1,2.3,782.84],[2,1.92,0]],"ltp":2.48,"tv":7224.38,"id":8257852}]}]}
{"op":"mcm","clk":"1012562852","pt":1580662091238,"mc":[{"id":"1.168223930","rc":[{"batb":[[0,1.84,39.26],[1,1.84,0]],"ltp":3.3,"tv":6746.29,"id":8444055},{"batb":[[0,1.43,95.13],[1,1.43,0]],"batl":[[0,2.3,782.84],[1,2.3,0]],"ltp":2.48,"tv":7224.38,"id":8257852}]}]}
{"op":"mcm","clk":"1012563001","pt":1580662092230,"mc":[{"id":"1.168223930","rc":[{"batb":[[0,1.43,719.47],[1,1.42,456.91]],"batl":[[0,2.18,289.18],[1,2.2,202.07],[2,2.3,782.84]],"ltp":2.48,"tv":7224.38,"id":8257852}]}]}
{"op":"mcm","clk":"1012563321","pt":1580662094233,"mc":[{"id":"1.168223930","rc":[{"batl":[[0,2.3,782.84],[1,2.2,0],[2,2.3,0]],"ltp":2.48,"tv":7224.38,"id":8257852}]}]}
{"op":"mcm","clk":"1012563792","pt":1580662097260,"mc":[{"id":"1.168223930","rc":[{"trd":[[3.05,2.27]],"ltp":3.05,"tv":6748.56,"id":8444055},{"trd":[[1.48,4.68]],"batl":[[0,1.48,514.38],[1,1.49,363.55],[2,1.58,532.68]],"ltp":1.48,"tv":7229.06,"id":8257852}],"tv":13977.62}]}
{"op":"mcm","clk":"1012563847","pt":1580662097636,"mc":[{"id":"1.168223930","rc":[{"batb":[[0,3.05,46.89],[1,2.86,21.85],[2,2.18,46.89]],"batl":[[0,3.25,18.48]],"ltp":3.05,"tv":6748.56,"id":8444055},{"batb":[[0,1.45,93.26],[1,1.43,719.47],[2,1.42,456.91]],"batl":[[2,1.54,42.01]],"ltp":1.48,"tv":7229.06,"id":8257852}]}]}
{"op":"mcm","clk":"1012565030","pt":1580662105137,"mc":[{"id":"1.168223930","rc":[{"trd":[[1.48,104.68]],"batl":[[0,1.48,464.38]],"ltp":1.48,"tv":7329.06,"id":8257852}],"tv":14077.62}]}
{"op":"mcm","clk":"1012565680","pt":1580662109174,"mc":[{"id":"1.168223930","rc":[{"batb":[[1,2.18,46.89],[2,2.18,0]],"ltp":3.05,"tv":6748.56,"id":8444055},{"batl":[[2,1.82,1080.26]],"ltp":1.48,"tv":7329.06,"id":8257852}]}]}
{"op":"mcm","clk":"1012566036","pt":1580662111187,"mc":[{"id":"1.168223930","rc":[{"batb":[[1,2.88,21.85],[2,2.18,46.89]],"ltp":3.05,"tv":6748.56,"id":8444055},{"batl":[[2,1.53,42.01]],"ltp":1.48,"tv":7329.06,"id":8257852}]}]}
{"op":"mcm","clk":"1012567334","pt":1580662119096,"mc":[{"id":"1.168223930","rc":[{"batb":[[0,2.88,21.85],[1,2.18,46.34],[2,2.18,0]],"ltp":3.05,"tv":6748.56,"id":8444055},{"batb":[[1,1.09,547.39],[2,1.42,0]],"batl":[[0,1.53,42.01],[1,1.82,1080.26],[2,3,4.66]],"ltp":1.48,"tv":7329.06,"id":8257852}]}]}
{"op":"mcm","clk":"1012567640","pt":1580662120900,"mc":[{"id":"1.168223930","rc":[{"batb":[[0,2.18,46.34],[1,2.18,0]],"ltp":3.05,"tv":6748.56,"id":8444055},{"batb":[[0,1.09,547.39],[1,1.09,0]],"batl":[[0,1.82,1080.26],[1,3,4.66],[2,3,0]],"ltp":1.48,"tv":7329.06,"id":8257852}]}]}
{"op":"mcm","clk":"1012567856","pt":1580662122182,"mc":[{"id":"1.168223930","rc":[{"batb":[[1,1.08,2400.58]],"batl":[[0,1.85,347.93],[1,1.87,328.19],[2,3,4.66]],"ltp":1.48,"tv":7329.06,"id":8257852}]}]}
{"op":"mcm","clk":"1012568439","pt":1580662126182,"mc":[{"id":"1.168223930","rc":[{"batb":[[1,1.08,0]],"ltp":1.48,"tv":7329.06,"id":8257852}]}]}
{"op":"mcm","clk":"1012568885","pt":1580662128993,"mc":[{"id":"1.168223930","rc":[{"batb":[[0,1.77,384.83],[1,1.75,401.63],[2,1.59,902.85]],"ltp":1.48,"tv":7329.06,"id":8257852}]}]}
{"op":"mcm","clk":"1012569020","pt":1580662129899,"mc":[{"id":"1.168223930","rc":[{"batb":[[1,2.1,37.81],[2,1.86,37.53]],"batl":[[0,2.3,31.93]],"ltp":3.05,"tv":6748.56,"id":8444055},{"batb":[[0,1.77,438.6],[1,1.76,43.59],[2,1.75,401.63]],"batl":[[2,1.9,42.01]],"ltp":1.48,"tv":7329.06,"id":8257852}]}]}
{"op":"mcm","clk":"1012571225","pt":1580662145210,"mc":[{"id":"1.168223930","rc":[{"batb":[[0,2.1,37.81],[1,1.86,37.53],[2,1.86,0]],"ltp":3.05,"tv":6748.56,"id":8444055},{"batb":[[0,1.77,53.77],[1,1.41,99.77],[2,1.75,0]],"batl":[[0,1.9,42.01],[1,2.3,776.41],[2,3,4.66]],"ltp":1.48,"tv":7329.06,"id":8257852}]}]}
{"op":"mcm","clk":"1012571505","pt":1580662147225,"mc":[{"id":"1.168223930","rc":[{"batb":[[0,1.86,37.53],[1,1.86,0]],"ltp":3.05,"tv":6748.56,"id":8444055},{"batb":[[0,1.41,99.77],[1,1.41,0]],"batl":[[0,2.3,776.41],[1,3,4.66],[2,3,0]],"ltp":1.48,"tv":7329.06,"id":8257852}]}]}
{"op":"mcm","clk":"1012571650","pt":1580662148245,"mc":[{"id":"1.168223930","rc":[{"batb":[[0,1.43,326.48],[1,1.42,454.24],[2,1.41,99.77]],"batl":[[0,2.16,230.68],[1,2.18,207.2],[2,2.3,776.41]],"ltp":1.48,"tv":7329.06,"id":8257852}]}]}
{"op":"mcm","clk":"1012572062","pt":1580662150903,"mc":[{"id":"1.168223930","rc":[{"batl":[[0,1.77,3],[1,2.16,230.68],[2,2.18,207.2]],"ltp":1.48,"tv":7329.06,"id":8257852}]}]}
{"op":"mcm","clk":"1012572247","pt":1580662152220,"mc":[{"id":"1.168223930","rc":[{"batl":[[0,2.16,230.68],[1,2.18,207.2],[2,2.3,776.41]],"ltp":1.48,"tv":7329.06,"id":8257852}]}]}
{"op":"mcm","clk":"1012574276","pt":1580662167243,"mc":[{"id":"1.168223930","rc":[{"batb":[[0,1.41,99.77],[1,1.42,0],[2,1.41,0]],"batl":[[0,2.3,776.41],[1,3,4.66],[2,2.3,0]],"ltp":1.48,"tv":7329.06,"id":8257852}]}]}
{"op":"mcm","clk":"1012574407","pt":1580662168246,"mc":[{"id":"1.168223930","rc":[{"batl":[[0,3,4.66],[1,3,0]],"ltp":1.48,"tv":7329.06,"id":8257852}]}]}
{"op":"mcm","clk":"1012574548","pt":1580662169224,"mc":[{"id":"1.168223930","rc":[{"batb":[[0,1.92,579],[1,1.41,99.77]],"ltp":1.48,"tv":7329.06,"id":8257852}]}]}
{"op":"mcm","clk":"1012574661","pt":1580662170230,"mc":[{"id":"1.168223930","rc":[{"batb":[[0,1.86,339.52],[1,1.84,338.11],[2,1.69,51.06]],"batl":[[0,1.94,249.15],[1,1.96,282.05]],"ltp":3.05,"tv":6748.56,"id":8444055},{"batb":[[0,2.04,54.21],[1,1.92,579],[2,1.74,45.16]],"ltp":1.48,"tv":7329.06,"id":8257852}]}]}
{"op":"mcm","clk":"1012574928","pt":1580662172265,"mc":[{"id":"1.168223930","rc":[{"batb":[[1,1.84,387.68]],"ltp":3.05,"tv":6748.56,"id":8444055},{"batb":[[1,2.02,41.17],[2,1.92,579]],"batl":[[0,2.2,34.45],[1,2.6,671.4],[2,3,4.66]],"ltp":1.48,"tv":7329.06,"id":8257852}]}]}
{"op":"mcm","clk":"1012575055","pt":1580662173250,"mc":[{"id":"1.168223930","rc":[{"batl":[[2,1.98,42.01]],"ltp":3.05,"tv":6748.56,"id":8444055},{"batb":[[2,1.74,45.16]],"ltp":1.48,"tv":7329.06,"id":8257852}]}]}
{"op":"mcm","clk":"1012575583","pt":1580662177146,"mc":[{"id":"1.168223930","rc":[{"trd":[[1.94,3.19]],"batl":[[0,1.94,245.96]],"ltp":1.94,"tv":6751.75,"id":8444055},{"trd":[[2.06,3]],"ltp":2.06,"tv":7332.06,"id":8257852}],"tv":14083.81}]}
{"op":"mcm","clk":"1012576836","pt":1580662186219,"mc":[{"id":"1.168223930","rc":[{"batb":[[0,1.84,49.57],[1,1.69,51.06],[2,1.69,0]],"batl":[[0,1.98,42.01],[1,1.96,0],[2,1.98,0]],"ltp":1.94,"tv":6751.75,"id":8444055},{"batb":[[0,2.02,41.17],[1,1.74,45.16],[2,1.74,0]],"ltp":2.06,"tv":7332.06,"id":8257852}]}]}
{"op":"mcm","clk":"1012576985","pt":1580662187243,"mc":[{"id":"1.168223930","rc":[{"batb":[[0,1.69,51.06],[1,1.69,0]],"ltp":1.94,"tv":6751.75,"id":8444055},{"batb":[[0,1.74,45.16],[1,1.74,0]],"batl":[[0,2.6,671.4],[1,3,4.66],[2,3,0]],"ltp":2.06,"tv":7332.06,"id":8257852}]}]}
{"op":"mcm","clk":"1012577241","pt":1580662189223,"mc":[{"id":"1.168223930","rc":[{"batb":[[0,1.71,418.26],[1,1.69,499.38]],"batl":[[0,2.32,287.75],[1,2.34,171.57]],"ltp":1.94,"tv":6751.75,"id":8444055}]}]}
{"op":"mcm","clk":"1012578413","pt":1580662198256,"mc":[{"id":"1.168223930","rc":[{"batl":[[0,1.78,255.74],[1,1.8,366]],"ltp":1.94,"tv":6751.75,"id":8444055},{"batb":[[0,2.28,416.16],[1,1.74,45.16]],"ltp":2.06,"tv":7332.06,"id":8257852}]}]}
{"op":"mcm","clk":"1012578524","pt":1580662199186,"mc":[{"id":"1.168223930","rc":[{"batb":[[2,1.48,85.21]],"ltp":1.94,"tv":6751.75,"id":8444055},{"batb":[[0,2.3,38.95],[1,2.28,416.16],[2,2.06,52.72]],"ltp":2.06,"tv":7332.06,"id":8257852}]}]}
{"op":"mcm","clk":"1012578644","pt":1580662200084,"mc":[{"id":"1.168223930","rc":[{"batb":[[0,1.71,477.07]],"batl":[[2,1.83,42.01]],"ltp":1.94,"tv":6751.75,"id":8444055},{"batb":[[2,2.2,34.45]],"batl":[[0,2.42,29.41],[1,2.6,671.4],[2,3,4.66]],"ltp":2.06,"tv":7332.06,"id":8257852}]}]}
{"op":"mcm","clk":"1012578791","pt":1580662201265,"mc":[{"id":"1.168223930","rc":[{"batb":[[1,2.2,34.45],[2,2.06,52.72]],"ltp":2.06,"tv":7332.06,"id":8257852}]}]}
{"op":"mcm","clk":"1012580913","pt":1580662216014,"mc":[{"id":"1.168223930","rc":[{"batb":[[1,1.7,51.06],[2,1.69,448.32]],"ltp":1.94,"tv":6751.75,"id":8444055}]}]}
{"op":"mcm","clk":"1012582133","pt":1580662224224,"mc":[{"id":"1.168223930","rc":[{"batb":[[1,1.7,50.75]],"ltp":1.94,"tv":6751.75,"id":8444055},{"batb":[[0,2.28,39.18]],"ltp":2.06,"tv":7332.06,"id":8257852}]}]}
{"op":"mcm","clk":"1012583727","pt":1580662235055,"mc":[{"id":"1.168223930","rc":[{"batb":[[0,1.71,418.26]],"batl":[[2,1.83,0]],"ltp":1.94,"tv":6751.75,"id":8444055},{"batb":[[1,2.06,52.72],[2,2.06,0]],"batl":[[0,2.6,671.4],[1,3,4.66],[2,3,0]],"ltp":2.06,"tv":7332.06,"id":8257852}]}]}
{"op":"mcm","clk":"1012584021","pt":1580662236960,"mc":[{"id":"1.168223930","rc":[{"batb":[[1,1.7,50.51]],"ltp":1.94,"tv":6751.75,"id":8444055}]}]}
{"op":"mcm","clk":"1012584212","pt":1580662238234,"mc":[{"id":"1.168223930","rc":[{"batl":[[2,1.81,42.01]],"ltp":1.94,"tv":6751.75,"id":8444055},{"batb":[[1,2.22,33.61],[2,2.06,52.72]],"ltp":2.06,"tv":7332.06,"id":8257852}]}]}
{"op":"mcm","clk":"1012585341","pt":1580662244988,"mc":[{"id":"1.168223930","rc":[{"batb":[[1,1.7,50.28]],"ltp":1.94,"tv":6751.75,"id":8444055}]}]}
{"op":"mcm","clk":"1012587552","pt":1580662259170,"mc":[{"id":"1.168223930","rc":[{"trd":[[1.78,724.33]],"batb":[[0,1.78,44.26],[2,1.48,83.87]],"batl":[[0,1.81,42.01],[1,1.8,0],[2,1.81,0]],"ltp":1.78,"tv":7263.23,"id":8444055}],"tv":14595.29}]}
{"op":"mcm","clk":"1012587946","pt":1580662261982,"mc":[{"id":"1.168223930","rc":[{"batb":[[1,1.72,298.12],[2,1.7,488.48]],"batl":[[0,1.79,346.39],[1,1.81,400.83]],"ltp":1.78,"tv":7263.23,"id":8444055}]}]}
{"op":"mcm","clk":"1012591948","pt":1580662295269,"mc":[{"id":"1.168223930","rc":[{"batb":[[1,1.7,50.28],[2,1.48,83.87]],"batl":[[0,1.81,42.01],[1,1.81,0]],"ltp":1.78,"tv":7263.23,"id":8444055}]}]}
{"op":"mcm","clk":"1012592059","pt":1580662296157,"mc":[{"id":"1.168223930","rc":[{"batb":[[1,1.48,83.87],[2,1.48,0]],"ltp":1.78,"tv":7263.23,"id":8444055},{"batb":[[0,2.22,33.61],[1,2.06,52.72],[2,2.06,0]],"ltp":2.06,"tv":7332.06,"id":8257852}]}]}
{"op":"mcm","clk":"1012592106","pt":1580662296572,"mc":[{"id":"1.168223930","rc":[{"batb":[[0,2.06,52.72],[1,2.06,0]],"ltp":2.06,"tv":7332.06,"id":8257852}]}]}
{"op":"mcm","clk":"1012592427","pt":1580662299084,"mc":[{"id":"1.168223930","rc":[{"batb":[[1,1.51,283.42],[2,1.5,348.88]],"batl":[[0,1.95,293.77],[1,1.97,277.51]],"ltp":1.78,"tv":7263.23,"id":8444055},{"batb":[[0,2.04,54.21]],"ltp":2.06,"tv":7332.06,"id":8257852}]}]}
{"op":"mcm","clk":"1012593131","pt":1580662305066,"mc":[{"id":"1.168223930","rc":[{"trd":[[1.78,812.85]],"batb":[[0,1.51,283.42],[1,1.5,348.88],[2,1.48,83.09]],"batl":[[0,1.56,450.36],[1,1.57,287.68],[2,1.59,488.42]],"ltp":1.78,"tv":7351.75,"id":8444055},{"batl":[[0,3,4.66],[1,3,0]],"ltp":2.06,"tv":7332.06,"id":8257852}],"tv":14683.81}]}
{"op":"mcm","clk":"1012593257","pt":1580662306202,"mc":[{"id":"1.168223930","rc":[{"batb":[[0,2.84,21.95],[1,2.38,35.25]],"ltp":2.06,"tv":7332.06,"id":8257852}]}]}
{"op":"mcm","clk":"1012593370","pt":1580662307202,"mc":[{"id":"1.168223930","rc":[{"batl":[[2,1.59,0]],"ltp":1.78,"tv":7351.75,"id":8444055}]}]}
{"op":"mcm","clk":"1012593488","pt":1580662308207,"mc":[{"id":"1.168223930","rc":[{"batb":[[0,1.51,365.76]],"batl":[[2,1.6,42.01]],"ltp":1.78,"tv":7351.75,"id":8444055},{"batb":[[1,2.64,25.21],[2,2.38,35.25]],"batl":[[0,2.94,21],[1,3,4.66]],"ltp":2.06,"tv":7332.06,"id":8257852}]}]}
{"op":"mcm","clk":"1012593619","pt":1580662309195,"mc":[{"id":"1.168223930","rc":[{"batl":[[2,3.65,458.8]],"ltp":2.06,"tv":7332.06,"id":8257852}]}]}
{"op":"mcm","clk":"1012593706","pt":1580662309892,"mc":[{"id":"1.168223930","rc":[{"trd":[[1.55,40.22],[1.56,20.56]],"batl":[[0,1.56,440.08]],"ltp":1.56,"tv":7412.54,"id":8444055},{"trd":[[2.84,21.95]],"batb":[[0,2.64,25.21],[1,2.38,35.25],[2,2.38,0]],"ltp":2.84,"tv":7354.01,"id":8257852}],"tv":14766.55}]}
{"op":"mcm","clk":"1012594528","pt":1580662317194,"mc":[{"id":"1.168223930","rc":[{"trd":[[1.5,186.68],[1.51,772.42]],"batb":[[0,1.5,255.54],[1,1.48,83.09],[2,1.26,176.4]],"batl":[[0,1.56,296.36],[1,1.57,0],[2,1.6,0]],"ltp":1.5,"tv":8371.64,"id":8444055},{"trd":[[2.94,21]],"batb":[[0,2.38,35.25],[1,2.38,0]],"batl":[[0,3,4.66],[1,3.65,458.8],[2,3.65,0]],"ltp":2.94,"tv":7375.01,"id":8257852}],"tv":15746.66}]}
{"op":"mcm","clk":"1012594760","pt":1580662319226,"mc":[{"id":"1.168223930","rc":[{"trd":[[1.56,21.07]],"batl":[[0,1.56,296.11]],"ltp":1.56,"tv":8372.14,"id":8444055}],"tv":15747.16}]}
{"op":"mcm","clk":"1012594876","pt":1580662320230,"mc":[{"id":"1.168223930","rc":[{"batb":[[0,1.5,84.02]],"batl":[[0,1.58,42.01]],"ltp":1.56,"tv":8372.14,"id":8444055},{"batb":[[0,2.68,24.37],[1,2.38,35.25]],"batl":[[0,2.98,21],[1,3,4.66],[2,3.65,458.8]],"ltp":2.94,"tv":7375.01,"id":8257852}]}]}
{"op":"mcm","clk":"1012594968","pt":1580662321000,"mc":[{"id":"1.168223930","rc":[{"batb":[[0,1.26,176.4],[1,1.48,0],[2,1.26,0]],"ltp":1.56,"tv":8372.14,"id":8444055},{"batb":[[0,2.38,35.25],[1,2.38,0]],"batl":[[0,3,4.66],[1,3.65,458.8],[2,3.65,0]],"ltp":2.94,"tv":7375.01,"id":8257852}]}]}
{"op":"mcm","clk":"1012595308","pt":1580662324209,"mc":[{"id":"1.168223930","rc":[{"batb":[[0,1.27,173.57]],"ltp":1.56,"tv":8372.14,"id":8444055},{"batb":[[0,2.36,36.04]],"ltp":2.94,"tv":7375.01,"id":8257852}]}]}
{"op":"mcm","clk":"1012595408","pt":1580662325195,"mc":[{"id":"1.168223930","rc":[{"trd":[[1.5,195.99]],"batb":[[0,1.45,562.02],[1,1.44,416.37],[2,1.27,173.57]],"batl":[[0,1.5,412.28],[1,1.51,334.08]],"ltp":1.5,"tv":8381.45,"id":8444055},{"trd":[[3,4.66]],"batl":[[0,3.65,458.8],[1,3.65,0]],"ltp":3.0,"tv":7379.67,"id":8257852}],"tv":15761.12}]}
{"op":"mcm","clk":"1012595830","pt":1580662329093,"mc":[{"id":"1.168223930","rc":[{"batb":[[0,1.27,173.57],[1,1.44,0],[2,1.27,0]],"ltp":1.5,"tv":8381.45,"id":8444055}]}]}
{"op":"mcm","clk":"1012596144","pt":1580662332032,"mc":[{"id":"1.168223930","rc":[{"batb":[[0,1.28,849.65],[1,1.27,947.96]],"batl":[[0,1.73,263.37],[1,1.75,400.88]],"ltp":1.5,"tv":8381.45,"id":8444055}]}]}
{"op":"mcm","clk":"1012596750","pt":1580662337248,"mc":[{"id":"1.168223930","rc":[{"batl":[[0,1.32,802.76],[1,1.33,1103.67]],"ltp":1.5,"tv":8381.45,"id":8444055}]}]}
{"op":"mcm","clk":"1012596843","pt":1580662338142,"mc":[{"id":"1.168223930","rc":[{"batb":[[2,1.08,585.79]],"ltp":1.5,"tv":8381.45,"id":8444055},{"batb":[[0,4.2,41.94],[1,3.15,42.02]],"batl":[[0,4.4,11.76]],"ltp":3.0,"tv":7379.67,"id":8257852}]}]}
{"op":"mcm","clk":"1012597067","pt":1580662340137,"mc":[{"id":"1.168223930","rc":[{"batl":[[1,1.33,570.99],[2,1.35,42.01]],"ltp":1.5,"tv":8381.45,"id":8444055},{"batb":[[1,3.8,14.28],[2,3.15,42.02]],"ltp":3.0,"tv":7379.67,"id":8257852}]}]}
{"op":"mcm","clk":"1012597173","pt":1580662341052,"mc":[{"id":"1.168223930","rc":[{"batb":[[1,3.85,14.28]],"batl":[[1,5.5,300.67]],"ltp":3.0,"tv":7379.67,"id":8257852}]}]}
{"op":"mcm","clk":"1012597287","pt":1580662342269,"mc":[{"id":"1.168223930","rc":[{"batb":[[0,1.29,144.51],[1,1.28,849.65],[2,1.27,947.96]],"ltp":1.5,"tv":8381.45,"id":8444055},{"batl":[[1,5.5,0]],"ltp":3.0,"tv":7379.67,"id":8257852}]}]}
{"op":"mcm","clk":"1012598575","pt":1580662352176,"mc":[{"id":"1.168223930","rc":[{"batb":[[1,1.08,584.76],[2,1.27,0]],"batl":[[0,1.35,42.01],[1,1.71,13.02],[2,1.35,0]],"ltp":1.5,"tv":8381.45,"id":8444055},{"batb":[[0,3.85,14.28],[1,3.15,42.02],[2,3.15,0]],"ltp":3.0,"tv":7379.67,"id":8257852}]}]}
{"op":"mcm","clk":"1012598692","pt":1580662353176,"mc":[{"id":"1.168223930","rc":[{"batb":[[0,1.08,584.76],[1,1.08,0]],"batl":[[0,1.71,13.02],[1,1.71,0]],"ltp":1.5,"tv":8381.45,"id":8444055},{"batb":[[0,3.15,42.02],[1,3.15,0]],"ltp":3.0,"tv":7379.67,"id":8257852}]}]}
{"op":"mcm","clk":"1012598830","pt":1580662354268,"mc":[{"id":"1.168223930","rc":[{"batb":[[0,1.1,1350.71],[1,1.09,1015.46],[2,1.08,584.76]],"batl":[[0,1.47,520.09],[1,1.48,360.34]],"ltp":1.5,"tv":8381.45,"id":8444055}]}]}
{"op":"mcm","clk":"1012598932","pt":1580662355137,"mc":[{"id":"1.168223930","rc":[{"batb":[[0,1.08,584.76],[1,1.09,0],[2,1.08,0]],"ltp":1.5,"tv":8381.45,"id":8444055}]}]}
{"op":"mcm","clk":"1012599209","pt":1580662357260,"mc":[{"id":"1.168223930","rc":[{"batb":[[0,1.24,868.33],[1,1.23,939.14],[2,1.08,584.76]],"batl":[[0,1.27,324.22],[1,1.28,701.62]],"ltp":1.5,"tv":8381.45,"id":8444055}]}]}
{"op":"mcm","clk":"1012599389","pt":1580662359038,"mc":[{"id":"1.168223930","rc":[{"batb":[[0,1.08,584.76],[1,1.23,0],[2,1.08,0]],"batl":[[0,1.66,764.96],[1,1.28,0]],"ltp":1.5,"tv":8381.45,"id":8444055},{"batl":[[0,6,72.65]],"ltp":3.0,"tv":7379.67,"id":8257852}]}]}
{"op":"mcm","clk":"1012599749","pt":1580662362064,"mc":[{"id":"1.168223930","rc":[{"batb":[[0,1.1,1593.21],[1,1.09,770.72],[2,1.08,584.76]],"batl":[[0,1.47,335.41],[1,1.48,360.01]],"ltp":1.5,"tv":8381.45,"id":8444055}]}]}
{"op":"mcm","clk":"1012600907","pt":1580662373076,"mc":[{"id":"1.168223930","rc":[{"batl":[[0,1.12,1403.04],[1,1.13,903.73],[2,1.19,532.68]],"ltp":1.5,"tv":8381.45,"id":8444055}]}]}
{"op":"mcm","clk":"1012601028","pt":1580662374184,"mc":[{"id":"1.168223930","rc":[{"batb":[[0,1.11,168.04],[1,1.1,1593.21],[2,1.09,1354.85]],"batl":[[2,1.14,42.01]],"ltp":1.5,"tv":8381.45,"id":8444055},{"batb":[[0,9.4,32.26],[1,8.2,5.04],[2,6,35.8]],"ltp":3.0,"tv":7379.67,"id":8257852}]}]}
{"op":"mcm","clk":"1012601231","pt":1580662376117,"mc":[{"id":"1.168223930","rc":[{"batl":[[0,13.5,40.17]],"ltp":3.0,"tv":7379.67,"id":8257852}]}]}
{"op":"mcm","clk":"1012601958","pt":1580662382094,"mc":[{"id":"1.168223930","rc":[{"trd":[[1.11,42.22]],"batb":[[0,1.11,146.93]],"ltp":1.11,"tv":8423.67,"id":8444055}],"tv":15803.34}]}
{"op":"mcm","clk":"1012602077","pt":1580662383089,"mc":[{"id":"1.168223930","rc":[{"batb":[[0,1.1,1593.21],[1,1.09,1354.85],[2,1.09,0]],"ltp":1.11,"tv":8423.67,"id":8444055}]}]}
{"op":"mcm","clk":"1012602317","pt":1580662385200,"mc":[{"id":"1.168223930","rc":[{"batb":[[1,6,35.8],[2,6,0]],"ltp":3.0,"tv":7379.67,"id":8257852}]}]}
{"op":"mcm","clk":"1012602535","pt":1580662387202,"mc":[{"id":"1.168223930","rc":[{"batb":[[0,1.1,1520.01]],"batl":[[1,1.13,832.02]],"ltp":1.11,"tv":8423.67,"id":8444055},{"batb":[[1,8.4,5.04],[2,6,35.8]],"batl":[[0,10.5,4.2],[1,13.5,40.17]],"ltp":3.0,"tv":7379.67,"id":8257852}]}]}
{"op":"mcm","clk":"1012602645","pt":1580662388225,"mc":[{"id":"1.168223930","rc":[{"batb":[[0,1.1,1222.47]],"batl":[[1,1.13,541.69]],"ltp":1.11,"tv":8423.67,"id":8444055}]}]}
{"op":"mcm","clk":"1012602883","pt":1580662390195,"mc":[{"id":"1.168223930","rc":[{"batb":[[1,1.09,1428.72]],"batl":[[0,1.12,1475.39]],"ltp":1.11,"tv":8423.67,"id":8444055}]}]}
{"op":"mcm","clk":"1012602995","pt":1580662391202,"mc":[{"id":"1.168223930","rc":[{"batb":[[0,1.1,1134.59],[1,1.09,1729]],"batl":[[0,1.12,1768.31],[1,1.13,455.95]],"ltp":1.11,"tv":8423.67,"id":8444055}]}]}
{"op":"mcm","clk":"1012603210","pt":1580662393212,"mc":[{"id":"1.168223930","rc":[{"batl":[[0,1.14,42.01],[1,1.44,1185.54],[2,1.14,0]],"ltp":1.11,"tv":8423.67,"id":8444055},{"batb":[[0,8.4,5.04],[1,6,35.8],[2,6,0]],"ltp":3.0,"tv":7379.67,"id":8257852}]}]}
{"op":"mcm","clk":"1012603449","pt":1580662395201,"mc":[{"id":"1.168223930","rc":[{"batl":[[0,1.44,1185.54],[1,1.44,0]],"ltp":1.11,"tv":8423.67,"id":8444055},{"batb":[[0,6,35.8],[1,6,0]],"batl":[[0,13.5,40.17],[1,13.5,0]],"ltp":3.0,"tv":7379.67,"id":8257852}]}]}
{"op":"mcm","clk":"1012603550","pt":1580662396113,"mc":[{"id":"1.168223930","rc":[{"batl":[[0,1.2,1175.66],[1,1.21,969.67]],"ltp":1.11,"tv":8423.67,"id":8444055},{"batb":[[0,5.9,36.98]],"ltp":3.0,"tv":7379.67,"id":8257852}]}]}
{"op":"mcm","clk":"1012604099","pt":1580662400951,"mc":[{"id":"1.168223930","marketDefinition":{"bspMarket":false,"turnInPlayEnabled":true,"persistenceEnabled":true,"marketBaseRate":5.0,"eventId":"29681623","eventTypeId":"2","numberOfWinners":1,"bettingType":"ODDS","marketType":"SET_WINNER","marketTime":"2020-02-02T14:50:00.000Z","suspendTime":"2020-02-02T14:50:00.000Z","bspReconciled":false,"complete":true,"inPlay":true,"crossMatching":true,"runnersVoidable":false,"numberOfActiveRunners":2,"betDelay":3,"status":"SUSPENDED","runners":[{"status":"ACTIVE","sortPriority":1,"id":8257852,"name":"Maxime Janvier"},{"status":"ACTIVE","sortPriority":2,"id":8444055,"name":"Cem Ilkel"}],"regulators":["MR_INT"],"countryCode":"FR","discountAllowed":true,"timezone":"UTC","openDate":"2020-02-02T14:50:00.000Z","version":3149885640,"name":"Set 2 Winner","eventName":"Janvier v Ilkel"}}]}
{"op":"mcm","clk":"1012626676","pt":1580662607180,"mc":[{"id":"1.168223930","tv":0.0}]}
{"op":"mcm","clk":"1012626805","pt":1580662608441,"mc":[{"id":"1.168223930","marketDefinition":{"bspMarket":false,"turnInPlayEnabled":true,"persistenceEnabled":true,"marketBaseRate":5.0,"eventId":"29681623","eventTypeId":"2","numberOfWinners":1,"bettingType":"ODDS","marketType":"SET_WINNER","marketTime":"2020-02-02T14:50:00.000Z","suspendTime":"2020-02-02T14:50:00.000Z","bspReconciled":false,"complete":true,"inPlay":true,"crossMatching":false,"runnersVoidable":false,"numberOfActiveRunners":0,"betDelay":3,"status":"CLOSED","settledTime":"2020-02-02T16:54:16.000Z","runners":[{"status":"LOSER","sortPriority":1,"id":8257852,"name":"Maxime Janvier"},{"status":"WINNER","sortPriority":2,"id":8444055,"name":"Cem Ilkel"}],"regulators":["MR_INT"],"countryCode":"FR","discountAllowed":true,"timezone":"UTC","openDate":"2020-02-02T14:50:00.000Z","version":3149905179,"name":"Set 2 Winner","eventName":"Janvier v Ilkel"}}]}
