{"op":"mcm","clk":"1004323371","pt":1580581675727,"mc":[{"id":"1.168223930","marketDefinition":{"bspMarket":false,"turnInPlayEnabled":true,"persistenceEnabled":true,"marketBaseRate":5.0,"eventId":"29681623","eventTypeId":"2","numberOfWinners":1,"bettingType":"ODDS","marketType":"SET_WINNER","marketTime":"2020-02-02T15:00:00.000Z","suspendTime":"2020-02-02T15:00:00.000Z","bspReconciled":false,"complete":true,"inPlay":false,"crossMatching":false,"runnersVoidable":false,"numberOfActiveRunners":2,"betDelay":0,"status":"OPEN","runners":[{"status":"ACTIVE","sortPriority":1,"id":8257852,"name":"Maxime Janvier"},{"status":"ACTIVE","sortPriority":2,"id":8444055,"name":"Cem Ilkel"}],"regulators":["MR_INT"],"countryCode":"FR","discountAllowed":false,"timezone":"UTC","openDate":"2020-02-02T15:00:00.000Z","version":3146826522,"name":"Set 2 Winner","eventName":"Janvier v Ilkel"},"rc":[{"batb":[[0,1.01,20]],"ltp":0.0,"tv":0.0,"id":8444055},{"batb":[[0,1.01,20]],"ltp":0.0,"tv":0.0,"id":8257852}]}]}
{"op":"mcm","clk":"1004323649","pt":1580581677280,"mc":[{"id":"1.168223930","marketDefinition":{"bspMarket":false,"turnInPlayEnabled":true,"persistenceEnabled":true,"marketBaseRate":5.0,"eventId":"29681623","eventTypeId":"2","numberOfWinners":1,"bettingType":"ODDS","marketType":"SET_WINNER","marketTime":"2020-02-02T15:00:00.000Z","suspendTime":"2020-02-02T15:00:00.000Z","bspReconciled":false,"complete":true,"inPlay":false,"crossMatching":false,"runnersVoidable":false,"numberOfActiveRunners":2,"betDelay":0,"status":"OPEN","runners":[{"status":"ACTIVE","sortPriority":1,"id":8257852,"name":"Maxime Janvier"},{"status":"ACTIVE","sortPriority":2,"id":8444055,"name":"Cem Ilkel"}],"regulators":["MR_INT"],"countryCode":"FR","discountAllowed":true,"timezone":"UTC","openDate":"2020-02-02T15:00:00.000Z","version":3146826522,"name":"Set 2 Winner","eventName":"Janvier v Ilkel"}}]}
{"op":"mcm","clk":"1004346957","pt":1580581820655,"mc":[{"id":"1.168223930","rc":[{"batb":[[0,1.01,15]],"ltp":0.0,"tv":0.0,"id":8444055},{"batb":[[0,1.01,15]],"ltp":0.0,"tv":0.0,"id":8257852}]}]}
{"op":"mcm","clk":"1006958470","pt":1580602584248,"mc":[{"id":"1.168223930","rc":[{"batb":[[0,1.01,17.53]],"ltp":0.0,"tv":0.0,"id":8444055},{"batb":[[0,1.01,17.53]],"ltp":0.0,"tv":0.0,"id":8257852}]}]}
{"op":"mcm","clk":"1006958545","pt":1580602585241,"mc":[{"id":"1.168223930","rc":[{"batb":[[0,1.01,15]],"ltp":0.0,"tv":0.0,"id":8444055},{"batb":[[0,1.01,15]],"ltp":0.0,"tv":0.0,"id":8257852}]}]}
{"op":"mcm","clk":"1006958585","pt":1580602585817,"mc":[{"id":"1.168223930","rc":[{"batb":[[0,1.01,15.51]],"ltp":0.0,"tv":0.0,"id":8444055},{"batb":[[0,1.01,15.51]],"ltp":0.0,"tv":0.0,"id":8257852}]}]}
{"op":"mcm","clk":"1007018697","pt":1580603351094,"mc":[{"id":"1.168223930","rc":[{"batb":[[0,1.01,16.01]],"ltp":0.0,"tv":0.0,"id":8444055},{"batb":[[0,1.01,16.01]],"ltp":0.0,"tv":0.0,"id":8257852}]}]}
{"op":"mcm","clk":"1011219631","pt":1580655112527,"mc":[{"id":"1.168223930","marketDefinition":{"bspMarket":false,"turnInPlayEnabled":true,"persistenceEnabled":true,"marketBaseRate":5.0,"eventId":"29681623","eventTypeId":"2","numberOfWinners":1,"bettingType":"ODDS","marketType":"SET_WINNER","marketTime":"2020-02-02T14:50:00.000Z","suspendTime":"2020-02-02T14:50:00.000Z","bspReconciled":false,"complete":true,"inPlay":false,"crossMatching":false,"runnersVoidable":false,"numberOfActiveRunners":2,"betDelay":0,"status":"OPEN","runners":[{"status":"ACTIVE","sortPriority":1,"id":8257852,"name":"Maxime Janvier"},{"status":"ACTIVE","sortPriority":2,"id":8444055,"name":"Cem Ilkel"}],"regulators":["MR_INT"],"countryCode":"FR","discountAllowed":true,"timezone":"UTC","openDate":"2020-02-02T15:00:00.000Z","version":3149299570,"name":"Set 2 Winner","eventName":"Janvier v Ilkel"}}]}
{"op":"mcm","clk":"1011220310","pt":1580655116547,"mc":[{"id":"1.168223930","marketDefinition":{"bspMarket":false,"turnInPlayEnabled":true,"persistenceEnabled":true,"marketBaseRate":5.0,"eventId":"29681623","eventTypeId":"2","numberOfWinners":1,"bettingType":"ODDS","marketType":"SET_WINNER","marketTime":"2020-02-02T14:50:00.000Z","suspendTime":"2020-02-02T14:50:00.000Z","bspReconciled":false,"complete":true,"inPlay":false,"crossMatching":false,"runnersVoidable":false,"numberOfActiveRunners":2,"betDelay":0,"status":"OPEN","runners":[{"status":"ACTIVE","sortPriority":1,"id":8257852,"name":"Maxime Janvier"},{"status":"ACTIVE","sortPriority":2,"id":8444055,"name":"Cem Ilkel"}],"regulators":["MR_INT"],"countryCode":"FR","discountAllowed":true,"timezone":"UTC","openDate":"2020-02-02T14:50:00.000Z","version":3149299570,"name":"Set 2 Winner","eventName":"Janvier v Ilkel"}}]}
{"op":"mcm","clk":"1011226539","pt":1580655155656,"mc":[{"id":"1.168223930","rc":[{"batb":[[0,2.12,48.7],[1,1.01,16.01]],"ltp":0.0,"tv":0.0,"id":8444055},{"batb":[[0,1.79,41.62],[1,1.01,16.01]],"ltp":0.0,"tv":0.0,"id":8257852}]}]}
{"op":"mcm","clk":"1011270700","pt":1580655427788,"mc":[{"id":"1.168223930","rc":[{"batb":[[0,2.12,48.15]],"ltp":0.0,"tv":0.0,"id":8444055},{"batb":[[0,1.78,42.02]],"ltp":0.0,"tv":0.0,"id":8257852}]}]}
{"op":"mcm","clk":"1011296747","pt":1580655598853,"mc":[{"id":"1.168223930","rc":[{"batb":[[0,2.14,47.76]],"ltp":0.0,"tv":0.0,"id":8444055}]}]}
{"op":"mcm","clk":"1011300484","pt":1580655618962,"mc":[{"id":"1.168223930","rc":[{"batb":[[0,2.14,47.13]],"ltp":0.0,"tv":0.0,"id":8444055},{"batb":[[0,1.77,42.88]],"ltp":0.0,"tv":0.0,"id":8257852}]}]}
{"op":"mcm","clk":"1011302159","pt":1580655629112,"mc":[{"id":"1.168223930","rc":[{"batb":[[0,2.16,46.66],[1,2.14,47.13],[2,1.01,16.01]],"ltp":0.0,"tv":0.0,"id":8444055},{"batb":[[1,1.76,43.28],[2,1.01,16.01]],"ltp":0.0,"tv":0.0,"id":8257852}]}]}
{"op":"mcm","clk":"1011321331","pt":1580655734483,"mc":[{"id":"1.168223930","rc":[{"batb":[[1,1.01,16.01],[2,1.01,0]],"ltp":0.0,"tv":0.0,"id":8444055},{"batb":[[0,1.76,43.28],[1,1.01,16.01],[2,1.01,0]],"ltp":0.0,"tv":0.0,"id":8257852}]}]}
{"op":"mcm","clk":"1011321671","pt":1580655736256,"mc":[{"id":"1.168223930","rc":[{"batb":[[0,2.18,1.16],[1,2.16,46.66],[2,1.01,16.01]],"ltp":0.0,"tv":0.0,"id":8444055},{"batb":[[0,1.77,1.42],[1,1.76,43.28],[2,1.01,16.01]],"ltp":0.0,"tv":0.0,"id":8257852}]}]}
{"op":"mcm","clk":"1011321811","pt":1580655737067,"mc":[{"id":"1.168223930","marketDefinition":{"bspMarket":false,"turnInPlayEnabled":true,"persistenceEnabled":true,"marketBaseRate":5.0,"eventId":"29681623","eventTypeId":"2","numberOfWinners":1,"bettingType":"ODDS","marketType":"SET_WINNER","marketTime":"2020-02-02T14:50:00.000Z","suspendTime":"2020-02-02T14:50:00.000Z","bspReconciled":false,"complete":true,"inPlay":false,"crossMatching":true,"runnersVoidable":false,"numberOfActiveRunners":2,"betDelay":0,"status":"OPEN","runners":[{"status":"ACTIVE","sortPriority":1,"id":8257852,"name":"Maxime Janvier"},{"status":"ACTIVE","sortPriority":2,"id":8444055,"name":"Cem Ilkel"}],"regulators":["MR_INT"],"countryCode":"FR","discountAllowed":true,"timezone":"UTC","openDate":"2020-02-02T14:50:00.000Z","version":3149299570,"name":"Set 2 Winner","eventName":"Janvier v Ilkel"}}]}
{"op":"mcm","clk":"1011354268","pt":1580655892216,"mc":[{"id":"1.168223930","rc":[{"batb":[[0,1.77,3.42]],"ltp":0.0,"tv":0.0,"id":8257852}]}]}
{"op":"mcm","clk":"1011354314","pt":1580655892447,"mc":[{"id":"1.168223930","rc":[{"batb":[[0,2.18,3.16]],"ltp":0.0,"tv":0.0,"id":8444055}]}]}
{"op":"mcm","clk":"1011367772","pt":1580655951996,"mc":[{"id":"1.168223930","rc":[{"batb":[[0,2.18,1.16]],"ltp":0.0,"tv":0.0,"id":8444055},{"batb":[[0,1.77,1.42]],"ltp":0.0,"tv":0.0,"id":8257852}]}]}
{"op":"mcm","clk":"1011374489","pt":1580655981284,"mc":[{"id":"1.168223930","rc":[{"batb":[[1,2.16,46.5]],"ltp":0.0,"tv":0.0,"id":8444055}]}]}
{"op":"mcm","clk":"1011433624","pt":1580656222882,"mc":[{"id":"1.168223930","rc":[{"batb":[[1,2.16,45.79]],"ltp":0.0,"tv":0.0,"id":8444055},{"batb":[[1,1.75,44.06]],"ltp":0.0,"tv":0.0,"id":8257852}]}]}
{"op":"mcm","clk":"1011445515","pt":1580656269630,"mc":[{"id":"1.168223930","rc":[{"batb":[[1,1.76,43.43]],"ltp":0.0,"tv":0.0,"id":8257852}]}]}
{"op":"mcm","clk":"1011453879","pt":1580656303983,"mc":[{"id":"1.168223930","rc":[{"batb":[[2,2.14,47.21]],"ltp":0.0,"tv":0.0,"id":8444055},{"batb":[[0,1.77,44.22]],"ltp":0.0,"tv":0.0,"id":8257852}]}]}
{"op":"mcm","clk":"1011457746","pt":1580656320007,"mc":[{"id":"1.168223930","rc":[{"batb":[[1,1.01,16.01],[2,2.14,0]],"ltp":0.0,"tv":0.0,"id":8444055},{"batb":[[0,1.77,1.42],[1,1.01,16.01],[2,1.01,0]],"ltp":0.0,"tv":0.0,"id":8257852}]}]}
{"op":"mcm","clk":"1011457918","pt":1580656320833,"mc":[{"id":"1.168223930","marketDefinition":{"bspMarket":false,"turnInPlayEnabled":true,"persistenceEnabled":true,"marketBaseRate":5.0,"eventId":"29681623","eventTypeId":"2","numberOfWinners":1,"bettingType":"ODDS","marketType":"SET_WINNER","marketTime":"2020-02-02T14:50:00.000Z","suspendTime":"2020-02-02T14:50:00.000Z","bspReconciled":false,"complete":true,"inPlay":true,"crossMatching":true,"runnersVoidable":false,"numberOfActiveRunners":2,"betDelay":3,"status":"OPEN","runners":[{"status":"ACTIVE","sortPriority":1,"id":8257852,"name":"Maxime Janvier"},{"status":"ACTIVE","sortPriority":2,"id":8444055,"name":"Cem Ilkel"}],"regulators":["MR_INT"],"countryCode":"FR","discountAllowed":true,"timezone":"UTC","openDate":"2020-02-02T14:50:00.000Z","version":3149418453,"name":"Set 2 Winner","eventName":"Janvier v Ilkel"},"rc":[{"batb":[[0,1.01,15.51],[1,1.01,0]],"ltp":0.0,"tv":0.0,"id":8444055},{"batb":[[0,1.01,15.51],[1,1.01,0]],"ltp":0.0,"tv":0.0,"id":8257852}]}]}
{"op":"mcm","clk":"1011463066","pt":1580656340969,"mc":[{"id":"1.168223930","rc":[{"batb":[[0,2.18,44.53],[1,2.12,48.23],[2,1.01,15.51]],"ltp":0.0,"tv":0.0,"id":8444055},{"batb":[[0,1.74,45.16],[1,1.72,46.97],[2,1.01,15.51]],"ltp":0.0,"tv":0.0,"id":8257852}]}]}
{"op":"mcm","clk":"1011466762","pt":1580656355815,"mc":[{"id":"1.168223930","rc":[{"batb":[[0,2.12,48.23],[1,1.01,15.51],[2,1.01,0]],"ltp":0.0,"tv":0.0,"id":8444055},{"batb":[[0,1.72,46.97],[1,1.01,15.51],[2,1.01,0]],"ltp":0.0,"tv":0.0,"id":8257852}]}]}
{"op":"mcm","clk":"1011468828","pt":1580656364088,"mc":[{"id":"1.168223930","rc":[{"batb":[[0,2.22,42.72],[1,2.16,46.34],[2,2.1,37.81]],"batl":[[0,2.36,30.25]],"ltp":0.0,"tv":0.0,"id":8444055},{"batb":[[0,1.74,56.29],[1,1.72,46.97],[2,1.7,48.78]],"batl":[[0,1.92,42.01]],"ltp":0.0,"tv":0.0,"id":8257852}]}]}
{"op":"mcm","clk":"1011471440","pt":1580656374512,"mc":[{"id":"1.168223930","rc":[{"batb":[[0,2.16,46.34],[1,2.1,37.81],[2,1.01,15.51]],"ltp":0.0,"tv":0.0,"id":8444055},{"batb":[[1,1.7,48.78],[2,1.01,15.51]],"ltp":0.0,"tv":0.0,"id":8257852}]}]}
{"op":"mcm","clk":"1011471903","pt":1580656376374,"mc":[{"id":"1.168223930","rc":[{"batb":[[1,1.01,15.51],[2,1.01,0]],"ltp":0.0,"tv":0.0,"id":8444055},{"batb":[[0,1.7,48.78],[1,1.01,15.51],[2,1.01,0]],"ltp":0.0,"tv":0.0,"id":8257852}]}]}
{"op":"mcm","clk":"1011472250","pt":1580656377809,"mc":[{"id":"1.168223930","rc":[{"batb":[[0,2.14,47.05]],"ltp":0.0,"tv":0.0,"id":8444055},{"batb":[[0,1.71,48.07]],"ltp":0.0,"tv":0.0,"id":8257852}]}]}
{"op":"mcm","clk":"1011475509","pt":1580656391212,"mc":[{"id":"1.168223930","rc":[{"batb":[[0,2.24,41.62],[1,2.18,44.85],[2,1.01,15.51]],"ltp":0.0,"tv":0.0,"id":8444055},{"batb":[[1,1.7,49.18],[2,1.01,15.51]],"ltp":0.0,"tv":0.0,"id":8257852}]}]}
{"op":"mcm","clk":"1011475652","pt":1580656391800,"mc":[{"id":"1.168223930","rc":[{"batb":[[2,2.14,36.13]],"batl":[[0,2.4,29.41]],"ltp":0.0,"tv":0.0,"id":8444055},{"batb":[[0,1.72,57.97],[1,1.71,48.07],[2,1.7,49.18]],"batl":[[0,1.9,42.01]],"ltp":0.0,"tv":0.0,"id":8257852}]}]}
{"op":"mcm","clk":"1011478298","pt":1580656403249,"mc":[{"id":"1.168223930","rc":[{"batb":[[0,2.18,44.85],[1,2.14,36.13],[2,1.01,15.51]],"ltp":0.0,"tv":0.0,"id":8444055},{"batb":[[1,1.7,48.78],[2,1.01,15.51]],"ltp":0.0,"tv":0.0,"id":8257852}]}]}
{"op":"mcm","clk":"1011478754","pt":1580656405099,"mc":[{"id":"1.168223930","rc":[{"batb":[[1,1.01,15.51],[2,1.01,0]],"ltp":0.0,"tv":0.0,"id":8444055},{"batb":[[0,1.7,48.78],[1,1.01,15.51],[2,1.01,0]],"ltp":0.0,"tv":0.0,"id":8257852}]}]}
{"op":"mcm","clk":"1011481661","pt":1580656417235,"mc":[{"id":"1.168223930","rc":[{"batb":[[0,2.18,80.14]],"batl":[[0,2.46,28.57]],"ltp":0.0,"tv":0.0,"id":8444055},{"batb":[[1,1.69,60.49],[2,1.01,15.51]],"batl":[[0,1.86,42.01]],"ltp":0.0,"tv":0.0,"id":8257852}]}]}
{"op":"mcm","clk":"1011481869","pt":1580656418148,"mc":[{"id":"1.168223930","rc":[{"batb":[[0,2.26,40.99],[1,2.22,42.57],[2,2.18,49.15]],"ltp":0.0,"tv":0.0,"id":8444055},{"batb":[[2,1.66,53.03]],"ltp":0.0,"tv":0.0,"id":8257852}]}]}
{"op":"mcm","clk":"1011481908","pt":1580656418315,"mc":[{"id":"1.168223930","rc":[{"batb":[[2,2.18,35.29]],"ltp":0.0,"tv":0.0,"id":8444055}]}]}
{"op":"mcm","clk":"1011493142","pt":1580656464002,"mc":[{"id":"1.168223930","rc":[{"batb":[[0,2.22,42.57],[1,2.18,35.29],[2,1.01,15.51]],"ltp":0.0,"tv":0.0,"id":8444055},{"batb":[[0,1.69,60.49],[1,1.66,53.03],[2,1.01,15.51]],"ltp":0.0,"tv":0.0,"id":8257852}]}]}
{"op":"mcm","clk":"1011493222","pt":1580656464376,"mc":[{"id":"1.168223930","rc":[{"batb":[[1,1.01,15.51],[2,1.01,0]],"ltp":0.0,"tv":0.0,"id":8444055},{"batb":[[0,1.66,53.03],[1,1.01,15.51],[2,1.01,0]],"ltp":0.0,"tv":0.0,"id":8257852}]}]}
{"op":"mcm","clk":"1011493952","pt":1580656467034,"mc":[{"id":"1.168223930","rc":[{"batb":[[0,1.67,52.4],[1,1.66,53.03],[2,1.01,15.51]],"ltp":0.0,"tv":0.0,"id":8257852}]}]}
{"op":"mcm","clk":"1011494138","pt":1580656467697,"mc":[{"id":"1.168223930","rc":[{"batb":[[1,1.01,15.51],[2,1.01,0]],"ltp":0.0,"tv":0.0,"id":8257852}]}]}
{"op":"mcm","clk":"1011498935","pt":1580656487248,"mc":[{"id":"1.168223930","rc":[{"batb":[[1,2.18,45.08],[2,2.16,36.13]],"batl":[[0,2.44,28.57]],"ltp":0.0,"tv":0.0,"id":8444055},{"batb":[[0,1.73,46.58],[1,1.7,59.65],[2,1.69,50.2]],"batl":[[0,1.87,42.01]],"ltp":0.0,"tv":0.0,"id":8257852}]}]}
{"op":"mcm","clk":"1011499372","pt":1580656489037,"mc":[{"id":"1.168223930","rc":[{"batl":[[0,2.42,29.41]],"ltp":0.0,"tv":0.0,"id":8444055}]}]}
{"op":"mcm","clk":"1011502053","pt":1580656499863,"mc":[{"id":"1.168223930","rc":[{"batb":[[0,2.18,45.08],[1,2.16,36.13],[2,1.01,15.51]],"ltp":0.0,"tv":0.0,"id":8444055},{"batb":[[0,1.7,59.65],[1,1.69,50.2],[2,1.01,15.51]],"ltp":0.0,"tv":0.0,"id":8257852}]}]}
{"op":"mcm","clk":"1011502443","pt":1580656501253,"mc":[{"id":"1.168223930","rc":[{"batb":[[1,1.01,15.51],[2,1.01,0]],"ltp":0.0,"tv":0.0,"id":8444055},{"batb":[[0,1.69,50.2],[1,1.01,15.51],[2,1.01,0]],"ltp":0.0,"tv":0.0,"id":8257852}]}]}
{"op":"mcm","clk":"1011506369","pt":1580656517266,"mc":[{"id":"1.168223930","rc":[{"batb":[[1,2.12,36.97],[2,1.01,15.51]],"batl":[[0,2.38,30.25]],"ltp":0.0,"tv":0.0,"id":8444055},{"batb":[[0,1.72,57.97],[1,1.69,50.2],[2,1.01,15.51]],"batl":[[0,1.9,42.01]],"ltp":0.0,"tv":0.0,"id":8257852}]}]}
{"op":"mcm","clk":"1011506527","pt":1580656517865,"mc":[{"id":"1.168223930","rc":[{"batb":[[1,2.14,46.89],[2,2.12,36.97]],"ltp":0.0,"tv":0.0,"id":8444055},{"batb":[[0,1.75,44.69],[1,1.72,57.97],[2,1.71,47.68]],"ltp":0.0,"tv":0.0,"id":8257852}]}]}
{"op":"mcm","clk":"1011509830","pt":1580656530986,"mc":[{"id":"1.168223930","rc":[{"batb":[[0,2.14,46.89],[1,2.12,36.97],[2,1.01,15.51]],"ltp":0.0,"tv":0.0,"id":8444055},{"batb":[[0,1.72,57.97],[1,1.71,47.68],[2,1.01,15.51]],"ltp":0.0,"tv":0.0,"id":8257852}]}]}
{"op":"mcm","clk":"1011510441","pt":1580656533090,"mc":[{"id":"1.168223930","rc":[{"batb":[[1,1.01,15.51],[2,1.01,0]],"ltp":0.0,"tv":0.0,"id":8444055},{"batb":[[0,1.71,47.68],[1,1.01,15.51],[2,1.01,0]],"ltp":0.0,"tv":0.0,"id":8257852}]}]}
{"op":"mcm","clk":"1011514375","pt":1580656549021,"mc":[{"id":"1.168223930","rc":[{"batb":[[0,2.24,41.86],[1,2.2,43.75],[2,1.01,15.51]],"ltp":0.0,"tv":0.0,"id":8444055},{"batb":[[1,1.67,52.09],[2,1.01,15.51]],"ltp":0.0,"tv":0.0,"id":8257852}]}]}
{"op":"mcm","clk":"1011514689","pt":1580656550228,"mc":[{"id":"1.168223930","rc":[{"batb":[[2,2.18,35.29]],"batl":[[0,2.44,28.57]],"ltp":0.0,"tv":0.0,"id":8444055},{"batb":[[1,1.69,60.49],[2,1.67,52.09]],"batl":[[0,1.86,42.01]],"ltp":0.0,"tv":0.0,"id":8257852}]}]}
{"op":"mcm","clk":"1011518018","pt":1580656563133,"mc":[{"id":"1.168223930","rc":[{"batb":[[0,2.2,43.75],[1,2.18,35.29],[2,1.01,15.51]],"ltp":0.0,"tv":0.0,"id":8444055},{"batb":[[0,1.69,60.49],[1,1.67,52.09],[2,1.01,15.51]],"ltp":0.0,"tv":0.0,"id":8257852}]}]}
{"op":"mcm","clk":"1011518501","pt":1580656565062,"mc":[{"id":"1.168223930","rc":[{"batb":[[1,1.01,15.51],[2,1.01,0]],"batl":[[0,3,213.45]],"ltp":0.0,"tv":0.0,"id":8444055},{"batb":[[0,1.67,52.09],[1,1.01,15.51],[2,1.01,0]],"batl":[[0,2.3,309.75]],"ltp":0.0,"tv":0.0,"id":8257852}]}]}
{"op":"mcm","clk":"1011525753","pt":1580656595268,"mc":[{"id":"1.168223930","rc":[{"batb":[[1,2.16,45.64],[2,1.01,15.51]],"ltp":0.0,"tv":0.0,"id":8444055},{"batb":[[0,1.73,45.95],[1,1.7,49.49],[2,1.67,52.09]],"ltp":0.0,"tv":0.0,"id":8257852}]}]}
{"op":"mcm","clk":"1011525966","pt":1580656596175,"mc":[{"id":"1.168223930","rc":[{"batb":[[2,2.14,36.13]],"batl":[[0,2.42,29.41]],"ltp":0.0,"tv":0.0,"id":8444055},{"batb":[[1,1.71,58.81],[2,1.7,49.49]],"batl":[[0,1.88,42.01],[1,2.3,309.75]],"ltp":0.0,"tv":0.0,"id":8257852}]}]}
{"op":"mcm","clk":"1011526181","pt":1580656597160,"mc":[{"id":"1.168223930","rc":[{"batl":[[1,2.84,228.62]],"ltp":0.0,"tv":0.0,"id":8444055}]}]}
{"op":"mcm","clk":"1011529826","pt":1580656613247,"mc":[{"id":"1.168223930","rc":[{"batb":[[0,2.16,45.64],[1,1.01,15.51],[2,2.14,0]],"batl":[[0,2.84,228.62],[1,2.84,0]],"ltp":0.0,"tv":0.0,"id":8444055},{"batb":[[0,1.7,49.49],[1,1.01,15.51],[2,1.7,0]],"batl":[[0,2.3,309.75],[1,2.3,0]],"ltp":0.0,"tv":0.0,"id":8257852}]}]}
{"op":"mcm","clk":"1011533950","pt":1580656631226,"mc":[{"id":"1.168223930","rc":[{"batb":[[1,2.1,50.59],[2,1.01,15.51]],"ltp":0.0,"tv":0.0,"id":8444055},{"batb":[[0,1.75,44.22],[1,1.73,45.87],[2,1.01,15.51]],"ltp":0.0,"tv":0.0,"id":8257852}]}]}
{"op":"mcm","clk":"1011534113","pt":1580656631924,"mc":[{"id":"1.168223930","rc":[{"batb":[[1,2.1,88.4]],"batl":[[0,2.36,30.25],[1,2.84,228.62]],"ltp":0.0,"tv":0.0,"id":8444055},{"batb":[[1,1.74,56.29],[2,1.73,45.87]],"batl":[[0,1.92,42.01],[1,2.3,309.75]],"ltp":0.0,"tv":0.0,"id":8257852}]}]}
{"op":"mcm","clk":"1011540673","pt":1580656660078,"mc":[{"id":"1.168223930","rc":[{"batb":[[0,2.1,87.77],[1,1.01,15.51],[2,1.01,0]],"ltp":0.0,"tv":0.0,"id":8444055},{"batb":[[0,1.74,56.29],[1,1.73,45.87],[2,1.01,15.51]],"ltp":0.0,"tv":0.0,"id":8257852}]}]}
{"op":"mcm","clk":"1011540847","pt":1580656660785,"mc":[{"id":"1.168223930","rc":[{"batb":[[0,2.1,49.96]],"batl":[[0,2.84,228.62],[1,2.84,0]],"ltp":0.0,"tv":0.0,"id":8444055},{"batb":[[0,1.73,45.87],[1,1.01,15.51],[2,1.01,0]],"batl":[[0,2.3,309.75],[1,2.3,0]],"ltp":0.0,"tv":0.0,"id":8257852}]}]}
{"op":"mcm","clk":"1011542312","pt":1580656667064,"mc":[{"id":"1.168223930","rc":[{"batb":[[0,2.2,43.28],[1,2.14,47.13],[2,1.01,15.51]],"ltp":0.0,"tv":0.0,"id":8444055},{"batb":[[1,1.71,48.47],[2,1.01,15.51]],"ltp":0.0,"tv":0.0,"id":8257852}]}]}
{"op":"mcm","clk":"1011542491","pt":1580656667877,"mc":[{"id":"1.168223930","rc":[{"batb":[[2,2.12,36.97]],"batl":[[0,2.38,30.25],[1,2.84,228.62]],"ltp":0.0,"tv":0.0,"id":8444055},{"batb":[[0,1.73,103]],"batl":[[0,1.9,42.01],[1,2.3,309.75]],"ltp":0.0,"tv":0.0,"id":8257852}]}]}
{"op":"mcm","clk":"1011545558","pt":1580656681136,"mc":[{"id":"1.168223930","rc":[{"batb":[[0,2.14,47.13],[1,1.01,15.51],[2,2.12,0]],"batl":[[0,2.84,228.62],[1,2.84,0]],"ltp":0.0,"tv":0.0,"id":8444055},{"batb":[[0,1.71,48.47],[1,1.01,15.51],[2,1.01,0]],"batl":[[0,2.3,309.75],[1,2.3,0]],"ltp":0.0,"tv":0.0,"id":8257852}]}]}
{"op":"mcm","clk":"1011546906","pt":1580656686950,"mc":[{"id":"1.168223930","rc":[{"batb":[[0,2.24,41.23],[1,2.18,44.85],[2,1.01,15.51]],"ltp":0.0,"tv":0.0,"id":8444055},{"batb":[[1,1.69,50.51],[2,1.01,15.51]],"ltp":0.0,"tv":0.0,"id":8257852}]}]}
{"op":"mcm","clk":"1011547115","pt":1580656687752,"mc":[{"id":"1.168223930","rc":[{"batb":[[2,2.16,36.13]],"batl":[[0,2.42,29.41],[1,2.84,228.62]],"ltp":0.0,"tv":0.0,"id":8444055},{"batb":[[0,1.71,107.28]],"batl":[[0,1.88,42.01],[1,2.3,309.75]],"ltp":0.0,"tv":0.0,"id":8257852}]}]}
{"op":"mcm","clk":"1011550116","pt":1580656700059,"mc":[{"id":"1.168223930","rc":[{"batb":[[0,2.18,44.85],[1,2.16,36.13],[2,1.01,15.51]],"ltp":0.0,"tv":0.0,"id":8444055},{"batb":[[0,1.71,58.81]],"ltp":0.0,"tv":0.0,"id":8257852}]}]}
{"op":"mcm","clk":"1011550332","pt":1580656700867,"mc":[{"id":"1.168223930","rc":[{"batb":[[1,1.01,15.51],[2,1.01,0]],"batl":[[0,2.84,228.62],[1,2.84,0]],"ltp":0.0,"tv":0.0,"id":8444055},{"batb":[[0,1.69,50.51],[1,1.01,15.51],[2,1.01,0]],"batl":[[0,2.3,309.75],[1,2.3,0]],"ltp":0.0,"tv":0.0,"id":8257852}]}]}
{"op":"mcm","clk":"1011552434","pt":1580656710220,"mc":[{"id":"1.168223930","rc":[{"batb":[[0,2.28,39.42],[1,2.22,42.72],[2,2.18,35.29]],"batl":[[0,2.44,28.57],[1,2.84,228.62]],"ltp":0.0,"tv":0.0,"id":8444055},{"batb":[[0,1.69,111.01],[1,1.67,52.01],[2,1.01,15.51]],"batl":[[0,1.86,42.01],[1,2.3,309.75]],"ltp":0.0,"tv":0.0,"id":8257852}]}]}
{"op":"mcm","clk":"1011555965","pt":1580656725961,"mc":[{"id":"1.168223930","rc":[{"batb":[[0,2.22,42.72],[1,2.18,35.29],[2,1.01,15.51]],"ltp":0.0,"tv":0.0,"id":8444055},{"batb":[[0,1.69,60.49]],"ltp":0.0,"tv":0.0,"id":8257852}]}]}
{"op":"mcm","clk":"1011556241","pt":1580656727184,"mc":[{"id":"1.168223930","rc":[{"batb":[[1,1.01,15.51],[2,1.01,0]],"batl":[[0,2.84,228.62],[1,2.84,0]],"ltp":0.0,"tv":0.0,"id":8444055},{"batb":[[0,1.67,52.01],[1,1.01,15.51],[2,1.01,0]],"batl":[[0,2.3,309.75],[1,2.3,0]],"ltp":0.0,"tv":0.0,"id":8257852}]}]}
{"op":"mcm","clk":"1011556705","pt":1580656729256,"mc":[{"id":"1.168223930","rc":[{"batb":[[0,2.2,43.35]],"ltp":0.0,"tv":0.0,"id":8444055},{"batb":[[0,1.68,51.3]],"ltp":0.0,"tv":0.0,"id":8257852}]}]}
{"op":"mcm","clk":"1011559541","pt":1580656741212,"mc":[{"id":"1.168223930","rc":[{"batb":[[1,2.14,47.29],[2,1.01,15.51]],"ltp":0.0,"tv":0.0,"id":8444055},{"batb":[[0,1.73,46.26],[1,1.71,47.84],[2,1.01,15.51]],"ltp":0.0,"tv":0.0,"id":8257852}]}]}
{"op":"mcm","clk":"1011559650","pt":1580656741750,"mc":[{"id":"1.168223930","rc":[{"batb":[[2,2.12,36.97]],"batl":[[0,2.38,30.25],[1,2.84,228.62]],"ltp":0.0,"tv":0.0,"id":8444055},{"batb":[[1,1.72,57.97],[2,1.71,47.84]],"batl":[[0,1.9,42.01],[1,2.3,309.75]],"ltp":0.0,"tv":0.0,"id":8257852}]}]}
{"op":"mcm","clk":"1011563130","pt":1580656757476,"mc":[{"id":"1.168223930","rc":[{"batb":[[0,2.14,47.29],[1,2.12,36.97],[2,1.01,15.51]],"ltp":0.0,"tv":0.0,"id":8444055},{"batb":[[0,1.72,57.97],[1,1.71,47.84],[2,1.01,15.51]],"ltp":0.0,"tv":0.0,"id":8257852}]}]}
{"op":"mcm","clk":"1011563442","pt":1580656758800,"mc":[{"id":"1.168223930","rc":[{"batb":[[1,1.01,15.51],[2,1.01,0]],"batl":[[0,2.84,228.62],[1,2.84,0]],"ltp":0.0,"tv":0.0,"id":8444055},{"batb":[[0,1.71,47.84],[1,1.01,15.51],[2,1.01,0]],"batl":[[0,2.3,309.75],[1,2.3,0]],"ltp":0.0,"tv":0.0,"id":8257852}]}]}
{"op":"mcm","clk":"1011564657","pt":1580656764186,"mc":[{"id":"1.168223930","rc":[{"batb":[[0,2.24,41.86],[1,2.2,44.22],[2,2.18,35.29]],"batl":[[0,2.44,28.57],[1,2.84,228.62]],"ltp":0.0,"tv":0.0,"id":8444055},{"batb":[[1,1.69,60.49],[2,1.67,52.01]],"batl":[[0,1.87,42.01],[1,2.3,309.75]],"ltp":0.0,"tv":0.0,"id":8257852}]}]}
{"op":"mcm","clk":"1011572968","pt":1580656801257,"mc":[{"id":"1.168223930","rc":[{"batb":[[0,2.24,41.23],[1,2.2,43.59]],"ltp":0.0,"tv":0.0,"id":8444055},{"batb":[[2,1.66,52.72]],"ltp":0.0,"tv":0.0,"id":8257852}]}]}
{"op":"mcm","clk":"1011582935","pt":1580656844817,"mc":[{"id":"1.168223930","rc":[{"batb":[[0,2.2,43.59],[1,1.01,15.51],[2,2.18,0]],"batl":[[0,2.84,228.62],[1,2.84,0]],"ltp":0.0,"tv":0.0,"id":8444055},{"batb":[[0,1.66,52.72],[1,1.01,15.51],[2,1.66,0]],"batl":[[0,2.3,309.75],[1,2.3,0]],"ltp":0.0,"tv":0.0,"id":8257852}]}]}
{"op":"mcm","clk":"1011583609","pt":1580656847736,"mc":[{"id":"1.168223930","rc":[{"batb":[[0,2.22,43.04]],"ltp":0.0,"tv":0.0,"id":8444055}]}]}
{"op":"mcm","clk":"1011587786","pt":1580656865813,"mc":[{"id":"1.168223930","rc":[{"batb":[[1,2.18,44.77],[2,2.14,36.13]],"batl":[[0,2.4,29.41],[1,2.84,228.62]],"ltp":0.0,"tv":0.0,"id":8444055},{"batb":[[0,1.72,46.66],[1,1.71,58.81],[2,1.68,51.14]],"batl":[[0,1.89,42.01],[1,2.3,309.75]],"ltp":0.0,"tv":0.0,"id":8257852}]}]}
{"op":"mcm","clk":"1011591154","pt":1580656880066,"mc":[{"id":"1.168223930","rc":[{"batb":[[0,2.18,44.77],[1,2.14,36.13],[2,1.01,15.51]],"ltp":0.0,"tv":0.0,"id":8444055},{"batb":[[0,1.71,58.81],[1,1.68,51.14],[2,1.01,15.51]],"ltp":0.0,"tv":0.0,"id":8257852}]}]}
{"op":"mcm","clk":"1011591345","pt":1580656881016,"mc":[{"id":"1.168223930","rc":[{"batb":[[1,1.01,15.51],[2,1.01,0]],"batl":[[0,2.84,228.62],[1,2.84,0]],"ltp":0.0,"tv":0.0,"id":8444055},{"batb":[[0,1.68,51.14],[1,1.01,15.51],[2,1.01,0]],"batl":[[0,2.3,309.75],[1,2.3,0]],"ltp":0.0,"tv":0.0,"id":8257852}]}]}
{"op":"mcm","clk":"1011593943","pt":1580656892191,"mc":[{"id":"1.168223930","rc":[{"batb":[[1,2.14,46.97],[2,2.12,36.97]],"batl":[[0,2.38,30.25],[1,2.84,228.62]],"ltp":0.0,"tv":0.0,"id":8444055},{"batb":[[0,1.74,44.85],[1,1.72,57.97],[2,1.71,48.23]],"batl":[[0,1.91,42.01],[1,2.3,309.75]],"ltp":0.0,"tv":0.0,"id":8257852}]}]}
{"op":"mcm","clk":"1011597250","pt":1580656906923,"mc":[{"id":"1.168223930","rc":[{"batb":[[0,2.14,46.97],[1,1.01,15.51],[2,2.12,0]],"batl":[[0,2.84,228.62],[1,2.84,0]],"ltp":0.0,"tv":0.0,"id":8444055},{"batb":[[0,1.71,48.23],[1,1.01,15.51],[2,1.71,0]],"batl":[[0,2.3,309.75],[1,2.3,0]],"ltp":0.0,"tv":0.0,"id":8257852}]}]}
{"op":"mcm","clk":"1011600813","pt":1580656922051,"mc":[{"id":"1.168223930","rc":[{"batb":[[1,2.1,37.81],[2,1.01,15.51]],"batl":[[0,2.34,31.09],[1,2.84,228.62]],"ltp":0.0,"tv":0.0,"id":8444055},{"batb":[[0,1.74,56.29],[1,1.71,48.23],[2,1.01,15.51]],"batl":[[0,1.93,42.01],[1,2.3,309.75]],"ltp":0.0,"tv":0.0,"id":8257852}]}]}
{"op":"mcm","clk":"1011601019","pt":1580656922958,"mc":[{"id":"1.168223930","rc":[{"batb":[[1,2.12,49.1],[2,2.1,37.81]],"ltp":0.0,"tv":0.0,"id":8444055},{"batb":[[0,1.77,43.04],[1,1.74,56.29],[2,1.73,46.5]],"ltp":0.0,"tv":0.0,"id":8257852}]}]}
{"op":"mcm","clk":"1011604067","pt":1580656936073,"mc":[{"id":"1.168223930","rc":[{"batb":[[0,2.12,49.1],[1,2.1,37.81],[2,1.01,15.51]],"ltp":0.0,"tv":0.0,"id":8444055},{"batb":[[0,1.74,56.29],[1,1.73,46.5],[2,1.01,15.51]],"ltp":0.0,"tv":0.0,"id":8257852}]}]}
{"op":"mcm","clk":"1011604256","pt":1580656936878,"mc":[{"id":"1.168223930","rc":[{"batb":[[1,1.01,15.51],[2,1.01,0]],"batl":[[0,2.84,228.62],[1,2.84,0]],"ltp":0.0,"tv":0.0,"id":8444055},{"batb":[[0,1.73,46.5],[1,1.01,15.51],[2,1.01,0]],"batl":[[0,2.3,309.75],[1,2.3,0]],"ltp":0.0,"tv":0.0,"id":8257852}]}]}
{"op":"mcm","clk":"1011606814","pt":1580656948024,"mc":[{"id":"1.168223930","rc":[{"batb":[[1,2.04,40.33],[2,1.01,15.51]],"batl":[[0,2.3,31.93]],"ltp":0.0,"tv":0.0,"id":8444055},{"batb":[[0,1.78,53.77],[1,1.73,46.5],[2,1.01,15.51]],"batl":[[0,1.97,42.01],[1,2.3,309.75]],"ltp":0.0,"tv":0.0,"id":8257852}]}]}
{"op":"mcm","clk":"1011607109","pt":1580656949217,"mc":[{"id":"1.168223930","rc":[{"batb":[[1,2.04,95.01]],"ltp":0.0,"tv":0.0,"id":8444055},{"batb":[[0,1.79,41.23],[1,1.78,53.77],[2,1.76,43.43]],"ltp":0.0,"tv":0.0,"id":8257852}]}]}
{"op":"mcm","clk":"1011607193","pt":1580656949591,"mc":[{"id":"1.168223930","rc":[{"batl":[[1,2.7,245.56]],"ltp":0.0,"tv":0.0,"id":8444055}]}]}
{"op":"mcm","clk":"1011612473","pt":1580656972842,"mc":[{"id":"1.168223930","rc":[{"batb":[[0,2.04,54.68],[1,1.01,15.51],[2,1.01,0]],"batl":[[0,2.7,245.56],[1,2.7,0]],"ltp":0.0,"tv":0.0,"id":8444055},{"batb":[[0,1.76,43.43],[1,1.01,15.51],[2,1.76,0]],"batl":[[0,2.3,309.75],[1,2.3,0]],"ltp":0.0,"tv":0.0,"id":8257852}]}]}
{"op":"mcm","clk":"1011613201","pt":1580656976242,"mc":[{"id":"1.168223930","rc":[{"batb":[[0,2.04,53.9]],"ltp":0.0,"tv":0.0,"id":8444055},{"batb":[[0,1.75,44.06]],"ltp":0.0,"tv":0.0,"id":8257852}]}]}
{"op":"mcm","clk":"1011615757","pt":1580656988109,"mc":[{"id":"1.168223930","rc":[{"batb":[[1,2,42.01],[2,1.98,59.72]],"batl":[[0,2.24,33.61],[1,2.7,245.56]],"ltp":0.0,"tv":0.0,"id":8444055},{"batb":[[0,1.84,37.77],[1,1.81,51.25],[2,1.8,40.13]],"batl":[[0,2,42.01]],"ltp":0.0,"tv":0.0,"id":8257852}]}]}
{"op":"mcm","clk":"1011616107","pt":1580656989814,"mc":[{"id":"1.168223930","rc":[{"batl":[[1,2.6,257.57]],"ltp":0.0,"tv":0.0,"id":8257852}]}]}
{"op":"mcm","clk":"1011618866","pt":1580657001217,"mc":[{"id":"1.168223930","rc":[{"batb":[[0,2,42.01],[1,1.98,59.72],[2,1.01,15.51]],"ltp":0.0,"tv":0.0,"id":8444055},{"batb":[[0,1.81,51.25],[1,1.8,40.13],[2,1.01,15.51]],"ltp":0.0,"tv":0.0,"id":8257852}]}]}
{"op":"mcm","clk":"1011619305","pt":1580657002953,"mc":[{"id":"1.168223930","rc":[{"batb":[[0,1.98,59.72],[1,1.01,15.51],[2,1.01,0]],"batl":[[0,2.7,245.56],[1,2.7,0]],"ltp":0.0,"tv":0.0,"id":8444055},{"batb":[[0,1.8,40.13],[1,1.01,15.51],[2,1.01,0]],"batl":[[0,2.6,257.57],[1,2.6,0]],"ltp":0.0,"tv":0.0,"id":8257852}]}]}
{"op":"mcm","clk":"1011619557","pt":1580657004133,"mc":[{"id":"1.168223930","rc":[{"batb":[[0,1.99,59.09],[1,1.98,59.72],[2,1.01,15.51]],"ltp":0.0,"tv":0.0,"id":8444055}]}]}
{"op":"mcm","clk":"1011619763","pt":1580657005019,"mc":[{"id":"1.168223930","rc":[{"batb":[[1,1.01,15.51],[2,1.01,0]],"ltp":0.0,"tv":0.0,"id":8444055}]}]}
{"op":"mcm","clk":"1011625510","pt":1580657031144,"mc":[{"id":"1.168223930","rc":[{"batb":[[0,1.99,58.93],[1,1.92,33.2],[2,1.01,15.51]],"ltp":0.0,"tv":0.0,"id":8444055},{"batb":[[0,1.89,34.62],[1,1.86,36.51],[2,1.01,15.51]],"ltp":0.0,"tv":0.0,"id":8257852}]}]}
{"op":"mcm","clk":"1011625728","pt":1580657032056,"mc":[{"id":"1.168223930","rc":[{"batb":[[1,1.96,43.69],[2,1.92,33.2]],"batl":[[0,2.18,35.29],[1,2.7,245.56]],"ltp":0.0,"tv":0.0,"id":8444055},{"batb":[[2,1.85,48.73]],"batl":[[0,2.04,40.33],[1,2.6,257.57]],"ltp":0.0,"tv":0.0,"id":8257852}]}]}
{"op":"mcm","clk":"1011629456","pt":1580657049065,"mc":[{"id":"1.168223930","rc":[{"batb":[[0,1.92,33.2],[1,1.01,15.51],[2,1.92,0]],"batl":[[0,2.7,245.56],[1,2.7,0]],"ltp":0.0,"tv":0.0,"id":8444055},{"batb":[[0,1.86,36.51],[1,1.01,15.51],[2,1.85,0]],"batl":[[0,2.6,257.57],[1,2.6,0]],"ltp":0.0,"tv":0.0,"id":8257852}]}]}
{"op":"mcm","clk":"1011630328","pt":1580657053174,"mc":[{"id":"1.168223930","rc":[{"batb":[[0,1.92,33.05]],"ltp":0.0,"tv":0.0,"id":8444055},{"batb":[[0,1.85,37.14]],"ltp":0.0,"tv":0.0,"id":8257852}]}]}
{"op":"mcm","clk":"1011634256","pt":1580657071094,"mc":[{"id":"1.168223930","rc":[{"batb":[[1,1.85,36.82],[2,1.01,15.51]],"ltp":0.0,"tv":0.0,"id":8444055},{"batb":[[0,1.96,61.77],[1,1.93,32.65],[2,1.85,37.14]],"ltp":0.0,"tv":0.0,"id":8257852}]}]}
{"op":"mcm","clk":"1011634515","pt":1580657072140,"mc":[{"id":"1.168223930","rc":[{"batb":[[1,1.91,45.37],[2,1.85,36.82]],"batl":[[0,2.14,36.13]],"ltp":0.0,"tv":0.0,"id":8444055},{"batb":[[2,1.9,46.21]],"batl":[[0,2.1,37.81],[1,2.6,257.57]],"ltp":0.0,"tv":0.0,"id":8257852}]}]}
{"op":"mcm","clk":"1011634658","pt":1580657072753,"mc":[{"id":"1.168223930","rc":[{"batl":[[1,2.52,270.1]],"ltp":0.0,"tv":0.0,"id":8444055}]}]}
{"op":"mcm","clk":"1011637686","pt":1580657085845,"mc":[{"id":"1.168223930","rc":[{"batb":[[0,1.91,45.37],[1,1.85,36.82],[2,1.01,15.51]],"ltp":0.0,"tv":0.0,"id":8444055},{"batb":[[0,1.93,32.65],[1,1.9,46.21],[2,1.01,15.51]],"ltp":0.0,"tv":0.0,"id":8257852}]}]}
{"op":"mcm","clk":"1011637934","pt":1580657086947,"mc":[{"id":"1.168223930","rc":[{"batb":[[0,1.85,36.82],[1,1.01,15.51],[2,1.01,0]],"batl":[[0,2.52,270.1],[1,2.52,0]],"ltp":0.0,"tv":0.0,"id":8444055},{"batb":[[1,1.01,15.51],[2,1.01,0]],"batl":[[0,2.6,257.57],[1,2.6,0]],"ltp":0.0,"tv":0.0,"id":8257852}]}]}
{"op":"mcm","clk":"1011639630","pt":1580657094261,"mc":[{"id":"1.168223930","rc":[{"batb":[[0,1.95,62.63],[1,1.93,44.53],[2,1.88,35.25]],"batl":[[0,2.16,36.13],[1,2.52,270.1]],"ltp":0.0,"tv":0.0,"id":8444055},{"batb":[[1,1.88,82.06],[2,1.01,15.51]],"batl":[[0,2.08,38.65],[1,2.6,257.57]],"ltp":0.0,"tv":0.0,"id":8257852}]}]}
{"op":"mcm","clk":"1011643028","pt":1580657108942,"mc":[{"id":"1.168223930","rc":[{"batb":[[0,1.88,35.25],[1,1.01,15.51],[2,1.88,0]],"batl":[[0,2.52,270.1],[1,2.52,0]],"ltp":0.0,"tv":0.0,"id":8444055},{"batb":[[0,1.88,35.01],[1,1.01,15.51],[2,1.01,0]],"batl":[[0,2.6,257.57],[1,2.6,0]],"ltp":0.0,"tv":0.0,"id":8257852}]}]}
{"op":"mcm","clk":"1011643657","pt":1580657111952,"mc":[{"id":"1.168223930","rc":[{"batb":[[0,1.87,35.64]],"ltp":0.0,"tv":0.0,"id":8444055},{"batb":[[0,1.89,34.54]],"ltp":0.0,"tv":0.0,"id":8257852}]}]}
{"op":"mcm","clk":"1011644713","pt":1580657116204,"mc":[{"id":"1.168223930","rc":[{"batb":[[0,1.99,59.09],[1,1.95,43.69],[2,1.9,34.31]],"batl":[[0,2.18,35.29],[1,2.52,270.1]],"ltp":0.0,"tv":0.0,"id":8444055},{"batb":[[1,1.86,48.73],[2,1.84,37.92]],"batl":[[0,2.06,39.49],[1,2.6,257.57]],"ltp":0.0,"tv":0.0,"id":8257852}]}]}
{"op":"mcm","clk":"1011647103","pt":1580657127011,"mc":[{"id":"1.168223930","rc":[{"batb":[[0,1.9,34.31],[1,1.01,15.51],[2,1.9,0]],"batl":[[0,2.52,270.1],[1,2.52,0]],"ltp":0.0,"tv":0.0,"id":8444055},{"batb":[[0,1.84,37.92],[1,1.01,15.51],[2,1.84,0]],"batl":[[0,2.6,257.57],[1,2.6,0]],"ltp":0.0,"tv":0.0,"id":8257852}]}]}
{"op":"mcm","clk":"1011650374","pt":1580657142065,"mc":[{"id":"1.168223930","rc":[{"batb":[[0,2.06,53.66],[1,1.97,42.85],[2,1.96,61.53]],"batl":[[0,2.22,33.61],[1,2.52,270.1]],"ltp":0.0,"tv":0.0,"id":8444055},{"batb":[[0,1.84,87.5],[1,1.81,40.13],[2,1.01,15.51]],"batl":[[0,2.02,41.17],[1,2.6,257.57]],"ltp":0.0,"tv":0.0,"id":8257852}]}]}
{"op":"mcm","clk":"1011653329","pt":1580657156077,"mc":[{"id":"1.168223930","rc":[{"batb":[[0,1.97,42.85],[1,1.96,61.53],[2,1.01,15.51]],"ltp":0.0,"tv":0.0,"id":8444055},{"batb":[[0,1.84,49.57]],"ltp":0.0,"tv":0.0,"id":8257852}]}]}
{"op":"mcm","clk":"1011653530","pt":1580657156950,"mc":[{"id":"1.168223930","rc":[{"batb":[[0,1.96,61.53],[1,1.01,15.51],[2,1.01,0]],"batl":[[0,2.52,270.1],[1,2.52,0]],"ltp":0.0,"tv":0.0,"id":8444055},{"batb":[[0,1.81,40.13],[1,1.01,15.51],[2,1.01,0]],"batl":[[0,2.6,257.57],[1,2.6,0]],"ltp":0.0,"tv":0.0,"id":8257852}]}]}
{"op":"mcm","clk":"1011655373","pt":1580657166257,"mc":[{"id":"1.168223930","rc":[{"batb":[[0,2.1,50.59],[1,2.02,56.41],[2,2,42.01]],"batl":[[0,2.24,33.61],[1,2.52,270.1]],"ltp":0.0,"tv":0.0,"id":8444055},{"batb":[[0,1.82,50.41],[1,1.81,40.13],[2,1.77,42.41]],"batl":[[0,2,42.01],[1,2.6,257.57]],"ltp":0.0,"tv":0.0,"id":8257852}]}]}
{"op":"mcm","clk":"1011658147","pt":1580657178153,"mc":[{"id":"1.168223930","rc":[{"batb":[[0,2.02,56.41],[1,2,42.01],[2,1.01,15.51]],"ltp":0.0,"tv":0.0,"id":8444055},{"batb":[[1,1.77,42.41],[2,1.01,15.51]],"ltp":0.0,"tv":0.0,"id":8257852}]}]}
{"op":"mcm","clk":"1011658290","pt":1580657178872,"mc":[{"id":"1.168223930","rc":[{"batb":[[1,1.01,15.51],[2,1.01,0]],"batl":[[0,2.52,270.1],[1,2.52,0]],"ltp":0.0,"tv":0.0,"id":8444055},{"batb":[[0,1.77,42.41],[1,1.01,15.51],[2,1.01,0]],"batl":[[0,2.6,257.57],[1,2.6,0]],"ltp":0.0,"tv":0.0,"id":8257852}]}]}
{"op":"mcm","clk":"1011662930","pt":1580657200195,"mc":[{"id":"1.168223930","rc":[{"batb":[[1,1.98,42.85],[2,1.01,15.51]],"batl":[[0,2.2,34.45],[1,2.52,270.1]],"ltp":0.0,"tv":0.0,"id":8444055},{"batb":[[0,1.83,50.41],[1,1.77,42.41],[2,1.01,15.51]],"batl":[[0,2.04,40.33],[1,2.6,257.57]],"ltp":0.0,"tv":0.0,"id":8257852}]}]}
{"op":"mcm","clk":"1011663146","pt":1580657201218,"mc":[{"id":"1.168223930","rc":[{"batb":[[1,1.97,42.85],[2,1.94,31.79]],"batl":[[0,2.18,35.29]],"ltp":0.0,"tv":0.0,"id":8444055},{"batb":[[0,1.87,36.12],[1,1.84,49.57],[2,1.83,38.63]],"ltp":0.0,"tv":0.0,"id":8257852}]}]}
{"op":"mcm","clk":"1011666432","pt":1580657216253,"mc":[{"id":"1.168223930","rc":[{"batb":[[0,1.97,42.85],[1,1.94,31.79],[2,1.01,15.51]],"ltp":0.0,"tv":0.0,"id":8444055},{"batb":[[0,1.84,49.57],[1,1.83,38.63],[2,1.01,15.51]],"ltp":0.0,"tv":0.0,"id":8257852}]}]}
{"op":"mcm","clk":"1011666694","pt":1580657217271,"mc":[{"id":"1.168223930","rc":[{"batb":[[0,1.94,31.79],[1,1.01,15.51],[2,1.01,0]],"batl":[[0,2.52,270.1],[1,2.52,0]],"ltp":0.0,"tv":0.0,"id":8444055},{"batb":[[0,1.83,38.63],[1,1.01,15.51],[2,1.01,0]],"batl":[[0,2.6,257.57],[1,2.6,0]],"ltp":0.0,"tv":0.0,"id":8257852}]}]}
{"op":"mcm","clk":"1011672680","pt":1580657244179,"mc":[{"id":"1.168223930","rc":[{"batb":[[0,2.06,52.56],[1,2.02,562.24],[2,1.99,100.86]],"batl":[[0,2.22,33.61],[1,2.52,270.1]],"ltp":0.0,"tv":0.0,"id":8444055},{"batb":[[1,1.82,50.41],[2,1.8,40.44]],"batl":[[0,2.02,41.17],[1,2.6,257.57]],"ltp":0.0,"tv":0.0,"id":8257852}]}]}
{"op":"mcm","clk":"1011678786","pt":1580657272124,"mc":[{"id":"1.168223930","rc":[{"batb":[[1,1.99,100.86],[2,1.01,15.51]],"ltp":0.0,"tv":0.0,"id":8444055}]}]}
{"op":"mcm","clk":"1011678978","pt":1580657272944,"mc":[{"id":"1.168223930","rc":[{"batb":[[0,1.99,58.85],[1,1.01,15.51],[2,1.01,0]],"batl":[[0,2.52,270.1],[1,2.52,0]],"ltp":0.0,"tv":0.0,"id":8444055},{"batb":[[0,1.8,40.44],[1,1.01,15.51],[2,1.8,0]],"batl":[[0,2.6,257.57],[1,2.6,0]],"ltp":0.0,"tv":0.0,"id":8257852}]}]}
{"op":"mcm","clk":"1011679737","pt":1580657276226,"mc":[{"id":"1.168223930","rc":[{"batb":[[0,2,58.7]],"ltp":0.0,"tv":0.0,"id":8444055}]}]}
{"op":"mcm","clk":"1011685882","pt":1580657304221,"mc":[{"id":"1.168223930","rc":[{"batb":[[0,2.1,49.96],[1,2.06,52.87],[2,2.04,142.45]],"batl":[[0,2.28,32.77],[1,2.52,270.1]],"ltp":0.0,"tv":0.0,"id":8444055},{"batb":[[1,1.78,53.77],[2,1.75,44.69]],"batl":[[0,1.98,42.01],[1,2.6,257.57]],"ltp":0.0,"tv":0.0,"id":8257852}]}]}
{"op":"mcm","clk":"1011695892","pt":1580657348703,"mc":[{"id":"1.168223930","rc":[{"batb":[[0,2.12,49.33],[1,2.08,52.17]],"ltp":0.0,"tv":0.0,"id":8444055},{"batb":[[0,1.79,41.07],[2,1.74,45.16]],"ltp":0.0,"tv":0.0,"id":8257852}]}]}
{"op":"mcm","clk":"1011705830","pt":1580657394993,"mc":[{"id":"1.168223930","rc":[{"batb":[[0,2.08,52.17],[1,1.01,15.51],[2,2.04,0]],"batl":[[0,2.52,270.1],[1,2.52,0]],"ltp":0.0,"tv":0.0,"id":8444055},{"batb":[[0,1.74,45.16],[1,1.01,15.51],[2,1.74,0]],"batl":[[0,2.6,257.57],[1,2.6,0]],"ltp":0.0,"tv":0.0,"id":8257852}]}]}
{"op":"mcm","clk":"1011710570","pt":1580657415962,"mc":[{"id":"1.168223930","rc":[{"batb":[[0,2.08,90.82]],"batl":[[0,2.32,31.09]],"ltp":0.0,"tv":0.0,"id":8444055},{"batb":[[0,1.75,55.45],[1,1.74,45.16],[2,1.01,15.51]],"batl":[[0,1.94,42.01]],"ltp":0.0,"tv":0.0,"id":8257852}]}]}
{"op":"mcm","clk":"1011710751","pt":1580657416765,"mc":[{"id":"1.168223930","rc":[{"batb":[[0,2.18,44.53],[1,2.14,47.13],[2,2.08,38.65]],"ltp":0.0,"tv":0.0,"id":8444055},{"batb":[[2,1.68,50.59]],"ltp":0.0,"tv":0.0,"id":8257852}]}]}
{"op":"mcm","clk":"1011711098","pt":1580657418176,"mc":[{"id":"1.168223930","rc":[{"batl":[[1,2.4,289.78]],"ltp":0.0,"tv":0.0,"id":8257852}]}]}
{"op":"mcm","clk":"1011711211","pt":1580657418663,"mc":[{"id":"1.168223930","rc":[{"batl":[[1,2.84,228.62]],"ltp":0.0,"tv":0.0,"id":8444055}]}]}
{"op":"mcm","clk":"1011711875","pt":1580657421813,"mc":[{"id":"1.168223930","rc":[{"batl":[[0,2.84,228.62],[1,2.84,0]],"ltp":0.0,"tv":0.0,"id":8444055},{"batl":[[0,2.4,289.78],[1,2.4,0]],"ltp":0.0,"tv":0.0,"id":8257852}]}]}
{"op":"mcm","clk":"1011712405","pt":1580657424198,"mc":[{"id":"1.168223930","rc":[{"batl":[[0,2.36,30.25],[1,2.84,228.62]],"ltp":0.0,"tv":0.0,"id":8444055},{"batl":[[0,1.92,42.01],[1,2.4,289.78]],"ltp":0.0,"tv":0.0,"id":8257852}]}]}
{"op":"mcm","clk":"1011714346","pt":1580657432997,"mc":[{"id":"1.168223930","rc":[{"batb":[[0,2.14,47.13],[1,1.01,15.51],[2,2.08,0]],"batl":[[0,2.84,228.62],[1,2.84,0]],"ltp":0.0,"tv":0.0,"id":8444055},{"batb":[[0,1.68,50.59],[1,1.01,15.51],[2,1.68,0]],"batl":[[0,2.4,289.78],[1,2.4,0]],"ltp":0.0,"tv":0.0,"id":8257852}]}]}
{"op":"mcm","clk":"1011714920","pt":1580657435693,"mc":[{"id":"1.168223930","rc":[{"batb":[[0,2.16,46.42]],"ltp":0.0,"tv":0.0,"id":8444055}]}]}
{"op":"mcm","clk":"1011717278","pt":1580657446221,"mc":[{"id":"1.168223930","rc":[{"batb":[[0,2.3,38.79],[1,2.24,41.54],[2,2.14,36.13]],"batl":[[0,2.42,29.41],[1,2.84,228.62]],"ltp":0.0,"tv":0.0,"id":8444055},{"batb":[[0,1.71,58.81],[1,1.68,50.59],[2,1.63,56.57]],"batl":[[0,1.89,42.01]],"ltp":0.0,"tv":0.0,"id":8257852}]}]}
{"op":"mcm","clk":"1011717803","pt":1580657448627,"mc":[{"id":"1.168223930","rc":[{"batl":[[1,2.3,309.75]],"ltp":0.0,"tv":0.0,"id":8257852}]}]}
{"op":"mcm","clk":"1011718570","pt":1580657452070,"mc":[{"id":"1.168223930","rc":[{"batl":[[0,2.3,309.75],[1,2.3,0]],"ltp":0.0,"tv":0.0,"id":8257852}]}]}
{"op":"mcm","clk":"1011719148","pt":1580657454953,"mc":[{"id":"1.168223930","rc":[{"batl":[[0,1.88,42.01],[1,2.3,309.75]],"ltp":0.0,"tv":0.0,"id":8257852}]}]}
{"op":"mcm","clk":"1011720957","pt":1580657463078,"mc":[{"id":"1.168223930","rc":[{"batb":[[0,2.24,41.54],[1,1.01,15.51],[2,2.14,0]],"batl":[[0,2.84,228.62],[1,2.84,0]],"ltp":0.0,"tv":0.0,"id":8444055},{"batb":[[0,1.63,56.57],[1,1.01,15.51],[2,1.63,0]],"batl":[[0,2.3,309.75],[1,2.3,0]],"ltp":0.0,"tv":0.0,"id":8257852}]}]}
{"op":"mcm","clk":"1011722488","pt":1580657470183,"mc":[{"id":"1.168223930","rc":[{"batb":[[1,2.18,44.46],[2,2.12,36.97]],"batl":[[0,2.38,30.25],[1,2.84,228.62]],"ltp":0.0,"tv":0.0,"id":8444055},{"batb":[[0,1.72,57.97],[1,1.71,48.15],[2,1.66,53.58]],"batl":[[0,1.91,42.01],[1,2.3,309.75]],"ltp":0.0,"tv":0.0,"id":8257852}]}]}
{"op":"mcm","clk":"1011722719","pt":1580657471250,"mc":[{"id":"1.168223930","rc":[{"batl":[[0,2.3,309.75],[1,2.3,0]],"ltp":0.0,"tv":0.0,"id":8257852}]}]}
{"op":"mcm","clk":"1011723319","pt":1580657474150,"mc":[{"id":"1.168223930","rc":[{"batl":[[0,1.91,42.01],[1,2.3,309.75]],"ltp":0.0,"tv":0.0,"id":8257852}]}]}
{"op":"mcm","clk":"1011724245","pt":1580657478167,"mc":[{"id":"1.168223930","rc":[{"batl":[[1,2.3,0]],"ltp":0.0,"tv":0.0,"id":8257852}]}]}
{"op":"mcm","clk":"1011724700","pt":1580657480094,"mc":[{"id":"1.168223930","rc":[{"batl":[[1,2.84,0]],"ltp":0.0,"tv":0.0,"id":8444055}]}]}
{"op":"mcm","clk":"1011725577","pt":1580657483823,"mc":[{"id":"1.168223930","rc":[{"batb":[[0,2.18,44.46],[1,2.12,36.97],[2,1.01,15.51]],"ltp":0.0,"tv":0.0,"id":8444055},{"batb":[[1,1.66,53.58],[2,1.01,15.51]],"ltp":0.0,"tv":0.0,"id":8257852}]}]}
{"op":"mcm","clk":"1011725848","pt":1580657485105,"mc":[{"id":"1.168223930","rc":[{"batb":[[1,1.01,15.51],[2,1.01,0]],"ltp":0.0,"tv":0.0,"id":8444055},{"batb":[[0,1.66,53.58],[1,1.01,15.51],[2,1.01,0]],"ltp":0.0,"tv":0.0,"id":8257852}]}]}
{"op":"mcm","clk":"1011729174","pt":1580657500243,"mc":[{"id":"1.168223930","rc":[{"batb":[[0,2.34,36.98],[1,2.28,39.73],[2,2.18,35.29]],"batl":[[0,2.44,28.57]],"ltp":0.0,"tv":0.0,"id":8444055},{"batb":[[0,1.69,60.49],[1,1.66,53.58],[2,1.6,60.03]],"batl":[[0,1.87,42.01]],"ltp":0.0,"tv":0.0,"id":8257852}]}]}
{"op":"mcm","clk":"1011731685","pt":1580657511264,"mc":[{"id":"1.168223930","rc":[{"batl":[[0,1.86,42.01]],"ltp":0.0,"tv":0.0,"id":8257852}]}]}
{"op":"mcm","clk":"1011732655","pt":1580657515170,"mc":[{"id":"1.168223930","rc":[{"batl":[[0,1.85,42.01]],"ltp":0.0,"tv":0.0,"id":8257852}]}]}
{"op":"mcm","clk":"1011734299","pt":1580657522104,"mc":[{"id":"1.168223930","rc":[{"batb":[[0,2.28,39.73],[1,2.18,35.29],[2,1.01,15.51]],"ltp":0.0,"tv":0.0,"id":8444055},{"batb":[[1,1.6,60.03],[2,1.01,15.51]],"ltp":0.0,"tv":0.0,"id":8257852}]}]}
{"op":"mcm","clk":"1011734571","pt":1580657523235,"mc":[{"id":"1.168223930","rc":[{"batb":[[1,1.01,15.51],[2,1.01,0]],"ltp":0.0,"tv":0.0,"id":8444055},{"batb":[[0,1.6,60.03],[1,1.01,15.51],[2,1.01,0]],"ltp":0.0,"tv":0.0,"id":8257852}]}]}
{"op":"mcm","clk":"1011738573","pt":1580657541228,"mc":[{"id":"1.168223930","rc":[{"batb":[[1,2.22,43.12],[2,1.01,15.51]],"ltp":0.0,"tv":0.0,"id":8444055},{"batb":[[0,1.69,50.12],[1,1.63,57.04],[2,1.6,60.03]],"ltp":0.0,"tv":0.0,"id":8257852}]}]}
{"op":"mcm","clk":"1011738735","pt":1580657541997,"mc":[{"id":"1.168223930","rc":[{"batb":[[2,2.18,35.29]],"batl":[[0,2.44,28.57]],"ltp":0.0,"tv":0.0,"id":8444055},{"batb":[[0,1.69,110.61],[1,1.63,215.27],[2,1.01,15.51]],"batl":[[0,1.87,42.01]],"ltp":0.0,"tv":0.0,"id":8257852}]}]}
{"op":"mcm","clk":"1011738827","pt":1580657542429,"mc":[{"id":"1.168223930","rc":[{"batb":[[2,1.01,15.51]],"ltp":0.0,"tv":0.0,"id":8444055},{"batb":[[0,1.69,50.12],[1,1.63,57.04]],"ltp":0.0,"tv":0.0,"id":8257852}]}]}
{"op":"mcm","clk":"1011739093","pt":1580657543634,"mc":[{"id":"1.168223930","rc":[{"batb":[[2,2.16,36.13]],"ltp":0.0,"tv":0.0,"id":8444055},{"batb":[[0,1.7,59.65],[1,1.69,50.12],[2,1.63,57.04]],"ltp":0.0,"tv":0.0,"id":8257852}]}]}
{"op":"mcm","clk":"1011743151","pt":1580657561750,"mc":[{"id":"1.168223930","rc":[{"batb":[[0,2.22,43.12],[1,2.16,36.13],[2,1.01,15.51]],"ltp":0.0,"tv":0.0,"id":8444055},{"batb":[[1,1.63,57.04],[2,1.01,15.51]],"ltp":0.0,"tv":0.0,"id":8257852}]}]}
{"op":"mcm","clk":"1011743438","pt":1580657563041,"mc":[{"id":"1.168223930","rc":[{"batb":[[1,1.01,15.51],[2,1.01,0]],"ltp":0.0,"tv":0.0,"id":8444055},{"batb":[[0,1.63,57.04],[1,1.01,15.51],[2,1.01,0]],"ltp":0.0,"tv":0.0,"id":8257852}]}]}
{"op":"mcm","clk":"1011746043","pt":1580657575270,"mc":[{"id":"1.168223930","rc":[{"batb":[[0,1.66,155.28],[1,1.63,57.04],[2,1.01,15.51]],"ltp":0.0,"tv":0.0,"id":8257852}]}]}
{"op":"mcm","clk":"1011746275","pt":1580657576267,"mc":[{"id":"1.168223930","rc":[{"batb":[[1,2.16,82.47],[2,1.01,15.51]],"batl":[[0,2.42,29.41]],"ltp":0.0,"tv":0.0,"id":8444055},{"batb":[[0,1.73,46.58],[1,1.71,58.81],[2,1.67,52.09]],"batl":[[0,1.88,42.01]],"ltp":0.0,"tv":0.0,"id":8257852}]}]}
{"op":"mcm","clk":"1011746491","pt":1580657577180,"mc":[{"id":"1.168223930","rc":[{"batb":[[1,2.16,46.34]],"ltp":0.0,"tv":0.0,"id":8444055}]}]}
{"op":"mcm","clk":"1011746735","pt":1580657578167,"mc":[{"id":"1.168223930","rc":[{"batb":[[2,2.14,36.13]],"batl":[[0,2.4,29.41]],"ltp":0.0,"tv":0.0,"id":8444055}]}]}
{"op":"mcm","clk":"1011750185","pt":1580657593195,"mc":[{"id":"1.168223930","rc":[{"batb":[[0,2.16,46.34],[1,1.01,15.51],[2,2.14,0]],"ltp":0.0,"tv":0.0,"id":8444055},{"batb":[[0,1.67,52.09],[1,1.01,15.51],[2,1.67,0]],"ltp":0.0,"tv":0.0,"id":8257852}]}]}
{"op":"mcm","clk":"1011752537","pt":1580657603168,"mc":[{"id":"1.168223930","rc":[{"batb":[[1,2.12,48.7],[2,1.01,15.51]],"ltp":0.0,"tv":0.0,"id":8444055},{"batb":[[0,1.76,43.59],[1,1.71,48.47],[2,1.01,15.51]],"ltp":0.0,"tv":0.0,"id":8257852}]}]}
{"op":"mcm","clk":"1011752802","pt":1580657604182,"mc":[{"id":"1.168223930","rc":[{"batb":[[1,2.12,85.67]],"batl":[[0,2.36,30.25]],"ltp":0.0,"tv":0.0,"id":8444055},{"batb":[[1,1.73,57.13],[2,1.71,48.47]],"batl":[[0,1.91,42.01]],"ltp":0.0,"tv":0.0,"id":8257852}]}]}
{"op":"mcm","clk":"1011755145","pt":1580657614206,"mc":[{"id":"1.168223930","rc":[{"batb":[[0,2.12,85.67],[1,1.01,15.51],[2,1.01,0]],"ltp":0.0,"tv":0.0,"id":8444055},{"batb":[[0,1.73,57.13],[1,1.71,48.47],[2,1.01,15.51]],"ltp":0.0,"tv":0.0,"id":8257852}]}]}
{"op":"mcm","clk":"1011755333","pt":1580657615014,"mc":[{"id":"1.168223930","rc":[{"batb":[[0,2.12,48.7]],"ltp":0.0,"tv":0.0,"id":8444055},{"batb":[[0,1.71,48.47],[1,1.01,15.51],[2,1.01,0]],"ltp":0.0,"tv":0.0,"id":8257852}]}]}
{"op":"mcm","clk":"1011756610","pt":1580657620220,"mc":[{"id":"1.168223930","rc":[{"batb":[[1,2.08,38.65],[2,2.04,54.21]],"batl":[[0,2.32,31.09]],"ltp":0.0,"tv":0.0,"id":8444055},{"batb":[[0,1.79,41.62],[1,1.77,53.77],[2,1.76,43.75]],"batl":[[0,1.94,42.01]],"ltp":0.0,"tv":0.0,"id":8257852}]}]}
{"op":"mcm","clk":"1011756816","pt":1580657621147,"mc":[{"id":"1.168223930","rc":[{"batb":[[1,2.04,54.21],[2,1.01,15.51]],"ltp":0.0,"tv":0.0,"id":8444055}]}]}
{"op":"mcm","clk":"1011757068","pt":1580657622222,"mc":[{"id":"1.168223930","rc":[{"batb":[[1,2.06,39.49],[2,2.04,54.21]],"ltp":0.0,"tv":0.0,"id":8444055}]}]}
{"op":"mcm","clk":"1011757218","pt":1580657622923,"mc":[{"id":"1.168223930","rc":[{"batl":[[1,2.7,245.56]],"ltp":0.0,"tv":0.0,"id":8444055}]}]}
{"op":"mcm","clk":"1011761815","pt":1580657642189,"mc":[{"id":"1.168223930","rc":[{"batb":[[0,2.06,39.49],[1,2.04,54.21],[2,1.01,15.51]],"ltp":0.0,"tv":0.0,"id":8444055},{"batb":[[0,1.77,53.77],[1,1.76,43.75],[2,1.01,15.51]],"ltp":0.0,"tv":0.0,"id":8257852}]}]}
{"op":"mcm","clk":"1011762024","pt":1580657643073,"mc":[{"id":"1.168223930","rc":[{"batb":[[0,2.04,54.21],[1,1.01,15.51],[2,1.01,0]],"batl":[[0,2.7,245.56],[1,2.7,0]],"ltp":0.0,"tv":0.0,"id":8444055},{"batb":[[0,1.76,43.75],[1,1.01,15.51],[2,1.01,0]],"ltp":0.0,"tv":0.0,"id":8257852}]}]}
{"op":"mcm","clk":"1011763151","pt":1580657648061,"mc":[{"id":"1.168223930","rc":[{"batb":[[0,2.16,45.95],[1,2.1,37.81],[2,2.08,51.38]],"batl":[[0,2.34,31.09],[1,2.7,245.56]],"ltp":0.0,"tv":0.0,"id":8444055},{"batb":[[0,1.76,98.36],[1,1.73,46.26],[2,1.01,15.51]],"batl":[[0,1.93,42.01]],"ltp":0.0,"tv":0.0,"id":8257852}]}]}
{"op":"mcm","clk":"1011765712","pt":1580657659268,"mc":[{"id":"1.168223930","rc":[{"batb":[[0,2.1,37.81],[1,2.08,51.38],[2,1.01,15.51]],"ltp":0.0,"tv":0.0,"id":8444055},{"batb":[[0,1.76,54.61]],"ltp":0.0,"tv":0.0,"id":8257852}]}]}
{"op":"mcm","clk":"1011766088","pt":1580657661062,"mc":[{"id":"1.168223930","rc":[{"batb":[[0,2.08,51.38],[1,1.01,15.51],[2,1.01,0]],"batl":[[0,2.7,245.56],[1,2.7,0]],"ltp":0.0,"tv":0.0,"id":8444055},{"batb":[[0,1.73,46.26],[1,1.01,15.51],[2,1.01,0]],"ltp":0.0,"tv":0.0,"id":8257852}]}]}
{"op":"mcm","clk":"1011768540","pt":1580657672166,"mc":[{"id":"1.168223930","rc":[{"batb":[[0,2.2,43.43],[1,2.12,85.28],[2,2.08,93.56]],"batl":[[0,2.38,30.25],[1,2.7,245.56]],"ltp":0.0,"tv":0.0,"id":8444055},{"batb":[[0,1.73,103.4],[1,1.71,48.47],[2,1.01,15.51]],"batl":[[0,1.91,42.01]],"ltp":0.0,"tv":0.0,"id":8257852}]}]}
{"op":"mcm","clk":"1011768599","pt":1580657672379,"mc":[{"id":"1.168223930","rc":[{"batb":[[2,1.01,15.51]],"ltp":0.0,"tv":0.0,"id":8444055}]}]}
{"op":"mcm","clk":"1011771596","pt":1580657686161,"mc":[{"id":"1.168223930","rc":[{"batb":[[0,2.12,85.28],[1,1.01,15.51],[2,1.01,0]],"ltp":0.0,"tv":0.0,"id":8444055},{"batb":[[0,1.73,57.13]],"ltp":0.0,"tv":0.0,"id":8257852}]}]}
{"op":"mcm","clk":"1011771780","pt":1580657687090,"mc":[{"id":"1.168223930","rc":[{"batb":[[0,2.12,48.31]],"batl":[[0,2.7,245.56],[1,2.7,0]],"ltp":0.0,"tv":0.0,"id":8444055},{"batb":[[0,1.71,47.92],[1,1.01,15.51],[2,1.01,0]],"ltp":0.0,"tv":0.0,"id":8257852}]}]}
{"op":"mcm","clk":"1011776186","pt":1580657706958,"mc":[{"id":"1.168223930","rc":[{"batb":[[1,2.04,54.29],[2,1.01,15.51]],"ltp":0.0,"tv":0.0,"id":8444055},{"batb":[[0,1.79,41.47],[1,1.76,43.75],[2,1.73,149.02]],"ltp":0.0,"tv":0.0,"id":8257852}]}]}
{"op":"mcm","clk":"1011776435","pt":1580657708110,"mc":[{"id":"1.168223930","rc":[{"batb":[[1,2.06,39.49],[2,2.04,54.29]],"batl":[[0,2.32,31.09],[1,2.7,245.56]],"ltp":0.0,"tv":0.0,"id":8444055},{"batb":[[1,1.76,98.36]],"batl":[[0,1.95,42.01]],"ltp":0.0,"tv":0.0,"id":8257852}]}]}
{"op":"mcm","clk":"1011776507","pt":1580657708370,"mc":[{"id":"1.168223930","rc":[{"batb":[[2,1.01,15.51]],"ltp":0.0,"tv":0.0,"id":8257852}]}]}
{"op":"mcm","clk":"1011779283","pt":1580657721236,"mc":[{"id":"1.168223930","rc":[{"batb":[[0,2.06,39.49],[1,2.04,54.29],[2,1.01,15.51]],"ltp":0.0,"tv":0.0,"id":8444055},{"batb":[[0,1.76,98.36],[1,1.01,15.51],[2,1.01,0]],"ltp":0.0,"tv":0.0,"id":8257852}]}]}
{"op":"mcm","clk":"1011779640","pt":1580657723009,"mc":[{"id":"1.168223930","rc":[{"batb":[[0,2.04,54.29],[1,1.01,15.51],[2,1.01,0]],"batl":[[0,2.7,245.56],[1,2.7,0]],"ltp":0.0,"tv":0.0,"id":8444055},{"batb":[[0,1.76,43.75]],"ltp":0.0,"tv":0.0,"id":8257852}]}]}
{"op":"mcm","clk":"1011783210","pt":1580657740035,"mc":[{"id":"1.168223930","rc":[{"batb":[[0,2.16,46.19],[1,2.1,37.81],[2,2.08,50.99]],"batl":[[0,2.34,31.09],[1,2.7,245.56]],"ltp":0.0,"tv":0.0,"id":8444055},{"batb":[[1,1.75,55.45],[2,1.74,45.64]],"batl":[[0,1.93,42.01]],"ltp":0.0,"tv":0.0,"id":8257852}]}]}
{"op":"mcm","clk":"1011786415","pt":1580657756085,"mc":[{"id":"1.168223930","rc":[{"batb":[[0,2.1,37.81],[1,2.08,50.99],[2,1.01,15.51]],"ltp":0.0,"tv":0.0,"id":8444055},{"batb":[[0,1.75,55.45],[1,1.74,45.64],[2,1.01,15.51]],"ltp":0.0,"tv":0.0,"id":8257852}]}]}
{"op":"mcm","clk":"1011786683","pt":1580657757078,"mc":[{"id":"1.168223930","rc":[{"batb":[[0,2.08,50.99],[1,1.01,15.51],[2,1.01,0]],"batl":[[0,2.7,245.56],[1,2.7,0]],"ltp":0.0,"tv":0.0,"id":8444055},{"batb":[[0,1.74,45.64],[1,1.01,15.51],[2,1.01,0]],"ltp":0.0,"tv":0.0,"id":8257852}]}]}
{"op":"mcm","clk":"1011788116","pt":1580657764195,"mc":[{"id":"1.168223930","rc":[{"batb":[[0,2.2,44.06],[1,2.16,46.74],[2,2.14,36.13]],"batl":[[0,2.4,29.41],[1,2.7,245.56]],"ltp":0.0,"tv":0.0,"id":8444055},{"batb":[[1,1.72,57.97],[2,1.68,50.83]],"batl":[[0,1.9,42.01]],"ltp":0.0,"tv":0.0,"id":8257852}]}]}
{"op":"mcm","clk":"1011799493","pt":1580657817162,"mc":[{"id":"1.168223930","rc":[{"batb":[[2,2.14,82.94]],"ltp":0.0,"tv":0.0,"id":8444055}]}]}
{"op":"mcm","clk":"1011799711","pt":1580657818076,"mc":[{"id":"1.168223930","rc":[{"batb":[[1,2.14,82.94],[2,1.01,15.51]],"ltp":0.0,"tv":0.0,"id":8444055}]}]}
{"op":"mcm","clk":"1011807910","pt":1580657855194,"mc":[{"id":"1.168223930","rc":[{"batb":[[0,2.14,46.82],[1,1.01,15.51],[2,1.01,0]],"batl":[[0,2.7,245.56],[1,2.7,0]],"ltp":0.0,"tv":0.0,"id":8444055},{"batb":[[0,1.68,50.67],[1,1.01,15.51],[2,1.68,0]],"ltp":0.0,"tv":0.0,"id":8257852}]}]}
{"op":"mcm","clk":"1011811719","pt":1580657872137,"mc":[{"id":"1.168223930","rc":[{"batb":[[0,2.28,39.26],[1,2.22,42.17],[2,2.18,35.29]],"batl":[[0,2.46,28.57]],"ltp":0.0,"tv":0.0,"id":8444055},{"batb":[[0,1.69,60.49],[1,1.68,50.67],[2,1.63,56.34]],"batl":[[0,1.86,42.01]],"ltp":0.0,"tv":0.0,"id":8257852}]}]}
{"op":"mcm","clk":"1011812029","pt":1580657873443,"mc":[{"id":"1.168223930","rc":[{"batb":[[2,2.18,48.26]],"ltp":0.0,"tv":0.0,"id":8444055}]}]}
{"op":"mcm","clk":"1011812504","pt":1580657875539,"mc":[{"id":"1.168223930","rc":[{"batl":[[1,3,213.45]],"ltp":0.0,"tv":0.0,"id":8444055}]}]}
{"op":"mcm","clk":"1011814746","pt":1580657885167,"mc":[{"id":"1.168223930","rc":[{"batb":[[0,2.22,42.17],[1,1.01,15.51],[2,2.18,0]],"batl":[[0,3,213.45],[1,3,0]],"ltp":0.0,"tv":0.0,"id":8444055},{"batb":[[0,1.63,56.34],[1,1.01,15.51],[2,1.63,0]],"ltp":0.0,"tv":0.0,"id":8257852}]}]}
{"op":"mcm","clk":"1011815463","pt":1580657888240,"mc":[{"id":"1.168223930","rc":[{"batb":[[0,1.64,55.79]],"ltp":0.0,"tv":0.0,"id":8257852}]}]}
{"op":"mcm","clk":"1011817310","pt":1580657896249,"mc":[{"id":"1.168223930","rc":[{"batb":[[1,2.18,45.08],[2,2.16,36.13]],"batl":[[0,2.42,29.41]],"ltp":0.0,"tv":0.0,"id":8444055},{"batb":[[0,1.72,47.05],[1,1.7,59.65],[2,1.67,52.56]],"batl":[[0,1.88,42.01]],"ltp":0.0,"tv":0.0,"id":8257852}]}]}
{"op":"mcm","clk":"1011817694","pt":1580657897940,"mc":[{"id":"1.168223930","rc":[{"batl":[[1,2.84,228.62]],"ltp":0.0,"tv":0.0,"id":8444055}]}]}
{"op":"mcm","clk":"1011820066","pt":1580657908049,"mc":[{"id":"1.168223930","rc":[{"batb":[[0,2.18,45.08],[1,2.16,36.13],[2,1.01,15.51]],"ltp":0.0,"tv":0.0,"id":8444055},{"batb":[[0,1.7,59.65],[1,1.67,52.56],[2,1.01,15.51]],"ltp":0.0,"tv":0.0,"id":8257852}]}]}
{"op":"mcm","clk":"1011820291","pt":1580657909060,"mc":[{"id":"1.168223930","rc":[{"batb":[[1,1.01,15.51],[2,1.01,0]],"batl":[[0,2.84,228.62],[1,2.84,0]],"ltp":0.0,"tv":0.0,"id":8444055},{"batb":[[0,1.67,52.56],[1,1.01,15.51],[2,1.01,0]],"ltp":0.0,"tv":0.0,"id":8257852}]}]}
{"op":"mcm","clk":"1011824683","pt":1580657929193,"mc":[{"id":"1.168223930","rc":[{"batb":[[1,2.12,48.39],[2,1.01,15.51]],"ltp":0.0,"tv":0.0,"id":8444055},{"batb":[[0,1.75,44.69],[1,1.7,49.41],[2,1.67,52.56]],"ltp":0.0,"tv":0.0,"id":8257852}]}]}
{"op":"mcm","clk":"1011824890","pt":1580657930115,"mc":[{"id":"1.168223930","rc":[{"batb":[[1,2.14,36.13],[2,2.12,48.39]],"batl":[[0,2.38,30.25],[1,2.84,228.62]],"ltp":0.0,"tv":0.0,"id":8444055},{"batb":[[1,1.72,57.97],[2,1.7,49.41]],"batl":[[0,1.9,42.01]],"ltp":0.0,"tv":0.0,"id":8257852}]}]}
{"op":"mcm","clk":"1011828526","pt":1580657946210,"mc":[{"id":"1.168223930","rc":[{"batb":[[0,2.14,36.13],[1,2.12,48.39],[2,1.01,15.51]],"ltp":0.0,"tv":0.0,"id":8444055},{"batb":[[0,1.72,57.97],[1,1.7,49.41],[2,1.01,15.51]],"ltp":0.0,"tv":0.0,"id":8257852}]}]}
{"op":"mcm","clk":"1011828725","pt":1580657947134,"mc":[{"id":"1.168223930","rc":[{"batb":[[0,2.12,48.39],[1,1.01,15.51],[2,1.01,0]],"batl":[[0,2.84,228.62],[1,2.84,0]],"ltp":0.0,"tv":0.0,"id":8444055},{"batb":[[0,1.7,49.41],[1,1.01,15.51],[2,1.01,0]],"ltp":0.0,"tv":0.0,"id":8257852}]}]}
{"op":"mcm","clk":"1011836678","pt":1580657983038,"mc":[{"id":"1.168223930","rc":[{"batb":[[0,2.26,40.36],[1,2.2,43.35],[2,2.12,48.39]],"ltp":0.0,"tv":0.0,"id":8444055},{"batb":[[1,1.64,55.71],[2,1.01,15.51]],"ltp":0.0,"tv":0.0,"id":8257852}]}]}
{"op":"mcm","clk":"1011836937","pt":1580657984074,"mc":[{"id":"1.168223930","rc":[{"batb":[[2,2.18,48.15]],"batl":[[0,2.44,28.57],[1,2.84,228.62]],"ltp":0.0,"tv":0.0,"id":8444055},{"batb":[[1,1.69,60.49],[2,1.64,55.71]],"batl":[[0,1.86,42.01]],"ltp":0.0,"tv":0.0,"id":8257852}]}]}
{"op":"mcm","clk":"1011841728","pt":1580658005927,"mc":[{"id":"1.168223930","rc":[{"batb":[[0,2.2,43.35],[1,2.18,35.29],[2,1.01,15.51]],"ltp":0.0,"tv":0.0,"id":8444055},{"batb":[[0,1.69,60.49],[1,1.64,55.16],[2,1.01,15.51]],"ltp":0.0,"tv":0.0,"id":8257852}]}]}
{"op":"mcm","clk":"1011842033","pt":1580658007195,"mc":[{"id":"1.168223930","rc":[{"batb":[[1,1.01,15.51],[2,1.01,0]],"batl":[[0,2.84,228.62],[1,2.84,0]],"ltp":0.0,"tv":0.0,"id":8444055},{"batb":[[0,1.64,55.16],[1,1.01,15.51],[2,1.01,0]],"ltp":0.0,"tv":0.0,"id":8257852}]}]}
{"op":"mcm","clk":"1011843493","pt":1580658014136,"mc":[{"id":"1.168223930","rc":[{"batb":[[1,2.16,36.13],[2,2.14,47.37]],"batl":[[0,2.42,29.41],[1,2.84,228.62]],"ltp":0.0,"tv":0.0,"id":8444055},{"batb":[[0,1.73,45.79],[1,1.7,59.65],[2,1.68,51.14]],"batl":[[0,1.88,42.01]],"ltp":0.0,"tv":0.0,"id":8257852}]}]}
{"op":"mcm","clk":"1011845819","pt":1580658025235,"mc":[{"id":"1.168223930","rc":[{"batb":[[0,2.14,47.37],[1,1.01,15.51],[2,2.14,0]],"batl":[[0,2.84,228.62],[1,2.84,0]],"ltp":0.0,"tv":0.0,"id":8444055},{"batb":[[0,1.68,51.14],[1,1.01,15.51],[2,1.68,0]],"ltp":0.0,"tv":0.0,"id":8257852}]}]}
{"op":"mcm","clk":"1011850546","pt":1580658048146,"mc":[{"id":"1.168223930","rc":[{"batb":[[0,2.3,38.87],[1,2.22,42.33],[2,2.2,47.42]],"batl":[[0,2.48,27.73],[1,2.84,228.62]],"ltp":0.0,"tv":0.0,"id":8444055},{"batb":[[0,1.68,112.48],[1,1.62,57.6],[2,1.01,15.51]],"batl":[[0,1.85,42.01]],"ltp":0.0,"tv":0.0,"id":8257852}]}]}
{"op":"mcm","clk":"1011854605","pt":1580658067877,"mc":[{"id":"1.168223930","rc":[{"batb":[[0,2.22,42.33],[1,2.2,34.45],[2,1.01,15.51]],"ltp":0.0,"tv":0.0,"id":8444055},{"batb":[[0,1.68,61.33]],"ltp":0.0,"tv":0.0,"id":8257852}]}]}
{"op":"mcm","clk":"1011854885","pt":1580658069218,"mc":[{"id":"1.168223930","rc":[{"batb":[[1,1.01,15.51],[2,1.01,0]],"batl":[[0,2.84,228.62],[1,2.84,0]],"ltp":0.0,"tv":0.0,"id":8444055},{"batb":[[0,1.62,57.6],[1,1.01,15.51],[2,1.01,0]],"ltp":0.0,"tv":0.0,"id":8257852}]}]}
{"op":"mcm","clk":"1011855271","pt":1580658071104,"mc":[{"id":"1.168223930","rc":[{"batb":[[0,1.63,57.04]],"ltp":0.0,"tv":0.0,"id":8257852}]}]}
{"op":"mcm","clk":"1011858215","pt":1580658086087,"mc":[{"id":"1.168223930","rc":[{"batb":[[1,2.18,80.85],[2,1.01,15.51]],"batl":[[0,2.44,28.57],[1,2.84,228.62]],"ltp":0.0,"tv":0.0,"id":8444055},{"batb":[[0,1.72,46.89],[1,1.69,60.49],[2,1.67,52.24]],"batl":[[0,1.87,42.01]],"ltp":0.0,"tv":0.0,"id":8257852}]}]}
{"op":"mcm","clk":"1011861501","pt":1580658102207,"mc":[{"id":"1.168223930","rc":[{"batb":[[0,2.18,80.85],[1,1.01,15.51],[2,1.01,0]],"ltp":0.0,"tv":0.0,"id":8444055},{"batb":[[0,1.69,60.49],[1,1.67,52.24],[2,1.01,15.51]],"ltp":0.0,"tv":0.0,"id":8257852}]}]}
{"op":"mcm","clk":"1011861686","pt":1580658103140,"mc":[{"id":"1.168223930","rc":[{"batb":[[0,2.18,45.56]],"batl":[[0,2.84,228.62],[1,2.84,0]],"ltp":0.0,"tv":0.0,"id":8444055},{"batb":[[0,1.67,52.24],[1,1.01,15.51],[2,1.01,0]],"ltp":0.0,"tv":0.0,"id":8257852}]}]}
{"op":"mcm","clk":"1011867095","pt":1580658128122,"mc":[{"id":"1.168223930","rc":[{"batb":[[0,2.22,33.61],[1,2.18,45.56],[2,1.01,15.51]],"batl":[[0,2.5,27.73],[1,2.84,228.62]],"ltp":0.0,"tv":0.0,"id":8444055},{"batb":[[1,1.66,63.01],[2,1.01,15.51]],"batl":[[0,1.83,42.01]],"ltp":0.0,"tv":0.0,"id":8257852}]}]}
{"op":"mcm","clk":"1011867276","pt":1580658128927,"mc":[{"id":"1.168223930","rc":[{"batb":[[0,2.32,37.92],[1,2.26,40.76],[2,2.22,46.72]],"ltp":0.0,"tv":0.0,"id":8444055},{"batb":[[2,1.6,60.11]],"ltp":0.0,"tv":0.0,"id":8257852}]}]}
{"op":"mcm","clk":"1011871820","pt":1580658150262,"mc":[{"id":"1.168223930","rc":[{"batb":[[0,2.26,40.76],[1,2.22,33.61],[2,1.01,15.51]],"ltp":0.0,"tv":0.0,"id":8444055},{"batb":[[0,1.66,63.01],[1,1.6,60.11],[2,1.01,15.51]],"ltp":0.0,"tv":0.0,"id":8257852}]}]}
{"op":"mcm","clk":"1011872026","pt":1580658151251,"mc":[{"id":"1.168223930","rc":[{"batb":[[1,1.01,15.51],[2,1.01,0]],"batl":[[0,2.84,228.62],[1,2.84,0]],"ltp":0.0,"tv":0.0,"id":8444055},{"batb":[[0,1.6,60.11],[1,1.01,15.51],[2,1.01,0]],"ltp":0.0,"tv":0.0,"id":8257852}]}]}
{"op":"mcm","clk":"1011873533","pt":1580658158156,"mc":[{"id":"1.168223930","rc":[{"batb":[[1,2.2,78.43],[2,1.01,15.51]],"batl":[[0,2.48,27.73],[1,2.84,228.62]],"ltp":0.0,"tv":0.0,"id":8444055},{"batb":[[0,1.7,48.94],[1,1.67,62.17],[2,1.65,54.05]],"batl":[[0,1.84,42.01]],"ltp":0.0,"tv":0.0,"id":8257852}]}]}
{"op":"mcm","clk":"1011873610","pt":1580658158569,"mc":[{"id":"1.168223930","rc":[{"batb":[[1,1.65,54.05],[2,1.01,15.51]],"ltp":0.0,"tv":0.0,"id":8257852}]}]}
{"op":"mcm","clk":"1011873937","pt":1580658160162,"mc":[{"id":"1.168223930","rc":[{"batb":[[1,1.68,61.33],[2,1.65,54.05]],"ltp":0.0,"tv":0.0,"id":8257852}]}]}
{"op":"mcm","clk":"1011876036","pt":1580658170186,"mc":[{"id":"1.168223930","rc":[{"batb":[[0,2.2,78.43],[1,1.01,15.51],[2,1.01,0]],"ltp":0.0,"tv":0.0,"id":8444055},{"batb":[[0,1.68,61.33],[1,1.65,54.05],[2,1.01,15.51]],"ltp":0.0,"tv":0.0,"id":8257852}]}]}
{"op":"mcm","clk":"1011876272","pt":1580658171266,"mc":[{"id":"1.168223930","rc":[{"batb":[[0,2.2,43.98]],"batl":[[0,2.84,228.62],[1,2.84,0]],"ltp":0.0,"tv":0.0,"id":8444055},{"batb":[[0,1.65,54.05],[1,1.01,15.51],[2,1.01,0]],"ltp":0.0,"tv":0.0,"id":8257852}]}]}
{"op":"mcm","clk":"1011879964","pt":1580658188269,"mc":[{"id":"1.168223930","rc":[{"batb":[[0,2.34,36.51],[1,2.3,39.1],[2,2.24,33.61]],"batl":[[0,2.54,26.89]],"ltp":0.0,"tv":0.0,"id":8444055},{"batb":[[0,1.65,117.91],[1,1.59,62.08],[2,1.01,15.51]],"batl":[[0,1.82,42.01]],"ltp":0.0,"tv":0.0,"id":8257852}]}]}
{"op":"mcm","clk":"1011880043","pt":1580658188677,"mc":[{"id":"1.168223930","rc":[{"batb":[[2,2.24,46.88]],"ltp":0.0,"tv":0.0,"id":8444055}]}]}
{"op":"mcm","clk":"1011880319","pt":1580658190093,"mc":[{"id":"1.168223930","rc":[{"batl":[[1,3.15,200.42]],"ltp":0.0,"tv":0.0,"id":8444055}]}]}
{"op":"mcm","clk":"1011884432","pt":1580658208098,"mc":[{"id":"1.168223930","rc":[{"batb":[[0,2.3,39.1],[1,2.24,33.61],[2,1.01,15.51]],"ltp":0.0,"tv":0.0,"id":8444055},{"batb":[[0,1.65,63.85]],"ltp":0.0,"tv":0.0,"id":8257852}]}]}
{"op":"mcm","clk":"1011884670","pt":1580658209201,"mc":[{"id":"1.168223930","rc":[{"batb":[[1,1.01,15.51],[2,1.01,0]],"batl":[[0,3.15,200.42],[1,3.15,0]],"ltp":0.0,"tv":0.0,"id":8444055},{"batb":[[0,1.59,62.08],[1,1.01,15.51],[2,1.01,0]],"ltp":0.0,"tv":0.0,"id":8257852}]}]}
{"op":"mcm","clk":"1011885088","pt":1580658211112,"mc":[{"id":"1.168223930","rc":[{"batb":[[0,2.28,39.34]],"ltp":0.0,"tv":0.0,"id":8444055},{"batb":[[0,1.59,61.69]],"ltp":0.0,"tv":0.0,"id":8257852}]}]}
{"op":"mcm","clk":"1011888235","pt":1580658225231,"mc":[{"id":"1.168223930","rc":[{"batb":[[0,2.48,31.39],[1,2.38,35.33],[2,2.3,31.93]],"batl":[[0,2.6,26.05],[1,3.15,200.42]],"ltp":0.0,"tv":0.0,"id":8444055},{"batb":[[0,1.63,66.38],[1,1.59,61.69],[2,1.52,72.78]],"batl":[[0,1.78,42.01]],"ltp":0.0,"tv":0.0,"id":8257852}]}]}
{"op":"mcm","clk":"1011888926","pt":1580658228215,"mc":[{"id":"1.168223930","rc":[{"batl":[[1,2.16,342.82]],"ltp":0.0,"tv":0.0,"id":8257852}]}]}
{"op":"mcm","clk":"1011892654","pt":1580658245563,"mc":[{"id":"1.168223930","rc":[{"batb":[[0,2.38,35.33],[1,2.3,31.93],[2,1.01,15.51]],"ltp":0.0,"tv":0.0,"id":8444055},{"batb":[[1,1.52,72.78],[2,1.01,15.51]],"ltp":0.0,"tv":0.0,"id":8257852}]}]}
{"op":"mcm","clk":"1011893175","pt":1580658247977,"mc":[{"id":"1.168223930","rc":[{"batb":[[1,1.01,15.51],[2,1.01,0]],"batl":[[0,3.15,200.42],[1,3.15,0]],"ltp":0.0,"tv":0.0,"id":8444055},{"batb":[[0,1.52,72.78],[1,1.01,15.51],[2,1.01,0]],"batl":[[0,2.16,342.82],[1,2.16,0]],"ltp":0.0,"tv":0.0,"id":8257852}]}]}
{"op":"mcm","clk":"1011893513","pt":1580658249268,"mc":[{"id":"1.168223930","rc":[{"batb":[[0,2.36,35.8]],"ltp":0.0,"tv":0.0,"id":8444055},{"batb":[[0,1.53,71.76]],"ltp":0.0,"tv":0.0,"id":8257852}]}]}
{"op":"mcm","clk":"1011894146","pt":1580658252241,"mc":[{"id":"1.168223930","rc":[{"batl":[[0,2.6,26.05],[1,3.15,200.42]],"ltp":0.0,"tv":0.0,"id":8444055},{"batb":[[0,1.63,66.38],[1,1.56,898.83],[2,1.53,71.76]],"batl":[[0,1.78,42.01],[1,2.16,342.82]],"ltp":0.0,"tv":0.0,"id":8257852}]}]}
{"op":"mcm","clk":"1011894343","pt":1580658253256,"mc":[{"id":"1.168223930","rc":[{"batb":[[1,2.28,71.95],[2,1.01,15.51]],"batl":[[0,2.58,26.05]],"ltp":0.0,"tv":0.0,"id":8444055},{"batb":[[0,1.64,55.08],[1,1.63,66.38],[2,1.59,62.63]],"ltp":0.0,"tv":0.0,"id":8257852}]}]}
{"op":"mcm","clk":"1011895572","pt":1580658259173,"mc":[{"id":"1.168223930","rc":[{"batl":[[0,2.56,528.17],[1,2.58,26.05],[2,3.15,200.42]],"ltp":0.0,"tv":0.0,"id":8444055}]}]}
{"op":"mcm","clk":"1011896565","pt":1580658264195,"mc":[{"id":"1.168223930","rc":[{"batl":[[0,2.58,26.05],[1,3.15,200.42],[2,3.15,0]],"ltp":0.0,"tv":0.0,"id":8444055}]}]}
{"op":"mcm","clk":"1011896783","pt":1580658265267,"mc":[{"id":"1.168223930","rc":[{"batb":[[0,2.28,39.18],[1,1.01,15.51],[2,1.01,0]],"batl":[[0,3.15,200.42],[1,3.15,0]],"ltp":0.0,"tv":0.0,"id":8444055},{"batb":[[0,1.59,62.63],[1,1.01,15.51],[2,1.59,0]],"batl":[[0,2.16,342.82],[1,2.16,0]],"ltp":0.0,"tv":0.0,"id":8257852}]}]}
{"op":"mcm","clk":"1011897368","pt":1580658268191,"mc":[{"id":"1.168223930","rc":[{"batb":[[0,2.3,38.79]],"ltp":0.0,"tv":0.0,"id":8444055},{"batb":[[0,1.58,62.87]],"ltp":0.0,"tv":0.0,"id":8257852}]}]}
{"op":"mcm","clk":"1011898057","pt":1580658271177,"mc":[{"id":"1.168223930","rc":[{"batb":[[1,2.24,41.7],[2,1.01,15.51]],"ltp":0.0,"tv":0.0,"id":8444055},{"batb":[[0,1.68,51.22],[1,1.63,57.28],[2,1.58,62.87]],"ltp":0.0,"tv":0.0,"id":8257852}]}]}
{"op":"mcm","clk":"1011898250","pt":1580658272202,"mc":[{"id":"1.168223930","rc":[{"batb":[[1,2.26,32.77],[2,2.24,41.7]],"batl":[[0,2.54,26.89],[1,3.15,200.42]],"ltp":0.0,"tv":0.0,"id":8444055},{"batb":[[1,1.65,63.85],[2,1.63,57.28]],"batl":[[0,1.81,42.01],[1,2.16,342.82]],"ltp":0.0,"tv":0.0,"id":8257852}]}]}
{"op":"mcm","clk":"1011900537","pt":1580658283221,"mc":[{"id":"1.168223930","rc":[{"batb":[[0,2.24,41.7],[1,1.01,15.51],[2,2.24,0]],"batl":[[0,3.15,200.42],[1,3.15,0]],"ltp":0.0,"tv":0.0,"id":8444055},{"batb":[[0,1.63,57.28],[1,1.01,15.51],[2,1.63,0]],"batl":[[0,2.16,342.82],[1,2.16,0]],"ltp":0.0,"tv":0.0,"id":8257852}]}]}
{"op":"mcm","clk":"1011901555","pt":1580658288206,"mc":[{"id":"1.168223930","rc":[{"batb":[[1,2.2,34.45],[2,1.01,15.51]],"batl":[[0,2.48,27.73]],"ltp":0.0,"tv":0.0,"id":8444055},{"batb":[[0,1.68,353.69],[1,1.63,57.28],[2,1.01,15.51]],"batl":[[0,1.85,42.01],[1,2.16,342.82]],"ltp":0.0,"tv":0.0,"id":8257852}]}]}
{"op":"mcm","clk":"1011901783","pt":1580658289255,"mc":[{"id":"1.168223930","rc":[{"batb":[[2,2.14,47.05]],"ltp":0.0,"tv":0.0,"id":8444055},{"batb":[[0,1.71,48],[1,1.68,404.44]],"ltp":0.0,"tv":0.0,"id":8257852}]}]}
{"op":"mcm","clk":"1011901938","pt":1580658290124,"mc":[{"id":"1.168223930","rc":[{"batl":[[1,3,213.45]],"ltp":0.0,"tv":0.0,"id":8444055}]}]}
{"op":"mcm","clk":"1011906592","pt":1580658311272,"mc":[{"id":"1.168223930","rc":[{"batb":[[0,2.14,47.05],[1,1.01,15.51],[2,2.14,0]],"batl":[[0,3,213.45],[1,3,0]],"ltp":0.0,"tv":0.0,"id":8444055},{"batb":[[0,1.68,50.75],[1,1.01,15.51],[2,1.01,0]],"batl":[[0,2.16,342.82],[1,2.16,0]],"ltp":0.0,"tv":0.0,"id":8257852}]}]}
{"op":"mcm","clk":"1011908422","pt":1580658320170,"mc":[{"id":"1.168223930","rc":[{"batb":[[0,2.28,39.26],[1,2.22,33.61],[2,2.2,44.06]],"batl":[[0,2.5,27.73],[1,3,213.45]],"ltp":0.0,"tv":0.0,"id":8444055},{"batb":[[1,1.67,62.17],[2,1.66,53.58]],"batl":[[0,1.83,42.01],[1,2.16,342.82]],"ltp":0.0,"tv":0.0,"id":8257852}]}]}
{"op":"mcm","clk":"1011909834","pt":1580658327270,"mc":[{"id":"1.168223930","rc":[{"batb":[[0,2.2,44.06],[1,1.01,15.51],[2,2.2,0]],"batl":[[0,3,213.45],[1,3,0]],"ltp":0.0,"tv":0.0,"id":8444055},{"batb":[[0,1.66,53.58],[1,1.01,15.51],[2,1.66,0]],"batl":[[0,2.16,342.82],[1,2.16,0]],"ltp":0.0,"tv":0.0,"id":8257852}]}]}
{"op":"mcm","clk":"1011911225","pt":1580658334242,"mc":[{"id":"1.168223930","rc":[{"batb":[[0,2.34,36.9],[1,2.26,32.77],[2,2.24,54.42]],"batl":[[0,2.54,26.89],[1,3,213.45]],"ltp":0.0,"tv":0.0,"id":8444055},{"batb":[[0,1.66,116.6],[1,1.64,55.71],[2,1.01,15.51]],"batl":[[0,1.81,42.01],[1,2.16,342.82]],"ltp":0.0,"tv":0.0,"id":8257852}]}]}
{"op":"mcm","clk":"1011913246","pt":1580658344192,"mc":[{"id":"1.168223930","rc":[{"batb":[[2,2.24,41.15]],"ltp":0.0,"tv":0.0,"id":8444055}]}]}
{"op":"mcm","clk":"1011913460","pt":1580658345251,"mc":[{"id":"1.168223930","rc":[{"batb":[[0,2.24,41.15],[1,1.01,15.51],[2,2.24,0]],"batl":[[0,3,213.45],[1,3,0]],"ltp":0.0,"tv":0.0,"id":8444055},{"batb":[[0,1.64,55.71],[1,1.01,15.51],[2,1.01,0]],"batl":[[0,2.16,342.82],[1,2.16,0]],"ltp":0.0,"tv":0.0,"id":8257852}]}]}
{"op":"mcm","clk":"1011916872","pt":1580658362268,"mc":[{"id":"1.168223930","rc":[{"batb":[[0,2.38,35.33],[1,2.3,38.95],[2,2.28,32.77]],"batl":[[0,2.56,26.89],[1,3,213.45]],"ltp":0.0,"tv":0.0,"id":8444055},{"batb":[[0,1.64,121.24],[1,1.61,58.85],[2,1.01,15.51]],"batl":[[0,1.8,42.01],[1,2.16,342.82]],"ltp":0.0,"tv":0.0,"id":8257852}]}]}
{"op":"mcm","clk":"1011919522","pt":1580658375262,"mc":[{"id":"1.168223930","rc":[{"batb":[[0,2.3,38.95],[1,1.01,15.51],[2,2.28,0]],"batl":[[0,3,213.45],[1,3,0]],"ltp":0.0,"tv":0.0,"id":8444055},{"batb":[[0,1.61,58.85],[1,1.01,15.51],[2,1.01,0]],"batl":[[0,2.16,342.82],[1,2.16,0]],"ltp":0.0,"tv":0.0,"id":8257852}]}]}
{"op":"mcm","clk":"1011921185","pt":1580658383220,"mc":[{"id":"1.168223930","rc":[{"batb":[[0,2.44,33.2],[1,2.36,35.64],[2,2.3,11.28]],"ltp":0.0,"tv":0.0,"id":8444055},{"batb":[[1,1.56,66.17],[2,1.01,15.51]],"ltp":0.0,"tv":0.0,"id":8257852}]}]}
{"op":"mcm","clk":"1011921387","pt":1580658384192,"mc":[{"id":"1.168223930","rc":[{"batb":[[2,2.32,31.09]],"batl":[[0,2.62,25.21],[1,3,213.45]],"ltp":0.0,"tv":0.0,"id":8444055},{"batb":[[0,1.62,67.22],[1,1.61,58.85],[2,1.56,66.17]],"batl":[[0,1.77,42.01],[1,2.16,342.82]],"ltp":0.0,"tv":0.0,"id":8257852}]}]}
{"op":"mcm","clk":"1011922741","pt":1580658391114,"mc":[{"id":"1.168223930","rc":[{"batb":[[0,2.42,33.99]],"ltp":0.0,"tv":0.0,"id":8444055},{"batb":[[0,1.62,124.89],[1,1.57,64.83],[2,1.01,15.51]],"ltp":0.0,"tv":0.0,"id":8257852}]}]}
{"op":"mcm","clk":"1011937981","pt":1580658471218,"mc":[{"id":"1.168223930","rc":[{"batb":[[0,2.36,35.64],[1,1.01,15.51],[2,2.32,0]],"batl":[[0,3,213.45],[1,3,0]],"ltp":0.0,"tv":0.0,"id":8444055},{"batb":[[0,1.57,64.83],[1,1.01,15.51],[2,1.01,0]],"batl":[[0,2.16,342.82],[1,2.16,0]],"ltp":0.0,"tv":0.0,"id":8257852}]}]}
{"op":"mcm","clk":"1011938978","pt":1580658476239,"mc":[{"id":"1.168223930","rc":[{"batb":[[1,2.3,39.03],[2,2.28,32.77]],"batl":[[0,2.58,26.05],[1,3,213.45]],"ltp":0.0,"tv":0.0,"id":8444055},{"batb":[[0,1.65,54.29],[1,1.64,821.07],[2,1.63,66.38]],"batl":[[0,1.79,42.01],[1,2.16,342.82]],"ltp":0.0,"tv":0.0,"id":8257852}]}]}
{"op":"mcm","clk":"1011940899","pt":1580658486028,"mc":[{"id":"1.168223930","rc":[{"batb":[[0,2.3,39.03],[1,2.28,32.77],[2,1.01,15.51]],"ltp":0.0,"tv":0.0,"id":8444055},{"batb":[[0,1.63,66.38],[1,1.6,60.51],[2,1.01,15.51]],"ltp":0.0,"tv":0.0,"id":8257852}]}]}
{"op":"mcm","clk":"1011941157","pt":1580658487247,"mc":[{"id":"1.168223930","rc":[{"batb":[[1,1.01,15.51],[2,1.01,0]],"batl":[[0,3,213.45],[1,3,0]],"ltp":0.0,"tv":0.0,"id":8444055},{"batb":[[0,1.6,60.51],[1,1.01,15.51],[2,1.01,0]],"batl":[[0,2.16,342.82],[1,2.16,0]],"ltp":0.0,"tv":0.0,"id":8257852}]}]}
{"op":"mcm","clk":"1011944635","pt":1580658506152,"mc":[{"id":"1.168223930","rc":[{"batb":[[1,2.26,32.77],[2,2.24,41.23]],"batl":[[0,2.56,26.89],[1,3,213.45]],"ltp":0.0,"tv":0.0,"id":8444055},{"batb":[[0,1.68,50.99],[1,1.65,156.33],[2,1.64,65.54]],"batl":[[0,1.81,42.01],[1,2.16,342.82]],"ltp":0.0,"tv":0.0,"id":8257852}]}]}
{"op":"mcm","clk":"1011946952","pt":1580658518242,"mc":[{"id":"1.168223930","rc":[{"batb":[[0,2.26,32.77],[1,2.24,41.23],[2,1.01,15.51]],"ltp":0.0,"tv":0.0,"id":8444055},{"batb":[[0,1.64,65.54],[1,1.63,56.49],[2,1.01,15.51]],"ltp":0.0,"tv":0.0,"id":8257852}]}]}
{"op":"mcm","clk":"1011947135","pt":1580658519204,"mc":[{"id":"1.168223930","rc":[{"batb":[[0,2.24,41.23],[1,1.01,15.51],[2,1.01,0]],"batl":[[0,3,213.45],[1,3,0]],"ltp":0.0,"tv":0.0,"id":8444055},{"batb":[[0,1.63,56.49],[1,1.01,15.51],[2,1.01,0]],"batl":[[0,2.16,342.82],[1,2.16,0]],"ltp":0.0,"tv":0.0,"id":8257852}]}]}
{"op":"mcm","clk":"1011950422","pt":1580658538233,"mc":[{"id":"1.168223930","rc":[{"batb":[[0,2.24,74.84]],"batl":[[0,2.52,26.89],[1,3,213.45]],"ltp":0.0,"tv":0.0,"id":8444055},{"batb":[[0,1.66,63.01],[1,1.63,56.49],[2,1.01,15.51]],"batl":[[0,1.82,42.01],[1,2.16,342.82]],"ltp":0.0,"tv":0.0,"id":8257852}]}]}
{"op":"mcm","clk":"1011950570","pt":1580658539143,"mc":[{"id":"1.168223930","rc":[{"batb":[[1,2.2,43.75],[2,1.01,15.51]],"ltp":0.0,"tv":0.0,"id":8444055},{"batb":[[0,1.71,48.47],[1,1.66,900.83]],"ltp":0.0,"tv":0.0,"id":8257852}]}]}
{"op":"mcm","clk":"1011952518","pt":1580658550259,"mc":[{"id":"1.168223930","rc":[{"batb":[[0,2.24,33.61]],"ltp":0.0,"tv":0.0,"id":8444055},{"batb":[[0,1.66,116.05],[1,1.01,15.51],[2,1.01,0]],"ltp":0.0,"tv":0.0,"id":8257852}]}]}
{"op":"mcm","clk":"1011952707","pt":1580658551239,"mc":[{"id":"1.168223930","rc":[{"batb":[[0,2.2,43.75],[1,1.01,15.51],[2,1.01,0]],"batl":[[0,3,213.45],[1,3,0]],"ltp":0.0,"tv":0.0,"id":8444055},{"batb":[[0,1.66,53.03]],"batl":[[0,2.16,342.82],[1,2.16,0]],"ltp":0.0,"tv":0.0,"id":8257852}]}]}
{"op":"mcm","clk":"1011954663","pt":1580658562180,"mc":[{"id":"1.168223930","rc":[{"batb":[[1,2.1,49.65],[2,1.01,15.51]],"ltp":0.0,"tv":0.0,"id":8444055},{"batb":[[0,1.73,46.03],[1,1.7,48.63],[2,1.01,15.51]],"ltp":0.0,"tv":0.0,"id":8257852}]}]}
{"op":"mcm","clk":"1011954856","pt":1580658563262,"mc":[{"id":"1.168223930","rc":[{"batb":[[1,2.18,35.29],[2,2.1,49.65]],"batl":[[0,2.46,28.57],[1,3,213.45]],"ltp":0.0,"tv":0.0,"id":8444055},{"batb":[[2,1.69,60.49]],"batl":[[0,1.86,42.01],[1,2.16,342.82]],"ltp":0.0,"tv":0.0,"id":8257852}]}]}
{"op":"mcm","clk":"1011955862","pt":1580658569087,"mc":[{"id":"1.168223930","rc":[{"batl":[[0,2.44,526.83],[1,2.46,28.57],[2,3,213.45]],"ltp":0.0,"tv":0.0,"id":8444055}]}]}
{"op":"mcm","clk":"1011958732","pt":1580658584992,"mc":[{"id":"1.168223930","rc":[{"batb":[[0,2.18,35.29],[1,2.1,49.65],[2,1.01,15.51]],"batl":[[0,2.46,28.57],[1,3,213.45],[2,3,0]],"ltp":0.0,"tv":0.0,"id":8444055},{"batb":[[0,1.7,48.63],[1,1.69,60.49],[2,1.01,15.51]],"ltp":0.0,"tv":0.0,"id":8257852}]}]}
{"op":"mcm","clk":"1011958937","pt":1580658586101,"mc":[{"id":"1.168223930","rc":[{"batb":[[0,2.1,49.65],[1,1.01,15.51],[2,1.01,0]],"batl":[[0,3,213.45],[1,3,0]],"ltp":0.0,"tv":0.0,"id":8444055},{"batb":[[1,1.01,15.51],[2,1.01,0]],"batl":[[0,2.16,342.82],[1,2.16,0]],"ltp":0.0,"tv":0.0,"id":8257852}]}]}
{"op":"mcm","clk":"1011959379","pt":1580658588768,"mc":[{"id":"1.168223930","rc":[{"batb":[[0,2.12,48.31]],"ltp":0.0,"tv":0.0,"id":8444055}]}]}
{"op":"mcm","clk":"1011959920","pt":1580658592181,"mc":[{"id":"1.168223930","rc":[{"batb":[[0,2.26,40.6],[1,2.16,45.64],[2,1.01,15.51]],"ltp":0.0,"tv":0.0,"id":8444055},{"batb":[[1,1.67,51.69],[2,1.01,15.51]],"ltp":0.0,"tv":0.0,"id":8257852}]}]}
{"op":"mcm","clk":"1011960002","pt":1580658592558,"mc":[{"id":"1.168223930","rc":[{"batb":[[1,2.2,34.45],[2,2.16,45.64]],"batl":[[0,2.48,27.73],[1,3,213.45]],"ltp":0.0,"tv":0.0,"id":8444055}]}]}
{"op":"mcm","clk":"1011960256","pt":1580658594054,"mc":[{"id":"1.168223930","rc":[{"batb":[[1,1.68,61.33],[2,1.67,51.69]],"batl":[[0,1.84,42.01],[1,2.16,342.82]],"ltp":0.0,"tv":0.0,"id":8257852}]}]}
{"op":"mcm","clk":"1011961909","pt":1580658604207,"mc":[{"id":"1.168223930","rc":[{"batb":[[0,2.2,34.45],[1,2.16,45.64],[2,1.01,15.51]],"ltp":0.0,"tv":0.0,"id":8444055},{"batb":[[0,1.68,61.33],[1,1.67,51.69],[2,1.01,15.51]],"ltp":0.0,"tv":0.0,"id":8257852}]}]}
{"op":"mcm","clk":"1011962192","pt":1580658606012,"mc":[{"id":"1.168223930","rc":[{"batb":[[0,2.16,45.64],[1,1.01,15.51],[2,1.01,0]],"batl":[[0,3,213.45],[1,3,0]],"ltp":0.0,"tv":0.0,"id":8444055},{"batb":[[0,1.67,51.69],[1,1.01,15.51],[2,1.01,0]],"batl":[[0,2.16,342.82],[1,2.16,0]],"ltp":0.0,"tv":0.0,"id":8257852}]}]}
{"op":"mcm","clk":"1011967359","pt":1580658638241,"mc":[{"id":"1.168223930","rc":[{"batb":[[0,2.3,38.4],[1,2.22,33.61],[2,2.2,43.43]],"batl":[[0,2.52,26.89],[1,3,213.45]],"ltp":0.0,"tv":0.0,"id":8444055},{"batb":[[0,1.67,113.87],[1,1.65,53.98],[2,1.01,15.51]],"batl":[[0,1.83,42.01],[1,2.16,342.82]],"ltp":0.0,"tv":0.0,"id":8257852}]}]}
{"op":"mcm","clk":"1011969555","pt":1580658652227,"mc":[{"id":"1.168223930","rc":[{"batb":[[0,2.22,33.61],[1,2.2,43.43],[2,1.01,15.51]],"ltp":0.0,"tv":0.0,"id":8444055},{"batb":[[0,1.67,62.17]],"ltp":0.0,"tv":0.0,"id":8257852}]}]}
{"op":"mcm","clk":"1011969874","pt":1580658654061,"mc":[{"id":"1.168223930","rc":[{"batb":[[0,2.2,43.43],[1,1.01,15.51],[2,1.01,0]],"batl":[[0,3,213.45],[1,3,0]],"ltp":0.0,"tv":0.0,"id":8444055},{"batb":[[0,1.65,53.98],[1,1.01,15.51],[2,1.01,0]],"batl":[[0,2.16,342.82],[1,2.16,0]],"ltp":0.0,"tv":0.0,"id":8257852}]}]}
{"op":"mcm","clk":"1011974207","pt":1580658683197,"mc":[{"id":"1.168223930","rc":[{"batb":[[0,2.34,36.67],[1,2.24,41.23],[2,2.2,43.43]],"ltp":0.0,"tv":0.0,"id":8444055},{"batb":[[1,1.63,56.18],[2,1.01,15.51]],"ltp":0.0,"tv":0.0,"id":8257852}]}]}
{"op":"mcm","clk":"1011974352","pt":1580658684208,"mc":[{"id":"1.168223930","rc":[{"batb":[[2,2.22,13.34]],"ltp":0.0,"tv":0.0,"id":8444055}]}]}
{"op":"mcm","clk":"1011974407","pt":1580658684582,"mc":[{"id":"1.168223930","rc":[{"batb":[[1,2.24,74.84]],"batl":[[0,2.54,26.89],[1,3,213.45]],"ltp":0.0,"tv":0.0,"id":8444055},{"batb":[[0,1.65,117.83]],"batl":[[0,1.81,42.01],[1,2.16,342.82]],"ltp":0.0,"tv":0.0,"id":8257852}]}]}
{"op":"mcm","clk":"1011975757","pt":1580658694901,"mc":[{"id":"1.168223930","rc":[{"batb":[[0,2.24,74.68],[1,1.01,15.51],[2,2.22,0]],"ltp":0.0,"tv":0.0,"id":8444055},{"batb":[[0,1.65,63.85]],"ltp":0.0,"tv":0.0,"id":8257852}]}]}
{"op":"mcm","clk":"1011975809","pt":1580658695328,"mc":[{"id":"1.168223930","rc":[{"batb":[[0,2.24,41.07]],"batl":[[0,3,213.45],[1,3,0]],"ltp":0.0,"tv":0.0,"id":8444055},{"batb":[[0,1.63,56.18],[1,1.01,15.51],[2,1.01,0]],"batl":[[0,2.16,342.82],[1,2.16,0]],"ltp":0.0,"tv":0.0,"id":8257852}]}]}
{"op":"mcm","clk":"1011977064","pt":1580658704224,"mc":[{"id":"1.168223930","rc":[{"batb":[[0,2.38,34.86],[1,2.34,36.98],[2,1.01,15.51]],"ltp":0.0,"tv":0.0,"id":8444055},{"batb":[[1,1.59,62.63],[2,1.01,15.51]],"ltp":0.0,"tv":0.0,"id":8257852}]}]}
{"op":"mcm","clk":"1011977192","pt":1580658705120,"mc":[{"id":"1.168223930","rc":[{"batb":[[2,2.28,32.77]],"batl":[[0,2.58,26.05],[1,3,213.45]],"ltp":0.0,"tv":0.0,"id":8444055},{"batb":[[0,1.63,122.55]],"batl":[[0,1.79,42.01],[1,2.16,342.82]],"ltp":0.0,"tv":0.0,"id":8257852}]}]}
{"op":"mcm","clk":"1011978214","pt":1580658712111,"mc":[{"id":"1.168223930","rc":[{"batb":[[0,1.64,56.02],[1,1.63,122.55],[2,1.59,62.63]],"ltp":0.0,"tv":0.0,"id":8257852}]}]}
{"op":"mcm","clk":"1011978328","pt":1580658712933,"mc":[{"id":"1.168223930","rc":[{"batb":[[1,1.63,66.38],[2,1.59,62.24]],"ltp":0.0,"tv":0.0,"id":8257852}]}]}
{"op":"mcm","clk":"1011988847","pt":1580658787249,"mc":[{"id":"1.168223930","rc":[{"batb":[[0,2.34,36.98],[1,2.28,32.77],[2,1.01,15.51]],"ltp":0.0,"tv":0.0,"id":8444055},{"batb":[[0,1.63,66.38],[1,1.59,62.24],[2,1.01,15.51]],"ltp":0.0,"tv":0.0,"id":8257852}]}]}
{"op":"mcm","clk":"1011988948","pt":1580658787849,"mc":[{"id":"1.168223930","rc":[{"batb":[[1,1.01,15.51],[2,1.01,0]],"batl":[[0,3,213.45],[1,3,0]],"ltp":0.0,"tv":0.0,"id":8444055},{"batb":[[0,1.59,62.24],[1,1.01,15.51],[2,1.01,0]],"batl":[[0,2.16,342.82],[1,2.16,0]],"ltp":0.0,"tv":0.0,"id":8257852}]}]}
{"op":"mcm","clk":"1011989749","pt":1580658793269,"mc":[{"id":"1.168223930","rc":[{"batb":[[1,2.28,39.5],[2,1.01,15.51]],"ltp":0.0,"tv":0.0,"id":8444055},{"batb":[[0,1.66,53.11],[1,1.61,59.56],[2,1.01,15.51]],"ltp":0.0,"tv":0.0,"id":8257852}]}]}
{"op":"mcm","clk":"1011989966","pt":1580658794843,"mc":[{"id":"1.168223930","rc":[{"batb":[[2,2.26,32.77]],"batl":[[0,2.54,26.89],[1,3,213.45]],"ltp":0.0,"tv":0.0,"id":8444055},{"batb":[[1,1.65,63.85],[2,1.61,59.56]],"batl":[[0,1.81,42.01],[1,2.16,342.82]],"ltp":0.0,"tv":0.0,"id":8257852}]}]}
{"op":"mcm","clk":"1011991342","pt":1580658803926,"mc":[{"id":"1.168223930","rc":[{"batb":[[0,2.28,39.5],[1,2.26,32.77],[2,1.01,15.51]],"ltp":0.0,"tv":0.0,"id":8444055},{"batb":[[0,1.65,63.85],[1,1.61,59.01],[2,1.01,15.51]],"ltp":0.0,"tv":0.0,"id":8257852}]}]}
{"op":"mcm","clk":"1011991685","pt":1580658806242,"mc":[{"id":"1.168223930","rc":[{"batb":[[1,1.01,15.51],[2,1.01,0]],"batl":[[0,3,213.45],[1,3,0]],"ltp":0.0,"tv":0.0,"id":8444055},{"batb":[[0,1.61,59.01],[1,1.01,15.51],[2,1.01,0]],"batl":[[0,2.16,342.82],[1,2.16,0]],"ltp":0.0,"tv":0.0,"id":8257852}]}]}
{"op":"mcm","clk":"1011993992","pt":1580658821173,"mc":[{"id":"1.168223930","rc":[{"batb":[[1,2.22,42.17],[2,1.01,15.51]],"ltp":0.0,"tv":0.0,"id":8444055},{"batb":[[0,1.69,49.88],[1,1.65,297.73],[2,1.64,55]],"ltp":0.0,"tv":0.0,"id":8257852}]}]}
{"op":"mcm","clk":"1011994168","pt":1580658822392,"mc":[{"id":"1.168223930","rc":[{"batb":[[1,2.24,33.61],[2,2.22,42.17]],"batl":[[0,2.52,26.89],[1,3,213.45]],"ltp":0.0,"tv":0.0,"id":8444055},{"batb":[[1,1.66,63.01],[2,1.65,297.73]],"batl":[[0,1.82,42.01],[1,2.16,342.82]],"ltp":0.0,"tv":0.0,"id":8257852}]}]}
{"op":"mcm","clk":"1011995874","pt":1580658834101,"mc":[{"id":"1.168223930","rc":[{"batb":[[0,2.24,33.61],[1,2.22,42.17],[2,1.01,15.51]],"ltp":0.0,"tv":0.0,"id":8444055},{"batb":[[0,1.66,63.01],[1,1.64,55],[2,1.01,15.51]],"ltp":0.0,"tv":0.0,"id":8257852}]}]}
{"op":"mcm","clk":"1011996127","pt":1580658835902,"mc":[{"id":"1.168223930","rc":[{"batb":[[0,2.22,42.17],[1,1.01,15.51],[2,1.01,0]],"batl":[[0,3,213.45],[1,3,0]],"ltp":0.0,"tv":0.0,"id":8444055},{"batb":[[0,1.64,55],[1,1.01,15.51],[2,1.01,0]],"batl":[[0,2.16,342.82],[1,2.16,0]],"ltp":0.0,"tv":0.0,"id":8257852}]}]}
{"op":"mcm","clk":"1011998943","pt":1580658856231,"mc":[{"id":"1.168223930","rc":[{"batb":[[1,2.2,44.3],[2,1.01,15.51]],"ltp":0.0,"tv":0.0,"id":8444055},{"batb":[[0,1.72,47.52],[1,1.66,52.87],[2,1.64,55]],"ltp":0.0,"tv":0.0,"id":8257852}]}]}
{"op":"mcm","clk":"1011999090","pt":1580658857233,"mc":[{"id":"1.168223930","rc":[{"batb":[[1,2.2,78.75]],"batl":[[0,2.48,27.73],[1,3,213.45]],"ltp":0.0,"tv":0.0,"id":8444055},{"batb":[[1,1.67,62.17],[2,1.66,52.87]],"batl":[[0,1.84,42.01],[1,2.16,342.82]],"ltp":0.0,"tv":0.0,"id":8257852}]}]}
{"op":"mcm","clk":"1012000887","pt":1580658869949,"mc":[{"id":"1.168223930","rc":[{"batb":[[0,2.2,78.75],[1,1.01,15.51],[2,1.01,0]],"ltp":0.0,"tv":0.0,"id":8444055},{"batb":[[0,1.67,62.17],[1,1.66,52.87],[2,1.01,15.51]],"ltp":0.0,"tv":0.0,"id":8257852}]}]}
{"op":"mcm","clk":"1012001160","pt":1580658872066,"mc":[{"id":"1.168223930","rc":[{"batb":[[0,2.2,44.3]],"batl":[[0,3,213.45],[1,3,0]],"ltp":0.0,"tv":0.0,"id":8444055},{"batb":[[0,1.66,52.87],[1,1.01,15.51],[2,1.01,0]],"batl":[[0,2.16,342.82],[1,2.16,0]],"ltp":0.0,"tv":0.0,"id":8257852}]}]}
{"op":"mcm","clk":"1012003031","pt":1580658885248,"mc":[{"id":"1.168223930","rc":[{"batb":[[1,2.16,36.13],[2,2.1,50.59]],"batl":[[0,2.44,28.57],[1,3,213.45]],"ltp":0.0,"tv":0.0,"id":8444055},{"batb":[[0,1.74,45.4],[1,1.71,106.65],[2,1.01,15.51]],"batl":[[0,1.87,42.01],[1,2.16,342.82]],"ltp":0.0,"tv":0.0,"id":8257852}]}]}
{"op":"mcm","clk":"1012007153","pt":1580658913213,"mc":[{"id":"1.168223930","rc":[{"batb":[[0,2.16,36.13],[1,2.1,49.41],[2,1.01,15.51]],"ltp":0.0,"tv":0.0,"id":8444055},{"batb":[[0,1.71,106.65],[1,1.01,15.51],[2,1.01,0]],"ltp":0.0,"tv":0.0,"id":8257852}]}]}
{"op":"mcm","clk":"1012007252","pt":1580658913911,"mc":[{"id":"1.168223930","rc":[{"batb":[[0,2.1,49.41],[1,1.01,15.51],[2,1.01,0]],"batl":[[0,3,213.45],[1,3,0]],"ltp":0.0,"tv":0.0,"id":8444055},{"batb":[[0,1.71,47.84]],"batl":[[0,2.16,342.82],[1,2.16,0]],"ltp":0.0,"tv":0.0,"id":8257852}]}]}
{"op":"mcm","clk":"1012009999","pt":1580658933239,"mc":[{"id":"1.168223930","rc":[{"batb":[[0,2.24,41.7],[1,2.18,44.53],[2,2.16,36.13]],"batl":[[0,2.44,28.57],[1,3,213.45]],"ltp":0.0,"tv":0.0,"id":8444055},{"batb":[[1,1.7,59.65],[2,1.66,52.95]],"batl":[[0,1.86,42.01],[1,2.16,342.82]],"ltp":0.0,"tv":0.0,"id":8257852}]}]}
{"op":"mcm","clk":"1012013348","pt":1580658957878,"mc":[{"id":"1.168223930","rc":[{"batb":[[0,2.18,44.53],[1,1.01,15.51],[2,2.16,0]],"batl":[[0,3,213.45],[1,3,0]],"ltp":0.0,"tv":0.0,"id":8444055},{"batb":[[0,1.66,52.72],[1,1.01,15.51],[2,1.66,0]],"batl":[[0,2.16,342.82],[1,2.16,0]],"ltp":0.0,"tv":0.0,"id":8257852}]}]}
{"op":"mcm","clk":"1012015721","pt":1580658974179,"mc":[{"id":"1.168223930","rc":[{"batb":[[1,2.14,47.05],[2,1.01,15.51]],"ltp":0.0,"tv":0.0,"id":8444055},{"batb":[[0,1.74,45.01],[1,1.68,50.91],[2,1.01,15.51]],"ltp":0.0,"tv":0.0,"id":8257852}]}]}
{"op":"mcm","clk":"1012015812","pt":1580658974968,"mc":[{"id":"1.168223930","rc":[{"batb":[[1,2.16,36.13],[2,2.14,47.05]],"batl":[[0,2.42,29.41],[1,3,213.45]],"ltp":0.0,"tv":0.0,"id":8444055},{"batb":[[1,1.7,59.65],[2,1.68,50.91]],"batl":[[0,1.87,42.01],[1,2.16,342.82]],"ltp":0.0,"tv":0.0,"id":8257852}]}]}
{"op":"mcm","clk":"1012017986","pt":1580658991266,"mc":[{"id":"1.168223930","rc":[{"batb":[[0,2.16,36.13],[1,2.14,47.05],[2,1.01,15.51]],"ltp":0.0,"tv":0.0,"id":8444055},{"batb":[[0,1.7,59.65],[1,1.68,50.91],[2,1.01,15.51]],"ltp":0.0,"tv":0.0,"id":8257852}]}]}
{"op":"mcm","clk":"1012018117","pt":1580658992212,"mc":[{"id":"1.168223930","rc":[{"batb":[[0,2.14,47.05],[1,1.01,15.51],[2,1.01,0]],"batl":[[0,3,213.45],[1,3,0]],"ltp":0.0,"tv":0.0,"id":8444055},{"batb":[[0,1.68,50.91],[1,1.01,15.51],[2,1.01,0]],"batl":[[0,2.16,342.82],[1,2.16,0]],"ltp":0.0,"tv":0.0,"id":8257852}]}]}
{"op":"mcm","clk":"1012021054","pt":1580659015266,"mc":[{"id":"1.168223930","rc":[{"batb":[[0,2.3,39.03],[1,2.18,44.61],[2,2.14,47.05]],"ltp":0.0,"tv":0.0,"id":8444055},{"batb":[[1,1.66,52.72],[2,1.01,15.51]],"ltp":0.0,"tv":0.0,"id":8257852}]}]}
{"op":"mcm","clk":"1012021083","pt":1580659015461,"mc":[{"id":"1.168223930","rc":[{"batb":[[2,1.01,15.51]],"ltp":0.0,"tv":0.0,"id":8444055}]}]}
{"op":"mcm","clk":"1012021322","pt":1580659017171,"mc":[{"id":"1.168223930","rc":[{"batb":[[1,2.2,34.45],[2,2.18,44.61]],"batl":[[0,2.48,27.73],[1,3,213.45]],"ltp":0.0,"tv":0.0,"id":8444055},{"batb":[[1,1.67,62.17],[2,1.66,52.72]],"batl":[[0,1.84,42.01],[1,2.16,342.82]],"ltp":0.0,"tv":0.0,"id":8257852}]}]}
{"op":"mcm","clk":"1012024123","pt":1580659037185,"mc":[{"id":"1.168223930","rc":[{"batb":[[0,2.2,34.45],[1,2.18,44.61],[2,1.01,15.51]],"ltp":0.0,"tv":0.0,"id":8444055},{"batb":[[0,1.67,62.17],[1,1.66,52.72],[2,1.01,15.51]],"ltp":0.0,"tv":0.0,"id":8257852}]}]}
{"op":"mcm","clk":"1012024288","pt":1580659038196,"mc":[{"id":"1.168223930","rc":[{"batb":[[0,2.18,44.61],[1,1.01,15.51],[2,1.01,0]],"batl":[[0,3,213.45],[1,3,0]],"ltp":0.0,"tv":0.0,"id":8444055},{"batb":[[0,1.66,52.72],[1,1.01,15.51],[2,1.01,0]],"batl":[[0,2.16,342.82],[1,2.16,0]],"ltp":0.0,"tv":0.0,"id":8257852}]}]}
{"op":"mcm","clk":"1012024438","pt":1580659039207,"mc":[{"id":"1.168223930","rc":[{"batb":[[0,1.67,52.48],[1,1.66,52.72],[2,1.01,15.51]],"ltp":0.0,"tv":0.0,"id":8257852}]}]}
{"op":"mcm","clk":"1012024559","pt":1580659040054,"mc":[{"id":"1.168223930","rc":[{"batb":[[1,1.01,15.51],[2,1.01,0]],"ltp":0.0,"tv":0.0,"id":8257852}]}]}
{"op":"mcm","clk":"1012025957","pt":1580659050204,"mc":[{"id":"1.168223930","rc":[{"batb":[[1,2.1,50.67],[2,1.01,15.51]],"ltp":0.0,"tv":0.0,"id":8444055},{"batb":[[0,1.74,44.93],[1,1.72,47.21],[2,1.69,747.92]],"ltp":0.0,"tv":0.0,"id":8257852}]}]}
{"op":"mcm","clk":"1012026102","pt":1580659051203,"mc":[{"id":"1.168223930","rc":[{"batb":[[0,2.18,79.9]],"batl":[[0,2.44,28.57],[1,3,213.45]],"ltp":0.0,"tv":0.0,"id":8444055},{"batb":[[2,1.7,59.65]],"batl":[[0,1.86,42.01],[1,2.16,342.82]],"ltp":0.0,"tv":0.0,"id":8257852}]}]}
{"op":"mcm","clk":"1012027568","pt":1580659061111,"mc":[{"id":"1.168223930","rc":[{"batb":[[0,2.18,44.61]],"ltp":0.0,"tv":0.0,"id":8444055}]}]}
{"op":"mcm","clk":"1012027966","pt":1580659063882,"mc":[{"id":"1.168223930","rc":[{"batb":[[1,2.16,36.13],[2,2.1,50.67]],"ltp":0.0,"tv":0.0,"id":8444055}]}]}
{"op":"mcm","clk":"1012028277","pt":1580659066102,"mc":[{"id":"1.168223930","rc":[{"batb":[[0,2.16,36.13],[1,2.1,50.67],[2,1.01,15.51]],"ltp":0.0,"tv":0.0,"id":8444055},{"batb":[[0,1.72,47.21],[1,1.7,59.65],[2,1.01,15.51]],"ltp":0.0,"tv":0.0,"id":8257852}]}]}
{"op":"mcm","clk":"1012028503","pt":1580659068195,"mc":[{"id":"1.168223930","rc":[{"batb":[[0,2.1,50.67],[1,1.01,15.51],[2,1.01,0]],"batl":[[0,3,213.45],[1,3,0]],"ltp":0.0,"tv":0.0,"id":8444055},{"batb":[[1,1.01,15.51],[2,1.01,0]],"batl":[[0,2.16,342.82],[1,2.16,0]],"ltp":0.0,"tv":0.0,"id":8257852}]}]}
{"op":"mcm","clk":"1012032422","pt":1580659100128,"mc":[{"id":"1.168223930","rc":[{"batb":[[1,2.06,53.5],[2,1.01,15.51]],"ltp":0.0,"tv":0.0,"id":8444055},{"batb":[[0,1.81,40.05],[1,1.76,146.48],[2,1.75,44.61]],"ltp":0.0,"tv":0.0,"id":8257852}]}]}
{"op":"mcm","clk":"1012032567","pt":1580659101141,"mc":[{"id":"1.168223930","rc":[{"batb":[[0,2.12,36.97],[1,2.1,50.67],[2,2.06,53.5]],"batl":[[0,2.38,30.25]],"ltp":0.0,"tv":0.0,"id":8444055},{"batl":[[0,1.89,42.01]],"ltp":0.0,"tv":0.0,"id":8257852}]}]}
{"op":"mcm","clk":"1012032692","pt":1580659102249,"mc":[{"id":"1.168223930","rc":[{"batl":[[1,2.84,228.62]],"ltp":0.0,"tv":0.0,"id":8444055},{"batl":[[1,2.4,289.78]],"ltp":0.0,"tv":0.0,"id":8257852}]}]}
{"op":"mcm","clk":"1012033402","pt":1580659107928,"mc":[{"id":"1.168223930","rc":[{"batb":[[0,2.1,50.67],[1,2.06,53.5],[2,1.01,15.51]],"batl":[[0,2.84,228.62],[1,2.84,0]],"ltp":0.0,"tv":0.0,"id":8444055},{"batl":[[0,2.4,289.78],[1,2.4,0]],"ltp":0.0,"tv":0.0,"id":8257852}]}]}
{"op":"mcm","clk":"1012033705","pt":1580659110034,"mc":[{"id":"1.168223930","rc":[{"batb":[[1,2.08,38.65],[2,2.06,53.5]],"batl":[[0,2.34,31.09],[1,2.84,228.62]],"ltp":0.0,"tv":0.0,"id":8444055},{"batb":[[2,1.75,100.07]],"batl":[[0,1.92,42.01],[1,2.4,289.78]],"ltp":0.0,"tv":0.0,"id":8257852}]}]}
{"op":"mcm","clk":"1012034688","pt":1580659117262,"mc":[{"id":"1.168223930","rc":[{"batb":[[0,2.08,38.65],[1,2.06,53.5],[2,1.01,15.51]],"ltp":0.0,"tv":0.0,"id":8444055},{"batb":[[0,1.76,146.48],[1,1.75,100.07],[2,1.01,15.51]],"ltp":0.0,"tv":0.0,"id":8257852}]}]}
{"op":"mcm","clk":"1012035047","pt":1580659120243,"mc":[{"id":"1.168223930","rc":[{"batb":[[1,2.06,53.27]],"ltp":0.0,"tv":0.0,"id":8444055},{"batb":[[1,1.75,55.45],[2,1.74,44.85]],"batl":[[0,1.92,42.02]],"ltp":0.0,"tv":0.0,"id":8257852}]}]}
{"op":"mcm","clk":"1012036097","pt":1580659128210,"mc":[{"id":"1.168223930","rc":[{"batb":[[0,1.75,55.45],[1,1.74,44.85],[2,1.01,15.51]],"ltp":0.0,"tv":0.0,"id":8257852}]}]}
{"op":"mcm","clk":"1012036329","pt":1580659130095,"mc":[{"id":"1.168223930","rc":[{"batb":[[0,2.06,53.27],[1,1.01,15.51],[2,1.01,0]],"batl":[[0,2.84,228.62],[1,2.84,0]],"ltp":0.0,"tv":0.0,"id":8444055},{"batb":[[0,1.74,44.85],[1,1.01,15.51],[2,1.01,0]],"batl":[[0,2.4,289.8],[1,2.4,0]],"ltp":0.0,"tv":0.0,"id":8257852}]}]}
{"op":"mcm","clk":"1012038632","pt":1580659147014,"mc":[{"id":"1.168223930","rc":[{"batl":[[0,1.81,0.02]],"ltp":0.0,"tv":0.0,"id":8257852}]}]}
{"op":"mcm","clk":"1012038925","pt":1580659149195,"mc":[{"id":"1.168223930","rc":[{"batb":[[0,2.18,44.85],[1,2.14,47.92],[2,2.06,53.27]],"ltp":0.0,"tv":0.0,"id":8444055},{"batb":[[1,1.69,50.36],[2,1.01,15.51]],"ltp":0.0,"tv":0.0,"id":8257852}]}]}
{"op":"mcm","clk":"1012039039","pt":1580659150202,"mc":[{"id":"1.168223930","rc":[{"batb":[[2,1.01,15.51]],"ltp":0.0,"tv":0.0,"id":8444055}]}]}
{"op":"mcm","clk":"1012039090","pt":1580659150729,"mc":[{"id":"1.168223930","rc":[{"batb":[[2,2.12,36.97]],"batl":[[0,2.4,29.41],[1,2.84,228.62]],"ltp":0.0,"tv":0.0,"id":8444055},{"batb":[[1,1.73,57.13],[2,1.69,50.36]],"batl":[[0,2.3,310.11]],"ltp":0.0,"tv":0.0,"id":8257852}]}]}
{"op":"mcm","clk":"1012039286","pt":1580659152118,"mc":[{"id":"1.168223930","rc":[{"batl":[[0,1.89,42.02],[1,2.3,310.1]],"ltp":0.0,"tv":0.0,"id":8257852}]}]}
{"op":"mcm","clk":"1012044265","pt":1580659189971,"mc":[{"id":"1.168223930","rc":[{"batb":[[2,1.72,734.84]],"ltp":0.0,"tv":0.0,"id":8257852}]}]}
{"op":"mcm","clk":"1012044998","pt":1580659196087,"mc":[{"id":"1.168223930","rc":[{"batb":[[0,2.14,47.92],[1,2.12,36.97],[2,1.01,15.51]],"ltp":0.0,"tv":0.0,"id":8444055},{"batb":[[0,1.73,57.13],[1,1.69,50.36],[2,1.01,15.51]],"ltp":0.0,"tv":0.0,"id":8257852}]}]}
{"op":"mcm","clk":"1012045223","pt":1580659197978,"mc":[{"id":"1.168223930","rc":[{"batb":[[1,1.01,15.51],[2,1.01,0]],"batl":[[0,2.84,228.62],[1,2.84,0]],"ltp":0.0,"tv":0.0,"id":8444055},{"batb":[[0,1.69,50.36],[1,1.01,15.51],[2,1.01,0]],"batl":[[0,2.3,310.11],[1,2.3,0]],"ltp":0.0,"tv":0.0,"id":8257852}]}]}
{"op":"mcm","clk":"1012045397","pt":1580659199165,"mc":[{"id":"1.168223930","rc":[{"batb":[[0,2.14,47.13]],"ltp":0.0,"tv":0.0,"id":8444055},{"batb":[[0,1.68,50.99]],"ltp":0.0,"tv":0.0,"id":8257852}]}]}
{"op":"mcm","clk":"1012048459","pt":1580659219223,"mc":[{"id":"1.168223930","rc":[{"batb":[[1,2.06,53.5],[2,1.01,15.51]],"ltp":0.0,"tv":0.0,"id":8444055},{"batb":[[0,1.77,42.88],[1,1.74,45.4],[2,1.68,50.99]],"ltp":0.0,"tv":0.0,"id":8257852}]}]}
{"op":"mcm","clk":"1012048609","pt":1580659220210,"mc":[{"id":"1.168223930","rc":[{"batb":[[2,1.01,15.51]],"ltp":0.0,"tv":0.0,"id":8257852}]}]}
{"op":"mcm","clk":"1012048746","pt":1580659221226,"mc":[{"id":"1.168223930","rc":[{"batb":[[1,2.12,36.97],[2,2.06,53.5]],"batl":[[0,2.38,30.25],[1,2.84,228.62]],"ltp":0.0,"tv":0.0,"id":8444055},{"batb":[[2,1.72,57.97]],"batl":[[0,1.89,42.02],[1,2.3,310.1]],"ltp":0.0,"tv":0.0,"id":8257852}]}]}
{"op":"mcm","clk":"1012048829","pt":1580659221823,"mc":[{"id":"1.168223930","rc":[{"batl":[[0,2.84,228.62],[1,2.84,0]],"ltp":0.0,"tv":0.0,"id":8444055},{"batb":[[2,1.01,15.51]],"batl":[[0,2.3,310.11],[1,2.3,0]],"ltp":0.0,"tv":0.0,"id":8257852}]}]}
{"op":"mcm","clk":"1012048932","pt":1580659222729,"mc":[{"id":"1.168223930","rc":[{"batb":[[2,1.73,229.13]],"ltp":0.0,"tv":0.0,"id":8257852}]}]}
{"op":"mcm","clk":"1012049233","pt":1580659225250,"mc":[{"id":"1.168223930","rc":[{"batl":[[0,2.36,30.25],[1,2.84,228.62]],"ltp":0.0,"tv":0.0,"id":8444055},{"batb":[[2,1.73,57.13]],"batl":[[0,1.9,42.02],[1,2.3,310.1]],"ltp":0.0,"tv":0.0,"id":8257852}]}]}
{"op":"mcm","clk":"1012049759","pt":1580659229067,"mc":[{"id":"1.168223930","rc":[{"batl":[[0,2.34,169.25],[1,2.36,30.25],[2,2.84,228.62]],"ltp":0.0,"tv":0.0,"id":8444055}]}]}
{"op":"mcm","clk":"1012050123","pt":1580659231268,"mc":[{"id":"1.168223930","rc":[{"batl":[[0,2.36,30.25],[1,2.84,228.62],[2,2.84,0]],"ltp":0.0,"tv":0.0,"id":8444055}]}]}
{"op":"mcm","clk":"1012050580","pt":1580659234135,"mc":[{"id":"1.168223930","rc":[{"batl":[[0,2.34,110.24],[1,2.36,30.25],[2,2.84,228.62]],"ltp":0.0,"tv":0.0,"id":8444055}]}]}
{"op":"mcm","clk":"1012050864","pt":1580659236156,"mc":[{"id":"1.168223930","rc":[{"batb":[[0,2.12,36.97],[1,2.06,53.5],[2,1.01,15.51]],"batl":[[0,2.36,30.25],[1,2.84,228.62],[2,2.84,0]],"ltp":0.0,"tv":0.0,"id":8444055},{"batb":[[0,1.74,45.4],[1,1.73,57.13],[2,1.01,15.51]],"ltp":0.0,"tv":0.0,"id":8257852}]}]}
{"op":"mcm","clk":"1012051182","pt":1580659238264,"mc":[{"id":"1.168223930","rc":[{"batb":[[0,2.06,53.5],[1,1.01,15.51],[2,1.01,0]],"batl":[[0,2.84,228.62],[1,2.84,0]],"ltp":0.0,"tv":0.0,"id":8444055},{"batb":[[1,1.01,15.51],[2,1.01,0]],"batl":[[0,2.3,310.11],[1,2.3,0]],"ltp":0.0,"tv":0.0,"id":8257852}]}]}
{"op":"mcm","clk":"1012052279","pt":1580659245262,"mc":[{"id":"1.168223930","rc":[{"batb":[[0,2.06,615.41]],"ltp":0.0,"tv":0.0,"id":8444055}]}]}
{"op":"mcm","clk":"1012052460","pt":1580659246265,"mc":[{"id":"1.168223930","rc":[{"batb":[[0,2.2,44.3],[1,2.1,50.28],[2,1.01,15.51]],"ltp":0.0,"tv":0.0,"id":8444055},{"batb":[[1,1.71,48.07],[2,1.01,15.51]],"ltp":0.0,"tv":0.0,"id":8257852}]}]}
{"op":"mcm","clk":"1012052614","pt":1580659246996,"mc":[{"id":"1.168223930","rc":[{"batb":[[1,2.14,36.13],[2,2.1,50.28]],"batl":[[0,2.4,29.41],[1,2.84,228.62]],"ltp":0.0,"tv":0.0,"id":8444055},{"batb":[[1,1.73,57.13],[2,1.71,48.07]],"batl":[[0,1.88,42.02],[1,2.3,310.1]],"ltp":0.0,"tv":0.0,"id":8257852}]}]}
{"op":"mcm","clk":"1012054735","pt":1580659261085,"mc":[{"id":"1.168223930","rc":[{"batb":[[0,2.14,36.13],[1,2.1,50.28],[2,1.01,15.51]],"ltp":0.0,"tv":0.0,"id":8444055},{"batb":[[0,1.73,57.13],[1,1.71,48.07],[2,1.01,15.51]],"ltp":0.0,"tv":0.0,"id":8257852}]}]}
{"op":"mcm","clk":"1012054891","pt":1580659261896,"mc":[{"id":"1.168223930","rc":[{"batb":[[0,2.1,50.28],[1,1.01,15.51],[2,1.01,0]],"batl":[[0,2.84,228.62],[1,2.84,0]],"ltp":0.0,"tv":0.0,"id":8444055},{"batb":[[0,1.71,48.07],[1,1.01,15.51],[2,1.01,0]],"batl":[[0,2.3,310.11],[1,2.3,0]],"ltp":0.0,"tv":0.0,"id":8257852}]}]}
{"op":"mcm","clk":"1012058400","pt":1580659285237,"mc":[{"id":"1.168223930","rc":[{"batb":[[1,2.06,53.35],[2,1.01,15.51]],"ltp":0.0,"tv":0.0,"id":8444055},{"batb":[[0,1.8,40.36],[1,1.79,193.74],[2,1.74,45.16]],"ltp":0.0,"tv":0.0,"id":8257852}]}]}
{"op":"mcm","clk":"1012058691","pt":1580659287238,"mc":[{"id":"1.168223930","rc":[{"batb":[[1,2.08,38.65],[2,2.06,53.35]],"batl":[[0,2.34,31.09],[1,2.84,228.62]],"ltp":0.0,"tv":0.0,"id":8444055},{"batb":[[1,1.75,55.45]],"batl":[[0,1.91,42.02],[1,2.3,310.1]],"ltp":0.0,"tv":0.0,"id":8257852}]}]}
{"op":"mcm","clk":"1012059134","pt":1580659290127,"mc":[{"id":"1.168223930","rc":[{"trd":[[1.81,0.04]],"batb":[[0,1.81,191.64],[1,1.8,40.36],[2,1.75,55.45]],"batl":[[0,1.91,42.01]],"ltp":1.81,"tv":0.03,"id":8257852}],"tv":0.03}]}
{"op":"mcm","clk":"1012062542","pt":1580659312155,"mc":[{"id":"1.168223930","rc":[{"batb":[[0,2.06,53.35],[1,1.01,15.51],[2,2.06,0]],"batl":[[0,2.84,228.62],[1,2.84,0]],"ltp":0.0,"tv":0.0,"id":8444055},{"batb":[[0,1.74,45.01],[1,1.01,15.52],[2,1.75,0]],"batl":[[0,2.3,310.1],[1,2.3,0]],"ltp":1.81,"tv":0.03,"id":8257852}]}]}
{"op":"mcm","clk":"1012062650","pt":1580659312957,"mc":[{"id":"1.168223930","rc":[{"batb":[[1,1.01,15.51]],"ltp":1.81,"tv":0.03,"id":8257852}]}]}
{"op":"mcm","clk":"1012063171","pt":1580659316264,"mc":[{"id":"1.168223930","rc":[{"batb":[[0,1.74,45.02]],"ltp":1.81,"tv":0.03,"id":8257852}]}]}
{"op":"mcm","clk":"1012064924","pt":1580659327252,"mc":[{"id":"1.168223930","rc":[{"batb":[[0,2.18,44.69],[1,2.12,85.36],[2,1.01,15.51]],"batl":[[0,2.38,30.25],[1,2.84,228.62]],"ltp":0.0,"tv":0.0,"id":8444055},{"batb":[[1,1.73,57.13],[2,1.68,51.06]],"ltp":1.81,"tv":0.03,"id":8257852}]}]}
{"op":"mcm","clk":"1012065076","pt":1580659328077,"mc":[{"id":"1.168223930","rc":[{"batb":[[1,2.12,97.9]],"ltp":0.0,"tv":0.0,"id":8444055},{"batl":[[0,1.89,42.01],[1,2.3,310.1]],"ltp":1.81,"tv":0.03,"id":8257852}]}]}
{"op":"mcm","clk":"1012068284","pt":1580659349106,"mc":[{"id":"1.168223930","rc":[{"batb":[[0,2.12,85.36],[1,1.01,15.51],[2,1.01,0]],"ltp":0.0,"tv":0.0,"id":8444055},{"batb":[[0,1.73,57.15],[1,1.68,51.06],[2,1.01,15.51]],"ltp":1.81,"tv":0.03,"id":8257852}]}]}
{"op":"mcm","clk":"1012068445","pt":1580659350226,"mc":[{"id":"1.168223930","rc":[{"batb":[[0,2.12,48.39]],"batl":[[0,2.84,228.62],[1,2.84,0]],"ltp":0.0,"tv":0.0,"id":8444055},{"batb":[[0,1.68,51.08],[1,1.01,15.51],[2,1.01,0]],"batl":[[0,2.3,310.1],[1,2.3,0]],"ltp":1.81,"tv":0.03,"id":8257852}]}]}
{"op":"mcm","clk":"1012068738","pt":1580659352216,"mc":[{"id":"1.168223930","rc":[{"batb":[[0,2.14,47.76]],"ltp":0.0,"tv":0.0,"id":8444055},{"batb":[[0,1.69,50.21]],"ltp":1.81,"tv":0.03,"id":8257852}]}]}
{"op":"mcm","clk":"1012071014","pt":1580659366243,"mc":[{"id":"1.168223930","rc":[{"trd":[[2.24,0.01]],"batb":[[0,2.28,39.64],[1,2.18,45.08],[2,1.01,15.51]],"ltp":2.24,"tv":0.01,"id":8444055},{"trd":[[1.81,0.05]],"batb":[[0,1.69,50.2],[1,1.66,52.95],[2,1.01,15.51]],"ltp":1.81,"tv":0.05,"id":8257852}],"tv":0.06}]}
{"op":"mcm","clk":"1012071318","pt":1580659368234,"mc":[{"id":"1.168223930","rc":[{"batb":[[1,2.2,34.45],[2,2.18,45.08]],"batl":[[0,3.15,200.24]],"ltp":2.24,"tv":0.01,"id":8444055},{"batb":[[1,1.68,61.33],[2,1.66,52.95]],"batl":[[0,1.84,42.01],[1,2.3,310.1]],"ltp":1.81,"tv":0.05,"id":8257852}]}]}
{"op":"mcm","clk":"1012071422","pt":1580659369023,"mc":[{"id":"1.168223930","rc":[{"batl":[[0,2.3,310.1],[1,2.3,0]],"ltp":1.81,"tv":0.05,"id":8257852}]}]}
{"op":"mcm","clk":"1012071534","pt":1580659369825,"mc":[{"id":"1.168223930","rc":[{"batl":[[0,2.5,27.73],[1,3.15,200.24]],"ltp":2.24,"tv":0.01,"id":8444055}]}]}
{"op":"mcm","clk":"1012071912","pt":1580659372131,"mc":[{"id":"1.168223930","rc":[{"batl":[[0,1.83,42.01],[1,2.3,310.1]],"ltp":1.81,"tv":0.05,"id":8257852}]}]}
{"op":"mcm","clk":"1012074857","pt":1580659389152,"mc":[{"id":"1.168223930","rc":[{"batb":[[0,2.2,34.45],[1,2.18,45.08],[2,1.01,15.51]],"ltp":2.24,"tv":0.01,"id":8444055},{"batb":[[0,1.68,61.33],[1,1.66,52.95],[2,1.01,15.51]],"ltp":1.81,"tv":0.05,"id":8257852}]}]}
{"op":"mcm","clk":"1012075001","pt":1580659390047,"mc":[{"id":"1.168223930","rc":[{"batb":[[0,2.18,45.08],[1,1.01,15.51],[2,1.01,0]],"batl":[[0,3.15,200.24],[1,3.15,0]],"ltp":2.24,"tv":0.01,"id":8444055},{"batb":[[0,1.66,52.95],[1,1.01,15.51],[2,1.01,0]],"batl":[[0,2.3,310.1],[1,2.3,0]],"ltp":1.81,"tv":0.05,"id":8257852}]}]}
{"op":"mcm","clk":"1012075373","pt":1580659392143,"mc":[{"id":"1.168223930","rc":[{"batb":[[0,2.2,43.75]],"ltp":2.24,"tv":0.01,"id":8444055},{"batb":[[0,1.64,56.1]],"ltp":1.81,"tv":0.05,"id":8257852}]}]}
{"op":"mcm","clk":"1012076111","pt":1580659397188,"mc":[{"id":"1.168223930","rc":[{"batb":[[1,2.16,36.13],[2,2.1,50.67]],"batl":[[0,2.42,29.41]],"ltp":2.24,"tv":0.01,"id":8444055},{"batb":[[0,1.73,45.95],[1,1.71,58.81],[2,1.7,49.02]],"batl":[[0,1.87,42.01],[1,2.3,310.1]],"ltp":1.81,"tv":0.05,"id":8257852}]}]}
{"op":"mcm","clk":"1012076435","pt":1580659399269,"mc":[{"id":"1.168223930","rc":[{"batl":[[1,3,213.2]],"ltp":2.24,"tv":0.01,"id":8444055}]}]}
{"op":"mcm","clk":"1012077365","pt":1580659405260,"mc":[{"id":"1.168223930","rc":[{"batb":[[1,2.18,44.38],[2,2.16,36.13]],"ltp":2.24,"tv":0.01,"id":8444055},{"batb":[[0,1.74,45.32],[1,1.73,45.95],[2,1.71,58.81]],"ltp":1.81,"tv":0.05,"id":8257852}]}]}
{"op":"mcm","clk":"1012077488","pt":1580659406197,"mc":[{"id":"1.168223930","rc":[{"batb":[[0,2.18,44.38],[1,2.16,36.13],[2,2.08,51.69]],"ltp":2.24,"tv":0.01,"id":8444055},{"batb":[[1,1.71,58.81],[2,1.7,48.7]],"ltp":1.81,"tv":0.05,"id":8257852}]}]}
{"op":"mcm","clk":"1012083915","pt":1580659446144,"mc":[{"id":"1.168223930","rc":[{"batb":[[0,2.08,51.69],[1,1.01,15.51],[2,2.08,0]],"batl":[[0,3,213.2],[1,3,0]],"ltp":2.24,"tv":0.01,"id":8444055},{"batb":[[0,1.7,48.7],[1,1.01,15.51],[2,1.7,0]],"batl":[[0,2.3,310.1],[1,2.3,0]],"ltp":1.81,"tv":0.05,"id":8257852}]}]}
{"op":"mcm","clk":"1012086196","pt":1580659459251,"mc":[{"id":"1.168223930","rc":[{"batb":[[0,2.1,37.81],[1,2.08,51.69],[2,2.02,55.79]],"batl":[[0,2.36,30.25]],"ltp":2.24,"tv":0.01,"id":8444055},{"batb":[[0,1.82,39.34],[1,1.75,55.45],[2,1.74,45.16]],"batl":[[0,1.92,42.01],[1,2.3,310.1]],"ltp":1.81,"tv":0.05,"id":8257852}]}]}
{"op":"mcm","clk":"1012086482","pt":1580659461104,"mc":[{"id":"1.168223930","rc":[{"batl":[[1,2.84,228.44]],"ltp":2.24,"tv":0.01,"id":8444055}]}]}
{"op":"mcm","clk":"1012086974","pt":1580659463970,"mc":[{"id":"1.168223930","rc":[{"batb":[[0,1.83,636.21],[1,1.82,39.34],[2,1.75,55.45]],"ltp":1.81,"tv":0.05,"id":8257852}]}]}
{"op":"mcm","clk":"1012090125","pt":1580659483195,"mc":[{"id":"1.168223930","rc":[{"batb":[[1,2.02,55.79],[2,1.01,15.51]],"ltp":2.24,"tv":0.01,"id":8444055},{"batb":[[0,1.75,55.45],[1,1.74,45.16],[2,1.01,15.51]],"ltp":1.81,"tv":0.05,"id":8257852}]}]}
{"op":"mcm","clk":"1012090272","pt":1580659484106,"mc":[{"id":"1.168223930","rc":[{"batb":[[0,2.02,55.79],[1,1.01,15.51],[2,1.01,0]],"batl":[[0,2.84,228.44],[1,2.84,0]],"ltp":2.24,"tv":0.01,"id":8444055},{"batb":[[0,1.74,45.16],[1,1.01,15.51],[2,1.01,0]],"batl":[[0,2.3,310.1],[1,2.3,0]],"ltp":1.81,"tv":0.05,"id":8257852}]}]}
{"op":"mcm","clk":"1012090588","pt":1580659486199,"mc":[{"id":"1.168223930","rc":[{"batb":[[0,1.75,44.53],[1,1.74,45.16],[2,1.01,15.51]],"ltp":1.81,"tv":0.05,"id":8257852}]}]}
{"op":"mcm","clk":"1012090766","pt":1580659487270,"mc":[{"id":"1.168223930","rc":[{"batb":[[1,1.01,15.51],[2,1.01,0]],"ltp":1.81,"tv":0.05,"id":8257852}]}]}
{"op":"mcm","clk":"1012093815","pt":1580659505242,"mc":[{"id":"1.168223930","rc":[{"batb":[[1,1.95,323.04],[2,1.93,293.18]],"batl":[[0,2.04,234.01],[1,2.06,245.66],[2,2.84,228.44]],"ltp":2.24,"tv":0.01,"id":8444055}]}]}
{"op":"mcm","clk":"1012093966","pt":1580659506214,"mc":[{"id":"1.168223930","rc":[{"batb":[[0,1.87,35.96],[1,1.7,49.41],[2,1.01,15.51]],"ltp":1.81,"tv":0.05,"id":8257852}]}]}
{"op":"mcm","clk":"1012094139","pt":1580659507228,"mc":[{"id":"1.168223930","rc":[{"batb":[[1,2,42.01],[2,1.95,323.04]],"batl":[[2,2.24,33.61]],"ltp":2.24,"tv":0.01,"id":8444055},{"batb":[[1,1.82,50.41],[2,1.7,49.41]],"batl":[[0,2,42.01]],"ltp":1.81,"tv":0.05,"id":8257852}]}]}
{"op":"mcm","clk":"1012094798","pt":1580659511059,"mc":[{"id":"1.168223930","rc":[{"batl":[[1,2.42,73.23]],"ltp":1.81,"tv":0.05,"id":8257852}]}]}
{"op":"mcm","clk":"1012095333","pt":1580659514217,"mc":[{"id":"1.168223930","rc":[{"batb":[[0,1.87,35.8],[2,1.69,49.81]],"ltp":1.81,"tv":0.05,"id":8257852}]}]}
{"op":"mcm","clk":"1012095997","pt":1580659518172,"mc":[{"id":"1.168223930","rc":[{"batb":[[2,1.91,33.68]],"batl":[[0,2.24,33.61],[1,2.84,228.44],[2,2.24,0]],"ltp":2.24,"tv":0.01,"id":8444055}]}]}
{"op":"mcm","clk":"1012096168","pt":1580659519240,"mc":[{"id":"1.168223930","rc":[{"batl":[[0,1.96,2],[1,2,42.01],[2,2.42,73.23]],"ltp":1.81,"tv":0.05,"id":8257852}]}]}
{"op":"mcm","clk":"1012096510","pt":1580659521242,"mc":[{"id":"1.168223930","rc":[{"trd":[[1.96,4]],"batb":[[0,1.95,329.03],[1,1.93,292.99],[2,1.87,35.8]],"batl":[[0,2,42.01],[1,2.04,210.68],[2,2.06,245.77]],"ltp":1.96,"tv":4.05,"id":8257852}],"tv":4.06}]}
{"op":"mcm","clk":"1012096675","pt":1580659522216,"mc":[{"id":"1.168223930","rc":[{"batl":[[1,2.04,246.39]],"ltp":1.96,"tv":4.05,"id":8257852}]}]}
{"op":"mcm","clk":"1012096847","pt":1580659523247,"mc":[{"id":"1.168223930","rc":[{"batb":[[0,2,99.13],[1,1.91,33.68],[2,1.01,15.51]],"ltp":2.24,"tv":0.01,"id":8444055}]}]}
{"op":"mcm","clk":"1012098325","pt":1580659531240,"mc":[{"id":"1.168223930","rc":[{"batb":[[1,1.9,33.99]],"ltp":2.24,"tv":0.01,"id":8444055},{"batb":[[2,1.88,35.49]],"ltp":1.96,"tv":4.05,"id":8257852}]}]}
{"op":"mcm","clk":"1012098491","pt":1580659532258,"mc":[{"id":"1.168223930","rc":[{"batl":[[0,1.98,150],[1,2,42.01],[2,2.04,246.39]],"ltp":1.96,"tv":4.05,"id":8257852}]}]}
{"op":"mcm","clk":"1012099274","pt":1580659536239,"mc":[{"id":"1.168223930","rc":[{"batb":[[2,1.88,35.33]],"ltp":1.96,"tv":4.05,"id":8257852}]}]}
{"op":"mcm","clk":"1012099469","pt":1580659537253,"mc":[{"id":"1.168223930","rc":[{"batl":[[0,2.84,228.44],[1,2.84,0]],"ltp":2.24,"tv":0.01,"id":8444055}]}]}
{"op":"mcm","clk":"1012099968","pt":1580659540167,"mc":[{"id":"1.168223930","rc":[{"batl":[[0,2.22,33.61],[1,2.84,228.44]],"ltp":2.24,"tv":0.01,"id":8444055}]}]}
{"op":"mcm","clk":"1012101247","pt":1580659547270,"mc":[{"id":"1.168223930","rc":[{"batb":[[1,1.89,34.46]],"ltp":2.24,"tv":0.01,"id":8444055},{"batb":[[2,1.88,35.01]],"ltp":1.96,"tv":4.05,"id":8257852}]}]}
{"op":"mcm","clk":"1012103283","pt":1580659558191,"mc":[{"id":"1.168223930","rc":[{"batl":[[0,2,42.01],[1,2.04,246.39],[2,2.06,245.77]],"ltp":1.96,"tv":4.05,"id":8257852}]}]}
{"op":"mcm","clk":"1012103781","pt":1580659561087,"mc":[{"id":"1.168223930","rc":[{"trd":[[1.95,300]],"batb":[[0,1.95,179.03]],"ltp":1.95,"tv":304.05,"id":8257852}],"tv":304.06}]}
{"op":"mcm","clk":"1012104305","pt":1580659564088,"mc":[{"id":"1.168223930","rc":[{"batb":[[0,1.95,246.03]],"batl":[[1,2.04,307.63]],"ltp":1.95,"tv":304.05,"id":8257852}]}]}
{"op":"mcm","clk":"1012112939","pt":1580659610165,"mc":[{"id":"1.168223930","rc":[{"trd":[[1.95,582.96]],"batb":[[0,1.88,35.01],[1,1.82,50.41],[2,1.7,48.7]],"ltp":1.95,"tv":587.01,"id":8257852}],"tv":587.02}]}
{"op":"mcm","clk":"1012113470","pt":1580659613147,"mc":[{"id":"1.168223930","rc":[{"batb":[[0,1.94,340.16],[1,1.92,297.75],[2,1.88,35.01]],"batl":[[1,2.04,357.17]],"ltp":1.95,"tv":587.01,"id":8257852}]}]}
{"op":"mcm","clk":"1012117873","pt":1580659636997,"mc":[{"id":"1.168223930","rc":[{"batb":[[0,1.88,35.01],[1,1.82,50.41],[2,1.7,48.7]],"batl":[[1,2.42,73.23],[2,2.06,0]],"ltp":1.95,"tv":587.01,"id":8257852}]}]}
{"op":"mcm","clk":"1012118106","pt":1580659638199,"mc":[{"id":"1.168223930","rc":[{"batb":[[0,1.89,34.46],[1,1.01,15.51],[2,1.01,0]],"batl":[[0,2.84,228.44],[1,2.84,0]],"ltp":2.24,"tv":0.01,"id":8444055},{"batb":[[0,1.7,48.7],[1,1.01,15.51],[2,1.7,0]],"batl":[[0,2.42,73.23],[1,2.42,0]],"ltp":1.95,"tv":587.01,"id":8257852}]}]}
{"op":"mcm","clk":"1012118438","pt":1580659639971,"mc":[{"id":"1.168223930","rc":[{"batb":[[0,1.77,229.69],[1,1.75,403.35],[2,1.7,48.7]],"batl":[[0,2.16,342.62],[1,2.18,208.78],[2,2.42,73.23]],"ltp":1.95,"tv":587.01,"id":8257852}]}]}
{"op":"mcm","clk":"1012118984","pt":1580659643067,"mc":[{"id":"1.168223930","rc":[{"batb":[[0,1.7,48.7],[1,1.01,15.51],[2,1.7,0]],"batl":[[0,2.42,73.23],[1,2.18,0],[2,2.42,0]],"ltp":1.95,"tv":587.01,"id":8257852}]}]}
{"op":"mcm","clk":"1012119581","pt":1580659646197,"mc":[{"id":"1.168223930","rc":[{"batb":[[0,1.91,216.78],[1,1.89,313.06],[2,1.7,48.7]],"batl":[[0,1.99,265.62],[1,2.02,392.67],[2,2.42,73.23]],"ltp":1.95,"tv":587.01,"id":8257852}]}]}
{"op":"mcm","clk":"1012119734","pt":1580659647007,"mc":[{"id":"1.168223930","rc":[{"batb":[[0,1.7,48.7],[1,1.01,15.51],[2,1.7,0]],"batl":[[0,2.42,73.23],[1,2.02,0],[2,2.42,0]],"ltp":1.95,"tv":587.01,"id":8257852}]}]}
{"op":"mcm","clk":"1012120295","pt":1580659649949,"mc":[{"id":"1.168223930","rc":[{"batb":[[0,1.77,229.69],[1,1.75,403.35],[2,1.7,48.7]],"batl":[[0,2.16,342.62],[1,2.18,208.78],[2,2.42,73.23]],"ltp":1.95,"tv":587.01,"id":8257852}]}]}
{"op":"mcm","clk":"1012121785","pt":1580659658127,"mc":[{"id":"1.168223930","rc":[{"batb":[[0,1.7,48.7],[1,1.01,15.51],[2,1.7,0]],"batl":[[0,2.42,73.23],[1,2.18,0],[2,2.42,0]],"ltp":1.95,"tv":587.01,"id":8257852}]}]}
{"op":"mcm","clk":"1012122310","pt":1580659660991,"mc":[{"id":"1.168223930","rc":[{"batb":[[1,1.87,265.53],[2,1.85,334.51]],"batl":[[0,1.95,276.29],[1,1.97,279.73]],"ltp":2.24,"tv":0.01,"id":8444055}]}]}
{"op":"mcm","clk":"1012122532","pt":1580659662188,"mc":[{"id":"1.168223930","rc":[{"batb":[[0,1.99,59.25],[1,1.82,38.79],[2,1.01,15.51]],"ltp":1.95,"tv":587.01,"id":8257852}]}]}
{"op":"mcm","clk":"1012122722","pt":1580659663166,"mc":[{"id":"1.168223930","rc":[{"batb":[[0,1.89,81.51]],"batl":[[2,2.1,37.81]],"ltp":2.24,"tv":0.01,"id":8444055},{"batb":[[1,1.91,45.37],[2,1.82,38.79]],"batl":[[0,2.12,36.97],[1,2.42,73.23]],"ltp":1.95,"tv":587.01,"id":8257852}]}]}
{"op":"mcm","clk":"1012125134","pt":1580659676126,"mc":[{"id":"1.168223930","rc":[{"batb":[[1,1.82,39.34],[2,1.01,15.51]],"batl":[[0,2.1,37.81],[1,2.72,428.21],[2,2.1,0]],"ltp":2.24,"tv":0.01,"id":8444055}]}]}
{"op":"mcm","clk":"1012125314","pt":1580659677036,"mc":[{"id":"1.168223930","rc":[{"batb":[[0,1.89,47.05]],"ltp":2.24,"tv":0.01,"id":8444055},{"batb":[[0,1.91,45.37],[1,1.82,38.79],[2,1.01,15.51]],"ltp":1.95,"tv":587.01,"id":8257852}]}]}
{"op":"mcm","clk":"1012125550","pt":1580659678123,"mc":[{"id":"1.168223930","rc":[{"batb":[[0,1.82,39.34],[1,1.01,15.51],[2,1.01,0]],"batl":[[0,2.72,428.21],[1,2.72,0]],"ltp":2.24,"tv":0.01,"id":8444055},{"batb":[[0,1.82,38.79],[1,1.01,15.51],[2,1.01,0]],"batl":[[0,2.42,73.23],[1,2.42,0]],"ltp":1.95,"tv":587.01,"id":8257852}]}]}
{"op":"mcm","clk":"1012126376","pt":1580659682133,"mc":[{"id":"1.168223930","rc":[{"batb":[[1,1.8,295.5],[2,1.78,378.93]],"batl":[[0,1.87,209.96],[1,1.89,317.05]],"ltp":2.24,"tv":0.01,"id":8444055}]}]}
{"op":"mcm","clk":"1012126558","pt":1580659683149,"mc":[{"id":"1.168223930","rc":[{"batb":[[0,1.82,89.75]],"batl":[[2,2.02,41.17]],"ltp":2.24,"tv":0.01,"id":8444055},{"batb":[[0,2.08,51.62],[1,1.99,42.01],[2,1.94,31.79]],"batl":[[0,2.2,34.45]],"ltp":1.95,"tv":587.01,"id":8257852}]}]}
{"op":"mcm","clk":"1012126952","pt":1580659685233,"mc":[{"id":"1.168223930","rc":[{"batl":[[1,2.72,49.62]],"ltp":1.95,"tv":587.01,"id":8257852}]}]}
{"op":"mcm","clk":"1012128100","pt":1580659691254,"mc":[{"id":"1.168223930","rc":[{"trd":[[1.87,209.96]],"batl":[[0,1.89,317.05],[1,2.02,41.17],[2,2.5,484.62]],"ltp":1.87,"tv":209.97,"id":8444055},{"trd":[[2.14,183.47]],"batl":[[0,2.14,16.53],[1,2.2,34.45],[2,2.72,49.62]],"ltp":2.14,"tv":770.48,"id":8257852}],"tv":980.45}]}
{"op":"mcm","clk":"1012128265","pt":1580659692165,"mc":[{"id":"1.168223930","rc":[{"batl":[[0,2.02,41.17],[1,2.5,484.62],[2,2.5,0]],"ltp":1.87,"tv":209.97,"id":8444055}]}]}
{"op":"mcm","clk":"1012128829","pt":1580659694941,"mc":[{"id":"1.168223930","rc":[{"batb":[[0,1.82,50.41],[1,1.76,43.75],[2,1.01,15.51]],"ltp":1.87,"tv":209.97,"id":8444055},{"batb":[[0,1.99,42.01],[1,1.94,31.79],[2,1.01,15.51]],"batl":[[0,2.2,34.45],[1,2.72,49.62],[2,2.72,0]],"ltp":2.14,"tv":770.48,"id":8257852}]}]}
{"op":"mcm","clk":"1012128960","pt":1580659695697,"mc":[{"id":"1.168223930","rc":[{"batb":[[0,1.76,43.75],[1,1.01,15.51],[2,1.01,0]],"batl":[[0,2.5,484.62],[1,2.5,0]],"ltp":1.87,"tv":209.97,"id":8444055},{"batb":[[0,1.94,31.79],[1,1.01,15.51],[2,1.01,0]],"batl":[[0,2.72,49.62],[1,2.72,0]],"ltp":2.14,"tv":770.48,"id":8257852}]}]}
{"op":"mcm","clk":"1012129433","pt":1580659698083,"mc":[{"id":"1.168223930","rc":[{"batb":[[0,1.76,395.35],[1,1.74,408.58],[2,1.01,15.51]],"ltp":1.87,"tv":209.97,"id":8444055},{"batb":[[0,1.95,63.1]],"ltp":2.14,"tv":770.48,"id":8257852}]}]}
{"op":"mcm","clk":"1012129973","pt":1580659701106,"mc":[{"id":"1.168223930","rc":[{"batb":[[0,1.78,53.77],[1,1.76,395.35],[2,1.74,408.58]],"batl":[[0,1.83,226.71],[1,1.85,338.4],[2,1.98,42.01]],"ltp":1.87,"tv":209.97,"id":8444055},{"batb":[[0,2.04,40.33],[1,1.95,63.1],[2,1.01,15.51]],"batl":[[0,2.28,32.77],[1,2.72,49.62]],"ltp":2.14,"tv":770.48,"id":8257852}]}]}
{"op":"mcm","clk":"1012130178","pt":1580659702211,"mc":[{"id":"1.168223930","rc":[{"batb":[[0,2.16,45.87],[1,2.06,53.19],[2,2.04,40.33]],"ltp":2.14,"tv":770.48,"id":8257852}]}]}
{"op":"mcm","clk":"1012130874","pt":1580659705906,"mc":[{"id":"1.168223930","rc":[{"trd":[[1.83,0.19]],"batl":[[0,1.83,226.52]],"ltp":1.83,"tv":210.16,"id":8444055},{"trd":[[2.2,0.16]],"ltp":2.2,"tv":770.63,"id":8257852}],"tv":980.8}]}
{"op":"mcm","clk":"1012132299","pt":1580659713194,"mc":[{"id":"1.168223930","rc":[{"batb":[[1,1.74,319.56],[2,1.72,47.05]],"batl":[[0,1.98,42.01],[1,2.5,484.62],[2,1.98,0]],"ltp":1.83,"tv":210.16,"id":8444055},{"batb":[[0,2.06,53.19],[1,2.04,40.33],[2,1.01,15.51]],"ltp":2.2,"tv":770.63,"id":8257852}]}]}
{"op":"mcm","clk":"1012132392","pt":1580659713703,"mc":[{"id":"1.168223930","rc":[{"batb":[[0,1.74,319.56],[1,1.72,47.05],[2,1.01,15.51]],"batl":[[0,2.5,484.62],[1,2.5,0]],"ltp":1.83,"tv":210.16,"id":8444055},{"batb":[[1,1.01,15.51],[2,1.01,0]],"batl":[[0,2.72,49.62],[1,2.72,0]],"ltp":2.2,"tv":770.63,"id":8257852}]}]}
{"op":"mcm","clk":"1012132695","pt":1580659715215,"mc":[{"id":"1.168223930","rc":[{"batb":[[0,2.06,53.58]],"ltp":2.2,"tv":770.63,"id":8257852}]}]}
{"op":"mcm","clk":"1012132876","pt":1580659716232,"mc":[{"id":"1.168223930","rc":[{"batb":[[0,1.72,47.05],[1,1.01,15.51],[2,1.01,0]],"ltp":1.83,"tv":210.16,"id":8444055}]}]}
{"op":"mcm","clk":"1012133423","pt":1580659719220,"mc":[{"id":"1.168223930","rc":[{"batb":[[0,1.77,328.36],[1,1.75,400.72],[2,1.72,47.05]],"batl":[[0,1.84,230.21],[1,1.86,332.77],[2,2.5,484.62]],"ltp":1.83,"tv":210.16,"id":8444055}]}]}
{"op":"mcm","clk":"1012134189","pt":1580659723194,"mc":[{"id":"1.168223930","rc":[{"batb":[[0,1.72,47.05],[1,1.01,15.51],[2,1.72,0]],"batl":[[0,2.5,484.62],[1,1.86,0],[2,2.5,0]],"ltp":1.83,"tv":210.16,"id":8444055}]}]}
{"op":"mcm","clk":"1012134560","pt":1580659725225,"mc":[{"id":"1.168223930","rc":[{"batb":[[0,1.74,319.56],[1,1.72,471.78],[2,1.01,15.51]],"batl":[[0,1.88,225.3],[1,1.9,311.71],[2,2.5,484.62]],"ltp":1.83,"tv":210.16,"id":8444055}]}]}
{"op":"mcm","clk":"1012135312","pt":1580659729253,"mc":[{"id":"1.168223930","rc":[{"batb":[[0,1.72,47.05],[1,1.01,15.51],[2,1.01,0]],"ltp":1.83,"tv":210.16,"id":8444055}]}]}
{"op":"mcm","clk":"1012135884","pt":1580659732222,"mc":[{"id":"1.168223930","rc":[{"trd":[[1.79,0.5]],"batb":[[0,1.83,38.24],[1,1.81,260.83],[2,1.79,371.67]],"ltp":1.79,"tv":210.66,"id":8444055},{"trd":[[2.28,0.39]],"batb":[[0,2.06,53.19],[1,1.94,31.87],[2,1.01,15.51]],"ltp":2.28,"tv":771.03,"id":8257852}],"tv":981.69}]}
{"op":"mcm","clk":"1012136069","pt":1580659733230,"mc":[{"id":"1.168223930","rc":[{"batl":[[2,2.02,41.17]],"ltp":1.79,"tv":210.66,"id":8444055},{"batb":[[1,1.99,42.01],[2,1.94,31.87]],"ltp":2.28,"tv":771.03,"id":8257852}]}]}
{"op":"mcm","clk":"1012136350","pt":1580659734821,"mc":[{"id":"1.168223930","rc":[{"batb":[[0,1.83,88.65]],"ltp":1.79,"tv":210.66,"id":8444055},{"batl":[[0,2.2,34.45],[1,2.72,49.62]],"ltp":2.28,"tv":771.03,"id":8257852}]}]}
{"op":"mcm","clk":"1012137358","pt":1580659740152,"mc":[{"id":"1.168223930","rc":[{"batl":[[2,1000,2.36]],"ltp":2.28,"tv":771.03,"id":8257852}]}]}
{"op":"mcm","clk":"1012137429","pt":1580659740633,"mc":[{"id":"1.168223930","rc":[{"batl":[[2,1000,0]],"ltp":2.28,"tv":771.03,"id":8257852}]}]}
{"op":"mcm","clk":"1012138103","pt":1580659744044,"mc":[{"id":"1.168223930","rc":[{"batl":[[2,2.88,0.31]],"ltp":2.28,"tv":771.03,"id":8257852}]}]}
{"op":"mcm","clk":"1012139263","pt":1580659750249,"mc":[{"id":"1.168223930","rc":[{"batb":[[0,1.83,50.41],[1,1.77,42.65],[2,1.01,15.51]],"batl":[[0,2.02,41.17],[1,2.5,484.62],[2,2.02,0]],"ltp":1.79,"tv":210.66,"id":8444055},{"batb":[[0,1.99,42.01],[1,1.94,31.87],[2,1.01,15.51]],"ltp":2.28,"tv":771.03,"id":8257852}]}]}
{"op":"mcm","clk":"1012139586","pt":1580659752265,"mc":[{"id":"1.168223930","rc":[{"batb":[[0,1.77,42.65],[1,1.01,15.51],[2,1.01,0]],"batl":[[0,2.5,484.62],[1,2.5,0]],"ltp":1.79,"tv":210.66,"id":8444055},{"batb":[[0,1.94,31.87],[1,1.01,15.69],[2,1.01,0]],"batl":[[0,2.72,49.62],[1,2.88,0.31],[2,2.88,0]],"ltp":2.28,"tv":771.03,"id":8257852}]}]}
{"op":"mcm","clk":"1012139736","pt":1580659752980,"mc":[{"id":"1.168223930","rc":[{"batb":[[0,1.77,295.41],[1,1.75,400.43],[2,1.01,15.51]],"batl":[[0,1.98,330.88],[1,2,267.29],[2,2.5,484.62]],"ltp":1.79,"tv":210.66,"id":8444055}]}]}
{"op":"mcm","clk":"1012140498","pt":1580659757050,"mc":[{"id":"1.168223930","rc":[{"batb":[[0,1.77,42.65],[1,1.01,15.51],[2,1.01,0]],"ltp":1.79,"tv":210.66,"id":8444055}]}]}
{"op":"mcm","clk":"1012140793","pt":1580659758746,"mc":[{"id":"1.168223930","rc":[{"batl":[[0,2.88,0.31],[1,2.88,0]],"ltp":2.28,"tv":771.03,"id":8257852}]}]}
{"op":"mcm","clk":"1012141095","pt":1580659760266,"mc":[{"id":"1.168223930","rc":[{"batb":[[0,1.94,32.1],[1,1.89,318.2],[2,1.87,323.2]],"ltp":1.79,"tv":210.66,"id":8444055},{"batb":[[1,1.75,44.96],[2,1.01,15.51]],"ltp":2.28,"tv":771.03,"id":8257852}]}]}
{"op":"mcm","clk":"1012141294","pt":1580659761243,"mc":[{"id":"1.168223930","rc":[{"batb":[[1,1.9,46.21],[2,1.89,318.2]],"batl":[[2,2.1,37.81]],"ltp":1.79,"tv":210.66,"id":8444055},{"batb":[[1,1.9,46.21],[2,1.75,44.96]],"batl":[[0,2.1,37.81],[1,2.88,0.31]],"ltp":2.28,"tv":771.03,"id":8257852}]}]}
{"op":"mcm","clk":"1012141600","pt":1580659763048,"mc":[{"id":"1.168223930","rc":[{"batl":[[1,2.5,63.78],[2,2.88,0.31]],"ltp":2.28,"tv":771.03,"id":8257852}]}]}
{"op":"mcm","clk":"1012143834","pt":1580659775241,"mc":[{"id":"1.168223930","rc":[{"batb":[[2,1.83,38.48]],"batl":[[0,2.1,37.81],[1,2.5,484.62],[2,2.1,0]],"ltp":1.79,"tv":210.66,"id":8444055}]}]}
{"op":"mcm","clk":"1012143980","pt":1580659776050,"mc":[{"id":"1.168223930","rc":[{"batb":[[0,1.83,38.48],[1,1.01,15.51],[2,1.83,0]],"batl":[[0,2.5,484.62],[1,2.5,0]],"ltp":1.79,"tv":210.66,"id":8444055},{"batb":[[0,1.75,44.96],[1,1.01,15.51],[2,1.75,0]],"batl":[[0,2.5,63.78],[1,2.88,0.31],[2,2.88,0]],"ltp":2.28,"tv":771.03,"id":8257852}]}]}
{"op":"mcm","clk":"1012144407","pt":1580659778129,"mc":[{"id":"1.168223930","rc":[{"batb":[[1,1.79,396.23],[2,1.77,386.07]],"batl":[[0,2.22,328.12],[1,2.24,194.08],[2,2.5,484.62]],"ltp":1.79,"tv":210.66,"id":8444055}]}]}
{"op":"mcm","clk":"1012145756","pt":1580659785239,"mc":[{"id":"1.168223930","rc":[{"batb":[[1,1.01,15.51],[2,1.77,0]],"batl":[[0,2.5,484.62],[1,2.24,0],[2,2.5,0]],"ltp":1.79,"tv":210.66,"id":8444055}]}]}
{"op":"mcm","clk":"1012145858","pt":1580659785835,"mc":[{"id":"1.168223930","rc":[{"batl":[[0,2.02,240],[1,2.5,63.78],[2,2.88,0.31]],"ltp":2.28,"tv":771.03,"id":8257852}]}]}
{"op":"mcm","clk":"1012146074","pt":1580659786874,"mc":[{"id":"1.168223930","rc":[{"batl":[[1,2.88,0.31],[2,2.88,0]],"ltp":2.28,"tv":771.03,"id":8257852}]}]}
{"op":"mcm","clk":"1012146292","pt":1580659788070,"mc":[{"id":"1.168223930","rc":[{"batb":[[0,1.83,215.45],[1,1.81,360.08],[2,1.75,44.77]],"batl":[[0,1.9,244.05],[1,1.92,303.74],[2,2.02,240]],"ltp":2.28,"tv":771.03,"id":8257852}]}]}
{"op":"mcm","clk":"1012146507","pt":1580659789260,"mc":[{"id":"1.168223930","rc":[{"trd":[[2.18,0.16]],"batb":[[0,2.18,44.85],[1,2.1,37.81],[2,1.97,61.45]],"batl":[[0,2.34,31.09]],"ltp":2.18,"tv":210.82,"id":8444055},{"trd":[[1.85,0.19]],"batb":[[0,1.83,215.26]],"batl":[[1,1.91,42.01],[2,1.92,303.74]],"ltp":1.85,"tv":771.21,"id":8257852}],"tv":982.04}]}
{"op":"mcm","clk":"1012146827","pt":1580659791056,"mc":[{"id":"1.168223930","rc":[{"batl":[[1,3,384.15]],"ltp":2.18,"tv":210.82,"id":8444055}]}]}
{"op":"mcm","clk":"1012149345","pt":1580659804169,"mc":[{"id":"1.168223930","rc":[{"batb":[[0,1.75,44.77],[1,1.74,56.29],[2,1.51,74.59]],"ltp":1.85,"tv":771.21,"id":8257852}]}]}
{"op":"mcm","clk":"1012149893","pt":1580659807174,"mc":[{"id":"1.168223930","rc":[{"batb":[[0,2.1,37.81],[1,1.97,61.45],[2,1.01,15.51]],"ltp":2.18,"tv":210.82,"id":8444055},{"batb":[[0,1.74,56.29],[1,1.51,74.59],[2,1.01,15.51]],"batl":[[0,1.91,42.01],[1,2.02,240],[2,2.3,87.62]],"ltp":1.85,"tv":771.21,"id":8257852}]}]}
{"op":"mcm","clk":"1012150105","pt":1580659808162,"mc":[{"id":"1.168223930","rc":[{"batb":[[0,1.97,61.45],[1,1.01,15.51],[2,1.01,0]],"batl":[[0,3,384.15],[1,3,0]],"ltp":2.18,"tv":210.82,"id":8444055},{"batb":[[0,1.51,74.59],[1,1.01,15.51],[2,1.01,0]],"batl":[[0,2.02,240],[1,2.3,87.62],[2,2.88,0.31]],"ltp":1.85,"tv":771.21,"id":8257852}]}]}
{"op":"mcm","clk":"1012150515","pt":1580659810172,"mc":[{"id":"1.168223930","rc":[{"batb":[[0,1.96,62.08]],"ltp":2.18,"tv":210.82,"id":8444055},{"batb":[[0,1.57,278.67],[1,1.56,307.91],[2,1.52,73.88]],"batl":[[1,2.1,244],[2,2.12,225.85]],"ltp":1.85,"tv":771.21,"id":8257852}]}]}
{"op":"mcm","clk":"1012150738","pt":1580659811175,"mc":[{"id":"1.168223930","rc":[{"batb":[[0,1.52,73.88],[1,1.01,15.51],[2,1.52,0]],"batl":[[1,2.3,87.62],[2,2.88,0.31]],"ltp":1.85,"tv":771.21,"id":8257852}]}]}
{"op":"mcm","clk":"1012151216","pt":1580659813790,"mc":[{"id":"1.168223930","rc":[{"batb":[[0,1.77,241.01],[1,1.75,403.27],[2,1.52,73.88]],"batl":[[0,1.84,323.12],[1,1.86,335.38],[2,2.02,240]],"ltp":1.85,"tv":771.21,"id":8257852}]}]}
{"op":"mcm","clk":"1012151811","pt":1580659817062,"mc":[{"id":"1.168223930","rc":[{"batb":[[0,1.52,73.88],[1,1.01,15.51],[2,1.52,0]],"batl":[[0,2.02,240],[1,2.3,87.62],[2,2.88,0.31]],"ltp":1.85,"tv":771.21,"id":8257852}]}]}
{"op":"mcm","clk":"1012152421","pt":1580659820194,"mc":[{"id":"1.168223930","rc":[{"batb":[[0,1.57,278.67],[1,1.56,307.91],[2,1.52,73.88]],"batl":[[1,2.1,244],[2,2.12,225.85]],"ltp":1.85,"tv":771.21,"id":8257852}]}]}
{"op":"mcm","clk":"1012152973","pt":1580659823180,"mc":[{"id":"1.168223930","rc":[{"batl":[[1,2.3,87.62],[2,2.88,0.31]],"ltp":1.85,"tv":771.21,"id":8257852}]}]}
{"op":"mcm","clk":"1012153346","pt":1580659825172,"mc":[{"id":"1.168223930","rc":[{"batl":[[1,2.88,0.31],[2,2.88,0]],"ltp":1.85,"tv":771.21,"id":8257852}]}]}
{"op":"mcm","clk":"1012153564","pt":1580659826269,"mc":[{"id":"1.168223930","rc":[{"batl":[[0,1.62,319.65],[1,1.63,259.81],[2,2.02,240]],"ltp":1.85,"tv":771.21,"id":8257852}]}]}
{"op":"mcm","clk":"1012153720","pt":1580659827108,"mc":[{"id":"1.168223930","rc":[{"batb":[[0,2.68,25.41],[1,2.54,26.89],[2,2.2,43.43]],"batl":[[0,2.92,21.85]],"ltp":2.18,"tv":210.82,"id":8444055},{"batb":[[2,1.52,154.54]],"batl":[[2,1.65,42.01]],"ltp":1.85,"tv":771.21,"id":8257852}]}]}
{"op":"mcm","clk":"1012154134","pt":1580659829272,"mc":[{"id":"1.168223930","rc":[{"batl":[[1,3.9,284.19]],"ltp":2.18,"tv":210.82,"id":8444055}]}]}
{"op":"mcm","clk":"1012155606","pt":1580659837214,"mc":[{"id":"1.168223930","rc":[{"trd":[[1.57,480]],"batb":[[0,1.57,38.67]],"ltp":1.57,"tv":1251.21,"id":8257852}],"tv":1462.04}]}
{"op":"mcm","clk":"1012155744","pt":1580659838024,"mc":[{"id":"1.168223930","rc":[{"batb":[[0,1.56,307.91],[1,1.52,154.54],[2,1.26,176.48]],"ltp":1.57,"tv":1251.21,"id":8257852}]}]}
{"op":"mcm","clk":"1012156326","pt":1580659841201,"mc":[{"id":"1.168223930","rc":[{"batb":[[0,1.56,499.99],[1,1.55,317],[2,1.52,154.54]],"batl":[[0,1.62,404.81]],"ltp":1.57,"tv":1251.21,"id":8257852}]}]}
{"op":"mcm","clk":"1012157240","pt":1580659846002,"mc":[{"id":"1.168223930","rc":[{"batb":[[0,2.54,26.89],[1,2.2,43.43],[2,1.01,15.51]],"ltp":2.18,"tv":210.82,"id":8444055},{"batb":[[0,1.52,80.66],[1,1.26,176.48],[2,1.01,15.51]],"batl":[[0,1.65,42.01],[1,1.95,160.26],[2,2.88,0.31]],"ltp":1.57,"tv":1251.21,"id":8257852}]}]}
{"op":"mcm","clk":"1012157650","pt":1580659848241,"mc":[{"id":"1.168223930","rc":[{"batb":[[0,2.2,43.43],[1,1.01,15.51],[2,1.01,0]],"ltp":2.18,"tv":210.82,"id":8444055},{"batb":[[0,1.26,176.48],[1,1.01,15.51],[2,1.01,0]],"batl":[[0,2.88,0.31],[1,1.95,0],[2,2.88,0]],"ltp":1.57,"tv":1251.21,"id":8257852}]}]}
{"op":"mcm","clk":"1012157869","pt":1580659849257,"mc":[{"id":"1.168223930","rc":[{"batl":[[0,1.88,264.44],[1,1.9,313.99],[2,2.88,0.31]],"ltp":1.57,"tv":1251.21,"id":8257852}]}]}
{"op":"mcm","clk":"1012158398","pt":1580659852226,"mc":[{"id":"1.168223930","rc":[{"batb":[[0,1.81,228.75],[1,1.79,373.9],[2,1.26,176.48]],"ltp":1.57,"tv":1251.21,"id":8257852}]}]}
{"op":"mcm","clk":"1012158578","pt":1580659853239,"mc":[{"id":"1.168223930","rc":[{"batb":[[1,2.14,36.13],[2,1.98,60.27]],"ltp":2.18,"tv":210.82,"id":8444055},{"batb":[[2,1.73,46.19]],"batl":[[0,1.88,306.45]],"ltp":1.57,"tv":1251.21,"id":8257852}]}]}
{"op":"mcm","clk":"1012158917","pt":1580659855261,"mc":[{"id":"1.168223930","rc":[{"batl":[[0,3,389.09]],"ltp":2.18,"tv":210.82,"id":8444055},{"batl":[[2,2.3,81.18]],"ltp":1.57,"tv":1251.21,"id":8257852}]}]}
{"op":"mcm","clk":"1012159061","pt":1580659856154,"mc":[{"id":"1.168223930","rc":[{"batl":[[0,2.38,30.25],[1,3,389.09]],"ltp":2.18,"tv":210.82,"id":8444055}]}]}
{"op":"mcm","clk":"1012161448","pt":1580659869139,"mc":[{"id":"1.168223930","rc":[{"batb":[[0,2.14,36.13],[1,1.98,60.27],[2,1.01,15.51]],"ltp":2.18,"tv":210.82,"id":8444055},{"batb":[[0,1.72,57.97],[1,1.5,76.56],[2,1.01,15.51]],"batl":[[0,1.88,42.01],[1,2.3,81.18],[2,2.88,0.31]],"ltp":1.57,"tv":1251.21,"id":8257852}]}]}
{"op":"mcm","clk":"1012161596","pt":1580659870056,"mc":[{"id":"1.168223930","rc":[{"batb":[[0,1.98,60.27],[1,1.01,15.51],[2,1.01,0]],"batl":[[0,3,389.09],[1,3,0]],"ltp":2.18,"tv":210.82,"id":8444055},{"batb":[[0,1.5,76.56],[1,1.01,15.51],[2,1.01,0]],"batl":[[0,2.3,81.18],[1,2.88,0.31],[2,2.88,0]],"ltp":1.57,"tv":1251.21,"id":8257852}]}]}
{"op":"mcm","clk":"1012161788","pt":1580659871156,"mc":[{"id":"1.168223930","rc":[{"batb":[[0,1.55,502.5],[1,1.54,325.22],[2,1.5,76.56]],"batl":[[0,2.08,289.54],[1,2.1,232.31],[2,2.3,81.18]],"ltp":1.57,"tv":1251.21,"id":8257852}]}]}
{"op":"mcm","clk":"1012161901","pt":1580659871856,"mc":[{"id":"1.168223930","rc":[{"batb":[[0,1.97,60.74]],"ltp":2.18,"tv":210.82,"id":8444055},{"batb":[[2,1.51,76.09]],"ltp":1.57,"tv":1251.21,"id":8257852}]}]}
{"op":"mcm","clk":"1012163102","pt":1580659878880,"mc":[{"id":"1.168223930","rc":[{"batl":[[0,2.3,81.18],[1,2.88,0.31],[2,2.3,0]],"ltp":1.57,"tv":1251.21,"id":8257852}]}]}
{"op":"mcm","clk":"1012163647","pt":1580659881998,"mc":[{"id":"1.168223930","rc":[{"batl":[[0,1.61,437.6],[1,1.62,265.55],[2,2.88,0.31]],"ltp":1.57,"tv":1251.21,"id":8257852}]}]}
{"op":"mcm","clk":"1012163875","pt":1580659883183,"mc":[{"id":"1.168223930","rc":[{"batb":[[0,2.72,24.47],[1,2.56,26.89],[2,2.24,42.02]],"batl":[[0,2.94,21]],"ltp":2.18,"tv":210.82,"id":8444055},{"batb":[[2,1.52,80.66]],"batl":[[2,1.64,42.01]],"ltp":1.57,"tv":1251.21,"id":8257852}]}]}
{"op":"mcm","clk":"1012164173","pt":1580659884900,"mc":[{"id":"1.168223930","rc":[{"batl":[[1,3.9,286.53]],"ltp":2.18,"tv":210.82,"id":8444055}]}]}
{"op":"mcm","clk":"1012167194","pt":1580659901183,"mc":[{"id":"1.168223930","rc":[{"batb":[[0,1.52,80.66],[1,1.51,76.09],[2,1.26,178.69]],"batl":[[0,1.64,42.01],[1,1.95,155.61],[2,2.88,0.31]],"ltp":1.57,"tv":1251.21,"id":8257852}]}]}
{"op":"mcm","clk":"1012167374","pt":1580659902096,"mc":[{"id":"1.168223930","rc":[{"batb":[[0,2.24,41.78],[1,1.01,15.51],[2,2.24,0]],"batl":[[0,3.9,286.53],[1,3.9,0]],"ltp":2.18,"tv":210.82,"id":8444055},{"batb":[[0,1.26,178.69],[1,1.01,15.51],[2,1.26,0]],"batl":[[0,1.95,155.61],[1,2.88,0.31],[2,2.88,0]],"ltp":1.57,"tv":1251.21,"id":8257852}]}]}
{"op":"mcm","clk":"1012167750","pt":1580659904216,"mc":[{"id":"1.168223930","rc":[{"batl":[[0,2.88,0.31],[1,2.88,0]],"ltp":1.57,"tv":1251.21,"id":8257852}]}]}
{"op":"mcm","clk":"1012168277","pt":1580659907092,"mc":[{"id":"1.168223930","rc":[{"batb":[[0,1.48,586.75],[1,1.47,393.98],[2,1.26,178.69]],"batl":[[0,1.53,331.37],[1,1.54,321.32],[2,2.88,0.31]],"ltp":1.57,"tv":1251.21,"id":8257852}]}]}
{"op":"mcm","clk":"1012168650","pt":1580659909213,"mc":[{"id":"1.168223930","rc":[{"batl":[[0,4.2,268.38]],"ltp":2.18,"tv":210.82,"id":8444055},{"batl":[[2,1.89,172.84]],"ltp":1.57,"tv":1251.21,"id":8257852}]}]}
{"op":"mcm","clk":"1012168811","pt":1580659910113,"mc":[{"id":"1.168223930","rc":[{"batb":[[0,1.26,178.69],[1,1.01,15.51],[2,1.26,0]],"batl":[[0,1.89,172.84],[1,2.88,0.31],[2,1.89,0]],"ltp":1.57,"tv":1251.21,"id":8257852}]}]}
{"op":"mcm","clk":"1012169369","pt":1580659913197,"mc":[{"id":"1.168223930","rc":[{"batb":[[0,1.26,1043.58],[1,1.25,893.75],[2,1.01,15.51]],"batl":[[0,1.87,343.56],[1,1.89,491.94],[2,2.88,0.31]],"ltp":1.57,"tv":1251.21,"id":8257852}]}]}
{"op":"mcm","clk":"1012169943","pt":1580659916238,"mc":[{"id":"1.168223930","rc":[{"batb":[[0,1.26,178.69],[1,1.01,15.51],[2,1.01,0]],"ltp":1.57,"tv":1251.21,"id":8257852}]}]}
{"op":"mcm","clk":"1012170516","pt":1580659919214,"mc":[{"id":"1.168223930","rc":[{"batb":[[0,1.79,352.89],[1,1.77,388.43],[2,1.26,178.69]],"batl":[[1,1.89,319.1]],"ltp":1.57,"tv":1251.21,"id":8257852}]}]}
{"op":"mcm","clk":"1012170728","pt":1580659920234,"mc":[{"id":"1.168223930","rc":[{"batb":[[1,2,57.83],[2,1.01,15.51]],"ltp":2.18,"tv":210.82,"id":8444055},{"batb":[[2,1.71,47.92]],"ltp":1.57,"tv":1251.21,"id":8257852}]}]}
{"op":"mcm","clk":"1012170866","pt":1580659920939,"mc":[{"id":"1.168223930","rc":[{"batb":[[1,2.16,36.13],[2,2,57.83]],"batl":[[0,2.42,29.41]],"ltp":2.18,"tv":210.82,"id":8444055},{"batl":[[0,1.87,385.57]],"ltp":1.57,"tv":1251.21,"id":8257852}]}]}
{"op":"mcm","clk":"1012171291","pt":1580659923232,"mc":[{"id":"1.168223930","rc":[{"batl":[[1,3.15,363.13]],"ltp":2.18,"tv":210.82,"id":8444055},{"batb":[[2,1.71,106.73]],"batl":[[2,2.22,97.8]],"ltp":1.57,"tv":1251.21,"id":8257852}]}]}
{"op":"mcm","clk":"1012174190","pt":1580659938267,"mc":[{"id":"1.168223930","rc":[{"batb":[[0,2.16,36.13],[1,2,57.83],[2,1.01,15.51]],"ltp":2.18,"tv":210.82,"id":8444055},{"batb":[[0,1.71,58.81],[1,1.49,78.92],[2,1.01,15.51]],"batl":[[0,1.87,42.01],[1,2.22,97.8],[2,2.88,0.31]],"ltp":1.57,"tv":1251.21,"id":8257852}]}]}
{"op":"mcm","clk":"1012174458","pt":1580659939669,"mc":[{"id":"1.168223930","rc":[{"batb":[[0,2,57.83],[1,1.01,15.51],[2,1.01,0]],"batl":[[0,3.15,363.13],[1,3.15,0]],"ltp":2.18,"tv":210.82,"id":8444055},{"batb":[[0,1.49,78.92],[1,1.01,15.51],[2,1.01,0]],"batl":[[0,2.22,97.8],[1,2.88,0.31],[2,2.88,0]],"ltp":1.57,"tv":1251.21,"id":8257852}]}]}
{"op":"mcm","clk":"1012175325","pt":1580659944255,"mc":[{"id":"1.168223930","rc":[{"batb":[[0,1.74,241.14],[1,1.72,428.25],[2,1.49,78.92]],"batl":[[0,1.81,383.51],[1,1.83,353.35],[2,2.22,97.8]],"ltp":1.57,"tv":1251.21,"id":8257852}]}]}
{"op":"mcm","clk":"1012176072","pt":1580659948182,"mc":[{"id":"1.168223930","rc":[{"batb":[[0,1.49,78.92],[1,1.01,15.51],[2,1.49,0]],"batl":[[0,2.22,97.8],[1,2.88,0.31],[2,2.22,0]],"ltp":1.57,"tv":1251.21,"id":8257852}]}]}
{"op":"mcm","clk":"1012176992","pt":1580659953129,"mc":[{"id":"1.168223930","rc":[{"batl":[[0,2.88,0.31],[1,2.88,0]],"ltp":1.57,"tv":1251.21,"id":8257852}]}]}
{"op":"mcm","clk":"1012177197","pt":1580659954208,"mc":[{"id":"1.168223930","rc":[{"batb":[[1,1.94,312.39],[2,1.92,297.75]],"batl":[[0,2.04,382.47],[1,2.06,245.37]],"ltp":2.18,"tv":210.82,"id":8444055}]}]}
{"op":"mcm","clk":"1012177403","pt":1580659955248,"mc":[{"id":"1.168223930","rc":[{"batb":[[1,1.97,42.85],[2,1.94,312.39]],"batl":[[2,2.18,35.29]],"ltp":2.18,"tv":210.82,"id":8444055},{"batb":[[0,1.88,35.25],[1,1.84,49.57],[2,1.69,49.88]],"batl":[[0,2.04,40.33],[1,2.88,0.31]],"ltp":1.57,"tv":1251.21,"id":8257852}]}]}
{"op":"mcm","clk":"1012177783","pt":1580659957028,"mc":[{"id":"1.168223930","rc":[{"batl":[[1,2.5,63.78],[2,2.88,0.31]],"ltp":1.57,"tv":1251.21,"id":8257852}]}]}
{"op":"mcm","clk":"1012180373","pt":1580659970130,"mc":[{"id":"1.168223930","rc":[{"batb":[[2,1.88,35.17]],"batl":[[0,2.18,35.29],[1,2.72,434.1],[2,2.18,0]],"ltp":2.18,"tv":210.82,"id":8444055}]}]}
{"op":"mcm","clk":"1012180559","pt":1580659971174,"mc":[{"id":"1.168223930","rc":[{"batb":[[0,1.97,42.85],[1,1.88,35.17],[2,1.01,15.51]],"ltp":2.18,"tv":210.82,"id":8444055},{"batb":[[0,1.84,49.57],[1,1.69,49.88],[2,1.01,15.51]],"ltp":1.57,"tv":1251.21,"id":8257852}]}]}
{"op":"mcm","clk":"1012180736","pt":1580659972145,"mc":[{"id":"1.168223930","rc":[{"batb":[[0,1.88,35.17],[1,1.01,15.51],[2,1.01,0]],"batl":[[0,2.72,434.1],[1,2.72,0]],"ltp":2.18,"tv":210.82,"id":8444055},{"batb":[[0,1.69,49.88],[1,1.01,15.51],[2,1.01,0]],"batl":[[0,2.5,63.78],[1,2.88,0.31],[2,2.88,0]],"ltp":1.57,"tv":1251.21,"id":8257852}]}]}
{"op":"mcm","clk":"1012180959","pt":1580659973234,"mc":[{"id":"1.168223930","rc":[{"batb":[[1,1.83,384.18],[2,1.81,358.87]],"ltp":2.18,"tv":210.82,"id":8444055}]}]}
{"op":"mcm","clk":"1012181524","pt":1580659976163,"mc":[{"id":"1.168223930","rc":[{"batl":[[0,1.91,228.99],[1,1.93,297.25]],"ltp":2.18,"tv":210.82,"id":8444055}]}]}
{"op":"mcm","clk":"1012181695","pt":1580659977139,"mc":[{"id":"1.168223930","rc":[{"batb":[[1,1.86,48.73],[2,1.83,384.18]],"batl":[[2,2.06,39.49]],"ltp":2.18,"tv":210.82,"id":8444055},{"batb":[[0,2,58.07],[1,1.95,43.69],[2,1.88,35.01]],"batl":[[0,2.18,35.29],[1,2.5,63.78],[2,2.88,0.31]],"ltp":1.57,"tv":1251.21,"id":8257852}]}]}
{"op":"mcm","clk":"1012181874","pt":1580659978263,"mc":[{"id":"1.168223930","rc":[{"batb":[[2,1.71,48.39]],"ltp":2.18,"tv":210.82,"id":8444055}]}]}
{"op":"mcm","clk":"1012182413","pt":1580659981086,"mc":[{"id":"1.168223930","rc":[{"batb":[[2,1.84,211.42]],"batl":[[0,2.06,39.49],[1,2.6,458.45],[2,2.06,0]],"ltp":2.18,"tv":210.82,"id":8444055}]}]}
{"op":"mcm","clk":"1012182965","pt":1580659983949,"mc":[{"id":"1.168223930","rc":[{"batb":[[2,1.84,319.65]],"batl":[[0,1.92,272.14],[1,1.94,292.38],[2,2.06,39.49]],"ltp":2.18,"tv":210.82,"id":8444055}]}]}
{"op":"mcm","clk":"1012184972","pt":1580659995060,"mc":[{"id":"1.168223930","rc":[{"trd":[[1.88,70.34]],"batb":[[0,1.86,48.73],[1,1.84,319.65],[2,1.82,352.05]],"batl":[[0,1.88,166.83],[1,1.92,272.14],[2,1.94,292.38]],"ltp":1.88,"tv":281.16,"id":8444055}],"tv":1532.38}]}
{"op":"mcm","clk":"1012186183","pt":1580660001224,"mc":[{"id":"1.168223930","rc":[{"batl":[[0,1.92,272.14],[1,1.94,292.38],[2,2.06,39.49]],"ltp":1.88,"tv":281.16,"id":8444055}]}]}
{"op":"mcm","clk":"1012186375","pt":1580660002207,"mc":[{"id":"1.168223930","rc":[{"batl":[[0,1.92,230.17]],"ltp":1.88,"tv":281.16,"id":8444055}]}]}
{"op":"mcm","clk":"1012186549","pt":1580660003067,"mc":[{"id":"1.168223930","rc":[{"batb":[[1,1.71,48.39],[2,1.01,15.51]],"batl":[[0,2.06,39.49],[1,2.6,458.45],[2,2.06,0]],"ltp":1.88,"tv":281.16,"id":8444055}]}]}
{"op":"mcm","clk":"1012186736","pt":1580660004090,"mc":[{"id":"1.168223930","rc":[{"trd":[[1.86,97.46]],"batb":[[0,1.71,48.39],[1,1.01,15.51],[2,1.01,0]],"batl":[[0,1.86,118.1]],"ltp":1.86,"tv":378.62,"id":8444055},{"batb":[[1,1.88,35.01],[2,1.01,15.51]],"ltp":1.57,"tv":1251.21,"id":8257852}],"tv":1629.84}]}
{"op":"mcm","clk":"1012187324","pt":1580660007185,"mc":[{"id":"1.168223930","rc":[{"trd":[[1.86,164.68]],"batb":[[0,1.85,48.73],[1,1.71,48.39],[2,1.01,15.51]],"batl":[[0,1.86,84.49],[1,2,42.01],[2,2.6,458.45]],"ltp":1.86,"tv":445.84,"id":8444055},{"batb":[[0,2,100.08]],"ltp":1.57,"tv":1251.21,"id":8257852}],"tv":1697.05}]}
{"op":"mcm","clk":"1012187512","pt":1580660008162,"mc":[{"id":"1.168223930","rc":[{"batl":[[1,1.94,286.76],[2,1.96,283.04]],"ltp":1.86,"tv":445.84,"id":8444055}]}]}
{"op":"mcm","clk":"1012187669","pt":1580660009083,"mc":[{"id":"1.168223930","rc":[{"trd":[[1.86,333.66]],"batb":[[0,1.86,182.89],[1,1.85,48.73],[2,1.84,339.35]],"batl":[[0,1.94,286.76],[1,1.96,283.04],[2,2,42.01]],"ltp":1.86,"tv":614.82,"id":8444055}],"tv":1866.03}]}
{"op":"mcm","clk":"1012188060","pt":1580660011191,"mc":[{"id":"1.168223930","rc":[{"batl":[[0,1.94,235.88]],"ltp":1.86,"tv":614.82,"id":8444055}]}]}
{"op":"mcm","clk":"1012188224","pt":1580660012076,"mc":[{"id":"1.168223930","rc":[{"batb":[[0,1.86,236.4]],"ltp":1.86,"tv":614.82,"id":8444055}]}]}
{"op":"mcm","clk":"1012188401","pt":1580660013094,"mc":[{"id":"1.168223930","rc":[{"batb":[[0,1.85,48.73],[1,1.71,48.39],[2,1.01,15.51]],"batl":[[0,2,42.01],[1,2.6,458.45],[2,2,0]],"ltp":1.86,"tv":614.82,"id":8444055}]}]}
{"op":"mcm","clk":"1012188920","pt":1580660016076,"mc":[{"id":"1.168223930","rc":[{"batb":[[2,1.69,398.09]],"batl":[[1,2.06,294],[2,2.08,238.27]],"ltp":1.86,"tv":614.82,"id":8444055}]}]}
{"op":"mcm","clk":"1012190798","pt":1580660026110,"mc":[{"id":"1.168223930","rc":[{"trd":[[2,70.74]],"batb":[[0,2,64.69]],"ltp":2.0,"tv":1321.96,"id":8257852}],"tv":1936.78}]}
{"op":"mcm","clk":"1012190946","pt":1580660027026,"mc":[{"id":"1.168223930","rc":[{"batb":[[0,2,42.01]],"ltp":2.0,"tv":1321.96,"id":8257852}]}]}
{"op":"mcm","clk":"1012191156","pt":1580660028230,"mc":[{"id":"1.168223930","rc":[{"batb":[[0,1.71,48.39],[1,1.69,398.09],[2,1.67,468.29]],"batl":[[0,2.06,294],[1,2.08,238.27],[2,2.6,458.45]],"ltp":1.86,"tv":614.82,"id":8444055},{"batb":[[0,1.88,35.01],[1,1.01,15.51],[2,1.01,0]],"batl":[[0,2.5,63.78],[1,2.88,0.31],[2,2.88,0]],"ltp":2.0,"tv":1321.96,"id":8257852}]}]}
{"op":"mcm","clk":"1012191366","pt":1580660029209,"mc":[{"id":"1.168223930","rc":[{"batb":[[1,1.01,15.51],[2,1.67,0]],"batl":[[0,2.6,458.45],[1,2.08,0],[2,2.6,0]],"ltp":1.86,"tv":614.82,"id":8444055}]}]}
{"op":"mcm","clk":"1012191547","pt":1580660030136,"mc":[{"id":"1.168223930","rc":[{"batb":[[0,1.72,47.45]],"ltp":1.86,"tv":614.82,"id":8444055},{"batb":[[0,1.87,35.72]],"ltp":2.0,"tv":1321.96,"id":8257852}]}]}
{"op":"mcm","clk":"1012191874","pt":1580660032037,"mc":[{"id":"1.168223930","rc":[{"batb":[[0,1.83,223.78],[1,1.81,357.36],[2,1.72,47.45]],"ltp":1.86,"tv":614.82,"id":8444055}]}]}
{"op":"mcm","clk":"1012192089","pt":1580660033237,"mc":[{"id":"1.168223930","rc":[{"batb":[[0,1.72,47.45],[1,1.01,15.51],[2,1.72,0]],"ltp":1.86,"tv":614.82,"id":8444055}]}]}
{"op":"mcm","clk":"1012192923","pt":1580660037221,"mc":[{"id":"1.168223930","rc":[{"batl":[[0,2.1,231.63],[1,2.6,458.45]],"ltp":1.86,"tv":614.82,"id":8444055}]}]}
{"op":"mcm","clk":"1012193284","pt":1580660039241,"mc":[{"id":"1.168223930","rc":[{"batb":[[1,1.71,400.88],[2,1.69,447.58]],"batl":[[0,2.1,384.43],[1,2.12,225.28],[2,2.6,458.45]],"ltp":1.86,"tv":614.82,"id":8444055}]}]}
{"op":"mcm","clk":"1012195004","pt":1580660048144,"mc":[{"id":"1.168223930","rc":[{"batb":[[1,1.01,15.51],[2,1.69,0]],"batl":[[0,2.6,458.45],[1,2.12,0],[2,2.6,0]],"ltp":1.86,"tv":614.82,"id":8444055}]}]}
{"op":"mcm","clk":"1012195569","pt":1580660051241,"mc":[{"id":"1.168223930","rc":[{"batb":[[0,1.92,255.71],[1,1.9,306.59],[2,1.87,35.72]],"batl":[[0,2,209.92],[1,2.02,259.55],[2,2.5,63.78]],"ltp":2.0,"tv":1321.96,"id":8257852}]}]}
{"op":"mcm","clk":"1012195676","pt":1580660051850,"mc":[{"id":"1.168223930","rc":[{"batb":[[0,2.02,57.04],[1,1.85,37.53],[2,1.01,15.51]],"ltp":1.86,"tv":614.82,"id":8444055}]}]}
{"op":"mcm","clk":"1012195894","pt":1580660053051,"mc":[{"id":"1.168223930","rc":[{"batb":[[1,1.92,45.37],[2,1.85,37.53]],"batl":[[0,2.1,37.81],[1,2.6,458.45]],"ltp":1.86,"tv":614.82,"id":8444055},{"batb":[[1,1.91,45.37],[2,1.9,306.59]],"batl":[[2,2.08,38.65]],"ltp":2.0,"tv":1321.96,"id":8257852}]}]}
{"op":"mcm","clk":"1012198267","pt":1580660066076,"mc":[{"id":"1.168223930","rc":[{"batb":[[0,1.91,45.37],[1,1.87,35.72],[2,1.8,40.52]],"batl":[[0,2.08,38.65],[1,2.5,63.78],[2,2.88,0.31]],"ltp":2.0,"tv":1321.96,"id":8257852}]}]}
{"op":"mcm","clk":"1012198492","pt":1580660067250,"mc":[{"id":"1.168223930","rc":[{"batb":[[0,1.92,45.37],[1,1.85,37.22],[2,1.01,15.51]],"ltp":1.86,"tv":614.82,"id":8444055},{"batb":[[1,1.8,40.52],[2,1.01,15.51]],"ltp":2.0,"tv":1321.96,"id":8257852}]}]}
{"op":"mcm","clk":"1012198633","pt":1580660068054,"mc":[{"id":"1.168223930","rc":[{"batb":[[0,1.85,37.22],[1,1.01,15.51],[2,1.01,0]],"batl":[[0,2.6,458.45],[1,2.6,0]],"ltp":1.86,"tv":614.82,"id":8444055},{"batb":[[0,1.8,40.52],[1,1.01,15.51],[2,1.01,0]],"batl":[[0,2.5,63.78],[1,2.88,0.31],[2,2.88,0]],"ltp":2.0,"tv":1321.96,"id":8257852}]}]}
{"op":"mcm","clk":"1012198842","pt":1580660069252,"mc":[{"id":"1.168223930","rc":[{"batb":[[0,1.84,319.25],[1,1.82,352.91],[2,1.8,40.52]],"batl":[[0,2.2,378.14],[1,2.22,197.24],[2,2.5,63.78]],"ltp":2.0,"tv":1321.96,"id":8257852}]}]}
{"op":"mcm","clk":"1012199879","pt":1580660074753,"mc":[{"id":"1.168223930","rc":[{"batb":[[0,1.8,40.52],[1,1.01,15.51],[2,1.8,0]],"batl":[[0,2.5,63.78],[1,2.88,0.31],[2,2.5,0]],"ltp":2.0,"tv":1321.96,"id":8257852}]}]}
{"op":"mcm","clk":"1012200562","pt":1580660078257,"mc":[{"id":"1.168223930","rc":[{"batb":[[1,1.84,337.64],[2,1.82,350.53]],"batl":[[0,1.92,248.79],[1,1.94,290.89]],"ltp":1.86,"tv":614.82,"id":8444055},{"batb":[[0,2.04,54.68],[1,1.9,34.07],[2,1.8,40.52]],"ltp":2.0,"tv":1321.96,"id":8257852}]}]}
{"op":"mcm","clk":"1012200720","pt":1580660079168,"mc":[{"id":"1.168223930","rc":[{"batl":[[2,1.96,42.01]],"ltp":1.86,"tv":614.82,"id":8444055},{"batb":[[2,1.01,15.51]],"batl":[[0,2.24,33.61],[1,2.5,63.78],[2,2.88,0.31]],"ltp":2.0,"tv":1321.96,"id":8257852}]}]}
{"op":"mcm","clk":"1012201135","pt":1580660081260,"mc":[{"id":"1.168223930","rc":[{"batb":[[0,2.06,39.49],[1,2.04,54.68],[2,1.9,34.07]],"ltp":2.0,"tv":1321.96,"id":8257852}]}]}
{"op":"mcm","clk":"1012203285","pt":1580660092110,"mc":[{"id":"1.168223930","rc":[{"batb":[[1,1.81,51.25],[2,1.64,55.79]],"batl":[[0,1.96,42.01],[1,2.5,490.14],[2,1.96,0]],"ltp":1.86,"tv":614.82,"id":8444055}]}]}
{"op":"mcm","clk":"1012203473","pt":1580660093097,"mc":[{"id":"1.168223930","rc":[{"batb":[[0,1.81,51.25],[1,1.64,55.79],[2,1.01,15.51]],"ltp":1.86,"tv":614.82,"id":8444055},{"batb":[[1,1.9,34.07],[2,1.01,15.51]],"ltp":2.0,"tv":1321.96,"id":8257852}]}]}
{"op":"mcm","clk":"1012203647","pt":1580660093966,"mc":[{"id":"1.168223930","rc":[{"batb":[[0,1.64,55.79],[1,1.01,15.51],[2,1.01,0]],"batl":[[0,2.5,490.14],[1,2.5,0]],"ltp":1.86,"tv":614.82,"id":8444055},{"batb":[[0,1.9,34.07],[1,1.01,15.51],[2,1.01,0]],"batl":[[0,2.5,63.78],[1,2.88,0.31],[2,2.88,0]],"ltp":2.0,"tv":1321.96,"id":8257852}]}]}
{"op":"mcm","clk":"1012204100","pt":1580660095984,"mc":[{"id":"1.168223930","rc":[{"batb":[[0,1.65,54.84]],"ltp":1.86,"tv":614.82,"id":8444055},{"batb":[[0,1.89,34.7]],"ltp":2.0,"tv":1321.96,"id":8257852}]}]}
{"op":"mcm","clk":"1012204508","pt":1580660097975,"mc":[{"id":"1.168223930","rc":[{"batb":[[0,1.94,244.28],[1,1.92,296.56],[2,1.89,34.7]],"batl":[[0,2.02,193.41],[1,2.04,252.01],[2,2.5,63.78]],"ltp":2.0,"tv":1321.96,"id":8257852}]}]}
{"op":"mcm","clk":"1012204735","pt":1580660099071,"mc":[{"id":"1.168223930","rc":[{"batb":[[0,2,58.85],[1,1.9,46.21],[2,1.81,40.21]],"batl":[[0,2.08,38.65],[1,2.5,490.14]],"ltp":1.86,"tv":614.82,"id":8444055},{"batb":[[1,1.92,341.93]],"ltp":2.0,"tv":1321.96,"id":8257852}]}]}
{"op":"mcm","clk":"1012206887","pt":1580660110105,"mc":[{"id":"1.168223930","rc":[{"batb":[[0,1.92,45.37],[1,1.89,34.7],[2,1.8,40.68]],"batl":[[0,2.5,63.78],[1,2.88,0.31],[2,2.5,0]],"ltp":2.0,"tv":1321.96,"id":8257852}]}]}
{"op":"mcm","clk":"1012207135","pt":1580660111220,"mc":[{"id":"1.168223930","rc":[{"batb":[[0,1.9,46.21],[1,1.81,40.21],[2,1.01,15.51]],"ltp":1.86,"tv":614.82,"id":8444055},{"batb":[[1,1.8,40.68],[2,1.01,15.51]],"ltp":2.0,"tv":1321.96,"id":8257852}]}]}
{"op":"mcm","clk":"1012207333","pt":1580660112098,"mc":[{"id":"1.168223930","rc":[{"batb":[[0,1.81,40.21],[1,1.01,15.51],[2,1.01,0]],"batl":[[0,2.5,490.14],[1,2.5,0]],"ltp":1.86,"tv":614.82,"id":8444055},{"batb":[[0,1.8,40.68],[1,1.01,15.51],[2,1.01,0]],"ltp":2.0,"tv":1321.96,"id":8257852}]}]}
{"op":"mcm","clk":"1012207697","pt":1580660114008,"mc":[{"id":"1.168223930","rc":[{"batb":[[0,1.8,40.44]],"ltp":1.86,"tv":614.82,"id":8444055},{"batb":[[0,1.79,40.91]],"ltp":2.0,"tv":1321.96,"id":8257852}]}]}
{"op":"mcm","clk":"1012207999","pt":1580660115795,"mc":[{"id":"1.168223930","rc":[{"batb":[[0,1.94,233.54],[1,1.92,296.52],[2,1.8,40.44]],"batl":[[0,2.02,202.29],[1,2.04,251.41],[2,2.5,490.14]],"ltp":1.86,"tv":614.82,"id":8444055}]}]}
{"op":"mcm","clk":"1012208587","pt":1580660118919,"mc":[{"id":"1.168223930","rc":[{"batb":[[0,1.8,40.44],[1,1.01,15.51],[2,1.8,0]],"batl":[[0,2.5,490.14],[1,2.04,0],[2,2.5,0]],"ltp":1.86,"tv":614.82,"id":8444055}]}]}
{"op":"mcm","clk":"1012209148","pt":1580660122002,"mc":[{"id":"1.168223930","rc":[{"batb":[[0,1.8,300.41],[1,1.78,376.23],[2,1.01,15.51]],"batl":[[0,2.18,187.5],[1,2.2,203.48],[2,2.5,490.14]],"ltp":1.86,"tv":614.82,"id":8444055}]}]}
{"op":"mcm","clk":"1012209372","pt":1580660123125,"mc":[{"id":"1.168223930","rc":[{"batl":[[0,2.5,490.14],[1,2.2,0],[2,2.5,0]],"ltp":1.86,"tv":614.82,"id":8444055}]}]}
{"op":"mcm","clk":"1012209951","pt":1580660126140,"mc":[{"id":"1.168223930","rc":[{"batl":[[0,1.87,235.41],[1,1.89,314.61],[2,2.5,490.14]],"ltp":1.86,"tv":614.82,"id":8444055}]}]}
{"op":"mcm","clk":"1012210111","pt":1580660127005,"mc":[{"id":"1.168223930","rc":[{"batb":[[2,1.77,53.77]],"batl":[[2,1.91,42.01]],"ltp":1.86,"tv":614.82,"id":8444055},{"batb":[[0,2.1,88.01],[1,1.9,34.15],[2,1.81,100.29]],"batl":[[0,2.3,31.93],[1,2.5,63.78],[2,2.88,0.31]],"ltp":2.0,"tv":1321.96,"id":8257852}]}]}
{"op":"mcm","clk":"1012210210","pt":1580660127744,"mc":[{"id":"1.168223930","rc":[{"batb":[[2,1.01,15.51]],"ltp":2.0,"tv":1321.96,"id":8257852}]}]}
{"op":"mcm","clk":"1012212841","pt":1580660142222,"mc":[{"id":"1.168223930","rc":[{"batb":[[0,1.77,53.77],[1,1.55,68.69],[2,1.01,15.51]],"batl":[[0,1.91,42.01],[1,2.5,490.14],[2,1.91,0]],"ltp":1.86,"tv":614.82,"id":8444055},{"batb":[[0,2.1,37.81]],"ltp":2.0,"tv":1321.96,"id":8257852}]}]}
{"op":"mcm","clk":"1012213186","pt":1580660144141,"mc":[{"id":"1.168223930","rc":[{"batb":[[0,1.55,68.69],[1,1.01,15.51],[2,1.01,0]],"batl":[[0,2.5,490.14],[1,2.5,0]],"ltp":1.86,"tv":614.82,"id":8444055},{"batb":[[0,1.9,34.15],[1,1.01,15.51],[2,1.01,0]],"batl":[[0,2.5,63.78],[1,2.88,0.31],[2,2.88,0]],"ltp":2.0,"tv":1321.96,"id":8257852}]}]}
{"op":"mcm","clk":"1012213346","pt":1580660145070,"mc":[{"id":"1.168223930","rc":[{"batb":[[1,1.54,342.47],[2,1.53,322.19]],"batl":[[0,2.08,371.19],[1,2.1,231.46],[2,2.5,490.14]],"ltp":1.86,"tv":614.82,"id":8444055}]}]}
{"op":"mcm","clk":"1012217188","pt":1580660165096,"mc":[{"id":"1.168223930","rc":[{"batb":[[1,1.01,15.51],[2,1.53,0]],"batl":[[0,2.5,490.14],[1,2.1,0],[2,2.5,0]],"ltp":1.86,"tv":614.82,"id":8444055}]}]}
{"op":"mcm","clk":"1012217568","pt":1580660167218,"mc":[{"id":"1.168223930","rc":[{"batb":[[0,1.93,339.72],[1,1.91,301.53],[2,1.9,34.15]],"batl":[[0,2.02,244.14],[1,2.04,252.15],[2,2.5,63.78]],"ltp":2.0,"tv":1321.96,"id":8257852}]}]}
{"op":"mcm","clk":"1012217734","pt":1580660168115,"mc":[{"id":"1.168223930","rc":[{"batb":[[0,1.99,59.64],[1,1.78,42.09],[2,1.55,68.69]],"ltp":1.86,"tv":614.82,"id":8444055}]}]}
{"op":"mcm","clk":"1012217946","pt":1580660169210,"mc":[{"id":"1.168223930","rc":[{"batb":[[1,1.9,46.21],[2,1.78,42.09]],"batl":[[0,2.08,38.65],[1,2.5,490.14]],"ltp":1.86,"tv":614.82,"id":8444055},{"batb":[[1,1.92,45.37],[2,1.91,301.53]],"batl":[[2,2.1,37.81]],"ltp":2.0,"tv":1321.96,"id":8257852}]}]}
{"op":"mcm","clk":"1012220640","pt":1580660183238,"mc":[{"id":"1.168223930","rc":[{"batb":[[0,1.92,45.37],[1,1.9,34.15],[2,1.79,41.15]],"batl":[[0,2.1,37.81],[1,2.5,63.78],[2,2.88,0.31]],"ltp":2.0,"tv":1321.96,"id":8257852}]}]}
{"op":"mcm","clk":"1012220741","pt":1580660183737,"mc":[{"id":"1.168223930","rc":[{"batb":[[0,1.78,42.09],[1,1.01,15.51],[2,1.78,0]],"batl":[[0,2.5,490.14],[1,2.5,0]],"ltp":1.86,"tv":614.82,"id":8444055},{"batb":[[0,1.79,41.15],[1,1.01,15.51],[2,1.79,0]],"batl":[[0,2.5,63.78],[1,2.88,0.31],[2,2.88,0]],"ltp":2.0,"tv":1321.96,"id":8257852}]}]}
{"op":"mcm","clk":"1012221196","pt":1580660186171,"mc":[{"id":"1.168223930","rc":[{"batb":[[0,1.83,270.14],[1,1.81,359.66],[2,1.79,41.15]],"batl":[[0,2.28,242.22],[1,2.3,178.29],[2,2.5,63.78]],"ltp":2.0,"tv":1321.96,"id":8257852}]}]}
{"op":"mcm","clk":"1012221440","pt":1580660187233,"mc":[{"id":"1.168223930","rc":[{"batb":[[0,1.79,41.15],[1,1.01,15.51],[2,1.79,0]],"batl":[[0,2.5,63.78],[1,2.88,0.31],[2,2.5,0]],"ltp":2.0,"tv":1321.96,"id":8257852}]}]}
{"op":"mcm","clk":"1012221821","pt":1580660189253,"mc":[{"id":"1.168223930","rc":[{"batb":[[0,1.94,221.03],[1,1.92,296.58],[2,1.78,42.09]],"batl":[[0,2.02,214.55],[1,2.04,251.46],[2,2.5,490.14]],"ltp":1.86,"tv":614.82,"id":8444055}]}]}
{"op":"mcm","clk":"1012222425","pt":1580660192243,"mc":[{"id":"1.168223930","rc":[{"batb":[[0,1.78,42.09],[1,1.01,15.51],[2,1.78,0]],"batl":[[0,2.5,490.14],[1,2.04,0],[2,2.5,0]],"ltp":1.86,"tv":614.82,"id":8444055}]}]}
{"op":"mcm","clk":"1012223357","pt":1580660197153,"mc":[{"id":"1.168223930","rc":[{"batb":[[0,1.83,270.14],[1,1.81,359.65],[2,1.79,41.15]],"batl":[[0,1.91,342.68],[1,1.93,298.66],[2,2.88,0.31]],"ltp":2.0,"tv":1321.96,"id":8257852}]}]}
{"op":"mcm","clk":"1012223608","pt":1580660198238,"mc":[{"id":"1.168223930","rc":[{"batb":[[0,2.12,49.25],[1,1.98,60.59],[2,1.01,15.51]],"ltp":1.86,"tv":614.82,"id":8444055}]}]}
{"op":"mcm","clk":"1012223764","pt":1580660198935,"mc":[{"id":"1.168223930","rc":[{"batb":[[1,2.02,41.17],[2,1.98,60.59]],"batl":[[0,2.2,34.45]],"ltp":1.86,"tv":614.82,"id":8444055},{"batb":[[1,1.82,50.41],[2,1.81,359.65]],"batl":[[2,1.99,42.01]],"ltp":2.0,"tv":1321.96,"id":8257852}]}]}
{"op":"mcm","clk":"1012224223","pt":1580660201243,"mc":[{"id":"1.168223930","rc":[{"batl":[[1,2.92,399.45]],"ltp":1.86,"tv":614.82,"id":8444055}]}]}
{"op":"mcm","clk":"1012228795","pt":1580660223978,"mc":[{"id":"1.168223930","rc":[{"batb":[[0,1.98,60.59],[1,1.01,15.51],[2,1.98,0]],"batl":[[0,2.92,399.45],[1,2.92,0]],"ltp":1.86,"tv":614.82,"id":8444055},{"batb":[[0,1.62,57.99],[1,1.01,15.51],[2,1.81,0]],"batl":[[0,2.36,78.63],[1,2.88,0.31],[2,1.99,0]],"ltp":2.0,"tv":1321.96,"id":8257852}]}]}
{"op":"mcm","clk":"1012229417","pt":1580660227082,"mc":[{"id":"1.168223930","rc":[{"batb":[[0,1.66,359.17],[1,1.65,250.25],[2,1.62,57.99]],"batl":[[0,2.02,245.43],[1,2.04,252.16],[2,2.36,78.63]],"ltp":2.0,"tv":1321.96,"id":8257852}]}]}
{"op":"mcm","clk":"1012230916","pt":1580660235031,"mc":[{"id":"1.168223930","rc":[{"batb":[[0,1.62,57.99],[1,1.01,15.51],[2,1.62,0]],"ltp":2.0,"tv":1321.96,"id":8257852}]}]}
{"op":"mcm","clk":"1012231566","pt":1580660238220,"mc":[{"id":"1.168223930","rc":[{"batb":[[0,1.93,338.46],[1,1.91,886.91],[2,1.62,57.99]],"ltp":2.0,"tv":1321.96,"id":8257852}]}]}
{"op":"mcm","clk":"1012231729","pt":1580660239030,"mc":[{"id":"1.168223930","rc":[{"batb":[[1,1.93,44.53],[2,1.88,35.25]],"batl":[[0,2.08,38.65]],"ltp":1.86,"tv":614.82,"id":8444055},{"batb":[[1,1.91,920.67],[2,1.75,44.77]],"batl":[[2,2.08,38.65]],"ltp":2.0,"tv":1321.96,"id":8257852}]}]}
{"op":"mcm","clk":"1012232149","pt":1580660241052,"mc":[{"id":"1.168223930","rc":[{"batb":[[1,1.92,45.37],[2,1.91,335.3]],"ltp":2.0,"tv":1321.96,"id":8257852}]}]}
{"op":"mcm","clk":"1012232344","pt":1580660242136,"mc":[{"id":"1.168223930","rc":[{"batl":[[1,2.72,434.1]],"ltp":1.86,"tv":614.82,"id":8444055}]}]}
{"op":"mcm","clk":"1012233991","pt":1580660251251,"mc":[{"id":"1.168223930","rc":[{"batb":[[0,1.93,44.53],[1,1.88,35.25],[2,1.01,15.51]],"ltp":1.86,"tv":614.82,"id":8444055},{"batb":[[0,1.92,45.37],[1,1.75,44.77],[2,1.01,15.51]],"batl":[[0,2.08,38.65],[1,2.36,78.63],[2,2.88,0.31]],"ltp":2.0,"tv":1321.96,"id":8257852}]}]}
{"op":"mcm","clk":"1012234152","pt":1580660252114,"mc":[{"id":"1.168223930","rc":[{"batb":[[0,1.88,35.25],[1,1.01,15.51],[2,1.01,0]],"batl":[[0,2.72,434.1],[1,2.72,0]],"ltp":1.86,"tv":614.82,"id":8444055},{"batb":[[0,1.75,44.77],[1,1.01,15.51],[2,1.01,0]],"batl":[[0,2.36,78.63],[1,2.88,0.31],[2,2.88,0]],"ltp":2.0,"tv":1321.96,"id":8257852}]}]}
{"op":"mcm","clk":"1012234442","pt":1580660253965,"mc":[{"id":"1.168223930","rc":[{"batb":[[0,1.79,223.24],[1,1.77,387.76],[2,1.75,44.77]],"batl":[[0,2.12,261.73],[1,2.14,219.02],[2,2.36,78.63]],"ltp":2.0,"tv":1321.96,"id":8257852}]}]}
{"op":"mcm","clk":"1012240037","pt":1580660287202,"mc":[{"id":"1.168223930","rc":[{"batb":[[0,1.75,44.77],[1,1.01,15.51],[2,1.75,0]],"batl":[[0,2.36,78.63],[1,2.88,0.31],[2,2.36,0]],"ltp":2.0,"tv":1321.96,"id":8257852}]}]}
{"op":"mcm","clk":"1012240512","pt":1580660290079,"mc":[{"id":"1.168223930","rc":[{"batb":[[0,1.9,319.45],[1,1.88,317.37],[2,1.75,44.77]],"batl":[[0,1.99,312.86],[1,2.02,391.72],[2,2.36,78.63]],"ltp":2.0,"tv":1321.96,"id":8257852}]}]}
{"op":"mcm","clk":"1012240966","pt":1580660292894,"mc":[{"id":"1.168223930","rc":[{"batb":[[0,1.75,44.77],[1,1.01,15.51],[2,1.75,0]],"batl":[[0,2.36,78.63],[1,2.88,0.31],[2,2.36,0]],"ltp":2.0,"tv":1321.96,"id":8257852}]}]}
{"op":"mcm","clk":"1012241444","pt":1580660295889,"mc":[{"id":"1.168223930","rc":[{"batb":[[0,1.79,225.18],[1,1.77,387.76],[2,1.75,44.77]],"batl":[[0,2.12,260.13],[1,2.14,219.02],[2,2.36,78.63]],"ltp":2.0,"tv":1321.96,"id":8257852}]}]}
{"op":"mcm","clk":"1012243308","pt":1580660307053,"mc":[{"id":"1.168223930","rc":[{"batb":[[0,1.75,44.77],[1,1.01,15.51],[2,1.75,0]],"batl":[[0,2.36,78.63],[1,2.88,0.31],[2,2.36,0]],"ltp":2.0,"tv":1321.96,"id":8257852}]}]}
{"op":"mcm","clk":"1012243879","pt":1580660310254,"mc":[{"id":"1.168223930","rc":[{"batb":[[0,1.89,336.65],[1,1.88,35.25],[2,1.87,322.03]],"batl":[[0,1.98,308.07],[1,2,266.11]],"ltp":1.86,"tv":614.82,"id":8444055},{"batb":[[0,1.96,554.87],[1,1.75,44.77],[2,1.01,15.51]],"batl":[[0,2.88,0.31],[1,2.88,0]],"ltp":2.0,"tv":1321.96,"id":8257852}]}]}
{"op":"mcm","clk":"1012244072","pt":1580660311249,"mc":[{"id":"1.168223930","rc":[{"batl":[[1,2,308.12]],"ltp":1.86,"tv":614.82,"id":8444055},{"batb":[[0,2,57.91],[1,1.99,42.01],[2,1.96,554.87]],"batl":[[0,2.18,35.29],[1,2.88,0.31]],"ltp":2.0,"tv":1321.96,"id":8257852}]}]}
{"op":"mcm","clk":"1012244408","pt":1580660313173,"mc":[{"id":"1.168223930","rc":[{"batl":[[2,2.6,458.45]],"ltp":1.86,"tv":614.82,"id":8444055},{"batb":[[2,1.87,35.72]],"batl":[[1,2.6,56.68],[2,2.88,0.31]],"ltp":2.0,"tv":1321.96,"id":8257852}]}]}
{"op":"mcm","clk":"1012247416","pt":1580660330162,"mc":[{"id":"1.168223930","rc":[{"batb":[[0,1.84,49.57],[1,1.82,39.18],[2,1.01,15.51]],"batl":[[0,2,42.01],[1,2.6,458.45],[2,2.6,0]],"ltp":1.86,"tv":614.82,"id":8444055},{"batb":[[0,1.99,42.01],[1,1.87,35.72],[2,1.01,15.51]],"ltp":2.0,"tv":1321.96,"id":8257852}]}]}
{"op":"mcm","clk":"1012247768","pt":1580660332180,"mc":[{"id":"1.168223930","rc":[{"batb":[[0,1.82,39.18],[1,1.01,15.51],[2,1.01,0]],"batl":[[0,2.6,458.45],[1,2.6,0]],"ltp":1.86,"tv":614.82,"id":8444055},{"batb":[[0,1.87,35.72],[1,1.01,15.51],[2,1.01,0]],"batl":[[0,2.6,56.68],[1,2.88,0.31],[2,2.88,0]],"ltp":2.0,"tv":1321.96,"id":8257852}]}]}
{"op":"mcm","clk":"1012247910","pt":1580660333103,"mc":[{"id":"1.168223930","rc":[{"batb":[[0,1.84,334.47],[1,1.82,389.98],[2,1.01,15.51]],"ltp":1.86,"tv":614.82,"id":8444055}]}]}
{"op":"mcm","clk":"1012248236","pt":1580660335099,"mc":[{"id":"1.168223930","rc":[{"batl":[[0,1.92,252.8],[1,1.94,291.12]],"ltp":1.86,"tv":614.82,"id":8444055},{"batb":[[0,2.16,459.21],[1,1.87,35.72],[2,1.01,15.51]],"ltp":2.0,"tv":1321.96,"id":8257852}]}]}
{"op":"mcm","clk":"1012248429","pt":1580660336087,"mc":[{"id":"1.168223930","rc":[{"batb":[[2,1.78,41.86]],"ltp":1.86,"tv":614.82,"id":8444055},{"batb":[[1,2.08,51.77],[2,1.98,59.88]],"ltp":2.0,"tv":1321.96,"id":8257852}]}]}
{"op":"mcm","clk":"1012248591","pt":1580660337108,"mc":[{"id":"1.168223930","rc":[{"batb":[[2,1.81,51.25]],"batl":[[2,1.96,42.01]],"ltp":1.86,"tv":614.82,"id":8444055},{"batl":[[0,2.24,33.61],[1,2.6,56.68],[2,2.88,0.31]],"ltp":2.0,"tv":1321.96,"id":8257852}]}]}
{"op":"mcm","clk":"1012248719","pt":1580660338017,"mc":[{"id":"1.168223930","rc":[{"batb":[[0,2.08,51.77],[1,2.06,39.49]],"ltp":2.0,"tv":1321.96,"id":8257852}]}]}
{"op":"mcm","clk":"1012250397","pt":1580660347209,"mc":[{"id":"1.168223930","rc":[{"batb":[[0,1.82,295.45],[1,1.81,51.25],[2,1.78,41.86]],"batl":[[0,1.96,42.01],[1,2.5,484.62],[2,1.96,0]],"ltp":1.86,"tv":614.82,"id":8444055}]}]}
{"op":"mcm","clk":"1012250532","pt":1580660347919,"mc":[{"id":"1.168223930","rc":[{"batb":[[0,1.82,256.27],[1,1.78,41.86],[2,1.01,15.51]],"batl":[[0,2.5,484.62],[1,2.5,0]],"ltp":1.86,"tv":614.82,"id":8444055},{"batb":[[0,1.98,59.88],[1,1.01,15.51],[2,1.98,0]],"batl":[[0,2.6,56.68],[1,2.88,0.31],[2,2.88,0]],"ltp":2.0,"tv":1321.96,"id":8257852}]}]}
{"op":"mcm","clk":"1012250967","pt":1580660350242,"mc":[{"id":"1.168223930","rc":[{"batb":[[1,1.8,363.23],[2,1.78,41.86]],"batl":[[0,1.98,288.94],[1,2,266.06],[2,2.5,484.62]],"ltp":1.86,"tv":614.82,"id":8444055}]}]}
{"op":"mcm","clk":"1012251106","pt":1580660350919,"mc":[{"id":"1.168223930","rc":[{"batl":[[0,2.5,484.62],[1,2,0],[2,2.5,0]],"ltp":1.86,"tv":614.82,"id":8444055}]}]}
{"op":"mcm","clk":"1012251514","pt":1580660353232,"mc":[{"id":"1.168223930","rc":[{"batl":[[0,1.89,208.48],[1,1.91,305.17],[2,2.5,484.62]],"ltp":1.86,"tv":614.82,"id":8444055}]}]}
{"op":"mcm","clk":"1012251703","pt":1580660354214,"mc":[{"id":"1.168223930","rc":[{"batb":[[2,1.79,41.78]],"ltp":1.86,"tv":614.82,"id":8444055},{"batb":[[0,2.12,48.47],[1,2,58.3],[2,1.01,15.51]],"ltp":2.0,"tv":1321.96,"id":8257852}]}]}
{"op":"mcm","clk":"1012251881","pt":1580660355130,"mc":[{"id":"1.168223930","rc":[{"batl":[[2,1.92,42.01]],"ltp":1.86,"tv":614.82,"id":8444055},{"batb":[[1,2.1,37.81],[2,2,58.3]],"batl":[[0,2.3,31.93],[1,2.6,56.68],[2,2.88,0.31]],"ltp":2.0,"tv":1321.96,"id":8257852}]}]}
{"op":"mcm","clk":"1012252589","pt":1580660359015,"mc":[{"id":"1.168223930","rc":[{"batb":[[2,1.79,41.54]],"ltp":1.86,"tv":614.82,"id":8444055}]}]}
{"op":"mcm","clk":"1012254443","pt":1580660370150,"mc":[{"id":"1.168223930","rc":[{"batb":[[2,1.79,41.07]],"ltp":1.86,"tv":614.82,"id":8444055},{"batb":[[2,1.99,59.33]],"ltp":2.0,"tv":1321.96,"id":8257852}]}]}
{"op":"mcm","clk":"1012254805","pt":1580660372272,"mc":[{"id":"1.168223930","rc":[{"trd":[[1.82,512.54]],"batb":[[0,1.8,363.23],[1,1.79,41.07],[2,1.78,53.77]],"batl":[[0,1.82,223.73],[1,1.89,208.48],[2,1.91,305.17]],"ltp":1.82,"tv":1127.36,"id":8444055}],"tv":2449.32}]}
{"op":"mcm","clk":"1012254947","pt":1580660373122,"mc":[{"id":"1.168223930","rc":[{"batb":[[0,1.79,41.07],[1,1.78,53.77],[2,1.61,58.85]],"ltp":1.82,"tv":1127.36,"id":8444055}]}]}
{"op":"mcm","clk":"1012255122","pt":1580660374249,"mc":[{"id":"1.168223930","rc":[{"trd":[[1.82,519.79]],"batl":[[0,1.82,216.48]],"ltp":1.82,"tv":1134.61,"id":8444055},{"trd":[[2.2,6.16]],"ltp":2.2,"tv":1327.96,"id":8257852}],"tv":2462.57}]}
{"op":"mcm","clk":"1012255426","pt":1580660376029,"mc":[{"id":"1.168223930","rc":[{"batb":[[0,1.81,342.37],[1,1.79,411.57],[2,1.78,53.77]],"batl":[[1,1.89,299.45]],"ltp":1.82,"tv":1134.61,"id":8444055}]}]}
{"op":"mcm","clk":"1012257109","pt":1580660386155,"mc":[{"id":"1.168223930","rc":[{"batb":[[1,1.8,40.91],[2,1.79,370.5]],"ltp":1.82,"tv":1134.61,"id":8444055},{"batb":[[0,2.1,87.38],[1,1.99,59.33],[2,1.01,15.51]],"ltp":2.2,"tv":1327.96,"id":8257852}]}]}
{"op":"mcm","clk":"1012259781","pt":1580660401989,"mc":[{"id":"1.168223930","rc":[{"batb":[[1,1.8,40.36]],"ltp":1.82,"tv":1134.61,"id":8444055},{"batb":[[1,1.98,60.35]],"ltp":2.2,"tv":1327.96,"id":8257852}]}]}
{"op":"mcm","clk":"1012265907","pt":1580660434934,"mc":[{"id":"1.168223930","rc":[{"batl":[[0,1.89,299.45],[1,1.91,305.17],[2,1.92,42.01]],"ltp":1.82,"tv":1134.61,"id":8444055}]}]}
{"op":"mcm","clk":"1012266537","pt":1580660438236,"mc":[{"id":"1.168223930","rc":[{"trd":[[1.81,432.96]],"batb":[[0,1.81,125.89]],"batl":[[0,1.92,42.01],[1,2.5,484.62],[2,1.92,0]],"ltp":1.81,"tv":1567.57,"id":8444055}],"tv":2895.53}]}
{"op":"mcm","clk":"1012267106","pt":1580660441229,"mc":[{"id":"1.168223930","rc":[{"batb":[[0,1.81,262.58]],"batl":[[0,1.88,220.21],[1,1.9,310.59],[2,1.92,42.01]],"ltp":1.81,"tv":1567.57,"id":8444055}]}]}
{"op":"mcm","clk":"1012267557","pt":1580660443225,"mc":[{"id":"1.168223930","rc":[{"batb":[[0,1.78,53.77],[1,1.62,57.91],[2,1.01,15.51]],"batl":[[0,1.92,42.01],[1,2.5,484.62],[2,1.92,0]],"ltp":1.81,"tv":1567.57,"id":8444055},{"batb":[[0,2.1,37.81]],"ltp":2.2,"tv":1327.96,"id":8257852}]}]}
{"op":"mcm","clk":"1012267778","pt":1580660444249,"mc":[{"id":"1.168223930","rc":[{"batb":[[0,1.62,57.91],[1,1.01,15.51],[2,1.01,0]],"batl":[[0,2.5,484.62],[1,2.5,0]],"ltp":1.81,"tv":1567.57,"id":8444055},{"batb":[[0,1.98,60.35],[1,1.01,15.51],[2,1.01,0]],"batl":[[0,2.6,56.68],[1,2.88,0.31],[2,2.88,0]],"ltp":2.2,"tv":1327.96,"id":8257852}]}]}
{"op":"mcm","clk":"1012268162","pt":1580660446264,"mc":[{"id":"1.168223930","rc":[{"batb":[[0,1.63,57.04],[1,1.62,57.91],[2,1.01,15.51]],"batl":[[0,2,280.8],[1,2.02,259.17],[2,2.5,484.62]],"ltp":1.81,"tv":1567.57,"id":8444055},{"batb":[[0,1.97,61.37]],"ltp":2.2,"tv":1327.96,"id":8257852}]}]}
{"op":"mcm","clk":"1012268340","pt":1580660447037,"mc":[{"id":"1.168223930","rc":[{"batb":[[1,1.01,15.51],[2,1.01,0]],"ltp":1.81,"tv":1567.57,"id":8444055}]}]}
{"op":"mcm","clk":"1012268547","pt":1580660448159,"mc":[{"id":"1.168223930","rc":[{"batb":[[0,1.91,334.15],[1,1.89,312.16],[2,1.84,634.15]],"ltp":1.81,"tv":1567.57,"id":8444055}]}]}
{"op":"mcm","clk":"1012268695","pt":1580660448851,"mc":[{"id":"1.168223930","rc":[{"batb":[[2,1.87,47.89]],"batl":[[1,2.02,300.34]],"ltp":1.81,"tv":1567.57,"id":8444055},{"batb":[[0,1.98,42.85],[1,1.97,61.37],[2,1.01,15.51]],"batl":[[0,2.18,35.29],[1,2.6,56.68],[2,2.88,0.31]],"ltp":2.2,"tv":1327.96,"id":8257852}]}]}
{"op":"mcm","clk":"1012268934","pt":1580660450265,"mc":[{"id":"1.168223930","rc":[{"batb":[[0,1.92,33.28],[1,1.91,334.15],[2,1.89,312.16]],"ltp":1.81,"tv":1567.57,"id":8444055},{"batb":[[2,1.88,35.17]],"ltp":2.2,"tv":1327.96,"id":8257852}]}]}
{"op":"mcm","clk":"1012270998","pt":1580660461153,"mc":[{"id":"1.168223930","rc":[{"batb":[[0,1.87,47.89],[1,1.76,44.14],[2,1.01,15.51]],"batl":[[0,2.02,41.17],[1,2.5,484.62],[2,2.5,0]],"ltp":1.81,"tv":1567.57,"id":8444055},{"batb":[[1,1.88,35.17],[2,1.01,15.51]],"batl":[[0,2.6,56.68],[1,2.88,0.31],[2,2.88,0]],"ltp":2.2,"tv":1327.96,"id":8257852}]}]}
{"op":"mcm","clk":"1012271225","pt":1580660462193,"mc":[{"id":"1.168223930","rc":[{"batb":[[0,1.76,44.14],[1,1.01,15.51],[2,1.01,0]],"batl":[[0,2.5,484.62],[1,2.5,0]],"ltp":1.81,"tv":1567.57,"id":8444055},{"batb":[[0,1.88,35.17],[1,1.01,15.51],[2,1.01,0]],"ltp":2.2,"tv":1327.96,"id":8257852}]}]}
{"op":"mcm","clk":"1012271603","pt":1580660464067,"mc":[{"id":"1.168223930","rc":[{"batb":[[0,1.76,458.19],[1,1.74,407.32],[2,1.01,15.51]],"batl":[[0,2.1,306.69],[1,2.12,225.9],[2,2.5,484.62]],"ltp":1.81,"tv":1567.57,"id":8444055}]}]}
{"op":"mcm","clk":"1012271820","pt":1580660465065,"mc":[{"id":"1.168223930","rc":[{"batb":[[0,1.76,414.05],[1,1.75,44.53],[2,1.74,407.32]],"batl":[[0,2.5,484.62],[1,2.12,0],[2,2.5,0]],"ltp":1.81,"tv":1567.57,"id":8444055}]}]}
{"op":"mcm","clk":"1012272347","pt":1580660468031,"mc":[{"id":"1.168223930","rc":[{"batl":[[0,1.84,332.02],[1,1.86,330.99],[2,1.91,532.68]],"ltp":1.81,"tv":1567.57,"id":8444055}]}]}
{"op":"mcm","clk":"1012272585","pt":1580660469121,"mc":[{"id":"1.168223930","rc":[{"batb":[[1,1.75,99.99]],"batl":[[2,1.88,42.01]],"ltp":1.81,"tv":1567.57,"id":8444055},{"batb":[[0,2.18,45.24],[1,2.14,36.13],[2,2,58.07]],"batl":[[0,2.36,30.25],[1,2.6,56.68],[2,2.88,0.31]],"ltp":2.2,"tv":1327.96,"id":8257852}]}]}
{"op":"mcm","clk":"1012274172","pt":1580660478124,"mc":[{"id":"1.168223930","rc":[{"batb":[[0,1.55,68.37],[1,1.01,15.51],[2,1.74,0]],"batl":[[0,2.5,484.62],[1,1.86,0],[2,1.88,0]],"ltp":1.81,"tv":1567.57,"id":8444055},{"batb":[[0,2,58.07],[1,1.01,15.51],[2,2,0]],"batl":[[0,2.6,56.68],[1,2.88,0.31],[2,2.88,0]],"ltp":2.2,"tv":1327.96,"id":8257852}]}]}
{"op":"mcm","clk":"1012274746","pt":1580660481071,"mc":[{"id":"1.168223930","rc":[{"batl":[[0,1.98,285.57],[1,2,266.8],[2,2.5,484.62]],"ltp":1.81,"tv":1567.57,"id":8444055}]}]}
{"op":"mcm","clk":"1012275275","pt":1580660484133,"mc":[{"id":"1.168223930","rc":[{"batb":[[0,1.9,205.73],[1,1.88,352.23],[2,1.86,619.39]],"ltp":1.81,"tv":1567.57,"id":8444055},{"batb":[[1,1.89,34.54],[2,1.01,15.51]],"ltp":2.2,"tv":1327.96,"id":8257852}]}]}
{"op":"mcm","clk":"1012275436","pt":1580660485046,"mc":[{"id":"1.168223930","rc":[{"batl":[[0,1.98,327.58]],"ltp":1.81,"tv":1567.57,"id":8444055},{"batb":[[0,2,100.08]],"ltp":2.2,"tv":1327.96,"id":8257852}]}]}
{"op":"mcm","clk":"1012275802","pt":1580660486922,"mc":[{"id":"1.168223930","rc":[{"batb":[[2,1.84,49.57]],"ltp":1.81,"tv":1567.57,"id":8444055}]}]}
{"op":"mcm","clk":"1012276884","pt":1580660493154,"mc":[{"id":"1.168223930","rc":[{"batb":[[0,1.84,49.57],[1,1.7,49.1],[2,1.01,15.51]],"batl":[[0,1.98,42.01],[1,2.5,484.62],[2,2.5,0]],"ltp":1.81,"tv":1567.57,"id":8444055},{"batb":[[0,2,42.01]],"ltp":2.2,"tv":1327.96,"id":8257852}]}]}
{"op":"mcm","clk":"1012277030","pt":1580660493864,"mc":[{"id":"1.168223930","rc":[{"batb":[[0,1.7,49.1],[1,1.01,15.51],[2,1.01,0]],"batl":[[0,2.5,484.62],[1,2.5,0]],"ltp":1.81,"tv":1567.57,"id":8444055},{"batb":[[0,1.89,34.54],[1,1.01,15.51],[2,1.01,0]],"ltp":2.2,"tv":1327.96,"id":8257852}]}]}
{"op":"mcm","clk":"1012277804","pt":1580660498257,"mc":[{"id":"1.168223930","rc":[{"batb":[[0,1.98,543.55],[1,1.7,49.1],[2,1.01,15.51]],"ltp":1.81,"tv":1567.57,"id":8444055},{"batl":[[0,2.88,0.31],[1,2.88,0]],"ltp":2.2,"tv":1327.96,"id":8257852}]}]}
{"op":"mcm","clk":"1012277971","pt":1580660499176,"mc":[{"id":"1.168223930","rc":[{"batb":[[0,1.99,59.09],[1,1.98,543.55],[2,1.87,35.72]],"batl":[[0,2.12,36.97],[1,2.5,484.62]],"ltp":1.81,"tv":1567.57,"id":8444055},{"batb":[[0,1.91,326.05],[1,1.9,46.21],[2,1.89,347.18]],"batl":[[0,2,292.34],[1,2.02,260.31],[2,2.88,0.31]],"ltp":2.2,"tv":1327.96,"id":8257852}]}]}
{"op":"mcm","clk":"1012278138","pt":1580660500046,"mc":[{"id":"1.168223930","rc":[{"batb":[[2,1.93,44.53]],"ltp":1.81,"tv":1567.57,"id":8444055}]}]}
{"op":"mcm","clk":"1012278554","pt":1580660502187,"mc":[{"id":"1.168223930","rc":[{"batb":[[1,1.93,44.53],[2,1.87,35.72]],"ltp":1.81,"tv":1567.57,"id":8444055},{"batl":[[2,2.06,39.49]],"ltp":2.2,"tv":1327.96,"id":8257852}]}]}
{"op":"mcm","clk":"1012279010","pt":1580660504884,"mc":[{"id":"1.168223930","rc":[{"trd":[[2,6.63]],"ltp":2.0,"tv":1574.2,"id":8444055},{"trd":[[2,77.37]],"batl":[[0,2,285.71]],"ltp":2.0,"tv":1334.59,"id":8257852}],"tv":2908.79}]}
{"op":"mcm","clk":"1012279790","pt":1580660509160,"mc":[{"id":"1.168223930","rc":[{"batb":[[0,1.93,44.53],[1,1.87,35.72],[2,1.01,15.51]],"ltp":2.0,"tv":1574.2,"id":8444055},{"batb":[[0,1.9,46.21],[1,1.83,38.24],[2,1.01,15.51]],"batl":[[0,2.06,39.49],[1,2.5,63.78],[2,2.88,0.31]],"ltp":2.0,"tv":1334.59,"id":8257852}]}]}
{"op":"mcm","clk":"1012279977","pt":1580660510269,"mc":[{"id":"1.168223930","rc":[{"batb":[[0,1.87,35.72],[1,1.01,15.51],[2,1.01,0]],"batl":[[0,2.5,484.62],[1,2.5,0]],"ltp":2.0,"tv":1574.2,"id":8444055},{"batb":[[0,1.83,38.24],[1,1.01,15.51],[2,1.01,0]],"batl":[[0,2.5,63.78],[1,2.88,0.31],[2,2.88,0]],"ltp":2.0,"tv":1334.59,"id":8257852}]}]}
{"op":"mcm","clk":"1012280697","pt":1580660514174,"mc":[{"id":"1.168223930","rc":[{"batb":[[0,1.93,319.26],[1,1.91,302.27],[2,1.83,38.24]],"batl":[[0,2.02,266.52],[1,2.04,252.74],[2,2.5,63.78]],"ltp":2.0,"tv":1334.59,"id":8257852}]}]}
{"op":"mcm","clk":"1012281220","pt":1580660517121,"mc":[{"id":"1.168223930","rc":[{"batb":[[0,1.83,38.24],[1,1.01,15.51],[2,1.83,0]],"batl":[[0,2.5,63.78],[1,2.88,0.31],[2,2.5,0]],"ltp":2.0,"tv":1334.59,"id":8257852}]}]}
{"op":"mcm","clk":"1012281746","pt":1580660519971,"mc":[{"id":"1.168223930","rc":[{"batb":[[0,1.86,358.53],[1,1.84,341.16],[2,1.83,38.24]],"batl":[[0,2.12,350.74],[1,2.14,219.75],[2,2.5,63.78]],"ltp":2.0,"tv":1334.59,"id":8257852}]}]}
{"op":"mcm","clk":"1012282200","pt":1580660522900,"mc":[{"id":"1.168223930","rc":[{"batl":[[0,2.5,63.78],[1,2.88,0.31],[2,2.5,0]],"ltp":2.0,"tv":1334.59,"id":8257852}]}]}
{"op":"mcm","clk":"1012282730","pt":1580660526070,"mc":[{"id":"1.168223930","rc":[{"batb":[[0,2.06,53.19],[1,1.94,32.26],[2,1.87,35.72]],"ltp":2.0,"tv":1574.2,"id":8444055},{"batl":[[0,1.94,207.37],[1,1.96,285.2],[2,2.5,63.78]],"ltp":2.0,"tv":1334.59,"id":8257852}]}]}
{"op":"mcm","clk":"1012282878","pt":1580660526902,"mc":[{"id":"1.168223930","rc":[{"batb":[[1,1.99,42.01],[2,1.94,32.26]],"batl":[[0,2.18,35.29]],"ltp":2.0,"tv":1574.2,"id":8444055},{"batb":[[1,1.85,48.73],[2,1.84,341.16]],"batl":[[2,2,42.01]],"ltp":2.0,"tv":1334.59,"id":8257852}]}]}
{"op":"mcm","clk":"1012283174","pt":1580660528515,"mc":[{"id":"1.168223930","rc":[{"batl":[[1,2.82,414.36]],"ltp":2.0,"tv":1574.2,"id":8444055}]}]}
{"op":"mcm","clk":"1012286813","pt":1580660549051,"mc":[{"id":"1.168223930","rc":[{"trd":[[2.06,56.07]],"batb":[[0,2.06,25.15]],"ltp":2.06,"tv":1630.27,"id":8444055}],"tv":2964.86}]}
{"op":"mcm","clk":"1012287585","pt":1580660553206,"mc":[{"id":"1.168223930","rc":[{"batb":[[0,1.99,42.01],[1,1.94,32.26],[2,1.01,15.51]],"ltp":2.06,"tv":1630.27,"id":8444055},{"batb":[[0,1.85,48.73],[1,1.64,55.16],[2,1.01,15.51]],"batl":[[0,2,42.01],[1,2.5,63.78],[2,2.88,0.31]],"ltp":2.0,"tv":1334.59,"id":8257852}]}]}
{"op":"mcm","clk":"1012287737","pt":1580660554106,"mc":[{"id":"1.168223930","rc":[{"batb":[[0,1.94,32.26],[1,1.01,15.51],[2,1.01,0]],"batl":[[0,2.82,414.36],[1,2.82,0]],"ltp":2.06,"tv":1630.27,"id":8444055},{"batb":[[0,1.64,55.16],[1,1.01,15.51],[2,1.01,0]],"batl":[[0,2.5,63.78],[1,2.88,0.31],[2,2.88,0]],"ltp":2.0,"tv":1334.59,"id":8257852}]}]}
{"op":"mcm","clk":"1012287918","pt":1580660555236,"mc":[{"id":"1.168223930","rc":[{"batb":[[0,1.68,263.65],[1,1.67,239.59],[2,1.64,55.16]],"batl":[[0,2.08,363.24],[1,2.1,232.06],[2,2.5,63.78]],"ltp":2.0,"tv":1334.59,"id":8257852}]}]}
{"op":"mcm","clk":"1012288085","pt":1580660556212,"mc":[{"id":"1.168223930","rc":[{"batb":[[0,1.93,32.73]],"ltp":2.06,"tv":1630.27,"id":8444055},{"batb":[[1,1.67,294.04],[2,1.01,15.51]],"ltp":2.0,"tv":1334.59,"id":8257852}]}]}
{"op":"mcm","clk":"1012289257","pt":1580660563125,"mc":[{"id":"1.168223930","rc":[{"batl":[[0,2.5,63.78],[1,2.88,0.31],[2,2.5,0]],"ltp":2.0,"tv":1334.59,"id":8257852}]}]}
{"op":"mcm","clk":"1012289525","pt":1580660564736,"mc":[{"id":"1.168223930","rc":[{"batl":[[0,2.88,0.31],[1,2.88,0]],"ltp":2.0,"tv":1334.59,"id":8257852}]}]}
{"op":"mcm","clk":"1012289750","pt":1580660565933,"mc":[{"id":"1.168223930","rc":[{"batl":[[0,1.74,301.7],[1,1.76,402.54],[2,2.88,0.31]],"ltp":2.0,"tv":1334.59,"id":8257852}]}]}
{"op":"mcm","clk":"1012289950","pt":1580660567151,"mc":[{"id":"1.168223930","rc":[{"batb":[[0,2.36,36.27],[1,2.22,33.61],[2,2.12,48.78]],"batl":[[0,2.46,28.57]],"ltp":2.06,"tv":1630.27,"id":8444055},{"batb":[[0,1.69,60.49],[1,1.68,263.65],[2,1.67,294.04]],"batl":[[2,1.82,42.01]],"ltp":2.0,"tv":1334.59,"id":8257852}]}]}
{"op":"mcm","clk":"1012290122","pt":1580660568244,"mc":[{"id":"1.168223930","rc":[{"batl":[[1,3.3,346.08]],"ltp":2.06,"tv":1630.27,"id":8444055}]}]}
{"op":"mcm","clk":"1012292374","pt":1580660581260,"mc":[{"id":"1.168223930","rc":[{"trd":[[2.36,10]],"batb":[[0,2.36,31.27],[1,2.12,48.78],[2,1.01,15.51]],"ltp":2.36,"tv":1640.27,"id":8444055},{"batb":[[0,1.68,263.65],[1,1.67,294.04],[2,1.45,90.8]],"batl":[[2,2.16,110.05]],"ltp":2.0,"tv":1334.59,"id":8257852}],"tv":2974.86}]}
{"op":"mcm","clk":"1012292740","pt":1580660583177,"mc":[{"id":"1.168223930","rc":[{"batb":[[0,2.12,48.78],[1,1.01,15.51],[2,1.01,0]],"ltp":2.36,"tv":1640.27,"id":8444055},{"batb":[[0,1.45,90.8],[1,1.01,15.51],[2,1.45,0]],"batl":[[0,2.16,110.05],[1,2.88,0.31],[2,2.16,0]],"ltp":2.0,"tv":1334.59,"id":8257852}]}]}
{"op":"mcm","clk":"1012292921","pt":1580660584180,"mc":[{"id":"1.168223930","rc":[{"batb":[[0,2.24,33.61],[1,2.12,48.78],[2,1.01,15.51]],"batl":[[0,3.3,346.08],[1,3.3,0]],"ltp":2.36,"tv":1640.27,"id":8444055},{"batb":[[0,1.68,61.33],[1,1.45,90.8],[2,1.01,15.51]],"batl":[[0,1.81,42.01],[1,2.16,110.05],[2,2.88,0.31]],"ltp":2.0,"tv":1334.59,"id":8257852}]}]}
{"op":"mcm","clk":"1012293112","pt":1580660585163,"mc":[{"id":"1.168223930","rc":[{"batb":[[0,2.12,48.78],[1,1.01,15.51],[2,1.01,0]],"ltp":2.36,"tv":1640.27,"id":8444055},{"batb":[[0,1.45,90.8],[1,1.01,15.51],[2,1.01,0]],"batl":[[0,2.16,110.05],[1,2.88,0.31],[2,2.88,0]],"ltp":2.0,"tv":1334.59,"id":8257852}]}]}
{"op":"mcm","clk":"1012293287","pt":1580660586186,"mc":[{"id":"1.168223930","rc":[{"batb":[[0,1.46,90.25]],"ltp":2.0,"tv":1334.59,"id":8257852}]}]}
{"op":"mcm","clk":"1012293855","pt":1580660589257,"mc":[{"id":"1.168223930","rc":[{"batb":[[0,1.63,358.74],[1,1.62,268.08],[2,1.46,90.25]],"batl":[[0,1.69,332.05],[1,1.71,443.85],[2,2.16,110.05]],"ltp":2.0,"tv":1334.59,"id":8257852}]}]}
{"op":"mcm","clk":"1012294347","pt":1580660591989,"mc":[{"id":"1.168223930","rc":[{"batb":[[0,1.46,90.25],[1,1.01,15.51],[2,1.46,0]],"batl":[[0,2.16,110.05],[1,2.88,0.31],[2,2.16,0]],"ltp":2.0,"tv":1334.59,"id":8257852}]}]}
{"op":"mcm","clk":"1012294883","pt":1580660595185,"mc":[{"id":"1.168223930","rc":[{"batb":[[0,1.47,378.15],[1,1.46,496.72],[2,1.01,15.51]],"ltp":2.0,"tv":1334.59,"id":8257852}]}]}
{"op":"mcm","clk":"1012295183","pt":1580660596831,"mc":[{"id":"1.168223930","rc":[{"batl":[[0,2.88,0.31],[1,2.88,0]],"ltp":2.0,"tv":1334.59,"id":8257852}]}]}
{"op":"mcm","clk":"1012295455","pt":1580660598190,"mc":[{"id":"1.168223930","rc":[{"batl":[[0,1.52,578.77],[1,1.53,330.24],[2,1.57,532.68]],"ltp":2.0,"tv":1334.59,"id":8257852}]}]}
{"op":"mcm","clk":"1012295654","pt":1580660599197,"mc":[{"id":"1.168223930","rc":[{"batb":[[0,2.94,50.2],[1,2.74,23.53],[2,2.54,29.66]],"batl":[[0,3.05,20.16]],"ltp":2.36,"tv":1640.27,"id":8444055},{"batb":[[0,1.48,87.38],[1,1.47,378.15],[2,1.46,496.72]],"batl":[[2,1.57,574.69]],"ltp":2.0,"tv":1334.59,"id":8257852}]}]}
{"op":"mcm","clk":"1012295990","pt":1580660601001,"mc":[{"id":"1.168223930","rc":[{"batb":[[1,2.54,29.66],[2,1.01,15.51]],"batl":[[0,4.2,265.14]],"ltp":2.36,"tv":1640.27,"id":8444055},{"batb":[[0,1.47,378.15],[1,1.46,496.72],[2,1.28,167.12]],"batl":[[2,1.57,42.01]],"ltp":2.0,"tv":1334.59,"id":8257852}]}]}
{"op":"mcm","clk":"1012296532","pt":1580660604006,"mc":[{"id":"1.168223930","rc":[{"batb":[[1,2.76,23.53],[2,2.54,29.66]],"batl":[[0,3.1,19.32],[1,4.2,265.14]],"ltp":2.36,"tv":1640.27,"id":8444055},{"batb":[[0,1.47,467.21]],"ltp":2.0,"tv":1334.59,"id":8257852}]}]}
{"op":"mcm","clk":"1012299457","pt":1580660621240,"mc":[{"id":"1.168223930","rc":[{"batb":[[0,2.76,23.53],[1,2.54,29.66],[2,1.01,15.51]],"ltp":2.36,"tv":1640.27,"id":8444055},{"batb":[[0,1.47,89.06],[1,1.28,167.12],[2,1.01,15.51]],"batl":[[0,1.89,179.89],[1,2.88,0.31],[2,1.57,0]],"ltp":2.0,"tv":1334.59,"id":8257852}]}]}
{"op":"mcm","clk":"1012299643","pt":1580660622232,"mc":[{"id":"1.168223930","rc":[{"batb":[[0,2.54,29.66],[1,1.01,15.51],[2,1.01,0]],"batl":[[0,4.2,265.14],[1,4.2,0]],"ltp":2.36,"tv":1640.27,"id":8444055},{"batb":[[0,1.28,167.12],[1,1.01,15.51],[2,1.01,0]],"ltp":2.0,"tv":1334.59,"id":8257852}]}]}
{"op":"mcm","clk":"1012299993","pt":1580660624265,"mc":[{"id":"1.168223930","rc":[{"batb":[[0,2.52,29.82]],"ltp":2.36,"tv":1640.27,"id":8444055},{"batb":[[0,1.28,1087],[1,1.27,822.22],[2,1.01,15.51]],"batl":[[0,1.65,247.91],[1,1.66,244.86],[2,1.89,179.89]],"ltp":2.0,"tv":1334.59,"id":8257852}]}]}
{"op":"mcm","clk":"1012302255","pt":1580660638059,"mc":[{"id":"1.168223930","rc":[{"trd":[[4.2,265.12]],"batl":[[0,4.2,0.03]],"ltp":4.2,"tv":1905.38,"id":8444055},{"trd":[[1.31,850]],"ltp":1.31,"tv":2184.59,"id":8257852}],"tv":4089.97}]}
{"op":"mcm","clk":"1012302577","pt":1580660640170,"mc":[{"id":"1.168223930","rc":[{"trd":[[2.52,15.15]],"batb":[[0,2.52,22.25]],"ltp":2.52,"tv":1920.53,"id":8444055}],"tv":4105.12}]}
{"op":"mcm","clk":"1012303613","pt":1580660645858,"mc":[{"id":"1.168223930","rc":[{"batb":[[0,1.28,166.65],[1,1.01,15.51],[2,1.01,0]],"ltp":1.31,"tv":2184.59,"id":8257852}]}]}
{"op":"mcm","clk":"1012303982","pt":1580660648078,"mc":[{"id":"1.168223930","rc":[{"batl":[[2,2.88,0.31]],"ltp":1.31,"tv":2184.59,"id":8257852}]}]}
{"op":"mcm","clk":"1012304182","pt":1580660649208,"mc":[{"id":"1.168223930","rc":[{"batb":[[1,2.46,28.57],[2,2.18,44.61]],"batl":[[0,2.72,24.37]],"ltp":2.52,"tv":1920.53,"id":8444055},{"batb":[[0,1.6,343.63],[1,1.59,287.47],[2,1.58,72.26]],"batl":[[2,1.69,42.01]],"ltp":1.31,"tv":2184.59,"id":8257852}]}]}
{"op":"mcm","clk":"1012304340","pt":1580660650077,"mc":[{"id":"1.168223930","rc":[{"batb":[[1,2.44,28.57]],"batl":[[0,2.7,24.37]],"ltp":2.52,"tv":1920.53,"id":8444055},{"batb":[[1,1.59,358.05],[2,1.52,1024.39]],"ltp":1.31,"tv":2184.59,"id":8257852}]}]}
{"op":"mcm","clk":"1012304460","pt":1580660651019,"mc":[{"id":"1.168223930","rc":[{"batl":[[1,3.45,4.34]],"ltp":2.52,"tv":1920.53,"id":8444055}]}]}
{"op":"mcm","clk":"1012304629","pt":1580660651988,"mc":[{"id":"1.168223930","rc":[{"batb":[[2,1.35,125.42]],"ltp":1.31,"tv":2184.59,"id":8257852}]}]}
{"op":"mcm","clk":"1012306562","pt":1580660662227,"mc":[{"id":"1.168223930","rc":[{"trd":[[1.6,600]],"batb":[[0,1.6,43.63]],"ltp":1.6,"tv":2784.59,"id":8257852}],"tv":4705.12}]}
{"op":"mcm","clk":"1012307297","pt":1580660666211,"mc":[{"id":"1.168223930","rc":[{"batb":[[1,1.59,536.13],[2,1.58,295.39]],"batl":[[0,1.65,347.14]],"ltp":1.6,"tv":2784.59,"id":8257852}]}]}
{"op":"mcm","clk":"1012307612","pt":1580660668013,"mc":[{"id":"1.168223930","rc":[{"batb":[[0,2.18,44.61],[1,1.01,15.51],[2,2.18,0]],"batl":[[0,3.45,4.34],[1,3.45,0]],"ltp":2.52,"tv":1920.53,"id":8444055},{"batb":[[0,1.35,125.42],[1,1.01,15.51],[2,1.58,0]],"batl":[[0,2.1,655.29],[1,2.88,0.31],[2,1.69,0]],"ltp":1.6,"tv":2784.59,"id":8257852}]}]}
{"op":"mcm","clk":"1012308179","pt":1580660671227,"mc":[{"id":"1.168223930","rc":[{"batb":[[0,2.2,44.3]],"ltp":2.52,"tv":1920.53,"id":8444055},{"batb":[[0,1.35,980.9],[1,1.34,613.32],[2,1.01,15.51]],"batl":[[0,1.84,372.07],[1,1.86,336.12],[2,2.1,655.29]],"ltp":1.6,"tv":2784.59,"id":8257852}]}]}
{"op":"mcm","clk":"1012308530","pt":1580660673197,"mc":[{"id":"1.168223930","rc":[{"batb":[[0,1.35,125.42],[1,1.01,15.51],[2,1.01,0]],"batl":[[0,2.1,655.29],[1,2.88,0.31],[2,2.1,0]],"ltp":1.6,"tv":2784.59,"id":8257852}]}]}
{"op":"mcm","clk":"1012309011","pt":1580660675823,"mc":[{"id":"1.168223930","rc":[{"batb":[[0,1.54,345.83],[1,1.53,334.82],[2,1.35,125.42]],"batl":[[0,1.59,353.42],[1,1.6,279.85],[2,2.1,655.29]],"ltp":1.6,"tv":2784.59,"id":8257852}]}]}
{"op":"mcm","clk":"1012309635","pt":1580660679218,"mc":[{"id":"1.168223930","rc":[{"batb":[[0,1.35,125.42],[1,1.01,15.51],[2,1.35,0]],"batl":[[0,2.1,655.29],[1,2.88,0.31],[2,2.1,0]],"ltp":1.6,"tv":2784.59,"id":8257852}]}]}
{"op":"mcm","clk":"1012310002","pt":1580660681269,"mc":[{"id":"1.168223930","rc":[{"batb":[[0,1.35,983.71],[1,1.34,613.32],[2,1.01,15.51]],"batl":[[0,1.84,370.06],[1,1.86,336.12],[2,2.1,655.29]],"ltp":1.6,"tv":2784.59,"id":8257852}]}]}
{"op":"mcm","clk":"1012311923","pt":1580660692063,"mc":[{"id":"1.168223930","rc":[{"batl":[[0,2.1,655.29],[1,2.88,0.31],[2,2.1,0]],"ltp":1.6,"tv":2784.59,"id":8257852}]}]}
{"op":"mcm","clk":"1012312250","pt":1580660694267,"mc":[{"id":"1.168223930","rc":[{"batl":[[0,2.88,0.31],[1,2.88,0]],"ltp":1.6,"tv":2784.59,"id":8257852}]}]}
{"op":"mcm","clk":"1012312413","pt":1580660695228,"mc":[{"id":"1.168223930","rc":[{"batb":[[0,3.5,32.34],[1,2.86,21.56],[2,2.2,44.3]],"ltp":2.52,"tv":1920.53,"id":8444055},{"batb":[[2,1.17,284.51]],"batl":[[0,1.39,372.95],[1,1.4,482.48],[2,1.46,532.68]],"ltp":1.6,"tv":2784.59,"id":8257852}]}]}
{"op":"mcm","clk":"1012312593","pt":1580660696263,"mc":[{"id":"1.168223930","rc":[{"batb":[[2,1.01,15.51]],"ltp":2.52,"tv":1920.53,"id":8444055}]}]}
{"op":"mcm","clk":"1012312687","pt":1580660696865,"mc":[{"id":"1.168223930","rc":[{"batb":[[1,3.3,17.64],[2,2.86,21.56]],"batl":[[0,3.75,15.12]],"ltp":2.52,"tv":1920.53,"id":8444055},{"batb":[[0,1.36,115.95],[1,1.35,983.71],[2,1.34,613.32]],"batl":[[2,1.43,42.01]],"ltp":1.6,"tv":2784.59,"id":8257852}]}]}
{"op":"mcm","clk":"1012312910","pt":1580660698157,"mc":[{"id":"1.168223930","rc":[{"batb":[[1,1.35,709.36],[2,1.17,284.51]],"ltp":1.6,"tv":2784.59,"id":8257852}]}]}
{"op":"mcm","clk":"1012313461","pt":1580660701203,"mc":[{"id":"1.168223930","rc":[{"batb":[[1,2.86,21.56],[2,1.01,15.51]],"ltp":2.52,"tv":1920.53,"id":8444055},{"batb":[[0,1.36,426.39]],"ltp":1.6,"tv":2784.59,"id":8257852}]}]}
{"op":"mcm","clk":"1012313794","pt":1580660703060,"mc":[{"id":"1.168223930","rc":[{"trd":[[1.36,557.64]],"batb":[[0,1.35,709.36],[1,1.17,284.51],[2,1.01,15.51]],"batl":[[2,1.73,901.5]],"ltp":1.36,"tv":3342.22,"id":8257852}],"tv":5262.76}]}
{"op":"mcm","clk":"1012314242","pt":1580660705970,"mc":[{"id":"1.168223930","rc":[{"batb":[[1,3.4,16.8],[2,2.86,21.56]],"batl":[[0,3.85,14.28]],"ltp":2.52,"tv":1920.53,"id":8444055},{"batb":[[0,1.35,962.21],[1,1.34,736.86],[2,1.17,284.51]],"batl":[[2,1.41,42.01]],"ltp":1.36,"tv":3342.22,"id":8257852}]}]}
{"op":"mcm","clk":"1012314690","pt":1580660708266,"mc":[{"id":"1.168223930","rc":[{"trd":[[1.39,3.96]],"batl":[[0,1.39,370.97]],"ltp":1.39,"tv":3346.18,"id":8257852}],"tv":5266.72}]}
{"op":"mcm","clk":"1012315204","pt":1580660711184,"mc":[{"id":"1.168223930","rc":[{"batl":[[0,1.36,52.73],[1,1.39,370.97],[2,1.4,482.48]],"ltp":1.39,"tv":3346.18,"id":8257852}]}]}
{"op":"mcm","clk":"1012315945","pt":1580660715158,"mc":[{"id":"1.168223930","rc":[{"trd":[[3.85,9.78]],"ltp":3.85,"tv":1930.31,"id":8444055}],"tv":5276.5}]}
{"op":"mcm","clk":"1012316460","pt":1580660718208,"mc":[{"id":"1.168223930","rc":[{"batl":[[0,3.9,14.28]],"ltp":3.85,"tv":1930.31,"id":8444055},{"batb":[[0,1.35,125.42],[1,1.34,123.51]],"batl":[[1,1.41,42.01],[2,1.73,901.5]],"ltp":1.39,"tv":3346.18,"id":8257852}]}]}
{"op":"mcm","clk":"1012316628","pt":1580660719176,"mc":[{"id":"1.168223930","rc":[{"batb":[[0,3.4,16.8],[1,2.86,21.56],[2,1.01,15.51]],"ltp":3.85,"tv":1930.31,"id":8444055},{"batb":[[0,1.34,123.51],[1,1.17,284.51],[2,1.01,15.51]],"ltp":1.39,"tv":3346.18,"id":8257852}]}]}
{"op":"mcm","clk":"1012316823","pt":1580660720264,"mc":[{"id":"1.168223930","rc":[{"batb":[[0,2.86,21.56],[1,1.01,15.51],[2,1.01,0]],"ltp":3.85,"tv":1930.31,"id":8444055},{"batb":[[0,1.17,284.51],[1,1.01,15.51],[2,1.01,0]],"batl":[[1,2.88,0.31],[2,1.73,0]],"ltp":1.39,"tv":3346.18,"id":8257852}]}]}
{"op":"mcm","clk":"1012316969","pt":1580660721116,"mc":[{"id":"1.168223930","rc":[{"batb":[[0,1.17,1553.29],[1,1.16,955.21],[2,1.01,15.51]],"batl":[[1,1.53,254.63],[2,1.54,324.17]],"ltp":1.39,"tv":3346.18,"id":8257852}]}]}
{"op":"mcm","clk":"1012317157","pt":1580660722194,"mc":[{"id":"1.168223930","rc":[{"trd":[[3.75,19.13]],"batl":[[0,3.55,5.23]],"ltp":3.75,"tv":1949.44,"id":8444055},{"trd":[[1.36,610.36]],"batl":[[0,1.53,254.63],[1,1.54,324.17],[2,2.88,0.31]],"ltp":1.36,"tv":3398.91,"id":8257852}],"tv":5348.36}]}
{"op":"mcm","clk":"1012317554","pt":1580660724264,"mc":[{"id":"1.168223930","rc":[{"batb":[[0,1.17,284.51],[1,1.01,15.51],[2,1.01,0]],"ltp":1.36,"tv":3398.91,"id":8257852}]}]}
{"op":"mcm","clk":"1012318073","pt":1580660727143,"mc":[{"id":"1.168223930","rc":[{"batb":[[1,2.84,22.69],[2,2.22,42.33]],"ltp":3.75,"tv":1949.44,"id":8444055},{"batb":[[0,1.49,295.95],[1,1.48,468.29],[2,1.44,1210.64]],"ltp":1.36,"tv":3398.91,"id":8257852}]}]}
{"op":"mcm","clk":"1012318278","pt":1580660728176,"mc":[{"id":"1.168223930","rc":[{"batl":[[0,3.15,19.32],[1,3.55,5.23]],"ltp":3.75,"tv":1949.44,"id":8444055},{"batb":[[2,1.46,90.74]],"batl":[[2,1.55,42.01]],"ltp":1.36,"tv":3398.91,"id":8257852}]}]}
{"op":"mcm","clk":"1012320496","pt":1580660740093,"mc":[{"id":"1.168223930","rc":[{"batb":[[0,2.22,42.33],[1,1.01,15.51],[2,2.22,0]],"batl":[[0,3.55,5.23],[1,3.55,0]],"ltp":3.75,"tv":1949.44,"id":8444055},{"batb":[[0,1.18,276.96],[1,1.01,15.51],[2,1.46,0]],"batl":[[0,1.95,728.72],[1,2.88,0.31],[2,1.55,0]],"ltp":1.36,"tv":3398.91,"id":8257852}]}]}
{"op":"mcm","clk":"1012320692","pt":1580660741222,"mc":[{"id":"1.168223930","rc":[{"batl":[[0,2.88,0.31],[1,2.88,0]],"ltp":1.36,"tv":3398.91,"id":8257852}]}]}
{"op":"mcm","clk":"1012320972","pt":1580660742581,"mc":[{"id":"1.168223930","rc":[{"batb":[[1,1.17,1652.27],[2,1.16,568.42]],"batl":[[0,1.82,291.85],[1,1.84,348.08],[2,2.88,0.31]],"ltp":1.36,"tv":3398.91,"id":8257852}]}]}
{"op":"mcm","clk":"1012321285","pt":1580660744200,"mc":[{"id":"1.168223930","rc":[{"batl":[[0,2.88,0.31],[1,1.84,0],[2,2.88,0]],"ltp":1.36,"tv":3398.91,"id":8257852}]}]}
{"op":"mcm","clk":"1012321805","pt":1580660747097,"mc":[{"id":"1.168223930","rc":[{"trd":[[3.55,5.23]],"ltp":3.55,"tv":1954.68,"id":8444055},{"trd":[[1.39,17.33]],"batl":[[0,1.2,1098.76],[1,1.21,1051.2],[2,1.31,519.32]],"ltp":1.39,"tv":3412.28,"id":8257852}],"tv":5366.96}]}
{"op":"mcm","clk":"1012321988","pt":1580660748221,"mc":[{"id":"1.168223930","rc":[{"batb":[[0,5.6,21.17],[1,4.2,41.94],[2,1.01,15.51]],"ltp":3.55,"tv":1954.68,"id":8444055},{"batl":[[2,2.88,0.31]],"ltp":1.39,"tv":3412.28,"id":8257852}]}]}
{"op":"mcm","clk":"1012322147","pt":1580660749243,"mc":[{"id":"1.168223930","rc":[{"batl":[[0,7.4,5.88],[1,9.4,2.6]],"ltp":3.55,"tv":1954.68,"id":8444055},{"batl":[[2,1.51,1190.88]],"ltp":1.39,"tv":3412.28,"id":8257852}]}]}
{"op":"mcm","clk":"1012322316","pt":1580660750269,"mc":[{"id":"1.168223930","rc":[{"batb":[[0,6.2,7.56],[1,5.6,21.17],[2,4.2,41.94]],"ltp":3.55,"tv":1954.68,"id":8444055},{"batl":[[0,1.19,42.01],[1,1.2,1098.76],[2,1.21,1051.2]],"ltp":1.39,"tv":3412.28,"id":8257852}]}]}
{"op":"mcm","clk":"1012322669","pt":1580660752226,"mc":[{"id":"1.168223930","rc":[{"trd":[[1.19,30.95]],"batl":[[0,1.19,26.53]],"ltp":1.19,"tv":3443.23,"id":8257852}],"tv":5397.91}]}
{"op":"mcm","clk":"1012323036","pt":1580660754217,"mc":[{"id":"1.168223930","rc":[{"batb":[[0,5.6,21.17],[1,4.2,41.94],[2,1.01,15.51]],"ltp":3.55,"tv":1954.68,"id":8444055},{"trd":[[1.19,84.02],[1.2,46.94]],"batl":[[0,1.2,1075.29],[1,1.21,1051.2],[2,1.51,1190.88]],"ltp":1.2,"tv":3543.23,"id":8257852}],"tv":5497.92}]}
{"op":"mcm","clk":"1012323619","pt":1580660757237,"mc":[{"id":"1.168223930","rc":[{"batb":[[0,6,8.4],[1,5.6,21.17],[2,4.2,41.94]],"ltp":3.55,"tv":1954.68,"id":8444055},{"batb":[[0,1.19,50],[1,1.18,276.96],[2,1.17,1652.27]],"batl":[[0,1.2,1117.3]],"ltp":1.2,"tv":3543.23,"id":8257852}]}]}
{"op":"mcm","clk":"1012324177","pt":1580660760220,"mc":[{"id":"1.168223930","rc":[{"trd":[[1.19,117.62]],"batb":[[0,1.19,33.2]],"ltp":1.19,"tv":3576.84,"id":8257852}],"tv":5531.52}]}
{"op":"mcm","clk":"1012325356","pt":1580660766268,"mc":[{"id":"1.168223930","rc":[{"trd":[[1.18,1.15],[1.19,184.02]],"batb":[[0,1.18,276.39],[1,1.17,1713.79],[2,1.16,506.36]],"ltp":1.18,"tv":3644.39,"id":8257852}],"tv":5599.07}]}
{"op":"mcm","clk":"1012326255","pt":1580660771256,"mc":[{"id":"1.168223930","rc":[{"batl":[[0,1.19,151.45],[1,1.2,1117.3],[2,1.21,1051.2]],"ltp":1.18,"tv":3644.39,"id":8257852}]}]}
{"op":"mcm","clk":"1012327278","pt":1580660777230,"mc":[{"id":"1.168223930","rc":[{"trd":[[1.18,1.57]],"batb":[[0,1.18,276.17]],"batl":[[0,1.2,1117.3],[1,1.21,1051.2],[2,1.51,1190.88]],"ltp":1.18,"tv":3644.81,"id":8257852}],"tv":5599.49}]}
{"op":"mcm","clk":"1012327439","pt":1580660778155,"mc":[{"id":"1.168223930","rc":[{"batb":[[0,1.17,1991.14],[1,1.16,506.36],[2,1.13,366.11]],"ltp":1.18,"tv":3644.81,"id":8257852}]}]}
{"op":"mcm","clk":"1012327958","pt":1580660781136,"mc":[{"id":"1.168223930","rc":[{"batl":[[0,1.18,15.91],[1,1.2,1117.3],[2,1.21,1051.2]],"ltp":1.18,"tv":3644.81,"id":8257852}]}]}
{"op":"mcm","clk":"1012328262","pt":1580660783000,"mc":[{"id":"1.168223930","rc":[{"batb":[[2,4.2,41.78]],"ltp":3.55,"tv":1954.68,"id":8444055},{"batl":[[0,1.18,37.76]],"ltp":1.18,"tv":3644.81,"id":8257852}]}]}
{"op":"mcm","clk":"1012329023","pt":1580660787056,"mc":[{"id":"1.168223930","rc":[{"batl":[[0,1.18,15.91]],"ltp":1.18,"tv":3644.81,"id":8257852}]}]}
{"op":"mcm","clk":"1012329600","pt":1580660790185,"mc":[{"id":"1.168223930","rc":[{"trd":[[1.17,43.7]],"batb":[[0,1.17,1969.29]],"batl":[[0,1.2,1117.3],[1,1.21,1051.2],[2,1.51,1190.88]],"ltp":1.17,"tv":3688.51,"id":8257852}],"tv":5643.19}]}
{"op":"mcm","clk":"1012330095","pt":1580660793079,"mc":[{"id":"1.168223930","rc":[{"trd":[[1.17,75.53]],"batb":[[0,1.17,1953.37]],"ltp":1.17,"tv":3720.34,"id":8257852}],"tv":5675.02}]}
{"op":"mcm","clk":"1012332507","pt":1580660807120,"mc":[{"id":"1.168223930","rc":[{"trd":[[1.17,391.44]],"batb":[[0,1.17,1795.41]],"ltp":1.17,"tv":4036.26,"id":8257852}],"tv":5990.94}]}
{"op":"mcm","clk":"1012333057","pt":1580660810193,"mc":[{"id":"1.168223930","rc":[{"batb":[[0,1.17,1930.87],[1,1.16,567.15]],"ltp":1.17,"tv":4036.26,"id":8257852}]}]}
{"op":"mcm","clk":"1012333934","pt":1580660815205,"mc":[{"id":"1.168223930","rc":[{"trd":[[1.17,504.03]],"batb":[[0,1.17,1874.58]],"ltp":1.17,"tv":4148.84,"id":8257852}],"tv":6103.52}]}
{"op":"mcm","clk":"1012335176","pt":1580660821793,"mc":[{"id":"1.168223930","rc":[{"trd":[[1.17,504.81]],"batb":[[0,1.17,1874.19]],"ltp":1.17,"tv":4149.62,"id":8257852}],"tv":6104.3}]}
{"op":"mcm","clk":"1012336746","pt":1580660831216,"mc":[{"id":"1.168223930","rc":[{"batb":[[1,4.2,41.78],[2,1.01,15.51]],"ltp":3.55,"tv":1954.68,"id":8444055},{"batb":[[0,1.13,366.11],[1,1.01,15.51],[2,1.13,0]],"batl":[[0,1.2,42.01],[1,1.51,1190.88],[2,2.88,0.31]],"ltp":1.17,"tv":4149.62,"id":8257852}]}]}
{"op":"mcm","clk":"1012336875","pt":1580660831924,"mc":[{"id":"1.168223930","rc":[{"batb":[[0,4.2,41.78],[1,1.01,15.51],[2,1.01,0]],"batl":[[0,9.4,2.6],[1,9.4,0]],"ltp":3.55,"tv":1954.68,"id":8444055},{"batl":[[0,1.51,1190.88],[1,2.88,0.31],[2,2.88,0]],"ltp":1.17,"tv":4149.62,"id":8257852}]}]}
{"op":"mcm","clk":"1012337289","pt":1580660834127,"mc":[{"id":"1.168223930","rc":[{"batb":[[0,1.14,935.13],[1,1.13,1716.96],[2,1.01,15.51]],"batl":[[0,1.28,451],[1,1.29,725.18],[2,1.51,1190.88]],"ltp":1.17,"tv":4149.62,"id":8257852}]}]}
{"op":"mcm","clk":"1012337450","pt":1580660835041,"mc":[{"id":"1.168223930","rc":[{"batb":[[0,1.13,366.11],[1,1.01,15.51],[2,1.01,0]],"batl":[[0,1.51,1190.88],[1,2.88,0.31],[2,1.51,0]],"ltp":1.17,"tv":4149.62,"id":8257852}]}]}
{"op":"mcm","clk":"1012337990","pt":1580660838238,"mc":[{"id":"1.168223930","rc":[{"batb":[[0,1.19,824.5],[1,1.18,1346.78],[2,1.13,366.11]],"batl":[[0,1.21,426.59],[1,1.22,1014.75],[2,1.51,1190.88]],"ltp":1.17,"tv":4149.62,"id":8257852}]}]}
{"op":"mcm","clk":"1012338292","pt":1580660840145,"mc":[{"id":"1.168223930","rc":[{"batb":[[0,1.13,366.11],[1,1.01,15.51],[2,1.13,0]],"batl":[[0,1.51,1190.88],[1,2.88,0.31],[2,1.51,0]],"ltp":1.17,"tv":4149.62,"id":8257852}]}]}
{"op":"mcm","clk":"1012338652","pt":1580660842212,"mc":[{"id":"1.168223930","rc":[{"batb":[[0,1.14,895.51],[1,1.13,1756.93],[2,1.01,15.51]],"batl":[[0,1.28,485.55],[1,1.29,725.28],[2,1.51,1190.88]],"ltp":1.17,"tv":4149.62,"id":8257852}]}]}
{"op":"mcm","clk":"1012340225","pt":1580660851243,"mc":[{"id":"1.168223930","rc":[{"batl":[[0,1.51,1190.88],[1,2.88,0.31],[2,1.51,0]],"ltp":1.17,"tv":4149.62,"id":8257852}]}]}
{"op":"mcm","clk":"1012340740","pt":1580660854055,"mc":[{"id":"1.168223930","rc":[{"batl":[[0,1.16,1201.61],[1,1.17,1024.49],[2,1.18,532.68]],"ltp":1.17,"tv":4149.62,"id":8257852}]}]}
{"op":"mcm","clk":"1012340963","pt":1580660855241,"mc":[{"id":"1.168223930","rc":[{"batb":[[0,7,6.72],[1,6.8,26.99],[2,5.2,25.26]],"batl":[[0,9,5.04]],"ltp":3.55,"tv":1954.68,"id":8444055},{"batb":[[2,1.11,469.18]],"ltp":1.17,"tv":4149.62,"id":8257852}]}]}
{"op":"mcm","clk":"1012341072","pt":1580660855883,"mc":[{"id":"1.168223930","rc":[{"batb":[[0,6.8,26.99],[1,5.2,25.26],[2,1.01,15.51]],"batl":[[1,10.5,6.04]],"ltp":3.55,"tv":1954.68,"id":8444055}]}]}
{"op":"mcm","clk":"1012341266","pt":1580660856972,"mc":[{"id":"1.168223930","rc":[{"batb":[[0,7.2,6.72],[1,6.8,26.99],[2,5.2,25.26]],"ltp":3.55,"tv":1954.68,"id":8444055},{"batl":[[0,1.16,1243.62],[2,1.51,1190.88]],"ltp":1.17,"tv":4149.62,"id":8257852}]}]}
{"op":"mcm","clk":"1012341640","pt":1580660859268,"mc":[{"id":"1.168223930","rc":[{"trd":[[1.14,0.04]],"batb":[[0,1.14,895.49]],"ltp":1.14,"tv":4149.66,"id":8257852}],"tv":6104.34}]}
{"op":"mcm","clk":"1012343530","pt":1580660870205,"mc":[{"id":"1.168223930","rc":[{"batb":[[1,5.2,25.26],[2,1.01,15.51]],"ltp":3.55,"tv":1954.68,"id":8444055},{"batb":[[0,1.11,469.18],[1,1.01,15.51],[2,1.11,0]],"batl":[[0,1.16,42.01],[1,1.51,1190.88],[2,2.88,0.31]],"ltp":1.14,"tv":4149.66,"id":8257852}]}]}
{"op":"mcm","clk":"1012343914","pt":1580660872266,"mc":[{"id":"1.168223930","rc":[{"batb":[[0,5.2,25.26],[1,1.01,15.51],[2,1.01,0]],"batl":[[0,10.5,6.04],[1,10.5,0]],"ltp":3.55,"tv":1954.68,"id":8444055},{"batl":[[0,1.51,1190.88],[1,2.88,0.31],[2,2.88,0]],"ltp":1.14,"tv":4149.66,"id":8257852}]}]}
{"op":"mcm","clk":"1012344594","pt":1580660876183,"mc":[{"id":"1.168223930","rc":[{"batb":[[0,1.15,874.18],[1,1.14,1392.28],[2,1.11,469.18]],"batl":[[0,1.17,1010.71],[1,1.18,1194.9],[2,1.51,1190.88]],"ltp":1.14,"tv":4149.66,"id":8257852}]}]}
{"op":"mcm","clk":"1012345078","pt":1580660879005,"mc":[{"id":"1.168223930","rc":[{"batb":[[0,1.11,469.18],[1,1.01,15.51],[2,1.11,0]],"batl":[[0,1.51,1190.88],[1,2.88,0.31],[2,1.51,0]],"ltp":1.14,"tv":4149.66,"id":8257852}]}]}
{"op":"mcm","clk":"1012345648","pt":1580660882198,"mc":[{"id":"1.168223930","rc":[{"batb":[[0,1.11,2804.78]],"batl":[[0,1.22,1198.88],[1,1.23,918.6],[2,1.51,1190.88]],"ltp":1.14,"tv":4149.66,"id":8257852}]}]}
{"op":"mcm","clk":"1012346155","pt":1580660885028,"mc":[{"id":"1.168223930","rc":[{"batb":[[0,1.11,469.18]],"ltp":1.14,"tv":4149.66,"id":8257852}]}]}
{"op":"mcm","clk":"1012346709","pt":1580660888229,"mc":[{"id":"1.168223930","rc":[{"batb":[[0,1.19,1097.54],[1,1.18,1090.21],[2,1.17,3133.43]],"ltp":1.14,"tv":4149.66,"id":8257852}]}]}
{"op":"mcm","clk":"1012346925","pt":1580660889247,"mc":[{"id":"1.168223930","rc":[{"batb":[[0,5.7,8.4],[1,5.2,25.26],[2,3.7,28.17]],"ltp":3.55,"tv":1954.68,"id":8444055},{"batb":[[0,1.2,243.99],[1,1.19,1097.54],[2,1.18,1090.21]],"ltp":1.14,"tv":4149.66,"id":8257852}]}]}
{"op":"mcm","clk":"1012347289","pt":1580660891238,"mc":[{"id":"1.168223930","rc":[{"batl":[[0,6.8,6.72],[1,9.4,4.13]],"ltp":3.55,"tv":1954.68,"id":8444055}]}]}
{"op":"mcm","clk":"1012349222","pt":1580660902200,"mc":[{"id":"1.168223930","rc":[{"batb":[[0,3.7,28.17],[1,1.01,15.51],[2,3.7,0]],"batl":[[0,9.4,4.13],[1,9.4,0]],"ltp":3.55,"tv":1954.68,"id":8444055},{"batb":[[0,1.14,342.9],[1,1.01,15.51],[2,1.18,0]],"batl":[[0,1.51,1190.88],[1,2.88,0.31],[2,1.51,0]],"ltp":1.14,"tv":4149.66,"id":8257852}]}]}
{"op":"mcm","clk":"1012349953","pt":1580660905189,"mc":[{"id":"1.168223930","rc":[{"batb":[[0,1.14,2151.23],[1,1.13,469.93],[2,1.01,15.51]],"batl":[[0,1.33,444.14],[1,1.34,594.95],[2,1.51,1190.88]],"ltp":1.14,"tv":4149.66,"id":8257852}]}]}
{"op":"mcm","clk":"1012350148","pt":1580660906053,"mc":[{"id":"1.168223930","rc":[{"batb":[[0,1.14,342.9],[1,1.01,15.51],[2,1.01,0]],"batl":[[0,1.51,1190.88],[1,2.88,0.31],[2,1.51,0]],"ltp":1.14,"tv":4149.66,"id":8257852}]}]}
{"op":"mcm","clk":"1012350756","pt":1580660908932,"mc":[{"id":"1.168223930","rc":[{"batb":[[0,1.21,990.45],[1,1.2,1161.72],[2,1.14,342.9]],"batl":[[0,1.24,973.76],[1,1.25,858.45],[2,1.51,1190.88]],"ltp":1.14,"tv":4149.66,"id":8257852}]}]}
{"op":"mcm","clk":"1012351152","pt":1580660911109,"mc":[{"id":"1.168223930","rc":[{"batb":[[0,1.14,342.9],[1,1.01,15.51],[2,1.14,0]],"batl":[[0,1.51,1190.88],[1,2.88,0.31],[2,1.51,0]],"ltp":1.14,"tv":4149.66,"id":8257852}]}]}
{"op":"mcm","clk":"1012351684","pt":1580660913944,"mc":[{"id":"1.168223930","rc":[{"batl":[[0,1.33,444.14],[1,1.34,594.95],[2,1.51,1190.88]],"ltp":1.14,"tv":4149.66,"id":8257852}]}]}
{"op":"mcm","clk":"1012352069","pt":1580660916248,"mc":[{"id":"1.168223930","rc":[{"batb":[[0,1.25,2130.73],[1,1.14,342.9],[2,1.01,15.51]],"ltp":1.14,"tv":4149.66,"id":8257852}]}]}
{"op":"mcm","clk":"1012352266","pt":1580660917219,"mc":[{"id":"1.168223930","rc":[{"batb":[[0,4.1,13.44],[1,3.7,28.17],[2,2.62,27.22]],"ltp":3.55,"tv":1954.68,"id":8444055},{"trd":[[1.32,84.02]],"batb":[[0,1.32,97.88],[1,1.3,568.67],[2,1.29,749.06]],"ltp":1.32,"tv":4233.68,"id":8257852}],"tv":6188.36}]}
{"op":"mcm","clk":"1012352284","pt":1580660917327,"mc":[{"id":"1.168223930","rc":[{"batb":[[0,3.7,28.17],[1,2.62,27.22],[2,1.01,15.51]],"ltp":3.55,"tv":1954.68,"id":8444055}]}]}
{"op":"mcm","clk":"1012352638","pt":1580660919245,"mc":[{"id":"1.168223930","rc":[{"batl":[[0,4.8,10.92]],"ltp":3.55,"tv":1954.68,"id":8444055}]}]}
{"op":"mcm","clk":"1012352801","pt":1580660920214,"mc":[{"id":"1.168223930","rc":[{"batl":[[0,4.7,10.92]],"ltp":3.55,"tv":1954.68,"id":8444055},{"trd":[[1.32,168.04]],"batb":[[0,1.32,55.87]],"batl":[[0,1.33,486.15]],"ltp":1.32,"tv":4317.7,"id":8257852}],"tv":6272.38}]}
{"op":"mcm","clk":"1012352938","pt":1580660921032,"mc":[{"id":"1.168223930","rc":[{"batb":[[0,4,13.44],[1,3.7,28.17],[2,2.62,27.22]],"ltp":3.55,"tv":1954.68,"id":8444055}]}]}
{"op":"mcm","clk":"1012353322","pt":1580660923218,"mc":[{"id":"1.168223930","rc":[{"batl":[[0,4.6,10.92]],"ltp":3.55,"tv":1954.68,"id":8444055}]}]}
{"op":"mcm","clk":"1012354774","pt":1580660931244,"mc":[{"id":"1.168223930","rc":[{"batb":[[1,2.62,27.22],[2,1.01,15.51]],"ltp":3.55,"tv":1954.68,"id":8444055},{"batb":[[0,1.27,155.44],[1,1.22,214.96],[2,1.01,15.51]],"batl":[[0,1.33,42.01],[1,1.51,1190.88],[2,2.88,0.31]],"ltp":1.32,"tv":4317.7,"id":8257852}]}]}
{"op":"mcm","clk":"1012354956","pt":1580660932258,"mc":[{"id":"1.168223930","rc":[{"batb":[[0,2.62,27.22],[1,1.01,15.51],[2,1.01,0]],"ltp":3.55,"tv":1954.68,"id":8444055},{"batb":[[0,1.22,214.96],[1,1.01,15.51],[2,1.01,0]],"batl":[[0,1.51,1190.88],[1,2.88,0.31],[2,2.88,0]],"ltp":1.32,"tv":4317.7,"id":8257852}]}]}
{"op":"mcm","clk":"1012355144","pt":1580660933125,"mc":[{"id":"1.168223930","rc":[{"batl":[[0,4,16.8]],"ltp":3.55,"tv":1954.68,"id":8444055}]}]}
{"op":"mcm","clk":"1012355354","pt":1580660934244,"mc":[{"id":"1.168223930","rc":[{"batb":[[0,2.72,25.26]],"ltp":3.55,"tv":1954.68,"id":8444055},{"batb":[[0,1.21,1115.46],[1,1.2,1191.5],[2,1.01,15.51]],"batl":[[1,1.57,534.14],[2,1.58,293.27]],"ltp":1.32,"tv":4317.7,"id":8257852}]}]}
{"op":"mcm","clk":"1012355702","pt":1580660936158,"mc":[{"id":"1.168223930","rc":[{"batl":[[1,2.88,0.31],[2,1.58,0]],"ltp":1.32,"tv":4317.7,"id":8257852}]}]}
{"op":"mcm","clk":"1012356282","pt":1580660939245,"mc":[{"id":"1.168223930","rc":[{"trd":[[4,16.8]],"ltp":4.0,"tv":1971.48,"id":8444055},{"trd":[[1.33,50.54]],"batl":[[0,1.24,1065.95],[1,1.25,856.36],[2,1.26,482.15]],"ltp":1.33,"tv":4368.24,"id":8257852}],"tv":6339.72}]}
{"op":"mcm","clk":"1012356453","pt":1580660940264,"mc":[{"id":"1.168223930","rc":[{"batb":[[0,5,28.17],[1,3.3,38.71],[2,1.01,15.51]],"ltp":4.0,"tv":1971.48,"id":8444055},{"batb":[[2,1.13,368.23]],"ltp":1.33,"tv":4368.24,"id":8257852}]}]}
{"op":"mcm","clk":"1012356643","pt":1580660941240,"mc":[{"id":"1.168223930","rc":[{"batl":[[2,1.51,1190.88]],"ltp":1.33,"tv":4368.24,"id":8257852}]}]}
{"op":"mcm","clk":"1012356824","pt":1580660942252,"mc":[{"id":"1.168223930","rc":[{"batl":[[0,8.2,2.36]],"ltp":4.0,"tv":1971.48,"id":8444055}]}]}
{"op":"mcm","clk":"1012356989","pt":1580660943053,"mc":[{"id":"1.168223930","rc":[{"batb":[[0,5.1,10.08],[1,5,28.17],[2,3.3,38.71]],"batl":[[0,6.2,7.56],[1,8.2,2.36]],"ltp":4.0,"tv":1971.48,"id":8444055},{"batb":[[2,1.19,168.04]],"batl":[[0,1.24,1107.96]],"ltp":1.33,"tv":4368.24,"id":8257852}]}]}
{"op":"mcm","clk":"1012357246","pt":1580660944238,"mc":[{"id":"1.168223930","rc":[{"trd":[[1.24,108.68]],"batl":[[0,1.24,1053.62]],"ltp":1.24,"tv":4476.91,"id":8257852}],"tv":6448.4}]}
{"op":"mcm","clk":"1012358673","pt":1580660952192,"mc":[{"id":"1.168223930","rc":[{"batb":[[0,3.3,38.71],[1,1.01,15.51],[2,3.3,0]],"batl":[[0,8.2,2.36],[1,8.2,0]],"ltp":4.0,"tv":1971.48,"id":8444055},{"batb":[[0,1.13,368.23],[1,1.01,15.51],[2,1.19,0]],"batl":[[0,1.51,1190.88],[1,2.88,0.31],[2,1.51,0]],"ltp":1.24,"tv":4476.91,"id":8257852}]}]}
{"op":"mcm","clk":"1012359239","pt":1580660955081,"mc":[{"id":"1.168223930","rc":[{"batb":[[0,1.14,1231.84],[1,1.13,1419.75],[2,1.01,15.51]],"ltp":1.24,"tv":4476.91,"id":8257852}]}]}
{"op":"mcm","clk":"1012359631","pt":1580660957176,"mc":[{"id":"1.168223930","rc":[{"batl":[[0,2.88,0.31],[1,2.88,0]],"ltp":1.24,"tv":4476.91,"id":8257852}]}]}
