{"op":"mcm","clk":"1004323371","pt":1580581675727,"mc":[{"id":"1.168223927","marketDefinition":{"bspMarket":false,"turnInPlayEnabled":true,"persistenceEnabled":true,"marketBaseRate":5.0,"eventId":"29681623","eventTypeId":"2","numberOfWinners":1,"bettingType":"ODDS","marketType":"MATCH_ODDS","marketTime":"2020-02-02T15:00:00.000Z","suspendTime":"2020-02-02T15:00:00.000Z","bspReconciled":false,"complete":true,"inPlay":false,"crossMatching":false,"runnersVoidable":false,"numberOfActiveRunners":2,"betDelay":0,"status":"OPEN","runners":[{"status":"ACTIVE","sortPriority":1,"id":8257852,"name":"Maxime Janvier"},{"status":"ACTIVE","sortPriority":2,"id":8444055,"name":"Cem Ilkel"}],"regulators":["MR_INT"],"countryCode":"FR","discountAllowed":false,"timezone":"UTC","openDate":"2020-02-02T15:00:00.000Z","version":3146826524,"name":"Match Odds","eventName":"Janvier v Ilkel"},"rc":[{"batb":[[0,1.01,346.52]],"ltp":0.0,"tv":0.0,"id":8444055},{"batb":[[0,1.05,152.2],[1,1.04,168.86],[2,1.03,237.77]],"ltp":0.0,"tv":0.0,"id":8257852}]}]}
{"op":"mcm","clk":"1004323649","pt":1580581677280,"mc":[{"id":"1.168223927","marketDefinition":{"bspMarket":false,"turnInPlayEnabled":true,"persistenceEnabled":true,"marketBaseRate":5.0,"eventId":"29681623","eventTypeId":"2","numberOfWinners":1,"bettingType":"ODDS","marketType":"MATCH_ODDS","marketTime":"2020-02-02T15:00:00.000Z","suspendTime":"2020-02-02T15:00:00.000Z","bspReconciled":false,"complete":true,"inPlay":false,"crossMatching":false,"runnersVoidable":false,"numberOfActiveRunners":2,"betDelay":0,"status":"OPEN","runners":[{"status":"ACTIVE","sortPriority":1,"id":8257852,"name":"Maxime Janvier"},{"status":"ACTIVE","sortPriority":2,"id":8444055,"name":"Cem Ilkel"}],"regulators":["MR_INT"],"countryCode":"FR","discountAllowed":true,"timezone":"UTC","openDate":"2020-02-02T15:00:00.000Z","version":3146826524,"name":"Match Odds","eventName":"Janvier v Ilkel"}}]}
{"op":"mcm","clk":"1004328524","pt":1580581708108,"mc":[{"id":"1.168223927","rc":[{"batb":[[0,1.01,646.52]],"ltp":0.0,"tv":0.0,"id":8444055}]}]}
{"op":"mcm","clk":"1004329168","pt":1580581712521,"mc":[{"id":"1.168223927","rc":[{"batb":[[0,1.01,346.52]],"ltp":0.0,"tv":0.0,"id":8444055}]}]}
{"op":"mcm","clk":"1004346957","pt":1580581820655,"mc":[{"id":"1.168223927","rc":[{"batb":[[0,1.01,336.52]],"ltp":0.0,"tv":0.0,"id":8444055}]}]}
{"op":"mcm","clk":"1004408742","pt":1580582165257,"mc":[{"id":"1.168223927","rc":[{"batb":[[0,1.13,75.72],[1,1.01,336.52]],"ltp":0.0,"tv":0.0,"id":8444055},{"batb":[[0,1.09,75.72],[1,1.05,152.2],[2,1.04,168.86]],"ltp":0.0,"tv":0.0,"id":8257852}]}]}
{"op":"mcm","clk":"1004413384","pt":1580582190098,"mc":[{"id":"1.168223927","marketDefinition":{"bspMarket":false,"turnInPlayEnabled":true,"persistenceEnabled":true,"marketBaseRate":5.0,"eventId":"29681623","eventTypeId":"2","numberOfWinners":1,"bettingType":"ODDS","marketType":"MATCH_ODDS","marketTime":"2020-02-02T15:00:00.000Z","suspendTime":"2020-02-02T15:00:00.000Z","bspReconciled":false,"complete":true,"inPlay":false,"crossMatching":true,"runnersVoidable":false,"numberOfActiveRunners":2,"betDelay":0,"status":"OPEN","runners":[{"status":"ACTIVE","sortPriority":1,"id":8257852,"name":"Maxime Janvier"},{"status":"ACTIVE","sortPriority":2,"id":8444055,"name":"Cem Ilkel"}],"regulators":["MR_INT"],"countryCode":"FR","discountAllowed":true,"timezone":"UTC","openDate":"2020-02-02T15:00:00.000Z","version":3146844612,"name":"Match Odds","eventName":"Janvier v Ilkel"}}]}
{"op":"mcm","clk":"1004517158","pt":1580582764669,"mc":[{"id":"1.168223927","rc":[{"batb":[[1,1.03,8.4],[2,1.02,25.21]],"ltp":0.0,"tv":0.0,"id":8444055}]}]}
{"op":"mcm","clk":"1004791118","pt":1580584351899,"mc":[{"id":"1.168223927","rc":[{"batl":[[0,990,2.2]],"ltp":0.0,"tv":0.0,"id":8444055},{"batl":[[0,990,2.2]],"ltp":0.0,"tv":0.0,"id":8257852}]}]}
{"op":"mcm","clk":"1005079893","pt":1580585985456,"mc":[{"id":"1.168223927","rc":[{"batl":[[0,48,31.05],[1,990,2.2]],"ltp":0.0,"tv":0.0,"id":8444055},{"batl":[[0,48,31.05],[1,990,2.2]],"ltp":0.0,"tv":0.0,"id":8257852}]}]}
{"op":"mcm","clk":"1006049576","pt":1580592757215,"mc":[{"id":"1.168223927","rc":[{"batb":[[0,1.14,15.12],[1,1.13,75.72],[2,1.03,8.4]],"batl":[[0,13,3.36],[1,48,31.05],[2,990,2.2]],"ltp":0.0,"tv":0.0,"id":8444055},{"batb":[[0,1.1,15.12],[1,1.09,75.72],[2,1.05,152.2]],"ltp":0.0,"tv":0.0,"id":8257852}]}]}
{"op":"mcm","clk":"1006049598","pt":1580592757382,"mc":[{"id":"1.168223927","rc":[{"batl":[[0,11.5,3.36],[1,48,31.05],[2,990,2.2]],"ltp":0.0,"tv":0.0,"id":8257852}]}]}
{"op":"mcm","clk":"1006313161","pt":1580595149220,"mc":[{"id":"1.168223927","rc":[{"batb":[[0,1.49,38.62],[1,1.1,15.12],[2,1.09,75.72]],"ltp":0.0,"tv":0.0,"id":8257852}]}]}
{"op":"mcm","clk":"1006313182","pt":1580595149379,"mc":[{"id":"1.168223927","rc":[{"batb":[[0,1.91,30.29],[1,1.14,15.12],[2,1.13,75.72]],"ltp":0.0,"tv":0.0,"id":8444055}]}]}
{"op":"mcm","clk":"1006319790","pt":1580595206999,"mc":[{"id":"1.168223927","rc":[{"batb":[[1,1.13,75.72],[2,1.03,8.4]],"ltp":0.0,"tv":0.0,"id":8444055}]}]}
{"op":"mcm","clk":"1006319817","pt":1580595207307,"mc":[{"id":"1.168223927","rc":[{"batb":[[1,1.09,75.72],[2,1.05,152.2]],"ltp":0.0,"tv":0.0,"id":8257852}]}]}
{"op":"mcm","clk":"1006325432","pt":1580595256862,"mc":[{"id":"1.168223927","rc":[{"batb":[[0,1.5,10.92],[1,1.49,38.62],[2,1.09,75.72]],"ltp":0.0,"tv":0.0,"id":8257852}]}]}
{"op":"mcm","clk":"1006449975","pt":1580596408163,"mc":[{"id":"1.168223927","rc":[{"batb":[[0,1.92,10.92],[1,1.91,30.29],[2,1.13,75.72]],"ltp":0.0,"tv":0.0,"id":8444055}]}]}
{"op":"mcm","clk":"1006469857","pt":1580596588409,"mc":[{"id":"1.168223927","rc":[{"batb":[[1,1.89,30.29]],"ltp":0.0,"tv":0.0,"id":8444055},{"batb":[[0,1.5,49.54],[1,1.09,75.72],[2,1.05,152.2]],"ltp":0.0,"tv":0.0,"id":8257852}]}]}
{"op":"mcm","clk":"1006572480","pt":1580597792187,"mc":[{"id":"1.168223927","rc":[{"batb":[[1,1.13,75.72],[2,1.03,8.4]],"ltp":0.0,"tv":0.0,"id":8444055},{"batb":[[0,1.5,10.92]],"ltp":0.0,"tv":0.0,"id":8257852}]}]}
{"op":"mcm","clk":"1006572964","pt":1580597797718,"mc":[{"id":"1.168223927","rc":[{"batb":[[0,1.93,40.13],[1,1.92,10.92],[2,1.13,75.72]],"ltp":0.0,"tv":0.0,"id":8444055},{"batb":[[0,1.52,51.49],[1,1.5,10.92],[2,1.09,75.72]],"ltp":0.0,"tv":0.0,"id":8257852}]}]}
{"op":"mcm","clk":"1006574945","pt":1580597829673,"mc":[{"id":"1.168223927","rc":[{"batb":[[1,1.13,75.72],[2,1.03,8.4]],"ltp":0.0,"tv":0.0,"id":8444055},{"batb":[[1,1.09,75.72],[2,1.05,152.2]],"ltp":0.0,"tv":0.0,"id":8257852}]}]}
{"op":"mcm","clk":"1006579805","pt":1580597908341,"mc":[{"id":"1.168223927","rc":[{"batb":[[0,1.94,10.08],[1,1.93,40.13],[2,1.13,75.72]],"ltp":0.0,"tv":0.0,"id":8444055}]}]}
{"op":"mcm","clk":"1006695462","pt":1580599350347,"mc":[{"id":"1.168223927","rc":[{"batb":[[0,2.02,22.51],[1,1.94,10.08],[2,1.93,40.13]],"ltp":0.0,"tv":0.0,"id":8444055},{"batb":[[0,1.57,32.06],[1,1.52,51.49],[2,1.09,75.72]],"ltp":0.0,"tv":0.0,"id":8257852}]}]}
{"op":"mcm","clk":"1006695679","pt":1580599352848,"mc":[{"id":"1.168223927","rc":[{"batb":[[0,1.55,33.99]],"ltp":0.0,"tv":0.0,"id":8257852}]}]}
{"op":"mcm","clk":"1006696094","pt":1580599357649,"mc":[{"id":"1.168223927","rc":[{"batb":[[0,1.94,10.08],[1,1.93,40.13],[2,1.13,75.72]],"ltp":0.0,"tv":0.0,"id":8444055},{"batb":[[0,1.52,51.49],[1,1.09,75.72],[2,1.05,152.2]],"ltp":0.0,"tv":0.0,"id":8257852}]}]}
{"op":"mcm","clk":"1006696257","pt":1580599359118,"mc":[{"id":"1.168223927","rc":[{"batb":[[0,1.52,37.86]],"ltp":0.0,"tv":0.0,"id":8257852}]}]}
{"op":"mcm","clk":"1006696368","pt":1580599360262,"mc":[{"id":"1.168223927","rc":[{"batb":[[0,2.26,20.98],[1,2.24,40.13],[2,1.94,10.08]],"ltp":0.0,"tv":0.0,"id":8444055},{"batb":[[0,1.6,37.86]],"ltp":0.0,"tv":0.0,"id":8257852}]}]}
{"op":"mcm","clk":"1006696461","pt":1580599361271,"mc":[{"id":"1.168223927","rc":[{"batb":[[0,1.09,75.72],[1,1.05,152.2],[2,1.04,168.86]],"ltp":0.0,"tv":0.0,"id":8257852}]}]}
{"op":"mcm","clk":"1006696540","pt":1580599362047,"mc":[{"id":"1.168223927","rc":[{"batb":[[0,2.26,61.11],[1,1.94,10.08],[2,1.13,75.72]],"ltp":0.0,"tv":0.0,"id":8444055},{"batb":[[0,1.37,38.77],[1,1.09,75.72],[2,1.05,152.2]],"ltp":0.0,"tv":0.0,"id":8257852}]}]}
{"op":"mcm","clk":"1006697203","pt":1580599368979,"mc":[{"id":"1.168223927","rc":[{"batb":[[0,1.56,74.97],[1,1.37,38.77],[2,1.09,75.72]],"ltp":0.0,"tv":0.0,"id":8257852}]}]}
{"op":"mcm","clk":"1006697843","pt":1580599375556,"mc":[{"id":"1.168223927","rc":[{"batb":[[1,1.13,75.72],[2,1.03,8.4]],"ltp":0.0,"tv":0.0,"id":8444055}]}]}
{"op":"mcm","clk":"1006701198","pt":1580599410005,"mc":[{"id":"1.168223927","rc":[{"batb":[[0,2.26,72.47]],"ltp":0.0,"tv":0.0,"id":8444055},{"batb":[[0,1.56,109.05],[1,1.09,75.72],[2,1.05,152.2]],"ltp":0.0,"tv":0.0,"id":8257852}]}]}
{"op":"mcm","clk":"1006703719","pt":1580599435441,"mc":[{"id":"1.168223927","rc":[{"batb":[[0,2.28,51.49],[1,2.26,20.98],[2,1.13,75.72]],"ltp":0.0,"tv":0.0,"id":8444055}]}]}
{"op":"mcm","clk":"1006711469","pt":1580599520044,"mc":[{"id":"1.168223927","rc":[{"batb":[[0,2.3,51.49]],"ltp":0.0,"tv":0.0,"id":8444055}]}]}
{"op":"mcm","clk":"1006765117","pt":1580600125792,"mc":[{"id":"1.168223927","rc":[{"batl":[[0,2.62,21.85],[1,13,3.36],[2,48,31.05]],"ltp":0.0,"tv":0.0,"id":8444055},{"batb":[[0,1.56,74.97]],"ltp":0.0,"tv":0.0,"id":8257852}]}]}
{"op":"mcm","clk":"1006768202","pt":1580600160103,"mc":[{"id":"1.168223927","rc":[{"batb":[[0,2.36,51.49],[1,1.13,75.72],[2,1.03,8.4]],"ltp":0.0,"tv":0.0,"id":8444055}]}]}
{"op":"mcm","clk":"1006768220","pt":1580600160307,"mc":[{"id":"1.168223927","rc":[{"batb":[[0,2.36,71.42]],"ltp":0.0,"tv":0.0,"id":8444055}]}]}
{"op":"mcm","clk":"1006768849","pt":1580600167612,"mc":[{"id":"1.168223927","rc":[{"batl":[[1,48,31.05],[2,990,2.2]],"ltp":0.0,"tv":0.0,"id":8444055}]}]}
{"op":"mcm","clk":"1006880080","pt":1580601569776,"mc":[{"id":"1.168223927","rc":[{"batb":[[1,1.13,75.82],[2,1.03,8.9]],"ltp":0.0,"tv":0.0,"id":8444055},{"batb":[[1,1.09,75.82]],"ltp":0.0,"tv":0.0,"id":8257852}]}]}
{"op":"mcm","clk":"1006883588","pt":1580601623546,"mc":[{"id":"1.168223927","rc":[{"batb":[[2,1.03,9]],"ltp":0.0,"tv":0.0,"id":8444055},{"batb":[[1,1.09,75.92]],"ltp":0.0,"tv":0.0,"id":8257852}]}]}
{"op":"mcm","clk":"1006988416","pt":1580602960110,"mc":[{"id":"1.168223927","rc":[{"batb":[[0,2.36,51.49]],"ltp":0.0,"tv":0.0,"id":8444055}]}]}
{"op":"mcm","clk":"1006988427","pt":1580602960307,"mc":[{"id":"1.168223927","rc":[{"batb":[[0,2.36,71.42]],"ltp":0.0,"tv":0.0,"id":8444055}]}]}
{"op":"mcm","clk":"1006993978","pt":1580603032630,"mc":[{"id":"1.168223927","rc":[{"batb":[[0,2.36,81.42]],"ltp":0.0,"tv":0.0,"id":8444055}]}]}
{"op":"mcm","clk":"1007058345","pt":1580603974651,"mc":[{"id":"1.168223927","rc":[{"batb":[[1,2.14,25.24],[2,1.13,75.82]],"ltp":0.0,"tv":0.0,"id":8444055},{"batb":[[1,1.49,58.72],[2,1.09,75.92]],"ltp":0.0,"tv":0.0,"id":8257852}]}]}
{"op":"mcm","clk":"1007117916","pt":1580605211889,"mc":[{"id":"1.168223927","rc":[{"batb":[[0,1.61,47.17],[1,1.56,74.97],[2,1.49,58.72]],"ltp":0.0,"tv":0.0,"id":8257852}]}]}
{"op":"mcm","clk":"1007118131","pt":1580605217315,"mc":[{"id":"1.168223927","rc":[{"batb":[[0,1.61,58.03]],"ltp":0.0,"tv":0.0,"id":8257852}]}]}
{"op":"mcm","clk":"1007181677","pt":1580606560887,"mc":[{"id":"1.168223927","rc":[{"batb":[[0,2.36,81.67]],"ltp":0.0,"tv":0.0,"id":8444055}]}]}
{"op":"mcm","clk":"1007192311","pt":1580606802173,"mc":[{"id":"1.168223927","rc":[{"batb":[[0,2.36,51.49]],"ltp":0.0,"tv":0.0,"id":8444055}]}]}
{"op":"mcm","clk":"1007192319","pt":1580606802378,"mc":[{"id":"1.168223927","rc":[{"batb":[[0,2.36,91.42]],"ltp":0.0,"tv":0.0,"id":8444055}]}]}
{"op":"mcm","clk":"1007192409","pt":1580606804751,"mc":[{"id":"1.168223927","rc":[{"batb":[[1,1.13,75.82],[2,1.03,9]],"ltp":0.0,"tv":0.0,"id":8444055},{"batb":[[2,1.09,75.92]],"ltp":0.0,"tv":0.0,"id":8257852}]}]}
{"op":"mcm","clk":"1007192432","pt":1580606805479,"mc":[{"id":"1.168223927","rc":[{"batb":[[1,2.14,33.21],[2,1.13,75.82]],"ltp":0.0,"tv":0.0,"id":8444055},{"batb":[[2,1.49,77.27]],"ltp":0.0,"tv":0.0,"id":8257852}]}]}
{"op":"mcm","clk":"1007192536","pt":1580606808271,"mc":[{"id":"1.168223927","rc":[{"batb":[[0,1.61,62.07]],"ltp":0.0,"tv":0.0,"id":8257852}]}]}
{"op":"mcm","clk":"1007312363","pt":1580610162212,"mc":[{"id":"1.168223927","rc":[{"batb":[[0,2.36,91.67]],"ltp":0.0,"tv":0.0,"id":8444055}]}]}
{"op":"mcm","clk":"1007314563","pt":1580610233096,"mc":[{"id":"1.168223927","rc":[{"batb":[[0,2.36,101.42]],"ltp":0.0,"tv":0.0,"id":8444055}]}]}
{"op":"mcm","clk":"1007314641","pt":1580610235208,"mc":[{"id":"1.168223927","rc":[{"batb":[[1,2.14,41.84]],"ltp":0.0,"tv":0.0,"id":8444055},{"batb":[[2,1.49,97.36]],"ltp":0.0,"tv":0.0,"id":8257852}]}]}
{"op":"mcm","clk":"1007314730","pt":1580610238035,"mc":[{"id":"1.168223927","rc":[{"batb":[[0,1.61,78.2]],"ltp":0.0,"tv":0.0,"id":8257852}]}]}
{"op":"mcm","clk":"1007347305","pt":1580611269314,"mc":[{"id":"1.168223927","rc":[{"batl":[[0,2.5,25.33],[1,2.62,21.85],[2,48,31.05]],"ltp":0.0,"tv":0.0,"id":8444055}]}]}
{"op":"mcm","clk":"1007347998","pt":1580611290154,"mc":[{"id":"1.168223927","rc":[{"batl":[[0,2.48,11.34]],"ltp":0.0,"tv":0.0,"id":8444055}]}]}
{"op":"mcm","clk":"1007348653","pt":1580611310105,"mc":[{"id":"1.168223927","rc":[{"batl":[[0,2.62,21.85],[1,48,31.05],[2,990,2.2]],"ltp":0.0,"tv":0.0,"id":8444055}]}]}
{"op":"mcm","clk":"1007349835","pt":1580611343825,"mc":[{"id":"1.168223927","rc":[{"batb":[[0,2.36,51.49]],"batl":[[0,2.62,69.6]],"ltp":0.0,"tv":0.0,"id":8444055}]}]}
{"op":"mcm","clk":"1007349949","pt":1580611347740,"mc":[{"id":"1.168223927","rc":[{"batb":[[0,1.13,75.82],[1,1.03,9],[2,1.02,25.21]],"ltp":0.0,"tv":0.0,"id":8444055},{"batb":[[2,1.09,75.92]],"ltp":0.0,"tv":0.0,"id":8257852}]}]}
{"op":"mcm","clk":"1007349997","pt":1580611349126,"mc":[{"id":"1.168223927","rc":[{"batb":[[0,2.04,45.87],[1,1.83,18.03],[2,1.13,75.82]],"ltp":0.0,"tv":0.0,"id":8444055},{"batb":[[0,1.62,74.97],[1,1.61,78.2],[2,1.53,90.01]],"ltp":0.0,"tv":0.0,"id":8257852}]}]}
{"op":"mcm","clk":"1007350041","pt":1580611350113,"mc":[{"id":"1.168223927","rc":[{"batb":[[0,2.24,51.49],[1,2.04,45.87]],"ltp":0.0,"tv":0.0,"id":8444055},{"batb":[[0,1.61,153.17],[1,1.53,90.01],[2,1.09,75.92]],"ltp":0.0,"tv":0.0,"id":8257852}]}]}
{"op":"mcm","clk":"1007350055","pt":1580611350627,"mc":[{"id":"1.168223927","rc":[{"batb":[[0,2.24,101.51]],"ltp":0.0,"tv":0.0,"id":8444055}]}]}
{"op":"mcm","clk":"1007376417","pt":1580612101736,"mc":[{"id":"1.168223927","rc":[{"batb":[[0,2.24,141.51]],"batl":[[0,2.62,107.85]],"ltp":0.0,"tv":0.0,"id":8444055}]}]}
{"op":"mcm","clk":"1007376484","pt":1580612104060,"mc":[{"id":"1.168223927","rc":[{"batb":[[1,1.13,75.82],[2,1.03,9]],"ltp":0.0,"tv":0.0,"id":8444055},{"batb":[[1,1.09,75.92],[2,1.05,152.2]],"ltp":0.0,"tv":0.0,"id":8257852}]}]}
{"op":"mcm","clk":"1007376496","pt":1580612104672,"mc":[{"id":"1.168223927","rc":[{"batb":[[1,2.08,79.23],[2,1.13,75.82]],"ltp":0.0,"tv":0.0,"id":8444055},{"batb":[[1,1.55,155.57],[2,1.09,75.92]],"ltp":0.0,"tv":0.0,"id":8257852}]}]}
{"op":"mcm","clk":"1007376659","pt":1580612109786,"mc":[{"id":"1.168223927","rc":[{"batb":[[0,1.61,199.19]],"ltp":0.0,"tv":0.0,"id":8257852}]}]}
{"op":"mcm","clk":"1007399204","pt":1580612859935,"mc":[{"id":"1.168223927","rc":[{"batl":[[0,2.62,21.85]],"ltp":0.0,"tv":0.0,"id":8444055}]}]}
{"op":"mcm","clk":"1007399293","pt":1580612863244,"mc":[{"id":"1.168223927","rc":[{"batb":[[0,2.32,89.89],[1,2.3,51.49],[2,2.14,75.06]],"ltp":0.0,"tv":0.0,"id":8444055},{"batb":[[0,1.61,124.22],[1,1.53,161.45]],"ltp":0.0,"tv":0.0,"id":8257852}]}]}
{"op":"mcm","clk":"1007399315","pt":1580612864436,"mc":[{"id":"1.168223927","rc":[{"batb":[[1,1.58,73.45],[2,1.53,161.45]],"ltp":0.0,"tv":0.0,"id":8257852}]}]}
{"op":"mcm","clk":"1007430236","pt":1580613838745,"mc":[{"id":"1.168223927","rc":[{"batb":[[0,1.62,6.46],[1,1.61,124.22],[2,1.58,73.45]],"ltp":0.0,"tv":0.0,"id":8257852}]}]}
{"op":"mcm","clk":"1007435009","pt":1580613970228,"mc":[{"id":"1.168223927","rc":[{"batb":[[0,2.32,124.39]],"ltp":0.0,"tv":0.0,"id":8444055}]}]}
{"op":"mcm","clk":"1007435132","pt":1580613972967,"mc":[{"id":"1.168223927","rc":[{"batb":[[2,2.2,98.44]],"ltp":0.0,"tv":0.0,"id":8444055}]}]}
{"op":"mcm","clk":"1007449724","pt":1580614434886,"mc":[{"id":"1.168223927","rc":[{"batb":[[0,2.3,51.49],[1,2.2,98.44],[2,1.13,75.82]],"ltp":0.0,"tv":0.0,"id":8444055},{"batl":[[0,1.63,1.68],[1,11.5,3.36],[2,48,31.05]],"ltp":0.0,"tv":0.0,"id":8257852}]}]}
{"op":"mcm","clk":"1007450877","pt":1580614474653,"mc":[{"id":"1.168223927","rc":[{"batl":[[1,48,31.05],[2,990,2.2]],"ltp":0.0,"tv":0.0,"id":8257852}]}]}
{"op":"mcm","clk":"1007461940","pt":1580614951593,"mc":[{"id":"1.168223927","rc":[{"batb":[[0,2.32,124.89],[1,2.3,51.49],[2,2.2,98.44]],"ltp":0.0,"tv":0.0,"id":8444055}]}]}
{"op":"mcm","clk":"1007465917","pt":1580615093191,"mc":[{"id":"1.168223927","rc":[{"batl":[[1,990,2.2],[2,1000,0.02]],"ltp":0.0,"tv":0.0,"id":8444055},{"batl":[[1,990,2.2],[2,1000,0.02]],"ltp":0.0,"tv":0.0,"id":8257852}]}]}
{"op":"mcm","clk":"1007514136","pt":1580616366013,"mc":[{"id":"1.168223927","rc":[{"batb":[[0,2.34,7.23]],"ltp":0.0,"tv":0.0,"id":8444055}]}]}
{"op":"mcm","clk":"1007528236","pt":1580616833649,"mc":[{"id":"1.168223927","rc":[{"batl":[[1,95,15.9],[2,990,2.2]],"ltp":0.0,"tv":0.0,"id":8444055},{"batl":[[1,95,15.9],[2,990,2.2]],"ltp":0.0,"tv":0.0,"id":8257852}]}]}
{"op":"mcm","clk":"1007606084","pt":1580618854488,"mc":[{"id":"1.168223927","rc":[{"batl":[[1,2.3,3.03],[2,95,15.9]],"ltp":0.0,"tv":0.0,"id":8257852}]}]}
{"op":"mcm","clk":"1007607363","pt":1580618891829,"mc":[{"id":"1.168223927","rc":[{"batb":[[0,2.32,124.89],[2,2.22,7.23]],"ltp":0.0,"tv":0.0,"id":8444055}]}]}
{"op":"mcm","clk":"1007713601","pt":1580621382746,"mc":[{"id":"1.168223927","rc":[{"batb":[[0,2.34,7.23],[1,2.32,124.89],[2,2.3,51.49]],"ltp":0.0,"tv":0.0,"id":8444055}]}]}
{"op":"mcm","clk":"1007714406","pt":1580621401194,"mc":[{"id":"1.168223927","rc":[{"batb":[[1,2.3,51.49],[2,2.2,98.44]],"ltp":0.0,"tv":0.0,"id":8444055}]}]}
{"op":"mcm","clk":"1007714430","pt":1580621401613,"mc":[{"id":"1.168223927","rc":[{"batb":[[0,2.36,124.18],[1,2.34,7.23],[2,2.3,51.49]],"ltp":0.0,"tv":0.0,"id":8444055}]}]}
{"op":"mcm","clk":"1007714645","pt":1580621404981,"mc":[{"id":"1.168223927","rc":[{"batb":[[1,2.34,58.72],[2,2.24,95.27]],"ltp":0.0,"tv":0.0,"id":8444055},{"batb":[[2,1.53,222.88]],"ltp":0.0,"tv":0.0,"id":8257852}]}]}
{"op":"mcm","clk":"1007715220","pt":1580621418447,"mc":[{"id":"1.168223927","rc":[{"batb":[[2,1.56,74.97]],"ltp":0.0,"tv":0.0,"id":8257852}]}]}
{"op":"mcm","clk":"1007769092","pt":1580622492254,"mc":[{"id":"1.168223927","rc":[{"batb":[[0,2.36,124.68]],"ltp":0.0,"tv":0.0,"id":8444055}]}]}
{"op":"mcm","clk":"1007804338","pt":1580623314747,"mc":[{"id":"1.168223927","rc":[{"batb":[[0,2.36,188.93]],"ltp":0.0,"tv":0.0,"id":8444055}]}]}
{"op":"mcm","clk":"1007804493","pt":1580623318248,"mc":[{"id":"1.168223927","rc":[{"batb":[[2,2.24,145.34]],"ltp":0.0,"tv":0.0,"id":8444055}]}]}
{"op":"mcm","clk":"1007825259","pt":1580623826172,"mc":[{"id":"1.168223927","rc":[{"batb":[[0,2.38,7.23],[1,2.36,188.93],[2,2.34,51.49]],"ltp":0.0,"tv":0.0,"id":8444055}]}]}
{"op":"mcm","clk":"1007825272","pt":1580623826478,"mc":[{"id":"1.168223927","rc":[{"batb":[[1,2.34,51.49],[2,2.24,145.34]],"ltp":0.0,"tv":0.0,"id":8444055}]}]}
{"op":"mcm","clk":"1007857605","pt":1580624552755,"mc":[{"id":"1.168223927","rc":[{"batb":[[2,1.13,75.82]],"ltp":0.0,"tv":0.0,"id":8444055}]}]}
{"op":"mcm","clk":"1007857635","pt":1580624553323,"mc":[{"id":"1.168223927","rc":[{"batb":[[2,2.24,145.34]],"ltp":0.0,"tv":0.0,"id":8444055}]}]}
{"op":"mcm","clk":"1007876741","pt":1580624960902,"mc":[{"id":"1.168223927","rc":[{"batb":[[1,2.32,51.49],[2,2.22,147.72]],"ltp":0.0,"tv":0.0,"id":8444055},{"batb":[[2,1.57,74.97]],"ltp":0.0,"tv":0.0,"id":8257852}]}]}
{"op":"mcm","clk":"1007921961","pt":1580626047191,"mc":[{"id":"1.168223927","rc":[{"batb":[[2,1.13,75.82]],"ltp":0.0,"tv":0.0,"id":8444055}]}]}
{"op":"mcm","clk":"1007921992","pt":1580626047808,"mc":[{"id":"1.168223927","rc":[{"batb":[[2,2.22,147.72]],"ltp":0.0,"tv":0.0,"id":8444055}]}]}
{"op":"mcm","clk":"1007941696","pt":1580626443261,"mc":[{"id":"1.168223927","rc":[{"batb":[[0,2.32,51.49],[1,2.22,147.72],[2,1.13,75.82]],"ltp":0.0,"tv":0.0,"id":8444055}]}]}
{"op":"mcm","clk":"1007941715","pt":1580626443570,"mc":[{"id":"1.168223927","rc":[{"batb":[[0,2.34,189.72],[1,2.32,51.49],[2,2.24,7.23]],"ltp":0.0,"tv":0.0,"id":8444055}]}]}
{"op":"mcm","clk":"1008062368","pt":1580628626500,"mc":[{"id":"1.168223927","rc":[{"batb":[[2,1.58,74.97]],"ltp":0.0,"tv":0.0,"id":8257852}]}]}
{"op":"mcm","clk":"1008062997","pt":1580628641607,"mc":[{"id":"1.168223927","rc":[{"trd":[[1.63,3.36]],"batl":[[0,2.3,3.03],[1,95,15.9],[2,990,2.2]],"ltp":1.63,"tv":3.36,"id":8257852}],"tv":3.36}]}
{"op":"mcm","clk":"1008063064","pt":1580628642901,"mc":[{"id":"1.168223927","rc":[{"batb":[[0,2.38,34.75],[1,2.34,189.72],[2,2.32,51.49]],"ltp":0.0,"tv":0.0,"id":8444055},{"batb":[[0,1.62,35.39]],"ltp":1.63,"tv":3.36,"id":8257852}]}]}
{"op":"mcm","clk":"1008063227","pt":1580628647223,"mc":[{"id":"1.168223927","rc":[{"batb":[[1,1.58,74.97],[2,1.54,333.74]],"ltp":1.63,"tv":3.36,"id":8257852}]}]}
{"op":"mcm","clk":"1008063497","pt":1580628652734,"mc":[{"id":"1.168223927","rc":[{"batb":[[0,1.62,118.6]],"ltp":1.63,"tv":3.36,"id":8257852}]}]}
{"op":"mcm","clk":"1008063773","pt":1580628658257,"mc":[{"id":"1.168223927","rc":[{"batb":[[0,1.62,145.02]],"ltp":1.63,"tv":3.36,"id":8257852}]}]}
{"op":"mcm","clk":"1008083190","pt":1580629040857,"mc":[{"id":"1.168223927","rc":[{"batb":[[0,1.62,138.56]],"ltp":1.63,"tv":3.36,"id":8257852}]}]}
{"op":"mcm","clk":"1008094503","pt":1580629282226,"mc":[{"id":"1.168223927","rc":[{"batb":[[1,2.32,51.49],[2,2.22,147.72]],"ltp":0.0,"tv":0.0,"id":8444055}]}]}
{"op":"mcm","clk":"1008158848","pt":1580630472638,"mc":[{"id":"1.168223927","rc":[{"batb":[[1,2.22,147.72],[2,2.12,51.49]],"ltp":0.0,"tv":0.0,"id":8444055},{"batb":[[1,1.54,333.74],[2,1.51,37.86]],"ltp":1.63,"tv":3.36,"id":8257852}]}]}
{"op":"mcm","clk":"1008166924","pt":1580630618593,"mc":[{"id":"1.168223927","rc":[{"batb":[[1,2.32,51.49],[2,2.22,147.72]],"ltp":0.0,"tv":0.0,"id":8444055},{"batb":[[1,1.58,74.97],[2,1.54,333.74]],"ltp":1.63,"tv":3.36,"id":8257852}]}]}
{"op":"mcm","clk":"1008250245","pt":1580631959179,"mc":[{"id":"1.168223927","rc":[{"batb":[[2,2.2,150.18]],"ltp":0.0,"tv":0.0,"id":8444055},{"batb":[[2,1.56,321.82]],"ltp":1.63,"tv":3.36,"id":8257852}]}]}
{"op":"mcm","clk":"1008250335","pt":1580631960883,"mc":[{"id":"1.168223927","rc":[{"batb":[[1,2.2,150.18],[2,2,37.86]],"ltp":0.0,"tv":0.0,"id":8444055}]}]}
{"op":"mcm","clk":"1008309408","pt":1580632884182,"mc":[{"id":"1.168223927","rc":[{"batb":[[0,2.4,32.89],[1,2.22,15.84],[2,2.2,150.18]],"ltp":0.0,"tv":0.0,"id":8444055},{"trd":[[1.62,10.13]],"batb":[[0,1.62,133.49]],"ltp":1.62,"tv":13.49,"id":8257852}],"tv":13.49}]}
{"op":"mcm","clk":"1008309420","pt":1580632884291,"mc":[{"id":"1.168223927","rc":[{"batb":[[1,2.2,150.18],[2,2,37.86]],"ltp":0.0,"tv":0.0,"id":8444055}]}]}
{"op":"mcm","clk":"1008369280","pt":1580634072507,"mc":[{"id":"1.168223927","rc":[{"batb":[[1,1.59,74.97]],"ltp":1.62,"tv":13.49,"id":8257852}]}]}
{"op":"mcm","clk":"1008370722","pt":1580634099824,"mc":[{"id":"1.168223927","rc":[{"batb":[[1,2.28,51.49],[2,2.2,150.18]],"ltp":0.0,"tv":0.0,"id":8444055}]}]}
{"op":"mcm","clk":"1008378734","pt":1580634234928,"mc":[{"id":"1.168223927","rc":[{"batb":[[2,2,37.86]],"ltp":0.0,"tv":0.0,"id":8444055},{"batb":[[2,1.51,37.86]],"ltp":1.62,"tv":13.49,"id":8257852}]}]}
{"op":"mcm","clk":"1008378783","pt":1580634235494,"mc":[{"id":"1.168223927","rc":[{"batb":[[2,2.22,194.28]],"ltp":0.0,"tv":0.0,"id":8444055},{"batb":[[2,1.57,415.81]],"ltp":1.62,"tv":13.49,"id":8257852}]}]}
{"op":"mcm","clk":"1008527658","pt":1580636617816,"mc":[{"id":"1.168223927","rc":[{"batl":[[1,2.46,74.21],[2,95,15.9]],"ltp":1.62,"tv":13.49,"id":8257852}]}]}
{"op":"mcm","clk":"1008563827","pt":1580637148489,"mc":[{"id":"1.168223927","rc":[{"batl":[[0,1.71,2.27],[1,2.3,3.03],[2,2.46,74.21]],"ltp":1.62,"tv":13.49,"id":8257852}]}]}
{"op":"mcm","clk":"1008724684","pt":1580639063409,"mc":[{"id":"1.168223927","rc":[{"batl":[[1,2.46,74.21],[2,95,15.9]],"ltp":1.62,"tv":13.49,"id":8257852}]}]}
{"op":"mcm","clk":"1008726553","pt":1580639083179,"mc":[{"id":"1.168223927","rc":[{"batl":[[1,2.2,15.14],[2,2.46,74.21]],"ltp":1.62,"tv":13.49,"id":8257852}]}]}
{"op":"mcm","clk":"1008775548","pt":1580639545913,"mc":[{"id":"1.168223927","rc":[{"batb":[[2,2,37.86]],"ltp":0.0,"tv":0.0,"id":8444055},{"batb":[[2,1.51,37.86]],"ltp":1.62,"tv":13.49,"id":8257852}]}]}
{"op":"mcm","clk":"1008775607","pt":1580639546489,"mc":[{"id":"1.168223927","rc":[{"batb":[[2,2.22,194.28]],"ltp":0.0,"tv":0.0,"id":8444055},{"batb":[[2,1.57,415.81]],"ltp":1.62,"tv":13.49,"id":8257852}]}]}
{"op":"mcm","clk":"1008776162","pt":1580639551106,"mc":[{"id":"1.168223927","rc":[{"batb":[[1,1.6,74.97]],"ltp":1.62,"tv":13.49,"id":8257852}]}]}
{"op":"mcm","clk":"1008897148","pt":1580640563104,"mc":[{"id":"1.168223927","rc":[{"trd":[[1.62,60.54]],"batb":[[0,1.62,108.29]],"ltp":1.62,"tv":63.89,"id":8257852}],"tv":63.89}]}
{"op":"mcm","clk":"1008897515","pt":1580640566218,"mc":[{"id":"1.168223927","rc":[{"batb":[[0,2.44,34.15]],"ltp":0.0,"tv":0.0,"id":8444055},{"batb":[[1,1.61,15.09],[2,1.6,74.97]],"ltp":1.62,"tv":63.89,"id":8257852}]}]}
{"op":"mcm","clk":"1008897542","pt":1580640566427,"mc":[{"id":"1.168223927","rc":[{"batb":[[2,2.22,232.14]],"ltp":0.0,"tv":0.0,"id":8444055}]}]}
{"op":"mcm","clk":"1008897724","pt":1580640567939,"mc":[{"id":"1.168223927","rc":[{"batb":[[0,1.61,15.09],[1,1.6,74.97],[2,1.57,415.81]],"ltp":1.62,"tv":63.89,"id":8257852}]}]}
{"op":"mcm","clk":"1008898411","pt":1580640573544,"mc":[{"id":"1.168223927","rc":[{"batb":[[0,1.61,73.12]],"ltp":1.62,"tv":63.89,"id":8257852}]}]}
{"op":"mcm","clk":"1008898842","pt":1580640576839,"mc":[{"id":"1.168223927","rc":[{"batl":[[1,1.8,16.8],[2,2.2,15.14]],"ltp":1.62,"tv":63.89,"id":8257852}]}]}
{"op":"mcm","clk":"1008899149","pt":1580640579154,"mc":[{"id":"1.168223927","rc":[{"batb":[[0,1.61,95.71]],"ltp":1.62,"tv":63.89,"id":8257852}]}]}
{"op":"mcm","clk":"1008900259","pt":1580640587538,"mc":[{"id":"1.168223927","rc":[{"batl":[[2,2,12.6]],"ltp":1.62,"tv":63.89,"id":8257852}]}]}
{"op":"mcm","clk":"1008941848","pt":1580640947262,"mc":[{"id":"1.168223927","rc":[{"trd":[[1.61,8.51]],"batb":[[0,1.61,91.45]],"ltp":1.61,"tv":72.41,"id":8257852}],"tv":72.41}]}
{"op":"mcm","clk":"1008942044","pt":1580640948771,"mc":[{"id":"1.168223927","rc":[{"batb":[[0,2.46,32]],"ltp":0.0,"tv":0.0,"id":8444055},{"batb":[[0,1.61,80.62],[2,1.58,37.64]],"ltp":1.61,"tv":72.41,"id":8257852}]}]}
{"op":"mcm","clk":"1008982025","pt":1580641256959,"mc":[{"id":"1.168223927","rc":[{"batb":[[0,1.62,7.57],[1,1.61,80.62],[2,1.6,74.97]],"ltp":1.61,"tv":72.41,"id":8257852}]}]}
{"op":"mcm","clk":"1009066109","pt":1580641815084,"mc":[{"id":"1.168223927","rc":[{"trd":[[1.62,64.59]],"batb":[[0,1.62,5.54]],"ltp":1.62,"tv":76.47,"id":8257852}],"tv":76.47}]}
{"op":"mcm","clk":"1009066524","pt":1580641817501,"mc":[{"id":"1.168223927","rc":[{"trd":[[1.63,7.39]],"ltp":1.63,"tv":80.49,"id":8257852}],"tv":80.49}]}
{"op":"mcm","clk":"1009105394","pt":1580642070040,"mc":[{"id":"1.168223927","rc":[{"batb":[[0,1.63,2.03],[1,1.62,5.54],[2,1.61,80.62]],"ltp":1.63,"tv":80.49,"id":8257852}]}]}
{"op":"mcm","clk":"1009115043","pt":1580642128109,"mc":[{"id":"1.168223927","rc":[{"batb":[[0,2.46,30.7]],"ltp":0.0,"tv":0.0,"id":8444055},{"trd":[[1.63,11.44]],"batb":[[0,1.62,5.54],[1,1.61,93.51],[2,1.6,74.97]],"ltp":1.63,"tv":84.54,"id":8257852}],"tv":84.54}]}
{"op":"mcm","clk":"1009152613","pt":1580642365226,"mc":[{"id":"1.168223927","rc":[{"batl":[[0,2.5,106.37],[1,2.62,21.85],[2,95,15.9]],"ltp":0.0,"tv":0.0,"id":8444055}]}]}
{"op":"mcm","clk":"1009152649","pt":1580642365449,"mc":[{"id":"1.168223927","rc":[{"trd":[[2.5,35.2]],"batl":[[0,2.5,88.78]],"ltp":2.5,"tv":35.2,"id":8444055}],"tv":119.74}]}
{"op":"mcm","clk":"1009156160","pt":1580642389898,"mc":[{"id":"1.168223927","rc":[{"trd":[[2.5,77.84]],"batl":[[0,2.5,67.47]],"ltp":2.5,"tv":77.84,"id":8444055}],"tv":162.38}]}
{"op":"mcm","clk":"1009156238","pt":1580642390483,"mc":[{"id":"1.168223927","rc":[{"batb":[[0,2.36,34.6]],"ltp":2.5,"tv":77.84,"id":8444055},{"batb":[[0,1.63,28.69],[1,1.62,5.54],[2,1.61,80.62]],"ltp":1.63,"tv":84.54,"id":8257852}]}]}
{"op":"mcm","clk":"1009183729","pt":1580642577596,"mc":[{"id":"1.168223927","rc":[{"batl":[[2,4.1,153.72]],"ltp":2.5,"tv":77.84,"id":8444055}]}]}
{"op":"mcm","clk":"1009221962","pt":1580642837298,"mc":[{"id":"1.168223927","rc":[{"trd":[[2.5,86.25]],"batl":[[0,2.5,59.06]],"ltp":2.5,"tv":86.24,"id":8444055},{"trd":[[1.66,12.67]],"ltp":1.66,"tv":97.21,"id":8257852}],"tv":183.45}]}
{"op":"mcm","clk":"1009247266","pt":1580643003320,"mc":[{"id":"1.168223927","rc":[{"batb":[[2,1.6,74.97]],"ltp":1.66,"tv":97.21,"id":8257852}]}]}
{"op":"mcm","clk":"1009248224","pt":1580643009440,"mc":[{"id":"1.168223927","rc":[{"batb":[[0,1.66,52.62],[1,1.63,28.69],[2,1.62,5.54]],"ltp":1.66,"tv":97.21,"id":8257852}]}]}
{"op":"mcm","clk":"1009277269","pt":1580643194812,"mc":[{"id":"1.168223927","rc":[{"trd":[[2.36,0.76],[2.4,1.62]],"batb":[[0,2.36,34.22]],"ltp":2.36,"tv":88.62,"id":8444055},{"trd":[[1.71,2.27]],"batl":[[0,1.8,16.8],[1,2,12.6],[2,2.2,15.14]],"ltp":1.71,"tv":99.48,"id":8257852}],"tv":188.1}]}
{"op":"mcm","clk":"1009353914","pt":1580643713256,"mc":[{"id":"1.168223927","rc":[{"trd":[[2.36,4.12]],"batb":[[0,2.36,32.54]],"ltp":2.36,"tv":91.98,"id":8444055},{"batb":[[1,1.63,31.64]],"ltp":1.71,"tv":99.48,"id":8257852}],"tv":191.46}]}
{"op":"mcm","clk":"1009381269","pt":1580643896959,"mc":[{"id":"1.168223927","rc":[{"batl":[[0,1.73,7.57],[1,1.8,16.8],[2,2,12.6]],"ltp":1.71,"tv":99.48,"id":8257852}]}]}
{"op":"mcm","clk":"1009460559","pt":1580644557004,"mc":[{"id":"1.168223927","rc":[{"batl":[[0,2.46,59.06]],"ltp":2.36,"tv":91.98,"id":8444055}]}]}
{"op":"mcm","clk":"1009460720","pt":1580644558235,"mc":[{"id":"1.168223927","rc":[{"batb":[[2,2.22,194.28]],"ltp":2.36,"tv":91.98,"id":8444055}]}]}
{"op":"mcm","clk":"1009469714","pt":1580644638232,"mc":[{"id":"1.168223927","rc":[{"trd":[[2.46,14.87]],"batb":[[0,2.36,25.03]],"batl":[[0,2.46,51.63]],"ltp":2.46,"tv":106.85,"id":8444055},{"batb":[[1,1.62,5.54],[2,1.6,74.97]],"ltp":1.71,"tv":99.48,"id":8257852}],"tv":206.33}]}
{"op":"mcm","clk":"1009469724","pt":1580644638341,"mc":[{"id":"1.168223927","rc":[{"batb":[[0,1.67,11.02],[1,1.66,52.62],[2,1.62,5.54]],"ltp":1.71,"tv":99.48,"id":8257852}]}]}
{"op":"mcm","clk":"1009473589","pt":1580644673948,"mc":[{"id":"1.168223927","rc":[{"batl":[[0,1.72,420.85],[1,1.73,7.57],[2,1.8,16.8]],"ltp":1.71,"tv":99.48,"id":8257852}]}]}
{"op":"mcm","clk":"1009484067","pt":1580644768197,"mc":[{"id":"1.168223927","rc":[{"batb":[[0,2.4,14.63]],"ltp":2.46,"tv":106.85,"id":8444055}]}]}
{"op":"mcm","clk":"1009484581","pt":1580644772508,"mc":[{"id":"1.168223927","rc":[{"batb":[[1,2.22,194.28],[2,2,37.86]],"ltp":2.46,"tv":106.85,"id":8444055}]}]}
{"op":"mcm","clk":"1009484807","pt":1580644774100,"mc":[{"id":"1.168223927","rc":[{"batb":[[1,2,37.86],[2,1.81,37.86]],"ltp":2.46,"tv":106.85,"id":8444055}]}]}
{"op":"mcm","clk":"1009484890","pt":1580644774700,"mc":[{"id":"1.168223927","rc":[{"batb":[[1,2.2,197.51],[2,2,37.86]],"ltp":2.46,"tv":106.85,"id":8444055}]}]}
{"op":"mcm","clk":"1009489005","pt":1580644806553,"mc":[{"id":"1.168223927","rc":[{"batb":[[1,1.62,5.54],[2,1.6,74.97]],"ltp":1.71,"tv":99.48,"id":8257852}]}]}
{"op":"mcm","clk":"1009489868","pt":1580644812327,"mc":[{"id":"1.168223927","rc":[{"batb":[[0,1.68,19.77],[1,1.67,11.02],[2,1.62,5.54]],"ltp":1.71,"tv":99.48,"id":8257852}]}]}
{"op":"mcm","clk":"1009495818","pt":1580644858029,"mc":[{"id":"1.168223927","rc":[{"batb":[[1,2.26,51.49],[2,2.2,197.51]],"ltp":2.46,"tv":106.85,"id":8444055}]}]}
{"op":"mcm","clk":"1009496299","pt":1580644861528,"mc":[{"id":"1.168223927","rc":[{"batb":[[0,1.68,29.15]],"ltp":1.71,"tv":99.48,"id":8257852}]}]}
{"op":"mcm","clk":"1009501328","pt":1580644900065,"mc":[{"id":"1.168223927","rc":[{"batb":[[1,1.63,42.7]],"ltp":1.71,"tv":99.48,"id":8257852}]}]}
{"op":"mcm","clk":"1009502076","pt":1580644905086,"mc":[{"id":"1.168223927","rc":[{"batb":[[0,1.68,42.99]],"ltp":1.71,"tv":99.48,"id":8257852}]}]}
{"op":"mcm","clk":"1009503038","pt":1580644910807,"mc":[{"id":"1.168223927","rc":[{"batb":[[0,1.68,62.99]],"ltp":1.71,"tv":99.48,"id":8257852}]}]}
{"op":"mcm","clk":"1009503750","pt":1580644915766,"mc":[{"id":"1.168223927","rc":[{"trd":[[2.4,9.98]],"batb":[[0,2.4,10.44]],"ltp":2.4,"tv":115.21,"id":8444055}],"tv":214.69}]}
{"op":"mcm","clk":"1009503989","pt":1580644917529,"mc":[{"id":"1.168223927","rc":[{"batb":[[1,1.63,48.76]],"ltp":1.71,"tv":99.48,"id":8257852}]}]}
{"op":"mcm","clk":"1009504702","pt":1580644921760,"mc":[{"id":"1.168223927","rc":[{"batb":[[0,1.68,71.93]],"ltp":1.71,"tv":99.48,"id":8257852}]}]}
{"op":"mcm","clk":"1009567333","pt":1580645354989,"mc":[{"id":"1.168223927","rc":[{"trd":[[2.46,24.91]],"batl":[[0,2.46,46.61]],"ltp":2.46,"tv":125.25,"id":8444055},{"batb":[[1,1.64,7.5],[2,1.63,48.76]],"ltp":1.71,"tv":99.48,"id":8257852}],"tv":224.74}]}
{"op":"mcm","clk":"1009568376","pt":1580645362199,"mc":[{"id":"1.168223927","rc":[{"batl":[[0,1.73,7.57],[1,1.8,16.8],[2,2,12.98]],"ltp":1.71,"tv":99.48,"id":8257852}]}]}
{"op":"mcm","clk":"1009568440","pt":1580645362632,"mc":[{"id":"1.168223927","rc":[{"trd":[[2.46,71.52]],"batb":[[2,2.22,37.86]],"batl":[[0,2.62,21.85],[1,4.1,153.72],[2,95,15.9]],"ltp":2.46,"tv":171.87,"id":8444055},{"trd":[[1.68,212.18]],"batb":[[0,1.64,7.5],[1,1.63,48.76],[2,1.62,5.54]],"batl":[[0,1.68,280.6],[1,1.73,7.57],[2,1.8,16.8]],"ltp":1.68,"tv":311.65,"id":8257852}],"tv":483.53}]}
{"op":"mcm","clk":"1009569308","pt":1580645367489,"mc":[{"id":"1.168223927","rc":[{"batb":[[1,1.63,65.42]],"ltp":1.68,"tv":311.65,"id":8257852}]}]}
{"op":"mcm","clk":"1009570164","pt":1580645373126,"mc":[{"id":"1.168223927","rc":[{"batl":[[0,1.7,280.6]],"ltp":1.68,"tv":311.65,"id":8257852}]}]}
{"op":"mcm","clk":"1009571981","pt":1580645385844,"mc":[{"id":"1.168223927","rc":[{"batb":[[0,1.65,146.19],[1,1.64,7.5],[2,1.63,65.42]],"ltp":1.68,"tv":311.65,"id":8257852}]}]}
{"op":"mcm","clk":"1009572453","pt":1580645389533,"mc":[{"id":"1.168223927","rc":[{"batb":[[2,1.63,48.76]],"ltp":1.68,"tv":311.65,"id":8257852}]}]}
{"op":"mcm","clk":"1009572795","pt":1580645392058,"mc":[{"id":"1.168223927","rc":[{"batl":[[0,1.68,7.57],[1,1.7,280.6],[2,1.73,7.57]],"ltp":1.68,"tv":311.65,"id":8257852}]}]}
{"op":"mcm","clk":"1009573059","pt":1580645393960,"mc":[{"id":"1.168223927","rc":[{"batl":[[0,1.7,280.6],[1,1.73,7.57],[2,1.8,16.8]],"ltp":1.68,"tv":311.65,"id":8257852}]}]}
{"op":"mcm","clk":"1009573227","pt":1580645395275,"mc":[{"id":"1.168223927","rc":[{"batb":[[0,1.65,168.68]],"ltp":1.68,"tv":311.65,"id":8257852}]}]}
{"op":"mcm","clk":"1009579788","pt":1580645444207,"mc":[{"id":"1.168223927","rc":[{"batb":[[0,2.38,15.6]],"ltp":2.46,"tv":171.87,"id":8444055},{"batb":[[0,1.66,24.66],[1,1.65,168.68],[2,1.64,7.5]],"ltp":1.68,"tv":311.65,"id":8257852}]}]}
{"op":"mcm","clk":"1009580512","pt":1580645449736,"mc":[{"id":"1.168223927","rc":[{"batb":[[1,1.65,146.19]],"ltp":1.68,"tv":311.65,"id":8257852}]}]}
{"op":"mcm","clk":"1009581340","pt":1580645455523,"mc":[{"id":"1.168223927","rc":[{"batb":[[0,1.66,57.28]],"ltp":1.68,"tv":311.65,"id":8257852}]}]}
{"op":"mcm","clk":"1009582124","pt":1580645461129,"mc":[{"id":"1.168223927","rc":[{"batb":[[0,1.66,71.04]],"ltp":1.68,"tv":311.65,"id":8257852}]}]}
{"op":"mcm","clk":"1009741610","pt":1580646615836,"mc":[{"id":"1.168223927","rc":[{"batb":[[1,1.64,7.5],[2,1.62,5.54]],"batl":[[0,1.73,7.57],[1,1.8,16.8],[2,2,12.98]],"ltp":1.68,"tv":311.65,"id":8257852}]}]}
{"op":"mcm","clk":"1009762619","pt":1580646762166,"mc":[{"id":"1.168223927","rc":[{"batb":[[0,2.38,21.37]],"ltp":2.46,"tv":171.87,"id":8444055},{"trd":[[1.66,29.47]],"batb":[[0,1.66,46.38],[1,1.65,24.13],[2,1.64,7.5]],"ltp":1.66,"tv":328.46,"id":8257852}],"tv":500.33}]}
{"op":"mcm","clk":"1009763042","pt":1580646764985,"mc":[{"id":"1.168223927","rc":[{"batl":[[0,1.72,7.57],[1,1.73,7.57],[2,1.8,16.8]],"ltp":1.66,"tv":328.46,"id":8257852}]}]}
{"op":"mcm","clk":"1009763257","pt":1580646766579,"mc":[{"id":"1.168223927","rc":[{"batb":[[0,1.65,24.13],[1,1.64,7.5],[2,1.62,5.54]],"ltp":1.66,"tv":328.46,"id":8257852}]}]}
{"op":"mcm","clk":"1009764071","pt":1580646772187,"mc":[{"id":"1.168223927","rc":[{"batb":[[0,1.65,48.27]],"ltp":1.66,"tv":328.46,"id":8257852}]}]}
{"op":"mcm","clk":"1009764949","pt":1580646777777,"mc":[{"id":"1.168223927","rc":[{"batb":[[0,1.65,65.67]],"ltp":1.66,"tv":328.46,"id":8257852}]}]}
{"op":"mcm","clk":"1009796776","pt":1580647016719,"mc":[{"id":"1.168223927","rc":[{"trd":[[1.65,30.29]],"batb":[[0,1.65,50.52]],"ltp":1.65,"tv":358.75,"id":8257852}],"tv":530.62}]}
{"op":"mcm","clk":"1009796905","pt":1580647017515,"mc":[{"id":"1.168223927","rc":[{"batb":[[0,2.4,10.27],[1,2.38,21.37],[2,2.26,51.49]],"ltp":2.46,"tv":171.87,"id":8444055},{"batb":[[0,1.65,41.54],[2,1.63,25.2]],"ltp":1.65,"tv":358.75,"id":8257852}]}]}
{"op":"mcm","clk":"1009797467","pt":1580647021616,"mc":[{"id":"1.168223927","rc":[{"batb":[[0,1.64,7.5],[1,1.63,25.2],[2,1.62,5.54]],"ltp":1.65,"tv":358.75,"id":8257852}]}]}
{"op":"mcm","clk":"1009798237","pt":1580647027128,"mc":[{"id":"1.168223927","rc":[{"batb":[[1,1.63,50.23]],"ltp":1.65,"tv":358.75,"id":8257852}]}]}
{"op":"mcm","clk":"1009892953","pt":1580647683880,"mc":[{"id":"1.168223927","rc":[{"batl":[[0,1.73,7.57],[1,1.8,16.8],[2,2,12.98]],"ltp":1.65,"tv":358.75,"id":8257852}]}]}
{"op":"mcm","clk":"1009893235","pt":1580647686091,"mc":[{"id":"1.168223927","rc":[{"batl":[[0,1.8,16.8],[1,2,12.98],[2,2.2,15.14]],"ltp":1.65,"tv":358.75,"id":8257852}]}]}
{"op":"mcm","clk":"1009893787","pt":1580647690386,"mc":[{"id":"1.168223927","rc":[{"batb":[[1,1.63,59.28]],"ltp":1.65,"tv":358.75,"id":8257852}]}]}
{"op":"mcm","clk":"1009898158","pt":1580647730430,"mc":[{"id":"1.168223927","rc":[{"batb":[[0,2.38,31.64],[1,2.26,51.49],[2,2.22,37.86]],"ltp":2.46,"tv":171.87,"id":8444055}]}]}
{"op":"mcm","clk":"1009898565","pt":1580647733938,"mc":[{"id":"1.168223927","rc":[{"batb":[[1,1.63,72.44]],"ltp":1.65,"tv":358.75,"id":8257852}]}]}
{"op":"mcm","clk":"1009907877","pt":1580647816542,"mc":[{"id":"1.168223927","rc":[{"trd":[[2.38,10.04]],"batb":[[0,2.38,26.63]],"ltp":2.38,"tv":181.9,"id":8444055}],"tv":540.66}]}
{"op":"mcm","clk":"1009908027","pt":1580647817959,"mc":[{"id":"1.168223927","rc":[{"batb":[[0,2.36,32.05]],"ltp":2.38,"tv":181.9,"id":8444055},{"batb":[[0,1.64,14.75]],"ltp":1.65,"tv":358.75,"id":8257852}]}]}
{"op":"mcm","clk":"1009938823","pt":1580648093431,"mc":[{"id":"1.168223927","rc":[{"batl":[[0,1.71,7.57],[1,1.8,16.8],[2,2,12.98]],"ltp":1.65,"tv":358.75,"id":8257852}]}]}
{"op":"mcm","clk":"1009945014","pt":1580648141463,"mc":[{"id":"1.168223927","rc":[{"batb":[[0,2.42,16.56]],"ltp":2.38,"tv":181.9,"id":8444055}]}]}
{"op":"mcm","clk":"1009967612","pt":1580648330058,"mc":[{"id":"1.168223927","rc":[{"batb":[[0,2.42,19.14]],"ltp":2.38,"tv":181.9,"id":8444055},{"trd":[[1.64,22.72]],"batb":[[0,1.64,3.39]],"ltp":1.64,"tv":381.47,"id":8257852}],"tv":563.38}]}
{"op":"mcm","clk":"1010041509","pt":1580648798994,"mc":[{"id":"1.168223927","rc":[{"batl":[[1,1.72,3.36],[2,1.8,16.8]],"ltp":1.64,"tv":381.47,"id":8257852}]}]}
{"op":"mcm","clk":"1010063090","pt":1580648937960,"mc":[{"id":"1.168223927","rc":[{"batb":[[0,2.42,16.56]],"ltp":2.38,"tv":181.9,"id":8444055},{"batb":[[0,1.64,5.81]],"ltp":1.64,"tv":381.47,"id":8257852}]}]}
{"op":"mcm","clk":"1010087379","pt":1580649097266,"mc":[{"id":"1.168223927","rc":[{"batb":[[0,2.42,18.86]],"ltp":2.38,"tv":181.9,"id":8444055},{"trd":[[1.64,26.72]],"batb":[[0,1.64,2.42]],"ltp":1.64,"tv":385.47,"id":8257852}],"tv":567.38}]}
{"op":"mcm","clk":"1010103711","pt":1580649192199,"mc":[{"id":"1.168223927","rc":[{"batl":[[0,1.68,38.65],[1,1.71,7.57],[2,1.72,3.36]],"ltp":1.64,"tv":385.47,"id":8257852}]}]}
{"op":"mcm","clk":"1010221703","pt":1580649937927,"mc":[{"id":"1.168223927","rc":[{"batb":[[2,1.6,74.97]],"ltp":1.64,"tv":385.47,"id":8257852}]}]}
{"op":"mcm","clk":"1010247196","pt":1580650112546,"mc":[{"id":"1.168223927","rc":[{"batl":[[0,1.71,7.57],[1,1.72,3.36],[2,1.8,16.8]],"ltp":1.64,"tv":385.47,"id":8257852}]}]}
{"op":"mcm","clk":"1010248129","pt":1580650118687,"mc":[{"id":"1.168223927","rc":[{"batl":[[0,1.68,38.65],[1,1.71,7.57],[2,1.72,3.36]],"ltp":1.64,"tv":385.47,"id":8257852}]}]}
{"op":"mcm","clk":"1010328629","pt":1580650591074,"mc":[{"id":"1.168223927","rc":[{"batb":[[2,2.2,197.51]],"ltp":2.38,"tv":181.9,"id":8444055},{"trd":[[1.68,289.47]],"batl":[[0,1.71,7.57],[1,1.72,3.36],[2,1.8,16.8]],"ltp":1.68,"tv":462.77,"id":8257852}],"tv":644.68}]}
{"op":"mcm","clk":"1010328833","pt":1580650592225,"mc":[{"id":"1.168223927","rc":[{"batb":[[2,2,37.86]],"ltp":2.38,"tv":181.9,"id":8444055}]}]}
{"op":"mcm","clk":"1010328949","pt":1580650592925,"mc":[{"id":"1.168223927","rc":[{"batb":[[2,2.12,211.62]],"ltp":2.38,"tv":181.9,"id":8444055},{"batb":[[1,1.63,448.65]],"ltp":1.68,"tv":462.77,"id":8257852}]}]}
{"op":"mcm","clk":"1010329696","pt":1580650597556,"mc":[{"id":"1.168223927","rc":[{"batb":[[1,2.12,211.62],[2,2,37.86]],"ltp":2.38,"tv":181.9,"id":8444055}]}]}
{"op":"mcm","clk":"1010330110","pt":1580650600269,"mc":[{"id":"1.168223927","rc":[{"trd":[[2.42,37.73]],"batb":[[0,2,37.86],[1,1.81,37.86],[2,1.71,37.86]],"batl":[[0,2.42,145.67],[1,2.62,21.85],[2,4.1,153.72]],"ltp":2.42,"tv":219.63,"id":8444055},{"batb":[[1,1.63,72.44]],"ltp":1.68,"tv":462.77,"id":8257852}],"tv":682.41}]}
{"op":"mcm","clk":"1010330272","pt":1580650601239,"mc":[{"id":"1.168223927","rc":[{"batb":[[0,2.3,32.01],[1,2.08,219.45],[2,2,37.86]],"batl":[[0,2.42,277.91]],"ltp":2.42,"tv":219.63,"id":8444055},{"trd":[[1.71,16.64]],"batb":[[0,1.7,7.23],[1,1.65,364.64],[2,1.64,48.31]],"batl":[[0,1.72,3.75],[1,1.8,16.8],[2,2,12.98]],"ltp":1.71,"tv":477.14,"id":8257852}],"tv":696.78}]}
{"op":"mcm","clk":"1010330330","pt":1580650601680,"mc":[{"id":"1.168223927","rc":[{"trd":[[1.7,14.46]],"batb":[[0,1.65,364.64],[1,1.64,48.31],[2,1.63,47.24]],"ltp":1.7,"tv":491.6,"id":8257852}],"tv":711.24}]}
{"op":"mcm","clk":"1010330919","pt":1580650605128,"mc":[{"id":"1.168223927","rc":[{"batl":[[0,2.42,13.75]],"ltp":2.42,"tv":219.63,"id":8444055},{"batl":[[0,1.72,3.36]],"ltp":1.7,"tv":491.6,"id":8257852}]}]}
{"op":"mcm","clk":"1010330972","pt":1580650605456,"mc":[{"id":"1.168223927","rc":[{"batl":[[0,2.62,21.85],[1,4.1,153.72],[2,95,15.9]],"ltp":2.42,"tv":219.63,"id":8444055}]}]}
{"op":"mcm","clk":"1010331273","pt":1580650607249,"mc":[{"id":"1.168223927","rc":[{"batl":[[0,1.71,15.14],[1,1.72,3.36],[2,1.8,16.8]],"ltp":1.7,"tv":491.6,"id":8257852}]}]}
{"op":"mcm","clk":"1010331729","pt":1580650610044,"mc":[{"id":"1.168223927","rc":[{"batl":[[0,1.71,7.57]],"ltp":1.7,"tv":491.6,"id":8257852}]}]}
{"op":"mcm","clk":"1010334751","pt":1580650628180,"mc":[{"id":"1.168223927","rc":[{"batl":[[0,1.71,15.14]],"ltp":1.7,"tv":491.6,"id":8257852}]}]}
{"op":"mcm","clk":"1010336441","pt":1580650639215,"mc":[{"id":"1.168223927","rc":[{"batb":[[1,1.63,47.24],[2,1.6,74.97]],"ltp":1.7,"tv":491.6,"id":8257852}]}]}
{"op":"mcm","clk":"1010336470","pt":1580650639424,"mc":[{"id":"1.168223927","rc":[{"batb":[[0,1.66,32.39],[1,1.65,364.64],[2,1.63,47.24]],"ltp":1.7,"tv":491.6,"id":8257852}]}]}
{"op":"mcm","clk":"1010339595","pt":1580650658430,"mc":[{"id":"1.168223927","rc":[{"batl":[[0,1.71,22.72]],"ltp":1.7,"tv":491.6,"id":8257852}]}]}
{"op":"mcm","clk":"1010339868","pt":1580650660344,"mc":[{"id":"1.168223927","rc":[{"batl":[[0,1.72,3.36],[1,1.8,16.8],[2,2,12.98]],"ltp":1.7,"tv":491.6,"id":8257852}]}]}
{"op":"mcm","clk":"1010343210","pt":1580650681565,"mc":[{"id":"1.168223927","rc":[{"batb":[[0,1.68,7.57],[1,1.66,32.39],[2,1.65,364.64]],"ltp":1.7,"tv":491.6,"id":8257852}]}]}
{"op":"mcm","clk":"1010363660","pt":1580650808252,"mc":[{"id":"1.168223927","rc":[{"batb":[[0,1.66,32.39],[1,1.65,364.64],[2,1.63,47.24]],"ltp":1.7,"tv":491.6,"id":8257852}]}]}
{"op":"mcm","clk":"1010363731","pt":1580650808672,"mc":[{"id":"1.168223927","rc":[{"batb":[[0,1.68,350.36],[1,1.66,32.39],[2,1.65,364.64]],"ltp":1.7,"tv":491.6,"id":8257852}]}]}
{"op":"mcm","clk":"1010390829","pt":1580650973097,"mc":[{"id":"1.168223927","rc":[{"trd":[[1.72,6.72]],"batb":[[0,1.72,3.13]],"batl":[[0,1.8,16.8],[1,2,12.98],[2,2.2,15.14]],"ltp":1.72,"tv":498.33,"id":8257852}],"tv":717.96}]}
{"op":"mcm","clk":"1010390969","pt":1580650973915,"mc":[{"id":"1.168223927","rc":[{"batb":[[0,1.66,32.39],[1,1.65,364.64],[2,1.63,47.24]],"batl":[[0,1.75,129.48],[1,1.8,16.8],[2,2,12.98]],"ltp":1.72,"tv":498.33,"id":8257852}]}]}
{"op":"mcm","clk":"1010391166","pt":1580650975108,"mc":[{"id":"1.168223927","rc":[{"batb":[[1,2.02,232.36]],"ltp":2.42,"tv":219.63,"id":8444055},{"batb":[[0,1.68,348.55],[1,1.66,32.39]],"batl":[[1,1.76,4.12],[2,1.8,16.8]],"ltp":1.72,"tv":498.33,"id":8257852}]}]}
{"op":"mcm","clk":"1010400928","pt":1580651033083,"mc":[{"id":"1.168223927","rc":[{"trd":[[1.75,258.96],[1.76,8.24]],"batb":[[0,1.76,1.99],[1,1.69,68.02],[2,1.68,348.55]],"batl":[[0,1.8,16.8],[1,2,12.98],[2,2.2,15.14]],"ltp":1.76,"tv":765.52,"id":8257852}],"tv":985.16}]}
{"op":"mcm","clk":"1010401096","pt":1580651034115,"mc":[{"id":"1.168223927","rc":[{"trd":[[2.3,64.02]],"batb":[[0,2.02,232.36],[1,2,37.86],[2,1.81,37.86]],"batl":[[0,2.3,163.63],[1,2.62,21.85],[2,4.1,153.72]],"ltp":2.3,"tv":283.65,"id":8444055},{"trd":[[1.76,12.22]],"batb":[[0,1.69,129.48],[1,1.68,348.55],[2,1.66,32.39]],"ltp":1.76,"tv":769.51,"id":8257852}],"tv":1053.16}]}
{"op":"mcm","clk":"1010401305","pt":1580651035268,"mc":[{"id":"1.168223927","rc":[{"batb":[[0,2.2,5.09],[1,2.18,37.25],[2,2,37.86]],"batl":[[1,2.46,4.55],[2,2.62,21.85]],"ltp":2.3,"tv":283.65,"id":8444055},{"batb":[[0,1.71,333.83],[1,1.7,45.62],[2,1.69,136.1]],"batl":[[1,1.84,6.46],[2,2,12.6]],"ltp":1.76,"tv":769.51,"id":8257852}]}]}
{"op":"mcm","clk":"1010401378","pt":1580651035793,"mc":[{"id":"1.168223927","rc":[{"batl":[[0,1.8,20.92]],"ltp":1.76,"tv":769.51,"id":8257852}]}]}
{"op":"mcm","clk":"1010401797","pt":1580651038180,"mc":[{"id":"1.168223927","rc":[{"batl":[[0,2.3,97.99]],"ltp":2.3,"tv":283.65,"id":8444055},{"batb":[[0,1.7,45.62],[1,1.69,136.1],[2,1.63,47.24]],"ltp":1.76,"tv":769.51,"id":8257852}]}]}
{"op":"mcm","clk":"1010401910","pt":1580651038801,"mc":[{"id":"1.168223927","rc":[{"batb":[[2,2.02,232.36]],"batl":[[0,2.46,4.55],[1,2.62,21.85],[2,4.1,153.72]],"ltp":2.3,"tv":283.65,"id":8444055},{"batb":[[1,1.69,479.6]],"ltp":1.76,"tv":769.51,"id":8257852}]}]}
{"op":"mcm","clk":"1010402460","pt":1580651042291,"mc":[{"id":"1.168223927","rc":[{"batl":[[0,1.76,7.57],[1,1.8,20.92],[2,1.84,6.46]],"ltp":1.76,"tv":769.51,"id":8257852}]}]}
{"op":"mcm","clk":"1010402894","pt":1580651045082,"mc":[{"id":"1.168223927","rc":[{"batb":[[0,1.71,331.19],[1,1.7,45.62],[2,1.69,479.6]],"ltp":1.76,"tv":769.51,"id":8257852}]}]}
{"op":"mcm","clk":"1010403253","pt":1580651047122,"mc":[{"id":"1.168223927","rc":[{"trd":[[1.76,27.36]],"batb":[[0,1.76,2.93]],"batl":[[0,1.8,20.92],[1,1.84,6.46],[2,2,12.6]],"ltp":1.76,"tv":784.65,"id":8257852}],"tv":1068.31}]}
{"op":"mcm","clk":"1010403354","pt":1580651047807,"mc":[{"id":"1.168223927","rc":[{"batb":[[1,1.75,7.62],[2,1.7,45.62]],"ltp":1.76,"tv":784.65,"id":8257852}]}]}
{"op":"mcm","clk":"1010403577","pt":1580651049207,"mc":[{"id":"1.168223927","rc":[{"batb":[[2,2,37.86]],"ltp":2.3,"tv":283.65,"id":8444055},{"batb":[[2,1.72,329.18]],"ltp":1.76,"tv":784.65,"id":8257852}]}]}
{"op":"mcm","clk":"1010403891","pt":1580651051231,"mc":[{"id":"1.168223927","rc":[{"trd":[[1.76,33.22]],"batb":[[0,1.75,7.62],[1,1.72,329.18],[2,1.7,45.62]],"batl":[[0,1.76,4.64],[1,1.8,20.92],[2,1.84,6.46]],"ltp":1.76,"tv":790.51,"id":8257852}],"tv":1074.17}]}
{"op":"mcm","clk":"1010404164","pt":1580651052997,"mc":[{"id":"1.168223927","rc":[{"batb":[[2,2.02,232.36]],"ltp":2.3,"tv":283.65,"id":8444055},{"batb":[[0,1.75,10.56],[1,1.7,45.62],[2,1.69,136.1]],"ltp":1.76,"tv":790.51,"id":8257852}]}]}
{"op":"mcm","clk":"1010404266","pt":1580651053589,"mc":[{"id":"1.168223927","rc":[{"batl":[[0,1.78,4.64]],"ltp":1.76,"tv":790.51,"id":8257852}]}]}
{"op":"mcm","clk":"1010404413","pt":1580651054711,"mc":[{"id":"1.168223927","rc":[{"batb":[[0,2.22,24.24],[1,2.2,5.09]],"ltp":2.3,"tv":283.65,"id":8444055},{"trd":[[1.75,276.42]],"batb":[[0,1.75,1.83]],"ltp":1.75,"tv":807.97,"id":8257852}],"tv":1091.63}]}
{"op":"mcm","clk":"1010404918","pt":1580651057939,"mc":[{"id":"1.168223927","rc":[{"batl":[[0,1.76,7.57],[1,1.78,4.64],[2,1.8,20.92]],"ltp":1.75,"tv":807.97,"id":8257852}]}]}
{"op":"mcm","clk":"1010405283","pt":1580651060215,"mc":[{"id":"1.168223927","rc":[{"trd":[[1.76,48.37]],"batb":[[0,1.76,62.63],[1,1.75,6.04],[2,1.7,45.62]],"batl":[[0,1.78,4.64],[1,1.8,20.92],[2,1.84,6.46]],"ltp":1.76,"tv":823.11,"id":8257852}],"tv":1106.77}]}
{"op":"mcm","clk":"1010405467","pt":1580651061016,"mc":[{"id":"1.168223927","rc":[{"batb":[[2,2,37.86]],"ltp":2.3,"tv":283.65,"id":8444055},{"batb":[[1,1.75,9.45]],"ltp":1.76,"tv":823.11,"id":8257852}]}]}
{"op":"mcm","clk":"1010405660","pt":1580651062225,"mc":[{"id":"1.168223927","rc":[{"batb":[[2,1.71,333.83]],"ltp":1.76,"tv":823.11,"id":8257852}]}]}
{"op":"mcm","clk":"1010406070","pt":1580651064920,"mc":[{"id":"1.168223927","rc":[{"batb":[[0,1.75,9.45],[1,1.71,333.83],[2,1.7,45.62]],"ltp":1.76,"tv":823.11,"id":8257852}]}]}
{"op":"mcm","clk":"1010406573","pt":1580651067925,"mc":[{"id":"1.168223927","rc":[{"batb":[[0,1.75,327.4]],"batl":[[0,1.79,4.64]],"ltp":1.76,"tv":823.11,"id":8257852}]}]}
{"op":"mcm","clk":"1010407650","pt":1580651074143,"mc":[{"id":"1.168223927","rc":[{"batl":[[0,1.79,12.21]],"ltp":1.76,"tv":823.11,"id":8257852}]}]}
{"op":"mcm","clk":"1010407810","pt":1580651075046,"mc":[{"id":"1.168223927","rc":[{"batl":[[0,1.78,7.57],[1,1.79,12.21],[2,1.8,20.92]],"ltp":1.76,"tv":823.11,"id":8257852}]}]}
{"op":"mcm","clk":"1010407940","pt":1580651075913,"mc":[{"id":"1.168223927","rc":[{"trd":[[1.75,356.42]],"batb":[[0,1.71,333.83],[1,1.7,45.62],[2,1.69,136.1]],"ltp":1.75,"tv":903.11,"id":8257852}],"tv":1186.77}]}
{"op":"mcm","clk":"1010408024","pt":1580651076441,"mc":[{"id":"1.168223927","rc":[{"batb":[[0,1.75,317.95],[1,1.71,333.83],[2,1.7,45.62]],"ltp":1.75,"tv":903.11,"id":8257852}]}]}
{"op":"mcm","clk":"1010408679","pt":1580651080259,"mc":[{"id":"1.168223927","rc":[{"batb":[[0,1.71,333.83],[1,1.7,45.62],[2,1.69,136.1]],"batl":[[0,1.8,20.92],[1,1.84,6.46],[2,2,12.6]],"ltp":1.75,"tv":903.11,"id":8257852}]}]}
{"op":"mcm","clk":"1010408755","pt":1580651080628,"mc":[{"id":"1.168223927","rc":[{"batl":[[0,1.77,7.57],[1,1.8,20.92],[2,1.84,6.46]],"ltp":1.75,"tv":903.11,"id":8257852}]}]}
{"op":"mcm","clk":"1010409048","pt":1580651082136,"mc":[{"id":"1.168223927","rc":[{"trd":[[1.77,15.15],[1.8,508.22]],"batb":[[0,1.8,181.47],[1,1.78,7.33],[2,1.76,7.62]],"batl":[[0,1.84,6.46],[1,2,12.6],[2,2.2,15.14]],"ltp":1.8,"tv":1426.48,"id":8257852}],"tv":1710.14}]}
{"op":"mcm","clk":"1010409225","pt":1580651083168,"mc":[{"id":"1.168223927","rc":[{"batl":[[0,1.84,10.58]],"ltp":1.8,"tv":1426.48,"id":8257852}]}]}
{"op":"mcm","clk":"1010409578","pt":1580651085248,"mc":[{"id":"1.168223927","rc":[{"trd":[[2.22,11.77]],"batb":[[0,2.22,18.35]],"ltp":2.22,"tv":295.42,"id":8444055},{"batb":[[1,1.76,7.62],[2,1.74,320.29]],"ltp":1.8,"tv":1426.48,"id":8257852}],"tv":1721.91}]}
{"op":"mcm","clk":"1010409733","pt":1580651086231,"mc":[{"id":"1.168223927","rc":[{"trd":[[1.8,603.15]],"batb":[[0,1.76,7.62],[1,1.71,46.01],[2,1.69,195.05]],"batl":[[0,1.8,168.72],[1,1.84,10.58],[2,2,12.6]],"ltp":1.8,"tv":1521.41,"id":8257852}],"tv":1816.84}]}
{"op":"mcm","clk":"1010409889","pt":1580651087159,"mc":[{"id":"1.168223927","rc":[{"trd":[[1.79,15.24]],"batb":[[1,1.71,379.83]],"ltp":1.79,"tv":1536.64,"id":8257852}],"tv":1832.07}]}
{"op":"mcm","clk":"1010410538","pt":1580651091080,"mc":[{"id":"1.168223927","rc":[{"batb":[[0,1.76,322.35]],"ltp":1.79,"tv":1536.64,"id":8257852}]}]}
{"op":"mcm","clk":"1010410681","pt":1580651091883,"mc":[{"id":"1.168223927","rc":[{"batb":[[1,1.71,46.01]],"ltp":1.79,"tv":1536.64,"id":8257852}]}]}
{"op":"mcm","clk":"1010410803","pt":1580651092440,"mc":[{"id":"1.168223927","rc":[{"batb":[[1,1.74,320.29],[2,1.71,46.01]],"ltp":1.79,"tv":1536.64,"id":8257852}]}]}
{"op":"mcm","clk":"1010411099","pt":1580651094160,"mc":[{"id":"1.168223927","rc":[{"batb":[[1,1.71,46.01],[2,1.69,195.05]],"ltp":1.79,"tv":1536.64,"id":8257852}]}]}
{"op":"mcm","clk":"1010411214","pt":1580651094853,"mc":[{"id":"1.168223927","rc":[{"batb":[[0,1.76,314.73],[1,1.71,379.83]],"ltp":1.79,"tv":1536.64,"id":8257852}]}]}
{"op":"mcm","clk":"1010411403","pt":1580651095981,"mc":[{"id":"1.168223927","rc":[{"batb":[[0,1.77,7.56],[1,1.76,314.73],[2,1.71,379.83]],"ltp":1.79,"tv":1536.64,"id":8257852}]}]}
{"op":"mcm","clk":"1010411602","pt":1580651097177,"mc":[{"id":"1.168223927","rc":[{"batb":[[0,2.26,14.7],[1,2.22,18.35],[2,2.2,5.09]],"batl":[[0,2.4,12.66],[1,2.46,4.55],[2,2.62,21.85]],"ltp":2.22,"tv":295.42,"id":8444055},{"trd":[[1.77,27.38]],"batb":[[0,1.77,1.44],[2,1.72,19.34]],"batl":[[0,1.8,185.6]],"ltp":1.77,"tv":1548.88,"id":8257852}],"tv":1844.31}]}
{"op":"mcm","clk":"1010411695","pt":1580651097679,"mc":[{"id":"1.168223927","rc":[{"batb":[[0,2.22,18.35],[1,2,37.86],[2,1.98,241.85]],"batl":[[0,2.62,21.85],[1,4.1,153.72],[2,95,15.9]],"ltp":2.22,"tv":295.42,"id":8444055},{"batb":[[2,1.71,379.83]],"batl":[[0,1.84,4.5],[1,2,12.6],[2,2.2,15.14]],"ltp":1.77,"tv":1548.88,"id":8257852}]}]}
{"op":"mcm","clk":"1010411853","pt":1580651098578,"mc":[{"id":"1.168223927","rc":[{"batl":[[0,1.79,7.57],[1,1.84,4.5],[2,2,12.6]],"ltp":1.77,"tv":1548.88,"id":8257852}]}]}
{"op":"mcm","clk":"1010412115","pt":1580651100056,"mc":[{"id":"1.168223927","rc":[{"batb":[[1,1.71,379.83],[2,1.69,188.42]],"batl":[[1,1.81,7.95],[2,1.84,4.12]],"ltp":1.77,"tv":1548.88,"id":8257852}]}]}
{"op":"mcm","clk":"1010412452","pt":1580651101883,"mc":[{"id":"1.168223927","rc":[{"batb":[[2,1.81,37.86]],"ltp":2.22,"tv":295.42,"id":8444055},{"batb":[[1,1.71,46.01]],"batl":[[0,1.81,7.95],[1,1.84,4.12],[2,1.85,7.57]],"ltp":1.77,"tv":1548.88,"id":8257852}]}]}
{"op":"mcm","clk":"1010412551","pt":1580651102384,"mc":[{"id":"1.168223927","rc":[{"batb":[[1,2.04,227.9],[2,2,37.86]],"ltp":2.22,"tv":295.42,"id":8444055}]}]}
{"op":"mcm","clk":"1010413342","pt":1580651106093,"mc":[{"id":"1.168223927","rc":[{"batb":[[1,2,37.86],[2,1.81,37.86]],"ltp":2.22,"tv":295.42,"id":8444055},{"batl":[[0,1.84,4.5],[1,1.85,7.57],[2,2,12.6]],"ltp":1.77,"tv":1548.88,"id":8257852}]}]}
{"op":"mcm","clk":"1010413454","pt":1580651106687,"mc":[{"id":"1.168223927","rc":[{"batb":[[1,2.06,223.6],[2,2,37.86]],"ltp":2.22,"tv":295.42,"id":8444055},{"batl":[[1,2,12.6],[2,2.2,15.14]],"ltp":1.77,"tv":1548.88,"id":8257852}]}]}
{"op":"mcm","clk":"1010413674","pt":1580651107891,"mc":[{"id":"1.168223927","rc":[{"batb":[[0,1.77,9.01]],"ltp":1.77,"tv":1548.88,"id":8257852}]}]}
{"op":"mcm","clk":"1010414310","pt":1580651111187,"mc":[{"id":"1.168223927","rc":[{"batb":[[0,1.71,46.01],[1,1.69,188.42],[2,1.65,364.64]],"ltp":1.77,"tv":1548.88,"id":8257852}]}]}
{"op":"mcm","clk":"1010414352","pt":1580651111396,"mc":[{"id":"1.168223927","rc":[{"batb":[[0,1.75,9.01],[1,1.71,46.01],[2,1.69,188.42]],"ltp":1.77,"tv":1548.88,"id":8257852}]}]}
{"op":"mcm","clk":"1010415251","pt":1580651116240,"mc":[{"id":"1.168223927","rc":[{"batb":[[1,2.02,232.36]],"ltp":2.22,"tv":295.42,"id":8444055}]}]}
{"op":"mcm","clk":"1010416930","pt":1580651126042,"mc":[{"id":"1.168223927","rc":[{"batb":[[1,2,274.88],[2,1.81,37.86]],"ltp":2.22,"tv":295.42,"id":8444055},{"batb":[[0,1.72,7.57],[2,1.7,338.59]],"ltp":1.77,"tv":1548.88,"id":8257852}]}]}
{"op":"mcm","clk":"1010417945","pt":1580651132134,"mc":[{"id":"1.168223927","rc":[{"batb":[[1,2.02,15.04],[2,2,274.88]],"batl":[[0,2.44,12.46],[1,2.62,21.85],[2,4.1,153.72]],"ltp":2.22,"tv":295.42,"id":8444055},{"batb":[[2,1.7,356.46]],"batl":[[1,1.98,15.35],[2,2,12.6]],"ltp":1.77,"tv":1548.88,"id":8257852}]}]}
{"op":"mcm","clk":"1010419468","pt":1580651141041,"mc":[{"id":"1.168223927","rc":[{"batb":[[2,2,37.86]],"ltp":2.22,"tv":295.42,"id":8444055},{"batb":[[2,1.7,17.87]],"ltp":1.77,"tv":1548.88,"id":8257852}]}]}
{"op":"mcm","clk":"1010419577","pt":1580651141645,"mc":[{"id":"1.168223927","rc":[{"batb":[[0,1.74,320.29],[1,1.72,7.57],[2,1.71,46.01]],"ltp":1.77,"tv":1548.88,"id":8257852}]}]}
{"op":"mcm","clk":"1010419808","pt":1580651142940,"mc":[{"id":"1.168223927","rc":[{"batb":[[0,1.76,310.73],[1,1.74,320.29],[2,1.72,7.57]],"ltp":1.77,"tv":1548.88,"id":8257852}]}]}
{"op":"mcm","clk":"1010420030","pt":1580651144228,"mc":[{"id":"1.168223927","rc":[{"batl":[[1,2,12.6],[2,2.2,15.14]],"ltp":1.77,"tv":1548.88,"id":8257852}]}]}
{"op":"mcm","clk":"1010420047","pt":1580651144335,"mc":[{"id":"1.168223927","rc":[{"batl":[[1,1.99,15.35],[2,2,12.6]],"ltp":1.77,"tv":1548.88,"id":8257852}]}]}
{"op":"mcm","clk":"1010421123","pt":1580651150272,"mc":[{"id":"1.168223927","rc":[{"batb":[[1,1.72,7.57],[2,1.71,379.83]],"batl":[[0,1.8,7.57],[1,1.84,4.5],[2,1.99,15.35]],"ltp":1.77,"tv":1548.88,"id":8257852}]}]}
{"op":"mcm","clk":"1010421373","pt":1580651151181,"mc":[{"id":"1.168223927","rc":[{"trd":[[1.76,172.37]],"batb":[[0,1.72,7.57],[1,1.71,379.83],[2,1.7,17.87]],"ltp":1.76,"tv":1672.88,"id":8257852}],"tv":1968.31}]}
{"op":"mcm","clk":"1010421551","pt":1580651152090,"mc":[{"id":"1.168223927","rc":[{"batb":[[0,1.75,317.95],[1,1.72,7.57],[2,1.71,379.83]],"ltp":1.76,"tv":1672.88,"id":8257852}]}]}
{"op":"mcm","clk":"1010421717","pt":1580651153047,"mc":[{"id":"1.168223927","rc":[{"batb":[[2,1.71,46.01]],"ltp":1.76,"tv":1672.88,"id":8257852}]}]}
{"op":"mcm","clk":"1010421844","pt":1580651153846,"mc":[{"id":"1.168223927","rc":[{"batb":[[2,1.71,379.83]],"batl":[[0,1.84,4.5],[1,1.99,15.35],[2,2,12.6]],"ltp":1.76,"tv":1672.88,"id":8257852}]}]}
{"op":"mcm","clk":"1010422314","pt":1580651156488,"mc":[{"id":"1.168223927","rc":[{"batb":[[1,1.71,379.83],[2,1.7,17.87]],"ltp":1.76,"tv":1672.88,"id":8257852}]}]}
{"op":"mcm","clk":"1010422587","pt":1580651157913,"mc":[{"id":"1.168223927","rc":[{"batb":[[1,1.72,7.57],[2,1.71,379.83]],"ltp":1.76,"tv":1672.88,"id":8257852}]}]}
{"op":"mcm","clk":"1010422834","pt":1580651159277,"mc":[{"id":"1.168223927","rc":[{"batb":[[0,1.76,1.45],[1,1.75,317.95],[2,1.72,7.57]],"ltp":1.76,"tv":1672.88,"id":8257852}]}]}
{"op":"mcm","clk":"1010423828","pt":1580651164709,"mc":[{"id":"1.168223927","rc":[{"batb":[[2,1.74,320.29]],"ltp":1.76,"tv":1672.88,"id":8257852}]}]}
{"op":"mcm","clk":"1010424521","pt":1580651168491,"mc":[{"id":"1.168223927","rc":[{"batb":[[1,2.02,59.58]],"ltp":2.22,"tv":295.42,"id":8444055}]}]}
{"op":"mcm","clk":"1010425324","pt":1580651172615,"mc":[{"id":"1.168223927","rc":[{"batb":[[2,1.72,7.57]],"ltp":1.76,"tv":1672.88,"id":8257852}]}]}
{"op":"mcm","clk":"1010425677","pt":1580651174005,"mc":[{"id":"1.168223927","rc":[{"batb":[[2,1.72,336.76]],"ltp":1.76,"tv":1672.88,"id":8257852}]}]}
{"op":"mcm","clk":"1010426769","pt":1580651178704,"mc":[{"id":"1.168223927","rc":[{"batb":[[1,1.72,336.76],[2,1.71,46.01]],"ltp":1.76,"tv":1672.88,"id":8257852}]}]}
{"op":"mcm","clk":"1010427036","pt":1580651180095,"mc":[{"id":"1.168223927","rc":[{"trd":[[2.22,48.78]],"batb":[[0,2.02,59.58],[1,2,37.86],[2,1.96,246.89]],"batl":[[0,2.22,189.07],[1,2.44,12.46],[2,2.62,21.85]],"ltp":2.22,"tv":332.43,"id":8444055},{"trd":[[1.81,0.38]],"batb":[[2,1.71,83.87]],"batl":[[0,1.84,4.12]],"ltp":1.81,"tv":1673.26,"id":8257852}],"tv":2005.7}]}
{"op":"mcm","clk":"1010427216","pt":1580651180907,"mc":[{"id":"1.168223927","rc":[{"batb":[[2,1.93,254.85]],"batl":[[0,2.22,327.08]],"ltp":2.22,"tv":332.43,"id":8444055},{"batb":[[1,1.75,316.02],[2,1.72,7.57]],"ltp":1.81,"tv":1673.26,"id":8257852}]}]}
{"op":"mcm","clk":"1010427446","pt":1580651182087,"mc":[{"id":"1.168223927","rc":[{"batb":[[0,2.12,33.73],[1,2.02,59.58],[2,2,37.86]],"ltp":2.22,"tv":332.43,"id":8444055},{"batb":[[0,1.76,36.97]],"ltp":1.81,"tv":1673.26,"id":8257852}]}]}
{"op":"mcm","clk":"1010427975","pt":1580651184928,"mc":[{"id":"1.168223927","rc":[{"batl":[[0,2.44,12.46],[1,2.62,21.85],[2,4.1,153.72]],"ltp":2.22,"tv":332.43,"id":8444055}]}]}
{"op":"mcm","clk":"1010428989","pt":1580651190000,"mc":[{"id":"1.168223927","rc":[{"batb":[[0,1.76,347.7],[2,1.73,17.87]],"ltp":1.81,"tv":1673.26,"id":8257852}]}]}
{"op":"mcm","clk":"1010429315","pt":1580651191791,"mc":[{"id":"1.168223927","rc":[{"batb":[[1,1.73,17.87],[2,1.72,7.57]],"ltp":1.81,"tv":1673.26,"id":8257852}]}]}
{"op":"mcm","clk":"1010429561","pt":1580651193060,"mc":[{"id":"1.168223927","rc":[{"batb":[[1,1.74,320.29],[2,1.73,17.87]],"ltp":1.81,"tv":1673.26,"id":8257852}]}]}
{"op":"mcm","clk":"1010430826","pt":1580651199272,"mc":[{"id":"1.168223927","rc":[{"batl":[[0,2.62,21.85],[1,4.1,153.72],[2,95,15.9]],"ltp":2.22,"tv":332.43,"id":8444055},{"batl":[[1,2,12.6],[2,2.2,15.14]],"ltp":1.81,"tv":1673.26,"id":8257852}]}]}
{"op":"mcm","clk":"1010430999","pt":1580651200174,"mc":[{"id":"1.168223927","rc":[{"batl":[[0,2.3,12.46],[1,2.62,21.85],[2,4.1,153.72]],"ltp":2.22,"tv":332.43,"id":8444055},{"trd":[[1.76,312.36]],"batb":[[0,1.74,320.29],[1,1.73,17.87],[2,1.72,7.57]],"batl":[[1,1.98,15.35],[2,2,12.6]],"ltp":1.76,"tv":1813.26,"id":8257852}],"tv":2145.7}]}
{"op":"mcm","clk":"1010431070","pt":1580651200555,"mc":[{"id":"1.168223927","rc":[{"batl":[[0,2.3,250.28]],"ltp":2.22,"tv":332.43,"id":8444055}]}]}
{"op":"mcm","clk":"1010432289","pt":1580651206880,"mc":[{"id":"1.168223927","rc":[{"batb":[[0,2.14,32.93]],"ltp":2.22,"tv":332.43,"id":8444055},{"batb":[[0,1.77,21.5],[1,1.74,320.29],[2,1.73,17.87]],"ltp":1.76,"tv":1813.26,"id":8257852}]}]}
{"op":"mcm","clk":"1010432558","pt":1580651208174,"mc":[{"id":"1.168223927","rc":[{"batl":[[0,2.3,12.46]],"ltp":2.22,"tv":332.43,"id":8444055},{"batb":[[0,1.77,330.48]],"ltp":1.76,"tv":1813.26,"id":8257852}]}]}
{"op":"mcm","clk":"1010434077","pt":1580651216156,"mc":[{"id":"1.168223927","rc":[{"batb":[[0,1.77,21.5]],"ltp":1.76,"tv":1813.26,"id":8257852}]}]}
{"op":"mcm","clk":"1010434643","pt":1580651219211,"mc":[{"id":"1.168223927","rc":[{"batb":[[1,1.73,17.87],[2,1.72,336.76]],"ltp":1.76,"tv":1813.26,"id":8257852}]}]}
{"op":"mcm","clk":"1010435334","pt":1580651222915,"mc":[{"id":"1.168223927","rc":[{"trd":[[1.77,64.27]],"batb":[[0,1.77,3.06]],"batl":[[0,1.83,7.57],[1,1.84,4.12],[2,1.98,15.35]],"ltp":1.77,"tv":1850.14,"id":8257852}],"tv":2182.58}]}
{"op":"mcm","clk":"1010435597","pt":1580651224221,"mc":[{"id":"1.168223927","rc":[{"batb":[[0,2.22,20.97]],"batl":[[0,2.38,12.46]],"ltp":2.22,"tv":332.43,"id":8444055},{"batb":[[0,1.74,22.3]],"ltp":1.77,"tv":1850.14,"id":8257852}]}]}
{"op":"mcm","clk":"1010435647","pt":1580651224454,"mc":[{"id":"1.168223927","rc":[{"batb":[[0,1.75,315.15],[1,1.74,22.3],[2,1.73,17.87]],"ltp":1.77,"tv":1850.14,"id":8257852}]}]}
{"op":"mcm","clk":"1010436406","pt":1580651228422,"mc":[{"id":"1.168223927","rc":[{"batb":[[0,2.22,36.01],[1,2.02,44.54]],"ltp":2.22,"tv":332.43,"id":8444055}]}]}
{"op":"mcm","clk":"1010437650","pt":1580651234835,"mc":[{"id":"1.168223927","rc":[{"batl":[[0,1.84,4.12],[1,1.98,15.35],[2,2,12.6]],"ltp":1.77,"tv":1850.14,"id":8257852}]}]}
{"op":"mcm","clk":"1010437924","pt":1580651236138,"mc":[{"id":"1.168223927","rc":[{"batb":[[0,1.77,7.57]],"ltp":1.77,"tv":1850.14,"id":8257852}]}]}
{"op":"mcm","clk":"1010439052","pt":1580651242413,"mc":[{"id":"1.168223927","rc":[{"batb":[[0,2.22,20.97],[1,2.04,15.04],[2,2.02,44.54]],"ltp":2.22,"tv":332.43,"id":8444055}]}]}
{"op":"mcm","clk":"1010441310","pt":1580651254985,"mc":[{"id":"1.168223927","rc":[{"trd":[[1.77,76.56]],"batb":[[0,1.77,1.42],[1,1.75,7.57],[2,1.74,22.3]],"ltp":1.77,"tv":1862.44,"id":8257852}],"tv":2194.88}]}
{"op":"mcm","clk":"1010441973","pt":1580651259072,"mc":[{"id":"1.168223927","rc":[{"batb":[[0,1.74,22.3],[1,1.73,17.87],[2,1.72,329.18]],"ltp":1.77,"tv":1862.44,"id":8257852}]}]}
{"op":"mcm","clk":"1010442158","pt":1580651260185,"mc":[{"id":"1.168223927","rc":[{"batb":[[0,1.76,313.48],[1,1.74,22.3],[2,1.73,17.87]],"batl":[[0,1.79,6.08],[1,1.84,4.12],[2,1.98,15.35]],"ltp":1.77,"tv":1862.44,"id":8257852}]}]}
{"op":"mcm","clk":"1010442331","pt":1580651261198,"mc":[{"id":"1.168223927","rc":[{"trd":[[1.79,27.4]],"batb":[[0,1.79,272.69],[1,1.77,7.57],[2,1.74,22.3]],"batl":[[0,1.84,4.12],[1,1.98,15.35],[2,2,12.6]],"ltp":1.79,"tv":1874.6,"id":8257852}],"tv":2207.04}]}
{"op":"mcm","clk":"1010442930","pt":1580651264507,"mc":[{"id":"1.168223927","rc":[{"batb":[[0,1.79,290.56]],"ltp":1.79,"tv":1874.6,"id":8257852}]}]}
{"op":"mcm","clk":"1010443135","pt":1580651265803,"mc":[{"id":"1.168223927","rc":[{"batb":[[0,1.79,17.87]],"ltp":1.79,"tv":1874.6,"id":8257852}]}]}
{"op":"mcm","clk":"1010443636","pt":1580651268819,"mc":[{"id":"1.168223927","rc":[{"batb":[[1,1.74,22.3],[2,1.72,329.18]],"ltp":1.79,"tv":1874.6,"id":8257852}]}]}
{"op":"mcm","clk":"1010443748","pt":1580651269419,"mc":[{"id":"1.168223927","rc":[{"batb":[[0,1.74,22.3],[1,1.73,17.87]],"ltp":1.79,"tv":1874.6,"id":8257852}]}]}
{"op":"mcm","clk":"1010444058","pt":1580651271206,"mc":[{"id":"1.168223927","rc":[{"batb":[[0,1.77,15.14],[1,1.74,22.3],[2,1.73,17.87]],"ltp":1.79,"tv":1874.6,"id":8257852}]}]}
{"op":"mcm","clk":"1010444181","pt":1580651271905,"mc":[{"id":"1.168223927","rc":[{"batb":[[1,1.76,15.14],[2,1.74,22.3]],"ltp":1.79,"tv":1874.6,"id":8257852}]}]}
{"op":"mcm","clk":"1010444529","pt":1580651273920,"mc":[{"id":"1.168223927","rc":[{"batb":[[0,1.76,15.14],[1,1.74,22.3],[2,1.73,17.87]],"ltp":1.79,"tv":1874.6,"id":8257852}]}]}
{"op":"mcm","clk":"1010444754","pt":1580651275197,"mc":[{"id":"1.168223927","rc":[{"batb":[[0,1.76,328.62]],"ltp":1.79,"tv":1874.6,"id":8257852}]}]}
{"op":"mcm","clk":"1010444905","pt":1580651276115,"mc":[{"id":"1.168223927","rc":[{"trd":[[1.76,438.09],[1.77,106.85]],"batb":[[0,1.74,22.3],[1,1.73,17.87],[2,1.72,329.18]],"ltp":1.76,"tv":2030.61,"id":8257852}],"tv":2363.05}]}
{"op":"mcm","clk":"1010445431","pt":1580651279123,"mc":[{"id":"1.168223927","rc":[{"batl":[[0,1.8,7.57],[1,1.84,4.12],[2,1.98,15.35]],"ltp":1.76,"tv":2030.61,"id":8257852}]}]}
{"op":"mcm","clk":"1010445481","pt":1580651279389,"mc":[{"id":"1.168223927","rc":[{"batb":[[0,1.75,315.15],[1,1.74,22.3],[2,1.73,17.87]],"ltp":1.76,"tv":2030.61,"id":8257852}]}]}
{"op":"mcm","clk":"1010445708","pt":1580651280721,"mc":[{"id":"1.168223927","rc":[{"batl":[[0,1.79,7.57],[1,1.8,7.57],[2,1.84,4.12]],"ltp":1.76,"tv":2030.61,"id":8257852}]}]}
{"op":"mcm","clk":"1010445902","pt":1580651281711,"mc":[{"id":"1.168223927","rc":[{"trd":[[1.79,42.54],[1.8,617.52]],"batb":[[0,1.79,433.25],[1,1.75,315.15],[2,1.74,22.3]],"batl":[[0,1.84,4.51],[1,1.98,15.35],[2,2,12.6]],"ltp":1.8,"tv":2060.13,"id":8257852}],"tv":2392.57}]}
{"op":"mcm","clk":"1010446018","pt":1580651282353,"mc":[{"id":"1.168223927","rc":[{"batb":[[1,1.74,22.3],[2,1.73,17.87]],"ltp":1.8,"tv":2060.13,"id":8257852}]}]}
{"op":"mcm","clk":"1010446241","pt":1580651283523,"mc":[{"id":"1.168223927","rc":[{"batl":[[0,1.8,7.96],[1,1.84,4.12],[2,1.98,15.35]],"ltp":1.8,"tv":2060.13,"id":8257852}]}]}
{"op":"mcm","clk":"1010446723","pt":1580651286211,"mc":[{"id":"1.168223927","rc":[{"trd":[[1.79,57.69]],"batb":[[0,1.74,22.3],[1,1.73,17.87],[2,1.72,329.18]],"ltp":1.79,"tv":2075.27,"id":8257852}],"tv":2407.71}]}
{"op":"mcm","clk":"1010446754","pt":1580651286478,"mc":[{"id":"1.168223927","rc":[{"batl":[[0,2.28,12.46]],"ltp":2.22,"tv":332.43,"id":8444055}]}]}
{"op":"mcm","clk":"1010446925","pt":1580651287416,"mc":[{"id":"1.168223927","rc":[{"batl":[[0,1.84,4.12],[1,1.98,15.35],[2,2,12.6]],"ltp":1.79,"tv":2075.27,"id":8257852}]}]}
{"op":"mcm","clk":"1010447174","pt":1580651288851,"mc":[{"id":"1.168223927","rc":[{"batl":[[0,1.8,7.46],[1,1.84,4.12],[2,1.98,15.35]],"ltp":1.79,"tv":2075.27,"id":8257852}]}]}
{"op":"mcm","clk":"1010447493","pt":1580651290709,"mc":[{"id":"1.168223927","rc":[{"batl":[[0,2.38,12.46]],"ltp":2.22,"tv":332.43,"id":8444055},{"batl":[[2,1.97,15.35]],"ltp":1.79,"tv":2075.27,"id":8257852}]}]}
{"op":"mcm","clk":"1010447599","pt":1580651291350,"mc":[{"id":"1.168223927","rc":[{"batb":[[0,1.75,315.15],[1,1.74,22.3],[2,1.73,17.87]],"ltp":1.79,"tv":2075.27,"id":8257852}]}]}
{"op":"mcm","clk":"1010448008","pt":1580651293516,"mc":[{"id":"1.168223927","rc":[{"batb":[[0,1.76,15.14],[1,1.75,315.15],[2,1.74,22.3]],"ltp":1.79,"tv":2075.27,"id":8257852}]}]}
{"op":"mcm","clk":"1010448714","pt":1580651297850,"mc":[{"id":"1.168223927","rc":[{"batb":[[0,1.77,15.14],[1,1.76,15.14],[2,1.75,315.15]],"ltp":1.79,"tv":2075.27,"id":8257852}]}]}
{"op":"mcm","clk":"1010448915","pt":1580651299042,"mc":[{"id":"1.168223927","rc":[{"trd":[[1.77,133.25]],"batb":[[0,1.77,9.52]],"ltp":1.77,"tv":2101.67,"id":8257852}],"tv":2434.11}]}
{"op":"mcm","clk":"1010449041","pt":1580651299840,"mc":[{"id":"1.168223927","rc":[{"batb":[[0,1.77,17.09]],"ltp":1.77,"tv":2101.67,"id":8257852}]}]}
{"op":"mcm","clk":"1010449456","pt":1580651302249,"mc":[{"id":"1.168223927","rc":[{"trd":[[1.79,72.83]],"batb":[[0,1.79,265.11],[1,1.77,17.09],[2,1.76,15.14]],"ltp":1.79,"tv":2116.82,"id":8257852}],"tv":2449.25}]}
{"op":"mcm","clk":"1010449476","pt":1580651302361,"mc":[{"id":"1.168223927","rc":[{"batb":[[0,1.79,433.25]],"ltp":1.79,"tv":2116.82,"id":8257852}]}]}
{"op":"mcm","clk":"1010449943","pt":1580651305236,"mc":[{"id":"1.168223927","rc":[{"trd":[[1.79,87.98]],"batb":[[0,1.79,425.68]],"batl":[[0,1.84,4.12],[1,1.97,15.35],[2,2,12.6]],"ltp":1.79,"tv":2131.96,"id":8257852}],"tv":2464.4}]}
{"op":"mcm","clk":"1010450223","pt":1580651306943,"mc":[{"id":"1.168223927","rc":[{"batb":[[0,1.77,17.09],[1,1.76,15.14],[2,1.75,315.15]],"ltp":1.79,"tv":2131.96,"id":8257852}]}]}
{"op":"mcm","clk":"1010450420","pt":1580651308065,"mc":[{"id":"1.168223927","rc":[{"batb":[[0,1.75,315.15],[1,1.74,22.3],[2,1.73,17.87]],"batl":[[1,1.98,15.35]],"ltp":1.79,"tv":2131.96,"id":8257852}]}]}
{"op":"mcm","clk":"1010450632","pt":1580651309260,"mc":[{"id":"1.168223927","rc":[{"batb":[[0,1.77,15.14],[1,1.75,315.15],[2,1.74,22.3]],"batl":[[0,1.8,5.38],[1,1.84,4.12],[2,1.98,15.35]],"ltp":1.79,"tv":2131.96,"id":8257852}]}]}
{"op":"mcm","clk":"1010450701","pt":1580651309652,"mc":[{"id":"1.168223927","rc":[{"batb":[[0,1.77,22.72],[1,1.74,22.3],[2,1.73,17.87]],"ltp":1.79,"tv":2131.96,"id":8257852}]}]}
{"op":"mcm","clk":"1010450965","pt":1580651311255,"mc":[{"id":"1.168223927","rc":[{"batb":[[1,1.76,7.57],[2,1.74,22.3]],"ltp":1.79,"tv":2131.96,"id":8257852}]}]}
{"op":"mcm","clk":"1010450992","pt":1580651311429,"mc":[{"id":"1.168223927","rc":[{"batb":[[1,2.2,15.04]],"ltp":2.22,"tv":332.43,"id":8444055},{"batb":[[1,1.76,15.14]],"ltp":1.79,"tv":2131.96,"id":8257852}]}]}
{"op":"mcm","clk":"1010451410","pt":1580651314137,"mc":[{"id":"1.168223927","rc":[{"batb":[[0,1.77,30.29]],"ltp":1.79,"tv":2131.96,"id":8257852}]}]}
{"op":"mcm","clk":"1010451764","pt":1580651316436,"mc":[{"id":"1.168223927","rc":[{"batb":[[0,1.77,37.86]],"ltp":1.79,"tv":2131.96,"id":8257852}]}]}
{"op":"mcm","clk":"1010452000","pt":1580651317942,"mc":[{"id":"1.168223927","rc":[{"batb":[[1,1.74,22.3],[2,1.73,17.87]],"ltp":1.79,"tv":2131.96,"id":8257852}]}]}
{"op":"mcm","clk":"1010452229","pt":1580651319270,"mc":[{"id":"1.168223927","rc":[{"trd":[[1.77,212.54]],"batb":[[0,1.77,5.79]],"ltp":1.77,"tv":2211.25,"id":8257852}],"tv":2543.69}]}
{"op":"mcm","clk":"1010452388","pt":1580651320176,"mc":[{"id":"1.168223927","rc":[{"batb":[[0,1.77,20.93]],"ltp":1.77,"tv":2211.25,"id":8257852}]}]}
{"op":"mcm","clk":"1010452835","pt":1580651323179,"mc":[{"id":"1.168223927","rc":[{"batl":[[0,1.79,15.14],[1,1.8,5.38],[2,1.84,4.12]],"ltp":1.77,"tv":2211.25,"id":8257852}]}]}
{"op":"mcm","clk":"1010453250","pt":1580651325651,"mc":[{"id":"1.168223927","rc":[{"batl":[[0,1.79,20.52],[1,1.84,4.12],[2,1.98,15.35]],"ltp":1.77,"tv":2211.25,"id":8257852}]}]}
{"op":"mcm","clk":"1010453485","pt":1580651327049,"mc":[{"id":"1.168223927","rc":[{"batb":[[0,1.75,20.93]],"ltp":1.77,"tv":2211.25,"id":8257852}]}]}
{"op":"mcm","clk":"1010454523","pt":1580651333770,"mc":[{"id":"1.168223927","rc":[{"batl":[[0,1.78,7.57],[1,1.79,20.52],[2,1.84,4.12]],"ltp":1.77,"tv":2211.25,"id":8257852}]}]}
{"op":"mcm","clk":"1010454660","pt":1580651334683,"mc":[{"id":"1.168223927","rc":[{"trd":[[1.78,15.15]],"batb":[[0,1.78,434.23],[1,1.75,20.93],[2,1.74,22.3]],"batl":[[0,1.79,20.52],[1,1.84,4.12],[2,1.98,15.35]],"ltp":1.78,"tv":2226.4,"id":8257852}],"tv":2558.83}]}
{"op":"mcm","clk":"1010454919","pt":1580651336498,"mc":[{"id":"1.168223927","rc":[{"trd":[[1.78,30.29]],"batb":[[0,1.78,426.65]],"ltp":1.78,"tv":2241.54,"id":8257852}],"tv":2573.98}]}
{"op":"mcm","clk":"1010455359","pt":1580651339171,"mc":[{"id":"1.168223927","rc":[{"batb":[[0,1.75,20.93],[1,1.74,22.3],[2,1.73,17.87]],"batl":[[0,1.84,4.12],[1,1.98,15.35],[2,2,12.6]],"ltp":1.78,"tv":2241.54,"id":8257852}]}]}
{"op":"mcm","clk":"1010455494","pt":1580651339977,"mc":[{"id":"1.168223927","rc":[{"batl":[[0,1.8,7.57],[1,1.84,4.12],[2,1.98,15.35]],"ltp":1.78,"tv":2241.54,"id":8257852}]}]}
{"op":"mcm","clk":"1010455705","pt":1580651341215,"mc":[{"id":"1.168223927","rc":[{"batb":[[1,2.02,44.54],[2,2,37.86]],"batl":[[0,2.62,21.85],[1,4.1,153.72],[2,95,15.9]],"ltp":2.22,"tv":332.43,"id":8444055},{"trd":[[1.76,473.35]],"batb":[[0,1.76,297.1],[1,1.75,20.93],[2,1.74,22.3]],"batl":[[2,2,12.6]],"ltp":1.76,"tv":2276.8,"id":8257852}],"tv":2609.24}]}
{"op":"mcm","clk":"1010455777","pt":1580651341597,"mc":[{"id":"1.168223927","rc":[{"batb":[[0,1.75,20.93],[1,1.74,22.3],[2,1.71,333.83]],"ltp":1.76,"tv":2276.8,"id":8257852}]}]}
{"op":"mcm","clk":"1010455941","pt":1580651342617,"mc":[{"id":"1.168223927","rc":[{"batl":[[0,1.84,4.12],[1,2,12.6],[2,2.2,15.14]],"ltp":1.76,"tv":2276.8,"id":8257852}]}]}
{"op":"mcm","clk":"1010456203","pt":1580651344186,"mc":[{"id":"1.168223927","rc":[{"batb":[[2,1.69,129.48]],"batl":[[0,1.78,7.57],[1,1.84,4.12],[2,2,12.6]],"ltp":1.76,"tv":2276.8,"id":8257852}]}]}
{"op":"mcm","clk":"1010456382","pt":1580651345106,"mc":[{"id":"1.168223927","rc":[{"batb":[[2,2,274.88]],"ltp":2.22,"tv":332.43,"id":8444055},{"trd":[[1.78,45.43]],"batb":[[2,1.7,406.81]],"batl":[[0,1.79,7.57]],"ltp":1.78,"tv":2291.94,"id":8257852}],"tv":2624.38}]}
{"op":"mcm","clk":"1010456627","pt":1580651346709,"mc":[{"id":"1.168223927","rc":[{"batl":[[0,1.79,15.14]],"ltp":1.78,"tv":2291.94,"id":8257852}]}]}
{"op":"mcm","clk":"1010457010","pt":1580651349104,"mc":[{"id":"1.168223927","rc":[{"trd":[[1.78,60.58]],"batl":[[0,1.84,4.12],[1,2,12.6],[2,2.2,15.14]],"ltp":1.78,"tv":2307.09,"id":8257852}],"tv":2639.52}]}
{"op":"mcm","clk":"1010457257","pt":1580651350733,"mc":[{"id":"1.168223927","rc":[{"batl":[[0,1.79,7.57],[1,1.84,4.12],[2,2,12.6]],"ltp":1.78,"tv":2307.09,"id":8257852}]}]}
{"op":"mcm","clk":"1010457354","pt":1580651351387,"mc":[{"id":"1.168223927","rc":[{"batb":[[1,2.2,13.81],[2,2.02,44.54]],"batl":[[0,2.42,12.56],[1,2.62,21.85],[2,4.1,153.72]],"ltp":2.22,"tv":332.43,"id":8444055},{"batb":[[2,1.71,17.77]],"batl":[[1,1.83,16.61],[2,1.84,4.12]],"ltp":1.78,"tv":2307.09,"id":8257852}]}]}
{"op":"mcm","clk":"1010457542","pt":1580651352620,"mc":[{"id":"1.168223927","rc":[{"batl":[[0,1.78,7.57],[1,1.79,7.57],[2,1.83,16.61]],"ltp":1.78,"tv":2307.09,"id":8257852}]}]}
{"op":"mcm","clk":"1010457926","pt":1580651355000,"mc":[{"id":"1.168223927","rc":[{"batl":[[1,1.83,16.61],[2,1.84,4.12]],"ltp":1.78,"tv":2307.09,"id":8257852}]}]}
{"op":"mcm","clk":"1010458080","pt":1580651355901,"mc":[{"id":"1.168223927","rc":[{"trd":[[2.28,5.91]],"batl":[[0,2.26,1009.53],[1,2.42,12.56],[2,2.62,21.85]],"ltp":2.28,"tv":338.35,"id":8444055},{"trd":[[1.78,68.15]],"batb":[[0,1.74,22.3],[1,1.71,17.77],[2,1.7,406.81]],"batl":[[0,1.83,16.61],[1,1.84,4.12],[2,2,12.6]],"ltp":1.78,"tv":2314.66,"id":8257852}],"tv":2653.01}]}
{"op":"mcm","clk":"1010458560","pt":1580651358825,"mc":[{"id":"1.168223927","rc":[{"trd":[[2.26,5.51]],"batl":[[0,2.26,1004.02]],"ltp":2.26,"tv":343.86,"id":8444055},{"trd":[[1.79,94.94]],"ltp":1.79,"tv":2321.62,"id":8257852}],"tv":2665.48}]}
{"op":"mcm","clk":"1010459062","pt":1580651362241,"mc":[{"id":"1.168223927","rc":[{"trd":[[2.26,167.51]],"batl":[[0,2.26,923.02]],"ltp":2.26,"tv":505.86,"id":8444055},{"batb":[[0,1.76,7.57],[1,1.75,7.57],[2,1.74,22.3]],"ltp":1.79,"tv":2321.62,"id":8257852}],"tv":2827.48}]}
{"op":"mcm","clk":"1010459322","pt":1580651363745,"mc":[{"id":"1.168223927","rc":[{"batb":[[1,2.04,13.81]],"ltp":2.26,"tv":505.86,"id":8444055},{"batb":[[0,1.76,30.29]],"batl":[[0,1.84,4.12],[1,1.98,16.61]],"ltp":1.79,"tv":2321.62,"id":8257852}]}]}
{"op":"mcm","clk":"1010460131","pt":1580651369046,"mc":[{"id":"1.168223927","rc":[{"batb":[[2,2.02,276.9]],"ltp":2.26,"tv":505.86,"id":8444055}]}]}
{"op":"mcm","clk":"1010460610","pt":1580651371831,"mc":[{"id":"1.168223927","rc":[{"batb":[[2,2.02,44.54]],"ltp":2.26,"tv":505.86,"id":8444055}]}]}
{"op":"mcm","clk":"1010460702","pt":1580651372467,"mc":[{"id":"1.168223927","rc":[{"batb":[[2,2.02,276.9]],"ltp":2.26,"tv":505.86,"id":8444055}]}]}
{"op":"mcm","clk":"1010461439","pt":1580651377171,"mc":[{"id":"1.168223927","rc":[{"batb":[[0,1.74,22.3],[1,1.71,17.77],[2,1.7,68.22]],"ltp":1.79,"tv":2321.62,"id":8257852}]}]}
{"op":"mcm","clk":"1010461661","pt":1580651378680,"mc":[{"id":"1.168223927","rc":[{"batb":[[0,1.76,7.57],[1,1.74,22.3],[2,1.71,17.77]],"ltp":1.79,"tv":2321.62,"id":8257852}]}]}
{"op":"mcm","clk":"1010462426","pt":1580651383261,"mc":[{"id":"1.168223927","rc":[{"trd":[[2.26,331.51]],"batl":[[0,2.26,841.02]],"ltp":2.26,"tv":669.86,"id":8444055},{"batb":[[0,1.79,3.8],[1,1.76,7.57],[2,1.74,22.3]],"ltp":1.79,"tv":2321.62,"id":8257852}],"tv":2991.48}]}
{"op":"mcm","clk":"1010462616","pt":1580651384500,"mc":[{"id":"1.168223927","rc":[{"batb":[[1,1.74,22.3],[2,1.71,17.77]],"ltp":1.79,"tv":2321.62,"id":8257852}]}]}
{"op":"mcm","clk":"1010463013","pt":1580651387283,"mc":[{"id":"1.168223927","rc":[{"trd":[[2.26,687.52]],"batl":[[0,2.26,663.02]],"ltp":2.26,"tv":1025.86,"id":8444055}],"tv":3347.49}]}
{"op":"mcm","clk":"1010463453","pt":1580651389766,"mc":[{"id":"1.168223927","rc":[{"batb":[[1,1.75,7.57],[2,1.74,22.3]],"ltp":1.79,"tv":2321.62,"id":8257852}]}]}
{"op":"mcm","clk":"1010463755","pt":1580651391654,"mc":[{"id":"1.168223927","rc":[{"batb":[[1,1.75,22.72]],"ltp":1.79,"tv":2321.62,"id":8257852}]}]}
{"op":"mcm","clk":"1010465370","pt":1580651401994,"mc":[{"id":"1.168223927","rc":[{"batb":[[1,2.04,241.71],[2,2.02,44.54]],"ltp":2.26,"tv":1025.86,"id":8444055}]}]}
{"op":"mcm","clk":"1010467461","pt":1580651415615,"mc":[{"id":"1.168223927","rc":[{"batl":[[1,2.62,21.85],[2,4.1,153.72]],"ltp":2.26,"tv":1025.86,"id":8444055},{"batb":[[0,1.79,21.57]],"batl":[[1,1.96,16.61]],"ltp":1.79,"tv":2321.62,"id":8257852}]}]}
{"op":"mcm","clk":"1010467559","pt":1580651416371,"mc":[{"id":"1.168223927","rc":[{"trd":[[2.26,1043.52]],"batl":[[0,2.26,485.01]],"ltp":2.26,"tv":1381.87,"id":8444055}],"tv":3703.49}]}
{"op":"mcm","clk":"1010471177","pt":1580651440028,"mc":[{"id":"1.168223927","rc":[{"trd":[[2.26,1481.43]],"batl":[[0,2.26,266.06]],"ltp":2.26,"tv":1819.77,"id":8444055},{"batb":[[1,1.74,22.3],[2,1.7,68.22]],"ltp":1.79,"tv":2321.62,"id":8257852}],"tv":4141.39}]}
{"op":"mcm","clk":"1010471223","pt":1580651440343,"mc":[{"id":"1.168223927","rc":[{"trd":[[2.26,1697.42]],"batl":[[0,2.26,158.06]],"ltp":2.26,"tv":2035.77,"id":8444055}],"tv":4357.39}]}
{"op":"mcm","clk":"1010477251","pt":1580651479312,"mc":[{"id":"1.168223927","rc":[{"trd":[[2.26,1714.9]],"batl":[[0,2.26,149.33]],"ltp":2.26,"tv":2053.25,"id":8444055}],"tv":4374.87}]}
{"op":"mcm","clk":"1010477429","pt":1580651480456,"mc":[{"id":"1.168223927","rc":[{"trd":[[2.26,1978.78]],"batl":[[0,2.26,17.39]],"ltp":2.26,"tv":2317.13,"id":8444055}],"tv":4638.75}]}
{"op":"mcm","clk":"1010477700","pt":1580651482187,"mc":[{"id":"1.168223927","rc":[{"batb":[[0,2.04,241.71],[1,2.02,44.54],[2,2,37.86]],"ltp":2.26,"tv":2317.13,"id":8444055},{"batb":[[1,1.7,68.22],[2,1.69,129.48]],"ltp":1.79,"tv":2321.62,"id":8257852}]}]}
{"op":"mcm","clk":"1010477729","pt":1580651482410,"mc":[{"id":"1.168223927","rc":[{"batb":[[0,2.14,38.8],[1,2.04,241.71],[2,2.02,44.54]],"ltp":2.26,"tv":2317.13,"id":8444055},{"batb":[[1,1.72,47.05],[2,1.7,68.22]],"ltp":1.79,"tv":2321.62,"id":8257852}]}]}
{"op":"mcm","clk":"1010479125","pt":1580651491952,"mc":[{"id":"1.168223927","rc":[{"batl":[[0,2.24,13.57],[1,2.26,17.39],[2,2.62,21.85]],"ltp":2.26,"tv":2317.13,"id":8444055},{"batb":[[0,1.8,17.77],[1,1.79,3.8],[2,1.72,47.05]],"ltp":1.79,"tv":2321.62,"id":8257852}]}]}
{"op":"mcm","clk":"1010481237","pt":1580651506054,"mc":[{"id":"1.168223927","rc":[{"batb":[[1,1.72,47.05],[2,1.7,68.22]],"ltp":1.79,"tv":2321.62,"id":8257852}]}]}
{"op":"mcm","clk":"1010481296","pt":1580651506474,"mc":[{"id":"1.168223927","rc":[{"trd":[[2.24,23.03]],"batl":[[0,2.24,2.06]],"ltp":2.24,"tv":2340.15,"id":8444055}],"tv":4661.78}]}
{"op":"mcm","clk":"1010481448","pt":1580651507646,"mc":[{"id":"1.168223927","rc":[{"batb":[[1,2.04,240.53]],"ltp":2.24,"tv":2340.15,"id":8444055}]}]}
{"op":"mcm","clk":"1010482896","pt":1580651517783,"mc":[{"id":"1.168223927","rc":[{"batl":[[1,1.87,16.61]],"ltp":1.79,"tv":2321.62,"id":8257852}]}]}
{"op":"mcm","clk":"1010483222","pt":1580651519951,"mc":[{"id":"1.168223927","rc":[{"batb":[[0,1.81,56],[1,1.8,17.77],[2,1.72,47.05]],"ltp":1.79,"tv":2321.62,"id":8257852}]}]}
{"op":"mcm","clk":"1010488059","pt":1580651551841,"mc":[{"id":"1.168223927","rc":[{"batb":[[1,2.04,227.9]],"ltp":2.24,"tv":2340.15,"id":8444055},{"batb":[[0,1.82,17.77],[1,1.81,56]],"ltp":1.79,"tv":2321.62,"id":8257852}]}]}
{"op":"mcm","clk":"1010488205","pt":1580651552627,"mc":[{"id":"1.168223927","rc":[{"trd":[[1.81,64.2],[1.82,35.56]],"batb":[[0,1.81,24.09],[1,1.72,47.05],[2,1.71,37.86]],"ltp":1.81,"tv":2421.0,"id":8257852}],"tv":4761.16}]}
{"op":"mcm","clk":"1010489892","pt":1580651564631,"mc":[{"id":"1.168223927","rc":[{"batl":[[0,2.26,17.39],[1,2.62,21.85],[2,4.1,153.72]],"ltp":2.24,"tv":2340.15,"id":8444055},{"batl":[[1,1.87,16.25]],"ltp":1.81,"tv":2421.0,"id":8257852}]}]}
{"op":"mcm","clk":"1010491219","pt":1580651573645,"mc":[{"id":"1.168223927","rc":[{"batb":[[0,2.18,11.83],[1,2.14,38.8],[2,2.04,227.9]],"ltp":2.24,"tv":2340.15,"id":8444055}]}]}
{"op":"mcm","clk":"1010491366","pt":1580651574679,"mc":[{"id":"1.168223927","rc":[{"trd":[[1.81,106.82]],"batb":[[0,1.81,2.78]],"ltp":1.81,"tv":2463.62,"id":8257852}],"tv":4803.78}]}
{"op":"mcm","clk":"1010491530","pt":1580651575666,"mc":[{"id":"1.168223927","rc":[{"batl":[[0,2.62,21.85],[1,4.1,153.72],[2,95,15.9]],"ltp":2.24,"tv":2340.15,"id":8444055}]}]}
{"op":"mcm","clk":"1010493669","pt":1580651588977,"mc":[{"id":"1.168223927","rc":[{"trd":[[1.81,112.38]],"batb":[[0,1.72,47.05],[1,1.71,37.86],[2,1.7,68.22]],"batl":[[0,1.81,4.79],[1,1.84,4.12],[2,1.87,16.25]],"ltp":1.81,"tv":2469.18,"id":8257852}],"tv":4809.34}]}
{"op":"mcm","clk":"1010493880","pt":1580651590272,"mc":[{"id":"1.168223927","rc":[{"batb":[[1,1.7,68.22],[2,1.69,129.48]],"ltp":1.81,"tv":2469.18,"id":8257852}]}]}
{"op":"mcm","clk":"1010494019","pt":1580651591195,"mc":[{"id":"1.168223927","rc":[{"trd":[[1.78,73.79]],"ltp":1.78,"tv":2474.82,"id":8257852}],"tv":4814.98}]}
{"op":"mcm","clk":"1010494625","pt":1580651594777,"mc":[{"id":"1.168223927","rc":[{"batb":[[0,2.16,11.83]],"ltp":2.24,"tv":2340.15,"id":8444055}]}]}
{"op":"mcm","clk":"1010494852","pt":1580651596686,"mc":[{"id":"1.168223927","rc":[{"batb":[[0,1.73,7.57],[1,1.72,47.05],[2,1.7,68.22]],"ltp":1.78,"tv":2474.82,"id":8257852}]}]}
{"op":"mcm","clk":"1010495145","pt":1580651598818,"mc":[{"id":"1.168223927","rc":[{"batl":[[0,1.81,12.37]],"ltp":1.78,"tv":2474.82,"id":8257852}]}]}
{"op":"mcm","clk":"1010495693","pt":1580651602708,"mc":[{"id":"1.168223927","rc":[{"batl":[[0,2.42,3.3],[1,2.62,21.85],[2,4.1,153.72]],"ltp":2.24,"tv":2340.15,"id":8444055}]}]}
{"op":"mcm","clk":"1010496737","pt":1580651609800,"mc":[{"id":"1.168223927","rc":[{"batl":[[0,1.8,16.25],[1,1.81,12.37],[2,1.84,4.12]],"ltp":1.78,"tv":2474.82,"id":8257852}]}]}
{"op":"mcm","clk":"1010497991","pt":1580651618917,"mc":[{"id":"1.168223927","rc":[{"batb":[[0,2.18,25.09],[1,2.16,11.83]],"ltp":2.24,"tv":2340.15,"id":8444055},{"batb":[[0,1.74,33.51],[1,1.73,7.57]],"ltp":1.78,"tv":2474.82,"id":8257852}]}]}
{"op":"mcm","clk":"1010498497","pt":1580651622682,"mc":[{"id":"1.168223927","rc":[{"batb":[[1,1.7,68.22],[2,1.69,129.48]],"ltp":1.78,"tv":2474.82,"id":8257852}]}]}
{"op":"mcm","clk":"1010498701","pt":1580651624014,"mc":[{"id":"1.168223927","rc":[{"batl":[[1,1.84,4.12],[2,2,12.6]],"ltp":1.78,"tv":2474.82,"id":8257852}]}]}
{"op":"mcm","clk":"1010499739","pt":1580651631949,"mc":[{"id":"1.168223927","rc":[{"batb":[[0,2.2,11.83],[1,2.18,25.09]],"ltp":2.24,"tv":2340.15,"id":8444055},{"batl":[[0,1.83,16.25]],"ltp":1.78,"tv":2474.82,"id":8257852}]}]}
{"op":"mcm","clk":"1010502884","pt":1580651652877,"mc":[{"id":"1.168223927","rc":[{"trd":[[2.36,10.79]],"ltp":2.36,"tv":2346.82,"id":8444055},{"trd":[[1.74,9.05]],"batb":[[0,1.74,24.46]],"batl":[[0,1.82,7.57],[1,1.83,16.25],[2,1.84,4.12]],"ltp":1.74,"tv":2483.87,"id":8257852}],"tv":4830.7}]}
{"op":"mcm","clk":"1010503066","pt":1580651653990,"mc":[{"id":"1.168223927","rc":[{"batb":[[0,2.22,19.2],[1,2.2,11.83],[2,2.06,44.54]],"ltp":2.36,"tv":2346.82,"id":8444055},{"batb":[[0,1.71,45.03]],"ltp":1.74,"tv":2483.87,"id":8257852}]}]}
{"op":"mcm","clk":"1010503258","pt":1580651655168,"mc":[{"id":"1.168223927","rc":[{"batb":[[0,1.72,7.57],[1,1.71,45.03],[2,1.7,68.22]],"ltp":1.74,"tv":2483.87,"id":8257852}]}]}
{"op":"mcm","clk":"1010503471","pt":1580651656567,"mc":[{"id":"1.168223927","rc":[{"batb":[[0,1.72,15.14]],"ltp":1.74,"tv":2483.87,"id":8257852}]}]}
{"op":"mcm","clk":"1010503843","pt":1580651659084,"mc":[{"id":"1.168223927","rc":[{"batl":[[0,1.81,7.57],[1,1.82,7.57],[2,1.83,16.25]],"ltp":1.74,"tv":2483.87,"id":8257852}]}]}
{"op":"mcm","clk":"1010503902","pt":1580651659500,"mc":[{"id":"1.168223927","rc":[{"batb":[[0,1.72,36.18]],"ltp":1.74,"tv":2483.87,"id":8257852}]}]}
{"op":"mcm","clk":"1010504421","pt":1580651662658,"mc":[{"id":"1.168223927","rc":[{"batb":[[1,1.71,49.71]],"ltp":1.74,"tv":2483.87,"id":8257852}]}]}
{"op":"mcm","clk":"1010505187","pt":1580651667804,"mc":[{"id":"1.168223927","rc":[{"batb":[[0,2.24,11.83],[1,2.22,19.2]],"batl":[[0,2.4,3.3]],"ltp":2.36,"tv":2346.82,"id":8444055},{"batb":[[0,1.72,40.86],[1,1.71,45.03]],"batl":[[0,1.8,16.25],[1,1.81,7.57],[2,1.82,7.57]],"ltp":1.74,"tv":2483.87,"id":8257852}]}]}
{"op":"mcm","clk":"1010507833","pt":1580651686750,"mc":[{"id":"1.168223927","rc":[{"batb":[[0,2.24,11.51]],"ltp":2.36,"tv":2346.82,"id":8444055}]}]}
{"op":"mcm","clk":"1010508624","pt":1580651692761,"mc":[{"id":"1.168223927","rc":[{"batl":[[0,1.8,16.88]],"ltp":1.74,"tv":2483.87,"id":8257852}]}]}
{"op":"mcm","clk":"1010508890","pt":1580651694270,"mc":[{"id":"1.168223927","rc":[{"batl":[[2,1.84,4.12]],"ltp":1.74,"tv":2483.87,"id":8257852}]}]}
{"op":"mcm","clk":"1010508955","pt":1580651694770,"mc":[{"id":"1.168223927","rc":[{"batl":[[1,1.84,4.12],[2,2,12.6]],"ltp":1.74,"tv":2483.87,"id":8257852}]}]}
{"op":"mcm","clk":"1010509272","pt":1580651697269,"mc":[{"id":"1.168223927","rc":[{"batb":[[0,1.72,25.71]],"ltp":1.74,"tv":2483.87,"id":8257852}]}]}
{"op":"mcm","clk":"1010510502","pt":1580651706006,"mc":[{"id":"1.168223927","rc":[{"batb":[[0,2.22,19.2],[1,2.2,11.51]],"ltp":2.36,"tv":2346.82,"id":8444055}]}]}
{"op":"mcm","clk":"1010511624","pt":1580651714016,"mc":[{"id":"1.168223927","rc":[{"batl":[[0,1.84,4.12],[1,2,12.6],[2,2.2,15.14]],"ltp":1.74,"tv":2483.87,"id":8257852}]}]}
{"op":"mcm","clk":"1010513273","pt":1580651726918,"mc":[{"id":"1.168223927","rc":[{"batb":[[1,2.08,11.51]],"ltp":2.36,"tv":2346.82,"id":8444055}]}]}
{"op":"mcm","clk":"1010514751","pt":1580651737842,"mc":[{"id":"1.168223927","rc":[{"batl":[[1,1.94,15.67],[2,2,12.6]],"ltp":1.74,"tv":2483.87,"id":8257852}]}]}
{"op":"mcm","clk":"1010517657","pt":1580651758073,"mc":[{"id":"1.168223927","rc":[{"batb":[[0,2.18,32.16]],"ltp":2.36,"tv":2346.82,"id":8444055},{"batb":[[0,1.73,31.25],[1,1.72,25.71]],"ltp":1.74,"tv":2483.87,"id":8257852}]}]}
{"op":"mcm","clk":"1010518418","pt":1580651762969,"mc":[{"id":"1.168223927","rc":[{"batb":[[0,1.74,7.57],[1,1.73,31.25],[2,1.72,25.71]],"ltp":1.74,"tv":2483.87,"id":8257852}]}]}
{"op":"mcm","clk":"1010518774","pt":1580651765064,"mc":[{"id":"1.168223927","rc":[{"batl":[[0,1.82,7.57],[1,1.84,4.12],[2,1.94,15.67]],"ltp":1.74,"tv":2483.87,"id":8257852}]}]}
{"op":"mcm","clk":"1010519224","pt":1580651767971,"mc":[{"id":"1.168223927","rc":[{"batb":[[0,2.2,11.51],[1,2.18,32.16]],"batl":[[0,2.38,3.3]],"ltp":2.36,"tv":2346.82,"id":8444055},{"batb":[[1,1.73,35.92],[2,1.72,21.04]],"ltp":1.74,"tv":2483.87,"id":8257852}]}]}
{"op":"mcm","clk":"1010520167","pt":1580651774177,"mc":[{"id":"1.168223927","rc":[{"batb":[[2,1.71,21.04]],"ltp":1.74,"tv":2483.87,"id":8257852}]}]}
{"op":"mcm","clk":"1010520776","pt":1580651777993,"mc":[{"id":"1.168223927","rc":[{"batl":[[0,2.4,3.3]],"ltp":2.36,"tv":2346.82,"id":8444055},{"batb":[[1,1.73,31.25],[2,1.72,4.68]],"batl":[[0,1.81,15.67],[1,1.82,7.57],[2,1.84,4.12]],"ltp":1.74,"tv":2483.87,"id":8257852}]}]}
{"op":"mcm","clk":"1010521299","pt":1580651781488,"mc":[{"id":"1.168223927","rc":[{"batl":[[0,1.8,7.57],[1,1.81,15.67]],"ltp":1.74,"tv":2483.87,"id":8257852}]}]}
{"op":"mcm","clk":"1010525934","pt":1580651813484,"mc":[{"id":"1.168223927","rc":[{"batl":[[0,1.8,15.14]],"ltp":1.74,"tv":2483.87,"id":8257852}]}]}
{"op":"mcm","clk":"1010526436","pt":1580651817001,"mc":[{"id":"1.168223927","rc":[{"batb":[[0,1.74,15.14]],"ltp":1.74,"tv":2483.87,"id":8257852}]}]}
{"op":"mcm","clk":"1010526671","pt":1580651818512,"mc":[{"id":"1.168223927","rc":[{"batb":[[0,1.73,31.25],[1,1.72,4.68],[2,1.71,21.04]],"ltp":1.74,"tv":2483.87,"id":8257852}]}]}
{"op":"mcm","clk":"1010526866","pt":1580651819899,"mc":[{"id":"1.168223927","rc":[{"batl":[[0,1.81,15.67],[1,1.84,4.12],[2,2,12.6]],"ltp":1.74,"tv":2483.87,"id":8257852}]}]}
{"op":"mcm","clk":"1010528353","pt":1580651829919,"mc":[{"id":"1.168223927","rc":[{"batb":[[0,2.18,32.16],[1,2.06,44.54],[2,2.04,227.9]],"batl":[[0,2.62,21.85],[1,4.1,153.72],[2,95,15.9]],"ltp":2.36,"tv":2346.82,"id":8444055},{"batb":[[1,1.71,21.04],[2,1.7,68.22]],"batl":[[0,1.84,4.12],[1,2,12.6],[2,2.2,15.14]],"ltp":1.74,"tv":2483.87,"id":8257852}]}]}
{"op":"mcm","clk":"1010533005","pt":1580651859973,"mc":[{"id":"1.168223927","rc":[{"batb":[[0,2.2,11.72],[1,2.18,32.16],[2,2.06,44.54]],"batl":[[0,2.4,3.58],[1,2.62,21.85],[2,4.1,153.72]],"ltp":2.36,"tv":2346.82,"id":8444055},{"batb":[[1,1.72,5.01],[2,1.71,21.04]],"batl":[[0,1.84,20.64]],"ltp":1.74,"tv":2483.87,"id":8257852}]}]}
{"op":"mcm","clk":"1010541464","pt":1580651912108,"mc":[{"id":"1.168223927","rc":[{"batb":[[0,2.22,19.2],[1,2.2,11.72]],"ltp":2.36,"tv":2346.82,"id":8444055}]}]}
{"op":"mcm","clk":"1010543492","pt":1580651925149,"mc":[{"id":"1.168223927","rc":[{"batb":[[0,2.24,11.72],[1,2.22,19.2]],"ltp":2.36,"tv":2346.82,"id":8444055}]}]}
{"op":"mcm","clk":"1010543542","pt":1580651925460,"mc":[{"id":"1.168223927","rc":[{"batl":[[0,1.81,16.52],[1,1.84,4.12],[2,2,12.6]],"ltp":1.74,"tv":2483.87,"id":8257852}]}]}
{"op":"mcm","clk":"1010546308","pt":1580651942986,"mc":[{"id":"1.168223927","rc":[{"batb":[[0,2.24,11.51]],"ltp":2.36,"tv":2346.82,"id":8444055}]}]}
{"op":"mcm","clk":"1010547328","pt":1580651948970,"mc":[{"id":"1.168223927","rc":[{"batl":[[0,1.81,16.79]],"ltp":1.74,"tv":2483.87,"id":8257852}]}]}
{"op":"mcm","clk":"1010552717","pt":1580651984182,"mc":[{"id":"1.168223927","rc":[{"batl":[[0,1.8,7.57],[1,1.81,16.79],[2,1.84,4.12]],"ltp":1.74,"tv":2483.87,"id":8257852}]}]}
{"op":"mcm","clk":"1010554639","pt":1580651996238,"mc":[{"id":"1.168223927","rc":[{"batb":[[0,2.26,11.51]],"ltp":2.36,"tv":2346.82,"id":8444055},{"batl":[[0,1.79,16.98],[1,1.8,7.57]],"ltp":1.74,"tv":2483.87,"id":8257852}]}]}
{"op":"mcm","clk":"1010554654","pt":1580651996305,"mc":[{"id":"1.168223927","rc":[{"batl":[[0,1.8,7.57],[1,1.84,4.12],[2,2,12.6]],"ltp":1.74,"tv":2483.87,"id":8257852}]}]}
{"op":"mcm","clk":"1010556715","pt":1580652006215,"mc":[{"id":"1.168223927","rc":[{"batb":[[0,1.73,38.1]],"ltp":1.74,"tv":2483.87,"id":8257852}]}]}
{"op":"mcm","clk":"1010556770","pt":1580652006535,"mc":[{"id":"1.168223927","rc":[{"batb":[[2,2.2,21]],"ltp":2.36,"tv":2346.82,"id":8444055}]}]}
{"op":"mcm","clk":"1010557229","pt":1580652008648,"mc":[{"id":"1.168223927","rc":[{"batb":[[0,1.73,106.32]],"ltp":1.74,"tv":2483.87,"id":8257852}]}]}
{"op":"mcm","clk":"1010558718","pt":1580652015527,"mc":[{"id":"1.168223927","rc":[{"batb":[[0,1.73,131.67]],"ltp":1.74,"tv":2483.87,"id":8257852}]}]}
{"op":"mcm","clk":"1010558844","pt":1580652016337,"mc":[{"id":"1.168223927","rc":[{"batl":[[0,1.8,15.14]],"ltp":1.74,"tv":2483.87,"id":8257852}]}]}
{"op":"mcm","clk":"1010559091","pt":1580652017942,"mc":[{"id":"1.168223927","rc":[{"batl":[[0,1.84,4.12],[1,2,12.6],[2,2.2,15.14]],"ltp":1.74,"tv":2483.87,"id":8257852}]}]}
{"op":"mcm","clk":"1010559178","pt":1580652018570,"mc":[{"id":"1.168223927","rc":[{"batb":[[2,2.18,21.36]],"ltp":2.36,"tv":2346.82,"id":8444055},{"batb":[[2,1.71,56.53]],"ltp":1.74,"tv":2483.87,"id":8257852}]}]}
{"op":"mcm","clk":"1010559589","pt":1580652021054,"mc":[{"id":"1.168223927","rc":[{"batb":[[0,2.22,19.2],[1,2.18,21.36],[2,2.06,44.54]],"batl":[[0,2.62,21.85],[1,4.1,153.72],[2,95,15.9]],"ltp":2.36,"tv":2346.82,"id":8444055},{"batb":[[1,1.71,56.53],[2,1.7,36.01]],"batl":[[0,1.81,16.79],[1,1.84,4.12],[2,2,12.6]],"ltp":1.74,"tv":2483.87,"id":8257852}]}]}
{"op":"mcm","clk":"1010559643","pt":1580652021404,"mc":[{"id":"1.168223927","rc":[{"batb":[[0,2.24,11.51],[1,2.22,19.2],[2,2.18,21.36]],"batl":[[0,2.36,3.58],[1,2.62,21.85],[2,4.1,153.72]],"ltp":2.36,"tv":2346.82,"id":8444055},{"batb":[[0,1.74,5.01],[1,1.73,131.67],[2,1.71,56.53]],"ltp":1.74,"tv":2483.87,"id":8257852}]}]}
{"op":"mcm","clk":"1010559874","pt":1580652022552,"mc":[{"id":"1.168223927","rc":[{"batb":[[2,1.71,21.04]],"ltp":1.74,"tv":2483.87,"id":8257852}]}]}
{"op":"mcm","clk":"1010568775","pt":1580652073024,"mc":[{"id":"1.168223927","rc":[{"batb":[[1,2.2,51.17]],"ltp":2.36,"tv":2346.82,"id":8444055},{"batb":[[0,1.74,36.25]],"ltp":1.74,"tv":2483.87,"id":8257852}]}]}
{"op":"mcm","clk":"1010568872","pt":1580652073548,"mc":[{"id":"1.168223927","rc":[{"batb":[[2,1.71,56.53]],"ltp":1.74,"tv":2483.87,"id":8257852}]}]}
{"op":"mcm","clk":"1010569868","pt":1580652079253,"mc":[{"id":"1.168223927","rc":[{"batb":[[0,2.2,51.17],[1,2.18,21.36],[2,2.06,44.54]],"ltp":2.36,"tv":2346.82,"id":8444055}]}]}
{"op":"mcm","clk":"1010569932","pt":1580652079644,"mc":[{"id":"1.168223927","rc":[{"batb":[[0,2.22,11.51],[1,2.2,51.17],[2,2.16,21.73]],"ltp":2.36,"tv":2346.82,"id":8444055},{"batb":[[2,1.72,35.01]],"batl":[[0,1.83,16.79]],"ltp":1.74,"tv":2483.87,"id":8257852}]}]}
{"op":"mcm","clk":"1010570655","pt":1580652083863,"mc":[{"id":"1.168223927","rc":[{"batl":[[0,1.81,7.57],[1,1.83,16.79],[2,1.84,4.12]],"ltp":1.74,"tv":2483.87,"id":8257852}]}]}
{"op":"mcm","clk":"1010570853","pt":1580652084960,"mc":[{"id":"1.168223927","rc":[{"batb":[[2,2.18,21.36]],"ltp":2.36,"tv":2346.82,"id":8444055},{"batb":[[2,1.71,56.53]],"ltp":1.74,"tv":2483.87,"id":8257852}]}]}
{"op":"mcm","clk":"1010571143","pt":1580652086556,"mc":[{"id":"1.168223927","rc":[{"batb":[[2,2.18,23.44]],"batl":[[1,2.4,2.04],[2,2.42,2.06]],"ltp":2.36,"tv":2346.82,"id":8444055},{"batb":[[2,1.72,2.02]],"batl":[[1,1.83,18.81],[2,1.84,6.15]],"ltp":1.74,"tv":2483.87,"id":8257852}]}]}
{"op":"mcm","clk":"1010571955","pt":1580652091235,"mc":[{"id":"1.168223927","rc":[{"batl":[[0,2.34,3.58]],"ltp":2.36,"tv":2346.82,"id":8444055}]}]}
{"op":"mcm","clk":"1010572039","pt":1580652091667,"mc":[{"id":"1.168223927","rc":[{"batl":[[1,2.38,2.04],[2,2.4,2.04]],"ltp":2.36,"tv":2346.82,"id":8444055}]}]}
{"op":"mcm","clk":"1010576870","pt":1580652117111,"mc":[{"id":"1.168223927","rc":[{"batb":[[0,2.24,11.51],[1,2.2,53.19]],"ltp":2.36,"tv":2346.82,"id":8444055},{"batl":[[0,1.8,16.79],[1,1.81,7.57],[2,1.82,2]],"ltp":1.74,"tv":2483.87,"id":8257852}]}]}
{"op":"mcm","clk":"1010577561","pt":1580652120905,"mc":[{"id":"1.168223927","rc":[{"batl":[[1,1.82,2],[2,1.83,2.01]],"ltp":1.74,"tv":2483.87,"id":8257852}]}]}
{"op":"mcm","clk":"1010580287","pt":1580652135216,"mc":[{"id":"1.168223927","rc":[{"batb":[[0,2.2,53.19],[1,2.18,23.44],[2,2.16,21.73]],"ltp":2.36,"tv":2346.82,"id":8444055},{"batl":[[0,1.82,2],[1,1.83,2.01],[2,1.84,4.12]],"ltp":1.74,"tv":2483.87,"id":8257852}]}]}
{"op":"mcm","clk":"1010580446","pt":1580652136022,"mc":[{"id":"1.168223927","rc":[{"batb":[[0,2.22,11.51],[1,2.2,51.17],[2,2.18,23.44]],"ltp":2.36,"tv":2346.82,"id":8444055},{"batl":[[0,1.82,16.79],[1,1.84,6.12],[2,1.85,2.1]],"ltp":1.74,"tv":2483.87,"id":8257852}]}]}
{"op":"mcm","clk":"1010580556","pt":1580652136621,"mc":[{"id":"1.168223927","rc":[{"batb":[[2,2.18,2.08]],"ltp":2.36,"tv":2346.82,"id":8444055},{"batb":[[2,1.72,37.03]],"ltp":1.74,"tv":2483.87,"id":8257852}]}]}
{"op":"mcm","clk":"1010581114","pt":1580652139533,"mc":[{"id":"1.168223927","rc":[{"batl":[[0,1.81,7.57],[1,1.82,16.79],[2,1.83,2.08]],"ltp":1.74,"tv":2483.87,"id":8257852}]}]}
{"op":"mcm","clk":"1010581292","pt":1580652140524,"mc":[{"id":"1.168223927","rc":[{"batb":[[2,2.18,23.44]],"ltp":2.36,"tv":2346.82,"id":8444055},{"batb":[[2,1.72,2.02]],"ltp":1.74,"tv":2483.87,"id":8257852}]}]}
{"op":"mcm","clk":"1010582366","pt":1580652146032,"mc":[{"id":"1.168223927","rc":[{"trd":[[1.74,45.02]],"batb":[[0,1.74,18.27]],"ltp":1.74,"tv":2519.84,"id":8257852}],"tv":4866.67}]}
{"op":"mcm","clk":"1010582572","pt":1580652147148,"mc":[{"id":"1.168223927","rc":[{"batb":[[0,2.24,35.96],[1,2.22,11.51],[2,2.2,2.02]],"ltp":2.36,"tv":2346.82,"id":8444055}]}]}
{"op":"mcm","clk":"1010583338","pt":1580652151031,"mc":[{"id":"1.168223927","rc":[{"batl":[[0,2.42,2.27],[1,2.44,2.08],[2,2.62,21.85]],"ltp":2.36,"tv":2346.82,"id":8444055}]}]}
{"op":"mcm","clk":"1010583549","pt":1580652152067,"mc":[{"id":"1.168223927","rc":[{"batb":[[2,2.2,23.02]],"batl":[[0,2.4,2.31],[1,2.42,2.06],[2,2.44,2.08]],"ltp":2.36,"tv":2346.82,"id":8444055}]}]}
{"op":"mcm","clk":"1010583581","pt":1580652152347,"mc":[{"id":"1.168223927","rc":[{"batb":[[1,1.73,135.89]],"ltp":1.74,"tv":2519.84,"id":8257852}]}]}
{"op":"mcm","clk":"1010586293","pt":1580652165979,"mc":[{"id":"1.168223927","rc":[{"batl":[[2,2.62,21.85]],"ltp":2.36,"tv":2346.82,"id":8444055},{"batl":[[0,1.8,16.79],[1,1.81,7.57],[2,1.82,2.08]],"ltp":1.74,"tv":2519.84,"id":8257852}]}]}
{"op":"mcm","clk":"1010586998","pt":1580652169048,"mc":[{"id":"1.168223927","rc":[{"batb":[[0,2.26,11.51],[1,2.24,35.96],[2,2.22,2.02]],"ltp":2.36,"tv":2346.82,"id":8444055}]}]}
{"op":"mcm","clk":"1010591165","pt":1580652187907,"mc":[{"id":"1.168223927","rc":[{"batb":[[0,2.26,11.41]],"ltp":2.36,"tv":2346.82,"id":8444055},{"batl":[[0,1.8,16.88]],"ltp":1.74,"tv":2519.84,"id":8257852}]}]}
{"op":"mcm","clk":"1010604172","pt":1580652246876,"mc":[{"id":"1.168223927","rc":[{"batl":[[1,2.42,2]],"ltp":2.36,"tv":2346.82,"id":8444055},{"batb":[[0,1.74,18.75]],"ltp":1.74,"tv":2519.84,"id":8257852}]}]}
{"op":"mcm","clk":"1010625980","pt":1580652343097,"mc":[{"id":"1.168223927","rc":[{"batl":[[1,2.62,21.85],[2,4.1,153.72]],"ltp":2.36,"tv":2346.82,"id":8444055},{"batl":[[1,1.82,2.08],[2,1.84,4.12]],"ltp":1.74,"tv":2519.84,"id":8257852}]}]}
{"op":"mcm","clk":"1010626025","pt":1580652343274,"mc":[{"id":"1.168223927","rc":[{"batl":[[1,2.42,2],[2,2.62,21.85]],"ltp":2.36,"tv":2346.82,"id":8444055},{"batl":[[2,1.83,2.26]],"ltp":1.74,"tv":2519.84,"id":8257852}]}]}
{"op":"mcm","clk":"1010631553","pt":1580652368052,"mc":[{"id":"1.168223927","rc":[{"batl":[[1,2.42,2.06]],"ltp":2.36,"tv":2346.82,"id":8444055},{"batl":[[1,1.82,191.12],[2,1.83,2.38]],"ltp":1.74,"tv":2519.84,"id":8257852}]}]}
{"op":"mcm","clk":"1010632337","pt":1580652371704,"mc":[{"id":"1.168223927","rc":[{"batb":[[1,1.73,67.67]],"ltp":1.74,"tv":2519.84,"id":8257852}]}]}
{"op":"mcm","clk":"1010643440","pt":1580652420195,"mc":[{"id":"1.168223927","rc":[{"batl":[[1,2.62,21.85],[2,4.1,153.72]],"ltp":2.36,"tv":2346.82,"id":8444055},{"trd":[[1.74,51.34]],"batb":[[0,1.74,15.59]],"batl":[[2,1.84,4.12]],"ltp":1.74,"tv":2526.16,"id":8257852}],"tv":4872.99}]}
{"op":"mcm","clk":"1010643482","pt":1580652420364,"mc":[{"id":"1.168223927","rc":[{"batl":[[1,2.42,2.06],[2,2.62,21.85]],"ltp":2.36,"tv":2346.82,"id":8444055},{"batl":[[2,1.83,2.2]],"ltp":1.74,"tv":2526.16,"id":8257852}]}]}
{"op":"mcm","clk":"1010643898","pt":1580652422180,"mc":[{"id":"1.168223927","rc":[{"batb":[[1,2.22,52.85],[2,2.2,23.02]],"ltp":2.36,"tv":2346.82,"id":8444055}]}]}
{"op":"mcm","clk":"1010644742","pt":1580652426191,"mc":[{"id":"1.168223927","rc":[{"batb":[[0,2.24,11.41],[1,2.22,50.83]],"ltp":2.36,"tv":2346.82,"id":8444055},{"batl":[[0,1.81,16.79]],"ltp":1.74,"tv":2526.16,"id":8257852}]}]}
{"op":"mcm","clk":"1010644898","pt":1580652426886,"mc":[{"id":"1.168223927","rc":[{"batb":[[2,2.2,2.02]],"batl":[[1,2.62,21.85],[2,4.1,153.72]],"ltp":2.36,"tv":2346.82,"id":8444055},{"batl":[[1,1.82,189.04]],"ltp":1.74,"tv":2526.16,"id":8257852}]}]}
{"op":"mcm","clk":"1010644993","pt":1580652427278,"mc":[{"id":"1.168223927","rc":[{"batl":[[1,2.42,2.06],[2,2.62,21.85]],"ltp":2.36,"tv":2346.82,"id":8444055}]}]}
{"op":"mcm","clk":"1010649865","pt":1580652447147,"mc":[{"id":"1.168223927","rc":[{"batb":[[0,2.24,11.51]],"ltp":2.36,"tv":2346.82,"id":8444055}]}]}
{"op":"mcm","clk":"1010659057","pt":1580652486165,"mc":[{"id":"1.168223927","rc":[{"batl":[[1,2.62,21.85],[2,4.1,153.72]],"ltp":2.36,"tv":2346.82,"id":8444055},{"batb":[[0,1.77,6.55],[1,1.75,2.03],[2,1.74,17.61]],"ltp":1.74,"tv":2526.16,"id":8257852}]}]}
{"op":"mcm","clk":"1010659336","pt":1580652487189,"mc":[{"id":"1.168223927","rc":[{"batl":[[0,2.38,2.29],[1,2.4,2.04],[2,2.42,2.06]],"ltp":2.36,"tv":2346.82,"id":8444055},{"trd":[[1.77,223.5]],"batb":[[0,1.77,1.07],[1,1.74,15.59],[2,1.73,69.8]],"ltp":1.77,"tv":2537.12,"id":8257852}],"tv":4883.95}]}
{"op":"mcm","clk":"1010659357","pt":1580652487284,"mc":[{"id":"1.168223927","rc":[{"batl":[[0,2.4,2.31],[1,2.42,2.06],[2,2.44,2.04]],"ltp":2.36,"tv":2346.82,"id":8444055},{"batb":[[2,1.73,67.67]],"ltp":1.77,"tv":2537.12,"id":8257852}]}]}
{"op":"mcm","clk":"1010666216","pt":1580652515096,"mc":[{"id":"1.168223927","rc":[{"batl":[[0,1.8,7.57],[1,1.81,16.79],[2,1.82,189.04]],"ltp":1.77,"tv":2537.12,"id":8257852}]}]}
{"op":"mcm","clk":"1010666401","pt":1580652515898,"mc":[{"id":"1.168223927","rc":[{"batb":[[2,2.2,23.02]],"batl":[[2,2.62,21.85]],"ltp":2.36,"tv":2346.82,"id":8444055},{"batl":[[2,1.82,191.29]],"ltp":1.77,"tv":2537.12,"id":8257852}]}]}
{"op":"mcm","clk":"1010667096","pt":1580652518717,"mc":[{"id":"1.168223927","rc":[{"batb":[[1,1.74,23.17]],"ltp":1.77,"tv":2537.12,"id":8257852}]}]}
{"op":"mcm","clk":"1010667607","pt":1580652520748,"mc":[{"id":"1.168223927","rc":[{"batb":[[2,2.2,2.02]],"ltp":2.36,"tv":2346.82,"id":8444055}]}]}
{"op":"mcm","clk":"1010668712","pt":1580652525196,"mc":[{"id":"1.168223927","rc":[{"batb":[[1,1.74,15.59]],"ltp":1.77,"tv":2537.12,"id":8257852}]}]}
{"op":"mcm","clk":"1010668866","pt":1580652525746,"mc":[{"id":"1.168223927","rc":[{"batb":[[2,2.2,23.02]],"ltp":2.36,"tv":2346.82,"id":8444055}]}]}
{"op":"mcm","clk":"1010674243","pt":1580652548192,"mc":[{"id":"1.168223927","rc":[{"batl":[[0,2.38,2.31],[1,2.4,2.04]],"ltp":2.36,"tv":2346.82,"id":8444055},{"batb":[[1,1.75,151.24],[2,1.74,15.59]],"batl":[[0,1.8,154.61]],"ltp":1.77,"tv":2537.12,"id":8257852}]}]}
{"op":"mcm","clk":"1010674387","pt":1580652548676,"mc":[{"id":"1.168223927","rc":[{"batb":[[2,2.2,2.02]],"ltp":2.36,"tv":2346.82,"id":8444055}]}]}
{"op":"mcm","clk":"1010675766","pt":1580652555122,"mc":[{"id":"1.168223927","rc":[{"batb":[[0,2.22,52.85],[1,2.2,2.02],[2,2.18,21.36]],"batl":[[1,2.62,21.85],[2,4.1,153.72]],"ltp":2.36,"tv":2346.82,"id":8444055},{"batb":[[1,1.75,151.72],[2,1.74,15.11]],"batl":[[0,1.79,16.79],[1,1.8,154.61]],"ltp":1.77,"tv":2537.12,"id":8257852}]}]}
{"op":"mcm","clk":"1010675900","pt":1580652555767,"mc":[{"id":"1.168223927","rc":[{"batl":[[1,2.4,2.04],[2,2.62,21.85]],"ltp":2.36,"tv":2346.82,"id":8444055},{"batl":[[2,1.81,2.13]],"ltp":1.77,"tv":2537.12,"id":8257852}]}]}
{"op":"mcm","clk":"1010680460","pt":1580652576086,"mc":[{"id":"1.168223927","rc":[{"batb":[[0,2.26,11.41],[1,2.22,52.85]],"batl":[[1,2.62,21.85],[2,4.1,153.72]],"ltp":2.36,"tv":2346.82,"id":8444055},{"batl":[[0,1.79,16.98]],"ltp":1.77,"tv":2537.12,"id":8257852}]}]}
{"op":"mcm","clk":"1010680614","pt":1580652576698,"mc":[{"id":"1.168223927","rc":[{"batb":[[2,2.2,23.02]],"batl":[[1,2.4,2.04],[2,2.62,21.85]],"ltp":2.36,"tv":2346.82,"id":8444055}]}]}
{"op":"mcm","clk":"1010689880","pt":1580652617230,"mc":[{"id":"1.168223927","rc":[{"batb":[[0,2.26,37.69],[1,2.22,2.02]],"ltp":2.36,"tv":2346.82,"id":8444055}]}]}
{"op":"mcm","clk":"1010695434","pt":1580652641752,"mc":[{"id":"1.168223927","rc":[{"batl":[[1,2.4,2]],"ltp":2.36,"tv":2346.82,"id":8444055}]}]}
{"op":"mcm","clk":"1010710222","pt":1580652709020,"mc":[{"id":"1.168223927","rc":[{"trd":[[2.26,2151.58]],"batb":[[0,2.2,23.02],[1,2.18,23.36],[2,2.16,21.73]],"batl":[[0,2.3,2.05],[1,2.32,2.11],[2,2.62,22.11]],"ltp":2.26,"tv":2519.62,"id":8444055},{"trd":[[1.79,111.92]],"batb":[[0,1.77,3.1],[1,1.76,2.72],[2,1.75,151.24]],"batl":[[0,1.8,154.61],[1,1.82,191.29],[2,1.83,2.32]],"ltp":1.79,"tv":2554.1,"id":8257852}],"tv":5073.73}]}
{"op":"mcm","clk":"1010710494","pt":1580652710179,"mc":[{"id":"1.168223927","rc":[{"batb":[[0,2.22,24.45],[1,2.2,2.02],[2,2.18,23.36]],"batl":[[0,2.36,2.29],[1,2.38,2.04],[2,2.4,2.04]],"ltp":2.26,"tv":2519.62,"id":8444055},{"trd":[[1.8,617.91]],"batb":[[0,1.77,1.07],[1,1.76,41.49]],"batl":[[0,1.8,154.41]],"ltp":1.8,"tv":2554.5,"id":8257852}],"tv":5074.12}]}
{"op":"mcm","clk":"1010710680","pt":1580652711001,"mc":[{"id":"1.168223927","rc":[{"batl":[[0,2.32,13.1],[1,2.36,2.02],[2,2.38,2.04]],"ltp":2.26,"tv":2519.62,"id":8444055}]}]}
{"op":"mcm","clk":"1010710864","pt":1580652711793,"mc":[{"id":"1.168223927","rc":[{"batb":[[0,1.77,1.27]],"ltp":1.8,"tv":2554.5,"id":8257852}]}]}
{"op":"mcm","clk":"1010715338","pt":1580652732121,"mc":[{"id":"1.168223927","rc":[{"batb":[[2,2.18,21.36]],"batl":[[2,2.62,21.85]],"ltp":2.26,"tv":2519.62,"id":8444055},{"batl":[[0,1.79,5.96],[1,1.8,154.41],[2,1.81,2.02]],"ltp":1.8,"tv":2554.5,"id":8257852}]}]}
{"op":"mcm","clk":"1010715532","pt":1580652732936,"mc":[{"id":"1.168223927","rc":[{"trd":[[2.3,64.99],[2.32,21.97]],"batb":[[0,2.22,26.47]],"batl":[[0,2.32,2.12],[2,2.38,2.04]],"ltp":2.32,"tv":2542.56,"id":8444055},{"trd":[[1.77,224.76]],"batb":[[0,1.76,41.49],[1,1.75,151.24],[2,1.74,2.02]],"ltp":1.77,"tv":2555.76,"id":8257852}],"tv":5098.33}]}
{"op":"mcm","clk":"1010716219","pt":1580652735926,"mc":[{"id":"1.168223927","rc":[{"batl":[[1,1.8,161.98]],"ltp":1.77,"tv":2555.76,"id":8257852}]}]}
{"op":"mcm","clk":"1010716962","pt":1580652739177,"mc":[{"id":"1.168223927","rc":[{"batb":[[0,2.26,11.27],[1,2.22,26.47],[2,2.2,2.02]],"batl":[[2,2.62,21.85]],"ltp":2.32,"tv":2542.56,"id":8444055}]}]}
{"op":"mcm","clk":"1010717099","pt":1580652739766,"mc":[{"id":"1.168223927","rc":[{"batl":[[2,2.38,2.04]],"ltp":2.32,"tv":2542.56,"id":8444055}]}]}
{"op":"mcm","clk":"1010747513","pt":1580652869167,"mc":[{"id":"1.168223927","rc":[{"batb":[[0,2.26,40.36],[1,2.22,2.02],[2,2.2,23.02]],"ltp":2.32,"tv":2542.56,"id":8444055},{"trd":[[1.76,549.1]],"batb":[[0,1.75,151.24],[1,1.74,29.51],[2,1.73,38.44]],"ltp":1.76,"tv":2631.52,"id":8257852}],"tv":5174.09}]}
{"op":"mcm","clk":"1010748445","pt":1580652873044,"mc":[{"id":"1.168223927","rc":[{"batl":[[0,2.34,12.92]],"ltp":2.32,"tv":2542.56,"id":8444055},{"batb":[[0,1.76,16.78],[1,1.75,151.24],[2,1.74,29.51]],"batl":[[0,1.79,6.44]],"ltp":1.76,"tv":2631.52,"id":8257852}]}]}
{"op":"mcm","clk":"1010748608","pt":1580652873767,"mc":[{"id":"1.168223927","rc":[{"batl":[[1,2.36,2.07]],"ltp":2.32,"tv":2542.56,"id":8444055},{"batb":[[2,1.74,31.53]],"ltp":1.76,"tv":2631.52,"id":8257852}]}]}
{"op":"mcm","clk":"1010758821","pt":1580652918166,"mc":[{"id":"1.168223927","rc":[{"batl":[[2,2.62,21.85]],"ltp":2.32,"tv":2542.56,"id":8444055}]}]}
{"op":"mcm","clk":"1010759066","pt":1580652919250,"mc":[{"id":"1.168223927","rc":[{"batl":[[0,2.38,2.04],[1,2.4,2.04]],"ltp":2.32,"tv":2542.56,"id":8444055},{"trd":[[1.76,578.69]],"batb":[[0,1.75,151.24],[1,1.74,29.51],[2,1.73,38.55]],"batl":[[0,1.79,16.98]],"ltp":1.76,"tv":2661.1,"id":8257852}],"tv":5203.67}]}
{"op":"mcm","clk":"1010759228","pt":1580652920076,"mc":[{"id":"1.168223927","rc":[{"batl":[[0,2.34,1.88],[1,2.38,2.04],[2,2.4,2.04]],"ltp":2.32,"tv":2542.56,"id":8444055}]}]}
{"op":"mcm","clk":"1010765818","pt":1580652948151,"mc":[{"id":"1.168223927","rc":[{"trd":[[2.26,2171.56]],"batb":[[0,2.26,30.37]],"ltp":2.26,"tv":2562.55,"id":8444055}],"tv":5223.66}]}
{"op":"mcm","clk":"1010765966","pt":1580652948715,"mc":[{"id":"1.168223927","rc":[{"batl":[[2,2.4,2.02]],"ltp":2.26,"tv":2562.55,"id":8444055}]}]}
{"op":"mcm","clk":"1010770701","pt":1580652969184,"mc":[{"id":"1.168223927","rc":[{"batb":[[0,2.26,29.09]],"ltp":2.26,"tv":2562.55,"id":8444055}]}]}
{"op":"mcm","clk":"1010770836","pt":1580652969772,"mc":[{"id":"1.168223927","rc":[{"batl":[[2,2.4,2]],"ltp":2.26,"tv":2562.55,"id":8444055}]}]}
{"op":"mcm","clk":"1010773815","pt":1580652982970,"mc":[{"id":"1.168223927","rc":[{"batb":[[0,2.28,1.27],[1,2.26,29.09],[2,2.22,2.02]],"batl":[[2,2.4,2.04]],"ltp":2.26,"tv":2562.55,"id":8444055}]}]}
{"op":"mcm","clk":"1010778036","pt":1580653002122,"mc":[{"id":"1.168223927","rc":[{"batb":[[0,1.76,2.52],[1,1.75,151.24],[2,1.74,31.53]],"ltp":1.76,"tv":2661.1,"id":8257852}]}]}
{"op":"mcm","clk":"1010802869","pt":1580653117166,"mc":[{"id":"1.168223927","rc":[{"batl":[[2,2.62,21.85]],"ltp":2.26,"tv":2562.55,"id":8444055},{"batl":[[1,1.8,147.03]],"ltp":1.76,"tv":2661.1,"id":8257852}]}]}
{"op":"mcm","clk":"1010802921","pt":1580653117373,"mc":[{"id":"1.168223927","rc":[{"batl":[[2,2.4,2.04]],"ltp":2.26,"tv":2562.55,"id":8444055}]}]}
{"op":"mcm","clk":"1010856241","pt":1580653380088,"mc":[{"id":"1.168223927","rc":[{"trd":[[1.75,376.59],[1.76,583.73]],"batb":[[0,1.75,141.15],[1,1.74,31.53],[2,1.73,38.55]],"ltp":1.75,"tv":2686.31,"id":8257852}],"tv":5248.86}]}
{"op":"mcm","clk":"1010856342","pt":1580653380570,"mc":[{"id":"1.168223927","rc":[{"batb":[[1,1.74,29.51]],"ltp":1.75,"tv":2686.31,"id":8257852}]}]}
{"op":"mcm","clk":"1010858198","pt":1580653390103,"mc":[{"id":"1.168223927","rc":[{"batl":[[1,2.36,2.07],[2,2.38,2.04]],"ltp":2.26,"tv":2562.55,"id":8444055},{"batb":[[0,1.76,10.07],[1,1.75,141.15],[2,1.74,31.53]],"ltp":1.75,"tv":2686.31,"id":8257852}]}]}
{"op":"mcm","clk":"1010860829","pt":1580653403154,"mc":[{"id":"1.168223927","rc":[{"batb":[[1,2.26,17.69]],"ltp":2.26,"tv":2562.55,"id":8444055},{"batb":[[2,1.74,46.34]],"ltp":1.75,"tv":2686.31,"id":8257852}]}]}
{"op":"mcm","clk":"1010861085","pt":1580653404173,"mc":[{"id":"1.168223927","rc":[{"trd":[[1.76,602.48]],"batb":[[0,1.75,141.85],[1,1.74,44.32],[2,1.73,38.55]],"ltp":1.76,"tv":2705.06,"id":8257852}],"tv":5267.61}]}
{"op":"mcm","clk":"1010861108","pt":1580653404277,"mc":[{"id":"1.168223927","rc":[{"batl":[[1,2.38,2.04],[2,2.4,2.04]],"ltp":2.26,"tv":2562.55,"id":8444055}]}]}
{"op":"mcm","clk":"1010861754","pt":1580653407553,"mc":[{"id":"1.168223927","rc":[{"batb":[[0,1.75,141.15]],"ltp":1.76,"tv":2705.06,"id":8257852}]}]}
{"op":"mcm","clk":"1010876514","pt":1580653480141,"mc":[{"id":"1.168223927","rc":[{"batl":[[0,1.78,7.57],[1,1.79,16.98],[2,1.8,149.05]],"ltp":1.76,"tv":2705.06,"id":8257852}]}]}
{"op":"mcm","clk":"1010876728","pt":1580653481061,"mc":[{"id":"1.168223927","rc":[{"batb":[[2,2.24,2.02]],"ltp":2.26,"tv":2562.55,"id":8444055}]}]}
{"op":"mcm","clk":"1010878268","pt":1580653488164,"mc":[{"id":"1.168223927","rc":[{"batl":[[2,2.62,21.85]],"ltp":2.26,"tv":2562.55,"id":8444055},{"batb":[[0,1.76,3.22],[1,1.75,141.15],[2,1.74,46.34]],"batl":[[0,1.78,15.14]],"ltp":1.76,"tv":2705.06,"id":8257852}]}]}
{"op":"mcm","clk":"1010878419","pt":1580653488772,"mc":[{"id":"1.168223927","rc":[{"batl":[[1,2.36,2.07],[2,2.38,2.04]],"ltp":2.26,"tv":2562.55,"id":8444055},{"batl":[[0,1.78,7.57]],"ltp":1.76,"tv":2705.06,"id":8257852}]}]}
{"op":"mcm","clk":"1010878934","pt":1580653491251,"mc":[{"id":"1.168223927","rc":[{"batl":[[0,1.79,16.98],[1,1.8,147.03],[2,1.81,2.13]],"ltp":1.76,"tv":2705.06,"id":8257852}]}]}
{"op":"mcm","clk":"1010879067","pt":1580653491850,"mc":[{"id":"1.168223927","rc":[{"batb":[[2,2.22,2.02]],"ltp":2.26,"tv":2562.55,"id":8444055}]}]}
{"op":"mcm","clk":"1010886257","pt":1580653526169,"mc":[{"id":"1.168223927","rc":[{"batb":[[0,2.26,17.69],[1,2.22,2.02],[2,2.2,21]],"batl":[[0,2.38,2.04],[1,2.4,2.04],[2,2.62,21.85]],"ltp":2.26,"tv":2562.55,"id":8444055},{"batb":[[0,1.75,141.15],[1,1.74,44.32],[2,1.73,38.55]],"batl":[[0,1.8,147.03],[1,1.82,191.29],[2,1.83,2.2]],"ltp":1.76,"tv":2705.06,"id":8257852}]}]}
{"op":"mcm","clk":"1010886455","pt":1580653527141,"mc":[{"id":"1.168223927","rc":[{"batb":[[0,2.28,1.27],[1,2.26,17.69],[2,2.22,2.02]],"batl":[[0,2.34,2.52],[1,2.36,2.02],[2,2.38,2.04]],"ltp":2.26,"tv":2562.55,"id":8444055},{"batb":[[0,1.76,3.22],[1,1.75,141.15],[2,1.74,46.34]],"batl":[[0,1.79,16.98],[1,1.8,147.03],[2,1.81,2.02]],"ltp":1.76,"tv":2705.06,"id":8257852}]}]}
{"op":"mcm","clk":"1010931317","pt":1580653745082,"mc":[{"id":"1.168223927","rc":[{"batl":[[2,2.62,21.85]],"ltp":2.26,"tv":2562.55,"id":8444055},{"trd":[[1.76,608.15]],"batb":[[0,1.75,141.53],[1,1.74,44.32],[2,1.73,38.55]],"ltp":1.76,"tv":2710.73,"id":8257852}],"tv":5273.29}]}
{"op":"mcm","clk":"1010931405","pt":1580653745509,"mc":[{"id":"1.168223927","rc":[{"batl":[[1,2.38,2.04],[2,2.4,2.04]],"ltp":2.26,"tv":2562.55,"id":8444055}]}]}
{"op":"mcm","clk":"1010931810","pt":1580653747149,"mc":[{"id":"1.168223927","rc":[{"batl":[[0,1.78,7.57],[1,1.79,16.98],[2,1.8,147.03]],"ltp":1.76,"tv":2710.73,"id":8257852}]}]}
{"op":"mcm","clk":"1010932113","pt":1580653748186,"mc":[{"id":"1.168223927","rc":[{"batb":[[2,2.24,2.02]],"ltp":2.26,"tv":2562.55,"id":8444055},{"batl":[[2,1.8,149.05]],"ltp":1.76,"tv":2710.73,"id":8257852}]}]}
{"op":"mcm","clk":"1010933629","pt":1580653754264,"mc":[{"id":"1.168223927","rc":[{"batl":[[0,2.38,2.04],[1,2.4,2.04],[2,2.62,21.85]],"ltp":2.26,"tv":2562.55,"id":8444055},{"batb":[[0,1.75,141.15]],"ltp":1.76,"tv":2710.73,"id":8257852}]}]}
{"op":"mcm","clk":"1010933816","pt":1580653754967,"mc":[{"id":"1.168223927","rc":[{"batl":[[0,2.38,2.44],[1,2.4,2],[2,2.42,2.02]],"ltp":2.26,"tv":2562.55,"id":8444055}]}]}
{"op":"mcm","clk":"1010937956","pt":1580653773154,"mc":[{"id":"1.168223927","rc":[{"batl":[[1,2.4,2.04],[2,2.62,21.85]],"ltp":2.26,"tv":2562.55,"id":8444055},{"batl":[[0,1.78,15.14]],"ltp":1.76,"tv":2710.73,"id":8257852}]}]}
{"op":"mcm","clk":"1010938441","pt":1580653775079,"mc":[{"id":"1.168223927","rc":[{"batb":[[2,2.22,2.02]],"ltp":2.26,"tv":2562.55,"id":8444055},{"batl":[[0,1.79,16.98],[1,1.8,147.03],[2,1.81,2.13]],"ltp":1.76,"tv":2710.73,"id":8257852}]}]}
{"op":"mcm","clk":"1010938666","pt":1580653776050,"mc":[{"id":"1.168223927","rc":[{"batb":[[2,2.24,2.02]],"ltp":2.26,"tv":2562.55,"id":8444055},{"batl":[[0,1.78,7.57],[1,1.79,16.98],[2,1.8,149.05]],"ltp":1.76,"tv":2710.73,"id":8257852}]}]}
{"op":"mcm","clk":"1010940011","pt":1580653782058,"mc":[{"id":"1.168223927","rc":[{"batb":[[0,2.3,1.27]],"ltp":2.26,"tv":2562.55,"id":8444055},{"batl":[[0,1.77,16.98],[1,1.78,7.57]],"ltp":1.76,"tv":2710.73,"id":8257852}]}]}
{"op":"mcm","clk":"1010940243","pt":1580653782974,"mc":[{"id":"1.168223927","rc":[{"batl":[[2,1.79,2.07]],"ltp":1.76,"tv":2710.73,"id":8257852}]}]}
{"op":"mcm","clk":"1010942441","pt":1580653793191,"mc":[{"id":"1.168223927","rc":[{"batb":[[0,2.28,1.27]],"batl":[[0,2.38,2.04]],"ltp":2.26,"tv":2562.55,"id":8444055},{"batl":[[0,1.78,24.55],[1,1.79,2.07],[2,1.8,149.05]],"ltp":1.76,"tv":2710.73,"id":8257852}]}]}
{"op":"mcm","clk":"1010942540","pt":1580653793613,"mc":[{"id":"1.168223927","rc":[{"batl":[[1,1.8,149.05],[2,1.81,2.13]],"ltp":1.76,"tv":2710.73,"id":8257852}]}]}
{"op":"mcm","clk":"1010945572","pt":1580653807242,"mc":[{"id":"1.168223927","rc":[{"batl":[[0,1.78,7.57]],"ltp":1.76,"tv":2710.73,"id":8257852}]}]}
{"op":"mcm","clk":"1010945602","pt":1580653807280,"mc":[{"id":"1.168223927","rc":[{"batl":[[1,1.79,16.98],[2,1.8,149.05]],"ltp":1.76,"tv":2710.73,"id":8257852}]}]}
{"op":"mcm","clk":"1010948785","pt":1580653823230,"mc":[{"id":"1.168223927","rc":[{"trd":[[2.28,14.37]],"batb":[[0,2.26,17.69],[1,2.22,2.02],[2,2.2,23.02]],"batl":[[0,2.28,36.68],[1,2.32,2.11],[2,2.34,2.02]],"ltp":2.28,"tv":2571.0,"id":8444055},{"trd":[[1.78,81.36]],"batb":[[0,1.77,7.62],[1,1.75,141.15],[2,1.74,44.32]],"batl":[[0,1.79,16.98],[1,1.8,147.03],[2,1.81,2.13]],"ltp":1.78,"tv":2718.31,"id":8257852}],"tv":5289.31}]}
{"op":"mcm","clk":"1010948923","pt":1580653824039,"mc":[{"id":"1.168223927","rc":[{"batb":[[2,2.2,2.02]],"ltp":2.28,"tv":2571.0,"id":8444055},{"batb":[[1,1.76,2.15],[2,1.75,143.18]],"ltp":1.78,"tv":2718.31,"id":8257852}]}]}
{"op":"mcm","clk":"1010949749","pt":1580653828229,"mc":[{"id":"1.168223927","rc":[{"batb":[[2,2.18,21.36]],"batl":[[2,2.62,21.85]],"ltp":2.28,"tv":2571.0,"id":8444055},{"batb":[[0,1.76,9.77],[1,1.75,143.18],[2,1.74,44.32]],"ltp":1.78,"tv":2718.31,"id":8257852}]}]}
{"op":"mcm","clk":"1010949785","pt":1580653828397,"mc":[{"id":"1.168223927","rc":[{"batb":[[2,2.2,2]],"batl":[[2,2.34,2.02]],"ltp":2.28,"tv":2571.0,"id":8444055}]}]}
{"op":"mcm","clk":"1010950134","pt":1580653830216,"mc":[{"id":"1.168223927","rc":[{"batb":[[1,2.24,12.27],[2,2.22,2.02]],"ltp":2.28,"tv":2571.0,"id":8444055}]}]}
{"op":"mcm","clk":"1010950900","pt":1580653834031,"mc":[{"id":"1.168223927","rc":[{"batb":[[0,1.76,2.15]],"ltp":1.78,"tv":2718.31,"id":8257852}]}]}
{"op":"mcm","clk":"1010951131","pt":1580653835214,"mc":[{"id":"1.168223927","rc":[{"batl":[[2,2.34,2.25]],"ltp":2.28,"tv":2571.0,"id":8444055},{"batb":[[0,1.76,9.81]],"ltp":1.78,"tv":2718.31,"id":8257852}]}]}
{"op":"mcm","clk":"1010952612","pt":1580653843216,"mc":[{"id":"1.168223927","rc":[{"trd":[[1.79,121.03]],"batl":[[0,1.79,12.42]],"ltp":1.79,"tv":2727.42,"id":8257852}],"tv":5298.43}]}
{"op":"mcm","clk":"1010952757","pt":1580653844050,"mc":[{"id":"1.168223927","rc":[{"trd":[[2.28,82.85]],"batl":[[0,2.28,2.44],[2,2.34,2.02]],"ltp":2.28,"tv":2639.48,"id":8444055}],"tv":5366.91}]}
{"op":"mcm","clk":"1010953156","pt":1580653846047,"mc":[{"id":"1.168223927","rc":[{"batl":[[2,2.34,7.05]],"ltp":2.28,"tv":2639.48,"id":8444055}]}]}
{"op":"mcm","clk":"1010953367","pt":1580653847233,"mc":[{"id":"1.168223927","rc":[{"trd":[[2.28,85.29]],"batl":[[0,2.34,7.05],[1,2.36,2.02],[2,2.62,21.85]],"ltp":2.28,"tv":2641.92,"id":8444055},{"trd":[[1.78,84.49]],"batb":[[0,1.76,7.66],[1,1.75,141.15],[2,1.74,46.34]],"batl":[[0,1.78,4.44],[1,1.79,19.99],[2,1.8,149.05]],"ltp":1.78,"tv":2730.55,"id":8257852}],"tv":5372.48}]}
{"op":"mcm","clk":"1010953529","pt":1580653848035,"mc":[{"id":"1.168223927","rc":[{"batb":[[1,2.24,14.29]],"batl":[[2,2.38,2.04]],"ltp":2.28,"tv":2641.92,"id":8444055},{"batb":[[0,1.77,3.14],[1,1.76,7.66],[2,1.75,143.18]],"ltp":1.78,"tv":2730.55,"id":8257852}]}]}
{"op":"mcm","clk":"1010953920","pt":1580653850243,"mc":[{"id":"1.168223927","rc":[{"batl":[[0,1.79,19.99],[1,1.8,147.03],[2,1.81,2.13]],"ltp":1.78,"tv":2730.55,"id":8257852}]}]}
{"op":"mcm","clk":"1010953945","pt":1580653850348,"mc":[{"id":"1.168223927","rc":[{"batb":[[1,2.24,12.27]],"ltp":2.28,"tv":2641.92,"id":8444055}]}]}
{"op":"mcm","clk":"1010954670","pt":1580653854208,"mc":[{"id":"1.168223927","rc":[{"batl":[[1,2.36,2.07],[2,2.62,21.85]],"ltp":2.28,"tv":2641.92,"id":8444055},{"batb":[[0,1.78,4.2],[1,1.76,2.03]],"batl":[[0,1.79,12.42]],"ltp":1.78,"tv":2730.55,"id":8257852}]}]}
{"op":"mcm","clk":"1010954822","pt":1580653855027,"mc":[{"id":"1.168223927","rc":[{"batl":[[0,1.79,16.98]],"ltp":1.78,"tv":2730.55,"id":8257852}]}]}
{"op":"mcm","clk":"1010954885","pt":1580653855359,"mc":[{"id":"1.168223927","rc":[{"batb":[[1,1.76,12.86]],"ltp":1.78,"tv":2730.55,"id":8257852}]}]}
{"op":"mcm","clk":"1010955513","pt":1580653858200,"mc":[{"id":"1.168223927","rc":[{"trd":[[1.78,92.9]],"batb":[[0,1.76,10.83],[1,1.75,141.15],[2,1.74,46.34]],"batl":[[0,1.78,3.37],[1,1.79,16.98],[2,1.8,149.03]],"ltp":1.78,"tv":2738.95,"id":8257852}],"tv":5380.88}]}
{"op":"mcm","clk":"1010955747","pt":1580653859265,"mc":[{"id":"1.168223927","rc":[{"batb":[[1,2.24,14.29]],"batl":[[2,2.38,2]],"ltp":2.28,"tv":2641.92,"id":8444055},{"batb":[[0,1.77,4.23],[1,1.76,10.83],[2,1.75,143.18]],"ltp":1.78,"tv":2738.95,"id":8257852}]}]}
{"op":"mcm","clk":"1010955894","pt":1580653860003,"mc":[{"id":"1.168223927","rc":[{"batb":[[0,1.76,10.83],[1,1.75,143.18],[2,1.74,46.34]],"ltp":1.78,"tv":2738.95,"id":8257852}]}]}
{"op":"mcm","clk":"1010956181","pt":1580653861239,"mc":[{"id":"1.168223927","rc":[{"batl":[[0,2.34,5.03]],"ltp":2.28,"tv":2641.92,"id":8444055},{"trd":[[1.76,627.17]],"batb":[[0,1.75,141.15],[1,1.74,44.32],[2,1.73,38.44]],"batl":[[0,1.79,16.98],[1,1.8,149.03],[2,1.81,2.13]],"ltp":1.76,"tv":2757.98,"id":8257852}],"tv":5399.9}]}
{"op":"mcm","clk":"1010956230","pt":1580653861458,"mc":[{"id":"1.168223927","rc":[{"batb":[[1,2.24,12.27]],"batl":[[1,2.38,2],[2,2.4,2.04]],"ltp":2.28,"tv":2641.92,"id":8444055},{"batl":[[1,1.8,147.03]],"ltp":1.76,"tv":2757.98,"id":8257852}]}]}
{"op":"mcm","clk":"1010956587","pt":1580653863093,"mc":[{"id":"1.168223927","rc":[{"batl":[[1,2.36,2.07],[2,2.38,2]],"ltp":2.28,"tv":2641.92,"id":8444055},{"batb":[[0,1.76,15.08],[1,1.75,141.15],[2,1.74,46.34]],"ltp":1.76,"tv":2757.98,"id":8257852}]}]}
{"op":"mcm","clk":"1010956820","pt":1580653864231,"mc":[{"id":"1.168223927","rc":[{"batl":[[0,1.79,24.55]],"ltp":1.76,"tv":2757.98,"id":8257852}]}]}
{"op":"mcm","clk":"1010957057","pt":1580653865259,"mc":[{"id":"1.168223927","rc":[{"batb":[[0,2.26,29.96],[1,2.22,2.02],[2,2.2,23.02]],"batl":[[2,2.38,2.04]],"ltp":2.28,"tv":2641.92,"id":8444055}]}]}
{"op":"mcm","clk":"1010957807","pt":1580653869040,"mc":[{"id":"1.168223927","rc":[{"batl":[[0,1.79,32.12]],"ltp":1.76,"tv":2757.98,"id":8257852}]}]}
{"op":"mcm","clk":"1010958224","pt":1580653871060,"mc":[{"id":"1.168223927","rc":[{"batb":[[0,2.26,31.13]],"ltp":2.28,"tv":2641.92,"id":8444055}]}]}
{"op":"mcm","clk":"1010959702","pt":1580653877143,"mc":[{"id":"1.168223927","rc":[{"batl":[[1,2.4,2.04],[2,2.62,21.85]],"ltp":2.28,"tv":2641.92,"id":8444055},{"batb":[[0,1.75,141.15],[1,1.74,44.32],[2,1.73,38.55]],"batl":[[0,1.79,16.98]],"ltp":1.76,"tv":2757.98,"id":8257852}]}]}
{"op":"mcm","clk":"1010959892","pt":1580653878054,"mc":[{"id":"1.168223927","rc":[{"batl":[[1,2.36,2.07],[2,2.38,2.04]],"ltp":2.28,"tv":2641.92,"id":8444055},{"trd":[[1.76,636.7]],"batb":[[0,1.75,141.96],[1,1.74,46.34]],"batl":[[0,1.79,24.55]],"ltp":1.76,"tv":2767.5,"id":8257852}],"tv":5409.43}]}
{"op":"mcm","clk":"1010960125","pt":1580653879108,"mc":[{"id":"1.168223927","rc":[{"batl":[[1,2.38,2.04],[2,2.4,2.04]],"ltp":2.28,"tv":2641.92,"id":8444055},{"batb":[[1,1.74,44.32]],"ltp":1.76,"tv":2767.5,"id":8257852}]}]}
{"op":"mcm","clk":"1010960617","pt":1580653881179,"mc":[{"id":"1.168223927","rc":[{"batb":[[1,2.24,2.02],[2,2.2,21]],"ltp":2.28,"tv":2641.92,"id":8444055},{"batl":[[0,1.78,15.14],[1,1.79,24.55],[2,1.8,149.05]],"ltp":1.76,"tv":2767.5,"id":8257852}]}]}
{"op":"mcm","clk":"1010960864","pt":1580653882158,"mc":[{"id":"1.168223927","rc":[{"batb":[[2,2.22,2.02]],"ltp":2.28,"tv":2641.92,"id":8444055}]}]}
{"op":"mcm","clk":"1010961523","pt":1580653885062,"mc":[{"id":"1.168223927","rc":[{"batb":[[0,1.75,148.52]],"ltp":1.76,"tv":2767.5,"id":8257852}]}]}
{"op":"mcm","clk":"1010962521","pt":1580653889204,"mc":[{"id":"1.168223927","rc":[{"batl":[[0,1.77,17.17],[1,1.78,15.14],[2,1.79,7.57]],"ltp":1.76,"tv":2767.5,"id":8257852}]}]}
{"op":"mcm","clk":"1010962702","pt":1580653889904,"mc":[{"id":"1.168223927","rc":[{"batb":[[2,2.22,4.04]],"batl":[[2,2.4,4.08]],"ltp":2.28,"tv":2641.92,"id":8444055},{"batl":[[0,1.78,15.14],[1,1.79,7.57],[2,1.8,149.05]],"ltp":1.76,"tv":2767.5,"id":8257852}]}]}
{"op":"mcm","clk":"1010964352","pt":1580653897081,"mc":[{"id":"1.168223927","rc":[{"batb":[[0,2.28,13.33],[1,2.26,17.69],[2,2.24,2.02]],"ltp":2.28,"tv":2641.92,"id":8444055}]}]}
{"op":"mcm","clk":"1010964516","pt":1580653897773,"mc":[{"id":"1.168223927","rc":[{"batl":[[2,2.4,2.04]],"ltp":2.28,"tv":2641.92,"id":8444055}]}]}
{"op":"mcm","clk":"1010965747","pt":1580653903186,"mc":[{"id":"1.168223927","rc":[{"batl":[[0,1.77,17.17],[1,1.78,15.14],[2,1.79,9.64]],"ltp":1.76,"tv":2767.5,"id":8257852}]}]}
{"op":"mcm","clk":"1010974855","pt":1580653944177,"mc":[{"id":"1.168223927","rc":[{"batb":[[0,1.75,147.72]],"batl":[[1,1.79,2.07],[2,1.8,149.05]],"ltp":1.76,"tv":2767.5,"id":8257852}]}]}
{"op":"mcm","clk":"1010975559","pt":1580653947169,"mc":[{"id":"1.168223927","rc":[{"batb":[[0,2.26,31.02],[1,2.24,2.02],[2,2.22,2.02]],"ltp":2.28,"tv":2641.92,"id":8444055},{"trd":[[1.77,226.35]],"batb":[[0,1.76,6.56],[1,1.75,141.15],[2,1.74,44.32]],"batl":[[0,1.79,18.45],[1,1.8,149.05],[2,1.82,189.04]],"ltp":1.77,"tv":2769.09,"id":8257852}],"tv":5411.02}]}
{"op":"mcm","clk":"1010975773","pt":1580653948081,"mc":[{"id":"1.168223927","rc":[{"batb":[[1,2.22,2.02],[2,2.2,23.02]],"batl":[[0,2.38,2.04],[1,2.4,2.04],[2,2.62,21.85]],"ltp":2.28,"tv":2641.92,"id":8444055},{"batb":[[0,1.75,141.15],[1,1.74,44.32],[2,1.73,38.55]],"batl":[[0,1.79,16.38],[1,1.8,147.03],[2,1.81,2.13]],"ltp":1.77,"tv":2769.09,"id":8257852}]}]}
{"op":"mcm","clk":"1010978917","pt":1580653962099,"mc":[{"id":"1.168223927","rc":[{"batl":[[0,1.79,16.98]],"ltp":1.77,"tv":2769.09,"id":8257852}]}]}
{"op":"mcm","clk":"1010979034","pt":1580653962588,"mc":[{"id":"1.168223927","rc":[{"batl":[[1,2.4,2]],"ltp":2.28,"tv":2641.92,"id":8444055}]}]}
{"op":"mcm","clk":"1010983640","pt":1580653984174,"mc":[{"id":"1.168223927","rc":[{"batl":[[0,2.34,5.63],[1,2.38,2.04],[2,2.4,2]],"ltp":2.28,"tv":2641.92,"id":8444055},{"batb":[[0,1.76,7.36],[1,1.75,141.15],[2,1.74,44.32]],"ltp":1.77,"tv":2769.09,"id":8257852}]}]}
{"op":"mcm","clk":"1010983865","pt":1580653985264,"mc":[{"id":"1.168223927","rc":[{"batl":[[1,2.36,2.07],[2,2.62,21.85]],"ltp":2.28,"tv":2641.92,"id":8444055},{"trd":[[1.76,650.05]],"batb":[[0,1.75,141.84],[1,1.74,46.32],[2,1.73,36.42]],"ltp":1.76,"tv":2782.44,"id":8257852}],"tv":5424.37}]}
{"op":"mcm","clk":"1010984015","pt":1580653985963,"mc":[{"id":"1.168223927","rc":[{"batl":[[1,2.38,2.04],[2,2.4,2.04]],"ltp":2.28,"tv":2641.92,"id":8444055},{"batb":[[1,1.74,44.32],[2,1.73,38.44]],"ltp":1.76,"tv":2782.44,"id":8257852}]}]}
{"op":"mcm","clk":"1010985288","pt":1580653991776,"mc":[{"id":"1.168223927","rc":[{"batl":[[0,2.38,2.69],[1,2.4,2.04],[2,2.42,2.02]],"ltp":2.28,"tv":2641.92,"id":8444055},{"batb":[[0,1.75,141.15]],"ltp":1.76,"tv":2782.44,"id":8257852}]}]}
{"op":"mcm","clk":"1010986044","pt":1580653995121,"mc":[{"id":"1.168223927","rc":[{"batl":[[0,1.78,7.57],[1,1.79,16.98],[2,1.8,147.03]],"ltp":1.76,"tv":2782.44,"id":8257852}]}]}
{"op":"mcm","clk":"1010986277","pt":1580653996180,"mc":[{"id":"1.168223927","rc":[{"batb":[[1,2.24,2.02],[2,2.22,2.02]],"ltp":2.28,"tv":2641.92,"id":8444055},{"batl":[[2,1.8,149.04]],"ltp":1.76,"tv":2782.44,"id":8257852}]}]}
{"op":"mcm","clk":"1010986492","pt":1580653997155,"mc":[{"id":"1.168223927","rc":[{"batl":[[2,2.62,21.85]],"ltp":2.28,"tv":2641.92,"id":8444055},{"batl":[[0,1.78,15.14]],"ltp":1.76,"tv":2782.44,"id":8257852}]}]}
{"op":"mcm","clk":"1010988025","pt":1580654004200,"mc":[{"id":"1.168223927","rc":[{"batb":[[0,2.26,17.69]],"ltp":2.28,"tv":2641.92,"id":8444055},{"batl":[[0,1.77,17.17],[1,1.78,15.14]],"ltp":1.76,"tv":2782.44,"id":8257852}]}]}
{"op":"mcm","clk":"1010988184","pt":1580654004898,"mc":[{"id":"1.168223927","rc":[{"batb":[[0,2.28,13.33],[1,2.26,17.69],[2,2.24,2.02]],"ltp":2.28,"tv":2641.92,"id":8444055},{"batl":[[2,1.79,2.07]],"ltp":1.76,"tv":2782.44,"id":8257852}]}]}
{"op":"mcm","clk":"1010998036","pt":1580654048931,"mc":[{"id":"1.168223927","rc":[{"trd":[[1.75,394.01]],"batb":[[0,1.75,132.44]],"ltp":1.75,"tv":2799.87,"id":8257852}],"tv":5441.79}]}
{"op":"mcm","clk":"1011000504","pt":1580654059741,"mc":[{"id":"1.168223927","rc":[{"batb":[[0,1.75,133.13]],"ltp":1.75,"tv":2799.87,"id":8257852}]}]}
{"op":"mcm","clk":"1011021768","pt":1580654150113,"mc":[{"id":"1.168223927","rc":[{"batl":[[1,1.79,2.07],[2,1.8,149.05]],"ltp":1.75,"tv":2799.87,"id":8257852}]}]}
{"op":"mcm","clk":"1011023784","pt":1580654158092,"mc":[{"id":"1.168223927","rc":[{"batb":[[0,2.26,31.02],[1,2.22,2.02],[2,2.2,23.02]],"batl":[[0,2.4,2.04],[1,2.42,2.06]],"ltp":2.28,"tv":2641.92,"id":8444055},{"batb":[[0,1.75,132.44]],"batl":[[0,1.79,17.17],[1,1.8,147.03],[2,1.81,2.13]],"ltp":1.75,"tv":2799.87,"id":8257852}]}]}
{"op":"mcm","clk":"1011023830","pt":1580654158279,"mc":[{"id":"1.168223927","rc":[{"batl":[[0,2.38,2.04],[1,2.4,2.04],[2,2.42,2.06]],"ltp":2.28,"tv":2641.92,"id":8444055}]}]}
{"op":"mcm","clk":"1011024521","pt":1580654161012,"mc":[{"id":"1.168223927","rc":[{"batl":[[0,1.78,15.14],[1,1.79,17.17],[2,1.8,149.05]],"ltp":1.75,"tv":2799.87,"id":8257852}]}]}
{"op":"mcm","clk":"1011024783","pt":1580654162206,"mc":[{"id":"1.168223927","rc":[{"batb":[[1,2.24,2.02],[2,2.22,2.02]],"ltp":2.28,"tv":2641.92,"id":8444055}]}]}
{"op":"mcm","clk":"1011029023","pt":1580654180997,"mc":[{"id":"1.168223927","rc":[{"batl":[[2,2.62,21.85]],"ltp":2.28,"tv":2641.92,"id":8444055},{"batl":[[0,1.77,17.17],[1,1.78,15.14],[2,1.79,2.07]],"ltp":1.75,"tv":2799.87,"id":8257852}]}]}
{"op":"mcm","clk":"1011030428","pt":1580654187214,"mc":[{"id":"1.168223927","rc":[{"batb":[[0,2.28,13.33],[1,2.26,17.69],[2,2.24,2.02]],"batl":[[0,2.38,2.69],[1,2.62,21.85],[2,2.76,1.68]],"ltp":2.28,"tv":2641.92,"id":8444055},{"batb":[[0,1.75,133.13]],"ltp":1.75,"tv":2799.87,"id":8257852}]}]}
{"op":"mcm","clk":"1011030551","pt":1580654187714,"mc":[{"id":"1.168223927","rc":[{"batl":[[1,2.4,2.04],[2,2.62,21.85]],"ltp":2.28,"tv":2641.92,"id":8444055}]}]}
{"op":"mcm","clk":"1011079210","pt":1580654407249,"mc":[{"id":"1.168223927","rc":[{"batl":[[1,2.62,21.85],[2,2.76,1.68]],"ltp":2.28,"tv":2641.92,"id":8444055},{"batl":[[1,1.79,2.07],[2,1.8,147.03]],"ltp":1.75,"tv":2799.87,"id":8257852}]}]}
{"op":"mcm","clk":"1011079241","pt":1580654407393,"mc":[{"id":"1.168223927","rc":[{"batl":[[1,2.4,2.04],[2,2.62,21.85]],"ltp":2.28,"tv":2641.92,"id":8444055},{"batl":[[2,1.8,149.05]],"ltp":1.75,"tv":2799.87,"id":8257852}]}]}
{"op":"mcm","clk":"1011079819","pt":1580654410154,"mc":[{"id":"1.168223927","rc":[{"batb":[[0,2.26,31.02],[1,2.22,2.02],[2,2.2,23]],"batl":[[0,2.4,2.04],[1,2.42,2.06]],"ltp":2.28,"tv":2641.92,"id":8444055},{"batb":[[0,1.75,132.44]],"batl":[[0,1.79,17.17],[1,1.8,147.03],[2,1.81,2.13]],"ltp":1.75,"tv":2799.87,"id":8257852}]}]}
{"op":"mcm","clk":"1011079862","pt":1580654410356,"mc":[{"id":"1.168223927","rc":[{"batl":[[0,2.38,2.04],[1,2.4,2.04],[2,2.42,2.06]],"ltp":2.28,"tv":2641.92,"id":8444055}]}]}
{"op":"mcm","clk":"1011082249","pt":1580654421214,"mc":[{"id":"1.168223927","rc":[{"trd":[[2.26,2244.59]],"batb":[[0,2.22,26.39],[1,2.2,2.02],[2,2.18,23.38]],"batl":[[2,2.62,21.85]],"ltp":2.26,"tv":2714.95,"id":8444055},{"trd":[[1.79,134.89]],"batb":[[0,1.76,41.09],[1,1.75,132.44],[2,1.74,2.02]],"batl":[[0,1.79,3.32]],"ltp":1.79,"tv":2813.72,"id":8257852}],"tv":5528.67}]}
{"op":"mcm","clk":"1011082462","pt":1580654422132,"mc":[{"id":"1.168223927","rc":[{"batl":[[0,2.36,2.07],[1,2.38,2.04],[2,2.4,2.04]],"ltp":2.26,"tv":2714.95,"id":8444055}]}]}
{"op":"mcm","clk":"1011082694","pt":1580654423344,"mc":[{"id":"1.168223927","rc":[{"batl":[[0,1.79,10.89]],"ltp":1.79,"tv":2813.72,"id":8257852}]}]}
{"op":"mcm","clk":"1011083086","pt":1580654425179,"mc":[{"id":"1.168223927","rc":[{"batb":[[0,2.28,19],[1,2.22,2.02],[2,2.2,2.02]],"batl":[[0,2.38,2.04],[1,2.4,2.04],[2,2.62,21.85]],"ltp":2.26,"tv":2714.95,"id":8444055},{"trd":[[1.76,729.37]],"batb":[[0,1.75,132.44],[1,1.74,27.31],[2,1.73,38.55]],"batl":[[0,1.76,3.32],[1,1.78,2.02],[2,1.79,9.59]],"ltp":1.76,"tv":2893.04,"id":8257852}],"tv":5607.99}]}
{"op":"mcm","clk":"1011083304","pt":1580654426153,"mc":[{"id":"1.168223927","rc":[{"batb":[[1,2.26,2.21],[2,2.24,2.02]],"ltp":2.26,"tv":2714.95,"id":8444055},{"batl":[[1,1.78,2.25],[2,1.79,9.64]],"ltp":1.76,"tv":2893.04,"id":8257852}]}]}
{"op":"mcm","clk":"1011086343","pt":1580654440155,"mc":[{"id":"1.168223927","rc":[{"batb":[[2,2.2,21]],"batl":[[1,2.62,21.85],[2,2.76,1.68]],"ltp":2.26,"tv":2714.95,"id":8444055},{"batl":[[0,1.79,7.57],[1,1.8,149.05],[2,1.81,2.02]],"ltp":1.76,"tv":2893.04,"id":8257852}]}]}
{"op":"mcm","clk":"1011086431","pt":1580654440591,"mc":[{"id":"1.168223927","rc":[{"batb":[[1,2.24,2.02],[2,2.22,2.02]],"batl":[[1,2.4,2.04],[2,2.62,21.85]],"ltp":2.26,"tv":2714.95,"id":8444055},{"batl":[[1,1.8,147.03]],"ltp":1.76,"tv":2893.04,"id":8257852}]}]}
{"op":"mcm","clk":"1011089182","pt":1580654453207,"mc":[{"id":"1.168223927","rc":[{"batl":[[0,2.32,12.99],[1,2.36,2.07]],"ltp":2.26,"tv":2714.95,"id":8444055},{"batb":[[0,1.75,147.16]],"batl":[[0,1.79,10.7]],"ltp":1.76,"tv":2893.04,"id":8257852}]}]}
{"op":"mcm","clk":"1011089268","pt":1580654453589,"mc":[{"id":"1.168223927","rc":[{"batl":[[2,2.38,2.04]],"ltp":2.26,"tv":2714.95,"id":8444055}]}]}
{"op":"mcm","clk":"1011091584","pt":1580654464255,"mc":[{"id":"1.168223927","rc":[{"batl":[[0,1.79,24.55]],"ltp":1.76,"tv":2893.04,"id":8257852}]}]}
{"op":"mcm","clk":"1011091674","pt":1580654464590,"mc":[{"id":"1.168223927","rc":[{"trd":[[2.32,47.12]],"batl":[[0,2.38,2.46],[1,2.4,2.04],[2,2.62,21.85]],"ltp":2.32,"tv":2740.1,"id":8444055}],"tv":5633.14}]}
{"op":"mcm","clk":"1011093889","pt":1580654474993,"mc":[{"id":"1.168223927","rc":[{"batl":[[0,2.38,2.04]],"ltp":2.32,"tv":2740.1,"id":8444055}]}]}
{"op":"mcm","clk":"1011096854","pt":1580654488245,"mc":[{"id":"1.168223927","rc":[{"batb":[[1,2.26,13.33],[2,2.24,2.02]],"batl":[[1,2.4,2]],"ltp":2.32,"tv":2740.1,"id":8444055}]}]}
{"op":"mcm","clk":"1011096893","pt":1580654488356,"mc":[{"id":"1.168223927","rc":[{"batl":[[0,2.38,2.46]],"ltp":2.32,"tv":2740.1,"id":8444055}]}]}
{"op":"mcm","clk":"1011104170","pt":1580654522081,"mc":[{"id":"1.168223927","rc":[{"batl":[[1,2.4,2.04]],"ltp":2.32,"tv":2740.1,"id":8444055},{"batl":[[0,1.78,7.57],[1,1.79,24.55],[2,1.8,149.03]],"ltp":1.76,"tv":2893.04,"id":8257852}]}]}
{"op":"mcm","clk":"1011106416","pt":1580654532174,"mc":[{"id":"1.168223927","rc":[{"batb":[[0,2.28,32.33],[1,2.24,2.02],[2,2.22,2.02]],"ltp":2.32,"tv":2740.1,"id":8444055},{"batl":[[1,1.79,7.57]],"ltp":1.76,"tv":2893.04,"id":8257852}]}]}
{"op":"mcm","clk":"1011108568","pt":1580654542111,"mc":[{"id":"1.168223927","rc":[{"batb":[[0,2.28,19],[1,2.26,13.33],[2,2.24,2.02]],"batl":[[1,2.62,21.85],[2,2.76,1.68]],"ltp":2.32,"tv":2740.1,"id":8444055},{"batl":[[0,1.78,24.65]],"ltp":1.76,"tv":2893.04,"id":8257852}]}]}
{"op":"mcm","clk":"1011108618","pt":1580654542281,"mc":[{"id":"1.168223927","rc":[{"batl":[[1,2.4,2.04],[2,2.62,21.85]],"ltp":2.32,"tv":2740.1,"id":8444055}]}]}
{"op":"mcm","clk":"1011112418","pt":1580654559184,"mc":[{"id":"1.168223927","rc":[{"batl":[[0,1.78,32.22]],"ltp":1.76,"tv":2893.04,"id":8257852}]}]}
{"op":"mcm","clk":"1011112692","pt":1580654560409,"mc":[{"id":"1.168223927","rc":[{"batl":[[0,1.78,17.07]],"ltp":1.76,"tv":2893.04,"id":8257852}]}]}
{"op":"mcm","clk":"1011113144","pt":1580654562308,"mc":[{"id":"1.168223927","rc":[{"batl":[[1,1.8,149.03],[2,1.81,2.13]],"ltp":1.76,"tv":2893.04,"id":8257852}]}]}
{"op":"mcm","clk":"1011113479","pt":1580654563923,"mc":[{"id":"1.168223927","rc":[{"batl":[[0,1.79,17.07],[1,1.8,147.03]],"ltp":1.76,"tv":2893.04,"id":8257852}]}]}
{"op":"mcm","clk":"1011113999","pt":1580654566243,"mc":[{"id":"1.168223927","rc":[{"batl":[[0,1.78,15.14],[1,1.79,17.07],[2,1.8,149.05]],"ltp":1.76,"tv":2893.04,"id":8257852}]}]}
{"op":"mcm","clk":"1011115085","pt":1580654571143,"mc":[{"id":"1.168223927","rc":[{"batb":[[0,2.28,32.33],[1,2.24,2.02],[2,2.2,21]],"batl":[[1,2.62,21.85],[2,2.76,1.68]],"ltp":2.32,"tv":2740.1,"id":8444055}]}]}
{"op":"mcm","clk":"1011115326","pt":1580654572126,"mc":[{"id":"1.168223927","rc":[{"batb":[[2,2.22,2]],"batl":[[1,2.4,2.04],[2,2.62,21.85]],"ltp":2.32,"tv":2740.1,"id":8444055}]}]}
{"op":"mcm","clk":"1011116201","pt":1580654576257,"mc":[{"id":"1.168223927","rc":[{"batl":[[0,1.77,17.07],[1,1.78,15.14],[2,1.79,2]],"ltp":1.76,"tv":2893.04,"id":8257852}]}]}
{"op":"mcm","clk":"1011116402","pt":1580654577137,"mc":[{"id":"1.168223927","rc":[{"batb":[[2,2.22,2.02]],"ltp":2.32,"tv":2740.1,"id":8444055}]}]}
{"op":"mcm","clk":"1011118179","pt":1580654585152,"mc":[{"id":"1.168223927","rc":[{"batb":[[2,2.2,21]],"batl":[[1,2.62,21.85],[2,2.76,1.68]],"ltp":2.32,"tv":2740.1,"id":8444055},{"batl":[[0,1.77,17.17]],"ltp":1.76,"tv":2893.04,"id":8257852}]}]}
{"op":"mcm","clk":"1011118229","pt":1580654585370,"mc":[{"id":"1.168223927","rc":[{"batb":[[2,2.22,2.02]],"batl":[[1,2.4,2.04],[2,2.62,21.85]],"ltp":2.32,"tv":2740.1,"id":8444055}]}]}
{"op":"mcm","clk":"1011122683","pt":1580654605169,"mc":[{"id":"1.168223927","rc":[{"trd":[[2.32,47.54]],"batb":[[0,2.28,34.49],[1,2.26,2.21],[2,2.24,22.34]],"batl":[[0,2.4,2.04],[1,2.42,2.06]],"ltp":2.32,"tv":2740.52,"id":8444055},{"trd":[[1.75,688.91]],"batb":[[0,1.74,27.31],[1,1.73,36.42],[2,1.72,2.09]],"batl":[[0,1.75,79.43],[1,1.77,19.19],[2,1.78,17.39]],"ltp":1.75,"tv":3187.94,"id":8257852}],"tv":5928.46}]}
{"op":"mcm","clk":"1011122731","pt":1580654605387,"mc":[{"id":"1.168223927","rc":[{"batb":[[2,2.24,20.32]],"ltp":2.32,"tv":2740.52,"id":8444055}]}]}
{"op":"mcm","clk":"1011123345","pt":1580654608086,"mc":[{"id":"1.168223927","rc":[{"batb":[[0,2.3,13.33],[1,2.28,21.16],[2,2.26,2.21]],"ltp":2.32,"tv":2740.52,"id":8444055},{"batl":[[0,1.75,96.8],[1,1.77,9.59]],"ltp":1.75,"tv":3187.94,"id":8257852}]}]}
{"op":"mcm","clk":"1011123568","pt":1580654609076,"mc":[{"id":"1.168223927","rc":[{"batl":[[2,1.78,2.25]],"ltp":1.75,"tv":3187.94,"id":8257852}]}]}
{"op":"mcm","clk":"1011127723","pt":1580654627203,"mc":[{"id":"1.168223927","rc":[{"batb":[[1,2.28,2.16],[2,2.24,20.32]],"batl":[[1,2.62,21.85],[2,2.76,1.68]],"ltp":2.32,"tv":2740.52,"id":8444055},{"trd":[[1.75,717.57]],"batb":[[0,1.73,36.42],[1,1.72,2.09],[2,1.69,129.48]],"batl":[[0,1.75,82.47],[2,1.8,147.03]],"ltp":1.75,"tv":3216.59,"id":8257852}],"tv":5957.11}]}
{"op":"mcm","clk":"1011127894","pt":1580654627887,"mc":[{"id":"1.168223927","rc":[{"batb":[[2,2.26,43.84]],"batl":[[0,2.42,2.06],[1,2.44,2.08],[2,2.62,21.85]],"ltp":2.32,"tv":2740.52,"id":8444055},{"batb":[[1,1.71,2],[2,1.7,69.76]],"batl":[[2,1.78,2.02]],"ltp":1.75,"tv":3216.59,"id":8257852}]}]}
{"op":"mcm","clk":"1011128625","pt":1580654631211,"mc":[{"id":"1.168223927","rc":[{"batb":[[0,1.73,6.85]],"ltp":1.75,"tv":3216.59,"id":8257852}]}]}
{"op":"mcm","clk":"1011128840","pt":1580654632227,"mc":[{"id":"1.168223927","rc":[{"batb":[[2,2.26,63.84]],"ltp":2.32,"tv":2740.52,"id":8444055}]}]}
{"op":"mcm","clk":"1011129957","pt":1580654637122,"mc":[{"id":"1.168223927","rc":[{"batb":[[2,2.26,63.92]],"batl":[[1,2.44,2.02]],"ltp":2.32,"tv":2740.52,"id":8444055},{"batb":[[2,1.7,90.21]],"batl":[[2,1.78,2.25]],"ltp":1.75,"tv":3216.59,"id":8257852}]}]}
{"op":"mcm","clk":"1011132193","pt":1580654646944,"mc":[{"id":"1.168223927","rc":[{"batb":[[0,2.28,2.16],[1,2.26,63.92],[2,2.24,20.32]],"ltp":2.32,"tv":2740.52,"id":8444055},{"batl":[[0,1.75,65.11]],"ltp":1.75,"tv":3216.59,"id":8257852}]}]}
{"op":"mcm","clk":"1011132344","pt":1580654647528,"mc":[{"id":"1.168223927","rc":[{"batl":[[1,2.44,2.08]],"ltp":2.32,"tv":2740.52,"id":8444055},{"batb":[[2,1.7,90.19]],"ltp":1.75,"tv":3216.59,"id":8257852}]}]}
{"op":"mcm","clk":"1011133497","pt":1580654652241,"mc":[{"id":"1.168223927","rc":[{"batb":[[0,2.3,2.08],[1,2.28,2.16],[2,2.26,63.92]],"ltp":2.32,"tv":2740.52,"id":8444055},{"batl":[[0,1.74,17.46],[1,1.75,65.11],[2,1.76,2.02]],"ltp":1.75,"tv":3216.59,"id":8257852}]}]}
{"op":"mcm","clk":"1011133746","pt":1580654653246,"mc":[{"id":"1.168223927","rc":[{"batb":[[1,2.28,21.7],[2,2.26,61.71]],"ltp":2.32,"tv":2740.52,"id":8444055},{"batb":[[2,1.7,90.21]],"ltp":1.75,"tv":3216.59,"id":8257852}]}]}
{"op":"mcm","clk":"1011138205","pt":1580654672970,"mc":[{"id":"1.168223927","rc":[{"batb":[[1,2.28,21.85]],"ltp":2.32,"tv":2740.52,"id":8444055},{"batl":[[1,1.76,2.02],[2,1.77,9.59]],"ltp":1.75,"tv":3216.59,"id":8257852}]}]}
{"op":"mcm","clk":"1011138873","pt":1580654676069,"mc":[{"id":"1.168223927","rc":[{"batl":[[0,1.76,19.48],[1,1.77,9.59],[2,1.8,147.03]],"ltp":1.75,"tv":3216.59,"id":8257852}]}]}
{"op":"mcm","clk":"1011139116","pt":1580654677178,"mc":[{"id":"1.168223927","rc":[{"batb":[[0,2.26,63.92],[1,2.24,22.34],[2,2.2,21]],"ltp":2.32,"tv":2740.52,"id":8444055},{"batl":[[0,1.76,17.46],[1,1.77,7.57],[2,1.78,2.25]],"ltp":1.75,"tv":3216.59,"id":8257852}]}]}
{"op":"mcm","clk":"1011140394","pt":1580654683085,"mc":[{"id":"1.168223927","rc":[{"batl":[[0,1.75,41.21],[1,1.76,17.46],[2,1.77,7.57]],"ltp":1.75,"tv":3216.59,"id":8257852}]}]}
{"op":"mcm","clk":"1011140671","pt":1580654684168,"mc":[{"id":"1.168223927","rc":[{"batb":[[0,2.28,2.16],[1,2.26,63.71],[2,2.24,20.32]],"batl":[[1,2.44,2]],"ltp":2.32,"tv":2740.52,"id":8444055},{"batl":[[2,1.77,9.59]],"ltp":1.75,"tv":3216.59,"id":8257852}]}]}
{"op":"mcm","clk":"1011141478","pt":1580654688260,"mc":[{"id":"1.168223927","rc":[{"batb":[[0,2.3,2.08],[1,2.28,2.16],[2,2.26,63.71]],"ltp":2.32,"tv":2740.52,"id":8444055},{"batl":[[0,1.74,17.46],[1,1.75,41.21],[2,1.76,2.02]],"ltp":1.75,"tv":3216.59,"id":8257852}]}]}
{"op":"mcm","clk":"1011141662","pt":1580654689183,"mc":[{"id":"1.168223927","rc":[{"batb":[[1,2.28,21.85]],"ltp":2.32,"tv":2740.52,"id":8444055}]}]}
{"op":"mcm","clk":"1011141840","pt":1580654690094,"mc":[{"id":"1.168223927","rc":[{"batb":[[1,2.28,21.74],[2,2.26,61.71]],"batl":[[1,2.44,2.08]],"ltp":2.32,"tv":2740.52,"id":8444055}]}]}
{"op":"mcm","clk":"1011143499","pt":1580654698192,"mc":[{"id":"1.168223927","rc":[{"batb":[[0,2.34,2.22],[1,2.32,2.01],[2,2.3,2.08]],"batl":[[0,2.46,2.12],[1,2.48,2.24]],"ltp":2.32,"tv":2740.52,"id":8444055},{"trd":[[1.72,123.23],[1.73,13.7]],"batb":[[0,1.72,235.22],[1,1.7,88.19],[2,1.69,129.48]],"batl":[[0,1.74,19.71],[1,1.75,43.23],[2,1.77,7.57]],"ltp":1.72,"tv":3346.8,"id":8257852}],"tv":6087.32}]}
{"op":"mcm","clk":"1011143711","pt":1580654699215,"mc":[{"id":"1.168223927","rc":[{"batb":[[0,2.3,2],[1,2.28,2.16],[2,2.26,61.71]],"batl":[[0,2.44,2],[1,2.46,2.12],[2,2.48,2.24]],"ltp":2.32,"tv":2740.52,"id":8444055},{"batb":[[0,1.72,403.45],[1,1.7,90.21],[2,1.69,131.69]],"batl":[[0,1.74,17.46],[1,1.75,41.21],[2,1.76,2.02]],"ltp":1.72,"tv":3346.8,"id":8257852}]}]}
{"op":"mcm","clk":"1011144407","pt":1580654702126,"mc":[{"id":"1.168223927","rc":[{"batb":[[1,1.7,69.76]],"ltp":1.72,"tv":3346.8,"id":8257852}]}]}
{"op":"mcm","clk":"1011144672","pt":1580654703078,"mc":[{"id":"1.168223927","rc":[{"batl":[[2,2.5,2.01]],"ltp":2.32,"tv":2740.52,"id":8444055},{"batb":[[0,1.7,69.76],[1,1.69,131.69],[2,1.68,2]],"ltp":1.72,"tv":3346.8,"id":8257852}]}]}
{"op":"mcm","clk":"1011144957","pt":1580654704216,"mc":[{"id":"1.168223927","rc":[{"batb":[[1,2.28,21.85]],"batl":[[0,2.48,2.16],[1,2.5,2.01],[2,2.62,21.85]],"ltp":2.32,"tv":2740.52,"id":8444055},{"batb":[[0,1.7,67.74],[1,1.69,129.48]],"ltp":1.72,"tv":3346.8,"id":8257852}]}]}
{"op":"mcm","clk":"1011145415","pt":1580654706197,"mc":[{"id":"1.168223927","rc":[{"batb":[[1,2.28,2.16]],"ltp":2.32,"tv":2740.52,"id":8444055}]}]}
{"op":"mcm","clk":"1011145908","pt":1580654708226,"mc":[{"id":"1.168223927","rc":[{"batb":[[0,1.71,7.57],[1,1.7,92.63],[2,1.69,129.48]],"ltp":1.72,"tv":3346.8,"id":8257852}]}]}
{"op":"mcm","clk":"1011146130","pt":1580654709217,"mc":[{"id":"1.168223927","rc":[{"batb":[[1,2.26,61.71],[2,2.24,20.32]],"batl":[[0,2.46,2.12],[1,2.62,21.85],[2,2.76,1.68]],"ltp":2.32,"tv":2740.52,"id":8444055},{"batb":[[0,1.71,22.72],[2,1.69,131.69]],"ltp":1.72,"tv":3346.8,"id":8257852}]}]}
{"op":"mcm","clk":"1011146201","pt":1580654709527,"mc":[{"id":"1.168223927","rc":[{"batb":[[1,2.28,2.05],[2,2.26,61.71]],"batl":[[1,2.48,2.24],[2,2.62,21.85]],"ltp":2.32,"tv":2740.52,"id":8444055}]}]}
{"op":"mcm","clk":"1011146587","pt":1580654711355,"mc":[{"id":"1.168223927","rc":[{"batb":[[0,1.71,30.29]],"ltp":1.72,"tv":3346.8,"id":8257852}]}]}
{"op":"mcm","clk":"1011147032","pt":1580654713202,"mc":[{"id":"1.168223927","rc":[{"batl":[[0,2.44,2.08],[1,2.46,2.12],[2,2.48,2.24]],"ltp":2.32,"tv":2740.52,"id":8444055},{"batb":[[0,1.72,7.57],[1,1.71,30.29],[2,1.7,94.65]],"ltp":1.72,"tv":3346.8,"id":8257852}]}]}
{"op":"mcm","clk":"1011147204","pt":1580654713993,"mc":[{"id":"1.168223927","rc":[{"batb":[[2,1.7,69.76]],"ltp":1.72,"tv":3346.8,"id":8257852}]}]}
{"op":"mcm","clk":"1011147543","pt":1580654715643,"mc":[{"id":"1.168223927","rc":[{"batb":[[0,1.71,30.29],[1,1.7,69.76],[2,1.69,131.53]],"ltp":1.72,"tv":3346.8,"id":8257852}]}]}
{"op":"mcm","clk":"1011147782","pt":1580654716706,"mc":[{"id":"1.168223927","rc":[{"batb":[[0,1.72,3.03],[1,1.71,30.29],[2,1.7,69.76]],"ltp":1.72,"tv":3346.8,"id":8257852}]}]}
{"op":"mcm","clk":"1011148044","pt":1580654717932,"mc":[{"id":"1.168223927","rc":[{"batb":[[1,2.28,2.16]],"batl":[[2,2.62,21.85]],"ltp":2.32,"tv":2740.52,"id":8444055},{"batb":[[1,1.7,69.76],[2,1.69,131.53]],"ltp":1.72,"tv":3346.8,"id":8257852}]}]}
{"op":"mcm","clk":"1011148326","pt":1580654719269,"mc":[{"id":"1.168223927","rc":[{"batb":[[1,1.71,3.03],[2,1.7,94.65]],"ltp":1.72,"tv":3346.8,"id":8257852}]}]}
{"op":"mcm","clk":"1011148511","pt":1580654720230,"mc":[{"id":"1.168223927","rc":[{"batb":[[1,1.71,6.06]],"ltp":1.72,"tv":3346.8,"id":8257852}]}]}
{"op":"mcm","clk":"1011157627","pt":1580654764078,"mc":[{"id":"1.168223927","rc":[{"batb":[[1,2.28,2.05]],"ltp":2.32,"tv":2740.52,"id":8444055}]}]}
{"op":"mcm","clk":"1011158947","pt":1580654770148,"mc":[{"id":"1.168223927","rc":[{"batb":[[1,2.28,2.16]],"batl":[[0,2.46,2.1],[1,2.48,2.08]],"ltp":2.32,"tv":2740.52,"id":8444055},{"batb":[[0,1.71,6.06],[1,1.7,92.63],[2,1.69,131.48]],"ltp":1.72,"tv":3346.8,"id":8257852}]}]}
{"op":"mcm","clk":"1011159157","pt":1580654771170,"mc":[{"id":"1.168223927","rc":[{"batb":[[0,1.71,21.2]],"ltp":1.72,"tv":3346.8,"id":8257852}]}]}
{"op":"mcm","clk":"1011159580","pt":1580654773060,"mc":[{"id":"1.168223927","rc":[{"batb":[[0,1.71,36.35]],"ltp":1.72,"tv":3346.8,"id":8257852}]}]}
{"op":"mcm","clk":"1011159847","pt":1580654774250,"mc":[{"id":"1.168223927","rc":[{"batb":[[1,1.7,67.74]],"ltp":1.72,"tv":3346.8,"id":8257852}]}]}
{"op":"mcm","clk":"1011160201","pt":1580654775979,"mc":[{"id":"1.168223927","rc":[{"trd":[[2.34,0.5]],"batl":[[1,2.48,2.16]],"ltp":2.34,"tv":2741.02,"id":8444055},{"trd":[[1.74,52.02]],"batb":[[0,1.71,43.92]],"batl":[[0,1.74,16.79]],"ltp":1.74,"tv":3347.48,"id":8257852}],"tv":6088.5}]}
{"op":"mcm","clk":"1011160474","pt":1580654777271,"mc":[{"id":"1.168223927","rc":[{"batb":[[1,2.28,11.97]],"ltp":2.34,"tv":2741.02,"id":8444055},{"trd":[[1.74,77.95]],"batb":[[0,1.72,34.28],[1,1.71,43.92]],"batl":[[0,1.74,3.82]],"ltp":1.74,"tv":3373.41,"id":8257852}],"tv":6114.44}]}
{"op":"mcm","clk":"1011160582","pt":1580654777863,"mc":[{"id":"1.168223927","rc":[{"batl":[[0,2.44,2.04],[1,2.46,2.1],[2,2.48,2.16]],"ltp":2.34,"tv":2741.02,"id":8444055},{"batb":[[2,1.7,2]],"ltp":1.74,"tv":3373.41,"id":8257852}]}]}
{"op":"mcm","clk":"1011160795","pt":1580654778997,"mc":[{"id":"1.168223927","rc":[{"batb":[[2,2.26,41.71]],"ltp":2.34,"tv":2741.02,"id":8444055},{"batb":[[0,1.72,41.14]],"ltp":1.74,"tv":3373.41,"id":8257852}]}]}
{"op":"mcm","clk":"1011162260","pt":1580654786197,"mc":[{"id":"1.168223927","rc":[{"batb":[[1,2.28,9.81],[2,2.26,61.71]],"batl":[[1,2.62,21.85],[2,2.76,1.68]],"ltp":2.34,"tv":2741.02,"id":8444055},{"batb":[[0,1.72,48.71]],"batl":[[0,1.74,17.46]],"ltp":1.74,"tv":3373.41,"id":8257852}]}]}
{"op":"mcm","clk":"1011162294","pt":1580654786414,"mc":[{"id":"1.168223927","rc":[{"batb":[[1,2.28,11.97]],"batl":[[1,2.46,2.12],[2,2.62,21.85]],"ltp":2.34,"tv":2741.02,"id":8444055}]}]}
{"op":"mcm","clk":"1011162641","pt":1580654788135,"mc":[{"id":"1.168223927","rc":[{"batb":[[0,1.72,33.57]],"batl":[[1,1.76,2.02],[2,1.77,9.59]],"ltp":1.74,"tv":3373.41,"id":8257852}]}]}
{"op":"mcm","clk":"1011162768","pt":1580654788701,"mc":[{"id":"1.168223927","rc":[{"batb":[[1,1.7,2],[2,1.69,131.69]],"batl":[[0,1.74,58.67]],"ltp":1.74,"tv":3373.41,"id":8257852}]}]}
{"op":"mcm","clk":"1011163024","pt":1580654790004,"mc":[{"id":"1.168223927","rc":[{"batb":[[0,1.72,60.29]],"ltp":1.74,"tv":3373.41,"id":8257852}]}]}
{"op":"mcm","clk":"1011163462","pt":1580654792106,"mc":[{"id":"1.168223927","rc":[{"batb":[[1,2.28,9.81]],"batl":[[1,2.62,21.85],[2,2.76,1.68]],"ltp":2.34,"tv":2741.02,"id":8444055},{"batb":[[1,1.7,17.14],[2,1.69,129.48]],"batl":[[2,1.77,7.57]],"ltp":1.74,"tv":3373.41,"id":8257852}]}]}
{"op":"mcm","clk":"1011163516","pt":1580654792285,"mc":[{"id":"1.168223927","rc":[{"batb":[[1,2.28,11.86]],"batl":[[1,2.46,2.12],[2,2.62,21.85]],"ltp":2.34,"tv":2741.02,"id":8444055},{"batb":[[2,1.69,131.53]],"batl":[[2,1.77,9.59]],"ltp":1.74,"tv":3373.41,"id":8257852}]}]}
{"op":"mcm","clk":"1011170293","pt":1580654826047,"mc":[{"id":"1.168223927","rc":[{"batl":[[0,1.74,41.21]],"ltp":1.74,"tv":3373.41,"id":8257852}]}]}
{"op":"mcm","clk":"1011170393","pt":1580654826532,"mc":[{"id":"1.168223927","rc":[{"batb":[[1,2.28,11.97]],"ltp":2.34,"tv":2741.02,"id":8444055},{"batb":[[2,1.69,131.5]],"ltp":1.74,"tv":3373.41,"id":8257852}]}]}
{"op":"mcm","clk":"1011171302","pt":1580654831232,"mc":[{"id":"1.168223927","rc":[{"batb":[[0,2.32,2.14],[1,2.3,2],[2,2.28,11.97]],"ltp":2.34,"tv":2741.02,"id":8444055},{"batl":[[0,1.73,17.57],[1,1.74,41.21],[2,1.75,2.02]],"ltp":1.74,"tv":3373.41,"id":8257852}]}]}
{"op":"mcm","clk":"1011171521","pt":1580654832262,"mc":[{"id":"1.168223927","rc":[{"batb":[[1,2.3,2.08],[2,2.28,29.51]],"ltp":2.34,"tv":2741.02,"id":8444055},{"batb":[[2,1.69,131.53]],"ltp":1.74,"tv":3373.41,"id":8257852}]}]}
{"op":"mcm","clk":"1011173692","pt":1580654842940,"mc":[{"id":"1.168223927","rc":[{"batb":[[2,1.69,131.69]],"ltp":1.74,"tv":3373.41,"id":8257852}]}]}
{"op":"mcm","clk":"1011173864","pt":1580654843864,"mc":[{"id":"1.168223927","rc":[{"batb":[[1,1.7,2]],"ltp":1.74,"tv":3373.41,"id":8257852}]}]}
{"op":"mcm","clk":"1011173987","pt":1580654844567,"mc":[{"id":"1.168223927","rc":[{"batb":[[1,1.7,9.57]],"ltp":1.74,"tv":3373.41,"id":8257852}]}]}
{"op":"mcm","clk":"1011174340","pt":1580654846183,"mc":[{"id":"1.168223927","rc":[{"batb":[[1,1.7,17.14]],"ltp":1.74,"tv":3373.41,"id":8257852}]}]}
{"op":"mcm","clk":"1011180334","pt":1580654877106,"mc":[{"id":"1.168223927","rc":[{"batl":[[1,1.75,2.02],[2,1.76,2.02]],"ltp":1.74,"tv":3373.41,"id":8257852}]}]}
{"op":"mcm","clk":"1011180421","pt":1580654877589,"mc":[{"id":"1.168223927","rc":[{"batb":[[1,2.3,2.01]],"batl":[[1,2.46,2]],"ltp":2.34,"tv":2741.02,"id":8444055},{"batl":[[1,1.75,43.23]],"ltp":1.74,"tv":3373.41,"id":8257852}]}]}
{"op":"mcm","clk":"1011181272","pt":1580654882206,"mc":[{"id":"1.168223927","rc":[{"batl":[[0,1.74,17.57]],"ltp":1.74,"tv":3373.41,"id":8257852}]}]}
{"op":"mcm","clk":"1011181462","pt":1580654883113,"mc":[{"id":"1.168223927","rc":[{"batb":[[0,2.3,2.01],[1,2.28,31.67],[2,2.26,61.71]],"batl":[[1,2.46,2.12]],"ltp":2.34,"tv":2741.02,"id":8444055},{"batl":[[1,1.75,41.21]],"ltp":1.74,"tv":3373.41,"id":8257852}]}]}
{"op":"mcm","clk":"1011181500","pt":1580654883308,"mc":[{"id":"1.168223927","rc":[{"batb":[[1,2.28,11.97]],"ltp":2.34,"tv":2741.02,"id":8444055}]}]}
{"op":"mcm","clk":"1011183404","pt":1580654893022,"mc":[{"id":"1.168223927","rc":[{"batl":[[0,1.74,17.46]],"ltp":1.74,"tv":3373.41,"id":8257852}]}]}
{"op":"mcm","clk":"1011183497","pt":1580654893518,"mc":[{"id":"1.168223927","rc":[{"batb":[[1,2.28,11.86]],"batl":[[1,2.46,2.02]],"ltp":2.34,"tv":2741.02,"id":8444055}]}]}
{"op":"mcm","clk":"1011184978","pt":1580654901031,"mc":[{"id":"1.168223927","rc":[{"batb":[[1,1.7,2]],"ltp":1.74,"tv":3373.41,"id":8257852}]}]}
{"op":"mcm","clk":"1011185069","pt":1580654901518,"mc":[{"id":"1.168223927","rc":[{"batl":[[1,2.46,2.1]],"ltp":2.34,"tv":2741.02,"id":8444055}]}]}
{"op":"mcm","clk":"1011188694","pt":1580654922247,"mc":[{"id":"1.168223927","rc":[{"batb":[[1,2.28,9.81]],"batl":[[1,2.62,21.85],[2,2.76,1.68]],"ltp":2.34,"tv":2741.02,"id":8444055},{"batb":[[0,1.72,33.58],[1,1.7,56.64],[2,1.69,129.48]],"ltp":1.74,"tv":3373.41,"id":8257852}]}]}
{"op":"mcm","clk":"1011188730","pt":1580654922460,"mc":[{"id":"1.168223927","rc":[{"batb":[[1,2.28,11.97]],"batl":[[1,2.46,2],[2,2.62,21.85]],"ltp":2.34,"tv":2741.02,"id":8444055},{"batb":[[2,1.69,131.53]],"ltp":1.74,"tv":3373.41,"id":8257852}]}]}
{"op":"mcm","clk":"1011189363","pt":1580654926151,"mc":[{"id":"1.168223927","rc":[{"batb":[[0,1.7,56.64],[1,1.69,131.53],[2,1.67,37.62]],"ltp":1.74,"tv":3373.41,"id":8257852}]}]}
{"op":"mcm","clk":"1011189554","pt":1580654927167,"mc":[{"id":"1.168223927","rc":[{"batl":[[0,2.48,2.1],[1,2.5,2.01],[2,2.52,2.01]],"ltp":2.34,"tv":2741.02,"id":8444055},{"batb":[[0,1.7,54.64],[1,1.69,129.48],[2,1.68,2]],"ltp":1.74,"tv":3373.41,"id":8257852}]}]}
{"op":"mcm","clk":"1011189573","pt":1580654927275,"mc":[{"id":"1.168223927","rc":[{"batb":[[1,2.28,31.67]],"ltp":2.34,"tv":2741.02,"id":8444055}]}]}
{"op":"mcm","clk":"1011190506","pt":1580654932139,"mc":[{"id":"1.168223927","rc":[{"batb":[[1,2.28,29.51]],"batl":[[2,2.62,21.85]],"ltp":2.34,"tv":2741.02,"id":8444055},{"batb":[[0,1.7,79.53]],"ltp":1.74,"tv":3373.41,"id":8257852}]}]}
{"op":"mcm","clk":"1011190534","pt":1580654932356,"mc":[{"id":"1.168223927","rc":[{"batb":[[1,2.28,31.56]],"ltp":2.34,"tv":2741.02,"id":8444055}]}]}
{"op":"mcm","clk":"1011197165","pt":1580654970213,"mc":[{"id":"1.168223927","rc":[{"batb":[[1,2.28,29.51]],"batl":[[1,2.62,21.85],[2,2.76,1.68]],"ltp":2.34,"tv":2741.02,"id":8444055},{"batb":[[0,1.71,7.57],[1,1.7,79.53],[2,1.69,131.69]],"ltp":1.74,"tv":3373.41,"id":8257852}]}]}
{"op":"mcm","clk":"1011197276","pt":1580654970812,"mc":[{"id":"1.168223927","rc":[{"batb":[[1,2.28,31.67]],"batl":[[0,2.46,2.04],[1,2.48,2.12],[2,2.62,21.85]],"ltp":2.34,"tv":2741.02,"id":8444055}]}]}
{"op":"mcm","clk":"1011198414","pt":1580654978240,"mc":[{"id":"1.168223927","rc":[{"batl":[[1,2.48,2.02]],"ltp":2.34,"tv":2741.02,"id":8444055},{"batb":[[0,1.71,15.14]],"ltp":1.74,"tv":3373.41,"id":8257852}]}]}
{"op":"mcm","clk":"1011199118","pt":1580654983176,"mc":[{"id":"1.168223927","rc":[{"batb":[[0,1.71,22.72]],"ltp":1.74,"tv":3373.41,"id":8257852}]}]}
{"op":"mcm","clk":"1011199440","pt":1580654985245,"mc":[{"id":"1.168223927","rc":[{"batl":[[0,2.48,2.24],[1,2.5,2.01]],"ltp":2.34,"tv":2741.02,"id":8444055},{"batb":[[0,1.71,7.57]],"ltp":1.74,"tv":3373.41,"id":8257852}]}]}
{"op":"mcm","clk":"1011199536","pt":1580654985838,"mc":[{"id":"1.168223927","rc":[{"trd":[[2.34,13.5]],"batb":[[0,2.28,31.67],[1,2.26,63.92],[2,2.24,20.32]],"batl":[[0,2.34,7],[1,2.38,2.04],[2,2.4,2.04]],"ltp":2.34,"tv":2754.02,"id":8444055},{"trd":[[1.74,95.42]],"batb":[[0,1.72,2.09],[1,1.71,9.76],[2,1.7,79.53]],"batl":[[0,1.75,41.21],[1,1.77,2.02],[2,1.78,2.02]],"ltp":1.74,"tv":3390.88,"id":8257852}],"tv":6144.9}]}
{"op":"mcm","clk":"1011199754","pt":1580654987184,"mc":[{"id":"1.168223927","rc":[{"batb":[[0,2.28,11.97],[1,2.26,43.92]],"ltp":2.34,"tv":2754.02,"id":8444055},{"batb":[[0,1.72,9.66]],"ltp":1.74,"tv":3390.88,"id":8257852}]}]}
{"op":"mcm","clk":"1011200321","pt":1580654990953,"mc":[{"id":"1.168223927","rc":[{"batb":[[1,1.71,2.19]],"ltp":1.74,"tv":3390.88,"id":8257852}]}]}
{"op":"mcm","clk":"1011200433","pt":1580654991687,"mc":[{"id":"1.168223927","rc":[{"batl":[[2,1.78,2.25]],"ltp":1.74,"tv":3390.88,"id":8257852}]}]}
{"op":"mcm","clk":"1011201320","pt":1580654997242,"mc":[{"id":"1.168223927","rc":[{"trd":[[2.32,77.79]],"ltp":2.32,"tv":2784.27,"id":8444055},{"trd":[[1.75,757.67]],"batl":[[0,1.75,1.11]],"ltp":1.75,"tv":3430.98,"id":8257852}],"tv":6215.25}]}
{"op":"mcm","clk":"1011201495","pt":1580654998253,"mc":[{"id":"1.168223927","rc":[{"batb":[[0,2.28,9.81],[1,2.26,41.71],[2,2.24,22.34]],"ltp":2.32,"tv":2784.27,"id":8444055},{"batl":[[1,1.8,147.03],[2,1.82,191.06]],"ltp":1.75,"tv":3430.98,"id":8257852}]}]}
{"op":"mcm","clk":"1011201509","pt":1580654998371,"mc":[{"id":"1.168223927","rc":[{"batb":[[2,2.24,2.02]],"ltp":2.32,"tv":2784.27,"id":8444055},{"batl":[[2,1.81,2.13]],"ltp":1.75,"tv":3430.98,"id":8257852}]}]}
{"op":"mcm","clk":"1011201777","pt":1580655000263,"mc":[{"id":"1.168223927","rc":[{"batb":[[2,2.24,22.34]],"ltp":2.32,"tv":2784.27,"id":8444055},{"batl":[[1,1.78,22.72],[2,1.8,149.04]],"ltp":1.75,"tv":3430.98,"id":8257852}]}]}
{"op":"mcm","clk":"1011202103","pt":1580655002174,"mc":[{"id":"1.168223927","rc":[{"batl":[[1,1.77,7.06],[2,1.78,22.72]],"ltp":1.75,"tv":3430.98,"id":8257852}]}]}
{"op":"mcm","clk":"1011202290","pt":1580655003184,"mc":[{"id":"1.168223927","rc":[{"trd":[[2.28,103.79],[2.32,78.62]],"batb":[[0,2.26,41.71],[1,2.24,22.34],[2,2.22,20.66]],"batl":[[2,2.62,21.85]],"ltp":2.28,"tv":2803.6,"id":8444055},{"trd":[[1.75,758.77]],"batb":[[1,1.71,12.24]],"batl":[[0,1.77,7.06],[1,1.78,22.72],[2,1.79,2.07]],"ltp":1.75,"tv":3432.08,"id":8257852}],"tv":6235.69}]}
{"op":"mcm","clk":"1011202324","pt":1580655003403,"mc":[{"id":"1.168223927","rc":[{"batb":[[2,2.22,22.68]],"batl":[[2,2.4,2.04]],"ltp":2.28,"tv":2803.6,"id":8444055},{"batb":[[1,1.71,14.43]],"ltp":1.75,"tv":3432.08,"id":8257852}]}]}
{"op":"mcm","clk":"1011202789","pt":1580655006171,"mc":[{"id":"1.168223927","rc":[{"batl":[[1,1.78,7.57]],"ltp":1.75,"tv":3432.08,"id":8257852}]}]}
{"op":"mcm","clk":"1011202816","pt":1580655006387,"mc":[{"id":"1.168223927","rc":[{"batb":[[1,2.24,2.02]],"ltp":2.28,"tv":2803.6,"id":8444055}]}]}
{"op":"mcm","clk":"1011203280","pt":1580655009187,"mc":[{"id":"1.168223927","rc":[{"trd":[[2.28,136.61]],"batb":[[1,2.22,22.68],[2,2.06,85.82]],"batl":[[0,2.34,7.57],[1,2.36,2.07],[2,2.38,2.04]],"ltp":2.28,"tv":2836.43,"id":8444055},{"trd":[[1.77,233.41],[1.78,100.47]],"batb":[[0,1.73,2.13],[1,1.72,9.66],[2,1.71,12.24]],"batl":[[0,1.8,147.03],[1,1.81,2.13],[2,1.82,191.06]],"ltp":1.78,"tv":3446.71,"id":8257852}],"tv":6283.14}]}
{"op":"mcm","clk":"1011203452","pt":1580655010184,"mc":[{"id":"1.168223927","rc":[{"trd":[[2.28,137.18]],"batb":[[2,2.2,2.02]],"batl":[[0,2.34,7],[1,2.38,2.04],[2,2.4,2.04]],"ltp":2.28,"tv":2837.0,"id":8444055},{"trd":[[1.77,247.19],[1.78,101.2]],"batb":[[0,1.73,2.86],[1,1.72,7.57]],"batl":[[1,1.82,191.06],[2,1.83,2.14]],"ltp":1.77,"tv":3461.22,"id":8257852}],"tv":6298.22}]}
{"op":"mcm","clk":"1011203614","pt":1580655011222,"mc":[{"id":"1.168223927","rc":[{"batb":[[0,1.72,10.39],[1,1.71,14.43],[2,1.7,81.55]],"batl":[[0,1.79,15.14],[1,1.8,147.03],[2,1.82,191.06]],"ltp":1.77,"tv":3461.22,"id":8257852}]}]}
{"op":"mcm","clk":"1011203711","pt":1580655011695,"mc":[{"id":"1.168223927","rc":[{"batl":[[0,1.79,22.72],[2,1.81,2.02]],"ltp":1.77,"tv":3461.22,"id":8257852}]}]}
{"op":"mcm","clk":"1011204115","pt":1580655014197,"mc":[{"id":"1.168223927","rc":[{"batb":[[0,1.72,9.66]],"ltp":1.77,"tv":3461.22,"id":8257852}]}]}
{"op":"mcm","clk":"1011204276","pt":1580655015154,"mc":[{"id":"1.168223927","rc":[{"batb":[[0,1.72,10.39],[2,1.7,79.53]],"ltp":1.77,"tv":3461.22,"id":8257852}]}]}
{"op":"mcm","clk":"1011204427","pt":1580655016168,"mc":[{"id":"1.168223927","rc":[{"batl":[[0,1.79,30.29]],"ltp":1.77,"tv":3461.22,"id":8257852}]}]}
{"op":"mcm","clk":"1011204601","pt":1580655017267,"mc":[{"id":"1.168223927","rc":[{"trd":[[2.26,2274.77],[2.28,143.1]],"batb":[[0,2.26,26.62],[1,2.24,2.01],[2,2.22,20.66]],"ltp":2.26,"tv":2873.09,"id":8444055},{"trd":[[1.78,108.77]],"batb":[[1,1.71,14.26]],"batl":[[1,1.8,149.05],[2,1.82,191.12]],"ltp":1.78,"tv":3468.79,"id":8257852}],"tv":6341.89}]}
{"op":"mcm","clk":"1011204740","pt":1580655018069,"mc":[{"id":"1.168223927","rc":[{"batb":[[1,2.22,22.68],[2,2.2,2.02]],"batl":[[0,2.34,9.02],[1,2.36,2]],"ltp":2.26,"tv":2873.09,"id":8444055},{"batb":[[0,1.77,7.62],[1,1.75,2.76],[2,1.74,2.02]],"batl":[[1,1.8,147.03],[2,1.81,2.13]],"ltp":1.78,"tv":3468.79,"id":8257852}]}]}
{"op":"mcm","clk":"1011204896","pt":1580655019077,"mc":[{"id":"1.168223927","rc":[{"batb":[[1,2.22,2.02],[2,2.2,23.02]],"batl":[[0,2.34,7],[1,2.38,2.04]],"ltp":2.26,"tv":2873.09,"id":8444055},{"trd":[[1.77,260.95]],"batb":[[0,1.75,1.46],[1,1.73,44.92],[2,1.72,9.66]],"ltp":1.77,"tv":3482.56,"id":8257852}],"tv":6355.65}]}
{"op":"mcm","clk":"1011205055","pt":1580655020080,"mc":[{"id":"1.168223927","rc":[{"batl":[[0,1.78,7.57],[1,1.79,30.29],[2,1.8,147.03]],"ltp":1.77,"tv":3482.56,"id":8257852}]}]}
{"op":"mcm","clk":"1011205082","pt":1580655020291,"mc":[{"id":"1.168223927","rc":[{"batb":[[1,2.24,2.02],[2,2.22,2.02]],"ltp":2.26,"tv":2873.09,"id":8444055},{"batl":[[0,1.78,15.14],[2,1.8,149.05]],"ltp":1.77,"tv":3482.56,"id":8257852}]}]}
{"op":"mcm","clk":"1011205371","pt":1580655022089,"mc":[{"id":"1.168223927","rc":[{"batl":[[1,1.8,149.05],[2,1.81,2.13]],"ltp":1.77,"tv":3482.56,"id":8257852}]}]}
{"op":"mcm","clk":"1011205525","pt":1580655022995,"mc":[{"id":"1.168223927","rc":[{"batl":[[1,1.79,7.57],[2,1.8,149.05]],"ltp":1.77,"tv":3482.56,"id":8257852}]}]}
{"op":"mcm","clk":"1011206401","pt":1580655028185,"mc":[{"id":"1.168223927","rc":[{"batb":[[2,2.2,21]],"batl":[[2,2.62,21.85]],"ltp":2.26,"tv":2873.09,"id":8444055},{"batb":[[0,1.73,44.92],[1,1.72,2.09],[2,1.7,24.89]],"batl":[[0,1.8,147.03],[1,1.82,191.29],[2,1.83,2.2]],"ltp":1.77,"tv":3482.56,"id":8257852}]}]}
{"op":"mcm","clk":"1011206559","pt":1580655029090,"mc":[{"id":"1.168223927","rc":[{"batb":[[2,2.22,2.02]],"batl":[[2,2.4,2.04]],"ltp":2.26,"tv":2873.09,"id":8444055},{"batb":[[2,1.71,2.19]],"batl":[[0,1.78,15.14],[1,1.8,149.05],[2,1.81,2.13]],"ltp":1.77,"tv":3482.56,"id":8257852}]}]}
{"op":"mcm","clk":"1011206864","pt":1580655030784,"mc":[{"id":"1.168223927","rc":[{"batb":[[0,1.75,1.48],[1,1.73,44.92],[2,1.72,2.09]],"batl":[[1,1.79,7.57],[2,1.8,149.05]],"ltp":1.77,"tv":3482.56,"id":8257852}]}]}
{"op":"mcm","clk":"1011207762","pt":1580655036216,"mc":[{"id":"1.168223927","rc":[{"batb":[[1,1.73,61.1]],"ltp":1.77,"tv":3482.56,"id":8257852}]}]}
{"op":"mcm","clk":"1011207850","pt":1580655036803,"mc":[{"id":"1.168223927","rc":[{"batl":[[0,1.78,22.72]],"ltp":1.77,"tv":3482.56,"id":8257852}]}]}
{"op":"mcm","clk":"1011207928","pt":1580655037320,"mc":[{"id":"1.168223927","rc":[{"batb":[[2,2.22,22.68]],"ltp":2.26,"tv":2873.09,"id":8444055}]}]}
{"op":"mcm","clk":"1011208356","pt":1580655040095,"mc":[{"id":"1.168223927","rc":[{"batb":[[1,2.22,22.68],[2,2.2,23.02]],"ltp":2.26,"tv":2873.09,"id":8444055},{"batb":[[0,1.73,61.1],[1,1.72,2.09],[2,1.71,2.19]],"batl":[[0,1.78,15.14],[1,1.8,147.03],[2,1.82,191.12]],"ltp":1.77,"tv":3482.56,"id":8257852}]}]}
{"op":"mcm","clk":"1011208438","pt":1580655040622,"mc":[{"id":"1.168223927","rc":[{"batb":[[1,2.24,2.02],[2,2.22,2.02]],"ltp":2.26,"tv":2873.09,"id":8444055},{"batl":[[1,1.79,7.57],[2,1.8,149.03]],"ltp":1.77,"tv":3482.56,"id":8257852}]}]}
{"op":"mcm","clk":"1011208648","pt":1580655042116,"mc":[{"id":"1.168223927","rc":[{"batb":[[0,1.76,1.47],[1,1.73,61.1],[2,1.72,2.09]],"ltp":1.77,"tv":3482.56,"id":8257852}]}]}
{"op":"mcm","clk":"1011208719","pt":1580655042539,"mc":[{"id":"1.168223927","rc":[{"batl":[[2,2.4,2]],"ltp":2.26,"tv":2873.09,"id":8444055}]}]}
{"op":"mcm","clk":"1011208935","pt":1580655044378,"mc":[{"id":"1.168223927","rc":[{"batl":[[0,1.78,22.72]],"ltp":1.77,"tv":3482.56,"id":8257852}]}]}
{"op":"mcm","clk":"1011209235","pt":1580655045919,"mc":[{"id":"1.168223927","rc":[{"batb":[[2,2.22,22.68]],"ltp":2.26,"tv":2873.09,"id":8444055}]}]}
{"op":"mcm","clk":"1011209364","pt":1580655046866,"mc":[{"id":"1.168223927","rc":[{"batb":[[1,2.22,22.68],[2,2.2,23.02]],"ltp":2.26,"tv":2873.09,"id":8444055},{"batb":[[1,1.73,69.2]],"batl":[[0,1.79,7.57],[1,1.8,147.03],[2,1.81,2]],"ltp":1.77,"tv":3482.56,"id":8257852}]}]}
{"op":"mcm","clk":"1011209535","pt":1580655047904,"mc":[{"id":"1.168223927","rc":[{"batb":[[1,2.24,2.02],[2,2.22,2.02]],"batl":[[2,2.4,2.04]],"ltp":2.26,"tv":2873.09,"id":8444055},{"batl":[[0,1.78,15.14],[1,1.79,7.57],[2,1.8,149.05]],"ltp":1.77,"tv":3482.56,"id":8257852}]}]}
{"op":"mcm","clk":"1011210317","pt":1580655053005,"mc":[{"id":"1.168223927","rc":[{"batl":[[0,1.78,22.72]],"ltp":1.77,"tv":3482.56,"id":8257852}]}]}
{"op":"mcm","clk":"1011210488","pt":1580655054107,"mc":[{"id":"1.168223927","rc":[{"batb":[[2,2.22,22.68]],"ltp":2.26,"tv":2873.09,"id":8444055},{"batl":[[0,1.79,7.57],[1,1.8,149.05],[2,1.81,2.13]],"ltp":1.77,"tv":3482.56,"id":8257852}]}]}
{"op":"mcm","clk":"1011210655","pt":1580655055205,"mc":[{"id":"1.168223927","rc":[{"batl":[[0,1.78,7.57],[1,1.79,7.57],[2,1.8,149.05]],"ltp":1.77,"tv":3482.56,"id":8257852}]}]}
{"op":"mcm","clk":"1011210684","pt":1580655055413,"mc":[{"id":"1.168223927","rc":[{"batb":[[2,2.22,2.02]],"ltp":2.26,"tv":2873.09,"id":8444055}]}]}
{"op":"mcm","clk":"1011211507","pt":1580655060858,"mc":[{"id":"1.168223927","rc":[{"batl":[[0,1.78,15.14]],"ltp":1.77,"tv":3482.56,"id":8257852}]}]}
{"op":"mcm","clk":"1011211760","pt":1580655062548,"mc":[{"id":"1.168223927","rc":[{"batl":[[0,1.78,30.29]],"ltp":1.77,"tv":3482.56,"id":8257852}]}]}
{"op":"mcm","clk":"1011212048","pt":1580655064238,"mc":[{"id":"1.168223927","rc":[{"batb":[[2,2.22,22.68]],"ltp":2.26,"tv":2873.09,"id":8444055},{"batb":[[1,1.73,77.29]],"batl":[[0,1.79,7.57],[1,1.8,149.05],[2,1.81,2.13]],"ltp":1.77,"tv":3482.56,"id":8257852}]}]}
{"op":"mcm","clk":"1011212109","pt":1580655064617,"mc":[{"id":"1.168223927","rc":[{"batb":[[1,2.22,22.68],[2,2.2,23.02]],"ltp":2.26,"tv":2873.09,"id":8444055},{"batl":[[1,1.8,147.03]],"ltp":1.77,"tv":3482.56,"id":8257852}]}]}
{"op":"mcm","clk":"1011212336","pt":1580655066050,"mc":[{"id":"1.168223927","rc":[{"batb":[[1,2.24,2.02],[2,2.22,2.02]],"ltp":2.26,"tv":2873.09,"id":8444055},{"batl":[[0,1.78,15.14],[1,1.79,7.57],[2,1.8,149.05]],"ltp":1.77,"tv":3482.56,"id":8257852}]}]}
{"op":"mcm","clk":"1011212768","pt":1580655068532,"mc":[{"id":"1.168223927","rc":[{"batb":[[0,1.75,1.47]],"ltp":1.77,"tv":3482.56,"id":8257852}]}]}
{"op":"mcm","clk":"1011213048","pt":1580655070251,"mc":[{"id":"1.168223927","rc":[{"batl":[[0,1.78,22.72]],"ltp":1.77,"tv":3482.56,"id":8257852}]}]}
{"op":"mcm","clk":"1011213177","pt":1580655071047,"mc":[{"id":"1.168223927","rc":[{"batl":[[2,2.4,2.02]],"ltp":2.26,"tv":2873.09,"id":8444055},{"batl":[[0,1.78,30.29]],"ltp":1.77,"tv":3482.56,"id":8257852}]}]}
{"op":"mcm","clk":"1011213222","pt":1580655071325,"mc":[{"id":"1.168223927","rc":[{"batb":[[2,2.22,22.68]],"ltp":2.26,"tv":2873.09,"id":8444055}]}]}
{"op":"mcm","clk":"1011213527","pt":1580655073272,"mc":[{"id":"1.168223927","rc":[{"batl":[[0,1.78,7.57]],"ltp":1.77,"tv":3482.56,"id":8257852}]}]}
{"op":"mcm","clk":"1011213565","pt":1580655073435,"mc":[{"id":"1.168223927","rc":[{"batb":[[2,2.22,2.02]],"ltp":2.26,"tv":2873.09,"id":8444055},{"batl":[[0,1.78,15.14]],"ltp":1.77,"tv":3482.56,"id":8257852}]}]}
{"op":"mcm","clk":"1011214145","pt":1580655077237,"mc":[{"id":"1.168223927","rc":[{"batb":[[2,2.22,22.67]],"batl":[[2,2.4,2.04]],"ltp":2.26,"tv":2873.09,"id":8444055},{"batl":[[0,1.78,22.72]],"ltp":1.77,"tv":3482.56,"id":8257852}]}]}
{"op":"mcm","clk":"1011214567","pt":1580655080038,"mc":[{"id":"1.168223927","rc":[{"batl":[[0,1.78,30.29]],"ltp":1.77,"tv":3482.56,"id":8257852}]}]}
{"op":"mcm","clk":"1011214927","pt":1580655082248,"mc":[{"id":"1.168223927","rc":[{"batb":[[2,2.22,2.01]],"ltp":2.26,"tv":2873.09,"id":8444055},{"batl":[[0,1.78,15.14]],"ltp":1.77,"tv":3482.56,"id":8257852}]}]}
{"op":"mcm","clk":"1011215206","pt":1580655083948,"mc":[{"id":"1.168223927","rc":[{"batb":[[2,2.22,2.02]],"ltp":2.26,"tv":2873.09,"id":8444055}]}]}
{"op":"mcm","clk":"1011215541","pt":1580655086265,"mc":[{"id":"1.168223927","rc":[{"batl":[[0,1.78,22.72]],"ltp":1.77,"tv":3482.56,"id":8257852}]}]}
{"op":"mcm","clk":"1011215726","pt":1580655087589,"mc":[{"id":"1.168223927","rc":[{"batb":[[2,2.22,22.68]],"ltp":2.26,"tv":2873.09,"id":8444055}]}]}
{"op":"mcm","clk":"1011215965","pt":1580655089167,"mc":[{"id":"1.168223927","rc":[{"batb":[[1,2.22,22.68],[2,2.2,23.01]],"ltp":2.26,"tv":2873.09,"id":8444055},{"batl":[[0,1.79,7.57],[1,1.8,147.03],[2,1.81,2.01]],"ltp":1.77,"tv":3482.56,"id":8257852}]}]}
{"op":"mcm","clk":"1011215978","pt":1580655089273,"mc":[{"id":"1.168223927","rc":[{"batb":[[1,2.22,2.02]],"ltp":2.26,"tv":2873.09,"id":8444055}]}]}
{"op":"mcm","clk":"1011216421","pt":1580655092082,"mc":[{"id":"1.168223927","rc":[{"batb":[[0,1.73,77.29],[1,1.72,2.09],[2,1.71,2.19]],"batl":[[0,1.8,147.03],[1,1.81,2.01],[2,1.82,191.29]],"ltp":1.77,"tv":3482.56,"id":8257852}]}]}
{"op":"mcm","clk":"1011216617","pt":1580655093258,"mc":[{"id":"1.168223927","rc":[{"batl":[[0,1.79,7.57],[1,1.8,147.03]],"ltp":1.77,"tv":3482.56,"id":8257852}]}]}
{"op":"mcm","clk":"1011216731","pt":1580655093895,"mc":[{"id":"1.168223927","rc":[{"batb":[[2,2.2,23.02]],"ltp":2.26,"tv":2873.09,"id":8444055},{"batl":[[2,1.81,2.13]],"ltp":1.77,"tv":3482.56,"id":8257852}]}]}
{"op":"mcm","clk":"1011216903","pt":1580655094949,"mc":[{"id":"1.168223927","rc":[{"trd":[[1.77,263.87]],"batb":[[2,1.71,2.02]],"batl":[[0,1.79,15.14]],"ltp":1.77,"tv":3485.48,"id":8257852}],"tv":6358.58}]}
{"op":"mcm","clk":"1011217235","pt":1580655097174,"mc":[{"id":"1.168223927","rc":[{"batl":[[0,1.78,7.57],[1,1.79,15.14],[2,1.8,147.03]],"ltp":1.77,"tv":3485.48,"id":8257852}]}]}
{"op":"mcm","clk":"1011217345","pt":1580655097968,"mc":[{"id":"1.168223927","rc":[{"batb":[[1,2.24,2.02],[2,2.22,2.02]],"ltp":2.26,"tv":2873.09,"id":8444055},{"batl":[[0,1.78,15.14],[2,1.8,149.05]],"ltp":1.77,"tv":3485.48,"id":8257852}]}]}
{"op":"mcm","clk":"1011217543","pt":1580655099187,"mc":[{"id":"1.168223927","rc":[{"batl":[[1,1.8,149.05],[2,1.82,189.04]],"ltp":1.77,"tv":3485.48,"id":8257852}]}]}
{"op":"mcm","clk":"1011217571","pt":1580655099400,"mc":[{"id":"1.168223927","rc":[{"trd":[[2.34,13.51]],"batl":[[0,2.34,6.99]],"ltp":2.34,"tv":2873.1,"id":8444055},{"trd":[[1.74,95.43]],"batl":[[2,1.81,2.13]],"ltp":1.74,"tv":3485.49,"id":8257852}],"tv":6358.6}]}
{"op":"mcm","clk":"1011217749","pt":1580655100777,"mc":[{"id":"1.168223927","rc":[{"batb":[[2,1.71,2.19]],"batl":[[0,1.78,22.72]],"ltp":1.74,"tv":3485.49,"id":8257852}]}]}
{"op":"mcm","clk":"1011217824","pt":1580655101392,"mc":[{"id":"1.168223927","rc":[{"batb":[[2,2.22,22.68]],"ltp":2.34,"tv":2873.1,"id":8444055}]}]}
{"op":"mcm","clk":"1011219631","pt":1580655112527,"mc":[{"id":"1.168223927","marketDefinition":{"bspMarket":false,"turnInPlayEnabled":true,"persistenceEnabled":true,"marketBaseRate":5.0,"eventId":"29681623","eventTypeId":"2","numberOfWinners":1,"bettingType":"ODDS","marketType":"MATCH_ODDS","marketTime":"2020-02-02T14:50:00.000Z","suspendTime":"2020-02-02T14:50:00.000Z","bspReconciled":false,"complete":true,"inPlay":false,"crossMatching":true,"runnersVoidable":false,"numberOfActiveRunners":2,"betDelay":0,"status":"OPEN","runners":[{"status":"ACTIVE","sortPriority":1,"id":8257852,"name":"Maxime Janvier"},{"status":"ACTIVE","sortPriority":2,"id":8444055,"name":"Cem Ilkel"}],"regulators":["MR_INT"],"countryCode":"FR","discountAllowed":true,"timezone":"UTC","openDate":"2020-02-02T15:00:00.000Z","version":3149299564,"name":"Match Odds","eventName":"Janvier v Ilkel"}}]}
{"op":"mcm","clk":"1011220310","pt":1580655116547,"mc":[{"id":"1.168223927","marketDefinition":{"bspMarket":false,"turnInPlayEnabled":true,"persistenceEnabled":true,"marketBaseRate":5.0,"eventId":"29681623","eventTypeId":"2","numberOfWinners":1,"bettingType":"ODDS","marketType":"MATCH_ODDS","marketTime":"2020-02-02T14:50:00.000Z","suspendTime":"2020-02-02T14:50:00.000Z","bspReconciled":false,"complete":true,"inPlay":false,"crossMatching":true,"runnersVoidable":false,"numberOfActiveRunners":2,"betDelay":0,"status":"OPEN","runners":[{"status":"ACTIVE","sortPriority":1,"id":8257852,"name":"Maxime Janvier"},{"status":"ACTIVE","sortPriority":2,"id":8444055,"name":"Cem Ilkel"}],"regulators":["MR_INT"],"countryCode":"FR","discountAllowed":true,"timezone":"UTC","openDate":"2020-02-02T14:50:00.000Z","version":3149299564,"name":"Match Odds","eventName":"Janvier v Ilkel"}}]}
{"op":"mcm","clk":"1011221136","pt":1580655121702,"mc":[{"id":"1.168223927","rc":[{"batb":[[1,2.22,20.66],[2,2.2,21]],"batl":[[1,2.62,21.85],[2,2.76,1.68]],"ltp":2.34,"tv":2873.1,"id":8444055},{"batb":[[1,1.69,166.01],[2,1.68,37.07]],"batl":[[0,1.8,147.03],[1,1.82,189.04],[2,1.84,4.12]],"ltp":1.74,"tv":3485.49,"id":8257852}]}]}
{"op":"mcm","clk":"1011221224","pt":1580655122335,"mc":[{"id":"1.168223927","rc":[{"batb":[[1,2.2,21],[2,2.06,85.82]],"ltp":2.34,"tv":2873.1,"id":8444055},{"batb":[[1,1.7,36.01],[2,1.69,166.01]],"ltp":1.74,"tv":3485.49,"id":8257852}]}]}
{"op":"mcm","clk":"1011221831","pt":1580655126211,"mc":[{"id":"1.168223927","rc":[{"batl":[[0,1.79,15.14],[1,1.8,147.03],[2,1.82,189.04]],"ltp":1.74,"tv":3485.49,"id":8257852}]}]}
{"op":"mcm","clk":"1011224477","pt":1580655143636,"mc":[{"id":"1.168223927","rc":[{"batl":[[0,1.79,22.72]],"ltp":1.74,"tv":3485.49,"id":8257852}]}]}
{"op":"mcm","clk":"1011224604","pt":1580655144429,"mc":[{"id":"1.168223927","rc":[{"batb":[[1,1.69,166.01],[2,1.68,37.07]],"ltp":1.74,"tv":3485.49,"id":8257852}]}]}
{"op":"mcm","clk":"1011225053","pt":1580655147123,"mc":[{"id":"1.168223927","rc":[{"batl":[[0,1.79,7.57]],"ltp":1.74,"tv":3485.49,"id":8257852}]}]}
{"op":"mcm","clk":"1011225087","pt":1580655147337,"mc":[{"id":"1.168223927","rc":[{"batb":[[1,1.7,36.01],[2,1.69,166.01]],"ltp":1.74,"tv":3485.49,"id":8257852}]}]}
{"op":"mcm","clk":"1011225301","pt":1580655148439,"mc":[{"id":"1.168223927","rc":[{"batl":[[0,1.79,15.14]],"ltp":1.74,"tv":3485.49,"id":8257852}]}]}
{"op":"mcm","clk":"1011226539","pt":1580655155656,"mc":[{"id":"1.168223927","rc":[{"batb":[[1,2.2,197.41]],"ltp":2.34,"tv":2873.1,"id":8444055},{"batb":[[0,1.75,182.38],[1,1.73,77.29],[2,1.7,36.01]],"ltp":1.74,"tv":3485.49,"id":8257852}]}]}
{"op":"mcm","clk":"1011226659","pt":1580655156347,"mc":[{"id":"1.168223927","rc":[{"batb":[[2,1.71,35.5]],"ltp":1.74,"tv":3485.49,"id":8257852}]}]}
{"op":"mcm","clk":"1011226942","pt":1580655157943,"mc":[{"id":"1.168223927","rc":[{"batl":[[0,1.79,22.72]],"ltp":1.74,"tv":3485.49,"id":8257852}]}]}
{"op":"mcm","clk":"1011227014","pt":1580655158401,"mc":[{"id":"1.168223927","rc":[{"batb":[[2,1.7,36.01]],"ltp":1.74,"tv":3485.49,"id":8257852}]}]}
{"op":"mcm","clk":"1011227473","pt":1580655160860,"mc":[{"id":"1.168223927","rc":[{"batl":[[0,1.79,7.57]],"ltp":1.74,"tv":3485.49,"id":8257852}]}]}
{"op":"mcm","clk":"1011227661","pt":1580655161862,"mc":[{"id":"1.168223927","rc":[{"batb":[[2,1.71,35.5]],"batl":[[0,1.79,15.14]],"ltp":1.74,"tv":3485.49,"id":8257852}]}]}
{"op":"mcm","clk":"1011228734","pt":1580655168400,"mc":[{"id":"1.168223927","rc":[{"batl":[[0,1.79,22.72]],"ltp":1.74,"tv":3485.49,"id":8257852}]}]}
{"op":"mcm","clk":"1011228993","pt":1580655169909,"mc":[{"id":"1.168223927","rc":[{"batb":[[2,1.7,36.01]],"ltp":1.74,"tv":3485.49,"id":8257852}]}]}
{"op":"mcm","clk":"1011229191","pt":1580655171172,"mc":[{"id":"1.168223927","rc":[{"batl":[[0,1.8,147.03],[1,1.82,189.04],[2,1.84,4.12]],"ltp":1.74,"tv":3485.49,"id":8257852}]}]}
{"op":"mcm","clk":"1011229356","pt":1580655172270,"mc":[{"id":"1.168223927","rc":[{"batb":[[2,1.71,35.5]],"ltp":1.74,"tv":3485.49,"id":8257852}]}]}
{"op":"mcm","clk":"1011229408","pt":1580655172588,"mc":[{"id":"1.168223927","rc":[{"batl":[[0,1.79,7.57],[1,1.8,147.03],[2,1.82,189.04]],"ltp":1.74,"tv":3485.49,"id":8257852}]}]}
{"op":"mcm","clk":"1011231207","pt":1580655184005,"mc":[{"id":"1.168223927","rc":[{"batl":[[0,1.79,15.14]],"ltp":1.74,"tv":3485.49,"id":8257852}]}]}
{"op":"mcm","clk":"1011232442","pt":1580655191597,"mc":[{"id":"1.168223927","rc":[{"batl":[[0,1.8,147.03],[1,1.82,189.04],[2,1.84,4.12]],"ltp":1.74,"tv":3485.49,"id":8257852}]}]}
{"op":"mcm","clk":"1011233592","pt":1580655198816,"mc":[{"id":"1.168223927","rc":[{"batb":[[1,1.73,77.3]],"ltp":1.74,"tv":3485.49,"id":8257852}]}]}
{"op":"mcm","clk":"1011245257","pt":1580655271573,"mc":[{"id":"1.168223927","rc":[{"batl":[[0,1.79,7.57],[1,1.8,147.03],[2,1.82,189.04]],"ltp":1.74,"tv":3485.49,"id":8257852}]}]}
{"op":"mcm","clk":"1011245669","pt":1580655274320,"mc":[{"id":"1.168223927","rc":[{"batl":[[0,1.8,147.03],[1,1.82,189.04],[2,1.84,4.12]],"ltp":1.74,"tv":3485.49,"id":8257852}]}]}
{"op":"mcm","clk":"1011249939","pt":1580655300010,"mc":[{"id":"1.168223927","rc":[{"trd":[[1.75,759.31]],"batb":[[0,1.75,182.12]],"ltp":1.75,"tv":3486.03,"id":8257852}],"tv":6359.14}]}
{"op":"mcm","clk":"1011250121","pt":1580655300934,"mc":[{"id":"1.168223927","rc":[{"trd":[[1.75,765.31]],"batb":[[0,1.75,179.12]],"ltp":1.75,"tv":3492.03,"id":8257852}],"tv":6365.14}]}
{"op":"mcm","clk":"1011250427","pt":1580655302532,"mc":[{"id":"1.168223927","rc":[{"batb":[[1,1.73,44.93]],"ltp":1.75,"tv":3492.03,"id":8257852}]}]}
{"op":"mcm","clk":"1011251484","pt":1580655308146,"mc":[{"id":"1.168223927","rc":[{"batb":[[0,1.75,223.12]],"ltp":1.75,"tv":3492.03,"id":8257852}]}]}
{"op":"mcm","clk":"1011251950","pt":1580655310859,"mc":[{"id":"1.168223927","rc":[{"batb":[[1,2.22,176.4],[2,2.2,21]],"ltp":2.34,"tv":2873.1,"id":8444055}]}]}
{"op":"mcm","clk":"1011261057","pt":1580655364064,"mc":[{"id":"1.168223927","rc":[{"batb":[[1,1.72,58.52]],"ltp":1.75,"tv":3492.03,"id":8257852}]}]}
{"op":"mcm","clk":"1011261956","pt":1580655369833,"mc":[{"id":"1.168223927","rc":[{"trd":[[1.75,767.21]],"batb":[[0,1.75,222.17]],"ltp":1.75,"tv":3493.93,"id":8257852}],"tv":6367.04}]}
{"op":"mcm","clk":"1011262552","pt":1580655373844,"mc":[{"id":"1.168223927","rc":[{"batl":[[0,1.79,7.57],[1,1.8,147.03],[2,1.82,189.04]],"ltp":1.75,"tv":3493.93,"id":8257852}]}]}
{"op":"mcm","clk":"1011262930","pt":1580655376234,"mc":[{"id":"1.168223927","rc":[{"batl":[[0,1.8,147.03],[1,1.82,189.04],[2,1.84,4.12]],"ltp":1.75,"tv":3493.93,"id":8257852}]}]}
{"op":"mcm","clk":"1011267530","pt":1580655407085,"mc":[{"id":"1.168223927","rc":[{"trd":[[2.3,72.93]],"batl":[[0,2.34,7.74]],"ltp":2.3,"tv":2881.04,"id":8444055}],"tv":6374.98}]}
{"op":"mcm","clk":"1011270700","pt":1580655427788,"mc":[{"id":"1.168223927","rc":[{"batb":[[0,2.26,32.72],[1,2.22,174.6]],"ltp":2.3,"tv":2881.04,"id":8444055},{"batb":[[0,1.75,44],[1,1.74,184.21],[2,1.72,58.5]],"batl":[[0,1.79,7.7],[1,1.8,147.03],[2,1.82,189.04]],"ltp":1.75,"tv":3493.93,"id":8257852}]}]}
{"op":"mcm","clk":"1011271563","pt":1580655433813,"mc":[{"id":"1.168223927","rc":[{"batb":[[0,2.26,26.62]],"ltp":2.3,"tv":2881.04,"id":8444055},{"batb":[[0,1.74,184.21],[1,1.72,58.5],[2,1.71,35.5]],"batl":[[0,1.8,147.03],[1,1.82,189.04],[2,1.84,4.12]],"ltp":1.75,"tv":3493.93,"id":8257852}]}]}
{"op":"mcm","clk":"1011271669","pt":1580655434537,"mc":[{"id":"1.168223927","rc":[{"batb":[[2,1.7,36.01]],"ltp":1.75,"tv":3493.93,"id":8257852}]}]}
{"op":"mcm","clk":"1011272025","pt":1580655437124,"mc":[{"id":"1.168223927","rc":[{"trd":[[2.3,73.68]],"batl":[[0,2.34,6.99]],"ltp":2.3,"tv":2881.79,"id":8444055},{"trd":[[1.74,99.82],[1.76,730.35]],"batb":[[0,1.74,182.01]],"ltp":1.74,"tv":3499.31,"id":8257852}],"tv":6381.11}]}
{"op":"mcm","clk":"1011272311","pt":1580655439151,"mc":[{"id":"1.168223927","rc":[{"batb":[[0,1.74,226.27]],"ltp":1.74,"tv":3499.31,"id":8257852}]}]}
{"op":"mcm","clk":"1011272486","pt":1580655440417,"mc":[{"id":"1.168223927","rc":[{"batl":[[0,1.79,7.57],[1,1.8,147.03],[2,1.82,189.04]],"ltp":1.74,"tv":3499.31,"id":8257852}]}]}
{"op":"mcm","clk":"1011282177","pt":1580655506621,"mc":[{"id":"1.168223927","rc":[{"batb":[[1,1.71,72.4]],"ltp":1.74,"tv":3499.31,"id":8257852}]}]}
{"op":"mcm","clk":"1011283298","pt":1580655514124,"mc":[{"id":"1.168223927","rc":[{"batl":[[0,1.8,147.03],[1,1.82,189.04],[2,1.84,4.12]],"ltp":1.74,"tv":3499.31,"id":8257852}]}]}
{"op":"mcm","clk":"1011284361","pt":1580655521207,"mc":[{"id":"1.168223927","rc":[{"trd":[[2.26,2310.14]],"batb":[[0,2.26,8.93]],"ltp":2.26,"tv":2917.16,"id":8444055}],"tv":6416.47}]}
{"op":"mcm","clk":"1011284519","pt":1580655522436,"mc":[{"id":"1.168223927","rc":[{"batb":[[2,2.18,21.36]],"ltp":2.26,"tv":2917.16,"id":8444055}]}]}
{"op":"mcm","clk":"1011284752","pt":1580655523931,"mc":[{"id":"1.168223927","rc":[{"batb":[[0,2.24,21.92]],"ltp":2.26,"tv":2917.16,"id":8444055},{"batb":[[0,1.75,41.32],[1,1.74,226.27]],"ltp":1.74,"tv":3499.31,"id":8257852}]}]}
{"op":"mcm","clk":"1011284834","pt":1580655524413,"mc":[{"id":"1.168223927","rc":[{"batb":[[2,1.71,35.5]],"ltp":1.74,"tv":3499.31,"id":8257852}]}]}
{"op":"mcm","clk":"1011285526","pt":1580655529555,"mc":[{"id":"1.168223927","rc":[{"batl":[[0,1.79,7.57],[1,1.8,147.03],[2,1.82,189.04]],"ltp":1.74,"tv":3499.31,"id":8257852}]}]}
{"op":"mcm","clk":"1011285914","pt":1580655532129,"mc":[{"id":"1.168223927","rc":[{"batb":[[1,1.74,182.01]],"ltp":1.74,"tv":3499.31,"id":8257852}]}]}
{"op":"mcm","clk":"1011285966","pt":1580655532549,"mc":[{"id":"1.168223927","rc":[{"batl":[[0,1.8,147.03],[1,1.82,189.04],[2,1.84,4.12]],"ltp":1.74,"tv":3499.31,"id":8257852}]}]}
{"op":"mcm","clk":"1011286735","pt":1580655537749,"mc":[{"id":"1.168223927","rc":[{"batb":[[0,1.75,85.32]],"ltp":1.74,"tv":3499.31,"id":8257852}]}]}
{"op":"mcm","clk":"1011290039","pt":1580655557796,"mc":[{"id":"1.168223927","rc":[{"batl":[[0,1.76,156],[1,1.8,147.03],[2,1.82,189.04]],"ltp":1.74,"tv":3499.31,"id":8257852}]}]}
{"op":"mcm","clk":"1011290175","pt":1580655558499,"mc":[{"id":"1.168223927","rc":[{"batb":[[1,2.22,195.26]],"ltp":2.26,"tv":2917.16,"id":8444055},{"batb":[[2,1.69,166.01]],"ltp":1.74,"tv":3499.31,"id":8257852}]}]}
{"op":"mcm","clk":"1011293434","pt":1580655578721,"mc":[{"id":"1.168223927","rc":[{"trd":[[1.75,775.75]],"batb":[[0,1.75,81.05]],"ltp":1.75,"tv":3507.85,"id":8257852}],"tv":6425.01}]}
{"op":"mcm","clk":"1011293553","pt":1580655579527,"mc":[{"id":"1.168223927","rc":[{"trd":[[1.76,778.99]],"batb":[[0,1.75,56.77]],"batl":[[0,1.76,131.68]],"ltp":1.76,"tv":3556.48,"id":8257852}],"tv":6473.65}]}
{"op":"mcm","clk":"1011293847","pt":1580655581498,"mc":[{"id":"1.168223927","rc":[{"batb":[[0,1.75,12.77]],"ltp":1.76,"tv":3556.48,"id":8257852}]}]}
{"op":"mcm","clk":"1011294078","pt":1580655582705,"mc":[{"id":"1.168223927","rc":[{"batb":[[0,2.26,22.16],[1,2.24,21.92],[2,2.22,195.26]],"ltp":2.26,"tv":2917.16,"id":8444055},{"batb":[[0,1.74,182.01],[1,1.7,80.67]],"ltp":1.76,"tv":3556.48,"id":8257852}]}]}
{"op":"mcm","clk":"1011294830","pt":1580655587128,"mc":[{"id":"1.168223927","rc":[{"batb":[[0,1.74,226.27]],"ltp":1.76,"tv":3556.48,"id":8257852}]}]}
{"op":"mcm","clk":"1011296747","pt":1580655598853,"mc":[{"id":"1.168223927","rc":[{"batb":[[2,2.22,193.68]],"ltp":2.26,"tv":2917.16,"id":8444055}]}]}
{"op":"mcm","clk":"1011296971","pt":1580655600148,"mc":[{"id":"1.168223927","rc":[{"trd":[[1.74,100.18]],"batb":[[0,1.74,226.09]],"ltp":1.74,"tv":3556.84,"id":8257852}],"tv":6474.01}]}
{"op":"mcm","clk":"1011298603","pt":1580655608031,"mc":[{"id":"1.168223927","rc":[{"trd":[[1.74,100.28]],"batb":[[0,1.74,226.04]],"ltp":1.74,"tv":3556.94,"id":8257852}],"tv":6474.11}]}
{"op":"mcm","clk":"1011299638","pt":1580655613926,"mc":[{"id":"1.168223927","rc":[{"trd":[[2.34,14.35]],"batl":[[0,2.34,6.15]],"ltp":2.34,"tv":2918.0,"id":8444055},{"trd":[[1.74,553.5]],"batb":[[0,1.7,80.67],[1,1.69,166.01],[2,1.68,78.28]],"ltp":1.74,"tv":4010.15,"id":8257852}],"tv":6928.16}]}
{"op":"mcm","clk":"1011299718","pt":1580655614431,"mc":[{"id":"1.168223927","rc":[{"batb":[[1,2.24,42.25]],"ltp":2.34,"tv":2918.0,"id":8444055},{"batb":[[1,1.69,129.48],[2,1.68,41.21]],"ltp":1.74,"tv":4010.15,"id":8257852}]}]}
{"op":"mcm","clk":"1011299889","pt":1580655615353,"mc":[{"id":"1.168223927","rc":[{"batl":[[1,2.76,1.68],[2,4.1,153.72]],"ltp":2.34,"tv":2918.0,"id":8444055}]}]}
{"op":"mcm","clk":"1011300484","pt":1580655618962,"mc":[{"id":"1.168223927","rc":[{"batb":[[0,2.28,169.56],[1,2.26,22.16],[2,2.24,42.25]],"ltp":2.34,"tv":2918.0,"id":8444055},{"batb":[[0,1.73,189.15],[1,1.7,80.67],[2,1.69,129.48]],"ltp":1.74,"tv":4010.15,"id":8257852}]}]}
{"op":"mcm","clk":"1011300623","pt":1580655619667,"mc":[{"id":"1.168223927","rc":[{"batb":[[2,2.24,21.92]],"ltp":2.34,"tv":2918.0,"id":8444055}]}]}
{"op":"mcm","clk":"1011301563","pt":1580655625533,"mc":[{"id":"1.168223927","rc":[{"trd":[[2.34,20.5]],"batl":[[0,2.76,1.68],[1,4.1,153.72],[2,95,15.9]],"ltp":2.34,"tv":2924.15,"id":8444055},{"trd":[[1.73,300.07],[1.74,561.77]],"batb":[[0,1.73,45.97]],"ltp":1.73,"tv":4304.79,"id":8257852}],"tv":7228.94}]}
{"op":"mcm","clk":"1011302159","pt":1580655629112,"mc":[{"id":"1.168223927","rc":[{"batb":[[0,2.3,166.96]],"ltp":2.34,"tv":2924.15,"id":8444055},{"batb":[[0,1.72,191.83]],"ltp":1.73,"tv":4304.79,"id":8257852}]}]}
{"op":"mcm","clk":"1011302250","pt":1580655629493,"mc":[{"id":"1.168223927","rc":[{"batb":[[2,2.24,42.25]],"ltp":2.34,"tv":2924.15,"id":8444055}]}]}
{"op":"mcm","clk":"1011302570","pt":1580655631516,"mc":[{"id":"1.168223927","rc":[{"batl":[[0,2.4,16.8],[1,2.76,1.68],[2,4.1,153.72]],"ltp":2.34,"tv":2924.15,"id":8444055}]}]}
{"op":"mcm","clk":"1011303335","pt":1580655635732,"mc":[{"id":"1.168223927","rc":[{"batl":[[0,2.36,16.8]],"ltp":2.34,"tv":2924.15,"id":8444055}]}]}
{"op":"mcm","clk":"1011306089","pt":1580655652243,"mc":[{"id":"1.168223927","rc":[{"batb":[[1,1.69,129.48],[2,1.68,78.28]],"ltp":1.73,"tv":4304.79,"id":8257852}]}]}
{"op":"mcm","clk":"1011306102","pt":1580655652315,"mc":[{"id":"1.168223927","rc":[{"batb":[[0,1.73,39.03],[1,1.72,191.83],[2,1.69,129.48]],"ltp":1.73,"tv":4304.79,"id":8257852}]}]}
{"op":"mcm","clk":"1011306314","pt":1580655653526,"mc":[{"id":"1.168223927","rc":[{"batb":[[2,2.24,21.92]],"ltp":2.34,"tv":2924.15,"id":8444055}]}]}
{"op":"mcm","clk":"1011307880","pt":1580655663337,"mc":[{"id":"1.168223927","rc":[{"trd":[[1.76,794.45]],"batl":[[0,1.76,123.95]],"ltp":1.76,"tv":4320.25,"id":8257852}],"tv":7244.4}]}
{"op":"mcm","clk":"1011310790","pt":1580655678789,"mc":[{"id":"1.168223927","rc":[{"batb":[[0,1.74,16],[1,1.73,39.03],[2,1.72,191.83]],"ltp":1.76,"tv":4320.25,"id":8257852}]}]}
{"op":"mcm","clk":"1011314275","pt":1580655696870,"mc":[{"id":"1.168223927","rc":[{"trd":[[1.74,593.77]],"batb":[[0,1.73,39.03],[1,1.72,191.83],[2,1.69,129.48]],"batl":[[0,1.74,54],[1,1.76,123.95],[2,1.8,147.03]],"ltp":1.74,"tv":4352.25,"id":8257852}],"tv":7276.4}]}
{"op":"mcm","clk":"1011314430","pt":1580655697489,"mc":[{"id":"1.168223927","rc":[{"batb":[[1,2.26,42.17]],"ltp":2.34,"tv":2924.15,"id":8444055}]}]}
{"op":"mcm","clk":"1011315747","pt":1580655704386,"mc":[{"id":"1.168223927","rc":[{"trd":[[1.74,663.79]],"batl":[[0,1.74,18.99]],"ltp":1.74,"tv":4422.27,"id":8257852}],"tv":7346.42}]}
{"op":"mcm","clk":"1011316063","pt":1580655706125,"mc":[{"id":"1.168223927","rc":[{"batb":[[1,2.26,22.16],[2,2.24,42.25]],"ltp":2.34,"tv":2924.15,"id":8444055},{"trd":[[1.74,701.77]],"batb":[[0,1.74,16.02],[1,1.73,39.03],[2,1.72,191.83]],"batl":[[0,1.76,123.95],[1,1.8,147.03],[2,1.82,189.04]],"ltp":1.74,"tv":4460.25,"id":8257852}],"tv":7384.4}]}
{"op":"mcm","clk":"1011316329","pt":1580655707621,"mc":[{"id":"1.168223927","rc":[{"batb":[[2,2.24,21.92]],"ltp":2.34,"tv":2924.15,"id":8444055}]}]}
{"op":"mcm","clk":"1011319311","pt":1580655723910,"mc":[{"id":"1.168223927","rc":[{"batb":[[1,1.73,100.48]],"ltp":1.74,"tv":4460.25,"id":8257852}]}]}
{"op":"mcm","clk":"1011320070","pt":1580655727831,"mc":[{"id":"1.168223927","rc":[{"batb":[[0,1.73,100.48],[1,1.72,191.83],[2,1.69,68.02]],"ltp":1.74,"tv":4460.25,"id":8257852}]}]}
{"op":"mcm","clk":"1011321331","pt":1580655734483,"mc":[{"id":"1.168223927","rc":[{"batb":[[0,2.3,166.73]],"ltp":2.34,"tv":2924.15,"id":8444055}]}]}
{"op":"mcm","clk":"1011322443","pt":1580655740551,"mc":[{"id":"1.168223927","rc":[{"trd":[[1.76,844.38]],"batl":[[0,1.76,98.98]],"ltp":1.76,"tv":4510.19,"id":8257852}],"tv":7434.34}]}
{"op":"mcm","clk":"1011323101","pt":1580655744166,"mc":[{"id":"1.168223927","rc":[{"trd":[[1.73,315.19]],"batb":[[0,1.73,92.92]],"ltp":1.73,"tv":4525.31,"id":8257852}],"tv":7449.46}]}
{"op":"mcm","clk":"1011323178","pt":1580655744552,"mc":[{"id":"1.168223927","rc":[{"batb":[[1,2.26,27.9]],"ltp":2.34,"tv":2924.15,"id":8444055}]}]}
{"op":"mcm","clk":"1011323475","pt":1580655746160,"mc":[{"id":"1.168223927","rc":[{"batb":[[0,1.73,160.94],[2,1.68,78.28]],"ltp":1.73,"tv":4525.31,"id":8257852}]}]}
{"op":"mcm","clk":"1011325048","pt":1580655754986,"mc":[{"id":"1.168223927","rc":[{"batb":[[0,1.74,7.57],[1,1.73,160.94],[2,1.72,191.83]],"ltp":1.73,"tv":4525.31,"id":8257852}]}]}
{"op":"mcm","clk":"1011325373","pt":1580655756682,"mc":[{"id":"1.168223927","rc":[{"batb":[[0,1.73,160.94],[1,1.72,191.83],[2,1.68,78.28]],"ltp":1.73,"tv":4525.31,"id":8257852}]}]}
{"op":"mcm","clk":"1011327560","pt":1580655766931,"mc":[{"id":"1.168223927","rc":[{"batl":[[1,1.8,336.08],[2,1.84,4.12]],"ltp":1.73,"tv":4525.31,"id":8257852}]}]}
{"op":"mcm","clk":"1011336734","pt":1580655811089,"mc":[{"id":"1.168223927","rc":[{"batl":[[0,2.36,255.62]],"ltp":2.34,"tv":2924.15,"id":8444055},{"trd":[[1.76,1042.35]],"batb":[[0,1.76,134.5],[1,1.73,160.94],[2,1.72,191.83]],"batl":[[0,1.8,336.08],[1,1.84,4.12],[2,2,12.6]],"ltp":1.76,"tv":4723.27,"id":8257852}],"tv":7647.43}]}
{"op":"mcm","clk":"1011336884","pt":1580655811893,"mc":[{"id":"1.168223927","rc":[{"trd":[[1.76,1310.35]],"batb":[[0,1.76,168.63]],"ltp":1.76,"tv":4991.28,"id":8257852}],"tv":7915.43}]}
{"op":"mcm","clk":"1011337723","pt":1580655816009,"mc":[{"id":"1.168223927","rc":[{"batb":[[0,1.73,160.94],[1,1.72,191.83],[2,1.7,36.01]],"ltp":1.76,"tv":4991.28,"id":8257852}]}]}
{"op":"mcm","clk":"1011337837","pt":1580655816505,"mc":[{"id":"1.168223927","rc":[{"batb":[[2,1.69,36.53]],"ltp":1.76,"tv":4991.28,"id":8257852}]}]}
{"op":"mcm","clk":"1011338355","pt":1580655819120,"mc":[{"id":"1.168223927","rc":[{"batl":[[0,2.36,16.8]],"ltp":2.34,"tv":2924.15,"id":8444055}]}]}
{"op":"mcm","clk":"1011338444","pt":1580655819501,"mc":[{"id":"1.168223927","rc":[{"batl":[[0,2.34,16.8]],"ltp":2.34,"tv":2924.15,"id":8444055}]}]}
{"op":"mcm","clk":"1011339593","pt":1580655825222,"mc":[{"id":"1.168223927","rc":[{"trd":[[2.34,54.11]],"batb":[[0,2.34,109.01],[1,2.3,166.73],[2,2.26,27.9]],"batl":[[0,2.76,1.68],[1,4.1,153.72],[2,95,15.9]],"ltp":2.34,"tv":2957.76,"id":8444055}],"tv":7949.04}]}
{"op":"mcm","clk":"1011339879","pt":1580655826531,"mc":[{"id":"1.168223927","rc":[{"batb":[[2,2.26,47.91]],"ltp":2.34,"tv":2957.76,"id":8444055},{"batb":[[2,1.68,41.21]],"ltp":1.76,"tv":4991.28,"id":8257852}]}]}
{"op":"mcm","clk":"1011341966","pt":1580655836434,"mc":[{"id":"1.168223927","rc":[{"batb":[[0,2.3,166.73],[1,2.26,47.91],[2,2.24,21.92]],"ltp":2.34,"tv":2957.76,"id":8444055}]}]}
{"op":"mcm","clk":"1011342214","pt":1580655837516,"mc":[{"id":"1.168223927","rc":[{"batb":[[1,2.26,27.9]],"ltp":2.34,"tv":2957.76,"id":8444055},{"batb":[[2,1.68,78.28]],"ltp":1.76,"tv":4991.28,"id":8257852}]}]}
{"op":"mcm","clk":"1011374489","pt":1580655981284,"mc":[{"id":"1.168223927","rc":[{"batb":[[0,2.3,166.18]],"ltp":2.34,"tv":2957.76,"id":8444055}]}]}
{"op":"mcm","clk":"1011378426","pt":1580655998623,"mc":[{"id":"1.168223927","rc":[{"batl":[[0,1.76,142],[1,1.8,336.08],[2,1.84,4.12]],"ltp":1.76,"tv":4991.28,"id":8257852}]}]}
{"op":"mcm","clk":"1011408557","pt":1580656122710,"mc":[{"id":"1.168223927","rc":[{"trd":[[1.73,317.11]],"batb":[[0,1.73,159.99]],"ltp":1.73,"tv":4993.2,"id":8257852}],"tv":7950.96}]}
{"op":"mcm","clk":"1011427028","pt":1580656196396,"mc":[{"id":"1.168223927","rc":[{"batb":[[0,1.74,8.4],[1,1.73,159.99],[2,1.72,191.83]],"ltp":1.73,"tv":4993.2,"id":8257852}]}]}
{"op":"mcm","clk":"1011427278","pt":1580656197454,"mc":[{"id":"1.168223927","rc":[{"batl":[[1,1.8,147.03],[2,1.82,189.04]],"ltp":1.73,"tv":4993.2,"id":8257852}]}]}
{"op":"mcm","clk":"1011431225","pt":1580656212932,"mc":[{"id":"1.168223927","rc":[{"batl":[[0,2.54,177.09],[1,2.76,1.68],[2,4.1,153.72]],"ltp":2.34,"tv":2957.76,"id":8444055}]}]}
{"op":"mcm","clk":"1011433624","pt":1580656222882,"mc":[{"id":"1.168223927","rc":[{"batb":[[0,2.32,163.66]],"ltp":2.34,"tv":2957.76,"id":8444055},{"batb":[[2,1.71,195.37]],"ltp":1.73,"tv":4993.2,"id":8257852}]}]}
{"op":"mcm","clk":"1011433821","pt":1580656223651,"mc":[{"id":"1.168223927","rc":[{"batb":[[2,2.24,42.25]],"ltp":2.34,"tv":2957.76,"id":8444055}]}]}
{"op":"mcm","clk":"1011439009","pt":1580656244004,"mc":[{"id":"1.168223927","rc":[{"trd":[[1.74,705.13]],"batb":[[0,1.74,6.72]],"ltp":1.74,"tv":4996.56,"id":8257852}],"tv":7954.32}]}
{"op":"mcm","clk":"1011445261","pt":1580656268741,"mc":[{"id":"1.168223927","rc":[{"trd":[[2.32,405.93]],"batb":[[0,2.26,27.9],[1,2.24,42.25],[2,2.22,20.66]],"batl":[[0,2.32,894.14],[1,2.54,177.09],[2,2.76,1.68]],"ltp":2.32,"tv":3285.08,"id":8444055},{"trd":[[1.76,1444.79]],"batl":[[0,1.76,74.78]],"ltp":1.76,"tv":5130.99,"id":8257852}],"tv":8416.07}]}
{"op":"mcm","clk":"1011445515","pt":1580656269630,"mc":[{"id":"1.168223927","rc":[{"batb":[[0,2.3,167.67],[1,2.26,27.9],[2,2.24,21.92]],"ltp":2.32,"tv":3285.08,"id":8444055},{"batb":[[2,1.72,191.12]],"ltp":1.76,"tv":5130.99,"id":8257852}]}]}
{"op":"mcm","clk":"1011453649","pt":1580656302995,"mc":[{"id":"1.168223927","rc":[{"trd":[[2.3,466.23]],"batb":[[0,2.26,27.9],[1,2.24,21.92],[2,2.22,20.66]],"ltp":2.3,"tv":3677.62,"id":8444055},{"trd":[[1.76,1519.54]],"batl":[[0,1.8,147.06],[1,1.82,189.04],[2,1.84,4.12]],"ltp":1.76,"tv":5205.74,"id":8257852}],"tv":8883.37}]}
{"op":"mcm","clk":"1011453879","pt":1580656303983,"mc":[{"id":"1.168223927","rc":[{"trd":[[2.32,753.94]],"batb":[[0,2.26,199.67],[2,2.2,21]],"batl":[[0,2.32,720.13]],"ltp":2.32,"tv":4025.63,"id":8444055},{"batb":[[1,1.73,346.86],[2,1.69,36.53]],"ltp":1.76,"tv":5205.74,"id":8257852}],"tv":9231.38}]}
{"op":"mcm","clk":"1011454021","pt":1580656304681,"mc":[{"id":"1.168223927","rc":[{"batb":[[2,1.71,35.5]],"ltp":1.76,"tv":5205.74,"id":8257852}]}]}
{"op":"mcm","clk":"1011457746","pt":1580656320007,"mc":[{"id":"1.168223927","rc":[{"batb":[[0,2.26,27.9]],"ltp":2.32,"tv":4025.63,"id":8444055},{"batb":[[1,1.73,159.99]],"ltp":1.76,"tv":5205.74,"id":8257852}]}]}
{"op":"mcm","clk":"1011457918","pt":1580656320833,"mc":[{"id":"1.168223927","marketDefinition":{"bspMarket":false,"turnInPlayEnabled":true,"persistenceEnabled":true,"marketBaseRate":5.0,"eventId":"29681623","eventTypeId":"2","numberOfWinners":1,"bettingType":"ODDS","marketType":"MATCH_ODDS","marketTime":"2020-02-02T14:50:00.000Z","suspendTime":"2020-02-02T14:50:00.000Z","bspReconciled":false,"complete":true,"inPlay":true,"crossMatching":true,"runnersVoidable":false,"numberOfActiveRunners":2,"betDelay":3,"status":"OPEN","runners":[{"status":"ACTIVE","sortPriority":1,"id":8257852,"name":"Maxime Janvier"},{"status":"ACTIVE","sortPriority":2,"id":8444055,"name":"Cem Ilkel"}],"regulators":["MR_INT"],"countryCode":"FR","discountAllowed":true,"timezone":"UTC","openDate":"2020-02-02T14:50:00.000Z","version":3149418503,"name":"Match Odds","eventName":"Janvier v Ilkel"},"rc":[{"batb":[[0,2,5.43],[1,1.87,21.03],[2,1.5,2.53]],"batl":[[0,2.54,177.09],[1,2.76,1.68],[2,1000,0.02]],"ltp":2.32,"tv":4025.63,"id":8444055},{"batb":[[1,1.68,41.21],[2,1.63,3.41]],"batl":[[0,1.8,147.03],[2,2,12.6]],"ltp":1.76,"tv":5205.74,"id":8257852}]}]}
{"op":"mcm","clk":"1011462624","pt":1580656339191,"mc":[{"id":"1.168223927","rc":[{"batl":[[1,2.56,916],[2,2.76,1.68]],"ltp":2.32,"tv":4025.63,"id":8444055},{"trd":[[1.74,718.57]],"batb":[[0,1.68,41.21],[1,1.63,3.41],[2,1.4,2.54]],"batl":[[0,1.74,1319.28],[1,1.75,3490.8],[2,1.8,147.03]],"ltp":1.74,"tv":5219.18,"id":8257852}],"tv":9244.82}]}
{"op":"mcm","clk":"1011462695","pt":1580656339508,"mc":[{"id":"1.168223927","rc":[{"trd":[[2.34,66.62]],"ltp":2.34,"tv":4038.14,"id":8444055},{"trd":[[1.74,2050.67]],"batl":[[0,1.74,644.82],[1,1.8,147.03],[2,1.82,189.04]],"ltp":1.74,"tv":6551.28,"id":8257852}],"tv":10589.43}]}
{"op":"mcm","clk":"1011463066","pt":1580656340969,"mc":[{"id":"1.168223927","rc":[{"batb":[[0,2.32,153.12],[1,2.18,182.07],[2,2,5.43]],"ltp":2.34,"tv":4038.14,"id":8444055},{"batb":[[0,1.7,207.41],[1,1.68,41.21],[2,1.65,226.84]],"ltp":1.74,"tv":6551.28,"id":8257852}]}]}
{"op":"mcm","clk":"1011464226","pt":1580656345580,"mc":[{"id":"1.168223927","rc":[{"batb":[[2,1.66,494.03]],"batl":[[1,1.78,480.59],[2,1.8,644.43]],"ltp":1.74,"tv":6551.28,"id":8257852}]}]}
{"op":"mcm","clk":"1011465176","pt":1580656349393,"mc":[{"id":"1.168223927","rc":[{"trd":[[1.7,21.22]],"batb":[[0,1.7,204.03]],"ltp":1.7,"tv":6558.04,"id":8257852}],"tv":10596.19}]}
{"op":"mcm","clk":"1011465931","pt":1580656352508,"mc":[{"id":"1.168223927","rc":[{"trd":[[1.74,2076.41]],"batl":[[0,1.74,631.95],[2,1.8,655.86]],"ltp":1.74,"tv":6583.78,"id":8257852}],"tv":10621.93}]}
{"op":"mcm","clk":"1011466578","pt":1580656355165,"mc":[{"id":"1.168223927","rc":[{"batl":[[1,2.76,1.68],[2,1000,0.02]],"ltp":2.34,"tv":4038.14,"id":8444055},{"batl":[[0,1.78,480.59],[1,1.8,655.86],[2,1.82,189.04]],"ltp":1.74,"tv":6583.78,"id":8257852}]}]}
{"op":"mcm","clk":"1011466762","pt":1580656355815,"mc":[{"id":"1.168223927","rc":[{"batb":[[0,2.18,182.07],[1,2,5.43],[2,1.87,21.03]],"ltp":2.34,"tv":4038.14,"id":8444055},{"batb":[[0,1.68,41.21],[1,1.66,494.03],[2,1.65,226.21]],"batl":[[1,1.8,644.43]],"ltp":1.74,"tv":6583.78,"id":8257852}]}]}
{"op":"mcm","clk":"1011467881","pt":1580656360180,"mc":[{"id":"1.168223927","rc":[{"batb":[[1,1.65,226.21],[2,1.63,3.41]],"batl":[[0,1.7,159],[1,1.78,480.59],[2,1.8,644.43]],"ltp":1.74,"tv":6583.78,"id":8257852}]}]}
{"op":"mcm","clk":"1011468311","pt":1580656361891,"mc":[{"id":"1.168223927","rc":[{"batb":[[0,2.36,12.77],[1,2.18,182.07],[2,2,5.43]],"batl":[[0,2.46,12],[1,2.54,177.09],[2,2.62,703]],"ltp":2.34,"tv":4038.14,"id":8444055},{"batb":[[0,1.68,592.05]],"batl":[[0,1.7,1232],[1,1.76,445.23],[2,1.78,480.59]],"ltp":1.74,"tv":6583.78,"id":8257852}]}]}
{"op":"mcm","clk":"1011468514","pt":1580656362668,"mc":[{"id":"1.168223927","rc":[{"batb":[[0,2.18,182.07],[1,2,5.43],[2,1.87,21.03]],"batl":[[0,2.54,177.09],[1,2.62,703],[2,2.76,1.68]],"ltp":2.34,"tv":4038.14,"id":8444055}]}]}
{"op":"mcm","clk":"1011468828","pt":1580656364088,"mc":[{"id":"1.168223927","rc":[{"batb":[[0,2.4,138.87],[1,2.28,159.8],[2,2.22,33.61]],"batl":[[0,2.52,26.89],[1,2.54,177.09],[2,2.62,703]],"ltp":2.34,"tv":4038.14,"id":8444055},{"batb":[[1,1.67,62.17],[2,1.65,226.21]],"ltp":1.74,"tv":6583.78,"id":8257852}]}]}
{"op":"mcm","clk":"1011468918","pt":1580656364459,"mc":[{"id":"1.168223927","rc":[{"batb":[[1,1.65,226.21],[2,1.63,3.41]],"ltp":1.74,"tv":6583.78,"id":8257852}]}]}
{"op":"mcm","clk":"1011469203","pt":1580656365714,"mc":[{"id":"1.168223927","rc":[{"batb":[[1,2.36,12.77],[2,2.28,159.8]],"batl":[[0,2.46,12],[1,2.52,26.89],[2,2.54,177.09]],"ltp":2.34,"tv":4038.14,"id":8444055}]}]}
{"op":"mcm","clk":"1011469618","pt":1580656367272,"mc":[{"id":"1.168223927","rc":[{"batb":[[1,1.66,63.01],[2,1.65,226.21]],"ltp":1.74,"tv":6583.78,"id":8257852}]}]}
{"op":"mcm","clk":"1011469861","pt":1580656368188,"mc":[{"id":"1.168223927","rc":[{"batl":[[0,1.7,1073],[2,1.8,147.03]],"ltp":1.74,"tv":6583.78,"id":8257852}]}]}
{"op":"mcm","clk":"1011470085","pt":1580656369192,"mc":[{"id":"1.168223927","rc":[{"batl":[[1,1.74,480.59],[2,1.76,942.63]],"ltp":1.74,"tv":6583.78,"id":8257852}]}]}
{"op":"mcm","clk":"1011470475","pt":1580656370815,"mc":[{"id":"1.168223927","rc":[{"trd":[[2.42,791.53]],"batl":[[0,2.42,120.43],[1,2.46,12],[2,2.52,26.89]],"ltp":2.42,"tv":4791.95,"id":8444055},{"trd":[[1.7,1094.22]],"batl":[[0,1.74,480.59],[1,1.76,942.63],[2,1.8,147.03]],"ltp":1.7,"tv":7656.78,"id":8257852}],"tv":12448.73}]}
{"op":"mcm","clk":"1011471294","pt":1580656373933,"mc":[{"id":"1.168223927","rc":[{"batb":[[1,2.28,159.8],[2,2.22,33.61]],"batl":[[0,2.52,26.89],[1,2.54,177.09],[2,2.76,1.68]],"ltp":2.42,"tv":4791.95,"id":8444055},{"batb":[[0,1.68,41.21]],"batl":[[1,1.76,497.4]],"ltp":1.7,"tv":7656.78,"id":8257852}]}]}
{"op":"mcm","clk":"1011471440","pt":1580656374512,"mc":[{"id":"1.168223927","rc":[{"batb":[[0,2.28,159.8],[1,2.22,33.61],[2,2,5.43]],"ltp":2.42,"tv":4791.95,"id":8444055},{"batb":[[2,1.64,494.03]],"ltp":1.7,"tv":7656.78,"id":8257852}]}]}
{"op":"mcm","clk":"1011471903","pt":1580656376374,"mc":[{"id":"1.168223927","rc":[{"batb":[[1,2,5.43],[2,1.87,21.03]],"batl":[[0,2.54,177.09],[1,2.76,1.68],[2,1000,0.02]],"ltp":2.42,"tv":4791.95,"id":8444055},{"batb":[[1,1.64,494.03],[2,1.63,3.41]],"ltp":1.7,"tv":7656.78,"id":8257852}]}]}
{"op":"mcm","clk":"1011472250","pt":1580656377809,"mc":[{"id":"1.168223927","rc":[{"batb":[[0,2.26,163.74]],"ltp":2.42,"tv":4791.95,"id":8444055},{"trd":[[1.68,371.88]],"batb":[[0,1.64,494.03],[1,1.63,240.63],[2,1.62,510.84]],"batl":[[0,1.68,117.8],[1,1.74,480.59],[2,1.76,497.4]],"ltp":1.68,"tv":7739.19,"id":8257852}],"tv":12531.14}]}
{"op":"mcm","clk":"1011474412","pt":1580656386699,"mc":[{"id":"1.168223927","rc":[{"trd":[[1.64,27.51]],"batb":[[0,1.64,493.64]],"ltp":1.64,"tv":7739.97,"id":8257852}],"tv":12531.93}]}
{"op":"mcm","clk":"1011474752","pt":1580656388107,"mc":[{"id":"1.168223927","rc":[{"trd":[[1.68,378.64]],"batb":[[0,1.63,240.63],[1,1.4,2.54],[2,1.3,113.58]],"batl":[[0,1.68,114.42]],"ltp":1.68,"tv":7746.73,"id":8257852}],"tv":12538.69}]}
