{"op":"mcm","clk":"1004323371","pt":1580581675727,"mc":[{"id":"1.168223928","marketDefinition":{"bspMarket":false,"turnInPlayEnabled":true,"persistenceEnabled":true,"marketBaseRate":5.0,"eventId":"29681623","eventTypeId":"2","numberOfWinners":1,"bettingType":"ODDS","marketType":"SET_BETTING","marketTime":"2020-02-02T15:00:00.000Z","suspendTime":"2020-02-02T15:00:00.000Z","bspReconciled":false,"complete":true,"inPlay":false,"crossMatching":false,"runnersVoidable":false,"numberOfActiveRunners":4,"betDelay":0,"status":"OPEN","runners":[{"status":"ACTIVE","sortPriority":1,"id":13015339,"name":"Janvier 2-0"},{"status":"ACTIVE","sortPriority":2,"id":13015338,"name":"Janvier 2-1"},{"status":"ACTIVE","sortPriority":3,"id":13014431,"name":"Ilkel 2-0"},{"status":"ACTIVE","sortPriority":4,"id":13014430,"name":"Ilkel 2-1"}],"regulators":["MR_INT"],"countryCode":"FR","discountAllowed":false,"timezone":"UTC","openDate":"2020-02-02T15:00:00.000Z","version":3146826540,"name":"Set Betting","eventName":"Janvier v Ilkel"}}]}
{"op":"mcm","clk":"1004323649","pt":1580581677280,"mc":[{"id":"1.168223928","marketDefinition":{"bspMarket":false,"turnInPlayEnabled":true,"persistenceEnabled":true,"marketBaseRate":5.0,"eventId":"29681623","eventTypeId":"2","numberOfWinners":1,"bettingType":"ODDS","marketType":"SET_BETTING","marketTime":"2020-02-02T15:00:00.000Z","suspendTime":"2020-02-02T15:00:00.000Z","bspReconciled":false,"complete":true,"inPlay":false,"crossMatching":false,"runnersVoidable":false,"numberOfActiveRunners":4,"betDelay":0,"status":"OPEN","runners":[{"status":"ACTIVE","sortPriority":1,"id":13015339,"name":"Janvier 2-0"},{"status":"ACTIVE","sortPriority":2,"id":13015338,"name":"Janvier 2-1"},{"status":"ACTIVE","sortPriority":3,"id":13014431,"name":"Ilkel 2-0"},{"status":"ACTIVE","sortPriority":4,"id":13014430,"name":"Ilkel 2-1"}],"regulators":["MR_INT"],"countryCode":"FR","discountAllowed":true,"timezone":"UTC","openDate":"2020-02-02T15:00:00.000Z","version":3146826540,"name":"Set Betting","eventName":"Janvier v Ilkel"}}]}
{"op":"mcm","clk":"1004791199","pt":1580584352331,"mc":[{"id":"1.168223928","rc":[{"batb":[[0,1.02,2]],"ltp":0.0,"tv":0.0,"id":13015339},{"batb":[[0,1.02,2]],"ltp":0.0,"tv":0.0,"id":13015338},{"batb":[[0,1.02,2]],"ltp":0.0,"tv":0.0,"id":13014431},{"batb":[[0,1.02,2]],"ltp":0.0,"tv":0.0,"id":13014430}]}]}
{"op":"mcm","clk":"1006765967","pt":1580600135488,"mc":[{"id":"1.168223928","rc":[{"batb":[[0,2.04,30.29],[1,1.02,2]],"ltp":0.0,"tv":0.0,"id":13015339}]}]}
{"op":"mcm","clk":"1006925674","pt":1580602197127,"mc":[{"id":"1.168223928","rc":[{"batb":[[0,2.08,123.56],[1,2.04,30.29],[2,1.02,2]],"ltp":0.0,"tv":0.0,"id":13015339}]}]}
{"op":"mcm","clk":"1006925740","pt":1580602197700,"mc":[{"id":"1.168223928","rc":[{"batl":[[0,4.7,198.75]],"ltp":0.0,"tv":0.0,"id":13015339},{"batb":[[0,2.88,88.96],[1,1.02,2]],"batl":[[0,7.2,364.17]],"ltp":0.0,"tv":0.0,"id":13015338},{"batb":[[0,2.64,97.32],[1,1.02,2]],"batl":[[0,9.8,263.42]],"ltp":0.0,"tv":0.0,"id":13014431},{"batb":[[0,3,85.57],[1,1.02,2]],"batl":[[0,40,61.65]],"ltp":0.0,"tv":0.0,"id":13014430}]}]}
{"op":"mcm","clk":"1006926260","pt":1580602204120,"mc":[{"id":"1.168223928","rc":[{"batb":[[0,2.1,30.29],[1,2.08,123.56]],"ltp":0.0,"tv":0.0,"id":13015339}]}]}
{"op":"mcm","clk":"1006926289","pt":1580602204428,"mc":[{"id":"1.168223928","rc":[{"batb":[[0,2.3,111.68],[1,2.1,30.29]],"ltp":0.0,"tv":0.0,"id":13015339}]}]}
{"op":"mcm","clk":"1006936559","pt":1580602325850,"mc":[{"id":"1.168223928","rc":[{"batb":[[0,2.32,30.29],[1,2.3,111.68]],"ltp":0.0,"tv":0.0,"id":13015339}]}]}
{"op":"mcm","clk":"1006958545","pt":1580602585241,"mc":[{"id":"1.168223928","rc":[{"batb":[[0,2.38,107.96],[1,2.32,30.29]],"ltp":0.0,"tv":0.0,"id":13015339},{"batb":[[2,1.01,0.51]],"ltp":0.0,"tv":0.0,"id":13015338},{"batb":[[2,1.01,0.51]],"ltp":0.0,"tv":0.0,"id":13014431},{"batb":[[2,1.01,0.51]],"ltp":0.0,"tv":0.0,"id":13014430}]}]}
{"op":"mcm","clk":"1006960250","pt":1580602605994,"mc":[{"id":"1.168223928","marketDefinition":{"bspMarket":false,"turnInPlayEnabled":true,"persistenceEnabled":true,"marketBaseRate":5.0,"eventId":"29681623","eventTypeId":"2","numberOfWinners":1,"bettingType":"ODDS","marketType":"SET_BETTING","marketTime":"2020-02-02T15:00:00.000Z","suspendTime":"2020-02-02T15:00:00.000Z","bspReconciled":false,"complete":true,"inPlay":false,"crossMatching":true,"runnersVoidable":false,"numberOfActiveRunners":4,"betDelay":0,"status":"OPEN","runners":[{"status":"ACTIVE","sortPriority":1,"id":13015339,"name":"Janvier 2-0"},{"status":"ACTIVE","sortPriority":2,"id":13015338,"name":"Janvier 2-1"},{"status":"ACTIVE","sortPriority":3,"id":13014431,"name":"Ilkel 2-0"},{"status":"ACTIVE","sortPriority":4,"id":13014430,"name":"Ilkel 2-1"}],"regulators":["MR_INT"],"countryCode":"FR","discountAllowed":true,"timezone":"UTC","openDate":"2020-02-02T15:00:00.000Z","version":3146844614,"name":"Set Betting","eventName":"Janvier v Ilkel"}}]}
{"op":"mcm","clk":"1006967338","pt":1580602690768,"mc":[{"id":"1.168223928","rc":[{"batb":[[1,1.02,2],[2,1.01,0.51]],"ltp":0.0,"tv":0.0,"id":13015339}]}]}
{"op":"mcm","clk":"1007018697","pt":1580603351094,"mc":[{"id":"1.168223928","rc":[{"batb":[[2,1.01,3.04]],"ltp":0.0,"tv":0.0,"id":13015339},{"batb":[[2,1.01,3.04]],"ltp":0.0,"tv":0.0,"id":13015338},{"batb":[[2,1.01,3.04]],"ltp":0.0,"tv":0.0,"id":13014431},{"batb":[[2,1.01,3.04]],"ltp":0.0,"tv":0.0,"id":13014430}]}]}
{"op":"mcm","clk":"1007018766","pt":1580603351976,"mc":[{"id":"1.168223928","rc":[{"batb":[[2,1.01,1.01]],"ltp":0.0,"tv":0.0,"id":13015339},{"batb":[[2,1.01,1.01]],"ltp":0.0,"tv":0.0,"id":13015338},{"batb":[[2,1.01,1.01]],"ltp":0.0,"tv":0.0,"id":13014431},{"batb":[[2,1.01,1.01]],"ltp":0.0,"tv":0.0,"id":13014430}]}]}
{"op":"mcm","clk":"1007144577","pt":1580605798112,"mc":[{"id":"1.168223928","rc":[{"batb":[[0,2.22,115.84]],"ltp":0.0,"tv":0.0,"id":13015339},{"batb":[[0,1.02,2],[1,1.01,1.01],[2,1.01,0]],"ltp":0.0,"tv":0.0,"id":13015338},{"batb":[[0,1.02,2],[1,1.01,1.01],[2,1.01,0]],"ltp":0.0,"tv":0.0,"id":13014431},{"batb":[[0,1.02,2],[1,1.01,1.01],[2,1.01,0]],"batl":[[0,21,117.37]],"ltp":0.0,"tv":0.0,"id":13014430}]}]}
{"op":"mcm","clk":"1007147410","pt":1580605856016,"mc":[{"id":"1.168223928","rc":[{"batb":[[0,2.28,112.66],[1,2.24,30.29],[2,1.02,2]],"batl":[[0,4,233.64]],"ltp":0.0,"tv":0.0,"id":13015339}]}]}
{"op":"mcm","clk":"1007153402","pt":1580605978117,"mc":[{"id":"1.168223928","rc":[{"batb":[[0,2.3,30.29],[1,2.28,112.66]],"ltp":0.0,"tv":0.0,"id":13015339}]}]}
{"op":"mcm","clk":"1007153422","pt":1580605978426,"mc":[{"id":"1.168223928","rc":[{"batb":[[0,2.32,110.64],[1,2.3,30.29]],"ltp":0.0,"tv":0.0,"id":13015339}]}]}
{"op":"mcm","clk":"1007159995","pt":1580606099701,"mc":[{"id":"1.168223928","rc":[{"batb":[[1,1.02,2],[2,1.01,1.01]],"ltp":0.0,"tv":0.0,"id":13015339}]}]}
{"op":"mcm","clk":"1007165875","pt":1580606221256,"mc":[{"id":"1.168223928","rc":[{"batb":[[0,2.34,30.29],[1,2.32,110.64],[2,1.02,2]],"ltp":0.0,"tv":0.0,"id":13015339}]}]}
{"op":"mcm","clk":"1007165921","pt":1580606222082,"mc":[{"id":"1.168223928","rc":[{"batb":[[0,2.38,107.96],[1,2.34,30.29]],"ltp":0.0,"tv":0.0,"id":13015339},{"batb":[[0,3.6,70.99],[1,3.4,30.29],[2,1.02,2]],"batl":[[0,15,172.39]],"ltp":0.0,"tv":0.0,"id":13014431}]}]}
{"op":"mcm","clk":"1007171313","pt":1580606343043,"mc":[{"id":"1.168223928","rc":[{"batb":[[1,1.02,2],[2,1.01,1.01]],"ltp":0.0,"tv":0.0,"id":13015339}]}]}
{"op":"mcm","clk":"1007171371","pt":1580606344023,"mc":[{"id":"1.168223928","rc":[{"batb":[[0,3.75,68.11],[1,3.65,30.29]],"ltp":0.0,"tv":0.0,"id":13014431}]}]}
{"op":"mcm","clk":"1007177346","pt":1580606465161,"mc":[{"id":"1.168223928","rc":[{"batb":[[0,3.85,66.37],[1,3.8,30.29]],"ltp":0.0,"tv":0.0,"id":13014431}]}]}
{"op":"mcm","clk":"1007182803","pt":1580606586729,"mc":[{"id":"1.168223928","rc":[{"batb":[[0,3.95,64.71],[1,3.9,30.29]],"ltp":0.0,"tv":0.0,"id":13014431}]}]}
{"op":"mcm","clk":"1007188224","pt":1580606708093,"mc":[{"id":"1.168223928","rc":[{"batb":[[0,4,30.29],[1,3.95,64.71]],"ltp":0.0,"tv":0.0,"id":13014431}]}]}
{"op":"mcm","clk":"1007188232","pt":1580606708298,"mc":[{"id":"1.168223928","rc":[{"batb":[[1,1.02,2],[2,1.01,1.01]],"ltp":0.0,"tv":0.0,"id":13014431}]}]}
{"op":"mcm","clk":"1007193305","pt":1580606830182,"mc":[{"id":"1.168223928","rc":[{"batb":[[0,3.65,70.13],[1,3.4,30.29],[2,1.02,2]],"ltp":0.0,"tv":0.0,"id":13014431}]}]}
{"op":"mcm","clk":"1007197132","pt":1580606951891,"mc":[{"id":"1.168223928","rc":[{"batb":[[0,3.75,68.11],[1,3.7,30.29]],"ltp":0.0,"tv":0.0,"id":13014431}]}]}
{"op":"mcm","clk":"1007201998","pt":1580607073236,"mc":[{"id":"1.168223928","rc":[{"batb":[[0,3.8,30.29],[1,1.02,2],[2,1.01,1.01]],"ltp":0.0,"tv":0.0,"id":13014431}]}]}
{"op":"mcm","clk":"1007202004","pt":1580607073343,"mc":[{"id":"1.168223928","rc":[{"batb":[[0,3.85,66.37],[1,3.8,30.29],[2,1.02,2]],"ltp":0.0,"tv":0.0,"id":13014431}]}]}
{"op":"mcm","clk":"1007207353","pt":1580607195183,"mc":[{"id":"1.168223928","rc":[{"batb":[[0,3.95,64.71],[1,3.9,30.29]],"ltp":0.0,"tv":0.0,"id":13014431}]}]}
{"op":"mcm","clk":"1007211527","pt":1580607317156,"mc":[{"id":"1.168223928","rc":[{"batb":[[0,4,30.29],[1,1.02,2],[2,1.01,1.01]],"ltp":0.0,"tv":0.0,"id":13014431}]}]}
{"op":"mcm","clk":"1007215982","pt":1580607438168,"mc":[{"id":"1.168223928","rc":[{"batb":[[0,1.02,2],[1,1.01,1.01],[2,1.01,0]],"ltp":0.0,"tv":0.0,"id":13014431}]}]}
{"op":"mcm","clk":"1007216011","pt":1580607438738,"mc":[{"id":"1.168223928","rc":[{"batb":[[0,3.5,73.28],[1,3.4,30.29],[2,1.02,2]],"ltp":0.0,"tv":0.0,"id":13014431}]}]}
{"op":"mcm","clk":"1007220966","pt":1580607560177,"mc":[{"id":"1.168223928","rc":[{"batb":[[0,3.6,70.99],[1,3.55,30.29]],"ltp":0.0,"tv":0.0,"id":13014431}]}]}
{"op":"mcm","clk":"1007225855","pt":1580607682031,"mc":[{"id":"1.168223928","rc":[{"batb":[[0,3.75,68.11],[1,3.65,30.29]],"ltp":0.0,"tv":0.0,"id":13014431}]}]}
{"op":"mcm","clk":"1007230049","pt":1580607803270,"mc":[{"id":"1.168223928","rc":[{"batb":[[0,3.8,30.29],[1,3.75,68.11]],"ltp":0.0,"tv":0.0,"id":13014431}]}]}
{"op":"mcm","clk":"1007230061","pt":1580607803581,"mc":[{"id":"1.168223928","rc":[{"batb":[[0,3.85,66.37],[1,3.8,30.29]],"ltp":0.0,"tv":0.0,"id":13014431}]}]}
{"op":"mcm","clk":"1007235388","pt":1580607925204,"mc":[{"id":"1.168223928","rc":[{"batb":[[0,3.95,64.71],[1,3.9,30.29]],"ltp":0.0,"tv":0.0,"id":13014431}]}]}
{"op":"mcm","clk":"1007240308","pt":1580608047171,"mc":[{"id":"1.168223928","rc":[{"batb":[[0,4,30.29],[1,3.95,64.71]],"ltp":0.0,"tv":0.0,"id":13014431}]}]}
{"op":"mcm","clk":"1007240320","pt":1580608047377,"mc":[{"id":"1.168223928","rc":[{"batb":[[1,1.02,2],[2,1.01,1.01]],"ltp":0.0,"tv":0.0,"id":13014431}]}]}
{"op":"mcm","clk":"1007245165","pt":1580608168212,"mc":[{"id":"1.168223928","rc":[{"batb":[[0,3.4,30.29]],"ltp":0.0,"tv":0.0,"id":13014431}]}]}
{"op":"mcm","clk":"1007245194","pt":1580608168731,"mc":[{"id":"1.168223928","rc":[{"batb":[[0,3.65,70.13],[1,3.4,30.29],[2,1.02,2]],"ltp":0.0,"tv":0.0,"id":13014431}]}]}
{"op":"mcm","clk":"1007249931","pt":1580608290197,"mc":[{"id":"1.168223928","rc":[{"batb":[[0,3.7,30.29],[1,1.02,2],[2,1.01,1.01]],"ltp":0.0,"tv":0.0,"id":13014431}]}]}
{"op":"mcm","clk":"1007249937","pt":1580608290301,"mc":[{"id":"1.168223928","rc":[{"batb":[[0,3.8,67.23],[1,3.7,30.29],[2,1.02,2]],"ltp":0.0,"tv":0.0,"id":13014431}]}]}
{"op":"mcm","clk":"1007253396","pt":1580608412965,"mc":[{"id":"1.168223928","rc":[{"batb":[[0,3.9,65.56],[1,3.85,30.29]],"ltp":0.0,"tv":0.0,"id":13014431}]}]}
{"op":"mcm","clk":"1007256820","pt":1580608534225,"mc":[{"id":"1.168223928","rc":[{"batb":[[1,1.02,2],[2,1.01,1.01]],"ltp":0.0,"tv":0.0,"id":13014431}]}]}
{"op":"mcm","clk":"1007256838","pt":1580608534631,"mc":[{"id":"1.168223928","rc":[{"batb":[[0,3.95,95]],"ltp":0.0,"tv":0.0,"id":13014431}]}]}
{"op":"mcm","clk":"1007260146","pt":1580608656069,"mc":[{"id":"1.168223928","rc":[{"batb":[[0,4,30.29]],"ltp":0.0,"tv":0.0,"id":13014431}]}]}
{"op":"mcm","clk":"1007263465","pt":1580608778238,"mc":[{"id":"1.168223928","rc":[{"batb":[[0,3.4,30.29]],"ltp":0.0,"tv":0.0,"id":13014431}]}]}
{"op":"mcm","clk":"1007263483","pt":1580608778601,"mc":[{"id":"1.168223928","rc":[{"batb":[[0,3.8,67.23],[1,3.4,30.29],[2,1.02,2]],"ltp":0.0,"tv":0.0,"id":13014431}]}]}
{"op":"mcm","clk":"1007267157","pt":1580608899752,"mc":[{"id":"1.168223928","rc":[{"batb":[[0,3.9,65.56],[1,3.85,30.29]],"ltp":0.0,"tv":0.0,"id":13014431}]}]}
{"op":"mcm","clk":"1007270270","pt":1580609021181,"mc":[{"id":"1.168223928","rc":[{"batb":[[0,3.95,30.29],[1,3.9,65.56]],"ltp":0.0,"tv":0.0,"id":13014431}]}]}
{"op":"mcm","clk":"1007270281","pt":1580609021594,"mc":[{"id":"1.168223928","rc":[{"batb":[[0,3.95,95],[1,1.02,2],[2,1.01,1.01]],"ltp":0.0,"tv":0.0,"id":13014431}]}]}
{"op":"mcm","clk":"1007274123","pt":1580609142833,"mc":[{"id":"1.168223928","rc":[{"batb":[[0,4,30.29]],"ltp":0.0,"tv":0.0,"id":13014431}]}]}
{"op":"mcm","clk":"1007278722","pt":1580609264214,"mc":[{"id":"1.168223928","rc":[{"batb":[[0,1.02,2],[1,1.01,1.01],[2,1.01,0]],"ltp":0.0,"tv":0.0,"id":13014431}]}]}
{"op":"mcm","clk":"1007278743","pt":1580609264627,"mc":[{"id":"1.168223928","rc":[{"batb":[[0,3.45,74.21],[1,3.4,30.29],[2,1.02,2]],"ltp":0.0,"tv":0.0,"id":13014431}]}]}
{"op":"mcm","clk":"1007282713","pt":1580609386245,"mc":[{"id":"1.168223928","rc":[{"batb":[[0,3.5,30.29],[1,1.02,2],[2,1.01,1.01]],"ltp":0.0,"tv":0.0,"id":13014431}]}]}
{"op":"mcm","clk":"1007282719","pt":1580609386347,"mc":[{"id":"1.168223928","rc":[{"batb":[[0,3.55,71.99],[1,3.5,30.29],[2,1.02,2]],"ltp":0.0,"tv":0.0,"id":13014431}]}]}
{"op":"mcm","clk":"1007283123","pt":1580609398265,"mc":[{"id":"1.168223928","rc":[{"batb":[[0,2.56,100.33],[1,1.02,2],[2,1.01,1.01]],"batl":[[0,9,291.5]],"ltp":0.0,"tv":0.0,"id":13015338},{"batb":[[0,3.15,81.23],[1,1.02,2],[2,1.01,1.01]],"ltp":0.0,"tv":0.0,"id":13014430}]}]}
{"op":"mcm","clk":"1007283139","pt":1580609398782,"mc":[{"id":"1.168223928","rc":[{"batb":[[0,2.18,117.86]],"ltp":0.0,"tv":0.0,"id":13015339}]}]}
{"op":"mcm","clk":"1007287228","pt":1580609508188,"mc":[{"id":"1.168223928","rc":[{"batb":[[0,2.2,30.29],[1,2.18,117.86],[2,1.02,2]],"ltp":0.0,"tv":0.0,"id":13015339}]}]}
{"op":"mcm","clk":"1007287276","pt":1580609509118,"mc":[{"id":"1.168223928","rc":[{"batb":[[0,2.34,109.72],[1,2.2,30.29]],"batl":[[0,4.5,207.55]],"ltp":0.0,"tv":0.0,"id":13015339},{"batb":[[0,3.65,70.13],[1,3.6,30.29]],"ltp":0.0,"tv":0.0,"id":13014431}]}]}
{"op":"mcm","clk":"1007292615","pt":1580609629251,"mc":[{"id":"1.168223928","rc":[{"batb":[[1,1.02,2],[2,1.01,1.01]],"ltp":0.0,"tv":0.0,"id":13015339}]}]}
{"op":"mcm","clk":"1007292661","pt":1580609630158,"mc":[{"id":"1.168223928","rc":[{"batb":[[0,2.38,107.96],[1,2.36,30.29],[2,1.02,2]],"ltp":0.0,"tv":0.0,"id":13015339},{"batb":[[0,3.9,65.56],[1,3.7,30.29]],"ltp":0.0,"tv":0.0,"id":13014431}]}]}
{"op":"mcm","clk":"1007298144","pt":1580609751016,"mc":[{"id":"1.168223928","rc":[{"batb":[[1,1.02,2],[2,1.01,1.01]],"ltp":0.0,"tv":0.0,"id":13015339}]}]}
{"op":"mcm","clk":"1007298187","pt":1580609751890,"mc":[{"id":"1.168223928","rc":[{"batb":[[0,3.95,95],[1,1.02,2],[2,1.01,1.01]],"ltp":0.0,"tv":0.0,"id":13014431}]}]}
{"op":"mcm","clk":"1007300695","pt":1580609822398,"mc":[{"id":"1.168223928","rc":[{"batl":[[0,13,198.87]],"ltp":0.0,"tv":0.0,"id":13014431}]}]}
{"op":"mcm","clk":"1007302441","pt":1580609872951,"mc":[{"id":"1.168223928","rc":[{"batb":[[0,4,30.29]],"ltp":0.0,"tv":0.0,"id":13014431}]}]}
{"op":"mcm","clk":"1007306203","pt":1580609994231,"mc":[{"id":"1.168223928","rc":[{"batb":[[0,1.02,2],[1,1.01,1.01],[2,1.01,0]],"ltp":0.0,"tv":0.0,"id":13014431}]}]}
{"op":"mcm","clk":"1007306236","pt":1580609994802,"mc":[{"id":"1.168223928","rc":[{"batb":[[0,3.45,74.21],[1,3.4,30.29],[2,1.02,2]],"ltp":0.0,"tv":0.0,"id":13014431}]}]}
{"op":"mcm","clk":"1007310661","pt":1580610116241,"mc":[{"id":"1.168223928","rc":[{"batb":[[0,3.5,30.29],[1,1.02,2],[2,1.01,1.01]],"ltp":0.0,"tv":0.0,"id":13014431}]}]}
{"op":"mcm","clk":"1007310664","pt":1580610116343,"mc":[{"id":"1.168223928","rc":[{"batb":[[0,3.6,70.99],[1,3.5,30.29],[2,1.02,2]],"ltp":0.0,"tv":0.0,"id":13014431}]}]}
{"op":"mcm","clk":"1007314730","pt":1580610238035,"mc":[{"id":"1.168223928","rc":[{"batb":[[0,3.75,68.11],[1,3.65,30.29]],"ltp":0.0,"tv":0.0,"id":13014431}]}]}
{"op":"mcm","clk":"1007318113","pt":1580610359687,"mc":[{"id":"1.168223928","rc":[{"batb":[[0,3.85,66.37],[1,3.8,30.29]],"ltp":0.0,"tv":0.0,"id":13014431}]}]}
{"op":"mcm","clk":"1007321922","pt":1580610481263,"mc":[{"id":"1.168223928","rc":[{"batb":[[0,3.9,30.29],[1,1.02,2],[2,1.01,1.01]],"ltp":0.0,"tv":0.0,"id":13014431}]}]}
{"op":"mcm","clk":"1007321927","pt":1580610481318,"mc":[{"id":"1.168223928","rc":[{"batb":[[0,3.95,64.71],[1,3.9,30.29],[2,1.02,2]],"ltp":0.0,"tv":0.0,"id":13014431}]}]}
{"op":"mcm","clk":"1007326016","pt":1580610603075,"mc":[{"id":"1.168223928","rc":[{"batb":[[0,4,30.29],[1,1.02,2],[2,1.01,1.01]],"ltp":0.0,"tv":0.0,"id":13014431}]}]}
{"op":"mcm","clk":"1007330657","pt":1580610726028,"mc":[{"id":"1.168223928","rc":[{"batb":[[0,3.55,71.99],[1,3.4,30.29],[2,1.02,2]],"ltp":0.0,"tv":0.0,"id":13014431}]}]}
{"op":"mcm","clk":"1007334828","pt":1580610847151,"mc":[{"id":"1.168223928","rc":[{"batb":[[0,3.6,30.29],[1,3.55,71.99]],"ltp":0.0,"tv":0.0,"id":13014431}]}]}
{"op":"mcm","clk":"1007334840","pt":1580610847458,"mc":[{"id":"1.168223928","rc":[{"batb":[[0,3.7,69.12],[1,3.6,30.29]],"ltp":0.0,"tv":0.0,"id":13014431}]}]}
{"op":"mcm","clk":"1007338777","pt":1580610969830,"mc":[{"id":"1.168223928","rc":[{"batb":[[0,3.85,66.37],[1,3.75,30.29]],"ltp":0.0,"tv":0.0,"id":13014431}]}]}
{"op":"mcm","clk":"1007341975","pt":1580611090813,"mc":[{"id":"1.168223928","rc":[{"batb":[[0,3.95,64.71],[1,3.9,30.29]],"ltp":0.0,"tv":0.0,"id":13014431}]}]}
{"op":"mcm","clk":"1007345537","pt":1580611212152,"mc":[{"id":"1.168223928","rc":[{"batb":[[0,4,30.29],[1,3.95,64.71]],"ltp":0.0,"tv":0.0,"id":13014431}]}]}
{"op":"mcm","clk":"1007345543","pt":1580611212355,"mc":[{"id":"1.168223928","rc":[{"batb":[[1,1.02,2],[2,1.01,1.01]],"ltp":0.0,"tv":0.0,"id":13014431}]}]}
{"op":"mcm","clk":"1007349290","pt":1580611327120,"mc":[{"id":"1.168223928","rc":[{"batl":[[0,4.5,57.31]],"ltp":0.0,"tv":0.0,"id":13015339},{"batl":[[0,13,190.62]],"ltp":0.0,"tv":0.0,"id":13014430}]}]}
{"op":"mcm","clk":"1007349548","pt":1580611334216,"mc":[{"id":"1.168223928","rc":[{"batb":[[0,3.4,30.29]],"ltp":0.0,"tv":0.0,"id":13014431}]}]}
{"op":"mcm","clk":"1007349552","pt":1580611334319,"mc":[{"id":"1.168223928","rc":[{"batb":[[0,3.45,74.21],[1,3.4,30.29],[2,1.02,2]],"ltp":0.0,"tv":0.0,"id":13014431}]}]}
{"op":"mcm","clk":"1007353793","pt":1580611455256,"mc":[{"id":"1.168223928","rc":[{"batb":[[0,2.4,30.29],[1,2.38,107.96],[2,1.02,2]],"ltp":0.0,"tv":0.0,"id":13015339}]}]}
{"op":"mcm","clk":"1007353831","pt":1580611456232,"mc":[{"id":"1.168223928","rc":[{"batb":[[0,2.42,106.13],[1,2.4,30.29]],"ltp":0.0,"tv":0.0,"id":13015339},{"batb":[[0,3.75,68.11],[1,3.5,30.29]],"ltp":0.0,"tv":0.0,"id":13014431}]}]}
{"op":"mcm","clk":"1007358445","pt":1580611577120,"mc":[{"id":"1.168223928","rc":[{"batb":[[0,2.44,30.29],[1,2.42,106.13]],"ltp":0.0,"tv":0.0,"id":13015339}]}]}
{"op":"mcm","clk":"1007358511","pt":1580611578092,"mc":[{"id":"1.168223928","rc":[{"batb":[[1,1.02,2],[2,1.01,1.01]],"ltp":0.0,"tv":0.0,"id":13015339},{"batb":[[0,3.85,66.37],[1,3.8,30.29]],"ltp":0.0,"tv":0.0,"id":13014431}]}]}
{"op":"mcm","clk":"1007359644","pt":1580611608921,"mc":[{"id":"1.168223928","rc":[{"batl":[[0,4.5,211.95]],"ltp":0.0,"tv":0.0,"id":13015339}]}]}
{"op":"mcm","clk":"1007362783","pt":1580611699247,"mc":[{"id":"1.168223928","rc":[{"batb":[[0,2.12,30.29]],"ltp":0.0,"tv":0.0,"id":13015339}]}]}
{"op":"mcm","clk":"1007362821","pt":1580611699963,"mc":[{"id":"1.168223928","rc":[{"batb":[[0,2.2,116.72],[1,2.12,30.29],[2,1.02,2]],"ltp":0.0,"tv":0.0,"id":13015339},{"batb":[[1,1.02,2],[2,1.01,1.01]],"ltp":0.0,"tv":0.0,"id":13014431}]}]}
{"op":"mcm","clk":"1007362854","pt":1580611701049,"mc":[{"id":"1.168223928","rc":[{"batb":[[0,3.95,64.71],[1,3.9,30.29],[2,1.02,2]],"ltp":0.0,"tv":0.0,"id":13014431}]}]}
{"op":"mcm","clk":"1007367425","pt":1580611821233,"mc":[{"id":"1.168223928","rc":[{"batb":[[0,2.28,112.66],[1,2.22,30.29]],"ltp":0.0,"tv":0.0,"id":13015339},{"batb":[[1,1.02,2],[2,1.01,1.01]],"ltp":0.0,"tv":0.0,"id":13014431}]}]}
{"op":"mcm","clk":"1007371746","pt":1580611942184,"mc":[{"id":"1.168223928","rc":[{"batb":[[0,2.3,30.29],[1,2.28,112.66]],"ltp":0.0,"tv":0.0,"id":13015339}]}]}
{"op":"mcm","clk":"1007371765","pt":1580611942596,"mc":[{"id":"1.168223928","rc":[{"batb":[[0,2.32,110.64],[1,2.3,30.29]],"ltp":0.0,"tv":0.0,"id":13015339}]}]}
{"op":"mcm","clk":"1007375274","pt":1580612064218,"mc":[{"id":"1.168223928","rc":[{"batb":[[0,2.4,106.91],[1,2.34,30.29]],"ltp":0.0,"tv":0.0,"id":13015339}]}]}
{"op":"mcm","clk":"1007379483","pt":1580612185753,"mc":[{"id":"1.168223928","rc":[{"batb":[[0,2.42,136.42],[1,1.02,2],[2,1.01,1.01]],"ltp":0.0,"tv":0.0,"id":13015339}]}]}
{"op":"mcm","clk":"1007383166","pt":1580612307225,"mc":[{"id":"1.168223928","rc":[{"batb":[[0,2.44,30.29],[1,2.42,106.13],[2,1.02,2]],"ltp":0.0,"tv":0.0,"id":13015339}]}]}
{"op":"mcm","clk":"1007383172","pt":1580612307428,"mc":[{"id":"1.168223928","rc":[{"batb":[[1,1.02,2],[2,1.01,1.01]],"ltp":0.0,"tv":0.0,"id":13015339}]}]}
{"op":"mcm","clk":"1007387450","pt":1580612429158,"mc":[{"id":"1.168223928","rc":[{"batb":[[0,2.12,30.29],[1,1.85,139.17],[2,1.02,2]],"ltp":0.0,"tv":0.0,"id":13015339}]}]}
{"op":"mcm","clk":"1007387461","pt":1580612429473,"mc":[{"id":"1.168223928","rc":[{"batb":[[0,2.26,113.71],[1,2.12,30.29]],"ltp":0.0,"tv":0.0,"id":13015339}]}]}
{"op":"mcm","clk":"1007391559","pt":1580612551253,"mc":[{"id":"1.168223928","rc":[{"batb":[[0,2.28,30.29],[1,1.02,2],[2,1.01,1.01]],"ltp":0.0,"tv":0.0,"id":13015339}]}]}
{"op":"mcm","clk":"1007391564","pt":1580612551354,"mc":[{"id":"1.168223928","rc":[{"batb":[[0,2.32,110.64],[1,2.28,30.29],[2,1.02,2]],"ltp":0.0,"tv":0.0,"id":13015339}]}]}
{"op":"mcm","clk":"1007394405","pt":1580612672228,"mc":[{"id":"1.168223928","rc":[{"batb":[[0,2.34,30.29],[1,2.32,110.64]],"ltp":0.0,"tv":0.0,"id":13015339}]}]}
{"op":"mcm","clk":"1007394413","pt":1580612672491,"mc":[{"id":"1.168223928","rc":[{"batb":[[0,2.36,108.93],[1,2.34,30.29]],"ltp":0.0,"tv":0.0,"id":13015339}]}]}
{"op":"mcm","clk":"1007397605","pt":1580612794070,"mc":[{"id":"1.168223928","rc":[{"batb":[[0,2.38,30.29],[1,2.36,108.93]],"ltp":0.0,"tv":0.0,"id":13015339}]}]}
{"op":"mcm","clk":"1007397612","pt":1580612794380,"mc":[{"id":"1.168223928","rc":[{"batb":[[0,2.4,106.91],[1,2.38,30.29]],"ltp":0.0,"tv":0.0,"id":13015339}]}]}
{"op":"mcm","clk":"1007400558","pt":1580612915887,"mc":[{"id":"1.168223928","rc":[{"batb":[[0,2.42,136.42],[1,1.02,2],[2,1.01,1.01]],"ltp":0.0,"tv":0.0,"id":13015339}]}]}
{"op":"mcm","clk":"1007402543","pt":1580612998221,"mc":[{"id":"1.168223928","rc":[{"batb":[[0,1.02,2],[1,1.01,1.01],[2,1.01,0]],"batl":[[0,8.8,297.87]],"ltp":0.0,"tv":0.0,"id":13015338}]}]}
{"op":"mcm","clk":"1007402564","pt":1580612998845,"mc":[{"id":"1.168223928","rc":[{"batb":[[0,2.62,98.04],[1,1.02,2],[2,1.01,1.01]],"ltp":0.0,"tv":0.0,"id":13015338},{"batb":[[0,3.35,76.47]],"ltp":0.0,"tv":0.0,"id":13014430}]}]}
{"op":"mcm","clk":"1007403505","pt":1580613037083,"mc":[{"id":"1.168223928","rc":[{"batb":[[0,2.42,106.13]],"ltp":0.0,"tv":0.0,"id":13015339}]}]}
{"op":"mcm","clk":"1007403522","pt":1580613037700,"mc":[{"id":"1.168223928","rc":[{"batb":[[0,4,30.29]],"ltp":0.0,"tv":0.0,"id":13014431}]}]}
{"op":"mcm","clk":"1007407328","pt":1580613160183,"mc":[{"id":"1.168223928","rc":[{"batb":[[0,3.35,30.29],[1,2.82,91.03],[2,1.02,2]],"ltp":0.0,"tv":0.0,"id":13014431}]}]}
{"op":"mcm","clk":"1007407337","pt":1580613160491,"mc":[{"id":"1.168223928","rc":[{"batb":[[0,3.6,70.99],[1,3.35,30.29]],"ltp":0.0,"tv":0.0,"id":13014431}]}]}
{"op":"mcm","clk":"1007411745","pt":1580613282015,"mc":[{"id":"1.168223928","rc":[{"batb":[[0,3.8,67.23],[1,3.65,30.29]],"ltp":0.0,"tv":0.0,"id":13014431}]}]}
{"op":"mcm","clk":"1007415530","pt":1580613403206,"mc":[{"id":"1.168223928","rc":[{"batb":[[1,1.02,2],[2,1.01,1.01]],"ltp":0.0,"tv":0.0,"id":13014431}]}]}
{"op":"mcm","clk":"1007415545","pt":1580613403722,"mc":[{"id":"1.168223928","rc":[{"batb":[[0,3.9,65.56],[1,3.85,30.29],[2,1.02,2]],"ltp":0.0,"tv":0.0,"id":13014431}]}]}
{"op":"mcm","clk":"1007418068","pt":1580613473138,"mc":[{"id":"1.168223928","rc":[{"batl":[[0,14,184.68]],"ltp":0.0,"tv":0.0,"id":13014431}]}]}
{"op":"mcm","clk":"1007419782","pt":1580613525192,"mc":[{"id":"1.168223928","rc":[{"batb":[[0,3.95,30.29],[1,1.02,2],[2,1.01,1.01]],"ltp":0.0,"tv":0.0,"id":13014431}]}]}
{"op":"mcm","clk":"1007419788","pt":1580613525295,"mc":[{"id":"1.168223928","rc":[{"batb":[[0,3.95,95]],"ltp":0.0,"tv":0.0,"id":13014431}]}]}
{"op":"mcm","clk":"1007423456","pt":1580613646781,"mc":[{"id":"1.168223928","rc":[{"batb":[[0,4,30.29]],"ltp":0.0,"tv":0.0,"id":13014431}]}]}
{"op":"mcm","clk":"1007427934","pt":1580613768270,"mc":[{"id":"1.168223928","rc":[{"batb":[[0,3.35,30.29]],"ltp":0.0,"tv":0.0,"id":13014431}]}]}
{"op":"mcm","clk":"1007427940","pt":1580613768471,"mc":[{"id":"1.168223928","rc":[{"batb":[[0,3.45,74.21],[1,3.35,30.29],[2,1.02,2]],"ltp":0.0,"tv":0.0,"id":13014431}]}]}
{"op":"mcm","clk":"1007431937","pt":1580613890022,"mc":[{"id":"1.168223928","rc":[{"batb":[[0,3.5,30.29],[1,3.45,74.21]],"ltp":0.0,"tv":0.0,"id":13014431}]}]}
{"op":"mcm","clk":"1007431954","pt":1580613890536,"mc":[{"id":"1.168223928","rc":[{"batb":[[0,3.65,70.13],[1,3.5,30.29]],"ltp":0.0,"tv":0.0,"id":13014431}]}]}
{"op":"mcm","clk":"1007436565","pt":1580614012271,"mc":[{"id":"1.168223928","rc":[{"batb":[[0,3.7,30.29],[1,3.65,70.13]],"ltp":0.0,"tv":0.0,"id":13014431}]}]}
{"op":"mcm","clk":"1007436576","pt":1580614012580,"mc":[{"id":"1.168223928","rc":[{"batb":[[0,3.85,66.37],[1,3.7,30.29]],"ltp":0.0,"tv":0.0,"id":13014431}]}]}
{"op":"mcm","clk":"1007440226","pt":1580614133221,"mc":[{"id":"1.168223928","rc":[{"batb":[[1,1.02,2],[2,1.01,1.01]],"ltp":0.0,"tv":0.0,"id":13014431}]}]}
{"op":"mcm","clk":"1007440249","pt":1580614133739,"mc":[{"id":"1.168223928","rc":[{"batb":[[0,3.95,64.71],[1,3.9,30.29],[2,1.02,2]],"ltp":0.0,"tv":0.0,"id":13014431}]}]}
{"op":"mcm","clk":"1007443997","pt":1580614255176,"mc":[{"id":"1.168223928","rc":[{"batb":[[0,4,30.29],[1,1.02,2],[2,1.01,1.01]],"ltp":0.0,"tv":0.0,"id":13014431}]}]}
{"op":"mcm","clk":"1007447980","pt":1580614377138,"mc":[{"id":"1.168223928","rc":[{"batb":[[0,3.5,73.28],[1,3.35,30.29],[2,1.02,2]],"ltp":0.0,"tv":0.0,"id":13014431}]}]}
{"op":"mcm","clk":"1007451628","pt":1580614498687,"mc":[{"id":"1.168223928","rc":[{"batb":[[0,3.75,68.11],[1,3.55,30.29]],"ltp":0.0,"tv":0.0,"id":13014431}]}]}
{"op":"mcm","clk":"1007454562","pt":1580614620268,"mc":[{"id":"1.168223928","rc":[{"batb":[[0,3.8,30.29],[1,1.02,2],[2,1.01,1.01]],"ltp":0.0,"tv":0.0,"id":13014431}]}]}
{"op":"mcm","clk":"1007454567","pt":1580614620368,"mc":[{"id":"1.168223928","rc":[{"batb":[[0,3.85,66.37],[1,3.8,30.29],[2,1.02,2]],"ltp":0.0,"tv":0.0,"id":13014431}]}]}
{"op":"mcm","clk":"1007457152","pt":1580614741993,"mc":[{"id":"1.168223928","rc":[{"batb":[[0,3.95,64.71],[1,3.9,30.29]],"ltp":0.0,"tv":0.0,"id":13014431}]}]}
{"op":"mcm","clk":"1007459873","pt":1580614863708,"mc":[{"id":"1.168223928","rc":[{"batb":[[0,4,30.29],[1,1.02,2],[2,1.01,1.01]],"ltp":0.0,"tv":0.0,"id":13014431}]}]}
{"op":"mcm","clk":"1007462901","pt":1580614985213,"mc":[{"id":"1.168223928","rc":[{"batb":[[0,3.35,30.29],[1,2.88,88.96],[2,1.02,2]],"ltp":0.0,"tv":0.0,"id":13014431}]}]}
{"op":"mcm","clk":"1007462908","pt":1580614985524,"mc":[{"id":"1.168223928","rc":[{"batb":[[0,3.45,74.21],[1,3.35,30.29]],"ltp":0.0,"tv":0.0,"id":13014431}]}]}
{"op":"mcm","clk":"1007466353","pt":1580615106994,"mc":[{"id":"1.168223928","rc":[{"batb":[[0,3.6,70.99],[1,3.5,30.29]],"ltp":0.0,"tv":0.0,"id":13014431}]}]}
{"op":"mcm","clk":"1007469598","pt":1580615228690,"mc":[{"id":"1.168223928","rc":[{"batb":[[0,3.7,69.12],[1,3.65,30.29]],"ltp":0.0,"tv":0.0,"id":13014431}]}]}
{"op":"mcm","clk":"1007473054","pt":1580615350257,"mc":[{"id":"1.168223928","rc":[{"batb":[[0,3.75,30.29],[1,1.02,2],[2,1.01,1.01]],"ltp":0.0,"tv":0.0,"id":13014431}]}]}
{"op":"mcm","clk":"1007473060","pt":1580615350359,"mc":[{"id":"1.168223928","rc":[{"batb":[[0,3.8,67.23],[1,3.75,30.29],[2,1.02,2]],"ltp":0.0,"tv":0.0,"id":13014431}]}]}
{"op":"mcm","clk":"1007477826","pt":1580615472106,"mc":[{"id":"1.168223928","rc":[{"batb":[[0,3.9,65.56],[1,3.85,30.29]],"ltp":0.0,"tv":0.0,"id":13014431}]}]}
{"op":"mcm","clk":"1007482905","pt":1580615593986,"mc":[{"id":"1.168223928","rc":[{"batb":[[0,3.95,95],[1,1.02,2],[2,1.01,1.01]],"ltp":0.0,"tv":0.0,"id":13014431}]}]}
{"op":"mcm","clk":"1007487245","pt":1580615715154,"mc":[{"id":"1.168223928","rc":[{"batb":[[0,4,30.29],[1,3.95,64.71],[2,1.02,2]],"ltp":0.0,"tv":0.0,"id":13014431}]}]}
{"op":"mcm","clk":"1007487257","pt":1580615715355,"mc":[{"id":"1.168223928","rc":[{"batb":[[1,1.02,2],[2,1.01,1.01]],"ltp":0.0,"tv":0.0,"id":13014431}]}]}
{"op":"mcm","clk":"1007491532","pt":1580615837249,"mc":[{"id":"1.168223928","rc":[{"batb":[[0,3.35,30.29]],"ltp":0.0,"tv":0.0,"id":13014431}]}]}
{"op":"mcm","clk":"1007491538","pt":1580615837454,"mc":[{"id":"1.168223928","rc":[{"batb":[[0,3.6,70.99],[1,3.35,30.29],[2,1.02,2]],"ltp":0.0,"tv":0.0,"id":13014431}]}]}
{"op":"mcm","clk":"1007496451","pt":1580615958738,"mc":[{"id":"1.168223928","rc":[{"batb":[[0,3.7,69.12],[1,3.65,30.29]],"ltp":0.0,"tv":0.0,"id":13014431}]}]}
{"op":"mcm","clk":"1007499969","pt":1580616030150,"mc":[{"id":"1.168223928","rc":[{"batb":[[0,1.02,2],[1,1.01,1.01],[2,1.01,0]],"ltp":0.0,"tv":0.0,"id":13015339}]}]}
{"op":"mcm","clk":"1007500135","pt":1580616031911,"mc":[{"id":"1.168223928","rc":[{"batb":[[0,2.02,127.5],[1,1.02,2],[2,1.01,1.01]],"ltp":0.0,"tv":0.0,"id":13015339}]}]}
{"op":"mcm","clk":"1007502573","pt":1580616080213,"mc":[{"id":"1.168223928","rc":[{"batb":[[0,2.08,30.29]],"ltp":0.0,"tv":0.0,"id":13015339}]}]}
{"op":"mcm","clk":"1007502604","pt":1580616080782,"mc":[{"id":"1.168223928","rc":[{"batb":[[0,2.22,115.84],[1,2.08,30.29],[2,1.02,2]],"ltp":0.0,"tv":0.0,"id":13015339},{"batb":[[0,3.9,65.56],[1,3.75,30.29]],"ltp":0.0,"tv":0.0,"id":13014431}]}]}
{"op":"mcm","clk":"1007507676","pt":1580616202100,"mc":[{"id":"1.168223928","rc":[{"batb":[[0,2.28,112.66],[1,2.24,30.29]],"ltp":0.0,"tv":0.0,"id":13015339}]}]}
{"op":"mcm","clk":"1007507714","pt":1580616202976,"mc":[{"id":"1.168223928","rc":[{"batb":[[0,3.95,95],[1,1.02,2],[2,1.01,1.01]],"ltp":0.0,"tv":0.0,"id":13014431}]}]}
{"op":"mcm","clk":"1007512232","pt":1580616324089,"mc":[{"id":"1.168223928","rc":[{"batb":[[0,2.3,30.29],[1,2.28,112.66]],"ltp":0.0,"tv":0.0,"id":13015339}]}]}
{"op":"mcm","clk":"1007512271","pt":1580616324809,"mc":[{"id":"1.168223928","rc":[{"batb":[[0,2.38,107.96],[1,2.3,30.29]],"ltp":0.0,"tv":0.0,"id":13015339},{"batb":[[0,4,30.29]],"ltp":0.0,"tv":0.0,"id":13014431}]}]}
{"op":"mcm","clk":"1007516974","pt":1580616445029,"mc":[{"id":"1.168223928","rc":[{"batb":[[1,1.02,2],[2,1.01,1.01]],"ltp":0.0,"tv":0.0,"id":13015339}]}]}
{"op":"mcm","clk":"1007517007","pt":1580616446162,"mc":[{"id":"1.168223928","rc":[{"batb":[[0,3.5,73.28],[1,3.35,30.29],[2,1.02,2]],"ltp":0.0,"tv":0.0,"id":13014431}]}]}
{"op":"mcm","clk":"1007520235","pt":1580616567212,"mc":[{"id":"1.168223928","rc":[{"batb":[[0,3.55,30.29],[1,1.02,2],[2,1.01,1.01]],"ltp":0.0,"tv":0.0,"id":13014431}]}]}
{"op":"mcm","clk":"1007520239","pt":1580616567317,"mc":[{"id":"1.168223928","rc":[{"batb":[[0,3.65,70.13],[1,3.55,30.29],[2,1.02,2]],"ltp":0.0,"tv":0.0,"id":13014431}]}]}
{"op":"mcm","clk":"1007521065","pt":1580616598830,"mc":[{"id":"1.168223928","rc":[{"batb":[[0,2.82,91.03]],"batl":[[0,7.6,344.81]],"ltp":0.0,"tv":0.0,"id":13015338},{"batb":[[0,1.02,2],[1,1.01,1.01],[2,1.01,0]],"batl":[[0,23,107.82]],"ltp":0.0,"tv":0.0,"id":13014430}]}]}
{"op":"mcm","clk":"1007523480","pt":1580616688758,"mc":[{"id":"1.168223928","rc":[{"batb":[[0,3.8,67.23],[1,3.7,30.29]],"ltp":0.0,"tv":0.0,"id":13014431}]}]}
{"op":"mcm","clk":"1007527558","pt":1580616810135,"mc":[{"id":"1.168223928","rc":[{"batb":[[0,3.85,30.29],[1,3.8,67.23]],"ltp":0.0,"tv":0.0,"id":13014431}]}]}
{"op":"mcm","clk":"1007527571","pt":1580616810536,"mc":[{"id":"1.168223928","rc":[{"batb":[[0,3.9,65.56],[1,3.85,30.29]],"ltp":0.0,"tv":0.0,"id":13014431}]}]}
{"op":"mcm","clk":"1007532125","pt":1580616932205,"mc":[{"id":"1.168223928","rc":[{"batb":[[0,3.95,30.29],[1,1.02,2],[2,1.01,1.01]],"ltp":0.0,"tv":0.0,"id":13014431}]}]}
{"op":"mcm","clk":"1007532130","pt":1580616932310,"mc":[{"id":"1.168223928","rc":[{"batb":[[0,3.95,95]],"ltp":0.0,"tv":0.0,"id":13014431}]}]}
{"op":"mcm","clk":"1007535357","pt":1580617053681,"mc":[{"id":"1.168223928","rc":[{"batb":[[0,4,30.29]],"ltp":0.0,"tv":0.0,"id":13014431}]}]}
{"op":"mcm","clk":"1007535816","pt":1580617073471,"mc":[{"id":"1.168223928","rc":[{"batl":[[0,11.5,224.51]],"ltp":0.0,"tv":0.0,"id":13014431}]}]}
{"op":"mcm","clk":"1007538750","pt":1580617175249,"mc":[{"id":"1.168223928","rc":[{"batb":[[0,3.35,30.29]],"ltp":0.0,"tv":0.0,"id":13014431}]}]}
{"op":"mcm","clk":"1007538778","pt":1580617175710,"mc":[{"id":"1.168223928","rc":[{"batb":[[0,3.55,71.99],[1,3.35,30.29],[2,1.02,2]],"ltp":0.0,"tv":0.0,"id":13014431}]}]}
{"op":"mcm","clk":"1007543219","pt":1580617297225,"mc":[{"id":"1.168223928","rc":[{"batb":[[0,3.75,68.11],[1,3.6,30.29]],"ltp":0.0,"tv":0.0,"id":13014431}]}]}
{"op":"mcm","clk":"1007546570","pt":1580617418821,"mc":[{"id":"1.168223928","rc":[{"batb":[[0,3.9,65.56],[1,3.8,30.29]],"ltp":0.0,"tv":0.0,"id":13014431}]}]}
{"op":"mcm","clk":"1007550390","pt":1580617540259,"mc":[{"id":"1.168223928","rc":[{"batb":[[0,3.95,30.29],[1,3.9,65.56]],"ltp":0.0,"tv":0.0,"id":13014431}]}]}
{"op":"mcm","clk":"1007550404","pt":1580617540574,"mc":[{"id":"1.168223928","rc":[{"batb":[[0,3.95,95],[1,1.02,2],[2,1.01,1.01]],"ltp":0.0,"tv":0.0,"id":13014431}]}]}
{"op":"mcm","clk":"1007556130","pt":1580617662174,"mc":[{"id":"1.168223928","rc":[{"batb":[[0,4,30.29]],"ltp":0.0,"tv":0.0,"id":13014431}]}]}
{"op":"mcm","clk":"1007560718","pt":1580617783634,"mc":[{"id":"1.168223928","rc":[{"batb":[[0,3.7,69.12],[1,3.35,30.29],[2,1.02,2]],"ltp":0.0,"tv":0.0,"id":13014431}]}]}
{"op":"mcm","clk":"1007566323","pt":1580617905747,"mc":[{"id":"1.168223928","rc":[{"batb":[[0,3.8,67.23],[1,3.75,30.29]],"ltp":0.0,"tv":0.0,"id":13014431}]}]}
{"op":"mcm","clk":"1007572064","pt":1580618027170,"mc":[{"id":"1.168223928","rc":[{"batb":[[0,3.85,30.29],[1,1.02,2],[2,1.01,1.01]],"ltp":0.0,"tv":0.0,"id":13014431}]}]}
{"op":"mcm","clk":"1007572070","pt":1580618027274,"mc":[{"id":"1.168223928","rc":[{"batb":[[0,3.9,65.56],[1,3.85,30.29],[2,1.02,2]],"ltp":0.0,"tv":0.0,"id":13014431}]}]}
{"op":"mcm","clk":"1007578381","pt":1580618148944,"mc":[{"id":"1.168223928","rc":[{"batb":[[0,3.95,95],[1,1.02,2],[2,1.01,1.01]],"ltp":0.0,"tv":0.0,"id":13014431}]}]}
{"op":"mcm","clk":"1007583909","pt":1580618270196,"mc":[{"id":"1.168223928","rc":[{"batb":[[0,4,30.29],[1,3.95,64.71],[2,1.02,2]],"ltp":0.0,"tv":0.0,"id":13014431}]}]}
{"op":"mcm","clk":"1007583921","pt":1580618270404,"mc":[{"id":"1.168223928","rc":[{"batb":[[1,1.02,2],[2,1.01,1.01]],"ltp":0.0,"tv":0.0,"id":13014431}]}]}
{"op":"mcm","clk":"1007589576","pt":1580618392131,"mc":[{"id":"1.168223928","rc":[{"batb":[[0,3.75,68.11],[1,3.35,30.29],[2,1.02,2]],"ltp":0.0,"tv":0.0,"id":13014431}]}]}
{"op":"mcm","clk":"1007594358","pt":1580618513916,"mc":[{"id":"1.168223928","rc":[{"batb":[[0,3.9,65.56],[1,3.8,30.29]],"ltp":0.0,"tv":0.0,"id":13014431}]}]}
{"op":"mcm","clk":"1007598783","pt":1580618636216,"mc":[{"id":"1.168223928","rc":[{"batb":[[0,3.95,95],[1,1.02,2],[2,1.01,1.01]],"ltp":0.0,"tv":0.0,"id":13014431}]}]}
{"op":"mcm","clk":"1007602712","pt":1580618757084,"mc":[{"id":"1.168223928","rc":[{"batb":[[0,4,30.29]],"ltp":0.0,"tv":0.0,"id":13014431}]}]}
{"op":"mcm","clk":"1007606983","pt":1580618879035,"mc":[{"id":"1.168223928","rc":[{"batb":[[0,3.55,71.99],[1,3.35,30.29],[2,1.02,2]],"ltp":0.0,"tv":0.0,"id":13014431}]}]}
{"op":"mcm","clk":"1007610468","pt":1580619000176,"mc":[{"id":"1.168223928","rc":[{"batb":[[1,1.02,2],[2,1.01,1.01]],"ltp":0.0,"tv":0.0,"id":13014431}]}]}
{"op":"mcm","clk":"1007610494","pt":1580619000689,"mc":[{"id":"1.168223928","rc":[{"batb":[[0,3.7,69.12],[1,3.6,30.29],[2,1.02,2]],"ltp":0.0,"tv":0.0,"id":13014431}]}]}
{"op":"mcm","clk":"1007614423","pt":1580619122171,"mc":[{"id":"1.168223928","rc":[{"batb":[[0,3.8,67.23],[1,3.75,30.29]],"ltp":0.0,"tv":0.0,"id":13014431}]}]}
{"op":"mcm","clk":"1007618553","pt":1580619243939,"mc":[{"id":"1.168223928","rc":[{"batb":[[0,3.9,65.56],[1,3.85,30.29]],"ltp":0.0,"tv":0.0,"id":13014431}]}]}
{"op":"mcm","clk":"1007622511","pt":1580619365233,"mc":[{"id":"1.168223928","rc":[{"batb":[[1,1.02,2],[2,1.01,1.01]],"ltp":0.0,"tv":0.0,"id":13014431}]}]}
{"op":"mcm","clk":"1007622525","pt":1580619365593,"mc":[{"id":"1.168223928","rc":[{"batb":[[0,3.95,95]],"ltp":0.0,"tv":0.0,"id":13014431}]}]}
{"op":"mcm","clk":"1007627016","pt":1580619487163,"mc":[{"id":"1.168223928","rc":[{"batb":[[0,4,30.29]],"ltp":0.0,"tv":0.0,"id":13014431}]}]}
{"op":"mcm","clk":"1007631573","pt":1580619609047,"mc":[{"id":"1.168223928","rc":[{"batb":[[0,3.8,67.23],[1,3.35,30.29],[2,1.02,2]],"ltp":0.0,"tv":0.0,"id":13014431}]}]}
{"op":"mcm","clk":"1007632637","pt":1580619632653,"mc":[{"id":"1.168223928","rc":[{"batb":[[0,1.91,134.84]],"ltp":0.0,"tv":0.0,"id":13015339}]}]}
{"op":"mcm","clk":"1007637080","pt":1580619730181,"mc":[{"id":"1.168223928","rc":[{"batb":[[0,2.1,30.29],[1,1.91,134.84],[2,1.02,2]],"ltp":0.0,"tv":0.0,"id":13015339}]}]}
{"op":"mcm","clk":"1007637128","pt":1580619731103,"mc":[{"id":"1.168223928","rc":[{"batb":[[0,2.32,110.64],[1,2.1,30.29]],"ltp":0.0,"tv":0.0,"id":13015339},{"batb":[[0,3.9,65.56],[1,3.85,30.29]],"ltp":0.0,"tv":0.0,"id":13014431}]}]}
{"op":"mcm","clk":"1007642591","pt":1580619852229,"mc":[{"id":"1.168223928","rc":[{"batb":[[0,2.38,107.96],[1,2.34,30.29]],"ltp":0.0,"tv":0.0,"id":13015339}]}]}
{"op":"mcm","clk":"1007642630","pt":1580619853049,"mc":[{"id":"1.168223928","rc":[{"batb":[[0,3.95,95],[1,1.02,2],[2,1.01,1.01]],"ltp":0.0,"tv":0.0,"id":13014431}]}]}
{"op":"mcm","clk":"1007646129","pt":1580619932872,"mc":[{"id":"1.168223928","rc":[{"batb":[[0,3.3,77.58],[1,1.02,2],[2,1.01,1.01]],"ltp":0.0,"tv":0.0,"id":13014430}]}]}
{"op":"mcm","clk":"1007648157","pt":1580619974246,"mc":[{"id":"1.168223928","rc":[{"batb":[[1,1.02,2],[2,1.01,1.01]],"ltp":0.0,"tv":0.0,"id":13015339},{"batb":[[0,4,30.29],[1,3.95,64.71],[2,1.02,2]],"ltp":0.0,"tv":0.0,"id":13014431}]}]}
{"op":"mcm","clk":"1007648166","pt":1580619974403,"mc":[{"id":"1.168223928","rc":[{"batb":[[1,1.02,2],[2,1.01,1.01]],"ltp":0.0,"tv":0.0,"id":13014431}]}]}
{"op":"mcm","clk":"1007655163","pt":1580620095884,"mc":[{"id":"1.168223928","rc":[{"batb":[[0,3.45,74.21],[1,3.35,30.29],[2,1.02,2]],"ltp":0.0,"tv":0.0,"id":13014431}]}]}
{"op":"mcm","clk":"1007660276","pt":1580620198941,"mc":[{"id":"1.168223928","rc":[{"batb":[[0,1.02,2],[1,1.01,1.01],[2,1.01,0]],"ltp":0.0,"tv":0.0,"id":13015338}]}]}
{"op":"mcm","clk":"1007661245","pt":1580620217197,"mc":[{"id":"1.168223928","rc":[{"batb":[[0,3.5,30.29],[1,3.45,74.21]],"ltp":0.0,"tv":0.0,"id":13014431}]}]}
{"op":"mcm","clk":"1007661270","pt":1580620217666,"mc":[{"id":"1.168223928","rc":[{"batb":[[0,3.8,67.23],[1,3.5,30.29]],"ltp":0.0,"tv":0.0,"id":13014431}]}]}
{"op":"mcm","clk":"1007666712","pt":1580620310347,"mc":[{"id":"1.168223928","rc":[{"batl":[[0,4.1,232.55]],"ltp":0.0,"tv":0.0,"id":13015339}]}]}
{"op":"mcm","clk":"1007668239","pt":1580620338962,"mc":[{"id":"1.168223928","rc":[{"batb":[[0,3.9,65.56],[1,3.85,30.29]],"ltp":0.0,"tv":0.0,"id":13014431}]}]}
{"op":"mcm","clk":"1007674416","pt":1580620460766,"mc":[{"id":"1.168223928","rc":[{"batb":[[0,3.95,95],[1,1.02,2],[2,1.01,1.01]],"ltp":0.0,"tv":0.0,"id":13014431}]}]}
{"op":"mcm","clk":"1007680524","pt":1580620582254,"mc":[{"id":"1.168223928","rc":[{"batb":[[0,4,30.29]],"ltp":0.0,"tv":0.0,"id":13014431}]}]}
{"op":"mcm","clk":"1007686361","pt":1580620704143,"mc":[{"id":"1.168223928","rc":[{"batb":[[0,3.45,74.21],[1,3.35,30.29],[2,1.02,2]],"batl":[[0,13,198.87]],"ltp":0.0,"tv":0.0,"id":13014431}]}]}
{"op":"mcm","clk":"1007692476","pt":1580620825776,"mc":[{"id":"1.168223928","rc":[{"batb":[[0,3.55,71.99],[1,3.5,30.29]],"ltp":0.0,"tv":0.0,"id":13014431}]}]}
{"op":"mcm","clk":"1007697673","pt":1580620948088,"mc":[{"id":"1.168223928","rc":[{"batb":[[0,3.75,68.11],[1,3.6,30.29]],"ltp":0.0,"tv":0.0,"id":13014431}]}]}
{"op":"mcm","clk":"1007702381","pt":1580621069036,"mc":[{"id":"1.168223928","rc":[{"batb":[[0,3.85,66.37],[1,3.8,30.29]],"ltp":0.0,"tv":0.0,"id":13014431}]}]}
{"op":"mcm","clk":"1007706604","pt":1580621190693,"mc":[{"id":"1.168223928","rc":[{"batb":[[0,3.95,64.71],[1,3.9,30.29]],"ltp":0.0,"tv":0.0,"id":13014431}]}]}
{"op":"mcm","clk":"1007710631","pt":1580621312200,"mc":[{"id":"1.168223928","rc":[{"batb":[[0,4,30.29],[1,3.95,64.71]],"ltp":0.0,"tv":0.0,"id":13014431}]}]}
{"op":"mcm","clk":"1007710639","pt":1580621312463,"mc":[{"id":"1.168223928","rc":[{"batb":[[1,1.02,2],[2,1.01,1.01]],"ltp":0.0,"tv":0.0,"id":13014431}]}]}
{"op":"mcm","clk":"1007715890","pt":1580621434142,"mc":[{"id":"1.168223928","rc":[{"batb":[[0,3.4,75.21],[1,3.35,30.29],[2,1.02,2]],"ltp":0.0,"tv":0.0,"id":13014431}]}]}
{"op":"mcm","clk":"1007721598","pt":1580621555660,"mc":[{"id":"1.168223928","rc":[{"batb":[[0,3.55,71.99],[1,3.45,30.29]],"ltp":0.0,"tv":0.0,"id":13014431}]}]}
{"op":"mcm","clk":"1007727905","pt":1580621677247,"mc":[{"id":"1.168223928","rc":[{"batb":[[0,3.6,30.29],[1,1.02,2],[2,1.01,1.01]],"ltp":0.0,"tv":0.0,"id":13014431}]}]}
{"op":"mcm","clk":"1007727912","pt":1580621677347,"mc":[{"id":"1.168223928","rc":[{"batb":[[0,3.7,69.12],[1,3.6,30.29],[2,1.02,2]],"ltp":0.0,"tv":0.0,"id":13014431}]}]}
{"op":"mcm","clk":"1007734235","pt":1580621798994,"mc":[{"id":"1.168223928","rc":[{"batb":[[0,3.8,67.23],[1,3.75,30.29]],"ltp":0.0,"tv":0.0,"id":13014431}]}]}
{"op":"mcm","clk":"1007740607","pt":1580621920799,"mc":[{"id":"1.168223928","rc":[{"batb":[[0,3.9,65.56],[1,3.85,30.29]],"ltp":0.0,"tv":0.0,"id":13014431}]}]}
{"op":"mcm","clk":"1007746307","pt":1580622042182,"mc":[{"id":"1.168223928","rc":[{"batb":[[0,3.95,30.29],[1,3.9,65.56]],"ltp":0.0,"tv":0.0,"id":13014431}]}]}
{"op":"mcm","clk":"1007746319","pt":1580622042500,"mc":[{"id":"1.168223928","rc":[{"batb":[[0,3.95,95],[1,1.02,2],[2,1.01,1.01]],"ltp":0.0,"tv":0.0,"id":13014431}]}]}
{"op":"mcm","clk":"1007752243","pt":1580622164110,"mc":[{"id":"1.168223928","rc":[{"batb":[[0,4,30.29]],"ltp":0.0,"tv":0.0,"id":13014431}]}]}
{"op":"mcm","clk":"1007758264","pt":1580622285973,"mc":[{"id":"1.168223928","rc":[{"batb":[[0,3.7,69.12],[1,3.4,30.29],[2,1.02,2]],"ltp":0.0,"tv":0.0,"id":13014431}]}]}
{"op":"mcm","clk":"1007764608","pt":1580622407115,"mc":[{"id":"1.168223928","rc":[{"batb":[[0,3.75,30.29],[1,3.7,69.12]],"ltp":0.0,"tv":0.0,"id":13014431}]}]}
{"op":"mcm","clk":"1007764626","pt":1580622407530,"mc":[{"id":"1.168223928","rc":[{"batb":[[0,3.8,67.23],[1,3.75,30.29]],"ltp":0.0,"tv":0.0,"id":13014431}]}]}
{"op":"mcm","clk":"1007770993","pt":1580622529217,"mc":[{"id":"1.168223928","rc":[{"batb":[[0,3.85,30.29],[1,1.02,2],[2,1.01,1.01]],"ltp":0.0,"tv":0.0,"id":13014431}]}]}
{"op":"mcm","clk":"1007770999","pt":1580622529320,"mc":[{"id":"1.168223928","rc":[{"batb":[[0,3.9,65.56],[1,3.85,30.29],[2,1.02,2]],"ltp":0.0,"tv":0.0,"id":13014431}]}]}
{"op":"mcm","clk":"1007777127","pt":1580622651000,"mc":[{"id":"1.168223928","rc":[{"batb":[[0,3.95,95],[1,1.02,2],[2,1.01,1.01]],"ltp":0.0,"tv":0.0,"id":13014431}]}]}
{"op":"mcm","clk":"1007782923","pt":1580622773229,"mc":[{"id":"1.168223928","rc":[{"batb":[[0,4,30.29],[1,3.95,64.71],[2,1.02,2]],"ltp":0.0,"tv":0.0,"id":13014431}]}]}
{"op":"mcm","clk":"1007782927","pt":1580622773331,"mc":[{"id":"1.168223928","rc":[{"batb":[[1,1.02,2],[2,1.01,1.01]],"ltp":0.0,"tv":0.0,"id":13014431}]}]}
{"op":"mcm","clk":"1007788587","pt":1580622895183,"mc":[{"id":"1.168223928","rc":[{"batb":[[0,3.4,30.29]],"ltp":0.0,"tv":0.0,"id":13014431}]}]}
{"op":"mcm","clk":"1007788592","pt":1580622895287,"mc":[{"id":"1.168223928","rc":[{"batb":[[0,3.6,70.99],[1,3.4,30.29],[2,1.02,2]],"ltp":0.0,"tv":0.0,"id":13014431}]}]}
{"op":"mcm","clk":"1007793346","pt":1580623016818,"mc":[{"id":"1.168223928","rc":[{"batb":[[0,3.7,69.12],[1,3.65,30.29]],"ltp":0.0,"tv":0.0,"id":13014431}]}]}
{"op":"mcm","clk":"1007797330","pt":1580623138194,"mc":[{"id":"1.168223928","rc":[{"batb":[[0,3.75,30.29],[1,3.7,69.12]],"ltp":0.0,"tv":0.0,"id":13014431}]}]}
{"op":"mcm","clk":"1007797338","pt":1580623138503,"mc":[{"id":"1.168223928","rc":[{"batb":[[0,3.85,66.37],[1,3.75,30.29]],"ltp":0.0,"tv":0.0,"id":13014431}]}]}
{"op":"mcm","clk":"1007801040","pt":1580623232934,"mc":[{"id":"1.168223928","rc":[{"batb":[[0,1.87,137.81]],"ltp":0.0,"tv":0.0,"id":13015339}]}]}
{"op":"mcm","clk":"1007802049","pt":1580623260259,"mc":[{"id":"1.168223928","rc":[{"batb":[[0,2.3,111.68],[1,2.06,30.29],[2,1.02,2]],"ltp":0.0,"tv":0.0,"id":13015339},{"batb":[[1,1.02,2],[2,1.01,1.01]],"ltp":0.0,"tv":0.0,"id":13014431}]}]}
{"op":"mcm","clk":"1007802063","pt":1580623260669,"mc":[{"id":"1.168223928","rc":[{"batb":[[0,3.95,64.71],[1,3.9,30.29],[2,1.02,2]],"ltp":0.0,"tv":0.0,"id":13014431}]}]}
{"op":"mcm","clk":"1007807165","pt":1580623382260,"mc":[{"id":"1.168223928","rc":[{"batb":[[0,2.38,107.96],[1,2.32,30.29]],"ltp":0.0,"tv":0.0,"id":13015339},{"batb":[[1,1.02,2],[2,1.01,1.01]],"ltp":0.0,"tv":0.0,"id":13014431}]}]}
{"op":"mcm","clk":"1007807179","pt":1580623382572,"mc":[{"id":"1.168223928","rc":[{"batb":[[0,4,30.29]],"ltp":0.0,"tv":0.0,"id":13014431}]}]}
{"op":"mcm","clk":"1007812222","pt":1580623503154,"mc":[{"id":"1.168223928","rc":[{"batb":[[1,1.02,2],[2,1.01,1.01]],"ltp":0.0,"tv":0.0,"id":13015339}]}]}
{"op":"mcm","clk":"1007812280","pt":1580623504239,"mc":[{"id":"1.168223928","rc":[{"batb":[[0,3.4,30.29]],"ltp":0.0,"tv":0.0,"id":13014431}]}]}
{"op":"mcm","clk":"1007812287","pt":1580623504342,"mc":[{"id":"1.168223928","rc":[{"batb":[[0,3.65,70.13],[1,3.4,30.29],[2,1.02,2]],"ltp":0.0,"tv":0.0,"id":13014431}]}]}
{"op":"mcm","clk":"1007813451","pt":1580623533171,"mc":[{"id":"1.168223928","rc":[{"batb":[[0,3.9,65.56]],"ltp":0.0,"tv":0.0,"id":13014430}]}]}
{"op":"mcm","clk":"1007813456","pt":1580623533273,"mc":[{"id":"1.168223928","rc":[{"batl":[[0,26,95.38]],"ltp":0.0,"tv":0.0,"id":13014430}]}]}
{"op":"mcm","clk":"1007816895","pt":1580623624906,"mc":[{"id":"1.168223928","rc":[{"batb":[[0,3.7,30.29],[1,3.65,70.13]],"ltp":0.0,"tv":0.0,"id":13014431}]}]}
{"op":"mcm","clk":"1007816904","pt":1580623626128,"mc":[{"id":"1.168223928","rc":[{"batb":[[0,3.85,66.37],[1,3.7,30.29]],"ltp":0.0,"tv":0.0,"id":13014431}]}]}
{"op":"mcm","clk":"1007821808","pt":1580623746991,"mc":[{"id":"1.168223928","rc":[{"batb":[[0,3.95,64.71],[1,3.9,30.29]],"ltp":0.0,"tv":0.0,"id":13014431}]}]}
{"op":"mcm","clk":"1007827073","pt":1580623868268,"mc":[{"id":"1.168223928","rc":[{"batb":[[1,1.02,2],[2,1.01,1.01]],"ltp":0.0,"tv":0.0,"id":13014431}]}]}
{"op":"mcm","clk":"1007827084","pt":1580623868530,"mc":[{"id":"1.168223928","rc":[{"batb":[[0,4,30.29]],"ltp":0.0,"tv":0.0,"id":13014431}]}]}
{"op":"mcm","clk":"1007829517","pt":1580623910605,"mc":[{"id":"1.168223928","rc":[{"batl":[[0,4.3,221.85]],"ltp":0.0,"tv":0.0,"id":13015339}]}]}
{"op":"mcm","clk":"1007832934","pt":1580623990231,"mc":[{"id":"1.168223928","rc":[{"batb":[[0,1.02,2],[1,1.01,1.01],[2,1.01,0]],"ltp":0.0,"tv":0.0,"id":13014431}]}]}
{"op":"mcm","clk":"1007832959","pt":1580623990849,"mc":[{"id":"1.168223928","rc":[{"batb":[[0,3.45,74.21],[1,3.4,30.29],[2,1.02,2]],"ltp":0.0,"tv":0.0,"id":13014431}]}]}
{"op":"mcm","clk":"1007837738","pt":1580624112158,"mc":[{"id":"1.168223928","rc":[{"batb":[[0,3.55,71.99],[1,3.5,30.29]],"ltp":0.0,"tv":0.0,"id":13014431}]}]}
{"op":"mcm","clk":"1007842970","pt":1580624233242,"mc":[{"id":"1.168223928","rc":[{"batb":[[1,1.02,2],[2,1.01,1.01]],"ltp":0.0,"tv":0.0,"id":13014431}]}]}
{"op":"mcm","clk":"1007842997","pt":1580624233651,"mc":[{"id":"1.168223928","rc":[{"batb":[[0,3.7,69.12],[1,3.6,30.29],[2,1.02,2]],"ltp":0.0,"tv":0.0,"id":13014431}]}]}
{"op":"mcm","clk":"1007848079","pt":1580624355068,"mc":[{"id":"1.168223928","rc":[{"batb":[[0,3.75,30.29],[1,3.7,69.12]],"ltp":0.0,"tv":0.0,"id":13014431}]}]}
{"op":"mcm","clk":"1007848093","pt":1580624355377,"mc":[{"id":"1.168223928","rc":[{"batb":[[0,3.85,66.37],[1,3.75,30.29]],"ltp":0.0,"tv":0.0,"id":13014431}]}]}
{"op":"mcm","clk":"1007854192","pt":1580624477032,"mc":[{"id":"1.168223928","rc":[{"batb":[[0,3.95,64.71],[1,3.9,30.29]],"ltp":0.0,"tv":0.0,"id":13014431}]}]}
{"op":"mcm","clk":"1007859493","pt":1580624598243,"mc":[{"id":"1.168223928","rc":[{"batb":[[1,1.02,2],[2,1.01,1.01]],"ltp":0.0,"tv":0.0,"id":13014431}]}]}
{"op":"mcm","clk":"1007859507","pt":1580624598556,"mc":[{"id":"1.168223928","rc":[{"batb":[[0,4,30.29]],"ltp":0.0,"tv":0.0,"id":13014431}]}]}
{"op":"mcm","clk":"1007865019","pt":1580624721234,"mc":[{"id":"1.168223928","rc":[{"batb":[[0,3.4,30.29]],"ltp":0.0,"tv":0.0,"id":13014431}]}]}
{"op":"mcm","clk":"1007865027","pt":1580624721338,"mc":[{"id":"1.168223928","rc":[{"batb":[[0,3.5,73.28],[1,3.4,30.29],[2,1.02,2]],"ltp":0.0,"tv":0.0,"id":13014431}]}]}
{"op":"mcm","clk":"1007871253","pt":1580624843152,"mc":[{"id":"1.168223928","rc":[{"batb":[[0,3.65,70.13],[1,3.55,30.29]],"ltp":0.0,"tv":0.0,"id":13014431}]}]}
{"op":"mcm","clk":"1007876879","pt":1580624964241,"mc":[{"id":"1.168223928","rc":[{"batb":[[1,1.02,2],[2,1.01,1.01]],"ltp":0.0,"tv":0.0,"id":13014431}]}]}
{"op":"mcm","clk":"1007876892","pt":1580624964495,"mc":[{"id":"1.168223928","rc":[{"batb":[[0,3.75,68.11],[1,3.7,30.29],[2,1.02,2]],"ltp":0.0,"tv":0.0,"id":13014431}]}]}
{"op":"mcm","clk":"1007882694","pt":1580625086218,"mc":[{"id":"1.168223928","rc":[{"batb":[[0,3.85,66.37],[1,3.8,30.29]],"ltp":0.0,"tv":0.0,"id":13014431}]}]}
{"op":"mcm","clk":"1007887824","pt":1580625208967,"mc":[{"id":"1.168223928","rc":[{"batb":[[0,3.95,64.71],[1,3.9,30.29]],"ltp":0.0,"tv":0.0,"id":13014431}]}]}
{"op":"mcm","clk":"1007891777","pt":1580625302024,"mc":[{"id":"1.168223928","rc":[{"batb":[[2,1.01,2.69]],"ltp":0.0,"tv":0.0,"id":13015339}]}]}
{"op":"mcm","clk":"1007892053","pt":1580625308471,"mc":[{"id":"1.168223928","rc":[{"batb":[[2,1.01,3.59]],"ltp":0.0,"tv":0.0,"id":13015339}]}]}
{"op":"mcm","clk":"1007893035","pt":1580625331224,"mc":[{"id":"1.168223928","rc":[{"batb":[[0,4,30.29],[1,1.02,2],[2,1.01,3.59]],"ltp":0.0,"tv":0.0,"id":13014431}]}]}
{"op":"mcm","clk":"1007897448","pt":1580625452120,"mc":[{"id":"1.168223928","rc":[{"batb":[[0,3.4,30.29]],"ltp":0.0,"tv":0.0,"id":13014431}]}]}
{"op":"mcm","clk":"1007897463","pt":1580625452632,"mc":[{"id":"1.168223928","rc":[{"batb":[[0,3.75,68.11],[1,3.4,30.29],[2,1.02,2]],"ltp":0.0,"tv":0.0,"id":13014431}]}]}
{"op":"mcm","clk":"1007901325","pt":1580625574198,"mc":[{"id":"1.168223928","rc":[{"batb":[[0,3.85,66.37],[1,3.8,30.29]],"ltp":0.0,"tv":0.0,"id":13014431}]}]}
{"op":"mcm","clk":"1007906748","pt":1580625695749,"mc":[{"id":"1.168223928","rc":[{"batb":[[0,3.95,64.71],[1,3.9,30.29]],"ltp":0.0,"tv":0.0,"id":13014431}]}]}
{"op":"mcm","clk":"1007911968","pt":1580625817079,"mc":[{"id":"1.168223928","rc":[{"batb":[[0,4,30.29],[1,3.95,64.71]],"ltp":0.0,"tv":0.0,"id":13014431}]}]}
{"op":"mcm","clk":"1007911976","pt":1580625817279,"mc":[{"id":"1.168223928","rc":[{"batb":[[1,1.02,2],[2,1.01,3.59]],"ltp":0.0,"tv":0.0,"id":13014431}]}]}
{"op":"mcm","clk":"1007916661","pt":1580625938759,"mc":[{"id":"1.168223928","rc":[{"batb":[[0,3.6,70.99],[1,3.4,30.29],[2,1.02,2]],"ltp":0.0,"tv":0.0,"id":13014431}]}]}
{"op":"mcm","clk":"1007922623","pt":1580626060698,"mc":[{"id":"1.168223928","rc":[{"batb":[[0,3.7,69.12],[1,3.65,30.29]],"ltp":0.0,"tv":0.0,"id":13014431}]}]}
{"op":"mcm","clk":"1007928060","pt":1580626182259,"mc":[{"id":"1.168223928","rc":[{"batb":[[0,3.75,30.29],[1,1.02,2],[2,1.01,3.59]],"ltp":0.0,"tv":0.0,"id":13014431}]}]}
{"op":"mcm","clk":"1007928069","pt":1580626182361,"mc":[{"id":"1.168223928","rc":[{"batb":[[0,3.8,67.23],[1,3.75,30.29],[2,1.02,2]],"ltp":0.0,"tv":0.0,"id":13014431}]}]}
{"op":"mcm","clk":"1007934211","pt":1580626304126,"mc":[{"id":"1.168223928","rc":[{"batb":[[0,3.9,65.56],[1,3.85,30.29]],"ltp":0.0,"tv":0.0,"id":13014431}]}]}
{"op":"mcm","clk":"1007940692","pt":1580626425840,"mc":[{"id":"1.168223928","rc":[{"batb":[[0,3.95,95],[1,1.02,2],[2,1.01,3.59]],"ltp":0.0,"tv":0.0,"id":13014431}]}]}
{"op":"mcm","clk":"1007947161","pt":1580626547225,"mc":[{"id":"1.168223928","rc":[{"batb":[[0,4,30.29],[1,3.95,64.71],[2,1.02,2]],"ltp":0.0,"tv":0.0,"id":13014431}]}]}
{"op":"mcm","clk":"1007947175","pt":1580626547432,"mc":[{"id":"1.168223928","rc":[{"batb":[[1,1.02,2],[2,1.01,3.59]],"ltp":0.0,"tv":0.0,"id":13014431}]}]}
{"op":"mcm","clk":"1007953846","pt":1580626669249,"mc":[{"id":"1.168223928","rc":[{"batb":[[0,3.35,30.29]],"ltp":0.0,"tv":0.0,"id":13014431}]}]}
{"op":"mcm","clk":"1007953850","pt":1580626669351,"mc":[{"id":"1.168223928","rc":[{"batb":[[0,3.7,69.12],[1,3.35,30.29],[2,1.02,2]],"ltp":0.0,"tv":0.0,"id":13014431}]}]}
{"op":"mcm","clk":"1007959714","pt":1580626790826,"mc":[{"id":"1.168223928","rc":[{"batb":[[0,3.8,67.23],[1,3.75,30.29]],"ltp":0.0,"tv":0.0,"id":13014431}]}]}
{"op":"mcm","clk":"1007962459","pt":1580626833067,"mc":[{"id":"1.168223928","rc":[{"batb":[[0,1.02,2],[1,1.01,3.59],[2,1.01,0]],"ltp":0.0,"tv":0.0,"id":13015339}]}]}
{"op":"mcm","clk":"1007962472","pt":1580626833273,"mc":[{"id":"1.168223928","rc":[{"batb":[[0,2.08,123.56],[1,1.02,2],[2,1.01,3.59]],"ltp":0.0,"tv":0.0,"id":13015339}]}]}
{"op":"mcm","clk":"1007967521","pt":1580626913202,"mc":[{"id":"1.168223928","rc":[{"batb":[[0,2.26,113.71],[1,2.1,30.29],[2,1.02,2]],"ltp":0.0,"tv":0.0,"id":13015339},{"batb":[[0,3.85,30.29],[1,1.02,2],[2,1.01,3.59]],"ltp":0.0,"tv":0.0,"id":13014431}]}]}
{"op":"mcm","clk":"1007967528","pt":1580626913303,"mc":[{"id":"1.168223928","rc":[{"batb":[[0,3.9,65.56],[1,3.85,30.29],[2,1.02,2]],"ltp":0.0,"tv":0.0,"id":13014431}]}]}
{"op":"mcm","clk":"1007974128","pt":1580627034137,"mc":[{"id":"1.168223928","rc":[{"batb":[[0,2.32,110.64],[1,2.28,30.29]],"ltp":0.0,"tv":0.0,"id":13015339}]}]}
{"op":"mcm","clk":"1007974168","pt":1580627034857,"mc":[{"id":"1.168223928","rc":[{"batb":[[0,3.95,95],[1,1.02,2],[2,1.01,3.59]],"ltp":0.0,"tv":0.0,"id":13014431}]}]}
{"op":"mcm","clk":"1007979309","pt":1580627133598,"mc":[{"id":"1.168223928","rc":[{"batb":[[0,3.1,82.54]],"batl":[[0,18.5,133.77]],"ltp":0.0,"tv":0.0,"id":13014430}]}]}
{"op":"mcm","clk":"1007980474","pt":1580627156211,"mc":[{"id":"1.168223928","rc":[{"batb":[[0,2.36,108.93],[1,2.34,30.29]],"ltp":0.0,"tv":0.0,"id":13015339},{"batb":[[0,4,30.29],[1,3.95,64.71],[2,1.02,2]],"ltp":0.0,"tv":0.0,"id":13014431}]}]}
{"op":"mcm","clk":"1007980487","pt":1580627156415,"mc":[{"id":"1.168223928","rc":[{"batb":[[1,1.02,2],[2,1.01,3.59]],"ltp":0.0,"tv":0.0,"id":13014431}]}]}
{"op":"mcm","clk":"1007986832","pt":1580627277210,"mc":[{"id":"1.168223928","rc":[{"batb":[[0,2.38,30.29],[1,2.36,108.93]],"ltp":0.0,"tv":0.0,"id":13015339}]}]}
{"op":"mcm","clk":"1007986892","pt":1580627278240,"mc":[{"id":"1.168223928","rc":[{"batb":[[0,2.4,106.91],[1,2.38,30.29]],"ltp":0.0,"tv":0.0,"id":13015339},{"batb":[[0,3.35,30.29]],"ltp":0.0,"tv":0.0,"id":13014431}]}]}
{"op":"mcm","clk":"1007986901","pt":1580627278344,"mc":[{"id":"1.168223928","rc":[{"batb":[[0,3.5,73.28],[1,3.35,30.29],[2,1.02,2]],"ltp":0.0,"tv":0.0,"id":13014431}]}]}
{"op":"mcm","clk":"1007993688","pt":1580627398756,"mc":[{"id":"1.168223928","rc":[{"batb":[[1,1.02,2],[2,1.01,3.59]],"ltp":0.0,"tv":0.0,"id":13015339}]}]}
{"op":"mcm","clk":"1007993763","pt":1580627399891,"mc":[{"id":"1.168223928","rc":[{"batb":[[0,3.85,66.37],[1,3.55,30.29]],"ltp":0.0,"tv":0.0,"id":13014431}]}]}
{"op":"mcm","clk":"1008001696","pt":1580627511008,"mc":[{"id":"1.168223928","rc":[{"batl":[[0,3.4,280.19]],"ltp":0.0,"tv":0.0,"id":13015339}]}]}
{"op":"mcm","clk":"1008002220","pt":1580627520862,"mc":[{"id":"1.168223928","rc":[{"batb":[[0,3.95,64.71],[1,3.9,30.29]],"ltp":0.0,"tv":0.0,"id":13014431}]}]}
{"op":"mcm","clk":"1008008579","pt":1580627643088,"mc":[{"id":"1.168223928","rc":[{"batb":[[0,4,30.29],[1,1.02,2],[2,1.01,3.59]],"ltp":0.0,"tv":0.0,"id":13014431}]}]}
{"op":"mcm","clk":"1008015054","pt":1580627764043,"mc":[{"id":"1.168223928","rc":[{"batb":[[0,3.35,106.76]],"ltp":0.0,"tv":0.0,"id":13014431}]}]}
{"op":"mcm","clk":"1008021561","pt":1580627885816,"mc":[{"id":"1.168223928","rc":[{"batb":[[0,3.5,73.28],[1,3.4,30.29],[2,1.02,2]],"ltp":0.0,"tv":0.0,"id":13014431}]}]}
{"op":"mcm","clk":"1008022499","pt":1580627904818,"mc":[{"id":"1.168223928","rc":[{"batl":[[0,13.5,191.27]],"ltp":0.0,"tv":0.0,"id":13014431}]}]}
{"op":"mcm","clk":"1008027367","pt":1580628007166,"mc":[{"id":"1.168223928","rc":[{"batb":[[0,3.55,30.29],[1,3.5,73.28]],"ltp":0.0,"tv":0.0,"id":13014431}]}]}
{"op":"mcm","clk":"1008027386","pt":1580628007473,"mc":[{"id":"1.168223928","rc":[{"batb":[[0,3.65,70.13],[1,3.55,30.29]],"ltp":0.0,"tv":0.0,"id":13014431}]}]}
{"op":"mcm","clk":"1008034803","pt":1580628129030,"mc":[{"id":"1.168223928","rc":[{"batb":[[0,3.8,67.23],[1,3.7,30.29]],"ltp":0.0,"tv":0.0,"id":13014431}]}]}
{"op":"mcm","clk":"1008041884","pt":1580628250920,"mc":[{"id":"1.168223928","rc":[{"batb":[[0,3.9,65.56],[1,3.85,30.29]],"ltp":0.0,"tv":0.0,"id":13014431}]}]}
{"op":"mcm","clk":"1008048081","pt":1580628372252,"mc":[{"id":"1.168223928","rc":[{"batb":[[0,3.95,30.29],[1,3.9,65.56]],"ltp":0.0,"tv":0.0,"id":13014431}]}]}
{"op":"mcm","clk":"1008048096","pt":1580628372456,"mc":[{"id":"1.168223928","rc":[{"batb":[[0,3.95,95],[1,1.02,2],[2,1.01,3.59]],"ltp":0.0,"tv":0.0,"id":13014431}]}]}
{"op":"mcm","clk":"1008055440","pt":1580628494133,"mc":[{"id":"1.168223928","rc":[{"batb":[[0,4,30.29]],"ltp":0.0,"tv":0.0,"id":13014431}]}]}
{"op":"mcm","clk":"1008061859","pt":1580628616100,"mc":[{"id":"1.168223928","rc":[{"batb":[[0,3.55,71.99],[1,3.35,30.29],[2,1.02,2]],"ltp":0.0,"tv":0.0,"id":13014431}]}]}
{"op":"mcm","clk":"1008067430","pt":1580628737252,"mc":[{"id":"1.168223928","rc":[{"batb":[[1,1.02,2],[2,1.01,3.59]],"ltp":0.0,"tv":0.0,"id":13014431}]}]}
{"op":"mcm","clk":"1008067455","pt":1580628737663,"mc":[{"id":"1.168223928","rc":[{"batb":[[0,3.8,67.23],[1,3.6,30.29],[2,1.02,2]],"ltp":0.0,"tv":0.0,"id":13014431}]}]}
{"op":"mcm","clk":"1008073656","pt":1580628859129,"mc":[{"id":"1.168223928","rc":[{"batb":[[0,3.9,65.56],[1,3.85,30.29]],"ltp":0.0,"tv":0.0,"id":13014431}]}]}
{"op":"mcm","clk":"1008079930","pt":1580628980790,"mc":[{"id":"1.168223928","rc":[{"batb":[[0,3.95,95],[1,1.02,2],[2,1.01,3.59]],"ltp":0.0,"tv":0.0,"id":13014431}]}]}
{"op":"mcm","clk":"1008086112","pt":1580629102585,"mc":[{"id":"1.168223928","rc":[{"batb":[[0,4,30.29]],"ltp":0.0,"tv":0.0,"id":13014431}]}]}
{"op":"mcm","clk":"1008091768","pt":1580629224946,"mc":[{"id":"1.168223928","rc":[{"batb":[[0,3.4,75.21],[1,3.35,30.29],[2,1.02,2]],"ltp":0.0,"tv":0.0,"id":13014431}]}]}
{"op":"mcm","clk":"1008098411","pt":1580629345976,"mc":[{"id":"1.168223928","rc":[{"batb":[[0,3.5,73.28],[1,3.45,30.29]],"ltp":0.0,"tv":0.0,"id":13014431}]}]}
{"op":"mcm","clk":"1008104820","pt":1580629467219,"mc":[{"id":"1.168223928","rc":[{"batb":[[1,1.02,2],[2,1.01,3.59]],"ltp":0.0,"tv":0.0,"id":13014431}]}]}
{"op":"mcm","clk":"1008104845","pt":1580629467634,"mc":[{"id":"1.168223928","rc":[{"batb":[[0,3.65,70.13],[1,3.55,30.29],[2,1.02,2]],"ltp":0.0,"tv":0.0,"id":13014431}]}]}
{"op":"mcm","clk":"1008110536","pt":1580629589180,"mc":[{"id":"1.168223928","rc":[{"batb":[[0,3.7,30.29],[1,1.02,2],[2,1.01,3.59]],"ltp":0.0,"tv":0.0,"id":13014431}]}]}
{"op":"mcm","clk":"1008110541","pt":1580629589281,"mc":[{"id":"1.168223928","rc":[{"batb":[[0,3.8,67.23],[1,3.7,30.29],[2,1.02,2]],"ltp":0.0,"tv":0.0,"id":13014431}]}]}
{"op":"mcm","clk":"1008115787","pt":1580629711045,"mc":[{"id":"1.168223928","rc":[{"batb":[[0,3.9,65.56],[1,3.85,30.29]],"ltp":0.0,"tv":0.0,"id":13014431}]}]}
{"op":"mcm","clk":"1008121152","pt":1580629832253,"mc":[{"id":"1.168223928","rc":[{"batb":[[1,1.02,2],[2,1.01,3.59]],"ltp":0.0,"tv":0.0,"id":13014431}]}]}
{"op":"mcm","clk":"1008121174","pt":1580629832662,"mc":[{"id":"1.168223928","rc":[{"batb":[[0,3.95,95]],"ltp":0.0,"tv":0.0,"id":13014431}]}]}
{"op":"mcm","clk":"1008127513","pt":1580629955121,"mc":[{"id":"1.168223928","rc":[{"batb":[[0,4,30.29],[1,3.95,64.71],[2,1.02,2]],"ltp":0.0,"tv":0.0,"id":13014431}]}]}
{"op":"mcm","clk":"1008127521","pt":1580629955325,"mc":[{"id":"1.168223928","rc":[{"batb":[[1,1.02,2],[2,1.01,3.59]],"ltp":0.0,"tv":0.0,"id":13014431}]}]}
{"op":"mcm","clk":"1008135101","pt":1580630077166,"mc":[{"id":"1.168223928","rc":[{"batb":[[0,3.5,73.28],[1,3.35,30.29],[2,1.02,2]],"ltp":0.0,"tv":0.0,"id":13014431}]}]}
{"op":"mcm","clk":"1008142573","pt":1580630198253,"mc":[{"id":"1.168223928","rc":[{"batb":[[1,1.02,2],[2,1.01,3.59]],"ltp":0.0,"tv":0.0,"id":13014431}]}]}
{"op":"mcm","clk":"1008142602","pt":1580630198666,"mc":[{"id":"1.168223928","rc":[{"batb":[[0,3.6,70.99],[1,3.55,30.29],[2,1.02,2]],"ltp":0.0,"tv":0.0,"id":13014431}]}]}
{"op":"mcm","clk":"1008149440","pt":1580630320230,"mc":[{"id":"1.168223928","rc":[{"batb":[[0,3.65,30.29],[1,1.02,2],[2,1.01,3.59]],"ltp":0.0,"tv":0.0,"id":13014431}]}]}
{"op":"mcm","clk":"1008149447","pt":1580630320333,"mc":[{"id":"1.168223928","rc":[{"batb":[[0,3.8,67.23],[1,3.65,30.29],[2,1.02,2]],"ltp":0.0,"tv":0.0,"id":13014431}]}]}
{"op":"mcm","clk":"1008154640","pt":1580630405339,"mc":[{"id":"1.168223928","rc":[{"batb":[[0,3.05,84.09],[1,1.02,2],[2,1.01,1.01]],"batl":[[0,11.5,227.99]],"ltp":0.0,"tv":0.0,"id":13015338}]}]}
{"op":"mcm","clk":"1008156569","pt":1580630433809,"mc":[{"id":"1.168223928","rc":[{"batb":[[0,1.02,2],[1,1.01,3.59],[2,1.01,0]],"ltp":0.0,"tv":0.0,"id":13015339}]}]}
{"op":"mcm","clk":"1008157155","pt":1580630442205,"mc":[{"id":"1.168223928","rc":[{"batb":[[0,2.12,121.29],[1,2.1,30.29],[2,1.02,2]],"ltp":0.0,"tv":0.0,"id":13015339},{"batb":[[1,1.02,2],[2,1.01,3.59]],"ltp":0.0,"tv":0.0,"id":13014431}]}]}
{"op":"mcm","clk":"1008157181","pt":1580630442614,"mc":[{"id":"1.168223928","rc":[{"batb":[[0,3.9,65.56],[1,3.85,30.29],[2,1.02,2]],"ltp":0.0,"tv":0.0,"id":13014431}]}]}
{"op":"mcm","clk":"1008164086","pt":1580630564272,"mc":[{"id":"1.168223928","rc":[{"batb":[[0,2.2,116.72],[1,2.14,30.29]],"ltp":0.0,"tv":0.0,"id":13015339},{"batb":[[0,3.95,95],[1,1.02,2],[2,1.01,3.59]],"ltp":0.0,"tv":0.0,"id":13014431}]}]}
{"op":"mcm","clk":"1008171418","pt":1580630686148,"mc":[{"id":"1.168223928","rc":[{"batb":[[0,2.28,112.66],[1,2.22,30.29]],"ltp":0.0,"tv":0.0,"id":13015339},{"batb":[[0,4,30.29],[1,3.95,64.71],[2,1.02,2]],"ltp":0.0,"tv":0.0,"id":13014431}]}]}
{"op":"mcm","clk":"1008171426","pt":1580630686353,"mc":[{"id":"1.168223928","rc":[{"batb":[[1,1.02,2],[2,1.01,3.59]],"ltp":0.0,"tv":0.0,"id":13014431}]}]}
{"op":"mcm","clk":"1008174172","pt":1580630733653,"mc":[{"id":"1.168223928","rc":[{"batb":[[0,1.02,2],[1,1.01,1.01],[2,1.01,0]],"ltp":0.0,"tv":0.0,"id":13014430}]}]}
{"op":"mcm","clk":"1008177829","pt":1580630807072,"mc":[{"id":"1.168223928","rc":[{"batb":[[0,2.32,110.64],[1,2.3,30.29]],"ltp":0.0,"tv":0.0,"id":13015339}]}]}
{"op":"mcm","clk":"1008177884","pt":1580630807997,"mc":[{"id":"1.168223928","rc":[{"batb":[[0,3.6,70.99],[1,3.35,30.29],[2,1.02,2]],"ltp":0.0,"tv":0.0,"id":13014431}]}]}
{"op":"mcm","clk":"1008184232","pt":1580630929128,"mc":[{"id":"1.168223928","rc":[{"batb":[[0,2.36,108.93],[1,2.34,30.29]],"ltp":0.0,"tv":0.0,"id":13015339},{"batb":[[0,3.65,30.29],[1,3.6,70.99]],"ltp":0.0,"tv":0.0,"id":13014431}]}]}
{"op":"mcm","clk":"1008184248","pt":1580630929438,"mc":[{"id":"1.168223928","rc":[{"batb":[[0,3.7,69.12],[1,3.65,30.29]],"ltp":0.0,"tv":0.0,"id":13014431}]}]}
{"op":"mcm","clk":"1008191062","pt":1580631050071,"mc":[{"id":"1.168223928","rc":[{"batb":[[0,2.38,30.29],[1,2.36,108.93]],"ltp":0.0,"tv":0.0,"id":13015339}]}]}
{"op":"mcm","clk":"1008191115","pt":1580631051099,"mc":[{"id":"1.168223928","rc":[{"batb":[[0,2.4,106.91],[1,2.38,30.29]],"ltp":0.0,"tv":0.0,"id":13015339},{"batb":[[0,3.85,66.37],[1,3.75,30.29]],"ltp":0.0,"tv":0.0,"id":13014431}]}]}
{"op":"mcm","clk":"1008198972","pt":1580631172217,"mc":[{"id":"1.168223928","rc":[{"batb":[[1,1.02,2],[2,1.01,3.59]],"batl":[[0,4,238.58]],"ltp":0.0,"tv":0.0,"id":13015339},{"batb":[[1,1.02,2],[2,1.01,3.59]],"ltp":0.0,"tv":0.0,"id":13014431}]}]}
{"op":"mcm","clk":"1008198995","pt":1580631172478,"mc":[{"id":"1.168223928","rc":[{"batb":[[0,3.95,64.71],[1,3.9,30.29],[2,1.02,2]],"ltp":0.0,"tv":0.0,"id":13014431}]}]}
{"op":"mcm","clk":"1008207679","pt":1580631293524,"mc":[{"id":"1.168223928","rc":[{"batb":[[0,4,30.29],[1,1.02,2],[2,1.01,3.59]],"ltp":0.0,"tv":0.0,"id":13014431}]}]}
{"op":"mcm","clk":"1008216064","pt":1580631416152,"mc":[{"id":"1.168223928","rc":[{"batb":[[0,3.7,69.12],[1,3.35,30.29],[2,1.02,2]],"ltp":0.0,"tv":0.0,"id":13014431}]}]}
{"op":"mcm","clk":"1008222168","pt":1580631505049,"mc":[{"id":"1.168223928","rc":[{"batl":[[0,7.6,339.56]],"ltp":0.0,"tv":0.0,"id":13014431}]}]}
{"op":"mcm","clk":"1008224264","pt":1580631537090,"mc":[{"id":"1.168223928","rc":[{"batb":[[0,3.8,67.23],[1,3.75,30.29]],"ltp":0.0,"tv":0.0,"id":13014431}]}]}
{"op":"mcm","clk":"1008232272","pt":1580631658795,"mc":[{"id":"1.168223928","rc":[{"batb":[[0,3.9,65.56],[1,3.85,30.29]],"ltp":0.0,"tv":0.0,"id":13014431}]}]}
{"op":"mcm","clk":"1008240577","pt":1580631780146,"mc":[{"id":"1.168223928","rc":[{"batb":[[0,3.95,30.29],[1,3.9,65.56]],"ltp":0.0,"tv":0.0,"id":13014431}]}]}
{"op":"mcm","clk":"1008240594","pt":1580631780478,"mc":[{"id":"1.168223928","rc":[{"batb":[[0,3.95,95],[1,1.02,2],[2,1.01,3.59]],"ltp":0.0,"tv":0.0,"id":13014431}]}]}
{"op":"mcm","clk":"1008247419","pt":1580631902110,"mc":[{"id":"1.168223928","rc":[{"batb":[[0,4,30.29]],"ltp":0.0,"tv":0.0,"id":13014431}]}]}
{"op":"mcm","clk":"1008254424","pt":1580632024166,"mc":[{"id":"1.168223928","rc":[{"batb":[[0,2.42,136.42]],"ltp":0.0,"tv":0.0,"id":13015339},{"batb":[[0,3.3,30.29],[1,3.05,84.09],[2,1.02,2]],"ltp":0.0,"tv":0.0,"id":13014431}]}]}
{"op":"mcm","clk":"1008254437","pt":1580632024474,"mc":[{"id":"1.168223928","rc":[{"batb":[[0,3.9,65.56],[1,3.3,30.29]],"ltp":0.0,"tv":0.0,"id":13014431}]}]}
{"op":"mcm","clk":"1008261511","pt":1580632145118,"mc":[{"id":"1.168223928","rc":[{"batb":[[0,2.42,106.13]],"ltp":0.0,"tv":0.0,"id":13015339}]}]}
{"op":"mcm","clk":"1008261623","pt":1580632146711,"mc":[{"id":"1.168223928","rc":[{"batb":[[0,3.95,95],[1,1.02,2],[2,1.01,3.59]],"ltp":0.0,"tv":0.0,"id":13014431}]}]}
{"op":"mcm","clk":"1008269652","pt":1580632266742,"mc":[{"id":"1.168223928","rc":[{"batb":[[0,3.95,64.71]],"ltp":0.0,"tv":0.0,"id":13014431}]}]}
{"op":"mcm","clk":"1008365310","pt":1580634005858,"mc":[{"id":"1.168223928","rc":[{"batl":[[0,12,218.75]],"ltp":0.0,"tv":0.0,"id":13015338}]}]}
{"op":"mcm","clk":"1008367545","pt":1580634042244,"mc":[{"id":"1.168223928","rc":[{"batb":[[0,1.02,2],[1,1.01,3.59],[2,1.01,0]],"ltp":0.0,"tv":0.0,"id":13015339}]}]}
{"op":"mcm","clk":"1008367558","pt":1580634042452,"mc":[{"id":"1.168223928","rc":[{"batb":[[0,2.04,126.12],[1,1.02,2],[2,1.01,3.59]],"ltp":0.0,"tv":0.0,"id":13015339}]}]}
{"op":"mcm","clk":"1008370375","pt":1580634093094,"mc":[{"id":"1.168223928","rc":[{"batb":[[0,2.14,120.03],[1,2.12,30.29],[2,1.02,2]],"ltp":0.0,"tv":0.0,"id":13015339}]}]}
{"op":"mcm","clk":"1008377572","pt":1580634214881,"mc":[{"id":"1.168223928","rc":[{"batb":[[0,2.22,115.84],[1,2.16,30.29]],"ltp":0.0,"tv":0.0,"id":13015339}]}]}
{"op":"mcm","clk":"1008384025","pt":1580634334419,"mc":[{"id":"1.168223928","rc":[{"batb":[[0,3.6,70.99],[1,1.02,2],[2,1.01,1.01]],"batl":[[0,28,88.58]],"ltp":0.0,"tv":0.0,"id":13014430}]}]}
{"op":"mcm","clk":"1008384125","pt":1580634336218,"mc":[{"id":"1.168223928","rc":[{"batb":[[1,1.02,2],[2,1.01,3.59]],"ltp":0.0,"tv":0.0,"id":13015339}]}]}
{"op":"mcm","clk":"1008384150","pt":1580634336633,"mc":[{"id":"1.168223928","rc":[{"batb":[[0,2.32,110.64],[1,2.24,30.29],[2,1.02,2]],"ltp":0.0,"tv":0.0,"id":13015339}]}]}
{"op":"mcm","clk":"1008391465","pt":1580634460196,"mc":[{"id":"1.168223928","rc":[{"batb":[[0,2.34,30.29],[1,1.02,2],[2,1.01,3.59]],"ltp":0.0,"tv":0.0,"id":13015339}]}]}
{"op":"mcm","clk":"1008391474","pt":1580634460297,"mc":[{"id":"1.168223928","rc":[{"batb":[[0,2.36,108.93],[1,2.34,30.29],[2,1.02,2]],"ltp":0.0,"tv":0.0,"id":13015339}]}]}
{"op":"mcm","clk":"1008399065","pt":1580634581965,"mc":[{"id":"1.168223928","rc":[{"batb":[[0,2.4,106.91],[1,2.38,30.29]],"ltp":0.0,"tv":0.0,"id":13015339}]}]}
{"op":"mcm","clk":"1008406942","pt":1580634703183,"mc":[{"id":"1.168223928","rc":[{"batb":[[1,1.02,2],[2,1.01,3.59]],"ltp":0.0,"tv":0.0,"id":13015339}]}]}
{"op":"mcm","clk":"1008406985","pt":1580634703595,"mc":[{"id":"1.168223928","rc":[{"batb":[[0,2.42,136.42]],"ltp":0.0,"tv":0.0,"id":13015339}]}]}
{"op":"mcm","clk":"1008411307","pt":1580634772272,"mc":[{"id":"1.168223928","rc":[{"batl":[[0,4.2,227.28]],"ltp":0.0,"tv":0.0,"id":13015339}]}]}
{"op":"mcm","clk":"1008414306","pt":1580634824912,"mc":[{"id":"1.168223928","rc":[{"batb":[[0,2.42,106.13]],"ltp":0.0,"tv":0.0,"id":13015339}]}]}
{"op":"mcm","clk":"1008440105","pt":1580635277662,"mc":[{"id":"1.168223928","rc":[{"batl":[[0,15,172.39]],"ltp":0.0,"tv":0.0,"id":13014431}]}]}
{"op":"mcm","clk":"1008460475","pt":1580635625118,"mc":[{"id":"1.168223928","rc":[{"batb":[[0,1.02,2],[1,1.01,3.59],[2,1.01,0]],"ltp":0.0,"tv":0.0,"id":13014431}]}]}
{"op":"mcm","clk":"1008463395","pt":1580635676862,"mc":[{"id":"1.168223928","rc":[{"batb":[[0,3.65,70.13],[1,3.3,30.29],[2,1.02,2]],"ltp":0.0,"tv":0.0,"id":13014431}]}]}
{"op":"mcm","clk":"1008470576","pt":1580635799120,"mc":[{"id":"1.168223928","rc":[{"batb":[[0,3.7,30.29],[1,3.65,70.13]],"ltp":0.0,"tv":0.0,"id":13014431}]}]}
{"op":"mcm","clk":"1008470595","pt":1580635799530,"mc":[{"id":"1.168223928","rc":[{"batb":[[0,3.9,65.56],[1,3.7,30.29]],"ltp":0.0,"tv":0.0,"id":13014431}]}]}
{"op":"mcm","clk":"1008477803","pt":1580635920111,"mc":[{"id":"1.168223928","rc":[{"batb":[[0,3.95,30.29],[1,3.9,65.56]],"ltp":0.0,"tv":0.0,"id":13014431}]}]}
{"op":"mcm","clk":"1008477827","pt":1580635920475,"mc":[{"id":"1.168223928","rc":[{"batb":[[0,3.95,95],[1,1.02,2],[2,1.01,3.59]],"ltp":0.0,"tv":0.0,"id":13014431}]}]}
{"op":"mcm","clk":"1008486475","pt":1580636041670,"mc":[{"id":"1.168223928","rc":[{"batb":[[0,3.95,64.71]],"ltp":0.0,"tv":0.0,"id":13014431}]}]}
{"op":"mcm","clk":"1008596089","pt":1580637605880,"mc":[{"id":"1.168223928","rc":[{"batb":[[0,1.02,2],[1,1.01,1.01],[2,1.01,0]],"ltp":0.0,"tv":0.0,"id":13015338}]}]}
{"op":"mcm","clk":"1008598743","pt":1580637642434,"mc":[{"id":"1.168223928","rc":[{"batb":[[0,1.02,2],[1,1.01,3.59],[2,1.01,0]],"ltp":0.0,"tv":0.0,"id":13015339}]}]}
{"op":"mcm","clk":"1008606330","pt":1580637746076,"mc":[{"id":"1.168223928","rc":[{"batb":[[0,2.12,30.29],[1,1.02,2],[2,1.01,3.59]],"ltp":0.0,"tv":0.0,"id":13015339}]}]}
{"op":"mcm","clk":"1008606348","pt":1580637746388,"mc":[{"id":"1.168223928","rc":[{"batb":[[0,2.24,114.77],[1,2.12,30.29],[2,1.02,2]],"ltp":0.0,"tv":0.0,"id":13015339}]}]}
{"op":"mcm","clk":"1008615686","pt":1580637868064,"mc":[{"id":"1.168223928","rc":[{"batb":[[0,2.28,112.66],[1,2.26,30.29]],"ltp":0.0,"tv":0.0,"id":13015339}]}]}
{"op":"mcm","clk":"1008621354","pt":1580637934429,"mc":[{"id":"1.168223928","rc":[{"batb":[[0,1.02,2],[1,1.01,1.01],[2,1.01,0]],"ltp":0.0,"tv":0.0,"id":13014430}]}]}
{"op":"mcm","clk":"1008625885","pt":1580637989774,"mc":[{"id":"1.168223928","rc":[{"batb":[[0,2.34,109.72],[1,2.3,30.29]],"ltp":0.0,"tv":0.0,"id":13015339}]}]}
{"op":"mcm","clk":"1008635946","pt":1580638111178,"mc":[{"id":"1.168223928","rc":[{"batb":[[1,1.02,2],[2,1.01,3.59]],"ltp":0.0,"tv":0.0,"id":13015339}]}]}
{"op":"mcm","clk":"1008635985","pt":1580638111687,"mc":[{"id":"1.168223928","rc":[{"batb":[[0,2.38,107.96],[1,2.36,30.29],[2,1.02,2]],"ltp":0.0,"tv":0.0,"id":13015339}]}]}
{"op":"mcm","clk":"1008645997","pt":1580638233240,"mc":[{"id":"1.168223928","rc":[{"batb":[[0,2.42,106.13],[1,2.4,30.29]],"ltp":0.0,"tv":0.0,"id":13015339}]}]}
{"op":"mcm","clk":"1008657768","pt":1580638354577,"mc":[{"id":"1.168223928","rc":[{"batb":[[1,1.02,2],[2,1.01,3.59]],"ltp":0.0,"tv":0.0,"id":13015339}]}]}
{"op":"mcm","clk":"1008747416","pt":1580639278106,"mc":[{"id":"1.168223928","rc":[{"batb":[[0,2.74,93.52]],"ltp":0.0,"tv":0.0,"id":13014431}]}]}
{"op":"mcm","clk":"1008752092","pt":1580639328146,"mc":[{"id":"1.168223928","rc":[{"batb":[[0,3.4,75.21],[1,3.3,30.29],[2,1.02,2]],"ltp":0.0,"tv":0.0,"id":13014431}]}]}
{"op":"mcm","clk":"1008764932","pt":1580639449932,"mc":[{"id":"1.168223928","rc":[{"batb":[[0,3.75,68.11],[1,3.45,30.29]],"ltp":0.0,"tv":0.0,"id":13014431}]}]}
{"op":"mcm","clk":"1008778570","pt":1580639572638,"mc":[{"id":"1.168223928","rc":[{"batb":[[0,3.85,66.37],[1,3.8,30.29]],"ltp":0.0,"tv":0.0,"id":13014431}]}]}
{"op":"mcm","clk":"1008791510","pt":1580639694108,"mc":[{"id":"1.168223928","rc":[{"batb":[[0,2.44,30.29]],"ltp":0.0,"tv":0.0,"id":13015339}]}]}
{"op":"mcm","clk":"1008791593","pt":1580639694794,"mc":[{"id":"1.168223928","rc":[{"batl":[[0,4.3,221.85]],"ltp":0.0,"tv":0.0,"id":13015339},{"batb":[[0,3.95,64.71],[1,3.9,30.29]],"ltp":0.0,"tv":0.0,"id":13014431}]}]}
{"op":"mcm","clk":"1008805016","pt":1580639816201,"mc":[{"id":"1.168223928","rc":[{"batb":[[0,2.22,115.84],[1,2.12,30.29],[2,1.02,2]],"ltp":0.0,"tv":0.0,"id":13015339}]}]}
{"op":"mcm","clk":"1008805026","pt":1580639816305,"mc":[{"id":"1.168223928","rc":[{"batb":[[1,1.02,2],[2,1.01,3.59]],"ltp":0.0,"tv":0.0,"id":13014431}]}]}
{"op":"mcm","clk":"1008819120","pt":1580639937712,"mc":[{"id":"1.168223928","rc":[{"batb":[[0,2.34,109.72],[1,2.24,30.29]],"ltp":0.0,"tv":0.0,"id":13015339}]}]}
{"op":"mcm","clk":"1008832417","pt":1580640059206,"mc":[{"id":"1.168223928","rc":[{"batb":[[0,2.36,30.29],[1,1.02,2],[2,1.01,3.59]],"ltp":0.0,"tv":0.0,"id":13015339}]}]}
{"op":"mcm","clk":"1008832426","pt":1580640059313,"mc":[{"id":"1.168223928","rc":[{"batb":[[0,2.4,106.91],[1,2.36,30.29],[2,1.02,2]],"ltp":0.0,"tv":0.0,"id":13015339}]}]}
{"op":"mcm","clk":"1008847725","pt":1580640181256,"mc":[{"id":"1.168223928","rc":[{"batb":[[0,2.42,30.29],[1,2.4,106.91]],"ltp":0.0,"tv":0.0,"id":13015339}]}]}
{"op":"mcm","clk":"1008847796","pt":1580640181666,"mc":[{"id":"1.168223928","rc":[{"batb":[[0,2.42,136.42],[1,1.02,2],[2,1.01,3.59]],"ltp":0.0,"tv":0.0,"id":13015339}]}]}
{"op":"mcm","clk":"1008984770","pt":1580641276174,"mc":[{"id":"1.168223928","rc":[{"batb":[[0,2.44,30.29]],"ltp":0.0,"tv":0.0,"id":13015339}]}]}
{"op":"mcm","clk":"1009001560","pt":1580641398108,"mc":[{"id":"1.168223928","rc":[{"batb":[[0,2.2,116.72],[1,2.12,30.29],[2,1.02,2]],"ltp":0.0,"tv":0.0,"id":13015339}]}]}
{"op":"mcm","clk":"1009019504","pt":1580641519233,"mc":[{"id":"1.168223928","rc":[{"batb":[[0,2.22,30.29],[1,2.2,116.72]],"ltp":0.0,"tv":0.0,"id":13015339}]}]}
{"op":"mcm","clk":"1009019555","pt":1580641519668,"mc":[{"id":"1.168223928","rc":[{"batb":[[0,2.38,107.96],[1,2.22,30.29]],"ltp":0.0,"tv":0.0,"id":13015339}]}]}
{"op":"mcm","clk":"1009022083","pt":1580641535042,"mc":[{"id":"1.168223928","rc":[{"batb":[[0,2.98,85.9],[1,1.02,2],[2,1.01,1.01]],"batl":[[0,34,72.95]],"ltp":0.0,"tv":0.0,"id":13014430}]}]}
{"op":"mcm","clk":"1009039673","pt":1580641641174,"mc":[{"id":"1.168223928","rc":[{"batb":[[0,2.4,30.29],[1,1.02,2],[2,1.01,3.59]],"ltp":0.0,"tv":0.0,"id":13015339}]}]}
{"op":"mcm","clk":"1009039721","pt":1580641641493,"mc":[{"id":"1.168223928","rc":[{"batb":[[0,2.42,106.13],[1,2.4,30.29],[2,1.02,2]],"ltp":0.0,"tv":0.0,"id":13015339}]}]}
{"op":"mcm","clk":"1009058395","pt":1580641762798,"mc":[{"id":"1.168223928","rc":[{"batb":[[0,2.44,30.29],[1,1.02,2],[2,1.01,3.59]],"ltp":0.0,"tv":0.0,"id":13015339}]}]}
{"op":"mcm","clk":"1009075947","pt":1580641884210,"mc":[{"id":"1.168223928","rc":[{"batb":[[0,2.12,30.29]],"ltp":0.0,"tv":0.0,"id":13015339}]}]}
{"op":"mcm","clk":"1009076025","pt":1580641884698,"mc":[{"id":"1.168223928","rc":[{"batb":[[0,2.36,108.93],[1,2.12,30.29],[2,1.02,2]],"ltp":0.0,"tv":0.0,"id":13015339}]}]}
{"op":"mcm","clk":"1009095460","pt":1580642007051,"mc":[{"id":"1.168223928","rc":[{"batb":[[0,2.38,30.29],[1,2.36,108.93]],"ltp":0.0,"tv":0.0,"id":13015339}]}]}
{"op":"mcm","clk":"1009095512","pt":1580642007422,"mc":[{"id":"1.168223928","rc":[{"batb":[[0,2.4,106.91],[1,2.38,30.29]],"ltp":0.0,"tv":0.0,"id":13015339}]}]}
{"op":"mcm","clk":"1009115208","pt":1580642129009,"mc":[{"id":"1.168223928","rc":[{"batb":[[0,2.42,136.42],[1,1.02,2],[2,1.01,3.59]],"ltp":0.0,"tv":0.0,"id":13015339}]}]}
{"op":"mcm","clk":"1009134806","pt":1580642250160,"mc":[{"id":"1.168223928","rc":[{"batb":[[0,2.44,30.29],[1,2.42,106.13],[2,1.02,2]],"ltp":0.0,"tv":0.0,"id":13015339}]}]}
{"op":"mcm","clk":"1009134842","pt":1580642250373,"mc":[{"id":"1.168223928","rc":[{"batb":[[1,1.02,2],[2,1.01,3.59]],"ltp":0.0,"tv":0.0,"id":13015339}]}]}
{"op":"mcm","clk":"1009153643","pt":1580642372128,"mc":[{"id":"1.168223928","rc":[{"batb":[[0,2.12,30.29],[1,1.93,133.36],[2,1.02,2]],"ltp":0.0,"tv":0.0,"id":13015339}]}]}
{"op":"mcm","clk":"1009153707","pt":1580642372545,"mc":[{"id":"1.168223928","rc":[{"batb":[[0,2.3,111.68],[1,2.12,30.29]],"ltp":0.0,"tv":0.0,"id":13015339}]}]}
{"op":"mcm","clk":"1009171457","pt":1580642494225,"mc":[{"id":"1.168223928","rc":[{"batb":[[1,1.02,2],[2,1.01,3.59]],"ltp":0.0,"tv":0.0,"id":13015339}]}]}
{"op":"mcm","clk":"1009171527","pt":1580642494743,"mc":[{"id":"1.168223928","rc":[{"batb":[[0,2.36,108.93],[1,2.32,30.29],[2,1.02,2]],"ltp":0.0,"tv":0.0,"id":13015339}]}]}
{"op":"mcm","clk":"1009189189","pt":1580642615250,"mc":[{"id":"1.168223928","rc":[{"batb":[[0,2.38,30.29],[1,2.36,108.93]],"ltp":0.0,"tv":0.0,"id":13015339}]}]}
{"op":"mcm","clk":"1009189244","pt":1580642615629,"mc":[{"id":"1.168223928","rc":[{"batb":[[0,2.4,106.91],[1,2.38,30.29]],"ltp":0.0,"tv":0.0,"id":13015339}]}]}
{"op":"mcm","clk":"1009206773","pt":1580642737112,"mc":[{"id":"1.168223928","rc":[{"batb":[[0,2.42,30.29],[1,1.02,2],[2,1.01,3.59]],"ltp":0.0,"tv":0.0,"id":13015339}]}]}
{"op":"mcm","clk":"1009206814","pt":1580642737432,"mc":[{"id":"1.168223928","rc":[{"batb":[[0,2.42,136.42]],"ltp":0.0,"tv":0.0,"id":13015339}]}]}
{"op":"mcm","clk":"1009225389","pt":1580642858771,"mc":[{"id":"1.168223928","rc":[{"batb":[[0,2.44,30.29]],"ltp":0.0,"tv":0.0,"id":13015339}]}]}
{"op":"mcm","clk":"1009228481","pt":1580642879004,"mc":[{"id":"1.168223928","rc":[{"batb":[[0,2.64,97.32]],"batl":[[0,16,161.63]],"ltp":0.0,"tv":0.0,"id":13014431}]}]}
{"op":"mcm","clk":"1009243612","pt":1580642980187,"mc":[{"id":"1.168223928","rc":[{"batb":[[0,1.02,2],[1,1.01,3.59],[2,1.01,0]],"ltp":0.0,"tv":0.0,"id":13015339}]}]}
{"op":"mcm","clk":"1009243771","pt":1580642981103,"mc":[{"id":"1.168223928","rc":[{"batb":[[0,2.14,120.03],[1,2.12,30.29],[2,1.02,2]],"ltp":0.0,"tv":0.0,"id":13015339},{"batb":[[0,3.35,76.47],[1,3.3,30.29],[2,1.02,2]],"ltp":0.0,"tv":0.0,"id":13014431}]}]}
{"op":"mcm","clk":"1009263069","pt":1580643102258,"mc":[{"id":"1.168223928","rc":[{"batb":[[0,2.16,30.29],[1,1.02,2],[2,1.01,3.59]],"ltp":0.0,"tv":0.0,"id":13015339}]}]}
{"op":"mcm","clk":"1009263248","pt":1580643103107,"mc":[{"id":"1.168223928","rc":[{"batb":[[0,2.28,112.66],[1,2.16,30.29],[2,1.02,2]],"ltp":0.0,"tv":0.0,"id":13015339},{"batb":[[0,3.6,70.99],[1,3.4,30.29]],"ltp":0.0,"tv":0.0,"id":13014431}]}]}
{"op":"mcm","clk":"1009282301","pt":1580643223962,"mc":[{"id":"1.168223928","rc":[{"batb":[[0,2.32,110.64],[1,2.3,30.29]],"ltp":0.0,"tv":0.0,"id":13015339}]}]}
{"op":"mcm","clk":"1009282475","pt":1580643225249,"mc":[{"id":"1.168223928","rc":[{"batb":[[0,3.65,30.29],[1,1.02,2],[2,1.01,3.59]],"ltp":0.0,"tv":0.0,"id":13014431}]}]}
{"op":"mcm","clk":"1009282497","pt":1580643225457,"mc":[{"id":"1.168223928","rc":[{"batb":[[0,3.8,67.23],[1,3.65,30.29],[2,1.02,2]],"ltp":0.0,"tv":0.0,"id":13014431}]}]}
{"op":"mcm","clk":"1009292004","pt":1580643294647,"mc":[{"id":"1.168223928","rc":[{"batl":[[0,3.7,257.65]],"ltp":0.0,"tv":0.0,"id":13015339}]}]}
{"op":"mcm","clk":"1009299543","pt":1580643346143,"mc":[{"id":"1.168223928","rc":[{"batb":[[0,2.36,108.93],[1,2.34,30.29]],"ltp":0.0,"tv":0.0,"id":13015339},{"batb":[[0,3.85,30.29],[1,3.8,67.23]],"ltp":0.0,"tv":0.0,"id":13014431}]}]}
{"op":"mcm","clk":"1009299649","pt":1580643346796,"mc":[{"id":"1.168223928","rc":[{"batb":[[0,3.9,65.56],[1,3.85,30.29]],"ltp":0.0,"tv":0.0,"id":13014431}]}]}
{"op":"mcm","clk":"1009317865","pt":1580643466921,"mc":[{"id":"1.168223928","rc":[{"batb":[[1,1.02,2],[2,1.01,3.59]],"ltp":0.0,"tv":0.0,"id":13014431}]}]}
{"op":"mcm","clk":"1009488954","pt":1580644806139,"mc":[{"id":"1.168223928","rc":[{"batb":[[0,2.38,30.29],[1,2.36,108.93]],"ltp":0.0,"tv":0.0,"id":13015339}]}]}
{"op":"mcm","clk":"1009489005","pt":1580644806553,"mc":[{"id":"1.168223928","rc":[{"batb":[[0,2.4,106.91],[1,2.38,30.29]],"ltp":0.0,"tv":0.0,"id":13015339}]}]}
{"op":"mcm","clk":"1009505518","pt":1580644927140,"mc":[{"id":"1.168223928","rc":[{"batb":[[0,2.42,30.29],[1,2.4,106.91]],"ltp":0.0,"tv":0.0,"id":13015339}]}]}
{"op":"mcm","clk":"1009505560","pt":1580644927395,"mc":[{"id":"1.168223928","rc":[{"batb":[[1,1.02,2],[2,1.01,3.59]],"ltp":0.0,"tv":0.0,"id":13015339}]}]}
{"op":"mcm","clk":"1009506333","pt":1580644932517,"mc":[{"id":"1.168223928","rc":[{"batb":[[0,2.42,136.42]],"ltp":0.0,"tv":0.0,"id":13015339}]}]}
{"op":"mcm","clk":"1009523617","pt":1580645049036,"mc":[{"id":"1.168223928","rc":[{"batb":[[0,2.44,30.29]],"ltp":0.0,"tv":0.0,"id":13015339}]}]}
{"op":"mcm","clk":"1009535391","pt":1580645135151,"mc":[{"id":"1.168223928","rc":[{"batb":[[0,1.02,2],[1,1.01,1.01],[2,1.01,0]],"ltp":0.0,"tv":0.0,"id":13014430}]}]}
{"op":"mcm","clk":"1009540352","pt":1580645171210,"mc":[{"id":"1.168223928","rc":[{"batb":[[0,2.22,115.84],[1,2.14,30.29],[2,1.02,2]],"ltp":0.0,"tv":0.0,"id":13015339}]}]}
{"op":"mcm","clk":"1009558204","pt":1580645292118,"mc":[{"id":"1.168223928","rc":[{"batb":[[0,2.24,30.29],[1,2.22,115.84]],"ltp":0.0,"tv":0.0,"id":13015339}]}]}
{"op":"mcm","clk":"1009558258","pt":1580645292539,"mc":[{"id":"1.168223928","rc":[{"batb":[[0,2.26,113.71],[1,2.24,30.29]],"ltp":0.0,"tv":0.0,"id":13015339}]}]}
{"op":"mcm","clk":"1009575732","pt":1580645414244,"mc":[{"id":"1.168223928","rc":[{"batb":[[0,2.28,30.29],[1,1.02,2],[2,1.01,3.59]],"ltp":0.0,"tv":0.0,"id":13015339}]}]}
{"op":"mcm","clk":"1009575746","pt":1580645414402,"mc":[{"id":"1.168223928","rc":[{"batb":[[0,2.32,110.64],[1,2.28,30.29],[2,1.02,2]],"ltp":0.0,"tv":0.0,"id":13015339}]}]}
{"op":"mcm","clk":"1009592462","pt":1580645536009,"mc":[{"id":"1.168223928","rc":[{"batb":[[0,2.36,108.93],[1,2.34,30.29]],"ltp":0.0,"tv":0.0,"id":13015339}]}]}
{"op":"mcm","clk":"1009611844","pt":1580645657269,"mc":[{"id":"1.168223928","rc":[{"batb":[[0,2.38,30.29],[1,2.36,108.93]],"ltp":0.0,"tv":0.0,"id":13015339}]}]}
{"op":"mcm","clk":"1009611909","pt":1580645657682,"mc":[{"id":"1.168223928","rc":[{"batb":[[0,2.4,106.91],[1,2.38,30.29]],"ltp":0.0,"tv":0.0,"id":13015339}]}]}
{"op":"mcm","clk":"1009629813","pt":1580645779251,"mc":[{"id":"1.168223928","rc":[{"batb":[[0,2.42,136.42],[1,1.02,2],[2,1.01,3.59]],"ltp":0.0,"tv":0.0,"id":13015339}]}]}
{"op":"mcm","clk":"1009646198","pt":1580645900722,"mc":[{"id":"1.168223928","rc":[{"batb":[[0,2.44,30.29]],"ltp":0.0,"tv":0.0,"id":13015339}]}]}
{"op":"mcm","clk":"1009661452","pt":1580646022148,"mc":[{"id":"1.168223928","rc":[{"batb":[[0,2.14,30.29]],"ltp":0.0,"tv":0.0,"id":13015339}]}]}
{"op":"mcm","clk":"1009661528","pt":1580646022743,"mc":[{"id":"1.168223928","rc":[{"batb":[[0,2.3,111.68],[1,2.14,30.29],[2,1.02,2]],"ltp":0.0,"tv":0.0,"id":13015339}]}]}
{"op":"mcm","clk":"1009678032","pt":1580646144224,"mc":[{"id":"1.168223928","rc":[{"batb":[[0,2.34,109.72],[1,2.32,30.29]],"ltp":0.0,"tv":0.0,"id":13015339}]}]}
{"op":"mcm","clk":"1009694601","pt":1580646265868,"mc":[{"id":"1.168223928","rc":[{"batb":[[0,2.38,107.96],[1,2.36,30.29]],"ltp":0.0,"tv":0.0,"id":13015339}]}]}
{"op":"mcm","clk":"1009710365","pt":1580646388153,"mc":[{"id":"1.168223928","rc":[{"batb":[[0,2.4,30.29],[1,1.02,2],[2,1.01,3.59]],"ltp":0.0,"tv":0.0,"id":13015339}]}]}
{"op":"mcm","clk":"1009710396","pt":1580646388357,"mc":[{"id":"1.168223928","rc":[{"batb":[[0,2.42,106.13],[1,2.4,30.29],[2,1.02,2]],"ltp":0.0,"tv":0.0,"id":13015339}]}]}
{"op":"mcm","clk":"1009723096","pt":1580646479110,"mc":[{"id":"1.168223928","rc":[{"batl":[[0,9.8,263.42]],"ltp":0.0,"tv":0.0,"id":13014431}]}]}
{"op":"mcm","clk":"1009723198","pt":1580646479950,"mc":[{"id":"1.168223928","rc":[{"batb":[[0,1.02,2],[1,1.01,3.59],[2,1.01,0]],"ltp":0.0,"tv":0.0,"id":13014431}]}]}
{"op":"mcm","clk":"1009723240","pt":1580646480320,"mc":[{"id":"1.168223928","rc":[{"batb":[[0,3.1,82.54],[1,1.02,2],[2,1.01,3.59]],"ltp":0.0,"tv":0.0,"id":13014431}]}]}
{"op":"mcm","clk":"1009727196","pt":1580646509197,"mc":[{"id":"1.168223928","rc":[{"batb":[[0,2.44,30.29],[1,1.02,2],[2,1.01,3.59]],"ltp":0.0,"tv":0.0,"id":13015339}]}]}
{"op":"mcm","clk":"1009727259","pt":1580646509664,"mc":[{"id":"1.168223928","rc":[{"batb":[[0,3.55,71.99],[1,3.3,30.29],[2,1.02,2]],"ltp":0.0,"tv":0.0,"id":13014431}]}]}
{"op":"mcm","clk":"1009743863","pt":1580646631230,"mc":[{"id":"1.168223928","rc":[{"batb":[[0,2.3,111.68],[1,2.14,30.29],[2,1.02,2]],"ltp":0.0,"tv":0.0,"id":13015339},{"batb":[[0,3.6,30.29],[1,3.55,71.99]],"ltp":0.0,"tv":0.0,"id":13014431}]}]}
{"op":"mcm","clk":"1009743924","pt":1580646631651,"mc":[{"id":"1.168223928","rc":[{"batb":[[0,3.8,67.23],[1,3.6,30.29]],"ltp":0.0,"tv":0.0,"id":13014431}]}]}
{"op":"mcm","clk":"1009761395","pt":1580646753166,"mc":[{"id":"1.168223928","rc":[{"batb":[[0,2.32,30.29],[1,2.3,111.68]],"ltp":0.0,"tv":0.0,"id":13015339}]}]}
{"op":"mcm","clk":"1009761536","pt":1580646754170,"mc":[{"id":"1.168223928","rc":[{"batb":[[0,2.36,108.93],[1,2.32,30.29]],"ltp":0.0,"tv":0.0,"id":13015339},{"batb":[[0,3.9,65.56],[1,3.85,30.29]],"ltp":0.0,"tv":0.0,"id":13014431}]}]}
{"op":"mcm","clk":"1009778076","pt":1580646875022,"mc":[{"id":"1.168223928","rc":[{"batb":[[0,2.38,30.29],[1,2.36,108.93]],"ltp":0.0,"tv":0.0,"id":13015339}]}]}
{"op":"mcm","clk":"1009778145","pt":1580646875501,"mc":[{"id":"1.168223928","rc":[{"batb":[[0,2.4,106.91],[1,2.38,30.29]],"ltp":0.0,"tv":0.0,"id":13015339},{"batb":[[1,1.02,2],[2,1.01,3.59]],"ltp":0.0,"tv":0.0,"id":13014431}]}]}
{"op":"mcm","clk":"1009780898","pt":1580646894960,"mc":[{"id":"1.168223928","rc":[{"batl":[[0,3.6,264.71]],"ltp":0.0,"tv":0.0,"id":13015339}]}]}
{"op":"mcm","clk":"1009794057","pt":1580646997187,"mc":[{"id":"1.168223928","rc":[{"batb":[[0,2.42,136.42],[1,1.02,2],[2,1.01,3.59]],"ltp":0.0,"tv":0.0,"id":13015339}]}]}
{"op":"mcm","clk":"1009811197","pt":1580647118271,"mc":[{"id":"1.168223928","rc":[{"batb":[[0,2.44,30.29],[1,2.42,106.13],[2,1.02,2]],"ltp":0.0,"tv":0.0,"id":13015339}]}]}
{"op":"mcm","clk":"1009811217","pt":1580647118487,"mc":[{"id":"1.168223928","rc":[{"batb":[[1,1.02,2],[2,1.01,3.59]],"ltp":0.0,"tv":0.0,"id":13015339}]}]}
{"op":"mcm","clk":"1009828598","pt":1580647240224,"mc":[{"id":"1.168223928","rc":[{"batb":[[0,2.14,30.29],[1,1.89,136.32],[2,1.02,2]],"ltp":0.0,"tv":0.0,"id":13015339}]}]}
{"op":"mcm","clk":"1009828644","pt":1580647240540,"mc":[{"id":"1.168223928","rc":[{"batb":[[0,2.22,115.84],[1,2.14,30.29]],"ltp":0.0,"tv":0.0,"id":13015339}]}]}
{"op":"mcm","clk":"1009846039","pt":1580647361958,"mc":[{"id":"1.168223928","rc":[{"batb":[[0,2.3,111.68],[1,2.24,30.29]],"ltp":0.0,"tv":0.0,"id":13015339}]}]}
{"op":"mcm","clk":"1009947344","pt":1580648161699,"mc":[{"id":"1.168223928","rc":[{"batb":[[0,3.15,81.23],[1,1.02,2],[2,1.01,1.01]],"batl":[[0,32,77.51]],"ltp":0.0,"tv":0.0,"id":13014430}]}]}
{"op":"mcm","clk":"1009987088","pt":1580648457145,"mc":[{"id":"1.168223928","rc":[{"batb":[[0,2.38,107.96],[1,2.32,30.29]],"ltp":0.0,"tv":0.0,"id":13015339}]}]}
{"op":"mcm","clk":"1010005856","pt":1580648579096,"mc":[{"id":"1.168223928","rc":[{"batb":[[0,2.4,30.29],[1,2.38,107.96]],"ltp":0.0,"tv":0.0,"id":13015339}]}]}
{"op":"mcm","clk":"1010005902","pt":1580648579410,"mc":[{"id":"1.168223928","rc":[{"batb":[[0,2.42,106.13],[1,2.4,30.29]],"ltp":0.0,"tv":0.0,"id":13015339}]}]}
{"op":"mcm","clk":"1010025868","pt":1580648700254,"mc":[{"id":"1.168223928","rc":[{"batb":[[0,2.44,30.29],[1,1.02,2],[2,1.01,3.59]],"ltp":0.0,"tv":0.0,"id":13015339}]}]}
{"op":"mcm","clk":"1010045275","pt":1580648821632,"mc":[{"id":"1.168223928","rc":[{"batb":[[0,2.16,30.29]],"ltp":0.0,"tv":0.0,"id":13015339}]}]}
{"op":"mcm","clk":"1010045713","pt":1580648823828,"mc":[{"id":"1.168223928","rc":[{"batb":[[0,2.24,114.77],[1,2.16,30.29],[2,1.02,2]],"ltp":0.0,"tv":0.0,"id":13015339}]}]}
{"op":"mcm","clk":"1010063917","pt":1580648943249,"mc":[{"id":"1.168223928","rc":[{"batb":[[1,1.02,2],[2,1.01,3.59]],"ltp":0.0,"tv":0.0,"id":13015339}]}]}
{"op":"mcm","clk":"1010063997","pt":1580648943683,"mc":[{"id":"1.168223928","rc":[{"batb":[[0,2.32,110.64],[1,2.26,30.29],[2,1.02,2]],"ltp":0.0,"tv":0.0,"id":13015339}]}]}
{"op":"mcm","clk":"1010082371","pt":1580649065026,"mc":[{"id":"1.168223928","rc":[{"batb":[[0,2.34,30.29],[1,2.32,110.64]],"ltp":0.0,"tv":0.0,"id":13015339}]}]}
{"op":"mcm","clk":"1010082435","pt":1580649065406,"mc":[{"id":"1.168223928","rc":[{"batb":[[0,2.36,108.93],[1,2.34,30.29]],"ltp":0.0,"tv":0.0,"id":13015339}]}]}
{"op":"mcm","clk":"1010102773","pt":1580649186994,"mc":[{"id":"1.168223928","rc":[{"batb":[[0,2.4,106.91],[1,2.38,30.29]],"ltp":0.0,"tv":0.0,"id":13015339}]}]}
{"op":"mcm","clk":"1010124963","pt":1580649308869,"mc":[{"id":"1.168223928","rc":[{"batb":[[0,2.42,136.42],[1,1.02,2],[2,1.01,3.59]],"ltp":0.0,"tv":0.0,"id":13015339}]}]}
{"op":"mcm","clk":"1010146728","pt":1580649430171,"mc":[{"id":"1.168223928","rc":[{"batb":[[0,2.42,106.13]],"ltp":0.0,"tv":0.0,"id":13015339}]}]}
{"op":"mcm","clk":"1010146816","pt":1580649430563,"mc":[{"id":"1.168223928","rc":[{"batb":[[0,2.44,30.29]],"ltp":0.0,"tv":0.0,"id":13015339}]}]}
{"op":"mcm","clk":"1010165283","pt":1580649552228,"mc":[{"id":"1.168223928","rc":[{"batb":[[0,2.16,30.29]],"ltp":0.0,"tv":0.0,"id":13015339}]}]}
{"op":"mcm","clk":"1010165316","pt":1580649552394,"mc":[{"id":"1.168223928","rc":[{"batb":[[0,2.32,110.64],[1,2.16,30.29],[2,1.02,2]],"ltp":0.0,"tv":0.0,"id":13015339}]}]}
{"op":"mcm","clk":"1010183519","pt":1580649674175,"mc":[{"id":"1.168223928","rc":[{"batb":[[0,2.36,108.93],[1,2.34,30.29]],"ltp":0.0,"tv":0.0,"id":13015339}]}]}
{"op":"mcm","clk":"1010201081","pt":1580649795033,"mc":[{"id":"1.168223928","rc":[{"batb":[[0,2.38,30.29],[1,2.36,108.93]],"ltp":0.0,"tv":0.0,"id":13015339}]}]}
{"op":"mcm","clk":"1010201147","pt":1580649795544,"mc":[{"id":"1.168223928","rc":[{"batb":[[0,2.4,106.91],[1,2.38,30.29]],"ltp":0.0,"tv":0.0,"id":13015339}]}]}
{"op":"mcm","clk":"1010218689","pt":1580649917083,"mc":[{"id":"1.168223928","rc":[{"batb":[[0,2.42,136.42],[1,1.02,2],[2,1.01,3.59]],"ltp":0.0,"tv":0.0,"id":13015339}]}]}
{"op":"mcm","clk":"1010236221","pt":1580650038721,"mc":[{"id":"1.168223928","rc":[{"batb":[[0,2.44,30.29]],"ltp":0.0,"tv":0.0,"id":13015339}]}]}
{"op":"mcm","clk":"1010242208","pt":1580650080807,"mc":[{"id":"1.168223928","rc":[{"batb":[[0,2.98,85.9]],"ltp":0.0,"tv":0.0,"id":13014431}]}]}
{"op":"mcm","clk":"1010254677","pt":1580650161210,"mc":[{"id":"1.168223928","rc":[{"batb":[[0,2.18,30.29]],"ltp":0.0,"tv":0.0,"id":13015339},{"batb":[[0,3.25,30.29],[1,2.98,85.9],[2,1.02,2]],"ltp":0.0,"tv":0.0,"id":13014431}]}]}
{"op":"mcm","clk":"1010255026","pt":1580650163200,"mc":[{"id":"1.168223928","rc":[{"batb":[[0,2.2,116.72],[1,2.18,30.29],[2,1.02,2]],"ltp":0.0,"tv":0.0,"id":13015339},{"batb":[[1,1.02,2],[2,1.01,3.59]],"ltp":0.0,"tv":0.0,"id":13014431}]}]}
{"op":"mcm","clk":"1010255047","pt":1580650163301,"mc":[{"id":"1.168223928","rc":[{"batb":[[0,3.4,75.21],[1,3.25,30.29],[2,1.02,2]],"batl":[[0,13.5,191.27]],"ltp":0.0,"tv":0.0,"id":13014431}]}]}
{"op":"mcm","clk":"1010276090","pt":1580650281764,"mc":[{"id":"1.168223928","rc":[{"batb":[[0,2.22,30.29],[1,2.2,116.72]],"ltp":0.0,"tv":0.0,"id":13015339}]}]}
{"op":"mcm","clk":"1010276266","pt":1580650282758,"mc":[{"id":"1.168223928","rc":[{"batb":[[0,2.26,113.71],[1,2.22,30.29]],"ltp":0.0,"tv":0.0,"id":13015339},{"batb":[[0,3.65,70.13],[1,3.45,30.29]],"ltp":0.0,"tv":0.0,"id":13014431}]}]}
{"op":"mcm","clk":"1010296914","pt":1580650404056,"mc":[{"id":"1.168223928","rc":[{"batb":[[0,2.32,110.64],[1,2.28,30.29]],"ltp":0.0,"tv":0.0,"id":13015339},{"batb":[[0,3.7,30.29],[1,3.65,70.13]],"ltp":0.0,"tv":0.0,"id":13014431}]}]}
{"op":"mcm","clk":"1010296993","pt":1580650404540,"mc":[{"id":"1.168223928","rc":[{"batb":[[0,3.8,67.23],[1,3.7,30.29]],"ltp":0.0,"tv":0.0,"id":13014431}]}]}
{"op":"mcm","clk":"1010312633","pt":1580650495217,"mc":[{"id":"1.168223928","rc":[{"batl":[[0,4.7,202.95]],"ltp":0.0,"tv":0.0,"id":13015339}]}]}
{"op":"mcm","clk":"1010317698","pt":1580650525156,"mc":[{"id":"1.168223928","rc":[{"batb":[[0,2.34,30.29],[1,2.32,110.64]],"ltp":0.0,"tv":0.0,"id":13015339}]}]}
{"op":"mcm","clk":"1010317883","pt":1580650526272,"mc":[{"id":"1.168223928","rc":[{"batb":[[0,2.38,107.96],[1,2.34,30.29]],"ltp":0.0,"tv":0.0,"id":13015339},{"batb":[[0,3.9,65.56],[1,3.85,30.29]],"ltp":0.0,"tv":0.0,"id":13014431}]}]}
{"op":"mcm","clk":"1010330576","pt":1580650603242,"mc":[{"id":"1.168223928","rc":[{"batl":[[0,4.7,207.25]],"ltp":0.0,"tv":0.0,"id":13015339},{"batb":[[0,3.85,96.66],[1,1.02,2],[2,1.01,3.59]],"batl":[[0,13.5,19.01]],"ltp":0.0,"tv":0.0,"id":13014431}]}]}
{"op":"mcm","clk":"1010337717","pt":1580650647223,"mc":[{"id":"1.168223928","rc":[{"batb":[[0,2.4,30.29],[1,1.02,2],[2,1.01,3.59]],"ltp":0.0,"tv":0.0,"id":13015339},{"batb":[[0,3.85,66.37]],"ltp":0.0,"tv":0.0,"id":13014431}]}]}
{"op":"mcm","clk":"1010337809","pt":1580650647800,"mc":[{"id":"1.168223928","rc":[{"batb":[[0,2.42,106.13],[1,2.4,30.29],[2,1.02,2]],"ltp":0.0,"tv":0.0,"id":13015339},{"batb":[[0,3.9,30.29]],"ltp":0.0,"tv":0.0,"id":13014431}]}]}
{"op":"mcm","clk":"1010356506","pt":1580650763167,"mc":[{"id":"1.168223928","rc":[{"batl":[[0,13.5,192.21]],"ltp":0.0,"tv":0.0,"id":13014431}]}]}
{"op":"mcm","clk":"1010357433","pt":1580650769174,"mc":[{"id":"1.168223928","rc":[{"batb":[[0,2.44,30.29],[1,1.02,2],[2,1.01,3.59]],"ltp":0.0,"tv":0.0,"id":13015339},{"batb":[[0,3.15,30.29]],"ltp":0.0,"tv":0.0,"id":13014431}]}]}
{"op":"mcm","clk":"1010357518","pt":1580650769592,"mc":[{"id":"1.168223928","rc":[{"batb":[[0,3.25,78.73],[1,3.15,30.29],[2,1.02,2]],"ltp":0.0,"tv":0.0,"id":13014431}]}]}
{"op":"mcm","clk":"1010377123","pt":1580650891017,"mc":[{"id":"1.168223928","rc":[{"batb":[[0,2.24,30.29]],"ltp":0.0,"tv":0.0,"id":13015339}]}]}
{"op":"mcm","clk":"1010377287","pt":1580650891992,"mc":[{"id":"1.168223928","rc":[{"batb":[[0,2.26,113.71],[1,2.24,30.29],[2,1.02,2]],"ltp":0.0,"tv":0.0,"id":13015339},{"batb":[[0,3.65,70.13],[1,3.3,30.29]],"ltp":0.0,"tv":0.0,"id":13014431}]}]}
{"op":"mcm","clk":"1010397473","pt":1580651012257,"mc":[{"id":"1.168223928","rc":[{"batb":[[0,2.36,108.93],[1,2.28,30.29]],"ltp":0.0,"tv":0.0,"id":13015339},{"batb":[[1,1.02,2],[2,1.01,3.59]],"ltp":0.0,"tv":0.0,"id":13014431}]}]}
{"op":"mcm","clk":"1010397545","pt":1580651012770,"mc":[{"id":"1.168223928","rc":[{"batb":[[0,3.8,67.23],[1,3.7,30.29],[2,1.02,2]],"ltp":0.0,"tv":0.0,"id":13014431}]}]}
{"op":"mcm","clk":"1010401561","pt":1580651036780,"mc":[{"id":"1.168223928","rc":[{"batl":[[0,4.7,54.95]],"ltp":0.0,"tv":0.0,"id":13015339},{"batb":[[0,2.74,93.52],[1,1.02,2],[2,1.01,1.01]],"batl":[[0,11.5,226.77]],"ltp":0.0,"tv":0.0,"id":13015338},{"batl":[[0,13.5,19.01]],"ltp":0.0,"tv":0.0,"id":13014431},{"batl":[[0,32,78.01]],"ltp":0.0,"tv":0.0,"id":13014430}]}]}
{"op":"mcm","clk":"1010405838","pt":1580651063338,"mc":[{"id":"1.168223928","rc":[{"batl":[[0,13.5,193.44]],"ltp":0.0,"tv":0.0,"id":13014431}]}]}
{"op":"mcm","clk":"1010410365","pt":1580651089848,"mc":[{"id":"1.168223928","rc":[{"batl":[[0,11.5,22.35]],"ltp":0.0,"tv":0.0,"id":13015338},{"batb":[[0,3.75,68.15]],"ltp":0.0,"tv":0.0,"id":13014431},{"batl":[[0,32,8.13]],"ltp":0.0,"tv":0.0,"id":13014430}]}]}
{"op":"mcm","clk":"1010411403","pt":1580651095981,"mc":[{"id":"1.168223928","rc":[{"batl":[[0,4.7,231.45]],"ltp":0.0,"tv":0.0,"id":13015339}]}]}
{"op":"mcm","clk":"1010418217","pt":1580651133853,"mc":[{"id":"1.168223928","rc":[{"batb":[[1,1.02,2],[2,1.01,3.59]],"ltp":0.0,"tv":0.0,"id":13015339},{"batb":[[1,1.02,2],[2,1.01,3.59]],"ltp":0.0,"tv":0.0,"id":13014431}]}]}
{"op":"mcm","clk":"1010423318","pt":1580651162021,"mc":[{"id":"1.168223928","rc":[{"batl":[[0,32,78.28]],"ltp":0.0,"tv":0.0,"id":13014430}]}]}
{"op":"mcm","clk":"1010427814","pt":1580651184010,"mc":[{"id":"1.168223928","rc":[{"batb":[[0,2.58,99.56]],"batl":[[0,13.5,19.01]],"ltp":0.0,"tv":0.0,"id":13014431}]}]}
{"op":"mcm","clk":"1010454919","pt":1580651336498,"mc":[{"id":"1.168223928","rc":[{"batl":[[0,11.5,225.61]],"ltp":0.0,"tv":0.0,"id":13015338}]}]}
{"op":"mcm","clk":"1010457926","pt":1580651355000,"mc":[{"id":"1.168223928","rc":[{"batl":[[0,11.5,22.35]],"ltp":0.0,"tv":0.0,"id":13015338},{"batl":[[0,32,8.13]],"ltp":0.0,"tv":0.0,"id":13014430}]}]}
{"op":"mcm","clk":"1010459322","pt":1580651363745,"mc":[{"id":"1.168223928","rc":[{"batl":[[0,13.5,193.44]],"ltp":0.0,"tv":0.0,"id":13014431}]}]}
{"op":"mcm","clk":"1010475280","pt":1580651466358,"mc":[{"id":"1.168223928","rc":[{"batl":[[0,32,78.28]],"ltp":0.0,"tv":0.0,"id":13014430}]}]}
{"op":"mcm","clk":"1010483784","pt":1580651523386,"mc":[{"id":"1.168223928","rc":[{"batl":[[0,13.5,19.01]],"ltp":0.0,"tv":0.0,"id":13014431}]}]}
{"op":"mcm","clk":"1010500345","pt":1580651636154,"mc":[{"id":"1.168223928","rc":[{"batl":[[0,11.5,225.61]],"ltp":0.0,"tv":0.0,"id":13015338}]}]}
{"op":"mcm","clk":"1010504503","pt":1580651663307,"mc":[{"id":"1.168223928","rc":[{"batl":[[0,13.5,194.48]],"ltp":0.0,"tv":0.0,"id":13014431}]}]}
{"op":"mcm","clk":"1010518301","pt":1580651762269,"mc":[{"id":"1.168223928","rc":[{"batb":[[0,1.02,2],[1,1.01,1.01],[2,1.01,0]],"batl":[[0,21,119.24]],"ltp":0.0,"tv":0.0,"id":13014430}]}]}
{"op":"mcm","clk":"1010520776","pt":1580651777993,"mc":[{"id":"1.168223928","rc":[{"batl":[[0,13.5,19.01]],"ltp":0.0,"tv":0.0,"id":13014431}]}]}
{"op":"mcm","clk":"1010549720","pt":1580651963386,"mc":[{"id":"1.168223928","rc":[{"batl":[[0,13.5,193.44]],"ltp":0.0,"tv":0.0,"id":13014431}]}]}
{"op":"mcm","clk":"1010561478","pt":1580652031868,"mc":[{"id":"1.168223928","rc":[{"batb":[[0,3.45,74.21],[1,1.6,2],[2,1.02,2]],"ltp":0.0,"tv":0.0,"id":13014430}]}]}
{"op":"mcm","clk":"1010690733","pt":1580652620966,"mc":[{"id":"1.168223928","rc":[{"batl":[[0,11.5,22.35]],"ltp":0.0,"tv":0.0,"id":13015338},{"batl":[[0,21,12.38]],"ltp":0.0,"tv":0.0,"id":13014430}]}]}
{"op":"mcm","clk":"1010693009","pt":1580652630897,"mc":[{"id":"1.168223928","rc":[{"batb":[[1,1.02,2],[2,1.01,1.01]],"ltp":0.0,"tv":0.0,"id":13014430}]}]}
{"op":"mcm","clk":"1010700043","pt":1580652662430,"mc":[{"id":"1.168223928","rc":[{"batl":[[0,21,118.83]],"ltp":0.0,"tv":0.0,"id":13014430}]}]}
{"op":"mcm","clk":"1010739611","pt":1580652836442,"mc":[{"id":"1.168223928","rc":[{"batl":[[0,11.5,226.77]],"ltp":0.0,"tv":0.0,"id":13015338}]}]}
{"op":"mcm","clk":"1010936023","pt":1580653764683,"mc":[{"id":"1.168223928","rc":[{"batl":[[0,12.5,208.65]],"ltp":0.0,"tv":0.0,"id":13014431}]}]}
{"op":"mcm","clk":"1010940829","pt":1580653785754,"mc":[{"id":"1.168223928","rc":[{"batl":[[0,4.7,54.95]],"ltp":0.0,"tv":0.0,"id":13015339}]}]}
{"op":"mcm","clk":"1010943020","pt":1580653795809,"mc":[{"id":"1.168223928","rc":[{"batl":[[0,4.7,220.5]],"ltp":0.0,"tv":0.0,"id":13015339}]}]}
{"op":"mcm","clk":"1010958447","pt":1580653872080,"mc":[{"id":"1.168223928","rc":[{"batb":[[0,2.38,2]],"ltp":0.0,"tv":0.0,"id":13015339},{"batb":[[0,2.76,2]],"ltp":0.0,"tv":0.0,"id":13015338},{"batb":[[0,2.6,2]],"ltp":0.0,"tv":0.0,"id":13014431},{"batb":[[0,3.5,2],[1,3.45,74.21],[2,1.02,2]],"ltp":0.0,"tv":0.0,"id":13014430}]}]}
{"op":"mcm","clk":"1010958547","pt":1580653872494,"mc":[{"id":"1.168223928","rc":[{"batb":[[0,2.4,106.91],[1,2.38,2],[2,1.02,2]],"ltp":0.0,"tv":0.0,"id":13015339},{"batb":[[0,2.9,88.36],[1,2.76,2],[2,1.02,2]],"ltp":0.0,"tv":0.0,"id":13015338},{"batb":[[0,2.74,93.52],[1,2.6,2],[2,1.02,2]],"ltp":0.0,"tv":0.0,"id":13014431},{"batb":[[0,3.75,68.11],[1,3.5,2]],"ltp":0.0,"tv":0.0,"id":13014430}]}]}
{"op":"mcm","clk":"1011008714","pt":1580654096012,"mc":[{"id":"1.168223928","rc":[{"batl":[[0,4.9,211.35]],"ltp":0.0,"tv":0.0,"id":13015339}]}]}
{"op":"mcm","clk":"1011071130","pt":1580654370082,"mc":[{"id":"1.168223928","rc":[{"batb":[[0,3.05,84.09]],"ltp":0.0,"tv":0.0,"id":13014431}]}]}
{"op":"mcm","clk":"1011093038","pt":1580654471095,"mc":[{"id":"1.168223928","rc":[{"batb":[[1,1.02,2],[2,1.01,3.59]],"ltp":0.0,"tv":0.0,"id":13014431}]}]}
{"op":"mcm","clk":"1011093199","pt":1580654471908,"mc":[{"id":"1.168223928","rc":[{"batb":[[1,1.02,2],[2,1.01,3.59]],"ltp":0.0,"tv":0.0,"id":13015339},{"batb":[[1,1.02,2],[2,1.01,1.01]],"ltp":0.0,"tv":0.0,"id":13015338},{"batb":[[1,1.02,2],[2,1.01,1.01]],"ltp":0.0,"tv":0.0,"id":13014430}]}]}
{"op":"mcm","clk":"1011097699","pt":1580654491945,"mc":[{"id":"1.168223928","rc":[{"batb":[[0,2.1,122.34]],"ltp":0.0,"tv":0.0,"id":13015339}]}]}
{"op":"mcm","clk":"1011123345","pt":1580654608086,"mc":[{"id":"1.168223928","rc":[{"batl":[[0,4.9,52.65]],"ltp":0.0,"tv":0.0,"id":13015339}]}]}
{"op":"mcm","clk":"1011130137","pt":1580654637940,"mc":[{"id":"1.168223928","rc":[{"batb":[[0,2.64,97.32]],"batl":[[0,9.6,271.61]],"ltp":0.0,"tv":0.0,"id":13015338}]}]}
{"op":"mcm","clk":"1011137530","pt":1580654670070,"mc":[{"id":"1.168223928","rc":[{"batl":[[0,21,12.38]],"ltp":0.0,"tv":0.0,"id":13014430}]}]}
{"op":"mcm","clk":"1011143073","pt":1580654696290,"mc":[{"id":"1.168223928","rc":[{"batl":[[0,4.9,207.15]],"ltp":0.0,"tv":0.0,"id":13015339}]}]}
{"op":"mcm","clk":"1011157263","pt":1580654762365,"mc":[{"id":"1.168223928","rc":[{"batl":[[0,21,118.07]],"ltp":0.0,"tv":0.0,"id":13014430}]}]}
{"op":"mcm","clk":"1011219631","pt":1580655112527,"mc":[{"id":"1.168223928","marketDefinition":{"bspMarket":false,"turnInPlayEnabled":true,"persistenceEnabled":true,"marketBaseRate":5.0,"eventId":"29681623","eventTypeId":"2","numberOfWinners":1,"bettingType":"ODDS","marketType":"SET_BETTING","marketTime":"2020-02-02T14:50:00.000Z","suspendTime":"2020-02-02T14:50:00.000Z","bspReconciled":false,"complete":true,"inPlay":false,"crossMatching":true,"runnersVoidable":false,"numberOfActiveRunners":4,"betDelay":0,"status":"OPEN","runners":[{"status":"ACTIVE","sortPriority":1,"id":13015339,"name":"Janvier 2-0"},{"status":"ACTIVE","sortPriority":2,"id":13015338,"name":"Janvier 2-1"},{"status":"ACTIVE","sortPriority":3,"id":13014431,"name":"Ilkel 2-0"},{"status":"ACTIVE","sortPriority":4,"id":13014430,"name":"Ilkel 2-1"}],"regulators":["MR_INT"],"countryCode":"FR","discountAllowed":true,"timezone":"UTC","openDate":"2020-02-02T15:00:00.000Z","version":3149299566,"name":"Set Betting","eventName":"Janvier v Ilkel"}}]}
{"op":"mcm","clk":"1011220310","pt":1580655116547,"mc":[{"id":"1.168223928","marketDefinition":{"bspMarket":false,"turnInPlayEnabled":true,"persistenceEnabled":true,"marketBaseRate":5.0,"eventId":"29681623","eventTypeId":"2","numberOfWinners":1,"bettingType":"ODDS","marketType":"SET_BETTING","marketTime":"2020-02-02T14:50:00.000Z","suspendTime":"2020-02-02T14:50:00.000Z","bspReconciled":false,"complete":true,"inPlay":false,"crossMatching":true,"runnersVoidable":false,"numberOfActiveRunners":4,"betDelay":0,"status":"OPEN","runners":[{"status":"ACTIVE","sortPriority":1,"id":13015339,"name":"Janvier 2-0"},{"status":"ACTIVE","sortPriority":2,"id":13015338,"name":"Janvier 2-1"},{"status":"ACTIVE","sortPriority":3,"id":13014431,"name":"Ilkel 2-0"},{"status":"ACTIVE","sortPriority":4,"id":13014430,"name":"Ilkel 2-1"}],"regulators":["MR_INT"],"countryCode":"FR","discountAllowed":true,"timezone":"UTC","openDate":"2020-02-02T14:50:00.000Z","version":3149299566,"name":"Set Betting","eventName":"Janvier v Ilkel"}}]}
{"op":"mcm","clk":"1011226539","pt":1580655155656,"mc":[{"id":"1.168223928","rc":[{"batb":[[0,2.76,23.53],[1,2.1,122.34],[2,1.02,2]],"batl":[[0,3,23.13],[1,4.9,207.15]],"ltp":0.0,"tv":0.0,"id":13015339},{"batb":[[0,4.4,37.53],[1,2.64,97.32],[2,1.02,2]],"batl":[[0,5,35.8],[1,9.6,271.61]],"ltp":0.0,"tv":0.0,"id":13015338},{"batb":[[0,3.7,28.33],[1,3.05,84.09],[2,1.02,2]],"batl":[[0,4.1,27.54],[1,12.5,208.65]],"ltp":0.0,"tv":0.0,"id":13014431},{"batb":[[0,5.1,26.52],[1,3.75,68.11],[2,1.02,2]],"batl":[[0,5.9,25.49],[1,21,118.07]],"ltp":0.0,"tv":0.0,"id":13014430}]}]}
{"op":"mcm","clk":"1011228993","pt":1580655169909,"mc":[{"id":"1.168223928","rc":[{"batb":[[1,1.02,2],[2,1.01,3.59]],"batl":[[1,4.9,0]],"ltp":0.0,"tv":0.0,"id":13015339},{"batb":[[1,1.02,2],[2,1.01,1.01]],"batl":[[1,9.6,0]],"ltp":0.0,"tv":0.0,"id":13015338},{"batb":[[0,3.75,68.11],[1,3.7,28.33]],"batl":[[1,12.5,0]],"ltp":0.0,"tv":0.0,"id":13014431},{"batb":[[1,1.02,2],[2,1.01,1.01]],"batl":[[1,21,0]],"ltp":0.0,"tv":0.0,"id":13014430}]}]}
{"op":"mcm","clk":"1011251950","pt":1580655310859,"mc":[{"id":"1.168223928","rc":[{"batl":[[0,4.2,27.46]],"ltp":0.0,"tv":0.0,"id":13014431}]}]}
{"op":"mcm","clk":"1011270590","pt":1580655427103,"mc":[{"id":"1.168223928","rc":[{"trd":[[2.76,87.19]],"batb":[[0,1.02,2],[1,1.01,3.59],[2,1.01,0]],"batl":[[0,2.76,159.06],[1,3,23.13]],"ltp":2.76,"tv":87.19,"id":13015339}],"tv":87.19}]}
{"op":"mcm","clk":"1011270700","pt":1580655427788,"mc":[{"id":"1.168223928","rc":[{"batb":[[0,2.74,23.92],[1,1.02,2],[2,1.01,3.59]],"batl":[[1,2.98,23.53]],"ltp":2.76,"tv":87.19,"id":13015339},{"batb":[[0,4.4,37.22]],"batl":[[0,5,35.49]],"ltp":0.0,"tv":0.0,"id":13015338},{"batb":[[1,3.7,28.09]],"batl":[[0,4.2,27.22]],"ltp":0.0,"tv":0.0,"id":13014431},{"batb":[[0,5.1,26.28]],"batl":[[0,5.9,25.26]],"ltp":0.0,"tv":0.0,"id":13014430}]}]}
{"op":"mcm","clk":"1011272134","pt":1580655437917,"mc":[{"id":"1.168223928","rc":[{"batl":[[1,2.9,23.53]],"ltp":2.76,"tv":87.19,"id":13015339},{"batb":[[0,3.75,96.2],[1,1.02,2],[2,1.01,3.59]],"batl":[[0,4.1,27.22]],"ltp":0.0,"tv":0.0,"id":13014431}]}]}
{"op":"mcm","clk":"1011280830","pt":1580655497778,"mc":[{"id":"1.168223928","rc":[{"batb":[[0,4.5,2],[1,4.4,37.22],[2,1.02,2]],"ltp":0.0,"tv":0.0,"id":13015338},{"batb":[[0,3.8,2],[1,3.75,96.2],[2,1.02,2]],"ltp":0.0,"tv":0.0,"id":13014431},{"batb":[[0,5.2,2],[1,5.1,26.28],[2,1.02,2]],"ltp":0.0,"tv":0.0,"id":13014430}]}]}
{"op":"mcm","clk":"1011289917","pt":1580655557080,"mc":[{"id":"1.168223928","rc":[{"batb":[[0,4.4,37.22],[1,1.02,2],[2,1.01,1.01]],"ltp":0.0,"tv":0.0,"id":13015338}]}]}
{"op":"mcm","clk":"1011290039","pt":1580655557796,"mc":[{"id":"1.168223928","rc":[{"batb":[[0,3.75,96.2],[1,1.02,2],[2,1.01,3.59]],"ltp":0.0,"tv":0.0,"id":13014431},{"batb":[[0,5.1,26.28],[1,1.02,2],[2,1.01,1.01]],"ltp":0.0,"tv":0.0,"id":13014430}]}]}
{"op":"mcm","clk":"1011293108","pt":1580655576590,"mc":[{"id":"1.168223928","rc":[{"trd":[[2.76,405.16]],"batl":[[0,2.9,23.6],[1,2.9,0]],"ltp":2.76,"tv":405.15,"id":13015339}],"tv":405.15}]}
{"op":"mcm","clk":"1011294830","pt":1580655587128,"mc":[{"id":"1.168223928","rc":[{"batl":[[0,2.9,23.53]],"ltp":2.76,"tv":405.15,"id":13015339}]}]}
{"op":"mcm","clk":"1011296618","pt":1580655597997,"mc":[{"id":"1.168223928","rc":[{"trd":[[2.74,40.53]],"batb":[[0,2.74,3.65]],"ltp":2.74,"tv":445.69,"id":13015339}],"tv":445.69}]}
{"op":"mcm","clk":"1011296747","pt":1580655598853,"mc":[{"id":"1.168223928","rc":[{"batb":[[0,2.74,24.35]],"batl":[[0,2.88,23.84]],"ltp":2.74,"tv":445.69,"id":13015339},{"batb":[[0,4.4,36.98]],"batl":[[0,5,35.25]],"ltp":0.0,"tv":0.0,"id":13015338},{"batb":[[0,3.8,27.85],[1,3.75,68.11],[2,1.02,2]],"batl":[[0,4.1,27.07]],"ltp":0.0,"tv":0.0,"id":13014431},{"batb":[[0,5.2,26.12]],"batl":[[0,5.9,25.1]],"ltp":0.0,"tv":0.0,"id":13014430}]}]}
{"op":"mcm","clk":"1011300484","pt":1580655618962,"mc":[{"id":"1.168223928","rc":[{"batb":[[0,2.72,24.63]],"ltp":2.74,"tv":445.69,"id":13015339},{"batb":[[0,3.8,27.38]],"batl":[[0,4.2,26.59]],"ltp":0.0,"tv":0.0,"id":13014431},{"batb":[[0,5.2,25.65]],"batl":[[0,5.9,24.71]],"ltp":0.0,"tv":0.0,"id":13014430}]}]}
{"op":"mcm","clk":"1011301210","pt":1580655623088,"mc":[{"id":"1.168223928","rc":[{"batl":[[0,2.74,6.75],[1,2.88,23.84]],"ltp":2.74,"tv":445.69,"id":13015339}]}]}
{"op":"mcm","clk":"1011302159","pt":1580655629112,"mc":[{"id":"1.168223928","rc":[{"batb":[[0,2.7,24.94]],"batl":[[1,2.86,24.47]],"ltp":2.74,"tv":445.69,"id":13015339},{"batb":[[0,3.8,27.07]],"ltp":0.0,"tv":0.0,"id":13014431},{"batb":[[0,5.2,25.34]],"batl":[[0,5.9,24.39]],"ltp":0.0,"tv":0.0,"id":13014430}]}]}
{"op":"mcm","clk":"1011321288","pt":1580655734260,"mc":[{"id":"1.168223928","rc":[{"trd":[[4.2,4.88]],"batb":[[0,3.85,26.99],[1,3.8,27.07],[2,3.75,68.11]],"batl":[[0,4.2,52.4]],"ltp":4.2,"tv":4.87,"id":13014431}],"tv":450.56}]}
{"op":"mcm","clk":"1011321331","pt":1580655734483,"mc":[{"id":"1.168223928","rc":[{"batb":[[1,3.75,68.11],[2,1.02,2]],"ltp":4.2,"tv":4.87,"id":13014431}]}]}
{"op":"mcm","clk":"1011340122","pt":1580655827647,"mc":[{"id":"1.168223928","rc":[{"batb":[[0,3.85,93.36],[1,1.02,2],[2,1.01,3.59]],"ltp":4.2,"tv":4.87,"id":13014431}]}]}
{"op":"mcm","clk":"1011347240","pt":1580655861093,"mc":[{"id":"1.168223928","rc":[{"batb":[[0,3.85,26.99]],"ltp":4.2,"tv":4.87,"id":13014431}]}]}
{"op":"mcm","clk":"1011354314","pt":1580655892447,"mc":[{"id":"1.168223928","rc":[{"batb":[[0,4.5,2],[1,4.4,36.98],[2,1.02,2]],"ltp":0.0,"tv":0.0,"id":13015338},{"batb":[[0,5.3,2],[1,5.2,25.34],[2,1.02,2]],"ltp":0.0,"tv":0.0,"id":13014430}]}]}
{"op":"mcm","clk":"1011367772","pt":1580655951996,"mc":[{"id":"1.168223928","rc":[{"batb":[[0,4.4,36.98],[1,1.02,2],[2,1.01,1.01]],"ltp":0.0,"tv":0.0,"id":13015338}]}]}
{"op":"mcm","clk":"1011367826","pt":1580655952310,"mc":[{"id":"1.168223928","rc":[{"batb":[[0,5.2,25.34],[1,1.02,2],[2,1.01,1.01]],"ltp":0.0,"tv":0.0,"id":13014430}]}]}
{"op":"mcm","clk":"1011374210","pt":1580655980098,"mc":[{"id":"1.168223928","rc":[{"batl":[[0,2.86,24.47],[1,2.86,0]],"ltp":2.74,"tv":445.69,"id":13015339}]}]}
{"op":"mcm","clk":"1011374254","pt":1580655980281,"mc":[{"id":"1.168223928","rc":[{"trd":[[2.7,13.51]],"batb":[[0,2.7,18.19]],"ltp":2.7,"tv":459.2,"id":13015339}],"tv":464.07}]}
{"op":"mcm","clk":"1011374489","pt":1580655981284,"mc":[{"id":"1.168223928","rc":[{"batl":[[0,4.2,52.24]],"ltp":4.2,"tv":4.87,"id":13014431}]}]}
{"op":"mcm","clk":"1011433414","pt":1580656221889,"mc":[{"id":"1.168223928","rc":[{"trd":[[4.2,54.88]],"batl":[[0,4.2,27.24]],"ltp":4.2,"tv":54.88,"id":13014431}],"tv":514.08}]}
{"op":"mcm","clk":"1011433624","pt":1580656222882,"mc":[{"id":"1.168223928","rc":[{"batb":[[0,2.68,25.34]],"batl":[[0,2.84,24.86]],"ltp":2.7,"tv":459.2,"id":13015339},{"batb":[[0,3.9,26.52]],"batl":[[0,4.3,50.04]],"ltp":4.2,"tv":54.88,"id":13014431}]}]}
{"op":"mcm","clk":"1011445515","pt":1580656269630,"mc":[{"id":"1.168223928","rc":[{"batb":[[0,2.7,24.94]],"batl":[[0,2.86,24.47]],"ltp":2.7,"tv":459.2,"id":13015339},{"batb":[[0,3.85,27.07]],"ltp":4.2,"tv":54.88,"id":13014431}]}]}
{"op":"mcm","clk":"1011453879","pt":1580656303983,"mc":[{"id":"1.168223928","rc":[{"batb":[[0,2.72,24.47]],"batl":[[0,2.88,24.08]],"ltp":2.7,"tv":459.2,"id":13015339},{"batl":[[0,4.2,26.44]],"ltp":4.2,"tv":54.88,"id":13014431},{"batb":[[0,5.1,26.59]],"batl":[[0,5.8,25.49]],"ltp":0.0,"tv":0.0,"id":13014430}]}]}
{"op":"mcm","clk":"1011457746","pt":1580656320007,"mc":[{"id":"1.168223928","rc":[{"batb":[[0,1.02,2],[1,1.01,3.59],[2,1.01,0]],"ltp":2.7,"tv":459.2,"id":13015339},{"batb":[[0,1.02,2],[1,1.01,1.01],[2,1.01,0]],"ltp":0.0,"tv":0.0,"id":13015338},{"batb":[[0,1.02,2],[1,1.01,3.59],[2,1.01,0]],"ltp":4.2,"tv":54.88,"id":13014431},{"batb":[[0,1.02,2],[1,1.01,1.01],[2,1.01,0]],"ltp":0.0,"tv":0.0,"id":13014430}]}]}
{"op":"mcm","clk":"1011457918","pt":1580656320833,"mc":[{"id":"1.168223928","marketDefinition":{"bspMarket":false,"turnInPlayEnabled":true,"persistenceEnabled":true,"marketBaseRate":5.0,"eventId":"29681623","eventTypeId":"2","numberOfWinners":1,"bettingType":"ODDS","marketType":"SET_BETTING","marketTime":"2020-02-02T14:50:00.000Z","suspendTime":"2020-02-02T14:50:00.000Z","bspReconciled":false,"complete":true,"inPlay":true,"crossMatching":true,"runnersVoidable":false,"numberOfActiveRunners":4,"betDelay":3,"status":"OPEN","runners":[{"status":"ACTIVE","sortPriority":1,"id":13015339,"name":"Janvier 2-0"},{"status":"ACTIVE","sortPriority":2,"id":13015338,"name":"Janvier 2-1"},{"status":"ACTIVE","sortPriority":3,"id":13014431,"name":"Ilkel 2-0"},{"status":"ACTIVE","sortPriority":4,"id":13014430,"name":"Ilkel 2-1"}],"regulators":["MR_INT"],"countryCode":"FR","discountAllowed":true,"timezone":"UTC","openDate":"2020-02-02T14:50:00.000Z","version":3149418513,"name":"Set Betting","eventName":"Janvier v Ilkel"},"rc":[{"batb":[[0,1.01,1.41],[1,1.01,0]],"ltp":2.7,"tv":459.2,"id":13015339},{"batb":[[0,1.01,0.51],[1,1.01,0]],"ltp":0.0,"tv":0.0,"id":13015338},{"batb":[[0,1.01,1.41],[1,1.01,0]],"ltp":4.2,"tv":54.88,"id":13014431},{"batb":[[0,1.01,0.51],[1,1.01,0]],"ltp":0.0,"tv":0.0,"id":13014430}]}]}
{"op":"mcm","clk":"1011463066","pt":1580656340969,"mc":[{"id":"1.168223928","rc":[{"batb":[[0,2.58,28.25],[1,2.48,31.71],[2,1.01,1.41]],"batl":[[0,2.72,27.7],[1,2.96,22.35]],"ltp":2.7,"tv":459.2,"id":13015339},{"batb":[[0,4.4,37.45],[1,1.01,0.51]],"batl":[[0,5.1,33.75]],"ltp":0.0,"tv":0.0,"id":13015338},{"batb":[[0,4.1,47.13],[1,3.7,29.35],[2,1.01,1.41]],"batl":[[0,4.5,44.61],[1,4.8,38.32]],"ltp":4.2,"tv":54.88,"id":13014431},{"batb":[[0,5.1,26.91],[1,1.01,0.51]],"batl":[[0,5.9,25.1]],"ltp":0.0,"tv":0.0,"id":13014430}]}]}
{"op":"mcm","clk":"1011466762","pt":1580656355815,"mc":[{"id":"1.168223928","rc":[{"batb":[[0,2.48,31.71],[1,1.01,1.41],[2,1.01,0]],"batl":[[0,2.96,22.35],[1,2.96,0]],"ltp":2.7,"tv":459.2,"id":13015339},{"batb":[[0,3.7,29.35],[1,1.01,1.41],[2,1.01,0]],"batl":[[0,4.8,38.32],[1,4.8,0]],"ltp":4.2,"tv":54.88,"id":13014431}]}]}
{"op":"mcm","clk":"1011468828","pt":1580656364088,"mc":[{"id":"1.168223928","rc":[{"batb":[[0,2.58,26.05],[1,2.48,31.71],[2,2.4,34.46]],"batl":[[0,2.62,31],[1,2.78,26.28],[2,2.96,21]],"ltp":2.7,"tv":459.2,"id":13015339},{"batb":[[0,4.5,36.51],[1,4.2,12.6],[2,1.01,0.51]],"batl":[[0,5.1,43.52]],"ltp":0.0,"tv":0.0,"id":13015338},{"batb":[[0,4.3,40.44],[1,3.95,63.56],[2,1.01,1.41]],"batl":[[0,4.8,49.24],[1,5.1,34.7]],"ltp":4.2,"tv":54.88,"id":13014431},{"batb":[[0,5.2,26.28],[1,4.7,10.92],[2,1.01,0.51]],"batl":[[0,5.8,8.4],[1,5.9,24.63]],"ltp":0.0,"tv":0.0,"id":13014430}]}]}
{"op":"mcm","clk":"1011468918","pt":1580656364459,"mc":[{"id":"1.168223928","rc":[{"batl":[[2,2.96,0]],"ltp":2.7,"tv":459.2,"id":13015339},{"batb":[[1,1.01,0.51],[2,1.01,0]],"ltp":0.0,"tv":0.0,"id":13015338},{"batb":[[1,3.95,50.12]],"batl":[[0,4.8,38.32]],"ltp":4.2,"tv":54.88,"id":13014431},{"batb":[[1,1.01,0.51],[2,1.01,0]],"ltp":0.0,"tv":0.0,"id":13014430}]}]}
{"op":"mcm","clk":"1011469618","pt":1580656367272,"mc":[{"id":"1.168223928","rc":[{"trd":[[2.62,45.37]],"batl":[[0,2.62,8.31],[2,2.9,21.85]],"ltp":2.62,"tv":504.57,"id":13015339},{"batb":[[1,4.3,12.6],[2,1.01,0.51]],"ltp":0.0,"tv":0.0,"id":13015338},{"batb":[[1,4,13.44],[2,3.95,50.12]],"batl":[[0,4.7,10.92],[1,4.8,38.32],[2,5.1,34.7]],"ltp":4.2,"tv":54.88,"id":13014431},{"batb":[[1,4.8,10.92],[2,1.01,0.51]],"ltp":0.0,"tv":0.0,"id":13014430}],"tv":559.45}]}
{"op":"mcm","clk":"1011471440","pt":1580656374512,"mc":[{"id":"1.168223928","rc":[{"batb":[[1,2.4,34.46],[2,1.01,1.41]],"batl":[[0,2.78,26.28],[1,2.9,21.85],[2,2.9,0]],"ltp":2.62,"tv":504.57,"id":13015339},{"batb":[[0,4,13.44],[1,3.95,50.12],[2,1.01,1.41]],"batl":[[1,5.1,34.7],[2,5.1,0]],"ltp":4.2,"tv":54.88,"id":13014431}]}]}
{"op":"mcm","clk":"1011471903","pt":1580656376374,"mc":[{"id":"1.168223928","rc":[{"batb":[[0,2.4,34.46],[1,1.01,1.41],[2,1.01,0]],"batl":[[1,2.9,0]],"ltp":2.62,"tv":504.57,"id":13015339},{"batb":[[1,1.01,0.51],[2,1.01,0]],"batl":[[0,5.1,33.44]],"ltp":0.0,"tv":0.0,"id":13015338},{"batb":[[0,3.95,50.12],[1,1.01,1.41],[2,1.01,0]],"batl":[[0,5.1,34.7],[1,5.1,0]],"ltp":4.2,"tv":54.88,"id":13014431},{"batb":[[1,1.01,0.51],[2,1.01,0]],"batl":[[0,5.9,24.63],[1,5.9,0]],"ltp":0.0,"tv":0.0,"id":13014430}]}]}
{"op":"mcm","clk":"1011472250","pt":1580656377809,"mc":[{"id":"1.168223928","rc":[{"batb":[[0,2.42,33.36]],"batl":[[0,2.84,25.41]],"ltp":2.62,"tv":504.57,"id":13015339},{"batb":[[0,4.4,36.9]],"ltp":0.0,"tv":0.0,"id":13015338},{"batb":[[0,3.9,51.62]],"batl":[[0,5,35.8]],"ltp":4.2,"tv":54.88,"id":13014431},{"batb":[[0,5.1,26.44]],"ltp":0.0,"tv":0.0,"id":13014430}]}]}
{"op":"mcm","clk":"1011475509","pt":1580656391212,"mc":[{"id":"1.168223928","rc":[{"batb":[[0,2.52,26.89],[1,2.42,33.36],[2,2.38,35.25]],"batl":[[0,2.58,32.65],[1,2.7,28.95],[2,2.8,22.69]],"ltp":2.62,"tv":504.57,"id":13015339},{"batb":[[0,4.5,35.88],[1,4.3,12.6],[2,1.01,0.51]],"batl":[[0,5.1,43.52]],"ltp":0.0,"tv":0.0,"id":13015338},{"batb":[[0,4.5,37.61],[1,4.2,56.43],[2,1.01,1.41]],"batl":[[0,4.9,10.08],[1,5,35.8],[2,5.2,33.13]],"ltp":4.2,"tv":54.88,"id":13014431},{"batb":[[1,4.9,10.08],[2,1.01,0.51]],"batl":[[0,5.8,8.4],[1,5.9,24.63]],"ltp":0.0,"tv":0.0,"id":13014430}]}]}
{"op":"mcm","clk":"1011477001","pt":1580656397616,"mc":[{"id":"1.168223928","rc":[{"batb":[[0,2.56,128.08],[1,2.52,164.12],[2,2.42,33.36]],"ltp":2.62,"tv":504.57,"id":13015339},{"batb":[[1,4.3,121.31],[2,4.2,94.94]],"ltp":0.0,"tv":0.0,"id":13015338},{"batb":[[0,4.6,61.63],[1,4.5,119.26],[2,4.2,56.43]],"ltp":4.2,"tv":54.88,"id":13014431},{"batb":[[0,5.1,68.55],[1,5,64.52],[2,4.9,10.08]],"ltp":0.0,"tv":0.0,"id":13014430}]}]}
{"op":"mcm","clk":"1011478298","pt":1580656403249,"mc":[{"id":"1.168223928","rc":[{"batb":[[0,2.52,164.12],[1,2.38,35.25],[2,1.01,1.41]],"batl":[[0,2.7,28.95],[1,2.8,22.69],[2,2.8,0]],"ltp":2.62,"tv":504.57,"id":13015339},{"batb":[[0,4.2,56.43],[1,1.01,1.41],[2,4.2,0]],"batl":[[1,5.2,33.13],[2,5.2,0]],"ltp":4.2,"tv":54.88,"id":13014431},{"batb":[[0,5.1,26.44]],"ltp":0.0,"tv":0.0,"id":13014430}]}]}
{"op":"mcm","clk":"1011478754","pt":1580656405099,"mc":[{"id":"1.168223928","rc":[{"batb":[[0,2.38,35.25],[1,1.01,1.41],[2,1.01,0]],"batl":[[1,2.8,0]],"ltp":2.62,"tv":504.57,"id":13015339},{"batb":[[1,4.3,108.71]],"batl":[[0,5.1,33.44]],"ltp":0.0,"tv":0.0,"id":13015338},{"batb":[[0,4.2,43.83]],"batl":[[0,5.2,33.13],[1,5.2,0]],"ltp":4.2,"tv":54.88,"id":13014431},{"batb":[[2,1.01,0.51]],"batl":[[0,5.9,24.63],[1,5.9,0]],"ltp":0.0,"tv":0.0,"id":13014430}]}]}
{"op":"mcm","clk":"1011479011","pt":1580656406131,"mc":[{"id":"1.168223928","rc":[{"batb":[[0,2.4,34.23],[1,2.38,35.25],[2,1.01,1.41]],"batl":[[1,2.72,28.09]],"ltp":2.62,"tv":504.57,"id":13015339},{"batb":[[0,4.4,68.53],[1,4.2,43.83],[2,4.1,45.64]],"batl":[[0,5.1,34.46],[1,5.2,33.13]],"ltp":4.2,"tv":54.88,"id":13014431},{"batb":[[1,5,79.43],[2,4.9,66.94]],"ltp":0.0,"tv":0.0,"id":13014430}]}]}
{"op":"mcm","clk":"1011479077","pt":1580656406395,"mc":[{"id":"1.168223928","rc":[{"batb":[[1,1.01,1.41],[2,1.01,0]],"batl":[[0,2.72,28.09],[1,2.72,0]],"ltp":2.62,"tv":504.57,"id":13015339},{"batb":[[1,4.1,45.64],[2,1.01,1.41]],"batl":[[1,5.2,0]],"ltp":4.2,"tv":54.88,"id":13014431}]}]}
{"op":"mcm","clk":"1011479449","pt":1580656408132,"mc":[{"id":"1.168223928","rc":[{"batb":[[0,2.58,110.99],[1,2.54,134.46],[2,2.4,34.23]],"ltp":2.62,"tv":504.57,"id":13015339},{"batb":[[0,4.5,112.26],[1,4.4,85.13],[2,4.1,45.64]],"ltp":4.2,"tv":54.88,"id":13014431},{"batb":[[1,5,101.8]],"ltp":0.0,"tv":0.0,"id":13014430}]}]}
{"op":"mcm","clk":"1011480089","pt":1580656410836,"mc":[{"id":"1.168223928","rc":[{"batb":[[0,2.4,34.23],[1,1.01,1.41],[2,2.4,0]],"ltp":2.62,"tv":504.57,"id":13015339},{"batb":[[0,4.4,68.53],[1,4.1,45.64],[2,1.01,1.41]],"ltp":4.2,"tv":54.88,"id":13014431},{"batb":[[1,5,79.43]],"ltp":0.0,"tv":0.0,"id":13014430}]}]}
{"op":"mcm","clk":"1011480904","pt":1580656414043,"mc":[{"id":"1.168223928","rc":[{"batb":[[0,2.52,142.07],[1,2.48,143.2],[2,2.4,34.23]],"ltp":2.62,"tv":504.57,"id":13015339},{"batb":[[0,4.1,45.64],[1,1.01,1.41],[2,1.01,0]],"ltp":4.2,"tv":54.88,"id":13014431},{"batb":[[1,5,64.52],[2,1.01,0.51]],"ltp":0.0,"tv":0.0,"id":13014430}]}]}
{"op":"mcm","clk":"1011481661","pt":1580656417235,"mc":[{"id":"1.168223928","rc":[{"batb":[[2,2.42,29.41]],"batl":[[0,2.7,24.37],[1,2.72,28.09]],"ltp":2.62,"tv":504.57,"id":13015339},{"batb":[[1,4.3,121.31]],"batl":[[0,5,10.08],[1,5.1,33.44]],"ltp":0.0,"tv":0.0,"id":13015338},{"batb":[[0,4.7,61.93],[1,4.6,77.63],[2,4.4,11.76]],"batl":[[1,5.2,9.24]],"ltp":4.2,"tv":54.88,"id":13014431},{"batb":[[0,5.1,82.69],[1,5,74.6]],"batl":[[1,6,8.4]],"ltp":0.0,"tv":0.0,"id":13014430}]}]}
{"op":"mcm","clk":"1011481869","pt":1580656418148,"mc":[{"id":"1.168223928","rc":[{"batl":[[0,2.54,33.52],[1,2.68,29.35],[2,2.7,24.37]],"ltp":2.62,"tv":504.57,"id":13015339},{"batb":[[0,4.5,35.64],[1,4.4,36.9],[2,4.3,121.31]],"batl":[[2,5.2,32.26]],"ltp":0.0,"tv":0.0,"id":13015338},{"batb":[[2,4.5,36.12]],"batl":[[2,6,24.47]],"ltp":4.2,"tv":54.88,"id":13014431},{"batb":[[0,5.2,25.65],[1,5.1,56.25],[2,5,74.6]],"batl":[[0,6,32.48],[1,6,0]],"ltp":0.0,"tv":0.0,"id":13014430}]}]}
{"op":"mcm","clk":"1011490590","pt":1580656453765,"mc":[{"id":"1.168223928","rc":[{"batb":[[0,2.42,29.41],[1,2.4,34.23],[2,2.2,43.59]],"ltp":2.62,"tv":504.57,"id":13015339},{"batb":[[2,4.3,12.6]],"ltp":0.0,"tv":0.0,"id":13015338},{"batb":[[0,4.5,36.12],[1,4.4,11.76],[2,4.2,43.2]],"ltp":4.2,"tv":54.88,"id":13014431},{"batb":[[1,5,10.08],[2,1.01,0.51]],"ltp":0.0,"tv":0.0,"id":13014430}]}]}
{"op":"mcm","clk":"1011491670","pt":1580656458209,"mc":[{"id":"1.168223928","rc":[{"batb":[[2,2.32,173.74]],"ltp":2.62,"tv":504.57,"id":13015339},{"batb":[[2,4.3,87.79]],"ltp":0.0,"tv":0.0,"id":13015338},{"batb":[[1,4.4,58.73],[2,4.3,90.89]],"ltp":4.2,"tv":54.88,"id":13014431},{"batb":[[1,5,109.4],[2,4.9,66.63]],"ltp":0.0,"tv":0.0,"id":13014430}]}]}
{"op":"mcm","clk":"1011493142","pt":1580656464002,"mc":[{"id":"1.168223928","rc":[{"batb":[[1,2.32,173.74],[2,2.3,88.81]],"batl":[[0,2.68,29.35],[1,2.7,24.37],[2,2.7,0]],"ltp":2.62,"tv":504.57,"id":13015339},{"batb":[[0,4.4,36.9],[1,4.3,87.79],[2,4.2,95.51]],"batl":[[1,5.2,32.26],[2,5.2,0]],"ltp":0.0,"tv":0.0,"id":13015338},{"batb":[[0,4.4,58.73],[1,4.3,90.89],[2,4.2,43.2]],"batl":[[0,5.2,9.24],[1,6,24.47],[2,6,0]],"ltp":4.2,"tv":54.88,"id":13014431}]}]}
{"op":"mcm","clk":"1011493222","pt":1580656464376,"mc":[{"id":"1.168223928","rc":[{"batb":[[0,2.32,173.74],[1,2.3,88.81],[2,2.2,43.59]],"batl":[[1,2.7,0]],"ltp":2.62,"tv":504.57,"id":13015339},{"batb":[[1,4.3,75.19]],"batl":[[0,5.2,32.26],[1,5.2,0]],"ltp":0.0,"tv":0.0,"id":13015338},{"batb":[[0,4.4,46.97]],"batl":[[0,6,24.47],[1,6,0]],"ltp":4.2,"tv":54.88,"id":13014431},{"batb":[[1,5,99.32]],"batl":[[0,6,24.08]],"ltp":0.0,"tv":0.0,"id":13014430}]}]}
{"op":"mcm","clk":"1011493952","pt":1580656467034,"mc":[{"id":"1.168223928","rc":[{"batb":[[2,2.22,43.04]],"batl":[[1,2.7,28.95]],"ltp":2.62,"tv":504.57,"id":13015339},{"batl":[[1,5.3,31.94]],"ltp":0.0,"tv":0.0,"id":13015338},{"batl":[[0,5.9,24.86],[1,6,24.47]],"ltp":4.2,"tv":54.88,"id":13014431},{"batb":[[1,5.1,26.12],[2,5,99.32]],"ltp":0.0,"tv":0.0,"id":13014430}]}]}
{"op":"mcm","clk":"1011494138","pt":1580656467697,"mc":[{"id":"1.168223928","rc":[{"batb":[[0,2.22,43.04],[1,1.01,1.41],[2,2.22,0]],"batl":[[0,2.7,28.95],[1,2.7,0]],"ltp":2.62,"tv":504.57,"id":13015339},{"batb":[[0,4.3,75.19],[1,4.2,95.51],[2,1.01,0.51]],"batl":[[0,5.3,31.94],[1,5.3,0]],"ltp":0.0,"tv":0.0,"id":13015338},{"batb":[[0,4.2,43.2],[1,1.01,1.41],[2,4.2,0]],"batl":[[1,6,0]],"ltp":4.2,"tv":54.88,"id":13014431},{"batb":[[0,5.1,26.12],[1,5,64.18],[2,1.01,0.51]],"ltp":0.0,"tv":0.0,"id":13014430}]}]}
{"op":"mcm","clk":"1011494829","pt":1580656470634,"mc":[{"id":"1.168223928","rc":[{"batb":[[0,2.48,139.58],[1,2.44,149.69],[2,2.22,43.04]],"ltp":2.62,"tv":504.57,"id":13015339},{"batb":[[0,4.3,124.4]],"ltp":0.0,"tv":0.0,"id":13015338},{"batb":[[0,4.8,78.26],[1,4.7,73.62],[2,4.2,43.2]],"ltp":4.2,"tv":54.88,"id":13014431},{"batb":[[0,5.1,90.21]],"ltp":0.0,"tv":0.0,"id":13014430}]}]}
{"op":"mcm","clk":"1011495369","pt":1580656472815,"mc":[{"id":"1.168223928","rc":[{"batb":[[0,2.22,43.04],[1,1.01,1.41],[2,2.22,0]],"ltp":2.62,"tv":504.57,"id":13015339},{"batb":[[0,4.3,75.19]],"ltp":0.0,"tv":0.0,"id":13015338},{"batb":[[0,4.2,43.2],[1,1.01,1.41],[2,4.2,0]],"ltp":4.2,"tv":54.88,"id":13014431},{"batb":[[0,5.1,26.12]],"ltp":0.0,"tv":0.0,"id":13014430}]}]}
{"op":"mcm","clk":"1011496083","pt":1580656475726,"mc":[{"id":"1.168223928","rc":[{"batb":[[0,2.32,173.74],[1,2.3,88.81],[2,2.22,43.04]],"ltp":2.62,"tv":504.57,"id":13015339},{"batb":[[0,4.4,46.97],[1,4.3,90.89],[2,4.2,43.2]],"ltp":4.2,"tv":54.88,"id":13014431},{"batb":[[1,5,99.32],[2,4.9,66.63]],"ltp":0.0,"tv":0.0,"id":13014430}]}]}
{"op":"mcm","clk":"1011497961","pt":1580656483128,"mc":[{"id":"1.168223928","rc":[{"batb":[[0,2.22,43.04],[1,1.01,1.41],[2,2.22,0]],"ltp":2.62,"tv":504.57,"id":13015339},{"batb":[[0,4.2,43.2],[1,1.01,1.41],[2,4.2,0]],"ltp":4.2,"tv":54.88,"id":13014431},{"batb":[[1,5,64.18],[2,1.01,0.51]],"ltp":0.0,"tv":0.0,"id":13014430}]}]}
{"op":"mcm","clk":"1011498699","pt":1580656486227,"mc":[{"id":"1.168223928","rc":[{"batb":[[0,2.66,90.86],[1,2.62,123.97],[2,2.22,43.04]],"ltp":2.62,"tv":504.57,"id":13015339},{"batb":[[0,4.4,46.97],[1,4.3,90.89],[2,4.2,43.2]],"ltp":4.2,"tv":54.88,"id":13014431},{"batb":[[1,5,99.32],[2,4.9,66.63]],"ltp":0.0,"tv":0.0,"id":13014430}]}]}
{"op":"mcm","clk":"1011498935","pt":1580656487248,"mc":[{"id":"1.168223928","rc":[{"batb":[[2,2.54,29.51]],"batl":[[1,2.8,22.69],[2,2.84,25.49]],"ltp":2.62,"tv":504.57,"id":13015339},{"batb":[[0,4.4,37.22],[1,4.3,75.19],[2,4.2,108.11]],"batl":[[0,5,10.08],[1,5.1,33.6]],"ltp":0.0,"tv":0.0,"id":13015338},{"batb":[[2,4.2,55.8]],"batl":[[0,4.7,41.7],[1,4.9,10.08],[2,5.3,31.63]],"ltp":4.2,"tv":54.88,"id":13014431},{"batb":[[1,5,109.4]],"batl":[[0,5.9,33.19]],"ltp":0.0,"tv":0.0,"id":13014430}]}]}
{"op":"mcm","clk":"1011499054","pt":1580656487671,"mc":[{"id":"1.168223928","rc":[{"batl":[[1,2.84,25.49],[2,2.84,0]],"ltp":2.62,"tv":504.57,"id":13015339},{"batb":[[2,4.2,43.2]],"batl":[[1,5.3,31.63],[2,5.3,0]],"ltp":4.2,"tv":54.88,"id":13014431},{"batb":[[1,5,99.32]],"ltp":0.0,"tv":0.0,"id":13014430}]}]}
{"op":"mcm","clk":"1011499372","pt":1580656489037,"mc":[{"id":"1.168223928","rc":[{"batb":[[2,2.54,56.39]],"batl":[[1,2.82,22.69],[2,2.84,25.49]],"ltp":2.62,"tv":504.57,"id":13015339},{"batl":[[1,4.8,10.92],[2,5.3,31.63]],"ltp":4.2,"tv":54.88,"id":13014431},{"batb":[[2,4.9,76.71]],"ltp":0.0,"tv":0.0,"id":13014430}]}]}
{"op":"mcm","clk":"1011502053","pt":1580656499863,"mc":[{"id":"1.168223928","rc":[{"batb":[[0,2.54,26.89],[1,2.36,36.19],[2,1.01,1.41]],"batl":[[0,2.82,22.69],[1,2.84,25.49],[2,2.84,0]],"ltp":2.62,"tv":504.57,"id":13015339},{"batb":[[1,4.3,49.41]],"ltp":0.0,"tv":0.0,"id":13015338},{"batb":[[0,4.1,13.44],[1,3.95,50.44],[2,1.01,1.41]],"batl":[[0,4.8,10.92],[1,5.3,31.63],[2,5.3,0]],"ltp":4.2,"tv":54.88,"id":13014431},{"batb":[[1,5,79.5]],"ltp":0.0,"tv":0.0,"id":13014430}]}]}
{"op":"mcm","clk":"1011502443","pt":1580656501253,"mc":[{"id":"1.168223928","rc":[{"batb":[[0,2.36,36.19],[1,1.01,1.41],[2,1.01,0]],"batl":[[0,2.84,25.49],[1,2.84,0]],"ltp":2.62,"tv":504.57,"id":13015339},{"batb":[[2,4.2,95.51]],"batl":[[0,5.1,33.6],[1,5.1,0]],"ltp":0.0,"tv":0.0,"id":13015338},{"batb":[[0,3.95,50.44],[1,1.01,1.41],[2,1.01,0]],"batl":[[0,5.3,31.63],[1,5.3,0]],"ltp":4.2,"tv":54.88,"id":13014431},{"batb":[[2,4.9,66.63]],"batl":[[0,5.9,24.78]],"ltp":0.0,"tv":0.0,"id":13014430}]}]}
{"op":"mcm","clk":"1011502706","pt":1580656502266,"mc":[{"id":"1.168223928","rc":[{"batb":[[0,2.48,103.97],[1,2.44,149.9],[2,2.36,36.19]],"ltp":2.62,"tv":504.57,"id":13015339},{"batb":[[0,4.1,126.39],[1,4,106.11],[2,3.95,50.44]],"ltp":4.2,"tv":54.88,"id":13014431}]}]}
{"op":"mcm","clk":"1011502766","pt":1580656502434,"mc":[{"id":"1.168223928","rc":[{"batb":[[0,2.36,36.19],[1,1.01,1.41],[2,2.36,0]],"ltp":2.62,"tv":504.57,"id":13015339},{"batb":[[0,3.95,50.44],[1,1.01,1.41],[2,3.95,0]],"ltp":4.2,"tv":54.88,"id":13014431},{"batb":[[1,5,64.53],[2,1.01,0.51]],"ltp":0.0,"tv":0.0,"id":13014430}]}]}
{"op":"mcm","clk":"1011503764","pt":1580656506261,"mc":[{"id":"1.168223928","rc":[{"batb":[[0,2.62,99.78],[1,2.58,129.06],[2,2.36,36.19]],"ltp":2.62,"tv":504.57,"id":13015339},{"batb":[[1,4.3,84.6]],"ltp":0.0,"tv":0.0,"id":13015338},{"batb":[[0,4.4,123.29],[1,4.3,89.6],[2,3.95,50.44]],"ltp":4.2,"tv":54.88,"id":13014431},{"batb":[[0,5.1,67.31]],"ltp":0.0,"tv":0.0,"id":13014430}]}]}
{"op":"mcm","clk":"1011504532","pt":1580656509354,"mc":[{"id":"1.168223928","rc":[{"batb":[[0,2.36,36.19],[1,1.01,1.41],[2,2.36,0]],"ltp":2.62,"tv":504.57,"id":13015339},{"batb":[[1,4.3,49.41]],"ltp":0.0,"tv":0.0,"id":13015338},{"batb":[[0,3.95,50.44],[1,1.01,1.41],[2,3.95,0]],"ltp":4.2,"tv":54.88,"id":13014431},{"batb":[[0,5.1,26.12]],"ltp":0.0,"tv":0.0,"id":13014430}]}]}
{"op":"mcm","clk":"1011505177","pt":1580656512317,"mc":[{"id":"1.168223928","rc":[{"batb":[[0,2.48,103.97],[1,2.44,149.9],[2,2.36,36.19]],"ltp":2.62,"tv":504.57,"id":13015339},{"batb":[[0,4.1,126.39],[1,4,106.11],[2,3.95,50.44]],"ltp":4.2,"tv":54.88,"id":13014431},{"batb":[[1,5,79.5],[2,4.9,66.94]],"ltp":0.0,"tv":0.0,"id":13014430}]}]}
{"op":"mcm","clk":"1011505560","pt":1580656513870,"mc":[{"id":"1.168223928","rc":[{"batb":[[0,2.36,36.19],[1,1.01,1.41],[2,2.36,0]],"ltp":2.62,"tv":504.57,"id":13015339}]}]}
{"op":"mcm","clk":"1011506369","pt":1580656517266,"mc":[{"id":"1.168223928","rc":[{"batb":[[0,2.76,112.77],[1,2.72,112.23],[2,2.64,25.21]],"batl":[[1,2.94,21]],"ltp":2.62,"tv":504.57,"id":13015339},{"batb":[[2,4.2,108.11]],"batl":[[0,5,10.08],[1,5.1,33.6]],"ltp":0.0,"tv":0.0,"id":13015338},{"batb":[[2,3.95,63.88]],"batl":[[0,4.6,10.92],[1,5.3,31.63]],"ltp":4.2,"tv":54.88,"id":13014431},{"batb":[[2,4.9,77.02]],"batl":[[0,5.8,8.4],[1,5.9,24.78]],"ltp":0.0,"tv":0.0,"id":13014430}]}]}
{"op":"mcm","clk":"1011506527","pt":1580656517865,"mc":[{"id":"1.168223928","rc":[{"batb":[[2,2.66,25.97]],"batl":[[1,2.94,44.22]],"ltp":2.62,"tv":504.57,"id":13015339},{"batl":[[0,4.4,47.6],[1,4.6,10.92],[2,4.8,39.34]],"ltp":4.2,"tv":54.88,"id":13014431}]}]}
{"op":"mcm","clk":"1011509830","pt":1580656530986,"mc":[{"id":"1.168223928","rc":[{"batb":[[0,2.64,25.21],[1,2.5,30.84],[2,1.01,1.41]],"batl":[[0,2.94,44.22],[1,2.94,0]],"ltp":2.62,"tv":504.57,"id":13015339},{"batb":[[1,4.2,108.11],[2,1.01,0.51]],"ltp":0.0,"tv":0.0,"id":13015338},{"batb":[[0,4,85.49],[1,3.95,13.44],[2,3.8,27.54]],"batl":[[0,4.6,10.92],[1,4.8,39.34],[2,4.8,0]],"ltp":4.2,"tv":54.88,"id":13014431},{"batb":[[1,5,64.18]],"ltp":0.0,"tv":0.0,"id":13014430}]}]}
{"op":"mcm","clk":"1011510441","pt":1580656533090,"mc":[{"id":"1.168223928","rc":[{"batb":[[0,2.5,30.84],[1,1.01,1.41],[2,1.01,0]],"batl":[[0,2.94,23.21]],"ltp":2.62,"tv":504.57,"id":13015339},{"batb":[[1,4.2,95.51]],"batl":[[0,5.1,33.6],[1,5.1,0]],"ltp":0.0,"tv":0.0,"id":13015338},{"batb":[[1,3.8,27.54],[2,1.01,1.41]],"batl":[[0,4.8,39.34],[1,4.8,0]],"ltp":4.2,"tv":54.88,"id":13014431},{"batb":[[2,4.9,66.94]],"batl":[[0,5.9,24.78],[1,5.9,0]],"ltp":0.0,"tv":0.0,"id":13014430}]}]}
{"op":"mcm","clk":"1011510694","pt":1580656534096,"mc":[{"id":"1.168223928","rc":[{"batb":[[1,4.2,95.87]],"ltp":0.0,"tv":0.0,"id":13015338},{"batb":[[0,3.85,27.38],[1,1.01,1.41],[2,1.01,0]],"batl":[[0,4.8,39.03]],"ltp":4.2,"tv":54.88,"id":13014431}]}]}
{"op":"mcm","clk":"1011511329","pt":1580656536700,"mc":[{"id":"1.168223928","rc":[{"batb":[[0,2.74,89.22],[1,2.7,114.57],[2,2.5,30.84]],"ltp":2.62,"tv":504.57,"id":13015339},{"batb":[[1,4.3,54.57],[2,4.2,95.87]],"ltp":0.0,"tv":0.0,"id":13015338},{"batb":[[0,4.2,78.39],[1,4.1,100.95],[2,3.85,27.38]],"ltp":4.2,"tv":54.88,"id":13014431},{"batb":[[1,5,86.01]],"ltp":0.0,"tv":0.0,"id":13014430}]}]}
{"op":"mcm","clk":"1011512562","pt":1580656541620,"mc":[{"id":"1.168223928","rc":[{"batb":[[0,2.5,30.84],[1,1.01,1.41],[2,2.5,0]],"ltp":2.62,"tv":504.57,"id":13015339},{"batb":[[1,4.2,95.87],[2,1.01,0.51]],"ltp":0.0,"tv":0.0,"id":13015338},{"batb":[[0,3.85,27.38],[1,1.01,1.41],[2,3.85,0]],"ltp":4.2,"tv":54.88,"id":13014431},{"batb":[[1,5,64.18]],"ltp":0.0,"tv":0.0,"id":13014430}]}]}
{"op":"mcm","clk":"1011513412","pt":1580656545122,"mc":[{"id":"1.168223928","rc":[{"batb":[[0,2.62,125.75],[1,2.58,128.89],[2,2.5,30.84]],"ltp":2.62,"tv":504.57,"id":13015339},{"batb":[[1,4.2,95.51]],"ltp":0.0,"tv":0.0,"id":13015338},{"batb":[[2,1.01,0.51]],"ltp":0.0,"tv":0.0,"id":13014430}]}]}
{"op":"mcm","clk":"1011514122","pt":1580656547992,"mc":[{"id":"1.168223928","rc":[{"batb":[[1,4.3,75.64],[2,4.2,95.51]],"ltp":0.0,"tv":0.0,"id":13015338},{"batb":[[0,4.4,105.5],[1,4.3,89.9],[2,3.85,27.38]],"ltp":4.2,"tv":54.88,"id":13014431},{"batb":[[0,5.1,73]],"ltp":0.0,"tv":0.0,"id":13014430}]}]}
{"op":"mcm","clk":"1011514375","pt":1580656549021,"mc":[{"id":"1.168223928","rc":[{"batl":[[0,2.64,30.37],[1,2.8,26.44]],"ltp":2.62,"tv":504.57,"id":13015339},{"batb":[[0,4.5,36.19],[1,4.4,37.22],[2,4.3,75.64]],"batl":[[1,5.2,32.89]],"ltp":0.0,"tv":0.0,"id":13015338},{"batb":[[1,4.3,130.97],[2,4,48]],"batl":[[1,5.6,28.72]],"ltp":4.2,"tv":54.88,"id":13014431},{"batl":[[1,6,24.16]],"ltp":0.0,"tv":0.0,"id":13014430}]}]}
{"op":"mcm","clk":"1011514689","pt":1580656550228,"mc":[{"id":"1.168223928","rc":[{"batb":[[2,2.54,26.89]],"batl":[[2,2.82,22.69]],"ltp":2.62,"tv":504.57,"id":13015339},{"batl":[[0,5,10.08],[1,5.1,33.6],[2,5.2,32.89]],"ltp":0.0,"tv":0.0,"id":13015338},{"batb":[[2,4.2,12.6]],"batl":[[1,4.9,10.08],[2,5.6,28.72]],"ltp":4.2,"tv":54.88,"id":13014431},{"batb":[[1,5,74.26]],"batl":[[0,5.9,33.19]],"ltp":0.0,"tv":0.0,"id":13014430}]}]}
{"op":"mcm","clk":"1011518018","pt":1580656563133,"mc":[{"id":"1.168223928","rc":[{"batb":[[0,2.54,26.89],[1,2.28,39.34],[2,1.01,1.41]],"batl":[[0,2.8,26.44],[1,2.82,22.69],[2,2.82,0]],"ltp":2.62,"tv":504.57,"id":13015339},{"batb":[[0,4.4,37.22],[1,4.2,108.11],[2,1.01,0.51]],"batl":[[1,5.2,32.89],[2,5.2,0]],"ltp":0.0,"tv":0.0,"id":13015338},{"batb":[[0,4.2,12.6],[1,4,48],[2,1.01,1.41]],"batl":[[0,4.9,10.08],[1,5.6,28.72],[2,5.6,0]],"ltp":4.2,"tv":54.88,"id":13014431},{"batb":[[0,5.1,26.12]],"batl":[[0,5.9,8.4]],"ltp":0.0,"tv":0.0,"id":13014430}]}]}
{"op":"mcm","clk":"1011518501","pt":1580656565062,"mc":[{"id":"1.168223928","rc":[{"batb":[[0,2.28,39.34],[1,1.01,1.41],[2,1.01,0]],"batl":[[1,2.82,0]],"ltp":2.62,"tv":504.57,"id":13015339},{"batb":[[1,4.2,95.51]],"batl":[[0,5.2,32.89],[1,5.2,0]],"ltp":0.0,"tv":0.0,"id":13015338},{"batb":[[0,4,48],[1,1.01,1.41],[2,1.01,0]],"batl":[[0,5.6,28.72],[1,5.6,0]],"ltp":4.2,"tv":54.88,"id":13014431},{"batb":[[1,5,64.18]],"batl":[[0,6,24.16],[1,6,0]],"ltp":0.0,"tv":0.0,"id":13014430}]}]}
{"op":"mcm","clk":"1011518598","pt":1580656565444,"mc":[{"id":"1.168223928","rc":[{"batb":[[0,2.42,134.97],[1,2.38,160.28],[2,2.28,39.34]],"ltp":2.62,"tv":504.57,"id":13015339},{"batb":[[1,4.2,139.85],[2,4.1,99.9]],"ltp":0.0,"tv":0.0,"id":13015338},{"batb":[[0,4.1,146.39],[1,4,153.76],[2,1.01,1.41]],"ltp":4.2,"tv":54.88,"id":13014431},{"batb":[[1,5,90.93],[2,4.9,66.76]],"ltp":0.0,"tv":0.0,"id":13014430}]}]}
{"op":"mcm","clk":"1011519143","pt":1580656567576,"mc":[{"id":"1.168223928","rc":[{"batb":[[0,2.28,39.34],[1,1.01,1.41],[2,2.28,0]],"ltp":2.62,"tv":504.57,"id":13015339},{"batb":[[1,4.2,95.51],[2,1.01,0.51]],"ltp":0.0,"tv":0.0,"id":13015338},{"batb":[[0,4,48],[1,1.01,1.41],[2,1.01,0]],"ltp":4.2,"tv":54.88,"id":13014431},{"batb":[[1,5,64.32],[2,1.01,0.51]],"ltp":0.0,"tv":0.0,"id":13014430}]}]}
{"op":"mcm","clk":"1011520039","pt":1580656571243,"mc":[{"id":"1.168223928","rc":[{"batb":[[0,2.58,118.96],[1,2.54,134.43],[2,2.28,39.34]],"ltp":2.62,"tv":504.57,"id":13015339},{"batb":[[1,4.3,87.48],[2,4.2,95.51]],"ltp":0.0,"tv":0.0,"id":13015338},{"batb":[[0,4.5,107.18],[1,4.4,85.2],[2,4,48]],"ltp":4.2,"tv":54.88,"id":13014431},{"batb":[[0,5.1,80.64]],"ltp":0.0,"tv":0.0,"id":13014430}]}]}
{"op":"mcm","clk":"1011520515","pt":1580656573159,"mc":[{"id":"1.168223928","rc":[{"batb":[[0,2.28,39.34],[1,1.01,1.41],[2,2.28,0]],"ltp":2.62,"tv":504.57,"id":13015339},{"batb":[[1,4.2,95.51],[2,1.01,0.51]],"ltp":0.0,"tv":0.0,"id":13015338},{"batb":[[0,4,48],[1,1.01,1.41],[2,4,0]],"ltp":4.2,"tv":54.88,"id":13014431},{"batb":[[0,5.1,26.12]],"ltp":0.0,"tv":0.0,"id":13014430}]}]}
{"op":"mcm","clk":"1011521181","pt":1580656575870,"mc":[{"id":"1.168223928","rc":[{"batb":[[0,2.42,134.97],[1,2.38,160.28],[2,2.28,39.34]],"ltp":2.62,"tv":504.57,"id":13015339},{"batb":[[1,4.2,139.85],[2,4.1,99.9]],"ltp":0.0,"tv":0.0,"id":13015338},{"batb":[[0,4.1,146.39],[1,4,153.76],[2,1.01,1.41]],"ltp":4.2,"tv":54.88,"id":13014431},{"batb":[[1,5,90.93],[2,4.9,66.76]],"ltp":0.0,"tv":0.0,"id":13014430}]}]}
{"op":"mcm","clk":"1011524981","pt":1580656591894,"mc":[{"id":"1.168223928","rc":[{"batb":[[0,2.28,39.34],[1,1.01,1.41],[2,2.28,0]],"ltp":2.62,"tv":504.57,"id":13015339}]}]}
{"op":"mcm","clk":"1011525753","pt":1580656595268,"mc":[{"id":"1.168223928","rc":[{"batb":[[0,2.76,82.8],[1,2.72,112.43],[2,2.62,26.99]],"batl":[[1,2.9,24.08]],"ltp":2.62,"tv":504.57,"id":13015339},{"batl":[[0,5.1,34.54],[1,5.2,32.89]],"ltp":0.0,"tv":0.0,"id":13015338},{"batb":[[2,3.85,26.91]],"batl":[[0,4.5,45.4],[1,4.9,37.3],[2,5.6,28.72]],"ltp":4.2,"tv":54.88,"id":13014431},{"batl":[[0,5.9,24.78],[1,6,24.16]],"ltp":0.0,"tv":0.0,"id":13014430}]}]}
{"op":"mcm","clk":"1011525966","pt":1580656596175,"mc":[{"id":"1.168223928","rc":[{"batb":[[2,2.62,52.19]],"batl":[[2,2.92,21.85]],"ltp":2.62,"tv":504.57,"id":13015339},{"batb":[[1,4.2,152.45]],"batl":[[0,4.9,10.08],[1,5.1,34.54]],"ltp":0.0,"tv":0.0,"id":13015338},{"batb":[[1,4,167.2]],"batl":[[1,4.6,10.92],[2,4.9,37.3]],"ltp":4.2,"tv":54.88,"id":13014431},{"batb":[[2,4.9,76.84]],"batl":[[0,5.9,33.19],[1,6,0]],"ltp":0.0,"tv":0.0,"id":13014430}]}]}
{"op":"mcm","clk":"1011529826","pt":1580656613247,"mc":[{"id":"1.168223928","rc":[{"batb":[[0,2.46,32.18],[1,1.01,1.41],[2,2.62,0]],"batl":[[0,2.9,24.08],[1,2.9,0],[2,2.92,0]],"ltp":2.62,"tv":504.57,"id":13015339},{"batb":[[1,4.2,139.85]],"batl":[[0,5.1,34.54],[1,5.1,0]],"ltp":0.0,"tv":0.0,"id":13015338},{"batb":[[0,4,105.76],[1,3.85,26.91],[2,1.01,1.41]],"batl":[[0,4.9,37.3],[1,4.6,0],[2,4.9,0]],"ltp":4.2,"tv":54.88,"id":13014431},{"batb":[[1,5,72.91],[2,4.9,66.76]],"batl":[[0,5.9,24.78]],"ltp":0.0,"tv":0.0,"id":13014430}]}]}
{"op":"mcm","clk":"1011530542","pt":1580656616246,"mc":[{"id":"1.168223928","rc":[{"batb":[[0,2.62,113.72],[1,2.58,128.97],[2,2.46,32.18]],"ltp":2.62,"tv":504.57,"id":13015339},{"batb":[[1,3.95,55.48],[2,3.85,26.91]],"ltp":4.2,"tv":54.88,"id":13014431}]}]}
{"op":"mcm","clk":"1011533049","pt":1580656627235,"mc":[{"id":"1.168223928","rc":[{"batb":[[0,2.46,32.18],[1,1.01,1.41],[2,2.46,0]],"ltp":2.62,"tv":504.57,"id":13015339}]}]}
{"op":"mcm","clk":"1011533705","pt":1580656630255,"mc":[{"id":"1.168223928","rc":[{"batb":[[0,2.84,73.35],[1,2.8,104.36],[2,2.46,32.18]],"ltp":2.62,"tv":504.57,"id":13015339}]}]}
{"op":"mcm","clk":"1011533950","pt":1580656631226,"mc":[{"id":"1.168223928","rc":[{"batb":[[2,2.72,24.55]],"batl":[[1,3.35,43.35]],"ltp":2.62,"tv":504.57,"id":13015339},{"batb":[[0,4.3,40.05]],"batl":[[0,5,35.41]],"ltp":0.0,"tv":0.0,"id":13015338},{"batl":[[0,4.3,50.83],[1,4.6,42.8]],"ltp":4.2,"tv":54.88,"id":13014431},{"batb":[[0,5,100.37],[1,4.9,66.76],[2,1.01,0.51]],"batl":[[0,5.8,25.73]],"ltp":0.0,"tv":0.0,"id":13014430}]}]}
{"op":"mcm","clk":"1011534113","pt":1580656631924,"mc":[{"id":"1.168223928","rc":[{"batb":[[2,2.76,23.53]],"batl":[[1,3.05,20.16],[2,3.35,43.35]],"ltp":2.62,"tv":504.57,"id":13015339},{"batb":[[1,4.2,152.45]],"batl":[[0,5,45.49]],"ltp":0.0,"tv":0.0,"id":13015338},{"batl":[[1,4.4,11.76],[2,4.6,42.8]],"ltp":4.2,"tv":54.88,"id":13014431},{"batb":[[2,4.8,10.92]],"batl":[[0,5.7,8.4],[1,5.8,25.73]],"ltp":0.0,"tv":0.0,"id":13014430}]}]}
{"op":"mcm","clk":"1011540673","pt":1580656660078,"mc":[{"id":"1.168223928","rc":[{"batb":[[0,2.76,23.53],[1,2.58,28.01],[2,1.01,1.41]],"batl":[[0,3.05,20.16],[1,3.35,43.35],[2,3.35,0]],"ltp":2.62,"tv":504.57,"id":13015339},{"batb":[[1,4.2,82.76]],"ltp":0.0,"tv":0.0,"id":13015338},{"batb":[[0,3.8,14.28],[1,3.4,36.12],[2,1.01,1.41]],"batl":[[0,4.4,11.76],[1,4.6,42.8],[2,4.6,0]],"ltp":4.2,"tv":54.88,"id":13014431},{"batb":[[0,5,70.52]],"ltp":0.0,"tv":0.0,"id":13014430}]}]}
{"op":"mcm","clk":"1011540847","pt":1580656660785,"mc":[{"id":"1.168223928","rc":[{"batb":[[0,2.58,28.01],[1,1.01,1.41],[2,1.01,0]],"batl":[[0,3.35,43.35],[1,3.35,0]],"ltp":2.62,"tv":504.57,"id":13015339},{"batb":[[1,4.2,70.16]],"batl":[[0,5,35.41]],"ltp":0.0,"tv":0.0,"id":13015338},{"batb":[[0,3.4,36.12],[1,1.01,1.41],[2,1.01,0]],"batl":[[0,4.6,42.8],[1,4.6,0]],"ltp":4.2,"tv":54.88,"id":13014431},{"batb":[[2,1.01,0.51]],"batl":[[0,5.8,25.73],[1,5.8,0]],"ltp":0.0,"tv":0.0,"id":13014430}]}]}
{"op":"mcm","clk":"1011541482","pt":1580656663231,"mc":[{"id":"1.168223928","rc":[{"batb":[[0,2.7,80.54],[1,2.66,119.19],[2,2.58,28.01]],"batl":[[0,3.3,44.06]],"ltp":2.62,"tv":504.57,"id":13015339},{"batb":[[0,4.2,110.84],[1,1.01,0.51],[2,4.1,0]],"ltp":0.0,"tv":0.0,"id":13015338},{"batb":[[0,3.45,35.49]],"batl":[[0,4.7,42.09]],"ltp":4.2,"tv":54.88,"id":13014431},{"batb":[[0,5.1,27.07],[1,5,43.06],[2,4.9,66.76]],"batl":[[0,5.9,25.34]],"ltp":0.0,"tv":0.0,"id":13014430}]}]}
{"op":"mcm","clk":"1011542077","pt":1580656666016,"mc":[{"id":"1.168223928","rc":[{"batb":[[0,4.3,57.44],[1,4.2,136.5],[2,1.01,0.51]],"ltp":0.0,"tv":0.0,"id":13015338},{"batb":[[0,4.3,79.09],[1,4.2,95.42],[2,3.45,35.49]],"ltp":4.2,"tv":54.88,"id":13014431},{"batb":[[1,5,87.92]],"ltp":0.0,"tv":0.0,"id":13014430}]}]}
{"op":"mcm","clk":"1011542312","pt":1580656667064,"mc":[{"id":"1.168223928","rc":[{"batl":[[0,2.74,27.85],[1,3,22.03]],"ltp":2.62,"tv":504.57,"id":13015339},{"batb":[[0,4.3,96.39],[1,4.2,95.82]],"batl":[[1,5.1,35.01]],"ltp":0.0,"tv":0.0,"id":13015338},{"batb":[[2,4.1,44.38]],"batl":[[1,4.9,37.06]],"ltp":4.2,"tv":54.88,"id":13014431},{"batb":[[0,5.1,26.75]],"batl":[[0,5.9,24.94]],"ltp":0.0,"tv":0.0,"id":13014430}]}]}
{"op":"mcm","clk":"1011542491","pt":1580656667877,"mc":[{"id":"1.168223928","rc":[{"batb":[[2,2.64,25.21]],"batl":[[1,2.9,21.85],[2,3,22.03]],"ltp":2.62,"tv":504.57,"id":13015339},{"batb":[[1,4.2,108.42]],"batl":[[0,5,45.49]],"ltp":0.0,"tv":0.0,"id":13015338},{"batl":[[0,4.7,53.02]],"ltp":4.2,"tv":54.88,"id":13014431},{"batl":[[0,5.8,8.4],[1,5.9,24.94]],"ltp":0.0,"tv":0.0,"id":13014430}]}]}
{"op":"mcm","clk":"1011545558","pt":1580656681136,"mc":[{"id":"1.168223928","rc":[{"batb":[[0,2.46,31.87],[1,1.01,1.41],[2,2.64,0]],"batl":[[0,3,22.03],[1,2.9,0],[2,3,0]],"ltp":2.62,"tv":504.57,"id":13015339},{"batb":[[0,4.3,38.95],[1,4.2,95.82]],"batl":[[0,5.1,35.01],[1,5.1,0]],"ltp":0.0,"tv":0.0,"id":13015338},{"batb":[[0,3.75,28.95],[1,1.01,1.41],[2,4.1,0]],"batl":[[0,4.9,37.06],[1,4.9,0]],"ltp":4.2,"tv":54.88,"id":13014431},{"batb":[[1,5,56.91]],"batl":[[0,5.9,24.94],[1,5.9,0]],"ltp":0.0,"tv":0.0,"id":13014430}]}]}
{"op":"mcm","clk":"1011546182","pt":1580656683803,"mc":[{"id":"1.168223928","rc":[{"batb":[[0,2.6,92.8],[1,2.56,131.81],[2,2.46,31.87]],"ltp":2.62,"tv":504.57,"id":13015339}]}]}
{"op":"mcm","clk":"1011546684","pt":1580656686032,"mc":[{"id":"1.168223928","rc":[{"batb":[[0,4.3,115.93]],"ltp":0.0,"tv":0.0,"id":13015338},{"batb":[[0,4.5,103.53],[1,4.4,85.26],[2,3.75,28.95]],"ltp":4.2,"tv":54.88,"id":13014431},{"batb":[[1,5,103.25]],"ltp":0.0,"tv":0.0,"id":13014430}]}]}
{"op":"mcm","clk":"1011546906","pt":1580656686950,"mc":[{"id":"1.168223928","rc":[{"batl":[[0,2.62,31.24],[1,2.8,26.2]],"ltp":2.62,"tv":504.57,"id":13015339},{"batb":[[0,4.4,37.77],[1,4.3,76.98],[2,4.2,95.82]],"batl":[[0,5.1,34.86]],"ltp":0.0,"tv":0.0,"id":13015338},{"batb":[[1,4.4,124.21],[2,4,48.07]],"batl":[[1,5.2,33.05]],"ltp":4.2,"tv":54.88,"id":13014431},{"batl":[[1,6,24.55]],"ltp":0.0,"tv":0.0,"id":13014430}]}]}
{"op":"mcm","clk":"1011547115","pt":1580656687752,"mc":[{"id":"1.168223928","rc":[{"batb":[[2,2.54,26.89]],"batl":[[1,2.8,48.89]],"ltp":2.62,"tv":504.57,"id":13015339},{"batb":[[2,4.2,108.42]],"batl":[[0,5,10.08],[1,5.1,34.86]],"ltp":0.0,"tv":0.0,"id":13015338},{"batb":[[2,4.2,12.6]],"batl":[[0,4.9,47.14]],"ltp":4.2,"tv":54.88,"id":13014431},{"batb":[[2,4.9,76.84]],"batl":[[0,5.8,8.4],[1,5.9,24.94],[2,6,24.55]],"ltp":0.0,"tv":0.0,"id":13014430}]}]}
{"op":"mcm","clk":"1011550116","pt":1580656700059,"mc":[{"id":"1.168223928","rc":[{"batb":[[0,2.54,26.89],[1,2.4,34.54],[2,1.01,1.41]],"batl":[[0,2.8,48.89],[1,2.8,0]],"ltp":2.62,"tv":504.57,"id":13015339},{"batb":[[1,4.3,56.74]],"ltp":0.0,"tv":0.0,"id":13015338},{"batb":[[0,4.2,12.6],[1,4,48.07],[2,1.01,1.41]],"batl":[[0,4.9,10.08]],"ltp":4.2,"tv":54.88,"id":13014431},{"batb":[[1,5,71.54]],"batl":[[1,6,24.55],[2,6,0]],"ltp":0.0,"tv":0.0,"id":13014430}]}]}
{"op":"mcm","clk":"1011550332","pt":1580656700867,"mc":[{"id":"1.168223928","rc":[{"batb":[[0,2.4,34.54],[1,1.01,1.41],[2,1.01,0]],"batl":[[0,2.8,26.2]],"ltp":2.62,"tv":504.57,"id":13015339},{"batb":[[2,4.2,95.82]],"batl":[[0,5.1,34.86],[1,5.1,0]],"ltp":0.0,"tv":0.0,"id":13015338},{"batb":[[0,4,48.07],[1,1.01,1.41],[2,1.01,0]],"batl":[[0,5.2,33.05],[1,5.2,0]],"ltp":4.2,"tv":54.88,"id":13014431},{"batb":[[2,4.9,66.76]],"batl":[[0,6,24.55],[1,6,0]],"ltp":0.0,"tv":0.0,"id":13014430}]}]}
{"op":"mcm","clk":"1011550893","pt":1580656703237,"mc":[{"id":"1.168223928","rc":[{"batb":[[0,2.54,90.12],[1,2.5,140.46],[2,2.4,34.54]],"ltp":2.62,"tv":504.57,"id":13015339},{"batb":[[0,4.2,101.17],[1,4.1,100.55],[2,4,48.07]],"ltp":4.2,"tv":54.88,"id":13014431}]}]}
{"op":"mcm","clk":"1011551512","pt":1580656706080,"mc":[{"id":"1.168223928","rc":[{"batb":[[0,2.4,34.54],[1,1.01,1.41],[2,2.4,0]],"ltp":2.62,"tv":504.57,"id":13015339},{"batb":[[0,4,48.07],[1,1.01,1.41],[2,4,0]],"ltp":4.2,"tv":54.88,"id":13014431},{"batb":[[2,1.01,0.51]],"ltp":0.0,"tv":0.0,"id":13014430}]}]}
{"op":"mcm","clk":"1011552221","pt":1580656709104,"mc":[{"id":"1.168223928","rc":[{"batb":[[0,2.54,90.12],[1,2.5,140.46],[2,2.4,34.54]],"ltp":2.62,"tv":504.57,"id":13015339},{"batb":[[1,4.3,87.15]],"ltp":0.0,"tv":0.0,"id":13015338},{"batb":[[0,4.7,74.63],[1,4.6,77.41],[2,4,48.07]],"ltp":4.2,"tv":54.88,"id":13014431},{"batb":[[0,5.1,80.27]],"ltp":0.0,"tv":0.0,"id":13014430}]}]}
{"op":"mcm","clk":"1011552434","pt":1580656710220,"mc":[{"id":"1.168223928","rc":[{"trd":[[2.54,67.66]],"batb":[[0,2.54,56.29],[2,2.48,27.73]],"batl":[[0,2.66,29.9],[1,2.72,24.37]],"ltp":2.54,"tv":572.23,"id":13015339},{"batb":[[0,4.4,36.9],[2,4.2,108.42]],"batl":[[0,5,45.17],[1,5.1,34.54]],"ltp":0.0,"tv":0.0,"id":13015338},{"batb":[[1,4.6,112.03],[2,4.4,11.76]],"batl":[[0,5.2,42.29],[1,5.4,30.84]],"ltp":4.2,"tv":54.88,"id":13014431},{"batb":[[0,5.1,80.11],[2,4.9,10.08]],"batl":[[0,5.9,8.4],[1,6,24.23]],"ltp":0.0,"tv":0.0,"id":13014430}],"tv":627.11}]}
{"op":"mcm","clk":"1011555965","pt":1580656725961,"mc":[{"id":"1.168223928","rc":[{"batb":[[0,2.5,102.06],[1,2.48,27.73],[2,2.34,36.67]],"ltp":2.54,"tv":572.23,"id":13015339},{"batl":[[0,5,10.08]],"ltp":0.0,"tv":0.0,"id":13015338},{"batb":[[0,4.4,11.76],[1,4.3,40.84],[2,1.01,1.41]],"batl":[[0,5.2,9.24]],"ltp":4.2,"tv":54.88,"id":13014431},{"batb":[[0,5.1,26.59]],"ltp":0.0,"tv":0.0,"id":13014430}]}]}
{"op":"mcm","clk":"1011556241","pt":1580656727184,"mc":[{"id":"1.168223928","rc":[{"batb":[[1,2.34,36.67],[2,1.01,1.41]],"batl":[[1,2.72,0]],"ltp":2.54,"tv":572.23,"id":13015339},{"batb":[[2,4.2,95.82]],"batl":[[0,5.1,34.54],[1,5.1,0]],"ltp":0.0,"tv":0.0,"id":13015338},{"batb":[[0,4.3,40.84],[1,1.01,1.41],[2,1.01,0]],"batl":[[0,5.4,30.84],[1,5.4,0]],"ltp":4.2,"tv":54.88,"id":13014431},{"batb":[[2,1.01,0.51]],"batl":[[0,6,24.23],[1,6,0]],"ltp":0.0,"tv":0.0,"id":13014430}]}]}
{"op":"mcm","clk":"1011556705","pt":1580656729256,"mc":[{"id":"1.168223928","rc":[{"batb":[[1,2.38,35.8]],"batl":[[0,2.7,29.19]],"ltp":2.54,"tv":572.23,"id":13015339},{"batl":[[0,5.3,31.24]],"ltp":4.2,"tv":54.88,"id":13014431},{"batl":[[0,5.9,24.55]],"ltp":0.0,"tv":0.0,"id":13014430}]}]}
{"op":"mcm","clk":"1011557174","pt":1580656731127,"mc":[{"id":"1.168223928","rc":[{"batb":[[0,2.54,135.92],[1,2.5,140.14],[2,2.38,35.8]],"ltp":2.54,"tv":572.23,"id":13015339},{"batb":[[0,4.7,43.89],[1,4.6,77.93],[2,4.3,40.84]],"ltp":4.2,"tv":54.88,"id":13014431},{"batb":[[0,5.1,75.04]],"ltp":0.0,"tv":0.0,"id":13014430}]}]}
{"op":"mcm","clk":"1011557639","pt":1580656733117,"mc":[{"id":"1.168223928","rc":[{"batb":[[0,2.5,102.06],[1,2.38,35.8],[2,1.01,1.41]],"ltp":2.54,"tv":572.23,"id":13015339},{"batb":[[0,4.3,40.84],[1,1.01,1.41],[2,4.3,0]],"ltp":4.2,"tv":54.88,"id":13014431},{"batb":[[0,5.1,26.59]],"ltp":0.0,"tv":0.0,"id":13014430}]}]}
{"op":"mcm","clk":"1011558332","pt":1580656736121,"mc":[{"id":"1.168223928","rc":[{"batb":[[1,2.46,146.59],[2,2.38,35.8]],"ltp":2.54,"tv":572.23,"id":13015339},{"batb":[[0,4.5,73.85],[1,4.4,85.79],[2,4.3,40.84]],"ltp":4.2,"tv":54.88,"id":13014431},{"batb":[[1,5,87.66],[2,4.9,66.84]],"ltp":0.0,"tv":0.0,"id":13014430}]}]}
{"op":"mcm","clk":"1011558605","pt":1580656737237,"mc":[{"id":"1.168223928","rc":[{"batb":[[0,2.38,35.8],[1,1.01,1.41],[2,2.38,0]],"ltp":2.54,"tv":572.23,"id":13015339}]}]}
{"op":"mcm","clk":"1011559322","pt":1580656740214,"mc":[{"id":"1.168223928","rc":[{"batb":[[0,2.62,77.61],[1,2.58,129.17],[2,2.38,35.8]],"ltp":2.54,"tv":572.23,"id":13015339}]}]}
{"op":"mcm","clk":"1011559541","pt":1580656741212,"mc":[{"id":"1.168223928","rc":[{"batb":[[2,2.56,29.82]],"batl":[[1,2.9,24.47]],"ltp":2.54,"tv":572.23,"id":13015339},{"batl":[[0,5,35.33]],"ltp":0.0,"tv":0.0,"id":13015338},{"batl":[[0,4.8,39.26],[1,5,35.49]],"ltp":4.2,"tv":54.88,"id":13014431},{"batb":[[0,5,115.28],[1,4.9,66.84],[2,1.01,0.51]],"batl":[[0,5.8,25.65]],"ltp":0.0,"tv":0.0,"id":13014430}]}]}
{"op":"mcm","clk":"1011559650","pt":1580656741750,"mc":[{"id":"1.168223928","rc":[{"batb":[[2,2.56,56.71]],"batl":[[1,2.82,22.69],[2,2.9,24.47]],"ltp":2.54,"tv":572.23,"id":13015339},{"batb":[[1,4.3,99.75]],"batl":[[0,5,45.41]],"ltp":0.0,"tv":0.0,"id":13015338},{"batl":[[1,4.9,10.08],[2,5,35.49]],"ltp":4.2,"tv":54.88,"id":13014431},{"batb":[[2,4.8,10.92]],"batl":[[0,5.7,8.4],[1,5.8,25.65]],"ltp":0.0,"tv":0.0,"id":13014430}]}]}
{"op":"mcm","clk":"1011563068","pt":1580656757183,"mc":[{"id":"1.168223928","rc":[{"batb":[[0,2.56,56.71],[1,2.48,32.02],[2,1.01,1.41]],"ltp":2.54,"tv":572.23,"id":13015339},{"batb":[[1,4.3,80.09]],"ltp":0.0,"tv":0.0,"id":13015338},{"batb":[[0,4.3,40.84],[1,4.2,12.6],[2,3.95,50.67]],"ltp":4.2,"tv":54.88,"id":13014431},{"batb":[[0,5,84.84]],"ltp":0.0,"tv":0.0,"id":13014430}]}]}
{"op":"mcm","clk":"1011563130","pt":1580656757476,"mc":[{"id":"1.168223928","rc":[{"batb":[[0,2.56,26.89]],"batl":[[0,2.82,22.69],[1,2.9,24.47],[2,2.9,0]],"ltp":2.54,"tv":572.23,"id":13015339},{"batb":[[0,4.2,12.6],[1,3.95,50.67],[2,1.01,1.41]],"batl":[[0,4.9,10.08],[1,5,35.49],[2,5,0]],"ltp":4.2,"tv":54.88,"id":13014431}]}]}
{"op":"mcm","clk":"1011563442","pt":1580656758800,"mc":[{"id":"1.168223928","rc":[{"batb":[[0,2.48,32.02],[1,1.01,1.41],[2,1.01,0]],"batl":[[0,2.9,24.47],[1,2.9,0]],"ltp":2.54,"tv":572.23,"id":13015339},{"batb":[[1,4.3,67.49]],"batl":[[0,5,35.33]],"ltp":0.0,"tv":0.0,"id":13015338},{"batb":[[0,3.95,50.67],[1,1.01,1.41],[2,1.01,0]],"batl":[[0,5,35.49],[1,5,0]],"ltp":4.2,"tv":54.88,"id":13014431},{"batb":[[2,1.01,0.51]],"batl":[[0,5.8,25.65],[1,5.8,0]],"ltp":0.0,"tv":0.0,"id":13014430}]}]}
{"op":"mcm","clk":"1011563775","pt":1580656760268,"mc":[{"id":"1.168223928","rc":[{"batb":[[0,2.56,82.14],[1,2.52,137.5],[2,2.48,32.02]],"ltp":2.54,"tv":572.23,"id":13015339},{"batb":[[0,4.2,82.56],[1,4.1,100.91],[2,3.95,50.67]],"ltp":4.2,"tv":54.88,"id":13014431}]}]}
{"op":"mcm","clk":"1011563944","pt":1580656761071,"mc":[{"id":"1.168223928","rc":[{"batb":[[0,3.95,50.67],[1,1.01,1.41],[2,3.95,0]],"ltp":4.2,"tv":54.88,"id":13014431}]}]}
{"op":"mcm","clk":"1011564315","pt":1580656762703,"mc":[{"id":"1.168223928","rc":[{"batb":[[1,4.3,92.26]],"ltp":0.0,"tv":0.0,"id":13015338},{"batb":[[0,4.6,118.43],[1,4.5,80.72],[2,3.95,50.67]],"ltp":4.2,"tv":54.88,"id":13014431},{"batb":[[0,5,130.44]],"ltp":0.0,"tv":0.0,"id":13014430}]}]}
{"op":"mcm","clk":"1011564657","pt":1580656764186,"mc":[{"id":"1.168223928","rc":[{"batb":[[2,2.48,59.75]],"batl":[[0,2.62,31.39],[1,2.72,24.37],[2,2.78,26.91]],"ltp":2.54,"tv":572.23,"id":13015339},{"batb":[[1,4.3,131.13],[2,4.2,108.42]],"batl":[[0,5,45.41],[1,5.1,33.36]],"ltp":0.0,"tv":0.0,"id":13015338},{"batb":[[1,4.5,117.94],[2,4.4,11.76]],"batl":[[1,5.2,9.24],[2,5.9,24.78]],"ltp":4.2,"tv":54.88,"id":13014431},{"batb":[[0,5.1,26.83],[1,5,102.82],[2,4.9,76.92]],"batl":[[0,5.8,8.4],[1,5.9,24.94]],"ltp":0.0,"tv":0.0,"id":13014430}]}]}
{"op":"mcm","clk":"1011571458","pt":1580656794242,"mc":[{"id":"1.168223928","rc":[{"batb":[[0,2.48,59.75],[1,2.26,41.62],[2,1.01,1.41]],"ltp":2.54,"tv":572.23,"id":13015339},{"batb":[[0,4.6,78.01],[1,4.5,37.22]],"ltp":4.2,"tv":54.88,"id":13014431},{"batb":[[1,5,64.62],[2,4.9,10.08]],"ltp":0.0,"tv":0.0,"id":13014430}]}]}
{"op":"mcm","clk":"1011572080","pt":1580656797222,"mc":[{"id":"1.168223928","rc":[{"batb":[[0,2.54,121.02],[1,2.5,140.05],[2,2.48,59.75]],"ltp":2.54,"tv":572.23,"id":13015339},{"batb":[[0,4.7,58.68],[1,4.6,78.01],[2,4.5,37.22]],"ltp":4.2,"tv":54.88,"id":13014431},{"batb":[[0,5.1,81.49]],"ltp":0.0,"tv":0.0,"id":13014430}]}]}
{"op":"mcm","clk":"1011572214","pt":1580656797860,"mc":[{"id":"1.168223928","rc":[{"batb":[[0,2.54,86.65]],"ltp":2.54,"tv":572.23,"id":13015339},{"batb":[[1,4.3,106.36]],"ltp":0.0,"tv":0.0,"id":13015338}]}]}
{"op":"mcm","clk":"1011572968","pt":1580656801257,"mc":[{"id":"1.168223928","rc":[{"batb":[[0,4.7,81.13]],"batl":[[1,5.1,34.7],[2,5.2,9.24]],"ltp":4.2,"tv":54.88,"id":13014431},{"batb":[[0,5.2,26.28],[1,5.1,101.77],[2,5,64.62]],"ltp":0.0,"tv":0.0,"id":13014430}]}]}
{"op":"mcm","clk":"1011573106","pt":1580656801868,"mc":[{"id":"1.168223928","rc":[{"batb":[[2,2.48,27.73]],"ltp":2.54,"tv":572.23,"id":13015339},{"batb":[[2,4.5,36.43]],"batl":[[0,5.1,34.7],[1,5.2,9.24],[2,6,24.23]],"ltp":4.2,"tv":54.88,"id":13014431},{"batb":[[1,5.1,74.94]],"batl":[[1,5.9,24.39]],"ltp":0.0,"tv":0.0,"id":13014430}]}]}
{"op":"mcm","clk":"1011577762","pt":1580656822327,"mc":[{"id":"1.168223928","rc":[{"batb":[[0,2.48,27.73],[1,2.46,32.57],[2,2.24,42.25]],"ltp":2.54,"tv":572.23,"id":13015339},{"batb":[[1,4.3,38.87]],"ltp":0.0,"tv":0.0,"id":13015338},{"batb":[[2,4.9,10.08]],"ltp":0.0,"tv":0.0,"id":13014430}]}]}
{"op":"mcm","clk":"1011578420","pt":1580656825171,"mc":[{"id":"1.168223928","rc":[{"batb":[[0,2.52,102.68],[1,2.48,170.38],[2,2.46,32.57]],"ltp":2.54,"tv":572.23,"id":13015339},{"batb":[[2,4.2,146.15]],"ltp":0.0,"tv":0.0,"id":13015338},{"batb":[[0,4.7,116.51]],"ltp":4.2,"tv":54.88,"id":13014431},{"batb":[[0,5.2,69.58]],"ltp":0.0,"tv":0.0,"id":13014430}]}]}
{"op":"mcm","clk":"1011582784","pt":1580656844204,"mc":[{"id":"1.168223928","rc":[{"batb":[[0,2.48,27.73],[1,2.46,32.57],[2,2.24,42.25]],"ltp":2.54,"tv":572.23,"id":13015339},{"batb":[[2,4.2,108.42]],"ltp":0.0,"tv":0.0,"id":13015338},{"batb":[[0,4.5,36.43],[1,4.4,11.76],[2,4.2,43.9]],"ltp":4.2,"tv":54.88,"id":13014431},{"batb":[[0,5.2,26.28]],"ltp":0.0,"tv":0.0,"id":13014430}]}]}
{"op":"mcm","clk":"1011582935","pt":1580656844817,"mc":[{"id":"1.168223928","rc":[{"batb":[[0,2.24,42.25],[1,1.01,1.41],[2,2.24,0]],"batl":[[0,2.78,26.91],[1,2.72,0],[2,2.78,0]],"ltp":2.54,"tv":572.23,"id":13015339},{"batb":[[0,4.3,38.87],[1,4.2,95.82],[2,4.1,99.04]],"batl":[[0,5.1,33.36],[1,5.1,0]],"ltp":0.0,"tv":0.0,"id":13015338},{"batb":[[0,4.2,43.9],[1,1.01,1.41],[2,4.2,0]],"batl":[[0,6,24.23],[1,5.2,0],[2,6,0]],"ltp":4.2,"tv":54.88,"id":13014431},{"batb":[[2,1.01,0.51]],"batl":[[0,5.9,24.39],[1,5.9,0]],"ltp":0.0,"tv":0.0,"id":13014430}]}]}
{"op":"mcm","clk":"1011583491","pt":1580656847234,"mc":[{"id":"1.168223928","rc":[{"batb":[[0,2.3,163.17],[1,2.28,90.59],[2,2.24,42.25]],"ltp":2.54,"tv":572.23,"id":13015339},{"batb":[[2,1.01,0.51]],"ltp":0.0,"tv":0.0,"id":13015338},{"batb":[[0,4.4,93.18],[1,4.3,91.6],[2,4.2,43.9]],"ltp":4.2,"tv":54.88,"id":13014431},{"batb":[[2,5,65.03]],"ltp":0.0,"tv":0.0,"id":13014430}]}]}
{"op":"mcm","clk":"1011583609","pt":1580656847736,"mc":[{"id":"1.168223928","rc":[{"batb":[[0,2.24,42.25],[1,1.01,1.41],[2,2.24,0]],"batl":[[0,2.76,27.77]],"ltp":2.54,"tv":572.23,"id":13015339},{"batb":[[0,4.2,43.04],[1,1.01,1.41],[2,4.2,0]],"batl":[[0,6.2,23.76]],"ltp":4.2,"tv":54.88,"id":13014431},{"batb":[[0,5.2,25.81],[2,1.01,0.51]],"batl":[[0,6,23.92]],"ltp":0.0,"tv":0.0,"id":13014430}]}]}
{"op":"mcm","clk":"1011584110","pt":1580656849915,"mc":[{"id":"1.168223928","rc":[{"batb":[[0,2.48,87.02],[1,2.44,149.19],[2,2.24,42.25]],"ltp":2.54,"tv":572.23,"id":13015339},{"batb":[[0,4.3,90.83]],"ltp":0.0,"tv":0.0,"id":13015338},{"batb":[[0,4.9,66.74],[1,4.8,71.55],[2,4.2,43.04]],"ltp":4.2,"tv":54.88,"id":13014431},{"batb":[[0,5.2,78.18]],"ltp":0.0,"tv":0.0,"id":13014430}]}]}
{"op":"mcm","clk":"1011585128","pt":1580656854210,"mc":[{"id":"1.168223928","rc":[{"batb":[[0,2.24,42.25],[1,1.01,1.41],[2,2.24,0]],"ltp":2.54,"tv":572.23,"id":13015339},{"batb":[[0,4.3,38.87]],"ltp":0.0,"tv":0.0,"id":13015338},{"batb":[[0,4.2,43.04],[1,1.01,1.41],[2,4.2,0]],"ltp":4.2,"tv":54.88,"id":13014431},{"batb":[[0,5.2,25.81]],"ltp":0.0,"tv":0.0,"id":13014430}]}]}
{"op":"mcm","clk":"1011585721","pt":1580656856926,"mc":[{"id":"1.168223928","rc":[{"batb":[[0,2.3,163.17],[1,2.28,90.59],[2,2.24,42.25]],"ltp":2.54,"tv":572.23,"id":13015339},{"batb":[[2,4.1,99.77]],"ltp":0.0,"tv":0.0,"id":13015338},{"batb":[[0,4.4,93.18],[1,4.3,91.6],[2,4.2,43.04]],"ltp":4.2,"tv":54.88,"id":13014431},{"batb":[[2,5,65.03]],"ltp":0.0,"tv":0.0,"id":13014430}]}]}
{"op":"mcm","clk":"1011586873","pt":1580656862168,"mc":[{"id":"1.168223928","rc":[{"batb":[[0,2.24,42.25],[1,1.01,1.41],[2,2.24,0]],"ltp":2.54,"tv":572.23,"id":13015339}]}]}
{"op":"mcm","clk":"1011587649","pt":1580656865257,"mc":[{"id":"1.168223928","rc":[{"batb":[[0,2.64,133.25],[1,2.6,125.48],[2,2.24,42.25]],"ltp":2.54,"tv":572.23,"id":13015339}]}]}
{"op":"mcm","clk":"1011587786","pt":1580656865813,"mc":[{"id":"1.168223928","rc":[{"batb":[[1,2.6,153.81],[2,2.58,26.05]],"batl":[[1,2.86,21.85],[2,2.9,24.55]],"ltp":2.54,"tv":572.23,"id":13015339},{"batb":[[1,4.2,108.42]],"batl":[[0,4.9,10.08],[1,5,36.19]],"ltp":0.0,"tv":0.0,"id":13015338},{"batl":[[0,4.7,40.84],[1,4.9,10.08],[2,5.4,30.45]],"ltp":4.2,"tv":54.88,"id":13014431},{"batb":[[1,5.1,101.46]],"batl":[[0,5.8,8.4],[1,5.9,24.78],[2,6,23.92]],"ltp":0.0,"tv":0.0,"id":13014430}]}]}
{"op":"mcm","clk":"1011591154","pt":1580656880066,"mc":[{"id":"1.168223928","rc":[{"batb":[[0,2.58,26.05],[1,2.38,35.8],[2,1.01,1.41]],"batl":[[0,2.86,21.85],[1,2.9,24.55],[2,2.9,0]],"ltp":2.54,"tv":572.23,"id":13015339},{"batb":[[1,4.2,82.76]],"ltp":0.0,"tv":0.0,"id":13015338},{"batb":[[0,4.1,13.44],[1,4,49.49],[2,1.01,1.41]],"batl":[[0,4.9,10.08],[1,5.4,30.45],[2,5.4,0]],"ltp":4.2,"tv":54.88,"id":13014431},{"batb":[[0,5.1,86.38],[1,5,65.03],[2,4.8,10.92]],"batl":[[1,6,23.92],[2,6,0]],"ltp":0.0,"tv":0.0,"id":13014430}]}]}
{"op":"mcm","clk":"1011591345","pt":1580656881016,"mc":[{"id":"1.168223928","rc":[{"batb":[[0,2.38,35.8],[1,1.01,1.41],[2,1.01,0]],"batl":[[0,2.9,24.55],[1,2.9,0]],"ltp":2.54,"tv":572.23,"id":13015339},{"batb":[[1,4.2,70.16]],"batl":[[0,5,36.19],[1,5,0]],"ltp":0.0,"tv":0.0,"id":13015338},{"batb":[[0,4,49.49],[1,1.01,1.41],[2,1.01,0]],"batl":[[0,5.4,30.45],[1,5.4,0]],"ltp":4.2,"tv":54.88,"id":13014431},{"batb":[[2,1.01,0.51]],"batl":[[0,6,23.92],[1,6,0]],"ltp":0.0,"tv":0.0,"id":13014430}]}]}
{"op":"mcm","clk":"1011591791","pt":1580656882977,"mc":[{"id":"1.168223928","rc":[{"batb":[[0,2.46,120.4],[1,2.42,152.37],[2,2.38,35.8]],"ltp":2.54,"tv":572.23,"id":13015339},{"batb":[[0,4.2,63.63],[1,4.1,102.83],[2,3.95,49.65]],"ltp":4.2,"tv":54.88,"id":13014431}]}]}
{"op":"mcm","clk":"1011593024","pt":1580656888168,"mc":[{"id":"1.168223928","rc":[{"batb":[[0,2.38,35.8],[1,1.01,1.41],[2,2.38,0]],"ltp":2.54,"tv":572.23,"id":13015339}]}]}
{"op":"mcm","clk":"1011593743","pt":1580656891272,"mc":[{"id":"1.168223928","rc":[{"batb":[[0,2.76,107.18],[1,2.72,111.56],[2,2.38,35.8]],"ltp":2.54,"tv":572.23,"id":13015339}]}]}
{"op":"mcm","clk":"1011593943","pt":1580656892191,"mc":[{"id":"1.168223928","rc":[{"batb":[[1,2.72,136.5],[2,2.68,24.37]],"batl":[[1,3,43.27]],"ltp":2.54,"tv":572.23,"id":13015339},{"batb":[[1,4.2,123.52]],"batl":[[0,4.9,47.53],[1,5,36.19]],"ltp":0.0,"tv":0.0,"id":13015338},{"batb":[[2,3.95,63.09]],"batl":[[0,4.4,46.97],[1,4.6,10.92],[2,4.9,38.08]],"ltp":4.2,"tv":54.88,"id":13014431},{"batb":[[2,4.8,10.92]],"batl":[[0,5.7,8.4],[1,5.9,24.47],[2,6,23.92]],"ltp":0.0,"tv":0.0,"id":13014430}]}]}
{"op":"mcm","clk":"1011593968","pt":1580656892300,"mc":[{"id":"1.168223928","rc":[{"batb":[[0,4.2,123.52],[1,4.1,99.77],[2,1.01,0.51]],"batl":[[1,5,0]],"ltp":0.0,"tv":0.0,"id":13015338},{"batl":[[2,6,0]],"ltp":0.0,"tv":0.0,"id":13014430}]}]}
{"op":"mcm","clk":"1011597250","pt":1580656906923,"mc":[{"id":"1.168223928","rc":[{"batb":[[0,2.54,30.29],[1,1.01,1.41],[2,2.68,0]],"batl":[[0,3,22.27],[1,3,0]],"ltp":2.54,"tv":572.23,"id":13015339},{"batb":[[0,4.2,91.56]],"batl":[[0,4.9,37.45]],"ltp":0.0,"tv":0.0,"id":13015338},{"batb":[[0,3.85,27.38],[1,1.01,1.41],[2,3.95,0]],"batl":[[0,4.9,38.08],[1,4.6,0],[2,4.9,0]],"ltp":4.2,"tv":54.88,"id":13014431},{"batb":[[0,5.1,67.02],[2,1.01,0.51]],"batl":[[0,5.9,24.47],[1,5.9,0]],"ltp":0.0,"tv":0.0,"id":13014430}]}]}
{"op":"mcm","clk":"1011597927","pt":1580656909825,"mc":[{"id":"1.168223928","rc":[{"batb":[[0,2.62,99.3],[1,2.58,128.31],[2,2.54,30.29]],"ltp":2.54,"tv":572.23,"id":13015339},{"batb":[[0,4,123.52],[1,3.95,56.29],[2,3.85,27.38]],"ltp":4.2,"tv":54.88,"id":13014431}]}]}
{"op":"mcm","clk":"1011598160","pt":1580656910802,"mc":[{"id":"1.168223928","rc":[{"batb":[[0,2.54,30.29],[1,1.01,1.41],[2,2.54,0]],"ltp":2.54,"tv":572.23,"id":13015339},{"batb":[[0,3.85,27.38],[1,1.01,1.41],[2,3.85,0]],"ltp":4.2,"tv":54.88,"id":13014431}]}]}
{"op":"mcm","clk":"1011599114","pt":1580656915060,"mc":[{"id":"1.168223928","rc":[{"batb":[[0,2.74,79.7],[1,2.7,113.93],[2,2.54,30.29]],"ltp":2.54,"tv":572.23,"id":13015339},{"batb":[[0,4.2,111.66]],"ltp":0.0,"tv":0.0,"id":13015338},{"batb":[[0,4.2,121.26],[1,4.1,101.85],[2,3.85,27.38]],"ltp":4.2,"tv":54.88,"id":13014431},{"batb":[[0,5.1,93.7]],"ltp":0.0,"tv":0.0,"id":13014430}]}]}
{"op":"mcm","clk":"1011599365","pt":1580656916190,"mc":[{"id":"1.168223928","rc":[{"batb":[[0,2.54,30.29],[1,1.01,1.41],[2,2.54,0]],"ltp":2.54,"tv":572.23,"id":13015339},{"batb":[[0,4.2,92.14]],"ltp":0.0,"tv":0.0,"id":13015338},{"batb":[[0,3.85,27.38],[1,1.01,1.41],[2,3.85,0]],"ltp":4.2,"tv":54.88,"id":13014431},{"batb":[[0,5.1,67.02]],"ltp":0.0,"tv":0.0,"id":13014430}]}]}
{"op":"mcm","clk":"1011600128","pt":1580656919266,"mc":[{"id":"1.168223928","rc":[{"batb":[[0,4,122.68],[1,3.95,56.29],[2,3.85,27.38]],"ltp":4.2,"tv":54.88,"id":13014431}]}]}
{"op":"mcm","clk":"1011600813","pt":1580656922051,"mc":[{"id":"1.168223928","rc":[{"batb":[[0,2.84,113.92],[1,2.8,103.42],[2,2.76,23.53]],"batl":[[1,3.1,19.32]],"ltp":2.54,"tv":572.23,"id":13015339},{"batb":[[0,4.2,104.74]],"batl":[[0,4.9,47.53]],"ltp":0.0,"tv":0.0,"id":13015338},{"batb":[[2,3.85,41.66]],"batl":[[0,4.4,11.76],[1,4.9,38.08]],"ltp":4.2,"tv":54.88,"id":13014431},{"batb":[[2,4.7,10.92]],"batl":[[0,5.6,8.4],[1,5.9,24.47]],"ltp":0.0,"tv":0.0,"id":13014430}]}]}
{"op":"mcm","clk":"1011601019","pt":1580656922958,"mc":[{"id":"1.168223928","rc":[{"batb":[[0,2.84,136.58]],"batl":[[2,3.15,50.99]],"ltp":2.54,"tv":572.23,"id":13015339},{"batl":[[0,4.8,38.63],[1,4.9,10.08]],"ltp":0.0,"tv":0.0,"id":13015338},{"batl":[[0,4.2,26.59],[1,4.4,11.76],[2,4.6,44.46]],"ltp":4.2,"tv":54.88,"id":13014431},{"batb":[[1,5,92.57]],"batl":[[1,5.8,25.81],[2,5.9,24.47]],"ltp":0.0,"tv":0.0,"id":13014430}]}]}
{"op":"mcm","clk":"1011604067","pt":1580656936073,"mc":[{"id":"1.168223928","rc":[{"batb":[[0,2.76,23.53],[1,2.68,26.12],[2,1.01,1.41]],"batl":[[0,3.1,19.32],[1,3.15,50.99],[2,3.15,0]],"ltp":2.54,"tv":572.23,"id":13015339},{"batb":[[0,4.2,104.16]],"ltp":0.0,"tv":0.0,"id":13015338},{"batb":[[0,3.95,56.29],[1,3.85,14.28],[2,3.75,29.51]],"batl":[[0,4.4,11.76],[1,4.6,44.46],[2,4.6,0]],"ltp":4.2,"tv":54.88,"id":13014431},{"batb":[[0,5,92.57],[1,4.7,10.92],[2,1.01,0.51]],"batl":[[1,5.9,24.47],[2,5.9,0]],"ltp":0.0,"tv":0.0,"id":13014430}]}]}
{"op":"mcm","clk":"1011604256","pt":1580656936878,"mc":[{"id":"1.168223928","rc":[{"batb":[[0,2.68,26.12],[1,1.01,1.41],[2,1.01,0]],"batl":[[0,3.15,50.99],[1,3.15,0]],"ltp":2.54,"tv":572.23,"id":13015339},{"batb":[[0,4.2,91.56]],"batl":[[1,4.9,0]],"ltp":0.0,"tv":0.0,"id":13015338},{"batb":[[1,3.75,29.51],[2,1.01,1.41]],"batl":[[0,4.6,44.46],[1,4.6,0]],"ltp":4.2,"tv":54.88,"id":13014431},{"batb":[[1,1.01,0.51],[2,1.01,0]],"batl":[[0,5.9,24.47],[1,5.9,0]],"ltp":0.0,"tv":0.0,"id":13014430}]}]}
{"op":"mcm","clk":"1011604778","pt":1580656939089,"mc":[{"id":"1.168223928","rc":[{"batb":[[0,2.74,127.39],[1,2.7,113.61],[2,2.68,26.12]],"ltp":2.54,"tv":572.23,"id":13015339},{"batb":[[0,3.95,88.03],[1,3.9,58.31],[2,3.75,29.51]],"ltp":4.2,"tv":54.88,"id":13014431},{"batb":[[0,5,117.08],[1,4.9,67.96],[2,1.01,0.51]],"ltp":0.0,"tv":0.0,"id":13014430}]}]}
{"op":"mcm","clk":"1011606238","pt":1580656945205,"mc":[{"id":"1.168223928","rc":[{"batb":[[0,2.68,26.12],[1,1.01,1.41],[2,2.68,0]],"ltp":2.54,"tv":572.23,"id":13015339}]}]}
{"op":"mcm","clk":"1011606814","pt":1580656948024,"mc":[{"id":"1.168223928","rc":[{"batb":[[0,2.9,90.63],[1,2.86,119.93],[2,2.68,26.12]],"batl":[[1,3.25,18.48]],"ltp":2.54,"tv":572.23,"id":13015339},{"batb":[[0,4.2,104.16]],"batl":[[1,4.9,10.08]],"ltp":0.0,"tv":0.0,"id":13015338},{"batl":[[0,4.2,12.6],[1,4.6,44.46]],"ltp":4.2,"tv":54.88,"id":13014431},{"batb":[[2,4.6,10.92]],"batl":[[0,5.5,9.24],[1,5.9,24.47]],"ltp":0.0,"tv":0.0,"id":13014430}]}]}
{"op":"mcm","clk":"1011607109","pt":1580656949217,"mc":[{"id":"1.168223928","rc":[{"batb":[[0,2.9,111.87],[2,2.74,24.47]],"batl":[[2,3.6,36.43]],"ltp":2.54,"tv":572.23,"id":13015339},{"batl":[[0,4.8,38.32]],"ltp":0.0,"tv":0.0,"id":13015338},{"batl":[[0,4.1,28.64],[1,4.2,12.6],[2,4.4,47.76]],"ltp":4.2,"tv":54.88,"id":13014431},{"batl":[[1,5.8,25.97]],"ltp":0.0,"tv":0.0,"id":13014430}]}]}
{"op":"mcm","clk":"1011612473","pt":1580656972842,"mc":[{"id":"1.168223928","rc":[{"batb":[[0,2.74,24.47],[1,1.01,1.41],[2,2.74,0]],"batl":[[0,3.6,36.43],[1,3.25,0],[2,3.6,0]],"ltp":2.54,"tv":572.23,"id":13015339},{"batb":[[0,4.2,40.76]],"batl":[[1,4.9,0]],"ltp":0.0,"tv":0.0,"id":13015338},{"batb":[[0,3.25,41.31],[1,1.01,1.41],[2,3.75,0]],"batl":[[0,4.4,47.76],[1,4.2,0],[2,4.4,0]],"ltp":4.2,"tv":54.88,"id":13014431},{"batb":[[0,5,76.7],[2,1.01,0.51]],"batl":[[0,5.8,25.97],[1,5.8,0]],"ltp":0.0,"tv":0.0,"id":13014430}]}]}
{"op":"mcm","clk":"1011613201","pt":1580656976242,"mc":[{"id":"1.168223928","rc":[{"batb":[[0,2.76,80.62],[1,2.72,137.04],[2,1.01,1.41]],"batl":[[0,3.55,37.53]],"ltp":2.54,"tv":572.23,"id":13015339},{"batb":[[2,4,105.8]],"ltp":0.0,"tv":0.0,"id":13015338},{"batb":[[0,3.45,127.29],[1,3.4,80.48],[2,3.3,40.13]],"batl":[[0,4.5,46.34]],"ltp":4.2,"tv":54.88,"id":13014431},{"batb":[[0,5.1,27.3],[1,5,49.16],[2,4.9,67.96]],"batl":[[0,5.8,25.57]],"ltp":0.0,"tv":0.0,"id":13014430}]}]}
{"op":"mcm","clk":"1011614994","pt":1580656984473,"mc":[{"id":"1.168223928","rc":[{"batb":[[0,2.72,25.1],[1,1.01,1.41],[2,1.01,0]],"ltp":2.54,"tv":572.23,"id":13015339}]}]}
{"op":"mcm","clk":"1011615757","pt":1580656988109,"mc":[{"id":"1.168223928","rc":[{"batb":[[0,3.25,175.52],[1,3.2,110.24],[2,2.98,49.1]],"batl":[[1,3.6,15.96],[2,4.5,45.01]],"ltp":2.54,"tv":572.23,"id":13015339},{"batb":[[0,4.2,53.36],[1,4.1,145.09]],"batl":[[0,4.7,40.13],[1,4.8,49.24]],"ltp":0.0,"tv":0.0,"id":13015338},{"batb":[[2,3.3,57.77]],"batl":[[0,3.55,38.71],[1,3.75,15.12],[2,3.95,30.76]],"ltp":4.2,"tv":54.88,"id":13014431},{"batb":[[1,5,76.62]],"batl":[[0,5.4,9.24],[1,5.8,25.57]],"ltp":0.0,"tv":0.0,"id":13014430}]}]}
{"op":"mcm","clk":"1011615939","pt":1580656988913,"mc":[{"id":"1.168223928","rc":[{"batb":[[0,4.2,12.6]],"batl":[[1,4.8,10.92]],"ltp":0.0,"tv":0.0,"id":13015338},{"batb":[[0,5,76.62],[1,4.9,67.96],[2,4.6,10.92]],"ltp":0.0,"tv":0.0,"id":13014430}]}]}
{"op":"mcm","clk":"1011618866","pt":1580657001217,"mc":[{"id":"1.168223928","rc":[{"batb":[[0,3.2,18.48],[1,2.98,49.1],[2,1.01,1.41]],"batl":[[0,3.6,15.96],[1,4.5,45.01],[2,4.5,0]],"ltp":2.54,"tv":572.23,"id":13015339},{"batb":[[1,4.1,45.32]],"ltp":0.0,"tv":0.0,"id":13015338},{"batb":[[0,3.3,17.64],[1,2.86,23.29],[2,1.01,1.41]],"batl":[[0,3.75,15.12],[1,3.95,30.76],[2,3.95,0]],"ltp":4.2,"tv":54.88,"id":13014431},{"batb":[[0,5,27.46]],"ltp":0.0,"tv":0.0,"id":13014430}]}]}
{"op":"mcm","clk":"1011619305","pt":1580657002953,"mc":[{"id":"1.168223928","rc":[{"batb":[[0,2.98,49.1],[1,1.01,1.41],[2,1.01,0]],"batl":[[0,4.5,45.01],[1,4.5,0]],"ltp":2.54,"tv":572.23,"id":13015339},{"batb":[[0,4.1,45.32],[1,4,105.8],[2,1.01,0.51]],"batl":[[1,4.8,0]],"ltp":0.0,"tv":0.0,"id":13015338},{"batb":[[0,2.86,23.29],[1,1.01,1.41],[2,1.01,0]],"batl":[[0,3.95,30.76],[1,3.95,0]],"ltp":4.2,"tv":54.88,"id":13014431},{"batb":[[2,1.01,0.51]],"batl":[[0,5.8,25.57],[1,5.8,0]],"ltp":0.0,"tv":0.0,"id":13014430}]}]}
{"op":"mcm","clk":"1011619557","pt":1580657004133,"mc":[{"id":"1.168223928","rc":[{"batb":[[1,4,151.83]],"ltp":0.0,"tv":0.0,"id":13015338},{"batb":[[0,5.1,27.15],[1,5,27.46],[2,4.9,68.51]],"ltp":0.0,"tv":0.0,"id":13014430}]}]}
{"op":"mcm","clk":"1011619763","pt":1580657005019,"mc":[{"id":"1.168223928","rc":[{"batb":[[0,4,151.83],[1,1.01,0.51],[2,1.01,0]],"ltp":0.0,"tv":0.0,"id":13015338},{"batb":[[0,2.86,22.98]],"batl":[[0,3.95,30.29]],"ltp":4.2,"tv":54.88,"id":13014431},{"batb":[[1,4.9,68.51],[2,1.01,0.51]],"ltp":0.0,"tv":0.0,"id":13014430}]}]}
{"op":"mcm","clk":"1011620238","pt":1580657007227,"mc":[{"id":"1.168223928","rc":[{"batb":[[0,3.4,89.02],[1,3.35,82.35],[2,2.98,49.1]],"ltp":2.54,"tv":572.23,"id":13015339},{"batb":[[0,4.1,86.44],[1,4,151.83],[2,1.01,0.51]],"ltp":0.0,"tv":0.0,"id":13015338},{"batb":[[0,3.35,105.66],[1,3.3,86.79],[2,2.86,22.98]],"ltp":4.2,"tv":54.88,"id":13014431},{"batb":[[1,5,43.93],[2,4.9,68.51]],"ltp":0.0,"tv":0.0,"id":13014430}]}]}
{"op":"mcm","clk":"1011620674","pt":1580657009120,"mc":[{"id":"1.168223928","rc":[{"batb":[[0,2.98,49.1],[1,1.01,1.41],[2,2.98,0]],"ltp":2.54,"tv":572.23,"id":13015339},{"batb":[[0,4,151.83],[1,1.01,0.51],[2,1.01,0]],"ltp":0.0,"tv":0.0,"id":13015338},{"batb":[[0,2.86,22.98],[1,1.01,1.41],[2,2.86,0]],"ltp":4.2,"tv":54.88,"id":13014431},{"batb":[[1,4.9,68.51],[2,1.01,0.51]],"ltp":0.0,"tv":0.0,"id":13014430}]}]}
{"op":"mcm","clk":"1011621377","pt":1580657012147,"mc":[{"id":"1.168223928","rc":[{"batb":[[0,3,87.2],[1,2.98,49.1],[2,2.96,90.01]],"ltp":2.54,"tv":572.23,"id":13015339},{"batb":[[1,3.95,55.06],[2,1.01,0.51]],"ltp":0.0,"tv":0.0,"id":13015338},{"batb":[[0,2.96,109.45],[1,2.92,94.52],[2,2.86,22.98]],"ltp":4.2,"tv":54.88,"id":13014431},{"batb":[[1,4.9,92.64],[2,4.8,71.03]],"ltp":0.0,"tv":0.0,"id":13014430}]}]}
{"op":"mcm","clk":"1011624660","pt":1580657026947,"mc":[{"id":"1.168223928","rc":[{"batb":[[0,2.98,49.1],[1,1.01,1.41],[2,2.96,0]],"ltp":2.54,"tv":572.23,"id":13015339}]}]}
{"op":"mcm","clk":"1011625297","pt":1580657030143,"mc":[{"id":"1.168223928","rc":[{"batb":[[0,4,97.55],[1,3.95,55.27],[2,2.98,49.1]],"ltp":2.54,"tv":572.23,"id":13015339}]}]}
{"op":"mcm","clk":"1011625510","pt":1580657031144,"mc":[{"id":"1.168223928","rc":[{"batb":[[1,3.95,104.29],[2,3.5,33.28]],"batl":[[0,4.4,46.42],[1,6.2,21.87]],"ltp":2.54,"tv":572.23,"id":13015339},{"batb":[[2,3.9,49.96]],"batl":[[0,4.6,41.86]],"ltp":0.0,"tv":0.0,"id":13015338},{"batb":[[2,2.88,22.74]],"batl":[[0,3.05,22.35],[1,3.4,43.75]],"ltp":4.2,"tv":54.88,"id":13014431},{"batl":[[0,5.8,25.34]],"ltp":0.0,"tv":0.0,"id":13014430}]}]}
{"op":"mcm","clk":"1011625728","pt":1580657032056,"mc":[{"id":"1.168223928","rc":[{"batb":[[2,3.8,14.28]],"batl":[[0,4.4,58.19]],"ltp":2.54,"tv":572.23,"id":13015339},{"batb":[[0,4.1,13.44],[1,4,151.83],[2,3.95,55.06]],"batl":[[1,4.7,10.92]],"ltp":0.0,"tv":0.0,"id":13015338},{"batl":[[1,3.25,18.48],[2,3.4,43.75]],"ltp":4.2,"tv":54.88,"id":13014431},{"batl":[[0,5.4,9.24],[1,5.8,25.34]],"ltp":0.0,"tv":0.0,"id":13014430}]}]}
{"op":"mcm","clk":"1011629456","pt":1580657049065,"mc":[{"id":"1.168223928","rc":[{"batb":[[0,3.5,33.28],[1,1.01,1.41],[2,3.8,0]],"batl":[[0,6.2,21.87],[1,6.2,0]],"ltp":2.54,"tv":572.23,"id":13015339},{"batb":[[0,3.95,55.06],[1,3.9,49.96],[2,1.01,0.51]],"batl":[[1,4.7,0]],"ltp":0.0,"tv":0.0,"id":13015338},{"batb":[[0,2.44,35.25],[1,1.01,1.41],[2,2.88,0]],"batl":[[0,3.4,43.75],[1,3.25,0],[2,3.4,0]],"ltp":4.2,"tv":54.88,"id":13014431},{"batb":[[1,4.9,71.57]],"batl":[[0,5.8,25.34],[1,5.8,0]],"ltp":0.0,"tv":0.0,"id":13014430}]}]}
{"op":"mcm","clk":"1011630328","pt":1580657053174,"mc":[{"id":"1.168223928","rc":[{"batb":[[0,3.45,33.83]],"ltp":2.54,"tv":572.23,"id":13015339},{"batb":[[0,3.95,104],[1,1.01,0.51],[2,1.01,0]],"ltp":0.0,"tv":0.0,"id":13015338},{"batb":[[0,2.44,35.01]],"batl":[[0,3.4,43.04]],"ltp":4.2,"tv":54.88,"id":13014431}]}]}
{"op":"mcm","clk":"1011630755","pt":1580657055167,"mc":[{"id":"1.168223928","rc":[{"batb":[[0,4.2,126.19],[1,4.1,99.45],[2,3.45,33.83]],"ltp":2.54,"tv":572.23,"id":13015339},{"batb":[[0,4,99.68],[1,3.95,104],[2,1.01,0.51]],"ltp":0.0,"tv":0.0,"id":13015338},{"batb":[[0,2.86,105.65],[1,2.82,103.35],[2,2.44,35.01]],"ltp":4.2,"tv":54.88,"id":13014431},{"batb":[[1,4.9,88.43]],"ltp":0.0,"tv":0.0,"id":13014430}]}]}
{"op":"mcm","clk":"1011631404","pt":1580657057996,"mc":[{"id":"1.168223928","rc":[{"batb":[[0,3.45,33.83],[1,1.01,1.41],[2,3.45,0]],"ltp":2.54,"tv":572.23,"id":13015339},{"batb":[[0,3.95,104],[1,1.01,0.51],[2,1.01,0]],"ltp":0.0,"tv":0.0,"id":13015338},{"batb":[[0,2.44,35.01],[1,1.01,1.41],[2,2.44,0]],"ltp":4.2,"tv":54.88,"id":13014431},{"batb":[[1,4.9,71.58]],"ltp":0.0,"tv":0.0,"id":13014430}]}]}
{"op":"mcm","clk":"1011632079","pt":1580657061190,"mc":[{"id":"1.168223928","rc":[{"batb":[[0,3.5,104.73],[1,3.45,110.31],[2,1.01,1.41]],"ltp":2.54,"tv":572.23,"id":13015339},{"batb":[[1,3.9,57.26],[2,1.01,0.51]],"ltp":0.0,"tv":0.0,"id":13015338},{"batb":[[0,2.52,87.15],[1,2.48,144.98],[2,2.44,35.01]],"ltp":4.2,"tv":54.88,"id":13014431}]}]}
{"op":"mcm","clk":"1011633514","pt":1580657067623,"mc":[{"id":"1.168223928","rc":[{"batb":[[0,3.45,33.83],[1,1.01,1.41],[2,1.01,0]],"ltp":2.54,"tv":572.23,"id":13015339}]}]}
{"op":"mcm","clk":"1011634256","pt":1580657071094,"mc":[{"id":"1.168223928","rc":[{"batb":[[0,5.6,40.25],[1,5.5,51.71],[2,5.4,23.29]],"batl":[[1,9.2,19.91]],"ltp":2.54,"tv":572.23,"id":13015339},{"batb":[[1,3.9,107.93]],"batl":[[0,4.5,45.56],[1,4.6,41.86]],"ltp":0.0,"tv":0.0,"id":13015338},{"batl":[[0,2.58,34.23],[1,2.76,28.4],[2,3.4,43.04]],"ltp":4.2,"tv":54.88,"id":13014431}]}]}
{"op":"mcm","clk":"1011634515","pt":1580657072140,"mc":[{"id":"1.168223928","rc":[{"batl":[[0,6,8.4],[1,6.2,21.87],[2,9.2,19.91]],"ltp":2.54,"tv":572.23,"id":13015339},{"batb":[[0,3.95,55.06],[1,3.9,122.21]],"batl":[[1,4.6,10.92]],"ltp":0.0,"tv":0.0,"id":13015338},{"batb":[[1,2.48,172.71]],"batl":[[1,2.76,51.93],[2,3.4,0]],"ltp":4.2,"tv":54.88,"id":13014431},{"batb":[[0,5.1,26.75]],"batl":[[0,5.4,9.24],[1,5.8,25.34]],"ltp":0.0,"tv":0.0,"id":13014430}]}]}
{"op":"mcm","clk":"1011637514","pt":1580657085034,"mc":[{"id":"1.168223928","rc":[{"batb":[[0,5.4,23.29],[1,5.1,10.08],[2,4.6,33.13]],"ltp":2.54,"tv":572.23,"id":13015339},{"batb":[[0,3.9,122.21],[1,1.01,0.51],[2,1.01,0]],"ltp":0.0,"tv":0.0,"id":13015338},{"batb":[[0,2.48,27.73],[1,2.44,35.01],[2,2.16,48.63]],"ltp":4.2,"tv":54.88,"id":13014431},{"batb":[[1,4.9,67.96]],"ltp":0.0,"tv":0.0,"id":13014430}]}]}
{"op":"mcm","clk":"1011637686","pt":1580657085845,"mc":[{"id":"1.168223928","rc":[{"batb":[[0,5.1,10.08],[1,4.6,33.13],[2,1.01,1.41]],"batl":[[1,9.2,19.91],[2,9.2,0]],"ltp":2.54,"tv":572.23,"id":13015339},{"batb":[[1,2.16,48.63],[2,1.01,1.41]],"batl":[[0,2.76,51.93],[1,2.76,0]],"ltp":4.2,"tv":54.88,"id":13014431}]}]}
{"op":"mcm","clk":"1011637934","pt":1580657086947,"mc":[{"id":"1.168223928","rc":[{"batb":[[0,4.6,33.13],[1,1.01,1.41],[2,1.01,0]],"batl":[[0,9.2,19.91],[1,9.2,0]],"ltp":2.54,"tv":572.23,"id":13015339},{"batb":[[0,3.9,107.93]],"batl":[[1,4.6,0]],"ltp":0.0,"tv":0.0,"id":13015338},{"batb":[[0,2.16,48.63],[1,1.01,1.41],[2,1.01,0]],"batl":[[0,2.76,28.4]],"ltp":4.2,"tv":54.88,"id":13014431},{"batl":[[0,5.8,25.34],[1,5.8,0]],"ltp":0.0,"tv":0.0,"id":13014430}]}]}
{"op":"mcm","clk":"1011638244","pt":1580657088245,"mc":[{"id":"1.168223928","rc":[{"batb":[[0,4.7,116.61],[1,4.6,109.3],[2,1.01,1.41]],"ltp":2.54,"tv":572.23,"id":13015339},{"batb":[[1,3.85,59.15],[2,1.01,0.51]],"ltp":0.0,"tv":0.0,"id":13015338},{"batb":[[0,2.22,165.9],[1,2.2,101.76],[2,2.16,48.63]],"ltp":4.2,"tv":54.88,"id":13014431}]}]}
{"op":"mcm","clk":"1011638696","pt":1580657090165,"mc":[{"id":"1.168223928","rc":[{"batb":[[1,1.01,0.51],[2,1.01,0]],"ltp":0.0,"tv":0.0,"id":13015338},{"batb":[[0,2.16,48.63],[1,1.01,1.41],[2,2.16,0]],"ltp":4.2,"tv":54.88,"id":13014431}]}]}
{"op":"mcm","clk":"1011639406","pt":1580657093255,"mc":[{"id":"1.168223928","rc":[{"batb":[[0,3.95,103.6],[1,3.9,107.93],[2,1.01,0.51]],"ltp":0.0,"tv":0.0,"id":13015338},{"batb":[[0,2.7,98.47],[1,2.66,120.31],[2,2.16,48.63]],"ltp":4.2,"tv":54.88,"id":13014431}]}]}
{"op":"mcm","clk":"1011639630","pt":1580657094261,"mc":[{"id":"1.168223928","rc":[{"batb":[[2,4.5,11.76]],"batl":[[0,5.3,40.87],[1,8.8,21.24]],"ltp":2.54,"tv":572.23,"id":13015339},{"batb":[[0,3.95,165.12],[1,3.9,57.26],[2,3.8,52.56]],"batl":[[1,4.6,54.28]],"ltp":0.0,"tv":0.0,"id":13015338},{"batb":[[2,2.62,29.03]],"batl":[[1,2.92,21.85],[2,3.1,21.48]],"ltp":4.2,"tv":54.88,"id":13014431},{"batb":[[0,5,27.62]],"batl":[[0,5.4,9.24],[1,5.8,25.34]],"ltp":0.0,"tv":0.0,"id":13014430}]}]}
{"op":"mcm","clk":"1011643028","pt":1580657108942,"mc":[{"id":"1.168223928","rc":[{"batb":[[0,3.85,51.22],[1,1.01,1.41],[2,4.5,0]],"batl":[[0,8.8,21.24],[1,8.8,0]],"ltp":2.54,"tv":572.23,"id":13015339},{"batb":[[0,3.8,52.56],[1,1.01,0.51],[2,3.8,0]],"batl":[[0,4.6,43.35],[1,4.6,0]],"ltp":0.0,"tv":0.0,"id":13015338},{"batb":[[0,2.2,46.11],[1,1.01,1.41],[2,2.62,0]],"batl":[[0,3.1,21.48],[1,2.92,0],[2,3.1,0]],"ltp":4.2,"tv":54.88,"id":13014431},{"batl":[[0,5.8,25.34],[1,5.8,0]],"ltp":0.0,"tv":0.0,"id":13014430}]}]}
{"op":"mcm","clk":"1011643657","pt":1580657111952,"mc":[{"id":"1.168223928","rc":[{"batb":[[0,3.95,61.14],[1,3.9,107.73],[2,1.01,1.41]],"batl":[[0,9,20.85]],"ltp":2.54,"tv":572.23,"id":13015339},{"batb":[[0,3.85,51.62]],"batl":[[0,4.6,42.72]],"ltp":0.0,"tv":0.0,"id":13015338}]}]}
{"op":"mcm","clk":"1011644450","pt":1580657115069,"mc":[{"id":"1.168223928","rc":[{"batb":[[0,4,121.29],[1,3.95,55.06],[2,3.85,51.62]],"ltp":0.0,"tv":0.0,"id":13015338},{"batb":[[0,3,128.91],[1,2.96,91.18],[2,2.2,46.11]],"ltp":4.2,"tv":54.88,"id":13014431},{"batb":[[1,4.9,88.18]],"ltp":0.0,"tv":0.0,"id":13014430}]}]}
{"op":"mcm","clk":"1011644713","pt":1580657116204,"mc":[{"id":"1.168223928","rc":[{"batb":[[2,3.8,14.28]],"batl":[[0,4.4,59.44],[1,8.8,21.95]],"ltp":2.54,"tv":572.23,"id":13015339},{"batb":[[0,4.1,58.45],[1,4,121.29],[2,3.95,55.06]],"batl":[[1,4.7,10.92],[2,4.8,39.58]],"ltp":0.0,"tv":0.0,"id":13015338},{"batb":[[2,2.9,22.19]],"batl":[[1,3.25,18.48],[2,3.7,34.86]],"ltp":4.2,"tv":54.88,"id":13014431},{"batl":[[0,5.4,9.24],[1,5.7,26.12]],"ltp":0.0,"tv":0.0,"id":13014430}]}]}
{"op":"mcm","clk":"1011647103","pt":1580657127011,"mc":[{"id":"1.168223928","rc":[{"batb":[[0,3.15,42.96],[1,1.01,1.41],[2,3.8,0]],"batl":[[0,8.8,21.95],[1,8.8,0]],"ltp":2.54,"tv":572.23,"id":13015339},{"batb":[[0,3.8,26.44],[1,1.01,0.51],[2,3.95,0]],"batl":[[0,4.8,39.58],[1,4.7,0],[2,4.8,0]],"ltp":0.0,"tv":0.0,"id":13015338},{"batb":[[0,2.22,44.93],[1,1.01,1.41],[2,2.9,0]],"batl":[[0,3.7,34.86],[1,3.25,0],[2,3.7,0]],"ltp":4.2,"tv":54.88,"id":13014431},{"batb":[[1,4.9,51.27]],"batl":[[0,5.7,26.12],[1,5.7,0]],"ltp":0.0,"tv":0.0,"id":13014430}]}]}
{"op":"mcm","clk":"1011648194","pt":1580657131992,"mc":[{"id":"1.168223928","rc":[{"batb":[[0,4.3,134.64],[1,4.2,93.82],[2,3.15,42.96]],"ltp":2.54,"tv":572.23,"id":13015339},{"batb":[[0,4,70.92],[1,3.95,55.52],[2,3.8,26.44]],"ltp":0.0,"tv":0.0,"id":13015338},{"batb":[[0,2.84,74.48],[1,2.8,105.47],[2,2.22,44.93]],"ltp":4.2,"tv":54.88,"id":13014431},{"batb":[[1,4.9,80.7]],"ltp":0.0,"tv":0.0,"id":13014430}]}]}
{"op":"mcm","clk":"1011649015","pt":1580657136069,"mc":[{"id":"1.168223928","rc":[{"batb":[[0,3.15,42.96],[1,1.01,1.41],[2,3.15,0]],"ltp":2.54,"tv":572.23,"id":13015339},{"batb":[[0,3.8,26.44],[1,1.01,0.51],[2,3.8,0]],"ltp":0.0,"tv":0.0,"id":13015338},{"batb":[[0,2.22,44.93],[1,1.01,1.41],[2,2.22,0]],"ltp":4.2,"tv":54.88,"id":13014431},{"batb":[[1,4.9,51.91]],"ltp":0.0,"tv":0.0,"id":13014430}]}]}
{"op":"mcm","clk":"1011649710","pt":1580657139204,"mc":[{"id":"1.168223928","rc":[{"batb":[[1,3.1,157.27],[2,3.05,103.29]],"ltp":2.54,"tv":572.23,"id":13015339}]}]}
{"op":"mcm","clk":"1011650138","pt":1580657141226,"mc":[{"id":"1.168223928","rc":[{"batb":[[0,4.1,142.74],[1,4,105.08],[2,3.8,26.44]],"ltp":0.0,"tv":0.0,"id":13015338},{"batb":[[0,3.65,59.97],[1,3.6,70.66],[2,2.22,44.93]],"ltp":4.2,"tv":54.88,"id":13014431},{"batb":[[1,4.9,108.68]],"ltp":0.0,"tv":0.0,"id":13014430}]}]}
{"op":"mcm","clk":"1011650374","pt":1580657142065,"mc":[{"id":"1.168223928","rc":[{"batb":[[0,3.15,62.28]],"batl":[[0,3.45,41.39],[1,3.55,15.96],[2,4.5,44.61]],"ltp":2.54,"tv":572.23,"id":13015339},{"batb":[[0,4.2,54.3],[1,4.1,187.2],[2,4,105.08]],"batl":[[0,4.8,38.16],[1,4.9,10.08]],"ltp":0.0,"tv":0.0,"id":13015338},{"batb":[[2,3.45,36.04]],"batl":[[1,3.85,14.28],[2,4.2,26.52]],"ltp":4.2,"tv":54.88,"id":13014431},{"batl":[[0,5.3,9.24],[1,5.6,27.15],[2,5.7,26.12]],"ltp":0.0,"tv":0.0,"id":13014430}]}]}
{"op":"mcm","clk":"1011653329","pt":1580657156077,"mc":[{"id":"1.168223928","rc":[{"batb":[[0,3.15,19.32],[1,2.84,22.27],[2,1.01,1.41]],"batl":[[0,3.55,15.96],[1,4.5,44.61],[2,4.5,0]],"ltp":2.54,"tv":572.23,"id":13015339},{"batb":[[0,4.2,12.6],[1,4.1,44.46]],"ltp":0.0,"tv":0.0,"id":13015338},{"batb":[[0,3.35,17.64],[1,2.84,23.53],[2,1.01,1.41]],"batl":[[0,3.85,14.28],[1,4.2,26.52],[2,4.2,0]],"ltp":4.2,"tv":54.88,"id":13014431},{"batb":[[1,4.9,83.7]],"batl":[[1,5.7,26.12],[2,5.7,0]],"ltp":0.0,"tv":0.0,"id":13014430}]}]}
{"op":"mcm","clk":"1011653530","pt":1580657156950,"mc":[{"id":"1.168223928","rc":[{"batb":[[0,2.84,22.27],[1,1.01,1.41],[2,1.01,0]],"batl":[[0,4.5,44.61],[1,4.5,0]],"ltp":2.54,"tv":572.23,"id":13015339},{"batb":[[0,4.1,44.46],[1,4,105.08],[2,1.01,0.51]],"batl":[[1,4.9,0]],"ltp":0.0,"tv":0.0,"id":13015338},{"batb":[[0,2.84,23.53],[1,1.01,1.41],[2,1.01,0]],"batl":[[0,4.2,26.52],[1,4.2,0]],"ltp":4.2,"tv":54.88,"id":13014431},{"batl":[[0,5.7,26.12],[1,5.7,0]],"ltp":0.0,"tv":0.0,"id":13014430}]}]}
{"op":"mcm","clk":"1011653920","pt":1580657159044,"mc":[{"id":"1.168223928","rc":[{"batb":[[1,2.82,104.1],[2,2.78,105.59]],"ltp":2.54,"tv":572.23,"id":13015339},{"batb":[[1,4,134.88],[2,3.95,54.93]],"ltp":0.0,"tv":0.0,"id":13015338},{"batb":[[0,2.98,91.23],[1,2.94,93.04],[2,2.84,23.53]],"ltp":4.2,"tv":54.88,"id":13014431}]}]}
{"op":"mcm","clk":"1011654718","pt":1580657163063,"mc":[{"id":"1.168223928","rc":[{"batb":[[1,1.01,0.51],[2,3.95,0]],"ltp":0.0,"tv":0.0,"id":13015338},{"batb":[[0,2.84,23.53],[1,1.01,1.41],[2,2.84,0]],"ltp":4.2,"tv":54.88,"id":13014431},{"batb":[[1,4.9,68.4],[2,1.01,0.51]],"ltp":0.0,"tv":0.0,"id":13014430}]}]}
{"op":"mcm","clk":"1011655373","pt":1580657166257,"mc":[{"id":"1.168223928","rc":[{"batb":[[0,2.84,44.95]],"batl":[[0,3.05,21.87],[1,3.2,18.48],[2,3.5,39.03]],"ltp":2.54,"tv":572.23,"id":13015339},{"batb":[[0,4.3,12.6],[1,4.2,140.82],[2,4.1,99.86]],"batl":[[0,4.9,37.3],[1,5,10.08]],"ltp":0.0,"tv":0.0,"id":13015338},{"batb":[[0,4.1,73.94],[1,4,108.49],[2,3.85,27.3]],"batl":[[1,4.3,12.6],[2,4.6,43.2]],"ltp":4.2,"tv":54.88,"id":13014431},{"batb":[[0,5,79.69],[2,4.5,11.76]],"batl":[[0,5.3,9.24],[1,5.7,26.12]],"ltp":0.0,"tv":0.0,"id":13014430}]}]}
{"op":"mcm","clk":"1011658147","pt":1580657178153,"mc":[{"id":"1.168223928","rc":[{"batb":[[0,2.84,22.69],[1,2.68,26.28],[2,1.01,1.41]],"batl":[[0,3.2,18.48],[1,3.5,39.03],[2,3.5,0]],"ltp":2.54,"tv":572.23,"id":13015339},{"batb":[[1,4.2,89.74]],"ltp":0.0,"tv":0.0,"id":13015338},{"batb":[[0,3.3,39.03],[1,1.01,1.41],[2,3.85,0]],"batl":[[0,4.3,12.6],[1,4.6,43.2],[2,4.6,0]],"ltp":4.2,"tv":54.88,"id":13014431},{"batb":[[0,5,27.62]],"ltp":0.0,"tv":0.0,"id":13014430}]}]}
{"op":"mcm","clk":"1011658290","pt":1580657178872,"mc":[{"id":"1.168223928","rc":[{"batb":[[0,2.68,26.28],[1,1.01,1.41],[2,1.01,0]],"batl":[[0,3.5,39.03],[1,3.5,0]],"ltp":2.54,"tv":572.23,"id":13015339},{"batb":[[0,4.2,89.74],[1,4.1,99.86],[2,1.01,0.51]],"batl":[[1,5,0]],"ltp":0.0,"tv":0.0,"id":13015338},{"batl":[[0,4.6,43.2],[1,4.6,0]],"ltp":4.2,"tv":54.88,"id":13014431},{"batb":[[2,1.01,0.51]],"batl":[[0,5.7,26.12],[1,5.7,0]],"ltp":0.0,"tv":0.0,"id":13014430}]}]}
{"op":"mcm","clk":"1011658695","pt":1580657180773,"mc":[{"id":"1.168223928","rc":[{"batb":[[0,2.68,112.56],[1,2.64,120.99],[2,1.01,1.41]],"ltp":2.54,"tv":572.23,"id":13015339},{"batb":[[0,3.55,129.37],[1,3.5,75],[2,3.3,39.03]],"ltp":4.2,"tv":54.88,"id":13014431},{"batb":[[1,4.9,98.04],[2,4.8,70.95]],"ltp":0.0,"tv":0.0,"id":13014430}]}]}
{"op":"mcm","clk":"1011659279","pt":1580657183262,"mc":[{"id":"1.168223928","rc":[{"batb":[[0,2.68,26.28],[1,1.01,1.41],[2,1.01,0]],"ltp":2.54,"tv":572.23,"id":13015339},{"batb":[[0,3.3,39.03],[1,1.01,1.41],[2,3.3,0]],"ltp":4.2,"tv":54.88,"id":13014431},{"batb":[[1,4.9,68.47],[2,1.01,0.51]],"ltp":0.0,"tv":0.0,"id":13014430}]}]}
{"op":"mcm","clk":"1011659752","pt":1580657185619,"mc":[{"id":"1.168223928","rc":[{"batb":[[0,2.88,111.86],[1,2.84,99.86],[2,2.68,26.28]],"ltp":2.54,"tv":572.23,"id":13015339},{"batb":[[0,4.2,130.58]],"ltp":0.0,"tv":0.0,"id":13015338},{"batb":[[0,4,58.29],[1,3.95,56.71],[2,3.3,39.03]],"ltp":4.2,"tv":54.88,"id":13014431},{"batb":[[0,5,75.01]],"ltp":0.0,"tv":0.0,"id":13014430}]}]}
{"op":"mcm","clk":"1011660089","pt":1580657187196,"mc":[{"id":"1.168223928","rc":[{"batb":[[0,2.68,26.28],[1,1.01,1.41],[2,2.68,0]],"ltp":2.54,"tv":572.23,"id":13015339},{"batb":[[0,4.2,89.74]],"ltp":0.0,"tv":0.0,"id":13015338},{"batb":[[0,3.3,39.03],[1,1.01,1.41],[2,3.3,0]],"ltp":4.2,"tv":54.88,"id":13014431},{"batb":[[0,5,27.62]],"ltp":0.0,"tv":0.0,"id":13014430}]}]}
{"op":"mcm","clk":"1011660674","pt":1580657189787,"mc":[{"id":"1.168223928","rc":[{"batb":[[0,2.68,112.56],[1,2.64,120.99],[2,1.01,1.41]],"ltp":2.54,"tv":572.23,"id":13015339},{"batb":[[0,3.55,129.37],[1,3.5,75],[2,3.3,39.03]],"ltp":4.2,"tv":54.88,"id":13014431},{"batb":[[1,4.9,98.04],[2,4.8,70.95]],"ltp":0.0,"tv":0.0,"id":13014430}]}]}
{"op":"mcm","clk":"1011662193","pt":1580657196922,"mc":[{"id":"1.168223928","rc":[{"batb":[[0,2.68,26.28],[1,1.01,1.41],[2,1.01,0]],"ltp":2.54,"tv":572.23,"id":13015339}]}]}
{"op":"mcm","clk":"1011662930","pt":1580657200195,"mc":[{"id":"1.168223928","rc":[{"batb":[[0,3.15,138.77],[1,3.1,99.31],[2,2.68,26.28]],"batl":[[1,3.55,15.96]],"ltp":2.54,"tv":572.23,"id":13015339},{"batb":[[2,3.35,17.64]],"batl":[[0,3.85,14.28],[1,4.6,43.2]],"ltp":4.2,"tv":54.88,"id":13014431},{"batl":[[0,5.3,9.24],[1,5.7,26.12]],"ltp":0.0,"tv":0.0,"id":13014430}]}]}
{"op":"mcm","clk":"1011663146","pt":1580657201218,"mc":[{"id":"1.168223928","rc":[{"batb":[[0,3.2,40.44],[1,3.15,158.09],[2,3.1,99.31]],"batl":[[2,4.6,41.94]],"ltp":2.54,"tv":572.23,"id":13015339},{"batb":[[0,4.3,12.6],[1,4.2,89.74],[2,4.1,144]],"batl":[[0,4.8,38],[1,5,10.08]],"ltp":0.0,"tv":0.0,"id":13015338},{"batl":[[0,3.6,37.61],[1,3.85,14.28],[2,4.1,28.4]],"ltp":4.2,"tv":54.88,"id":13014431}]}]}
{"op":"mcm","clk":"1011666432","pt":1580657216253,"mc":[{"id":"1.168223928","rc":[{"batb":[[0,3.15,19.32],[1,2.9,21.24],[2,1.01,1.41]],"batl":[[0,3.55,15.96],[1,4.6,41.94],[2,4.6,0]],"ltp":2.54,"tv":572.23,"id":13015339},{"batb":[[1,4.1,44.14],[2,1.01,0.51]],"ltp":0.0,"tv":0.0,"id":13015338},{"batb":[[0,3.35,17.64],[1,2.78,24.86],[2,1.01,1.41]],"batl":[[0,3.85,14.28],[1,4.1,28.4],[2,4.1,0]],"ltp":4.2,"tv":54.88,"id":13014431},{"batb":[[1,4.9,78.72]],"ltp":0.0,"tv":0.0,"id":13014430}]}]}
{"op":"mcm","clk":"1011666694","pt":1580657217271,"mc":[{"id":"1.168223928","rc":[{"batb":[[0,2.9,21.24],[1,1.01,1.41],[2,1.01,0]],"batl":[[0,4.6,41.94],[1,4.6,0]],"ltp":2.54,"tv":572.23,"id":13015339},{"batb":[[0,4.1,44.14],[1,1.01,0.51],[2,1.01,0]],"batl":[[1,5,0]],"ltp":0.0,"tv":0.0,"id":13015338},{"batb":[[0,2.78,24.86],[1,1.01,1.41],[2,1.01,0]],"batl":[[0,4.1,28.4],[1,4.1,0]],"ltp":4.2,"tv":54.88,"id":13014431},{"batl":[[0,5.7,26.12],[1,5.7,0]],"ltp":0.0,"tv":0.0,"id":13014430}]}]}
{"op":"mcm","clk":"1011667081","pt":1580657219089,"mc":[{"id":"1.168223928","rc":[{"batb":[[1,2.86,83.97],[2,2.82,101.9]],"ltp":2.54,"tv":572.23,"id":13015339},{"batb":[[1,4,150.37],[2,3.95,54.8]],"ltp":0.0,"tv":0.0,"id":13015338},{"batb":[[0,2.94,97.29],[1,2.9,96.29],[2,2.78,24.86]],"ltp":4.2,"tv":54.88,"id":13014431}]}]}
{"op":"mcm","clk":"1011671852","pt":1580657240148,"mc":[{"id":"1.168223928","rc":[{"batb":[[1,1.01,0.51],[2,3.95,0]],"ltp":0.0,"tv":0.0,"id":13015338},{"batb":[[0,2.78,24.86],[1,1.01,1.41],[2,2.78,0]],"ltp":4.2,"tv":54.88,"id":13014431}]}]}
{"op":"mcm","clk":"1011672456","pt":1580657243120,"mc":[{"id":"1.168223928","rc":[{"batb":[[0,4.2,104.37],[1,4.1,143.92],[2,1.01,0.51]],"ltp":0.0,"tv":0.0,"id":13015338},{"batb":[[0,4,120.96],[1,3.95,56.18],[2,2.78,24.86]],"ltp":4.2,"tv":54.88,"id":13014431},{"batb":[[1,4.9,108.13]],"ltp":0.0,"tv":0.0,"id":13014430}]}]}
{"op":"mcm","clk":"1011672680","pt":1580657244179,"mc":[{"id":"1.168223928","rc":[{"batb":[[0,2.9,43.09]],"batl":[[0,3.15,51.14],[1,3.25,18.48],[2,3.6,36.35]],"ltp":2.54,"tv":572.23,"id":13015339},{"batb":[[0,4.3,12.6],[1,4.2,145.91],[2,4.1,99.78]],"batl":[[0,4.9,37.37],[1,5,10.08]],"ltp":0.0,"tv":0.0,"id":13015338},{"batb":[[2,3.75,29.19]],"batl":[[1,4.3,12.6],[2,4.5,46.58]],"ltp":4.2,"tv":54.88,"id":13014431},{"batl":[[0,5.3,9.24],[1,5.6,27.15]],"ltp":0.0,"tv":0.0,"id":13014430}]}]}
{"op":"mcm","clk":"1011678530","pt":1580657270927,"mc":[{"id":"1.168223928","rc":[{"batb":[[0,2.9,21.24]],"ltp":2.54,"tv":572.23,"id":13015339}]}]}
{"op":"mcm","clk":"1011678786","pt":1580657272124,"mc":[{"id":"1.168223928","rc":[{"batb":[[1,2.74,24.63],[2,1.01,1.41]],"ltp":2.54,"tv":572.23,"id":13015339},{"batb":[[1,4.2,97.94]],"ltp":0.0,"tv":0.0,"id":13015338},{"batb":[[0,3.75,29.19],[1,3.25,41.31],[2,1.01,1.41]],"ltp":4.2,"tv":54.88,"id":13014431},{"batb":[[1,4.9,87.99]],"ltp":0.0,"tv":0.0,"id":13014430}]}]}
{"op":"mcm","clk":"1011678978","pt":1580657272944,"mc":[{"id":"1.168223928","rc":[{"batb":[[0,2.74,24.63],[1,1.01,1.41],[2,1.01,0]],"batl":[[0,3.6,36.35],[1,3.25,0],[2,3.6,0]],"ltp":2.54,"tv":572.23,"id":13015339},{"batb":[[0,4.2,97.94],[1,4.1,99.78],[2,1.01,0.51]],"batl":[[1,5,0]],"ltp":0.0,"tv":0.0,"id":13015338},{"batb":[[0,3.25,41.31],[1,1.01,1.41],[2,1.01,0]],"batl":[[0,4.5,46.58],[1,4.3,0],[2,4.5,0]],"ltp":4.2,"tv":54.88,"id":13014431},{"batl":[[0,5.6,27.15],[1,5.6,0]],"ltp":0.0,"tv":0.0,"id":13014430}]}]}
{"op":"mcm","clk":"1011679492","pt":1580657275130,"mc":[{"id":"1.168223928","rc":[{"batb":[[1,2.7,109.66],[2,2.66,118.48]],"ltp":2.54,"tv":572.23,"id":13015339},{"batb":[[0,3.5,128.62],[1,3.45,77.64],[2,3.25,41.31]],"ltp":4.2,"tv":54.88,"id":13014431}]}]}
{"op":"mcm","clk":"1011679737","pt":1580657276226,"mc":[{"id":"1.168223928","rc":[{"batb":[[0,2.72,24.94],[1,1.01,1.41],[2,2.66,0]],"ltp":2.54,"tv":572.23,"id":13015339},{"batb":[[0,3.25,40.76],[1,1.01,1.41],[2,3.25,0]],"batl":[[0,4.5,45.87]],"ltp":4.2,"tv":54.88,"id":13014431}]}]}
{"op":"mcm","clk":"1011680411","pt":1580657279077,"mc":[{"id":"1.168223928","rc":[{"batb":[[0,2.92,99.57],[1,2.88,96.45],[2,2.72,24.94]],"ltp":2.54,"tv":572.23,"id":13015339},{"batb":[[0,4.2,136.15]],"ltp":0.0,"tv":0.0,"id":13015338},{"batb":[[0,3.9,107.04],[1,3.85,59.8],[2,3.25,40.76]],"ltp":4.2,"tv":54.88,"id":13014431},{"batb":[[1,4.9,103.98]],"ltp":0.0,"tv":0.0,"id":13014430}]}]}
{"op":"mcm","clk":"1011680937","pt":1580657281272,"mc":[{"id":"1.168223928","rc":[{"batb":[[0,2.72,24.94],[1,1.01,1.41],[2,2.72,0]],"ltp":2.54,"tv":572.23,"id":13015339},{"batb":[[0,4.2,97.94]],"ltp":0.0,"tv":0.0,"id":13015338},{"batb":[[0,3.25,40.76],[1,1.01,1.41],[2,3.25,0]],"ltp":4.2,"tv":54.88,"id":13014431},{"batb":[[1,4.9,87.99]],"ltp":0.0,"tv":0.0,"id":13014430}]}]}
{"op":"mcm","clk":"1011681532","pt":1580657284198,"mc":[{"id":"1.168223928","rc":[{"batb":[[1,2.7,109.66],[2,2.66,118.48]],"ltp":2.54,"tv":572.23,"id":13015339},{"batb":[[0,3.5,128.62],[1,3.45,77.64],[2,3.25,40.76]],"ltp":4.2,"tv":54.88,"id":13014431}]}]}
{"op":"mcm","clk":"1011685158","pt":1580657300926,"mc":[{"id":"1.168223928","rc":[{"batb":[[1,1.01,1.41],[2,2.66,0]],"ltp":2.54,"tv":572.23,"id":13015339},{"batb":[[0,3.25,40.76],[1,1.01,1.41],[2,3.25,0]],"ltp":4.2,"tv":54.88,"id":13014431},{"batb":[[1,4.9,68.47],[2,1.01,0.51]],"ltp":0.0,"tv":0.0,"id":13014430}]}]}
{"op":"mcm","clk":"1011685882","pt":1580657304221,"mc":[{"id":"1.168223928","rc":[{"batb":[[0,2.72,49.31],[1,2.7,109.67],[2,2.66,118.49]],"batl":[[0,2.9,24.55],[1,3,21],[2,3.1,52.24]],"ltp":2.54,"tv":572.23,"id":13015339},{"batb":[[0,4.3,52.73],[1,4.2,128.37],[2,4.1,99.78]],"batl":[[1,5,46.28]],"ltp":0.0,"tv":0.0,"id":13015338},{"batb":[[0,4.3,124.23],[1,4.2,95.95],[2,4,61.91]],"batl":[[1,4.7,10.92],[2,5.4,30.84]],"ltp":4.2,"tv":54.88,"id":13014431},{"batb":[[0,5,76.3],[2,4.5,11.76]],"batl":[[0,5.3,9.24],[1,5.6,27.15]],"ltp":0.0,"tv":0.0,"id":13014430}]}]}
{"op":"mcm","clk":"1011693483","pt":1580657338258,"mc":[{"id":"1.168223928","rc":[{"batb":[[2,4,61.75]],"ltp":4.2,"tv":54.88,"id":13014431}]}]}
{"op":"mcm","clk":"1011695892","pt":1580657348703,"mc":[{"id":"1.168223928","rc":[{"batl":[[0,2.88,24.86],[2,3.1,21.24]],"ltp":2.54,"tv":572.23,"id":13015339},{"batl":[[0,4.9,36.67],[1,5,10.08]],"ltp":0.0,"tv":0.0,"id":13015338},{"batb":[[2,4,61.05]],"batl":[[0,4.5,45.08],[2,5.4,30.29]],"ltp":4.2,"tv":54.88,"id":13014431},{"batl":[[1,5.7,26.75]],"ltp":0.0,"tv":0.0,"id":13014430}]}]}
{"op":"mcm","clk":"1011705830","pt":1580657394993,"mc":[{"id":"1.168223928","rc":[{"batb":[[0,2.44,33.28],[1,1.01,1.41],[2,2.66,0]],"batl":[[0,3.1,21.24],[1,3,0],[2,3.1,0]],"ltp":2.54,"tv":572.23,"id":13015339},{"batb":[[0,4.3,40.13],[1,4.2,98.22]],"batl":[[1,5,0]],"ltp":0.0,"tv":0.0,"id":13015338},{"batb":[[0,3.8,28.33],[1,1.01,1.41],[2,4,0]],"batl":[[0,5.4,30.29],[1,4.7,0],[2,5.4,0]],"ltp":4.2,"tv":54.88,"id":13014431},{"batb":[[0,5,27.62],[2,1.01,0.51]],"batl":[[0,5.7,26.75],[1,5.7,0]],"ltp":0.0,"tv":0.0,"id":13014430}]}]}
{"op":"mcm","clk":"1011706243","pt":1580657397083,"mc":[{"id":"1.168223928","rc":[{"batb":[[1,4.9,68.4]],"ltp":0.0,"tv":0.0,"id":13014430}]}]}
{"op":"mcm","clk":"1011706768","pt":1580657399444,"mc":[{"id":"1.168223928","rc":[{"batb":[[0,2.64,128.6],[1,2.6,125.75],[2,2.44,33.28]],"ltp":2.54,"tv":572.23,"id":13015339},{"batb":[[1,4.2,139.77]],"ltp":0.0,"tv":0.0,"id":13015338},{"batb":[[0,4.5,58.58],[1,4.4,87.18],[2,3.8,28.33]],"ltp":4.2,"tv":54.88,"id":13014431},{"batb":[[0,5,82.43]],"ltp":0.0,"tv":0.0,"id":13014430}]}]}
{"op":"mcm","clk":"1011707328","pt":1580657401703,"mc":[{"id":"1.168223928","rc":[{"batb":[[0,2.44,33.28],[1,1.01,1.41],[2,2.44,0]],"ltp":2.54,"tv":572.23,"id":13015339},{"batb":[[1,4.2,98.22],[2,1.01,0.51]],"ltp":0.0,"tv":0.0,"id":13015338},{"batb":[[0,4.4,87.18],[1,3.8,28.33],[2,1.01,1.41]],"ltp":4.2,"tv":54.88,"id":13014431},{"batb":[[0,5,27.62]],"ltp":0.0,"tv":0.0,"id":13014430}]}]}
{"op":"mcm","clk":"1011708053","pt":1580657404882,"mc":[{"id":"1.168223928","rc":[{"batb":[[0,3.8,28.33],[1,1.01,1.41],[2,1.01,0]],"ltp":4.2,"tv":54.88,"id":13014431},{"batb":[[1,4.9,79.87],[2,4.8,70.53]],"ltp":0.0,"tv":0.0,"id":13014430}]}]}
{"op":"mcm","clk":"1011708839","pt":1580657408067,"mc":[{"id":"1.168223928","rc":[{"batb":[[0,2.46,109.44],[1,2.44,33.28],[2,2.42,153.06]],"ltp":2.54,"tv":572.23,"id":13015339},{"batb":[[1,4.2,118.27],[2,4.1,99.88]],"ltp":0.0,"tv":0.0,"id":13015338},{"batb":[[0,4,94.49],[1,3.95,56.12],[2,3.8,28.33]],"ltp":4.2,"tv":54.88,"id":13014431}]}]}
{"op":"mcm","clk":"1011709865","pt":1580657412791,"mc":[{"id":"1.168223928","rc":[{"batb":[[0,2.44,33.28],[1,1.01,1.41],[2,2.42,0]],"ltp":2.54,"tv":572.23,"id":13015339},{"batb":[[1,4.2,98.22],[2,1.01,0.51]],"ltp":0.0,"tv":0.0,"id":13015338},{"batb":[[0,3.8,28.33],[1,1.01,1.41],[2,3.8,0]],"ltp":4.2,"tv":54.88,"id":13014431},{"batb":[[1,4.9,68.4],[2,1.01,0.51]],"ltp":0.0,"tv":0.0,"id":13014430}]}]}
{"op":"mcm","clk":"1011710570","pt":1580657415962,"mc":[{"id":"1.168223928","rc":[{"batb":[[0,2.46,138.03],[1,2.44,33.28],[2,2.42,153.06]],"batl":[[0,2.76,23.53],[1,3.1,21.24]],"ltp":2.54,"tv":572.23,"id":13015339},{"batb":[[0,4.3,158.85]],"batl":[[1,5,10.08]],"ltp":0.0,"tv":0.0,"id":13015338},{"batb":[[0,5.1,43.69],[1,5,65.06],[2,4.6,10.92]],"batl":[[0,5.4,39.53]],"ltp":4.2,"tv":54.88,"id":13014431},{"batb":[[0,5,83.83],[2,4.6,10.92]],"batl":[[0,5.4,9.24],[1,5.7,26.75]],"ltp":0.0,"tv":0.0,"id":13014430}]}]}
{"op":"mcm","clk":"1011710751","pt":1580657416765,"mc":[{"id":"1.168223928","rc":[{"batl":[[0,2.58,33.05],[1,2.76,23.53],[2,2.78,27.3]],"ltp":2.54,"tv":572.23,"id":13015339},{"batb":[[0,4.4,38.48],[1,4.3,158.46],[2,4.2,98.22]],"batl":[[0,5,10.08],[1,5.1,33.75]],"ltp":0.0,"tv":0.0,"id":13015338},{"batb":[[2,4.8,31.63]],"batl":[[1,7.2,32.73]],"ltp":4.2,"tv":54.88,"id":13014431},{"batl":[[1,5.8,25.97]],"ltp":0.0,"tv":0.0,"id":13014430}]}]}
{"op":"mcm","clk":"1011711739","pt":1580657421206,"mc":[{"id":"1.168223928","rc":[{"batb":[[0,2.46,28.57],[2,2.12,49.1]],"ltp":2.54,"tv":572.23,"id":13015339},{"batb":[[1,4.3,139.54]],"ltp":0.0,"tv":0.0,"id":13015338}]}]}
{"op":"mcm","clk":"1011711875","pt":1580657421813,"mc":[{"id":"1.168223928","rc":[{"batb":[[0,2.44,33.28],[1,2.12,49.1],[2,1.01,1.41]],"batl":[[1,2.78,27.3],[2,2.78,0]],"ltp":2.54,"tv":572.23,"id":13015339},{"batl":[[0,5.4,30.29]],"ltp":4.2,"tv":54.88,"id":13014431}]}]}
{"op":"mcm","clk":"1011712405","pt":1580657424198,"mc":[{"id":"1.168223928","rc":[{"batb":[[0,2.44,204.57],[1,2.4,156.11],[2,2.12,49.1]],"batl":[[1,2.72,24.37],[2,2.78,27.3]],"ltp":2.54,"tv":572.23,"id":13015339},{"batb":[[0,5.1,68.99]],"batl":[[1,5.5,9.24],[2,7.2,32.73]],"ltp":4.2,"tv":54.88,"id":13014431},{"batb":[[0,5,109.72]],"ltp":0.0,"tv":0.0,"id":13014430}]}]}
{"op":"mcm","clk":"1011714170","pt":1580657432235,"mc":[{"id":"1.168223928","rc":[{"batb":[[0,2.44,61.85],[1,2.12,49.1],[2,1.01,1.41]],"ltp":2.54,"tv":572.23,"id":13015339},{"batb":[[1,4.3,52.34]],"ltp":0.0,"tv":0.0,"id":13015338},{"batb":[[0,4.8,31.63],[1,4.7,10.92],[2,4.3,41.62]],"ltp":4.2,"tv":54.88,"id":13014431},{"batb":[[0,5,92.09]],"ltp":0.0,"tv":0.0,"id":13014430}]}]}
{"op":"mcm","clk":"1011714346","pt":1580657432997,"mc":[{"id":"1.168223928","rc":[{"batb":[[0,2.12,49.1],[1,1.01,1.41],[2,1.01,0]],"batl":[[0,2.78,27.3],[1,2.72,0],[2,2.78,0]],"ltp":2.54,"tv":572.23,"id":13015339},{"batb":[[0,4.3,39.73],[1,4.2,98.22],[2,1.01,0.51]],"batl":[[0,5.1,33.75],[1,5.1,0]],"ltp":0.0,"tv":0.0,"id":13015338},{"batb":[[0,4.3,41.62],[1,1.01,1.41],[2,4.3,0]],"batl":[[0,7.2,32.73],[1,5.5,0],[2,7.2,0]],"ltp":4.2,"tv":54.88,"id":13014431},{"batb":[[2,1.01,0.51]],"batl":[[0,5.8,25.97],[1,5.8,0]],"ltp":0.0,"tv":0.0,"id":13014430}]}]}
{"op":"mcm","clk":"1011714818","pt":1580657435214,"mc":[{"id":"1.168223928","rc":[{"batb":[[0,2.16,171.33],[1,2.14,108.96],[2,2.12,49.1]],"ltp":2.54,"tv":572.23,"id":13015339},{"batb":[[1,4.2,133.77],[2,4.1,99.28]],"ltp":0.0,"tv":0.0,"id":13015338},{"batb":[[0,4.5,93.62],[1,4.4,86.69],[2,4.3,41.62]],"ltp":4.2,"tv":54.88,"id":13014431}]}]}
{"op":"mcm","clk":"1011714920","pt":1580657435693,"mc":[{"id":"1.168223928","rc":[{"batl":[[0,2.76,27.93]],"ltp":2.54,"tv":572.23,"id":13015339},{"batb":[[2,4.3,40.44]],"batl":[[0,7.4,31.71]],"ltp":4.2,"tv":54.88,"id":13014431},{"batb":[[0,5.1,27.3],[1,5,64.47],[2,4.9,68.4]],"batl":[[0,5.8,25.34]],"ltp":0.0,"tv":0.0,"id":13014430}]}]}
{"op":"mcm","clk":"1011716349","pt":1580657442228,"mc":[{"id":"1.168223928","rc":[{"batb":[[1,1.01,0.51],[2,4.1,0]],"ltp":0.0,"tv":0.0,"id":13015338},{"batb":[[0,4.3,40.44],[1,1.01,1.41],[2,4.3,0]],"ltp":4.2,"tv":54.88,"id":13014431},{"batb":[[2,1.01,0.51]],"ltp":0.0,"tv":0.0,"id":13014430}]}]}
{"op":"mcm","clk":"1011717079","pt":1580657445246,"mc":[{"id":"1.168223928","rc":[{"batb":[[0,4.4,87.42],[1,4.3,129.3],[2,1.01,0.51]],"ltp":0.0,"tv":0.0,"id":13015338},{"batb":[[0,6.6,87.42],[1,6.4,73.34],[2,4.3,40.44]],"ltp":4.2,"tv":54.88,"id":13014431},{"batb":[[0,5.1,75.99]],"ltp":0.0,"tv":0.0,"id":13014430}]}]}
{"op":"mcm","clk":"1011717278","pt":1580657446221,"mc":[{"id":"1.168223928","rc":[{"batb":[[0,2.18,35.29],[1,2.16,171.33],[2,2.14,108.96]],"batl":[[0,2.24,48.7],[1,2.42,68.35]],"ltp":2.54,"tv":572.23,"id":13015339},{"batb":[[0,4.5,35.8],[1,4.4,125.27],[2,4.3,102.17]],"batl":[[0,5.1,43.84],[1,5.3,31.16]],"ltp":0.0,"tv":0.0,"id":13015338},{"batb":[[2,6.2,33.83]],"batl":[[0,7.2,6.72],[1,7.4,31.71],[2,12,30.84]],"ltp":4.2,"tv":54.88,"id":13014431},{"batb":[[0,5.2,26.44],[1,5.1,75.52],[2,5,64.47]],"batl":[[0,5.5,9.24],[1,5.9,25.18]],"ltp":0.0,"tv":0.0,"id":13014430}]}]}
