{"op":"mcm","clk":"1011475238","pt":1580656390007,"mc":[{"id":"1.168223927","rc":[{"trd":[[2.54,64.5]],"batb":[[0,2.46,6.33],[1,2.26,163.74],[2,2,5.43]],"batl":[[0,2.54,112.58],[1,2.56,428.05],[2,2.66,788]],"ltp":2.54,"tv":4856.45,"id":8444055},{"trd":[[1.64,127.51]],"batb":[[0,1.66,9.42],[1,1.63,240.63],[2,1.4,2.54]],"batl":[[1,1.69,1244],[2,1.72,464.92]],"ltp":1.64,"tv":7846.73,"id":8257852}],"tv":12703.19}]}
{"op":"mcm","clk":"1011475509","pt":1580656391212,"mc":[{"id":"1.168223927","rc":[{"batb":[[0,2.46,137.89],[1,2.36,147.29]],"ltp":2.54,"tv":4856.45,"id":8444055},{"batb":[[2,1.61,248.71]],"ltp":1.64,"tv":7846.73,"id":8257852}]}]}
{"op":"mcm","clk":"1011475652","pt":1580656391800,"mc":[{"id":"1.168223927","rc":[{"trd":[[2.46,71.9]],"batb":[[0,2.46,137.7],[2,2.3,31.93]],"batl":[[2,2.58,26.05]],"ltp":2.46,"tv":4856.83,"id":8444055}],"tv":12703.57}]}
{"op":"mcm","clk":"1011475975","pt":1580656393294,"mc":[{"id":"1.168223927","rc":[{"trd":[[2.46,73.9]],"batb":[[0,2.46,136.7]],"ltp":2.46,"tv":4858.83,"id":8444055}],"tv":12705.57}]}
{"op":"mcm","clk":"1011476414","pt":1580656395139,"mc":[{"id":"1.168223927","rc":[{"batb":[[1,1.63,307.01]],"ltp":1.64,"tv":7846.73,"id":8257852}]}]}
{"op":"mcm","clk":"1011476585","pt":1580656395884,"mc":[{"id":"1.168223927","rc":[{"batl":[[0,1.67,840.19],[1,1.68,114.42],[2,1.69,1244]],"ltp":1.64,"tv":7846.73,"id":8257852}]}]}
{"op":"mcm","clk":"1011476706","pt":1580656396422,"mc":[{"id":"1.168223927","rc":[{"batb":[[2,1.62,494.03]],"ltp":1.64,"tv":7846.73,"id":8257852}]}]}
{"op":"mcm","clk":"1011477001","pt":1580656397616,"mc":[{"id":"1.168223927","rc":[{"batb":[[1,1.64,683.04],[2,1.63,685.08]],"ltp":1.64,"tv":7846.73,"id":8257852}]}]}
{"op":"mcm","clk":"1011477741","pt":1580656400836,"mc":[{"id":"1.168223927","rc":[{"trd":[[1.66,29.89]],"batb":[[0,1.66,9.21]],"ltp":1.66,"tv":7847.15,"id":8257852}],"tv":12705.98}]}
{"op":"mcm","clk":"1011478034","pt":1580656402031,"mc":[{"id":"1.168223927","rc":[{"batb":[[0,2.46,131.56]],"ltp":2.46,"tv":4858.83,"id":8444055},{"trd":[[1.66,30.66]],"batb":[[0,1.64,683.04],[1,1.63,685.08],[2,1.62,494.03]],"ltp":1.66,"tv":7847.92,"id":8257852}],"tv":12706.76}]}
{"op":"mcm","clk":"1011478298","pt":1580656403249,"mc":[{"id":"1.168223927","rc":[{"trd":[[2.48,0.66]],"batb":[[0,2.36,147.29],[1,2.3,31.93],[2,2,5.43]],"batl":[[1,2.58,26.05],[2,2.76,1.68]],"ltp":2.48,"tv":4859.49,"id":8444055},{"trd":[[1.67,0.97]],"batb":[[0,1.63,447.85],[1,1.62,494.03],[2,1.61,248.71]],"batl":[[0,1.67,839.22],[2,1.72,480.59]],"ltp":1.67,"tv":7848.9,"id":8257852}],"tv":12708.39}]}
{"op":"mcm","clk":"1011478406","pt":1580656403729,"mc":[{"id":"1.168223927","rc":[{"trd":[[1.67,5.36]],"batl":[[0,1.67,837.03],[1,1.72,480.59],[2,1.74,497.4]],"ltp":1.67,"tv":7853.29,"id":8257852}],"tv":12712.78}]}
{"op":"mcm","clk":"1011478754","pt":1580656405099,"mc":[{"id":"1.168223927","rc":[{"batb":[[1,2,5.43],[2,1.87,21.03]],"batl":[[1,2.76,1.68],[2,1000,0.02]],"ltp":2.48,"tv":4859.49,"id":8444055},{"batb":[[0,1.63,3.41]],"ltp":1.67,"tv":7853.29,"id":8257852}]}]}
{"op":"mcm","clk":"1011479011","pt":1580656406131,"mc":[{"id":"1.168223927","rc":[{"batb":[[1,2.34,151.15],[2,2,5.43]],"ltp":2.48,"tv":4859.49,"id":8444055},{"batb":[[1,1.62,737.24]],"ltp":1.67,"tv":7853.29,"id":8257852}]}]}
{"op":"mcm","clk":"1011479077","pt":1580656406395,"mc":[{"id":"1.168223927","rc":[{"trd":[[2.54,138.31]],"batb":[[0,2.34,151.15],[1,2,5.43],[2,1.87,21.03]],"batl":[[0,2.54,38.78]],"ltp":2.54,"tv":4933.29,"id":8444055},{"trd":[[1.64,241.93]],"batb":[[2,1.6,510.84]],"ltp":1.64,"tv":7967.71,"id":8257852}],"tv":12901.0}]}
{"op":"mcm","clk":"1011479449","pt":1580656408132,"mc":[{"id":"1.168223927","rc":[{"batb":[[0,1.65,524.67],[1,1.64,369.31],[2,1.63,3.41]],"batl":[[0,1.67,837.3],[1,1.7,404.48],[2,1.72,1108.75]],"ltp":1.64,"tv":7967.71,"id":8257852}]}]}
{"op":"mcm","clk":"1011479825","pt":1580656409695,"mc":[{"id":"1.168223927","rc":[{"batl":[[0,1.66,9.2],[1,1.67,837.03],[2,1.7,404.48]],"ltp":1.64,"tv":7967.71,"id":8257852}]}]}
{"op":"mcm","clk":"1011480089","pt":1580656410836,"mc":[{"id":"1.168223927","rc":[{"batb":[[0,1.63,3.41],[1,1.62,737.24],[2,1.6,510.84]],"batl":[[2,1.72,480.59]],"ltp":1.64,"tv":7967.71,"id":8257852}]}]}
{"op":"mcm","clk":"1011480469","pt":1580656412303,"mc":[{"id":"1.168223927","rc":[{"batb":[[0,1.62,737.24],[1,1.6,510.84],[2,1.4,2.54]],"ltp":1.64,"tv":7967.71,"id":8257852}]}]}
{"op":"mcm","clk":"1011480904","pt":1580656414043,"mc":[{"id":"1.168223927","rc":[{"batb":[[0,1.63,524.88],[1,1.62,629.32]],"ltp":1.64,"tv":7967.71,"id":8257852}]}]}
{"op":"mcm","clk":"1011481002","pt":1580656414427,"mc":[{"id":"1.168223927","rc":[{"batl":[[0,1.66,8.93]],"ltp":1.64,"tv":7967.71,"id":8257852}]}]}
{"op":"mcm","clk":"1011481207","pt":1580656415450,"mc":[{"id":"1.168223927","rc":[{"trd":[[2.5,86.48]],"ltp":2.5,"tv":4933.53,"id":8444055},{"trd":[[1.66,37.83]],"batl":[[0,1.66,5.16]],"ltp":1.66,"tv":7974.88,"id":8257852}],"tv":12908.41}]}
{"op":"mcm","clk":"1011481661","pt":1580656417235,"mc":[{"id":"1.168223927","rc":[{"batb":[[0,2.46,102.06],[1,2.38,30.25],[2,2.34,151.15]],"batl":[[1,2.6,317.79],[2,2.66,25.21]],"ltp":2.5,"tv":4933.53,"id":8444055},{"batb":[[2,1.6,69.74]],"batl":[[0,1.66,14.02],[1,1.67,2378.03],[2,1.68,467.09]],"ltp":1.66,"tv":7974.88,"id":8257852}]}]}
{"op":"mcm","clk":"1011481869","pt":1580656418148,"mc":[{"id":"1.168223927","rc":[{"batb":[[0,2.48,127.78],[1,2.46,102.06],[2,2.38,173.29]],"ltp":2.5,"tv":4933.53,"id":8444055}]}]}
{"op":"mcm","clk":"1011482791","pt":1580656421963,"mc":[{"id":"1.168223927","rc":[{"batl":[[0,1.66,13.74]],"ltp":1.66,"tv":7974.88,"id":8257852}]}]}
{"op":"mcm","clk":"1011483049","pt":1580656423122,"mc":[{"id":"1.168223927","rc":[{"trd":[[2.54,143.93]],"batl":[[0,2.54,33.16]],"ltp":2.54,"tv":4939.15,"id":8444055},{"trd":[[1.64,250.65]],"ltp":1.64,"tv":7983.6,"id":8257852}],"tv":12922.75}]}
{"op":"mcm","clk":"1011483261","pt":1580656424156,"mc":[{"id":"1.168223927","rc":[{"trd":[[2.5,87.02]],"ltp":2.5,"tv":4939.69,"id":8444055},{"trd":[[1.66,38.64]],"batl":[[0,1.66,12.94]],"ltp":1.66,"tv":7984.4,"id":8257852}],"tv":12924.1}]}
{"op":"mcm","clk":"1011483512","pt":1580656425349,"mc":[{"id":"1.168223927","rc":[{"trd":[[2.54,144.11]],"batl":[[0,2.54,32.98]],"ltp":2.54,"tv":4939.86,"id":8444055},{"trd":[[1.64,250.93]],"ltp":1.64,"tv":7984.68,"id":8257852}],"tv":12924.55}]}
{"op":"mcm","clk":"1011484886","pt":1580656431265,"mc":[{"id":"1.168223927","rc":[{"batb":[[0,2.52,7.56],[1,2.48,127.78],[2,2.46,102.06]],"ltp":2.54,"tv":4939.86,"id":8444055}]}]}
{"op":"mcm","clk":"1011485204","pt":1580656432543,"mc":[{"id":"1.168223927","rc":[{"trd":[[2.52,1.49]],"batb":[[0,2.52,6.81]],"ltp":2.52,"tv":4941.36,"id":8444055},{"batb":[[0,1.63,525.32]],"ltp":1.64,"tv":7984.68,"id":8257852}],"tv":12926.04}]}
{"op":"mcm","clk":"1011486027","pt":1580656436129,"mc":[{"id":"1.168223927","rc":[{"batb":[[0,1.65,113.27],[1,1.63,524.88],[2,1.62,629.32]],"ltp":1.64,"tv":7984.68,"id":8257852}]}]}
{"op":"mcm","clk":"1011486266","pt":1580656437073,"mc":[{"id":"1.168223927","rc":[{"trd":[[2.52,8.25]],"batb":[[0,2.52,3.44]],"ltp":2.52,"tv":4948.11,"id":8444055},{"trd":[[1.65,30.88]],"batb":[[0,1.65,112.97]],"batl":[[0,1.66,12.66]],"ltp":1.65,"tv":7985.27,"id":8257852}],"tv":12933.38}]}
{"op":"mcm","clk":"1011486393","pt":1580656437580,"mc":[{"id":"1.168223927","rc":[{"batl":[[0,1.66,12.14]],"ltp":1.65,"tv":7985.27,"id":8257852}]}]}
{"op":"mcm","clk":"1011487052","pt":1580656440197,"mc":[{"id":"1.168223927","rc":[{"trd":[[2.52,11.68]],"batb":[[0,2.48,127.78],[1,2.46,102.06],[2,2.38,173.29]],"ltp":2.52,"tv":4951.55,"id":8444055},{"trd":[[1.66,68.14]],"batb":[[0,1.66,14.91],[1,1.65,112.97],[2,1.63,524.88]],"batl":[[0,1.67,2378.03],[1,1.68,467.09],[2,1.7,1290.5]],"ltp":1.66,"tv":8014.76,"id":8257852}],"tv":12966.32}]}
{"op":"mcm","clk":"1011487871","pt":1580656443057,"mc":[{"id":"1.168223927","rc":[{"trd":[[1.66,95.96]],"batb":[[0,1.66,1]],"ltp":1.66,"tv":8042.59,"id":8257852}],"tv":12994.14}]}
{"op":"mcm","clk":"1011488847","pt":1580656447091,"mc":[{"id":"1.168223927","rc":[{"trd":[[2.48,561.98]],"batb":[[0,2.46,102.06],[1,2.38,173.29],[2,2,5.43]],"ltp":2.48,"tv":5512.87,"id":8444055},{"trd":[[1.67,459.39]],"batl":[[0,1.67,1923.99]],"ltp":1.67,"tv":8496.62,"id":8257852}],"tv":14009.49}]}
{"op":"mcm","clk":"1011489039","pt":1580656447908,"mc":[{"id":"1.168223927","rc":[{"batb":[[0,1.66,1.19]],"ltp":1.67,"tv":8496.62,"id":8257852}]}]}
{"op":"mcm","clk":"1011489571","pt":1580656450089,"mc":[{"id":"1.168223927","rc":[{"batl":[[1,2.6,305.77]],"ltp":2.48,"tv":5512.87,"id":8444055}]}]}
{"op":"mcm","clk":"1011490047","pt":1580656451860,"mc":[{"id":"1.168223927","rc":[{"batb":[[0,1.65,113.61],[1,1.63,524.88],[2,1.62,629.32]],"ltp":1.67,"tv":8496.62,"id":8257852}]}]}
{"op":"mcm","clk":"1011490362","pt":1580656452996,"mc":[{"id":"1.168223927","rc":[{"batl":[[1,2.56,9.59],[2,2.6,305.77]],"ltp":2.48,"tv":5512.87,"id":8444055},{"batl":[[1,1.68,481.95]],"ltp":1.67,"tv":8496.62,"id":8257852}]}]}
{"op":"mcm","clk":"1011490590","pt":1580656453765,"mc":[{"id":"1.168223927","rc":[{"batb":[[1,1.62,243.21],[2,1.6,69.74]],"batl":[[1,1.68,14.86],[2,1.7,637.36]],"ltp":1.67,"tv":8496.62,"id":8257852}]}]}
{"op":"mcm","clk":"1011491670","pt":1580656458209,"mc":[{"id":"1.168223927","rc":[{"batb":[[0,1.65,113.42]],"ltp":1.67,"tv":8496.62,"id":8257852}]}]}
{"op":"mcm","clk":"1011492099","pt":1580656459968,"mc":[{"id":"1.168223927","rc":[{"trd":[[2.48,603.7]],"ltp":2.48,"tv":5554.59,"id":8444055},{"trd":[[1.67,521.36]],"batl":[[0,1.67,1862.03]],"ltp":1.67,"tv":8558.58,"id":8257852}],"tv":14113.18}]}
{"op":"mcm","clk":"1011493142","pt":1580656464002,"mc":[{"id":"1.168223927","rc":[{"batb":[[0,2.38,173.29],[1,2,5.43],[2,1.87,21.03]],"batl":[[1,2.66,25.21],[2,2.76,1.68]],"ltp":2.48,"tv":5554.59,"id":8444055},{"batb":[[1,1.6,69.74],[2,1.56,437.41]],"batl":[[0,1.67,321.03],[1,1.73,573.92],[2,1.75,592.36]],"ltp":1.67,"tv":8558.58,"id":8257852}]}]}
{"op":"mcm","clk":"1011493222","pt":1580656464376,"mc":[{"id":"1.168223927","rc":[{"batb":[[0,2.38,143.04]],"batl":[[1,2.76,1.68],[2,1000,0.02]],"ltp":2.48,"tv":5554.59,"id":8444055},{"batb":[[1,1.56,437.41],[2,1.55,455.18]],"batl":[[1,1.73,531.91]],"ltp":1.67,"tv":8558.58,"id":8257852}]}]}
{"op":"mcm","clk":"1011493537","pt":1580656465630,"mc":[{"id":"1.168223927","rc":[{"trd":[[2.48,604.81]],"ltp":2.48,"tv":5555.7,"id":8444055},{"trd":[[1.67,523]],"batl":[[0,1.67,319.39]],"ltp":1.67,"tv":8560.22,"id":8257852}],"tv":14115.92}]}
{"op":"mcm","clk":"1011493952","pt":1580656467034,"mc":[{"id":"1.168223927","rc":[{"batb":[[1,2.36,145.95],[2,2,5.43]],"ltp":2.48,"tv":5555.7,"id":8444055},{"trd":[[1.67,524.32]],"batb":[[1,1.56,726.25]],"batl":[[0,1.67,318.73]],"ltp":1.67,"tv":8561.54,"id":8257852}],"tv":14117.25}]}
{"op":"mcm","clk":"1011494138","pt":1580656467697,"mc":[{"id":"1.168223927","rc":[{"batb":[[0,2.36,145.95],[1,2,5.43],[2,1.87,21.03]],"ltp":2.48,"tv":5555.7,"id":8444055},{"trd":[[1.65,56.47]],"batb":[[0,1.65,100.03],[1,1.56,288.84],[2,1.4,2.54]],"batl":[[1,1.8,147.03],[2,1.82,189.04]],"ltp":1.65,"tv":8587.14,"id":8257852}],"tv":14142.84}]}
{"op":"mcm","clk":"1011494530","pt":1580656469386,"mc":[{"id":"1.168223927","rc":[{"trd":[[1.67,525.28]],"batl":[[0,1.67,318.25]],"ltp":1.67,"tv":8588.1,"id":8257852}],"tv":14143.8}]}
{"op":"mcm","clk":"1011494829","pt":1580656470634,"mc":[{"id":"1.168223927","rc":[{"batb":[[1,1.61,734.3],[2,1.6,404.92]],"batl":[[0,1.67,996.75],[1,1.69,665.06],[2,1.8,147.03]],"ltp":1.67,"tv":8588.1,"id":8257852}]}]}
{"op":"mcm","clk":"1011495369","pt":1580656472815,"mc":[{"id":"1.168223927","rc":[{"batb":[[1,1.56,288.84],[2,1.4,2.54]],"batl":[[0,1.67,318.25],[1,1.8,147.03],[2,1.82,189.04]],"ltp":1.67,"tv":8588.1,"id":8257852}]}]}
{"op":"mcm","clk":"1011496083","pt":1580656475726,"mc":[{"id":"1.168223927","rc":[{"batb":[[0,1.56,726.25],[1,1.55,455.18]],"batl":[[1,1.73,531.91],[2,1.75,592.36]],"ltp":1.67,"tv":8588.1,"id":8257852}]}]}
{"op":"mcm","clk":"1011496601","pt":1580656477603,"mc":[{"id":"1.168223927","rc":[{"trd":[[1.67,525.95]],"batl":[[0,1.67,317.91]],"ltp":1.67,"tv":8588.77,"id":8257852}],"tv":14144.47}]}
{"op":"mcm","clk":"1011496976","pt":1580656479099,"mc":[{"id":"1.168223927","rc":[{"trd":[[2.54,177.09]],"batl":[[0,2.76,1.68],[1,1000,0.02],[2,1000,0]],"ltp":2.54,"tv":5588.68,"id":8444055},{"trd":[[1.64,302.06],[1.67,529.67]],"batl":[[0,1.63,534.04],[1,1.67,316.06],[2,1.73,531.91]],"ltp":1.64,"tv":8643.62,"id":8257852}],"tv":14232.3}]}
{"op":"mcm","clk":"1011497198","pt":1580656480013,"mc":[{"id":"1.168223927","rc":[{"trd":[[1.63,22.58]],"batl":[[0,1.63,528.46]],"ltp":1.63,"tv":8654.76,"id":8257852}],"tv":14243.44}]}
{"op":"mcm","clk":"1011497961","pt":1580656483128,"mc":[{"id":"1.168223927","rc":[{"batb":[[0,1.56,288.84],[1,1.4,2.54],[2,1.3,113.58]],"batl":[[2,1.8,147.03]],"ltp":1.63,"tv":8654.76,"id":8257852}]}]}
{"op":"mcm","clk":"1011498699","pt":1580656486227,"mc":[{"id":"1.168223927","rc":[{"trd":[[2.48,817.64],[2.58,333.86]],"batb":[[0,2.36,154.39],[1,2.32,373.08],[2,2,5.43]],"batl":[[0,2.42,6.72],[1,2.54,107.65],[2,2.56,861.31]],"ltp":2.48,"tv":6135.37,"id":8444055},{"trd":[[1.63,551.04],[1.67,845.72]],"batb":[[0,1.67,649.24],[1,1.66,353.97],[2,1.65,163.08]],"batl":[[0,1.72,1056],[1,1.73,531.91],[2,1.75,592.36]],"ltp":1.67,"tv":9499.28,"id":8257852}],"tv":15634.65}]}
{"op":"mcm","clk":"1011498935","pt":1580656487248,"mc":[{"id":"1.168223927","rc":[{"batb":[[1,2.34,31.09],[2,2.32,373.08]],"ltp":2.48,"tv":6135.37,"id":8444055},{"batb":[[0,1.69,216.45],[1,1.67,649.24],[2,1.66,353.97]],"batl":[[1,1.73,573.92]],"ltp":1.67,"tv":9499.28,"id":8257852}]}]}
{"op":"mcm","clk":"1011499054","pt":1580656487671,"mc":[{"id":"1.168223927","rc":[{"batb":[[1,2.32,373.08],[2,2.28,162.32]],"ltp":2.48,"tv":6135.37,"id":8444055},{"batl":[[1,1.73,531.91]],"ltp":1.67,"tv":9499.28,"id":8257852}]}]}
{"op":"mcm","clk":"1011499372","pt":1580656489037,"mc":[{"id":"1.168223927","rc":[{"batb":[[2,2.28,195.09]],"batl":[[2,2.56,888.2]],"ltp":2.48,"tv":6135.37,"id":8444055}]}]}
{"op":"mcm","clk":"1011500381","pt":1580656493076,"mc":[{"id":"1.168223927","rc":[{"batb":[[2,1.66,848]],"ltp":1.67,"tv":9499.28,"id":8257852}]}]}
{"op":"mcm","clk":"1011501353","pt":1580656497044,"mc":[{"id":"1.168223927","rc":[{"trd":[[2.42,798.25]],"batl":[[0,2.54,107.65],[1,2.56,888.2],[2,2.58,789]],"ltp":2.42,"tv":6142.09,"id":8444055},{"trd":[[1.7,1103.79],[1.72,132.01]],"batl":[[0,1.7,990.43],[1,1.72,1051.61],[2,1.73,531.91]],"ltp":1.7,"tv":9517.63,"id":8257852}],"tv":15659.72}]}
{"op":"mcm","clk":"1011501848","pt":1580656499059,"mc":[{"id":"1.168223927","rc":[{"batb":[[0,2.36,145.95],[1,2.28,195.09],[2,2,5.43]],"batl":[[0,2.56,26.89],[1,2.6,3.46],[2,2.76,1.68]],"ltp":2.42,"tv":6142.09,"id":8444055},{"batl":[[1,1.73,531.91],[2,1.74,25.25]],"ltp":1.7,"tv":9517.63,"id":8257852}]}]}
{"op":"mcm","clk":"1011502053","pt":1580656499863,"mc":[{"id":"1.168223927","rc":[{"batb":[[0,2.34,4.72],[1,2.32,4.64],[2,2.28,195.09]],"ltp":2.42,"tv":6142.09,"id":8444055},{"trd":[[1.7,1110.48]],"batb":[[0,1.66,494.03],[1,1.64,576.37],[2,1.63,27.23]],"batl":[[0,1.7,987.08],[1,1.74,25.25],[2,1.75,25.1]],"ltp":1.7,"tv":9524.33,"id":8257852}],"tv":15666.42}]}
{"op":"mcm","clk":"1011502443","pt":1580656501253,"mc":[{"id":"1.168223927","rc":[{"batb":[[2,2.28,162.32]],"batl":[[0,2.6,3.46],[1,2.76,1.68],[2,1000,0.02]],"ltp":2.42,"tv":6142.09,"id":8444055},{"trd":[[1.7,1115.7]],"batb":[[1,1.64,510.84]],"batl":[[0,1.7,984.47]],"ltp":1.7,"tv":9529.55,"id":8257852}],"tv":15671.64}]}
{"op":"mcm","clk":"1011503248","pt":1580656504269,"mc":[{"id":"1.168223927","rc":[{"trd":[[1.7,1116.18]],"batl":[[0,1.7,984.23]],"ltp":1.7,"tv":9530.03,"id":8257852}],"tv":15672.12}]}
{"op":"mcm","clk":"1011503388","pt":1580656504660,"mc":[{"id":"1.168223927","rc":[{"trd":[[1.7,1117.5]],"batl":[[0,1.7,983.57]],"ltp":1.7,"tv":9531.34,"id":8257852}],"tv":15673.44}]}
{"op":"mcm","clk":"1011503764","pt":1580656506261,"mc":[{"id":"1.168223927","rc":[{"batb":[[0,1.66,1043.24],[1,1.65,361.41],[2,1.64,510.84]],"batl":[[1,1.71,351.11],[2,1.73,616.3]],"ltp":1.7,"tv":9531.34,"id":8257852}]}]}
{"op":"mcm","clk":"1011503786","pt":1580656506373,"mc":[{"id":"1.168223927","rc":[{"batb":[[1,1.65,490.14]],"ltp":1.7,"tv":9531.34,"id":8257852}]}]}
{"op":"mcm","clk":"1011504174","pt":1580656507883,"mc":[{"id":"1.168223927","rc":[{"batb":[[0,1.67,461],[1,1.66,1043.24],[2,1.65,490.14]],"batl":[[2,1.73,1077.3]],"ltp":1.7,"tv":9531.34,"id":8257852}]}]}
{"op":"mcm","clk":"1011504532","pt":1580656509354,"mc":[{"id":"1.168223927","rc":[{"batb":[[1,1.66,494.03],[2,1.65,128.73]],"batl":[[1,1.73,461],[2,1.74,25.25]],"ltp":1.7,"tv":9531.34,"id":8257852}]}]}
{"op":"mcm","clk":"1011505704","pt":1580656514476,"mc":[{"id":"1.168223927","rc":[{"batl":[[1,1.74,25.25],[2,1.75,25.1]],"ltp":1.7,"tv":9531.34,"id":8257852}]}]}
{"op":"mcm","clk":"1011506369","pt":1580656517266,"mc":[{"id":"1.168223927","rc":[{"trd":[[2.42,1179.64]],"batl":[[0,2.46,954.92],[1,2.48,1022.73],[2,2.6,3.46]],"ltp":2.42,"tv":6523.48,"id":8444055},{"trd":[[1.7,2541.73],[1.74,2097.11]],"batb":[[0,1.71,2714.89],[1,1.69,660.06],[2,1.68,61.33]],"batl":[[0,1.74,14.9],[1,1.75,25.1],[2,1.77,3066.31]],"ltp":1.74,"tv":10976.27,"id":8257852}],"tv":17499.76}]}
{"op":"mcm","clk":"1011506527","pt":1580656517865,"mc":[{"id":"1.168223927","rc":[{"trd":[[1.74,2126.91]],"batb":[[0,1.74,181.96],[1,1.71,2714.89],[2,1.69,660.06]],"batl":[[0,1.75,25.1],[1,1.77,3066.31],[2,1.78,1255.71]],"ltp":1.74,"tv":11006.08,"id":8257852}],"tv":17529.56}]}
{"op":"mcm","clk":"1011506803","pt":1580656518705,"mc":[{"id":"1.168223927","rc":[{"batb":[[2,1.7,461]],"ltp":1.74,"tv":11006.08,"id":8257852}]}]}
{"op":"mcm","clk":"1011507078","pt":1580656519749,"mc":[{"id":"1.168223927","rc":[{"batb":[[1,1.72,1],[2,1.71,2714.89]],"ltp":1.74,"tv":11006.08,"id":8257852}]}]}
{"op":"mcm","clk":"1011508644","pt":1580656526268,"mc":[{"id":"1.168223927","rc":[{"trd":[[1.74,2136.74]],"batb":[[0,1.74,177.05],[1,1.71,2714.89],[2,1.7,494.3]],"ltp":1.74,"tv":11015.9,"id":8257852}],"tv":17539.38}]}
{"op":"mcm","clk":"1011508771","pt":1580656526807,"mc":[{"id":"1.168223927","rc":[{"batl":[[2,1.78,1241]],"ltp":1.74,"tv":11015.9,"id":8257852}]}]}
{"op":"mcm","clk":"1011509471","pt":1580656529665,"mc":[{"id":"1.168223927","rc":[{"batb":[[1,2.32,13.15]],"ltp":2.42,"tv":6523.48,"id":8444055},{"trd":[[1.74,2137.22]],"batb":[[0,1.74,176.81],[1,1.72,13.44],[2,1.71,2714.89]],"ltp":1.74,"tv":11016.38,"id":8257852}],"tv":17539.86}]}
{"op":"mcm","clk":"1011509830","pt":1580656530986,"mc":[{"id":"1.168223927","rc":[{"batb":[[1,2.32,4.64],[2,2.22,207.97]],"batl":[[0,2.48,27.73],[1,2.6,3.46],[2,2.76,1.68]],"ltp":2.42,"tv":6523.48,"id":8444055},{"trd":[[1.75,777.08]],"batb":[[0,1.7,494.3],[1,1.68,572.17],[2,1.67,223.69]],"batl":[[0,1.75,24.43],[1,1.79,480.59],[2,1.8,147.03]],"ltp":1.75,"tv":11017.72,"id":8257852}],"tv":17541.2}]}
{"op":"mcm","clk":"1011509991","pt":1580656531521,"mc":[{"id":"1.168223927","rc":[{"batl":[[0,2.48,28.13]],"ltp":2.42,"tv":6523.48,"id":8444055}]}]}
{"op":"mcm","clk":"1011510441","pt":1580656533090,"mc":[{"id":"1.168223927","rc":[{"batb":[[2,2.22,174.36]],"batl":[[0,2.6,3.86],[1,2.76,1.68],[2,1000,0.02]],"ltp":2.42,"tv":6523.48,"id":8444055},{"trd":[[1.75,780.87]],"batb":[[1,1.68,510.84]],"batl":[[0,1.75,22.54]],"ltp":1.75,"tv":11021.5,"id":8257852}],"tv":17544.98}]}
{"op":"mcm","clk":"1011511200","pt":1580656536098,"mc":[{"id":"1.168223927","rc":[{"batb":[[0,1.7,494.03]],"ltp":1.75,"tv":11021.5,"id":8257852}]}]}
{"op":"mcm","clk":"1011511329","pt":1580656536700,"mc":[{"id":"1.168223927","rc":[{"batl":[[0,2.6,3.46]],"ltp":2.42,"tv":6523.48,"id":8444055},{"batb":[[0,1.7,1027.4],[1,1.68,1184.76]],"batl":[[1,1.76,545.2],[2,1.78,560.23]],"ltp":1.75,"tv":11021.5,"id":8257852}]}]}
{"op":"mcm","clk":"1011512107","pt":1580656539802,"mc":[{"id":"1.168223927","rc":[{"batb":[[0,1.7,1156.13]],"ltp":1.75,"tv":11021.5,"id":8257852}]}]}
{"op":"mcm","clk":"1011512562","pt":1580656541620,"mc":[{"id":"1.168223927","rc":[{"batb":[[0,1.7,622.76],[1,1.68,510.84]],"batl":[[1,1.79,480.59],[2,1.8,147.03]],"ltp":1.75,"tv":11021.5,"id":8257852}]}]}
{"op":"mcm","clk":"1011513412","pt":1580656545122,"mc":[{"id":"1.168223927","rc":[{"trd":[[2.34,67.42]],"batb":[[0,2.34,4.32]],"ltp":2.34,"tv":6524.28,"id":8444055},{"batb":[[0,1.7,128.73],[1,1.67,223.69],[2,1.66,614.14]],"ltp":1.75,"tv":11021.5,"id":8257852}],"tv":17545.79}]}
{"op":"mcm","clk":"1011514122","pt":1580656547992,"mc":[{"id":"1.168223927","rc":[{"batb":[[0,2.46,7.88],[1,2.34,4.32],[2,2.32,4.64]],"batl":[[0,2.56,569.02],[1,2.6,3.46],[2,2.62,710]],"ltp":2.34,"tv":6524.28,"id":8444055},{"trd":[[1.7,2799.19]],"batb":[[0,1.67,223.69],[1,1.66,3324.98],[2,1.65,361.58]],"batl":[[0,1.7,934.27],[1,1.72,3216.16],[2,1.74,603.37]],"ltp":1.7,"tv":11278.96,"id":8257852}],"tv":17803.25}]}
{"op":"mcm","clk":"1011514375","pt":1580656549021,"mc":[{"id":"1.168223927","rc":[{"trd":[[2.46,74.87]],"batb":[[0,2.46,7.4],[1,2.4,139.9],[2,2.34,4.32]],"ltp":2.46,"tv":6525.24,"id":8444055}],"tv":17804.21}]}
{"op":"mcm","clk":"1011514689","pt":1580656550228,"mc":[{"id":"1.168223927","rc":[{"batb":[[2,2.36,2.61]],"batl":[[2,2.62,735.21]],"ltp":2.46,"tv":6525.24,"id":8444055},{"batb":[[2,1.65,364.16]],"batl":[[2,1.74,1064.37]],"ltp":1.7,"tv":11278.96,"id":8257852}]}]}
{"op":"mcm","clk":"1011515176","pt":1580656552048,"mc":[{"id":"1.168223927","rc":[{"batl":[[1,1.71,461],[2,1.72,3216.16]],"ltp":1.7,"tv":11278.96,"id":8257852}]}]}
{"op":"mcm","clk":"1011515422","pt":1580656553125,"mc":[{"id":"1.168223927","rc":[{"batb":[[1,1.66,3785.98]],"ltp":1.7,"tv":11278.96,"id":8257852}]}]}
{"op":"mcm","clk":"1011515638","pt":1580656554036,"mc":[{"id":"1.168223927","rc":[{"trd":[[2.46,75.05]],"batb":[[0,2.46,7.22]],"ltp":2.46,"tv":6525.42,"id":8444055},{"trd":[[1.69,0.27]],"ltp":1.69,"tv":11279.23,"id":8257852}],"tv":17804.66}]}
{"op":"mcm","clk":"1011516744","pt":1580656558151,"mc":[{"id":"1.168223927","rc":[{"trd":[[2.46,75.5]],"batb":[[0,2.46,6.77]],"ltp":2.46,"tv":6525.87,"id":8444055},{"trd":[[1.69,0.93]],"ltp":1.69,"tv":11279.89,"id":8257852}],"tv":17805.76}]}
{"op":"mcm","clk":"1011516900","pt":1580656558803,"mc":[{"id":"1.168223927","rc":[{"batb":[[0,2.4,139.9],[1,2.36,2.61],[2,2.34,4.32]],"batl":[[0,2.56,554.7]],"ltp":2.46,"tv":6525.87,"id":8444055}]}]}
{"op":"mcm","clk":"1011517238","pt":1580656560213,"mc":[{"id":"1.168223927","rc":[{"trd":[[1.67,847.89]],"batb":[[0,1.67,222.61]],"ltp":1.67,"tv":11282.06,"id":8257852}],"tv":17807.93}]}
{"op":"mcm","clk":"1011517769","pt":1580656562245,"mc":[{"id":"1.168223927","rc":[{"trd":[[2.46,85.21]],"batl":[[0,2.6,3.46],[1,2.62,25.21],[2,2.76,1.68]],"ltp":2.46,"tv":6535.58,"id":8444055},{"trd":[[1.69,3.41]],"batl":[[0,1.71,461],[1,1.72,3216.16],[2,1.73,480.59]],"ltp":1.69,"tv":11284.54,"id":8257852}],"tv":17820.13}]}
{"op":"mcm","clk":"1011518018","pt":1580656563133,"mc":[{"id":"1.168223927","rc":[{"batb":[[0,2.36,2.61],[1,2.34,4.32],[2,2.32,35.73]],"ltp":2.46,"tv":6535.58,"id":8444055},{"batb":[[0,1.66,461],[1,1.65,2.58],[2,1.64,461]],"batl":[[0,1.67,1.32],[1,1.71,461]],"ltp":1.69,"tv":11284.54,"id":8257852}]}]}
{"op":"mcm","clk":"1011518293","pt":1580656564141,"mc":[{"id":"1.168223927","rc":[{"trd":[[2.48,818.36]],"batl":[[0,2.42,1.28],[1,2.6,3.46],[2,2.62,25.21]],"ltp":2.48,"tv":6536.3,"id":8444055},{"trd":[[1.67,848.96]],"batl":[[0,1.71,461],[1,1.73,480.59],[2,1.74,461]],"ltp":1.67,"tv":11285.61,"id":8257852}],"tv":17821.91}]}
{"op":"mcm","clk":"1011518501","pt":1580656565062,"mc":[{"id":"1.168223927","rc":[{"batb":[[2,2.32,4.64]],"batl":[[2,2.76,1.68]],"ltp":2.48,"tv":6536.3,"id":8444055}]}]}
{"op":"mcm","clk":"1011518598","pt":1580656565444,"mc":[{"id":"1.168223927","rc":[{"batl":[[0,2.6,3.46],[1,2.76,1.68],[2,1000,0.02]],"ltp":2.48,"tv":6536.3,"id":8444055}]}]}
{"op":"mcm","clk":"1011519533","pt":1580656569259,"mc":[{"id":"1.168223927","rc":[{"batb":[[0,1.65,2.87],[1,1.64,461],[2,1.63,521.26]],"ltp":1.67,"tv":11285.61,"id":8257852}]}]}
{"op":"mcm","clk":"1011520039","pt":1580656571243,"mc":[{"id":"1.168223927","rc":[{"batb":[[0,1.65,445.67],[1,1.64,830.04]],"batl":[[0,1.7,482.71],[1,1.72,627.72],[2,1.73,480.59]],"ltp":1.67,"tv":11285.61,"id":8257852}]}]}
{"op":"mcm","clk":"1011520174","pt":1580656571748,"mc":[{"id":"1.168223927","rc":[{"trd":[[1.69,3.97]],"batb":[[0,1.65,445.38]],"ltp":1.69,"tv":11286.17,"id":8257852}],"tv":17822.48}]}
{"op":"mcm","clk":"1011520515","pt":1580656573159,"mc":[{"id":"1.168223927","rc":[{"trd":[[1.7,2800.97]],"batb":[[0,1.65,2.58],[1,1.64,461]],"batl":[[0,1.7,933.46],[1,1.73,480.59],[2,1.75,519.94]],"ltp":1.7,"tv":11287.95,"id":8257852}],"tv":17824.26}]}
{"op":"mcm","clk":"1011520893","pt":1580656574681,"mc":[{"id":"1.168223927","rc":[{"batl":[[0,1.7,1394.46],[1,1.72,461],[2,1.73,480.59]],"ltp":1.7,"tv":11287.95,"id":8257852}]}]}
{"op":"mcm","clk":"1011521534","pt":1580656577239,"mc":[{"id":"1.168223927","rc":[{"batb":[[0,2.34,4.32],[1,2.32,4.64],[2,2.3,156.42]],"ltp":2.48,"tv":6536.3,"id":8444055},{"batb":[[0,1.64,461],[1,1.63,521.26],[2,1.62,461]],"ltp":1.7,"tv":11287.95,"id":8257852}]}]}
{"op":"mcm","clk":"1011522015","pt":1580656579167,"mc":[{"id":"1.168223927","rc":[{"trd":[[1.7,2801.85]],"batb":[[0,1.66,461],[1,1.64,461],[2,1.63,521.26]],"batl":[[0,1.7,1394.02]],"ltp":1.7,"tv":11288.83,"id":8257852}],"tv":17825.13}]}
{"op":"mcm","clk":"1011522341","pt":1580656580547,"mc":[{"id":"1.168223927","rc":[{"batb":[[0,1.66,461.28]],"ltp":1.7,"tv":11288.83,"id":8257852}]}]}
{"op":"mcm","clk":"1011523730","pt":1580656586257,"mc":[{"id":"1.168223927","rc":[{"batb":[[0,1.66,461.72]],"ltp":1.7,"tv":11288.83,"id":8257852}]}]}
{"op":"mcm","clk":"1011524050","pt":1580656587564,"mc":[{"id":"1.168223927","rc":[{"trd":[[1.66,248.52],[1.68,379.2],[1.69,4.85]],"batb":[[0,1.66,384.72]],"ltp":1.66,"tv":11442.83,"id":8257852}],"tv":17979.13}]}
{"op":"mcm","clk":"1011524479","pt":1580656589568,"mc":[{"id":"1.168223927","rc":[{"batl":[[0,1.7,461]],"ltp":1.66,"tv":11442.83,"id":8257852}]}]}
{"op":"mcm","clk":"1011524981","pt":1580656591894,"mc":[{"id":"1.168223927","rc":[{"batl":[[0,1.75,22.54],[1,1.76,398.91],[2,1.78,560.8]],"ltp":1.66,"tv":11442.83,"id":8257852}]}]}
{"op":"mcm","clk":"1011525529","pt":1580656594176,"mc":[{"id":"1.168223927","rc":[{"batb":[[1,2.32,13.67]],"batl":[[0,2.4,2528.6],[1,2.42,446.59],[2,2.5,930]],"ltp":2.48,"tv":6536.3,"id":8444055},{"batb":[[0,1.72,12.67],[1,1.7,2647.06],[2,1.66,384.72]],"batl":[[1,1.76,2955.73],[2,1.77,1339]],"ltp":1.66,"tv":11442.83,"id":8257852}]}]}
{"op":"mcm","clk":"1011525753","pt":1580656595268,"mc":[{"id":"1.168223927","rc":[{"batl":[[0,2.42,446.59],[1,2.5,930],[2,2.6,3.46]],"ltp":2.48,"tv":6536.3,"id":8444055},{"batb":[[0,1.72,216.14],[1,1.71,360.18],[2,1.7,2647.06]],"ltp":1.66,"tv":11442.83,"id":8257852}]}]}
{"op":"mcm","clk":"1011525966","pt":1580656596175,"mc":[{"id":"1.168223927","rc":[{"batl":[[1,2.5,957.73]],"ltp":2.48,"tv":6536.3,"id":8444055},{"batb":[[0,1.72,1149.6],[2,1.7,2649.74]],"ltp":1.66,"tv":11442.83,"id":8257852}]}]}
{"op":"mcm","clk":"1011526483","pt":1580656598678,"mc":[{"id":"1.168223927","rc":[{"batl":[[0,1.73,73.19],[1,1.75,22.54],[2,1.76,2955.73]],"ltp":1.66,"tv":11442.83,"id":8257852}]}]}
{"op":"mcm","clk":"1011526726","pt":1580656599784,"mc":[{"id":"1.168223927","rc":[{"batb":[[2,1.7,2650.18]],"ltp":1.66,"tv":11442.83,"id":8257852}]}]}
{"op":"mcm","clk":"1011527581","pt":1580656603360,"mc":[{"id":"1.168223927","rc":[{"trd":[[1.73,317.57]],"batl":[[0,1.73,72.96]],"ltp":1.73,"tv":11443.29,"id":8257852}],"tv":17979.59}]}
{"op":"mcm","clk":"1011527814","pt":1580656604548,"mc":[{"id":"1.168223927","rc":[{"batb":[[2,1.7,2649.74]],"ltp":1.73,"tv":11443.29,"id":8257852}]}]}
{"op":"mcm","clk":"1011528480","pt":1580656607463,"mc":[{"id":"1.168223927","rc":[{"trd":[[1.73,318.59]],"batl":[[0,1.73,72.45]],"ltp":1.73,"tv":11444.3,"id":8257852}],"tv":17980.61}]}
{"op":"mcm","clk":"1011529389","pt":1580656611211,"mc":[{"id":"1.168223927","rc":[{"trd":[[1.72,135.73]],"batb":[[0,1.72,1147.74]],"ltp":1.72,"tv":11448.02,"id":8257852}],"tv":17984.33}]}
{"op":"mcm","clk":"1011529588","pt":1580656612231,"mc":[{"id":"1.168223927","rc":[{"batb":[[1,2.32,4.64]],"batl":[[0,2.5,27.73],[1,2.6,3.46],[2,2.76,1.68]],"ltp":2.48,"tv":6536.3,"id":8444055},{"trd":[[1.72,136.84]],"batb":[[0,1.72,1136.37]],"ltp":1.72,"tv":11449.13,"id":8257852}],"tv":17985.44}]}
{"op":"mcm","clk":"1011529826","pt":1580656613247,"mc":[{"id":"1.168223927","rc":[{"batb":[[2,2.26,2.68]],"batl":[[0,2.6,3.46],[1,2.76,1.68],[2,1000,0.02]],"ltp":2.48,"tv":6536.3,"id":8444055},{"batb":[[0,1.7,2.68],[1,1.68,494.03],[2,1.66,510.84]],"batl":[[2,1.79,480.59]],"ltp":1.72,"tv":11449.13,"id":8257852}]}]}
{"op":"mcm","clk":"1011530542","pt":1580656616246,"mc":[{"id":"1.168223927","rc":[{"trd":[[1.73,344.91]],"batb":[[2,1.66,1031.76]],"batl":[[0,1.73,59.29],[2,1.79,934.2]],"ltp":1.73,"tv":11475.46,"id":8257852}],"tv":18011.76}]}
{"op":"mcm","clk":"1011532214","pt":1580656623828,"mc":[{"id":"1.168223927","rc":[{"batb":[[2,2.24,170.03]],"ltp":2.48,"tv":6536.3,"id":8444055},{"batb":[[0,1.68,494.03],[1,1.66,1031.76],[2,1.65,593.43]],"ltp":1.73,"tv":11475.46,"id":8257852}]}]}
{"op":"mcm","clk":"1011533049","pt":1580656627235,"mc":[{"id":"1.168223927","rc":[{"trd":[[1.73,350.13]],"batb":[[1,1.66,510.84],[2,1.65,232.11]],"batl":[[0,1.73,56.68]],"ltp":1.73,"tv":11480.67,"id":8257852}],"tv":18016.98}]}
{"op":"mcm","clk":"1011533233","pt":1580656628047,"mc":[{"id":"1.168223927","rc":[{"batl":[[0,1.75,22.54],[1,1.79,453.61],[2,1.8,147.03]],"ltp":1.73,"tv":11480.67,"id":8257852}]}]}
{"op":"mcm","clk":"1011533705","pt":1580656630255,"mc":[{"id":"1.168223927","rc":[{"batl":[[0,2.42,968],[1,2.6,3.46],[2,2.76,1.68]],"ltp":2.48,"tv":6536.3,"id":8444055},{"trd":[[1.75,801.45]],"batb":[[0,1.73,3138.4],[1,1.72,1119.33],[2,1.71,633.78]],"batl":[[0,1.75,12.25],[1,1.79,2967.58],[2,1.8,160.94]],"ltp":1.75,"tv":11501.25,"id":8257852}],"tv":18037.56}]}
{"op":"mcm","clk":"1011533950","pt":1580656631226,"mc":[{"id":"1.168223927","rc":[{"trd":[[2.32,758.58],[2.34,71.74]],"batb":[[0,2.24,170.03],[1,2.2,335.27],[2,2.06,213.39]],"ltp":2.32,"tv":6545.26,"id":8444055},{"trd":[[1.75,831.73],[1.76,1525.65]],"batb":[[0,1.76,164.53],[1,1.73,3138.4],[2,1.72,1119.33]],"batl":[[0,1.79,2967.58],[1,1.8,160.94],[2,1.81,1718.11]],"ltp":1.76,"tv":11537.65,"id":8257852}],"tv":18082.91}]}
{"op":"mcm","clk":"1011534113","pt":1580656631924,"mc":[{"id":"1.168223927","rc":[{"batb":[[1,2.22,2.57],[2,2.2,335.27]],"batl":[[0,2.42,997.41]],"ltp":2.32,"tv":6545.26,"id":8444055},{"batb":[[1,1.74,461],[2,1.73,3142.88]],"ltp":1.76,"tv":11537.65,"id":8257852}]}]}
{"op":"mcm","clk":"1011535113","pt":1580656636187,"mc":[{"id":"1.168223927","rc":[{"batl":[[2,1.81,2179.11]],"ltp":1.76,"tv":11537.65,"id":8257852}]}]}
{"op":"mcm","clk":"1011535420","pt":1580656637544,"mc":[{"id":"1.168223927","rc":[{"batl":[[0,1.78,55.09],[1,1.79,2967.58],[2,1.8,160.94]],"ltp":1.76,"tv":11537.65,"id":8257852}]}]}
{"op":"mcm","clk":"1011536007","pt":1580656639965,"mc":[{"id":"1.168223927","rc":[{"trd":[[1.76,1528.33]],"batb":[[0,1.76,163.2]],"ltp":1.76,"tv":11540.32,"id":8257852}],"tv":18085.59}]}
{"op":"mcm","clk":"1011536194","pt":1580656640881,"mc":[{"id":"1.168223927","rc":[{"batl":[[1,2.76,1.68],[2,1000,0.02]],"ltp":2.32,"tv":6545.26,"id":8444055},{"trd":[[1.76,1528.99]],"batb":[[0,1.76,162.87]],"batl":[[2,1.8,147.03]],"ltp":1.76,"tv":11540.98,"id":8257852}],"tv":18086.25}]}
{"op":"mcm","clk":"1011536704","pt":1580656643136,"mc":[{"id":"1.168223927","rc":[{"trd":[[1.76,1552.46]],"batb":[[0,1.76,151.13],[1,1.74,473.93]],"batl":[[0,1.78,67.35]],"ltp":1.76,"tv":11564.45,"id":8257852}],"tv":18109.72}]}
{"op":"mcm","clk":"1011537032","pt":1580656644474,"mc":[{"id":"1.168223927","rc":[{"trd":[[1.76,1556.91]],"batb":[[0,1.76,148.91]],"ltp":1.76,"tv":11568.9,"id":8257852}],"tv":18114.17}]}
{"op":"mcm","clk":"1011537675","pt":1580656647131,"mc":[{"id":"1.168223927","rc":[{"trd":[[1.76,1566.12]],"batb":[[0,1.76,144.3]],"ltp":1.76,"tv":11578.12,"id":8257852}],"tv":18123.38}]}
{"op":"mcm","clk":"1011537803","pt":1580656647778,"mc":[{"id":"1.168223927","rc":[{"trd":[[1.76,1567.87]],"batb":[[0,1.76,143.43]],"ltp":1.76,"tv":11579.86,"id":8257852}],"tv":18125.12}]}
{"op":"mcm","clk":"1011538049","pt":1580656648887,"mc":[{"id":"1.168223927","rc":[{"trd":[[1.76,1568.67]],"batb":[[0,1.76,143.03]],"ltp":1.76,"tv":11580.66,"id":8257852}],"tv":18125.93}]}
{"op":"mcm","clk":"1011538339","pt":1580656650184,"mc":[{"id":"1.168223927","rc":[{"trd":[[1.76,1854.71]],"batb":[[0,1.74,473.93],[1,1.73,3142.88],[2,1.72,1119.33]],"batl":[[0,1.76,235.6],[1,1.78,67.35],[2,1.79,2967.58]],"ltp":1.76,"tv":11866.71,"id":8257852}],"tv":18411.97}]}
{"op":"mcm","clk":"1011538471","pt":1580656650667,"mc":[{"id":"1.168223927","rc":[{"batl":[[0,1.75,213.41],[1,1.76,235.6],[2,1.78,67.35]],"ltp":1.76,"tv":11866.71,"id":8257852}]}]}
{"op":"mcm","clk":"1011538775","pt":1580656651882,"mc":[{"id":"1.168223927","rc":[{"batl":[[1,1.76,237.72]],"ltp":1.76,"tv":11866.71,"id":8257852}]}]}
{"op":"mcm","clk":"1011539004","pt":1580656652961,"mc":[{"id":"1.168223927","rc":[{"batl":[[1,1.76,238.95]],"ltp":1.76,"tv":11866.71,"id":8257852}]}]}
{"op":"mcm","clk":"1011539738","pt":1580656655879,"mc":[{"id":"1.168223927","rc":[{"batl":[[1,1.76,239.39]],"ltp":1.76,"tv":11866.71,"id":8257852}]}]}
{"op":"mcm","clk":"1011539876","pt":1580656656489,"mc":[{"id":"1.168223927","rc":[{"batl":[[0,1.76,239.39],[1,1.78,67.35],[2,1.79,2967.58]],"ltp":1.76,"tv":11866.71,"id":8257852}]}]}
{"op":"mcm","clk":"1011540271","pt":1580656658190,"mc":[{"id":"1.168223927","rc":[{"trd":[[1.73,552.27],[1.74,3085.08]],"batb":[[0,1.73,3041.81],[1,1.72,1119.33],[2,1.71,901.89]],"ltp":1.73,"tv":13016.71,"id":8257852}],"tv":19561.97}]}
{"op":"mcm","clk":"1011540334","pt":1580656658511,"mc":[{"id":"1.168223927","rc":[{"batl":[[0,1.76,238.51]],"ltp":1.73,"tv":13016.71,"id":8257852}]}]}
{"op":"mcm","clk":"1011540673","pt":1580656660078,"mc":[{"id":"1.168223927","rc":[{"trd":[[2.34,185.43]],"batb":[[0,2.16,36.13],[1,2.06,213.39],[2,2,5.43]],"batl":[[0,2.42,29.41]],"ltp":2.34,"tv":6658.94,"id":8444055},{"trd":[[1.74,3238.05]],"batb":[[0,1.73,2502.02],[1,1.71,268.11],[2,1.65,232.11]],"batl":[[0,1.74,60.44],[1,1.76,238.51],[2,1.78,55.09]],"ltp":1.74,"tv":13169.67,"id":8257852}],"tv":19828.62}]}
{"op":"mcm","clk":"1011540847","pt":1580656660785,"mc":[{"id":"1.168223927","rc":[{"batb":[[0,2.06,213.39],[1,2,5.43],[2,1.87,21.03]],"batl":[[0,2.76,1.68],[1,1000,0.02],[2,1000,0]],"ltp":2.34,"tv":6658.94,"id":8444055},{"batb":[[0,1.73,1.93],[1,1.71,209.29]],"ltp":1.74,"tv":13169.67,"id":8257852}]}]}
{"op":"mcm","clk":"1011541482","pt":1580656663231,"mc":[{"id":"1.168223927","rc":[{"batb":[[0,2.08,209.06]],"ltp":2.34,"tv":6658.94,"id":8444055},{"batb":[[0,1.73,462.93],[1,1.68,893.21],[2,1.66,703.75]],"batl":[[1,1.76,258.51]],"ltp":1.74,"tv":13169.67,"id":8257852}]}]}
{"op":"mcm","clk":"1011541640","pt":1580656663926,"mc":[{"id":"1.168223927","rc":[{"trd":[[1.74,3358.93]],"batb":[[0,1.73,1.93]],"batl":[[0,1.76,258.51],[1,1.78,55.09],[2,1.8,147.03]],"ltp":1.74,"tv":13290.56,"id":8257852}],"tv":19949.5}]}
{"op":"mcm","clk":"1011541918","pt":1580656665208,"mc":[{"id":"1.168223927","rc":[{"trd":[[1.76,1876.56]],"batl":[[0,1.76,246.7]],"ltp":1.76,"tv":13312.4,"id":8257852}],"tv":19971.35}]}
{"op":"mcm","clk":"1011542077","pt":1580656666016,"mc":[{"id":"1.168223927","rc":[{"batb":[[0,2.3,220.46],[1,2.08,209.06],[2,2,5.43]],"batl":[[0,2.46,416.37],[1,2.5,7.23],[2,2.54,872]],"ltp":2.34,"tv":6658.94,"id":8444055},{"trd":[[1.7,2802.35],[1.73,556.13]],"batb":[[0,1.68,893.21],[1,1.66,703.75],[2,1.5,426.9]],"batl":[[0,1.7,13.39],[1,1.74,1402.7],[2,1.75,1410]],"ltp":1.7,"tv":13316.76,"id":8257852}],"tv":19975.71}]}
{"op":"mcm","clk":"1011542312","pt":1580656667064,"mc":[{"id":"1.168223927","rc":[{"batb":[[0,2.36,148.39],[1,2.3,222.99],[2,2.2,179.79]],"ltp":2.34,"tv":6658.94,"id":8444055},{"batb":[[0,1.69,2.57],[1,1.68,893.21],[2,1.66,703.75]],"ltp":1.7,"tv":13316.76,"id":8257852}]}]}
{"op":"mcm","clk":"1011542491","pt":1580656667877,"mc":[{"id":"1.168223927","rc":[{"batb":[[2,2.24,33.61]],"batl":[[2,2.52,26.89]],"ltp":2.34,"tv":6658.94,"id":8444055},{"batb":[[2,1.66,766.76]],"ltp":1.7,"tv":13316.76,"id":8257852}]}]}
{"op":"mcm","clk":"1011542613","pt":1580656668415,"mc":[{"id":"1.168223927","rc":[{"batl":[[1,2.52,26.89],[2,2.54,872]],"ltp":2.34,"tv":6658.94,"id":8444055},{"batl":[[0,1.74,1402.7],[1,1.75,1410],[2,1.76,827.98]],"ltp":1.7,"tv":13316.76,"id":8257852}]}]}
{"op":"mcm","clk":"1011542933","pt":1580656669977,"mc":[{"id":"1.168223927","rc":[{"batl":[[0,1.71,587.93],[1,1.74,1402.7],[2,1.75,1410]],"ltp":1.7,"tv":13316.76,"id":8257852}]}]}
{"op":"mcm","clk":"1011543198","pt":1580656671107,"mc":[{"id":"1.168223927","rc":[{"batl":[[0,1.7,1.36],[1,1.71,587.93],[2,1.73,461]],"ltp":1.7,"tv":13316.76,"id":8257852}]}]}
{"op":"mcm","clk":"1011543407","pt":1580656672016,"mc":[{"id":"1.168223927","rc":[{"batl":[[1,2.5,7.4],[2,2.52,26.89]],"ltp":2.34,"tv":6658.94,"id":8444055},{"batb":[[2,1.67,461]],"batl":[[0,1.7,14.75],[2,1.74,1403.14]],"ltp":1.7,"tv":13316.76,"id":8257852}]}]}
{"op":"mcm","clk":"1011544152","pt":1580656675223,"mc":[{"id":"1.168223927","rc":[{"trd":[[1.7,2803.46]],"batl":[[0,1.7,14.2],[1,1.74,1403.14],[2,1.75,1871]],"ltp":1.7,"tv":13317.87,"id":8257852}],"tv":19976.82}]}
{"op":"mcm","clk":"1011544415","pt":1580656676210,"mc":[{"id":"1.168223927","rc":[{"batl":[[1,2.52,26.89],[2,2.54,872]],"ltp":2.34,"tv":6658.94,"id":8444055},{"batl":[[0,1.73,1.26],[1,1.74,1402.7]],"ltp":1.7,"tv":13317.87,"id":8257852}]}]}
{"op":"mcm","clk":"1011544541","pt":1580656676811,"mc":[{"id":"1.168223927","rc":[{"batl":[[0,1.7,592.2],[1,1.73,1.32],[2,1.74,1402.7]],"ltp":1.7,"tv":13317.87,"id":8257852}]}]}
{"op":"mcm","clk":"1011545083","pt":1580656679206,"mc":[{"id":"1.168223927","rc":[{"batl":[[1,2.5,7.4],[2,2.52,26.89]],"ltp":2.34,"tv":6658.94,"id":8444055},{"trd":[[1.69,9.99]],"batb":[[0,1.68,893.21],[1,1.67,461],[2,1.66,766.76]],"batl":[[0,1.69,23.76],[1,1.7,605.59],[2,1.73,1.32]],"ltp":1.69,"tv":13323.01,"id":8257852}],"tv":19981.96}]}
{"op":"mcm","clk":"1011545339","pt":1580656680227,"mc":[{"id":"1.168223927","rc":[{"batl":[[0,2.52,26.89],[1,2.76,1.68],[2,1000,0.02]],"ltp":2.34,"tv":6658.94,"id":8444055},{"batl":[[1,1.7,592.2]],"ltp":1.69,"tv":13323.01,"id":8257852}]}]}
{"op":"mcm","clk":"1011545558","pt":1580656681136,"mc":[{"id":"1.168223927","rc":[{"trd":[[2.42,1337.28],[2.44,31.67]],"batb":[[0,2.3,2.53],[1,2.2,179.79],[2,2,5.43]],"batl":[[0,2.76,1.68],[1,1000,0.02],[2,1000,0]],"ltp":2.42,"tv":6848.25,"id":8444055},{"trd":[[1.69,55.72],[1.7,3027.85]],"batb":[[0,1.67,461],[1,1.65,955.03],[2,1.64,231.88]],"batl":[[0,1.7,367.81],[1,1.73,1.32],[2,1.74,933.46]],"ltp":1.7,"tv":13593.13,"id":8257852}],"tv":20441.39}]}
{"op":"mcm","clk":"1011546029","pt":1580656683206,"mc":[{"id":"1.168223927","rc":[{"batb":[[1,1.65,461]],"batl":[[0,1.7,368.15],[2,1.75,461]],"ltp":1.7,"tv":13593.13,"id":8257852}]}]}
{"op":"mcm","clk":"1011546182","pt":1580656683803,"mc":[{"id":"1.168223927","rc":[{"batb":[[0,1.65,553.22],[1,1.64,601.27],[2,1.5,426.9]],"batl":[[0,1.73,1.66],[1,1.76,189.48],[2,1.78,480.59]],"ltp":1.7,"tv":13593.13,"id":8257852}]}]}
{"op":"mcm","clk":"1011546480","pt":1580656685037,"mc":[{"id":"1.168223927","rc":[{"batl":[[0,1.69,2.58],[1,1.73,1.32],[2,1.76,189.48]],"ltp":1.7,"tv":13593.13,"id":8257852}]}]}
{"op":"mcm","clk":"1011546684","pt":1580656686032,"mc":[{"id":"1.168223927","rc":[{"trd":[[2.5,88.7]],"batb":[[0,2.48,130.96],[1,2.44,107.86],[2,2.3,2.53]],"batl":[[0,2.56,384.01],[1,2.6,5.68],[2,2.64,704]],"ltp":2.5,"tv":6849.93,"id":8444055},{"trd":[[1.66,251.05]],"batl":[[0,1.66,16.35],[1,1.69,2.58],[2,1.7,1825.07]],"ltp":1.66,"tv":13595.66,"id":8257852}],"tv":20445.6}]}
{"op":"mcm","clk":"1011546906","pt":1580656686950,"mc":[{"id":"1.168223927","rc":[{"batb":[[1,2.44,242.88],[2,2.3,159.58]],"ltp":2.5,"tv":6849.93,"id":8444055},{"batb":[[2,1.6,249.42]],"ltp":1.66,"tv":13595.66,"id":8257852}]}]}
{"op":"mcm","clk":"1011547115","pt":1580656687752,"mc":[{"id":"1.168223927","rc":[{"batb":[[2,2.3,191.51]],"batl":[[2,2.62,25.21]],"ltp":2.5,"tv":6849.93,"id":8444055},{"batb":[[2,1.63,66.38]],"batl":[[0,1.66,393.02]],"ltp":1.66,"tv":13595.66,"id":8257852}]}]}
{"op":"mcm","clk":"1011547939","pt":1580656691228,"mc":[{"id":"1.168223927","rc":[{"trd":[[1.66,255.43]],"batl":[[0,1.66,390.83]],"ltp":1.66,"tv":13600.04,"id":8257852}],"tv":20449.98}]}
{"op":"mcm","clk":"1011548192","pt":1580656692131,"mc":[{"id":"1.168223927","rc":[{"batl":[[1,1.7,1825.41],[2,1.71,461]],"ltp":1.66,"tv":13600.04,"id":8257852}]}]}
{"op":"mcm","clk":"1011548417","pt":1580656693037,"mc":[{"id":"1.168223927","rc":[{"batb":[[1,2.44,247.05],[2,2.4,3.61]],"batl":[[1,2.6,14.09]],"ltp":2.5,"tv":6849.93,"id":8444055},{"trd":[[1.65,57.67]],"batb":[[0,1.65,552.62],[2,1.63,107.61]],"batl":[[1,1.69,25.5],[2,1.7,2305.66]],"ltp":1.65,"tv":13601.25,"id":8257852}],"tv":20451.18}]}
{"op":"mcm","clk":"1011548533","pt":1580656693527,"mc":[{"id":"1.168223927","rc":[{"batb":[[1,2.44,242.88],[2,2.3,191.51]],"ltp":2.5,"tv":6849.93,"id":8444055},{"trd":[[1.66,256.55]],"batb":[[2,1.63,66.38]],"batl":[[0,1.66,390.27]],"ltp":1.66,"tv":13602.36,"id":8257852}],"tv":20452.3}]}
{"op":"mcm","clk":"1011548829","pt":1580656694726,"mc":[{"id":"1.168223927","rc":[{"batb":[[2,2.3,188.98]],"ltp":2.5,"tv":6849.93,"id":8444055}]}]}
{"op":"mcm","clk":"1011549216","pt":1580656696246,"mc":[{"id":"1.168223927","rc":[{"batl":[[1,2.6,8.41]],"ltp":2.5,"tv":6849.93,"id":8444055},{"batl":[[0,1.66,376.67]],"ltp":1.66,"tv":13602.36,"id":8257852}]}]}
{"op":"mcm","clk":"1011549892","pt":1580656699165,"mc":[{"id":"1.168223927","rc":[{"batl":[[1,2.6,17.47]],"ltp":2.5,"tv":6849.93,"id":8444055},{"batl":[[0,1.66,390.27],[2,1.7,857.66]],"ltp":1.66,"tv":13602.36,"id":8257852}]}]}
{"op":"mcm","clk":"1011550116","pt":1580656700059,"mc":[{"id":"1.168223927","rc":[{"batb":[[0,2.44,4.17],[1,2.4,3.86]],"batl":[[0,2.6,8.41],[1,2.62,25.21],[2,2.76,1.68]],"ltp":2.5,"tv":6849.93,"id":8444055},{"batb":[[0,1.63,107.61],[1,1.62,461],[2,1.61,955.03]],"batl":[[0,1.66,376.67],[2,1.7,480.59]],"ltp":1.66,"tv":13602.36,"id":8257852}]}]}
{"op":"mcm","clk":"1011550332","pt":1580656700867,"mc":[{"id":"1.168223927","rc":[{"batb":[[2,2.3,157.05]],"batl":[[1,2.76,1.68],[2,1000,0.02]],"ltp":2.5,"tv":6849.93,"id":8444055},{"batb":[[0,1.63,41.23]],"batl":[[0,1.66,377.55]],"ltp":1.66,"tv":13602.36,"id":8257852}]}]}
{"op":"mcm","clk":"1011550893","pt":1580656703237,"mc":[{"id":"1.168223927","rc":[{"trd":[[1.66,257.29]],"batb":[[0,1.63,503.44],[1,1.62,846.88]],"batl":[[0,1.65,2.01],[1,1.66,376.3],[2,1.69,25.5]],"ltp":1.66,"tv":13603.1,"id":8257852}],"tv":20453.04}]}
{"op":"mcm","clk":"1011551512","pt":1580656706080,"mc":[{"id":"1.168223927","rc":[{"batb":[[0,1.63,41.23],[1,1.62,461],[2,1.61,461]],"ltp":1.66,"tv":13603.1,"id":8257852}]}]}
{"op":"mcm","clk":"1011551610","pt":1580656706575,"mc":[{"id":"1.168223927","rc":[{"batb":[[1,1.6,249.42],[2,1.5,426.9]],"ltp":1.66,"tv":13603.1,"id":8257852}]}]}
{"op":"mcm","clk":"1011551797","pt":1580656707333,"mc":[{"id":"1.168223927","rc":[{"batb":[[2,1.4,2.54]],"ltp":1.66,"tv":13603.1,"id":8257852}]}]}
{"op":"mcm","clk":"1011552221","pt":1580656709104,"mc":[{"id":"1.168223927","rc":[{"batb":[[0,2.5,2.6],[1,2.44,4.17],[2,2.4,3.86]],"batl":[[1,2.66,476.7],[2,2.72,14.99]],"ltp":2.5,"tv":6849.93,"id":8444055},{"trd":[[1.63,568.24]],"batb":[[0,1.63,3255.58],[1,1.62,385.88],[2,1.6,249.42]],"batl":[[1,1.66,1650.3],[2,1.68,3656.26]],"ltp":1.63,"tv":13620.3,"id":8257852}],"tv":20470.24}]}
{"op":"mcm","clk":"1011552434","pt":1580656710220,"mc":[{"id":"1.168223927","rc":[{"batb":[[0,2.52,124.08],[1,2.5,2.6],[2,2.44,4.17]],"batl":[[1,2.66,501.91]],"ltp":2.5,"tv":6849.93,"id":8444055},{"trd":[[1.63,1334.7]],"batb":[[0,1.63,2872.35],[2,1.6,319.16]],"batl":[[1,1.66,1274]],"ltp":1.63,"tv":14386.76,"id":8257852}],"tv":21236.7}]}
{"op":"mcm","clk":"1011553573","pt":1580656715015,"mc":[{"id":"1.168223927","rc":[{"batb":[[0,1.64,64],[1,1.63,2872.35],[2,1.62,385.88]],"ltp":1.63,"tv":14386.76,"id":8257852}]}]}
{"op":"mcm","clk":"1011553956","pt":1580656716767,"mc":[{"id":"1.168223927","rc":[{"batb":[[0,2.52,128.07],[1,2.5,6.79]],"batl":[[1,2.62,3.75],[2,2.66,501.91]],"ltp":2.5,"tv":6849.93,"id":8444055},{"batb":[[2,1.62,417.92]],"batl":[[0,1.65,28.55],[1,1.66,1297.25]],"ltp":1.63,"tv":14386.76,"id":8257852}]}]}
{"op":"mcm","clk":"1011554294","pt":1580656718230,"mc":[{"id":"1.168223927","rc":[{"batb":[[2,2.48,4.76]],"ltp":2.5,"tv":6849.93,"id":8444055},{"batl":[[2,1.67,28.5]],"ltp":1.63,"tv":14386.76,"id":8257852}]}]}
{"op":"mcm","clk":"1011554409","pt":1580656718726,"mc":[{"id":"1.168223927","rc":[{"trd":[[1.65,59.99]],"batl":[[0,1.65,25.94]],"ltp":1.65,"tv":14389.08,"id":8257852}],"tv":21239.01}]}
{"op":"mcm","clk":"1011554665","pt":1580656719972,"mc":[{"id":"1.168223927","rc":[{"trd":[[1.65,60.43]],"batl":[[0,1.65,25.72]],"ltp":1.65,"tv":14389.52,"id":8257852}],"tv":21239.45}]}
{"op":"mcm","clk":"1011554789","pt":1580656720630,"mc":[{"id":"1.168223927","rc":[{"trd":[[1.65,64.45]],"batl":[[0,1.65,23.71]],"ltp":1.65,"tv":14393.53,"id":8257852}],"tv":21243.47}]}
{"op":"mcm","clk":"1011555015","pt":1580656721622,"mc":[{"id":"1.168223927","rc":[{"batl":[[2,2.66,511.11]],"ltp":2.5,"tv":6849.93,"id":8444055},{"trd":[[1.64,334.52]],"batb":[[0,1.64,47.77]],"ltp":1.64,"tv":14425.99,"id":8257852}],"tv":21275.93}]}
{"op":"mcm","clk":"1011555785","pt":1580656725160,"mc":[{"id":"1.168223927","rc":[{"batl":[[2,2.66,25.21]],"ltp":2.5,"tv":6849.93,"id":8444055},{"batl":[[1,1.66,23.25]],"ltp":1.64,"tv":14425.99,"id":8257852}]}]}
{"op":"mcm","clk":"1011555965","pt":1580656725961,"mc":[{"id":"1.168223927","rc":[{"batb":[[0,2.5,2.6],[1,2.48,4.76],[2,2.44,4.17]],"batl":[[0,2.62,3.75],[1,2.66,25.21],[2,2.76,1.68]],"ltp":2.5,"tv":6849.93,"id":8444055},{"batb":[[1,1.62,32.04],[2,1.6,69.74]],"batl":[[0,1.69,506.09],[1,1.71,522.9],[2,1.73,42.46]],"ltp":1.64,"tv":14425.99,"id":8257852}]}]}
{"op":"mcm","clk":"1011556241","pt":1580656727184,"mc":[{"id":"1.168223927","rc":[{"batl":[[1,2.76,1.68],[2,1000,0.02]],"ltp":2.5,"tv":6849.93,"id":8444055},{"batb":[[1,1.62,36.43],[2,1.59,754.31]],"batl":[[2,1.76,189.93]],"ltp":1.64,"tv":14425.99,"id":8257852}]}]}
{"op":"mcm","clk":"1011556391","pt":1580656727873,"mc":[{"id":"1.168223927","rc":[{"trd":[[2.5,89.15]],"batb":[[0,2.5,2.37]],"ltp":2.5,"tv":6850.39,"id":8444055},{"batb":[[0,1.65,1],[1,1.64,47.77],[2,1.62,36.43]],"ltp":1.64,"tv":14425.99,"id":8257852}],"tv":21276.39}]}
{"op":"mcm","clk":"1011556705","pt":1580656729256,"mc":[{"id":"1.168223927","rc":[{"batl":[[0,2.6,3.71],[1,2.62,3.75],[2,2.76,1.68]],"ltp":2.5,"tv":6850.39,"id":8444055},{"batb":[[0,1.65,1.25]],"batl":[[0,1.67,25.5],[1,1.69,506.09],[2,1.71,975.33]],"ltp":1.64,"tv":14425.99,"id":8257852}]}]}
{"op":"mcm","clk":"1011556843","pt":1580656729893,"mc":[{"id":"1.168223927","rc":[{"batl":[[0,2.62,3.75],[1,2.76,1.68],[2,1000,0.02]],"ltp":2.5,"tv":6850.39,"id":8444055}]}]}
{"op":"mcm","clk":"1011557174","pt":1580656731127,"mc":[{"id":"1.168223927","rc":[{"trd":[[1.65,66.95]],"batb":[[0,1.64,47.77],[1,1.63,668.36],[2,1.62,423.08]],"batl":[[1,1.69,1166.23],[2,1.71,1162.21]],"ltp":1.65,"tv":14428.5,"id":8257852}],"tv":21278.89}]}
{"op":"mcm","clk":"1011557419","pt":1580656732226,"mc":[{"id":"1.168223927","rc":[{"batb":[[0,2.5,6.3]],"ltp":2.5,"tv":6850.39,"id":8444055},{"batb":[[1,1.63,695.59]],"batl":[[0,1.66,26.25],[1,1.67,25.5],[2,1.69,1166.23]],"ltp":1.65,"tv":14428.5,"id":8257852}]}]}
{"op":"mcm","clk":"1011557639","pt":1580656733117,"mc":[{"id":"1.168223927","rc":[{"batb":[[0,2.5,2.37]],"ltp":2.5,"tv":6850.39,"id":8444055},{"batb":[[1,1.62,36.43],[2,1.59,751.01]],"batl":[[0,1.67,25.5],[1,1.69,506.09],[2,1.71,975.33]],"ltp":1.65,"tv":14428.5,"id":8257852}]}]}
{"op":"mcm","clk":"1011557925","pt":1580656734422,"mc":[{"id":"1.168223927","rc":[{"trd":[[1.64,372.52]],"batb":[[0,1.64,28.77]],"ltp":1.64,"tv":14466.5,"id":8257852}],"tv":21316.89}]}
{"op":"mcm","clk":"1011558332","pt":1580656736121,"mc":[{"id":"1.168223927","rc":[{"batb":[[0,2.5,6.49]],"ltp":2.5,"tv":6850.39,"id":8444055},{"batb":[[0,1.65,1.76],[1,1.64,28.77],[2,1.62,36.43]],"batl":[[0,1.66,27.25],[1,1.67,25.5],[2,1.69,506.09]],"ltp":1.64,"tv":14466.5,"id":8257852}]}]}
{"op":"mcm","clk":"1011558605","pt":1580656737237,"mc":[{"id":"1.168223927","rc":[{"batb":[[0,2.48,4.76],[1,2.44,4.17],[2,2.4,3.86]],"ltp":2.5,"tv":6850.39,"id":8444055},{"batl":[[0,1.67,25.5],[1,1.69,506.09],[2,1.71,975.33]],"ltp":1.64,"tv":14466.5,"id":8257852}]}]}
{"op":"mcm","clk":"1011558721","pt":1580656737701,"mc":[{"id":"1.168223927","rc":[{"batb":[[1,2.4,3.86],[2,2.38,142.81]],"ltp":2.5,"tv":6850.39,"id":8444055},{"batl":[[1,1.71,477.93],[2,1.73,615.92]],"ltp":1.64,"tv":14466.5,"id":8257852}]}]}
{"op":"mcm","clk":"1011559006","pt":1580656738883,"mc":[{"id":"1.168223927","rc":[{"trd":[[1.65,70.31]],"batb":[[0,1.64,28.85],[1,1.62,36.43],[2,1.59,751.01]],"ltp":1.65,"tv":14469.86,"id":8257852}],"tv":21320.25}]}
{"op":"mcm","clk":"1011559322","pt":1580656740214,"mc":[{"id":"1.168223927","rc":[{"batb":[[1,2.42,6.62],[2,2.4,3.86]],"batl":[[0,2.5,12],[1,2.58,3.75],[2,2.6,725]],"ltp":2.5,"tv":6850.39,"id":8444055},{"batb":[[0,1.66,952],[1,1.65,3088.73],[2,1.64,46.59]],"batl":[[1,1.71,4210.51]],"ltp":1.65,"tv":14469.86,"id":8257852}]}]}
{"op":"mcm","clk":"1011559541","pt":1580656741212,"mc":[{"id":"1.168223927","rc":[{"batb":[[0,1.66,1172.7],[1,1.65,4022.18]],"ltp":1.65,"tv":14469.86,"id":8257852}]}]}
{"op":"mcm","clk":"1011559650","pt":1580656741750,"mc":[{"id":"1.168223927","rc":[{"batl":[[1,2.56,26.89],[2,2.58,3.75]],"ltp":2.5,"tv":6850.39,"id":8444055},{"batb":[[2,1.64,112.13]],"ltp":1.65,"tv":14469.86,"id":8257852}]}]}
{"op":"mcm","clk":"1011560206","pt":1580656744214,"mc":[{"id":"1.168223927","rc":[{"batb":[[2,2.38,142.81]],"ltp":2.5,"tv":6850.39,"id":8444055},{"batb":[[2,1.64,83.36]],"batl":[[1,1.71,4185.01]],"ltp":1.65,"tv":14469.86,"id":8257852}]}]}
{"op":"mcm","clk":"1011560881","pt":1580656747158,"mc":[{"id":"1.168223927","rc":[{"batb":[[1,2.44,3.92],[2,2.42,10.56]],"ltp":2.5,"tv":6850.39,"id":8444055},{"batl":[[1,1.69,24.79],[2,1.7,24.55]],"ltp":1.65,"tv":14469.86,"id":8257852}]}]}
{"op":"mcm","clk":"1011561635","pt":1580656750717,"mc":[{"id":"1.168223927","rc":[{"trd":[[1.67,849.44]],"batl":[[0,1.67,25.26]],"ltp":1.67,"tv":14470.34,"id":8257852}],"tv":21320.73}]}
{"op":"mcm","clk":"1011561990","pt":1580656752374,"mc":[{"id":"1.168223927","rc":[{"trd":[[1.66,257.97]],"batb":[[0,1.66,1172.36]],"ltp":1.66,"tv":14471.02,"id":8257852}],"tv":21321.41}]}
{"op":"mcm","clk":"1011562350","pt":1580656754014,"mc":[{"id":"1.168223927","rc":[{"trd":[[2.5,95.15]],"batl":[[0,2.5,9]],"ltp":2.5,"tv":6856.39,"id":8444055}],"tv":21327.41}]}
{"op":"mcm","clk":"1011562414","pt":1580656754281,"mc":[{"id":"1.168223927","rc":[{"trd":[[1.66,258.86]],"batb":[[0,1.66,1171.91]],"ltp":1.66,"tv":14471.91,"id":8257852}],"tv":21328.3}]}
{"op":"mcm","clk":"1011562847","pt":1580656756178,"mc":[{"id":"1.168223927","rc":[{"trd":[[1.67,851.18]],"batl":[[0,1.67,24.39]],"ltp":1.67,"tv":14473.65,"id":8257852}],"tv":21330.04}]}
{"op":"mcm","clk":"1011563068","pt":1580656757183,"mc":[{"id":"1.168223927","rc":[{"batb":[[0,2.42,3.94],[1,2.38,142.81],[2,2.28,32.77]],"batl":[[0,2.56,26.89],[1,2.6,3.66],[2,2.62,3.75]],"ltp":2.5,"tv":6856.39,"id":8444055},{"batb":[[0,1.66,220.7],[1,1.65,3661.02],[2,1.64,65.54]],"batl":[[0,1.71,3112.17],[1,1.73,497.4],[2,1.76,189.48]],"ltp":1.67,"tv":14473.65,"id":8257852}]}]}
{"op":"mcm","clk":"1011563130","pt":1580656757476,"mc":[{"id":"1.168223927","rc":[{"batb":[[1,2.28,32.77],[2,2.26,165.39]],"batl":[[0,2.56,27.33]],"ltp":2.5,"tv":6856.39,"id":8444055},{"batb":[[0,1.64,65.61],[1,1.63,261.78],[2,1.62,530.46]],"batl":[[0,1.71,480.59]],"ltp":1.67,"tv":14473.65,"id":8257852}]}]}
{"op":"mcm","clk":"1011563442","pt":1580656758800,"mc":[{"id":"1.168223927","rc":[{"batb":[[1,2.26,165.39],[2,2,5.43]],"batl":[[0,2.6,4.11],[1,2.62,3.75],[2,2.64,3.68]],"ltp":2.5,"tv":6856.39,"id":8444055},{"batb":[[0,1.63,261.86],[1,1.62,530.46],[2,1.61,27.09]],"ltp":1.67,"tv":14473.65,"id":8257852}]}]}
{"op":"mcm","clk":"1011563775","pt":1580656760268,"mc":[{"id":"1.168223927","rc":[{"batb":[[0,2.44,4.17],[1,2.42,3.94],[2,2.26,165.39]],"batl":[[1,2.64,3.68],[2,2.76,1.68]],"ltp":2.5,"tv":6856.39,"id":8444055},{"batb":[[0,1.64,371.48],[1,1.63,638.9],[2,1.62,4.39]],"batl":[[0,1.69,26.5],[1,1.7,24.95],[2,1.71,480.59]],"ltp":1.67,"tv":14473.65,"id":8257852}]}]}
{"op":"mcm","clk":"1011563944","pt":1580656761071,"mc":[{"id":"1.168223927","rc":[{"batb":[[0,2.42,3.94],[1,2.26,165.39],[2,2,5.43]],"ltp":2.5,"tv":6856.39,"id":8444055},{"batl":[[0,1.69,1.46]],"ltp":1.67,"tv":14473.65,"id":8257852}]}]}
{"op":"mcm","clk":"1011564069","pt":1580656761617,"mc":[{"id":"1.168223927","rc":[{"trd":[[2.5,95.6]],"batl":[[0,2.6,3.66]],"ltp":2.5,"tv":6856.83,"id":8444055},{"trd":[[1.66,259.54]],"batl":[[0,1.66,1.52],[1,1.69,1.46],[2,1.7,24.95]],"ltp":1.66,"tv":14474.33,"id":8257852}],"tv":21331.17}]}
{"op":"mcm","clk":"1011564315","pt":1580656762703,"mc":[{"id":"1.168223927","rc":[{"batb":[[0,2.5,7.94],[1,2.42,3.94],[2,2.4,98.34]],"batl":[[0,2.6,387.42],[2,2.7,894]],"ltp":2.5,"tv":6856.83,"id":8444055},{"batb":[[0,1.64,380.28]],"batl":[[1,1.68,1354],[2,1.69,583.49]],"ltp":1.66,"tv":14474.33,"id":8257852}]}]}
{"op":"mcm","clk":"1011564657","pt":1580656764186,"mc":[{"id":"1.168223927","rc":[{"batb":[[0,2.44,133.21]],"batl":[[2,2.66,25.21]],"ltp":2.5,"tv":6856.83,"id":8444055},{"batb":[[0,1.64,371.48]],"ltp":1.66,"tv":14474.33,"id":8257852}]}]}
{"op":"mcm","clk":"1011564955","pt":1580656765487,"mc":[{"id":"1.168223927","rc":[{"batl":[[0,1.66,2.04]],"ltp":1.66,"tv":14474.33,"id":8257852}]}]}
{"op":"mcm","clk":"1011565365","pt":1580656767182,"mc":[{"id":"1.168223927","rc":[{"batb":[[0,2.5,7.94],[1,2.44,133.21],[2,2.42,3.94]],"ltp":2.5,"tv":6856.83,"id":8444055},{"batb":[[0,1.64,380.28]],"ltp":1.66,"tv":14474.33,"id":8257852}]}]}
{"op":"mcm","clk":"1011565745","pt":1580656768887,"mc":[{"id":"1.168223927","rc":[{"batl":[[0,1.68,1354.84],[1,1.69,583.49],[2,1.7,651.86]],"ltp":1.66,"tv":14474.33,"id":8257852}]}]}
{"op":"mcm","clk":"1011566338","pt":1580656771515,"mc":[{"id":"1.168223927","rc":[{"trd":[[2.5,97.64]],"batb":[[0,2.5,6.92]],"ltp":2.5,"tv":6858.87,"id":8444055}],"tv":21333.2}]}
{"op":"mcm","clk":"1011566950","pt":1580656774291,"mc":[{"id":"1.168223927","rc":[{"batl":[[0,1.68,1354.61]],"ltp":1.66,"tv":14474.33,"id":8257852}]}]}
{"op":"mcm","clk":"1011567376","pt":1580656776205,"mc":[{"id":"1.168223927","rc":[{"batb":[[2,1.61,27.09]],"batl":[[0,1.68,1354.17]],"ltp":1.66,"tv":14474.33,"id":8257852}]}]}
{"op":"mcm","clk":"1011567756","pt":1580656777795,"mc":[{"id":"1.168223927","rc":[{"trd":[[2.5,98.54]],"batb":[[0,2.5,6.47]],"ltp":2.5,"tv":6859.77,"id":8444055}],"tv":21334.1}]}
{"op":"mcm","clk":"1011567998","pt":1580656778904,"mc":[{"id":"1.168223927","rc":[{"batb":[[0,1.65,1.02],[1,1.64,380.2],[2,1.63,638.9]],"batl":[[0,1.68,1354]],"ltp":1.66,"tv":14474.33,"id":8257852}]}]}
{"op":"mcm","clk":"1011568171","pt":1580656779615,"mc":[{"id":"1.168223927","rc":[{"trd":[[2.5,99.44]],"batb":[[0,2.5,5.72]],"ltp":2.5,"tv":6860.67,"id":8444055},{"trd":[[1.67,852.06]],"ltp":1.67,"tv":14475.2,"id":8257852}],"tv":21335.88}]}
{"op":"mcm","clk":"1011568481","pt":1580656780929,"mc":[{"id":"1.168223927","rc":[{"trd":[[2.5,109.22]],"batb":[[0,2.44,134.04],[1,2.42,3.94],[2,2.4,98.34]],"ltp":2.5,"tv":6870.46,"id":8444055},{"batb":[[0,1.64,381.15],[1,1.63,638.9],[2,1.61,27.09]],"ltp":1.67,"tv":14475.2,"id":8257852}],"tv":21345.66}]}
{"op":"mcm","clk":"1011568678","pt":1580656781729,"mc":[{"id":"1.168223927","rc":[{"trd":[[2.5,109.81]],"batb":[[0,2.44,133.21]],"ltp":2.5,"tv":6871.05,"id":8444055},{"trd":[[1.67,852.93]],"batb":[[0,1.64,372.35]],"ltp":1.67,"tv":14476.08,"id":8257852}],"tv":21347.13}]}
{"op":"mcm","clk":"1011569037","pt":1580656783243,"mc":[{"id":"1.168223927","rc":[{"batb":[[0,1.66,1.61],[1,1.64,371.4],[2,1.63,638.9]],"ltp":1.67,"tv":14476.08,"id":8257852}]}]}
{"op":"mcm","clk":"1011569203","pt":1580656783917,"mc":[{"id":"1.168223927","rc":[{"trd":[[2.5,110.25],[2.52,13.76]],"batb":[[0,2.52,5.89],[1,2.44,133.21],[2,2.42,3.94]],"ltp":2.52,"tv":6873.56,"id":8444055},{"trd":[[1.66,262.7],[1.67,853.59]],"batb":[[0,1.64,371.4],[1,1.63,638.9],[2,1.61,27.09]],"ltp":1.66,"tv":14479.9,"id":8257852}],"tv":21353.46}]}
{"op":"mcm","clk":"1011569342","pt":1580656784604,"mc":[{"id":"1.168223927","rc":[{"trd":[[2.52,13.9]],"batb":[[0,2.52,5.75]],"batl":[[0,2.56,12.06],[1,2.6,387.42],[2,2.64,3.68]],"ltp":2.52,"tv":6873.7,"id":8444055},{"trd":[[1.66,262.92]],"batl":[[0,1.68,1365.07]],"ltp":1.66,"tv":14480.12,"id":8257852}],"tv":21353.82}]}
{"op":"mcm","clk":"1011569902","pt":1580656787106,"mc":[{"id":"1.168223927","rc":[{"trd":[[2.52,17.13]],"batb":[[0,2.52,3.52]],"ltp":2.52,"tv":6876.93,"id":8444055},{"trd":[[1.66,264.77]],"ltp":1.66,"tv":14481.98,"id":8257852}],"tv":21358.91}]}
{"op":"mcm","clk":"1011570138","pt":1580656788038,"mc":[{"id":"1.168223927","rc":[{"trd":[[2.52,17.58]],"batb":[[0,2.52,3.08]],"batl":[[0,2.6,387.42],[1,2.64,3.68],[2,2.66,25.21]],"ltp":2.52,"tv":6877.38,"id":8444055},{"trd":[[1.66,265.45]],"batl":[[0,1.68,1354]],"ltp":1.66,"tv":14482.65,"id":8257852}],"tv":21360.03}]}
{"op":"mcm","clk":"1011570303","pt":1580656788733,"mc":[{"id":"1.168223927","rc":[{"trd":[[2.52,18.24]],"batb":[[0,2.52,2.41]],"ltp":2.52,"tv":6878.04,"id":8444055},{"trd":[[1.66,266.45]],"ltp":1.66,"tv":14483.65,"id":8257852}],"tv":21361.69}]}
{"op":"mcm","clk":"1011570509","pt":1580656789713,"mc":[{"id":"1.168223927","rc":[{"batl":[[0,1.65,2.01],[1,1.68,1354],[2,1.69,583.49]],"ltp":1.66,"tv":14483.65,"id":8257852}]}]}
{"op":"mcm","clk":"1011571458","pt":1580656794242,"mc":[{"id":"1.168223927","rc":[{"trd":[[2.56,12.64]],"ltp":2.56,"tv":6890.68,"id":8444055},{"trd":[[1.64,1135.05]],"batb":[[0,1.63,638.9],[1,1.61,27.09],[2,1.6,69.74]],"batl":[[0,1.64,608.87],[1,1.65,2.01],[2,1.68,1364.19]],"ltp":1.64,"tv":15246.18,"id":8257852}],"tv":22136.86}]}
{"op":"mcm","clk":"1011571656","pt":1580656795243,"mc":[{"id":"1.168223927","rc":[{"batb":[[0,2.58,45],[1,2.52,2.41],[2,2.44,133.21]],"ltp":2.56,"tv":6890.68,"id":8444055},{"batl":[[2,1.68,1354]],"ltp":1.64,"tv":15246.18,"id":8257852}]}]}
{"op":"mcm","clk":"1011571825","pt":1580656796125,"mc":[{"id":"1.168223927","rc":[{"batl":[[1,1.68,1354],[2,1.69,1.46]],"ltp":1.64,"tv":15246.18,"id":8257852}]}]}
{"op":"mcm","clk":"1011572080","pt":1580656797222,"mc":[{"id":"1.168223927","rc":[{"trd":[[1.63,2734.72]],"batb":[[0,1.63,105.65],[1,1.62,386.92],[2,1.61,27.09]],"batl":[[1,1.68,1806.38]],"ltp":1.63,"tv":16646.19,"id":8257852}],"tv":23536.87}]}
{"op":"mcm","clk":"1011572214","pt":1580656797860,"mc":[{"id":"1.168223927","rc":[{"trd":[[2.58,359.14]],"batb":[[0,2.58,32.36]],"ltp":2.58,"tv":6915.96,"id":8444055},{"batb":[[0,1.62,386.92],[1,1.61,27.09],[2,1.6,69.74]],"batl":[[1,1.68,1354]],"ltp":1.63,"tv":16646.19,"id":8257852}],"tv":23562.15}]}
{"op":"mcm","clk":"1011572426","pt":1580656798841,"mc":[{"id":"1.168223927","rc":[{"trd":[[1.64,1136.79]],"batl":[[0,1.64,608]],"ltp":1.64,"tv":16647.93,"id":8257852}],"tv":23563.89}]}
{"op":"mcm","clk":"1011572612","pt":1580656799666,"mc":[{"id":"1.168223927","rc":[{"trd":[[1.64,1145.56]],"batl":[[0,1.64,603.61]],"ltp":1.64,"tv":16656.71,"id":8257852}],"tv":23572.67}]}
{"op":"mcm","clk":"1011572968","pt":1580656801257,"mc":[{"id":"1.168223927","rc":[{"batb":[[2,2.46,129.98]],"ltp":2.58,"tv":6915.96,"id":8444055},{"trd":[[1.64,1149.71]],"batb":[[0,1.62,930.24],[1,1.61,424.24]],"batl":[[0,1.64,601.81],[1,1.67,349.6],[2,1.68,1354]],"ltp":1.64,"tv":16660.85,"id":8257852}],"tv":23576.81}]}
{"op":"mcm","clk":"1011573106","pt":1580656801868,"mc":[{"id":"1.168223927","rc":[{"trd":[[1.64,1189.71]],"batl":[[0,1.64,581.81]],"ltp":1.64,"tv":16700.85,"id":8257852}],"tv":23616.81}]}
{"op":"mcm","clk":"1011573559","pt":1580656803817,"mc":[{"id":"1.168223927","rc":[{"batl":[[2,2.66,32.76]],"ltp":2.58,"tv":6915.96,"id":8444055},{"batl":[[0,1.64,600.88]],"ltp":1.64,"tv":16700.85,"id":8257852}]}]}
{"op":"mcm","clk":"1011573697","pt":1580656804398,"mc":[{"id":"1.168223927","rc":[{"batl":[[2,2.66,25.21]],"ltp":2.58,"tv":6915.96,"id":8444055},{"batl":[[0,1.64,581.81]],"ltp":1.64,"tv":16700.85,"id":8257852}]}]}
{"op":"mcm","clk":"1011574542","pt":1580656808123,"mc":[{"id":"1.168223927","rc":[{"batb":[[1,2.46,129.98],[2,2.42,3.94]],"ltp":2.58,"tv":6915.96,"id":8444055}]}]}
{"op":"mcm","clk":"1011575231","pt":1580656811239,"mc":[{"id":"1.168223927","rc":[{"trd":[[2.6,4.82]],"batl":[[0,2.6,385.01],[2,2.66,32.76]],"ltp":2.6,"tv":6920.78,"id":8444055},{"trd":[[1.64,1192.62]],"batl":[[0,1.64,599.42]],"ltp":1.64,"tv":16703.77,"id":8257852}],"tv":23624.55}]}
{"op":"mcm","clk":"1011575255","pt":1580656811348,"mc":[{"id":"1.168223927","rc":[{"trd":[[1.64,1193.78]],"batl":[[0,1.64,598.84]],"ltp":1.64,"tv":16704.93,"id":8257852}],"tv":23625.71}]}
{"op":"mcm","clk":"1011575610","pt":1580656812932,"mc":[{"id":"1.168223927","rc":[{"trd":[[1.64,1196.38]],"batl":[[0,1.64,597.54]],"ltp":1.64,"tv":16707.53,"id":8257852}],"tv":23628.31}]}
{"op":"mcm","clk":"1011575801","pt":1580656813721,"mc":[{"id":"1.168223927","rc":[{"trd":[[2.58,364.24]],"batb":[[0,2.58,29.81]],"ltp":2.58,"tv":6925.88,"id":8444055}],"tv":23633.41}]}
{"op":"mcm","clk":"1011576569","pt":1580656817079,"mc":[{"id":"1.168223927","rc":[{"trd":[[2.58,365.99]],"batb":[[0,2.58,28.93]],"ltp":2.58,"tv":6927.63,"id":8444055},{"trd":[[1.64,1197.9]],"batl":[[0,1.64,596.78]],"ltp":1.64,"tv":16709.04,"id":8257852}],"tv":23636.68}]}
{"op":"mcm","clk":"1011576731","pt":1580656817789,"mc":[{"id":"1.168223927","rc":[{"trd":[[1.62,65.21]],"batb":[[0,1.62,929.93]],"ltp":1.62,"tv":16709.66,"id":8257852}],"tv":23637.3}]}
{"op":"mcm","clk":"1011577014","pt":1580656818866,"mc":[{"id":"1.168223927","rc":[{"trd":[[1.64,1198.8]],"batl":[[0,1.64,596.33]],"ltp":1.64,"tv":16710.56,"id":8257852}],"tv":23638.2}]}
{"op":"mcm","clk":"1011577714","pt":1580656822086,"mc":[{"id":"1.168223927","rc":[{"batb":[[0,2.46,129.98],[1,2.42,3.94],[2,2.4,98.34]],"ltp":2.58,"tv":6927.63,"id":8444055},{"trd":[[1.62,1865.23]],"batb":[[0,1.62,29.91]],"batl":[[0,1.64,19.34]],"ltp":1.62,"tv":18510.57,"id":8257852}],"tv":25438.21}]}
{"op":"mcm","clk":"1011578420","pt":1580656825171,"mc":[{"id":"1.168223927","rc":[{"batb":[[1,1.61,735.22],[2,1.6,477.56]],"batl":[[1,1.66,373.95],[2,1.67,349.6]],"ltp":1.62,"tv":18510.57,"id":8257852}]}]}
{"op":"mcm","clk":"1011578796","pt":1580656826986,"mc":[{"id":"1.168223927","rc":[{"trd":[[1.64,1200.12]],"batl":[[0,1.64,18.41]],"ltp":1.64,"tv":18511.89,"id":8257852}],"tv":25439.53}]}
{"op":"mcm","clk":"1011579417","pt":1580656829823,"mc":[{"id":"1.168223927","rc":[{"trd":[[2.6,62.68]],"batl":[[0,2.6,356.08]],"ltp":2.6,"tv":6985.49,"id":8444055}],"tv":25497.39}]}
{"op":"mcm","clk":"1011580006","pt":1580656832474,"mc":[{"id":"1.168223927","rc":[{"trd":[[1.64,1200.51]],"batl":[[0,1.64,18.21]],"ltp":1.64,"tv":18512.29,"id":8257852}],"tv":25497.79}]}
{"op":"mcm","clk":"1011580595","pt":1580656835084,"mc":[{"id":"1.168223927","rc":[{"trd":[[1.62,1865.85]],"batb":[[0,1.62,29.6]],"ltp":1.62,"tv":18512.91,"id":8257852}],"tv":25498.41}]}
{"op":"mcm","clk":"1011581088","pt":1580656837216,"mc":[{"id":"1.168223927","rc":[{"batl":[[2,2.66,25.21]],"ltp":2.6,"tv":6985.49,"id":8444055},{"trd":[[1.64,1202.52]],"batl":[[0,1.66,373.95],[1,1.67,349.6],[2,1.68,1354]],"ltp":1.64,"tv":18514.91,"id":8257852}],"tv":25500.41}]}
{"op":"mcm","clk":"1011581837","pt":1580656840133,"mc":[{"id":"1.168223927","rc":[{"batl":[[2,2.66,33.29]],"ltp":2.6,"tv":6985.49,"id":8444055},{"trd":[[1.62,1871.12]],"batb":[[0,1.62,26.97]],"batl":[[0,1.64,18.21],[1,1.66,373.95],[2,1.67,349.6]],"ltp":1.62,"tv":18520.18,"id":8257852}],"tv":25505.68}]}
{"op":"mcm","clk":"1011582445","pt":1580656842709,"mc":[{"id":"1.168223927","rc":[{"batl":[[2,2.66,25.21]],"ltp":2.6,"tv":6985.49,"id":8444055},{"batl":[[0,1.66,373.95],[1,1.67,349.6],[2,1.68,1354]],"ltp":1.62,"tv":18520.18,"id":8257852}]}]}
{"op":"mcm","clk":"1011582784","pt":1580656844204,"mc":[{"id":"1.168223927","rc":[{"batb":[[0,2.42,3.94],[1,2.4,98.34],[2,2.36,176.91]],"batl":[[0,2.66,25.43],[1,2.76,1.68],[2,1000,0.02]],"ltp":2.6,"tv":6985.49,"id":8444055},{"batb":[[0,1.6,69.74],[1,1.54,286.8],[2,1.46,435.71]],"batl":[[0,1.69,1.46],[1,1.7,161.01],[2,1.73,42.01]],"ltp":1.62,"tv":18520.18,"id":8257852}]}]}
{"op":"mcm","clk":"1011582935","pt":1580656844817,"mc":[{"id":"1.168223927","rc":[{"batb":[[1,2.36,146.66],[2,2,5.43]],"batl":[[0,2.76,1.9],[1,1000,0.02],[2,1000,0]],"ltp":2.6,"tv":6985.49,"id":8444055},{"batb":[[0,1.54,286.8],[1,1.46,435.71],[2,1.4,2.53]],"batl":[[1,1.7,25.84],[2,1.75,1.98]],"ltp":1.62,"tv":18520.18,"id":8257852}]}]}
{"op":"mcm","clk":"1011583183","pt":1580656845815,"mc":[{"id":"1.168223927","rc":[{"trd":[[2.56,14.18]],"batl":[[0,2.76,1.68]],"ltp":2.56,"tv":6987.03,"id":8444055},{"trd":[[1.64,1204.92]],"ltp":1.64,"tv":18522.58,"id":8257852}],"tv":25509.61}]}
{"op":"mcm","clk":"1011583491","pt":1580656847234,"mc":[{"id":"1.168223927","rc":[{"batl":[[0,2.76,2.08],[1,2.82,3.75],[2,2.9,3.05]],"ltp":2.56,"tv":6987.03,"id":8444055},{"batb":[[0,1.55,29.59],[1,1.54,781.27],[2,1.53,515.5]],"batl":[[2,1.71,419.49]],"ltp":1.64,"tv":18522.58,"id":8257852}]}]}
{"op":"mcm","clk":"1011583609","pt":1580656847736,"mc":[{"id":"1.168223927","rc":[{"batb":[[0,2.44,143.44],[1,2.42,3.94]],"batl":[[1,2.9,3.05],[2,2.94,3.08]],"ltp":2.56,"tv":6987.03,"id":8444055},{"batb":[[0,1.53,32.77],[1,1.52,332.01],[2,1.46,435.71]],"batl":[[2,1.75,1.98]],"ltp":1.64,"tv":18522.58,"id":8257852}]}]}
{"op":"mcm","clk":"1011583955","pt":1580656849257,"mc":[{"id":"1.168223927","rc":[{"batb":[[0,1.53,32.46]],"ltp":1.64,"tv":18522.58,"id":8257852}]}]}
{"op":"mcm","clk":"1011584110","pt":1580656849915,"mc":[{"id":"1.168223927","rc":[{"trd":[[2.56,14.58]],"batl":[[0,2.76,1.68]],"ltp":2.56,"tv":6987.43,"id":8444055},{"trd":[[1.64,1205.8]],"batb":[[0,1.6,479.8],[1,1.59,416.68],[2,1.53,32.33]],"batl":[[0,1.65,627.87],[1,1.66,354.72],[2,1.69,1.46]],"ltp":1.64,"tv":18523.47,"id":8257852}],"tv":25510.9}]}
{"op":"mcm","clk":"1011584264","pt":1580656850609,"mc":[{"id":"1.168223927","rc":[{"batb":[[0,2.46,3.51],[1,2.44,143.44],[2,2.42,3.94]],"batl":[[1,2.82,3.75],[2,2.9,3.05]],"ltp":2.56,"tv":6987.43,"id":8444055},{"batb":[[2,1.55,29.39]],"batl":[[2,1.68,29.39]],"ltp":1.64,"tv":18523.47,"id":8257852}]}]}
{"op":"mcm","clk":"1011585128","pt":1580656854210,"mc":[{"id":"1.168223927","rc":[{"batb":[[0,2.44,143.44],[1,2.42,3.94],[2,2,5.43]],"batl":[[1,2.9,3.05],[2,2.94,3.08]],"ltp":2.56,"tv":6987.43,"id":8444055},{"batb":[[0,1.53,32.33],[1,1.52,332.01],[2,1.46,435.71]],"batl":[[0,1.69,1.46],[1,1.7,25.84],[2,1.75,1.98]],"ltp":1.64,"tv":18523.47,"id":8257852}]}]}
{"op":"mcm","clk":"1011585721","pt":1580656856926,"mc":[{"id":"1.168223927","rc":[{"trd":[[2.44,32.34]],"batb":[[0,2.44,143.11]],"ltp":2.44,"tv":6988.09,"id":8444055},{"batb":[[0,1.54,494.47],[1,1.53,515.5],[2,1.52,332.01]],"batl":[[2,1.71,419.49]],"ltp":1.64,"tv":18523.47,"id":8257852}],"tv":25511.56}]}
{"op":"mcm","clk":"1011586329","pt":1580656860013,"mc":[{"id":"1.168223927","rc":[{"batl":[[0,2.52,17.68],[1,2.76,1.68],[2,2.9,3.05]],"ltp":2.44,"tv":6988.09,"id":8444055},{"batl":[[1,1.7,28.84]],"ltp":1.64,"tv":18523.47,"id":8257852}]}]}
{"op":"mcm","clk":"1011586873","pt":1580656862168,"mc":[{"id":"1.168223927","rc":[{"batb":[[0,1.53,32.33],[1,1.52,332.01],[2,1.46,435.71]],"ltp":1.64,"tv":18523.47,"id":8257852}]}]}
{"op":"mcm","clk":"1011587093","pt":1580656862927,"mc":[{"id":"1.168223927","rc":[{"batl":[[0,2.76,1.68],[1,2.9,3.05],[2,2.94,3.08]],"ltp":2.44,"tv":6988.09,"id":8444055}]}]}
{"op":"mcm","clk":"1011587649","pt":1580656865257,"mc":[{"id":"1.168223927","rc":[{"batl":[[0,2.5,5.73],[1,2.54,737],[2,2.76,1.68]],"ltp":2.44,"tv":6988.09,"id":8444055},{"batb":[[0,1.68,540.35],[1,1.66,490.04],[2,1.65,3091]],"batl":[[1,1.7,44.67],[2,1.71,3051.07]],"ltp":1.64,"tv":18523.47,"id":8257852}]}]}
{"op":"mcm","clk":"1011587786","pt":1580656865813,"mc":[{"id":"1.168223927","rc":[{"batb":[[2,2.34,159.41]],"batl":[[1,2.54,763.89]],"ltp":2.44,"tv":6988.09,"id":8444055},{"batb":[[2,1.65,3310.84]],"ltp":1.64,"tv":18523.47,"id":8257852}]}]}
{"op":"mcm","clk":"1011587949","pt":1580656866514,"mc":[{"id":"1.168223927","rc":[{"trd":[[2.44,34.09]],"batb":[[0,2.44,142.23]],"ltp":2.44,"tv":6989.85,"id":8444055}],"tv":25513.32}]}
{"op":"mcm","clk":"1011588496","pt":1580656868968,"mc":[{"id":"1.168223927","rc":[{"trd":[[1.68,379.82]],"batb":[[0,1.68,540.04]],"ltp":1.68,"tv":18524.09,"id":8257852}],"tv":25513.94}]}
{"op":"mcm","clk":"1011589073","pt":1580656871154,"mc":[{"id":"1.168223927","rc":[{"trd":[[2.44,35.09]],"batb":[[0,2.44,141.73]],"ltp":2.44,"tv":6990.84,"id":8444055}],"tv":25514.94}]}
{"op":"mcm","clk":"1011589281","pt":1580656871959,"mc":[{"id":"1.168223927","rc":[{"batb":[[2,2.38,4.46]],"batl":[[2,2.62,4.25]],"ltp":2.44,"tv":6990.84,"id":8444055}]}]}
{"op":"mcm","clk":"1011590234","pt":1580656876241,"mc":[{"id":"1.168223927","rc":[{"trd":[[2.44,72.95]],"batb":[[0,2.44,122.8]],"ltp":2.44,"tv":7028.7,"id":8444055},{"batl":[[1,1.7,41.67]],"ltp":1.68,"tv":18524.09,"id":8257852}],"tv":25552.8}]}
{"op":"mcm","clk":"1011590338","pt":1580656876673,"mc":[{"id":"1.168223927","rc":[{"trd":[[2.44,74.27]],"batb":[[0,2.44,122.14]],"ltp":2.44,"tv":7030.02,"id":8444055},{"trd":[[1.68,382.45]],"batb":[[0,1.68,538.72]],"ltp":1.68,"tv":18526.72,"id":8257852}],"tv":25556.75}]}
{"op":"mcm","clk":"1011590972","pt":1580656879262,"mc":[{"id":"1.168223927","rc":[{"batl":[[0,2.54,26.89],[1,2.62,4.25],[2,2.68,3.39]],"ltp":2.44,"tv":7030.02,"id":8444055},{"batb":[[0,1.66,490.04],[1,1.65,3310.84],[2,1.64,559.57]],"batl":[[0,1.69,4.46],[1,1.7,25.84]],"ltp":1.68,"tv":18526.72,"id":8257852}]}]}
{"op":"mcm","clk":"1011591154","pt":1580656880066,"mc":[{"id":"1.168223927","rc":[{"batb":[[0,2.34,163.63],[1,2.28,32.77],[2,2,5.43]],"ltp":2.44,"tv":7030.02,"id":8444055},{"batb":[[0,1.64,559.57],[1,1.62,542.38],[2,1.6,28.94]],"batl":[[0,1.68,4.39],[1,1.69,1.46],[2,1.73,481.48]],"ltp":1.68,"tv":18526.72,"id":8257852}]}]}
{"op":"mcm","clk":"1011591345","pt":1580656881016,"mc":[{"id":"1.168223927","rc":[{"batb":[[1,2,5.43],[2,1.87,21.03]],"batl":[[0,2.62,4.25],[1,2.68,3.39],[2,2.76,1.68]],"ltp":2.44,"tv":7030.02,"id":8444055},{"batb":[[0,1.64,494.03]],"batl":[[0,1.68,6.52]],"ltp":1.68,"tv":18526.72,"id":8257852}]}]}
{"op":"mcm","clk":"1011591585","pt":1580656882069,"mc":[{"id":"1.168223927","rc":[{"trd":[[2.46,85.73]],"ltp":2.46,"tv":7030.54,"id":8444055},{"trd":[[1.68,383.22]],"batl":[[0,1.68,6.2]],"ltp":1.68,"tv":18527.49,"id":8257852}],"tv":25558.03}]}
{"op":"mcm","clk":"1011591851","pt":1580656883279,"mc":[{"id":"1.168223927","rc":[{"batb":[[0,2.38,4.17],[1,2.34,163.63],[2,2,5.43]],"ltp":2.46,"tv":7030.54,"id":8444055},{"batl":[[2,1.72,27.05]],"ltp":1.68,"tv":18527.49,"id":8257852}]}]}
{"op":"mcm","clk":"1011592297","pt":1580656885158,"mc":[{"id":"1.168223927","rc":[{"batb":[[0,1.65,461],[1,1.64,494.03],[2,1.62,1003.38]],"batl":[[2,1.72,488.05]],"ltp":1.68,"tv":18527.49,"id":8257852}]}]}
{"op":"mcm","clk":"1011592753","pt":1580656887074,"mc":[{"id":"1.168223927","rc":[{"batl":[[2,1.71,461.89]],"ltp":1.68,"tv":18527.49,"id":8257852}]}]}
{"op":"mcm","clk":"1011593024","pt":1580656888168,"mc":[{"id":"1.168223927","rc":[{"trd":[[2.46,86.38]],"ltp":2.46,"tv":7031.2,"id":8444055},{"trd":[[1.68,384.18]],"batl":[[0,1.68,5.24]],"ltp":1.68,"tv":18528.45,"id":8257852}],"tv":25559.66}]}
{"op":"mcm","clk":"1011593168","pt":1580656888779,"mc":[{"id":"1.168223927","rc":[{"batl":[[2,1.72,27.05]],"ltp":1.68,"tv":18528.45,"id":8257852}]}]}
{"op":"mcm","clk":"1011593424","pt":1580656889872,"mc":[{"id":"1.168223927","rc":[{"batb":[[0,1.65,491]],"ltp":1.68,"tv":18528.45,"id":8257852}]}]}
{"op":"mcm","clk":"1011593743","pt":1580656891272,"mc":[{"id":"1.168223927","rc":[{"trd":[[2.38,37.29],[2.42,1337.91]],"batb":[[0,2.34,163.63],[1,2.32,14.19]],"batl":[[0,2.36,304.55],[1,2.4,6.96],[2,2.44,922]],"ltp":2.38,"tv":7059.08,"id":8444055},{"trd":[[1.68,394.66],[1.69,58.64],[1.7,3028.74],[1.72,163]],"batb":[[0,1.7,399.41],[1,1.69,2656.02],[2,1.68,682.75]],"batl":[[0,1.74,23.25],[1,1.75,2968.76],[2,1.77,575.14]],"ltp":1.72,"tv":18568.91,"id":8257852}],"tv":25627.99}]}
{"op":"mcm","clk":"1011593943","pt":1580656892191,"mc":[{"id":"1.168223927","rc":[{"batb":[[2,2.28,173.65]],"ltp":2.38,"tv":7059.08,"id":8444055},{"batb":[[0,1.7,598.87],[1,1.69,2663.58],[2,1.68,677.64]],"ltp":1.72,"tv":18568.91,"id":8257852}]}]}
{"op":"mcm","clk":"1011593968","pt":1580656892300,"mc":[{"id":"1.168223927","rc":[{"batb":[[1,1.69,2656.02]],"ltp":1.72,"tv":18568.91,"id":8257852}]}]}
{"op":"mcm","clk":"1011594409","pt":1580656894174,"mc":[{"id":"1.168223927","rc":[{"trd":[[2.36,28.27]],"batb":[[2,2.3,2.55]],"batl":[[0,2.36,295.81]],"ltp":2.36,"tv":7076.56,"id":8444055},{"batb":[[2,1.68,678.39]],"ltp":1.72,"tv":18568.91,"id":8257852}],"tv":25645.47}]}
{"op":"mcm","clk":"1011594518","pt":1580656894588,"mc":[{"id":"1.168223927","rc":[{"batl":[[2,2.44,922.17]],"ltp":2.36,"tv":7076.56,"id":8444055}]}]}
{"op":"mcm","clk":"1011594744","pt":1580656895576,"mc":[{"id":"1.168223927","rc":[{"batb":[[2,1.68,678.65]],"ltp":1.72,"tv":18568.91,"id":8257852}]}]}
{"op":"mcm","clk":"1011595021","pt":1580656896877,"mc":[{"id":"1.168223927","rc":[{"batb":[[2,1.68,679.53]],"ltp":1.72,"tv":18568.91,"id":8257852}]}]}
{"op":"mcm","clk":"1011595235","pt":1580656897901,"mc":[{"id":"1.168223927","rc":[{"batb":[[2,2.3,6.83]],"ltp":2.36,"tv":7076.56,"id":8444055},{"batb":[[0,1.7,615.31],[1,1.69,3150.05],[2,1.68,678.78]],"batl":[[2,1.76,23.02]],"ltp":1.72,"tv":18568.91,"id":8257852}]}]}
{"op":"mcm","clk":"1011595737","pt":1580656900198,"mc":[{"id":"1.168223927","rc":[{"trd":[[1.74,3361.27]],"batl":[[0,1.74,22.08]],"ltp":1.74,"tv":18571.24,"id":8257852}],"tv":25647.81}]}
{"op":"mcm","clk":"1011595786","pt":1580656900425,"mc":[{"id":"1.168223927","rc":[{"batb":[[2,1.68,678.52]],"ltp":1.74,"tv":18571.24,"id":8257852}]}]}
{"op":"mcm","clk":"1011596149","pt":1580656901974,"mc":[{"id":"1.168223927","rc":[{"trd":[[2.36,29.08]],"batl":[[0,2.36,295]],"ltp":2.36,"tv":7077.37,"id":8444055},{"trd":[[1.73,557.24]],"batb":[[0,1.7,598.87]],"ltp":1.73,"tv":18572.36,"id":8257852}],"tv":25649.73}]}
{"op":"mcm","clk":"1011596407","pt":1580656903188,"mc":[{"id":"1.168223927","rc":[{"trd":[[2.36,30.44]],"batl":[[0,2.36,293.64]],"ltp":2.36,"tv":7078.73,"id":8444055},{"trd":[[1.73,559.1]],"ltp":1.73,"tv":18574.21,"id":8257852}],"tv":25652.95}]}
{"op":"mcm","clk":"1011596581","pt":1580656903880,"mc":[{"id":"1.168223927","rc":[{"trd":[[2.34,189.97]],"batb":[[0,2.34,161.36]],"ltp":2.34,"tv":7083.27,"id":8444055}],"tv":25657.49}]}
{"op":"mcm","clk":"1011596789","pt":1580656904910,"mc":[{"id":"1.168223927","rc":[{"trd":[[2.36,32.01]],"batl":[[0,2.36,292.07]],"ltp":2.36,"tv":7084.84,"id":8444055},{"trd":[[1.73,561.24]],"ltp":1.73,"tv":18576.35,"id":8257852}],"tv":25661.2}]}
{"op":"mcm","clk":"1011597089","pt":1580656906204,"mc":[{"id":"1.168223927","rc":[{"batb":[[1,2.3,6.83],[2,2.28,178.06]],"batl":[[0,2.48,27.9],[1,2.5,4.07],[2,2.54,3.88]],"ltp":2.36,"tv":7084.84,"id":8444055},{"trd":[[1.74,3362.26]],"batl":[[0,1.74,21.58]],"ltp":1.74,"tv":18577.35,"id":8257852}],"tv":25662.2}]}
{"op":"mcm","clk":"1011597250","pt":1580656906923,"mc":[{"id":"1.168223927","rc":[{"batb":[[0,2.3,6.83],[1,2.28,178.06],[2,2,5.43]],"batl":[[0,2.5,4.24],[1,2.54,3.88],[2,2.62,4.25]],"ltp":2.36,"tv":7084.84,"id":8444055},{"batb":[[0,1.69,3150.05],[1,1.67,537.19],[2,1.65,54.53]],"batl":[[0,1.75,2572.97],[1,1.76,23.02],[2,1.77,20.5]],"ltp":1.74,"tv":18577.35,"id":8257852}]}]}
{"op":"mcm","clk":"1011597543","pt":1580656908194,"mc":[{"id":"1.168223927","rc":[{"trd":[[2.36,32.23]],"batl":[[0,2.5,4.07]],"ltp":2.36,"tv":7085.06,"id":8444055},{"trd":[[1.74,3362.56]],"batb":[[0,1.74,2.3],[1,1.69,494.03],[2,1.67,537.19]],"batl":[[0,1.75,1.54]],"ltp":1.74,"tv":18577.65,"id":8257852}],"tv":25662.71}]}
{"op":"mcm","clk":"1011597740","pt":1580656909015,"mc":[{"id":"1.168223927","rc":[{"batb":[[0,2.3,2.55]],"ltp":2.36,"tv":7085.06,"id":8444055},{"batb":[[0,1.74,1.65]],"batl":[[1,1.77,20.5],[2,1.78,481.03]],"ltp":1.74,"tv":18577.65,"id":8257852}]}]}
{"op":"mcm","clk":"1011597927","pt":1580656909825,"mc":[{"id":"1.168223927","rc":[{"batl":[[0,2.5,4.34]],"ltp":2.36,"tv":7085.06,"id":8444055},{"batl":[[2,1.78,878.24]],"ltp":1.74,"tv":18577.65,"id":8257852}]}]}
{"op":"mcm","clk":"1011598160","pt":1580656910802,"mc":[{"id":"1.168223927","rc":[{"batl":[[2,1.78,481.03]],"ltp":1.74,"tv":18577.65,"id":8257852}]}]}
{"op":"mcm","clk":"1011598403","pt":1580656911925,"mc":[{"id":"1.168223927","rc":[{"batb":[[0,1.74,2.65]],"ltp":1.74,"tv":18577.65,"id":8257852}]}]}
{"op":"mcm","clk":"1011598654","pt":1580656913110,"mc":[{"id":"1.168223927","rc":[{"batb":[[0,1.74,3.09]],"batl":[[2,1.78,480.59]],"ltp":1.74,"tv":18577.65,"id":8257852}]}]}
{"op":"mcm","clk":"1011598887","pt":1580656914053,"mc":[{"id":"1.168223927","rc":[{"batb":[[0,2.36,10.18],[1,2.3,2.55],[2,2.28,178.06]],"batl":[[0,2.38,10.75],[1,2.5,4.07],[2,2.54,3.88]],"ltp":2.36,"tv":7085.06,"id":8444055},{"trd":[[1.74,3368.74]],"batb":[[0,1.72,10.59]],"batl":[[0,1.74,7.66],[1,1.75,1.54],[2,1.77,20.5]],"ltp":1.74,"tv":18583.82,"id":8257852}],"tv":25668.89}]}
{"op":"mcm","clk":"1011599114","pt":1580656915060,"mc":[{"id":"1.168223927","rc":[{"batb":[[0,2.3,2.55],[1,2.28,178.06],[2,2,5.43]],"batl":[[0,2.5,4.07],[1,2.54,3.88],[2,2.62,4.25]],"ltp":2.36,"tv":7085.06,"id":8444055},{"trd":[[1.74,3395.06]],"batb":[[0,1.69,889.66],[1,1.67,1229.23],[2,1.65,54.53]],"batl":[[0,1.74,412.49],[2,1.76,585.88]],"ltp":1.74,"tv":18610.15,"id":8257852}],"tv":25695.21}]}
{"op":"mcm","clk":"1011599365","pt":1580656916190,"mc":[{"id":"1.168223927","rc":[{"batb":[[0,2.3,6.73]],"ltp":2.36,"tv":7085.06,"id":8444055},{"batb":[[0,1.69,494.03],[1,1.67,537.19]],"batl":[[0,1.75,1.54],[1,1.76,24.52],[2,1.77,20.5]],"ltp":1.74,"tv":18610.15,"id":8257852}]}]}
{"op":"mcm","clk":"1011599599","pt":1580656917048,"mc":[{"id":"1.168223927","rc":[{"batb":[[0,2.3,2.55]],"ltp":2.36,"tv":7085.06,"id":8444055},{"batl":[[0,1.75,1.76],[1,1.77,20.5],[2,1.78,480.59]],"ltp":1.74,"tv":18610.15,"id":8257852}]}]}
{"op":"mcm","clk":"1011600128","pt":1580656919266,"mc":[{"id":"1.168223927","rc":[{"batl":[[2,1.78,390.1]],"ltp":1.74,"tv":18610.15,"id":8257852}]}]}
{"op":"mcm","clk":"1011600439","pt":1580656920560,"mc":[{"id":"1.168223927","rc":[{"batl":[[0,1.73,16.22],[1,1.75,1.54],[2,1.77,20.5]],"ltp":1.74,"tv":18610.15,"id":8257852}]}]}
{"op":"mcm","clk":"1011600813","pt":1580656922051,"mc":[{"id":"1.168223927","rc":[{"trd":[[2.36,44.12]],"batb":[[0,2.28,178.06],[1,2.16,36.13]],"batl":[[0,2.36,940],[1,2.4,33.9],[2,2.5,4.07]],"ltp":2.36,"tv":7096.95,"id":8444055},{"trd":[[1.73,577.46],[1.75,834.82]],"batb":[[0,1.76,723.71],[1,1.74,19.1],[2,1.72,3338.16]],"batl":[[0,1.77,20.5],[1,1.78,2918.19],[2,1.8,709.84]],"ltp":1.75,"tv":18629.46,"id":8257852}],"tv":25726.42}]}
{"op":"mcm","clk":"1011601019","pt":1580656922958,"mc":[{"id":"1.168223927","rc":[{"batb":[[1,2.22,184.98],[2,2.16,36.13]],"batl":[[0,2.36,940.45]],"ltp":2.36,"tv":7096.95,"id":8444055},{"batb":[[1,1.74,204.08]],"ltp":1.75,"tv":18629.46,"id":8257852}]}]}
{"op":"mcm","clk":"1011601306","pt":1580656924261,"mc":[{"id":"1.168223927","rc":[{"batl":[[0,2.36,940.71]],"ltp":2.36,"tv":7096.95,"id":8444055}]}]}
{"op":"mcm","clk":"1011601369","pt":1580656924530,"mc":[{"id":"1.168223927","rc":[{"trd":[[1.76,1882.62]],"batb":[[0,1.76,720.68]],"ltp":1.76,"tv":18635.52,"id":8257852}],"tv":25732.48}]}
{"op":"mcm","clk":"1011602019","pt":1580656926977,"mc":[{"id":"1.168223927","rc":[{"batl":[[0,2.36,940.45]],"ltp":2.36,"tv":7096.95,"id":8444055}]}]}
{"op":"mcm","clk":"1011602234","pt":1580656927962,"mc":[{"id":"1.168223927","rc":[{"batb":[[2,1.72,3832.2]],"ltp":1.76,"tv":18635.52,"id":8257852}]}]}
{"op":"mcm","clk":"1011602492","pt":1580656929176,"mc":[{"id":"1.168223927","rc":[{"batb":[[1,2.26,5.21],[2,2.22,184.98]],"batl":[[2,2.42,4.56]],"ltp":2.36,"tv":7096.95,"id":8444055},{"trd":[[1.76,1914.62]],"batb":[[0,1.76,704.68]],"batl":[[2,1.79,22.69]],"ltp":1.76,"tv":18667.52,"id":8257852}],"tv":25764.48}]}
{"op":"mcm","clk":"1011602704","pt":1580656929994,"mc":[{"id":"1.168223927","rc":[{"batl":[[0,2.36,940]],"ltp":2.36,"tv":7096.95,"id":8444055}]}]}
{"op":"mcm","clk":"1011602950","pt":1580656931176,"mc":[{"id":"1.168223927","rc":[{"trd":[[1.76,1915.73]],"batb":[[0,1.76,704.12]],"ltp":1.76,"tv":18668.64,"id":8257852}],"tv":25765.59}]}
{"op":"mcm","clk":"1011603181","pt":1580656932153,"mc":[{"id":"1.168223927","rc":[{"trd":[[1.76,1924.65]],"batb":[[0,1.76,699.66]],"ltp":1.76,"tv":18677.55,"id":8257852}],"tv":25774.51}]}
{"op":"mcm","clk":"1011603235","pt":1580656932366,"mc":[{"id":"1.168223927","rc":[{"batl":[[1,1.78,2938.44]],"ltp":1.76,"tv":18677.55,"id":8257852}]}]}
{"op":"mcm","clk":"1011603844","pt":1580656935171,"mc":[{"id":"1.168223927","rc":[{"trd":[[1.76,1931.31]],"batb":[[0,1.76,696.33]],"ltp":1.76,"tv":18684.21,"id":8257852}],"tv":25781.17}]}
{"op":"mcm","clk":"1011604067","pt":1580656936073,"mc":[{"id":"1.168223927","rc":[{"trd":[[2.28,143.63]],"batb":[[0,2.28,4.41]],"batl":[[0,2.4,29.41],[1,2.42,4.56],[2,2.46,4.25]],"ltp":2.28,"tv":7097.49,"id":8444055},{"trd":[[1.76,1932.2]],"batb":[[0,1.76,3],[1,1.72,3168.29],[2,1.71,24.19]],"batl":[[0,1.78,2548.34],[1,1.79,22.69],[2,1.8,566.47]],"ltp":1.76,"tv":18685.11,"id":8257852}],"tv":25782.6}]}
{"op":"mcm","clk":"1011604256","pt":1580656936878,"mc":[{"id":"1.168223927","rc":[{"batb":[[0,2.26,5.21],[1,2.22,184.98],[2,2,5.43]],"batl":[[0,2.42,4.56],[1,2.46,4.25],[2,2.5,4.07]],"ltp":2.28,"tv":7097.49,"id":8444055},{"batb":[[1,1.72,494.03]],"batl":[[0,1.79,22.69],[1,1.8,566.47],[2,1.81,480.59]],"ltp":1.76,"tv":18685.11,"id":8257852}]}]}
{"op":"mcm","clk":"1011604584","pt":1580656938170,"mc":[{"id":"1.168223927","rc":[{"trd":[[1.76,1932.64]],"batb":[[0,1.76,2.78]],"ltp":1.76,"tv":18685.55,"id":8257852}],"tv":25783.04}]}
{"op":"mcm","clk":"1011604977","pt":1580656939866,"mc":[{"id":"1.168223927","rc":[{"trd":[[1.76,1938.2]],"batb":[[0,1.72,494.03],[1,1.71,24.19],[2,1.7,510.84]],"batl":[[0,1.76,1.61],[1,1.79,22.69],[2,1.8,566.47]],"ltp":1.76,"tv":18691.11,"id":8257852}],"tv":25788.6}]}
{"op":"mcm","clk":"1011605173","pt":1580656940686,"mc":[{"id":"1.168223927","rc":[{"batl":[[0,1.76,3.27]],"ltp":1.76,"tv":18691.11,"id":8257852}]}]}
{"op":"mcm","clk":"1011605790","pt":1580656943091,"mc":[{"id":"1.168223927","rc":[{"batb":[[0,2.28,5.41],[1,2.26,5.21],[2,2.22,184.98]],"ltp":2.28,"tv":7097.49,"id":8444055},{"batl":[[1,1.78,23.75],[2,1.79,22.69]],"ltp":1.76,"tv":18691.11,"id":8257852}]}]}
{"op":"mcm","clk":"1011605914","pt":1580656943586,"mc":[{"id":"1.168223927","rc":[{"batb":[[0,2.26,5.21],[1,2.22,184.98],[2,2,5.43]],"ltp":2.28,"tv":7097.49,"id":8444055},{"batl":[[1,1.79,22.69],[2,1.8,566.47]],"ltp":1.76,"tv":18691.11,"id":8257852}]}]}
{"op":"mcm","clk":"1011606238","pt":1580656945205,"mc":[{"id":"1.168223927","rc":[{"batl":[[0,1.76,2.38]],"ltp":1.76,"tv":18691.11,"id":8257852}]}]}
{"op":"mcm","clk":"1011606814","pt":1580656948024,"mc":[{"id":"1.168223927","rc":[{"trd":[[2.24,320.34],[2.26,2338.53],[2.28,147.06],[2.3,468.37]],"batb":[[0,2.22,184.98],[1,2.08,38.65]],"batl":[[0,2.28,5.07],[1,2.3,824.86],[2,2.32,31.09]],"ltp":2.24,"tv":7428.76,"id":8444055},{"trd":[[1.76,1941],[1.78,113.16],[1.79,157.58],[1.8,987.9]],"batb":[[0,1.75,55.45],[1,1.73,162.24],[2,1.72,494.03]],"batl":[[0,1.8,4.39],[1,1.82,194.04],[2,1.83,17.25]],"ltp":1.8,"tv":19090.97,"id":8257852}],"tv":26519.73}]}
{"op":"mcm","clk":"1011607109","pt":1580656949217,"mc":[{"id":"1.168223927","rc":[{"trd":[[2.28,152.18]],"batb":[[2,2.04,236.28]],"batl":[[0,2.28,2.51]],"ltp":2.28,"tv":7433.88,"id":8444055},{"batb":[[0,1.77,174.96],[1,1.75,55.45],[2,1.73,162.24]],"ltp":1.8,"tv":19090.97,"id":8257852}],"tv":26524.85}]}
{"op":"mcm","clk":"1011607479","pt":1580656950854,"mc":[{"id":"1.168223927","rc":[{"batb":[[0,1.79,8.17],[1,1.77,174.52],[2,1.75,438.67]],"batl":[[1,1.81,555.96],[2,1.82,194.04]],"ltp":1.8,"tv":19090.97,"id":8257852}]}]}
{"op":"mcm","clk":"1011607868","pt":1580656952486,"mc":[{"id":"1.168223927","rc":[{"batl":[[1,1.81,1489.42]],"ltp":1.8,"tv":19090.97,"id":8257852}]}]}
{"op":"mcm","clk":"1011608185","pt":1580656953901,"mc":[{"id":"1.168223927","rc":[{"trd":[[1.79,163.48]],"batb":[[0,1.79,4.78]],"ltp":1.79,"tv":19096.87,"id":8257852}],"tv":26530.75}]}
{"op":"mcm","clk":"1011608408","pt":1580656954995,"mc":[{"id":"1.168223927","rc":[{"batb":[[0,1.79,4.3]],"ltp":1.79,"tv":19096.87,"id":8257852}]}]}
{"op":"mcm","clk":"1011608742","pt":1580656956202,"mc":[{"id":"1.168223927","rc":[{"trd":[[2.28,153.37]],"batl":[[0,2.28,1.32]],"ltp":2.28,"tv":7435.07,"id":8444055},{"trd":[[1.78,114.69]],"batb":[[0,1.77,174.52],[1,1.75,438.67],[2,1.73,773.98]],"ltp":1.78,"tv":19098.4,"id":8257852}],"tv":26533.47}]}
{"op":"mcm","clk":"1011608852","pt":1580656956752,"mc":[{"id":"1.168223927","rc":[{"batl":[[2,1.82,5]],"ltp":1.78,"tv":19098.4,"id":8257852}]}]}
{"op":"mcm","clk":"1011609163","pt":1580656958041,"mc":[{"id":"1.168223927","rc":[{"trd":[[2.28,154.69]],"batl":[[0,2.3,824.86],[1,2.32,31.09],[2,2.34,106.67]],"ltp":2.28,"tv":7436.39,"id":8444055},{"trd":[[1.78,116.37]],"batl":[[0,1.78,228.22],[1,1.8,4.39],[2,1.81,1489.42]],"ltp":1.78,"tv":19100.09,"id":8257852}],"tv":26536.48}]}
{"op":"mcm","clk":"1011609424","pt":1580656959119,"mc":[{"id":"1.168223927","rc":[{"batl":[[0,1.78,229.41],[2,1.81,555.96]],"ltp":1.78,"tv":19100.09,"id":8257852}]}]}
{"op":"mcm","clk":"1011609638","pt":1580656960022,"mc":[{"id":"1.168223927","rc":[{"batl":[[0,1.78,233.42],[1,1.79,189.04],[2,1.8,4.39]],"ltp":1.78,"tv":19100.09,"id":8257852}]}]}
{"op":"mcm","clk":"1011610076","pt":1580656961845,"mc":[{"id":"1.168223927","rc":[{"trd":[[1.77,264.66]],"batb":[[0,1.77,174.13]],"batl":[[1,1.79,202.21]],"ltp":1.77,"tv":19100.87,"id":8257852}],"tv":26537.26}]}
{"op":"mcm","clk":"1011610349","pt":1580656963252,"mc":[{"id":"1.168223927","rc":[{"trd":[[1.78,518.54]],"batl":[[0,1.78,32.33],[1,1.79,13.3]],"ltp":1.78,"tv":19503.04,"id":8257852}],"tv":26939.43}]}
{"op":"mcm","clk":"1011610564","pt":1580656964234,"mc":[{"id":"1.168223927","rc":[{"trd":[[1.78,518.98]],"batb":[[1,1.76,13.25],[2,1.75,438.67]],"batl":[[0,1.78,29.92],[1,1.79,17.43],[2,1.8,15.49]],"ltp":1.78,"tv":19503.48,"id":8257852}],"tv":26939.87}]}
{"op":"mcm","clk":"1011610737","pt":1580656965138,"mc":[{"id":"1.168223927","rc":[{"batl":[[0,1.78,30.74],[1,1.79,17.64]],"ltp":1.78,"tv":19503.48,"id":8257852}]}]}
{"op":"mcm","clk":"1011611013","pt":1580656966234,"mc":[{"id":"1.168223927","rc":[{"trd":[[1.77,612.9]],"batb":[[0,1.76,13.25],[1,1.75,438.67],[2,1.73,773.98]],"batl":[[0,1.77,14.93],[1,1.78,30.74],[2,1.79,17.64]],"ltp":1.77,"tv":19851.72,"id":8257852}],"tv":27288.11}]}
{"op":"mcm","clk":"1011611093","pt":1580656966553,"mc":[{"id":"1.168223927","rc":[{"batb":[[0,1.75,438.67],[1,1.73,773.98],[2,1.71,219.79]],"batl":[[1,1.78,28.51],[2,1.79,19.34]],"ltp":1.77,"tv":19851.72,"id":8257852}]}]}
{"op":"mcm","clk":"1011611433","pt":1580656968051,"mc":[{"id":"1.168223927","rc":[{"trd":[[1.77,638.1]],"batl":[[0,1.77,2.33]],"ltp":1.77,"tv":19876.92,"id":8257852}],"tv":27313.31}]}
{"op":"mcm","clk":"1011611536","pt":1580656968542,"mc":[{"id":"1.168223927","rc":[{"trd":[[2.3,482.89]],"batl":[[0,2.3,810.34]],"ltp":2.3,"tv":7450.91,"id":8444055},{"trd":[[1.76,1959.96]],"batl":[[2,1.79,19.12]],"ltp":1.76,"tv":19895.89,"id":8257852}],"tv":27346.8}]}
{"op":"mcm","clk":"1011611872","pt":1580656970016,"mc":[{"id":"1.168223927","rc":[{"trd":[[1.77,642.76]],"batl":[[0,1.77,1.24]],"ltp":1.77,"tv":19900.54,"id":8257852}],"tv":27351.46}]}
{"op":"mcm","clk":"1011612002","pt":1580656970622,"mc":[{"id":"1.168223927","rc":[{"batl":[[0,1.78,28.89],[1,1.79,17.43],[2,1.81,555.96]],"ltp":1.77,"tv":19900.54,"id":8257852}]}]}
{"op":"mcm","clk":"1011612341","pt":1580656972245,"mc":[{"id":"1.168223927","rc":[{"batl":[[0,2.32,31.09],[1,2.34,106.67],[2,2.38,4.54]],"ltp":2.3,"tv":7450.91,"id":8444055},{"batl":[[0,1.77,3.04],[1,1.78,28.05],[2,1.79,17.43]],"ltp":1.77,"tv":19900.54,"id":8257852}]}]}
{"op":"mcm","clk":"1011612473","pt":1580656972842,"mc":[{"id":"1.168223927","rc":[{"batb":[[0,2.04,236.28],[1,2,5.43],[2,1.87,21.03]],"batl":[[0,2.46,4.25],[1,2.52,8.01],[2,2.76,1.68]],"ltp":2.3,"tv":7450.91,"id":8444055},{"batb":[[0,1.71,195.6],[1,1.69,25.21],[2,1.66,37.16]],"batl":[[0,1.77,6.46],[2,1.79,13.52]],"ltp":1.77,"tv":19900.54,"id":8257852}]}]}
{"op":"mcm","clk":"1011612746","pt":1580656974131,"mc":[{"id":"1.168223927","rc":[{"batl":[[1,1.78,3.87]],"ltp":1.77,"tv":19900.54,"id":8257852}]}]}
{"op":"mcm","clk":"1011612838","pt":1580656974593,"mc":[{"id":"1.168223927","rc":[{"batl":[[0,1.77,2.13],[1,1.78,1.86]],"ltp":1.77,"tv":19900.54,"id":8257852}]}]}
{"op":"mcm","clk":"1011613201","pt":1580656976242,"mc":[{"id":"1.168223927","rc":[{"batb":[[0,2.06,229.67]],"ltp":2.3,"tv":7450.91,"id":8444055},{"batb":[[0,1.7,592.78],[2,1.68,678.01]],"batl":[[0,1.76,2.21],[1,1.77,1.09],[2,1.78,1.86]],"ltp":1.77,"tv":19900.54,"id":8257852}]}]}
{"op":"mcm","clk":"1011613633","pt":1580656978247,"mc":[{"id":"1.168223927","rc":[{"batl":[[0,1.76,453.41]],"ltp":1.77,"tv":19900.54,"id":8257852}]}]}
{"op":"mcm","clk":"1011613813","pt":1580656979127,"mc":[{"id":"1.168223927","rc":[{"batl":[[0,1.76,58.01],[1,1.78,2.74],[2,1.79,13.72]],"ltp":1.77,"tv":19900.54,"id":8257852}]}]}
{"op":"mcm","clk":"1011613997","pt":1580656980047,"mc":[{"id":"1.168223927","rc":[{"batl":[[0,1.76,8.01],[1,1.78,3.61]],"ltp":1.77,"tv":19900.54,"id":8257852}]}]}
{"op":"mcm","clk":"1011614229","pt":1580656981127,"mc":[{"id":"1.168223927","rc":[{"trd":[[2.3,483.11]],"ltp":2.3,"tv":7451.13,"id":8444055},{"trd":[[1.76,1960.25]],"batl":[[0,1.76,6.85]],"ltp":1.76,"tv":19900.83,"id":8257852}],"tv":27351.96}]}
{"op":"mcm","clk":"1011614679","pt":1580656983051,"mc":[{"id":"1.168223927","rc":[{"batl":[[0,1.76,4.39]],"ltp":1.76,"tv":19900.83,"id":8257852}]}]}
{"op":"mcm","clk":"1011614994","pt":1580656984473,"mc":[{"id":"1.168223927","rc":[{"batb":[[0,1.7,200.95],[2,1.66,37.16]],"batl":[[1,1.78,2.74]],"ltp":1.76,"tv":19900.83,"id":8257852}]}]}
{"op":"mcm","clk":"1011615244","pt":1580656985660,"mc":[{"id":"1.168223927","rc":[{"trd":[[1.7,3068.74]],"batb":[[0,1.7,180.95]],"ltp":1.7,"tv":19940.83,"id":8257852}],"tv":27391.96}]}
{"op":"mcm","clk":"1011615566","pt":1580656987172,"mc":[{"id":"1.168223927","rc":[{"batl":[[0,2.12,1663.66],[1,2.16,420.66],[2,2.3,6.27]],"ltp":2.3,"tv":7451.13,"id":8444055},{"trd":[[1.76,1969.03],[1.77,644.53],[1.78,522.7],[1.79,190.92],[1.82,45.56]],"batb":[[0,1.86,2393.49],[1,1.7,180.95],[2,1.69,25.21]],"batl":[[0,1.9,2.19],[1,1.93,2809.76],[2,1.94,12.11]],"ltp":1.82,"tv":19992.55,"id":8257852}],"tv":27443.68}]}
{"op":"mcm","clk":"1011615757","pt":1580656988109,"mc":[{"id":"1.168223927","rc":[{"batb":[[2,1.96,43.69]],"batl":[[1,2.18,10.75],[2,2.46,4.25]],"ltp":2.3,"tv":7451.13,"id":8444055},{"batb":[[0,1.89,142.1],[1,1.86,2824.79],[2,1.85,36.57]],"ltp":1.82,"tv":19992.55,"id":8257852}]}]}
{"op":"mcm","clk":"1011615939","pt":1580656988913,"mc":[{"id":"1.168223927","rc":[{"batb":[[2,1.87,175.17]],"ltp":2.3,"tv":7451.13,"id":8444055}]}]}
{"op":"mcm","clk":"1011616439","pt":1580656991173,"mc":[{"id":"1.168223927","rc":[{"batb":[[2,1.95,43.69]],"batl":[[1,2.16,36.13],[2,2.18,10.75]],"ltp":2.3,"tv":7451.13,"id":8444055},{"batb":[[2,1.85,85.3]],"ltp":1.82,"tv":19992.55,"id":8257852}]}]}
{"op":"mcm","clk":"1011617766","pt":1580656996917,"mc":[{"id":"1.168223927","rc":[{"trd":[[1.89,51.74]],"batb":[[0,1.89,116.23]],"ltp":1.89,"tv":20044.29,"id":8257852}],"tv":27495.42}]}
{"op":"mcm","clk":"1011618082","pt":1580656998211,"mc":[{"id":"1.168223927","rc":[{"trd":[[2.12,356.15]],"batl":[[0,2.12,1311.3]],"ltp":2.12,"tv":7807.27,"id":8444055},{"trd":[[1.89,675.17]],"batb":[[0,1.86,2824.79],[1,1.85,85.3],[2,1.84,498.56]],"ltp":1.89,"tv":20667.72,"id":8257852}],"tv":28475.0}]}
{"op":"mcm","clk":"1011618286","pt":1580656998935,"mc":[{"id":"1.168223927","rc":[{"trd":[[2.12,390.16]],"batl":[[0,2.12,1292.08]],"ltp":2.12,"tv":7841.28,"id":8444055},{"trd":[[1.89,680.15]],"ltp":1.89,"tv":20672.69,"id":8257852}],"tv":28513.98}]}
{"op":"mcm","clk":"1011618620","pt":1580657000182,"mc":[{"id":"1.168223927","rc":[{"trd":[[2.12,395.85]],"batl":[[0,2.12,1286.39]],"ltp":2.12,"tv":7846.97,"id":8444055},{"trd":[[1.89,686.53]],"ltp":1.89,"tv":20679.08,"id":8257852}],"tv":28526.06}]}
{"op":"mcm","clk":"1011618866","pt":1580657001217,"mc":[{"id":"1.168223927","rc":[{"batb":[[0,2,5.43],[1,1.95,43.69],[2,1.87,175.17]],"batl":[[0,2.16,36.13],[1,2.32,8.61],[2,2.42,8.25]],"ltp":2.12,"tv":7846.97,"id":8444055},{"batb":[[0,1.85,48.73],[1,1.79,167.59],[2,1.76,34.23]],"batl":[[0,1.9,2.4],[1,2,12.6],[2,2.06,39.49]],"ltp":1.89,"tv":20679.08,"id":8257852}]}]}
{"op":"mcm","clk":"1011619058","pt":1580657001997,"mc":[{"id":"1.168223927","rc":[{"batl":[[0,1.89,4.41],[1,1.9,2.19],[2,2,12.6]],"ltp":1.89,"tv":20679.08,"id":8257852}]}]}
{"op":"mcm","clk":"1011619305","pt":1580657002953,"mc":[{"id":"1.168223927","rc":[{"batb":[[1,1.87,175.17],[2,1.6,32.24]],"batl":[[0,2.32,8.61],[1,2.42,8.25],[2,2.46,4.25]],"ltp":2.12,"tv":7846.97,"id":8444055},{"batb":[[0,1.79,167.59],[1,1.76,34.23],[2,1.71,34.19]],"batl":[[0,1.89,4.66]],"ltp":1.89,"tv":20679.08,"id":8257852}]}]}
{"op":"mcm","clk":"1011619557","pt":1580657004133,"mc":[{"id":"1.168223927","rc":[{"batb":[[1,1.88,151.38],[2,1.87,175.17]],"ltp":2.12,"tv":7846.97,"id":8444055},{"batb":[[1,1.78,170.58],[2,1.76,34.23]],"ltp":1.89,"tv":20679.08,"id":8257852}]}]}
{"op":"mcm","clk":"1011619763","pt":1580657005019,"mc":[{"id":"1.168223927","rc":[{"batb":[[2,1.87,21.03]],"ltp":2.12,"tv":7846.97,"id":8444055},{"batb":[[0,1.78,170.58],[1,1.76,34.23],[2,1.71,34.19]],"batl":[[0,1.89,7.08]],"ltp":1.89,"tv":20679.08,"id":8257852}]}]}
{"op":"mcm","clk":"1011619911","pt":1580657005705,"mc":[{"id":"1.168223927","rc":[{"batl":[[0,1.89,7.28]],"ltp":1.89,"tv":20679.08,"id":8257852}]}]}
{"op":"mcm","clk":"1011620238","pt":1580657007227,"mc":[{"id":"1.168223927","rc":[{"batb":[[0,2.04,10.12],[1,2,5.43],[2,1.88,151.38]],"batl":[[0,2.12,10.21],[1,2.32,8.61],[2,2.42,8.25]],"ltp":2.12,"tv":7846.97,"id":8444055},{"trd":[[1.89,706.03],[1.9,4.38]],"batb":[[0,1.9,8.97],[1,1.89,524.17],[2,1.87,473.36]],"batl":[[0,1.95,10.7],[1,1.96,314.86],[2,1.98,404.12]],"ltp":1.9,"tv":20702.97,"id":8257852}],"tv":28549.94}]}
{"op":"mcm","clk":"1011620400","pt":1580657008027,"mc":[{"id":"1.168223927","rc":[{"batb":[[0,2,5.43],[1,1.88,151.38],[2,1.87,21.03]],"batl":[[0,2.32,8.61],[1,2.42,8.25],[2,2.46,4.25]],"ltp":2.12,"tv":7846.97,"id":8444055},{"batb":[[0,1.9,13.39]],"batl":[[0,1.96,314.86],[1,1.98,404.12],[2,2,12.6]],"ltp":1.9,"tv":20702.97,"id":8257852}]}]}
{"op":"mcm","clk":"1011620674","pt":1580657009120,"mc":[{"id":"1.168223927","rc":[{"batb":[[1,1.86,754.37],[2,1.78,170.58]],"batl":[[0,2,12.6],[1,2.42,286.52],[2,2.68,4.34]],"ltp":1.9,"tv":20702.97,"id":8257852}]}]}
{"op":"mcm","clk":"1011620824","pt":1580657009728,"mc":[{"id":"1.168223927","rc":[{"batb":[[1,1.78,170.58],[2,1.76,34.23]],"ltp":1.9,"tv":20702.97,"id":8257852}]}]}
{"op":"mcm","clk":"1011621377","pt":1580657012147,"mc":[{"id":"1.168223927","rc":[{"batb":[[0,1.9,12.62],[1,1.78,544.08],[2,1.76,611.35]],"batl":[[1,2.14,531.53],[2,2.16,313.42]],"ltp":1.9,"tv":20702.97,"id":8257852}]}]}
{"op":"mcm","clk":"1011622229","pt":1580657015914,"mc":[{"id":"1.168223927","rc":[{"batb":[[1,1.79,461],[2,1.78,544.08]],"ltp":1.9,"tv":20702.97,"id":8257852}]}]}
{"op":"mcm","clk":"1011622400","pt":1580657016664,"mc":[{"id":"1.168223927","rc":[{"batl":[[1,2.1,461],[2,2.14,531.53]],"ltp":1.9,"tv":20702.97,"id":8257852}]}]}
{"op":"mcm","clk":"1011622705","pt":1580657018022,"mc":[{"id":"1.168223927","rc":[{"trd":[[2,0.48]],"batl":[[0,2,12.36]],"ltp":2.0,"tv":20703.45,"id":8257852}],"tv":28550.43}]}
{"op":"mcm","clk":"1011624660","pt":1580657026947,"mc":[{"id":"1.168223927","rc":[{"batb":[[2,1.78,170.58]],"batl":[[2,2.42,286.52]],"ltp":2.0,"tv":20703.45,"id":8257852}]}]}
{"op":"mcm","clk":"1011624827","pt":1580657027853,"mc":[{"id":"1.168223927","rc":[{"trd":[[2,1.1]],"batl":[[0,2,12.05],[1,2.42,286.52],[2,2.68,4.34]],"ltp":2.0,"tv":20704.07,"id":8257852}],"tv":28551.05}]}
{"op":"mcm","clk":"1011625297","pt":1580657030143,"mc":[{"id":"1.168223927","rc":[{"trd":[[2,22.91]],"batb":[[0,1.88,690.31],[1,1.87,21.03],[2,1.86,481.11]],"batl":[[0,1.92,1659.19],[1,1.94,443.46],[2,1.95,329.02]],"ltp":2.0,"tv":7869.88,"id":8444055},{"trd":[[2,13.15]],"batb":[[0,2.06,2184.47],[1,2.04,367.65],[2,2.02,11.74]],"batl":[[0,2.14,2102.8],[1,2.16,13.18],[2,2.24,945]],"ltp":2.0,"tv":20716.12,"id":8257852}],"tv":28586.0}]}
{"op":"mcm","clk":"1011625510","pt":1580657031144,"mc":[{"id":"1.168223927","rc":[{"batb":[[0,1.89,150.13],[1,1.88,538.93],[2,1.87,21.03]],"ltp":2.0,"tv":7869.88,"id":8444055},{"batb":[[0,2.06,2401.4]],"ltp":2.0,"tv":20716.12,"id":8257852}]}]}
{"op":"mcm","clk":"1011625961","pt":1580657033067,"mc":[{"id":"1.168223927","rc":[{"batb":[[2,2.02,52.91]],"ltp":2.0,"tv":20716.12,"id":8257852}]}]}
{"op":"mcm","clk":"1011626176","pt":1580657033847,"mc":[{"id":"1.168223927","rc":[{"trd":[[2.14,1299.2]],"batl":[[0,2.14,1453.2]],"ltp":2.14,"tv":22015.32,"id":8257852}],"tv":29885.2}]}
{"op":"mcm","clk":"1011626471","pt":1580657035155,"mc":[{"id":"1.168223927","rc":[{"trd":[[1.92,0.48]],"batl":[[0,1.92,1658.71]],"ltp":1.92,"tv":7870.36,"id":8444055},{"trd":[[2.08,0.45],[2.14,2139.39]],"batl":[[0,2.14,1033.1]],"ltp":2.14,"tv":22855.96,"id":8257852}],"tv":30726.33}]}
{"op":"mcm","clk":"1011627088","pt":1580657038178,"mc":[{"id":"1.168223927","rc":[{"trd":[[1.92,64.34]],"batl":[[0,1.92,1626.78]],"ltp":1.92,"tv":7934.22,"id":8444055}],"tv":30790.18}]}
{"op":"mcm","clk":"1011627679","pt":1580657040748,"mc":[{"id":"1.168223927","rc":[{"trd":[[1.92,65.19]],"batl":[[0,1.92,1626.11]],"ltp":1.92,"tv":7935.07,"id":8444055},{"trd":[[2.08,0.89],[2.14,2189.39]],"batl":[[0,2.14,1008.1]],"ltp":2.14,"tv":22906.4,"id":8257852}],"tv":30841.48}]}
{"op":"mcm","clk":"1011627982","pt":1580657042155,"mc":[{"id":"1.168223927","rc":[{"trd":[[1.92,65.59]],"batl":[[0,1.92,1625.91]],"ltp":1.92,"tv":7935.47,"id":8444055}],"tv":30841.88}]}
{"op":"mcm","clk":"1011628218","pt":1580657043261,"mc":[{"id":"1.168223927","rc":[{"trd":[[1.92,67.82]],"batl":[[0,1.92,1624.8]],"ltp":1.92,"tv":7937.7,"id":8444055}],"tv":30844.1}]}
{"op":"mcm","clk":"1011628372","pt":1580657043959,"mc":[{"id":"1.168223927","rc":[{"trd":[[1.92,72.63]],"batl":[[0,1.92,1622.39]],"ltp":1.92,"tv":7942.51,"id":8444055}],"tv":30848.92}]}
{"op":"mcm","clk":"1011628605","pt":1580657045055,"mc":[{"id":"1.168223927","rc":[{"trd":[[1.92,85.29]],"batl":[[0,1.92,1616.06]],"ltp":1.92,"tv":7955.17,"id":8444055}],"tv":30861.57}]}
{"op":"mcm","clk":"1011628985","pt":1580657047109,"mc":[{"id":"1.168223927","rc":[{"trd":[[1.92,86.97]],"batl":[[0,1.92,1615.22]],"ltp":1.92,"tv":7956.85,"id":8444055}],"tv":30863.25}]}
{"op":"mcm","clk":"1011629121","pt":1580657047663,"mc":[{"id":"1.168223927","rc":[{"trd":[[1.89,8.78]],"batb":[[0,1.9,1.3],[1,1.89,145.74],[2,1.88,538.93]],"ltp":1.89,"tv":7965.62,"id":8444055}],"tv":30872.03}]}
{"op":"mcm","clk":"1011629456","pt":1580657049065,"mc":[{"id":"1.168223927","rc":[{"trd":[[1.92,87.55]],"batb":[[0,1.9,1.52],[1,1.87,21.03],[2,1.81,461]],"batl":[[0,1.96,461],[1,2.02,461],[2,2.12,461]],"ltp":1.92,"tv":7966.2,"id":8444055},{"batb":[[0,1.94,129.75],[1,1.9,12.62],[2,1.88,30.71]],"batl":[[0,2.48,3.49],[1,2.64,3.88],[2,2.68,3.64]],"ltp":2.14,"tv":22906.4,"id":8257852}],"tv":30872.61}]}
{"op":"mcm","clk":"1011629602","pt":1580657049666,"mc":[{"id":"1.168223927","rc":[{"batb":[[0,1.92,1.34],[1,1.9,1.3],[2,1.87,21.03]],"ltp":1.92,"tv":7966.2,"id":8444055}]}]}
{"op":"mcm","clk":"1011629932","pt":1580657051272,"mc":[{"id":"1.168223927","rc":[{"batb":[[0,1.87,21.03],[1,1.81,461],[2,1.75,461]],"batl":[[0,1.89,51.55],[1,1.96,461],[2,2.02,461]],"ltp":1.92,"tv":7966.2,"id":8444055}]}]}
{"op":"mcm","clk":"1011630118","pt":1580657052206,"mc":[{"id":"1.168223927","rc":[{"trd":[[1.89,8.89]],"batl":[[0,1.89,51.44]],"ltp":1.89,"tv":7966.31,"id":8444055},{"trd":[[2.12,0.1]],"batl":[[1,2.62,4.66],[2,2.64,3.18]],"ltp":2.12,"tv":22906.5,"id":8257852}],"tv":30872.82}]}
{"op":"mcm","clk":"1011630328","pt":1580657053174,"mc":[{"id":"1.168223927","rc":[{"trd":[[1.89,60.33],[1.92,87.77]],"batl":[[0,1.96,461],[1,2.02,461],[2,2.12,461]],"ltp":1.92,"tv":8017.98,"id":8444055},{"trd":[[2.08,1.09],[2.12,45.96]],"batb":[[0,1.93,131.63]],"batl":[[0,2.48,3.64]],"ltp":2.08,"tv":22952.56,"id":8257852}],"tv":30970.54}]}
{"op":"mcm","clk":"1011630755","pt":1580657055167,"mc":[{"id":"1.168223927","rc":[{"trd":[[1.87,4.87],[1.91,0.24]],"batb":[[0,1.87,18.59],[1,1.84,514.04],[2,1.82,515.8]],"batl":[[0,1.91,441.44],[1,1.93,435.63],[2,1.96,461]],"ltp":1.91,"tv":8023.1,"id":8444055},{"trd":[[2.08,1.39]],"batl":[[0,2.48,3.49]],"ltp":2.08,"tv":22952.86,"id":8257852}],"tv":30975.96}]}
{"op":"mcm","clk":"1011630936","pt":1580657055968,"mc":[{"id":"1.168223927","rc":[{"batl":[[0,1.9,461],[1,1.91,441.44],[2,1.93,435.63]],"ltp":1.91,"tv":8023.1,"id":8444055}]}]}
{"op":"mcm","clk":"1011631072","pt":1580657056601,"mc":[{"id":"1.168223927","rc":[{"batl":[[0,1.91,441.44],[1,1.93,435.63],[2,1.96,461]],"ltp":1.91,"tv":8023.1,"id":8444055}]}]}
{"op":"mcm","clk":"1011631404","pt":1580657057996,"mc":[{"id":"1.168223927","rc":[{"batb":[[1,1.8,461],[2,1.75,461]],"batl":[[0,2.14,9.25],[1,2.22,8.75],[2,2.32,8.61]],"ltp":1.91,"tv":8023.1,"id":8444055}]}]}
{"op":"mcm","clk":"1011631568","pt":1580657058765,"mc":[{"id":"1.168223927","rc":[{"batl":[[0,1.88,1.68],[1,2.14,9.25],[2,2.22,8.75]],"ltp":1.91,"tv":8023.1,"id":8444055}]}]}
{"op":"mcm","clk":"1011631874","pt":1580657060185,"mc":[{"id":"1.168223927","rc":[{"trd":[[1.88,0.57]],"batl":[[0,1.88,1.39],[1,1.94,461],[2,2.14,9.25]],"ltp":1.88,"tv":8023.67,"id":8444055}],"tv":30976.53}]}
{"op":"mcm","clk":"1011632079","pt":1580657061190,"mc":[{"id":"1.168223927","rc":[{"trd":[[1.87,42.04]],"batb":[[0,1.8,461.01],[1,1.75,461],[2,1.69,803.11]],"batl":[[0,1.94,461],[1,2,461],[2,2.08,356.76]],"ltp":1.87,"tv":8060.84,"id":8444055}],"tv":31013.7}]}
{"op":"mcm","clk":"1011632747","pt":1580657064184,"mc":[{"id":"1.168223927","rc":[{"trd":[[1.94,0.7]],"batb":[[0,1.89,1],[1,1.8,461.01],[2,1.75,461]],"batl":[[0,1.94,460.65]],"ltp":1.94,"tv":8061.54,"id":8444055}],"tv":31014.4}]}
{"op":"mcm","clk":"1011633514","pt":1580657067623,"mc":[{"id":"1.168223927","rc":[{"batl":[[2,2.1,461]],"ltp":1.94,"tv":8061.54,"id":8444055}]}]}
{"op":"mcm","clk":"1011633865","pt":1580657069231,"mc":[{"id":"1.168223927","rc":[{"batb":[[1,1.69,803.12],[2,1.68,28.36]],"ltp":1.94,"tv":8061.54,"id":8444055}]}]}
{"op":"mcm","clk":"1011634069","pt":1580657070172,"mc":[{"id":"1.168223927","rc":[{"trd":[[1.87,42.06],[1.89,62.33]],"batb":[[0,1.69,3465.83],[1,1.68,28.36],[2,1.67,689.17]],"batl":[[0,1.72,11.14],[1,1.73,1206],[2,1.75,2571.43]],"ltp":1.87,"tv":8063.56,"id":8444055},{"batb":[[0,2.36,623.93],[1,1.93,131.63],[2,1.9,12.62]],"batl":[[0,2.46,9.02],[1,2.48,3.49],[2,2.56,713.7]],"ltp":2.08,"tv":22952.86,"id":8257852}],"tv":31016.42}]}
{"op":"mcm","clk":"1011634256","pt":1580657071094,"mc":[{"id":"1.168223927","rc":[{"batl":[[2,1.75,3096.25]],"ltp":1.87,"tv":8063.56,"id":8444055},{"batb":[[0,2.36,771.77],[1,2.28,10.41],[2,2.2,176.8]],"ltp":2.08,"tv":22952.86,"id":8257852}]}]}
{"op":"mcm","clk":"1011634515","pt":1580657072140,"mc":[{"id":"1.168223927","rc":[{"batl":[[2,2.56,740.59]],"ltp":2.08,"tv":22952.86,"id":8257852}]}]}
{"op":"mcm","clk":"1011634878","pt":1580657073619,"mc":[{"id":"1.168223927","rc":[{"batb":[[1,2.28,43.18]],"ltp":2.08,"tv":22952.86,"id":8257852}]}]}
{"op":"mcm","clk":"1011635292","pt":1580657075210,"mc":[{"id":"1.168223927","rc":[{"batl":[[2,1.74,461]],"ltp":1.87,"tv":8063.56,"id":8444055}]}]}
{"op":"mcm","clk":"1011636177","pt":1580657079239,"mc":[{"id":"1.168223927","rc":[{"trd":[[1.72,3.64]],"batl":[[0,1.72,7.5]],"ltp":1.72,"tv":8067.2,"id":8444055},{"trd":[[2.38,2.63]],"ltp":2.38,"tv":22955.49,"id":8257852}],"tv":31022.69}]}
{"op":"mcm","clk":"1011637043","pt":1580657082948,"mc":[{"id":"1.168223927","rc":[{"trd":[[1.69,18.69],[1.72,4.02]],"batb":[[0,1.69,3456.49]],"batl":[[0,1.72,940.77]],"ltp":1.72,"tv":8086.27,"id":8444055}],"tv":31041.76}]}
{"op":"mcm","clk":"1011637303","pt":1580657084177,"mc":[{"id":"1.168223927","rc":[{"trd":[[1.72,16.65]],"batl":[[0,1.72,928.13]],"ltp":1.72,"tv":8098.9,"id":8444055},{"trd":[[2.38,11.76]],"ltp":2.38,"tv":22964.62,"id":8257852}],"tv":31063.53}]}
{"op":"mcm","clk":"1011637514","pt":1580657085034,"mc":[{"id":"1.168223927","rc":[{"batb":[[0,1.69,204.67],[1,1.66,461],[2,1.65,494.03]],"batl":[[1,1.74,461],[2,1.76,480.59]],"ltp":1.72,"tv":8098.9,"id":8444055},{"batb":[[0,2.36,147.84],[1,2.28,32.77]],"batl":[[0,2.56,27.59],[1,2.8,3.02],[2,2.92,3.31]],"ltp":2.38,"tv":22964.62,"id":8257852}]}]}
{"op":"mcm","clk":"1011637686","pt":1580657085845,"mc":[{"id":"1.168223927","rc":[{"batb":[[0,1.66,461],[1,1.65,494.03],[2,1.64,65.54]],"batl":[[0,1.69,14.03],[1,1.72,928.13],[2,1.74,461]],"ltp":1.72,"tv":8098.9,"id":8444055},{"batb":[[0,2.28,32.77],[1,2.2,176.64],[2,2.06,9.08]],"ltp":2.38,"tv":22964.62,"id":8257852}]}]}
{"op":"mcm","clk":"1011637934","pt":1580657086947,"mc":[{"id":"1.168223927","rc":[{"batb":[[2,1.63,971.84]],"batl":[[0,1.69,14.45]],"ltp":1.72,"tv":8098.9,"id":8444055},{"batb":[[0,2.2,176.64],[1,2.06,9.08],[2,1.92,394.91]],"batl":[[0,2.8,3.02],[1,2.92,3.31],[2,2.98,3.75]],"ltp":2.38,"tv":22964.62,"id":8257852}]}]}
{"op":"mcm","clk":"1011638244","pt":1580657088245,"mc":[{"id":"1.168223927","rc":[{"trd":[[1.69,29.41]],"batl":[[0,1.69,8.65]],"ltp":1.69,"tv":8109.62,"id":8444055},{"batb":[[1,2.12,9.04],[2,2.06,9.08]],"ltp":2.38,"tv":22964.62,"id":8257852}],"tv":31074.25}]}
{"op":"mcm","clk":"1011638317","pt":1580657088537,"mc":[{"id":"1.168223927","rc":[{"batb":[[1,2.06,9.08],[2,1.92,394.91]],"ltp":2.38,"tv":22964.62,"id":8257852}]}]}
{"op":"mcm","clk":"1011638696","pt":1580657090165,"mc":[{"id":"1.168223927","rc":[{"batl":[[0,1.69,6.88],[1,1.74,461],[2,1.79,461]],"ltp":1.69,"tv":8109.62,"id":8444055}]}]}
{"op":"mcm","clk":"1011638840","pt":1580657090743,"mc":[{"id":"1.168223927","rc":[{"batl":[[0,1.69,4.85],[1,1.83,334.28],[2,1.85,496.59]],"ltp":1.69,"tv":8109.62,"id":8444055}]}]}
{"op":"mcm","clk":"1011639125","pt":1580657091982,"mc":[{"id":"1.168223927","rc":[{"batl":[[0,1.69,3.53]],"ltp":1.69,"tv":8109.62,"id":8444055}]}]}
{"op":"mcm","clk":"1011639406","pt":1580657093255,"mc":[{"id":"1.168223927","rc":[{"trd":[[1.69,34.83]],"batb":[[0,1.77,3094.88],[1,1.75,586.96],[2,1.66,461]],"batl":[[0,1.8,595.03],[1,1.81,978],[2,1.83,2793.3]],"ltp":1.69,"tv":8115.04,"id":8444055},{"trd":[[2.44,0.22]],"batl":[[0,2.4,815],[1,2.42,353.98],[2,2.8,3.02]],"ltp":2.44,"tv":22964.84,"id":8257852}],"tv":31079.89}]}
{"op":"mcm","clk":"1011639630","pt":1580657094261,"mc":[{"id":"1.168223927","rc":[{"batb":[[0,1.78,182.23],[1,1.77,3094.88],[2,1.75,1047.96]],"ltp":1.69,"tv":8115.04,"id":8444055},{"batb":[[1,2.18,35.29],[2,2.06,9.08]],"ltp":2.44,"tv":22964.84,"id":8257852}]}]}
{"op":"mcm","clk":"1011639812","pt":1580657095155,"mc":[{"id":"1.168223927","rc":[{"trd":[[1.77,635.96],[1.78,364.45]],"batb":[[0,1.77,2776.9],[1,1.75,1047.96],[2,1.73,461]],"ltp":1.77,"tv":9115.45,"id":8444055}],"tv":32080.3}]}
{"op":"mcm","clk":"1011640058","pt":1580657096151,"mc":[{"id":"1.168223927","rc":[{"batl":[[2,2.44,28.57]],"ltp":2.44,"tv":22964.84,"id":8257852}]}]}
{"op":"mcm","clk":"1011640294","pt":1580657097139,"mc":[{"id":"1.168223927","rc":[{"batb":[[1,1.75,586.96]],"ltp":1.77,"tv":9115.45,"id":8444055}]}]}
{"op":"mcm","clk":"1011640605","pt":1580657098256,"mc":[{"id":"1.168223927","rc":[{"batl":[[2,1.82,461]],"ltp":1.77,"tv":9115.45,"id":8444055},{"batl":[[2,2.44,28.79]],"ltp":2.44,"tv":22964.84,"id":8257852}]}]}
{"op":"mcm","clk":"1011640845","pt":1580657099265,"mc":[{"id":"1.168223927","rc":[{"batl":[[0,2.28,10.76],[1,2.4,815],[2,2.42,353.98]],"ltp":2.44,"tv":22964.84,"id":8257852}]}]}
{"op":"mcm","clk":"1011642006","pt":1580657104560,"mc":[{"id":"1.168223927","rc":[{"trd":[[1.78,364.67]],"ltp":1.78,"tv":9115.67,"id":8444055},{"trd":[[2.28,0.17]],"batl":[[0,2.28,10.59]],"ltp":2.28,"tv":22965.01,"id":8257852}],"tv":32080.69}]}
{"op":"mcm","clk":"1011642836","pt":1580657108071,"mc":[{"id":"1.168223927","rc":[{"trd":[[1.78,364.93]],"ltp":1.78,"tv":9115.93,"id":8444055},{"trd":[[2.28,0.38]],"batl":[[0,2.28,10.38]],"ltp":2.28,"tv":22965.22,"id":8257852}],"tv":32081.16}]}
{"op":"mcm","clk":"1011643028","pt":1580657108942,"mc":[{"id":"1.168223927","rc":[{"batb":[[0,1.73,461],[1,1.7,955.48],[2,1.69,1]],"batl":[[0,1.82,461],[1,1.83,480.59],[2,1.85,497.4]],"ltp":1.78,"tv":9115.93,"id":8444055},{"batb":[[0,2.04,222.51],[1,1.95,28.51],[2,1.92,394.91]],"batl":[[0,2.44,1.16],[1,2.82,3.36],[2,2.92,3.31]],"ltp":2.28,"tv":22965.22,"id":8257852}]}]}
{"op":"mcm","clk":"1011643193","pt":1580657109846,"mc":[{"id":"1.168223927","rc":[{"batb":[[0,1.73,461.66]],"ltp":1.78,"tv":9115.93,"id":8444055}]}]}
{"op":"mcm","clk":"1011643483","pt":1580657111175,"mc":[{"id":"1.168223927","rc":[{"batb":[[0,1.73,461.99]],"ltp":1.78,"tv":9115.93,"id":8444055}]}]}
{"op":"mcm","clk":"1011643657","pt":1580657111952,"mc":[{"id":"1.168223927","rc":[{"batb":[[0,1.8,1.26],[1,1.73,461],[2,1.7,955.48]],"batl":[[1,1.87,461],[2,1.91,461]],"ltp":1.78,"tv":9115.93,"id":8444055},{"batb":[[0,2.06,218.11],[1,2,28.55],[2,1.95,28.51]],"ltp":2.28,"tv":22965.22,"id":8257852}]}]}
{"op":"mcm","clk":"1011643856","pt":1580657112772,"mc":[{"id":"1.168223927","rc":[{"batl":[[0,1.97,334.13],[1,1.99,427.03],[2,2.06,9.25]],"ltp":1.78,"tv":9115.93,"id":8444055},{"batb":[[1,1.95,28.51],[2,1.92,394.91]],"ltp":2.28,"tv":22965.22,"id":8257852}]}]}
{"op":"mcm","clk":"1011644121","pt":1580657113757,"mc":[{"id":"1.168223927","rc":[{"trd":[[1.8,0.3]],"batb":[[0,1.73,461],[1,1.7,955.48],[2,1.69,1]],"batl":[[0,1.78,1.19],[1,1.97,334.13],[2,1.99,427.03]],"ltp":1.8,"tv":9116.23,"id":8444055},{"trd":[[2.24,0.24]],"batb":[[2,1.6,76.02]],"batl":[[0,2.82,4.28],[1,2.92,3.31],[2,2.98,3.75]],"ltp":2.24,"tv":22965.46,"id":8257852}],"tv":32081.7}]}
{"op":"mcm","clk":"1011644450","pt":1580657115069,"mc":[{"id":"1.168223927","rc":[{"trd":[[1.78,367.31],[1.92,88.88]],"batb":[[0,1.9,1148.68],[1,1.88,465.04],[2,1.87,401.07]],"batl":[[0,1.94,616.36],[1,1.95,1127],[2,1.97,333.57]],"ltp":1.92,"tv":9119.73,"id":8444055},{"batl":[[0,2.2,839],[1,2.24,546.89],[2,2.82,4.28]],"ltp":2.24,"tv":22965.46,"id":8257852}],"tv":32085.19}]}
{"op":"mcm","clk":"1011644713","pt":1580657116204,"mc":[{"id":"1.168223927","rc":[{"batb":[[1,1.89,149.34],[2,1.88,465.04]],"batl":[[2,1.97,375.58]],"ltp":1.92,"tv":9119.73,"id":8444055},{"batb":[[1,2.02,41.17],[2,1.95,28.51]],"ltp":2.24,"tv":22965.46,"id":8257852}]}]}
{"op":"mcm","clk":"1011644927","pt":1580657117253,"mc":[{"id":"1.168223927","rc":[{"batl":[[2,2.82,235.56]],"ltp":2.24,"tv":22965.46,"id":8257852}]}]}
{"op":"mcm","clk":"1011645111","pt":1580657118059,"mc":[{"id":"1.168223927","rc":[{"batb":[[0,1.92,7.97],[1,1.9,1148.68],[2,1.89,149.34]],"batl":[[2,1.96,10.27]],"ltp":1.92,"tv":9119.73,"id":8444055},{"batl":[[0,2.2,839.31],[2,2.26,32.77]],"ltp":2.24,"tv":22965.46,"id":8257852}]}]}
{"op":"mcm","clk":"1011645377","pt":1580657119181,"mc":[{"id":"1.168223927","rc":[{"trd":[[1.9,1.56],[1.92,89.21]],"batb":[[0,1.9,1147.9],[1,1.89,149.34],[2,1.88,465.04]],"batl":[[2,1.97,375.58]],"ltp":1.9,"tv":9121.62,"id":8444055},{"trd":[[2.08,1.69]],"batl":[[0,2.2,839]],"ltp":2.08,"tv":22965.77,"id":8257852}],"tv":32087.39}]}
{"op":"mcm","clk":"1011645542","pt":1580657119964,"mc":[{"id":"1.168223927","rc":[{"batl":[[1,1.95,1588]],"ltp":1.9,"tv":9121.62,"id":8444055}]}]}
{"op":"mcm","clk":"1011645802","pt":1580657121164,"mc":[{"id":"1.168223927","rc":[{"batb":[[0,1.92,7.41],[1,1.9,1147.9],[2,1.89,149.34]],"batl":[[2,1.96,10.82]],"ltp":1.9,"tv":9121.62,"id":8444055},{"batl":[[1,2.24,548.66]],"ltp":2.08,"tv":22965.77,"id":8257852}]}]}
{"op":"mcm","clk":"1011646244","pt":1580657123002,"mc":[{"id":"1.168223927","rc":[{"trd":[[1.92,94.17]],"batb":[[0,1.92,4.93]],"batl":[[1,1.95,1127]],"ltp":1.92,"tv":9126.58,"id":8444055}],"tv":32092.35}]}
{"op":"mcm","clk":"1011646515","pt":1580657124092,"mc":[{"id":"1.168223927","rc":[{"batl":[[1,2.24,546.89]],"ltp":2.08,"tv":22965.77,"id":8257852}]}]}
{"op":"mcm","clk":"1011646672","pt":1580657124861,"mc":[{"id":"1.168223927","rc":[{"batb":[[0,1.9,1147.9],[1,1.89,149.34],[2,1.88,465.04]],"batl":[[0,1.92,1.3],[1,1.94,616.36],[2,1.95,1127]],"ltp":1.92,"tv":9126.58,"id":8444055}]}]}
{"op":"mcm","clk":"1011646970","pt":1580657126262,"mc":[{"id":"1.168223927","rc":[{"trd":[[1.92,94.43]],"batl":[[0,1.92,1.05],[1,1.96,461],[2,1.97,375.58]],"ltp":1.92,"tv":9126.83,"id":8444055},{"trd":[[2.08,1.93]],"batl":[[0,2.26,32.77],[1,2.82,235.56],[2,3.15,2.9]],"ltp":2.08,"tv":22966.0,"id":8257852}],"tv":32092.84}]}
{"op":"mcm","clk":"1011647103","pt":1580657127011,"mc":[{"id":"1.168223927","rc":[{"batb":[[0,1.82,461],[1,1.76,461.44],[2,1.58,271.35]],"batl":[[2,2.08,461]],"ltp":1.92,"tv":9126.83,"id":8444055},{"batb":[[0,1.85,150.52],[1,1.84,31.22],[2,1.77,31.37]],"batl":[[0,2.82,232.2],[1,1000,0.02],[2,3.15,0]],"ltp":2.08,"tv":22966.0,"id":8257852}]}]}
{"op":"mcm","clk":"1011647286","pt":1580657127869,"mc":[{"id":"1.168223927","rc":[{"batl":[[0,1.92,1.79]],"ltp":1.92,"tv":9126.83,"id":8444055},{"batl":[[0,2.82,231.98]],"ltp":2.08,"tv":22966.0,"id":8257852}]}]}
{"op":"mcm","clk":"1011647479","pt":1580657128770,"mc":[{"id":"1.168223927","rc":[{"trd":[[1.9,3.62],[1.92,95.47]],"batb":[[0,1.82,461.31]],"batl":[[0,1.96,461],[1,2.08,461],[2,2.16,461]],"ltp":1.92,"tv":9129.94,"id":8444055},{"trd":[[2.08,2.89],[2.1,1.86]],"batl":[[0,2.06,14.85],[1,2.82,231.98],[2,1000,0.02]],"ltp":2.08,"tv":22968.83,"id":8257852}],"tv":32098.78}]}
{"op":"mcm","clk":"1011647762","pt":1580657130048,"mc":[{"id":"1.168223927","rc":[{"trd":[[1.94,1.82]],"batb":[[0,1.82,461]],"ltp":1.94,"tv":9131.07,"id":8444055},{"trd":[[2.06,1.06]],"batl":[[0,2.06,13.79]],"ltp":2.06,"tv":22969.89,"id":8257852}],"tv":32100.96}]}
{"op":"mcm","clk":"1011648022","pt":1580657131193,"mc":[{"id":"1.168223927","rc":[{"batb":[[0,1.82,461.31],[2,1.58,270.9]],"ltp":1.94,"tv":9131.07,"id":8444055}]}]}
{"op":"mcm","clk":"1011648194","pt":1580657131992,"mc":[{"id":"1.168223927","rc":[{"trd":[[1.94,17.1]],"batb":[[0,1.83,402.62],[1,1.82,461],[2,1.81,524.84]],"batl":[[0,1.89,331.27],[1,1.91,450.39],[2,1.96,461]],"ltp":1.94,"tv":9146.35,"id":8444055},{"trd":[[2.06,14.85]],"batl":[[0,2.82,231.98],[1,1000,0.02],[2,1000,0]],"ltp":2.06,"tv":22983.68,"id":8257852}],"tv":32130.03}]}
{"op":"mcm","clk":"1011648447","pt":1580657133178,"mc":[{"id":"1.168223927","rc":[{"trd":[[1.89,63.57]],"batb":[[1,1.81,524.84],[2,1.58,271.34]],"batl":[[0,1.89,330.65]],"ltp":1.89,"tv":9147.59,"id":8444055}],"tv":32131.27}]}
{"op":"mcm","clk":"1011648481","pt":1580657133399,"mc":[{"id":"1.168223927","rc":[{"trd":[[1.89,65.55]],"batl":[[0,1.89,328.67],[1,1.91,911.39]],"ltp":1.89,"tv":9149.57,"id":8444055},{"trd":[[2.12,47.73]],"ltp":2.12,"tv":22985.45,"id":8257852}],"tv":32135.02}]}
{"op":"mcm","clk":"1011648725","pt":1580657134636,"mc":[{"id":"1.168223927","rc":[{"batl":[[2,1.96,461.47]],"ltp":1.89,"tv":9149.57,"id":8444055}]}]}
{"op":"mcm","clk":"1011649015","pt":1580657136069,"mc":[{"id":"1.168223927","rc":[{"batb":[[0,1.79,461.44],[1,1.73,461],[2,1.58,270.9]],"batl":[[0,1.91,461.56],[1,1.96,461.47],[2,2.08,461]],"ltp":1.89,"tv":9149.57,"id":8444055}]}]}
{"op":"mcm","clk":"1011649172","pt":1580657136796,"mc":[{"id":"1.168223927","rc":[{"batb":[[0,1.58,271.34],[1,1.5,2.53],[2,1.4,75.73]],"batl":[[0,1.92,1.02],[1,2.2,8.63],[2,2.3,8.05]],"ltp":1.89,"tv":9149.57,"id":8444055}]}]}
{"op":"mcm","clk":"1011649338","pt":1580657137507,"mc":[{"id":"1.168223927","rc":[{"batl":[[0,1.92,1.13]],"ltp":1.89,"tv":9149.57,"id":8444055}]}]}
{"op":"mcm","clk":"1011649710","pt":1580657139204,"mc":[{"id":"1.168223927","rc":[{"trd":[[1.9,3.87]],"batl":[[0,2.2,9.3],[1,2.3,8.05],[2,2.76,1.68]],"ltp":1.9,"tv":9149.81,"id":8444055},{"trd":[[2.1,2.09]],"batb":[[0,1.85,150.97]],"ltp":2.1,"tv":22985.67,"id":8257852}],"tv":32135.49}]}
{"op":"mcm","clk":"1011649909","pt":1580657140221,"mc":[{"id":"1.168223927","rc":[{"batb":[[2,1.3,113.59]],"batl":[[0,1.82,2.23],[1,2.2,9.3],[2,2.3,8.05]],"ltp":1.9,"tv":9149.81,"id":8444055}]}]}
{"op":"mcm","clk":"1011650138","pt":1580657141226,"mc":[{"id":"1.168223927","rc":[{"trd":[[1.82,1.23],[1.9,3.96],[1.92,95.59]],"batb":[[0,2.12,2122.64],[1,2,285.54],[2,1.58,271.34]],"batl":[[0,2.18,1000],[1,2.2,820.05],[2,2.22,2027.03]],"ltp":1.92,"tv":9151.24,"id":8444055},{"trd":[[2.06,15.75],[2.08,2.99],[2.1,2.17],[2.2,1.01]],"batb":[[0,1.85,150.52],[1,1.82,471.87],[2,1.8,535.74]],"batl":[[0,1.89,546.77],[1,1.91,450.78],[2,1.97,1059]],"ltp":2.06,"tv":22987.76,"id":8257852}],"tv":32139.0}]}
{"op":"mcm","clk":"1011650374","pt":1580657142065,"mc":[{"id":"1.168223927","rc":[{"batb":[[1,2.1,216.45],[2,2,285.54]],"batl":[[0,2.18,1035.29]],"ltp":1.92,"tv":9151.24,"id":8444055},{"batb":[[0,1.85,199.25]],"ltp":2.06,"tv":22987.76,"id":8257852}]}]}
{"op":"mcm","clk":"1011650802","pt":1580657144089,"mc":[{"id":"1.168223927","rc":[{"trd":[[2.12,399.21]],"batb":[[0,2.12,2120.96]],"ltp":2.12,"tv":9154.6,"id":8444055}],"tv":32142.36}]}
{"op":"mcm","clk":"1011651189","pt":1580657145920,"mc":[{"id":"1.168223927","rc":[{"batl":[[0,1.88,25],[1,1.89,546.77],[2,1.91,450.78]],"ltp":2.06,"tv":22987.76,"id":8257852}]}]}
{"op":"mcm","clk":"1011651382","pt":1580657146927,"mc":[{"id":"1.168223927","rc":[{"batb":[[1,1.84,461],[2,1.82,471.87]],"ltp":2.06,"tv":22987.76,"id":8257852}]}]}
{"op":"mcm","clk":"1011652347","pt":1580657151225,"mc":[{"id":"1.168223927","rc":[{"trd":[[1.88,13.46]],"batl":[[0,1.88,18.27]],"ltp":1.88,"tv":23001.22,"id":8257852}],"tv":32155.83}]}
{"op":"mcm","clk":"1011652627","pt":1580657152645,"mc":[{"id":"1.168223927","rc":[{"trd":[[1.85,1.01]],"batb":[[0,1.85,198.74]],"ltp":1.85,"tv":23002.23,"id":8257852}],"tv":32156.84}]}
{"op":"mcm","clk":"1011652907","pt":1580657154140,"mc":[{"id":"1.168223927","rc":[{"trd":[[1.88,15.68]],"batl":[[0,1.88,17.16]],"ltp":1.88,"tv":23004.45,"id":8257852}],"tv":32159.06}]}
{"op":"mcm","clk":"1011653329","pt":1580657156077,"mc":[{"id":"1.168223927","rc":[{"batb":[[1,1.95,43.69],[2,1.86,156.81]],"batl":[[0,2.18,35.29],[1,2.22,2027.03],[2,2.32,8.86]],"ltp":2.12,"tv":9154.6,"id":8444055},{"trd":[[1.88,16.8]],"batb":[[0,1.85,48.73],[2,1.79,461]],"batl":[[0,1.88,16.6],[1,1.96,461],[2,2.04,501.33]],"ltp":1.88,"tv":23005.57,"id":8257852}],"tv":32160.17}]}
{"op":"mcm","clk":"1011653530","pt":1580657156950,"mc":[{"id":"1.168223927","rc":[{"batb":[[0,1.86,156.81],[1,1.59,34.55],[2,1.52,33.99]],"batl":[[0,2.32,8.86],[1,2.4,8.24],[2,2.76,1.68]],"ltp":2.12,"tv":9154.6,"id":8444055},{"batb":[[0,1.84,461],[1,1.79,461],[2,1.76,34.73]],"batl":[[2,2.04,461]],"ltp":1.88,"tv":23005.57,"id":8257852}]}]}
{"op":"mcm","clk":"1011653690","pt":1580657157752,"mc":[{"id":"1.168223927","rc":[{"trd":[[2.12,399.61],[2.16,1.28]],"ltp":2.12,"tv":9156.28,"id":8444055},{"trd":[[1.85,2.5],[1.88,19.85]],"batl":[[0,1.88,14.85]],"ltp":1.88,"tv":23010.11,"id":8257852}],"tv":32166.39}]}
{"op":"mcm","clk":"1011654311","pt":1580657161050,"mc":[{"id":"1.168223927","rc":[{"trd":[[1.85,2.95],[1.88,22.45]],"batl":[[0,1.85,3.43],[1,1.88,13.55],[2,1.96,461]],"ltp":1.85,"tv":23013.15,"id":8257852}],"tv":32169.44}]}
{"op":"mcm","clk":"1011654503","pt":1580657161935,"mc":[{"id":"1.168223927","rc":[{"trd":[[1.85,4.04]],"batl":[[0,1.85,2.89]],"ltp":1.85,"tv":23014.25,"id":8257852}],"tv":32170.54}]}
{"op":"mcm","clk":"1011654718","pt":1580657163063,"mc":[{"id":"1.168223927","rc":[{"trd":[[2.16,2.15]],"ltp":2.16,"tv":9157.16,"id":8444055},{"trd":[[1.85,5.07]],"batb":[[0,1.76,34.73],[1,1.75,181.2],[2,1.72,654.67]],"batl":[[0,1.85,1.86]],"ltp":1.85,"tv":23015.27,"id":8257852}],"tv":32172.44}]}
{"op":"mcm","clk":"1011654879","pt":1580657163841,"mc":[{"id":"1.168223927","rc":[{"batl":[[0,2.4,8.24],[1,2.76,1.68],[2,1000,0.02]],"ltp":2.16,"tv":9157.16,"id":8444055},{"trd":[[1.85,5.6]],"batb":[[0,1.75,181.2],[1,1.72,654.67],[2,1.7,650.62]],"batl":[[0,1.85,1.59]],"ltp":1.85,"tv":23015.81,"id":8257852}],"tv":32172.97}]}
{"op":"mcm","clk":"1011655167","pt":1580657165256,"mc":[{"id":"1.168223927","rc":[{"batl":[[0,2.32,413.05],[1,2.36,1084],[2,2.4,8.24]],"ltp":2.16,"tv":9157.16,"id":8444055},{"batb":[[1,1.74,10.8],[2,1.72,3270.95]],"batl":[[0,1.78,2542.47],[1,1.85,1201.59],[2,1.86,478.22]],"ltp":1.85,"tv":23015.81,"id":8257852}]}]}
{"op":"mcm","clk":"1011655373","pt":1580657166257,"mc":[{"id":"1.168223927","rc":[{"batb":[[0,2.26,177.74],[1,2.08,38.65],[2,2.06,228.18]],"batl":[[0,2.32,444.14]],"ltp":2.16,"tv":9157.16,"id":8444055},{"batb":[[0,1.76,54.61],[1,1.75,181.2],[2,1.74,10.8]],"batl":[[0,1.78,2955.17],[1,1.79,933.46],[2,1.8,543.99]],"ltp":1.85,"tv":23015.81,"id":8257852}]}]}
{"op":"mcm","clk":"1011655594","pt":1580657167236,"mc":[{"id":"1.168223927","rc":[{"trd":[[1.78,524.82]],"batl":[[0,1.78,2954.11],[1,1.8,543.99],[2,1.84,448.63]],"ltp":1.78,"tv":23017.92,"id":8257852}],"tv":32175.09}]}
{"op":"mcm","clk":"1011656166","pt":1580657169962,"mc":[{"id":"1.168223927","rc":[{"batl":[[2,1.85,1201.59]],"ltp":1.78,"tv":23017.92,"id":8257852}]}]}
{"op":"mcm","clk":"1011656615","pt":1580657171754,"mc":[{"id":"1.168223927","rc":[{"trd":[[1.78,530.82]],"batl":[[0,1.78,2951.11]],"ltp":1.78,"tv":23023.92,"id":8257852}],"tv":32181.09}]}
{"op":"mcm","clk":"1011656971","pt":1580657173183,"mc":[{"id":"1.168223927","rc":[{"batb":[[1,2.14,5.32],[2,2.08,43.46]],"ltp":2.16,"tv":9157.16,"id":8444055}]}]}
{"op":"mcm","clk":"1011657196","pt":1580657173957,"mc":[{"id":"1.168223927","rc":[{"trd":[[2.28,154.94]],"ltp":2.28,"tv":9157.41,"id":8444055},{"trd":[[1.78,531.14]],"batl":[[0,1.78,2950.79]],"ltp":1.78,"tv":23024.24,"id":8257852}],"tv":32181.66}]}
{"op":"mcm","clk":"1011657282","pt":1580657174291,"mc":[{"id":"1.168223927","rc":[{"trd":[[1.78,532.25]],"batl":[[0,1.78,2950.23]],"ltp":1.78,"tv":23025.36,"id":8257852}],"tv":32182.78}]}
{"op":"mcm","clk":"1011657819","pt":1580657176636,"mc":[{"id":"1.168223927","rc":[{"trd":[[1.76,1996.13]],"batb":[[0,1.76,41.06]],"ltp":1.76,"tv":23052.46,"id":8257852}],"tv":32209.88}]}
{"op":"mcm","clk":"1011658147","pt":1580657178153,"mc":[{"id":"1.168223927","rc":[{"trd":[[2.28,156.94]],"batb":[[0,2.14,5.32],[1,2.08,43.46],[2,2.06,228.18]],"batl":[[0,2.32,31.09],[1,2.4,8.24],[2,2.44,8.58]],"ltp":2.28,"tv":9159.41,"id":8444055},{"trd":[[1.76,1996.53],[1.78,534.81]],"batb":[[0,1.76,40.86],[1,1.72,34.59],[2,1.7,36.52]],"batl":[[0,1.85,1.59],[1,1.87,21.73],[2,1.91,22.5]],"ltp":1.76,"tv":23055.43,"id":8257852}],"tv":32214.84}]}
{"op":"mcm","clk":"1011658290","pt":1580657178872,"mc":[{"id":"1.168223927","rc":[{"batb":[[0,2.08,4.81],[1,2.06,228.18],[2,1.59,34.55]],"batl":[[0,2.4,8.24],[1,2.44,8.58],[2,2.76,1.68]],"ltp":2.28,"tv":9159.41,"id":8444055},{"batb":[[0,1.78,3.47]],"batl":[[1,1.91,22.5],[2,2.5,275.24]],"ltp":1.76,"tv":23055.43,"id":8257852}]}]}
{"op":"mcm","clk":"1011658513","pt":1580657179953,"mc":[{"id":"1.168223927","rc":[{"batl":[[0,2.26,1.68],[1,2.4,8.24],[2,2.44,8.58]],"ltp":2.28,"tv":9159.41,"id":8444055},{"batb":[[0,1.78,67.79]],"ltp":1.76,"tv":23055.43,"id":8257852}]}]}
{"op":"mcm","clk":"1011658695","pt":1580657180773,"mc":[{"id":"1.168223927","rc":[{"trd":[[2.26,2340.21]],"batl":[[0,2.4,8.47],[1,2.44,8.58],[2,2.76,1.68]],"ltp":2.26,"tv":9161.09,"id":8444055},{"trd":[[1.79,193.04]],"batb":[[0,1.78,65.93]],"batl":[[0,1.9,385.48],[2,1.92,443.78]],"ltp":1.79,"tv":23057.55,"id":8257852}],"tv":32218.64}]}
{"op":"mcm","clk":"1011659065","pt":1580657182269,"mc":[{"id":"1.168223927","rc":[{"batb":[[0,1.78,65.7],[1,1.74,461],[2,1.72,34.59]],"batl":[[0,1.8,461],[1,1.84,461],[2,1.9,385.48]],"ltp":1.79,"tv":23057.55,"id":8257852}]}]}
{"op":"mcm","clk":"1011659279","pt":1580657183262,"mc":[{"id":"1.168223927","rc":[{"batb":[[0,1.78,74.84]],"batl":[[0,1.91,22.5],[1,2.5,275.24],[2,2.7,3.15]],"ltp":1.79,"tv":23057.55,"id":8257852}]}]}
{"op":"mcm","clk":"1011659621","pt":1580657185000,"mc":[{"id":"1.168223927","rc":[{"batb":[[0,1.78,74.44]],"ltp":1.79,"tv":23057.55,"id":8257852}]}]}
{"op":"mcm","clk":"1011659752","pt":1580657185619,"mc":[{"id":"1.168223927","rc":[{"batb":[[0,1.78,74.26],[1,1.75,339.44],[2,1.74,461]],"batl":[[0,1.8,333.95],[1,1.82,525.15],[2,1.91,22.5]],"ltp":1.79,"tv":23057.55,"id":8257852}]}]}
{"op":"mcm","clk":"1011660089","pt":1580657187196,"mc":[{"id":"1.168223927","rc":[{"batb":[[0,1.78,64.9],[1,1.74,461],[2,1.72,34.59]],"batl":[[0,1.84,461],[1,1.91,22.5],[2,2.5,275.24]],"ltp":1.79,"tv":23057.55,"id":8257852}]}]}
{"op":"mcm","clk":"1011660226","pt":1580657187793,"mc":[{"id":"1.168223927","rc":[{"batl":[[1,1.89,461],[2,1.91,22.5]],"ltp":1.79,"tv":23057.55,"id":8257852}]}]}
{"op":"mcm","clk":"1011660440","pt":1580657188802,"mc":[{"id":"1.168223927","rc":[{"batb":[[0,2.14,5.32],[1,2.08,4.81],[2,2.06,228.18]],"ltp":2.26,"tv":9161.09,"id":8444055},{"batb":[[1,1.77,461],[2,1.74,461]],"batl":[[1,1.87,21.5],[2,1.89,461]],"ltp":1.79,"tv":23057.55,"id":8257852}]}]}
{"op":"mcm","clk":"1011661167","pt":1580657192095,"mc":[{"id":"1.168223927","rc":[{"batb":[[0,1.78,64.61]],"ltp":1.79,"tv":23057.55,"id":8257852}]}]}
{"op":"mcm","clk":"1011661770","pt":1580657194897,"mc":[{"id":"1.168223927","rc":[{"batb":[[0,1.78,64.1]],"ltp":1.79,"tv":23057.55,"id":8257852}]}]}
{"op":"mcm","clk":"1011662482","pt":1580657198177,"mc":[{"id":"1.168223927","rc":[{"batb":[[0,2.08,4.81],[1,2.06,228.18],[2,1.6,76.16]],"batl":[[0,2.44,8.81],[1,2.76,1.68],[2,1000,0.02]],"ltp":2.26,"tv":9161.09,"id":8444055},{"batb":[[1,1.7,36.52],[2,1.69,204.73]],"batl":[[0,1.9,385.48],[1,1.91,22.5],[2,1.92,443.78]],"ltp":1.79,"tv":23057.55,"id":8257852}]}]}
{"op":"mcm","clk":"1011662930","pt":1580657200195,"mc":[{"id":"1.168223927","rc":[{"trd":[[2.14,1.49]],"batb":[[2,2,42.01]],"batl":[[0,2.14,825.51],[1,2.16,792.39],[2,2.18,10.75]],"ltp":2.14,"tv":9162.58,"id":8444055},{"trd":[[1.87,1.71]],"batb":[[0,1.86,36.68],[1,1.84,393.82],[2,1.83,2459.02]],"batl":[[0,1.9,2753.9],[2,1.92,459.15]],"ltp":1.87,"tv":23059.25,"id":8257852}],"tv":32221.84}]}
{"op":"mcm","clk":"1011663146","pt":1580657201218,"mc":[{"id":"1.168223927","rc":[{"batb":[[2,1.84,163.34]],"batl":[[1,2.16,828.52]],"ltp":2.14,"tv":9162.58,"id":8444055},{"batb":[[0,1.88,142.97],[1,1.86,36.68],[2,1.85,48.73]],"ltp":1.87,"tv":23059.25,"id":8257852}]}]}
{"op":"mcm","clk":"1011663445","pt":1580657202791,"mc":[{"id":"1.168223927","rc":[{"batl":[[2,2.18,11.22]],"ltp":2.14,"tv":9162.58,"id":8444055}]}]}
{"op":"mcm","clk":"1011663631","pt":1580657203676,"mc":[{"id":"1.168223927","rc":[{"batb":[[2,1.96,43.69]],"ltp":2.14,"tv":9162.58,"id":8444055}]}]}
{"op":"mcm","clk":"1011663875","pt":1580657204858,"mc":[{"id":"1.168223927","rc":[{"batl":[[2,2.18,10.75]],"ltp":2.14,"tv":9162.58,"id":8444055}]}]}
{"op":"mcm","clk":"1011664141","pt":1580657206119,"mc":[{"id":"1.168223927","rc":[{"batb":[[1,1.87,461],[2,1.86,36.68]],"ltp":1.87,"tv":23059.25,"id":8257852}]}]}
{"op":"mcm","clk":"1011664775","pt":1580657209036,"mc":[{"id":"1.168223927","rc":[{"batb":[[0,1.88,654.97],[1,1.86,36.68],[2,1.85,48.73]],"ltp":1.87,"tv":23059.25,"id":8257852}]}]}
{"op":"mcm","clk":"1011664887","pt":1580657209557,"mc":[{"id":"1.168223927","rc":[{"batl":[[0,1.89,25],[1,1.9,2753.9],[2,1.91,22.5]],"ltp":1.87,"tv":23059.25,"id":8257852}]}]}
{"op":"mcm","clk":"1011665282","pt":1580657211269,"mc":[{"id":"1.168223927","rc":[{"trd":[[2.12,400.08]],"ltp":2.12,"tv":9163.05,"id":8444055},{"trd":[[1.89,707.36]],"batl":[[0,1.89,24.08]],"ltp":1.89,"tv":23060.58,"id":8257852}],"tv":32223.63}]}
{"op":"mcm","clk":"1011665499","pt":1580657212261,"mc":[{"id":"1.168223927","rc":[{"trd":[[1.88,22.89]],"batb":[[0,1.88,654.74],[2,1.85,509.73]],"ltp":1.88,"tv":23061.02,"id":8257852}],"tv":32224.07}]}
{"op":"mcm","clk":"1011665687","pt":1580657213070,"mc":[{"id":"1.168223927","rc":[{"batb":[[1,1.85,509.73],[2,1.84,344.25]],"ltp":1.88,"tv":23061.02,"id":8257852}]}]}
{"op":"mcm","clk":"1011665878","pt":1580657213926,"mc":[{"id":"1.168223927","rc":[{"trd":[[1.88,67.53]],"batb":[[0,1.88,632.42]],"ltp":1.88,"tv":23105.66,"id":8257852}],"tv":32268.71}]}
{"op":"mcm","clk":"1011666071","pt":1580657214840,"mc":[{"id":"1.168223927","rc":[{"trd":[[1.88,69.9]],"batb":[[0,1.88,631.24]],"ltp":1.88,"tv":23108.03,"id":8257852}],"tv":32271.08}]}
{"op":"mcm","clk":"1011666432","pt":1580657216253,"mc":[{"id":"1.168223927","rc":[{"batb":[[0,1.96,43.69],[1,1.84,162.87],[2,1.58,28.5]],"batl":[[0,2.16,36.13],[1,2.36,8.8],[2,2.44,8.58]],"ltp":2.12,"tv":9163.05,"id":8444055},{"batb":[[0,1.85,509.73],[1,1.79,461],[2,1.78,98.16]],"batl":[[0,1.94,461],[1,1.98,461],[2,2.02,461]],"ltp":1.88,"tv":23108.03,"id":8257852}]}]}
{"op":"mcm","clk":"1011666694","pt":1580657217271,"mc":[{"id":"1.168223927","rc":[{"trd":[[2.12,404.17]],"batb":[[0,1.84,162.87],[1,1.58,28.5],[2,1.51,33.99]],"batl":[[0,2.1,3.48]],"ltp":2.12,"tv":9167.14,"id":8444055},{"trd":[[1.88,74.51]],"batb":[[0,1.79,461],[1,1.78,98.16],[2,1.77,172.71]],"ltp":1.88,"tv":23112.64,"id":8257852}],"tv":32279.78}]}
{"op":"mcm","clk":"1011666851","pt":1580657217958,"mc":[{"id":"1.168223927","rc":[{"batb":[[0,1.9,512],[1,1.79,461],[2,1.78,98.16]],"ltp":1.88,"tv":23112.64,"id":8257852}]}]}
{"op":"mcm","clk":"1011667081","pt":1580657219089,"mc":[{"id":"1.168223927","rc":[{"batb":[[1,1.59,32.55],[2,1.58,28.06]],"batl":[[1,2.3,9.08],[2,2.36,8.57]],"ltp":2.12,"tv":9167.14,"id":8444055},{"batb":[[1,1.86,461],[2,1.79,461]],"ltp":1.88,"tv":23112.64,"id":8257852}]}]}
{"op":"mcm","clk":"1011667159","pt":1580657219832,"mc":[{"id":"1.168223927","rc":[{"batb":[[1,1.58,28.5],[2,1.51,33.99]],"batl":[[1,2.36,8.8],[2,2.44,8.58]],"ltp":2.12,"tv":9167.14,"id":8444055},{"trd":[[1.9,52.54]],"batb":[[0,1.9,487.92]],"batl":[[0,1.98,461],[1,2.02,461],[2,2.16,577.68]],"ltp":1.9,"tv":23160.8,"id":8257852}],"tv":32327.94}]}
{"op":"mcm","clk":"1011667624","pt":1580657221434,"mc":[{"id":"1.168223927","rc":[{"trd":[[1.9,57.64]],"batb":[[0,1.9,485.37]],"ltp":1.9,"tv":23165.89,"id":8257852}],"tv":32333.04}]}
{"op":"mcm","clk":"1011667981","pt":1580657222961,"mc":[{"id":"1.168223927","rc":[{"batb":[[0,1.9,485.99]],"ltp":1.9,"tv":23165.89,"id":8257852}]}]}
{"op":"mcm","clk":"1011668133","pt":1580657223646,"mc":[{"id":"1.168223927","rc":[{"trd":[[1.9,58.66]],"batb":[[0,1.86,461.62],[1,1.79,461],[2,1.78,98.16]],"ltp":1.9,"tv":23166.92,"id":8257852}],"tv":32334.06}]}
{"op":"mcm","clk":"1011668688","pt":1580657226127,"mc":[{"id":"1.168223927","rc":[{"batb":[[1,1.59,30.55],[2,1.58,28.06]],"batl":[[1,2.3,9.08],[2,2.36,8.57]],"ltp":2.12,"tv":9167.14,"id":8444055},{"batb":[[0,1.86,461.83]],"batl":[[0,2.02,461],[1,2.16,577.68],[2,2.18,305.39]],"ltp":1.9,"tv":23166.92,"id":8257852}]}]}
{"op":"mcm","clk":"1011668964","pt":1580657227162,"mc":[{"id":"1.168223927","rc":[{"batb":[[1,1.58,28.5],[2,1.51,33.99]],"batl":[[1,2.36,8.8],[2,2.44,8.58]],"ltp":2.12,"tv":9167.14,"id":8444055},{"batb":[[0,1.86,461.46]],"ltp":1.9,"tv":23166.92,"id":8257852}]}]}
{"op":"mcm","clk":"1011669351","pt":1580657229036,"mc":[{"id":"1.168223927","rc":[{"batb":[[0,1.86,461]],"ltp":1.9,"tv":23166.92,"id":8257852}]}]}
{"op":"mcm","clk":"1011670296","pt":1580657233181,"mc":[{"id":"1.168223927","rc":[{"batl":[[1,2.14,461],[2,2.16,577.68]],"ltp":1.9,"tv":23166.92,"id":8257852}]}]}
{"op":"mcm","clk":"1011671852","pt":1580657240148,"mc":[{"id":"1.168223927","rc":[{"batb":[[1,1.59,30.55],[2,1.58,28.06]],"batl":[[1,2.3,9.08],[2,2.36,8.57]],"ltp":2.12,"tv":9167.14,"id":8444055},{"batb":[[0,1.78,98.16],[1,1.77,172.71],[2,1.74,414.27]],"batl":[[2,2.5,275.24]],"ltp":1.9,"tv":23166.92,"id":8257852}]}]}
{"op":"mcm","clk":"1011672065","pt":1580657241253,"mc":[{"id":"1.168223927","rc":[{"batb":[[1,1.58,28.5],[2,1.51,33.99]],"batl":[[1,2.36,8.8],[2,2.44,8.58]],"ltp":2.12,"tv":9167.14,"id":8444055},{"batb":[[0,1.78,64]],"ltp":1.9,"tv":23166.92,"id":8257852}]}]}
{"op":"mcm","clk":"1011672456","pt":1580657243120,"mc":[{"id":"1.168223927","rc":[{"trd":[[2.1,3.48]],"batl":[[0,2.32,1031.23],[1,2.36,8.57]],"ltp":2.1,"tv":9170.62,"id":8444055},{"trd":[[1.9,62.51]],"batb":[[2,1.76,882.22]],"batl":[[0,1.8,3100.09],[1,1.82,524.47],[2,1.83,933.46]],"ltp":1.9,"tv":23170.77,"id":8257852}],"tv":32341.39}]}
{"op":"mcm","clk":"1011672680","pt":1580657244179,"mc":[{"id":"1.168223927","rc":[{"batb":[[0,2.22,186.55],[1,2.06,39.49],[2,2.04,239.27]],"batl":[[0,2.28,33],[1,2.32,1031],[2,2.36,8.57]],"ltp":2.1,"tv":9170.62,"id":8444055},{"batb":[[0,1.78,117.77]],"batl":[[2,1.83,1394.46]],"ltp":1.9,"tv":23170.77,"id":8257852}]}]}
{"op":"mcm","clk":"1011672739","pt":1580657244486,"mc":[{"id":"1.168223927","rc":[{"batl":[[2,1.83,461]],"ltp":1.9,"tv":23170.77,"id":8257852}]}]}
{"op":"mcm","clk":"1011673080","pt":1580657246192,"mc":[{"id":"1.168223927","rc":[{"trd":[[1.8,993.9]],"batl":[[0,1.8,3097.09]],"ltp":1.8,"tv":23176.77,"id":8257852}],"tv":32347.39}]}
{"op":"mcm","clk":"1011673362","pt":1580657247264,"mc":[{"id":"1.168223927","rc":[{"batb":[[1,1.77,684.71]],"ltp":1.8,"tv":23176.77,"id":8257852}]}]}
{"op":"mcm","clk":"1011673570","pt":1580657248197,"mc":[{"id":"1.168223927","rc":[{"batb":[[1,1.77,1145.71]],"ltp":1.8,"tv":23176.77,"id":8257852}]}]}
{"op":"mcm","clk":"1011673869","pt":1580657249673,"mc":[{"id":"1.168223927","rc":[{"batb":[[1,2.12,5.29],[2,2.08,5.31]],"ltp":2.1,"tv":9170.62,"id":8444055}]}]}
{"op":"mcm","clk":"1011674461","pt":1580657252488,"mc":[{"id":"1.168223927","rc":[{"trd":[[1.8,995.02]],"batl":[[0,1.8,3096.53]],"ltp":1.8,"tv":23177.88,"id":8257852}],"tv":32348.51}]}
{"op":"mcm","clk":"1011674972","pt":1580657254804,"mc":[{"id":"1.168223927","rc":[{"trd":[[1.8,1045.02]],"batl":[[0,1.8,3071.53]],"ltp":1.8,"tv":23227.88,"id":8257852}],"tv":32398.51}]}
{"op":"mcm","clk":"1011675262","pt":1580657256007,"mc":[{"id":"1.168223927","rc":[{"trd":[[1.8,1053.68]],"batb":[[0,1.78,117.78]],"batl":[[0,1.8,3067.2]],"ltp":1.8,"tv":23236.55,"id":8257852}],"tv":32407.17}]}
{"op":"mcm","clk":"1011675511","pt":1580657256891,"mc":[{"id":"1.168223927","rc":[{"trd":[[1.8,1074.18]],"batl":[[0,1.8,3056.95]],"ltp":1.8,"tv":23257.05,"id":8257852}],"tv":32427.67}]}
{"op":"mcm","clk":"1011675808","pt":1580657258225,"mc":[{"id":"1.168223927","rc":[{"trd":[[1.8,1115.19]],"batl":[[0,1.8,3036.45]],"ltp":1.8,"tv":23298.05,"id":8257852}],"tv":32468.68}]}
{"op":"mcm","clk":"1011676030","pt":1580657259211,"mc":[{"id":"1.168223927","rc":[{"trd":[[1.8,1121.56]],"batl":[[0,1.8,3033.26]],"ltp":1.8,"tv":23304.42,"id":8257852}],"tv":32475.05}]}
{"op":"mcm","clk":"1011676197","pt":1580657260111,"mc":[{"id":"1.168223927","rc":[{"trd":[[2.24,320.74]],"ltp":2.24,"tv":9171.02,"id":8444055},{"trd":[[1.78,536.11],[1.8,1122.06]],"batb":[[0,1.78,117.12]],"batl":[[0,1.8,3032.76]],"ltp":1.78,"tv":23306.22,"id":8257852}],"tv":32477.25}]}
{"op":"mcm","clk":"1011676307","pt":1580657260619,"mc":[{"id":"1.168223927","rc":[{"trd":[[1.78,567.14],[1.8,1122.5]],"batb":[[0,1.78,53.77],[1,1.77,633.71]],"batl":[[0,1.8,3032.54]],"ltp":1.8,"tv":23337.69,"id":8257852}],"tv":32508.71}]}
{"op":"mcm","clk":"1011676610","pt":1580657262121,"mc":[{"id":"1.168223927","rc":[{"trd":[[2.24,320.96]],"ltp":2.24,"tv":9171.24,"id":8444055},{"trd":[[1.8,1125.81]],"batl":[[0,1.8,3030.75]],"ltp":1.8,"tv":23340.99,"id":8257852}],"tv":32512.24}]}
{"op":"mcm","clk":"1011676766","pt":1580657262918,"mc":[{"id":"1.168223927","rc":[{"trd":[[1.78,568.14],[1.8,2149.81]],"batb":[[0,1.78,53.27]],"batl":[[0,1.8,2518.75]],"ltp":1.78,"tv":24366.0,"id":8257852}],"tv":33537.25}]}
{"op":"mcm","clk":"1011677004","pt":1580657263941,"mc":[{"id":"1.168223927","rc":[{"trd":[[1.8,2153.12]],"batl":[[0,1.8,2517.09]],"ltp":1.8,"tv":24369.31,"id":8257852}],"tv":33540.56}]}
{"op":"mcm","clk":"1011677205","pt":1580657264824,"mc":[{"id":"1.168223927","rc":[{"trd":[[2.24,321.4]],"batl":[[1,2.36,8.57],[2,2.4,8.59]],"ltp":2.24,"tv":9171.68,"id":8444055},{"trd":[[1.8,2153.67]],"batl":[[0,1.8,2516.54]],"ltp":1.8,"tv":24369.86,"id":8257852}],"tv":33541.55}]}
{"op":"mcm","clk":"1011677507","pt":1580657266132,"mc":[{"id":"1.168223927","rc":[{"trd":[[1.8,2629.63]],"batl":[[0,1.8,2278.56]],"ltp":1.8,"tv":24845.82,"id":8257852}],"tv":34017.51}]}
{"op":"mcm","clk":"1011677578","pt":1580657266512,"mc":[{"id":"1.168223927","rc":[{"trd":[[2.24,322.01]],"ltp":2.24,"tv":9172.29,"id":8444055},{"trd":[[1.8,2630.39]],"batl":[[0,1.8,2277.8]],"ltp":1.8,"tv":24846.58,"id":8257852}],"tv":34018.88}]}
{"op":"mcm","clk":"1011677924","pt":1580657268038,"mc":[{"id":"1.168223927","rc":[{"trd":[[1.8,2631.71]],"batl":[[0,1.8,2277.14]],"ltp":1.8,"tv":24847.9,"id":8257852}],"tv":34020.2}]}
{"op":"mcm","clk":"1011678055","pt":1580657268639,"mc":[{"id":"1.168223927","rc":[{"trd":[[1.8,2632.73]],"batl":[[0,1.8,2276.63]],"ltp":1.8,"tv":24848.92,"id":8257852}],"tv":34021.22}]}
{"op":"mcm","clk":"1011678530","pt":1580657270927,"mc":[{"id":"1.168223927","rc":[{"batl":[[0,2.36,8.8],[1,2.4,8.59],[2,2.44,8.58]],"ltp":2.24,"tv":9172.29,"id":8444055},{"trd":[[1.78,655.91],[1.8,2637.95]],"batb":[[0,1.77,633.71],[1,1.76,882.22],[2,1.74,3461.48]],"batl":[[0,1.8,2274.02]],"ltp":1.8,"tv":24941.91,"id":8257852}],"tv":34114.21}]}
{"op":"mcm","clk":"1011678786","pt":1580657272124,"mc":[{"id":"1.168223927","rc":[{"batb":[[1,1.74,3081.73],[2,1.72,36.09]],"batl":[[0,1.8,1673.93],[1,1.83,461],[2,1.89,478.5]],"ltp":1.8,"tv":24941.91,"id":8257852}]}]}
{"op":"mcm","clk":"1011678978","pt":1580657272944,"mc":[{"id":"1.168223927","rc":[{"batb":[[0,2.12,5.29],[1,2.08,5.31],[2,2.04,236.91]],"ltp":2.24,"tv":9172.29,"id":8444055},{"batb":[[0,1.77,461],[1,1.74,495.52]],"batl":[[0,1.83,461],[1,1.89,478.5],[2,1.92,18.56]],"ltp":1.8,"tv":24941.91,"id":8257852}]}]}
{"op":"mcm","clk":"1011679263","pt":1580657274135,"mc":[{"id":"1.168223927","rc":[{"batb":[[0,1.8,1.12],[1,1.77,461],[2,1.74,495.52]],"ltp":1.8,"tv":24941.91,"id":8257852}]}]}
{"op":"mcm","clk":"1011679492","pt":1580657275130,"mc":[{"id":"1.168223927","rc":[{"batb":[[2,2.06,5.08]],"ltp":2.24,"tv":9172.29,"id":8444055},{"batl":[[2,1.92,474]],"ltp":1.8,"tv":24941.91,"id":8257852}]}]}
{"op":"mcm","clk":"1011679737","pt":1580657276226,"mc":[{"id":"1.168223927","rc":[{"batl":[[0,1.89,478.5],[1,1.92,18.56],[2,1.93,17.5]],"ltp":1.8,"tv":24941.91,"id":8257852}]}]}
{"op":"mcm","clk":"1011679983","pt":1580657277152,"mc":[{"id":"1.168223927","rc":[{"batb":[[0,2.08,5.31],[1,2.06,5.08],[2,2.04,236.91]],"ltp":2.24,"tv":9172.29,"id":8444055},{"batl":[[0,1.92,18.56],[1,1.93,17.5],[2,2.5,275.24]],"ltp":1.8,"tv":24941.91,"id":8257852}]}]}
{"op":"mcm","clk":"1011680411","pt":1580657279077,"mc":[{"id":"1.168223927","rc":[{"batb":[[2,1.76,437.69]],"batl":[[0,1.82,477.64],[1,1.84,506.75],[2,1.92,18.56]],"ltp":1.8,"tv":24941.91,"id":8257852}]}]}
{"op":"mcm","clk":"1011680674","pt":1580657280222,"mc":[{"id":"1.168223927","rc":[{"batl":[[2,1.85,461]],"ltp":1.8,"tv":24941.91,"id":8257852}]}]}
{"op":"mcm","clk":"1011680937","pt":1580657281272,"mc":[{"id":"1.168223927","rc":[{"batb":[[0,2.12,5.29],[1,2.08,5.31],[2,2.06,5.08]],"ltp":2.24,"tv":9172.29,"id":8444055},{"batb":[[2,1.74,495.52]],"batl":[[0,1.85,461],[1,1.88,461],[2,1.89,19.5]],"ltp":1.8,"tv":24941.91,"id":8257852}]}]}
{"op":"mcm","clk":"1011681317","pt":1580657283105,"mc":[{"id":"1.168223927","rc":[{"batb":[[1,1.79,461],[2,1.77,461]],"ltp":1.8,"tv":24941.91,"id":8257852}]}]}
{"op":"mcm","clk":"1011682540","pt":1580657289102,"mc":[{"id":"1.168223927","rc":[{"batb":[[0,1.79,461],[1,1.77,461],[2,1.74,495.52]],"ltp":1.8,"tv":24941.91,"id":8257852}]}]}
{"op":"mcm","clk":"1011684673","pt":1580657298712,"mc":[{"id":"1.168223927","rc":[{"trd":[[2.16,7.37]],"ltp":2.16,"tv":9177.5,"id":8444055},{"trd":[[1.85,11.69]],"batl":[[0,1.85,454.91]],"ltp":1.85,"tv":24948.0,"id":8257852}],"tv":34125.51}]}
{"op":"mcm","clk":"1011685158","pt":1580657300926,"mc":[{"id":"1.168223927","rc":[{"batl":[[2,2.76,1.68]],"ltp":2.16,"tv":9177.5,"id":8444055},{"batb":[[0,1.74,34.52],[1,1.72,42.12],[2,1.71,194.11]],"ltp":1.85,"tv":24948.0,"id":8257852}]}]}
{"op":"mcm","clk":"1011685652","pt":1580657303227,"mc":[{"id":"1.168223927","rc":[{"trd":[[2.28,157.18]],"batb":[[0,2.36,11.86],[1,2.24,410.82],[2,2.12,5.29]],"batl":[[0,2.4,416.12],[1,2.44,951],[2,2.46,13.03]],"ltp":2.28,"tv":9177.74,"id":8444055},{"trd":[[1.78,656.21]],"batb":[[0,1.72,42.12],[1,1.71,194.11],[2,1.68,2678.57]],"batl":[[0,1.74,2586.21],[1,1.76,2256.93],[2,1.8,1250]],"ltp":1.78,"tv":24948.3,"id":8257852}],"tv":34126.04}]}
{"op":"mcm","clk":"1011685882","pt":1580657304221,"mc":[{"id":"1.168223927","rc":[{"batb":[[1,2.32,163.11],[2,2.24,410.82]],"batl":[[1,2.42,29.41],[2,2.44,951]],"ltp":2.28,"tv":9177.74,"id":8444055},{"batb":[[2,1.7,59.65]],"batl":[[0,1.74,3085.86],[1,1.75,933.46],[2,1.76,585.17]],"ltp":1.78,"tv":24948.3,"id":8257852}]}]}
{"op":"mcm","clk":"1011686776","pt":1580657308046,"mc":[{"id":"1.168223927","rc":[{"trd":[[1.74,3450.1]],"batl":[[0,1.74,3058.34]],"ltp":1.74,"tv":25003.34,"id":8257852}],"tv":34181.08}]}
{"op":"mcm","clk":"1011686946","pt":1580657308764,"mc":[{"id":"1.168223927","rc":[{"batb":[[0,1.73,6.12],[1,1.72,42.12],[2,1.71,194.11]],"ltp":1.74,"tv":25003.34,"id":8257852}]}]}
{"op":"mcm","clk":"1011687666","pt":1580657312219,"mc":[{"id":"1.168223927","rc":[{"trd":[[1.74,4450.1]],"batl":[[0,1.74,2558.34]],"ltp":1.74,"tv":26003.34,"id":8257852}],"tv":35181.08}]}
{"op":"mcm","clk":"1011687734","pt":1580657312538,"mc":[{"id":"1.168223927","rc":[{"trd":[[2.38,41.73]],"batb":[[0,2.38,4.8],[1,2.36,11.86],[2,2.32,163.11]],"ltp":2.38,"tv":9182.18,"id":8444055},{"trd":[[1.73,583.58]],"batb":[[0,1.72,42.12],[1,1.71,194.11],[2,1.7,59.65]],"ltp":1.73,"tv":26009.46,"id":8257852}],"tv":35191.65}]}
{"op":"mcm","clk":"1011688126","pt":1580657314128,"mc":[{"id":"1.168223927","rc":[{"trd":[[2.38,44.56]],"batb":[[0,2.38,1.97]],"ltp":2.38,"tv":9185.01,"id":8444055},{"trd":[[1.73,587.47]],"ltp":1.73,"tv":26013.35,"id":8257852}],"tv":35198.37}]}
{"op":"mcm","clk":"1011688254","pt":1580657314774,"mc":[{"id":"1.168223927","rc":[{"trd":[[2.38,45.49]],"batb":[[0,2.38,1.34]],"ltp":2.38,"tv":9185.94,"id":8444055},{"trd":[[1.73,587.91]],"ltp":1.73,"tv":26013.79,"id":8257852}],"tv":35199.74}]}
{"op":"mcm","clk":"1011688550","pt":1580657316136,"mc":[{"id":"1.168223927","rc":[{"trd":[[2.36,44.76],[2.38,46.83]],"batb":[[0,2.36,11.54],[1,2.32,163.11],[2,2.24,410.82]],"ltp":2.36,"tv":9187.93,"id":8444055},{"trd":[[1.73,589.76],[1.74,4750.24]],"batl":[[0,1.74,2408.27]],"ltp":1.74,"tv":26315.78,"id":8257852}],"tv":35503.71}]}
{"op":"mcm","clk":"1011688760","pt":1580657317138,"mc":[{"id":"1.168223927","rc":[{"trd":[[1.74,4764.22]],"batl":[[0,1.74,2401.28]],"ltp":1.74,"tv":26329.76,"id":8257852}],"tv":35517.69}]}
{"op":"mcm","clk":"1011688944","pt":1580657318067,"mc":[{"id":"1.168223927","rc":[{"trd":[[2.36,48.92]],"batb":[[0,2.36,9.46]],"ltp":2.36,"tv":9192.08,"id":8444055},{"trd":[[1.74,4783.98]],"batl":[[0,1.74,2391.4]],"ltp":1.74,"tv":26349.52,"id":8257852}],"tv":35541.6}]}
{"op":"mcm","clk":"1011689209","pt":1580657319236,"mc":[{"id":"1.168223927","rc":[{"trd":[[2.36,49.44]],"batb":[[0,2.36,9.2]],"ltp":2.36,"tv":9192.61,"id":8444055},{"trd":[[1.72,220.48],[1.74,4836.65]],"batb":[[0,1.72,13.38]],"batl":[[0,1.74,2365.06]],"ltp":1.74,"tv":26459.66,"id":8257852}],"tv":35652.27}]}
{"op":"mcm","clk":"1011689246","pt":1580657319442,"mc":[{"id":"1.168223927","rc":[{"trd":[[1.74,4840.87]],"batl":[[0,1.74,2362.95]],"ltp":1.74,"tv":26463.88,"id":8257852}],"tv":35656.49}]}
{"op":"mcm","clk":"1011689477","pt":1580657320543,"mc":[{"id":"1.168223927","rc":[{"trd":[[2.36,50.18]],"batb":[[0,2.36,8.83]],"ltp":2.36,"tv":9193.35,"id":8444055},{"batl":[[1,1.76,585.17],[2,1.8,1250]],"ltp":1.74,"tv":26463.88,"id":8257852}],"tv":35657.24}]}
{"op":"mcm","clk":"1011690007","pt":1580657322943,"mc":[{"id":"1.168223927","rc":[{"trd":[[2.36,51.37]],"batb":[[0,2.36,8.24]],"ltp":2.36,"tv":9194.53,"id":8444055},{"trd":[[1.74,4844.67]],"batb":[[0,1.72,13.93]],"batl":[[0,1.74,2361.05]],"ltp":1.74,"tv":26467.68,"id":8257852}],"tv":35662.22}]}
{"op":"mcm","clk":"1011690339","pt":1580657324246,"mc":[{"id":"1.168223927","rc":[{"trd":[[1.74,5010.21]],"batb":[[0,1.73,22.32],[1,1.72,14.49],[2,1.71,194.11]],"batl":[[0,1.74,2278.28]],"ltp":1.74,"tv":26633.23,"id":8257852}],"tv":35827.76}]}
{"op":"mcm","clk":"1011690556","pt":1580657325122,"mc":[{"id":"1.168223927","rc":[{"trd":[[2.36,52.25]],"batb":[[0,2.36,7.8]],"ltp":2.36,"tv":9195.41,"id":8444055}],"tv":35828.64}]}
{"op":"mcm","clk":"1011690768","pt":1580657326065,"mc":[{"id":"1.168223927","rc":[{"trd":[[2.38,77.12]],"batb":[[0,2.32,163.11],[1,2.24,410.82],[2,2.22,184.9]],"ltp":2.38,"tv":9225.7,"id":8444055},{"trd":[[1.72,297.62],[1.73,634.39]],"batb":[[0,1.71,194.11],[1,1.7,59.65],[2,1.68,3338.45]],"batl":[[0,1.72,718.14],[1,1.74,2278.28],[2,1.76,585.17]],"ltp":1.72,"tv":26755.01,"id":8257852}],"tv":35980.72}]}
{"op":"mcm","clk":"1011690816","pt":1580657326332,"mc":[{"id":"1.168223927","rc":[{"trd":[[1.72,299.64]],"batl":[[0,1.72,717.13]],"ltp":1.72,"tv":26757.03,"id":8257852}],"tv":35982.74}]}
{"op":"mcm","clk":"1011691191","pt":1580657328128,"mc":[{"id":"1.168223927","rc":[{"trd":[[1.71,19.68],[1.72,301.2]],"batb":[[0,1.71,192.59]],"batl":[[0,1.72,716.35]],"ltp":1.72,"tv":26761.63,"id":8257852}],"tv":35987.33}]}
{"op":"mcm","clk":"1011691416","pt":1580657329177,"mc":[{"id":"1.168223927","rc":[{"trd":[[2.38,177.45]],"ltp":2.38,"tv":9326.03,"id":8444055},{"trd":[[1.72,441.89]],"batl":[[0,1.72,576.59]],"ltp":1.72,"tv":26902.32,"id":8257852}],"tv":36228.36}]}
{"op":"mcm","clk":"1011691568","pt":1580657329885,"mc":[{"id":"1.168223927","rc":[{"trd":[[1.72,448.44]],"batl":[[0,1.72,574.15]],"ltp":1.72,"tv":26908.86,"id":8257852}],"tv":36234.9}]}
{"op":"mcm","clk":"1011691906","pt":1580657331249,"mc":[{"id":"1.168223927","rc":[{"trd":[[2.38,207.74]],"ltp":2.38,"tv":9356.32,"id":8444055},{"trd":[[1.72,504.66]],"batl":[[0,1.72,525.08]],"ltp":1.72,"tv":26965.09,"id":8257852}],"tv":36321.42}]}
{"op":"mcm","clk":"1011692086","pt":1580657332066,"mc":[{"id":"1.168223927","rc":[{"batb":[[0,2.36,7.8],[1,2.32,163.11],[2,2.24,410.82]],"batl":[[1,2.42,36.87]],"ltp":2.38,"tv":9356.32,"id":8444055},{"trd":[[1.72,504.98]],"batl":[[0,1.72,524.92]],"ltp":1.72,"tv":26965.4,"id":8257852}],"tv":36321.73}]}
{"op":"mcm","clk":"1011692247","pt":1580657332797,"mc":[{"id":"1.168223927","rc":[{"batb":[[0,2.32,163.11],[1,2.24,410.82],[2,2.22,184.9]],"batl":[[1,2.42,29.41]],"ltp":2.38,"tv":9356.32,"id":8444055},{"trd":[[1.72,508.4]],"batl":[[0,1.72,523.21]],"ltp":1.72,"tv":26968.83,"id":8257852}],"tv":36325.15}]}
{"op":"mcm","clk":"1011692403","pt":1580657333440,"mc":[{"id":"1.168223927","rc":[{"trd":[[1.72,509.2]],"batl":[[0,1.72,522.81]],"ltp":1.72,"tv":26969.63,"id":8257852}],"tv":36325.95}]}
{"op":"mcm","clk":"1011692814","pt":1580657335162,"mc":[{"id":"1.168223927","rc":[{"batb":[[0,2.36,7.8],[1,2.32,163.11],[2,2.24,410.82]],"batl":[[1,2.42,36.87]],"ltp":2.38,"tv":9356.32,"id":8444055},{"trd":[[1.72,516.37]],"batl":[[0,1.72,519.22]],"ltp":1.72,"tv":26976.8,"id":8257852}],"tv":36333.13}]}
{"op":"mcm","clk":"1011692935","pt":1580657335707,"mc":[{"id":"1.168223927","rc":[{"batb":[[0,2.32,163.11],[1,2.24,410.82],[2,2.22,184.9]],"batl":[[1,2.42,29.41]],"ltp":2.38,"tv":9356.32,"id":8444055},{"trd":[[1.72,520.76]],"batl":[[0,1.72,517.03]],"ltp":1.72,"tv":26981.18,"id":8257852}],"tv":36337.51}]}
{"op":"mcm","clk":"1011693209","pt":1580657336993,"mc":[{"id":"1.168223927","rc":[{"trd":[[2.38,207.99]],"ltp":2.38,"tv":9356.57,"id":8444055},{"trd":[[1.71,59.68],[1.72,521.1]],"batb":[[0,1.71,172.59]],"batl":[[0,1.72,516.69]],"ltp":1.72,"tv":27021.52,"id":8257852}],"tv":36378.1}]}
{"op":"mcm","clk":"1011693483","pt":1580657338258,"mc":[{"id":"1.168223927","rc":[{"batb":[[0,2.36,7.8],[1,2.32,162.71],[2,2.24,410.82]],"batl":[[1,2.42,36.87]],"ltp":2.38,"tv":9356.57,"id":8444055}]}]}
{"op":"mcm","clk":"1011693529","pt":1580657338475,"mc":[{"id":"1.168223927","rc":[{"batb":[[0,2.32,162.71],[1,2.24,410.82],[2,2.22,184.43]],"batl":[[1,2.42,29.41]],"ltp":2.38,"tv":9356.57,"id":8444055}]}]}
{"op":"mcm","clk":"1011693811","pt":1580657339674,"mc":[{"id":"1.168223927","rc":[{"trd":[[2.4,29.52]],"batl":[[0,2.4,396.58]],"ltp":2.4,"tv":9376.11,"id":8444055},{"trd":[[1.71,432.27]],"batb":[[0,1.7,59.65],[1,1.68,3338.45],[2,1.67,348.58]],"ltp":1.71,"tv":27394.11,"id":8257852}],"tv":36770.23}]}
{"op":"mcm","clk":"1011694100","pt":1580657340795,"mc":[{"id":"1.168223927","rc":[{"trd":[[1.72,529.87]],"batl":[[0,1.72,512.3]],"ltp":1.72,"tv":27402.89,"id":8257852}],"tv":36779.01}]}
{"op":"mcm","clk":"1011694402","pt":1580657341969,"mc":[{"id":"1.168223927","rc":[{"trd":[[1.72,530.45]],"batl":[[0,1.72,512.01]],"ltp":1.72,"tv":27403.47,"id":8257852}],"tv":36779.59}]}
{"op":"mcm","clk":"1011694687","pt":1580657343209,"mc":[{"id":"1.168223927","rc":[{"trd":[[2.38,210.03]],"ltp":2.38,"tv":9378.15,"id":8444055},{"trd":[[1.72,534.81]],"batl":[[0,1.74,2279.11],[1,1.76,585.17],[2,1.8,1250]],"ltp":1.72,"tv":27407.83,"id":8257852}],"tv":36785.98}]}
{"op":"mcm","clk":"1011695110","pt":1580657345088,"mc":[{"id":"1.168223927","rc":[{"batb":[[0,1.72,3.19],[1,1.7,59.65],[2,1.68,3338.45]],"batl":[[0,1.74,2278.28]],"ltp":1.72,"tv":27407.83,"id":8257852}]}]}
{"op":"mcm","clk":"1011695302","pt":1580657345985,"mc":[{"id":"1.168223927","rc":[{"batl":[[0,2.4,397.46]],"ltp":2.38,"tv":9378.15,"id":8444055},{"batb":[[0,1.72,3.95]],"ltp":1.72,"tv":27407.83,"id":8257852}]}]}
{"op":"mcm","clk":"1011695533","pt":1580657347018,"mc":[{"id":"1.168223927","rc":[{"batb":[[0,1.72,4.88]],"ltp":1.72,"tv":27407.83,"id":8257852}]}]}
{"op":"mcm","clk":"1011695745","pt":1580657347986,"mc":[{"id":"1.168223927","rc":[{"batb":[[0,1.72,15.29]],"ltp":1.72,"tv":27407.83,"id":8257852}]}]}
{"op":"mcm","clk":"1011695892","pt":1580657348703,"mc":[{"id":"1.168223927","rc":[{"batb":[[0,2.34,159.72],[1,2.24,591.87],[2,2.2,34.45]],"ltp":2.38,"tv":9378.15,"id":8444055},{"batb":[[0,1.72,15.51],[1,1.7,259.35]],"ltp":1.72,"tv":27407.83,"id":8257852}]}]}
{"op":"mcm","clk":"1011696227","pt":1580657350222,"mc":[{"id":"1.168223927","rc":[{"batl":[[0,2.38,2.33],[1,2.4,396.58],[2,2.42,29.41]],"ltp":2.38,"tv":9378.15,"id":8444055}]}]}
{"op":"mcm","clk":"1011696422","pt":1580657351096,"mc":[{"id":"1.168223927","rc":[{"batb":[[0,2.36,7.8],[1,2.34,159.72],[2,2.24,591.87]],"batl":[[2,2.42,36.87]],"ltp":2.38,"tv":9378.15,"id":8444055},{"trd":[[1.74,5011.8]],"batb":[[0,1.72,21.56]],"batl":[[0,1.74,2277.49]],"ltp":1.74,"tv":27409.41,"id":8257852}],"tv":36787.57}]}
{"op":"mcm","clk":"1011697472","pt":1580657355791,"mc":[{"id":"1.168223927","rc":[{"trd":[[2.36,54.48],[2.38,212.36]],"batb":[[0,2.36,6.68]],"batl":[[0,2.4,396.58],[1,2.42,36.87],[2,2.44,951]],"ltp":2.38,"tv":9382.71,"id":8444055},{"trd":[[1.72,569.67]],"batb":[[0,1.7,259.35],[1,1.68,3338.45],[2,1.67,348.58]],"batl":[[0,1.72,80.96],[1,1.74,2277.49],[2,1.76,585.17]],"ltp":1.72,"tv":27444.27,"id":8257852}],"tv":36826.99}]}
{"op":"mcm","clk":"1011697598","pt":1580657356297,"mc":[{"id":"1.168223927","rc":[{"trd":[[1.72,571.21]],"batl":[[0,1.72,80.19]],"ltp":1.72,"tv":27445.81,"id":8257852}],"tv":36828.53}]}
{"op":"mcm","clk":"1011698264","pt":1580657359178,"mc":[{"id":"1.168223927","rc":[{"trd":[[2.38,214.36]],"ltp":2.38,"tv":9384.72,"id":8444055},{"trd":[[1.72,574.42]],"batl":[[0,1.72,77.2]],"ltp":1.72,"tv":27449.02,"id":8257852}],"tv":36833.74}]}
{"op":"mcm","clk":"1011698701","pt":1580657361208,"mc":[{"id":"1.168223927","rc":[{"batl":[[0,1.72,77.98]],"ltp":1.72,"tv":27449.02,"id":8257852}]}]}
{"op":"mcm","clk":"1011699179","pt":1580657363346,"mc":[{"id":"1.168223927","rc":[{"trd":[[1.72,575.32]],"batl":[[0,1.72,77.53]],"ltp":1.72,"tv":27449.92,"id":8257852}],"tv":36834.64}]}
{"op":"mcm","clk":"1011699706","pt":1580657365722,"mc":[{"id":"1.168223927","rc":[{"batb":[[0,2.34,159.72],[1,2.24,591.87],[2,2.2,34.45]],"batl":[[1,2.42,29.41]],"ltp":2.38,"tv":9384.72,"id":8444055},{"batl":[[0,1.72,76.75]],"ltp":1.72,"tv":27449.92,"id":8257852}]}]}
{"op":"mcm","clk":"1011700195","pt":1580657368048,"mc":[{"id":"1.168223927","rc":[{"trd":[[2.38,218.15]],"ltp":2.38,"tv":9388.5,"id":8444055},{"trd":[[1.72,581]],"batl":[[0,1.72,71.29]],"ltp":1.72,"tv":27455.6,"id":8257852}],"tv":36844.11}]}
{"op":"mcm","clk":"1011700331","pt":1580657368644,"mc":[{"id":"1.168223927","rc":[{"trd":[[2.36,67.84],[2.38,269.67]],"batl":[[0,2.36,320.41],[1,2.4,396.58],[2,2.42,37.96]],"ltp":2.36,"tv":9453.38,"id":8444055},{"trd":[[1.72,652.29]],"batl":[[0,1.74,2277.49],[1,1.76,585.17],[2,1.8,1250]],"ltp":1.72,"tv":27526.89,"id":8257852}],"tv":36980.28}]}
{"op":"mcm","clk":"1011700518","pt":1580657369563,"mc":[{"id":"1.168223927","rc":[{"batl":[[2,1.78,1.77]],"ltp":1.72,"tv":27526.89,"id":8257852}]}]}
{"op":"mcm","clk":"1011700685","pt":1580657370439,"mc":[{"id":"1.168223927","rc":[{"batb":[[0,1.7,259.65]],"ltp":1.72,"tv":27526.89,"id":8257852}]}]}
{"op":"mcm","clk":"1011701006","pt":1580657371959,"mc":[{"id":"1.168223927","rc":[{"batb":[[0,1.72,26.04],[1,1.7,259.35],[2,1.68,3338.45]],"ltp":1.72,"tv":27526.89,"id":8257852}]}]}
{"op":"mcm","clk":"1011701166","pt":1580657372725,"mc":[{"id":"1.168223927","rc":[{"trd":[[1.74,5012.24]],"batb":[[0,1.72,26.35]],"batl":[[0,1.74,2277.27]],"ltp":1.74,"tv":27527.33,"id":8257852}],"tv":36980.72}]}
{"op":"mcm","clk":"1011701348","pt":1580657373640,"mc":[{"id":"1.168223927","rc":[{"batl":[[1,2.38,1.77],[2,2.4,396.58]],"ltp":2.36,"tv":9453.38,"id":8444055}]}]}
{"op":"mcm","clk":"1011701588","pt":1580657374727,"mc":[{"id":"1.168223927","rc":[{"batb":[[0,1.72,26.05]],"ltp":1.74,"tv":27527.33,"id":8257852}]}]}
{"op":"mcm","clk":"1011701901","pt":1580657376258,"mc":[{"id":"1.168223927","rc":[{"batb":[[0,1.72,20]],"ltp":1.74,"tv":27527.33,"id":8257852}]}]}
{"op":"mcm","clk":"1011702736","pt":1580657380343,"mc":[{"id":"1.168223927","rc":[{"trd":[[2.36,68.41]],"batl":[[0,2.36,319.85]],"ltp":2.36,"tv":9453.95,"id":8444055},{"trd":[[1.73,635.17]],"ltp":1.73,"tv":27528.11,"id":8257852}],"tv":36982.07}]}
{"op":"mcm","clk":"1011703032","pt":1580657381774,"mc":[{"id":"1.168223927","rc":[{"trd":[[2.36,68.57]],"batb":[[1,2.32,10.81],[2,2.24,591.87]],"batl":[[0,2.36,319.68]],"ltp":2.36,"tv":9454.12,"id":8444055},{"trd":[[1.73,635.39]],"batb":[[0,1.72,30.31]],"ltp":1.73,"tv":27528.33,"id":8257852}],"tv":36982.46}]}
{"op":"mcm","clk":"1011703521","pt":1580657383971,"mc":[{"id":"1.168223927","rc":[{"batl":[[0,2.38,1.77],[1,2.4,396.58],[2,2.42,29.41]],"ltp":2.36,"tv":9454.12,"id":8444055},{"trd":[[1.74,5012.58]],"batl":[[0,1.74,2277.1]],"ltp":1.74,"tv":27528.68,"id":8257852}],"tv":36982.8}]}
{"op":"mcm","clk":"1011703824","pt":1580657385369,"mc":[{"id":"1.168223927","rc":[{"batl":[[0,2.38,2.87]],"ltp":2.36,"tv":9454.12,"id":8444055}]}]}
{"op":"mcm","clk":"1011704018","pt":1580657386370,"mc":[{"id":"1.168223927","rc":[{"trd":[[2.38,272.55],[2.4,290.09]],"batl":[[0,2.4,136.01],[1,2.42,29.41],[2,2.44,951]],"ltp":2.4,"tv":9717.56,"id":8444055},{"trd":[[1.71,797.98],[1.72,716.89]],"batb":[[0,1.7,259.35],[1,1.68,3338.45],[2,1.67,348.58]],"ltp":1.71,"tv":27958.99,"id":8257852}],"tv":37676.55}]}
{"op":"mcm","clk":"1011704303","pt":1580657387660,"mc":[{"id":"1.168223927","rc":[{"trd":[[2.34,190.59]],"batb":[[0,2.34,159.41]],"ltp":2.34,"tv":9718.18,"id":8444055},{"batl":[[0,1.74,2277.55]],"ltp":1.71,"tv":27958.99,"id":8257852}],"tv":37677.17}]}
{"op":"mcm","clk":"1011704552","pt":1580657388859,"mc":[{"id":"1.168223927","rc":[{"batl":[[0,1.74,2277.16]],"ltp":1.71,"tv":27958.99,"id":8257852}]}]}
{"op":"mcm","clk":"1011704798","pt":1580657390083,"mc":[{"id":"1.168223927","rc":[{"batl":[[2,2.76,1.68]],"ltp":2.34,"tv":9718.18,"id":8444055}]}]}
{"op":"mcm","clk":"1011704983","pt":1580657390859,"mc":[{"id":"1.168223927","rc":[{"batl":[[0,1.73,256.06],[1,1.74,2277.1],[2,1.76,585.17]],"ltp":1.71,"tv":27958.99,"id":8257852}]}]}
{"op":"mcm","clk":"1011705330","pt":1580657392439,"mc":[{"id":"1.168223927","rc":[{"batl":[[0,1.74,2277.16],[1,1.76,585.17],[2,1.78,1.77]],"ltp":1.71,"tv":27958.99,"id":8257852}]}]}
{"op":"mcm","clk":"1011705684","pt":1580657394265,"mc":[{"id":"1.168223927","rc":[{"batb":[[1,2.24,185.57],[2,2.2,38.72]],"batl":[[0,2.42,29.41],[1,2.62,3.75],[2,2.74,3.48]],"ltp":2.34,"tv":9718.18,"id":8444055},{"trd":[[1.74,5023.32]],"batl":[[0,1.74,2271.73]],"ltp":1.74,"tv":27969.72,"id":8257852}],"tv":37687.91}]}
{"op":"mcm","clk":"1011705830","pt":1580657394993,"mc":[{"id":"1.168223927","rc":[{"batb":[[0,2.36,94.12],[2,2.2,4.27]],"batl":[[0,2.62,3.75],[1,2.74,3.48],[2,2.76,1.68]],"ltp":2.34,"tv":9718.18,"id":8444055},{"batb":[[0,1.62,25.6],[1,1.59,250.59],[2,1.58,31.06]],"batl":[[0,1.78,1.77],[1,1.8,23.37],[2,1.83,19.5]],"ltp":1.74,"tv":27969.72,"id":8257852}]}]}
{"op":"mcm","clk":"1011705992","pt":1580657395750,"mc":[{"id":"1.168223927","rc":[{"batl":[[0,2.74,3.48],[1,2.76,1.68],[2,1000,0.02]],"ltp":2.34,"tv":9718.18,"id":8444055},{"batb":[[0,1.59,251.14],[1,1.58,31.06],[2,1.52,425.49]],"ltp":1.74,"tv":27969.72,"id":8257852}]}]}
{"op":"mcm","clk":"1011706243","pt":1580657397083,"mc":[{"id":"1.168223927","rc":[{"trd":[[2.36,68.79]],"batb":[[0,2.36,188.02]],"ltp":2.36,"tv":9718.4,"id":8444055},{"trd":[[1.74,5023.62]],"ltp":1.74,"tv":27970.03,"id":8257852}],"tv":37688.43}]}
{"op":"mcm","clk":"1011706464","pt":1580657398067,"mc":[{"id":"1.168223927","rc":[{"batb":[[0,2.24,181.05],[1,2.2,4.27],[2,1.7,76.16]],"ltp":2.36,"tv":9718.4,"id":8444055},{"batl":[[1,1.83,19.5],[2,1.9,16.68]],"ltp":1.74,"tv":27970.03,"id":8257852}]}]}
{"op":"mcm","clk":"1011706649","pt":1580657398942,"mc":[{"id":"1.168223927","rc":[{"batl":[[0,2.62,3.75],[1,2.74,3.48],[2,2.76,1.68]],"ltp":2.36,"tv":9718.4,"id":8444055},{"batb":[[0,1.74,86.13],[1,1.62,29.6],[2,1.59,250.59]],"ltp":1.74,"tv":27970.03,"id":8257852}]}]}
{"op":"mcm","clk":"1011706768","pt":1580657399444,"mc":[{"id":"1.168223927","rc":[{"trd":[[2.36,89.75]],"batl":[[0,2.74,3.48],[1,2.76,1.68],[2,1000,0.02]],"ltp":2.36,"tv":9739.36,"id":8444055},{"trd":[[1.74,5167.45]],"batb":[[0,1.67,353.4],[1,1.66,355.35],[2,1.59,251.14]],"batl":[[0,1.72,482.97],[1,1.74,607.73],[2,1.78,1.77]],"ltp":1.74,"tv":28113.85,"id":8257852}],"tv":37853.22}]}
{"op":"mcm","clk":"1011707198","pt":1580657401189,"mc":[{"id":"1.168223927","rc":[{"trd":[[2.38,575.44]],"batb":[[0,2.24,185.32]],"ltp":2.38,"tv":10042.26,"id":8444055},{"trd":[[1.72,1136.01]],"batl":[[0,1.72,63.85]],"ltp":1.72,"tv":28532.97,"id":8257852}],"tv":38575.23}]}
{"op":"mcm","clk":"1011707328","pt":1580657401703,"mc":[{"id":"1.168223927","rc":[{"batb":[[2,1.64,1.11]],"batl":[[0,1.78,1.77],[1,1.79,134.43],[2,1.8,23.27]],"ltp":1.72,"tv":28532.97,"id":8257852}]}]}
{"op":"mcm","clk":"1011707544","pt":1580657402646,"mc":[{"id":"1.168223927","rc":[{"batl":[[0,2.62,3.92],[1,2.74,3.48],[2,2.76,1.68]],"ltp":2.38,"tv":10042.26,"id":8444055}]}]}
{"op":"mcm","clk":"1011708053","pt":1580657404882,"mc":[{"id":"1.168223927","rc":[{"trd":[[2.34,190.76]],"batl":[[0,2.74,3.48],[1,2.76,1.68],[2,1000,0.02]],"ltp":2.34,"tv":10042.42,"id":8444055},{"trd":[[1.74,5167.68]],"batb":[[0,1.64,1.11],[1,1.59,250.59],[2,1.58,31.06]],"ltp":1.74,"tv":28533.2,"id":8257852}],"tv":38575.63}]}
{"op":"mcm","clk":"1011708839","pt":1580657408067,"mc":[{"id":"1.168223927","rc":[{"batb":[[1,1.6,544.69],[2,1.59,666.12]],"batl":[[2,1.8,348.92]],"ltp":1.74,"tv":28533.2,"id":8257852}]}]}
{"op":"mcm","clk":"1011709563","pt":1580657411267,"mc":[{"id":"1.168223927","rc":[{"batl":[[0,2.62,4.25],[1,2.74,3.48],[2,2.76,1.68]],"ltp":2.34,"tv":10042.42,"id":8444055},{"batb":[[1,1.62,25.54],[2,1.6,544.69]],"ltp":1.74,"tv":28533.2,"id":8257852}]}]}
{"op":"mcm","clk":"1011709626","pt":1580657411614,"mc":[{"id":"1.168223927","rc":[{"batl":[[0,2.74,3.48],[1,2.76,1.68],[2,1000,0.02]],"ltp":2.34,"tv":10042.42,"id":8444055},{"batb":[[1,1.6,544.69],[2,1.59,666.12]],"ltp":1.74,"tv":28533.2,"id":8257852}]}]}
{"op":"mcm","clk":"1011709865","pt":1580657412791,"mc":[{"id":"1.168223927","rc":[{"batb":[[1,1.59,250.59],[2,1.58,31.06]],"batl":[[2,1.8,23.27]],"ltp":1.74,"tv":28533.2,"id":8257852}]}]}
{"op":"mcm","clk":"1011710433","pt":1580657415256,"mc":[{"id":"1.168223927","rc":[{"trd":[[1.78,659.75],[1.79,230.09]],"batl":[[0,1.77,4.45],[1,1.79,115.9]],"ltp":1.79,"tv":28573.78,"id":8257852}],"tv":38616.21}]}
{"op":"mcm","clk":"1011710570","pt":1580657415962,"mc":[{"id":"1.168223927","rc":[{"batb":[[0,2.6,6.05],[1,2.38,30.25],[2,2.24,185.32]],"batl":[[0,2.66,31.05],[1,2.68,719],[2,2.72,495.65]],"ltp":2.34,"tv":10042.42,"id":8444055},{"trd":[[1.64,1208.04]],"batb":[[0,1.61,68.06],[1,1.6,544.83],[2,1.59,3496.31]],"batl":[[0,1.64,2742.78],[1,1.65,1494.52],[2,1.66,353.93]],"ltp":1.64,"tv":28576.01,"id":8257852}],"tv":38618.44}]}
{"op":"mcm","clk":"1011710751","pt":1580657416765,"mc":[{"id":"1.168223927","rc":[{"batb":[[1,2.58,123.61],[2,2.42,146.35]],"ltp":2.34,"tv":10042.42,"id":8444055}]}]}
{"op":"mcm","clk":"1011711098","pt":1580657418176,"mc":[{"id":"1.168223927","rc":[{"batl":[[1,1.65,561.06]],"ltp":1.64,"tv":28576.01,"id":8257852}]}]}
{"op":"mcm","clk":"1011711211","pt":1580657418663,"mc":[{"id":"1.168223927","rc":[{"trd":[[2.6,68.73]],"batb":[[0,2.58,123.61],[1,2.42,146.35],[2,2.38,30.25]],"ltp":2.6,"tv":10048.47,"id":8444055},{"trd":[[1.63,2744.37],[1.64,1975.5]],"batl":[[0,1.64,2359.05]],"ltp":1.64,"tv":29353.13,"id":8257852}],"tv":39401.61}]}
{"op":"mcm","clk":"1011711529","pt":1580657420190,"mc":[{"id":"1.168223927","rc":[{"batb":[[1,1.6,567.55]],"ltp":1.64,"tv":29353.13,"id":8257852}]}]}
{"op":"mcm","clk":"1011711739","pt":1580657421206,"mc":[{"id":"1.168223927","rc":[{"trd":[[2.66,31.05]],"batl":[[0,2.68,719],[1,2.72,495.65],[2,2.74,3.48]],"ltp":2.66,"tv":10079.52,"id":8444055},{"trd":[[1.59,1146.16],[1.6,1186.71],[1.61,144.63],[1.64,1975.77]],"batb":[[0,1.59,2923.22],[1,1.58,31.06],[2,1.48,337.16]],"batl":[[0,1.64,2358.92],[1,1.65,362.8],[2,1.68,1952.77]],"ltp":1.59,"tv":31822.38,"id":8257852}],"tv":41901.91}]}
{"op":"mcm","clk":"1011711875","pt":1580657421813,"mc":[{"id":"1.168223927","rc":[{"batb":[[2,2.24,4.27]],"ltp":2.66,"tv":10079.52,"id":8444055},{"trd":[[1.59,2826.55]],"batb":[[0,1.59,2083.02],[2,1.57,494.03]],"batl":[[2,1.67,480.59]],"ltp":1.59,"tv":33502.78,"id":8257852}],"tv":43582.3}]}
{"op":"mcm","clk":"1011712155","pt":1580657423111,"mc":[{"id":"1.168223927","rc":[{"batb":[[2,2.36,4.18]],"ltp":2.66,"tv":10079.52,"id":8444055},{"trd":[[1.63,2786.78]],"batb":[[0,1.62,82.38],[1,1.59,2083.02],[2,1.58,31.06]],"batl":[[0,1.63,51.08],[1,1.64,2418.99],[2,1.65,362.8]],"ltp":1.63,"tv":33545.18,"id":8257852}],"tv":43624.71}]}
{"op":"mcm","clk":"1011712405","pt":1580657424198,"mc":[{"id":"1.168223927","rc":[{"batb":[[1,2.42,175.76]],"batl":[[1,2.7,24.37],[2,2.72,495.65]],"ltp":2.66,"tv":10079.52,"id":8444055},{"batb":[[1,1.61,66.77],[2,1.59,2398.83]],"batl":[[1,1.64,2912.11]],"ltp":1.63,"tv":33545.18,"id":8257852}]}]}
{"op":"mcm","clk":"1011712598","pt":1580657425120,"mc":[{"id":"1.168223927","rc":[{"batl":[[0,2.68,719.44]],"ltp":2.66,"tv":10079.52,"id":8444055},{"trd":[[1.63,2787.17]],"batl":[[0,1.63,50.88]],"ltp":1.63,"tv":33545.57,"id":8257852}],"tv":43625.1}]}
{"op":"mcm","clk":"1011712850","pt":1580657426193,"mc":[{"id":"1.168223927","rc":[{"trd":[[1.62,1874.48],[1.63,2789.02]],"batb":[[0,1.62,80.7]],"batl":[[0,1.63,49.96]],"ltp":1.63,"tv":33550.79,"id":8257852}],"tv":43630.31}]}
{"op":"mcm","clk":"1011712948","pt":1580657426629,"mc":[{"id":"1.168223927","rc":[{"trd":[[1.63,2789.64]],"batl":[[0,1.63,49.65]],"ltp":1.63,"tv":33551.41,"id":8257852}],"tv":43630.93}]}
{"op":"mcm","clk":"1011713311","pt":1580657428113,"mc":[{"id":"1.168223927","rc":[{"trd":[[1.63,2795.51]],"batb":[[0,1.62,75.85],[1,1.61,94.82],[2,1.6,56.34]],"batl":[[0,1.63,126.3],[1,1.64,2852.28]],"ltp":1.63,"tv":33557.27,"id":8257852}],"tv":43636.8}]}
{"op":"mcm","clk":"1011713416","pt":1580657428693,"mc":[{"id":"1.168223927","rc":[{"trd":[[1.62,1890.41],[1.63,2798.07]],"batb":[[0,1.62,67.89]],"batl":[[0,1.63,125.02]],"ltp":1.63,"tv":33575.76,"id":8257852}],"tv":43655.29}]}
{"op":"mcm","clk":"1011713701","pt":1580657430120,"mc":[{"id":"1.168223927","rc":[{"trd":[[2.58,381.45]],"batb":[[0,2.58,115.88]],"ltp":2.58,"tv":10094.98,"id":8444055},{"trd":[[1.63,2799.41]],"batl":[[0,1.63,124.35]],"ltp":1.63,"tv":33577.1,"id":8257852}],"tv":43672.08}]}
{"op":"mcm","clk":"1011713926","pt":1580657431204,"mc":[{"id":"1.168223927","rc":[{"trd":[[2.6,69.27]],"batl":[[0,2.68,719]],"ltp":2.6,"tv":10095.51,"id":8444055},{"trd":[[1.62,2027.04]],"batb":[[0,1.61,94.82],[1,1.6,56.34],[2,1.59,2398.83]],"batl":[[0,1.62,181.25],[1,1.63,124.35],[2,1.64,2852.28]],"ltp":1.62,"tv":33713.74,"id":8257852}],"tv":43809.26}]}
{"op":"mcm","clk":"1011714170","pt":1580657432235,"mc":[{"id":"1.168223927","rc":[{"batl":[[0,2.7,24.37],[1,2.76,1.68],[2,3.05,2.9]],"ltp":2.6,"tv":10095.51,"id":8444055},{"trd":[[1.62,2072.67]],"batb":[[2,1.59,70.58]],"batl":[[0,1.62,159.78],[2,1.67,480.83]],"ltp":1.62,"tv":33759.36,"id":8257852}],"tv":43854.88}]}
{"op":"mcm","clk":"1011714346","pt":1580657432997,"mc":[{"id":"1.168223927","rc":[{"trd":[[2.6,86.95]],"batb":[[0,2.42,146.35],[1,2.36,4.18],[2,2.28,4.41]],"batl":[[0,2.76,1.68],[1,3.05,2.9],[2,3.2,2.83]],"ltp":2.6,"tv":10113.19,"id":8444055},{"trd":[[1.62,2101.06]],"batb":[[2,1.57,494.03]],"batl":[[0,1.62,131.39]],"ltp":1.62,"tv":33787.75,"id":8257852}],"tv":43900.95}]}
{"op":"mcm","clk":"1011714479","pt":1580657433612,"mc":[{"id":"1.168223927","rc":[{"trd":[[1.62,2102.84]],"batl":[[0,1.62,130.5]],"ltp":1.62,"tv":33789.54,"id":8257852}],"tv":43902.73}]}
{"op":"mcm","clk":"1011714818","pt":1580657435214,"mc":[{"id":"1.168223927","rc":[{"batl":[[1,3,2.78],[2,3.05,2.9]],"ltp":2.6,"tv":10113.19,"id":8444055},{"trd":[[1.61,179.99],[1.62,2107.49]],"batb":[[0,1.61,77.13]],"batl":[[0,1.62,128.17]],"ltp":1.62,"tv":33829.56,"id":8257852}],"tv":43942.76}]}
{"op":"mcm","clk":"1011714920","pt":1580657435693,"mc":[{"id":"1.168223927","rc":[{"batb":[[0,2.44,142.02]],"ltp":2.6,"tv":10113.19,"id":8444055},{"trd":[[1.62,2109.73]],"batl":[[0,1.62,127.05]],"ltp":1.62,"tv":33831.79,"id":8257852}],"tv":43944.99}]}
{"op":"mcm","clk":"1011715214","pt":1580657437099,"mc":[{"id":"1.168223927","rc":[{"trd":[[1.62,2112.51]],"batl":[[0,1.62,125.66]],"ltp":1.62,"tv":33834.57,"id":8257852}],"tv":43947.77}]}
{"op":"mcm","clk":"1011715309","pt":1580657437533,"mc":[{"id":"1.168223927","rc":[{"trd":[[2.6,88.07]],"ltp":2.6,"tv":10114.31,"id":8444055},{"trd":[[1.62,2114.3]],"batl":[[0,1.62,123.87]],"ltp":1.62,"tv":33836.36,"id":8257852}],"tv":43950.67}]}
{"op":"mcm","clk":"1011715641","pt":1580657439117,"mc":[{"id":"1.168223927","rc":[{"trd":[[2.6,88.31]],"ltp":2.6,"tv":10114.55,"id":8444055},{"trd":[[1.62,2114.69]],"batl":[[0,1.62,122.14]],"ltp":1.62,"tv":33836.75,"id":8257852}],"tv":43951.31}]}
{"op":"mcm","clk":"1011715677","pt":1580657439315,"mc":[{"id":"1.168223927","rc":[{"trd":[[1.62,2115.13]],"batl":[[0,1.62,121.92]],"ltp":1.62,"tv":33837.19,"id":8257852}],"tv":43951.74}]}
{"op":"mcm","clk":"1011716349","pt":1580657442228,"mc":[{"id":"1.168223927","rc":[{"trd":[[1.62,2115.79]],"batb":[[2,1.57,494.3]],"batl":[[0,1.62,121.59]],"ltp":1.62,"tv":33837.85,"id":8257852}],"tv":43952.41}]}
{"op":"mcm","clk":"1011716549","pt":1580657443060,"mc":[{"id":"1.168223927","rc":[{"trd":[[2.6,88.53]],"batl":[[1,3.2,2.83],[2,3.25,2.42]],"ltp":2.6,"tv":10114.77,"id":8444055},{"trd":[[1.62,2116.15]],"batb":[[0,1.48,835],[1,1.47,916.49],[2,1.46,36.38]],"batl":[[0,1.62,121.23]],"ltp":1.62,"tv":33838.21,"id":8257852}],"tv":43952.99}]}
{"op":"mcm","clk":"1011717079","pt":1580657445246,"mc":[{"id":"1.168223927","rc":[{"trd":[[2.76,1.68]],"batb":[[0,2.96,7.03],[1,2.44,142.02],[2,2.36,4.18]],"batl":[[0,3.05,5.75],[1,3.1,838],[2,3.2,2.83]],"ltp":2.76,"tv":10116.45,"id":8444055},{"trd":[[1.52,27.1],[1.56,2.97],[1.58,0.54]],"batb":[[0,1.48,3875.27],[1,1.47,1825.74]],"batl":[[0,1.52,3332.11],[1,1.53,480.09],[2,1.55,1235]],"ltp":1.52,"tv":33868.82,"id":8257852}],"tv":43985.28}]}
{"op":"mcm","clk":"1011717278","pt":1580657446221,"mc":[{"id":"1.168223927","rc":[{"batb":[[0,2.98,84.82],[1,2.96,7.03],[2,2.74,104.65]],"batl":[[0,3.05,25.91]],"ltp":2.76,"tv":10116.45,"id":8444055},{"batb":[[0,1.49,85.7],[1,1.48,3875.27],[2,1.47,1825.74]],"ltp":1.52,"tv":33868.82,"id":8257852}]}]}
{"op":"mcm","clk":"1011718570","pt":1580657452070,"mc":[{"id":"1.168223927","rc":[{"trd":[[3.05,20.27]],"batl":[[0,3.05,15.78]],"ltp":3.05,"tv":10136.72,"id":8444055},{"batl":[[2,1.54,480.59]],"ltp":1.52,"tv":33868.82,"id":8257852}],"tv":44005.55}]}
{"op":"mcm","clk":"1011718811","pt":1580657453165,"mc":[{"id":"1.168223927","rc":[{"batb":[[0,1.5,77.02],[1,1.49,155.19],[2,1.48,3875.27]],"batl":[[0,1.51,123.16],[1,1.52,3388.96],[2,1.53,480.09]],"ltp":1.52,"tv":33868.82,"id":8257852}]}]}
{"op":"mcm","clk":"1011718993","pt":1580657454120,"mc":[{"id":"1.168223927","rc":[{"trd":[[3,0.12]],"ltp":3.0,"tv":10136.84,"id":8444055},{"trd":[[1.5,2.91]],"batb":[[0,1.5,75.45]],"ltp":1.5,"tv":33871.73,"id":8257852}],"tv":44008.58}]}
{"op":"mcm","clk":"1011719148","pt":1580657454953,"mc":[{"id":"1.168223927","rc":[{"batl":[[0,3.05,19.98]],"ltp":3.0,"tv":10136.84,"id":8444055},{"trd":[[1.5,6.27]],"batb":[[0,1.5,73.77]],"ltp":1.5,"tv":33875.09,"id":8257852}],"tv":44011.94}]}
{"op":"mcm","clk":"1011719409","pt":1580657456265,"mc":[{"id":"1.168223927","rc":[{"trd":[[1.51,0.6]],"batl":[[0,1.51,122.86]],"ltp":1.51,"tv":33875.7,"id":8257852}],"tv":44012.54}]}
{"op":"mcm","clk":"1011719614","pt":1580657457179,"mc":[{"id":"1.168223927","rc":[{"trd":[[2.98,0.88]],"batb":[[0,2.98,84.38]],"ltp":2.98,"tv":10137.72,"id":8444055},{"trd":[[1.51,3.04]],"batl":[[0,1.51,121.64]],"ltp":1.51,"tv":33878.13,"id":8257852}],"tv":44015.86}]}
{"op":"mcm","clk":"1011719849","pt":1580657458164,"mc":[{"id":"1.168223927","rc":[{"batl":[[0,3.05,36.78]],"ltp":2.98,"tv":10137.72,"id":8444055},{"trd":[[1.51,6.12]],"batb":[[1,1.49,85.7]],"batl":[[0,1.51,120.11],[1,1.52,3332.11]],"ltp":1.51,"tv":33881.21,"id":8257852}],"tv":44018.93}]}
{"op":"mcm","clk":"1011720040","pt":1580657459174,"mc":[{"id":"1.168223927","rc":[{"trd":[[1.51,7.23]],"batl":[[0,1.51,119.55]],"ltp":1.51,"tv":33882.32,"id":8257852}],"tv":44020.04}]}
{"op":"mcm","clk":"1011720263","pt":1580657460043,"mc":[{"id":"1.168223927","rc":[{"trd":[[1.5,9.38],[1.51,51.56]],"batb":[[0,1.5,72.21]],"batl":[[0,1.51,97.39]],"ltp":1.5,"tv":33929.76,"id":8257852}],"tv":44067.48}]}
{"op":"mcm","clk":"1011720469","pt":1580657460994,"mc":[{"id":"1.168223927","rc":[{"trd":[[2.98,2.21]],"batb":[[0,2.98,83.05]],"ltp":2.98,"tv":10139.04,"id":8444055},{"trd":[[1.5,12.59],[1.51,248.94]],"batb":[[0,1.5,70.61]],"batl":[[0,1.52,3332.11],[1,1.53,480.09],[2,1.54,480.59]],"ltp":1.51,"tv":34130.36,"id":8257852}],"tv":44269.41}]}
{"op":"mcm","clk":"1011720759","pt":1580657462172,"mc":[{"id":"1.168223927","rc":[{"batb":[[1,2.74,104.65],[2,2.7,24.37]],"batl":[[1,3.2,2.83],[2,3.25,2.42]],"ltp":2.98,"tv":10139.04,"id":8444055},{"trd":[[1.5,109.86]],"batb":[[0,1.5,21.98]],"ltp":1.5,"tv":34227.63,"id":8257852}],"tv":44366.68}]}
{"op":"mcm","clk":"1011720957","pt":1580657463078,"mc":[{"id":"1.168223927","rc":[{"trd":[[2.98,4.44]],"batb":[[0,2.74,104.65],[1,2.58,3.87],[2,2.48,4.01]],"batl":[[0,3.05,16.8],[1,3.65,2.5],[2,3.75,2.18]],"ltp":2.98,"tv":10141.28,"id":8444055},{"batb":[[0,1.5,22.49],[1,1.46,494.04],[2,1.44,510.84]],"batl":[[0,1.54,480.59],[1,1.56,497.4],[2,1.63,26.5]],"ltp":1.5,"tv":34227.63,"id":8257852}],"tv":44368.91}]}
{"op":"mcm","clk":"1011721064","pt":1580657463583,"mc":[{"id":"1.168223927","rc":[{"batb":[[0,1.5,22.64]],"ltp":1.5,"tv":34227.63,"id":8257852}]}]}
{"op":"mcm","clk":"1011721352","pt":1580657465003,"mc":[{"id":"1.168223927","rc":[{"trd":[[3,3.64]],"ltp":3.0,"tv":10144.8,"id":8444055},{"trd":[[1.5,146.31],[1.51,250.44]],"batb":[[0,1.46,494.28],[1,1.44,510.84],[2,1.4,2.53]],"ltp":1.5,"tv":34265.57,"id":8257852}],"tv":44410.37}]}
{"op":"mcm","clk":"1011721553","pt":1580657465991,"mc":[{"id":"1.168223927","rc":[{"batl":[[0,2.98,215],[1,3.05,16.8],[2,3.65,2.5]],"ltp":3.0,"tv":10144.8,"id":8444055},{"batb":[[0,1.46,494.95]],"batl":[[2,1.6,660.5]],"ltp":1.5,"tv":34265.57,"id":8257852}]}]}
{"op":"mcm","clk":"1011721773","pt":1580657466975,"mc":[{"id":"1.168223927","rc":[{"batl":[[0,2.98,200.62]],"ltp":3.0,"tv":10144.8,"id":8444055},{"batb":[[0,1.51,1.42],[1,1.46,494.28],[2,1.44,510.84]],"batl":[[0,1.6,660.5],[1,1.61,395.39],[2,1.63,26.5]],"ltp":1.5,"tv":34265.57,"id":8257852}]}]}
{"op":"mcm","clk":"1011721969","pt":1580657467960,"mc":[{"id":"1.168223927","rc":[{"batl":[[0,3.05,17.42],[1,3.65,2.5],[2,3.75,2.18]],"ltp":3.0,"tv":10144.8,"id":8444055},{"batb":[[0,1.51,2.53]],"ltp":1.5,"tv":34265.57,"id":8257852}]}]}
{"op":"mcm","clk":"1011722248","pt":1580657469179,"mc":[{"id":"1.168223927","rc":[{"batb":[[1,2.6,367.8],[2,2.58,3.87]],"batl":[[0,2.76,2249],[1,2.78,5.62],[2,2.82,821]],"ltp":3.0,"tv":10144.8,"id":8444055},{"batb":[[0,1.55,2903.23],[1,1.53,4.63],[2,1.51,3.68]],"batl":[[0,1.6,3498.05],[2,1.63,1188.5]],"ltp":1.5,"tv":34265.57,"id":8257852}]}]}
{"op":"mcm","clk":"1011722488","pt":1580657470183,"mc":[{"id":"1.168223927","rc":[{"batl":[[0,2.78,5.62],[1,2.8,2.02]],"ltp":3.0,"tv":10144.8,"id":8444055},{"batb":[[0,1.56,9.58],[1,1.55,3639.15],[2,1.54,759.83]],"ltp":1.5,"tv":34265.57,"id":8257852}]}]}
{"op":"mcm","clk":"1011722719","pt":1580657471250,"mc":[{"id":"1.168223927","rc":[{"batb":[[1,1.55,3563.53]],"ltp":1.5,"tv":34265.57,"id":8257852}]}]}
{"op":"mcm","clk":"1011722886","pt":1580657472079,"mc":[{"id":"1.168223927","rc":[{"batb":[[1,1.55,3639.15]],"ltp":1.5,"tv":34265.57,"id":8257852}]}]}
{"op":"mcm","clk":"1011723104","pt":1580657473158,"mc":[{"id":"1.168223927","rc":[{"trd":[[1.56,3.53]],"batb":[[0,1.56,9.3]],"ltp":1.56,"tv":34266.13,"id":8257852}],"tv":44410.93}]}
{"op":"mcm","clk":"1011723502","pt":1580657474981,"mc":[{"id":"1.168223927","rc":[{"batl":[[0,2.8,2.02],[1,2.82,821],[2,2.84,455.87]],"ltp":3.0,"tv":10144.8,"id":8444055},{"batl":[[0,1.6,3473]],"ltp":1.56,"tv":34266.13,"id":8257852}]}]}
{"op":"mcm","clk":"1011723792","pt":1580657476213,"mc":[{"id":"1.168223927","rc":[{"batl":[[0,1.58,77.84],[1,1.6,3473],[2,1.61,875.98]],"ltp":1.56,"tv":34266.13,"id":8257852}]}]}
{"op":"mcm","clk":"1011723935","pt":1580657476821,"mc":[{"id":"1.168223927","rc":[{"batb":[[0,1.57,65.01],[1,1.56,68.12],[2,1.55,3639.15]],"batl":[[1,1.59,55.54],[2,1.6,3473]],"ltp":1.56,"tv":34266.13,"id":8257852}]}]}
{"op":"mcm","clk":"1011724245","pt":1580657478167,"mc":[{"id":"1.168223927","rc":[{"batl":[[0,2.78,5.62],[1,2.8,2.02],[2,2.82,821]],"ltp":3.0,"tv":10144.8,"id":8444055},{"batl":[[2,1.6,3498.05]],"ltp":1.56,"tv":34266.13,"id":8257852}]}]}
{"op":"mcm","clk":"1011724463","pt":1580657479089,"mc":[{"id":"1.168223927","rc":[{"trd":[[2.76,14.35]],"ltp":2.76,"tv":10157.47,"id":8444055},{"trd":[[1.57,22.27],[1.58,1.43]],"batb":[[0,1.57,42.73]],"batl":[[0,1.58,77.39]],"ltp":1.57,"tv":34289.29,"id":8257852}],"tv":44446.76}]}
{"op":"mcm","clk":"1011724700","pt":1580657480094,"mc":[{"id":"1.168223927","rc":[{"trd":[[1.57,22.88],[1.58,1.88]],"batb":[[0,1.57,42.43]],"batl":[[0,1.58,77.16]],"ltp":1.57,"tv":34290.35,"id":8257852}],"tv":44447.82}]}
{"op":"mcm","clk":"1011725180","pt":1580657482255,"mc":[{"id":"1.168223927","rc":[{"trd":[[2.74,33.61],[2.76,15.23]],"batb":[[0,2.74,87.84]],"ltp":2.74,"tv":10191.95,"id":8444055},{"trd":[[1.57,24.42]],"batb":[[0,1.57,40.88],[1,1.56,146.8]],"ltp":1.57,"tv":34291.89,"id":8257852}],"tv":44483.85}]}
{"op":"mcm","clk":"1011725454","pt":1580657483230,"mc":[{"id":"1.168223927","rc":[{"batb":[[1,2.58,3.87],[2,2.56,26.89]],"batl":[[0,2.8,2.02],[1,2.84,22.69],[2,3.4,3.11]],"ltp":2.74,"tv":10191.95,"id":8444055},{"trd":[[1.58,12.76]],"batl":[[0,1.58,71.72],[2,1.6,3473]],"ltp":1.58,"tv":34302.78,"id":8257852}],"tv":44494.73}]}
{"op":"mcm","clk":"1011725577","pt":1580657483823,"mc":[{"id":"1.168223927","rc":[{"batb":[[0,2.56,26.89],[1,2.52,131.48],[2,2.42,3.94]],"batl":[[0,2.84,22.69],[1,3.4,3.11],[2,3.45,2.5]],"ltp":2.74,"tv":10191.95,"id":8444055},{"trd":[[1.57,68.3],[1.58,14.58]],"batb":[[0,1.57,18.95],[1,1.56,137.5],[2,1.55,75.62]],"batl":[[0,1.58,70.81],[2,1.61,480.59]],"ltp":1.57,"tv":34348.47,"id":8257852}],"tv":44540.43}]}
{"op":"mcm","clk":"1011725848","pt":1580657485105,"mc":[{"id":"1.168223927","rc":[{"batb":[[0,2.52,131.48],[1,2.42,3.94],[2,2.36,4.18]],"batl":[[0,3.4,3.11],[1,3.45,2.5],[2,3.65,2.5]],"ltp":2.74,"tv":10191.95,"id":8444055},{"trd":[[1.57,72.69],[1.58,19.4]],"batb":[[0,1.57,16.75],[2,1.53,494.03]],"batl":[[0,1.58,68.4]],"ltp":1.57,"tv":34357.68,"id":8257852}],"tv":44549.64}]}
{"op":"mcm","clk":"1011726021","pt":1580657485922,"mc":[{"id":"1.168223927","rc":[{"trd":[[1.58,21.08]],"batl":[[0,1.58,67.56]],"ltp":1.58,"tv":34359.36,"id":8257852}],"tv":44551.32}]}
{"op":"mcm","clk":"1011726962","pt":1580657489838,"mc":[{"id":"1.168223927","rc":[{"trd":[[1.58,22.94]],"batl":[[0,1.58,66.63]],"ltp":1.58,"tv":34361.22,"id":8257852}],"tv":44553.18}]}
{"op":"mcm","clk":"1011727612","pt":1580657492810,"mc":[{"id":"1.168223927","rc":[{"trd":[[1.58,23.69]],"batl":[[0,1.58,66.26]],"ltp":1.58,"tv":34361.96,"id":8257852}],"tv":44553.92}]}
{"op":"mcm","clk":"1011727893","pt":1580657494128,"mc":[{"id":"1.168223927","rc":[{"trd":[[1.58,34.8]],"batl":[[0,1.58,60.7]],"ltp":1.58,"tv":34373.08,"id":8257852}],"tv":44565.03}]}
{"op":"mcm","clk":"1011727952","pt":1580657494442,"mc":[{"id":"1.168223927","rc":[{"trd":[[1.58,39.18]],"batl":[[0,1.58,58.51]],"ltp":1.58,"tv":34377.46,"id":8257852}],"tv":44569.42}]}
{"op":"mcm","clk":"1011728292","pt":1580657496055,"mc":[{"id":"1.168223927","rc":[{"batb":[[0,1.42,855.75],[1,1.41,1139.76],[2,1.4,2.53]],"ltp":1.58,"tv":34377.46,"id":8257852}]}]}
{"op":"mcm","clk":"1011728691","pt":1580657498148,"mc":[{"id":"1.168223927","rc":[{"trd":[[1.58,40.52]],"batl":[[0,1.58,58.07]],"ltp":1.58,"tv":34378.79,"id":8257852}],"tv":44570.75}]}
{"op":"mcm","clk":"1011728889","pt":1580657499141,"mc":[{"id":"1.168223927","rc":[{"trd":[[2.98,5.06]],"batb":[[0,3,279.14],[1,2.52,131.48],[2,2.42,3.94]],"batl":[[0,3.4,856.49]],"ltp":2.98,"tv":10192.57,"id":8444055},{"trd":[[1.48,0.02],[1.5,147.54],[1.51,251.32]],"batb":[[0,1.43,13.81],[1,1.42,4024.31],[2,1.41,2163.4]],"batl":[[0,1.45,13.25],[1,1.46,3825.93],[2,1.47,560.58]],"ltp":1.48,"tv":34380.92,"id":8257852}],"tv":44573.5}]}
{"op":"mcm","clk":"1011729174","pt":1580657500243,"mc":[{"id":"1.168223927","rc":[{"batb":[[0,3.25,169.56],[1,3,279.14],[2,2.94,87.57]],"batl":[[0,3.3,17.64],[1,3.4,856.49],[2,3.45,2.5]],"ltp":2.98,"tv":10192.57,"id":8444055},{"batb":[[0,1.43,111.27]],"ltp":1.48,"tv":34380.92,"id":8257852}]}]}
{"op":"mcm","clk":"1011729261","pt":1580657500672,"mc":[{"id":"1.168223927","rc":[{"trd":[[1.45,4.38]],"batl":[[0,1.45,11.06]],"ltp":1.45,"tv":34385.31,"id":8257852}],"tv":44577.88}]}
{"op":"mcm","clk":"1011729592","pt":1580657502055,"mc":[{"id":"1.168223927","rc":[{"trd":[[3.25,1.02]],"batb":[[0,3.25,169.05]],"ltp":3.25,"tv":10193.59,"id":8444055}],"tv":44578.9}]}
{"op":"mcm","clk":"1011729867","pt":1580657503241,"mc":[{"id":"1.168223927","rc":[{"batl":[[1,1.46,4759.39]],"ltp":1.45,"tv":34385.31,"id":8257852}]}]}
{"op":"mcm","clk":"1011730277","pt":1580657505185,"mc":[{"id":"1.168223927","rc":[{"batl":[[2,1.47,1041.17]],"ltp":1.45,"tv":34385.31,"id":8257852}]}]}
{"op":"mcm","clk":"1011730475","pt":1580657506060,"mc":[{"id":"1.168223927","rc":[{"batb":[[0,1.44,59.77],[1,1.43,111.27],[2,1.42,4024.31]],"batl":[[0,1.45,1038.27]],"ltp":1.45,"tv":34385.31,"id":8257852}]}]}
{"op":"mcm","clk":"1011730693","pt":1580657506960,"mc":[{"id":"1.168223927","rc":[{"trd":[[3.3,21.69]],"batl":[[0,3.3,6.8]],"ltp":3.3,"tv":10215.28,"id":8444055},{"batb":[[1,1.43,167.21]],"batl":[[1,1.46,4828.94]],"ltp":1.45,"tv":34385.31,"id":8257852}],"tv":44600.59}]}
{"op":"mcm","clk":"1011730899","pt":1580657508047,"mc":[{"id":"1.168223927","rc":[{"trd":[[1.45,8.77]],"batl":[[0,1.45,1032.53]],"ltp":1.45,"tv":34389.69,"id":8257852}],"tv":44604.98}]}
{"op":"mcm","clk":"1011731375","pt":1580657509949,"mc":[{"id":"1.168223927","rc":[{"trd":[[1.45,84.69]],"batl":[[0,1.45,994.57]],"ltp":1.45,"tv":34465.61,"id":8257852}],"tv":44680.9}]}
{"op":"mcm","clk":"1011731685","pt":1580657511264,"mc":[{"id":"1.168223927","rc":[{"batb":[[2,2.94,108.58]],"batl":[[0,3.3,16.88]],"ltp":3.3,"tv":10215.28,"id":8444055},{"trd":[[1.43,13.44],[1.44,50.87],[1.45,123.14]],"batb":[[0,1.43,218.95],[1,1.42,4024.31],[2,1.41,2163.4]],"batl":[[0,1.45,1044.85],[1,1.46,3825.93]],"ltp":1.45,"tv":34568.36,"id":8257852}],"tv":44783.65}]}
{"op":"mcm","clk":"1011731937","pt":1580657512254,"mc":[{"id":"1.168223927","rc":[{"batb":[[2,2.94,87.57]],"batl":[[0,3.4,856.49],[1,3.45,2.5],[2,3.65,2.5]],"ltp":3.3,"tv":10215.28,"id":8444055},{"trd":[[1.43,338.17]],"batb":[[0,1.43,56.51]],"ltp":1.43,"tv":34893.09,"id":8257852}],"tv":45108.38}]}
{"op":"mcm","clk":"1011732060","pt":1580657512751,"mc":[{"id":"1.168223927","rc":[{"trd":[[1.43,338.84],[1.45,123.71]],"batb":[[0,1.43,56.18]],"batl":[[0,1.45,1044.56]],"ltp":1.43,"tv":34894.34,"id":8257852}],"tv":45109.62}]}
{"op":"mcm","clk":"1011732359","pt":1580657513961,"mc":[{"id":"1.168223927","rc":[{"trd":[[3.3,21.86]],"ltp":3.3,"tv":10215.45,"id":8444055},{"trd":[[1.43,343.88],[1.44,51.25]],"batb":[[0,1.44,12.94],[1,1.43,1774.85],[2,1.42,4024.31]],"batl":[[1,1.46,3838.68]],"ltp":1.44,"tv":34899.76,"id":8257852}],"tv":45115.21}]}
{"op":"mcm","clk":"1011732655","pt":1580657515170,"mc":[{"id":"1.168223927","rc":[{"batb":[[2,2.98,21]],"batl":[[0,3.35,17.64],[1,3.4,856.49],[2,3.45,2.5]],"ltp":3.3,"tv":10215.45,"id":8444055},{"trd":[[1.45,127.85]],"batb":[[2,1.42,4124.29]],"batl":[[0,1.45,1042.5]],"ltp":1.45,"tv":34903.9,"id":8257852}],"tv":45119.35}]}
{"op":"mcm","clk":"1011732893","pt":1580657516210,"mc":[{"id":"1.168223927","rc":[{"trd":[[1.44,55.63],[1.45,183.13]],"batb":[[0,1.44,10.75]],"batl":[[0,1.45,1014.85]],"ltp":1.45,"tv":34963.57,"id":8257852}],"tv":45179.02}]}
{"op":"mcm","clk":"1011733115","pt":1580657517010,"mc":[{"id":"1.168223927","rc":[{"trd":[[1.44,56.6],[1.45,186.14]],"batb":[[0,1.44,10.27]],"batl":[[0,1.45,1013.35]],"ltp":1.45,"tv":34967.54,"id":8257852}],"tv":45182.99}]}
{"op":"mcm","clk":"1011733295","pt":1580657517787,"mc":[{"id":"1.168223927","rc":[{"trd":[[1.45,196.01]],"batl":[[0,1.45,1008.42]],"ltp":1.45,"tv":34977.41,"id":8257852}],"tv":45192.86}]}
{"op":"mcm","clk":"1011733628","pt":1580657519206,"mc":[{"id":"1.168223927","rc":[{"batb":[[0,1.43,1774.85],[1,1.42,4124.29],[2,1.41,2163.4]],"batl":[[0,1.44,361.38],[1,1.45,1008.42],[2,1.46,3825.93]],"ltp":1.45,"tv":34977.41,"id":8257852}]}]}
{"op":"mcm","clk":"1011733715","pt":1580657519613,"mc":[{"id":"1.168223927","rc":[{"batl":[[0,1.44,361.16]],"ltp":1.45,"tv":34977.41,"id":8257852}]}]}
{"op":"mcm","clk":"1011733991","pt":1580657520818,"mc":[{"id":"1.168223927","rc":[{"batl":[[1,3.4,2.49]],"ltp":3.3,"tv":10215.45,"id":8444055},{"batl":[[0,1.44,362.69]],"ltp":1.45,"tv":34977.41,"id":8257852}]}]}
{"op":"mcm","clk":"1011734299","pt":1580657522104,"mc":[{"id":"1.168223927","rc":[{"trd":[[3.25,7.3]],"batb":[[0,2.98,21.88],[1,2.94,87.57],[2,2.78,3.66]],"batl":[[1,4.4,2.04],[2,5,2]],"ltp":3.25,"tv":10221.73,"id":8444055},{"trd":[[1.43,364.45]],"batb":[[0,1.43,1764.57],[1,1.42,3268.99],[2,1.4,2.53]],"batl":[[0,1.44,361.25],[2,1.46,3080.51]],"ltp":1.43,"tv":34997.97,"id":8257852}],"tv":45219.71}]}
{"op":"mcm","clk":"1011734571","pt":1580657523235,"mc":[{"id":"1.168223927","rc":[{"batb":[[0,2.94,88.45],[1,2.78,3.66],[2,2.66,3.84]],"batl":[[0,4.4,2.04],[1,5,2],[2,1000,0.02]],"ltp":3.25,"tv":10221.73,"id":8444055},{"batb":[[1,1.4,2.53],[2,1.38,494.03]],"batl":[[0,1.44,361.1],[1,1.45,74.96],[2,1.47,480.59]],"ltp":1.43,"tv":34997.97,"id":8257852}]}]}
{"op":"mcm","clk":"1011734803","pt":1580657524191,"mc":[{"id":"1.168223927","rc":[{"batl":[[0,1.44,359.61]],"ltp":1.43,"tv":34997.97,"id":8257852}]}]}
{"op":"mcm","clk":"1011734986","pt":1580657525014,"mc":[{"id":"1.168223927","rc":[{"batl":[[0,4.3,2.05],[1,4.4,2.04],[2,4.9,2]],"ltp":3.25,"tv":10221.73,"id":8444055},{"trd":[[1.44,208.05]],"batl":[[0,1.44,283.89]],"ltp":1.44,"tv":35149.42,"id":8257852}],"tv":45371.16}]}
{"op":"mcm","clk":"1011735044","pt":1580657525326,"mc":[{"id":"1.168223927","rc":[{"trd":[[1.43,440.17]],"batb":[[0,1.43,5.51]],"ltp":1.43,"tv":35225.14,"id":8257852}],"tv":45446.88}]}
{"op":"mcm","clk":"1011735327","pt":1580657526592,"mc":[{"id":"1.168223927","rc":[{"trd":[[3.25,8.76]],"batb":[[0,2.94,87.57]],"ltp":3.25,"tv":10223.19,"id":8444055},{"trd":[[1.44,211.34]],"batl":[[0,1.44,280.6]],"ltp":1.44,"tv":35228.44,"id":8257852}],"tv":45451.63}]}
{"op":"mcm","clk":"1011735626","pt":1580657528005,"mc":[{"id":"1.168223927","rc":[{"batl":[[0,1.44,278.07]],"ltp":1.44,"tv":35228.44,"id":8257852}]}]}
{"op":"mcm","clk":"1011735714","pt":1580657528421,"mc":[{"id":"1.168223927","rc":[{"trd":[[1.43,440.61]],"batb":[[0,1.43,5.29]],"ltp":1.43,"tv":35228.87,"id":8257852}],"tv":45452.07}]}
{"op":"mcm","clk":"1011736153","pt":1580657530316,"mc":[{"id":"1.168223927","rc":[{"trd":[[1.44,211.82]],"batl":[[0,1.44,277.35]],"ltp":1.44,"tv":35229.36,"id":8257852}],"tv":45452.55}]}
{"op":"mcm","clk":"1011736510","pt":1580657531916,"mc":[{"id":"1.168223927","rc":[{"trd":[[1.43,451.19]],"batb":[[0,1.4,2.53],[1,1.38,494.03],[2,1.36,510.84]],"batl":[[0,1.43,12.39],[1,1.44,277.35],[2,1.45,74.96]],"ltp":1.43,"tv":35239.94,"id":8257852}],"tv":45463.14}]}
{"op":"mcm","clk":"1011736749","pt":1580657533119,"mc":[{"id":"1.168223927","rc":[{"trd":[[3.25,103.39],[3.3,27.23]],"ltp":3.25,"tv":10323.19,"id":8444055},{"trd":[[1.43,463.58],[1.44,425.41]],"batl":[[0,1.44,63.77],[1,1.45,74.96],[2,1.47,480.59]],"ltp":1.44,"tv":35465.92,"id":8257852}],"tv":45789.11}]}
{"op":"mcm","clk":"1011736857","pt":1580657533501,"mc":[{"id":"1.168223927","rc":[{"batl":[[0,1.42,122],[1,1.44,63.77],[2,1.45,74.96]],"ltp":1.44,"tv":35465.92,"id":8257852}]}]}
{"op":"mcm","clk":"1011737451","pt":1580657536249,"mc":[{"id":"1.168223927","rc":[{"trd":[[1.42,43.51]],"batl":[[0,1.44,63.77],[1,1.45,74.96],[2,1.47,480.59]],"ltp":1.42,"tv":35509.42,"id":8257852}],"tv":45832.62}]}
{"op":"mcm","clk":"1011737764","pt":1580657537722,"mc":[{"id":"1.168223927","rc":[{"batb":[[0,2.94,88.45]],"ltp":3.25,"tv":10323.19,"id":8444055},{"batl":[[0,1.44,64],[1,1.54,683.19],[2,1.55,455.08]],"ltp":1.42,"tv":35509.42,"id":8257852}]}]}
{"op":"mcm","clk":"1011738329","pt":1580657540247,"mc":[{"id":"1.168223927","rc":[{"trd":[[3.25,131.64],[3.3,27.33],[3.35,1.76]],"batb":[[0,2.94,87.57]],"batl":[[0,2.96,8.19],[1,2.98,2090.17],[2,3.05,1470.19]],"ltp":3.25,"tv":10353.3,"id":8444055},{"trd":[[1.43,463.81],[1.44,489.17]],"batb":[[0,1.5,3000],[1,1.4,2.53],[2,1.38,494.03]],"batl":[[0,1.54,3620.8],[1,1.55,455.08],[2,1.56,29.92]],"ltp":1.44,"tv":35573.43,"id":8257852}],"tv":45926.73}]}
{"op":"mcm","clk":"1011738573","pt":1580657541228,"mc":[{"id":"1.168223927","rc":[{"batl":[[1,3,2]],"ltp":3.25,"tv":10353.3,"id":8444055},{"batb":[[0,1.5,3432.53],[1,1.49,537.16],[2,1.48,333.38]],"ltp":1.44,"tv":35573.43,"id":8257852}]}]}
{"op":"mcm","clk":"1011739093","pt":1580657543634,"mc":[{"id":"1.168223927","rc":[{"batb":[[2,1.48,420.76]],"ltp":1.44,"tv":35573.43,"id":8257852}]}]}
{"op":"mcm","clk":"1011739888","pt":1580657547240,"mc":[{"id":"1.168223927","rc":[{"batl":[[0,1.54,4101.39],[2,1.56,527.32]],"ltp":1.44,"tv":35573.43,"id":8257852}]}]}
{"op":"mcm","clk":"1011740091","pt":1580657547933,"mc":[{"id":"1.168223927","rc":[{"batb":[[0,1.51,55.78],[1,1.5,3509.19],[2,1.49,537.16]],"batl":[[0,1.52,96.41],[1,1.53,63.53],[2,1.54,4164.31]],"ltp":1.44,"tv":35573.43,"id":8257852}]}]}
{"op":"mcm","clk":"1011740380","pt":1580657549223,"mc":[{"id":"1.168223927","rc":[{"trd":[[1.52,27.64]],"batl":[[0,1.52,96.14]],"ltp":1.52,"tv":35573.97,"id":8257852}],"tv":45927.27}]}
{"op":"mcm","clk":"1011740509","pt":1580657549835,"mc":[{"id":"1.168223927","rc":[{"trd":[[1.52,28.75]],"batl":[[0,1.52,95.59]],"ltp":1.52,"tv":35575.08,"id":8257852}],"tv":45928.38}]}
{"op":"mcm","clk":"1011740748","pt":1580657550924,"mc":[{"id":"1.168223927","rc":[{"trd":[[1.51,255.02]],"batb":[[0,1.51,53.92]],"ltp":1.51,"tv":35578.79,"id":8257852}],"tv":45932.09}]}
{"op":"mcm","clk":"1011740955","pt":1580657551955,"mc":[{"id":"1.168223927","rc":[{"trd":[[1.51,256.05]],"batb":[[0,1.51,53.41]],"ltp":1.51,"tv":35579.81,"id":8257852}],"tv":45933.11}]}
{"op":"mcm","clk":"1011741145","pt":1580657552722,"mc":[{"id":"1.168223927","rc":[{"batb":[[1,1.5,3432.53]],"batl":[[2,1.54,4101.39]],"ltp":1.51,"tv":35579.81,"id":8257852}]}]}
{"op":"mcm","clk":"1011741584","pt":1580657554622,"mc":[{"id":"1.168223927","rc":[{"trd":[[1.51,256.35],[1.52,30.3]],"batb":[[0,1.51,53.26]],"batl":[[0,1.52,94.82]],"ltp":1.52,"tv":35581.66,"id":8257852}],"tv":45934.96}]}
{"op":"mcm","clk":"1011742103","pt":1580657556864,"mc":[{"id":"1.168223927","rc":[{"trd":[[2.96,16.38]],"batb":[[0,2.96,91.81],[1,2.94,87.57],[2,2.78,3.66]],"batl":[[0,3,2],[1,3.05,1470.19],[2,4.3,2.05]],"ltp":2.96,"tv":10369.68,"id":8444055}],"tv":45951.34}]}
{"op":"mcm","clk":"1011742354","pt":1580657558051,"mc":[{"id":"1.168223927","rc":[{"trd":[[1.52,30.74]],"batl":[[0,1.52,94.6]],"ltp":1.52,"tv":35582.1,"id":8257852}],"tv":45951.78}]}
{"op":"mcm","clk":"1011742825","pt":1580657560230,"mc":[{"id":"1.168223927","rc":[{"trd":[[1.51,258.05]],"batb":[[0,1.51,52.41]],"ltp":1.51,"tv":35583.8,"id":8257852}],"tv":45953.48}]}
{"op":"mcm","clk":"1011743023","pt":1580657561162,"mc":[{"id":"1.168223927","rc":[{"batb":[[0,2.94,87.57],[1,2.56,126.28],[2,2.48,4.26]],"batl":[[0,4.6,2.01],[1,4.9,2],[2,5,2]],"ltp":2.96,"tv":10369.68,"id":8444055},{"trd":[[1.51,260.14]],"batb":[[0,1.51,51.37],[1,1.5,3000],[2,1.48,420.76]],"batl":[[2,1.54,3402.67]],"ltp":1.51,"tv":35585.89,"id":8257852}],"tv":45955.57}]}
{"op":"mcm","clk":"1011743151","pt":1580657561750,"mc":[{"id":"1.168223927","rc":[{"batb":[[0,2.56,126.28],[1,2.48,4.26],[2,2.38,4.67]],"ltp":2.96,"tv":10369.68,"id":8444055},{"trd":[[1.51,262.37]],"batb":[[0,1.51,50.25],[1,1.48,87.38],[2,1.46,494.03]],"batl":[[2,1.54,480.59]],"ltp":1.51,"tv":35588.12,"id":8257852}],"tv":45957.8}]}
{"op":"mcm","clk":"1011743438","pt":1580657563041,"mc":[{"id":"1.168223927","rc":[{"batb":[[1,1.46,494.03],[2,1.44,510.84]],"ltp":1.51,"tv":35588.12,"id":8257852}]}]}
{"op":"mcm","clk":"1011743660","pt":1580657564171,"mc":[{"id":"1.168223927","rc":[{"trd":[[1.51,273.85],[1.52,40.66]],"batb":[[0,1.51,44.51]],"batl":[[0,1.52,89.64]],"ltp":1.52,"tv":35609.52,"id":8257852}],"tv":45979.2}]}
{"op":"mcm","clk":"1011743853","pt":1580657565147,"mc":[{"id":"1.168223927","rc":[{"trd":[[2.98,27.62]],"batb":[[0,2.98,69.25],[1,2.56,126.28],[2,2.48,4.26]],"ltp":2.98,"tv":10392.24,"id":8444055},{"trd":[[1.51,318.36]],"batb":[[0,1.46,494.03],[1,1.44,510.84],[2,1.43,4]],"batl":[[0,1.52,90.04]],"ltp":1.51,"tv":35654.03,"id":8257852}],"tv":46046.27}]}
{"op":"mcm","clk":"1011744066","pt":1580657566155,"mc":[{"id":"1.168223927","rc":[{"batb":[[0,2.56,126.28],[1,2.48,4.26],[2,2.38,4.67]],"ltp":2.98,"tv":10392.24,"id":8444055}]}]}
{"op":"mcm","clk":"1011744459","pt":1580657568061,"mc":[{"id":"1.168223927","rc":[{"batl":[[0,1.52,89.84]],"ltp":1.51,"tv":35654.03,"id":8257852}]}]}
{"op":"mcm","clk":"1011744693","pt":1580657569087,"mc":[{"id":"1.168223927","rc":[{"batl":[[0,1.51,1000.2],[1,1.52,89.64],[2,1.53,63.53]],"ltp":1.51,"tv":35654.03,"id":8257852}]}]}
{"op":"mcm","clk":"1011744859","pt":1580657569986,"mc":[{"id":"1.168223927","rc":[{"batl":[[1,1.54,480.59],[2,1.56,497.4]],"ltp":1.51,"tv":35654.03,"id":8257852}]}]}
{"op":"mcm","clk":"1011745280","pt":1580657571777,"mc":[{"id":"1.168223927","rc":[{"batb":[[1,2.38,4.67],[2,1.8,76.16]],"ltp":2.98,"tv":10392.24,"id":8444055},{"batl":[[1,1.67,359.33],[2,1.69,671.9]],"ltp":1.51,"tv":35654.03,"id":8257852}]}]}
{"op":"mcm","clk":"1011745791","pt":1580657574127,"mc":[{"id":"1.168223927","rc":[{"batb":[[1,2.4,482.84],[2,2.38,4.67]],"batl":[[0,2.6,760.33],[1,2.62,2356],[2,2.76,5.29]],"ltp":2.98,"tv":10392.24,"id":8444055},{"trd":[[1.51,2318.76]],"batb":[[0,1.62,1777.58],[1,1.46,494.03],[2,1.44,510.84]],"batl":[[0,1.66,17.91],[1,1.67,3053.94]],"ltp":1.51,"tv":37654.43,"id":8257852}],"tv":48046.67}]}
{"op":"mcm","clk":"1011746043","pt":1580657575270,"mc":[{"id":"1.168223927","rc":[{"batl":[[0,2.6,762.34],[1,3.05,2327.45],[2,4.6,2.01]],"ltp":2.98,"tv":10392.24,"id":8444055},{"batb":[[0,1.63,9.42],[1,1.62,2463.28],[2,1.61,398.24]],"ltp":1.51,"tv":37654.43,"id":8257852}]}]}
{"op":"mcm","clk":"1011746275","pt":1580657576267,"mc":[{"id":"1.168223927","rc":[{"batl":[[1,2.72,37.86],[2,3.05,2327.45]],"ltp":2.98,"tv":10392.24,"id":8444055}]}]}
{"op":"mcm","clk":"1011746491","pt":1580657577180,"mc":[{"id":"1.168223927","rc":[{"batl":[[1,3.05,2327.45],[2,4.6,2.01]],"ltp":2.98,"tv":10392.24,"id":8444055}]}]}
{"op":"mcm","clk":"1011746735","pt":1580657578167,"mc":[{"id":"1.168223927","rc":[{"batl":[[1,2.72,24.37],[2,3.05,2327.45]],"ltp":2.98,"tv":10392.24,"id":8444055}]}]}
{"op":"mcm","clk":"1011747132","pt":1580657579890,"mc":[{"id":"1.168223927","rc":[{"trd":[[1.62,2116.97],[1.63,2818.25]],"batb":[[0,1.62,2462.87],[1,1.61,398.24],[2,1.6,245.8]],"ltp":1.62,"tv":37674.09,"id":8257852}],"tv":48066.33}]}
{"op":"mcm","clk":"1011747428","pt":1580657581261,"mc":[{"id":"1.168223927","rc":[{"batl":[[0,1.65,133.62],[1,1.66,17.91],[2,1.67,3053.94]],"ltp":1.62,"tv":37674.09,"id":8257852}]}]}
{"op":"mcm","clk":"1011747633","pt":1580657582184,"mc":[{"id":"1.168223927","rc":[{"batb":[[0,1.64,67.19],[1,1.63,68.46],[2,1.62,2462.87]],"batl":[[0,1.65,190.64],[1,1.66,74.76]],"ltp":1.62,"tv":37674.09,"id":8257852}]}]}
{"op":"mcm","clk":"1011747750","pt":1580657582671,"mc":[{"id":"1.168223927","rc":[{"trd":[[1.64,2034.24]],"batb":[[0,1.64,37.95]],"ltp":1.64,"tv":37732.57,"id":8257852}],"tv":48124.81}]}
{"op":"mcm","clk":"1011748091","pt":1580657584187,"mc":[{"id":"1.168223927","rc":[{"trd":[[1.64,2110.14]],"batb":[[0,1.63,68.46],[1,1.62,2462.87],[2,1.61,398.24]],"batl":[[0,1.64,118.3],[1,1.65,344.49],[2,1.66,226.28]],"ltp":1.64,"tv":37808.47,"id":8257852}],"tv":48200.71}]}
{"op":"mcm","clk":"1011748307","pt":1580657585056,"mc":[{"id":"1.168223927","rc":[{"trd":[[2.56,15.63]],"batb":[[0,2.56,125.76]],"ltp":2.56,"tv":10393.29,"id":8444055},{"trd":[[1.63,2819.99]],"batb":[[0,1.63,67.59]],"ltp":1.63,"tv":37810.21,"id":8257852}],"tv":48203.51}]}
{"op":"mcm","clk":"1011748709","pt":1580657586886,"mc":[{"id":"1.168223927","rc":[{"trd":[[1.63,2827.78],[1.64,2560.24]],"batb":[[0,1.63,63.7]],"batl":[[0,1.64,56.93],[1,1.65,210.87],[2,1.66,169.43]],"ltp":1.63,"tv":38268.09,"id":8257852}],"tv":48661.38}]}
{"op":"mcm","clk":"1011748889","pt":1580657587691,"mc":[{"id":"1.168223927","rc":[{"trd":[[1.64,2590.89]],"batl":[[0,1.64,41.6]],"ltp":1.64,"tv":38298.75,"id":8257852}],"tv":48692.04}]}
{"op":"mcm","clk":"1011749444","pt":1580657589960,"mc":[{"id":"1.168223927","rc":[{"trd":[[1.63,2829.53],[1.64,2594.41]],"batb":[[0,1.63,62.82]],"batl":[[0,1.64,39.84]],"ltp":1.63,"tv":38304.01,"id":8257852}],"tv":48697.3}]}
{"op":"mcm","clk":"1011749657","pt":1580657590912,"mc":[{"id":"1.168223927","rc":[{"trd":[[2.56,18.03]],"batb":[[0,2.56,124.56]],"ltp":2.56,"tv":10395.69,"id":8444055},{"trd":[[1.64,2595.4]],"batl":[[0,1.64,39.35]],"ltp":1.64,"tv":38305.0,"id":8257852}],"tv":48700.7}]}
{"op":"mcm","clk":"1011749918","pt":1580657592008,"mc":[{"id":"1.168223927","rc":[{"batb":[[1,2.38,4.67],[2,2.36,156.58]],"batl":[[0,2.6,2.01],[2,3.1,3.05]],"ltp":2.56,"tv":10395.69,"id":8444055},{"batl":[[2,1.66,151.52]],"ltp":1.64,"tv":38305.0,"id":8257852}]}]}
{"op":"mcm","clk":"1011750185","pt":1580657593195,"mc":[{"id":"1.168223927","rc":[{"trd":[[2.56,43.24]],"batb":[[0,2.36,156.58],[1,2.32,4.89],[2,2.26,4.71]],"batl":[[0,2.54,56.81],[1,3.15,2.9],[2,3.35,2.3]],"ltp":2.56,"tv":10420.9,"id":8444055},{"trd":[[1.64,2634.74]],"batb":[[1,1.59,494.03],[2,1.57,510.84]],"batl":[[0,1.65,210.87],[1,1.66,151.52],[2,1.69,480.59]],"ltp":1.64,"tv":38344.35,"id":8257852}],"tv":48765.25}]}
{"op":"mcm","clk":"1011750316","pt":1580657593675,"mc":[{"id":"1.168223927","rc":[{"trd":[[2.54,177.37]],"batl":[[0,2.54,56.53],[1,2.56,2.19],[2,3.15,2.9]],"ltp":2.54,"tv":10421.19,"id":8444055},{"trd":[[1.64,2635.19]],"ltp":1.64,"tv":38344.79,"id":8257852}],"tv":48765.99}]}
{"op":"mcm","clk":"1011750651","pt":1580657595204,"mc":[{"id":"1.168223927","rc":[{"trd":[[2.54,180.8]],"batl":[[0,2.54,53.1]],"ltp":2.54,"tv":10424.62,"id":8444055},{"trd":[[1.64,2640.5]],"ltp":1.64,"tv":38350.1,"id":8257852}],"tv":48774.72}]}
{"op":"mcm","clk":"1011750873","pt":1580657596219,"mc":[{"id":"1.168223927","rc":[{"trd":[[2.56,43.33]],"batl":[[0,2.56,19.78],[1,3.15,2.9],[2,3.35,2.3]],"ltp":2.56,"tv":10424.71,"id":8444055},{"trd":[[1.64,2640.64],[1.65,107.75]],"batl":[[0,1.65,192.15],[1,1.69,480.59],[2,1.71,497.4]],"ltp":1.64,"tv":38387.68,"id":8257852}],"tv":48812.39}]}
{"op":"mcm","clk":"1011751104","pt":1580657597117,"mc":[{"id":"1.168223927","rc":[{"trd":[[2.56,43.62]],"batl":[[0,2.56,19.5]],"ltp":2.56,"tv":10424.99,"id":8444055},{"trd":[[1.64,2641.08]],"batl":[[0,1.65,38.3]],"ltp":1.64,"tv":38388.13,"id":8257852}],"tv":48813.12}]}
{"op":"mcm","clk":"1011751335","pt":1580657598137,"mc":[{"id":"1.168223927","rc":[{"trd":[[2.56,82.63],[2.6,128.26]],"batb":[[0,2.6,10.76],[1,2.36,156.58],[2,2.32,4.89]],"batl":[[0,3.15,2.9],[1,3.35,2.3],[2,3.4,2.69]],"ltp":2.6,"tv":10503.73,"id":8444055},{"trd":[[1.63,2892.9]],"batb":[[0,1.59,494.03],[1,1.57,510.84],[2,1.49,504.28]],"batl":[[0,1.65,38.77]],"ltp":1.63,"tv":38451.5,"id":8257852}],"tv":48955.24}]}
{"op":"mcm","clk":"1011751592","pt":1580657599207,"mc":[{"id":"1.168223927","rc":[{"trd":[[2.6,132.26]],"batb":[[0,2.6,8.76]],"ltp":2.6,"tv":10507.73,"id":8444055},{"batl":[[0,1.69,481.06],[1,1.71,497.4],[2,1.75,26.94]],"ltp":1.63,"tv":38451.5,"id":8257852}],"tv":48959.24}]}
{"op":"mcm","clk":"1011751658","pt":1580657599539,"mc":[{"id":"1.168223927","rc":[{"batb":[[2,1.47,384.89]],"batl":[[0,1.75,27.41],[1,1.77,579.35],[2,1.78,1.77]],"ltp":1.63,"tv":38451.5,"id":8257852}]}]}
{"op":"mcm","clk":"1011752076","pt":1580657601211,"mc":[{"id":"1.168223927","rc":[{"trd":[[2.6,149.78]],"batb":[[0,2.36,156.58],[1,2.32,4.89],[2,2.26,4.71]],"batl":[[0,2.6,43.12],[1,3.15,2.9],[2,3.35,2.3]],"ltp":2.6,"tv":10525.25,"id":8444055},{"batl":[[0,1.63,5.48],[1,1.75,26.94],[2,1.77,579.35]],"ltp":1.63,"tv":38451.5,"id":8257852}],"tv":48976.76}]}
{"op":"mcm","clk":"1011752297","pt":1580657602180,"mc":[{"id":"1.168223927","rc":[{"batb":[[1,2.32,17.52]],"batl":[[0,2.4,983.49],[1,2.42,480.99],[2,2.6,43.12]],"ltp":2.6,"tv":10525.25,"id":8444055},{"trd":[[1.63,2903.87]],"batb":[[0,1.71,2626.1],[1,1.59,494.03],[2,1.57,510.84]],"batl":[[0,1.75,26.94],[1,1.77,3121.72],[2,1.78,1.77]],"ltp":1.63,"tv":38462.47,"id":8257852}],"tv":48987.72}]}
{"op":"mcm","clk":"1011752537","pt":1580657603168,"mc":[{"id":"1.168223927","rc":[{"batl":[[1,2.42,482.99]],"ltp":2.6,"tv":10525.25,"id":8444055},{"trd":[[1.71,798.58]],"batb":[[0,1.71,3105.45],[1,1.69,866.87],[2,1.59,494.03]],"ltp":1.71,"tv":38463.07,"id":8257852}],"tv":48988.32}]}
{"op":"mcm","clk":"1011752802","pt":1580657604182,"mc":[{"id":"1.168223927","rc":[{"batl":[[2,2.6,51.53]],"ltp":2.6,"tv":10525.25,"id":8444055},{"trd":[[1.71,799.38]],"batb":[[0,1.71,3105.05]],"ltp":1.71,"tv":38463.87,"id":8257852}],"tv":48989.12}]}
{"op":"mcm","clk":"1011752998","pt":1580657605106,"mc":[{"id":"1.168223927","rc":[{"batl":[[2,2.52,4.54]],"ltp":2.6,"tv":10525.25,"id":8444055},{"batb":[[2,1.63,57.02]],"ltp":1.71,"tv":38463.87,"id":8257852}]}]}
{"op":"mcm","clk":"1011753236","pt":1580657606107,"mc":[{"id":"1.168223927","rc":[{"batl":[[2,2.54,26.89]],"ltp":2.6,"tv":10525.25,"id":8444055},{"batb":[[2,1.66,63.01]],"batl":[[0,1.73,136.99],[1,1.74,135.14],[2,1.75,26.94]],"ltp":1.71,"tv":38463.87,"id":8257852}]}]}
{"op":"mcm","clk":"1011753469","pt":1580657607013,"mc":[{"id":"1.168223927","rc":[{"batl":[[2,1.75,160.27]],"ltp":1.71,"tv":38463.87,"id":8257852}]}]}
{"op":"mcm","clk":"1011753699","pt":1580657608024,"mc":[{"id":"1.168223927","rc":[{"trd":[[1.71,823.04]],"batb":[[0,1.71,3093.22]],"batl":[[1,1.75,160.27],[2,1.76,131.58]],"ltp":1.71,"tv":38487.53,"id":8257852}],"tv":49012.78}]}
{"op":"mcm","clk":"1011753959","pt":1580657609213,"mc":[{"id":"1.168223927","rc":[{"trd":[[1.71,829.42]],"batb":[[0,1.72,76.52],[1,1.71,3090.03],[2,1.69,866.87]],"batl":[[0,1.73,277.42],[2,1.77,3121.72]],"ltp":1.71,"tv":38493.91,"id":8257852}],"tv":49019.16}]}
{"op":"mcm","clk":"1011754083","pt":1580657609804,"mc":[{"id":"1.168223927","rc":[{"batb":[[2,2.28,4.16]],"ltp":2.6,"tv":10525.25,"id":8444055},{"batb":[[2,1.7,79.33]],"batl":[[1,1.74,70.41],[2,1.75,160.27]],"ltp":1.71,"tv":38493.91,"id":8257852}]}]}
{"op":"mcm","clk":"1011754278","pt":1580657610634,"mc":[{"id":"1.168223927","rc":[{"trd":[[1.73,687.28]],"batl":[[0,1.73,251.48]],"ltp":1.73,"tv":38545.79,"id":8257852}],"tv":49071.05}]}
