{"op":"mcm","clk":"1004963113","pt":1580585272153,"mc":[{"id":"1.168224423","marketDefinition":{"bspMarket":false,"turnInPlayEnabled":true,"persistenceEnabled":true,"marketBaseRate":5.0,"eventId":"29681737","eventTypeId":"2","numberOfWinners":1,"bettingType":"ODDS","marketType":"MATCH_ODDS","marketTime":"2020-02-02T09:30:00.000Z","suspendTime":"2020-02-02T09:30:00.000Z","bspReconciled":false,"complete":true,"inPlay":false,"crossMatching":false,"runnersVoidable":false,"numberOfActiveRunners":2,"betDelay":0,"status":"OPEN","runners":[{"status":"ACTIVE","sortPriority":1,"id":8260126,"name":"Guillermo Garcia-Lopez"},{"status":"ACTIVE","sortPriority":2,"id":4486603,"name":"Dustin Brown"}],"regulators":["MR_INT"],"countryCode":"FR","discountAllowed":false,"timezone":"UTC","openDate":"2020-02-02T09:30:00.000Z","version":3147098412,"name":"Match Odds","eventName":"Garcia-Lopez v Brown"},"rc":[{"batb":[[0,1.05,152.2],[1,1.04,168.86],[2,1.03,190.07]],"ltp":0.0,"tv":0.0,"id":8260126},{"batb":[[0,1.05,152.2],[1,1.04,168.86],[2,1.03,190.07]],"ltp":0.0,"tv":0.0,"id":4486603}]}]}
{"op":"mcm","clk":"1004963376","pt":1580585273491,"mc":[{"id":"1.168224423","marketDefinition":{"bspMarket":false,"turnInPlayEnabled":true,"persistenceEnabled":true,"marketBaseRate":5.0,"eventId":"29681737","eventTypeId":"2","numberOfWinners":1,"bettingType":"ODDS","marketType":"MATCH_ODDS","marketTime":"2020-02-02T09:30:00.000Z","suspendTime":"2020-02-02T09:30:00.000Z","bspReconciled":false,"complete":true,"inPlay":false,"crossMatching":false,"runnersVoidable":false,"numberOfActiveRunners":2,"betDelay":0,"status":"OPEN","runners":[{"status":"ACTIVE","sortPriority":1,"id":8260126,"name":"Guillermo Garcia-Lopez"},{"status":"ACTIVE","sortPriority":2,"id":4486603,"name":"Dustin Brown"}],"regulators":["MR_INT"],"countryCode":"FR","discountAllowed":false,"timezone":"UTC","openDate":"2020-02-02T09:30:00.000Z","version":3147098412,"name":"Match Odds","eventName":"Garcia-Lopez v Brown"}}]}
{"op":"mcm","clk":"1004963561","pt":1580585274501,"mc":[{"id":"1.168224423","marketDefinition":{"bspMarket":false,"turnInPlayEnabled":true,"persistenceEnabled":true,"marketBaseRate":5.0,"eventId":"29681737","eventTypeId":"2","numberOfWinners":1,"bettingType":"ODDS","marketType":"MATCH_ODDS","marketTime":"2020-02-02T09:30:00.000Z","suspendTime":"2020-02-02T09:30:00.000Z","bspReconciled":false,"complete":true,"inPlay":false,"crossMatching":false,"runnersVoidable":false,"numberOfActiveRunners":2,"betDelay":0,"status":"OPEN","runners":[{"status":"ACTIVE","sortPriority":1,"id":8260126,"name":"Guillermo Garcia-Lopez"},{"status":"ACTIVE","sortPriority":2,"id":4486603,"name":"Dustin Brown"}],"regulators":["MR_INT"],"countryCode":"FR","discountAllowed":true,"timezone":"UTC","openDate":"2020-02-02T09:30:00.000Z","version":3147098412,"name":"Match Odds","eventName":"Garcia-Lopez v Brown"}}]}
{"op":"mcm","clk":"1004974322","pt":1580585341280,"mc":[{"id":"1.168224423","marketDefinition":{"bspMarket":false,"turnInPlayEnabled":true,"persistenceEnabled":true,"marketBaseRate":5.0,"eventId":"29681737","eventTypeId":"2","numberOfWinners":1,"bettingType":"ODDS","marketType":"MATCH_ODDS","marketTime":"2020-02-02T09:30:00.000Z","suspendTime":"2020-02-02T09:30:00.000Z","bspReconciled":false,"complete":true,"inPlay":false,"crossMatching":true,"runnersVoidable":false,"numberOfActiveRunners":2,"betDelay":0,"status":"OPEN","runners":[{"status":"ACTIVE","sortPriority":1,"id":8260126,"name":"Guillermo Garcia-Lopez"},{"status":"ACTIVE","sortPriority":2,"id":4486603,"name":"Dustin Brown"}],"regulators":["MR_INT"],"countryCode":"FR","discountAllowed":true,"timezone":"UTC","openDate":"2020-02-02T09:30:00.000Z","version":3147098412,"name":"Match Odds","eventName":"Garcia-Lopez v Brown"}}]}
{"op":"mcm","clk":"1005007195","pt":1580585542320,"mc":[{"id":"1.168224423","rc":[{"batb":[[0,1.06,50.48],[1,1.05,152.2],[2,1.04,168.86]],"ltp":0.0,"tv":0.0,"id":8260126}]}]}
{"op":"mcm","clk":"1005007255","pt":1580585542699,"mc":[{"id":"1.168224423","rc":[{"batb":[[0,1.06,50.48],[1,1.05,152.2],[2,1.04,168.86]],"ltp":0.0,"tv":0.0,"id":4486603}]}]}
{"op":"mcm","clk":"1005060464","pt":1580585865180,"mc":[{"id":"1.168224423","rc":[{"batl":[[0,48,31.05]],"ltp":0.0,"tv":0.0,"id":8260126},{"batl":[[0,48,31.05]],"ltp":0.0,"tv":0.0,"id":4486603}]}]}
{"op":"mcm","clk":"1005380027","pt":1580587944375,"mc":[{"id":"1.168224423","rc":[{"batl":[[1,990,2.2]],"ltp":0.0,"tv":0.0,"id":8260126},{"batl":[[1,990,2.2]],"ltp":0.0,"tv":0.0,"id":4486603}]}]}
{"op":"mcm","clk":"1005827976","pt":1580591116606,"mc":[{"id":"1.168224423","rc":[{"batl":[[0,1.7,681.51],[1,48,31.05],[2,990,2.2]],"ltp":0.0,"tv":0.0,"id":8260126}]}]}
{"op":"mcm","clk":"1005829035","pt":1580591124316,"mc":[{"id":"1.168224423","rc":[{"batl":[[0,1.72,681.51]],"ltp":0.0,"tv":0.0,"id":8260126}]}]}
{"op":"mcm","clk":"1005912587","pt":1580591723367,"mc":[{"id":"1.168224423","rc":[{"trd":[[1.72,134.43]],"batl":[[0,1.72,614.3]],"ltp":1.72,"tv":134.42,"id":8260126}],"tv":134.42}]}
{"op":"mcm","clk":"1005913416","pt":1580591728738,"mc":[{"id":"1.168224423","rc":[{"batb":[[0,1.62,21],[1,1.06,50.48],[2,1.05,152.2]],"ltp":1.72,"tv":134.42,"id":8260126}]}]}
{"op":"mcm","clk":"1005918796","pt":1580591766300,"mc":[{"id":"1.168224423","rc":[{"trd":[[1.72,176.44]],"batl":[[0,1.72,593.29]],"ltp":1.72,"tv":176.43,"id":8260126}],"tv":176.43}]}
{"op":"mcm","clk":"1005923415","pt":1580591798617,"mc":[{"id":"1.168224423","rc":[{"trd":[[1.72,216.77]],"batl":[[0,1.72,573.13]],"ltp":1.72,"tv":216.76,"id":8260126}],"tv":216.76}]}
{"op":"mcm","clk":"1005924845","pt":1580591809547,"mc":[{"id":"1.168224423","rc":[{"trd":[[1.72,248.69]],"batl":[[0,1.72,557.16]],"ltp":1.72,"tv":248.69,"id":8260126}],"tv":248.69}]}
{"op":"mcm","clk":"1005926767","pt":1580591823300,"mc":[{"id":"1.168224423","rc":[{"trd":[[1.72,285.66]],"batl":[[0,1.72,538.68]],"ltp":1.72,"tv":285.66,"id":8260126}],"tv":285.66}]}
{"op":"mcm","clk":"1005928414","pt":1580591834615,"mc":[{"id":"1.168224423","rc":[{"trd":[[1.72,315.91]],"batl":[[0,1.72,523.56]],"ltp":1.72,"tv":315.9,"id":8260126}],"tv":315.9}]}
{"op":"mcm","clk":"1005930992","pt":1580591853192,"mc":[{"id":"1.168224423","rc":[{"trd":[[1.72,356.24]],"batl":[[0,1.72,503.39]],"ltp":1.72,"tv":356.23,"id":8260126}],"tv":356.23}]}
{"op":"mcm","clk":"1005932966","pt":1580591867994,"mc":[{"id":"1.168224423","rc":[{"trd":[[1.72,383.12]],"batl":[[0,1.72,489.95]],"ltp":1.72,"tv":383.12,"id":8260126}],"tv":383.12}]}
{"op":"mcm","clk":"1005937685","pt":1580591901263,"mc":[{"id":"1.168224423","rc":[{"trd":[[1.72,399.93]],"batl":[[0,1.72,481.55]],"ltp":1.72,"tv":399.92,"id":8260126}],"tv":399.92}]}
{"op":"mcm","clk":"1005940330","pt":1580591918776,"mc":[{"id":"1.168224423","rc":[{"trd":[[1.72,440.26]],"batl":[[0,1.72,461.38]],"ltp":1.72,"tv":440.25,"id":8260126}],"tv":440.25}]}
{"op":"mcm","clk":"1005942543","pt":1580591934615,"mc":[{"id":"1.168224423","rc":[{"trd":[[1.72,453.7]],"batl":[[0,1.72,454.66]],"ltp":1.72,"tv":453.7,"id":8260126}],"tv":453.7}]}
{"op":"mcm","clk":"1005970446","pt":1580592141152,"mc":[{"id":"1.168224423","rc":[{"trd":[[1.72,500.22]],"batl":[[0,1.72,431.4]],"ltp":1.72,"tv":500.21,"id":8260126}],"tv":500.21}]}
{"op":"mcm","clk":"1005983700","pt":1580592239119,"mc":[{"id":"1.168224423","rc":[{"trd":[[1.72,508.62]],"batl":[[0,1.72,427.2]],"ltp":1.72,"tv":508.61,"id":8260126}],"tv":508.61}]}
{"op":"mcm","clk":"1005985983","pt":1580592256019,"mc":[{"id":"1.168224423","rc":[{"trd":[[1.72,518.57]],"batl":[[0,1.72,422.22]],"ltp":1.72,"tv":518.56,"id":8260126}],"tv":518.56}]}
{"op":"mcm","clk":"1005988131","pt":1580592272079,"mc":[{"id":"1.168224423","rc":[{"trd":[[1.72,558.9]],"batl":[[0,1.72,402.06]],"ltp":1.72,"tv":558.89,"id":8260126}],"tv":558.89}]}
{"op":"mcm","clk":"1005993998","pt":1580592315253,"mc":[{"id":"1.168224423","rc":[{"trd":[[1.72,570.8]],"batl":[[0,1.72,396.11]],"ltp":1.72,"tv":570.79,"id":8260126}],"tv":570.79}]}
{"op":"mcm","clk":"1005999307","pt":1580592354092,"mc":[{"id":"1.168224423","rc":[{"trd":[[1.72,579.2]],"batl":[[0,1.72,391.91]],"ltp":1.72,"tv":579.2,"id":8260126}],"tv":579.2}]}
{"op":"mcm","clk":"1006001716","pt":1580592372197,"mc":[{"id":"1.168224423","rc":[{"trd":[[1.72,619.53]],"batl":[[0,1.72,371.74]],"ltp":1.72,"tv":619.53,"id":8260126}],"tv":619.53}]}
{"op":"mcm","clk":"1006002762","pt":1580592379094,"mc":[{"id":"1.168224423","rc":[{"trd":[[1.72,649.78]],"batl":[[0,1.72,356.62]],"ltp":1.72,"tv":649.77,"id":8260126}],"tv":649.77}]}
{"op":"mcm","clk":"1006007938","pt":1580592416714,"mc":[{"id":"1.168224423","rc":[{"trd":[[1.72,730.44]],"batl":[[0,1.72,316.29]],"ltp":1.72,"tv":730.43,"id":8260126}],"tv":730.43}]}
{"op":"mcm","clk":"1006014829","pt":1580592472200,"mc":[{"id":"1.168224423","rc":[{"trd":[[1.72,773.45]],"batl":[[0,1.72,294.78]],"ltp":1.72,"tv":773.45,"id":8260126}],"tv":773.45}]}
{"op":"mcm","clk":"1006026598","pt":1580592573223,"mc":[{"id":"1.168224423","rc":[{"trd":[[1.72,781.85]],"batl":[[0,1.72,290.58]],"ltp":1.72,"tv":781.85,"id":8260126}],"tv":781.85}]}
{"op":"mcm","clk":"1006026859","pt":1580592575613,"mc":[{"id":"1.168224423","rc":[{"trd":[[1.72,849.07]],"batl":[[0,1.72,256.97]],"ltp":1.72,"tv":849.06,"id":8260126}],"tv":849.06}]}
{"op":"mcm","clk":"1006032105","pt":1580592619058,"mc":[{"id":"1.168224423","rc":[{"trd":[[1.72,917.96]],"batl":[[0,1.72,222.53]],"ltp":1.72,"tv":917.96,"id":8260126}],"tv":917.96}]}
{"op":"mcm","clk":"1006039159","pt":1580592673332,"mc":[{"id":"1.168224423","rc":[{"batl":[[0,1.71,8.4],[1,1.72,222.53],[2,48,31.05]],"ltp":1.72,"tv":917.96,"id":8260126}]}]}
{"op":"mcm","clk":"1006039277","pt":1580592674175,"mc":[{"id":"1.168224423","rc":[{"batb":[[0,1.62,34.56]],"ltp":1.72,"tv":917.96,"id":8260126},{"batb":[[0,2.4,6],[1,1.06,50.48],[2,1.05,152.2]],"batl":[[0,2.62,8.4],[1,48,31.05],[2,990,2.2]],"ltp":0.0,"tv":0.0,"id":4486603}]}]}
{"op":"mcm","clk":"1006040239","pt":1580592681473,"mc":[{"id":"1.168224423","rc":[{"trd":[[1.71,16.8]],"batb":[[0,1.71,58.81],[1,1.62,34.56],[2,1.06,50.48]],"batl":[[0,1.72,222.53],[1,48,31.05],[2,990,2.2]],"ltp":1.71,"tv":934.76,"id":8260126}],"tv":934.76}]}
{"op":"mcm","clk":"1006041255","pt":1580592689148,"mc":[{"id":"1.168224423","rc":[{"batb":[[0,1.68,58.81]],"ltp":1.71,"tv":934.76,"id":8260126}]}]}
{"op":"mcm","clk":"1006042008","pt":1580592694979,"mc":[{"id":"1.168224423","rc":[{"batb":[[1,1.62,13.55]],"ltp":1.71,"tv":934.76,"id":8260126}]}]}
{"op":"mcm","clk":"1006042321","pt":1580592697299,"mc":[{"id":"1.168224423","rc":[{"trd":[[2.4,12]],"batb":[[0,1.06,50.48],[1,1.05,152.2],[2,1.04,168.86]],"batl":[[0,2.4,9.12],[1,2.62,8.4],[2,48,31.05]],"ltp":2.4,"tv":11.99,"id":4486603}],"tv":946.76}]}
{"op":"mcm","clk":"1006043347","pt":1580592706374,"mc":[{"id":"1.168224423","rc":[{"batb":[[1,1.06,50.48],[2,1.05,152.2]],"ltp":1.71,"tv":934.76,"id":8260126},{"batl":[[0,2.4,21.11],[1,48,31.05],[2,990,2.2]],"ltp":2.4,"tv":11.99,"id":4486603}]}]}
{"op":"mcm","clk":"1006044786","pt":1580592718603,"mc":[{"id":"1.168224423","rc":[{"batb":[[0,1.71,58.81]],"ltp":1.71,"tv":934.76,"id":8260126}]}]}
{"op":"mcm","clk":"1006044960","pt":1580592720138,"mc":[{"id":"1.168224423","rc":[{"trd":[[1.72,1035.59]],"batb":[[0,1.06,50.48],[1,1.05,152.2],[2,1.04,168.86]],"batl":[[0,1.72,163.71]],"ltp":1.72,"tv":1052.39,"id":8260126}],"tv":1064.39}]}
{"op":"mcm","clk":"1006045341","pt":1580592723288,"mc":[{"id":"1.168224423","rc":[{"trd":[[1.72,1048.21]],"batl":[[0,1.72,151.09]],"ltp":1.72,"tv":1065.01,"id":8260126},{"trd":[[2.38,9.12]],"batl":[[0,2.4,11.99]],"ltp":2.38,"tv":21.12,"id":4486603}],"tv":1086.13}]}
{"op":"mcm","clk":"1006046021","pt":1580592728543,"mc":[{"id":"1.168224423","rc":[{"batb":[[0,1.14,9.24],[1,1.06,50.48],[2,1.05,152.2]],"ltp":1.72,"tv":1065.01,"id":8260126}]}]}
{"op":"mcm","clk":"1006046399","pt":1580592731684,"mc":[{"id":"1.168224423","rc":[{"trd":[[1.72,1051.57]],"batl":[[0,1.72,149.41]],"ltp":1.72,"tv":1068.37,"id":8260126}],"tv":1089.5}]}
{"op":"mcm","clk":"1006046752","pt":1580592734439,"mc":[{"id":"1.168224423","rc":[{"batl":[[1,3.95,1.68],[2,48,31.05]],"ltp":1.72,"tv":1068.37,"id":8260126}]}]}
{"op":"mcm","clk":"1006047385","pt":1580592739874,"mc":[{"id":"1.168224423","rc":[{"batb":[[0,1.14,9.24],[1,1.06,50.48],[2,1.05,152.2]],"ltp":2.38,"tv":21.12,"id":4486603}]}]}
{"op":"mcm","clk":"1006175829","pt":1580593797381,"mc":[{"id":"1.168224423","rc":[{"trd":[[1.71,27.34]],"ltp":1.71,"tv":1078.91,"id":8260126},{"trd":[[2.4,19.5]],"batl":[[0,2.4,4.49]],"ltp":2.4,"tv":28.62,"id":4486603}],"tv":1107.54}]}
{"op":"mcm","clk":"1006180690","pt":1580593845437,"mc":[{"id":"1.168224423","rc":[{"batb":[[0,1.4,77.46],[1,1.14,9.24],[2,1.06,50.48]],"ltp":1.71,"tv":1078.91,"id":8260126},{"batl":[[0,48,31.05],[1,990,2.2],[2,990,0]],"ltp":2.4,"tv":28.62,"id":4486603}]}]}
{"op":"mcm","clk":"1006180772","pt":1580593846122,"mc":[{"id":"1.168224423","rc":[{"batb":[[0,1.14,9.24],[1,1.06,50.48],[2,1.05,152.2]],"ltp":1.71,"tv":1078.91,"id":8260126}]}]}
{"op":"mcm","clk":"1006183675","pt":1580593875991,"mc":[{"id":"1.168224423","rc":[{"batb":[[0,1.14,69.26]],"ltp":1.71,"tv":1078.91,"id":8260126},{"batl":[[0,18,8.4],[1,48,31.05],[2,990,2.2]],"ltp":2.4,"tv":28.62,"id":4486603}]}]}
{"op":"mcm","clk":"1006186898","pt":1580593907379,"mc":[{"id":"1.168224423","rc":[{"batl":[[0,8.2,8.4]],"ltp":2.4,"tv":28.62,"id":4486603}]}]}
{"op":"mcm","clk":"1006187164","pt":1580593909519,"mc":[{"id":"1.168224423","rc":[{"batb":[[0,1.14,85.06]],"ltp":1.71,"tv":1078.91,"id":8260126}]}]}
{"op":"mcm","clk":"1006254175","pt":1580594631933,"mc":[{"id":"1.168224423","rc":[{"batb":[[0,1.15,6.24],[1,1.14,85.06],[2,1.06,50.48]],"ltp":1.71,"tv":1078.91,"id":8260126}]}]}
{"op":"mcm","clk":"1006255714","pt":1580594647870,"mc":[{"id":"1.168224423","rc":[{"batb":[[0,1.15,62.26],[1,1.14,25.05]],"ltp":1.71,"tv":1078.91,"id":8260126}]}]}
{"op":"mcm","clk":"1006258822","pt":1580594679387,"mc":[{"id":"1.168224423","rc":[{"batl":[[0,7.8,8.4]],"ltp":2.4,"tv":28.62,"id":4486603}]}]}
{"op":"mcm","clk":"1006258862","pt":1580594680010,"mc":[{"id":"1.168224423","rc":[{"batb":[[1,1.14,9.24]],"ltp":1.71,"tv":1078.91,"id":8260126}]}]}
{"op":"mcm","clk":"1006259017","pt":1580594681720,"mc":[{"id":"1.168224423","rc":[{"batb":[[0,1.15,77.93]],"ltp":1.71,"tv":1078.91,"id":8260126}]}]}
{"op":"mcm","clk":"1006326024","pt":1580595261699,"mc":[{"id":"1.168224423","rc":[{"batb":[[0,1.16,946.54],[1,1.15,77.93],[2,1.14,9.24]],"ltp":1.71,"tv":1078.91,"id":8260126}]}]}
{"op":"mcm","clk":"1006326242","pt":1580595263637,"mc":[{"id":"1.168224423","rc":[{"batb":[[0,1.17,15.4],[1,1.16,946.54],[2,1.15,62.26]],"ltp":1.71,"tv":1078.91,"id":8260126}]}]}
{"op":"mcm","clk":"1006326503","pt":1580595266011,"mc":[{"id":"1.168224423","rc":[{"batb":[[0,1.2,757.23],[1,1.17,15.4],[2,1.16,946.54]],"ltp":1.71,"tv":1078.91,"id":8260126}]}]}
{"op":"mcm","clk":"1006326666","pt":1580595267423,"mc":[{"id":"1.168224423","rc":[{"batl":[[0,48,31.05],[1,990,2.2],[2,990,0]],"ltp":2.4,"tv":28.62,"id":4486603}]}]}
{"op":"mcm","clk":"1006326775","pt":1580595268429,"mc":[{"id":"1.168224423","rc":[{"batb":[[0,1.21,40.01],[1,1.2,757.23]],"ltp":1.71,"tv":1078.91,"id":8260126},{"batl":[[0,5.9,16.8],[1,48,31.05],[2,990,2.2]],"ltp":2.4,"tv":28.62,"id":4486603}]}]}
{"op":"mcm","clk":"1006326991","pt":1580595270306,"mc":[{"id":"1.168224423","rc":[{"batb":[[0,1.4,378.62],[1,1.14,9.24],[2,1.06,50.48]],"ltp":2.4,"tv":28.62,"id":4486603}]}]}
{"op":"mcm","clk":"1006327170","pt":1580595272068,"mc":[{"id":"1.168224423","rc":[{"batb":[[0,1.21,797.24],[1,1.16,946.54],[2,1.15,6.24]],"ltp":1.71,"tv":1078.91,"id":8260126}]}]}
{"op":"mcm","clk":"1006327268","pt":1580595272751,"mc":[{"id":"1.168224423","rc":[{"batl":[[0,5.9,8.4]],"ltp":2.4,"tv":28.62,"id":4486603}]}]}
{"op":"mcm","clk":"1006327649","pt":1580595275907,"mc":[{"id":"1.168224423","rc":[{"batb":[[0,1.22,14.77],[1,1.21,797.24],[2,1.16,946.54]],"ltp":1.71,"tv":1078.91,"id":8260126}]}]}
{"op":"mcm","clk":"1006327909","pt":1580595278262,"mc":[{"id":"1.168224423","rc":[{"batb":[[0,1.22,772],[1,1.21,40.01]],"ltp":1.71,"tv":1078.91,"id":8260126}]}]}
{"op":"mcm","clk":"1006328213","pt":1580595281163,"mc":[{"id":"1.168224423","rc":[{"batl":[[0,5.5,8.4],[1,5.9,8.4],[2,48,31.05]],"ltp":2.4,"tv":28.62,"id":4486603}]}]}
{"op":"mcm","clk":"1006330255","pt":1580595299258,"mc":[{"id":"1.168224423","rc":[{"batl":[[1,48,31.05],[2,990,2.2]],"ltp":2.4,"tv":28.62,"id":4486603}]}]}
{"op":"mcm","clk":"1006330368","pt":1580595300275,"mc":[{"id":"1.168224423","rc":[{"batb":[[0,1.23,36.53],[1,1.22,772]],"ltp":1.71,"tv":1078.91,"id":8260126},{"batl":[[0,5.5,16.8]],"ltp":2.4,"tv":28.62,"id":4486603}]}]}
{"op":"mcm","clk":"1006330696","pt":1580595303158,"mc":[{"id":"1.168224423","rc":[{"batb":[[0,1.23,793.76],[1,1.22,14.77]],"ltp":1.71,"tv":1078.91,"id":8260126},{"batl":[[0,5.5,8.4]],"ltp":2.4,"tv":28.62,"id":4486603}]}]}
{"op":"mcm","clk":"1006330878","pt":1580595304756,"mc":[{"id":"1.168224423","rc":[{"batb":[[0,1.24,14.53],[1,1.23,793.76]],"ltp":1.71,"tv":1078.91,"id":8260126},{"batl":[[0,5.3,8.4],[1,5.5,8.4],[2,48,31.05]],"ltp":2.4,"tv":28.62,"id":4486603}]}]}
{"op":"mcm","clk":"1006332733","pt":1580595321114,"mc":[{"id":"1.168224423","rc":[{"batb":[[0,1.24,771.76],[1,1.23,36.53]],"ltp":1.71,"tv":1078.91,"id":8260126}]}]}
{"op":"mcm","clk":"1006332964","pt":1580595322906,"mc":[{"id":"1.168224423","rc":[{"batl":[[0,5.1,8.4]],"ltp":2.4,"tv":28.62,"id":4486603}]}]}
{"op":"mcm","clk":"1006333890","pt":1580595331437,"mc":[{"id":"1.168224423","rc":[{"batl":[[1,48,31.05],[2,990,2.2]],"ltp":2.4,"tv":28.62,"id":4486603}]}]}
{"op":"mcm","clk":"1006333997","pt":1580595332431,"mc":[{"id":"1.168224423","rc":[{"batb":[[0,1.25,33.61],[1,1.24,771.76]],"ltp":1.71,"tv":1078.91,"id":8260126},{"batl":[[0,5.1,16.8]],"ltp":2.4,"tv":28.62,"id":4486603}]}]}
{"op":"mcm","clk":"1006334169","pt":1580595334251,"mc":[{"id":"1.168224423","rc":[{"batb":[[0,1.25,790.84],[1,1.24,14.53]],"ltp":1.71,"tv":1078.91,"id":8260126}]}]}
{"op":"mcm","clk":"1006334381","pt":1580595336249,"mc":[{"id":"1.168224423","rc":[{"batb":[[0,1.26,14.3],[1,1.25,790.84]],"ltp":1.71,"tv":1078.91,"id":8260126},{"batl":[[0,4.9,8.4],[1,5.1,8.4],[2,48,31.05]],"ltp":2.4,"tv":28.62,"id":4486603}]}]}
{"op":"mcm","clk":"1006337618","pt":1580595364156,"mc":[{"id":"1.168224423","rc":[{"batb":[[1,1.25,757.23]],"ltp":1.71,"tv":1078.91,"id":8260126},{"batl":[[0,4.9,16.8],[1,48,31.05],[2,990,2.2]],"ltp":2.4,"tv":28.62,"id":4486603}]}]}
{"op":"mcm","clk":"1006337654","pt":1580595364467,"mc":[{"id":"1.168224423","rc":[{"batb":[[0,1.26,46.61]],"ltp":1.71,"tv":1078.91,"id":8260126}]}]}
{"op":"mcm","clk":"1006346240","pt":1580595430128,"mc":[{"id":"1.168224423","rc":[{"batb":[[0,1.26,803.85],[1,1.16,946.54],[2,1.15,6.24]],"ltp":1.71,"tv":1078.91,"id":8260126},{"batl":[[0,4.9,8.4]],"ltp":2.4,"tv":28.62,"id":4486603}]}]}
{"op":"mcm","clk":"1006346486","pt":1580595431915,"mc":[{"id":"1.168224423","rc":[{"batl":[[0,4.8,8.4],[1,4.9,8.4],[2,48,31.05]],"ltp":2.4,"tv":28.62,"id":4486603}]}]}
{"op":"mcm","clk":"1006349621","pt":1580595457834,"mc":[{"id":"1.168224423","rc":[{"batl":[[0,4.8,16.8],[1,48,31.05],[2,990,2.2]],"ltp":2.4,"tv":28.62,"id":4486603}]}]}
{"op":"mcm","clk":"1006357009","pt":1580595519767,"mc":[{"id":"1.168224423","rc":[{"batl":[[0,4.8,8.4]],"ltp":2.4,"tv":28.62,"id":4486603}]}]}
{"op":"mcm","clk":"1006382267","pt":1580595766058,"mc":[{"id":"1.168224423","rc":[{"batl":[[0,4.8,16.8]],"ltp":2.4,"tv":28.62,"id":4486603}]}]}
{"op":"mcm","clk":"1006483472","pt":1580596724945,"mc":[{"id":"1.168224423","rc":[{"batb":[[0,1.27,6.24],[1,1.26,803.85],[2,1.16,946.54]],"ltp":1.71,"tv":1078.91,"id":8260126}]}]}
{"op":"mcm","clk":"1006486519","pt":1580596755245,"mc":[{"id":"1.168224423","rc":[{"batb":[[1,1.26,771.53]],"ltp":1.71,"tv":1078.91,"id":8260126}]}]}
{"op":"mcm","clk":"1006486537","pt":1580596755456,"mc":[{"id":"1.168224423","rc":[{"batb":[[0,1.27,37.36]],"ltp":1.71,"tv":1078.91,"id":8260126}]}]}
{"op":"mcm","clk":"1006487487","pt":1580596765383,"mc":[{"id":"1.168224423","rc":[{"batb":[[1,1.26,14.3]],"ltp":1.71,"tv":1078.91,"id":8260126}]}]}
{"op":"mcm","clk":"1006487497","pt":1580596765488,"mc":[{"id":"1.168224423","rc":[{"batb":[[0,1.27,794.59]],"ltp":1.71,"tv":1078.91,"id":8260126}]}]}
{"op":"mcm","clk":"1006487625","pt":1580596766681,"mc":[{"id":"1.168224423","rc":[{"batb":[[0,1.28,14.07],[1,1.27,794.59]],"ltp":1.71,"tv":1078.91,"id":8260126}]}]}
{"op":"mcm","clk":"1006489626","pt":1580596787373,"mc":[{"id":"1.168224423","rc":[{"batb":[[1,1.27,763.47]],"ltp":1.71,"tv":1078.91,"id":8260126},{"batl":[[0,4.6,8.4],[1,4.8,8.4],[2,48,31.05]],"ltp":2.4,"tv":28.62,"id":4486603}]}]}
{"op":"mcm","clk":"1006489653","pt":1580596787682,"mc":[{"id":"1.168224423","rc":[{"batb":[[0,1.28,44.08]],"ltp":1.71,"tv":1078.91,"id":8260126}]}]}
{"op":"mcm","clk":"1006489726","pt":1580596788504,"mc":[{"id":"1.168224423","rc":[{"batl":[[1,48,31.05],[2,990,2.2]],"ltp":2.4,"tv":28.62,"id":4486603}]}]}
{"op":"mcm","clk":"1006541896","pt":1580597371391,"mc":[{"id":"1.168224423","rc":[{"batb":[[0,1.28,801.31],[1,1.27,6.24]],"ltp":1.71,"tv":1078.91,"id":8260126}]}]}
{"op":"mcm","clk":"1006542117","pt":1580597373797,"mc":[{"id":"1.168224423","rc":[{"batl":[[0,4.5,8.4],[1,4.6,8.4],[2,48,31.05]],"ltp":2.4,"tv":28.62,"id":4486603}]}]}
{"op":"mcm","clk":"1006542175","pt":1580597374474,"mc":[{"id":"1.168224423","rc":[{"batb":[[0,1.28,795.18]],"ltp":1.71,"tv":1078.91,"id":8260126}]}]}
{"op":"mcm","clk":"1006542320","pt":1580597375975,"mc":[{"id":"1.168224423","rc":[{"batb":[[0,1.28,422.69]],"ltp":1.71,"tv":1078.91,"id":8260126},{"batl":[[0,4.5,16.8],[1,48,31.05],[2,990,2.2]],"ltp":2.4,"tv":28.62,"id":4486603}]}]}
{"op":"mcm","clk":"1006693798","pt":1580599331599,"mc":[{"id":"1.168224423","rc":[{"batb":[[2,1.15,946.54]],"ltp":1.71,"tv":1078.91,"id":8260126}]}]}
{"op":"mcm","clk":"1006697717","pt":1580599374084,"mc":[{"id":"1.168224423","rc":[{"batb":[[0,1.29,6.24],[1,1.28,422.69]],"ltp":1.71,"tv":1078.91,"id":8260126}]}]}
{"op":"mcm","clk":"1006698881","pt":1580599386043,"mc":[{"id":"1.168224423","rc":[{"batb":[[0,1.29,35.21],[1,1.28,392.69]],"ltp":1.71,"tv":1078.91,"id":8260126}]}]}
{"op":"mcm","clk":"1006708937","pt":1580599491091,"mc":[{"id":"1.168224423","rc":[{"batb":[[0,1.29,413.83],[1,1.28,14.07]],"ltp":1.71,"tv":1078.91,"id":8260126}]}]}
{"op":"mcm","clk":"1006709041","pt":1580599492292,"mc":[{"id":"1.168224423","rc":[{"batb":[[0,1.3,13.85],[1,1.29,413.83]],"ltp":1.71,"tv":1078.91,"id":8260126}]}]}
{"op":"mcm","clk":"1006709250","pt":1580599494427,"mc":[{"id":"1.168224423","rc":[{"batb":[[0,1.3,392.47],[1,1.29,35.21]],"ltp":1.71,"tv":1078.91,"id":8260126}]}]}
{"op":"mcm","clk":"1006709402","pt":1580599495998,"mc":[{"id":"1.168224423","rc":[{"batl":[[0,4.3,8.4],[1,4.5,8.4],[2,48,31.05]],"ltp":2.4,"tv":28.62,"id":4486603}]}]}
{"op":"mcm","clk":"1006710695","pt":1580599510177,"mc":[{"id":"1.168224423","rc":[{"batl":[[1,48,31.05],[2,990,2.2]],"ltp":2.4,"tv":28.62,"id":4486603}]}]}
{"op":"mcm","clk":"1006710804","pt":1580599511171,"mc":[{"id":"1.168224423","rc":[{"batb":[[0,1.31,27.1],[1,1.3,392.47],[2,1.29,6.24]],"ltp":1.71,"tv":1078.91,"id":8260126},{"batl":[[0,4.3,16.8]],"ltp":2.4,"tv":28.62,"id":4486603}]}]}
{"op":"mcm","clk":"1006717633","pt":1580599593905,"mc":[{"id":"1.168224423","rc":[{"batb":[[1,1.3,13.85]],"ltp":1.71,"tv":1078.91,"id":8260126}]}]}
{"op":"mcm","clk":"1006717792","pt":1580599595431,"mc":[{"id":"1.168224423","rc":[{"batb":[[0,1.31,271.37],[1,1.29,6.24],[2,1.15,946.54]],"ltp":1.71,"tv":1078.91,"id":8260126},{"batl":[[0,4.3,8.4]],"ltp":2.4,"tv":28.62,"id":4486603}]}]}
{"op":"mcm","clk":"1006717934","pt":1580599597028,"mc":[{"id":"1.168224423","rc":[{"batb":[[0,1.32,13.64],[1,1.31,271.37],[2,1.29,6.24]],"ltp":1.71,"tv":1078.91,"id":8260126}]}]}
{"op":"mcm","clk":"1006718581","pt":1580599604363,"mc":[{"id":"1.168224423","rc":[{"batl":[[0,48,31.05],[1,990,2.2],[2,990,0]],"ltp":2.4,"tv":28.62,"id":4486603}]}]}
{"op":"mcm","clk":"1006718660","pt":1580599605286,"mc":[{"id":"1.168224423","rc":[{"batb":[[1,1.31,244.27]],"ltp":1.71,"tv":1078.91,"id":8260126},{"batl":[[0,4.2,8.4],[1,48,31.05],[2,990,2.2]],"ltp":2.4,"tv":28.62,"id":4486603}]}]}
{"op":"mcm","clk":"1006718685","pt":1580599605600,"mc":[{"id":"1.168224423","rc":[{"batb":[[0,1.32,39.9]],"ltp":1.71,"tv":1078.91,"id":8260126}]}]}
{"op":"mcm","clk":"1006879763","pt":1580601564767,"mc":[{"id":"1.168224423","rc":[{"batb":[[1,1.14,9.34]],"ltp":2.4,"tv":28.62,"id":4486603}]}]}
{"op":"mcm","clk":"1006883437","pt":1580601621618,"mc":[{"id":"1.168224423","rc":[{"batb":[[2,1.06,50.58]],"ltp":2.4,"tv":28.62,"id":4486603}]}]}
{"op":"mcm","clk":"1006909622","pt":1580602005918,"mc":[{"id":"1.168224423","rc":[{"batb":[[2,1.15,946.64]],"ltp":1.71,"tv":1078.91,"id":8260126}]}]}
{"op":"mcm","clk":"1007131190","pt":1580605498212,"mc":[{"id":"1.168224423","rc":[{"trd":[[1.32,5.07]],"batb":[[0,1.32,37.36]],"ltp":1.32,"tv":1083.98,"id":8260126}],"tv":1112.61}]}
{"op":"mcm","clk":"1007199559","pt":1580607020771,"mc":[{"id":"1.168224423","rc":[{"batb":[[0,1.32,37.37]],"ltp":1.32,"tv":1083.98,"id":8260126},{"batb":[[0,1.4,378.63]],"ltp":2.4,"tv":28.62,"id":4486603}]}]}
{"op":"mcm","clk":"1007465907","pt":1580615092988,"mc":[{"id":"1.168224423","rc":[{"batl":[[2,990,2.2]],"ltp":1.32,"tv":1083.98,"id":8260126},{"batl":[[1,990,2.2],[2,1000,0.02]],"ltp":2.4,"tv":28.62,"id":4486603}]}]}
{"op":"mcm","clk":"1007467685","pt":1580615161360,"mc":[{"id":"1.168224423","rc":[{"trd":[[1.72,1062.1]],"batl":[[0,1.72,138.88]],"ltp":1.72,"tv":1094.51,"id":8260126},{"trd":[[2.38,16.72]],"ltp":2.38,"tv":36.22,"id":4486603}],"tv":1130.73}]}
{"op":"mcm","clk":"1007472731","pt":1580615339115,"mc":[{"id":"1.168224423","rc":[{"batl":[[2,95,2.27]],"ltp":1.72,"tv":1094.51,"id":8260126},{"batl":[[1,95,2.27],[2,990,2.2]],"ltp":2.38,"tv":36.22,"id":4486603}]}]}
{"op":"mcm","clk":"1007492038","pt":1580615853916,"mc":[{"id":"1.168224423","rc":[{"batl":[[1,3.45,229.44],[2,3.95,1.68]],"ltp":1.72,"tv":1094.51,"id":8260126},{"batl":[[0,4.1,229.44],[1,4.2,8.4],[2,95,2.27]],"ltp":2.38,"tv":36.22,"id":4486603}]}]}
{"op":"mcm","clk":"1007492950","pt":1580615880075,"mc":[{"id":"1.168224423","rc":[{"batl":[[0,4,8.4],[1,4.1,229.44]],"ltp":2.38,"tv":36.22,"id":4486603}]}]}
{"op":"mcm","clk":"1007493922","pt":1580615911455,"mc":[{"id":"1.168224423","rc":[{"batb":[[0,1.32,11.12]],"ltp":1.72,"tv":1094.51,"id":8260126}]}]}
{"op":"mcm","clk":"1007493932","pt":1580615911762,"mc":[{"id":"1.168224423","rc":[{"batb":[[0,1.33,25.47],[1,1.32,11.11],[2,1.31,244.27]],"ltp":1.72,"tv":1094.51,"id":8260126}]}]}
{"op":"mcm","clk":"1007493987","pt":1580615913296,"mc":[{"id":"1.168224423","rc":[{"batl":[[0,4,237.84],[1,95,2.27],[2,990,2.2]],"ltp":2.38,"tv":36.22,"id":4486603}]}]}
{"op":"mcm","clk":"1007494014","pt":1580615914068,"mc":[{"id":"1.168224423","rc":[{"batb":[[0,1.34,10.96],[1,1.33,25.46]],"ltp":1.72,"tv":1094.51,"id":8260126},{"batl":[[0,3.95,8.4],[1,4,237.84],[2,95,2.27]],"ltp":2.38,"tv":36.22,"id":4486603}]}]}
{"op":"mcm","clk":"1007494326","pt":1580615923570,"mc":[{"id":"1.168224423","rc":[{"batl":[[0,3.95,237.84],[1,4,8.4]],"ltp":2.38,"tv":36.22,"id":4486603}]}]}
{"op":"mcm","clk":"1007495298","pt":1580615943387,"mc":[{"id":"1.168224423","rc":[{"batb":[[1,1.31,244.27],[2,1.15,946.64]],"ltp":1.72,"tv":1094.51,"id":8260126},{"batl":[[1,95,2.27],[2,990,2.2]],"ltp":2.38,"tv":36.22,"id":4486603}]}]}
{"op":"mcm","clk":"1007495371","pt":1580615944012,"mc":[{"id":"1.168224423","rc":[{"batb":[[0,1.34,35.67]],"ltp":1.72,"tv":1094.51,"id":8260126},{"batl":[[0,3.9,8.4],[1,3.95,237.84],[2,95,2.27]],"ltp":2.38,"tv":36.22,"id":4486603}]}]}
{"op":"mcm","clk":"1007520292","pt":1580616569218,"mc":[{"id":"1.168224423","rc":[{"batl":[[0,3,84.02],[1,3.9,8.4],[2,3.95,237.84]],"ltp":2.38,"tv":36.22,"id":4486603}]}]}
{"op":"mcm","clk":"1007520341","pt":1580616570816,"mc":[{"id":"1.168224423","rc":[{"batb":[[0,1.51,18.52],[1,1.34,24.72],[2,1.31,244.27]],"ltp":1.72,"tv":1094.51,"id":8260126},{"batl":[[2,3.95,229.44]],"ltp":2.38,"tv":36.22,"id":4486603}]}]}
{"op":"mcm","clk":"1007520558","pt":1580616579150,"mc":[{"id":"1.168224423","rc":[{"batb":[[0,1.5,84.02],[1,1.4,378.63],[2,1.14,9.34]],"ltp":2.38,"tv":36.22,"id":4486603}]}]}
{"op":"mcm","clk":"1007520975","pt":1580616595383,"mc":[{"id":"1.168224423","rc":[{"batb":[[1,1.31,244.28],[2,1.15,946.64]],"ltp":1.72,"tv":1094.51,"id":8260126},{"batl":[[0,2.98,8.4],[1,3,84.02]],"ltp":2.38,"tv":36.22,"id":4486603}]}]}
{"op":"mcm","clk":"1007520981","pt":1580616595588,"mc":[{"id":"1.168224423","rc":[{"batb":[[0,1.51,34.99]],"ltp":1.72,"tv":1094.51,"id":8260126}]}]}
{"op":"mcm","clk":"1007521889","pt":1580616626617,"mc":[{"id":"1.168224423","rc":[{"batl":[[0,3,84.02],[1,3.95,229.44],[2,95,2.27]],"ltp":2.38,"tv":36.22,"id":4486603}]}]}
{"op":"mcm","clk":"1007545322","pt":1580617367284,"mc":[{"id":"1.168224423","rc":[{"batl":[[0,2.98,8.4],[1,3,84.02],[2,3.95,229.44]],"ltp":2.38,"tv":36.22,"id":4486603}]}]}
{"op":"mcm","clk":"1007546277","pt":1580617406496,"mc":[{"id":"1.168224423","rc":[{"batb":[[0,1.51,41.84]],"ltp":1.72,"tv":1094.51,"id":8260126}]}]}
{"op":"mcm","clk":"1007591534","pt":1580618443717,"mc":[{"id":"1.168224423","rc":[{"batb":[[1,1.34,75.73],[2,1.31,244.27]],"ltp":1.72,"tv":1094.51,"id":8260126},{"batb":[[0,1.52,75.72],[1,1.5,84.02],[2,1.4,378.63]],"ltp":2.38,"tv":36.22,"id":4486603}]}]}
{"op":"mcm","clk":"1007609162","pt":1580618952200,"mc":[{"id":"1.168224423","rc":[{"batb":[[0,1.5,84.02],[1,1.4,378.63],[2,1.14,9.34]],"ltp":2.38,"tv":36.22,"id":4486603}]}]}
{"op":"mcm","clk":"1007609415","pt":1580618961419,"mc":[{"id":"1.168224423","rc":[{"batl":[[1,2.3,25.75],[2,3.45,229.44]],"ltp":1.72,"tv":1094.51,"id":8260126}]}]}
{"op":"mcm","clk":"1007619213","pt":1580619267639,"mc":[{"id":"1.168224423","rc":[{"batb":[[0,1.52,6.12],[1,1.51,41.84],[2,1.34,75.73]],"batl":[[0,1.71,4.12],[1,1.72,138.88],[2,2.3,25.75]],"ltp":1.72,"tv":1094.51,"id":8260126},{"batb":[[0,2.4,4.12],[1,1.5,84.02],[2,1.4,378.63]],"batl":[[0,2.96,3.12],[1,2.98,8.4],[2,3,84.02]],"ltp":2.38,"tv":36.22,"id":4486603}]}]}
{"op":"mcm","clk":"1007619778","pt":1580619284341,"mc":[{"id":"1.168224423","rc":[{"batb":[[1,1.51,25.36]],"ltp":1.72,"tv":1094.51,"id":8260126},{"batl":[[0,2.92,3.24],[1,2.96,3.12]],"ltp":2.38,"tv":36.22,"id":4486603}]}]}
{"op":"mcm","clk":"1007619793","pt":1580619284754,"mc":[{"id":"1.168224423","rc":[{"batb":[[0,1.52,22.28]],"ltp":1.72,"tv":1094.51,"id":8260126},{"batl":[[1,2.94,8.4],[2,2.96,3.12]],"ltp":2.38,"tv":36.22,"id":4486603}]}]}
{"op":"mcm","clk":"1007620816","pt":1580619316189,"mc":[{"id":"1.168224423","rc":[{"batl":[[0,2.92,11.64],[1,2.96,3.12],[2,3,84.02]],"ltp":2.38,"tv":36.22,"id":4486603}]}]}
{"op":"mcm","clk":"1007719829","pt":1580621526223,"mc":[{"id":"1.168224423","rc":[{"trd":[[1.52,35.37]],"batb":[[0,1.53,7.03],[1,1.52,4.59],[2,1.51,25.36]],"ltp":1.52,"tv":1129.87,"id":8260126}],"tv":1166.1}]}
{"op":"mcm","clk":"1007720831","pt":1580621543946,"mc":[{"id":"1.168224423","rc":[{"batl":[[0,2.92,3.24]],"ltp":2.38,"tv":36.22,"id":4486603}]}]}
{"op":"mcm","clk":"1007720945","pt":1580621545352,"mc":[{"id":"1.168224423","rc":[{"batb":[[1,1.51,25.36],[2,1.34,75.73]],"batl":[[0,1.71,12.52]],"ltp":1.52,"tv":1129.87,"id":8260126},{"batb":[[0,2.4,10.12]],"batl":[[0,2.88,3.13],[1,2.9,8.4],[2,2.92,3.24]],"ltp":2.38,"tv":36.22,"id":4486603}]}]}
{"op":"mcm","clk":"1007720961","pt":1580621545559,"mc":[{"id":"1.168224423","rc":[{"batb":[[0,1.53,22.88]],"ltp":1.52,"tv":1129.87,"id":8260126}]}]}
{"op":"mcm","clk":"1007722876","pt":1580621577206,"mc":[{"id":"1.168224423","rc":[{"batl":[[0,2.88,11.53],[1,2.92,3.24],[2,3,84.02]],"ltp":2.38,"tv":36.22,"id":4486603}]}]}
{"op":"mcm","clk":"1007723458","pt":1580621588595,"mc":[{"id":"1.168224423","rc":[{"batb":[[0,1.53,22.96]],"ltp":1.52,"tv":1129.87,"id":8260126}]}]}
{"op":"mcm","clk":"1007723805","pt":1580621595442,"mc":[{"id":"1.168224423","rc":[{"trd":[[2.4,23.5]],"batb":[[0,2.4,8.12]],"ltp":2.4,"tv":40.22,"id":4486603}],"tv":1170.1}]}
{"op":"mcm","clk":"1007730569","pt":1580621728730,"mc":[{"id":"1.168224423","rc":[{"batl":[[0,2.88,30.57]],"ltp":2.4,"tv":40.22,"id":4486603}]}]}
{"op":"mcm","clk":"1007730994","pt":1580621736974,"mc":[{"id":"1.168224423","rc":[{"batl":[[0,2.88,11.53]],"ltp":2.4,"tv":40.22,"id":4486603}]}]}
{"op":"mcm","clk":"1007731102","pt":1580621739248,"mc":[{"id":"1.168224423","rc":[{"batb":[[0,1.61,7.21],[1,1.53,15.93],[2,1.51,16.56]],"ltp":1.52,"tv":1129.87,"id":8260126},{"batb":[[0,2.4,11]],"batl":[[0,2.62,3.21],[1,2.64,17.93],[2,2.88,8.4]],"ltp":2.4,"tv":40.22,"id":4486603}]}]}
{"op":"mcm","clk":"1007731141","pt":1580621739965,"mc":[{"id":"1.168224423","rc":[{"batb":[[0,1.64,6.21],[1,1.61,7.21],[2,1.53,15.93]],"ltp":1.52,"tv":1129.87,"id":8260126},{"batb":[[0,2.42,5.21],[1,2.4,11],[2,1.5,84.02]],"batl":[[0,2.56,3.21],[1,2.58,18.25]],"ltp":2.4,"tv":40.22,"id":4486603}]}]}
{"op":"mcm","clk":"1007731221","pt":1580621741465,"mc":[{"id":"1.168224423","rc":[{"batl":[[1,2.88,8.4],[2,3,84.02]],"ltp":2.4,"tv":40.22,"id":4486603}]}]}
{"op":"mcm","clk":"1007732418","pt":1580621764200,"mc":[{"id":"1.168224423","rc":[{"batb":[[2,1.51,16.63]],"ltp":1.52,"tv":1129.87,"id":8260126},{"batl":[[0,2.58,3],[1,3,84.02],[2,3.9,229.44]],"ltp":2.4,"tv":40.22,"id":4486603}]}]}
{"op":"mcm","clk":"1007732486","pt":1580621765383,"mc":[{"id":"1.168224423","rc":[{"batb":[[0,1.64,19.34]],"ltp":1.52,"tv":1129.87,"id":8260126},{"batb":[[0,2.42,11.12],[1,2.4,5]],"batl":[[0,2.56,11.4],[1,2.58,3],[2,3,84.02]],"ltp":2.4,"tv":40.22,"id":4486603}]}]}
{"op":"mcm","clk":"1007734086","pt":1580621796375,"mc":[{"id":"1.168224423","rc":[{"batl":[[0,1.71,4.12]],"ltp":1.52,"tv":1129.87,"id":8260126}]}]}
{"op":"mcm","clk":"1007734138","pt":1580621797360,"mc":[{"id":"1.168224423","rc":[{"batb":[[0,1.64,6.21]],"ltp":1.52,"tv":1129.87,"id":8260126},{"batl":[[0,2.56,3]],"ltp":2.4,"tv":40.22,"id":4486603}]}]}
{"op":"mcm","clk":"1007734176","pt":1580621797976,"mc":[{"id":"1.168224423","rc":[{"batb":[[0,2.42,5.21]],"batl":[[0,2.58,3],[1,3,84.02],[2,3.9,229.44]],"ltp":2.4,"tv":40.22,"id":4486603}]}]}
{"op":"mcm","clk":"1007735650","pt":1580621826002,"mc":[{"id":"1.168224423","rc":[{"batb":[[2,1.51,16.56]],"ltp":1.52,"tv":1129.87,"id":8260126}]}]}
{"op":"mcm","clk":"1007739144","pt":1580621888289,"mc":[{"id":"1.168224423","rc":[{"batb":[[0,1.5,84.1],[1,1.4,378.63],[2,1.14,9.34]],"ltp":2.4,"tv":40.22,"id":4486603}]}]}
{"op":"mcm","clk":"1007739160","pt":1580621888599,"mc":[{"id":"1.168224423","rc":[{"batb":[[0,1.64,6.29]],"ltp":1.52,"tv":1129.87,"id":8260126}]}]}
{"op":"mcm","clk":"1007739248","pt":1580621890402,"mc":[{"id":"1.168224423","rc":[{"batb":[[0,1.51,15.2],[1,1.5,84.02],[2,1.4,378.63]],"ltp":2.4,"tv":40.22,"id":4486603}]}]}
{"op":"mcm","clk":"1007741117","pt":1580621931184,"mc":[{"id":"1.168224423","rc":[{"batb":[[0,2.42,5.25],[1,1.51,15.12],[2,1.5,84.02]],"ltp":2.4,"tv":40.22,"id":4486603}]}]}
{"op":"mcm","clk":"1007741131","pt":1580621931493,"mc":[{"id":"1.168224423","rc":[{"batb":[[0,1.51,15.2],[1,1.5,84.02],[2,1.4,378.63]],"ltp":2.4,"tv":40.22,"id":4486603}]}]}
{"op":"mcm","clk":"1007744970","pt":1580622013300,"mc":[{"id":"1.168224423","rc":[{"batb":[[0,2.42,5.37],[1,1.51,15.12],[2,1.5,84.02]],"ltp":2.4,"tv":40.22,"id":4486603}]}]}
{"op":"mcm","clk":"1007744982","pt":1580622013613,"mc":[{"id":"1.168224423","rc":[{"batb":[[0,1.51,15.2],[1,1.5,84.02],[2,1.4,378.63]],"ltp":2.4,"tv":40.22,"id":4486603}]}]}
{"op":"mcm","clk":"1007748186","pt":1580622076280,"mc":[{"id":"1.168224423","rc":[{"batb":[[0,2.42,5.38],[1,1.51,15.12],[2,1.5,84.02]],"ltp":2.4,"tv":40.22,"id":4486603}]}]}
{"op":"mcm","clk":"1007748203","pt":1580622076591,"mc":[{"id":"1.168224423","rc":[{"batb":[[0,1.51,15.2],[1,1.5,84.02],[2,1.4,378.63]],"ltp":2.4,"tv":40.22,"id":4486603}]}]}
{"op":"mcm","clk":"1007751993","pt":1580622158297,"mc":[{"id":"1.168224423","rc":[{"batb":[[0,2.42,5.18],[1,1.51,15.12],[2,1.5,84.02]],"ltp":2.4,"tv":40.22,"id":4486603}]}]}
{"op":"mcm","clk":"1007752005","pt":1580622158604,"mc":[{"id":"1.168224423","rc":[{"batb":[[0,1.51,15.2],[1,1.5,84.02],[2,1.4,378.63]],"ltp":2.4,"tv":40.22,"id":4486603}]}]}
{"op":"mcm","clk":"1007755104","pt":1580622221224,"mc":[{"id":"1.168224423","rc":[{"batb":[[0,2.42,5.19],[1,1.51,15.12],[2,1.5,84.02]],"ltp":2.4,"tv":40.22,"id":4486603}]}]}
{"op":"mcm","clk":"1007755122","pt":1580622221536,"mc":[{"id":"1.168224423","rc":[{"batb":[[0,1.51,15.2],[1,1.5,84.02],[2,1.4,378.63]],"ltp":2.4,"tv":40.22,"id":4486603}]}]}
{"op":"mcm","clk":"1007759170","pt":1580622303319,"mc":[{"id":"1.168224423","rc":[{"batb":[[0,2.42,5.31],[1,1.51,15.12],[2,1.5,84.02]],"ltp":2.4,"tv":40.22,"id":4486603}]}]}
{"op":"mcm","clk":"1007759193","pt":1580622303629,"mc":[{"id":"1.168224423","rc":[{"batb":[[0,1.51,15.2],[1,1.5,84.02],[2,1.4,378.63]],"ltp":2.4,"tv":40.22,"id":4486603}]}]}
{"op":"mcm","clk":"1007763084","pt":1580622378320,"mc":[{"id":"1.168224423","rc":[{"batb":[[2,1.51,9.71]],"ltp":1.52,"tv":1129.87,"id":8260126},{"batb":[[0,2.42,5.18],[1,1.51,15.12],[2,1.5,84.02]],"ltp":2.4,"tv":40.22,"id":4486603}]}]}
{"op":"mcm","clk":"1007763108","pt":1580622378632,"mc":[{"id":"1.168224423","rc":[{"batb":[[0,1.51,15.2],[1,1.5,84.02],[2,1.4,378.63]],"ltp":2.4,"tv":40.22,"id":4486603}]}]}
{"op":"mcm","clk":"1007767384","pt":1580622459455,"mc":[{"id":"1.168224423","rc":[{"batb":[[0,2.42,5.18],[1,1.51,15.12],[2,1.5,84.02]],"ltp":2.4,"tv":40.22,"id":4486603}]}]}
{"op":"mcm","clk":"1007767404","pt":1580622459761,"mc":[{"id":"1.168224423","rc":[{"batb":[[0,1.51,15.2],[1,1.5,84.02],[2,1.4,378.63]],"ltp":2.4,"tv":40.22,"id":4486603}]}]}
{"op":"mcm","clk":"1007770625","pt":1580622522375,"mc":[{"id":"1.168224423","rc":[{"batb":[[0,2.42,5.2],[1,1.51,15.12],[2,1.5,84.02]],"ltp":2.4,"tv":40.22,"id":4486603}]}]}
{"op":"mcm","clk":"1007770644","pt":1580622522636,"mc":[{"id":"1.168224423","rc":[{"batb":[[0,1.51,15.2],[1,1.5,84.02],[2,1.4,378.63]],"ltp":2.4,"tv":40.22,"id":4486603}]}]}
{"op":"mcm","clk":"1007771396","pt":1580622536375,"mc":[{"id":"1.168224423","rc":[{"batb":[[0,1.64,19.42]],"batl":[[0,1.71,12.52]],"ltp":1.52,"tv":1129.87,"id":8260126},{"batl":[[0,2.56,3.3],[1,2.58,3],[2,3,84.02]],"ltp":2.4,"tv":40.22,"id":4486603}]}]}
{"op":"mcm","clk":"1007774626","pt":1580622598372,"mc":[{"id":"1.168224423","rc":[{"batb":[[0,2.42,5.29],[1,1.51,15.12],[2,1.5,84.02]],"ltp":2.4,"tv":40.22,"id":4486603}]}]}
{"op":"mcm","clk":"1007774642","pt":1580622598680,"mc":[{"id":"1.168224423","rc":[{"batb":[[0,1.51,15.2],[1,1.5,84.02],[2,1.4,378.63]],"ltp":2.4,"tv":40.22,"id":4486603}]}]}
{"op":"mcm","clk":"1007780571","pt":1580622722160,"mc":[{"id":"1.168224423","rc":[{"batb":[[0,2.42,5.31],[1,1.51,15.12],[2,1.5,84.02]],"ltp":2.4,"tv":40.22,"id":4486603}]}]}
{"op":"mcm","clk":"1007780584","pt":1580622722467,"mc":[{"id":"1.168224423","rc":[{"batb":[[0,1.51,15.2],[1,1.5,84.02],[2,1.4,378.63]],"ltp":2.4,"tv":40.22,"id":4486603}]}]}
{"op":"mcm","clk":"1007781483","pt":1580622743391,"mc":[{"id":"1.168224423","rc":[{"batb":[[0,2.42,5.09],[1,1.51,15.12],[2,1.5,84.02]],"ltp":2.4,"tv":40.22,"id":4486603}]}]}
{"op":"mcm","clk":"1007781503","pt":1580622743698,"mc":[{"id":"1.168224423","rc":[{"batb":[[0,1.51,15.2],[1,1.5,84.02],[2,1.4,378.63]],"ltp":2.4,"tv":40.22,"id":4486603}]}]}
{"op":"mcm","clk":"1007784583","pt":1580622806339,"mc":[{"id":"1.168224423","rc":[{"batb":[[0,2.42,5.11],[1,1.51,15.12],[2,1.5,84.02]],"ltp":2.4,"tv":40.22,"id":4486603}]}]}
{"op":"mcm","clk":"1007784600","pt":1580622806649,"mc":[{"id":"1.168224423","rc":[{"batb":[[0,1.51,15.2],[1,1.5,84.02],[2,1.4,378.63]],"ltp":2.4,"tv":40.22,"id":4486603}]}]}
{"op":"mcm","clk":"1007786538","pt":1580622846272,"mc":[{"id":"1.168224423","rc":[{"batb":[[0,2.4,6.07],[1,1.51,15.12],[2,1.5,84.02]],"ltp":2.4,"tv":40.22,"id":4486603}]}]}
{"op":"mcm","clk":"1007786564","pt":1580622846785,"mc":[{"id":"1.168224423","rc":[{"batl":[[0,2.56,11.7]],"ltp":2.4,"tv":40.22,"id":4486603}]}]}
{"op":"mcm","clk":"1007788599","pt":1580622895337,"mc":[{"id":"1.168224423","rc":[{"batb":[[0,2.42,5.38],[1,2.4,6]],"ltp":2.4,"tv":40.22,"id":4486603}]}]}
{"op":"mcm","clk":"1007788604","pt":1580622895541,"mc":[{"id":"1.168224423","rc":[{"batb":[[0,2.4,6.07],[1,1.5,84.02],[2,1.4,378.63]],"ltp":2.4,"tv":40.22,"id":4486603}]}]}
{"op":"mcm","clk":"1007791078","pt":1580622958367,"mc":[{"id":"1.168224423","rc":[{"batb":[[0,2.42,5.28],[1,2.4,6],[2,1.5,84.02]],"ltp":2.4,"tv":40.22,"id":4486603}]}]}
{"op":"mcm","clk":"1007791090","pt":1580622958573,"mc":[{"id":"1.168224423","rc":[{"batb":[[0,2.4,6.07],[1,1.5,84.02],[2,1.4,378.63]],"ltp":2.4,"tv":40.22,"id":4486603}]}]}
{"op":"mcm","clk":"1007793516","pt":1580623022307,"mc":[{"id":"1.168224423","rc":[{"batb":[[0,2.42,5.3],[1,2.4,6],[2,1.5,84.02]],"ltp":2.4,"tv":40.22,"id":4486603}]}]}
{"op":"mcm","clk":"1007793522","pt":1580623022513,"mc":[{"id":"1.168224423","rc":[{"batb":[[0,2.4,6.07],[1,1.5,84.02],[2,1.4,378.63]],"ltp":2.4,"tv":40.22,"id":4486603}]}]}
{"op":"mcm","clk":"1007795011","pt":1580623066374,"mc":[{"id":"1.168224423","rc":[{"batb":[[0,2.42,5.99]],"ltp":2.4,"tv":40.22,"id":4486603}]}]}
{"op":"mcm","clk":"1007795055","pt":1580623067455,"mc":[{"id":"1.168224423","rc":[{"batl":[[0,1.69,6.26],[1,1.7,6.25],[2,1.71,12.52]],"ltp":1.52,"tv":1129.87,"id":8260126},{"batb":[[0,2.48,5.26],[1,2.44,5.33],[2,2.42,5.91]],"ltp":2.4,"tv":40.22,"id":4486603}]}]}
{"op":"mcm","clk":"1007795065","pt":1580623067866,"mc":[{"id":"1.168224423","rc":[{"batb":[[0,2.46,5.26]],"ltp":2.4,"tv":40.22,"id":4486603}]}]}
{"op":"mcm","clk":"1007796045","pt":1580623098418,"mc":[{"id":"1.168224423","rc":[{"batl":[[0,1.69,14.66],[2,1.71,4.12]],"ltp":1.52,"tv":1129.87,"id":8260126},{"batb":[[2,1.5,84.02]],"ltp":2.4,"tv":40.22,"id":4486603}]}]}
{"op":"mcm","clk":"1007796053","pt":1580623098623,"mc":[{"id":"1.168224423","rc":[{"batb":[[0,2.46,11.02]],"ltp":2.4,"tv":40.22,"id":4486603}]}]}
{"op":"mcm","clk":"1007797668","pt":1580623148512,"mc":[{"id":"1.168224423","rc":[{"batb":[[0,1.65,3.08],[1,1.64,19.34],[2,1.61,7.21]],"ltp":1.52,"tv":1129.87,"id":8260126}]}]}
{"op":"mcm","clk":"1007798104","pt":1580623161431,"mc":[{"id":"1.168224423","rc":[{"batb":[[1,1.64,6.21]],"ltp":1.52,"tv":1129.87,"id":8260126},{"batl":[[0,2.56,3.3]],"ltp":2.4,"tv":40.22,"id":4486603}]}]}
{"op":"mcm","clk":"1007798120","pt":1580623162050,"mc":[{"id":"1.168224423","rc":[{"batb":[[0,1.65,16]],"ltp":1.52,"tv":1129.87,"id":8260126},{"batl":[[0,2.54,8.4],[1,2.56,3.3],[2,2.58,3]],"ltp":2.4,"tv":40.22,"id":4486603}]}]}
{"op":"mcm","clk":"1007801315","pt":1580623240288,"mc":[{"id":"1.168224423","rc":[{"batb":[[2,1.63,5]],"batl":[[0,1.67,19.74],[1,1.68,4.22],[2,1.69,14.66]],"ltp":1.52,"tv":1129.87,"id":8260126},{"batb":[[0,2.48,4],[1,2.46,11.02],[2,2.44,5.33]],"ltp":2.4,"tv":40.22,"id":4486603}]}]}
{"op":"mcm","clk":"1007801353","pt":1580623241370,"mc":[{"id":"1.168224423","rc":[{"batb":[[0,1.65,21]],"batl":[[0,1.67,15.74]],"ltp":1.52,"tv":1129.87,"id":8260126},{"batl":[[0,2.54,11.4]],"ltp":2.4,"tv":40.22,"id":4486603}]}]}
{"op":"mcm","clk":"1007801426","pt":1580623243369,"mc":[{"id":"1.168224423","rc":[{"batl":[[0,1.68,4.22],[1,1.69,14.66],[2,1.7,6.25]],"ltp":1.52,"tv":1129.87,"id":8260126}]}]}
{"op":"mcm","clk":"1007801441","pt":1580623243678,"mc":[{"id":"1.168224423","rc":[{"batb":[[0,1.65,16]],"batl":[[0,1.66,15.74],[1,1.67,4.23],[2,1.68,4.22]],"ltp":1.52,"tv":1129.87,"id":8260126},{"batb":[[0,2.46,11.02],[1,2.44,5.33],[2,1.5,84.02]],"batl":[[0,2.54,8.4]],"ltp":2.4,"tv":40.22,"id":4486603}]}]}
{"op":"mcm","clk":"1007801611","pt":1580623248402,"mc":[{"id":"1.168224423","rc":[{"batl":[[0,1.67,4.23],[1,1.68,4.22],[2,1.69,14.66]],"ltp":1.52,"tv":1129.87,"id":8260126}]}]}
{"op":"mcm","clk":"1007801632","pt":1580623248810,"mc":[{"id":"1.168224423","rc":[{"trd":[[1.65,31.47]],"batb":[[0,1.64,6.47],[1,1.63,5],[2,1.61,7.21]],"batl":[[0,1.68,4.22],[1,1.69,14.66],[2,1.7,6.25]],"ltp":1.65,"tv":1161.35,"id":8260126}],"tv":1201.57}]}
{"op":"mcm","clk":"1007801739","pt":1580623251685,"mc":[{"id":"1.168224423","rc":[{"batb":[[2,2.3,39.38]],"ltp":2.4,"tv":40.22,"id":4486603}]}]}
{"op":"mcm","clk":"1007801874","pt":1580623255791,"mc":[{"id":"1.168224423","rc":[{"batl":[[1,1.69,6.26]],"ltp":1.65,"tv":1161.35,"id":8260126}]}]}
{"op":"mcm","clk":"1007801924","pt":1580623257383,"mc":[{"id":"1.168224423","rc":[{"batb":[[0,1.63,5],[1,1.61,7.21],[2,1.51,9.71]],"batl":[[0,1.68,16.82]],"ltp":1.65,"tv":1161.35,"id":8260126},{"batb":[[0,2.46,8.76]],"batl":[[0,2.58,3],[1,3,84.02],[2,3.9,229.44]],"ltp":2.4,"tv":40.22,"id":4486603}]}]}
{"op":"mcm","clk":"1007802868","pt":1580623282126,"mc":[{"id":"1.168224423","rc":[{"batb":[[1,1.61,4]],"ltp":1.65,"tv":1161.35,"id":8260126},{"batb":[[0,2.48,3.31],[1,2.46,8.76],[2,2.44,3.08]],"batl":[[0,2.6,2]],"ltp":2.4,"tv":40.22,"id":4486603}]}]}
{"op":"mcm","clk":"1007802879","pt":1580623282637,"mc":[{"id":"1.168224423","rc":[{"batl":[[1,2.98,8.4],[2,3,84.02]],"ltp":2.4,"tv":40.22,"id":4486603}]}]}
{"op":"mcm","clk":"1007803161","pt":1580623289063,"mc":[{"id":"1.168224423","rc":[{"batb":[[0,2.48,11.83],[1,2.46,3]],"ltp":2.4,"tv":40.22,"id":4486603}]}]}
{"op":"mcm","clk":"1007804727","pt":1580623325157,"mc":[{"id":"1.168224423","rc":[{"batb":[[2,2.44,3]],"ltp":2.4,"tv":40.22,"id":4486603}]}]}
{"op":"mcm","clk":"1007804851","pt":1580623328286,"mc":[{"id":"1.168224423","rc":[{"batl":[[0,1.66,4.04],[1,1.67,3],[2,1.68,16.82]],"ltp":1.65,"tv":1161.35,"id":8260126}]}]}
{"op":"mcm","clk":"1007805984","pt":1580623351319,"mc":[{"id":"1.168224423","rc":[{"batl":[[2,1.68,4.22]],"ltp":1.65,"tv":1161.35,"id":8260126}]}]}
{"op":"mcm","clk":"1007806039","pt":1580623352240,"mc":[{"id":"1.168224423","rc":[{"batl":[[0,1.66,12.6]],"ltp":1.65,"tv":1161.35,"id":8260126},{"batb":[[0,2.48,3.31]],"ltp":2.4,"tv":40.22,"id":4486603}]}]}
{"op":"mcm","clk":"1007806057","pt":1580623352700,"mc":[{"id":"1.168224423","rc":[{"batl":[[0,1.66,16.6]],"ltp":1.65,"tv":1161.35,"id":8260126},{"batb":[[0,2.52,3.17],[1,2.5,8.4],[2,2.48,3.31]],"ltp":2.4,"tv":40.22,"id":4486603}]}]}
{"op":"mcm","clk":"1007807261","pt":1580623384376,"mc":[{"id":"1.168224423","rc":[{"batl":[[0,1.65,4.02],[1,1.66,16.6],[2,1.67,3]],"ltp":1.65,"tv":1161.35,"id":8260126},{"batb":[[0,2.52,11.46],[1,2.48,3.31],[2,2.3,39.38]],"ltp":2.4,"tv":40.22,"id":4486603}]}]}
{"op":"mcm","clk":"1007808419","pt":1580623415417,"mc":[{"id":"1.168224423","rc":[{"batl":[[1,1.66,4]],"ltp":1.65,"tv":1161.35,"id":8260126}]}]}
{"op":"mcm","clk":"1007808439","pt":1580623415829,"mc":[{"id":"1.168224423","rc":[{"batl":[[0,1.65,12.6]],"ltp":1.65,"tv":1161.35,"id":8260126}]}]}
{"op":"mcm","clk":"1007809209","pt":1580623435968,"mc":[{"id":"1.168224423","rc":[{"batl":[[0,1.65,16.6]],"ltp":1.65,"tv":1161.35,"id":8260126}]}]}
{"op":"mcm","clk":"1007819426","pt":1580623686475,"mc":[{"id":"1.168224423","rc":[{"batb":[[0,2.52,11.54]],"ltp":2.4,"tv":40.22,"id":4486603}]}]}
{"op":"mcm","clk":"1007882810","pt":1580625088009,"mc":[{"id":"1.168224423","rc":[{"batb":[[2,1.5,84.02]],"ltp":2.4,"tv":40.22,"id":4486603}]}]}
{"op":"mcm","clk":"1007882873","pt":1580625088987,"mc":[{"id":"1.168224423","rc":[{"batb":[[0,1.62,4],[2,1.56,60.58]],"batl":[[0,1.65,12.6]],"ltp":1.65,"tv":1161.35,"id":8260126}]}]}
{"op":"mcm","clk":"1007882942","pt":1580625090269,"mc":[{"id":"1.168224423","rc":[{"batl":[[0,1.65,16.6]],"ltp":1.65,"tv":1161.35,"id":8260126},{"batl":[[1,3,84.02],[2,3.9,229.44]],"ltp":2.4,"tv":40.22,"id":4486603}]}]}
{"op":"mcm","clk":"1007882955","pt":1580625090473,"mc":[{"id":"1.168224423","rc":[{"batl":[[0,1.65,12.6]],"ltp":1.65,"tv":1161.35,"id":8260126}]}]}
{"op":"mcm","clk":"1007883144","pt":1580625094370,"mc":[{"id":"1.168224423","rc":[{"batb":[[2,1.55,60.58]],"ltp":1.65,"tv":1161.35,"id":8260126}]}]}
{"op":"mcm","clk":"1007883156","pt":1580625094572,"mc":[{"id":"1.168224423","rc":[{"batl":[[0,1.65,16.6]],"ltp":1.65,"tv":1161.35,"id":8260126},{"batb":[[2,2.18,41.65]],"batl":[[0,2.62,2]],"ltp":2.4,"tv":40.22,"id":4486603}]}]}
{"op":"mcm","clk":"1007896438","pt":1580625423168,"mc":[{"id":"1.168224423","rc":[{"batl":[[0,1.65,12.6]],"ltp":1.65,"tv":1161.35,"id":8260126}]}]}
{"op":"mcm","clk":"1007904743","pt":1580625662165,"mc":[{"id":"1.168224423","rc":[{"batb":[[2,1.6,2.04]],"batl":[[2,1.67,5.01]],"ltp":1.65,"tv":1161.35,"id":8260126},{"batb":[[1,2.48,5.32],[2,2.46,2.01]],"batl":[[1,2.66,2.1],[2,2.68,2.14]],"ltp":2.4,"tv":40.22,"id":4486603}]}]}
{"op":"mcm","clk":"1007904806","pt":1580625663187,"mc":[{"id":"1.168224423","rc":[{"batb":[[0,1.6,4],[1,1.58,2.06],[2,1.57,2.06]],"batl":[[0,1.64,3.01],[1,1.65,12.6],[2,1.66,6.01]],"ltp":1.65,"tv":1161.35,"id":8260126},{"batb":[[0,2.52,8.37],[1,2.48,2.01]],"batl":[[0,2.68,2],[1,2.72,2],[2,2.74,2.01]],"ltp":2.4,"tv":40.22,"id":4486603}]}]}
{"op":"mcm","clk":"1007905430","pt":1580625677420,"mc":[{"id":"1.168224423","rc":[{"batl":[[0,1.64,12.6],[1,1.67,3],[2,1.69,2.08]],"ltp":1.65,"tv":1161.35,"id":8260126},{"batb":[[0,2.44,2.09],[1,2.42,2.13],[2,2.18,41.65]],"batl":[[2,2.74,2]],"ltp":2.4,"tv":40.22,"id":4486603}]}]}
{"op":"mcm","clk":"1007905505","pt":1580625678293,"mc":[{"id":"1.168224423","rc":[{"batb":[[0,1.59,4],[1,1.57,2.06],[2,1.56,2.08]],"batl":[[0,1.63,3.09],[1,1.64,12.6],[2,1.65,2.1]],"ltp":1.65,"tv":1161.35,"id":8260126},{"batb":[[0,2.56,8.08],[1,2.52,2.24],[2,2.5,2]],"batl":[[0,2.7,2],[1,2.74,2],[2,2.76,2.02]],"ltp":2.4,"tv":40.22,"id":4486603}]}]}
{"op":"mcm","clk":"1007907307","pt":1580625709266,"mc":[{"id":"1.168224423","rc":[{"batl":[[0,1.64,3.26],[1,1.65,2.1],[2,1.66,2.22]],"ltp":1.65,"tv":1161.35,"id":8260126},{"batb":[[0,2.52,2.24],[1,2.5,2],[2,2.18,41.65]],"ltp":2.4,"tv":40.22,"id":4486603}]}]}
{"op":"mcm","clk":"1007907370","pt":1580625710388,"mc":[{"id":"1.168224423","rc":[{"batb":[[0,1.58,3],[1,1.56,2.08],[2,1.55,62.66]],"batl":[[0,1.62,3.27],[1,1.63,12.6],[2,1.64,2.18]],"ltp":1.65,"tv":1161.35,"id":8260126},{"batb":[[0,2.6,3.27],[1,2.58,7.97],[2,2.56,2.08]],"batl":[[0,2.72,2.27],[1,2.76,2.02],[2,2.78,2.25]],"ltp":2.4,"tv":40.22,"id":4486603}]}]}
{"op":"mcm","clk":"1007907648","pt":1580625716185,"mc":[{"id":"1.168224423","rc":[{"batb":[[2,1.55,62.77]],"ltp":1.65,"tv":1161.35,"id":8260126}]}]}
{"op":"mcm","clk":"1007907954","pt":1580625722376,"mc":[{"id":"1.168224423","rc":[{"batb":[[2,1.55,60.58]],"ltp":1.65,"tv":1161.35,"id":8260126},{"batl":[[2,3,84.02]],"ltp":2.4,"tv":40.22,"id":4486603}]}]}
{"op":"mcm","clk":"1007907973","pt":1580625722578,"mc":[{"id":"1.168224423","rc":[{"batb":[[2,1.55,62.66]],"ltp":1.65,"tv":1161.35,"id":8260126},{"batl":[[2,2.78,2.25]],"ltp":2.4,"tv":40.22,"id":4486603}]}]}
{"op":"mcm","clk":"1007908857","pt":1580625741408,"mc":[{"id":"1.168224423","rc":[{"batb":[[2,1.55,60.58]],"batl":[[1,1.64,2.18],[2,1.65,3.27]],"ltp":1.65,"tv":1161.35,"id":8260126},{"batl":[[2,3,84.02]],"ltp":2.4,"tv":40.22,"id":4486603}]}]}
{"op":"mcm","clk":"1007908914","pt":1580625742429,"mc":[{"id":"1.168224423","rc":[{"batb":[[2,1.55,62.77]],"batl":[[0,1.61,3.12],[1,1.62,12.6],[2,1.63,5.04]],"ltp":1.65,"tv":1161.35,"id":8260126},{"batb":[[0,2.62,2.12],[1,2.6,7.88],[2,2.58,2.06]],"batl":[[0,2.74,2],[2,2.78,2.02]],"ltp":2.4,"tv":40.22,"id":4486603}]}]}
{"op":"mcm","clk":"1007908939","pt":1580625742840,"mc":[{"id":"1.168224423","rc":[{"batb":[[0,2.6,7.88],[1,2.56,2.08],[2,2.54,2]],"batl":[[1,2.78,2.02],[2,2.8,2.02]],"ltp":2.4,"tv":40.22,"id":4486603}]}]}
{"op":"mcm","clk":"1007910158","pt":1580625773399,"mc":[{"id":"1.168224423","rc":[{"batl":[[1,1.62,3.29]],"ltp":1.65,"tv":1161.35,"id":8260126}]}]}
{"op":"mcm","clk":"1007910204","pt":1580625774377,"mc":[{"id":"1.168224423","rc":[{"batb":[[0,1.57,3]],"batl":[[0,1.6,3.29],[1,1.61,15.6]],"ltp":1.65,"tv":1161.35,"id":8260126},{"batb":[[0,2.64,2.29],[1,2.62,7.78],[2,2.58,2.06]],"ltp":2.4,"tv":40.22,"id":4486603}]}]}
{"op":"mcm","clk":"1007910243","pt":1580625775092,"mc":[{"id":"1.168224423","rc":[{"trd":[[1.6,10.16]],"batb":[[1,1.55,62.77],[2,1.54,2.12]],"batl":[[0,1.61,15.6],[1,1.63,5.04],[2,1.64,2.18]],"ltp":1.6,"tv":1171.51,"id":8260126},{"batb":[[0,2.64,2.3],[2,2.6,2.04]],"batl":[[0,2.76,2.29],[1,2.8,2.02],[2,2.82,2.25]],"ltp":2.4,"tv":40.22,"id":4486603}],"tv":1211.73}]}
{"op":"mcm","clk":"1007910310","pt":1580625776377,"mc":[{"id":"1.168224423","rc":[{"trd":[[1.61,34.98],[1.62,11.95]],"batb":[[0,1.61,127.99],[1,1.6,5.3],[2,1.59,7.11]],"batl":[[0,1.63,3],[1,1.64,4.18],[2,1.65,2.07]],"ltp":1.62,"tv":1218.43,"id":8260126},{"trd":[[2.62,7.39],[2.64,2.3]],"batb":[[0,2.58,4.45],[1,2.56,4.08],[2,2.54,2]],"batl":[[0,2.66,3.3],[1,2.68,5.44],[2,2.7,2.05]],"ltp":2.62,"tv":49.9,"id":4486603}],"tv":1268.34}]}
{"op":"mcm","clk":"1007910353","pt":1580625777299,"mc":[{"id":"1.168224423","rc":[{"trd":[[1.62,12.59]],"batb":[[0,1.62,24.36],[1,1.61,132.99],[2,1.6,7.34]],"batl":[[0,1.67,5],[1,1.68,2.14],[2,1.69,2.08]],"ltp":1.62,"tv":1219.07,"id":8260126},{"trd":[[2.62,7.78]],"batb":[[0,2.5,2],[1,2.48,2.01],[2,2.46,2.01]],"batl":[[0,2.62,3.31],[1,2.66,5.37],[2,2.68,2.14]],"ltp":2.62,"tv":50.3,"id":4486603}],"tv":1269.38}]}
{"op":"mcm","clk":"1007910399","pt":1580625778015,"mc":[{"id":"1.168224423","rc":[{"batl":[[0,1.67,3],[1,1.68,2]],"ltp":1.62,"tv":1219.07,"id":8260126},{"batb":[[0,2.46,2],[1,2.44,2.17],[2,2.42,2.13]],"ltp":2.62,"tv":50.3,"id":4486603}]}]}
{"op":"mcm","clk":"1007910510","pt":1580625780320,"mc":[{"id":"1.168224423","rc":[{"batb":[[1,1.61,76.88]],"batl":[[1,1.69,4.08],[2,1.7,2.05]],"ltp":1.62,"tv":1219.07,"id":8260126}]}]}
{"op":"mcm","clk":"1007910574","pt":1580625781394,"mc":[{"id":"1.168224423","rc":[{"batb":[[0,1.62,4.67],[1,1.61,5]],"batl":[[0,1.66,2],[1,1.67,3],[2,1.69,4.08]],"ltp":1.62,"tv":1219.07,"id":8260126}]}]}
{"op":"mcm","clk":"1007910610","pt":1580625782217,"mc":[{"id":"1.168224423","rc":[{"batl":[[0,1.67,5],[1,1.69,4.08],[2,1.7,2.05]],"ltp":1.62,"tv":1219.07,"id":8260126},{"batb":[[0,2.44,2.25],[1,2.42,2.13],[2,2.18,41.65]],"ltp":2.62,"tv":50.3,"id":4486603}]}]}
{"op":"mcm","clk":"1007910681","pt":1580625783398,"mc":[{"id":"1.168224423","rc":[{"batl":[[0,1.66,2.01],[1,1.67,5],[2,1.68,2.14]],"ltp":1.62,"tv":1219.07,"id":8260126},{"batb":[[0,2.46,2.09],[1,2.42,2.01]],"ltp":2.62,"tv":50.3,"id":4486603}]}]}
{"op":"mcm","clk":"1007910729","pt":1580625784317,"mc":[{"id":"1.168224423","rc":[{"batl":[[0,1.67,5],[1,1.69,4.08],[2,1.7,2.05]],"ltp":1.62,"tv":1219.07,"id":8260126},{"batb":[[0,2.44,2.25],[2,2.36,41.65]],"ltp":2.62,"tv":50.3,"id":4486603}]}]}
{"op":"mcm","clk":"1007911177","pt":1580625792425,"mc":[{"id":"1.168224423","rc":[{"batb":[[0,1.61,5],[1,1.6,7.34],[2,1.59,7.11]],"ltp":1.62,"tv":1219.07,"id":8260126},{"batb":[[0,2.46,2.09],[1,2.42,2],[2,2.32,41.65]],"batl":[[0,2.6,3.06],[1,2.64,3]],"ltp":2.62,"tv":50.3,"id":4486603}]}]}
{"op":"mcm","clk":"1007911224","pt":1580625793447,"mc":[{"id":"1.168224423","rc":[{"batb":[[0,1.65,4.07],[1,1.63,4.07],[2,1.62,6.1]],"batl":[[1,1.68,2],[2,1.69,4.08]],"ltp":1.62,"tv":1219.07,"id":8260126},{"batb":[[0,2.48,2.08],[1,2.44,2.01],[2,2.42,2]],"batl":[[0,2.56,3.07],[1,2.6,5.08],[2,2.62,2.25]],"ltp":2.62,"tv":50.3,"id":4486603}]}]}
{"op":"mcm","clk":"1007911254","pt":1580625794116,"mc":[{"id":"1.168224423","rc":[{"batb":[[0,1.64,4.07]],"batl":[[0,1.67,3]],"ltp":1.62,"tv":1219.07,"id":8260126},{"batl":[[1,2.58,3.07],[2,2.6,2.01]],"ltp":2.62,"tv":50.3,"id":4486603}]}]}
{"op":"mcm","clk":"1007911722","pt":1580625809345,"mc":[{"id":"1.168224423","rc":[{"batb":[[2,2.42,2.13]],"ltp":2.62,"tv":50.3,"id":4486603}]}]}
{"op":"mcm","clk":"1007929126","pt":1580626204431,"mc":[{"id":"1.168224423","rc":[{"batb":[[0,2.46,2.1],[1,2.42,2.13],[2,2.4,2.01]],"batl":[[0,2.56,11.47]],"ltp":2.62,"tv":50.3,"id":4486603}]}]}
{"op":"mcm","clk":"1007929132","pt":1580626204532,"mc":[{"id":"1.168224423","rc":[{"batb":[[1,2.44,2.17],[2,2.42,2.13]],"ltp":2.62,"tv":50.3,"id":4486603}]}]}
{"op":"mcm","clk":"1007929269","pt":1580626207455,"mc":[{"id":"1.168224423","rc":[{"batl":[[0,1.67,14.87]],"ltp":1.62,"tv":1219.07,"id":8260126},{"batb":[[0,2.48,4.08],[1,2.46,2.02],[2,2.44,2.17]],"ltp":2.62,"tv":50.3,"id":4486603}]}]}
{"op":"mcm","clk":"1007932242","pt":1580626266410,"mc":[{"id":"1.168224423","rc":[{"batb":[[0,1.64,17.2]],"batl":[[0,1.67,10.87]],"ltp":1.62,"tv":1219.07,"id":8260126},{"batb":[[0,2.48,2.08]],"ltp":2.62,"tv":50.3,"id":4486603}]}]}
{"op":"mcm","clk":"1008036254","pt":1580628155106,"mc":[{"id":"1.168224423","rc":[{"trd":[[2.56,4]],"batl":[[0,2.56,9.47]],"ltp":2.56,"tv":54.3,"id":4486603}],"tv":1273.38}]}
{"op":"mcm","clk":"1008055660","pt":1580628498375,"mc":[{"id":"1.168224423","rc":[{"trd":[[1.64,8.81]],"batb":[[0,1.64,12.8]],"ltp":1.64,"tv":1227.88,"id":8260126},{"trd":[[2.56,22.94]],"batl":[[0,2.58,3.07],[1,2.6,2.01],[2,2.62,2.25]],"ltp":2.56,"tv":73.24,"id":4486603}],"tv":1301.13}]}
{"op":"mcm","clk":"1008055719","pt":1580628499356,"mc":[{"id":"1.168224423","rc":[{"batb":[[1,1.63,4.23],[2,1.62,2]],"batl":[[0,1.66,2.1],[1,1.67,12.87],[2,1.68,4.01]],"ltp":1.64,"tv":1227.88,"id":8260126},{"batb":[[0,2.5,2.18],[1,2.48,2],[2,2.46,38.44]],"batl":[[0,2.56,2.1],[1,2.58,5.08],[2,2.6,2.01]],"ltp":2.56,"tv":73.24,"id":4486603}]}]}
{"op":"mcm","clk":"1008055765","pt":1580628500176,"mc":[{"id":"1.168224423","rc":[{"batb":[[1,1.63,2],[2,1.62,4.04]],"ltp":1.64,"tv":1227.88,"id":8260126},{"batl":[[0,2.6,2.1],[1,2.62,2.09],[2,2.64,2.18]],"ltp":2.56,"tv":73.24,"id":4486603}]}]}
{"op":"mcm","clk":"1008057034","pt":1580628524300,"mc":[{"id":"1.168224423","rc":[{"batl":[[0,1.66,10.5]],"ltp":1.64,"tv":1227.88,"id":8260126},{"batb":[[0,2.5,7.78]],"batl":[[0,2.58,8.4],[1,2.6,2.1]],"ltp":2.56,"tv":73.24,"id":4486603}]}]}
{"op":"mcm","clk":"1008057046","pt":1580628524507,"mc":[{"id":"1.168224423","rc":[{"batl":[[2,2.62,2.17]],"ltp":2.56,"tv":73.24,"id":4486603}]}]}
{"op":"mcm","clk":"1008058083","pt":1580628544432,"mc":[{"id":"1.168224423","rc":[{"batl":[[0,2.58,10.4]],"ltp":2.56,"tv":73.24,"id":4486603}]}]}
{"op":"mcm","clk":"1008085067","pt":1580629081444,"mc":[{"id":"1.168224423","rc":[{"batb":[[0,1.65,37.86],[1,1.64,14.8],[2,1.63,4.23]],"batl":[[0,1.66,8.4]],"ltp":1.64,"tv":1227.88,"id":8260126},{"batl":[[0,2.56,2],[1,2.58,12.65],[2,2.6,4.11]],"ltp":2.56,"tv":73.24,"id":4486603}]}]}
{"op":"mcm","clk":"1008085103","pt":1580629081956,"mc":[{"id":"1.168224423","rc":[{"batb":[[0,1.65,39.86],[2,1.63,13.23]],"ltp":1.64,"tv":1227.88,"id":8260126},{"batl":[[0,2.54,2],[1,2.56,2],[2,2.58,12.65]],"ltp":2.56,"tv":73.24,"id":4486603}]}]}
{"op":"mcm","clk":"1008085362","pt":1580629087366,"mc":[{"id":"1.168224423","rc":[{"batb":[[1,1.64,2]],"ltp":1.64,"tv":1227.88,"id":8260126},{"batl":[[0,2.56,2],[1,2.58,4.25],[2,2.6,2.01]],"ltp":2.56,"tv":73.24,"id":4486603}]}]}
{"op":"mcm","clk":"1008085421","pt":1580629088291,"mc":[{"id":"1.168224423","rc":[{"batb":[[2,1.63,4.23]],"ltp":1.64,"tv":1227.88,"id":8260126},{"batl":[[0,2.54,8.4],[1,2.56,2],[2,2.58,4.13]],"ltp":2.56,"tv":73.24,"id":4486603}]}]}
{"op":"mcm","clk":"1008086394","pt":1580629108397,"mc":[{"id":"1.168224423","rc":[{"batl":[[0,2.54,10.4]],"ltp":2.56,"tv":73.24,"id":4486603}]}]}
{"op":"mcm","clk":"1008090642","pt":1580629197447,"mc":[{"id":"1.168224423","rc":[{"trd":[[1.65,55.12]],"batb":[[0,1.65,28.04]],"ltp":1.65,"tv":1251.52,"id":8260126}],"tv":1324.77}]}
{"op":"mcm","clk":"1008090651","pt":1580629197600,"mc":[{"id":"1.168224423","rc":[{"batb":[[2,2.46,30.66]],"ltp":2.56,"tv":73.24,"id":4486603}]}]}
{"op":"mcm","clk":"1008107400","pt":1580629518417,"mc":[{"id":"1.168224423","rc":[{"batb":[[0,1.65,2]],"ltp":1.65,"tv":1251.52,"id":8260126}]}]}
{"op":"mcm","clk":"1008107414","pt":1580629518776,"mc":[{"id":"1.168224423","rc":[{"batb":[[0,1.64,4],[1,1.63,4],[2,1.62,6.04]],"batl":[[0,1.66,11.4]],"ltp":1.65,"tv":1251.52,"id":8260126},{"batl":[[0,2.54,8.4]],"ltp":2.56,"tv":73.24,"id":4486603}]}]}
{"op":"mcm","clk":"1008107531","pt":1580629521394,"mc":[{"id":"1.168224423","rc":[{"batb":[[0,1.63,4],[1,1.62,6.04],[2,1.61,5.09]],"batl":[[0,1.65,3.11],[1,1.66,11.4],[2,1.67,12.87]],"ltp":1.65,"tv":1251.52,"id":8260126},{"trd":[[2.54,15.36]],"batl":[[0,2.6,4.72],[1,2.62,2.25],[2,3,42.01]],"ltp":2.54,"tv":88.6,"id":4486603}],"tv":1340.13}]}
{"op":"mcm","clk":"1008107576","pt":1580629522205,"mc":[{"id":"1.168224423","rc":[{"batb":[[1,1.62,4]],"batl":[[2,1.67,14.88]],"ltp":1.65,"tv":1251.52,"id":8260126},{"batb":[[1,2.48,4.01]],"batl":[[0,2.6,2.72],[1,2.64,2.18],[2,2.66,2.25]],"ltp":2.54,"tv":88.6,"id":4486603}]}]}
{"op":"mcm","clk":"1008107616","pt":1580629522919,"mc":[{"id":"1.168224423","rc":[{"batb":[[0,1.6,11.21],[1,1.59,78.05],[2,1.51,98.44]],"ltp":1.65,"tv":1251.52,"id":8260126}]}]}
{"op":"mcm","clk":"1008107677","pt":1580629524405,"mc":[{"id":"1.168224423","rc":[{"batl":[[0,1.66,3],[1,1.67,12.87],[2,1.68,4.01]],"ltp":1.65,"tv":1251.52,"id":8260126},{"batb":[[1,2.48,2]],"batl":[[0,2.6,2]],"ltp":2.54,"tv":88.6,"id":4486603}]}]}
{"op":"mcm","clk":"1008107716","pt":1580629525380,"mc":[{"id":"1.168224423","rc":[{"batb":[[0,1.62,4],[1,1.6,11.21],[2,1.59,78.05]],"batl":[[0,1.65,15.6],[1,1.66,3],[2,1.67,14.88]],"ltp":1.65,"tv":1251.52,"id":8260126},{"batb":[[0,2.54,3.13],[1,2.52,8.29],[2,2.5,4.18]],"batl":[[0,2.62,2.13],[1,2.66,2.25],[2,2.68,2.14]],"ltp":2.54,"tv":88.6,"id":4486603}]}]}
{"op":"mcm","clk":"1008108665","pt":1580629546345,"mc":[{"id":"1.168224423","rc":[{"batl":[[0,1.64,3.13],[1,1.65,15.6],[2,1.66,5.1]],"ltp":1.65,"tv":1251.52,"id":8260126}]}]}
{"op":"mcm","clk":"1008108704","pt":1580629547221,"mc":[{"id":"1.168224423","rc":[{"batb":[[0,1.61,4],[1,1.6,9.17],[2,1.59,78.16]],"ltp":1.65,"tv":1251.52,"id":8260126},{"batb":[[1,2.52,10.47]],"batl":[[0,2.64,2],[1,2.68,2.14],[2,2.7,2.05]],"ltp":2.54,"tv":88.6,"id":4486603}]}]}
{"op":"mcm","clk":"1008109098","pt":1580629556453,"mc":[{"id":"1.168224423","rc":[{"batl":[[1,1.65,3]],"ltp":1.65,"tv":1251.52,"id":8260126}]}]}
{"op":"mcm","clk":"1008109152","pt":1580629557428,"mc":[{"id":"1.168224423","rc":[{"batl":[[0,1.64,12.6],[1,1.66,5.13],[2,1.67,14.88]],"ltp":1.65,"tv":1251.52,"id":8260126},{"batb":[[0,2.56,8.08],[1,2.52,5.02]],"ltp":2.54,"tv":88.6,"id":4486603}]}]}
{"op":"mcm","clk":"1008109168","pt":1580629557734,"mc":[{"id":"1.168224423","rc":[{"batl":[[0,1.64,15.6]],"ltp":1.65,"tv":1251.52,"id":8260126},{"batb":[[0,2.56,11.08],[2,2.5,2.08]],"ltp":2.54,"tv":88.6,"id":4486603}]}]}
{"op":"mcm","clk":"1008111503","pt":1580629610426,"mc":[{"id":"1.168224423","rc":[{"trd":[[1.64,32.55]],"batl":[[0,1.64,3.73]],"ltp":1.64,"tv":1275.27,"id":8260126}],"tv":1363.87}]}
{"op":"mcm","clk":"1008111564","pt":1580629611411,"mc":[{"id":"1.168224423","rc":[{"batb":[[0,1.62,4.27],[1,1.61,41.42],[2,1.6,11.21]],"batl":[[0,1.65,3.73],[1,1.66,5.07]],"ltp":1.64,"tv":1275.27,"id":8260126},{"batb":[[0,2.56,8.08],[1,2.54,5.39]],"batl":[[0,2.62,2.28],[1,2.66,4.52],[2,2.68,2.14]],"ltp":2.54,"tv":88.6,"id":4486603}]}]}
{"op":"mcm","clk":"1008111590","pt":1580629611923,"mc":[{"id":"1.168224423","rc":[{"batb":[[2,1.6,2.04]],"batl":[[1,1.66,3]],"ltp":1.64,"tv":1275.27,"id":8260126},{"batb":[[1,2.54,3.27],[2,2.52,2.08]],"batl":[[2,2.68,2]],"ltp":2.54,"tv":88.6,"id":4486603}]}]}
{"op":"mcm","clk":"1008111927","pt":1580629619849,"mc":[{"id":"1.168224423","rc":[{"batl":[[2,2.68,2.14]],"ltp":2.54,"tv":88.6,"id":4486603}]}]}
{"op":"mcm","clk":"1008113259","pt":1580629651259,"mc":[{"id":"1.168224423","rc":[{"batl":[[0,1.65,3]],"ltp":1.64,"tv":1275.27,"id":8260126},{"batl":[[2,3,42.01]],"ltp":2.54,"tv":88.6,"id":4486603}]}]}
{"op":"mcm","clk":"1008113297","pt":1580629652078,"mc":[{"id":"1.168224423","rc":[{"batl":[[0,1.66,3],[1,1.67,12.87],[2,1.68,4.01]],"ltp":1.64,"tv":1275.27,"id":8260126},{"batb":[[0,2.52,3],[1,2.48,9.79],[2,2.46,28.64]],"batl":[[2,2.68,2.01]],"ltp":2.54,"tv":88.6,"id":4486603}]}]}
{"op":"mcm","clk":"1008115859","pt":1580629713258,"mc":[{"id":"1.168224423","rc":[{"batl":[[0,1.65,3.18],[1,1.66,11.4],[2,1.67,12.87]],"ltp":1.64,"tv":1275.27,"id":8260126},{"batb":[[0,2.52,8.53]],"ltp":2.54,"tv":88.6,"id":4486603}]}]}
{"op":"mcm","clk":"1008115885","pt":1580629713975,"mc":[{"id":"1.168224423","rc":[{"batb":[[0,1.62,17.82]],"batl":[[0,1.66,11.4],[1,1.67,12.87],[2,1.68,4.01]],"ltp":1.64,"tv":1275.27,"id":8260126},{"batl":[[0,2.62,10.68],[2,2.68,2.14]],"ltp":2.54,"tv":88.6,"id":4486603}]}]}
{"op":"mcm","clk":"1008115905","pt":1580629714487,"mc":[{"id":"1.168224423","rc":[{"batb":[[1,1.61,50.53]],"ltp":1.64,"tv":1275.27,"id":8260126}]}]}
{"op":"mcm","clk":"1008129023","pt":1580629978280,"mc":[{"id":"1.168224423","rc":[{"batb":[[0,2.52,8.6]],"batl":[[2,2.68,2.01]],"ltp":2.54,"tv":88.6,"id":4486603}]}]}
{"op":"mcm","clk":"1008138883","pt":1580630144408,"mc":[{"id":"1.168224423","rc":[{"batl":[[2,2.68,2.14]],"ltp":2.54,"tv":88.6,"id":4486603}]}]}
{"op":"mcm","clk":"1008158347","pt":1580630463997,"mc":[{"id":"1.168224423","rc":[{"batl":[[2,2.68,2.01]],"ltp":2.54,"tv":88.6,"id":4486603}]}]}
{"op":"mcm","clk":"1008159097","pt":1580630477312,"mc":[{"id":"1.168224423","rc":[{"batb":[[2,2.46,26.63]],"batl":[[2,3,42.01]],"ltp":2.54,"tv":88.6,"id":4486603}]}]}
{"op":"mcm","clk":"1008159113","pt":1580630477514,"mc":[{"id":"1.168224423","rc":[{"batb":[[2,2.46,28.64]],"batl":[[2,2.68,2.01]],"ltp":2.54,"tv":88.6,"id":4486603}]}]}
{"op":"mcm","clk":"1008165422","pt":1580630590313,"mc":[{"id":"1.168224423","rc":[{"trd":[[1.62,17.63]],"batb":[[0,1.62,15.3]],"ltp":1.62,"tv":1280.31,"id":8260126},{"batl":[[2,2.68,2.14]],"ltp":2.54,"tv":88.6,"id":4486603}],"tv":1368.91}]}
{"op":"mcm","clk":"1008165453","pt":1580630590877,"mc":[{"id":"1.168224423","rc":[{"batb":[[1,1.61,41.42]],"ltp":1.62,"tv":1280.31,"id":8260126}]}]}
{"op":"mcm","clk":"1008168196","pt":1580630637974,"mc":[{"id":"1.168224423","rc":[{"batl":[[2,2.68,2]],"ltp":2.54,"tv":88.6,"id":4486603}]}]}
{"op":"mcm","clk":"1008173267","pt":1580630717316,"mc":[{"id":"1.168224423","rc":[{"trd":[[1.65,55.23],[1.66,3.12]],"batl":[[0,1.66,9.84]],"ltp":1.66,"tv":1283.55,"id":8260126},{"trd":[[2.54,15.43]],"batb":[[0,2.52,8.53],[2,2.46,26.63]],"batl":[[2,3,42.01]],"ltp":2.54,"tv":88.67,"id":4486603}],"tv":1372.23}]}
{"op":"mcm","clk":"1008173290","pt":1580630717625,"mc":[{"id":"1.168224423","rc":[{"batb":[[2,2.46,28.64]],"batl":[[2,2.68,2.14]],"ltp":2.54,"tv":88.67,"id":4486603}]}]}
{"op":"mcm","clk":"1008179647","pt":1580630841912,"mc":[{"id":"1.168224423","rc":[{"batb":[[2,2.46,28.63]],"batl":[[2,2.68,2.01]],"ltp":2.54,"tv":88.67,"id":4486603}]}]}
{"op":"mcm","clk":"1008180031","pt":1580630848738,"mc":[{"id":"1.168224423","rc":[{"batb":[[2,2.46,28.64]],"batl":[[2,2.68,2.14]],"ltp":2.54,"tv":88.67,"id":4486603}]}]}
{"op":"mcm","clk":"1008180362","pt":1580630855858,"mc":[{"id":"1.168224423","rc":[{"batl":[[2,2.68,2.01]],"ltp":2.54,"tv":88.67,"id":4486603}]}]}
{"op":"mcm","clk":"1008180714","pt":1580630862434,"mc":[{"id":"1.168224423","rc":[{"batb":[[2,2.46,26.63]],"batl":[[2,3,42.01]],"ltp":2.54,"tv":88.67,"id":4486603}]}]}
{"op":"mcm","clk":"1008180727","pt":1580630862634,"mc":[{"id":"1.168224423","rc":[{"batb":[[2,2.46,28.64]],"batl":[[2,2.68,2]],"ltp":2.54,"tv":88.67,"id":4486603}]}]}
{"op":"mcm","clk":"1008189875","pt":1580631029774,"mc":[{"id":"1.168224423","rc":[{"batl":[[2,2.68,2.14]],"ltp":2.54,"tv":88.67,"id":4486603}]}]}
{"op":"mcm","clk":"1008193449","pt":1580631086248,"mc":[{"id":"1.168224423","rc":[{"batl":[[2,2.68,2.01]],"ltp":2.54,"tv":88.67,"id":4486603}]}]}
{"op":"mcm","clk":"1008194393","pt":1580631100262,"mc":[{"id":"1.168224423","rc":[{"batl":[[2,2.68,2.14]],"ltp":2.54,"tv":88.67,"id":4486603}]}]}
{"op":"mcm","clk":"1008209725","pt":1580631323313,"mc":[{"id":"1.168224423","rc":[{"batb":[[2,2.46,26.63]],"batl":[[2,3,42.01]],"ltp":2.54,"tv":88.67,"id":4486603}]}]}
{"op":"mcm","clk":"1008209743","pt":1580631323517,"mc":[{"id":"1.168224423","rc":[{"batb":[[2,2.46,28.64]],"batl":[[2,2.68,2.14]],"ltp":2.54,"tv":88.67,"id":4486603}]}]}
{"op":"mcm","clk":"1008232857","pt":1580631667386,"mc":[{"id":"1.168224423","rc":[{"batb":[[2,2.46,26.63]],"batl":[[2,3,42.01]],"ltp":2.54,"tv":88.67,"id":4486603}]}]}
{"op":"mcm","clk":"1008232883","pt":1580631667799,"mc":[{"id":"1.168224423","rc":[{"batb":[[2,2.46,28.64]],"batl":[[2,2.68,2.01]],"ltp":2.54,"tv":88.67,"id":4486603}]}]}
{"op":"mcm","clk":"1008237640","pt":1580631734442,"mc":[{"id":"1.168224423","rc":[{"trd":[[1.66,6.49]],"batl":[[0,1.66,8.16]],"ltp":1.66,"tv":1286.91,"id":8260126},{"batb":[[2,2.46,26.63]],"batl":[[2,3,42.01]],"ltp":2.54,"tv":88.67,"id":4486603}],"tv":1375.59}]}
{"op":"mcm","clk":"1008237701","pt":1580631735367,"mc":[{"id":"1.168224423","rc":[{"batb":[[0,1.62,19.8],[1,1.61,50.53]],"batl":[[0,1.66,14.16]],"ltp":1.66,"tv":1286.91,"id":8260126},{"batb":[[2,2.46,28.64]],"batl":[[2,2.68,2.14]],"ltp":2.54,"tv":88.67,"id":4486603}]}]}
{"op":"mcm","clk":"1008239095","pt":1580631754309,"mc":[{"id":"1.168224423","rc":[{"batb":[[2,2.46,26.63]],"batl":[[2,3,42.01]],"ltp":2.54,"tv":88.67,"id":4486603}]}]}
{"op":"mcm","clk":"1008239111","pt":1580631754508,"mc":[{"id":"1.168224423","rc":[{"batb":[[2,2.46,28.64]],"batl":[[2,2.68,2]],"ltp":2.54,"tv":88.67,"id":4486603}]}]}
{"op":"mcm","clk":"1008261019","pt":1580632137327,"mc":[{"id":"1.168224423","rc":[{"batb":[[0,1.62,24.92]],"ltp":1.66,"tv":1286.91,"id":8260126}]}]}
{"op":"mcm","clk":"1008261041","pt":1580632137635,"mc":[{"id":"1.168224423","rc":[{"batb":[[0,1.62,19.8]],"batl":[[0,1.66,11.16]],"ltp":1.66,"tv":1286.91,"id":8260126},{"batb":[[0,2.52,5.53],[1,2.5,3],[2,2.48,9.79]],"batl":[[2,2.68,2.01]],"ltp":2.54,"tv":88.67,"id":4486603}]}]}
{"op":"mcm","clk":"1008261145","pt":1580632139442,"mc":[{"id":"1.168224423","rc":[{"batb":[[0,1.63,6.59],[1,1.62,19.8],[2,1.61,52.62]],"ltp":1.66,"tv":1286.91,"id":8260126},{"batb":[[0,2.52,8.53]],"batl":[[0,2.6,2.32],[1,2.62,10.68],[2,2.66,2.25]],"ltp":2.54,"tv":88.67,"id":4486603}]}]}
{"op":"mcm","clk":"1008261179","pt":1580632139853,"mc":[{"id":"1.168224423","rc":[{"batl":[[2,2.64,2.04]],"ltp":2.54,"tv":88.67,"id":4486603}]}]}
{"op":"mcm","clk":"1008261966","pt":1580632152277,"mc":[{"id":"1.168224423","rc":[{"batb":[[1,1.62,6.25]],"ltp":1.66,"tv":1286.91,"id":8260126},{"batl":[[1,2.62,2.28]],"ltp":2.54,"tv":88.67,"id":4486603}]}]}
{"op":"mcm","clk":"1008262002","pt":1580632152885,"mc":[{"id":"1.168224423","rc":[{"batb":[[0,1.63,19.93],[2,1.61,43.51]],"ltp":1.66,"tv":1286.91,"id":8260126},{"batl":[[0,2.6,10.72]],"ltp":2.54,"tv":88.67,"id":4486603}]}]}
{"op":"mcm","clk":"1008262054","pt":1580632153760,"mc":[{"id":"1.168224423","rc":[{"batb":[[1,1.62,15.31]],"ltp":1.66,"tv":1286.91,"id":8260126}]}]}
{"op":"mcm","clk":"1008262366","pt":1580632160055,"mc":[{"id":"1.168224423","rc":[{"batb":[[2,1.61,80.94]],"ltp":1.66,"tv":1286.91,"id":8260126},{"batb":[[2,2.48,44.19]],"ltp":2.54,"tv":88.67,"id":4486603}]}]}
{"op":"mcm","clk":"1008265144","pt":1580632204314,"mc":[{"id":"1.168224423","rc":[{"batb":[[0,1.63,27.87]],"ltp":1.66,"tv":1286.91,"id":8260126}]}]}
{"op":"mcm","clk":"1008266049","pt":1580632216372,"mc":[{"id":"1.168224423","rc":[{"batl":[[0,2.6,2.32]],"ltp":2.54,"tv":88.67,"id":4486603}]}]}
{"op":"mcm","clk":"1008266066","pt":1580632216575,"mc":[{"id":"1.168224423","rc":[{"batb":[[0,1.63,14.53]],"ltp":1.66,"tv":1286.91,"id":8260126}]}]}
{"op":"mcm","clk":"1008269625","pt":1580632266276,"mc":[{"id":"1.168224423","rc":[{"batb":[[0,1.63,12.26]],"ltp":1.66,"tv":1286.91,"id":8260126}]}]}
{"op":"mcm","clk":"1008272948","pt":1580632312443,"mc":[{"id":"1.168224423","rc":[{"batb":[[0,1.63,7.94]],"batl":[[0,1.65,8],[1,1.66,11.16],[2,1.67,18.88]],"ltp":1.66,"tv":1286.91,"id":8260126},{"batb":[[0,2.54,55.83],[1,2.52,8.53],[2,2.5,5]],"batl":[[0,2.62,2.28],[1,2.64,2.04],[2,2.66,2]],"ltp":2.54,"tv":88.67,"id":4486603}]}]}
{"op":"mcm","clk":"1008273825","pt":1580632324062,"mc":[{"id":"1.168224423","rc":[{"batb":[[1,1.62,17.58]],"ltp":1.66,"tv":1286.91,"id":8260126},{"batl":[[2,2.66,2.25]],"ltp":2.54,"tv":88.67,"id":4486603}]}]}
{"op":"mcm","clk":"1008274789","pt":1580632340362,"mc":[{"id":"1.168224423","rc":[{"batl":[[1,1.66,3]],"ltp":1.66,"tv":1286.91,"id":8260126}]}]}
{"op":"mcm","clk":"1008274843","pt":1580632341286,"mc":[{"id":"1.168224423","rc":[{"batl":[[0,1.64,5.33],[1,1.65,8],[2,1.66,5]],"ltp":1.66,"tv":1286.91,"id":8260126},{"batb":[[1,2.52,5.02]],"ltp":2.54,"tv":88.67,"id":4486603}]}]}
{"op":"mcm","clk":"1008275240","pt":1580632347266,"mc":[{"id":"1.168224423","rc":[{"batl":[[0,1.64,66.11]],"ltp":1.66,"tv":1286.91,"id":8260126}]}]}
{"op":"mcm","clk":"1008275310","pt":1580632348301,"mc":[{"id":"1.168224423","rc":[{"trd":[[1.63,15.08]],"batb":[[0,1.62,11.73],[1,1.61,78.85],[2,1.6,8]],"batl":[[0,1.64,70.11],[1,1.65,4]],"ltp":1.63,"tv":1301.99,"id":8260126},{"batb":[[0,2.58,4.15],[1,2.56,4],[2,2.54,53.83]],"batl":[[0,2.64,3],[1,2.66,2.25],[2,2.68,2.14]],"ltp":2.54,"tv":88.67,"id":4486603}],"tv":1390.67}]}
{"op":"mcm","clk":"1008275355","pt":1580632348876,"mc":[{"id":"1.168224423","rc":[{"batb":[[0,1.62,2.67],[1,1.61,87.96]],"ltp":1.63,"tv":1301.99,"id":8260126},{"batl":[[1,2.68,2.14],[2,2.7,2.05]],"ltp":2.54,"tv":88.67,"id":4486603}]}]}
{"op":"mcm","clk":"1008280032","pt":1580632414380,"mc":[{"id":"1.168224423","rc":[{"batb":[[1,1.61,90.96]],"ltp":1.63,"tv":1301.99,"id":8260126},{"trd":[[2.58,8.3]],"batb":[[0,2.58,4]],"ltp":2.58,"tv":96.97,"id":4486603}],"tv":1398.97}]}
{"op":"mcm","clk":"1008280073","pt":1580632414998,"mc":[{"id":"1.168224423","rc":[{"batb":[[1,1.61,84.37]],"ltp":1.63,"tv":1301.99,"id":8260126}]}]}
{"op":"mcm","clk":"1008289475","pt":1580632553274,"mc":[{"id":"1.168224423","rc":[{"batl":[[2,3,42.01]],"ltp":2.58,"tv":96.97,"id":4486603}]}]}
{"op":"mcm","clk":"1008289485","pt":1580632553482,"mc":[{"id":"1.168224423","rc":[{"batl":[[2,2.7,2.05]],"ltp":2.58,"tv":96.97,"id":4486603}]}]}
{"op":"mcm","clk":"1008290666","pt":1580632574405,"mc":[{"id":"1.168224423","rc":[{"batl":[[2,3,42.01]],"ltp":2.58,"tv":96.97,"id":4486603}]}]}
{"op":"mcm","clk":"1008290674","pt":1580632574508,"mc":[{"id":"1.168224423","rc":[{"batl":[[2,2.7,2.05]],"ltp":2.58,"tv":96.97,"id":4486603}]}]}
{"op":"mcm","clk":"1008291394","pt":1580632587412,"mc":[{"id":"1.168224423","rc":[{"trd":[[1.62,18.85],[1.63,15.88]],"batb":[[0,1.62,1.66]],"ltp":1.62,"tv":1304.02,"id":8260126}],"tv":1400.99}]}
{"op":"mcm","clk":"1008291424","pt":1580632587925,"mc":[{"id":"1.168224423","rc":[{"batb":[[2,1.6,6]],"ltp":1.62,"tv":1304.02,"id":8260126}]}]}
{"op":"mcm","clk":"1008303345","pt":1580632791323,"mc":[{"id":"1.168224423","rc":[{"batb":[[1,1.61,86.46],[2,1.6,12.04]],"batl":[[2,1.66,8]],"ltp":1.62,"tv":1304.02,"id":8260126},{"trd":[[2.58,36.2]],"batb":[[0,2.58,4.49]],"batl":[[0,2.62,2],[1,2.64,7.04],[2,2.68,2.14]],"ltp":2.58,"tv":124.88,"id":4486603}],"tv":1428.9}]}
{"op":"mcm","clk":"1008303407","pt":1580632792350,"mc":[{"id":"1.168224423","rc":[{"batb":[[1,1.61,84.37],[2,1.6,10]],"ltp":1.62,"tv":1304.02,"id":8260126},{"batb":[[2,2.54,53.95]],"batl":[[0,2.64,5],[1,2.68,2.14],[2,2.7,2.05]],"ltp":2.58,"tv":124.88,"id":4486603}]}]}
{"op":"mcm","clk":"1008305448","pt":1580632823410,"mc":[{"id":"1.168224423","rc":[{"batl":[[0,1.64,72.38]],"ltp":1.62,"tv":1304.02,"id":8260126},{"batl":[[2,3,42.01]],"ltp":2.58,"tv":124.88,"id":4486603}]}]}
{"op":"mcm","clk":"1008305463","pt":1580632823620,"mc":[{"id":"1.168224423","rc":[{"batl":[[2,2.7,2.05]],"ltp":2.58,"tv":124.88,"id":4486603}]}]}
{"op":"mcm","clk":"1008306866","pt":1580632845448,"mc":[{"id":"1.168224423","rc":[{"batl":[[0,1.64,70.11]],"ltp":1.62,"tv":1304.02,"id":8260126}]}]}
{"op":"mcm","clk":"1008307192","pt":1580632850141,"mc":[{"id":"1.168224423","rc":[{"batb":[[2,1.6,147.79]],"batl":[[0,1.64,204.54]],"ltp":1.62,"tv":1304.02,"id":8260126}]}]}
{"op":"mcm","clk":"1008311793","pt":1580632919432,"mc":[{"id":"1.168224423","rc":[{"batb":[[1,1.61,89.37]],"batl":[[0,1.64,200.54]],"ltp":1.62,"tv":1304.02,"id":8260126},{"trd":[[2.58,45.19]],"batb":[[0,2.58,5]],"batl":[[1,2.68,2.01]],"ltp":2.58,"tv":133.86,"id":4486603}],"tv":1437.88}]}
{"op":"mcm","clk":"1008311856","pt":1580632920417,"mc":[{"id":"1.168224423","rc":[{"trd":[[1.64,445.7]],"batb":[[0,1.64,21.41],[1,1.63,14.32],[2,1.62,18.02]],"batl":[[0,1.65,4],[1,1.66,6],[2,1.67,18.88]],"ltp":1.64,"tv":1717.17,"id":8260126},{"trd":[[2.58,54.69]],"batb":[[0,2.54,51.83],[1,2.52,5],[2,2.5,18.74]],"batl":[[0,2.6,8.32],[1,2.62,10.57],[2,2.64,10.04]],"ltp":2.58,"tv":143.36,"id":4486603}],"tv":1860.53}]}
{"op":"mcm","clk":"1008311916","pt":1580632921449,"mc":[{"id":"1.168224423","rc":[{"batl":[[0,1.65,6]],"ltp":1.64,"tv":1717.17,"id":8260126},{"trd":[[2.56,48.1]],"batb":[[0,2.54,52.83],[2,2.5,23.74]],"ltp":2.56,"tv":168.52,"id":4486603}],"tv":1885.69}]}
{"op":"mcm","clk":"1008312099","pt":1580632924342,"mc":[{"id":"1.168224423","rc":[{"batb":[[0,1.63,14.32],[1,1.62,18.02],[2,1.61,91.46]],"ltp":1.64,"tv":1717.17,"id":8260126}]}]}
{"op":"mcm","clk":"1008312158","pt":1580632925421,"mc":[{"id":"1.168224423","rc":[{"batb":[[0,1.62,15.98],[1,1.61,89.37],[2,1.6,154.83]],"ltp":1.64,"tv":1717.17,"id":8260126},{"batl":[[1,2.62,8.32]],"ltp":2.56,"tv":168.52,"id":4486603}]}]}
{"op":"mcm","clk":"1008312318","pt":1580632928421,"mc":[{"id":"1.168224423","rc":[{"trd":[[1.62,64.16]],"batb":[[0,1.61,89.37],[1,1.6,154.83],[2,1.59,2.11]],"batl":[[0,1.62,83.9],[1,1.65,6],[2,1.66,6]],"ltp":1.62,"tv":1762.48,"id":8260126},{"trd":[[2.6,8.32]],"batl":[[0,2.62,8.32],[1,2.64,10.04],[2,2.66,2.22]],"ltp":2.6,"tv":176.84,"id":4486603}],"tv":1939.32}]}
{"op":"mcm","clk":"1008312372","pt":1580632929450,"mc":[{"id":"1.168224423","rc":[{"trd":[[1.62,149.58]],"batb":[[1,1.6,146.79],[2,1.59,12.15]],"batl":[[0,1.62,41.19],[1,1.63,6.04],[2,1.64,8.22]],"ltp":1.62,"tv":1847.89,"id":8260126},{"batb":[[0,2.58,5.04],[1,2.56,7.12],[2,2.54,54.91]],"batl":[[0,2.66,5.04],[1,2.68,2.01],[2,2.7,2.05]],"ltp":2.6,"tv":176.84,"id":4486603}],"tv":2024.74}]}
{"op":"mcm","clk":"1008312424","pt":1580632930428,"mc":[{"id":"1.168224423","rc":[{"batb":[[0,1.61,21.11],[2,1.59,90.52]],"ltp":1.62,"tv":1847.89,"id":8260126},{"batb":[[1,2.56,39.72]],"batl":[[1,2.68,7.01]],"ltp":2.6,"tv":176.84,"id":4486603}]}]}
{"op":"mcm","clk":"1008312967","pt":1580632940453,"mc":[{"id":"1.168224423","rc":[{"batl":[[0,1.64,6.04],[1,1.65,6],[2,1.66,8.25]],"ltp":1.62,"tv":1847.89,"id":8260126},{"batb":[[1,2.56,37.64],[2,2.54,54.93]],"batl":[[0,2.64,5],[1,2.66,5.04],[2,2.68,7.01]],"ltp":2.6,"tv":176.84,"id":4486603}]}]}
{"op":"mcm","clk":"1008313016","pt":1580632941275,"mc":[{"id":"1.168224423","rc":[{"trd":[[1.61,77.19]],"batb":[[0,1.6,146.79],[1,1.59,90.52],[2,1.58,2.06]],"batl":[[0,1.61,20.54],[1,1.64,6.04],[2,1.65,6]],"ltp":1.61,"tv":1890.11,"id":8260126},{"batb":[[0,2.56,37.64],[1,2.54,52.83],[2,2.52,7.24]],"ltp":2.6,"tv":176.84,"id":4486603}],"tv":2066.96}]}
{"op":"mcm","clk":"1008313069","pt":1580632941946,"mc":[{"id":"1.168224423","rc":[{"trd":[[1.61,116.2]],"batb":[[1,1.59,88.41],[2,1.58,11.17]],"batl":[[0,1.61,1.03],[1,1.62,8.11],[2,1.63,8.11]],"ltp":1.61,"tv":1929.11,"id":8260126},{"batb":[[0,2.6,6.11],[1,2.56,39.7],[2,2.54,54.83]],"batl":[[0,2.68,5],[1,2.72,2.16],[2,2.74,2.05]],"ltp":2.6,"tv":176.84,"id":4486603}],"tv":2105.96}]}
{"op":"mcm","clk":"1008313163","pt":1580632943448,"mc":[{"id":"1.168224423","rc":[{"batl":[[1,1.63,8.11],[2,1.64,6.04]],"ltp":1.61,"tv":1929.11,"id":8260126},{"batl":[[0,2.66,4.12],[1,2.68,5],[2,2.7,2.05]],"ltp":2.6,"tv":176.84,"id":4486603}]}]}
{"op":"mcm","clk":"1008313213","pt":1580632944273,"mc":[{"id":"1.168224423","rc":[{"batl":[[2,1.64,8.31]],"ltp":1.61,"tv":1929.11,"id":8260126}]}]}
{"op":"mcm","clk":"1008313678","pt":1580632953357,"mc":[{"id":"1.168224423","rc":[{"batb":[[0,1.61,9.17],[1,1.6,146.79],[2,1.59,90.52]],"batl":[[0,1.64,8.31],[1,1.65,6],[2,1.66,8.01]],"ltp":1.61,"tv":1929.11,"id":8260126},{"batb":[[0,2.56,37.64],[1,2.54,54.83],[2,2.52,2.12]],"batl":[[0,2.64,5],[1,2.66,4.12],[2,2.68,7.14]],"ltp":2.6,"tv":176.84,"id":4486603}]}]}
{"op":"mcm","clk":"1008313735","pt":1580632954392,"mc":[{"id":"1.168224423","rc":[{"batb":[[1,2.54,52.83]],"ltp":2.6,"tv":176.84,"id":4486603}]}]}
{"op":"mcm","clk":"1008323119","pt":1580633160437,"mc":[{"id":"1.168224423","rc":[{"trd":[[1.61,126.33]],"batb":[[0,1.61,4.1]],"ltp":1.61,"tv":1939.25,"id":8260126}],"tv":2116.09}]}
{"op":"mcm","clk":"1008349162","pt":1580633724382,"mc":[{"id":"1.168224423","rc":[{"batb":[[0,1.62,137.79],[1,1.61,4.1],[2,1.6,9]],"ltp":1.61,"tv":1939.25,"id":8260126}]}]}
{"op":"mcm","clk":"1008349204","pt":1580633725306,"mc":[{"id":"1.168224423","rc":[{"batb":[[0,1.62,148.79],[1,1.61,11.13],[2,1.6,11.04]],"batl":[[0,1.64,2.27],[1,1.65,11],[2,1.66,12.01]],"ltp":1.61,"tv":1939.25,"id":8260126},{"batb":[[0,2.56,40.6],[1,2.54,55.83]],"batl":[[0,2.62,6],[1,2.66,6.37]],"ltp":2.6,"tv":176.84,"id":4486603}]}]}
{"op":"mcm","clk":"1008349282","pt":1580633727100,"mc":[{"id":"1.168224423","rc":[{"batl":[[0,1.64,3.95]],"ltp":1.61,"tv":1939.25,"id":8260126}]}]}
{"op":"mcm","clk":"1008349565","pt":1580633733409,"mc":[{"id":"1.168224423","rc":[{"batl":[[2,2.68,7.01]],"ltp":2.6,"tv":176.84,"id":4486603}]}]}
{"op":"mcm","clk":"1008351772","pt":1580633773342,"mc":[{"id":"1.168224423","rc":[{"batb":[[0,1.63,238.17],[1,1.62,148.79],[2,1.61,13.15]],"ltp":1.61,"tv":1939.25,"id":8260126},{"batb":[[0,2.56,32.6],[2,2.52,10.12]],"batl":[[0,2.6,6],[1,2.62,6],[2,2.66,6.37]],"ltp":2.6,"tv":176.84,"id":4486603}]}]}
{"op":"mcm","clk":"1008351805","pt":1580633773907,"mc":[{"id":"1.168224423","rc":[{"batl":[[2,2.64,2.04]],"ltp":2.6,"tv":176.84,"id":4486603}]}]}
{"op":"mcm","clk":"1008355417","pt":1580633824993,"mc":[{"id":"1.168224423","rc":[{"trd":[[1.63,151.88]],"batb":[[0,1.63,170.17]],"ltp":1.63,"tv":2075.25,"id":8260126}],"tv":2252.09}]}
{"op":"mcm","clk":"1008355655","pt":1580633829405,"mc":[{"id":"1.168224423","rc":[{"trd":[[1.63,201.01]],"batb":[[0,1.63,145.61]],"ltp":1.63,"tv":2124.38,"id":8260126},{"batb":[[0,2.54,85.76],[1,2.52,10.12],[2,2.5,2]],"ltp":2.6,"tv":176.84,"id":4486603}],"tv":2301.23}]}
{"op":"mcm","clk":"1008355677","pt":1580633829713,"mc":[{"id":"1.168224423","rc":[{"batb":[[1,2.52,10.24]],"ltp":2.6,"tv":176.84,"id":4486603}]}]}
{"op":"mcm","clk":"1008358478","pt":1580633877419,"mc":[{"id":"1.168224423","rc":[{"batb":[[0,1.63,978.56]],"ltp":1.63,"tv":2124.38,"id":8260126},{"batb":[[2,2.48,2.01]],"ltp":2.6,"tv":176.84,"id":4486603}]}]}
{"op":"mcm","clk":"1008358532","pt":1580633878446,"mc":[{"id":"1.168224423","rc":[{"trd":[[1.63,437.01],[1.64,453.6]],"batb":[[0,1.64,11.11],[1,1.63,860.56],[2,1.62,150.81]],"batl":[[0,1.66,10],[1,1.67,22.88],[2,1.68,2.14]],"ltp":1.64,"tv":2368.28,"id":8260126},{"batb":[[0,2.54,77.76],[1,2.52,8],[2,2.5,2]],"batl":[[0,2.58,6.31],[1,2.6,6],[2,2.62,8]],"ltp":2.6,"tv":176.84,"id":4486603}],"tv":2545.12}]}
{"op":"mcm","clk":"1008359616","pt":1580633899172,"mc":[{"id":"1.168224423","rc":[{"batl":[[2,1.68,2.01]],"ltp":1.64,"tv":2368.28,"id":8260126},{"batb":[[2,2.5,11]],"ltp":2.6,"tv":176.84,"id":4486603}]}]}
{"op":"mcm","clk":"1008359657","pt":1580633900043,"mc":[{"id":"1.168224423","rc":[{"trd":[[1.64,475.18]],"batb":[[0,1.64,11],[2,1.62,150.83]],"ltp":1.64,"tv":2389.86,"id":8260126},{"batl":[[0,2.6,6],[1,2.62,8],[2,2.64,2.04]],"ltp":2.6,"tv":176.84,"id":4486603}],"tv":2566.7}]}
{"op":"mcm","clk":"1008360221","pt":1580633911170,"mc":[{"id":"1.168224423","rc":[{"trd":[[1.65,55.26]],"batl":[[2,1.68,2.14]],"ltp":1.65,"tv":2389.88,"id":8260126},{"trd":[[2.54,15.45]],"batb":[[0,2.54,77.74]],"batl":[[0,2.58,5],[1,2.6,6],[2,2.62,8]],"ltp":2.54,"tv":176.86,"id":4486603}],"tv":2566.74}]}
{"op":"mcm","clk":"1008362596","pt":1580633956356,"mc":[{"id":"1.168224423","rc":[{"trd":[[1.64,497.18],[1.65,122.47]],"batb":[[0,1.64,10],[2,1.62,186.72]],"batl":[[0,1.66,14],[1,1.67,26.88]],"ltp":1.65,"tv":2479.09,"id":8260126},{"trd":[[2.54,59.07]],"batb":[[0,2.54,4.19],[1,2.52,44.02]],"ltp":2.54,"tv":220.48,"id":4486603}],"tv":2699.58}]}
{"op":"mcm","clk":"1008362635","pt":1580633957130,"mc":[{"id":"1.168224423","rc":[{"trd":[[2.58,64.49]],"batl":[[0,2.6,6.1],[1,2.62,8.17],[2,2.64,2.01]],"ltp":2.58,"tv":230.28,"id":4486603}],"tv":2709.38}]}
{"op":"mcm","clk":"1008363853","pt":1580633983251,"mc":[{"id":"1.168224423","rc":[{"trd":[[1.64,517.18]],"batb":[[0,1.63,860.56],[1,1.62,186.72],[2,1.61,13.22]],"ltp":1.64,"tv":2499.09,"id":8260126}],"tv":2729.37}]}
{"op":"mcm","clk":"1008363920","pt":1580633984382,"mc":[{"id":"1.168224423","rc":[{"trd":[[1.63,1454.42],[1.64,557.66],[1.65,128.61]],"batb":[[0,1.63,351.86],[1,1.62,184.68]],"batl":[[0,1.64,10.18],[1,1.67,30.87]],"ltp":1.63,"tv":3563.12,"id":8260126},{"trd":[[2.54,63.05],[2.58,74.23]],"batb":[[0,2.52,36.23],[1,2.5,14],[2,2.48,2.01]],"batl":[[0,2.58,5],[1,2.6,6],[2,2.62,6]],"ltp":2.58,"tv":244.0,"id":4486603}],"tv":3807.13}]}
{"op":"mcm","clk":"1008363980","pt":1580633985359,"mc":[{"id":"1.168224423","rc":[{"batb":[[0,1.64,9.24],[1,1.63,360.86],[2,1.62,186.72]],"batl":[[0,1.67,10.87],[1,1.68,22.38],[2,1.69,2.08]],"ltp":1.63,"tv":3563.12,"id":8260126},{"trd":[[2.52,72.04],[2.54,63.47]],"batb":[[0,2.48,19.01],[1,2.46,2.01],[2,2.44,19.67]],"batl":[[0,2.58,5.24],[2,2.62,8.01]],"ltp":2.52,"tv":316.46,"id":4486603}],"tv":3879.59}]}
{"op":"mcm","clk":"1008364003","pt":1580633985773,"mc":[{"id":"1.168224423","rc":[{"batb":[[0,1.66,9],[1,1.65,9.25],[2,1.64,11.31]],"batl":[[1,1.68,20.24],[2,1.69,22.33]],"ltp":1.63,"tv":3563.12,"id":8260126},{"trd":[[2.5,9.46]],"batb":[[0,2.46,17],[1,2.44,19.17],[2,2.42,2.01]],"batl":[[0,2.5,68.03],[1,2.54,7.25],[2,2.56,7.26]],"ltp":2.5,"tv":325.92,"id":4486603}],"tv":3889.05}]}
{"op":"mcm","clk":"1008364098","pt":1580633987375,"mc":[{"id":"1.168224423","rc":[{"trd":[[1.67,21.74]],"batb":[[0,1.68,10.25],[1,1.67,172.51],[2,1.66,11]],"batl":[[0,1.71,20.25],[1,1.72,2.16],[2,1.73,2.69]],"ltp":1.67,"tv":3584.86,"id":8260126},{"batb":[[0,2.4,18],[1,2.38,20.44],[2,2.36,2]],"batl":[[0,2.48,5.25],[1,2.5,73.03],[2,2.52,7.01]],"ltp":2.5,"tv":325.92,"id":4486603}],"tv":3910.78}]}
{"op":"mcm","clk":"1008364120","pt":1580633987783,"mc":[{"id":"1.168224423","rc":[{"batl":[[0,1.72,22.42],[1,1.73,2.69],[2,1.74,2.05]],"ltp":1.67,"tv":3584.86,"id":8260126},{"batb":[[0,2.44,55.61],[1,2.4,2.01],[2,2.38,21.17]],"ltp":2.5,"tv":325.92,"id":4486603}]}]}
{"op":"mcm","clk":"1008364261","pt":1580633990360,"mc":[{"id":"1.168224423","rc":[{"batb":[[0,1.67,172.51],[1,1.66,9],[2,1.65,11.27]],"batl":[[0,1.7,20],[1,1.72,22.42],[2,1.73,2.69]],"ltp":1.67,"tv":3584.86,"id":8260126},{"batb":[[0,2.44,73.61],[1,2.42,18.27],[2,2.4,2.01]],"batl":[[0,2.5,5],[1,2.52,5],[2,2.54,2]],"ltp":2.5,"tv":325.92,"id":4486603}]}]}
{"op":"mcm","clk":"1008364295","pt":1580633991079,"mc":[{"id":"1.168224423","rc":[{"batb":[[0,1.67,117.94]],"ltp":1.67,"tv":3584.86,"id":8260126}]}]}
{"op":"mcm","clk":"1008364353","pt":1580633992303,"mc":[{"id":"1.168224423","rc":[{"batb":[[0,1.65,9.25],[1,1.64,51.21],[2,1.63,353.93]],"ltp":1.67,"tv":3584.86,"id":8260126},{"batl":[[0,2.56,5.28],[1,2.58,2.13],[2,2.6,2.01]],"ltp":2.5,"tv":325.92,"id":4486603}]}]}
{"op":"mcm","clk":"1008364384","pt":1580633992768,"mc":[{"id":"1.168224423","rc":[{"batl":[[1,2.58,2.25]],"ltp":2.5,"tv":325.92,"id":4486603}]}]}
{"op":"mcm","clk":"1008364474","pt":1580633994372,"mc":[{"id":"1.168224423","rc":[{"trd":[[1.65,136.31]],"batb":[[0,1.65,10]],"batl":[[2,1.73,2.54]],"ltp":1.65,"tv":3592.56,"id":8260126},{"trd":[[2.54,68.47]],"batl":[[0,2.56,7.29]],"ltp":2.54,"tv":330.92,"id":4486603}],"tv":3923.48}]}
{"op":"mcm","clk":"1008364502","pt":1580633994774,"mc":[{"id":"1.168224423","rc":[{"batl":[[0,2.56,5.28]],"ltp":2.54,"tv":330.92,"id":4486603}]}]}
{"op":"mcm","clk":"1008365048","pt":1580634003316,"mc":[{"id":"1.168224423","rc":[{"batl":[[0,2.56,7.45],[1,2.6,2],[2,3,42.01]],"ltp":2.54,"tv":330.92,"id":4486603}]}]}
{"op":"mcm","clk":"1008365160","pt":1580634004285,"mc":[{"id":"1.168224423","rc":[{"trd":[[1.65,155.95]],"batb":[[0,1.64,51.39],[1,1.63,351.86],[2,1.62,139.83]],"ltp":1.65,"tv":3612.2,"id":8260126},{"trd":[[2.44,81.96]],"batb":[[0,2.44,32.64]],"batl":[[0,2.56,5.28],[2,2.62,2.25]],"ltp":2.44,"tv":412.88,"id":4486603}],"tv":4025.08}]}
{"op":"mcm","clk":"1008365352","pt":1580634006370,"mc":[{"id":"1.168224423","rc":[{"batb":[[0,2.44,18]],"ltp":2.44,"tv":412.88,"id":4486603}]}]}
{"op":"mcm","clk":"1008365417","pt":1580634007211,"mc":[{"id":"1.168224423","rc":[{"batb":[[0,1.65,69.4],[1,1.64,51.21],[2,1.63,353.93]],"batl":[[0,1.67,2],[1,1.68,21.03],[2,1.69,23.11]],"ltp":1.65,"tv":3612.2,"id":8260126},{"batb":[[1,2.42,20.28],[2,2.4,46.65]],"batl":[[0,2.54,5],[1,2.56,5.28],[2,2.58,2.25]],"ltp":2.44,"tv":412.88,"id":4486603}]}]}
{"op":"mcm","clk":"1008366061","pt":1580634017285,"mc":[{"id":"1.168224423","rc":[{"batb":[[0,2.44,33.77],[2,2.4,44.64]],"ltp":2.44,"tv":412.88,"id":4486603}]}]}
{"op":"mcm","clk":"1008366121","pt":1580634018411,"mc":[{"id":"1.168224423","rc":[{"batb":[[2,2.4,46.65]],"ltp":2.44,"tv":412.88,"id":4486603}]}]}
{"op":"mcm","clk":"1008366160","pt":1580634019029,"mc":[{"id":"1.168224423","rc":[{"batb":[[2,1.63,2.07]],"ltp":1.65,"tv":3612.2,"id":8260126}]}]}
{"op":"mcm","clk":"1008369016","pt":1580634068176,"mc":[{"id":"1.168224423","rc":[{"batb":[[2,2.4,44.64]],"ltp":2.44,"tv":412.88,"id":4486603}]}]}
{"op":"mcm","clk":"1008369102","pt":1580634069366,"mc":[{"id":"1.168224423","rc":[{"trd":[[1.65,291.55]],"batb":[[0,1.65,1.6],[1,1.64,9.24],[2,1.62,139.83]],"ltp":1.65,"tv":3747.8,"id":8260126},{"batb":[[2,2.4,2.01]],"ltp":2.44,"tv":412.88,"id":4486603}],"tv":4160.68}]}
{"op":"mcm","clk":"1008369152","pt":1580634070195,"mc":[{"id":"1.168224423","rc":[{"batb":[[0,1.64,9.24],[1,1.63,66.6]],"batl":[[0,1.67,19],[1,1.68,23.04]],"ltp":1.65,"tv":3747.8,"id":8260126},{"batb":[[0,2.5,15.05],[1,2.46,43.09],[2,2.44,35.94]],"batl":[[0,2.58,3],[1,2.62,2.25],[2,2.64,2.04]],"ltp":2.44,"tv":412.88,"id":4486603}]}]}
{"op":"mcm","clk":"1008369192","pt":1580634070759,"mc":[{"id":"1.168224423","rc":[{"batl":[[1,1.68,21.03]],"ltp":1.65,"tv":3747.8,"id":8260126}]}]}
{"op":"mcm","clk":"1008369322","pt":1580634073181,"mc":[{"id":"1.168224423","rc":[{"batb":[[0,1.63,66.6],[1,1.62,144.79],[2,1.61,9.09]],"batl":[[0,1.65,168.45],[1,1.66,17.06],[2,1.67,21.01]],"ltp":1.65,"tv":3747.8,"id":8260126},{"batb":[[0,2.54,14.06],[1,2.5,17.05],[2,2.48,2.01]],"batl":[[0,2.62,3],[1,2.64,2.04],[2,2.66,2.22]],"ltp":2.44,"tv":412.88,"id":4486603}]}]}
{"op":"mcm","clk":"1008370274","pt":1580634091393,"mc":[{"id":"1.168224423","rc":[{"batl":[[2,2.66,2.25]],"ltp":2.44,"tv":412.88,"id":4486603}]}]}
{"op":"mcm","clk":"1008370329","pt":1580634092268,"mc":[{"id":"1.168224423","rc":[{"trd":[[1.63,1584.16]],"batb":[[0,1.63,1.73],[2,1.61,7]],"ltp":1.63,"tv":3877.54,"id":8260126},{"batl":[[1,2.66,2.25],[2,2.68,2.14]],"ltp":2.44,"tv":412.88,"id":4486603}],"tv":4290.42}]}
{"op":"mcm","clk":"1008370439","pt":1580634094380,"mc":[{"id":"1.168224423","rc":[{"trd":[[1.63,1598.52]],"batb":[[0,1.62,144.79],[1,1.61,81.29],[2,1.6,2.04]],"batl":[[0,1.63,144.27],[1,1.65,17],[2,1.66,19.31]],"ltp":1.63,"tv":3891.9,"id":8260126},{"batb":[[1,2.52,30.05],[2,2.5,17.05]],"batl":[[0,2.6,3.18],[1,2.62,3],[2,2.66,2.25]],"ltp":2.44,"tv":412.88,"id":4486603}],"tv":4304.78}]}
{"op":"mcm","clk":"1008370463","pt":1580634094891,"mc":[{"id":"1.168224423","rc":[{"batb":[[0,1.62,137.79],[2,1.6,10.22]],"batl":[[1,1.64,19.18],[2,1.65,19.1]],"ltp":1.63,"tv":3891.9,"id":8260126},{"batb":[[0,2.58,15],[1,2.56,15.18],[2,2.54,16.18]],"batl":[[0,2.64,4],[1,2.66,2.25],[2,2.68,2.14]],"ltp":2.44,"tv":412.88,"id":4486603}]}]}
{"op":"mcm","clk":"1008372688","pt":1580634134107,"mc":[{"id":"1.168224423","rc":[{"trd":[[1.61,151.54],[1.62,497.69]],"batb":[[0,1.61,25.49],[1,1.6,8.18],[2,1.59,10.29]],"batl":[[0,1.62,219.49],[1,1.63,166.27],[2,1.64,21.22]],"ltp":1.62,"tv":4265.22,"id":8260126},{"batb":[[0,2.56,2.08],[1,2.54,2.12],[2,2.52,29.91]],"batl":[[0,2.68,7.14],[1,2.7,2.05],[2,3,42.01]],"ltp":2.44,"tv":412.88,"id":4486603}],"tv":4678.1}]}
{"op":"mcm","clk":"1008372772","pt":1580634135442,"mc":[{"id":"1.168224423","rc":[{"batb":[[0,1.59,78.34],[1,1.58,10.07],[2,1.57,168.34]],"batl":[[0,1.61,22.08],[1,1.62,219.49],[2,1.63,168.31]],"ltp":1.62,"tv":4265.22,"id":8260126},{"batb":[[0,2.58,2.06],[1,2.56,2.08],[2,2.54,37.06]],"batl":[[0,2.72,4.08],[1,2.74,2.05],[2,2.76,2.02]],"ltp":2.44,"tv":412.88,"id":4486603}]}]}
{"op":"mcm","clk":"1008372905","pt":1580634137737,"mc":[{"id":"1.168224423","rc":[{"batb":[[2,2.54,53.43]],"ltp":2.44,"tv":412.88,"id":4486603}]}]}
{"op":"mcm","clk":"1008374308","pt":1580634161840,"mc":[{"id":"1.168224423","rc":[{"batb":[[2,2.54,47.32]],"ltp":2.44,"tv":412.88,"id":4486603}]}]}
{"op":"mcm","clk":"1008375634","pt":1580634184290,"mc":[{"id":"1.168224423","rc":[{"batb":[[1,2.54,47.32],[2,2.52,44.4]],"batl":[[2,3,42.01]],"ltp":2.44,"tv":412.88,"id":4486603}]}]}
{"op":"mcm","clk":"1008375649","pt":1580634184487,"mc":[{"id":"1.168224423","rc":[{"batb":[[1,2.56,2.08],[2,2.54,47.32]],"batl":[[2,2.76,2.02]],"ltp":2.44,"tv":412.88,"id":4486603}]}]}
{"op":"mcm","clk":"1008377769","pt":1580634218400,"mc":[{"id":"1.168224423","rc":[{"trd":[[1.61,195.7]],"batl":[[0,1.62,219.49],[1,1.63,168.31],[2,1.64,21.19]],"ltp":1.61,"tv":4309.38,"id":8260126}],"tv":4722.26}]}
{"op":"mcm","clk":"1008377838","pt":1580634219428,"mc":[{"id":"1.168224423","rc":[{"batb":[[0,1.58,93.64],[1,1.57,179.28],[2,1.56,2.53]],"batl":[[0,1.61,26],[1,1.62,219.49],[2,1.63,168.31]],"ltp":1.61,"tv":4309.38,"id":8260126},{"batb":[[0,2.6,21.34],[1,2.58,2.02],[2,2.54,18.49]],"batl":[[0,2.74,6],[1,2.78,2.25],[2,2.8,2.02]],"ltp":2.44,"tv":412.88,"id":4486603}]}]}
{"op":"mcm","clk":"1008377844","pt":1580634219528,"mc":[{"id":"1.168224423","rc":[{"batb":[[2,2.56,2.08]],"ltp":2.44,"tv":412.88,"id":4486603}]}]}
{"op":"mcm","clk":"1008378428","pt":1580634229421,"mc":[{"id":"1.168224423","rc":[{"batl":[[0,1.62,22],[1,1.63,166.27],[2,1.64,28.04]],"ltp":1.61,"tv":4309.38,"id":8260126},{"batb":[[1,2.56,2.06],[2,2.54,18.49]],"batl":[[0,2.72,6.26],[1,2.74,6],[2,2.76,2.02]],"ltp":2.44,"tv":412.88,"id":4486603}]}]}
{"op":"mcm","clk":"1008379585","pt":1580634250325,"mc":[{"id":"1.168224423","rc":[{"batl":[[0,1.62,24.27]],"ltp":1.61,"tv":4309.38,"id":8260126}]}]}
{"op":"mcm","clk":"1008383159","pt":1580634319321,"mc":[{"id":"1.168224423","rc":[{"batl":[[0,1.61,43.37],[1,1.62,24.27],[2,1.63,166.27]],"ltp":1.61,"tv":4309.38,"id":8260126}]}]}
{"op":"mcm","clk":"1008383204","pt":1580634320040,"mc":[{"id":"1.168224423","rc":[{"batl":[[2,1.63,168.27]],"ltp":1.61,"tv":4309.38,"id":8260126},{"batb":[[1,2.58,2.06],[2,2.56,2.08]],"ltp":2.44,"tv":412.88,"id":4486603}]}]}
{"op":"mcm","clk":"1008385396","pt":1580634359276,"mc":[{"id":"1.168224423","rc":[{"batl":[[1,1.62,26.54]],"ltp":1.61,"tv":4309.38,"id":8260126}]}]}
{"op":"mcm","clk":"1008385839","pt":1580634366283,"mc":[{"id":"1.168224423","rc":[{"trd":[[2.72,12.52]],"batb":[[0,2.72,111.29],[1,2.6,21.34],[2,2.58,2.06]],"batl":[[0,2.74,6],[1,2.76,2.02],[2,2.78,2.25]],"ltp":2.72,"tv":425.4,"id":4486603}],"tv":4734.78}]}
{"op":"mcm","clk":"1008385907","pt":1580634367310,"mc":[{"id":"1.168224423","rc":[{"batb":[[0,1.58,83.57],[2,1.56,16.56]],"batl":[[0,1.59,29],[1,1.6,29.03],[2,1.61,74.51]],"ltp":1.61,"tv":4309.38,"id":8260126},{"trd":[[2.72,26.52]],"batb":[[0,2.72,104.29],[1,2.68,24.03],[2,2.66,24.31]],"batl":[[0,2.78,8.05],[1,2.8,2.02],[2,2.82,2.08]],"ltp":2.72,"tv":439.4,"id":4486603}],"tv":4748.78}]}
{"op":"mcm","clk":"1008386964","pt":1580634387116,"mc":[{"id":"1.168224423","rc":[{"batb":[[1,2.7,22.04],[2,2.68,24.03]],"ltp":2.72,"tv":439.4,"id":4486603}]}]}
{"op":"mcm","clk":"1008387007","pt":1580634387731,"mc":[{"id":"1.168224423","rc":[{"batl":[[2,3,42.01]],"ltp":2.72,"tv":439.4,"id":4486603}]}]}
{"op":"mcm","clk":"1008392916","pt":1580634483404,"mc":[{"id":"1.168224423","rc":[{"trd":[[2.72,119.19]],"batb":[[0,2.72,57.96]],"ltp":2.72,"tv":532.07,"id":4486603}],"tv":4841.45}]}
{"op":"mcm","clk":"1008392989","pt":1580634484277,"mc":[{"id":"1.168224423","rc":[{"batb":[[0,1.57,166.28],[1,1.56,14.48],[2,1.55,16.11]],"ltp":1.61,"tv":4309.38,"id":8260126},{"batb":[[0,2.72,101.96],[2,2.68,45.87]],"batl":[[0,2.78,6.03],[2,2.82,2.08]],"ltp":2.72,"tv":532.07,"id":4486603}]}]}
{"op":"mcm","clk":"1008393123","pt":1580634486178,"mc":[{"id":"1.168224423","rc":[{"batb":[[0,2.72,79.96]],"batl":[[1,2.8,8.02]],"ltp":2.72,"tv":532.07,"id":4486603}]}]}
{"op":"mcm","clk":"1008394108","pt":1580634502423,"mc":[{"id":"1.168224423","rc":[{"batl":[[0,1.59,71.01]],"ltp":1.61,"tv":4309.38,"id":8260126}]}]}
{"op":"mcm","clk":"1008394340","pt":1580634506220,"mc":[{"id":"1.168224423","rc":[{"batl":[[0,1.58,173.27],[1,1.59,71.01],[2,1.6,29.03]],"ltp":1.61,"tv":4309.38,"id":8260126}]}]}
{"op":"mcm","clk":"1008394408","pt":1580634507195,"mc":[{"id":"1.168224423","rc":[{"batl":[[2,1.6,31.04]],"ltp":1.61,"tv":4309.38,"id":8260126}]}]}
{"op":"mcm","clk":"1008397002","pt":1580634548413,"mc":[{"id":"1.168224423","rc":[{"batl":[[0,1.58,29]],"ltp":1.61,"tv":4309.38,"id":8260126},{"batl":[[2,3,42.01]],"ltp":2.72,"tv":532.07,"id":4486603}]}]}
{"op":"mcm","clk":"1008397014","pt":1580634548619,"mc":[{"id":"1.168224423","rc":[{"batl":[[2,2.82,2.08]],"ltp":2.72,"tv":532.07,"id":4486603}]}]}
{"op":"mcm","clk":"1008397587","pt":1580634558311,"mc":[{"id":"1.168224423","rc":[{"trd":[[1.57,328.14]],"batb":[[0,1.57,2.19]],"ltp":1.57,"tv":4637.52,"id":8260126},{"batl":[[0,2.8,8.02],[1,3,42.01],[2,3.85,229.44]],"ltp":2.72,"tv":532.07,"id":4486603}],"tv":5169.59}]}
{"op":"mcm","clk":"1008397624","pt":1580634558934,"mc":[{"id":"1.168224423","rc":[{"batl":[[0,2.8,6],[1,2.84,2.03],[2,2.86,2.03]],"ltp":2.72,"tv":532.07,"id":4486603}]}]}
{"op":"mcm","clk":"1008399288","pt":1580634586340,"mc":[{"id":"1.168224423","rc":[{"batl":[[0,1.59,71.01],[1,1.6,29.03],[2,1.61,74.51]],"ltp":1.57,"tv":4637.52,"id":8260126},{"batb":[[0,2.72,57.96]],"batl":[[2,3,42.01]],"ltp":2.72,"tv":532.07,"id":4486603}]}]}
{"op":"mcm","clk":"1008399304","pt":1580634586548,"mc":[{"id":"1.168224423","rc":[{"batl":[[2,2.86,2.03]],"ltp":2.72,"tv":532.07,"id":4486603}]}]}
{"op":"mcm","clk":"1008399658","pt":1580634593256,"mc":[{"id":"1.168224423","rc":[{"batl":[[0,1.58,15.14],[1,1.59,71.01],[2,1.6,31.04]],"ltp":1.57,"tv":4637.52,"id":8260126},{"batl":[[2,3,42.01]],"ltp":2.72,"tv":532.07,"id":4486603}]}]}
{"op":"mcm","clk":"1008399679","pt":1580634593674,"mc":[{"id":"1.168224423","rc":[{"batl":[[2,2.86,2.03]],"ltp":2.72,"tv":532.07,"id":4486603}]}]}
{"op":"mcm","clk":"1008400979","pt":1580634615260,"mc":[{"id":"1.168224423","rc":[{"batb":[[2,1.55,106.31]],"ltp":1.57,"tv":4637.52,"id":8260126},{"batl":[[2,3,42.01]],"ltp":2.72,"tv":532.07,"id":4486603}]}]}
{"op":"mcm","clk":"1008400991","pt":1580634615465,"mc":[{"id":"1.168224423","rc":[{"batl":[[2,2.86,2.25]],"ltp":2.72,"tv":532.07,"id":4486603}]}]}
{"op":"mcm","clk":"1008401219","pt":1580634619378,"mc":[{"id":"1.168224423","rc":[{"trd":[[1.57,332.52]],"batb":[[0,1.55,104.68],[1,1.54,14.14],[2,1.53,16.26]],"batl":[[0,1.57,12.96],[1,1.58,29.1],[2,1.59,73.02]],"ltp":1.57,"tv":4641.89,"id":8260126},{"batb":[[0,2.72,79.96],[1,2.7,24.06],[2,2.68,43.87]],"batl":[[0,2.82,6],[1,2.84,8.13]],"ltp":2.72,"tv":532.07,"id":4486603}],"tv":5173.97}]}
{"op":"mcm","clk":"1008401252","pt":1580634619895,"mc":[{"id":"1.168224423","rc":[{"batb":[[0,1.55,90.65]],"batl":[[0,1.57,42.06]],"ltp":1.57,"tv":4641.89,"id":8260126},{"batb":[[2,2.68,45.92]],"batl":[[0,2.84,6.1],[1,2.86,2.03],[2,2.88,2.04]],"ltp":2.72,"tv":532.07,"id":4486603}]}]}
{"op":"mcm","clk":"1008407660","pt":1580634712319,"mc":[{"id":"1.168224423","rc":[{"batb":[[0,2.72,121.13],[2,2.68,43.87]],"batl":[[2,3,42.01]],"ltp":2.72,"tv":532.07,"id":4486603}]}]}
{"op":"mcm","clk":"1008407672","pt":1580634712526,"mc":[{"id":"1.168224423","rc":[{"batb":[[2,2.68,45.98]],"batl":[[2,2.88,2.04]],"ltp":2.72,"tv":532.07,"id":4486603}]}]}
{"op":"mcm","clk":"1008408356","pt":1580634724323,"mc":[{"id":"1.168224423","rc":[{"batl":[[0,2.86,6.03],[1,2.88,2.04],[2,3,42.01]],"ltp":2.72,"tv":532.07,"id":4486603}]}]}
{"op":"mcm","clk":"1008408422","pt":1580634725452,"mc":[{"id":"1.168224423","rc":[{"trd":[[1.56,0.9]],"batb":[[0,1.55,90.2]],"batl":[[0,1.56,1.82],[1,1.57,42.06],[2,1.58,29.1]],"ltp":1.56,"tv":4642.79,"id":8260126},{"batb":[[2,2.68,45.89]],"batl":[[1,2.88,2.02]],"ltp":2.72,"tv":532.07,"id":4486603}],"tv":5174.86}]}
{"op":"mcm","clk":"1008409622","pt":1580634746055,"mc":[{"id":"1.168224423","rc":[{"batb":[[0,2.72,63.17],[2,2.68,45.95]],"batl":[[1,2.88,2.04]],"ltp":2.72,"tv":532.07,"id":4486603}]}]}
{"op":"mcm","clk":"1008409816","pt":1580634749450,"mc":[{"id":"1.168224423","rc":[{"trd":[[1.56,4.54],[1.57,393.07]],"batb":[[0,1.55,57.96]],"batl":[[0,1.57,11.78],[1,1.58,29.1],[2,1.59,73.02]],"ltp":1.57,"tv":4707.0,"id":8260126}],"tv":5239.07}]}
{"op":"mcm","clk":"1008409876","pt":1580634750432,"mc":[{"id":"1.168224423","rc":[{"batb":[[0,1.54,102.28],[1,1.53,14.1],[2,1.52,13.26]],"batl":[[0,1.58,29.1],[1,1.59,71.01],[2,1.6,31.03]],"ltp":1.57,"tv":4707.0,"id":8260126},{"batb":[[1,2.7,40.64]],"batl":[[0,2.88,5.16],[1,2.9,2.05],[2,2.92,2.06]],"ltp":2.72,"tv":532.07,"id":4486603}]}]}
{"op":"mcm","clk":"1008409919","pt":1580634751257,"mc":[{"id":"1.168224423","rc":[{"batl":[[0,2.86,5],[1,2.88,5.16],[2,2.9,2.05]],"ltp":2.72,"tv":532.07,"id":4486603}]}]}
{"op":"mcm","clk":"1008410176","pt":1580634755449,"mc":[{"id":"1.168224423","rc":[{"batl":[[0,1.57,7.57],[1,1.58,29.1],[2,1.59,73.07]],"ltp":1.57,"tv":4707.0,"id":8260126},{"batb":[[1,2.7,42.66],[2,2.68,43.87]],"batl":[[1,2.88,7.2]],"ltp":2.72,"tv":532.07,"id":4486603}]}]}
{"op":"mcm","clk":"1008410215","pt":1580634755959,"mc":[{"id":"1.168224423","rc":[{"batl":[[0,1.56,24.19],[1,1.57,7.57],[2,1.58,31.35]],"ltp":1.57,"tv":4707.0,"id":8260126},{"batb":[[0,2.74,2.02],[1,2.72,65.26],[2,2.7,42.66]],"batl":[[1,2.88,5.16]],"ltp":2.72,"tv":532.07,"id":4486603}]}]}
{"op":"mcm","clk":"1008410327","pt":1580634757451,"mc":[{"id":"1.168224423","rc":[{"batl":[[0,1.57,24.2],[1,1.58,29.1],[2,1.59,73.07]],"ltp":1.57,"tv":4707.0,"id":8260126},{"batb":[[0,2.72,22],[1,2.7,42.66],[2,2.68,102.15]],"batl":[[0,2.84,5.2],[1,2.86,5],[2,2.88,7.2]],"ltp":2.72,"tv":532.07,"id":4486603}]}]}
{"op":"mcm","clk":"1008410374","pt":1580634757971,"mc":[{"id":"1.168224423","rc":[{"batl":[[0,1.58,29.1],[1,1.59,71.01],[2,1.6,31.04]],"ltp":1.57,"tv":4707.0,"id":8260126},{"batb":[[1,2.7,40.64],[2,2.68,87.15]],"ltp":2.72,"tv":532.07,"id":4486603}]}]}
{"op":"mcm","clk":"1008411631","pt":1580634777431,"mc":[{"id":"1.168224423","rc":[{"batl":[[0,1.57,2],[1,1.58,29.1],[2,1.59,73.07]],"ltp":1.57,"tv":4707.0,"id":8260126}]}]}
{"op":"mcm","clk":"1008412620","pt":1580634795346,"mc":[{"id":"1.168224423","rc":[{"batl":[[0,1.57,26.08]],"ltp":1.57,"tv":4707.0,"id":8260126},{"batb":[[1,2.7,42.66]],"ltp":2.72,"tv":532.07,"id":4486603}]}]}
{"op":"mcm","clk":"1008414800","pt":1580634833370,"mc":[{"id":"1.168224423","rc":[{"trd":[[1.54,204.57]],"batb":[[0,1.53,9],[1,1.52,73.82],[2,1.51,56.68]],"batl":[[1,1.58,21],[2,1.59,65.07]],"ltp":1.54,"tv":4911.57,"id":8260126},{"trd":[[2.84,0.01]],"batb":[[0,2.78,35.42],[1,2.76,16.28],[2,2.74,2.02]],"batl":[[0,2.9,4],[1,2.92,2.04],[2,2.94,2.08]],"ltp":2.84,"tv":532.08,"id":4486603}],"tv":5443.65}]}
{"op":"mcm","clk":"1008414862","pt":1580634834455,"mc":[{"id":"1.168224423","rc":[{"batb":[[0,2.8,16.29],[1,2.78,35.42],[2,2.76,16.28]],"batl":[[1,2.94,2.08],[2,2.96,2]],"ltp":2.84,"tv":532.08,"id":4486603}]}]}
{"op":"mcm","clk":"1008414896","pt":1580634835071,"mc":[{"id":"1.168224423","rc":[{"batl":[[1,1.58,23.25]],"ltp":1.54,"tv":4911.57,"id":8260126},{"batb":[[2,2.76,18.47]],"ltp":2.84,"tv":532.08,"id":4486603}]}]}
{"op":"mcm","clk":"1008414999","pt":1580634836977,"mc":[{"id":"1.168224423","rc":[{"batb":[[0,1.53,16.57]],"batl":[[0,1.55,22.31],[1,1.57,28.09],[2,1.58,23.25]],"ltp":1.54,"tv":4911.57,"id":8260126}]}]}
{"op":"mcm","clk":"1008415081","pt":1580634838277,"mc":[{"id":"1.168224423","rc":[{"trd":[[1.55,44.38]],"batl":[[0,1.56,22.31]],"ltp":1.55,"tv":4955.95,"id":8260126},{"batb":[[0,2.82,16.31],[2,2.76,2.19]],"ltp":2.84,"tv":532.08,"id":4486603}],"tv":5488.03}]}
{"op":"mcm","clk":"1008415120","pt":1580634838787,"mc":[{"id":"1.168224423","rc":[{"batl":[[0,1.55,22],[1,1.56,22.31],[2,1.57,28.09]],"ltp":1.55,"tv":4955.95,"id":8260126},{"batb":[[0,2.8,16.32]],"ltp":2.84,"tv":532.08,"id":4486603}]}]}
{"op":"mcm","clk":"1008415213","pt":1580634840288,"mc":[{"id":"1.168224423","rc":[{"batl":[[1,1.56,24.31],[2,1.57,26.09]],"ltp":1.55,"tv":4955.95,"id":8260126}]}]}
{"op":"mcm","clk":"1008415255","pt":1580634840859,"mc":[{"id":"1.168224423","rc":[{"batb":[[0,1.53,9]],"ltp":1.55,"tv":4955.95,"id":8260126},{"batl":[[2,2.96,2.08]],"ltp":2.84,"tv":532.08,"id":4486603}]}]}
{"op":"mcm","clk":"1008415407","pt":1580634843085,"mc":[{"id":"1.168224423","rc":[{"batl":[[0,1.56,24.31],[1,1.57,24.08],[2,1.58,23.13]],"ltp":1.55,"tv":4955.95,"id":8260126},{"trd":[[2.8,32.14]],"batb":[[0,2.8,14]],"ltp":2.8,"tv":564.22,"id":4486603}],"tv":5520.17}]}
{"op":"mcm","clk":"1008415680","pt":1580634848091,"mc":[{"id":"1.168224423","rc":[{"trd":[[2.8,59.68]],"batb":[[0,2.78,35.65],[1,2.74,2.02],[2,2.72,16.74]],"batl":[[2,2.96,2.12]],"ltp":2.8,"tv":591.76,"id":4486603}],"tv":5547.71}]}
{"op":"mcm","clk":"1008416090","pt":1580634854389,"mc":[{"id":"1.168224423","rc":[{"batl":[[0,1.55,2],[1,1.56,22.31],[2,1.57,24.08]],"ltp":1.55,"tv":4955.95,"id":8260126},{"batb":[[2,2.72,14.65]],"batl":[[2,3,52.14]],"ltp":2.8,"tv":591.76,"id":4486603}]}]}
{"op":"mcm","clk":"1008416136","pt":1580634855314,"mc":[{"id":"1.168224423","rc":[{"trd":[[1.55,48.38]],"batl":[[0,1.56,22.31],[1,1.57,24.08],[2,1.58,23.13]],"ltp":1.55,"tv":4959.95,"id":8260126},{"batb":[[2,2.72,16.74]],"batl":[[2,2.96,2.12]],"ltp":2.8,"tv":591.76,"id":4486603}],"tv":5551.71}]}
{"op":"mcm","clk":"1008417465","pt":1580634879441,"mc":[{"id":"1.168224423","rc":[{"batb":[[2,1.51,13]],"ltp":1.55,"tv":4959.95,"id":8260126}]}]}
{"op":"mcm","clk":"1008417598","pt":1580634881450,"mc":[{"id":"1.168224423","rc":[{"batb":[[1,1.52,11.02],[2,1.51,108.37]],"ltp":1.55,"tv":4959.95,"id":8260126},{"batb":[[0,2.76,46.09]],"ltp":2.8,"tv":591.76,"id":4486603}]}]}
{"op":"mcm","clk":"1008418829","pt":1580634902344,"mc":[{"id":"1.168224423","rc":[{"batb":[[0,1.52,11.02],[1,1.51,106.37],[2,1.5,2]],"batl":[[0,1.56,16],[1,1.57,15],[2,1.58,17.13]],"ltp":1.55,"tv":4959.95,"id":8260126},{"batb":[[0,2.8,10],[1,2.76,47.97],[2,2.72,14.65]],"batl":[[0,2.92,3.01],[1,2.96,2.12],[2,2.98,2.19]],"ltp":2.8,"tv":591.76,"id":4486603}]}]}
{"op":"mcm","clk":"1008418900","pt":1580634903428,"mc":[{"id":"1.168224423","rc":[{"trd":[[2.8,79.22]],"batb":[[0,2.76,48.2],[1,2.74,2]],"ltp":2.8,"tv":611.3,"id":4486603}],"tv":5571.25}]}
{"op":"mcm","clk":"1008418941","pt":1580634904050,"mc":[{"id":"1.168224423","rc":[{"batb":[[0,2.76,46.09],[2,2.72,2.09]],"ltp":2.8,"tv":611.3,"id":4486603}]}]}
{"op":"mcm","clk":"1008419371","pt":1580634911363,"mc":[{"id":"1.168224423","rc":[{"batl":[[2,2.98,2.25]],"ltp":2.8,"tv":611.3,"id":4486603}]}]}
{"op":"mcm","clk":"1008420058","pt":1580634922751,"mc":[{"id":"1.168224423","rc":[{"batl":[[0,2.92,3.77]],"ltp":2.8,"tv":611.3,"id":4486603}]}]}
{"op":"mcm","clk":"1008420487","pt":1580634930292,"mc":[{"id":"1.168224423","rc":[{"batb":[[2,2.7,14.83]],"batl":[[2,3,52.14]],"ltp":2.8,"tv":611.3,"id":4486603}]}]}
{"op":"mcm","clk":"1008420499","pt":1580634930502,"mc":[{"id":"1.168224423","rc":[{"batb":[[2,2.72,2.09]],"batl":[[2,2.98,2.07]],"ltp":2.8,"tv":611.3,"id":4486603}]}]}
{"op":"mcm","clk":"1008425720","pt":1580635021373,"mc":[{"id":"1.168224423","rc":[{"trd":[[1.56,20.54]],"batl":[[0,1.57,15],[1,1.58,17.13],[2,1.59,59.07]],"ltp":1.56,"tv":4975.95,"id":8260126},{"trd":[[2.76,23.59],[2.78,8.98],[2.8,79.68]],"batb":[[0,2.76,34.06]],"ltp":2.76,"tv":644.33,"id":4486603}],"tv":5620.28}]}
{"op":"mcm","clk":"1008425767","pt":1580635022092,"mc":[{"id":"1.168224423","rc":[{"batb":[[0,1.52,28.32],[1,1.51,102.37]],"batl":[[0,1.55,8.16],[1,1.57,10.01],[2,1.58,10.25]],"ltp":1.56,"tv":4975.95,"id":8260126},{"batb":[[0,2.8,5.16],[1,2.76,2.23],[2,2.74,61.35]],"batl":[[2,2.98,2.04]],"ltp":2.76,"tv":644.33,"id":4486603}]}]}
{"op":"mcm","clk":"1008425834","pt":1580635023373,"mc":[{"id":"1.168224423","rc":[{"batb":[[0,1.53,7.01],[1,1.52,28.32],[2,1.51,104.45]],"batl":[[0,1.56,8]],"ltp":1.56,"tv":4975.95,"id":8260126},{"batb":[[2,2.74,46.86]],"batl":[[0,2.9,3.76],[1,2.92,3.01],[2,2.94,2.08]],"ltp":2.76,"tv":644.33,"id":4486603}]}]}
{"op":"mcm","clk":"1008425893","pt":1580635024411,"mc":[{"id":"1.168224423","rc":[{"batl":[[0,1.57,8],[1,1.58,8],[2,1.59,52.07]],"ltp":1.56,"tv":4975.95,"id":8260126},{"batb":[[0,2.76,6.02],[1,2.74,44.84],[2,2.72,2.09]],"ltp":2.76,"tv":644.33,"id":4486603}]}]}
{"op":"mcm","clk":"1008430455","pt":1580635105367,"mc":[{"id":"1.168224423","rc":[{"trd":[[1.53,7.01]],"batb":[[0,1.52,28.32],[1,1.51,104.45],[2,1.5,2]],"ltp":1.53,"tv":4982.96,"id":8260126},{"trd":[[2.88,1.51],[2.9,53.18]],"batb":[[0,2.9,55.24],[1,2.76,6.02],[2,2.74,44.84]],"batl":[[0,2.92,3.01],[1,2.94,2.08],[2,2.96,2.07]],"ltp":2.9,"tv":699.02,"id":4486603}],"tv":5681.98}]}
{"op":"mcm","clk":"1008430531","pt":1580635106399,"mc":[{"id":"1.168224423","rc":[{"trd":[[1.53,13.01]],"batb":[[0,1.52,21.32],[1,1.51,102.37],[2,1.5,8]],"batl":[[0,1.54,10.13],[1,1.55,10.13],[2,1.56,2.01]],"ltp":1.53,"tv":4988.96,"id":8260126},{"trd":[[2.9,160.05]],"batb":[[0,2.88,7.36],[1,2.86,9.31],[2,2.84,2.22]],"batl":[[0,2.98,5.05],[1,3,54.14],[2,3.85,229.44]],"ltp":2.9,"tv":805.89,"id":4486603}],"tv":5794.85}]}
{"op":"mcm","clk":"1008430604","pt":1580635107281,"mc":[{"id":"1.168224423","rc":[{"trd":[[1.53,13.44]],"batb":[[0,1.53,5.71],[1,1.52,27.32],[2,1.51,104.67]],"batl":[[0,1.56,12],[1,1.57,12],[2,1.58,2.01]],"ltp":1.53,"tv":4989.39,"id":8260126},{"trd":[[2.9,160.27]],"batb":[[0,2.8,8],[1,2.76,2],[2,2.74,46.84]],"batl":[[0,2.92,3.14],[1,2.94,5.08],[2,2.96,2.12]],"ltp":2.9,"tv":806.11,"id":4486603}],"tv":5795.51}]}
{"op":"mcm","clk":"1008430656","pt":1580635107899,"mc":[{"id":"1.168224423","rc":[{"batl":[[0,2.9,3],[1,2.92,3.14],[2,2.94,5.08]],"ltp":2.9,"tv":806.11,"id":4486603}]}]}
{"op":"mcm","clk":"1008435967","pt":1580635205378,"mc":[{"id":"1.168224423","rc":[{"batb":[[0,1.52,27.32],[1,1.51,104.67],[2,1.5,8]],"ltp":1.53,"tv":4989.39,"id":8260126},{"batb":[[0,2.78,8],[1,2.74,46.86],[2,2.72,16.74]],"batl":[[0,2.92,3.14],[1,2.94,5.08],[2,2.96,2.12]],"ltp":2.9,"tv":806.11,"id":4486603}]}]}
{"op":"mcm","clk":"1008436012","pt":1580635206102,"mc":[{"id":"1.168224423","rc":[{"batb":[[1,1.51,102.37]],"ltp":1.53,"tv":4989.39,"id":8260126},{"batl":[[1,2.94,3]],"ltp":2.9,"tv":806.11,"id":4486603}]}]}
{"op":"mcm","clk":"1008436978","pt":1580635222209,"mc":[{"id":"1.168224423","rc":[{"batb":[[0,1.53,6.12],[1,1.52,33.93],[2,1.51,104.63]],"ltp":1.53,"tv":4989.39,"id":8260126},{"batb":[[1,2.74,43.24]],"batl":[[1,2.94,5.08]],"ltp":2.9,"tv":806.11,"id":4486603}]}]}
{"op":"mcm","clk":"1008437197","pt":1580635226191,"mc":[{"id":"1.168224423","rc":[{"trd":[[1.53,13.48]],"batb":[[0,1.52,33.93],[1,1.51,102.37],[2,1.5,8]],"batl":[[2,1.58,14.01]],"ltp":1.53,"tv":4989.42,"id":8260126},{"batl":[[1,2.94,3]],"ltp":2.9,"tv":806.11,"id":4486603}],"tv":5795.54}]}
{"op":"mcm","clk":"1008437385","pt":1580635229435,"mc":[{"id":"1.168224423","rc":[{"batb":[[0,1.53,6.16],[1,1.52,33.93],[2,1.51,102.37]],"ltp":1.53,"tv":4989.42,"id":8260126}]}]}
{"op":"mcm","clk":"1008437429","pt":1580635230108,"mc":[{"id":"1.168224423","rc":[{"batb":[[0,1.52,33.94],[1,1.51,102.37],[2,1.5,8]],"ltp":1.53,"tv":4989.42,"id":8260126},{"batl":[[2,2.96,2]],"ltp":2.9,"tv":806.11,"id":4486603}]}]}
{"op":"mcm","clk":"1008439220","pt":1580635262087,"mc":[{"id":"1.168224423","rc":[{"batb":[[2,2.72,16.65]],"ltp":2.9,"tv":806.11,"id":4486603}]}]}
{"op":"mcm","clk":"1008439597","pt":1580635268259,"mc":[{"id":"1.168224423","rc":[{"batb":[[2,2.72,14.65]],"ltp":2.9,"tv":806.11,"id":4486603}]}]}
{"op":"mcm","clk":"1008439622","pt":1580635268670,"mc":[{"id":"1.168224423","rc":[{"batb":[[2,2.72,16.74]],"ltp":2.9,"tv":806.11,"id":4486603}]}]}
{"op":"mcm","clk":"1008441961","pt":1580635312376,"mc":[{"id":"1.168224423","rc":[{"batl":[[0,1.55,58.02],[1,1.56,12],[2,1.57,14.01]],"ltp":1.53,"tv":4989.42,"id":8260126},{"batb":[[0,2.82,8.28],[1,2.78,8],[2,2.76,2.15]],"batl":[[0,2.94,3],[1,2.96,2],[2,3,52.14]],"ltp":2.9,"tv":806.11,"id":4486603}]}]}
{"op":"mcm","clk":"1008442019","pt":1580635313373,"mc":[{"id":"1.168224423","rc":[{"batb":[[1,2.78,10.16]],"batl":[[0,2.94,5.08],[1,2.96,2.12],[2,2.98,2.25]],"ltp":2.9,"tv":806.11,"id":4486603}]}]}
{"op":"mcm","clk":"1008442080","pt":1580635314277,"mc":[{"id":"1.168224423","rc":[{"batb":[[1,1.51,104.79],[2,1.5,6]],"ltp":1.53,"tv":4989.42,"id":8260126},{"batl":[[0,2.92,3.29],[1,2.94,5.08],[2,2.96,2.12]],"ltp":2.9,"tv":806.11,"id":4486603}]}]}
{"op":"mcm","clk":"1008442155","pt":1580635315352,"mc":[{"id":"1.168224423","rc":[{"batb":[[1,1.51,104.71],[2,1.5,8]],"ltp":1.53,"tv":4989.42,"id":8260126},{"batl":[[0,2.92,3.3]],"ltp":2.9,"tv":806.11,"id":4486603}]}]}
{"op":"mcm","clk":"1008442225","pt":1580635316378,"mc":[{"id":"1.168224423","rc":[{"batb":[[0,1.53,7.32],[1,1.52,33.93],[2,1.51,104.77]],"batl":[[0,1.55,45.02]],"ltp":1.53,"tv":4989.42,"id":8260126},{"batl":[[2,2.96,2.04]],"ltp":2.9,"tv":806.11,"id":4486603}]}]}
{"op":"mcm","clk":"1008442274","pt":1580635317259,"mc":[{"id":"1.168224423","rc":[{"batb":[[0,1.52,33.94],[1,1.51,102.37],[2,1.5,8]],"batl":[[0,1.55,58.02]],"ltp":1.53,"tv":4989.42,"id":8260126},{"batl":[[0,2.94,3],[1,2.98,2.25],[2,3,54.14]],"ltp":2.9,"tv":806.11,"id":4486603}]}]}
{"op":"mcm","clk":"1008442459","pt":1580635319364,"mc":[{"id":"1.168224423","rc":[{"batb":[[2,2.76,2.03]],"ltp":2.9,"tv":806.11,"id":4486603}]}]}
{"op":"mcm","clk":"1008442484","pt":1580635319771,"mc":[{"id":"1.168224423","rc":[{"batl":[[0,1.55,45.02]],"ltp":1.53,"tv":4989.42,"id":8260126},{"batb":[[0,2.8,8],[1,2.78,8]],"ltp":2.9,"tv":806.11,"id":4486603}]}]}
{"op":"mcm","clk":"1008451128","pt":1580635471405,"mc":[{"id":"1.168224423","rc":[{"batb":[[0,1.53,7.19],[1,1.52,33.93],[2,1.51,102.37]],"ltp":1.53,"tv":4989.42,"id":8260126},{"batl":[[0,2.9,3.17],[1,2.92,18.48],[2,2.94,3]],"ltp":2.9,"tv":806.11,"id":4486603}]}]}
{"op":"mcm","clk":"1008451161","pt":1580635472023,"mc":[{"id":"1.168224423","rc":[{"batb":[[2,1.51,104.47]],"ltp":1.53,"tv":4989.42,"id":8260126},{"batl":[[2,2.94,5.08]],"ltp":2.9,"tv":806.11,"id":4486603}]}]}
{"op":"mcm","clk":"1008452311","pt":1580635495333,"mc":[{"id":"1.168224423","rc":[{"trd":[[1.53,17.12]],"batb":[[0,1.53,5.36]],"ltp":1.53,"tv":4993.07,"id":8260126}],"tv":5799.19}]}
{"op":"mcm","clk":"1008452642","pt":1580635501259,"mc":[{"id":"1.168224423","rc":[{"trd":[[1.53,21.14]],"batb":[[0,1.53,6.99]],"ltp":1.53,"tv":4997.09,"id":8260126},{"batb":[[0,2.82,9],[1,2.8,8],[2,2.78,10.03]],"ltp":2.9,"tv":806.11,"id":4486603}],"tv":5803.21}]}
{"op":"mcm","clk":"1008452813","pt":1580635504292,"mc":[{"id":"1.168224423","rc":[{"batb":[[0,1.52,33.93],[1,1.51,102.37],[2,1.5,8]],"batl":[[0,1.55,59.02]],"ltp":1.53,"tv":4997.09,"id":8260126},{"batl":[[0,2.92,3.02],[1,2.94,3],[2,2.96,2.12]],"ltp":2.9,"tv":806.11,"id":4486603}]}]}
{"op":"mcm","clk":"1008453065","pt":1580635509264,"mc":[{"id":"1.168224423","rc":[{"batb":[[1,1.51,104.77]],"ltp":1.53,"tv":4997.09,"id":8260126},{"batl":[[1,2.94,5.08]],"ltp":2.9,"tv":806.11,"id":4486603}]}]}
{"op":"mcm","clk":"1008453124","pt":1580635510394,"mc":[{"id":"1.168224423","rc":[{"batb":[[0,1.53,7.05],[1,1.52,33.93],[2,1.51,104.41]],"ltp":1.53,"tv":4997.09,"id":8260126},{"batb":[[0,2.82,9.05],[2,2.78,8]],"batl":[[0,2.9,3],[1,2.92,3.02],[2,2.94,5.08]],"ltp":2.9,"tv":806.11,"id":4486603}]}]}
{"op":"mcm","clk":"1008453153","pt":1580635511010,"mc":[{"id":"1.168224423","rc":[{"batb":[[0,1.52,33.93],[1,1.51,102.37],[2,1.5,8]],"ltp":1.53,"tv":4997.09,"id":8260126},{"batb":[[2,2.78,10]],"batl":[[0,2.92,3.02],[1,2.94,3],[2,2.96,2.01]],"ltp":2.9,"tv":806.11,"id":4486603}]}]}
{"op":"mcm","clk":"1008453479","pt":1580635517398,"mc":[{"id":"1.168224423","rc":[{"batb":[[0,1.53,8.06],[1,1.52,33.93],[2,1.51,102.37]],"ltp":1.53,"tv":4997.09,"id":8260126},{"trd":[[2.82,16.8]],"batb":[[0,2.82,7],[2,2.78,8]],"ltp":2.82,"tv":822.92,"id":4486603}],"tv":5820.01}]}
{"op":"mcm","clk":"1008453520","pt":1580635518121,"mc":[{"id":"1.168224423","rc":[{"batb":[[0,1.52,33.93],[1,1.51,102.37],[2,1.5,8]],"ltp":1.53,"tv":4997.09,"id":8260126},{"batb":[[2,2.78,10.16]],"ltp":2.82,"tv":822.92,"id":4486603}]}]}
{"op":"mcm","clk":"1008456942","pt":1580635580283,"mc":[{"id":"1.168224423","rc":[{"batb":[[0,1.53,8.32],[1,1.52,33.93],[2,1.51,102.37]],"ltp":1.53,"tv":4997.09,"id":8260126}]}]}
{"op":"mcm","clk":"1008457009","pt":1580635581363,"mc":[{"id":"1.168224423","rc":[{"batb":[[0,1.53,8.11],[2,1.51,254.13]],"batl":[[0,1.55,45.02]],"ltp":1.53,"tv":4997.09,"id":8260126},{"batb":[[0,2.8,8],[1,2.78,10.16],[2,2.76,2]],"batl":[[0,2.88,4.11],[1,2.92,3.02],[2,2.94,2.03]],"ltp":2.82,"tv":822.92,"id":4486603}]}]}
{"op":"mcm","clk":"1008457034","pt":1580635581875,"mc":[{"id":"1.168224423","rc":[{"batb":[[1,2.78,8]],"batl":[[0,2.9,3]],"ltp":2.82,"tv":822.92,"id":4486603}]}]}
{"op":"mcm","clk":"1008457417","pt":1580635589394,"mc":[{"id":"1.168224423","rc":[{"batb":[[2,1.51,252.79]],"ltp":1.53,"tv":4997.09,"id":8260126}]}]}
{"op":"mcm","clk":"1008457460","pt":1580635590008,"mc":[{"id":"1.168224423","rc":[{"batb":[[0,1.52,33.93],[1,1.51,250.53],[2,1.5,8]],"batl":[[0,1.55,57.02]],"ltp":1.53,"tv":4997.09,"id":8260126},{"batb":[[0,2.82,7.16],[1,2.78,10.07],[2,2.76,2.23]],"batl":[[0,2.92,3.02],[1,2.96,2.12],[2,2.98,2.24]],"ltp":2.82,"tv":822.92,"id":4486603}]}]}
{"op":"mcm","clk":"1008457538","pt":1580635591194,"mc":[{"id":"1.168224423","rc":[{"batl":[[0,1.54,42.01],[1,1.55,57.02],[2,1.56,16.34]],"ltp":1.53,"tv":4997.09,"id":8260126},{"batb":[[1,2.8,2.03],[2,2.78,10.07]],"ltp":2.82,"tv":822.92,"id":4486603}]}]}
{"op":"mcm","clk":"1008459324","pt":1580635612338,"mc":[{"id":"1.168224423","rc":[{"batl":[[2,1.56,14.17]],"ltp":1.53,"tv":4997.09,"id":8260126},{"batb":[[2,2.78,10.16]],"batl":[[2,2.98,2.25]],"ltp":2.82,"tv":822.92,"id":4486603}]}]}
{"op":"mcm","clk":"1008459675","pt":1580635615447,"mc":[{"id":"1.168224423","marketDefinition":{"bspMarket":false,"turnInPlayEnabled":true,"persistenceEnabled":true,"marketBaseRate":5.0,"eventId":"29681737","eventTypeId":"2","numberOfWinners":1,"bettingType":"ODDS","marketType":"MATCH_ODDS","marketTime":"2020-02-02T09:24:00.000Z","suspendTime":"2020-02-02T09:24:00.000Z","bspReconciled":false,"complete":true,"inPlay":false,"crossMatching":true,"runnersVoidable":false,"numberOfActiveRunners":2,"betDelay":0,"status":"OPEN","runners":[{"status":"ACTIVE","sortPriority":1,"id":8260126,"name":"Guillermo Garcia-Lopez"},{"status":"ACTIVE","sortPriority":2,"id":4486603,"name":"Dustin Brown"}],"regulators":["MR_INT"],"countryCode":"FR","discountAllowed":true,"timezone":"UTC","openDate":"2020-02-02T09:30:00.000Z","version":3148345633,"name":"Match Odds","eventName":"Garcia-Lopez v Brown"}}]}
{"op":"mcm","clk":"1008459927","pt":1580635617379,"mc":[{"id":"1.168224423","marketDefinition":{"bspMarket":false,"turnInPlayEnabled":true,"persistenceEnabled":true,"marketBaseRate":5.0,"eventId":"29681737","eventTypeId":"2","numberOfWinners":1,"bettingType":"ODDS","marketType":"MATCH_ODDS","marketTime":"2020-02-02T09:24:00.000Z","suspendTime":"2020-02-02T09:24:00.000Z","bspReconciled":false,"complete":true,"inPlay":false,"crossMatching":true,"runnersVoidable":false,"numberOfActiveRunners":2,"betDelay":0,"status":"OPEN","runners":[{"status":"ACTIVE","sortPriority":1,"id":8260126,"name":"Guillermo Garcia-Lopez"},{"status":"ACTIVE","sortPriority":2,"id":4486603,"name":"Dustin Brown"}],"regulators":["MR_INT"],"countryCode":"FR","discountAllowed":true,"timezone":"UTC","openDate":"2020-02-02T09:24:00.000Z","version":3148345633,"name":"Match Odds","eventName":"Garcia-Lopez v Brown"}}]}
{"op":"mcm","clk":"1008460669","pt":1580635628438,"mc":[{"id":"1.168224423","rc":[{"batb":[[2,1.5,6]],"batl":[[2,1.56,12]],"ltp":1.53,"tv":4997.09,"id":8260126},{"batb":[[1,2.78,8],[2,2.74,102.99]],"batl":[[1,3,52.14],[2,3.85,229.44]],"ltp":2.82,"tv":822.92,"id":4486603}]}]}
{"op":"mcm","clk":"1008460686","pt":1580635628644,"mc":[{"id":"1.168224423","rc":[{"batb":[[0,1.53,8.04],[1,1.52,33.93],[2,1.51,250.53]],"ltp":1.53,"tv":4997.09,"id":8260126}]}]}
{"op":"mcm","clk":"1008460915","pt":1580635632044,"mc":[{"id":"1.168224423","rc":[{"batl":[[1,1.55,12]],"ltp":1.53,"tv":4997.09,"id":8260126},{"batl":[[0,2.9,4],[1,2.92,3.02],[2,3,52.14]],"ltp":2.82,"tv":822.92,"id":4486603}]}]}
{"op":"mcm","clk":"1008463705","pt":1580635682207,"mc":[{"id":"1.168224423","rc":[{"trd":[[1.54,260.7]],"batb":[[1,1.52,6],[2,1.51,250.16]],"batl":[[0,1.54,13.95]],"ltp":1.54,"tv":5053.22,"id":8260126},{"batb":[[2,2.76,15.5]],"ltp":2.82,"tv":822.92,"id":4486603}],"tv":5876.14}]}
{"op":"mcm","clk":"1008465725","pt":1580635716432,"mc":[{"id":"1.168224423","rc":[{"trd":[[1.52,60.8],[1.53,37.23]],"batb":[[0,1.51,250.16],[1,1.5,9],[2,1.49,9]],"batl":[[0,1.52,17.96],[1,1.54,13.95],[2,1.55,12]],"ltp":1.52,"tv":5094.73,"id":8260126},{"trd":[[2.9,164.27],[2.92,3.02]],"batl":[[0,3,52.14],[1,3.85,229.44],[2,8,58.81]],"ltp":2.92,"tv":829.94,"id":4486603}],"tv":5924.67}]}
{"op":"mcm","clk":"1008465792","pt":1580635717359,"mc":[{"id":"1.168224423","rc":[{"trd":[[1.52,88.65]],"batb":[[0,1.53,8.2],[1,1.52,8],[2,1.51,250.16]],"batl":[[0,1.54,13.95],[1,1.55,17],[2,1.56,17]],"ltp":1.52,"tv":5122.58,"id":8260126},{"trd":[[2.92,7.22]],"batb":[[0,2.82,11],[1,2.78,12]],"batl":[[0,2.92,3.2],[1,3,52.14],[2,3.85,229.44]],"ltp":2.92,"tv":834.14,"id":4486603}],"tv":5956.72}]}
{"op":"mcm","clk":"1008466101","pt":1580635721872,"mc":[{"id":"1.168224423","rc":[{"trd":[[1.53,39.53]],"batb":[[0,1.53,7.05]],"ltp":1.53,"tv":5124.88,"id":8260126}],"tv":5959.02}]}
{"op":"mcm","clk":"1008466331","pt":1580635726251,"mc":[{"id":"1.168224423","rc":[{"batb":[[0,1.52,8],[1,1.51,250.16],[2,1.5,9]],"batl":[[0,1.54,196.17]],"ltp":1.53,"tv":5124.88,"id":8260126},{"batb":[[0,2.86,12.25],[1,2.82,11]],"batl":[[0,2.94,3]],"ltp":2.92,"tv":834.14,"id":4486603}]}]}
{"op":"mcm","clk":"1008466394","pt":1580635727257,"mc":[{"id":"1.168224423","rc":[{"batb":[[2,2.78,14.16]],"ltp":2.92,"tv":834.14,"id":4486603}]}]}
{"op":"mcm","clk":"1008468915","pt":1580635771389,"mc":[{"id":"1.168224423","rc":[{"batl":[[0,1.54,13.95]],"ltp":1.53,"tv":5124.88,"id":8260126},{"batb":[[0,2.82,11],[1,2.76,15.5],[2,2.74,102.99]],"ltp":2.92,"tv":834.14,"id":4486603}]}]}
{"op":"mcm","clk":"1008470607","pt":1580635799736,"mc":[{"id":"1.168224423","rc":[{"trd":[[1.52,88.99]],"batb":[[0,1.52,7.83]],"ltp":1.52,"tv":5125.22,"id":8260126}],"tv":5959.36}]}
{"op":"mcm","clk":"1008471514","pt":1580635812276,"mc":[{"id":"1.168224423","rc":[{"batb":[[0,1.52,50.39]],"ltp":1.52,"tv":5125.22,"id":8260126}]}]}
{"op":"mcm","clk":"1008481681","pt":1580635974294,"mc":[{"id":"1.168224423","rc":[{"trd":[[1.54,288.59]],"batb":[[0,1.54,28.27],[1,1.53,9.29],[2,1.52,50.39]],"batl":[[0,1.56,17],[1,1.57,17],[2,1.58,182.23]],"ltp":1.54,"tv":5153.12,"id":8260126},{"batb":[[0,2.8,13.29]],"batl":[[0,2.88,4.29],[1,2.94,3],[2,3,52.14]],"ltp":2.92,"tv":834.14,"id":4486603}],"tv":5987.26}]}
{"op":"mcm","clk":"1008481798","pt":1580635975683,"mc":[{"id":"1.168224423","rc":[{"batb":[[2,2.74,88.51]],"batl":[[0,2.9,4]],"ltp":2.92,"tv":834.14,"id":4486603}]}]}
{"op":"mcm","clk":"1008482379","pt":1580635983413,"mc":[{"id":"1.168224423","rc":[{"batb":[[0,1.53,9.29],[1,1.52,50.39],[2,1.51,250.16]],"ltp":1.54,"tv":5153.12,"id":8260126}]}]}
{"op":"mcm","clk":"1008482459","pt":1580635984395,"mc":[{"id":"1.168224423","rc":[{"trd":[[1.56,65.82]],"batl":[[0,1.56,16]],"ltp":1.56,"tv":5198.39,"id":8260126},{"trd":[[2.8,85.96]],"batb":[[0,2.8,11]],"ltp":2.8,"tv":840.42,"id":4486603}],"tv":6038.81}]}
{"op":"mcm","clk":"1008482992","pt":1580635991290,"mc":[{"id":"1.168224423","rc":[{"trd":[[1.53,44.6]],"batb":[[0,1.53,6.75]],"ltp":1.53,"tv":5203.46,"id":8260126}],"tv":6043.88}]}
{"op":"mcm","clk":"1008486856","pt":1580636046373,"mc":[{"id":"1.168224423","rc":[{"batb":[[0,1.52,50.39],[1,1.51,250.16],[2,1.5,9]],"ltp":1.53,"tv":5203.46,"id":8260126},{"batl":[[0,2.92,4.03],[2,2.96,2.53]],"ltp":2.8,"tv":840.42,"id":4486603}]}]}
{"op":"mcm","clk":"1008489991","pt":1580636086285,"mc":[{"id":"1.168224423","rc":[{"batl":[[2,1.58,184.5]],"ltp":1.53,"tv":5203.46,"id":8260126}]}]}
{"op":"mcm","clk":"1008506225","pt":1580636306257,"mc":[{"id":"1.168224423","rc":[{"batb":[[1,1.51,254.16]],"batl":[[0,1.55,182.23],[1,1.56,16],[2,1.57,17]],"ltp":1.53,"tv":5203.46,"id":8260126},{"batb":[[0,2.82,11.14],[1,2.8,11],[2,2.76,15.5]],"batl":[[1,2.94,5]],"ltp":2.8,"tv":840.42,"id":4486603}]}]}
{"op":"mcm","clk":"1008510477","pt":1580636368438,"mc":[{"id":"1.168224423","rc":[{"batb":[[0,1.52,179.78]],"batl":[[0,1.54,127.71],[1,1.55,182.23],[2,1.56,16]],"ltp":1.53,"tv":5203.46,"id":8260126},{"batb":[[0,2.84,11],[1,2.82,11.14],[2,2.8,11]],"ltp":2.8,"tv":840.42,"id":4486603}]}]}
{"op":"mcm","clk":"1008511283","pt":1580636379329,"mc":[{"id":"1.168224423","rc":[{"trd":[[1.52,286.34]],"batb":[[0,1.52,81.11]],"ltp":1.52,"tv":5400.8,"id":8260126}],"tv":6241.22}]}
{"op":"mcm","clk":"1008511358","pt":1580636380427,"mc":[{"id":"1.168224423","rc":[{"batl":[[0,1.54,146.71]],"ltp":1.52,"tv":5400.8,"id":8260126},{"batb":[[0,2.86,12.21],[1,2.84,11],[2,2.82,11.14]],"batl":[[0,2.96,6.74],[1,3,73.14],[2,3.85,229.44]],"ltp":2.8,"tv":840.42,"id":4486603}]}]}
{"op":"mcm","clk":"1008511411","pt":1580636381147,"mc":[{"id":"1.168224423","rc":[{"trd":[[1.52,448.56]],"batb":[[0,1.51,159.16],[1,1.5,66.87],[2,1.49,94.7]],"ltp":1.52,"tv":5563.03,"id":8260126},{"batb":[[0,2.86,45.52]],"ltp":2.8,"tv":840.42,"id":4486603}],"tv":6403.45}]}
{"op":"mcm","clk":"1008512392","pt":1580636394370,"mc":[{"id":"1.168224423","rc":[{"batb":[[0,1.52,112],[1,1.51,159.16],[2,1.5,66.87]],"ltp":1.52,"tv":5563.03,"id":8260126}]}]}
{"op":"mcm","clk":"1008512491","pt":1580636395443,"mc":[{"id":"1.168224423","rc":[{"batb":[[0,1.51,159.16],[1,1.5,66.87],[2,1.49,94.7]],"ltp":1.52,"tv":5563.03,"id":8260126}]}]}
{"op":"mcm","clk":"1008513889","pt":1580636417273,"mc":[{"id":"1.168224423","marketDefinition":{"bspMarket":false,"turnInPlayEnabled":true,"persistenceEnabled":true,"marketBaseRate":5.0,"eventId":"29681737","eventTypeId":"2","numberOfWinners":1,"bettingType":"ODDS","marketType":"MATCH_ODDS","marketTime":"2020-02-02T09:24:00.000Z","suspendTime":"2020-02-02T09:24:00.000Z","bspReconciled":false,"complete":true,"inPlay":true,"crossMatching":true,"runnersVoidable":false,"numberOfActiveRunners":2,"betDelay":3,"status":"OPEN","runners":[{"status":"ACTIVE","sortPriority":1,"id":8260126,"name":"Guillermo Garcia-Lopez"},{"status":"ACTIVE","sortPriority":2,"id":4486603,"name":"Dustin Brown"}],"regulators":["MR_INT"],"countryCode":"FR","discountAllowed":true,"timezone":"UTC","openDate":"2020-02-02T09:24:00.000Z","version":3148353237,"name":"Match Odds","eventName":"Garcia-Lopez v Brown"},"rc":[{"batb":[[0,1.33,3.37],[1,1.32,756.18],[2,1.22,756.18]],"batl":[[0,1.54,127.71],[1,1.55,165.23],[2,1.58,2.27]],"ltp":1.52,"tv":5563.03,"id":8260126},{"batb":[[0,2.04,756.18],[1,1.82,756.18],[2,1.52,378.62]],"batl":[[0,2.96,2.53],[1,3,52.14],[2,8,58.81]],"ltp":2.8,"tv":840.42,"id":4486603}]}]}
{"op":"mcm","clk":"1008514115","pt":1580636420691,"mc":[{"id":"1.168224423","rc":[{"batb":[[2,1.8,75.72]],"ltp":2.8,"tv":840.42,"id":4486603}]}]}
{"op":"mcm","clk":"1008514325","pt":1580636424031,"mc":[{"id":"1.168224423","rc":[{"batl":[[1,1.58,2.27],[2,1.6,4.66]],"ltp":1.52,"tv":5563.03,"id":8260126}]}]}
{"op":"mcm","clk":"1008514532","pt":1580636427514,"mc":[{"id":"1.168224423","rc":[{"batb":[[2,1.25,378.62]],"ltp":1.52,"tv":5563.03,"id":8260126}]}]}
{"op":"mcm","clk":"1008515567","pt":1580636446220,"mc":[{"id":"1.168224423","rc":[{"batb":[[0,1.47,723.28],[1,1.46,581.12],[2,1.33,3.36]],"ltp":1.52,"tv":5563.03,"id":8260126}]}]}
{"op":"mcm","clk":"1008515813","pt":1580636450435,"mc":[{"id":"1.168224423","rc":[{"batb":[[0,1.33,3.37],[1,1.32,756.18],[2,1.25,378.62]],"ltp":1.52,"tv":5563.03,"id":8260126}]}]}
{"op":"mcm","clk":"1008516015","pt":1580636453342,"mc":[{"id":"1.168224423","rc":[{"batb":[[0,1.52,622.84],[1,1.51,505.45],[2,1.33,3.37]],"batl":[[1,1.56,390.35],[2,1.57,430.98]],"ltp":1.52,"tv":5563.03,"id":8260126}]}]}
{"op":"mcm","clk":"1008516048","pt":1580636453852,"mc":[{"id":"1.168224423","rc":[{"batb":[[0,1.33,3.37],[1,1.32,756.18],[2,1.25,378.62]],"batl":[[1,1.58,2.27],[2,1.6,4.66]],"ltp":1.52,"tv":5563.03,"id":8260126}]}]}
{"op":"mcm","clk":"1008516238","pt":1580636456952,"mc":[{"id":"1.168224423","rc":[{"batb":[[0,1.47,723.28],[1,1.46,581.12],[2,1.33,3.36]],"ltp":1.52,"tv":5563.03,"id":8260126}]}]}
{"op":"mcm","clk":"1008516902","pt":1580636468443,"mc":[{"id":"1.168224423","rc":[{"batb":[[0,1.33,3.37],[1,1.32,756.18],[2,1.25,378.62]],"ltp":1.52,"tv":5563.03,"id":8260126},{"batl":[[2,3.1,4.99]],"ltp":2.8,"tv":840.42,"id":4486603}]}]}
{"op":"mcm","clk":"1008517079","pt":1580636471372,"mc":[{"id":"1.168224423","rc":[{"trd":[[1.54,416.3],[1.58,2.27],[1.6,14.82],[1.61,725.28]],"batb":[[0,1.57,616.48],[1,1.56,444.96],[2,1.33,3.37]],"batl":[[0,1.61,52.54],[1,1.62,598.88],[2,1.63,375.2]],"ltp":1.61,"tv":6227.25,"id":8260126},{"trd":[[2.62,320.77],[2.66,2.81],[2.72,120.51],[2.84,69.26]],"batb":[[0,2.46,5.94],[1,2.42,299.24],[2,2.04,756.18]],"batl":[[0,2.88,327],[1,2.96,2.53],[2,3,52.14]],"ltp":2.62,"tv":1226.79,"id":4486603}],"tv":7454.04}]}
{"op":"mcm","clk":"1008517139","pt":1580636472141,"mc":[{"id":"1.168224423","rc":[{"batb":[[2,1.55,133.52]],"ltp":1.61,"tv":6227.25,"id":8260126},{"batb":[[0,2.6,54.21],[1,2.5,60.74],[2,2.46,5.94]],"ltp":2.62,"tv":1226.79,"id":4486603}]}]}
{"op":"mcm","clk":"1008517327","pt":1580636475187,"mc":[{"id":"1.168224423","rc":[{"trd":[[1.61,830.18]],"batl":[[0,1.62,598.97],[1,1.63,375.2],[2,1.65,42.01]],"ltp":1.61,"tv":6332.15,"id":8260126},{"batb":[[1,2.52,26.89],[2,2.5,60.74]],"ltp":2.62,"tv":1226.79,"id":4486603}],"tv":7558.94}]}
{"op":"mcm","clk":"1008517706","pt":1580636479887,"mc":[{"id":"1.168224423","rc":[{"batb":[[0,1.49,154.37],[1,1.33,3.37],[2,1.25,378.62]],"batl":[[0,1.65,42.01],[1,3.95,2.13],[2,1000,0.02]],"ltp":1.61,"tv":6332.15,"id":8260126},{"batb":[[0,2.52,26.89],[1,2.5,60.74],[2,1.8,75.72]],"batl":[[0,2.96,2.53],[1,3,52.14],[2,8,58.81]],"ltp":2.62,"tv":1226.79,"id":4486603}]}]}
{"op":"mcm","clk":"1008517753","pt":1580636480556,"mc":[{"id":"1.168224423","rc":[{"batl":[[0,3.95,2.13],[1,1000,0.02],[2,1000,0]],"ltp":1.61,"tv":6332.15,"id":8260126},{"batb":[[0,2.5,60.74],[1,1.8,75.72],[2,1.7,75.72]],"ltp":2.62,"tv":1226.79,"id":4486603}]}]}
{"op":"mcm","clk":"1008517896","pt":1580636483179,"mc":[{"id":"1.168224423","rc":[{"batb":[[0,1.53,78.98],[1,1.52,464.27],[2,1.51,504.51]],"batl":[[0,1.65,420.78],[1,1.66,352.54],[2,3.95,2.13]],"ltp":1.61,"tv":6332.15,"id":8260126},{"batl":[[0,2.86,21.85],[1,2.96,2.53],[2,3,52.14]],"ltp":2.62,"tv":1226.79,"id":4486603}]}]}
{"op":"mcm","clk":"1008517912","pt":1580636483593,"mc":[{"id":"1.168224423","rc":[{"batb":[[0,1.52,464.27],[1,1.51,504.51],[2,1.49,154.37]],"ltp":1.61,"tv":6332.15,"id":8260126},{"batl":[[0,2.96,2.53],[1,3,52.14],[2,8,58.81]],"ltp":2.62,"tv":1226.79,"id":4486603}]}]}
{"op":"mcm","clk":"1008519063","pt":1580636499286,"mc":[{"id":"1.168224423","rc":[{"batb":[[0,1.49,154.37],[1,1.33,3.37],[2,1.25,378.62]],"ltp":1.61,"tv":6332.15,"id":8260126}]}]}
{"op":"mcm","clk":"1008519271","pt":1580636502387,"mc":[{"id":"1.168224423","rc":[{"trd":[[1.65,308.09]],"batb":[[0,1.6,2088.18],[1,1.59,414.31],[2,1.49,154.37]],"batl":[[0,1.65,1767.88],[2,1.68,608]],"ltp":1.65,"tv":6348.69,"id":8260126},{"trd":[[2.52,82.87]],"batb":[[1,2.36,331.02],[2,1.8,75.72]],"batl":[[0,2.56,620.23],[1,2.7,393],[2,2.96,2.53]],"ltp":2.52,"tv":1237.62,"id":4486603}],"tv":7586.31}]}
{"op":"mcm","clk":"1008519363","pt":1580636503421,"mc":[{"id":"1.168224423","rc":[{"trd":[[1.64,714.05]],"batb":[[1,1.59,535.4],[2,1.54,136.04]],"ltp":1.64,"tv":6505.07,"id":8260126},{"trd":[[2.56,148.26]],"batb":[[1,2.42,65.94],[2,2.36,331.02]],"batl":[[0,2.56,520.07]],"ltp":2.56,"tv":1337.78,"id":4486603}],"tv":7842.86}]}
{"op":"mcm","clk":"1008519372","pt":1580636503532,"mc":[{"id":"1.168224423","rc":[{"batb":[[2,1.56,74.78]],"ltp":1.64,"tv":6505.07,"id":8260126},{"batb":[[1,2.42,95.34]],"batl":[[2,2.78,23.53]],"ltp":2.56,"tv":1337.78,"id":4486603}]}]}
{"op":"mcm","clk":"1008519762","pt":1580636508627,"mc":[{"id":"1.168224423","rc":[{"batb":[[0,1.61,494.03],[1,1.6,2088.18],[2,1.59,1046.24]],"ltp":1.64,"tv":6505.07,"id":8260126}]}]}
{"op":"mcm","clk":"1008520032","pt":1580636512236,"mc":[{"id":"1.168224423","rc":[{"trd":[[1.64,716.91]],"ltp":1.64,"tv":6507.94,"id":8260126},{"trd":[[2.56,150.09]],"batl":[[0,2.56,518.24]],"ltp":2.56,"tv":1339.61,"id":4486603}],"tv":7847.55}]}
{"op":"mcm","clk":"1008520246","pt":1580636515126,"mc":[{"id":"1.168224423","rc":[{"trd":[[1.65,321.64]],"batl":[[0,1.65,1754.33]],"ltp":1.65,"tv":6521.49,"id":8260126},{"trd":[[2.52,91.74]],"ltp":2.52,"tv":1348.48,"id":4486603}],"tv":7869.97}]}
{"op":"mcm","clk":"1008520473","pt":1580636518323,"mc":[{"id":"1.168224423","rc":[{"batb":[[1,1.6,681.93]],"batl":[[0,1.65,390.69],[2,1.69,522.6]],"ltp":1.65,"tv":6521.49,"id":8260126},{"batb":[[2,1.8,75.72]],"batl":[[0,2.78,23.53],[1,2.96,2.53],[2,3,52.14]],"ltp":2.52,"tv":1348.48,"id":4486603}]}]}
{"op":"mcm","clk":"1008520490","pt":1580636518534,"mc":[{"id":"1.168224423","rc":[{"batb":[[1,1.59,510.84],[2,1.54,136.04]],"batl":[[0,1.69,480.59],[1,1.71,497.4],[2,3.95,2.13]],"ltp":1.65,"tv":6521.49,"id":8260126},{"batb":[[0,2.42,65.94],[1,1.8,75.72],[2,1.7,75.72]],"batl":[[0,2.96,2.53],[1,3,52.14],[2,8,58.81]],"ltp":2.52,"tv":1348.48,"id":4486603}]}]}
{"op":"mcm","clk":"1008520697","pt":1580636521433,"mc":[{"id":"1.168224423","rc":[{"batb":[[2,1.56,683.6]],"batl":[[0,1.68,542.99],[1,1.69,480.59],[2,1.7,652.6]],"ltp":1.65,"tv":6521.49,"id":8260126}]}]}
{"op":"mcm","clk":"1008520711","pt":1580636521645,"mc":[{"id":"1.168224423","rc":[{"batb":[[2,1.54,136.04]],"batl":[[0,1.69,480.59],[1,1.71,497.4],[2,3.95,2.13]],"ltp":1.65,"tv":6521.49,"id":8260126}]}]}
{"op":"mcm","clk":"1008520924","pt":1580636524429,"mc":[{"id":"1.168224423","rc":[{"batb":[[1,1.59,1284.14],[2,1.58,424.55]],"batl":[[0,1.64,370.8],[1,1.65,360.18],[2,1.69,480.59]],"ltp":1.65,"tv":6521.49,"id":8260126}]}]}
{"op":"mcm","clk":"1008521185","pt":1580636527229,"mc":[{"id":"1.168224423","rc":[{"batb":[[1,1.59,510.84],[2,1.54,136.04]],"batl":[[0,1.69,480.59],[1,1.71,497.4],[2,3.95,2.13]],"ltp":1.65,"tv":6521.49,"id":8260126}]}]}
{"op":"mcm","clk":"1008521421","pt":1580636530239,"mc":[{"id":"1.168224423","rc":[{"batb":[[2,1.56,683.6]],"batl":[[0,1.68,542.99],[1,1.69,480.59],[2,1.7,652.6]],"ltp":1.65,"tv":6521.49,"id":8260126}]}]}
{"op":"mcm","clk":"1008521757","pt":1580636533951,"mc":[{"id":"1.168224423","rc":[{"batl":[[0,1.69,480.59],[1,1.71,497.4],[2,3.95,2.13]],"ltp":1.65,"tv":6521.49,"id":8260126}]}]}
{"op":"mcm","clk":"1008521835","pt":1580636534625,"mc":[{"id":"1.168224423","rc":[{"batb":[[0,1.56,683.6],[1,1.55,456.34],[2,1.54,136.04]],"ltp":1.65,"tv":6521.49,"id":8260126}]}]}
{"op":"mcm","clk":"1008522144","pt":1580636537370,"mc":[{"id":"1.168224423","rc":[{"batb":[[0,1.58,561.54],[1,1.56,2125.91],[2,1.55,456.34]],"batl":[[0,1.61,1974.13],[1,1.62,1118.98],[2,1.66,653.65]],"ltp":1.65,"tv":6521.49,"id":8260126},{"batl":[[0,2.72,7.22],[1,2.86,293],[2,2.96,2.53]],"ltp":2.52,"tv":1348.48,"id":4486603}]}]}
{"op":"mcm","clk":"1008522188","pt":1580636537786,"mc":[{"id":"1.168224423","rc":[{"batl":[[2,1.64,42.01]],"ltp":1.65,"tv":6521.49,"id":8260126},{"batb":[[0,2.62,53.03],[1,2.54,26.89],[2,2.52,59.01]],"batl":[[2,2.94,21]],"ltp":2.52,"tv":1348.48,"id":4486603}]}]}
{"op":"mcm","clk":"1008522721","pt":1580636543779,"mc":[{"id":"1.168224423","rc":[{"batl":[[2,2.94,24.25]],"ltp":2.52,"tv":1348.48,"id":4486603}]}]}
{"op":"mcm","clk":"1008522812","pt":1580636545276,"mc":[{"id":"1.168224423","rc":[{"trd":[[1.61,1426.72]],"batl":[[0,1.61,1675.86]],"ltp":1.61,"tv":7118.03,"id":8260126}],"tv":8466.51}]}
{"op":"mcm","clk":"1008523143","pt":1580636550452,"mc":[{"id":"1.168224423","rc":[{"batb":[[0,1.52,114.15],[1,1.48,162.17],[2,1.33,3.36]],"batl":[[0,1.64,42.01],[1,1.67,26.5],[2,3.95,2.13]],"ltp":1.61,"tv":7118.03,"id":8260126},{"batb":[[0,2.54,26.89],[1,2.52,59.01],[2,2.48,3.51]],"batl":[[0,2.94,24.25],[1,2.96,2.53],[2,3,52.14]],"ltp":2.52,"tv":1348.48,"id":4486603}]}]}
{"op":"mcm","clk":"1008523155","pt":1580636550660,"mc":[{"id":"1.168224423","rc":[{"batb":[[0,1.52,33.49]],"batl":[[0,1.67,26.5],[1,3.95,2.13],[2,1000,0.02]],"ltp":1.61,"tv":7118.03,"id":8260126},{"batb":[[0,2.52,59.01],[1,2.48,3.51],[2,1.8,75.72]],"batl":[[0,2.94,3.25]],"ltp":2.52,"tv":1348.48,"id":4486603}]}]}
{"op":"mcm","clk":"1008523317","pt":1580636552984,"mc":[{"id":"1.168224423","rc":[{"batb":[[1,1.5,676.23],[2,1.49,533.69]],"batl":[[0,1.65,551.4],[1,1.66,352.04],[2,1.67,26.5]],"ltp":1.61,"tv":7118.03,"id":8260126}]}]}
{"op":"mcm","clk":"1008523363","pt":1580636553608,"mc":[{"id":"1.168224423","rc":[{"batl":[[0,1.65,579.3]],"ltp":1.61,"tv":7118.03,"id":8260126},{"batb":[[0,2.52,63]],"ltp":2.52,"tv":1348.48,"id":4486603}]}]}
{"op":"mcm","clk":"1008523478","pt":1580636555161,"mc":[{"id":"1.168224423","rc":[{"batb":[[0,1.61,33.74],[1,1.52,33.49],[2,1.5,676.23]],"ltp":1.61,"tv":7118.03,"id":8260126}]}]}
{"op":"mcm","clk":"1008523554","pt":1580636556452,"mc":[{"id":"1.168224423","rc":[{"batb":[[2,1.48,162.17]],"batl":[[0,1.65,27.9],[1,1.67,26.5],[2,3.95,2.13]],"ltp":1.61,"tv":7118.03,"id":8260126}]}]}
{"op":"mcm","clk":"1008523567","pt":1580636556660,"mc":[{"id":"1.168224423","rc":[{"batl":[[0,1.67,26.5],[1,3.95,2.13],[2,1000,0.02]],"ltp":1.61,"tv":7118.03,"id":8260126},{"batb":[[0,2.52,59.01]],"ltp":2.52,"tv":1348.48,"id":4486603}]}]}
{"op":"mcm","clk":"1008523756","pt":1580636559293,"mc":[{"id":"1.168224423","rc":[{"trd":[[1.61,1494.2]],"batb":[[0,1.55,572.05],[1,1.54,467.37],[2,1.52,33.49]],"batl":[[0,1.6,691.84],[1,1.61,391.5],[2,1.67,26.5]],"ltp":1.61,"tv":7185.51,"id":8260126}],"tv":8533.99}]}
{"op":"mcm","clk":"1008523819","pt":1580636559975,"mc":[{"id":"1.168224423","rc":[{"batb":[[0,1.52,33.49],[1,1.48,162.17],[2,1.33,3.36]],"batl":[[0,1.67,26.5],[1,3.95,2.13],[2,1000,0.02]],"ltp":1.61,"tv":7185.51,"id":8260126}]}]}
{"op":"mcm","clk":"1008524016","pt":1580636563114,"mc":[{"id":"1.168224423","rc":[{"batb":[[1,1.5,696.29],[2,1.49,533.7]],"batl":[[0,1.65,558.1],[1,1.66,352.03],[2,1.67,26.5]],"ltp":1.61,"tv":7185.51,"id":8260126},{"batb":[[0,2.52,63]],"ltp":2.52,"tv":1348.48,"id":4486603}]}]}
{"op":"mcm","clk":"1008524174","pt":1580636565694,"mc":[{"id":"1.168224423","rc":[{"batb":[[1,1.48,162.17],[2,1.33,3.36]],"ltp":1.61,"tv":7185.51,"id":8260126}]}]}
{"op":"mcm","clk":"1008524353","pt":1580636568425,"mc":[{"id":"1.168224423","rc":[{"batb":[[0,1.6,1406.25],[1,1.52,33.49],[2,1.48,162.17]],"batl":[[0,1.65,1921.74],[1,1.66,899.16]],"ltp":1.61,"tv":7185.51,"id":8260126},{"batb":[[2,2.42,367.15]],"batl":[[0,2.6,392.49],[1,2.62,2353],[2,2.74,378]],"ltp":2.52,"tv":1348.48,"id":4486603}]}]}
{"op":"mcm","clk":"1008524417","pt":1580636569312,"mc":[{"id":"1.168224423","rc":[{"batb":[[0,1.6,1969.42],[1,1.59,413.69],[2,1.58,124.24]],"ltp":1.61,"tv":7185.51,"id":8260126},{"batb":[[2,2.44,63.81]],"batl":[[1,2.74,378],[2,2.94,3.25]],"ltp":2.52,"tv":1348.48,"id":4486603}]}]}
{"op":"mcm","clk":"1008524478","pt":1580636570188,"mc":[{"id":"1.168224423","rc":[{"batb":[[0,1.6,1406.25],[1,1.58,124.24],[2,1.56,74.78]],"batl":[[0,1.65,1388.54],[1,1.66,547.13]],"ltp":1.61,"tv":7185.51,"id":8260126},{"batb":[[2,2.44,92.38]],"batl":[[2,2.78,23.53]],"ltp":2.52,"tv":1348.48,"id":4486603}]}]}
{"op":"mcm","clk":"1008524830","pt":1580636575220,"mc":[{"id":"1.168224423","rc":[{"batb":[[0,1.61,16.87],[1,1.6,1406.25],[2,1.59,494.03]],"batl":[[0,1.65,1363.64]],"ltp":1.61,"tv":7185.51,"id":8260126},{"batb":[[0,2.52,59.01]],"ltp":2.52,"tv":1348.48,"id":4486603}]}]}
{"op":"mcm","clk":"1008525027","pt":1580636578010,"mc":[{"id":"1.168224423","rc":[{"batb":[[0,1.61,43.96],[1,1.6,1432.64]],"batl":[[0,1.65,1391.54],[1,1.66,572.88]],"ltp":1.61,"tv":7185.51,"id":8260126},{"batb":[[0,2.52,63.5],[1,2.5,4.33],[2,2.48,3.51]],"batl":[[1,2.64,3.68],[2,2.68,3.64]],"ltp":2.52,"tv":1348.48,"id":4486603}]}]}
{"op":"mcm","clk":"1008525421","pt":1580636584008,"mc":[{"id":"1.168224423","rc":[{"batb":[[0,1.61,16.87],[1,1.6,26.39]],"batl":[[0,1.66,25.75],[1,1.68,42.01],[2,1.69,480.59]],"ltp":1.61,"tv":7185.51,"id":8260126},{"batb":[[0,2.5,4.33],[1,2.44,92.38],[2,1.8,75.72]],"batl":[[0,2.68,3.64],[1,2.78,23.53],[2,2.94,3.25]],"ltp":2.52,"tv":1348.48,"id":4486603}]}]}
{"op":"mcm","clk":"1008525458","pt":1580636584626,"mc":[{"id":"1.168224423","rc":[{"batl":[[1,1.69,480.59],[2,1.71,497.4]],"ltp":1.61,"tv":7185.51,"id":8260126},{"batb":[[1,2.44,63.81]],"batl":[[1,2.94,3.25],[2,2.96,2.53]],"ltp":2.52,"tv":1348.48,"id":4486603}]}]}
{"op":"mcm","clk":"1008525622","pt":1580636587318,"mc":[{"id":"1.168224423","rc":[{"batb":[[0,1.61,42.96]],"batl":[[0,1.65,27.9],[1,1.66,25.75],[2,1.69,480.59]],"ltp":1.61,"tv":7185.51,"id":8260126},{"batb":[[0,2.52,3.49],[1,2.5,4.33],[2,2.44,63.81]],"batl":[[0,2.64,3.43],[1,2.68,3.64],[2,2.94,3.25]],"ltp":2.52,"tv":1348.48,"id":4486603}]}]}
{"op":"mcm","clk":"1008525676","pt":1580636588035,"mc":[{"id":"1.168224423","rc":[{"batb":[[0,1.61,16.87]],"batl":[[0,1.66,25.75],[1,1.69,480.59],[2,1.71,497.4]],"ltp":1.61,"tv":7185.51,"id":8260126},{"batb":[[0,2.5,4.33],[1,2.44,63.81],[2,1.8,75.72]],"batl":[[0,2.68,3.64],[1,2.94,3.25],[2,2.96,2.53]],"ltp":2.52,"tv":1348.48,"id":4486603}]}]}
{"op":"mcm","clk":"1008526317","pt":1580636596427,"mc":[{"id":"1.168224423","rc":[{"trd":[[1.66,32.24],[1.69,29.19]],"batl":[[0,3.95,2.13],[1,1000,0.02],[2,1.71,0]],"ltp":1.69,"tv":7240.45,"id":8260126},{"trd":[[2.44,229.79],[2.5,35.22]],"batb":[[0,1.8,75.72],[1,1.7,75.72],[2,1.6,75.72]],"batl":[[0,2.5,416.2],[1,2.68,3.64]],"ltp":2.44,"tv":1522.07,"id":4486603}],"tv":8762.52}]}
{"op":"mcm","clk":"1008526427","pt":1580636598029,"mc":[{"id":"1.168224423","rc":[{"trd":[[1.66,59.74]],"batb":[[0,1.61,43.96]],"ltp":1.66,"tv":7267.95,"id":8260126},{"trd":[[2.5,61.46]],"batl":[[0,2.5,393.95],[1,2.64,3.68],[2,2.68,3.64]],"ltp":2.5,"tv":1548.31,"id":4486603}],"tv":8816.26}]}
{"op":"mcm","clk":"1008526522","pt":1580636599427,"mc":[{"id":"1.168224423","rc":[{"batb":[[0,1.66,13.39],[1,1.61,43.96],[2,1.6,26.39]],"batl":[[0,1.7,665.17],[1,1.74,472.54],[2,3.95,1.68]],"ltp":1.66,"tv":7267.95,"id":8260126},{"trd":[[2.5,74.04]],"batl":[[0,2.5,698.02],[1,2.56,79.07],[2,2.64,312.68]],"ltp":2.5,"tv":1560.89,"id":4486603}],"tv":8828.84}]}
{"op":"mcm","clk":"1008526553","pt":1580636600045,"mc":[{"id":"1.168224423","rc":[{"batb":[[1,1.61,228.15]],"batl":[[1,1.74,514.55]],"ltp":1.66,"tv":7267.95,"id":8260126},{"batb":[[0,2.44,63.81],[1,2.36,30.25],[2,2.26,80.02]],"batl":[[2,2.64,337.89]],"ltp":2.5,"tv":1560.89,"id":4486603}]}]}
{"op":"mcm","clk":"1008526704","pt":1580636602669,"mc":[{"id":"1.168224423","rc":[{"batl":[[0,2.5,706.42]],"ltp":2.5,"tv":1560.89,"id":4486603}]}]}
{"op":"mcm","clk":"1008526915","pt":1580636606174,"mc":[{"id":"1.168224423","rc":[{"batb":[[1,1.62,331.42],[2,1.61,425.82]],"batl":[[0,1.67,184],[1,1.69,333.4],[2,1.7,665.17]],"ltp":1.66,"tv":7267.95,"id":8260126}]}]}
{"op":"mcm","clk":"1008527032","pt":1580636607876,"mc":[{"id":"1.168224423","rc":[{"batb":[[1,1.64,114.09],[2,1.62,331.42]],"ltp":1.66,"tv":7267.95,"id":8260126},{"batb":[[2,2.24,81.59]],"ltp":2.5,"tv":1560.89,"id":4486603}]}]}
{"op":"mcm","clk":"1008527112","pt":1580636609171,"mc":[{"id":"1.168224423","rc":[{"trd":[[1.66,157.15],[1.67,79.78]],"batb":[[0,1.64,114.09],[1,1.62,331.42],[2,1.61,425.82]],"batl":[[0,1.7,665.17],[1,1.74,514.55],[2,3.95,1.68]],"ltp":1.66,"tv":7423.4,"id":8260126},{"trd":[[2.5,120.94]],"batl":[[0,2.5,659.52]],"ltp":2.5,"tv":1607.79,"id":4486603}],"tv":9031.19}]}
{"op":"mcm","clk":"1008527308","pt":1580636612148,"mc":[{"id":"1.168224423","rc":[{"batl":[[0,1.68,336.14],[1,1.7,990.93],[2,1.74,514.55]],"ltp":1.66,"tv":7423.4,"id":8260126}]}]}
{"op":"mcm","clk":"1008527741","pt":1580636619155,"mc":[{"id":"1.168224423","rc":[{"batl":[[1,1.7,974.76]],"ltp":1.66,"tv":7423.4,"id":8260126}]}]}
{"op":"mcm","clk":"1008527905","pt":1580636621380,"mc":[{"id":"1.168224423","rc":[{"batl":[[0,1.67,2],[1,1.68,336.14],[2,1.7,974.76]],"ltp":1.66,"tv":7423.4,"id":8260126}]}]}
{"op":"mcm","clk":"1008527965","pt":1580636622355,"mc":[{"id":"1.168224423","rc":[{"batl":[[1,1.68,351.19]],"ltp":1.66,"tv":7423.4,"id":8260126},{"batl":[[0,2.5,651.12],[1,2.56,88.78]],"ltp":2.5,"tv":1607.79,"id":4486603}]}]}
{"op":"mcm","clk":"1008528174","pt":1580636625492,"mc":[{"id":"1.168224423","rc":[{"trd":[[1.67,81.78]],"batl":[[0,1.68,351.19],[1,1.7,974.76],[2,1.74,514.55]],"ltp":1.67,"tv":7425.4,"id":8260126},{"trd":[[2.48,1.34]],"batl":[[0,2.48,7.06],[1,2.5,651.12],[2,2.56,88.78]],"ltp":2.48,"tv":1609.13,"id":4486603}],"tv":9034.54}]}
{"op":"mcm","clk":"1008528877","pt":1580636636376,"mc":[{"id":"1.168224423","rc":[{"batb":[[1,1.61,228.15],[2,1.6,151.81]],"batl":[[0,1.68,15.05],[1,1.7,649]],"ltp":1.67,"tv":7425.4,"id":8260126}]}]}
{"op":"mcm","clk":"1008529519","pt":1580636645316,"mc":[{"id":"1.168224423","rc":[{"batl":[[0,2.5,651.12],[1,2.56,88.78],[2,2.64,337.89]],"ltp":2.48,"tv":1609.13,"id":4486603}]}]}
{"op":"mcm","clk":"1008529710","pt":1580636648398,"mc":[{"id":"1.168224423","rc":[{"trd":[[1.68,10.33]],"batl":[[0,1.68,4.72]],"ltp":1.68,"tv":7435.73,"id":8260126},{"trd":[[2.46,7.06]],"ltp":2.46,"tv":1616.19,"id":4486603}],"tv":9051.93}]}
{"op":"mcm","clk":"1008529779","pt":1580636649431,"mc":[{"id":"1.168224423","rc":[{"batb":[[0,1.61,112.02],[1,1.6,125.42],[2,1.58,394.45]],"batl":[[0,1.74,42.46],[1,1.77,297.46],[2,1.79,274.84]],"ltp":1.68,"tv":7435.73,"id":8260126},{"batb":[[0,2.36,30.25],[1,2.24,81.59],[2,1.8,75.72]],"batl":[[0,2.5,340.76],[1,2.64,28.89],[2,2.96,2.53]],"ltp":2.46,"tv":1616.19,"id":4486603}]}]}
{"op":"mcm","clk":"1008529863","pt":1580636650716,"mc":[{"id":"1.168224423","rc":[{"batb":[[0,1.61,43.96]],"batl":[[0,1.77,297.91],[1,1.79,274.84],[2,3.95,1.68]],"ltp":1.68,"tv":7435.73,"id":8260126},{"batb":[[0,2.24,81.59],[1,1.8,75.72],[2,1.7,75.72]],"batl":[[1,2.64,3.68]],"ltp":2.46,"tv":1616.19,"id":4486603}]}]}
{"op":"mcm","clk":"1008529962","pt":1580636652104,"mc":[{"id":"1.168224423","rc":[{"batb":[[2,1.59,40.11]],"batl":[[2,2.26,4.75]],"ltp":1.68,"tv":7435.73,"id":8260126},{"batb":[[1,1.8,98.4],[2,1.7,102.14]],"batl":[[2,2.7,7.85]],"ltp":2.46,"tv":1616.19,"id":4486603}]}]}
{"op":"mcm","clk":"1008530801","pt":1580636663427,"mc":[{"id":"1.168224423","rc":[{"trd":[[1.73,0.45]],"batb":[[0,1.76,752.36],[1,1.75,126.23],[2,1.72,39.84]],"batl":[[0,1.77,297.46],[2,1.8,450]],"ltp":1.73,"tv":7436.19,"id":8260126},{"trd":[[2.36,0.33]],"batb":[[0,2.24,89.19]],"batl":[[0,2.4,9.49],[1,2.42,367],[2,2.48,74.23]],"ltp":2.36,"tv":1616.52,"id":4486603}],"tv":9052.71}]}
{"op":"mcm","clk":"1008530888","pt":1580636664455,"mc":[{"id":"1.168224423","rc":[{"batb":[[2,1.74,93.32]],"ltp":1.73,"tv":7436.19,"id":8260126},{"batb":[[1,2.2,34.45],[2,2.04,107.79]],"batl":[[2,2.48,101.96]],"ltp":2.36,"tv":1616.52,"id":4486603}]}]}
{"op":"mcm","clk":"1008531286","pt":1580636669859,"mc":[{"id":"1.168224423","rc":[{"batl":[[2,1.8,930.59]],"ltp":1.73,"tv":7436.19,"id":8260126}]}]}
{"op":"mcm","clk":"1008531381","pt":1580636671354,"mc":[{"id":"1.168224423","rc":[{"trd":[[1.76,318]],"batb":[[0,1.76,593.36]],"ltp":1.76,"tv":7754.19,"id":8260126}],"tv":9370.71}]}
{"op":"mcm","clk":"1008531503","pt":1580636673153,"mc":[{"id":"1.168224423","rc":[{"trd":[[1.77,297.46]],"batl":[[0,1.79,274.84],[1,1.8,930.59],[2,1.82,497.4]],"ltp":1.77,"tv":8051.65,"id":8260126},{"trd":[[2.28,230.94]],"batl":[[0,2.28,5.11],[1,2.4,9.49],[2,2.42,367]],"ltp":2.28,"tv":1847.46,"id":4486603}],"tv":9899.11}]}
{"op":"mcm","clk":"1008531569","pt":1580636673947,"mc":[{"id":"1.168224423","rc":[{"batl":[[0,1.8,930.59],[1,1.82,497.4],[2,1.83,42.01]],"ltp":1.77,"tv":8051.65,"id":8260126},{"batl":[[0,2.28,25.11]],"ltp":2.28,"tv":1847.46,"id":4486603}]}]}
{"op":"mcm","clk":"1008531641","pt":1580636674859,"mc":[{"id":"1.168224423","rc":[{"batl":[[0,2.28,20]],"ltp":2.28,"tv":1847.46,"id":4486603}]}]}
{"op":"mcm","clk":"1008531742","pt":1580636676446,"mc":[{"id":"1.168224423","rc":[{"trd":[[1.78,25.62]],"batb":[[0,1.76,593.85]],"batl":[[0,1.78,245.92],[1,1.8,1200.03],[2,1.82,497.4]],"ltp":1.78,"tv":8077.27,"id":8260126},{"trd":[[2.28,250.94]],"batl":[[0,2.4,9.49],[1,2.42,367],[2,2.48,101.96]],"ltp":2.28,"tv":1867.46,"id":4486603}],"tv":9944.73}]}
{"op":"mcm","clk":"1008532138","pt":1580636681252,"mc":[{"id":"1.168224423","rc":[{"batb":[[0,2.24,81.59]],"ltp":2.28,"tv":1867.46,"id":4486603}]}]}
{"op":"mcm","clk":"1008532365","pt":1580636684235,"mc":[{"id":"1.168224423","rc":[{"batb":[[0,1.72,494.52],[1,1.7,510.84],[2,1.68,61.33]],"batl":[[0,1.8,480.59],[1,1.82,497.4],[2,1.83,42.01]],"ltp":1.78,"tv":8077.27,"id":8260126},{"batb":[[0,2.2,34.45],[1,2.04,107.79],[2,1.69,24.21]],"batl":[[0,2.48,27.73],[1,2.52,8.26],[2,2.62,7.75]],"ltp":2.28,"tv":1867.46,"id":4486603}]}]}
{"op":"mcm","clk":"1008532404","pt":1580636684751,"mc":[{"id":"1.168224423","rc":[{"batb":[[2,1.67,107.4]],"batl":[[2,2.42,286.52]],"ltp":1.78,"tv":8077.27,"id":8260126},{"batb":[[0,2.04,107.79],[1,1.69,24.21],[2,1.68,28.61]],"batl":[[0,2.52,8.26],[1,2.62,7.75],[2,2.64,3.68]],"ltp":2.28,"tv":1867.46,"id":4486603}]}]}
{"op":"mcm","clk":"1008532529","pt":1580636686861,"mc":[{"id":"1.168224423","rc":[{"batb":[[0,1.67,107.4],[1,1.66,255.89],[2,1.65,179.97]],"ltp":1.78,"tv":8077.27,"id":8260126}]}]}
{"op":"mcm","clk":"1008532700","pt":1580636689278,"mc":[{"id":"1.168224423","rc":[{"batl":[[0,1.73,513],[1,1.78,122.32],[2,1.8,1253.45]],"ltp":1.78,"tv":8077.27,"id":8260126},{"batb":[[0,2.42,7.69],[1,2.28,91.21],[2,2.04,107.79]],"batl":[[0,2.46,535.43],[1,2.5,11.21],[2,2.52,8.26]],"ltp":2.28,"tv":1867.46,"id":4486603}]}]}
{"op":"mcm","clk":"1008532773","pt":1580636690363,"mc":[{"id":"1.168224423","rc":[{"batl":[[0,1.71,227.02],[1,1.73,819.87],[2,1.78,164.33]],"ltp":1.78,"tv":8077.27,"id":8260126},{"batb":[[1,2.38,69.79],[2,2.28,123.98]],"ltp":2.28,"tv":1867.46,"id":4486603}]}]}
{"op":"mcm","clk":"1008533145","pt":1580636695675,"mc":[{"id":"1.168224423","rc":[{"batl":[[2,1.74,480.59]],"ltp":1.78,"tv":8077.27,"id":8260126}]}]}
{"op":"mcm","clk":"1008533439","pt":1580636699587,"mc":[{"id":"1.168224423","rc":[{"trd":[[1.68,12.01]],"ltp":1.68,"tv":8078.95,"id":8260126},{"trd":[[2.46,8.21]],"batl":[[0,2.46,534.28]],"ltp":2.46,"tv":1868.61,"id":4486603}],"tv":9947.56}]}
{"op":"mcm","clk":"1008533591","pt":1580636701398,"mc":[{"id":"1.168224423","rc":[{"batb":[[1,1.64,494.03],[2,1.63,105.61]],"batl":[[0,1.74,480.59],[1,1.76,497.4],[2,1.78,42.01]],"ltp":1.68,"tv":8078.95,"id":8260126},{"batb":[[0,2.38,69.79],[1,2.28,32.77],[2,2.16,91.27]],"batl":[[0,2.58,26.05],[1,2.6,8.16],[2,2.62,7.75]],"ltp":2.46,"tv":1868.61,"id":4486603}]}]}
{"op":"mcm","clk":"1008533599","pt":1580636701505,"mc":[{"id":"1.168224423","rc":[{"batb":[[0,1.64,494.54],[1,1.63,105.61],[2,1.62,669.1]],"ltp":1.68,"tv":8078.95,"id":8260126},{"batb":[[0,2.28,32.77],[1,2.16,91.27],[2,1.76,25.48]],"ltp":2.46,"tv":1868.61,"id":4486603}]}]}
{"op":"mcm","clk":"1008533710","pt":1580636702703,"mc":[{"id":"1.168224423","rc":[{"batb":[[0,1.69,207.19],[1,1.64,494.03],[2,1.63,39.23]],"batl":[[2,2.32,4.61]],"ltp":1.68,"tv":8078.95,"id":8260126},{"batb":[[0,2.16,91.27],[1,1.76,25.48],[2,1.7,75.72]],"batl":[[0,2.6,8.16],[1,2.62,7.75],[2,2.64,3.68]],"ltp":2.46,"tv":1868.61,"id":4486603}]}]}
{"op":"mcm","clk":"1008533839","pt":1580636704306,"mc":[{"id":"1.168224423","rc":[{"batl":[[2,1.83,213.21]],"ltp":1.68,"tv":8078.95,"id":8260126}]}]}
{"op":"mcm","clk":"1008534064","pt":1580636706996,"mc":[{"id":"1.168224423","rc":[{"trd":[[1.74,27.02]],"batl":[[0,1.74,467.08]],"ltp":1.74,"tv":8105.97,"id":8260126}],"tv":9974.58}]}
{"op":"mcm","clk":"1008534398","pt":1580636710769,"mc":[{"id":"1.168224423","rc":[{"batb":[[0,1.64,494.54],[1,1.63,39.23],[2,1.62,669.1]],"ltp":1.74,"tv":8105.97,"id":8260126}]}]}
{"op":"mcm","clk":"1008535121","pt":1580636720113,"mc":[{"id":"1.168224423","rc":[{"batl":[[0,1.83,213.21],[1,1.85,247.14],[2,2.32,4.61]],"ltp":1.74,"tv":8105.97,"id":8260126}]}]}
{"op":"mcm","clk":"1008535274","pt":1580636722440,"mc":[{"id":"1.168224423","rc":[{"trd":[[1.83,426.42]],"batb":[[0,1.83,327.9],[1,1.73,1124.37],[2,1.64,494.54]],"batl":[[0,1.85,247.14],[1,1.87,510],[2,1.96,570.62]],"ltp":1.83,"tv":8532.39,"id":8260126},{"batl":[[0,2.26,2669],[1,2.32,2041.96],[2,2.42,5.95]],"ltp":2.46,"tv":1868.61,"id":4486603}],"tv":10401.0}]}
{"op":"mcm","clk":"1008535339","pt":1580636723212,"mc":[{"id":"1.168224423","rc":[{"batb":[[1,1.78,39.16],[2,1.73,112.44]],"batl":[[0,1.86,16.04]],"ltp":1.83,"tv":8532.39,"id":8260126},{"batb":[[2,1.69,24.21]],"batl":[[0,2.24,10.93],[1,2.3,10.05],[2,2.32,597.5]],"ltp":2.46,"tv":1868.61,"id":4486603}]}]}
{"op":"mcm","clk":"1008535383","pt":1580636723829,"mc":[{"id":"1.168224423","rc":[{"batb":[[1,1.8,84.11],[2,1.78,39.16]],"batl":[[2,1.88,42.01]],"ltp":1.83,"tv":8532.39,"id":8260126},{"batb":[[1,2.14,36.13],[2,1.92,64.44]],"ltp":2.46,"tv":1868.61,"id":4486603}]}]}
{"op":"mcm","clk":"1008535586","pt":1580636726212,"mc":[{"id":"1.168224423","rc":[{"batb":[[2,1.78,244.71]],"batl":[[0,1.84,219.93],[1,1.86,258.71],[2,1.87,510]],"ltp":1.83,"tv":8532.39,"id":8260126}]}]}
{"op":"mcm","clk":"1008535816","pt":1580636729203,"mc":[{"id":"1.168224423","rc":[{"batb":[[2,1.79,494.03]],"batl":[[2,1.87,990.59]],"ltp":1.83,"tv":8532.39,"id":8260126}]}]}
{"op":"mcm","clk":"1008535973","pt":1580636731414,"mc":[{"id":"1.168224423","rc":[{"trd":[[1.84,26.5]],"batl":[[0,1.84,206.68]],"ltp":1.84,"tv":8558.89,"id":8260126}],"tv":10427.5}]}
{"op":"mcm","clk":"1008535979","pt":1580636731515,"mc":[{"id":"1.168224423","rc":[{"trd":[[1.83,433.14]],"batb":[[0,1.83,324.54]],"ltp":1.83,"tv":8565.61,"id":8260126}],"tv":10434.22}]}
{"op":"mcm","clk":"1008536131","pt":1580636733429,"mc":[{"id":"1.168224423","rc":[{"trd":[[1.84,233.18]],"batl":[[0,1.86,258.71],[1,1.87,990.59],[2,1.88,42.01]],"ltp":1.84,"tv":8772.29,"id":8260126},{"trd":[[2.18,174.46]],"batl":[[0,2.18,9.11],[1,2.24,10.93],[2,2.3,10.05]],"ltp":2.18,"tv":2043.06,"id":4486603}],"tv":10815.36}]}
{"op":"mcm","clk":"1008536171","pt":1580636733944,"mc":[{"id":"1.168224423","rc":[{"batl":[[0,1.86,16.04]],"ltp":1.84,"tv":8772.29,"id":8260126}]}]}
{"op":"mcm","clk":"1008536427","pt":1580636737151,"mc":[{"id":"1.168224423","rc":[{"batb":[[2,1.79,685.72]],"batl":[[0,1.85,220.64],[1,1.86,16.04],[2,1.87,1228.92]],"ltp":1.84,"tv":8772.29,"id":8260126}]}]}
{"op":"mcm","clk":"1008536466","pt":1580636737515,"mc":[{"id":"1.168224423","rc":[{"trd":[[2.18,192.18]],"batl":[[0,2.24,11.18],[1,2.3,10.05],[2,2.32,597.5]],"ltp":2.18,"tv":2060.78,"id":4486603}],"tv":10833.08}]}
{"op":"mcm","clk":"1008536994","pt":1580636744420,"mc":[{"id":"1.168224423","rc":[{"batl":[[2,1.87,718.92]],"ltp":1.84,"tv":8772.29,"id":8260126},{"batl":[[2,2.32,160.5]],"ltp":2.18,"tv":2060.78,"id":4486603}]}]}
{"op":"mcm","clk":"1008537350","pt":1580636749364,"mc":[{"id":"1.168224423","rc":[{"trd":[[1.83,436.56],[1.84,233.47]],"batb":[[0,1.83,322.83]],"ltp":1.83,"tv":8776.0,"id":8260126},{"trd":[[2.18,192.42]],"batl":[[0,2.24,10.93]],"ltp":2.18,"tv":2061.03,"id":4486603}],"tv":10837.03}]}
{"op":"mcm","clk":"1008537431","pt":1580636750555,"mc":[{"id":"1.168224423","rc":[{"trd":[[1.85,40]],"batl":[[0,1.85,200.64]],"ltp":1.85,"tv":8816.0,"id":8260126}],"tv":10877.03}]}
{"op":"mcm","clk":"1008538061","pt":1580636758437,"mc":[{"id":"1.168224423","rc":[{"batb":[[0,1.79,494.03],[1,1.77,510.84],[2,1.72,57.97]],"batl":[[0,1.87,481.21],[1,1.88,42.01],[2,1.89,497.4]],"ltp":1.85,"tv":8816.0,"id":8260126},{"batb":[[0,2.14,36.13],[1,1.92,64.44],[2,1.61,30.09]],"batl":[[0,2.4,29.41],[1,2.46,8.25],[2,2.58,7.75]],"ltp":2.18,"tv":2061.03,"id":4486603}]}]}
{"op":"mcm","clk":"1008538081","pt":1580636758643,"mc":[{"id":"1.168224423","rc":[{"batb":[[2,1.7,100.87]],"batl":[[1,1.89,497.4],[2,2.42,286.52]],"ltp":1.85,"tv":8816.0,"id":8260126},{"batb":[[0,1.92,64.44],[1,1.61,30.09],[2,1.6,75.72]],"batl":[[0,2.46,8.25],[1,2.58,7.75],[2,2.6,8.16]],"ltp":2.18,"tv":2061.03,"id":4486603}]}]}
{"op":"mcm","clk":"1008538376","pt":1580636761445,"mc":[{"id":"1.168224423","rc":[{"batb":[[0,1.7,339.9],[1,1.69,36.21],[2,1.68,334.81]],"batl":[[0,1.87,480.59],[2,2.08,306.81]],"ltp":1.85,"tv":8816.0,"id":8260126}]}]}
{"op":"mcm","clk":"1008538397","pt":1580636761643,"mc":[{"id":"1.168224423","rc":[{"batl":[[2,2.42,286.52]],"ltp":1.85,"tv":8816.0,"id":8260126}]}]}
{"op":"mcm","clk":"1008538622","pt":1580636764327,"mc":[{"id":"1.168224423","rc":[{"trd":[[1.72,1065.79]],"batb":[[0,1.72,700.24],[1,1.7,339.9],[2,1.69,36.21]],"batl":[[0,1.76,293.37],[1,1.77,516],[2,1.78,278.19]],"ltp":1.72,"tv":8819.69,"id":8260126},{"trd":[[2.4,26.14]],"batb":[[0,2.32,11.64],[1,1.92,64.44],[2,1.61,30.09]],"batl":[[1,2.48,343],[2,2.58,7.75]],"ltp":2.4,"tv":2063.67,"id":4486603}],"tv":10883.36}]}
{"op":"mcm","clk":"1008538683","pt":1580636765149,"mc":[{"id":"1.168224423","rc":[{"batb":[[0,2.32,86.55],[1,2.06,105.12]],"ltp":2.4,"tv":2063.67,"id":4486603}]}]}
{"op":"mcm","clk":"1008538797","pt":1580636766388,"mc":[{"id":"1.168224423","rc":[{"batb":[[1,2.24,33.61],[2,2.06,105.12]],"batl":[[2,2.52,26.89]],"ltp":2.4,"tv":2063.67,"id":4486603}]}]}
{"op":"mcm","clk":"1008539091","pt":1580636770395,"mc":[{"id":"1.168224423","rc":[{"trd":[[1.72,1109.31]],"batb":[[0,1.72,678.48]],"ltp":1.72,"tv":8863.21,"id":8260126}],"tv":10926.88}]}
{"op":"mcm","clk":"1008539404","pt":1580636774419,"mc":[{"id":"1.168224423","rc":[{"batb":[[0,2.32,74.91]],"ltp":2.4,"tv":2063.67,"id":4486603}]}]}
{"op":"mcm","clk":"1008539548","pt":1580636776021,"mc":[{"id":"1.168224423","rc":[{"batl":[[0,2.36,2.52],[1,2.46,8.25],[2,2.48,343]],"ltp":2.4,"tv":2063.67,"id":4486603}]}]}
{"op":"mcm","clk":"1008539641","pt":1580636777313,"mc":[{"id":"1.168224423","rc":[{"trd":[[1.76,351.74]],"batl":[[0,1.76,276.5]],"ltp":1.76,"tv":8896.95,"id":8260126},{"trd":[[2.36,5.37]],"batb":[[0,2.36,5.04],[1,2.32,74.91],[2,2.24,33.61]],"batl":[[0,2.42,7.8]],"ltp":2.36,"tv":2068.71,"id":4486603}],"tv":10965.67}]}
{"op":"mcm","clk":"1008539810","pt":1580636779429,"mc":[{"id":"1.168224423","rc":[{"batb":[[0,1.7,100.87],[1,1.68,494.03],[2,1.66,573.85]],"batl":[[0,1.79,480.59],[1,1.8,150.49],[2,1.81,497.4]],"ltp":1.76,"tv":8896.95,"id":8260126},{"batb":[[0,2.32,74.91],[1,2.24,33.61],[2,2.06,105.12]],"batl":[[0,2.52,26.89],[1,2.58,7.75],[2,2.6,8.16]],"ltp":2.36,"tv":2068.71,"id":4486603}]}]}
{"op":"mcm","clk":"1008539825","pt":1580636779587,"mc":[{"id":"1.168224423","rc":[{"batb":[[0,1.68,494.03],[1,1.66,573.85],[2,1.64,36.32]],"batl":[[1,1.8,42.01]],"ltp":1.76,"tv":8896.95,"id":8260126},{"batb":[[0,2.24,33.61],[1,2.06,105.12],[2,1.7,75.72]],"ltp":2.36,"tv":2068.71,"id":4486603}]}]}
{"op":"mcm","clk":"1008539936","pt":1580636781130,"mc":[{"id":"1.168224423","rc":[{"batb":[[1,1.66,510.84]],"batl":[[1,1.8,3.36]],"ltp":1.76,"tv":8896.95,"id":8260126},{"batb":[[0,2.06,105.12],[1,1.7,75.72],[2,1.69,26.21]],"batl":[[0,2.58,7.75],[1,2.6,8.16],[2,2.62,7.75]],"ltp":2.36,"tv":2068.71,"id":4486603}]}]}
{"op":"mcm","clk":"1008540447","pt":1580636788139,"mc":[{"id":"1.168224423","rc":[{"batl":[[0,1.8,3.36],[1,1.93,154.42],[2,1.95,209.81]],"ltp":1.76,"tv":8896.95,"id":8260126}]}]}
{"op":"mcm","clk":"1008540705","pt":1580636791448,"mc":[{"id":"1.168224423","rc":[{"trd":[[1.8,6.72]],"batb":[[0,1.88,73.65],[1,1.87,214.32],[2,1.85,491.97]],"batl":[[0,1.93,154.42],[1,1.94,9.76]],"ltp":1.8,"tv":8903.67,"id":8260126},{"batb":[[1,1.94,599.46],[2,1.74,89.7]],"batl":[[0,2.12,712.92],[1,2.14,175.23],[2,2.16,10.97]],"ltp":2.36,"tv":2068.71,"id":4486603}],"tv":10972.39}]}
{"op":"mcm","clk":"1008540745","pt":1580636791923,"mc":[{"id":"1.168224423","rc":[{"batl":[[2,1.95,251.82]],"ltp":1.8,"tv":8903.67,"id":8260126},{"batb":[[1,2.04,40.33],[2,1.94,599.46]],"ltp":2.36,"tv":2068.71,"id":4486603}]}]}
{"op":"mcm","clk":"1008540981","pt":1580636795018,"mc":[{"id":"1.168224423","rc":[{"trd":[[1.89,1.68]],"ltp":1.89,"tv":8905.35,"id":8260126},{"trd":[[2.12,1.5]],"batl":[[0,2.12,711.42]],"ltp":2.12,"tv":2070.21,"id":4486603}],"tv":10975.57}]}
{"op":"mcm","clk":"1008541069","pt":1580636796144,"mc":[{"id":"1.168224423","rc":[{"trd":[[1.89,29.92]],"ltp":1.89,"tv":8933.59,"id":8260126},{"trd":[[2.12,26.68]],"batl":[[0,2.12,686.24]],"ltp":2.12,"tv":2095.39,"id":4486603}],"tv":11028.99}]}
{"op":"mcm","clk":"1008541615","pt":1580636803141,"mc":[{"id":"1.168224423","rc":[{"trd":[[1.93,3.36]],"batl":[[0,1.93,152.74]],"ltp":1.93,"tv":8936.95,"id":8260126}],"tv":11032.35}]}
{"op":"mcm","clk":"1008541746","pt":1580636804928,"mc":[{"id":"1.168224423","rc":[{"batl":[[1,1.95,251.82],[2,1.96,410]],"ltp":1.93,"tv":8936.95,"id":8260126}]}]}
{"op":"mcm","clk":"1008541973","pt":1580636808022,"mc":[{"id":"1.168224423","rc":[{"batl":[[0,1.9,1.68],[1,1.93,152.74],[2,1.95,251.82]],"ltp":1.93,"tv":8936.95,"id":8260126}]}]}
{"op":"mcm","clk":"1008542157","pt":1580636810148,"mc":[{"id":"1.168224423","rc":[{"batb":[[0,1.77,53.77],[1,1.73,96.46],[2,1.67,409.76]],"batl":[[1,1.95,42.01],[2,2.72,241.55]],"ltp":1.93,"tv":8936.95,"id":8260126},{"batb":[[0,2.04,40.33],[1,1.74,89.7],[2,1.5,75.72]],"batl":[[0,2.28,32.77],[1,2.58,7.75],[2,2.6,8.16]],"ltp":2.12,"tv":2095.39,"id":4486603}]}]}
{"op":"mcm","clk":"1008542250","pt":1580636811126,"mc":[{"id":"1.168224423","rc":[{"batb":[[0,1.73,96.46],[1,1.67,409.76],[2,1.64,36.32]],"batl":[[1,2.72,241.55],[2,3.95,1.68]],"ltp":1.93,"tv":8936.95,"id":8260126},{"batb":[[0,1.74,89.7],[1,1.5,75.72],[2,1.48,172.22]],"batl":[[0,2.58,7.75],[1,2.6,8.16],[2,2.62,7.75]],"ltp":2.12,"tv":2095.39,"id":4486603}]}]}
{"op":"mcm","clk":"1008542424","pt":1580636813340,"mc":[{"id":"1.168224423","rc":[{"batb":[[1,1.71,281.84],[2,1.7,34.72]],"batl":[[1,2.36,205.4],[2,2.4,235.54]],"ltp":1.93,"tv":8936.95,"id":8260126},{"batl":[[0,2.44,8.08],[1,2.58,7.75],[2,2.6,8.16]],"ltp":2.12,"tv":2095.39,"id":4486603}]}]}
{"op":"mcm","clk":"1008542534","pt":1580636814834,"mc":[{"id":"1.168224423","rc":[{"batl":[[0,2.72,241.55],[1,3.95,1.68],[2,1000,0.02]],"ltp":1.93,"tv":8936.95,"id":8260126}]}]}
{"op":"mcm","clk":"1008542701","pt":1580636817162,"mc":[{"id":"1.168224423","rc":[{"batl":[[0,3.95,1.68],[1,1000,0.02],[2,1000,0]],"ltp":1.93,"tv":8936.95,"id":8260126}]}]}
{"op":"mcm","clk":"1008542758","pt":1580636817943,"mc":[{"id":"1.168224423","rc":[{"trd":[[1.74,1642.34]],"batb":[[1,1.72,10.75],[2,1.71,281.84]],"batl":[[0,1.74,212.59],[1,1.77,237.56],[2,1.79,273.43]],"ltp":1.74,"tv":10552.27,"id":8260126},{"batb":[[0,2.32,10.66],[1,2.28,164.47],[2,1.74,89.7]],"batl":[[0,2.44,417.08]],"ltp":2.12,"tv":2095.39,"id":4486603}],"tv":12647.67}]}
{"op":"mcm","clk":"1008542811","pt":1580636818666,"mc":[{"id":"1.168224423","rc":[{"batb":[[1,2.28,243.15],[2,2.02,110.08]],"ltp":2.12,"tv":2095.39,"id":4486603}]}]}
{"op":"mcm","clk":"1008542946","pt":1580636820370,"mc":[{"id":"1.168224423","rc":[{"trd":[[1.74,1647.76]],"batl":[[0,1.74,209.88]],"ltp":1.74,"tv":10557.69,"id":8260126},{"batb":[[2,2.2,34.45]],"batl":[[1,2.48,27.73],[2,2.58,7.75]],"ltp":2.12,"tv":2095.39,"id":4486603}],"tv":12653.08}]}
{"op":"mcm","clk":"1008543206","pt":1580636824165,"mc":[{"id":"1.168224423","rc":[{"batl":[[1,1.77,718.15],[2,1.79,770.83]],"ltp":1.74,"tv":10557.69,"id":8260126}]}]}
{"op":"mcm","clk":"1008543229","pt":1580636824473,"mc":[{"id":"1.168224423","rc":[{"batl":[[2,2.54,8.38]],"ltp":2.12,"tv":2095.39,"id":4486603}]}]}
{"op":"mcm","clk":"1008543978","pt":1580636834114,"mc":[{"id":"1.168224423","rc":[{"batb":[[0,1.69,494.03],[1,1.67,982.78],[2,1.65,38.33]],"batl":[[0,1.77,480.59],[1,1.79,497.4],[2,1.83,42.01]],"ltp":1.74,"tv":10557.69,"id":8260126},{"batb":[[0,2.2,34.45],[1,2.02,110.08],[2,1.7,75.72]],"batl":[[0,2.48,27.73],[1,2.54,8.38],[2,2.58,7.75]],"ltp":2.12,"tv":2095.39,"id":4486603}]}]}
{"op":"mcm","clk":"1008544032","pt":1580636834795,"mc":[{"id":"1.168224423","rc":[{"batb":[[1,1.67,920.6]],"batl":[[2,2.46,4.75]],"ltp":1.74,"tv":10557.69,"id":8260126},{"batb":[[0,2.02,110.08],[1,1.7,75.72],[2,1.69,26.21]],"batl":[[0,2.54,8.38],[1,2.58,7.75],[2,2.6,8.16]],"ltp":2.12,"tv":2095.39,"id":4486603}]}]}
{"op":"mcm","clk":"1008544098","pt":1580636835673,"mc":[{"id":"1.168224423","rc":[{"batb":[[0,1.74,33.74],[1,1.69,494.03],[2,1.67,920.6]],"ltp":1.74,"tv":10557.69,"id":8260126}]}]}
{"op":"mcm","clk":"1008544174","pt":1580636836801,"mc":[{"id":"1.168224423","rc":[{"batl":[[2,1.95,197.82]],"ltp":1.74,"tv":10557.69,"id":8260126}]}]}
{"op":"mcm","clk":"1008544587","pt":1580636843204,"mc":[{"id":"1.168224423","rc":[{"batb":[[1,1.67,409.76],[2,1.65,38.33]],"batl":[[2,2.46,4.75]],"ltp":1.74,"tv":10557.69,"id":8260126}]}]}
{"op":"mcm","clk":"1008544666","pt":1580636844087,"mc":[{"id":"1.168224423","rc":[{"trd":[[1.77,358.26]],"batl":[[0,1.77,436.67]],"ltp":1.77,"tv":10618.48,"id":8260126},{"trd":[[2.28,271.94]],"ltp":2.28,"tv":2116.4,"id":4486603}],"tv":12734.89}]}
{"op":"mcm","clk":"1008544717","pt":1580636844804,"mc":[{"id":"1.168224423","rc":[{"batb":[[1,1.64,351.06],[2,1.63,226.45]],"ltp":1.77,"tv":10618.48,"id":8260126},{"batl":[[0,2.58,7.75],[1,2.6,8.16],[2,2.62,7.75]],"ltp":2.28,"tv":2116.4,"id":4486603}]}]}
{"op":"mcm","clk":"1008544825","pt":1580636846406,"mc":[{"id":"1.168224423","rc":[{"trd":[[1.74,1715.24]],"batb":[[0,1.64,351.06],[1,1.63,226.45],[2,1.62,38.04]],"batl":[[0,1.68,183.66],[1,1.69,270.35],[2,1.71,819.46]],"ltp":1.74,"tv":10685.97,"id":8260126},{"batb":[[0,2.46,152.44],[1,2.44,65.07],[2,2.36,537.15]],"batl":[[0,2.56,376.03],[1,2.58,7.75],[2,2.6,322.16]],"ltp":2.28,"tv":2116.4,"id":4486603}],"tv":12802.37}]}
{"op":"mcm","clk":"1008544892","pt":1580636847190,"mc":[{"id":"1.168224423","rc":[{"batl":[[2,1.71,866.57]],"ltp":1.74,"tv":10685.97,"id":8260126}]}]}
{"op":"mcm","clk":"1008545096","pt":1580636849414,"mc":[{"id":"1.168224423","rc":[{"batl":[[2,1.71,844.72]],"ltp":1.74,"tv":10685.97,"id":8260126}]}]}
{"op":"mcm","clk":"1008545152","pt":1580636850099,"mc":[{"id":"1.168224423","rc":[{"trd":[[1.68,15.79]],"batl":[[0,1.68,181.77],[2,1.71,819.46]],"ltp":1.68,"tv":10689.75,"id":8260126}],"tv":12806.15}]}
{"op":"mcm","clk":"1008545306","pt":1580636852310,"mc":[{"id":"1.168224423","rc":[{"batb":[[2,2.36,541.58]],"ltp":2.28,"tv":2116.4,"id":4486603}]}]}
{"op":"mcm","clk":"1008545443","pt":1580636854312,"mc":[{"id":"1.168224423","rc":[{"trd":[[1.68,177.25]],"batl":[[0,1.68,101.04]],"ltp":1.68,"tv":10851.21,"id":8260126}],"tv":12967.61}]}
{"op":"mcm","clk":"1008545942","pt":1580636861341,"mc":[{"id":"1.168224423","rc":[{"batb":[[0,1.62,38.04],[1,1.61,84.93],[2,1.6,124.71]],"batl":[[0,1.75,42.01],[1,1.76,21.77],[2,2.36,299.17]],"ltp":1.68,"tv":10851.21,"id":8260126},{"batb":[[0,2.32,31.09],[1,2.3,4.48],[2,2.24,82.07]],"batl":[[0,2.62,7.75],[1,2.64,25.21],[2,2.7,7.85]],"ltp":2.28,"tv":2116.4,"id":4486603}]}]}
{"op":"mcm","clk":"1008545974","pt":1580636861908,"mc":[{"id":"1.168224423","rc":[{"batb":[[0,1.68,206.69],[1,1.62,38.04],[2,1.61,84.93]],"ltp":1.68,"tv":10851.21,"id":8260126}]}]}
{"op":"mcm","clk":"1008546042","pt":1580636862995,"mc":[{"id":"1.168224423","rc":[{"batb":[[2,1.61,16.87]],"batl":[[0,1.76,21.77],[1,2.36,299.17],[2,2.46,4.75]],"ltp":1.68,"tv":10851.21,"id":8260126},{"batb":[[0,2.3,4.48],[1,2.24,82.07],[2,1.7,75.72]],"batl":[[0,2.46,7],[1,2.62,7.75]],"ltp":2.28,"tv":2116.4,"id":4486603}]}]}
{"op":"mcm","clk":"1008546143","pt":1580636864228,"mc":[{"id":"1.168224423","rc":[{"batb":[[0,1.62,38.04],[1,1.61,16.87],[2,1.6,124.71]],"batl":[[1,1.78,185.93],[2,1.8,268.79]],"ltp":1.68,"tv":10851.21,"id":8260126}]}]}
{"op":"mcm","clk":"1008546226","pt":1580636865420,"mc":[{"id":"1.168224423","rc":[{"batl":[[0,2.62,7.75],[1,2.7,7.85],[2,2.96,2.53]],"ltp":2.28,"tv":2116.4,"id":4486603}]}]}
{"op":"mcm","clk":"1008546322","pt":1580636867114,"mc":[{"id":"1.168224423","rc":[{"batl":[[1,2.36,299.17],[2,2.46,4.75]],"ltp":1.68,"tv":10851.21,"id":8260126}]}]}
{"op":"mcm","clk":"1008546511","pt":1580636870249,"mc":[{"id":"1.168224423","rc":[{"batb":[[2,1.6,649]],"batl":[[0,1.64,179.04],[1,1.65,178.64],[2,1.66,481]],"ltp":1.68,"tv":10851.21,"id":8260126},{"batb":[[0,2.6,7.8],[1,2.54,71.45],[2,2.5,87.55]],"batl":[[2,2.72,310]],"ltp":2.28,"tv":2116.4,"id":4486603}]}]}
{"op":"mcm","clk":"1008546544","pt":1580636870711,"mc":[{"id":"1.168224423","rc":[{"batb":[[2,2.52,58.78]],"ltp":2.28,"tv":2116.4,"id":4486603}]}]}
{"op":"mcm","clk":"1008546930","pt":1580636877035,"mc":[{"id":"1.168224423","rc":[{"trd":[[2.6,22.32]],"batb":[[0,2.54,72.25],[1,2.52,58.78],[2,2.5,87.55]],"ltp":2.6,"tv":2130.4,"id":4486603}],"tv":12981.61}]}
{"op":"mcm","clk":"1008547118","pt":1580636880220,"mc":[{"id":"1.168224423","rc":[{"trd":[[1.63,1599.8]],"batb":[[0,1.63,2.46],[1,1.62,38.04],[2,1.61,16.87]],"ltp":1.63,"tv":10852.48,"id":8260126},{"trd":[[2.6,23.12]],"batb":[[0,2.54,71.45]],"ltp":2.6,"tv":2131.2,"id":4486603}],"tv":12983.68}]}
{"op":"mcm","clk":"1008547235","pt":1580636882229,"mc":[{"id":"1.168224423","rc":[{"trd":[[1.64,1075]],"batb":[[0,1.64,872.1],[1,1.63,2.05],[2,1.62,38.04]],"batl":[[0,1.65,178.64],[1,1.66,481],[2,1.67,23.5]],"ltp":1.64,"tv":11210.57,"id":8260126}],"tv":13341.77}]}
{"op":"mcm","clk":"1008547365","pt":1580636884133,"mc":[{"id":"1.168224423","rc":[{"trd":[[1.64,1275]],"batb":[[0,1.64,772.09]],"ltp":1.64,"tv":11410.57,"id":8260126}],"tv":13541.77}]}
{"op":"mcm","clk":"1008547462","pt":1580636885419,"mc":[{"id":"1.168224423","rc":[{"trd":[[1.64,1329.05]],"batb":[[0,1.64,745.07]],"batl":[[0,1.65,258.29],[2,1.67,366.85]],"ltp":1.64,"tv":11464.61,"id":8260126}],"tv":13595.81}]}
{"op":"mcm","clk":"1008547770","pt":1580636890346,"mc":[{"id":"1.168224423","rc":[{"trd":[[1.64,1353.65]],"batb":[[0,1.64,732.77]],"ltp":1.64,"tv":11489.21,"id":8260126}],"tv":13620.42}]}
{"op":"mcm","clk":"1008547881","pt":1580636892247,"mc":[{"id":"1.168224423","rc":[{"batb":[[0,1.65,50.62],[1,1.64,732.77],[2,1.63,2.05]],"batl":[[0,1.69,42.01],[1,1.7,23.85],[2,2.36,299.17]],"ltp":1.64,"tv":11489.21,"id":8260126},{"batb":[[0,2.46,28.57],[1,2.42,4.63],[2,2.4,66.88]],"batl":[[0,2.78,23.53],[1,2.8,7.47],[2,2.82,7.75]],"ltp":2.6,"tv":2131.2,"id":4486603}]}]}
{"op":"mcm","clk":"1008547944","pt":1580636893431,"mc":[{"id":"1.168224423","rc":[{"trd":[[1.65,346.24]],"batb":[[0,1.65,38.32]],"batl":[[0,1.7,23.85],[1,2.36,299.17],[2,2.46,4.75]],"ltp":1.65,"tv":11513.81,"id":8260126},{"batb":[[0,2.42,4.63],[1,2.4,66.88],[2,1.8,75.72]],"batl":[[0,2.8,7.47],[1,2.82,7.75],[2,2.9,7.15]],"ltp":2.6,"tv":2131.2,"id":4486603}],"tv":13645.02}]}
{"op":"mcm","clk":"1008548023","pt":1580636894819,"mc":[{"id":"1.168224423","rc":[{"batl":[[0,1.7,304.39],[1,1.72,310.65],[2,2.36,299.17]],"ltp":1.65,"tv":11513.81,"id":8260126}]}]}
{"op":"mcm","clk":"1008548213","pt":1580636898070,"mc":[{"id":"1.168224423","rc":[{"batl":[[0,1.7,23.85],[1,2.36,299.17],[2,2.46,4.75]],"ltp":1.65,"tv":11513.81,"id":8260126}]}]}
{"op":"mcm","clk":"1008548366","pt":1580636901049,"mc":[{"id":"1.168224423","rc":[{"trd":[[1.7,17.18]],"batb":[[0,1.66,40.78],[1,1.65,38.32],[2,1.64,1214.03]],"batl":[[0,1.7,295.8],[1,1.72,860.65],[2,2.36,299.17]],"ltp":1.7,"tv":11530.99,"id":8260126},{"batb":[[2,2.36,466.34]],"batl":[[0,2.52,9.01],[1,2.56,483.62],[2,2.6,411]],"ltp":2.6,"tv":2131.2,"id":4486603}],"tv":13662.2}]}
{"op":"mcm","clk":"1008548413","pt":1580636901870,"mc":[{"id":"1.168224423","rc":[{"batb":[[1,1.65,149.65]],"batl":[[2,1.73,42.01]],"ltp":1.7,"tv":11530.99,"id":8260126},{"batb":[[2,2.36,496.59]],"ltp":2.6,"tv":2131.2,"id":4486603}]}]}
{"op":"mcm","clk":"1008548496","pt":1580636903974,"mc":[{"id":"1.168224423","rc":[{"trd":[[1.7,34.36]],"batl":[[0,1.7,287.21]],"ltp":1.7,"tv":11548.17,"id":8260126}],"tv":13679.38}]}
{"op":"mcm","clk":"1008548548","pt":1580636904853,"mc":[{"id":"1.168224423","rc":[{"trd":[[1.7,37.88]],"batl":[[0,1.7,285.45]],"ltp":1.7,"tv":11551.7,"id":8260126}],"tv":13682.9}]}
{"op":"mcm","clk":"1008548658","pt":1580636906955,"mc":[{"id":"1.168224423","rc":[{"batl":[[0,1.7,294.04],[1,1.71,26.5],[2,1.72,887.31]],"ltp":1.7,"tv":11551.7,"id":8260126},{"batb":[[1,2.4,70.79],[2,2.38,4.96]],"batl":[[0,2.5,10.72],[1,2.52,9.01],[2,2.56,483.62]],"ltp":2.6,"tv":2131.2,"id":4486603}]}]}
{"op":"mcm","clk":"1008548729","pt":1580636908445,"mc":[{"id":"1.168224423","rc":[{"batl":[[1,1.71,72.5]],"ltp":1.7,"tv":11551.7,"id":8260126}]}]}
{"op":"mcm","clk":"1008548867","pt":1580636910853,"mc":[{"id":"1.168224423","rc":[{"batl":[[0,1.7,285.45]],"ltp":1.7,"tv":11551.7,"id":8260126},{"batl":[[0,2.52,9.01],[1,2.56,483.62],[2,2.6,421.46]],"ltp":2.6,"tv":2131.2,"id":4486603}]}]}
{"op":"mcm","clk":"1008548961","pt":1580636912655,"mc":[{"id":"1.168224423","rc":[{"trd":[[1.66,159.63]],"batb":[[0,1.66,39.54]],"ltp":1.66,"tv":11554.18,"id":8260126}],"tv":13685.38}]}
{"op":"mcm","clk":"1008549060","pt":1580636914356,"mc":[{"id":"1.168224423","rc":[{"batb":[[0,1.65,38.32],[1,1.64,732.77],[2,1.63,546.31]],"batl":[[0,1.71,46],[1,1.72,26.66],[2,1.73,42.01]],"ltp":1.66,"tv":11554.18,"id":8260126},{"batb":[[0,2.38,4.96],[1,2.36,30.25],[2,2.32,73.72]],"batl":[[0,2.6,10.46],[1,2.64,10.18],[2,2.66,25.21]],"ltp":2.6,"tv":2131.2,"id":4486603}]}]}
{"op":"mcm","clk":"1008549102","pt":1580636914971,"mc":[{"id":"1.168224423","rc":[{"batl":[[2,1.74,480.59]],"ltp":1.66,"tv":11554.18,"id":8260126},{"batb":[[1,2.32,73.72],[2,1.8,75.72]],"batl":[[2,2.8,7.47]],"ltp":2.6,"tv":2131.2,"id":4486603}]}]}
{"op":"mcm","clk":"1008549245","pt":1580636917086,"mc":[{"id":"1.168224423","rc":[{"batl":[[2,1.74,743.29]],"ltp":1.66,"tv":11554.18,"id":8260126}]}]}
{"op":"mcm","clk":"1008549428","pt":1580636920378,"mc":[{"id":"1.168224423","rc":[{"batl":[[2,1.74,480.59]],"ltp":1.66,"tv":11554.18,"id":8260126}]}]}
{"op":"mcm","clk":"1008549581","pt":1580636923362,"mc":[{"id":"1.168224423","rc":[{"batb":[[2,1.63,846.12]],"batl":[[0,1.68,189.58],[1,1.7,323.65],[2,1.71,46]],"ltp":1.66,"tv":11554.18,"id":8260126}]}]}
{"op":"mcm","clk":"1008549646","pt":1580636924384,"mc":[{"id":"1.168224423","rc":[{"batb":[[2,1.63,546.31]],"batl":[[0,1.71,46],[1,1.72,26.66],[2,1.74,480.59]],"ltp":1.66,"tv":11554.18,"id":8260126}]}]}
{"op":"mcm","clk":"1008549807","pt":1580636927793,"mc":[{"id":"1.168224423","rc":[{"batl":[[2,1.74,743.29]],"ltp":1.66,"tv":11554.18,"id":8260126}]}]}
{"op":"mcm","clk":"1008549881","pt":1580636929189,"mc":[{"id":"1.168224423","rc":[{"batb":[[0,1.68,16.61],[1,1.65,38.32],[2,1.64,732.77]],"ltp":1.66,"tv":11554.18,"id":8260126},{"batb":[[2,1.7,75.72]],"ltp":2.6,"tv":2131.2,"id":4486603}]}]}
{"op":"mcm","clk":"1008549947","pt":1580636930371,"mc":[{"id":"1.168224423","rc":[{"batl":[[2,1.74,480.59]],"ltp":1.66,"tv":11554.18,"id":8260126}]}]}
{"op":"mcm","clk":"1008549986","pt":1580636931093,"mc":[{"id":"1.168224423","rc":[{"batl":[[0,2.64,10.18],[1,2.8,7.47],[2,2.82,7.75]],"ltp":2.6,"tv":2131.2,"id":4486603}]}]}
{"op":"mcm","clk":"1008550130","pt":1580636933412,"mc":[{"id":"1.168224423","rc":[{"trd":[[1.63,1603.9],[1.64,2819.16],[1.65,422.87],[1.68,193.86]],"batb":[[0,1.61,66.96],[1,1.58,293.16],[2,1.57,348.08]],"batl":[[0,1.62,18.2],[1,1.63,283.51],[2,1.64,1471.13]],"ltp":1.63,"tv":13117.04,"id":8260126},{"trd":[[2.48,12.59]],"batb":[[0,2.5,84.34],[1,2.38,4.96],[2,2.32,73.72]],"batl":[[1,2.72,9.26],[2,2.8,311.47]],"ltp":2.48,"tv":2142.45,"id":4486603}],"tv":15259.49}]}
{"op":"mcm","clk":"1008550179","pt":1580636934187,"mc":[{"id":"1.168224423","rc":[{"batb":[[0,2.6,54.37],[1,2.5,84.34],[2,2.46,63.5]],"ltp":2.48,"tv":2142.45,"id":4486603}]}]}
{"op":"mcm","clk":"1008550366","pt":1580636937324,"mc":[{"id":"1.168224423","rc":[{"batb":[[1,2.5,112.07]],"ltp":2.48,"tv":2142.45,"id":4486603}]}]}
{"op":"mcm","clk":"1008550538","pt":1580636940416,"mc":[{"id":"1.168224423","rc":[{"batb":[[1,1.58,787.19]],"ltp":1.63,"tv":13117.04,"id":8260126},{"batb":[[2,2.46,67.88]],"ltp":2.48,"tv":2142.45,"id":4486603}]}]}
{"op":"mcm","clk":"1008550989","pt":1580636947406,"mc":[{"id":"1.168224423","rc":[{"batb":[[0,1.61,16.87]],"batl":[[0,1.63,283.51],[1,1.64,181.64],[2,1.66,568.6]],"ltp":1.63,"tv":13117.04,"id":8260126},{"batb":[[1,2.5,27.73]],"batl":[[0,2.84,22.69],[1,2.96,2.53],[2,2.98,9.25]],"ltp":2.48,"tv":2142.45,"id":4486603}]}]}
{"op":"mcm","clk":"1008550995","pt":1580636947507,"mc":[{"id":"1.168224423","rc":[{"batb":[[1,1.58,494.03],[2,1.56,510.84]],"batl":[[0,1.66,568.6],[1,1.68,523.04],[2,1.7,24.55]],"ltp":1.63,"tv":13117.04,"id":8260126},{"batb":[[0,2.5,27.73],[1,2.46,67.88],[2,2.42,4.13]],"ltp":2.48,"tv":2142.45,"id":4486603}]}]}
{"op":"mcm","clk":"1008551078","pt":1580636948903,"mc":[{"id":"1.168224423","rc":[{"batl":[[0,1.66,526.59]],"ltp":1.63,"tv":13117.04,"id":8260126},{"batb":[[0,2.46,67.88],[1,2.42,4.13],[2,2.38,4.96]],"batl":[[0,2.96,2.53],[1,2.98,9.25],[2,3,52.14]],"ltp":2.48,"tv":2142.45,"id":4486603}]}]}
{"op":"mcm","clk":"1008551173","pt":1580636950407,"mc":[{"id":"1.168224423","rc":[{"batl":[[2,1.69,302.71]],"ltp":1.63,"tv":13117.04,"id":8260126}]}]}
{"op":"mcm","clk":"1008551358","pt":1580636953808,"mc":[{"id":"1.168224423","rc":[{"batl":[[0,1.66,46],[1,1.69,302.71],[2,1.7,24.55]],"ltp":1.63,"tv":13117.04,"id":8260126},{"batb":[[0,2.46,63.5]],"ltp":2.48,"tv":2142.45,"id":4486603}]}]}
{"op":"mcm","clk":"1008551400","pt":1580636954634,"mc":[{"id":"1.168224423","rc":[{"batl":[[0,1.69,302.71],[1,1.7,24.55],[2,1.71,316.59]],"ltp":1.63,"tv":13117.04,"id":8260126}]}]}
{"op":"mcm","clk":"1008551527","pt":1580636956339,"mc":[{"id":"1.168224423","rc":[{"batb":[[0,1.65,52.53],[1,1.64,1371.95],[2,1.63,352.59]],"batl":[[0,1.68,15.39],[1,1.69,1634.07],[2,1.7,1137.12]],"ltp":1.63,"tv":13117.04,"id":8260126},{"batl":[[0,2.54,11.75],[1,2.56,9.46],[2,2.64,352]],"ltp":2.48,"tv":2142.45,"id":4486603}]}]}
{"op":"mcm","clk":"1008551575","pt":1580636957118,"mc":[{"id":"1.168224423","rc":[{"batb":[[2,1.63,469.2]],"ltp":1.63,"tv":13117.04,"id":8260126}]}]}
{"op":"mcm","clk":"1008551614","pt":1580636957952,"mc":[{"id":"1.168224423","rc":[{"batb":[[2,2.4,29.41]],"ltp":2.48,"tv":2142.45,"id":4486603}]}]}
{"op":"mcm","clk":"1008551931","pt":1580636963221,"mc":[{"id":"1.168224423","rc":[{"batl":[[0,1.68,61.39]],"ltp":1.63,"tv":13117.04,"id":8260126},{"batb":[[2,2.4,33.87]],"batl":[[2,2.64,362.43]],"ltp":2.48,"tv":2142.45,"id":4486603}]}]}
{"op":"mcm","clk":"1008552368","pt":1580636969171,"mc":[{"id":"1.168224423","rc":[{"batl":[[0,1.68,46],[2,1.7,24.55]],"ltp":1.63,"tv":13117.04,"id":8260126},{"batl":[[1,2.64,10.43],[2,2.7,10.05]],"ltp":2.48,"tv":2142.45,"id":4486603}]}]}
{"op":"mcm","clk":"1008552425","pt":1580636970046,"mc":[{"id":"1.168224423","rc":[{"batb":[[0,1.62,494.03],[1,1.61,67.96],[2,1.6,510.84]],"batl":[[1,1.71,88.01],[2,1.72,507.25]],"ltp":1.63,"tv":13117.04,"id":8260126},{"batb":[[0,2.4,29.41],[1,2.38,4.96],[2,2.36,4.43]],"batl":[[0,2.64,10.43],[1,2.7,10.05],[2,2.72,24.37]],"ltp":2.48,"tv":2142.45,"id":4486603}]}]}
{"op":"mcm","clk":"1008552482","pt":1580636970977,"mc":[{"id":"1.168224423","rc":[{"batl":[[1,1.71,46]],"ltp":1.63,"tv":13117.04,"id":8260126},{"batb":[[0,2.38,4.96],[1,2.36,4.43],[2,2.34,71.44]],"batl":[[2,2.96,2.53]],"ltp":2.48,"tv":2142.45,"id":4486603}]}]}
{"op":"mcm","clk":"1008552630","pt":1580636973455,"mc":[{"id":"1.168224423","rc":[{"batl":[[2,1.73,201.19]],"ltp":1.63,"tv":13117.04,"id":8260126},{"batb":[[0,2.36,4.43],[1,2.34,71.44],[2,1.8,75.72]],"ltp":2.48,"tv":2142.45,"id":4486603}]}]}
{"op":"mcm","clk":"1008552640","pt":1580636973566,"mc":[{"id":"1.168224423","rc":[{"batl":[[0,1.73,201.19],[1,1.75,293.94],[2,2.22,329.01]],"ltp":1.63,"tv":13117.04,"id":8260126}]}]}
{"op":"mcm","clk":"1008552856","pt":1580636976355,"mc":[{"id":"1.168224423","rc":[{"batb":[[0,1.7,8.64],[1,1.69,227.1],[2,1.68,338.87]],"batl":[[1,1.75,779.94],[2,1.77,42.01]],"ltp":1.63,"tv":13117.04,"id":8260126},{"batb":[[0,2.36,15.83],[2,2.32,428.09]],"batl":[[0,2.46,11.75],[1,2.5,533.22],[2,2.52,365]],"ltp":2.48,"tv":2142.45,"id":4486603}]}]}
{"op":"mcm","clk":"1008553160","pt":1580636981143,"mc":[{"id":"1.168224423","rc":[{"batl":[[1,1.74,46],[2,1.75,779.94]],"ltp":1.63,"tv":13117.04,"id":8260126}]}]}
{"op":"mcm","clk":"1008553236","pt":1580636982395,"mc":[{"id":"1.168224423","rc":[{"batl":[[2,1.75,825.94]],"ltp":1.63,"tv":13117.04,"id":8260126}]}]}
{"op":"mcm","clk":"1008553271","pt":1580636983063,"mc":[{"id":"1.168224423","rc":[{"batl":[[1,1.74,70.25]],"ltp":1.63,"tv":13117.04,"id":8260126},{"batb":[[1,2.34,76.16]],"batl":[[1,2.5,544.19]],"ltp":2.48,"tv":2142.45,"id":4486603}]}]}
{"op":"mcm","clk":"1008553440","pt":1580636985455,"mc":[{"id":"1.168224423","rc":[{"batb":[[0,1.69,51.21],[1,1.67,543.5],[2,1.65,560.37]],"batl":[[0,1.74,70.25],[1,1.75,46],[2,1.77,522.6]],"ltp":1.63,"tv":13117.04,"id":8260126},{"batb":[[0,2.34,4.72],[1,2.3,31.93],[2,2.28,78.13]],"batl":[[1,2.5,10.97],[2,2.54,10.75]],"ltp":2.48,"tv":2142.45,"id":4486603}]}]}
{"op":"mcm","clk":"1008553535","pt":1580636986955,"mc":[{"id":"1.168224423","rc":[{"batl":[[2,1.77,480.59]],"ltp":1.63,"tv":13117.04,"id":8260126},{"batb":[[1,2.28,78.13],[2,1.7,75.72]],"ltp":2.48,"tv":2142.45,"id":4486603}]}]}
{"op":"mcm","clk":"1008553629","pt":1580636988300,"mc":[{"id":"1.168224423","rc":[{"batb":[[2,1.66,125]],"batl":[[0,1.73,23.5],[1,1.74,70.25],[2,1.75,46]],"ltp":1.63,"tv":13117.04,"id":8260126},{"batb":[[0,2.36,4.43],[1,2.34,4.72],[2,2.28,78.13]],"ltp":2.48,"tv":2142.45,"id":4486603}]}]}
{"op":"mcm","clk":"1008553671","pt":1580636988867,"mc":[{"id":"1.168224423","rc":[{"batb":[[0,1.67,543.5],[1,1.66,125],[2,1.65,560.37]],"batl":[[0,1.74,70.25],[1,1.75,46],[2,1.76,201.9]],"ltp":1.63,"tv":13117.04,"id":8260126},{"batb":[[0,2.34,4.72],[1,2.28,78.13],[2,1.7,75.72]],"batl":[[0,2.5,10.97],[1,2.54,10.75],[2,2.64,10.43]],"ltp":2.48,"tv":2142.45,"id":4486603}]}]}
{"op":"mcm","clk":"1008554288","pt":1580636998277,"mc":[{"id":"1.168224423","rc":[{"batl":[[0,1.73,24.87],[1,1.74,70.25],[2,1.75,46]],"ltp":1.63,"tv":13117.04,"id":8260126},{"batb":[[0,2.36,4.43],[1,2.34,4.72],[2,2.28,78.13]],"ltp":2.48,"tv":2142.45,"id":4486603}]}]}
{"op":"mcm","clk":"1008554306","pt":1580636998588,"mc":[{"id":"1.168224423","rc":[{"batl":[[0,1.74,70.25],[1,1.75,46],[2,1.76,201.9]],"ltp":1.63,"tv":13117.04,"id":8260126},{"batb":[[0,2.34,4.72],[1,2.28,78.13],[2,1.7,75.72]],"ltp":2.48,"tv":2142.45,"id":4486603}]}]}
{"op":"mcm","clk":"1008554696","pt":1580637004317,"mc":[{"id":"1.168224423","rc":[{"batl":[[0,1.74,24.25],[1,1.76,201.9],[2,1.78,278.03]],"ltp":1.63,"tv":13117.04,"id":8260126},{"batl":[[2,2.96,2.53]],"ltp":2.48,"tv":2142.45,"id":4486603}]}]}
{"op":"mcm","clk":"1008554846","pt":1580637006431,"mc":[{"id":"1.168224423","rc":[{"batb":[[0,1.71,221.19],[1,1.69,327.01],[2,1.67,543.5]],"batl":[[2,1.78,296.63]],"ltp":1.63,"tv":13117.04,"id":8260126},{"batl":[[0,2.36,7.08],[1,2.4,396.03],[2,2.42,11.75]],"ltp":2.48,"tv":2142.45,"id":4486603}]}]}
{"op":"mcm","clk":"1008554909","pt":1580637007313,"mc":[{"id":"1.168224423","rc":[{"batb":[[0,1.72,97.09],[1,1.71,221.19],[2,1.69,327.01]],"ltp":1.63,"tv":13117.04,"id":8260126},{"batb":[[2,2.1,97.8]],"ltp":2.48,"tv":2142.45,"id":4486603}]}]}
{"op":"mcm","clk":"1008554963","pt":1580637007926,"mc":[{"id":"1.168224423","rc":[{"batb":[[2,2.2,34.45]],"ltp":2.48,"tv":2142.45,"id":4486603}]}]}
{"op":"mcm","clk":"1008555803","pt":1580637019148,"mc":[{"id":"1.168224423","rc":[{"trd":[[1.74,1739.16]],"batl":[[0,1.74,12.29]],"ltp":1.74,"tv":13140.96,"id":8260126},{"batb":[[1,2.28,77.9]],"ltp":2.48,"tv":2142.45,"id":4486603}],"tv":15283.41}]}
{"op":"mcm","clk":"1008556218","pt":1580637025142,"mc":[{"id":"1.168224423","rc":[{"trd":[[1.73,6.42]],"ltp":1.73,"tv":13146.93,"id":8260126},{"trd":[[2.36,9.75]],"batl":[[0,2.36,2.7]],"ltp":2.36,"tv":2146.83,"id":4486603}],"tv":15293.76}]}
{"op":"mcm","clk":"1008556264","pt":1580637025821,"mc":[{"id":"1.168224423","rc":[{"trd":[[1.73,10.1]],"batl":[[0,1.73,97.32],[1,1.74,12.29],[2,1.76,201.9]],"ltp":1.73,"tv":13150.61,"id":8260126},{"trd":[[2.36,12.45]],"batl":[[0,2.4,396.03],[1,2.42,11.75],[2,2.44,327]],"ltp":2.36,"tv":2149.53,"id":4486603}],"tv":15300.14}]}
{"op":"mcm","clk":"1008557174","pt":1580637041326,"mc":[{"id":"1.168224423","rc":[{"batb":[[0,1.72,107.46]],"ltp":1.73,"tv":13150.61,"id":8260126},{"batb":[[1,2.32,10.87],[2,2.28,77.9]],"ltp":2.36,"tv":2149.53,"id":4486603}]}]}
{"op":"mcm","clk":"1008558146","pt":1580637056161,"mc":[{"id":"1.168224423","rc":[{"batb":[[2,1.7,63]],"ltp":1.73,"tv":13150.61,"id":8260126}]}]}
{"op":"mcm","clk":"1008560058","pt":1580637089422,"mc":[{"id":"1.168224423","rc":[{"trd":[[1.73,34.09]],"batl":[[0,1.73,73.33]],"ltp":1.73,"tv":13174.6,"id":8260126},{"trd":[[2.36,30.03]],"ltp":2.36,"tv":2167.1,"id":4486603}],"tv":15341.7}]}
{"op":"mcm","clk":"1008560291","pt":1580637093112,"mc":[{"id":"1.168224423","rc":[{"batl":[[2,2.46,112.71]],"ltp":2.36,"tv":2167.1,"id":4486603}]}]}
{"op":"mcm","clk":"1008560472","pt":1580637096345,"mc":[{"id":"1.168224423","rc":[{"batb":[[0,1.7,63],[1,1.68,117.94],[2,1.67,49.47]],"batl":[[1,1.83,42.01],[2,2.22,329.01]],"ltp":1.73,"tv":13174.6,"id":8260126},{"batb":[[0,2.2,34.45],[1,2.1,97.57],[2,1.75,21.07]],"batl":[[0,2.46,28.57],[1,2.48,12.74],[2,2.5,10.97]],"ltp":2.36,"tv":2167.1,"id":4486603}]}]}
{"op":"mcm","clk":"1008560517","pt":1580637097062,"mc":[{"id":"1.168224423","rc":[{"batb":[[1,1.66,165.91],[2,1.61,16.87]],"batl":[[1,2.22,329.01],[2,2.34,4.25]],"ltp":1.73,"tv":13174.6,"id":8260126},{"batb":[[0,2.1,97.57],[1,1.75,21.07],[2,1.7,75.72]],"batl":[[0,2.52,12.51],[1,2.96,2.53],[2,3,52.14]],"ltp":2.36,"tv":2167.1,"id":4486603}]}]}
{"op":"mcm","clk":"1008560635","pt":1580637098860,"mc":[{"id":"1.168224423","rc":[{"batb":[[1,1.66,392.21],[2,1.65,178.98]],"batl":[[1,1.87,187.83],[2,1.89,230.29]],"ltp":1.73,"tv":13174.6,"id":8260126}]}]}
{"op":"mcm","clk":"1008560750","pt":1580637100566,"mc":[{"id":"1.168224423","rc":[{"trd":[[1.73,180.74]],"batl":[[0,1.87,187.84],[1,1.89,230.29],[2,2.22,329.01]],"ltp":1.73,"tv":13321.24,"id":8260126}],"tv":15488.35}]}
{"op":"mcm","clk":"1008561135","pt":1580637106374,"mc":[{"id":"1.168224423","rc":[{"batb":[[1,1.68,56.61],[2,1.66,392.21]],"ltp":1.73,"tv":13321.24,"id":8260126},{"batl":[[0,2.48,12.74],[1,2.52,12.51],[2,2.96,2.53]],"ltp":2.36,"tv":2167.1,"id":4486603}]}]}
{"op":"mcm","clk":"1008561144","pt":1580637106536,"mc":[{"id":"1.168224423","rc":[{"batb":[[1,1.66,392.21],[2,1.65,178.98]],"ltp":1.73,"tv":13321.24,"id":8260126},{"batl":[[0,2.52,12.51],[1,2.96,2.53],[2,3,52.14]],"ltp":2.36,"tv":2167.1,"id":4486603}]}]}
{"op":"mcm","clk":"1008561239","pt":1580637108272,"mc":[{"id":"1.168224423","rc":[{"batb":[[1,1.67,63],[2,1.66,392.21]],"ltp":1.73,"tv":13321.24,"id":8260126}]}]}
{"op":"mcm","clk":"1008561454","pt":1580637112084,"mc":[{"id":"1.168224423","rc":[{"batl":[[0,2.22,329.02],[1,2.34,4.25],[2,2.54,3.75]],"ltp":1.73,"tv":13321.24,"id":8260126}]}]}
{"op":"mcm","clk":"1008561534","pt":1580637113266,"mc":[{"id":"1.168224423","rc":[{"batb":[[0,1.68,56.61],[1,1.66,392.21],[2,1.65,178.98]],"ltp":1.73,"tv":13321.24,"id":8260126},{"batl":[[0,2.48,12.74],[1,2.52,12.51],[2,2.96,2.53]],"ltp":2.36,"tv":2167.1,"id":4486603}]}]}
{"op":"mcm","clk":"1008561574","pt":1580637113883,"mc":[{"id":"1.168224423","rc":[{"batb":[[0,1.66,392.21],[1,1.65,178.98],[2,1.61,16.87]],"ltp":1.73,"tv":13321.24,"id":8260126},{"batl":[[0,2.52,12.51],[1,2.96,2.53],[2,3,52.14]],"ltp":2.36,"tv":2167.1,"id":4486603}]}]}
{"op":"mcm","clk":"1008561662","pt":1580637115374,"mc":[{"id":"1.168224423","rc":[{"batl":[[0,1.7,13.64],[1,1.71,214.43],[2,1.73,880.38]],"ltp":1.73,"tv":13321.24,"id":8260126},{"batb":[[0,2.36,368.29],[1,2.34,85.64],[2,2.1,97.57]],"batl":[[0,2.5,7.29],[1,2.52,12.51],[2,2.56,952.23]],"ltp":2.36,"tv":2167.1,"id":4486603}]}]}
{"op":"mcm","clk":"1008561696","pt":1580637116045,"mc":[{"id":"1.168224423","rc":[{"batb":[[2,1.64,65.54]],"ltp":1.73,"tv":13321.24,"id":8260126},{"batb":[[0,2.38,68.3],[1,2.36,368.29],[2,2.34,85.64]],"batl":[[2,2.56,979.12]],"ltp":2.36,"tv":2167.1,"id":4486603}]}]}
{"op":"mcm","clk":"1008561998","pt":1580637121390,"mc":[{"id":"1.168224423","rc":[{"batb":[[0,1.66,455.21]],"batl":[[2,1.73,1360.97]],"ltp":1.73,"tv":13321.24,"id":8260126}]}]}
{"op":"mcm","clk":"1008562076","pt":1580637122577,"mc":[{"id":"1.168224423","rc":[{"batb":[[1,1.65,236.91],[2,1.64,123.61]],"ltp":1.73,"tv":13321.24,"id":8260126},{"batb":[[2,2.34,90.36]],"batl":[[2,2.54,12.75]],"ltp":2.36,"tv":2167.1,"id":4486603}]}]}
{"op":"mcm","clk":"1008562627","pt":1580637131402,"mc":[{"id":"1.168224423","rc":[{"batl":[[2,1.73,896.97]],"ltp":1.73,"tv":13321.24,"id":8260126}]}]}
{"op":"mcm","clk":"1008562687","pt":1580637132212,"mc":[{"id":"1.168224423","rc":[{"batb":[[0,1.66,63],[1,1.64,123.61],[2,1.63,63]],"batl":[[0,1.73,480.6],[1,1.74,24.75],[2,1.75,497.4]],"ltp":1.73,"tv":13321.24,"id":8260126},{"batb":[[0,2.34,4.72],[1,2.3,36.61],[2,2.22,83.56]],"batl":[[0,2.42,1.78],[1,2.56,26.89],[2,2.58,12.25]],"ltp":2.36,"tv":2167.1,"id":4486603}]}]}
{"op":"mcm","clk":"1008562760","pt":1580637133063,"mc":[{"id":"1.168224423","rc":[{"batb":[[1,1.64,58.07]],"ltp":1.73,"tv":13321.24,"id":8260126},{"batb":[[1,2.3,4.68]],"batl":[[1,2.58,12.25],[2,2.96,2.53]],"ltp":2.36,"tv":2167.1,"id":4486603}]}]}
{"op":"mcm","clk":"1008562918","pt":1580637135392,"mc":[{"id":"1.168224423","rc":[{"batb":[[1,1.65,57.93],[2,1.64,58.07]],"ltp":1.73,"tv":13321.24,"id":8260126},{"batl":[[1,2.54,12.75],[2,2.58,12.25]],"ltp":2.36,"tv":2167.1,"id":4486603}]}]}
{"op":"mcm","clk":"1008562936","pt":1580637135694,"mc":[{"id":"1.168224423","rc":[{"batb":[[1,1.64,58.07],[2,1.63,63]],"ltp":1.73,"tv":13321.24,"id":8260126},{"batl":[[1,2.58,12.25],[2,2.96,2.53]],"ltp":2.36,"tv":2167.1,"id":4486603}]}]}
{"op":"mcm","clk":"1008563114","pt":1580637138384,"mc":[{"id":"1.168224423","rc":[{"batb":[[0,1.64,58.07],[1,1.62,447.06],[2,1.61,212.8]],"batl":[[0,1.72,75],[1,1.73,480.6],[2,1.74,24.75]],"ltp":1.73,"tv":13321.24,"id":8260126}]}]}
{"op":"mcm","clk":"1008563274","pt":1580637140388,"mc":[{"id":"1.168224423","rc":[{"trd":[[1.7,40.42]],"batl":[[0,1.66,16.29],[1,1.67,179.43],[2,1.69,848.76]],"ltp":1.7,"tv":13323.78,"id":8260126},{"trd":[[2.42,1.78]],"batb":[[0,2.48,61.84],[1,2.46,73.93],[2,2.42,77.26]],"batl":[[0,2.58,12.25],[1,2.6,7.42],[2,2.66,958.81]],"ltp":2.42,"tv":2168.88,"id":4486603}],"tv":15492.67}]}
{"op":"mcm","clk":"1008563602","pt":1580637145385,"mc":[{"id":"1.168224423","rc":[{"batl":[[2,1.68,75]],"ltp":1.7,"tv":13323.78,"id":8260126}]}]}
{"op":"mcm","clk":"1008563721","pt":1580637147000,"mc":[{"id":"1.168224423","rc":[{"batb":[[1,1.63,59.23],[2,1.62,506.1]],"ltp":1.7,"tv":13323.78,"id":8260126},{"batb":[[2,2.44,4.67]],"batl":[[1,2.6,19.73],[2,2.62,12.25]],"ltp":2.42,"tv":2168.88,"id":4486603}]}]}
{"op":"mcm","clk":"1008563811","pt":1580637148185,"mc":[{"id":"1.168224423","rc":[{"trd":[[1.66,192.19]],"batl":[[0,1.67,179.44],[1,1.68,75],[2,1.69,1355.85]],"ltp":1.66,"tv":13356.34,"id":8260126}],"tv":15525.23}]}
{"op":"mcm","clk":"1008563884","pt":1580637149220,"mc":[{"id":"1.168224423","rc":[{"batb":[[0,1.66,307.08],[1,1.62,59.04],[2,1.61,16.87]],"batl":[[0,1.68,75],[1,1.69,507.09],[2,1.7,75]],"ltp":1.66,"tv":13356.34,"id":8260126},{"batb":[[0,2.44,4.67],[1,2.4,4.66],[2,2.34,77.82]],"batl":[[0,2.62,12.25],[1,2.96,2.53],[2,3,52.14]],"ltp":2.42,"tv":2168.88,"id":4486603}]}]}
{"op":"mcm","clk":"1008564051","pt":1580637152021,"mc":[{"id":"1.168224423","rc":[{"batb":[[0,1.66,407.08],[1,1.63,59.23],[2,1.62,59.04]],"ltp":1.66,"tv":13356.34,"id":8260126},{"batl":[[0,2.6,12.26],[1,2.62,12.25],[2,2.96,2.53]],"ltp":2.42,"tv":2168.88,"id":4486603}]}]}
{"op":"mcm","clk":"1008564238","pt":1580637154912,"mc":[{"id":"1.168224423","rc":[{"batb":[[0,1.66,100]],"ltp":1.66,"tv":13356.34,"id":8260126}]}]}
{"op":"mcm","clk":"1008564373","pt":1580637157435,"mc":[{"id":"1.168224423","rc":[{"trd":[[1.66,392.19]],"batb":[[0,1.63,59.23],[1,1.62,59.04],[2,1.61,91.87]],"batl":[[0,1.64,9.29],[1,1.65,256.13],[2,1.66,650.34]],"ltp":1.66,"tv":13556.34,"id":8260126},{"batl":[[2,2.66,13.62]],"ltp":2.42,"tv":2168.88,"id":4486603}],"tv":15725.23}]}
{"op":"mcm","clk":"1008564427","pt":1580637158315,"mc":[{"id":"1.168224423","rc":[{"batb":[[2,1.61,16.87]],"batl":[[0,1.65,256.13],[1,1.66,650.34],[2,1.67,343.43]],"ltp":1.66,"tv":13556.34,"id":8260126},{"batb":[[0,2.54,57.36],[1,2.44,33.24],[2,2.42,65.62]],"batl":[[2,2.72,435.73]],"ltp":2.42,"tv":2168.88,"id":4486603}]}]}
{"op":"mcm","clk":"1008564551","pt":1580637160321,"mc":[{"id":"1.168224423","rc":[{"batl":[[1,1.66,725.34]],"ltp":1.66,"tv":13556.34,"id":8260126}]}]}
{"op":"mcm","clk":"1008564605","pt":1580637161088,"mc":[{"id":"1.168224423","rc":[{"trd":[[1.65,426.23]],"batl":[[0,1.64,9.29],[1,1.65,254.45],[2,1.66,725.34]],"ltp":1.65,"tv":13559.71,"id":8260126},{"batl":[[2,2.66,13.62]],"ltp":2.42,"tv":2168.88,"id":4486603}],"tv":15728.59}]}
{"op":"mcm","clk":"1008564801","pt":1580637164295,"mc":[{"id":"1.168224423","rc":[{"batl":[[2,1.66,752.09]],"ltp":1.65,"tv":13559.71,"id":8260126},{"batb":[[1,2.5,3.68],[2,2.48,4.26]],"ltp":2.42,"tv":2168.88,"id":4486603}]}]}
{"op":"mcm","clk":"1008565177","pt":1580637169613,"mc":[{"id":"1.168224423","rc":[{"trd":[[1.64,2821.24]],"batl":[[0,1.64,8.25]],"ltp":1.64,"tv":13561.79,"id":8260126}],"tv":15730.67}]}
{"op":"mcm","clk":"1008565360","pt":1580637172448,"mc":[{"id":"1.168224423","rc":[{"trd":[[1.64,2837.74],[1.65,982.46]],"batl":[[0,1.66,752.09],[1,1.67,25.5],[2,1.68,1245.83]],"ltp":1.65,"tv":14134.51,"id":8260126},{"trd":[[2.54,99.21]],"batb":[[0,2.54,26.62]],"ltp":2.54,"tv":2199.62,"id":4486603}],"tv":16334.14}]}
{"op":"mcm","clk":"1008565422","pt":1580637173442,"mc":[{"id":"1.168224423","rc":[{"batb":[[0,1.61,16.87],[1,1.59,585.03],[2,1.57,716.99]],"batl":[[0,1.66,75],[2,1.68,75]],"ltp":1.65,"tv":14134.51,"id":8260126},{"batb":[[0,2.48,4.26],[1,2.44,33.24],[2,2.42,65.62]],"batl":[[0,2.62,12.25],[1,2.74,23.53],[2,2.96,2.53]],"ltp":2.54,"tv":2199.62,"id":4486603}]}]}
{"op":"mcm","clk":"1008565566","pt":1580637175410,"mc":[{"id":"1.168224423","rc":[{"batb":[[0,1.61,245.17],[2,1.57,643.89]],"batl":[[0,1.66,363.25],[2,1.68,410.22]],"ltp":1.65,"tv":14134.51,"id":8260126},{"batb":[[1,2.44,4.67]],"batl":[[1,2.96,2.53],[2,3,53.23]],"ltp":2.54,"tv":2199.62,"id":4486603}]}]}
{"op":"mcm","clk":"1008565650","pt":1580637176338,"mc":[{"id":"1.168224423","rc":[{"batb":[[0,1.63,60.23],[1,1.62,59.54],[2,1.61,16.87]],"batl":[[0,1.66,101.25],[2,1.68,75]],"ltp":1.65,"tv":14134.51,"id":8260126},{"batb":[[0,2.5,4],[1,2.48,4.26],[2,2.44,4.67]],"batl":[[0,2.6,12.41],[1,2.62,12.25],[2,2.96,2.53]],"ltp":2.54,"tv":2199.62,"id":4486603}]}]}
{"op":"mcm","clk":"1008565699","pt":1580637177009,"mc":[{"id":"1.168224423","rc":[{"batb":[[0,1.62,59.54],[1,1.61,16.87],[2,1.59,585.03]],"batl":[[0,1.66,75]],"ltp":1.65,"tv":14134.51,"id":8260126},{"batb":[[0,2.48,4.26],[1,2.44,4.67],[2,2.42,65.62]],"batl":[[0,2.62,12.25],[1,2.96,2.53],[2,3,53.23]],"ltp":2.54,"tv":2199.62,"id":4486603}]}]}
{"op":"mcm","clk":"1008565834","pt":1580637179436,"mc":[{"id":"1.168224423","rc":[{"batb":[[0,1.63,10.23],[1,1.62,59.54],[2,1.61,16.87]],"batl":[[0,1.64,10.18],[1,1.66,75],[2,1.67,25.5]],"ltp":1.65,"tv":14134.51,"id":8260126},{"batb":[[0,2.56,10.33],[1,2.48,4.26],[2,2.44,4.67]],"batl":[[0,2.6,9.66],[1,2.62,12.25],[2,2.96,2.53]],"ltp":2.54,"tv":2199.62,"id":4486603}]}]}
{"op":"mcm","clk":"1008565909","pt":1580637180422,"mc":[{"id":"1.168224423","rc":[{"batb":[[0,1.62,59.54],[1,1.61,362.34],[2,1.6,199.96]],"batl":[[0,1.66,251.72],[1,1.67,25.5],[2,1.68,411.04]],"ltp":1.65,"tv":14134.51,"id":8260126},{"batb":[[0,2.48,4.26],[1,2.44,4.67],[2,2.42,65.62]],"batl":[[0,2.62,12.25],[1,2.96,2.53],[2,3,53.23]],"ltp":2.54,"tv":2199.62,"id":4486603}]}]}
{"op":"mcm","clk":"1008565952","pt":1580637181227,"mc":[{"id":"1.168224423","rc":[{"batb":[[1,1.61,16.87],[2,1.59,585.03]],"batl":[[0,1.66,75],[2,1.68,75]],"ltp":1.65,"tv":14134.51,"id":8260126}]}]}
{"op":"mcm","clk":"1008566158","pt":1580637184171,"mc":[{"id":"1.168224423","rc":[{"batb":[[2,1.59,943.4]],"ltp":1.65,"tv":14134.51,"id":8260126}]}]}
{"op":"mcm","clk":"1008566258","pt":1580637185668,"mc":[{"id":"1.168224423","rc":[{"batb":[[2,1.59,585.03]],"ltp":1.65,"tv":14134.51,"id":8260126}]}]}
{"op":"mcm","clk":"1008566334","pt":1580637186848,"mc":[{"id":"1.168224423","rc":[{"batl":[[0,1.67,25.5],[1,1.68,75],[2,1.69,261.12]],"ltp":1.65,"tv":14134.51,"id":8260126}]}]}
{"op":"mcm","clk":"1008566425","pt":1580637188348,"mc":[{"id":"1.168224423","rc":[{"trd":[[1.67,86.59]],"batb":[[0,1.64,293.43],[1,1.63,186.49],[2,1.62,321.61]],"batl":[[0,1.67,20.69]],"ltp":1.67,"tv":14139.32,"id":8260126},{"trd":[[2.48,24.35]],"batb":[[0,2.44,4.67],[1,2.42,65.62],[2,2.4,11.71]],"batl":[[0,2.56,349.86],[1,2.58,12.75],[2,2.6,313]],"ltp":2.48,"tv":2211.38,"id":4486603}],"tv":16350.71}]}
{"op":"mcm","clk":"1008566483","pt":1580637189174,"mc":[{"id":"1.168224423","rc":[{"batb":[[0,1.65,112.36],[1,1.64,293.43],[2,1.63,186.49]],"ltp":1.67,"tv":14139.32,"id":8260126}]}]}
{"op":"mcm","clk":"1008566699","pt":1580637192079,"mc":[{"id":"1.168224423","rc":[{"batl":[[2,1.69,234.62]],"ltp":1.67,"tv":14139.32,"id":8260126},{"batb":[[0,2.42,65.62],[1,2.4,11.71],[2,2.34,35.81]],"ltp":2.48,"tv":2211.38,"id":4486603}]}]}
{"op":"mcm","clk":"1008566783","pt":1580637193061,"mc":[{"id":"1.168224423","rc":[{"trd":[[1.67,127.96]],"batl":[[0,1.68,75],[1,1.69,234.62],[2,1.7,75]],"ltp":1.67,"tv":14180.7,"id":8260126}],"tv":16392.09}]}
{"op":"mcm","clk":"1008566938","pt":1580637195279,"mc":[{"id":"1.168224423","rc":[{"batb":[[2,1.63,252.72]],"batl":[[1,1.69,260.12],[2,1.7,578.24]],"ltp":1.67,"tv":14180.7,"id":8260126},{"batb":[[0,2.44,3.92],[1,2.42,70.25],[2,2.4,11.71]],"batl":[[2,2.6,326.66]],"ltp":2.48,"tv":2211.38,"id":4486603}]}]}
{"op":"mcm","clk":"1008567153","pt":1580637198277,"mc":[{"id":"1.168224423","rc":[{"batb":[[2,2.4,4.66]],"ltp":2.48,"tv":2211.38,"id":4486603}]}]}
{"op":"mcm","clk":"1008567239","pt":1580637199497,"mc":[{"id":"1.168224423","rc":[{"batb":[[1,1.64,250.46]],"ltp":1.67,"tv":14180.7,"id":8260126}]}]}
{"op":"mcm","clk":"1008567348","pt":1580637201380,"mc":[{"id":"1.168224423","rc":[{"trd":[[1.65,994.31],[1.66,405.91]],"batb":[[0,1.65,106.43]],"batl":[[2,1.7,589.13]],"ltp":1.65,"tv":14206.27,"id":8260126},{"trd":[[2.5,130.05]],"ltp":2.5,"tv":2220.49,"id":4486603}],"tv":16426.77}]}
{"op":"mcm","clk":"1008567407","pt":1580637202358,"mc":[{"id":"1.168224423","rc":[{"batl":[[1,1.69,301.93]],"ltp":1.65,"tv":14206.27,"id":8260126}]}]}
{"op":"mcm","clk":"1008567592","pt":1580637205257,"mc":[{"id":"1.168224423","rc":[{"batb":[[1,1.64,190.89]],"batl":[[2,1.7,578.24]],"ltp":1.65,"tv":14206.27,"id":8260126},{"batl":[[0,2.6,13.66],[1,2.62,37.46],[2,2.96,2.53]],"ltp":2.5,"tv":2220.49,"id":4486603}]}]}
{"op":"mcm","clk":"1008567632","pt":1580637205877,"mc":[{"id":"1.168224423","rc":[{"batb":[[0,1.63,66.23],[1,1.62,120.78],[2,1.61,578.96]],"batl":[[1,1.7,578.24],[2,1.71,23.5]],"ltp":1.65,"tv":14206.27,"id":8260126},{"batb":[[0,2.42,4.63],[1,2.4,4.66],[2,2.34,35.81]],"batl":[[1,2.62,25.21]],"ltp":2.5,"tv":2220.49,"id":4486603}]}]}
{"op":"mcm","clk":"1008567723","pt":1580637207165,"mc":[{"id":"1.168224423","rc":[{"batb":[[2,1.61,510.91]],"batl":[[0,1.65,150],[1,1.68,75],[2,1.7,578.24]],"ltp":1.65,"tv":14206.27,"id":8260126},{"batb":[[2,2.34,4.72]],"batl":[[1,2.96,2.53],[2,3,53.23]],"ltp":2.5,"tv":2220.49,"id":4486603}]}]}
{"op":"mcm","clk":"1008567914","pt":1580637209999,"mc":[{"id":"1.168224423","rc":[{"batl":[[1,1.7,578.24],[2,1.71,23.5]],"ltp":1.65,"tv":14206.27,"id":8260126}]}]}
{"op":"mcm","clk":"1008567983","pt":1580637211083,"mc":[{"id":"1.168224423","rc":[{"trd":[[1.65,1294.31]],"batb":[[0,1.65,26.78],[1,1.64,182.43],[2,1.63,66.23]],"batl":[[0,1.7,853.19],[1,1.71,23.5],[2,1.72,882.54]],"ltp":1.65,"tv":14506.27,"id":8260126}],"tv":16726.77}]}
{"op":"mcm","clk":"1008568034","pt":1580637212065,"mc":[{"id":"1.168224423","rc":[{"batb":[[0,1.64,182.43],[1,1.63,66.23],[2,1.62,120.78]],"batl":[[0,1.7,578.24],[2,1.72,572.4]],"ltp":1.65,"tv":14506.27,"id":8260126}]}]}
{"op":"mcm","clk":"1008568099","pt":1580637213407,"mc":[{"id":"1.168224423","rc":[{"batb":[[0,1.63,66.23],[1,1.62,120.78],[2,1.61,510.91]],"ltp":1.65,"tv":14506.27,"id":8260126}]}]}
{"op":"mcm","clk":"1008568198","pt":1580637215306,"mc":[{"id":"1.168224423","rc":[{"batb":[[0,1.64,77.57],[1,1.63,66.23],[2,1.62,120.78]],"ltp":1.65,"tv":14506.27,"id":8260126},{"batl":[[0,2.58,16.75],[1,2.6,13.66],[2,2.96,2.53]],"ltp":2.5,"tv":2220.49,"id":4486603}]}]}
{"op":"mcm","clk":"1008568261","pt":1580637216289,"mc":[{"id":"1.168224423","rc":[{"batb":[[0,1.63,66.23],[1,1.62,120.78],[2,1.61,774.91]],"ltp":1.65,"tv":14506.27,"id":8260126},{"batl":[[0,2.6,13.66],[1,2.96,2.53],[2,3,53.23]],"ltp":2.5,"tv":2220.49,"id":4486603}]}]}
{"op":"mcm","clk":"1008568528","pt":1580637220983,"mc":[{"id":"1.168224423","rc":[{"batb":[[2,1.61,280.87]],"ltp":1.65,"tv":14506.27,"id":8260126}]}]}
{"op":"mcm","clk":"1008568598","pt":1580637222216,"mc":[{"id":"1.168224423","rc":[{"batb":[[0,1.64,77.57],[1,1.63,66.23],[2,1.62,120.78]],"ltp":1.65,"tv":14506.27,"id":8260126},{"batl":[[0,2.58,16.75],[1,2.6,13.66],[2,2.96,2.53]],"ltp":2.5,"tv":2220.49,"id":4486603}]}]}
