{"op":"mcm","clk":"1004963113","pt":1580585272153,"mc":[{"id":"1.168224425","marketDefinition":{"bspMarket":false,"turnInPlayEnabled":true,"persistenceEnabled":true,"marketBaseRate":5.0,"eventId":"29681737","eventTypeId":"2","numberOfWinners":1,"bettingType":"ODDS","marketType":"SET_WINNER","marketTime":"2020-02-02T09:30:00.000Z","suspendTime":"2020-02-02T09:30:00.000Z","bspReconciled":false,"complete":true,"inPlay":false,"crossMatching":false,"runnersVoidable":false,"numberOfActiveRunners":2,"betDelay":0,"status":"OPEN","runners":[{"status":"ACTIVE","sortPriority":1,"id":8260126,"name":"Guillermo Garcia-Lopez"},{"status":"ACTIVE","sortPriority":2,"id":4486603,"name":"Dustin Brown"}],"regulators":["MR_INT"],"countryCode":"FR","discountAllowed":false,"timezone":"UTC","openDate":"2020-02-02T09:30:00.000Z","version":3147098435,"name":"Set 1 Winner","eventName":"Garcia-Lopez v Brown"},"rc":[{"batb":[[0,1.01,20]],"ltp":0.0,"tv":0.0,"id":8260126},{"batb":[[0,1.01,20]],"ltp":0.0,"tv":0.0,"id":4486603}]}]}
{"op":"mcm","clk":"1004963376","pt":1580585273491,"mc":[{"id":"1.168224425","marketDefinition":{"bspMarket":false,"turnInPlayEnabled":true,"persistenceEnabled":true,"marketBaseRate":5.0,"eventId":"29681737","eventTypeId":"2","numberOfWinners":1,"bettingType":"ODDS","marketType":"SET_WINNER","marketTime":"2020-02-02T09:30:00.000Z","suspendTime":"2020-02-02T09:30:00.000Z","bspReconciled":false,"complete":true,"inPlay":false,"crossMatching":false,"runnersVoidable":false,"numberOfActiveRunners":2,"betDelay":0,"status":"OPEN","runners":[{"status":"ACTIVE","sortPriority":1,"id":8260126,"name":"Guillermo Garcia-Lopez"},{"status":"ACTIVE","sortPriority":2,"id":4486603,"name":"Dustin Brown"}],"regulators":["MR_INT"],"countryCode":"FR","discountAllowed":false,"timezone":"UTC","openDate":"2020-02-02T09:30:00.000Z","version":3147098435,"name":"Set 1 Winner","eventName":"Garcia-Lopez v Brown"}}]}
{"op":"mcm","clk":"1004963561","pt":1580585274501,"mc":[{"id":"1.168224425","marketDefinition":{"bspMarket":false,"turnInPlayEnabled":true,"persistenceEnabled":true,"marketBaseRate":5.0,"eventId":"29681737","eventTypeId":"2","numberOfWinners":1,"bettingType":"ODDS","marketType":"SET_WINNER","marketTime":"2020-02-02T09:30:00.000Z","suspendTime":"2020-02-02T09:30:00.000Z","bspReconciled":false,"complete":true,"inPlay":false,"crossMatching":false,"runnersVoidable":false,"numberOfActiveRunners":2,"betDelay":0,"status":"OPEN","runners":[{"status":"ACTIVE","sortPriority":1,"id":8260126,"name":"Guillermo Garcia-Lopez"},{"status":"ACTIVE","sortPriority":2,"id":4486603,"name":"Dustin Brown"}],"regulators":["MR_INT"],"countryCode":"FR","discountAllowed":true,"timezone":"UTC","openDate":"2020-02-02T09:30:00.000Z","version":3147098435,"name":"Set 1 Winner","eventName":"Garcia-Lopez v Brown"}}]}
{"op":"mcm","clk":"1004986256","pt":1580585417713,"mc":[{"id":"1.168224425","rc":[{"batb":[[0,1.01,15]],"ltp":0.0,"tv":0.0,"id":8260126},{"batb":[[0,1.01,15]],"ltp":0.0,"tv":0.0,"id":4486603}]}]}
{"op":"mcm","clk":"1006924384","pt":1580602183340,"mc":[{"id":"1.168224425","rc":[{"batb":[[0,1.01,15.51]],"ltp":0.0,"tv":0.0,"id":8260126},{"batb":[[0,1.01,15.51]],"ltp":0.0,"tv":0.0,"id":4486603}]}]}
{"op":"mcm","clk":"1007043238","pt":1580603723387,"mc":[{"id":"1.168224425","rc":[{"batb":[[0,1.01,16.01]],"ltp":0.0,"tv":0.0,"id":8260126},{"batb":[[0,1.01,16.01]],"ltp":0.0,"tv":0.0,"id":4486603}]}]}
{"op":"mcm","clk":"1007201860","pt":1580607070334,"mc":[{"id":"1.168224425","rc":[{"batb":[[0,1.01,16.02]],"ltp":0.0,"tv":0.0,"id":8260126},{"batb":[[0,1.01,16.02]],"ltp":0.0,"tv":0.0,"id":4486603}]}]}
{"op":"mcm","clk":"1007973568","pt":1580627024394,"mc":[{"id":"1.168224425","rc":[{"batl":[[0,2.28,7.57]],"ltp":0.0,"tv":0.0,"id":8260126},{"batl":[[0,3.55,3.03]],"ltp":0.0,"tv":0.0,"id":4486603}]}]}
{"op":"mcm","clk":"1007974606","pt":1580627042620,"mc":[{"id":"1.168224425","marketDefinition":{"bspMarket":false,"turnInPlayEnabled":true,"persistenceEnabled":true,"marketBaseRate":5.0,"eventId":"29681737","eventTypeId":"2","numberOfWinners":1,"bettingType":"ODDS","marketType":"SET_WINNER","marketTime":"2020-02-02T09:30:00.000Z","suspendTime":"2020-02-02T09:30:00.000Z","bspReconciled":false,"complete":true,"inPlay":false,"crossMatching":true,"runnersVoidable":false,"numberOfActiveRunners":2,"betDelay":0,"status":"OPEN","runners":[{"status":"ACTIVE","sortPriority":1,"id":8260126,"name":"Guillermo Garcia-Lopez"},{"status":"ACTIVE","sortPriority":2,"id":4486603,"name":"Dustin Brown"}],"regulators":["MR_INT"],"countryCode":"FR","discountAllowed":true,"timezone":"UTC","openDate":"2020-02-02T09:30:00.000Z","version":3147125267,"name":"Set 1 Winner","eventName":"Garcia-Lopez v Brown"}}]}
{"op":"mcm","clk":"1008402338","pt":1580634637277,"mc":[{"id":"1.168224425","rc":[{"batl":[[0,1.96,7.57]],"ltp":0.0,"tv":0.0,"id":8260126},{"batl":[[0,3.25,3.03]],"ltp":0.0,"tv":0.0,"id":4486603}]}]}
{"op":"mcm","clk":"1008457009","pt":1580635581363,"mc":[{"id":"1.168224425","rc":[{"batb":[[0,1.58,30.53],[1,1.01,16.02]],"ltp":0.0,"tv":0.0,"id":8260126},{"batb":[[0,2.48,15.11],[1,1.01,16.02]],"ltp":0.0,"tv":0.0,"id":4486603}]}]}
{"op":"mcm","clk":"1008459675","pt":1580635615447,"mc":[{"id":"1.168224425","marketDefinition":{"bspMarket":false,"turnInPlayEnabled":true,"persistenceEnabled":true,"marketBaseRate":5.0,"eventId":"29681737","eventTypeId":"2","numberOfWinners":1,"bettingType":"ODDS","marketType":"SET_WINNER","marketTime":"2020-02-02T09:24:00.000Z","suspendTime":"2020-02-02T09:24:00.000Z","bspReconciled":false,"complete":true,"inPlay":false,"crossMatching":true,"runnersVoidable":false,"numberOfActiveRunners":2,"betDelay":0,"status":"OPEN","runners":[{"status":"ACTIVE","sortPriority":1,"id":8260126,"name":"Guillermo Garcia-Lopez"},{"status":"ACTIVE","sortPriority":2,"id":4486603,"name":"Dustin Brown"}],"regulators":["MR_INT"],"countryCode":"FR","discountAllowed":true,"timezone":"UTC","openDate":"2020-02-02T09:30:00.000Z","version":3148345637,"name":"Set 1 Winner","eventName":"Garcia-Lopez v Brown"}}]}
{"op":"mcm","clk":"1008459927","pt":1580635617379,"mc":[{"id":"1.168224425","marketDefinition":{"bspMarket":false,"turnInPlayEnabled":true,"persistenceEnabled":true,"marketBaseRate":5.0,"eventId":"29681737","eventTypeId":"2","numberOfWinners":1,"bettingType":"ODDS","marketType":"SET_WINNER","marketTime":"2020-02-02T09:24:00.000Z","suspendTime":"2020-02-02T09:24:00.000Z","bspReconciled":false,"complete":true,"inPlay":false,"crossMatching":true,"runnersVoidable":false,"numberOfActiveRunners":2,"betDelay":0,"status":"OPEN","runners":[{"status":"ACTIVE","sortPriority":1,"id":8260126,"name":"Guillermo Garcia-Lopez"},{"status":"ACTIVE","sortPriority":2,"id":4486603,"name":"Dustin Brown"}],"regulators":["MR_INT"],"countryCode":"FR","discountAllowed":true,"timezone":"UTC","openDate":"2020-02-02T09:24:00.000Z","version":3148345637,"name":"Set 1 Winner","eventName":"Garcia-Lopez v Brown"}}]}
{"op":"mcm","clk":"1008462472","pt":1580635660289,"mc":[{"id":"1.168224425","rc":[{"batb":[[1,1.01,17.7]],"ltp":0.0,"tv":0.0,"id":8260126},{"batb":[[1,1.01,17.7]],"ltp":0.0,"tv":0.0,"id":4486603}]}]}
{"op":"mcm","clk":"1008462497","pt":1580635660804,"mc":[{"id":"1.168224425","rc":[{"batb":[[0,1.59,1.59],[1,1.58,30.53],[2,1.01,16.02]],"ltp":0.0,"tv":0.0,"id":8260126},{"batb":[[0,2.5,1.01],[1,2.48,15.11],[2,1.01,16.02]],"ltp":0.0,"tv":0.0,"id":4486603}]}]}
{"op":"mcm","clk":"1008498146","pt":1580636191054,"mc":[{"id":"1.168224425","rc":[{"batb":[[2,1.57,73.1]],"batl":[[0,1.71,42.01],[1,1.96,7.57]],"ltp":0.0,"tv":0.0,"id":8260126},{"batb":[[2,2.44,28.57]],"batl":[[0,2.78,23.53],[1,3.25,3.03]],"ltp":0.0,"tv":0.0,"id":4486603}]}]}
{"op":"mcm","clk":"1008513889","pt":1580636417273,"mc":[{"id":"1.168224425","marketDefinition":{"bspMarket":false,"turnInPlayEnabled":true,"persistenceEnabled":true,"marketBaseRate":5.0,"eventId":"29681737","eventTypeId":"2","numberOfWinners":1,"bettingType":"ODDS","marketType":"SET_WINNER","marketTime":"2020-02-02T09:24:00.000Z","suspendTime":"2020-02-02T09:24:00.000Z","bspReconciled":false,"complete":true,"inPlay":true,"crossMatching":true,"runnersVoidable":false,"numberOfActiveRunners":2,"betDelay":3,"status":"OPEN","runners":[{"status":"ACTIVE","sortPriority":1,"id":8260126,"name":"Guillermo Garcia-Lopez"},{"status":"ACTIVE","sortPriority":2,"id":4486603,"name":"Dustin Brown"}],"regulators":["MR_INT"],"countryCode":"FR","discountAllowed":true,"timezone":"UTC","openDate":"2020-02-02T09:24:00.000Z","version":3148353228,"name":"Set 1 Winner","eventName":"Garcia-Lopez v Brown"},"rc":[{"batb":[[0,1.01,15.52],[1,1.58,0],[2,1.57,0]],"ltp":0.0,"tv":0.0,"id":8260126},{"batb":[[0,1.01,15.52],[1,2.48,0],[2,2.44,0]],"ltp":0.0,"tv":0.0,"id":4486603}]}]}
{"op":"mcm","clk":"1008515567","pt":1580636446220,"mc":[{"id":"1.168224425","rc":[{"batb":[[0,1.5,523.11],[1,1.49,355.13],[2,1.01,15.52]],"batl":[[0,1.77,338.55],[1,1.79,364.3]],"ltp":0.0,"tv":0.0,"id":8260126}]}]}
{"op":"mcm","clk":"1008515813","pt":1580636450435,"mc":[{"id":"1.168224425","rc":[{"batb":[[0,1.01,15.52],[1,1.49,0],[2,1.01,0]],"ltp":0.0,"tv":0.0,"id":8260126}]}]}
{"op":"mcm","clk":"1008516015","pt":1580636453342,"mc":[{"id":"1.168224425","rc":[{"batb":[[0,1.6,286.1],[1,1.59,274.43],[2,1.01,15.52]],"batl":[[0,1.66,422.8],[1,1.68,449.23]],"ltp":0.0,"tv":0.0,"id":8260126}]}]}
{"op":"mcm","clk":"1008516048","pt":1580636453852,"mc":[{"id":"1.168224425","rc":[{"batb":[[0,1.01,15.52],[1,1.59,0],[2,1.01,0]],"ltp":0.0,"tv":0.0,"id":8260126}]}]}
{"op":"mcm","clk":"1008516238","pt":1580636456952,"mc":[{"id":"1.168224425","rc":[{"batb":[[0,1.5,523.11],[1,1.49,355.13],[2,1.01,15.52]],"batl":[[0,1.77,338.55],[1,1.79,364.3]],"ltp":0.0,"tv":0.0,"id":8260126}]}]}
{"op":"mcm","clk":"1008516902","pt":1580636468443,"mc":[{"id":"1.168224425","rc":[{"batb":[[0,1.01,15.52],[1,1.49,0],[2,1.01,0]],"ltp":0.0,"tv":0.0,"id":8260126}]}]}
{"op":"mcm","clk":"1008517079","pt":1580636471372,"mc":[{"id":"1.168224425","rc":[{"batb":[[0,1.7,331.08],[1,1.68,447.14],[2,1.01,15.52]],"ltp":0.0,"tv":0.0,"id":8260126}]}]}
{"op":"mcm","clk":"1008517139","pt":1580636472141,"mc":[{"id":"1.168224425","rc":[{"batb":[[2,1.66,25.57]],"batl":[[1,1.79,406.31]],"ltp":0.0,"tv":0.0,"id":8260126},{"batb":[[0,2.32,18.41],[1,2.26,32.77],[2,2.18,21.72]],"batl":[[0,2.58,26.05]],"ltp":0.0,"tv":0.0,"id":4486603}]}]}
{"op":"mcm","clk":"1008517706","pt":1580636479887,"mc":[{"id":"1.168224425","rc":[{"batb":[[0,1.63,66.38],[1,1.55,32.73],[2,1.01,15.52]],"batl":[[0,1.79,42.01],[1,1.79,0]],"ltp":0.0,"tv":0.0,"id":8260126},{"batb":[[0,2.26,32.77],[1,2.18,21.72],[2,1.01,15.52]],"ltp":0.0,"tv":0.0,"id":4486603}]}]}
{"op":"mcm","clk":"1008517753","pt":1580636480556,"mc":[{"id":"1.168224425","rc":[{"batb":[[0,1.55,32.73],[1,1.01,15.52],[2,1.01,0]],"ltp":0.0,"tv":0.0,"id":8260126},{"batb":[[0,2.18,21.72],[1,1.01,15.52],[2,1.01,0]],"ltp":0.0,"tv":0.0,"id":4486603}]}]}
{"op":"mcm","clk":"1008517896","pt":1580636483179,"mc":[{"id":"1.168224425","rc":[{"batb":[[0,1.59,484.66],[1,1.58,281.83],[2,1.55,32.73]],"batl":[[0,1.84,283.73],[1,1.86,322.68]],"ltp":0.0,"tv":0.0,"id":8260126}]}]}
{"op":"mcm","clk":"1008519063","pt":1580636499286,"mc":[{"id":"1.168224425","rc":[{"batb":[[0,1.55,32.73],[1,1.01,15.52],[2,1.55,0]],"ltp":0.0,"tv":0.0,"id":8260126}]}]}
{"op":"mcm","clk":"1008519271","pt":1580636502387,"mc":[{"id":"1.168224425","rc":[{"batb":[[0,1.77,241.19],[1,1.75,388.29],[2,1.55,32.73]],"ltp":0.0,"tv":0.0,"id":8260126}]}]}
{"op":"mcm","clk":"1008519363","pt":1580636503421,"mc":[{"id":"1.168224425","rc":[{"batb":[[2,1.74,21.95]],"ltp":0.0,"tv":0.0,"id":8260126},{"batb":[[1,2.1,24.39],[2,1.01,15.52]],"ltp":0.0,"tv":0.0,"id":4486603}]}]}
{"op":"mcm","clk":"1008519372","pt":1580636503532,"mc":[{"id":"1.168224425","rc":[{"batl":[[2,1.87,42.01]],"ltp":0.0,"tv":0.0,"id":8260126},{"batb":[[1,2.16,36.13],[2,2.1,24.39]],"batl":[[0,2.44,28.57]],"ltp":0.0,"tv":0.0,"id":4486603}]}]}
{"op":"mcm","clk":"1008520490","pt":1580636518534,"mc":[{"id":"1.168224425","rc":[{"batb":[[0,1.65,26.36],[1,1.01,15.52],[2,1.74,0]],"ltp":0.0,"tv":0.0,"id":8260126},{"batb":[[0,2.1,24.39],[1,1.01,15.52],[2,2.1,0]],"ltp":0.0,"tv":0.0,"id":4486603}]}]}
{"op":"mcm","clk":"1008520697","pt":1580636521433,"mc":[{"id":"1.168224425","rc":[{"batb":[[0,1.69,290.19],[1,1.67,456.41],[2,1.65,26.36]],"batl":[[0,1.89,249.6],[1,1.91,297.31]],"ltp":0.0,"tv":0.0,"id":8260126}]}]}
{"op":"mcm","clk":"1008520711","pt":1580636521645,"mc":[{"id":"1.168224425","rc":[{"batb":[[0,1.65,26.36],[1,1.01,15.52],[2,1.65,0]],"ltp":0.0,"tv":0.0,"id":8260126}]}]}
{"op":"mcm","clk":"1008520924","pt":1580636524429,"mc":[{"id":"1.168224425","rc":[{"batb":[[0,1.75,322.25],[1,1.73,403.96],[2,1.65,26.36]],"batl":[[0,1.82,243.4],[1,1.84,333.92]],"ltp":0.0,"tv":0.0,"id":8260126}]}]}
{"op":"mcm","clk":"1008521185","pt":1580636527229,"mc":[{"id":"1.168224425","rc":[{"batb":[[0,1.65,26.36],[1,1.01,15.52],[2,1.65,0]],"ltp":0.0,"tv":0.0,"id":8260126}]}]}
{"op":"mcm","clk":"1008521421","pt":1580636530239,"mc":[{"id":"1.168224425","rc":[{"batb":[[0,1.69,290.19],[1,1.67,456.41],[2,1.65,26.36]],"batl":[[0,1.89,249.6],[1,1.91,297.31]],"ltp":0.0,"tv":0.0,"id":8260126}]}]}
{"op":"mcm","clk":"1008522144","pt":1580636537370,"mc":[{"id":"1.168224425","rc":[{"batl":[[0,1.76,399.97],[1,1.78,370.69]],"ltp":0.0,"tv":0.0,"id":8260126},{"batb":[[0,2.1,588.43]],"ltp":0.0,"tv":0.0,"id":4486603}]}]}
{"op":"mcm","clk":"1008522188","pt":1580636537786,"mc":[{"id":"1.168224425","rc":[{"batl":[[1,1.78,412.7]],"ltp":0.0,"tv":0.0,"id":8260126},{"batb":[[0,2.34,17.78],[1,2.28,32.77],[2,2.2,21.17]],"batl":[[0,2.6,26.05]],"ltp":0.0,"tv":0.0,"id":4486603}]}]}
{"op":"mcm","clk":"1008523143","pt":1580636550452,"mc":[{"id":"1.168224425","rc":[{"batb":[[0,1.63,66.38],[1,1.52,35.64],[2,1.01,15.52]],"batl":[[0,1.78,42.01],[1,1.78,0]],"ltp":0.0,"tv":0.0,"id":8260126},{"batb":[[0,2.28,32.77],[1,2.2,21.17],[2,1.01,15.52]],"ltp":0.0,"tv":0.0,"id":4486603}]}]}
{"op":"mcm","clk":"1008523155","pt":1580636550660,"mc":[{"id":"1.168224425","rc":[{"batb":[[0,1.52,35.64],[1,1.01,15.52],[2,1.01,0]],"ltp":0.0,"tv":0.0,"id":8260126},{"batb":[[0,2.2,21.17],[1,1.01,15.52],[2,1.01,0]],"ltp":0.0,"tv":0.0,"id":4486603}]}]}
{"op":"mcm","clk":"1008523317","pt":1580636552984,"mc":[{"id":"1.168224425","rc":[{"batb":[[0,1.57,254.69],[1,1.56,294.77],[2,1.52,35.64]],"batl":[[0,1.84,268.38],[1,1.86,322.71]],"ltp":0.0,"tv":0.0,"id":8260126}]}]}
{"op":"mcm","clk":"1008523554","pt":1580636556452,"mc":[{"id":"1.168224425","rc":[{"batb":[[0,1.52,35.64],[1,1.01,15.52],[2,1.52,0]],"ltp":0.0,"tv":0.0,"id":8260126}]}]}
{"op":"mcm","clk":"1008523756","pt":1580636559293,"mc":[{"id":"1.168224425","rc":[{"batb":[[0,1.66,391.75],[1,1.65,239.96],[2,1.52,35.64]],"batl":[[0,1.73,377.38],[1,1.75,391.94]],"ltp":0.0,"tv":0.0,"id":8260126}]}]}
{"op":"mcm","clk":"1008523819","pt":1580636559975,"mc":[{"id":"1.168224425","rc":[{"batb":[[0,1.52,35.64],[1,1.01,15.52],[2,1.52,0]],"ltp":0.0,"tv":0.0,"id":8260126}]}]}
{"op":"mcm","clk":"1008524016","pt":1580636563114,"mc":[{"id":"1.168224425","rc":[{"batb":[[0,1.57,261.8],[1,1.56,294.78],[2,1.52,35.64]],"batl":[[0,1.84,262.33],[1,1.86,322.71]],"ltp":0.0,"tv":0.0,"id":8260126}]}]}
{"op":"mcm","clk":"1008524174","pt":1580636565694,"mc":[{"id":"1.168224425","rc":[{"batb":[[0,1.52,35.64],[1,1.01,15.52],[2,1.52,0]],"ltp":0.0,"tv":0.0,"id":8260126}]}]}
{"op":"mcm","clk":"1008524417","pt":1580636569312,"mc":[{"id":"1.168224425","rc":[{"batb":[[0,1.77,263.54],[1,1.75,388.33],[2,1.73,22.5]],"ltp":0.0,"tv":0.0,"id":8260126},{"batb":[[1,2.12,23.84],[2,1.01,15.52]],"ltp":0.0,"tv":0.0,"id":4486603}]}]}
{"op":"mcm","clk":"1008524478","pt":1580636570188,"mc":[{"id":"1.168224425","rc":[{"batb":[[0,1.73,22.5],[1,1.7,59.65],[2,1.64,26.99]],"batl":[[0,1.87,42.01],[1,1.86,0]],"ltp":0.0,"tv":0.0,"id":8260126},{"batb":[[1,2.16,36.13],[2,2.12,23.84]],"batl":[[0,2.44,28.57]],"ltp":0.0,"tv":0.0,"id":4486603}]}]}
{"op":"mcm","clk":"1008525421","pt":1580636584008,"mc":[{"id":"1.168224425","rc":[{"batb":[[0,1.7,59.65],[1,1.64,26.99],[2,1.01,15.52]],"ltp":0.0,"tv":0.0,"id":8260126},{"batb":[[0,2.16,36.13],[1,2.12,23.84],[2,1.01,15.52]],"ltp":0.0,"tv":0.0,"id":4486603}]}]}
{"op":"mcm","clk":"1008525458","pt":1580636584626,"mc":[{"id":"1.168224425","rc":[{"batb":[[0,1.64,26.99],[1,1.01,15.52],[2,1.01,0]],"ltp":0.0,"tv":0.0,"id":8260126},{"batb":[[0,2.12,23.84],[1,1.01,15.52],[2,1.01,0]],"ltp":0.0,"tv":0.0,"id":4486603}]}]}
{"op":"mcm","clk":"1008526553","pt":1580636600045,"mc":[{"id":"1.168224425","rc":[{"batb":[[0,1.78,20.22],[1,1.76,54.61],[2,1.7,23.76]],"batl":[[0,1.94,42.01]],"ltp":0.0,"tv":0.0,"id":8260126},{"batb":[[1,2.06,39.49],[2,1.9,16.6]],"batl":[[0,2.32,31.09]],"ltp":0.0,"tv":0.0,"id":4486603}]}]}
{"op":"mcm","clk":"1008526915","pt":1580636606174,"mc":[{"id":"1.168224425","rc":[{"batb":[[0,1.81,172.48],[1,1.79,180.16],[2,1.78,20.22]],"batl":[[0,1.89,134.77],[1,1.91,148.62],[2,1.94,42.01]],"ltp":0.0,"tv":0.0,"id":8260126}]}]}
{"op":"mcm","clk":"1008527032","pt":1580636607876,"mc":[{"id":"1.168224425","rc":[{"batb":[[1,1.79,200.15],[2,1.76,54.61]],"ltp":0.0,"tv":0.0,"id":8260126},{"batb":[[0,2.1,24.08],[2,1.89,16.84]],"ltp":0.0,"tv":0.0,"id":4486603}]}]}
{"op":"mcm","clk":"1008528877","pt":1580636636376,"mc":[{"id":"1.168224425","rc":[{"batb":[[0,1.79,19.99],[1,1.76,54.61],[2,1.7,23.53]],"batl":[[0,1.94,42.01],[1,1.91,0],[2,1.94,0]],"ltp":0.0,"tv":0.0,"id":8260126}]}]}
{"op":"mcm","clk":"1008529074","pt":1580636639301,"mc":[{"id":"1.168224425","rc":[{"batb":[[2,1.73,156.72]],"batl":[[1,2.12,198.63],[2,2.14,106.37]],"ltp":0.0,"tv":0.0,"id":8260126}]}]}
{"op":"mcm","clk":"1008529779","pt":1580636649431,"mc":[{"id":"1.168224425","rc":[{"batb":[[0,1.76,54.61],[1,1.73,156.72],[2,1.71,210.15]],"ltp":0.0,"tv":0.0,"id":8260126},{"batb":[[0,2.06,39.49],[1,1.89,16.84],[2,1.01,15.52]],"ltp":0.0,"tv":0.0,"id":4486603}]}]}
{"op":"mcm","clk":"1008529863","pt":1580636650716,"mc":[{"id":"1.168224425","rc":[{"batb":[[0,1.73,156.72],[1,1.71,210.15],[2,1.7,23.53]],"batl":[[0,2.12,198.63],[1,2.14,106.37],[2,2.14,0]],"ltp":0.0,"tv":0.0,"id":8260126},{"batb":[[0,1.89,16.84],[1,1.01,15.52],[2,1.01,0]],"ltp":0.0,"tv":0.0,"id":4486603}]}]}
{"op":"mcm","clk":"1008530574","pt":1580636660251,"mc":[{"id":"1.168224425","rc":[{"batb":[[0,1.7,23.53],[1,1.01,15.52],[2,1.7,0]],"ltp":0.0,"tv":0.0,"id":8260126}]}]}
{"op":"mcm","clk":"1008530801","pt":1580636663427,"mc":[{"id":"1.168224425","rc":[{"batb":[[0,1.9,167.72],[1,1.89,16.84],[2,1.88,153.68]],"batl":[[0,1.99,131.93],[1,2.02,189.37]],"ltp":0.0,"tv":0.0,"id":4486603}]}]}
{"op":"mcm","clk":"1008530888","pt":1580636664455,"mc":[{"id":"1.168224425","rc":[{"batb":[[0,1.99,28.88],[1,1.92,45.37],[2,1.84,18.25]],"batl":[[0,2.16,36.13]],"ltp":0.0,"tv":0.0,"id":8260126},{"batb":[[2,1.88,200.73]],"batl":[[2,2.08,38.65]],"ltp":0.0,"tv":0.0,"id":4486603}]}]}
{"op":"mcm","clk":"1008531569","pt":1580636673947,"mc":[{"id":"1.168224425","rc":[{"batb":[[0,1.9,110.78]],"batl":[[0,2.08,38.65],[1,2.02,0],[2,2.08,0]],"ltp":0.0,"tv":0.0,"id":4486603}]}]}
{"op":"mcm","clk":"1008531742","pt":1580636676446,"mc":[{"id":"1.168224425","rc":[{"batl":[[0,1.98,121.61],[1,2,129.45],[2,2.08,38.65]],"ltp":0.0,"tv":0.0,"id":4486603}]}]}
{"op":"mcm","clk":"1008532365","pt":1580636684235,"mc":[{"id":"1.168224425","rc":[{"batb":[[0,1.92,45.37],[1,1.84,18.25],[2,1.7,409.32]],"ltp":0.0,"tv":0.0,"id":8260126},{"batb":[[0,1.88,47.05],[1,1.64,26.75],[2,1.55,420.5]],"batl":[[0,2.08,38.65],[1,2,0],[2,2.08,0]],"ltp":0.0,"tv":0.0,"id":4486603}]}]}
{"op":"mcm","clk":"1008532404","pt":1580636684751,"mc":[{"id":"1.168224425","rc":[{"batb":[[0,1.84,18.25],[1,1.7,409.32],[2,1.01,15.52]],"ltp":0.0,"tv":0.0,"id":8260126},{"batb":[[0,1.64,26.75],[1,1.55,420.5],[2,1.01,15.52]],"ltp":0.0,"tv":0.0,"id":4486603}]}]}
{"op":"mcm","clk":"1008532587","pt":1580636687676,"mc":[{"id":"1.168224425","rc":[{"batb":[[1,1.01,15.52],[2,1.01,0]],"ltp":0.0,"tv":0.0,"id":4486603}]}]}
{"op":"mcm","clk":"1008532773","pt":1580636690363,"mc":[{"id":"1.168224425","rc":[{"batb":[[0,1.87,121.4],[1,1.85,161.74],[2,1.84,18.25]],"batl":[[0,1.95,133.25],[1,1.97,135.33],[2,2,42.01]],"ltp":0.0,"tv":0.0,"id":8260126},{"batb":[[0,2.04,26.44],[1,2,42.01],[2,1.78,20.14]],"batl":[[0,2.26,32.77]],"ltp":0.0,"tv":0.0,"id":4486603}]}]}
{"op":"mcm","clk":"1008533591","pt":1580636701398,"mc":[{"id":"1.168224425","rc":[{"batb":[[0,1.84,18.25],[1,1.81,51.25],[2,1.73,22.5]],"batl":[[0,2,42.01],[1,1.97,0],[2,2,0]],"ltp":0.0,"tv":0.0,"id":8260126}]}]}
{"op":"mcm","clk":"1008533599","pt":1580636701505,"mc":[{"id":"1.168224425","rc":[{"batb":[[0,1.81,51.25],[1,1.73,22.5],[2,1.7,409.32]],"ltp":0.0,"tv":0.0,"id":8260126},{"batb":[[0,2,42.01],[1,1.78,20.14],[2,1.62,415.43]],"ltp":0.0,"tv":0.0,"id":4486603}]}]}
{"op":"mcm","clk":"1008533710","pt":1580636702703,"mc":[{"id":"1.168224425","rc":[{"batb":[[0,1.73,22.5],[1,1.7,409.32],[2,1.01,15.52]],"ltp":0.0,"tv":0.0,"id":8260126},{"batb":[[0,1.78,20.14],[1,1.62,415.43],[2,1.01,15.52]],"ltp":0.0,"tv":0.0,"id":4486603}]}]}
{"op":"mcm","clk":"1008533839","pt":1580636704306,"mc":[{"id":"1.168224425","rc":[{"batb":[[0,1.75,194.64],[1,1.73,224.53],[2,1.7,409.32]],"batl":[[0,2.26,147.27],[1,2.28,89.17]],"ltp":0.0,"tv":0.0,"id":8260126}]}]}
{"op":"mcm","clk":"1008535121","pt":1580636720113,"mc":[{"id":"1.168224425","rc":[{"batb":[[0,1.73,22.5],[1,1.7,409.32],[2,1.01,15.52]],"ltp":0.0,"tv":0.0,"id":8260126}]}]}
{"op":"mcm","clk":"1008535274","pt":1580636722440,"mc":[{"id":"1.168224425","rc":[{"batb":[[1,1.01,15.52],[2,1.01,0]],"ltp":0.0,"tv":0.0,"id":8260126},{"batb":[[1,1.01,15.52],[2,1.01,0]],"ltp":0.0,"tv":0.0,"id":4486603}]}]}
{"op":"mcm","clk":"1008535339","pt":1580636723212,"mc":[{"id":"1.168224425","rc":[{"batl":[[0,1.87,109.78],[1,1.89,153.69]],"ltp":0.0,"tv":0.0,"id":4486603}]}]}
{"op":"mcm","clk":"1008535383","pt":1580636723829,"mc":[{"id":"1.168224425","rc":[{"batb":[[0,2.12,23.84],[1,2.02,41.17],[2,1.9,16.44]],"batl":[[0,2.28,32.77]],"ltp":0.0,"tv":0.0,"id":8260126},{"batb":[[0,1.78,73.92],[1,1.5,37.14],[2,1.01,15.52]],"batl":[[2,1.98,42.01]],"ltp":0.0,"tv":0.0,"id":4486603}]}]}
{"op":"mcm","clk":"1008535586","pt":1580636726212,"mc":[{"id":"1.168224425","rc":[{"batb":[[0,1.79,174.28],[1,1.78,73.92],[2,1.77,187.26]],"batl":[[0,1.87,152.82]],"ltp":0.0,"tv":0.0,"id":4486603}]}]}
{"op":"mcm","clk":"1008536171","pt":1580636733944,"mc":[{"id":"1.168224425","rc":[{"batb":[[0,1.79,127.62]],"batl":[[0,1.98,42.01],[1,1.89,0],[2,1.98,0]],"ltp":0.0,"tv":0.0,"id":4486603}]}]}
{"op":"mcm","clk":"1008536427","pt":1580636737151,"mc":[{"id":"1.168224425","rc":[{"batl":[[0,1.86,119.04],[1,1.88,156.44],[2,1.98,42.01]],"ltp":0.0,"tv":0.0,"id":4486603}]}]}
{"op":"mcm","clk":"1008538061","pt":1580636758437,"mc":[{"id":"1.168224425","rc":[{"batb":[[0,2.02,41.17],[1,1.9,16.44],[2,1.77,402.27]],"ltp":0.0,"tv":0.0,"id":8260126},{"batb":[[0,1.78,53.77],[1,1.5,464.04],[2,1.01,15.52]],"batl":[[0,1.98,42.01],[1,1.88,0],[2,1.98,0]],"ltp":0.0,"tv":0.0,"id":4486603}]}]}
{"op":"mcm","clk":"1008538081","pt":1580636758643,"mc":[{"id":"1.168224425","rc":[{"batb":[[0,1.9,16.44],[1,1.77,402.27],[2,1.01,15.52]],"ltp":0.0,"tv":0.0,"id":8260126},{"batb":[[0,1.5,464.04],[1,1.01,15.52],[2,1.01,0]],"ltp":0.0,"tv":0.0,"id":4486603}]}]}
{"op":"mcm","clk":"1008538376","pt":1580636761445,"mc":[{"id":"1.168224425","rc":[{"batb":[[0,1.5,753.73],[1,1.49,178.54],[2,1.01,15.52]],"batl":[[0,2.08,168.04],[1,2.1,112.34]],"ltp":0.0,"tv":0.0,"id":4486603}]}]}
{"op":"mcm","clk":"1008538397","pt":1580636761643,"mc":[{"id":"1.168224425","rc":[{"batb":[[0,1.5,464.04],[1,1.01,15.52],[2,1.01,0]],"ltp":0.0,"tv":0.0,"id":4486603}]}]}
{"op":"mcm","clk":"1008538457","pt":1580636762465,"mc":[{"id":"1.168224425","rc":[{"batb":[[0,1.5,37.14]],"ltp":0.0,"tv":0.0,"id":4486603}]}]}
{"op":"mcm","clk":"1008538622","pt":1580636764327,"mc":[{"id":"1.168224425","rc":[{"batb":[[0,1.93,151.87],[1,1.91,146.32],[2,1.9,16.44]],"batl":[[0,2.02,124.4],[1,2.04,122.14]],"ltp":0.0,"tv":0.0,"id":8260126}]}]}
{"op":"mcm","clk":"1008538683","pt":1580636765149,"mc":[{"id":"1.168224425","rc":[{"batb":[[0,1.97,29.51],[1,1.66,25.57],[2,1.01,15.52]],"ltp":0.0,"tv":0.0,"id":4486603}]}]}
{"op":"mcm","clk":"1008538797","pt":1580636766388,"mc":[{"id":"1.168224425","rc":[{"batl":[[1,2.04,162.47]],"ltp":0.0,"tv":0.0,"id":8260126},{"batb":[[1,1.95,43.69],[2,1.66,25.57]],"batl":[[0,2.18,35.29]],"ltp":0.0,"tv":0.0,"id":4486603}]}]}
{"op":"mcm","clk":"1008539810","pt":1580636779429,"mc":[{"id":"1.168224425","rc":[{"batb":[[0,1.9,16.44],[1,1.85,48.73],[2,1.77,402.27]],"batl":[[0,2.04,40.33],[1,2.04,0]],"ltp":0.0,"tv":0.0,"id":8260126}]}]}
{"op":"mcm","clk":"1008539825","pt":1580636779587,"mc":[{"id":"1.168224425","rc":[{"batb":[[0,1.85,48.73],[1,1.77,402.27],[2,1.74,21.95]],"ltp":0.0,"tv":0.0,"id":8260126},{"batb":[[0,1.95,43.69],[1,1.66,25.57],[2,1.58,416.47]],"ltp":0.0,"tv":0.0,"id":4486603}]}]}
{"op":"mcm","clk":"1008539936","pt":1580636781130,"mc":[{"id":"1.168224425","rc":[{"batb":[[0,1.77,402.27],[1,1.74,21.95],[2,1.01,15.52]],"ltp":0.0,"tv":0.0,"id":8260126},{"batb":[[0,1.66,25.57],[1,1.58,416.47],[2,1.01,15.52]],"ltp":0.0,"tv":0.0,"id":4486603}]}]}
{"op":"mcm","clk":"1008540022","pt":1580636782325,"mc":[{"id":"1.168224425","rc":[{"batb":[[1,1.76,184.81],[2,1.74,220.02]],"batl":[[0,2.52,120.26],[1,2.56,132.11]],"ltp":0.0,"tv":0.0,"id":8260126}]}]}
{"op":"mcm","clk":"1008540447","pt":1580636788139,"mc":[{"id":"1.168224425","rc":[{"batb":[[1,1.74,21.95],[2,1.01,15.52]],"ltp":0.0,"tv":0.0,"id":8260126}]}]}
{"op":"mcm","clk":"1008540583","pt":1580636789952,"mc":[{"id":"1.168224425","rc":[{"batb":[[0,1.74,21.95],[1,1.01,15.52],[2,1.01,0]],"ltp":0.0,"tv":0.0,"id":8260126},{"batb":[[1,1.01,15.52],[2,1.01,0]],"ltp":0.0,"tv":0.0,"id":4486603}]}]}
{"op":"mcm","clk":"1008540705","pt":1580636791448,"mc":[{"id":"1.168224425","rc":[{"batb":[[0,2.32,18.41],[1,1.93,15.66],[2,1.74,21.95]],"ltp":0.0,"tv":0.0,"id":8260126},{"batb":[[0,1.66,183.15],[1,1.65,120.24],[2,1.29,73.26]],"batl":[[0,1.72,126.19],[1,1.74,200.69]],"ltp":0.0,"tv":0.0,"id":4486603}]}]}
{"op":"mcm","clk":"1008540745","pt":1580636791923,"mc":[{"id":"1.168224425","rc":[{"batb":[[1,2.18,35.29],[2,1.93,15.66]],"batl":[[0,2.48,27.73]],"ltp":0.0,"tv":0.0,"id":8260126},{"batb":[[0,1.67,62.17],[1,1.66,183.15],[2,1.65,120.24]],"batl":[[2,1.85,42.01]],"ltp":0.0,"tv":0.0,"id":4486603}]}]}
{"op":"mcm","clk":"1008542157","pt":1580636810148,"mc":[{"id":"1.168224425","rc":[{"batb":[[0,2.18,35.29],[1,1.93,15.66],[2,1.92,394.91]],"ltp":0.0,"tv":0.0,"id":8260126},{"batb":[[1,1.4,451.01],[2,1.29,73.25]],"batl":[[0,1.85,42.01],[1,1.74,0],[2,1.85,0]],"ltp":0.0,"tv":0.0,"id":4486603}]}]}
{"op":"mcm","clk":"1008542250","pt":1580636811126,"mc":[{"id":"1.168224425","rc":[{"batb":[[0,1.93,15.66],[1,1.01,15.52],[2,1.92,0]],"ltp":0.0,"tv":0.0,"id":8260126},{"batb":[[0,1.29,73.26],[1,1.01,15.51],[2,1.29,0]],"ltp":0.0,"tv":0.0,"id":4486603}]}]}
{"op":"mcm","clk":"1008542424","pt":1580636813340,"mc":[{"id":"1.168224425","rc":[{"batb":[[1,1.28,507.03],[2,1.27,389.31]],"batl":[[0,2.06,177.3],[1,2.08,115.48]],"ltp":0.0,"tv":0.0,"id":4486603}]}]}
{"op":"mcm","clk":"1008542534","pt":1580636814834,"mc":[{"id":"1.168224425","rc":[{"batb":[[1,1.01,15.51],[2,1.27,0]],"ltp":0.0,"tv":0.0,"id":4486603}]}]}
{"op":"mcm","clk":"1008542758","pt":1580636817943,"mc":[{"id":"1.168224425","rc":[{"batb":[[0,1.95,141.35],[1,1.93,157.29],[2,1.01,15.52]],"batl":[[0,2.04,120.07],[1,2.06,118.72]],"ltp":0.0,"tv":0.0,"id":8260126}]}]}
{"op":"mcm","clk":"1008542811","pt":1580636818666,"mc":[{"id":"1.168224425","rc":[{"batb":[[2,1.76,21.17]],"ltp":0.0,"tv":0.0,"id":8260126},{"batb":[[0,1.94,15.58],[1,1.64,27.15],[2,1.01,15.52]],"ltp":0.0,"tv":0.0,"id":4486603}]}]}
{"op":"mcm","clk":"1008542946","pt":1580636820370,"mc":[{"id":"1.168224425","rc":[{"batb":[[2,1.87,47.89]],"batl":[[1,2.06,158.21]],"ltp":0.0,"tv":0.0,"id":8260126},{"batb":[[1,1.93,44.53],[2,1.64,27.15]],"batl":[[0,2.16,36.13]],"ltp":0.0,"tv":0.0,"id":4486603}]}]}
{"op":"mcm","clk":"1008543978","pt":1580636834114,"mc":[{"id":"1.168224425","rc":[{"batb":[[0,1.87,47.89],[1,1.76,21.17],[2,1.67,409.76]],"batl":[[0,2.06,39.49],[1,2.06,0]],"ltp":0.0,"tv":0.0,"id":8260126},{"batb":[[0,1.93,44.53],[1,1.64,27.15],[2,1.58,416.47]],"ltp":0.0,"tv":0.0,"id":4486603}]}]}
{"op":"mcm","clk":"1008544032","pt":1580636834795,"mc":[{"id":"1.168224425","rc":[{"batb":[[0,1.76,21.17],[1,1.67,409.76],[2,1.01,15.52]],"ltp":0.0,"tv":0.0,"id":8260126},{"batb":[[0,1.64,27.15],[1,1.58,416.47],[2,1.01,15.52]],"ltp":0.0,"tv":0.0,"id":4486603}]}]}
{"op":"mcm","clk":"1008544174","pt":1580636836801,"mc":[{"id":"1.168224425","rc":[{"batb":[[0,1.78,123.06],[1,1.76,211.57],[2,1.67,409.76]],"batl":[[0,2.54,88.63],[1,2.58,129.31]],"ltp":0.0,"tv":0.0,"id":8260126}]}]}
{"op":"mcm","clk":"1008544717","pt":1580636844804,"mc":[{"id":"1.168224425","rc":[{"batb":[[1,1.01,15.52],[2,1.01,0]],"ltp":0.0,"tv":0.0,"id":4486603}]}]}
{"op":"mcm","clk":"1008544825","pt":1580636846406,"mc":[{"id":"1.168224425","rc":[{"batb":[[2,1.67,434.78]],"batl":[[0,1.85,130.44],[1,1.87,158.6],[2,1.9,42.01]],"ltp":0.0,"tv":0.0,"id":8260126},{"batb":[[0,2.14,22.66],[1,2.12,36.97],[2,1.92,15.89]],"batl":[[0,2.4,29.41]],"ltp":0.0,"tv":0.0,"id":4486603}]}]}
{"op":"mcm","clk":"1008544892","pt":1580636847190,"mc":[{"id":"1.168224425","rc":[{"batl":[[2,1.9,0]],"ltp":0.0,"tv":0.0,"id":8260126}]}]}
{"op":"mcm","clk":"1008545096","pt":1580636849414,"mc":[{"id":"1.168224425","rc":[{"batb":[[2,1.72,57.97]],"batl":[[2,1.89,42.01]],"ltp":0.0,"tv":0.0,"id":8260126}]}]}
{"op":"mcm","clk":"1008545942","pt":1580636861341,"mc":[{"id":"1.168224425","rc":[{"batb":[[0,1.72,57.97],[1,1.67,434.78],[2,1.01,15.52]],"batl":[[0,1.89,42.01],[1,1.87,0],[2,1.89,0]],"ltp":0.0,"tv":0.0,"id":8260126},{"batb":[[0,2.12,36.97],[1,1.92,15.89],[2,1.67,409.76]],"ltp":0.0,"tv":0.0,"id":4486603}]}]}
{"op":"mcm","clk":"1008546042","pt":1580636862995,"mc":[{"id":"1.168224425","rc":[{"batb":[[0,1.67,434.78],[1,1.01,15.52],[2,1.01,0]],"ltp":0.0,"tv":0.0,"id":8260126},{"batb":[[0,1.92,15.89],[1,1.67,409.76],[2,1.01,15.52]],"ltp":0.0,"tv":0.0,"id":4486603}]}]}
{"op":"mcm","clk":"1008546143","pt":1580636864228,"mc":[{"id":"1.168224425","rc":[{"batb":[[0,1.69,200.95],[1,1.67,663.05],[2,1.01,15.52]],"batl":[[0,2.06,113.5],[1,2.08,115.44]],"ltp":0.0,"tv":0.0,"id":8260126}]}]}
{"op":"mcm","clk":"1008546322","pt":1580636867114,"mc":[{"id":"1.168224425","rc":[{"batb":[[0,1.67,434.78],[1,1.01,15.52],[2,1.01,0]],"ltp":0.0,"tv":0.0,"id":8260126}]}]}
{"op":"mcm","clk":"1008546427","pt":1580636868812,"mc":[{"id":"1.168224425","rc":[{"batb":[[0,1.67,25.02]],"ltp":0.0,"tv":0.0,"id":8260126},{"batb":[[1,1.01,15.52],[2,1.01,0]],"ltp":0.0,"tv":0.0,"id":4486603}]}]}
{"op":"mcm","clk":"1008546511","pt":1580636870249,"mc":[{"id":"1.168224425","rc":[{"batb":[[0,1.69,200.95],[1,1.67,253.29],[2,1.01,15.52]],"batl":[[0,1.76,146.4],[1,1.78,185.33]],"ltp":0.0,"tv":0.0,"id":8260126}]}]}
{"op":"mcm","clk":"1008546544","pt":1580636870711,"mc":[{"id":"1.168224425","rc":[{"batb":[[2,1.53,34.62]],"ltp":0.0,"tv":0.0,"id":8260126},{"batb":[[0,2.3,18.88],[1,2.14,23.05],[2,1.01,15.52]],"ltp":0.0,"tv":0.0,"id":4486603}]}]}
{"op":"mcm","clk":"1008546624","pt":1580636871840,"mc":[{"id":"1.168224425","rc":[{"batb":[[2,1.63,66.38]],"batl":[[1,1.78,227.34]],"ltp":0.0,"tv":0.0,"id":8260126},{"batb":[[1,2.28,32.77],[2,2.14,23.05]],"batl":[[0,2.6,26.05]],"ltp":0.0,"tv":0.0,"id":4486603}]}]}
{"op":"mcm","clk":"1008547235","pt":1580636882229,"mc":[{"id":"1.168224425","rc":[{"batb":[[0,1.67,25.02],[1,1.63,66.38],[2,1.53,34.62]],"batl":[[0,1.76,111.89]],"ltp":0.0,"tv":0.0,"id":8260126}]}]}
{"op":"mcm","clk":"1008547462","pt":1580636885419,"mc":[{"id":"1.168224425","rc":[{"batb":[[0,1.7,126.29],[1,1.68,223],[2,1.67,25.02]],"ltp":0.0,"tv":0.0,"id":8260126}]}]}
{"op":"mcm","clk":"1008547881","pt":1580636892247,"mc":[{"id":"1.168224425","rc":[{"batb":[[0,1.63,66.38],[1,1.53,34.62],[2,1.52,425.49]],"batl":[[0,1.78,42.01],[1,1.78,0]],"ltp":0.0,"tv":0.0,"id":8260126},{"batb":[[0,2.28,32.77],[1,2.14,23.05],[2,1.74,404.28]],"ltp":0.0,"tv":0.0,"id":4486603}]}]}
{"op":"mcm","clk":"1008547944","pt":1580636893431,"mc":[{"id":"1.168224425","rc":[{"batb":[[0,1.53,34.62],[1,1.52,425.49],[2,1.01,15.52]],"ltp":0.0,"tv":0.0,"id":8260126},{"batb":[[0,2.14,23.05],[1,1.74,404.28],[2,1.01,15.52]],"ltp":0.0,"tv":0.0,"id":4486603}]}]}
{"op":"mcm","clk":"1008548023","pt":1580636894819,"mc":[{"id":"1.168224425","rc":[{"batb":[[0,1.56,124.15],[1,1.55,150.58],[2,1.53,34.62]],"batl":[[0,1.86,116.06],[1,1.88,155.94]],"ltp":0.0,"tv":0.0,"id":8260126}]}]}
{"op":"mcm","clk":"1008548213","pt":1580636898070,"mc":[{"id":"1.168224425","rc":[{"batb":[[0,1.53,34.62],[1,1.52,425.49],[2,1.01,15.52]],"ltp":0.0,"tv":0.0,"id":8260126}]}]}
{"op":"mcm","clk":"1008548322","pt":1580636900339,"mc":[{"id":"1.168224425","rc":[{"batb":[[1,1.01,15.52],[2,1.01,0]],"ltp":0.0,"tv":0.0,"id":8260126}]}]}
{"op":"mcm","clk":"1008548366","pt":1580636901049,"mc":[{"id":"1.168224425","rc":[{"batb":[[0,1.79,128.9],[1,1.77,186.75],[2,1.53,34.62]],"batl":[[0,1.86,116.06],[1,1.88,155.94]],"ltp":0.0,"tv":0.0,"id":8260126}]}]}
{"op":"mcm","clk":"1008548413","pt":1580636901870,"mc":[{"id":"1.168224425","rc":[{"batb":[[1,1.77,207.52],[2,1.71,58.81]],"batl":[[1,1.88,197.95]],"ltp":0.0,"tv":0.0,"id":8260126},{"batb":[[0,2.14,59.18],[1,2.02,26.99],[2,1.74,404.28]],"batl":[[0,2.42,29.41]],"ltp":0.0,"tv":0.0,"id":4486603}]}]}
{"op":"mcm","clk":"1008549060","pt":1580636914356,"mc":[{"id":"1.168224425","rc":[{"batb":[[0,1.71,58.81],[1,1.63,27.22],[2,1.58,416.47]],"batl":[[0,1.88,42.01],[1,1.88,0]],"ltp":0.0,"tv":0.0,"id":8260126},{"batb":[[0,2.14,36.13]],"ltp":0.0,"tv":0.0,"id":4486603}]}]}
{"op":"mcm","clk":"1008549102","pt":1580636914971,"mc":[{"id":"1.168224425","rc":[{"batb":[[0,1.63,27.22],[1,1.58,416.47],[2,1.01,15.52]],"ltp":0.0,"tv":0.0,"id":8260126},{"batb":[[0,2.02,26.99],[1,1.74,404.28],[2,1.01,15.52]],"ltp":0.0,"tv":0.0,"id":4486603}]}]}
{"op":"mcm","clk":"1008549245","pt":1580636917086,"mc":[{"id":"1.168224425","rc":[{"batb":[[0,1.66,199.26],[1,1.65,119.76],[2,1.63,27.22]],"batl":[[0,1.95,151.36],[1,1.97,135.27]],"ltp":0.0,"tv":0.0,"id":8260126}]}]}
{"op":"mcm","clk":"1008549428","pt":1580636920378,"mc":[{"id":"1.168224425","rc":[{"batb":[[0,1.63,27.22],[1,1.58,416.47],[2,1.01,15.52]],"ltp":0.0,"tv":0.0,"id":8260126}]}]}
{"op":"mcm","clk":"1008549581","pt":1580636923362,"mc":[{"id":"1.168224425","rc":[{"batb":[[0,1.76,165.54],[1,1.74,197.88],[2,1.63,27.22]],"batl":[[0,1.83,107.38],[1,1.85,163.96]],"ltp":0.0,"tv":0.0,"id":8260126}]}]}
{"op":"mcm","clk":"1008549646","pt":1580636924384,"mc":[{"id":"1.168224425","rc":[{"batb":[[0,1.63,27.22],[1,1.58,416.47],[2,1.01,15.52]],"ltp":0.0,"tv":0.0,"id":8260126}]}]}
{"op":"mcm","clk":"1008549807","pt":1580636927793,"mc":[{"id":"1.168224425","rc":[{"batb":[[0,1.66,199.26],[1,1.65,119.76],[2,1.63,27.22]],"batl":[[0,1.95,151.36],[1,1.97,135.27]],"ltp":0.0,"tv":0.0,"id":8260126}]}]}
{"op":"mcm","clk":"1008549947","pt":1580636930371,"mc":[{"id":"1.168224425","rc":[{"batb":[[0,1.63,27.22],[1,1.58,416.47],[2,1.01,15.52]],"ltp":0.0,"tv":0.0,"id":8260126}]}]}
{"op":"mcm","clk":"1008550130","pt":1580636933412,"mc":[{"id":"1.168224425","rc":[{"batb":[[0,1.66,199.26],[1,1.65,119.76],[2,1.63,27.22]],"batl":[[0,1.73,183.95],[1,1.75,195.55]],"ltp":0.0,"tv":0.0,"id":8260126}]}]}
{"op":"mcm","clk":"1008550179","pt":1580636934187,"mc":[{"id":"1.168224425","rc":[{"batb":[[0,2.38,17.15],[1,2.18,21.95],[2,1.74,404.28]],"batl":[[0,2.66,25.21]],"ltp":0.0,"tv":0.0,"id":4486603}]}]}
{"op":"mcm","clk":"1008550366","pt":1580636937324,"mc":[{"id":"1.168224425","rc":[{"batl":[[1,1.75,237.56]],"ltp":0.0,"tv":0.0,"id":8260126},{"batb":[[1,2.34,31.09],[2,2.18,21.95]],"ltp":0.0,"tv":0.0,"id":4486603}]}]}
{"op":"mcm","clk":"1008550995","pt":1580636947507,"mc":[{"id":"1.168224425","rc":[{"batb":[[0,1.61,68.06],[1,1.58,416.47],[2,1.47,40.69]],"batl":[[0,1.75,42.01],[1,1.75,0]],"ltp":0.0,"tv":0.0,"id":8260126},{"batb":[[0,2.34,31.09],[1,2.18,21.95],[2,1.74,404.28]],"ltp":0.0,"tv":0.0,"id":4486603}]}]}
{"op":"mcm","clk":"1008551078","pt":1580636948903,"mc":[{"id":"1.168224425","rc":[{"batb":[[0,1.58,416.47],[1,1.47,40.69],[2,1.01,15.51]],"ltp":0.0,"tv":0.0,"id":8260126},{"batb":[[0,2.18,21.95],[1,1.74,404.28],[2,1.01,15.52]],"ltp":0.0,"tv":0.0,"id":4486603}]}]}
{"op":"mcm","clk":"1008551173","pt":1580636950407,"mc":[{"id":"1.168224425","rc":[{"batb":[[1,1.5,163.15],[2,1.49,176.23]],"batl":[[0,1.85,155.78],[1,1.87,158.44]],"ltp":0.0,"tv":0.0,"id":8260126}]}]}
{"op":"mcm","clk":"1008551332","pt":1580636953340,"mc":[{"id":"1.168224425","rc":[{"batb":[[1,1.47,40.69],[2,1.01,15.51]],"ltp":0.0,"tv":0.0,"id":8260126}]}]}
{"op":"mcm","clk":"1008551527","pt":1580636956339,"mc":[{"id":"1.168224425","rc":[{"batb":[[0,1.77,190.55],[1,1.75,194.19],[2,1.58,416.47]],"ltp":0.0,"tv":0.0,"id":8260126}]}]}
{"op":"mcm","clk":"1008551575","pt":1580636957118,"mc":[{"id":"1.168224425","rc":[{"batb":[[2,1.74,21.79]],"ltp":0.0,"tv":0.0,"id":8260126},{"batb":[[1,2.04,26.36],[2,1.74,404.28]],"ltp":0.0,"tv":0.0,"id":4486603}]}]}
{"op":"mcm","clk":"1008551614","pt":1580636957952,"mc":[{"id":"1.168224425","rc":[{"batl":[[1,1.86,42.01],[2,1.87,158.44]],"ltp":0.0,"tv":0.0,"id":8260126},{"batb":[[1,2.16,36.13],[2,2.04,26.36]],"batl":[[0,2.44,28.57]],"ltp":0.0,"tv":0.0,"id":4486603}]}]}
{"op":"mcm","clk":"1008551931","pt":1580636963221,"mc":[{"id":"1.168224425","rc":[{"batl":[[0,2.34,15.14],[1,2.44,28.57]],"ltp":0.0,"tv":0.0,"id":4486603}]}]}
{"op":"mcm","clk":"1008552425","pt":1580636970046,"mc":[{"id":"1.168224425","rc":[{"batb":[[0,1.7,59.65],[1,1.59,29.98],[2,1.58,416.47]],"batl":[[0,1.86,42.01],[1,1.86,0],[2,1.87,0]],"ltp":0.0,"tv":0.0,"id":8260126},{"batb":[[0,2.16,36.13],[1,2.04,26.36],[2,1.74,404.28]],"ltp":0.0,"tv":0.0,"id":4486603}]}]}
{"op":"mcm","clk":"1008552482","pt":1580636970977,"mc":[{"id":"1.168224425","rc":[{"batb":[[0,1.59,29.98],[1,1.58,416.47],[2,1.01,15.52]],"ltp":0.0,"tv":0.0,"id":8260126},{"batb":[[0,2.04,26.36],[1,1.74,404.28],[2,1.01,15.52]],"ltp":0.0,"tv":0.0,"id":4486603}]}]}
{"op":"mcm","clk":"1008552630","pt":1580636973455,"mc":[{"id":"1.168224425","rc":[{"batl":[[0,1.95,135.69],[1,1.97,135.29]],"ltp":0.0,"tv":0.0,"id":8260126}]}]}
{"op":"mcm","clk":"1008552778","pt":1580636975379,"mc":[{"id":"1.168224425","rc":[{"batb":[[1,1.01,15.52],[2,1.01,0]],"ltp":0.0,"tv":0.0,"id":8260126},{"batb":[[1,1.01,15.52],[2,1.01,0]],"ltp":0.0,"tv":0.0,"id":4486603}]}]}
{"op":"mcm","clk":"1008552856","pt":1580636976355,"mc":[{"id":"1.168224425","rc":[{"batb":[[0,1.87,118.73],[1,1.85,161.72],[2,1.84,18.33]],"batl":[[1,1.96,42.01],[2,1.97,135.29]],"ltp":0.0,"tv":0.0,"id":8260126},{"batb":[[0,2.04,66.69],[1,1.97,29.58],[2,1.01,15.52]],"batl":[[0,2.28,32.77]],"ltp":0.0,"tv":0.0,"id":4486603}]}]}
{"op":"mcm","clk":"1008553048","pt":1580636979244,"mc":[{"id":"1.168224425","rc":[{"batb":[[2,1.62,415.43]],"ltp":0.0,"tv":0.0,"id":4486603}]}]}
{"op":"mcm","clk":"1008553271","pt":1580636983063,"mc":[{"id":"1.168224425","rc":[{"batl":[[1,2.3,15.14]],"ltp":0.0,"tv":0.0,"id":4486603}]}]}
{"op":"mcm","clk":"1008553440","pt":1580636985455,"mc":[{"id":"1.168224425","rc":[{"batb":[[0,1.78,53.77],[1,1.74,21.95],[2,1.62,415.43]],"batl":[[0,1.96,42.01],[1,1.96,0],[2,1.97,0]],"ltp":0.0,"tv":0.0,"id":8260126},{"batb":[[0,2.04,40.33]],"ltp":0.0,"tv":0.0,"id":4486603}]}]}
{"op":"mcm","clk":"1008553535","pt":1580636986955,"mc":[{"id":"1.168224425","rc":[{"batb":[[0,1.74,21.95],[1,1.62,415.43],[2,1.01,15.52]],"ltp":0.0,"tv":0.0,"id":8260126},{"batb":[[0,1.97,29.58],[1,1.62,415.43],[2,1.01,15.52]],"batl":[[0,2.3,15.14],[1,2.3,0]],"ltp":0.0,"tv":0.0,"id":4486603}]}]}
{"op":"mcm","clk":"1008553629","pt":1580636988300,"mc":[{"id":"1.168224425","rc":[{"batb":[[0,1.78,150.19],[1,1.76,190.41],[2,1.74,21.95]],"batl":[[0,2,96.18],[1,2.02,125.65]],"ltp":0.0,"tv":0.0,"id":8260126}]}]}
{"op":"mcm","clk":"1008554620","pt":1580637003315,"mc":[{"id":"1.168224425","rc":[{"batb":[[0,1.74,21.95],[1,1.62,415.43],[2,1.01,15.52]],"ltp":0.0,"tv":0.0,"id":8260126}]}]}
{"op":"mcm","clk":"1008554846","pt":1580637006431,"mc":[{"id":"1.168224425","rc":[{"batb":[[0,1.92,122.88],[1,1.9,148.63],[2,1.74,21.95]],"ltp":0.0,"tv":0.0,"id":8260126}]}]}
{"op":"mcm","clk":"1008554909","pt":1580637007313,"mc":[{"id":"1.168224425","rc":[{"batb":[[1,1.9,165],[2,1.79,19.83]],"ltp":0.0,"tv":0.0,"id":8260126},{"batb":[[1,1.76,20.93],[2,1.62,415.43]],"ltp":0.0,"tv":0.0,"id":4486603}]}]}
{"op":"mcm","clk":"1008554963","pt":1580637007926,"mc":[{"id":"1.168224425","rc":[{"batb":[[2,1.85,48.73]],"batl":[[2,2.06,39.49]],"ltp":0.0,"tv":0.0,"id":8260126},{"batb":[[1,1.94,44.53],[2,1.76,20.93]],"batl":[[0,2.16,36.13],[1,2.3,15.14]],"ltp":0.0,"tv":0.0,"id":4486603}]}]}
{"op":"mcm","clk":"1008556072","pt":1580637022417,"mc":[{"id":"1.168224425","rc":[{"batb":[[2,1.77,20.93]],"ltp":0.0,"tv":0.0,"id":4486603}]}]}
{"op":"mcm","clk":"1008560472","pt":1580637096345,"mc":[{"id":"1.168224425","rc":[{"batb":[[0,1.85,48.73],[1,1.79,19.83],[2,1.67,409.76]],"batl":[[0,2.06,39.49],[1,2.02,0],[2,2.06,0]],"ltp":0.0,"tv":0.0,"id":8260126},{"batb":[[0,1.94,44.53],[1,1.77,20.93],[2,1.62,415.43]],"ltp":0.0,"tv":0.0,"id":4486603}]}]}
{"op":"mcm","clk":"1008560517","pt":1580637097062,"mc":[{"id":"1.168224425","rc":[{"batb":[[0,1.79,19.83],[1,1.67,409.76],[2,1.01,15.52]],"ltp":0.0,"tv":0.0,"id":8260126},{"batb":[[0,1.77,20.93],[1,1.62,415.43],[2,1.01,15.52]],"batl":[[0,2.3,15.14],[1,2.3,0]],"ltp":0.0,"tv":0.0,"id":4486603}]}]}
{"op":"mcm","clk":"1008560635","pt":1580637098860,"mc":[{"id":"1.168224425","rc":[{"batb":[[0,1.82,119.94],[1,1.8,176.68],[2,1.79,19.83]],"batl":[[0,2.28,163.81],[1,2.3,87.17]],"ltp":0.0,"tv":0.0,"id":8260126}]}]}
{"op":"mcm","clk":"1008561574","pt":1580637113883,"mc":[{"id":"1.168224425","rc":[{"batb":[[1,1.01,15.52],[2,1.01,0]],"ltp":0.0,"tv":0.0,"id":4486603}]}]}
{"op":"mcm","clk":"1008561662","pt":1580637115374,"mc":[{"id":"1.168224425","rc":[{"batl":[[0,1.9,175.33],[1,1.92,146.09]],"ltp":0.0,"tv":0.0,"id":8260126},{"batb":[[0,1.82,309.42],[1,1.77,20.93],[2,1.01,15.52]],"ltp":0.0,"tv":0.0,"id":4486603}]}]}
{"op":"mcm","clk":"1008561696","pt":1580637116045,"mc":[{"id":"1.168224425","rc":[{"batl":[[2,1.95,42.01]],"ltp":0.0,"tv":0.0,"id":8260126},{"batb":[[0,2.1,24.23],[1,2.06,39.49],[2,1.91,16.37]],"batl":[[0,2.3,47.07]],"ltp":0.0,"tv":0.0,"id":4486603}]}]}
{"op":"mcm","clk":"1008561998","pt":1580637121390,"mc":[{"id":"1.168224425","rc":[{"batl":[[0,1.95,42.01],[1,1.92,0],[2,1.95,0]],"ltp":0.0,"tv":0.0,"id":8260126}]}]}
{"op":"mcm","clk":"1008562171","pt":1580637123872,"mc":[{"id":"1.168224425","rc":[{"batl":[[0,1.89,109.08],[1,1.91,148.57],[2,1.95,42.01]],"ltp":0.0,"tv":0.0,"id":8260126}]}]}
{"op":"mcm","clk":"1008562687","pt":1580637132212,"mc":[{"id":"1.168224425","rc":[{"batb":[[0,1.77,53.77],[1,1.72,22.66],[2,1.67,409.76]],"batl":[[0,1.95,42.01],[1,1.91,0],[2,1.95,0]],"ltp":0.0,"tv":0.0,"id":8260126},{"batb":[[0,2.06,39.49],[1,1.91,16.37],[2,1.67,409.76]],"ltp":0.0,"tv":0.0,"id":4486603}]}]}
{"op":"mcm","clk":"1008562760","pt":1580637133063,"mc":[{"id":"1.168224425","rc":[{"batb":[[0,1.72,22.66],[1,1.67,409.76],[2,1.01,15.52]],"ltp":0.0,"tv":0.0,"id":8260126},{"batb":[[0,1.91,16.37],[1,1.67,409.76],[2,1.01,15.52]],"batl":[[0,2.3,15.14]],"ltp":0.0,"tv":0.0,"id":4486603}]}]}
{"op":"mcm","clk":"1008562918","pt":1580637135392,"mc":[{"id":"1.168224425","rc":[{"batb":[[0,1.75,135.3],[1,1.73,201.69],[2,1.72,22.66]],"batl":[[0,2.06,99.83],[1,2.08,115.4]],"ltp":0.0,"tv":0.0,"id":8260126}]}]}
{"op":"mcm","clk":"1008563274","pt":1580637140388,"mc":[{"id":"1.168224425","rc":[{"batl":[[0,1.82,145.56],[1,1.84,166.68],[2,1.85,42.01]],"ltp":0.0,"tv":0.0,"id":8260126},{"batb":[[0,2.2,21.09],[1,2.16,36.13],[2,2.04,26.2]],"batl":[[1,2.42,29.41]],"ltp":0.0,"tv":0.0,"id":4486603}]}]}
{"op":"mcm","clk":"1008563884","pt":1580637149220,"mc":[{"id":"1.168224425","rc":[{"batb":[[0,1.68,24.78],[1,1.55,420.5],[2,1.01,15.52]],"ltp":0.0,"tv":0.0,"id":8260126},{"batb":[[0,2.04,26.2],[1,1.67,409.76],[2,1.01,15.52]],"batl":[[1,2.42,0]],"ltp":0.0,"tv":0.0,"id":4486603}]}]}
{"op":"mcm","clk":"1008564051","pt":1580637152021,"mc":[{"id":"1.168224425","rc":[{"batb":[[0,1.71,141.23],[1,1.69,218.58],[2,1.68,24.78]],"batl":[[0,1.92,162.72],[1,1.94,141.61]],"ltp":0.0,"tv":0.0,"id":8260126}]}]}
{"op":"mcm","clk":"1008564304","pt":1580637156310,"mc":[{"id":"1.168224425","rc":[{"batb":[[1,1.01,15.52],[2,1.01,0]],"ltp":0.0,"tv":0.0,"id":4486603}]}]}
{"op":"mcm","clk":"1008564373","pt":1580637157435,"mc":[{"id":"1.168224425","rc":[{"batl":[[0,1.78,180.29],[1,1.8,178.58]],"ltp":0.0,"tv":0.0,"id":8260126}]}]}
{"op":"mcm","clk":"1008564427","pt":1580637158315,"mc":[{"id":"1.168224425","rc":[{"batl":[[1,1.8,220.59]],"ltp":0.0,"tv":0.0,"id":8260126},{"batb":[[0,2.28,19.04],[1,2.22,33.61],[2,2.18,22.03]],"batl":[[1,2.5,27.73]],"ltp":0.0,"tv":0.0,"id":4486603}]}]}
{"op":"mcm","clk":"1008565360","pt":1580637172448,"mc":[{"id":"1.168224425","rc":[{"batl":[[0,1.78,131.34]],"ltp":0.0,"tv":0.0,"id":8260126}]}]}
{"op":"mcm","clk":"1008565422","pt":1580637173442,"mc":[{"id":"1.168224425","rc":[{"batb":[[0,1.69,218.58],[1,1.66,63.01],[2,1.65,26.28]],"batl":[[0,1.8,42.01],[1,1.8,0]],"ltp":0.0,"tv":0.0,"id":8260126},{"batb":[[0,2.22,33.61],[1,2.18,22.03],[2,1.74,404.28]],"ltp":0.0,"tv":0.0,"id":4486603}]}]}
{"op":"mcm","clk":"1008565566","pt":1580637175410,"mc":[{"id":"1.168224425","rc":[{"batb":[[0,1.71,51],[1,1.69,218.58]],"ltp":0.0,"tv":0.0,"id":8260126},{"batb":[[0,2.18,22.03],[1,1.74,404.28],[2,1.01,15.52]],"batl":[[1,2.5,0]],"ltp":0.0,"tv":0.0,"id":4486603}]}]}
{"op":"mcm","clk":"1008565650","pt":1580637176338,"mc":[{"id":"1.168224425","rc":[{"batb":[[0,1.69,218.58],[1,1.67,228.01]],"batl":[[0,1.83,146.04],[1,1.85,163.7]],"ltp":0.0,"tv":0.0,"id":8260126},{"batb":[[1,2.16,22.19],[2,1.74,404.28]],"ltp":0.0,"tv":0.0,"id":4486603}]}]}
{"op":"mcm","clk":"1008565699","pt":1580637177009,"mc":[{"id":"1.168224425","rc":[{"batb":[[0,1.65,26.28],[1,1.55,420.5],[2,1.01,15.52]],"ltp":0.0,"tv":0.0,"id":8260126},{"batb":[[0,2.16,22.19],[1,1.74,404.28],[2,1.01,15.52]],"ltp":0.0,"tv":0.0,"id":4486603}]}]}
{"op":"mcm","clk":"1008565909","pt":1580637180422,"mc":[{"id":"1.168224425","rc":[{"batb":[[0,1.72,175.62],[1,1.7,214.12],[2,1.65,26.28]],"batl":[[0,1.79,136.46],[1,1.81,175.43]],"ltp":0.0,"tv":0.0,"id":8260126}]}]}
{"op":"mcm","clk":"1008565952","pt":1580637181227,"mc":[{"id":"1.168224425","rc":[{"batb":[[0,1.65,26.28],[1,1.55,420.5],[2,1.01,15.52]],"ltp":0.0,"tv":0.0,"id":8260126}]}]}
{"op":"mcm","clk":"1008566158","pt":1580637184171,"mc":[{"id":"1.168224425","rc":[{"batb":[[0,1.69,206.3],[1,1.67,228.01],[2,1.65,26.28]],"batl":[[0,1.83,146.04],[1,1.85,163.7]],"ltp":0.0,"tv":0.0,"id":8260126}]}]}
{"op":"mcm","clk":"1008566258","pt":1580637185668,"mc":[{"id":"1.168224425","rc":[{"batb":[[0,1.65,26.28],[1,1.55,420.5],[2,1.01,15.52]],"ltp":0.0,"tv":0.0,"id":8260126}]}]}
{"op":"mcm","clk":"1008566425","pt":1580637188348,"mc":[{"id":"1.168224425","rc":[{"batb":[[0,1.76,124.35],[1,1.74,197.56],[2,1.65,26.28]],"ltp":0.0,"tv":0.0,"id":8260126}]}]}
{"op":"mcm","clk":"1008566483","pt":1580637189174,"mc":[{"id":"1.168224425","rc":[{"batb":[[1,1.75,21.64],[2,1.74,197.56]],"ltp":0.0,"tv":0.0,"id":8260126},{"batb":[[1,2.02,27.15],[2,1.74,404.28]],"ltp":0.0,"tv":0.0,"id":4486603}]}]}
{"op":"mcm","clk":"1008566556","pt":1580637190057,"mc":[{"id":"1.168224425","rc":[{"batl":[[1,1.85,205.71]],"ltp":0.0,"tv":0.0,"id":8260126},{"batb":[[0,2.16,58.32]],"batl":[[1,2.42,29.41]],"ltp":0.0,"tv":0.0,"id":4486603}]}]}
{"op":"mcm","clk":"1008567201","pt":1580637198856,"mc":[{"id":"1.168224425","rc":[{"trd":[[1.76,268.49]],"batb":[[0,1.75,21.64],[1,1.74,197.56],[2,1.71,58.81]],"batl":[[0,1.76,4.57],[1,1.83,146.04],[2,1.85,205.71]],"ltp":1.76,"tv":268.49,"id":8260126},{"trd":[[2.3,15.14]],"batl":[[0,2.42,29.41],[1,2.42,0]],"ltp":2.3,"tv":15.14,"id":4486603}],"tv":283.63}]}
{"op":"mcm","clk":"1008567239","pt":1580637199497,"mc":[{"id":"1.168224425","rc":[{"batb":[[1,1.71,58.81],[2,1.7,23.53]],"batl":[[1,1.85,42.01],[2,1.85,0]],"ltp":1.76,"tv":268.49,"id":8260126}]}]}
{"op":"mcm","clk":"1008567407","pt":1580637202358,"mc":[{"id":"1.168224425","rc":[{"batb":[[0,1.75,198.36],[1,1.73,201.82],[2,1.71,58.81]],"batl":[[1,1.82,106.1],[2,1.84,166.78]],"ltp":1.76,"tv":268.49,"id":8260126}]}]}
{"op":"mcm","clk":"1008567632","pt":1580637205877,"mc":[{"id":"1.168224425","rc":[{"batb":[[0,1.71,58.81],[1,1.7,23.53],[2,1.55,420.5]],"batl":[[1,1.85,42.01],[2,1.84,0]],"ltp":1.76,"tv":268.49,"id":8260126},{"batb":[[0,2.16,36.13]],"ltp":2.3,"tv":15.14,"id":4486603}]}]}
{"op":"mcm","clk":"1008567723","pt":1580637207165,"mc":[{"id":"1.168224425","rc":[{"batb":[[0,1.7,23.53],[1,1.55,420.5],[2,1.01,15.52]],"batl":[[1,1.85,0]],"ltp":1.76,"tv":268.49,"id":8260126},{"batb":[[0,2.02,27.15],[1,1.74,404.28],[2,1.01,15.52]],"ltp":2.3,"tv":15.14,"id":4486603}]}]}
{"op":"mcm","clk":"1008567983","pt":1580637211083,"mc":[{"id":"1.168224425","rc":[{"trd":[[1.77,9.14]],"batb":[[0,1.77,131.57],[1,1.75,194],[2,1.7,23.53]],"batl":[[0,1.84,126.34],[1,1.86,161.17]],"ltp":1.77,"tv":277.63,"id":8260126}],"tv":292.77}]}
{"op":"mcm","clk":"1008568034","pt":1580637212065,"mc":[{"id":"1.168224425","rc":[{"batb":[[0,1.7,23.53],[1,1.55,420.5],[2,1.01,15.52]],"ltp":1.77,"tv":277.63,"id":8260126}]}]}
{"op":"mcm","clk":"1008568261","pt":1580637216289,"mc":[{"id":"1.168224425","rc":[{"batb":[[0,1.71,182.39],[1,1.7,23.53],[2,1.69,218.87]],"batl":[[0,1.91,126.4],[1,1.93,143.95]],"ltp":1.77,"tv":277.63,"id":8260126}]}]}
{"op":"mcm","clk":"1008568744","pt":1580637224375,"mc":[{"id":"1.168224425","rc":[{"batl":[[0,1.78,141.64],[1,1.8,220.82]],"ltp":1.77,"tv":277.63,"id":8260126},{"batb":[[0,2.24,53.83],[1,2.08,24.78],[2,1.74,404.28]],"batl":[[0,2.52,26.89]],"ltp":2.3,"tv":15.14,"id":4486603}]}]}
{"op":"mcm","clk":"1008569178","pt":1580637231421,"mc":[{"id":"1.168224425","rc":[{"batb":[[0,1.7,23.53],[1,1.66,63.01],[2,1.55,420.5]],"batl":[[0,1.8,42.01],[1,1.8,0]],"ltp":1.77,"tv":277.63,"id":8260126}]}]}
{"op":"mcm","clk":"1008569370","pt":1580637234306,"mc":[{"id":"1.168224425","rc":[{"batb":[[0,1.72,127.7],[1,1.7,237.53],[2,1.66,63.01]],"batl":[[0,1.79,182.23],[1,1.8,42.01],[2,1.81,175.36]],"ltp":1.77,"tv":277.63,"id":8260126}]}]}
{"op":"mcm","clk":"1008570148","pt":1580637246449,"mc":[{"id":"1.168224425","rc":[{"batb":[[0,1.66,63.01],[1,1.55,420.5],[2,1.54,33.91]],"batl":[[0,1.8,42.01],[1,1.8,0],[2,1.81,0]],"ltp":1.77,"tv":277.63,"id":8260126},{"batb":[[0,2.24,33.61]],"ltp":2.3,"tv":15.14,"id":4486603}]}]}
{"op":"mcm","clk":"1008570206","pt":1580637247374,"mc":[{"id":"1.168224425","rc":[{"batb":[[0,1.55,420.5],[1,1.54,33.91],[2,1.01,15.52]],"ltp":1.77,"tv":277.63,"id":8260126},{"batb":[[0,2.08,24.78],[1,1.74,404.28],[2,1.01,15.52]],"ltp":2.3,"tv":15.14,"id":4486603}]}]}
{"op":"mcm","clk":"1008570328","pt":1580637249379,"mc":[{"id":"1.168224425","rc":[{"batb":[[0,1.56,215.81],[1,1.55,571.5],[2,1.54,33.91]],"batl":[[0,1.89,104.71],[1,1.91,148.54]],"ltp":1.77,"tv":277.63,"id":8260126}]}]}
{"op":"mcm","clk":"1008570493","pt":1580637251456,"mc":[{"id":"1.168224425","rc":[{"batb":[[0,1.55,420.5],[1,1.54,33.91],[2,1.01,15.52]],"ltp":1.77,"tv":277.63,"id":8260126}]}]}
{"op":"mcm","clk":"1008570716","pt":1580637254391,"mc":[{"id":"1.168224425","rc":[{"batb":[[0,1.68,204.92],[1,1.66,232.97],[2,1.55,420.5]],"batl":[[0,1.75,153.71],[1,1.77,188.52]],"ltp":1.77,"tv":277.63,"id":8260126}]}]}
{"op":"mcm","clk":"1008570756","pt":1580637254904,"mc":[{"id":"1.168224425","rc":[{"batb":[[0,1.55,420.5],[1,1.54,33.91],[2,1.01,15.52]],"ltp":1.77,"tv":277.63,"id":8260126}]}]}
{"op":"mcm","clk":"1008570939","pt":1580637257289,"mc":[{"id":"1.168224425","rc":[{"batb":[[0,1.56,215.81],[1,1.55,571.5],[2,1.54,33.91]],"batl":[[0,1.89,104.71],[1,1.91,148.54]],"ltp":1.77,"tv":277.63,"id":8260126}]}]}
{"op":"mcm","clk":"1008571006","pt":1580637258368,"mc":[{"id":"1.168224425","rc":[{"batl":[[0,1.9,176.2],[1,1.92,146.06]],"ltp":1.77,"tv":277.63,"id":8260126}]}]}
{"op":"mcm","clk":"1008571290","pt":1580637262394,"mc":[{"id":"1.168224425","rc":[{"batb":[[1,1.55,151]],"ltp":1.77,"tv":277.63,"id":8260126},{"batb":[[1,1.01,15.52],[2,1.01,0]],"ltp":2.3,"tv":15.14,"id":4486603}]}]}
{"op":"mcm","clk":"1008571362","pt":1580637263383,"mc":[{"id":"1.168224425","rc":[{"batl":[[0,1.62,195.77],[1,1.63,123.6]],"ltp":1.77,"tv":277.63,"id":8260126}]}]}
{"op":"mcm","clk":"1008571418","pt":1580637264409,"mc":[{"id":"1.168224425","rc":[{"batl":[[2,1.65,42.01]],"ltp":1.77,"tv":277.63,"id":8260126},{"batb":[[0,2.6,13.3],[1,2.54,26.89],[2,2.32,18.1]],"batl":[[0,2.94,21]],"ltp":2.3,"tv":15.14,"id":4486603}]}]}
{"op":"mcm","clk":"1008572195","pt":1580637276318,"mc":[{"id":"1.168224425","rc":[{"batb":[[0,1.54,33.91],[1,1.52,80.66],[2,1.4,451.01]],"batl":[[0,1.65,42.01],[1,1.63,0],[2,1.65,0]],"ltp":1.77,"tv":277.63,"id":8260126}]}]}
{"op":"mcm","clk":"1008572271","pt":1580637277307,"mc":[{"id":"1.168224425","rc":[{"batb":[[0,1.4,451.01],[1,1.37,55.31],[2,1.01,15.51]],"ltp":1.77,"tv":277.63,"id":8260126},{"batb":[[0,2.32,18.1],[1,1.92,394.91],[2,1.01,15.52]],"ltp":2.3,"tv":15.14,"id":4486603}]}]}
{"op":"mcm","clk":"1008572435","pt":1580637279925,"mc":[{"id":"1.168224425","rc":[{"batb":[[1,1.39,223.2],[2,1.38,246.38]],"batl":[[0,1.75,186.63],[1,1.77,188.37]],"ltp":1.77,"tv":277.63,"id":8260126}]}]}
{"op":"mcm","clk":"1008572947","pt":1580637287405,"mc":[{"id":"1.168224425","rc":[{"trd":[[1.48,0.02]],"batb":[[0,1.39,223.2],[1,1.38,246.38],[2,1.37,55.31]],"batl":[[0,1.43,204.9],[1,1.44,198.48]],"ltp":1.48,"tv":277.65,"id":8260126},{"batb":[[1,1.01,15.52],[2,1.01,0]],"ltp":2.3,"tv":15.14,"id":4486603}],"tv":292.79}]}
{"op":"mcm","clk":"1008573011","pt":1580637288432,"mc":[{"id":"1.168224425","rc":[{"batb":[[2,1.37,168.74]],"ltp":1.48,"tv":277.65,"id":8260126},{"batb":[[0,3.3,18.18],[1,2.82,10.86],[2,1.01,15.52]],"batl":[[0,3.7,15.12]],"ltp":2.3,"tv":15.14,"id":4486603}]}]}
{"op":"mcm","clk":"1008573221","pt":1580637291418,"mc":[{"id":"1.168224425","rc":[{"batl":[[2,1.46,42.01]],"ltp":1.48,"tv":277.65,"id":8260126},{"batb":[[1,3.15,19.32],[2,2.82,10.86]],"ltp":2.3,"tv":15.14,"id":4486603}]}]}
{"op":"mcm","clk":"1008573872","pt":1580637300441,"mc":[{"id":"1.168224425","rc":[{"batb":[[0,1.37,113.43],[1,1.28,485.89],[2,1.22,104.17]],"batl":[[0,1.46,42.01],[1,1.44,0],[2,1.46,0]],"ltp":1.48,"tv":277.65,"id":8260126},{"batb":[[0,3.15,19.32],[1,2.82,10.86],[2,2.22,384.52]],"ltp":2.3,"tv":15.14,"id":4486603}]}]}
{"op":"mcm","clk":"1008573961","pt":1580637301232,"mc":[{"id":"1.168224425","rc":[{"batb":[[0,1.28,485.89],[1,1.22,104.17],[2,1.01,15.51]],"ltp":1.48,"tv":277.65,"id":8260126},{"batb":[[0,2.82,10.86],[1,2.22,384.52],[2,1.01,15.52]],"ltp":2.3,"tv":15.14,"id":4486603}]}]}
{"op":"mcm","clk":"1008574155","pt":1580637303408,"mc":[{"id":"1.168224425","rc":[{"batb":[[1,1.23,550.57],[2,1.22,596.36]],"batl":[[0,1.55,194.67],[1,1.56,144.86]],"ltp":1.48,"tv":277.65,"id":8260126}]}]}
{"op":"mcm","clk":"1008574274","pt":1580637305212,"mc":[{"id":"1.168224425","rc":[{"batb":[[1,1.22,104.17],[2,1.01,15.51]],"ltp":1.48,"tv":277.65,"id":8260126}]}]}
{"op":"mcm","clk":"1008574504","pt":1580637308410,"mc":[{"id":"1.168224425","rc":[{"batb":[[0,1.35,402.24],[1,1.34,286.32],[2,1.28,485.89]],"batl":[[0,1.39,145.5],[1,1.4,224.78]],"ltp":1.48,"tv":277.65,"id":8260126}]}]}
{"op":"mcm","clk":"1008574548","pt":1580637308925,"mc":[{"id":"1.168224425","rc":[{"batl":[[0,1.39,257.25]],"ltp":1.48,"tv":277.65,"id":8260126}]}]}
{"op":"mcm","clk":"1008574689","pt":1580637310523,"mc":[{"id":"1.168224425","rc":[{"batb":[[0,1.28,485.89],[1,1.22,104.17],[2,1.01,15.51]],"batl":[[0,1.39,111.75],[1,1.4,0]],"ltp":1.48,"tv":277.65,"id":8260126}]}]}
{"op":"mcm","clk":"1008574938","pt":1580637313427,"mc":[{"id":"1.168224425","rc":[{"batb":[[1,1.23,550.57],[2,1.22,596.36]],"batl":[[1,1.55,194.67],[2,1.56,144.86]],"ltp":1.48,"tv":277.65,"id":8260126}]}]}
{"op":"mcm","clk":"1008575083","pt":1580637315331,"mc":[{"id":"1.168224425","rc":[{"batl":[[1,1.55,0],[2,1.56,0]],"ltp":1.48,"tv":277.65,"id":8260126}]}]}
{"op":"mcm","clk":"1008575219","pt":1580637317141,"mc":[{"id":"1.168224425","rc":[{"batb":[[0,1.23,550.57],[1,1.22,596.36],[2,1.01,15.51]],"ltp":1.48,"tv":277.65,"id":8260126},{"batb":[[1,1.01,15.52],[2,1.01,0]],"ltp":2.3,"tv":15.14,"id":4486603}]}]}
{"op":"mcm","clk":"1008575326","pt":1580637318435,"mc":[{"id":"1.168224425","rc":[{"batb":[[0,1.24,168.04],[1,1.23,550.57],[2,1.22,596.36]],"batl":[[0,1.26,201.75],[1,1.27,363.26]],"ltp":1.48,"tv":277.65,"id":8260126},{"batl":[[0,5.2,9.24]],"ltp":2.3,"tv":15.14,"id":4486603}]}]}
{"op":"mcm","clk":"1008575383","pt":1580637319208,"mc":[{"id":"1.168224425","rc":[{"batb":[[0,4.7,15.03],[1,4.3,12.6],[2,3.95,23.6]],"ltp":2.3,"tv":15.14,"id":4486603}]}]}
{"op":"mcm","clk":"1008575521","pt":1580637321356,"mc":[{"id":"1.168224425","rc":[{"trd":[[1.24,223.49]],"batb":[[0,1.23,550.57],[1,1.22,596.36],[2,1.16,576.13]],"ltp":1.24,"tv":501.14,"id":8260126},{"batb":[[1,3.95,23.6],[2,2.72,378.25]],"ltp":2.3,"tv":15.14,"id":4486603}],"tv":516.29}]}
{"op":"mcm","clk":"1008575768","pt":1580637324313,"mc":[{"id":"1.168224425","rc":[{"batb":[[0,1.23,718.61]],"batl":[[2,1.29,42.01]],"ltp":1.24,"tv":501.14,"id":8260126},{"batb":[[1,4.5,11.76],[2,3.95,23.6]],"ltp":2.3,"tv":15.14,"id":4486603}]}]}
{"op":"mcm","clk":"1008576217","pt":1580637330044,"mc":[{"id":"1.168224425","rc":[{"batb":[[0,1.23,168.04],[1,1.16,576.13],[2,1.12,190.88]],"batl":[[0,1.29,42.01],[1,1.27,0],[2,1.29,0]],"ltp":1.24,"tv":501.14,"id":8260126},{"batb":[[0,4.5,11.76],[1,3.95,23.6],[2,2.72,378.25]],"ltp":2.3,"tv":15.14,"id":4486603}]}]}
{"op":"mcm","clk":"1008576311","pt":1580637331246,"mc":[{"id":"1.168224425","rc":[{"batb":[[0,1.16,576.13],[1,1.12,190.88],[2,1.01,15.51]],"ltp":1.24,"tv":501.14,"id":8260126},{"batb":[[0,3.95,23.6],[1,2.72,378.25],[2,1.01,15.52]],"ltp":2.3,"tv":15.14,"id":4486603}]}]}
{"op":"mcm","clk":"1008576389","pt":1580637332317,"mc":[{"id":"1.168224425","rc":[{"batb":[[0,2.72,378.25],[1,1.01,15.52],[2,1.01,0]],"ltp":2.3,"tv":15.14,"id":4486603}]}]}
{"op":"mcm","clk":"1008576478","pt":1580637333454,"mc":[{"id":"1.168224425","rc":[{"batb":[[0,1.12,188.99],[1,1.01,15.51],[2,1.01,0]],"batl":[[0,1.33,190.02],[1,1.34,274.73]],"ltp":1.24,"tv":501.14,"id":8260126},{"batb":[[0,3.9,24],[1,2.72,378.25],[2,1.01,15.52]],"ltp":2.3,"tv":15.14,"id":4486603}]}]}
{"op":"mcm","clk":"1008576590","pt":1580637334847,"mc":[{"id":"1.168224425","rc":[{"batb":[[0,1.3,246.11],[1,1.29,346.41],[2,1.12,188.99]],"ltp":1.24,"tv":501.14,"id":8260126}]}]}
{"op":"mcm","clk":"1008576717","pt":1580637336445,"mc":[{"id":"1.168224425","rc":[{"batb":[[1,1.29,422.18],[2,1.13,182.86]],"batl":[[2,1.35,42.01]],"ltp":1.24,"tv":501.14,"id":8260126},{"batb":[[0,3.9,38.28],[1,3.15,20.14],[2,2.72,378.25]],"ltp":2.3,"tv":15.14,"id":4486603}]}]}
{"op":"mcm","clk":"1008576793","pt":1580637337432,"mc":[{"id":"1.168224425","rc":[{"batb":[[2,1.22,523]],"batl":[[2,1.35,0]],"ltp":1.24,"tv":501.14,"id":8260126}]}]}
{"op":"mcm","clk":"1008576987","pt":1580637340148,"mc":[{"id":"1.168224425","rc":[{"batl":[[2,1.35,42.01]],"ltp":1.24,"tv":501.14,"id":8260126}]}]}
{"op":"mcm","clk":"1008577551","pt":1580637348442,"mc":[{"id":"1.168224425","rc":[{"batb":[[0,1.22,523],[1,1.13,182.86],[2,1.01,15.51]],"batl":[[0,1.35,42.01],[1,1.34,0],[2,1.35,0]],"ltp":1.24,"tv":501.14,"id":8260126},{"batb":[[0,3.9,14.28]],"ltp":2.3,"tv":15.14,"id":4486603}]}]}
{"op":"mcm","clk":"1008577605","pt":1580637349263,"mc":[{"id":"1.168224425","rc":[{"batb":[[0,3.15,20.14],[1,2.72,378.25],[2,1.01,15.52]],"ltp":2.3,"tv":15.14,"id":4486603}]}]}
{"op":"mcm","clk":"1008577643","pt":1580637349786,"mc":[{"id":"1.168224425","rc":[{"batb":[[0,1.13,182.86],[1,1.01,15.51],[2,1.01,0]],"ltp":1.24,"tv":501.14,"id":8260126},{"batb":[[1,1.01,15.52],[2,1.01,0]],"ltp":2.3,"tv":15.14,"id":4486603}]}]}
{"op":"mcm","clk":"1008577764","pt":1580637351378,"mc":[{"id":"1.168224425","rc":[{"batb":[[0,1.14,662.55],[1,1.13,648.7],[2,1.01,15.51]],"batl":[[0,1.46,285.91],[1,1.47,181.61]],"ltp":1.24,"tv":501.14,"id":8260126}]}]}
{"op":"mcm","clk":"1008577779","pt":1580637351586,"mc":[{"id":"1.168224425","rc":[{"batb":[[0,1.13,182.86],[1,1.01,15.51],[2,1.01,0]],"ltp":1.24,"tv":501.14,"id":8260126}]}]}
{"op":"mcm","clk":"1008577983","pt":1580637354376,"mc":[{"id":"1.168224425","rc":[{"batb":[[0,1.26,479.71],[1,1.25,420.5],[2,1.13,182.86]],"batl":[[0,1.3,441.57],[1,1.31,303.09]],"ltp":1.24,"tv":501.14,"id":8260126}]}]}
{"op":"mcm","clk":"1008578098","pt":1580637355983,"mc":[{"id":"1.168224425","rc":[{"batb":[[0,1.2,530.86],[1,1.13,182.86],[2,1.01,15.51]],"ltp":1.24,"tv":501.14,"id":8260126},{"batb":[[1,2.52,381.46],[2,1.01,15.52]],"ltp":2.3,"tv":15.14,"id":4486603}]}]}
{"op":"mcm","clk":"1008578171","pt":1580637356859,"mc":[{"id":"1.168224425","rc":[{"batb":[[0,1.13,182.86],[1,1.01,15.51],[2,1.01,0]],"ltp":1.24,"tv":501.14,"id":8260126},{"batb":[[1,1.01,15.52],[2,1.01,0]],"ltp":2.3,"tv":15.14,"id":4486603}]}]}
{"op":"mcm","clk":"1008578306","pt":1580637358662,"mc":[{"id":"1.168224425","rc":[{"batb":[[0,1.14,662.55],[1,1.13,648.7],[2,1.01,15.51]],"batl":[[0,1.46,285.91],[1,1.47,181.61]],"ltp":1.24,"tv":501.14,"id":8260126}]}]}
{"op":"mcm","clk":"1008578883","pt":1580637367404,"mc":[{"id":"1.168224425","rc":[{"batl":[[0,1.16,272.29],[1,1.17,618.83]],"ltp":1.24,"tv":501.14,"id":8260126}]}]}
{"op":"mcm","clk":"1008578951","pt":1580637368288,"mc":[{"id":"1.168224425","rc":[{"batb":[[2,1.1,242.58]],"ltp":1.24,"tv":501.14,"id":8260126},{"batb":[[0,6.8,12.67],[1,6.4,7.56],[2,5,13.38]],"batl":[[0,7.8,5.88]],"ltp":2.3,"tv":15.14,"id":4486603}]}]}
{"op":"mcm","clk":"1008582149","pt":1580637409618,"mc":[{"id":"1.168224425","rc":[{"trd":[[1.14,14]],"batb":[[0,1.14,655.55]],"ltp":1.14,"tv":515.14,"id":8260126}],"tv":530.29}]}
{"op":"mcm","clk":"1008585579","pt":1580637453295,"mc":[{"id":"1.168224425","rc":[{"batb":[[0,1.1,242.58],[1,1.09,779.05],[2,1.01,15.51]],"ltp":1.14,"tv":515.14,"id":8260126},{"batb":[[0,5,13.38],[1,3.15,373.59],[2,1.01,15.52]],"ltp":2.3,"tv":15.14,"id":4486603}]}]}
{"op":"mcm","clk":"1008585796","pt":1580637456383,"mc":[{"id":"1.168224425","rc":[{"batb":[[0,1.11,868.26],[1,1.1,531.62],[2,1.09,779.05]],"ltp":1.14,"tv":515.14,"id":8260126}]}]}
{"op":"mcm","clk":"1008585851","pt":1580637457201,"mc":[{"id":"1.168224425","rc":[{"batb":[[2,1.01,15.51]],"ltp":1.14,"tv":515.14,"id":8260126}]}]}
{"op":"mcm","clk":"1008585990","pt":1580637459408,"mc":[{"id":"1.168224425","rc":[{"batb":[[0,1.11,721.27]],"batl":[[0,1.13,474.29],[1,1.14,654.18]],"ltp":1.14,"tv":515.14,"id":8260126}]}]}
{"op":"mcm","clk":"1008586052","pt":1580637460287,"mc":[{"id":"1.168224425","rc":[{"batb":[[2,1.08,305.52]],"batl":[[1,1.14,510.93],[2,1.15,42.01]],"ltp":1.14,"tv":515.14,"id":8260126},{"batb":[[0,8.4,7.95],[1,7.6,5.88],[2,6.2,15.97]],"batl":[[0,9.6,4.2]],"ltp":2.3,"tv":15.14,"id":4486603}]}]}
{"op":"mcm","clk":"1008586194","pt":1580637462300,"mc":[{"id":"1.168224425","rc":[{"batb":[[1,1.1,679.94]],"batl":[[0,1.13,618.8]],"ltp":1.14,"tv":515.14,"id":8260126}]}]}
{"op":"mcm","clk":"1008586211","pt":1580637462606,"mc":[{"id":"1.168224425","rc":[{"batb":[[0,1.11,655.65]],"batl":[[1,1.14,447.02]],"ltp":1.14,"tv":515.14,"id":8260126}]}]}
{"op":"mcm","clk":"1008586497","pt":1580637466222,"mc":[{"id":"1.168224425","rc":[{"batb":[[1,1.1,746.16]],"batl":[[0,1.13,683.28]],"ltp":1.14,"tv":515.14,"id":8260126}]}]}
{"op":"mcm","clk":"1008586737","pt":1580637469428,"mc":[{"id":"1.168224425","rc":[{"batb":[[0,1.08,305.52],[1,1.07,893.98],[2,1.01,15.51]],"ltp":1.14,"tv":515.14,"id":8260126},{"batb":[[0,6.2,15.97],[1,3.15,373.59],[2,1.01,15.52]],"ltp":2.3,"tv":15.14,"id":4486603}]}]}
{"op":"mcm","clk":"1008586945","pt":1580637472305,"mc":[{"id":"1.168224425","rc":[{"batb":[[0,1.09,827.51],[1,1.08,657.12]],"ltp":1.14,"tv":515.14,"id":8260126},{"batb":[[1,1.01,15.52],[2,1.01,0]],"ltp":2.3,"tv":15.14,"id":4486603}]}]}
{"op":"mcm","clk":"1008587084","pt":1580637474320,"mc":[{"id":"1.168224425","rc":[{"batl":[[0,1.11,919.07],[1,1.12,233.52]],"ltp":1.14,"tv":515.14,"id":8260126},{"batb":[[0,8.8,5.04],[1,6.2,15.97],[2,1.01,15.52]],"batl":[[0,11.5,3.36]],"ltp":2.3,"tv":15.14,"id":4486603}]}]}
{"op":"mcm","clk":"1008587123","pt":1580637474937,"mc":[{"id":"1.168224425","rc":[{"batb":[[2,1.06,366.26]],"ltp":1.14,"tv":515.14,"id":8260126},{"batb":[[0,9.8,13.93],[1,8.8,5.04],[2,7.8,9.21]],"ltp":2.3,"tv":15.14,"id":4486603}]}]}
{"op":"mcm","clk":"1008587721","pt":1580637483416,"mc":[{"id":"1.168224425","rc":[{"batb":[[0,1.08,351.6],[1,1.06,366.26],[2,1.05,1069.56]],"ltp":1.14,"tv":515.14,"id":8260126},{"batb":[[0,7.8,9.21],[1,3.6,374.22],[2,1.01,15.52]],"ltp":2.3,"tv":15.14,"id":4486603}]}]}
{"op":"mcm","clk":"1008587936","pt":1580637486246,"mc":[{"id":"1.168224425","rc":[{"batb":[[0,1.08,754.84],[1,1.07,435.96],[2,1.06,366.26]],"batl":[[0,1.13,201.19],[1,1.14,785.33]],"ltp":1.14,"tv":515.14,"id":8260126}]}]}
{"op":"mcm","clk":"1008587999","pt":1580637487176,"mc":[{"id":"1.168224425","rc":[{"batb":[[0,1.06,366.26],[1,1.05,1069.56],[2,1.01,15.51]],"ltp":1.14,"tv":515.14,"id":8260126}]}]}
{"op":"mcm","clk":"1008588217","pt":1580637490163,"mc":[{"id":"1.168224425","rc":[{"batb":[[0,1.09,1175.88],[1,1.06,366.26],[2,1.05,1069.56]],"batl":[[0,1.11,377.93],[1,1.12,769.83]],"ltp":1.14,"tv":515.14,"id":8260126}]}]}
{"op":"mcm","clk":"1008588283","pt":1580637491294,"mc":[{"id":"1.168224425","rc":[{"batb":[[0,1.06,366.26],[1,1.05,1069.56],[2,1.01,15.51]],"ltp":1.14,"tv":515.14,"id":8260126}]}]}
{"op":"mcm","clk":"1008588507","pt":1580637494481,"mc":[{"id":"1.168224425","rc":[{"batb":[[0,1.08,754.84],[1,1.07,435.96],[2,1.06,366.26]],"batl":[[0,1.13,201.19],[1,1.14,785.33]],"ltp":1.14,"tv":515.14,"id":8260126}]}]}
{"op":"mcm","clk":"1008588986","pt":1580637502349,"mc":[{"id":"1.168224425","rc":[{"batl":[[0,1.1,1165.19],[1,1.11,42.01]],"ltp":1.14,"tv":515.14,"id":8260126},{"batb":[[0,9.8,4.2],[1,7.8,9.21],[2,3.6,374.22]],"batl":[[0,13,3.36]],"ltp":2.3,"tv":15.14,"id":4486603}]}]}
{"op":"mcm","clk":"1008589019","pt":1580637502975,"mc":[{"id":"1.168224425","rc":[{"batb":[[0,11,10.23],[1,9.8,4.2],[2,9.6,14.71]],"ltp":2.3,"tv":15.14,"id":4486603}]}]}
{"op":"mcm","clk":"1008589438","pt":1580637509869,"mc":[{"id":"1.168224425","rc":[{"trd":[[1.08,223.5]],"batb":[[0,1.08,643.09]],"ltp":1.08,"tv":738.64,"id":8260126}],"tv":753.78}]}
{"op":"mcm","clk":"1008589650","pt":1580637513281,"mc":[{"id":"1.168224425","rc":[{"batb":[[0,1.08,713.91],[1,1.07,477.27]],"ltp":1.08,"tv":738.64,"id":8260126}]}]}
{"op":"mcm","clk":"1008590093","pt":1580637519409,"mc":[{"id":"1.168224425","rc":[{"batb":[[0,1.07,477.27],[1,1.06,366.26],[2,1.04,1263]],"ltp":1.08,"tv":738.64,"id":8260126},{"batb":[[0,9.6,14.71],[1,3.6,374.22],[2,1.01,15.52]],"ltp":2.3,"tv":15.14,"id":4486603}]}]}
{"op":"mcm","clk":"1008590271","pt":1580637522384,"mc":[{"id":"1.168224425","rc":[{"batb":[[0,1.07,1197.86]],"batl":[[0,1.11,989.95]],"ltp":1.08,"tv":738.64,"id":8260126}]}]}
{"op":"mcm","clk":"1008590316","pt":1580637523214,"mc":[{"id":"1.168224425","rc":[{"batb":[[0,1.07,477.27]],"ltp":1.08,"tv":738.64,"id":8260126}]}]}
{"op":"mcm","clk":"1008590536","pt":1580637526414,"mc":[{"id":"1.168224425","rc":[{"batb":[[0,1.07,1197.86],[2,1.04,1796.93]],"batl":[[0,1.09,771.19],[1,1.1,401.01]],"ltp":1.08,"tv":738.64,"id":8260126},{"batb":[[0,12,8.5],[1,10.5,15.37],[2,3.6,374.22]],"ltp":2.3,"tv":15.14,"id":4486603}]}]}
{"op":"mcm","clk":"1008592105","pt":1580637550350,"mc":[{"id":"1.168224425","rc":[{"batb":[[0,1.06,366.26],[1,1.04,1796.93],[2,1.01,15.51]],"batl":[[0,1.1,401.01],[1,1.1,0]],"ltp":1.08,"tv":738.64,"id":8260126}]}]}
{"op":"mcm","clk":"1008592176","pt":1580637551430,"mc":[{"id":"1.168224425","rc":[{"batb":[[0,1.04,1796.93],[1,1.01,15.51],[2,1.01,0]],"ltp":1.08,"tv":738.64,"id":8260126},{"batb":[[0,10.5,11.17],[1,3.6,374.22],[2,1.01,15.52]],"ltp":2.3,"tv":15.14,"id":4486603}]}]}
{"op":"mcm","clk":"1008592285","pt":1580637553337,"mc":[{"id":"1.168224425","rc":[{"batb":[[0,1.06,699.13],[1,1.05,514.88],[2,1.04,1796.93]],"batl":[[0,1.1,611.93],[1,1.11,548.28]],"ltp":1.08,"tv":738.64,"id":8260126}]}]}
{"op":"mcm","clk":"1008592322","pt":1580637553854,"mc":[{"id":"1.168224425","rc":[{"batb":[[0,1.04,1796.93],[1,1.01,15.51],[2,1.04,0]],"ltp":1.08,"tv":738.64,"id":8260126}]}]}
{"op":"mcm","clk":"1008592526","pt":1580637556331,"mc":[{"id":"1.168224425","rc":[{"batb":[[0,1.09,168.04],[1,1.08,1186.77],[2,1.05,427.01]],"ltp":1.08,"tv":738.64,"id":8260126},{"batb":[[1,10,13.38],[2,9.8,4.2]],"batl":[[0,12.5,3.36]],"ltp":2.3,"tv":15.14,"id":4486603}]}]}
{"op":"mcm","clk":"1008593175","pt":1580637566356,"mc":[{"id":"1.168224425","rc":[{"batb":[[1,1.05,427.01],[2,1.04,1263]],"batl":[[0,1.11,548.28],[1,1.11,0]],"ltp":1.08,"tv":738.64,"id":8260126},{"batb":[[0,10,13.38],[1,9.8,4.2],[2,3.6,374.22]],"ltp":2.3,"tv":15.14,"id":4486603}]}]}
{"op":"mcm","clk":"1008593241","pt":1580637567452,"mc":[{"id":"1.168224425","rc":[{"batb":[[0,1.05,427.01],[1,1.04,1263],[2,1.01,15.51]],"ltp":1.08,"tv":738.64,"id":8260126},{"batb":[[1,3.6,374.22],[2,1.01,15.52]],"ltp":2.3,"tv":15.14,"id":4486603}]}]}
{"op":"mcm","clk":"1008593253","pt":1580637567671,"mc":[{"id":"1.168224425","rc":[{"batl":[[0,1.11,219.26]],"ltp":1.08,"tv":738.64,"id":8260126}]}]}
{"op":"mcm","clk":"1008593446","pt":1580637570769,"mc":[{"id":"1.168224425","rc":[{"batb":[[0,1.08,1114.59],[1,1.05,427.01],[2,1.04,1263]],"batl":[[0,1.1,943.94],[1,1.11,219.26]],"ltp":1.08,"tv":738.64,"id":8260126}]}]}
{"op":"mcm","clk":"1008593540","pt":1580637572375,"mc":[{"id":"1.168224425","rc":[{"batb":[[0,1.05,427.01],[1,1.04,1263],[2,1.01,15.51]],"batl":[[0,1.11,219.26],[1,1.11,0]],"ltp":1.08,"tv":738.64,"id":8260126}]}]}
{"op":"mcm","clk":"1008593750","pt":1580637575369,"mc":[{"id":"1.168224425","rc":[{"batb":[[0,1.07,1153.7],[1,1.05,427.01],[2,1.04,1263]],"batl":[[0,1.11,710.42],[1,1.12,440.31]],"ltp":1.08,"tv":738.64,"id":8260126}]}]}
{"op":"mcm","clk":"1008594751","pt":1580637589958,"mc":[{"id":"1.168224425","rc":[{"batb":[[0,1.05,427.01],[1,1.04,1263],[2,1.01,15.51]],"ltp":1.08,"tv":738.64,"id":8260126}]}]}
{"op":"mcm","clk":"1008594828","pt":1580637591406,"mc":[{"id":"1.168224425","rc":[{"batb":[[1,1.01,15.51],[2,1.01,0]],"ltp":1.08,"tv":738.64,"id":8260126}]}]}
{"op":"mcm","clk":"1008594938","pt":1580637593313,"mc":[{"id":"1.168224425","rc":[{"batb":[[0,1.09,1085.51],[1,1.07,312.52],[2,1.06,1170.37]],"ltp":1.08,"tv":738.64,"id":8260126},{"batb":[[1,9.6,15.03],[2,3.6,374.22]],"ltp":2.3,"tv":15.14,"id":4486603}]}]}
{"op":"mcm","clk":"1008595005","pt":1580637594400,"mc":[{"id":"1.168224425","rc":[{"batb":[[2,1.06,358.63]],"batl":[[2,1.13,42.01]],"ltp":1.08,"tv":738.64,"id":8260126},{"batb":[[2,9,5.04]],"batl":[[0,11,4.2]],"ltp":2.3,"tv":15.14,"id":4486603}]}]}
{"op":"mcm","clk":"1008595242","pt":1580637597290,"mc":[{"id":"1.168224425","rc":[{"batb":[[1,1.06,358.63],[2,1.05,1069.56]],"ltp":1.08,"tv":738.64,"id":8260126},{"batb":[[0,9.6,15.03],[1,9,5.04],[2,3.6,374.22]],"ltp":2.3,"tv":15.14,"id":4486603}]}]}
{"op":"mcm","clk":"1008596563","pt":1580637612327,"mc":[{"id":"1.168224425","rc":[{"batb":[[0,1.06,358.63],[1,1.05,1069.56],[2,1.01,15.51]],"batl":[[0,1.12,440.31],[1,1.13,42.01],[2,1.13,0]],"ltp":1.08,"tv":738.64,"id":8260126}]}]}
{"op":"mcm","clk":"1008596624","pt":1580637613519,"mc":[{"id":"1.168224425","rc":[{"batl":[[1,1.13,0]],"ltp":1.08,"tv":738.64,"id":8260126},{"batb":[[1,3.6,374.22],[2,1.01,15.52]],"ltp":2.3,"tv":15.14,"id":4486603}]}]}
{"op":"mcm","clk":"1008596721","pt":1580637615219,"mc":[{"id":"1.168224425","rc":[{"batb":[[0,1.08,1186.77],[1,1.06,358.63],[2,1.05,1069.56]],"batl":[[0,1.12,1068.88]],"ltp":1.08,"tv":738.64,"id":8260126}]}]}
{"op":"mcm","clk":"1008597005","pt":1580637619402,"mc":[{"id":"1.168224425","rc":[{"batb":[[0,1.06,358.63],[1,1.05,1069.56],[2,1.01,15.51]],"ltp":1.08,"tv":738.64,"id":8260126}]}]}
{"op":"mcm","clk":"1008597236","pt":1580637622441,"mc":[{"id":"1.168224425","rc":[{"batb":[[0,1.1,411.69],[1,1.09,760.41],[2,1.07,312.21]],"ltp":1.08,"tv":738.64,"id":8260126},{"batb":[[1,9.2,15.82],[2,8.6,5.04]],"batl":[[0,10.5,4.2]],"ltp":2.3,"tv":15.14,"id":4486603}]}]}
{"op":"mcm","clk":"1008598085","pt":1580637632929,"mc":[{"id":"1.168224425","rc":[{"batb":[[0,1.09,760.41],[1,1.07,312.21],[2,1.05,1069.56]],"batl":[[0,1.12,814.89]],"ltp":1.08,"tv":738.64,"id":8260126},{"batb":[[0,9.2,15.82],[1,8.6,5.04],[2,3.6,374.22]],"ltp":2.3,"tv":15.14,"id":4486603}]}]}
{"op":"mcm","clk":"1008598125","pt":1580637633546,"mc":[{"id":"1.168224425","rc":[{"batb":[[1,3.6,374.22],[2,1.01,15.52]],"ltp":2.3,"tv":15.14,"id":4486603}]}]}
{"op":"mcm","clk":"1008598322","pt":1580637636341,"mc":[{"id":"1.168224425","rc":[{"batb":[[0,1.09,1167.77]],"batl":[[1,1.13,326.57]],"ltp":1.08,"tv":738.64,"id":8260126}]}]}
{"op":"mcm","clk":"1008598355","pt":1580637637164,"mc":[{"id":"1.168224425","rc":[{"batb":[[0,1.09,1106.19]],"batl":[[1,1.13,267.01]],"ltp":1.08,"tv":738.64,"id":8260126}]}]}
{"op":"mcm","clk":"1008598413","pt":1580637637982,"mc":[{"id":"1.168224425","rc":[{"batb":[[0,1.09,520.08]],"ltp":1.08,"tv":738.64,"id":8260126}]}]}
{"op":"mcm","clk":"1008598485","pt":1580637639081,"mc":[{"id":"1.168224425","rc":[{"batb":[[2,1.01,15.51]],"ltp":1.08,"tv":738.64,"id":8260126}]}]}
{"op":"mcm","clk":"1008598583","pt":1580637640271,"mc":[{"id":"1.168224425","rc":[{"batl":[[0,1.12,874.98]],"ltp":1.08,"tv":738.64,"id":8260126}]}]}
{"op":"mcm","clk":"1008598651","pt":1580637641303,"mc":[{"id":"1.168224425","rc":[{"batb":[[0,1.1,649.83],[1,1.09,520.08],[2,1.08,283.41]],"ltp":1.08,"tv":738.64,"id":8260126},{"batb":[[1,6,17.15],[2,3.6,374.22]],"ltp":2.3,"tv":15.14,"id":4486603}]}]}
{"op":"mcm","clk":"1008598803","pt":1580637643267,"mc":[{"id":"1.168224425","rc":[{"batb":[[0,1.11,168.04],[1,1.1,649.83],[2,1.09,520.08]],"batl":[[2,1.14,42.01]],"ltp":1.08,"tv":738.64,"id":8260126},{"batb":[[1,8.2,5.04],[2,6,17.15]],"batl":[[0,10,4.2]],"ltp":2.3,"tv":15.14,"id":4486603}]}]}
{"op":"mcm","clk":"1008599672","pt":1580637654804,"mc":[{"id":"1.168224425","rc":[{"trd":[[1.11,6.06]],"batb":[[0,1.11,165.01]],"ltp":1.11,"tv":744.7,"id":8260126}],"tv":759.84}]}
{"op":"mcm","clk":"1008604674","pt":1580637725093,"mc":[{"id":"1.168224425","rc":[{"batb":[[1,1.06,955.61],[2,1.05,410.4]],"batl":[[0,1.14,42.01],[1,1.13,0],[2,1.14,0]],"ltp":1.11,"tv":744.7,"id":8260126},{"batb":[[0,8.2,5.04],[1,6,17.15],[2,3.6,374.22]],"ltp":2.3,"tv":15.14,"id":4486603}]}]}
{"op":"mcm","clk":"1008604730","pt":1580637725820,"mc":[{"id":"1.168224425","rc":[{"batb":[[0,1.06,955.61],[1,1.05,410.4],[2,1.01,15.51]],"ltp":1.11,"tv":744.7,"id":8260126},{"batb":[[0,6,17.15],[1,3.6,374.22],[2,1.01,15.52]],"ltp":2.3,"tv":15.14,"id":4486603}]}]}
{"op":"mcm","clk":"1008604950","pt":1580637728234,"mc":[{"id":"1.168224425","rc":[{"batb":[[0,1.07,1193.58],[1,1.06,955.61],[2,1.05,410.4]],"batl":[[0,1.19,483.25],[1,1.2,519.77]],"ltp":1.11,"tv":744.7,"id":8260126}]}]}
{"op":"mcm","clk":"1008605268","pt":1580637731534,"mc":[{"id":"1.168224425","rc":[{"batb":[[1,1.05,410.4],[2,1.01,15.51]],"ltp":1.11,"tv":744.7,"id":8260126}]}]}
{"op":"mcm","clk":"1008605377","pt":1580637733089,"mc":[{"id":"1.168224425","rc":[{"batl":[[0,1.09,1175.88]],"ltp":1.11,"tv":744.7,"id":8260126}]}]}
{"op":"mcm","clk":"1008605443","pt":1580637733930,"mc":[{"id":"1.168224425","rc":[{"batb":[[2,1.04,582.88]],"ltp":1.11,"tv":744.7,"id":8260126},{"batb":[[0,12,8.42],[1,8.2,8.5],[2,3.6,374.22]],"ltp":2.3,"tv":15.14,"id":4486603}]}]}
{"op":"mcm","clk":"1008605581","pt":1580637735402,"mc":[{"id":"1.168224425","rc":[{"batb":[[0,1.08,168.04],[1,1.07,1193.58],[2,1.05,410.4]],"ltp":1.11,"tv":744.7,"id":8260126},{"batb":[[1,10.5,4.2],[2,8.2,8.5]],"batl":[[0,13.5,3.36]],"ltp":2.3,"tv":15.14,"id":4486603}]}]}
{"op":"mcm","clk":"1008606035","pt":1580637741366,"mc":[{"id":"1.168224425","rc":[{"batb":[[1,1.05,410.4],[2,1.04,582.88]],"ltp":1.11,"tv":744.7,"id":8260126}]}]}
{"op":"mcm","clk":"1008606094","pt":1580637742220,"mc":[{"id":"1.168224425","rc":[{"batb":[[0,1.04,582.88],[1,1.03,1571.88],[2,1.01,15.51]],"ltp":1.11,"tv":744.7,"id":8260126},{"batb":[[0,8.2,8.5],[1,3.6,374.22],[2,1.01,15.52]],"ltp":2.3,"tv":15.14,"id":4486603}]}]}
{"op":"mcm","clk":"1008606145","pt":1580637742947,"mc":[{"id":"1.168224425","rc":[{"batl":[[0,1.07,300]],"ltp":1.11,"tv":744.7,"id":8260126}]}]}
{"op":"mcm","clk":"1008606222","pt":1580637744357,"mc":[{"id":"1.168224425","rc":[{"batb":[[0,1.05,1220.68],[1,1.04,582.88],[2,1.03,1571.88]],"batl":[[1,1.13,270.01],[2,1.14,788.83]],"ltp":1.11,"tv":744.7,"id":8260126}]}]}
{"op":"mcm","clk":"1008606351","pt":1580637746450,"mc":[{"id":"1.168224425","rc":[{"batl":[[1,1.13,0],[2,1.14,0]],"ltp":1.11,"tv":744.7,"id":8260126}]}]}
{"op":"mcm","clk":"1008606437","pt":1580637747654,"mc":[{"id":"1.168224425","rc":[{"batb":[[2,1.01,15.51]],"ltp":1.11,"tv":744.7,"id":8260126}]}]}
{"op":"mcm","clk":"1008606560","pt":1580637749271,"mc":[{"id":"1.168224425","rc":[{"batl":[[0,1.07,1497.86]],"ltp":1.11,"tv":744.7,"id":8260126}]}]}
{"op":"mcm","clk":"1008606653","pt":1580637750060,"mc":[{"id":"1.168224425","rc":[{"batb":[[2,1.02,766.36]],"ltp":1.11,"tv":744.7,"id":8260126},{"batb":[[0,15.5,4.56],[1,11,10.07],[2,3.6,374.22]],"ltp":2.3,"tv":15.14,"id":4486603}]}]}
{"op":"mcm","clk":"1008606691","pt":1580637750532,"mc":[{"id":"1.168224425","rc":[{"batb":[[0,1.06,168.04],[1,1.05,1220.68],[2,1.04,582.88]],"batl":[[1,1.08,42.01]],"ltp":1.11,"tv":744.7,"id":8260126},{"batb":[[1,13,3.36],[2,11,10.07]],"ltp":2.3,"tv":15.14,"id":4486603}]}]}
{"op":"mcm","clk":"1008607451","pt":1580637761355,"mc":[{"id":"1.168224425","rc":[{"batb":[[1,1.04,582.88],[2,1.02,2950.44]],"batl":[[0,1.07,300]],"ltp":1.11,"tv":744.7,"id":8260126}]}]}
{"op":"mcm","clk":"1008607473","pt":1580637761671,"mc":[{"id":"1.168224425","rc":[{"batb":[[0,1.02,2950.44],[1,1.01,15.51],[2,1.02,0]],"batl":[[1,1.08,0]],"ltp":1.11,"tv":744.7,"id":8260126},{"batb":[[0,11,10.07],[1,3.6,374.22],[2,1.01,15.52]],"ltp":2.3,"tv":15.14,"id":4486603}]}]}
{"op":"mcm","clk":"1008607661","pt":1580637764378,"mc":[{"id":"1.168224425","rc":[{"batb":[[0,1.04,1232.42],[1,1.02,2950.44],[2,1.01,15.51]],"batl":[[1,1.09,605.27],[2,1.1,565.42]],"ltp":1.11,"tv":744.7,"id":8260126}]}]}
{"op":"mcm","clk":"1008608217","pt":1580637773268,"mc":[{"id":"1.168224425","rc":[{"batb":[[0,1.02,2950.44],[1,1.01,15.51],[2,1.01,0]],"ltp":1.11,"tv":744.7,"id":8260126}]}]}
{"op":"mcm","clk":"1008608337","pt":1580637775391,"mc":[{"id":"1.168224425","rc":[{"batb":[[0,1.02,766.36]],"ltp":1.11,"tv":744.7,"id":8260126}]}]}
{"op":"mcm","clk":"1008608392","pt":1580637776382,"mc":[{"id":"1.168224425","rc":[{"trd":[[1.07,600]],"batb":[[0,1.07,896.14],[1,1.06,369.96],[2,1.04,568.32]],"batl":[[0,1.09,605.27],[1,1.1,458.39],[2,1.1,0]],"ltp":1.07,"tv":1344.7,"id":8260126},{"batb":[[1,7,11.88],[2,3.6,374.22]],"ltp":2.3,"tv":15.14,"id":4486603}],"tv":1359.84}]}
{"op":"mcm","clk":"1008608425","pt":1580637776960,"mc":[{"id":"1.168224425","rc":[{"batb":[[1,10.5,4.2],[2,7,11.88]],"ltp":2.3,"tv":15.14,"id":4486603}]}]}
{"op":"mcm","clk":"1008608578","pt":1580637779077,"mc":[{"id":"1.168224425","rc":[{"batb":[[0,1.08,168.04],[1,1.07,1197.86],[2,1.06,369.96]],"batl":[[0,1.09,713.28],[2,1.11,42.01]],"ltp":1.07,"tv":1344.7,"id":8260126},{"batl":[[0,13.5,3.36]],"ltp":2.3,"tv":15.14,"id":4486603}]}]}
{"op":"mcm","clk":"1008609820","pt":1580637793428,"mc":[{"id":"1.168224425","rc":[{"batb":[[1,1.04,1831.32],[2,1.01,15.51]],"batl":[[0,1.11,42.01],[1,1.1,0],[2,1.11,0]],"ltp":1.07,"tv":1344.7,"id":8260126},{"batb":[[0,10.5,4.2],[1,7,11.88],[2,3.6,374.22]],"ltp":2.3,"tv":15.14,"id":4486603}]}]}
{"op":"mcm","clk":"1008609837","pt":1580637793692,"mc":[{"id":"1.168224425","rc":[{"batb":[[0,1.04,1831.32],[1,1.01,15.51],[2,1.01,0]],"ltp":1.07,"tv":1344.7,"id":8260126},{"batb":[[0,7,11.88],[1,3.6,374.22],[2,1.01,15.52]],"ltp":2.3,"tv":15.14,"id":4486603}]}]}
{"op":"mcm","clk":"1008610185","pt":1580637798211,"mc":[{"id":"1.168224425","rc":[{"batb":[[0,1.09,189.41],[1,1.08,995.61],[2,1.04,1831.32]],"batl":[[0,1.1,466.76],[1,1.11,692.13]],"ltp":1.07,"tv":1344.7,"id":8260126}]}]}
{"op":"mcm","clk":"1008610436","pt":1580637801318,"mc":[{"id":"1.168224425","rc":[{"batb":[[0,1.04,1831.32],[1,1.01,15.51],[2,1.04,0]],"ltp":1.07,"tv":1344.7,"id":8260126}]}]}
{"op":"mcm","clk":"1008610591","pt":1580637803447,"mc":[{"id":"1.168224425","rc":[{"batb":[[0,1.05,1220.68],[1,1.04,1831.32],[2,1.01,15.51]],"ltp":1.07,"tv":1344.7,"id":8260126}]}]}
{"op":"mcm","clk":"1008610729","pt":1580637805224,"mc":[{"id":"1.168224425","rc":[{"batb":[[1,1.04,568.32]],"ltp":1.07,"tv":1344.7,"id":8260126}]}]}
{"op":"mcm","clk":"1008610811","pt":1580637806445,"mc":[{"id":"1.168224425","rc":[{"batb":[[2,1.03,731.27]],"batl":[[0,1.06,211.32],[1,1.07,988.52]],"ltp":1.07,"tv":1344.7,"id":8260126},{"batb":[[0,15.5,4.8],[1,11,10.23],[2,7,11.88]],"ltp":2.3,"tv":15.14,"id":4486603}]}]}
{"op":"mcm","clk":"1008610825","pt":1580637806653,"mc":[{"id":"1.168224425","rc":[{"batb":[[2,3.6,374.22]],"ltp":2.3,"tv":15.14,"id":4486603}]}]}
{"op":"mcm","clk":"1008611885","pt":1580637819077,"mc":[{"id":"1.168224425","rc":[{"batb":[[0,1.03,731.27],[1,1.02,2184.08],[2,1.01,15.51]],"ltp":1.07,"tv":1344.7,"id":8260126},{"batb":[[0,11,10.23],[1,3.6,374.22],[2,1.01,15.52]],"ltp":2.3,"tv":15.14,"id":4486603}]}]}
{"op":"mcm","clk":"1008612070","pt":1580637821465,"mc":[{"id":"1.168224425","rc":[{"batb":[[0,1.04,1232.42],[1,1.03,731.27],[2,1.02,2184.08]],"batl":[[0,1.09,1107.26]],"ltp":1.07,"tv":1344.7,"id":8260126}]}]}
{"op":"mcm","clk":"1008612253","pt":1580637823392,"mc":[{"id":"1.168224425","rc":[{"batb":[[2,1.01,15.51]],"ltp":1.07,"tv":1344.7,"id":8260126},{"batb":[[1,1.01,15.52],[2,1.01,0]],"ltp":2.3,"tv":15.14,"id":4486603}]}]}
{"op":"mcm","clk":"1008612421","pt":1580637825453,"mc":[{"id":"1.168224425","rc":[{"batl":[[0,1.05,228.57],[1,1.06,980.69]],"ltp":1.07,"tv":1344.7,"id":8260126}]}]}
{"op":"mcm","clk":"1008612478","pt":1580637826282,"mc":[{"id":"1.168224425","rc":[{"batb":[[1,1.02,975.97]],"ltp":1.07,"tv":1344.7,"id":8260126},{"batb":[[0,18.5,6.37],[1,17,7.87],[2,1.01,15.52]],"ltp":2.3,"tv":15.14,"id":4486603}]}]}
{"op":"mcm","clk":"1008612643","pt":1580637828373,"mc":[{"id":"1.168224425","rc":[{"batb":[[2,1.01,4081.97]],"ltp":1.07,"tv":1344.7,"id":8260126},{"batb":[[2,4.1,374.13]],"ltp":2.3,"tv":15.14,"id":4486603}]}]}
{"op":"mcm","clk":"1008614021","pt":1580637847310,"mc":[{"id":"1.168224425","rc":[{"batb":[[0,1.02,975.97],[1,1.01,4081.97],[2,1.01,0]],"batl":[[0,1.06,980.69],[1,1.06,0]],"ltp":1.07,"tv":1344.7,"id":8260126},{"batb":[[0,17,7.87],[1,4.1,374.13],[2,1.01,15.52]],"ltp":2.3,"tv":15.14,"id":4486603}]}]}
{"op":"mcm","clk":"1008614257","pt":1580637850374,"mc":[{"id":"1.168224425","rc":[{"batb":[[0,1.03,1242.27],[1,1.02,975.97],[2,1.01,4081.97]],"batl":[[1,1.07,205.69]],"ltp":1.07,"tv":1344.7,"id":8260126}]}]}
{"op":"mcm","clk":"1008614394","pt":1580637852289,"mc":[{"id":"1.168224425","rc":[{"batb":[[0,1.02,975.97],[1,1.01,4081.97],[2,1.01,0]],"batl":[[0,1.06,484.59],[1,1.07,0]],"ltp":1.07,"tv":1344.7,"id":8260126}]}]}
{"op":"mcm","clk":"1008614628","pt":1580637855194,"mc":[{"id":"1.168224425","rc":[{"batb":[[0,1.04,1230.32],[1,1.02,975.97],[2,1.01,4081.97]],"batl":[[0,1.05,729.4],[1,1.06,484.59]],"ltp":1.07,"tv":1344.7,"id":8260126}]}]}
{"op":"mcm","clk":"1008614694","pt":1580637855976,"mc":[{"id":"1.168224425","rc":[{"batb":[[0,1.02,975.97],[1,1.01,4081.97],[2,1.01,0]],"batl":[[0,1.06,484.59],[1,1.06,0]],"ltp":1.07,"tv":1344.7,"id":8260126}]}]}
{"op":"mcm","clk":"1008614960","pt":1580637859082,"mc":[{"id":"1.168224425","rc":[{"batb":[[0,1.03,1242.27],[1,1.02,975.97],[2,1.01,4081.97]],"batl":[[0,1.06,999.47],[1,1.07,205.69]],"ltp":1.07,"tv":1344.7,"id":8260126}]}]}
{"op":"mcm","clk":"1008615158","pt":1580637861685,"mc":[{"id":"1.168224425","rc":[{"batb":[[2,1.01,15.51]],"ltp":1.07,"tv":1344.7,"id":8260126}]}]}
{"op":"mcm","clk":"1008615310","pt":1580637863399,"mc":[{"id":"1.168224425","rc":[{"batl":[[0,1.04,365.54],[1,1.05,856.54]],"ltp":1.07,"tv":1344.7,"id":8260126}]}]}
{"op":"mcm","clk":"1008615397","pt":1580637864387,"mc":[{"id":"1.168224425","rc":[{"batb":[[1,1.01,15.51],[2,1.01,0]],"ltp":1.07,"tv":1344.7,"id":8260126},{"batb":[[0,22,3.54],[1,19.5,5.67],[2,4.1,374.13]],"ltp":2.3,"tv":15.14,"id":4486603}]}]}
{"op":"mcm","clk":"1008615419","pt":1580637864697,"mc":[{"id":"1.168224425","rc":[{"batl":[[1,1.05,898.55]],"ltp":1.07,"tv":1344.7,"id":8260126}]}]}
{"op":"mcm","clk":"1008615525","pt":1580637866101,"mc":[{"id":"1.168224425","rc":[{"batb":[[1,1.01,3892.94]],"ltp":1.07,"tv":1344.7,"id":8260126}]}]}
{"op":"mcm","clk":"1008616127","pt":1580637873426,"mc":[{"id":"1.168224425","rc":[{"batb":[[0,1.01,3892.94],[1,1.01,0]],"batl":[[0,1.05,785.55],[1,1.05,0]],"ltp":1.07,"tv":1344.7,"id":8260126},{"batb":[[0,19.5,5.67],[1,4.1,374.13],[2,1.01,15.52]],"ltp":2.3,"tv":15.14,"id":4486603}]}]}
{"op":"mcm","clk":"1008616141","pt":1580637873636,"mc":[{"id":"1.168224425","rc":[{"batl":[[0,1.05,743.54]],"ltp":1.07,"tv":1344.7,"id":8260126}]}]}
{"op":"mcm","clk":"1008616344","pt":1580637876442,"mc":[{"id":"1.168224425","rc":[{"batb":[[0,1.02,1254.45],[1,1.01,3892.94]],"batl":[[1,1.06,470.58]],"ltp":1.07,"tv":1344.7,"id":8260126}]}]}
{"op":"mcm","clk":"1008617183","pt":1580637887436,"mc":[{"id":"1.168224425","rc":[{"batb":[[0,1.01,3892.94],[1,1.01,0]],"ltp":1.07,"tv":1344.7,"id":8260126}]}]}
{"op":"mcm","clk":"1008617312","pt":1580637889041,"mc":[{"id":"1.168224425","rc":[{"batb":[[0,1.01,15.51]],"ltp":1.07,"tv":1344.7,"id":8260126}]}]}
{"op":"mcm","clk":"1008617414","pt":1580637890346,"mc":[{"id":"1.168224425","rc":[{"batb":[[0,1.04,1230.32],[1,1.01,15.51]],"ltp":1.07,"tv":1344.7,"id":8260126}]}]}
{"op":"mcm","clk":"1008617482","pt":1580637891125,"mc":[{"id":"1.168224425","rc":[{"batb":[[1,1.02,786.82],[2,1.01,15.51]],"batl":[[1,1.06,512.59]],"ltp":1.07,"tv":1344.7,"id":8260126},{"batb":[[1,17,7.55],[2,4.1,374.13]],"ltp":2.3,"tv":15.14,"id":4486603}]}]}
{"op":"mcm","clk":"1008617632","pt":1580637893247,"mc":[{"id":"1.168224425","rc":[{"batb":[[2,1.01,4081.97]],"ltp":1.07,"tv":1344.7,"id":8260126}]}]}
{"op":"mcm","clk":"1008618246","pt":1580637901401,"mc":[{"id":"1.168224425","rc":[{"batb":[[0,1.01,4081.97],[1,1.02,0],[2,1.01,0]],"batl":[[0,1.06,512.59],[1,1.06,0]],"ltp":1.07,"tv":1344.7,"id":8260126},{"batb":[[0,17,7.55],[1,4.1,374.13],[2,1.01,15.52]],"ltp":2.3,"tv":15.14,"id":4486603}]}]}
{"op":"mcm","clk":"1008618288","pt":1580637901772,"mc":[{"id":"1.168224425","rc":[{"batl":[[0,1.06,470.58]],"ltp":1.07,"tv":1344.7,"id":8260126}]}]}
{"op":"mcm","clk":"1008618548","pt":1580637904277,"mc":[{"id":"1.168224425","rc":[{"batl":[[0,1.06,1116.92]],"ltp":1.07,"tv":1344.7,"id":8260126}]}]}
{"op":"mcm","clk":"1008618820","pt":1580637907179,"mc":[{"id":"1.168224425","rc":[{"batb":[[0,1.05,625.62],[1,1.04,768.34],[2,1.03,661.79]],"batl":[[1,1.07,42.01]],"ltp":1.07,"tv":1344.7,"id":8260126},{"batb":[[1,16,4.56],[2,4.1,374.13]],"ltp":2.3,"tv":15.14,"id":4486603}]}]}
{"op":"mcm","clk":"1008619778","pt":1580637917293,"mc":[{"id":"1.168224425","rc":[{"batb":[[0,1.05,168.04],[2,1.02,834.19]],"batl":[[0,1.07,42.01],[1,1.07,0]],"ltp":1.07,"tv":1344.7,"id":8260126},{"batb":[[0,16,4.56],[1,4.1,374.13],[2,1.01,15.52]],"ltp":2.3,"tv":15.14,"id":4486603}]}]}
{"op":"mcm","clk":"1008619819","pt":1580637917711,"mc":[{"id":"1.168224425","rc":[{"batb":[[0,1.04,768.34],[1,1.02,834.19],[2,1.01,4081.97]],"ltp":1.07,"tv":1344.7,"id":8260126}]}]}
{"op":"mcm","clk":"1008620060","pt":1580637920314,"mc":[{"id":"1.168224425","rc":[{"batb":[[0,1.04,826.73]],"ltp":1.07,"tv":1344.7,"id":8260126}]}]}
{"op":"mcm","clk":"1008620336","pt":1580637923391,"mc":[{"id":"1.168224425","rc":[{"batb":[[0,1.04,1230.32]],"batl":[[0,1.06,1207.11]],"ltp":1.07,"tv":1344.7,"id":8260126}]}]}
{"op":"mcm","clk":"1008620577","pt":1580637925897,"mc":[{"id":"1.168224425","rc":[{"batb":[[0,1.04,826.73]],"ltp":1.07,"tv":1344.7,"id":8260126}]}]}
{"op":"mcm","clk":"1008620884","pt":1580637929429,"mc":[{"id":"1.168224425","rc":[{"batb":[[1,1.03,407.51],[2,1.02,834.19]],"batl":[[0,1.07,1195.83]],"ltp":1.07,"tv":1344.7,"id":8260126}]}]}
{"op":"mcm","clk":"1008621527","pt":1580637936347,"mc":[{"id":"1.168224425","rc":[{"batl":[[0,1.05,1218.61]],"ltp":1.07,"tv":1344.7,"id":8260126},{"batb":[[0,20,5.11],[1,17,7.71],[2,16,4.56]],"ltp":2.3,"tv":15.14,"id":4486603}]}]}
{"op":"mcm","clk":"1008621557","pt":1580637936731,"mc":[{"id":"1.168224425","rc":[{"batb":[[0,1.04,994.77]],"batl":[[1,1.06,42.01]],"ltp":1.07,"tv":1344.7,"id":8260126},{"batb":[[2,4.1,374.13]],"ltp":2.3,"tv":15.14,"id":4486603}]}]}
{"op":"mcm","clk":"1008622580","pt":1580637949250,"mc":[{"id":"1.168224425","rc":[{"batb":[[0,1.04,168.04],[1,1.01,3892.94],[2,1.02,0]],"batl":[[0,1.06,42.01],[1,1.06,0]],"ltp":1.07,"tv":1344.7,"id":8260126},{"batb":[[0,17,7.71],[1,4.1,374.13],[2,1.01,15.52]],"ltp":2.3,"tv":15.14,"id":4486603}]}]}
{"op":"mcm","clk":"1008622618","pt":1580637949719,"mc":[{"id":"1.168224425","rc":[{"batb":[[0,1.01,3892.94],[1,1.01,0]],"ltp":1.07,"tv":1344.7,"id":8260126}]}]}
{"op":"mcm","clk":"1008623091","pt":1580637955193,"mc":[{"id":"1.168224425","rc":[{"batb":[[0,1.03,1242.27],[1,1.01,3892.94]],"batl":[[0,1.05,1218.61]],"ltp":1.07,"tv":1344.7,"id":8260126}]}]}
{"op":"mcm","clk":"1008623333","pt":1580637958305,"mc":[{"id":"1.168224425","rc":[{"batb":[[0,1.01,3892.94],[1,1.01,0]],"ltp":1.07,"tv":1344.7,"id":8260126}]}]}
{"op":"mcm","clk":"1008623452","pt":1580637959810,"mc":[{"id":"1.168224425","rc":[{"batb":[[0,1.01,15.51]],"ltp":1.07,"tv":1344.7,"id":8260126},{"batb":[[1,1.01,15.52],[2,1.01,0]],"ltp":2.3,"tv":15.14,"id":4486603}]}]}
{"op":"mcm","clk":"1008623577","pt":1580637961323,"mc":[{"id":"1.168224425","rc":[{"batb":[[0,1.02,1254.45],[1,1.01,15.51]],"batl":[[0,1.06,955.29],[1,1.07,249.47]],"ltp":1.07,"tv":1344.7,"id":8260126}]}]}
{"op":"mcm","clk":"1008624549","pt":1580637973120,"mc":[{"id":"1.168224425","rc":[{"batl":[[0,1.03,1125.43]],"ltp":1.07,"tv":1344.7,"id":8260126}]}]}
{"op":"mcm","clk":"1008624627","pt":1580637974108,"mc":[{"id":"1.168224425","rc":[{"batb":[[0,20,4.96]],"ltp":2.3,"tv":15.14,"id":4486603}]}]}
{"op":"mcm","clk":"1008624693","pt":1580637975094,"mc":[{"id":"1.168224425","rc":[{"batb":[[1,4.4,369.4],[2,1.01,15.52]],"batl":[[0,520,35.52]],"ltp":2.3,"tv":15.14,"id":4486603}]}]}
{"op":"mcm","clk":"1008625364","pt":1580637983114,"mc":[{"id":"1.168224425","rc":[{"batb":[[0,1.01,15.51],[1,1.01,0]],"ltp":1.07,"tv":1344.7,"id":8260126}]}]}
{"op":"mcm","clk":"1008625440","pt":1580637984149,"mc":[{"id":"1.168224425","rc":[{"batb":[[1,1.01,15.52],[2,1.01,0]],"ltp":2.3,"tv":15.14,"id":4486603}]}]}
{"op":"mcm","clk":"1008625761","pt":1580637988058,"mc":[{"id":"1.168224425","rc":[{"batb":[[0,1.02,425.12],[1,1.01,853.04]],"batl":[[0,1.03,1242.27]],"ltp":1.07,"tv":1344.7,"id":8260126}]}]}
{"op":"mcm","clk":"1008625937","pt":1580637990346,"mc":[{"id":"1.168224425","rc":[{"batb":[[0,1.01,15.51],[1,1.01,0]],"ltp":1.07,"tv":1344.7,"id":8260126},{"batb":[[1,4.5,371.06],[2,1.01,15.52]],"ltp":2.3,"tv":15.14,"id":4486603}]}]}
{"op":"mcm","clk":"1008626080","pt":1580637992343,"mc":[{"id":"1.168224425","rc":[{"batb":[[1,1.01,15.52],[2,1.01,0]],"ltp":2.3,"tv":15.14,"id":4486603}]}]}
{"op":"mcm","clk":"1008626139","pt":1580637993236,"mc":[{"id":"1.168224425","rc":[{"batl":[[0,1.05,1218.61]],"ltp":1.07,"tv":1344.7,"id":8260126}]}]}
{"op":"mcm","clk":"1008626529","pt":1580637998438,"mc":[{"id":"1.168224425","rc":[{"batb":[[0,1.01,15.52],[1,1.01,0]],"ltp":2.3,"tv":15.14,"id":4486603}]}]}
{"op":"mcm","clk":"1008626579","pt":1580637999059,"mc":[{"id":"1.168224425","marketDefinition":{"bspMarket":false,"turnInPlayEnabled":true,"persistenceEnabled":true,"marketBaseRate":5.0,"eventId":"29681737","eventTypeId":"2","numberOfWinners":1,"bettingType":"ODDS","marketType":"SET_WINNER","marketTime":"2020-02-02T09:24:00.000Z","suspendTime":"2020-02-02T09:24:00.000Z","bspReconciled":false,"complete":true,"inPlay":true,"crossMatching":true,"runnersVoidable":false,"numberOfActiveRunners":2,"betDelay":3,"status":"SUSPENDED","runners":[{"status":"ACTIVE","sortPriority":1,"id":8260126,"name":"Guillermo Garcia-Lopez"},{"status":"ACTIVE","sortPriority":2,"id":4486603,"name":"Dustin Brown"}],"regulators":["MR_INT"],"countryCode":"FR","discountAllowed":true,"timezone":"UTC","openDate":"2020-02-02T09:24:00.000Z","version":3148387387,"name":"Set 1 Winner","eventName":"Garcia-Lopez v Brown"}}]}
{"op":"mcm","clk":"1008878525","pt":1580640409295,"mc":[{"id":"1.168224425","tv":0.0}]}
{"op":"mcm","clk":"1008878640","pt":1580640410412,"mc":[{"id":"1.168224425","marketDefinition":{"bspMarket":false,"turnInPlayEnabled":true,"persistenceEnabled":true,"marketBaseRate":5.0,"eventId":"29681737","eventTypeId":"2","numberOfWinners":1,"bettingType":"ODDS","marketType":"SET_WINNER","marketTime":"2020-02-02T09:24:00.000Z","suspendTime":"2020-02-02T09:24:00.000Z","bspReconciled":false,"complete":true,"inPlay":true,"crossMatching":false,"runnersVoidable":false,"numberOfActiveRunners":0,"betDelay":3,"status":"CLOSED","settledTime":"2020-02-02T10:46:47.000Z","runners":[{"status":"WINNER","sortPriority":1,"id":8260126,"name":"Guillermo Garcia-Lopez"},{"status":"LOSER","sortPriority":2,"id":4486603,"name":"Dustin Brown"}],"regulators":["MR_INT"],"countryCode":"FR","discountAllowed":true,"timezone":"UTC","openDate":"2020-02-02T09:24:00.000Z","version":3148437409,"name":"Set 1 Winner","eventName":"Garcia-Lopez v Brown"}}]}
