{"op":"mcm","clk":"1004963113","pt":1580585272153,"mc":[{"id":"1.168224424","marketDefinition":{"bspMarket":false,"turnInPlayEnabled":true,"persistenceEnabled":true,"marketBaseRate":5.0,"eventId":"29681737","eventTypeId":"2","numberOfWinners":1,"bettingType":"ODDS","marketType":"SET_BETTING","marketTime":"2020-02-02T09:30:00.000Z","suspendTime":"2020-02-02T09:30:00.000Z","bspReconciled":false,"complete":true,"inPlay":false,"crossMatching":false,"runnersVoidable":false,"numberOfActiveRunners":4,"betDelay":0,"status":"OPEN","runners":[{"status":"ACTIVE","sortPriority":1,"id":13010314,"name":"Garcia-Lopez 2-0"},{"status":"ACTIVE","sortPriority":2,"id":13010313,"name":"Garcia-Lopez 2-1"},{"status":"ACTIVE","sortPriority":3,"id":16575965,"name":"Brown 2-0"},{"status":"ACTIVE","sortPriority":4,"id":16575966,"name":"Brown 2-1"}],"regulators":["MR_INT"],"countryCode":"FR","discountAllowed":false,"timezone":"UTC","openDate":"2020-02-02T09:30:00.000Z","version":3147098405,"name":"Set Betting","eventName":"Garcia-Lopez v Brown"}}]}
{"op":"mcm","clk":"1004963376","pt":1580585273491,"mc":[{"id":"1.168224424","marketDefinition":{"bspMarket":false,"turnInPlayEnabled":true,"persistenceEnabled":true,"marketBaseRate":5.0,"eventId":"29681737","eventTypeId":"2","numberOfWinners":1,"bettingType":"ODDS","marketType":"SET_BETTING","marketTime":"2020-02-02T09:30:00.000Z","suspendTime":"2020-02-02T09:30:00.000Z","bspReconciled":false,"complete":true,"inPlay":false,"crossMatching":false,"runnersVoidable":false,"numberOfActiveRunners":4,"betDelay":0,"status":"OPEN","runners":[{"status":"ACTIVE","sortPriority":1,"id":13010314,"name":"Garcia-Lopez 2-0"},{"status":"ACTIVE","sortPriority":2,"id":13010313,"name":"Garcia-Lopez 2-1"},{"status":"ACTIVE","sortPriority":3,"id":16575965,"name":"Brown 2-0"},{"status":"ACTIVE","sortPriority":4,"id":16575966,"name":"Brown 2-1"}],"regulators":["MR_INT"],"countryCode":"FR","discountAllowed":false,"timezone":"UTC","openDate":"2020-02-02T09:30:00.000Z","version":3147098405,"name":"Set Betting","eventName":"Garcia-Lopez v Brown"}}]}
{"op":"mcm","clk":"1004963561","pt":1580585274501,"mc":[{"id":"1.168224424","marketDefinition":{"bspMarket":false,"turnInPlayEnabled":true,"persistenceEnabled":true,"marketBaseRate":5.0,"eventId":"29681737","eventTypeId":"2","numberOfWinners":1,"bettingType":"ODDS","marketType":"SET_BETTING","marketTime":"2020-02-02T09:30:00.000Z","suspendTime":"2020-02-02T09:30:00.000Z","bspReconciled":false,"complete":true,"inPlay":false,"crossMatching":false,"runnersVoidable":false,"numberOfActiveRunners":4,"betDelay":0,"status":"OPEN","runners":[{"status":"ACTIVE","sortPriority":1,"id":13010314,"name":"Garcia-Lopez 2-0"},{"status":"ACTIVE","sortPriority":2,"id":13010313,"name":"Garcia-Lopez 2-1"},{"status":"ACTIVE","sortPriority":3,"id":16575965,"name":"Brown 2-0"},{"status":"ACTIVE","sortPriority":4,"id":16575966,"name":"Brown 2-1"}],"regulators":["MR_INT"],"countryCode":"FR","discountAllowed":true,"timezone":"UTC","openDate":"2020-02-02T09:30:00.000Z","version":3147098405,"name":"Set Betting","eventName":"Garcia-Lopez v Brown"}}]}
{"op":"mcm","clk":"1005380027","pt":1580587944375,"mc":[{"id":"1.168224424","rc":[{"batb":[[0,1.02,2]],"ltp":0.0,"tv":0.0,"id":13010313},{"batb":[[0,1.02,2]],"ltp":0.0,"tv":0.0,"id":16575966},{"batb":[[0,1.02,2]],"ltp":0.0,"tv":0.0,"id":16575965},{"batb":[[0,1.02,2]],"ltp":0.0,"tv":0.0,"id":13010314}]}]}
{"op":"mcm","clk":"1006924384","pt":1580602183340,"mc":[{"id":"1.168224424","rc":[{"batb":[[1,1.01,2.53]],"ltp":0.0,"tv":0.0,"id":13010313},{"batb":[[1,1.01,2.53]],"ltp":0.0,"tv":0.0,"id":16575966},{"batb":[[1,1.01,2.53]],"ltp":0.0,"tv":0.0,"id":16575965},{"batb":[[1,1.01,2.53]],"ltp":0.0,"tv":0.0,"id":13010314}]}]}
{"op":"mcm","clk":"1006924495","pt":1580602184378,"mc":[{"id":"1.168224424","rc":[{"batb":[[1,1.01,0.51]],"ltp":0.0,"tv":0.0,"id":13010313},{"batb":[[1,1.01,0.51]],"ltp":0.0,"tv":0.0,"id":16575966},{"batb":[[1,1.01,0.51]],"ltp":0.0,"tv":0.0,"id":16575965},{"batb":[[1,1.01,0.51]],"ltp":0.0,"tv":0.0,"id":13010314}]}]}
{"op":"mcm","clk":"1007043238","pt":1580603723387,"mc":[{"id":"1.168224424","rc":[{"batb":[[1,1.01,3.04]],"ltp":0.0,"tv":0.0,"id":13010313},{"batb":[[1,1.01,3.04]],"ltp":0.0,"tv":0.0,"id":16575966},{"batb":[[1,1.01,3.04]],"ltp":0.0,"tv":0.0,"id":16575965},{"batb":[[1,1.01,3.04]],"ltp":0.0,"tv":0.0,"id":13010314}]}]}
{"op":"mcm","clk":"1007043310","pt":1580603724270,"mc":[{"id":"1.168224424","rc":[{"batb":[[1,1.01,1.01]],"ltp":0.0,"tv":0.0,"id":13010313},{"batb":[[1,1.01,1.01]],"ltp":0.0,"tv":0.0,"id":16575966},{"batb":[[1,1.01,1.01]],"ltp":0.0,"tv":0.0,"id":16575965},{"batb":[[1,1.01,1.01]],"ltp":0.0,"tv":0.0,"id":13010314}]}]}
{"op":"mcm","clk":"1007810898","pt":1580623473591,"mc":[{"id":"1.168224424","rc":[{"batb":[[0,2.06,30.29],[1,1.02,2],[2,1.01,1.01]],"ltp":0.0,"tv":0.0,"id":13010314}]}]}
{"op":"mcm","clk":"1008254289","pt":1580632022263,"mc":[{"id":"1.168224424","rc":[{"trd":[[2.06,2.53]],"batb":[[0,2.06,29.02]],"ltp":2.06,"tv":2.53,"id":13010314}],"tv":2.53}]}
{"op":"mcm","clk":"1008419785","pt":1580634917187,"mc":[{"id":"1.168224424","rc":[{"batb":[[0,1.02,2],[1,1.01,1.01],[2,1.01,0]],"ltp":2.06,"tv":2.53,"id":13010314}]}]}
{"op":"mcm","clk":"1008435276","pt":1580635193091,"mc":[{"id":"1.168224424","rc":[{"batl":[[0,6,7.57]],"ltp":0.0,"tv":0.0,"id":16575966}]}]}
{"op":"mcm","clk":"1008457009","pt":1580635581363,"mc":[{"id":"1.168224424","rc":[{"batb":[[0,4.2,19.51],[1,1.02,2],[2,1.01,1.01]],"batl":[[0,4.9,18.57]],"ltp":0.0,"tv":0.0,"id":13010313},{"trd":[[6,15.15]],"batb":[[0,6,9.97],[1,3.1,3.94],[2,1.02,2]],"batl":[[0,7.2,16.44]],"ltp":6.0,"tv":15.14,"id":16575966},{"batb":[[0,4.7,15.5],[1,1.02,2],[2,1.01,1.01]],"batl":[[0,5.4,14.79]],"ltp":0.0,"tv":0.0,"id":16575965},{"batb":[[0,2.24,20.14],[1,1.02,2],[2,1.01,1.01]],"batl":[[0,2.42,19.67]],"ltp":2.06,"tv":2.53,"id":13010314}],"tv":17.67}]}
{"op":"mcm","clk":"1008457034","pt":1580635581875,"mc":[{"id":"1.168224424","rc":[{"batb":[[1,2.62,6.54],[2,1.02,2]],"ltp":0.0,"tv":0.0,"id":13010313},{"batb":[[1,3.15,4.83],[2,1.02,2]],"ltp":0.0,"tv":0.0,"id":16575965},{"batb":[[1,1.71,5.57],[2,1.02,2]],"ltp":2.06,"tv":2.53,"id":13010314}]}]}
{"op":"mcm","clk":"1008457417","pt":1580635589394,"mc":[{"id":"1.168224424","rc":[{"batb":[[0,4.3,19.43]],"ltp":0.0,"tv":0.0,"id":13010313},{"batb":[[0,5.9,18.1]],"batl":[[0,7,16.92]],"ltp":6.0,"tv":15.14,"id":16575966},{"batb":[[0,2.26,19.99]],"batl":[[0,2.42,19.51]],"ltp":2.06,"tv":2.53,"id":13010314}]}]}
{"op":"mcm","clk":"1008457460","pt":1580635590008,"mc":[{"id":"1.168224424","rc":[{"batb":[[1,3.05,7.29]],"ltp":6.0,"tv":15.14,"id":16575966}]}]}
{"op":"mcm","clk":"1008457832","pt":1580635594297,"mc":[{"id":"1.168224424","marketDefinition":{"bspMarket":false,"turnInPlayEnabled":true,"persistenceEnabled":true,"marketBaseRate":5.0,"eventId":"29681737","eventTypeId":"2","numberOfWinners":1,"bettingType":"ODDS","marketType":"SET_BETTING","marketTime":"2020-02-02T09:30:00.000Z","suspendTime":"2020-02-02T09:30:00.000Z","bspReconciled":false,"complete":true,"inPlay":false,"crossMatching":true,"runnersVoidable":false,"numberOfActiveRunners":4,"betDelay":0,"status":"OPEN","runners":[{"status":"ACTIVE","sortPriority":1,"id":13010314,"name":"Garcia-Lopez 2-0"},{"status":"ACTIVE","sortPriority":2,"id":13010313,"name":"Garcia-Lopez 2-1"},{"status":"ACTIVE","sortPriority":3,"id":16575965,"name":"Brown 2-0"},{"status":"ACTIVE","sortPriority":4,"id":16575966,"name":"Brown 2-1"}],"regulators":["MR_INT"],"countryCode":"FR","discountAllowed":true,"timezone":"UTC","openDate":"2020-02-02T09:30:00.000Z","version":3147125265,"name":"Set Betting","eventName":"Garcia-Lopez v Brown"}}]}
{"op":"mcm","clk":"1008459675","pt":1580635615447,"mc":[{"id":"1.168224424","marketDefinition":{"bspMarket":false,"turnInPlayEnabled":true,"persistenceEnabled":true,"marketBaseRate":5.0,"eventId":"29681737","eventTypeId":"2","numberOfWinners":1,"bettingType":"ODDS","marketType":"SET_BETTING","marketTime":"2020-02-02T09:24:00.000Z","suspendTime":"2020-02-02T09:24:00.000Z","bspReconciled":false,"complete":true,"inPlay":false,"crossMatching":true,"runnersVoidable":false,"numberOfActiveRunners":4,"betDelay":0,"status":"OPEN","runners":[{"status":"ACTIVE","sortPriority":1,"id":13010314,"name":"Garcia-Lopez 2-0"},{"status":"ACTIVE","sortPriority":2,"id":13010313,"name":"Garcia-Lopez 2-1"},{"status":"ACTIVE","sortPriority":3,"id":16575965,"name":"Brown 2-0"},{"status":"ACTIVE","sortPriority":4,"id":16575966,"name":"Brown 2-1"}],"regulators":["MR_INT"],"countryCode":"FR","discountAllowed":true,"timezone":"UTC","openDate":"2020-02-02T09:30:00.000Z","version":3148345635,"name":"Set Betting","eventName":"Garcia-Lopez v Brown"},"rc":[{"batb":[[1,1.02,2],[2,1.01,1.01]],"ltp":0.0,"tv":0.0,"id":13010313},{"batb":[[1,1.02,2],[2,1.01,1.01]],"ltp":6.0,"tv":15.14,"id":16575966},{"batb":[[1,1.02,2],[2,1.01,1.01]],"ltp":0.0,"tv":0.0,"id":16575965},{"batb":[[1,1.02,2],[2,1.01,1.01]],"ltp":2.06,"tv":2.53,"id":13010314}]}]}
{"op":"mcm","clk":"1008459927","pt":1580635617379,"mc":[{"id":"1.168224424","marketDefinition":{"bspMarket":false,"turnInPlayEnabled":true,"persistenceEnabled":true,"marketBaseRate":5.0,"eventId":"29681737","eventTypeId":"2","numberOfWinners":1,"bettingType":"ODDS","marketType":"SET_BETTING","marketTime":"2020-02-02T09:24:00.000Z","suspendTime":"2020-02-02T09:24:00.000Z","bspReconciled":false,"complete":true,"inPlay":false,"crossMatching":true,"runnersVoidable":false,"numberOfActiveRunners":4,"betDelay":0,"status":"OPEN","runners":[{"status":"ACTIVE","sortPriority":1,"id":13010314,"name":"Garcia-Lopez 2-0"},{"status":"ACTIVE","sortPriority":2,"id":13010313,"name":"Garcia-Lopez 2-1"},{"status":"ACTIVE","sortPriority":3,"id":16575965,"name":"Brown 2-0"},{"status":"ACTIVE","sortPriority":4,"id":16575966,"name":"Brown 2-1"}],"regulators":["MR_INT"],"countryCode":"FR","discountAllowed":true,"timezone":"UTC","openDate":"2020-02-02T09:24:00.000Z","version":3148345635,"name":"Set Betting","eventName":"Garcia-Lopez v Brown"}}]}
{"op":"mcm","clk":"1008498146","pt":1580636191054,"mc":[{"id":"1.168224424","rc":[{"batb":[[1,4,13.44],[2,1.02,2]],"batl":[[0,4.8,10.92],[1,4.9,18.57]],"ltp":0.0,"tv":0.0,"id":13010313},{"batb":[[1,5.6,8.4],[2,1.02,2]],"batl":[[0,6.8,6.72],[1,7,16.92]],"ltp":6.0,"tv":15.14,"id":16575966},{"batb":[[0,4.7,26.42]],"batl":[[1,5.8,8.4]],"ltp":0.0,"tv":0.0,"id":16575965},{"batb":[[0,2.26,52.75]],"batl":[[1,2.54,26.89]],"ltp":2.06,"tv":2.53,"id":13010314}]}]}
{"op":"mcm","clk":"1008513889","pt":1580636417273,"mc":[{"id":"1.168224424","marketDefinition":{"bspMarket":false,"turnInPlayEnabled":true,"persistenceEnabled":true,"marketBaseRate":5.0,"eventId":"29681737","eventTypeId":"2","numberOfWinners":1,"bettingType":"ODDS","marketType":"SET_BETTING","marketTime":"2020-02-02T09:24:00.000Z","suspendTime":"2020-02-02T09:24:00.000Z","bspReconciled":false,"complete":true,"inPlay":true,"crossMatching":true,"runnersVoidable":false,"numberOfActiveRunners":4,"betDelay":3,"status":"OPEN","runners":[{"status":"ACTIVE","sortPriority":1,"id":13010314,"name":"Garcia-Lopez 2-0"},{"status":"ACTIVE","sortPriority":2,"id":13010313,"name":"Garcia-Lopez 2-1"},{"status":"ACTIVE","sortPriority":3,"id":16575965,"name":"Brown 2-0"},{"status":"ACTIVE","sortPriority":4,"id":16575966,"name":"Brown 2-1"}],"regulators":["MR_INT"],"countryCode":"FR","discountAllowed":true,"timezone":"UTC","openDate":"2020-02-02T09:24:00.000Z","version":3148353231,"name":"Set Betting","eventName":"Garcia-Lopez v Brown"},"rc":[{"batb":[[0,1.01,0.51],[1,4,0],[2,1.02,0]],"ltp":0.0,"tv":0.0,"id":13010313},{"batb":[[0,1.01,0.51],[1,5.6,0],[2,1.02,0]],"ltp":6.0,"tv":15.14,"id":16575966},{"batb":[[0,1.01,0.51],[1,1.02,0],[2,1.01,0]],"ltp":0.0,"tv":0.0,"id":16575965},{"batb":[[0,1.01,0.51],[1,1.02,0],[2,1.01,0]],"ltp":2.06,"tv":2.53,"id":13010314}]}]}
{"op":"mcm","clk":"1008515567","pt":1580636446220,"mc":[{"id":"1.168224424","rc":[{"batb":[[0,4,51.29],[1,3.95,56.04],[2,1.01,0.51]],"ltp":0.0,"tv":0.0,"id":13010313},{"batb":[[0,5.8,62.87],[1,5.7,47.82],[2,1.01,0.51]],"ltp":6.0,"tv":15.14,"id":16575966},{"batb":[[0,4.7,57.48],[1,4.6,77.7],[2,1.01,0.51]],"ltp":0.0,"tv":0.0,"id":16575965},{"batb":[[0,2.2,160.12],[1,2.18,103.48],[2,1.01,0.51]],"ltp":2.06,"tv":2.53,"id":13010314}]}]}
{"op":"mcm","clk":"1008515813","pt":1580636450435,"mc":[{"id":"1.168224424","rc":[{"batb":[[0,5.8,46.01],[1,1.01,0.51],[2,1.01,0]],"ltp":6.0,"tv":15.14,"id":16575966},{"batb":[[0,1.01,0.51],[1,4.6,0],[2,1.01,0]],"ltp":0.0,"tv":0.0,"id":16575965},{"batb":[[0,1.01,0.51],[1,2.18,0],[2,1.01,0]],"ltp":2.06,"tv":2.53,"id":13010314}]}]}
{"op":"mcm","clk":"1008516015","pt":1580636453342,"mc":[{"id":"1.168224424","rc":[{"batb":[[0,4,142.5]],"ltp":0.0,"tv":0.0,"id":13010313},{"batb":[[0,5.9,62.11],[1,5.8,46.01],[2,1.01,0.51]],"ltp":6.0,"tv":15.14,"id":16575966},{"batb":[[0,5.1,97.96],[1,5,63.65],[2,1.01,0.51]],"ltp":0.0,"tv":0.0,"id":16575965},{"batb":[[0,2.34,166.88],[1,2.3,176.06],[2,1.01,0.51]],"ltp":2.06,"tv":2.53,"id":13010314}]}]}
{"op":"mcm","clk":"1008516048","pt":1580636453852,"mc":[{"id":"1.168224424","rc":[{"batb":[[0,4,51.29]],"ltp":0.0,"tv":0.0,"id":13010313},{"batb":[[0,5.8,46.01],[1,1.01,0.51],[2,1.01,0]],"ltp":6.0,"tv":15.14,"id":16575966},{"batb":[[0,1.01,0.51],[1,5,0],[2,1.01,0]],"ltp":0.0,"tv":0.0,"id":16575965},{"batb":[[0,1.01,0.51],[1,2.3,0],[2,1.01,0]],"ltp":2.06,"tv":2.53,"id":13010314}]}]}
{"op":"mcm","clk":"1008516238","pt":1580636456952,"mc":[{"id":"1.168224424","rc":[{"batb":[[0,5.8,62.87],[1,5.7,47.82],[2,1.01,0.51]],"ltp":6.0,"tv":15.14,"id":16575966},{"batb":[[0,4.7,57.48],[1,4.6,77.7],[2,1.01,0.51]],"ltp":0.0,"tv":0.0,"id":16575965},{"batb":[[0,2.2,160.12],[1,2.18,103.48],[2,1.01,0.51]],"ltp":2.06,"tv":2.53,"id":13010314}]}]}
{"op":"mcm","clk":"1008516902","pt":1580636468443,"mc":[{"id":"1.168224424","rc":[{"batb":[[0,1.01,0.51],[1,2.18,0],[2,1.01,0]],"ltp":2.06,"tv":2.53,"id":13010314}]}]}
{"op":"mcm","clk":"1008517079","pt":1580636471372,"mc":[{"id":"1.168224424","rc":[{"batb":[[0,2.5,150.26],[1,2.46,146.32],[2,1.01,0.51]],"ltp":2.06,"tv":2.53,"id":13010314}]}]}
{"op":"mcm","clk":"1008517139","pt":1580636472141,"mc":[{"id":"1.168224424","rc":[{"batb":[[0,4.2,20.54],[1,4.1,21.32],[2,4,51.29]],"batl":[[0,4.7,10.92],[1,4.8,19.51],[2,4.9,18.25]],"ltp":0.0,"tv":0.0,"id":13010313},{"batb":[[0,5.8,81.52],[2,5.4,9.24]],"batl":[[0,6.8,6.72],[1,7.2,16.6]],"ltp":6.0,"tv":15.14,"id":16575966},{"batb":[[2,4.5,11.76]],"batl":[[0,5,17.62],[1,5.4,9.24],[2,5.6,13.77]],"ltp":0.0,"tv":0.0,"id":16575965},{"batb":[[2,2.38,17.23]],"batl":[[0,2.56,16.84],[1,2.7,39.08]],"ltp":2.06,"tv":2.53,"id":13010314}]}]}
{"op":"mcm","clk":"1008517706","pt":1580636479887,"mc":[{"id":"1.168224424","rc":[{"batb":[[0,4.1,21.32],[1,3.95,56.04],[2,3.9,14.28]],"batl":[[1,4.9,18.25],[2,4.9,0]],"ltp":0.0,"tv":0.0,"id":13010313},{"batb":[[0,5.8,18.65]],"ltp":6.0,"tv":15.14,"id":16575966},{"batb":[[0,4.5,11.76],[1,4.1,21.64],[2,1.01,0.51]],"batl":[[0,5.4,9.24],[1,5.6,13.77],[2,5.6,0]],"ltp":0.0,"tv":0.0,"id":16575965},{"batb":[[0,2.36,30.25],[1,2.22,21.09],[2,1.01,0.51]],"batl":[[0,2.7,39.08],[1,2.7,0]],"ltp":2.06,"tv":2.53,"id":13010314}]}]}
{"op":"mcm","clk":"1008517753","pt":1580636480556,"mc":[{"id":"1.168224424","rc":[{"batb":[[2,1.01,0.51]],"batl":[[0,4.9,18.25],[1,4.9,0]],"ltp":0.0,"tv":0.0,"id":13010313},{"batb":[[2,1.01,0.51]],"batl":[[0,7.2,16.6],[1,7.2,0]],"ltp":6.0,"tv":15.14,"id":16575966},{"batb":[[0,4.1,21.64],[1,1.01,0.51],[2,1.01,0]],"batl":[[0,5.6,13.77],[1,5.6,0]],"ltp":0.0,"tv":0.0,"id":16575965},{"batb":[[0,2.22,21.09],[1,1.01,0.51],[2,1.01,0]],"batl":[[0,2.7,14.71]],"ltp":2.06,"tv":2.53,"id":13010314}]}]}
{"op":"mcm","clk":"1008517896","pt":1580636483179,"mc":[{"id":"1.168224424","rc":[{"batb":[[2,3.9,57.69]],"ltp":0.0,"tv":0.0,"id":13010313},{"batb":[[1,5.7,82.68],[2,5.6,49.46]],"batl":[[0,7,16.68]],"ltp":6.0,"tv":15.14,"id":16575966},{"batb":[[0,4.4,111.05],[1,4.3,89.83],[2,4.1,21.64]],"ltp":0.0,"tv":0.0,"id":16575965},{"batb":[[0,2.34,135.57],[1,2.3,176.21],[2,2.22,21.09]],"ltp":2.06,"tv":2.53,"id":13010314}]}]}
{"op":"mcm","clk":"1008519063","pt":1580636499286,"mc":[{"id":"1.168224424","rc":[{"batb":[[0,2.22,21.09],[1,1.01,0.51],[2,2.22,0]],"ltp":2.06,"tv":2.53,"id":13010314}]}]}
{"op":"mcm","clk":"1008519271","pt":1580636502387,"mc":[{"id":"1.168224424","rc":[{"batb":[[0,2.62,94.48],[1,2.58,129.08],[2,2.22,21.09]],"ltp":2.06,"tv":2.53,"id":13010314}]}]}
{"op":"mcm","clk":"1008519363","pt":1580636503421,"mc":[{"id":"1.168224424","rc":[{"batb":[[2,3.9,71.97]],"batl":[[0,4.7,10.92],[1,4.8,19.36]],"ltp":0.0,"tv":0.0,"id":13010313},{"batb":[[0,5.7,101.96],[1,5.6,49.46],[2,5.4,9.24]],"batl":[[0,6.6,6.72],[1,7,16.68]],"ltp":6.0,"tv":15.14,"id":16575966},{"batb":[[2,4.2,12.6]],"batl":[[0,4.7,20.54],[1,5.1,27]],"ltp":0.0,"tv":0.0,"id":16575965},{"batb":[[2,2.52,15.03]],"batl":[[1,2.78,13.45],[2,2.8,22.69]],"ltp":2.06,"tv":2.53,"id":13010314}]}]}
{"op":"mcm","clk":"1008520490","pt":1580636518534,"mc":[{"id":"1.168224424","rc":[{"batb":[[1,3.9,57.69],[2,1.01,0.51]],"batl":[[0,4.8,19.36],[1,4.8,0]],"ltp":0.0,"tv":0.0,"id":13010313},{"batb":[[0,5.7,77.6],[2,1.01,0.51]],"batl":[[0,7,16.68],[1,7,0]],"ltp":6.0,"tv":15.14,"id":16575966},{"batb":[[0,4.3,61.24],[1,3.95,23.84],[2,1.01,0.51]],"batl":[[0,5.1,16.92],[1,5.1,0]],"ltp":0.0,"tv":0.0,"id":16575965},{"batb":[[0,2.36,17.7],[1,1.01,0.51],[2,2.52,0]],"batl":[[0,2.78,13.45],[1,2.78,0],[2,2.8,0]],"ltp":2.06,"tv":2.53,"id":13010314}]}]}
{"op":"mcm","clk":"1008520697","pt":1580636521433,"mc":[{"id":"1.168224424","rc":[{"batb":[[1,3.9,87.49],[2,3.85,59.23]],"ltp":0.0,"tv":0.0,"id":13010313},{"batb":[[1,1.01,0.51],[2,1.01,0]],"ltp":6.0,"tv":15.14,"id":16575966},{"batb":[[0,4.2,95.72]],"ltp":0.0,"tv":0.0,"id":16575965},{"batb":[[0,2.48,136.03],[1,2.44,149.72],[2,2.36,17.7]],"ltp":2.06,"tv":2.53,"id":13010314}]}]}
{"op":"mcm","clk":"1008520711","pt":1580636521645,"mc":[{"id":"1.168224424","rc":[{"batb":[[1,3.9,57.69],[2,1.01,0.51]],"ltp":0.0,"tv":0.0,"id":13010313},{"batb":[[0,3.95,23.84],[1,1.01,0.51],[2,1.01,0]],"ltp":0.0,"tv":0.0,"id":16575965},{"batb":[[0,2.36,17.7],[1,1.01,0.51],[2,2.36,0]],"ltp":2.06,"tv":2.53,"id":13010314}]}]}
{"op":"mcm","clk":"1008520924","pt":1580636524429,"mc":[{"id":"1.168224424","rc":[{"batb":[[1,3.95,69.48],[2,3.9,57.69]],"ltp":0.0,"tv":0.0,"id":13010313},{"batb":[[0,5.8,40.91],[1,5.7,77.6],[2,1.01,0.51]],"ltp":6.0,"tv":15.14,"id":16575966},{"batb":[[0,4.5,71.92],[1,4.4,85.78],[2,3.95,23.84]],"ltp":0.0,"tv":0.0,"id":16575965},{"batb":[[0,2.58,139.92],[1,2.54,134.3],[2,2.36,17.7]],"ltp":2.06,"tv":2.53,"id":13010314}]}]}
{"op":"mcm","clk":"1008521185","pt":1580636527229,"mc":[{"id":"1.168224424","rc":[{"batb":[[1,3.9,57.69],[2,1.01,0.51]],"ltp":0.0,"tv":0.0,"id":13010313},{"batb":[[0,5.7,77.6],[1,1.01,0.51],[2,1.01,0]],"ltp":6.0,"tv":15.14,"id":16575966},{"batb":[[0,3.95,23.84],[1,1.01,0.51],[2,3.95,0]],"ltp":0.0,"tv":0.0,"id":16575965},{"batb":[[0,2.36,17.7],[1,1.01,0.51],[2,2.36,0]],"ltp":2.06,"tv":2.53,"id":13010314}]}]}
{"op":"mcm","clk":"1008521421","pt":1580636530239,"mc":[{"id":"1.168224424","rc":[{"batb":[[1,3.9,87.49],[2,3.85,59.23]],"ltp":0.0,"tv":0.0,"id":13010313},{"batb":[[1,5.6,49.79],[2,1.01,0.51]],"ltp":6.0,"tv":15.14,"id":16575966},{"batb":[[0,4.3,61.24],[1,4.2,95.72],[2,3.95,23.84]],"ltp":0.0,"tv":0.0,"id":16575965},{"batb":[[0,2.48,136.03],[1,2.44,149.72],[2,2.36,17.7]],"ltp":2.06,"tv":2.53,"id":13010314}]}]}
{"op":"mcm","clk":"1008521757","pt":1580636533951,"mc":[{"id":"1.168224424","rc":[{"batb":[[1,1.01,0.51],[2,3.85,0]],"ltp":0.0,"tv":0.0,"id":13010313},{"batb":[[0,5.7,67.1],[1,1.01,0.51],[2,1.01,0]],"ltp":6.0,"tv":15.14,"id":16575966},{"batb":[[0,3.95,23.84],[1,1.01,0.51],[2,3.95,0]],"ltp":0.0,"tv":0.0,"id":16575965}]}]}
{"op":"mcm","clk":"1008522144","pt":1580636537370,"mc":[{"id":"1.168224424","rc":[{"batb":[[1,4,55.96],[2,3.95,56.01]],"ltp":0.0,"tv":0.0,"id":13010313},{"batb":[[0,5.8,74.23],[1,5.7,67.1],[2,1.01,0.51]],"ltp":6.0,"tv":15.14,"id":16575966},{"batb":[[0,4.7,107.47],[1,4.6,76.86],[2,3.95,23.84]],"ltp":0.0,"tv":0.0,"id":16575965}]}]}
{"op":"mcm","clk":"1008522188","pt":1580636537786,"mc":[{"id":"1.168224424","rc":[{"batb":[[0,4.2,20.3],[1,4.1,21.09],[2,4,55.96]],"batl":[[0,4.7,10.92],[1,4.8,19.36],[2,5,17.7]],"ltp":0.0,"tv":0.0,"id":13010313},{"batb":[[0,5.8,93.11],[1,5.7,47.82],[2,5.5,9.24]],"batl":[[0,6.8,6.72],[1,7.2,16.6]],"ltp":6.0,"tv":15.14,"id":16575966},{"batb":[[2,4.5,11.76]],"batl":[[1,5.4,9.24],[2,5.8,12.59]],"ltp":0.0,"tv":0.0,"id":16575965},{"batb":[[2,2.36,47.95]],"batl":[[0,2.54,17.31],[1,2.66,15.26],[2,2.68,24.37]],"ltp":2.06,"tv":2.53,"id":13010314}]}]}
{"op":"mcm","clk":"1008523143","pt":1580636550452,"mc":[{"id":"1.168224424","rc":[{"batb":[[0,4.1,21.09],[1,3.95,13.44],[2,1.01,0.51]],"batl":[[1,5,17.7],[2,5,0]],"ltp":0.0,"tv":0.0,"id":13010313},{"batb":[[0,5.8,60.3]],"ltp":6.0,"tv":15.14,"id":16575966},{"batb":[[0,4.5,11.76],[1,4.2,20.54],[2,1.01,0.51]],"batl":[[0,5.4,9.24],[1,5.8,12.59],[2,5.8,0]],"ltp":0.0,"tv":0.0,"id":16575965},{"batb":[[0,2.36,30.25],[1,2.16,22.58],[2,1.01,0.51]],"batl":[[0,2.66,15.26],[1,2.68,24.37],[2,2.68,0]],"ltp":2.06,"tv":2.53,"id":13010314}]}]}
{"op":"mcm","clk":"1008523155","pt":1580636550660,"mc":[{"id":"1.168224424","rc":[{"batb":[[1,1.01,0.51],[2,1.01,0]],"batl":[[0,5,17.7],[1,5,0]],"ltp":0.0,"tv":0.0,"id":13010313},{"batb":[[2,1.01,0.51]],"batl":[[0,7.2,16.6],[1,7.2,0]],"ltp":6.0,"tv":15.14,"id":16575966},{"batb":[[0,4.2,20.54],[1,1.01,0.51],[2,1.01,0]],"batl":[[0,5.8,12.59],[1,5.8,0]],"ltp":0.0,"tv":0.0,"id":16575965},{"batb":[[0,2.16,22.58],[1,1.01,0.51],[2,1.01,0]],"batl":[[1,2.68,0]],"ltp":2.06,"tv":2.53,"id":13010314}]}]}
{"op":"mcm","clk":"1008523317","pt":1580636552984,"mc":[{"id":"1.168224424","rc":[{"batb":[[1,3.9,108.42],[2,3.85,59.04]],"ltp":0.0,"tv":0.0,"id":13010313},{"batb":[[0,4.4,126.64],[1,4.3,89.53],[2,4.2,20.54]],"ltp":0.0,"tv":0.0,"id":16575965},{"batb":[[0,2.3,108.46],[1,2.28,91.17],[2,2.16,22.58]],"ltp":2.06,"tv":2.53,"id":13010314}]}]}
{"op":"mcm","clk":"1008523554","pt":1580636556452,"mc":[{"id":"1.168224424","rc":[{"batb":[[1,1.01,0.51],[2,3.85,0]],"ltp":0.0,"tv":0.0,"id":13010313},{"batb":[[1,1.01,0.51],[2,1.01,0]],"ltp":6.0,"tv":15.14,"id":16575966},{"batb":[[0,4.2,20.54],[1,1.01,0.51],[2,4.2,0]],"ltp":0.0,"tv":0.0,"id":16575965},{"batb":[[0,2.16,22.58],[1,1.01,0.51],[2,2.16,0]],"ltp":2.06,"tv":2.53,"id":13010314}]}]}
{"op":"mcm","clk":"1008523756","pt":1580636559293,"mc":[{"id":"1.168224424","rc":[{"batb":[[1,4,77.81],[2,3.95,55.82]],"ltp":0.0,"tv":0.0,"id":13010313},{"batb":[[0,5.9,38.71],[1,5.8,60.3],[2,1.01,0.51]],"ltp":6.0,"tv":15.14,"id":16575966},{"batb":[[0,4.8,111.73],[1,4.7,73.08],[2,4.2,20.54]],"ltp":0.0,"tv":0.0,"id":16575965},{"batb":[[0,2.44,137.74],[1,2.4,156.62],[2,2.16,22.58]],"ltp":2.06,"tv":2.53,"id":13010314}]}]}
{"op":"mcm","clk":"1008523819","pt":1580636559975,"mc":[{"id":"1.168224424","rc":[{"batb":[[1,3.95,55.82],[2,1.01,0.51]],"ltp":0.0,"tv":0.0,"id":13010313},{"batb":[[0,5.8,60.3],[1,1.01,0.51],[2,1.01,0]],"ltp":6.0,"tv":15.14,"id":16575966},{"batb":[[0,4.2,20.54],[1,1.01,0.51],[2,4.2,0]],"ltp":0.0,"tv":0.0,"id":16575965},{"batb":[[0,2.16,22.58],[1,1.01,0.51],[2,2.16,0]],"ltp":2.06,"tv":2.53,"id":13010314}]}]}
{"op":"mcm","clk":"1008524016","pt":1580636563114,"mc":[{"id":"1.168224424","rc":[{"batb":[[2,3.9,57.77]],"ltp":0.0,"tv":0.0,"id":13010313},{"batb":[[1,5.7,48.1],[2,1.01,0.51]],"ltp":6.0,"tv":15.14,"id":16575966},{"batb":[[0,4.4,124.76],[1,4.3,89.53],[2,4.2,20.54]],"ltp":0.0,"tv":0.0,"id":16575965},{"batb":[[0,2.3,111.16],[1,2.28,91.18],[2,2.16,22.58]],"ltp":2.06,"tv":2.53,"id":13010314}]}]}
{"op":"mcm","clk":"1008524174","pt":1580636565694,"mc":[{"id":"1.168224424","rc":[{"batb":[[0,2.16,22.58],[1,1.01,0.51],[2,2.16,0]],"ltp":2.06,"tv":2.53,"id":13010314}]}]}
{"op":"mcm","clk":"1008524417","pt":1580636569312,"mc":[{"id":"1.168224424","rc":[{"batl":[[0,4.8,19.43],[1,5,17.7]],"ltp":0.0,"tv":0.0,"id":13010313},{"batl":[[0,7,16.76],[1,7.2,16.6]],"ltp":6.0,"tv":15.14,"id":16575966},{"batl":[[0,4.8,19.51],[1,5.2,16.29],[2,5.8,12.59]],"ltp":0.0,"tv":0.0,"id":16575965},{"batb":[[0,2.6,140.76],[1,2.56,131.52],[2,2.48,15.58]],"batl":[[1,2.76,13.85]],"ltp":2.06,"tv":2.53,"id":13010314}]}]}
{"op":"mcm","clk":"1008524478","pt":1580636570188,"mc":[{"id":"1.168224424","rc":[{"batb":[[1,3.9,14.28],[2,1.01,0.51]],"batl":[[0,4.6,10.92],[1,4.8,19.43]],"ltp":0.0,"tv":0.0,"id":13010313},{"batb":[[0,5.8,18.88],[1,5.4,9.24]],"batl":[[0,6.6,6.72],[1,7,16.76]],"ltp":6.0,"tv":15.14,"id":16575966},{"batb":[[0,4.3,12.6],[1,4.2,20.54],[2,4,23.05]],"batl":[[1,5.1,10.08],[2,5.2,16.29]],"ltp":0.0,"tv":0.0,"id":16575965},{"batb":[[0,2.48,15.58],[1,2.46,28.57],[2,2.34,18.33]],"batl":[[2,2.78,23.53]],"ltp":2.06,"tv":2.53,"id":13010314}]}]}
{"op":"mcm","clk":"1008525421","pt":1580636584008,"mc":[{"id":"1.168224424","rc":[{"batb":[[1,4,23.05],[2,1.01,0.51]],"batl":[[0,5.1,10.08],[1,5.2,16.29],[2,5.2,0]],"ltp":0.0,"tv":0.0,"id":16575965},{"batb":[[0,2.46,28.57],[1,2.34,18.33],[2,1.01,0.51]],"batl":[[0,2.76,13.85],[1,2.78,23.53],[2,2.78,0]],"ltp":2.06,"tv":2.53,"id":13010314}]}]}
{"op":"mcm","clk":"1008525458","pt":1580636584626,"mc":[{"id":"1.168224424","rc":[{"batb":[[1,1.01,0.51],[2,1.01,0]],"batl":[[0,4.8,19.43],[1,4.8,0]],"ltp":0.0,"tv":0.0,"id":13010313},{"batb":[[1,1.01,0.51],[2,1.01,0]],"batl":[[0,7,16.76],[1,7,0]],"ltp":6.0,"tv":15.14,"id":16575966},{"batb":[[0,4,23.05],[1,1.01,0.51],[2,1.01,0]],"batl":[[0,5.2,16.29],[1,5.2,0]],"ltp":0.0,"tv":0.0,"id":16575965},{"batb":[[0,2.34,18.33],[1,1.01,0.51],[2,1.01,0]],"batl":[[1,2.78,0]],"ltp":2.06,"tv":2.53,"id":13010314}]}]}
{"op":"mcm","clk":"1008526522","pt":1580636599427,"mc":[{"id":"1.168224424","rc":[{"batb":[[1,3.9,14.28],[2,1.01,0.51]],"batl":[[0,4.6,10.92],[1,4.8,19.43]],"ltp":0.0,"tv":0.0,"id":13010313},{"batb":[[1,5.3,9.24],[2,1.01,0.51]],"batl":[[0,6.4,7.56],[1,7,16.76]],"ltp":6.0,"tv":15.14,"id":16575966},{"batb":[[0,4,36.5]],"batl":[[0,4.8,10.92],[1,5.2,16.29]],"ltp":0.0,"tv":0.0,"id":16575965},{"batb":[[0,2.56,26.89],[1,2.34,18.33],[2,1.01,0.51]],"batl":[[1,2.94,21]],"ltp":2.06,"tv":2.53,"id":13010314}]}]}
{"op":"mcm","clk":"1008526553","pt":1580636600045,"mc":[{"id":"1.168224424","rc":[{"batb":[[0,3.95,23.29]],"batl":[[1,4.7,19.91]],"ltp":0.0,"tv":0.0,"id":13010313},{"batb":[[0,5.6,20.06]],"ltp":6.0,"tv":15.14,"id":16575966},{"batb":[[1,3.55,15.11],[2,1.01,0.51]],"batl":[[0,4.5,21.79],[1,4.8,10.92],[2,4.9,18.73]],"ltp":0.0,"tv":0.0,"id":16575965},{"batb":[[0,2.56,41.05],[1,2.44,16.13]],"batl":[[2,3.1,10.31]],"ltp":2.06,"tv":2.53,"id":13010314}]}]}
{"op":"mcm","clk":"1008526915","pt":1580636606174,"mc":[{"id":"1.168224424","rc":[{"batb":[[1,3.9,54.81],[2,3.85,29.65]],"ltp":0.0,"tv":0.0,"id":13010313},{"batb":[[0,5.7,32.87],[1,5.6,44.89],[2,5.3,9.24]],"ltp":6.0,"tv":15.14,"id":16575966},{"batb":[[0,4.3,41.13],[1,4.2,47.66],[2,4,36.5]],"ltp":0.0,"tv":0.0,"id":16575965},{"batb":[[0,2.68,61.18],[1,2.64,60.65],[2,2.56,41.05]],"ltp":2.06,"tv":2.53,"id":13010314}]}]}
{"op":"mcm","clk":"1008527032","pt":1580636607876,"mc":[{"id":"1.168224424","rc":[{"batb":[[0,4,23.05]],"batl":[[2,4.8,19.67]],"ltp":0.0,"tv":0.0,"id":13010313},{"batb":[[0,5.7,52.23]],"batl":[[1,6.8,17.78]],"ltp":6.0,"tv":15.14,"id":16575966},{"batb":[[2,4,13.44]],"batl":[[1,4.8,30.04],[2,4.9,0]],"ltp":0.0,"tv":0.0,"id":16575965},{"batb":[[2,2.58,13.93]],"batl":[[0,2.78,13.69],[2,3.15,25.1]],"ltp":2.06,"tv":2.53,"id":13010314}]}]}
{"op":"mcm","clk":"1008528877","pt":1580636636376,"mc":[{"id":"1.168224424","rc":[{"batb":[[1,3.9,14.28],[2,1.01,0.51]],"ltp":0.0,"tv":0.0,"id":13010313},{"batb":[[0,5.7,19.36]],"ltp":6.0,"tv":15.14,"id":16575966},{"batb":[[0,4,13.44],[1,3.95,23.45],[2,3.55,15.11]],"ltp":0.0,"tv":0.0,"id":16575965},{"batb":[[0,2.58,13.93],[1,2.56,26.89],[2,2.46,15.89]],"ltp":2.06,"tv":2.53,"id":13010314}]}]}
{"op":"mcm","clk":"1008529074","pt":1580636639301,"mc":[{"id":"1.168224424","rc":[{"batb":[[2,3.8,47.8]],"ltp":0.0,"tv":0.0,"id":13010313},{"batb":[[2,5.5,25.89]],"ltp":6.0,"tv":15.14,"id":16575966},{"batb":[[2,3.85,32.74]],"ltp":0.0,"tv":0.0,"id":16575965},{"batb":[[1,2.56,80.98],[2,2.52,68.71]],"ltp":2.06,"tv":2.53,"id":13010314}]}]}
{"op":"mcm","clk":"1008529779","pt":1580636649431,"mc":[{"id":"1.168224424","rc":[{"batl":[[1,4.8,19.67],[2,4.8,0]],"ltp":0.0,"tv":0.0,"id":13010313},{"batb":[[0,5.6,44.89],[1,5.5,25.89],[2,5.3,9.24]],"ltp":6.0,"tv":15.14,"id":16575966},{"batb":[[1,3.85,32.74],[2,3.8,30.6]],"batl":[[0,4.8,30.04],[1,4.8,0]],"ltp":0.0,"tv":0.0,"id":16575965},{"batb":[[0,2.56,80.98],[1,2.52,68.71],[2,2.46,15.89]],"batl":[[0,2.94,21],[1,3.15,25.1],[2,3.15,0]],"ltp":2.06,"tv":2.53,"id":13010314}]}]}
{"op":"mcm","clk":"1008529863","pt":1580636650716,"mc":[{"id":"1.168224424","rc":[{"batb":[[1,3.8,47.8],[2,3.75,31.51]],"batl":[[0,4.8,19.67],[1,4.8,0]],"ltp":0.0,"tv":0.0,"id":13010313},{"batb":[[2,1.01,0.51]],"batl":[[0,6.8,17.78],[1,6.8,0]],"ltp":6.0,"tv":15.14,"id":16575966},{"batb":[[0,3.85,32.74],[1,3.8,30.6],[2,3.55,15.11]],"batl":[[0,4.8,19.12]],"ltp":0.0,"tv":0.0,"id":16575965},{"batb":[[0,2.56,54.09]],"batl":[[0,3.15,25.1],[1,3.15,0]],"ltp":2.06,"tv":2.53,"id":13010314}]}]}
{"op":"mcm","clk":"1008530574","pt":1580636660251,"mc":[{"id":"1.168224424","rc":[{"batb":[[0,2.46,15.89],[1,1.01,0.51],[2,2.46,0]],"ltp":2.06,"tv":2.53,"id":13010314}]}]}
{"op":"mcm","clk":"1008530801","pt":1580636663427,"mc":[{"id":"1.168224424","rc":[{"batb":[[0,3,35.89],[1,2.96,45.3],[2,2.46,15.89]],"ltp":2.06,"tv":2.53,"id":13010314}]}]}
{"op":"mcm","clk":"1008530888","pt":1580636664455,"mc":[{"id":"1.168224424","rc":[{"batb":[[0,3.85,39.62]],"batl":[[0,4.5,33.56],[1,4.6,20.85]],"ltp":0.0,"tv":0.0,"id":13010313},{"batb":[[0,5.6,35.14],[2,5.1,10.08]],"batl":[[0,6.2,7.56],[1,6.8,17.78]],"ltp":6.0,"tv":15.14,"id":16575966},{"batb":[[2,3.65,15.12]],"batl":[[0,3.95,14.87],[1,4.3,36.76]],"ltp":0.0,"tv":0.0,"id":16575965},{"batb":[[2,2.88,10.46]],"batl":[[1,3.25,18.48],[2,3.8,16.37]],"ltp":2.06,"tv":2.53,"id":13010314}]}]}
{"op":"mcm","clk":"1008531569","pt":1580636673947,"mc":[{"id":"1.168224424","rc":[{"batb":[[1,3.8,30.81],[2,1.01,0.51]],"ltp":0.0,"tv":0.0,"id":13010313},{"batb":[[0,5.6,10.31]],"ltp":6.0,"tv":15.14,"id":16575966},{"batb":[[0,3.8,30.6],[1,3.65,15.12],[2,3.55,15.11]],"ltp":0.0,"tv":0.0,"id":16575965}]}]}
{"op":"mcm","clk":"1008531742","pt":1580636676446,"mc":[{"id":"1.168224424","rc":[{"batb":[[0,3.85,71.44]],"ltp":0.0,"tv":0.0,"id":13010313},{"batb":[[1,5.5,42.9],[2,5.4,26.58]],"ltp":6.0,"tv":15.14,"id":16575966},{"batb":[[0,3.8,43.26],[1,3.75,31.31],[2,3.65,15.12]],"ltp":0.0,"tv":0.0,"id":16575965},{"batb":[[0,3,57.22]],"ltp":2.06,"tv":2.53,"id":13010314}]}]}
{"op":"mcm","clk":"1008532365","pt":1580636684235,"mc":[{"id":"1.168224424","rc":[{"batb":[[0,3.85,39.62],[1,1.01,0.51],[2,1.01,0]],"batl":[[0,4.5,11.76]],"ltp":0.0,"tv":0.0,"id":13010313},{"batb":[[1,5.4,26.58],[2,5.1,10.08]],"ltp":6.0,"tv":15.14,"id":16575966},{"batb":[[0,3.65,15.12],[1,3.05,22.11],[2,1.01,0.51]],"batl":[[0,4.3,36.76],[1,4.3,0]],"ltp":0.0,"tv":0.0,"id":16575965},{"batb":[[0,2.82,22.69],[1,2.68,12.75],[2,1.01,0.51]],"batl":[[0,3.25,18.48],[1,3.8,16.37],[2,3.8,0]],"ltp":2.06,"tv":2.53,"id":13010314}]}]}
{"op":"mcm","clk":"1008532404","pt":1580636684751,"mc":[{"id":"1.168224424","rc":[{"batb":[[0,3.85,25.34]],"batl":[[0,4.6,20.85],[1,4.6,0]],"ltp":0.0,"tv":0.0,"id":13010313},{"batb":[[2,1.01,0.51]],"batl":[[0,6.8,17.78],[1,6.8,0]],"ltp":6.0,"tv":15.14,"id":16575966},{"batb":[[0,3.05,22.11],[1,1.01,0.51],[2,1.01,0]],"batl":[[0,4.3,24.16]],"ltp":0.0,"tv":0.0,"id":16575965},{"batb":[[0,2.68,12.75],[1,1.01,0.51],[2,1.01,0]],"batl":[[0,3.8,16.37],[1,3.8,0]],"ltp":2.06,"tv":2.53,"id":13010314}]}]}
{"op":"mcm","clk":"1008532529","pt":1580636686861,"mc":[{"id":"1.168224424","rc":[{"batb":[[1,1.01,0.51],[2,1.01,0]],"ltp":6.0,"tv":15.14,"id":16575966},{"batb":[[0,2.78,53.09],[1,2.74,55.29],[2,2.68,12.75]],"ltp":2.06,"tv":2.53,"id":13010314}]}]}
{"op":"mcm","clk":"1008532773","pt":1580636690363,"mc":[{"id":"1.168224424","rc":[{"batb":[[0,4,21.95],[1,3.95,23.84],[2,3.9,58.85]],"batl":[[0,4.6,31.77],[1,4.8,19.67]],"ltp":0.0,"tv":0.0,"id":13010313},{"batb":[[0,5.6,43.25],[1,5.5,25.64],[2,5.2,9.24]],"batl":[[0,6.4,7.56],[1,6.8,17.78]],"ltp":6.0,"tv":15.14,"id":16575966},{"batb":[[0,4.1,51.65],[1,4,52.85],[2,3.85,14.28]],"batl":[[1,4.6,10.92],[2,4.7,20.22]],"ltp":0.0,"tv":0.0,"id":16575965},{"batl":[[0,2.86,12.51],[1,3.05,20.16],[2,3.4,21.32]],"ltp":2.06,"tv":2.53,"id":13010314}]}]}
{"op":"mcm","clk":"1008533591","pt":1580636701398,"mc":[{"id":"1.168224424","rc":[{"batb":[[2,3.9,14.28]],"ltp":0.0,"tv":0.0,"id":13010313},{"batb":[[0,5.6,10.31]],"ltp":6.0,"tv":15.14,"id":16575966},{"batb":[[0,3.85,14.28],[1,3.8,25.57],[2,3.35,17.86]],"ltp":0.0,"tv":0.0,"id":16575965},{"batb":[[0,2.68,12.75],[1,2.66,25.21],[2,2.5,15.19]],"ltp":2.06,"tv":2.53,"id":13010314}]}]}
{"op":"mcm","clk":"1008533599","pt":1580636701505,"mc":[{"id":"1.168224424","rc":[{"batb":[[0,3.95,23.84],[1,3.9,14.28],[2,1.01,0.51]],"batl":[[0,4.6,10.92]],"ltp":0.0,"tv":0.0,"id":13010313},{"batb":[[1,3.35,17.86],[2,1.01,0.51]],"batl":[[0,4.6,10.92],[1,4.7,20.22],[2,4.7,0]],"ltp":0.0,"tv":0.0,"id":16575965},{"batb":[[0,2.66,25.21],[1,2.5,15.19],[2,1.01,0.51]],"batl":[[0,3.05,20.16],[1,3.4,21.32],[2,3.4,0]],"ltp":2.06,"tv":2.53,"id":13010314}]}]}
{"op":"mcm","clk":"1008533710","pt":1580636702703,"mc":[{"id":"1.168224424","rc":[{"batb":[[1,1.01,0.51],[2,1.01,0]],"batl":[[0,4.8,19.67],[1,4.8,0]],"ltp":0.0,"tv":0.0,"id":13010313},{"batb":[[2,1.01,0.51]],"batl":[[0,6.8,17.78],[1,6.8,0]],"ltp":6.0,"tv":15.14,"id":16575966},{"batb":[[0,3.35,17.86],[1,1.01,0.51],[2,1.01,0]],"batl":[[0,4.7,20.22],[1,4.7,0]],"ltp":0.0,"tv":0.0,"id":16575965},{"batb":[[0,2.5,15.19],[1,1.01,0.51],[2,1.01,0]],"batl":[[0,3.4,21.32],[1,3.4,0]],"ltp":2.06,"tv":2.53,"id":13010314}]}]}
{"op":"mcm","clk":"1008533839","pt":1580636704306,"mc":[{"id":"1.168224424","rc":[{"batb":[[1,3.8,34.41],[2,3.75,31.78]],"ltp":0.0,"tv":0.0,"id":13010313},{"batb":[[2,5.4,26.8]],"ltp":6.0,"tv":15.14,"id":16575966},{"batb":[[0,3.6,40.02],[1,3.55,35.73],[2,3.35,17.86]],"ltp":0.0,"tv":0.0,"id":16575965},{"batb":[[0,2.6,69.7],[1,2.56,66],[2,2.5,15.19]],"ltp":2.06,"tv":2.53,"id":13010314}]}]}
{"op":"mcm","clk":"1008535121","pt":1580636720113,"mc":[{"id":"1.168224424","rc":[{"batb":[[0,2.5,15.19],[1,1.01,0.51],[2,2.5,0]],"ltp":2.06,"tv":2.53,"id":13010314}]}]}
{"op":"mcm","clk":"1008535339","pt":1580636723212,"mc":[{"id":"1.168224424","rc":[{"batb":[[1,5.4,26.8],[2,1.01,0.51]],"ltp":6.0,"tv":15.14,"id":16575966},{"batb":[[0,3.55,35.73],[1,3.35,17.86],[2,1.01,0.51]],"ltp":0.0,"tv":0.0,"id":16575965},{"batb":[[0,3.2,48.21],[1,3.15,48.38],[2,2.5,15.19]],"ltp":2.06,"tv":2.53,"id":13010314}]}]}
{"op":"mcm","clk":"1008535383","pt":1580636723829,"mc":[{"id":"1.168224424","rc":[{"batb":[[1,3.8,48.69],[2,3.75,45]],"batl":[[0,4.5,34.34],[1,4.6,21.17]],"ltp":0.0,"tv":0.0,"id":13010313},{"batb":[[1,5.5,10.62],[2,5.4,26.8]],"batl":[[0,6.2,7.56],[1,6.8,17.78]],"ltp":6.0,"tv":15.14,"id":16575966},{"batb":[[1,3.5,16.8],[2,3.35,17.86]],"batl":[[0,3.7,17.23],[1,4.1,26.9]],"ltp":0.0,"tv":0.0,"id":16575965},{"batb":[[2,3.05,22.19]],"batl":[[1,3.45,16.8],[2,4.4,23.29]],"ltp":2.06,"tv":2.53,"id":13010314}]}]}
{"op":"mcm","clk":"1008535586","pt":1580636726212,"mc":[{"id":"1.168224424","rc":[{"batb":[[1,3.8,60.61]],"ltp":0.0,"tv":0.0,"id":13010313},{"batb":[[2,5.4,45.31]],"ltp":6.0,"tv":15.14,"id":16575966},{"batb":[[0,3.55,60.31],[1,3.5,53.44]],"ltp":0.0,"tv":0.0,"id":16575965},{"batb":[[0,3.2,63.31]],"ltp":2.06,"tv":2.53,"id":13010314}]}]}
{"op":"mcm","clk":"1008536171","pt":1580636733944,"mc":[{"id":"1.168224424","rc":[{"batb":[[1,3.8,48.69],[2,3.75,13.22]],"ltp":0.0,"tv":0.0,"id":13010313},{"batb":[[2,5.4,35.72]],"ltp":6.0,"tv":15.14,"id":16575966},{"batb":[[0,3.55,43.79]],"ltp":0.0,"tv":0.0,"id":16575965},{"batb":[[0,3.2,48.21],[1,3.05,22.19],[2,2.96,21]],"ltp":2.06,"tv":2.53,"id":13010314}]}]}
{"op":"mcm","clk":"1008536427","pt":1580636737151,"mc":[{"id":"1.168224424","rc":[{"batb":[[1,3.85,27.37],[2,3.8,48.69]],"ltp":0.0,"tv":0.0,"id":13010313},{"batb":[[0,3.25,31.64],[1,3.2,48.21],[2,3.05,22.19]],"ltp":2.06,"tv":2.53,"id":13010314}]}]}
{"op":"mcm","clk":"1008538061","pt":1580636758437,"mc":[{"id":"1.168224424","rc":[{"batb":[[0,3.8,14.28],[1,3.75,13.22],[2,1.01,0.51]],"batl":[[0,4.5,11.76]],"ltp":0.0,"tv":0.0,"id":13010313},{"batb":[[0,5.5,10.62],[1,5.3,27.53],[2,5.1,10.08]],"ltp":6.0,"tv":15.14,"id":16575966},{"batb":[[0,3.5,16.8],[1,2.84,10.86],[2,1.01,0.51]],"batl":[[0,4.1,26.9],[1,4.1,0]],"ltp":0.0,"tv":0.0,"id":16575965},{"batb":[[0,2.96,21],[1,2.76,11.64],[2,1.01,0.51]],"batl":[[0,3.45,16.8],[1,4.4,23.29],[2,4.4,0]],"ltp":2.06,"tv":2.53,"id":13010314}]}]}
{"op":"mcm","clk":"1008538081","pt":1580636758643,"mc":[{"id":"1.168224424","rc":[{"batb":[[0,3.75,13.22],[1,1.01,0.51],[2,1.01,0]],"batl":[[0,4.6,21.17],[1,4.6,0]],"ltp":0.0,"tv":0.0,"id":13010313},{"batb":[[2,1.01,0.51]],"batl":[[0,6.8,17.78],[1,6.8,0]],"ltp":6.0,"tv":15.14,"id":16575966},{"batb":[[0,2.84,10.86],[1,1.01,0.51],[2,1.01,0]],"batl":[[0,4.1,13.45]],"ltp":0.0,"tv":0.0,"id":16575965},{"batb":[[0,2.76,11.64],[1,1.01,0.51],[2,1.01,0]],"batl":[[0,4.4,23.29],[1,4.4,0]],"ltp":2.06,"tv":2.53,"id":13010314}]}]}
{"op":"mcm","clk":"1008538376","pt":1580636761445,"mc":[{"id":"1.168224424","rc":[{"batb":[[0,3.8,13.14],[1,3.75,13.22],[2,3.65,49.81]],"ltp":0.0,"tv":0.0,"id":13010313},{"batb":[[1,5.2,28.92]],"ltp":6.0,"tv":15.14,"id":16575966},{"batb":[[0,2.98,53.67],[1,2.94,45.27],[2,2.84,10.86]],"ltp":0.0,"tv":0.0,"id":16575965},{"batb":[[0,2.9,44.51],[1,2.86,49.84],[2,2.76,11.64]],"ltp":2.06,"tv":2.53,"id":13010314}]}]}
{"op":"mcm","clk":"1008538397","pt":1580636761643,"mc":[{"id":"1.168224424","rc":[{"batb":[[1,1.01,0.51],[2,3.65,0]],"ltp":0.0,"tv":0.0,"id":13010313},{"batb":[[1,1.01,0.51],[2,1.01,0]],"ltp":6.0,"tv":15.14,"id":16575966},{"batb":[[0,2.84,10.86],[1,1.01,0.51],[2,2.84,0]],"ltp":0.0,"tv":0.0,"id":16575965}]}]}
{"op":"mcm","clk":"1008538622","pt":1580636764327,"mc":[{"id":"1.168224424","rc":[{"batb":[[0,3.9,54.58],[1,3.85,29.91],[2,3.8,13.14]],"ltp":0.0,"tv":0.0,"id":13010313},{"batb":[[0,5.5,39.55],[1,5.4,26.49],[2,1.01,0.51]],"ltp":6.0,"tv":15.14,"id":16575966},{"batb":[[0,3.95,31.42],[1,3.9,28.34],[2,2.84,10.86]],"ltp":0.0,"tv":0.0,"id":16575965}]}]}
{"op":"mcm","clk":"1008538683","pt":1580636765149,"mc":[{"id":"1.168224424","rc":[{"batb":[[0,4,22.27],[1,3.9,54.58],[2,3.85,55.01]],"batl":[[1,4.7,19.75]],"ltp":0.0,"tv":0.0,"id":13010313},{"batb":[[2,3.7,13.85]],"batl":[[1,4.6,21.17]],"ltp":0.0,"tv":0.0,"id":16575965},{"batl":[[0,2.98,11.49],[1,3.7,17.07],[2,4.4,23.29]],"ltp":2.06,"tv":2.53,"id":13010314}]}]}
{"op":"mcm","clk":"1008538797","pt":1580636766388,"mc":[{"id":"1.168224424","rc":[{"batb":[[1,3.9,68.86]],"batl":[[0,4.6,32.09]],"ltp":0.0,"tv":0.0,"id":13010313},{"batb":[[0,5.5,39.39],[2,5.1,10.08]],"batl":[[0,6.2,7.56],[1,6.8,17.78]],"ltp":6.0,"tv":15.14,"id":16575966},{"batb":[[2,3.75,15.12]],"batl":[[1,4.5,11.76],[2,4.6,21.17]],"ltp":0.0,"tv":0.0,"id":16575965},{"batl":[[1,3.15,19.32],[2,3.7,17.07]],"ltp":2.06,"tv":2.53,"id":13010314}]}]}
{"op":"mcm","clk":"1008539683","pt":1580636777785,"mc":[{"id":"1.168224424","rc":[{"batb":[[1,3.9,43.54],[2,3.85,25.1]],"ltp":0.0,"tv":0.0,"id":13010313}]}]}
{"op":"mcm","clk":"1008539810","pt":1580636779429,"mc":[{"id":"1.168224424","rc":[{"batb":[[1,3.9,14.28]],"ltp":0.0,"tv":0.0,"id":13010313},{"batb":[[0,5.5,10.46],[1,5.1,10.08],[2,1.01,0.51]],"ltp":6.0,"tv":15.14,"id":16575966},{"batb":[[0,3.75,15.12],[1,3.7,13.85],[2,3.1,21.24]],"ltp":0.0,"tv":0.0,"id":16575965},{"batb":[[0,2.76,11.64],[1,2.74,23.53],[2,2.54,14.63]],"ltp":2.06,"tv":2.53,"id":13010314}]}]}
{"op":"mcm","clk":"1008539825","pt":1580636779587,"mc":[{"id":"1.168224424","rc":[{"batb":[[0,3.9,14.28],[1,3.85,25.1],[2,1.01,0.51]],"batl":[[0,4.6,10.92]],"ltp":0.0,"tv":0.0,"id":13010313},{"batb":[[1,3.1,21.24],[2,1.01,0.51]],"batl":[[0,4.5,11.76],[1,4.6,21.17],[2,4.6,0]],"ltp":0.0,"tv":0.0,"id":16575965},{"batb":[[0,2.74,23.53],[1,2.54,14.63],[2,1.01,0.51]],"batl":[[0,3.15,19.32],[1,3.7,17.07],[2,3.7,0]],"ltp":2.06,"tv":2.53,"id":13010314}]}]}
{"op":"mcm","clk":"1008539936","pt":1580636781130,"mc":[{"id":"1.168224424","rc":[{"batb":[[0,3.85,25.1],[1,1.01,0.51],[2,1.01,0]],"batl":[[0,4.7,19.75],[1,4.7,0]],"ltp":0.0,"tv":0.0,"id":13010313},{"batb":[[1,1.01,0.51],[2,1.01,0]],"batl":[[0,6.8,17.78],[1,6.8,0]],"ltp":6.0,"tv":15.14,"id":16575966},{"batb":[[0,3.1,21.24],[1,1.01,0.51],[2,1.01,0]],"batl":[[0,4.6,21.17],[1,4.6,0]],"ltp":0.0,"tv":0.0,"id":16575965},{"batb":[[0,2.54,14.63],[1,1.01,0.51],[2,1.01,0]],"batl":[[0,3.7,17.07],[1,3.7,0]],"ltp":2.06,"tv":2.53,"id":13010314}]}]}
{"op":"mcm","clk":"1008540022","pt":1580636782325,"mc":[{"id":"1.168224424","rc":[{"batb":[[1,3.75,46.9],[2,3.7,32.93]],"ltp":0.0,"tv":0.0,"id":13010313},{"batb":[[1,5.3,43.92],[2,5.2,28.59]],"ltp":6.0,"tv":15.14,"id":16575966},{"batb":[[0,3.3,38.56],[1,3.25,43.96],[2,3.1,21.24]],"ltp":0.0,"tv":0.0,"id":16575965},{"batb":[[0,2.64,56.88],[1,2.6,63.76],[2,2.54,14.63]],"ltp":2.06,"tv":2.53,"id":13010314}]}]}
{"op":"mcm","clk":"1008540447","pt":1580636788139,"mc":[{"id":"1.168224424","rc":[{"batb":[[0,2.54,14.63],[1,1.01,0.51],[2,2.54,0]],"ltp":2.06,"tv":2.53,"id":13010314}]}]}
{"op":"mcm","clk":"1008540705","pt":1580636791448,"mc":[{"id":"1.168224424","rc":[{"batl":[[0,4.4,23.76],[1,4.6,21.24],[2,4.7,19.75]],"ltp":0.0,"tv":0.0,"id":13010313},{"batl":[[0,6.6,19.43],[1,6.8,17.78]],"ltp":6.0,"tv":15.14,"id":16575966},{"batl":[[0,3.45,20.46],[1,4,14.4],[2,4.6,21.17]],"ltp":0.0,"tv":0.0,"id":16575965},{"batb":[[0,3.55,61.8],[1,3.5,37.5],[2,3.35,17.62]],"batl":[[1,6.4,10.54]],"ltp":2.06,"tv":2.53,"id":13010314}]}]}
{"op":"mcm","clk":"1008540745","pt":1580636791923,"mc":[{"id":"1.168224424","rc":[{"batb":[[2,3.7,48.05]],"batl":[[0,4.4,35.52],[2,4.7,0]],"ltp":0.0,"tv":0.0,"id":13010313},{"batl":[[0,6.2,7.56],[1,6.6,19.43],[2,6.8,17.78]],"ltp":6.0,"tv":15.14,"id":16575966},{"batb":[[0,3.3,56.2]],"batl":[[1,3.85,14.28],[2,4,14.4]],"ltp":0.0,"tv":0.0,"id":16575965},{"batl":[[1,3.75,15.12],[2,6.4,10.54]],"ltp":2.06,"tv":2.53,"id":13010314}]}]}
{"op":"mcm","clk":"1008542157","pt":1580636810148,"mc":[{"id":"1.168224424","rc":[{"batb":[[0,3.7,15.12],[1,3.55,15.34],[2,1.01,0.51]],"batl":[[0,4.4,11.76]],"ltp":0.0,"tv":0.0,"id":13010313},{"batb":[[1,5,10.08],[2,1.01,0.51]],"batl":[[1,6.8,17.78],[2,6.8,0]],"ltp":6.0,"tv":15.14,"id":16575966},{"batb":[[0,3.3,17.64],[1,2.46,15.82],[2,1.01,0.51]],"batl":[[0,3.85,14.28],[1,4,14.4],[2,4,0]],"ltp":0.0,"tv":0.0,"id":16575965},{"batb":[[0,3.2,18.48],[1,2.82,11.02],[2,1.01,0.51]],"batl":[[0,3.75,15.12],[1,6.4,10.54],[2,6.4,0]],"ltp":2.06,"tv":2.53,"id":13010314}]}]}
{"op":"mcm","clk":"1008542250","pt":1580636811126,"mc":[{"id":"1.168224424","rc":[{"batb":[[0,3.55,15.34],[1,1.01,0.51],[2,1.01,0]],"batl":[[0,4.6,21.24],[1,4.6,0]],"ltp":0.0,"tv":0.0,"id":13010313},{"batb":[[1,1.01,0.51],[2,1.01,0]],"batl":[[0,6.8,17.78],[1,6.8,0]],"ltp":6.0,"tv":15.14,"id":16575966},{"batb":[[0,2.46,15.82],[1,1.01,0.51],[2,1.01,0]],"batl":[[0,4,14.4],[1,4,0]],"ltp":0.0,"tv":0.0,"id":16575965},{"batb":[[0,2.82,11.02],[1,1.01,0.51],[2,1.01,0]],"batl":[[0,6.4,10.54],[1,6.4,0]],"ltp":2.06,"tv":2.53,"id":13010314}]}]}
{"op":"mcm","clk":"1008542424","pt":1580636813340,"mc":[{"id":"1.168224424","rc":[{"batb":[[1,3.45,64.53],[2,3.4,40.14]],"ltp":0.0,"tv":0.0,"id":13010313},{"batb":[[1,5.1,38.32],[2,5,31.32]],"ltp":6.0,"tv":15.14,"id":16575966},{"batb":[[0,2.56,54.48],[1,2.52,67.75],[2,2.46,15.82]],"ltp":0.0,"tv":0.0,"id":16575965},{"batb":[[0,2.94,40.67],[1,2.9,48.15],[2,2.82,11.02]],"ltp":2.06,"tv":2.53,"id":13010314}]}]}
{"op":"mcm","clk":"1008542534","pt":1580636814834,"mc":[{"id":"1.168224424","rc":[{"batb":[[1,1.01,0.51],[2,3.4,0]],"ltp":0.0,"tv":0.0,"id":13010313},{"batb":[[1,1.01,0.51],[2,5,0]],"ltp":6.0,"tv":15.14,"id":16575966},{"batb":[[0,2.46,15.82],[1,1.01,0.51],[2,2.46,0]],"ltp":0.0,"tv":0.0,"id":16575965}]}]}
{"op":"mcm","clk":"1008542758","pt":1580636817943,"mc":[{"id":"1.168224424","rc":[{"batb":[[0,3.95,26.72],[1,3.9,29.25],[2,3.55,15.34]],"ltp":0.0,"tv":0.0,"id":13010313},{"batb":[[0,5.5,33.41],[1,5.4,26.57],[2,1.01,0.51]],"ltp":6.0,"tv":15.14,"id":16575966},{"batb":[[0,3.9,26.56],[1,3.85,29.26],[2,2.46,15.82]],"ltp":0.0,"tv":0.0,"id":16575965}]}]}
{"op":"mcm","clk":"1008542811","pt":1580636818666,"mc":[{"id":"1.168224424","rc":[{"batb":[[0,4,22.35],[1,3.95,26.72],[2,3.9,29.25]],"batl":[[1,4.7,19.83]],"ltp":0.0,"tv":0.0,"id":13010313},{"batb":[[2,3.6,14.87]],"batl":[[1,4.5,21.87]],"ltp":0.0,"tv":0.0,"id":16575965},{"batl":[[0,3.05,10.86],[1,3.8,15.97]],"ltp":2.06,"tv":2.53,"id":13010314}]}]}
{"op":"mcm","clk":"1008542946","pt":1580636820370,"mc":[{"id":"1.168224424","rc":[{"batl":[[0,4.6,32.17]],"ltp":0.0,"tv":0.0,"id":13010313},{"batb":[[2,5.1,10.08]],"batl":[[0,6.2,7.56],[1,6.8,17.78]],"ltp":6.0,"tv":15.14,"id":16575966},{"batb":[[2,3.7,15.12]],"batl":[[1,4.4,11.76],[2,4.5,21.87]],"ltp":0.0,"tv":0.0,"id":16575965},{"batl":[[1,3.2,18.48],[2,3.8,15.97]],"ltp":2.06,"tv":2.53,"id":13010314}]}]}
{"op":"mcm","clk":"1008543978","pt":1580636834114,"mc":[{"id":"1.168224424","rc":[{"batb":[[0,3.85,39.46],[1,1.01,0.51],[2,3.9,0]],"batl":[[0,4.6,10.92]],"ltp":0.0,"tv":0.0,"id":13010313},{"batb":[[0,5.5,10.46],[1,5.1,10.08],[2,1.01,0.51]],"ltp":6.0,"tv":15.14,"id":16575966},{"batb":[[0,3.7,15.12],[1,3.05,22.42],[2,1.01,0.51]],"batl":[[0,4.4,11.76],[1,4.5,21.87],[2,4.5,0]],"ltp":0.0,"tv":0.0,"id":16575965},{"batb":[[0,2.78,23.53],[1,2.56,14.24],[2,1.01,0.51]],"batl":[[0,3.2,18.48],[1,3.8,15.97],[2,3.8,0]],"ltp":2.06,"tv":2.53,"id":13010314}]}]}
{"op":"mcm","clk":"1008544032","pt":1580636834795,"mc":[{"id":"1.168224424","rc":[{"batb":[[0,3.85,25.18]],"batl":[[0,4.7,19.83],[1,4.7,0]],"ltp":0.0,"tv":0.0,"id":13010313},{"batb":[[1,1.01,0.51],[2,1.01,0]],"batl":[[0,6.8,17.78],[1,6.8,0]],"ltp":6.0,"tv":15.14,"id":16575966},{"batb":[[0,3.05,22.42],[1,1.01,0.51],[2,1.01,0]],"batl":[[0,4.5,21.87],[1,4.5,0]],"ltp":0.0,"tv":0.0,"id":16575965},{"batb":[[0,2.56,14.24],[1,1.01,0.51],[2,1.01,0]],"batl":[[0,3.8,15.97],[1,3.8,0]],"ltp":2.06,"tv":2.53,"id":13010314}]}]}
{"op":"mcm","clk":"1008544174","pt":1580636836801,"mc":[{"id":"1.168224424","rc":[{"batb":[[1,3.75,51.15],[2,3.7,32.89]],"ltp":0.0,"tv":0.0,"id":13010313},{"batb":[[1,5.3,40.32],[2,5.2,28.64]],"ltp":6.0,"tv":15.14,"id":16575966},{"batb":[[0,3.25,46.55],[1,3.2,45.61],[2,3.05,22.42]],"ltp":0.0,"tv":0.0,"id":16575965},{"batb":[[0,2.68,38.7],[1,2.64,61.36],[2,2.56,14.24]],"ltp":2.06,"tv":2.53,"id":13010314}]}]}
{"op":"mcm","clk":"1008544587","pt":1580636843204,"mc":[{"id":"1.168224424","rc":[{"batb":[[1,1.01,0.51],[2,3.7,0]],"ltp":0.0,"tv":0.0,"id":13010313},{"batb":[[1,1.01,0.51],[2,5.2,0]],"ltp":6.0,"tv":15.14,"id":16575966},{"batb":[[0,3.05,22.42],[1,1.01,0.51],[2,3.05,0]],"ltp":0.0,"tv":0.0,"id":16575965}]}]}
{"op":"mcm","clk":"1008544825","pt":1580636846406,"mc":[{"id":"1.168224424","rc":[{"batb":[[0,4.1,20.85],[1,4,70.91],[2,3.95,41.65]],"batl":[[0,4.7,30.75],[1,4.8,19.2]],"ltp":0.0,"tv":0.0,"id":13010313},{"batb":[[0,5.6,20.54],[1,5.5,52.8],[2,5.4,26.28]],"batl":[[0,6.2,7.56],[1,6.8,17.78]],"ltp":6.0,"tv":15.14,"id":16575966},{"batb":[[0,4.3,39.88],[1,4.2,46.87],[2,4,23.05]],"batl":[[1,4.9,18.8]],"ltp":0.0,"tv":0.0,"id":16575965},{"batb":[[2,2.58,26.05]],"batl":[[0,2.76,13.93],[1,3.1,10.39],[2,3.8,15.97]],"ltp":2.06,"tv":2.53,"id":13010314}]}]}
{"op":"mcm","clk":"1008544892","pt":1580636847190,"mc":[{"id":"1.168224424","rc":[{"batb":[[1,5.5,42.34]],"ltp":6.0,"tv":15.14,"id":16575966},{"batl":[[2,3.8,0]],"ltp":2.06,"tv":2.53,"id":13010314}]}]}
{"op":"mcm","clk":"1008545096","pt":1580636849414,"mc":[{"id":"1.168224424","rc":[{"batb":[[2,4.1,13.44]],"batl":[[1,4.9,28.89]],"ltp":0.0,"tv":0.0,"id":16575965},{"batl":[[1,2.94,21],[2,3.1,10.39]],"ltp":2.06,"tv":2.53,"id":13010314}]}]}
{"op":"mcm","clk":"1008545942","pt":1580636861341,"mc":[{"id":"1.168224424","rc":[{"batb":[[0,4,22.11],[1,3.95,41.65],[2,1.01,0.51]],"batl":[[0,4.7,10.92]],"ltp":0.0,"tv":0.0,"id":13010313},{"batb":[[1,5.4,26.28],[2,5.1,10.08]],"ltp":6.0,"tv":15.14,"id":16575966},{"batb":[[0,4.1,13.44],[1,3.55,15.42],[2,1.01,0.51]],"batl":[[0,4.9,28.89],[1,4.9,0]],"ltp":0.0,"tv":0.0,"id":16575965},{"batb":[[0,2.58,26.05],[1,2.44,16.13],[2,1.01,0.51]],"batl":[[0,2.94,21],[1,3.1,10.39],[2,3.1,0]],"ltp":2.06,"tv":2.53,"id":13010314}]}]}
{"op":"mcm","clk":"1008546042","pt":1580636862995,"mc":[{"id":"1.168224424","rc":[{"batb":[[1,3.95,28.21]],"batl":[[0,4.8,19.2],[1,4.8,0]],"ltp":0.0,"tv":0.0,"id":13010313},{"batb":[[2,1.01,0.51]],"batl":[[0,6.8,17.78],[1,6.8,0]],"ltp":6.0,"tv":15.14,"id":16575966},{"batb":[[0,3.55,15.42],[1,1.01,0.51],[2,1.01,0]],"batl":[[0,4.9,18.8]],"ltp":0.0,"tv":0.0,"id":16575965},{"batb":[[0,2.44,16.13],[1,1.01,0.51],[2,1.01,0]],"batl":[[0,3.1,10.39],[1,3.1,0]],"ltp":2.06,"tv":2.53,"id":13010314}]}]}
{"op":"mcm","clk":"1008546143","pt":1580636864228,"mc":[{"id":"1.168224424","rc":[{"batb":[[2,3.9,29.24]],"ltp":0.0,"tv":0.0,"id":13010313},{"batb":[[1,5.4,44.77],[2,5.3,27.37]],"ltp":6.0,"tv":15.14,"id":16575966},{"batb":[[0,3.8,53.05],[1,3.75,30.91],[2,3.55,15.42]],"ltp":0.0,"tv":0.0,"id":16575965},{"batb":[[0,2.54,57.82],[1,2.5,70.77],[2,2.44,16.13]],"ltp":2.06,"tv":2.53,"id":13010314}]}]}
{"op":"mcm","clk":"1008546322","pt":1580636867114,"mc":[{"id":"1.168224424","rc":[{"batb":[[2,1.01,0.51]],"ltp":0.0,"tv":0.0,"id":13010313},{"batb":[[1,1.01,0.51],[2,5.3,0]],"ltp":6.0,"tv":15.14,"id":16575966},{"batb":[[0,3.55,15.42],[1,1.01,0.51],[2,3.55,0]],"ltp":0.0,"tv":0.0,"id":16575965},{"batb":[[0,2.44,16.13],[1,1.01,0.51],[2,2.44,0]],"ltp":2.06,"tv":2.53,"id":13010314}]}]}
{"op":"mcm","clk":"1008546511","pt":1580636870249,"mc":[{"id":"1.168224424","rc":[{"batb":[[0,4,96.01]],"ltp":0.0,"tv":0.0,"id":13010313},{"batb":[[0,5.6,49.33],[1,5.5,25.42],[2,1.01,0.51]],"ltp":6.0,"tv":15.14,"id":16575966},{"batb":[[0,4.6,35.89],[1,4.5,40],[2,3.55,15.42]],"ltp":0.0,"tv":0.0,"id":16575965},{"batb":[[0,2.54,57.82],[1,2.5,70.77],[2,2.44,16.13]],"ltp":2.06,"tv":2.53,"id":13010314}]}]}
{"op":"mcm","clk":"1008546544","pt":1580636870711,"mc":[{"id":"1.168224424","rc":[{"batb":[[0,4.2,20.14],[1,4.1,20.93],[2,4,73.9]],"batl":[[1,5,17.86]],"ltp":0.0,"tv":0.0,"id":13010313},{"batb":[[0,5.7,19.67],[1,5.6,49.33],[2,5.5,25.42]],"batl":[[1,7,17.55]],"ltp":6.0,"tv":15.14,"id":16575966},{"batb":[[2,4.2,19.83]],"batl":[[1,5.6,13.53]],"ltp":0.0,"tv":0.0,"id":16575965},{"batl":[[0,2.62,15.82],[1,2.78,13.53]],"ltp":2.06,"tv":2.53,"id":13010314}]}]}
{"op":"mcm","clk":"1008546624","pt":1580636871840,"mc":[{"id":"1.168224424","rc":[{"batb":[[2,4,87.34]],"batl":[[0,4.8,30.12]],"ltp":0.0,"tv":0.0,"id":13010313},{"batl":[[0,6.4,7.56],[1,6.8,17.78],[2,7,17.55]],"ltp":6.0,"tv":15.14,"id":16575966},{"batb":[[2,4.4,11.76]],"batl":[[1,5.3,9.24],[2,5.6,13.53]],"ltp":0.0,"tv":0.0,"id":16575965},{"batl":[[1,2.76,23.53],[2,2.78,13.53]],"ltp":2.06,"tv":2.53,"id":13010314}]}]}
{"op":"mcm","clk":"1008547235","pt":1580636882229,"mc":[{"id":"1.168224424","rc":[{"batb":[[2,4,68.06]],"ltp":0.0,"tv":0.0,"id":13010313},{"batb":[[1,5.6,41.87]],"ltp":6.0,"tv":15.14,"id":16575966},{"batb":[[0,4.6,26.35]],"ltp":0.0,"tv":0.0,"id":16575965}]}]}
{"op":"mcm","clk":"1008547462","pt":1580636885419,"mc":[{"id":"1.168224424","rc":[{"batb":[[1,4.1,46.79]],"ltp":0.0,"tv":0.0,"id":13010313},{"batb":[[0,2.54,71.81]],"ltp":2.06,"tv":2.53,"id":13010314}]}]}
{"op":"mcm","clk":"1008547881","pt":1580636892247,"mc":[{"id":"1.168224424","rc":[{"batb":[[0,4.1,20.93],[1,4,68.06],[2,1.01,0.51]],"batl":[[0,4.8,10.92]],"ltp":0.0,"tv":0.0,"id":13010313},{"batb":[[0,5.6,20.54],[1,5.5,25.42],[2,5.2,9.24]],"batl":[[1,7,17.55],[2,7,0]],"ltp":6.0,"tv":15.14,"id":16575966},{"batb":[[0,4.4,11.76],[1,3.95,23.37],[2,1.01,0.51]],"batl":[[0,5.3,9.24],[1,5.6,13.53],[2,5.6,0]],"ltp":0.0,"tv":0.0,"id":16575965},{"batb":[[0,2.42,29.41],[1,2.22,21.09],[2,1.01,0.51]],"batl":[[0,2.76,23.53],[1,2.78,13.53],[2,2.78,0]],"ltp":2.06,"tv":2.53,"id":13010314}]}]}
{"op":"mcm","clk":"1008547944","pt":1580636893431,"mc":[{"id":"1.168224424","rc":[{"batb":[[1,4,54.62]],"batl":[[0,5,17.86],[1,5,0]],"ltp":0.0,"tv":0.0,"id":13010313},{"batb":[[2,1.01,0.51]],"batl":[[0,7,17.55],[1,7,0]],"ltp":6.0,"tv":15.14,"id":16575966},{"batb":[[0,3.95,23.37],[1,1.01,0.51],[2,1.01,0]],"batl":[[0,5.6,13.53],[1,5.6,0]],"ltp":0.0,"tv":0.0,"id":16575965},{"batb":[[0,2.22,21.09],[1,1.01,0.51],[2,1.01,0]],"batl":[[0,2.78,13.53],[1,2.78,0]],"ltp":2.06,"tv":2.53,"id":13010314}]}]}
{"op":"mcm","clk":"1008548023","pt":1580636894819,"mc":[{"id":"1.168224424","rc":[{"batb":[[2,3.95,28.26]],"ltp":0.0,"tv":0.0,"id":13010313},{"batb":[[2,5.4,26.33]],"ltp":6.0,"tv":15.14,"id":16575966},{"batb":[[0,4.2,70.21],[1,4.1,48.85],[2,3.95,23.37]],"ltp":0.0,"tv":0.0,"id":16575965},{"batb":[[0,2.32,78.57],[1,2.3,44.83],[2,2.22,21.09]],"ltp":2.06,"tv":2.53,"id":13010314}]}]}
{"op":"mcm","clk":"1008548213","pt":1580636898070,"mc":[{"id":"1.168224424","rc":[{"batb":[[2,1.01,0.51]],"ltp":0.0,"tv":0.0,"id":13010313},{"batb":[[2,1.01,0.51]],"ltp":6.0,"tv":15.14,"id":16575966},{"batb":[[0,3.95,23.37],[1,1.01,0.51],[2,3.95,0]],"ltp":0.0,"tv":0.0,"id":16575965},{"batb":[[0,2.22,21.09],[1,1.01,0.51],[2,2.22,0]],"ltp":2.06,"tv":2.53,"id":13010314}]}]}
{"op":"mcm","clk":"1008548366","pt":1580636901049,"mc":[{"id":"1.168224424","rc":[{"batb":[[2,3.95,28.26]],"ltp":0.0,"tv":0.0,"id":13010313},{"batb":[[2,5.4,26.33]],"ltp":6.0,"tv":15.14,"id":16575966},{"batb":[[0,4.2,70.21],[1,4.1,48.85],[2,3.95,23.37]],"ltp":0.0,"tv":0.0,"id":16575965},{"batb":[[0,2.7,42.37],[1,2.66,60.21],[2,2.22,21.09]],"ltp":2.06,"tv":2.53,"id":13010314}]}]}
{"op":"mcm","clk":"1008548413","pt":1580636901870,"mc":[{"id":"1.168224424","rc":[{"batb":[[2,3.95,41.7]],"batl":[[0,4.7,10.92],[1,4.8,18.96]],"ltp":0.0,"tv":0.0,"id":13010313},{"batb":[[0,5.6,10.31]],"batl":[[0,6.2,7.56],[1,6.8,17.94]],"ltp":6.0,"tv":15.14,"id":16575966},{"batb":[[1,4.1,62.29]],"batl":[[0,4.5,22.11],[1,5,10.08],[2,5.1,17.07]],"ltp":0.0,"tv":0.0,"id":16575965},{"batb":[[2,2.6,13.77]],"batl":[[1,2.88,21.85],[2,2.92,11.88]],"ltp":2.06,"tv":2.53,"id":13010314}]}]}
{"op":"mcm","clk":"1008549060","pt":1580636914356,"mc":[{"id":"1.168224424","rc":[{"batb":[[1,4,28.86]],"ltp":0.0,"tv":0.0,"id":13010313},{"batb":[[1,5.4,26.33],[2,5.2,9.24]],"ltp":6.0,"tv":15.14,"id":16575966},{"batb":[[0,4.1,13.44],[1,3.75,13.22],[2,1.01,0.51]],"batl":[[0,5,10.08],[1,5.1,17.07],[2,5.1,0]],"ltp":0.0,"tv":0.0,"id":16575965},{"batb":[[0,2.54,26.89],[1,2.38,17.47],[2,1.01,0.51]],"batl":[[0,2.88,21.85],[1,2.92,11.88],[2,2.92,0]],"ltp":2.06,"tv":2.53,"id":13010314}]}]}
{"op":"mcm","clk":"1008549102","pt":1580636914971,"mc":[{"id":"1.168224424","rc":[{"batb":[[2,3.95,28.26]],"batl":[[0,4.8,18.96],[1,4.8,0]],"ltp":0.0,"tv":0.0,"id":13010313},{"batb":[[2,1.01,0.51]],"batl":[[0,6.8,17.94],[1,6.8,0]],"ltp":6.0,"tv":15.14,"id":16575966},{"batb":[[0,3.75,13.22],[1,1.01,0.51],[2,1.01,0]],"batl":[[0,5.1,17.07],[1,5.1,0]],"ltp":0.0,"tv":0.0,"id":16575965},{"batb":[[0,2.38,17.47],[1,1.01,0.51],[2,1.01,0]],"batl":[[0,2.92,11.88],[1,2.92,0]],"ltp":2.06,"tv":2.53,"id":13010314}]}]}
{"op":"mcm","clk":"1008549245","pt":1580636917086,"mc":[{"id":"1.168224424","rc":[{"batb":[[1,5.4,45.2],[2,5.3,27.25]],"ltp":6.0,"tv":15.14,"id":16575966},{"batb":[[0,4,66.41],[1,3.95,27.07],[2,3.75,13.22]],"ltp":0.0,"tv":0.0,"id":16575965},{"batb":[[0,2.5,41.78],[1,2.46,74.09],[2,2.38,17.47]],"ltp":2.06,"tv":2.53,"id":13010314}]}]}
{"op":"mcm","clk":"1008549428","pt":1580636920378,"mc":[{"id":"1.168224424","rc":[{"batb":[[1,5.4,26.33],[2,1.01,0.51]],"ltp":6.0,"tv":15.14,"id":16575966},{"batb":[[0,3.75,13.22],[1,1.01,0.51],[2,3.75,0]],"ltp":0.0,"tv":0.0,"id":16575965},{"batb":[[0,2.38,17.47],[1,1.01,0.51],[2,2.38,0]],"ltp":2.06,"tv":2.53,"id":13010314}]}]}
{"op":"mcm","clk":"1008549459","pt":1580636921002,"mc":[{"id":"1.168224424","rc":[{"batb":[[0,2.78,7],[1,2.38,17.47],[2,1.01,0.51]],"ltp":2.06,"tv":2.53,"id":13010314}]}]}
{"op":"mcm","clk":"1008549581","pt":1580636923362,"mc":[{"id":"1.168224424","rc":[{"batb":[[1,4,58.51]],"ltp":0.0,"tv":0.0,"id":13010313},{"batb":[[1,5.5,36.34],[2,5.4,26.33]],"ltp":6.0,"tv":15.14,"id":16575966},{"batb":[[0,4.3,61.04],[1,4.2,46.31],[2,3.75,13.22]],"ltp":0.0,"tv":0.0,"id":16575965},{"batb":[[1,2.66,38.56],[2,2.62,62.67]],"ltp":2.06,"tv":2.53,"id":13010314}]}]}
{"op":"mcm","clk":"1008549646","pt":1580636924384,"mc":[{"id":"1.168224424","rc":[{"batb":[[1,4,28.86]],"ltp":0.0,"tv":0.0,"id":13010313},{"batb":[[1,5.4,26.33],[2,1.01,0.51]],"ltp":6.0,"tv":15.14,"id":16575966},{"batb":[[0,3.75,13.22],[1,1.01,0.51],[2,3.75,0]],"ltp":0.0,"tv":0.0,"id":16575965},{"batb":[[1,2.38,17.47],[2,1.01,0.51]],"ltp":2.06,"tv":2.53,"id":13010314}]}]}
{"op":"mcm","clk":"1008549807","pt":1580636927793,"mc":[{"id":"1.168224424","rc":[{"batb":[[1,5.4,45.2],[2,5.3,27.25]],"ltp":6.0,"tv":15.14,"id":16575966},{"batb":[[0,4,66.41],[1,3.95,27.07],[2,3.75,13.22]],"ltp":0.0,"tv":0.0,"id":16575965},{"batb":[[1,2.5,41.78],[2,2.46,74.09]],"ltp":2.06,"tv":2.53,"id":13010314}]}]}
{"op":"mcm","clk":"1008549947","pt":1580636930371,"mc":[{"id":"1.168224424","rc":[{"batb":[[1,5.4,26.33],[2,1.01,0.51]],"ltp":6.0,"tv":15.14,"id":16575966},{"batb":[[0,3.75,13.22],[1,1.01,0.51],[2,3.75,0]],"ltp":0.0,"tv":0.0,"id":16575965},{"batb":[[1,2.38,17.47],[2,1.01,0.51]],"ltp":2.06,"tv":2.53,"id":13010314}]}]}
{"op":"mcm","clk":"1008549986","pt":1580636931093,"mc":[{"id":"1.168224424","rc":[{"batb":[[2,1.01,0.51]],"ltp":0.0,"tv":0.0,"id":13010313},{"batb":[[1,1.01,0.51],[2,1.01,0]],"ltp":6.0,"tv":15.14,"id":16575966}]}]}
{"op":"mcm","clk":"1008550130","pt":1580636933412,"mc":[{"id":"1.168224424","rc":[{"trd":[[4.1,4.75]],"batb":[[0,4.1,51.15],[1,4,54.47]],"ltp":4.1,"tv":4.74,"id":13010313},{"trd":[[5.6,3.48]],"batb":[[0,5.6,36.71],[1,5.5,25.29],[2,1.01,0.51]],"ltp":5.6,"tv":18.62,"id":16575966},{"trd":[[4.6,4.23]],"batb":[[0,4.7,41.64],[1,4.6,37.7],[2,3.75,13.22]],"ltp":4.6,"tv":4.23,"id":16575965},{"trd":[[2.78,7]],"batb":[[0,2.5,41.78],[1,2.46,74.09],[2,2.38,17.47]],"ltp":2.78,"tv":9.53,"id":13010314}],"tv":37.12}]}
{"op":"mcm","clk":"1008550179","pt":1580636934187,"mc":[{"id":"1.168224424","rc":[{"batb":[[0,4.2,19.91],[1,4.1,51.15],[2,4,67.91]],"batl":[[0,4.7,10.92],[1,4.8,18.96],[2,5,17.39]],"ltp":4.1,"tv":4.74,"id":13010313},{"batb":[[0,5.7,19.83],[1,5.6,29.88],[2,5.5,25.29]],"batl":[[0,6.4,7.56],[1,7,17.39]],"ltp":5.6,"tv":18.62,"id":16575966},{"batb":[[2,4.5,11.76]],"batl":[[1,6.2,11.25]],"ltp":4.6,"tv":4.23,"id":16575965},{"batl":[[0,2.54,17.15],[1,2.72,14.24]],"ltp":2.78,"tv":9.53,"id":13010314}]}]}
{"op":"mcm","clk":"1008550366","pt":1580636937324,"mc":[{"id":"1.168224424","rc":[{"batl":[[1,5.5,9.24],[2,6.2,11.25]],"ltp":4.6,"tv":4.23,"id":16575965},{"batb":[[2,2.38,47.71]],"batl":[[1,2.7,24.37],[2,2.72,14.24]],"ltp":2.78,"tv":9.53,"id":13010314}]}]}
{"op":"mcm","clk":"1008550995","pt":1580636947507,"mc":[{"id":"1.168224424","rc":[{"batb":[[0,4.1,16.18],[1,4,67.91],[2,1.01,0.51]],"batl":[[1,5,17.39],[2,5,0]],"ltp":4.1,"tv":4.74,"id":13010313},{"batb":[[1,5.5,25.29],[2,5.3,9.24]],"ltp":5.6,"tv":18.62,"id":16575966},{"batb":[[0,4.5,11.76],[1,4,22.19],[2,1.01,0.51]],"batl":[[0,5.5,9.24],[1,6.2,11.25],[2,6.2,0]],"ltp":4.6,"tv":4.23,"id":16575965},{"batb":[[0,2.38,30.25],[1,2.14,23.68],[2,1.01,0.51]],"batl":[[0,2.7,24.37],[1,2.72,14.24],[2,2.72,0]],"ltp":2.78,"tv":9.53,"id":13010314}]}]}
{"op":"mcm","clk":"1008551078","pt":1580636948903,"mc":[{"id":"1.168224424","rc":[{"batb":[[1,4,54.47]],"batl":[[0,5,17.39],[1,5,0]],"ltp":4.1,"tv":4.74,"id":13010313},{"batb":[[2,1.01,0.51]],"batl":[[0,7,17.39],[1,7,0]],"ltp":5.6,"tv":18.62,"id":16575966},{"batb":[[0,4,22.19],[1,1.01,0.51],[2,1.01,0]],"batl":[[0,6.2,11.25],[1,6.2,0]],"ltp":4.6,"tv":4.23,"id":16575965},{"batb":[[0,2.14,23.68],[1,1.01,0.51],[2,1.01,0]],"batl":[[0,2.72,14.24],[1,2.72,0]],"ltp":2.78,"tv":9.53,"id":13010314}]}]}
{"op":"mcm","clk":"1008551173","pt":1580636950407,"mc":[{"id":"1.168224424","rc":[{"batb":[[2,3.95,28.26]],"ltp":4.1,"tv":4.74,"id":13010313},{"batb":[[1,5.6,19.99],[2,5.5,37.83]],"batl":[[0,6.8,17.55],[1,7,17.39]],"ltp":5.6,"tv":18.62,"id":16575966},{"batb":[[0,4.3,50.11],[1,4.2,46.49],[2,4,22.19]],"ltp":4.6,"tv":4.23,"id":16575965},{"batb":[[0,2.24,57.88],[1,2.22,49.58],[2,2.14,23.68]],"batl":[[1,2.74,14.16]],"ltp":2.78,"tv":9.53,"id":13010314}]}]}
{"op":"mcm","clk":"1008551192","pt":1580636950716,"mc":[{"id":"1.168224424","rc":[{"batb":[[0,5.6,19.99],[1,5.5,37.83],[2,5.4,26.24]],"batl":[[1,7,0]],"ltp":5.6,"tv":18.62,"id":16575966},{"batb":[[2,4,22.03]],"ltp":4.6,"tv":4.23,"id":16575965},{"batb":[[2,2.14,23.53]],"batl":[[0,2.74,14.16],[1,2.74,0]],"ltp":2.78,"tv":9.53,"id":13010314}]}]}
{"op":"mcm","clk":"1008551332","pt":1580636953340,"mc":[{"id":"1.168224424","rc":[{"batb":[[0,2.14,23.53],[1,1.01,0.51],[2,2.14,0]],"ltp":2.78,"tv":9.53,"id":13010314}]}]}
{"op":"mcm","clk":"1008551527","pt":1580636956339,"mc":[{"id":"1.168224424","rc":[{"batb":[[0,2.66,59.66],[1,2.62,62.55],[2,2.14,23.53]],"ltp":2.78,"tv":9.53,"id":13010314}]}]}
{"op":"mcm","clk":"1008551575","pt":1580636957118,"mc":[{"id":"1.168224424","rc":[{"batb":[[1,4,76.26]],"batl":[[0,4.7,20.06],[1,4.8,18.88]],"ltp":4.1,"tv":4.74,"id":13010313},{"batl":[[0,4.6,20.93],[1,5.3,15.19]],"ltp":4.6,"tv":4.23,"id":16575965},{"batb":[[2,2.56,14.48]],"batl":[[1,2.9,12.27]],"ltp":2.78,"tv":9.53,"id":13010314}]}]}
{"op":"mcm","clk":"1008551614","pt":1580636957952,"mc":[{"id":"1.168224424","rc":[{"batb":[[2,3.95,41.7]],"batl":[[0,4.7,30.99]],"ltp":4.1,"tv":4.74,"id":13010313},{"batl":[[0,6.4,7.56],[1,6.8,17.55]],"ltp":5.6,"tv":18.62,"id":16575966},{"batb":[[1,4.2,59.09]],"batl":[[1,5,10.08],[2,5.3,15.19]],"ltp":4.6,"tv":4.23,"id":16575965},{"batl":[[1,2.86,21.85],[2,2.9,12.27]],"ltp":2.78,"tv":9.53,"id":13010314}]}]}
{"op":"mcm","clk":"1008552425","pt":1580636970046,"mc":[{"id":"1.168224424","rc":[{"batb":[[0,4,21.79],[1,3.95,41.7],[2,1.01,0.51]],"batl":[[0,4.7,10.92]],"ltp":4.1,"tv":4.74,"id":13010313},{"batb":[[1,5.5,25.29]],"ltp":5.6,"tv":18.62,"id":16575966},{"batb":[[0,4.2,12.6],[1,3.85,12.9],[2,1.01,0.51]],"batl":[[0,5,10.08],[1,5.3,15.19],[2,5.3,0]],"ltp":4.6,"tv":4.23,"id":16575965},{"batb":[[0,2.5,27.73],[1,2.32,18.88],[2,1.01,0.51]],"batl":[[0,2.86,21.85],[1,2.9,12.27],[2,2.9,0]],"ltp":2.78,"tv":9.53,"id":13010314}]}]}
{"op":"mcm","clk":"1008552482","pt":1580636970977,"mc":[{"id":"1.168224424","rc":[{"batb":[[1,3.95,28.26]],"batl":[[0,4.8,18.88],[1,4.8,0]],"ltp":4.1,"tv":4.74,"id":13010313},{"batl":[[0,6.8,17.55],[1,6.8,0]],"ltp":5.6,"tv":18.62,"id":16575966},{"batb":[[0,3.85,12.9],[1,1.01,0.51],[2,1.01,0]],"batl":[[0,5.3,15.19],[1,5.3,0]],"ltp":4.6,"tv":4.23,"id":16575965},{"batb":[[0,2.32,18.88],[1,1.01,0.51],[2,1.01,0]],"batl":[[0,2.9,12.27],[1,2.9,0]],"ltp":2.78,"tv":9.53,"id":13010314}]}]}
{"op":"mcm","clk":"1008552630","pt":1580636973455,"mc":[{"id":"1.168224424","rc":[{"batb":[[1,3.95,51.84],[2,3.9,29.11]],"ltp":4.1,"tv":4.74,"id":13010313},{"batb":[[0,4,74.33],[1,3.95,26.99],[2,3.85,12.9]],"ltp":4.6,"tv":4.23,"id":16575965}]}]}
{"op":"mcm","clk":"1008552856","pt":1580636976355,"mc":[{"id":"1.168224424","rc":[{"batb":[[2,3.9,43.39]],"batl":[[0,4.6,10.92],[1,4.7,20.22],[2,4.8,18.88]],"ltp":4.1,"tv":4.74,"id":13010313},{"batb":[[1,5.5,35.75]],"batl":[[0,6.2,7.56],[1,6.8,17.55]],"ltp":5.6,"tv":18.62,"id":16575966},{"batb":[[1,3.95,40.43]],"batl":[[0,4.3,24.31],[1,4.7,31.22],[2,5.3,15.19]],"ltp":4.6,"tv":4.23,"id":16575965},{"batb":[[0,2.82,39.68],[1,2.78,53.72],[2,2.7,12.51]],"batl":[[1,3.05,31.1]],"ltp":2.78,"tv":9.53,"id":13010314}]}]}
{"op":"mcm","clk":"1008552865","pt":1580636976562,"mc":[{"id":"1.168224424","rc":[{"batl":[[2,4.8,0]],"ltp":4.1,"tv":4.74,"id":13010313},{"batb":[[0,5.5,35.75],[1,5.4,26.24],[2,5.1,10.08]],"ltp":5.6,"tv":18.62,"id":16575966},{"batl":[[2,5.3,0]],"ltp":4.6,"tv":4.23,"id":16575965}]}]}
{"op":"mcm","clk":"1008553440","pt":1580636985455,"mc":[{"id":"1.168224424","rc":[{"batb":[[1,3.95,40.91]],"ltp":4.1,"tv":4.74,"id":13010313},{"batb":[[0,5.5,10.46]],"ltp":5.6,"tv":18.62,"id":16575966},{"batb":[[0,3.95,40.43],[1,3.7,14.16],[2,1.01,0.51]],"batl":[[0,4.7,31.22],[1,4.7,0]],"ltp":4.6,"tv":4.23,"id":16575965},{"batb":[[0,2.64,25.21],[1,2.54,14.71],[2,1.01,0.51]],"batl":[[0,3.05,31.1],[1,3.05,0]],"ltp":2.78,"tv":9.53,"id":13010314}]}]}
{"op":"mcm","clk":"1008553535","pt":1580636986955,"mc":[{"id":"1.168224424","rc":[{"batb":[[2,3.9,29.11]],"batl":[[0,4.7,20.22],[1,4.7,0]],"ltp":4.1,"tv":4.74,"id":13010313},{"batb":[[2,1.01,0.51]],"batl":[[0,6.8,17.55],[1,6.8,0]],"ltp":5.6,"tv":18.62,"id":16575966},{"batb":[[0,3.95,26.99]],"batl":[[0,4.7,20.3]],"ltp":4.6,"tv":4.23,"id":16575965},{"batb":[[0,2.54,14.71],[1,1.01,0.51],[2,1.01,0]],"batl":[[0,3.05,10.94]],"ltp":2.78,"tv":9.53,"id":13010314}]}]}
{"op":"mcm","clk":"1008553629","pt":1580636988300,"mc":[{"id":"1.168224424","rc":[{"batb":[[1,5.4,39.1],[2,5.3,27.34]],"ltp":5.6,"tv":18.62,"id":16575966},{"batb":[[1,3.9,28.22],[2,3.7,14.16]],"ltp":4.6,"tv":4.23,"id":16575965},{"batb":[[0,2.66,57.26],[1,2.62,62.56],[2,2.54,14.71]],"ltp":2.78,"tv":9.53,"id":13010314}]}]}
{"op":"mcm","clk":"1008554620","pt":1580637003315,"mc":[{"id":"1.168224424","rc":[{"batb":[[0,2.54,14.71],[1,1.01,0.51],[2,2.54,0]],"ltp":2.78,"tv":9.53,"id":13010314}]}]}
{"op":"mcm","clk":"1008554846","pt":1580637006431,"mc":[{"id":"1.168224424","rc":[{"batb":[[0,2.9,49.08],[1,2.86,49.89],[2,2.54,14.71]],"ltp":2.78,"tv":9.53,"id":13010314}]}]}
{"op":"mcm","clk":"1008554909","pt":1580637007313,"mc":[{"id":"1.168224424","rc":[{"batb":[[1,3.95,64.51]],"batl":[[0,4.6,20.54]],"ltp":4.1,"tv":4.74,"id":13010313},{"batl":[[0,6.6,19.36]],"ltp":5.6,"tv":18.62,"id":16575966},{"batl":[[0,4.1,13.77],[1,4.5,22.66]],"ltp":4.6,"tv":4.23,"id":16575965},{"batb":[[2,2.84,11.17]],"batl":[[1,3.5,19.75]],"ltp":2.78,"tv":9.53,"id":13010314}]}]}
{"op":"mcm","clk":"1008554963","pt":1580637007926,"mc":[{"id":"1.168224424","rc":[{"batb":[[2,3.9,43.39]],"batl":[[0,4.6,31.46]],"ltp":4.1,"tv":4.74,"id":13010313},{"batl":[[0,6,8.4],[1,6.6,19.36]],"ltp":5.6,"tv":18.62,"id":16575966},{"batb":[[2,3.75,15.12]],"batl":[[1,4.4,11.76],[2,4.5,22.66]],"ltp":4.6,"tv":4.23,"id":16575965},{"batl":[[1,3.2,18.48],[2,3.5,19.75]],"ltp":2.78,"tv":9.53,"id":13010314}]}]}
{"op":"mcm","clk":"1008556072","pt":1580637022417,"mc":[{"id":"1.168224424","rc":[{"batb":[[2,2.82,11.17]],"ltp":2.78,"tv":9.53,"id":13010314}]}]}
{"op":"mcm","clk":"1008560472","pt":1580637096345,"mc":[{"id":"1.168224424","rc":[{"batb":[[0,3.95,23.6],[1,3.9,14.28],[2,1.01,0.51]],"ltp":4.1,"tv":4.74,"id":13010313},{"batb":[[1,5.3,27.34],[2,5,10.08]],"ltp":5.6,"tv":18.62,"id":16575966},{"batb":[[0,3.75,15.12],[1,3.25,19.12],[2,1.01,0.51]],"batl":[[0,4.4,11.76],[1,4.5,22.66],[2,4.5,0]],"ltp":4.6,"tv":4.23,"id":16575965},{"batb":[[0,2.78,23.53],[1,2.66,13.14],[2,1.01,0.51]],"batl":[[0,3.2,18.48],[1,3.5,19.75],[2,3.5,0]],"ltp":2.78,"tv":9.53,"id":13010314}]}]}
{"op":"mcm","clk":"1008560517","pt":1580637097062,"mc":[{"id":"1.168224424","rc":[{"batb":[[1,1.01,0.51],[2,1.01,0]],"batl":[[0,4.6,20.54]],"ltp":4.1,"tv":4.74,"id":13010313},{"batb":[[2,1.01,0.51]],"batl":[[0,6.6,19.36],[1,6.6,0]],"ltp":5.6,"tv":18.62,"id":16575966},{"batb":[[0,3.25,19.12],[1,1.01,0.51],[2,1.01,0]],"batl":[[0,4.5,22.66],[1,4.5,0]],"ltp":4.6,"tv":4.23,"id":16575965},{"batb":[[0,2.66,13.14],[1,1.01,0.51],[2,1.01,0]],"batl":[[0,3.5,19.75],[1,3.5,0]],"ltp":2.78,"tv":9.53,"id":13010314}]}]}
{"op":"mcm","clk":"1008560635","pt":1580637098860,"mc":[{"id":"1.168224424","rc":[{"batb":[[1,3.85,52.96],[2,3.8,30.92]],"ltp":4.1,"tv":4.74,"id":13010313},{"batb":[[1,5.3,42.51],[2,5.2,28.49]],"ltp":5.6,"tv":18.62,"id":16575966},{"batb":[[0,3.5,42.95],[1,3.45,37.77],[2,3.25,19.12]],"ltp":4.6,"tv":4.23,"id":16575965},{"batb":[[0,2.74,54.8],[1,2.7,57.84],[2,2.66,13.14]],"ltp":2.78,"tv":9.53,"id":13010314}]}]}
{"op":"mcm","clk":"1008561454","pt":1580637112084,"mc":[{"id":"1.168224424","rc":[{"batb":[[1,1.01,0.51],[2,3.8,0]],"ltp":4.1,"tv":4.74,"id":13010313},{"batb":[[1,1.01,0.51],[2,5.2,0]],"ltp":5.6,"tv":18.62,"id":16575966},{"batb":[[0,3.25,19.12],[1,1.01,0.51],[2,3.25,0]],"ltp":4.6,"tv":4.23,"id":16575965}]}]}
{"op":"mcm","clk":"1008561662","pt":1580637115374,"mc":[{"id":"1.168224424","rc":[{"batb":[[0,4,36.13],[1,3.95,51.98],[2,1.01,0.51]],"ltp":4.1,"tv":4.74,"id":13010313},{"batb":[[0,5.5,35.01],[1,5.4,26.43],[2,1.01,0.51]],"ltp":5.6,"tv":18.62,"id":16575966},{"batb":[[0,4.2,34.57],[1,4.1,49.47],[2,3.25,19.12]],"ltp":4.6,"tv":4.23,"id":16575965}]}]}
{"op":"mcm","clk":"1008561696","pt":1580637116045,"mc":[{"id":"1.168224424","rc":[{"batb":[[0,4,58.95],[1,3.95,28.38],[2,3.9,14.28]],"batl":[[1,4.7,31.07]],"ltp":4.1,"tv":4.74,"id":13010313},{"batb":[[2,5,10.08]],"batl":[[0,6.2,7.56],[1,6.6,18.65]],"ltp":5.6,"tv":18.62,"id":16575966},{"batb":[[2,3.95,37.36]],"batl":[[1,4.7,30.99]],"ltp":4.6,"tv":4.23,"id":16575965},{"batb":[[2,2.68,24.37]],"batl":[[0,2.84,12.9],[1,3.05,20.16],[2,3.2,24.55]],"ltp":2.78,"tv":9.53,"id":13010314}]}]}
{"op":"mcm","clk":"1008561998","pt":1580637121390,"mc":[{"id":"1.168224424","rc":[{"trd":[[2.74,47.72]],"batb":[[0,2.74,30.94]],"ltp":2.74,"tv":57.25,"id":13010314}],"tv":84.84}]}
{"op":"mcm","clk":"1008562171","pt":1580637123872,"mc":[{"id":"1.168224424","rc":[{"batb":[[0,2.74,50.2]],"ltp":2.74,"tv":57.25,"id":13010314}]}]}
{"op":"mcm","clk":"1008562687","pt":1580637132212,"mc":[{"id":"1.168224424","rc":[{"batb":[[0,4,22.82]],"batl":[[0,4.7,31.07],[1,4.7,0]],"ltp":4.1,"tv":4.74,"id":13010313},{"batb":[[0,5.5,10.46]],"ltp":5.6,"tv":18.62,"id":16575966},{"batb":[[0,3.95,13.44],[1,3.55,15.58],[2,1.01,0.51]],"batl":[[0,4.7,30.99],[1,4.7,0]],"ltp":4.6,"tv":4.23,"id":16575965},{"batb":[[0,2.68,24.37],[1,2.54,14.79],[2,1.01,0.51]],"batl":[[0,3.05,20.16],[1,3.2,24.55],[2,3.2,0]],"ltp":2.74,"tv":57.25,"id":13010314}]}]}
{"op":"mcm","clk":"1008562760","pt":1580637133063,"mc":[{"id":"1.168224424","rc":[{"batb":[[2,1.01,0.51]],"batl":[[0,4.7,20.14]],"ltp":4.1,"tv":4.74,"id":13010313},{"batb":[[2,1.01,0.51]],"batl":[[0,6.6,18.65],[1,6.6,0]],"ltp":5.6,"tv":18.62,"id":16575966},{"batb":[[0,3.55,15.58],[1,1.01,0.51],[2,1.01,0]],"batl":[[0,4.7,20.06]],"ltp":4.6,"tv":4.23,"id":16575965},{"batb":[[0,2.54,14.79],[1,1.01,0.51],[2,1.01,0]],"batl":[[0,3.2,24.55],[1,3.2,0]],"ltp":2.74,"tv":57.25,"id":13010314}]}]}
{"op":"mcm","clk":"1008562918","pt":1580637135392,"mc":[{"id":"1.168224424","rc":[{"batb":[[2,3.9,29.28]],"ltp":4.1,"tv":4.74,"id":13010313},{"batb":[[2,5.3,27.49]],"ltp":5.6,"tv":18.62,"id":16575966},{"batb":[[0,3.8,44.79],[1,3.75,30.87],[2,3.55,15.58]],"ltp":4.6,"tv":4.23,"id":16575965},{"batb":[[0,2.64,38.73],[1,2.6,63.92],[2,2.54,14.79]],"ltp":2.74,"tv":57.25,"id":13010314}]}]}
{"op":"mcm","clk":"1008563005","pt":1580637136983,"mc":[{"id":"1.168224424","rc":[{"batb":[[2,1.01,0.51]],"ltp":4.1,"tv":4.74,"id":13010313},{"batb":[[2,1.01,0.51]],"ltp":5.6,"tv":18.62,"id":16575966},{"batb":[[0,3.55,15.58],[1,1.01,0.51],[2,3.55,0]],"ltp":4.6,"tv":4.23,"id":16575965}]}]}
{"op":"mcm","clk":"1008563274","pt":1580637140388,"mc":[{"id":"1.168224424","rc":[{"batb":[[0,4.1,21.64],[1,4,77.22],[2,3.95,41.82]],"batl":[[0,4.7,31.07]],"ltp":4.1,"tv":4.74,"id":13010313},{"batb":[[0,5.6,19.99],[1,5.5,46.77],[2,5.4,26.43]],"batl":[[0,6.2,7.56],[1,6.6,18.65],[2,6.8,18.49]],"ltp":5.6,"tv":18.62,"id":16575966},{"batb":[[0,4.4,44.21],[1,4.3,44.12],[2,4.2,12.6]],"batl":[[1,4.9,18.1],[2,5,10.08]],"ltp":4.6,"tv":4.23,"id":16575965},{"batb":[[2,2.56,26.89]],"batl":[[0,2.7,14.48],[1,2.92,12.04],[2,2.94,21]],"ltp":2.74,"tv":57.25,"id":13010314}]}]}
{"op":"mcm","clk":"1008563291","pt":1580637140598,"mc":[{"id":"1.168224424","rc":[{"batb":[[1,4,54.4]],"ltp":4.1,"tv":4.74,"id":13010313},{"batl":[[1,6.8,18.49],[2,6.8,0]],"ltp":5.6,"tv":18.62,"id":16575966}]}]}
{"op":"mcm","clk":"1008563884","pt":1580637149220,"mc":[{"id":"1.168224424","rc":[{"batb":[[1,4,36.46],[2,3.95,28.38]],"batl":[[0,4.7,20.14]],"ltp":4.1,"tv":4.74,"id":13010313},{"batb":[[0,5.5,10.46],[1,5.4,26.43],[2,1.01,0.51]],"batl":[[0,6.8,18.49],[1,6.8,0]],"ltp":5.6,"tv":18.62,"id":16575966},{"batb":[[0,3.8,13.14],[1,1.01,0.51],[2,4.2,0]],"batl":[[0,4.9,18.1],[1,4.9,0],[2,5,0]],"ltp":4.6,"tv":4.23,"id":16575965},{"batb":[[0,2.46,15.97],[1,1.01,0.51],[2,2.56,0]],"batl":[[0,2.92,12.04],[1,2.92,0],[2,2.94,0]],"ltp":2.74,"tv":57.25,"id":13010314}]}]}
{"op":"mcm","clk":"1008564051","pt":1580637152021,"mc":[{"id":"1.168224424","rc":[{"batb":[[1,5.4,44.63],[2,5.3,27.28]],"ltp":5.6,"tv":18.62,"id":16575966},{"batb":[[0,4.1,47.79],[1,4,52.21],[2,3.8,13.14]],"ltp":4.6,"tv":4.23,"id":16575965},{"batb":[[0,2.56,60.6],[1,2.52,69.32],[2,2.46,15.97]],"ltp":2.74,"tv":57.25,"id":13010314}]}]}
{"op":"mcm","clk":"1008564238","pt":1580637154912,"mc":[{"id":"1.168224424","rc":[{"batb":[[1,1.01,0.51],[2,5.3,0]],"ltp":5.6,"tv":18.62,"id":16575966},{"batb":[[0,3.8,13.14],[1,1.01,0.51],[2,3.8,0]],"ltp":4.6,"tv":4.23,"id":16575965}]}]}
{"op":"mcm","clk":"1008564373","pt":1580637157435,"mc":[{"id":"1.168224424","rc":[{"batb":[[1,4,63.31]],"ltp":4.1,"tv":4.74,"id":13010313},{"batb":[[0,5.6,19.61],[1,5.5,35.92],[2,1.01,0.51]],"ltp":5.6,"tv":18.62,"id":16575966},{"batb":[[0,4.6,27.03],[1,4.5,39.99],[2,3.8,13.14]],"ltp":4.6,"tv":4.23,"id":16575965}]}]}
{"op":"mcm","clk":"1008564427","pt":1580637158315,"mc":[{"id":"1.168224424","rc":[{"batb":[[0,4.1,21.24],[2,3.95,41.82]],"batl":[[0,4.7,30.75]],"ltp":4.1,"tv":4.74,"id":13010313},{"batb":[[0,5.6,30],[1,5.5,25.46],[2,5.1,10.08]],"batl":[[0,6.2,7.56],[1,6.8,18.33]],"ltp":5.6,"tv":18.62,"id":16575966},{"batb":[[2,4.3,31.57]],"batl":[[1,5.1,16.84],[2,5.2,9.24]],"ltp":4.6,"tv":4.23,"id":16575965},{"batb":[[2,2.5,27.73]],"batl":[[0,2.62,15.66],[1,2.78,13.61],[2,2.84,22.69]],"ltp":2.74,"tv":57.25,"id":13010314}]}]}
{"op":"mcm","clk":"1008565360","pt":1580637172448,"mc":[{"id":"1.168224424","rc":[{"batb":[[0,5.6,10.39]],"ltp":5.6,"tv":18.62,"id":16575966},{"batb":[[0,4.5,39.99],[1,4.3,18.96],[2,4,22.5]],"ltp":4.6,"tv":4.23,"id":16575965},{"batb":[[0,2.5,27.73],[1,2.46,15.97],[2,2.42,16.92]],"ltp":2.74,"tv":57.25,"id":13010314}]}]}
{"op":"mcm","clk":"1008565422","pt":1580637173442,"mc":[{"id":"1.168224424","rc":[{"batb":[[1,5.5,18.57]],"ltp":5.6,"tv":18.62,"id":16575966},{"batb":[[0,4,22.5],[1,1.01,0.51],[2,4,0]],"batl":[[0,5.1,16.84],[1,5.2,9.24],[2,5.2,0]],"ltp":4.6,"tv":4.23,"id":16575965},{"batb":[[1,2.42,16.92],[2,1.01,0.51]],"batl":[[0,2.78,13.61],[1,2.84,22.69],[2,2.84,0]],"ltp":2.74,"tv":57.25,"id":13010314}]}]}
{"op":"mcm","clk":"1008565566","pt":1580637175410,"mc":[{"id":"1.168224424","rc":[{"batb":[[1,4,73.85],[2,3.95,28.38]],"batl":[[0,4.7,19.83]],"ltp":4.1,"tv":4.74,"id":13010313},{"batb":[[1,5.5,27.66],[2,5.4,26.14]],"batl":[[0,6.8,18.33],[1,6.8,0]],"ltp":5.6,"tv":18.62,"id":16575966},{"batb":[[0,4.5,13.68],[1,4.4,53.18],[2,4,22.5]],"batl":[[1,5.2,0]],"ltp":4.6,"tv":4.23,"id":16575965},{"batb":[[0,2.58,46.72],[1,2.54,68.06],[2,2.42,16.92]],"batl":[[1,2.84,0]],"ltp":2.74,"tv":57.25,"id":13010314}]}]}
{"op":"mcm","clk":"1008565650","pt":1580637176338,"mc":[{"id":"1.168224424","rc":[{"batb":[[1,5.5,29.03]],"ltp":5.6,"tv":18.62,"id":16575966},{"batb":[[0,4.3,57.17],[1,4.2,46.12]],"ltp":4.6,"tv":4.23,"id":16575965},{"batb":[[0,2.54,51.69],[1,2.5,70.98]],"ltp":2.74,"tv":57.25,"id":13010314}]}]}
{"op":"mcm","clk":"1008565699","pt":1580637177009,"mc":[{"id":"1.168224424","rc":[{"batb":[[0,5.5,29.03],[1,5.4,26.14],[2,1.01,0.51]],"ltp":5.6,"tv":18.62,"id":16575966},{"batb":[[0,4,22.5],[1,1.01,0.51],[2,4,0]],"ltp":4.6,"tv":4.23,"id":16575965},{"batb":[[0,2.42,16.92],[1,1.01,0.51],[2,2.42,0]],"ltp":2.74,"tv":57.25,"id":13010314}]}]}
{"op":"mcm","clk":"1008565909","pt":1580637180422,"mc":[{"id":"1.168224424","rc":[{"batb":[[0,5.5,41.78]],"ltp":5.6,"tv":18.62,"id":16575966},{"batb":[[0,4.5,37.1],[1,4.4,41.7],[2,4,22.5]],"ltp":4.6,"tv":4.23,"id":16575965},{"batb":[[0,2.6,41.07],[1,2.56,66.69],[2,2.42,16.92]],"ltp":2.74,"tv":57.25,"id":13010314}]}]}
{"op":"mcm","clk":"1008565952","pt":1580637181227,"mc":[{"id":"1.168224424","rc":[{"batb":[[0,5.5,29.03]],"ltp":5.6,"tv":18.62,"id":16575966},{"batb":[[0,4,22.5],[1,1.01,0.51],[2,4,0]],"ltp":4.6,"tv":4.23,"id":16575965},{"batb":[[0,2.42,16.92],[1,1.01,0.51],[2,2.42,0]],"ltp":2.74,"tv":57.25,"id":13010314}]}]}
{"op":"mcm","clk":"1008566158","pt":1580637184171,"mc":[{"id":"1.168224424","rc":[{"batb":[[0,4.3,57.17],[1,4.2,46.12],[2,4,22.5]],"ltp":4.6,"tv":4.23,"id":16575965},{"batb":[[0,2.54,51.69],[1,2.5,70.98],[2,2.42,16.92]],"ltp":2.74,"tv":57.25,"id":13010314}]}]}
{"op":"mcm","clk":"1008566258","pt":1580637185668,"mc":[{"id":"1.168224424","rc":[{"batb":[[0,2.42,16.92],[1,1.01,0.51],[2,2.42,0]],"ltp":2.74,"tv":57.25,"id":13010314}]}]}
{"op":"mcm","clk":"1008566425","pt":1580637188348,"mc":[{"id":"1.168224424","rc":[{"batb":[[0,2.66,54.45],[1,2.62,62.66],[2,2.42,16.92]],"ltp":2.74,"tv":57.25,"id":13010314}]}]}
{"op":"mcm","clk":"1008566483","pt":1580637189174,"mc":[{"id":"1.168224424","rc":[{"batl":[[0,6.6,18.65]],"ltp":5.6,"tv":18.62,"id":16575966},{"batl":[[0,4.6,21.48],[1,4.8,19.67]],"ltp":4.6,"tv":4.23,"id":16575965},{"batb":[[2,2.6,13.85]],"batl":[[1,2.98,11.33]],"ltp":2.74,"tv":57.25,"id":13010314}]}]}
{"op":"mcm","clk":"1008566556","pt":1580637190057,"mc":[{"id":"1.168224424","rc":[{"batb":[[2,3.95,41.82]],"batl":[[0,4.7,30.75]],"ltp":4.1,"tv":4.74,"id":13010313},{"batb":[[2,5,10.08]],"batl":[[0,6.2,7.56],[1,6.6,18.65]],"ltp":5.6,"tv":18.62,"id":16575966},{"batb":[[2,4.1,13.44]],"batl":[[2,5,10.08]],"ltp":4.6,"tv":4.23,"id":16575965},{"batl":[[1,2.92,21.85],[2,2.98,11.33]],"ltp":2.74,"tv":57.25,"id":13010314}]}]}
{"op":"mcm","clk":"1008567632","pt":1580637205877,"mc":[{"id":"1.168224424","rc":[{"batb":[[1,4,63.31]],"ltp":4.1,"tv":4.74,"id":13010313},{"batb":[[0,5.5,10.46]],"ltp":5.6,"tv":18.62,"id":16575966},{"batb":[[0,4.1,13.44],[1,3.75,13.69],[2,1.01,0.51]],"batl":[[0,4.8,19.67],[1,5,10.08],[2,5,0]],"ltp":4.6,"tv":4.23,"id":16575965},{"batb":[[0,2.58,26.05],[1,2.52,15.03],[2,1.01,0.51]],"batl":[[0,2.92,21.85],[1,2.98,11.33],[2,2.98,0]],"ltp":2.74,"tv":57.25,"id":13010314}]}]}
{"op":"mcm","clk":"1008567723","pt":1580637207165,"mc":[{"id":"1.168224424","rc":[{"batb":[[2,3.95,28.38]],"batl":[[0,4.7,19.83]],"ltp":4.1,"tv":4.74,"id":13010313},{"batb":[[2,1.01,0.51]],"batl":[[0,6.6,18.65],[1,6.6,0]],"ltp":5.6,"tv":18.62,"id":16575966},{"batb":[[0,3.75,13.69],[1,1.01,0.51],[2,1.01,0]],"batl":[[1,5,0]],"ltp":4.6,"tv":4.23,"id":16575965},{"batb":[[0,2.52,15.03],[1,1.01,0.51],[2,1.01,0]],"batl":[[0,2.98,11.33],[1,2.98,0]],"ltp":2.74,"tv":57.25,"id":13010314}]}]}
{"op":"mcm","clk":"1008567827","pt":1580637208657,"mc":[{"id":"1.168224424","rc":[{"batb":[[2,5.3,27.36]],"ltp":5.6,"tv":18.62,"id":16575966}]}]}
{"op":"mcm","clk":"1008567983","pt":1580637211083,"mc":[{"id":"1.168224424","rc":[{"batb":[[1,5.4,42.61]],"ltp":5.6,"tv":18.62,"id":16575966},{"batb":[[0,4.3,37.74],[1,4.2,46.59],[2,3.75,13.69]],"ltp":4.6,"tv":4.23,"id":16575965},{"batb":[[0,2.68,54.67],[1,2.64,61.35],[2,2.52,15.03]],"ltp":2.74,"tv":57.25,"id":13010314}]}]}
{"op":"mcm","clk":"1008568034","pt":1580637212065,"mc":[{"id":"1.168224424","rc":[{"batb":[[1,5.4,26.44],[2,1.01,0.51]],"ltp":5.6,"tv":18.62,"id":16575966}]}]}
{"op":"mcm","clk":"1008568099","pt":1580637213407,"mc":[{"id":"1.168224424","rc":[{"batb":[[1,4,48.96]],"ltp":4.1,"tv":4.74,"id":13010313},{"batb":[[0,3.75,13.69],[1,1.01,0.51],[2,3.75,0]],"ltp":4.6,"tv":4.23,"id":16575965},{"batb":[[0,2.52,15.03],[1,1.01,0.51],[2,2.52,0]],"ltp":2.74,"tv":57.25,"id":13010314}]}]}
{"op":"mcm","clk":"1008568261","pt":1580637216289,"mc":[{"id":"1.168224424","rc":[{"batb":[[1,5.4,35.04],[2,5.3,27.37]],"ltp":5.6,"tv":18.62,"id":16575966},{"batb":[[0,4.1,37.28],[1,4,52.42],[2,3.75,13.69]],"ltp":4.6,"tv":4.23,"id":16575965},{"batb":[[0,2.58,58.49],[1,2.54,67.85],[2,2.52,15.03]],"ltp":2.74,"tv":57.25,"id":13010314}]}]}
{"op":"mcm","clk":"1008568528","pt":1580637220983,"mc":[{"id":"1.168224424","rc":[{"batb":[[1,5.4,26.44],[2,1.01,0.51]],"ltp":5.6,"tv":18.62,"id":16575966},{"batb":[[0,3.75,13.69],[1,1.01,0.51],[2,3.75,0]],"ltp":4.6,"tv":4.23,"id":16575965}]}]}
{"op":"mcm","clk":"1008568744","pt":1580637224375,"mc":[{"id":"1.168224424","rc":[{"batb":[[1,4,93.26],[2,3.95,41.82]],"batl":[[0,4.7,30.75],[1,4.9,18.57]],"ltp":4.1,"tv":4.74,"id":13010313},{"batb":[[0,5.6,20.06],[1,5.5,44.67],[2,5.4,26.44]],"batl":[[0,6.2,7.56],[1,6.8,18.33]],"ltp":5.6,"tv":18.62,"id":16575966},{"batb":[[0,4.5,47.91],[1,4.4,53.54],[2,4.2,20.69]],"batl":[[1,5.2,9.24],[2,5.6,13.45]],"ltp":4.6,"tv":4.23,"id":16575965},{"batl":[[0,2.7,14.71],[1,2.8,22.69],[2,2.88,12.51]],"ltp":2.74,"tv":57.25,"id":13010314}]}]}
{"op":"mcm","clk":"1008569178","pt":1580637231421,"mc":[{"id":"1.168224424","rc":[{"batb":[[1,4,76.86],[2,3.95,13.44]],"ltp":4.1,"tv":4.74,"id":13010313},{"batb":[[1,5.5,33.74]],"ltp":5.6,"tv":18.62,"id":16575966},{"batb":[[0,4.5,33.88]],"ltp":4.6,"tv":4.23,"id":16575965},{"batb":[[0,2.52,15.03],[1,2.48,27.73],[2,2.26,20.14]],"ltp":2.74,"tv":57.25,"id":13010314}]}]}
{"op":"mcm","clk":"1008569370","pt":1580637234306,"mc":[{"id":"1.168224424","rc":[{"batb":[[0,4.1,47.69]],"ltp":4.1,"tv":4.74,"id":13010313},{"batb":[[0,2.6,45.44],[1,2.56,66.65],[2,2.52,15.03]],"ltp":2.74,"tv":57.25,"id":13010314}]}]}
{"op":"mcm","clk":"1008570148","pt":1580637246449,"mc":[{"id":"1.168224424","rc":[{"batb":[[0,4,76.86],[1,3.95,13.44],[2,1.01,0.51]],"batl":[[0,4.7,10.92]],"ltp":4.1,"tv":4.74,"id":13010313},{"batb":[[0,5.5,10.46],[1,5.4,26.44],[2,5.1,10.08]],"ltp":5.6,"tv":18.62,"id":16575966},{"batb":[[0,4.4,11.76],[1,3.9,24.63],[2,1.01,0.51]],"batl":[[0,5.2,9.24],[1,5.6,13.45],[2,5.6,0]],"ltp":4.6,"tv":4.23,"id":16575965},{"batb":[[0,2.48,27.73],[1,2.26,20.14],[2,1.01,0.51]],"batl":[[0,2.8,22.69],[1,2.88,12.51],[2,2.88,0]],"ltp":2.74,"tv":57.25,"id":13010314}]}]}
{"op":"mcm","clk":"1008570206","pt":1580637247374,"mc":[{"id":"1.168224424","rc":[{"batb":[[1,1.01,0.51],[2,1.01,0]],"batl":[[0,4.9,18.57],[1,4.9,0]],"ltp":4.1,"tv":4.74,"id":13010313},{"batb":[[2,1.01,0.51]],"batl":[[0,6.8,18.33],[1,6.8,0]],"ltp":5.6,"tv":18.62,"id":16575966},{"batb":[[0,3.9,24.63],[1,1.01,0.51],[2,1.01,0]],"batl":[[0,5.6,13.45],[1,5.6,0]],"ltp":4.6,"tv":4.23,"id":16575965},{"batb":[[0,2.26,20.14],[1,1.01,0.51],[2,1.01,0]],"batl":[[0,2.88,12.51],[1,2.88,0]],"ltp":2.74,"tv":57.25,"id":13010314}]}]}
{"op":"mcm","clk":"1008570328","pt":1580637249379,"mc":[{"id":"1.168224424","rc":[{"batb":[[1,3.95,28.41],[2,1.01,0.51]],"ltp":4.1,"tv":4.74,"id":13010313},{"batb":[[1,5.4,34.02],[2,5.3,27.22]],"ltp":5.6,"tv":18.62,"id":16575966},{"batb":[[0,4.2,27.27],[1,4.1,49.37],[2,3.9,24.63]],"ltp":4.6,"tv":4.23,"id":16575965},{"batb":[[0,2.34,81.28],[1,2.32,43.79],[2,2.26,20.14]],"ltp":2.74,"tv":57.25,"id":13010314}]}]}
{"op":"mcm","clk":"1008570493","pt":1580637251456,"mc":[{"id":"1.168224424","rc":[{"batb":[[1,1.01,0.51],[2,1.01,0]],"ltp":4.1,"tv":4.74,"id":13010313},{"batb":[[1,5.4,26.44],[2,1.01,0.51]],"ltp":5.6,"tv":18.62,"id":16575966},{"batb":[[0,3.9,24.63],[1,1.01,0.51],[2,3.9,0]],"ltp":4.6,"tv":4.23,"id":16575965},{"batb":[[0,2.26,20.14],[1,1.01,0.51],[2,2.26,0]],"ltp":2.74,"tv":57.25,"id":13010314}]}]}
{"op":"mcm","clk":"1008570716","pt":1580637254391,"mc":[{"id":"1.168224424","rc":[{"batb":[[0,4.1,37.7],[1,4,76.86],[2,1.01,0.51]],"ltp":4.1,"tv":4.74,"id":13010313},{"batb":[[0,5.5,39.51]],"ltp":5.6,"tv":18.62,"id":16575966},{"batb":[[0,4.6,43.98],[1,4.5,39.49],[2,3.9,24.63]],"ltp":4.6,"tv":4.23,"id":16575965},{"batb":[[0,2.54,58.35],[1,2.5,70.92],[2,2.26,20.14]],"ltp":2.74,"tv":57.25,"id":13010314}]}]}
{"op":"mcm","clk":"1008570756","pt":1580637254904,"mc":[{"id":"1.168224424","rc":[{"batb":[[0,4,76.86],[1,1.01,0.51],[2,1.01,0]],"ltp":4.1,"tv":4.74,"id":13010313},{"batb":[[0,5.5,10.46]],"ltp":5.6,"tv":18.62,"id":16575966},{"batb":[[0,3.9,24.63],[1,1.01,0.51],[2,3.9,0]],"ltp":4.6,"tv":4.23,"id":16575965},{"batb":[[0,2.26,20.14],[1,1.01,0.51],[2,2.26,0]],"ltp":2.74,"tv":57.25,"id":13010314}]}]}
{"op":"mcm","clk":"1008570939","pt":1580637257289,"mc":[{"id":"1.168224424","rc":[{"batb":[[1,3.95,28.41],[2,1.01,0.51]],"ltp":4.1,"tv":4.74,"id":13010313},{"batb":[[1,5.4,34.02],[2,5.3,27.22]],"ltp":5.6,"tv":18.62,"id":16575966},{"batb":[[0,4.2,27.27],[1,4.1,49.37],[2,3.9,24.63]],"ltp":4.6,"tv":4.23,"id":16575965},{"batb":[[0,2.34,81.28],[1,2.32,43.79],[2,2.26,20.14]],"ltp":2.74,"tv":57.25,"id":13010314}]}]}
{"op":"mcm","clk":"1008571185","pt":1580637261002,"mc":[{"id":"1.168224424","rc":[{"batb":[[0,4,21.95],[1,1.01,0.51],[2,1.01,0]],"ltp":4.1,"tv":4.74,"id":13010313},{"batb":[[1,1.01,0.51],[2,5.3,0]],"ltp":5.6,"tv":18.62,"id":16575966},{"batb":[[0,3.9,24.63],[1,1.01,0.51],[2,3.9,0]],"ltp":4.6,"tv":4.23,"id":16575965}]}]}
{"op":"mcm","clk":"1008571362","pt":1580637263383,"mc":[{"id":"1.168224424","rc":[{"batb":[[0,4.2,30.94],[1,4.1,51.8],[2,4,21.95]],"ltp":4.1,"tv":4.74,"id":13010313},{"batb":[[0,5.6,25.82],[1,5.5,35.61],[2,1.01,0.51]],"ltp":5.6,"tv":18.62,"id":16575966},{"batb":[[0,5.2,36.09],[1,5.1,29.73],[2,3.9,24.63]],"ltp":4.6,"tv":4.23,"id":16575965}]}]}
{"op":"mcm","clk":"1008571418","pt":1580637264409,"mc":[{"id":"1.168224424","rc":[{"batb":[[0,4.2,50.45],[1,4.1,72.49],[2,4,35.4]],"batl":[[0,4.8,10.92],[1,4.9,18.57],[2,5.1,16.52]],"ltp":4.1,"tv":4.74,"id":13010313},{"batb":[[0,5.7,19.67],[1,5.6,46.12],[2,5.5,35.61]],"batl":[[0,6.4,7.56],[1,6.8,18.33],[2,7,17.23]],"ltp":5.6,"tv":18.62,"id":16575966},{"batb":[[2,5,10.08]],"batl":[[1,6,8.4],[2,7.4,15.42]],"ltp":4.6,"tv":4.23,"id":16575965},{"batb":[[2,2.28,32.77]],"batl":[[0,2.42,19.67],[1,2.58,26.05],[2,2.6,15.97]],"ltp":2.74,"tv":57.25,"id":13010314}]}]}
{"op":"mcm","clk":"1008571423","pt":1580637264512,"mc":[{"id":"1.168224424","rc":[{"batb":[[2,4,13.44]],"ltp":4.1,"tv":4.74,"id":13010313},{"batb":[[2,5.5,25.15]],"ltp":5.6,"tv":18.62,"id":16575966}]}]}
{"op":"mcm","clk":"1008572195","pt":1580637276318,"mc":[{"id":"1.168224424","rc":[{"batb":[[0,4.2,19.51],[1,4.1,20.69]],"ltp":4.1,"tv":4.74,"id":13010313},{"batb":[[1,5.6,20.3],[2,5.2,9.24]],"ltp":5.6,"tv":18.62,"id":16575966},{"batb":[[0,5,10.08],[1,4.9,14.08],[2,4.4,18.49]],"ltp":4.6,"tv":4.23,"id":16575965},{"batb":[[0,2.28,32.77],[1,2.26,20.14],[2,2,28.88]],"ltp":2.74,"tv":57.25,"id":13010314}]}]}
{"op":"mcm","clk":"1008572271","pt":1580637277307,"mc":[{"id":"1.168224424","rc":[{"batb":[[0,4.1,20.69],[1,1.01,0.51],[2,4,0]],"batl":[[0,5.1,16.52],[1,4.9,0],[2,5.1,0]],"ltp":4.1,"tv":4.74,"id":13010313},{"batb":[[0,5.6,20.3],[1,1.01,0.51],[2,5.2,0]],"batl":[[0,7,17.23],[1,6.8,0],[2,7,0]],"ltp":5.6,"tv":18.62,"id":16575966},{"batb":[[0,4.4,18.49],[1,1.01,0.51],[2,4.4,0]],"batl":[[0,7.4,15.42],[1,6,0],[2,7.4,0]],"ltp":4.6,"tv":4.23,"id":16575965},{"batb":[[0,2,28.88],[1,1.01,0.51],[2,2,0]],"batl":[[0,2.6,15.97],[1,2.58,0],[2,2.6,0]],"ltp":2.74,"tv":57.25,"id":13010314}]}]}
{"op":"mcm","clk":"1008572435","pt":1580637279925,"mc":[{"id":"1.168224424","rc":[{"batb":[[0,4.1,56.61],[1,4,54.76],[2,1.01,0.51]],"ltp":4.1,"tv":4.74,"id":13010313},{"batb":[[1,5.5,31.18],[2,5.4,26.12]],"ltp":5.6,"tv":18.62,"id":16575966},{"batb":[[0,4.6,54.62],[1,4.5,39.29],[2,4.4,18.49]],"ltp":4.6,"tv":4.23,"id":16575965},{"batb":[[0,2.08,81.77],[1,2.06,61.61],[2,2,28.88]],"ltp":2.74,"tv":57.25,"id":13010314}]}]}
{"op":"mcm","clk":"1008572704","pt":1580637284206,"mc":[{"id":"1.168224424","rc":[{"batb":[[0,4.1,20.69],[1,1.01,0.51],[2,1.01,0]],"ltp":4.1,"tv":4.74,"id":13010313},{"batb":[[1,1.01,0.51],[2,5.4,0]],"ltp":5.6,"tv":18.62,"id":16575966},{"batb":[[0,4.4,18.49],[1,1.01,0.51],[2,4.4,0]],"ltp":4.6,"tv":4.23,"id":16575965}]}]}
{"op":"mcm","clk":"1008572947","pt":1580637287405,"mc":[{"id":"1.168224424","rc":[{"batb":[[0,4.3,64.79],[1,4.2,48.44],[2,4.1,20.69]],"ltp":4.1,"tv":4.74,"id":13010313},{"batb":[[0,5.7,37.17],[1,5.6,44.28],[2,1.01,0.51]],"ltp":5.6,"tv":18.62,"id":16575966},{"batb":[[0,6.6,35.19],[1,6.4,35.16],[2,4.4,18.49]],"ltp":4.6,"tv":4.23,"id":16575965}]}]}
{"op":"mcm","clk":"1008573011","pt":1580637288432,"mc":[{"id":"1.168224424","rc":[{"batb":[[0,4.5,17.31],[1,4.3,83.52],[2,4.2,48.44]],"batl":[[0,5,10.08],[1,5.1,16.52],[2,5.5,14.16]],"ltp":4.1,"tv":4.74,"id":13010313},{"batb":[[0,5.8,18.49],[1,5.7,56.53],[2,5.6,23.98]],"batl":[[0,6.4,7.56],[1,7,16.68]],"ltp":5.6,"tv":18.62,"id":16575966},{"batb":[[2,6.2,16.44]],"batl":[[1,7.6,5.88],[2,11,6.85]],"ltp":4.6,"tv":4.23,"id":16575965},{"batb":[[1,2.06,101.1]],"batl":[[0,2.12,28.09],[1,2.3,54.19]],"ltp":2.74,"tv":57.25,"id":13010314}]}]}
{"op":"mcm","clk":"1008573142","pt":1580637290436,"mc":[{"id":"1.168224424","rc":[{"batb":[[2,6.2,24.01]],"ltp":4.6,"tv":4.23,"id":16575965}]}]}
{"op":"mcm","clk":"1008573872","pt":1580637300441,"mc":[{"id":"1.168224424","rc":[{"batb":[[0,4.3,18.73],[1,4.1,13.44],[2,1.01,0.51]],"batl":[[1,5.5,14.16],[2,5.5,0]],"ltp":4.1,"tv":4.74,"id":13010313},{"batb":[[0,5.7,19.36],[1,5.3,9.24],[2,1.01,0.51]],"ltp":5.6,"tv":18.62,"id":16575966},{"batb":[[0,6.2,7.56],[1,5.3,11.72],[2,1.01,0.51]],"batl":[[0,7.6,5.88],[1,11,6.85],[2,11,0]],"ltp":4.6,"tv":4.23,"id":16575965},{"batb":[[0,2.06,39.49],[1,1.79,20.93],[2,1.01,0.51]],"batl":[[0,2.3,54.19],[1,2.3,0]],"ltp":2.74,"tv":57.25,"id":13010314}]}]}
{"op":"mcm","clk":"1008573961","pt":1580637301232,"mc":[{"id":"1.168224424","rc":[{"batb":[[1,1.01,0.51],[2,1.01,0]],"batl":[[0,5.5,14.16],[1,5.5,0]],"ltp":4.1,"tv":4.74,"id":13010313},{"batb":[[1,1.01,0.51],[2,1.01,0]],"batl":[[0,7,16.68],[1,7,0]],"ltp":5.6,"tv":18.62,"id":16575966},{"batb":[[0,5.3,11.72],[1,1.01,0.51],[2,1.01,0]],"batl":[[0,11,6.85],[1,11,0]],"ltp":4.6,"tv":4.23,"id":16575965},{"batb":[[0,1.79,20.93],[1,1.01,0.51],[2,1.01,0]],"batl":[[0,2.3,22.27]],"ltp":2.74,"tv":57.25,"id":13010314}]}]}
{"op":"mcm","clk":"1008574155","pt":1580637303408,"mc":[{"id":"1.168224424","rc":[{"batb":[[1,4.2,56.44],[2,4.1,51.38]],"ltp":4.1,"tv":4.74,"id":13010313},{"batb":[[1,5.6,38.01],[2,5.5,24.96]],"ltp":5.6,"tv":18.62,"id":16575966},{"batb":[[0,5.6,39.75],[1,5.5,25],[2,5.3,11.72]],"ltp":4.6,"tv":4.23,"id":16575965},{"batb":[[0,1.85,68.17],[1,1.83,88.83],[2,1.79,20.93]],"ltp":2.74,"tv":57.25,"id":13010314}]}]}
{"op":"mcm","clk":"1008574274","pt":1580637305212,"mc":[{"id":"1.168224424","rc":[{"batb":[[1,1.01,0.51],[2,4.1,0]],"ltp":4.1,"tv":4.74,"id":13010313},{"batb":[[1,1.01,0.51],[2,5.5,0]],"ltp":5.6,"tv":18.62,"id":16575966},{"batb":[[0,5.3,11.72],[1,1.01,0.51],[2,5.3,0]],"ltp":4.6,"tv":4.23,"id":16575965},{"batb":[[0,1.79,20.93],[1,1.01,0.51],[2,1.79,0]],"batl":[[0,2.08,2.36],[1,2.3,22.27]],"ltp":2.74,"tv":57.25,"id":13010314}]}]}
{"op":"mcm","clk":"1008574504","pt":1580637308410,"mc":[{"id":"1.168224424","rc":[{"batb":[[0,4.4,37.55],[1,4.3,65.05],[2,1.01,0.51]],"ltp":4.1,"tv":4.74,"id":13010313},{"batb":[[0,5.8,21.67],[1,5.7,42.63],[2,1.01,0.51]],"ltp":5.6,"tv":18.62,"id":16575966},{"batb":[[0,7,38.7],[1,6.8,30.68],[2,5.3,11.72]],"ltp":4.6,"tv":4.23,"id":16575965},{"batb":[[0,2.02,111.17],[1,2,67.31],[2,1.79,20.93]],"ltp":2.74,"tv":57.25,"id":13010314}]}]}
{"op":"mcm","clk":"1008574689","pt":1580637310523,"mc":[{"id":"1.168224424","rc":[{"batb":[[0,4.3,18.73],[1,1.01,0.51],[2,1.01,0]],"ltp":4.1,"tv":4.74,"id":13010313},{"batb":[[0,5.7,19.36],[1,1.01,0.51],[2,1.01,0]],"ltp":5.6,"tv":18.62,"id":16575966},{"batb":[[0,5.3,11.72],[1,1.01,0.51],[2,5.3,0]],"ltp":4.6,"tv":4.23,"id":16575965},{"batb":[[0,1.79,20.93],[1,1.01,0.51],[2,1.79,0]],"ltp":2.74,"tv":57.25,"id":13010314}]}]}
{"op":"mcm","clk":"1008574938","pt":1580637313427,"mc":[{"id":"1.168224424","rc":[{"batb":[[1,4.2,56.44],[2,4.1,51.38]],"ltp":4.1,"tv":4.74,"id":13010313},{"batb":[[1,5.6,38.01],[2,5.5,24.96]],"ltp":5.6,"tv":18.62,"id":16575966},{"batb":[[0,5.6,39.75],[1,5.5,25],[2,5.3,11.72]],"ltp":4.6,"tv":4.23,"id":16575965},{"batb":[[0,1.85,68.17],[1,1.83,88.83],[2,1.79,20.93]],"ltp":2.74,"tv":57.25,"id":13010314}]}]}
{"op":"mcm","clk":"1008575083","pt":1580637315331,"mc":[{"id":"1.168224424","rc":[{"batb":[[1,1.01,0.51],[2,4.1,0]],"ltp":4.1,"tv":4.74,"id":13010313},{"batb":[[1,1.01,0.51],[2,5.5,0]],"ltp":5.6,"tv":18.62,"id":16575966},{"batb":[[0,5.3,11.72],[1,1.01,0.51],[2,5.3,0]],"ltp":4.6,"tv":4.23,"id":16575965}]}]}
{"op":"mcm","clk":"1008575326","pt":1580637318435,"mc":[{"id":"1.168224424","rc":[{"batb":[[0,4.6,29.6],[1,4.5,41.85],[2,4.3,31.33]],"batl":[[0,5.2,9.24],[1,5.5,14.16]],"ltp":4.1,"tv":4.74,"id":13010313},{"batb":[[0,5.9,31.46],[1,5.8,22.24],[2,5.7,19.36]],"batl":[[0,6.6,6.72],[1,7,16.68]],"ltp":5.6,"tv":18.62,"id":16575966},{"batb":[[0,9.6,23.83],[1,9.4,15.42],[2,5.3,11.72]],"batl":[[0,10.5,4.2],[1,11,6.85]],"ltp":4.6,"tv":4.23,"id":16575965},{"batb":[[0,1.85,116.9]],"batl":[[0,2.06,39.49],[1,2.08,2.36],[2,2.3,22.27]],"ltp":2.74,"tv":57.25,"id":13010314}]}]}
{"op":"mcm","clk":"1008575383","pt":1580637319208,"mc":[{"id":"1.168224424","rc":[{"batb":[[0,4.8,14.79],[1,4.6,45.73],[2,4.5,41.85]],"batl":[[2,5.8,12.51]],"ltp":4.1,"tv":4.74,"id":13010313},{"batb":[[0,5.9,49.87],[2,5.4,9.24]],"batl":[[1,7.4,15.34]],"ltp":5.6,"tv":18.62,"id":16575966},{"batb":[[2,8.8,7.16]],"batl":[[2,18,7]],"ltp":4.6,"tv":4.23,"id":16575965},{"batl":[[0,1.87,20.54],[1,1.98,17.07],[2,2.08,2.36]],"ltp":2.74,"tv":57.25,"id":13010314}]}]}
{"op":"mcm","clk":"1008575521","pt":1580637321356,"mc":[{"id":"1.168224424","rc":[{"batb":[[2,1.01,0.51]],"ltp":5.6,"tv":18.62,"id":16575966},{"batl":[[0,11,6.85],[1,18,7],[2,18,0]],"ltp":4.6,"tv":4.23,"id":16575965},{"batl":[[2,2.08,0]],"ltp":2.74,"tv":57.25,"id":13010314}]}]}
{"op":"mcm","clk":"1008575604","pt":1580637322439,"mc":[{"id":"1.168224424","rc":[{"trd":[[1.87,40.33]],"batl":[[0,1.98,17.44],[1,1.98,0]],"ltp":1.87,"tv":97.58,"id":13010314}],"tv":125.18}]}
{"op":"mcm","clk":"1008575768","pt":1580637324313,"mc":[{"id":"1.168224424","rc":[{"batb":[[2,5.5,9.24]],"ltp":5.6,"tv":18.62,"id":16575966},{"batl":[[0,11,11.05]],"ltp":4.6,"tv":4.23,"id":16575965},{"batl":[[1,2.02,41.17]],"ltp":1.87,"tv":97.58,"id":13010314}]}]}
{"op":"mcm","clk":"1008576217","pt":1580637330044,"mc":[{"id":"1.168224424","rc":[{"batb":[[0,4.6,16.13],[1,4.5,24.51],[2,4.4,11.76]],"batl":[[1,5.8,12.51],[2,5.8,0]],"ltp":4.1,"tv":4.74,"id":13010313},{"batb":[[0,5.9,18.41]],"ltp":5.6,"tv":18.62,"id":16575966},{"batb":[[0,8.4,5.04],[1,7.4,11.02],[2,1.01,0.51]],"batl":[[0,11,4.2]],"ltp":4.6,"tv":4.23,"id":16575965},{"batb":[[0,1.85,48.73],[1,1.63,28.33],[2,1.01,0.51]],"batl":[[0,1.98,17.07]],"ltp":1.87,"tv":97.58,"id":13010314}]}]}
{"op":"mcm","clk":"1008576311","pt":1580637331246,"mc":[{"id":"1.168224424","rc":[{"batb":[[2,1.01,0.51]],"batl":[[0,5.8,12.51],[1,5.8,0]],"ltp":4.1,"tv":4.74,"id":13010313},{"batb":[[2,1.01,0.51]],"batl":[[0,7.4,15.34],[1,7.4,0]],"ltp":5.6,"tv":18.62,"id":16575966},{"batb":[[0,7.4,11.02],[1,1.01,0.51],[2,1.01,0]],"batl":[[0,18,7],[1,18,0]],"ltp":4.6,"tv":4.23,"id":16575965},{"batb":[[0,1.63,28.33],[1,1.01,0.51],[2,1.01,0]],"batl":[[1,2.02,0]],"ltp":1.87,"tv":97.58,"id":13010314}]}]}
{"op":"mcm","clk":"1008576389","pt":1580637332317,"mc":[{"id":"1.168224424","rc":[{"batb":[[0,5.8,22.24],[1,1.01,0.51],[2,1.01,0]],"ltp":5.6,"tv":18.62,"id":16575966},{"batb":[[0,1.01,0.51],[1,1.01,0]],"ltp":4.6,"tv":4.23,"id":16575965}]}]}
{"op":"mcm","clk":"1008576478","pt":1580637333454,"mc":[{"id":"1.168224424","rc":[{"batb":[[2,4.4,44.14]],"batl":[[0,5.7,12.75]],"ltp":4.1,"tv":4.74,"id":13010313},{"batb":[[0,5.8,49.85],[1,5.7,23.13],[2,1.01,0.51]],"batl":[[0,7.2,15.58]],"ltp":5.6,"tv":18.62,"id":16575966},{"batb":[[0,8,26.96],[1,7.8,22.98],[2,7.2,11.17]],"batl":[[0,17.5,7.16]],"ltp":4.6,"tv":4.23,"id":16575965},{"batb":[[0,1.65,27.77]],"batl":[[0,2,16.76]],"ltp":1.87,"tv":97.58,"id":13010314}]}]}
{"op":"mcm","clk":"1008576590","pt":1580637334847,"mc":[{"id":"1.168224424","rc":[{"batb":[[0,1.95,72.8],[1,1.93,75.08],[2,1.65,27.77]],"ltp":1.87,"tv":97.58,"id":13010314}]}]}
{"op":"mcm","clk":"1008576717","pt":1580637336445,"mc":[{"id":"1.168224424","rc":[{"batb":[[2,4.4,62.16]],"batl":[[0,5.1,10.08],[1,5.2,15.58],[2,5.7,12.75]],"ltp":4.1,"tv":4.74,"id":13010313},{"batb":[[1,5.7,42.49],[2,5.5,9.24]],"batl":[[0,6.6,6.72],[1,7,16.37],[2,7.2,15.58]],"ltp":5.6,"tv":18.62,"id":16575966},{"batb":[[2,7.4,5.88]],"batl":[[0,8.8,10.62],[1,9.2,5.04],[2,17,7.79]],"ltp":4.6,"tv":4.23,"id":16575965},{"batb":[[2,1.92,62.37]],"batl":[[1,2.18,25.97]],"ltp":1.87,"tv":97.58,"id":13010314}]}]}
{"op":"mcm","clk":"1008576793","pt":1580637337432,"mc":[{"id":"1.168224424","rc":[{"batl":[[2,7.2,0]],"ltp":5.6,"tv":18.62,"id":16575966}]}]}
{"op":"mcm","clk":"1008576987","pt":1580637340148,"mc":[{"id":"1.168224424","rc":[{"batl":[[1,2.12,36.97],[2,2.18,25.97]],"ltp":1.87,"tv":97.58,"id":13010314}]}]}
{"op":"mcm","clk":"1008577551","pt":1580637348442,"mc":[{"id":"1.168224424","rc":[{"batb":[[0,4.4,18.02],[1,4.3,12.6],[2,1.01,0.51]],"batl":[[1,5.7,12.75],[2,5.7,0]],"ltp":4.1,"tv":4.74,"id":13010313},{"batb":[[0,5.7,42.49],[1,5.5,9.24],[2,1.01,0.51]],"ltp":5.6,"tv":18.62,"id":16575966},{"batb":[[0,7.4,5.88],[1,6,17.94],[2,1.01,0.51]],"batl":[[0,9.2,5.04],[1,17,7.79],[2,17,0]],"ltp":4.6,"tv":4.23,"id":16575965},{"batb":[[0,1.92,45.37],[1,1.67,26.52],[2,1.01,0.51]],"batl":[[0,2.12,36.97],[1,2.18,25.97],[2,2.18,0]],"ltp":1.87,"tv":97.58,"id":13010314}]}]}
{"op":"mcm","clk":"1008577605","pt":1580637349263,"mc":[{"id":"1.168224424","rc":[{"batb":[[1,1.01,0.51],[2,1.01,0]],"batl":[[0,5.7,12.75],[1,5.7,0]],"ltp":4.1,"tv":4.74,"id":13010313},{"batb":[[1,1.01,0.51],[2,1.01,0]],"batl":[[0,7,16.37],[1,7,0]],"ltp":5.6,"tv":18.62,"id":16575966},{"batb":[[0,6,17.94],[1,1.01,0.51],[2,1.01,0]],"batl":[[0,17,7.79],[1,17,0]],"ltp":4.6,"tv":4.23,"id":16575965},{"batb":[[0,1.67,26.52],[1,1.01,0.51],[2,1.01,0]],"batl":[[0,2.18,25.97],[1,2.18,0]],"ltp":1.87,"tv":97.58,"id":13010314}]}]}
{"op":"mcm","clk":"1008577764","pt":1580637351378,"mc":[{"id":"1.168224424","rc":[{"batb":[[1,4.3,47.39],[2,4.2,48.73]],"ltp":4.1,"tv":4.74,"id":13010313},{"batb":[[0,5.7,19.36],[1,5.6,24.11],[2,1.01,0.51]],"ltp":5.6,"tv":18.62,"id":16575966},{"batb":[[0,6.4,27.54],[1,6.2,37.93],[2,6,17.94]],"ltp":4.6,"tv":4.23,"id":16575965},{"batb":[[0,1.71,93.84],[1,1.69,116.04],[2,1.67,26.52]],"ltp":1.87,"tv":97.58,"id":13010314}]}]}
{"op":"mcm","clk":"1008577779","pt":1580637351586,"mc":[{"id":"1.168224424","rc":[{"batb":[[1,1.01,0.51],[2,4.2,0]],"ltp":4.1,"tv":4.74,"id":13010313},{"batb":[[1,1.01,0.51],[2,1.01,0]],"ltp":5.6,"tv":18.62,"id":16575966},{"batb":[[0,6,17.94],[1,1.01,0.51],[2,6,0]],"ltp":4.6,"tv":4.23,"id":16575965},{"batb":[[0,1.67,26.52],[1,1.01,0.51],[2,1.67,0]],"ltp":1.87,"tv":97.58,"id":13010314}]}]}
{"op":"mcm","clk":"1008577983","pt":1580637354376,"mc":[{"id":"1.168224424","rc":[{"batb":[[0,4.5,47.83],[1,4.4,61.78],[2,1.01,0.51]],"ltp":4.1,"tv":4.74,"id":13010313},{"batb":[[0,5.9,17.47],[1,5.8,22.44],[2,5.7,19.36]],"ltp":5.6,"tv":18.62,"id":16575966},{"batb":[[0,8.8,21.72],[1,8.6,18.71],[2,6,17.94]],"ltp":4.6,"tv":4.23,"id":16575965},{"batb":[[0,1.9,64.22],[1,1.88,81.5],[2,1.67,26.52]],"ltp":1.87,"tv":97.58,"id":13010314}]}]}
{"op":"mcm","clk":"1008578036","pt":1580637355154,"mc":[{"id":"1.168224424","rc":[{"batl":[[0,1.95,10.36],[1,2.18,25.97]],"ltp":1.87,"tv":97.58,"id":13010314}]}]}
{"op":"mcm","clk":"1008578098","pt":1580637355983,"mc":[{"id":"1.168224424","rc":[{"batb":[[0,4.4,18.02],[1,1.01,0.51],[2,1.01,0]],"ltp":4.1,"tv":4.74,"id":13010313},{"batb":[[0,5.7,19.36],[1,1.01,0.51],[2,5.7,0]],"ltp":5.6,"tv":18.62,"id":16575966},{"batb":[[0,6,17.94],[1,1.01,0.51],[2,6,0]],"ltp":4.6,"tv":4.23,"id":16575965},{"batb":[[0,1.67,26.52],[1,1.01,0.51],[2,1.67,0]],"ltp":1.87,"tv":97.58,"id":13010314}]}]}
{"op":"mcm","clk":"1008578287","pt":1580637358361,"mc":[{"id":"1.168224424","rc":[{"batl":[[0,2.18,25.97],[1,2.18,0]],"ltp":1.87,"tv":97.58,"id":13010314}]}]}
{"op":"mcm","clk":"1008578306","pt":1580637358662,"mc":[{"id":"1.168224424","rc":[{"batb":[[1,4.3,47.39],[2,4.2,48.73]],"ltp":4.1,"tv":4.74,"id":13010313},{"batb":[[0,5.7,47.67],[1,5.6,24.11],[2,1.01,0.51]],"ltp":5.6,"tv":18.62,"id":16575966},{"batb":[[0,6.4,27.54],[1,6.2,37.93],[2,6,17.94]],"ltp":4.6,"tv":4.23,"id":16575965},{"batb":[[0,1.71,93.84],[1,1.69,116.04],[2,1.67,26.52]],"ltp":1.87,"tv":97.58,"id":13010314}]}]}
{"op":"mcm","clk":"1008578673","pt":1580637364096,"mc":[{"id":"1.168224424","rc":[{"batb":[[1,1.01,0.51],[2,4.2,0]],"ltp":4.1,"tv":4.74,"id":13010313},{"batb":[[0,5.7,19.36],[1,1.01,0.51],[2,1.01,0]],"ltp":5.6,"tv":18.62,"id":16575966},{"batb":[[0,6,17.94],[1,1.01,0.51],[2,6,0]],"ltp":4.6,"tv":4.23,"id":16575965}]}]}
{"op":"mcm","clk":"1008578883","pt":1580637367404,"mc":[{"id":"1.168224424","rc":[{"batb":[[0,4.7,58.38],[1,4.6,39.35],[2,4.4,18.02]],"ltp":4.1,"tv":4.74,"id":13010313},{"batb":[[0,6,31.76],[1,5.9,21.4],[2,5.7,19.36]],"ltp":5.6,"tv":18.62,"id":16575966},{"batb":[[0,14.5,9.72],[1,14,16.59],[2,6,17.94]],"ltp":4.6,"tv":4.23,"id":16575965}]}]}
{"op":"mcm","clk":"1008578951","pt":1580637368288,"mc":[{"id":"1.168224424","rc":[{"batb":[[0,5,13.53],[1,4.7,73.49],[2,4.6,39.35]],"batl":[[0,5.4,9.24],[1,5.7,12.75],[2,5.8,12.43]],"ltp":4.1,"tv":4.74,"id":13010313},{"batb":[[2,5.8,27.05]],"batl":[[0,7,23.09],[1,7.2,15.89]],"ltp":5.6,"tv":18.62,"id":16575966},{"batb":[[2,12,11.7]],"batl":[[1,22,4.88]],"ltp":4.6,"tv":4.23,"id":16575965},{"batb":[[1,1.69,176.53]],"batl":[[0,1.74,25.97],[1,1.83,42.01],[2,1.88,20.38]],"ltp":1.87,"tv":97.58,"id":13010314}]}]}
{"op":"mcm","clk":"1008585579","pt":1580637453295,"mc":[{"id":"1.168224424","rc":[{"batb":[[0,4.7,15.11],[1,4.6,39.35],[2,1.01,0.51]],"batl":[[0,5.8,12.43],[1,5.7,0],[2,5.8,0]],"ltp":4.1,"tv":4.74,"id":13010313},{"batb":[[0,5.9,21.4],[1,5.8,18.65],[2,1.01,0.51]],"batl":[[0,7.2,15.89],[1,7.2,0]],"ltp":5.6,"tv":18.62,"id":16575966},{"batb":[[0,9,6.92],[1,1.01,0.51],[2,12,0]],"batl":[[0,22,4.88],[1,22,0]],"ltp":4.6,"tv":4.23,"id":16575965},{"batb":[[0,1.62,29.74],[1,1.01,0.51],[2,1.67,0]],"batl":[[0,1.88,20.38],[1,1.83,0],[2,1.88,0]],"ltp":1.87,"tv":97.58,"id":13010314}]}]}
{"op":"mcm","clk":"1008585796","pt":1580637456383,"mc":[{"id":"1.168224424","rc":[{"batb":[[1,1.01,0.51],[2,1.01,0]],"ltp":4.1,"tv":4.74,"id":13010313},{"batb":[[0,1.66,104.73],[1,1.65,63.56],[2,1.62,29.74]],"ltp":1.87,"tv":97.58,"id":13010314}]}]}
{"op":"mcm","clk":"1008585990","pt":1580637459408,"mc":[{"id":"1.168224424","rc":[{"batb":[[0,4.8,47.34],[1,4.7,52.74],[2,1.01,0.51]],"ltp":4.1,"tv":4.74,"id":13010313},{"batb":[[0,6,48.72]],"ltp":5.6,"tv":18.62,"id":16575966},{"batb":[[0,17.5,12.63],[1,17,11.02],[2,9,6.92]],"ltp":4.6,"tv":4.23,"id":16575965},{"batb":[[0,1.65,63.56],[1,1.62,29.74],[2,1.01,0.51]],"ltp":1.87,"tv":97.58,"id":13010314}]}]}
{"op":"mcm","clk":"1008586052","pt":1580637460287,"mc":[{"id":"1.168224424","rc":[{"batb":[[0,4.9,14.16],[1,4.8,38.84],[2,4.7,37.63]],"batl":[[0,5.5,9.24],[1,5.8,12.43],[2,5.9,11.96]],"ltp":4.1,"tv":4.74,"id":13010313},{"batb":[[0,6,66.63],[1,5.9,18.33]],"batl":[[0,7.2,22.62],[1,7.4,15.34]],"ltp":5.6,"tv":18.62,"id":16575966},{"batb":[[1,15,5.19],[2,11,10.31]],"batl":[[1,28,6.61]],"ltp":4.6,"tv":4.23,"id":16575965},{"batb":[[1,1.64,65.54],[2,1.62,29.74]],"batl":[[0,1.68,29.11],[1,1.76,42.01],[2,1.79,23.92]],"ltp":1.87,"tv":97.58,"id":13010314}]}]}
{"op":"mcm","clk":"1008586194","pt":1580637462300,"mc":[{"id":"1.168224424","rc":[{"batb":[[0,6.2,29.93],[1,6,66.63],[2,5.9,18.33]],"ltp":5.6,"tv":18.62,"id":16575966},{"batb":[[0,18,8.82],[1,17.5,12.63],[2,15,5.19]],"ltp":4.6,"tv":4.23,"id":16575965},{"batb":[[0,1.65,121.06],[1,1.64,130.73]],"ltp":1.87,"tv":97.58,"id":13010314}]}]}
{"op":"mcm","clk":"1008586497","pt":1580637466222,"mc":[{"id":"1.168224424","rc":[{"batb":[[0,6.2,40.09]],"ltp":5.6,"tv":18.62,"id":16575966},{"batb":[[0,18,11.93]],"ltp":4.6,"tv":4.23,"id":16575965}]}]}
{"op":"mcm","clk":"1008586737","pt":1580637469428,"mc":[{"id":"1.168224424","rc":[{"batb":[[1,4.7,25.2],[2,1.01,0.51]],"batl":[[0,5.9,11.96],[1,5.8,0],[2,5.9,0]],"ltp":4.1,"tv":4.74,"id":13010313},{"batb":[[0,6,41.23],[1,5.9,18.33],[2,1.01,0.51]],"batl":[[0,7.4,15.34],[1,7.4,0]],"ltp":5.6,"tv":18.62,"id":16575966},{"batb":[[0,11,10.31],[1,1.01,0.51],[2,15,0]],"batl":[[0,28,6.61],[1,28,0]],"ltp":4.6,"tv":4.23,"id":16575965},{"batb":[[0,1.58,32.57],[1,1.01,0.51],[2,1.62,0]],"batl":[[0,1.79,23.92],[1,1.76,0],[2,1.79,0]],"ltp":1.87,"tv":97.58,"id":13010314}]}]}
{"op":"mcm","clk":"1008586856","pt":1580637471022,"mc":[{"id":"1.168224424","rc":[{"batb":[[1,1.01,0.51],[2,1.01,0]],"ltp":4.1,"tv":4.74,"id":13010313},{"batb":[[0,5.9,18.33],[1,1.01,0.51],[2,1.01,0]],"ltp":5.6,"tv":18.62,"id":16575966}]}]}
{"op":"mcm","clk":"1008586945","pt":1580637472305,"mc":[{"id":"1.168224424","rc":[{"batb":[[0,1.62,72.24],[1,1.61,69.63],[2,1.58,32.57]],"ltp":1.87,"tv":97.58,"id":13010314}]}]}
{"op":"mcm","clk":"1008587084","pt":1580637474320,"mc":[{"id":"1.168224424","rc":[{"batb":[[0,4.9,35.27],[1,4.8,36.1],[2,4.7,10.92]],"batl":[[0,5.6,8.4],[1,5.9,11.96]],"ltp":4.1,"tv":4.74,"id":13010313},{"batb":[[0,6.4,17.01],[1,6.2,38.97],[2,6,8.4]],"batl":[[0,7.4,21.22]],"ltp":5.6,"tv":18.62,"id":16575966},{"batb":[[0,21,15.97],[1,20,15.6],[2,11,10.31]],"ltp":4.6,"tv":4.23,"id":16575965},{"batb":[[2,1.6,69.74]],"batl":[[0,1.72,42.01],[1,1.79,23.92]],"ltp":1.87,"tv":97.58,"id":13010314}]}]}
{"op":"mcm","clk":"1008587123","pt":1580637474937,"mc":[{"id":"1.168224424","rc":[{"batb":[[0,5.1,12.43],[1,5,13.38],[2,4.9,21.11]],"batl":[[2,6,11.57]],"ltp":4.1,"tv":4.74,"id":13010313},{"batl":[[0,7.4,20.83]],"ltp":5.6,"tv":18.62,"id":16575966},{"batb":[[2,17.5,7.24]],"ltp":4.6,"tv":4.23,"id":16575965},{"batl":[[0,1.64,31.87],[1,1.71,27.46],[2,1.72,42.01]],"ltp":1.87,"tv":97.58,"id":13010314}]}]}
{"op":"mcm","clk":"1008587721","pt":1580637483416,"mc":[{"id":"1.168224424","rc":[{"batb":[[0,5,13.38],[1,4.8,22.11],[2,1.01,0.51]],"batl":[[0,6,11.57],[1,5.9,0],[2,6,0]],"ltp":4.1,"tv":4.74,"id":13010313},{"batb":[[0,6.2,22.3],[1,5.9,17.86],[2,1.01,0.51]],"batl":[[0,7.4,14.95]],"ltp":5.6,"tv":18.62,"id":16575966},{"batb":[[0,14,6.06],[1,1.01,0.51],[2,17.5,0]],"ltp":4.6,"tv":4.23,"id":16575965},{"batb":[[0,1.55,34.86],[1,1.01,0.51],[2,1.6,0]],"batl":[[0,1.71,27.46],[1,1.71,0],[2,1.72,0]],"ltp":1.87,"tv":97.58,"id":13010314}]}]}
{"op":"mcm","clk":"1008587936","pt":1580637486246,"mc":[{"id":"1.168224424","rc":[{"batb":[[2,4.7,37.85]],"ltp":4.1,"tv":4.74,"id":13010313},{"batb":[[1,6,41.73],[2,5.9,17.86]],"ltp":5.6,"tv":18.62,"id":16575966},{"batb":[[0,17.5,5.85],[1,17,11.51],[2,14,6.06]],"ltp":4.6,"tv":4.23,"id":16575965},{"batb":[[0,1.59,127.49],[1,1.58,74.91],[2,1.55,34.86]],"ltp":1.87,"tv":97.58,"id":13010314}]}]}
{"op":"mcm","clk":"1008587999","pt":1580637487176,"mc":[{"id":"1.168224424","rc":[{"batb":[[0,14,6.06],[1,1.01,0.51],[2,14,0]],"ltp":4.6,"tv":4.23,"id":16575965},{"batb":[[0,1.55,34.86],[1,1.01,0.51],[2,1.55,0]],"ltp":1.87,"tv":97.58,"id":13010314}]}]}
{"op":"mcm","clk":"1008588217","pt":1580637490163,"mc":[{"id":"1.168224424","rc":[{"batb":[[1,4.8,50.52]],"ltp":4.1,"tv":4.74,"id":13010313},{"batb":[[0,6.2,49.71]],"ltp":5.6,"tv":18.62,"id":16575966},{"batb":[[0,20,17.29],[1,19.5,8.4],[2,14,6.06]],"ltp":4.6,"tv":4.23,"id":16575965},{"batb":[[0,1.63,71.81],[1,1.62,68.06],[2,1.55,34.86]],"ltp":1.87,"tv":97.58,"id":13010314}]}]}
{"op":"mcm","clk":"1008588283","pt":1580637491294,"mc":[{"id":"1.168224424","rc":[{"batb":[[1,4.8,22.11]],"ltp":4.1,"tv":4.74,"id":13010313},{"batb":[[0,6.2,22.3]],"ltp":5.6,"tv":18.62,"id":16575966},{"batb":[[0,14,6.06],[1,1.01,0.51],[2,14,0]],"ltp":4.6,"tv":4.23,"id":16575965},{"batb":[[0,1.55,34.86],[1,1.01,0.51],[2,1.55,0]],"ltp":1.87,"tv":97.58,"id":13010314}]}]}
{"op":"mcm","clk":"1008588507","pt":1580637494481,"mc":[{"id":"1.168224424","rc":[{"batb":[[0,17.5,5.85],[1,17,11.51],[2,14,6.06]],"ltp":4.6,"tv":4.23,"id":16575965},{"batb":[[0,1.59,127.49],[1,1.58,74.91],[2,1.55,34.86]],"ltp":1.87,"tv":97.58,"id":13010314}]}]}
{"op":"mcm","clk":"1008588794","pt":1580637499366,"mc":[{"id":"1.168224424","rc":[{"batb":[[2,1.01,0.51]],"ltp":4.1,"tv":4.74,"id":13010313},{"batb":[[1,5.9,17.86],[2,1.01,0.51]],"ltp":5.6,"tv":18.62,"id":16575966},{"batb":[[0,14,6.06],[1,1.01,0.51],[2,14,0]],"ltp":4.6,"tv":4.23,"id":16575965}]}]}
{"op":"mcm","clk":"1008588986","pt":1580637502349,"mc":[{"id":"1.168224424","rc":[{"batb":[[1,4.9,37.58],[2,4.8,35.84]],"batl":[[0,5.6,8.4],[1,6,11.57]],"ltp":4.1,"tv":4.74,"id":13010313},{"batb":[[0,6.4,32.67],[1,6.2,46.1],[2,5.9,17.86]],"batl":[[1,7.6,5.88]],"ltp":5.6,"tv":18.62,"id":16575966},{"batb":[[0,24,9.81],[1,23,11.95],[2,14,6.06]],"ltp":4.6,"tv":4.23,"id":16575965},{"batb":[[2,1.57,73.1]],"batl":[[0,1.69,42.01],[1,1.71,27.46]],"ltp":1.87,"tv":97.58,"id":13010314}]}]}
{"op":"mcm","clk":"1008589019","pt":1580637502975,"mc":[{"id":"1.168224424","rc":[{"batb":[[0,5.2,11.96],[1,5.1,12.83],[2,4.9,37.58]],"batl":[[2,6.2,11.33]],"ltp":4.1,"tv":4.74,"id":13010313},{"batb":[[1,6.2,62.07],[2,6,17.55]],"batl":[[1,7.6,19.97]],"ltp":5.6,"tv":18.62,"id":16575966},{"batb":[[2,20,5.27]],"ltp":4.6,"tv":4.23,"id":16575965},{"batl":[[0,1.61,33.99],[1,1.67,30.21],[2,1.69,42.01]],"ltp":1.87,"tv":97.58,"id":13010314}]}]}
{"op":"mcm","clk":"1008590093","pt":1580637519409,"mc":[{"id":"1.168224424","rc":[{"batb":[[0,5.1,12.83],[1,4.8,35.84],[2,1.01,0.51]],"batl":[[0,6.2,11.33],[1,6,0],[2,6.2,0]],"ltp":4.1,"tv":4.74,"id":13010313},{"batb":[[0,6.2,38.54],[1,6,17.55],[2,1.01,0.51]],"batl":[[0,7.6,14.08],[1,7.6,0]],"ltp":5.6,"tv":18.62,"id":16575966},{"batb":[[0,17,7.87],[1,1.01,0.51],[2,20,0]],"ltp":4.6,"tv":4.23,"id":16575965},{"batb":[[0,1.58,74.91],[1,1.53,36.74],[2,1.01,0.51]],"batl":[[0,1.67,30.21],[1,1.67,0],[2,1.69,0]],"ltp":1.87,"tv":97.58,"id":13010314}]}]}
{"op":"mcm","clk":"1008590271","pt":1580637522384,"mc":[{"id":"1.168224424","rc":[{"batb":[[1,4.8,48.48],[2,4.7,37.43]],"ltp":4.1,"tv":4.74,"id":13010313},{"batb":[[1,6,58.82]],"ltp":5.6,"tv":18.62,"id":16575966},{"batb":[[0,21,15.7],[1,20,15.67],[2,17,7.87]],"ltp":4.6,"tv":4.23,"id":16575965},{"batb":[[0,1.58,97.56],[1,1.57,76.61],[2,1.53,36.74]],"ltp":1.87,"tv":97.58,"id":13010314}]}]}
{"op":"mcm","clk":"1008590316","pt":1580637523214,"mc":[{"id":"1.168224424","rc":[{"batb":[[1,4.8,35.84],[2,1.01,0.51]],"ltp":4.1,"tv":4.74,"id":13010313},{"batb":[[1,6,17.55]],"ltp":5.6,"tv":18.62,"id":16575966},{"batb":[[0,17,7.87],[1,1.01,0.51],[2,17,0]],"ltp":4.6,"tv":4.23,"id":16575965},{"batb":[[0,1.58,74.91],[1,1.53,36.74],[2,1.01,0.51]],"ltp":1.87,"tv":97.58,"id":13010314}]}]}
{"op":"mcm","clk":"1008590536","pt":1580637526414,"mc":[{"id":"1.168224424","rc":[{"batb":[[0,5.3,11.72],[1,5.2,12.27],[2,4.9,49.63]],"batl":[[0,5.7,8.4],[1,6.2,11.33],[2,6.4,10.39]],"ltp":4.1,"tv":4.74,"id":13010313},{"batb":[[0,6.4,70.47],[1,6.2,54.43]],"batl":[[1,7.8,5.88],[2,8,12.9]],"ltp":5.6,"tv":18.62,"id":16575966},{"batb":[[0,26,4.6],[1,25,10.31],[2,21,4.19]],"ltp":4.6,"tv":4.23,"id":16575965},{"batb":[[0,1.58,97.56],[1,1.57,76.61],[2,1.55,75.62]],"batl":[[0,1.59,35.8],[1,1.62,33.36],[2,1.65,42.01]],"ltp":1.87,"tv":97.58,"id":13010314}]}]}
{"op":"mcm","clk":"1008592105","pt":1580637550350,"mc":[{"id":"1.168224424","rc":[{"batb":[[2,4.9,27.49]],"ltp":4.1,"tv":4.74,"id":13010313},{"batb":[[0,6.4,48.6]],"ltp":5.6,"tv":18.62,"id":16575966},{"batb":[[0,21,4.19],[1,19.5,5.67],[2,1.01,0.51]],"ltp":4.6,"tv":4.23,"id":16575965},{"batb":[[0,1.55,75.62],[1,1.53,36.74],[2,1.48,41.39]],"ltp":1.87,"tv":97.58,"id":13010314}]}]}
{"op":"mcm","clk":"1008592176","pt":1580637551430,"mc":[{"id":"1.168224424","rc":[{"batb":[[0,5.2,12.27],[1,4.9,27.49],[2,4.8,35.84]],"batl":[[0,6.4,10.39],[1,6.2,0],[2,6.4,0]],"ltp":4.1,"tv":4.74,"id":13010313},{"batb":[[0,6.4,26.01]],"batl":[[0,8,12.9],[1,7.8,0],[2,8,0]],"ltp":5.6,"tv":18.62,"id":16575966},{"batb":[[0,19.5,5.67],[1,1.01,0.51],[2,1.01,0]],"ltp":4.6,"tv":4.23,"id":16575965},{"batb":[[0,1.48,41.39],[1,1.01,0.51],[2,1.48,0]],"batl":[[0,1.62,33.36],[1,1.62,0],[2,1.65,0]],"ltp":1.87,"tv":97.58,"id":13010314}]}]}
{"op":"mcm","clk":"1008592285","pt":1580637553337,"mc":[{"id":"1.168224424","rc":[{"batb":[[0,23,8.28],[1,22,13.2],[2,19.5,5.67]],"ltp":4.6,"tv":4.23,"id":16575965},{"batb":[[0,1.54,108.52],[1,1.53,84.7],[2,1.48,41.39]],"ltp":1.87,"tv":97.58,"id":13010314}]}]}
{"op":"mcm","clk":"1008592322","pt":1580637553854,"mc":[{"id":"1.168224424","rc":[{"batb":[[0,1.48,41.39],[1,1.01,0.51],[2,1.48,0]],"ltp":1.87,"tv":97.58,"id":13010314}]}]}
{"op":"mcm","clk":"1008592526","pt":1580637556331,"mc":[{"id":"1.168224424","rc":[{"batb":[[1,5.1,12.9],[2,4.9,27.49]],"batl":[[0,5.6,8.4],[1,5.9,11.8],[2,6.2,11.02]],"ltp":4.1,"tv":4.74,"id":13010313},{"batb":[[1,6.2,62],[2,6,17.23]],"batl":[[0,7.4,14.87],[1,7.6,19.65],[2,8,12.9]],"ltp":5.6,"tv":18.62,"id":16575966},{"batb":[[0,1.6,127.19],[1,1.59,73.17],[2,1.58,72.26]],"batl":[[1,1.66,30.84],[2,1.68,42.01]],"ltp":1.87,"tv":97.58,"id":13010314}]}]}
{"op":"mcm","clk":"1008592543","pt":1580637556537,"mc":[{"id":"1.168224424","rc":[{"batl":[[2,8,0]],"ltp":5.6,"tv":18.62,"id":16575966}]}]}
{"op":"mcm","clk":"1008593175","pt":1580637566356,"mc":[{"id":"1.168224424","rc":[{"batb":[[0,5.1,12.9],[1,4.8,35.84],[2,4.7,10.92]],"batl":[[1,6.2,11.02],[2,6.2,0]],"ltp":4.1,"tv":4.74,"id":13010313},{"batb":[[0,6.2,46.1],[1,6,17.23],[2,1.01,0.51]],"batl":[[0,7.6,19.65],[1,7.6,0]],"ltp":5.6,"tv":18.62,"id":16575966},{"batb":[[0,18,6.92],[1,1.01,0.51],[2,19.5,0]],"ltp":4.6,"tv":4.23,"id":16575965},{"batb":[[0,1.58,72.26],[1,1.51,38],[2,1.01,0.51]],"batl":[[0,1.66,30.84],[1,1.68,42.01],[2,1.68,0]],"ltp":1.87,"tv":97.58,"id":13010314}]}]}
{"op":"mcm","clk":"1008593241","pt":1580637567452,"mc":[{"id":"1.168224424","rc":[{"batb":[[2,1.01,0.51]],"batl":[[0,6.2,11.02],[1,6.2,0]],"ltp":4.1,"tv":4.74,"id":13010313},{"batb":[[0,6.2,38.54]],"batl":[[0,7.6,13.77]],"ltp":5.6,"tv":18.62,"id":16575966},{"batb":[[0,1.51,38],[1,1.01,0.51],[2,1.01,0]],"batl":[[1,1.68,0]],"ltp":1.87,"tv":97.58,"id":13010314}]}]}
{"op":"mcm","clk":"1008593359","pt":1580637569381,"mc":[{"id":"1.168224424","rc":[{"batb":[[1,4.8,35.9]],"ltp":4.1,"tv":4.74,"id":13010313}]}]}
{"op":"mcm","clk":"1008593446","pt":1580637570769,"mc":[{"id":"1.168224424","rc":[{"batb":[[1,4.9,34.06],[2,4.8,35.9]],"ltp":4.1,"tv":4.74,"id":13010313},{"batb":[[0,6.4,32.98],[1,6.2,38.54],[2,6,17.23]],"ltp":5.6,"tv":18.62,"id":16575966},{"batb":[[0,24,4.24],[1,23,12.22],[2,18,6.92]],"ltp":4.6,"tv":4.23,"id":16575965},{"batb":[[0,1.6,75.67],[1,1.59,72.96],[2,1.51,38]],"ltp":1.87,"tv":97.58,"id":13010314}]}]}
{"op":"mcm","clk":"1008593540","pt":1580637572375,"mc":[{"id":"1.168224424","rc":[{"batb":[[1,4.8,35.9],[2,1.01,0.51]],"ltp":4.1,"tv":4.74,"id":13010313},{"batb":[[0,6.2,38.54],[1,6,17.23],[2,1.01,0.51]],"ltp":5.6,"tv":18.62,"id":16575966},{"batb":[[0,18,6.92],[1,1.01,0.51],[2,18,0]],"ltp":4.6,"tv":4.23,"id":16575965},{"batb":[[0,1.51,38],[1,1.01,0.51],[2,1.51,0]],"ltp":1.87,"tv":97.58,"id":13010314}]}]}
{"op":"mcm","clk":"1008593750","pt":1580637575369,"mc":[{"id":"1.168224424","rc":[{"batb":[[1,4.8,44.82],[2,4.7,37.49]],"ltp":4.1,"tv":4.74,"id":13010313},{"batb":[[0,6.2,44.92],[1,6,58.33]],"ltp":5.6,"tv":18.62,"id":16575966},{"batb":[[0,21,12.13],[1,20,15.84],[2,18,6.92]],"ltp":4.6,"tv":4.23,"id":16575965},{"batb":[[0,1.57,90.46],[1,1.56,78.47],[2,1.51,38]],"ltp":1.87,"tv":97.58,"id":13010314}]}]}
{"op":"mcm","clk":"1008594751","pt":1580637589958,"mc":[{"id":"1.168224424","rc":[{"batb":[[0,1.51,38],[1,1.01,0.51],[2,1.51,0]],"ltp":1.87,"tv":97.58,"id":13010314}]}]}
{"op":"mcm","clk":"1008594938","pt":1580637593313,"mc":[{"id":"1.168224424","rc":[{"batb":[[1,5,13.3],[2,4.8,44.82]],"batl":[[0,5.8,12.43],[1,6,11.57],[2,6.2,11.02]],"ltp":4.1,"tv":4.74,"id":13010313},{"batb":[[2,5.9,17.94]],"batl":[[0,7.2,16.13],[1,7.4,14.63],[2,7.6,13.77]],"ltp":5.6,"tv":18.62,"id":16575966},{"batl":[[0,28,6.29]],"ltp":4.6,"tv":4.23,"id":16575965},{"batb":[[0,1.63,66.06],[1,1.62,68.06],[2,1.59,31.55]],"batl":[[1,1.68,29.43]],"ltp":1.87,"tv":97.58,"id":13010314}]}]}
{"op":"mcm","clk":"1008595005","pt":1580637594400,"mc":[{"id":"1.168224424","rc":[{"batl":[[0,5.6,8.4],[1,5.8,12.43],[2,6,11.57]],"ltp":4.1,"tv":4.74,"id":13010313},{"batb":[[1,6,66.73]],"batl":[[1,7.4,20.52],[2,7.6,0]],"ltp":5.6,"tv":18.62,"id":16575966},{"batb":[[2,1.6,69.74]],"batl":[[2,1.71,42.01]],"ltp":1.87,"tv":97.58,"id":13010314}]}]}
{"op":"mcm","clk":"1008595242","pt":1580637597290,"mc":[{"id":"1.168224424","rc":[{"batb":[[0,5,13.3],[1,4.8,44.82],[2,4.7,48.41]],"batl":[[1,6,11.57],[2,6,0]],"ltp":4.1,"tv":4.74,"id":13010313},{"batb":[[1,6,49.5]],"batl":[[0,7.4,20.52],[1,7.4,0]],"ltp":5.6,"tv":18.62,"id":16575966},{"batb":[[2,17,7.87]],"ltp":4.6,"tv":4.23,"id":16575965},{"batl":[[0,1.68,29.43],[1,1.71,42.01],[2,1.71,0]],"ltp":1.87,"tv":97.58,"id":13010314}]}]}
{"op":"mcm","clk":"1008596563","pt":1580637612327,"mc":[{"id":"1.168224424","rc":[{"batb":[[1,4.8,35.84]],"ltp":4.1,"tv":4.74,"id":13010313},{"batb":[[0,6.2,25.44]],"ltp":5.6,"tv":18.62,"id":16575966},{"batb":[[0,20,11.66],[1,17,7.87],[2,1.01,0.51]],"ltp":4.6,"tv":4.23,"id":16575965},{"batb":[[0,1.6,69.74],[1,1.55,35.09],[2,1.01,0.51]],"ltp":1.87,"tv":97.58,"id":13010314}]}]}
{"op":"mcm","clk":"1008596624","pt":1580637613519,"mc":[{"id":"1.168224424","rc":[{"batb":[[2,4.7,37.49]],"batl":[[0,6,11.57],[1,6,0]],"ltp":4.1,"tv":4.74,"id":13010313},{"batb":[[1,6,41.1]],"batl":[[0,7.4,14.63]],"ltp":5.6,"tv":18.62,"id":16575966},{"batb":[[0,1.55,35.09],[1,1.01,0.51],[2,1.01,0]],"batl":[[1,1.71,0]],"ltp":1.87,"tv":97.58,"id":13010314}]}]}
{"op":"mcm","clk":"1008596721","pt":1580637615219,"mc":[{"id":"1.168224424","rc":[{"batb":[[1,19.5,8.57],[2,17,7.87]],"ltp":4.6,"tv":4.23,"id":16575965},{"batb":[[0,1.6,68.84],[1,1.59,72.93],[2,1.55,35.09]],"ltp":1.87,"tv":97.58,"id":13010314}]}]}
{"op":"mcm","clk":"1008597005","pt":1580637619402,"mc":[{"id":"1.168224424","rc":[{"batb":[[0,1.55,35.09],[1,1.01,0.51],[2,1.55,0]],"ltp":1.87,"tv":97.58,"id":13010314}]}]}
{"op":"mcm","clk":"1008597236","pt":1580637622441,"mc":[{"id":"1.168224424","rc":[{"batb":[[1,4.9,13.69],[2,4.8,35.84]],"batl":[[0,5.5,9.24],[1,5.9,12.04]],"ltp":4.1,"tv":4.74,"id":13010313},{"batb":[[1,6,49.5]],"batl":[[0,7,16.76],[1,7.2,6.72],[2,7.4,14.63]],"ltp":5.6,"tv":18.62,"id":16575966},{"batl":[[0,29,6.22]],"ltp":4.6,"tv":4.23,"id":16575965},{"batb":[[0,1.64,116.4],[1,1.63,66.72],[2,1.62,67.22]],"batl":[[1,1.7,28.25],[2,1.74,42.01]],"ltp":1.87,"tv":97.58,"id":13010314}]}]}
{"op":"mcm","clk":"1008598085","pt":1580637632929,"mc":[{"id":"1.168224424","rc":[{"batb":[[0,4.9,13.69],[1,4.7,48.41],[2,1.01,0.51]],"ltp":4.1,"tv":4.74,"id":13010313},{"batb":[[0,6,49.5],[1,5.8,18.88],[2,1.01,0.51]],"batl":[[0,7.2,6.72],[1,7.4,14.63],[2,7.4,0]],"ltp":5.6,"tv":18.62,"id":16575966},{"batb":[[0,19.5,8.57],[1,16.5,4.17],[2,1.01,0.51]],"ltp":4.6,"tv":4.23,"id":16575965},{"batb":[[0,1.62,67.22],[1,1.57,32.73],[2,1.01,0.51]],"batl":[[0,1.7,28.25],[1,1.74,42.01],[2,1.74,0]],"ltp":1.87,"tv":97.58,"id":13010314}]}]}
{"op":"mcm","clk":"1008598125","pt":1580637633546,"mc":[{"id":"1.168224424","rc":[{"batb":[[1,4.7,37.49]],"batl":[[0,5.9,12.04],[1,5.9,0]],"ltp":4.1,"tv":4.74,"id":13010313},{"batb":[[0,6,41.1]],"batl":[[0,7.4,14.63],[1,7.4,0]],"ltp":5.6,"tv":18.62,"id":16575966},{"batb":[[0,1.57,32.73],[1,1.01,0.51],[2,1.01,0]],"batl":[[1,1.74,0]],"ltp":1.87,"tv":97.58,"id":13010314}]}]}
{"op":"mcm","clk":"1008598322","pt":1580637636341,"mc":[{"id":"1.168224424","rc":[{"batb":[[1,4.7,54.31],[2,4.6,39.23]],"ltp":4.1,"tv":4.74,"id":13010313},{"batb":[[0,6,49.44],[1,5.9,21.64],[2,5.8,18.88]],"ltp":5.6,"tv":18.62,"id":16575966},{"batb":[[0,19.5,11.19],[1,19,9.05],[2,16.5,4.17]],"ltp":4.6,"tv":4.23,"id":16575965},{"batb":[[0,1.62,90.88],[1,1.61,69.72],[2,1.57,32.73]],"ltp":1.87,"tv":97.58,"id":13010314}]}]}
{"op":"mcm","clk":"1008598413","pt":1580637637982,"mc":[{"id":"1.168224424","rc":[{"batb":[[0,1.57,32.73],[1,1.01,0.51],[2,1.57,0]],"ltp":1.87,"tv":97.58,"id":13010314}]}]}
{"op":"mcm","clk":"1008598651","pt":1580637641303,"mc":[{"id":"1.168224424","rc":[{"batb":[[1,4.7,69.73]],"batl":[[0,5.7,12.67]],"ltp":4.1,"tv":4.74,"id":13010313},{"batl":[[0,6.8,17.62],[1,7,17.23]],"ltp":5.6,"tv":18.62,"id":16575966},{"batl":[[0,26,7.55]],"ltp":4.6,"tv":4.23,"id":16575965},{"batb":[[0,1.66,70.24],[1,1.65,63.73],[2,1.63,28.88]],"batl":[[1,1.85,21.48]],"ltp":1.87,"tv":97.58,"id":13010314}]}]}
{"op":"mcm","clk":"1008598803","pt":1580637643267,"mc":[{"id":"1.168224424","rc":[{"batb":[[2,4.6,50.15]],"batl":[[0,5.5,9.24],[1,5.7,12.67]],"ltp":4.1,"tv":4.74,"id":13010313},{"batb":[[2,5.8,27.29]],"batl":[[1,7,23.95]],"ltp":5.6,"tv":18.62,"id":16575966},{"batb":[[0,19.5,13.48]],"ltp":4.6,"tv":4.23,"id":16575965},{"batb":[[1,1.65,127.58]],"batl":[[1,1.77,42.01],[2,1.85,21.48]],"ltp":1.87,"tv":97.58,"id":13010314}]}]}
{"op":"mcm","clk":"1008601548","pt":1580637680267,"mc":[{"id":"1.168224424","rc":[{"batl":[[1,7,17.23]],"ltp":5.6,"tv":18.62,"id":16575966}]}]}
{"op":"mcm","clk":"1008601743","pt":1580637683126,"mc":[{"id":"1.168224424","rc":[{"batl":[[0,6.8,24.35]],"ltp":5.6,"tv":18.62,"id":16575966}]}]}
{"op":"mcm","clk":"1008604674","pt":1580637725093,"mc":[{"id":"1.168224424","rc":[{"batb":[[0,4.7,15.42],[1,4.6,41.78],[2,1.01,0.51]],"ltp":4.1,"tv":4.74,"id":13010313},{"batb":[[0,5.9,21.64],[1,5.8,8.4],[2,5.6,10.31]],"batl":[[0,6.8,6.72]],"ltp":5.6,"tv":18.62,"id":16575966},{"batb":[[0,11,11.09],[1,1.01,0.51],[2,16.5,0]],"ltp":4.6,"tv":4.23,"id":16575965},{"batb":[[0,1.65,63.85],[1,1.59,31.87],[2,1.01,0.51]],"batl":[[0,1.77,42.01],[1,1.85,21.48],[2,1.85,0]],"ltp":1.87,"tv":97.58,"id":13010314}]}]}
{"op":"mcm","clk":"1008604730","pt":1580637725820,"mc":[{"id":"1.168224424","rc":[{"batb":[[1,4.6,30.86]],"batl":[[0,5.7,12.67],[1,5.7,0]],"ltp":4.1,"tv":4.74,"id":13010313},{"batb":[[1,5.6,10.31],[2,1.01,0.51]],"batl":[[0,7,17.23],[1,7,0]],"ltp":5.6,"tv":18.62,"id":16575966},{"batb":[[0,1.59,31.87],[1,1.01,0.51],[2,1.01,0]],"batl":[[0,1.85,21.48],[1,1.85,0]],"ltp":1.87,"tv":97.58,"id":13010314}]}]}
{"op":"mcm","clk":"1008604950","pt":1580637728234,"mc":[{"id":"1.168224424","rc":[{"batb":[[2,4.5,41.76]],"ltp":4.1,"tv":4.74,"id":13010313},{"batb":[[0,5.9,33.19],[1,5.8,22.79],[2,5.6,10.31]],"ltp":5.6,"tv":18.62,"id":16575966},{"batb":[[0,12.5,26.19],[1,12,23.08],[2,11,11.09]],"ltp":4.6,"tv":4.23,"id":16575965},{"batb":[[0,1.61,90.47],[1,1.6,71.29],[2,1.59,31.87]],"ltp":1.87,"tv":97.58,"id":13010314}]}]}
{"op":"mcm","clk":"1008605169","pt":1580637730236,"mc":[{"id":"1.168224424","rc":[{"batb":[[1,1.01,0.51],[2,4.5,0]],"ltp":4.1,"tv":4.74,"id":13010313},{"batb":[[0,5.6,10.31],[1,1.01,0.51],[2,5.6,0]],"ltp":5.6,"tv":18.62,"id":16575966},{"batb":[[0,11,11.09],[1,1.01,0.51],[2,11,0]],"ltp":4.6,"tv":4.23,"id":16575965}]}]}
{"op":"mcm","clk":"1008605377","pt":1580637733089,"mc":[{"id":"1.168224424","rc":[{"batb":[[0,4.8,45.78],[1,4.7,52.86],[2,1.01,0.51]],"ltp":4.1,"tv":4.74,"id":13010313},{"batb":[[0,6.2,25.09],[1,6,41.62],[2,5.6,10.31]],"ltp":5.6,"tv":18.62,"id":16575966},{"batb":[[0,26,10.65],[1,25,10.12],[2,11,11.09]],"ltp":4.6,"tv":4.23,"id":16575965}]}]}
{"op":"mcm","clk":"1008605443","pt":1580637733930,"mc":[{"id":"1.168224424","rc":[{"batb":[[0,5,13.22],[1,4.8,60.26],[2,4.7,37.44]],"batl":[[1,5.9,11.88]],"ltp":4.1,"tv":4.74,"id":13010313},{"batb":[[2,5.9,18.49]],"batl":[[0,7,16.52]],"ltp":5.6,"tv":18.62,"id":16575966},{"batb":[[2,21,4.26]],"ltp":4.6,"tv":4.23,"id":16575965},{"batl":[[0,1.65,31.16],[1,1.75,25.41]],"ltp":1.87,"tv":97.58,"id":13010314}]}]}
{"op":"mcm","clk":"1008605581","pt":1580637735402,"mc":[{"id":"1.168224424","rc":[{"batb":[[2,4.7,48.36]],"batl":[[0,5.5,9.24],[1,5.7,12.67],[2,5.9,11.88]],"ltp":4.1,"tv":4.74,"id":13010313},{"batl":[[0,7,23.24]],"ltp":5.6,"tv":18.62,"id":16575966},{"batb":[[2,1.59,102.44]],"batl":[[1,1.72,42.01],[2,1.75,25.41]],"ltp":1.87,"tv":97.58,"id":13010314}]}]}
{"op":"mcm","clk":"1008606035","pt":1580637741366,"mc":[{"id":"1.168224424","rc":[{"batb":[[1,4.8,14.48]],"ltp":4.1,"tv":4.74,"id":13010313},{"batb":[[0,6,28.53],[1,5.9,18.49],[2,5.8,8.4]],"ltp":5.6,"tv":18.62,"id":16575966},{"batb":[[0,21,4.26],[1,14.5,5.74],[2,1.01,0.51]],"ltp":4.6,"tv":4.23,"id":16575965},{"batb":[[0,1.59,102.44],[1,1.54,35.33],[2,1.01,0.51]],"ltp":1.87,"tv":97.58,"id":13010314}]}]}
{"op":"mcm","clk":"1008606094","pt":1580637742220,"mc":[{"id":"1.168224424","rc":[{"batb":[[0,4.8,14.48],[1,4.7,37.44],[2,1.01,0.51]],"batl":[[0,5.9,11.88],[1,5.7,0],[2,5.9,0]],"ltp":4.1,"tv":4.74,"id":13010313},{"batb":[[1,5.6,10.31],[2,1.01,0.51]],"batl":[[0,7,16.52]],"ltp":5.6,"tv":18.62,"id":16575966},{"batb":[[0,14.5,5.74],[1,1.01,0.51],[2,1.01,0]],"ltp":4.6,"tv":4.23,"id":16575965},{"batb":[[0,1.54,35.33],[1,1.01,0.51],[2,1.01,0]],"batl":[[0,1.75,25.41],[1,1.72,0],[2,1.75,0]],"ltp":1.87,"tv":97.58,"id":13010314}]}]}
{"op":"mcm","clk":"1008606222","pt":1580637744357,"mc":[{"id":"1.168224424","rc":[{"batb":[[2,4.6,39.61]],"ltp":4.1,"tv":4.74,"id":13010313},{"batb":[[1,5.9,21.96],[2,5.6,10.31]],"ltp":5.6,"tv":18.62,"id":16575966},{"batb":[[0,17.5,8.43],[1,17,11.55],[2,14.5,5.74]],"ltp":4.6,"tv":4.23,"id":16575965},{"batb":[[0,1.58,66.68],[1,1.57,76.37],[2,1.54,35.33]],"ltp":1.87,"tv":97.58,"id":13010314}]}]}
{"op":"mcm","clk":"1008606351","pt":1580637746450,"mc":[{"id":"1.168224424","rc":[{"batb":[[1,1.01,0.51],[2,4.6,0]],"ltp":4.1,"tv":4.74,"id":13010313},{"batb":[[1,5.6,10.31],[2,1.01,0.51]],"ltp":5.6,"tv":18.62,"id":16575966},{"batb":[[0,14.5,5.74],[1,1.01,0.51],[2,14.5,0]],"ltp":4.6,"tv":4.23,"id":16575965}]}]}
{"op":"mcm","clk":"1008606560","pt":1580637749271,"mc":[{"id":"1.168224424","rc":[{"batb":[[0,4.9,32.52],[1,4.8,50.34],[2,1.01,0.51]],"ltp":4.1,"tv":4.74,"id":13010313},{"batb":[[0,6.2,42.45],[1,6,41.1],[2,5.6,10.31]],"ltp":5.6,"tv":18.62,"id":16575966},{"batb":[[0,34,7.6],[1,32,11.97],[2,14.5,5.74]],"ltp":4.6,"tv":4.23,"id":16575965}]}]}
{"op":"mcm","clk":"1008606653","pt":1580637750060,"mc":[{"id":"1.168224424","rc":[{"batb":[[0,4.9,46.21],[1,4.8,35.86]],"batl":[[1,6,11.57]],"ltp":4.1,"tv":4.74,"id":13010313},{"batb":[[2,5.7,19.83]],"batl":[[1,7.2,15.82]],"ltp":5.6,"tv":18.62,"id":16575966},{"batb":[[2,27,3.32]],"ltp":4.6,"tv":4.23,"id":16575965},{"batl":[[0,1.61,34.54],[1,1.68,29.19]],"ltp":1.87,"tv":97.58,"id":13010314}]}]}
{"op":"mcm","clk":"1008606691","pt":1580637750532,"mc":[{"id":"1.168224424","rc":[{"batb":[[2,4.7,10.92]],"batl":[[0,5.6,8.4],[1,5.9,11.88],[2,6,11.57]],"ltp":4.1,"tv":4.74,"id":13010313},{"batb":[[2,5.9,8.4]],"batl":[[1,7.2,22.54]],"ltp":5.6,"tv":18.62,"id":16575966},{"batb":[[2,1.56,74.78]],"batl":[[1,1.67,42.01],[2,1.68,29.19]],"ltp":1.87,"tv":97.58,"id":13010314}]}]}
{"op":"mcm","clk":"1008607451","pt":1580637761355,"mc":[{"id":"1.168224424","rc":[{"batb":[[0,4.9,13.69]],"ltp":4.1,"tv":4.74,"id":13010313},{"batb":[[0,6,41.1],[1,5.9,8.4],[2,5.7,19.83]],"batl":[[1,7.2,15.82]],"ltp":5.6,"tv":18.62,"id":16575966},{"batb":[[0,27,3.32],[1,20,5.43],[2,1.01,0.51]],"ltp":4.6,"tv":4.23,"id":16575965},{"batb":[[0,1.56,74.78],[1,1.54,35.33],[2,1.52,37.77]],"ltp":1.87,"tv":97.58,"id":13010314}]}]}
{"op":"mcm","clk":"1008607473","pt":1580637761671,"mc":[{"id":"1.168224424","rc":[{"batb":[[2,1.01,0.51]],"batl":[[0,6,11.57],[1,5.9,0],[2,6,0]],"ltp":4.1,"tv":4.74,"id":13010313},{"batb":[[1,5.7,19.83],[2,1.01,0.51]],"batl":[[0,7.2,15.82],[1,7.2,0]],"ltp":5.6,"tv":18.62,"id":16575966},{"batb":[[0,20,5.43],[1,1.01,0.51],[2,1.01,0]],"ltp":4.6,"tv":4.23,"id":16575965},{"batb":[[0,1.52,37.77],[1,1.01,0.51],[2,1.52,0]],"batl":[[0,1.68,29.19],[1,1.67,0],[2,1.68,0]],"ltp":1.87,"tv":97.58,"id":13010314}]}]}
{"op":"mcm","clk":"1008607600","pt":1580637763442,"mc":[{"id":"1.168224424","rc":[{"batb":[[0,1.57,62.95],[1,1.56,78.61],[2,1.52,37.77]],"ltp":1.87,"tv":97.58,"id":13010314}]}]}
{"op":"mcm","clk":"1008607661","pt":1580637764378,"mc":[{"id":"1.168224424","rc":[{"batb":[[2,4.7,37.69]],"ltp":4.1,"tv":4.74,"id":13010313},{"batb":[[0,6,48.41],[1,5.9,21.67],[2,5.7,19.83]],"ltp":5.6,"tv":18.62,"id":16575966},{"batb":[[0,25,6.71],[1,24,11.18],[2,20,5.43]],"ltp":4.6,"tv":4.23,"id":16575965},{"batb":[[0,1.55,131.2],[1,1.54,82.56]],"ltp":1.87,"tv":97.58,"id":13010314}]}]}
{"op":"mcm","clk":"1008608217","pt":1580637773268,"mc":[{"id":"1.168224424","rc":[{"batb":[[0,1.52,37.77],[1,1.01,0.51],[2,1.52,0]],"ltp":1.87,"tv":97.58,"id":13010314}]}]}
{"op":"mcm","clk":"1008608392","pt":1580637776382,"mc":[{"id":"1.168224424","rc":[{"batb":[[2,4.7,53.03]],"batl":[[0,5.7,13.14],[1,5.8,12.59],[2,6,11.57]],"ltp":4.1,"tv":4.74,"id":13010313},{"batl":[[0,6.6,18.41],[1,6.8,17.47],[2,7.2,15.82]],"ltp":5.6,"tv":18.62,"id":16575966},{"batb":[[0,1.62,97.85],[1,1.57,33.52],[2,1.52,37.77]],"batl":[[1,1.81,22.74]],"ltp":1.87,"tv":97.58,"id":13010314}]}]}
{"op":"mcm","clk":"1008608425","pt":1580637776960,"mc":[{"id":"1.168224424","rc":[{"batb":[[2,4.7,63.96]],"batl":[[0,5.5,9.24],[1,5.7,13.14],[2,5.8,12.59]],"ltp":4.1,"tv":4.74,"id":13010313},{"batb":[[2,5.7,28.23]],"batl":[[1,6.8,24.19],[2,7.2,0]],"ltp":5.6,"tv":18.62,"id":16575966},{"batb":[[1,1.61,68.06],[2,1.57,33.52]],"batl":[[1,1.73,42.01],[2,1.81,22.74]],"ltp":1.87,"tv":97.58,"id":13010314}]}]}
{"op":"mcm","clk":"1008608578","pt":1580637779077,"mc":[{"id":"1.168224424","rc":[{"batb":[[0,25,9.09]],"ltp":4.6,"tv":4.23,"id":16575965},{"batb":[[0,1.62,155.46],[1,1.61,137.91]],"ltp":1.87,"tv":97.58,"id":13010314}]}]}
{"op":"mcm","clk":"1008609820","pt":1580637793428,"mc":[{"id":"1.168224424","rc":[{"batb":[[0,4.7,26.27],[1,1.01,0.51],[2,4.7,0]],"batl":[[1,5.8,12.59],[2,5.8,0]],"ltp":4.1,"tv":4.74,"id":13010313},{"batb":[[0,5.9,21.67],[1,5.7,8.4],[2,5.5,10.54]],"batl":[[0,6.8,24.19],[1,6.8,0]],"ltp":5.6,"tv":18.62,"id":16575966},{"batb":[[0,12.5,7.87],[1,1.01,0.51],[2,20,0]],"ltp":4.6,"tv":4.23,"id":16575965},{"batb":[[0,1.61,68.06],[1,1.57,33.52],[2,1.01,0.51]],"batl":[[0,1.73,42.01],[1,1.81,22.74],[2,1.81,0]],"ltp":1.87,"tv":97.58,"id":13010314}]}]}
{"op":"mcm","clk":"1008609837","pt":1580637793692,"mc":[{"id":"1.168224424","rc":[{"batb":[[0,4.7,15.34]],"batl":[[0,5.8,12.59],[1,5.8,0]],"ltp":4.1,"tv":4.74,"id":13010313},{"batb":[[1,5.5,10.54],[2,1.01,0.51]],"batl":[[0,6.8,17.47]],"ltp":5.6,"tv":18.62,"id":16575966},{"batb":[[0,1.57,33.52],[1,1.01,0.51],[2,1.01,0]],"batl":[[0,1.81,22.74],[1,1.81,0]],"ltp":1.87,"tv":97.58,"id":13010314}]}]}
{"op":"mcm","clk":"1008610028","pt":1580637796135,"mc":[{"id":"1.168224424","rc":[{"batb":[[1,4.6,39.18],[2,1.01,0.51]],"ltp":4.1,"tv":4.74,"id":13010313},{"batb":[[0,5.9,21.8]],"ltp":5.6,"tv":18.62,"id":16575966}]}]}
{"op":"mcm","clk":"1008610185","pt":1580637798211,"mc":[{"id":"1.168224424","rc":[{"batb":[[0,4.7,72.25]],"ltp":4.1,"tv":4.74,"id":13010313},{"batb":[[0,6,41.01],[1,5.9,21.8],[2,5.5,10.54]],"ltp":5.6,"tv":18.62,"id":16575966},{"batb":[[0,22,13.61],[1,21,14.49],[2,12.5,7.87]],"ltp":4.6,"tv":4.23,"id":16575965},{"batb":[[0,1.64,114.33],[1,1.63,66.76],[2,1.57,33.52]],"ltp":1.87,"tv":97.58,"id":13010314}]}]}
{"op":"mcm","clk":"1008610436","pt":1580637801318,"mc":[{"id":"1.168224424","rc":[{"batb":[[0,4.7,15.34]],"ltp":4.1,"tv":4.74,"id":13010313},{"batb":[[0,5.9,21.8],[1,5.5,10.54],[2,1.01,0.51]],"ltp":5.6,"tv":18.62,"id":16575966},{"batb":[[0,12.5,7.87],[1,1.01,0.51],[2,12.5,0]],"ltp":4.6,"tv":4.23,"id":16575965},{"batb":[[0,1.57,33.52],[1,1.01,0.51],[2,1.57,0]],"ltp":1.87,"tv":97.58,"id":13010314}]}]}
{"op":"mcm","clk":"1008610591","pt":1580637803447,"mc":[{"id":"1.168224424","rc":[{"batb":[[1,1.01,0.51],[2,1.01,0]],"ltp":4.1,"tv":4.74,"id":13010313},{"batb":[[0,5.5,10.54],[1,1.01,0.51],[2,1.01,0]],"ltp":5.6,"tv":18.62,"id":16575966},{"batb":[[0,1.58,119.89],[1,1.57,110.15],[2,1.01,0.51]],"ltp":1.87,"tv":97.58,"id":13010314}]}]}
{"op":"mcm","clk":"1008610811","pt":1580637806445,"mc":[{"id":"1.168224424","rc":[{"batb":[[0,5,13.06],[1,4.9,35.55],[2,4.8,36.02]],"batl":[[1,5.9,12.04]],"ltp":4.1,"tv":4.74,"id":13010313},{"batb":[[0,6.2,24.25],[1,6,41.66],[2,5.8,18.73]],"batl":[[1,7,17]],"ltp":5.6,"tv":18.62,"id":16575966},{"batb":[[0,34,12.68],[1,32,7.61],[2,26,3.8]],"ltp":4.6,"tv":4.23,"id":16575965},{"batb":[[2,1.54,35.72]],"batl":[[0,1.63,32.73],[1,1.71,27.77],[2,1.81,22.74]],"ltp":1.87,"tv":97.58,"id":13010314}]}]}
{"op":"mcm","clk":"1008610825","pt":1580637806653,"mc":[{"id":"1.168224424","rc":[{"batl":[[0,5.6,8.4],[1,5.8,12.59],[2,5.9,12.04]],"ltp":4.1,"tv":4.74,"id":13010313},{"batb":[[2,5.8,27.13]],"batl":[[1,7,23.72]],"ltp":5.6,"tv":18.62,"id":16575966},{"batb":[[1,1.57,183.25]],"batl":[[1,1.69,42.01],[2,1.71,27.77]],"ltp":1.87,"tv":97.58,"id":13010314}]}]}
{"op":"mcm","clk":"1008611885","pt":1580637819077,"mc":[{"id":"1.168224424","rc":[{"batb":[[0,4.9,14.08],[1,4.8,21.61],[2,4.7,10.92]],"batl":[[1,5.9,12.04],[2,5.9,0]],"ltp":4.1,"tv":4.74,"id":13010313},{"batb":[[0,6,28.28],[1,5.8,8.4],[2,5.5,10.54]],"batl":[[0,7,23.72],[1,7,0]],"ltp":5.6,"tv":18.62,"id":16575966},{"batb":[[0,19.5,5.74],[1,1.01,0.51],[2,26,0]],"ltp":4.6,"tv":4.23,"id":16575965},{"batb":[[0,1.57,73.1],[1,1.54,35.72],[2,1.01,0.51]],"batl":[[0,1.69,42.01],[1,1.71,27.77],[2,1.71,0]],"ltp":1.87,"tv":97.58,"id":13010314}]}]}
{"op":"mcm","clk":"1008611944","pt":1580637819647,"mc":[{"id":"1.168224424","rc":[{"batb":[[2,1.01,0.51]],"batl":[[0,5.9,12.04],[1,5.9,0]],"ltp":4.1,"tv":4.74,"id":13010313},{"batb":[[1,5.5,10.54],[2,1.01,0.51]],"batl":[[0,7,17]],"ltp":5.6,"tv":18.62,"id":16575966},{"batb":[[0,1.54,35.72],[1,1.01,0.51],[2,1.01,0]],"batl":[[0,1.71,27.77],[1,1.71,0]],"ltp":1.87,"tv":97.58,"id":13010314}]}]}
{"op":"mcm","clk":"1008612070","pt":1580637821465,"mc":[{"id":"1.168224424","rc":[{"batb":[[2,4.7,37.82]],"ltp":4.1,"tv":4.74,"id":13010313},{"batb":[[1,5.9,21.96],[2,5.5,10.54]],"ltp":5.6,"tv":18.62,"id":16575966},{"batb":[[0,26,5.26],[1,25,10.43],[2,19.5,5.74]],"ltp":4.6,"tv":4.23,"id":16575965},{"batb":[[0,1.56,115.79],[1,1.55,80.57],[2,1.54,35.72]],"ltp":1.87,"tv":97.58,"id":13010314}]}]}
{"op":"mcm","clk":"1008612253","pt":1580637823392,"mc":[{"id":"1.168224424","rc":[{"batb":[[2,1.01,0.51]],"ltp":4.1,"tv":4.74,"id":13010313},{"batb":[[1,5.5,10.54],[2,1.01,0.51]],"ltp":5.6,"tv":18.62,"id":16575966},{"batb":[[0,19.5,5.74],[1,1.01,0.51],[2,19.5,0]],"ltp":4.6,"tv":4.23,"id":16575965}]}]}
{"op":"mcm","clk":"1008612421","pt":1580637825453,"mc":[{"id":"1.168224424","rc":[{"batb":[[0,4.9,52.1],[1,4.8,35.75]],"ltp":4.1,"tv":4.74,"id":13010313},{"batb":[[0,6.2,41.5],[1,6,41.16],[2,5.5,10.54]],"ltp":5.6,"tv":18.62,"id":16575966},{"batb":[[0,42,5.59],[1,40,7.78],[2,19.5,5.74]],"ltp":4.6,"tv":4.23,"id":16575965}]}]}
{"op":"mcm","clk":"1008612478","pt":1580637826282,"mc":[{"id":"1.168224424","rc":[{"batb":[[0,5.1,12.51],[1,5,13.22],[2,4.9,38.02]],"batl":[[1,6.2,11.17]],"ltp":4.1,"tv":4.74,"id":13010313},{"batb":[[2,5.9,18.18]],"batl":[[1,7.4,15.03]],"ltp":5.6,"tv":18.62,"id":16575966},{"batb":[[2,28,2.6]],"ltp":4.6,"tv":4.23,"id":16575965},{"batl":[[0,1.6,34.86],[1,1.63,32.57]],"ltp":1.87,"tv":97.58,"id":13010314}]}]}
{"op":"mcm","clk":"1008612495","pt":1580637826595,"mc":[{"id":"1.168224424","rc":[{"batl":[[0,5.7,8.4],[1,5.9,12.04],[2,6.2,11.17]],"ltp":4.1,"tv":4.74,"id":13010313},{"batb":[[1,6,49.56]],"batl":[[1,7.2,6.72],[2,7.4,15.03]],"ltp":5.6,"tv":18.62,"id":16575966},{"batl":[[2,1.64,42.01]],"ltp":1.87,"tv":97.58,"id":13010314}]}]}
{"op":"mcm","clk":"1008614021","pt":1580637847310,"mc":[{"id":"1.168224424","rc":[{"batb":[[0,5,13.22],[1,4.8,46.67],[2,1.01,0.51]],"batl":[[1,6.2,11.17],[2,6.2,0]],"ltp":4.1,"tv":4.74,"id":13010313},{"batb":[[0,6.2,16.75],[2,5.7,19.51]],"batl":[[0,7.2,6.72],[1,7.4,15.03],[2,7.4,0]],"ltp":5.6,"tv":18.62,"id":16575966},{"batb":[[0,28,2.6],[1,1.01,0.51],[2,28,0]],"ltp":4.6,"tv":4.23,"id":16575965},{"batb":[[0,1.53,78.98],[1,1.49,40.21],[2,1.01,0.51]],"batl":[[0,1.63,32.57],[1,1.64,42.01],[2,1.64,0]],"ltp":1.87,"tv":97.58,"id":13010314}]}]}
{"op":"mcm","clk":"1008614057","pt":1580637847682,"mc":[{"id":"1.168224424","rc":[{"batb":[[1,4.8,35.75]],"batl":[[0,6.2,11.17],[1,6.2,0]],"ltp":4.1,"tv":4.74,"id":13010313},{"batb":[[1,6,41.16]],"batl":[[0,7.4,15.03],[1,7.4,0]],"ltp":5.6,"tv":18.62,"id":16575966},{"batb":[[0,1.49,40.21],[1,1.01,0.51],[2,1.01,0]],"batl":[[1,1.64,0]],"ltp":1.87,"tv":97.58,"id":13010314}]}]}
{"op":"mcm","clk":"1008614257","pt":1580637850374,"mc":[{"id":"1.168224424","rc":[{"batb":[[1,4.8,51.01],[2,4.7,37.3]],"ltp":4.1,"tv":4.74,"id":13010313},{"batb":[[0,38,4.17],[1,36,9.69],[2,28,2.6]],"ltp":4.6,"tv":4.23,"id":16575965},{"batb":[[0,1.53,77.47],[1,1.52,86.6],[2,1.49,40.21]],"ltp":1.87,"tv":97.58,"id":13010314}]}]}
{"op":"mcm","clk":"1008614394","pt":1580637852289,"mc":[{"id":"1.168224424","rc":[{"batb":[[1,4.8,35.75],[2,1.01,0.51]],"ltp":4.1,"tv":4.74,"id":13010313},{"batb":[[0,28,2.6],[1,1.01,0.51],[2,28,0]],"ltp":4.6,"tv":4.23,"id":16575965},{"batb":[[0,1.49,40.21],[1,1.01,0.51],[2,1.49,0]],"ltp":1.87,"tv":97.58,"id":13010314}]}]}
{"op":"mcm","clk":"1008614628","pt":1580637855194,"mc":[{"id":"1.168224424","rc":[{"batb":[[1,4.9,46.22],[2,4.8,35.75]],"ltp":4.1,"tv":4.74,"id":13010313},{"batb":[[0,6.2,50.13]],"ltp":5.6,"tv":18.62,"id":16575966},{"batb":[[0,44,4.69],[1,42,7.09],[2,28,2.6]],"ltp":4.6,"tv":4.23,"id":16575965},{"batb":[[0,1.55,139.97],[1,1.54,82.6],[2,1.49,40.21]],"ltp":1.87,"tv":97.58,"id":13010314}]}]}
{"op":"mcm","clk":"1008614694","pt":1580637855976,"mc":[{"id":"1.168224424","rc":[{"batb":[[1,4.8,35.75],[2,1.01,0.51]],"ltp":4.1,"tv":4.74,"id":13010313},{"batb":[[0,6.2,16.75]],"ltp":5.6,"tv":18.62,"id":16575966},{"batb":[[0,28,2.6],[1,1.01,0.51],[2,28,0]],"ltp":4.6,"tv":4.23,"id":16575965},{"batb":[[0,1.49,40.21],[1,1.01,0.51],[2,1.49,0]],"ltp":1.87,"tv":97.58,"id":13010314}]}]}
{"op":"mcm","clk":"1008614960","pt":1580637859082,"mc":[{"id":"1.168224424","rc":[{"batb":[[1,4.8,51.01],[2,4.7,37.3]],"ltp":4.1,"tv":4.74,"id":13010313},{"batb":[[0,38,4.17],[1,36,9.69],[2,28,2.6]],"ltp":4.6,"tv":4.23,"id":16575965},{"batb":[[0,1.53,77.47],[1,1.52,86.6],[2,1.49,40.21]],"ltp":1.87,"tv":97.58,"id":13010314}]}]}
{"op":"mcm","clk":"1008615066","pt":1580637860431,"mc":[{"id":"1.168224424","rc":[{"batb":[[1,1.01,0.51],[2,4.7,0]],"ltp":4.1,"tv":4.74,"id":13010313},{"batb":[[1,5.7,19.51],[2,1.01,0.51]],"ltp":5.6,"tv":18.62,"id":16575966},{"batb":[[0,28,2.6],[1,1.01,0.51],[2,28,0]],"ltp":4.6,"tv":4.23,"id":16575965}]}]}
{"op":"mcm","clk":"1008615310","pt":1580637863399,"mc":[{"id":"1.168224424","rc":[{"batb":[[0,5,57.35],[1,4.9,34.01],[2,1.01,0.51]],"ltp":4.1,"tv":4.74,"id":13010313},{"batb":[[0,6.4,44.91],[1,6.2,38.17],[2,5.7,19.51]],"ltp":5.6,"tv":18.62,"id":16575966},{"batb":[[0,50,11.9],[1,28,2.6],[2,1.01,0.51]],"ltp":4.6,"tv":4.23,"id":16575965}]}]}
{"op":"mcm","clk":"1008615397","pt":1580637864387,"mc":[{"id":"1.168224424","rc":[{"batb":[[0,5.3,11.57],[1,5.2,12.35],[2,5,44.13]],"batl":[[1,6.4,20.14]],"ltp":4.1,"tv":4.74,"id":13010313},{"batb":[[1,6.2,54.22],[2,6,17]],"batl":[[1,7.8,13.14]],"ltp":5.6,"tv":18.62,"id":16575966},{"batb":[[1,30,2.79]],"ltp":4.6,"tv":4.23,"id":16575965},{"batl":[[0,1.55,39.18],[1,1.58,36.35]],"ltp":1.87,"tv":97.58,"id":13010314}]}]}
{"op":"mcm","clk":"1008615419","pt":1580637864697,"mc":[{"id":"1.168224424","rc":[{"batl":[[0,5.8,8.4],[1,6.2,11.17],[2,6.4,20.14]],"ltp":4.1,"tv":4.74,"id":13010313},{"batb":[[1,6.2,61.78]],"batl":[[1,7.6,5.88],[2,7.8,13.14]],"ltp":5.6,"tv":18.62,"id":16575966},{"batb":[[2,1.5,84.02]],"batl":[[2,1.61,42.01]],"ltp":1.87,"tv":97.58,"id":13010314}]}]}
{"op":"mcm","clk":"1008616127","pt":1580637873426,"mc":[{"id":"1.168224424","rc":[{"batb":[[0,5.2,12.35],[1,4.9,44.09],[2,1.01,0.51]],"batl":[[1,6.4,20.14],[2,6.4,0]],"ltp":4.1,"tv":4.74,"id":13010313},{"batb":[[0,6.4,19.64],[1,6.2,45.73]],"batl":[[0,7.6,5.88],[1,7.8,13.14],[2,7.8,0]],"ltp":5.6,"tv":18.62,"id":16575966},{"batb":[[0,1.01,0.51],[1,30,0],[2,1.01,0]],"ltp":4.6,"tv":4.23,"id":16575965},{"batb":[[0,1.5,84.02],[1,1.44,46.26],[2,1.01,0.51]],"batl":[[0,1.58,36.35],[1,1.61,42.01],[2,1.61,0]],"ltp":1.87,"tv":97.58,"id":13010314}]}]}
{"op":"mcm","clk":"1008616141","pt":1580637873636,"mc":[{"id":"1.168224424","rc":[{"batb":[[1,4.9,34.01]],"batl":[[0,6.4,20.14],[1,6.4,0]],"ltp":4.1,"tv":4.74,"id":13010313},{"batb":[[1,6.2,38.17]],"batl":[[0,7.8,13.14],[1,7.8,0]],"ltp":5.6,"tv":18.62,"id":16575966},{"batb":[[0,1.44,46.26],[1,1.01,0.51],[2,1.01,0]],"batl":[[1,1.61,0]],"ltp":1.87,"tv":97.58,"id":13010314}]}]}
{"op":"mcm","clk":"1008616344","pt":1580637876442,"mc":[{"id":"1.168224424","rc":[{"batb":[[1,4.9,50.4],[2,4.8,35.54]],"ltp":4.1,"tv":4.74,"id":13010313},{"batb":[[0,44,5.55],[1,42,7.06],[2,1.01,0.51]],"ltp":4.6,"tv":4.23,"id":16575965},{"batb":[[0,1.49,80.19],[1,1.48,96.47],[2,1.44,46.26]],"ltp":1.87,"tv":97.58,"id":13010314}]}]}
{"op":"mcm","clk":"1008617183","pt":1580637887436,"mc":[{"id":"1.168224424","rc":[{"batb":[[0,1.44,46.26],[1,1.01,0.51],[2,1.44,0]],"ltp":1.87,"tv":97.58,"id":13010314}]}]}
{"op":"mcm","clk":"1008617414","pt":1580637890346,"mc":[{"id":"1.168224424","rc":[{"batb":[[0,1.55,106.7],[1,1.54,82.45],[2,1.44,46.26]],"ltp":1.87,"tv":97.58,"id":13010314}]}]}
{"op":"mcm","clk":"1008617482","pt":1580637891125,"mc":[{"id":"1.168224424","rc":[{"batb":[[1,5.1,12.83],[2,4.9,50.4]],"batl":[[0,5.7,8.4],[1,5.9,11.88],[2,6.2,10.78]],"ltp":4.1,"tv":4.74,"id":13010313},{"batb":[[2,6,25.4]],"batl":[[0,7.2,15.97],[1,7.4,5.88],[2,7.6,14.01]],"ltp":5.6,"tv":18.62,"id":16575966},{"batb":[[2,1.52,117.95]],"batl":[[1,1.61,33.91],[2,1.63,42.01]],"ltp":1.87,"tv":97.58,"id":13010314}]}]}
{"op":"mcm","clk":"1008618246","pt":1580637901401,"mc":[{"id":"1.168224424","rc":[{"batb":[[0,5.1,12.83],[1,4.9,23.95],[2,4.8,46.46]],"batl":[[1,6.2,10.78],[2,6.2,0]],"ltp":4.1,"tv":4.74,"id":13010313},{"batb":[[0,6.2,38.17],[1,6,8.4],[2,5.9,18.41]],"batl":[[0,7.4,5.88],[1,7.6,14.01],[2,7.6,0]],"ltp":5.6,"tv":18.62,"id":16575966},{"batb":[[0,1.01,0.51],[1,42,0],[2,1.01,0]],"ltp":4.6,"tv":4.23,"id":16575965},{"batb":[[0,1.52,80.66],[1,1.47,42.65],[2,1.01,0.51]],"batl":[[0,1.61,33.91],[1,1.63,42.01],[2,1.63,0]],"ltp":1.87,"tv":97.58,"id":13010314}]}]}
{"op":"mcm","clk":"1008618288","pt":1580637901772,"mc":[{"id":"1.168224424","rc":[{"batb":[[2,4.8,35.54]],"batl":[[0,6.2,10.78],[1,6.2,0]],"ltp":4.1,"tv":4.74,"id":13010313},{"batb":[[1,5.9,18.41],[2,1.01,0.51]],"batl":[[0,7.6,14.01],[1,7.6,0]],"ltp":5.6,"tv":18.62,"id":16575966},{"batb":[[0,1.47,42.65],[1,1.01,0.51],[2,1.01,0]],"batl":[[1,1.63,0]],"ltp":1.87,"tv":97.58,"id":13010314}]}]}
{"op":"mcm","clk":"1008618548","pt":1580637904277,"mc":[{"id":"1.168224424","rc":[{"batb":[[1,6,41.45],[2,5.9,18.41]],"ltp":5.6,"tv":18.62,"id":16575966},{"batb":[[0,38,6.99],[1,36,9.55],[2,1.01,0.51]],"ltp":4.6,"tv":4.23,"id":16575965}]}]}
{"op":"mcm","clk":"1008618820","pt":1580637907179,"mc":[{"id":"1.168224424","rc":[{"batb":[[1,5,13.45],[2,4.9,23.95]],"batl":[[0,5.6,8.4],[1,5.8,12.35],[2,6,11.41]],"ltp":4.1,"tv":4.74,"id":13010313},{"batb":[[2,5.9,26.81]],"batl":[[0,7,17.23],[1,7.2,22.14]],"ltp":5.6,"tv":18.62,"id":16575966},{"batb":[[2,27,3.27]],"ltp":4.6,"tv":4.23,"id":16575965},{"batb":[[0,1.57,130.05],[1,1.56,78.56],[2,1.55,110.39]],"batl":[[1,1.64,31.71],[2,1.66,42.01]],"ltp":1.87,"tv":97.58,"id":13010314}]}]}
{"op":"mcm","clk":"1008619778","pt":1580637917293,"mc":[{"id":"1.168224424","rc":[{"batb":[[0,5,13.45],[1,4.8,35.54],[2,4.7,10.92]],"batl":[[1,6,11.41],[2,6,0]],"ltp":4.1,"tv":4.74,"id":13010313},{"batb":[[0,6,41.45],[1,5.9,8.4],[2,5.7,19.91]],"batl":[[0,7.2,22.14],[1,7.2,0]],"ltp":5.6,"tv":18.62,"id":16575966},{"batb":[[0,27,3.27],[1,1.01,0.51],[2,27,0]],"ltp":4.6,"tv":4.23,"id":16575965},{"batb":[[0,1.55,75.62],[1,1.5,38.95],[2,1.01,0.51]],"batl":[[0,1.64,31.71],[1,1.66,42.01],[2,1.66,0]],"ltp":1.87,"tv":97.58,"id":13010314}]}]}
{"op":"mcm","clk":"1008619819","pt":1580637917711,"mc":[{"id":"1.168224424","rc":[{"batb":[[2,1.01,0.51]],"batl":[[0,6,11.41],[1,6,0]],"ltp":4.1,"tv":4.74,"id":13010313},{"batb":[[1,5.7,19.91],[2,1.01,0.51]],"batl":[[0,7.2,15.42]],"ltp":5.6,"tv":18.62,"id":16575966},{"batb":[[0,1.5,38.95],[1,1.01,0.51],[2,1.01,0]],"batl":[[1,1.66,0]],"ltp":1.87,"tv":97.58,"id":13010314}]}]}
{"op":"mcm","clk":"1008620336","pt":1580637923391,"mc":[{"id":"1.168224424","rc":[{"batb":[[1,4.9,31.91],[2,4.8,35.54]],"ltp":4.1,"tv":4.74,"id":13010313},{"batb":[[0,6.2,41.65],[1,6,41.45],[2,5.7,19.91]],"ltp":5.6,"tv":18.62,"id":16575966},{"batb":[[0,40,4.13],[1,38,8.71],[2,27,3.27]],"ltp":4.6,"tv":4.23,"id":16575965},{"batb":[[0,1.57,76.18],[1,1.56,78.3],[2,1.5,38.95]],"ltp":1.87,"tv":97.58,"id":13010314}]}]}
{"op":"mcm","clk":"1008620577","pt":1580637925897,"mc":[{"id":"1.168224424","rc":[{"batb":[[1,4.8,35.54],[2,1.01,0.51]],"ltp":4.1,"tv":4.74,"id":13010313},{"batb":[[0,6,41.45],[1,5.7,19.91],[2,1.01,0.51]],"ltp":5.6,"tv":18.62,"id":16575966},{"batb":[[0,27,3.27],[1,1.01,0.51],[2,27,0]],"ltp":4.6,"tv":4.23,"id":16575965},{"batb":[[0,1.5,38.95],[1,1.01,0.51],[2,1.5,0]],"ltp":1.87,"tv":97.58,"id":13010314}]}]}
{"op":"mcm","clk":"1008620884","pt":1580637929429,"mc":[{"id":"1.168224424","rc":[{"batb":[[2,4.7,37.51]],"ltp":4.1,"tv":4.74,"id":13010313},{"batb":[[0,6,51.02],[1,5.9,21.63],[2,5.7,19.91]],"ltp":5.6,"tv":18.62,"id":16575966},{"batb":[[0,34,10.76],[1,32,9.61],[2,27,3.27]],"ltp":4.6,"tv":4.23,"id":16575965},{"batb":[[0,1.54,97.88],[1,1.53,84.53],[2,1.5,38.95]],"ltp":1.87,"tv":97.58,"id":13010314}]}]}
{"op":"mcm","clk":"1008621260","pt":1580637933403,"mc":[{"id":"1.168224424","rc":[{"batb":[[1,1.01,0.51],[2,4.7,0]],"ltp":4.1,"tv":4.74,"id":13010313},{"batb":[[0,5.7,19.91],[1,1.01,0.51],[2,5.7,0]],"ltp":5.6,"tv":18.62,"id":16575966},{"batb":[[0,27,3.27],[1,1.01,0.51],[2,27,0]],"ltp":4.6,"tv":4.23,"id":16575965}]}]}
{"op":"mcm","clk":"1008621527","pt":1580637936347,"mc":[{"id":"1.168224424","rc":[{"batb":[[0,5.3,11.8],[1,5.1,12.43],[2,5,42.51]],"batl":[[1,6.4,10.39]],"ltp":4.1,"tv":4.74,"id":13010313},{"batb":[[0,6.4,36.28],[1,6.2,54.9],[2,6,17.62]],"batl":[[1,7.8,13.22]],"ltp":5.6,"tv":18.62,"id":16575966},{"batb":[[0,46,6.28],[1,44,6.39],[2,27,3.27]],"ltp":4.6,"tv":4.23,"id":16575965},{"batl":[[0,1.57,37.92],[1,1.6,35.01],[2,1.64,31.71]],"ltp":1.87,"tv":97.58,"id":13010314}]}]}
{"op":"mcm","clk":"1008621557","pt":1580637936731,"mc":[{"id":"1.168224424","rc":[{"batb":[[2,5,29.06]],"batl":[[0,5.7,8.4],[1,6,11.41],[2,6.4,10.39]],"ltp":4.1,"tv":4.74,"id":13010313},{"batb":[[1,6.2,62.47]],"batl":[[1,7.4,5.88],[2,7.8,13.22]],"ltp":5.6,"tv":18.62,"id":16575966},{"batb":[[2,1.01,0.51]],"ltp":4.6,"tv":4.23,"id":16575965},{"batb":[[2,1.51,82.34]],"batl":[[2,1.62,42.01]],"ltp":1.87,"tv":97.58,"id":13010314}]}]}
{"op":"mcm","clk":"1008622580","pt":1580637949250,"mc":[{"id":"1.168224424","rc":[{"batb":[[0,5.1,12.43],[1,4.9,34.24],[2,4.8,10.92]],"batl":[[1,6.4,10.39],[2,6.4,0]],"ltp":4.1,"tv":4.74,"id":13010313},{"batb":[[0,6.2,46.02],[1,6,17.62],[2,1.01,0.51]],"batl":[[0,7.4,5.88],[1,7.8,13.22],[2,7.8,0]],"ltp":5.6,"tv":18.62,"id":16575966},{"batb":[[0,1.01,0.51],[1,44,0],[2,1.01,0]],"ltp":4.6,"tv":4.23,"id":16575965},{"batb":[[0,1.51,82.34],[1,1.45,45.32],[2,1.01,0.51]],"batl":[[0,1.6,35.01],[1,1.62,42.01],[2,1.62,0]],"ltp":1.87,"tv":97.58,"id":13010314}]}]}
{"op":"mcm","clk":"1008622618","pt":1580637949719,"mc":[{"id":"1.168224424","rc":[{"batb":[[2,1.01,0.51]],"batl":[[0,6.4,10.39],[1,6.4,0]],"ltp":4.1,"tv":4.74,"id":13010313},{"batb":[[0,6.2,38.46]],"batl":[[0,7.8,13.22],[1,7.8,0]],"ltp":5.6,"tv":18.62,"id":16575966},{"batb":[[0,1.45,45.32],[1,1.01,0.51],[2,1.01,0]],"batl":[[1,1.62,0]],"ltp":1.87,"tv":97.58,"id":13010314}]}]}
{"op":"mcm","clk":"1008623091","pt":1580637955193,"mc":[{"id":"1.168224424","rc":[{"batb":[[1,5,39.89],[2,4.9,34.24]],"ltp":4.1,"tv":4.74,"id":13010313},{"batb":[[0,6.4,45.95],[1,6.2,38.46],[2,6,17.62]],"ltp":5.6,"tv":18.62,"id":16575966},{"batb":[[0,50,5.29],[1,48,5.4],[2,1.01,0.51]],"ltp":4.6,"tv":4.23,"id":16575965},{"batb":[[0,1.53,103.66],[1,1.52,86.77],[2,1.45,45.32]],"ltp":1.87,"tv":97.58,"id":13010314}]}]}
{"op":"mcm","clk":"1008623333","pt":1580637958305,"mc":[{"id":"1.168224424","rc":[{"batb":[[1,4.9,34.24],[2,1.01,0.51]],"ltp":4.1,"tv":4.74,"id":13010313},{"batb":[[0,6.2,38.46],[1,6,17.62],[2,1.01,0.51]],"ltp":5.6,"tv":18.62,"id":16575966},{"batb":[[0,1.01,0.51],[1,48,0],[2,1.01,0]],"ltp":4.6,"tv":4.23,"id":16575965},{"batb":[[0,1.45,45.32],[1,1.01,0.51],[2,1.45,0]],"ltp":1.87,"tv":97.58,"id":13010314}]}]}
{"op":"mcm","clk":"1008623577","pt":1580637961323,"mc":[{"id":"1.168224424","rc":[{"batb":[[2,4.8,35.84]],"ltp":4.1,"tv":4.74,"id":13010313},{"batb":[[0,6.2,47.49],[1,6,58.67]],"ltp":5.6,"tv":18.62,"id":16575966},{"batb":[[0,38,5.76],[1,36,9.62],[2,1.01,0.51]],"ltp":4.6,"tv":4.23,"id":16575965},{"batb":[[0,1.49,140.54],[1,1.48,96.89],[2,1.45,45.32]],"ltp":1.87,"tv":97.58,"id":13010314}]}]}
{"op":"mcm","clk":"1008624324","pt":1580637970329,"mc":[{"id":"1.168224424","rc":[{"batb":[[1,1.01,0.51],[2,4.8,0]],"ltp":4.1,"tv":4.74,"id":13010313},{"batb":[[0,6,17.62],[1,1.01,0.51],[2,1.01,0]],"ltp":5.6,"tv":18.62,"id":16575966},{"batb":[[0,1.01,0.51],[1,36,0],[2,1.01,0]],"ltp":4.6,"tv":4.23,"id":16575965}]}]}
{"op":"mcm","clk":"1008624549","pt":1580637973120,"mc":[{"id":"1.168224424","rc":[{"batb":[[0,5.1,62.26],[1,5,32.38],[2,1.01,0.51]],"ltp":4.1,"tv":4.74,"id":13010313},{"batb":[[0,6.6,47.51],[1,6.4,35.54],[2,6,17.62]],"ltp":5.6,"tv":18.62,"id":16575966},{"batb":[[0,75,3.35],[1,70,6.03],[2,1.01,0.51]],"ltp":4.6,"tv":4.23,"id":16575965}]}]}
{"op":"mcm","clk":"1008624627","pt":1580637974108,"mc":[{"id":"1.168224424","rc":[{"batb":[[0,5.5,10.78],[1,5.3,11.41],[2,5.1,49.83]],"batl":[[1,6.8,17.94]],"ltp":4.1,"tv":4.74,"id":13010313},{"batb":[[0,6.6,61.59],[2,6.2,15.42]],"batl":[[1,8.4,11.33]],"ltp":5.6,"tv":18.62,"id":16575966},{"batl":[[0,1.51,44.06],[1,1.55,39.66]],"ltp":1.87,"tv":97.58,"id":13010314}]}]}
{"op":"mcm","clk":"1008624693","pt":1580637975094,"mc":[{"id":"1.168224424","rc":[{"batl":[[0,5.9,8.4],[1,6.4,10.39],[2,6.8,17.94]],"ltp":4.1,"tv":4.74,"id":13010313},{"batb":[[1,6.4,43.1]],"batl":[[0,7.8,19.1]],"ltp":5.6,"tv":18.62,"id":16575966},{"batb":[[1,1.48,184.27]],"batl":[[2,1.58,42.01]],"ltp":1.87,"tv":97.58,"id":13010314}]}]}
{"op":"mcm","clk":"1008625364","pt":1580637983114,"mc":[{"id":"1.168224424","rc":[{"batb":[[0,5.3,11.41],[1,5,32.38],[2,4.9,10.08]],"batl":[[1,6.8,17.94],[2,6.8,0]],"ltp":4.1,"tv":4.74,"id":13010313},{"batb":[[0,6.4,43.1],[1,6.2,15.42],[2,1.01,0.51]],"batl":[[0,7.8,5.88]],"ltp":5.6,"tv":18.62,"id":16575966},{"batb":[[0,1.01,0.51],[1,70,0],[2,1.01,0]],"ltp":4.6,"tv":4.23,"id":16575965},{"batb":[[0,1.48,87.38],[1,1.38,55.31],[2,1.01,0.51]],"batl":[[0,1.55,39.66],[1,1.58,42.01],[2,1.58,0]],"ltp":1.87,"tv":97.58,"id":13010314}]}]}
{"op":"mcm","clk":"1008625440","pt":1580637984149,"mc":[{"id":"1.168224424","rc":[{"batb":[[2,1.01,0.51]],"batl":[[0,6.8,17.94],[1,6.8,0]],"ltp":4.1,"tv":4.74,"id":13010313},{"batb":[[0,6.4,35.54]],"batl":[[0,8.4,11.33],[1,8.4,0]],"ltp":5.6,"tv":18.62,"id":16575966},{"batb":[[0,1.38,55.31],[1,1.01,0.51],[2,1.01,0]],"batl":[[1,1.58,0]],"ltp":1.87,"tv":97.58,"id":13010314}]}]}
{"op":"mcm","clk":"1008625507","pt":1580637984929,"mc":[{"id":"1.168224424","rc":[{"batb":[[1,1.01,0.51],[2,1.01,0]],"ltp":4.1,"tv":4.74,"id":13010313},{"batb":[[0,6.2,15.42],[1,1.01,0.51],[2,1.01,0]],"ltp":5.6,"tv":18.62,"id":16575966}]}]}
{"op":"mcm","clk":"1008625761","pt":1580637988058,"mc":[{"id":"1.168224424","rc":[{"batb":[[1,5.2,32.8],[2,5.1,31.21]],"ltp":4.1,"tv":4.74,"id":13010313},{"batb":[[0,6.8,24.63],[1,6.6,33.79],[2,6.2,15.42]],"ltp":5.6,"tv":18.62,"id":16575966},{"batb":[[0,1.48,118.28],[1,1.47,99.49],[2,1.38,55.31]],"ltp":1.87,"tv":97.58,"id":13010314}]}]}
{"op":"mcm","clk":"1008625937","pt":1580637990346,"mc":[{"id":"1.168224424","rc":[{"batb":[[1,1.01,0.51],[2,5.1,0]],"ltp":4.1,"tv":4.74,"id":13010313},{"batb":[[0,6.2,15.42],[1,1.01,0.51],[2,6.2,0]],"ltp":5.6,"tv":18.62,"id":16575966},{"batb":[[0,1.38,55.31],[1,1.01,0.51],[2,1.38,0]],"ltp":1.87,"tv":97.58,"id":13010314}]}]}
{"op":"mcm","clk":"1008626139","pt":1580637993236,"mc":[{"id":"1.168224424","rc":[{"batb":[[1,5,38.66],[2,4.9,34.09]],"ltp":4.1,"tv":4.74,"id":13010313},{"batb":[[0,6.4,49.52],[1,6.2,53.52],[2,1.01,0.51]],"ltp":5.6,"tv":18.62,"id":16575966},{"batb":[[0,48,2.16],[1,46,6.02],[2,1.01,0.51]],"ltp":4.6,"tv":4.23,"id":16575965},{"batb":[[0,1.43,149.45],[1,1.42,116.09],[2,1.38,55.31]],"ltp":1.87,"tv":97.58,"id":13010314}]}]}
{"op":"mcm","clk":"1008626529","pt":1580637998438,"mc":[{"id":"1.168224424","rc":[{"batb":[[1,1.01,0.51],[2,4.9,0]],"ltp":4.1,"tv":4.74,"id":13010313},{"batb":[[0,6.2,15.42],[1,1.01,0.51],[2,1.01,0]],"ltp":5.6,"tv":18.62,"id":16575966},{"batb":[[0,1.01,0.51],[1,46,0],[2,1.01,0]],"ltp":4.6,"tv":4.23,"id":16575965}]}]}
{"op":"mcm","clk":"1008626789","pt":1580638001448,"mc":[{"id":"1.168224424","rc":[{"batb":[[0,5.8,19.2],[1,5.4,32.1],[2,5.3,40.03]],"batl":[[1,7.4,15.34]],"ltp":4.1,"tv":4.74,"id":13010313},{"batb":[[0,7,50.67],[1,6.8,31.28],[2,6.2,15.42]],"batl":[[1,9,9.76]],"ltp":5.6,"tv":18.62,"id":16575966},{"batl":[[0,1.44,53.58],[1,1.55,39.66]],"ltp":1.87,"tv":97.58,"id":13010314}]}]}
{"op":"mcm","clk":"1008626805","pt":1580638001654,"mc":[{"id":"1.168224424","rc":[{"batb":[[2,5.3,28.62]],"ltp":4.1,"tv":4.74,"id":13010313},{"batb":[[2,6,17.47]],"ltp":5.6,"tv":18.62,"id":16575966}]}]}
{"op":"mcm","clk":"1008626909","pt":1580638003057,"mc":[{"id":"1.168224424","rc":[{"batl":[[0,6,8.4],[1,6.8,17.94],[2,7.4,15.34]],"ltp":4.1,"tv":4.74,"id":13010313},{"batl":[[0,8,5.88],[1,8.4,11.33],[2,9,9.76]],"ltp":5.6,"tv":18.62,"id":16575966},{"batl":[[1,1.52,42.01],[2,1.55,39.66]],"ltp":1.87,"tv":97.58,"id":13010314}]}]}
{"op":"mcm","clk":"1008627185","pt":1580638006347,"mc":[{"id":"1.168224424","rc":[{"batb":[[2,6.6,6.72]],"ltp":5.6,"tv":18.62,"id":16575966},{"batb":[[1,1.42,216.07]],"ltp":1.87,"tv":97.58,"id":13010314}]}]}
{"op":"mcm","clk":"1008627415","pt":1580638009360,"mc":[{"id":"1.168224424","rc":[{"batb":[[1,5.7,19.83],[2,5.4,32.1]],"batl":[[2,7.2,15.82]],"ltp":4.1,"tv":4.74,"id":13010313},{"batb":[[2,1.39,53.98]],"batl":[[1,1.45,52.32],[2,1.52,42.01]],"ltp":1.87,"tv":97.58,"id":13010314}]}]}
{"op":"mcm","clk":"1008627451","pt":1580638009774,"mc":[{"id":"1.168224424","rc":[{"batb":[[0,5.7,19.83],[1,5.4,32.1],[2,5.3,28.62]],"ltp":4.1,"tv":4.74,"id":13010313},{"batl":[[0,1.45,52.32],[1,1.52,42.01],[2,1.56,38.55]],"ltp":1.87,"tv":97.58,"id":13010314}]}]}
{"op":"mcm","clk":"1008628783","pt":1580638025909,"mc":[{"id":"1.168224424","rc":[{"batb":[[0,5.6,20.46]],"batl":[[1,6.6,19.04]],"ltp":4.1,"tv":4.74,"id":13010313},{"batb":[[0,7,38.71],[1,6.8,44.03]],"batl":[[1,8.2,12.04],[2,8.8,10.39]],"ltp":5.6,"tv":18.62,"id":16575966},{"batb":[[2,1.4,52.48]],"batl":[[0,1.46,50.91],[2,1.57,37.53]],"ltp":1.87,"tv":97.58,"id":13010314}]}]}
{"op":"mcm","clk":"1008630033","pt":1580638041705,"mc":[{"id":"1.168224424","rc":[{"batb":[[2,1.4,52.32]],"batl":[[0,1.46,50.75],[2,1.57,37.37]],"ltp":1.87,"tv":97.58,"id":13010314}]}]}
{"op":"mcm","clk":"1008631112","pt":1580638054921,"mc":[{"id":"1.168224424","rc":[{"batb":[[0,7,30.1],[1,6.8,12.75]],"ltp":5.6,"tv":18.62,"id":16575966},{"batb":[[0,1.43,118]],"ltp":1.87,"tv":97.58,"id":13010314}]}]}
{"op":"mcm","clk":"1008631396","pt":1580638057847,"mc":[{"id":"1.168224424","rc":[{"batb":[[0,7.2,15.95],[1,7,30.1],[2,6.8,12.75]],"ltp":5.6,"tv":18.62,"id":16575966}]}]}
{"op":"mcm","clk":"1008633773","pt":1580638085103,"mc":[{"id":"1.168224424","rc":[{"trd":[[1.43,8.4]],"batb":[[0,1.43,113.8]],"ltp":1.43,"tv":105.98,"id":13010314}],"tv":133.58}]}
{"op":"mcm","clk":"1008637060","pt":1580638124238,"mc":[{"id":"1.168224424","rc":[{"batb":[[0,5.1,10.08],[1,4.9,13.61],[2,1.01,0.51]],"batl":[[1,7.2,15.82],[2,7.2,0]],"ltp":4.1,"tv":4.74,"id":13010313},{"batb":[[0,6.6,6.72],[1,5.8,18.65],[2,1.01,0.51]],"batl":[[1,8.8,10.39],[2,8.8,0]],"ltp":5.6,"tv":18.62,"id":16575966},{"batb":[[0,1.42,99.98],[1,1.36,59.48],[2,1.01,0.51]],"batl":[[0,1.52,42.01],[1,1.57,37.37],[2,1.57,0]],"ltp":1.43,"tv":105.98,"id":13010314}]}]}
{"op":"mcm","clk":"1008637190","pt":1580638125849,"mc":[{"id":"1.168224424","rc":[{"batb":[[0,4.9,13.61],[1,1.01,0.51],[2,1.01,0]],"batl":[[0,7.2,15.82],[1,7.2,0]],"ltp":4.1,"tv":4.74,"id":13010313},{"batb":[[0,5.8,18.65],[1,1.01,0.51],[2,1.01,0]],"batl":[[0,8.8,10.39],[1,8.8,0]],"ltp":5.6,"tv":18.62,"id":16575966},{"batb":[[0,1.36,59.48],[1,1.01,0.51],[2,1.01,0]],"batl":[[0,1.57,37.37],[1,1.57,0]],"ltp":1.43,"tv":105.98,"id":13010314}]}]}
{"op":"mcm","clk":"1008637306","pt":1580638127248,"mc":[{"id":"1.168224424","rc":[{"batb":[[0,1.39,98.93],[1,1.38,131.46],[2,1.36,59.48]],"ltp":1.43,"tv":105.98,"id":13010314}]}]}
{"op":"mcm","clk":"1008637571","pt":1580638130420,"mc":[{"id":"1.168224424","rc":[{"batb":[[0,6,17.47],[1,5.8,30.1],[2,5.7,24.39]],"batl":[[1,7.6,14.48]],"ltp":4.1,"tv":4.74,"id":13010313},{"batb":[[0,7.6,33.95],[1,7.4,26.27],[2,7.2,11.09]],"batl":[[1,9.2,9.36]],"ltp":5.6,"tv":18.62,"id":16575966},{"batl":[[0,1.42,57.52],[1,1.5,45.4],[2,1.57,37.37]],"ltp":1.43,"tv":105.98,"id":13010314}]}]}
{"op":"mcm","clk":"1008637594","pt":1580638130735,"mc":[{"id":"1.168224424","rc":[{"batl":[[0,6.6,6.72],[1,7.2,15.82],[2,7.6,14.48]],"ltp":4.1,"tv":4.74,"id":13010313},{"batl":[[0,8.6,5.04],[1,8.8,10.39],[2,9.2,9.36]],"ltp":5.6,"tv":18.62,"id":16575966},{"batb":[[1,1.38,241.53]],"batl":[[1,1.46,42.01],[2,1.5,45.4]],"ltp":1.43,"tv":105.98,"id":13010314}]}]}
{"op":"mcm","clk":"1008638112","pt":1580638137455,"mc":[{"id":"1.168224424","rc":[{"batb":[[1,5.4,20.49],[2,1.01,0.51]],"ltp":4.1,"tv":4.74,"id":13010313},{"batb":[[0,7.2,11.09],[1,7,6.72],[2,6.4,15.03]],"ltp":5.6,"tv":18.62,"id":16575966},{"batb":[[0,1.38,110.07],[1,1.36,59.48],[2,1.33,65.54]],"ltp":1.43,"tv":105.98,"id":13010314}]}]}
{"op":"mcm","clk":"1008638162","pt":1580638138034,"mc":[{"id":"1.168224424","rc":[{"batb":[[0,5.4,11.25],[1,1.01,0.51],[2,1.01,0]],"batl":[[0,7.6,14.48],[1,7.2,0],[2,7.6,0]],"ltp":4.1,"tv":4.74,"id":13010313},{"batb":[[0,6.4,15.03],[1,1.01,0.51],[2,6.4,0]],"batl":[[0,9.2,9.36],[1,8.8,0],[2,9.2,0]],"ltp":5.6,"tv":18.62,"id":16575966},{"batb":[[0,1.33,65.54],[1,1.01,0.51],[2,1.33,0]],"batl":[[0,1.5,45.4],[1,1.46,0],[2,1.5,0]],"ltp":1.43,"tv":105.98,"id":13010314}]}]}
{"op":"mcm","clk":"1008638347","pt":1580638140419,"mc":[{"id":"1.168224424","rc":[{"batb":[[1,5.2,37.11],[2,5.1,31.25]],"ltp":4.1,"tv":4.74,"id":13010313},{"batb":[[0,6.8,30.21],[1,6.6,33.92],[2,6.4,15.03]],"ltp":5.6,"tv":18.62,"id":16575966},{"batb":[[0,1.36,128.31],[1,1.35,146.29],[2,1.33,65.54]],"ltp":1.43,"tv":105.98,"id":13010314}]}]}
{"op":"mcm","clk":"1008638476","pt":1580638142342,"mc":[{"id":"1.168224424","rc":[{"batb":[[1,1.01,0.51],[2,5.1,0]],"ltp":4.1,"tv":4.74,"id":13010313},{"batb":[[0,6.4,15.03],[1,1.01,0.51],[2,6.4,0]],"ltp":5.6,"tv":18.62,"id":16575966},{"batb":[[0,1.33,65.54],[1,1.01,0.51],[2,1.33,0]],"ltp":1.43,"tv":105.98,"id":13010314}]}]}
{"op":"mcm","clk":"1008638766","pt":1580638145252,"mc":[{"id":"1.168224424","rc":[{"batb":[[0,5.7,23.67],[1,5.6,25.47],[2,5.4,11.25]],"ltp":4.1,"tv":4.74,"id":13010313},{"batb":[[0,7.4,36.85],[1,7.2,27.83],[2,6.4,15.03]],"ltp":5.6,"tv":18.62,"id":16575966},{"batb":[[0,1.4,138.03],[1,1.39,127.59],[2,1.33,65.54]],"ltp":1.43,"tv":105.98,"id":13010314}]}]}
{"op":"mcm","clk":"1008639017","pt":1580638148129,"mc":[{"id":"1.168224424","rc":[{"batb":[[0,5.4,11.25],[1,1.01,0.51],[2,5.4,0]],"ltp":4.1,"tv":4.74,"id":13010313},{"batb":[[0,6.4,15.03],[1,1.01,0.51],[2,6.4,0]],"ltp":5.6,"tv":18.62,"id":16575966},{"batb":[[0,1.33,65.54],[1,1.01,0.51],[2,1.33,0]],"ltp":1.43,"tv":105.98,"id":13010314}]}]}
{"op":"mcm","clk":"1008639186","pt":1580638150429,"mc":[{"id":"1.168224424","rc":[{"batb":[[1,5.2,36.96],[2,5.1,31.25]],"ltp":4.1,"tv":4.74,"id":13010313},{"batb":[[0,6.8,30.88],[1,6.6,33.92],[2,6.4,15.03]],"ltp":5.6,"tv":18.62,"id":16575966},{"batb":[[0,1.36,126.85],[1,1.35,146.29],[2,1.33,65.54]],"ltp":1.43,"tv":105.98,"id":13010314}]}]}
{"op":"mcm","clk":"1008639269","pt":1580638151368,"mc":[{"id":"1.168224424","rc":[{"batb":[[0,1.33,65.54],[1,1.01,0.51],[2,1.33,0]],"ltp":1.43,"tv":105.98,"id":13010314}]}]}
{"op":"mcm","clk":"1008639431","pt":1580638153356,"mc":[{"id":"1.168224424","rc":[{"batl":[[0,6.2,10.86],[1,7,17.15],[2,7.6,14.48]],"ltp":4.1,"tv":4.74,"id":13010313},{"batl":[[0,7.6,14.08],[1,8.4,11.64],[2,9.2,9.36]],"ltp":5.6,"tv":18.62,"id":16575966},{"batb":[[0,1.46,82.85],[1,1.45,105.49],[2,1.44,46.74]],"batl":[[1,1.65,31.16]],"ltp":1.43,"tv":105.98,"id":13010314}]}]}
{"op":"mcm","clk":"1008639446","pt":1580638153563,"mc":[{"id":"1.168224424","rc":[{"batl":[[2,7.6,0]],"ltp":4.1,"tv":4.74,"id":13010313},{"batl":[[2,9.2,0]],"ltp":5.6,"tv":18.62,"id":16575966}]}]}
{"op":"mcm","clk":"1008639552","pt":1580638154784,"mc":[{"id":"1.168224424","rc":[{"batl":[[0,5.9,8.4],[1,6.2,10.86],[2,7,17.15]],"ltp":4.1,"tv":4.74,"id":13010313},{"batb":[[2,6.4,22.59]],"batl":[[1,7.8,5.88],[2,8.4,11.64]],"ltp":5.6,"tv":18.62,"id":16575966},{"batb":[[1,1.45,198.75]],"batl":[[1,1.54,42.01],[2,1.65,31.16]],"ltp":1.43,"tv":105.98,"id":13010314}]}]}
{"op":"mcm","clk":"1008640848","pt":1580638170332,"mc":[{"id":"1.168224424","rc":[{"batb":[[0,4.9,10.08],[1,4.5,17.07],[2,1.01,0.51]],"batl":[[1,7,17.15],[2,7,0]],"ltp":4.1,"tv":4.74,"id":13010313},{"batb":[[0,6.4,7.56],[1,5.4,11.09],[2,1.01,0.51]],"batl":[[0,7.8,5.88],[1,8.4,11.64],[2,8.4,0]],"ltp":5.6,"tv":18.62,"id":16575966},{"batb":[[0,1.45,93.26],[1,1.38,55.79],[2,1.01,0.51]],"batl":[[0,1.54,42.01],[1,1.65,31.16],[2,1.65,0]],"ltp":1.43,"tv":105.98,"id":13010314}]}]}
{"op":"mcm","clk":"1008640920","pt":1580638170991,"mc":[{"id":"1.168224424","rc":[{"batl":[[1,8.4,11.49]],"ltp":5.6,"tv":18.62,"id":16575966}]}]}
{"op":"mcm","clk":"1008641014","pt":1580638171982,"mc":[{"id":"1.168224424","rc":[{"batb":[[0,4.5,17.07],[1,1.01,0.51],[2,1.01,0]],"batl":[[0,7,17.15],[1,7,0]],"ltp":4.1,"tv":4.74,"id":13010313},{"batb":[[0,5.4,11.09],[1,1.01,0.51],[2,1.01,0]],"batl":[[0,8.4,11.49],[1,8.4,0]],"ltp":5.6,"tv":18.62,"id":16575966},{"batb":[[0,1.38,55.79],[1,1.01,0.51],[2,1.01,0]],"batl":[[0,1.65,31.16],[1,1.65,0]],"ltp":1.43,"tv":105.98,"id":13010314}]}]}
{"op":"mcm","clk":"1008641118","pt":1580638173184,"mc":[{"id":"1.168224424","rc":[{"batb":[[1,4.4,30.38],[2,4.3,46.42]],"ltp":4.1,"tv":4.74,"id":13010313},{"batb":[[0,5.7,37.46],[1,5.6,24.8],[2,5.4,11.09]],"ltp":5.6,"tv":18.62,"id":16575966},{"batb":[[0,1.4,122.23],[1,1.39,127.4],[2,1.38,55.79]],"ltp":1.43,"tv":105.98,"id":13010314}]}]}
{"op":"mcm","clk":"1008641975","pt":1580638183204,"mc":[{"id":"1.168224424","rc":[{"batb":[[0,1.38,55.79],[1,1.01,0.51],[2,1.38,0]],"ltp":1.43,"tv":105.98,"id":13010314}]}]}
{"op":"mcm","clk":"1008642240","pt":1580638186315,"mc":[{"id":"1.168224424","rc":[{"batb":[[0,1.6,111.92],[1,1.59,73.43],[2,1.38,55.79]],"ltp":1.43,"tv":105.98,"id":13010314}]}]}
{"op":"mcm","clk":"1008642312","pt":1580638187199,"mc":[{"id":"1.168224424","rc":[{"batl":[[0,5,10.08],[1,5.1,16.21],[2,5.8,12.2]],"ltp":4.1,"tv":4.74,"id":13010313},{"batb":[[2,5.5,9.24]],"batl":[[0,6.2,10.7],[1,6.6,6.72],[2,7.2,15.97]],"ltp":5.6,"tv":18.62,"id":16575966},{"batb":[[1,1.59,105.37],[2,1.57,73.1]],"batl":[[1,1.69,42.01],[2,1.97,17.47]],"ltp":1.43,"tv":105.98,"id":13010314}]}]}
{"op":"mcm","clk":"1008642496","pt":1580638189529,"mc":[{"id":"1.168224424","rc":[{"batb":[[0,8,15.12],[1,1.01,0.51]],"ltp":4.6,"tv":4.23,"id":16575965}]}]}
{"op":"mcm","clk":"1008644000","pt":1580638208141,"mc":[{"id":"1.168224424","rc":[{"batb":[[0,4.2,12.6],[1,3.6,14.79],[2,1.01,0.51]],"batl":[[1,5.8,12.2],[2,5.8,0]],"ltp":4.1,"tv":4.74,"id":13010313},{"batb":[[0,5.5,9.24],[1,4.4,18.33],[2,1.01,0.51]],"batl":[[0,6.6,6.72],[1,7.2,15.97],[2,7.2,0]],"ltp":5.6,"tv":18.62,"id":16575966},{"batb":[[0,1.57,73.1],[1,1.48,41.78],[2,1.01,0.51]],"batl":[[0,1.69,42.01],[1,1.97,17.47],[2,1.97,0]],"ltp":1.43,"tv":105.98,"id":13010314}]}]}
{"op":"mcm","clk":"1008644149","pt":1580638209857,"mc":[{"id":"1.168224424","rc":[{"batb":[[0,3.6,14.79],[1,1.01,0.51],[2,1.01,0]],"batl":[[0,5.8,12.2],[1,5.8,0]],"ltp":4.1,"tv":4.74,"id":13010313},{"batb":[[0,4.4,18.33],[1,1.01,0.51],[2,1.01,0]],"batl":[[0,7.2,15.97],[1,7.2,0]],"ltp":5.6,"tv":18.62,"id":16575966},{"batb":[[0,1.48,41.78],[1,1.01,0.51],[2,1.01,0]],"batl":[[0,1.97,17.47],[1,1.97,0]],"ltp":1.43,"tv":105.98,"id":13010314}]}]}
{"op":"mcm","clk":"1008644430","pt":1580638213270,"mc":[{"id":"1.168224424","rc":[{"batb":[[0,4.1,72.87],[1,4,54.22],[2,3.6,14.79]],"ltp":4.1,"tv":4.74,"id":13010313},{"batb":[[0,5.4,44.94],[1,5.3,28],[2,4.4,18.33]],"ltp":5.6,"tv":18.62,"id":16575966},{"batb":[[0,1.66,69.29],[1,1.65,64.04],[2,1.48,41.78]],"ltp":1.43,"tv":105.98,"id":13010314}]}]}
{"op":"mcm","clk":"1008644618","pt":1580638215669,"mc":[{"id":"1.168224424","rc":[{"batb":[[0,3.6,14.79],[1,1.01,0.51],[2,3.6,0]],"ltp":4.1,"tv":4.74,"id":13010313},{"batb":[[0,4.4,18.33],[1,1.01,0.51],[2,4.4,0]],"ltp":5.6,"tv":18.62,"id":16575966},{"batb":[[0,1.48,41.78],[1,1.01,0.51],[2,1.48,0]],"ltp":1.43,"tv":105.98,"id":13010314}]}]}
{"op":"mcm","clk":"1008644825","pt":1580638218600,"mc":[{"id":"1.168224424","rc":[{"batb":[[1,3.45,56.82],[2,3.4,40.89]],"ltp":4.1,"tv":4.74,"id":13010313},{"batb":[[0,4.5,58.76],[1,4.4,61.13],[2,1.01,0.51]],"ltp":5.6,"tv":18.62,"id":16575966},{"batb":[[0,1.49,94.62],[1,1.48,138.73],[2,1.01,0.51]],"ltp":1.43,"tv":105.98,"id":13010314}]}]}
{"op":"mcm","clk":"1008646003","pt":1580638233396,"mc":[{"id":"1.168224424","rc":[{"batb":[[1,1.01,0.51],[2,3.4,0]],"ltp":4.1,"tv":4.74,"id":13010313},{"batb":[[0,4.4,18.33],[1,1.01,0.51],[2,1.01,0]],"ltp":5.6,"tv":18.62,"id":16575966}]}]}
{"op":"mcm","clk":"1008646225","pt":1580638236430,"mc":[{"id":"1.168224424","rc":[{"batb":[[0,5.1,12.67],[1,5,35.58],[2,4.9,34.26]],"batl":[[1,6.8,17.86]],"ltp":4.1,"tv":4.74,"id":13010313},{"batb":[[0,6.4,48.63],[1,6.2,38.46],[2,6,17.07]],"batl":[[1,8.2,12.12]],"ltp":5.6,"tv":18.62,"id":16575966},{"batb":[[2,1.39,53.98]],"batl":[[0,1.54,40.68],[1,1.78,24.16],[2,1.97,17.47]],"ltp":1.43,"tv":105.98,"id":13010314}]}]}
{"op":"mcm","clk":"1008646292","pt":1580638237320,"mc":[{"id":"1.168224424","rc":[{"batl":[[0,5.7,8.4],[1,5.8,12.2],[2,6.8,17.86]],"ltp":4.1,"tv":4.74,"id":13010313},{"batb":[[2,6,25.48]],"batl":[[1,7.4,5.88],[2,8.2,12.12]],"ltp":5.6,"tv":18.62,"id":16575966},{"batb":[[1,1.48,226.11]],"batl":[[1,1.58,42.01],[2,1.78,24.16]],"ltp":1.43,"tv":105.98,"id":13010314}]}]}
{"op":"mcm","clk":"1008647215","pt":1580638249423,"mc":[{"id":"1.168224424","rc":[{"batb":[[0,1.01,0.51],[1,1.01,0]],"ltp":4.6,"tv":4.23,"id":16575965}]}]}
{"op":"mcm","clk":"1008647942","pt":1580638259158,"mc":[{"id":"1.168224424","rc":[{"batb":[[0,4.7,10.92],[1,4,22.11],[2,1.01,0.51]],"batl":[[1,6.8,17.86],[2,6.8,0]],"ltp":4.1,"tv":4.74,"id":13010313},{"batb":[[0,6,8.4],[1,4.9,14.08],[2,1.01,0.51]],"batl":[[0,7.4,5.88],[1,8.2,12.12],[2,8.2,0]],"ltp":5.6,"tv":18.62,"id":16575966},{"batb":[[0,1.48,87.38],[1,1.39,53.98],[2,1.01,0.51]],"batl":[[0,1.58,42.01],[1,1.78,24.16],[2,1.78,0]],"ltp":1.43,"tv":105.98,"id":13010314}]}]}
{"op":"mcm","clk":"1008648008","pt":1580638259935,"mc":[{"id":"1.168224424","rc":[{"batb":[[0,4,22.11],[1,1.01,0.51],[2,1.01,0]],"batl":[[0,6.8,17.86],[1,6.8,0]],"ltp":4.1,"tv":4.74,"id":13010313},{"batb":[[0,4.9,14.08],[1,1.01,0.51],[2,1.01,0]],"batl":[[0,8.2,12.12],[1,8.2,0]],"ltp":5.6,"tv":18.62,"id":16575966},{"batb":[[0,1.39,53.98],[1,1.01,0.51],[2,1.01,0]],"batl":[[0,1.78,24.16],[1,1.78,0]],"ltp":1.43,"tv":105.98,"id":13010314}]}]}
{"op":"mcm","clk":"1008648140","pt":1580638261759,"mc":[{"id":"1.168224424","rc":[{"batb":[[1,3.95,37.79],[2,3.9,29.49]],"ltp":4.1,"tv":4.74,"id":13010313},{"batb":[[0,5.2,21.57],[1,5.1,30.95],[2,4.9,14.08]],"ltp":5.6,"tv":18.62,"id":16575966},{"batb":[[0,1.4,144.46],[1,1.39,181.57],[2,1.01,0.51]],"ltp":1.43,"tv":105.98,"id":13010314}]}]}
{"op":"mcm","clk":"1008648226","pt":1580638262866,"mc":[{"id":"1.168224424","rc":[{"batb":[[1,1.01,0.51],[2,3.9,0]],"ltp":4.1,"tv":4.74,"id":13010313},{"batb":[[0,4.9,14.08],[1,1.01,0.51],[2,4.9,0]],"ltp":5.6,"tv":18.62,"id":16575966}]}]}
{"op":"mcm","clk":"1008648541","pt":1580638266257,"mc":[{"id":"1.168224424","rc":[{"batb":[[0,5.8,19.2],[1,5.7,33.85],[2,5.6,25.31]],"batl":[[1,7.4,15.03]],"ltp":4.1,"tv":4.74,"id":13010313},{"batb":[[0,7.4,25.21],[1,7.2,28.11],[2,6.8,12.83]],"batl":[[1,8.8,10.15]],"ltp":5.6,"tv":18.62,"id":16575966},{"batb":[[2,1.35,62.55]],"batl":[[0,1.45,52.24],[1,1.56,38.71],[2,1.78,24.16]],"ltp":1.43,"tv":105.98,"id":13010314}]}]}
{"op":"mcm","clk":"1008648590","pt":1580638266829,"mc":[{"id":"1.168224424","rc":[{"batl":[[0,6.4,7.56],[1,6.8,17.86],[2,7.4,15.03]],"ltp":4.1,"tv":4.74,"id":13010313},{"batb":[[2,6.8,19.55]],"batl":[[0,8.2,17.16]],"ltp":5.6,"tv":18.62,"id":16575966},{"batb":[[1,1.39,289.11]],"batl":[[1,1.48,42.01],[2,1.56,38.71]],"ltp":1.43,"tv":105.98,"id":13010314}]}]}
{"op":"mcm","clk":"1008649423","pt":1580638276449,"mc":[{"id":"1.168224424","rc":[{"batb":[[0,5,13.06],[1,1.01,0.51],[2,5.6,0]],"batl":[[0,7.4,15.03],[1,6.8,0],[2,7.4,0]],"ltp":4.1,"tv":4.74,"id":13010313},{"batb":[[0,5.8,18.73],[1,1.01,0.51],[2,6.8,0]],"batl":[[0,8.8,10.15],[1,8.8,0]],"ltp":5.6,"tv":18.62,"id":16575966},{"batb":[[0,1.35,62.55],[1,1.01,0.51],[2,1.35,0]],"batl":[[0,1.56,38.71],[1,1.48,0],[2,1.56,0]],"ltp":1.43,"tv":105.98,"id":13010314}]}]}
{"op":"mcm","clk":"1008649634","pt":1580638278701,"mc":[{"id":"1.168224424","rc":[{"batb":[[1,4.9,50.01],[2,4.8,35.68]],"ltp":4.1,"tv":4.74,"id":13010313},{"batb":[[0,6.4,19.92],[1,6.2,39.24],[2,5.8,18.73]],"ltp":5.6,"tv":18.62,"id":16575966},{"batb":[[0,1.36,142.04],[1,1.35,209.17],[2,1.01,0.51]],"ltp":1.43,"tv":105.98,"id":13010314}]}]}
{"op":"mcm","clk":"1008649746","pt":1580638279999,"mc":[{"id":"1.168224424","rc":[{"batb":[[1,1.01,0.51],[2,4.8,0]],"ltp":4.1,"tv":4.74,"id":13010313},{"batb":[[0,5.8,18.73],[1,1.01,0.51],[2,5.8,0]],"ltp":5.6,"tv":18.62,"id":16575966}]}]}
{"op":"mcm","clk":"1008650079","pt":1580638283382,"mc":[{"id":"1.168224424","rc":[{"batb":[[0,6.2,33.78],[1,6,43.05],[2,5.8,8.4]],"batl":[[0,7,6.72],[1,7.4,15.03],[2,8.8,10.54]],"ltp":4.1,"tv":4.74,"id":13010313},{"batb":[[0,8,23.33],[1,7.8,23.63],[2,7.4,16.58]],"batl":[[1,9.2,5.04],[2,11,6.92]],"ltp":5.6,"tv":18.62,"id":16575966},{"batb":[[2,1.34,123.51]],"batl":[[0,1.4,60.43],[1,1.42,42.01],[2,1.46,50.51]],"ltp":1.43,"tv":105.98,"id":13010314}]}]}
{"op":"mcm","clk":"1008650156","pt":1580638284168,"mc":[{"id":"1.168224424","rc":[{"batb":[[0,10,16.8],[1,1.01,0.51]],"ltp":4.6,"tv":4.23,"id":16575965}]}]}
{"op":"mcm","clk":"1008651287","pt":1580638296202,"mc":[{"id":"1.168224424","rc":[{"trd":[[1.4,50]],"batl":[[0,1.4,35.43]],"ltp":1.4,"tv":155.98,"id":13010314}],"tv":183.58}]}
{"op":"mcm","clk":"1008651606","pt":1580638300128,"mc":[{"id":"1.168224424","rc":[{"batb":[[1,1.35,208.23]],"batl":[[2,1.46,49.73]],"ltp":1.4,"tv":155.98,"id":13010314}]}]}
{"op":"mcm","clk":"1008653078","pt":1580638313070,"mc":[{"id":"1.168224424","rc":[{"batb":[[0,1.01,0.51],[1,1.01,0]],"ltp":4.6,"tv":4.23,"id":16575965}]}]}
{"op":"mcm","clk":"1008653831","pt":1580638319733,"mc":[{"id":"1.168224424","rc":[{"batb":[[0,6.2,15.97],[1,5.8,8.4],[2,5.6,20.22]],"ltp":4.1,"tv":4.74,"id":13010313},{"batb":[[0,7.4,16.58],[1,6.6,13.53],[2,1.01,0.51]],"ltp":5.6,"tv":18.62,"id":16575966},{"batb":[[0,1.35,61.61],[1,1.34,123.51],[2,1.27,82.62]],"ltp":1.4,"tv":155.98,"id":13010314}]}]}
{"op":"mcm","clk":"1008654233","pt":1580638323202,"mc":[{"id":"1.168224424","rc":[{"batb":[[0,5.8,8.4],[1,5.6,55.75],[2,5.5,26.27]],"batl":[[1,8.8,10.54],[2,8.8,0]],"ltp":4.1,"tv":4.74,"id":13010313},{"batb":[[0,7.4,5.88],[1,7.2,38.18],[2,7,29.49]],"batl":[[0,9.2,5.04],[1,11,6.92],[2,11,0]],"ltp":5.6,"tv":18.62,"id":16575966},{"batb":[[0,1.34,123.51],[1,1.29,99.87],[2,1.28,192.68]],"batl":[[0,1.42,42.01],[1,1.46,49.73],[2,1.46,0]],"ltp":1.4,"tv":155.98,"id":13010314}]}]}
{"op":"mcm","clk":"1008654323","pt":1580638323929,"mc":[{"id":"1.168224424","rc":[{"batb":[[0,5.6,55.75],[1,5.5,26.27],[2,1.01,0.51]],"batl":[[0,8.8,10.54],[1,8.8,0]],"ltp":4.1,"tv":4.74,"id":13010313},{"batb":[[0,7.2,38.18],[1,7,29.49],[2,6.6,13.53]],"batl":[[0,11,6.92],[1,11,0]],"ltp":5.6,"tv":18.62,"id":16575966},{"batb":[[0,1.29,99.87],[1,1.28,192.68],[2,1.27,82.62]],"batl":[[0,1.46,49.73],[1,1.46,0]],"ltp":1.4,"tv":155.98,"id":13010314}]}]}
{"op":"mcm","clk":"1008654581","pt":1580638326228,"mc":[{"id":"1.168224424","rc":[{"batb":[[0,5.6,20.22],[1,1.01,0.51],[2,1.01,0]],"batl":[[0,8.6,10.7]],"ltp":4.1,"tv":4.74,"id":13010313},{"batb":[[0,6.6,13.53],[1,1.01,0.51],[2,6.6,0]],"ltp":5.6,"tv":18.62,"id":16575966},{"batb":[[0,1.28,82.62],[1,1.01,0.51],[2,1.27,0]],"ltp":1.4,"tv":155.98,"id":13010314}]}]}
{"op":"mcm","clk":"1008654907","pt":1580638329331,"mc":[{"id":"1.168224424","rc":[{"batb":[[0,6.2,40.12],[1,5.6,20.22],[2,1.01,0.51]],"ltp":4.1,"tv":4.74,"id":13010313},{"batb":[[0,8.2,28.71],[1,8,22.25],[2,6.6,13.53]],"ltp":5.6,"tv":18.62,"id":16575966},{"batb":[[0,1.34,219.84],[1,1.33,158.78],[2,1.28,82.62]],"ltp":1.4,"tv":155.98,"id":13010314}]}]}
{"op":"mcm","clk":"1008655178","pt":1580638331805,"mc":[{"id":"1.168224424","rc":[{"batb":[[0,6.4,15.93],[1,6.2,40.12],[2,5.6,20.22]],"ltp":4.1,"tv":4.74,"id":13010313}]}]}
{"op":"mcm","clk":"1008655303","pt":1580638333107,"mc":[{"id":"1.168224424","rc":[{"batb":[[0,5.6,20.22],[1,1.01,0.51],[2,5.6,0]],"ltp":4.1,"tv":4.74,"id":13010313},{"batb":[[0,6.6,13.53],[1,1.01,0.51],[2,6.6,0]],"ltp":5.6,"tv":18.62,"id":16575966},{"batb":[[0,1.28,82.62],[1,1.01,0.51],[2,1.28,0]],"ltp":1.4,"tv":155.98,"id":13010314}]}]}
{"op":"mcm","clk":"1008655717","pt":1580638336413,"mc":[{"id":"1.168224424","rc":[{"batb":[[0,1.29,104.13],[1,1.28,275.3],[2,1.01,0.51]],"ltp":1.4,"tv":155.98,"id":13010314}]}]}
{"op":"mcm","clk":"1008656036","pt":1580638339239,"mc":[{"id":"1.168224424","rc":[{"batb":[[0,7.2,31.99],[1,7,30.44],[2,5.6,20.22]],"ltp":4.1,"tv":4.74,"id":13010313},{"batb":[[0,9.4,25.45],[1,9.2,16.5],[2,6.6,13.53]],"ltp":5.6,"tv":18.62,"id":16575966}]}]}
{"op":"mcm","clk":"1008656166","pt":1580638340443,"mc":[{"id":"1.168224424","rc":[{"batb":[[0,7.2,43.32],[2,6.4,15.19]],"batl":[[1,12,14.4]],"ltp":4.1,"tv":4.74,"id":13010313},{"batb":[[2,8.8,7.4]],"batl":[[1,14.5,9.76]],"ltp":5.6,"tv":18.62,"id":16575966},{"batb":[[2,1.19,126.13]],"batl":[[0,1.32,79.23],[1,1.39,63.18]],"ltp":1.4,"tv":155.98,"id":13010314}]}]}
{"op":"mcm","clk":"1008656262","pt":1580638341233,"mc":[{"id":"1.168224424","rc":[{"batb":[[2,6.6,6.72]],"batl":[[0,8.4,5.04],[1,8.6,10.7],[2,12,14.4]],"ltp":4.1,"tv":4.74,"id":13010313},{"batb":[[1,1.28,424.85]],"batl":[[1,1.35,42.01],[2,1.39,63.18]],"ltp":1.4,"tv":155.98,"id":13010314}]}]}
{"op":"mcm","clk":"1008656385","pt":1580638342322,"mc":[{"id":"1.168224424","rc":[{"batl":[[0,11,11.12]],"ltp":5.6,"tv":18.62,"id":16575966}]}]}
{"op":"mcm","clk":"1008657285","pt":1580638350137,"mc":[{"id":"1.168224424","rc":[{"batb":[[0,7.2,11.33],[1,6.6,6.72],[2,6.4,15.19]],"ltp":4.1,"tv":4.74,"id":13010313},{"batb":[[0,8.8,7.4],[1,8.4,5.04],[2,7.6,10.07]],"ltp":5.6,"tv":18.62,"id":16575966},{"batb":[[0,1.28,232.17],[1,1.19,126.13],[2,1.01,0.51]],"ltp":1.4,"tv":155.98,"id":13010314}]}]}
{"op":"mcm","clk":"1008657340","pt":1580638350659,"mc":[{"id":"1.168224424","rc":[{"batb":[[0,6.6,6.72],[1,6.4,15.19],[2,1.01,0.51]],"batl":[[1,12,14.4],[2,12,0]],"ltp":4.1,"tv":4.74,"id":13010313},{"batb":[[0,8.4,5.04],[1,7.6,10.07],[2,1.01,0.51]],"batl":[[0,11,4.2]],"ltp":5.6,"tv":18.62,"id":16575966},{"batb":[[0,1.28,149.55]],"batl":[[0,1.35,42.01],[1,1.39,63.18],[2,1.39,0]],"ltp":1.4,"tv":155.98,"id":13010314}]}]}
{"op":"mcm","clk":"1008657512","pt":1580638352273,"mc":[{"id":"1.168224424","rc":[{"batb":[[0,6.4,15.19],[1,1.01,0.51],[2,1.01,0]],"batl":[[0,12,14.4],[1,12,0]],"ltp":4.1,"tv":4.74,"id":13010313},{"batb":[[0,7.6,10.07],[1,1.01,0.51],[2,1.01,0]],"batl":[[0,14.5,9.76],[1,14.5,0]],"ltp":5.6,"tv":18.62,"id":16575966},{"batb":[[0,1.19,126.13],[1,1.01,0.51],[2,1.01,0]],"batl":[[0,1.39,63.18],[1,1.39,0]],"ltp":1.4,"tv":155.98,"id":13010314}]}]}
{"op":"mcm","clk":"1008657848","pt":1580638355354,"mc":[{"id":"1.168224424","rc":[{"batb":[[0,7.6,23.65],[1,7.4,27.17],[2,6.4,15.19]],"ltp":4.1,"tv":4.74,"id":13010313},{"batb":[[0,10,13.64],[1,9.8,14.62],[2,7.6,10.07]],"ltp":5.6,"tv":18.62,"id":16575966},{"batb":[[0,1.27,159],[1,1.26,212.14],[2,1.19,126.13]],"ltp":1.4,"tv":155.98,"id":13010314}]}]}
{"op":"mcm","clk":"1008657939","pt":1580638356182,"mc":[{"id":"1.168224424","rc":[{"batb":[[0,6.4,15.19],[1,1.01,0.51],[2,6.4,0]],"ltp":4.1,"tv":4.74,"id":13010313},{"batb":[[0,7.6,10.07],[1,1.01,0.51],[2,7.6,0]],"ltp":5.6,"tv":18.62,"id":16575966},{"batb":[[0,1.19,126.13],[1,1.01,0.51],[2,1.19,0]],"ltp":1.4,"tv":155.98,"id":13010314}]}]}
{"op":"mcm","clk":"1008658260","pt":1580638359362,"mc":[{"id":"1.168224424","rc":[{"batb":[[1,6.2,52.72],[2,6,42.09]],"ltp":4.1,"tv":4.74,"id":13010313},{"batb":[[0,8.2,28.65],[1,8,22.21],[2,7.6,10.07]],"ltp":5.6,"tv":18.62,"id":16575966},{"batb":[[0,1.2,331.61],[1,1.19,354.8],[2,1.01,0.51]],"ltp":1.4,"tv":155.98,"id":13010314}]}]}
{"op":"mcm","clk":"1008658801","pt":1580638365173,"mc":[{"id":"1.168224424","rc":[{"batb":[[1,1.01,0.51],[2,6,0]],"ltp":4.1,"tv":4.74,"id":13010313},{"batb":[[0,7.6,10.07],[1,1.01,0.51],[2,7.6,0]],"ltp":5.6,"tv":18.62,"id":16575966}]}]}
{"op":"mcm","clk":"1008659107","pt":1580638368344,"mc":[{"id":"1.168224424","rc":[{"batb":[[0,9.4,22.62],[1,9.2,17.04],[2,6.4,15.19]],"ltp":4.1,"tv":4.74,"id":13010313},{"batb":[[0,12,31.4],[1,11.5,24.69],[2,7.6,10.07]],"ltp":5.6,"tv":18.62,"id":16575966}]}]}
{"op":"mcm","clk":"1008659178","pt":1580638369099,"mc":[{"id":"1.168224424","rc":[{"batb":[[1,9.2,32.93],[2,8.2,5.04]],"batl":[[0,10.5,4.2],[1,12,14.4],[2,18.5,6.37]],"ltp":4.1,"tv":4.74,"id":13010313},{"batb":[[2,11,10.62]],"batl":[[0,13.5,3.36],[1,14.5,9.76],[2,22,4.64]],"ltp":5.6,"tv":18.62,"id":16575966},{"batb":[[0,1.21,168.04],[1,1.2,331.61],[2,1.19,354.8]],"batl":[[0,1.23,119.2],[1,1.26,42.01],[2,1.3,89.23]],"ltp":1.4,"tv":155.98,"id":13010314}]}]}
{"op":"mcm","clk":"1008659757","pt":1580638375611,"mc":[{"id":"1.168224424","rc":[{"batb":[[0,12,23.48],[1,11,10.62],[2,10.5,4.2]],"ltp":5.6,"tv":18.62,"id":16575966}]}]}
{"op":"mcm","clk":"1008660089","pt":1580638379319,"mc":[{"id":"1.168224424","rc":[{"batb":[[0,12.5,8.06],[1,12,23.48],[2,11,10.62]],"ltp":5.6,"tv":18.62,"id":16575966}]}]}
{"op":"mcm","clk":"1008660174","pt":1580638380215,"mc":[{"id":"1.168224424","rc":[{"batb":[[0,7.8,9.52],[1,1.01,0.51],[2,8.2,0]],"batl":[[0,18.5,6.37],[1,12,0],[2,18.5,0]],"ltp":4.1,"tv":4.74,"id":13010313},{"batb":[[0,9.2,16.21],[1,1.01,0.51],[2,11,0]],"batl":[[0,22,4.64],[1,14.5,0],[2,22,0]],"ltp":5.6,"tv":18.62,"id":16575966},{"batb":[[0,1.11,213.07],[1,1.01,0.51],[2,1.19,0]],"batl":[[0,1.3,89.23],[1,1.26,0],[2,1.3,0]],"ltp":1.4,"tv":155.98,"id":13010314}]}]}
{"op":"mcm","clk":"1008660374","pt":1580638382391,"mc":[{"id":"1.168224424","rc":[{"batb":[[0,7.8,33.9],[1,7.6,25.63],[2,1.01,0.51]],"ltp":4.1,"tv":4.74,"id":13010313},{"batb":[[0,10,35.47],[1,9.8,14.23],[2,9.2,16.21]],"ltp":5.6,"tv":18.62,"id":16575966},{"batb":[[0,1.13,210.15],[1,1.12,386.24],[2,1.11,213.07]],"ltp":1.4,"tv":155.98,"id":13010314}]}]}
{"op":"mcm","clk":"1008660936","pt":1580638388914,"mc":[{"id":"1.168224424","rc":[{"batb":[[0,7.8,9.52],[1,1.01,0.51],[2,1.01,0]],"ltp":4.1,"tv":4.74,"id":13010313},{"batb":[[0,9.2,16.21],[1,1.01,0.51],[2,9.2,0]],"ltp":5.6,"tv":18.62,"id":16575966}]}]}
{"op":"mcm","clk":"1008661252","pt":1580638392221,"mc":[{"id":"1.168224424","rc":[{"batb":[[0,14,9.69],[1,13.5,25.75],[2,11,10.78]],"batl":[[1,30,5.59]],"ltp":4.1,"tv":4.74,"id":13010313},{"batb":[[0,18,11.55],[1,17.5,10.69],[2,15.5,4.88]],"ltp":5.6,"tv":18.62,"id":16575966},{"batl":[[0,1.16,151.15],[1,1.19,142.41],[2,1.3,89.23]],"ltp":1.4,"tv":155.98,"id":13010314}]}]}
{"op":"mcm","clk":"1008661316","pt":1580638392837,"mc":[{"id":"1.168224424","rc":[{"batb":[[2,11.5,3.36]],"ltp":4.1,"tv":4.74,"id":13010313},{"batl":[[1,1.18,42.01],[2,1.19,142.41]],"ltp":1.4,"tv":155.98,"id":13010314}]}]}
{"op":"mcm","clk":"1008662296","pt":1580638403244,"mc":[{"id":"1.168224424","rc":[{"batb":[[0,11.5,3.36],[1,11,10.78],[2,1.01,0.51]],"batl":[[0,30,5.59],[1,30,0]],"ltp":4.1,"tv":4.74,"id":13010313},{"batb":[[0,13.5,3.36],[1,13,7.4],[2,1.01,0.51]],"ltp":5.6,"tv":18.62,"id":16575966},{"batb":[[0,1.07,350.29],[1,1.01,0.51],[2,1.11,0]],"batl":[[0,1.18,42.01],[1,1.19,142.41],[2,1.19,0]],"ltp":1.4,"tv":155.98,"id":13010314}]}]}
{"op":"mcm","clk":"1008662396","pt":1580638404343,"mc":[{"id":"1.168224424","rc":[{"batb":[[0,11,10.78],[1,1.01,0.51],[2,1.01,0]],"ltp":4.1,"tv":4.74,"id":13010313},{"batb":[[0,13,7.4],[1,1.01,0.51],[2,1.01,0]],"ltp":5.6,"tv":18.62,"id":16575966},{"batl":[[0,1.19,142.41],[1,1.19,0]],"ltp":1.4,"tv":155.98,"id":13010314}]}]}
{"op":"mcm","clk":"1008662556","pt":1580638405952,"mc":[{"id":"1.168224424","rc":[{"batb":[[0,11.5,10.83],[1,11,39.61],[2,1.01,0.51]],"ltp":4.1,"tv":4.74,"id":13010313},{"batb":[[0,15,7.94],[1,14.5,15.89],[2,13,7.4]],"ltp":5.6,"tv":18.62,"id":16575966}]}]}
{"op":"mcm","clk":"1008662760","pt":1580638408333,"mc":[{"id":"1.168224424","rc":[{"batb":[[0,1.16,330.94],[1,1.15,248.84],[2,1.07,350.29]],"ltp":1.4,"tv":155.98,"id":13010314}]}]}
{"op":"mcm","clk":"1008662803","pt":1580638408851,"mc":[{"id":"1.168224424","rc":[{"batb":[[2,9.8,4.2]],"batl":[[0,12.5,3.36],[1,14.5,9.91],[2,29,6.06]],"ltp":4.1,"tv":4.74,"id":13010313},{"batl":[[0,17.5,6.92]],"ltp":5.6,"tv":18.62,"id":16575966},{"batb":[[0,1.17,168.04],[1,1.16,330.94],[2,1.15,410.45]],"batl":[[1,1.22,42.01],[2,1.26,106.46]],"ltp":1.4,"tv":155.98,"id":13010314}]}]}
{"op":"mcm","clk":"1008663030","pt":1580638411453,"mc":[{"id":"1.168224424","rc":[{"batb":[[0,8,15.12],[1,1.01,0.51]],"ltp":4.6,"tv":4.23,"id":16575965}]}]}
{"op":"mcm","clk":"1008663829","pt":1580638420327,"mc":[{"id":"1.168224424","rc":[{"batb":[[0,11,10.78],[1,9.8,4.2],[2,8.8,7.24]],"ltp":4.1,"tv":4.74,"id":13010313},{"batb":[[0,13,7.4],[1,12,3.36],[2,10,12.75]],"ltp":5.6,"tv":18.62,"id":16575966},{"batb":[[1,1.15,161.61],[2,1.07,333.14]],"ltp":1.4,"tv":155.98,"id":13010314}]}]}
{"op":"mcm","clk":"1008663844","pt":1580638420549,"mc":[{"id":"1.168224424","rc":[{"batb":[[0,9.8,4.2],[1,8.8,7.24],[2,1.01,0.51]],"batl":[[1,29,6.06],[2,29,0]],"ltp":4.1,"tv":4.74,"id":13010313},{"batb":[[0,12,3.36],[1,10,12.75],[2,1.01,0.51]],"ltp":5.6,"tv":18.62,"id":16575966},{"batb":[[1,1.07,333.14],[2,1.01,0.51]],"batl":[[0,1.22,42.01],[1,1.26,106.46],[2,1.26,0]],"ltp":1.4,"tv":155.98,"id":13010314}]}]}
{"op":"mcm","clk":"1008663950","pt":1580638421855,"mc":[{"id":"1.168224424","rc":[{"batb":[[0,8.8,7.24],[1,1.01,0.51],[2,1.01,0]],"batl":[[0,29,6.06],[1,29,0]],"ltp":4.1,"tv":4.74,"id":13010313},{"batb":[[0,10,12.75],[1,1.01,0.51],[2,1.01,0]],"ltp":5.6,"tv":18.62,"id":16575966},{"batb":[[0,1.07,333.14],[1,1.01,0.51],[2,1.01,0]],"batl":[[0,1.26,106.46],[1,1.26,0]],"ltp":1.4,"tv":155.98,"id":13010314}]}]}
{"op":"mcm","clk":"1008664084","pt":1580638423266,"mc":[{"id":"1.168224424","rc":[{"batb":[[0,8.8,34.02],[1,8.6,19.6],[2,1.01,0.51]],"ltp":4.1,"tv":4.74,"id":13010313},{"batb":[[0,11.5,22.04],[1,11,27.54],[2,10,12.75]],"ltp":5.6,"tv":18.62,"id":16575966},{"batb":[[0,1.08,620.43],[1,1.07,333.14],[2,1.01,0.51]],"ltp":1.4,"tv":155.98,"id":13010314}]}]}
{"op":"mcm","clk":"1008664144","pt":1580638423942,"mc":[{"id":"1.168224424","rc":[{"batb":[[0,8.8,7.24],[1,1.01,0.51],[2,1.01,0]],"ltp":4.1,"tv":4.74,"id":13010313},{"batb":[[0,10,12.75],[1,1.01,0.51],[2,10,0]],"ltp":5.6,"tv":18.62,"id":16575966},{"batb":[[0,1.07,333.14],[1,1.01,0.51],[2,1.01,0]],"ltp":1.4,"tv":155.98,"id":13010314}]}]}
{"op":"mcm","clk":"1008664427","pt":1580638427329,"mc":[{"id":"1.168224424","rc":[{"batb":[[0,12.5,14.88],[1,12,23.91],[2,8.8,7.24]],"ltp":4.1,"tv":4.74,"id":13010313},{"batb":[[0,16,17.91],[1,15.5,13.54],[2,10,12.75]],"ltp":5.6,"tv":18.62,"id":16575966},{"batb":[[0,1.14,513.01],[1,1.07,333.14],[2,1.01,0.51]],"ltp":1.4,"tv":155.98,"id":13010314}]}]}
{"op":"mcm","clk":"1008664632","pt":1580638429952,"mc":[{"id":"1.168224424","rc":[{"batb":[[0,8.8,7.24],[1,1.01,0.51],[2,8.8,0]],"ltp":4.1,"tv":4.74,"id":13010313},{"batb":[[0,10,12.75],[1,1.01,0.51],[2,10,0]],"ltp":5.6,"tv":18.62,"id":16575966},{"batb":[[0,1.07,333.14],[1,1.01,0.51],[2,1.01,0]],"ltp":1.4,"tv":155.98,"id":13010314}]}]}
{"op":"mcm","clk":"1008664872","pt":1580638432876,"mc":[{"id":"1.168224424","rc":[{"batb":[[0,8.8,34.02],[1,8.6,19.6],[2,1.01,0.51]],"ltp":4.1,"tv":4.74,"id":13010313},{"batb":[[0,11.5,22.04],[1,11,27.54],[2,10,12.75]],"ltp":5.6,"tv":18.62,"id":16575966},{"batb":[[0,1.08,620.43],[1,1.07,333.14],[2,1.01,0.51]],"ltp":1.4,"tv":155.98,"id":13010314}]}]}
{"op":"mcm","clk":"1008665686","pt":1580638442912,"mc":[{"id":"1.168224424","rc":[{"batb":[[0,1.07,333.14],[1,1.01,0.51],[2,1.01,0]],"ltp":1.4,"tv":155.98,"id":13010314}]}]}
{"op":"mcm","clk":"1008666008","pt":1580638446413,"mc":[{"id":"1.168224424","rc":[{"batb":[[2,6.6,14.01]],"batl":[[0,11,6.92],[1,28,6.45],[2,29,6.06]],"ltp":4.1,"tv":4.74,"id":13010313},{"batl":[[0,13.5,11.64]],"ltp":5.6,"tv":18.62,"id":16575966},{"batb":[[0,1.22,215],[1,1.21,388.02],[2,1.08,314.57]],"batl":[[1,1.37,67.27]],"ltp":1.4,"tv":155.98,"id":13010314}]}]}
{"op":"mcm","clk":"1008666063","pt":1580638446939,"mc":[{"id":"1.168224424","rc":[{"batb":[[2,8,5.88]],"batl":[[0,10,4.2],[1,11,6.92],[2,28,6.45]],"ltp":4.1,"tv":4.74,"id":13010313},{"batb":[[2,10,16.95]],"batl":[[0,13,3.36],[1,13.5,11.64]],"ltp":5.6,"tv":18.62,"id":16575966},{"batb":[[0,1.22,383.04]],"batl":[[1,1.28,42.01],[2,1.37,67.27]],"ltp":1.4,"tv":155.98,"id":13010314}]}]}
{"op":"mcm","clk":"1008667380","pt":1580638462125,"mc":[{"id":"1.168224424","rc":[{"batb":[[0,6.6,14.01],[1,1.01,0.51],[2,8,0]],"batl":[[0,28,6.45],[1,11,0],[2,28,0]],"ltp":4.1,"tv":4.74,"id":13010313},{"batb":[[0,7.8,9.21],[1,1.01,0.51],[2,10,0]],"ltp":5.6,"tv":18.62,"id":16575966},{"batb":[[0,1.08,314.57],[1,1.01,0.51],[2,1.08,0]],"batl":[[0,1.37,67.27],[1,1.28,0],[2,1.37,0]],"ltp":1.4,"tv":155.98,"id":13010314}]}]}
{"op":"mcm","clk":"1008667575","pt":1580638464388,"mc":[{"id":"1.168224424","rc":[{"batb":[[0,6.6,32.81],[1,6.4,37.44],[2,1.01,0.51]],"ltp":4.1,"tv":4.74,"id":13010313},{"batb":[[0,8.6,26.66],[1,8.4,20.09],[2,7.8,9.21]],"ltp":5.6,"tv":18.62,"id":16575966},{"batb":[[0,1.08,935]],"ltp":1.4,"tv":155.98,"id":13010314}]}]}
{"op":"mcm","clk":"1008667668","pt":1580638465422,"mc":[{"id":"1.168224424","rc":[{"batb":[[0,6.6,14.01],[1,1.01,0.51],[2,1.01,0]],"ltp":4.1,"tv":4.74,"id":13010313},{"batb":[[0,7.8,9.21],[1,1.01,0.51],[2,7.8,0]],"ltp":5.6,"tv":18.62,"id":16575966},{"batb":[[0,1.08,314.57]],"ltp":1.4,"tv":155.98,"id":13010314}]}]}
{"op":"mcm","clk":"1008667835","pt":1580638467218,"mc":[{"id":"1.168224424","rc":[{"batb":[[0,10,18.17],[1,9.8,15.01],[2,6.6,14.01]],"ltp":4.1,"tv":4.74,"id":13010313},{"batb":[[0,13,16.37],[1,12.5,21.33],[2,7.8,9.21]],"ltp":5.6,"tv":18.62,"id":16575966},{"batb":[[0,1.19,228.88],[1,1.18,331.92],[2,1.08,314.57]],"ltp":1.4,"tv":155.98,"id":13010314}]}]}
{"op":"mcm","clk":"1008668168","pt":1580638471300,"mc":[{"id":"1.168224424","rc":[{"batb":[[0,6.6,14.01],[1,1.01,0.51],[2,6.6,0]],"ltp":4.1,"tv":4.74,"id":13010313},{"batb":[[0,7.8,9.21],[1,1.01,0.51],[2,7.8,0]],"ltp":5.6,"tv":18.62,"id":16575966},{"batb":[[0,1.08,314.57],[1,1.01,0.51],[2,1.08,0]],"ltp":1.4,"tv":155.98,"id":13010314}]}]}
{"op":"mcm","clk":"1008668425","pt":1580638474044,"mc":[{"id":"1.168224424","rc":[{"batb":[[0,6.6,32.81],[1,6.4,37.44],[2,1.01,0.51]],"ltp":4.1,"tv":4.74,"id":13010313},{"batb":[[0,8.6,26.66],[1,8.4,20.09],[2,7.8,9.21]],"ltp":5.6,"tv":18.62,"id":16575966},{"batb":[[0,1.08,935]],"ltp":1.4,"tv":155.98,"id":13010314}]}]}
{"op":"mcm","clk":"1008669337","pt":1580638484062,"mc":[{"id":"1.168224424","rc":[{"batb":[[0,1.08,314.57]],"ltp":1.4,"tv":155.98,"id":13010314}]}]}
{"op":"mcm","clk":"1008669669","pt":1580638487220,"mc":[{"id":"1.168224424","rc":[{"batb":[[0,1.33,97.22],[1,1.32,163.45],[2,1.08,314.57]],"ltp":1.4,"tv":155.98,"id":13010314}]}]}
{"op":"mcm","clk":"1008669750","pt":1580638488049,"mc":[{"id":"1.168224424","rc":[{"batb":[[2,5.6,20.3]],"batl":[[0,7.8,13.14],[1,11.5,16.13]],"ltp":4.1,"tv":4.74,"id":13010313},{"batl":[[0,9.6,8.81],[1,14,11.02]],"ltp":5.6,"tv":18.62,"id":16575966},{"batb":[[1,1.32,233.32],[2,1.2,115.98]],"batl":[[1,1.45,51.06]],"ltp":1.4,"tv":155.98,"id":13010314}]}]}
{"op":"mcm","clk":"1008669835","pt":1580638489382,"mc":[{"id":"1.168224424","rc":[{"batb":[[2,6.2,7.56]],"batl":[[0,7.4,5.88],[1,7.8,13.14],[2,11.5,16.13]],"ltp":4.1,"tv":4.74,"id":13010313},{"batb":[[2,8,5.88]],"batl":[[1,10,4.2],[2,14,11.02]],"ltp":5.6,"tv":18.62,"id":16575966},{"batb":[[1,1.32,364.39]],"batl":[[1,1.38,42.01],[2,1.45,51.06]],"ltp":1.4,"tv":155.98,"id":13010314}]}]}
{"op":"mcm","clk":"1008670508","pt":1580638496328,"mc":[{"id":"1.168224424","rc":[{"batb":[[0,6.6,14.01],[1,6.2,7.56],[2,5.6,20.3]],"ltp":4.1,"tv":4.74,"id":13010313},{"batb":[[0,8,5.88],[1,7.8,9.21],[2,6.8,12.75]],"ltp":5.6,"tv":18.62,"id":16575966},{"batb":[[0,1.32,200.94],[1,1.2,115.98],[2,1.01,0.51]],"ltp":1.4,"tv":155.98,"id":13010314}]}]}
{"op":"mcm","clk":"1008670553","pt":1580638496844,"mc":[{"id":"1.168224424","rc":[{"batb":[[0,6.2,7.56],[1,5.6,20.3],[2,1.01,0.51]],"batl":[[1,11.5,16.13],[2,11.5,0]],"ltp":4.1,"tv":4.74,"id":13010313},{"batb":[[1,6.8,12.75],[2,1.01,0.51]],"batl":[[0,10,4.2],[1,14,11.02],[2,14,0]],"ltp":5.6,"tv":18.62,"id":16575966},{"batb":[[0,1.32,131.07]],"batl":[[0,1.38,42.01],[1,1.45,51.06],[2,1.45,0]],"ltp":1.4,"tv":155.98,"id":13010314}]}]}
{"op":"mcm","clk":"1008670692","pt":1580638498248,"mc":[{"id":"1.168224424","rc":[{"batb":[[0,5.6,20.3],[1,1.01,0.51],[2,1.01,0]],"batl":[[0,11.5,16.13],[1,11.5,0]],"ltp":4.1,"tv":4.74,"id":13010313},{"batb":[[0,6.8,12.75],[1,1.01,0.51],[2,1.01,0]],"batl":[[0,14,11.02],[1,14,0]],"ltp":5.6,"tv":18.62,"id":16575966},{"batb":[[0,1.2,115.98],[1,1.01,0.51],[2,1.01,0]],"batl":[[0,1.45,51.06],[1,1.45,0]],"ltp":1.4,"tv":155.98,"id":13010314}]}]}
{"op":"mcm","clk":"1008670802","pt":1580638499246,"mc":[{"id":"1.168224424","rc":[{"batb":[[0,5.6,53],[1,5.5,26.36],[2,1.01,0.51]],"ltp":4.1,"tv":4.74,"id":13010313},{"batb":[[0,7.4,25.71],[1,7.2,28.07],[2,6.8,12.75]],"ltp":5.6,"tv":18.62,"id":16575966},{"batb":[[0,1.22,120.59],[1,1.21,273.66],[2,1.2,115.98]],"ltp":1.4,"tv":155.98,"id":13010314}]}]}
{"op":"mcm","clk":"1008671190","pt":1580638503357,"mc":[{"id":"1.168224424","rc":[{"batb":[[0,5.6,20.3],[1,1.01,0.51],[2,1.01,0]],"ltp":4.1,"tv":4.74,"id":13010313},{"batb":[[0,6.8,12.75],[1,1.01,0.51],[2,6.8,0]],"ltp":5.6,"tv":18.62,"id":16575966}]}]}
{"op":"mcm","clk":"1008671465","pt":1580638506351,"mc":[{"id":"1.168224424","rc":[{"batb":[[0,9,16.98],[1,8.8,26.06],[2,6.6,13.61]],"batl":[[1,28,6.22]],"ltp":4.1,"tv":4.74,"id":13010313},{"batb":[[0,11.5,31.77],[1,11,27.21],[2,10.5,12.04]],"ltp":5.6,"tv":18.62,"id":16575966},{"batl":[[0,1.25,110],[1,1.36,69.16],[2,1.45,51.06]],"ltp":1.4,"tv":155.98,"id":13010314}]}]}
{"op":"mcm","clk":"1008671559","pt":1580638507349,"mc":[{"id":"1.168224424","rc":[{"batb":[[2,8,5.88]],"batl":[[0,10,4.2],[1,11.5,16.13],[2,28,6.22]],"ltp":4.1,"tv":4.74,"id":13010313},{"batl":[[0,13,3.36],[1,14,11.02]],"ltp":5.6,"tv":18.62,"id":16575966},{"batb":[[0,1.22,288.63]],"batl":[[1,1.27,42.01],[2,1.36,69.16]],"ltp":1.4,"tv":155.98,"id":13010314}]}]}
{"op":"mcm","clk":"1008672970","pt":1580638523411,"mc":[{"id":"1.168224424","rc":[{"batb":[[0,8,5.88],[1,6.6,13.61],[2,1.01,0.51]],"batl":[[1,28,6.22],[2,28,0]],"ltp":4.1,"tv":4.74,"id":13010313},{"batb":[[0,10,4.2],[1,8,8.81],[2,1.01,0.51]],"batl":[[1,14,0]],"ltp":5.6,"tv":18.62,"id":16575966},{"batb":[[0,1.22,168.04],[1,1.07,322.75],[2,1.01,0.51]],"batl":[[0,1.27,42.01],[1,1.36,69.16],[2,1.36,0]],"ltp":1.4,"tv":155.98,"id":13010314}]}]}
{"op":"mcm","clk":"1008673029","pt":1580638523996,"mc":[{"id":"1.168224424","rc":[{"batb":[[0,6.6,13.61],[1,1.01,0.51],[2,1.01,0]],"batl":[[0,28,6.22],[1,28,0]],"ltp":4.1,"tv":4.74,"id":13010313},{"batb":[[0,8,8.81],[1,1.01,0.51],[2,1.01,0]],"ltp":5.6,"tv":18.62,"id":16575966},{"batb":[[0,1.07,322.75],[1,1.01,0.51],[2,1.01,0]],"batl":[[0,1.36,69.16],[1,1.36,0]],"ltp":1.4,"tv":155.98,"id":13010314}]}]}
{"op":"mcm","clk":"1008673252","pt":1580638526395,"mc":[{"id":"1.168224424","rc":[{"batb":[[0,6.6,40.86],[1,6.4,37.22],[2,1.01,0.51]],"ltp":4.1,"tv":4.74,"id":13010313},{"batb":[[0,8.8,16.94],[1,8.6,19.3],[2,8,8.81]],"ltp":5.6,"tv":18.62,"id":16575966}]}]}
{"op":"mcm","clk":"1008673512","pt":1580638529420,"mc":[{"id":"1.168224424","rc":[{"batb":[[0,1.32,195.24],[1,1.31,171.66],[2,1.07,322.75]],"ltp":1.4,"tv":155.98,"id":13010314}]}]}
{"op":"mcm","clk":"1008673580","pt":1580638530095,"mc":[{"id":"1.168224424","rc":[{"batb":[[2,5.7,19.75]],"batl":[[0,8,12.83],[1,11.5,16.13]],"ltp":4.1,"tv":4.74,"id":13010313},{"batl":[[0,9.8,8.42],[1,14,10.78]],"ltp":5.6,"tv":18.62,"id":16575966},{"batb":[[1,1.31,243.5],[2,1.2,117]],"batl":[[1,1.45,51.93]],"ltp":1.4,"tv":155.98,"id":13010314}]}]}
{"op":"mcm","clk":"1008673680","pt":1580638531295,"mc":[{"id":"1.168224424","rc":[{"batb":[[2,6.2,7.56]],"ltp":4.1,"tv":4.74,"id":13010313},{"batb":[[2,8.2,5.04]],"ltp":5.6,"tv":18.62,"id":16575966},{"batb":[[1,1.31,378.77]],"batl":[[1,1.38,42.01],[2,1.45,51.93]],"ltp":1.4,"tv":155.98,"id":13010314}]}]}
{"op":"mcm","clk":"1008673775","pt":1580638532398,"mc":[{"id":"1.168224424","rc":[{"batl":[[0,7.4,5.88],[1,8,12.83],[2,11.5,16.13]],"ltp":4.1,"tv":4.74,"id":13010313},{"batl":[[1,10.5,4.2],[2,14,10.78]],"ltp":5.6,"tv":18.62,"id":16575966}]}]}
{"op":"mcm","clk":"1008674082","pt":1580638535438,"mc":[{"id":"1.168224424","rc":[{"batb":[[0,1.01,0.51],[1,1.01,0]],"ltp":4.6,"tv":4.23,"id":16575965}]}]}
{"op":"mcm","clk":"1008674451","pt":1580638539305,"mc":[{"id":"1.168224424","rc":[{"batb":[[0,6.6,13.61],[1,6.2,7.56],[2,5.7,19.75]],"ltp":4.1,"tv":4.74,"id":13010313},{"batb":[[0,8.2,5.04],[1,8,8.81],[2,6.8,12.59]],"ltp":5.6,"tv":18.62,"id":16575966},{"batb":[[0,1.31,207.11],[1,1.2,117],[2,1.01,0.51]],"ltp":1.4,"tv":155.98,"id":13010314}]}]}
{"op":"mcm","clk":"1008674502","pt":1580638539938,"mc":[{"id":"1.168224424","rc":[{"batb":[[0,5.7,19.75],[1,1.01,0.51],[2,5.7,0]],"batl":[[0,11.5,16.13],[1,8,0],[2,11.5,0]],"ltp":4.1,"tv":4.74,"id":13010313},{"batb":[[0,6.8,12.59],[1,1.01,0.51],[2,6.8,0]],"batl":[[0,14,10.78],[1,10.5,0],[2,14,0]],"ltp":5.6,"tv":18.62,"id":16575966},{"batb":[[0,1.2,117],[1,1.01,0.51],[2,1.01,0]],"batl":[[0,1.45,51.93],[1,1.38,0],[2,1.45,0]],"ltp":1.4,"tv":155.98,"id":13010314}]}]}
{"op":"mcm","clk":"1008674703","pt":1580638542248,"mc":[{"id":"1.168224424","rc":[{"batb":[[1,5.6,40.84],[2,5.5,26.24]],"ltp":4.1,"tv":4.74,"id":13010313},{"batb":[[0,7.4,36.29],[1,7.2,27.81],[2,6.8,12.59]],"ltp":5.6,"tv":18.62,"id":16575966},{"batb":[[0,1.21,319.36],[1,1.2,353.35],[2,1.01,0.51]],"ltp":1.4,"tv":155.98,"id":13010314}]}]}
{"op":"mcm","clk":"1008675006","pt":1580638545833,"mc":[{"id":"1.168224424","rc":[{"batb":[[1,1.01,0.51],[2,5.5,0]],"ltp":4.1,"tv":4.74,"id":13010313},{"batb":[[0,6.8,12.59],[1,1.01,0.51],[2,6.8,0]],"ltp":5.6,"tv":18.62,"id":16575966}]}]}
{"op":"mcm","clk":"1008675247","pt":1580638548435,"mc":[{"id":"1.168224424","rc":[{"batb":[[0,9,23.88],[1,8.8,18.76],[2,5.7,19.75]],"ltp":4.1,"tv":4.74,"id":13010313},{"batb":[[0,12,13.35],[1,11.5,25.5],[2,6.8,12.59]],"ltp":5.6,"tv":18.62,"id":16575966}]}]}
{"op":"mcm","clk":"1008675308","pt":1580638549219,"mc":[{"id":"1.168224424","rc":[{"batb":[[1,8.8,25.92],[2,8,5.88]],"batl":[[0,10,4.2],[1,11.5,16.13],[2,28,6.22]],"ltp":4.1,"tv":4.74,"id":13010313},{"batb":[[2,10.5,11.72]],"batl":[[0,13.5,3.36],[1,14,10.78]],"ltp":5.6,"tv":18.62,"id":16575966},{"batb":[[0,1.22,168.04],[1,1.21,319.36],[2,1.2,353.35]],"batl":[[0,1.25,110.94],[1,1.27,42.01],[2,1.36,69.95]],"ltp":1.4,"tv":155.98,"id":13010314}]}]}
{"op":"mcm","clk":"1008675461","pt":1580638551411,"mc":[{"id":"1.168224424","rc":[{"batb":[[2,10.5,15.92]],"ltp":5.6,"tv":18.62,"id":16575966}]}]}
{"op":"mcm","clk":"1008676308","pt":1580638562301,"mc":[{"id":"1.168224424","rc":[{"batb":[[0,6.6,13.45],[1,1.01,0.51],[2,8,0]],"batl":[[0,28,6.22],[1,11.5,0],[2,28,0]],"ltp":4.1,"tv":4.74,"id":13010313},{"batb":[[0,8.2,8.66],[1,1.01,0.51],[2,10.5,0]],"ltp":5.6,"tv":18.62,"id":16575966},{"batb":[[0,1.07,324.17],[1,1.01,0.51],[2,1.2,0]],"batl":[[0,1.36,69.95],[1,1.27,0],[2,1.36,0]],"ltp":1.4,"tv":155.98,"id":13010314}]}]}
{"op":"mcm","clk":"1008676513","pt":1580638564911,"mc":[{"id":"1.168224424","rc":[{"batb":[[0,6.6,48.85],[1,6.4,37.01],[2,1.01,0.51]],"ltp":4.1,"tv":4.74,"id":13010313},{"batb":[[0,8.8,26.48],[1,8.6,19.1],[2,8.2,8.66]],"ltp":5.6,"tv":18.62,"id":16575966},{"batb":[[0,1.08,620.43],[1,1.07,324.17],[2,1.01,0.51]],"ltp":1.4,"tv":155.98,"id":13010314}]}]}
{"op":"mcm","clk":"1008676672","pt":1580638566692,"mc":[{"id":"1.168224424","rc":[{"batb":[[0,6.6,13.45],[1,1.01,0.51],[2,1.01,0]],"ltp":4.1,"tv":4.74,"id":13010313},{"batb":[[0,8.2,8.66],[1,1.01,0.51],[2,8.2,0]],"ltp":5.6,"tv":18.62,"id":16575966}]}]}
{"op":"mcm","clk":"1008677025","pt":1580638570380,"mc":[{"id":"1.168224424","rc":[{"batb":[[0,20,16.23],[1,19.5,8.74],[2,18,6.85]],"ltp":4.1,"tv":4.74,"id":13010313},{"batb":[[0,26,6.65],[1,25,10.26],[2,20,5.27]],"ltp":5.6,"tv":18.62,"id":16575966},{"batb":[[2,1.06,407.81]],"batl":[[0,1.11,139.98],[1,1.16,151.86],[2,1.36,69.95]],"ltp":1.4,"tv":155.98,"id":13010314}]}]}
{"op":"mcm","clk":"1008677109","pt":1580638571381,"mc":[{"id":"1.168224424","rc":[{"batb":[[0,5,15.96],[1,1.01,0.51]],"ltp":4.6,"tv":4.23,"id":16575965},{"batl":[[2,1.36,0]],"ltp":1.4,"tv":155.98,"id":13010314}]}]}
{"op":"mcm","clk":"1008677601","pt":1580638578000,"mc":[{"id":"1.168224424","rc":[{"batb":[[0,26,9.54]],"ltp":5.6,"tv":18.62,"id":16575966}]}]}
{"op":"mcm","clk":"1008679248","pt":1580638598855,"mc":[{"id":"1.168224424","rc":[{"batb":[[0,13.5,6.45],[1,1.01,0.51],[2,18,0]],"ltp":4.1,"tv":4.74,"id":13010313},{"batb":[[0,15,5.11],[1,1.01,0.51],[2,20,0]],"ltp":5.6,"tv":18.62,"id":16575966},{"batb":[[0,1.06,407.81],[1,1.01,0.51],[2,1.06,0]],"batl":[[0,1.16,151.86],[1,1.16,0]],"ltp":1.4,"tv":155.98,"id":13010314}]}]}
{"op":"mcm","clk":"1008679349","pt":1580638600059,"mc":[{"id":"1.168224424","rc":[{"batb":[[0,1.01,0.51],[1,1.01,0]],"ltp":4.6,"tv":4.23,"id":16575965}]}]}
{"op":"mcm","clk":"1008679467","pt":1580638601429,"mc":[{"id":"1.168224424","rc":[{"batb":[[0,15,11.9],[1,14.5,16.37],[2,13.5,6.45]],"ltp":4.1,"tv":4.74,"id":13010313},{"batb":[[0,19,14.51],[1,18.5,9.64],[2,15,5.11]],"ltp":5.6,"tv":18.62,"id":16575966},{"batb":[[0,1.07,293.1],[1,1.06,745.44],[2,1.01,0.51]],"ltp":1.4,"tv":155.98,"id":13010314}]}]}
{"op":"mcm","clk":"1008679485","pt":1580638601634,"mc":[{"id":"1.168224424","rc":[{"batb":[[0,13.5,6.45],[1,1.01,0.51],[2,13.5,0]],"ltp":4.1,"tv":4.74,"id":13010313},{"batb":[[0,15,5.11],[1,1.01,0.51],[2,15,0]],"ltp":5.6,"tv":18.62,"id":16575966}]}]}
{"op":"mcm","clk":"1008679806","pt":1580638605270,"mc":[{"id":"1.168224424","rc":[{"batb":[[0,24,8.51],[1,23,12.34],[2,21,4.26]],"ltp":4.1,"tv":4.74,"id":13010313},{"batb":[[0,30,13.15],[1,29,7.39],[2,23,3.15]],"ltp":5.6,"tv":18.62,"id":16575966},{"batb":[[1,1.06,704.14],[2,1.04,495.22]],"batl":[[0,1.1,151.62],[1,1.13,151.86]],"ltp":1.4,"tv":155.98,"id":13010314}]}]}
{"op":"mcm","clk":"1008680084","pt":1580638608284,"mc":[{"id":"1.168224424","rc":[{"batb":[[0,1.07,334.01]],"batl":[[0,1.1,193.63]],"ltp":1.4,"tv":155.98,"id":13010314}]}]}
{"op":"mcm","clk":"1008680623","pt":1580638615284,"mc":[{"id":"1.168224424","rc":[{"batb":[[0,16.5,4.25],[1,1.01,0.51],[2,21,0]],"ltp":4.1,"tv":4.74,"id":13010313},{"batb":[[0,18,6.61],[1,1.01,0.51],[2,23,0]],"ltp":5.6,"tv":18.62,"id":16575966},{"batb":[[0,1.04,495.22],[1,1.01,0.51],[2,1.04,0]],"batl":[[0,1.1,42.01]],"ltp":1.4,"tv":155.98,"id":13010314}]}]}
{"op":"mcm","clk":"1008680679","pt":1580638615974,"mc":[{"id":"1.168224424","rc":[{"batl":[[0,1.13,151.86],[1,1.13,0]],"ltp":1.4,"tv":155.98,"id":13010314}]}]}
{"op":"mcm","clk":"1008680874","pt":1580638618278,"mc":[{"id":"1.168224424","rc":[{"batb":[[0,18.5,9.79],[1,18,10.44],[2,16.5,4.25]],"ltp":4.1,"tv":4.74,"id":13010313},{"batb":[[0,23,16.2],[1,22,12.96],[2,18,6.61]],"ltp":5.6,"tv":18.62,"id":16575966},{"batb":[[0,1.06,361.76],[1,1.05,274.33],[2,1.04,495.22]],"ltp":1.4,"tv":155.98,"id":13010314}]}]}
{"op":"mcm","clk":"1008680940","pt":1580638619060,"mc":[{"id":"1.168224424","rc":[{"batb":[[0,16.5,4.25],[1,1.01,0.51],[2,16.5,0]],"ltp":4.1,"tv":4.74,"id":13010313},{"batb":[[0,18,6.61],[1,1.01,0.51],[2,18,0]],"ltp":5.6,"tv":18.62,"id":16575966}]}]}
{"op":"mcm","clk":"1008681263","pt":1580638622274,"mc":[{"id":"1.168224424","rc":[{"batb":[[0,27,12.75],[1,26,9.43],[2,23,5.89]],"ltp":4.1,"tv":4.74,"id":13010313},{"batb":[[0,36,3.66],[1,34,10.83],[2,26,3.69]],"ltp":5.6,"tv":18.62,"id":16575966},{"batl":[[0,1.1,138.64]],"ltp":1.4,"tv":155.98,"id":13010314}]}]}
{"op":"mcm","clk":"1008681346","pt":1580638623261,"mc":[{"id":"1.168224424","rc":[{"batl":[[0,1.09,42.01],[1,1.1,138.64]],"ltp":1.4,"tv":155.98,"id":13010314}]}]}
{"op":"mcm","clk":"1008682257","pt":1580638634409,"mc":[{"id":"1.168224424","rc":[{"batb":[[0,19.5,5.35],[1,1.01,0.51],[2,23,0]],"ltp":4.1,"tv":4.74,"id":13010313},{"batb":[[0,21,4.11],[1,1.01,0.51],[2,26,0]],"ltp":5.6,"tv":18.62,"id":16575966},{"batb":[[0,1.05,274.33],[1,1.04,495.22],[2,1.01,0.51]],"batl":[[0,1.1,138.64],[1,1.1,0]],"ltp":1.4,"tv":155.98,"id":13010314}]}]}
