{"op":"mcm","clk":"1004963113","pt":1580585272153,"mc":[{"id":"1.168224426","marketDefinition":{"bspMarket":false,"turnInPlayEnabled":true,"persistenceEnabled":true,"marketBaseRate":5.0,"eventId":"29681737","eventTypeId":"2","numberOfWinners":1,"bettingType":"ODDS","marketType":"SET_WINNER","marketTime":"2020-02-02T09:30:00.000Z","suspendTime":"2020-02-02T09:30:00.000Z","bspReconciled":false,"complete":true,"inPlay":false,"crossMatching":false,"runnersVoidable":false,"numberOfActiveRunners":2,"betDelay":0,"status":"OPEN","runners":[{"status":"ACTIVE","sortPriority":1,"id":8260126,"name":"Guillermo Garcia-Lopez"},{"status":"ACTIVE","sortPriority":2,"id":4486603,"name":"Dustin Brown"}],"regulators":["MR_INT"],"countryCode":"FR","discountAllowed":false,"timezone":"UTC","openDate":"2020-02-02T09:30:00.000Z","version":3147098407,"name":"Set 2 Winner","eventName":"Garcia-Lopez v Brown"},"rc":[{"batb":[[0,1.01,20]],"ltp":0.0,"tv":0.0,"id":8260126},{"batb":[[0,1.01,20]],"ltp":0.0,"tv":0.0,"id":4486603}]}]}
{"op":"mcm","clk":"1004963376","pt":1580585273491,"mc":[{"id":"1.168224426","marketDefinition":{"bspMarket":false,"turnInPlayEnabled":true,"persistenceEnabled":true,"marketBaseRate":5.0,"eventId":"29681737","eventTypeId":"2","numberOfWinners":1,"bettingType":"ODDS","marketType":"SET_WINNER","marketTime":"2020-02-02T09:30:00.000Z","suspendTime":"2020-02-02T09:30:00.000Z","bspReconciled":false,"complete":true,"inPlay":false,"crossMatching":false,"runnersVoidable":false,"numberOfActiveRunners":2,"betDelay":0,"status":"OPEN","runners":[{"status":"ACTIVE","sortPriority":1,"id":8260126,"name":"Guillermo Garcia-Lopez"},{"status":"ACTIVE","sortPriority":2,"id":4486603,"name":"Dustin Brown"}],"regulators":["MR_INT"],"countryCode":"FR","discountAllowed":false,"timezone":"UTC","openDate":"2020-02-02T09:30:00.000Z","version":3147098407,"name":"Set 2 Winner","eventName":"Garcia-Lopez v Brown"}}]}
{"op":"mcm","clk":"1004963561","pt":1580585274501,"mc":[{"id":"1.168224426","marketDefinition":{"bspMarket":false,"turnInPlayEnabled":true,"persistenceEnabled":true,"marketBaseRate":5.0,"eventId":"29681737","eventTypeId":"2","numberOfWinners":1,"bettingType":"ODDS","marketType":"SET_WINNER","marketTime":"2020-02-02T09:30:00.000Z","suspendTime":"2020-02-02T09:30:00.000Z","bspReconciled":false,"complete":true,"inPlay":false,"crossMatching":false,"runnersVoidable":false,"numberOfActiveRunners":2,"betDelay":0,"status":"OPEN","runners":[{"status":"ACTIVE","sortPriority":1,"id":8260126,"name":"Guillermo Garcia-Lopez"},{"status":"ACTIVE","sortPriority":2,"id":4486603,"name":"Dustin Brown"}],"regulators":["MR_INT"],"countryCode":"FR","discountAllowed":true,"timezone":"UTC","openDate":"2020-02-02T09:30:00.000Z","version":3147098407,"name":"Set 2 Winner","eventName":"Garcia-Lopez v Brown"}}]}
{"op":"mcm","clk":"1004986256","pt":1580585417713,"mc":[{"id":"1.168224426","rc":[{"batb":[[0,1.01,15]],"ltp":0.0,"tv":0.0,"id":8260126},{"batb":[[0,1.01,15]],"ltp":0.0,"tv":0.0,"id":4486603}]}]}
{"op":"mcm","clk":"1006924384","pt":1580602183340,"mc":[{"id":"1.168224426","rc":[{"batb":[[0,1.01,15.51]],"ltp":0.0,"tv":0.0,"id":8260126},{"batb":[[0,1.01,15.51]],"ltp":0.0,"tv":0.0,"id":4486603}]}]}
{"op":"mcm","clk":"1007043167","pt":1580603722151,"mc":[{"id":"1.168224426","rc":[{"batb":[[0,1.01,18.04]],"ltp":0.0,"tv":0.0,"id":8260126},{"batb":[[0,1.01,18.04]],"ltp":0.0,"tv":0.0,"id":4486603}]}]}
{"op":"mcm","clk":"1007043238","pt":1580603723387,"mc":[{"id":"1.168224426","rc":[{"batb":[[0,1.01,16.01]],"ltp":0.0,"tv":0.0,"id":8260126},{"batb":[[0,1.01,16.01]],"ltp":0.0,"tv":0.0,"id":4486603}]}]}
{"op":"mcm","clk":"1007201743","pt":1580607068314,"mc":[{"id":"1.168224426","rc":[{"batb":[[0,1.01,18.01]],"ltp":0.0,"tv":0.0,"id":8260126},{"batb":[[0,1.01,18.01]],"ltp":0.0,"tv":0.0,"id":4486603}]}]}
{"op":"mcm","clk":"1007201782","pt":1580607069036,"mc":[{"id":"1.168224426","rc":[{"batb":[[0,1.01,16.02]],"ltp":0.0,"tv":0.0,"id":8260126},{"batb":[[0,1.01,16.02]],"ltp":0.0,"tv":0.0,"id":4486603}]}]}
{"op":"mcm","clk":"1008457009","pt":1580635581363,"mc":[{"id":"1.168224426","rc":[{"batb":[[0,1.58,30.84],[1,1.01,16.02]],"ltp":0.0,"tv":0.0,"id":8260126},{"batb":[[0,2.5,14.87],[1,1.01,16.02]],"ltp":0.0,"tv":0.0,"id":4486603}]}]}
{"op":"mcm","clk":"1008457832","pt":1580635594297,"mc":[{"id":"1.168224426","marketDefinition":{"bspMarket":false,"turnInPlayEnabled":true,"persistenceEnabled":true,"marketBaseRate":5.0,"eventId":"29681737","eventTypeId":"2","numberOfWinners":1,"bettingType":"ODDS","marketType":"SET_WINNER","marketTime":"2020-02-02T09:30:00.000Z","suspendTime":"2020-02-02T09:30:00.000Z","bspReconciled":false,"complete":true,"inPlay":false,"crossMatching":true,"runnersVoidable":false,"numberOfActiveRunners":2,"betDelay":0,"status":"OPEN","runners":[{"status":"ACTIVE","sortPriority":1,"id":8260126,"name":"Guillermo Garcia-Lopez"},{"status":"ACTIVE","sortPriority":2,"id":4486603,"name":"Dustin Brown"}],"regulators":["MR_INT"],"countryCode":"FR","discountAllowed":true,"timezone":"UTC","openDate":"2020-02-02T09:30:00.000Z","version":3147125269,"name":"Set 2 Winner","eventName":"Garcia-Lopez v Brown"}}]}
{"op":"mcm","clk":"1008459675","pt":1580635615447,"mc":[{"id":"1.168224426","marketDefinition":{"bspMarket":false,"turnInPlayEnabled":true,"persistenceEnabled":true,"marketBaseRate":5.0,"eventId":"29681737","eventTypeId":"2","numberOfWinners":1,"bettingType":"ODDS","marketType":"SET_WINNER","marketTime":"2020-02-02T09:24:00.000Z","suspendTime":"2020-02-02T09:24:00.000Z","bspReconciled":false,"complete":true,"inPlay":false,"crossMatching":true,"runnersVoidable":false,"numberOfActiveRunners":2,"betDelay":0,"status":"OPEN","runners":[{"status":"ACTIVE","sortPriority":1,"id":8260126,"name":"Guillermo Garcia-Lopez"},{"status":"ACTIVE","sortPriority":2,"id":4486603,"name":"Dustin Brown"}],"regulators":["MR_INT"],"countryCode":"FR","discountAllowed":true,"timezone":"UTC","openDate":"2020-02-02T09:30:00.000Z","version":3148345639,"name":"Set 2 Winner","eventName":"Garcia-Lopez v Brown"}}]}
{"op":"mcm","clk":"1008459927","pt":1580635617379,"mc":[{"id":"1.168224426","marketDefinition":{"bspMarket":false,"turnInPlayEnabled":true,"persistenceEnabled":true,"marketBaseRate":5.0,"eventId":"29681737","eventTypeId":"2","numberOfWinners":1,"bettingType":"ODDS","marketType":"SET_WINNER","marketTime":"2020-02-02T09:24:00.000Z","suspendTime":"2020-02-02T09:24:00.000Z","bspReconciled":false,"complete":true,"inPlay":false,"crossMatching":true,"runnersVoidable":false,"numberOfActiveRunners":2,"betDelay":0,"status":"OPEN","runners":[{"status":"ACTIVE","sortPriority":1,"id":8260126,"name":"Guillermo Garcia-Lopez"},{"status":"ACTIVE","sortPriority":2,"id":4486603,"name":"Dustin Brown"}],"regulators":["MR_INT"],"countryCode":"FR","discountAllowed":true,"timezone":"UTC","openDate":"2020-02-02T09:24:00.000Z","version":3148345639,"name":"Set 2 Winner","eventName":"Garcia-Lopez v Brown"}}]}
{"op":"mcm","clk":"1008498146","pt":1580636191054,"mc":[{"id":"1.168224426","rc":[{"batb":[[1,1.57,73.1],[2,1.01,16.02]],"batl":[[0,1.71,42.01]],"ltp":0.0,"tv":0.0,"id":8260126},{"batb":[[1,2.44,28.57],[2,1.01,16.02]],"batl":[[0,2.78,23.53]],"ltp":0.0,"tv":0.0,"id":4486603}]}]}
{"op":"mcm","clk":"1008513889","pt":1580636417273,"mc":[{"id":"1.168224426","marketDefinition":{"bspMarket":false,"turnInPlayEnabled":true,"persistenceEnabled":true,"marketBaseRate":5.0,"eventId":"29681737","eventTypeId":"2","numberOfWinners":1,"bettingType":"ODDS","marketType":"SET_WINNER","marketTime":"2020-02-02T09:24:00.000Z","suspendTime":"2020-02-02T09:24:00.000Z","bspReconciled":false,"complete":true,"inPlay":true,"crossMatching":true,"runnersVoidable":false,"numberOfActiveRunners":2,"betDelay":3,"status":"OPEN","runners":[{"status":"ACTIVE","sortPriority":1,"id":8260126,"name":"Guillermo Garcia-Lopez"},{"status":"ACTIVE","sortPriority":2,"id":4486603,"name":"Dustin Brown"}],"regulators":["MR_INT"],"countryCode":"FR","discountAllowed":true,"timezone":"UTC","openDate":"2020-02-02T09:24:00.000Z","version":3148353315,"name":"Set 2 Winner","eventName":"Garcia-Lopez v Brown"},"rc":[{"batb":[[0,1.01,15.52],[1,1.57,0],[2,1.01,0]],"ltp":0.0,"tv":0.0,"id":8260126},{"batb":[[0,1.01,15.52],[1,2.44,0],[2,1.01,0]],"ltp":0.0,"tv":0.0,"id":4486603}]}]}
{"op":"mcm","clk":"1008517139","pt":1580636472141,"mc":[{"id":"1.168224426","rc":[{"batb":[[0,1.6,29.11],[1,1.58,31.16],[2,1.01,15.52]],"batl":[[0,1.72,42.01]],"ltp":0.0,"tv":0.0,"id":8260126},{"batb":[[0,2.44,15.89],[1,2.38,47.24],[2,1.01,15.52]],"batl":[[0,2.74,23.53]],"ltp":0.0,"tv":0.0,"id":4486603}]}]}
{"op":"mcm","clk":"1008517327","pt":1580636475187,"mc":[{"id":"1.168224426","rc":[{"batb":[[1,1.58,103.41]],"ltp":0.0,"tv":0.0,"id":8260126}]}]}
{"op":"mcm","clk":"1008517706","pt":1580636479887,"mc":[{"id":"1.168224426","rc":[{"batb":[[0,1.58,103.41],[1,1.01,15.52],[2,1.01,0]],"ltp":0.0,"tv":0.0,"id":8260126},{"batb":[[0,2.38,47.24],[1,1.01,15.52],[2,1.01,0]],"ltp":0.0,"tv":0.0,"id":4486603}]}]}
{"op":"mcm","clk":"1008517753","pt":1580636480556,"mc":[{"id":"1.168224426","rc":[{"batb":[[0,1.58,31.16]],"ltp":0.0,"tv":0.0,"id":8260126},{"batb":[[0,2.38,17]],"ltp":0.0,"tv":0.0,"id":4486603}]}]}
{"op":"mcm","clk":"1008519363","pt":1580636503421,"mc":[{"id":"1.168224426","rc":[{"batb":[[0,1.63,27.46],[1,1.6,29.58],[2,1.01,15.52]],"ltp":0.0,"tv":0.0,"id":8260126},{"batb":[[1,2.36,17.55],[2,1.01,15.52]],"ltp":0.0,"tv":0.0,"id":4486603}]}]}
{"op":"mcm","clk":"1008519372","pt":1580636503532,"mc":[{"id":"1.168224426","rc":[{"batb":[[2,1.59,70.58]],"batl":[[0,1.74,42.01]],"ltp":0.0,"tv":0.0,"id":8260126},{"batb":[[2,2.34,31.09]],"batl":[[0,2.68,24.37]],"ltp":0.0,"tv":0.0,"id":4486603}]}]}
{"op":"mcm","clk":"1008520490","pt":1580636518534,"mc":[{"id":"1.168224426","rc":[{"batb":[[0,1.6,29.58],[1,1.01,15.52],[2,1.59,0]],"ltp":0.0,"tv":0.0,"id":8260126},{"batb":[[0,2.36,17.55],[1,1.01,15.52],[2,2.34,0]],"ltp":0.0,"tv":0.0,"id":4486603}]}]}
{"op":"mcm","clk":"1008522188","pt":1580636537786,"mc":[{"id":"1.168224426","rc":[{"batb":[[1,1.58,72.26],[2,1.56,32.02]],"batl":[[0,1.71,42.01]],"ltp":0.0,"tv":0.0,"id":8260126},{"batb":[[0,2.46,15.66],[1,2.42,16.29],[2,2.4,29.41]],"batl":[[0,2.76,23.53]],"ltp":0.0,"tv":0.0,"id":4486603}]}]}
{"op":"mcm","clk":"1008523143","pt":1580636550452,"mc":[{"id":"1.168224426","rc":[{"batb":[[0,1.58,72.26],[1,1.56,32.02],[2,1.01,15.52]],"ltp":0.0,"tv":0.0,"id":8260126},{"batb":[[0,2.42,16.29],[1,2.4,29.41],[2,1.01,15.52]],"ltp":0.0,"tv":0.0,"id":4486603}]}]}
{"op":"mcm","clk":"1008523155","pt":1580636550660,"mc":[{"id":"1.168224426","rc":[{"batb":[[0,1.56,32.02],[1,1.01,15.52],[2,1.01,0]],"ltp":0.0,"tv":0.0,"id":8260126},{"batb":[[1,1.01,15.52],[2,1.01,0]],"ltp":0.0,"tv":0.0,"id":4486603}]}]}
{"op":"mcm","clk":"1008524417","pt":1580636569312,"mc":[{"id":"1.168224426","rc":[{"batb":[[0,1.61,28.56],[1,1.58,30.53],[2,1.56,32.02]],"ltp":0.0,"tv":0.0,"id":8260126},{"batb":[[1,2.38,17],[2,1.01,15.52]],"ltp":0.0,"tv":0.0,"id":4486603}]}]}
{"op":"mcm","clk":"1008524478","pt":1580636570188,"mc":[{"id":"1.168224426","rc":[{"batb":[[1,1.59,70.58],[2,1.58,30.53]],"batl":[[0,1.73,42.01]],"ltp":0.0,"tv":0.0,"id":8260126},{"batb":[[1,2.38,47.24]],"batl":[[0,2.72,24.37]],"ltp":0.0,"tv":0.0,"id":4486603}]}]}
{"op":"mcm","clk":"1008525421","pt":1580636584008,"mc":[{"id":"1.168224426","rc":[{"batb":[[0,1.59,70.58],[1,1.58,30.53],[2,1.01,15.52]],"ltp":0.0,"tv":0.0,"id":8260126},{"batb":[[0,2.38,47.24],[1,1.01,15.52],[2,1.01,0]],"ltp":0.0,"tv":0.0,"id":4486603}]}]}
{"op":"mcm","clk":"1008525458","pt":1580636584626,"mc":[{"id":"1.168224426","rc":[{"batb":[[0,1.58,30.53],[1,1.01,15.52],[2,1.01,0]],"ltp":0.0,"tv":0.0,"id":8260126},{"batb":[[0,2.38,17]],"ltp":0.0,"tv":0.0,"id":4486603}]}]}
{"op":"mcm","clk":"1008526553","pt":1580636600045,"mc":[{"id":"1.168224426","rc":[{"batb":[[0,1.63,27.46],[1,1.62,67.22],[2,1.61,28.48]],"batl":[[0,1.77,42.01]],"ltp":0.0,"tv":0.0,"id":8260126},{"batb":[[1,2.32,31.09],[2,2.3,18.88]],"batl":[[0,2.64,25.21]],"ltp":0.0,"tv":0.0,"id":4486603}]}]}
{"op":"mcm","clk":"1008527032","pt":1580636607876,"mc":[{"id":"1.168224426","rc":[{"batb":[[0,1.64,27.15],[1,1.62,95.38],[2,1.01,15.52]],"ltp":0.0,"tv":0.0,"id":8260126},{"batb":[[0,2.36,17.23],[2,2.28,19.2]],"ltp":0.0,"tv":0.0,"id":4486603}]}]}
{"op":"mcm","clk":"1008529519","pt":1580636645316,"mc":[{"id":"1.168224426","rc":[{"batl":[[1,2.3,309.75]],"ltp":0.0,"tv":0.0,"id":8260126},{"batl":[[1,3,213.45]],"ltp":0.0,"tv":0.0,"id":4486603}]}]}
{"op":"mcm","clk":"1008529779","pt":1580636649431,"mc":[{"id":"1.168224426","rc":[{"batb":[[0,1.62,95.38],[1,1.01,15.52],[2,1.01,0]],"ltp":0.0,"tv":0.0,"id":8260126},{"batb":[[0,2.32,31.09],[1,2.28,19.2],[2,1.01,15.52]],"ltp":0.0,"tv":0.0,"id":4486603}]}]}
{"op":"mcm","clk":"1008529863","pt":1580636650716,"mc":[{"id":"1.168224426","rc":[{"batb":[[0,1.62,28.17]],"batl":[[0,2.3,309.75],[1,2.3,0]],"ltp":0.0,"tv":0.0,"id":8260126},{"batb":[[0,2.28,19.2],[1,1.01,15.52],[2,1.01,0]],"batl":[[0,3,213.45],[1,3,0]],"ltp":0.0,"tv":0.0,"id":4486603}]}]}
{"op":"mcm","clk":"1008530888","pt":1580636664455,"mc":[{"id":"1.168224426","rc":[{"batb":[[0,1.68,24.71],[1,1.65,89.98],[2,1.01,15.52]],"batl":[[0,1.8,42.01],[1,2.3,309.75]],"ltp":0.0,"tv":0.0,"id":8260126},{"batb":[[1,2.26,32.77],[2,2.18,21.56]],"batl":[[0,2.56,26.89]],"ltp":0.0,"tv":0.0,"id":4486603}]}]}
{"op":"mcm","clk":"1008530940","pt":1580636665328,"mc":[{"id":"1.168224426","rc":[{"batl":[[1,2.84,228.62]],"ltp":0.0,"tv":0.0,"id":4486603}]}]}
{"op":"mcm","clk":"1008532365","pt":1580636684235,"mc":[{"id":"1.168224426","rc":[{"batb":[[0,1.65,89.98],[1,1.01,15.52],[2,1.01,0]],"ltp":0.0,"tv":0.0,"id":8260126},{"batb":[[0,2.26,32.77],[1,2.18,21.56],[2,1.01,15.52]],"ltp":0.0,"tv":0.0,"id":4486603}]}]}
{"op":"mcm","clk":"1008532404","pt":1580636684751,"mc":[{"id":"1.168224426","rc":[{"batb":[[0,1.65,26.12]],"batl":[[0,2.3,309.75],[1,2.3,0]],"ltp":0.0,"tv":0.0,"id":8260126},{"batb":[[0,2.18,21.56],[1,1.01,15.52],[2,1.01,0]],"batl":[[0,2.84,228.62],[1,2.84,0]],"ltp":0.0,"tv":0.0,"id":4486603}]}]}
{"op":"mcm","clk":"1008532773","pt":1580636690363,"mc":[{"id":"1.168224426","rc":[{"batb":[[1,1.63,93.76],[2,1.01,15.52]],"batl":[[0,1.78,42.01],[1,2.3,309.75]],"ltp":0.0,"tv":0.0,"id":8260126},{"batb":[[0,2.34,18.02],[1,2.3,31.93],[2,2.24,20.14]],"batl":[[0,2.6,26.05],[1,2.84,228.62]],"ltp":0.0,"tv":0.0,"id":4486603}]}]}
{"op":"mcm","clk":"1008533599","pt":1580636701505,"mc":[{"id":"1.168224426","rc":[{"batb":[[0,1.63,93.76],[1,1.01,15.52],[2,1.01,0]],"ltp":0.0,"tv":0.0,"id":8260126},{"batb":[[0,2.3,31.93],[1,2.24,20.14],[2,1.01,15.52]],"ltp":0.0,"tv":0.0,"id":4486603}]}]}
{"op":"mcm","clk":"1008533710","pt":1580636702703,"mc":[{"id":"1.168224426","rc":[{"batb":[[0,1.63,27.38]],"batl":[[0,2.3,309.75],[1,2.3,0]],"ltp":0.0,"tv":0.0,"id":8260126},{"batb":[[0,2.24,20.14],[1,1.01,15.52],[2,1.01,0]],"batl":[[0,2.84,228.62],[1,2.84,0]],"ltp":0.0,"tv":0.0,"id":4486603}]}]}
{"op":"mcm","clk":"1008535383","pt":1580636723829,"mc":[{"id":"1.168224426","rc":[{"batb":[[0,1.7,23.6],[1,1.67,25.34],[2,1.66,63.01]],"batl":[[0,1.82,42.01],[1,2.3,309.75]],"ltp":0.0,"tv":0.0,"id":8260126},{"batb":[[1,2.22,33.61],[2,2.14,22.9]],"batl":[[0,2.54,26.89],[1,2.84,228.62]],"ltp":0.0,"tv":0.0,"id":4486603}]}]}
{"op":"mcm","clk":"1008538061","pt":1580636758437,"mc":[{"id":"1.168224426","rc":[{"batb":[[0,1.67,25.34],[1,1.66,63.01],[2,1.01,15.52]],"ltp":0.0,"tv":0.0,"id":8260126},{"batb":[[0,2.22,33.61],[1,2.14,22.9],[2,1.01,15.52]],"ltp":0.0,"tv":0.0,"id":4486603}]}]}
{"op":"mcm","clk":"1008538081","pt":1580636758643,"mc":[{"id":"1.168224426","rc":[{"batb":[[1,1.01,15.52],[2,1.01,0]],"batl":[[0,2.3,309.75],[1,2.3,0]],"ltp":0.0,"tv":0.0,"id":8260126},{"batb":[[0,2.14,22.9],[1,1.01,15.52],[2,1.01,0]],"batl":[[0,2.84,228.62],[1,2.84,0]],"ltp":0.0,"tv":0.0,"id":4486603}]}]}
{"op":"mcm","clk":"1008538683","pt":1580636765149,"mc":[{"id":"1.168224426","rc":[{"batb":[[1,1.65,26.44],[2,1.01,15.52]],"ltp":0.0,"tv":0.0,"id":8260126},{"batb":[[0,2.3,18.65],[1,2.2,21.24],[2,1.01,15.52]],"ltp":0.0,"tv":0.0,"id":4486603}]}]}
{"op":"mcm","clk":"1008538797","pt":1580636766388,"mc":[{"id":"1.168224426","rc":[{"batb":[[1,1.65,90.29]],"batl":[[0,1.8,42.01],[1,2.3,309.75]],"ltp":0.0,"tv":0.0,"id":8260126},{"batb":[[1,2.26,32.77],[2,2.2,21.24]],"batl":[[0,2.56,26.89],[1,2.84,228.62]],"ltp":0.0,"tv":0.0,"id":4486603}]}]}
{"op":"mcm","clk":"1008539825","pt":1580636779587,"mc":[{"id":"1.168224426","rc":[{"batb":[[0,1.65,90.29],[1,1.01,15.52],[2,1.01,0]],"ltp":0.0,"tv":0.0,"id":8260126},{"batb":[[0,2.26,32.77],[1,2.2,21.24],[2,1.01,15.52]],"ltp":0.0,"tv":0.0,"id":4486603}]}]}
{"op":"mcm","clk":"1008539936","pt":1580636781130,"mc":[{"id":"1.168224426","rc":[{"batb":[[0,1.65,26.44]],"batl":[[0,2.3,309.75],[1,2.3,0]],"ltp":0.0,"tv":0.0,"id":8260126},{"batb":[[0,2.2,21.24],[1,1.01,15.52],[2,1.01,0]],"batl":[[0,2.84,228.62],[1,2.84,0]],"ltp":0.0,"tv":0.0,"id":4486603}]}]}
{"op":"mcm","clk":"1008540705","pt":1580636791448,"mc":[{"id":"1.168224426","rc":[{"batb":[[0,1.73,22.42],[1,1.69,24.39],[2,1.65,430.97]],"ltp":0.0,"tv":0.0,"id":8260126},{"batb":[[1,2.06,25.65],[2,1.01,15.52]],"ltp":0.0,"tv":0.0,"id":4486603}]}]}
{"op":"mcm","clk":"1008540745","pt":1580636791923,"mc":[{"id":"1.168224426","rc":[{"batb":[[2,1.67,62.17]],"batl":[[0,1.83,42.01],[1,2.3,309.75]],"ltp":0.0,"tv":0.0,"id":8260126},{"batb":[[0,2.2,55.69]],"batl":[[0,2.5,27.73]],"ltp":0.0,"tv":0.0,"id":4486603}]}]}
{"op":"mcm","clk":"1008540899","pt":1580636793830,"mc":[{"id":"1.168224426","rc":[{"batl":[[1,2.7,245.56]],"ltp":0.0,"tv":0.0,"id":4486603}]}]}
{"op":"mcm","clk":"1008542157","pt":1580636810148,"mc":[{"id":"1.168224426","rc":[{"batb":[[0,1.69,24.39],[1,1.67,62.17],[2,1.01,15.52]],"ltp":0.0,"tv":0.0,"id":8260126},{"batb":[[0,2.2,34.45]],"ltp":0.0,"tv":0.0,"id":4486603}]}]}
{"op":"mcm","clk":"1008542250","pt":1580636811126,"mc":[{"id":"1.168224426","rc":[{"batb":[[1,1.01,15.52],[2,1.01,0]],"batl":[[0,2.3,309.75],[1,2.3,0]],"ltp":0.0,"tv":0.0,"id":8260126},{"batb":[[0,2.06,25.65],[1,1.01,15.52],[2,1.01,0]],"batl":[[0,2.7,245.56],[1,2.7,0]],"ltp":0.0,"tv":0.0,"id":4486603}]}]}
{"op":"mcm","clk":"1008542811","pt":1580636818666,"mc":[{"id":"1.168224426","rc":[{"batb":[[1,1.65,26.28],[2,1.01,15.52]],"ltp":0.0,"tv":0.0,"id":8260126},{"batb":[[0,2.26,19.43],[1,2.18,21.95],[2,1.01,15.52]],"ltp":0.0,"tv":0.0,"id":4486603}]}]}
{"op":"mcm","clk":"1008542946","pt":1580636820370,"mc":[{"id":"1.168224426","rc":[{"batb":[[1,1.66,63.01],[2,1.65,26.28]],"batl":[[0,1.81,42.01],[1,2.3,309.75]],"ltp":0.0,"tv":0.0,"id":8260126},{"batb":[[1,2.24,33.61],[2,2.18,21.95]],"batl":[[0,2.54,26.89],[1,2.7,245.56]],"ltp":0.0,"tv":0.0,"id":4486603}]}]}
{"op":"mcm","clk":"1008543978","pt":1580636834114,"mc":[{"id":"1.168224426","rc":[{"batb":[[0,1.66,63.01],[1,1.65,26.28],[2,1.01,15.52]],"ltp":0.0,"tv":0.0,"id":8260126},{"batb":[[0,2.24,33.61],[1,2.18,21.95],[2,1.01,15.52]],"ltp":0.0,"tv":0.0,"id":4486603}]}]}
{"op":"mcm","clk":"1008544032","pt":1580636834795,"mc":[{"id":"1.168224426","rc":[{"batb":[[0,1.65,26.28],[1,1.01,15.52],[2,1.01,0]],"batl":[[0,2.3,309.75],[1,2.3,0]],"ltp":0.0,"tv":0.0,"id":8260126},{"batb":[[0,2.18,21.95],[1,1.01,15.52],[2,1.01,0]],"batl":[[0,2.7,245.56],[1,2.7,0]],"ltp":0.0,"tv":0.0,"id":4486603}]}]}
{"op":"mcm","clk":"1008544825","pt":1580636846406,"mc":[{"id":"1.168224426","rc":[{"batb":[[1,1.64,27.07],[2,1.01,15.52]],"batl":[[0,1.8,42.01],[1,2.3,309.75]],"ltp":0.0,"tv":0.0,"id":8260126},{"batb":[[0,2.34,17.86],[1,2.26,32.77],[2,2.24,19.99]],"batl":[[0,2.56,26.89],[1,2.7,245.56]],"ltp":0.0,"tv":0.0,"id":4486603}]}]}
{"op":"mcm","clk":"1008545096","pt":1580636849414,"mc":[{"id":"1.168224426","rc":[{"batb":[[1,1.64,92.6]],"ltp":0.0,"tv":0.0,"id":8260126}]}]}
{"op":"mcm","clk":"1008545942","pt":1580636861341,"mc":[{"id":"1.168224426","rc":[{"batb":[[0,1.64,92.6],[1,1.01,15.52],[2,1.01,0]],"ltp":0.0,"tv":0.0,"id":8260126},{"batb":[[0,2.26,32.77],[1,2.24,19.99],[2,1.01,15.52]],"ltp":0.0,"tv":0.0,"id":4486603}]}]}
{"op":"mcm","clk":"1008546042","pt":1580636862995,"mc":[{"id":"1.168224426","rc":[{"batb":[[0,1.64,27.07]],"batl":[[0,2.3,309.75],[1,2.3,0]],"ltp":0.0,"tv":0.0,"id":8260126},{"batb":[[0,2.24,19.99],[1,1.01,15.52],[2,1.01,0]],"batl":[[0,2.7,245.56],[1,2.7,0]],"ltp":0.0,"tv":0.0,"id":4486603}]}]}
{"op":"mcm","clk":"1008546544","pt":1580636870711,"mc":[{"id":"1.168224426","rc":[{"batb":[[1,1.59,29.74],[2,1.01,15.52]],"ltp":0.0,"tv":0.0,"id":8260126},{"batb":[[0,2.36,17.31],[1,2.32,18.18],[2,1.01,15.52]],"ltp":0.0,"tv":0.0,"id":4486603}]}]}
{"op":"mcm","clk":"1008546624","pt":1580636871840,"mc":[{"id":"1.168224426","rc":[{"batb":[[1,1.62,67.22],[2,1.59,29.74]],"batl":[[0,1.77,42.01],[1,2.3,309.75]],"ltp":0.0,"tv":0.0,"id":8260126},{"batb":[[1,2.32,49.26]],"batl":[[0,2.64,25.21],[1,2.7,245.56]],"ltp":0.0,"tv":0.0,"id":4486603}]}]}
{"op":"mcm","clk":"1008547881","pt":1580636892247,"mc":[{"id":"1.168224426","rc":[{"batb":[[0,1.62,67.22],[1,1.59,29.74],[2,1.01,15.52]],"ltp":0.0,"tv":0.0,"id":8260126},{"batb":[[0,2.32,49.26],[1,1.01,15.52],[2,1.01,0]],"ltp":0.0,"tv":0.0,"id":4486603}]}]}
{"op":"mcm","clk":"1008547944","pt":1580636893431,"mc":[{"id":"1.168224426","rc":[{"batb":[[0,1.59,29.74],[1,1.01,15.52],[2,1.01,0]],"batl":[[0,2.3,309.75],[1,2.3,0]],"ltp":0.0,"tv":0.0,"id":8260126},{"batb":[[0,2.32,18.18]],"batl":[[0,2.7,245.56],[1,2.7,0]],"ltp":0.0,"tv":0.0,"id":4486603}]}]}
{"op":"mcm","clk":"1008548413","pt":1580636901870,"mc":[{"id":"1.168224426","rc":[{"batb":[[0,1.66,25.81],[1,1.64,65.54],[2,1.62,28.25]],"batl":[[0,1.79,42.01],[1,2.3,309.75]],"ltp":0.0,"tv":0.0,"id":8260126},{"batb":[[1,2.3,31.93],[2,2.28,19.12]],"batl":[[0,2.6,26.05],[1,2.7,245.56]],"ltp":0.0,"tv":0.0,"id":4486603}]}]}
{"op":"mcm","clk":"1008549060","pt":1580636914356,"mc":[{"id":"1.168224426","rc":[{"batb":[[0,1.64,65.54],[1,1.62,28.25],[2,1.01,15.52]],"ltp":0.0,"tv":0.0,"id":8260126},{"batb":[[0,2.3,31.93],[1,2.28,19.12],[2,1.01,15.52]],"ltp":0.0,"tv":0.0,"id":4486603}]}]}
{"op":"mcm","clk":"1008549102","pt":1580636914971,"mc":[{"id":"1.168224426","rc":[{"batb":[[0,1.62,28.25],[1,1.01,15.52],[2,1.01,0]],"batl":[[0,2.3,309.75],[1,2.3,0]],"ltp":0.0,"tv":0.0,"id":8260126},{"batb":[[0,2.28,19.12],[1,1.01,15.52],[2,1.01,0]],"batl":[[0,2.7,245.56],[1,2.7,0]],"ltp":0.0,"tv":0.0,"id":4486603}]}]}
{"op":"mcm","clk":"1008550179","pt":1580636934187,"mc":[{"id":"1.168224426","rc":[{"batb":[[1,1.61,68.06],[2,1.58,30.92]],"ltp":0.0,"tv":0.0,"id":8260126},{"batb":[[0,2.4,16.44],[1,2.36,17.62],[2,2.34,31.09]],"batl":[[0,2.66,25.21]],"ltp":0.0,"tv":0.0,"id":4486603}]}]}
{"op":"mcm","clk":"1008550278","pt":1580636935779,"mc":[{"id":"1.168224426","rc":[{"batl":[[1,3,213.45]],"ltp":0.0,"tv":0.0,"id":4486603}]}]}
{"op":"mcm","clk":"1008550366","pt":1580636937324,"mc":[{"id":"1.168224426","rc":[{"batl":[[0,1.75,42.01],[1,2.3,309.75]],"ltp":0.0,"tv":0.0,"id":8260126}]}]}
{"op":"mcm","clk":"1008550995","pt":1580636947507,"mc":[{"id":"1.168224426","rc":[{"batb":[[0,1.61,68.06],[1,1.58,30.92],[2,1.01,15.52]],"ltp":0.0,"tv":0.0,"id":8260126},{"batb":[[0,2.36,17.62],[1,2.34,31.09],[2,1.01,15.52]],"ltp":0.0,"tv":0.0,"id":4486603}]}]}
{"op":"mcm","clk":"1008551078","pt":1580636948903,"mc":[{"id":"1.168224426","rc":[{"batb":[[0,1.58,30.92],[1,1.01,15.52],[2,1.01,0]],"batl":[[0,2.3,309.75],[1,2.3,0]],"ltp":0.0,"tv":0.0,"id":8260126},{"batb":[[1,1.01,15.52],[2,1.01,0]],"batl":[[0,3,213.45],[1,3,0]],"ltp":0.0,"tv":0.0,"id":4486603}]}]}
{"op":"mcm","clk":"1008551575","pt":1580636957118,"mc":[{"id":"1.168224426","rc":[{"batb":[[0,1.65,26.59],[1,1.6,29.27],[2,1.01,15.52]],"ltp":0.0,"tv":0.0,"id":8260126},{"batb":[[1,2.3,18.49],[2,1.01,15.52]],"ltp":0.0,"tv":0.0,"id":4486603}]}]}
{"op":"mcm","clk":"1008551614","pt":1580636957952,"mc":[{"id":"1.168224426","rc":[{"batb":[[1,1.62,67.22],[2,1.6,29.27]],"batl":[[0,1.77,42.01],[1,2.3,309.75]],"ltp":0.0,"tv":0.0,"id":8260126},{"batb":[[1,2.32,31.09],[2,2.3,18.49]],"batl":[[0,2.62,25.21]],"ltp":0.0,"tv":0.0,"id":4486603}]}]}
{"op":"mcm","clk":"1008551673","pt":1580636959031,"mc":[{"id":"1.168224426","rc":[{"batl":[[1,2.84,228.62]],"ltp":0.0,"tv":0.0,"id":4486603}]}]}
{"op":"mcm","clk":"1008552425","pt":1580636970046,"mc":[{"id":"1.168224426","rc":[{"batb":[[0,1.62,67.22],[1,1.6,29.27],[2,1.01,15.52]],"ltp":0.0,"tv":0.0,"id":8260126},{"batb":[[0,2.32,31.09],[1,2.3,18.49],[2,1.01,15.52]],"ltp":0.0,"tv":0.0,"id":4486603}]}]}
{"op":"mcm","clk":"1008552482","pt":1580636970977,"mc":[{"id":"1.168224426","rc":[{"batb":[[0,1.6,29.27],[1,1.01,15.52],[2,1.01,0]],"batl":[[0,2.3,309.75],[1,2.3,0]],"ltp":0.0,"tv":0.0,"id":8260126},{"batb":[[0,2.3,18.49],[1,1.01,15.52],[2,1.01,0]],"batl":[[0,2.84,228.62],[1,2.84,0]],"ltp":0.0,"tv":0.0,"id":4486603}]}]}
{"op":"mcm","clk":"1008552856","pt":1580636976355,"mc":[{"id":"1.168224426","rc":[{"batb":[[0,1.67,25.49],[1,1.64,65.54],[2,1.63,27.3]],"batl":[[0,1.79,42.01],[1,2.3,309.75]],"ltp":0.0,"tv":0.0,"id":8260126},{"batb":[[1,2.28,32.77],[2,2.26,19.59]],"batl":[[0,2.58,26.05],[1,2.84,228.62]],"ltp":0.0,"tv":0.0,"id":4486603}]}]}
{"op":"mcm","clk":"1008553440","pt":1580636985455,"mc":[{"id":"1.168224426","rc":[{"batb":[[0,1.64,65.54],[1,1.63,27.3],[2,1.01,15.52]],"ltp":0.0,"tv":0.0,"id":8260126},{"batb":[[0,2.28,32.77],[1,2.26,19.59],[2,1.01,15.52]],"ltp":0.0,"tv":0.0,"id":4486603}]}]}
{"op":"mcm","clk":"1008553535","pt":1580636986955,"mc":[{"id":"1.168224426","rc":[{"batb":[[0,1.63,27.3],[1,1.01,15.52],[2,1.01,0]],"batl":[[0,2.3,309.75],[1,2.3,0]],"ltp":0.0,"tv":0.0,"id":8260126},{"batb":[[0,2.26,19.59],[1,1.01,15.52],[2,1.01,0]],"batl":[[0,2.84,228.62],[1,2.84,0]],"ltp":0.0,"tv":0.0,"id":4486603}]}]}
{"op":"mcm","clk":"1008554909","pt":1580637007313,"mc":[{"id":"1.168224426","rc":[{"batb":[[0,1.69,24.23],[1,1.66,25.65],[2,1.01,15.52]],"ltp":0.0,"tv":0.0,"id":8260126},{"batb":[[1,2.18,21.72],[2,1.01,15.52]],"ltp":0.0,"tv":0.0,"id":4486603}]}]}
{"op":"mcm","clk":"1008554963","pt":1580637007926,"mc":[{"id":"1.168224426","rc":[{"batb":[[1,1.67,62.17],[2,1.66,25.65]],"batl":[[0,1.83,42.01],[1,2.3,309.75]],"ltp":0.0,"tv":0.0,"id":8260126},{"batb":[[1,2.22,33.61],[2,2.18,21.72]],"batl":[[0,2.5,27.73],[1,2.84,228.62]],"ltp":0.0,"tv":0.0,"id":4486603}]}]}
{"op":"mcm","clk":"1008560472","pt":1580637096345,"mc":[{"id":"1.168224426","rc":[{"batb":[[0,1.67,62.17],[1,1.66,25.65],[2,1.01,15.52]],"ltp":0.0,"tv":0.0,"id":8260126},{"batb":[[0,2.22,33.61],[1,2.18,21.72],[2,1.01,15.52]],"ltp":0.0,"tv":0.0,"id":4486603}]}]}
{"op":"mcm","clk":"1008560517","pt":1580637097062,"mc":[{"id":"1.168224426","rc":[{"batb":[[0,1.66,25.65],[1,1.01,15.52],[2,1.01,0]],"batl":[[0,2.3,309.75],[1,2.3,0]],"ltp":0.0,"tv":0.0,"id":8260126},{"batb":[[0,2.18,21.72],[1,1.01,15.52],[2,1.01,0]],"batl":[[0,2.84,228.62],[1,2.84,0]],"ltp":0.0,"tv":0.0,"id":4486603}]}]}
{"op":"mcm","clk":"1008561696","pt":1580637116045,"mc":[{"id":"1.168224426","rc":[{"batb":[[0,1.66,88.66],[1,1.64,26.75],[2,1.01,15.52]],"batl":[[0,1.81,42.01],[1,2.3,309.75]],"ltp":0.0,"tv":0.0,"id":8260126},{"batb":[[0,2.32,18.33],[1,2.24,53.99],[2,1.01,15.52]],"batl":[[0,2.54,26.89],[1,2.84,228.62]],"ltp":0.0,"tv":0.0,"id":4486603}]}]}
{"op":"mcm","clk":"1008562687","pt":1580637132212,"mc":[{"id":"1.168224426","rc":[{"batb":[[0,1.66,63.01]],"ltp":0.0,"tv":0.0,"id":8260126},{"batb":[[0,2.24,53.99],[1,1.01,15.52],[2,1.01,0]],"ltp":0.0,"tv":0.0,"id":4486603}]}]}
{"op":"mcm","clk":"1008562760","pt":1580637133063,"mc":[{"id":"1.168224426","rc":[{"batb":[[0,1.64,26.75],[1,1.01,15.52],[2,1.01,0]],"batl":[[0,2.3,309.75],[1,2.3,0]],"ltp":0.0,"tv":0.0,"id":8260126},{"batb":[[0,2.24,20.38]],"batl":[[0,2.84,228.62],[1,2.84,0]],"ltp":0.0,"tv":0.0,"id":4486603}]}]}
{"op":"mcm","clk":"1008563274","pt":1580637140388,"mc":[{"id":"1.168224426","rc":[{"batb":[[0,1.64,92.29],[1,1.63,27.77],[2,1.01,15.52]],"batl":[[0,1.79,42.01],[1,2.3,309.75]],"ltp":0.0,"tv":0.0,"id":8260126},{"batb":[[0,2.36,17.47],[1,2.28,51.97],[2,2.24,20.38]],"batl":[[0,2.58,26.05],[1,2.84,228.62]],"ltp":0.0,"tv":0.0,"id":4486603}]}]}
{"op":"mcm","clk":"1008563291","pt":1580637140598,"mc":[{"id":"1.168224426","rc":[{"batb":[[2,1.01,15.52]],"ltp":0.0,"tv":0.0,"id":4486603}]}]}
{"op":"mcm","clk":"1008563884","pt":1580637149220,"mc":[{"id":"1.168224426","rc":[{"batb":[[0,1.63,27.77],[1,1.01,15.52],[2,1.01,0]],"batl":[[0,2.3,309.75],[1,2.3,0]],"ltp":0.0,"tv":0.0,"id":8260126},{"batb":[[0,2.28,19.2],[1,1.01,15.52],[2,1.01,0]],"batl":[[0,2.84,228.62],[1,2.84,0]],"ltp":0.0,"tv":0.0,"id":4486603}]}]}
{"op":"mcm","clk":"1008564427","pt":1580637158315,"mc":[{"id":"1.168224426","rc":[{"batb":[[1,1.62,67.22],[2,1.61,28.64]],"batl":[[0,1.78,42.01],[1,2.3,309.75]],"ltp":0.0,"tv":0.0,"id":8260126},{"batb":[[0,2.4,16.76],[1,2.32,49.58],[2,1.01,15.52]],"batl":[[0,2.62,25.21],[1,2.84,228.62]],"ltp":0.0,"tv":0.0,"id":4486603}]}]}
{"op":"mcm","clk":"1008565422","pt":1580637173442,"mc":[{"id":"1.168224426","rc":[{"batb":[[0,1.62,67.22],[1,1.61,28.64],[2,1.01,15.52]],"ltp":0.0,"tv":0.0,"id":8260126},{"batb":[[0,2.32,49.58],[1,1.01,15.52],[2,1.01,0]],"ltp":0.0,"tv":0.0,"id":4486603}]}]}
{"op":"mcm","clk":"1008565566","pt":1580637175410,"mc":[{"id":"1.168224426","rc":[{"batb":[[0,1.61,28.64],[1,1.01,15.52],[2,1.01,0]],"batl":[[0,2.3,309.75],[1,2.3,0]],"ltp":0.0,"tv":0.0,"id":8260126},{"batb":[[0,2.32,18.49]],"batl":[[0,2.84,228.62],[1,2.84,0]],"ltp":0.0,"tv":0.0,"id":4486603}]}]}
{"op":"mcm","clk":"1008565650","pt":1580637176338,"mc":[{"id":"1.168224426","rc":[{"batb":[[1,2.3,18.57],[2,1.01,15.52]],"ltp":0.0,"tv":0.0,"id":4486603}]}]}
{"op":"mcm","clk":"1008565699","pt":1580637177009,"mc":[{"id":"1.168224426","rc":[{"batb":[[0,1.61,28.48]],"ltp":0.0,"tv":0.0,"id":8260126},{"batb":[[0,2.3,18.57],[1,1.01,15.52],[2,1.01,0]],"ltp":0.0,"tv":0.0,"id":4486603}]}]}
{"op":"mcm","clk":"1008566483","pt":1580637189174,"mc":[{"id":"1.168224426","rc":[{"batb":[[0,1.67,25.34],[1,1.65,26.44],[2,1.01,15.52]],"ltp":0.0,"tv":0.0,"id":8260126},{"batb":[[1,2.24,20.3],[2,1.01,15.52]],"ltp":0.0,"tv":0.0,"id":4486603}]}]}
{"op":"mcm","clk":"1008566556","pt":1580637190057,"mc":[{"id":"1.168224426","rc":[{"batb":[[1,1.65,90.29]],"batl":[[0,1.81,42.01],[1,2.3,309.75]],"ltp":0.0,"tv":0.0,"id":8260126},{"batb":[[1,2.26,32.77],[2,2.24,20.3]],"batl":[[0,2.54,26.89],[1,2.84,228.62]],"ltp":0.0,"tv":0.0,"id":4486603}]}]}
{"op":"mcm","clk":"1008567632","pt":1580637205877,"mc":[{"id":"1.168224426","rc":[{"batb":[[0,1.65,90.29],[1,1.01,15.52],[2,1.01,0]],"ltp":0.0,"tv":0.0,"id":8260126},{"batb":[[0,2.26,32.77],[1,2.24,20.3],[2,1.01,15.52]],"ltp":0.0,"tv":0.0,"id":4486603}]}]}
{"op":"mcm","clk":"1008567723","pt":1580637207165,"mc":[{"id":"1.168224426","rc":[{"batb":[[0,1.65,26.44]],"batl":[[0,2.3,309.75],[1,2.3,0]],"ltp":0.0,"tv":0.0,"id":8260126},{"batb":[[0,2.24,20.3],[1,1.01,15.52],[2,1.01,0]],"batl":[[0,2.84,228.62],[1,2.84,0]],"ltp":0.0,"tv":0.0,"id":4486603}]}]}
{"op":"mcm","clk":"1008568744","pt":1580637224375,"mc":[{"id":"1.168224426","rc":[{"batb":[[1,1.63,66.38],[2,1.6,29.19]],"batl":[[0,1.78,42.01],[1,2.3,309.75]],"ltp":0.0,"tv":0.0,"id":8260126},{"batb":[[0,2.34,17.78],[1,2.3,50.73],[2,1.01,15.52]],"batl":[[0,2.62,25.21],[1,2.84,228.62]],"ltp":0.0,"tv":0.0,"id":4486603}]}]}
{"op":"mcm","clk":"1008570148","pt":1580637246449,"mc":[{"id":"1.168224426","rc":[{"batb":[[0,1.63,66.38],[1,1.6,29.19],[2,1.01,15.52]],"ltp":0.0,"tv":0.0,"id":8260126},{"batb":[[0,2.3,50.73],[1,1.01,15.52],[2,1.01,0]],"ltp":0.0,"tv":0.0,"id":4486603}]}]}
{"op":"mcm","clk":"1008570206","pt":1580637247374,"mc":[{"id":"1.168224426","rc":[{"batb":[[0,1.6,29.19],[1,1.01,15.52],[2,1.01,0]],"batl":[[0,2.3,309.75],[1,2.3,0]],"ltp":0.0,"tv":0.0,"id":8260126},{"batb":[[0,2.3,18.8]],"batl":[[0,2.84,228.62],[1,2.84,0]],"ltp":0.0,"tv":0.0,"id":4486603}]}]}
{"op":"mcm","clk":"1008571418","pt":1580637264409,"mc":[{"id":"1.168224426","rc":[{"batb":[[0,1.6,98.93],[1,1.56,32.65],[2,1.01,15.52]],"batl":[[0,1.75,42.01],[1,2.3,309.75]],"ltp":0.0,"tv":0.0,"id":8260126},{"batb":[[0,2.44,15.82],[1,2.38,17.07],[2,2.36,30.25]],"batl":[[0,2.68,24.37],[1,2.84,228.62]],"ltp":0.0,"tv":0.0,"id":4486603}]}]}
{"op":"mcm","clk":"1008572271","pt":1580637277307,"mc":[{"id":"1.168224426","rc":[{"batb":[[0,1.56,32.65],[1,1.01,15.52],[2,1.01,0]],"batl":[[0,2.3,309.75],[1,2.3,0]],"ltp":0.0,"tv":0.0,"id":8260126},{"batb":[[0,2.38,17.07],[1,1.01,15.52],[2,2.36,0]],"batl":[[0,2.84,228.62],[1,2.84,0]],"ltp":0.0,"tv":0.0,"id":4486603}]}]}
{"op":"mcm","clk":"1008573011","pt":1580637288432,"mc":[{"id":"1.168224426","rc":[{"batb":[[0,1.58,72.26],[1,1.56,32.65],[2,1.51,36.59]],"batl":[[0,1.72,42.01],[1,2.3,309.75]],"ltp":0.0,"tv":0.0,"id":8260126},{"batb":[[0,2.56,13.93],[1,2.48,15.11],[2,2.4,29.41]],"batl":[[0,2.74,23.53]],"ltp":0.0,"tv":0.0,"id":4486603}]}]}
{"op":"mcm","clk":"1008573221","pt":1580637291418,"mc":[{"id":"1.168224426","rc":[{"batl":[[1,3.15,200.42]],"ltp":0.0,"tv":0.0,"id":4486603}]}]}
{"op":"mcm","clk":"1008573872","pt":1580637300441,"mc":[{"id":"1.168224426","rc":[{"batb":[[1,1.51,36.59],[2,1.01,15.52]],"ltp":0.0,"tv":0.0,"id":8260126},{"batb":[[0,2.48,15.11],[1,2.4,29.41],[2,1.01,15.52]],"ltp":0.0,"tv":0.0,"id":4486603}]}]}
{"op":"mcm","clk":"1008573961","pt":1580637301232,"mc":[{"id":"1.168224426","rc":[{"batb":[[0,1.51,36.59],[1,1.01,15.52],[2,1.01,0]],"batl":[[0,2.3,309.75],[1,2.3,0]],"ltp":0.0,"tv":0.0,"id":8260126},{"batb":[[1,1.01,15.52],[2,1.01,0]],"batl":[[0,3.15,200.42],[1,3.15,0]],"ltp":0.0,"tv":0.0,"id":4486603}]}]}
{"op":"mcm","clk":"1008575326","pt":1580637318435,"mc":[{"id":"1.168224426","rc":[{"batb":[[0,1.55,75.62],[1,1.51,36.59],[2,1.01,15.52]],"batl":[[0,1.69,42.01]],"ltp":0.0,"tv":0.0,"id":8260126},{"batb":[[1,2.46,28.57],[2,1.01,15.52]],"batl":[[0,2.8,22.69],[1,3.15,200.42]],"ltp":0.0,"tv":0.0,"id":4486603}]}]}
{"op":"mcm","clk":"1008575383","pt":1580637319208,"mc":[{"id":"1.168224426","rc":[{"batb":[[2,1.47,40.77]],"ltp":0.0,"tv":0.0,"id":8260126},{"batb":[[0,2.7,12.12],[1,2.62,13.22],[2,2.46,28.57]],"ltp":0.0,"tv":0.0,"id":4486603}]}]}
{"op":"mcm","clk":"1008575521","pt":1580637321356,"mc":[{"id":"1.168224426","rc":[{"batl":[[0,2.16,342.82]],"ltp":0.0,"tv":0.0,"id":8260126}]}]}
{"op":"mcm","clk":"1008575768","pt":1580637324313,"mc":[{"id":"1.168224426","rc":[{"batl":[[0,1.68,42.01],[1,2.16,342.82]],"ltp":0.0,"tv":0.0,"id":8260126}]}]}
{"op":"mcm","clk":"1008576217","pt":1580637330044,"mc":[{"id":"1.168224426","rc":[{"batb":[[1,1.47,40.77],[2,1.01,15.51]],"ltp":0.0,"tv":0.0,"id":8260126},{"batb":[[0,2.62,13.22],[1,2.46,28.57],[2,1.01,15.52]],"ltp":0.0,"tv":0.0,"id":4486603}]}]}
{"op":"mcm","clk":"1008576311","pt":1580637331246,"mc":[{"id":"1.168224426","rc":[{"batb":[[0,1.47,40.77],[1,1.01,15.51],[2,1.01,0]],"batl":[[0,2.16,342.82],[1,2.16,0]],"ltp":0.0,"tv":0.0,"id":8260126},{"batb":[[1,1.01,15.52],[2,1.01,0]],"batl":[[0,3.15,200.42],[1,3.15,0]],"ltp":0.0,"tv":0.0,"id":4486603}]}]}
{"op":"mcm","clk":"1008576389","pt":1580637332317,"mc":[{"id":"1.168224426","rc":[{"batb":[[0,1.01,15.52],[1,1.01,0]],"ltp":0.0,"tv":0.0,"id":4486603}]}]}
{"op":"mcm","clk":"1008576478","pt":1580637333454,"mc":[{"id":"1.168224426","rc":[{"batb":[[0,1.48,40.14]],"ltp":0.0,"tv":0.0,"id":8260126},{"batb":[[0,2.6,13.45],[1,1.01,15.52]],"ltp":0.0,"tv":0.0,"id":4486603}]}]}
{"op":"mcm","clk":"1008576717","pt":1580637336445,"mc":[{"id":"1.168224426","rc":[{"batb":[[0,1.56,74.78],[1,1.54,33.6],[2,1.49,38.24]],"batl":[[0,1.7,42.01],[1,2.16,342.82]],"ltp":0.0,"tv":0.0,"id":8260126},{"batb":[[1,2.52,14.56],[2,2.46,28.57]],"batl":[[0,2.8,22.69],[1,3.15,200.42]],"ltp":0.0,"tv":0.0,"id":4486603}]}]}
{"op":"mcm","clk":"1008576793","pt":1580637337432,"mc":[{"id":"1.168224426","rc":[{"batl":[[0,1.69,42.01]],"ltp":0.0,"tv":0.0,"id":8260126}]}]}
{"op":"mcm","clk":"1008576857","pt":1580637338253,"mc":[{"id":"1.168224426","rc":[{"batl":[[0,3.15,200.42],[1,3.15,0]],"ltp":0.0,"tv":0.0,"id":4486603}]}]}
{"op":"mcm","clk":"1008577064","pt":1580637341434,"mc":[{"id":"1.168224426","rc":[{"batl":[[0,2.78,23.53],[1,3.15,200.42]],"ltp":0.0,"tv":0.0,"id":4486603}]}]}
{"op":"mcm","clk":"1008577551","pt":1580637348442,"mc":[{"id":"1.168224426","rc":[{"batb":[[1,1.49,38.24],[2,1.01,15.52]],"ltp":0.0,"tv":0.0,"id":8260126},{"batb":[[0,2.52,14.56],[1,2.46,28.57],[2,1.01,15.52]],"ltp":0.0,"tv":0.0,"id":4486603}]}]}
{"op":"mcm","clk":"1008577605","pt":1580637349263,"mc":[{"id":"1.168224426","rc":[{"batb":[[0,1.49,38.24],[1,1.01,15.52],[2,1.01,0]],"batl":[[0,2.16,342.82],[1,2.16,0]],"ltp":0.0,"tv":0.0,"id":8260126},{"batb":[[1,1.01,15.52],[2,1.01,0]],"batl":[[0,3.15,200.42],[1,3.15,0]],"ltp":0.0,"tv":0.0,"id":4486603}]}]}
{"op":"mcm","clk":"1008578951","pt":1580637368288,"mc":[{"id":"1.168224426","rc":[{"batb":[[0,1.5,84.02],[1,1.49,38.24],[2,1.47,40.22]],"batl":[[0,1.62,42.01],[1,2.16,342.82]],"ltp":0.0,"tv":0.0,"id":8260126},{"batb":[[0,2.76,11.49],[1,2.64,12.9],[2,2.6,26.05]],"batl":[[0,3,21],[1,3.15,200.42]],"ltp":0.0,"tv":0.0,"id":4486603}]}]}
{"op":"mcm","clk":"1008585579","pt":1580637453295,"mc":[{"id":"1.168224426","rc":[{"batb":[[0,1.47,40.22],[1,1.01,15.51],[2,1.47,0]],"batl":[[0,2.16,342.82],[1,2.16,0]],"ltp":0.0,"tv":0.0,"id":8260126},{"batb":[[0,2.64,12.9],[1,1.01,15.52],[2,2.6,0]],"batl":[[0,3.15,200.42],[1,3.15,0]],"ltp":0.0,"tv":0.0,"id":4486603}]}]}
{"op":"mcm","clk":"1008586052","pt":1580637460287,"mc":[{"id":"1.168224426","rc":[{"batb":[[0,1.49,85.7],[1,1.47,40.22],[2,1.46,41.94]],"batl":[[0,1.61,42.01],[1,2.16,342.82]],"ltp":0.0,"tv":0.0,"id":8260126},{"batb":[[0,2.82,10.78],[1,2.7,12.04],[2,2.66,25.21]],"batl":[[0,3.05,20.16],[1,3.15,200.42]],"ltp":0.0,"tv":0.0,"id":4486603}]}]}
{"op":"mcm","clk":"1008586737","pt":1580637469428,"mc":[{"id":"1.168224426","rc":[{"batb":[[0,1.46,41.95],[1,1.01,15.51],[2,1.46,0]],"batl":[[0,2.16,342.82],[1,2.16,0]],"ltp":0.0,"tv":0.0,"id":8260126},{"batb":[[0,2.7,12.04],[1,1.01,15.52],[2,2.66,0]],"batl":[[0,3.15,200.42],[1,3.15,0]],"ltp":0.0,"tv":0.0,"id":4486603}]}]}
{"op":"mcm","clk":"1008587084","pt":1580637474320,"mc":[{"id":"1.168224426","rc":[{"batb":[[0,1.48,87.39],[1,1.46,41.94],[2,1.01,15.51]],"batl":[[0,1.6,42.01]],"ltp":0.0,"tv":0.0,"id":8260126},{"batb":[[0,2.7,36.4]],"batl":[[0,3.1,19.32]],"ltp":0.0,"tv":0.0,"id":4486603}]}]}
{"op":"mcm","clk":"1008587123","pt":1580637474937,"mc":[{"id":"1.168224426","rc":[{"batb":[[2,1.45,43.51]],"ltp":0.0,"tv":0.0,"id":8260126},{"batb":[[0,2.86,10.39],[1,2.76,11.41],[2,2.7,24.37]],"ltp":0.0,"tv":0.0,"id":4486603}]}]}
{"op":"mcm","clk":"1008587240","pt":1580637476536,"mc":[{"id":"1.168224426","rc":[{"batl":[[1,2.04,383.01]],"ltp":0.0,"tv":0.0,"id":8260126},{"batl":[[1,3.65,170.41]],"ltp":0.0,"tv":0.0,"id":4486603}]}]}
{"op":"mcm","clk":"1008587721","pt":1580637483416,"mc":[{"id":"1.168224426","rc":[{"batb":[[0,1.45,43.52],[1,1.01,15.51],[2,1.45,0]],"batl":[[0,2.04,383.01],[1,2.04,0]],"ltp":0.0,"tv":0.0,"id":8260126},{"batb":[[0,2.76,11.41],[1,1.01,15.52],[2,2.7,0]],"batl":[[0,3.65,170.41],[1,3.65,0]],"ltp":0.0,"tv":0.0,"id":4486603}]}]}
{"op":"mcm","clk":"1008588986","pt":1580637502349,"mc":[{"id":"1.168224426","rc":[{"batb":[[0,1.47,89.07],[1,1.45,43.51],[2,1.01,15.51]],"batl":[[0,1.59,42.01],[1,2.04,383.01]],"ltp":0.0,"tv":0.0,"id":8260126},{"batb":[[1,2.74,23.53],[2,1.01,15.52]],"batl":[[0,3.15,19.32],[1,3.65,170.41]],"ltp":0.0,"tv":0.0,"id":4486603}]}]}
{"op":"mcm","clk":"1008589019","pt":1580637502975,"mc":[{"id":"1.168224426","rc":[{"batb":[[2,1.43,45.08]],"ltp":0.0,"tv":0.0,"id":8260126},{"batb":[[0,2.92,24.86],[1,2.82,10.94],[2,2.74,23.53]],"ltp":0.0,"tv":0.0,"id":4486603}]}]}
{"op":"mcm","clk":"1008590093","pt":1580637519409,"mc":[{"id":"1.168224426","rc":[{"batb":[[0,1.43,45.09],[1,1.01,15.51],[2,1.43,0]],"batl":[[0,2.04,383.01],[1,2.04,0]],"ltp":0.0,"tv":0.0,"id":8260126},{"batb":[[0,2.82,10.94],[1,1.01,15.52],[2,2.74,0]],"batl":[[0,3.65,170.41],[1,3.65,0]],"ltp":0.0,"tv":0.0,"id":4486603}]}]}
{"op":"mcm","clk":"1008590536","pt":1580637526414,"mc":[{"id":"1.168224426","rc":[{"batb":[[0,1.45,93.27],[1,1.43,45.08],[2,1.41,49.02]],"batl":[[0,1.56,42.01],[1,2.04,383.01]],"ltp":0.0,"tv":0.0,"id":8260126},{"batb":[[0,2.98,23.68],[1,2.9,25.1],[2,2.8,22.69]],"batl":[[0,3.2,18.48],[1,3.65,170.41]],"ltp":0.0,"tv":0.0,"id":4486603}]}]}
{"op":"mcm","clk":"1008592176","pt":1580637551430,"mc":[{"id":"1.168224426","rc":[{"batb":[[0,1.41,49.03],[1,1.01,15.51],[2,1.41,0]],"batl":[[0,2.04,383.01],[1,2.04,0]],"ltp":0.0,"tv":0.0,"id":8260126},{"batb":[[0,2.9,25.1],[1,1.01,15.52],[2,2.8,0]],"batl":[[0,3.65,170.41],[1,3.65,0]],"ltp":0.0,"tv":0.0,"id":4486603}]}]}
{"op":"mcm","clk":"1008592526","pt":1580637556331,"mc":[{"id":"1.168224426","rc":[{"batb":[[0,1.46,90.75],[1,1.45,43.12],[2,1.42,46.58]],"batl":[[0,1.58,42.01],[1,2.04,383.01]],"ltp":0.0,"tv":0.0,"id":8260126},{"batb":[[1,2.84,10.7],[2,2.76,23.53]],"batl":[[0,3.15,19.32],[1,3.65,170.41]],"ltp":0.0,"tv":0.0,"id":4486603}]}]}
{"op":"mcm","clk":"1008593175","pt":1580637566356,"mc":[{"id":"1.168224426","rc":[{"batb":[[1,1.42,46.58],[2,1.01,15.51]],"ltp":0.0,"tv":0.0,"id":8260126},{"batb":[[0,2.84,10.7],[1,2.76,23.53],[2,1.01,15.52]],"ltp":0.0,"tv":0.0,"id":4486603}]}]}
{"op":"mcm","clk":"1008593241","pt":1580637567452,"mc":[{"id":"1.168224426","rc":[{"batb":[[0,1.42,46.59],[1,1.01,15.51],[2,1.01,0]],"batl":[[0,2.04,383.01],[1,2.04,0]],"ltp":0.0,"tv":0.0,"id":8260126},{"batb":[[1,1.01,15.52],[2,1.01,0]],"batl":[[0,3.65,170.41],[1,3.65,0]],"ltp":0.0,"tv":0.0,"id":4486603}]}]}
{"op":"mcm","clk":"1008594938","pt":1580637593313,"mc":[{"id":"1.168224426","rc":[{"batb":[[0,1.47,40.53],[1,1.44,44.14],[2,1.42,46.58]],"ltp":0.0,"tv":0.0,"id":8260126},{"batb":[[1,2.78,11.25],[2,1.01,15.52]],"ltp":0.0,"tv":0.0,"id":4486603}]}]}
{"op":"mcm","clk":"1008595005","pt":1580637594400,"mc":[{"id":"1.168224426","rc":[{"batb":[[0,1.48,87.39],[1,1.47,40.52],[2,1.44,44.14]],"batl":[[0,1.59,42.01],[1,2.04,383.01]],"ltp":0.0,"tv":0.0,"id":8260126},{"batb":[[2,2.72,24.37]],"batl":[[0,3.1,19.32],[1,3.65,170.41]],"ltp":0.0,"tv":0.0,"id":4486603}]}]}
{"op":"mcm","clk":"1008595242","pt":1580637597290,"mc":[{"id":"1.168224426","rc":[{"batb":[[1,1.44,44.14],[2,1.01,15.51]],"ltp":0.0,"tv":0.0,"id":8260126},{"batb":[[0,2.78,11.25],[1,2.72,24.37],[2,1.01,15.52]],"ltp":0.0,"tv":0.0,"id":4486603}]}]}
{"op":"mcm","clk":"1008596624","pt":1580637613519,"mc":[{"id":"1.168224426","rc":[{"batb":[[0,1.44,44.15],[1,1.01,15.51],[2,1.01,0]],"batl":[[0,2.04,383.01],[1,2.04,0]],"ltp":0.0,"tv":0.0,"id":8260126},{"batb":[[1,1.01,15.52],[2,1.01,0]],"batl":[[0,3.65,170.41],[1,3.65,0]],"ltp":0.0,"tv":0.0,"id":4486603}]}]}
{"op":"mcm","clk":"1008597236","pt":1580637622441,"mc":[{"id":"1.168224426","rc":[{"batb":[[0,1.49,124.65],[1,1.46,42.18],[2,1.01,15.51]],"batl":[[0,1.61,42.01],[1,2.04,383.01]],"ltp":0.0,"tv":0.0,"id":8260126},{"batb":[[1,2.74,11.72],[2,2.68,24.37]],"batl":[[0,3.05,20.16]],"ltp":0.0,"tv":0.0,"id":4486603}]}]}
{"op":"mcm","clk":"1008597437","pt":1580637624846,"mc":[{"id":"1.168224426","rc":[{"batl":[[1,3.45,180.4]],"ltp":0.0,"tv":0.0,"id":4486603}]}]}
{"op":"mcm","clk":"1008598085","pt":1580637632929,"mc":[{"id":"1.168224426","rc":[{"batb":[[0,1.49,85.7]],"ltp":0.0,"tv":0.0,"id":8260126},{"batb":[[0,2.74,11.72],[1,2.68,24.37],[2,1.01,15.52]],"ltp":0.0,"tv":0.0,"id":4486603}]}]}
{"op":"mcm","clk":"1008598125","pt":1580637633546,"mc":[{"id":"1.168224426","rc":[{"batb":[[0,1.46,42.18],[1,1.01,15.51],[2,1.01,0]],"batl":[[0,2.04,383.01],[1,2.04,0]],"ltp":0.0,"tv":0.0,"id":8260126},{"batb":[[1,1.01,15.52],[2,1.01,0]],"batl":[[0,3.45,180.4],[1,3.45,0]],"ltp":0.0,"tv":0.0,"id":4486603}]}]}
{"op":"mcm","clk":"1008598651","pt":1580637641303,"mc":[{"id":"1.168224426","rc":[{"batb":[[0,1.5,37.53],[1,1.49,38.79],[2,1.01,15.52]],"ltp":0.0,"tv":0.0,"id":8260126},{"batb":[[1,2.58,13.61],[2,1.01,15.52]],"ltp":0.0,"tv":0.0,"id":4486603}]}]}
{"op":"mcm","clk":"1008598803","pt":1580637643267,"mc":[{"id":"1.168224426","rc":[{"batb":[[0,1.51,82.34],[1,1.5,37.53],[2,1.49,38.79]],"batl":[[0,1.63,42.01],[1,2.04,383.01]],"ltp":0.0,"tv":0.0,"id":8260126},{"batb":[[1,2.6,26.05],[2,2.58,13.61]],"batl":[[0,2.98,21],[1,3.3,191.92]],"ltp":0.0,"tv":0.0,"id":4486603}]}]}
{"op":"mcm","clk":"1008604674","pt":1580637725093,"mc":[{"id":"1.168224426","rc":[{"batb":[[1,1.49,38.79],[2,1.01,15.52]],"ltp":0.0,"tv":0.0,"id":8260126},{"batb":[[0,2.6,26.05],[1,2.58,13.61],[2,1.01,15.52]],"ltp":0.0,"tv":0.0,"id":4486603}]}]}
{"op":"mcm","clk":"1008604730","pt":1580637725820,"mc":[{"id":"1.168224426","rc":[{"batb":[[0,1.49,38.79],[1,1.01,15.52],[2,1.01,0]],"batl":[[0,2.04,383.01],[1,2.04,0]],"ltp":0.0,"tv":0.0,"id":8260126},{"batb":[[0,2.58,13.61],[1,1.01,15.52],[2,1.01,0]],"batl":[[0,3.3,191.92],[1,3.3,0]],"ltp":0.0,"tv":0.0,"id":4486603}]}]}
{"op":"mcm","clk":"1008605443","pt":1580637733930,"mc":[{"id":"1.168224426","rc":[{"batb":[[1,1.47,41],[2,1.01,15.51]],"ltp":0.0,"tv":0.0,"id":8260126},{"batb":[[0,2.78,11.33],[1,2.66,12.75],[2,1.01,15.52]],"ltp":0.0,"tv":0.0,"id":4486603}]}]}
{"op":"mcm","clk":"1008605581","pt":1580637735402,"mc":[{"id":"1.168224426","rc":[{"batb":[[0,1.49,124.49]],"batl":[[0,1.62,42.01],[1,2.04,383.01]],"ltp":0.0,"tv":0.0,"id":8260126},{"batb":[[2,2.64,25.21]],"batl":[[0,3,21],[1,3.3,191.92]],"ltp":0.0,"tv":0.0,"id":4486603}]}]}
{"op":"mcm","clk":"1008606094","pt":1580637742220,"mc":[{"id":"1.168224426","rc":[{"batb":[[0,1.47,41],[1,1.01,15.51],[2,1.01,0]],"batl":[[0,2.04,383.01],[1,2.04,0]],"ltp":0.0,"tv":0.0,"id":8260126},{"batb":[[0,2.66,12.75],[1,1.01,15.52],[2,2.64,0]],"batl":[[0,3.3,191.92],[1,3.3,0]],"ltp":0.0,"tv":0.0,"id":4486603}]}]}
{"op":"mcm","clk":"1008606653","pt":1580637750060,"mc":[{"id":"1.168224426","rc":[{"batb":[[1,1.45,42.57],[2,1.01,15.51]],"ltp":0.0,"tv":0.0,"id":8260126},{"batb":[[0,2.84,10.54],[1,2.7,12.04],[2,1.01,15.52]],"ltp":0.0,"tv":0.0,"id":4486603}]}]}
{"op":"mcm","clk":"1008606691","pt":1580637750532,"mc":[{"id":"1.168224426","rc":[{"batb":[[0,1.48,87.39],[1,1.47,40.99],[2,1.45,42.57]],"batl":[[0,1.61,42.01],[1,2.04,383.01]],"ltp":0.0,"tv":0.0,"id":8260126},{"batb":[[2,2.68,24.37]],"batl":[[0,3.05,20.16]],"ltp":0.0,"tv":0.0,"id":4486603}]}]}
{"op":"mcm","clk":"1008606811","pt":1580637752137,"mc":[{"id":"1.168224426","rc":[{"batl":[[1,3.65,170.41]],"ltp":0.0,"tv":0.0,"id":4486603}]}]}
{"op":"mcm","clk":"1008607473","pt":1580637761671,"mc":[{"id":"1.168224426","rc":[{"batb":[[0,1.45,42.58],[1,1.01,15.51],[2,1.45,0]],"batl":[[0,2.04,383.01],[1,2.04,0]],"ltp":0.0,"tv":0.0,"id":8260126},{"batb":[[0,2.7,12.04],[1,1.01,15.52],[2,2.68,0]],"batl":[[0,3.65,170.41],[1,3.65,0]],"ltp":0.0,"tv":0.0,"id":4486603}]}]}
{"op":"mcm","clk":"1008608392","pt":1580637776382,"mc":[{"id":"1.168224426","rc":[{"batb":[[0,1.51,36.9],[1,1.49,38.95],[2,1.45,42.58]],"ltp":0.0,"tv":0.0,"id":8260126},{"batb":[[1,2.58,13.77],[2,1.01,15.52]],"ltp":0.0,"tv":0.0,"id":4486603}]}]}
{"op":"mcm","clk":"1008608425","pt":1580637776960,"mc":[{"id":"1.168224426","rc":[{"batb":[[1,1.5,84.02],[2,1.49,38.95]],"batl":[[0,1.63,42.01],[1,2.04,383.01]],"ltp":0.0,"tv":0.0,"id":8260126},{"batl":[[0,2.98,21]],"ltp":0.0,"tv":0.0,"id":4486603}]}]}
{"op":"mcm","clk":"1008608578","pt":1580637779077,"mc":[{"id":"1.168224426","rc":[{"batb":[[1,2.6,26.05],[2,2.58,13.77]],"batl":[[1,3.3,191.92]],"ltp":0.0,"tv":0.0,"id":4486603}]}]}
{"op":"mcm","clk":"1008609820","pt":1580637793428,"mc":[{"id":"1.168224426","rc":[{"batb":[[0,1.5,84.02],[1,1.49,38.95],[2,1.01,15.52]],"ltp":0.0,"tv":0.0,"id":8260126},{"batb":[[0,2.6,26.05],[1,2.58,13.77],[2,1.01,15.52]],"ltp":0.0,"tv":0.0,"id":4486603}]}]}
{"op":"mcm","clk":"1008609837","pt":1580637793692,"mc":[{"id":"1.168224426","rc":[{"batb":[[0,1.49,38.95],[1,1.01,15.52],[2,1.01,0]],"batl":[[0,2.04,383.01],[1,2.04,0]],"ltp":0.0,"tv":0.0,"id":8260126},{"batb":[[0,2.58,13.77],[1,1.01,15.52],[2,1.01,0]],"batl":[[0,3.3,191.92],[1,3.3,0]],"ltp":0.0,"tv":0.0,"id":4486603}]}]}
{"op":"mcm","clk":"1008610811","pt":1580637806445,"mc":[{"id":"1.168224426","rc":[{"batb":[[1,1.47,40.37],[2,1.01,15.51]],"ltp":0.0,"tv":0.0,"id":8260126},{"batb":[[0,2.78,11.25],[1,2.64,12.83],[2,2.58,13.77]],"ltp":0.0,"tv":0.0,"id":4486603}]}]}
{"op":"mcm","clk":"1008610825","pt":1580637806653,"mc":[{"id":"1.168224426","rc":[{"batb":[[0,1.49,124.65]],"batl":[[0,1.62,42.01],[1,2.04,383.01]],"ltp":0.0,"tv":0.0,"id":8260126},{"batb":[[1,2.64,38.03],[2,1.01,15.52]],"batl":[[0,3,21],[1,3.3,191.92]],"ltp":0.0,"tv":0.0,"id":4486603}]}]}
{"op":"mcm","clk":"1008611885","pt":1580637819077,"mc":[{"id":"1.168224426","rc":[{"batb":[[0,1.49,85.7]],"ltp":0.0,"tv":0.0,"id":8260126},{"batb":[[0,2.64,38.03],[1,1.01,15.52],[2,1.01,0]],"ltp":0.0,"tv":0.0,"id":4486603}]}]}
{"op":"mcm","clk":"1008611944","pt":1580637819647,"mc":[{"id":"1.168224426","rc":[{"batb":[[0,1.47,40.37],[1,1.01,15.51],[2,1.01,0]],"batl":[[0,2.04,383.01],[1,2.04,0]],"ltp":0.0,"tv":0.0,"id":8260126},{"batb":[[0,2.64,12.83]],"batl":[[0,3.3,191.92],[1,3.3,0]],"ltp":0.0,"tv":0.0,"id":4486603}]}]}
{"op":"mcm","clk":"1008612478","pt":1580637826282,"mc":[{"id":"1.168224426","rc":[{"batb":[[1,1.44,44.46],[2,1.01,15.51]],"ltp":0.0,"tv":0.0,"id":8260126},{"batb":[[0,2.82,10.78],[1,2.76,11.57],[2,1.01,15.52]],"ltp":0.0,"tv":0.0,"id":4486603}]}]}
{"op":"mcm","clk":"1008612495","pt":1580637826595,"mc":[{"id":"1.168224426","rc":[{"batb":[[0,1.48,87.39],[1,1.47,40.36],[2,1.44,44.46]],"batl":[[0,1.6,42.01],[1,2.04,383.01]],"ltp":0.0,"tv":0.0,"id":8260126},{"batb":[[2,2.7,24.37]],"batl":[[0,3.1,19.32],[1,3.3,191.92]],"ltp":0.0,"tv":0.0,"id":4486603}]}]}
{"op":"mcm","clk":"1008614021","pt":1580637847310,"mc":[{"id":"1.168224426","rc":[{"batb":[[1,1.44,44.46],[2,1.01,15.51]],"ltp":0.0,"tv":0.0,"id":8260126},{"batb":[[0,2.76,11.57],[1,2.7,24.37],[2,1.01,15.52]],"ltp":0.0,"tv":0.0,"id":4486603}]}]}
{"op":"mcm","clk":"1008614057","pt":1580637847682,"mc":[{"id":"1.168224426","rc":[{"batb":[[0,1.44,44.47],[1,1.01,15.51],[2,1.01,0]],"batl":[[0,2.04,383.01],[1,2.04,0]],"ltp":0.0,"tv":0.0,"id":8260126},{"batb":[[1,1.01,15.52],[2,1.01,0]],"batl":[[0,3.3,191.92],[1,3.3,0]],"ltp":0.0,"tv":0.0,"id":4486603}]}]}
{"op":"mcm","clk":"1008615397","pt":1580637864387,"mc":[{"id":"1.168224426","rc":[{"batb":[[1,1.4,49.49],[2,1.01,15.51]],"ltp":0.0,"tv":0.0,"id":8260126},{"batb":[[0,2.94,24.16],[1,2.86,10.39],[2,1.01,15.52]],"ltp":0.0,"tv":0.0,"id":4486603}]}]}
{"op":"mcm","clk":"1008615419","pt":1580637864697,"mc":[{"id":"1.168224426","rc":[{"batb":[[0,1.46,90.75],[1,1.44,44.46],[2,1.4,49.49]],"batl":[[0,1.58,42.01],[1,2.04,383.01]],"ltp":0.0,"tv":0.0,"id":8260126},{"batb":[[2,2.76,23.53]],"batl":[[0,3.15,19.32]],"ltp":0.0,"tv":0.0,"id":4486603}]}]}
{"op":"mcm","clk":"1008615525","pt":1580637866101,"mc":[{"id":"1.168224426","rc":[{"batl":[[1,3.65,170.41]],"ltp":0.0,"tv":0.0,"id":4486603}]}]}
{"op":"mcm","clk":"1008616127","pt":1580637873426,"mc":[{"id":"1.168224426","rc":[{"batb":[[1,1.4,49.49],[2,1.01,15.51]],"ltp":0.0,"tv":0.0,"id":8260126},{"batb":[[0,2.86,10.39],[1,2.76,23.53],[2,1.01,15.52]],"ltp":0.0,"tv":0.0,"id":4486603}]}]}
{"op":"mcm","clk":"1008616141","pt":1580637873636,"mc":[{"id":"1.168224426","rc":[{"batb":[[0,1.4,49.5],[1,1.01,15.51],[2,1.01,0]],"batl":[[0,2.04,383.01],[1,2.04,0]],"ltp":0.0,"tv":0.0,"id":8260126},{"batb":[[1,1.01,15.52],[2,1.01,0]],"batl":[[0,3.65,170.41],[1,3.65,0]],"ltp":0.0,"tv":0.0,"id":4486603}]}]}
{"op":"mcm","clk":"1008617482","pt":1580637891125,"mc":[{"id":"1.168224426","rc":[{"batb":[[0,1.47,89.07],[1,1.46,41.94],[2,1.42,46.74]],"batl":[[0,1.59,42.01],[1,2.04,383.01]],"ltp":0.0,"tv":0.0,"id":8260126},{"batb":[[1,2.8,10.94],[2,2.72,24.37]],"batl":[[0,3.1,19.32],[1,3.65,170.41]],"ltp":0.0,"tv":0.0,"id":4486603}]}]}
{"op":"mcm","clk":"1008618246","pt":1580637901401,"mc":[{"id":"1.168224426","rc":[{"batb":[[1,1.42,46.74],[2,1.01,15.51]],"ltp":0.0,"tv":0.0,"id":8260126},{"batb":[[0,2.8,10.94],[1,2.72,24.37],[2,1.01,15.52]],"ltp":0.0,"tv":0.0,"id":4486603}]}]}
{"op":"mcm","clk":"1008618288","pt":1580637901772,"mc":[{"id":"1.168224426","rc":[{"batb":[[0,1.42,46.75],[1,1.01,15.51],[2,1.01,0]],"batl":[[0,2.04,383.01],[1,2.04,0]],"ltp":0.0,"tv":0.0,"id":8260126},{"batb":[[1,1.01,15.52],[2,1.01,0]],"batl":[[0,3.65,170.41],[1,3.65,0]],"ltp":0.0,"tv":0.0,"id":4486603}]}]}
{"op":"mcm","clk":"1008618820","pt":1580637907179,"mc":[{"id":"1.168224426","rc":[{"batb":[[0,1.49,85.7],[1,1.48,39.74],[2,1.45,43.67]],"batl":[[0,1.6,42.01],[1,2.04,383.01]],"ltp":0.0,"tv":0.0,"id":8260126},{"batb":[[1,2.74,11.8],[2,2.68,24.37]],"batl":[[0,3.05,20.16]],"ltp":0.0,"tv":0.0,"id":4486603}]}]}
{"op":"mcm","clk":"1008619068","pt":1580637909709,"mc":[{"id":"1.168224426","rc":[{"batl":[[1,3.45,180.4]],"ltp":0.0,"tv":0.0,"id":4486603}]}]}
{"op":"mcm","clk":"1008619778","pt":1580637917293,"mc":[{"id":"1.168224426","rc":[{"batb":[[1,1.45,43.68],[2,1.01,15.51]],"ltp":0.0,"tv":0.0,"id":8260126},{"batb":[[0,2.74,11.8],[1,2.68,24.37],[2,1.01,15.52]],"ltp":0.0,"tv":0.0,"id":4486603}]}]}
{"op":"mcm","clk":"1008619819","pt":1580637917711,"mc":[{"id":"1.168224426","rc":[{"batb":[[0,1.45,43.68],[1,1.01,15.51],[2,1.01,0]],"batl":[[0,2.04,383.01],[1,2.04,0]],"ltp":0.0,"tv":0.0,"id":8260126},{"batb":[[1,1.01,15.52],[2,1.01,0]],"batl":[[0,3.45,180.4],[1,3.45,0]],"ltp":0.0,"tv":0.0,"id":4486603}]}]}
{"op":"mcm","clk":"1008621527","pt":1580637936347,"mc":[{"id":"1.168224426","rc":[{"batb":[[1,1.41,48.78],[2,1.01,15.51]],"ltp":0.0,"tv":0.0,"id":8260126},{"batb":[[0,2.92,24.71],[1,2.86,10.54],[2,2.74,11.8]],"ltp":0.0,"tv":0.0,"id":4486603}]}]}
{"op":"mcm","clk":"1008621557","pt":1580637936731,"mc":[{"id":"1.168224426","rc":[{"batb":[[0,1.47,89.07],[1,1.45,43.67],[2,1.41,48.78]],"batl":[[0,1.58,42.01],[1,2.04,383.01]],"ltp":0.0,"tv":0.0,"id":8260126},{"batb":[[2,2.76,23.53]],"batl":[[0,3.15,19.32],[1,3.45,180.4]],"ltp":0.0,"tv":0.0,"id":4486603}]}]}
{"op":"mcm","clk":"1008622580","pt":1580637949250,"mc":[{"id":"1.168224426","rc":[{"batb":[[1,1.41,48.78],[2,1.01,15.51]],"ltp":0.0,"tv":0.0,"id":8260126},{"batb":[[0,2.86,10.54],[1,2.76,23.53],[2,1.01,15.52]],"ltp":0.0,"tv":0.0,"id":4486603}]}]}
{"op":"mcm","clk":"1008622618","pt":1580637949719,"mc":[{"id":"1.168224426","rc":[{"batb":[[0,1.41,48.79],[1,1.01,15.51],[2,1.01,0]],"batl":[[0,2.04,383.01],[1,2.04,0]],"ltp":0.0,"tv":0.0,"id":8260126},{"batb":[[1,1.01,15.52],[2,1.01,0]],"batl":[[0,3.45,180.4],[1,3.45,0]],"ltp":0.0,"tv":0.0,"id":4486603}]}]}
{"op":"mcm","clk":"1008624627","pt":1580637974108,"mc":[{"id":"1.168224426","rc":[{"trd":[[1.48,0.01]],"batb":[[0,1.41,48.78],[1,1.37,55.31],[2,1.01,15.51]],"ltp":1.48,"tv":0.01,"id":8260126},{"trd":[[3.1,0]],"batb":[[0,3.1,21.48],[1,2.98,23.37],[2,1.01,15.52]],"ltp":3.1,"tv":0.0,"id":4486603}],"tv":0.01}]}
{"op":"mcm","clk":"1008624693","pt":1580637975094,"mc":[{"id":"1.168224426","rc":[{"batb":[[0,1.45,93.26],[1,1.41,48.78],[2,1.37,55.31]],"batl":[[0,1.56,42.01],[1,2.04,383.01]],"ltp":1.48,"tv":0.01,"id":8260126},{"batb":[[2,2.82,22.69]],"batl":[[0,3.25,18.48]],"ltp":3.1,"tv":0.0,"id":4486603}]}]}
{"op":"mcm","clk":"1008624776","pt":1580637976133,"mc":[{"id":"1.168224426","rc":[{"batl":[[1,3.9,158.24]],"ltp":3.1,"tv":0.0,"id":4486603}]}]}
{"op":"mcm","clk":"1008625364","pt":1580637983114,"mc":[{"id":"1.168224426","rc":[{"batb":[[1,1.37,55.31],[2,1.01,15.51]],"ltp":1.48,"tv":0.01,"id":8260126},{"batb":[[0,2.98,23.37],[1,2.82,22.69],[2,1.01,15.52]],"ltp":3.1,"tv":0.0,"id":4486603}]}]}
{"op":"mcm","clk":"1008625440","pt":1580637984149,"mc":[{"id":"1.168224426","rc":[{"batb":[[0,1.37,55.31],[1,1.01,15.51],[2,1.01,0]],"batl":[[0,2.04,383.01],[1,2.04,0]],"ltp":1.48,"tv":0.01,"id":8260126},{"batb":[[1,1.01,15.52],[2,1.01,0]],"batl":[[0,3.9,158.24],[1,3.9,0]],"ltp":3.1,"tv":0.0,"id":4486603}]}]}
{"op":"mcm","clk":"1008626789","pt":1580638001448,"mc":[{"id":"1.168224426","rc":[{"batb":[[0,1.43,281.6],[1,1.42,219.71],[2,1.37,55.31]],"batl":[[0,1.48,257.38],[1,1.49,174.58],[2,2.04,383.01]],"ltp":1.48,"tv":0.01,"id":8260126},{"batb":[[0,3.3,18.18],[1,2.98,23.37],[2,2.84,10.7]],"ltp":3.1,"tv":0.0,"id":4486603}]}]}
{"op":"mcm","clk":"1008626805","pt":1580638001654,"mc":[{"id":"1.168224426","rc":[{"batb":[[1,2.84,10.7],[2,1.01,15.52]],"ltp":3.1,"tv":0.0,"id":4486603}]}]}
{"op":"mcm","clk":"1008626909","pt":1580638003057,"mc":[{"id":"1.168224426","rc":[{"trd":[[3.3,35.29]],"batb":[[0,2.84,11.23],[1,1.01,15.52],[2,1.01,0]],"ltp":3.3,"tv":35.29,"id":4486603}],"tv":35.3}]}
{"op":"mcm","clk":"1008627086","pt":1580638005143,"mc":[{"id":"1.168224426","rc":[{"batb":[[0,2.98,21.54],[1,2.84,10.7],[2,1.01,15.52]],"batl":[[0,3.35,17.64],[1,3.9,158.24]],"ltp":3.3,"tv":35.29,"id":4486603}]}]}
{"op":"mcm","clk":"1008627185","pt":1580638006347,"mc":[{"id":"1.168224426","rc":[{"batb":[[1,1.42,319.69]],"ltp":1.48,"tv":0.01,"id":8260126},{"trd":[[3.3,36.35]],"batb":[[0,2.98,21]],"ltp":3.3,"tv":36.35,"id":4486603}],"tv":36.36}]}
{"op":"mcm","clk":"1008627192","pt":1580638006457,"mc":[{"id":"1.168224426","rc":[{"batl":[[2,1.51,42.01]],"ltp":1.48,"tv":0.01,"id":8260126}]}]}
{"op":"mcm","clk":"1008627415","pt":1580638009360,"mc":[{"id":"1.168224426","rc":[{"batb":[[2,1.39,53.98]],"ltp":1.48,"tv":0.01,"id":8260126},{"batb":[[0,3.25,18.8],[1,2.98,21],[2,2.84,10.7]],"ltp":3.3,"tv":36.35,"id":4486603}]}]}
{"op":"mcm","clk":"1008627451","pt":1580638009774,"mc":[{"id":"1.168224426","rc":[{"batb":[[2,2.8,11.02]],"ltp":3.3,"tv":36.35,"id":4486603}]}]}
{"op":"mcm","clk":"1008628065","pt":1580638017271,"mc":[{"id":"1.168224426","rc":[{"trd":[[1.43,168.04]],"batb":[[0,1.43,197.58]],"ltp":1.43,"tv":168.04,"id":8260126}],"tv":204.4}]}
{"op":"mcm","clk":"1008628290","pt":1580638020182,"mc":[{"id":"1.168224426","rc":[{"batb":[[0,1.43,247.95]],"batl":[[0,1.48,289.94]],"ltp":1.43,"tv":168.04,"id":8260126}]}]}
{"op":"mcm","clk":"1008628370","pt":1580638021187,"mc":[{"id":"1.168224426","rc":[{"trd":[[3.25,37.59]],"batb":[[0,2.98,21.01],[1,2.8,11.02],[2,1.01,15.52]],"ltp":3.25,"tv":73.94,"id":4486603}],"tv":241.99}]}
{"op":"mcm","clk":"1008628783","pt":1580638025909,"mc":[{"id":"1.168224426","rc":[{"batb":[[2,1.4,52.48]],"ltp":1.43,"tv":168.04,"id":8260126},{"batb":[[0,3.2,19.43],[1,2.98,21],[2,2.76,11.41]],"ltp":3.25,"tv":73.94,"id":4486603}]}]}
{"op":"mcm","clk":"1008629796","pt":1580638038513,"mc":[{"id":"1.168224426","rc":[{"batb":[[2,1.4,52.32]],"ltp":1.43,"tv":168.04,"id":8260126}]}]}
{"op":"mcm","clk":"1008631112","pt":1580638054921,"mc":[{"id":"1.168224426","rc":[{"batb":[[0,1.43,223.2]],"batl":[[0,1.48,180.79],[1,1.51,42.01],[2,2.04,383.01]],"ltp":1.43,"tv":168.04,"id":8260126}]}]}
{"op":"mcm","clk":"1008631396","pt":1580638057847,"mc":[{"id":"1.168224426","rc":[{"batl":[[0,1.47,133.98],[1,1.48,180.79],[2,1.51,42.01]],"ltp":1.43,"tv":168.04,"id":8260126}]}]}
{"op":"mcm","clk":"1008637060","pt":1580638124238,"mc":[{"id":"1.168224426","rc":[{"batb":[[0,1.42,99.98],[1,1.36,59.48],[2,1.01,15.51]],"batl":[[0,1.51,42.01],[1,2.04,383.01],[2,1.51,0]],"ltp":1.43,"tv":168.04,"id":8260126},{"batb":[[0,2.98,21],[1,2.76,11.41],[2,1.01,15.52]],"ltp":3.25,"tv":73.94,"id":4486603}]}]}
{"op":"mcm","clk":"1008637190","pt":1580638125849,"mc":[{"id":"1.168224426","rc":[{"batb":[[0,1.36,59.48],[1,1.01,15.51],[2,1.01,0]],"batl":[[0,2.04,383.01],[1,2.04,0]],"ltp":1.43,"tv":168.04,"id":8260126},{"batb":[[0,2.76,11.41],[1,1.01,15.52],[2,1.01,0]],"batl":[[0,3.9,158.24],[1,3.9,0]],"ltp":3.25,"tv":73.94,"id":4486603}]}]}
{"op":"mcm","clk":"1008637306","pt":1580638127248,"mc":[{"id":"1.168224426","rc":[{"batb":[[0,1.39,186.97],[1,1.38,249.7],[2,1.36,59.48]],"ltp":1.43,"tv":168.04,"id":8260126}]}]}
{"op":"mcm","clk":"1008637571","pt":1580638130420,"mc":[{"id":"1.168224426","rc":[{"batl":[[0,1.43,254.43],[1,1.44,201.21]],"ltp":1.43,"tv":168.04,"id":8260126},{"batb":[[0,3.4,16.52],[1,3,22.66],[2,2.76,11.41]],"ltp":3.25,"tv":73.94,"id":4486603}]}]}
{"op":"mcm","clk":"1008637594","pt":1580638130735,"mc":[{"id":"1.168224426","rc":[{"batb":[[1,1.38,359.77]],"batl":[[2,1.46,42.01]],"ltp":1.43,"tv":168.04,"id":8260126},{"batb":[[1,3.15,19.32],[2,3,22.66]],"batl":[[0,3.6,15.96],[1,3.9,158.24]],"ltp":3.25,"tv":73.94,"id":4486603}]}]}
{"op":"mcm","clk":"1008638112","pt":1580638137455,"mc":[{"id":"1.168224426","rc":[{"batb":[[0,1.38,110.07],[1,1.36,59.48],[2,1.34,65.54]],"batl":[[0,1.46,42.01],[1,1.89,435.28],[2,1.46,0]],"ltp":1.43,"tv":168.04,"id":8260126}]}]}
{"op":"mcm","clk":"1008638162","pt":1580638138034,"mc":[{"id":"1.168224426","rc":[{"batb":[[0,1.34,65.54],[1,1.01,15.51],[2,1.34,0]],"batl":[[0,1.89,435.28],[1,1.89,0]],"ltp":1.43,"tv":168.04,"id":8260126},{"batb":[[0,3,22.66],[1,1.01,15.52],[2,3,0]],"batl":[[0,3.9,158.24],[1,3.9,0]],"ltp":3.25,"tv":73.94,"id":4486603}]}]}
{"op":"mcm","clk":"1008638347","pt":1580638140419,"mc":[{"id":"1.168224426","rc":[{"batb":[[0,1.36,242.75],[1,1.35,277.87],[2,1.34,65.54]],"batl":[[0,1.5,141.06],[1,1.51,167.11],[2,1.89,435.28]],"ltp":1.43,"tv":168.04,"id":8260126}]}]}
{"op":"mcm","clk":"1008638476","pt":1580638142342,"mc":[{"id":"1.168224426","rc":[{"batb":[[0,1.34,65.54],[1,1.01,15.51],[2,1.34,0]],"batl":[[0,1.89,435.28],[1,1.51,0],[2,1.89,0]],"ltp":1.43,"tv":168.04,"id":8260126}]}]}
{"op":"mcm","clk":"1008638766","pt":1580638145252,"mc":[{"id":"1.168224426","rc":[{"batb":[[0,1.4,261.25],[1,1.39,242.36],[2,1.34,65.54]],"batl":[[0,1.44,161.88],[1,1.45,196.38],[2,1.89,435.28]],"ltp":1.43,"tv":168.04,"id":8260126}]}]}
{"op":"mcm","clk":"1008639017","pt":1580638148129,"mc":[{"id":"1.168224426","rc":[{"batb":[[0,1.34,65.54],[1,1.01,15.51],[2,1.34,0]],"batl":[[0,1.89,435.28],[1,1.45,0],[2,1.89,0]],"ltp":1.43,"tv":168.04,"id":8260126}]}]}
{"op":"mcm","clk":"1008639186","pt":1580638150429,"mc":[{"id":"1.168224426","rc":[{"batb":[[0,1.36,240.02],[1,1.35,277.87],[2,1.34,65.54]],"batl":[[0,1.5,143.57],[1,1.51,167.11],[2,1.89,435.28]],"ltp":1.43,"tv":168.04,"id":8260126}]}]}
{"op":"mcm","clk":"1008639269","pt":1580638151368,"mc":[{"id":"1.168224426","rc":[{"batb":[[0,1.34,65.54],[1,1.01,15.51],[2,1.34,0]],"ltp":1.43,"tv":168.04,"id":8260126}]}]}
{"op":"mcm","clk":"1008639431","pt":1580638153356,"mc":[{"id":"1.168224426","rc":[{"batb":[[0,1.46,156.52],[1,1.45,200.38],[2,1.44,46.74]],"ltp":1.43,"tv":168.04,"id":8260126},{"batb":[[1,2.54,14.32],[2,1.01,15.52]],"ltp":3.25,"tv":73.94,"id":4486603}]}]}
{"op":"mcm","clk":"1008639552","pt":1580638154784,"mc":[{"id":"1.168224426","rc":[{"batb":[[1,1.45,293.64]],"batl":[[2,1.54,42.01]],"ltp":1.43,"tv":168.04,"id":8260126},{"batb":[[1,2.88,21.85],[2,2.54,14.32]],"batl":[[0,3.25,18.48],[1,3.9,158.24]],"ltp":3.25,"tv":73.94,"id":4486603}]}]}
{"op":"mcm","clk":"1008640848","pt":1580638170332,"mc":[{"id":"1.168224426","rc":[{"batb":[[0,1.45,93.26],[1,1.38,55.79],[2,1.01,15.51]],"batl":[[0,1.54,42.01],[1,1.89,435.28],[2,1.54,0]],"ltp":1.43,"tv":168.04,"id":8260126},{"batb":[[0,2.88,21.85],[1,2.54,14.32],[2,1.01,15.52]],"ltp":3.25,"tv":73.94,"id":4486603}]}]}
{"op":"mcm","clk":"1008641014","pt":1580638171982,"mc":[{"id":"1.168224426","rc":[{"batb":[[0,1.38,55.79],[1,1.01,15.51],[2,1.01,0]],"batl":[[0,1.89,435.28],[1,1.89,0]],"ltp":1.43,"tv":168.04,"id":8260126},{"batb":[[0,2.54,14.32],[1,1.01,15.52],[2,1.01,0]],"batl":[[0,3.9,158.24],[1,3.9,0]],"ltp":3.25,"tv":73.94,"id":4486603}]}]}
{"op":"mcm","clk":"1008641118","pt":1580638173184,"mc":[{"id":"1.168224426","rc":[{"batb":[[0,1.4,231.28],[1,1.39,241.99],[2,1.38,55.79]],"batl":[[0,1.66,159.27],[1,1.67,115.84],[2,1.89,435.28]],"ltp":1.43,"tv":168.04,"id":8260126}]}]}
{"op":"mcm","clk":"1008641975","pt":1580638183204,"mc":[{"id":"1.168224426","rc":[{"batb":[[0,1.38,55.79],[1,1.01,15.51],[2,1.38,0]],"ltp":1.43,"tv":168.04,"id":8260126}]}]}
{"op":"mcm","clk":"1008642128","pt":1580638185013,"mc":[{"id":"1.168224426","rc":[{"batl":[[2,1.89,0]],"ltp":1.43,"tv":168.04,"id":8260126}]}]}
{"op":"mcm","clk":"1008642240","pt":1580638186315,"mc":[{"id":"1.168224426","rc":[{"batb":[[0,1.6,211.8],[1,1.59,139.48],[2,1.38,55.79]],"ltp":1.43,"tv":168.04,"id":8260126}]}]}
{"op":"mcm","clk":"1008642312","pt":1580638187199,"mc":[{"id":"1.168224426","rc":[{"batb":[[1,1.59,171.42],[2,1.57,73.1]],"batl":[[2,1.68,42.01]],"ltp":1.43,"tv":168.04,"id":8260126},{"batb":[[1,2.48,27.73],[2,2.02,27.3]],"batl":[[0,2.76,23.53]],"ltp":3.25,"tv":73.94,"id":4486603}]}]}
{"op":"mcm","clk":"1008642445","pt":1580638188915,"mc":[{"id":"1.168224426","rc":[{"batl":[[1,3.15,200.42]],"ltp":3.25,"tv":73.94,"id":4486603}]}]}
{"op":"mcm","clk":"1008644000","pt":1580638208141,"mc":[{"id":"1.168224426","rc":[{"batb":[[0,1.57,73.1],[1,1.48,41.78],[2,1.01,15.51]],"batl":[[0,1.68,42.01],[1,2.22,329.01],[2,1.68,0]],"ltp":1.43,"tv":168.04,"id":8260126},{"batb":[[0,2.48,27.73],[1,2.02,27.3],[2,1.01,15.52]],"ltp":3.25,"tv":73.94,"id":4486603}]}]}
{"op":"mcm","clk":"1008644149","pt":1580638209857,"mc":[{"id":"1.168224426","rc":[{"batb":[[0,1.48,41.78],[1,1.01,15.51],[2,1.01,0]],"batl":[[0,2.22,329.01],[1,2.22,0]],"ltp":1.43,"tv":168.04,"id":8260126},{"batb":[[0,2.02,27.3],[1,1.01,15.52],[2,1.01,0]],"batl":[[0,3.15,200.42],[1,3.15,0]],"ltp":3.25,"tv":73.94,"id":4486603}]}]}
{"op":"mcm","clk":"1008644430","pt":1580638213270,"mc":[{"id":"1.168224426","rc":[{"batb":[[0,1.66,130.86],[1,1.65,121.65],[2,1.48,41.78]],"batl":[[0,1.72,161.53],[1,1.74,203],[2,2.22,329.01]],"ltp":1.43,"tv":168.04,"id":8260126}]}]}
{"op":"mcm","clk":"1008644618","pt":1580638215669,"mc":[{"id":"1.168224426","rc":[{"batb":[[0,1.48,41.78],[1,1.01,15.51],[2,1.48,0]],"batl":[[0,2.22,329.01],[1,1.74,0],[2,2.22,0]],"ltp":1.43,"tv":168.04,"id":8260126},{"batl":[[0,3,213.45]],"ltp":3.25,"tv":73.94,"id":4486603}]}]}
{"op":"mcm","clk":"1008644825","pt":1580638218600,"mc":[{"id":"1.168224426","rc":[{"batb":[[0,1.49,178.89],[1,1.48,225.94],[2,1.01,15.51]],"batl":[[0,2,95.72],[1,2.02,128.06],[2,2.22,329.01]],"ltp":1.43,"tv":168.04,"id":8260126}]}]}
{"op":"mcm","clk":"1008646003","pt":1580638233396,"mc":[{"id":"1.168224426","rc":[{"batl":[[0,2.22,329.01],[1,2.02,0],[2,2.22,0]],"ltp":1.43,"tv":168.04,"id":8260126}]}]}
{"op":"mcm","clk":"1008646225","pt":1580638236430,"mc":[{"id":"1.168224426","rc":[{"batb":[[2,1.39,53.98]],"batl":[[0,1.54,230.75],[1,1.55,150.73]],"ltp":1.43,"tv":168.04,"id":8260126},{"batb":[[0,2.86,10.46],[1,2.28,19.2],[2,2.02,27.3]],"ltp":3.25,"tv":73.94,"id":4486603}]}]}
{"op":"mcm","clk":"1008646292","pt":1580638237320,"mc":[{"id":"1.168224426","rc":[{"batb":[[1,1.48,313.32]],"batl":[[2,1.57,42.01]],"ltp":1.43,"tv":168.04,"id":8260126},{"batb":[[1,2.74,23.53],[2,2.28,19.2]],"batl":[[0,3.1,19.32]],"ltp":3.25,"tv":73.94,"id":4486603}]}]}
{"op":"mcm","clk":"1008646482","pt":1580638239879,"mc":[{"id":"1.168224426","rc":[{"batl":[[1,3.65,170.41]],"ltp":3.25,"tv":73.94,"id":4486603}]}]}
{"op":"mcm","clk":"1008647942","pt":1580638259158,"mc":[{"id":"1.168224426","rc":[{"batb":[[0,1.48,87.38],[1,1.39,53.98],[2,1.01,15.51]],"batl":[[0,1.57,42.01],[1,2.04,383.01],[2,1.57,0]],"ltp":1.43,"tv":168.04,"id":8260126},{"batb":[[0,2.74,23.53],[1,2.28,19.2],[2,1.01,15.52]],"ltp":3.25,"tv":73.94,"id":4486603}]}]}
{"op":"mcm","clk":"1008648008","pt":1580638259935,"mc":[{"id":"1.168224426","rc":[{"batb":[[0,1.39,53.98],[1,1.01,15.51],[2,1.01,0]],"batl":[[0,2.04,383.01],[1,2.04,0]],"ltp":1.43,"tv":168.04,"id":8260126},{"batb":[[0,2.28,19.2],[1,1.01,15.52],[2,1.01,0]],"batl":[[0,3.65,170.41],[1,3.65,0]],"ltp":3.25,"tv":73.94,"id":4486603}]}]}
{"op":"mcm","clk":"1008648140","pt":1580638261759,"mc":[{"id":"1.168224426","rc":[{"batb":[[0,1.4,273.48],[1,1.39,296.34],[2,1.01,15.51]],"batl":[[0,1.79,146.33],[1,1.81,178.77],[2,2.04,383.01]],"ltp":1.43,"tv":168.04,"id":8260126}]}]}
{"op":"mcm","clk":"1008648226","pt":1580638262866,"mc":[{"id":"1.168224426","rc":[{"batl":[[0,2.04,383.01],[1,1.81,0],[2,2.04,0]],"ltp":1.43,"tv":168.04,"id":8260126}]}]}
{"op":"mcm","clk":"1008648541","pt":1580638266257,"mc":[{"id":"1.168224426","rc":[{"batb":[[2,1.35,62.55]],"batl":[[0,1.44,150],[1,1.45,196.39]],"ltp":1.43,"tv":168.04,"id":8260126},{"batb":[[0,3.25,18.8],[1,2.8,11.02],[2,2.28,19.2]],"ltp":3.25,"tv":73.94,"id":4486603}]}]}
{"op":"mcm","clk":"1008648590","pt":1580638266829,"mc":[{"id":"1.168224426","rc":[{"batb":[[1,1.39,403.88]],"batl":[[2,1.47,42.01]],"ltp":1.43,"tv":168.04,"id":8260126},{"batb":[[1,3.1,19.32],[2,2.8,11.02]],"batl":[[0,3.55,15.96]],"ltp":3.25,"tv":73.94,"id":4486603}]}]}
{"op":"mcm","clk":"1008648701","pt":1580638268222,"mc":[{"id":"1.168224426","rc":[{"batl":[[1,4.2,148.03]],"ltp":3.25,"tv":73.94,"id":4486603}]}]}
{"op":"mcm","clk":"1008649423","pt":1580638276449,"mc":[{"id":"1.168224426","rc":[{"batb":[[0,1.35,62.55],[1,1.01,15.51],[2,1.35,0]],"batl":[[0,1.89,435.28],[1,1.45,0],[2,1.47,0]],"ltp":1.43,"tv":168.04,"id":8260126},{"batb":[[0,2.8,11.02],[1,1.01,15.52],[2,2.8,0]],"batl":[[0,4.2,148.03],[1,4.2,0]],"ltp":3.25,"tv":73.94,"id":4486603}]}]}
{"op":"mcm","clk":"1008649634","pt":1580638278701,"mc":[{"id":"1.168224426","rc":[{"batb":[[0,1.36,268.88],[1,1.35,341.06],[2,1.01,15.51]],"batl":[[0,1.55,161.63],[1,1.56,147.52],[2,1.89,435.28]],"ltp":1.43,"tv":168.04,"id":8260126}]}]}
{"op":"mcm","clk":"1008649746","pt":1580638279999,"mc":[{"id":"1.168224426","rc":[{"batl":[[0,1.89,435.28],[1,1.56,0],[2,1.89,0]],"ltp":1.43,"tv":168.04,"id":8260126}]}]}
{"op":"mcm","clk":"1008650079","pt":1580638283382,"mc":[{"id":"1.168224426","rc":[{"batb":[[2,1.34,123.51]],"batl":[[0,1.4,256.88],[1,1.41,219.86],[2,1.42,42.01]],"ltp":1.43,"tv":168.04,"id":8260126},{"batb":[[0,3.5,15.42],[1,3.4,16.8],[2,3.2,19.67]],"batl":[[0,3.9,14.28],[1,4.2,148.03]],"ltp":3.25,"tv":73.94,"id":4486603}]}]}
{"op":"mcm","clk":"1008651606","pt":1580638300128,"mc":[{"id":"1.168224426","rc":[{"batb":[[1,1.35,340.12]],"ltp":1.43,"tv":168.04,"id":8260126},{"batb":[[2,3.15,20.06]],"ltp":3.25,"tv":73.94,"id":4486603}]}]}
{"op":"mcm","clk":"1008653831","pt":1580638319733,"mc":[{"id":"1.168224426","rc":[{"batb":[[0,1.35,61.61],[1,1.34,123.51],[2,1.28,82.62]],"batl":[[0,1.42,42.01],[1,1.89,435.28],[2,1.42,0]],"ltp":1.43,"tv":168.04,"id":8260126}]}]}
{"op":"mcm","clk":"1008654233","pt":1580638323202,"mc":[{"id":"1.168224426","rc":[{"batb":[[0,1.34,123.51],[1,1.29,188.73],[2,1.28,448.6]],"batl":[[1,1.45,140.57],[2,1.46,190.58]],"ltp":1.43,"tv":168.04,"id":8260126},{"batb":[[0,3.4,16.8],[1,3.15,20.06],[2,1.01,15.52]],"ltp":3.25,"tv":73.94,"id":4486603}]}]}
{"op":"mcm","clk":"1008654323","pt":1580638323929,"mc":[{"id":"1.168224426","rc":[{"batb":[[0,1.29,188.73],[1,1.28,448.6],[2,1.01,15.51]],"batl":[[0,1.45,140.57],[1,1.46,190.58],[2,1.89,435.28]],"ltp":1.43,"tv":168.04,"id":8260126},{"batb":[[0,3.15,20.06],[1,1.01,15.52],[2,1.01,0]],"batl":[[0,4.2,148.03],[1,4.2,0]],"ltp":3.25,"tv":73.94,"id":4486603}]}]}
{"op":"mcm","clk":"1008654581","pt":1580638326228,"mc":[{"id":"1.168224426","rc":[{"batb":[[0,1.28,82.62],[1,1.01,15.51],[2,1.01,0]],"batl":[[0,1.89,435.28],[1,1.46,0],[2,1.89,0]],"ltp":1.43,"tv":168.04,"id":8260126}]}]}
{"op":"mcm","clk":"1008654907","pt":1580638329331,"mc":[{"id":"1.168224426","rc":[{"batb":[[0,1.34,416.63],[1,1.33,301.61],[2,1.28,82.62]],"batl":[[0,1.38,180.93],[1,1.39,235.12],[2,1.89,435.28]],"ltp":1.43,"tv":168.04,"id":8260126}]}]}
{"op":"mcm","clk":"1008655303","pt":1580638333107,"mc":[{"id":"1.168224426","rc":[{"batb":[[0,1.28,82.62],[1,1.01,15.51],[2,1.28,0]],"batl":[[0,1.89,435.28],[1,1.39,0],[2,1.89,0]],"ltp":1.43,"tv":168.04,"id":8260126}]}]}
{"op":"mcm","clk":"1008655717","pt":1580638336413,"mc":[{"id":"1.168224426","rc":[{"batb":[[0,1.29,196.7],[1,1.28,448.62],[2,1.01,15.51]],"ltp":1.43,"tv":168.04,"id":8260126}]}]}
{"op":"mcm","clk":"1008656036","pt":1580638339239,"mc":[{"id":"1.168224426","rc":[{"batl":[[0,1.32,285.73],[1,1.33,287.97]],"ltp":1.43,"tv":168.04,"id":8260126}]}]}
{"op":"mcm","clk":"1008656166","pt":1580638340443,"mc":[{"id":"1.168224426","rc":[{"batb":[[2,1.19,126.13]],"ltp":1.43,"tv":168.04,"id":8260126},{"batb":[[0,4.1,21.17],[1,3.6,14.48],[2,1.01,15.52]],"ltp":3.25,"tv":73.94,"id":4486603}]}]}
{"op":"mcm","clk":"1008656262","pt":1580638341233,"mc":[{"id":"1.168224426","rc":[{"batb":[[1,1.28,598.17]],"batl":[[2,1.34,42.01]],"ltp":1.43,"tv":168.04,"id":8260126},{"batb":[[1,3.9,14.28],[2,3.6,14.48]],"batl":[[0,4.5,11.76]],"ltp":3.25,"tv":73.94,"id":4486603}]}]}
{"op":"mcm","clk":"1008656441","pt":1580638342843,"mc":[{"id":"1.168224426","rc":[{"batl":[[1,5.5,115.06]],"ltp":3.25,"tv":73.94,"id":4486603}]}]}
{"op":"mcm","clk":"1008657285","pt":1580638350137,"mc":[{"id":"1.168224426","rc":[{"batb":[[0,1.28,232.17],[1,1.19,126.13],[2,1.01,15.51]],"batl":[[0,1.34,42.01],[1,1.71,542.06],[2,1.34,0]],"ltp":1.43,"tv":168.04,"id":8260126}]}]}
{"op":"mcm","clk":"1008657340","pt":1580638350659,"mc":[{"id":"1.168224426","rc":[{"batb":[[0,1.28,149.55]],"ltp":1.43,"tv":168.04,"id":8260126},{"batb":[[0,3.9,14.28],[1,3.6,14.48],[2,1.01,15.52]],"ltp":3.25,"tv":73.94,"id":4486603}]}]}
{"op":"mcm","clk":"1008657512","pt":1580638352273,"mc":[{"id":"1.168224426","rc":[{"batb":[[0,1.19,126.13],[1,1.01,15.51],[2,1.01,0]],"batl":[[0,1.71,542.06],[1,1.71,0]],"ltp":1.43,"tv":168.04,"id":8260126},{"batb":[[0,3.6,14.48],[1,1.01,15.52],[2,1.01,0]],"batl":[[0,5.5,115.06],[1,5.5,0]],"ltp":3.25,"tv":73.94,"id":4486603}]}]}
{"op":"mcm","clk":"1008657848","pt":1580638355354,"mc":[{"id":"1.168224426","rc":[{"batb":[[0,1.27,300.91],[1,1.26,402.97],[2,1.19,126.13]],"batl":[[0,1.3,263.39],[1,1.31,311.34],[2,1.71,542.06]],"ltp":1.43,"tv":168.04,"id":8260126}]}]}
{"op":"mcm","clk":"1008657939","pt":1580638356182,"mc":[{"id":"1.168224426","rc":[{"batb":[[0,1.19,126.13],[1,1.01,15.51],[2,1.19,0]],"batl":[[0,1.71,542.06],[1,1.31,0],[2,1.71,0]],"ltp":1.43,"tv":168.04,"id":8260126}]}]}
{"op":"mcm","clk":"1008658260","pt":1580638359362,"mc":[{"id":"1.168224426","rc":[{"batb":[[0,1.2,628.71],[1,1.19,561.5],[2,1.01,15.51]],"batl":[[0,1.38,160.39],[1,1.39,235.28],[2,1.71,542.06]],"ltp":1.43,"tv":168.04,"id":8260126}]}]}
{"op":"mcm","clk":"1008658801","pt":1580638365173,"mc":[{"id":"1.168224426","rc":[{"batl":[[0,1.71,542.06],[1,1.39,0],[2,1.71,0]],"ltp":1.43,"tv":168.04,"id":8260126}]}]}
{"op":"mcm","clk":"1008659107","pt":1580638368344,"mc":[{"id":"1.168224426","rc":[{"batl":[[0,1.23,347.31],[1,1.24,421.25]],"ltp":1.43,"tv":168.04,"id":8260126}]}]}
{"op":"mcm","clk":"1008659178","pt":1580638369099,"mc":[{"id":"1.168224426","rc":[{"batb":[[0,1.21,168.04],[1,1.2,628.71],[2,1.19,561.5]],"batl":[[2,1.26,42.01]],"ltp":1.43,"tv":168.04,"id":8260126},{"batb":[[0,5.4,11.25],[1,4.8,10.92],[2,4.4,17.7]],"batl":[[0,5.7,8.4]],"ltp":3.25,"tv":73.94,"id":4486603}]}]}
{"op":"mcm","clk":"1008659386","pt":1580638371186,"mc":[{"id":"1.168224426","rc":[{"batl":[[1,7.2,92.18]],"ltp":3.25,"tv":73.94,"id":4486603}]}]}
{"op":"mcm","clk":"1008660174","pt":1580638380215,"mc":[{"id":"1.168224426","rc":[{"batb":[[0,1.11,213.07],[1,1.01,15.51],[2,1.19,0]],"batl":[[0,1.58,650.58],[1,1.24,0],[2,1.26,0]],"ltp":1.43,"tv":168.04,"id":8260126},{"batb":[[0,4.4,17.7],[1,1.01,15.52],[2,4.4,0]],"batl":[[0,7.2,92.18],[1,7.2,0]],"ltp":3.25,"tv":73.94,"id":4486603}]}]}
{"op":"mcm","clk":"1008660374","pt":1580638382391,"mc":[{"id":"1.168224426","rc":[{"batb":[[0,1.13,398],[1,1.12,734.65],[2,1.11,213.07]],"batl":[[0,1.29,297.44],[1,1.3,323.49],[2,1.58,650.58]],"ltp":1.43,"tv":168.04,"id":8260126}]}]}
{"op":"mcm","clk":"1008660936","pt":1580638388914,"mc":[{"id":"1.168224426","rc":[{"batl":[[0,1.58,650.58],[1,1.3,0],[2,1.58,0]],"ltp":1.43,"tv":168.04,"id":8260126}]}]}
{"op":"mcm","clk":"1008661252","pt":1580638392221,"mc":[{"id":"1.168224426","rc":[{"batl":[[0,1.15,647.36],[1,1.16,455.24]],"ltp":1.43,"tv":168.04,"id":8260126},{"batb":[[0,7.6,9.91],[1,6.2,15.5],[2,4.4,17.7]],"ltp":3.25,"tv":73.94,"id":4486603}]}]}
{"op":"mcm","clk":"1008661316","pt":1580638392837,"mc":[{"id":"1.168224426","rc":[{"batl":[[2,1.18,42.01]],"ltp":1.43,"tv":168.04,"id":8260126},{"batb":[[1,6.4,7.56],[2,6.2,15.5]],"batl":[[0,7.8,5.88]],"ltp":3.25,"tv":73.94,"id":4486603}]}]}
{"op":"mcm","clk":"1008661532","pt":1580638395122,"mc":[{"id":"1.168224426","rc":[{"batl":[[1,11.5,70.11]],"ltp":3.25,"tv":73.94,"id":4486603}]}]}
{"op":"mcm","clk":"1008662296","pt":1580638403244,"mc":[{"id":"1.168224426","rc":[{"batb":[[0,1.07,350.29],[1,1.01,15.51],[2,1.11,0]],"batl":[[0,1.18,42.01],[1,1.47,803.22],[2,1.18,0]],"ltp":1.43,"tv":168.04,"id":8260126},{"batb":[[0,6.4,7.56],[1,6.2,15.5],[2,1.01,15.52]],"ltp":3.25,"tv":73.94,"id":4486603}]}]}
{"op":"mcm","clk":"1008662396","pt":1580638404343,"mc":[{"id":"1.168224426","rc":[{"batl":[[0,1.47,803.22],[1,1.47,0]],"ltp":1.43,"tv":168.04,"id":8260126},{"batb":[[0,6.2,15.5],[1,1.01,15.52],[2,1.01,0]],"batl":[[0,11.5,70.11],[1,11.5,0]],"ltp":3.25,"tv":73.94,"id":4486603}]}]}
{"op":"mcm","clk":"1008662556","pt":1580638405952,"mc":[{"id":"1.168224426","rc":[{"batl":[[0,1.19,710.69],[1,1.2,355.68],[2,1.47,803.22]],"ltp":1.43,"tv":168.04,"id":8260126}]}]}
{"op":"mcm","clk":"1008662760","pt":1580638408333,"mc":[{"id":"1.168224426","rc":[{"batb":[[0,1.16,627.45],[1,1.15,473.65],[2,1.07,350.29]],"ltp":1.43,"tv":168.04,"id":8260126}]}]}
{"op":"mcm","clk":"1008662803","pt":1580638408851,"mc":[{"id":"1.168224426","rc":[{"batb":[[0,1.17,168.04],[1,1.16,627.45],[2,1.15,635.26]],"batl":[[2,1.22,42.01]],"ltp":1.43,"tv":168.04,"id":8260126},{"batb":[[1,5.7,8.4],[2,5,13.45]],"batl":[[0,6.8,6.72]],"ltp":3.25,"tv":73.94,"id":4486603}]}]}
{"op":"mcm","clk":"1008663090","pt":1580638412042,"mc":[{"id":"1.168224426","rc":[{"batl":[[1,9.8,75.27]],"ltp":3.25,"tv":73.94,"id":4486603}]}]}
{"op":"mcm","clk":"1008663829","pt":1580638420327,"mc":[{"id":"1.168224426","rc":[{"batb":[[1,1.15,161.61],[2,1.07,333.14]],"batl":[[0,1.22,42.01],[1,1.47,803.22],[2,1.22,0]],"ltp":1.43,"tv":168.04,"id":8260126}]}]}
{"op":"mcm","clk":"1008663844","pt":1580638420549,"mc":[{"id":"1.168224426","rc":[{"batb":[[1,1.07,333.14],[2,1.01,15.51]],"ltp":1.43,"tv":168.04,"id":8260126},{"batb":[[0,5.7,8.4],[1,5,13.45],[2,1.01,15.52]],"ltp":3.25,"tv":73.94,"id":4486603}]}]}
{"op":"mcm","clk":"1008663950","pt":1580638421855,"mc":[{"id":"1.168224426","rc":[{"batb":[[0,1.07,333.14],[1,1.01,15.51],[2,1.01,0]],"batl":[[0,1.47,803.22],[1,1.47,0]],"ltp":1.43,"tv":168.04,"id":8260126},{"batb":[[0,5,13.45],[1,1.01,15.52],[2,1.01,0]],"batl":[[0,9.8,75.27],[1,9.8,0]],"ltp":3.25,"tv":73.94,"id":4486603}]}]}
{"op":"mcm","clk":"1008664084","pt":1580638423266,"mc":[{"id":"1.168224426","rc":[{"batb":[[0,1.08,1178.29],[1,1.07,333.14],[2,1.01,15.51]],"batl":[[0,1.25,412.71],[1,1.26,381.63]],"ltp":1.43,"tv":168.04,"id":8260126}]}]}
{"op":"mcm","clk":"1008664144","pt":1580638423942,"mc":[{"id":"1.168224426","rc":[{"batb":[[0,1.07,333.14],[1,1.01,15.51],[2,1.01,0]],"ltp":1.43,"tv":168.04,"id":8260126}]}]}
{"op":"mcm","clk":"1008664427","pt":1580638427329,"mc":[{"id":"1.168224426","rc":[{"batb":[[0,1.14,973.26],[1,1.07,333.14],[2,1.01,15.51]],"batl":[[0,1.17,667.91],[1,1.18,416.17]],"ltp":1.43,"tv":168.04,"id":8260126}]}]}
{"op":"mcm","clk":"1008664632","pt":1580638429952,"mc":[{"id":"1.168224426","rc":[{"batb":[[0,1.07,333.14],[1,1.01,15.51],[2,1.01,0]],"ltp":1.43,"tv":168.04,"id":8260126}]}]}
{"op":"mcm","clk":"1008664872","pt":1580638432876,"mc":[{"id":"1.168224426","rc":[{"batb":[[0,1.08,1178.29],[1,1.07,333.14],[2,1.01,15.51]],"batl":[[0,1.25,412.71],[1,1.26,381.63]],"ltp":1.43,"tv":168.04,"id":8260126}]}]}
{"op":"mcm","clk":"1008665686","pt":1580638442912,"mc":[{"id":"1.168224426","rc":[{"batb":[[0,1.07,333.14],[1,1.01,15.51],[2,1.01,0]],"ltp":1.43,"tv":168.04,"id":8260126}]}]}
{"op":"mcm","clk":"1008666008","pt":1580638446413,"mc":[{"id":"1.168224426","rc":[{"batb":[[0,1.22,407.29],[1,1.21,636.19],[2,1.08,1686.88]],"ltp":1.43,"tv":168.04,"id":8260126},{"batb":[[1,3.75,13.22],[2,1.01,15.52]],"ltp":3.25,"tv":73.94,"id":4486603}]}]}
{"op":"mcm","clk":"1008666063","pt":1580638446939,"mc":[{"id":"1.168224426","rc":[{"batb":[[0,1.22,575.33],[2,1.08,314.57]],"batl":[[2,1.28,42.01]],"ltp":1.43,"tv":168.04,"id":8260126},{"batb":[[1,4.7,10.92],[2,3.75,13.22]],"batl":[[0,5.5,9.24]],"ltp":3.25,"tv":73.94,"id":4486603}]}]}
{"op":"mcm","clk":"1008666268","pt":1580638449148,"mc":[{"id":"1.168224426","rc":[{"batl":[[1,7.2,92.18]],"ltp":3.25,"tv":73.94,"id":4486603}]}]}
{"op":"mcm","clk":"1008666866","pt":1580638456443,"mc":[{"id":"1.168224426","rc":[{"batb":[[0,1.22,540.74]],"ltp":1.43,"tv":168.04,"id":8260126}]}]}
{"op":"mcm","clk":"1008667111","pt":1580638459357,"mc":[{"id":"1.168224426","rc":[{"batl":[[0,1.25,446.7]],"ltp":1.43,"tv":168.04,"id":8260126}]}]}
{"op":"mcm","clk":"1008667380","pt":1580638462125,"mc":[{"id":"1.168224426","rc":[{"batb":[[0,1.08,314.57],[1,1.01,15.51],[2,1.08,0]],"batl":[[0,1.58,650.58],[1,1.26,0],[2,1.28,0]],"ltp":1.43,"tv":168.04,"id":8260126},{"batb":[[0,3.75,13.22],[1,1.01,15.52],[2,3.75,0]],"batl":[[0,7.2,92.18],[1,7.2,0]],"ltp":3.25,"tv":73.94,"id":4486603}]}]}
{"op":"mcm","clk":"1008667575","pt":1580638464388,"mc":[{"id":"1.168224426","rc":[{"batb":[[0,1.08,1492.86]],"batl":[[0,1.36,179.86],[1,1.37,251.68]],"ltp":1.43,"tv":168.04,"id":8260126}]}]}
{"op":"mcm","clk":"1008667668","pt":1580638465422,"mc":[{"id":"1.168224426","rc":[{"batb":[[0,1.08,314.57]],"ltp":1.43,"tv":168.04,"id":8260126}]}]}
{"op":"mcm","clk":"1008667835","pt":1580638467218,"mc":[{"id":"1.168224426","rc":[{"batb":[[0,1.19,433.63],[1,1.18,630.47],[2,1.08,314.57]],"batl":[[0,1.22,601.24],[1,1.23,436.89]],"ltp":1.43,"tv":168.04,"id":8260126}]}]}
{"op":"mcm","clk":"1008667927","pt":1580638468329,"mc":[{"id":"1.168224426","rc":[{"batl":[[2,1.56,675.59]],"ltp":1.43,"tv":168.04,"id":8260126},{"batl":[[0,7.8,87.91]],"ltp":3.25,"tv":73.94,"id":4486603}]}]}
{"op":"mcm","clk":"1008668168","pt":1580638471300,"mc":[{"id":"1.168224426","rc":[{"batb":[[0,1.08,314.57],[1,1.01,15.51],[2,1.08,0]],"batl":[[0,1.56,675.59],[1,1.23,0],[2,1.56,0]],"ltp":1.43,"tv":168.04,"id":8260126}]}]}
{"op":"mcm","clk":"1008668425","pt":1580638474044,"mc":[{"id":"1.168224426","rc":[{"batb":[[0,1.08,1492.86]],"batl":[[0,1.36,179.86],[1,1.37,251.68]],"ltp":1.43,"tv":168.04,"id":8260126}]}]}
{"op":"mcm","clk":"1008669337","pt":1580638484062,"mc":[{"id":"1.168224426","rc":[{"batb":[[0,1.08,314.57]],"ltp":1.43,"tv":168.04,"id":8260126}]}]}
{"op":"mcm","clk":"1008669669","pt":1580638487220,"mc":[{"id":"1.168224426","rc":[{"batb":[[0,1.33,183.66],[1,1.32,310.47],[2,1.08,314.57]],"ltp":1.43,"tv":168.04,"id":8260126}]}]}
{"op":"mcm","clk":"1008669750","pt":1580638488049,"mc":[{"id":"1.168224426","rc":[{"batb":[[1,1.32,380.34],[2,1.2,115.98]],"ltp":1.43,"tv":168.04,"id":8260126},{"batb":[[1,3.2,19.43],[2,1.01,15.52]],"ltp":3.25,"tv":73.94,"id":4486603}]}]}
{"op":"mcm","clk":"1008669835","pt":1580638489382,"mc":[{"id":"1.168224426","rc":[{"batb":[[1,1.32,511.41]],"batl":[[2,1.38,42.01]],"ltp":1.43,"tv":168.04,"id":8260126},{"batb":[[1,3.65,15.12],[2,3.2,19.43]],"batl":[[0,4.1,13.44]],"ltp":3.25,"tv":73.94,"id":4486603}]}]}
{"op":"mcm","clk":"1008669928","pt":1580638490289,"mc":[{"id":"1.168224426","rc":[{"batl":[[1,5.3,118.79]],"ltp":3.25,"tv":73.94,"id":4486603}]}]}
{"op":"mcm","clk":"1008670508","pt":1580638496328,"mc":[{"id":"1.168224426","rc":[{"batb":[[0,1.32,200.94],[1,1.2,115.98],[2,1.01,15.51]],"batl":[[0,1.38,42.01],[1,1.73,527.57],[2,1.38,0]],"ltp":1.43,"tv":168.04,"id":8260126}]}]}
{"op":"mcm","clk":"1008670553","pt":1580638496844,"mc":[{"id":"1.168224426","rc":[{"batb":[[0,1.32,131.07]],"ltp":1.43,"tv":168.04,"id":8260126},{"batb":[[0,3.65,15.12],[1,3.2,19.43],[2,1.01,15.52]],"ltp":3.25,"tv":73.94,"id":4486603}]}]}
{"op":"mcm","clk":"1008670692","pt":1580638498248,"mc":[{"id":"1.168224426","rc":[{"batb":[[0,1.2,115.98],[1,1.01,15.51],[2,1.01,0]],"batl":[[0,1.73,527.57],[1,1.73,0]],"ltp":1.43,"tv":168.04,"id":8260126},{"batb":[[0,3.2,19.43],[1,1.01,15.52],[2,1.01,0]],"batl":[[0,5.3,118.79],[1,5.3,0]],"ltp":3.25,"tv":73.94,"id":4486603}]}]}
{"op":"mcm","clk":"1008670802","pt":1580638499246,"mc":[{"id":"1.168224426","rc":[{"batb":[[0,1.22,227.96],[1,1.21,519.82],[2,1.2,115.98]],"batl":[[0,1.45,213.32],[1,1.46,190.21],[2,1.73,527.57]],"ltp":1.43,"tv":168.04,"id":8260126}]}]}
{"op":"mcm","clk":"1008671190","pt":1580638503357,"mc":[{"id":"1.168224426","rc":[{"batl":[[0,1.73,527.57],[1,1.46,0],[2,1.73,0]],"ltp":1.43,"tv":168.04,"id":8260126}]}]}
{"op":"mcm","clk":"1008671465","pt":1580638506351,"mc":[{"id":"1.168224426","rc":[{"batl":[[0,1.24,171.7],[1,1.25,406.81]],"ltp":1.43,"tv":168.04,"id":8260126},{"batb":[[0,5.1,12.83],[1,3.8,12.9],[2,3.2,19.43]],"ltp":3.25,"tv":73.94,"id":4486603}]}]}
{"op":"mcm","clk":"1008671559","pt":1580638507349,"mc":[{"id":"1.168224426","rc":[{"batb":[[0,1.22,396]],"batl":[[2,1.27,42.01]],"ltp":1.43,"tv":168.04,"id":8260126},{"batb":[[1,4.7,10.92],[2,3.8,12.9]],"ltp":3.25,"tv":73.94,"id":4486603}]}]}
{"op":"mcm","clk":"1008671580","pt":1580638507618,"mc":[{"id":"1.168224426","rc":[{"batl":[[0,5.5,9.24]],"ltp":3.25,"tv":73.94,"id":4486603}]}]}
{"op":"mcm","clk":"1008671752","pt":1580638509677,"mc":[{"id":"1.168224426","rc":[{"batl":[[1,7.2,92.18]],"ltp":3.25,"tv":73.94,"id":4486603}]}]}
{"op":"mcm","clk":"1008672970","pt":1580638523411,"mc":[{"id":"1.168224426","rc":[{"batb":[[0,1.22,168.04],[1,1.07,322.75],[2,1.01,15.51]],"batl":[[0,1.27,42.01],[1,1.58,650.58],[2,1.27,0]],"ltp":1.43,"tv":168.04,"id":8260126},{"batb":[[0,4.7,10.92],[1,3.8,12.9],[2,1.01,15.52]],"ltp":3.25,"tv":73.94,"id":4486603}]}]}
{"op":"mcm","clk":"1008673029","pt":1580638523996,"mc":[{"id":"1.168224426","rc":[{"batb":[[0,1.07,322.75],[1,1.01,15.51],[2,1.01,0]],"batl":[[0,1.58,650.58],[1,1.58,0]],"ltp":1.43,"tv":168.04,"id":8260126},{"batb":[[0,3.8,12.9],[1,1.01,15.52],[2,1.01,0]],"batl":[[0,7.2,92.18],[1,7.2,0]],"ltp":3.25,"tv":73.94,"id":4486603}]}]}
{"op":"mcm","clk":"1008673252","pt":1580638526395,"mc":[{"id":"1.168224426","rc":[{"batl":[[0,1.36,295.08],[1,1.37,250.18]],"ltp":1.43,"tv":168.04,"id":8260126}]}]}
{"op":"mcm","clk":"1008673512","pt":1580638529420,"mc":[{"id":"1.168224426","rc":[{"batb":[[0,1.32,369.83],[1,1.31,326.07],[2,1.07,322.75]],"ltp":1.43,"tv":168.04,"id":8260126}]}]}
{"op":"mcm","clk":"1008673580","pt":1580638530095,"mc":[{"id":"1.168224426","rc":[{"batb":[[1,1.31,397.91],[2,1.2,117]],"ltp":1.43,"tv":168.04,"id":8260126},{"batb":[[1,3.25,18.96],[2,1.01,15.52]],"ltp":3.25,"tv":73.94,"id":4486603}]}]}
{"op":"mcm","clk":"1008673680","pt":1580638531295,"mc":[{"id":"1.168224426","rc":[{"batb":[[1,1.31,533.18]],"ltp":1.43,"tv":168.04,"id":8260126},{"batb":[[1,3.65,15.12],[2,3.25,18.96]],"batl":[[0,4.2,12.6]],"ltp":3.25,"tv":73.94,"id":4486603}]}]}
{"op":"mcm","clk":"1008673775","pt":1580638532398,"mc":[{"id":"1.168224426","rc":[{"batl":[[2,1.73,527.57]],"ltp":1.43,"tv":168.04,"id":8260126},{"batl":[[1,5.3,118.79]],"ltp":3.25,"tv":73.94,"id":4486603}]}]}
{"op":"mcm","clk":"1008674082","pt":1580638535438,"mc":[{"id":"1.168224426","rc":[{"batl":[[2,1.38,42.01]],"ltp":1.43,"tv":168.04,"id":8260126}]}]}
{"op":"mcm","clk":"1008674451","pt":1580638539305,"mc":[{"id":"1.168224426","rc":[{"batb":[[0,1.31,207.11],[1,1.2,117],[2,1.01,15.51]],"batl":[[0,1.38,42.01],[1,1.73,527.57],[2,1.38,0]],"ltp":1.43,"tv":168.04,"id":8260126}]}]}
{"op":"mcm","clk":"1008674502","pt":1580638539938,"mc":[{"id":"1.168224426","rc":[{"batb":[[0,1.2,117],[1,1.01,15.51],[2,1.01,0]],"batl":[[0,1.73,527.57],[1,1.73,0]],"ltp":1.43,"tv":168.04,"id":8260126},{"batb":[[0,3.25,18.96],[1,1.01,15.52],[2,3.25,0]],"batl":[[0,5.3,118.79],[1,5.3,0]],"ltp":3.25,"tv":73.94,"id":4486603}]}]}
{"op":"mcm","clk":"1008674703","pt":1580638542248,"mc":[{"id":"1.168224426","rc":[{"batb":[[0,1.21,605.52],[1,1.2,566.89],[2,1.01,15.51]],"batl":[[0,1.45,310.7],[1,1.46,189.38],[2,1.73,527.57]],"ltp":1.43,"tv":168.04,"id":8260126}]}]}
{"op":"mcm","clk":"1008675006","pt":1580638545833,"mc":[{"id":"1.168224426","rc":[{"batl":[[0,1.73,527.57],[1,1.46,0],[2,1.73,0]],"ltp":1.43,"tv":168.04,"id":8260126}]}]}
{"op":"mcm","clk":"1008675247","pt":1580638548435,"mc":[{"id":"1.168224426","rc":[{"batl":[[0,1.24,301.13],[1,1.25,403.59]],"ltp":1.43,"tv":168.04,"id":8260126}]}]}
{"op":"mcm","clk":"1008675308","pt":1580638549219,"mc":[{"id":"1.168224426","rc":[{"batb":[[0,1.22,168.04],[1,1.21,605.52],[2,1.2,566.89]],"batl":[[2,1.27,42.01]],"ltp":1.43,"tv":168.04,"id":8260126},{"batb":[[0,5.1,12.67],[1,4.7,10.92],[2,3.8,25.41]],"batl":[[0,5.5,9.24]],"ltp":3.25,"tv":73.94,"id":4486603}]}]}
{"op":"mcm","clk":"1008675529","pt":1580638552244,"mc":[{"id":"1.168224426","rc":[{"batl":[[1,7.2,92.18]],"ltp":3.25,"tv":73.94,"id":4486603}]}]}
{"op":"mcm","clk":"1008676308","pt":1580638562301,"mc":[{"id":"1.168224426","rc":[{"batb":[[0,1.07,324.17],[1,1.01,15.51],[2,1.2,0]],"batl":[[0,1.58,650.58],[1,1.25,0],[2,1.27,0]],"ltp":1.43,"tv":168.04,"id":8260126},{"batb":[[0,3.8,25.41],[1,1.01,15.52],[2,3.8,0]],"batl":[[0,7.2,92.18],[1,7.2,0]],"ltp":3.25,"tv":73.94,"id":4486603}]}]}
{"op":"mcm","clk":"1008676513","pt":1580638564911,"mc":[{"id":"1.168224426","rc":[{"batb":[[0,1.08,1178.29],[1,1.07,324.17],[2,1.01,15.51]],"batl":[[0,1.35,145.91],[1,1.36,260.96]],"ltp":1.43,"tv":168.04,"id":8260126}]}]}
{"op":"mcm","clk":"1008677025","pt":1580638570380,"mc":[{"id":"1.168224426","rc":[{"batb":[[2,1.06,407.81]],"batl":[[0,1.1,811.38],[1,1.11,344.85]],"ltp":1.43,"tv":168.04,"id":8260126},{"batb":[[0,10,12.59],[1,7.6,9.84],[2,3.8,25.41]],"ltp":3.25,"tv":73.94,"id":4486603}]}]}
{"op":"mcm","clk":"1008677109","pt":1580638571381,"mc":[{"id":"1.168224426","rc":[{"batl":[[2,1.38,972.97]],"ltp":1.43,"tv":168.04,"id":8260126},{"batb":[[1,9,5.04],[2,7.6,9.84]],"batl":[[0,11.5,3.36],[1,21,53.48]],"ltp":3.25,"tv":73.94,"id":4486603}]}]}
{"op":"mcm","clk":"1008677349","pt":1580638574706,"mc":[{"id":"1.168224426","rc":[{"batl":[[1,1.11,288.52]],"ltp":1.43,"tv":168.04,"id":8260126}]}]}
{"op":"mcm","clk":"1008677601","pt":1580638578000,"mc":[{"id":"1.168224426","rc":[{"batl":[[0,1.1,868.22]],"ltp":1.43,"tv":168.04,"id":8260126}]}]}
{"op":"mcm","clk":"1008679248","pt":1580638598855,"mc":[{"id":"1.168224426","rc":[{"batb":[[0,1.06,407.81],[1,1.01,15.51],[2,1.06,0]],"batl":[[0,1.38,972.97],[1,1.11,0],[2,1.38,0]],"ltp":1.43,"tv":168.04,"id":8260126},{"batb":[[0,9,5.04],[1,7.6,9.84],[2,1.01,15.52]],"ltp":3.25,"tv":73.94,"id":4486603}]}]}
{"op":"mcm","clk":"1008679349","pt":1580638600059,"mc":[{"id":"1.168224426","rc":[{"batb":[[0,7.6,9.84],[1,1.01,15.52],[2,1.01,0]],"batl":[[0,21,53.48],[1,21,0]],"ltp":3.25,"tv":73.94,"id":4486603}]}]}
{"op":"mcm","clk":"1008679467","pt":1580638601429,"mc":[{"id":"1.168224426","rc":[{"batb":[[0,1.07,556.2],[1,1.06,1049.47],[2,1.01,15.51]],"batl":[[0,1.14,770.31],[1,1.15,345.34],[2,1.38,972.97]],"ltp":1.43,"tv":168.04,"id":8260126}]}]}
{"op":"mcm","clk":"1008679485","pt":1580638601634,"mc":[{"id":"1.168224426","rc":[{"batl":[[0,1.38,972.97],[1,1.15,0],[2,1.38,0]],"ltp":1.43,"tv":168.04,"id":8260126}]}]}
{"op":"mcm","clk":"1008679806","pt":1580638605270,"mc":[{"id":"1.168224426","rc":[{"trd":[[1.08,378.09]],"batb":[[1,1.06,971.05],[2,1.04,495.22]],"batl":[[0,1.08,258.58],[1,1.09,705.67],[2,1.38,972.97]],"ltp":1.08,"tv":546.13,"id":8260126},{"trd":[[13.5,3.36]],"batb":[[0,12,8.5],[1,9.2,16.05],[2,1.01,15.52]],"ltp":13.5,"tv":77.3,"id":4486603}],"tv":623.44}]}
{"op":"mcm","clk":"1008679916","pt":1580638606254,"mc":[{"id":"1.168224426","rc":[{"batl":[[1,1.09,714.76]],"ltp":1.08,"tv":546.13,"id":8260126}]}]}
{"op":"mcm","clk":"1008680018","pt":1580638607455,"mc":[{"id":"1.168224426","rc":[{"batl":[[0,24,50.52]],"ltp":13.5,"tv":77.3,"id":4486603}]}]}
{"op":"mcm","clk":"1008680084","pt":1580638608284,"mc":[{"id":"1.168224426","rc":[{"batb":[[0,1.07,633.89]],"batl":[[0,1.08,391.7],[1,1.09,790.98],[2,1.1,42.01]],"ltp":1.08,"tv":546.13,"id":8260126},{"batb":[[1,11,4.2],[2,9.2,16.05]],"ltp":13.5,"tv":77.3,"id":4486603}]}]}
{"op":"mcm","clk":"1008680623","pt":1580638615284,"mc":[{"id":"1.168224426","rc":[{"batb":[[0,1.04,495.22],[1,1.01,15.51],[2,1.04,0]],"batl":[[0,1.09,9.09],[1,1.1,42.01],[2,1.38,972.97]],"ltp":1.08,"tv":546.13,"id":8260126},{"batb":[[0,11,4.2],[1,9.2,16.05],[2,1.01,15.52]],"ltp":13.5,"tv":77.3,"id":4486603}]}]}
{"op":"mcm","clk":"1008680679","pt":1580638615974,"mc":[{"id":"1.168224426","rc":[{"batl":[[1,1.38,972.97],[2,1.38,0]],"ltp":1.08,"tv":546.13,"id":8260126},{"batb":[[0,9.2,16.05],[1,1.01,15.52],[2,1.01,0]],"ltp":13.5,"tv":77.3,"id":4486603}]}]}
{"op":"mcm","clk":"1008680738","pt":1580638616656,"mc":[{"id":"1.168224426","rc":[{"batl":[[0,1.38,972.97],[1,1.38,0]],"ltp":1.08,"tv":546.13,"id":8260126}]}]}
{"op":"mcm","clk":"1008680874","pt":1580638618278,"mc":[{"id":"1.168224426","rc":[{"batb":[[0,1.06,686.58],[1,1.05,521.45],[2,1.04,495.22]],"batl":[[0,1.11,693.12],[1,1.12,451.73],[2,1.38,972.97]],"ltp":1.08,"tv":546.13,"id":8260126}]}]}
{"op":"mcm","clk":"1008680940","pt":1580638619060,"mc":[{"id":"1.168224426","rc":[{"batl":[[0,1.38,972.97],[1,1.12,0],[2,1.38,0]],"ltp":1.08,"tv":546.13,"id":8260126}]}]}
{"op":"mcm","clk":"1008680996","pt":1580638619793,"mc":[{"id":"1.168224426","rc":[{"batl":[[0,1.07,9.09],[1,1.38,972.97]],"ltp":1.08,"tv":546.13,"id":8260126}]}]}
{"op":"mcm","clk":"1008681263","pt":1580638622274,"mc":[{"id":"1.168224426","rc":[{"batl":[[0,1.07,595.08],[1,1.08,600.27],[2,1.38,972.97]],"ltp":1.08,"tv":546.13,"id":8260126},{"batb":[[0,14,6.06],[1,11,10.07],[2,1.01,15.52]],"ltp":13.5,"tv":77.3,"id":4486603}]}]}
{"op":"mcm","clk":"1008681346","pt":1580638623261,"mc":[{"id":"1.168224426","rc":[{"batl":[[2,1.09,42.01]],"ltp":1.08,"tv":546.13,"id":8260126},{"batb":[[1,12,3.36],[2,11,10.07]],"ltp":13.5,"tv":77.3,"id":4486603}]}]}
{"op":"mcm","clk":"1008681466","pt":1580638624570,"mc":[{"id":"1.168224426","rc":[{"batl":[[0,30,47.16]],"ltp":13.5,"tv":77.3,"id":4486603}]}]}
{"op":"mcm","clk":"1008681594","pt":1580638626083,"mc":[{"id":"1.168224426","rc":[{"batl":[[0,1.07,585.99]],"ltp":1.08,"tv":546.13,"id":8260126}]}]}
{"op":"mcm","clk":"1008681669","pt":1580638627081,"mc":[{"id":"1.168224426","rc":[{"trd":[[1.07,28.04]],"batl":[[0,1.07,571.97]],"ltp":1.07,"tv":574.17,"id":8260126}],"tv":651.48}]}
{"op":"mcm","clk":"1008681832","pt":1580638629267,"mc":[{"id":"1.168224426","rc":[{"trd":[[1.06,18.18]],"batb":[[0,1.06,677.49]],"ltp":1.06,"tv":592.35,"id":8260126}],"tv":669.65}]}
{"op":"mcm","clk":"1008682257","pt":1580638634409,"mc":[{"id":"1.168224426","rc":[{"batb":[[0,1.05,521.45],[1,1.04,495.22],[2,1.01,15.51]],"batl":[[0,1.38,972.97],[1,1.08,0],[2,1.09,0]],"ltp":1.06,"tv":592.35,"id":8260126},{"batb":[[0,11,10.07],[1,1.01,15.52],[2,11,0]],"ltp":13.5,"tv":77.3,"id":4486603}]}]}
{"op":"mcm","clk":"1008682404","pt":1580638636404,"mc":[{"id":"1.168224426","rc":[{"batb":[[0,1.05,1214.58]],"batl":[[0,1.09,1106.55],[1,1.38,972.97]],"ltp":1.06,"tv":592.35,"id":8260126}]}]}
{"op":"mcm","clk":"1008682761","pt":1580638640633,"mc":[{"id":"1.168224426","rc":[{"batl":[[0,1.06,5.3],[1,1.09,1106.55],[2,1.38,972.97]],"ltp":1.06,"tv":592.35,"id":8260126}]}]}
{"op":"mcm","clk":"1008683204","pt":1580638646310,"mc":[{"id":"1.168224426","rc":[{"batl":[[0,1.09,1106.55],[1,1.38,972.97],[2,1.38,0]],"ltp":1.06,"tv":592.35,"id":8260126}]}]}
{"op":"mcm","clk":"1008683455","pt":1580638649417,"mc":[{"id":"1.168224426","rc":[{"trd":[[1.05,10.6]],"batb":[[0,1.05,1209.28]],"ltp":1.05,"tv":602.95,"id":8260126}],"tv":680.25}]}
{"op":"mcm","clk":"1008683466","pt":1580638649623,"mc":[{"id":"1.168224426","rc":[{"batb":[[0,1.04,495.22],[1,1.01,15.51],[2,1.01,0]],"ltp":1.05,"tv":602.95,"id":8260126}]}]}
{"op":"mcm","clk":"1008683791","pt":1580638653426,"mc":[{"id":"1.168224426","rc":[{"batb":[[0,1.07,1191.87],[1,1.06,368.55],[2,1.05,468]],"ltp":1.05,"tv":602.95,"id":8260126},{"batb":[[1,10.5,4.2],[2,8.4,7.95]],"ltp":13.5,"tv":77.3,"id":4486603}]}]}
{"op":"mcm","clk":"1008683902","pt":1580638654145,"mc":[{"id":"1.168224426","rc":[{"batb":[[0,1.08,168.04],[1,1.07,1191.87],[2,1.06,368.55]],"ltp":1.05,"tv":602.95,"id":8260126}]}]}
{"op":"mcm","clk":"1008684089","pt":1580638656024,"mc":[{"id":"1.168224426","rc":[{"batl":[[0,24,50.52]],"ltp":13.5,"tv":77.3,"id":4486603}]}]}
{"op":"mcm","clk":"1008685303","pt":1580638670348,"mc":[{"id":"1.168224426","rc":[{"batl":[[0,30,47.16]],"ltp":13.5,"tv":77.3,"id":4486603}]}]}
{"op":"mcm","clk":"1008685866","pt":1580638675160,"mc":[{"id":"1.168224426","rc":[{"batb":[[1,1.05,468],[2,1.01,15.51]],"batl":[[0,1.38,972.97],[1,1.38,0]],"ltp":1.05,"tv":602.95,"id":8260126},{"batb":[[0,10.5,4.2],[1,8.4,7.95],[2,1.01,15.52]],"ltp":13.5,"tv":77.3,"id":4486603}]}]}
{"op":"mcm","clk":"1008685960","pt":1580638676050,"mc":[{"id":"1.168224426","rc":[{"batb":[[0,1.05,468],[1,1.01,15.51],[2,1.01,0]],"ltp":1.05,"tv":602.95,"id":8260126},{"batb":[[0,8.4,7.95],[1,1.01,15.52],[2,1.01,0]],"ltp":13.5,"tv":77.3,"id":4486603}]}]}
{"op":"mcm","clk":"1008686191","pt":1580638677943,"mc":[{"id":"1.168224426","rc":[{"batb":[[0,1.06,834.43],[1,1.05,840.19],[2,1.01,15.51]],"batl":[[0,1.12,452.09],[1,1.13,680.49],[2,1.38,972.97]],"ltp":1.05,"tv":602.95,"id":8260126}]}]}
{"op":"mcm","clk":"1008686333","pt":1580638679245,"mc":[{"id":"1.168224426","rc":[{"batl":[[0,1.38,972.97],[1,1.13,0],[2,1.38,0]],"ltp":1.05,"tv":602.95,"id":8260126}]}]}
{"op":"mcm","clk":"1008686638","pt":1580638682283,"mc":[{"id":"1.168224426","rc":[{"batl":[[0,1.07,457.23],[1,1.08,727.84],[2,1.38,972.97]],"ltp":1.05,"tv":602.95,"id":8260126}]}]}
{"op":"mcm","clk":"1008686776","pt":1580638682966,"mc":[{"id":"1.168224426","rc":[{"batb":[[2,1.04,544.16]],"batl":[[2,1.09,42.01]],"ltp":1.05,"tv":602.95,"id":8260126},{"batb":[[0,13.5,6.69],[1,12.5,3.36],[2,11,10.86]],"ltp":13.5,"tv":77.3,"id":4486603}]}]}
{"op":"mcm","clk":"1008687042","pt":1580638685381,"mc":[{"id":"1.168224426","rc":[{"batl":[[0,42,43.68]],"ltp":13.5,"tv":77.3,"id":4486603}]}]}
{"op":"mcm","clk":"1008687996","pt":1580638692253,"mc":[{"id":"1.168224426","rc":[{"batl":[[0,65,40.67]],"ltp":13.5,"tv":77.3,"id":4486603}]}]}
{"op":"mcm","clk":"1008688329","pt":1580638694886,"mc":[{"id":"1.168224426","rc":[{"trd":[[1.06,32.56]],"batb":[[0,1.06,737.1]],"batl":[[1,1.08,639.45]],"ltp":1.06,"tv":617.33,"id":8260126}],"tv":694.64}]}
{"op":"mcm","clk":"1008688684","pt":1580638698058,"mc":[{"id":"1.168224426","rc":[{"batb":[[0,1.05,463.19],[1,1.04,544.16],[2,1.01,15.51]],"batl":[[0,1.32,1159.8],[1,1.08,0],[2,1.09,0]],"ltp":1.06,"tv":617.33,"id":8260126},{"batb":[[0,11,10.86],[1,1.01,15.52],[2,11,0]],"ltp":13.5,"tv":77.3,"id":4486603}]}]}
{"op":"mcm","clk":"1008688995","pt":1580638700892,"mc":[{"id":"1.168224426","rc":[{"batb":[[0,1.05,1214.58]],"batl":[[0,1.09,1170],[1,1.32,1159.8]],"ltp":1.06,"tv":617.33,"id":8260126}]}]}
{"op":"mcm","clk":"1008689073","pt":1580638701772,"mc":[{"id":"1.168224426","rc":[{"batb":[[0,1.04,544.16],[1,1.01,15.51],[2,1.01,0]],"batl":[[0,1.32,1159.8],[1,1.32,0]],"ltp":1.06,"tv":617.33,"id":8260126}]}]}
{"op":"mcm","clk":"1008689461","pt":1580638705229,"mc":[{"id":"1.168224426","rc":[{"batb":[[0,1.06,1140.12],[1,1.04,544.16],[2,1.01,15.51]],"batl":[[0,1.08,958.62],[1,1.32,1159.8]],"ltp":1.06,"tv":617.33,"id":8260126}]}]}
{"op":"mcm","clk":"1008689576","pt":1580638706015,"mc":[{"id":"1.168224426","rc":[{"batb":[[0,1.04,544.16],[1,1.01,15.51],[2,1.01,0]],"batl":[[0,1.32,1159.8],[1,1.32,0]],"ltp":1.06,"tv":617.33,"id":8260126}]}]}
{"op":"mcm","clk":"1008689932","pt":1580638709032,"mc":[{"id":"1.168224426","rc":[{"batb":[[0,1.05,1214.58],[1,1.04,544.16],[2,1.01,15.51]],"batl":[[0,1.09,1170],[1,1.32,1159.8]],"ltp":1.06,"tv":617.33,"id":8260126}]}]}
{"op":"mcm","clk":"1008690086","pt":1580638710740,"mc":[{"id":"1.168224426","rc":[{"batl":[[0,1.32,1159.8],[1,1.32,0]],"ltp":1.06,"tv":617.33,"id":8260126}]}]}
{"op":"mcm","clk":"1008690380","pt":1580638713410,"mc":[{"id":"1.168224426","rc":[{"batl":[[0,1.07,1189.79],[1,1.32,1159.8]],"ltp":1.06,"tv":617.33,"id":8260126}]}]}
{"op":"mcm","clk":"1008690453","pt":1580638714132,"mc":[{"id":"1.168224426","rc":[{"batb":[[2,1.03,729.07]],"batl":[[0,1.06,2],[1,1.07,1189.79],[2,1.32,1159.8]],"ltp":1.06,"tv":617.33,"id":8260126},{"batb":[[0,15,5.19],[1,13,7.08],[2,1.01,15.52]],"ltp":13.5,"tv":77.3,"id":4486603}]}]}
{"op":"mcm","clk":"1008690551","pt":1580638715018,"mc":[{"id":"1.168224426","rc":[{"batl":[[2,1.08,42.01]],"ltp":1.06,"tv":617.33,"id":8260126},{"batb":[[1,13.5,3.36],[2,13,7.08]],"ltp":13.5,"tv":77.3,"id":4486603}]}]}
{"op":"mcm","clk":"1008693113","pt":1580638741981,"mc":[{"id":"1.168224426","rc":[{"batl":[[0,1.07,1189.79],[1,1.08,42.01],[2,1.32,1159.8]],"ltp":1.06,"tv":617.33,"id":8260126}]}]}
{"op":"mcm","clk":"1008694023","pt":1580638751151,"mc":[{"id":"1.168224426","rc":[{"trd":[[1.05,14.6]],"batb":[[0,1.05,1212.58]],"ltp":1.05,"tv":621.33,"id":8260126}],"tv":698.64}]}
{"op":"mcm","clk":"1008699435","pt":1580638812245,"mc":[{"id":"1.168224426","rc":[{"batb":[[0,1.03,729.07],[1,1.01,15.51],[2,1.03,0]],"batl":[[0,1.07,209.02]],"ltp":1.05,"tv":621.33,"id":8260126},{"batb":[[0,13.5,3.36],[1,13,7.08],[2,1.01,15.52]],"ltp":13.5,"tv":77.3,"id":4486603}]}]}
{"op":"mcm","clk":"1008699657","pt":1580638814137,"mc":[{"id":"1.168224426","rc":[{"batl":[[1,1.32,1159.8],[2,1.32,0]],"ltp":1.05,"tv":621.33,"id":8260126},{"batb":[[0,13,7.08],[1,1.01,15.52],[2,1.01,0]],"ltp":13.5,"tv":77.3,"id":4486603}]}]}
{"op":"mcm","clk":"1008699746","pt":1580638815014,"mc":[{"id":"1.168224426","rc":[{"batb":[[0,1.04,1224.11],[1,1.03,729.07],[2,1.01,15.51]],"batl":[[1,1.08,971.68],[2,1.32,1159.8]],"ltp":1.05,"tv":621.33,"id":8260126}]}]}
{"op":"mcm","clk":"1008700115","pt":1580638818837,"mc":[{"id":"1.168224426","rc":[{"batl":[[0,1.32,1159.8],[1,1.08,0],[2,1.32,0]],"ltp":1.05,"tv":621.33,"id":8260126}]}]}
{"op":"mcm","clk":"1008700385","pt":1580638822217,"mc":[{"id":"1.168224426","rc":[{"batl":[[0,1.05,817.89],[1,1.06,390.83],[2,1.32,1159.8]],"ltp":1.05,"tv":621.33,"id":8260126},{"batb":[[0,18.5,6.45],[1,15.5,4.88],[2,13,7.08]],"ltp":13.5,"tv":77.3,"id":4486603}]}]}
{"op":"mcm","clk":"1008700412","pt":1580638822528,"mc":[{"id":"1.168224426","rc":[{"batb":[[2,1.01,15.52]],"ltp":13.5,"tv":77.3,"id":4486603}]}]}
{"op":"mcm","clk":"1008700666","pt":1580638825136,"mc":[{"id":"1.168224426","rc":[{"batl":[[0,160,37.1]],"ltp":13.5,"tv":77.3,"id":4486603}]}]}
{"op":"mcm","clk":"1008701135","pt":1580638830354,"mc":[{"id":"1.168224426","rc":[{"batb":[[0,1.03,729.07],[1,1.01,15.51],[2,1.01,0]],"batl":[[0,1.06,390.83],[1,1.32,1159.8],[2,1.32,0]],"ltp":1.05,"tv":621.33,"id":8260126}]}]}
{"op":"mcm","clk":"1008701161","pt":1580638830670,"mc":[{"id":"1.168224426","rc":[{"batb":[[0,1.01,15.51],[1,1.01,0]],"ltp":1.05,"tv":621.33,"id":8260126},{"batb":[[0,15.5,4.88],[1,1.01,15.52],[2,1.01,0]],"ltp":13.5,"tv":77.3,"id":4486603}]}]}
{"op":"mcm","clk":"1008701431","pt":1580638833341,"mc":[{"id":"1.168224426","rc":[{"batb":[[0,1.02,1248.11],[1,1.01,15.51]],"batl":[[0,1.06,496.89],[1,1.07,697.53],[2,1.32,1159.8]],"ltp":1.05,"tv":621.33,"id":8260126}]}]}
{"op":"mcm","clk":"1008702054","pt":1580638839586,"mc":[{"id":"1.168224426","rc":[{"batb":[[0,1.01,15.51],[1,1.01,0]],"ltp":1.05,"tv":621.33,"id":8260126}]}]}
{"op":"mcm","clk":"1008702396","pt":1580638843162,"mc":[{"id":"1.168224426","rc":[{"batb":[[0,1.05,1212.45],[1,1.04,563.68],[2,1.02,810.11]],"ltp":1.05,"tv":621.33,"id":8260126},{"batb":[[1,13.5,6.85],[2,1.01,15.52]],"ltp":13.5,"tv":77.3,"id":4486603}]}]}
{"op":"mcm","clk":"1008702722","pt":1580638846165,"mc":[{"id":"1.168224426","rc":[{"trd":[[1.05,33.84]],"batb":[[0,1.05,1202.83]],"ltp":1.05,"tv":640.57,"id":8260126},{"batl":[[0,95,38.77]],"ltp":13.5,"tv":77.3,"id":4486603}],"tv":717.87}]}
{"op":"mcm","clk":"1008702947","pt":1580638848283,"mc":[{"id":"1.168224426","rc":[{"batb":[[0,1.02,810.11],[1,1.01,15.51],[2,1.02,0]],"batl":[[0,1.07,276.83],[1,1.32,1159.8],[2,1.32,0]],"ltp":1.05,"tv":640.57,"id":8260126},{"batb":[[0,13.5,6.85],[1,1.01,15.52],[2,1.01,0]],"ltp":13.5,"tv":77.3,"id":4486603}]}]}
{"op":"mcm","clk":"1008703214","pt":1580638850894,"mc":[{"id":"1.168224426","rc":[{"batb":[[0,1.03,1235.99],[1,1.02,810.11],[2,1.01,15.51]],"batl":[[1,1.08,904.5],[2,1.32,1159.8]],"ltp":1.05,"tv":640.57,"id":8260126}]}]}
{"op":"mcm","clk":"1008703269","pt":1580638851464,"mc":[{"id":"1.168224426","rc":[{"batb":[[0,1.02,810.11],[1,1.01,15.51],[2,1.01,0]],"batl":[[0,1.32,1159.8],[1,1.08,0],[2,1.32,0]],"ltp":1.05,"tv":640.57,"id":8260126}]}]}
{"op":"mcm","clk":"1008703506","pt":1580638854375,"mc":[{"id":"1.168224426","rc":[{"batb":[[0,1.05,463.47],[1,1.04,756.18],[2,1.02,810.11]],"batl":[[0,1.06,1141.13],[1,1.32,1159.8]],"ltp":1.05,"tv":640.57,"id":8260126}]}]}
{"op":"mcm","clk":"1008703792","pt":1580638857504,"mc":[{"id":"1.168224426","rc":[{"batb":[[0,1.02,810.11],[1,1.01,15.51],[2,1.02,0]],"batl":[[0,1.32,1159.8],[1,1.32,0]],"ltp":1.05,"tv":640.57,"id":8260126}]}]}
{"op":"mcm","clk":"1008704043","pt":1580638860547,"mc":[{"id":"1.168224426","rc":[{"batb":[[0,1.03,1235.99],[1,1.02,810.11],[2,1.01,15.51]],"batl":[[0,1.07,276.83],[1,1.08,904.5],[2,1.32,1159.8]],"ltp":1.05,"tv":640.57,"id":8260126}]}]}
{"op":"mcm","clk":"1008705369","pt":1580638874755,"mc":[{"id":"1.168224426","rc":[{"batb":[[0,1.02,810.11],[1,1.01,15.51],[2,1.01,0]],"ltp":1.05,"tv":640.57,"id":8260126}]}]}
{"op":"mcm","clk":"1008705699","pt":1580638878359,"mc":[{"id":"1.168224426","rc":[{"batb":[[0,1.06,1082.98],[1,1.05,462.18],[2,1.04,588.23]],"ltp":1.05,"tv":640.57,"id":8260126},{"batb":[[1,12,8.73],[2,1.01,15.52]],"ltp":13.5,"tv":77.3,"id":4486603}]}]}
{"op":"mcm","clk":"1008705771","pt":1580638879147,"mc":[{"id":"1.168224426","rc":[{"batl":[[2,1.09,42.01]],"ltp":1.05,"tv":640.57,"id":8260126},{"batb":[[1,12.5,3.36],[2,12,8.73]],"ltp":13.5,"tv":77.3,"id":4486603}]}]}
{"op":"mcm","clk":"1008705962","pt":1580638881236,"mc":[{"id":"1.168224426","rc":[{"batl":[[0,65,40.67]],"ltp":13.5,"tv":77.3,"id":4486603}]}]}
{"op":"mcm","clk":"1008706807","pt":1580638890661,"mc":[{"id":"1.168224426","rc":[{"batb":[[0,1.06,1044.3]],"batl":[[1,1.08,866.5]],"ltp":1.05,"tv":640.57,"id":8260126}]}]}
{"op":"mcm","clk":"1008706945","pt":1580638892074,"mc":[{"id":"1.168224426","rc":[{"batb":[[0,1.04,588.23],[1,1.01,15.51],[2,1.04,0]],"batl":[[0,1.08,434.12],[1,1.32,1159.8],[2,1.09,0]],"ltp":1.05,"tv":640.57,"id":8260126},{"batb":[[0,12,8.73],[1,1.01,15.52],[2,12,0]],"ltp":13.5,"tv":77.3,"id":4486603}]}]}
{"op":"mcm","clk":"1008707183","pt":1580638894881,"mc":[{"id":"1.168224426","rc":[{"batb":[[0,1.05,641.23],[1,1.04,1164.94],[2,1.01,15.51]],"batl":[[1,1.09,737.82],[2,1.32,1159.8]],"ltp":1.05,"tv":640.57,"id":8260126}]}]}
{"op":"mcm","clk":"1008707624","pt":1580638899502,"mc":[{"id":"1.168224426","rc":[{"batl":[[0,1.32,1159.8],[1,1.09,0],[2,1.32,0]],"ltp":1.05,"tv":640.57,"id":8260126}]}]}
{"op":"mcm","clk":"1008707945","pt":1580638903191,"mc":[{"id":"1.168224426","rc":[{"batb":[[2,1.02,1023.89]],"batl":[[0,1.06,997.4],[1,1.07,201.71],[2,1.32,1159.8]],"ltp":1.05,"tv":640.57,"id":8260126},{"batb":[[0,16,4.48],[1,13,7],[2,1.01,15.52]],"ltp":13.5,"tv":77.3,"id":4486603}]}]}
{"op":"mcm","clk":"1008708198","pt":1580638905887,"mc":[{"id":"1.168224426","rc":[{"batl":[[0,95,38.77]],"ltp":13.5,"tv":77.3,"id":4486603}]}]}
{"op":"mcm","clk":"1008708987","pt":1580638914237,"mc":[{"id":"1.168224426","rc":[{"batb":[[0,1.04,588.23],[1,1.02,1023.89],[2,1.01,15.51]],"batl":[[0,1.32,1159.8],[1,1.07,0],[2,1.32,0]],"ltp":1.05,"tv":640.57,"id":8260126}]}]}
{"op":"mcm","clk":"1008709029","pt":1580638914653,"mc":[{"id":"1.168224426","rc":[{"batb":[[0,1.02,1023.89],[1,1.01,15.51],[2,1.01,0]],"ltp":1.05,"tv":640.57,"id":8260126},{"batb":[[0,13,7],[1,1.01,15.52],[2,1.01,0]],"ltp":13.5,"tv":77.3,"id":4486603}]}]}
{"op":"mcm","clk":"1008709237","pt":1580638917151,"mc":[{"id":"1.168224426","rc":[{"batb":[[0,1.03,1235.99],[1,1.02,1023.89],[2,1.01,15.51]],"batl":[[0,1.08,1178.77],[1,1.32,1159.8]],"ltp":1.05,"tv":640.57,"id":8260126}]}]}
{"op":"mcm","clk":"1008709291","pt":1580638917831,"mc":[{"id":"1.168224426","rc":[{"batb":[[0,1.02,1023.89],[1,1.01,15.51],[2,1.01,0]],"ltp":1.05,"tv":640.57,"id":8260126}]}]}
{"op":"mcm","clk":"1008709349","pt":1580638918553,"mc":[{"id":"1.168224426","rc":[{"batl":[[0,1.05,8.4],[1,1.08,1178.77],[2,1.32,1159.8]],"ltp":1.05,"tv":640.57,"id":8260126}]}]}
{"op":"mcm","clk":"1008709597","pt":1580638921341,"mc":[{"id":"1.168224426","rc":[{"trd":[[1.05,50.64]],"batb":[[0,1.06,1192.61],[1,1.05,457.3],[2,1.03,606.17]],"batl":[[0,1.08,1178.77],[1,1.09,42.01]],"ltp":1.05,"tv":657.37,"id":8260126},{"batb":[[1,12.5,3.36],[2,11.5,9.36]],"ltp":13.5,"tv":77.3,"id":4486603}],"tv":734.68}]}
{"op":"mcm","clk":"1008709886","pt":1580638924331,"mc":[{"id":"1.168224426","rc":[{"batl":[[0,65,40.67]],"ltp":13.5,"tv":77.3,"id":4486603}]}]}
{"op":"mcm","clk":"1008710686","pt":1580638932272,"mc":[{"id":"1.168224426","rc":[{"batb":[[0,1.05,457.3],[1,1.03,606.17],[2,1.01,15.51]],"batl":[[0,1.09,42.01],[1,1.32,1159.8],[2,1.32,0]],"ltp":1.05,"tv":657.37,"id":8260126}]}]}
{"op":"mcm","clk":"1008710770","pt":1580638933054,"mc":[{"id":"1.168224426","rc":[{"batb":[[0,1.03,606.17],[1,1.01,15.51],[2,1.01,0]],"ltp":1.05,"tv":657.37,"id":8260126},{"batb":[[0,12.5,3.36],[1,11.5,9.36],[2,1.01,15.52]],"ltp":13.5,"tv":77.3,"id":4486603}]}]}
{"op":"mcm","clk":"1008710880","pt":1580638934158,"mc":[{"id":"1.168224426","rc":[{"batl":[[0,1.32,1159.8],[1,1.32,0]],"ltp":1.05,"tv":657.37,"id":8260126},{"batb":[[0,11.5,9.36],[1,1.01,15.52],[2,1.01,0]],"ltp":13.5,"tv":77.3,"id":4486603}]}]}
{"op":"mcm","clk":"1008710992","pt":1580638935353,"mc":[{"id":"1.168224426","rc":[{"batb":[[0,1.05,482.46],[1,1.04,737],[2,1.03,606.17]],"batl":[[0,1.09,1167.96],[1,1.32,1159.8]],"ltp":1.05,"tv":657.37,"id":8260126}]}]}
{"op":"mcm","clk":"1008711086","pt":1580638936179,"mc":[{"id":"1.168224426","rc":[{"batb":[[1,1.03,606.17],[2,1.01,15.51]],"batl":[[0,1.32,1159.8],[1,1.32,0]],"ltp":1.05,"tv":657.37,"id":8260126}]}]}
{"op":"mcm","clk":"1008711665","pt":1580638942276,"mc":[{"id":"1.168224426","rc":[{"batb":[[1,1.04,737],[2,1.03,606.17]],"batl":[[0,1.09,1167.96],[1,1.32,1159.8]],"ltp":1.05,"tv":657.37,"id":8260126}]}]}
{"op":"mcm","clk":"1008711967","pt":1580638945672,"mc":[{"id":"1.168224426","rc":[{"batb":[[0,1.03,606.17],[1,1.01,15.51],[2,1.03,0]],"ltp":1.05,"tv":657.37,"id":8260126}]}]}
{"op":"mcm","clk":"1008712308","pt":1580638949299,"mc":[{"id":"1.168224426","rc":[{"batb":[[0,1.07,1042.73],[1,1.06,1291.89],[2,1.04,510.02]],"batl":[[1,1.1,42.01],[2,1.32,1159.8]],"ltp":1.05,"tv":657.37,"id":8260126},{"batb":[[1,11,4.2],[2,8.2,8.42]],"ltp":13.5,"tv":77.3,"id":4486603}]}]}
{"op":"mcm","clk":"1008712590","pt":1580638952163,"mc":[{"id":"1.168224426","rc":[{"batl":[[0,42,43.68]],"ltp":13.5,"tv":77.3,"id":4486603}]}]}
{"op":"mcm","clk":"1008715226","pt":1580638978356,"mc":[{"id":"1.168224426","rc":[{"batb":[[0,1.06,1291.89],[1,1.04,510.02],[2,1.01,15.51]],"batl":[[0,1.1,42.01],[1,1.32,1159.8],[2,1.32,0]],"ltp":1.05,"tv":657.37,"id":8260126}]}]}
{"op":"mcm","clk":"1008715296","pt":1580638978938,"mc":[{"id":"1.168224426","rc":[{"batb":[[0,1.04,510.02],[1,1.01,15.51],[2,1.01,0]],"ltp":1.05,"tv":657.37,"id":8260126},{"batb":[[0,11,4.2],[1,8.2,8.42],[2,1.01,15.52]],"ltp":13.5,"tv":77.3,"id":4486603}]}]}
{"op":"mcm","clk":"1008715424","pt":1580638980186,"mc":[{"id":"1.168224426","rc":[{"batl":[[0,1.32,1159.8],[1,1.32,0]],"ltp":1.05,"tv":657.37,"id":8260126},{"batb":[[0,8.2,8.42],[1,1.01,15.52],[2,1.01,0]],"ltp":13.5,"tv":77.3,"id":4486603}]}]}
{"op":"mcm","clk":"1008715540","pt":1580638981345,"mc":[{"id":"1.168224426","rc":[{"batb":[[0,1.05,1212.45],[1,1.04,510.02],[2,1.01,15.51]],"batl":[[0,1.13,960.29],[1,1.32,1159.8]],"ltp":1.05,"tv":657.37,"id":8260126}]}]}
{"op":"mcm","clk":"1008715647","pt":1580638982441,"mc":[{"id":"1.168224426","rc":[{"batb":[[0,1.04,510.02],[1,1.01,15.51],[2,1.01,0]],"batl":[[0,1.32,1159.8],[1,1.32,0]],"ltp":1.05,"tv":657.37,"id":8260126}]}]}
{"op":"mcm","clk":"1008715860","pt":1580638984726,"mc":[{"id":"1.168224426","rc":[{"batb":[[0,1.08,497.93],[1,1.07,687.2],[2,1.04,510.02]],"batl":[[0,1.09,355.21],[1,1.1,805.35],[2,1.32,1159.8]],"ltp":1.05,"tv":657.37,"id":8260126}]}]}
{"op":"mcm","clk":"1008716065","pt":1580638986863,"mc":[{"id":"1.168224426","rc":[{"batb":[[0,1.04,510.02],[1,1.01,15.51],[2,1.04,0]],"batl":[[0,1.32,1159.8],[1,1.1,0],[2,1.32,0]],"ltp":1.05,"tv":657.37,"id":8260126}]}]}
{"op":"mcm","clk":"1008716343","pt":1580638989888,"mc":[{"id":"1.168224426","rc":[{"batb":[[0,1.05,1212.45],[1,1.04,510.02],[2,1.01,15.51]],"batl":[[0,1.13,960.41],[1,1.32,1159.8]],"ltp":1.05,"tv":657.37,"id":8260126}]}]}
{"op":"mcm","clk":"1008717457","pt":1580639000504,"mc":[{"id":"1.168224426","rc":[{"batb":[[0,1.04,510.02],[1,1.01,15.51],[2,1.01,0]],"batl":[[0,1.32,1159.8],[1,1.32,0]],"ltp":1.05,"tv":657.37,"id":8260126}]}]}
{"op":"mcm","clk":"1008718156","pt":1580639004393,"mc":[{"id":"1.168224426","rc":[{"batb":[[0,1.11,399.07],[1,1.1,989.51],[2,1.07,326.92]],"batl":[[0,1.13,960.41],[1,1.32,1159.8]],"ltp":1.05,"tv":657.37,"id":8260126},{"batb":[[1,5.5,10.39],[2,1.01,15.52]],"ltp":13.5,"tv":77.3,"id":4486603}]}]}
{"op":"mcm","clk":"1008718343","pt":1580639005228,"mc":[{"id":"1.168224426","rc":[{"batb":[[0,1.11,567.11]],"batl":[[1,1.14,42.01],[2,1.32,1159.8]],"ltp":1.05,"tv":657.37,"id":8260126},{"batb":[[0,8.2,13.46]],"batl":[[0,10,4.2]],"ltp":13.5,"tv":77.3,"id":4486603}]}]}
{"op":"mcm","clk":"1008718522","pt":1580639006558,"mc":[{"id":"1.168224426","rc":[{"batl":[[1,24,50.52]],"ltp":13.5,"tv":77.3,"id":4486603}]}]}
{"op":"mcm","clk":"1008720613","pt":1580639024972,"mc":[{"id":"1.168224426","rc":[{"batb":[[0,1.11,168.04],[1,1.07,326.92],[2,1.01,15.51]],"batl":[[0,1.14,42.01],[1,1.32,1159.8],[2,1.32,0]],"ltp":1.05,"tv":657.37,"id":8260126},{"batb":[[0,8.2,5.04]],"ltp":13.5,"tv":77.3,"id":4486603}]}]}
{"op":"mcm","clk":"1008720785","pt":1580639026393,"mc":[{"id":"1.168224426","rc":[{"batb":[[0,1.07,326.92],[1,1.01,15.51],[2,1.01,0]],"batl":[[0,1.32,1159.8],[1,1.32,0]],"ltp":1.05,"tv":657.37,"id":8260126},{"batb":[[0,5.5,10.39],[1,1.01,15.52],[2,1.01,0]],"batl":[[0,24,50.52],[1,24,0]],"ltp":13.5,"tv":77.3,"id":4486603}]}]}
{"op":"mcm","clk":"1008721262","pt":1580639031406,"mc":[{"id":"1.168224426","rc":[{"batb":[[0,1.08,849.28],[1,1.07,659.49],[2,1.05,469.34]],"batl":[[0,1.1,1157.34],[1,1.11,42.01],[2,1.32,1159.8]],"ltp":1.05,"tv":657.37,"id":8260126},{"batb":[[0,10,16.63],[1,6.8,12.43],[2,5.5,10.39]],"batl":[[0,13,3.36]],"ltp":13.5,"tv":77.3,"id":4486603}]}]}
{"op":"mcm","clk":"1008721280","pt":1580639031622,"mc":[{"id":"1.168224426","rc":[{"batb":[[2,1.01,15.52]],"ltp":13.5,"tv":77.3,"id":4486603}]}]}
{"op":"mcm","clk":"1008721521","pt":1580639033928,"mc":[{"id":"1.168224426","rc":[{"batl":[[1,30,47.16]],"ltp":13.5,"tv":77.3,"id":4486603}]}]}
{"op":"mcm","clk":"1008723070","pt":1580639047150,"mc":[{"id":"1.168224426","rc":[{"batb":[[0,1.05,469.34],[1,1.01,15.51],[2,1.05,0]],"batl":[[0,1.11,42.01],[1,1.32,1159.8],[2,1.32,0]],"ltp":1.05,"tv":657.37,"id":8260126},{"batb":[[0,10,4.2]],"ltp":13.5,"tv":77.3,"id":4486603}]}]}
{"op":"mcm","clk":"1008723190","pt":1580639048253,"mc":[{"id":"1.168224426","rc":[{"batl":[[0,1.32,1159.8],[1,1.32,0]],"ltp":1.05,"tv":657.37,"id":8260126},{"batb":[[0,6.8,12.43],[1,1.01,15.52],[2,1.01,0]],"batl":[[0,30,47.16],[1,30,0]],"ltp":13.5,"tv":77.3,"id":4486603}]}]}
{"op":"mcm","clk":"1008723358","pt":1580639049727,"mc":[{"id":"1.168224426","rc":[{"batb":[[0,1.06,774.51],[1,1.05,899.89],[2,1.01,15.51]],"batl":[[0,1.15,362.01],[1,1.16,689.7],[2,1.32,1159.8]],"ltp":1.05,"tv":657.37,"id":8260126}]}]}
{"op":"mcm","clk":"1008724105","pt":1580639057676,"mc":[{"id":"1.168224426","rc":[{"batb":[[0,1.05,469.34],[1,1.01,15.51],[2,1.01,0]],"ltp":1.05,"tv":657.37,"id":8260126}]}]}
{"op":"mcm","clk":"1008724492","pt":1580639061273,"mc":[{"id":"1.168224426","rc":[{"batb":[[0,1.13,1117.63],[1,1.12,365.47],[2,1.09,279.64]],"batl":[[1,1.16,731.71]],"ltp":1.05,"tv":657.37,"id":8260126},{"batb":[[0,7.2,6.72],[1,6.8,12.43],[2,4.4,17.39]],"batl":[[0,8.8,5.04]],"ltp":13.5,"tv":77.3,"id":4486603}]}]}
{"op":"mcm","clk":"1008724654","pt":1580639063153,"mc":[{"id":"1.168224426","rc":[{"batl":[[1,17,57.33]],"ltp":13.5,"tv":77.3,"id":4486603}]}]}
{"op":"mcm","clk":"1008726558","pt":1580639083184,"mc":[{"id":"1.168224426","rc":[{"batb":[[0,1.13,168.04],[1,1.09,279.64],[2,1.01,15.51]],"batl":[[0,1.16,42.01],[1,1.32,1159.8],[2,1.32,0]],"ltp":1.05,"tv":657.37,"id":8260126},{"batb":[[1,4.4,17.39],[2,1.01,15.52]],"ltp":13.5,"tv":77.3,"id":4486603}]}]}
{"op":"mcm","clk":"1008726675","pt":1580639084384,"mc":[{"id":"1.168224426","rc":[{"batb":[[0,1.09,279.64],[1,1.01,15.51],[2,1.01,0]],"batl":[[0,1.32,1159.8],[1,1.32,0]],"ltp":1.05,"tv":657.37,"id":8260126},{"batb":[[0,4.4,17.39],[1,1.01,15.52],[2,1.01,0]],"batl":[[0,17,57.33],[1,17,0]],"ltp":13.5,"tv":77.3,"id":4486603}]}]}
{"op":"mcm","clk":"1008726812","pt":1580639085793,"mc":[{"id":"1.168224426","rc":[{"batb":[[0,1.09,1155.24],[1,1.08,295.05],[2,1.01,15.51]],"batl":[[0,1.26,212.7],[1,1.27,379.72],[2,1.32,1159.8]],"ltp":1.05,"tv":657.37,"id":8260126}]}]}
{"op":"mcm","clk":"1008727599","pt":1580639094510,"mc":[{"id":"1.168224426","rc":[{"batl":[[0,1.32,1159.8],[1,1.27,0],[2,1.32,0]],"ltp":1.05,"tv":657.37,"id":8260126}]}]}
{"op":"mcm","clk":"1008727913","pt":1580639098294,"mc":[{"id":"1.168224426","rc":[{"batb":[[0,1.09,1083.9],[2,1.05,459.35]],"batl":[[0,1.11,946.89],[1,1.32,1159.8]],"ltp":1.05,"tv":657.37,"id":8260126},{"batb":[[0,9.2,16.21],[1,5.6,10.39],[2,1.01,15.52]],"ltp":13.5,"tv":77.3,"id":4486603}]}]}
{"op":"mcm","clk":"1008728005","pt":1580639099297,"mc":[{"id":"1.168224426","rc":[{"batb":[[0,1.09,1251.93]],"batl":[[1,1.12,42.01],[2,1.32,1159.8]],"ltp":1.05,"tv":657.37,"id":8260126},{"batb":[[0,9.2,21.25]],"batl":[[0,12,3.36]],"ltp":13.5,"tv":77.3,"id":4486603}]}]}
{"op":"mcm","clk":"1008728122","pt":1580639100695,"mc":[{"id":"1.168224426","rc":[{"batb":[[1,1.08,367.05]],"batl":[[0,1.11,1016.93]],"ltp":1.05,"tv":657.37,"id":8260126}]}]}
{"op":"mcm","clk":"1008728205","pt":1580639101529,"mc":[{"id":"1.168224426","rc":[{"batl":[[1,30,47.16]],"ltp":13.5,"tv":77.3,"id":4486603}]}]}
{"op":"mcm","clk":"1008729863","pt":1580639118871,"mc":[{"id":"1.168224426","rc":[{"batb":[[0,1.09,168.04],[1,1.05,459.35],[2,1.01,15.51]],"batl":[[0,1.12,42.01],[1,1.32,1159.8],[2,1.32,0]],"ltp":1.05,"tv":657.37,"id":8260126},{"batb":[[0,9.2,5.04]],"ltp":13.5,"tv":77.3,"id":4486603}]}]}
{"op":"mcm","clk":"1008729985","pt":1580639120332,"mc":[{"id":"1.168224426","rc":[{"batb":[[0,1.05,459.35],[1,1.01,15.51],[2,1.01,0]],"batl":[[0,1.32,1159.8],[1,1.32,0]],"ltp":1.05,"tv":657.37,"id":8260126},{"batb":[[0,5.6,10.39],[1,1.01,15.52],[2,1.01,0]],"batl":[[0,30,47.16],[1,30,0]],"ltp":13.5,"tv":77.3,"id":4486603}]}]}
{"op":"mcm","clk":"1008730135","pt":1580639121898,"mc":[{"id":"1.168224426","rc":[{"batb":[[0,1.06,533.14],[1,1.05,1133.57],[2,1.01,15.51]],"batl":[[0,1.19,169.65],[1,1.2,544.72],[2,1.32,1159.8]],"ltp":1.05,"tv":657.37,"id":8260126}]}]}
{"op":"mcm","clk":"1008730283","pt":1580639123411,"mc":[{"id":"1.168224426","rc":[{"batb":[[0,1.05,459.35],[1,1.01,15.51],[2,1.01,0]],"batl":[[0,1.32,1159.8],[1,1.2,0],[2,1.32,0]],"ltp":1.05,"tv":657.37,"id":8260126}]}]}
{"op":"mcm","clk":"1008730578","pt":1580639126441,"mc":[{"id":"1.168224426","rc":[{"batb":[[0,1.1,1157.34],[1,1.05,459.35],[2,1.01,15.51]],"batl":[[0,1.12,315.5],[1,1.13,813.9],[2,1.32,1159.8]],"ltp":1.05,"tv":657.37,"id":8260126}]}]}
{"op":"mcm","clk":"1008730657","pt":1580639127125,"mc":[{"id":"1.168224426","rc":[{"batb":[[0,1.05,459.35],[1,1.01,15.51],[2,1.01,0]],"batl":[[0,1.32,1159.8],[1,1.13,0],[2,1.32,0]],"ltp":1.05,"tv":657.37,"id":8260126}]}]}
{"op":"mcm","clk":"1008730943","pt":1580639130248,"mc":[{"id":"1.168224426","rc":[{"batb":[[0,1.06,569.56],[1,1.05,1096.81],[2,1.01,15.51]],"batl":[[0,1.2,681.41],[1,1.21,376.34],[2,1.32,1159.8]],"ltp":1.05,"tv":657.37,"id":8260126},{"batl":[[0,24,50.52]],"ltp":13.5,"tv":77.3,"id":4486603}]}]}
{"op":"mcm","clk":"1008731215","pt":1580639133742,"mc":[{"id":"1.168224426","rc":[{"batl":[[0,1.2,681.43]],"ltp":1.05,"tv":657.37,"id":8260126}]}]}
{"op":"mcm","clk":"1008731653","pt":1580639138071,"mc":[{"id":"1.168224426","rc":[{"batl":[[0,1.32,1159.81],[1,1.21,0],[2,1.32,0]],"ltp":1.05,"tv":657.37,"id":8260126}]}]}
{"op":"mcm","clk":"1008731994","pt":1580639141269,"mc":[{"id":"1.168224426","rc":[{"batb":[[0,1.06,737.6]],"batl":[[0,1.07,731.81],[1,1.08,453.74],[2,1.32,1159.81]],"ltp":1.05,"tv":657.37,"id":8260126}]}]}
{"op":"mcm","clk":"1008732081","pt":1580639142052,"mc":[{"id":"1.168224426","rc":[{"batb":[[2,1.03,655.18]],"ltp":1.05,"tv":657.37,"id":8260126},{"batb":[[0,13,10.28],[1,8.8,7.16],[2,1.01,15.52]],"ltp":13.5,"tv":77.3,"id":4486603}]}]}
{"op":"mcm","clk":"1008732270","pt":1580639143767,"mc":[{"id":"1.168224426","rc":[{"batl":[[0,65,40.67]],"ltp":13.5,"tv":77.3,"id":4486603}]}]}
{"op":"mcm","clk":"1008733309","pt":1580639153183,"mc":[{"id":"1.168224426","rc":[{"batb":[[1,1.05,1048.53]],"batl":[[0,1.07,684.49]],"ltp":1.05,"tv":657.37,"id":8260126}]}]}
{"op":"mcm","clk":"1008733631","pt":1580639156075,"mc":[{"id":"1.168224426","rc":[{"batb":[[0,1.06,785.42]],"batl":[[1,1.08,500.62]],"ltp":1.05,"tv":657.37,"id":8260126}]}]}
{"op":"mcm","clk":"1008734565","pt":1580639163418,"mc":[{"id":"1.168224426","rc":[{"batb":[[0,1.06,168.04],[1,1.05,459.35]],"batl":[[0,1.32,1159.81],[1,1.08,0],[2,1.32,0]],"ltp":1.05,"tv":657.37,"id":8260126}]}]}
{"op":"mcm","clk":"1008734681","pt":1580639164325,"mc":[{"id":"1.168224426","rc":[{"batb":[[0,1.03,655.18],[1,1.01,15.51],[2,1.03,0]],"ltp":1.05,"tv":657.37,"id":8260126},{"batb":[[0,8.8,7.16],[1,1.01,15.52],[2,1.01,0]],"ltp":13.5,"tv":77.3,"id":4486603}]}]}
{"op":"mcm","clk":"1008734920","pt":1580639166419,"mc":[{"id":"1.168224426","rc":[{"batb":[[0,1.04,1224.11],[1,1.03,655.18],[2,1.01,15.51]],"batl":[[0,1.11,482.52],[1,1.12,658.48],[2,1.32,1159.8]],"ltp":1.05,"tv":657.37,"id":8260126}]}]}
{"op":"mcm","clk":"1008734957","pt":1580639166733,"mc":[{"id":"1.168224426","rc":[{"batl":[[0,1.32,1159.81],[1,1.12,0],[2,1.32,0]],"ltp":1.05,"tv":657.37,"id":8260126}]}]}
{"op":"mcm","clk":"1008735413","pt":1580639170429,"mc":[{"id":"1.168224426","rc":[{"batb":[[2,1.02,890.05]],"batl":[[0,1.06,1199.09],[1,1.32,1159.81]],"ltp":1.05,"tv":657.37,"id":8260126},{"batb":[[0,17,7.71],[1,15,5.04],[2,8.8,7.16]],"ltp":13.5,"tv":77.3,"id":4486603}]}]}
{"op":"mcm","clk":"1008735513","pt":1580639171325,"mc":[{"id":"1.168224426","rc":[{"batb":[[2,1.01,15.52]],"ltp":13.5,"tv":77.3,"id":4486603}]}]}
{"op":"mcm","clk":"1008735718","pt":1580639173153,"mc":[{"id":"1.168224426","rc":[{"batl":[[0,95,38.77]],"ltp":13.5,"tv":77.3,"id":4486603}]}]}
{"op":"mcm","clk":"1008739720","pt":1580639209003,"mc":[{"id":"1.168224426","rc":[{"trd":[[1.04,10.08]],"batb":[[0,1.04,1219.07]],"ltp":1.04,"tv":667.45,"id":8260126}],"tv":744.76}]}
{"op":"mcm","clk":"1008744714","pt":1580639251306,"mc":[{"id":"1.168224426","rc":[{"batb":[[0,1.02,890.05],[1,1.01,15.51],[2,1.02,0]],"batl":[[0,1.06,606]],"ltp":1.04,"tv":667.45,"id":8260126},{"batb":[[0,15,5.04],[1,1.01,15.52],[2,1.01,0]],"ltp":13.5,"tv":77.3,"id":4486603}]}]}
{"op":"mcm","clk":"1008744992","pt":1580639254086,"mc":[{"id":"1.168224426","rc":[{"batb":[[0,1.03,1234.01],[1,1.02,890.05],[2,1.01,15.51]],"batl":[[1,1.07,587.54],[2,1.32,1159.81]],"ltp":1.04,"tv":667.45,"id":8260126}]}]}
{"op":"mcm","clk":"1008745256","pt":1580639256291,"mc":[{"id":"1.168224426","rc":[{"batb":[[0,1.02,890.05],[1,1.01,15.51],[2,1.01,0]],"ltp":1.04,"tv":667.45,"id":8260126}]}]}
{"op":"mcm","clk":"1008745560","pt":1580639259408,"mc":[{"id":"1.168224426","rc":[{"batb":[[0,1.05,1266.36],[1,1.02,890.05],[2,1.01,15.51]],"batl":[[1,1.07,629.55]],"ltp":1.04,"tv":667.45,"id":8260126}]}]}
{"op":"mcm","clk":"1008745624","pt":1580639259998,"mc":[{"id":"1.168224426","rc":[{"batb":[[1,1.04,552.03],[2,1.03,684.53]],"ltp":1.04,"tv":667.45,"id":8260126},{"batb":[[1,13.5,6.29],[2,1.01,15.52]],"ltp":13.5,"tv":77.3,"id":4486603}]}]}
{"op":"mcm","clk":"1008745975","pt":1580639263402,"mc":[{"id":"1.168224426","rc":[{"batl":[[0,65,40.67]],"ltp":13.5,"tv":77.3,"id":4486603}]}]}
{"op":"mcm","clk":"1008746587","pt":1580639269406,"mc":[{"id":"1.168224426","rc":[{"batb":[[0,1.05,168.04],[1,1.03,684.53],[2,1.01,15.51]],"batl":[[0,1.07,629.55],[1,1.32,1159.81],[2,1.32,0]],"ltp":1.04,"tv":667.45,"id":8260126},{"batb":[[0,13.5,6.29],[1,1.01,15.52],[2,1.01,0]],"ltp":13.5,"tv":77.3,"id":4486603}]}]}
{"op":"mcm","clk":"1008746679","pt":1580639270389,"mc":[{"id":"1.168224426","rc":[{"batb":[[0,1.03,684.53],[1,1.01,15.51],[2,1.01,0]],"batl":[[0,1.07,587.54]],"ltp":1.04,"tv":667.45,"id":8260126}]}]}
{"op":"mcm","clk":"1008746848","pt":1580639272320,"mc":[{"id":"1.168224426","rc":[{"batb":[[0,1.04,1222.15],[1,1.03,684.53],[2,1.01,15.51]],"batl":[[0,1.07,1146.88]],"ltp":1.04,"tv":667.45,"id":8260126}]}]}
{"op":"mcm","clk":"1008747721","pt":1580639281125,"mc":[{"id":"1.168224426","rc":[{"batb":[[0,1.04,578.96]],"batl":[[0,1.07,203.63]],"ltp":1.04,"tv":667.45,"id":8260126}]}]}
{"op":"mcm","clk":"1008748042","pt":1580639284333,"mc":[{"id":"1.168224426","rc":[{"batb":[[0,1.05,637.06],[1,1.04,578.96],[2,1.03,684.53]],"batl":[[0,1.06,993.53],[1,1.07,203.63],[2,1.32,1159.81]],"ltp":1.04,"tv":667.45,"id":8260126}]}]}
{"op":"mcm","clk":"1008748346","pt":1580639287263,"mc":[{"id":"1.168224426","rc":[{"batb":[[0,1.04,578.96],[1,1.03,684.53],[2,1.01,15.51]],"batl":[[0,1.07,203.63],[1,1.32,1159.81],[2,1.32,0]],"ltp":1.04,"tv":667.45,"id":8260126},{"batl":[[0,95,38.77]],"ltp":13.5,"tv":77.3,"id":4486603}]}]}
{"op":"mcm","clk":"1008748572","pt":1580639289823,"mc":[{"id":"1.168224426","rc":[{"batb":[[0,1.04,1222.15]],"batl":[[0,1.07,1146.88]],"ltp":1.04,"tv":667.45,"id":8260126}]}]}
{"op":"mcm","clk":"1008748721","pt":1580639291532,"mc":[{"id":"1.168224426","rc":[{"batb":[[0,1.03,684.53],[1,1.01,15.51],[2,1.01,0]],"ltp":1.04,"tv":667.45,"id":8260126}]}]}
{"op":"mcm","clk":"1008749121","pt":1580639295353,"mc":[{"id":"1.168224426","rc":[{"batb":[[0,1.05,1210.51],[1,1.03,684.53],[2,1.01,15.51]],"ltp":1.04,"tv":667.45,"id":8260126}]}]}
{"op":"mcm","clk":"1008749157","pt":1580639295728,"mc":[{"id":"1.168224426","rc":[{"batb":[[1,1.04,562.81]],"ltp":1.04,"tv":667.45,"id":8260126},{"batb":[[1,13,7.16],[2,1.01,15.52]],"ltp":13.5,"tv":77.3,"id":4486603}]}]}
{"op":"mcm","clk":"1008749325","pt":1580639297403,"mc":[{"id":"1.168224426","rc":[{"batl":[[0,65,40.67]],"ltp":13.5,"tv":77.3,"id":4486603}]}]}
{"op":"mcm","clk":"1008750188","pt":1580639306696,"mc":[{"id":"1.168224426","rc":[{"batb":[[0,1.05,999.44]],"batl":[[0,1.07,381.71]],"ltp":1.04,"tv":667.45,"id":8260126},{"batb":[[0,13,7.16],[1,1.01,15.52],[2,1.01,0]],"ltp":13.5,"tv":77.3,"id":4486603}]}]}
{"op":"mcm","clk":"1008750458","pt":1580639309474,"mc":[{"id":"1.168224426","rc":[{"batb":[[1,1.04,775.9]],"batl":[[1,1.08,798.7],[2,1.32,1159.81]],"ltp":1.04,"tv":667.45,"id":8260126}]}]}
{"op":"mcm","clk":"1008750754","pt":1580639313068,"mc":[{"id":"1.168224426","rc":[{"batb":[[0,1.05,241.24],[1,1.04,562.81]],"ltp":1.04,"tv":667.45,"id":8260126}]}]}
{"op":"mcm","clk":"1008751052","pt":1580639316263,"mc":[{"id":"1.168224426","rc":[{"batb":[[0,1.06,960.11],[1,1.05,241.24],[2,1.04,562.81]],"ltp":1.04,"tv":667.45,"id":8260126}]}]}
{"op":"mcm","clk":"1008751088","pt":1580639316638,"mc":[{"id":"1.168224426","rc":[{"batb":[[1,1.05,726.39],[2,1.01,15.51]],"ltp":1.04,"tv":667.45,"id":8260126},{"batb":[[1,12.5,8.03],[2,1.01,15.52]],"ltp":13.5,"tv":77.3,"id":4486603}]}]}
{"op":"mcm","clk":"1008751173","pt":1580639317471,"mc":[{"id":"1.168224426","rc":[{"batb":[[0,1.06,1128.15]],"batl":[[1,1.08,840.71]],"ltp":1.04,"tv":667.45,"id":8260126},{"batb":[[0,13,10.52]],"ltp":13.5,"tv":77.3,"id":4486603}]}]}
{"op":"mcm","clk":"1008752247","pt":1580639329786,"mc":[{"id":"1.168224426","rc":[{"batb":[[0,1.06,376.22]],"batl":[[0,1.08,840.71],[1,1.32,1159.81],[2,1.32,0]],"ltp":1.04,"tv":667.45,"id":8260126},{"batb":[[0,13,3.36]],"ltp":13.5,"tv":77.3,"id":4486603}]}]}
{"op":"mcm","clk":"1008752379","pt":1580639331182,"mc":[{"id":"1.168224426","rc":[{"batb":[[0,1.06,208.18]],"batl":[[0,1.08,798.7]],"ltp":1.04,"tv":667.45,"id":8260126},{"batb":[[0,12.5,8.03],[1,1.01,15.52],[2,1.01,0]],"ltp":13.5,"tv":77.3,"id":4486603}]}]}
{"op":"mcm","clk":"1008752503","pt":1580639332389,"mc":[{"id":"1.168224426","rc":[{"batb":[[1,1.05,1485.48]],"batl":[[0,1.08,1047.84]],"ltp":1.04,"tv":667.45,"id":8260126}]}]}
{"op":"mcm","clk":"1008752527","pt":1580639332556,"mc":[{"id":"1.168224426","rc":[{"batb":[[1,1.05,878.4]],"batl":[[0,1.08,669.66]],"ltp":1.04,"tv":667.45,"id":8260126}]}]}
{"op":"mcm","clk":"1008752802","pt":1580639335191,"mc":[{"id":"1.168224426","rc":[{"batb":[[0,1.06,809.54]],"batl":[[0,1.07,511.95],[1,1.08,669.66],[2,1.32,1159.81]],"ltp":1.04,"tv":667.45,"id":8260126}]}]}
{"op":"mcm","clk":"1008752829","pt":1580639335503,"mc":[{"id":"1.168224426","rc":[{"batb":[[1,1.05,813.75]],"batl":[[0,1.07,448.59]],"ltp":1.04,"tv":667.45,"id":8260126}]}]}
{"op":"mcm","clk":"1008752935","pt":1580639336608,"mc":[{"id":"1.168224426","rc":[{"batb":[[0,1.06,271.65]],"batl":[[0,1.08,669.66],[1,1.32,1159.81],[2,1.32,0]],"ltp":1.04,"tv":667.45,"id":8260126}]}]}
{"op":"mcm","clk":"1008753128","pt":1580639338709,"mc":[{"id":"1.168224426","rc":[{"batl":[[0,1.08,732.44]],"ltp":1.04,"tv":667.45,"id":8260126}]}]}
{"op":"mcm","clk":"1008753290","pt":1580639340130,"mc":[{"id":"1.168224426","rc":[{"batb":[[1,1.05,1421.42]],"batl":[[0,1.07,840.19],[1,1.08,1176.88],[2,1.32,1159.81]],"ltp":1.04,"tv":667.45,"id":8260126}]}]}
{"op":"mcm","clk":"1008753332","pt":1580639340503,"mc":[{"id":"1.168224426","rc":[{"batl":[[1,1.08,216.54]],"ltp":1.04,"tv":667.45,"id":8260126}]}]}
{"op":"mcm","clk":"1008753652","pt":1580639343411,"mc":[{"id":"1.168224426","rc":[{"batl":[[0,1.07,1809.51]],"ltp":1.04,"tv":667.45,"id":8260126}]}]}
{"op":"mcm","clk":"1008753731","pt":1580639344243,"mc":[{"id":"1.168224426","rc":[{"batb":[[1,1.05,936.27],[2,1.04,554.08]],"ltp":1.04,"tv":667.45,"id":8260126},{"batb":[[0,13.5,6.29],[1,13,7.24],[2,1.01,15.52]],"ltp":13.5,"tv":77.3,"id":4486603}]}]}
{"op":"mcm","clk":"1008753862","pt":1580639345400,"mc":[{"id":"1.168224426","rc":[{"batl":[[1,1.08,258.55]],"ltp":1.04,"tv":667.45,"id":8260126},{"batb":[[0,13.5,9.66]],"ltp":13.5,"tv":77.3,"id":4486603}]}]}
{"op":"mcm","clk":"1008754432","pt":1580639351199,"mc":[{"id":"1.168224426","rc":[{"batb":[[0,1.05,936.27],[1,1.04,554.08],[2,1.01,15.51]],"batl":[[0,1.07,1101.22]],"ltp":1.04,"tv":667.45,"id":8260126},{"batb":[[0,13.5,3.36]],"ltp":13.5,"tv":77.3,"id":4486603}]}]}
{"op":"mcm","clk":"1008754565","pt":1580639352504,"mc":[{"id":"1.168224426","rc":[{"batl":[[1,1.08,216.54]],"ltp":1.04,"tv":667.45,"id":8260126},{"batb":[[0,13,7.24],[1,1.01,15.52],[2,1.01,0]],"ltp":13.5,"tv":77.3,"id":4486603}]}]}
{"op":"mcm","clk":"1008754684","pt":1580639353711,"mc":[{"id":"1.168224426","rc":[{"batb":[[0,1.05,1210.51]],"batl":[[1,1.08,918.26]],"ltp":1.04,"tv":667.45,"id":8260126}]}]}
{"op":"mcm","clk":"1008755250","pt":1580639359813,"mc":[{"id":"1.168224426","rc":[{"batl":[[1,1.32,1159.81],[2,1.32,0]],"ltp":1.04,"tv":667.45,"id":8260126}]}]}
{"op":"mcm","clk":"1008755612","pt":1580639363409,"mc":[{"id":"1.168224426","rc":[{"batb":[[0,1.05,1378.55]],"batl":[[0,1.06,415.1],[1,1.07,1658.86],[2,1.32,1159.81]],"ltp":1.04,"tv":667.45,"id":8260126}]}]}
{"op":"mcm","clk":"1008755645","pt":1580639363834,"mc":[{"id":"1.168224426","rc":[{"batb":[[2,1.03,751.18]],"ltp":1.04,"tv":667.45,"id":8260126},{"batb":[[0,15,5.04],[1,13.5,6.53],[2,1.01,15.52]],"ltp":13.5,"tv":77.3,"id":4486603}]}]}
{"op":"mcm","clk":"1008756800","pt":1580639375435,"mc":[{"id":"1.168224426","rc":[{"batb":[[0,1.05,168.04]],"batl":[[0,1.07,1476.66],[1,1.32,1159.81],[2,1.32,0]],"ltp":1.04,"tv":667.45,"id":8260126}]}]}
{"op":"mcm","clk":"1008756910","pt":1580639376440,"mc":[{"id":"1.168224426","rc":[{"batb":[[0,1.03,751.18],[1,1.01,15.51],[2,1.03,0]],"batl":[[0,1.07,1434.65]],"ltp":1.04,"tv":667.45,"id":8260126},{"batb":[[0,13.5,6.53],[1,1.01,15.52],[2,1.01,0]],"ltp":13.5,"tv":77.3,"id":4486603}]}]}
{"op":"mcm","clk":"1008757095","pt":1580639378444,"mc":[{"id":"1.168224426","rc":[{"batb":[[0,1.04,954.14],[1,1.03,1021.78],[2,1.01,15.51]],"batl":[[1,1.08,587.92],[2,1.32,1159.81]],"ltp":1.04,"tv":667.45,"id":8260126}]}]}
{"op":"mcm","clk":"1008757968","pt":1580639386131,"mc":[{"id":"1.168224426","rc":[{"batl":[[0,1.07,840.19],[1,1.32,1159.81],[2,1.32,0]],"ltp":1.04,"tv":667.45,"id":8260126}]}]}
{"op":"mcm","clk":"1008758373","pt":1580639389428,"mc":[{"id":"1.168224426","rc":[{"batb":[[0,1.04,1122.18]],"batl":[[0,1.05,1192.45],[1,1.06,42.01],[2,1.07,840.19]],"ltp":1.04,"tv":667.45,"id":8260126}]}]}
{"op":"mcm","clk":"1008758411","pt":1580639389737,"mc":[{"id":"1.168224426","rc":[{"batb":[[0,18.5,6.06],[1,15.5,4.88],[2,1.01,15.52]],"ltp":13.5,"tv":77.3,"id":4486603}]}]}
{"op":"mcm","clk":"1008758638","pt":1580639391841,"mc":[{"id":"1.168224426","rc":[{"batl":[[0,160,37.1]],"ltp":13.5,"tv":77.3,"id":4486603}]}]}
{"op":"mcm","clk":"1008761804","pt":1580639420421,"mc":[{"id":"1.168224426","rc":[{"batb":[[0,1.04,168.04],[1,1.03,751.18]],"batl":[[0,1.06,42.01],[1,1.07,840.19],[2,1.32,1159.81]],"ltp":1.04,"tv":667.45,"id":8260126}]}]}
{"op":"mcm","clk":"1008761841","pt":1580639420692,"mc":[{"id":"1.168224426","rc":[{"batb":[[1,1.01,15.51],[2,1.01,0]],"ltp":1.04,"tv":667.45,"id":8260126},{"batb":[[0,15.5,4.88],[1,1.01,15.52],[2,1.01,0]],"ltp":13.5,"tv":77.3,"id":4486603}]}]}
{"op":"mcm","clk":"1008762081","pt":1580639423293,"mc":[{"id":"1.168224426","rc":[{"batb":[[0,1.02,1246.11]],"batl":[[0,1.06,537.52],[1,1.07,1495.57]],"ltp":1.04,"tv":667.45,"id":8260126}]}]}
{"op":"mcm","clk":"1008762154","pt":1580639424086,"mc":[{"id":"1.168224426","rc":[{"batb":[[0,1.01,15.51],[1,1.01,0]],"batl":[[0,1.07,840.19],[1,1.32,1159.81],[2,1.32,0]],"ltp":1.04,"tv":667.45,"id":8260126}]}]}
{"op":"mcm","clk":"1008762479","pt":1580639427318,"mc":[{"id":"1.168224426","rc":[{"batb":[[0,1.03,1234.01],[1,1.01,15.51]],"batl":[[0,1.05,1210.51],[1,1.07,840.19],[2,1.32,1159.81]],"ltp":1.04,"tv":667.45,"id":8260126}]}]}
{"op":"mcm","clk":"1008762665","pt":1580639429247,"mc":[{"id":"1.168224426","rc":[{"batb":[[0,1.01,15.51],[1,1.01,0]],"batl":[[0,1.07,840.19],[1,1.32,1159.81],[2,1.32,0]],"ltp":1.04,"tv":667.45,"id":8260126}]}]}
{"op":"mcm","clk":"1008762940","pt":1580639432133,"mc":[{"id":"1.168224426","rc":[{"batb":[[0,1.02,1246.11],[1,1.01,15.51]],"batl":[[0,1.06,537.52],[1,1.07,1495.57],[2,1.1,0.02]],"ltp":1.04,"tv":667.45,"id":8260126}]}]}
{"op":"mcm","clk":"1008764244","pt":1580639443929,"mc":[{"id":"1.168224426","rc":[{"batl":[[0,1.07,840.19],[1,1.1,0.02],[2,1.1,0]],"ltp":1.04,"tv":667.45,"id":8260126}]}]}
{"op":"mcm","clk":"1008764622","pt":1580639447265,"mc":[{"id":"1.168224426","rc":[{"batl":[[0,1.03,1051.69],[1,1.07,840.19],[2,1.1,0.02]],"ltp":1.04,"tv":667.45,"id":8260126},{"batb":[[0,27,3.07],[1,18.5,6.06],[2,1.01,15.52]],"ltp":13.5,"tv":77.3,"id":4486603}]}]}
{"op":"mcm","clk":"1008764736","pt":1580639448363,"mc":[{"id":"1.168224426","rc":[{"batl":[[1,1.04,42.01],[2,1.07,840.19]],"ltp":1.04,"tv":667.45,"id":8260126}]}]}
{"op":"mcm","clk":"1008766284","pt":1580639461404,"mc":[{"id":"1.168224426","rc":[{"batb":[[0,1.01,15.51],[1,1.01,0]],"batl":[[0,1.04,42.01],[1,1.07,840.19],[2,1.29,1298.74]],"ltp":1.04,"tv":667.45,"id":8260126},{"batb":[[0,18.5,6.06],[1,1.01,15.52],[2,1.01,0]],"ltp":13.5,"tv":77.3,"id":4486603}]}]}
{"op":"mcm","clk":"1008766510","pt":1580639463081,"mc":[{"id":"1.168224426","rc":[{"batl":[[0,1.07,840.19],[1,1.1,0.02],[2,1.29,0]],"ltp":1.04,"tv":667.45,"id":8260126}]}]}
{"op":"mcm","clk":"1008766634","pt":1580639464085,"mc":[{"id":"1.168224426","rc":[{"batl":[[0,1.05,1210.51],[1,1.07,840.19],[2,1.1,0.02]],"ltp":1.04,"tv":667.45,"id":8260126}]}]}
{"op":"mcm","clk":"1008767322","pt":1580639471099,"mc":[{"id":"1.168224426","rc":[{"batb":[[0,1.04,809.5],[1,1.03,416.65],[2,1.01,15.51]],"ltp":1.04,"tv":667.45,"id":8260126}]}]}
{"op":"mcm","clk":"1008767413","pt":1580639471834,"mc":[{"id":"1.168224426","rc":[{"batb":[[0,1.04,977.54],[1,1.03,1169.4]],"ltp":1.04,"tv":667.45,"id":8260126},{"batb":[[1,15.5,4.8],[2,1.01,15.52]],"ltp":13.5,"tv":77.3,"id":4486603}]}]}
{"op":"mcm","clk":"1008767649","pt":1580639473827,"mc":[{"id":"1.168224426","rc":[{"batl":[[2,1.3,1224.88]],"ltp":1.04,"tv":667.45,"id":8260126},{"batl":[[0,160,37.1]],"ltp":13.5,"tv":77.3,"id":4486603}]}]}
{"op":"mcm","clk":"1008769513","pt":1580639489324,"mc":[{"id":"1.168224426","rc":[{"batb":[[0,1.04,168.04],[1,1.01,15.51],[2,1.01,0]],"batl":[[0,1.07,840.19],[1,1.3,1224.88],[2,1.3,0]],"ltp":1.04,"tv":667.45,"id":8260126},{"batb":[[0,15.5,4.8],[1,1.01,15.52],[2,1.01,0]],"ltp":13.5,"tv":77.3,"id":4486603}]}]}
{"op":"mcm","clk":"1008769637","pt":1580639490628,"mc":[{"id":"1.168224426","rc":[{"batb":[[0,1.01,15.51],[1,1.01,0]],"ltp":1.04,"tv":667.45,"id":8260126}]}]}
{"op":"mcm","clk":"1008769824","pt":1580639492252,"mc":[{"id":"1.168224426","rc":[{"batl":[[0,1.06,629.15],[1,1.07,1404.79],[2,1.3,1224.88]],"ltp":1.04,"tv":667.45,"id":8260126}]}]}
{"op":"mcm","clk":"1008770169","pt":1580639495340,"mc":[{"id":"1.168224426","rc":[{"batb":[[0,1.05,1061.26],[1,1.01,15.51]],"ltp":1.04,"tv":667.45,"id":8260126}]}]}
{"op":"mcm","clk":"1008770229","pt":1580639495950,"mc":[{"id":"1.168224426","rc":[{"batb":[[0,1.05,1229.3],[1,1.04,567.22],[2,1.02,778.79]],"batl":[[1,1.07,1446.8]],"ltp":1.04,"tv":667.45,"id":8260126},{"batb":[[1,14,6.29],[2,1.01,15.52]],"ltp":13.5,"tv":77.3,"id":4486603}]}]}
{"op":"mcm","clk":"1008770466","pt":1580639498254,"mc":[{"id":"1.168224426","rc":[{"batl":[[0,95,38.77]],"ltp":13.5,"tv":77.3,"id":4486603}]}]}
{"op":"mcm","clk":"1008771150","pt":1580639505354,"mc":[{"id":"1.168224426","rc":[{"batb":[[0,1.05,168.04],[1,1.02,778.79],[2,1.01,15.51]],"batl":[[0,1.07,1446.8],[1,1.3,1224.88],[2,1.3,0]],"ltp":1.04,"tv":667.45,"id":8260126},{"batb":[[0,14,6.29],[1,1.01,15.52],[2,1.01,0]],"ltp":13.5,"tv":77.3,"id":4486603}]}]}
{"op":"mcm","clk":"1008771275","pt":1580639506568,"mc":[{"id":"1.168224426","rc":[{"batb":[[0,1.02,778.79],[1,1.01,15.51],[2,1.01,0]],"batl":[[0,1.07,1404.79]],"ltp":1.04,"tv":667.45,"id":8260126}]}]}
{"op":"mcm","clk":"1008771440","pt":1580639508180,"mc":[{"id":"1.168224426","rc":[{"batb":[[0,1.04,672.85],[1,1.03,554.63],[2,1.02,778.79]],"batl":[[0,1.07,1617.31],[1,1.08,406.95],[2,1.3,1224.88]],"ltp":1.04,"tv":667.45,"id":8260126}]}]}
{"op":"mcm","clk":"1008771884","pt":1580639512580,"mc":[{"id":"1.168224426","rc":[{"batb":[[0,1.02,778.79],[1,1.01,15.51],[2,1.02,0]],"ltp":1.04,"tv":667.45,"id":8260126}]}]}
{"op":"mcm","clk":"1008772305","pt":1580639516206,"mc":[{"id":"1.168224426","rc":[{"batb":[[0,1.06,496.2],[1,1.05,1195.35],[2,1.03,717.11]],"ltp":1.04,"tv":667.45,"id":8260126},{"batb":[[1,8.8,7],[2,1.01,15.52]],"ltp":13.5,"tv":77.3,"id":4486603}]}]}
{"op":"mcm","clk":"1008772553","pt":1580639518129,"mc":[{"id":"1.168224426","rc":[{"batl":[[1,1.08,448.96]],"ltp":1.04,"tv":667.45,"id":8260126},{"batb":[[1,13.5,3.36],[2,8.8,7]],"batl":[[0,65,40.67]],"ltp":13.5,"tv":77.3,"id":4486603}]}]}
{"op":"mcm","clk":"1008772627","pt":1580639518709,"mc":[{"id":"1.168224426","rc":[{"batb":[[0,1.06,664.24]],"ltp":1.04,"tv":667.45,"id":8260126}]}]}
{"op":"mcm","clk":"1008775387","pt":1580639544394,"mc":[{"id":"1.168224426","rc":[{"batb":[[0,1.06,168.04],[1,1.05,485.78]],"batl":[[0,1.07,840.19],[1,1.08,42.01]],"ltp":1.04,"tv":667.45,"id":8260126}]}]}
{"op":"mcm","clk":"1008775435","pt":1580639544762,"mc":[{"id":"1.168224426","rc":[{"batb":[[0,1.03,717.11],[1,1.01,15.51],[2,1.03,0]],"batl":[[1,1.3,1224.88],[2,1.3,0]],"ltp":1.04,"tv":667.45,"id":8260126},{"batb":[[0,8.8,7],[1,1.01,15.52],[2,8.8,0]],"ltp":13.5,"tv":77.3,"id":4486603}]}]}
{"op":"mcm","clk":"1008775811","pt":1580639548224,"mc":[{"id":"1.168224426","rc":[{"batl":[[0,1.3,1224.88],[1,1.3,0]],"ltp":1.04,"tv":667.45,"id":8260126}]}]}
{"op":"mcm","clk":"1008776071","pt":1580639550310,"mc":[{"id":"1.168224426","rc":[{"batb":[[0,1.06,1199.09],[1,1.03,717.11],[2,1.01,15.51]],"batl":[[0,1.08,920.27],[1,1.09,254.25],[2,1.3,1224.88]],"ltp":1.04,"tv":667.45,"id":8260126}]}]}
{"op":"mcm","clk":"1008776303","pt":1580639552323,"mc":[{"id":"1.168224426","rc":[{"batb":[[0,1.03,717.11],[1,1.01,15.51],[2,1.01,0]],"batl":[[0,1.3,1224.88],[1,1.09,0],[2,1.3,0]],"ltp":1.04,"tv":667.45,"id":8260126},{"batl":[[0,42,43.68]],"ltp":13.5,"tv":77.3,"id":4486603}]}]}
{"op":"mcm","clk":"1008776594","pt":1580639555200,"mc":[{"id":"1.168224426","rc":[{"batb":[[0,1.04,1222.15],[1,1.03,717.11],[2,1.01,15.51]],"batl":[[0,1.12,1115.47],[1,1.3,1224.86]],"ltp":1.04,"tv":667.45,"id":8260126}]}]}
{"op":"mcm","clk":"1008776617","pt":1580639555517,"mc":[{"id":"1.168224426","rc":[{"batb":[[0,1.03,717.11],[1,1.01,15.51],[2,1.01,0]],"batl":[[0,1.3,1224.88],[1,1.3,0]],"ltp":1.04,"tv":667.45,"id":8260126}]}]}
{"op":"mcm","clk":"1008777093","pt":1580639559302,"mc":[{"id":"1.168224426","rc":[{"batb":[[0,1.04,1222.15],[1,1.03,717.11],[2,1.02,1031.76]],"batl":[[0,1.05,634.66],[1,1.06,570.4],[2,1.3,1224.88]],"ltp":1.04,"tv":667.45,"id":8260126},{"batb":[[0,18,6.61],[1,12,8.97],[2,1.01,15.52]],"ltp":13.5,"tv":77.3,"id":4486603}]}]}
{"op":"mcm","clk":"1008777127","pt":1580639559629,"mc":[{"id":"1.168224426","rc":[{"batl":[[1,1.06,612.41]],"ltp":1.04,"tv":667.45,"id":8260126}]}]}
{"op":"mcm","clk":"1008777408","pt":1580639561427,"mc":[{"id":"1.168224426","rc":[{"batl":[[0,160,37.1]],"ltp":13.5,"tv":77.3,"id":4486603}]}]}
{"op":"mcm","clk":"1008779062","pt":1580639577064,"mc":[{"id":"1.168224426","rc":[{"batb":[[0,1.02,1031.76],[1,1.01,15.51],[2,1.02,0]],"batl":[[0,1.06,42.01],[1,1.3,1224.88],[2,1.3,0]],"ltp":1.04,"tv":667.45,"id":8260126},{"batb":[[0,12,8.97],[1,1.01,15.52],[2,1.01,0]],"ltp":13.5,"tv":77.3,"id":4486603}]}]}
{"op":"mcm","clk":"1008779218","pt":1580639578746,"mc":[{"id":"1.168224426","rc":[{"batl":[[0,1.3,1224.88],[1,1.3,0]],"ltp":1.04,"tv":667.45,"id":8260126}]}]}
{"op":"mcm","clk":"1008779347","pt":1580639580265,"mc":[{"id":"1.168224426","rc":[{"batb":[[0,1.03,1234.01],[1,1.02,1031.76],[2,1.01,15.51]],"batl":[[0,1.08,625.13],[1,1.09,546.68],[2,1.3,1224.88]],"ltp":1.04,"tv":667.45,"id":8260126}]}]}
{"op":"mcm","clk":"1008779497","pt":1580639581758,"mc":[{"id":"1.168224426","rc":[{"batl":[[0,1.3,1224.88],[1,1.09,0],[2,1.3,0]],"ltp":1.04,"tv":667.45,"id":8260126}]}]}
{"op":"mcm","clk":"1008779883","pt":1580639585383,"mc":[{"id":"1.168224426","rc":[{"batl":[[0,1.04,1222.15],[1,1.3,1224.88]],"ltp":1.04,"tv":667.45,"id":8260126},{"batb":[[0,23,3.15],[1,16.5,4.09],[2,12,8.97]],"ltp":13.5,"tv":77.3,"id":4486603}]}]}
{"op":"mcm","clk":"1008779914","pt":1580639585691,"mc":[{"id":"1.168224426","rc":[{"batb":[[0,1.03,1402.05]],"ltp":1.04,"tv":667.45,"id":8260126},{"batb":[[2,1.01,15.52]],"ltp":13.5,"tv":77.3,"id":4486603}]}]}
{"op":"mcm","clk":"1008780117","pt":1580639587776,"mc":[{"id":"1.168224426","rc":[{"batl":[[0,520,35.52]],"ltp":13.5,"tv":77.3,"id":4486603}]}]}
{"op":"mcm","clk":"1008781173","pt":1580639598289,"mc":[{"id":"1.168224426","rc":[{"batb":[[0,1.03,168.04],[1,1.01,15.51],[2,1.01,0]],"batl":[[0,1.3,1224.88],[1,1.3,0]],"ltp":1.04,"tv":667.45,"id":8260126},{"batb":[[0,16.5,4.09],[1,1.01,15.52],[2,1.01,0]],"ltp":13.5,"tv":77.3,"id":4486603}]}]}
{"op":"mcm","clk":"1008781215","pt":1580639598659,"mc":[{"id":"1.168224426","rc":[{"batb":[[0,1.01,15.51],[1,1.01,0]],"ltp":1.04,"tv":667.45,"id":8260126}]}]}
{"op":"mcm","clk":"1008781431","pt":1580639600968,"mc":[{"id":"1.168224426","rc":[{"batb":[[0,1.02,1246.11],[1,1.01,15.51]],"batl":[[0,1.06,1199.09],[1,1.3,1224.88]],"ltp":1.04,"tv":667.45,"id":8260126}]}]}
{"op":"mcm","clk":"1008781582","pt":1580639602277,"mc":[{"id":"1.168224426","rc":[{"batl":[[0,1.3,1224.88],[1,1.3,0]],"ltp":1.04,"tv":667.45,"id":8260126}]}]}
{"op":"mcm","clk":"1008781864","pt":1580639605184,"mc":[{"id":"1.168224426","rc":[{"batl":[[0,1.03,352.85],[1,1.04,872.69],[2,1.3,1224.88]],"ltp":1.04,"tv":667.45,"id":8260126},{"batb":[[0,28,2.69],[1,23,3.15],[2,16.5,4.09]],"ltp":13.5,"tv":77.3,"id":4486603}]}]}
{"op":"mcm","clk":"1008781914","pt":1580639605608,"mc":[{"id":"1.168224426","rc":[{"batl":[[1,1.04,914.7]],"ltp":1.04,"tv":667.45,"id":8260126},{"batb":[[2,1.01,15.52]],"ltp":13.5,"tv":77.3,"id":4486603}]}]}
{"op":"mcm","clk":"1008782671","pt":1580639612319,"mc":[{"id":"1.168224426","rc":[{"batl":[[0,1.04,914.7],[1,1.3,1224.88],[2,1.3,0]],"ltp":1.04,"tv":667.45,"id":8260126}]}]}
{"op":"mcm","clk":"1008782708","pt":1580639612585,"mc":[{"id":"1.168224426","rc":[{"batl":[[0,1.04,872.69]],"ltp":1.04,"tv":667.45,"id":8260126},{"batb":[[0,23,3.15],[1,1.01,15.52],[2,1.01,0]],"ltp":13.5,"tv":77.3,"id":4486603}]}]}
{"op":"mcm","clk":"1008782986","pt":1580639615390,"mc":[{"id":"1.168224426","rc":[{"batl":[[0,1.04,1222.15]],"ltp":1.04,"tv":667.45,"id":8260126}]}]}
{"op":"mcm","clk":"1008784030","pt":1580639625347,"mc":[{"id":"1.168224426","rc":[{"batl":[[0,1.3,1224.88],[1,1.3,0]],"ltp":1.04,"tv":667.45,"id":8260126}]}]}
{"op":"mcm","clk":"1008784361","pt":1580639628334,"mc":[{"id":"1.168224426","rc":[{"batl":[[0,1.03,1234.01],[1,1.3,1224.88]],"ltp":1.04,"tv":667.45,"id":8260126}]}]}
{"op":"mcm","clk":"1008784436","pt":1580639628914,"mc":[{"id":"1.168224426","rc":[{"batb":[[0,27,3.23]],"ltp":13.5,"tv":77.3,"id":4486603}]}]}
{"op":"mcm","clk":"1008794849","pt":1580639725355,"mc":[{"id":"1.168224426","rc":[{"batl":[[0,1.03,2914.4]],"ltp":1.04,"tv":667.45,"id":8260126}]}]}
{"op":"mcm","clk":"1008795270","pt":1580639729134,"mc":[{"id":"1.168224426","rc":[{"batb":[[0,1.01,15.51],[1,1.01,0]],"batl":[[0,1.03,1680.39]],"ltp":1.04,"tv":667.45,"id":8260126}]}]}
{"op":"mcm","clk":"1008795594","pt":1580639732054,"mc":[{"id":"1.168224426","rc":[{"batb":[[0,1.01,1273.96]],"batl":[[1,1.04,1222.15],[2,1.3,1224.88]],"ltp":1.04,"tv":667.45,"id":8260126}]}]}
{"op":"mcm","clk":"1008796860","pt":1580639742768,"mc":[{"id":"1.168224426","rc":[{"batl":[[1,1.3,1224.88],[2,1.3,0]],"ltp":1.04,"tv":667.45,"id":8260126}]}]}
{"op":"mcm","clk":"1008797144","pt":1580639745436,"mc":[{"id":"1.168224426","rc":[{"batl":[[0,1.03,2914.4]],"ltp":1.04,"tv":667.45,"id":8260126}]}]}
{"op":"mcm","clk":"1008797236","pt":1580639746167,"mc":[{"id":"1.168224426","rc":[{"batl":[[0,1.03,2956.41]],"ltp":1.04,"tv":667.45,"id":8260126},{"batb":[[0,30,2.75],[1,27,3.23],[2,1.01,15.52]],"ltp":13.5,"tv":77.3,"id":4486603}]}]}
{"op":"mcm","clk":"1008797268","pt":1580639746480,"mc":[{"id":"1.168224426","rc":[{"batb":[[1,1.01,15.52],[2,1.01,0]],"ltp":13.5,"tv":77.3,"id":4486603}]}]}
{"op":"mcm","clk":"1008798248","pt":1580639755272,"mc":[{"id":"1.168224426","rc":[{"batb":[[0,1.01,15.52],[1,1.01,0]],"ltp":13.5,"tv":77.3,"id":4486603}]}]}
{"op":"mcm","clk":"1008798465","pt":1580639757145,"mc":[{"id":"1.168224426","rc":[{"batl":[[0,1.03,2914.4],[1,1.1,0.02]],"ltp":1.04,"tv":667.45,"id":8260126}]}]}
{"op":"mcm","clk":"1008798602","pt":1580639758458,"mc":[{"id":"1.168224426","rc":[{"batb":[[0,1.01,15.51]],"ltp":1.04,"tv":667.45,"id":8260126}]}]}
{"op":"mcm","clk":"1008799023","pt":1580639762188,"mc":[{"id":"1.168224426","rc":[{"batb":[[0,1.02,1246.11],[1,1.01,15.51]],"ltp":1.04,"tv":667.45,"id":8260126},{"batb":[[0,27,3.12],[1,1.01,15.52]],"ltp":13.5,"tv":77.3,"id":4486603}]}]}
{"op":"mcm","clk":"1008799263","pt":1580639764338,"mc":[{"id":"1.168224426","rc":[{"batl":[[1,1.29,1298.74]],"ltp":1.04,"tv":667.45,"id":8260126}]}]}
{"op":"mcm","clk":"1008799736","pt":1580639768281,"mc":[{"id":"1.168224426","rc":[{"batb":[[0,1.01,15.51],[1,1.01,0]],"batl":[[0,1.03,1680.39]],"ltp":1.04,"tv":667.45,"id":8260126}]}]}
{"op":"mcm","clk":"1008800097","pt":1580639771055,"mc":[{"id":"1.168224426","rc":[{"batb":[[0,1.01,1273.96]],"batl":[[1,1.04,1222.15],[2,1.29,1298.74]],"ltp":1.04,"tv":667.45,"id":8260126}]}]}
{"op":"mcm","clk":"1008800813","pt":1580639776775,"mc":[{"id":"1.168224426","rc":[{"batl":[[1,1.29,1298.74],[2,1.29,0]],"ltp":1.04,"tv":667.45,"id":8260126}]}]}
{"op":"mcm","clk":"1008800923","pt":1580639777756,"mc":[{"id":"1.168224426","rc":[{"batb":[[0,1.01,15.52],[1,1.01,0]],"ltp":13.5,"tv":77.3,"id":4486603}]}]}
{"op":"mcm","clk":"1008801179","pt":1580639779989,"mc":[{"id":"1.168224426","rc":[{"batl":[[0,1.02,1246.11],[1,1.03,1680.39],[2,1.29,1298.74]],"ltp":1.04,"tv":667.45,"id":8260126}]}]}
{"op":"mcm","clk":"1008802631","pt":1580639792797,"mc":[{"id":"1.168224426","rc":[{"batb":[[0,1.01,15.51]],"batl":[[0,1.03,1680.39],[1,1.29,1298.74],[2,1.29,0]],"ltp":1.04,"tv":667.45,"id":8260126}]}]}
{"op":"mcm","clk":"1008802828","pt":1580639794512,"mc":[{"id":"1.168224426","rc":[{"batl":[[1,1.1,0.02]],"ltp":1.04,"tv":667.45,"id":8260126}]}]}
{"op":"mcm","clk":"1008803218","pt":1580639798171,"mc":[{"id":"1.168224426","rc":[{"batb":[[0,1.01,1273.96]],"batl":[[0,1.02,1246.11],[1,1.03,1680.39],[2,1.1,0.02]],"ltp":1.04,"tv":667.45,"id":8260126}]}]}
{"op":"mcm","clk":"1008803417","pt":1580639800203,"mc":[{"id":"1.168224426","rc":[{"batb":[[0,1.01,15.51]],"batl":[[0,1.03,1680.39],[1,1.1,0.02],[2,1.1,0]],"ltp":1.04,"tv":667.45,"id":8260126}]}]}
{"op":"mcm","clk":"1008803737","pt":1580639803108,"mc":[{"id":"1.168224426","rc":[{"batl":[[0,1.03,2914.4]],"ltp":1.04,"tv":667.45,"id":8260126}]}]}
{"op":"mcm","clk":"1008804543","pt":1580639811317,"mc":[{"id":"1.168224426","rc":[{"batb":[[0,1.02,1246.11],[1,1.01,15.51]],"ltp":1.04,"tv":667.45,"id":8260126}]}]}
{"op":"mcm","clk":"1008804578","pt":1580639811730,"mc":[{"id":"1.168224426","rc":[{"batb":[[0,1.02,1414.15]],"ltp":1.04,"tv":667.45,"id":8260126},{"batb":[[0,27,3.17],[1,1.01,15.52]],"ltp":13.5,"tv":77.3,"id":4486603}]}]}
{"op":"mcm","clk":"1008804773","pt":1580639813649,"mc":[{"id":"1.168224426","rc":[{"batl":[[1,1.29,1298.74]],"ltp":1.04,"tv":667.45,"id":8260126}]}]}
{"op":"mcm","clk":"1008806108","pt":1580639825847,"mc":[{"id":"1.168224426","rc":[{"batb":[[0,1.02,168.04]],"batl":[[0,1.03,1680.39]],"ltp":1.04,"tv":667.45,"id":8260126}]}]}
{"op":"mcm","clk":"1008806214","pt":1580639826739,"mc":[{"id":"1.168224426","rc":[{"batb":[[0,1.01,15.51],[1,1.01,0]],"ltp":1.04,"tv":667.45,"id":8260126}]}]}
{"op":"mcm","clk":"1008806383","pt":1580639828349,"mc":[{"id":"1.168224426","rc":[{"batb":[[0,1.01,1273.96]],"batl":[[1,1.04,1222.15],[2,1.1,0.02]],"ltp":1.04,"tv":667.45,"id":8260126}]}]}
{"op":"mcm","clk":"1008806917","pt":1580639833846,"mc":[{"id":"1.168224426","rc":[{"batb":[[0,1.01,15.51]],"ltp":1.04,"tv":667.45,"id":8260126}]}]}
{"op":"mcm","clk":"1008807331","pt":1580639837144,"mc":[{"id":"1.168224426","rc":[{"batb":[[0,1.02,1246.11],[1,1.01,15.51]],"ltp":1.04,"tv":667.45,"id":8260126},{"batb":[[1,24,5.16],[2,1.01,15.52]],"ltp":13.5,"tv":77.3,"id":4486603}]}]}
{"op":"mcm","clk":"1008807396","pt":1580639837670,"mc":[{"id":"1.168224426","rc":[{"batl":[[1,1.04,1264.16]],"ltp":1.04,"tv":667.45,"id":8260126}]}]}
{"op":"mcm","clk":"1008807541","pt":1580639838972,"mc":[{"id":"1.168224426","rc":[{"batl":[[2,1.29,1276.57]],"ltp":1.04,"tv":667.45,"id":8260126}]}]}
{"op":"mcm","clk":"1008809468","pt":1580639855211,"mc":[{"id":"1.168224426","rc":[{"batb":[[0,24,5.16],[1,1.01,15.52],[2,1.01,0]],"ltp":13.5,"tv":77.3,"id":4486603}]}]}
{"op":"mcm","clk":"1008809675","pt":1580639856994,"mc":[{"id":"1.168224426","rc":[{"batl":[[1,1.04,907.89]],"ltp":1.04,"tv":667.45,"id":8260126}]}]}
{"op":"mcm","clk":"1008810032","pt":1580639860227,"mc":[{"id":"1.168224426","rc":[{"batl":[[0,1.03,1997.7]],"ltp":1.04,"tv":667.45,"id":8260126}]}]}
{"op":"mcm","clk":"1008810624","pt":1580639863421,"mc":[{"id":"1.168224426","rc":[{"batl":[[0,1.03,1680.39]],"ltp":1.04,"tv":667.45,"id":8260126}]}]}
{"op":"mcm","clk":"1008810899","pt":1580639865589,"mc":[{"id":"1.168224426","rc":[{"batl":[[1,1.04,1222.15]],"ltp":1.04,"tv":667.45,"id":8260126}]}]}
{"op":"mcm","clk":"1008811182","pt":1580639866904,"mc":[{"id":"1.168224426","rc":[{"batl":[[1,1.29,1276.57],[2,1.29,0]],"ltp":1.04,"tv":667.45,"id":8260126}]}]}
{"op":"mcm","clk":"1008811702","pt":1580639869915,"mc":[{"id":"1.168224426","rc":[{"batl":[[0,1.03,2914.4]],"ltp":1.04,"tv":667.45,"id":8260126}]}]}
{"op":"mcm","clk":"1008811791","pt":1580639870698,"mc":[{"id":"1.168224426","rc":[{"batb":[[0,27,3.17]],"ltp":13.5,"tv":77.3,"id":4486603}]}]}
{"op":"mcm","clk":"1008811908","pt":1580639871685,"mc":[{"id":"1.168224426","rc":[{"batb":[[0,1.02,1414.15]],"ltp":1.04,"tv":667.45,"id":8260126}]}]}
{"op":"mcm","clk":"1008812911","pt":1580639881350,"mc":[{"id":"1.168224426","rc":[{"batb":[[0,1.02,168.04]],"batl":[[0,1.03,1680.39]],"ltp":1.04,"tv":667.45,"id":8260126}]}]}
{"op":"mcm","clk":"1008813150","pt":1580639883445,"mc":[{"id":"1.168224426","rc":[{"batb":[[0,1.01,15.51],[1,1.01,0]],"batl":[[1,1.1,0.02]],"ltp":1.04,"tv":667.45,"id":8260126}]}]}
{"op":"mcm","clk":"1008813246","pt":1580639884329,"mc":[{"id":"1.168224426","rc":[{"batb":[[0,1.01,1273.96]],"batl":[[1,1.04,1222.15],[2,1.1,0.02]],"ltp":1.04,"tv":667.45,"id":8260126}]}]}
{"op":"mcm","clk":"1008813387","pt":1580639885428,"mc":[{"id":"1.168224426","rc":[{"batb":[[0,1.01,15.51]],"ltp":1.04,"tv":667.45,"id":8260126}]}]}
{"op":"mcm","clk":"1008813719","pt":1580639888415,"mc":[{"id":"1.168224426","rc":[{"batb":[[0,1.02,1246.11],[1,1.01,15.51]],"ltp":1.04,"tv":667.45,"id":8260126}]}]}
{"op":"mcm","clk":"1008813777","pt":1580639888934,"mc":[{"id":"1.168224426","rc":[{"batb":[[1,24,5.04],[2,1.01,15.52]],"ltp":13.5,"tv":77.3,"id":4486603}]}]}
{"op":"mcm","clk":"1008813844","pt":1580639889710,"mc":[{"id":"1.168224426","rc":[{"batl":[[1,1.04,1264.16]],"ltp":1.04,"tv":667.45,"id":8260126}]}]}
{"op":"mcm","clk":"1008814063","pt":1580639891636,"mc":[{"id":"1.168224426","rc":[{"batl":[[2,1.29,1276.57]],"ltp":1.04,"tv":667.45,"id":8260126}]}]}
{"op":"mcm","clk":"1008815001","pt":1580639899867,"mc":[{"id":"1.168224426","rc":[{"batb":[[0,24,5.04],[1,1.01,15.52],[2,1.01,0]],"ltp":13.5,"tv":77.3,"id":4486603}]}]}
{"op":"mcm","clk":"1008815096","pt":1580639900754,"mc":[{"id":"1.168224426","rc":[{"batl":[[1,1.04,1222.15]],"ltp":1.04,"tv":667.45,"id":8260126}]}]}
{"op":"mcm","clk":"1008815318","pt":1580639902945,"mc":[{"id":"1.168224426","rc":[{"batl":[[1,1.04,815.53]],"ltp":1.04,"tv":667.45,"id":8260126}]}]}
{"op":"mcm","clk":"1008815629","pt":1580639905937,"mc":[{"id":"1.168224426","rc":[{"batl":[[0,1.03,2090.95]],"ltp":1.04,"tv":667.45,"id":8260126}]}]}
{"op":"mcm","clk":"1008815734","pt":1580639907036,"mc":[{"id":"1.168224426","rc":[{"batl":[[0,1.03,1680.39]],"ltp":1.04,"tv":667.45,"id":8260126}]}]}
{"op":"mcm","clk":"1008816100","pt":1580639910213,"mc":[{"id":"1.168224426","rc":[{"batl":[[1,1.04,1222.15]],"ltp":1.04,"tv":667.45,"id":8260126}]}]}
{"op":"mcm","clk":"1008816959","pt":1580639918053,"mc":[{"id":"1.168224426","rc":[{"batb":[[0,1.01,15.51],[1,1.01,0]],"ltp":1.04,"tv":667.45,"id":8260126}]}]}
{"op":"mcm","clk":"1008817326","pt":1580639921359,"mc":[{"id":"1.168224426","rc":[{"trd":[[1.03,2468.02]],"batb":[[0,1.01,1430]],"batl":[[0,1.03,446.38]],"ltp":1.03,"tv":3135.47,"id":8260126}],"tv":3212.78}]}
{"op":"mcm","clk":"1008817374","pt":1580639921867,"mc":[{"id":"1.168224426","rc":[{"trd":[[1.03,2888.12]],"batl":[[0,1.03,236.33]],"ltp":1.03,"tv":3555.57,"id":8260126},{"batb":[[1,12.5,8.1],[2,1.01,15.52]],"ltp":13.5,"tv":77.3,"id":4486603}],"tv":3632.88}]}
{"op":"mcm","clk":"1008817676","pt":1580639924381,"mc":[{"id":"1.168224426","rc":[{"trd":[[1.03,3360.78]],"batb":[[0,1.03,997.68],[1,1.01,1430]],"batl":[[0,1.04,1222.15],[1,1.29,1276.57],[2,1.29,0]],"ltp":1.03,"tv":4028.23,"id":8260126},{"batl":[[0,520,35.52]],"ltp":13.5,"tv":77.3,"id":4486603}],"tv":4105.54}]}
{"op":"mcm","clk":"1008817788","pt":1580639925279,"mc":[{"id":"1.168224426","rc":[{"batb":[[0,1.03,1207.73],[1,1.01,15.51]],"ltp":1.03,"tv":4028.23,"id":8260126}]}]}
{"op":"mcm","clk":"1008817826","pt":1580639925588,"mc":[{"id":"1.168224426","rc":[{"batb":[[0,1.03,997.68]],"ltp":1.03,"tv":4028.23,"id":8260126}]}]}
{"op":"mcm","clk":"1008818024","pt":1580639927677,"mc":[{"id":"1.168224426","rc":[{"batb":[[0,1.03,1402.05]],"ltp":1.03,"tv":4028.23,"id":8260126}]}]}
{"op":"mcm","clk":"1008820442","pt":1580639948387,"mc":[{"id":"1.168224426","rc":[{"batb":[[0,1.03,168.04]],"batl":[[0,1.29,1276.57],[1,1.29,0]],"ltp":1.03,"tv":4028.23,"id":8260126}]}]}
{"op":"mcm","clk":"1008820494","pt":1580639948802,"mc":[{"id":"1.168224426","rc":[{"batb":[[0,1.01,15.51],[1,1.01,0]],"ltp":1.03,"tv":4028.23,"id":8260126},{"batb":[[0,12.5,8.1],[1,1.01,15.52],[2,1.01,0]],"ltp":13.5,"tv":77.3,"id":4486603}]}]}
{"op":"mcm","clk":"1008820746","pt":1580639951103,"mc":[{"id":"1.168224426","rc":[{"batb":[[0,1.01,1273.96]],"batl":[[0,1.08,771.01],[1,1.09,402.14],[2,1.1,0.02]],"ltp":1.03,"tv":4028.23,"id":8260126}]}]}
{"op":"mcm","clk":"1008820838","pt":1580639951994,"mc":[{"id":"1.168224426","rc":[{"batb":[[0,1.01,15.51]],"batl":[[0,1.1,0.02],[1,1.09,0],[2,1.1,0]],"ltp":1.03,"tv":4028.23,"id":8260126}]}]}
{"op":"mcm","clk":"1008821216","pt":1580639955292,"mc":[{"id":"1.168224426","rc":[{"batb":[[0,1.03,1234.01],[1,1.01,15.51]],"batl":[[0,1.05,1210.51],[1,1.1,0.02]],"ltp":1.03,"tv":4028.23,"id":8260126}]}]}
{"op":"mcm","clk":"1008821414","pt":1580639957121,"mc":[{"id":"1.168224426","rc":[{"batl":[[1,1.3,1224.88]],"ltp":1.03,"tv":4028.23,"id":8260126},{"batl":[[0,160,37.1]],"ltp":13.5,"tv":77.3,"id":4486603}]}]}
{"op":"mcm","clk":"1008821531","pt":1580639958156,"mc":[{"id":"1.168224426","rc":[{"batb":[[0,1.01,15.51],[1,1.01,0]],"batl":[[0,1.3,1224.88],[1,1.3,0]],"ltp":1.03,"tv":4028.23,"id":8260126}]}]}
{"op":"mcm","clk":"1008821761","pt":1580639959954,"mc":[{"id":"1.168224426","rc":[{"batl":[[0,1.1,0.02]],"ltp":1.03,"tv":4028.23,"id":8260126}]}]}
{"op":"mcm","clk":"1008821873","pt":1580639960848,"mc":[{"id":"1.168224426","rc":[{"batl":[[0,1.08,771.01],[1,1.09,402.14],[2,1.1,0.02]],"ltp":1.03,"tv":4028.23,"id":8260126}]}]}
{"op":"mcm","clk":"1008822170","pt":1580639963375,"mc":[{"id":"1.168224426","rc":[{"batb":[[0,1.07,310.09],[1,1.06,886.07],[2,1.01,15.51]],"ltp":1.03,"tv":4028.23,"id":8260126}]}]}
{"op":"mcm","clk":"1008822214","pt":1580639963741,"mc":[{"id":"1.168224426","rc":[{"batb":[[2,1.05,419.69]],"ltp":1.03,"tv":4028.23,"id":8260126},{"batb":[[0,12.5,11.47],[1,6.8,13.14],[2,1.01,15.52]],"ltp":13.5,"tv":77.3,"id":4486603}]}]}
{"op":"mcm","clk":"1008822373","pt":1580639965166,"mc":[{"id":"1.168224426","rc":[{"batl":[[2,1.34,1109.81]],"ltp":1.03,"tv":4028.23,"id":8260126},{"batl":[[0,42,43.68]],"ltp":13.5,"tv":77.3,"id":4486603}]}]}
{"op":"mcm","clk":"1008822608","pt":1580639967370,"mc":[{"id":"1.168224426","rc":[{"batb":[[0,12.5,8.1]],"ltp":13.5,"tv":77.3,"id":4486603}]}]}
{"op":"mcm","clk":"1008822954","pt":1580639970277,"mc":[{"id":"1.168224426","rc":[{"batb":[[0,13,3.36],[1,12.5,8.1],[2,6.8,13.14]],"ltp":13.5,"tv":77.3,"id":4486603}]}]}
{"op":"mcm","clk":"1008824084","pt":1580639980068,"mc":[{"id":"1.168224426","rc":[{"batb":[[0,1.02,809.64],[1,1.01,15.51],[2,1.05,0]],"batl":[[0,1.34,1109.81],[1,1.09,0],[2,1.34,0]],"ltp":1.03,"tv":4028.23,"id":8260126},{"batb":[[1,6.8,13.14],[2,1.01,15.52]],"ltp":13.5,"tv":77.3,"id":4486603}]}]}
{"op":"mcm","clk":"1008824186","pt":1580639981064,"mc":[{"id":"1.168224426","rc":[{"batl":[[0,1.1,0.02]],"ltp":1.03,"tv":4028.23,"id":8260126},{"batb":[[0,6.8,13.14],[1,1.01,15.52],[2,1.01,0]],"ltp":13.5,"tv":77.3,"id":4486603}]}]}
{"op":"mcm","clk":"1008824461","pt":1580639983363,"mc":[{"id":"1.168224426","rc":[{"batb":[[0,1.04,553.05],[1,1.03,675.59],[2,1.02,809.64]],"ltp":1.03,"tv":4028.23,"id":8260126}]}]}
{"op":"mcm","clk":"1008824728","pt":1580639985454,"mc":[{"id":"1.168224426","rc":[{"batl":[[0,1.05,1210.51],[1,1.1,0.02]],"ltp":1.03,"tv":4028.23,"id":8260126}]}]}
{"op":"mcm","clk":"1008824812","pt":1580639986188,"mc":[{"id":"1.168224426","rc":[{"batb":[[0,19.5,5.35],[1,9.4,15.34],[2,1.01,15.52]],"ltp":13.5,"tv":77.3,"id":4486603}]}]}
{"op":"mcm","clk":"1008825028","pt":1580639988167,"mc":[{"id":"1.168224426","rc":[{"batl":[[1,1.3,1224.88]],"ltp":1.03,"tv":4028.23,"id":8260126},{"batl":[[0,160,37.1]],"ltp":13.5,"tv":77.3,"id":4486603}]}]}
{"op":"mcm","clk":"1008825507","pt":1580639992564,"mc":[{"id":"1.168224426","rc":[{"batb":[[0,1.04,494.23]],"ltp":1.03,"tv":4028.23,"id":8260126}]}]}
{"op":"mcm","clk":"1008825864","pt":1580639995610,"mc":[{"id":"1.168224426","rc":[{"batb":[[1,1.03,734.97]],"ltp":1.03,"tv":4028.23,"id":8260126}]}]}
{"op":"mcm","clk":"1008826024","pt":1580639997312,"mc":[{"id":"1.168224426","rc":[{"batb":[[0,1.01,15.51],[1,1.03,0],[2,1.02,0]],"batl":[[0,1.3,1224.88],[1,1.3,0]],"ltp":1.03,"tv":4028.23,"id":8260126},{"batb":[[0,9.4,15.34],[1,1.01,15.52],[2,1.01,0]],"ltp":13.5,"tv":77.3,"id":4486603}]}]}
{"op":"mcm","clk":"1008826235","pt":1580639999396,"mc":[{"id":"1.168224426","rc":[{"batl":[[0,1.1,0.02]],"ltp":1.03,"tv":4028.23,"id":8260126}]}]}
{"op":"mcm","clk":"1008826288","pt":1580639999909,"mc":[{"id":"1.168224426","rc":[{"batb":[[0,1.01,1273.96]],"batl":[[0,1.11,947.02],[1,1.12,196.3]],"ltp":1.03,"tv":4028.23,"id":8260126}]}]}
{"op":"mcm","clk":"1008827150","pt":1580640008440,"mc":[{"id":"1.168224426","rc":[{"batb":[[0,1.01,15.51]],"ltp":1.03,"tv":4028.23,"id":8260126}]}]}
{"op":"mcm","clk":"1008827464","pt":1580640011326,"mc":[{"id":"1.168224426","rc":[{"batb":[[0,1.09,979.5],[1,1.08,188.31],[2,1.01,15.51]],"ltp":1.03,"tv":4028.23,"id":8260126}]}]}
{"op":"mcm","clk":"1008827540","pt":1580640012007,"mc":[{"id":"1.168224426","rc":[{"batb":[[1,1.08,289],[2,1.04,594.05]],"batl":[[0,1.11,989.02]],"ltp":1.03,"tv":4028.23,"id":8260126},{"batb":[[0,10.5,4.2],[1,9.4,15.34],[2,4.9,13.61]],"ltp":13.5,"tv":77.3,"id":4486603}]}]}
{"op":"mcm","clk":"1008827792","pt":1580640014725,"mc":[{"id":"1.168224426","rc":[{"batl":[[2,1.35,1057.18]],"ltp":1.03,"tv":4028.23,"id":8260126},{"batl":[[0,30,47.16]],"ltp":13.5,"tv":77.3,"id":4486603}]}]}
{"op":"mcm","clk":"1008829508","pt":1580640031192,"mc":[{"id":"1.168224426","rc":[{"batb":[[0,1.04,594.05],[1,1.01,15.51],[2,1.04,0]],"batl":[[0,1.35,1057.2],[1,1.12,0],[2,1.35,0]],"ltp":1.03,"tv":4028.23,"id":8260126},{"batb":[[0,4.9,13.61],[1,1.01,15.52],[2,4.9,0]],"ltp":13.5,"tv":77.3,"id":4486603}]}]}
{"op":"mcm","clk":"1008829714","pt":1580640032852,"mc":[{"id":"1.168224426","rc":[{"batl":[[0,1.1,0.02]],"ltp":1.03,"tv":4028.23,"id":8260126}]}]}
{"op":"mcm","clk":"1008829881","pt":1580640034363,"mc":[{"id":"1.168224426","rc":[{"batb":[[0,1.05,491.44],[1,1.04,1320.03],[2,1.01,15.51]],"batl":[[0,1.23,399.99],[1,1.24,445.32]],"ltp":1.03,"tv":4028.23,"id":8260126}]}]}
{"op":"mcm","clk":"1008830345","pt":1580640038794,"mc":[{"id":"1.168224426","rc":[{"batl":[[0,1.1,0.02],[1,1.24,0]],"ltp":1.03,"tv":4028.23,"id":8260126}]}]}
{"op":"mcm","clk":"1008830696","pt":1580640041884,"mc":[{"id":"1.168224426","rc":[{"batl":[[0,1.06,1199.09],[1,1.1,0.02]],"ltp":1.03,"tv":4028.23,"id":8260126}]}]}
{"op":"mcm","clk":"1008830804","pt":1580640042879,"mc":[{"id":"1.168224426","rc":[{"batb":[[0,16,4.48],[1,6.8,12.83],[2,1.01,15.52]],"ltp":13.5,"tv":77.3,"id":4486603}]}]}
{"op":"mcm","clk":"1008830968","pt":1580640044384,"mc":[{"id":"1.168224426","rc":[{"batl":[[0,1.06,1241.1],[1,1.31,1193.44]],"ltp":1.03,"tv":4028.23,"id":8260126},{"batl":[[0,95,38.77]],"ltp":13.5,"tv":77.3,"id":4486603}]}]}
{"op":"mcm","clk":"1008832628","pt":1580640061336,"mc":[{"id":"1.168224426","rc":[{"batb":[[1,1.04,1063.82]],"batl":[[0,1.06,1009.16]],"ltp":1.03,"tv":4028.23,"id":8260126}]}]}
{"op":"mcm","clk":"1008832966","pt":1580640064311,"mc":[{"id":"1.168224426","rc":[{"batb":[[0,1.05,745.21]],"batl":[[1,1.07,229.77],[2,1.31,1193.44]],"ltp":1.03,"tv":4028.23,"id":8260126}]}]}
{"op":"mcm","clk":"1008833032","pt":1580640064938,"mc":[{"id":"1.168224426","rc":[{"batb":[[0,1.01,15.51],[1,1.04,0],[2,1.01,0]],"batl":[[0,1.31,1193.44],[1,1.07,0],[2,1.31,0]],"ltp":1.03,"tv":4028.23,"id":8260126},{"batb":[[0,6.8,12.83],[1,1.01,15.52],[2,1.01,0]],"ltp":13.5,"tv":77.3,"id":4486603}]}]}
{"op":"mcm","clk":"1008833300","pt":1580640067314,"mc":[{"id":"1.168224426","rc":[{"batb":[[0,1.01,1273.96]],"batl":[[0,1.16,659.94],[1,1.17,432.07]],"ltp":1.03,"tv":4028.23,"id":8260126}]}]}
{"op":"mcm","clk":"1008835628","pt":1580640089882,"mc":[{"id":"1.168224426","rc":[{"batl":[[0,1.1,0.02],[1,1.17,0]],"ltp":1.03,"tv":4028.23,"id":8260126}]}]}
{"op":"mcm","clk":"1008836023","pt":1580640093400,"mc":[{"id":"1.168224426","rc":[{"batl":[[0,1.02,1246.11],[1,1.1,0.02]],"ltp":1.03,"tv":4028.23,"id":8260126},{"batb":[[0,15,5.04],[1,6.8,12.83],[2,1.01,15.52]],"ltp":13.5,"tv":77.3,"id":4486603}]}]}
{"op":"mcm","clk":"1008836050","pt":1580640093606,"mc":[{"id":"1.168224426","rc":[{"batb":[[1,1.01,15.52],[2,1.01,0]],"ltp":13.5,"tv":77.3,"id":4486603}]}]}
{"op":"mcm","clk":"1008836236","pt":1580640095419,"mc":[{"id":"1.168224426","rc":[{"batl":[[1,1.28,1345.71]],"ltp":1.03,"tv":4028.23,"id":8260126}]}]}
{"op":"mcm","clk":"1008838613","pt":1580640117240,"mc":[{"id":"1.168224426","rc":[{"batb":[[0,1.01,15.51]],"batl":[[0,1.28,1345.71],[1,1.28,0]],"ltp":1.03,"tv":4028.23,"id":8260126}]}]}
{"op":"mcm","clk":"1008838784","pt":1580640118761,"mc":[{"id":"1.168224426","rc":[{"batl":[[0,1.1,0.02]],"ltp":1.03,"tv":4028.23,"id":8260126}]}]}
{"op":"mcm","clk":"1008839226","pt":1580640122178,"mc":[{"id":"1.168224426","rc":[{"batb":[[0,1.02,1246.11],[1,1.01,15.51]],"batl":[[0,1.03,1234.01],[1,1.1,0.02]],"ltp":1.03,"tv":4028.23,"id":8260126}]}]}
{"op":"mcm","clk":"1008839509","pt":1580640123968,"mc":[{"id":"1.168224426","rc":[{"batl":[[1,1.29,1298.74]],"ltp":1.03,"tv":4028.23,"id":8260126}]}]}
{"op":"mcm","clk":"1008839721","pt":1580640125441,"mc":[{"id":"1.168224426","rc":[{"batb":[[0,1.01,15.51],[1,1.01,0]],"batl":[[0,1.29,1298.74],[1,1.29,0]],"ltp":1.03,"tv":4028.23,"id":8260126}]}]}
{"op":"mcm","clk":"1008839925","pt":1580640126851,"mc":[{"id":"1.168224426","rc":[{"batl":[[0,1.1,0.02]],"ltp":1.03,"tv":4028.23,"id":8260126}]}]}
{"op":"mcm","clk":"1008840096","pt":1580640128266,"mc":[{"id":"1.168224426","rc":[{"batl":[[0,1.06,256.98],[1,1.07,933.29],[2,1.1,0.02]],"ltp":1.03,"tv":4028.23,"id":8260126}]}]}
{"op":"mcm","clk":"1008840371","pt":1580640130367,"mc":[{"id":"1.168224426","rc":[{"batb":[[0,1.05,1210.51],[1,1.01,15.51]],"ltp":1.03,"tv":4028.23,"id":8260126}]}]}
{"op":"mcm","clk":"1008840384","pt":1580640130464,"mc":[{"id":"1.168224426","rc":[{"batb":[[1,1.04,551.01],[2,1.01,15.51]],"ltp":1.03,"tv":4028.23,"id":8260126},{"batb":[[1,6.4,14.24],[2,1.01,15.52]],"ltp":13.5,"tv":77.3,"id":4486603}]}]}
{"op":"mcm","clk":"1008840614","pt":1580640132049,"mc":[{"id":"1.168224426","rc":[{"batl":[[2,1.32,1159.81]],"ltp":1.03,"tv":4028.23,"id":8260126},{"batl":[[0,65,40.67]],"ltp":13.5,"tv":77.3,"id":4486603}]}]}
{"op":"mcm","clk":"1008843480","pt":1580640151161,"mc":[{"id":"1.168224426","rc":[{"batb":[[0,1.01,15.51],[1,1.04,0],[2,1.01,0]],"batl":[[0,1.32,1159.81],[1,1.07,0],[2,1.32,0]],"ltp":1.03,"tv":4028.23,"id":8260126},{"batb":[[0,6.4,14.24],[1,1.01,15.52],[2,1.01,0]],"ltp":13.5,"tv":77.3,"id":4486603}]}]}
{"op":"mcm","clk":"1008843769","pt":1580640153142,"mc":[{"id":"1.168224426","rc":[{"batl":[[0,1.1,0.02]],"ltp":1.03,"tv":4028.23,"id":8260126}]}]}
{"op":"mcm","clk":"1008843966","pt":1580640154451,"mc":[{"id":"1.168224426","rc":[{"batb":[[0,1.01,1273.96]],"batl":[[0,1.17,800.89],[1,1.18,283.06]],"ltp":1.03,"tv":4028.23,"id":8260126}]}]}
{"op":"mcm","clk":"1008844625","pt":1580640159676,"mc":[{"id":"1.168224426","rc":[{"batb":[[0,1.01,15.51]],"ltp":1.03,"tv":4028.23,"id":8260126}]}]}
{"op":"mcm","clk":"1008845156","pt":1580640163358,"mc":[{"id":"1.168224426","rc":[{"trd":[[1.1,0.04]],"batb":[[0,1.14,1063.13],[1,1.13,224.02],[2,1.04,506.08]],"batl":[[0,1.17,800.87]],"ltp":1.1,"tv":4028.26,"id":8260126},{"batb":[[1,3.05,22.11],[2,1.01,15.52]],"ltp":13.5,"tv":77.3,"id":4486603}],"tv":4105.57}]}
{"op":"mcm","clk":"1008845247","pt":1580640164093,"mc":[{"id":"1.168224426","rc":[{"batl":[[0,1.15,42.01],[1,1.17,800.87],[2,1.18,283.06]],"ltp":1.1,"tv":4028.26,"id":8260126},{"batb":[[0,7.6,5.88],[1,6.4,14.24],[2,3.05,22.11]],"ltp":13.5,"tv":77.3,"id":4486603}]}]}
{"op":"mcm","clk":"1008845579","pt":1580640166297,"mc":[{"id":"1.168224426","rc":[{"batl":[[0,9.6,4.2],[1,17,57.33]],"ltp":13.5,"tv":77.3,"id":4486603}]}]}
{"op":"mcm","clk":"1008846443","pt":1580640172414,"mc":[{"id":"1.168224426","rc":[{"batb":[[0,1.14,984.44]],"batl":[[1,1.17,658.07],[2,1.4,927.7]],"ltp":1.1,"tv":4028.26,"id":8260126}]}]}
{"op":"mcm","clk":"1008846813","pt":1580640174835,"mc":[{"id":"1.168224426","rc":[{"batb":[[1,1.13,303.43]],"batl":[[1,1.16,221.3],[2,1.17,658.07]],"ltp":1.1,"tv":4028.26,"id":8260126}]}]}
{"op":"mcm","clk":"1008847416","pt":1580640179032,"mc":[{"id":"1.168224426","rc":[{"batb":[[2,1.12,168.04]],"ltp":1.1,"tv":4028.26,"id":8260126}]}]}
{"op":"mcm","clk":"1008848095","pt":1580640183455,"mc":[{"id":"1.168224426","rc":[{"batb":[[0,1.04,506.08],[1,1.01,15.51],[2,1.12,0]],"batl":[[0,1.4,927.7],[1,1.16,0],[2,1.17,0]],"ltp":1.1,"tv":4028.26,"id":8260126},{"batb":[[0,3.05,22.11],[1,1.01,15.52],[2,3.05,0]],"batl":[[0,17,57.33],[1,17,0]],"ltp":13.5,"tv":77.3,"id":4486603}]}]}
{"op":"mcm","clk":"1008848429","pt":1580640185439,"mc":[{"id":"1.168224426","rc":[{"batb":[[0,1.05,1210.51],[1,1.04,506.08],[2,1.01,15.51]],"batl":[[0,1.44,203.07],[1,1.45,201.7]],"ltp":1.1,"tv":4028.26,"id":8260126}]}]}
{"op":"mcm","clk":"1008848440","pt":1580640185550,"mc":[{"id":"1.168224426","rc":[{"batb":[[0,1.05,1210.53]],"ltp":1.1,"tv":4028.26,"id":8260126}]}]}
{"op":"mcm","clk":"1008850379","pt":1580640198169,"mc":[{"id":"1.168224426","rc":[{"batb":[[0,1.04,506.1],[1,1.01,15.51],[2,1.01,0]],"ltp":1.1,"tv":4028.26,"id":8260126}]}]}
{"op":"mcm","clk":"1008850928","pt":1580640201254,"mc":[{"id":"1.168224426","rc":[{"trd":[[1.1,0.07]],"batb":[[0,1.05,1210.51],[1,1.04,506.08],[2,1.01,15.51]],"batl":[[0,1.07,1187.86]],"ltp":1.1,"tv":4028.3,"id":8260126}],"tv":4105.61}]}
{"op":"mcm","clk":"1008851104","pt":1580640202359,"mc":[{"id":"1.168224426","rc":[{"batb":[[0,14,5.82],[1,6.2,15.42],[2,1.01,15.52]],"ltp":13.5,"tv":77.3,"id":4486603}]}]}
{"op":"mcm","clk":"1008851277","pt":1580640203773,"mc":[{"id":"1.168224426","rc":[{"batl":[[1,1.32,1159.8]],"ltp":1.1,"tv":4028.3,"id":8260126},{"batl":[[0,65,40.67]],"ltp":13.5,"tv":77.3,"id":4486603}]}]}
{"op":"mcm","clk":"1008854069","pt":1580640224446,"mc":[{"id":"1.168224426","rc":[{"batb":[[0,1.04,506.08],[1,1.01,15.51],[2,1.01,0]],"batl":[[0,1.32,1159.8],[1,1.32,0]],"ltp":1.1,"tv":4028.3,"id":8260126}]}]}
{"op":"mcm","clk":"1008854162","pt":1580640225174,"mc":[{"id":"1.168224426","rc":[{"batb":[[0,1.01,15.51],[1,1.01,0]],"ltp":1.1,"tv":4028.3,"id":8260126},{"batb":[[0,6.2,15.42],[1,1.01,15.52],[2,1.01,0]],"ltp":13.5,"tv":77.3,"id":4486603}]}]}
{"op":"mcm","clk":"1008854457","pt":1580640227539,"mc":[{"id":"1.168224426","rc":[{"batb":[[0,1.01,1273.96]],"batl":[[0,1.17,539.49],[1,1.18,542.22]],"ltp":1.1,"tv":4028.3,"id":8260126}]}]}
{"op":"mcm","clk":"1008855637","pt":1580640236430,"mc":[{"id":"1.168224426","rc":[{"batl":[[0,1.02,469.53],[1,1.03,769.03]],"ltp":1.1,"tv":4028.3,"id":8260126},{"batb":[[0,30,3.15],[1,13.5,6.53],[2,6.2,15.42]],"ltp":13.5,"tv":77.3,"id":4486603}]}]}
{"op":"mcm","clk":"1008855677","pt":1580640236784,"mc":[{"id":"1.168224426","rc":[{"batb":[[2,1.01,15.52]],"ltp":13.5,"tv":77.3,"id":4486603}]}]}
{"op":"mcm","clk":"1008855852","pt":1580640238255,"mc":[{"id":"1.168224426","rc":[{"batl":[[2,1.28,1326.22]],"ltp":1.1,"tv":4028.3,"id":8260126}]}]}
{"op":"mcm","clk":"1008857847","pt":1580640253401,"mc":[{"id":"1.168224426","rc":[{"batb":[[0,1.01,15.51]],"batl":[[0,1.28,1326.22],[1,1.03,0],[2,1.28,0]],"ltp":1.1,"tv":4028.3,"id":8260126}]}]}
{"op":"mcm","clk":"1008857896","pt":1580640253703,"mc":[{"id":"1.168224426","rc":[{"batb":[[0,13.5,6.53],[1,1.01,15.52],[2,1.01,0]],"ltp":13.5,"tv":77.3,"id":4486603}]}]}
{"op":"mcm","clk":"1008858219","pt":1580640256367,"mc":[{"id":"1.168224426","rc":[{"batl":[[0,1.07,1142.89]],"ltp":1.1,"tv":4028.3,"id":8260126}]}]}
{"op":"mcm","clk":"1008858430","pt":1580640258408,"mc":[{"id":"1.168224426","rc":[{"batb":[[0,1.02,1246.11],[1,1.01,15.51]],"batl":[[0,1.03,921.77],[1,1.04,309.23]],"ltp":1.1,"tv":4028.3,"id":8260126}]}]}
{"op":"mcm","clk":"1008858699","pt":1580640260395,"mc":[{"id":"1.168224426","rc":[{"batl":[[2,1.29,1298.72]],"ltp":1.1,"tv":4028.3,"id":8260126}]}]}
{"op":"mcm","clk":"1008858852","pt":1580640261392,"mc":[{"id":"1.168224426","rc":[{"batb":[[0,1.01,15.51],[1,1.01,0]],"batl":[[0,1.29,1298.72],[1,1.04,0],[2,1.29,0]],"ltp":1.1,"tv":4028.3,"id":8260126}]}]}
{"op":"mcm","clk":"1008859230","pt":1580640264403,"mc":[{"id":"1.168224426","rc":[{"batl":[[0,1.07,1142.89]],"ltp":1.1,"tv":4028.3,"id":8260126}]}]}
{"op":"mcm","clk":"1008859587","pt":1580640267311,"mc":[{"id":"1.168224426","rc":[{"batb":[[0,1.05,1210.51],[1,1.01,15.51]],"ltp":1.1,"tv":4028.3,"id":8260126}]}]}
{"op":"mcm","clk":"1008859718","pt":1580640268196,"mc":[{"id":"1.168224426","rc":[{"batb":[[0,1.05,1684.65]],"ltp":1.1,"tv":4028.3,"id":8260126},{"batb":[[1,6,17],[2,1.01,15.52]],"ltp":13.5,"tv":77.3,"id":4486603}]}]}
{"op":"mcm","clk":"1008859874","pt":1580640269499,"mc":[{"id":"1.168224426","rc":[{"batl":[[1,1.32,1159.8]],"ltp":1.1,"tv":4028.3,"id":8260126},{"batl":[[0,65,40.67]],"ltp":13.5,"tv":77.3,"id":4486603}]}]}
{"op":"mcm","clk":"1008862188","pt":1580640287247,"mc":[{"id":"1.168224426","rc":[{"batb":[[0,1.01,15.51],[1,1.01,0]],"batl":[[0,1.32,1159.8],[1,1.32,0]],"ltp":1.1,"tv":4028.3,"id":8260126},{"batb":[[0,6,17],[1,1.01,15.52],[2,1.01,0]],"ltp":13.5,"tv":77.3,"id":4486603}]}]}
{"op":"mcm","clk":"1008862595","pt":1580640290329,"mc":[{"id":"1.168224426","rc":[{"batb":[[0,1.01,1273.96]],"batl":[[0,1.17,205.54],[1,1.18,615.25]],"ltp":1.1,"tv":4028.3,"id":8260126}]}]}
{"op":"mcm","clk":"1008863547","pt":1580640297927,"mc":[{"id":"1.168224426","rc":[{"batl":[[0,1.03,1234.01]],"ltp":1.1,"tv":4028.3,"id":8260126}]}]}
{"op":"mcm","clk":"1008863660","pt":1580640298864,"mc":[{"id":"1.168224426","rc":[{"batb":[[0,13,7.4]],"ltp":13.5,"tv":77.3,"id":4486603}]}]}
{"op":"mcm","clk":"1008863943","pt":1580640300815,"mc":[{"id":"1.168224426","rc":[{"batl":[[1,1.28,1326.22]],"ltp":1.1,"tv":4028.3,"id":8260126}]}]}
{"op":"mcm","clk":"1008865580","pt":1580640312444,"mc":[{"id":"1.168224426","rc":[{"batb":[[0,1.01,15.51]],"batl":[[0,1.28,1326.22],[1,1.28,0]],"ltp":1.1,"tv":4028.3,"id":8260126}]}]}
{"op":"mcm","clk":"1008865940","pt":1580640314969,"mc":[{"id":"1.168224426","rc":[{"batl":[[0,1.07,651.43],[1,1.08,531.48]],"ltp":1.1,"tv":4028.3,"id":8260126}]}]}
{"op":"mcm","clk":"1008866740","pt":1580640320391,"mc":[{"id":"1.168224426","rc":[{"batb":[[0,1.06,682.37],[1,1.05,521.63],[2,1.01,15.51]],"ltp":1.1,"tv":4028.3,"id":8260126}]}]}
{"op":"mcm","clk":"1008866849","pt":1580640321066,"mc":[{"id":"1.168224426","rc":[{"batb":[[1,1.05,962.64]],"ltp":1.1,"tv":4028.3,"id":8260126},{"batb":[[1,5.9,18.25],[2,1.01,15.52]],"ltp":13.5,"tv":77.3,"id":4486603}]}]}
{"op":"mcm","clk":"1008867142","pt":1580640322985,"mc":[{"id":"1.168224426","rc":[{"batl":[[2,1.32,1159.8]],"ltp":1.1,"tv":4028.3,"id":8260126},{"batl":[[0,65,40.67]],"ltp":13.5,"tv":77.3,"id":4486603}]}]}
{"op":"mcm","clk":"1008868855","pt":1580640335303,"mc":[{"id":"1.168224426","rc":[{"batb":[[0,1.01,15.51],[1,1.05,0],[2,1.01,0]],"batl":[[0,1.32,1159.8],[1,1.08,0],[2,1.32,0]],"ltp":1.1,"tv":4028.3,"id":8260126},{"batb":[[0,5.9,18.25],[1,1.01,15.52],[2,1.01,0]],"ltp":13.5,"tv":77.3,"id":4486603}]}]}
{"op":"mcm","clk":"1008869183","pt":1580640337705,"mc":[{"id":"1.168224426","rc":[{"batb":[[0,1.02,223.23],[1,1.01,1048.51]],"batl":[[0,1.18,475.74],[1,1.19,566.23]],"ltp":1.1,"tv":4028.3,"id":8260126}]}]}
{"op":"mcm","clk":"1008870336","pt":1580640346032,"mc":[{"id":"1.168224426","rc":[{"batl":[[0,1.03,1234.01]],"ltp":1.1,"tv":4028.3,"id":8260126}]}]}
{"op":"mcm","clk":"1008870507","pt":1580640347290,"mc":[{"id":"1.168224426","rc":[{"batb":[[0,12,8.26]],"ltp":13.5,"tv":77.3,"id":4486603}]}]}
{"op":"mcm","clk":"1008870609","pt":1580640348224,"mc":[{"id":"1.168224426","rc":[{"batl":[[1,1.28,1326.22]],"ltp":1.1,"tv":4028.3,"id":8260126}]}]}
{"op":"mcm","clk":"1008872453","pt":1580640362444,"mc":[{"id":"1.168224426","rc":[{"batb":[[0,1.01,15.51],[1,1.01,0]],"batl":[[0,1.28,1326.22],[1,1.28,0]],"ltp":1.1,"tv":4028.3,"id":8260126}]}]}
{"op":"mcm","clk":"1008872869","pt":1580640365335,"mc":[{"id":"1.168224426","rc":[{"batl":[[0,1.07,187.65],[1,1.08,990.97]],"ltp":1.1,"tv":4028.3,"id":8260126}]}]}
{"op":"mcm","clk":"1008873003","pt":1580640366322,"mc":[{"id":"1.168224426","marketDefinition":{"bspMarket":false,"turnInPlayEnabled":true,"persistenceEnabled":true,"marketBaseRate":5.0,"eventId":"29681737","eventTypeId":"2","numberOfWinners":1,"bettingType":"ODDS","marketType":"SET_WINNER","marketTime":"2020-02-02T09:24:00.000Z","suspendTime":"2020-02-02T09:24:00.000Z","bspReconciled":false,"complete":true,"inPlay":true,"crossMatching":true,"runnersVoidable":false,"numberOfActiveRunners":2,"betDelay":3,"status":"SUSPENDED","runners":[{"status":"ACTIVE","sortPriority":1,"id":8260126,"name":"Guillermo Garcia-Lopez"},{"status":"ACTIVE","sortPriority":2,"id":4486603,"name":"Dustin Brown"}],"regulators":["MR_INT"],"countryCode":"FR","discountAllowed":true,"timezone":"UTC","openDate":"2020-02-02T09:24:00.000Z","version":3148436738,"name":"Set 2 Winner","eventName":"Garcia-Lopez v Brown"}}]}
{"op":"mcm","clk":"1008873143","pt":1580640367330,"mc":[{"id":"1.168224426","rc":[{"batb":[[0,1.01,15.52],[1,1.01,0]],"ltp":13.5,"tv":77.3,"id":4486603}]}]}
{"op":"mcm","clk":"1008877444","pt":1580640400409,"mc":[{"id":"1.168224426","tv":0.0}]}
{"op":"mcm","clk":"1008877567","pt":1580640401420,"mc":[{"id":"1.168224426","marketDefinition":{"bspMarket":false,"turnInPlayEnabled":true,"persistenceEnabled":true,"marketBaseRate":5.0,"eventId":"29681737","eventTypeId":"2","numberOfWinners":1,"bettingType":"ODDS","marketType":"SET_WINNER","marketTime":"2020-02-02T09:24:00.000Z","suspendTime":"2020-02-02T09:24:00.000Z","bspReconciled":false,"complete":true,"inPlay":true,"crossMatching":false,"runnersVoidable":false,"numberOfActiveRunners":0,"betDelay":3,"status":"CLOSED","settledTime":"2020-02-02T10:46:39.000Z","runners":[{"status":"WINNER","sortPriority":1,"id":8260126,"name":"Guillermo Garcia-Lopez"},{"status":"LOSER","sortPriority":2,"id":4486603,"name":"Dustin Brown"}],"regulators":["MR_INT"],"countryCode":"FR","discountAllowed":true,"timezone":"UTC","openDate":"2020-02-02T09:24:00.000Z","version":3148437162,"name":"Set 2 Winner","eventName":"Garcia-Lopez v Brown"}}]}
