{"op":"mcm","clk":"1001501051","pt":1580587070468,"mc":[{"id":"1.168230755","marketDefinition":{"bspMarket":false,"turnInPlayEnabled":true,"persistenceEnabled":true,"marketBaseRate":5.0,"eventId":"29681775","eventTypeId":"2","numberOfWinners":1,"bettingType":"ODDS","marketType":"SET_BETTING","marketTime":"2020-02-02T18:00:00.000Z","suspendTime":"2020-02-02T18:00:00.000Z","bspReconciled":false,"complete":true,"inPlay":false,"crossMatching":true,"runnersVoidable":false,"numberOfActiveRunners":4,"betDelay":0,"status":"OPEN","runners":[{"status":"ACTIVE","sortPriority":1,"id":13095165,"name":"Brengle 2-0"},{"status":"ACTIVE","sortPriority":2,"id":13095168,"name":"Brengle 2-1"},{"status":"ACTIVE","sortPriority":3,"id":14343845,"name":"Voegele 2-0"},{"status":"ACTIVE","sortPriority":4,"id":14343850,"name":"Voegele 2-1"}],"regulators":["MR_INT"],"discountAllowed":false,"timezone":"UTC","openDate":"2020-02-02T18:00:00.000Z","version":3147219573,"name":"Set Betting","eventName":"Brengle v Voegele"}}]}
{"op":"mcm","clk":"1001501273","pt":1580587071655,"mc":[{"id":"1.168230755","marketDefinition":{"bspMarket":false,"turnInPlayEnabled":true,"persistenceEnabled":true,"marketBaseRate":5.0,"eventId":"29681775","eventTypeId":"2","numberOfWinners":1,"bettingType":"ODDS","marketType":"SET_BETTING","marketTime":"2020-02-02T18:00:00.000Z","suspendTime":"2020-02-02T18:00:00.000Z","bspReconciled":false,"complete":true,"inPlay":false,"crossMatching":true,"runnersVoidable":false,"numberOfActiveRunners":4,"betDelay":0,"status":"OPEN","runners":[{"status":"ACTIVE","sortPriority":1,"id":13095165,"name":"Brengle 2-0"},{"status":"ACTIVE","sortPriority":2,"id":13095168,"name":"Brengle 2-1"},{"status":"ACTIVE","sortPriority":3,"id":14343845,"name":"Voegele 2-0"},{"status":"ACTIVE","sortPriority":4,"id":14343850,"name":"Voegele 2-1"}],"regulators":["MR_INT"],"discountAllowed":false,"timezone":"UTC","openDate":"2020-02-02T18:00:00.000Z","version":3147219573,"name":"Set Betting","eventName":"Brengle v Voegele"}}]}
{"op":"mcm","clk":"1001501657","pt":1580587073688,"mc":[{"id":"1.168230755","marketDefinition":{"bspMarket":false,"turnInPlayEnabled":true,"persistenceEnabled":true,"marketBaseRate":5.0,"eventId":"29681775","eventTypeId":"2","numberOfWinners":1,"bettingType":"ODDS","marketType":"SET_BETTING","marketTime":"2020-02-02T18:00:00.000Z","suspendTime":"2020-02-02T18:00:00.000Z","bspReconciled":false,"complete":true,"inPlay":false,"crossMatching":true,"runnersVoidable":false,"numberOfActiveRunners":4,"betDelay":0,"status":"OPEN","runners":[{"status":"ACTIVE","sortPriority":1,"id":13095165,"name":"Brengle 2-0"},{"status":"ACTIVE","sortPriority":2,"id":13095168,"name":"Brengle 2-1"},{"status":"ACTIVE","sortPriority":3,"id":14343845,"name":"Voegele 2-0"},{"status":"ACTIVE","sortPriority":4,"id":14343850,"name":"Voegele 2-1"}],"regulators":["MR_INT"],"discountAllowed":true,"timezone":"UTC","openDate":"2020-02-02T18:00:00.000Z","version":3147219573,"name":"Set Betting","eventName":"Brengle v Voegele"}}]}
{"op":"mcm","clk":"1001666351","pt":1580587950891,"mc":[{"id":"1.168230755","rc":[{"batb":[[0,1.02,2]],"ltp":0.0,"tv":0.0,"id":13095168},{"batb":[[0,1.02,2]],"ltp":0.0,"tv":0.0,"id":13095165},{"batb":[[0,1.02,2]],"ltp":0.0,"tv":0.0,"id":14343850},{"batb":[[0,1.02,2]],"ltp":0.0,"tv":0.0,"id":14343845}]}]}
{"op":"mcm","clk":"1002482684","pt":1580594263454,"mc":[{"id":"1.168230755","rc":[{"batb":[[0,2.46,30.29],[1,1.02,2]],"ltp":0.0,"tv":0.0,"id":13095165}]}]}
{"op":"mcm","clk":"1002635900","pt":1580596405651,"mc":[{"id":"1.168230755","rc":[{"batb":[[0,1.02,2],[1,1.02,0]],"ltp":0.0,"tv":0.0,"id":13095165}]}]}
{"op":"mcm","clk":"1002649258","pt":1580596611139,"mc":[{"id":"1.168230755","rc":[{"batb":[[0,2.46,30.29],[1,1.02,2]],"ltp":0.0,"tv":0.0,"id":13095165}]}]}
{"op":"mcm","clk":"1003055219","pt":1580602433303,"mc":[{"id":"1.168230755","rc":[{"batb":[[0,3.4,75.21],[1,1.02,2]],"ltp":0.0,"tv":0.0,"id":13095168},{"batb":[[0,2.58,99.56],[1,2.46,30.29],[2,1.02,2]],"ltp":0.0,"tv":0.0,"id":13095165},{"batb":[[0,4,64.07],[1,1.02,2]],"ltp":0.0,"tv":0.0,"id":14343850},{"batb":[[0,2.54,101.12],[1,1.02,2]],"ltp":0.0,"tv":0.0,"id":14343845}]}]}
{"op":"mcm","clk":"1003055392","pt":1580602434601,"mc":[{"id":"1.168230755","rc":[{"batl":[[0,7.6,332.31]],"ltp":0.0,"tv":0.0,"id":13095168},{"batl":[[0,4.8,323.77]],"ltp":0.0,"tv":0.0,"id":13095165},{"batl":[[0,9,279.87]],"ltp":0.0,"tv":0.0,"id":14343850},{"batl":[[0,4.1,426.65]],"ltp":0.0,"tv":0.0,"id":14343845}]}]}
{"op":"mcm","clk":"1003057054","pt":1580602451642,"mc":[{"id":"1.168230755","rc":[{"batb":[[0,2.6,30.29],[1,2.58,99.56]],"ltp":0.0,"tv":0.0,"id":13095165}]}]}
{"op":"mcm","clk":"1003057088","pt":1580602452055,"mc":[{"id":"1.168230755","rc":[{"batb":[[0,2.66,96.34],[1,2.6,30.29]],"ltp":0.0,"tv":0.0,"id":13095165}]}]}
{"op":"mcm","clk":"1003068151","pt":1580602573568,"mc":[{"id":"1.168230755","rc":[{"batb":[[0,2.72,94.34],[1,2.68,30.29]],"ltp":0.0,"tv":0.0,"id":13095165}]}]}
{"op":"mcm","clk":"1003070537","pt":1580602600505,"mc":[{"id":"1.168230755","rc":[{"batb":[[2,1.01,0.51]],"ltp":0.0,"tv":0.0,"id":13095168},{"batb":[[2,1.01,0.51]],"ltp":0.0,"tv":0.0,"id":14343850},{"batb":[[2,1.01,0.51]],"ltp":0.0,"tv":0.0,"id":14343845}]}]}
{"op":"mcm","clk":"1003079098","pt":1580602695269,"mc":[{"id":"1.168230755","rc":[{"batb":[[0,2.76,92.98],[1,2.74,30.29]],"ltp":0.0,"tv":0.0,"id":13095165}]}]}
{"op":"mcm","clk":"1003088195","pt":1580602816583,"mc":[{"id":"1.168230755","rc":[{"batb":[[0,2.78,30.29],[1,2.76,92.98]],"ltp":0.0,"tv":0.0,"id":13095165}]}]}
{"op":"mcm","clk":"1003088218","pt":1580602816894,"mc":[{"id":"1.168230755","rc":[{"batb":[[0,2.8,91.48],[1,2.78,30.29]],"ltp":0.0,"tv":0.0,"id":13095165}]}]}
{"op":"mcm","clk":"1003096835","pt":1580602938603,"mc":[{"id":"1.168230755","rc":[{"batb":[[0,2.84,90.22],[1,2.82,30.29]],"ltp":0.0,"tv":0.0,"id":13095165}]}]}
{"op":"mcm","clk":"1003105477","pt":1580603060397,"mc":[{"id":"1.168230755","rc":[{"batb":[[0,2.86,119.97],[1,1.02,2],[2,1.01,0.51]],"ltp":0.0,"tv":0.0,"id":13095165}]}]}
{"op":"mcm","clk":"1003114421","pt":1580603181540,"mc":[{"id":"1.168230755","rc":[{"batb":[[0,2.86,89.68]],"ltp":0.0,"tv":0.0,"id":13095165}]}]}
{"op":"mcm","clk":"1003129911","pt":1580603366468,"mc":[{"id":"1.168230755","rc":[{"batb":[[2,1.01,3.04]],"ltp":0.0,"tv":0.0,"id":13095168},{"batb":[[2,1.01,3.04]],"ltp":0.0,"tv":0.0,"id":13095165},{"batb":[[2,1.01,3.04]],"ltp":0.0,"tv":0.0,"id":14343850},{"batb":[[2,1.01,3.04]],"ltp":0.0,"tv":0.0,"id":14343845}]}]}
{"op":"mcm","clk":"1003129976","pt":1580603367494,"mc":[{"id":"1.168230755","rc":[{"batb":[[2,1.01,1.01]],"ltp":0.0,"tv":0.0,"id":13095168},{"batb":[[2,1.01,1.01]],"ltp":0.0,"tv":0.0,"id":13095165},{"batb":[[2,1.01,1.01]],"ltp":0.0,"tv":0.0,"id":14343850},{"batb":[[2,1.01,1.01]],"ltp":0.0,"tv":0.0,"id":14343845}]}]}
{"op":"mcm","clk":"1003309800","pt":1580606033435,"mc":[{"id":"1.168230755","rc":[{"batb":[[0,1.02,2],[1,1.01,1.01],[2,1.01,0]],"ltp":0.0,"tv":0.0,"id":13095168},{"batb":[[0,1.02,2],[1,1.01,1.01],[2,1.01,0]],"ltp":0.0,"tv":0.0,"id":13095165},{"batb":[[0,1.02,2],[1,1.01,1.01],[2,1.01,0]],"ltp":0.0,"tv":0.0,"id":14343850},{"batb":[[0,1.02,2],[1,1.01,1.01],[2,1.01,0]],"ltp":0.0,"tv":0.0,"id":14343845}]}]}
{"op":"mcm","clk":"1003309894","pt":1580606034516,"mc":[{"id":"1.168230755","rc":[{"batb":[[0,3.55,71.99],[1,1.02,2],[2,1.01,1.01]],"ltp":0.0,"tv":0.0,"id":13095168},{"batb":[[0,2.38,107.96],[1,1.02,2],[2,1.01,1.01]],"ltp":0.0,"tv":0.0,"id":13095165},{"batb":[[0,3.4,75.21],[1,1.02,2],[2,1.01,1.01]],"batl":[[0,10,251.94]],"ltp":0.0,"tv":0.0,"id":14343850},{"batb":[[0,2.56,100.33],[1,1.02,2],[2,1.01,1.01]],"ltp":0.0,"tv":0.0,"id":14343845}]}]}
{"op":"mcm","clk":"1003314792","pt":1580606103641,"mc":[{"id":"1.168230755","rc":[{"batb":[[0,2.46,30.29],[1,2.38,107.96],[2,1.02,2]],"ltp":0.0,"tv":0.0,"id":13095165}]}]}
{"op":"mcm","clk":"1003314816","pt":1580606103948,"mc":[{"id":"1.168230755","rc":[{"batb":[[0,2.56,100.33],[1,2.46,30.29]],"batl":[[0,4.2,369.83]],"ltp":0.0,"tv":0.0,"id":13095165}]}]}
{"op":"mcm","clk":"1003323936","pt":1580606226621,"mc":[{"id":"1.168230755","rc":[{"batb":[[0,2.68,95.86],[1,2.58,30.29]],"ltp":0.0,"tv":0.0,"id":13095165}]}]}
{"op":"mcm","clk":"1003333770","pt":1580606347534,"mc":[{"id":"1.168230755","rc":[{"batb":[[0,2.7,30.28],[1,2.68,95.86]],"ltp":0.0,"tv":0.0,"id":13095165}]}]}
{"op":"mcm","clk":"1003333796","pt":1580606347842,"mc":[{"id":"1.168230755","rc":[{"batb":[[0,2.8,91.48],[1,2.7,30.28]],"ltp":0.0,"tv":0.0,"id":13095165}]}]}
{"op":"mcm","clk":"1003342570","pt":1580606469556,"mc":[{"id":"1.168230755","rc":[{"batb":[[0,2.84,90.22],[1,2.82,30.29]],"ltp":0.0,"tv":0.0,"id":13095165}]}]}
{"op":"mcm","clk":"1003350373","pt":1580606590606,"mc":[{"id":"1.168230755","rc":[{"batb":[[0,2.86,30.29],[1,2.84,90.22]],"ltp":0.0,"tv":0.0,"id":13095165}]}]}
{"op":"mcm","clk":"1003350400","pt":1580606590965,"mc":[{"id":"1.168230755","rc":[{"batb":[[0,2.86,119.97],[1,1.02,2],[2,1.01,1.01]],"ltp":0.0,"tv":0.0,"id":13095165}]}]}
{"op":"mcm","clk":"1003358900","pt":1580606712122,"mc":[{"id":"1.168230755","rc":[{"batb":[[0,2.86,89.68]],"ltp":0.0,"tv":0.0,"id":13095165}]}]}
{"op":"mcm","clk":"1003424443","pt":1580607564557,"mc":[{"id":"1.168230755","rc":[{"batb":[[0,2.88,30.28]],"ltp":0.0,"tv":0.0,"id":13095165},{"batb":[[0,2.66,96.34],[1,2.64,30.29],[2,1.02,2]],"batl":[[0,4.7,372.45]],"ltp":0.0,"tv":0.0,"id":14343845}]}]}
{"op":"mcm","clk":"1003433855","pt":1580607685527,"mc":[{"id":"1.168230755","rc":[{"batb":[[0,1.02,2],[1,1.01,1.01],[2,1.01,0]],"ltp":0.0,"tv":0.0,"id":13095165}]}]}
{"op":"mcm","clk":"1003433877","pt":1580607685837,"mc":[{"id":"1.168230755","rc":[{"batb":[[0,2.42,106.13],[1,1.02,2],[2,1.01,1.01]],"ltp":0.0,"tv":0.0,"id":13095165}]}]}
{"op":"mcm","clk":"1003434012","pt":1580607687637,"mc":[{"id":"1.168230755","rc":[{"batb":[[0,2.72,94.34],[1,2.52,30.29],[2,1.02,2]],"ltp":0.0,"tv":0.0,"id":13095165},{"batb":[[0,2.68,30.29],[1,1.02,2],[2,1.01,1.01]],"ltp":0.0,"tv":0.0,"id":14343845}]}]}
{"op":"mcm","clk":"1003434027","pt":1580607687755,"mc":[{"id":"1.168230755","rc":[{"batb":[[0,2.76,92.98],[1,2.68,30.29],[2,1.02,2]],"ltp":0.0,"tv":0.0,"id":14343845}]}]}
{"op":"mcm","clk":"1003443229","pt":1580607807502,"mc":[{"id":"1.168230755","rc":[{"batb":[[0,2.74,30.29],[1,2.72,94.34]],"ltp":0.0,"tv":0.0,"id":13095165}]}]}
{"op":"mcm","clk":"1003443308","pt":1580607808586,"mc":[{"id":"1.168230755","rc":[{"batb":[[0,2.76,92.98],[1,2.74,30.29]],"ltp":0.0,"tv":0.0,"id":13095165},{"batb":[[0,2.86,89.68],[1,2.78,30.29]],"ltp":0.0,"tv":0.0,"id":14343845}]}]}
{"op":"mcm","clk":"1003452450","pt":1580607929538,"mc":[{"id":"1.168230755","rc":[{"batb":[[0,2.8,91.48],[1,2.78,30.29]],"ltp":0.0,"tv":0.0,"id":13095165},{"batb":[[1,1.02,2],[2,1.01,1.01]],"ltp":0.0,"tv":0.0,"id":14343845}]}]}
{"op":"mcm","clk":"1003452506","pt":1580607930314,"mc":[{"id":"1.168230755","rc":[{"batb":[[0,2.92,87.69],[1,2.88,30.28],[2,1.02,2]],"ltp":0.0,"tv":0.0,"id":14343845}]}]}
{"op":"mcm","clk":"1003461225","pt":1580608050575,"mc":[{"id":"1.168230755","rc":[{"batb":[[1,1.02,2],[2,1.01,1.01]],"ltp":0.0,"tv":0.0,"id":13095165}]}]}
{"op":"mcm","clk":"1003461270","pt":1580608051298,"mc":[{"id":"1.168230755","rc":[{"batb":[[0,2.84,90.22],[1,2.82,30.29],[2,1.02,2]],"ltp":0.0,"tv":0.0,"id":13095165},{"batb":[[1,1.02,2],[2,1.01,1.01]],"ltp":0.0,"tv":0.0,"id":14343845}]}]}
{"op":"mcm","clk":"1003461315","pt":1580608051970,"mc":[{"id":"1.168230755","rc":[{"batb":[[0,2.96,86.63],[1,2.94,30.29],[2,1.02,2]],"ltp":0.0,"tv":0.0,"id":14343845}]}]}
{"op":"mcm","clk":"1003469961","pt":1580608172634,"mc":[{"id":"1.168230755","rc":[{"batb":[[0,2.86,119.97],[1,1.02,2],[2,1.01,1.01]],"ltp":0.0,"tv":0.0,"id":13095165}]}]}
{"op":"mcm","clk":"1003470022","pt":1580608173254,"mc":[{"id":"1.168230755","rc":[{"batb":[[0,3,85.57],[1,2.98,30.29]],"ltp":0.0,"tv":0.0,"id":14343845}]}]}
{"op":"mcm","clk":"1003478521","pt":1580608294573,"mc":[{"id":"1.168230755","rc":[{"batb":[[0,2.88,30.28]],"ltp":0.0,"tv":0.0,"id":13095165}]}]}
{"op":"mcm","clk":"1003478565","pt":1580608295189,"mc":[{"id":"1.168230755","rc":[{"batb":[[0,3.05,30.29],[1,1.02,2],[2,1.01,1.01]],"ltp":0.0,"tv":0.0,"id":14343845}]}]}
{"op":"mcm","clk":"1003486554","pt":1580608416561,"mc":[{"id":"1.168230755","rc":[{"batb":[[0,1.02,2],[1,1.01,1.01],[2,1.01,0]],"ltp":0.0,"tv":0.0,"id":13095165}]}]}
{"op":"mcm","clk":"1003486632","pt":1580608417567,"mc":[{"id":"1.168230755","rc":[{"batb":[[0,2.68,95.86],[1,2.52,30.29],[2,1.02,2]],"ltp":0.0,"tv":0.0,"id":13095165}]}]}
{"op":"mcm","clk":"1003486674","pt":1580608418157,"mc":[{"id":"1.168230755","rc":[{"batb":[[0,2.92,87.69],[1,2.64,30.29],[2,1.02,2]],"ltp":0.0,"tv":0.0,"id":14343845}]}]}
{"op":"mcm","clk":"1003494957","pt":1580608538184,"mc":[{"id":"1.168230755","rc":[{"batb":[[1,1.02,2],[2,1.01,1.01]],"ltp":0.0,"tv":0.0,"id":13095165}]}]}
{"op":"mcm","clk":"1003495063","pt":1580608539580,"mc":[{"id":"1.168230755","rc":[{"batb":[[0,2.82,91.03],[1,2.7,30.28],[2,1.02,2]],"ltp":0.0,"tv":0.0,"id":13095165},{"batb":[[0,2.94,30.29],[1,1.02,2],[2,1.01,1.01]],"ltp":0.0,"tv":0.0,"id":14343845}]}]}
{"op":"mcm","clk":"1003495072","pt":1580608539683,"mc":[{"id":"1.168230755","rc":[{"batb":[[0,2.96,86.63],[1,2.94,30.29],[2,1.02,2]],"ltp":0.0,"tv":0.0,"id":14343845}]}]}
{"op":"mcm","clk":"1003502751","pt":1580608660544,"mc":[{"id":"1.168230755","rc":[{"batb":[[0,2.84,30.29],[1,1.02,2],[2,1.01,1.01]],"ltp":0.0,"tv":0.0,"id":13095165}]}]}
{"op":"mcm","clk":"1003502799","pt":1580608661365,"mc":[{"id":"1.168230755","rc":[{"batb":[[0,2.86,89.68],[1,2.84,30.29],[2,1.02,2]],"ltp":0.0,"tv":0.0,"id":13095165},{"batb":[[0,3,85.57],[1,2.98,30.29]],"ltp":0.0,"tv":0.0,"id":14343845}]}]}
{"op":"mcm","clk":"1003510279","pt":1580608781529,"mc":[{"id":"1.168230755","rc":[{"batb":[[1,1.02,2],[2,1.01,1.01]],"ltp":0.0,"tv":0.0,"id":13095165}]}]}
{"op":"mcm","clk":"1003510355","pt":1580608782504,"mc":[{"id":"1.168230755","rc":[{"batb":[[0,2.88,30.28]],"ltp":0.0,"tv":0.0,"id":13095165},{"batb":[[0,3.05,30.29],[1,3,85.57]],"ltp":0.0,"tv":0.0,"id":14343845}]}]}
{"op":"mcm","clk":"1003510368","pt":1580608782708,"mc":[{"id":"1.168230755","rc":[{"batb":[[1,1.02,2],[2,1.01,1.01]],"ltp":0.0,"tv":0.0,"id":14343845}]}]}
{"op":"mcm","clk":"1003518949","pt":1580608903579,"mc":[{"id":"1.168230755","rc":[{"batb":[[0,2.42,106.13]],"ltp":0.0,"tv":0.0,"id":13095165}]}]}
{"op":"mcm","clk":"1003519038","pt":1580608904462,"mc":[{"id":"1.168230755","rc":[{"batb":[[0,2.58,99.56],[1,2.52,30.29],[2,1.02,2]],"ltp":0.0,"tv":0.0,"id":13095165},{"batb":[[0,2.76,92.98],[1,2.64,30.29],[2,1.02,2]],"ltp":0.0,"tv":0.0,"id":14343845}]}]}
{"op":"mcm","clk":"1003526671","pt":1580609025561,"mc":[{"id":"1.168230755","rc":[{"batb":[[0,2.66,96.34],[1,2.6,30.29]],"ltp":0.0,"tv":0.0,"id":13095165},{"batb":[[1,1.02,2],[2,1.01,1.01]],"ltp":0.0,"tv":0.0,"id":14343845}]}]}
{"op":"mcm","clk":"1003526694","pt":1580609025968,"mc":[{"id":"1.168230755","rc":[{"batb":[[0,2.94,87.09],[1,2.78,30.29],[2,1.02,2]],"ltp":0.0,"tv":0.0,"id":14343845}]}]}
{"op":"mcm","clk":"1003534309","pt":1580609146591,"mc":[{"id":"1.168230755","rc":[{"batb":[[1,1.02,2],[2,1.01,1.01]],"ltp":0.0,"tv":0.0,"id":13095165}]}]}
{"op":"mcm","clk":"1003534341","pt":1580609147109,"mc":[{"id":"1.168230755","rc":[{"batb":[[0,2.78,92.16],[1,2.68,30.29],[2,1.02,2]],"ltp":0.0,"tv":0.0,"id":13095165}]}]}
{"op":"mcm","clk":"1003534438","pt":1580609148402,"mc":[{"id":"1.168230755","rc":[{"batb":[[0,2.98,85.9],[1,2.96,30.29]],"ltp":0.0,"tv":0.0,"id":14343845}]}]}
{"op":"mcm","clk":"1003542281","pt":1580609268570,"mc":[{"id":"1.168230755","rc":[{"batb":[[1,1.02,2],[2,1.01,1.01]],"ltp":0.0,"tv":0.0,"id":13095165}]}]}
{"op":"mcm","clk":"1003542357","pt":1580609269555,"mc":[{"id":"1.168230755","rc":[{"batb":[[0,2.82,91.03],[1,2.8,30.29],[2,1.02,2]],"ltp":0.0,"tv":0.0,"id":13095165},{"batb":[[0,3,115.86],[1,1.02,2],[2,1.01,1.01]],"ltp":0.0,"tv":0.0,"id":14343845}]}]}
{"op":"mcm","clk":"1003550991","pt":1580609390414,"mc":[{"id":"1.168230755","rc":[{"batb":[[0,2.86,89.68],[1,2.84,30.29]],"ltp":0.0,"tv":0.0,"id":13095165}]}]}
{"op":"mcm","clk":"1003551048","pt":1580609391080,"mc":[{"id":"1.168230755","rc":[{"batb":[[0,3.05,30.29]],"ltp":0.0,"tv":0.0,"id":14343845}]}]}
{"op":"mcm","clk":"1003559981","pt":1580609511649,"mc":[{"id":"1.168230755","rc":[{"batb":[[1,1.02,2],[2,1.01,1.01]],"ltp":0.0,"tv":0.0,"id":13095165}]}]}
{"op":"mcm","clk":"1003560029","pt":1580609512367,"mc":[{"id":"1.168230755","rc":[{"batb":[[0,2.88,30.28]],"ltp":0.0,"tv":0.0,"id":13095165}]}]}
{"op":"mcm","clk":"1003560118","pt":1580609513350,"mc":[{"id":"1.168230755","rc":[{"batb":[[0,2.74,93.52],[1,2.64,30.29],[2,1.02,2]],"ltp":0.0,"tv":0.0,"id":14343845}]}]}
{"op":"mcm","clk":"1003568760","pt":1580609633513,"mc":[{"id":"1.168230755","rc":[{"batb":[[0,2.4,106.91]],"ltp":0.0,"tv":0.0,"id":13095165}]}]}
{"op":"mcm","clk":"1003568859","pt":1580609634599,"mc":[{"id":"1.168230755","rc":[{"batb":[[0,3.6,70.99]],"batl":[[0,7.8,323.82]],"ltp":0.0,"tv":0.0,"id":13095168},{"batb":[[0,2.64,97.32],[1,2.52,30.29],[2,1.02,2]],"ltp":0.0,"tv":0.0,"id":13095165},{"batb":[[0,2.88,88.96],[1,2.76,30.29]],"ltp":0.0,"tv":0.0,"id":14343845}]}]}
{"op":"mcm","clk":"1003568928","pt":1580609635312,"mc":[{"id":"1.168230755","rc":[{"batl":[[0,9.4,267.74]],"ltp":0.0,"tv":0.0,"id":14343850}]}]}
{"op":"mcm","clk":"1003577330","pt":1580609755645,"mc":[{"id":"1.168230755","rc":[{"batb":[[0,2.78,92.16],[1,2.66,30.29]],"batl":[[0,4.6,337.81]],"ltp":0.0,"tv":0.0,"id":13095165},{"batb":[[1,1.02,2],[2,1.01,1.01]],"ltp":0.0,"tv":0.0,"id":14343845}]}]}
{"op":"mcm","clk":"1003577357","pt":1580609756008,"mc":[{"id":"1.168230755","rc":[{"batb":[[0,2.92,87.69],[1,2.9,30.29],[2,1.02,2]],"ltp":0.0,"tv":0.0,"id":14343845}]}]}
{"op":"mcm","clk":"1003585394","pt":1580609876571,"mc":[{"id":"1.168230755","rc":[{"batb":[[1,1.02,2],[2,1.01,1.01]],"ltp":0.0,"tv":0.0,"id":13095165}]}]}
{"op":"mcm","clk":"1003585462","pt":1580609877601,"mc":[{"id":"1.168230755","rc":[{"batb":[[0,2.82,91.03],[1,2.8,30.29],[2,1.02,2]],"ltp":0.0,"tv":0.0,"id":13095165},{"batb":[[0,2.98,85.9],[1,2.94,30.29]],"ltp":0.0,"tv":0.0,"id":14343845}]}]}
{"op":"mcm","clk":"1003594781","pt":1580609999555,"mc":[{"id":"1.168230755","rc":[{"batb":[[0,2.86,89.68],[1,2.84,30.29]],"ltp":0.0,"tv":0.0,"id":13095165},{"batb":[[1,1.02,2],[2,1.01,1.01]],"ltp":0.0,"tv":0.0,"id":14343845}]}]}
{"op":"mcm","clk":"1003594804","pt":1580609999865,"mc":[{"id":"1.168230755","rc":[{"batb":[[0,3,115.86]],"ltp":0.0,"tv":0.0,"id":14343845}]}]}
{"op":"mcm","clk":"1003604401","pt":1580610120464,"mc":[{"id":"1.168230755","rc":[{"batb":[[0,2.88,30.28],[1,2.86,89.68]],"ltp":0.0,"tv":0.0,"id":13095165}]}]}
{"op":"mcm","clk":"1003604477","pt":1580610121400,"mc":[{"id":"1.168230755","rc":[{"batb":[[1,1.02,2],[2,1.01,1.01]],"ltp":0.0,"tv":0.0,"id":13095165},{"batb":[[0,3.05,30.29]],"ltp":0.0,"tv":0.0,"id":14343845}]}]}
{"op":"mcm","clk":"1003612903","pt":1580610242633,"mc":[{"id":"1.168230755","rc":[{"batb":[[0,2.62,98.04],[1,2.52,30.29],[2,1.02,2]],"ltp":0.0,"tv":0.0,"id":13095165}]}]}
{"op":"mcm","clk":"1003612940","pt":1580610243145,"mc":[{"id":"1.168230755","rc":[{"batb":[[0,2.9,88.36],[1,2.64,30.29],[2,1.02,2]],"ltp":0.0,"tv":0.0,"id":14343845}]}]}
{"op":"mcm","clk":"1003622582","pt":1580610363644,"mc":[{"id":"1.168230755","rc":[{"batb":[[0,2.64,30.29],[1,1.02,2],[2,1.01,1.01]],"ltp":0.0,"tv":0.0,"id":13095165}]}]}
{"op":"mcm","clk":"1003622663","pt":1580610364579,"mc":[{"id":"1.168230755","rc":[{"batb":[[0,2.68,95.86],[1,2.64,30.29],[2,1.02,2]],"ltp":0.0,"tv":0.0,"id":13095165},{"batb":[[0,2.94,87.09],[1,2.92,30.29]],"ltp":0.0,"tv":0.0,"id":14343845}]}]}
{"op":"mcm","clk":"1003632512","pt":1580610485503,"mc":[{"id":"1.168230755","rc":[{"batb":[[0,2.7,30.28],[1,2.68,95.86]],"ltp":0.0,"tv":0.0,"id":13095165}]}]}
{"op":"mcm","clk":"1003632600","pt":1580610486545,"mc":[{"id":"1.168230755","rc":[{"batb":[[0,2.78,92.16],[1,2.7,30.28]],"ltp":0.0,"tv":0.0,"id":13095165},{"batb":[[0,2.98,85.9],[1,2.96,30.29]],"ltp":0.0,"tv":0.0,"id":14343845}]}]}
{"op":"mcm","clk":"1003642133","pt":1580610607482,"mc":[{"id":"1.168230755","rc":[{"batb":[[0,2.82,91.03],[1,2.8,30.29]],"ltp":0.0,"tv":0.0,"id":13095165}]}]}
{"op":"mcm","clk":"1003642199","pt":1580610608198,"mc":[{"id":"1.168230755","rc":[{"batb":[[0,3,115.86],[1,1.02,2],[2,1.01,1.01]],"ltp":0.0,"tv":0.0,"id":14343845}]}]}
{"op":"mcm","clk":"1003651463","pt":1580610729560,"mc":[{"id":"1.168230755","rc":[{"batb":[[1,1.02,2],[2,1.01,1.01]],"ltp":0.0,"tv":0.0,"id":13095165}]}]}
{"op":"mcm","clk":"1003651547","pt":1580610730543,"mc":[{"id":"1.168230755","rc":[{"batb":[[0,2.86,89.68],[1,2.84,30.29],[2,1.02,2]],"ltp":0.0,"tv":0.0,"id":13095165},{"batb":[[0,3.05,30.29]],"ltp":0.0,"tv":0.0,"id":14343845}]}]}
{"op":"mcm","clk":"1003659729","pt":1580610851633,"mc":[{"id":"1.168230755","rc":[{"batb":[[0,2.88,30.28],[1,2.86,89.68]],"ltp":0.0,"tv":0.0,"id":13095165}]}]}
{"op":"mcm","clk":"1003659798","pt":1580610852515,"mc":[{"id":"1.168230755","rc":[{"batb":[[1,1.02,2],[2,1.01,1.01]],"ltp":0.0,"tv":0.0,"id":13095165},{"batb":[[0,2.64,30.29],[1,2.52,101.99],[2,1.02,2]],"ltp":0.0,"tv":0.0,"id":14343845}]}]}
{"op":"mcm","clk":"1003659817","pt":1580610852821,"mc":[{"id":"1.168230755","rc":[{"batb":[[0,2.72,94.34],[1,2.64,30.29]],"ltp":0.0,"tv":0.0,"id":14343845}]}]}
{"op":"mcm","clk":"1003668150","pt":1580610972614,"mc":[{"id":"1.168230755","rc":[{"batb":[[0,1.02,2],[1,1.01,1.01],[2,1.01,0]],"ltp":0.0,"tv":0.0,"id":13095165}]}]}
{"op":"mcm","clk":"1003668237","pt":1580610973643,"mc":[{"id":"1.168230755","rc":[{"batb":[[0,2.68,95.86],[1,2.52,30.29],[2,1.02,2]],"ltp":0.0,"tv":0.0,"id":13095165},{"batb":[[1,1.02,2],[2,1.01,1.01]],"ltp":0.0,"tv":0.0,"id":14343845}]}]}
{"op":"mcm","clk":"1003668280","pt":1580610974108,"mc":[{"id":"1.168230755","rc":[{"batb":[[0,2.76,92.98],[1,2.74,30.29],[2,1.02,2]],"ltp":0.0,"tv":0.0,"id":14343845}]}]}
{"op":"mcm","clk":"1003676617","pt":1580611094378,"mc":[{"id":"1.168230755","rc":[{"batb":[[1,1.02,2],[2,1.01,1.01]],"ltp":0.0,"tv":0.0,"id":13095165}]}]}
{"op":"mcm","clk":"1003676703","pt":1580611095462,"mc":[{"id":"1.168230755","rc":[{"batb":[[0,2.72,94.34],[1,2.7,30.28],[2,1.02,2]],"ltp":0.0,"tv":0.0,"id":13095165},{"batb":[[0,2.78,30.29],[1,2.76,92.98]],"ltp":0.0,"tv":0.0,"id":14343845}]}]}
{"op":"mcm","clk":"1003676724","pt":1580611095772,"mc":[{"id":"1.168230755","rc":[{"batb":[[0,2.8,91.48],[1,2.78,30.29]],"ltp":0.0,"tv":0.0,"id":14343845}]}]}
{"op":"mcm","clk":"1003685016","pt":1580611216114,"mc":[{"id":"1.168230755","rc":[{"batb":[[1,1.02,2],[2,1.01,1.01]],"ltp":0.0,"tv":0.0,"id":13095165}]}]}
{"op":"mcm","clk":"1003685115","pt":1580611217605,"mc":[{"id":"1.168230755","rc":[{"batb":[[0,2.74,30.29]],"ltp":0.0,"tv":0.0,"id":13095165},{"batb":[[1,1.02,2],[2,1.01,1.01]],"ltp":0.0,"tv":0.0,"id":14343845}]}]}
{"op":"mcm","clk":"1003685141","pt":1580611218016,"mc":[{"id":"1.168230755","rc":[{"batb":[[0,2.78,92.16],[1,2.74,30.29],[2,1.02,2]],"ltp":0.0,"tv":0.0,"id":13095165},{"batb":[[0,2.84,90.22],[1,2.82,30.29],[2,1.02,2]],"batl":[[0,4.3,407.14]],"ltp":0.0,"tv":0.0,"id":14343845}]}]}
{"op":"mcm","clk":"1003692480","pt":1580611338643,"mc":[{"id":"1.168230755","rc":[{"batb":[[0,2.84,90.22],[1,2.8,30.29]],"ltp":0.0,"tv":0.0,"id":13095165},{"batb":[[0,2.86,30.29],[1,1.02,2],[2,1.01,1.01]],"ltp":0.0,"tv":0.0,"id":14343845}]}]}
{"op":"mcm","clk":"1003692489","pt":1580611338755,"mc":[{"id":"1.168230755","rc":[{"batb":[[0,2.92,87.69],[1,2.86,30.29],[2,1.02,2]],"ltp":0.0,"tv":0.0,"id":14343845}]}]}
{"op":"mcm","clk":"1003699574","pt":1580611460605,"mc":[{"id":"1.168230755","rc":[{"batb":[[0,2.86,119.97],[1,1.02,2],[2,1.01,1.01]],"ltp":0.0,"tv":0.0,"id":13095165}]}]}
{"op":"mcm","clk":"1003699604","pt":1580611461112,"mc":[{"id":"1.168230755","rc":[{"batb":[[0,2.98,85.9],[1,2.94,30.29]],"ltp":0.0,"tv":0.0,"id":14343845}]}]}
{"op":"mcm","clk":"1003706530","pt":1580611581646,"mc":[{"id":"1.168230755","rc":[{"batb":[[0,2.88,30.28],[1,2.86,89.68],[2,1.02,2]],"ltp":0.0,"tv":0.0,"id":13095165}]}]}
{"op":"mcm","clk":"1003706542","pt":1580611581848,"mc":[{"id":"1.168230755","rc":[{"batb":[[1,1.02,2],[2,1.01,1.01]],"ltp":0.0,"tv":0.0,"id":13095165}]}]}
{"op":"mcm","clk":"1003706651","pt":1580611583645,"mc":[{"id":"1.168230755","rc":[{"batb":[[0,3,30.29],[1,1.02,2],[2,1.01,1.01]],"ltp":0.0,"tv":0.0,"id":14343845}]}]}
{"op":"mcm","clk":"1003706660","pt":1580611583748,"mc":[{"id":"1.168230755","rc":[{"batb":[[0,3,115.86]],"ltp":0.0,"tv":0.0,"id":14343845}]}]}
{"op":"mcm","clk":"1003713463","pt":1580611703629,"mc":[{"id":"1.168230755","rc":[{"batb":[[0,2.6,98.59],[1,2.52,30.29],[2,1.02,2]],"ltp":0.0,"tv":0.0,"id":13095165}]}]}
{"op":"mcm","clk":"1003713506","pt":1580611704197,"mc":[{"id":"1.168230755","rc":[{"batb":[[0,3.05,30.29]],"ltp":0.0,"tv":0.0,"id":14343845}]}]}
{"op":"mcm","clk":"1003719690","pt":1580611825183,"mc":[{"id":"1.168230755","rc":[{"batb":[[1,1.02,2],[2,1.01,1.01]],"ltp":0.0,"tv":0.0,"id":13095165}]}]}
{"op":"mcm","clk":"1003719763","pt":1580611826470,"mc":[{"id":"1.168230755","rc":[{"batb":[[0,2.66,96.34],[1,2.62,30.29],[2,1.02,2]],"ltp":0.0,"tv":0.0,"id":13095165}]}]}
{"op":"mcm","clk":"1003719818","pt":1580611827293,"mc":[{"id":"1.168230755","rc":[{"batb":[[0,2.86,89.68],[1,2.64,30.29],[2,1.02,2]],"ltp":0.0,"tv":0.0,"id":14343845}]}]}
{"op":"mcm","clk":"1003726290","pt":1580611946542,"mc":[{"id":"1.168230755","rc":[{"batb":[[0,2.7,94.92],[1,2.68,30.29]],"ltp":0.0,"tv":0.0,"id":13095165}]}]}
{"op":"mcm","clk":"1003726368","pt":1580611947625,"mc":[{"id":"1.168230755","rc":[{"batb":[[0,2.9,88.36],[1,2.88,30.28]],"ltp":0.0,"tv":0.0,"id":14343845}]}]}
{"op":"mcm","clk":"1003733688","pt":1580612068290,"mc":[{"id":"1.168230755","rc":[{"batb":[[0,2.76,92.98],[1,2.72,30.29]],"ltp":0.0,"tv":0.0,"id":13095165},{"batb":[[1,1.02,2],[2,1.01,1.01]],"ltp":0.0,"tv":0.0,"id":14343845}]}]}
{"op":"mcm","clk":"1003733738","pt":1580612069119,"mc":[{"id":"1.168230755","rc":[{"batb":[[0,2.94,87.09],[1,2.92,30.29],[2,1.02,2]],"ltp":0.0,"tv":0.0,"id":14343845}]}]}
{"op":"mcm","clk":"1003741880","pt":1580612189554,"mc":[{"id":"1.168230755","rc":[{"batb":[[1,1.02,2],[2,1.01,1.01]],"ltp":0.0,"tv":0.0,"id":13095165}]}]}
{"op":"mcm","clk":"1003741945","pt":1580612190580,"mc":[{"id":"1.168230755","rc":[{"batb":[[0,2.84,90.22],[1,2.78,30.29],[2,1.02,2]],"ltp":0.0,"tv":0.0,"id":13095165},{"batb":[[0,2.96,30.29],[1,2.94,87.09]],"ltp":0.0,"tv":0.0,"id":14343845}]}]}
{"op":"mcm","clk":"1003741970","pt":1580612190943,"mc":[{"id":"1.168230755","rc":[{"batb":[[0,2.98,85.9],[1,2.96,30.29]],"ltp":0.0,"tv":0.0,"id":14343845}]}]}
{"op":"mcm","clk":"1003748933","pt":1580612311632,"mc":[{"id":"1.168230755","rc":[{"batb":[[0,2.86,119.97],[1,1.02,2],[2,1.01,1.01]],"ltp":0.0,"tv":0.0,"id":13095165}]}]}
{"op":"mcm","clk":"1003748967","pt":1580612312251,"mc":[{"id":"1.168230755","rc":[{"batb":[[0,3,115.86],[1,1.02,2],[2,1.01,1.01]],"ltp":0.0,"tv":0.0,"id":14343845}]}]}
{"op":"mcm","clk":"1003756976","pt":1580612433488,"mc":[{"id":"1.168230755","rc":[{"batb":[[0,2.88,30.28]],"ltp":0.0,"tv":0.0,"id":13095165}]}]}
{"op":"mcm","clk":"1003757035","pt":1580612434312,"mc":[{"id":"1.168230755","rc":[{"batb":[[0,3.05,30.29]],"ltp":0.0,"tv":0.0,"id":14343845}]}]}
{"op":"mcm","clk":"1003765224","pt":1580612554442,"mc":[{"id":"1.168230755","rc":[{"batb":[[0,1.02,2],[1,1.01,1.01],[2,1.01,0]],"ltp":0.0,"tv":0.0,"id":13095165}]}]}
{"op":"mcm","clk":"1003765307","pt":1580612555574,"mc":[{"id":"1.168230755","rc":[{"batb":[[0,2.62,98.04],[1,2.52,30.29],[2,1.02,2]],"ltp":0.0,"tv":0.0,"id":13095165},{"batb":[[0,2.64,30.29]],"ltp":0.0,"tv":0.0,"id":14343845}]}]}
{"op":"mcm","clk":"1003765319","pt":1580612555760,"mc":[{"id":"1.168230755","rc":[{"batb":[[0,2.64,127.61]],"ltp":0.0,"tv":0.0,"id":14343845}]}]}
{"op":"mcm","clk":"1003772522","pt":1580612676526,"mc":[{"id":"1.168230755","rc":[{"batb":[[0,2.68,95.86],[1,2.64,30.29]],"ltp":0.0,"tv":0.0,"id":13095165}]}]}
{"op":"mcm","clk":"1003772565","pt":1580612677097,"mc":[{"id":"1.168230755","rc":[{"batb":[[0,2.86,89.68],[1,2.66,30.29],[2,1.02,2]],"ltp":0.0,"tv":0.0,"id":14343845}]}]}
{"op":"mcm","clk":"1003779148","pt":1580612798580,"mc":[{"id":"1.168230755","rc":[{"batb":[[0,2.8,91.48],[1,2.7,30.28]],"ltp":0.0,"tv":0.0,"id":13095165}]}]}
{"op":"mcm","clk":"1003779212","pt":1580612799563,"mc":[{"id":"1.168230755","rc":[{"batb":[[0,2.88,30.28],[1,1.02,2],[2,1.01,1.01]],"ltp":0.0,"tv":0.0,"id":14343845}]}]}
{"op":"mcm","clk":"1003779221","pt":1580612799672,"mc":[{"id":"1.168230755","rc":[{"batb":[[0,2.92,87.69],[1,2.88,30.28],[2,1.02,2]],"ltp":0.0,"tv":0.0,"id":14343845}]}]}
{"op":"mcm","clk":"1003785234","pt":1580612919436,"mc":[{"id":"1.168230755","rc":[{"batb":[[1,1.02,2],[2,1.01,1.01]],"ltp":0.0,"tv":0.0,"id":13095165}]}]}
{"op":"mcm","clk":"1003785270","pt":1580612920360,"mc":[{"id":"1.168230755","rc":[{"batb":[[0,2.84,90.22],[1,2.82,30.29],[2,1.02,2]],"ltp":0.0,"tv":0.0,"id":13095165}]}]}
{"op":"mcm","clk":"1003785320","pt":1580612921439,"mc":[{"id":"1.168230755","rc":[{"batb":[[0,2.94,30.29],[1,2.92,87.69]],"ltp":0.0,"tv":0.0,"id":14343845}]}]}
{"op":"mcm","clk":"1003785337","pt":1580612921948,"mc":[{"id":"1.168230755","rc":[{"batb":[[0,2.96,86.63],[1,2.94,30.29]],"ltp":0.0,"tv":0.0,"id":14343845}]}]}
{"op":"mcm","clk":"1003789638","pt":1580613041561,"mc":[{"id":"1.168230755","rc":[{"batb":[[0,2.86,30.29],[1,2.84,90.22]],"ltp":0.0,"tv":0.0,"id":13095165}]}]}
{"op":"mcm","clk":"1003789689","pt":1580613042542,"mc":[{"id":"1.168230755","rc":[{"batb":[[0,2.86,119.97],[1,1.02,2],[2,1.01,1.01]],"ltp":0.0,"tv":0.0,"id":13095165},{"batb":[[0,3,85.57],[1,2.98,30.29]],"ltp":0.0,"tv":0.0,"id":14343845}]}]}
{"op":"mcm","clk":"1003794332","pt":1580613164568,"mc":[{"id":"1.168230755","rc":[{"batb":[[0,2.88,30.28]],"ltp":0.0,"tv":0.0,"id":13095165}]}]}
{"op":"mcm","clk":"1003794360","pt":1580613165288,"mc":[{"id":"1.168230755","rc":[{"batb":[[0,3.05,30.29],[1,1.02,2],[2,1.01,1.01]],"ltp":0.0,"tv":0.0,"id":14343845}]}]}
{"op":"mcm","clk":"1003797068","pt":1580613234217,"mc":[{"id":"1.168230755","rc":[{"batb":[[0,1.02,2],[1,1.01,1.01],[2,1.01,0]],"ltp":0.0,"tv":0.0,"id":13095168},{"batb":[[0,1.02,2],[1,1.01,1.01],[2,1.01,0]],"ltp":0.0,"tv":0.0,"id":14343850}]}]}
{"op":"mcm","clk":"1003799015","pt":1580613285587,"mc":[{"id":"1.168230755","rc":[{"batb":[[0,1.02,2],[1,1.01,1.01],[2,1.01,0]],"ltp":0.0,"tv":0.0,"id":13095165}]}]}
{"op":"mcm","clk":"1003799050","pt":1580613286309,"mc":[{"id":"1.168230755","rc":[{"batb":[[0,2.64,97.32],[1,2.52,30.29],[2,1.02,2]],"ltp":0.0,"tv":0.0,"id":13095165}]}]}
{"op":"mcm","clk":"1003799087","pt":1580613287292,"mc":[{"id":"1.168230755","rc":[{"batb":[[0,2.7,94.92],[1,2.64,30.29],[2,1.02,2]],"ltp":0.0,"tv":0.0,"id":14343845}]}]}
{"op":"mcm","clk":"1003803809","pt":1580613407550,"mc":[{"id":"1.168230755","rc":[{"batb":[[0,2.66,30.29],[1,1.02,2],[2,1.01,1.01]],"ltp":0.0,"tv":0.0,"id":13095165}]}]}
{"op":"mcm","clk":"1003803839","pt":1580613408168,"mc":[{"id":"1.168230755","rc":[{"batb":[[0,2.7,94.92],[1,2.66,30.29],[2,1.02,2]],"ltp":0.0,"tv":0.0,"id":13095165},{"batb":[[0,2.74,93.52],[1,2.72,30.29]],"ltp":0.0,"tv":0.0,"id":14343845}]}]}
{"op":"mcm","clk":"1003808274","pt":1580613529624,"mc":[{"id":"1.168230755","rc":[{"batb":[[0,2.78,92.16],[1,2.72,30.29]],"ltp":0.0,"tv":0.0,"id":13095165},{"batb":[[0,2.76,30.29],[1,1.02,2],[2,1.01,1.01]],"ltp":0.0,"tv":0.0,"id":14343845}]}]}
{"op":"mcm","clk":"1003808277","pt":1580613529726,"mc":[{"id":"1.168230755","rc":[{"batb":[[0,2.82,91.03],[1,2.76,30.29],[2,1.02,2]],"ltp":0.0,"tv":0.0,"id":14343845}]}]}
{"op":"mcm","clk":"1003812704","pt":1580613650601,"mc":[{"id":"1.168230755","rc":[{"batb":[[0,2.8,30.29],[1,2.78,92.16]],"ltp":0.0,"tv":0.0,"id":13095165}]}]}
{"op":"mcm","clk":"1003812754","pt":1580613651530,"mc":[{"id":"1.168230755","rc":[{"batb":[[0,2.82,91.03],[1,2.8,30.29]],"ltp":0.0,"tv":0.0,"id":13095165},{"batb":[[0,2.84,30.29],[1,2.82,91.03]],"ltp":0.0,"tv":0.0,"id":14343845}]}]}
{"op":"mcm","clk":"1003812766","pt":1580613651790,"mc":[{"id":"1.168230755","rc":[{"batb":[[0,2.86,89.68],[1,2.84,30.29]],"ltp":0.0,"tv":0.0,"id":14343845}]}]}
{"op":"mcm","clk":"1003817455","pt":1580613772551,"mc":[{"id":"1.168230755","rc":[{"batb":[[0,2.86,89.68],[1,2.84,30.29]],"ltp":0.0,"tv":0.0,"id":13095165}]}]}
{"op":"mcm","clk":"1003817496","pt":1580613773574,"mc":[{"id":"1.168230755","rc":[{"batb":[[0,2.88,30.28],[1,1.02,2],[2,1.01,1.01]],"ltp":0.0,"tv":0.0,"id":14343845}]}]}
{"op":"mcm","clk":"1003817503","pt":1580613773676,"mc":[{"id":"1.168230755","rc":[{"batb":[[0,2.9,88.36],[1,2.88,30.28],[2,1.02,2]],"ltp":0.0,"tv":0.0,"id":14343845}]}]}
{"op":"mcm","clk":"1003822995","pt":1580613894645,"mc":[{"id":"1.168230755","rc":[{"batb":[[0,2.88,30.28],[1,1.02,2],[2,1.01,1.01]],"ltp":0.0,"tv":0.0,"id":13095165}]}]}
{"op":"mcm","clk":"1003823042","pt":1580613895520,"mc":[{"id":"1.168230755","rc":[{"batb":[[0,2.92,30.29],[1,2.9,88.36]],"ltp":0.0,"tv":0.0,"id":14343845}]}]}
{"op":"mcm","clk":"1003823057","pt":1580613895934,"mc":[{"id":"1.168230755","rc":[{"batb":[[0,2.94,87.09],[1,2.92,30.29]],"ltp":0.0,"tv":0.0,"id":14343845}]}]}
{"op":"mcm","clk":"1003828863","pt":1580614015578,"mc":[{"id":"1.168230755","rc":[{"batb":[[0,1.02,2],[1,1.01,1.01],[2,1.01,0]],"ltp":0.0,"tv":0.0,"id":13095165}]}]}
{"op":"mcm","clk":"1003828925","pt":1580614016607,"mc":[{"id":"1.168230755","rc":[{"batb":[[0,2.68,95.86],[1,2.52,30.29],[2,1.02,2]],"ltp":0.0,"tv":0.0,"id":13095165},{"batb":[[1,1.02,2],[2,1.01,1.01]],"ltp":0.0,"tv":0.0,"id":14343845}]}]}
{"op":"mcm","clk":"1003828938","pt":1580614016915,"mc":[{"id":"1.168230755","rc":[{"batb":[[0,2.98,85.9],[1,2.96,30.29],[2,1.02,2]],"ltp":0.0,"tv":0.0,"id":14343845}]}]}
{"op":"mcm","clk":"1003834996","pt":1580614137261,"mc":[{"id":"1.168230755","rc":[{"batb":[[1,1.02,2],[2,1.01,1.01]],"ltp":0.0,"tv":0.0,"id":13095165}]}]}
{"op":"mcm","clk":"1003835064","pt":1580614138648,"mc":[{"id":"1.168230755","rc":[{"batb":[[0,2.82,91.03],[1,2.7,30.28],[2,1.02,2]],"ltp":0.0,"tv":0.0,"id":13095165},{"batb":[[0,3,115.86],[1,1.02,2],[2,1.01,1.01]],"ltp":0.0,"tv":0.0,"id":14343845}]}]}
{"op":"mcm","clk":"1003841478","pt":1580614259470,"mc":[{"id":"1.168230755","rc":[{"batb":[[0,2.84,30.29],[1,2.82,91.03]],"ltp":0.0,"tv":0.0,"id":13095165}]}]}
{"op":"mcm","clk":"1003841516","pt":1580614260407,"mc":[{"id":"1.168230755","rc":[{"batb":[[0,2.86,89.68],[1,2.84,30.29]],"ltp":0.0,"tv":0.0,"id":13095165},{"batb":[[0,3.05,30.29]],"ltp":0.0,"tv":0.0,"id":14343845}]}]}
{"op":"mcm","clk":"1003848021","pt":1580614381382,"mc":[{"id":"1.168230755","rc":[{"batb":[[0,2.88,30.28],[1,1.02,2],[2,1.01,1.01]],"ltp":0.0,"tv":0.0,"id":13095165}]}]}
{"op":"mcm","clk":"1003848104","pt":1580614382583,"mc":[{"id":"1.168230755","rc":[{"batb":[[0,2.64,30.29]],"ltp":0.0,"tv":0.0,"id":14343845}]}]}
{"op":"mcm","clk":"1003848119","pt":1580614382790,"mc":[{"id":"1.168230755","rc":[{"batb":[[0,2.96,86.63],[1,2.64,30.29],[2,1.02,2]],"ltp":0.0,"tv":0.0,"id":14343845}]}]}
{"op":"mcm","clk":"1003854557","pt":1580614502612,"mc":[{"id":"1.168230755","rc":[{"batb":[[0,1.02,2],[1,1.01,1.01],[2,1.01,0]],"ltp":0.0,"tv":0.0,"id":13095165}]}]}
{"op":"mcm","clk":"1003854605","pt":1580614503436,"mc":[{"id":"1.168230755","rc":[{"batb":[[0,2.64,97.32],[1,2.52,30.29],[2,1.02,2]],"ltp":0.0,"tv":0.0,"id":13095165}]}]}
{"op":"mcm","clk":"1003854656","pt":1580614504107,"mc":[{"id":"1.168230755","rc":[{"batb":[[0,3,85.57],[1,2.98,30.29]],"ltp":0.0,"tv":0.0,"id":14343845}]}]}
{"op":"mcm","clk":"1003860910","pt":1580614624391,"mc":[{"id":"1.168230755","rc":[{"batb":[[0,2.68,95.86],[1,2.66,30.29]],"ltp":0.0,"tv":0.0,"id":13095165}]}]}
{"op":"mcm","clk":"1003860939","pt":1580614625004,"mc":[{"id":"1.168230755","rc":[{"batb":[[0,3.05,30.29],[1,1.02,2],[2,1.01,1.01]],"ltp":0.0,"tv":0.0,"id":14343845}]}]}
{"op":"mcm","clk":"1003867601","pt":1580614746471,"mc":[{"id":"1.168230755","rc":[{"batb":[[0,2.8,91.48],[1,2.7,30.28]],"ltp":0.0,"tv":0.0,"id":13095165}]}]}
{"op":"mcm","clk":"1003867634","pt":1580614746940,"mc":[{"id":"1.168230755","rc":[{"batb":[[0,2.92,87.69],[1,2.64,30.29],[2,1.02,2]],"ltp":0.0,"tv":0.0,"id":14343845}]}]}
{"op":"mcm","clk":"1003873940","pt":1580614867316,"mc":[{"id":"1.168230755","rc":[{"batb":[[1,1.02,2],[2,1.01,1.01]],"ltp":0.0,"tv":0.0,"id":13095165}]}]}
{"op":"mcm","clk":"1003873994","pt":1580614868620,"mc":[{"id":"1.168230755","rc":[{"batb":[[0,2.84,90.22],[1,2.82,30.29],[2,1.02,2]],"ltp":0.0,"tv":0.0,"id":13095165},{"batb":[[0,2.94,30.29],[1,1.02,2],[2,1.01,1.01]],"batl":[[0,5,350.37]],"ltp":0.0,"tv":0.0,"id":14343845}]}]}
{"op":"mcm","clk":"1003873998","pt":1580614868723,"mc":[{"id":"1.168230755","rc":[{"batb":[[0,2.96,86.63],[1,2.94,30.29],[2,1.02,2]],"ltp":0.0,"tv":0.0,"id":14343845}]}]}
{"op":"mcm","clk":"1003878257","pt":1580614989239,"mc":[{"id":"1.168230755","rc":[{"batb":[[0,2.86,30.29],[1,2.84,90.22]],"ltp":0.0,"tv":0.0,"id":13095165}]}]}
{"op":"mcm","clk":"1003878296","pt":1580614990130,"mc":[{"id":"1.168230755","rc":[{"batb":[[0,2.86,119.97],[1,1.02,2],[2,1.01,1.01]],"ltp":0.0,"tv":0.0,"id":13095165},{"batb":[[0,3,85.57],[1,2.98,30.29]],"ltp":0.0,"tv":0.0,"id":14343845}]}]}
{"op":"mcm","clk":"1003881672","pt":1580615111436,"mc":[{"id":"1.168230755","rc":[{"batb":[[0,2.88,30.28]],"ltp":0.0,"tv":0.0,"id":13095165}]}]}
{"op":"mcm","clk":"1003881695","pt":1580615112157,"mc":[{"id":"1.168230755","rc":[{"batb":[[0,3.05,30.29],[1,1.02,2],[2,1.01,1.01]],"ltp":0.0,"tv":0.0,"id":14343845}]}]}
{"op":"mcm","clk":"1003885563","pt":1580615233207,"mc":[{"id":"1.168230755","rc":[{"batb":[[0,2.62,98.04],[1,2.52,30.29],[2,1.02,2]],"ltp":0.0,"tv":0.0,"id":13095165}]}]}
{"op":"mcm","clk":"1003885593","pt":1580615234230,"mc":[{"id":"1.168230755","rc":[{"batb":[[0,2.86,89.68],[1,2.64,30.29],[2,1.02,2]],"ltp":0.0,"tv":0.0,"id":14343845}]}]}
{"op":"mcm","clk":"1003889299","pt":1580615354544,"mc":[{"id":"1.168230755","rc":[{"batb":[[0,2.8,91.48],[1,2.64,30.29]],"ltp":0.0,"tv":0.0,"id":13095165},{"batb":[[1,1.02,2],[2,1.01,1.01]],"ltp":0.0,"tv":0.0,"id":14343845}]}]}
{"op":"mcm","clk":"1003889330","pt":1580615355363,"mc":[{"id":"1.168230755","rc":[{"batb":[[0,2.9,88.36],[1,2.88,30.28],[2,1.02,2]],"ltp":0.0,"tv":0.0,"id":14343845}]}]}
{"op":"mcm","clk":"1003892798","pt":1580615476409,"mc":[{"id":"1.168230755","rc":[{"batb":[[0,2.84,90.22],[1,2.82,30.29]],"ltp":0.0,"tv":0.0,"id":13095165},{"batb":[[1,1.02,2],[2,1.01,1.01]],"ltp":0.0,"tv":0.0,"id":14343845}]}]}
{"op":"mcm","clk":"1003892824","pt":1580615477331,"mc":[{"id":"1.168230755","rc":[{"batb":[[0,2.96,86.63],[1,2.92,30.29],[2,1.02,2]],"ltp":0.0,"tv":0.0,"id":14343845}]}]}
{"op":"mcm","clk":"1003896373","pt":1580615597488,"mc":[{"id":"1.168230755","rc":[{"batb":[[0,2.86,30.29],[1,2.84,90.22]],"ltp":0.0,"tv":0.0,"id":13095165}]}]}
{"op":"mcm","clk":"1003896408","pt":1580615598510,"mc":[{"id":"1.168230755","rc":[{"batb":[[0,2.86,119.97],[1,1.02,2],[2,1.01,1.01]],"ltp":0.0,"tv":0.0,"id":13095165},{"batb":[[0,3,85.57],[1,2.98,30.29]],"ltp":0.0,"tv":0.0,"id":14343845}]}]}
{"op":"mcm","clk":"1003900464","pt":1580615719574,"mc":[{"id":"1.168230755","rc":[{"batb":[[0,2.88,30.28],[1,2.86,89.68],[2,1.02,2]],"ltp":0.0,"tv":0.0,"id":13095165}]}]}
{"op":"mcm","clk":"1003900489","pt":1580615720452,"mc":[{"id":"1.168230755","rc":[{"batb":[[1,1.02,2],[2,1.01,1.01]],"ltp":0.0,"tv":0.0,"id":13095165},{"batb":[[0,3.05,30.29],[1,1.02,2],[2,1.01,1.01]],"ltp":0.0,"tv":0.0,"id":14343845}]}]}
{"op":"mcm","clk":"1003904825","pt":1580615841248,"mc":[{"id":"1.168230755","rc":[{"batb":[[0,2.7,94.92],[1,2.52,30.29],[2,1.02,2]],"ltp":0.0,"tv":0.0,"id":13095165}]}]}
{"op":"mcm","clk":"1003904861","pt":1580615842173,"mc":[{"id":"1.168230755","rc":[{"batb":[[0,2.88,88.96],[1,2.64,30.29],[2,1.02,2]],"ltp":0.0,"tv":0.0,"id":14343845}]}]}
{"op":"mcm","clk":"1003910106","pt":1580615962618,"mc":[{"id":"1.168230755","rc":[{"batb":[[0,2.72,30.29],[1,1.02,2],[2,1.01,1.01]],"ltp":0.0,"tv":0.0,"id":13095165}]}]}
{"op":"mcm","clk":"1003910150","pt":1580615963441,"mc":[{"id":"1.168230755","rc":[{"batb":[[0,2.8,91.48],[1,2.72,30.29],[2,1.02,2]],"ltp":0.0,"tv":0.0,"id":13095165},{"batb":[[0,2.9,30.29],[1,2.88,88.96]],"ltp":0.0,"tv":0.0,"id":14343845}]}]}
{"op":"mcm","clk":"1003910167","pt":1580615963853,"mc":[{"id":"1.168230755","rc":[{"batb":[[0,2.92,87.69],[1,2.9,30.29]],"ltp":0.0,"tv":0.0,"id":14343845}]}]}
{"op":"mcm","clk":"1003916103","pt":1580616084632,"mc":[{"id":"1.168230755","rc":[{"batb":[[0,2.84,90.22],[1,2.82,30.29]],"ltp":0.0,"tv":0.0,"id":13095165},{"batb":[[1,1.02,2],[2,1.01,1.01]],"ltp":0.0,"tv":0.0,"id":14343845}]}]}
{"op":"mcm","clk":"1003916125","pt":1580616084992,"mc":[{"id":"1.168230755","rc":[{"batb":[[0,2.96,86.63],[1,2.94,30.29],[2,1.02,2]],"ltp":0.0,"tv":0.0,"id":14343845}]}]}
{"op":"mcm","clk":"1003921056","pt":1580616206569,"mc":[{"id":"1.168230755","rc":[{"batb":[[0,2.86,119.97],[1,1.02,2],[2,1.01,1.01]],"ltp":0.0,"tv":0.0,"id":13095165},{"batb":[[0,2.98,30.29],[1,2.96,86.63]],"ltp":0.0,"tv":0.0,"id":14343845}]}]}
{"op":"mcm","clk":"1003921070","pt":1580616206928,"mc":[{"id":"1.168230755","rc":[{"batb":[[0,3,85.57],[1,2.98,30.29]],"ltp":0.0,"tv":0.0,"id":14343845}]}]}
{"op":"mcm","clk":"1003925244","pt":1580616327423,"mc":[{"id":"1.168230755","rc":[{"batb":[[0,2.86,89.68]],"ltp":0.0,"tv":0.0,"id":13095165}]}]}
{"op":"mcm","clk":"1003925286","pt":1580616328538,"mc":[{"id":"1.168230755","rc":[{"batb":[[0,2.88,30.28]],"ltp":0.0,"tv":0.0,"id":13095165},{"batb":[[0,3.05,30.29],[1,3,85.57]],"ltp":0.0,"tv":0.0,"id":14343845}]}]}
{"op":"mcm","clk":"1003925293","pt":1580616328688,"mc":[{"id":"1.168230755","rc":[{"batb":[[1,1.02,2],[2,1.01,1.01]],"ltp":0.0,"tv":0.0,"id":14343845}]}]}
{"op":"mcm","clk":"1003930210","pt":1580616449450,"mc":[{"id":"1.168230755","rc":[{"batb":[[0,2.58,99.56]],"ltp":0.0,"tv":0.0,"id":13095165}]}]}
{"op":"mcm","clk":"1003930266","pt":1580616450634,"mc":[{"id":"1.168230755","rc":[{"batb":[[1,2.52,30.29],[2,1.02,2]],"ltp":0.0,"tv":0.0,"id":13095165},{"batb":[[0,2.76,92.98],[1,2.64,30.29],[2,1.02,2]],"ltp":0.0,"tv":0.0,"id":14343845}]}]}
{"op":"mcm","clk":"1003935461","pt":1580616571588,"mc":[{"id":"1.168230755","rc":[{"batb":[[0,2.64,97.32],[1,2.6,30.29]],"ltp":0.0,"tv":0.0,"id":13095165},{"batb":[[0,2.78,30.29],[1,1.02,2],[2,1.01,1.01]],"ltp":0.0,"tv":0.0,"id":14343845}]}]}
{"op":"mcm","clk":"1003935468","pt":1580616571691,"mc":[{"id":"1.168230755","rc":[{"batb":[[0,2.88,88.96],[1,2.78,30.29],[2,1.02,2]],"ltp":0.0,"tv":0.0,"id":14343845}]}]}
{"op":"mcm","clk":"1003941041","pt":1580616692560,"mc":[{"id":"1.168230755","rc":[{"batb":[[0,2.66,30.29],[1,1.02,2],[2,1.01,1.01]],"ltp":0.0,"tv":0.0,"id":13095165}]}]}
{"op":"mcm","clk":"1003941096","pt":1580616693382,"mc":[{"id":"1.168230755","rc":[{"batb":[[0,2.7,94.92],[1,2.66,30.29],[2,1.02,2]],"ltp":0.0,"tv":0.0,"id":13095165},{"batb":[[0,2.92,87.69],[1,2.9,30.29]],"ltp":0.0,"tv":0.0,"id":14343845}]}]}
{"op":"mcm","clk":"1003947070","pt":1580616814604,"mc":[{"id":"1.168230755","rc":[{"batb":[[0,2.72,30.29],[1,1.02,2],[2,1.01,1.01]],"ltp":0.0,"tv":0.0,"id":13095165}]}]}
{"op":"mcm","clk":"1003947106","pt":1580616815377,"mc":[{"id":"1.168230755","rc":[{"batb":[[0,2.76,92.98],[1,2.72,30.29],[2,1.02,2]],"ltp":0.0,"tv":0.0,"id":13095165},{"batb":[[0,2.98,85.9],[1,2.94,30.29]],"ltp":0.0,"tv":0.0,"id":14343845}]}]}
{"op":"mcm","clk":"1003947956","pt":1580616834933,"mc":[{"id":"1.168230755","rc":[{"batb":[[0,3.4,75.21],[1,1.02,2],[2,1.01,1.01]],"batl":[[0,9.6,262.16]],"ltp":0.0,"tv":0.0,"id":14343850}]}]}
{"op":"mcm","clk":"1003954638","pt":1580616936457,"mc":[{"id":"1.168230755","rc":[{"batb":[[0,2.8,91.48],[1,2.78,30.29]],"ltp":0.0,"tv":0.0,"id":13095165},{"batb":[[0,3,30.29],[1,2.98,85.9]],"ltp":0.0,"tv":0.0,"id":14343845}]}]}
{"op":"mcm","clk":"1003954664","pt":1580616936766,"mc":[{"id":"1.168230755","rc":[{"batb":[[0,3,115.86],[1,1.02,2],[2,1.01,1.01]],"ltp":0.0,"tv":0.0,"id":14343845}]}]}
{"op":"mcm","clk":"1003960018","pt":1580617057549,"mc":[{"id":"1.168230755","rc":[{"batb":[[0,2.82,30.29],[1,2.8,91.48]],"ltp":0.0,"tv":0.0,"id":13095165}]}]}
{"op":"mcm","clk":"1003960058","pt":1580617058329,"mc":[{"id":"1.168230755","rc":[{"batb":[[0,2.84,90.22],[1,2.82,30.29]],"ltp":0.0,"tv":0.0,"id":13095165},{"batb":[[0,3.05,30.29]],"ltp":0.0,"tv":0.0,"id":14343845}]}]}
{"op":"mcm","clk":"1003965677","pt":1580617179474,"mc":[{"id":"1.168230755","rc":[{"batb":[[0,2.86,119.97],[1,1.02,2],[2,1.01,1.01]],"ltp":0.0,"tv":0.0,"id":13095165}]}]}
{"op":"mcm","clk":"1003965700","pt":1580617179991,"mc":[{"id":"1.168230755","rc":[{"batb":[[0,2.72,94.34],[1,2.64,30.29],[2,1.02,2]],"ltp":0.0,"tv":0.0,"id":14343845}]}]}
{"op":"mcm","clk":"1003971193","pt":1580617301347,"mc":[{"id":"1.168230755","rc":[{"batb":[[0,2.88,30.28]],"ltp":0.0,"tv":0.0,"id":13095165}]}]}
{"op":"mcm","clk":"1003971257","pt":1580617302121,"mc":[{"id":"1.168230755","rc":[{"batb":[[0,2.8,91.48],[1,2.74,30.29]],"ltp":0.0,"tv":0.0,"id":14343845}]}]}
{"op":"mcm","clk":"1003976811","pt":1580617422454,"mc":[{"id":"1.168230755","rc":[{"batb":[[0,1.02,2],[1,1.01,1.01],[2,1.01,0]],"ltp":0.0,"tv":0.0,"id":13095165}]}]}
{"op":"mcm","clk":"1003976865","pt":1580617423646,"mc":[{"id":"1.168230755","rc":[{"batb":[[0,2.56,100.33],[1,2.52,30.29],[2,1.02,2]],"ltp":0.0,"tv":0.0,"id":13095165},{"batb":[[0,2.82,30.29],[1,1.02,2],[2,1.01,1.01]],"ltp":0.0,"tv":0.0,"id":14343845}]}]}
{"op":"mcm","clk":"1003976872","pt":1580617423748,"mc":[{"id":"1.168230755","rc":[{"batb":[[0,2.84,90.22],[1,2.82,30.29],[2,1.02,2]],"ltp":0.0,"tv":0.0,"id":14343845}]}]}
{"op":"mcm","clk":"1003982564","pt":1580617544616,"mc":[{"id":"1.168230755","rc":[{"batb":[[0,2.58,30.29],[1,2.56,100.33]],"ltp":0.0,"tv":0.0,"id":13095165}]}]}
{"op":"mcm","clk":"1003982610","pt":1580617545237,"mc":[{"id":"1.168230755","rc":[{"batb":[[0,2.64,97.32],[1,2.58,30.29]],"ltp":0.0,"tv":0.0,"id":13095165},{"batb":[[0,2.86,30.29],[1,2.84,90.22]],"ltp":0.0,"tv":0.0,"id":14343845}]}]}
{"op":"mcm","clk":"1003982637","pt":1580617545909,"mc":[{"id":"1.168230755","rc":[{"batb":[[0,2.88,88.96],[1,2.86,30.29]],"ltp":0.0,"tv":0.0,"id":14343845}]}]}
{"op":"mcm","clk":"1003988034","pt":1580617666485,"mc":[{"id":"1.168230755","rc":[{"batb":[[0,2.74,93.52],[1,2.66,30.29]],"ltp":0.0,"tv":0.0,"id":13095165},{"batb":[[0,2.9,30.29],[1,2.88,88.96]],"ltp":0.0,"tv":0.0,"id":14343845}]}]}
{"op":"mcm","clk":"1003988044","pt":1580617666742,"mc":[{"id":"1.168230755","rc":[{"batb":[[0,2.96,86.63],[1,2.9,30.29]],"ltp":0.0,"tv":0.0,"id":14343845}]}]}
{"op":"mcm","clk":"1003993113","pt":1580617787503,"mc":[{"id":"1.168230755","rc":[{"batb":[[0,2.76,30.29],[1,2.74,93.52]],"ltp":0.0,"tv":0.0,"id":13095165}]}]}
{"op":"mcm","clk":"1003993161","pt":1580617788529,"mc":[{"id":"1.168230755","rc":[{"batb":[[0,2.8,91.48],[1,2.76,30.29]],"ltp":0.0,"tv":0.0,"id":13095165},{"batb":[[0,3,85.57],[1,2.98,30.29]],"ltp":0.0,"tv":0.0,"id":14343845}]}]}
{"op":"mcm","clk":"1003999047","pt":1580617909573,"mc":[{"id":"1.168230755","rc":[{"batb":[[0,2.84,90.22],[1,2.82,30.29]],"ltp":0.0,"tv":0.0,"id":13095165}]}]}
{"op":"mcm","clk":"1003999079","pt":1580617910194,"mc":[{"id":"1.168230755","rc":[{"batb":[[0,3.05,30.29],[1,1.02,2],[2,1.01,1.01]],"ltp":0.0,"tv":0.0,"id":14343845}]}]}
{"op":"mcm","clk":"1004005359","pt":1580618031569,"mc":[{"id":"1.168230755","rc":[{"batb":[[0,2.86,119.97],[1,1.02,2],[2,1.01,1.01]],"ltp":0.0,"tv":0.0,"id":13095165},{"batb":[[0,1.02,2],[1,1.01,1.01],[2,1.01,0]],"ltp":0.0,"tv":0.0,"id":14343845}]}]}
{"op":"mcm","clk":"1004005390","pt":1580618032041,"mc":[{"id":"1.168230755","rc":[{"batb":[[0,2.72,94.34],[1,2.64,30.29],[2,1.02,2]],"ltp":0.0,"tv":0.0,"id":14343845}]}]}
{"op":"mcm","clk":"1004010893","pt":1580618152541,"mc":[{"id":"1.168230755","rc":[{"batb":[[0,2.86,89.68]],"ltp":0.0,"tv":0.0,"id":13095165}]}]}
{"op":"mcm","clk":"1004010940","pt":1580618153576,"mc":[{"id":"1.168230755","rc":[{"batb":[[0,2.88,30.28]],"ltp":0.0,"tv":0.0,"id":13095165},{"batb":[[1,1.02,2],[2,1.01,1.01]],"ltp":0.0,"tv":0.0,"id":14343845}]}]}
{"op":"mcm","clk":"1004010959","pt":1580618153988,"mc":[{"id":"1.168230755","rc":[{"batb":[[0,2.8,91.48],[1,2.74,30.29],[2,1.02,2]],"ltp":0.0,"tv":0.0,"id":14343845}]}]}
{"op":"mcm","clk":"1004016217","pt":1580618274456,"mc":[{"id":"1.168230755","rc":[{"batb":[[0,2.5,102.82]],"ltp":0.0,"tv":0.0,"id":13095165}]}]}
{"op":"mcm","clk":"1004016264","pt":1580618275640,"mc":[{"id":"1.168230755","rc":[{"batb":[[0,2.76,92.98],[1,2.52,30.29],[2,1.02,2]],"ltp":0.0,"tv":0.0,"id":13095165},{"batb":[[0,2.82,30.29],[1,2.8,91.48]],"ltp":0.0,"tv":0.0,"id":14343845}]}]}
{"op":"mcm","clk":"1004016276","pt":1580618275846,"mc":[{"id":"1.168230755","rc":[{"batb":[[0,2.84,90.22],[1,2.82,30.29]],"ltp":0.0,"tv":0.0,"id":14343845}]}]}
{"op":"mcm","clk":"1004021122","pt":1580618396501,"mc":[{"id":"1.168230755","rc":[{"batb":[[0,2.82,91.03],[1,2.78,30.29]],"ltp":0.0,"tv":0.0,"id":13095165},{"batb":[[0,2.86,30.29],[1,2.84,90.22]],"ltp":0.0,"tv":0.0,"id":14343845}]}]}
{"op":"mcm","clk":"1004021135","pt":1580618396810,"mc":[{"id":"1.168230755","rc":[{"batb":[[0,2.96,86.63],[1,2.86,30.29]],"ltp":0.0,"tv":0.0,"id":14343845}]}]}
{"op":"mcm","clk":"1004027126","pt":1580618517465,"mc":[{"id":"1.168230755","rc":[{"batb":[[1,1.02,2],[2,1.01,1.01]],"ltp":0.0,"tv":0.0,"id":13095165}]}]}
{"op":"mcm","clk":"1004027186","pt":1580618518543,"mc":[{"id":"1.168230755","rc":[{"batb":[[0,2.86,89.68],[1,2.84,30.29],[2,1.02,2]],"ltp":0.0,"tv":0.0,"id":13095165},{"batb":[[0,3,85.57],[1,2.98,30.29]],"batl":[[0,4.9,357.25]],"ltp":0.0,"tv":0.0,"id":14343845}]}]}
{"op":"mcm","clk":"1004033680","pt":1580618639193,"mc":[{"id":"1.168230755","rc":[{"batb":[[1,1.02,2],[2,1.01,1.01]],"ltp":0.0,"tv":0.0,"id":13095165}]}]}
{"op":"mcm","clk":"1004033771","pt":1580618640585,"mc":[{"id":"1.168230755","rc":[{"batb":[[0,2.88,30.28]],"ltp":0.0,"tv":0.0,"id":13095165},{"batb":[[0,3.05,30.29],[1,1.02,2],[2,1.01,1.01]],"ltp":0.0,"tv":0.0,"id":14343845}]}]}
{"op":"mcm","clk":"1004039593","pt":1580618761550,"mc":[{"id":"1.168230755","rc":[{"batb":[[0,2.62,98.04],[1,2.52,30.29],[2,1.02,2]],"ltp":0.0,"tv":0.0,"id":13095165}]}]}
{"op":"mcm","clk":"1004039655","pt":1580618762431,"mc":[{"id":"1.168230755","rc":[{"batb":[[0,2.7,94.92],[1,2.64,30.29],[2,1.02,2]],"ltp":0.0,"tv":0.0,"id":14343845}]}]}
{"op":"mcm","clk":"1004045186","pt":1580618882636,"mc":[{"id":"1.168230755","rc":[{"batb":[[0,2.64,30.29],[1,2.62,98.04]],"ltp":0.0,"tv":0.0,"id":13095165}]}]}
{"op":"mcm","clk":"1004045227","pt":1580618883526,"mc":[{"id":"1.168230755","rc":[{"batb":[[0,2.78,92.16],[1,2.64,30.29]],"ltp":0.0,"tv":0.0,"id":13095165},{"batb":[[0,2.74,93.52],[1,2.72,30.29]],"ltp":0.0,"tv":0.0,"id":14343845}]}]}
{"op":"mcm","clk":"1004050570","pt":1580619004593,"mc":[{"id":"1.168230755","rc":[{"batb":[[0,2.84,90.22],[1,2.8,30.29]],"ltp":0.0,"tv":0.0,"id":13095165}]}]}
{"op":"mcm","clk":"1004050600","pt":1580619005318,"mc":[{"id":"1.168230755","rc":[{"batb":[[0,2.86,89.68],[1,2.76,30.29]],"ltp":0.0,"tv":0.0,"id":14343845}]}]}
{"op":"mcm","clk":"1004055326","pt":1580619126454,"mc":[{"id":"1.168230755","rc":[{"batb":[[0,2.86,119.97],[1,1.02,2],[2,1.01,1.01]],"ltp":0.0,"tv":0.0,"id":13095165}]}]}
{"op":"mcm","clk":"1004055377","pt":1580619127485,"mc":[{"id":"1.168230755","rc":[{"batb":[[0,2.92,87.69],[1,2.88,30.28]],"ltp":0.0,"tv":0.0,"id":14343845}]}]}
{"op":"mcm","clk":"1004059497","pt":1580619247539,"mc":[{"id":"1.168230755","rc":[{"batb":[[0,2.86,89.68]],"ltp":0.0,"tv":0.0,"id":13095165}]}]}
{"op":"mcm","clk":"1004059530","pt":1580619248258,"mc":[{"id":"1.168230755","rc":[{"batb":[[0,2.88,30.28]],"ltp":0.0,"tv":0.0,"id":13095165}]}]}
{"op":"mcm","clk":"1004059575","pt":1580619249460,"mc":[{"id":"1.168230755","rc":[{"batb":[[0,2.96,86.63],[1,2.94,30.29]],"ltp":0.0,"tv":0.0,"id":14343845}]}]}
{"op":"mcm","clk":"1004063814","pt":1580619369602,"mc":[{"id":"1.168230755","rc":[{"batb":[[0,2.52,30.29],[1,2.4,106.91],[2,1.02,2]],"ltp":0.0,"tv":0.0,"id":13095165}]}]}
{"op":"mcm","clk":"1004063845","pt":1580619370371,"mc":[{"id":"1.168230755","rc":[{"batb":[[0,2.74,93.52],[1,2.52,30.29]],"ltp":0.0,"tv":0.0,"id":13095165},{"batb":[[0,3,85.57],[1,2.98,30.29]],"ltp":0.0,"tv":0.0,"id":14343845}]}]}
{"op":"mcm","clk":"1004068570","pt":1580619491580,"mc":[{"id":"1.168230755","rc":[{"batb":[[0,2.82,91.03],[1,2.76,30.29]],"ltp":0.0,"tv":0.0,"id":13095165},{"batb":[[1,1.02,2],[2,1.01,1.01]],"ltp":0.0,"tv":0.0,"id":14343845}]}]}
{"op":"mcm","clk":"1004068582","pt":1580619491885,"mc":[{"id":"1.168230755","rc":[{"batb":[[0,3.05,30.29]],"ltp":0.0,"tv":0.0,"id":14343845}]}]}
{"op":"mcm","clk":"1004072351","pt":1580619612649,"mc":[{"id":"1.168230755","rc":[{"batb":[[1,1.02,2],[2,1.01,1.01]],"ltp":0.0,"tv":0.0,"id":13095165}]}]}
{"op":"mcm","clk":"1004072384","pt":1580619613524,"mc":[{"id":"1.168230755","rc":[{"batb":[[0,2.86,89.68],[1,2.84,30.29],[2,1.02,2]],"ltp":0.0,"tv":0.0,"id":13095165},{"batb":[[0,2.64,30.29],[1,2.48,103.51],[2,1.02,2]],"ltp":0.0,"tv":0.0,"id":14343845}]}]}
{"op":"mcm","clk":"1004072397","pt":1580619613834,"mc":[{"id":"1.168230755","rc":[{"batb":[[0,2.68,95.61],[1,2.64,30.29]],"ltp":0.0,"tv":0.0,"id":14343845}]}]}
{"op":"mcm","clk":"1004077106","pt":1580619734300,"mc":[{"id":"1.168230755","rc":[{"batb":[[1,1.02,2],[2,1.01,1.01]],"ltp":0.0,"tv":0.0,"id":13095165}]}]}
{"op":"mcm","clk":"1004077161","pt":1580619735279,"mc":[{"id":"1.168230755","rc":[{"batb":[[0,2.88,30.28]],"ltp":0.0,"tv":0.0,"id":13095165},{"batb":[[1,1.02,2],[2,1.01,1.01]],"ltp":0.0,"tv":0.0,"id":14343845}]}]}
{"op":"mcm","clk":"1004077210","pt":1580619736411,"mc":[{"id":"1.168230755","rc":[{"batb":[[0,2.72,94.34],[1,2.7,30.28],[2,1.02,2]],"ltp":0.0,"tv":0.0,"id":14343845}]}]}
{"op":"mcm","clk":"1004082199","pt":1580619856561,"mc":[{"id":"1.168230755","rc":[{"batb":[[0,2.68,95.86]],"ltp":0.0,"tv":0.0,"id":13095165}]}]}
{"op":"mcm","clk":"1004082227","pt":1580619857234,"mc":[{"id":"1.168230755","rc":[{"batb":[[1,2.52,30.29],[2,1.02,2]],"ltp":0.0,"tv":0.0,"id":13095165},{"batb":[[1,1.02,2],[2,1.01,1.01]],"ltp":0.0,"tv":0.0,"id":14343845}]}]}
{"op":"mcm","clk":"1004082261","pt":1580619858052,"mc":[{"id":"1.168230755","rc":[{"batb":[[0,2.76,92.98],[1,2.74,30.29],[2,1.02,2]],"ltp":0.0,"tv":0.0,"id":14343845}]}]}
{"op":"mcm","clk":"1004086829","pt":1580619977599,"mc":[{"id":"1.168230755","rc":[{"batb":[[1,1.02,2],[2,1.01,1.01]],"ltp":0.0,"tv":0.0,"id":13095165}]}]}
{"op":"mcm","clk":"1004086870","pt":1580619978583,"mc":[{"id":"1.168230755","rc":[{"batb":[[0,2.84,90.22],[1,2.7,30.28],[2,1.02,2]],"ltp":0.0,"tv":0.0,"id":13095165},{"batb":[[1,1.02,2],[2,1.01,1.01]],"ltp":0.0,"tv":0.0,"id":14343845}]}]}
{"op":"mcm","clk":"1004086885","pt":1580619978993,"mc":[{"id":"1.168230755","rc":[{"batb":[[0,2.82,91.03],[1,2.78,30.29],[2,1.02,2]],"ltp":0.0,"tv":0.0,"id":14343845}]}]}
{"op":"mcm","clk":"1004091894","pt":1580620099235,"mc":[{"id":"1.168230755","rc":[{"batb":[[1,1.02,2],[2,1.01,1.01]],"ltp":0.0,"tv":0.0,"id":13095165}]}]}
{"op":"mcm","clk":"1004091956","pt":1580620100577,"mc":[{"id":"1.168230755","rc":[{"batb":[[0,2.86,119.97]],"ltp":0.0,"tv":0.0,"id":13095165},{"batb":[[0,2.84,30.29],[1,1.02,2],[2,1.01,1.01]],"ltp":0.0,"tv":0.0,"id":14343845}]}]}
{"op":"mcm","clk":"1004091965","pt":1580620100681,"mc":[{"id":"1.168230755","rc":[{"batb":[[0,2.88,88.96],[1,2.84,30.29],[2,1.02,2]],"ltp":0.0,"tv":0.0,"id":14343845}]}]}
{"op":"mcm","clk":"1004095929","pt":1580620221509,"mc":[{"id":"1.168230755","rc":[{"batb":[[0,2.88,30.28]],"ltp":0.0,"tv":0.0,"id":13095165}]}]}
{"op":"mcm","clk":"1004095953","pt":1580620222331,"mc":[{"id":"1.168230755","rc":[{"batb":[[0,2.96,86.63],[1,2.9,30.29]],"ltp":0.0,"tv":0.0,"id":14343845}]}]}
{"op":"mcm","clk":"1004100393","pt":1580620343435,"mc":[{"id":"1.168230755","rc":[{"batb":[[0,2.66,96.34],[1,2.52,30.29],[2,1.02,2]],"ltp":0.0,"tv":0.0,"id":13095165}]}]}
{"op":"mcm","clk":"1004100418","pt":1580620344165,"mc":[{"id":"1.168230755","rc":[{"batb":[[0,3,85.57],[1,2.98,30.29]],"ltp":0.0,"tv":0.0,"id":14343845}]}]}
{"op":"mcm","clk":"1004103483","pt":1580620435064,"mc":[{"id":"1.168230755","rc":[{"batb":[[0,1.02,2],[1,1.01,1.01],[2,1.01,0]],"ltp":0.0,"tv":0.0,"id":14343850}]}]}
{"op":"mcm","clk":"1004104528","pt":1580620464566,"mc":[{"id":"1.168230755","rc":[{"batb":[[0,2.68,30.29],[1,1.02,2],[2,1.01,1.01]],"ltp":0.0,"tv":0.0,"id":13095165}]}]}
{"op":"mcm","clk":"1004104559","pt":1580620465287,"mc":[{"id":"1.168230755","rc":[{"batb":[[0,2.7,94.92],[1,2.68,30.29],[2,1.02,2]],"ltp":0.0,"tv":0.0,"id":13095165},{"batb":[[0,3.05,30.29],[1,1.02,2],[2,1.01,1.01]],"ltp":0.0,"tv":0.0,"id":14343845}]}]}
{"op":"mcm","clk":"1004110218","pt":1580620586366,"mc":[{"id":"1.168230755","rc":[{"batb":[[0,2.76,92.98],[1,2.72,30.29]],"ltp":0.0,"tv":0.0,"id":13095165}]}]}
{"op":"mcm","clk":"1004110265","pt":1580620587245,"mc":[{"id":"1.168230755","rc":[{"batb":[[0,2.64,127.61]],"ltp":0.0,"tv":0.0,"id":14343845}]}]}
{"op":"mcm","clk":"1004113782","pt":1580620657839,"mc":[{"id":"1.168230755","rc":[{"batl":[[0,4.7,330.65]],"ltp":0.0,"tv":0.0,"id":13095165}]}]}
{"op":"mcm","clk":"1004116259","pt":1580620708581,"mc":[{"id":"1.168230755","rc":[{"batb":[[0,2.8,91.48],[1,2.78,30.29]],"ltp":0.0,"tv":0.0,"id":13095165},{"batb":[[0,2.76,92.98],[1,2.66,30.29],[2,1.02,2]],"ltp":0.0,"tv":0.0,"id":14343845}]}]}
{"op":"mcm","clk":"1004122800","pt":1580620829578,"mc":[{"id":"1.168230755","rc":[{"batb":[[0,2.82,30.29],[1,1.02,2],[2,1.01,1.01]],"ltp":0.0,"tv":0.0,"id":13095165}]}]}
{"op":"mcm","clk":"1004122839","pt":1580620830146,"mc":[{"id":"1.168230755","rc":[{"batb":[[0,2.84,90.22],[1,2.82,30.29],[2,1.02,2]],"ltp":0.0,"tv":0.0,"id":13095165},{"batb":[[0,2.88,88.96],[1,2.78,30.29]],"ltp":0.0,"tv":0.0,"id":14343845}]}]}
{"op":"mcm","clk":"1004129086","pt":1580620951442,"mc":[{"id":"1.168230755","rc":[{"batb":[[0,2.86,119.97],[1,1.02,2],[2,1.01,1.01]],"ltp":0.0,"tv":0.0,"id":13095165}]}]}
{"op":"mcm","clk":"1004129125","pt":1580620952115,"mc":[{"id":"1.168230755","rc":[{"batb":[[0,2.94,87.09],[1,2.9,30.29]],"ltp":0.0,"tv":0.0,"id":14343845}]}]}
{"op":"mcm","clk":"1004135644","pt":1580621073375,"mc":[{"id":"1.168230755","rc":[{"batb":[[0,2.88,30.28]],"ltp":0.0,"tv":0.0,"id":13095165}]}]}
{"op":"mcm","clk":"1004135677","pt":1580621074093,"mc":[{"id":"1.168230755","rc":[{"batb":[[0,2.98,85.9],[1,2.96,30.29]],"ltp":0.0,"tv":0.0,"id":14343845}]}]}
{"op":"mcm","clk":"1004140958","pt":1580621194362,"mc":[{"id":"1.168230755","rc":[{"batb":[[0,1.02,2],[1,1.01,1.01],[2,1.01,0]],"ltp":0.0,"tv":0.0,"id":13095165}]}]}
{"op":"mcm","clk":"1004141014","pt":1580621195447,"mc":[{"id":"1.168230755","rc":[{"batb":[[0,2.64,97.32],[1,2.52,30.29],[2,1.02,2]],"ltp":0.0,"tv":0.0,"id":13095165},{"batb":[[0,3,30.29],[1,2.98,85.9]],"ltp":0.0,"tv":0.0,"id":14343845}]}]}
{"op":"mcm","clk":"1004141030","pt":1580621195757,"mc":[{"id":"1.168230755","rc":[{"batb":[[0,3,115.86],[1,1.02,2],[2,1.01,1.01]],"ltp":0.0,"tv":0.0,"id":14343845}]}]}
{"op":"mcm","clk":"1004145440","pt":1580621316621,"mc":[{"id":"1.168230755","rc":[{"batb":[[0,2.82,91.03],[1,2.66,30.29]],"ltp":0.0,"tv":0.0,"id":13095165},{"batb":[[0,3,85.57]],"ltp":0.0,"tv":0.0,"id":14343845}]}]}
{"op":"mcm","clk":"1004145456","pt":1580621317032,"mc":[{"id":"1.168230755","rc":[{"batb":[[0,3.05,30.29]],"ltp":0.0,"tv":0.0,"id":14343845}]}]}
{"op":"mcm","clk":"1004149359","pt":1580621438590,"mc":[{"id":"1.168230755","rc":[{"batb":[[0,2.86,89.68],[1,2.84,30.29]],"ltp":0.0,"tv":0.0,"id":13095165},{"batb":[[0,2.64,30.29]],"ltp":0.0,"tv":0.0,"id":14343845}]}]}
{"op":"mcm","clk":"1004149373","pt":1580621439101,"mc":[{"id":"1.168230755","rc":[{"batb":[[0,2.88,88.96],[1,2.64,30.29],[2,1.02,2]],"ltp":0.0,"tv":0.0,"id":14343845}]}]}
{"op":"mcm","clk":"1004153907","pt":1580621559386,"mc":[{"id":"1.168230755","rc":[{"batb":[[1,1.02,2],[2,1.01,1.01]],"ltp":0.0,"tv":0.0,"id":13095165}]}]}
{"op":"mcm","clk":"1004153950","pt":1580621560478,"mc":[{"id":"1.168230755","rc":[{"batb":[[0,2.88,30.28]],"ltp":0.0,"tv":0.0,"id":13095165},{"batb":[[0,2.9,30.29],[1,2.88,88.96]],"ltp":0.0,"tv":0.0,"id":14343845}]}]}
{"op":"mcm","clk":"1004153964","pt":1580621560850,"mc":[{"id":"1.168230755","rc":[{"batb":[[0,2.96,86.63],[1,2.9,30.29]],"ltp":0.0,"tv":0.0,"id":14343845}]}]}
{"op":"mcm","clk":"1004158258","pt":1580621681621,"mc":[{"id":"1.168230755","rc":[{"batb":[[0,2.52,30.29],[1,2.4,106.91],[2,1.02,2]],"ltp":0.0,"tv":0.0,"id":13095165}]}]}
{"op":"mcm","clk":"1004158291","pt":1580621682544,"mc":[{"id":"1.168230755","rc":[{"batb":[[0,2.66,96.34],[1,2.52,30.29]],"ltp":0.0,"tv":0.0,"id":13095165},{"batb":[[0,3,85.57],[1,2.98,30.29]],"ltp":0.0,"tv":0.0,"id":14343845}]}]}
{"op":"mcm","clk":"1004162639","pt":1580621803458,"mc":[{"id":"1.168230755","rc":[{"batb":[[0,2.72,94.34],[1,2.68,30.29]],"ltp":0.0,"tv":0.0,"id":13095165},{"batb":[[0,3.05,30.29],[1,3,85.57]],"ltp":0.0,"tv":0.0,"id":14343845}]}]}
{"op":"mcm","clk":"1004162645","pt":1580621803664,"mc":[{"id":"1.168230755","rc":[{"batb":[[1,1.02,2],[2,1.01,1.01]],"ltp":0.0,"tv":0.0,"id":14343845}]}]}
{"op":"mcm","clk":"1004167616","pt":1580621924603,"mc":[{"id":"1.168230755","rc":[{"batb":[[0,2.74,30.29],[1,1.02,2],[2,1.01,1.01]],"ltp":0.0,"tv":0.0,"id":13095165}]}]}
{"op":"mcm","clk":"1004167654","pt":1580621925526,"mc":[{"id":"1.168230755","rc":[{"batb":[[0,2.78,92.16],[1,2.74,30.29],[2,1.02,2]],"ltp":0.0,"tv":0.0,"id":13095165},{"batb":[[0,2.92,87.69],[1,2.64,30.29],[2,1.02,2]],"ltp":0.0,"tv":0.0,"id":14343845}]}]}
{"op":"mcm","clk":"1004171797","pt":1580622046452,"mc":[{"id":"1.168230755","rc":[{"batb":[[0,2.82,91.03],[1,2.8,30.29]],"ltp":0.0,"tv":0.0,"id":13095165}]}]}
{"op":"mcm","clk":"1004171821","pt":1580622047022,"mc":[{"id":"1.168230755","rc":[{"batb":[[0,2.96,86.63],[1,2.94,30.29]],"ltp":0.0,"tv":0.0,"id":14343845}]}]}
{"op":"mcm","clk":"1004173773","pt":1580622118643,"mc":[{"id":"1.168230755","rc":[{"batl":[[0,4.5,388.87]],"ltp":0.0,"tv":0.0,"id":14343845}]}]}
{"op":"mcm","clk":"1004175349","pt":1580622168592,"mc":[{"id":"1.168230755","rc":[{"batb":[[0,2.86,89.68],[1,2.84,30.29]],"ltp":0.0,"tv":0.0,"id":13095165}]}]}
{"op":"mcm","clk":"1004175381","pt":1580622169313,"mc":[{"id":"1.168230755","rc":[{"batb":[[0,3,85.57],[1,2.98,30.29]],"ltp":0.0,"tv":0.0,"id":14343845}]}]}
{"op":"mcm","clk":"1004178957","pt":1580622289530,"mc":[{"id":"1.168230755","rc":[{"batb":[[1,1.02,2],[2,1.01,1.01]],"ltp":0.0,"tv":0.0,"id":13095165}]}]}
{"op":"mcm","clk":"1004178982","pt":1580622290249,"mc":[{"id":"1.168230755","rc":[{"batb":[[0,2.88,30.28]],"ltp":0.0,"tv":0.0,"id":13095165}]}]}
{"op":"mcm","clk":"1004179009","pt":1580622290919,"mc":[{"id":"1.168230755","rc":[{"batb":[[0,3.05,30.29],[1,1.02,2],[2,1.01,1.01]],"ltp":0.0,"tv":0.0,"id":14343845}]}]}
{"op":"mcm","clk":"1004183434","pt":1580622411604,"mc":[{"id":"1.168230755","rc":[{"batb":[[0,2.52,30.29],[1,2.46,104.38],[2,1.02,2]],"ltp":0.0,"tv":0.0,"id":13095165}]}]}
{"op":"mcm","clk":"1004183464","pt":1580622412524,"mc":[{"id":"1.168230755","rc":[{"batb":[[0,2.62,98.04],[1,2.52,30.29]],"ltp":0.0,"tv":0.0,"id":13095165},{"batb":[[0,2.64,30.29],[1,2.52,101.99],[2,1.02,2]],"ltp":0.0,"tv":0.0,"id":14343845}]}]}
{"op":"mcm","clk":"1004183477","pt":1580622412833,"mc":[{"id":"1.168230755","rc":[{"batb":[[0,2.84,90.22],[1,2.64,30.29]],"ltp":0.0,"tv":0.0,"id":14343845}]}]}
{"op":"mcm","clk":"1004188080","pt":1580622533546,"mc":[{"id":"1.168230755","rc":[{"batb":[[0,2.68,95.86],[1,2.64,30.29]],"ltp":0.0,"tv":0.0,"id":13095165},{"batb":[[0,2.86,30.29],[1,2.84,90.22]],"ltp":0.0,"tv":0.0,"id":14343845}]}]}
{"op":"mcm","clk":"1004188094","pt":1580622533851,"mc":[{"id":"1.168230755","rc":[{"batb":[[0,2.94,87.09],[1,2.86,30.29]],"ltp":0.0,"tv":0.0,"id":14343845}]}]}
{"op":"mcm","clk":"1004192063","pt":1580622654451,"mc":[{"id":"1.168230755","rc":[{"batb":[[1,1.02,2],[2,1.01,1.01]],"ltp":0.0,"tv":0.0,"id":13095165}]}]}
{"op":"mcm","clk":"1004192098","pt":1580622655536,"mc":[{"id":"1.168230755","rc":[{"batb":[[0,2.72,94.34],[1,2.7,30.28],[2,1.02,2]],"ltp":0.0,"tv":0.0,"id":13095165},{"batb":[[0,2.96,30.29],[1,2.94,87.09]],"ltp":0.0,"tv":0.0,"id":14343845}]}]}
{"op":"mcm","clk":"1004192112","pt":1580622655845,"mc":[{"id":"1.168230755","rc":[{"batb":[[0,2.98,85.9],[1,2.96,30.29]],"ltp":0.0,"tv":0.0,"id":14343845}]}]}
{"op":"mcm","clk":"1004195989","pt":1580622777192,"mc":[{"id":"1.168230755","rc":[{"batb":[[1,1.02,2],[2,1.01,1.01]],"ltp":0.0,"tv":0.0,"id":13095165}]}]}
{"op":"mcm","clk":"1004196015","pt":1580622778009,"mc":[{"id":"1.168230755","rc":[{"batb":[[0,2.82,91.03],[1,2.74,30.29],[2,1.02,2]],"ltp":0.0,"tv":0.0,"id":13095165}]}]}
{"op":"mcm","clk":"1004196062","pt":1580622779291,"mc":[{"id":"1.168230755","rc":[{"batb":[[0,3,115.86],[1,1.02,2],[2,1.01,1.01]],"ltp":0.0,"tv":0.0,"id":14343845}]}]}
{"op":"mcm","clk":"1004199401","pt":1580622899641,"mc":[{"id":"1.168230755","rc":[{"batb":[[0,2.84,30.29],[1,1.02,2],[2,1.01,1.01]],"ltp":0.0,"tv":0.0,"id":13095165}]}]}
{"op":"mcm","clk":"1004199423","pt":1580622900357,"mc":[{"id":"1.168230755","rc":[{"batb":[[0,2.86,89.68],[1,2.84,30.29],[2,1.02,2]],"ltp":0.0,"tv":0.0,"id":13095165},{"batb":[[0,3.05,30.29]],"ltp":0.0,"tv":0.0,"id":14343845}]}]}
{"op":"mcm","clk":"1004202828","pt":1580623020513,"mc":[{"id":"1.168230755","rc":[{"batb":[[1,1.02,2],[2,1.01,1.01]],"ltp":0.0,"tv":0.0,"id":13095165}]}]}
{"op":"mcm","clk":"1004202855","pt":1580623021589,"mc":[{"id":"1.168230755","rc":[{"batb":[[0,2.88,30.28]],"ltp":0.0,"tv":0.0,"id":13095165},{"batb":[[0,1.02,2],[1,1.01,1.01],[2,1.01,0]],"ltp":0.0,"tv":0.0,"id":14343845}]}]}
{"op":"mcm","clk":"1004202872","pt":1580623021999,"mc":[{"id":"1.168230755","rc":[{"batb":[[0,2.8,91.48],[1,2.64,30.29],[2,1.02,2]],"ltp":0.0,"tv":0.0,"id":14343845}]}]}
{"op":"mcm","clk":"1004206240","pt":1580623142452,"mc":[{"id":"1.168230755","rc":[{"batb":[[0,2.48,103.51]],"ltp":0.0,"tv":0.0,"id":13095165}]}]}
{"op":"mcm","clk":"1004206281","pt":1580623143636,"mc":[{"id":"1.168230755","rc":[{"batb":[[0,2.64,97.32],[1,2.52,30.29],[2,1.02,2]],"ltp":0.0,"tv":0.0,"id":13095165},{"batb":[[0,2.88,88.96],[1,2.82,30.29]],"ltp":0.0,"tv":0.0,"id":14343845}]}]}
{"op":"mcm","clk":"1004210189","pt":1580623264624,"mc":[{"id":"1.168230755","rc":[{"batb":[[0,2.68,95.86],[1,2.66,30.29]],"ltp":0.0,"tv":0.0,"id":13095165},{"batb":[[1,1.02,2],[2,1.01,1.01]],"ltp":0.0,"tv":0.0,"id":14343845}]}]}
{"op":"mcm","clk":"1004210199","pt":1580623265030,"mc":[{"id":"1.168230755","rc":[{"batb":[[0,2.94,87.09],[1,2.9,30.29],[2,1.02,2]],"ltp":0.0,"tv":0.0,"id":14343845}]}]}
{"op":"mcm","clk":"1004214281","pt":1580623385509,"mc":[{"id":"1.168230755","rc":[{"batb":[[1,1.02,2],[2,1.01,1.01]],"ltp":0.0,"tv":0.0,"id":13095165}]}]}
{"op":"mcm","clk":"1004214327","pt":1580623386633,"mc":[{"id":"1.168230755","rc":[{"batb":[[0,2.78,92.16],[1,2.7,30.28],[2,1.02,2]],"ltp":0.0,"tv":0.0,"id":13095165},{"batb":[[0,2.96,30.29],[1,2.94,87.09]],"ltp":0.0,"tv":0.0,"id":14343845}]}]}
{"op":"mcm","clk":"1004214340","pt":1580623386894,"mc":[{"id":"1.168230755","rc":[{"batb":[[0,2.98,85.9],[1,2.96,30.29]],"ltp":0.0,"tv":0.0,"id":14343845}]}]}
{"op":"mcm","clk":"1004218382","pt":1580623507235,"mc":[{"id":"1.168230755","rc":[{"batb":[[1,1.02,2],[2,1.01,1.01]],"ltp":0.0,"tv":0.0,"id":13095165}]}]}
{"op":"mcm","clk":"1004218427","pt":1580623508629,"mc":[{"id":"1.168230755","rc":[{"batb":[[0,2.84,90.22],[1,2.8,30.29],[2,1.02,2]],"ltp":0.0,"tv":0.0,"id":13095165},{"batb":[[0,3,30.29],[1,1.02,2],[2,1.01,1.01]],"ltp":0.0,"tv":0.0,"id":14343845}]}]}
{"op":"mcm","clk":"1004218431","pt":1580623508733,"mc":[{"id":"1.168230755","rc":[{"batb":[[0,3,115.86]],"ltp":0.0,"tv":0.0,"id":14343845}]}]}
{"op":"mcm","clk":"1004222037","pt":1580623629604,"mc":[{"id":"1.168230755","rc":[{"batb":[[0,2.86,30.29],[1,2.84,90.22]],"ltp":0.0,"tv":0.0,"id":13095165}]}]}
{"op":"mcm","clk":"1004222067","pt":1580623630478,"mc":[{"id":"1.168230755","rc":[{"batb":[[0,2.86,119.97],[1,1.02,2],[2,1.01,1.01]],"ltp":0.0,"tv":0.0,"id":13095165},{"batb":[[0,3.05,30.29]],"ltp":0.0,"tv":0.0,"id":14343845}]}]}
{"op":"mcm","clk":"1004225092","pt":1580623750636,"mc":[{"id":"1.168230755","rc":[{"batb":[[0,2.86,89.68]],"ltp":0.0,"tv":0.0,"id":13095165}]}]}
{"op":"mcm","clk":"1004225109","pt":1580623751350,"mc":[{"id":"1.168230755","rc":[{"batb":[[0,2.88,30.28]],"ltp":0.0,"tv":0.0,"id":13095165}]}]}
{"op":"mcm","clk":"1004225124","pt":1580623751966,"mc":[{"id":"1.168230755","rc":[{"batb":[[0,2.76,92.98],[1,2.64,30.29],[2,1.02,2]],"ltp":0.0,"tv":0.0,"id":14343845}]}]}
{"op":"mcm","clk":"1004228405","pt":1580623872536,"mc":[{"id":"1.168230755","rc":[{"batb":[[0,2.42,106.13]],"ltp":0.0,"tv":0.0,"id":13095165}]}]}
{"op":"mcm","clk":"1004228441","pt":1580623873557,"mc":[{"id":"1.168230755","rc":[{"batb":[[0,2.64,97.32],[1,2.52,30.29],[2,1.02,2]],"ltp":0.0,"tv":0.0,"id":13095165},{"batb":[[0,2.78,30.29],[1,1.02,2],[2,1.01,1.01]],"ltp":0.0,"tv":0.0,"id":14343845}]}]}
{"op":"mcm","clk":"1004228446","pt":1580623873659,"mc":[{"id":"1.168230755","rc":[{"batb":[[0,2.8,91.48],[1,2.78,30.29],[2,1.02,2]],"ltp":0.0,"tv":0.0,"id":14343845}]}]}
{"op":"mcm","clk":"1004232490","pt":1580623994647,"mc":[{"id":"1.168230755","rc":[{"batb":[[0,2.8,91.48],[1,2.66,30.29]],"ltp":0.0,"tv":0.0,"id":13095165},{"batb":[[0,2.82,30.29],[1,2.8,91.48]],"ltp":0.0,"tv":0.0,"id":14343845}]}]}
{"op":"mcm","clk":"1004232500","pt":1580623994962,"mc":[{"id":"1.168230755","rc":[{"batb":[[0,2.94,87.09],[1,2.82,30.29]],"ltp":0.0,"tv":0.0,"id":14343845}]}]}
{"op":"mcm","clk":"1004233721","pt":1580624035477,"mc":[{"id":"1.168230755","rc":[{"batb":[[0,3.8,67.23],[1,1.02,2],[2,1.01,1.01]],"batl":[[0,8.2,306.88]],"ltp":0.0,"tv":0.0,"id":14343850}]}]}
{"op":"mcm","clk":"1004236166","pt":1580624115556,"mc":[{"id":"1.168230755","rc":[{"batb":[[1,1.02,2],[2,1.01,1.01]],"ltp":0.0,"tv":0.0,"id":13095165}]}]}
{"op":"mcm","clk":"1004236227","pt":1580624116637,"mc":[{"id":"1.168230755","rc":[{"batb":[[0,2.84,90.22],[1,2.82,30.29],[2,1.02,2]],"ltp":0.0,"tv":0.0,"id":13095165},{"batb":[[0,2.98,85.9],[1,2.96,30.29]],"ltp":0.0,"tv":0.0,"id":14343845}]}]}
{"op":"mcm","clk":"1004239850","pt":1580624237556,"mc":[{"id":"1.168230755","rc":[{"batb":[[0,2.86,30.29],[1,1.02,2],[2,1.01,1.01]],"ltp":0.0,"tv":0.0,"id":13095165}]}]}
{"op":"mcm","clk":"1004239865","pt":1580624238335,"mc":[{"id":"1.168230755","rc":[{"batb":[[0,2.86,119.97]],"ltp":0.0,"tv":0.0,"id":13095165},{"batb":[[0,3,115.86],[1,1.02,2],[2,1.01,1.01]],"ltp":0.0,"tv":0.0,"id":14343845}]}]}
{"op":"mcm","clk":"1004242208","pt":1580624308335,"mc":[{"id":"1.168230755","rc":[{"batl":[[0,4.8,323.77]],"ltp":0.0,"tv":0.0,"id":13095165}]}]}
{"op":"mcm","clk":"1004243866","pt":1580624359022,"mc":[{"id":"1.168230755","rc":[{"batb":[[0,2.86,89.68]],"ltp":0.0,"tv":0.0,"id":13095165}]}]}
{"op":"mcm","clk":"1004243905","pt":1580624360620,"mc":[{"id":"1.168230755","rc":[{"batb":[[0,2.88,30.28]],"ltp":0.0,"tv":0.0,"id":13095165},{"batb":[[0,3.05,30.29],[1,3,85.57],[2,1.02,2]],"ltp":0.0,"tv":0.0,"id":14343845}]}]}
{"op":"mcm","clk":"1004243915","pt":1580624360822,"mc":[{"id":"1.168230755","rc":[{"batb":[[1,1.02,2],[2,1.01,1.01]],"ltp":0.0,"tv":0.0,"id":14343845}]}]}
{"op":"mcm","clk":"1004248349","pt":1580624480638,"mc":[{"id":"1.168230755","rc":[{"batb":[[0,1.02,2],[1,1.01,1.01],[2,1.01,0]],"ltp":0.0,"tv":0.0,"id":13095165}]}]}
{"op":"mcm","clk":"1004248382","pt":1580624481406,"mc":[{"id":"1.168230755","rc":[{"batb":[[0,2.68,95.86],[1,2.52,30.29],[2,1.02,2]],"ltp":0.0,"tv":0.0,"id":13095165}]}]}
{"op":"mcm","clk":"1004248408","pt":1580624482020,"mc":[{"id":"1.168230755","rc":[{"batb":[[0,2.74,93.52],[1,2.64,30.29],[2,1.02,2]],"ltp":0.0,"tv":0.0,"id":14343845}]}]}
{"op":"mcm","clk":"1004252090","pt":1580624602303,"mc":[{"id":"1.168230755","rc":[{"batb":[[1,1.02,2],[2,1.01,1.01]],"ltp":0.0,"tv":0.0,"id":13095165}]}]}
{"op":"mcm","clk":"1004252145","pt":1580624603639,"mc":[{"id":"1.168230755","rc":[{"batb":[[0,2.72,94.34],[1,2.7,30.28],[2,1.02,2]],"ltp":0.0,"tv":0.0,"id":13095165},{"batb":[[0,2.76,30.29],[1,1.02,2],[2,1.01,1.01]],"ltp":0.0,"tv":0.0,"id":14343845}]}]}
{"op":"mcm","clk":"1004252153","pt":1580624603746,"mc":[{"id":"1.168230755","rc":[{"batb":[[0,2.86,89.68],[1,2.76,30.29],[2,1.02,2]],"ltp":0.0,"tv":0.0,"id":14343845}]}]}
{"op":"mcm","clk":"1004255688","pt":1580624725451,"mc":[{"id":"1.168230755","rc":[{"batb":[[0,2.74,30.29],[1,2.72,94.34]],"ltp":0.0,"tv":0.0,"id":13095165}]}]}
{"op":"mcm","clk":"1004255714","pt":1580624726632,"mc":[{"id":"1.168230755","rc":[{"batb":[[0,2.8,91.48],[1,2.74,30.29]],"ltp":0.0,"tv":0.0,"id":13095165},{"batb":[[0,2.88,30.28],[1,1.02,2],[2,1.01,1.01]],"ltp":0.0,"tv":0.0,"id":14343845}]}]}
{"op":"mcm","clk":"1004255719","pt":1580624726734,"mc":[{"id":"1.168230755","rc":[{"batb":[[0,2.94,87.09],[1,2.88,30.28],[2,1.02,2]],"ltp":0.0,"tv":0.0,"id":14343845}]}]}
{"op":"mcm","clk":"1004259549","pt":1580624846636,"mc":[{"id":"1.168230755","rc":[{"batb":[[1,1.02,2],[2,1.01,1.01]],"ltp":0.0,"tv":0.0,"id":13095165}]}]}
{"op":"mcm","clk":"1004259583","pt":1580624847255,"mc":[{"id":"1.168230755","rc":[{"batb":[[0,2.84,90.22],[1,2.82,30.29],[2,1.02,2]],"ltp":0.0,"tv":0.0,"id":13095165},{"batb":[[1,1.02,2],[2,1.01,1.01]],"ltp":0.0,"tv":0.0,"id":14343845}]}]}
{"op":"mcm","clk":"1004259616","pt":1580624848022,"mc":[{"id":"1.168230755","rc":[{"batb":[[0,2.98,85.9],[1,2.96,30.29],[2,1.02,2]],"ltp":0.0,"tv":0.0,"id":14343845}]}]}
{"op":"mcm","clk":"1004262832","pt":1580624968607,"mc":[{"id":"1.168230755","rc":[{"batb":[[0,2.86,30.29],[1,1.02,2],[2,1.01,1.01]],"ltp":0.0,"tv":0.0,"id":13095165}]}]}
{"op":"mcm","clk":"1004262861","pt":1580624969432,"mc":[{"id":"1.168230755","rc":[{"batb":[[0,2.86,119.97]],"ltp":0.0,"tv":0.0,"id":13095165},{"batb":[[0,3,115.86],[1,1.02,2],[2,1.01,1.01]],"ltp":0.0,"tv":0.0,"id":14343845}]}]}
{"op":"mcm","clk":"1004266359","pt":1580625090625,"mc":[{"id":"1.168230755","rc":[{"batb":[[0,2.86,89.68]],"ltp":0.0,"tv":0.0,"id":13095165}]}]}
{"op":"mcm","clk":"1004266389","pt":1580625091342,"mc":[{"id":"1.168230755","rc":[{"batb":[[0,2.88,30.28]],"ltp":0.0,"tv":0.0,"id":13095165}]}]}
{"op":"mcm","clk":"1004266411","pt":1580625092059,"mc":[{"id":"1.168230755","rc":[{"batb":[[0,3.05,30.29]],"ltp":0.0,"tv":0.0,"id":14343845}]}]}
{"op":"mcm","clk":"1004269870","pt":1580625213335,"mc":[{"id":"1.168230755","rc":[{"batb":[[0,2.56,100.33],[1,2.52,30.29],[2,1.02,2]],"ltp":0.0,"tv":0.0,"id":13095165}]}]}
{"op":"mcm","clk":"1004269906","pt":1580625214152,"mc":[{"id":"1.168230755","rc":[{"batb":[[0,2.8,91.48],[1,2.64,30.29],[2,1.02,2]],"ltp":0.0,"tv":0.0,"id":14343845}]}]}
{"op":"mcm","clk":"1004273858","pt":1580625334623,"mc":[{"id":"1.168230755","rc":[{"batb":[[0,2.58,30.29],[1,1.02,2],[2,1.01,1.01]],"ltp":0.0,"tv":0.0,"id":13095165}]}]}
{"op":"mcm","clk":"1004273894","pt":1580625335497,"mc":[{"id":"1.168230755","rc":[{"batb":[[0,2.66,96.34],[1,2.58,30.29],[2,1.02,2]],"ltp":0.0,"tv":0.0,"id":13095165},{"batb":[[0,2.86,89.68],[1,2.82,30.29]],"ltp":0.0,"tv":0.0,"id":14343845}]}]}
{"op":"mcm","clk":"1004277452","pt":1580625456432,"mc":[{"id":"1.168230755","rc":[{"batb":[[0,2.72,94.34],[1,2.68,30.29]],"ltp":0.0,"tv":0.0,"id":13095165}]}]}
{"op":"mcm","clk":"1004277484","pt":1580625457613,"mc":[{"id":"1.168230755","rc":[{"batb":[[0,2.9,88.36],[1,2.88,30.28]],"ltp":0.0,"tv":0.0,"id":14343845}]}]}
{"op":"mcm","clk":"1004281692","pt":1580625578467,"mc":[{"id":"1.168230755","rc":[{"batb":[[0,2.76,92.98],[1,2.74,30.29]],"ltp":0.0,"tv":0.0,"id":13095165},{"batb":[[1,1.02,2],[2,1.01,1.01]],"ltp":0.0,"tv":0.0,"id":14343845}]}]}
{"op":"mcm","clk":"1004281731","pt":1580625579243,"mc":[{"id":"1.168230755","rc":[{"batb":[[0,2.96,86.63],[1,2.92,30.29],[2,1.02,2]],"ltp":0.0,"tv":0.0,"id":14343845}]}]}
{"op":"mcm","clk":"1004286445","pt":1580625699630,"mc":[{"id":"1.168230755","rc":[{"batb":[[0,2.78,30.29],[1,1.02,2],[2,1.01,1.01]],"ltp":0.0,"tv":0.0,"id":13095165}]}]}
{"op":"mcm","clk":"1004286470","pt":1580625700448,"mc":[{"id":"1.168230755","rc":[{"batb":[[0,2.8,91.48],[1,2.78,30.29],[2,1.02,2]],"ltp":0.0,"tv":0.0,"id":13095165},{"batb":[[0,3,85.57],[1,2.98,30.29]],"ltp":0.0,"tv":0.0,"id":14343845}]}]}
{"op":"mcm","clk":"1004289563","pt":1580625821619,"mc":[{"id":"1.168230755","rc":[{"batb":[[1,1.02,2],[2,1.01,1.01]],"ltp":0.0,"tv":0.0,"id":13095165}]}]}
{"op":"mcm","clk":"1004289574","pt":1580625822594,"mc":[{"id":"1.168230755","rc":[{"batb":[[0,2.84,90.22],[1,2.82,30.29],[2,1.02,2]],"ltp":0.0,"tv":0.0,"id":13095165},{"batb":[[0,3.05,30.29],[1,1.02,2],[2,1.01,1.01]],"batl":[[0,4.5,388.87]],"ltp":0.0,"tv":0.0,"id":14343845}]}]}
{"op":"mcm","clk":"1004291794","pt":1580625943577,"mc":[{"id":"1.168230755","rc":[{"batb":[[0,2.86,119.97],[1,1.02,2],[2,1.01,1.01]],"ltp":0.0,"tv":0.0,"id":13095165},{"batb":[[0,2.64,30.29],[1,2.48,103.51],[2,1.02,2]],"ltp":0.0,"tv":0.0,"id":14343845}]}]}
{"op":"mcm","clk":"1004291804","pt":1580625943886,"mc":[{"id":"1.168230755","rc":[{"batb":[[0,2.66,96.34],[1,2.64,30.29]],"ltp":0.0,"tv":0.0,"id":14343845}]}]}
{"op":"mcm","clk":"1004294957","pt":1580626064386,"mc":[{"id":"1.168230755","rc":[{"batb":[[0,2.86,89.68]],"ltp":0.0,"tv":0.0,"id":13095165}]}]}
{"op":"mcm","clk":"1004294992","pt":1580626065615,"mc":[{"id":"1.168230755","rc":[{"batb":[[0,2.88,30.28]],"ltp":0.0,"tv":0.0,"id":13095165},{"batb":[[0,2.68,30.29],[1,2.66,96.34]],"ltp":0.0,"tv":0.0,"id":14343845}]}]}
{"op":"mcm","clk":"1004295002","pt":1580626065923,"mc":[{"id":"1.168230755","rc":[{"batb":[[0,2.8,91.48],[1,2.68,30.29]],"ltp":0.0,"tv":0.0,"id":14343845}]}]}
{"op":"mcm","clk":"1004298076","pt":1580626186605,"mc":[{"id":"1.168230755","rc":[{"batb":[[0,2.52,30.29],[1,2.48,103.51],[2,1.02,2]],"ltp":0.0,"tv":0.0,"id":13095165}]}]}
{"op":"mcm","clk":"1004298118","pt":1580626187477,"mc":[{"id":"1.168230755","rc":[{"batb":[[0,2.66,96.34],[1,2.52,30.29]],"ltp":0.0,"tv":0.0,"id":13095165},{"batb":[[0,2.88,88.96],[1,2.82,30.29]],"ltp":0.0,"tv":0.0,"id":14343845}]}]}
{"op":"mcm","clk":"1004301986","pt":1580626308588,"mc":[{"id":"1.168230755","rc":[{"batb":[[0,2.76,92.98],[1,2.68,30.29]],"ltp":0.0,"tv":0.0,"id":13095165},{"batb":[[0,2.9,30.29],[1,2.88,88.96]],"ltp":0.0,"tv":0.0,"id":14343845}]}]}
{"op":"mcm","clk":"1004301999","pt":1580626308997,"mc":[{"id":"1.168230755","rc":[{"batb":[[0,2.92,87.69],[1,2.9,30.29]],"ltp":0.0,"tv":0.0,"id":14343845}]}]}
{"op":"mcm","clk":"1004306484","pt":1580626429590,"mc":[{"id":"1.168230755","rc":[{"batb":[[0,2.78,30.29],[1,2.76,92.98]],"ltp":0.0,"tv":0.0,"id":13095165}]}]}
{"op":"mcm","clk":"1004306495","pt":1580626429847,"mc":[{"id":"1.168230755","rc":[{"batb":[[0,2.8,91.48],[1,2.78,30.29]],"ltp":0.0,"tv":0.0,"id":13095165}]}]}
{"op":"mcm","clk":"1004306567","pt":1580626432274,"mc":[{"id":"1.168230755","rc":[{"batb":[[0,2.96,86.63],[1,2.94,30.29]],"ltp":0.0,"tv":0.0,"id":14343845}]}]}
{"op":"mcm","clk":"1004310874","pt":1580626552525,"mc":[{"id":"1.168230755","rc":[{"batb":[[0,2.84,90.22],[1,2.82,30.29]],"ltp":0.0,"tv":0.0,"id":13095165},{"batb":[[0,2.98,30.29],[1,2.96,86.63]],"ltp":0.0,"tv":0.0,"id":14343845}]}]}
{"op":"mcm","clk":"1004310888","pt":1580626552832,"mc":[{"id":"1.168230755","rc":[{"batb":[[0,3,85.57],[1,2.98,30.29]],"ltp":0.0,"tv":0.0,"id":14343845}]}]}
{"op":"mcm","clk":"1004315177","pt":1580626673552,"mc":[{"id":"1.168230755","rc":[{"batb":[[0,2.86,119.97],[1,1.02,2],[2,1.01,1.01]],"ltp":0.0,"tv":0.0,"id":13095165},{"batb":[[0,3.05,30.29],[1,3,85.57]],"ltp":0.0,"tv":0.0,"id":14343845}]}]}
{"op":"mcm","clk":"1004315183","pt":1580626673759,"mc":[{"id":"1.168230755","rc":[{"batb":[[1,1.02,2],[2,1.01,1.01]],"ltp":0.0,"tv":0.0,"id":14343845}]}]}
{"op":"mcm","clk":"1004318490","pt":1580626794445,"mc":[{"id":"1.168230755","rc":[{"batb":[[0,2.86,89.68]],"ltp":0.0,"tv":0.0,"id":13095165}]}]}
{"op":"mcm","clk":"1004318535","pt":1580626795574,"mc":[{"id":"1.168230755","rc":[{"batb":[[0,2.88,30.28]],"ltp":0.0,"tv":0.0,"id":13095165},{"batb":[[0,2.64,30.29]],"ltp":0.0,"tv":0.0,"id":14343845}]}]}
{"op":"mcm","clk":"1004318555","pt":1580626796039,"mc":[{"id":"1.168230755","rc":[{"batb":[[0,2.74,93.52],[1,2.64,30.29],[2,1.02,2]],"ltp":0.0,"tv":0.0,"id":14343845}]}]}
{"op":"mcm","clk":"1004322639","pt":1580626916643,"mc":[{"id":"1.168230755","rc":[{"batb":[[0,2.52,30.29],[1,2.42,106.13],[2,1.02,2]],"ltp":0.0,"tv":0.0,"id":13095165}]}]}
{"op":"mcm","clk":"1004322665","pt":1580626917564,"mc":[{"id":"1.168230755","rc":[{"batb":[[0,2.6,98.59],[1,2.52,30.29]],"ltp":0.0,"tv":0.0,"id":13095165},{"batb":[[0,2.84,90.22],[1,2.76,30.29]],"ltp":0.0,"tv":0.0,"id":14343845}]}]}
{"op":"mcm","clk":"1004325780","pt":1580627038499,"mc":[{"id":"1.168230755","rc":[{"batb":[[0,2.68,95.86],[1,2.62,30.29]],"ltp":0.0,"tv":0.0,"id":13095165},{"batb":[[0,2.86,30.29],[1,2.84,90.22]],"ltp":0.0,"tv":0.0,"id":14343845}]}]}
{"op":"mcm","clk":"1004325789","pt":1580627038806,"mc":[{"id":"1.168230755","rc":[{"batb":[[0,2.92,87.69],[1,2.86,30.29]],"ltp":0.0,"tv":0.0,"id":14343845}]}]}
{"op":"mcm","clk":"1004329785","pt":1580627159436,"mc":[{"id":"1.168230755","rc":[{"batb":[[1,1.02,2],[2,1.01,1.01]],"ltp":0.0,"tv":0.0,"id":13095165}]}]}
{"op":"mcm","clk":"1004329825","pt":1580627160564,"mc":[{"id":"1.168230755","rc":[{"batb":[[0,2.76,92.98],[1,2.7,30.28],[2,1.02,2]],"ltp":0.0,"tv":0.0,"id":13095165},{"batb":[[0,2.94,30.29],[1,2.92,87.69]],"ltp":0.0,"tv":0.0,"id":14343845}]}]}
{"op":"mcm","clk":"1004329835","pt":1580627160873,"mc":[{"id":"1.168230755","rc":[{"batb":[[0,2.96,86.63],[1,2.94,30.29]],"ltp":0.0,"tv":0.0,"id":14343845}]}]}
{"op":"mcm","clk":"1004334152","pt":1580627281226,"mc":[{"id":"1.168230755","rc":[{"batb":[[1,1.02,2],[2,1.01,1.01]],"ltp":0.0,"tv":0.0,"id":13095165}]}]}
{"op":"mcm","clk":"1004334196","pt":1580627282624,"mc":[{"id":"1.168230755","rc":[{"batb":[[0,2.8,91.48],[1,2.78,30.29],[2,1.02,2]],"ltp":0.0,"tv":0.0,"id":13095165}]}]}
{"op":"mcm","clk":"1004334223","pt":1580627283243,"mc":[{"id":"1.168230755","rc":[{"batb":[[0,3,85.57],[1,2.98,30.29]],"ltp":0.0,"tv":0.0,"id":14343845}]}]}
{"op":"mcm","clk":"1004338442","pt":1580627403552,"mc":[{"id":"1.168230755","rc":[{"batb":[[0,2.84,90.22],[1,2.82,30.29]],"ltp":0.0,"tv":0.0,"id":13095165},{"batb":[[0,3.05,30.29],[1,3,85.57]],"ltp":0.0,"tv":0.0,"id":14343845}]}]}
{"op":"mcm","clk":"1004338450","pt":1580627403655,"mc":[{"id":"1.168230755","rc":[{"batb":[[1,1.02,2],[2,1.01,1.01]],"ltp":0.0,"tv":0.0,"id":14343845}]}]}
{"op":"mcm","clk":"1004343189","pt":1580627524506,"mc":[{"id":"1.168230755","rc":[{"batb":[[1,1.02,2],[2,1.01,1.01]],"ltp":0.0,"tv":0.0,"id":13095165}]}]}
{"op":"mcm","clk":"1004343225","pt":1580627525641,"mc":[{"id":"1.168230755","rc":[{"batb":[[0,2.7,30.28],[1,2.68,95.61],[2,1.02,2]],"ltp":0.0,"tv":0.0,"id":14343845}]}]}
{"op":"mcm","clk":"1004343234","pt":1580627525846,"mc":[{"id":"1.168230755","rc":[{"batb":[[0,2.72,94.34],[1,2.7,30.28]],"ltp":0.0,"tv":0.0,"id":14343845}]}]}
{"op":"mcm","clk":"1004347039","pt":1580627635528,"mc":[{"id":"1.168230755","rc":[{"batb":[[0,1.02,2],[1,1.01,1.01],[2,1.01,0]],"ltp":0.0,"tv":0.0,"id":14343850}]}]}
{"op":"mcm","clk":"1004347066","pt":1580627636040,"mc":[{"id":"1.168230755","rc":[{"batb":[[0,3.45,74.21],[1,1.02,2],[2,1.01,1.01]],"batl":[[0,6.6,381.33]],"ltp":0.0,"tv":0.0,"id":14343850}]}]}
{"op":"mcm","clk":"1004347560","pt":1580627646168,"mc":[{"id":"1.168230755","rc":[{"batb":[[1,1.02,2],[2,1.01,1.01]],"ltp":0.0,"tv":0.0,"id":14343845}]}]}
{"op":"mcm","clk":"1004347597","pt":1580627646987,"mc":[{"id":"1.168230755","rc":[{"batb":[[0,2.9,88.36],[1,2.74,30.29],[2,1.02,2]],"ltp":0.0,"tv":0.0,"id":14343845}]}]}
{"op":"mcm","clk":"1004352519","pt":1580627768412,"mc":[{"id":"1.168230755","rc":[{"batb":[[0,2.96,86.63],[1,2.92,30.29]],"ltp":0.0,"tv":0.0,"id":14343845}]}]}
{"op":"mcm","clk":"1004357045","pt":1580627889600,"mc":[{"id":"1.168230755","rc":[{"batb":[[1,1.02,2],[2,1.01,1.01]],"ltp":0.0,"tv":0.0,"id":14343845}]}]}
{"op":"mcm","clk":"1004357073","pt":1580627890113,"mc":[{"id":"1.168230755","rc":[{"batb":[[0,3,85.57],[1,2.98,30.29],[2,1.02,2]],"ltp":0.0,"tv":0.0,"id":14343845}]}]}
{"op":"mcm","clk":"1004362474","pt":1580628011552,"mc":[{"id":"1.168230755","rc":[{"batb":[[0,3.05,30.29],[1,1.02,2],[2,1.01,1.01]],"ltp":0.0,"tv":0.0,"id":14343845}]}]}
{"op":"mcm","clk":"1004368377","pt":1580628133533,"mc":[{"id":"1.168230755","rc":[{"batb":[[0,1.02,2],[1,1.01,1.01],[2,1.01,0]],"ltp":0.0,"tv":0.0,"id":14343845}]}]}
{"op":"mcm","clk":"1004368425","pt":1580628134313,"mc":[{"id":"1.168230755","rc":[{"batb":[[0,2.8,91.48],[1,2.7,30.28],[2,1.02,2]],"ltp":0.0,"tv":0.0,"id":14343845}]}]}
{"op":"mcm","clk":"1004373279","pt":1580628254516,"mc":[{"id":"1.168230755","rc":[{"batb":[[1,1.02,2],[2,1.01,1.01]],"ltp":0.0,"tv":0.0,"id":14343845}]}]}
{"op":"mcm","clk":"1004373307","pt":1580628255285,"mc":[{"id":"1.168230755","rc":[{"batb":[[0,2.92,87.69],[1,2.82,30.29],[2,1.02,2]],"ltp":0.0,"tv":0.0,"id":14343845}]}]}
{"op":"mcm","clk":"1004377818","pt":1580628376573,"mc":[{"id":"1.168230755","rc":[{"batb":[[0,2.98,85.9],[1,2.94,30.29]],"ltp":0.0,"tv":0.0,"id":14343845}]}]}
{"op":"mcm","clk":"1004382731","pt":1580628498219,"mc":[{"id":"1.168230755","rc":[{"batb":[[0,3,115.86],[1,1.02,2],[2,1.01,1.01]],"ltp":0.0,"tv":0.0,"id":14343845}]}]}
{"op":"mcm","clk":"1004387400","pt":1580628619603,"mc":[{"id":"1.168230755","rc":[{"batb":[[0,3,85.57]],"ltp":0.0,"tv":0.0,"id":14343845}]}]}
{"op":"mcm","clk":"1004387414","pt":1580628619912,"mc":[{"id":"1.168230755","rc":[{"batb":[[0,3.05,30.29]],"ltp":0.0,"tv":0.0,"id":14343845}]}]}
{"op":"mcm","clk":"1004392482","pt":1580628741524,"mc":[{"id":"1.168230755","rc":[{"batb":[[0,2.54,101.12]],"ltp":0.0,"tv":0.0,"id":14343845}]}]}
{"op":"mcm","clk":"1004392506","pt":1580628741988,"mc":[{"id":"1.168230755","rc":[{"batb":[[0,2.76,92.98],[1,2.7,30.28],[2,1.02,2]],"ltp":0.0,"tv":0.0,"id":14343845}]}]}
{"op":"mcm","clk":"1004397375","pt":1580628863558,"mc":[{"id":"1.168230755","rc":[{"batb":[[1,1.02,2],[2,1.01,1.01]],"ltp":0.0,"tv":0.0,"id":14343845}]}]}
{"op":"mcm","clk":"1004397412","pt":1580628864403,"mc":[{"id":"1.168230755","rc":[{"batb":[[0,2.94,87.09],[1,2.78,30.29],[2,1.02,2]],"ltp":0.0,"tv":0.0,"id":14343845}]}]}
{"op":"mcm","clk":"1004401701","pt":1580628985033,"mc":[{"id":"1.168230755","rc":[{"batb":[[0,2.98,85.9],[1,2.96,30.29]],"ltp":0.0,"tv":0.0,"id":14343845}]}]}
{"op":"mcm","clk":"1004406543","pt":1580629106643,"mc":[{"id":"1.168230755","rc":[{"batb":[[0,3,115.86],[1,1.02,2],[2,1.01,1.01]],"ltp":0.0,"tv":0.0,"id":14343845}]}]}
{"op":"mcm","clk":"1004411596","pt":1580629228104,"mc":[{"id":"1.168230755","rc":[{"batb":[[0,3.05,30.29]],"ltp":0.0,"tv":0.0,"id":14343845}]}]}
{"op":"mcm","clk":"1004416609","pt":1580629349566,"mc":[{"id":"1.168230755","rc":[{"batb":[[0,1.02,2],[1,1.01,1.01],[2,1.01,0]],"ltp":0.0,"tv":0.0,"id":14343845}]}]}
{"op":"mcm","clk":"1004416650","pt":1580629350381,"mc":[{"id":"1.168230755","rc":[{"batb":[[0,2.8,91.48],[1,2.7,30.28],[2,1.02,2]],"ltp":0.0,"tv":0.0,"id":14343845}]}]}
{"op":"mcm","clk":"1004421423","pt":1580629471278,"mc":[{"id":"1.168230755","rc":[{"batb":[[1,1.02,2],[2,1.01,1.01]],"ltp":0.0,"tv":0.0,"id":14343845}]}]}
{"op":"mcm","clk":"1004421452","pt":1580629472098,"mc":[{"id":"1.168230755","rc":[{"batb":[[0,2.98,85.9],[1,2.82,30.29],[2,1.02,2]],"batl":[[0,4.5,388.87]],"ltp":0.0,"tv":0.0,"id":14343845}]}]}
{"op":"mcm","clk":"1004426644","pt":1580629593229,"mc":[{"id":"1.168230755","rc":[{"batb":[[0,3,115.86],[1,1.02,2],[2,1.01,1.01]],"ltp":0.0,"tv":0.0,"id":14343845}]}]}
{"op":"mcm","clk":"1004432120","pt":1580629714641,"mc":[{"id":"1.168230755","rc":[{"batb":[[0,3,85.57]],"ltp":0.0,"tv":0.0,"id":14343845}]}]}
{"op":"mcm","clk":"1004432135","pt":1580629714949,"mc":[{"id":"1.168230755","rc":[{"batb":[[0,3.05,30.29]],"ltp":0.0,"tv":0.0,"id":14343845}]}]}
{"op":"mcm","clk":"1004437871","pt":1580629836565,"mc":[{"id":"1.168230755","rc":[{"batb":[[0,2.52,101.99]],"ltp":0.0,"tv":0.0,"id":14343845}]}]}
{"op":"mcm","clk":"1004437898","pt":1580629837180,"mc":[{"id":"1.168230755","rc":[{"batb":[[0,2.82,91.03],[1,2.7,30.28],[2,1.02,2]],"ltp":0.0,"tv":0.0,"id":14343845}]}]}
{"op":"mcm","clk":"1004443105","pt":1580629959503,"mc":[{"id":"1.168230755","rc":[{"batb":[[0,2.84,30.29],[1,2.82,91.03]],"ltp":0.0,"tv":0.0,"id":14343845}]}]}
{"op":"mcm","clk":"1004443120","pt":1580629960027,"mc":[{"id":"1.168230755","rc":[{"batb":[[0,2.86,89.68],[1,2.84,30.29]],"ltp":0.0,"tv":0.0,"id":14343845}]}]}
{"op":"mcm","clk":"1004448162","pt":1580630081452,"mc":[{"id":"1.168230755","rc":[{"batb":[[0,2.9,88.36],[1,2.88,30.28]],"ltp":0.0,"tv":0.0,"id":14343845}]}]}
{"op":"mcm","clk":"1004453954","pt":1580630202458,"mc":[{"id":"1.168230755","rc":[{"batb":[[1,1.02,2],[2,1.01,1.01]],"ltp":0.0,"tv":0.0,"id":14343845}]}]}
{"op":"mcm","clk":"1004453985","pt":1580630203231,"mc":[{"id":"1.168230755","rc":[{"batb":[[0,2.94,87.09],[1,2.92,30.29],[2,1.02,2]],"ltp":0.0,"tv":0.0,"id":14343845}]}]}
{"op":"mcm","clk":"1004459840","pt":1580630325115,"mc":[{"id":"1.168230755","rc":[{"batb":[[0,2.98,85.9],[1,2.96,30.29]],"ltp":0.0,"tv":0.0,"id":14343845}]}]}
{"op":"mcm","clk":"1004465930","pt":1580630446025,"mc":[{"id":"1.168230755","rc":[{"batb":[[0,3,115.86],[1,1.02,2],[2,1.01,1.01]],"ltp":0.0,"tv":0.0,"id":14343845}]}]}
{"op":"mcm","clk":"1004469073","pt":1580630517404,"mc":[{"id":"1.168230755","rc":[{"batb":[[0,2.82,91.03]],"ltp":0.0,"tv":0.0,"id":13095165}]}]}
{"op":"mcm","clk":"1004471707","pt":1580630567603,"mc":[{"id":"1.168230755","rc":[{"batb":[[0,2.86,89.68],[1,2.84,30.29],[2,1.02,2]],"ltp":0.0,"tv":0.0,"id":13095165}]}]}
{"op":"mcm","clk":"1004471727","pt":1580630568102,"mc":[{"id":"1.168230755","rc":[{"batb":[[0,3.05,30.29]],"ltp":0.0,"tv":0.0,"id":14343845}]}]}
{"op":"mcm","clk":"1004477083","pt":1580630689076,"mc":[{"id":"1.168230755","rc":[{"batb":[[1,1.02,2],[2,1.01,1.01]],"ltp":0.0,"tv":0.0,"id":13095165}]}]}
{"op":"mcm","clk":"1004477137","pt":1580630690467,"mc":[{"id":"1.168230755","rc":[{"batb":[[0,2.86,89.68],[1,2.7,30.28],[2,1.02,2]],"ltp":0.0,"tv":0.0,"id":14343845}]}]}
{"op":"mcm","clk":"1004482322","pt":1580630811101,"mc":[{"id":"1.168230755","rc":[{"batb":[[0,2.9,88.36],[1,2.88,30.28]],"ltp":0.0,"tv":0.0,"id":14343845}]}]}
{"op":"mcm","clk":"1004487197","pt":1580630932377,"mc":[{"id":"1.168230755","rc":[{"batb":[[1,1.02,2],[2,1.01,1.01]],"ltp":0.0,"tv":0.0,"id":14343845}]}]}
{"op":"mcm","clk":"1004487226","pt":1580630932993,"mc":[{"id":"1.168230755","rc":[{"batb":[[0,2.94,87.09],[1,2.92,30.29],[2,1.02,2]],"ltp":0.0,"tv":0.0,"id":14343845}]}]}
{"op":"mcm","clk":"1004492971","pt":1580631054408,"mc":[{"id":"1.168230755","rc":[{"batb":[[0,2.98,85.9],[1,2.96,30.29]],"ltp":0.0,"tv":0.0,"id":14343845}]}]}
{"op":"mcm","clk":"1004493790","pt":1580631071555,"mc":[{"id":"1.168230755","rc":[{"batb":[[0,2.46,104.38]],"ltp":0.0,"tv":0.0,"id":13095165},{"batl":[[0,6.6,39.06]],"ltp":0.0,"tv":0.0,"id":14343850},{"batl":[[0,4.5,57.31]],"ltp":0.0,"tv":0.0,"id":14343845}]}]}
{"op":"mcm","clk":"1004498406","pt":1580631176478,"mc":[{"id":"1.168230755","rc":[{"batb":[[0,2.72,94.34],[1,2.48,30.29],[2,1.02,2]],"ltp":0.0,"tv":0.0,"id":13095165},{"batb":[[0,3,30.29],[1,2.98,85.9]],"ltp":0.0,"tv":0.0,"id":14343845}]}]}
{"op":"mcm","clk":"1004498454","pt":1580631177504,"mc":[{"id":"1.168230755","rc":[{"batb":[[0,3,115.86],[1,1.02,2],[2,1.01,1.01]],"ltp":0.0,"tv":0.0,"id":14343845}]}]}
{"op":"mcm","clk":"1004500549","pt":1580631222925,"mc":[{"id":"1.168230755","rc":[{"batl":[[0,4.5,403.99]],"ltp":0.0,"tv":0.0,"id":14343845}]}]}
{"op":"mcm","clk":"1004501075","pt":1580631236463,"mc":[{"id":"1.168230755","rc":[{"batl":[[0,8.2,305.73]],"ltp":0.0,"tv":0.0,"id":14343850}]}]}
{"op":"mcm","clk":"1004503511","pt":1580631297547,"mc":[{"id":"1.168230755","rc":[{"batb":[[0,2.74,30.29],[1,2.72,94.34]],"ltp":0.0,"tv":0.0,"id":13095165}]}]}
{"op":"mcm","clk":"1004503547","pt":1580631298372,"mc":[{"id":"1.168230755","rc":[{"batb":[[0,2.8,91.48],[1,2.74,30.29]],"ltp":0.0,"tv":0.0,"id":13095165},{"batb":[[0,3.05,30.29]],"ltp":0.0,"tv":0.0,"id":14343845}]}]}
{"op":"mcm","clk":"1004508742","pt":1580631419502,"mc":[{"id":"1.168230755","rc":[{"batb":[[0,2.84,90.22],[1,2.82,30.29]],"ltp":0.0,"tv":0.0,"id":13095165}]}]}
{"op":"mcm","clk":"1004508781","pt":1580631420283,"mc":[{"id":"1.168230755","rc":[{"batb":[[0,2.74,93.52],[1,2.66,30.29],[2,1.02,2]],"ltp":0.0,"tv":0.0,"id":14343845}]}]}
{"op":"mcm","clk":"1004512379","pt":1580631509321,"mc":[{"id":"1.168230755","rc":[{"batl":[[0,4.7,330.65]],"ltp":0.0,"tv":0.0,"id":13095165}]}]}
{"op":"mcm","clk":"1004513779","pt":1580631541566,"mc":[{"id":"1.168230755","rc":[{"batb":[[0,2.86,30.29],[1,1.02,2],[2,1.01,1.01]],"ltp":0.0,"tv":0.0,"id":13095165},{"batb":[[0,2.76,30.29],[1,2.74,93.52]],"ltp":0.0,"tv":0.0,"id":14343845}]}]}
{"op":"mcm","clk":"1004513795","pt":1580631541873,"mc":[{"id":"1.168230755","rc":[{"batb":[[0,2.78,92.16],[1,2.76,30.29]],"ltp":0.0,"tv":0.0,"id":14343845}]}]}
{"op":"mcm","clk":"1004519464","pt":1580631662498,"mc":[{"id":"1.168230755","rc":[{"batb":[[0,2.52,30.29]],"ltp":0.0,"tv":0.0,"id":13095165}]}]}
{"op":"mcm","clk":"1004519514","pt":1580631663421,"mc":[{"id":"1.168230755","rc":[{"batb":[[0,2.58,99.56],[1,2.52,30.29],[2,1.02,2]],"ltp":0.0,"tv":0.0,"id":13095165},{"batb":[[0,2.9,88.36],[1,2.8,30.29]],"ltp":0.0,"tv":0.0,"id":14343845}]}]}
{"op":"mcm","clk":"1004524686","pt":1580631784526,"mc":[{"id":"1.168230755","rc":[{"batb":[[0,2.62,98.04],[1,2.6,30.29]],"ltp":0.0,"tv":0.0,"id":13095165}]}]}
{"op":"mcm","clk":"1004524715","pt":1580631785147,"mc":[{"id":"1.168230755","rc":[{"batb":[[0,2.96,86.63],[1,2.92,30.29]],"ltp":0.0,"tv":0.0,"id":14343845}]}]}
{"op":"mcm","clk":"1004530265","pt":1580631906648,"mc":[{"id":"1.168230755","rc":[{"batb":[[0,2.64,30.29],[1,1.02,2],[2,1.01,1.01]],"ltp":0.0,"tv":0.0,"id":13095165}]}]}
{"op":"mcm","clk":"1004530314","pt":1580631907471,"mc":[{"id":"1.168230755","rc":[{"batb":[[0,2.66,96.34],[1,2.64,30.29],[2,1.02,2]],"ltp":0.0,"tv":0.0,"id":13095165},{"batb":[[0,3,85.57],[1,2.98,30.29]],"ltp":0.0,"tv":0.0,"id":14343845}]}]}
{"op":"mcm","clk":"1004536385","pt":1580632027505,"mc":[{"id":"1.168230755","rc":[{"batb":[[0,2.68,30.29],[1,2.66,96.34]],"ltp":0.0,"tv":0.0,"id":13095165}]}]}
{"op":"mcm","clk":"1004536428","pt":1580632028277,"mc":[{"id":"1.168230755","rc":[{"batb":[[0,2.7,94.92],[1,2.68,30.29]],"ltp":0.0,"tv":0.0,"id":13095165},{"batb":[[0,3.05,30.29],[1,1.02,2],[2,1.01,1.01]],"ltp":0.0,"tv":0.0,"id":14343845}]}]}
{"op":"mcm","clk":"1004540995","pt":1580632149540,"mc":[{"id":"1.168230755","rc":[{"batb":[[0,2.74,93.52],[1,2.72,30.29]],"ltp":0.0,"tv":0.0,"id":13095165}]}]}
{"op":"mcm","clk":"1004541017","pt":1580632150155,"mc":[{"id":"1.168230755","rc":[{"batb":[[0,2.68,95.61],[1,2.66,30.29],[2,1.02,2]],"ltp":0.0,"tv":0.0,"id":14343845}]}]}
{"op":"mcm","clk":"1004546165","pt":1580632271426,"mc":[{"id":"1.168230755","rc":[{"batb":[[0,2.8,91.48],[1,2.76,30.29]],"ltp":0.0,"tv":0.0,"id":13095165},{"batb":[[1,1.02,2],[2,1.01,1.01]],"ltp":0.0,"tv":0.0,"id":14343845}]}]}
{"op":"mcm","clk":"1004546206","pt":1580632272311,"mc":[{"id":"1.168230755","rc":[{"batb":[[0,2.78,92.16],[1,2.7,30.28],[2,1.02,2]],"ltp":0.0,"tv":0.0,"id":14343845}]}]}
{"op":"mcm","clk":"1004551952","pt":1580632393576,"mc":[{"id":"1.168230755","rc":[{"batb":[[0,2.82,30.29],[1,2.8,91.48]],"ltp":0.0,"tv":0.0,"id":13095165}]}]}
{"op":"mcm","clk":"1004551983","pt":1580632394187,"mc":[{"id":"1.168230755","rc":[{"batb":[[0,2.84,90.22],[1,2.82,30.29]],"ltp":0.0,"tv":0.0,"id":13095165},{"batb":[[1,1.02,2],[2,1.01,1.01]],"ltp":0.0,"tv":0.0,"id":14343845}]}]}
{"op":"mcm","clk":"1004552017","pt":1580632394958,"mc":[{"id":"1.168230755","rc":[{"batb":[[0,2.86,89.68],[1,2.8,30.29],[2,1.02,2]],"ltp":0.0,"tv":0.0,"id":14343845}]}]}
{"op":"mcm","clk":"1004557039","pt":1580632515303,"mc":[{"id":"1.168230755","rc":[{"batb":[[0,2.86,30.29],[1,1.02,2],[2,1.01,1.01]],"ltp":0.0,"tv":0.0,"id":13095165}]}]}
{"op":"mcm","clk":"1004557080","pt":1580632516529,"mc":[{"id":"1.168230755","rc":[{"batb":[[1,1.02,2],[2,1.01,1.01]],"ltp":0.0,"tv":0.0,"id":14343845}]}]}
{"op":"mcm","clk":"1004557115","pt":1580632517205,"mc":[{"id":"1.168230755","rc":[{"batb":[[0,2.92,87.69],[1,2.88,30.28],[2,1.02,2]],"ltp":0.0,"tv":0.0,"id":14343845}]}]}
{"op":"mcm","clk":"1004562013","pt":1580632637357,"mc":[{"id":"1.168230755","rc":[{"batb":[[0,2.52,132.28]],"ltp":0.0,"tv":0.0,"id":13095165}]}]}
{"op":"mcm","clk":"1004562072","pt":1580632638591,"mc":[{"id":"1.168230755","rc":[{"batb":[[0,2.96,86.63],[1,2.94,30.29]],"ltp":0.0,"tv":0.0,"id":14343845}]}]}
{"op":"mcm","clk":"1004567040","pt":1580632758633,"mc":[{"id":"1.168230755","rc":[{"batb":[[0,2.52,101.99]],"ltp":0.0,"tv":0.0,"id":13095165}]}]}
{"op":"mcm","clk":"1004567085","pt":1580632759456,"mc":[{"id":"1.168230755","rc":[{"batb":[[0,2.62,98.04],[1,2.54,30.29],[2,1.02,2]],"ltp":0.0,"tv":0.0,"id":13095165},{"batb":[[0,2.98,30.29],[1,2.96,86.63]],"ltp":0.0,"tv":0.0,"id":14343845}]}]}
{"op":"mcm","clk":"1004567094","pt":1580632759762,"mc":[{"id":"1.168230755","rc":[{"batb":[[0,3,85.57],[1,2.98,30.29]],"ltp":0.0,"tv":0.0,"id":14343845}]}]}
{"op":"mcm","clk":"1004572657","pt":1580632880516,"mc":[{"id":"1.168230755","rc":[{"batb":[[0,2.78,92.16],[1,2.64,30.29]],"ltp":0.0,"tv":0.0,"id":13095165}]}]}
{"op":"mcm","clk":"1004572682","pt":1580632880983,"mc":[{"id":"1.168230755","rc":[{"batb":[[0,3.05,30.29],[1,1.02,2],[2,1.01,1.01]],"ltp":0.0,"tv":0.0,"id":14343845}]}]}
{"op":"mcm","clk":"1004579255","pt":1580633002524,"mc":[{"id":"1.168230755","rc":[{"batb":[[0,2.82,91.03],[1,2.8,30.29]],"ltp":0.0,"tv":0.0,"id":13095165},{"batb":[[0,2.66,30.29]],"ltp":0.0,"tv":0.0,"id":14343845}]}]}
{"op":"mcm","clk":"1004579271","pt":1580633002728,"mc":[{"id":"1.168230755","rc":[{"batb":[[0,2.72,94.34],[1,2.66,30.29],[2,1.02,2]],"ltp":0.0,"tv":0.0,"id":14343845}]}]}
{"op":"mcm","clk":"1004582569","pt":1580633072033,"mc":[{"id":"1.168230755","rc":[{"batl":[[0,4.6,395.26]],"ltp":0.0,"tv":0.0,"id":14343845}]}]}
{"op":"mcm","clk":"1004585016","pt":1580633123578,"mc":[{"id":"1.168230755","rc":[{"batb":[[0,2.84,30.29],[1,2.82,91.03]],"ltp":0.0,"tv":0.0,"id":13095165}]}]}
{"op":"mcm","clk":"1004585067","pt":1580633124457,"mc":[{"id":"1.168230755","rc":[{"batb":[[0,2.84,120.51],[1,1.02,2],[2,1.01,1.01]],"ltp":0.0,"tv":0.0,"id":13095165},{"batb":[[0,2.76,92.98],[1,2.74,30.29]],"ltp":0.0,"tv":0.0,"id":14343845}]}]}
{"op":"mcm","clk":"1004590621","pt":1580633245440,"mc":[{"id":"1.168230755","rc":[{"batb":[[0,2.86,30.29]],"ltp":0.0,"tv":0.0,"id":13095165}]}]}
{"op":"mcm","clk":"1004590662","pt":1580633246234,"mc":[{"id":"1.168230755","rc":[{"batb":[[0,2.8,91.48],[1,2.78,30.29]],"ltp":0.0,"tv":0.0,"id":14343845}]}]}
{"op":"mcm","clk":"1004596090","pt":1580633367616,"mc":[{"id":"1.168230755","rc":[{"batb":[[0,2.52,30.29]],"ltp":0.0,"tv":0.0,"id":13095165}]}]}
{"op":"mcm","clk":"1004596158","pt":1580633368499,"mc":[{"id":"1.168230755","rc":[{"batb":[[0,2.72,94.34],[1,2.52,30.29],[2,1.02,2]],"ltp":0.0,"tv":0.0,"id":13095165},{"batb":[[0,2.94,87.09],[1,2.82,30.29]],"ltp":0.0,"tv":0.0,"id":14343845}]}]}
{"op":"mcm","clk":"1004601543","pt":1580633488631,"mc":[{"id":"1.168230755","rc":[{"batb":[[0,2.74,30.29],[1,2.72,94.34]],"ltp":0.0,"tv":0.0,"id":13095165}]}]}
{"op":"mcm","clk":"1004601592","pt":1580633489548,"mc":[{"id":"1.168230755","rc":[{"batb":[[0,2.82,91.03],[1,2.74,30.29]],"ltp":0.0,"tv":0.0,"id":13095165},{"batb":[[0,2.96,30.29],[1,1.02,2],[2,1.01,1.01]],"ltp":0.0,"tv":0.0,"id":14343845}]}]}
{"op":"mcm","clk":"1004601595","pt":1580633489652,"mc":[{"id":"1.168230755","rc":[{"batb":[[0,2.98,85.9],[1,2.96,30.29],[2,1.02,2]],"ltp":0.0,"tv":0.0,"id":14343845}]}]}
{"op":"mcm","clk":"1004606430","pt":1580633610570,"mc":[{"id":"1.168230755","rc":[{"batb":[[0,2.84,120.51],[1,1.02,2],[2,1.01,1.01]],"ltp":0.0,"tv":0.0,"id":13095165}]}]}
{"op":"mcm","clk":"1004606467","pt":1580633611288,"mc":[{"id":"1.168230755","rc":[{"batb":[[0,3,115.86],[1,1.02,2],[2,1.01,1.01]],"ltp":0.0,"tv":0.0,"id":14343845}]}]}
{"op":"mcm","clk":"1004611975","pt":1580633732641,"mc":[{"id":"1.168230755","rc":[{"batb":[[0,2.86,30.29]],"ltp":0.0,"tv":0.0,"id":13095165},{"batb":[[0,3.05,30.29],[1,3,85.57],[2,1.02,2]],"ltp":0.0,"tv":0.0,"id":14343845}]}]}
{"op":"mcm","clk":"1004611983","pt":1580633732846,"mc":[{"id":"1.168230755","rc":[{"batb":[[1,1.02,2],[2,1.01,1.01]],"ltp":0.0,"tv":0.0,"id":14343845}]}]}
{"op":"mcm","clk":"1004618213","pt":1580633853609,"mc":[{"id":"1.168230755","rc":[{"batb":[[0,1.02,2],[1,1.01,1.01],[2,1.01,0]],"ltp":0.0,"tv":0.0,"id":13095165}]}]}
{"op":"mcm","clk":"1004618266","pt":1580633854531,"mc":[{"id":"1.168230755","rc":[{"batb":[[0,2.6,98.59],[1,2.52,30.29],[2,1.02,2]],"ltp":0.0,"tv":0.0,"id":13095165},{"batb":[[0,2.84,90.22],[1,2.66,30.29],[2,1.02,2]],"ltp":0.0,"tv":0.0,"id":14343845}]}]}
{"op":"mcm","clk":"1004624973","pt":1580633975619,"mc":[{"id":"1.168230755","rc":[{"batb":[[0,2.74,93.52],[1,2.62,30.29]],"ltp":0.0,"tv":0.0,"id":13095165}]}]}
{"op":"mcm","clk":"1004625010","pt":1580633976082,"mc":[{"id":"1.168230755","rc":[{"batb":[[0,2.9,88.36],[1,2.86,30.29]],"ltp":0.0,"tv":0.0,"id":14343845}]}]}
{"op":"mcm","clk":"1004627427","pt":1580634014442,"mc":[{"id":"1.168230755","rc":[{"batl":[[0,4.7,54.95]],"ltp":0.0,"tv":0.0,"id":13095165}]}]}
{"op":"mcm","clk":"1004632589","pt":1580634098586,"mc":[{"id":"1.168230755","rc":[{"batb":[[0,2.8,91.48],[1,2.76,30.29]],"ltp":0.0,"tv":0.0,"id":13095165},{"batb":[[0,2.92,30.29],[1,2.9,88.36]],"ltp":0.0,"tv":0.0,"id":14343845}]}]}
{"op":"mcm","clk":"1004632604","pt":1580634098847,"mc":[{"id":"1.168230755","rc":[{"batb":[[0,2.96,86.63],[1,2.92,30.29]],"ltp":0.0,"tv":0.0,"id":14343845}]}]}
{"op":"mcm","clk":"1004637782","pt":1580634209533,"mc":[{"id":"1.168230755","rc":[{"batl":[[0,4.7,317.35]],"ltp":0.0,"tv":0.0,"id":13095165}]}]}
{"op":"mcm","clk":"1004638163","pt":1580634218649,"mc":[{"id":"1.168230755","rc":[{"batb":[[1,1.02,2],[2,1.01,1.01]],"ltp":0.0,"tv":0.0,"id":13095165}]}]}
{"op":"mcm","clk":"1004638216","pt":1580634219635,"mc":[{"id":"1.168230755","rc":[{"batb":[[0,2.84,90.22],[1,2.82,30.29],[2,1.02,2]],"ltp":0.0,"tv":0.0,"id":13095165},{"batb":[[0,2.98,30.29],[1,1.02,2],[2,1.01,1.01]],"ltp":0.0,"tv":0.0,"id":14343845}]}]}
{"op":"mcm","clk":"1004638220","pt":1580634219736,"mc":[{"id":"1.168230755","rc":[{"batb":[[0,3,85.57],[1,2.98,30.29],[2,1.02,2]],"ltp":0.0,"tv":0.0,"id":14343845}]}]}
{"op":"mcm","clk":"1004643753","pt":1580634340484,"mc":[{"id":"1.168230755","rc":[{"batb":[[0,2.86,30.29],[1,2.84,90.22]],"ltp":0.0,"tv":0.0,"id":13095165}]}]}
{"op":"mcm","clk":"1004643787","pt":1580634341305,"mc":[{"id":"1.168230755","rc":[{"batb":[[1,1.02,2],[2,1.01,1.01]],"ltp":0.0,"tv":0.0,"id":13095165},{"batb":[[0,3.05,30.29],[1,1.02,2],[2,1.01,1.01]],"ltp":0.0,"tv":0.0,"id":14343845}]}]}
{"op":"mcm","clk":"1004650029","pt":1580634464573,"mc":[{"id":"1.168230755","rc":[{"batb":[[0,2.56,100.33],[1,2.52,30.29],[2,1.02,2]],"ltp":0.0,"tv":0.0,"id":13095165}]}]}
{"op":"mcm","clk":"1004650061","pt":1580634465143,"mc":[{"id":"1.168230755","rc":[{"batb":[[0,2.9,88.36],[1,2.66,30.29],[2,1.02,2]],"ltp":0.0,"tv":0.0,"id":14343845}]}]}
{"op":"mcm","clk":"1004655328","pt":1580634585617,"mc":[{"id":"1.168230755","rc":[{"batb":[[0,2.58,30.29],[1,2.56,100.33]],"ltp":0.0,"tv":0.0,"id":13095165}]}]}
{"op":"mcm","clk":"1004655379","pt":1580634586649,"mc":[{"id":"1.168230755","rc":[{"batb":[[0,2.76,92.98],[1,2.58,30.29]],"ltp":0.0,"tv":0.0,"id":13095165},{"batb":[[0,2.96,86.63],[1,2.92,30.29]],"ltp":0.0,"tv":0.0,"id":14343845}]}]}
{"op":"mcm","clk":"1004660933","pt":1580634708602,"mc":[{"id":"1.168230755","rc":[{"batb":[[0,2.78,30.29],[1,1.02,2],[2,1.01,1.01]],"ltp":0.0,"tv":0.0,"id":13095165}]}]}
{"op":"mcm","clk":"1004660962","pt":1580634709272,"mc":[{"id":"1.168230755","rc":[{"batb":[[0,2.8,91.48],[1,2.78,30.29],[2,1.02,2]],"ltp":0.0,"tv":0.0,"id":13095165},{"batb":[[0,3,85.57],[1,2.98,30.29]],"ltp":0.0,"tv":0.0,"id":14343845}]}]}
{"op":"mcm","clk":"1004667125","pt":1580634829599,"mc":[{"id":"1.168230755","rc":[{"batb":[[0,2.84,90.22],[1,2.82,30.29]],"ltp":0.0,"tv":0.0,"id":13095165},{"batb":[[0,3.05,30.29],[1,3,85.57]],"ltp":0.0,"tv":0.0,"id":14343845}]}]}
{"op":"mcm","clk":"1004667134","pt":1580634829805,"mc":[{"id":"1.168230755","rc":[{"batb":[[1,1.02,2],[2,1.01,1.01]],"ltp":0.0,"tv":0.0,"id":14343845}]}]}
{"op":"mcm","clk":"1004667504","pt":1580634836518,"mc":[{"id":"1.168230755","rc":[{"batb":[[0,1.02,2],[1,1.01,1.01],[2,1.01,0]],"ltp":0.0,"tv":0.0,"id":14343850}]}]}
{"op":"mcm","clk":"1004673724","pt":1580634951387,"mc":[{"id":"1.168230755","rc":[{"batb":[[0,2.86,30.29],[1,1.02,2],[2,1.01,1.01]],"ltp":0.0,"tv":0.0,"id":13095165},{"batb":[[0,2.66,30.29]],"ltp":0.0,"tv":0.0,"id":14343845}]}]}
{"op":"mcm","clk":"1004673755","pt":1580634952012,"mc":[{"id":"1.168230755","rc":[{"batb":[[0,2.94,87.09],[1,2.66,30.29],[2,1.02,2]],"ltp":0.0,"tv":0.0,"id":14343845}]}]}
{"op":"mcm","clk":"1004679919","pt":1580635072453,"mc":[{"id":"1.168230755","rc":[{"batb":[[0,2.52,30.29]],"ltp":0.0,"tv":0.0,"id":13095165}]}]}
{"op":"mcm","clk":"1004679971","pt":1580635073398,"mc":[{"id":"1.168230755","rc":[{"batb":[[0,2.72,94.34],[1,2.52,30.29],[2,1.02,2]],"ltp":0.0,"tv":0.0,"id":13095165},{"batb":[[0,2.98,85.9],[1,2.96,30.29]],"ltp":0.0,"tv":0.0,"id":14343845}]}]}
{"op":"mcm","clk":"1004682052","pt":1580635109912,"mc":[{"id":"1.168230755","rc":[{"batl":[[0,4.4,338.84]],"ltp":0.0,"tv":0.0,"id":13095165}]}]}
{"op":"mcm","clk":"1004686332","pt":1580635194583,"mc":[{"id":"1.168230755","rc":[{"batb":[[0,2.76,92.98],[1,2.74,30.29]],"ltp":0.0,"tv":0.0,"id":13095165},{"batb":[[1,1.02,2],[2,1.01,1.01]],"ltp":0.0,"tv":0.0,"id":14343845}]}]}
{"op":"mcm","clk":"1004686360","pt":1580635194998,"mc":[{"id":"1.168230755","rc":[{"batb":[[0,3,115.86]],"ltp":0.0,"tv":0.0,"id":14343845}]}]}
{"op":"mcm","clk":"1004691955","pt":1580635316534,"mc":[{"id":"1.168230755","rc":[{"batb":[[0,2.8,91.48],[1,2.78,30.29]],"ltp":0.0,"tv":0.0,"id":13095165},{"batb":[[0,3.05,30.29]],"ltp":0.0,"tv":0.0,"id":14343845}]}]}
{"op":"mcm","clk":"1004696372","pt":1580635437498,"mc":[{"id":"1.168230755","rc":[{"batb":[[0,2.82,30.29],[1,2.8,91.48]],"ltp":0.0,"tv":0.0,"id":13095165}]}]}
{"op":"mcm","clk":"1004696389","pt":1580635437809,"mc":[{"id":"1.168230755","rc":[{"batb":[[0,2.84,90.22],[1,2.82,30.29]],"ltp":0.0,"tv":0.0,"id":13095165}]}]}
{"op":"mcm","clk":"1004696438","pt":1580635439305,"mc":[{"id":"1.168230755","rc":[{"batb":[[0,2.76,92.98],[1,2.66,30.29],[2,1.02,2]],"ltp":0.0,"tv":0.0,"id":14343845}]}]}
{"op":"mcm","clk":"1004701672","pt":1580635559539,"mc":[{"id":"1.168230755","rc":[{"batb":[[0,2.86,30.29],[1,1.02,2],[2,1.01,1.01]],"ltp":0.0,"tv":0.0,"id":13095165}]}]}
{"op":"mcm","clk":"1004701705","pt":1580635560361,"mc":[{"id":"1.168230755","rc":[{"batb":[[0,2.92,87.69],[1,2.78,30.29]],"ltp":0.0,"tv":0.0,"id":14343845}]}]}
{"op":"mcm","clk":"1004707228","pt":1580635681597,"mc":[{"id":"1.168230755","rc":[{"batb":[[0,2.6,98.59],[1,2.52,30.29],[2,1.02,2]],"ltp":0.0,"tv":0.0,"id":13095165},{"batb":[[0,2.94,30.29],[1,1.02,2],[2,1.01,1.01]],"ltp":0.0,"tv":0.0,"id":14343845}]}]}
{"op":"mcm","clk":"1004707238","pt":1580635681694,"mc":[{"id":"1.168230755","rc":[{"batb":[[0,2.96,86.63],[1,2.94,30.29],[2,1.02,2]],"ltp":0.0,"tv":0.0,"id":14343845}]}]}
{"op":"mcm","clk":"1004712107","pt":1580635802522,"mc":[{"id":"1.168230755","rc":[{"batb":[[0,2.62,30.29],[1,2.6,98.59]],"ltp":0.0,"tv":0.0,"id":13095165}]}]}
{"op":"mcm","clk":"1004712162","pt":1580635803455,"mc":[{"id":"1.168230755","rc":[{"batb":[[0,2.68,95.86],[1,2.62,30.29]],"ltp":0.0,"tv":0.0,"id":13095165},{"batb":[[0,3,85.57],[1,2.98,30.29]],"ltp":0.0,"tv":0.0,"id":14343845}]}]}
{"op":"mcm","clk":"1004717034","pt":1580635924511,"mc":[{"id":"1.168230755","rc":[{"batb":[[0,2.7,30.28],[1,2.68,95.86]],"ltp":0.0,"tv":0.0,"id":13095165}]}]}
{"op":"mcm","clk":"1004717076","pt":1580635925294,"mc":[{"id":"1.168230755","rc":[{"batb":[[0,2.72,94.34],[1,2.7,30.28]],"ltp":0.0,"tv":0.0,"id":13095165},{"batb":[[0,3.05,30.29],[1,1.02,2],[2,1.01,1.01]],"ltp":0.0,"tv":0.0,"id":14343845}]}]}
{"op":"mcm","clk":"1004722588","pt":1580636046577,"mc":[{"id":"1.168230755","rc":[{"batb":[[0,2.74,30.29],[1,1.02,2],[2,1.01,1.01]],"ltp":0.0,"tv":0.0,"id":13095165}]}]}
{"op":"mcm","clk":"1004722639","pt":1580636047250,"mc":[{"id":"1.168230755","rc":[{"batb":[[0,2.78,92.16],[1,2.74,30.29],[2,1.02,2]],"ltp":0.0,"tv":0.0,"id":13095165},{"batb":[[0,2.7,94.92],[1,2.66,30.29],[2,1.02,2]],"ltp":0.0,"tv":0.0,"id":14343845}]}]}
{"op":"mcm","clk":"1004727588","pt":1580636167579,"mc":[{"id":"1.168230755","rc":[{"batb":[[0,2.8,30.29],[1,2.78,92.16]],"ltp":0.0,"tv":0.0,"id":13095165}]}]}
{"op":"mcm","clk":"1004727631","pt":1580636168560,"mc":[{"id":"1.168230755","rc":[{"batb":[[0,2.82,91.03],[1,2.8,30.29]],"ltp":0.0,"tv":0.0,"id":13095165},{"batb":[[0,2.86,89.68],[1,2.72,30.29]],"ltp":0.0,"tv":0.0,"id":14343845}]}]}
{"op":"mcm","clk":"1004732571","pt":1580636290437,"mc":[{"id":"1.168230755","rc":[{"batb":[[0,2.84,120.51],[1,1.02,2],[2,1.01,1.01]],"ltp":0.0,"tv":0.0,"id":13095165},{"batb":[[1,1.02,2],[2,1.01,1.01]],"ltp":0.0,"tv":0.0,"id":14343845}]}]}
{"op":"mcm","clk":"1004732601","pt":1580636291267,"mc":[{"id":"1.168230755","rc":[{"batb":[[0,2.9,88.36],[1,2.88,30.28],[2,1.02,2]],"ltp":0.0,"tv":0.0,"id":14343845}]}]}
{"op":"mcm","clk":"1004738229","pt":1580636411473,"mc":[{"id":"1.168230755","rc":[{"batb":[[0,2.86,30.29]],"ltp":0.0,"tv":0.0,"id":13095165},{"batb":[[1,1.02,2],[2,1.01,1.01]],"ltp":0.0,"tv":0.0,"id":14343845}]}]}
{"op":"mcm","clk":"1004738283","pt":1580636412351,"mc":[{"id":"1.168230755","rc":[{"batb":[[0,2.94,87.09],[1,2.92,30.29],[2,1.02,2]],"ltp":0.0,"tv":0.0,"id":14343845}]}]}
{"op":"mcm","clk":"1004744901","pt":1580636532598,"mc":[{"id":"1.168230755","rc":[{"batb":[[0,1.02,2],[1,1.01,1.01],[2,1.01,0]],"ltp":0.0,"tv":0.0,"id":13095165}]}]}
{"op":"mcm","clk":"1004744981","pt":1580636533585,"mc":[{"id":"1.168230755","rc":[{"batb":[[0,2.54,101.12],[1,2.52,30.29],[2,1.02,2]],"ltp":0.0,"tv":0.0,"id":13095165},{"batb":[[0,2.98,85.9],[1,2.96,30.29]],"ltp":0.0,"tv":0.0,"id":14343845}]}]}
{"op":"mcm","clk":"1004750930","pt":1580636654585,"mc":[{"id":"1.168230755","rc":[{"batb":[[0,2.6,98.59],[1,2.56,30.29]],"ltp":0.0,"tv":0.0,"id":13095165}]}]}
{"op":"mcm","clk":"1004750956","pt":1580636655356,"mc":[{"id":"1.168230755","rc":[{"batb":[[0,3,115.86],[1,1.02,2],[2,1.01,1.01]],"ltp":0.0,"tv":0.0,"id":14343845}]}]}
{"op":"mcm","clk":"1004756401","pt":1580636776490,"mc":[{"id":"1.168230755","rc":[{"batb":[[0,2.64,97.32],[1,2.62,30.29]],"ltp":0.0,"tv":0.0,"id":13095165},{"batb":[[0,3.05,30.29],[1,3,85.57],[2,1.02,2]],"ltp":0.0,"tv":0.0,"id":14343845}]}]}
{"op":"mcm","clk":"1004756411","pt":1580636776694,"mc":[{"id":"1.168230755","rc":[{"batb":[[1,1.02,2],[2,1.01,1.01]],"ltp":0.0,"tv":0.0,"id":14343845}]}]}
{"op":"mcm","clk":"1004762145","pt":1580636897604,"mc":[{"id":"1.168230755","rc":[{"batb":[[0,2.66,30.29],[1,2.64,97.32]],"ltp":0.0,"tv":0.0,"id":13095165}]}]}
{"op":"mcm","clk":"1004762197","pt":1580636898530,"mc":[{"id":"1.168230755","rc":[{"batb":[[0,2.68,95.86],[1,2.66,30.29]],"ltp":0.0,"tv":0.0,"id":13095165},{"batb":[[0,2.66,30.29],[1,2.56,100.33],[2,1.02,2]],"ltp":0.0,"tv":0.0,"id":14343845}]}]}
{"op":"mcm","clk":"1004762215","pt":1580636898840,"mc":[{"id":"1.168230755","rc":[{"batb":[[0,2.74,93.52],[1,2.66,30.29]],"ltp":0.0,"tv":0.0,"id":14343845}]}]}
{"op":"mcm","clk":"1004769085","pt":1580637020503,"mc":[{"id":"1.168230755","rc":[{"batb":[[0,2.7,30.28],[1,2.68,95.86]],"ltp":0.0,"tv":0.0,"id":13095165}]}]}
{"op":"mcm","clk":"1004769149","pt":1580637021541,"mc":[{"id":"1.168230755","rc":[{"batb":[[0,2.76,92.98],[1,2.7,30.28]],"ltp":0.0,"tv":0.0,"id":13095165},{"batb":[[0,2.84,90.22],[1,2.76,30.29]],"ltp":0.0,"tv":0.0,"id":14343845}]}]}
{"op":"mcm","clk":"1004775605","pt":1580637142458,"mc":[{"id":"1.168230755","rc":[{"batb":[[0,2.78,30.29],[1,2.76,92.98]],"ltp":0.0,"tv":0.0,"id":13095165}]}]}
{"op":"mcm","clk":"1004775662","pt":1580637143357,"mc":[{"id":"1.168230755","rc":[{"batb":[[0,2.8,91.48],[1,2.78,30.29]],"ltp":0.0,"tv":0.0,"id":13095165},{"batb":[[0,2.88,88.96],[1,2.86,30.29]],"ltp":0.0,"tv":0.0,"id":14343845}]}]}
{"op":"mcm","clk":"1004781842","pt":1580637263635,"mc":[{"id":"1.168230755","rc":[{"batb":[[1,1.02,2],[2,1.01,1.01]],"ltp":0.0,"tv":0.0,"id":13095165}]}]}
{"op":"mcm","clk":"1004781893","pt":1580637264613,"mc":[{"id":"1.168230755","rc":[{"batb":[[0,2.84,90.22],[1,2.82,30.29],[2,1.02,2]],"ltp":0.0,"tv":0.0,"id":13095165},{"batb":[[0,2.9,30.29],[1,1.02,2],[2,1.01,1.01]],"ltp":0.0,"tv":0.0,"id":14343845}]}]}
{"op":"mcm","clk":"1004781898","pt":1580637264719,"mc":[{"id":"1.168230755","rc":[{"batb":[[0,2.98,85.9],[1,2.9,30.29],[2,1.02,2]],"ltp":0.0,"tv":0.0,"id":14343845}]}]}
{"op":"mcm","clk":"1004787991","pt":1580637385446,"mc":[{"id":"1.168230755","rc":[{"batb":[[0,2.86,30.29],[1,1.02,2],[2,1.01,1.01]],"ltp":0.0,"tv":0.0,"id":13095165}]}]}
{"op":"mcm","clk":"1004788034","pt":1580637386271,"mc":[{"id":"1.168230755","rc":[{"batb":[[0,3,115.86],[1,1.02,2],[2,1.01,1.01]],"ltp":0.0,"tv":0.0,"id":14343845}]}]}
{"op":"mcm","clk":"1004795402","pt":1580637507546,"mc":[{"id":"1.168230755","rc":[{"batb":[[0,2.52,132.28]],"ltp":0.0,"tv":0.0,"id":13095165},{"batb":[[0,3.05,30.29],[1,3,85.57],[2,1.02,2]],"ltp":0.0,"tv":0.0,"id":14343845}]}]}
{"op":"mcm","clk":"1004795412","pt":1580637507752,"mc":[{"id":"1.168230755","rc":[{"batb":[[1,1.02,2],[2,1.01,1.01]],"ltp":0.0,"tv":0.0,"id":14343845}]}]}
{"op":"mcm","clk":"1004803022","pt":1580637628632,"mc":[{"id":"1.168230755","rc":[{"batb":[[0,2.54,30.29],[1,2.52,101.99],[2,1.02,2]],"ltp":0.0,"tv":0.0,"id":13095165}]}]}
{"op":"mcm","clk":"1004803088","pt":1580637629558,"mc":[{"id":"1.168230755","rc":[{"batb":[[0,2.68,95.86],[1,2.54,30.29]],"ltp":0.0,"tv":0.0,"id":13095165},{"batb":[[0,2.66,126.63]],"ltp":0.0,"tv":0.0,"id":14343845}]}]}
{"op":"mcm","clk":"1004812489","pt":1580637751571,"mc":[{"id":"1.168230755","rc":[{"batb":[[0,2.7,30.28],[1,1.02,2],[2,1.01,1.01]],"ltp":0.0,"tv":0.0,"id":13095165}]}]}
{"op":"mcm","clk":"1004812545","pt":1580637752288,"mc":[{"id":"1.168230755","rc":[{"batb":[[0,2.76,92.98],[1,2.7,30.28],[2,1.02,2]],"ltp":0.0,"tv":0.0,"id":13095165},{"batb":[[0,2.74,93.52],[1,2.68,30.29],[2,1.02,2]],"ltp":0.0,"tv":0.0,"id":14343845}]}]}
{"op":"mcm","clk":"1004820641","pt":1580637872587,"mc":[{"id":"1.168230755","rc":[{"batb":[[0,2.78,30.29],[1,1.02,2],[2,1.01,1.01]],"ltp":0.0,"tv":0.0,"id":13095165}]}]}
{"op":"mcm","clk":"1004820688","pt":1580637873423,"mc":[{"id":"1.168230755","rc":[{"batb":[[0,2.82,91.03],[1,2.78,30.29],[2,1.02,2]],"ltp":0.0,"tv":0.0,"id":13095165},{"batb":[[0,2.78,92.16],[1,2.76,30.29]],"ltp":0.0,"tv":0.0,"id":14343845}]}]}
{"op":"mcm","clk":"1004828260","pt":1580637993587,"mc":[{"id":"1.168230755","rc":[{"batb":[[1,1.02,2],[2,1.01,1.01]],"ltp":0.0,"tv":0.0,"id":13095165}]}]}
{"op":"mcm","clk":"1004828330","pt":1580637994582,"mc":[{"id":"1.168230755","rc":[{"batb":[[0,2.84,120.51]],"ltp":0.0,"tv":0.0,"id":13095165},{"batb":[[0,2.8,30.29],[1,1.02,2],[2,1.01,1.01]],"ltp":0.0,"tv":0.0,"id":14343845}]}]}
{"op":"mcm","clk":"1004828336","pt":1580637994739,"mc":[{"id":"1.168230755","rc":[{"batb":[[0,2.86,89.68],[1,2.8,30.29],[2,1.02,2]],"ltp":0.0,"tv":0.0,"id":14343845}]}]}
{"op":"mcm","clk":"1004836232","pt":1580638115599,"mc":[{"id":"1.168230755","rc":[{"batb":[[0,2.86,30.29]],"ltp":0.0,"tv":0.0,"id":13095165}]}]}
{"op":"mcm","clk":"1004836296","pt":1580638116639,"mc":[{"id":"1.168230755","rc":[{"batb":[[0,2.88,30.28],[1,1.02,2],[2,1.01,1.01]],"ltp":0.0,"tv":0.0,"id":14343845}]}]}
{"op":"mcm","clk":"1004836311","pt":1580638116792,"mc":[{"id":"1.168230755","rc":[{"batb":[[0,2.92,87.69],[1,2.88,30.28],[2,1.02,2]],"ltp":0.0,"tv":0.0,"id":14343845}]}]}
{"op":"mcm","clk":"1004844876","pt":1580638237470,"mc":[{"id":"1.168230755","rc":[{"batb":[[0,2.62,98.04],[1,2.52,30.29],[2,1.02,2]],"ltp":0.0,"tv":0.0,"id":13095165}]}]}
{"op":"mcm","clk":"1004844955","pt":1580638238463,"mc":[{"id":"1.168230755","rc":[{"batb":[[0,2.96,86.63],[1,2.94,30.29]],"ltp":0.0,"tv":0.0,"id":14343845}]}]}
{"op":"mcm","clk":"1004854215","pt":1580638358641,"mc":[{"id":"1.168230755","rc":[{"batb":[[1,1.02,2],[2,1.01,1.01]],"ltp":0.0,"tv":0.0,"id":13095165}]}]}
{"op":"mcm","clk":"1004854281","pt":1580638359625,"mc":[{"id":"1.168230755","rc":[{"batb":[[0,2.66,96.34],[1,2.64,30.29],[2,1.02,2]],"ltp":0.0,"tv":0.0,"id":13095165},{"batb":[[0,2.98,30.29],[1,1.02,2],[2,1.01,1.01]],"ltp":0.0,"tv":0.0,"id":14343845}]}]}
{"op":"mcm","clk":"1004854291","pt":1580638359727,"mc":[{"id":"1.168230755","rc":[{"batb":[[0,3,85.57],[1,2.98,30.29],[2,1.02,2]],"ltp":0.0,"tv":0.0,"id":14343845}]}]}
{"op":"mcm","clk":"1004863831","pt":1580638481594,"mc":[{"id":"1.168230755","rc":[{"batb":[[0,2.68,30.29],[1,1.02,2],[2,1.01,1.01]],"ltp":0.0,"tv":0.0,"id":13095165}]}]}
{"op":"mcm","clk":"1004863891","pt":1580638482277,"mc":[{"id":"1.168230755","rc":[{"batb":[[0,2.7,94.92],[1,2.68,30.29],[2,1.02,2]],"ltp":0.0,"tv":0.0,"id":13095165},{"batb":[[0,3.05,30.29],[1,1.02,2],[2,1.01,1.01]],"ltp":0.0,"tv":0.0,"id":14343845}]}]}
{"op":"mcm","clk":"1004873490","pt":1580638602626,"mc":[{"id":"1.168230755","rc":[{"batb":[[0,2.76,92.98],[1,2.72,30.29]],"ltp":0.0,"tv":0.0,"id":13095165},{"batb":[[0,1.02,2],[1,1.01,1.01],[2,1.01,0]],"ltp":0.0,"tv":0.0,"id":14343845}]}]}
{"op":"mcm","clk":"1004873521","pt":1580638602888,"mc":[{"id":"1.168230755","rc":[{"batb":[[0,2.66,126.63],[1,1.02,2],[2,1.01,1.01]],"ltp":0.0,"tv":0.0,"id":14343845}]}]}
{"op":"mcm","clk":"1004881959","pt":1580638710644,"mc":[{"id":"1.168230755","rc":[{"batl":[[0,3.9,382.15]],"ltp":0.0,"tv":0.0,"id":13095165}]}]}
{"op":"mcm","clk":"1004882973","pt":1580638723568,"mc":[{"id":"1.168230755","rc":[{"batb":[[1,1.02,2],[2,1.01,1.01]],"ltp":0.0,"tv":0.0,"id":13095165}]}]}
{"op":"mcm","clk":"1004883037","pt":1580638724409,"mc":[{"id":"1.168230755","rc":[{"batb":[[0,2.8,91.48],[1,2.78,30.29],[2,1.02,2]],"ltp":0.0,"tv":0.0,"id":13095165},{"batb":[[0,2.68,30.29],[1,2.66,96.34],[2,1.02,2]],"ltp":0.0,"tv":0.0,"id":14343845}]}]}
{"op":"mcm","clk":"1004883083","pt":1580638724881,"mc":[{"id":"1.168230755","rc":[{"batb":[[0,2.7,94.92],[1,2.68,30.29]],"ltp":0.0,"tv":0.0,"id":14343845}]}]}
{"op":"mcm","clk":"1004892889","pt":1580638845628,"mc":[{"id":"1.168230755","rc":[{"batb":[[0,2.84,90.22],[1,2.82,30.29]],"ltp":0.0,"tv":0.0,"id":13095165}]}]}
{"op":"mcm","clk":"1004892965","pt":1580638846528,"mc":[{"id":"1.168230755","rc":[{"batb":[[0,2.74,93.52],[1,2.72,30.29]],"ltp":0.0,"tv":0.0,"id":14343845}]}]}
{"op":"mcm","clk":"1004903230","pt":1580638967617,"mc":[{"id":"1.168230755","rc":[{"batb":[[0,2.86,30.29],[1,1.02,2],[2,1.01,1.01]],"ltp":0.0,"tv":0.0,"id":13095165},{"batb":[[1,1.02,2],[2,1.01,1.01]],"ltp":0.0,"tv":0.0,"id":14343845}]}]}
{"op":"mcm","clk":"1004903273","pt":1580638967978,"mc":[{"id":"1.168230755","rc":[{"batb":[[0,2.88,88.96],[1,2.76,30.29],[2,1.02,2]],"ltp":0.0,"tv":0.0,"id":14343845}]}]}
{"op":"mcm","clk":"1004915997","pt":1580639088573,"mc":[{"id":"1.168230755","rc":[{"batb":[[0,1.02,2],[1,1.01,1.01],[2,1.01,0]],"ltp":0.0,"tv":0.0,"id":13095165}]}]}
{"op":"mcm","clk":"1004916096","pt":1580639089455,"mc":[{"id":"1.168230755","rc":[{"batb":[[0,2.56,100.33],[1,2.52,30.29],[2,1.02,2]],"ltp":0.0,"tv":0.0,"id":13095165},{"batb":[[0,2.94,87.09],[1,2.9,30.29]],"ltp":0.0,"tv":0.0,"id":14343845}]}]}
{"op":"mcm","clk":"1004928625","pt":1580639210580,"mc":[{"id":"1.168230755","rc":[{"batb":[[0,2.8,91.48],[1,2.58,30.29]],"ltp":0.0,"tv":0.0,"id":13095165}]}]}
{"op":"mcm","clk":"1004928783","pt":1580639212181,"mc":[{"id":"1.168230755","rc":[{"batb":[[0,2.98,85.9],[1,2.96,30.29]],"ltp":0.0,"tv":0.0,"id":14343845}]}]}
{"op":"mcm","clk":"1004941697","pt":1580639332600,"mc":[{"id":"1.168230755","rc":[{"batb":[[0,2.82,30.29],[1,1.02,2],[2,1.01,1.01]],"ltp":0.0,"tv":0.0,"id":13095165}]}]}
{"op":"mcm","clk":"1004941823","pt":1580639333602,"mc":[{"id":"1.168230755","rc":[{"batb":[[0,2.84,90.22],[1,2.82,30.29],[2,1.02,2]],"ltp":0.0,"tv":0.0,"id":13095165},{"batb":[[0,3,115.86],[1,1.02,2],[2,1.01,1.01]],"ltp":0.0,"tv":0.0,"id":14343845}]}]}
{"op":"mcm","clk":"1004954054","pt":1580639454528,"mc":[{"id":"1.168230755","rc":[{"batb":[[0,2.86,30.29],[1,1.02,2],[2,1.01,1.01]],"ltp":0.0,"tv":0.0,"id":13095165},{"batb":[[0,3.05,30.29],[1,3,85.57],[2,1.02,2]],"ltp":0.0,"tv":0.0,"id":14343845}]}]}
{"op":"mcm","clk":"1004954072","pt":1580639454739,"mc":[{"id":"1.168230755","rc":[{"batb":[[1,1.02,2],[2,1.01,1.01]],"ltp":0.0,"tv":0.0,"id":14343845}]}]}
{"op":"mcm","clk":"1004966769","pt":1580639576432,"mc":[{"id":"1.168230755","rc":[{"batb":[[0,2.52,30.29]],"ltp":0.0,"tv":0.0,"id":13095165}]}]}
{"op":"mcm","clk":"1004966869","pt":1580639577325,"mc":[{"id":"1.168230755","rc":[{"batb":[[0,2.56,100.33],[1,2.52,30.29],[2,1.02,2]],"ltp":0.0,"tv":0.0,"id":13095165},{"batb":[[0,2.8,91.48],[1,2.64,30.29],[2,1.02,2]],"ltp":0.0,"tv":0.0,"id":14343845}]}]}
{"op":"mcm","clk":"1004977593","pt":1580639698412,"mc":[{"id":"1.168230755","rc":[{"batb":[[0,2.66,96.34],[1,2.58,30.29]],"ltp":0.0,"tv":0.0,"id":13095165}]}]}
{"op":"mcm","clk":"1004977646","pt":1580639699099,"mc":[{"id":"1.168230755","rc":[{"batb":[[0,2.94,87.09],[1,2.82,30.29]],"ltp":0.0,"tv":0.0,"id":14343845}]}]}
{"op":"mcm","clk":"1004989371","pt":1580639820381,"mc":[{"id":"1.168230755","rc":[{"batb":[[0,2.7,94.92],[1,2.68,30.29]],"ltp":0.0,"tv":0.0,"id":13095165},{"batb":[[0,2.96,30.29],[1,2.94,87.09]],"ltp":0.0,"tv":0.0,"id":14343845}]}]}
{"op":"mcm","clk":"1004989428","pt":1580639820959,"mc":[{"id":"1.168230755","rc":[{"batb":[[0,2.98,85.9],[1,2.96,30.29]],"ltp":0.0,"tv":0.0,"id":14343845}]}]}
{"op":"mcm","clk":"1005001003","pt":1580639941386,"mc":[{"id":"1.168230755","rc":[{"batb":[[0,2.72,30.29],[1,2.7,94.92]],"ltp":0.0,"tv":0.0,"id":13095165}]}]}
{"op":"mcm","clk":"1005001126","pt":1580639942599,"mc":[{"id":"1.168230755","rc":[{"batb":[[0,2.8,91.48],[1,2.72,30.29]],"ltp":0.0,"tv":0.0,"id":13095165},{"batb":[[0,3,30.29],[1,1.02,2],[2,1.01,1.01]],"ltp":0.0,"tv":0.0,"id":14343845}]}]}
{"op":"mcm","clk":"1005001135","pt":1580639942706,"mc":[{"id":"1.168230755","rc":[{"batb":[[0,3,115.86]],"ltp":0.0,"tv":0.0,"id":14343845}]}]}
{"op":"mcm","clk":"1005012474","pt":1580640063575,"mc":[{"id":"1.168230755","rc":[{"batb":[[0,2.84,90.22],[1,2.82,30.29]],"ltp":0.0,"tv":0.0,"id":13095165}]}]}
{"op":"mcm","clk":"1005012521","pt":1580640064057,"mc":[{"id":"1.168230755","rc":[{"batb":[[0,3.05,30.29]],"ltp":0.0,"tv":0.0,"id":14343845}]}]}
{"op":"mcm","clk":"1005026531","pt":1580640185597,"mc":[{"id":"1.168230755","rc":[{"batb":[[0,2.86,30.29],[1,1.02,2],[2,1.01,1.01]],"ltp":0.0,"tv":0.0,"id":13095165},{"batb":[[0,2.64,30.29]],"ltp":0.0,"tv":0.0,"id":14343845}]}]}
{"op":"mcm","clk":"1005026666","pt":1580640186601,"mc":[{"id":"1.168230755","rc":[{"batb":[[0,2.68,95.61],[1,2.64,30.29],[2,1.02,2]],"ltp":0.0,"tv":0.0,"id":14343845}]}]}
{"op":"mcm","clk":"1005038409","pt":1580640272631,"mc":[{"id":"1.168230755","rc":[{"batl":[[0,5.1,356.65]],"ltp":0.0,"tv":0.0,"id":14343845}]}]}
{"op":"mcm","clk":"1005042978","pt":1580640306500,"mc":[{"id":"1.168230755","rc":[{"batb":[[0,2.52,30.29]],"ltp":0.0,"tv":0.0,"id":13095165}]}]}
{"op":"mcm","clk":"1005043149","pt":1580640307500,"mc":[{"id":"1.168230755","rc":[{"batb":[[0,2.62,98.04],[1,2.52,30.29],[2,1.02,2]],"ltp":0.0,"tv":0.0,"id":13095165},{"batb":[[1,1.02,2],[2,1.01,1.01]],"ltp":0.0,"tv":0.0,"id":14343845}]}]}
{"op":"mcm","clk":"1005170690","pt":1580641281565,"mc":[{"id":"1.168230755","rc":[{"batb":[[0,2.78,92.16],[1,2.64,30.29]],"ltp":0.0,"tv":0.0,"id":13095165},{"batb":[[0,2.7,30.28]],"ltp":0.0,"tv":0.0,"id":14343845}]}]}
{"op":"mcm","clk":"1005170858","pt":1580641282569,"mc":[{"id":"1.168230755","rc":[{"batb":[[0,2.82,91.03],[1,2.7,30.28],[2,1.02,2]],"ltp":0.0,"tv":0.0,"id":14343845}]}]}
{"op":"mcm","clk":"1005193090","pt":1580641401618,"mc":[{"id":"1.168230755","rc":[{"batb":[[0,2.8,30.29],[1,2.78,92.16]],"ltp":0.0,"tv":0.0,"id":13095165}]}]}
{"op":"mcm","clk":"1005193170","pt":1580641402041,"mc":[{"id":"1.168230755","rc":[{"batb":[[0,2.82,91.03],[1,2.8,30.29]],"ltp":0.0,"tv":0.0,"id":13095165},{"batb":[[1,1.02,2],[2,1.01,1.01]],"ltp":0.0,"tv":0.0,"id":14343845}]}]}
{"op":"mcm","clk":"1005193491","pt":1580641403626,"mc":[{"id":"1.168230755","rc":[{"batb":[[0,2.84,30.29]],"ltp":0.0,"tv":0.0,"id":14343845}]}]}
{"op":"mcm","clk":"1005193545","pt":1580641403835,"mc":[{"id":"1.168230755","rc":[{"batb":[[0,2.88,88.96],[1,2.84,30.29],[2,1.02,2]],"ltp":0.0,"tv":0.0,"id":14343845}]}]}
{"op":"mcm","clk":"1005218081","pt":1580641524507,"mc":[{"id":"1.168230755","rc":[{"batb":[[0,2.84,120.51],[1,1.02,2],[2,1.01,1.01]],"ltp":0.0,"tv":0.0,"id":13095165},{"batb":[[0,2.9,30.29],[1,2.88,88.96]],"ltp":0.0,"tv":0.0,"id":14343845}]}]}
{"op":"mcm","clk":"1005218138","pt":1580641524825,"mc":[{"id":"1.168230755","rc":[{"batb":[[0,2.94,87.09],[1,2.9,30.29]],"ltp":0.0,"tv":0.0,"id":14343845}]}]}
{"op":"mcm","clk":"1005243428","pt":1580641645647,"mc":[{"id":"1.168230755","rc":[{"batb":[[0,2.86,30.29]],"ltp":0.0,"tv":0.0,"id":13095165},{"batb":[[0,2.96,30.29],[1,1.02,2],[2,1.01,1.01]],"ltp":0.0,"tv":0.0,"id":14343845}]}]}
{"op":"mcm","clk":"1005243448","pt":1580641645760,"mc":[{"id":"1.168230755","rc":[{"batb":[[0,2.98,85.9],[1,2.96,30.29],[2,1.02,2]],"ltp":0.0,"tv":0.0,"id":14343845}]}]}
{"op":"mcm","clk":"1005267249","pt":1580641766593,"mc":[{"id":"1.168230755","rc":[{"batb":[[0,1.02,2],[1,1.01,1.01],[2,1.01,0]],"ltp":0.0,"tv":0.0,"id":13095165}]}]}
{"op":"mcm","clk":"1005267499","pt":1580641767636,"mc":[{"id":"1.168230755","rc":[{"batb":[[0,2.52,132.28],[1,1.02,2],[2,1.01,1.01]],"ltp":0.0,"tv":0.0,"id":13095165},{"batb":[[0,3,30.29],[1,1.02,2],[2,1.01,1.01]],"ltp":0.0,"tv":0.0,"id":14343845}]}]}
{"op":"mcm","clk":"1005267539","pt":1580641767838,"mc":[{"id":"1.168230755","rc":[{"batb":[[0,3,115.86]],"ltp":0.0,"tv":0.0,"id":14343845}]}]}
{"op":"mcm","clk":"1005290338","pt":1580641888619,"mc":[{"id":"1.168230755","rc":[{"batb":[[0,2.54,30.29]],"ltp":0.0,"tv":0.0,"id":13095165}]}]}
{"op":"mcm","clk":"1005290439","pt":1580641889090,"mc":[{"id":"1.168230755","rc":[{"batb":[[0,2.62,98.04],[1,2.54,30.29],[2,1.02,2]],"ltp":0.0,"tv":0.0,"id":13095165},{"batb":[[0,3.05,30.29]],"ltp":0.0,"tv":0.0,"id":14343845}]}]}
{"op":"mcm","clk":"1005312137","pt":1580642011441,"mc":[{"id":"1.168230755","rc":[{"batb":[[0,2.74,93.52],[1,2.64,30.29]],"ltp":0.0,"tv":0.0,"id":13095165},{"batb":[[0,2.64,30.29]],"ltp":0.0,"tv":0.0,"id":14343845}]}]}
{"op":"mcm","clk":"1005312232","pt":1580642012076,"mc":[{"id":"1.168230755","rc":[{"batb":[[0,2.7,94.92],[1,2.64,30.29],[2,1.02,2]],"ltp":0.0,"tv":0.0,"id":14343845}]}]}
{"op":"mcm","clk":"1005333911","pt":1580642132640,"mc":[{"id":"1.168230755","rc":[{"batb":[[0,2.76,30.29],[1,2.74,93.52]],"ltp":0.0,"tv":0.0,"id":13095165}]}]}
{"op":"mcm","clk":"1005334079","pt":1580642133502,"mc":[{"id":"1.168230755","rc":[{"batb":[[0,2.8,91.48],[1,2.76,30.29]],"ltp":0.0,"tv":0.0,"id":13095165}]}]}
{"op":"mcm","clk":"1005334211","pt":1580642134348,"mc":[{"id":"1.168230755","rc":[{"batb":[[0,2.78,92.16],[1,2.72,30.29]],"ltp":0.0,"tv":0.0,"id":14343845}]}]}
{"op":"mcm","clk":"1005356091","pt":1580642254584,"mc":[{"id":"1.168230755","rc":[{"batb":[[0,2.82,30.29],[1,2.8,91.48]],"ltp":0.0,"tv":0.0,"id":13095165}]}]}
{"op":"mcm","clk":"1005356258","pt":1580642255486,"mc":[{"id":"1.168230755","rc":[{"batb":[[0,2.84,90.22],[1,2.82,30.29]],"ltp":0.0,"tv":0.0,"id":13095165},{"batb":[[0,2.8,30.29],[1,1.02,2],[2,1.01,1.01]],"ltp":0.0,"tv":0.0,"id":14343845}]}]}
{"op":"mcm","clk":"1005356439","pt":1580642256558,"mc":[{"id":"1.168230755","rc":[{"batb":[[0,2.84,90.22],[1,2.8,30.29],[2,1.02,2]],"ltp":0.0,"tv":0.0,"id":14343845}]}]}
{"op":"mcm","clk":"1005366977","pt":1580642311445,"mc":[{"id":"1.168230755","rc":[{"batl":[[0,4.6,324.16]],"ltp":0.0,"tv":0.0,"id":13095165}]}]}
{"op":"mcm","clk":"1005379527","pt":1580642376510,"mc":[{"id":"1.168230755","rc":[{"batb":[[0,2.86,30.29],[1,1.02,2],[2,1.01,1.01]],"ltp":0.0,"tv":0.0,"id":13095165},{"batb":[[0,2.86,30.29],[1,2.84,90.22]],"ltp":0.0,"tv":0.0,"id":14343845}]}]}
{"op":"mcm","clk":"1005379634","pt":1580642377049,"mc":[{"id":"1.168230755","rc":[{"batb":[[0,2.88,88.96],[1,2.86,30.29]],"ltp":0.0,"tv":0.0,"id":14343845}]}]}
{"op":"mcm","clk":"1005380097","pt":1580642379649,"mc":[{"id":"1.168230755","rc":[{"batb":[[0,4,64.07],[1,1.02,2],[2,1.01,1.01]],"batl":[[0,7.8,323.82]],"ltp":0.0,"tv":0.0,"id":13095168},{"batb":[[0,3.95,64.71],[1,1.02,2],[2,1.01,1.01]],"batl":[[0,7.8,321.42]],"ltp":0.0,"tv":0.0,"id":14343850}]}]}
{"op":"mcm","clk":"1005401523","pt":1580642497549,"mc":[{"id":"1.168230755","rc":[{"batb":[[0,1.02,2],[1,1.01,1.01],[2,1.01,0]],"ltp":0.0,"tv":0.0,"id":13095165}]}]}
{"op":"mcm","clk":"1005401738","pt":1580642498627,"mc":[{"id":"1.168230755","rc":[{"batb":[[0,2.6,98.59],[1,2.52,30.29],[2,1.02,2]],"ltp":0.0,"tv":0.0,"id":13095165},{"batb":[[0,2.92,87.69],[1,2.9,30.29]],"ltp":0.0,"tv":0.0,"id":14343845}]}]}
{"op":"mcm","clk":"1005424922","pt":1580642619614,"mc":[{"id":"1.168230755","rc":[{"batb":[[0,2.62,30.29],[1,1.02,2],[2,1.01,1.01]],"ltp":0.0,"tv":0.0,"id":13095165}]}]}
{"op":"mcm","clk":"1005425078","pt":1580642620479,"mc":[{"id":"1.168230755","rc":[{"batb":[[0,2.64,97.32],[1,2.62,30.29],[2,1.02,2]],"ltp":0.0,"tv":0.0,"id":13095165},{"batb":[[0,2.98,85.9],[1,2.94,30.29]],"ltp":0.0,"tv":0.0,"id":14343845}]}]}
{"op":"mcm","clk":"1005447918","pt":1580642741610,"mc":[{"id":"1.168230755","rc":[{"batb":[[0,2.74,93.52],[1,2.66,30.29]],"ltp":0.0,"tv":0.0,"id":13095165},{"batb":[[0,3,30.29],[1,2.98,85.9]],"ltp":0.0,"tv":0.0,"id":14343845}]}]}
{"op":"mcm","clk":"1005448116","pt":1580642742583,"mc":[{"id":"1.168230755","rc":[{"batb":[[0,3,115.86],[1,1.02,2],[2,1.01,1.01]],"ltp":0.0,"tv":0.0,"id":14343845}]}]}
{"op":"mcm","clk":"1005471174","pt":1580642862637,"mc":[{"id":"1.168230755","rc":[{"batb":[[1,1.02,2],[2,1.01,1.01]],"ltp":0.0,"tv":0.0,"id":13095165}]}]}
{"op":"mcm","clk":"1005471333","pt":1580642863522,"mc":[{"id":"1.168230755","rc":[{"batb":[[0,2.8,91.48],[1,2.76,30.29],[2,1.02,2]],"ltp":0.0,"tv":0.0,"id":13095165},{"batb":[[0,3.05,30.29]],"ltp":0.0,"tv":0.0,"id":14343845}]}]}
{"op":"mcm","clk":"1005493002","pt":1580642985485,"mc":[{"id":"1.168230755","rc":[{"batb":[[0,2.82,30.29],[1,1.02,2],[2,1.01,1.01]],"ltp":0.0,"tv":0.0,"id":13095165}]}]}
{"op":"mcm","clk":"1005493110","pt":1580642986077,"mc":[{"id":"1.168230755","rc":[{"batb":[[0,2.84,90.22],[1,2.82,30.29],[2,1.02,2]],"ltp":0.0,"tv":0.0,"id":13095165},{"batb":[[0,2.68,95.61],[1,2.64,30.29],[2,1.02,2]],"ltp":0.0,"tv":0.0,"id":14343845}]}]}
{"op":"mcm","clk":"1005515714","pt":1580643106464,"mc":[{"id":"1.168230755","rc":[{"batb":[[0,2.86,30.29],[1,1.02,2],[2,1.01,1.01]],"ltp":0.0,"tv":0.0,"id":13095165},{"batb":[[1,1.02,2],[2,1.01,1.01]],"ltp":0.0,"tv":0.0,"id":14343845}]}]}
{"op":"mcm","clk":"1005515935","pt":1580643107553,"mc":[{"id":"1.168230755","rc":[{"batb":[[0,2.76,92.98],[1,2.7,30.28],[2,1.02,2]],"ltp":0.0,"tv":0.0,"id":14343845}]}]}
{"op":"mcm","clk":"1005539313","pt":1580643228524,"mc":[{"id":"1.168230755","rc":[{"batb":[[0,2.54,101.12],[1,2.52,30.29],[2,1.02,2]],"ltp":0.0,"tv":0.0,"id":13095165},{"batb":[[1,1.02,2],[2,1.01,1.01]],"ltp":0.0,"tv":0.0,"id":14343845}]}]}
{"op":"mcm","clk":"1005539440","pt":1580643229222,"mc":[{"id":"1.168230755","rc":[{"batb":[[0,2.92,87.69],[1,2.78,30.29],[2,1.02,2]],"ltp":0.0,"tv":0.0,"id":14343845}]}]}
{"op":"mcm","clk":"1005563163","pt":1580643349283,"mc":[{"id":"1.168230755","rc":[{"batb":[[0,2.56,30.29],[1,2.54,101.12]],"ltp":0.0,"tv":0.0,"id":13095165}]}]}
{"op":"mcm","clk":"1005563316","pt":1580643350232,"mc":[{"id":"1.168230755","rc":[{"batb":[[0,2.68,95.86],[1,2.56,30.29]],"ltp":0.0,"tv":0.0,"id":13095165},{"batb":[[0,2.96,86.63],[1,2.94,30.29]],"ltp":0.0,"tv":0.0,"id":14343845}]}]}
{"op":"mcm","clk":"1005587765","pt":1580643470872,"mc":[{"id":"1.168230755","rc":[{"batb":[[1,1.02,2],[2,1.01,1.01]],"ltp":0.0,"tv":0.0,"id":13095165}]}]}
{"op":"mcm","clk":"1005687699","pt":1580643977597,"mc":[{"id":"1.168230755","rc":[{"batl":[[0,4.8,378.87]],"ltp":0.0,"tv":0.0,"id":14343845}]}]}
{"op":"mcm","clk":"1005801321","pt":1580644809586,"mc":[{"id":"1.168230755","rc":[{"batb":[[0,2.7,30.28]],"ltp":0.0,"tv":0.0,"id":13095165}]}]}
{"op":"mcm","clk":"1005801477","pt":1580644810485,"mc":[{"id":"1.168230755","rc":[{"batb":[[0,2.72,94.34],[1,2.7,30.28],[2,1.02,2]],"ltp":0.0,"tv":0.0,"id":13095165},{"batb":[[0,3,85.57],[1,2.98,30.29]],"ltp":0.0,"tv":0.0,"id":14343845}]}]}
{"op":"mcm","clk":"1005819545","pt":1580644931553,"mc":[{"id":"1.168230755","rc":[{"batb":[[0,2.74,30.29],[1,2.72,94.34]],"ltp":0.0,"tv":0.0,"id":13095165}]}]}
{"op":"mcm","clk":"1005819750","pt":1580644932536,"mc":[{"id":"1.168230755","rc":[{"batb":[[1,1.02,2],[2,1.01,1.01]],"ltp":0.0,"tv":0.0,"id":13095165},{"batb":[[1,1.02,2],[2,1.01,1.01]],"ltp":0.0,"tv":0.0,"id":14343845}]}]}
{"op":"mcm","clk":"1005819786","pt":1580644932741,"mc":[{"id":"1.168230755","rc":[{"batb":[[0,2.78,92.16],[1,2.74,30.29],[2,1.02,2]],"ltp":0.0,"tv":0.0,"id":13095165}]}]}
{"op":"mcm","clk":"1005841558","pt":1580645053293,"mc":[{"id":"1.168230755","rc":[{"batb":[[0,2.82,91.03],[1,2.8,30.29]],"ltp":0.0,"tv":0.0,"id":13095165}]}]}
{"op":"mcm","clk":"1005864884","pt":1580645174600,"mc":[{"id":"1.168230755","rc":[{"batb":[[0,2.84,30.29],[1,2.82,91.03]],"ltp":0.0,"tv":0.0,"id":13095165}]}]}
{"op":"mcm","clk":"1005864978","pt":1580645174991,"mc":[{"id":"1.168230755","rc":[{"batb":[[0,2.84,120.51],[1,1.02,2],[2,1.01,1.01]],"ltp":0.0,"tv":0.0,"id":13095165}]}]}
{"op":"mcm","clk":"1005888905","pt":1580645297244,"mc":[{"id":"1.168230755","rc":[{"batb":[[0,2.86,30.29]],"ltp":0.0,"tv":0.0,"id":13095165}]}]}
{"op":"mcm","clk":"1005912750","pt":1580645418240,"mc":[{"id":"1.168230755","rc":[{"batb":[[0,2.6,98.59],[1,2.58,30.29],[2,1.02,2]],"ltp":0.0,"tv":0.0,"id":13095165}]}]}
{"op":"mcm","clk":"1005934668","pt":1580645539482,"mc":[{"id":"1.168230755","rc":[{"batb":[[0,2.62,30.29],[1,2.6,98.59]],"ltp":0.0,"tv":0.0,"id":13095165}]}]}
{"op":"mcm","clk":"1005934764","pt":1580645539969,"mc":[{"id":"1.168230755","rc":[{"batb":[[0,2.72,94.34],[1,2.62,30.29]],"ltp":0.0,"tv":0.0,"id":13095165}]}]}
{"op":"mcm","clk":"1005956840","pt":1580645661635,"mc":[{"id":"1.168230755","rc":[{"batb":[[0,2.78,92.16],[1,2.74,30.29]],"ltp":0.0,"tv":0.0,"id":13095165}]}]}
{"op":"mcm","clk":"1005978294","pt":1580645783300,"mc":[{"id":"1.168230755","rc":[{"batb":[[0,2.82,91.03],[1,2.8,30.29]],"ltp":0.0,"tv":0.0,"id":13095165}]}]}
{"op":"mcm","clk":"1005999265","pt":1580645904527,"mc":[{"id":"1.168230755","rc":[{"batb":[[0,2.84,30.29],[1,2.82,91.03]],"ltp":0.0,"tv":0.0,"id":13095165}]}]}
{"op":"mcm","clk":"1005999338","pt":1580645904954,"mc":[{"id":"1.168230755","rc":[{"batb":[[0,2.84,120.51],[1,1.02,2],[2,1.01,1.01]],"ltp":0.0,"tv":0.0,"id":13095165}]}]}
{"op":"mcm","clk":"1006011834","pt":1580645979552,"mc":[{"id":"1.168230755","rc":[{"batb":[[0,1.02,2],[1,1.01,1.01],[2,1.01,0]],"ltp":0.0,"tv":0.0,"id":13095168},{"batb":[[0,1.02,2],[1,1.01,1.01],[2,1.01,0]],"ltp":0.0,"tv":0.0,"id":14343850}]}]}
{"op":"mcm","clk":"1006011931","pt":1580645980142,"mc":[{"id":"1.168230755","rc":[{"batl":[[0,9,280.94]],"ltp":0.0,"tv":0.0,"id":13095168},{"batl":[[0,8.6,291.56]],"ltp":0.0,"tv":0.0,"id":14343850}]}]}
{"op":"mcm","clk":"1006020099","pt":1580646026484,"mc":[{"id":"1.168230755","rc":[{"batb":[[0,2.86,30.29]],"batl":[[0,4.1,363.75]],"ltp":0.0,"tv":0.0,"id":13095165}]}]}
{"op":"mcm","clk":"1006042083","pt":1580646148559,"mc":[{"id":"1.168230755","rc":[{"batb":[[0,2.72,94.34],[1,2.58,30.29],[2,1.02,2]],"ltp":0.0,"tv":0.0,"id":13095165}]}]}
{"op":"mcm","clk":"1006062971","pt":1580646269506,"mc":[{"id":"1.168230755","rc":[{"batb":[[0,2.74,30.29],[1,2.72,94.34]],"ltp":0.0,"tv":0.0,"id":13095165}]}]}
{"op":"mcm","clk":"1006063031","pt":1580646269927,"mc":[{"id":"1.168230755","rc":[{"batb":[[0,2.82,91.03],[1,2.74,30.29]],"ltp":0.0,"tv":0.0,"id":13095165}]}]}
{"op":"mcm","clk":"1006084323","pt":1580646391534,"mc":[{"id":"1.168230755","rc":[{"batb":[[0,2.84,30.29],[1,1.02,2],[2,1.01,1.01]],"ltp":0.0,"tv":0.0,"id":13095165}]}]}
{"op":"mcm","clk":"1006084363","pt":1580646391704,"mc":[{"id":"1.168230755","rc":[{"batb":[[0,2.84,120.51]],"ltp":0.0,"tv":0.0,"id":13095165}]}]}
{"op":"mcm","clk":"1006104879","pt":1580646513207,"mc":[{"id":"1.168230755","rc":[{"batb":[[0,2.86,30.29]],"ltp":0.0,"tv":0.0,"id":13095165}]}]}
{"op":"mcm","clk":"1006117560","pt":1580646587048,"mc":[{"id":"1.168230755","rc":[{"batb":[[0,2.68,95.61]],"ltp":0.0,"tv":0.0,"id":14343845}]}]}
{"op":"mcm","clk":"1006126124","pt":1580646634506,"mc":[{"id":"1.168230755","rc":[{"batb":[[0,2.58,30.29]],"ltp":0.0,"tv":0.0,"id":13095165}]}]}
{"op":"mcm","clk":"1006126283","pt":1580646635420,"mc":[{"id":"1.168230755","rc":[{"batb":[[0,2.74,93.52],[1,2.58,30.29],[2,1.02,2]],"ltp":0.0,"tv":0.0,"id":13095165},{"batb":[[0,2.9,88.36],[1,2.7,30.28],[2,1.02,2]],"ltp":0.0,"tv":0.0,"id":14343845}]}]}
{"op":"mcm","clk":"1006148063","pt":1580646758647,"mc":[{"id":"1.168230755","rc":[{"batb":[[0,2.78,92.16],[1,2.76,30.29]],"ltp":0.0,"tv":0.0,"id":13095165}]}]}
{"op":"mcm","clk":"1006148188","pt":1580646759424,"mc":[{"id":"1.168230755","rc":[{"batb":[[0,2.92,30.29],[1,2.9,88.36]],"ltp":0.0,"tv":0.0,"id":14343845}]}]}
{"op":"mcm","clk":"1006148286","pt":1580646759959,"mc":[{"id":"1.168230755","rc":[{"batb":[[0,2.94,87.09],[1,2.92,30.29]],"ltp":0.0,"tv":0.0,"id":14343845}]}]}
{"op":"mcm","clk":"1006170140","pt":1580646879496,"mc":[{"id":"1.168230755","rc":[{"batb":[[0,2.82,91.03],[1,2.8,30.29]],"ltp":0.0,"tv":0.0,"id":13095165},{"batb":[[0,2.96,30.29],[1,2.94,87.09]],"ltp":0.0,"tv":0.0,"id":14343845}]}]}
{"op":"mcm","clk":"1006170238","pt":1580646879990,"mc":[{"id":"1.168230755","rc":[{"batb":[[0,2.98,85.9],[1,2.96,30.29]],"ltp":0.0,"tv":0.0,"id":14343845}]}]}
{"op":"mcm","clk":"1006193383","pt":1580647000613,"mc":[{"id":"1.168230755","rc":[{"batb":[[0,2.84,30.29],[1,2.82,91.03]],"ltp":0.0,"tv":0.0,"id":13095165}]}]}
{"op":"mcm","clk":"1006193574","pt":1580647001469,"mc":[{"id":"1.168230755","rc":[{"batb":[[0,2.84,120.51],[1,1.02,2],[2,1.01,1.01]],"ltp":0.0,"tv":0.0,"id":13095165},{"batb":[[0,3,30.29],[1,1.02,2],[2,1.01,1.01]],"ltp":0.0,"tv":0.0,"id":14343845}]}]}
{"op":"mcm","clk":"1006193625","pt":1580647001680,"mc":[{"id":"1.168230755","rc":[{"batb":[[0,3,115.86]],"ltp":0.0,"tv":0.0,"id":14343845}]}]}
{"op":"mcm","clk":"1006217716","pt":1580647122302,"mc":[{"id":"1.168230755","rc":[{"batb":[[0,2.86,30.29],[1,2.84,90.22],[2,1.02,2]],"ltp":0.0,"tv":0.0,"id":13095165}]}]}
{"op":"mcm","clk":"1006217825","pt":1580647122894,"mc":[{"id":"1.168230755","rc":[{"batb":[[1,1.02,2],[2,1.01,1.01]],"ltp":0.0,"tv":0.0,"id":13095165},{"batb":[[0,3,85.57]],"ltp":0.0,"tv":0.0,"id":14343845}]}]}
{"op":"mcm","clk":"1006242661","pt":1580647244530,"mc":[{"id":"1.168230755","rc":[{"batb":[[0,2.8,91.48],[1,2.58,30.29],[2,1.02,2]],"ltp":0.0,"tv":0.0,"id":13095165}]}]}
{"op":"mcm","clk":"1006266760","pt":1580647365580,"mc":[{"id":"1.168230755","rc":[{"batb":[[1,1.02,2],[2,1.01,1.01]],"ltp":0.0,"tv":0.0,"id":13095165}]}]}
{"op":"mcm","clk":"1006266857","pt":1580647366060,"mc":[{"id":"1.168230755","rc":[{"batb":[[0,2.84,90.22],[1,2.82,30.29],[2,1.02,2]],"ltp":0.0,"tv":0.0,"id":13095165}]}]}
{"op":"mcm","clk":"1006433789","pt":1580648460622,"mc":[{"id":"1.168230755","rc":[{"batb":[[1,1.02,2],[2,1.01,1.01]],"ltp":0.0,"tv":0.0,"id":13095165}]}]}
{"op":"mcm","clk":"1006433822","pt":1580648460946,"mc":[{"id":"1.168230755","rc":[{"batb":[[0,2.86,30.29]],"ltp":0.0,"tv":0.0,"id":13095165}]}]}
{"op":"mcm","clk":"1006436834","pt":1580648482484,"mc":[{"id":"1.168230755","rc":[{"batl":[[0,4.9,371.15]],"ltp":0.0,"tv":0.0,"id":14343845}]}]}
{"op":"mcm","clk":"1006449971","pt":1580648582403,"mc":[{"id":"1.168230755","rc":[{"batb":[[0,2.58,30.29]],"ltp":0.0,"tv":0.0,"id":13095165}]}]}
{"op":"mcm","clk":"1006450071","pt":1580648583097,"mc":[{"id":"1.168230755","rc":[{"batb":[[0,2.62,98.04],[1,2.58,30.29],[2,1.02,2]],"ltp":0.0,"tv":0.0,"id":13095165}]}]}
{"op":"mcm","clk":"1006466268","pt":1580648704354,"mc":[{"id":"1.168230755","rc":[{"batb":[[0,2.7,94.92],[1,2.64,30.29]],"ltp":0.0,"tv":0.0,"id":13095165}]}]}
{"op":"mcm","clk":"1006483798","pt":1580648825623,"mc":[{"id":"1.168230755","rc":[{"batb":[[1,1.02,2],[2,1.01,1.01]],"ltp":0.0,"tv":0.0,"id":13095165}]}]}
{"op":"mcm","clk":"1006483895","pt":1580648826262,"mc":[{"id":"1.168230755","rc":[{"batb":[[0,2.74,93.52],[1,2.72,30.29],[2,1.02,2]],"ltp":0.0,"tv":0.0,"id":13095165}]}]}
{"op":"mcm","clk":"1006501307","pt":1580648947628,"mc":[{"id":"1.168230755","rc":[{"batb":[[0,2.76,30.29],[1,1.02,2],[2,1.01,1.01]],"ltp":0.0,"tv":0.0,"id":13095165}]}]}
{"op":"mcm","clk":"1006501335","pt":1580648947831,"mc":[{"id":"1.168230755","rc":[{"batb":[[0,2.78,92.16],[1,2.76,30.29],[2,1.02,2]],"ltp":0.0,"tv":0.0,"id":13095165}]}]}
{"op":"mcm","clk":"1006519099","pt":1580649069591,"mc":[{"id":"1.168230755","rc":[{"batb":[[0,2.8,30.29],[1,2.78,92.16]],"ltp":0.0,"tv":0.0,"id":13095165}]}]}
{"op":"mcm","clk":"1006519186","pt":1580649070179,"mc":[{"id":"1.168230755","rc":[{"batb":[[0,2.82,91.03],[1,2.8,30.29]],"ltp":0.0,"tv":0.0,"id":13095165}]}]}
{"op":"mcm","clk":"1006537750","pt":1580649191332,"mc":[{"id":"1.168230755","rc":[{"batb":[[0,2.84,120.51],[1,1.02,2],[2,1.01,1.01]],"ltp":0.0,"tv":0.0,"id":13095165}]}]}
{"op":"mcm","clk":"1006556938","pt":1580649312374,"mc":[{"id":"1.168230755","rc":[{"batb":[[0,2.86,30.29],[1,2.84,90.22],[2,1.02,2]],"ltp":0.0,"tv":0.0,"id":13095165}]}]}
{"op":"mcm","clk":"1006556978","pt":1580649312670,"mc":[{"id":"1.168230755","rc":[{"batb":[[1,1.02,2],[2,1.01,1.01]],"ltp":0.0,"tv":0.0,"id":13095165}]}]}
{"op":"mcm","clk":"1006575161","pt":1580649434515,"mc":[{"id":"1.168230755","rc":[{"batb":[[0,2.58,30.29],[1,2.48,103.51],[2,1.02,2]],"ltp":0.0,"tv":0.0,"id":13095165}]}]}
{"op":"mcm","clk":"1006575204","pt":1580649434838,"mc":[{"id":"1.168230755","rc":[{"batb":[[0,2.72,94.34],[1,2.58,30.29]],"ltp":0.0,"tv":0.0,"id":13095165}]}]}
{"op":"mcm","clk":"1006592277","pt":1580649555635,"mc":[{"id":"1.168230755","rc":[{"batb":[[1,1.02,2],[2,1.01,1.01]],"ltp":0.0,"tv":0.0,"id":13095165}]}]}
{"op":"mcm","clk":"1006592343","pt":1580649556062,"mc":[{"id":"1.168230755","rc":[{"batb":[[0,2.76,92.98],[1,2.74,30.29],[2,1.02,2]],"ltp":0.0,"tv":0.0,"id":13095165}]}]}
{"op":"mcm","clk":"1006595959","pt":1580649580607,"mc":[{"id":"1.168230755","rc":[{"batl":[[0,8.8,287.07]],"ltp":0.0,"tv":0.0,"id":13095168},{"batl":[[0,10.5,238.85]],"ltp":0.0,"tv":0.0,"id":14343850}]}]}
{"op":"mcm","clk":"1006596050","pt":1580649581201,"mc":[{"id":"1.168230755","rc":[{"batb":[[0,3.9,65.56],[1,1.02,2],[2,1.01,1.01]],"ltp":0.0,"tv":0.0,"id":13095168},{"batb":[[0,3.5,73.28],[1,1.02,2],[2,1.01,1.01]],"ltp":0.0,"tv":0.0,"id":14343850}]}]}
{"op":"mcm","clk":"1006609792","pt":1580649677417,"mc":[{"id":"1.168230755","rc":[{"batb":[[0,2.78,30.29],[1,2.76,92.98]],"ltp":0.0,"tv":0.0,"id":13095165}]}]}
{"op":"mcm","clk":"1006609873","pt":1580649677895,"mc":[{"id":"1.168230755","rc":[{"batb":[[0,2.8,91.48],[1,2.78,30.29]],"batl":[[0,4.4,338.84]],"ltp":0.0,"tv":0.0,"id":13095165}]}]}
{"op":"mcm","clk":"1006626841","pt":1580649799599,"mc":[{"id":"1.168230755","rc":[{"batb":[[0,2.84,90.22],[1,2.82,30.29]],"ltp":0.0,"tv":0.0,"id":13095165}]}]}
{"op":"mcm","clk":"1006644985","pt":1580649920964,"mc":[{"id":"1.168230755","rc":[{"batb":[[0,2.86,30.29],[1,1.02,2],[2,1.01,1.01]],"ltp":0.0,"tv":0.0,"id":13095165}]}]}
{"op":"mcm","clk":"1006662715","pt":1580650042402,"mc":[{"id":"1.168230755","rc":[{"batb":[[0,2.58,30.29]],"ltp":0.0,"tv":0.0,"id":13095165}]}]}
{"op":"mcm","clk":"1006662758","pt":1580650042715,"mc":[{"id":"1.168230755","rc":[{"batb":[[0,2.74,93.52],[1,2.58,30.29],[2,1.02,2]],"ltp":0.0,"tv":0.0,"id":13095165}]}]}
{"op":"mcm","clk":"1006679618","pt":1580650164463,"mc":[{"id":"1.168230755","rc":[{"batb":[[0,2.78,92.16],[1,2.76,30.29]],"ltp":0.0,"tv":0.0,"id":13095165}]}]}
{"op":"mcm","clk":"1006682793","pt":1580650188178,"mc":[{"id":"1.168230755","rc":[{"batb":[[0,2.52,101.99]],"ltp":0.0,"tv":0.0,"id":14343845}]}]}
{"op":"mcm","clk":"1006696958","pt":1580650285634,"mc":[{"id":"1.168230755","rc":[{"batb":[[1,1.02,2],[2,1.01,1.01]],"ltp":0.0,"tv":0.0,"id":13095165}]}]}
{"op":"mcm","clk":"1006697103","pt":1580650286539,"mc":[{"id":"1.168230755","rc":[{"batb":[[0,2.82,91.03],[1,2.8,30.29],[2,1.02,2]],"ltp":0.0,"tv":0.0,"id":13095165},{"batb":[[0,2.58,30.29]],"ltp":0.0,"tv":0.0,"id":14343845}]}]}
{"op":"mcm","clk":"1006697137","pt":1580650286722,"mc":[{"id":"1.168230755","rc":[{"batb":[[0,2.82,91.03],[1,2.58,30.29],[2,1.02,2]],"ltp":0.0,"tv":0.0,"id":14343845}]}]}
{"op":"mcm","clk":"1006714774","pt":1580650407592,"mc":[{"id":"1.168230755","rc":[{"batb":[[1,1.02,2],[2,1.01,1.01]],"ltp":0.0,"tv":0.0,"id":13095165}]}]}
{"op":"mcm","clk":"1006714903","pt":1580650408550,"mc":[{"id":"1.168230755","rc":[{"batb":[[0,2.84,120.51]],"ltp":0.0,"tv":0.0,"id":13095165},{"batb":[[0,2.84,30.29],[1,2.82,91.03]],"ltp":0.0,"tv":0.0,"id":14343845}]}]}
{"op":"mcm","clk":"1006714951","pt":1580650408966,"mc":[{"id":"1.168230755","rc":[{"batb":[[0,2.94,87.09],[1,2.84,30.29]],"ltp":0.0,"tv":0.0,"id":14343845}]}]}
{"op":"mcm","clk":"1006731889","pt":1580650529235,"mc":[{"id":"1.168230755","rc":[{"batb":[[0,2.86,30.29],[1,2.84,90.22],[2,1.02,2]],"ltp":0.0,"tv":0.0,"id":13095165}]}]}
{"op":"mcm","clk":"1006731980","pt":1580650529816,"mc":[{"id":"1.168230755","rc":[{"batb":[[0,2.96,30.29],[1,2.94,87.09]],"ltp":0.0,"tv":0.0,"id":14343845}]}]}
{"op":"mcm","clk":"1006732352","pt":1580650532331,"mc":[{"id":"1.168230755","rc":[{"batb":[[1,1.02,2],[2,1.01,1.01]],"ltp":0.0,"tv":0.0,"id":13095165},{"batb":[[1,1.02,2],[2,1.01,1.01]],"ltp":0.0,"tv":0.0,"id":14343845}]}]}
{"op":"mcm","clk":"1006732407","pt":1580650532702,"mc":[{"id":"1.168230755","rc":[{"batb":[[0,2.98,85.9],[1,2.96,30.29],[2,1.02,2]],"ltp":0.0,"tv":0.0,"id":14343845}]}]}
{"op":"mcm","clk":"1006749698","pt":1580650651597,"mc":[{"id":"1.168230755","rc":[{"batb":[[0,2.56,30.29]],"ltp":0.0,"tv":0.0,"id":13095165}]}]}
{"op":"mcm","clk":"1006749816","pt":1580650652362,"mc":[{"id":"1.168230755","rc":[{"batb":[[0,2.6,98.59],[1,2.56,30.29],[2,1.02,2]],"ltp":0.0,"tv":0.0,"id":13095165},{"batb":[[0,3,115.86],[1,1.02,2],[2,1.01,1.01]],"ltp":0.0,"tv":0.0,"id":14343845}]}]}
{"op":"mcm","clk":"1006767871","pt":1580650772647,"mc":[{"id":"1.168230755","rc":[{"batb":[[0,2.62,30.29],[1,1.02,2],[2,1.01,1.01]],"ltp":0.0,"tv":0.0,"id":13095165}]}]}
{"op":"mcm","clk":"1006767920","pt":1580650772914,"mc":[{"id":"1.168230755","rc":[{"batb":[[0,2.74,93.52],[1,2.62,30.29],[2,1.02,2]],"ltp":0.0,"tv":0.0,"id":13095165},{"batb":[[0,3,85.57]],"ltp":0.0,"tv":0.0,"id":14343845}]}]}
{"op":"mcm","clk":"1006786280","pt":1580650894567,"mc":[{"id":"1.168230755","rc":[{"batb":[[0,2.78,92.16],[1,2.76,30.29]],"ltp":0.0,"tv":0.0,"id":13095165}]}]}
{"op":"mcm","clk":"1006805633","pt":1580651016340,"mc":[{"id":"1.168230755","rc":[{"batb":[[0,2.82,91.03],[1,2.8,30.29]],"ltp":0.0,"tv":0.0,"id":13095165}]}]}
{"op":"mcm","clk":"1006956616","pt":1580652112611,"mc":[{"id":"1.168230755","rc":[{"batb":[[0,2.84,30.29],[1,1.02,2],[2,1.01,1.01]],"ltp":0.0,"tv":0.0,"id":13095165}]}]}
{"op":"mcm","clk":"1006956647","pt":1580652112787,"mc":[{"id":"1.168230755","rc":[{"batb":[[0,2.84,120.51]],"ltp":0.0,"tv":0.0,"id":13095165}]}]}
{"op":"mcm","clk":"1006975689","pt":1580652233627,"mc":[{"id":"1.168230755","rc":[{"batb":[[0,2.86,30.29],[1,2.84,90.22],[2,1.02,2]],"ltp":0.0,"tv":0.0,"id":13095165}]}]}
{"op":"mcm","clk":"1006975784","pt":1580652234159,"mc":[{"id":"1.168230755","rc":[{"batb":[[1,1.02,2],[2,1.01,1.01]],"ltp":0.0,"tv":0.0,"id":13095165}]}]}
{"op":"mcm","clk":"1006996564","pt":1580652355321,"mc":[{"id":"1.168230755","rc":[{"batb":[[0,2.56,30.29]],"ltp":0.0,"tv":0.0,"id":13095165}]}]}
{"op":"mcm","clk":"1006996640","pt":1580652355714,"mc":[{"id":"1.168230755","rc":[{"batb":[[0,2.58,99.56],[1,2.56,30.29],[2,1.02,2]],"ltp":0.0,"tv":0.0,"id":13095165}]}]}
{"op":"mcm","clk":"1007018212","pt":1580652477513,"mc":[{"id":"1.168230755","rc":[{"batb":[[0,2.74,93.52],[1,2.6,30.29]],"ltp":0.0,"tv":0.0,"id":13095165}]}]}
{"op":"mcm","clk":"1007040760","pt":1580652598625,"mc":[{"id":"1.168230755","rc":[{"batb":[[1,1.02,2],[2,1.01,1.01]],"ltp":0.0,"tv":0.0,"id":13095165}]}]}
{"op":"mcm","clk":"1007040864","pt":1580652599342,"mc":[{"id":"1.168230755","rc":[{"batb":[[0,2.82,91.03],[1,2.76,30.29],[2,1.02,2]],"ltp":0.0,"tv":0.0,"id":13095165}]}]}
{"op":"mcm","clk":"1007044609","pt":1580652620751,"mc":[{"id":"1.168230755","rc":[{"batl":[[0,4.4,58.64]],"ltp":0.0,"tv":0.0,"id":13095165}]}]}
{"op":"mcm","clk":"1007054652","pt":1580652678102,"mc":[{"id":"1.168230755","rc":[{"batl":[[0,4.4,353.34]],"ltp":0.0,"tv":0.0,"id":13095165}]}]}
{"op":"mcm","clk":"1007062137","pt":1580652720607,"mc":[{"id":"1.168230755","rc":[{"batb":[[0,2.84,120.51],[1,1.02,2],[2,1.01,1.01]],"ltp":0.0,"tv":0.0,"id":13095165}]}]}
{"op":"mcm","clk":"1007084388","pt":1580652842436,"mc":[{"id":"1.168230755","rc":[{"batb":[[0,2.84,90.22]],"ltp":0.0,"tv":0.0,"id":13095165}]}]}
{"op":"mcm","clk":"1007084563","pt":1580652843215,"mc":[{"id":"1.168230755","rc":[{"batb":[[0,2.86,30.29]],"ltp":0.0,"tv":0.0,"id":13095165}]}]}
{"op":"mcm","clk":"1007106036","pt":1580652963554,"mc":[{"id":"1.168230755","rc":[{"batb":[[0,1.02,2],[1,1.01,1.01],[2,1.01,0]],"ltp":0.0,"tv":0.0,"id":13095165}]}]}
{"op":"mcm","clk":"1007106158","pt":1580652964231,"mc":[{"id":"1.168230755","rc":[{"batb":[[0,2.68,95.86],[1,2.56,30.29],[2,1.02,2]],"ltp":0.0,"tv":0.0,"id":13095165}]}]}
{"op":"mcm","clk":"1007126796","pt":1580653085231,"mc":[{"id":"1.168230755","rc":[{"batb":[[1,1.02,2],[2,1.01,1.01]],"ltp":0.0,"tv":0.0,"id":13095165}]}]}
{"op":"mcm","clk":"1007127046","pt":1580653086606,"mc":[{"id":"1.168230755","rc":[{"batb":[[0,2.76,92.98],[1,2.7,30.28],[2,1.02,2]],"ltp":0.0,"tv":0.0,"id":13095165}]}]}
{"op":"mcm","clk":"1007141596","pt":1580653181172,"mc":[{"id":"1.168230755","rc":[{"batb":[[0,1.02,2],[1,1.01,1.01],[2,1.01,0]],"ltp":0.0,"tv":0.0,"id":13095168},{"batb":[[0,1.02,2],[1,1.01,1.01],[2,1.01,0]],"ltp":0.0,"tv":0.0,"id":14343850}]}]}
{"op":"mcm","clk":"1007145947","pt":1580653207406,"mc":[{"id":"1.168230755","rc":[{"batb":[[0,2.78,30.29],[1,2.76,92.98]],"ltp":0.0,"tv":0.0,"id":13095165}]}]}
{"op":"mcm","clk":"1007146023","pt":1580653207830,"mc":[{"id":"1.168230755","rc":[{"batb":[[0,2.8,91.48],[1,2.78,30.29]],"ltp":0.0,"tv":0.0,"id":13095165}]}]}
{"op":"mcm","clk":"1007157857","pt":1580653278712,"mc":[{"id":"1.168230755","rc":[{"batl":[[0,4.3,361.52]],"ltp":0.0,"tv":0.0,"id":13095165}]}]}
{"op":"mcm","clk":"1007166573","pt":1580653328596,"mc":[{"id":"1.168230755","rc":[{"batb":[[1,1.02,2],[2,1.01,1.01]],"ltp":0.0,"tv":0.0,"id":13095165}]}]}
{"op":"mcm","clk":"1007166677","pt":1580653329179,"mc":[{"id":"1.168230755","rc":[{"batb":[[0,2.84,90.22],[1,2.82,30.29],[2,1.02,2]],"ltp":0.0,"tv":0.0,"id":13095165}]}]}
{"op":"mcm","clk":"1007185650","pt":1580653450355,"mc":[{"id":"1.168230755","rc":[{"batb":[[0,2.86,30.29],[1,2.84,90.22]],"ltp":0.0,"tv":0.0,"id":13095165}]}]}
{"op":"mcm","clk":"1007185699","pt":1580653450657,"mc":[{"id":"1.168230755","rc":[{"batb":[[1,1.02,2],[2,1.01,1.01]],"ltp":0.0,"tv":0.0,"id":13095165}]}]}
{"op":"mcm","clk":"1007204294","pt":1580653573290,"mc":[{"id":"1.168230755","rc":[{"batb":[[0,2.56,30.29]],"ltp":0.0,"tv":0.0,"id":13095165}]}]}
{"op":"mcm","clk":"1007204375","pt":1580653573997,"mc":[{"id":"1.168230755","rc":[{"batb":[[0,2.6,98.59],[1,2.56,30.29],[2,1.02,2]],"ltp":0.0,"tv":0.0,"id":13095165}]}]}
{"op":"mcm","clk":"1007223255","pt":1580653693637,"mc":[{"id":"1.168230755","rc":[{"batb":[[0,2.62,30.29],[1,2.6,98.59]],"ltp":0.0,"tv":0.0,"id":13095165}]}]}
{"op":"mcm","clk":"1007223342","pt":1580653694175,"mc":[{"id":"1.168230755","rc":[{"batb":[[0,2.72,94.34],[1,2.62,30.29]],"ltp":0.0,"tv":0.0,"id":13095165}]}]}
{"op":"mcm","clk":"1007239144","pt":1580653788563,"mc":[{"id":"1.168230755","rc":[{"batb":[[0,1.02,2],[1,1.01,1.01],[2,1.01,0]],"ltp":0.0,"tv":0.0,"id":14343845}]}]}
{"op":"mcm","clk":"1007239259","pt":1580653789387,"mc":[{"id":"1.168230755","rc":[{"batb":[[0,2.54,101.12],[1,1.02,2],[2,1.01,1.01]],"batl":[[0,4.8,378.87]],"ltp":0.0,"tv":0.0,"id":14343845}]}]}
{"op":"mcm","clk":"1007243513","pt":1580653815427,"mc":[{"id":"1.168230755","rc":[{"batb":[[0,2.74,30.29],[1,2.72,94.34]],"ltp":0.0,"tv":0.0,"id":13095165}]}]}
{"op":"mcm","clk":"1007243685","pt":1580653816403,"mc":[{"id":"1.168230755","rc":[{"batb":[[0,2.76,92.98],[1,2.74,30.29]],"ltp":0.0,"tv":0.0,"id":13095165},{"batb":[[0,2.76,92.98],[1,2.6,30.29],[2,1.02,2]],"ltp":0.0,"tv":0.0,"id":14343845}]}]}
{"op":"mcm","clk":"1007263273","pt":1580653937484,"mc":[{"id":"1.168230755","rc":[{"batb":[[0,2.78,30.29],[1,1.02,2],[2,1.01,1.01]],"ltp":0.0,"tv":0.0,"id":13095165}]}]}
{"op":"mcm","clk":"1007263368","pt":1580653938180,"mc":[{"id":"1.168230755","rc":[{"batb":[[0,2.8,91.48],[1,2.78,30.29],[2,1.02,2]],"ltp":0.0,"tv":0.0,"id":13095165},{"batb":[[0,2.8,91.48],[1,2.78,30.29]],"ltp":0.0,"tv":0.0,"id":14343845}]}]}
{"op":"mcm","clk":"1007283254","pt":1580654059643,"mc":[{"id":"1.168230755","rc":[{"batb":[[0,2.84,90.22],[1,2.82,30.29]],"ltp":0.0,"tv":0.0,"id":13095165},{"batb":[[0,2.82,30.29],[1,1.02,2],[2,1.01,1.01]],"ltp":0.0,"tv":0.0,"id":14343845}]}]}
{"op":"mcm","clk":"1007283289","pt":1580654059857,"mc":[{"id":"1.168230755","rc":[{"batb":[[0,2.92,87.69],[1,2.82,30.29],[2,1.02,2]],"ltp":0.0,"tv":0.0,"id":14343845}]}]}
{"op":"mcm","clk":"1007303924","pt":1580654180450,"mc":[{"id":"1.168230755","rc":[{"batb":[[0,2.86,30.29],[1,2.84,90.22]],"ltp":0.0,"tv":0.0,"id":13095165}]}]}
{"op":"mcm","clk":"1007304122","pt":1580654181581,"mc":[{"id":"1.168230755","rc":[{"batb":[[1,1.02,2],[2,1.01,1.01]],"ltp":0.0,"tv":0.0,"id":13095165},{"batb":[[0,2.94,30.29],[1,1.02,2],[2,1.01,1.01]],"ltp":0.0,"tv":0.0,"id":14343845}]}]}
{"op":"mcm","clk":"1007304162","pt":1580654181738,"mc":[{"id":"1.168230755","rc":[{"batb":[[0,2.96,86.63],[1,2.94,30.29],[2,1.02,2]],"ltp":0.0,"tv":0.0,"id":14343845}]}]}
{"op":"mcm","clk":"1007304951","pt":1580654186347,"mc":[{"id":"1.168230755","rc":[{"batb":[[0,2.86,119.97]],"ltp":0.0,"tv":0.0,"id":13095165},{"batb":[[0,3.8,67.23],[1,1.02,2],[2,1.01,1.01]],"batl":[[0,8.4,298.72]],"ltp":0.0,"tv":0.0,"id":14343850},{"batl":[[0,4.8,53.77]],"ltp":0.0,"tv":0.0,"id":14343845}]}]}
{"op":"mcm","clk":"1007325504","pt":1580654302520,"mc":[{"id":"1.168230755","rc":[{"batb":[[0,2.88,30.28],[1,2.86,89.68],[2,1.02,2]],"ltp":0.0,"tv":0.0,"id":13095165}]}]}
{"op":"mcm","clk":"1007325682","pt":1580654303498,"mc":[{"id":"1.168230755","rc":[{"batb":[[1,1.02,2],[2,1.01,1.01]],"ltp":0.0,"tv":0.0,"id":13095165},{"batb":[[0,2.98,30.29],[1,2.96,86.63]],"ltp":0.0,"tv":0.0,"id":14343845}]}]}
{"op":"mcm","clk":"1007325804","pt":1580654304324,"mc":[{"id":"1.168230755","rc":[{"batb":[[0,3,85.57],[1,2.98,30.29]],"ltp":0.0,"tv":0.0,"id":14343845}]}]}
{"op":"mcm","clk":"1007339279","pt":1580654389017,"mc":[{"id":"1.168230755","rc":[{"batl":[[0,4.8,364.67]],"ltp":0.0,"tv":0.0,"id":14343845}]}]}
{"op":"mcm","clk":"1007344754","pt":1580654424466,"mc":[{"id":"1.168230755","rc":[{"batb":[[0,2.8,91.48],[1,2.54,30.29],[2,1.02,2]],"ltp":0.0,"tv":0.0,"id":13095165}]}]}
{"op":"mcm","clk":"1007344835","pt":1580654425061,"mc":[{"id":"1.168230755","rc":[{"batb":[[1,1.02,2],[2,1.01,1.01]],"ltp":0.0,"tv":0.0,"id":14343845}]}]}
{"op":"mcm","clk":"1007363687","pt":1580654545380,"mc":[{"id":"1.168230755","rc":[{"batb":[[0,2.82,30.29],[1,2.8,91.48]],"ltp":0.0,"tv":0.0,"id":13095165}]}]}
{"op":"mcm","clk":"1007363778","pt":1580654545886,"mc":[{"id":"1.168230755","rc":[{"batb":[[0,2.84,90.22],[1,2.82,30.29]],"ltp":0.0,"tv":0.0,"id":13095165}]}]}
{"op":"mcm","clk":"1007383005","pt":1580654667239,"mc":[{"id":"1.168230755","rc":[{"batb":[[0,2.86,30.29],[1,2.84,90.22]],"ltp":0.0,"tv":0.0,"id":13095165}]}]}
{"op":"mcm","clk":"1007383479","pt":1580654670116,"mc":[{"id":"1.168230755","rc":[{"batb":[[0,2.86,119.97],[1,1.02,2],[2,1.01,1.01]],"ltp":0.0,"tv":0.0,"id":13095165}]}]}
{"op":"mcm","clk":"1007401902","pt":1580654788647,"mc":[{"id":"1.168230755","rc":[{"batb":[[0,2.86,89.68]],"ltp":0.0,"tv":0.0,"id":13095165}]}]}
{"op":"mcm","clk":"1007402021","pt":1580654789353,"mc":[{"id":"1.168230755","rc":[{"batb":[[0,2.88,30.28]],"ltp":0.0,"tv":0.0,"id":13095165}]}]}
{"op":"mcm","clk":"1007417485","pt":1580654908148,"mc":[{"id":"1.168230755","rc":[{"batl":[[0,8.4,30.69]],"ltp":0.0,"tv":0.0,"id":14343850}]}]}
{"op":"mcm","clk":"1007417789","pt":1580654910452,"mc":[{"id":"1.168230755","rc":[{"batb":[[0,1.02,2],[1,1.01,1.01],[2,1.01,0]],"ltp":0.0,"tv":0.0,"id":13095165}]}]}
{"op":"mcm","clk":"1007417897","pt":1580654911250,"mc":[{"id":"1.168230755","rc":[{"batb":[[0,2.72,94.34],[1,2.54,30.29],[2,1.02,2]],"ltp":0.0,"tv":0.0,"id":13095165}]}]}
{"op":"mcm","clk":"1007433556","pt":1580655032581,"mc":[{"id":"1.168230755","rc":[{"batb":[[0,2.76,92.98],[1,2.74,30.29]],"ltp":0.0,"tv":0.0,"id":13095165}]}]}
{"op":"mcm","clk":"1007440089","pt":1580655085633,"mc":[{"id":"1.168230755","rc":[{"batl":[[0,8.4,299.59]],"ltp":0.0,"tv":0.0,"id":14343850}]}]}
{"op":"mcm","clk":"1007448032","pt":1580655154521,"mc":[{"id":"1.168230755","rc":[{"batb":[[0,2.78,30.29],[1,1.02,2],[2,1.01,1.01]],"ltp":0.0,"tv":0.0,"id":13095165}]}]}
{"op":"mcm","clk":"1007448057","pt":1580655154711,"mc":[{"id":"1.168230755","rc":[{"batb":[[0,2.8,91.48],[1,2.78,30.29],[2,1.02,2]],"ltp":0.0,"tv":0.0,"id":13095165}]}]}
{"op":"mcm","clk":"1007463285","pt":1580655275611,"mc":[{"id":"1.168230755","rc":[{"batb":[[0,2.82,30.29],[1,1.02,2],[2,1.01,1.01]],"ltp":0.0,"tv":0.0,"id":13095165}]}]}
{"op":"mcm","clk":"1007463313","pt":1580655275824,"mc":[{"id":"1.168230755","rc":[{"batb":[[0,2.84,90.22],[1,2.82,30.29],[2,1.02,2]],"ltp":0.0,"tv":0.0,"id":13095165}]}]}
{"op":"mcm","clk":"1007479193","pt":1580655397466,"mc":[{"id":"1.168230755","rc":[{"batb":[[0,2.86,30.29],[1,1.02,2],[2,1.01,1.01]],"ltp":0.0,"tv":0.0,"id":13095165}]}]}
{"op":"mcm","clk":"1007479229","pt":1580655397786,"mc":[{"id":"1.168230755","rc":[{"batb":[[0,2.86,119.97]],"ltp":0.0,"tv":0.0,"id":13095165}]}]}
{"op":"mcm","clk":"1007493581","pt":1580655519407,"mc":[{"id":"1.168230755","rc":[{"batb":[[0,2.88,30.28]],"ltp":0.0,"tv":0.0,"id":13095165}]}]}
{"op":"mcm","clk":"1007509464","pt":1580655640381,"mc":[{"id":"1.168230755","rc":[{"batb":[[0,1.02,2],[1,1.01,1.01],[2,1.01,0]],"ltp":0.0,"tv":0.0,"id":13095165}]}]}
{"op":"mcm","clk":"1007509543","pt":1580655640862,"mc":[{"id":"1.168230755","rc":[{"batb":[[0,2.62,98.04],[1,2.54,30.29],[2,1.02,2]],"ltp":0.0,"tv":0.0,"id":13095165}]}]}
{"op":"mcm","clk":"1007529939","pt":1580655762633,"mc":[{"id":"1.168230755","rc":[{"batb":[[0,2.64,30.29],[1,1.02,2],[2,1.01,1.01]],"ltp":0.0,"tv":0.0,"id":13095165}]}]}
{"op":"mcm","clk":"1007529982","pt":1580655762862,"mc":[{"id":"1.168230755","rc":[{"batb":[[0,2.74,93.52],[1,2.64,30.29],[2,1.02,2]],"ltp":0.0,"tv":0.0,"id":13095165}]}]}
{"op":"mcm","clk":"1007553631","pt":1580655884374,"mc":[{"id":"1.168230755","rc":[{"batb":[[0,2.8,91.48],[1,2.76,30.29]],"ltp":0.0,"tv":0.0,"id":13095165}]}]}
{"op":"mcm","clk":"1007578464","pt":1580656005471,"mc":[{"id":"1.168230755","rc":[{"batb":[[0,2.82,30.29],[1,2.8,91.48]],"ltp":0.0,"tv":0.0,"id":13095165}]}]}
{"op":"mcm","clk":"1007578524","pt":1580656005806,"mc":[{"id":"1.168230755","rc":[{"batb":[[0,2.84,90.22],[1,2.82,30.29]],"ltp":0.0,"tv":0.0,"id":13095165}]}]}
{"op":"mcm","clk":"1007605817","pt":1580656127487,"mc":[{"id":"1.168230755","rc":[{"batb":[[0,2.86,30.29],[1,1.02,2],[2,1.01,1.01]],"ltp":0.0,"tv":0.0,"id":13095165}]}]}
{"op":"mcm","clk":"1007605875","pt":1580656127697,"mc":[{"id":"1.168230755","rc":[{"batb":[[0,2.86,119.97]],"ltp":0.0,"tv":0.0,"id":13095165}]}]}
{"op":"mcm","clk":"1007635497","pt":1580656249245,"mc":[{"id":"1.168230755","rc":[{"batb":[[0,2.88,30.28],[1,2.86,89.68],[2,1.02,2]],"ltp":0.0,"tv":0.0,"id":13095165}]}]}
{"op":"mcm","clk":"1007636265","pt":1580656252278,"mc":[{"id":"1.168230755","rc":[{"batb":[[1,1.02,2],[2,1.01,1.01]],"ltp":0.0,"tv":0.0,"id":13095165}]}]}
{"op":"mcm","clk":"1007660474","pt":1580656352495,"mc":[{"id":"1.168230755","rc":[{"batb":[[0,1.02,2],[1,1.01,1.01],[2,1.01,0]],"ltp":0.0,"tv":0.0,"id":14343845}]}]}
{"op":"mcm","clk":"1007660564","pt":1580656352875,"mc":[{"id":"1.168230755","rc":[{"batb":[[0,2.44,105.17],[1,1.02,2],[2,1.01,1.01]],"ltp":0.0,"tv":0.0,"id":14343845}]}]}
{"op":"mcm","clk":"1007664837","pt":1580656371601,"mc":[{"id":"1.168230755","rc":[{"batb":[[0,1.02,2],[1,1.01,1.01],[2,1.01,0]],"ltp":0.0,"tv":0.0,"id":13095165}]}]}
{"op":"mcm","clk":"1007665084","pt":1580656372594,"mc":[{"id":"1.168230755","rc":[{"batb":[[0,2.54,30.29],[1,1.02,2],[2,1.01,1.01]],"ltp":0.0,"tv":0.0,"id":13095165}]}]}
{"op":"mcm","clk":"1007665251","pt":1580656373392,"mc":[{"id":"1.168230755","rc":[{"batb":[[0,2.68,95.86],[1,2.54,30.29],[2,1.02,2]],"ltp":0.0,"tv":0.0,"id":13095165},{"batb":[[0,2.84,90.22],[1,2.6,30.29],[2,1.02,2]],"ltp":0.0,"tv":0.0,"id":14343845}]}]}
{"op":"mcm","clk":"1007693763","pt":1580656493149,"mc":[{"id":"1.168230755","rc":[{"batb":[[1,1.02,2],[2,1.01,1.01]],"ltp":0.0,"tv":0.0,"id":13095165}]}]}
{"op":"mcm","clk":"1007694088","pt":1580656494563,"mc":[{"id":"1.168230755","rc":[{"batb":[[0,2.72,94.34],[1,2.7,30.28],[2,1.02,2]],"ltp":0.0,"tv":0.0,"id":13095165},{"batb":[[0,2.86,30.29],[1,1.02,2],[2,1.01,1.01]],"ltp":0.0,"tv":0.0,"id":14343845}]}]}
{"op":"mcm","clk":"1007694138","pt":1580656494767,"mc":[{"id":"1.168230755","rc":[{"batb":[[0,2.9,88.36],[1,2.86,30.29],[2,1.02,2]],"ltp":0.0,"tv":0.0,"id":14343845}]}]}
{"op":"mcm","clk":"1007721406","pt":1580656615335,"mc":[{"id":"1.168230755","rc":[{"batb":[[1,1.02,2],[2,1.01,1.01]],"ltp":0.0,"tv":0.0,"id":13095165}]}]}
{"op":"mcm","clk":"1007721680","pt":1580656616536,"mc":[{"id":"1.168230755","rc":[{"batb":[[0,2.78,92.16],[1,2.74,30.29],[2,1.02,2]],"ltp":0.0,"tv":0.0,"id":13095165},{"batb":[[0,2.92,30.29],[1,2.9,88.36]],"ltp":0.0,"tv":0.0,"id":14343845}]}]}
{"op":"mcm","clk":"1007721820","pt":1580656617046,"mc":[{"id":"1.168230755","rc":[{"batb":[[0,2.94,87.09],[1,2.92,30.29]],"ltp":0.0,"tv":0.0,"id":14343845}]}]}
{"op":"mcm","clk":"1007749837","pt":1580656736602,"mc":[{"id":"1.168230755","rc":[{"batb":[[1,1.02,2],[2,1.01,1.01]],"ltp":0.0,"tv":0.0,"id":13095165}]}]}
{"op":"mcm","clk":"1007750032","pt":1580656737633,"mc":[{"id":"1.168230755","rc":[{"batb":[[0,2.82,91.03],[1,2.8,30.29],[2,1.02,2]],"ltp":0.0,"tv":0.0,"id":13095165},{"batb":[[0,2.96,30.29],[1,1.02,2],[2,1.01,1.01]],"ltp":0.0,"tv":0.0,"id":14343845}]}]}
{"op":"mcm","clk":"1007750078","pt":1580656737852,"mc":[{"id":"1.168230755","rc":[{"batb":[[0,2.96,116.92]],"ltp":0.0,"tv":0.0,"id":14343845}]}]}
{"op":"mcm","clk":"1007759966","pt":1580656781585,"mc":[{"id":"1.168230755","rc":[{"batb":[[0,3.4,75.21],[1,1.02,2],[2,1.01,1.01]],"batl":[[0,9.6,263.21]],"ltp":0.0,"tv":0.0,"id":13095168}]}]}
{"op":"mcm","clk":"1007777397","pt":1580656858434,"mc":[{"id":"1.168230755","rc":[{"batb":[[0,2.84,30.29],[1,1.02,2],[2,1.01,1.01]],"ltp":0.0,"tv":0.0,"id":13095165}]}]}
{"op":"mcm","clk":"1007777596","pt":1580656859367,"mc":[{"id":"1.168230755","rc":[{"batb":[[0,2.86,89.68],[1,2.84,30.29],[2,1.02,2]],"ltp":0.0,"tv":0.0,"id":13095165},{"batb":[[0,2.98,30.29]],"ltp":0.0,"tv":0.0,"id":14343845}]}]}
{"op":"mcm","clk":"1007782171","pt":1580656879205,"mc":[{"id":"1.168230755","rc":[{"batl":[[0,4.7,330.65]],"ltp":0.0,"tv":0.0,"id":13095165}]}]}
{"op":"mcm","clk":"1007804774","pt":1580656980483,"mc":[{"id":"1.168230755","rc":[{"batb":[[0,2.88,30.28],[1,2.86,89.68]],"ltp":0.0,"tv":0.0,"id":13095165}]}]}
{"op":"mcm","clk":"1007805032","pt":1580656981571,"mc":[{"id":"1.168230755","rc":[{"batb":[[1,1.02,2],[2,1.01,1.01]],"ltp":0.0,"tv":0.0,"id":13095165},{"batb":[[0,2.6,30.29],[1,2.58,99.56],[2,1.02,2]],"ltp":0.0,"tv":0.0,"id":14343845}]}]}
{"op":"mcm","clk":"1007805138","pt":1580656981993,"mc":[{"id":"1.168230755","rc":[{"batb":[[0,2.64,97.32],[1,2.6,30.29]],"ltp":0.0,"tv":0.0,"id":14343845}]}]}
{"op":"mcm","clk":"1007832240","pt":1580657101470,"mc":[{"id":"1.168230755","rc":[{"batb":[[0,1.02,2],[1,1.01,1.01],[2,1.01,0]],"ltp":0.0,"tv":0.0,"id":13095165}]}]}
{"op":"mcm","clk":"1007832490","pt":1580657102599,"mc":[{"id":"1.168230755","rc":[{"batb":[[0,2.6,98.59],[1,2.54,30.29],[2,1.02,2]],"ltp":0.0,"tv":0.0,"id":13095165},{"batb":[[1,1.02,2],[2,1.01,1.01]],"ltp":0.0,"tv":0.0,"id":14343845}]}]}
{"op":"mcm","clk":"1007832727","pt":1580657103580,"mc":[{"id":"1.168230755","rc":[{"batb":[[0,2.7,94.92],[1,2.66,30.29],[2,1.02,2]],"ltp":0.0,"tv":0.0,"id":14343845}]}]}
{"op":"mcm","clk":"1007859666","pt":1580657223602,"mc":[{"id":"1.168230755","rc":[{"batb":[[0,2.62,30.29],[1,1.02,2],[2,1.01,1.01]],"ltp":0.0,"tv":0.0,"id":13095165}]}]}
{"op":"mcm","clk":"1007859862","pt":1580657224424,"mc":[{"id":"1.168230755","rc":[{"batb":[[0,2.82,91.03],[1,2.62,30.29],[2,1.02,2]],"ltp":0.0,"tv":0.0,"id":13095165},{"batb":[[0,2.82,91.03],[1,2.72,30.29]],"ltp":0.0,"tv":0.0,"id":14343845}]}]}
{"op":"mcm","clk":"1007888196","pt":1580657345578,"mc":[{"id":"1.168230755","rc":[{"batb":[[0,2.86,89.68],[1,2.84,30.29]],"ltp":0.0,"tv":0.0,"id":13095165}]}]}
{"op":"mcm","clk":"1007888400","pt":1580657346584,"mc":[{"id":"1.168230755","rc":[{"batb":[[0,2.84,30.29],[1,1.02,2],[2,1.01,1.01]],"ltp":0.0,"tv":0.0,"id":14343845}]}]}
{"op":"mcm","clk":"1007888441","pt":1580657346820,"mc":[{"id":"1.168230755","rc":[{"batb":[[0,2.88,88.96],[1,2.84,30.29],[2,1.02,2]],"ltp":0.0,"tv":0.0,"id":14343845}]}]}
{"op":"mcm","clk":"1007897671","pt":1580657390682,"mc":[{"id":"1.168230755","rc":[{"batl":[[0,4.3,407.14]],"ltp":0.0,"tv":0.0,"id":14343845}]}]}
{"op":"mcm","clk":"1007914847","pt":1580657466594,"mc":[{"id":"1.168230755","rc":[{"batb":[[1,1.02,2],[2,1.01,1.01]],"ltp":0.0,"tv":0.0,"id":13095165}]}]}
{"op":"mcm","clk":"1007915026","pt":1580657467362,"mc":[{"id":"1.168230755","rc":[{"batb":[[0,2.88,30.28]],"ltp":0.0,"tv":0.0,"id":13095165}]}]}
{"op":"mcm","clk":"1007915219","pt":1580657468172,"mc":[{"id":"1.168230755","rc":[{"batb":[[0,2.94,87.09],[1,2.9,30.29]],"ltp":0.0,"tv":0.0,"id":14343845}]}]}
{"op":"mcm","clk":"1007942029","pt":1580657588146,"mc":[{"id":"1.168230755","rc":[{"batb":[[0,1.02,2],[1,1.01,1.01],[2,1.01,0]],"ltp":0.0,"tv":0.0,"id":13095165}]}]}
{"op":"mcm","clk":"1007942319","pt":1580657589457,"mc":[{"id":"1.168230755","rc":[{"batb":[[0,2.54,30.29],[1,1.02,2],[2,1.01,1.01]],"ltp":0.0,"tv":0.0,"id":13095165},{"batb":[[0,2.96,30.29],[1,2.94,87.09]],"ltp":0.0,"tv":0.0,"id":14343845}]}]}
{"op":"mcm","clk":"1007942764","pt":1580657591345,"mc":[{"id":"1.168230755","rc":[{"batb":[[0,2.74,93.52],[1,2.54,30.29],[2,1.02,2]],"ltp":0.0,"tv":0.0,"id":13095165},{"batb":[[0,2.96,116.92],[1,1.02,2],[2,1.01,1.01]],"ltp":0.0,"tv":0.0,"id":14343845}]}]}
{"op":"mcm","clk":"1007969772","pt":1580657710630,"mc":[{"id":"1.168230755","rc":[{"batb":[[0,2.78,92.16],[1,2.76,30.29]],"ltp":0.0,"tv":0.0,"id":13095165},{"batb":[[0,2.98,30.29],[1,2.96,86.63],[2,1.02,2]],"ltp":0.0,"tv":0.0,"id":14343845}]}]}
{"op":"mcm","clk":"1007969844","pt":1580657710913,"mc":[{"id":"1.168230755","rc":[{"batb":[[1,1.02,2],[2,1.01,1.01]],"ltp":0.0,"tv":0.0,"id":14343845}]}]}
{"op":"mcm","clk":"1007986196","pt":1580657786425,"mc":[{"id":"1.168230755","rc":[{"batb":[[0,1.02,2],[1,1.01,1.01],[2,1.01,0]],"ltp":0.0,"tv":0.0,"id":14343850}]}]}
{"op":"mcm","clk":"1007986263","pt":1580657786724,"mc":[{"id":"1.168230755","rc":[{"batl":[[0,7,359.6]],"ltp":0.0,"tv":0.0,"id":14343850}]}]}
{"op":"mcm","clk":"1007995976","pt":1580657831612,"mc":[{"id":"1.168230755","rc":[{"batb":[[0,2.8,30.29],[1,2.78,92.16]],"ltp":0.0,"tv":0.0,"id":13095165}]}]}
{"op":"mcm","clk":"1007996220","pt":1580657832611,"mc":[{"id":"1.168230755","rc":[{"batb":[[0,2.84,90.22],[1,2.8,30.29]],"ltp":0.0,"tv":0.0,"id":13095165},{"batb":[[0,2.6,30.29],[1,2.56,100.33],[2,1.02,2]],"ltp":0.0,"tv":0.0,"id":14343845}]}]}
{"op":"mcm","clk":"1007996327","pt":1580657832996,"mc":[{"id":"1.168230755","rc":[{"batb":[[0,2.64,97.32],[1,2.6,30.29]],"ltp":0.0,"tv":0.0,"id":14343845}]}]}
{"op":"mcm","clk":"1008023859","pt":1580657954414,"mc":[{"id":"1.168230755","rc":[{"batb":[[0,2.86,30.29],[1,2.84,90.22]],"ltp":0.0,"tv":0.0,"id":13095165}]}]}
{"op":"mcm","clk":"1008024116","pt":1580657955559,"mc":[{"id":"1.168230755","rc":[{"batb":[[0,2.86,119.97],[1,1.02,2],[2,1.01,1.01]],"ltp":0.0,"tv":0.0,"id":13095165},{"batb":[[0,2.66,30.29],[1,1.02,2],[2,1.01,1.01]],"ltp":0.0,"tv":0.0,"id":14343845}]}]}
{"op":"mcm","clk":"1008024198","pt":1580657955835,"mc":[{"id":"1.168230755","rc":[{"batb":[[0,2.72,94.34],[1,2.66,30.29],[2,1.02,2]],"ltp":0.0,"tv":0.0,"id":14343845}]}]}
{"op":"mcm","clk":"1008052968","pt":1580658076461,"mc":[{"id":"1.168230755","rc":[{"batb":[[0,2.86,89.68]],"ltp":0.0,"tv":0.0,"id":13095165}]}]}
{"op":"mcm","clk":"1008053181","pt":1580658077568,"mc":[{"id":"1.168230755","rc":[{"batb":[[0,2.88,30.28]],"ltp":0.0,"tv":0.0,"id":13095165},{"batb":[[1,1.02,2],[2,1.01,1.01]],"ltp":0.0,"tv":0.0,"id":14343845}]}]}
{"op":"mcm","clk":"1008053270","pt":1580658077995,"mc":[{"id":"1.168230755","rc":[{"batb":[[0,2.76,92.98],[1,2.74,30.29],[2,1.02,2]],"ltp":0.0,"tv":0.0,"id":14343845}]}]}
{"op":"mcm","clk":"1008081620","pt":1580658198169,"mc":[{"id":"1.168230755","rc":[{"batb":[[0,2.6,98.59],[1,2.54,30.29],[2,1.02,2]],"ltp":0.0,"tv":0.0,"id":13095165}]}]}
{"op":"mcm","clk":"1008081917","pt":1580658199346,"mc":[{"id":"1.168230755","rc":[{"batb":[[0,2.92,87.69],[1,2.78,30.29]],"ltp":0.0,"tv":0.0,"id":14343845}]}]}
{"op":"mcm","clk":"1008109830","pt":1580658319639,"mc":[{"id":"1.168230755","rc":[{"batb":[[0,2.62,30.29],[1,1.02,2],[2,1.01,1.01]],"ltp":0.0,"tv":0.0,"id":13095165}]}]}
{"op":"mcm","clk":"1008109974","pt":1580658320339,"mc":[{"id":"1.168230755","rc":[{"batb":[[0,2.64,97.32],[1,2.62,30.29],[2,1.02,2]],"ltp":0.0,"tv":0.0,"id":13095165},{"batb":[[0,2.96,86.63],[1,2.94,30.29]],"ltp":0.0,"tv":0.0,"id":14343845}]}]}
{"op":"mcm","clk":"1008134945","pt":1580658441505,"mc":[{"id":"1.168230755","rc":[{"batb":[[0,2.68,95.86],[1,2.66,30.29]],"ltp":0.0,"tv":0.0,"id":13095165}]}]}
{"op":"mcm","clk":"1008135066","pt":1580658442032,"mc":[{"id":"1.168230755","rc":[{"batb":[[0,2.98,30.29],[1,1.02,2],[2,1.01,1.01]],"ltp":0.0,"tv":0.0,"id":14343845}]}]}
{"op":"mcm","clk":"1008158939","pt":1580658563581,"mc":[{"id":"1.168230755","rc":[{"batb":[[0,2.76,92.98],[1,2.7,30.28]],"ltp":0.0,"tv":0.0,"id":13095165}]}]}
{"op":"mcm","clk":"1008159096","pt":1580658564373,"mc":[{"id":"1.168230755","rc":[{"batb":[[0,2.72,94.34],[1,2.6,30.29],[2,1.02,2]],"ltp":0.0,"tv":0.0,"id":14343845}]}]}
{"op":"mcm","clk":"1008180037","pt":1580658684324,"mc":[{"id":"1.168230755","rc":[{"batb":[[1,1.02,2],[2,1.01,1.01]],"ltp":0.0,"tv":0.0,"id":13095165}]}]}
{"op":"mcm","clk":"1008180222","pt":1580658685547,"mc":[{"id":"1.168230755","rc":[{"batb":[[0,2.8,91.48],[1,2.78,30.29],[2,1.02,2]],"ltp":0.0,"tv":0.0,"id":13095165},{"batb":[[0,2.74,30.29],[1,2.72,94.34]],"ltp":0.0,"tv":0.0,"id":14343845}]}]}
{"op":"mcm","clk":"1008180307","pt":1580658686020,"mc":[{"id":"1.168230755","rc":[{"batb":[[0,2.78,92.16],[1,2.74,30.29]],"ltp":0.0,"tv":0.0,"id":14343845}]}]}
{"op":"mcm","clk":"1008199346","pt":1580658806551,"mc":[{"id":"1.168230755","rc":[{"batb":[[0,2.84,90.22],[1,2.82,30.29]],"ltp":0.0,"tv":0.0,"id":13095165}]}]}
{"op":"mcm","clk":"1008199516","pt":1580658807554,"mc":[{"id":"1.168230755","rc":[{"batb":[[0,2.82,91.03],[1,2.8,30.29]],"ltp":0.0,"tv":0.0,"id":14343845}]}]}
{"op":"mcm","clk":"1008218884","pt":1580658927646,"mc":[{"id":"1.168230755","rc":[{"batb":[[0,2.86,30.29],[1,2.84,90.22]],"ltp":0.0,"tv":0.0,"id":13095165}]}]}
{"op":"mcm","clk":"1008219053","pt":1580658928541,"mc":[{"id":"1.168230755","rc":[{"batb":[[0,2.86,119.97],[1,1.02,2],[2,1.01,1.01]],"ltp":0.0,"tv":0.0,"id":13095165},{"batb":[[0,2.84,30.29],[1,1.02,2],[2,1.01,1.01]],"ltp":0.0,"tv":0.0,"id":14343845}]}]}
{"op":"mcm","clk":"1008219081","pt":1580658928755,"mc":[{"id":"1.168230755","rc":[{"batb":[[0,2.86,89.68],[1,2.84,30.29],[2,1.02,2]],"ltp":0.0,"tv":0.0,"id":14343845}]}]}
{"op":"mcm","clk":"1008238851","pt":1580659049386,"mc":[{"id":"1.168230755","rc":[{"batb":[[0,2.86,89.68]],"ltp":0.0,"tv":0.0,"id":13095165}]}]}
{"op":"mcm","clk":"1008239029","pt":1580659050500,"mc":[{"id":"1.168230755","rc":[{"batb":[[0,2.88,30.28]],"ltp":0.0,"tv":0.0,"id":13095165},{"batb":[[1,1.02,2],[2,1.01,1.01]],"ltp":0.0,"tv":0.0,"id":14343845}]}]}
{"op":"mcm","clk":"1008239211","pt":1580659051635,"mc":[{"id":"1.168230755","rc":[{"batb":[[0,2.94,87.09],[1,2.88,30.28],[2,1.02,2]],"ltp":0.0,"tv":0.0,"id":14343845}]}]}
{"op":"mcm","clk":"1008257129","pt":1580659171522,"mc":[{"id":"1.168230755","rc":[{"batb":[[0,2.54,30.29],[1,2.5,102.82],[2,1.02,2]],"ltp":0.0,"tv":0.0,"id":13095165}]}]}
{"op":"mcm","clk":"1008257294","pt":1580659172529,"mc":[{"id":"1.168230755","rc":[{"batb":[[0,2.6,98.59],[1,2.54,30.29]],"ltp":0.0,"tv":0.0,"id":13095165},{"batb":[[0,2.96,30.29],[1,2.94,87.09]],"ltp":0.0,"tv":0.0,"id":14343845}]}]}
{"op":"mcm","clk":"1008257389","pt":1580659173108,"mc":[{"id":"1.168230755","rc":[{"batb":[[0,2.96,116.92],[1,1.02,2],[2,1.01,1.01]],"ltp":0.0,"tv":0.0,"id":14343845}]}]}
{"op":"mcm","clk":"1008278581","pt":1580659292643,"mc":[{"id":"1.168230755","rc":[{"batb":[[1,1.02,2],[2,1.01,1.01]],"ltp":0.0,"tv":0.0,"id":13095165}]}]}
{"op":"mcm","clk":"1008278720","pt":1580659293541,"mc":[{"id":"1.168230755","rc":[{"batb":[[0,2.78,92.16],[1,2.62,30.29],[2,1.02,2]],"ltp":0.0,"tv":0.0,"id":13095165},{"batb":[[0,2.98,30.29],[1,2.96,86.63],[2,1.02,2]],"ltp":0.0,"tv":0.0,"id":14343845}]}]}
{"op":"mcm","clk":"1008278795","pt":1580659293813,"mc":[{"id":"1.168230755","rc":[{"batb":[[1,1.02,2],[2,1.01,1.01]],"ltp":0.0,"tv":0.0,"id":14343845}]}]}
{"op":"mcm","clk":"1008301751","pt":1580659414455,"mc":[{"id":"1.168230755","rc":[{"batb":[[0,2.8,30.29],[1,2.78,92.16]],"ltp":0.0,"tv":0.0,"id":13095165}]}]}
{"op":"mcm","clk":"1008301957","pt":1580659415531,"mc":[{"id":"1.168230755","rc":[{"batb":[[0,2.82,91.03],[1,2.8,30.29]],"ltp":0.0,"tv":0.0,"id":13095165},{"batb":[[0,2.7,94.92],[1,2.6,30.29],[2,1.02,2]],"ltp":0.0,"tv":0.0,"id":14343845}]}]}
{"op":"mcm","clk":"1008325051","pt":1580659536617,"mc":[{"id":"1.168230755","rc":[{"batb":[[0,2.84,30.29],[1,1.02,2],[2,1.01,1.01]],"ltp":0.0,"tv":0.0,"id":13095165}]}]}
{"op":"mcm","clk":"1008325229","pt":1580659537634,"mc":[{"id":"1.168230755","rc":[{"batb":[[0,2.86,89.68],[1,2.84,30.29],[2,1.02,2]],"ltp":0.0,"tv":0.0,"id":13095165},{"batb":[[0,2.8,91.48],[1,2.72,30.29]],"ltp":0.0,"tv":0.0,"id":14343845}]}]}
{"op":"mcm","clk":"1008350466","pt":1580659658603,"mc":[{"id":"1.168230755","rc":[{"batb":[[0,2.88,30.28],[1,2.86,89.68]],"ltp":0.0,"tv":0.0,"id":13095165}]}]}
{"op":"mcm","clk":"1008350673","pt":1580659659410,"mc":[{"id":"1.168230755","rc":[{"batb":[[1,1.02,2],[2,1.01,1.01]],"ltp":0.0,"tv":0.0,"id":13095165},{"batb":[[0,2.82,30.29],[1,2.8,91.48]],"ltp":0.0,"tv":0.0,"id":14343845}]}]}
{"op":"mcm","clk":"1008350790","pt":1580659659907,"mc":[{"id":"1.168230755","rc":[{"batb":[[0,2.84,90.22],[1,2.82,30.29]],"ltp":0.0,"tv":0.0,"id":14343845}]}]}
{"op":"mcm","clk":"1008377392","pt":1580659779387,"mc":[{"id":"1.168230755","rc":[{"batb":[[0,1.02,2],[1,1.01,1.01],[2,1.01,0]],"ltp":0.0,"tv":0.0,"id":13095165}]}]}
{"op":"mcm","clk":"1008377497","pt":1580659779948,"mc":[{"id":"1.168230755","rc":[{"batb":[[0,2.64,97.32],[1,2.54,30.29],[2,1.02,2]],"ltp":0.0,"tv":0.0,"id":13095165}]}]}
{"op":"mcm","clk":"1008377790","pt":1580659781273,"mc":[{"id":"1.168230755","rc":[{"batb":[[0,2.9,88.36],[1,2.86,30.29]],"ltp":0.0,"tv":0.0,"id":14343845}]}]}
{"op":"mcm","clk":"1008404975","pt":1580659901614,"mc":[{"id":"1.168230755","rc":[{"batb":[[0,2.66,30.29],[1,1.02,2],[2,1.01,1.01]],"ltp":0.0,"tv":0.0,"id":13095165}]}]}
{"op":"mcm","clk":"1008405158","pt":1580659902485,"mc":[{"id":"1.168230755","rc":[{"batb":[[0,2.72,94.34],[1,2.66,30.29],[2,1.02,2]],"ltp":0.0,"tv":0.0,"id":13095165},{"batb":[[0,2.92,30.29],[1,1.02,2],[2,1.01,1.01]],"ltp":0.0,"tv":0.0,"id":14343845}]}]}
{"op":"mcm","clk":"1008405231","pt":1580659902746,"mc":[{"id":"1.168230755","rc":[{"batb":[[0,2.94,87.09],[1,2.92,30.29],[2,1.02,2]],"ltp":0.0,"tv":0.0,"id":14343845}]}]}
{"op":"mcm","clk":"1008432788","pt":1580660023568,"mc":[{"id":"1.168230755","rc":[{"batb":[[0,2.82,91.03],[1,2.74,30.29]],"ltp":0.0,"tv":0.0,"id":13095165},{"batb":[[0,2.96,30.29],[1,2.94,87.09]],"ltp":0.0,"tv":0.0,"id":14343845}]}]}
{"op":"mcm","clk":"1008432945","pt":1580660024173,"mc":[{"id":"1.168230755","rc":[{"batb":[[0,2.96,116.92],[1,1.02,2],[2,1.01,1.01]],"ltp":0.0,"tv":0.0,"id":14343845}]}]}
{"op":"mcm","clk":"1008461148","pt":1580660144565,"mc":[{"id":"1.168230755","rc":[{"batb":[[0,2.84,30.29],[1,2.82,91.03]],"ltp":0.0,"tv":0.0,"id":13095165}]}]}
{"op":"mcm","clk":"1008461399","pt":1580660145495,"mc":[{"id":"1.168230755","rc":[{"batb":[[0,2.86,89.68],[1,2.84,30.29]],"ltp":0.0,"tv":0.0,"id":13095165},{"batb":[[0,2.98,30.29]],"ltp":0.0,"tv":0.0,"id":14343845}]}]}
{"op":"mcm","clk":"1008489969","pt":1580660266608,"mc":[{"id":"1.168230755","rc":[{"batb":[[0,2.88,30.28],[1,2.86,89.68]],"ltp":0.0,"tv":0.0,"id":13095165}]}]}
{"op":"mcm","clk":"1008490144","pt":1580660267431,"mc":[{"id":"1.168230755","rc":[{"batb":[[0,2.6,30.29]],"ltp":0.0,"tv":0.0,"id":14343845}]}]}
{"op":"mcm","clk":"1008491217","pt":1580660271647,"mc":[{"id":"1.168230755","rc":[{"batb":[[1,1.02,2],[2,1.01,1.01]],"ltp":0.0,"tv":0.0,"id":13095165}]}]}
{"op":"mcm","clk":"1008491271","pt":1580660271812,"mc":[{"id":"1.168230755","rc":[{"batb":[[0,2.64,97.32],[1,2.6,30.29],[2,1.02,2]],"ltp":0.0,"tv":0.0,"id":14343845}]}]}
{"op":"mcm","clk":"1008516630","pt":1580660382003,"mc":[{"id":"1.168230755","rc":[{"batb":[[0,3.5,73.28]],"ltp":0.0,"tv":0.0,"id":13095168}]}]}
{"op":"mcm","clk":"1008518079","pt":1580660388381,"mc":[{"id":"1.168230755","rc":[{"batb":[[0,1.02,2],[1,1.01,1.01],[2,1.01,0]],"ltp":0.0,"tv":0.0,"id":13095165}]}]}
{"op":"mcm","clk":"1008518343","pt":1580660389582,"mc":[{"id":"1.168230755","rc":[{"batb":[[0,2.82,91.03],[1,2.56,30.29],[2,1.02,2]],"ltp":0.0,"tv":0.0,"id":13095165},{"batb":[[0,2.66,30.29],[1,2.64,97.32]],"ltp":0.0,"tv":0.0,"id":14343845}]}]}
{"op":"mcm","clk":"1008518463","pt":1580660390077,"mc":[{"id":"1.168230755","rc":[{"batb":[[0,2.78,92.16],[1,2.66,30.29]],"ltp":0.0,"tv":0.0,"id":14343845}]}]}
{"op":"mcm","clk":"1008539510","pt":1580660479697,"mc":[{"id":"1.168230755","rc":[{"batl":[[0,4.8,323.77]],"ltp":0.0,"tv":0.0,"id":13095165}]}]}
{"op":"mcm","clk":"1008546441","pt":1580660509628,"mc":[{"id":"1.168230755","rc":[{"batb":[[0,2.84,30.29],[1,2.82,91.03]],"ltp":0.0,"tv":0.0,"id":13095165}]}]}
{"op":"mcm","clk":"1008546641","pt":1580660510620,"mc":[{"id":"1.168230755","rc":[{"batb":[[0,2.86,89.68],[1,2.84,30.29]],"ltp":0.0,"tv":0.0,"id":13095165},{"batb":[[0,2.8,30.29],[1,1.02,2],[2,1.01,1.01]],"ltp":0.0,"tv":0.0,"id":14343845}]}]}
{"op":"mcm","clk":"1008546686","pt":1580660510794,"mc":[{"id":"1.168230755","rc":[{"batb":[[0,2.86,89.68],[1,2.8,30.29],[2,1.02,2]],"ltp":0.0,"tv":0.0,"id":14343845}]}]}
{"op":"mcm","clk":"1008573611","pt":1580660631637,"mc":[{"id":"1.168230755","rc":[{"batb":[[0,2.88,30.28],[1,2.86,89.68]],"ltp":0.0,"tv":0.0,"id":13095165}]}]}
{"op":"mcm","clk":"1008573761","pt":1580660632249,"mc":[{"id":"1.168230755","rc":[{"batb":[[1,1.02,2],[2,1.01,1.01]],"ltp":0.0,"tv":0.0,"id":13095165},{"batb":[[1,1.02,2],[2,1.01,1.01]],"ltp":0.0,"tv":0.0,"id":14343845}]}]}
{"op":"mcm","clk":"1008573982","pt":1580660633225,"mc":[{"id":"1.168230755","rc":[{"batb":[[0,2.94,87.09],[1,2.88,30.28],[2,1.02,2]],"ltp":0.0,"tv":0.0,"id":14343845}]}]}
{"op":"mcm","clk":"1008600271","pt":1580660753361,"mc":[{"id":"1.168230755","rc":[{"batb":[[0,2.56,130.62]],"ltp":0.0,"tv":0.0,"id":13095165}]}]}
{"op":"mcm","clk":"1008600490","pt":1580660754455,"mc":[{"id":"1.168230755","rc":[{"batb":[[0,2.96,30.29],[1,2.94,87.09]],"ltp":0.0,"tv":0.0,"id":14343845}]}]}
{"op":"mcm","clk":"1008600568","pt":1580660754872,"mc":[{"id":"1.168230755","rc":[{"batb":[[0,2.96,116.92],[1,1.02,2],[2,1.01,1.01]],"ltp":0.0,"tv":0.0,"id":14343845}]}]}
{"op":"mcm","clk":"1008626171","pt":1580660874622,"mc":[{"id":"1.168230755","rc":[{"batb":[[0,2.58,30.29],[1,2.56,100.33],[2,1.02,2]],"ltp":0.0,"tv":0.0,"id":13095165}]}]}
{"op":"mcm","clk":"1008626314","pt":1580660875339,"mc":[{"id":"1.168230755","rc":[{"batb":[[0,2.64,97.32],[1,2.58,30.29]],"ltp":0.0,"tv":0.0,"id":13095165},{"batb":[[0,2.98,30.29],[1,2.96,86.63],[2,1.02,2]],"ltp":0.0,"tv":0.0,"id":14343845}]}]}
{"op":"mcm","clk":"1008627259","pt":1580660879658,"mc":[{"id":"1.168230755","rc":[{"batb":[[1,1.02,2],[2,1.01,1.01]],"ltp":0.0,"tv":0.0,"id":14343845}]}]}
{"op":"mcm","clk":"1008636832","pt":1580660923212,"mc":[{"id":"1.168230755","rc":[{"batl":[[0,9.4,268.79]],"ltp":0.0,"tv":0.0,"id":13095168},{"batb":[[0,3.5,73.26],[1,1.02,2],[2,1.01,1.01]],"ltp":0.0,"tv":0.0,"id":14343850}]}]}
{"op":"mcm","clk":"1008650840","pt":1580660990995,"mc":[{"id":"1.168230755","rc":[{"batl":[[0,4.7,372.45]],"ltp":0.0,"tv":0.0,"id":14343845}]}]}
{"op":"mcm","clk":"1008652044","pt":1580660996641,"mc":[{"id":"1.168230755","rc":[{"batb":[[0,2.66,30.29],[1,1.02,2],[2,1.01,1.01]],"ltp":0.0,"tv":0.0,"id":13095165}]}]}
{"op":"mcm","clk":"1008652251","pt":1580660997508,"mc":[{"id":"1.168230755","rc":[{"batb":[[0,2.8,91.48],[1,2.66,30.29],[2,1.02,2]],"ltp":0.0,"tv":0.0,"id":13095165},{"batb":[[0,2.7,94.92],[1,2.6,30.29],[2,1.02,2]],"ltp":0.0,"tv":0.0,"id":14343845}]}]}
{"op":"mcm","clk":"1008678470","pt":1580661118529,"mc":[{"id":"1.168230755","rc":[{"batb":[[0,2.84,90.22],[1,2.82,30.29]],"ltp":0.0,"tv":0.0,"id":13095165}]}]}
{"op":"mcm","clk":"1008678692","pt":1580661119456,"mc":[{"id":"1.168230755","rc":[{"batb":[[0,2.72,30.29],[1,1.02,2],[2,1.01,1.01]],"ltp":0.0,"tv":0.0,"id":14343845}]}]}
{"op":"mcm","clk":"1008678739","pt":1580661119688,"mc":[{"id":"1.168230755","rc":[{"batb":[[0,2.8,91.48],[1,2.72,30.29],[2,1.02,2]],"ltp":0.0,"tv":0.0,"id":14343845}]}]}
{"op":"mcm","clk":"1008704770","pt":1580661239557,"mc":[{"id":"1.168230755","rc":[{"batb":[[1,1.02,2],[2,1.01,1.01]],"ltp":0.0,"tv":0.0,"id":13095165}]}]}
{"op":"mcm","clk":"1008704952","pt":1580661240366,"mc":[{"id":"1.168230755","rc":[{"batb":[[0,2.86,119.97]],"ltp":0.0,"tv":0.0,"id":13095165},{"batb":[[0,2.82,30.29],[1,2.8,91.48]],"ltp":0.0,"tv":0.0,"id":14343845}]}]}
{"op":"mcm","clk":"1008705081","pt":1580661240985,"mc":[{"id":"1.168230755","rc":[{"batb":[[0,2.86,89.68],[1,2.82,30.29]],"ltp":0.0,"tv":0.0,"id":14343845}]}]}
{"op":"mcm","clk":"1008730533","pt":1580661361182,"mc":[{"id":"1.168230755","rc":[{"batb":[[0,2.86,89.68]],"ltp":0.0,"tv":0.0,"id":13095165}]}]}
{"op":"mcm","clk":"1008730779","pt":1580661362277,"mc":[{"id":"1.168230755","rc":[{"batb":[[0,2.88,30.28]],"ltp":0.0,"tv":0.0,"id":13095165},{"batb":[[1,1.02,2],[2,1.01,1.01]],"ltp":0.0,"tv":0.0,"id":14343845}]}]}
{"op":"mcm","clk":"1008731019","pt":1580661363254,"mc":[{"id":"1.168230755","rc":[{"batb":[[0,2.9,88.36],[1,2.88,30.28],[2,1.02,2]],"ltp":0.0,"tv":0.0,"id":14343845}]}]}
{"op":"mcm","clk":"1008736320","pt":1580661387132,"mc":[{"id":"1.168230755","rc":[{"batl":[[0,7.4,339.99]],"ltp":0.0,"tv":0.0,"id":14343850}]}]}
{"op":"mcm","clk":"1008758095","pt":1580661483318,"mc":[{"id":"1.168230755","rc":[{"batb":[[0,2.56,30.29],[1,2.44,105.17],[2,1.02,2]],"ltp":0.0,"tv":0.0,"id":13095165}]}]}
{"op":"mcm","clk":"1008758405","pt":1580661484597,"mc":[{"id":"1.168230755","rc":[{"batb":[[0,2.62,98.04],[1,2.56,30.29]],"ltp":0.0,"tv":0.0,"id":13095165},{"batb":[[0,2.92,30.29],[1,1.02,2],[2,1.01,1.01]],"ltp":0.0,"tv":0.0,"id":14343845}]}]}
{"op":"mcm","clk":"1008758449","pt":1580661484796,"mc":[{"id":"1.168230755","rc":[{"batb":[[0,2.94,87.09],[1,2.92,30.29],[2,1.02,2]],"ltp":0.0,"tv":0.0,"id":14343845}]}]}
{"op":"mcm","clk":"1008784726","pt":1580661604555,"mc":[{"id":"1.168230755","rc":[{"batb":[[1,1.02,2],[2,1.01,1.01]],"ltp":0.0,"tv":0.0,"id":13095165}]}]}
{"op":"mcm","clk":"1008784906","pt":1580661605346,"mc":[{"id":"1.168230755","rc":[{"batb":[[0,2.68,95.86],[1,2.64,30.29],[2,1.02,2]],"ltp":0.0,"tv":0.0,"id":13095165},{"batb":[[0,2.96,30.29],[1,2.94,87.09]],"ltp":0.0,"tv":0.0,"id":14343845}]}]}
{"op":"mcm","clk":"1008785052","pt":1580661606051,"mc":[{"id":"1.168230755","rc":[{"batb":[[0,2.96,116.92],[1,1.02,2],[2,1.01,1.01]],"ltp":0.0,"tv":0.0,"id":14343845}]}]}
{"op":"mcm","clk":"1008810765","pt":1580661726237,"mc":[{"id":"1.168230755","rc":[{"batb":[[1,1.02,2],[2,1.01,1.01]],"ltp":0.0,"tv":0.0,"id":13095165}]}]}
{"op":"mcm","clk":"1008811055","pt":1580661727536,"mc":[{"id":"1.168230755","rc":[{"batb":[[0,2.72,94.34],[1,2.7,30.28],[2,1.02,2]],"ltp":0.0,"tv":0.0,"id":13095165},{"batb":[[0,2.98,30.29],[1,2.96,86.63],[2,1.02,2]],"ltp":0.0,"tv":0.0,"id":14343845}]}]}
{"op":"mcm","clk":"1008811218","pt":1580661728436,"mc":[{"id":"1.168230755","rc":[{"batb":[[1,1.02,2],[2,1.01,1.01]],"ltp":0.0,"tv":0.0,"id":14343845}]}]}
{"op":"mcm","clk":"1008835493","pt":1580661848389,"mc":[{"id":"1.168230755","rc":[{"batb":[[0,2.74,30.29],[1,2.72,94.34]],"ltp":0.0,"tv":0.0,"id":13095165}]}]}
{"op":"mcm","clk":"1008835752","pt":1580661849588,"mc":[{"id":"1.168230755","rc":[{"batb":[[0,2.78,92.16],[1,2.74,30.29]],"ltp":0.0,"tv":0.0,"id":13095165},{"batb":[[0,1.02,2],[1,1.01,1.01],[2,1.01,0]],"ltp":0.0,"tv":0.0,"id":14343845}]}]}
{"op":"mcm","clk":"1008835846","pt":1580661850086,"mc":[{"id":"1.168230755","rc":[{"batb":[[0,2.64,97.32],[1,2.6,30.29],[2,1.02,2]],"ltp":0.0,"tv":0.0,"id":14343845}]}]}
{"op":"mcm","clk":"1008860871","pt":1580661970066,"mc":[{"id":"1.168230755","rc":[{"batb":[[1,1.02,2],[2,1.01,1.01]],"ltp":0.0,"tv":0.0,"id":13095165}]}]}
{"op":"mcm","clk":"1008861034","pt":1580661970728,"mc":[{"id":"1.168230755","rc":[{"batb":[[1,1.02,2],[2,1.01,1.01]],"ltp":0.0,"tv":0.0,"id":14343845}]}]}
{"op":"mcm","clk":"1008892602","pt":1580662150357,"mc":[{"id":"1.168230755","rc":[{"batl":[[0,4.8,53.77]],"ltp":0.0,"tv":0.0,"id":13095165}]}]}
{"op":"mcm","clk":"1008899645","pt":1580662196761,"mc":[{"id":"1.168230755","rc":[{"batl":[[0,4.8,337.17]],"ltp":0.0,"tv":0.0,"id":13095165}]}]}
{"op":"mcm","clk":"1008908231","pt":1580662251422,"mc":[{"id":"1.168230755","rc":[{"batl":[[0,9.4,27.39]],"ltp":0.0,"tv":0.0,"id":13095168}]}]}
{"op":"mcm","clk":"1008931527","pt":1580662421804,"mc":[{"id":"1.168230755","rc":[{"batl":[[0,9.4,267.74]],"ltp":0.0,"tv":0.0,"id":13095168}]}]}
{"op":"mcm","clk":"1008946118","pt":1580662533485,"mc":[{"id":"1.168230755","rc":[{"batl":[[0,9.4,27.39]],"ltp":0.0,"tv":0.0,"id":13095168},{"batl":[[0,4.8,53.77]],"ltp":0.0,"tv":0.0,"id":13095165}]}]}
{"op":"mcm","clk":"1008952619","pt":1580662582928,"mc":[{"id":"1.168230755","rc":[{"batl":[[0,4.8,323.77]],"ltp":0.0,"tv":0.0,"id":13095165}]}]}
{"op":"mcm","clk":"1008956497","pt":1580662612995,"mc":[{"id":"1.168230755","rc":[{"batl":[[0,4.8,53.77]],"ltp":0.0,"tv":0.0,"id":13095165}]}]}
{"op":"mcm","clk":"1008970319","pt":1580662721819,"mc":[{"id":"1.168230755","rc":[{"batl":[[0,9.4,268.79]],"ltp":0.0,"tv":0.0,"id":13095168}]}]}
{"op":"mcm","clk":"1008979302","pt":1580662796801,"mc":[{"id":"1.168230755","rc":[{"batl":[[0,4.8,337.17]],"ltp":0.0,"tv":0.0,"id":13095165}]}]}
{"op":"mcm","clk":"1009016031","pt":1580663042208,"mc":[{"id":"1.168230755","rc":[{"batl":[[0,9.4,27.39]],"ltp":0.0,"tv":0.0,"id":13095168}]}]}
{"op":"mcm","clk":"1009066198","pt":1580663321890,"mc":[{"id":"1.168230755","rc":[{"batl":[[0,9.4,267.74]],"ltp":0.0,"tv":0.0,"id":13095168}]}]}
{"op":"mcm","clk":"1009071878","pt":1580663356428,"mc":[{"id":"1.168230755","rc":[{"batb":[[0,3.8,67.23],[1,3.55,5],[2,1.02,2]],"ltp":0.0,"tv":0.0,"id":13095168},{"batb":[[0,2.82,91.03],[1,2.8,6],[2,1.02,2]],"ltp":0.0,"tv":0.0,"id":13095165},{"batb":[[0,3.95,64.71],[1,3.55,5],[2,1.02,2]],"ltp":0.0,"tv":0.0,"id":14343850},{"batb":[[0,2.74,93.52],[1,2.66,6],[2,1.02,2]],"ltp":0.0,"tv":0.0,"id":14343845}]}]}
{"op":"mcm","clk":"1009081608","pt":1580663416530,"mc":[{"id":"1.168230755","rc":[{"batb":[[0,2.84,6],[1,2.82,91.03]],"ltp":0.0,"tv":0.0,"id":13095165}]}]}
{"op":"mcm","clk":"1009081826","pt":1580663417587,"mc":[{"id":"1.168230755","rc":[{"batb":[[0,4.2,60.77],[1,3.85,5]],"ltp":0.0,"tv":0.0,"id":13095168},{"batb":[[0,2.86,89.68],[1,2.84,6]],"ltp":0.0,"tv":0.0,"id":13095165},{"batb":[[0,4,5],[1,3.95,64.71]],"ltp":0.0,"tv":0.0,"id":14343850},{"batb":[[0,2.76,6],[1,1.02,2],[2,1.01,1.01]],"ltp":0.0,"tv":0.0,"id":14343845}]}]}
{"op":"mcm","clk":"1009081945","pt":1580663418172,"mc":[{"id":"1.168230755","rc":[{"batb":[[0,4.1,62.34],[1,4,5]],"ltp":0.0,"tv":0.0,"id":14343850},{"batb":[[0,2.84,90.22],[1,2.76,6],[2,1.02,2]],"ltp":0.0,"tv":0.0,"id":14343845}]}]}
{"op":"mcm","clk":"1009087882","pt":1580663455385,"mc":[{"id":"1.168230755","rc":[{"batl":[[0,9.4,27.39]],"ltp":0.0,"tv":0.0,"id":13095168}]}]}
{"op":"mcm","clk":"1009091290","pt":1580663478617,"mc":[{"id":"1.168230755","rc":[{"batb":[[1,1.02,2],[2,1.01,1.01]],"ltp":0.0,"tv":0.0,"id":13095165}]}]}
{"op":"mcm","clk":"1009091438","pt":1580663479627,"mc":[{"id":"1.168230755","rc":[{"batb":[[0,4.4,58.01],[1,4.3,5]],"ltp":0.0,"tv":0.0,"id":13095168},{"batb":[[0,2.88,94.96]],"ltp":0.0,"tv":0.0,"id":13095165},{"batb":[[0,4.2,5],[1,4.1,62.34]],"ltp":0.0,"tv":0.0,"id":14343850},{"batb":[[0,2.86,6],[1,1.02,2],[2,1.01,1.01]],"ltp":0.0,"tv":0.0,"id":14343845}]}]}
{"op":"mcm","clk":"1009091489","pt":1580663480001,"mc":[{"id":"1.168230755","rc":[{"batb":[[0,4.3,59.38],[1,4.2,5]],"ltp":0.0,"tv":0.0,"id":14343850},{"batb":[[0,2.92,87.69],[1,2.86,6],[2,1.02,2]],"ltp":0.0,"tv":0.0,"id":14343845}]}]}
{"op":"mcm","clk":"1009101441","pt":1580663540592,"mc":[{"id":"1.168230755","rc":[{"batb":[[0,4.5,5],[1,1.02,2],[2,1.01,1.01]],"ltp":0.0,"tv":0.0,"id":13095168},{"batb":[[0,2.94,6],[1,2.92,87.69]],"ltp":0.0,"tv":0.0,"id":14343845}]}]}
{"op":"mcm","clk":"1009101584","pt":1580663541504,"mc":[{"id":"1.168230755","rc":[{"batb":[[0,4.5,61.92]],"ltp":0.0,"tv":0.0,"id":13095168},{"batb":[[0,4.5,56.92],[1,4.4,5]],"ltp":0.0,"tv":0.0,"id":14343850},{"batb":[[0,2.96,86.63],[1,2.94,6]],"ltp":0.0,"tv":0.0,"id":14343845}]}]}
{"op":"mcm","clk":"1009112008","pt":1580663601569,"mc":[{"id":"1.168230755","rc":[{"batb":[[0,2.98,6],[1,2.96,86.63]],"ltp":0.0,"tv":0.0,"id":14343845}]}]}
{"op":"mcm","clk":"1009112117","pt":1580663602155,"mc":[{"id":"1.168230755","rc":[{"batb":[[0,4.6,5],[1,1.02,2],[2,1.01,1.01]],"ltp":0.0,"tv":0.0,"id":14343850},{"batb":[[1,1.02,2],[2,1.01,1.01]],"ltp":0.0,"tv":0.0,"id":14343845}]}]}
{"op":"mcm","clk":"1009115309","pt":1580663622008,"mc":[{"id":"1.168230755","rc":[{"batl":[[0,9.4,268.79]],"ltp":0.0,"tv":0.0,"id":13095168}]}]}
{"op":"mcm","clk":"1009122208","pt":1580663663139,"mc":[{"id":"1.168230755","rc":[{"batl":[[0,8.8,287.07],[1,9.2,6]],"ltp":0.0,"tv":0.0,"id":13095168},{"batl":[[0,4.6,351.76],[1,4.7,5]],"ltp":0.0,"tv":0.0,"id":13095165},{"batl":[[0,7.2,6],[1,7.4,339.99]],"ltp":0.0,"tv":0.0,"id":14343850},{"batl":[[0,4.3,407.14],[1,4.6,5]],"ltp":0.0,"tv":0.0,"id":14343845}]}]}
{"op":"mcm","clk":"1009127680","pt":1580663696279,"mc":[{"id":"1.168230755","rc":[{"batl":[[0,4.6,56.32]],"ltp":0.0,"tv":0.0,"id":13095165}]}]}
{"op":"mcm","clk":"1009127793","pt":1580663696872,"mc":[{"id":"1.168230755","rc":[{"batl":[[0,4.6,337.81]],"ltp":0.0,"tv":0.0,"id":13095165}]}]}
{"op":"mcm","clk":"1009132476","pt":1580663723600,"mc":[{"id":"1.168230755","rc":[{"batl":[[1,9.2,0]],"ltp":0.0,"tv":0.0,"id":13095168},{"batl":[[0,4.5,5],[1,4.7,0]],"ltp":0.0,"tv":0.0,"id":13095165}]}]}
{"op":"mcm","clk":"1009132626","pt":1580663724576,"mc":[{"id":"1.168230755","rc":[{"batl":[[0,8.6,6],[1,8.8,287.07]],"ltp":0.0,"tv":0.0,"id":13095168},{"batl":[[0,3.9,398.15],[1,4.5,5]],"ltp":0.0,"tv":0.0,"id":13095165},{"batl":[[0,4.1,426.65],[1,4.2,5]],"ltp":0.0,"tv":0.0,"id":14343845}]}]}
{"op":"mcm","clk":"1009143004","pt":1580663785573,"mc":[{"id":"1.168230755","rc":[{"batl":[[0,3.85,5],[1,3.9,398.15]],"ltp":0.0,"tv":0.0,"id":13095165},{"batl":[[0,4,5],[1,4.2,0]],"ltp":0.0,"tv":0.0,"id":14343845}]}]}
{"op":"mcm","clk":"1009143037","pt":1580663785775,"mc":[{"id":"1.168230755","rc":[{"batl":[[0,3.95,442.9],[1,4,5]],"ltp":0.0,"tv":0.0,"id":14343845}]}]}
{"op":"mcm","clk":"1009152903","pt":1580663845973,"mc":[{"id":"1.168230755","rc":[{"batl":[[0,3.9,5],[1,3.95,442.9]],"ltp":0.0,"tv":0.0,"id":14343845}]}]}
{"op":"mcm","clk":"1009189456","pt":1580664080440,"mc":[{"id":"1.168230755","rc":[{"batl":[[1,3.9,0]],"ltp":0.0,"tv":0.0,"id":13095165}]}]}
{"op":"mcm","clk":"1009189573","pt":1580664081250,"mc":[{"id":"1.168230755","rc":[{"batl":[[0,3.7,419.65],[1,3.85,5]],"ltp":0.0,"tv":0.0,"id":13095165}]}]}
{"op":"mcm","clk":"1009218463","pt":1580664268492,"mc":[{"id":"1.168230755","rc":[{"batb":[[0,4.5,56.92]],"ltp":0.0,"tv":0.0,"id":13095168},{"batb":[[0,2.88,88.96]],"ltp":0.0,"tv":0.0,"id":13095165}]}]}
{"op":"mcm","clk":"1009218600","pt":1580664269409,"mc":[{"id":"1.168230755","rc":[{"batb":[[0,1.02,2],[1,1.01,1.01],[2,1.01,0]],"batl":[[0,7.4,339.99],[1,7.4,0]],"ltp":0.0,"tv":0.0,"id":14343850},{"batb":[[0,2.48,103.51]],"ltp":0.0,"tv":0.0,"id":14343845}]}]}
{"op":"mcm","clk":"1009218720","pt":1580664270199,"mc":[{"id":"1.168230755","rc":[{"batl":[[0,8.8,287.07],[1,8.8,0]],"ltp":0.0,"tv":0.0,"id":13095168},{"batl":[[1,3.85,0]],"ltp":0.0,"tv":0.0,"id":13095165},{"batb":[[0,3.4,75.21],[1,1.02,2],[2,1.01,1.01]],"ltp":0.0,"tv":0.0,"id":14343850},{"batl":[[0,3.95,442.9],[1,3.95,0]],"ltp":0.0,"tv":0.0,"id":14343845}]}]}
{"op":"mcm","clk":"1009219269","pt":1580664273604,"mc":[{"id":"1.168230755","rc":[{"batb":[[0,4.6,5]],"ltp":0.0,"tv":0.0,"id":13095168},{"batb":[[0,2.9,6]],"ltp":0.0,"tv":0.0,"id":13095165},{"batb":[[0,3.45,5]],"ltp":0.0,"tv":0.0,"id":14343850},{"batb":[[0,2.5,6]],"ltp":0.0,"tv":0.0,"id":14343845}]}]}
{"op":"mcm","clk":"1009219307","pt":1580664273809,"mc":[{"id":"1.168230755","rc":[{"batb":[[0,4,64.07],[1,3.45,5],[2,1.02,2]],"ltp":0.0,"tv":0.0,"id":14343850},{"batb":[[0,2.54,101.12],[1,2.5,6],[2,1.02,2]],"ltp":0.0,"tv":0.0,"id":14343845}]}]}
{"op":"mcm","clk":"1009228779","pt":1580664334485,"mc":[{"id":"1.168230755","rc":[{"batb":[[0,4.1,5],[1,1.02,2],[2,1.01,1.01]],"ltp":0.0,"tv":0.0,"id":14343850},{"batb":[[0,2.84,90.22],[1,2.56,6]],"ltp":0.0,"tv":0.0,"id":14343845}]}]}
{"op":"mcm","clk":"1009228852","pt":1580664334966,"mc":[{"id":"1.168230755","rc":[{"batb":[[0,4.3,59.38],[1,4.1,5],[2,1.02,2]],"ltp":0.0,"tv":0.0,"id":14343850}]}]}
{"op":"mcm","clk":"1009237343","pt":1580664395497,"mc":[{"id":"1.168230755","rc":[{"batb":[[0,2.86,6],[1,2.84,90.22]],"ltp":0.0,"tv":0.0,"id":14343845}]}]}
{"op":"mcm","clk":"1009237471","pt":1580664396167,"mc":[{"id":"1.168230755","rc":[{"batb":[[0,4.5,56.92],[1,4.4,5]],"ltp":0.0,"tv":0.0,"id":14343850},{"batb":[[0,2.92,87.69],[1,2.86,6]],"ltp":0.0,"tv":0.0,"id":14343845}]}]}
{"op":"mcm","clk":"1009246150","pt":1580664456422,"mc":[{"id":"1.168230755","rc":[{"batb":[[0,2.94,6],[1,2.92,87.69]],"ltp":0.0,"tv":0.0,"id":14343845}]}]}
{"op":"mcm","clk":"1009246244","pt":1580664457051,"mc":[{"id":"1.168230755","rc":[{"batb":[[0,4.6,5],[1,1.02,2],[2,1.01,1.01]],"ltp":0.0,"tv":0.0,"id":14343850},{"batb":[[0,2.96,86.63],[1,2.94,6]],"ltp":0.0,"tv":0.0,"id":14343845}]}]}
{"op":"mcm","clk":"1009255448","pt":1580664517391,"mc":[{"id":"1.168230755","rc":[{"batb":[[0,2.98,6],[1,2.96,86.63]],"ltp":0.0,"tv":0.0,"id":14343845}]}]}
{"op":"mcm","clk":"1009255705","pt":1580664519201,"mc":[{"id":"1.168230755","rc":[{"batb":[[1,1.02,2],[2,1.01,1.01]],"ltp":0.0,"tv":0.0,"id":14343845}]}]}
{"op":"mcm","clk":"1009256510","pt":1580664524587,"mc":[{"id":"1.168230755","rc":[{"batl":[[0,6,420.93]],"ltp":0.0,"tv":0.0,"id":13095168}]}]}
{"op":"mcm","clk":"1009264499","pt":1580664578545,"mc":[{"id":"1.168230755","rc":[{"batl":[[0,5.9,4],[1,6,420.93]],"ltp":0.0,"tv":0.0,"id":13095168},{"batl":[[0,3.6,431.16],[1,3.65,5]],"ltp":0.0,"tv":0.0,"id":13095165},{"batl":[[0,7.2,6],[1,7.4,339.99]],"ltp":0.0,"tv":0.0,"id":14343850},{"batl":[[0,3.9,5],[1,3.95,442.9]],"ltp":0.0,"tv":0.0,"id":14343845}]}]}
{"op":"mcm","clk":"1009266447","pt":1580664591443,"mc":[{"id":"1.168230755","rc":[{"batl":[[0,3.85,454.3],[1,3.9,5]],"ltp":0.0,"tv":0.0,"id":14343845}]}]}
{"op":"mcm","clk":"1009273714","pt":1580664638561,"mc":[{"id":"1.168230755","rc":[{"batl":[[1,3.65,0]],"ltp":0.0,"tv":0.0,"id":13095165}]}]}
{"op":"mcm","clk":"1009273798","pt":1580664639034,"mc":[{"id":"1.168230755","rc":[{"batl":[[0,3.55,5]],"ltp":0.0,"tv":0.0,"id":13095165},{"batl":[[0,3.8,5],[1,3.85,454.3]],"ltp":0.0,"tv":0.0,"id":14343845}]}]}
{"op":"mcm","clk":"1009328974","pt":1580664987560,"mc":[{"id":"1.168230755","rc":[{"batl":[[0,6.6,381.33],[1,7.2,6]],"ltp":0.0,"tv":0.0,"id":14343850}]}]}
{"op":"mcm","clk":"1009341489","pt":1580665062445,"mc":[{"id":"1.168230755","rc":[{"batb":[[0,1.02,2],[1,1.01,1.01],[2,1.01,0]],"ltp":0.0,"tv":0.0,"id":13095168},{"batb":[[0,1.02,2],[1,1.01,1.01],[2,1.01,0]],"ltp":0.0,"tv":0.0,"id":13095165},{"batb":[[0,1.02,2],[1,1.01,1.01],[2,1.01,0]],"ltp":0.0,"tv":0.0,"id":14343850},{"batb":[[0,1.02,2],[1,1.01,1.01],[2,1.01,0]],"ltp":0.0,"tv":0.0,"id":14343845}]}]}
{"op":"mcm","clk":"1009341711","pt":1580665063634,"mc":[{"id":"1.168230755","rc":[{"batb":[[0,3.4,75.21],[1,1.03,137],[2,1.02,2]],"ltp":0.0,"tv":0.0,"id":13095168},{"batb":[[0,2.74,93.52],[1,1.03,137],[2,1.02,2]],"ltp":0.0,"tv":0.0,"id":13095165},{"batb":[[0,4.7,5],[1,1.02,2],[2,1.01,1.01]],"ltp":0.0,"tv":0.0,"id":14343850},{"batb":[[0,3,6],[1,1.02,2],[2,1.01,1.01]],"ltp":0.0,"tv":0.0,"id":14343845}]}]}
{"op":"mcm","clk":"1009352115","pt":1580665123642,"mc":[{"id":"1.168230755","rc":[{"batb":[[0,2.76,137],[1,2.74,93.52]],"ltp":0.0,"tv":0.0,"id":13095165}]}]}
{"op":"mcm","clk":"1009352242","pt":1580665124404,"mc":[{"id":"1.168230755","rc":[{"batb":[[0,4,64.07],[1,3.45,137]],"ltp":0.0,"tv":0.0,"id":13095168},{"batb":[[0,2.78,92.16],[1,2.76,137]],"ltp":0.0,"tv":0.0,"id":13095165}]}]}
{"op":"mcm","clk":"1009362697","pt":1580665185517,"mc":[{"id":"1.168230755","rc":[{"batb":[[0,4.1,137],[1,1.02,2],[2,1.01,1.01]],"ltp":0.0,"tv":0.0,"id":13095168},{"batb":[[0,2.82,91.03],[1,2.8,137]],"ltp":0.0,"tv":0.0,"id":13095165}]}]}
{"op":"mcm","clk":"1009362743","pt":1580665185782,"mc":[{"id":"1.168230755","rc":[{"batb":[[0,4.2,60.77],[1,4.1,137],[2,1.02,2]],"ltp":0.0,"tv":0.0,"id":13095168}]}]}
{"op":"mcm","clk":"1009373018","pt":1580665247455,"mc":[{"id":"1.168230755","rc":[{"batb":[[0,4.3,137],[1,1.02,2],[2,1.01,1.01]],"ltp":0.0,"tv":0.0,"id":13095168},{"batb":[[0,2.86,89.68],[1,2.84,137]],"ltp":0.0,"tv":0.0,"id":13095165}]}]}
{"op":"mcm","clk":"1009373058","pt":1580665247691,"mc":[{"id":"1.168230755","rc":[{"batb":[[0,4.4,58.01],[1,4.3,137],[2,1.02,2]],"ltp":0.0,"tv":0.0,"id":13095168}]}]}
{"op":"mcm","clk":"1009383050","pt":1580665307586,"mc":[{"id":"1.168230755","rc":[{"batb":[[1,1.02,2],[2,1.01,1.01]],"ltp":0.0,"tv":0.0,"id":13095165}]}]}
{"op":"mcm","clk":"1009383189","pt":1580665308272,"mc":[{"id":"1.168230755","rc":[{"batb":[[0,4.5,137],[1,1.02,2],[2,1.01,1.01]],"ltp":0.0,"tv":0.0,"id":13095168},{"batb":[[0,2.88,137]],"ltp":0.0,"tv":0.0,"id":13095165}]}]}
{"op":"mcm","clk":"1009410877","pt":1580665502165,"mc":[{"id":"1.168230755","rc":[{"batl":[[0,6.6,39.06]],"ltp":0.0,"tv":0.0,"id":14343850},{"batb":[[0,3,91.57]],"ltp":0.0,"tv":0.0,"id":14343845}]}]}
{"op":"mcm","clk":"1009421746","pt":1580665587604,"mc":[{"id":"1.168230755","rc":[{"batl":[[0,7.2,6],[1,7.2,0]],"ltp":0.0,"tv":0.0,"id":14343850}]}]}
{"op":"mcm","clk":"1009421779","pt":1580665587764,"mc":[{"id":"1.168230755","rc":[{"batl":[[0,6.6,379.71],[1,7.2,6]],"ltp":0.0,"tv":0.0,"id":14343850}]}]}
{"op":"mcm","clk":"1009439602","pt":1580665742467,"mc":[{"id":"1.168230755","rc":[{"batl":[[0,7.2,6],[1,7.2,0]],"ltp":0.0,"tv":0.0,"id":14343850}]}]}
{"op":"mcm","clk":"1009439623","pt":1580665742680,"mc":[{"id":"1.168230755","rc":[{"batl":[[0,6.6,39.06],[1,7.2,6]],"ltp":0.0,"tv":0.0,"id":14343850}]}]}
{"op":"mcm","clk":"1009454022","pt":1580665887497,"mc":[{"id":"1.168230755","rc":[{"batl":[[0,7.2,6],[1,7.2,0]],"ltp":0.0,"tv":0.0,"id":14343850}]}]}
{"op":"mcm","clk":"1009454044","pt":1580665887709,"mc":[{"id":"1.168230755","rc":[{"batl":[[0,6.6,381.33],[1,7.2,6]],"ltp":0.0,"tv":0.0,"id":14343850}]}]}
{"op":"mcm","clk":"1009499344","pt":1580666344337,"mc":[{"id":"1.168230755","rc":[{"batb":[[0,3,6]],"ltp":0.0,"tv":0.0,"id":14343845}]}]}
{"op":"mcm","clk":"1009510102","pt":1580666455637,"mc":[{"id":"1.168230755","rc":[{"batb":[[0,1.02,2],[1,1.01,1.01],[2,1.01,0]],"ltp":0.0,"tv":0.0,"id":14343850},{"batb":[[0,2.5,102.82]],"ltp":0.0,"tv":0.0,"id":14343845}]}]}
{"op":"mcm","clk":"1009510221","pt":1580666456636,"mc":[{"id":"1.168230755","rc":[{"batb":[[0,3.4,75.21],[1,1.03,137],[2,1.02,2]],"ltp":0.0,"tv":0.0,"id":13095168},{"batb":[[0,2.58,99.56],[1,1.03,137],[2,1.02,2]],"ltp":0.0,"tv":0.0,"id":13095165},{"batb":[[0,3.55,5],[1,1.02,2],[2,1.01,1.01]],"ltp":0.0,"tv":0.0,"id":14343850},{"batb":[[0,2.52,6]],"ltp":0.0,"tv":0.0,"id":14343845}]}]}
