{"op":"mcm","clk":"1001501051","pt":1580587070468,"mc":[{"id":"1.168230754","marketDefinition":{"bspMarket":false,"turnInPlayEnabled":true,"persistenceEnabled":true,"marketBaseRate":5.0,"eventId":"29681775","eventTypeId":"2","numberOfWinners":1,"bettingType":"ODDS","marketType":"MATCH_ODDS","marketTime":"2020-02-02T18:00:00.000Z","suspendTime":"2020-02-02T18:00:00.000Z","bspReconciled":false,"complete":true,"inPlay":false,"crossMatching":true,"runnersVoidable":false,"numberOfActiveRunners":2,"betDelay":0,"status":"OPEN","runners":[{"status":"ACTIVE","sortPriority":1,"id":2263603,"name":"Madison Brengle"},{"status":"ACTIVE","sortPriority":2,"id":3622149,"name":"Stefanie Voegele"}],"regulators":["MR_INT"],"discountAllowed":false,"timezone":"UTC","openDate":"2020-02-02T18:00:00.000Z","version":3147219548,"name":"Match Odds","eventName":"Brengle v Voegele"},"rc":[{"batb":[[0,1.05,152.2],[1,1.04,168.86],[2,1.03,237.77]],"ltp":0.0,"tv":0.0,"id":2263603},{"batb":[[0,1.05,152.2],[1,1.04,168.86],[2,1.03,237.77]],"ltp":0.0,"tv":0.0,"id":3622149}]}]}
{"op":"mcm","clk":"1001501273","pt":1580587071655,"mc":[{"id":"1.168230754","marketDefinition":{"bspMarket":false,"turnInPlayEnabled":true,"persistenceEnabled":true,"marketBaseRate":5.0,"eventId":"29681775","eventTypeId":"2","numberOfWinners":1,"bettingType":"ODDS","marketType":"MATCH_ODDS","marketTime":"2020-02-02T18:00:00.000Z","suspendTime":"2020-02-02T18:00:00.000Z","bspReconciled":false,"complete":true,"inPlay":false,"crossMatching":true,"runnersVoidable":false,"numberOfActiveRunners":2,"betDelay":0,"status":"OPEN","runners":[{"status":"ACTIVE","sortPriority":1,"id":2263603,"name":"Madison Brengle"},{"status":"ACTIVE","sortPriority":2,"id":3622149,"name":"Stefanie Voegele"}],"regulators":["MR_INT"],"discountAllowed":false,"timezone":"UTC","openDate":"2020-02-02T18:00:00.000Z","version":3147219548,"name":"Match Odds","eventName":"Brengle v Voegele"}}]}
{"op":"mcm","clk":"1001501657","pt":1580587073688,"mc":[{"id":"1.168230754","marketDefinition":{"bspMarket":false,"turnInPlayEnabled":true,"persistenceEnabled":true,"marketBaseRate":5.0,"eventId":"29681775","eventTypeId":"2","numberOfWinners":1,"bettingType":"ODDS","marketType":"MATCH_ODDS","marketTime":"2020-02-02T18:00:00.000Z","suspendTime":"2020-02-02T18:00:00.000Z","bspReconciled":false,"complete":true,"inPlay":false,"crossMatching":true,"runnersVoidable":false,"numberOfActiveRunners":2,"betDelay":0,"status":"OPEN","runners":[{"status":"ACTIVE","sortPriority":1,"id":2263603,"name":"Madison Brengle"},{"status":"ACTIVE","sortPriority":2,"id":3622149,"name":"Stefanie Voegele"}],"regulators":["MR_INT"],"discountAllowed":true,"timezone":"UTC","openDate":"2020-02-02T18:00:00.000Z","version":3147219548,"name":"Match Odds","eventName":"Brengle v Voegele"}}]}
{"op":"mcm","clk":"1001642682","pt":1580587834624,"mc":[{"id":"1.168230754","rc":[{"batb":[[0,1.06,50.48],[1,1.05,152.2],[2,1.04,168.86]],"ltp":0.0,"tv":0.0,"id":2263603}]}]}
{"op":"mcm","clk":"1001642705","pt":1580587834730,"mc":[{"id":"1.168230754","rc":[{"batb":[[0,1.06,50.48],[1,1.05,152.2],[2,1.04,168.86]],"ltp":0.0,"tv":0.0,"id":3622149}]}]}
{"op":"mcm","clk":"1001666262","pt":1580587950509,"mc":[{"id":"1.168230754","rc":[{"batl":[[0,990,2.2]],"ltp":0.0,"tv":0.0,"id":2263603},{"batl":[[0,990,2.2]],"ltp":0.0,"tv":0.0,"id":3622149}]}]}
{"op":"mcm","clk":"1001962084","pt":1580589590357,"mc":[{"id":"1.168230754","rc":[{"batb":[[0,1.12,92.38],[1,1.06,50.48],[2,1.05,152.2]],"ltp":0.0,"tv":0.0,"id":2263603},{"batb":[[0,1.12,92.38],[1,1.06,50.48],[2,1.05,152.2]],"ltp":0.0,"tv":0.0,"id":3622149}]}]}
{"op":"mcm","clk":"1002002505","pt":1580589833287,"mc":[{"id":"1.168230754","rc":[{"batb":[[0,1.13,7.5],[1,1.12,92.38],[2,1.06,50.48]],"ltp":0.0,"tv":0.0,"id":2263603}]}]}
{"op":"mcm","clk":"1002002690","pt":1580589834198,"mc":[{"id":"1.168230754","rc":[{"batb":[[0,1.13,7.56],[1,1.12,92.38],[2,1.06,50.48]],"ltp":0.0,"tv":0.0,"id":3622149}]}]}
{"op":"mcm","clk":"1002148956","pt":1580590931535,"mc":[{"id":"1.168230754","rc":[{"batb":[[0,1.14,15.12],[1,1.13,7.5],[2,1.12,92.38]],"ltp":0.0,"tv":0.0,"id":2263603},{"batb":[[0,1.14,15.12],[1,1.13,7.56],[2,1.12,92.38]],"ltp":0.0,"tv":0.0,"id":3622149}]}]}
{"op":"mcm","clk":"1002149004","pt":1580590931907,"mc":[{"id":"1.168230754","rc":[{"batl":[[0,11,3.36],[1,990,2.2]],"ltp":0.0,"tv":0.0,"id":2263603},{"batl":[[0,13.5,3.36],[1,990,2.2]],"ltp":0.0,"tv":0.0,"id":3622149}]}]}
{"op":"mcm","clk":"1002246284","pt":1580591803437,"mc":[{"id":"1.168230754","rc":[{"batb":[[0,1.2,840.19],[1,1.14,15.12],[2,1.13,7.5]],"ltp":0.0,"tv":0.0,"id":2263603},{"batb":[[0,1.2,840.19],[1,1.14,15.12],[2,1.13,7.56]],"ltp":0.0,"tv":0.0,"id":3622149}]}]}
{"op":"mcm","clk":"1002252301","pt":1580591859431,"mc":[{"id":"1.168230754","rc":[{"batb":[[1,1.13,7.56],[2,1.12,92.38]],"ltp":0.0,"tv":0.0,"id":3622149}]}]}
{"op":"mcm","clk":"1002252349","pt":1580591859814,"mc":[{"id":"1.168230754","rc":[{"batb":[[1,1.13,7.5],[2,1.12,92.38]],"ltp":0.0,"tv":0.0,"id":2263603}]}]}
{"op":"mcm","clk":"1002258330","pt":1580591907002,"mc":[{"id":"1.168230754","rc":[{"batb":[[0,1.21,15.12],[1,1.2,840.19],[2,1.13,7.5]],"ltp":0.0,"tv":0.0,"id":2263603},{"batb":[[0,1.21,15.12],[1,1.2,840.19],[2,1.13,7.56]],"ltp":0.0,"tv":0.0,"id":3622149}]}]}
{"op":"mcm","clk":"1002259221","pt":1580591914816,"mc":[{"id":"1.168230754","rc":[{"batb":[[0,1.3,840.19],[1,1.21,15.12]],"ltp":0.0,"tv":0.0,"id":2263603},{"batb":[[0,1.3,840.19],[1,1.21,15.12]],"ltp":0.0,"tv":0.0,"id":3622149}]}]}
{"op":"mcm","clk":"1002263905","pt":1580591954480,"mc":[{"id":"1.168230754","rc":[{"batb":[[1,1.13,7.5],[2,1.12,92.38]],"ltp":0.0,"tv":0.0,"id":2263603},{"batb":[[1,1.13,7.56],[2,1.12,92.38]],"ltp":0.0,"tv":0.0,"id":3622149}]}]}
{"op":"mcm","clk":"1002269732","pt":1580592001424,"mc":[{"id":"1.168230754","rc":[{"batb":[[0,1.31,14.28],[1,1.3,840.19],[2,1.13,7.5]],"ltp":0.0,"tv":0.0,"id":2263603},{"batb":[[0,1.31,15.12],[1,1.3,840.19],[2,1.13,7.56]],"ltp":0.0,"tv":0.0,"id":3622149}]}]}
{"op":"mcm","clk":"1002311816","pt":1580592379567,"mc":[{"id":"1.168230754","rc":[{"batb":[[0,1.31,21.79],[2,1.12,92.38]],"ltp":0.0,"tv":0.0,"id":2263603}]}]}
{"op":"mcm","clk":"1002311885","pt":1580592380246,"mc":[{"id":"1.168230754","rc":[{"batb":[[0,1.31,22.69],[2,1.12,92.38]],"ltp":0.0,"tv":0.0,"id":3622149}]}]}
{"op":"mcm","clk":"1002321450","pt":1580592470257,"mc":[{"id":"1.168230754","rc":[{"batb":[[0,1.36,840.19],[1,1.31,21.79]],"ltp":0.0,"tv":0.0,"id":2263603},{"batb":[[0,1.36,840.19],[1,1.31,22.69]],"ltp":0.0,"tv":0.0,"id":3622149}]}]}
{"op":"mcm","clk":"1002325546","pt":1580592514533,"mc":[{"id":"1.168230754","rc":[{"batb":[[1,1.31,7.56]],"ltp":0.0,"tv":0.0,"id":3622149}]}]}
{"op":"mcm","clk":"1002325579","pt":1580592514848,"mc":[{"id":"1.168230754","rc":[{"batb":[[1,1.31,7.5]],"ltp":0.0,"tv":0.0,"id":2263603}]}]}
{"op":"mcm","clk":"1002329906","pt":1580592561908,"mc":[{"id":"1.168230754","rc":[{"batb":[[0,1.37,13.44],[1,1.36,840.19],[2,1.31,7.5]],"ltp":0.0,"tv":0.0,"id":2263603},{"batb":[[0,1.37,15.12],[1,1.36,840.19],[2,1.31,7.56]],"ltp":0.0,"tv":0.0,"id":3622149}]}]}
{"op":"mcm","clk":"1002445598","pt":1580593783088,"mc":[{"id":"1.168230754","rc":[{"batb":[[0,1.7,35.12],[1,1.37,13.44],[2,1.36,840.19]],"ltp":0.0,"tv":0.0,"id":2263603},{"batb":[[0,1.78,34.16],[1,1.37,15.12],[2,1.36,840.19]],"ltp":0.0,"tv":0.0,"id":3622149}]}]}
{"op":"mcm","clk":"1002446853","pt":1580593802522,"mc":[{"id":"1.168230754","rc":[{"batb":[[1,1.36,840.19],[2,1.31,7.5]],"ltp":0.0,"tv":0.0,"id":2263603},{"batb":[[1,1.36,840.19],[2,1.31,7.56]],"ltp":0.0,"tv":0.0,"id":3622149}]}]}
{"op":"mcm","clk":"1002451543","pt":1580593864113,"mc":[{"id":"1.168230754","rc":[{"batb":[[0,1.79,11.76],[1,1.78,34.16],[2,1.36,840.19]],"ltp":0.0,"tv":0.0,"id":3622149}]}]}
{"op":"mcm","clk":"1002492283","pt":1580594405990,"mc":[{"id":"1.168230754","rc":[{"batb":[[0,1.88,62.09],[1,1.7,35.12],[2,1.36,840.19]],"ltp":0.0,"tv":0.0,"id":2263603},{"batb":[[0,1.89,62.09],[1,1.81,33.66],[2,1.79,11.76]],"ltp":0.0,"tv":0.0,"id":3622149}]}]}
{"op":"mcm","clk":"1002492381","pt":1580594407390,"mc":[{"id":"1.168230754","rc":[{"batb":[[2,1.36,840.19]],"ltp":0.0,"tv":0.0,"id":3622149}]}]}
{"op":"mcm","clk":"1002502555","pt":1580594546370,"mc":[{"id":"1.168230754","rc":[{"batb":[[0,1.9,62.09]],"ltp":0.0,"tv":0.0,"id":2263603}]}]}
{"op":"mcm","clk":"1002508971","pt":1580594647201,"mc":[{"id":"1.168230754","rc":[{"batb":[[0,1.9,62.09]],"ltp":0.0,"tv":0.0,"id":3622149}]}]}
{"op":"mcm","clk":"1002527122","pt":1580594932596,"mc":[{"id":"1.168230754","rc":[{"batb":[[1,1.36,840.19],[2,1.12,92.38]],"ltp":0.0,"tv":0.0,"id":2263603},{"batb":[[1,1.36,840.19],[2,1.31,7.56]],"ltp":0.0,"tv":0.0,"id":3622149}]}]}
{"op":"mcm","clk":"1002527183","pt":1580594933490,"mc":[{"id":"1.168230754","rc":[{"batb":[[0,1.91,31.62],[1,1.9,62.09],[2,1.36,840.19]],"ltp":0.0,"tv":0.0,"id":2263603},{"batb":[[0,1.91,31.62],[1,1.9,62.09],[2,1.36,840.19]],"ltp":0.0,"tv":0.0,"id":3622149}]}]}
{"op":"mcm","clk":"1002530181","pt":1580594973596,"mc":[{"id":"1.168230754","rc":[{"batb":[[2,1.51,37.86]],"ltp":0.0,"tv":0.0,"id":2263603}]}]}
{"op":"mcm","clk":"1002530234","pt":1580594974088,"mc":[{"id":"1.168230754","rc":[{"batb":[[2,1.71,37.86]],"ltp":0.0,"tv":0.0,"id":2263603},{"batb":[[2,1.61,37.86]],"ltp":0.0,"tv":0.0,"id":3622149}]}]}
{"op":"mcm","clk":"1002530300","pt":1580594974981,"mc":[{"id":"1.168230754","rc":[{"batb":[[2,1.71,37.86]],"ltp":0.0,"tv":0.0,"id":3622149}]}]}
{"op":"mcm","clk":"1002604373","pt":1580595955141,"mc":[{"id":"1.168230754","rc":[{"trd":[[1.91,20]],"batb":[[0,1.9,62.09],[1,1.71,37.86],[2,1.61,37.86]],"ltp":1.91,"tv":20.0,"id":2263603}],"tv":20.0}]}
{"op":"mcm","clk":"1002604763","pt":1580595960588,"mc":[{"id":"1.168230754","rc":[{"batb":[[0,1.71,37.86],[1,1.61,37.86],[2,1.51,37.86]],"ltp":1.91,"tv":20.0,"id":2263603}]}]}
{"op":"mcm","clk":"1002604773","pt":1580595960691,"mc":[{"id":"1.168230754","rc":[{"batb":[[0,1.89,62.09],[1,1.71,37.86],[2,1.61,37.86]],"ltp":1.91,"tv":20.0,"id":2263603}]}]}
{"op":"mcm","clk":"1002620677","pt":1580596186089,"mc":[{"id":"1.168230754","rc":[{"batb":[[0,1.71,37.86],[1,1.61,37.86],[2,1.51,37.86]],"ltp":1.91,"tv":20.0,"id":2263603},{"batb":[[1,1.71,37.86],[2,1.61,37.86]],"ltp":0.0,"tv":0.0,"id":3622149}]}]}
{"op":"mcm","clk":"1002644244","pt":1580596525212,"mc":[{"id":"1.168230754","rc":[{"batb":[[0,1.84,32.97],[1,1.82,15.14],[2,1.71,37.86]],"ltp":1.91,"tv":20.0,"id":2263603},{"batb":[[1,1.84,15.14],[2,1.71,37.86]],"ltp":0.0,"tv":0.0,"id":3622149}]}]}
{"op":"mcm","clk":"1002655246","pt":1580596715588,"mc":[{"id":"1.168230754","rc":[{"batb":[[0,1.9,31.86],[1,1.89,15.14]],"ltp":1.91,"tv":20.0,"id":2263603},{"batb":[[1,1.9,15.14]],"ltp":0.0,"tv":0.0,"id":3622149}]}]}
{"op":"mcm","clk":"1002655808","pt":1580596725521,"mc":[{"id":"1.168230754","rc":[{"batb":[[1,1.89,62.09]],"ltp":1.91,"tv":20.0,"id":2263603}]}]}
{"op":"mcm","clk":"1002655829","pt":1580596725924,"mc":[{"id":"1.168230754","rc":[{"batb":[[1,1.9,60.58]],"ltp":0.0,"tv":0.0,"id":3622149}]}]}
{"op":"mcm","clk":"1002694509","pt":1580597384405,"mc":[{"id":"1.168230754","rc":[{"batb":[[0,1.91,31.39]],"ltp":0.0,"tv":0.0,"id":3622149}]}]}
{"op":"mcm","clk":"1002707575","pt":1580597594621,"mc":[{"id":"1.168230754","rc":[{"batb":[[0,1.9,52.96]],"ltp":1.91,"tv":20.0,"id":2263603},{"batb":[[0,1.91,52.28]],"ltp":0.0,"tv":0.0,"id":3622149}]}]}
{"op":"mcm","clk":"1002737375","pt":1580598050241,"mc":[{"id":"1.168230754","rc":[{"trd":[[1.89,124.08],[1.9,105.92]],"batb":[[0,1.71,37.91],[1,1.61,37.86],[2,1.51,37.86]],"ltp":1.89,"tv":249.99,"id":2263603}],"tv":249.99}]}
{"op":"mcm","clk":"1002737431","pt":1580598050917,"mc":[{"id":"1.168230754","rc":[{"batb":[[0,1.78,57.62],[1,1.71,37.86],[2,1.61,37.86]],"ltp":1.89,"tv":249.99,"id":2263603},{"batb":[[0,1.91,34.39]],"ltp":0.0,"tv":0.0,"id":3622149}]}]}
{"op":"mcm","clk":"1002738014","pt":1580598058960,"mc":[{"id":"1.168230754","rc":[{"batl":[[0,2.1,62.09],[1,11,3.36],[2,990,2.2]],"ltp":1.89,"tv":249.99,"id":2263603}]}]}
{"op":"mcm","clk":"1002738330","pt":1580598062643,"mc":[{"id":"1.168230754","rc":[{"batl":[[0,2.02,62.09]],"ltp":1.89,"tv":249.99,"id":2263603},{"batb":[[0,1.92,60.58],[1,1.91,34.39]],"ltp":0.0,"tv":0.0,"id":3622149}]}]}
{"op":"mcm","clk":"1002738345","pt":1580598062851,"mc":[{"id":"1.168230754","rc":[{"batb":[[1,1.81,37.86]],"ltp":0.0,"tv":0.0,"id":3622149}]}]}
{"op":"mcm","clk":"1002740456","pt":1580598091138,"mc":[{"id":"1.168230754","rc":[{"batl":[[1,990,2.2],[2,990,0]],"ltp":1.89,"tv":249.99,"id":2263603}]}]}
{"op":"mcm","clk":"1002744208","pt":1580598148581,"mc":[{"id":"1.168230754","rc":[{"batb":[[0,1.88,54.46],[1,1.87,62.09],[2,1.71,37.86]],"ltp":1.89,"tv":249.99,"id":2263603}]}]}
{"op":"mcm","clk":"1002758107","pt":1580598362631,"mc":[{"id":"1.168230754","rc":[{"batb":[[0,1.87,117.13],[1,1.71,37.86],[2,1.61,37.86]],"ltp":1.89,"tv":249.99,"id":2263603}]}]}
{"op":"mcm","clk":"1002758366","pt":1580598365632,"mc":[{"id":"1.168230754","rc":[{"batb":[[0,1.87,55.04],[1,1.86,62.09],[2,1.71,37.86]],"ltp":1.89,"tv":249.99,"id":2263603},{"batb":[[0,1.94,60.58]],"ltp":0.0,"tv":0.0,"id":3622149}]}]}
{"op":"mcm","clk":"1002758912","pt":1580598373324,"mc":[{"id":"1.168230754","rc":[{"batl":[[0,2,62.09]],"ltp":1.89,"tv":249.99,"id":2263603}]}]}
{"op":"mcm","clk":"1002805304","pt":1580598998466,"mc":[{"id":"1.168230754","rc":[{"batl":[[0,2,70.49]],"ltp":1.89,"tv":249.99,"id":2263603}]}]}
{"op":"mcm","clk":"1002805357","pt":1580598999203,"mc":[{"id":"1.168230754","rc":[{"batb":[[0,1.87,64.69]],"ltp":1.89,"tv":249.99,"id":2263603},{"batb":[[0,2,8.4],[1,1.94,60.58],[2,1.81,37.86]],"batl":[[0,2.16,8.4],[1,13.5,3.36],[2,990,2.2]],"ltp":0.0,"tv":0.0,"id":3622149}]}]}
{"op":"mcm","clk":"1002806514","pt":1580599017265,"mc":[{"id":"1.168230754","rc":[{"batl":[[1,990,2.2],[2,990,0]],"ltp":0.0,"tv":0.0,"id":3622149}]}]}
{"op":"mcm","clk":"1002876357","pt":1580599948184,"mc":[{"id":"1.168230754","rc":[{"batb":[[0,1.87,9.65]],"ltp":1.89,"tv":249.99,"id":2263603}]}]}
{"op":"mcm","clk":"1002877281","pt":1580599960601,"mc":[{"id":"1.168230754","rc":[{"batb":[[1,1.71,37.86],[2,1.61,37.86]],"ltp":1.89,"tv":249.99,"id":2263603}]}]}
{"op":"mcm","clk":"1002877286","pt":1580599960706,"mc":[{"id":"1.168230754","rc":[{"batb":[[1,1.85,62.09],[2,1.71,37.86]],"ltp":1.89,"tv":249.99,"id":2263603}]}]}
{"op":"mcm","clk":"1002897400","pt":1580600260487,"mc":[{"id":"1.168230754","rc":[{"batl":[[1,2.28,18.48],[2,990,2.2]],"ltp":1.89,"tv":249.99,"id":2263603}]}]}
{"op":"mcm","clk":"1002898309","pt":1580600274406,"mc":[{"id":"1.168230754","rc":[{"batl":[[1,2.28,18.48],[2,990,2.2]],"ltp":0.0,"tv":0.0,"id":3622149}]}]}
{"op":"mcm","clk":"1002975931","pt":1580601432767,"mc":[{"id":"1.168230754","rc":[{"batb":[[2,1.77,79.65]],"ltp":1.89,"tv":249.99,"id":2263603},{"batb":[[2,1.85,72.16]],"ltp":0.0,"tv":0.0,"id":3622149}]}]}
{"op":"mcm","clk":"1003041296","pt":1580602282649,"mc":[{"id":"1.168230754","rc":[{"batb":[[0,2,65.35]],"ltp":0.0,"tv":0.0,"id":3622149}]}]}
{"op":"mcm","clk":"1003058231","pt":1580602464347,"mc":[{"id":"1.168230754","rc":[{"batb":[[0,1.87,81.46]],"ltp":1.89,"tv":249.99,"id":2263603}]}]}
{"op":"mcm","clk":"1003058367","pt":1580602465588,"mc":[{"id":"1.168230754","rc":[{"batb":[[2,1.71,37.86]],"ltp":1.89,"tv":249.99,"id":2263603},{"batb":[[0,2,69.74],[2,1.81,37.86]],"ltp":0.0,"tv":0.0,"id":3622149}]}]}
{"op":"mcm","clk":"1003058416","pt":1580602466258,"mc":[{"id":"1.168230754","rc":[{"batb":[[2,1.78,78.64]],"ltp":1.89,"tv":249.99,"id":2263603},{"batb":[[2,1.85,72.16]],"ltp":0.0,"tv":0.0,"id":3622149}]}]}
{"op":"mcm","clk":"1003058947","pt":1580602472099,"mc":[{"id":"1.168230754","rc":[{"batb":[[1,1.86,62.09]],"ltp":1.89,"tv":249.99,"id":2263603}]}]}
{"op":"mcm","clk":"1003219673","pt":1580604651358,"mc":[{"id":"1.168230754","rc":[{"batb":[[0,1.87,97.69]],"ltp":1.89,"tv":249.99,"id":2263603}]}]}
{"op":"mcm","clk":"1003219746","pt":1580604652644,"mc":[{"id":"1.168230754","rc":[{"batb":[[2,1.71,37.86]],"ltp":1.89,"tv":249.99,"id":2263603},{"batb":[[2,1.81,37.86]],"ltp":0.0,"tv":0.0,"id":3622149}]}]}
{"op":"mcm","clk":"1003219777","pt":1580604653257,"mc":[{"id":"1.168230754","rc":[{"batb":[[2,1.78,97.08]],"ltp":1.89,"tv":249.99,"id":2263603},{"batb":[[2,1.85,89.09]],"ltp":0.0,"tv":0.0,"id":3622149}]}]}
{"op":"mcm","clk":"1003219900","pt":1580604654960,"mc":[{"id":"1.168230754","rc":[{"batb":[[0,2,84.13]],"ltp":0.0,"tv":0.0,"id":3622149}]}]}
{"op":"mcm","clk":"1003312055","pt":1580606064568,"mc":[{"id":"1.168230754","rc":[{"batb":[[0,1.87,9.65]],"ltp":1.89,"tv":249.99,"id":2263603}]}]}
{"op":"mcm","clk":"1003312076","pt":1580606064774,"mc":[{"id":"1.168230754","rc":[{"batb":[[0,1.87,98]],"ltp":1.89,"tv":249.99,"id":2263603}]}]}
{"op":"mcm","clk":"1003343921","pt":1580606490552,"mc":[{"id":"1.168230754","rc":[{"batb":[[0,1.87,163.69]],"ltp":1.89,"tv":249.99,"id":2263603}]}]}
{"op":"mcm","clk":"1003344035","pt":1580606492265,"mc":[{"id":"1.168230754","rc":[{"batb":[[2,1.71,37.86]],"ltp":1.89,"tv":249.99,"id":2263603},{"batb":[[2,1.81,37.86]],"ltp":0.0,"tv":0.0,"id":3622149}]}]}
{"op":"mcm","clk":"1003344077","pt":1580606492884,"mc":[{"id":"1.168230754","rc":[{"batb":[[2,1.81,163.6]],"ltp":1.89,"tv":249.99,"id":2263603},{"batb":[[2,1.88,150.58]],"ltp":0.0,"tv":0.0,"id":3622149}]}]}
{"op":"mcm","clk":"1003344171","pt":1580606494282,"mc":[{"id":"1.168230754","rc":[{"batb":[[0,2,108.41]],"ltp":0.0,"tv":0.0,"id":3622149}]}]}
{"op":"mcm","clk":"1003411762","pt":1580607388566,"mc":[{"id":"1.168230754","rc":[{"batb":[[0,1.87,9.65]],"ltp":1.89,"tv":249.99,"id":2263603}]}]}
{"op":"mcm","clk":"1003411911","pt":1580607390633,"mc":[{"id":"1.168230754","rc":[{"batb":[[0,1.87,164.46]],"ltp":1.89,"tv":249.99,"id":2263603}]}]}
{"op":"mcm","clk":"1003669425","pt":1580610990559,"mc":[{"id":"1.168230754","rc":[{"batb":[[0,1.87,9.65]],"ltp":1.89,"tv":249.99,"id":2263603}]}]}
{"op":"mcm","clk":"1003669460","pt":1580610991025,"mc":[{"id":"1.168230754","rc":[{"batb":[[0,1.87,164.46]],"ltp":1.89,"tv":249.99,"id":2263603}]}]}
{"op":"mcm","clk":"1003947253","pt":1580616819182,"mc":[{"id":"1.168230754","rc":[{"batl":[[2,4,3.03]],"ltp":1.89,"tv":249.99,"id":2263603}]}]}
{"op":"mcm","clk":"1003947642","pt":1580616828814,"mc":[{"id":"1.168230754","rc":[{"batl":[[2,4,3.48]],"ltp":1.89,"tv":249.99,"id":2263603}]}]}
{"op":"mcm","clk":"1003949037","pt":1580616852646,"mc":[{"id":"1.168230754","rc":[{"batl":[[1,2.28,18.94],[2,990,2.2]],"ltp":1.89,"tv":249.99,"id":2263603}]}]}
{"op":"mcm","clk":"1003961534","pt":1580617089362,"mc":[{"id":"1.168230754","rc":[{"batl":[[2,95,15.9]],"ltp":1.89,"tv":249.99,"id":2263603},{"batl":[[2,95,15.9]],"ltp":0.0,"tv":0.0,"id":3622149}]}]}
{"op":"mcm","clk":"1004012680","pt":1580618191612,"mc":[{"id":"1.168230754","rc":[{"batb":[[0,1.87,9.65]],"ltp":1.89,"tv":249.99,"id":2263603}]}]}
{"op":"mcm","clk":"1004012704","pt":1580618192024,"mc":[{"id":"1.168230754","rc":[{"batb":[[0,1.87,164.46]],"ltp":1.89,"tv":249.99,"id":2263603}]}]}
{"op":"mcm","clk":"1004028649","pt":1580618543779,"mc":[{"id":"1.168230754","rc":[{"batl":[[2,2.5,15.14]],"ltp":1.89,"tv":249.99,"id":2263603}]}]}
{"op":"mcm","clk":"1004162134","pt":1580621792048,"mc":[{"id":"1.168230754","rc":[{"batb":[[0,1.87,9.65]],"ltp":1.89,"tv":249.99,"id":2263603}]}]}
{"op":"mcm","clk":"1004167205","pt":1580621912877,"mc":[{"id":"1.168230754","rc":[{"batb":[[0,1.87,164.46]],"ltp":1.89,"tv":249.99,"id":2263603}]}]}
{"op":"mcm","clk":"1004212461","pt":1580623329626,"mc":[{"id":"1.168230754","rc":[{"batb":[[0,1.87,229.92]],"ltp":1.89,"tv":249.99,"id":2263603}]}]}
{"op":"mcm","clk":"1004279104","pt":1580625513582,"mc":[{"id":"1.168230754","rc":[{"batb":[[0,1.87,230.92]],"ltp":1.89,"tv":249.99,"id":2263603}]}]}
{"op":"mcm","clk":"1004336903","pt":1580627359830,"mc":[{"id":"1.168230754","rc":[{"batb":[[0,1.87,9.65]],"ltp":1.89,"tv":249.99,"id":2263603}]}]}
{"op":"mcm","clk":"1004336986","pt":1580627362510,"mc":[{"id":"1.168230754","rc":[{"batb":[[2,1.78,242.7]],"ltp":1.89,"tv":249.99,"id":2263603},{"batb":[[2,1.91,208.03]],"ltp":0.0,"tv":0.0,"id":3622149}]}]}
{"op":"mcm","clk":"1004337028","pt":1580627363642,"mc":[{"id":"1.168230754","rc":[{"batb":[[1,1.78,242.7],[2,1.71,37.86]],"batl":[[0,2,8.4]],"ltp":1.89,"tv":249.99,"id":2263603},{"batb":[[1,1.91,208.03],[2,1.81,37.86]],"ltp":0.0,"tv":0.0,"id":3622149}]}]}
{"op":"mcm","clk":"1004337042","pt":1580627364208,"mc":[{"id":"1.168230754","rc":[{"batl":[[0,2,70.49]],"ltp":1.89,"tv":249.99,"id":2263603},{"batb":[[1,1.97,60.58],[2,1.91,208.03]],"ltp":0.0,"tv":0.0,"id":3622149}]}]}
{"op":"mcm","clk":"1004337309","pt":1580627370608,"mc":[{"id":"1.168230754","rc":[{"batl":[[0,1.97,62.09],[1,2,8.4],[2,2.28,18.94]],"ltp":1.89,"tv":249.99,"id":2263603}]}]}
{"op":"mcm","clk":"1004337317","pt":1580627370815,"mc":[{"id":"1.168230754","rc":[{"batb":[[1,1.83,62.85],[2,1.78,242.7]],"ltp":1.89,"tv":249.99,"id":2263603}]}]}
{"op":"mcm","clk":"1004338366","pt":1580627402162,"mc":[{"id":"1.168230754","rc":[{"batl":[[1,2.28,18.94],[2,2.5,15.14]],"ltp":1.89,"tv":249.99,"id":2263603}]}]}
{"op":"mcm","clk":"1004338442","pt":1580627403552,"mc":[{"id":"1.168230754","rc":[{"batl":[[0,1.97,70.49]],"ltp":1.89,"tv":249.99,"id":2263603},{"batb":[[0,2.02,8.23],[1,2,100.01],[2,1.97,60.58]],"ltp":0.0,"tv":0.0,"id":3622149}]}]}
{"op":"mcm","clk":"1004339064","pt":1580627420001,"mc":[{"id":"1.168230754","rc":[{"batb":[[1,1.78,242.7],[2,1.71,100.71]],"ltp":1.89,"tv":249.99,"id":2263603},{"batb":[[2,1.91,208.03]],"ltp":0.0,"tv":0.0,"id":3622149}]}]}
{"op":"mcm","clk":"1004346087","pt":1580627611021,"mc":[{"id":"1.168230754","rc":[{"batb":[[1,1.83,62.85],[2,1.78,242.7]],"ltp":1.89,"tv":249.99,"id":2263603},{"batb":[[2,1.97,60.58]],"ltp":0.0,"tv":0.0,"id":3622149}]}]}
{"op":"mcm","clk":"1004394809","pt":1580628792484,"mc":[{"id":"1.168230754","rc":[{"batb":[[2,1.94,60.58]],"ltp":0.0,"tv":0.0,"id":3622149}]}]}
{"op":"mcm","clk":"1004396440","pt":1580628836544,"mc":[{"id":"1.168230754","rc":[{"batb":[[2,1.97,60.58]],"ltp":0.0,"tv":0.0,"id":3622149}]}]}
{"op":"mcm","clk":"1004463832","pt":1580630407881,"mc":[{"id":"1.168230754","rc":[{"batb":[[1,1.97,60.58],[2,1.91,208.03]],"ltp":0.0,"tv":0.0,"id":3622149}]}]}
{"op":"mcm","clk":"1004464288","pt":1580630413483,"mc":[{"id":"1.168230754","rc":[{"batb":[[0,2.02,31.43]],"ltp":0.0,"tv":0.0,"id":3622149}]}]}
{"op":"mcm","clk":"1004464535","pt":1580630417558,"mc":[{"id":"1.168230754","rc":[{"batl":[[0,1.97,8.4]],"ltp":1.89,"tv":249.99,"id":2263603}]}]}
{"op":"mcm","clk":"1004464539","pt":1580630417662,"mc":[{"id":"1.168230754","rc":[{"batl":[[1,2,62.09],[2,2.28,18.94]],"ltp":1.89,"tv":249.99,"id":2263603}]}]}
{"op":"mcm","clk":"1004464611","pt":1580630418859,"mc":[{"id":"1.168230754","rc":[{"batb":[[0,2.02,8.23]],"ltp":0.0,"tv":0.0,"id":3622149}]}]}
{"op":"mcm","clk":"1004464877","pt":1580630424292,"mc":[{"id":"1.168230754","rc":[{"batb":[[1,2,19.45],[2,1.97,60.58]],"ltp":0.0,"tv":0.0,"id":3622149}]}]}
{"op":"mcm","clk":"1004465415","pt":1580630435096,"mc":[{"id":"1.168230754","rc":[{"batl":[[0,1.97,70.49],[1,2.28,18.94],[2,2.5,15.14]],"ltp":1.89,"tv":249.99,"id":2263603}]}]}
{"op":"mcm","clk":"1004465673","pt":1580630440299,"mc":[{"id":"1.168230754","rc":[{"batb":[[1,1.97,60.58],[2,1.91,208.03]],"ltp":0.0,"tv":0.0,"id":3622149}]}]}
{"op":"mcm","clk":"1004465930","pt":1580630446025,"mc":[{"id":"1.168230754","rc":[{"batb":[[0,2.02,31.43]],"ltp":0.0,"tv":0.0,"id":3622149}]}]}
{"op":"mcm","clk":"1004466171","pt":1580630451100,"mc":[{"id":"1.168230754","rc":[{"batb":[[0,2.02,39.21]],"ltp":0.0,"tv":0.0,"id":3622149}]}]}
{"op":"mcm","clk":"1004466443","pt":1580630456541,"mc":[{"id":"1.168230754","rc":[{"batb":[[0,2.02,46.87]],"ltp":0.0,"tv":0.0,"id":3622149}]}]}
{"op":"mcm","clk":"1004466686","pt":1580630461939,"mc":[{"id":"1.168230754","rc":[{"batb":[[0,2.02,54.42]],"ltp":0.0,"tv":0.0,"id":3622149}]}]}
{"op":"mcm","clk":"1004466938","pt":1580630467341,"mc":[{"id":"1.168230754","rc":[{"batb":[[0,2.02,59.38]],"ltp":0.0,"tv":0.0,"id":3622149}]}]}
{"op":"mcm","clk":"1004489911","pt":1580630992124,"mc":[{"id":"1.168230754","rc":[{"batl":[[0,1.91,25.33],[1,1.97,70.49],[2,2.28,18.94]],"ltp":1.89,"tv":249.99,"id":2263603}]}]}
{"op":"mcm","clk":"1004489983","pt":1580630993615,"mc":[{"id":"1.168230754","rc":[{"batl":[[1,1.97,62.09]],"ltp":1.89,"tv":249.99,"id":2263603}]}]}
{"op":"mcm","clk":"1004490034","pt":1580630994600,"mc":[{"id":"1.168230754","rc":[{"batb":[[0,1.88,4.5],[1,1.87,9.65],[2,1.83,62.85]],"batl":[[0,1.9,3],[1,1.91,33.73],[2,1.97,62.09]],"ltp":1.89,"tv":249.99,"id":2263603},{"batb":[[0,2.02,51.15]],"ltp":0.0,"tv":0.0,"id":3622149}]}]}
{"op":"mcm","clk":"1004490054","pt":1580630994910,"mc":[{"id":"1.168230754","rc":[{"batb":[[0,2.08,7.78],[1,2.02,51.15],[2,1.97,60.58]],"ltp":0.0,"tv":0.0,"id":3622149}]}]}
{"op":"mcm","clk":"1004491620","pt":1580631026179,"mc":[{"id":"1.168230754","rc":[{"batl":[[1,1.91,25.33]],"ltp":1.89,"tv":249.99,"id":2263603}]}]}
{"op":"mcm","clk":"1004491690","pt":1580631027574,"mc":[{"id":"1.168230754","rc":[{"batb":[[1,1.83,62.85],[2,1.78,242.7]],"ltp":1.89,"tv":249.99,"id":2263603},{"batb":[[0,2.02,51.15],[1,1.97,60.58],[2,1.91,208.03]],"batl":[[0,2.28,18.48],[1,95,15.9],[2,990,2.2]],"ltp":0.0,"tv":0.0,"id":3622149}]}]}
{"op":"mcm","clk":"1004498454","pt":1580631177504,"mc":[{"id":"1.168230754","rc":[{"trd":[[1.9,111.44]],"batl":[[0,1.91,25.57],[1,1.97,62.09],[2,2.28,18.94]],"ltp":1.9,"tv":255.51,"id":2263603}],"tv":255.51}]}
{"op":"mcm","clk":"1004498496","pt":1580631178381,"mc":[{"id":"1.168230754","rc":[{"batb":[[2,1.71,37.86]],"ltp":1.9,"tv":255.51,"id":2263603},{"batb":[[2,1.81,37.86]],"ltp":0.0,"tv":0.0,"id":3622149}]}]}
{"op":"mcm","clk":"1004498529","pt":1580631178998,"mc":[{"id":"1.168230754","rc":[{"batb":[[2,1.82,230.86]],"ltp":1.9,"tv":255.51,"id":2263603},{"batb":[[2,1.87,217.6]],"ltp":0.0,"tv":0.0,"id":3622149}]}]}
{"op":"mcm","clk":"1004498655","pt":1580631181472,"mc":[{"id":"1.168230754","rc":[{"batb":[[1,1.87,217.6],[2,1.81,37.86]],"ltp":0.0,"tv":0.0,"id":3622149}]}]}
{"op":"mcm","clk":"1004498888","pt":1580631186869,"mc":[{"id":"1.168230754","rc":[{"batb":[[1,1.83,92.46]],"ltp":1.9,"tv":255.51,"id":2263603}]}]}
{"op":"mcm","clk":"1004499013","pt":1580631189793,"mc":[{"id":"1.168230754","rc":[{"batl":[[1,2.02,62.09]],"ltp":1.9,"tv":255.51,"id":2263603}]}]}
{"op":"mcm","clk":"1004500073","pt":1580631212205,"mc":[{"id":"1.168230754","rc":[{"batb":[[0,2.08,7.78],[1,2.02,51.15],[2,1.87,217.6]],"batl":[[0,2.14,8.4],[1,2.28,18.48],[2,95,15.9]],"ltp":0.0,"tv":0.0,"id":3622149}]}]}
{"op":"mcm","clk":"1004511833","pt":1580631494560,"mc":[{"id":"1.168230754","rc":[{"batb":[[1,1.84,61.34],[2,1.83,92.46]],"ltp":1.9,"tv":255.51,"id":2263603}]}]}
{"op":"mcm","clk":"1004511933","pt":1580631497496,"mc":[{"id":"1.168230754","rc":[{"batb":[[1,1.83,92.46],[2,1.82,230.86]],"ltp":1.9,"tv":255.51,"id":2263603}]}]}
{"op":"mcm","clk":"1004521473","pt":1580631706926,"mc":[{"id":"1.168230754","rc":[{"batb":[[0,1.88,14.04]],"batl":[[0,1.91,33.97]],"ltp":1.9,"tv":255.51,"id":2263603}]}]}
{"op":"mcm","clk":"1004571907","pt":1580632866370,"mc":[{"id":"1.168230754","rc":[{"trd":[[1.88,10.14]],"batb":[[0,1.88,8.97]],"ltp":1.88,"tv":265.65,"id":2263603}],"tv":265.65}]}
{"op":"mcm","clk":"1004626748","pt":1580634005540,"mc":[{"id":"1.168230754","rc":[{"batb":[[1,1.87,217.6],[2,1.81,37.86]],"ltp":0.0,"tv":0.0,"id":3622149}]}]}
{"op":"mcm","clk":"1004627230","pt":1580634011342,"mc":[{"id":"1.168230754","rc":[{"batb":[[0,2.08,24.98]],"ltp":0.0,"tv":0.0,"id":3622149}]}]}
{"op":"mcm","clk":"1004627522","pt":1580634016040,"mc":[{"id":"1.168230754","rc":[{"trd":[[1.9,111.92]],"batb":[[0,1.9,6.09],[1,1.88,8.97],[2,1.83,92.46]],"batl":[[0,1.91,33.73]],"ltp":1.9,"tv":266.13,"id":2263603}],"tv":266.13}]}
{"op":"mcm","clk":"1004627669","pt":1580634018358,"mc":[{"id":"1.168230754","rc":[{"batl":[[0,2.28,18.48],[1,95,15.9],[2,990,2.2]],"ltp":0.0,"tv":0.0,"id":3622149}]}]}
{"op":"mcm","clk":"1004627731","pt":1580634019143,"mc":[{"id":"1.168230754","rc":[{"batb":[[1,1.83,92.46],[2,1.82,230.86]],"ltp":1.9,"tv":266.13,"id":2263603},{"batl":[[0,2.12,8.4],[1,2.28,18.48],[2,95,15.9]],"ltp":0.0,"tv":0.0,"id":3622149}]}]}
{"op":"mcm","clk":"1004627935","pt":1580634022443,"mc":[{"id":"1.168230754","rc":[{"batb":[[0,2.08,30.97]],"ltp":0.0,"tv":0.0,"id":3622149}]}]}
{"op":"mcm","clk":"1004628306","pt":1580634028177,"mc":[{"id":"1.168230754","rc":[{"trd":[[2.08,15.14]],"batb":[[0,2.08,28.65]],"ltp":2.08,"tv":15.14,"id":3622149}],"tv":281.27}]}
{"op":"mcm","clk":"1004629669","pt":1580634050186,"mc":[{"id":"1.168230754","rc":[{"batl":[[0,1.91,25.33]],"ltp":1.9,"tv":266.13,"id":2263603}]}]}
{"op":"mcm","clk":"1004632008","pt":1580634088091,"mc":[{"id":"1.168230754","rc":[{"batb":[[1,1.86,62.85],[2,1.83,29.61]],"ltp":1.9,"tv":266.13,"id":2263603}]}]}
{"op":"mcm","clk":"1004633376","pt":1580634114659,"mc":[{"id":"1.168230754","rc":[{"batb":[[1,1.92,60.58],[2,1.87,217.6]],"ltp":2.08,"tv":15.14,"id":3622149}]}]}
{"op":"mcm","clk":"1004640049","pt":1580634260010,"mc":[{"id":"1.168230754","rc":[{"trd":[[1.91,45.1]],"batl":[[0,2.02,62.32],[1,2.28,18.94],[2,2.5,15.14]],"ltp":1.91,"tv":291.23,"id":2263603},{"trd":[[2.08,95.46]],"batb":[[0,1.92,60.58],[1,1.87,217.6],[2,1.81,37.86]],"ltp":2.08,"tv":95.45,"id":3622149}],"tv":386.69}]}
{"op":"mcm","clk":"1004640190","pt":1580634263411,"mc":[{"id":"1.168230754","rc":[{"batb":[[0,1.98,8.56],[1,1.92,60.58],[2,1.87,217.6]],"ltp":2.08,"tv":95.45,"id":3622149}]}]}
{"op":"mcm","clk":"1004640644","pt":1580634272208,"mc":[{"id":"1.168230754","rc":[{"batb":[[1,1.87,62.85]],"ltp":1.91,"tv":291.23,"id":2263603}]}]}
{"op":"mcm","clk":"1004644879","pt":1580634360712,"mc":[{"id":"1.168230754","rc":[{"batb":[[0,1.9,15.43]],"ltp":1.91,"tv":291.23,"id":2263603}]}]}
{"op":"mcm","clk":"1004645124","pt":1580634365000,"mc":[{"id":"1.168230754","rc":[{"batb":[[0,1.98,14.18]],"ltp":2.08,"tv":95.45,"id":3622149}]}]}
{"op":"mcm","clk":"1004695980","pt":1580635425876,"mc":[{"id":"1.168230754","rc":[{"batl":[[0,1.95,20.22],[1,2.02,62.09],[2,2.28,18.94]],"ltp":1.91,"tv":291.23,"id":2263603}]}]}
{"op":"mcm","clk":"1004696100","pt":1580635428897,"mc":[{"id":"1.168230754","rc":[{"batb":[[0,1.98,20.3]],"ltp":2.08,"tv":95.45,"id":3622149}]}]}
{"op":"mcm","clk":"1004696338","pt":1580635436208,"mc":[{"id":"1.168230754","rc":[{"batl":[[0,1.97,20.22]],"ltp":1.91,"tv":291.23,"id":2263603}]}]}
{"op":"mcm","clk":"1004700357","pt":1580635528523,"mc":[{"id":"1.168230754","rc":[{"batl":[[0,1.94,20.22]],"ltp":1.91,"tv":291.23,"id":2263603}]}]}
{"op":"mcm","clk":"1004702073","pt":1580635568758,"mc":[{"id":"1.168230754","rc":[{"batb":[[0,1.9,6.09]],"ltp":1.91,"tv":291.23,"id":2263603}]}]}
{"op":"mcm","clk":"1004739194","pt":1580636431079,"mc":[{"id":"1.168230754","rc":[{"batb":[[0,1.9,15.43]],"ltp":1.91,"tv":291.23,"id":2263603}]}]}
{"op":"mcm","clk":"1004777139","pt":1580637168480,"mc":[{"id":"1.168230754","rc":[{"batb":[[0,1.9,435.53]],"ltp":1.91,"tv":291.23,"id":2263603}]}]}
{"op":"mcm","clk":"1004777298","pt":1580637170997,"mc":[{"id":"1.168230754","rc":[{"batb":[[1,1.89,420.1],[2,1.87,62.85]],"ltp":1.91,"tv":291.23,"id":2263603}]}]}
{"op":"mcm","clk":"1004777468","pt":1580637174005,"mc":[{"id":"1.168230754","rc":[{"batb":[[2,1.88,420.1]],"ltp":1.91,"tv":291.23,"id":2263603},{"batb":[[0,1.98,64.41]],"ltp":2.08,"tv":95.45,"id":3622149}]}]}
{"op":"mcm","clk":"1004777736","pt":1580637179486,"mc":[{"id":"1.168230754","rc":[{"batb":[[0,1.98,71.13]],"ltp":2.08,"tv":95.45,"id":3622149}]}]}
{"op":"mcm","clk":"1004950894","pt":1580639421578,"mc":[{"id":"1.168230754","rc":[{"batb":[[2,1.81,37.86]],"ltp":2.08,"tv":95.45,"id":3622149}]}]}
{"op":"mcm","clk":"1004950959","pt":1580639422203,"mc":[{"id":"1.168230754","rc":[{"batb":[[2,1.89,319.06]],"ltp":2.08,"tv":95.45,"id":3622149}]}]}
{"op":"mcm","clk":"1004952014","pt":1580639433587,"mc":[{"id":"1.168230754","rc":[{"batb":[[2,1.88,482.95]],"ltp":1.91,"tv":291.23,"id":2263603},{"batb":[[1,1.93,60.58]],"ltp":2.08,"tv":95.45,"id":3622149}]}]}
{"op":"mcm","clk":"1005008066","pt":1580640016305,"mc":[{"id":"1.168230754","rc":[{"trd":[[1.91,45.33],[1.94,20]],"batl":[[0,2.02,62.09],[1,2.28,18.94],[2,2.44,15.14]],"ltp":1.94,"tv":311.46,"id":2263603},{"trd":[[2.06,18.82],[2.08,95.66]],"batl":[[0,2.12,8.63]],"ltp":2.06,"tv":114.47,"id":3622149}],"tv":425.93}]}
{"op":"mcm","clk":"1005104093","pt":1580640789929,"mc":[{"id":"1.168230754","rc":[{"batb":[[0,1.91,28.51],[1,1.9,435.53],[2,1.89,420.1]],"ltp":1.94,"tv":311.46,"id":2263603},{"batb":[[0,1.99,16.41],[1,1.98,71.13],[2,1.93,60.58]],"ltp":2.06,"tv":114.47,"id":3622149}]}]}
{"op":"mcm","clk":"1005104735","pt":1580640795533,"mc":[{"id":"1.168230754","rc":[{"batl":[[0,2.28,18.71],[1,95,15.9],[2,990,2.2]],"ltp":2.06,"tv":114.47,"id":3622149}]}]}
{"op":"mcm","clk":"1005104837","pt":1580640796418,"mc":[{"id":"1.168230754","rc":[{"batb":[[0,1.91,37.74],[1,1.9,426.19]],"ltp":1.94,"tv":311.46,"id":2263603},{"batl":[[0,2.1,8.63],[1,2.28,18.48],[2,95,15.9]],"ltp":2.06,"tv":114.47,"id":3622149}]}]}
{"op":"mcm","clk":"1005348739","pt":1580642214310,"mc":[{"id":"1.168230754","rc":[{"batl":[[0,2.1,107.24]],"ltp":2.06,"tv":114.47,"id":3622149}]}]}
{"op":"mcm","clk":"1005446887","pt":1580642735985,"mc":[{"id":"1.168230754","rc":[{"batl":[[0,2,7.57],[1,2.02,62.09],[2,2.28,18.94]],"ltp":1.94,"tv":311.46,"id":2263603}]}]}
{"op":"mcm","clk":"1005481752","pt":1580642922638,"mc":[{"id":"1.168230754","rc":[{"batl":[[0,1.95,10],[1,2,7.57],[2,2.02,62.09]],"ltp":1.94,"tv":311.46,"id":2263603}]}]}
{"op":"mcm","clk":"1005488850","pt":1580642962602,"mc":[{"id":"1.168230754","rc":[{"batb":[[0,1.91,28.51]],"ltp":1.94,"tv":311.46,"id":2263603}]}]}
{"op":"mcm","clk":"1005499571","pt":1580643019619,"mc":[{"id":"1.168230754","rc":[{"trd":[[1.95,19.16]],"batb":[[0,1.91,18.85]],"batl":[[0,2,7.99],[1,2.02,62.09],[2,2.28,18.94]],"ltp":1.95,"tv":330.61,"id":2263603},{"batb":[[0,1.99,25.68]],"ltp":2.06,"tv":114.47,"id":3622149}],"tv":445.09}]}
{"op":"mcm","clk":"1005499974","pt":1580643021828,"mc":[{"id":"1.168230754","rc":[{"batb":[[1,1.93,60.58],[2,1.88,322.69]],"ltp":2.06,"tv":114.47,"id":3622149}]}]}
{"op":"mcm","clk":"1005501045","pt":1580643027399,"mc":[{"id":"1.168230754","rc":[{"batb":[[0,1.99,33.33]],"ltp":2.06,"tv":114.47,"id":3622149}]}]}
{"op":"mcm","clk":"1005506019","pt":1580643055400,"mc":[{"id":"1.168230754","rc":[{"batb":[[0,1.91,28.09]],"ltp":1.95,"tv":330.61,"id":2263603}]}]}
{"op":"mcm","clk":"1005650609","pt":1580643778618,"mc":[{"id":"1.168230754","rc":[{"batb":[[0,1.92,310.94],[1,1.91,28.09],[2,1.9,426.19]],"ltp":1.95,"tv":330.61,"id":2263603}]}]}
{"op":"mcm","clk":"1005650804","pt":1580643779602,"mc":[{"id":"1.168230754","rc":[{"batb":[[2,1.81,37.86]],"ltp":2.06,"tv":114.47,"id":3622149}]}]}
{"op":"mcm","clk":"1005650933","pt":1580643780236,"mc":[{"id":"1.168230754","rc":[{"batb":[[1,1.85,334.08]],"ltp":2.06,"tv":114.47,"id":3622149}]}]}
{"op":"mcm","clk":"1005652367","pt":1580643787611,"mc":[{"id":"1.168230754","rc":[{"batl":[[1,2.06,62.55],[2,2.28,18.48]],"ltp":1.95,"tv":330.61,"id":2263603}]}]}
{"op":"mcm","clk":"1005654755","pt":1580643799628,"mc":[{"id":"1.168230754","rc":[{"batb":[[1,1.91,18.85]],"ltp":1.95,"tv":330.61,"id":2263603}]}]}
{"op":"mcm","clk":"1005654811","pt":1580643799905,"mc":[{"id":"1.168230754","rc":[{"batb":[[0,1.93,9.03],[1,1.92,310.94],[2,1.91,18.85]],"ltp":1.95,"tv":330.61,"id":2263603}]}]}
{"op":"mcm","clk":"1005656809","pt":1580643810453,"mc":[{"id":"1.168230754","rc":[{"batb":[[0,1.93,23.25],[1,1.9,426.19],[2,1.89,420.1]],"ltp":1.95,"tv":330.61,"id":2263603},{"batb":[[0,1.99,7.65],[1,1.95,38.81],[2,1.85,334.08]],"ltp":2.06,"tv":114.47,"id":3622149}]}]}
{"op":"mcm","clk":"1005660672","pt":1580643831285,"mc":[{"id":"1.168230754","rc":[{"batl":[[0,2.08,8.63],[1,2.1,98.61],[2,2.28,18.48]],"ltp":2.06,"tv":114.47,"id":3622149}]}]}
{"op":"mcm","clk":"1005681584","pt":1580643944184,"mc":[{"id":"1.168230754","rc":[{"batb":[[0,1.93,9.03],[1,1.91,23.83],[2,1.9,426.19]],"ltp":1.95,"tv":330.61,"id":2263603}]}]}
{"op":"mcm","clk":"1005685472","pt":1580643965030,"mc":[{"id":"1.168230754","rc":[{"batb":[[2,1.81,37.86]],"ltp":2.06,"tv":114.47,"id":3622149}]}]}
{"op":"mcm","clk":"1005685734","pt":1580643966501,"mc":[{"id":"1.168230754","rc":[{"batb":[[2,1.86,330.19]],"ltp":2.06,"tv":114.47,"id":3622149}]}]}
{"op":"mcm","clk":"1005687341","pt":1580643975433,"mc":[{"id":"1.168230754","rc":[{"batl":[[1,2.04,62.55]],"ltp":1.95,"tv":330.61,"id":2263603}]}]}
{"op":"mcm","clk":"1005700419","pt":1580644054417,"mc":[{"id":"1.168230754","rc":[{"batl":[[0,1.96,10.42],[1,2,7.57],[2,2.04,62.55]],"ltp":1.95,"tv":330.61,"id":2263603}]}]}
{"op":"mcm","clk":"1005702985","pt":1580644071375,"mc":[{"id":"1.168230754","rc":[{"batl":[[0,2,7.99],[1,2.04,62.55],[2,2.28,18.48]],"ltp":1.95,"tv":330.61,"id":2263603}]}]}
{"op":"mcm","clk":"1005703855","pt":1580644076574,"mc":[{"id":"1.168230754","rc":[{"batb":[[1,1.86,330.19],[2,1.81,37.86]],"ltp":2.06,"tv":114.47,"id":3622149}]}]}
{"op":"mcm","clk":"1005704043","pt":1580644077641,"mc":[{"id":"1.168230754","rc":[{"batb":[[1,1.97,29.7],[2,1.86,330.19]],"ltp":2.06,"tv":114.47,"id":3622149}]}]}
{"op":"mcm","clk":"1005705076","pt":1580644085168,"mc":[{"id":"1.168230754","rc":[{"batl":[[0,1.97,10.42],[1,2,7.57],[2,2.04,62.55]],"ltp":1.95,"tv":330.61,"id":2263603}]}]}
{"op":"mcm","clk":"1005810072","pt":1580644871555,"mc":[{"id":"1.168230754","rc":[{"batb":[[2,1.9,489.04]],"ltp":1.95,"tv":330.61,"id":2263603},{"batb":[[2,1.9,60.58]],"ltp":2.06,"tv":114.47,"id":3622149}]}]}
{"op":"mcm","clk":"1005941242","pt":1580645576157,"mc":[{"id":"1.168230754","rc":[{"batl":[[0,1.97,10]],"ltp":1.95,"tv":330.61,"id":2263603}]}]}
{"op":"mcm","clk":"1005942089","pt":1580645581150,"mc":[{"id":"1.168230754","rc":[{"batl":[[0,2,7.57],[1,2.04,62.55],[2,2.28,18.48]],"ltp":1.95,"tv":330.61,"id":2263603}]}]}
{"op":"mcm","clk":"1005943037","pt":1580645586382,"mc":[{"id":"1.168230754","rc":[{"batb":[[0,1.97,29.7],[1,1.9,60.58],[2,1.86,330.19]],"ltp":2.06,"tv":114.47,"id":3622149}]}]}
{"op":"mcm","clk":"1005944069","pt":1580645592003,"mc":[{"id":"1.168230754","rc":[{"batb":[[0,1.97,38.36]],"ltp":2.06,"tv":114.47,"id":3622149}]}]}
{"op":"mcm","clk":"1005973261","pt":1580645754342,"mc":[{"id":"1.168230754","rc":[{"batl":[[0,2,36.57]],"ltp":1.95,"tv":330.61,"id":2263603}]}]}
{"op":"mcm","clk":"1005973467","pt":1580645755561,"mc":[{"id":"1.168230754","rc":[{"batb":[[0,1.97,29.7]],"ltp":2.06,"tv":114.47,"id":3622149}]}]}
{"op":"mcm","clk":"1005974457","pt":1580645761262,"mc":[{"id":"1.168230754","rc":[{"batb":[[0,2,28.81],[1,1.97,29.7],[2,1.9,60.58]],"ltp":2.06,"tv":114.47,"id":3622149}]}]}
{"op":"mcm","clk":"1005977777","pt":1580645780274,"mc":[{"id":"1.168230754","rc":[{"batl":[[1,2.02,21],[2,2.04,62.55]],"ltp":1.95,"tv":330.61,"id":2263603}]}]}
{"op":"mcm","clk":"1005986310","pt":1580645830353,"mc":[{"id":"1.168230754","rc":[{"batb":[[1,1.99,20.91]],"ltp":2.06,"tv":114.47,"id":3622149}]}]}
{"op":"mcm","clk":"1006040338","pt":1580646138422,"mc":[{"id":"1.168230754","rc":[{"trd":[[1.93,18.06],[1.94,20.24]],"batb":[[0,1.91,23.83],[1,1.9,489.04],[2,1.89,420.1]],"batl":[[0,2,37.3]],"ltp":1.93,"tv":348.92,"id":2263603},{"trd":[[2.06,19.04]],"batl":[[0,2.08,8.4]],"ltp":2.06,"tv":114.7,"id":3622149}],"tv":463.62}]}
{"op":"mcm","clk":"1006040884","pt":1580646141751,"mc":[{"id":"1.168230754","rc":[{"batl":[[0,2,36.57]],"ltp":1.93,"tv":348.92,"id":2263603}]}]}
{"op":"mcm","clk":"1006041679","pt":1580646146052,"mc":[{"id":"1.168230754","rc":[{"batb":[[0,2,42.44]],"ltp":2.06,"tv":114.7,"id":3622149}]}]}
{"op":"mcm","clk":"1006042083","pt":1580646148559,"mc":[{"id":"1.168230754","rc":[{"trd":[[1.92,9.1]],"batl":[[0,2,37.47]],"ltp":1.92,"tv":358.02,"id":2263603},{"trd":[[2.08,104.06]],"batl":[[0,2.1,98.61],[1,2.28,18.48],[2,95,15.9]],"ltp":2.08,"tv":123.1,"id":3622149}],"tv":481.12}]}
{"op":"mcm","clk":"1006042121","pt":1580646148770,"mc":[{"id":"1.168230754","rc":[{"trd":[[1.92,10.9]],"batl":[[0,2,36.57]],"ltp":1.92,"tv":359.82,"id":2263603}],"tv":482.92}]}
{"op":"mcm","clk":"1006042678","pt":1580646151996,"mc":[{"id":"1.168230754","rc":[{"batb":[[0,2,70.42]],"ltp":2.08,"tv":123.1,"id":3622149}]}]}
{"op":"mcm","clk":"1006043103","pt":1580646154477,"mc":[{"id":"1.168230754","rc":[{"batb":[[0,1.92,416.69],[1,1.91,23.83],[2,1.9,489.04]],"batl":[[0,1.99,12.6],[1,2,36.57],[2,2.02,21]],"ltp":1.92,"tv":359.82,"id":2263603},{"batb":[[0,2.02,12.36],[1,2,70.42],[2,1.99,20.91]],"ltp":2.08,"tv":123.1,"id":3622149}]}]}
{"op":"mcm","clk":"1006056589","pt":1580646231595,"mc":[{"id":"1.168230754","rc":[{"batb":[[1,1.9,489.04],[2,1.89,420.1]],"ltp":1.92,"tv":359.82,"id":2263603}]}]}
{"op":"mcm","clk":"1006056625","pt":1580646231806,"mc":[{"id":"1.168230754","rc":[{"batb":[[0,1.93,14.22],[1,1.92,416.69],[2,1.9,489.04]],"ltp":1.92,"tv":359.82,"id":2263603}]}]}
{"op":"mcm","clk":"1006098829","pt":1580646475555,"mc":[{"id":"1.168230754","rc":[{"trd":[[1.99,62.53]],"batb":[[0,1.99,1.43],[1,1.93,14.22],[2,1.92,416.69]],"batl":[[0,2,36.57],[1,2.02,21],[2,2.04,62.55]],"ltp":1.99,"tv":422.35,"id":2263603},{"trd":[[2.02,12.36]],"batb":[[0,2,70.42],[1,1.99,20.91],[2,1.9,60.58]],"ltp":2.02,"tv":135.46,"id":3622149}],"tv":557.81}]}
{"op":"mcm","clk":"1006098844","pt":1580646475662,"mc":[{"id":"1.168230754","rc":[{"batb":[[2,1.9,489.04]],"ltp":1.99,"tv":422.35,"id":2263603}]}]}
{"op":"mcm","clk":"1006101318","pt":1580646491395,"mc":[{"id":"1.168230754","rc":[{"trd":[[2,2.86]],"batb":[[0,1.93,14.22],[1,1.9,489.04],[2,1.89,420.1]],"batl":[[0,2,35.14]],"ltp":2.0,"tv":425.21,"id":2263603}],"tv":560.68}]}
{"op":"mcm","clk":"1006101555","pt":1580646493099,"mc":[{"id":"1.168230754","rc":[{"trd":[[1.99,65.41]],"ltp":1.99,"tv":428.09,"id":2263603}],"tv":563.55}]}
{"op":"mcm","clk":"1006102003","pt":1580646496110,"mc":[{"id":"1.168230754","rc":[{"batb":[[0,1.93,27.77]],"ltp":1.99,"tv":428.09,"id":2263603},{"batl":[[0,2.08,12.6],[1,2.1,98.61],[2,2.28,18.48]],"ltp":2.02,"tv":135.46,"id":3622149}]}]}
{"op":"mcm","clk":"1006102436","pt":1580646499138,"mc":[{"id":"1.168230754","rc":[{"batb":[[0,1.93,13.55],[1,1.91,23.83],[2,1.9,489.04]],"ltp":1.99,"tv":428.09,"id":2263603}]}]}
{"op":"mcm","clk":"1006103991","pt":1580646508203,"mc":[{"id":"1.168230754","rc":[{"batl":[[1,2.28,18.48],[2,95,15.9]],"ltp":2.02,"tv":135.46,"id":3622149}]}]}
{"op":"mcm","clk":"1006104672","pt":1580646512106,"mc":[{"id":"1.168230754","rc":[{"batb":[[1,1.91,86.68],[2,1.9,426.19]],"batl":[[2,2.06,62.55]],"ltp":1.99,"tv":428.09,"id":2263603}]}]}
{"op":"mcm","clk":"1006131968","pt":1580646668370,"mc":[{"id":"1.168230754","rc":[{"batl":[[2,4.2,153.72]],"ltp":2.02,"tv":135.46,"id":3622149}]}]}
{"op":"mcm","clk":"1006338674","pt":1580647778120,"mc":[{"id":"1.168230754","rc":[{"batl":[[0,1.99,7.57],[1,2,35.14],[2,2.02,21]],"ltp":1.99,"tv":428.09,"id":2263603}]}]}
{"op":"mcm","clk":"1006338934","pt":1580647779737,"mc":[{"id":"1.168230754","rc":[{"batl":[[0,2,35.14],[1,2.02,21],[2,2.06,62.55]],"ltp":1.99,"tv":428.09,"id":2263603}]}]}
{"op":"mcm","clk":"1006339310","pt":1580647781966,"mc":[{"id":"1.168230754","rc":[{"batl":[[0,2,29]],"ltp":1.99,"tv":428.09,"id":2263603}]}]}
{"op":"mcm","clk":"1006339958","pt":1580647785875,"mc":[{"id":"1.168230754","rc":[{"batl":[[0,1.99,7.57],[1,2,29],[2,2.02,21]],"ltp":1.99,"tv":428.09,"id":2263603}]}]}
{"op":"mcm","clk":"1006369118","pt":1580647988304,"mc":[{"id":"1.168230754","rc":[{"batb":[[0,1.93,433.65],[1,1.92,420.1],[2,1.91,506.78]],"ltp":1.99,"tv":428.09,"id":2263603}]}]}
{"op":"mcm","clk":"1006386616","pt":1580648108532,"mc":[{"id":"1.168230754","rc":[{"batb":[[0,1.94,9.54],[1,1.93,433.65],[2,1.92,420.1]],"ltp":1.99,"tv":428.09,"id":2263603}]}]}
{"op":"mcm","clk":"1006390643","pt":1580648136273,"mc":[{"id":"1.168230754","rc":[{"batb":[[0,1.94,22.95],[1,1.93,420.1]],"ltp":1.99,"tv":428.09,"id":2263603}]}]}
{"op":"mcm","clk":"1006418772","pt":1580648346477,"mc":[{"id":"1.168230754","rc":[{"batl":[[0,1.98,2],[1,1.99,7.57],[2,2,29]],"ltp":1.99,"tv":428.09,"id":2263603}]}]}
{"op":"mcm","clk":"1006429872","pt":1580648429793,"mc":[{"id":"1.168230754","rc":[{"trd":[[1.94,35.23]],"batb":[[0,1.94,15.44]],"ltp":1.94,"tv":443.08,"id":2263603}],"tv":578.55}]}
{"op":"mcm","clk":"1006430155","pt":1580648432528,"mc":[{"id":"1.168230754","rc":[{"batb":[[0,1.94,22.95]],"ltp":1.94,"tv":443.08,"id":2263603}]}]}
{"op":"mcm","clk":"1006477646","pt":1580648785679,"mc":[{"id":"1.168230754","rc":[{"batb":[[0,2.02,15.2],[1,2,70.42],[2,1.99,20.91]],"ltp":2.02,"tv":135.46,"id":3622149}]}]}
{"op":"mcm","clk":"1006525332","pt":1580649111325,"mc":[{"id":"1.168230754","rc":[{"batb":[[0,2,70.42],[1,1.99,20.91],[2,1.9,60.58]],"ltp":2.02,"tv":135.46,"id":3622149}]}]}
{"op":"mcm","clk":"1006832272","pt":1580651185631,"mc":[{"id":"1.168230754","rc":[{"trd":[[1.94,35.44]],"batb":[[0,1.94,22.84]],"ltp":1.94,"tv":443.28,"id":2263603},{"batb":[[0,2.02,8.39],[1,2,70.42]],"ltp":2.02,"tv":135.46,"id":3622149}],"tv":578.75}]}
{"op":"mcm","clk":"1006834682","pt":1580651201562,"mc":[{"id":"1.168230754","rc":[{"trd":[[2.02,12.56]],"batb":[[0,2.02,8.29]],"ltp":2.02,"tv":135.66,"id":3622149}],"tv":578.95}]}
{"op":"mcm","clk":"1006834902","pt":1580651203175,"mc":[{"id":"1.168230754","rc":[{"batb":[[0,2,70.42],[1,1.99,20.91]],"ltp":2.02,"tv":135.66,"id":3622149}]}]}
{"op":"mcm","clk":"1006835412","pt":1580651206876,"mc":[{"id":"1.168230754","rc":[{"batl":[[2,4.2,153.82]],"ltp":2.02,"tv":135.66,"id":3622149}]}]}
{"op":"mcm","clk":"1006878686","pt":1580651542989,"mc":[{"id":"1.168230754","rc":[{"trd":[[1.94,42.53]],"batb":[[0,1.94,19.29]],"ltp":1.94,"tv":450.38,"id":2263603}],"tv":586.05}]}
{"op":"mcm","clk":"1006879062","pt":1580651545878,"mc":[{"id":"1.168230754","rc":[{"batb":[[0,1.94,11.79],[1,1.93,432.39]],"ltp":1.94,"tv":450.38,"id":2263603},{"batb":[[0,2.02,10.13],[1,2,70.42]],"ltp":2.02,"tv":135.66,"id":3622149}]}]}
{"op":"mcm","clk":"1006889302","pt":1580651625683,"mc":[{"id":"1.168230754","rc":[{"batl":[[1,2,29],[2,2.02,83.09]],"ltp":1.94,"tv":450.38,"id":2263603}]}]}
{"op":"mcm","clk":"1006950253","pt":1580652070577,"mc":[{"id":"1.168230754","rc":[{"batb":[[2,1.92,60.58]],"ltp":2.02,"tv":135.66,"id":3622149}]}]}
{"op":"mcm","clk":"1006969231","pt":1580652193319,"mc":[{"id":"1.168230754","rc":[{"batl":[[0,1.98,9.57]],"ltp":1.94,"tv":450.38,"id":2263603}]}]}
{"op":"mcm","clk":"1006969533","pt":1580652195131,"mc":[{"id":"1.168230754","rc":[{"batl":[[0,1.98,2]],"ltp":1.94,"tv":450.38,"id":2263603}]}]}
{"op":"mcm","clk":"1007034939","pt":1580652565032,"mc":[{"id":"1.168230754","rc":[{"batb":[[0,1.94,431.89]],"ltp":1.94,"tv":450.38,"id":2263603}]}]}
{"op":"mcm","clk":"1007063354","pt":1580652727638,"mc":[{"id":"1.168230754","rc":[{"trd":[[1.98,2]],"batb":[[0,1.95,13.49],[1,1.94,431.89],[2,1.93,420.1]],"batl":[[0,2,29],[1,2.02,83.09],[2,2.28,18.94]],"ltp":1.98,"tv":452.38,"id":2263603},{"trd":[[2,9.43],[2.02,34.78]],"batb":[[0,2,65.7],[1,1.99,12.59]],"ltp":2.0,"tv":167.31,"id":3622149}],"tv":619.7}]}
{"op":"mcm","clk":"1007069096","pt":1580652759498,"mc":[{"id":"1.168230754","rc":[{"batb":[[1,1.94,420.1]],"ltp":1.98,"tv":452.38,"id":2263603},{"batl":[[0,2.28,18.48],[1,4.2,153.82],[2,95,15.9]],"ltp":2.0,"tv":167.31,"id":3622149}]}]}
{"op":"mcm","clk":"1007069203","pt":1580652760094,"mc":[{"id":"1.168230754","rc":[{"batb":[[0,1.95,26.75]],"ltp":1.98,"tv":452.38,"id":2263603},{"batl":[[0,2.06,12.6],[1,2.28,18.48],[2,4.2,153.82]],"ltp":2.0,"tv":167.31,"id":3622149}]}]}
{"op":"mcm","clk":"1007069519","pt":1580652762108,"mc":[{"id":"1.168230754","rc":[{"trd":[[2,27.12]],"batb":[[0,2,56.85]],"ltp":2.0,"tv":185.0,"id":3622149}],"tv":637.39}]}
{"op":"mcm","clk":"1007072590","pt":1580652779731,"mc":[{"id":"1.168230754","rc":[{"trd":[[2,31.67]],"batb":[[0,2,54.58]],"ltp":2.0,"tv":189.54,"id":3622149}],"tv":641.93}]}
{"op":"mcm","clk":"1007075628","pt":1580652796268,"mc":[{"id":"1.168230754","rc":[{"trd":[[2,33.43]],"batb":[[0,2,53.7]],"ltp":2.0,"tv":191.31,"id":3622149}],"tv":643.7}]}
{"op":"mcm","clk":"1007081023","pt":1580652824464,"mc":[{"id":"1.168230754","rc":[{"trd":[[1.95,36.72]],"batb":[[0,1.95,13.27],[1,1.94,429.43]],"ltp":1.95,"tv":469.95,"id":2263603},{"batb":[[0,2.02,8.49],[1,2,53.7]],"ltp":2.0,"tv":191.31,"id":3622149}],"tv":661.26}]}
{"op":"mcm","clk":"1007084080","pt":1580652840898,"mc":[{"id":"1.168230754","rc":[{"trd":[[2.02,36.29]],"batb":[[0,2.02,7.73]],"ltp":2.02,"tv":192.82,"id":3622149}],"tv":662.78}]}
{"op":"mcm","clk":"1007084563","pt":1580652843215,"mc":[{"id":"1.168230754","rc":[{"batb":[[0,2,53.7],[1,1.99,20.35]],"ltp":2.02,"tv":192.82,"id":3622149}]}]}
{"op":"mcm","clk":"1007095588","pt":1580652903094,"mc":[{"id":"1.168230754","rc":[{"trd":[[1.95,63.26]],"batb":[[0,1.94,429.43],[1,1.93,420.1],[2,1.92,420.1]],"batl":[[0,1.95,308.73],[1,2,29],[2,2.02,83.09]],"ltp":1.95,"tv":496.49,"id":2263603}],"tv":689.31}]}
{"op":"mcm","clk":"1007097966","pt":1580652916595,"mc":[{"id":"1.168230754","rc":[{"trd":[[1.94,659.99]],"batb":[[0,1.94,120.7]],"batl":[[0,2,29],[1,2.02,83.09],[2,2.28,18.94]],"ltp":1.94,"tv":1113.94,"id":2263603}],"tv":1306.77}]}
{"op":"mcm","clk":"1007102977","pt":1580652946615,"mc":[{"id":"1.168230754","rc":[{"batb":[[0,2,62.1]],"ltp":2.02,"tv":192.82,"id":3622149}]}]}
{"op":"mcm","clk":"1007108705","pt":1580652978231,"mc":[{"id":"1.168230754","rc":[{"batb":[[0,1.95,8.85],[1,1.94,120.7],[2,1.93,420.1]],"batl":[[0,1.99,8.4],[1,2,29],[2,2.02,83.09]],"ltp":1.94,"tv":1113.94,"id":2263603}]}]}
{"op":"mcm","clk":"1007118681","pt":1580653035660,"mc":[{"id":"1.168230754","rc":[{"trd":[[1.99,73.81],[2,14.2]],"batl":[[0,2,17.66],[1,2.02,83.09],[2,2.28,18.94]],"ltp":2.0,"tv":1133.69,"id":2263603},{"trd":[[2,177.29]],"batb":[[0,1.99,20.35],[1,1.92,60.58],[2,1.88,430.24]],"ltp":2.0,"tv":336.68,"id":3622149}],"tv":1470.37}]}
{"op":"mcm","clk":"1007119244","pt":1580653038955,"mc":[{"id":"1.168230754","rc":[{"batl":[[0,1.99,7.57],[1,2,17.66],[2,2.02,83.09]],"ltp":2.0,"tv":1133.69,"id":2263603}]}]}
{"op":"mcm","clk":"1007150216","pt":1580653233565,"mc":[{"id":"1.168230754","rc":[{"trd":[[1.99,74.86]],"batl":[[0,1.99,6.53]],"ltp":1.99,"tv":1134.73,"id":2263603},{"trd":[[2,178.33]],"ltp":2.0,"tv":337.72,"id":3622149}],"tv":1472.46}]}
{"op":"mcm","clk":"1007150561","pt":1580653235640,"mc":[{"id":"1.168230754","rc":[{"batb":[[0,1.98,1.05],[1,1.95,8.85],[2,1.94,120.7]],"ltp":1.99,"tv":1134.73,"id":2263603}]}]}
{"op":"mcm","clk":"1007150592","pt":1580653235855,"mc":[{"id":"1.168230754","rc":[{"trd":[[1.98,4.1]],"batb":[[0,1.95,8.85],[1,1.94,120.7],[2,1.93,420.1]],"ltp":1.98,"tv":1136.83,"id":2263603}],"tv":1474.56}]}
{"op":"mcm","clk":"1007182404","pt":1580653428913,"mc":[{"id":"1.168230754","rc":[{"batl":[[0,1.99,14.1]],"ltp":1.98,"tv":1136.83,"id":2263603}]}]}
{"op":"mcm","clk":"1007196852","pt":1580653523661,"mc":[{"id":"1.168230754","rc":[{"batl":[[1,2.1,50.41],[2,2.28,18.48]],"ltp":2.0,"tv":337.72,"id":3622149}]}]}
{"op":"mcm","clk":"1007206341","pt":1580653587452,"mc":[{"id":"1.168230754","rc":[{"batb":[[0,2.02,15.2],[1,1.99,20.35],[2,1.92,60.58]],"ltp":2.0,"tv":337.72,"id":3622149}]}]}
{"op":"mcm","clk":"1007206952","pt":1580653591141,"mc":[{"id":"1.168230754","rc":[{"batl":[[0,1.99,21.67]],"ltp":1.98,"tv":1136.83,"id":2263603}]}]}
{"op":"mcm","clk":"1007207111","pt":1580653592161,"mc":[{"id":"1.168230754","rc":[{"batb":[[2,1.93,60.58]],"ltp":2.0,"tv":337.72,"id":3622149}]}]}
{"op":"mcm","clk":"1007207236","pt":1580653593015,"mc":[{"id":"1.168230754","rc":[{"batl":[[0,2,17.66],[1,2.02,83.09],[2,2.28,18.94]],"ltp":1.98,"tv":1136.83,"id":2263603}]}]}
{"op":"mcm","clk":"1007238000","pt":1580653781078,"mc":[{"id":"1.168230754","rc":[{"batl":[[0,1.99,7.57],[1,2,17.66],[2,2.02,83.09]],"ltp":1.98,"tv":1136.83,"id":2263603}]}]}
{"op":"mcm","clk":"1007238295","pt":1580653782863,"mc":[{"id":"1.168230754","rc":[{"batl":[[0,2,17.66],[1,2.02,83.09],[2,2.28,18.94]],"ltp":1.98,"tv":1136.83,"id":2263603}]}]}
{"op":"mcm","clk":"1007266239","pt":1580653958480,"mc":[{"id":"1.168230754","rc":[{"trd":[[2.02,53.23]],"batb":[[0,2.02,6.73]],"ltp":2.02,"tv":354.66,"id":3622149}],"tv":1491.5}]}
{"op":"mcm","clk":"1007271073","pt":1580653989430,"mc":[{"id":"1.168230754","rc":[{"trd":[[2.02,66.7]],"batb":[[0,1.99,20.35],[1,1.93,60.58],[2,1.89,425.41]],"batl":[[0,2.02,2.04],[1,2.06,12.6],[2,2.1,50.41]],"ltp":2.02,"tv":368.13,"id":3622149}],"tv":1504.97}]}
{"op":"mcm","clk":"1007272242","pt":1580653996447,"mc":[{"id":"1.168230754","rc":[{"trd":[[1.98,10.22]],"batl":[[0,2,19.66]],"ltp":1.98,"tv":1142.95,"id":2263603}],"tv":1511.09}]}
{"op":"mcm","clk":"1007273170","pt":1580654002269,"mc":[{"id":"1.168230754","rc":[{"batl":[[1,2.1,50.41],[2,2.28,18.48]],"ltp":2.02,"tv":368.13,"id":3622149}]}]}
{"op":"mcm","clk":"1007273332","pt":1580654003189,"mc":[{"id":"1.168230754","rc":[{"trd":[[1.98,35.95]],"batb":[[0,1.94,120.7],[1,1.93,420.1],[2,1.92,420.1]],"ltp":1.98,"tv":1168.68,"id":2263603}],"tv":1536.81}]}
{"op":"mcm","clk":"1007274037","pt":1580654007445,"mc":[{"id":"1.168230754","rc":[{"trd":[[1.98,38.03]],"batl":[[0,1.98,5.49],[1,2,19.66],[2,2.02,83.09]],"ltp":1.98,"tv":1170.76,"id":2263603},{"trd":[[2.02,68.74]],"batl":[[0,2.1,50.41],[1,2.28,18.48],[2,4.2,153.82]],"ltp":2.02,"tv":370.17,"id":3622149}],"tv":1540.94}]}
{"op":"mcm","clk":"1007274265","pt":1580654008852,"mc":[{"id":"1.168230754","rc":[{"batb":[[0,1.97,2.09],[1,1.94,120.7],[2,1.93,420.1]],"batl":[[0,2,19.66],[1,2.02,83.09],[2,2.28,18.94]],"ltp":1.98,"tv":1170.76,"id":2263603}]}]}
{"op":"mcm","clk":"1007276035","pt":1580654018971,"mc":[{"id":"1.168230754","rc":[{"batb":[[0,1.94,120.7],[1,1.93,420.1],[2,1.92,420.1]],"ltp":1.98,"tv":1170.76,"id":2263603}]}]}
{"op":"mcm","clk":"1007276481","pt":1580654021666,"mc":[{"id":"1.168230754","rc":[{"batb":[[0,1.95,2.11],[1,1.94,120.7],[2,1.93,420.1]],"ltp":1.98,"tv":1170.76,"id":2263603}]}]}
{"op":"mcm","clk":"1007277454","pt":1580654027281,"mc":[{"id":"1.168230754","rc":[{"batl":[[0,2,22.69]],"ltp":1.98,"tv":1170.76,"id":2263603}]}]}
{"op":"mcm","clk":"1007284232","pt":1580654065341,"mc":[{"id":"1.168230754","rc":[{"batb":[[0,1.95,10.96]],"ltp":1.98,"tv":1170.76,"id":2263603},{"batl":[[0,2.06,8.4],[1,2.1,50.41],[2,2.28,18.48]],"ltp":2.02,"tv":370.17,"id":3622149}]}]}
{"op":"mcm","clk":"1007293473","pt":1580654119927,"mc":[{"id":"1.168230754","rc":[{"batb":[[0,1.95,20.97]],"ltp":1.98,"tv":1170.76,"id":2263603},{"batl":[[0,2.06,16.8]],"ltp":2.02,"tv":370.17,"id":3622149}]}]}
{"op":"mcm","clk":"1007297635","pt":1580654143215,"mc":[{"id":"1.168230754","rc":[{"batb":[[0,1.95,18.85]],"ltp":1.98,"tv":1170.76,"id":2263603}]}]}
{"op":"mcm","clk":"1007298106","pt":1580654145937,"mc":[{"id":"1.168230754","rc":[{"batb":[[0,1.97,2.09],[1,1.95,18.85],[2,1.94,120.7]],"ltp":1.98,"tv":1170.76,"id":2263603}]}]}
{"op":"mcm","clk":"1007300427","pt":1580654159477,"mc":[{"id":"1.168230754","rc":[{"batb":[[1,1.95,10.01]],"ltp":1.98,"tv":1170.76,"id":2263603},{"batl":[[0,2.04,8.4],[1,2.06,8.4],[2,2.1,50.41]],"ltp":2.02,"tv":370.17,"id":3622149}]}]}
{"op":"mcm","clk":"1007300483","pt":1580654159751,"mc":[{"id":"1.168230754","rc":[{"batb":[[0,1.97,10.75]],"ltp":1.98,"tv":1170.76,"id":2263603}]}]}
{"op":"mcm","clk":"1007305791","pt":1580654191058,"mc":[{"id":"1.168230754","rc":[{"batb":[[0,1.97,2.09]],"ltp":1.98,"tv":1170.76,"id":2263603}]}]}
{"op":"mcm","clk":"1007319184","pt":1580654266876,"mc":[{"id":"1.168230754","rc":[{"trd":[[2,19.3]],"batl":[[0,2,20.14]],"ltp":2.0,"tv":1175.86,"id":2263603}],"tv":1546.04}]}
{"op":"mcm","clk":"1007319718","pt":1580654270051,"mc":[{"id":"1.168230754","rc":[{"batb":[[0,1.95,10.01],[1,1.94,120.7],[2,1.93,420.1]],"ltp":2.0,"tv":1175.86,"id":2263603}]}]}
{"op":"mcm","clk":"1007319948","pt":1580654271275,"mc":[{"id":"1.168230754","rc":[{"batl":[[0,2,27.71]],"ltp":2.0,"tv":1175.86,"id":2263603}]}]}
{"op":"mcm","clk":"1007320230","pt":1580654272806,"mc":[{"id":"1.168230754","rc":[{"batb":[[0,1.98,2.08],[1,1.95,10.01],[2,1.94,120.7]],"ltp":2.0,"tv":1175.86,"id":2263603}]}]}
{"op":"mcm","clk":"1007320449","pt":1580654274002,"mc":[{"id":"1.168230754","rc":[{"trd":[[1.98,42.19]],"batb":[[0,1.95,10.01],[1,1.94,120.7],[2,1.93,420.1]],"ltp":1.98,"tv":1180.02,"id":2263603}],"tv":1550.2}]}
{"op":"mcm","clk":"1007322326","pt":1580654284190,"mc":[{"id":"1.168230754","rc":[{"batb":[[0,1.96,8.75],[1,1.95,10.01],[2,1.94,120.7]],"ltp":1.98,"tv":1180.02,"id":2263603}]}]}
{"op":"mcm","clk":"1007323267","pt":1580654289218,"mc":[{"id":"1.168230754","rc":[{"trd":[[2,27.7]],"batl":[[0,2,19.31]],"ltp":2.0,"tv":1188.42,"id":2263603},{"trd":[[2,186.73]],"ltp":2.0,"tv":378.58,"id":3622149}],"tv":1567.0}]}
{"op":"mcm","clk":"1007323941","pt":1580654293420,"mc":[{"id":"1.168230754","rc":[{"batl":[[0,2,26.88]],"ltp":2.0,"tv":1188.42,"id":2263603}]}]}
{"op":"mcm","clk":"1007324584","pt":1580654297091,"mc":[{"id":"1.168230754","rc":[{"batl":[[0,2,34.46]],"ltp":2.0,"tv":1188.42,"id":2263603}]}]}
{"op":"mcm","clk":"1007324956","pt":1580654299308,"mc":[{"id":"1.168230754","rc":[{"batl":[[0,2,11.74]],"ltp":2.0,"tv":1188.42,"id":2263603}]}]}
{"op":"mcm","clk":"1007325044","pt":1580654299800,"mc":[{"id":"1.168230754","rc":[{"batl":[[0,2,19.31]],"ltp":2.0,"tv":1188.42,"id":2263603}]}]}
{"op":"mcm","clk":"1007325315","pt":1580654301423,"mc":[{"id":"1.168230754","rc":[{"batl":[[0,2,26.88]],"ltp":2.0,"tv":1188.42,"id":2263603}]}]}
{"op":"mcm","clk":"1007325804","pt":1580654304324,"mc":[{"id":"1.168230754","rc":[{"batl":[[0,2,19.31]],"ltp":2.0,"tv":1188.42,"id":2263603}]}]}
{"op":"mcm","clk":"1007336614","pt":1580654372009,"mc":[{"id":"1.168230754","rc":[{"trd":[[2,28.58]],"batl":[[0,2,18.43]],"ltp":2.0,"tv":1189.3,"id":2263603},{"trd":[[2,187.61]],"ltp":2.0,"tv":379.46,"id":3622149}],"tv":1568.77}]}
{"op":"mcm","clk":"1007341074","pt":1580654400924,"mc":[{"id":"1.168230754","rc":[{"batl":[[0,2,26]],"ltp":2.0,"tv":1189.3,"id":2263603}]}]}
{"op":"mcm","clk":"1007341407","pt":1580654403003,"mc":[{"id":"1.168230754","rc":[{"batl":[[0,2,18.43]],"ltp":2.0,"tv":1189.3,"id":2263603}]}]}
{"op":"mcm","clk":"1007405882","pt":1580654817846,"mc":[{"id":"1.168230754","rc":[{"batl":[[0,2,26]],"ltp":2.0,"tv":1189.3,"id":2263603}]}]}
{"op":"mcm","clk":"1007406108","pt":1580654819761,"mc":[{"id":"1.168230754","rc":[{"batl":[[0,2,10.86]],"ltp":2.0,"tv":1189.3,"id":2263603}]}]}
{"op":"mcm","clk":"1007412251","pt":1580654867552,"mc":[{"id":"1.168230754","rc":[{"batl":[[0,2.02,7.57],[1,2.04,8.4],[2,2.06,8.4]],"ltp":2.0,"tv":379.46,"id":3622149}]}]}
{"op":"mcm","clk":"1007413007","pt":1580654873534,"mc":[{"id":"1.168230754","rc":[{"batb":[[0,1.95,10.01],[1,1.94,120.7],[2,1.93,420.1]],"ltp":2.0,"tv":1189.3,"id":2263603},{"batl":[[1,2.06,8.4],[2,2.1,50.41]],"ltp":2.0,"tv":379.46,"id":3622149}]}]}
{"op":"mcm","clk":"1007413071","pt":1580654873923,"mc":[{"id":"1.168230754","rc":[{"trd":[[1.98,46.51]],"batb":[[0,1.98,6.41],[1,1.95,10.01],[2,1.94,120.7]],"ltp":1.98,"tv":1193.62,"id":2263603}],"tv":1573.09}]}
{"op":"mcm","clk":"1007414627","pt":1580654885320,"mc":[{"id":"1.168230754","rc":[{"trd":[[2.02,83.89]],"batl":[[0,2.06,8.4],[1,2.1,50.41],[2,2.28,18.48]],"ltp":2.02,"tv":394.6,"id":3622149}],"tv":1588.23}]}
{"op":"mcm","clk":"1007414741","pt":1580654886065,"mc":[{"id":"1.168230754","rc":[{"batb":[[1,1.95,18.61]],"ltp":1.98,"tv":1193.62,"id":2263603},{"batb":[[0,1.99,12.75]],"ltp":2.02,"tv":394.6,"id":3622149}]}]}
{"op":"mcm","clk":"1007417136","pt":1580654905123,"mc":[{"id":"1.168230754","rc":[{"batb":[[0,1.95,18.61],[1,1.94,120.7],[2,1.93,420.1]],"ltp":1.98,"tv":1193.62,"id":2263603}]}]}
{"op":"mcm","clk":"1007421132","pt":1580654936461,"mc":[{"id":"1.168230754","rc":[{"batl":[[0,2,19.26]],"ltp":1.98,"tv":1193.62,"id":2263603},{"batb":[[0,2,8.4],[1,1.99,12.75],[2,1.93,60.58]],"ltp":2.02,"tv":394.6,"id":3622149}]}]}
{"op":"mcm","clk":"1007421222","pt":1580654937091,"mc":[{"id":"1.168230754","rc":[{"batb":[[0,1.95,27.46]],"ltp":1.98,"tv":1193.62,"id":2263603},{"batl":[[0,2.06,16.8]],"ltp":2.02,"tv":394.6,"id":3622149}]}]}
{"op":"mcm","clk":"1007428890","pt":1580654994810,"mc":[{"id":"1.168230754","rc":[{"batl":[[0,1.99,7.57],[1,2,19.26],[2,2.02,83.09]],"ltp":1.98,"tv":1193.62,"id":2263603}]}]}
{"op":"mcm","clk":"1007429634","pt":1580655000546,"mc":[{"id":"1.168230754","rc":[{"batl":[[0,1.99,15.97],[1,2,10.86]],"ltp":1.98,"tv":1193.62,"id":2263603}]}]}
{"op":"mcm","clk":"1007445553","pt":1580655132086,"mc":[{"id":"1.168230754","rc":[{"batl":[[0,1.99,23.55]],"ltp":1.98,"tv":1193.62,"id":2263603}]}]}
{"op":"mcm","clk":"1007445715","pt":1580655133402,"mc":[{"id":"1.168230754","rc":[{"batl":[[0,1.99,8.4]],"ltp":1.98,"tv":1193.62,"id":2263603}]}]}
{"op":"mcm","clk":"1007445818","pt":1580655134195,"mc":[{"id":"1.168230754","rc":[{"batl":[[0,1.99,15.97]],"ltp":1.98,"tv":1193.62,"id":2263603}]}]}
{"op":"mcm","clk":"1007451669","pt":1580655185383,"mc":[{"id":"1.168230754","rc":[{"batl":[[0,1.99,23.55]],"ltp":1.98,"tv":1193.62,"id":2263603}]}]}
{"op":"mcm","clk":"1007452102","pt":1580655188665,"mc":[{"id":"1.168230754","rc":[{"batl":[[0,1.99,8.4]],"ltp":1.98,"tv":1193.62,"id":2263603}]}]}
{"op":"mcm","clk":"1007511068","pt":1580655651720,"mc":[{"id":"1.168230754","rc":[{"trd":[[2,190.98]],"batb":[[0,2,6.72]],"ltp":2.0,"tv":397.96,"id":3622149}],"tv":1591.59}]}
{"op":"mcm","clk":"1007515531","pt":1580655681462,"mc":[{"id":"1.168230754","rc":[{"batb":[[2,1.93,422.18]],"batl":[[2,2.02,85.34]],"ltp":1.98,"tv":1193.62,"id":2263603},{"batb":[[2,1.98,2]],"batl":[[1,2.1,52.41],[2,2.12,2.21]],"ltp":2.0,"tv":397.96,"id":3622149}]}]}
{"op":"mcm","clk":"1007545226","pt":1580655842579,"mc":[{"id":"1.168230754","rc":[{"trd":[[2,198.4]],"batb":[[0,2,3.01]],"ltp":2.0,"tv":405.39,"id":3622149}],"tv":1599.02}]}
{"op":"mcm","clk":"1007570019","pt":1580655964372,"mc":[{"id":"1.168230754","rc":[{"batb":[[0,1.95,36.36]],"batl":[[0,1.99,14.03]],"ltp":1.98,"tv":1193.62,"id":2263603}]}]}
{"op":"mcm","clk":"1007570146","pt":1580655965006,"mc":[{"id":"1.168230754","rc":[{"batl":[[2,2.12,2.13]],"ltp":2.0,"tv":405.39,"id":3622149}]}]}
{"op":"mcm","clk":"1007584003","pt":1580656031644,"mc":[{"id":"1.168230754","rc":[{"batb":[[0,1.96,4.72],[1,1.95,36.36],[2,1.94,111.37]],"ltp":1.98,"tv":1193.62,"id":2263603}]}]}
{"op":"mcm","clk":"1007584197","pt":1580656032531,"mc":[{"id":"1.168230754","rc":[{"batb":[[2,1.94,113.46]],"ltp":1.98,"tv":1193.62,"id":2263603},{"batl":[[2,2.12,2.21]],"ltp":2.0,"tv":405.39,"id":3622149}]}]}
{"op":"mcm","clk":"1007584818","pt":1580656035541,"mc":[{"id":"1.168230754","rc":[{"batb":[[0,1.96,13.48],[1,1.95,27.51]],"ltp":1.98,"tv":1193.62,"id":2263603}]}]}
{"op":"mcm","clk":"1007585755","pt":1580656039542,"mc":[{"id":"1.168230754","rc":[{"batl":[[0,1.99,8.4]],"ltp":1.98,"tv":1193.62,"id":2263603},{"batl":[[0,2.04,5.49],[1,2.06,16.8],[2,2.1,52.41]],"ltp":2.0,"tv":405.39,"id":3622149}]}]}
{"op":"mcm","clk":"1007585922","pt":1580656040350,"mc":[{"id":"1.168230754","rc":[{"batl":[[2,2.08,2.07]],"ltp":2.0,"tv":405.39,"id":3622149}]}]}
{"op":"mcm","clk":"1007591985","pt":1580656067399,"mc":[{"id":"1.168230754","rc":[{"batl":[[0,2.04,13.89],[1,2.06,8.4]],"ltp":2.0,"tv":405.39,"id":3622149}]}]}
{"op":"mcm","clk":"1007615037","pt":1580656166207,"mc":[{"id":"1.168230754","rc":[{"batb":[[0,1.96,8.75],[1,1.95,32.23]],"ltp":1.98,"tv":1193.62,"id":2263603}]}]}
{"op":"mcm","clk":"1007617880","pt":1580656178396,"mc":[{"id":"1.168230754","rc":[{"batl":[[0,1.99,14.03]],"ltp":1.98,"tv":1193.62,"id":2263603},{"batl":[[0,2.04,8.4]],"ltp":2.0,"tv":405.39,"id":3622149}]}]}
{"op":"mcm","clk":"1007655660","pt":1580656332419,"mc":[{"id":"1.168230754","rc":[{"batb":[[0,1.96,428.85],[1,1.95,452.33]],"ltp":1.98,"tv":1193.62,"id":2263603}]}]}
{"op":"mcm","clk":"1007656180","pt":1580656334644,"mc":[{"id":"1.168230754","rc":[{"batb":[[0,1.97,12.43],[1,1.96,428.85],[2,1.95,444.43]],"ltp":1.98,"tv":1193.62,"id":2263603}]}]}
{"op":"mcm","clk":"1007657309","pt":1580656339347,"mc":[{"id":"1.168230754","rc":[{"batl":[[0,1.99,8.4]],"ltp":1.98,"tv":1193.62,"id":2263603},{"batl":[[0,2.04,13.89]],"ltp":2.0,"tv":405.39,"id":3622149}]}]}
{"op":"mcm","clk":"1007658073","pt":1580656342451,"mc":[{"id":"1.168230754","rc":[{"batb":[[2,1.95,435.53]],"batl":[[2,2.02,451.67]],"ltp":1.98,"tv":1193.62,"id":2263603}]}]}
{"op":"mcm","clk":"1007658514","pt":1580656344232,"mc":[{"id":"1.168230754","rc":[{"batl":[[1,2,21.4]],"ltp":1.98,"tv":1193.62,"id":2263603},{"batb":[[1,1.99,21.32]],"ltp":2.0,"tv":405.39,"id":3622149}]}]}
{"op":"mcm","clk":"1007659731","pt":1580656349377,"mc":[{"id":"1.168230754","rc":[{"batb":[[0,1.97,21.1],[1,1.96,420.1]],"ltp":1.98,"tv":1193.62,"id":2263603}]}]}
{"op":"mcm","clk":"1007678292","pt":1580656429570,"mc":[{"id":"1.168230754","rc":[{"batb":[[0,1.97,30.12]],"ltp":1.98,"tv":1193.62,"id":2263603}]}]}
{"op":"mcm","clk":"1007763235","pt":1580656796296,"mc":[{"id":"1.168230754","rc":[{"trd":[[1.97,1.8]],"batb":[[0,1.97,29.22]],"ltp":1.97,"tv":1195.42,"id":2263603}],"tv":1600.81}]}
{"op":"mcm","clk":"1007829885","pt":1580657090578,"mc":[{"id":"1.168230754","rc":[{"trd":[[2,201.94]],"batb":[[0,2,1.24]],"ltp":2.0,"tv":408.93,"id":3622149}],"tv":1604.35}]}
{"op":"mcm","clk":"1007830077","pt":1580657091495,"mc":[{"id":"1.168230754","rc":[{"batb":[[2,1.98,2.26]],"ltp":2.0,"tv":408.93,"id":3622149}]}]}
{"op":"mcm","clk":"1007832490","pt":1580657102599,"mc":[{"id":"1.168230754","rc":[{"batl":[[0,2,21.4],[1,2.02,449.42],[2,2.04,2.58]],"ltp":1.97,"tv":1195.42,"id":2263603},{"batb":[[0,1.99,21.32],[1,1.97,2.17],[2,1.96,2.13]],"ltp":2.0,"tv":408.93,"id":3622149}]}]}
{"op":"mcm","clk":"1007832727","pt":1580657103580,"mc":[{"id":"1.168230754","rc":[{"batb":[[0,1.99,29.74],[1,1.98,2],[2,1.97,2.17]],"ltp":2.0,"tv":408.93,"id":3622149}]}]}
{"op":"mcm","clk":"1008029717","pt":1580657979617,"mc":[{"id":"1.168230754","rc":[{"trd":[[1.97,5.59]],"batb":[[0,1.97,27.33]],"ltp":1.97,"tv":1199.22,"id":2263603}],"tv":1608.15}]}
{"op":"mcm","clk":"1008029806","pt":1580657979940,"mc":[{"id":"1.168230754","rc":[{"batb":[[2,1.97,2]],"ltp":2.0,"tv":408.93,"id":3622149}]}]}
{"op":"mcm","clk":"1008119636","pt":1580658366539,"mc":[{"id":"1.168230754","rc":[{"batb":[[2,1.93,60.58]],"ltp":2.0,"tv":408.93,"id":3622149}]}]}
{"op":"mcm","clk":"1008119663","pt":1580658366707,"mc":[{"id":"1.168230754","rc":[{"batb":[[2,1.97,2]],"ltp":2.0,"tv":408.93,"id":3622149}]}]}
{"op":"mcm","clk":"1008121801","pt":1580658376612,"mc":[{"id":"1.168230754","rc":[{"batb":[[2,1.93,60.58]],"ltp":2.0,"tv":408.93,"id":3622149}]}]}
{"op":"mcm","clk":"1008121848","pt":1580658376825,"mc":[{"id":"1.168230754","rc":[{"batb":[[2,1.97,2.17]],"ltp":2.0,"tv":408.93,"id":3622149}]}]}
{"op":"mcm","clk":"1008200348","pt":1580658812455,"mc":[{"id":"1.168230754","rc":[{"batb":[[0,1.97,18.3]],"ltp":1.97,"tv":1199.22,"id":2263603},{"batb":[[0,1.99,21.32]],"batl":[[0,2.04,8.4]],"ltp":2.0,"tv":408.93,"id":3622149}]}]}
{"op":"mcm","clk":"1008200444","pt":1580658813049,"mc":[{"id":"1.168230754","rc":[{"batb":[[2,1.97,2]],"ltp":2.0,"tv":408.93,"id":3622149}]}]}
{"op":"mcm","clk":"1008203618","pt":1580658832393,"mc":[{"id":"1.168230754","rc":[{"batb":[[0,1.97,27.66]],"ltp":1.97,"tv":1199.22,"id":2263603},{"batb":[[0,1.99,30.59]],"batl":[[0,2.04,13.89]],"ltp":2.0,"tv":408.93,"id":3622149}]}]}
{"op":"mcm","clk":"1008203708","pt":1580658832985,"mc":[{"id":"1.168230754","rc":[{"batb":[[2,1.97,2.17]],"ltp":2.0,"tv":408.93,"id":3622149}]}]}
{"op":"mcm","clk":"1008212060","pt":1580658886458,"mc":[{"id":"1.168230754","rc":[{"batb":[[0,1.97,18.3]],"ltp":1.97,"tv":1199.22,"id":2263603},{"batb":[[0,1.99,21.32]],"batl":[[0,2.04,8.4]],"ltp":2.0,"tv":408.93,"id":3622149}]}]}
{"op":"mcm","clk":"1008217575","pt":1580658919462,"mc":[{"id":"1.168230754","rc":[{"batb":[[0,1.97,27.66]],"ltp":1.97,"tv":1199.22,"id":2263603},{"batb":[[0,1.99,30.59]],"batl":[[0,2.04,13.89]],"ltp":2.0,"tv":408.93,"id":3622149}]}]}
{"op":"mcm","clk":"1008217661","pt":1580658920023,"mc":[{"id":"1.168230754","rc":[{"batb":[[2,1.97,2]],"ltp":2.0,"tv":408.93,"id":3622149}]}]}
{"op":"mcm","clk":"1008236099","pt":1580659032503,"mc":[{"id":"1.168230754","rc":[{"trd":[[2,30.35]],"batl":[[0,2,19.63]],"ltp":2.0,"tv":1200.99,"id":2263603},{"trd":[[2,203.71]],"batb":[[2,1.93,60.58]],"ltp":2.0,"tv":410.7,"id":3622149}],"tv":1611.69}]}
{"op":"mcm","clk":"1008236136","pt":1580659032720,"mc":[{"id":"1.168230754","rc":[{"batb":[[2,1.97,2.17]],"ltp":2.0,"tv":410.7,"id":3622149}]}]}
{"op":"mcm","clk":"1008261449","pt":1580659198523,"mc":[{"id":"1.168230754","rc":[{"batl":[[0,2,81.73],[1,2.02,387.32]],"ltp":2.0,"tv":1200.99,"id":2263603}]}]}
{"op":"mcm","clk":"1008262257","pt":1580659202669,"mc":[{"id":"1.168230754","rc":[{"batb":[[0,1.97,18.03]],"batl":[[0,2,71.18]],"ltp":2.0,"tv":1200.99,"id":2263603},{"batb":[[0,1.99,22.02]],"batl":[[1,2.08,2.07],[2,2.1,52.41]],"ltp":2.0,"tv":410.7,"id":3622149}]}]}
{"op":"mcm","clk":"1008263298","pt":1580659207520,"mc":[{"id":"1.168230754","rc":[{"batb":[[0,1.97,8.66]],"ltp":2.0,"tv":1200.99,"id":2263603},{"batl":[[2,2.1,52.46]],"ltp":2.0,"tv":410.7,"id":3622149}]}]}
{"op":"mcm","clk":"1008263397","pt":1580659208009,"mc":[{"id":"1.168230754","rc":[{"batl":[[0,2,73.94]],"ltp":2.0,"tv":1200.99,"id":2263603}]}]}
{"op":"mcm","clk":"1008265415","pt":1580659218400,"mc":[{"id":"1.168230754","rc":[{"batb":[[0,1.99,12.75]],"ltp":2.0,"tv":410.7,"id":3622149}]}]}
{"op":"mcm","clk":"1008267080","pt":1580659227082,"mc":[{"id":"1.168230754","rc":[{"batb":[[2,1.97,2]],"batl":[[2,2.1,52.41]],"ltp":2.0,"tv":410.7,"id":3622149}]}]}
{"op":"mcm","clk":"1008273984","pt":1580659266515,"mc":[{"id":"1.168230754","rc":[{"batl":[[2,2.1,52.46]],"ltp":2.0,"tv":410.7,"id":3622149}]}]}
{"op":"mcm","clk":"1008297486","pt":1580659392509,"mc":[{"id":"1.168230754","rc":[{"batb":[[2,1.93,60.58]],"batl":[[2,2.1,50.41]],"ltp":2.0,"tv":410.7,"id":3622149}]}]}
{"op":"mcm","clk":"1008297544","pt":1580659392820,"mc":[{"id":"1.168230754","rc":[{"batb":[[2,1.97,2.17]],"batl":[[2,2.1,52.46]],"ltp":2.0,"tv":410.7,"id":3622149}]}]}
{"op":"mcm","clk":"1008305312","pt":1580659432966,"mc":[{"id":"1.168230754","rc":[{"batl":[[2,2.1,52.41]],"ltp":2.0,"tv":410.7,"id":3622149}]}]}
{"op":"mcm","clk":"1008469159","pt":1580660179087,"mc":[{"id":"1.168230754","rc":[{"batb":[[2,1.97,2]],"batl":[[2,2.1,52.46]],"ltp":2.0,"tv":410.7,"id":3622149}]}]}
{"op":"mcm","clk":"1008473135","pt":1580660196452,"mc":[{"id":"1.168230754","rc":[{"batl":[[2,2.1,52.41]],"ltp":2.0,"tv":410.7,"id":3622149}]}]}
{"op":"mcm","clk":"1008473401","pt":1580660197634,"mc":[{"id":"1.168230754","rc":[{"batl":[[0,2,11.85]],"ltp":2.0,"tv":1200.99,"id":2263603}]}]}
{"op":"mcm","clk":"1008473461","pt":1580660197965,"mc":[{"id":"1.168230754","rc":[{"batl":[[2,2.04,64.68]],"ltp":2.0,"tv":1200.99,"id":2263603}]}]}
{"op":"mcm","clk":"1008473791","pt":1580660199471,"mc":[{"id":"1.168230754","rc":[{"batl":[[0,2.04,123.12]],"ltp":2.0,"tv":410.7,"id":3622149}]}]}
{"op":"mcm","clk":"1008474955","pt":1580660204463,"mc":[{"id":"1.168230754","rc":[{"batb":[[0,1.99,21.03],[2,1.97,2.17]],"batl":[[2,2.1,52.46]],"ltp":2.0,"tv":410.7,"id":3622149}]}]}
{"op":"mcm","clk":"1008570552","pt":1580660617402,"mc":[{"id":"1.168230754","rc":[{"batb":[[0,1.99,12.75]],"batl":[[0,2.04,117.63]],"ltp":2.0,"tv":410.7,"id":3622149}]}]}
{"op":"mcm","clk":"1008587891","pt":1580660695350,"mc":[{"id":"1.168230754","rc":[{"batb":[[0,1.99,21.47]],"ltp":2.0,"tv":410.7,"id":3622149}]}]}
{"op":"mcm","clk":"1008605742","pt":1580660779530,"mc":[{"id":"1.168230754","rc":[{"batl":[[0,2.04,119.63]],"ltp":2.0,"tv":410.7,"id":3622149}]}]}
{"op":"mcm","clk":"1008605877","pt":1580660780210,"mc":[{"id":"1.168230754","rc":[{"batl":[[2,2.1,52.41]],"ltp":2.0,"tv":410.7,"id":3622149}]}]}
{"op":"mcm","clk":"1008642506","pt":1580660950050,"mc":[{"id":"1.168230754","rc":[{"batb":[[2,1.97,2]],"batl":[[2,2.1,52.46]],"ltp":2.0,"tv":410.7,"id":3622149}]}]}
{"op":"mcm","clk":"1008650740","pt":1580660990506,"mc":[{"id":"1.168230754","rc":[{"batb":[[2,1.97,2.17]],"ltp":2.0,"tv":410.7,"id":3622149}]}]}
{"op":"mcm","clk":"1008654604","pt":1580661008895,"mc":[{"id":"1.168230754","rc":[{"batb":[[2,1.95,433.42]],"batl":[[2,2.04,62.55]],"ltp":2.0,"tv":1200.99,"id":2263603}]}]}
{"op":"mcm","clk":"1008654913","pt":1580661010283,"mc":[{"id":"1.168230754","rc":[{"batb":[[1,1.91,60.58],[2,1.88,430.24]],"batl":[[1,2.1,50.41],[2,2.28,18.48]],"ltp":2.0,"tv":410.7,"id":3622149}]}]}
{"op":"mcm","clk":"1008685261","pt":1580661149055,"mc":[{"id":"1.168230754","rc":[{"batl":[[0,2,56.18]],"ltp":2.0,"tv":1200.99,"id":2263603}]}]}
{"op":"mcm","clk":"1008687159","pt":1580661158005,"mc":[{"id":"1.168230754","rc":[{"batb":[[0,1.99,12.75]],"ltp":2.0,"tv":410.7,"id":3622149}]}]}
{"op":"mcm","clk":"1008699179","pt":1580661212305,"mc":[{"id":"1.168230754","rc":[{"trd":[[2,36.35]],"batb":[[2,1.95,435.42]],"batl":[[0,2,50.18],[2,2.04,64.55]],"ltp":2.0,"tv":1206.99,"id":2263603},{"trd":[[2,209.71]],"batb":[[1,1.98,2.26],[2,1.97,2.17]],"batl":[[1,2.08,2.19],[2,2.1,52.41]],"ltp":2.0,"tv":416.7,"id":3622149}],"tv":1623.69}]}
{"op":"mcm","clk":"1008707118","pt":1580661250568,"mc":[{"id":"1.168230754","rc":[{"trd":[[2,61.35]],"batl":[[0,2,25.18]],"ltp":2.0,"tv":1231.99,"id":2263603},{"trd":[[2,234.71]],"ltp":2.0,"tv":441.7,"id":3622149}],"tv":1673.69}]}
{"op":"mcm","clk":"1008707227","pt":1580661251105,"mc":[{"id":"1.168230754","rc":[{"batl":[[2,2.1,52.46]],"ltp":2.0,"tv":441.7,"id":3622149}]}]}
{"op":"mcm","clk":"1008707815","pt":1580661253908,"mc":[{"id":"1.168230754","rc":[{"batb":[[0,1.99,36.41]],"ltp":2.0,"tv":441.7,"id":3622149}]}]}
{"op":"mcm","clk":"1008740860","pt":1580661406607,"mc":[{"id":"1.168230754","rc":[{"batb":[[2,1.91,60.58]],"batl":[[2,2.1,50.41]],"ltp":2.0,"tv":441.7,"id":3622149}]}]}
{"op":"mcm","clk":"1008740912","pt":1580661406815,"mc":[{"id":"1.168230754","rc":[{"batb":[[2,1.97,2]],"batl":[[2,2.1,52.46]],"ltp":2.0,"tv":441.7,"id":3622149}]}]}
{"op":"mcm","clk":"1008800823","pt":1580661679496,"mc":[{"id":"1.168230754","rc":[{"batb":[[0,1.99,12.75]],"ltp":2.0,"tv":441.7,"id":3622149}]}]}
{"op":"mcm","clk":"1008801001","pt":1580661680395,"mc":[{"id":"1.168230754","rc":[{"batb":[[0,1.99,36.41],[2,1.97,2.17]],"ltp":2.0,"tv":441.7,"id":3622149}]}]}
{"op":"mcm","clk":"1008811055","pt":1580661727536,"mc":[{"id":"1.168230754","rc":[{"batb":[[0,1.97,426.51]],"ltp":2.0,"tv":1231.99,"id":2263603},{"batb":[[2,1.97,2]],"batl":[[2,2.1,52.41]],"ltp":2.0,"tv":441.7,"id":3622149}]}]}
{"op":"mcm","clk":"1008811218","pt":1580661728436,"mc":[{"id":"1.168230754","rc":[{"batb":[[0,1.97,454.59]],"ltp":2.0,"tv":1231.99,"id":2263603}]}]}
{"op":"mcm","clk":"1008814248","pt":1580661743558,"mc":[{"id":"1.168230754","rc":[{"batb":[[0,1.97,426.51]],"ltp":2.0,"tv":1231.99,"id":2263603}]}]}
{"op":"mcm","clk":"1008814422","pt":1580661744160,"mc":[{"id":"1.168230754","rc":[{"batb":[[2,1.97,2.17]],"ltp":2.0,"tv":441.7,"id":3622149}]}]}
{"op":"mcm","clk":"1008820224","pt":1580661774208,"mc":[{"id":"1.168230754","rc":[{"trd":[[1.97,40.43]],"batb":[[0,1.97,409.09]],"ltp":1.97,"tv":1266.82,"id":2263603},{"batb":[[2,1.97,2]],"batl":[[2,2.1,52.46]],"ltp":2.0,"tv":441.7,"id":3622149}],"tv":1708.52}]}
{"op":"mcm","clk":"1008822261","pt":1580661784325,"mc":[{"id":"1.168230754","rc":[{"batb":[[0,1.97,412.18]],"ltp":1.97,"tv":1266.82,"id":2263603}]}]}
{"op":"mcm","clk":"1008824934","pt":1580661797547,"mc":[{"id":"1.168230754","rc":[{"batb":[[0,1.98,8.57],[1,1.97,412.18],[2,1.96,422.23]],"ltp":1.97,"tv":1266.82,"id":2263603},{"batb":[[2,1.91,60.58]],"batl":[[2,2.1,50.41]],"ltp":2.0,"tv":441.7,"id":3622149}]}]}
{"op":"mcm","clk":"1008825052","pt":1580661798022,"mc":[{"id":"1.168230754","rc":[{"batb":[[2,1.97,2.17]],"batl":[[2,2.1,52.41]],"ltp":2.0,"tv":441.7,"id":3622149}]}]}
{"op":"mcm","clk":"1008828502","pt":1580661814500,"mc":[{"id":"1.168230754","rc":[{"batb":[[1,1.97,409.09]],"ltp":1.97,"tv":1266.82,"id":2263603}]}]}
{"op":"mcm","clk":"1008828637","pt":1580661815063,"mc":[{"id":"1.168230754","rc":[{"batl":[[2,2.1,52.46]],"ltp":2.0,"tv":441.7,"id":3622149}]}]}
{"op":"mcm","clk":"1008836403","pt":1580661852591,"mc":[{"id":"1.168230754","rc":[{"trd":[[1.98,95.19]],"batb":[[0,1.97,409.09],[1,1.96,422.23],[2,1.95,433.42]],"batl":[[0,2.02,388.16],[1,2.04,62.55],[2,2.06,2.09]],"ltp":1.98,"tv":1315.5,"id":2263603},{"batb":[[2,1.91,60.58]],"batl":[[2,2.1,50.41]],"ltp":2.0,"tv":441.7,"id":3622149}],"tv":1757.2}]}
{"op":"mcm","clk":"1008836578","pt":1580661853424,"mc":[{"id":"1.168230754","rc":[{"batb":[[1,1.96,420.1],[2,1.95,435.42]],"batl":[[2,2.06,2.25]],"ltp":1.98,"tv":1315.5,"id":2263603},{"batb":[[1,1.97,2.17],[2,1.96,2.13]],"batl":[[2,2.1,52.46]],"ltp":2.0,"tv":441.7,"id":3622149}]}]}
{"op":"mcm","clk":"1008837912","pt":1580661859595,"mc":[{"id":"1.168230754","rc":[{"batb":[[0,1.99,44.9]],"ltp":2.0,"tv":441.7,"id":3622149}]}]}
{"op":"mcm","clk":"1008838040","pt":1580661860178,"mc":[{"id":"1.168230754","rc":[{"batb":[[2,1.96,2]],"ltp":2.0,"tv":441.7,"id":3622149}]}]}
{"op":"mcm","clk":"1008841576","pt":1580661876620,"mc":[{"id":"1.168230754","rc":[{"batb":[[0,1.99,21.23]],"ltp":2.0,"tv":441.7,"id":3622149}]}]}
{"op":"mcm","clk":"1008843292","pt":1580661884618,"mc":[{"id":"1.168230754","rc":[{"batb":[[0,1.99,48.94]],"ltp":2.0,"tv":441.7,"id":3622149}]}]}
{"op":"mcm","clk":"1008846113","pt":1580661898165,"mc":[{"id":"1.168230754","rc":[{"batl":[[0,2.02,450.25],[1,2.06,2.7],[2,2.08,2]],"ltp":1.98,"tv":1315.5,"id":2263603},{"batb":[[2,1.96,2.13]],"ltp":2.0,"tv":441.7,"id":3622149}]}]}
{"op":"mcm","clk":"1008860056","pt":1580661966329,"mc":[{"id":"1.168230754","rc":[{"batl":[[2,2.08,2.07]],"ltp":1.98,"tv":1315.5,"id":2263603}]}]}
{"op":"mcm","clk":"1008862786","pt":1580661979552,"mc":[{"id":"1.168230754","rc":[{"batl":[[0,2.02,388.16],[1,2.04,62.55],[2,2.06,2.25]],"ltp":1.98,"tv":1315.5,"id":2263603}]}]}
{"op":"mcm","clk":"1008862882","pt":1580661980021,"mc":[{"id":"1.168230754","rc":[{"batb":[[2,1.96,2]],"ltp":2.0,"tv":441.7,"id":3622149}]}]}
{"op":"mcm","clk":"1008865943","pt":1580661995558,"mc":[{"id":"1.168230754","rc":[{"trd":[[1.98,96.03],[2.02,280.62]],"batl":[[0,2.02,106.7]],"ltp":2.02,"tv":1596.95,"id":2263603},{"trd":[[1.98,286.29],[1.99,97.92],[2.02,84.7]],"batb":[[0,1.97,2.17],[1,1.96,2],[2,1.95,2.11]],"ltp":1.98,"tv":826.72,"id":3622149}],"tv":2423.68}]}
{"op":"mcm","clk":"1008866153","pt":1580661996575,"mc":[{"id":"1.168230754","rc":[{"batb":[[0,1.98,12.75],[1,1.97,409.09],[2,1.96,420.1]],"ltp":2.02,"tv":1596.95,"id":2263603},{"batb":[[0,1.97,8.73]],"ltp":1.98,"tv":826.72,"id":3622149}]}]}
{"op":"mcm","clk":"1008866293","pt":1580661997381,"mc":[{"id":"1.168230754","rc":[{"batb":[[2,1.96,422.23]],"ltp":2.02,"tv":1596.95,"id":2263603},{"batl":[[0,2.02,15.04],[1,2.04,119.63],[2,2.06,2.09]],"ltp":1.98,"tv":826.72,"id":3622149}]}]}
{"op":"mcm","clk":"1008866802","pt":1580662000054,"mc":[{"id":"1.168230754","rc":[{"batb":[[0,1.98,3.06],[1,1.97,8.73],[2,1.96,2]],"ltp":1.98,"tv":826.72,"id":3622149}]}]}
{"op":"mcm","clk":"1008867229","pt":1580662002356,"mc":[{"id":"1.168230754","rc":[{"trd":[[2.02,387.32]],"batl":[[0,2.04,62.55],[1,2.08,2.07],[2,2.1,2.05]],"ltp":2.02,"tv":1703.66,"id":2263603},{"trd":[[1.97,17.46],[1.98,401.27]],"batb":[[0,1.94,2],[1,1.93,2.08],[2,1.92,2.07]],"ltp":1.97,"tv":959.16,"id":3622149}],"tv":2662.83}]}
{"op":"mcm","clk":"1008867812","pt":1580662005387,"mc":[{"id":"1.168230754","rc":[{"batl":[[1,2.08,2],[2,2.1,2]],"ltp":2.02,"tv":1703.66,"id":2263603}]}]}
{"op":"mcm","clk":"1008869235","pt":1580662012572,"mc":[{"id":"1.168230754","rc":[{"batl":[[0,2.06,62.55]],"ltp":2.02,"tv":1703.66,"id":2263603}]}]}
{"op":"mcm","clk":"1008869422","pt":1580662013482,"mc":[{"id":"1.168230754","rc":[{"batl":[[1,2.1,2],[2,2.12,2.21]],"ltp":2.02,"tv":1703.66,"id":2263603},{"batb":[[0,1.92,2.19],[1,1.91,2.06],[2,1.88,60.58]],"ltp":1.97,"tv":959.16,"id":3622149}]}]}
{"op":"mcm","clk":"1008869590","pt":1580662014394,"mc":[{"id":"1.168230754","rc":[{"batb":[[0,1.99,8.6],[1,1.98,12.75],[2,1.97,411.09]],"ltp":2.02,"tv":1703.66,"id":2263603},{"batb":[[0,1.95,8.97],[1,1.93,2.08],[2,1.92,2.19]],"ltp":1.97,"tv":959.16,"id":3622149}]}]}
{"op":"mcm","clk":"1008869859","pt":1580662015579,"mc":[{"id":"1.168230754","rc":[{"trd":[[2.04,0.45]],"batb":[[0,1.99,10.6],[1,1.98,14.75]],"batl":[[0,2.06,70.49]],"ltp":2.04,"tv":1704.11,"id":2263603},{"trd":[[1.96,19.53]],"batl":[[0,2,2],[1,2.02,17.04],[2,2.04,111.23]],"ltp":1.96,"tv":978.69,"id":3622149}],"tv":2682.81}]}
{"op":"mcm","clk":"1008870037","pt":1580662016373,"mc":[{"id":"1.168230754","rc":[{"batb":[[0,1.99,17.08],[1,1.98,12.75]],"ltp":2.04,"tv":1704.11,"id":2263603},{"batb":[[0,1.95,17.82]],"batl":[[0,2.02,23.45],[1,2.04,111.23],[2,2.06,2.25]],"ltp":1.96,"tv":978.69,"id":3622149}]}]}
{"op":"mcm","clk":"1008870122","pt":1580662016925,"mc":[{"id":"1.168230754","rc":[{"batb":[[1,1.98,36.95]],"batl":[[0,2.04,8.2],[1,2.06,70.49],[2,2.08,2.07]],"ltp":2.04,"tv":1704.11,"id":2263603},{"batb":[[1,1.94,2],[2,1.93,2.08]],"ltp":1.96,"tv":978.69,"id":3622149}]}]}
{"op":"mcm","clk":"1008871402","pt":1580662023493,"mc":[{"id":"1.168230754","rc":[{"batb":[[2,1.88,60.58]],"ltp":1.96,"tv":978.69,"id":3622149}]}]}
{"op":"mcm","clk":"1008871572","pt":1580662024413,"mc":[{"id":"1.168230754","rc":[{"batb":[[2,1.93,2.08]],"ltp":1.96,"tv":978.69,"id":3622149}]}]}
{"op":"mcm","clk":"1008872928","pt":1580662031594,"mc":[{"id":"1.168230754","rc":[{"batb":[[2,1.87,60.58]],"batl":[[0,2,3.03],[1,2.02,23.45],[2,2.04,113.36]],"ltp":1.96,"tv":978.69,"id":3622149}]}]}
{"op":"mcm","clk":"1008873062","pt":1580662032186,"mc":[{"id":"1.168230754","rc":[{"batb":[[1,1.98,38.95],[2,1.97,411.26]],"ltp":2.04,"tv":1704.11,"id":2263603},{"batb":[[2,1.93,2.08]],"ltp":1.96,"tv":978.69,"id":3622149}]}]}
{"op":"mcm","clk":"1008874413","pt":1580662039237,"mc":[{"id":"1.168230754","rc":[{"batb":[[2,1.97,411.09]],"ltp":2.04,"tv":1704.11,"id":2263603},{"batl":[[0,2,18.07],[1,2.02,8.4]],"ltp":1.96,"tv":978.69,"id":3622149}]}]}
{"op":"mcm","clk":"1008875851","pt":1580662047504,"mc":[{"id":"1.168230754","rc":[{"batl":[[1,2.06,62.09]],"ltp":2.04,"tv":1704.11,"id":2263603}]}]}
{"op":"mcm","clk":"1008876075","pt":1580662048499,"mc":[{"id":"1.168230754","rc":[{"batb":[[0,1.99,8.6]],"ltp":2.04,"tv":1704.11,"id":2263603},{"batl":[[1,2.04,113.36],[2,2.06,2]],"ltp":1.96,"tv":978.69,"id":3622149}]}]}
{"op":"mcm","clk":"1008876270","pt":1580662049631,"mc":[{"id":"1.168230754","rc":[{"batb":[[0,1.96,8.75],[1,1.95,8.97],[2,1.94,2]],"batl":[[0,2,26.48]],"ltp":1.96,"tv":978.69,"id":3622149}]}]}
{"op":"mcm","clk":"1008876830","pt":1580662053004,"mc":[{"id":"1.168230754","rc":[{"batl":[[0,2.06,62.09],[1,2.1,2.05],[2,2.12,2.21]],"ltp":2.04,"tv":1704.11,"id":2263603}]}]}
{"op":"mcm","clk":"1008880067","pt":1580662072323,"mc":[{"id":"1.168230754","rc":[{"batb":[[1,1.98,14.75],[2,1.97,411.26]],"ltp":2.04,"tv":1704.11,"id":2263603},{"batl":[[2,2.06,2.25]],"ltp":1.96,"tv":978.69,"id":3622149}]}]}
{"op":"mcm","clk":"1008881222","pt":1580662079433,"mc":[{"id":"1.168230754","rc":[{"batl":[[2,2.12,2.13]],"ltp":2.04,"tv":1704.11,"id":2263603},{"batl":[[0,1.99,15.04],[1,2,11.43],[2,2.02,2.25]],"ltp":1.96,"tv":978.69,"id":3622149}]}]}
{"op":"mcm","clk":"1008881568","pt":1580662081457,"mc":[{"id":"1.168230754","rc":[{"batb":[[0,1.95,8.97],[1,1.93,2.08],[2,1.92,2]],"batl":[[1,2,3.03]],"ltp":1.96,"tv":978.69,"id":3622149}]}]}
{"op":"mcm","clk":"1008883208","pt":1580662091448,"mc":[{"id":"1.168230754","rc":[{"batb":[[1,1.98,41.2],[2,1.97,411.09]],"batl":[[0,2.04,8.29],[1,2.06,62.09],[2,2.08,2.19]],"ltp":2.04,"tv":1704.11,"id":2263603},{"batb":[[1,1.94,2],[2,1.87,60.58]],"ltp":1.96,"tv":978.69,"id":3622149}]}]}
{"op":"mcm","clk":"1008883233","pt":1580662091655,"mc":[{"id":"1.168230754","rc":[{"batb":[[2,1.93,2.08]],"ltp":1.96,"tv":978.69,"id":3622149}]}]}
{"op":"mcm","clk":"1008885526","pt":1580662106467,"mc":[{"id":"1.168230754","rc":[{"batb":[[2,1.97,411.26]],"batl":[[0,2.06,62.09],[1,2.1,2.05],[2,2.12,2.21]],"ltp":2.04,"tv":1704.11,"id":2263603},{"batb":[[0,1.95,17.5],[1,1.93,2.08],[2,1.92,2.19]],"batl":[[0,2,3.03],[1,2.02,15.04],[2,2.04,113.36]],"ltp":1.96,"tv":978.69,"id":3622149}]}]}
{"op":"mcm","clk":"1008886804","pt":1580662114283,"mc":[{"id":"1.168230754","rc":[{"batb":[[2,1.97,411.09]],"batl":[[2,2.12,2.13]],"ltp":2.04,"tv":1704.11,"id":2263603}]}]}
{"op":"mcm","clk":"1008888465","pt":1580662124416,"mc":[{"id":"1.168230754","rc":[{"batb":[[2,1.97,411.26]],"batl":[[0,2.1,64.14],[1,2.12,2],[2,2.14,2.25]],"ltp":2.04,"tv":1704.11,"id":2263603}]}]}
{"op":"mcm","clk":"1008889074","pt":1580662128039,"mc":[{"id":"1.168230754","rc":[{"batl":[[0,2.08,8.02],[1,2.1,64.14],[2,2.12,2]],"ltp":2.04,"tv":1704.11,"id":2263603},{"batb":[[0,1.95,8.97]],"ltp":1.96,"tv":978.69,"id":3622149}]}]}
{"op":"mcm","clk":"1008890991","pt":1580662140313,"mc":[{"id":"1.168230754","rc":[{"batl":[[0,2.06,914.97],[1,2.08,8.02],[2,2.1,64.14]],"ltp":2.04,"tv":1704.11,"id":2263603}]}]}
{"op":"mcm","clk":"1008891954","pt":1580662146422,"mc":[{"id":"1.168230754","rc":[{"batb":[[0,2,485.63],[1,1.99,8.6],[2,1.98,41.2]],"ltp":2.04,"tv":1704.11,"id":2263603}]}]}
{"op":"mcm","clk":"1008892107","pt":1580662147406,"mc":[{"id":"1.168230754","rc":[{"batb":[[2,1.92,2]],"batl":[[1,2.02,15.51]],"ltp":1.96,"tv":978.69,"id":3622149}]}]}
{"op":"mcm","clk":"1008892454","pt":1580662149559,"mc":[{"id":"1.168230754","rc":[{"batb":[[0,2.02,6.12],[1,2,485.63],[2,1.98,28.45]],"ltp":2.04,"tv":1704.11,"id":2263603},{"trd":[[1.95,3.54]],"batb":[[0,1.95,7.2]],"ltp":1.95,"tv":982.23,"id":3622149}],"tv":2686.35}]}
{"op":"mcm","clk":"1008892602","pt":1580662150357,"mc":[{"id":"1.168230754","rc":[{"batb":[[2,1.99,2]],"ltp":2.04,"tv":1704.11,"id":2263603},{"batl":[[1,2.02,17.51]],"ltp":1.95,"tv":982.23,"id":3622149}]}]}
{"op":"mcm","clk":"1008897925","pt":1580662185595,"mc":[{"id":"1.168230754","rc":[{"trd":[[2.02,397.91]],"batb":[[0,2,486.46],[1,1.99,2],[2,1.97,409.09]],"batl":[[1,2.1,64.14],[2,2.28,18.48]],"ltp":2.02,"tv":1714.7,"id":2263603},{"batb":[[0,1.95,15.73],[2,1.81,467.81]],"batl":[[1,2.04,111.23],[2,2.1,50.41]],"ltp":1.95,"tv":982.23,"id":3622149}],"tv":2696.93}]}
{"op":"mcm","clk":"1008898012","pt":1580662186082,"mc":[{"id":"1.168230754","rc":[{"batb":[[0,2,485.63],[1,1.99,13.39],[2,1.98,2]],"batl":[[2,2.12,2.21]],"ltp":2.02,"tv":1714.7,"id":2263603},{"batb":[[0,1.95,21.19],[2,1.92,2]],"batl":[[1,2.04,113.23],[2,2.06,2.25]],"ltp":1.95,"tv":982.23,"id":3622149}]}]}
{"op":"mcm","clk":"1008901809","pt":1580662210541,"mc":[{"id":"1.168230754","rc":[{"batl":[[2,2.28,18.48]],"ltp":2.02,"tv":1714.7,"id":2263603},{"trd":[[1.99,124.4]],"batb":[[2,1.81,467.81]],"batl":[[0,1.99,2.04],[1,2,3.03],[2,2.02,2]],"ltp":1.99,"tv":1008.72,"id":3622149}],"tv":2723.42}]}
{"op":"mcm","clk":"1008901837","pt":1580662210752,"mc":[{"id":"1.168230754","rc":[{"batl":[[2,2.12,2.21]],"ltp":2.02,"tv":1714.7,"id":2263603},{"batb":[[2,1.92,2.19]],"ltp":1.99,"tv":1008.72,"id":3622149}]}]}
{"op":"mcm","clk":"1008902337","pt":1580662214002,"mc":[{"id":"1.168230754","rc":[{"batb":[[1,1.98,19.73],[2,1.97,411.26]],"ltp":2.02,"tv":1714.7,"id":2263603}]}]}
{"op":"mcm","clk":"1008908406","pt":1580662252637,"mc":[{"id":"1.168230754","rc":[{"batb":[[2,1.97,411.09]],"ltp":2.02,"tv":1714.7,"id":2263603},{"trd":[[1.99,149.15]],"batl":[[0,1.99,2.11]],"ltp":1.99,"tv":1033.46,"id":3622149}],"tv":2748.16}]}
{"op":"mcm","clk":"1008911448","pt":1580662273646,"mc":[{"id":"1.168230754","rc":[{"batb":[[2,1.97,411.26]],"batl":[[2,2.12,2]],"ltp":2.02,"tv":1714.7,"id":2263603},{"batl":[[0,2,3.03],[1,2.04,113.36],[2,2.06,2]],"ltp":1.99,"tv":1033.46,"id":3622149}]}]}
{"op":"mcm","clk":"1008914739","pt":1580662298553,"mc":[{"id":"1.168230754","rc":[{"batl":[[2,2.12,2.21]],"ltp":2.02,"tv":1714.7,"id":2263603},{"batb":[[2,1.92,2]],"batl":[[0,1.99,2.11],[1,2,3.03],[2,2.02,2]],"ltp":1.99,"tv":1033.46,"id":3622149}]}]}
{"op":"mcm","clk":"1008944761","pt":1580662522533,"mc":[{"id":"1.168230754","rc":[{"batl":[[0,1.98,41.65],[1,1.99,2.11],[2,2,3.03]],"ltp":1.99,"tv":1033.46,"id":3622149}]}]}
{"op":"mcm","clk":"1008944884","pt":1580662523524,"mc":[{"id":"1.168230754","rc":[{"batb":[[1,1.99,2],[2,1.98,19.99]],"ltp":2.02,"tv":1714.7,"id":2263603},{"trd":[[1.98,474.43]],"batb":[[2,1.92,2.19]],"batl":[[0,1.98,5.07],[2,2,5.03]],"ltp":1.98,"tv":1106.62,"id":3622149}],"tv":2821.32}]}
{"op":"mcm","clk":"1008945160","pt":1580662525649,"mc":[{"id":"1.168230754","rc":[{"trd":[[1.99,78.66],[2,2924.71],[2.02,402.88]],"batb":[[0,1.98,17.73],[1,1.97,409.09],[2,1.96,420.1]],"batl":[[0,2,3499.54],[1,2.04,2.13],[2,2.06,917.22]],"ltp":2.0,"tv":4586.82,"id":2263603},{"trd":[[1.98,479.5],[1.99,151.26],[2,239.74]],"batb":[[0,1.98,2],[1,1.97,2],[2,1.95,21.19]],"batl":[[0,2.04,111.23],[1,2.1,50.41],[2,2.28,18.48]],"ltp":2.0,"tv":1118.83,"id":3622149}],"tv":5705.66}]}
{"op":"mcm","clk":"1008945255","pt":1580662526320,"mc":[{"id":"1.168230754","rc":[{"trd":[[2,3135.37]],"batl":[[0,2,3394.21]],"ltp":2.0,"tv":4797.48,"id":2263603}],"tv":5916.32}]}
{"op":"mcm","clk":"1008945357","pt":1580662527261,"mc":[{"id":"1.168230754","rc":[{"batl":[[1,2.04,31.35]],"ltp":2.0,"tv":4797.48,"id":2263603}]}]}
{"op":"mcm","clk":"1008945896","pt":1580662531636,"mc":[{"id":"1.168230754","rc":[{"trd":[[1.98,131.48]],"batb":[[0,1.97,409.09],[1,1.96,429.01],[2,1.95,420.1]],"batl":[[0,1.98,88.58],[1,2,3396.21],[2,2.02,2]],"ltp":1.98,"tv":4832.94,"id":2263603},{"batb":[[0,2,3],[1,1.99,2],[2,1.98,2]],"ltp":2.0,"tv":1118.83,"id":3622149}],"tv":5951.78}]}
{"op":"mcm","clk":"1008945955","pt":1580662532165,"mc":[{"id":"1.168230754","rc":[{"batb":[[2,1.98,2.26]],"ltp":2.0,"tv":1118.83,"id":3622149}]}]}
{"op":"mcm","clk":"1008946706","pt":1580662538581,"mc":[{"id":"1.168230754","rc":[{"trd":[[1.98,308.64],[2,3142.37]],"batb":[[0,2,1451.99],[1,1.98,2.26],[2,1.97,411.26]],"batl":[[0,2.04,29.22],[1,2.06,977.07],[2,2.28,18.48]],"ltp":2.0,"tv":5017.09,"id":2263603},{"trd":[[2,242.74]],"batb":[[0,1.97,23.54],[1,1.96,2],[2,1.95,2.11]],"ltp":2.0,"tv":1121.83,"id":3622149}],"tv":6138.93}]}
{"op":"mcm","clk":"1008946717","pt":1580662538698,"mc":[{"id":"1.168230754","rc":[{"batb":[[0,1.97,21.37],[1,1.95,2.11],[2,1.94,2.09]],"ltp":2.0,"tv":1121.83,"id":3622149}]}]}
{"op":"mcm","clk":"1008947153","pt":1580662542268,"mc":[{"id":"1.168230754","rc":[{"batb":[[1,1.95,32.5]],"ltp":2.0,"tv":1121.83,"id":3622149}]}]}
{"op":"mcm","clk":"1008948310","pt":1580662551296,"mc":[{"id":"1.168230754","rc":[{"batb":[[2,1.97,411.09]],"batl":[[0,2.04,91.31],[1,2.06,914.97]],"ltp":2.0,"tv":5017.09,"id":2263603}]}]}
{"op":"mcm","clk":"1008949571","pt":1580662560577,"mc":[{"id":"1.168230754","rc":[{"batl":[[0,2.04,114.17]],"ltp":2.0,"tv":1121.83,"id":3622149}]}]}
{"op":"mcm","clk":"1008958781","pt":1580662630492,"mc":[{"id":"1.168230754","rc":[{"batb":[[0,1.98,2.26],[1,1.97,411.09],[2,1.96,429.01]],"batl":[[0,2,3487.78],[1,2.04,91.31],[2,2.06,914.97]],"ltp":2.0,"tv":5017.09,"id":2263603}]}]}
{"op":"mcm","clk":"1008958874","pt":1580662631206,"mc":[{"id":"1.168230754","rc":[{"batb":[[0,1.97,409.09],[1,1.96,429.01],[2,1.95,422.1]],"ltp":2.0,"tv":5017.09,"id":2263603},{"batb":[[0,1.98,2.26],[1,1.97,23.37],[2,1.95,30.39]],"ltp":2.0,"tv":1121.83,"id":3622149}]}]}
{"op":"mcm","clk":"1008960372","pt":1580662643403,"mc":[{"id":"1.168230754","rc":[{"batl":[[1,2.04,62.09]],"ltp":2.0,"tv":5017.09,"id":2263603},{"batb":[[2,1.88,430.24]],"ltp":2.0,"tv":1121.83,"id":3622149}]}]}
{"op":"mcm","clk":"1008964461","pt":1580662677644,"mc":[{"id":"1.168230754","rc":[{"trd":[[2,3147.41]],"batl":[[0,2,3482.74]],"ltp":2.0,"tv":5022.13,"id":2263603},{"trd":[[2,247.78]],"ltp":2.0,"tv":1126.87,"id":3622149}],"tv":6149.01}]}
{"op":"mcm","clk":"1008964821","pt":1580662680969,"mc":[{"id":"1.168230754","rc":[{"trd":[[2,3149.09]],"batl":[[0,2,3481.06]],"ltp":2.0,"tv":5023.81,"id":2263603},{"trd":[[2,249.46]],"ltp":2.0,"tv":1128.55,"id":3622149}],"tv":6152.37}]}
{"op":"mcm","clk":"1008966285","pt":1580662692569,"mc":[{"id":"1.168230754","rc":[{"batb":[[0,1.97,405.29]],"ltp":2.0,"tv":5023.81,"id":2263603}]}]}
{"op":"mcm","clk":"1008971979","pt":1580662735438,"mc":[{"id":"1.168230754","rc":[{"trd":[[2,3249.09]],"batl":[[0,2,3381.06]],"ltp":2.0,"tv":5123.82,"id":2263603},{"trd":[[2,349.46]],"ltp":2.0,"tv":1228.55,"id":3622149}],"tv":6352.38}]}
{"op":"mcm","clk":"1008973182","pt":1580662744620,"mc":[{"id":"1.168230754","rc":[{"batb":[[0,2,1558.72],[1,1.98,2],[2,1.97,407.46]],"batl":[[0,2.04,62.09],[1,2.06,914.97],[2,2.28,18.48]],"ltp":2.0,"tv":5123.82,"id":2263603},{"batb":[[0,1.97,21.37],[1,1.96,2],[2,1.95,2.11]],"ltp":2.0,"tv":1228.55,"id":3622149}]}]}
{"op":"mcm","clk":"1008973286","pt":1580662745560,"mc":[{"id":"1.168230754","rc":[{"batb":[[1,1.98,32.39]],"batl":[[0,2.04,85.5]],"ltp":2.0,"tv":5123.82,"id":2263603},{"batb":[[1,1.95,32.5],[2,1.94,2.09]],"batl":[[0,2.02,15.04],[1,2.04,114.17],[2,2.1,50.41]],"ltp":2.0,"tv":1228.55,"id":3622149}]}]}
{"op":"mcm","clk":"1008977214","pt":1580662779608,"mc":[{"id":"1.168230754","rc":[{"trd":[[2,3265.83]],"batb":[[0,2,1550.35],[2,1.97,405.29]],"ltp":2.0,"tv":5140.55,"id":2263603},{"batb":[[2,1.88,430.24]],"ltp":2.0,"tv":1228.55,"id":3622149}],"tv":6369.11}]}
{"op":"mcm","clk":"1008977277","pt":1580662780060,"mc":[{"id":"1.168230754","rc":[{"batb":[[1,1.98,40.92],[2,1.97,407.46]],"ltp":2.0,"tv":5140.55,"id":2263603},{"batb":[[0,1.97,12.96],[2,1.94,2.09]],"ltp":2.0,"tv":1228.55,"id":3622149}]}]}
{"op":"mcm","clk":"1008979096","pt":1580662795213,"mc":[{"id":"1.168230754","rc":[{"batb":[[1,1.98,10.53]],"ltp":2.0,"tv":5140.55,"id":2263603},{"batl":[[0,2.04,114.17],[1,2.1,50.41],[2,2.28,18.48]],"ltp":2.0,"tv":1228.55,"id":3622149}]}]}
{"op":"mcm","clk":"1008980224","pt":1580662803615,"mc":[{"id":"1.168230754","rc":[{"batl":[[0,2.02,62.09],[1,2.04,23.41],[2,2.06,917.06]],"ltp":2.0,"tv":5140.55,"id":2263603},{"batb":[[0,1.97,18.11],[1,1.96,2],[2,1.95,32.5]],"ltp":2.0,"tv":1228.55,"id":3622149}]}]}
{"op":"mcm","clk":"1008984321","pt":1580662836355,"mc":[{"id":"1.168230754","rc":[{"batb":[[2,1.97,407.29]],"ltp":2.0,"tv":5140.55,"id":2263603}]}]}
{"op":"mcm","clk":"1008986801","pt":1580662854554,"mc":[{"id":"1.168230754","rc":[{"batb":[[2,1.97,405.29]],"batl":[[0,2.02,2038]],"ltp":2.0,"tv":5140.55,"id":2263603},{"batb":[[2,1.95,30.39]],"ltp":2.0,"tv":1228.55,"id":3622149}]}]}
{"op":"mcm","clk":"1008986825","pt":1580662854765,"mc":[{"id":"1.168230754","rc":[{"batb":[[2,1.97,407.46]],"ltp":2.0,"tv":5140.55,"id":2263603},{"batb":[[2,1.95,32.5]],"ltp":2.0,"tv":1228.55,"id":3622149}]}]}
{"op":"mcm","clk":"1008987675","pt":1580662861178,"mc":[{"id":"1.168230754","rc":[{"batl":[[1,2.06,917.06],[2,2.08,2]],"ltp":2.0,"tv":5140.55,"id":2263603},{"batb":[[2,1.95,2.11]],"ltp":2.0,"tv":1228.55,"id":3622149}]}]}
{"op":"mcm","clk":"1008989601","pt":1580662875394,"mc":[{"id":"1.168230754","rc":[{"batb":[[0,1.98,8.53],[1,1.97,405.29],[2,1.96,422.1]],"batl":[[0,2,3389.43],[1,2.02,2038],[2,2.04,2]],"ltp":2.0,"tv":5140.55,"id":2263603},{"batb":[[0,1.98,2],[1,1.97,20.11],[2,1.92,27.4]],"ltp":2.0,"tv":1228.55,"id":3622149}]}]}
{"op":"mcm","clk":"1008989649","pt":1580662875706,"mc":[{"id":"1.168230754","rc":[{"batb":[[2,1.94,26.81]],"ltp":2.0,"tv":1228.55,"id":3622149}]}]}
{"op":"mcm","clk":"1008991868","pt":1580662891131,"mc":[{"id":"1.168230754","rc":[{"trd":[[2.04,78]],"batl":[[0,2.04,75.16]],"ltp":2.04,"tv":1306.56,"id":3622149}],"tv":6447.11}]}
{"op":"mcm","clk":"1008992026","pt":1580662891922,"mc":[{"id":"1.168230754","rc":[{"batb":[[1,1.97,20.28]],"ltp":2.04,"tv":1306.56,"id":3622149}]}]}
{"op":"mcm","clk":"1008992777","pt":1580662897548,"mc":[{"id":"1.168230754","rc":[{"batl":[[1,2.02,62.09]],"ltp":2.0,"tv":5140.55,"id":2263603}]}]}
{"op":"mcm","clk":"1008996848","pt":1580662923571,"mc":[{"id":"1.168230754","rc":[{"batb":[[0,1.98,17.06]],"ltp":2.0,"tv":5140.55,"id":2263603},{"batb":[[1,1.97,7.15],[2,1.95,43.98]],"ltp":2.04,"tv":1306.56,"id":3622149}]}]}
{"op":"mcm","clk":"1009000787","pt":1580662950201,"mc":[{"id":"1.168230754","rc":[{"batb":[[0,2,1550.35],[1,1.98,19.06],[2,1.97,407.29]],"batl":[[0,2.02,62.09],[1,2.06,917.06],[2,2.08,2.19]],"ltp":2.0,"tv":5140.55,"id":2263603},{"batb":[[0,1.97,5.15],[1,1.96,2.13],[2,1.95,46.09]],"ltp":2.04,"tv":1306.56,"id":3622149}]}]}
{"op":"mcm","clk":"1009001300","pt":1580662953324,"mc":[{"id":"1.168230754","rc":[{"batb":[[1,1.98,49.45]],"batl":[[1,2.04,22.35],[2,2.06,917.06]],"ltp":2.0,"tv":5140.55,"id":2263603},{"batb":[[2,1.95,76.48]],"batl":[[0,2.02,15.04],[1,2.04,75.16],[2,2.1,50.41]],"ltp":2.04,"tv":1306.56,"id":3622149}]}]}
{"op":"mcm","clk":"1009002112","pt":1580662958204,"mc":[{"id":"1.168230754","rc":[{"batb":[[2,1.97,407.46]],"batl":[[0,2.02,2038]],"ltp":2.0,"tv":5140.55,"id":2263603}]}]}
{"op":"mcm","clk":"1009002874","pt":1580662962911,"mc":[{"id":"1.168230754","rc":[{"batl":[[0,2.04,75.16],[1,2.1,50.41],[2,2.28,18.48]],"ltp":2.04,"tv":1306.56,"id":3622149}]}]}
{"op":"mcm","clk":"1009004784","pt":1580662975317,"mc":[{"id":"1.168230754","rc":[{"batb":[[2,1.97,407.29]],"batl":[[1,2.06,917.06],[2,2.08,2.19]],"ltp":2.0,"tv":5140.55,"id":2263603}]}]}
{"op":"mcm","clk":"1009008548","pt":1580662998635,"mc":[{"id":"1.168230754","rc":[{"trd":[[2.02,2474.09]],"batb":[[2,1.97,405.29]],"batl":[[0,2.02,34],[2,2.28,18.48]],"ltp":2.02,"tv":7211.77,"id":2263603},{"trd":[[1.98,2455.41]],"batb":[[2,1.95,74.37]],"ltp":1.98,"tv":3282.47,"id":3622149}],"tv":10494.24}]}
{"op":"mcm","clk":"1009008560","pt":1580662998744,"mc":[{"id":"1.168230754","rc":[{"batb":[[1,1.98,19.06],[2,1.97,407.29]],"batl":[[2,2.08,2.19]],"ltp":2.02,"tv":7211.77,"id":2263603},{"batb":[[2,1.95,76.48]],"ltp":1.98,"tv":3282.47,"id":3622149}]}]}
{"op":"mcm","clk":"1009009941","pt":1580663007584,"mc":[{"id":"1.168230754","rc":[{"batb":[[0,1.98,19.06],[1,1.97,407.29],[2,1.96,420.1]],"batl":[[0,2.06,917.06],[1,2.08,2.19],[2,2.28,18.48]],"ltp":2.02,"tv":7211.77,"id":2263603}]}]}
{"op":"mcm","clk":"1009010111","pt":1580663008278,"mc":[{"id":"1.168230754","rc":[{"batb":[[0,1.98,17.06],[1,1.97,405.29],[2,1.96,422.23]],"batl":[[0,2.06,914.97],[2,2.1,2.05]],"ltp":2.02,"tv":7211.77,"id":2263603},{"batb":[[1,1.95,76.48],[2,1.94,2]],"ltp":1.98,"tv":3282.47,"id":3622149}]}]}
{"op":"mcm","clk":"1009010368","pt":1580663009760,"mc":[{"id":"1.168230754","rc":[{"batb":[[0,1.98,36.25]],"ltp":2.02,"tv":7211.77,"id":2263603},{"batb":[[1,1.95,61.67]],"ltp":1.98,"tv":3282.47,"id":3622149}]}]}
{"op":"mcm","clk":"1009014509","pt":1580663033476,"mc":[{"id":"1.168230754","rc":[{"batb":[[0,2,1555.86],[1,1.98,36.25],[2,1.97,405.29]],"ltp":2.02,"tv":7211.77,"id":2263603}]}]}
{"op":"mcm","clk":"1009014620","pt":1580663034118,"mc":[{"id":"1.168230754","rc":[{"batb":[[1,1.98,38.25],[2,1.97,407.46]],"ltp":2.02,"tv":7211.77,"id":2263603},{"batb":[[2,1.94,2.09]],"ltp":1.98,"tv":3282.47,"id":3622149}]}]}
{"op":"mcm","clk":"1009015853","pt":1580663041291,"mc":[{"id":"1.168230754","rc":[{"batl":[[0,1.99,15.27],[1,2.04,75.16],[2,2.1,50.41]],"ltp":1.98,"tv":3282.47,"id":3622149}]}]}
{"op":"mcm","clk":"1009017970","pt":1580663053252,"mc":[{"id":"1.168230754","rc":[{"batl":[[1,2,70.22],[2,2.04,4.94]],"ltp":1.98,"tv":3282.47,"id":3622149}]}]}
{"op":"mcm","clk":"1009018119","pt":1580663054159,"mc":[{"id":"1.168230754","rc":[{"trd":[[1.99,178.44]],"batl":[[0,1.99,1.69]],"ltp":1.99,"tv":3309.65,"id":3622149}],"tv":10521.43}]}
{"op":"mcm","clk":"1009018837","pt":1580663058251,"mc":[{"id":"1.168230754","rc":[{"trd":[[1.99,181.8]],"batb":[[1,1.95,59.97]],"batl":[[0,2,70.23],[1,2.04,4.94],[2,2.1,50.41]],"ltp":1.99,"tv":3313.01,"id":3622149}],"tv":10524.78}]}
{"op":"mcm","clk":"1009019225","pt":1580663060461,"mc":[{"id":"1.168230754","rc":[{"batb":[[1,1.98,19.06]],"ltp":2.02,"tv":7211.77,"id":2263603}]}]}
{"op":"mcm","clk":"1009022891","pt":1580663080572,"mc":[{"id":"1.168230754","rc":[{"trd":[[2.02,2535.75]],"batb":[[2,1.97,405.29]],"batl":[[0,2.02,56.93],[1,2.06,917.22],[2,2.08,2.19]],"ltp":2.02,"tv":7273.43,"id":2263603},{"batb":[[2,1.9,28]],"ltp":1.99,"tv":3313.01,"id":3622149}],"tv":10586.44}]}
{"op":"mcm","clk":"1009022998","pt":1580663081162,"mc":[{"id":"1.168230754","rc":[{"trd":[[2.02,2576.93]],"batb":[[2,1.97,407.29]],"batl":[[0,2.02,15.75],[2,2.08,2]],"ltp":2.02,"tv":7314.61,"id":2263603},{"trd":[[1.98,2497.42]],"batb":[[1,1.96,2.13],[2,1.95,59.86]],"ltp":1.98,"tv":3355.02,"id":3622149}],"tv":10669.63}]}
{"op":"mcm","clk":"1009023146","pt":1580663081961,"mc":[{"id":"1.168230754","rc":[{"batl":[[0,2,70.22]],"ltp":1.98,"tv":3355.02,"id":3622149}]}]}
{"op":"mcm","clk":"1009024866","pt":1580663091507,"mc":[{"id":"1.168230754","rc":[{"trd":[[2.02,2608.44]],"batb":[[0,2.02,4.01],[1,2,1555.86],[2,1.99,2]],"batl":[[0,2.06,914.97],[1,2.08,2],[2,2.1,2]],"ltp":2.02,"tv":7346.12,"id":2263603},{"batb":[[1,1.95,59.97],[2,1.94,2.09]],"ltp":1.98,"tv":3355.02,"id":3622149}],"tv":10701.14}]}
{"op":"mcm","clk":"1009027007","pt":1580663103384,"mc":[{"id":"1.168230754","rc":[{"trd":[[2.02,2615.7]],"batb":[[0,2,1556.24],[1,1.98,19.32],[2,1.97,407.46]],"batl":[[2,2.1,2.05]],"ltp":2.02,"tv":7353.38,"id":2263603},{"batb":[[0,1.97,9.65]],"batl":[[0,1.99,3],[1,2,70.22],[2,2.04,4.94]],"ltp":1.98,"tv":3355.02,"id":3622149}],"tv":10708.4}]}
{"op":"mcm","clk":"1009031795","pt":1580663130439,"mc":[{"id":"1.168230754","rc":[{"batb":[[2,1.94,2]],"batl":[[0,1.99,3.01]],"ltp":1.98,"tv":3355.02,"id":3622149}]}]}
{"op":"mcm","clk":"1009031921","pt":1580663131212,"mc":[{"id":"1.168230754","rc":[{"trd":[[1.99,187.24]],"batl":[[0,2,70.51],[1,2.04,4.94],[2,2.1,50.41]],"ltp":1.99,"tv":3360.46,"id":3622149}],"tv":10713.84}]}
{"op":"mcm","clk":"1009046132","pt":1580663210461,"mc":[{"id":"1.168230754","rc":[{"trd":[[2,4417.28],[2.02,2616.45]],"batb":[[0,2,980.14]],"batl":[[2,2.1,2]],"ltp":2.0,"tv":8505.58,"id":2263603},{"batb":[[2,1.94,2.09]],"ltp":1.99,"tv":3360.46,"id":3622149}],"tv":11866.04}]}
{"op":"mcm","clk":"1009048371","pt":1580663222450,"mc":[{"id":"1.168230754","rc":[{"batb":[[2,1.97,405.29]],"batl":[[2,2.28,18.48]],"ltp":2.0,"tv":8505.58,"id":2263603},{"batb":[[1,1.96,15.59],[2,1.95,44.39]],"ltp":1.99,"tv":3360.46,"id":3622149}]}]}
{"op":"mcm","clk":"1009048412","pt":1580663222675,"mc":[{"id":"1.168230754","rc":[{"batb":[[2,1.97,407.29]],"batl":[[2,2.1,2.05]],"ltp":2.0,"tv":8505.58,"id":2263603}]}]}
{"op":"mcm","clk":"1009051829","pt":1580663241503,"mc":[{"id":"1.168230754","rc":[{"batb":[[2,1.97,405.29]],"batl":[[2,2.28,18.48]],"ltp":2.0,"tv":8505.58,"id":2263603},{"batb":[[1,1.96,15.49]],"ltp":1.99,"tv":3360.46,"id":3622149}]}]}
{"op":"mcm","clk":"1009051878","pt":1580663241711,"mc":[{"id":"1.168230754","rc":[{"batb":[[2,1.97,407.46]],"batl":[[2,2.1,2.05]],"ltp":2.0,"tv":8505.58,"id":2263603}]}]}
{"op":"mcm","clk":"1009055020","pt":1580663259633,"mc":[{"id":"1.168230754","rc":[{"batb":[[2,1.97,407.29]],"batl":[[2,2.1,2]],"ltp":2.0,"tv":8505.58,"id":2263603},{"trd":[[1.97,22.68]],"batb":[[0,1.97,7.04],[2,1.95,47.02]],"ltp":1.97,"tv":3365.68,"id":3622149}],"tv":11871.26}]}
{"op":"mcm","clk":"1009055222","pt":1580663260697,"mc":[{"id":"1.168230754","rc":[{"trd":[[2,4501.3]],"batb":[[0,2,938.13]],"ltp":2.0,"tv":8589.6,"id":2263603}],"tv":11955.28}]}
{"op":"mcm","clk":"1009062623","pt":1580663300432,"mc":[{"id":"1.168230754","rc":[{"batb":[[0,1.98,19.06],[1,1.97,407.29],[2,1.96,422.23]],"batl":[[2,2.1,2.05]],"ltp":2.0,"tv":8589.6,"id":2263603}]}]}
{"op":"mcm","clk":"1009064796","pt":1580663313583,"mc":[{"id":"1.168230754","rc":[{"batb":[[0,2,918.36],[1,1.98,19.06],[2,1.97,407.29]],"ltp":2.0,"tv":8589.6,"id":2263603}]}]}
{"op":"mcm","clk":"1009067898","pt":1580663332408,"mc":[{"id":"1.168230754","rc":[{"trd":[[1.97,24.44]],"batb":[[0,1.97,6.16]],"ltp":1.97,"tv":3367.43,"id":3622149}],"tv":11957.04}]}
{"op":"mcm","clk":"1009067974","pt":1580663332974,"mc":[{"id":"1.168230754","rc":[{"batb":[[2,1.97,407.46]],"ltp":2.0,"tv":8589.6,"id":2263603}]}]}
{"op":"mcm","clk":"1009071740","pt":1580663355616,"mc":[{"id":"1.168230754","rc":[{"trd":[[2,4571.82]],"batb":[[0,1.98,17.06],[1,1.97,405.29],[2,1.96,422.23]],"batl":[[0,2,914.61],[1,2.04,2.13],[2,2.06,917.06]],"ltp":2.0,"tv":8660.12,"id":2263603},{"trd":[[1.99,187.53],[2,419.69]],"batb":[[0,1.98,2],[1,1.97,8.33],[2,1.96,15.49]],"batl":[[0,2.04,4.94],[1,2.1,50.41],[2,2.28,18.48]],"ltp":2.0,"tv":3437.95,"id":3622149}],"tv":12098.07}]}
{"op":"mcm","clk":"1009072153","pt":1580663358233,"mc":[{"id":"1.168230754","rc":[{"batl":[[1,2.04,31.35]],"ltp":2.0,"tv":8660.12,"id":2263603}]}]}
{"op":"mcm","clk":"1009073644","pt":1580663367365,"mc":[{"id":"1.168230754","rc":[{"batb":[[0,2,15.49],[1,1.98,2],[2,1.97,8.33]],"ltp":2.0,"tv":3437.95,"id":3622149}]}]}
{"op":"mcm","clk":"1009076619","pt":1580663385578,"mc":[{"id":"1.168230754","rc":[{"batl":[[2,2.06,914.97]],"ltp":2.0,"tv":8660.12,"id":2263603},{"batb":[[0,2,15.2],[2,1.97,6.16]],"ltp":2.0,"tv":3437.95,"id":3622149}]}]}
{"op":"mcm","clk":"1009076650","pt":1580663385790,"mc":[{"id":"1.168230754","rc":[{"batl":[[2,2.06,917.06]],"ltp":2.0,"tv":8660.12,"id":2263603},{"batb":[[2,1.97,8.33]],"ltp":2.0,"tv":3437.95,"id":3622149}]}]}
{"op":"mcm","clk":"1009076860","pt":1580663387106,"mc":[{"id":"1.168230754","rc":[{"batl":[[0,2,2820.92]],"ltp":2.0,"tv":8660.12,"id":2263603}]}]}
{"op":"mcm","clk":"1009079437","pt":1580663403347,"mc":[{"id":"1.168230754","rc":[{"batl":[[1,2.04,2.13]],"ltp":2.0,"tv":8660.12,"id":2263603}]}]}
{"op":"mcm","clk":"1009082985","pt":1580663424636,"mc":[{"id":"1.168230754","rc":[{"trd":[[2,4576.28]],"batl":[[0,2,2818.69],[2,2.06,917.22]],"ltp":2.0,"tv":8664.58,"id":2263603}],"tv":12102.53}]}
{"op":"mcm","clk":"1009083651","pt":1580663429140,"mc":[{"id":"1.168230754","rc":[{"trd":[[2,4586.28]],"batl":[[0,2,2813.69]],"ltp":2.0,"tv":8674.58,"id":2263603}],"tv":12112.53}]}
{"op":"mcm","clk":"1009089650","pt":1580663467119,"mc":[{"id":"1.168230754","rc":[{"trd":[[1.98,310.87]],"batb":[[0,1.98,15.94]],"batl":[[2,2.06,914.97]],"ltp":1.98,"tv":8676.81,"id":2263603},{"batb":[[2,1.97,6.16]],"ltp":2.0,"tv":3437.95,"id":3622149}],"tv":12114.77}]}
{"op":"mcm","clk":"1009089920","pt":1580663469127,"mc":[{"id":"1.168230754","rc":[{"batb":[[0,1.98,17.63]],"batl":[[2,2.06,916.97]],"ltp":1.98,"tv":8676.81,"id":2263603},{"batb":[[2,1.97,8.16]],"ltp":2.0,"tv":3437.95,"id":3622149}]}]}
{"op":"mcm","clk":"1009094256","pt":1580663497638,"mc":[{"id":"1.168230754","rc":[{"trd":[[1.98,312.45]],"batb":[[0,1.97,430.91],[1,1.96,422.23],[2,1.95,422.1]],"ltp":1.98,"tv":8678.39,"id":2263603}],"tv":12116.35}]}
{"op":"mcm","clk":"1009094270","pt":1580663497742,"mc":[{"id":"1.168230754","rc":[{"batb":[[1,1.96,420.1]],"ltp":1.98,"tv":8678.39,"id":2263603}]}]}
{"op":"mcm","clk":"1009114083","pt":1580663614411,"mc":[{"id":"1.168230754","rc":[{"batl":[[0,1.99,27.06],[1,2,2813.69],[2,2.02,2]],"ltp":1.98,"tv":8678.39,"id":2263603},{"trd":[[2,422.49]],"batb":[[0,2,40.73]],"batl":[[0,2.04,31.34]],"ltp":2.0,"tv":3440.75,"id":3622149}],"tv":12119.14}]}
{"op":"mcm","clk":"1009115235","pt":1580663621478,"mc":[{"id":"1.168230754","rc":[{"batb":[[0,2,39.33]],"ltp":2.0,"tv":3440.75,"id":3622149}]}]}
{"op":"mcm","clk":"1009115309","pt":1580663622008,"mc":[{"id":"1.168230754","rc":[{"batb":[[2,1.97,8.33]],"ltp":2.0,"tv":3440.75,"id":3622149}]}]}
{"op":"mcm","clk":"1009117580","pt":1580663635523,"mc":[{"id":"1.168230754","rc":[{"batb":[[0,2,40.73]],"ltp":2.0,"tv":3440.75,"id":3622149}]}]}
{"op":"mcm","clk":"1009123220","pt":1580663669574,"mc":[{"id":"1.168230754","rc":[{"batb":[[0,1.99,26.73],[1,1.97,8.16],[2,1.96,2.13]],"ltp":2.0,"tv":3440.75,"id":3622149}]}]}
{"op":"mcm","clk":"1009123280","pt":1580663669947,"mc":[{"id":"1.168230754","rc":[{"batb":[[0,1.99,26.72],[1,1.98,28.86],[2,1.97,8.16]],"ltp":2.0,"tv":3440.75,"id":3622149}]}]}
{"op":"mcm","clk":"1009124974","pt":1580663680592,"mc":[{"id":"1.168230754","rc":[{"batb":[[0,2.02,13.66],[1,1.99,26.72],[2,1.98,28.86]],"ltp":2.0,"tv":3440.75,"id":3622149}]}]}
{"op":"mcm","clk":"1009125169","pt":1580663681553,"mc":[{"id":"1.168230754","rc":[{"trd":[[2.02,112.03]],"batb":[[0,1.99,26.72],[1,1.98,28.86],[2,1.97,8.33]],"ltp":2.02,"tv":3468.08,"id":3622149}],"tv":12146.47}]}
{"op":"mcm","clk":"1009125242","pt":1580663682084,"mc":[{"id":"1.168230754","rc":[{"batb":[[0,1.99,26.71],[1,1.98,29.12]],"ltp":2.02,"tv":3468.08,"id":3622149}]}]}
{"op":"mcm","clk":"1009129745","pt":1580663707968,"mc":[{"id":"1.168230754","rc":[{"trd":[[1.99,105.72],[2,4759.37]],"batl":[[0,2,2640.61],[1,2.04,2],[2,2.06,916.97]],"ltp":2.0,"tv":8878.54,"id":2263603},{"trd":[[2,622.49]],"batb":[[0,1.98,2.26],[1,1.97,8.33],[2,1.95,46.83]],"ltp":2.0,"tv":3668.08,"id":3622149}],"tv":12546.62}]}
{"op":"mcm","clk":"1009136217","pt":1580663746420,"mc":[{"id":"1.168230754","rc":[{"batl":[[0,2,2640.91]],"ltp":2.0,"tv":8878.54,"id":2263603}]}]}
{"op":"mcm","clk":"1009136292","pt":1580663746948,"mc":[{"id":"1.168230754","rc":[{"batl":[[2,2.06,917.22]],"ltp":2.0,"tv":8878.54,"id":2263603}]}]}
{"op":"mcm","clk":"1009138296","pt":1580663758417,"mc":[{"id":"1.168230754","rc":[{"batl":[[2,2.06,917.06]],"ltp":2.0,"tv":8878.54,"id":2263603},{"batb":[[1,1.97,8.16]],"ltp":2.0,"tv":3668.08,"id":3622149}]}]}
{"op":"mcm","clk":"1009145119","pt":1580663798547,"mc":[{"id":"1.168230754","rc":[{"trd":[[1.97,41.25]],"batb":[[0,1.97,430.5]],"batl":[[2,2.06,914.97]],"ltp":1.97,"tv":8879.36,"id":2263603},{"batb":[[1,1.97,6.16]],"ltp":2.0,"tv":3668.08,"id":3622149}],"tv":12547.44}]}
{"op":"mcm","clk":"1009145151","pt":1580663798714,"mc":[{"id":"1.168230754","rc":[{"batl":[[2,2.06,917.22]],"ltp":1.97,"tv":8879.36,"id":2263603},{"batb":[[1,1.97,8.33]],"ltp":2.0,"tv":3668.08,"id":3622149}]}]}
{"op":"mcm","clk":"1009145989","pt":1580663803473,"mc":[{"id":"1.168230754","rc":[{"batl":[[0,1.99,2.5],[1,2,2640.61],[2,2.04,2]],"ltp":1.97,"tv":8879.36,"id":2263603}]}]}
{"op":"mcm","clk":"1009146092","pt":1580663804206,"mc":[{"id":"1.168230754","rc":[{"batl":[[2,2.02,2]],"ltp":1.97,"tv":8879.36,"id":2263603}]}]}
{"op":"mcm","clk":"1009159129","pt":1580663883588,"mc":[{"id":"1.168230754","rc":[{"batb":[[1,1.97,6.16]],"batl":[[0,2.04,32.15]],"ltp":2.0,"tv":3668.08,"id":3622149}]}]}
{"op":"mcm","clk":"1009159161","pt":1580663883806,"mc":[{"id":"1.168230754","rc":[{"batb":[[1,1.97,8.33]],"ltp":2.0,"tv":3668.08,"id":3622149}]}]}
{"op":"mcm","clk":"1009177209","pt":1580663996429,"mc":[{"id":"1.168230754","rc":[{"batb":[[0,1.97,434.84],[1,1.96,424.46]],"batl":[[0,1.99,6.81],[1,2,2644.88]],"ltp":1.97,"tv":8879.36,"id":2263603},{"batb":[[0,1.98,6.58],[1,1.97,12.67]],"batl":[[0,2.04,36.34],[1,2.06,4.15],[2,2.1,50.41]],"ltp":2.0,"tv":3668.08,"id":3622149}]}]}
{"op":"mcm","clk":"1009177318","pt":1580663997060,"mc":[{"id":"1.168230754","rc":[{"batb":[[1,1.97,12.5]],"ltp":2.0,"tv":3668.08,"id":3622149}]}]}
{"op":"mcm","clk":"1009178521","pt":1580664004647,"mc":[{"id":"1.168230754","rc":[{"trd":[[1.98,320.57]],"batb":[[1,1.96,426.46]],"ltp":1.98,"tv":8887.48,"id":2263603},{"trd":[[2.02,120.84]],"batb":[[0,2.02,7.54],[1,1.99,2],[2,1.98,6.58]],"batl":[[0,2.04,35.53]],"ltp":2.02,"tv":3676.88,"id":3622149}],"tv":12564.36}]}
{"op":"mcm","clk":"1009178628","pt":1580664005331,"mc":[{"id":"1.168230754","rc":[{"batb":[[1,1.96,424.46]],"ltp":1.98,"tv":8887.48,"id":2263603},{"batb":[[0,1.98,6.32],[1,1.97,12.67],[2,1.95,46.83]],"ltp":2.02,"tv":3676.88,"id":3622149}]}]}
{"op":"mcm","clk":"1009178688","pt":1580664005749,"mc":[{"id":"1.168230754","rc":[{"batb":[[0,1.99,4.3],[1,1.98,6.32],[2,1.97,12.67]],"ltp":2.02,"tv":3676.88,"id":3622149}]}]}
{"op":"mcm","clk":"1009184498","pt":1580664046300,"mc":[{"id":"1.168230754","rc":[{"trd":[[1.99,106]],"batl":[[0,1.99,6.52]],"ltp":1.99,"tv":8887.76,"id":2263603},{"trd":[[2,622.77]],"ltp":2.0,"tv":3677.17,"id":3622149}],"tv":12564.94}]}
{"op":"mcm","clk":"1009189915","pt":1580664083538,"mc":[{"id":"1.168230754","rc":[{"batb":[[0,1.97,435.15]],"ltp":1.99,"tv":8887.76,"id":2263603}]}]}
{"op":"mcm","clk":"1009192836","pt":1580664103573,"mc":[{"id":"1.168230754","rc":[{"batb":[[0,1.97,434.84]],"ltp":1.99,"tv":8887.76,"id":2263603}]}]}
{"op":"mcm","clk":"1009196580","pt":1580664128272,"mc":[{"id":"1.168230754","rc":[{"trd":[[1.97,474.39]],"batb":[[0,1.97,218.27]],"ltp":1.97,"tv":9320.91,"id":2263603}],"tv":12998.08}]}
{"op":"mcm","clk":"1009204734","pt":1580664180589,"mc":[{"id":"1.168230754","rc":[{"batl":[[0,2.04,52.34]],"ltp":2.0,"tv":3677.17,"id":3622149}]}]}
{"op":"mcm","clk":"1009205187","pt":1580664183568,"mc":[{"id":"1.168230754","rc":[{"batl":[[0,2.02,16.8],[1,2.04,35.53],[2,2.06,4.15]],"ltp":2.0,"tv":3677.17,"id":3622149}]}]}
{"op":"mcm","clk":"1009205347","pt":1580664184471,"mc":[{"id":"1.168230754","rc":[{"trd":[[1.98,333.17]],"batl":[[0,1.99,36.91]],"ltp":1.98,"tv":9333.51,"id":2263603},{"trd":[[2.02,142.09]],"batl":[[0,2.04,35.53],[1,2.06,4.15],[2,2.1,50.41]],"ltp":2.02,"tv":3698.42,"id":3622149}],"tv":13031.94}]}
{"op":"mcm","clk":"1009206427","pt":1580664191481,"mc":[{"id":"1.168230754","rc":[{"batl":[[0,1.99,6.52]],"ltp":1.98,"tv":9333.51,"id":2263603},{"batb":[[2,1.97,10.5]],"ltp":2.02,"tv":3698.42,"id":3622149}]}]}
{"op":"mcm","clk":"1009206455","pt":1580664191694,"mc":[{"id":"1.168230754","rc":[{"batb":[[2,1.97,12.5]],"ltp":2.02,"tv":3698.42,"id":3622149}]}]}
{"op":"mcm","clk":"1009213944","pt":1580664240576,"mc":[{"id":"1.168230754","rc":[{"trd":[[1.99,110.34]],"batl":[[0,1.99,2.13]],"ltp":1.99,"tv":9337.85,"id":2263603},{"batb":[[2,1.97,10.5]],"ltp":2.02,"tv":3698.42,"id":3622149}],"tv":13036.28}]}
{"op":"mcm","clk":"1009213980","pt":1580664240780,"mc":[{"id":"1.168230754","rc":[{"batb":[[2,1.97,12.5]],"ltp":2.02,"tv":3698.42,"id":3622149}]}]}
{"op":"mcm","clk":"1009214226","pt":1580664242268,"mc":[{"id":"1.168230754","rc":[{"trd":[[1.99,112.48],[2,4798.25]],"batl":[[0,1.99,4.34],[1,2,2606]],"ltp":2.0,"tv":9378.87,"id":2263603},{"trd":[[2,663.77]],"ltp":2.0,"tv":3739.42,"id":3622149}],"tv":13118.29}]}
{"op":"mcm","clk":"1009215036","pt":1580664247168,"mc":[{"id":"1.168230754","rc":[{"batb":[[0,1.97,218.58]],"ltp":2.0,"tv":9378.87,"id":2263603}]}]}
{"op":"mcm","clk":"1009226022","pt":1580664315561,"mc":[{"id":"1.168230754","rc":[{"trd":[[1.99,112.72]],"batl":[[0,1.99,4.1]],"ltp":1.99,"tv":9379.11,"id":2263603},{"trd":[[2,664.01]],"ltp":2.0,"tv":3739.66,"id":3622149}],"tv":13118.78}]}
{"op":"mcm","clk":"1009228515","pt":1580664332583,"mc":[{"id":"1.168230754","rc":[{"batb":[[0,1.97,30.27]],"ltp":1.99,"tv":9379.11,"id":2263603},{"batb":[[2,1.97,10.5]],"ltp":2.0,"tv":3739.66,"id":3622149}]}]}
{"op":"mcm","clk":"1009228541","pt":1580664332788,"mc":[{"id":"1.168230754","rc":[{"batb":[[2,1.97,12.5]],"ltp":2.0,"tv":3739.66,"id":3622149}]}]}
{"op":"mcm","clk":"1009237081","pt":1580664393590,"mc":[{"id":"1.168230754","rc":[{"trd":[[1.97,524.44],[1.98,333.79]],"batb":[[0,1.97,4.94]],"ltp":1.97,"tv":9429.77,"id":2263603}],"tv":13169.44}]}
{"op":"mcm","clk":"1009237121","pt":1580664393867,"mc":[{"id":"1.168230754","rc":[{"batb":[[0,1.97,4.34],[2,1.95,440.7]],"ltp":1.97,"tv":9429.77,"id":2263603},{"batb":[[1,1.98,48.36]],"ltp":2.0,"tv":3739.66,"id":3622149}]}]}
{"op":"mcm","clk":"1009241048","pt":1580664421621,"mc":[{"id":"1.168230754","rc":[{"batl":[[0,2.04,161.69]],"ltp":2.0,"tv":3739.66,"id":3622149}]}]}
{"op":"mcm","clk":"1009241088","pt":1580664421935,"mc":[{"id":"1.168230754","rc":[{"batl":[[0,1.99,4.41]],"ltp":1.97,"tv":9429.77,"id":2263603}]}]}
{"op":"mcm","clk":"1009242690","pt":1580664432955,"mc":[{"id":"1.168230754","rc":[{"batb":[[2,1.97,12.67]],"ltp":2.0,"tv":3739.66,"id":3622149}]}]}
{"op":"mcm","clk":"1009251838","pt":1580664494543,"mc":[{"id":"1.168230754","rc":[{"trd":[[1.99,113.5]],"batl":[[0,1.99,3.63]],"ltp":1.99,"tv":9430.55,"id":2263603},{"trd":[[2,664.79]],"batb":[[2,1.97,10.5]],"ltp":2.0,"tv":3740.44,"id":3622149}],"tv":13171.0}]}
{"op":"mcm","clk":"1009251889","pt":1580664494954,"mc":[{"id":"1.168230754","rc":[{"batb":[[2,1.97,12.5]],"ltp":2.0,"tv":3740.44,"id":3622149}]}]}
{"op":"mcm","clk":"1009262997","pt":1580664568445,"mc":[{"id":"1.168230754","rc":[{"batb":[[1,1.98,46.36]],"ltp":2.0,"tv":3740.44,"id":3622149}]}]}
{"op":"mcm","clk":"1009263174","pt":1580664569616,"mc":[{"id":"1.168230754","rc":[{"batb":[[2,1.95,438.7]],"ltp":1.99,"tv":9430.55,"id":2263603},{"batb":[[2,1.97,10.5]],"ltp":2.0,"tv":3740.44,"id":3622149}]}]}
{"op":"mcm","clk":"1009263293","pt":1580664570409,"mc":[{"id":"1.168230754","rc":[{"batl":[[2,2.06,914.97]],"ltp":1.99,"tv":9430.55,"id":2263603}]}]}
{"op":"mcm","clk":"1009263440","pt":1580664571315,"mc":[{"id":"1.168230754","rc":[{"batb":[[0,1.97,193.07]],"ltp":1.99,"tv":9430.55,"id":2263603}]}]}
{"op":"mcm","clk":"1009263696","pt":1580664573021,"mc":[{"id":"1.168230754","rc":[{"trd":[[1.97,525.26]],"batb":[[0,1.97,192.66]],"ltp":1.97,"tv":9431.38,"id":2263603}],"tv":13171.82}]}
{"op":"mcm","clk":"1009264207","pt":1580664576529,"mc":[{"id":"1.168230754","rc":[{"batb":[[0,1.97,209.23]],"ltp":1.97,"tv":9431.38,"id":2263603}]}]}
{"op":"mcm","clk":"1009265135","pt":1580664582635,"mc":[{"id":"1.168230754","rc":[{"batb":[[0,1.97,192.66]],"ltp":1.97,"tv":9431.38,"id":2263603}]}]}
{"op":"mcm","clk":"1009270200","pt":1580664615545,"mc":[{"id":"1.168230754","rc":[{"trd":[[1.99,117.13],[2,4844.64]],"batl":[[0,2,2559.61],[1,2.02,4.34]],"ltp":2.0,"tv":9481.4,"id":2263603},{"trd":[[2,714.79]],"ltp":2.0,"tv":3790.44,"id":3622149}],"tv":13271.84}]}
{"op":"mcm","clk":"1009270354","pt":1580664616503,"mc":[{"id":"1.168230754","rc":[{"batl":[[0,1.99,4.41],[1,2,2559.61],[2,2.02,4.34]],"ltp":2.0,"tv":9481.4,"id":2263603}]}]}
{"op":"mcm","clk":"1009271852","pt":1580664626026,"mc":[{"id":"1.168230754","rc":[{"trd":[[1.99,117.35]],"batl":[[0,1.99,4.3]],"ltp":1.99,"tv":9481.61,"id":2263603}],"tv":13272.06}]}
{"op":"mcm","clk":"1009272472","pt":1580664630208,"mc":[{"id":"1.168230754","rc":[{"trd":[[1.97,526.08]],"batb":[[0,1.97,192.25]],"ltp":1.97,"tv":9482.44,"id":2263603}],"tv":13272.88}]}
{"op":"mcm","clk":"1009274208","pt":1580664641637,"mc":[{"id":"1.168230754","rc":[{"batb":[[0,1.97,192.56]],"ltp":1.97,"tv":9482.44,"id":2263603}]}]}
{"op":"mcm","clk":"1009280685","pt":1580664682617,"mc":[{"id":"1.168230754","rc":[{"trd":[[1.99,121.65],[2,4944.27]],"batl":[[0,2,2459.97],[1,2.02,4.34],[2,2.06,914.97]],"ltp":2.0,"tv":9586.37,"id":2263603},{"trd":[[2,818.7]],"ltp":2.0,"tv":3894.35,"id":3622149}],"tv":13480.73}]}
{"op":"mcm","clk":"1009280730","pt":1580664682881,"mc":[{"id":"1.168230754","rc":[{"trd":[[2,4948.06]],"batl":[[0,2,2456.19]],"ltp":2.0,"tv":9590.16,"id":2263603},{"trd":[[2,822.48]],"ltp":2.0,"tv":3898.14,"id":3622149}],"tv":13488.3}]}
{"op":"mcm","clk":"1009281139","pt":1580664685398,"mc":[{"id":"1.168230754","rc":[{"batl":[[0,1.99,4.43],[1,2,2456.19],[2,2.02,4.34]],"ltp":2.0,"tv":9590.16,"id":2263603}]}]}
{"op":"mcm","clk":"1009282158","pt":1580664692497,"mc":[{"id":"1.168230754","rc":[{"trd":[[1.99,126.08],[2,4948.2]],"batb":[[0,1.98,4.76],[1,1.97,192.25],[2,1.96,424.46]],"batl":[[0,2,2456.05],[1,2.02,4.34],[2,2.04,2.13]],"ltp":2.0,"tv":9594.72,"id":2263603},{"trd":[[2,827.03]],"batb":[[1,1.98,48.36],[2,1.97,12.5]],"batl":[[0,2.02,4.36],[1,2.04,161.69],[2,2.06,4.15]],"ltp":2.0,"tv":3902.68,"id":3622149}],"tv":13497.41}]}
{"op":"mcm","clk":"1009282317","pt":1580664693524,"mc":[{"id":"1.168230754","rc":[{"batb":[[0,1.97,192.56],[1,1.96,424.46],[2,1.95,440.81]],"batl":[[0,1.99,4.43],[1,2,2456.05],[2,2.02,4.34]],"ltp":2.0,"tv":9594.72,"id":2263603},{"trd":[[2.02,150.38]],"batl":[[0,2.04,161.69],[1,2.06,4.15],[2,2.1,50.41]],"ltp":2.02,"tv":3910.96,"id":3622149}],"tv":13505.69}]}
{"op":"mcm","clk":"1009282341","pt":1580664693719,"mc":[{"id":"1.168230754","rc":[{"batl":[[2,2.02,6.59]],"ltp":2.0,"tv":9594.72,"id":2263603}]}]}
{"op":"mcm","clk":"1009283330","pt":1580664700623,"mc":[{"id":"1.168230754","rc":[{"batl":[[0,2,2456.05],[1,2.02,6.59],[2,2.04,2.13]],"ltp":2.0,"tv":9594.72,"id":2263603}]}]}
{"op":"mcm","clk":"1009283471","pt":1580664701625,"mc":[{"id":"1.168230754","rc":[{"batl":[[0,1.99,4.43],[1,2,2456.05],[2,2.02,6.59]],"ltp":2.0,"tv":9594.72,"id":2263603}]}]}
{"op":"mcm","clk":"1009288702","pt":1580664736643,"mc":[{"id":"1.168230754","rc":[{"trd":[[1.97,910.58],[1.98,334.4]],"batb":[[0,1.96,475.93],[1,1.95,438.7],[2,1.94,113.37]],"batl":[[0,1.97,87.7],[1,1.99,6.73],[2,2,2458.05]],"ltp":1.97,"tv":9979.84,"id":2263603},{"batb":[[0,1.99,6.3],[2,1.97,10.5]],"ltp":2.02,"tv":3910.96,"id":3622149}],"tv":13890.81}]}
{"op":"mcm","clk":"1009288824","pt":1580664737449,"mc":[{"id":"1.168230754","rc":[{"batb":[[1,1.95,443.24]],"batl":[[1,1.98,4.47],[2,1.99,37.12]],"ltp":1.97,"tv":9979.84,"id":2263603},{"trd":[[2.02,172.89]],"batb":[[0,2.02,8.17],[1,2,4.43],[2,1.99,6.3]],"ltp":2.02,"tv":3933.47,"id":3622149}],"tv":13913.32}]}
{"op":"mcm","clk":"1009291248","pt":1580664753491,"mc":[{"id":"1.168230754","rc":[{"batl":[[0,2.04,172.83]],"ltp":2.02,"tv":3933.47,"id":3622149}]}]}
{"op":"mcm","clk":"1009291313","pt":1580664753862,"mc":[{"id":"1.168230754","rc":[{"batl":[[2,1.99,37.74]],"ltp":1.97,"tv":9979.84,"id":2263603}]}]}
{"op":"mcm","clk":"1009298401","pt":1580664799312,"mc":[{"id":"1.168230754","rc":[{"batb":[[0,2.02,19.42]],"ltp":2.02,"tv":3933.47,"id":3622149}]}]}
{"op":"mcm","clk":"1009302420","pt":1580664825566,"mc":[{"id":"1.168230754","rc":[{"trd":[[2.02,205.77]],"batb":[[0,2.02,7.39]],"ltp":2.02,"tv":3966.36,"id":3622149}],"tv":13946.2}]}
{"op":"mcm","clk":"1009303118","pt":1580664829891,"mc":[{"id":"1.168230754","rc":[{"batl":[[2,1.99,21.35]],"ltp":1.97,"tv":9979.84,"id":2263603},{"batl":[[0,2.04,182.15]],"ltp":2.02,"tv":3966.36,"id":3622149}]}]}
{"op":"mcm","clk":"1009308534","pt":1580664863571,"mc":[{"id":"1.168230754","rc":[{"trd":[[1.97,921.14]],"batl":[[0,1.97,77.15],[1,1.99,21.35],[2,2,2458.05]],"ltp":1.97,"tv":9990.4,"id":2263603},{"trd":[[2.02,230.84]],"batb":[[0,2,4.43],[1,1.99,6.3],[2,1.98,48.36]],"ltp":2.02,"tv":3991.43,"id":3622149}],"tv":13981.83}]}
{"op":"mcm","clk":"1009308956","pt":1580664866285,"mc":[{"id":"1.168230754","rc":[{"batl":[[1,1.98,4.5],[2,1.99,21.35]],"ltp":1.97,"tv":9990.4,"id":2263603},{"batl":[[0,2.04,183.64]],"ltp":2.02,"tv":3991.43,"id":3622149}]}]}
{"op":"mcm","clk":"1009310708","pt":1580664877209,"mc":[{"id":"1.168230754","rc":[{"batl":[[1,1.99,21.35],[2,2,2458.05]],"ltp":1.97,"tv":9990.4,"id":2263603}]}]}
{"op":"mcm","clk":"1009311400","pt":1580664881619,"mc":[{"id":"1.168230754","rc":[{"batl":[[1,1.98,4.5],[2,1.99,21.35]],"ltp":1.97,"tv":9990.4,"id":2263603}]}]}
{"op":"mcm","clk":"1009313315","pt":1580664893447,"mc":[{"id":"1.168230754","rc":[{"batb":[[2,1.98,48.62]],"batl":[[0,2.04,182.11]],"ltp":2.02,"tv":3991.43,"id":3622149}]}]}
{"op":"mcm","clk":"1009316170","pt":1580664910422,"mc":[{"id":"1.168230754","rc":[{"batl":[[2,1.99,7.35]],"ltp":1.97,"tv":9990.4,"id":2263603},{"batl":[[0,2.04,161.69]],"ltp":2.02,"tv":3991.43,"id":3622149}]}]}
{"op":"mcm","clk":"1009316843","pt":1580664914444,"mc":[{"id":"1.168230754","rc":[{"batl":[[2,1.99,18.3]],"ltp":1.97,"tv":9990.4,"id":2263603},{"batb":[[0,2.02,12.17],[1,2,4.43],[2,1.99,6.3]],"batl":[[0,2.04,182.09]],"ltp":2.02,"tv":3991.43,"id":3622149}]}]}
{"op":"mcm","clk":"1009320679","pt":1580664937366,"mc":[{"id":"1.168230754","rc":[{"batb":[[0,2.02,15.16]],"ltp":2.02,"tv":3991.43,"id":3622149}]}]}
{"op":"mcm","clk":"1009338158","pt":1580665042384,"mc":[{"id":"1.168230754","rc":[{"trd":[[1.96,10.42]],"batb":[[0,1.96,470.72]],"ltp":1.96,"tv":10000.82,"id":2263603}],"tv":13992.25}]}
{"op":"mcm","clk":"1009342053","pt":1580665065550,"mc":[{"id":"1.168230754","rc":[{"trd":[[2.04,92]],"batl":[[0,2.04,175.09]],"ltp":2.04,"tv":4005.43,"id":3622149}],"tv":14006.25}]}
{"op":"mcm","clk":"1009346069","pt":1580665089075,"mc":[{"id":"1.168230754","rc":[{"batl":[[2,1.99,7.35]],"ltp":1.96,"tv":10000.82,"id":2263603},{"batb":[[0,2.02,4.42]],"batl":[[0,2.04,154.69]],"ltp":2.04,"tv":4005.43,"id":3622149}]}]}
{"op":"mcm","clk":"1009347147","pt":1580665095449,"mc":[{"id":"1.168230754","rc":[{"batl":[[2,1.99,18.3]],"ltp":1.96,"tv":10000.82,"id":2263603},{"batb":[[0,2.02,15.16]],"batl":[[0,2.04,175.08]],"ltp":2.04,"tv":4005.43,"id":3622149}]}]}
{"op":"mcm","clk":"1009348347","pt":1580665102508,"mc":[{"id":"1.168230754","rc":[{"batb":[[0,1.96,473.84]],"ltp":1.96,"tv":10000.82,"id":2263603}]}]}
{"op":"mcm","clk":"1009350139","pt":1580665112602,"mc":[{"id":"1.168230754","rc":[{"trd":[[2.02,231.26]],"batb":[[0,2.02,14.95]],"ltp":2.02,"tv":4005.85,"id":3622149}],"tv":14006.67}]}
{"op":"mcm","clk":"1009357554","pt":1580665154481,"mc":[{"id":"1.168230754","rc":[{"batb":[[0,1.96,474.1]],"ltp":1.96,"tv":10000.82,"id":2263603}]}]}
{"op":"mcm","clk":"1009359069","pt":1580665163576,"mc":[{"id":"1.168230754","rc":[{"trd":[[1.96,12.56]],"batb":[[0,1.96,473.03]],"ltp":1.96,"tv":10002.95,"id":2263603}],"tv":14008.81}]}
{"op":"mcm","clk":"1009365226","pt":1580665200448,"mc":[{"id":"1.168230754","rc":[{"trd":[[1.97,921.44]],"batl":[[0,1.97,76.84]],"ltp":1.97,"tv":10003.26,"id":2263603},{"trd":[[2.02,261.48]],"batb":[[0,2,4.43],[1,1.99,6.3],[2,1.98,48.36]],"ltp":2.02,"tv":4036.07,"id":3622149}],"tv":14039.34}]}
{"op":"mcm","clk":"1009365402","pt":1580665201415,"mc":[{"id":"1.168230754","rc":[{"trd":[[1.97,930.64]],"batl":[[0,1.97,72.24],[1,1.98,4.57]],"ltp":1.97,"tv":10012.46,"id":2263603}],"tv":14048.53}]}
{"op":"mcm","clk":"1009365851","pt":1580665204291,"mc":[{"id":"1.168230754","rc":[{"batl":[[2,1.99,7.35]],"ltp":1.97,"tv":10012.46,"id":2263603},{"batl":[[0,2.04,175.03]],"ltp":2.02,"tv":4036.07,"id":3622149}]}]}
{"op":"mcm","clk":"1009365963","pt":1580665204928,"mc":[{"id":"1.168230754","rc":[{"batl":[[1,1.99,7.35],[2,2,2458.05]],"ltp":1.97,"tv":10012.46,"id":2263603}]}]}
{"op":"mcm","clk":"1009368233","pt":1580665218631,"mc":[{"id":"1.168230754","rc":[{"batl":[[2,2,2456.05]],"ltp":1.97,"tv":10012.46,"id":2263603},{"batb":[[2,1.98,46.36]],"batl":[[0,2.04,176.57]],"ltp":2.02,"tv":4036.07,"id":3622149}]}]}
{"op":"mcm","clk":"1009368348","pt":1580665219319,"mc":[{"id":"1.168230754","rc":[{"batl":[[1,1.98,4.58],[2,1.99,7.35]],"ltp":1.97,"tv":10012.46,"id":2263603},{"batb":[[2,1.98,48.62]],"ltp":2.02,"tv":4036.07,"id":3622149}]}]}
{"op":"mcm","clk":"1009370795","pt":1580665233339,"mc":[{"id":"1.168230754","rc":[{"batl":[[0,2.04,175.03]],"ltp":2.02,"tv":4036.07,"id":3622149}]}]}
{"op":"mcm","clk":"1009370882","pt":1580665233875,"mc":[{"id":"1.168230754","rc":[{"batb":[[2,1.98,48.36]],"ltp":2.02,"tv":4036.07,"id":3622149}]}]}
{"op":"mcm","clk":"1009374607","pt":1580665257501,"mc":[{"id":"1.168230754","rc":[{"batl":[[0,2.04,48.87]],"ltp":2.02,"tv":4036.07,"id":3622149}]}]}
{"op":"mcm","clk":"1009374943","pt":1580665259388,"mc":[{"id":"1.168230754","rc":[{"batl":[[0,2.04,48.17]],"ltp":2.02,"tv":4036.07,"id":3622149}]}]}
{"op":"mcm","clk":"1009376696","pt":1580665269509,"mc":[{"id":"1.168230754","rc":[{"batb":[[2,1.98,48.62]],"ltp":2.02,"tv":4036.07,"id":3622149}]}]}
{"op":"mcm","clk":"1009384935","pt":1580665319282,"mc":[{"id":"1.168230754","rc":[{"trd":[[1.96,23.68]],"batb":[[0,1.96,467.47]],"ltp":1.96,"tv":10023.58,"id":2263603},{"batb":[[2,1.98,48.36]],"ltp":2.02,"tv":4036.07,"id":3622149}],"tv":14059.65}]}
{"op":"mcm","clk":"1009387843","pt":1580665338503,"mc":[{"id":"1.168230754","rc":[{"batb":[[0,2,6.11]],"batl":[[0,2.04,46.88]],"ltp":2.02,"tv":4036.07,"id":3622149}]}]}
{"op":"mcm","clk":"1009388730","pt":1580665344542,"mc":[{"id":"1.168230754","rc":[{"trd":[[1.97,932.69]],"batl":[[0,1.97,70.19]],"ltp":1.97,"tv":10025.63,"id":2263603},{"trd":[[2.02,263.49]],"ltp":2.02,"tv":4038.07,"id":3622149}],"tv":14063.71}]}
{"op":"mcm","clk":"1009388815","pt":1580665345127,"mc":[{"id":"1.168230754","rc":[{"batb":[[2,1.98,48.62]],"ltp":2.02,"tv":4038.07,"id":3622149}]}]}
{"op":"mcm","clk":"1009390819","pt":1580665358548,"mc":[{"id":"1.168230754","rc":[{"trd":[[1.96,24.49]],"batb":[[0,1.96,467.07]],"ltp":1.96,"tv":10026.44,"id":2263603},{"batb":[[2,1.98,46.36]],"ltp":2.02,"tv":4038.07,"id":3622149}],"tv":14064.52}]}
{"op":"mcm","clk":"1009391001","pt":1580665359616,"mc":[{"id":"1.168230754","rc":[{"trd":[[1.97,1002.88],[1.98,351.59]],"batb":[[0,1.97,21.01],[1,1.96,469.2],[2,1.95,445.35]],"batl":[[0,2,2456.67],[1,2.02,10.38],[2,2.04,4.27]],"ltp":1.98,"tv":10113.81,"id":2263603},{"trd":[[2.02,483.21]],"batb":[[1,1.99,4.3],[2,1.98,48.36]],"batl":[[0,2.02,52.02],[1,2.04,49.42],[2,2.06,4.15]],"ltp":2.02,"tv":4257.8,"id":3622149}],"tv":14371.61}]}
{"op":"mcm","clk":"1009391019","pt":1580665359728,"mc":[{"id":"1.168230754","rc":[{"batl":[[1,2.02,8.13]],"ltp":1.98,"tv":10113.81,"id":2263603}]}]}
{"op":"mcm","clk":"1009393047","pt":1580665373572,"mc":[{"id":"1.168230754","rc":[{"batb":[[2,1.95,443.24]],"batl":[[0,2,2456.05]],"ltp":1.98,"tv":10113.81,"id":2263603}]}]}
{"op":"mcm","clk":"1009393078","pt":1580665373736,"mc":[{"id":"1.168230754","rc":[{"batb":[[2,1.95,445.35]],"ltp":1.98,"tv":10113.81,"id":2263603}]}]}
{"op":"mcm","clk":"1009393872","pt":1580665379561,"mc":[{"id":"1.168230754","rc":[{"batl":[[0,2.02,74.86],[1,2.04,28.53]],"ltp":2.02,"tv":4257.8,"id":3622149}]}]}
{"op":"mcm","clk":"1009393917","pt":1580665379881,"mc":[{"id":"1.168230754","rc":[{"batb":[[2,1.95,445.24]],"ltp":1.98,"tv":10113.81,"id":2263603},{"batl":[[0,2.02,52.02]],"ltp":2.02,"tv":4257.8,"id":3622149}]}]}
{"op":"mcm","clk":"1009394244","pt":1580665382090,"mc":[{"id":"1.168230754","rc":[{"batb":[[0,1.98,4.63],[1,1.97,21.01],[2,1.96,466.08]],"ltp":1.98,"tv":10113.81,"id":2263603}]}]}
{"op":"mcm","clk":"1009395068","pt":1580665387586,"mc":[{"id":"1.168230754","rc":[{"batl":[[0,2.02,91.02]],"ltp":2.02,"tv":4257.8,"id":3622149}]}]}
{"op":"mcm","clk":"1009395189","pt":1580665388403,"mc":[{"id":"1.168230754","rc":[{"batb":[[0,1.97,21.01],[1,1.96,466.08],[2,1.95,445.35]],"ltp":1.98,"tv":10113.81,"id":2263603}]}]}
{"op":"mcm","clk":"1009395331","pt":1580665389366,"mc":[{"id":"1.168230754","rc":[{"batb":[[0,1.98,4.63],[1,1.97,21.01],[2,1.96,466.08]],"ltp":1.98,"tv":10113.81,"id":2263603},{"batl":[[0,2.02,114.12]],"ltp":2.02,"tv":4257.8,"id":3622149}]}]}
{"op":"mcm","clk":"1009396407","pt":1580665396513,"mc":[{"id":"1.168230754","rc":[{"batb":[[2,1.96,468.31]],"ltp":1.98,"tv":10113.81,"id":2263603}]}]}
{"op":"mcm","clk":"1009396698","pt":1580665398592,"mc":[{"id":"1.168230754","rc":[{"batb":[[1,1.97,4.65]],"ltp":1.98,"tv":10113.81,"id":2263603}]}]}
{"op":"mcm","clk":"1009397473","pt":1580665403499,"mc":[{"id":"1.168230754","rc":[{"trd":[[2,4949.24]],"batl":[[0,2,2450.74]],"ltp":2.0,"tv":10114.85,"id":2263603},{"trd":[[2,840.28]],"batb":[[0,1.99,4.3],[1,1.98,46.36],[2,1.97,6.16]],"ltp":2.0,"tv":4271.05,"id":3622149}],"tv":14385.9}]}
{"op":"mcm","clk":"1009397561","pt":1580665404086,"mc":[{"id":"1.168230754","rc":[{"batl":[[0,2,2455.32],[2,2.04,8.78]],"ltp":2.0,"tv":10114.85,"id":2263603},{"batb":[[1,1.98,48.36],[2,1.97,8.33]],"ltp":2.0,"tv":4271.05,"id":3622149}]}]}
{"op":"mcm","clk":"1009397932","pt":1580665406586,"mc":[{"id":"1.168230754","rc":[{"trd":[[1.98,477.29]],"batb":[[0,1.97,4.65],[1,1.96,414.71],[2,1.95,445.35]],"batl":[[0,1.98,604.01],[1,2,2457.32],[2,2.02,10.13]],"ltp":1.98,"tv":10240.55,"id":2263603},{"trd":[[2.02,597.33]],"batb":[[0,1.99,6.3]],"batl":[[0,2.04,28.53],[1,2.06,4.15],[2,2.1,50.41]],"ltp":2.02,"tv":4385.16,"id":3622149}],"tv":14625.72}]}
{"op":"mcm","clk":"1009398049","pt":1580665407435,"mc":[{"id":"1.168230754","rc":[{"batb":[[0,1.96,414.71],[1,1.95,443.24],[2,1.94,113.46]],"batl":[[0,1.98,608.66],[1,1.99,4.62],[2,2,2457.63]],"ltp":1.98,"tv":10240.55,"id":2263603}]}]}
{"op":"mcm","clk":"1009398667","pt":1580665411522,"mc":[{"id":"1.168230754","rc":[{"batl":[[1,1.99,28.18]],"ltp":1.98,"tv":10240.55,"id":2263603}]}]}
{"op":"mcm","clk":"1009398777","pt":1580665412296,"mc":[{"id":"1.168230754","rc":[{"batb":[[1,1.98,48.62],[2,1.97,6.16]],"ltp":2.02,"tv":4385.16,"id":3622149}]}]}
{"op":"mcm","clk":"1009399168","pt":1580665415129,"mc":[{"id":"1.168230754","rc":[{"trd":[[1.98,539.69]],"batl":[[0,1.98,546.26]],"ltp":1.98,"tv":10302.94,"id":2263603},{"trd":[[2.02,658.49]],"ltp":2.02,"tv":4446.33,"id":3622149}],"tv":14749.28}]}
{"op":"mcm","clk":"1009399561","pt":1580665417511,"mc":[{"id":"1.168230754","rc":[{"batl":[[1,1.99,4.62]],"ltp":1.98,"tv":10302.94,"id":2263603},{"batl":[[0,2.04,42.33]],"ltp":2.02,"tv":4446.33,"id":3622149}]}]}
{"op":"mcm","clk":"1009400393","pt":1580665422637,"mc":[{"id":"1.168230754","rc":[{"batl":[[1,1.99,5.63]],"ltp":1.98,"tv":10302.94,"id":2263603}]}]}
{"op":"mcm","clk":"1009400444","pt":1580665423025,"mc":[{"id":"1.168230754","rc":[{"batb":[[1,1.98,48.36]],"ltp":2.02,"tv":4446.33,"id":3622149}]}]}
{"op":"mcm","clk":"1009400677","pt":1580665424618,"mc":[{"id":"1.168230754","rc":[{"batb":[[0,1.96,415.02]],"ltp":1.98,"tv":10302.94,"id":2263603}]}]}
{"op":"mcm","clk":"1009402256","pt":1580665435541,"mc":[{"id":"1.168230754","rc":[{"batl":[[1,1.99,4.62]],"ltp":1.98,"tv":10302.94,"id":2263603},{"batb":[[1,1.98,48.62]],"ltp":2.02,"tv":4446.33,"id":3622149}]}]}
{"op":"mcm","clk":"1009404004","pt":1580665448566,"mc":[{"id":"1.168230754","rc":[{"trd":[[1.97,1003.5]],"batb":[[0,1.96,414.71]],"batl":[[0,1.97,199.69],[1,1.98,546.26],[2,1.99,6.92]],"ltp":1.97,"tv":10303.56,"id":2263603},{"batb":[[1,1.98,48.36]],"batl":[[0,2.04,17.99]],"ltp":2.02,"tv":4446.33,"id":3622149}],"tv":14749.9}]}
{"op":"mcm","clk":"1009404114","pt":1580665449372,"mc":[{"id":"1.168230754","rc":[{"batl":[[1,1.98,4.65]],"ltp":1.97,"tv":10303.56,"id":2263603},{"batl":[[0,2.04,62.4]],"ltp":2.02,"tv":4446.33,"id":3622149}]}]}
{"op":"mcm","clk":"1009405342","pt":1580665459362,"mc":[{"id":"1.168230754","rc":[{"batb":[[0,1.96,412.48]],"ltp":1.97,"tv":10303.56,"id":2263603}]}]}
{"op":"mcm","clk":"1009405893","pt":1580665463593,"mc":[{"id":"1.168230754","rc":[{"trd":[[1.96,914.41]],"batb":[[0,1.95,443.24],[1,1.94,111.37],[2,1.93,422.18]],"batl":[[0,1.96,64.18],[1,1.97,199.69],[2,1.98,6.73]],"ltp":1.96,"tv":11193.48,"id":2263603},{"trd":[[2.04,154.41]],"batb":[[0,2,42.18],[1,1.99,6.3],[2,1.98,48.36]],"batl":[[0,2.06,49.32],[1,2.1,50.41],[2,2.28,18.48]],"ltp":2.04,"tv":4508.74,"id":3622149}],"tv":15702.23}]}
{"op":"mcm","clk":"1009405990","pt":1580665464495,"mc":[{"id":"1.168230754","rc":[{"batb":[[1,1.94,116.16]],"batl":[[1,1.97,204.41]],"ltp":1.96,"tv":11193.48,"id":2263603},{"batb":[[0,2.02,45.17],[1,2,48.83],[2,1.99,6.3]],"batl":[[1,2.08,4.47],[2,2.1,50.41]],"ltp":2.04,"tv":4508.74,"id":3622149}]}]}
{"op":"mcm","clk":"1009407160","pt":1580665473487,"mc":[{"id":"1.168230754","rc":[{"batb":[[2,1.93,424.41]],"ltp":1.96,"tv":11193.48,"id":2263603}]}]}
{"op":"mcm","clk":"1009407826","pt":1580665478602,"mc":[{"id":"1.168230754","rc":[{"trd":[[1.96,926.89]],"batl":[[0,1.96,51.69]],"ltp":1.96,"tv":11205.97,"id":2263603},{"trd":[[2.04,166.41]],"ltp":2.04,"tv":4520.74,"id":3622149}],"tv":15726.71}]}
{"op":"mcm","clk":"1009408343","pt":1580665482611,"mc":[{"id":"1.168230754","rc":[{"batb":[[0,1.95,424.63],[2,1.93,450.4]],"ltp":1.96,"tv":11205.97,"id":2263603},{"batb":[[0,2.02,64.09]],"ltp":2.04,"tv":4520.74,"id":3622149}]}]}
{"op":"mcm","clk":"1009410512","pt":1580665499436,"mc":[{"id":"1.168230754","rc":[{"batl":[[1,1.97,4.72]],"ltp":1.96,"tv":11205.97,"id":2263603},{"batb":[[2,1.99,4.3]],"ltp":2.04,"tv":4520.74,"id":3622149}]}]}
{"op":"mcm","clk":"1009410541","pt":1580665499657,"mc":[{"id":"1.168230754","rc":[{"batb":[[2,1.99,6.3]],"ltp":2.04,"tv":4520.74,"id":3622149}]}]}
{"op":"mcm","clk":"1009414098","pt":1580665526407,"mc":[{"id":"1.168230754","rc":[{"trd":[[1.95,64.27]],"batb":[[0,1.95,424.13]],"ltp":1.95,"tv":11206.98,"id":2263603}],"tv":15727.72}]}
{"op":"mcm","clk":"1009415038","pt":1580665533504,"mc":[{"id":"1.168230754","rc":[{"trd":[[1.96,929]],"batl":[[0,1.96,49.58]],"ltp":1.96,"tv":11209.09,"id":2263603},{"trd":[[2.04,168.43]],"ltp":2.04,"tv":4522.76,"id":3622149}],"tv":15731.86}]}
{"op":"mcm","clk":"1009415800","pt":1580665539331,"mc":[{"id":"1.168230754","rc":[{"trd":[[1.95,430.27]],"batb":[[0,1.95,241.13]],"ltp":1.95,"tv":11575.09,"id":2263603}],"tv":16097.86}]}
{"op":"mcm","clk":"1009416071","pt":1580665541191,"mc":[{"id":"1.168230754","rc":[{"trd":[[1.95,440.57]],"batb":[[0,1.95,235.98]],"ltp":1.95,"tv":11585.4,"id":2263603}],"tv":16108.17}]}
{"op":"mcm","clk":"1009419255","pt":1580665567358,"mc":[{"id":"1.168230754","rc":[{"batb":[[0,1.95,239.14]],"ltp":1.95,"tv":11585.4,"id":2263603}]}]}
{"op":"mcm","clk":"1009423763","pt":1580665603471,"mc":[{"id":"1.168230754","rc":[{"trd":[[1.95,441.04]],"batb":[[0,1.95,238.9]],"ltp":1.95,"tv":11585.87,"id":2263603},{"batb":[[2,1.99,4.3]],"ltp":2.04,"tv":4522.76,"id":3622149}],"tv":16108.63}]}
{"op":"mcm","clk":"1009423790","pt":1580665603685,"mc":[{"id":"1.168230754","rc":[{"batb":[[2,1.99,6.3]],"ltp":2.04,"tv":4522.76,"id":3622149}]}]}
{"op":"mcm","clk":"1009430245","pt":1580665660553,"mc":[{"id":"1.168230754","rc":[{"trd":[[1.95,442.55]],"batb":[[0,1.95,238.15]],"ltp":1.95,"tv":11587.38,"id":2263603}],"tv":16110.15}]}
{"op":"mcm","clk":"1009431627","pt":1580665672504,"mc":[{"id":"1.168230754","rc":[{"trd":[[1.95,443.43]],"batb":[[0,1.95,237.71]],"ltp":1.95,"tv":11588.25,"id":2263603},{"batb":[[2,1.99,4.3]],"ltp":2.04,"tv":4522.76,"id":3622149}],"tv":16111.02}]}
{"op":"mcm","clk":"1009431648","pt":1580665672658,"mc":[{"id":"1.168230754","rc":[{"batb":[[2,1.99,6.3]],"ltp":2.04,"tv":4522.76,"id":3622149}]}]}
{"op":"mcm","clk":"1009433147","pt":1580665685485,"mc":[{"id":"1.168230754","rc":[{"batb":[[2,1.93,424.41]],"ltp":1.95,"tv":11588.25,"id":2263603}]}]}
{"op":"mcm","clk":"1009433368","pt":1580665687289,"mc":[{"id":"1.168230754","rc":[{"trd":[[1.95,452.2]],"batb":[[0,1.95,233.32]],"ltp":1.95,"tv":11597.03,"id":2263603}],"tv":16119.8}]}
{"op":"mcm","clk":"1009434784","pt":1580665698595,"mc":[{"id":"1.168230754","rc":[{"trd":[[1.96,978.66]],"batb":[[0,1.96,4.77],[1,1.95,233.32],[2,1.94,116.16]],"batl":[[0,1.98,4.65],[1,1.99,4.93],[2,2,2457.63]],"ltp":1.96,"tv":11646.68,"id":2263603},{"trd":[[2.04,216]],"batb":[[1,2,46.83]],"batl":[[0,2.04,4.65],[1,2.06,49.32],[2,2.08,4.47]],"ltp":2.04,"tv":4570.33,"id":3622149}],"tv":16217.01}]}
{"op":"mcm","clk":"1009434893","pt":1580665699631,"mc":[{"id":"1.168230754","rc":[{"batb":[[0,1.95,233.32],[1,1.94,116.16],[2,1.93,424.33]],"ltp":1.96,"tv":11646.68,"id":2263603},{"trd":[[2.04,224.82]],"batl":[[0,2.06,49.32],[1,2.08,4.47],[2,2.1,50.41]],"ltp":2.04,"tv":4579.15,"id":3622149}],"tv":16225.83}]}
{"op":"mcm","clk":"1009435077","pt":1580665701010,"mc":[{"id":"1.168230754","rc":[{"batb":[[0,1.95,233.93]],"ltp":1.96,"tv":11646.68,"id":2263603}]}]}
{"op":"mcm","clk":"1009435352","pt":1580665703521,"mc":[{"id":"1.168230754","rc":[{"trd":[[1.95,453.2]],"batb":[[0,1.96,4.85],[1,1.95,232.83],[2,1.94,118.25]],"ltp":1.95,"tv":11647.67,"id":2263603}],"tv":16226.82}]}
{"op":"mcm","clk":"1009435527","pt":1580665705025,"mc":[{"id":"1.168230754","rc":[{"batl":[[0,2.04,9.87],[1,2.06,49.32],[2,2.08,4.47]],"ltp":2.04,"tv":4579.15,"id":3622149}]}]}
{"op":"mcm","clk":"1009436241","pt":1580665711492,"mc":[{"id":"1.168230754","rc":[{"trd":[[1.96,998.63]],"batb":[[0,1.95,232.83],[1,1.94,116.16],[2,1.93,424.41]],"batl":[[0,1.96,4.87],[1,1.97,4.83],[2,1.98,6.81]],"ltp":1.96,"tv":11667.65,"id":2263603},{"trd":[[2.04,234.69]],"batb":[[1,2,48.83]],"batl":[[0,2.06,49.32],[1,2.08,4.47],[2,2.1,50.41]],"ltp":2.04,"tv":4589.02,"id":3622149}],"tv":16256.68}]}
{"op":"mcm","clk":"1009437450","pt":1580665722544,"mc":[{"id":"1.168230754","rc":[{"batl":[[0,1.97,4.83],[1,1.98,4.65],[2,1.99,7.11]],"ltp":1.96,"tv":11667.65,"id":2263603},{"batb":[[2,1.99,4.3]],"ltp":2.04,"tv":4589.02,"id":3622149}]}]}
{"op":"mcm","clk":"1009437468","pt":1580665722708,"mc":[{"id":"1.168230754","rc":[{"batb":[[1,2,46.83],[2,1.99,6.3]],"ltp":2.04,"tv":4589.02,"id":3622149}]}]}
{"op":"mcm","clk":"1009437902","pt":1580665726616,"mc":[{"id":"1.168230754","rc":[{"trd":[[1.95,493.19]],"batb":[[0,1.95,212.83]],"batl":[[0,1.98,4.65],[1,1.99,4.93],[2,2,2457.63]],"ltp":1.95,"tv":11707.65,"id":2263603}],"tv":16296.67}]}
{"op":"mcm","clk":"1009438381","pt":1580665731372,"mc":[{"id":"1.168230754","rc":[{"trd":[[1.95,503.19]],"batb":[[0,1.95,207.83]],"ltp":1.95,"tv":11717.64,"id":2263603}],"tv":16306.67}]}
{"op":"mcm","clk":"1009439238","pt":1580665739295,"mc":[{"id":"1.168230754","rc":[{"batb":[[0,1.95,208.95]],"ltp":1.95,"tv":11717.64,"id":2263603}]}]}
{"op":"mcm","clk":"1009439343","pt":1580665740188,"mc":[{"id":"1.168230754","rc":[{"trd":[[1.95,523.19]],"batb":[[0,1.95,198.95]],"ltp":1.95,"tv":11737.64,"id":2263603}],"tv":16326.67}]}
{"op":"mcm","clk":"1009441208","pt":1580665757586,"mc":[{"id":"1.168230754","rc":[{"batl":[[0,1.98,4.96]],"ltp":1.95,"tv":11737.64,"id":2263603}]}]}
{"op":"mcm","clk":"1009442334","pt":1580665768598,"mc":[{"id":"1.168230754","rc":[{"batl":[[0,1.98,4.73]],"ltp":1.95,"tv":11737.64,"id":2263603}]}]}
{"op":"mcm","clk":"1009443125","pt":1580665775330,"mc":[{"id":"1.168230754","rc":[{"trd":[[1.95,524.94]],"batb":[[0,1.95,198.07]],"ltp":1.95,"tv":11739.39,"id":2263603}],"tv":16328.42}]}
{"op":"mcm","clk":"1009445614","pt":1580665801649,"mc":[{"id":"1.168230754","rc":[{"batl":[[0,2.06,4.15]],"ltp":2.04,"tv":4589.02,"id":3622149}]}]}
{"op":"mcm","clk":"1009445931","pt":1580665805291,"mc":[{"id":"1.168230754","rc":[{"trd":[[1.95,570.32],[1.96,1008.43]],"batb":[[0,1.95,175.38]],"ltp":1.95,"tv":11794.57,"id":2263603}],"tv":16383.6}]}
{"op":"mcm","clk":"1009447810","pt":1580665825598,"mc":[{"id":"1.168230754","rc":[{"trd":[[1.95,572.46]],"batb":[[0,1.95,174.31]],"ltp":1.95,"tv":11796.71,"id":2263603}],"tv":16385.74}]}
{"op":"mcm","clk":"1009448820","pt":1580665835532,"mc":[{"id":"1.168230754","rc":[{"trd":[[1.95,573.36]],"batb":[[0,1.95,168.88],[2,1.93,429.4]],"ltp":1.95,"tv":11797.61,"id":2263603},{"trd":[[2.06,28.2]],"batb":[[0,2.04,4.72],[1,2.02,64.09],[2,2,46.83]],"batl":[[0,2.08,4.47],[1,2.1,55],[2,2.28,18.48]],"ltp":2.06,"tv":4598.17,"id":3622149}],"tv":16395.79}]}
{"op":"mcm","clk":"1009448882","pt":1580665836114,"mc":[{"id":"1.168230754","rc":[{"batl":[[1,1.99,7.2]],"ltp":1.95,"tv":11797.61,"id":2263603},{"batb":[[2,2,48.83]],"ltp":2.06,"tv":4598.17,"id":3622149}]}]}
{"op":"mcm","clk":"1009450060","pt":1580665848325,"mc":[{"id":"1.168230754","rc":[{"trd":[[1.95,576.38]],"batb":[[0,1.95,167.36]],"ltp":1.95,"tv":11800.63,"id":2263603}],"tv":16398.81}]}
{"op":"mcm","clk":"1009450615","pt":1580665854144,"mc":[{"id":"1.168230754","rc":[{"batl":[[2,2,2455.63]],"ltp":1.95,"tv":11800.63,"id":2263603},{"trd":[[2.04,236.44]],"batb":[[0,2.04,3.85]],"ltp":2.04,"tv":4599.92,"id":3622149}],"tv":16400.56}]}
{"op":"mcm","clk":"1009450643","pt":1580665855186,"mc":[{"id":"1.168230754","rc":[{"batb":[[0,1.95,172.31]],"batl":[[2,2,2457.63]],"ltp":1.95,"tv":11800.63,"id":2263603},{"batb":[[0,2.02,64.09],[1,2,48.83],[2,1.99,6.3]],"ltp":2.04,"tv":4599.92,"id":3622149}]}]}
{"op":"mcm","clk":"1009450746","pt":1580665856926,"mc":[{"id":"1.168230754","rc":[{"batl":[[1,1.99,4.93]],"ltp":1.95,"tv":11800.63,"id":2263603},{"batb":[[1,2,46.83]],"ltp":2.04,"tv":4599.92,"id":3622149}]}]}
{"op":"mcm","clk":"1009452392","pt":1580665871457,"mc":[{"id":"1.168230754","rc":[{"batb":[[0,1.95,178.04]],"ltp":1.95,"tv":11800.63,"id":2263603},{"trd":[[2.02,670.49]],"batb":[[0,2.02,58.09]],"batl":[[0,2.06,5.42],[1,2.08,4.47],[2,2.1,55]],"ltp":2.02,"tv":4611.92,"id":3622149}],"tv":16412.56}]}
{"op":"mcm","clk":"1009452473","pt":1580665872141,"mc":[{"id":"1.168230754","rc":[{"batb":[[0,1.95,178.03]],"ltp":1.95,"tv":11800.63,"id":2263603},{"batl":[[0,2.06,10.12]],"ltp":2.02,"tv":4611.92,"id":3622149}]}]}
{"op":"mcm","clk":"1009453528","pt":1580665882490,"mc":[{"id":"1.168230754","rc":[{"batb":[[0,1.95,177.97]],"ltp":1.95,"tv":11800.63,"id":2263603},{"batl":[[0,2.06,10.05]],"ltp":2.02,"tv":4611.92,"id":3622149}]}]}
{"op":"mcm","clk":"1009453585","pt":1580665882977,"mc":[{"id":"1.168230754","rc":[{"batb":[[0,1.95,177.96]],"ltp":1.95,"tv":11800.63,"id":2263603}]}]}
{"op":"mcm","clk":"1009456827","pt":1580665914526,"mc":[{"id":"1.168230754","rc":[{"trd":[[1.95,578.41]],"batb":[[0,1.95,171.3]],"ltp":1.95,"tv":11802.67,"id":2263603},{"batl":[[0,2.06,4.7]],"ltp":2.02,"tv":4611.92,"id":3622149}],"tv":16414.59}]}
{"op":"mcm","clk":"1009456894","pt":1580665915214,"mc":[{"id":"1.168230754","rc":[{"batb":[[0,1.95,176.74]],"ltp":1.95,"tv":11802.67,"id":2263603},{"batl":[[0,2.06,9.85]],"ltp":2.02,"tv":4611.92,"id":3622149}]}]}
{"op":"mcm","clk":"1009457849","pt":1580665924608,"mc":[{"id":"1.168230754","rc":[{"batb":[[0,1.95,176.68]],"ltp":1.95,"tv":11802.67,"id":2263603},{"batl":[[0,2.06,9.79]],"ltp":2.02,"tv":4611.92,"id":3622149}]}]}
{"op":"mcm","clk":"1009462846","pt":1580665977640,"mc":[{"id":"1.168230754","rc":[{"trd":[[1.97,1003.67],[1.98,548.98],[1.99,194.91],[2,5746.96]],"batb":[[0,1.96,46.79],[1,1.95,176.68],[2,1.94,118.16]],"batl":[[0,1.99,4.96],[1,2,2056.77],[2,2.02,3.79]],"ltp":2.0,"tv":12678.68,"id":2263603},{"trd":[[2.02,728.58]],"batb":[[0,2,4.65],[1,1.99,4.3],[2,1.98,2.26]],"batl":[[0,2.04,4.84],[1,2.06,44.43],[2,2.08,4.47]],"ltp":2.02,"tv":4670.01,"id":3622149}],"tv":17348.7}]}
{"op":"mcm","clk":"1009462897","pt":1580665978123,"mc":[{"id":"1.168230754","rc":[{"batb":[[0,1.96,64.71]],"batl":[[2,2.02,6.04]],"ltp":2.0,"tv":12678.68,"id":2263603},{"batb":[[2,1.98,36.09]],"ltp":2.02,"tv":4670.01,"id":3622149}]}]}
{"op":"mcm","clk":"1009463813","pt":1580665987550,"mc":[{"id":"1.168230754","rc":[{"trd":[[2,842.91]],"batb":[[0,2,3.33]],"ltp":2.0,"tv":4672.65,"id":3622149}],"tv":17351.33}]}
{"op":"mcm","clk":"1009463916","pt":1580665988561,"mc":[{"id":"1.168230754","rc":[{"batb":[[0,1.97,5.33],[1,1.96,64.71],[2,1.95,176.68]],"batl":[[0,2,2056.77],[1,2.02,8.68],[2,2.04,4.4]],"ltp":2.0,"tv":12678.68,"id":2263603}]}]}
{"op":"mcm","clk":"1009464009","pt":1580665989457,"mc":[{"id":"1.168230754","rc":[{"batb":[[2,1.95,178.68]],"batl":[[0,1.99,4.97],[1,2,2056.77],[2,2.02,8.68]],"ltp":2.0,"tv":12678.68,"id":2263603}]}]}
{"op":"mcm","clk":"1009464029","pt":1580665989663,"mc":[{"id":"1.168230754","rc":[{"batl":[[2,2.02,10.68]],"ltp":2.0,"tv":12678.68,"id":2263603}]}]}
{"op":"mcm","clk":"1009465342","pt":1580666001593,"mc":[{"id":"1.168230754","rc":[{"batb":[[2,1.95,175.52]],"ltp":2.0,"tv":12678.68,"id":2263603}]}]}
{"op":"mcm","clk":"1009465483","pt":1580666002943,"mc":[{"id":"1.168230754","rc":[{"batb":[[0,1.96,65.02],[1,1.95,173.52],[2,1.94,118.25]],"ltp":2.0,"tv":12678.68,"id":2263603}]}]}
{"op":"mcm","clk":"1009468975","pt":1580666038580,"mc":[{"id":"1.168230754","rc":[{"trd":[[1.99,197.06]],"batl":[[0,1.99,3.89]],"ltp":1.99,"tv":12680.84,"id":2263603}],"tv":17353.49}]}
{"op":"mcm","clk":"1009469075","pt":1580666039584,"mc":[{"id":"1.168230754","rc":[{"batb":[[0,1.97,5.37],[1,1.96,64.71],[2,1.95,175.63]],"ltp":1.99,"tv":12680.84,"id":2263603}]}]}
{"op":"mcm","clk":"1009469157","pt":1580666040482,"mc":[{"id":"1.168230754","rc":[{"batb":[[0,1.96,65.02],[1,1.95,175.63],[2,1.94,118.25]],"ltp":1.99,"tv":12680.84,"id":2263603}]}]}
{"op":"mcm","clk":"1009469178","pt":1580666040696,"mc":[{"id":"1.168230754","rc":[{"batb":[[1,1.95,173.52]],"ltp":1.99,"tv":12680.84,"id":2263603}]}]}
{"op":"mcm","clk":"1009471189","pt":1580666060523,"mc":[{"id":"1.168230754","rc":[{"batb":[[0,1.96,65.7]],"ltp":1.99,"tv":12680.84,"id":2263603}]}]}
{"op":"mcm","clk":"1009473863","pt":1580666088547,"mc":[{"id":"1.168230754","rc":[{"trd":[[1.99,198.27]],"batl":[[0,1.99,3.29]],"ltp":1.99,"tv":12682.04,"id":2263603}],"tv":17354.7}]}
{"op":"mcm","clk":"1009473985","pt":1580666089644,"mc":[{"id":"1.168230754","rc":[{"batb":[[0,1.97,6.08],[1,1.96,64.71],[2,1.95,175.52]],"ltp":1.99,"tv":12682.04,"id":2263603}]}]}
{"op":"mcm","clk":"1009474177","pt":1580666091458,"mc":[{"id":"1.168230754","rc":[{"trd":[[1.97,1009.19]],"batb":[[0,1.96,64.71],[1,1.95,173.52],[2,1.94,118.25]],"ltp":1.97,"tv":12687.56,"id":2263603},{"trd":[[2,843.3],[2.02,732.58],[2.04,251.45]],"batb":[[0,2,3.13],[2,1.98,35.83]],"batl":[[0,2.06,44.43],[1,2.08,4.47],[2,2.1,55]],"ltp":2.0,"tv":4692.04,"id":3622149}],"tv":17379.61}]}
{"op":"mcm","clk":"1009474315","pt":1580666092477,"mc":[{"id":"1.168230754","rc":[{"batb":[[0,1.96,59.68]],"ltp":1.97,"tv":12687.56,"id":2263603},{"batb":[[0,2.02,4.97],[1,2,3.13],[2,1.99,6.3]],"ltp":2.0,"tv":4692.04,"id":3622149}]}]}
{"op":"mcm","clk":"1009475268","pt":1580666101584,"mc":[{"id":"1.168230754","rc":[{"trd":[[1.96,1032.19]],"batb":[[0,1.96,47.8],[1,1.95,168.57],[2,1.94,113.46]],"batl":[[0,1.99,10.86],[1,2,2052.18],[2,2.02,6.04]],"ltp":1.96,"tv":12711.32,"id":2263603},{"batb":[[0,1.99,10.86],[1,1.98,36.09],[2,1.97,8.16]],"batl":[[0,2.08,38.59],[1,2.1,50.41],[2,2.28,18.48]],"ltp":2.0,"tv":4692.04,"id":3622149}],"tv":17403.36}]}
{"op":"mcm","clk":"1009475372","pt":1580666102559,"mc":[{"id":"1.168230754","rc":[{"batb":[[1,1.98,33.83]],"ltp":2.0,"tv":4692.04,"id":3622149}]}]}
{"op":"mcm","clk":"1009475386","pt":1580666102766,"mc":[{"id":"1.168230754","rc":[{"batb":[[1,1.98,36.09]],"ltp":2.0,"tv":4692.04,"id":3622149}]}]}
{"op":"mcm","clk":"1009475869","pt":1580666107360,"mc":[{"id":"1.168230754","rc":[{"batl":[[0,1.99,11.17]],"ltp":1.96,"tv":12711.32,"id":2263603},{"batb":[[2,1.97,8.33]],"ltp":2.0,"tv":4692.04,"id":3622149}]}]}
{"op":"mcm","clk":"1009476791","pt":1580666117566,"mc":[{"id":"1.168230754","rc":[{"batb":[[0,2.02,12.59],[1,1.99,12.86],[2,1.98,36.09]],"ltp":2.0,"tv":4692.04,"id":3622149}]}]}
{"op":"mcm","clk":"1009476816","pt":1580666117884,"mc":[{"id":"1.168230754","rc":[{"batb":[[2,1.98,35.83]],"ltp":2.0,"tv":4692.04,"id":3622149}]}]}
{"op":"mcm","clk":"1009477480","pt":1580666125403,"mc":[{"id":"1.168230754","rc":[{"batb":[[0,1.96,50.92]],"ltp":1.96,"tv":12711.32,"id":2263603}]}]}
{"op":"mcm","clk":"1009477536","pt":1580666125882,"mc":[{"id":"1.168230754","rc":[{"batb":[[2,1.98,36.09]],"ltp":2.0,"tv":4692.04,"id":3622149}]}]}
{"op":"mcm","clk":"1009480501","pt":1580666156448,"mc":[{"id":"1.168230754","rc":[{"trd":[[1.96,1036.39],[1.99,204.6]],"batb":[[0,1.96,48.82]],"batl":[[0,1.99,8]],"ltp":1.99,"tv":12721.86,"id":2263603}],"tv":17413.9}]}
{"op":"mcm","clk":"1009481093","pt":1580666162529,"mc":[{"id":"1.168230754","rc":[{"batl":[[2,2.02,2.25]],"ltp":1.99,"tv":12721.86,"id":2263603}]}]}
{"op":"mcm","clk":"1009481145","pt":1580666162964,"mc":[{"id":"1.168230754","rc":[{"batb":[[2,1.98,35.83]],"ltp":2.0,"tv":4692.04,"id":3622149}]}]}
{"op":"mcm","clk":"1009481448","pt":1580666166058,"mc":[{"id":"1.168230754","rc":[{"trd":[[1.96,1086.39]],"batb":[[0,1.96,23.82],[1,1.95,163.19]],"ltp":1.96,"tv":12771.86,"id":2263603}],"tv":17463.9}]}
{"op":"mcm","clk":"1009481901","pt":1580666170629,"mc":[{"id":"1.168230754","rc":[{"batl":[[0,1.98,3.79],[1,1.99,8],[2,2,2054.18]],"ltp":1.96,"tv":12771.86,"id":2263603}]}]}
{"op":"mcm","clk":"1009483119","pt":1580666183641,"mc":[{"id":"1.168230754","rc":[{"trd":[[1.98,551.14]],"batl":[[0,1.98,1.63],[2,2,2052.18]],"ltp":1.98,"tv":12774.01,"id":2263603},{"trd":[[2.02,759.87]],"batb":[[0,2.02,22.84],[1,2,23.07],[2,1.99,10.86]],"ltp":2.02,"tv":4719.33,"id":3622149}],"tv":17493.35}]}
{"op":"mcm","clk":"1009483177","pt":1580666184270,"mc":[{"id":"1.168230754","rc":[{"batb":[[0,1.99,10.86],[1,1.98,35.83],[2,1.97,8.16]],"ltp":2.02,"tv":4719.33,"id":3622149}]}]}
{"op":"mcm","clk":"1009486285","pt":1580666217209,"mc":[{"id":"1.168230754","rc":[{"batl":[[0,2.04,3.89],[1,2.08,38.59],[2,2.1,50.41]],"ltp":2.02,"tv":4719.33,"id":3622149}]}]}
{"op":"mcm","clk":"1009494475","pt":1580666294598,"mc":[{"id":"1.168230754","rc":[{"batl":[[0,1.98,26.95],[2,2,2054.18]],"ltp":1.98,"tv":12774.01,"id":2263603},{"batb":[[0,2,22.34],[1,1.99,12.86],[2,1.98,35.83]],"ltp":2.02,"tv":4719.33,"id":3622149}]}]}
{"op":"mcm","clk":"1009497208","pt":1580666321614,"mc":[{"id":"1.168230754","rc":[{"trd":[[1.98,605.07]],"batb":[[0,1.98,251.65],[1,1.96,25.95],[2,1.95,165.3]],"batl":[[0,1.99,8],[1,2,2052.18],[2,2.02,2]],"ltp":1.98,"tv":12827.95,"id":2263603},{"batb":[[1,1.99,10.86]],"batl":[[0,2.04,18.13]],"ltp":2.02,"tv":4719.33,"id":3622149}],"tv":17547.29}]}
{"op":"mcm","clk":"1009497261","pt":1580666322094,"mc":[{"id":"1.168230754","rc":[{"batl":[[0,1.99,22.64]],"ltp":1.98,"tv":12827.95,"id":2263603},{"batb":[[0,1.99,10.86],[1,1.98,36.09],[2,1.97,8.33]],"ltp":2.02,"tv":4719.33,"id":3622149}]}]}
{"op":"mcm","clk":"1009497465","pt":1580666324446,"mc":[{"id":"1.168230754","rc":[{"batb":[[1,1.96,23.17]],"batl":[[0,1.99,4.18]],"ltp":1.98,"tv":12827.95,"id":2263603},{"batb":[[0,1.98,36.09],[1,1.97,8.33],[2,1.96,2.13]],"batl":[[0,2.04,3.89],[1,2.1,50.41],[2,2.28,18.48]],"ltp":2.02,"tv":4719.33,"id":3622149}]}]}
{"op":"mcm","clk":"1009498757","pt":1580666338463,"mc":[{"id":"1.168230754","rc":[{"trd":[[1.98,607.27]],"batb":[[0,1.98,250.55]],"ltp":1.98,"tv":12830.14,"id":2263603},{"batb":[[1,1.97,8.16],[2,1.95,2.63]],"ltp":2.02,"tv":4719.33,"id":3622149}],"tv":17549.48}]}
{"op":"mcm","clk":"1009498805","pt":1580666338944,"mc":[{"id":"1.168230754","rc":[{"trd":[[1.98,619.77]],"batb":[[0,1.98,244.3]],"ltp":1.98,"tv":12842.64,"id":2263603}],"tv":17561.98}]}
{"op":"mcm","clk":"1009499134","pt":1580666342160,"mc":[{"id":"1.168230754","rc":[{"batb":[[1,1.96,20.05]],"ltp":1.98,"tv":12842.64,"id":2263603}]}]}
{"op":"mcm","clk":"1009499454","pt":1580666345540,"mc":[{"id":"1.168230754","rc":[{"batb":[[2,1.95,163.19]],"ltp":1.98,"tv":12842.64,"id":2263603},{"batb":[[1,1.97,6.16]],"ltp":2.02,"tv":4719.33,"id":3622149}]}]}
{"op":"mcm","clk":"1009499479","pt":1580666345746,"mc":[{"id":"1.168230754","rc":[{"batb":[[2,1.95,165.19]],"ltp":1.98,"tv":12842.64,"id":2263603},{"batb":[[1,1.97,8.16]],"ltp":2.02,"tv":4719.33,"id":3622149}]}]}
{"op":"mcm","clk":"1009500362","pt":1580666354468,"mc":[{"id":"1.168230754","rc":[{"batb":[[0,1.96,17.92],[1,1.95,163.19],[2,1.94,113.37]],"batl":[[0,1.98,3.89],[1,2,2052.49],[2,2.04,4.27]],"ltp":1.98,"tv":12842.64,"id":2263603},{"batb":[[1,1.97,8.33]],"ltp":2.02,"tv":4719.33,"id":3622149}]}]}
{"op":"mcm","clk":"1009500430","pt":1580666355058,"mc":[{"id":"1.168230754","rc":[{"batl":[[1,2,2054.49],[2,2.02,2]],"ltp":1.98,"tv":12842.64,"id":2263603},{"batb":[[0,1.99,2],[1,1.98,35.83],[2,1.97,8.33]],"ltp":2.02,"tv":4719.33,"id":3622149}]}]}
{"op":"mcm","clk":"1009500981","pt":1580666360560,"mc":[{"id":"1.168230754","rc":[{"batl":[[2,2.06,914.97]],"ltp":1.98,"tv":12842.64,"id":2263603},{"batb":[[1,1.98,33.83],[2,1.97,6.16]],"ltp":2.02,"tv":4719.33,"id":3622149}]}]}
{"op":"mcm","clk":"1009500998","pt":1580666360765,"mc":[{"id":"1.168230754","rc":[{"batl":[[2,2.02,2]],"ltp":1.98,"tv":12842.64,"id":2263603},{"batb":[[1,1.98,35.83]],"ltp":2.02,"tv":4719.33,"id":3622149}]}]}
{"op":"mcm","clk":"1009501465","pt":1580666365456,"mc":[{"id":"1.168230754","rc":[{"trd":[[1.98,627.55],[1.99,205.22]],"batb":[[0,1.99,237.63],[1,1.97,2.17],[2,1.96,20.05]],"batl":[[0,2,2052.18],[1,2.04,2.13],[2,2.06,917.22]],"ltp":1.99,"tv":12851.04,"id":2263603},{"batb":[[0,1.98,35.83],[1,1.97,8.33],[2,1.95,2.63]],"ltp":2.02,"tv":4719.33,"id":3622149}],"tv":17570.38}]}
{"op":"mcm","clk":"1009501656","pt":1580666367562,"mc":[{"id":"1.168230754","rc":[{"batb":[[0,1.96,17.92],[1,1.95,165.3],[2,1.94,113.46]],"ltp":1.99,"tv":12851.04,"id":2263603}]}]}
{"op":"mcm","clk":"1009501673","pt":1580666367760,"mc":[{"id":"1.168230754","rc":[{"batb":[[1,1.95,163.19]],"ltp":1.99,"tv":12851.04,"id":2263603}]}]}
{"op":"mcm","clk":"1009502249","pt":1580666373489,"mc":[{"id":"1.168230754","rc":[{"trd":[[2,5982.27]],"batl":[[0,2,1816.88],[2,2.06,916.97]],"ltp":2.0,"tv":13086.35,"id":2263603},{"trd":[[2,1078.6]],"ltp":2.0,"tv":4954.63,"id":3622149}],"tv":18040.99}]}
{"op":"mcm","clk":"1009503570","pt":1580666387613,"mc":[{"id":"1.168230754","rc":[{"batl":[[2,2.06,917.06]],"ltp":2.0,"tv":13086.35,"id":2263603}]}]}
{"op":"mcm","clk":"1009503913","pt":1580666391079,"mc":[{"id":"1.168230754","rc":[{"batb":[[2,1.94,117.24]],"ltp":2.0,"tv":13086.35,"id":2263603}]}]}
{"op":"mcm","clk":"1009504073","pt":1580666392501,"mc":[{"id":"1.168230754","rc":[{"batb":[[0,1.96,18.23]],"ltp":2.0,"tv":13086.35,"id":2263603}]}]}
{"op":"mcm","clk":"1009504272","pt":1580666394511,"mc":[{"id":"1.168230754","rc":[{"trd":[[1.96,1089.77],[1.97,1009.81]],"batb":[[0,1.96,16.23]],"ltp":1.96,"tv":13090.35,"id":2263603}],"tv":18044.98}]}
{"op":"mcm","clk":"1009504358","pt":1580666395322,"mc":[{"id":"1.168230754","rc":[{"batb":[[0,1.95,188.48],[1,1.94,117.24],[2,1.93,424.33]],"ltp":1.96,"tv":13090.35,"id":2263603}]}]}
{"op":"mcm","clk":"1009505097","pt":1580666402620,"mc":[{"id":"1.168230754","rc":[{"batl":[[0,2,1817.78]],"ltp":1.96,"tv":13090.35,"id":2263603}]}]}
{"op":"mcm","clk":"1009505103","pt":1580666402712,"mc":[{"id":"1.168230754","rc":[{"trd":[[1.96,1090.72]],"ltp":1.96,"tv":13091.3,"id":2263603},{"trd":[[2.04,252.36]],"batl":[[0,2.04,2.98]],"ltp":2.04,"tv":4955.54,"id":3622149}],"tv":18046.84}]}
{"op":"mcm","clk":"1009505309","pt":1580666404608,"mc":[{"id":"1.168230754","rc":[{"batb":[[0,1.96,3.12],[1,1.95,188.48],[2,1.94,117.24]],"ltp":1.96,"tv":13091.3,"id":2263603}]}]}
{"op":"mcm","clk":"1009505770","pt":1580666408628,"mc":[{"id":"1.168230754","rc":[{"batl":[[0,1.99,1.52],[1,2,1816.88],[2,2.04,2.13]],"ltp":1.96,"tv":13091.3,"id":2263603}]}]}
{"op":"mcm","clk":"1009506140","pt":1580666412603,"mc":[{"id":"1.168230754","rc":[{"trd":[[1.96,1090.82]],"batb":[[0,1.96,3.07]],"ltp":1.96,"tv":13091.4,"id":2263603}],"tv":18046.94}]}
{"op":"mcm","clk":"1009506478","pt":1580666416615,"mc":[{"id":"1.168230754","rc":[{"batb":[[0,2,1.11],[1,1.98,35.83],[2,1.97,8.33]],"ltp":2.04,"tv":4955.54,"id":3622149}]}]}
{"op":"mcm","clk":"1009506639","pt":1580666418508,"mc":[{"id":"1.168230754","rc":[{"batl":[[1,2,1816.57]],"ltp":1.96,"tv":13091.4,"id":2263603}]}]}
{"op":"mcm","clk":"1009507357","pt":1580666426612,"mc":[{"id":"1.168230754","rc":[{"trd":[[1.96,1100.06]],"batb":[[0,1.95,188.48],[1,1.94,117.24],[2,1.93,424.33]],"batl":[[0,1.96,109.05],[1,1.99,1.52],[2,2,1816.57]],"ltp":1.96,"tv":13100.64,"id":2263603},{"trd":[[2.04,255.34]],"batl":[[0,2.1,50.41],[1,2.28,18.48],[2,2.4,22.41]],"ltp":2.04,"tv":4958.52,"id":3622149}],"tv":18059.16}]}
{"op":"mcm","clk":"1009507629","pt":1580666429550,"mc":[{"id":"1.168230754","rc":[{"trd":[[1.96,1101.9]],"batl":[[0,1.96,108.13]],"ltp":1.96,"tv":13102.48,"id":2263603}],"tv":18061.01}]}
{"op":"mcm","clk":"1009507887","pt":1580666432226,"mc":[{"id":"1.168230754","rc":[{"batl":[[1,2.4,22.41],[2,95,16]],"ltp":2.04,"tv":4958.52,"id":3622149}]}]}
{"op":"mcm","clk":"1009508200","pt":1580666435436,"mc":[{"id":"1.168230754","rc":[{"batl":[[1,1.98,3.09],[2,1.99,1.52]],"ltp":1.96,"tv":13102.48,"id":2263603}]}]}
{"op":"mcm","clk":"1009510221","pt":1580666456636,"mc":[{"id":"1.168230754","rc":[{"batl":[[2,2,1817.47]],"ltp":1.96,"tv":13102.48,"id":2263603}]}]}
{"op":"mcm","clk":"1009511009","pt":1580666464279,"mc":[{"id":"1.168230754","rc":[{"batb":[[1,1.94,115.15],[2,1.93,422.33]],"batl":[[2,1.99,1.52]],"ltp":1.96,"tv":13102.48,"id":2263603},{"batb":[[1,1.98,33.83],[2,1.97,6.16]],"ltp":2.04,"tv":4958.52,"id":3622149}]}]}
{"op":"mcm","clk":"1009511695","pt":1580666471279,"mc":[{"id":"1.168230754","rc":[{"trd":[[1.96,1134.36]],"batb":[[0,1.95,172.25]],"batl":[[0,1.96,91.9]],"ltp":1.96,"tv":13134.94,"id":2263603}],"tv":18093.47}]}
{"op":"mcm","clk":"1009511745","pt":1580666471755,"mc":[{"id":"1.168230754","rc":[{"batb":[[0,1.95,163.19],[1,1.94,133.39]],"ltp":1.96,"tv":13134.94,"id":2263603},{"batb":[[0,2.02,17.4],[1,2,1.11]],"ltp":2.04,"tv":4958.52,"id":3622149}]}]}
{"op":"mcm","clk":"1009515467","pt":1580666510637,"mc":[{"id":"1.168230754","marketDefinition":{"bspMarket":false,"turnInPlayEnabled":true,"persistenceEnabled":true,"marketBaseRate":5.0,"eventId":"29681775","eventTypeId":"2","numberOfWinners":1,"bettingType":"ODDS","marketType":"MATCH_ODDS","marketTime":"2020-02-02T18:01:00.000Z","suspendTime":"2020-02-02T18:01:00.000Z","bspReconciled":false,"complete":true,"inPlay":false,"crossMatching":true,"runnersVoidable":false,"numberOfActiveRunners":2,"betDelay":0,"status":"OPEN","runners":[{"status":"ACTIVE","sortPriority":1,"id":2263603,"name":"Madison Brengle"},{"status":"ACTIVE","sortPriority":2,"id":3622149,"name":"Stefanie Voegele"}],"regulators":["MR_INT"],"discountAllowed":true,"timezone":"UTC","openDate":"2020-02-02T18:00:00.000Z","version":3150167963,"name":"Match Odds","eventName":"Brengle v Voegele"},"rc":[{"trd":[[1.95,579.15]],"batb":[[0,1.95,162.82]],"ltp":1.95,"tv":13135.68,"id":2263603}],"tv":18094.21}]}
{"op":"mcm","clk":"1009515709","pt":1580666513126,"mc":[{"id":"1.168230754","marketDefinition":{"bspMarket":false,"turnInPlayEnabled":true,"persistenceEnabled":true,"marketBaseRate":5.0,"eventId":"29681775","eventTypeId":"2","numberOfWinners":1,"bettingType":"ODDS","marketType":"MATCH_ODDS","marketTime":"2020-02-02T18:01:00.000Z","suspendTime":"2020-02-02T18:01:00.000Z","bspReconciled":false,"complete":true,"inPlay":false,"crossMatching":true,"runnersVoidable":false,"numberOfActiveRunners":2,"betDelay":0,"status":"OPEN","runners":[{"status":"ACTIVE","sortPriority":1,"id":2263603,"name":"Madison Brengle"},{"status":"ACTIVE","sortPriority":2,"id":3622149,"name":"Stefanie Voegele"}],"regulators":["MR_INT"],"discountAllowed":true,"timezone":"UTC","openDate":"2020-02-02T18:01:00.000Z","version":3150167963,"name":"Match Odds","eventName":"Brengle v Voegele"}}]}
{"op":"mcm","clk":"1009517357","pt":1580666530117,"mc":[{"id":"1.168230754","rc":[{"trd":[[1.96,1138.89]],"batl":[[0,1.96,87.37]],"ltp":1.96,"tv":13140.21,"id":2263603},{"trd":[[2.04,259.69]],"ltp":2.04,"tv":4962.87,"id":3622149}],"tv":18103.09}]}
{"op":"mcm","clk":"1009519906","pt":1580666557406,"mc":[{"id":"1.168230754","rc":[{"batb":[[2,1.99,239.98]],"ltp":2.04,"tv":4962.87,"id":3622149}]}]}
{"op":"mcm","clk":"1009521820","pt":1580666576213,"mc":[{"id":"1.168230754","rc":[{"trd":[[1.95,639.15]],"batb":[[0,1.95,132.82]],"ltp":1.95,"tv":13200.22,"id":2263603}],"tv":18163.09}]}
{"op":"mcm","clk":"1009522020","pt":1580666578319,"mc":[{"id":"1.168230754","rc":[{"trd":[[1.96,1140.64]],"batl":[[0,1.96,85.62]],"ltp":1.96,"tv":13201.97,"id":2263603},{"trd":[[2.04,261.37]],"ltp":2.04,"tv":4964.55,"id":3622149}],"tv":18166.52}]}
{"op":"mcm","clk":"1009523730","pt":1580666595419,"mc":[{"id":"1.168230754","rc":[{"trd":[[1.96,1161.46]],"batl":[[0,1.96,64.8]],"ltp":1.96,"tv":13222.79,"id":2263603},{"trd":[[2.04,281.37]],"ltp":2.04,"tv":4984.55,"id":3622149}],"tv":18207.34}]}
{"op":"mcm","clk":"1009525019","pt":1580666607043,"mc":[{"id":"1.168230754","rc":[{"batb":[[2,1.93,420.1]],"ltp":1.96,"tv":13222.79,"id":2263603}]}]}
{"op":"mcm","clk":"1009525631","pt":1580666612352,"mc":[{"id":"1.168230754","rc":[{"trd":[[1.95,643.17]],"batb":[[0,1.95,130.81]],"ltp":1.95,"tv":13226.81,"id":2263603}],"tv":18211.36}]}
{"op":"mcm","clk":"1009525720","pt":1580666613216,"mc":[{"id":"1.168230754","rc":[{"batb":[[1,1.99,239.98],[2,1.97,6.16]],"ltp":2.04,"tv":4984.55,"id":3622149}]}]}
{"op":"mcm","clk":"1009525797","pt":1580666613948,"mc":[{"id":"1.168230754","rc":[{"batb":[[0,1.95,129.69]],"ltp":1.95,"tv":13226.81,"id":2263603}]}]}
{"op":"mcm","clk":"1009526075","pt":1580666616448,"mc":[{"id":"1.168230754","rc":[{"trd":[[1.95,645.41]],"batb":[[0,1.95,128.58]],"ltp":1.95,"tv":13229.04,"id":2263603}],"tv":18213.59}]}
{"op":"mcm","clk":"1009526179","pt":1580666617339,"mc":[{"id":"1.168230754","rc":[{"trd":[[1.95,646.85]],"batb":[[0,1.95,127.85]],"ltp":1.95,"tv":13230.48,"id":2263603}],"tv":18215.04}]}
{"op":"mcm","clk":"1009526264","pt":1580666618142,"mc":[{"id":"1.168230754","rc":[{"batl":[[1,1.98,4.01]],"ltp":1.95,"tv":13230.48,"id":2263603}]}]}
{"op":"mcm","clk":"1009526740","pt":1580666622652,"mc":[{"id":"1.168230754","rc":[{"batl":[[2,2,1817.19]],"ltp":1.95,"tv":13230.48,"id":2263603}]}]}
{"op":"mcm","clk":"1009527220","pt":1580666627247,"mc":[{"id":"1.168230754","rc":[{"trd":[[1.96,1256.03]],"batl":[[0,1.96,17.52]],"ltp":1.96,"tv":13325.05,"id":2263603}],"tv":18309.61}]}
{"op":"mcm","clk":"1009527288","pt":1580666627936,"mc":[{"id":"1.168230754","rc":[{"trd":[[1.95,647.73]],"batb":[[0,1.95,127.42]],"ltp":1.95,"tv":13325.92,"id":2263603}],"tv":18310.48}]}
{"op":"mcm","clk":"1009527938","pt":1580666634075,"mc":[{"id":"1.168230754","rc":[{"trd":[[1.95,653.73]],"batb":[[0,1.95,124.42]],"ltp":1.95,"tv":13331.92,"id":2263603}],"tv":18316.48}]}
{"op":"mcm","clk":"1009528612","pt":1580666640472,"mc":[{"id":"1.168230754","rc":[{"trd":[[1.95,655.73]],"batb":[[0,1.95,123.42]],"ltp":1.95,"tv":13333.93,"id":2263603}],"tv":18318.48}]}
{"op":"mcm","clk":"1009528759","pt":1580666641879,"mc":[{"id":"1.168230754","rc":[{"trd":[[1.95,660.01]],"batb":[[0,1.95,121.27]],"ltp":1.95,"tv":13338.21,"id":2263603}],"tv":18322.76}]}
{"op":"mcm","clk":"1009528998","pt":1580666644058,"mc":[{"id":"1.168230754","rc":[{"trd":[[1.95,727.23]],"batb":[[0,1.95,87.67]],"ltp":1.95,"tv":13405.42,"id":2263603}],"tv":18389.98}]}
{"op":"mcm","clk":"1009529796","pt":1580666651487,"mc":[{"id":"1.168230754","rc":[{"trd":[[1.95,787.23]],"batb":[[0,1.95,57.66]],"ltp":1.95,"tv":13465.43,"id":2263603}],"tv":18449.98}]}
{"op":"mcm","clk":"1009529876","pt":1580666652070,"mc":[{"id":"1.168230754","rc":[{"batl":[[2,2,1816.57]],"ltp":1.95,"tv":13465.43,"id":2263603}]}]}
{"op":"mcm","clk":"1009530246","pt":1580666655577,"mc":[{"id":"1.168230754","rc":[{"trd":[[1.95,789.21]],"batb":[[0,1.95,56.67]],"ltp":1.95,"tv":13467.41,"id":2263603}],"tv":18451.97}]}
{"op":"mcm","clk":"1009530395","pt":1580666656850,"mc":[{"id":"1.168230754","rc":[{"trd":[[1.95,793.6]],"batb":[[0,1.95,54.48]],"ltp":1.95,"tv":13471.8,"id":2263603}],"tv":18456.36}]}
{"op":"mcm","clk":"1009531224","pt":1580666664446,"mc":[{"id":"1.168230754","rc":[{"trd":[[1.96,1256.27]],"batl":[[0,1.96,17.4]],"ltp":1.96,"tv":13472.04,"id":2263603}],"tv":18456.6}]}
{"op":"mcm","clk":"1009531253","pt":1580666664761,"mc":[{"id":"1.168230754","rc":[{"trd":[[1.95,794.49]],"batb":[[0,1.95,54.03]],"ltp":1.95,"tv":13472.93,"id":2263603}],"tv":18457.49}]}
{"op":"mcm","clk":"1009531517","pt":1580666666992,"mc":[{"id":"1.168230754","rc":[{"batl":[[2,2,1816.88]],"ltp":1.95,"tv":13472.93,"id":2263603}]}]}
{"op":"mcm","clk":"1009532058","pt":1580666671760,"mc":[{"id":"1.168230754","rc":[{"trd":[[1.95,818.72]],"batb":[[0,1.95,41.92]],"ltp":1.95,"tv":13497.16,"id":2263603}],"tv":18481.72}]}
{"op":"mcm","clk":"1009532331","pt":1580666674200,"mc":[{"id":"1.168230754","rc":[{"trd":[[1.96,1291.07]],"batb":[[0,1.96,282.6],[1,1.95,41.92],[2,1.94,133.39]],"batl":[[0,1.98,4.01],[1,2,1816.88],[2,2.06,914.97]],"ltp":1.96,"tv":13531.96,"id":2263603}],"tv":18516.52}]}
{"op":"mcm","clk":"1009532806","pt":1580666678277,"mc":[{"id":"1.168230754","rc":[{"trd":[[1.96,1293.42]],"batb":[[0,1.96,281.43]],"ltp":1.96,"tv":13534.31,"id":2263603}],"tv":18518.86}]}
{"op":"mcm","clk":"1009533652","pt":1580666686101,"mc":[{"id":"1.168230754","rc":[{"batb":[[0,1.96,200]],"ltp":1.96,"tv":13534.31,"id":2263603}]}]}
{"op":"mcm","clk":"1009534202","pt":1580666691389,"mc":[{"id":"1.168230754","rc":[{"batl":[[0,2.04,99],[1,2.1,50.41],[2,2.4,22.41]],"ltp":2.04,"tv":4984.55,"id":3622149}]}]}
{"op":"mcm","clk":"1009534780","pt":1580666697529,"mc":[{"id":"1.168230754","rc":[{"trd":[[1.96,1298.32]],"batb":[[0,1.96,197.55]],"ltp":1.96,"tv":13539.2,"id":2263603}],"tv":18523.76}]}
{"op":"mcm","clk":"1009536006","pt":1580666710035,"mc":[{"id":"1.168230754","rc":[{"trd":[[1.96,1298.39]],"batb":[[0,1.96,197.51]],"ltp":1.96,"tv":13539.28,"id":2263603}],"tv":18523.84}]}
{"op":"mcm","clk":"1009536954","pt":1580666719525,"mc":[{"id":"1.168230754","rc":[{"trd":[[1.96,1300.63],[1.97,1010.73],[1.98,630.64],[2,6360.95]],"batb":[[0,1.96,196.39]],"batl":[[0,2,1438.19],[1,2.06,914.97],[2,2.1,12.66]],"ltp":1.96,"tv":13924.22,"id":2263603},{"trd":[[2,1457.27],[2.02,798.61]],"batb":[[0,1.99,239.98],[1,1.97,6.16],[2,1.95,2.63]],"ltp":2.0,"tv":5401.95,"id":3622149}],"tv":19326.17}]}
{"op":"mcm","clk":"1009537024","pt":1580666720218,"mc":[{"id":"1.168230754","rc":[{"batb":[[0,1.96,214.32],[2,1.94,115.15]],"ltp":1.96,"tv":13924.22,"id":2263603},{"batb":[[1,1.98,33.83],[2,1.97,6.16]],"ltp":2.0,"tv":5401.95,"id":3622149}]}]}
{"op":"mcm","clk":"1009537724","pt":1580666728027,"mc":[{"id":"1.168230754","rc":[{"batl":[[0,2,1444.34]],"ltp":1.96,"tv":13924.22,"id":2263603}]}]}
{"op":"mcm","clk":"1009537845","pt":1580666729406,"mc":[{"id":"1.168230754","rc":[{"batl":[[0,2,1451.12]],"ltp":1.96,"tv":13924.22,"id":2263603}]}]}
{"op":"mcm","clk":"1009538036","pt":1580666731319,"mc":[{"id":"1.168230754","rc":[{"batl":[[0,1.99,537.5],[1,2,1456.65],[2,2.06,914.97]],"ltp":1.96,"tv":13924.22,"id":2263603}]}]}
{"op":"mcm","clk":"1009538223","pt":1580666733536,"mc":[{"id":"1.168230754","rc":[{"trd":[[1.96,1305.13]],"batb":[[0,1.96,212.07]],"batl":[[1,2,1468.96]],"ltp":1.96,"tv":13928.72,"id":2263603}],"tv":19330.68}]}
{"op":"mcm","clk":"1009538264","pt":1580666734059,"mc":[{"id":"1.168230754","rc":[{"batl":[[0,1.99,536.88]],"ltp":1.96,"tv":13928.72,"id":2263603}]}]}
{"op":"mcm","clk":"1009538408","pt":1580666735763,"mc":[{"id":"1.168230754","rc":[{"trd":[[1.99,255.48]],"batl":[[0,1.99,486.63]],"ltp":1.99,"tv":13978.97,"id":2263603},{"trd":[[2,1507.27]],"ltp":2.0,"tv":5451.95,"id":3622149}],"tv":19430.93}]}
{"op":"mcm","clk":"1009538736","pt":1580666739163,"mc":[{"id":"1.168230754","rc":[{"trd":[[1.96,1355.13]],"batb":[[0,1.96,187.07]],"ltp":1.96,"tv":14028.97,"id":2263603}],"tv":19480.93}]}
{"op":"mcm","clk":"1009538826","pt":1580666740163,"mc":[{"id":"1.168230754","rc":[{"trd":[[1.96,1358.49]],"batb":[[0,1.96,185.39]],"batl":[[0,1.99,487.25]],"ltp":1.96,"tv":14032.33,"id":2263603}],"tv":19484.28}]}
{"op":"mcm","clk":"1009538914","pt":1580666741165,"mc":[{"id":"1.168230754","rc":[{"batb":[[2,1.94,111.37]],"ltp":1.96,"tv":14032.33,"id":2263603}]}]}
{"op":"mcm","clk":"1009539072","pt":1580666742865,"mc":[{"id":"1.168230754","rc":[{"batl":[[1,2,1468.65]],"ltp":1.96,"tv":14032.33,"id":2263603}]}]}
{"op":"mcm","clk":"1009539312","pt":1580666745362,"mc":[{"id":"1.168230754","rc":[{"batb":[[0,1.96,188.51]],"ltp":1.96,"tv":14032.33,"id":2263603}]}]}
{"op":"mcm","clk":"1009539731","pt":1580666749972,"mc":[{"id":"1.168230754","rc":[{"batb":[[0,1.97,1.32],[1,1.96,188.51],[2,1.95,41.92]],"ltp":1.96,"tv":14032.33,"id":2263603}]}]}
{"op":"mcm","clk":"1009539892","pt":1580666751772,"mc":[{"id":"1.168230754","rc":[{"trd":[[1.99,257.23]],"batl":[[0,1.99,486.38]],"ltp":1.99,"tv":14034.08,"id":2263603}],"tv":19486.03}]}
{"op":"mcm","clk":"1009540372","pt":1580666756971,"mc":[{"id":"1.168230754","rc":[{"trd":[[1.99,617.23]],"batl":[[0,1.99,306.37]],"ltp":1.99,"tv":14394.08,"id":2263603}],"tv":19846.04}]}
{"op":"mcm","clk":"1009541038","pt":1580666763487,"mc":[{"id":"1.168230754","rc":[{"batb":[[0,1.96,188.51],[1,1.95,41.92],[2,1.94,111.37]],"batl":[[0,1.97,5.38],[1,1.99,306.37],[2,2,1468.65]],"ltp":1.99,"tv":14394.08,"id":2263603}]}]}
{"op":"mcm","clk":"1009541440","pt":1580666767493,"mc":[{"id":"1.168230754","rc":[{"batl":[[1,1.99,305.76],[2,2,1437.88]],"ltp":1.99,"tv":14394.08,"id":2263603}]}]}
{"op":"mcm","clk":"1009541534","pt":1580666768288,"mc":[{"id":"1.168230754","rc":[{"batl":[[0,1.97,7.39]],"ltp":1.99,"tv":14394.08,"id":2263603}]}]}
{"op":"mcm","clk":"1009541582","pt":1580666768710,"mc":[{"id":"1.168230754","rc":[{"batl":[[1,1.99,305.95]],"ltp":1.99,"tv":14394.08,"id":2263603}]}]}
{"op":"mcm","clk":"1009541992","pt":1580666772408,"mc":[{"id":"1.168230754","rc":[{"trd":[[1.97,1011.09]],"batl":[[0,1.97,13.36]],"ltp":1.97,"tv":14394.44,"id":2263603},{"trd":[[2.02,798.95]],"ltp":2.02,"tv":5452.3,"id":3622149}],"tv":19846.74}]}
{"op":"mcm","clk":"1009542137","pt":1580666773811,"mc":[{"id":"1.168230754","rc":[{"trd":[[1.97,1013.01]],"batl":[[0,1.97,11.44]],"ltp":1.97,"tv":14396.36,"id":2263603},{"trd":[[2.02,800.82]],"ltp":2.02,"tv":5454.17,"id":3622149}],"tv":19850.53}]}
{"op":"mcm","clk":"1009542364","pt":1580666776048,"mc":[{"id":"1.168230754","rc":[{"trd":[[1.96,1446.49]],"batb":[[0,1.96,144.51]],"batl":[[1,1.99,306.57]],"ltp":1.96,"tv":14484.36,"id":2263603}],"tv":19938.53}]}
{"op":"mcm","clk":"1009542661","pt":1580666778585,"mc":[{"id":"1.168230754","rc":[{"batl":[[1,1.98,1.31],[2,1.99,306.37]],"ltp":1.96,"tv":14484.36,"id":2263603}]}]}
{"op":"mcm","clk":"1009542737","pt":1580666779329,"mc":[{"id":"1.168230754","rc":[{"trd":[[1.97,1035.01]],"batl":[[0,1.98,1.75],[1,1.99,306.37],[2,2,1437.88]],"ltp":1.97,"tv":14506.36,"id":2263603}],"tv":19960.53}]}
{"op":"mcm","clk":"1009544009","pt":1580666790529,"mc":[{"id":"1.168230754","rc":[{"trd":[[1.97,1035.45],[1.98,631.95]],"batl":[[0,1.99,306.37],[1,2,1437.88],[2,2.06,914.97]],"ltp":1.98,"tv":14508.11,"id":2263603},{"trd":[[2.02,802.54]],"batl":[[0,2.02,33.75],[1,2.04,99],[2,2.1,50.41]],"ltp":2.02,"tv":5455.89,"id":3622149}],"tv":19964.0}]}
{"op":"mcm","clk":"1009544106","pt":1580666791400,"mc":[{"id":"1.168230754","rc":[{"trd":[[1.96,1449.71],[1.98,633.68]],"batb":[[0,1.96,142.9]],"ltp":1.96,"tv":14513.07,"id":2263603},{"trd":[[2.02,868.33]],"batl":[[0,2.04,99],[1,2.1,50.41],[2,2.4,22.41]],"ltp":2.02,"tv":5521.68,"id":3622149}],"tv":20034.75}]}
{"op":"mcm","clk":"1009545096","pt":1580666799947,"mc":[{"id":"1.168230754","rc":[{"trd":[[1.96,1489.89]],"batb":[[0,1.96,122.81]],"ltp":1.96,"tv":14553.25,"id":2263603}],"tv":20074.93}]}
{"op":"mcm","clk":"1009545215","pt":1580666800941,"mc":[{"id":"1.168230754","rc":[{"batb":[[1,1.95,724.16]],"ltp":1.96,"tv":14553.25,"id":2263603}]}]}
{"op":"mcm","clk":"1009545380","pt":1580666802424,"mc":[{"id":"1.168230754","rc":[{"batb":[[0,1.97,1.11],[1,1.96,122.81],[2,1.95,724.16]],"ltp":1.96,"tv":14553.25,"id":2263603}]}]}
{"op":"mcm","clk":"1009545700","pt":1580666805329,"mc":[{"id":"1.168230754","rc":[{"batb":[[0,1.97,1.32]],"ltp":1.96,"tv":14553.25,"id":2263603}]}]}
{"op":"mcm","clk":"1009545936","pt":1580666807451,"mc":[{"id":"1.168230754","rc":[{"trd":[[1.99,618.92]],"batb":[[1,1.96,119.69]],"batl":[[0,1.99,304.68]],"ltp":1.99,"tv":14554.93,"id":2263603},{"trd":[[2,1508.95]],"ltp":2.0,"tv":5523.36,"id":3622149}],"tv":20078.3}]}
{"op":"mcm","clk":"1009546688","pt":1580666814377,"mc":[{"id":"1.168230754","rc":[{"trd":[[1.95,1582.62],[1.96,1832.31],[1.97,1038.08]],"batb":[[0,1.95,342.21],[1,1.94,111.37],[2,1.93,420.1]],"ltp":1.95,"tv":15663.87,"id":2263603},{"trd":[[2.04,380.37]],"batl":[[0,2.1,50.41],[1,2.4,22.41],[2,95,16]],"ltp":2.04,"tv":5622.36,"id":3622149}],"tv":21286.24}]}
{"op":"mcm","clk":"1009546807","pt":1580666815358,"mc":[{"id":"1.168230754","rc":[{"batb":[[1,1.94,129.61]],"ltp":1.95,"tv":15663.87,"id":2263603},{"batb":[[0,2.02,17.39],[1,1.99,239.98]],"ltp":2.04,"tv":5622.36,"id":3622149}]}]}
{"op":"mcm","clk":"1009547251","pt":1580666819378,"mc":[{"id":"1.168230754","rc":[{"batl":[[0,1.97,3.65],[1,1.99,304.68],[2,2,1437.88]],"ltp":1.95,"tv":15663.87,"id":2263603}]}]}
{"op":"mcm","clk":"1009547383","pt":1580666820878,"mc":[{"id":"1.168230754","rc":[{"batl":[[0,1.97,5.84]],"ltp":1.95,"tv":15663.87,"id":2263603}]}]}
{"op":"mcm","clk":"1009547792","pt":1580666824545,"mc":[{"id":"1.168230754","rc":[{"batb":[[0,1.95,342.52]],"ltp":1.95,"tv":15663.87,"id":2263603}]}]}
{"op":"mcm","clk":"1009547853","pt":1580666825175,"mc":[{"id":"1.168230754","rc":[{"batb":[[0,1.95,357.07]],"ltp":1.95,"tv":15663.87,"id":2263603},{"trd":[[2.02,896.5]],"batb":[[0,2,19.97]],"ltp":2.02,"tv":5650.53,"id":3622149}],"tv":21314.41}]}
{"op":"mcm","clk":"1009547946","pt":1580666825994,"mc":[{"id":"1.168230754","rc":[{"batl":[[1,1.98,1.31],[2,1.99,304.68]],"ltp":1.95,"tv":15663.87,"id":2263603}]}]}
{"op":"mcm","clk":"1009548256","pt":1580666828763,"mc":[{"id":"1.168230754","rc":[{"trd":[[1.95,1585.1]],"batb":[[0,1.95,355.52]],"ltp":1.95,"tv":15666.36,"id":2263603}],"tv":21316.89}]}
{"op":"mcm","clk":"1009548484","pt":1580666830858,"mc":[{"id":"1.168230754","rc":[{"trd":[[1.95,1589.57]],"batb":[[0,1.95,353.29]],"ltp":1.95,"tv":15670.83,"id":2263603}],"tv":21321.36}]}
{"op":"mcm","clk":"1009548700","pt":1580666832863,"mc":[{"id":"1.168230754","rc":[{"trd":[[1.97,1041.82]],"batl":[[0,1.97,2.1]],"ltp":1.97,"tv":15674.57,"id":2263603},{"trd":[[2.02,900.15]],"ltp":2.02,"tv":5654.17,"id":3622149}],"tv":21328.75}]}
{"op":"mcm","clk":"1009549466","pt":1580666839948,"mc":[{"id":"1.168230754","rc":[{"batl":[[0,1.97,2.33]],"ltp":1.97,"tv":15674.57,"id":2263603}]}]}
{"op":"mcm","clk":"1009549605","pt":1580666841062,"mc":[{"id":"1.168230754","rc":[{"trd":[[1.97,1044.15],[1.98,635]],"batl":[[0,1.99,304.68],[1,2,1437.88],[2,2.06,914.97]],"ltp":1.98,"tv":15678.21,"id":2263603},{"trd":[[2.02,904.75]],"ltp":2.02,"tv":5658.78,"id":3622149}],"tv":21336.99}]}
{"op":"mcm","clk":"1009549880","pt":1580666843880,"mc":[{"id":"1.168230754","rc":[{"trd":[[1.95,1593.95]],"batb":[[0,1.95,351.09]],"ltp":1.95,"tv":15682.6,"id":2263603}],"tv":21341.38}]}
{"op":"mcm","clk":"1009550370","pt":1580666848880,"mc":[{"id":"1.168230754","rc":[{"batl":[[0,1.99,304.99]],"ltp":1.95,"tv":15682.6,"id":2263603}]}]}
{"op":"mcm","clk":"1009550522","pt":1580666850266,"mc":[{"id":"1.168230754","rc":[{"batl":[[1,2,1453.96]],"ltp":1.95,"tv":15682.6,"id":2263603}]}]}
{"op":"mcm","clk":"1009550644","pt":1580666851588,"mc":[{"id":"1.168230754","rc":[{"batb":[[0,1.96,1.29],[1,1.95,351.09],[2,1.94,129.61]],"ltp":1.95,"tv":15682.6,"id":2263603}]}]}
{"op":"mcm","clk":"1009551410","pt":1580666859299,"mc":[{"id":"1.168230754","rc":[{"batb":[[0,1.95,351.51],[1,1.94,129.61],[2,1.93,420.1]],"ltp":1.95,"tv":15682.6,"id":2263603}]}]}
{"op":"mcm","clk":"1009552019","pt":1580666864892,"mc":[{"id":"1.168230754","rc":[{"batb":[[0,1.95,351.09]],"batl":[[0,1.96,2.85],[1,1.99,304.99],[2,2,1453.96]],"ltp":1.95,"tv":15682.6,"id":2263603}]}]}
{"op":"mcm","clk":"1009552117","pt":1580666865915,"mc":[{"id":"1.168230754","rc":[{"trd":[[1.95,1594.71]],"batb":[[0,1.95,350.71]],"ltp":1.95,"tv":15683.36,"id":2263603}],"tv":21342.14}]}
{"op":"mcm","clk":"1009552329","pt":1580666867693,"mc":[{"id":"1.168230754","rc":[{"batl":[[0,1.96,2.65]],"ltp":1.95,"tv":15683.36,"id":2263603}]}]}
{"op":"mcm","clk":"1009552457","pt":1580666868803,"mc":[{"id":"1.168230754","rc":[{"batb":[[0,1.95,353.87]],"ltp":1.95,"tv":15683.36,"id":2263603}]}]}
{"op":"mcm","clk":"1009552806","pt":1580666872106,"mc":[{"id":"1.168230754","rc":[{"trd":[[1.95,1595.13]],"batb":[[0,1.95,353.66]],"ltp":1.95,"tv":15683.78,"id":2263603}],"tv":21342.56}]}
{"op":"mcm","clk":"1009553518","pt":1580666878823,"mc":[{"id":"1.168230754","rc":[{"batb":[[0,1.96,1.74],[1,1.95,353.66],[2,1.94,129.61]],"batl":[[0,1.99,304.99],[1,2,1453.96],[2,2.06,914.97]],"ltp":1.95,"tv":15683.78,"id":2263603}]}]}
{"op":"mcm","clk":"1009553695","pt":1580666880524,"mc":[{"id":"1.168230754","rc":[{"batl":[[0,1.99,305.16]],"ltp":1.95,"tv":15683.78,"id":2263603}]}]}
{"op":"mcm","clk":"1009554108","pt":1580666884403,"mc":[{"id":"1.168230754","rc":[{"batl":[[0,1.98,1.94],[1,1.99,304.68],[2,2,1453.96]],"ltp":1.95,"tv":15683.78,"id":2263603}]}]}
{"op":"mcm","clk":"1009555777","pt":1580666900444,"mc":[{"id":"1.168230754","marketDefinition":{"bspMarket":false,"turnInPlayEnabled":true,"persistenceEnabled":true,"marketBaseRate":5.0,"eventId":"29681775","eventTypeId":"2","numberOfWinners":1,"bettingType":"ODDS","marketType":"MATCH_ODDS","marketTime":"2020-02-02T18:01:00.000Z","suspendTime":"2020-02-02T18:01:00.000Z","bspReconciled":false,"complete":true,"inPlay":true,"crossMatching":true,"runnersVoidable":false,"numberOfActiveRunners":2,"betDelay":3,"status":"OPEN","runners":[{"status":"ACTIVE","sortPriority":1,"id":2263603,"name":"Madison Brengle"},{"status":"ACTIVE","sortPriority":2,"id":3622149,"name":"Stefanie Voegele"}],"regulators":["MR_INT"],"discountAllowed":true,"timezone":"UTC","openDate":"2020-02-02T18:01:00.000Z","version":3150176520,"name":"Match Odds","eventName":"Brengle v Voegele"},"rc":[{"batb":[[0,1.95,3.16],[1,1.72,2.8],[2,1.36,1.99]],"batl":[[0,2,1453.96],[1,2.1,12.66],[2,2.2,12.6]],"ltp":1.95,"tv":15683.78,"id":2263603},{"batb":[[0,1.95,2.63],[1,1.72,2.8],[2,1.71,19.85]],"batl":[[2,1000,0.12]],"ltp":2.02,"tv":5658.78,"id":3622149}]}]}
{"op":"mcm","clk":"1009555828","pt":1580666901286,"mc":[{"id":"1.168230754","rc":[{"batb":[[0,1.72,2.8],[1,1.36,1.99],[2,1.1,8.23]],"ltp":1.95,"tv":15683.78,"id":2263603}]}]}
{"op":"mcm","clk":"1009556806","pt":1580666910642,"mc":[{"id":"1.168230754","rc":[{"batb":[[0,1.96,368.36],[1,1.94,479.87],[2,1.72,2.8]],"batl":[[1,2.04,643.63],[2,2.06,408.86]],"ltp":1.95,"tv":15683.78,"id":2263603}]}]}
{"op":"mcm","clk":"1009556830","pt":1580666910856,"mc":[{"id":"1.168230754","rc":[{"batb":[[0,1.72,2.8],[1,1.36,1.99],[2,1.1,8.23]],"batl":[[1,2.1,12.66],[2,2.2,12.6]],"ltp":1.95,"tv":15683.78,"id":2263603}]}]}
{"op":"mcm","clk":"1009557095","pt":1580666913037,"mc":[{"id":"1.168230754","rc":[{"batb":[[0,1.84,503.35],[1,1.82,587.48],[2,1.72,2.8]],"batl":[[2,2.14,620.79]],"ltp":1.95,"tv":15683.78,"id":2263603}]}]}
{"op":"mcm","clk":"1009557397","pt":1580666916045,"mc":[{"id":"1.168230754","rc":[{"batl":[[0,2,1454.27]],"ltp":1.95,"tv":15683.78,"id":2263603}]}]}
{"op":"mcm","clk":"1009557851","pt":1580666920635,"mc":[{"id":"1.168230754","rc":[{"batb":[[0,1.91,61.48],[1,1.84,503.35],[2,1.82,587.48]],"ltp":1.95,"tv":15683.78,"id":2263603},{"batb":[[1,1.93,82.97],[2,1.72,2.8]],"batl":[[0,2.04,16.89],[1,2.1,50.41],[2,2.4,22.41]],"ltp":2.02,"tv":5658.78,"id":3622149}]}]}
{"op":"mcm","clk":"1009558015","pt":1580666922228,"mc":[{"id":"1.168230754","rc":[{"trd":[[1.96,1833.97]],"batl":[[0,2,1454.44]],"ltp":1.96,"tv":15685.45,"id":2263603},{"trd":[[2.04,381.97]],"batl":[[0,2.04,15.29]],"ltp":2.04,"tv":5660.38,"id":3622149}],"tv":21345.83}]}
{"op":"mcm","clk":"1009558081","pt":1580666922862,"mc":[{"id":"1.168230754","rc":[{"batb":[[1,1.72,2.8],[2,1.36,1.99]],"batl":[[2,2.2,12.6]],"ltp":1.96,"tv":15685.45,"id":2263603}]}]}
{"op":"mcm","clk":"1009558277","pt":1580666924647,"mc":[{"id":"1.168230754","rc":[{"trd":[[1.99,619.4],[2,6361.58]],"batb":[[2,1.4,75.73]],"batl":[[0,2,1453.34]],"ltp":2.0,"tv":15686.54,"id":2263603},{"trd":[[2,1510.05]],"ltp":2.0,"tv":5661.48,"id":3622149}],"tv":21348.03}]}
{"op":"mcm","clk":"1009558357","pt":1580666925551,"mc":[{"id":"1.168230754","rc":[{"trd":[[2,7814.92]],"batb":[[0,2,450],[1,1.91,61.48],[2,1.72,2.8]],"batl":[[0,2.1,12.66],[1,2.2,12.6],[2,2.5,8.4]],"ltp":2.0,"tv":17139.89,"id":2263603},{"trd":[[1.95,8.81],[2,2963.33]],"batb":[[0,1.93,82.97],[1,1.72,2.8],[2,1.71,19.85]],"batl":[[0,1.95,309.2],[1,2.04,15.29],[2,2.1,50.41]],"ltp":1.95,"tv":7120.03,"id":3622149}],"tv":24259.92}]}
{"op":"mcm","clk":"1009558456","pt":1580666926557,"mc":[{"id":"1.168230754","rc":[{"batb":[[0,2,1800]],"ltp":2.0,"tv":17139.89,"id":2263603},{"batb":[[1,1.89,363.26],[2,1.87,538.34]],"batl":[[0,1.95,355.92],[1,1.97,466.7],[2,2.04,15.29]],"ltp":1.95,"tv":7120.03,"id":3622149}]}]}
{"op":"mcm","clk":"1009558525","pt":1580666927252,"mc":[{"id":"1.168230754","rc":[{"batb":[[0,2.02,228.57],[1,1.93,132.74],[2,1.91,61.48]],"ltp":2.0,"tv":17139.89,"id":2263603},{"batb":[[2,1.88,142.73]],"ltp":1.95,"tv":7120.03,"id":3622149}]}]}
{"op":"mcm","clk":"1009558685","pt":1580666928631,"mc":[{"id":"1.168230754","rc":[{"trd":[[1.95,83.97]],"batl":[[0,1.95,318.34]],"ltp":1.95,"tv":7195.19,"id":3622149}],"tv":24335.08}]}
{"op":"mcm","clk":"1009559056","pt":1580666932273,"mc":[{"id":"1.168230754","rc":[{"batb":[[2,1.72,2.8]],"ltp":2.0,"tv":17139.89,"id":2263603},{"batb":[[0,1.89,363.26],[1,1.88,142.73],[2,1.87,538.34]],"ltp":1.95,"tv":7195.19,"id":3622149}]}]}
{"op":"mcm","clk":"1009559402","pt":1580666935454,"mc":[{"id":"1.168230754","rc":[{"trd":[[1.95,93.24]],"batl":[[0,1.95,313.71]],"ltp":1.95,"tv":7204.45,"id":3622149}],"tv":24344.34}]}
{"op":"mcm","clk":"1009559496","pt":1580666936249,"mc":[{"id":"1.168230754","rc":[{"batb":[[0,1.93,132.74],[1,1.72,2.8],[2,1.5,113.58]],"ltp":2.0,"tv":17139.89,"id":2263603},{"batb":[[1,1.87,538.34],[2,1.78,169.66]],"ltp":1.95,"tv":7204.45,"id":3622149}]}]}
{"op":"mcm","clk":"1009559657","pt":1580666937582,"mc":[{"id":"1.168230754","rc":[{"batb":[[0,1.78,169.66],[1,1.72,2.7],[2,1.71,19.85]],"batl":[[0,1.93,45.88],[1,2.04,15.29],[2,2.1,50.41]],"ltp":1.95,"tv":7204.45,"id":3622149}]}]}
{"op":"mcm","clk":"1009559672","pt":1580666937697,"mc":[{"id":"1.168230754","rc":[{"batl":[[0,1.93,44.59]],"ltp":1.95,"tv":7204.45,"id":3622149}]}]}
{"op":"mcm","clk":"1009559868","pt":1580666939444,"mc":[{"id":"1.168230754","rc":[{"trd":[[2.06,1.1]],"ltp":2.06,"tv":17140.98,"id":2263603},{"trd":[[1.93,1.17]],"batb":[[0,1.91,20],[1,1.78,169.66],[2,1.72,2.7]],"batl":[[0,1.93,43.42]],"ltp":1.93,"tv":7205.62,"id":3622149}],"tv":24346.61}]}
{"op":"mcm","clk":"1009559974","pt":1580666940445,"mc":[{"id":"1.168230754","rc":[{"trd":[[2.06,3.24]],"ltp":2.06,"tv":17143.12,"id":2263603},{"trd":[[1.93,7.74]],"batl":[[0,1.93,30.47]],"ltp":1.93,"tv":7212.19,"id":3622149}],"tv":24355.31}]}
{"op":"mcm","clk":"1009560087","pt":1580666941460,"mc":[{"id":"1.168230754","rc":[{"batb":[[0,1.94,700],[1,1.93,132.74],[2,1.72,2.8]],"ltp":2.06,"tv":17143.12,"id":2263603},{"trd":[[1.91,40],[1.93,11.74]],"batb":[[0,1.78,169.66],[1,1.72,2.7],[2,1.71,19.85]],"batl":[[0,1.93,42.55]],"ltp":1.93,"tv":7256.19,"id":3622149}],"tv":24399.32}]}
{"op":"mcm","clk":"1009560209","pt":1580666942564,"mc":[{"id":"1.168230754","rc":[{"trd":[[1.99,637.85],[2.06,43.11]],"batb":[[0,1.94,1110.6],[2,1.92,495.54]],"batl":[[0,2.02,648.75],[1,2.04,420.66],[2,2.06,17.85]],"ltp":1.99,"tv":17201.44,"id":2263603},{"trd":[[1.93,54.29],[2,2969.45]],"batl":[[0,2.04,544.67],[1,2.1,50.41],[2,2.4,22.41]],"ltp":2.0,"tv":7304.86,"id":3622149}],"tv":24506.31}]}
{"op":"mcm","clk":"1009560328","pt":1580666943594,"mc":[{"id":"1.168230754","rc":[{"batl":[[2,2.06,30.16]],"ltp":1.99,"tv":17201.44,"id":2263603},{"trd":[[1.98,2598.75]],"batb":[[0,1.98,195.53],[1,1.93,64.95],[2,1.87,146.74]],"ltp":1.98,"tv":7406.19,"id":3622149}],"tv":24607.64}]}
{"op":"mcm","clk":"1009560458","pt":1580666944648,"mc":[{"id":"1.168230754","rc":[{"batl":[[2,2.06,36.31]],"ltp":1.99,"tv":17201.44,"id":2263603},{"batb":[[1,1.93,90.41]],"ltp":1.98,"tv":7406.19,"id":3622149}]}]}
{"op":"mcm","clk":"1009560574","pt":1580666945643,"mc":[{"id":"1.168230754","rc":[{"batb":[[1,1.93,90.85]],"ltp":1.98,"tv":7406.19,"id":3622149}]}]}
{"op":"mcm","clk":"1009560688","pt":1580666946584,"mc":[{"id":"1.168230754","rc":[{"batl":[[1,2.04,420.88]],"ltp":1.99,"tv":17201.44,"id":2263603},{"trd":[[1.98,2643.97]],"batb":[[0,1.98,172.92],[1,1.93,25.89]],"ltp":1.98,"tv":7451.41,"id":3622149}],"tv":24652.86}]}
{"op":"mcm","clk":"1009560770","pt":1580666947275,"mc":[{"id":"1.168230754","rc":[{"trd":[[1.98,2647.97]],"batb":[[0,1.98,170.92],[1,1.87,147.18],[2,1.72,2.8]],"ltp":1.98,"tv":7455.41,"id":3622149}],"tv":24656.86}]}
{"op":"mcm","clk":"1009560875","pt":1580666948279,"mc":[{"id":"1.168230754","rc":[{"batl":[[2,2.06,11.7]],"ltp":1.99,"tv":17201.44,"id":2263603},{"batl":[[2,2.32,1.66]],"ltp":1.98,"tv":7455.41,"id":3622149}]}]}
{"op":"mcm","clk":"1009561132","pt":1580666950365,"mc":[{"id":"1.168230754","rc":[{"trd":[[2.04,384.51]],"batb":[[1,1.87,146.74]],"batl":[[0,2.04,543.4]],"ltp":2.04,"tv":7457.95,"id":3622149}],"tv":24659.4}]}
{"op":"mcm","clk":"1009561285","pt":1580666951476,"mc":[{"id":"1.168230754","rc":[{"batb":[[0,1.94,700],[1,1.83,157.68],[2,1.72,2.8]],"batl":[[0,2.1,12.66],[1,2.2,12.6],[2,2.5,8.4]],"ltp":1.99,"tv":17201.44,"id":2263603},{"batb":[[0,1.87,146.74],[1,1.72,2.8],[2,1.71,19.85]],"batl":[[0,2.04,14.02]],"ltp":2.04,"tv":7457.95,"id":3622149}]}]}
{"op":"mcm","clk":"1009561328","pt":1580666951788,"mc":[{"id":"1.168230754","rc":[{"batl":[[0,2.04,2.36],[1,2.1,12.66],[2,2.2,12.6]],"ltp":1.99,"tv":17201.44,"id":2263603}]}]}
{"op":"mcm","clk":"1009561515","pt":1580666953577,"mc":[{"id":"1.168230754","rc":[{"trd":[[1.96,1835.84],[2.02,2618.1],[2.04,2.07]],"batl":[[0,2.1,13.41],[1,2.2,12.6],[2,2.5,8.4]],"ltp":1.96,"tv":17206.57,"id":2263603},{"trd":[[1.96,21.21],[1.98,2649.65],[2.04,386.31]],"batl":[[0,2.04,12.22]],"ltp":2.04,"tv":7463.11,"id":3622149}],"tv":24669.68}]}
{"op":"mcm","clk":"1009561625","pt":1580666954487,"mc":[{"id":"1.168230754","rc":[{"batb":[[0,2.02,1.11],[1,1.85,156.34],[2,1.83,528.13]],"batl":[[1,2.16,569.35],[2,2.18,347.71]],"ltp":1.96,"tv":17206.57,"id":2263603},{"batb":[[0,1.86,148.08]],"ltp":2.04,"tv":7463.11,"id":3622149}]}]}
{"op":"mcm","clk":"1009561715","pt":1580666955391,"mc":[{"id":"1.168230754","rc":[{"batb":[[2,1.72,2.8]],"batl":[[1,2.2,12.6],[2,2.5,8.4]],"ltp":1.96,"tv":17206.57,"id":2263603},{"batl":[[0,1.98,4.78],[1,2.04,12.22],[2,2.1,50.41]],"ltp":2.04,"tv":7463.11,"id":3622149}]}]}
{"op":"mcm","clk":"1009562052","pt":1580666958196,"mc":[{"id":"1.168230754","rc":[{"batb":[[0,1.85,157.05],[1,1.72,2.8],[2,1.5,113.58]],"ltp":1.96,"tv":17206.57,"id":2263603}]}]}
{"op":"mcm","clk":"1009562186","pt":1580666959464,"mc":[{"id":"1.168230754","rc":[{"trd":[[2.02,2620.46]],"batb":[[0,1.88,700],[1,1.85,156.34],[2,1.72,2.8]],"ltp":2.02,"tv":17208.93,"id":2263603},{"trd":[[1.98,2652.06]],"batl":[[0,2.04,12.22],[1,2.1,50.41],[2,2.32,1.66]],"ltp":1.98,"tv":7465.51,"id":3622149}],"tv":24674.45}]}
{"op":"mcm","clk":"1009562250","pt":1580666960197,"mc":[{"id":"1.168230754","rc":[{"trd":[[1.96,1836.72]],"ltp":1.96,"tv":17209.81,"id":2263603},{"trd":[[2.04,387.15]],"batl":[[0,1.98,2.19],[1,2.04,11.38],[2,2.1,50.41]],"ltp":2.04,"tv":7466.36,"id":3622149}],"tv":24676.17}]}
{"op":"mcm","clk":"1009562378","pt":1580666961589,"mc":[{"id":"1.168230754","rc":[{"batl":[[0,1.97,20],[1,1.98,2.19],[2,2.04,11.38]],"ltp":2.04,"tv":7466.36,"id":3622149}]}]}
{"op":"mcm","clk":"1009562667","pt":1580666964584,"mc":[{"id":"1.168230754","rc":[{"trd":[[1.97,28.44]],"batl":[[0,1.97,18]],"ltp":1.97,"tv":7470.36,"id":3622149}],"tv":24680.18}]}
{"op":"mcm","clk":"1009562742","pt":1580666965279,"mc":[{"id":"1.168230754","rc":[{"trd":[[2.02,2620.68]],"batb":[[2,1.83,528.35]],"batl":[[1,2.16,569.17],[2,2.18,347.71]],"ltp":2.02,"tv":17210.04,"id":2263603},{"trd":[[1.97,28.67]],"batl":[[0,1.97,17.77]],"ltp":1.97,"tv":7470.59,"id":3622149}],"tv":24680.63}]}
{"op":"mcm","clk":"1009562794","pt":1580666965795,"mc":[{"id":"1.168230754","rc":[{"trd":[[2.04,2.81]],"batl":[[0,2.1,12.66]],"ltp":2.04,"tv":17210.78,"id":2263603},{"trd":[[1.96,21.99]],"batl":[[0,1.97,18.53]],"ltp":1.96,"tv":7471.37,"id":3622149}],"tv":24682.15}]}
{"op":"mcm","clk":"1009563132","pt":1580666969086,"mc":[{"id":"1.168230754","rc":[{"batb":[[2,1.71,37.87]],"ltp":1.96,"tv":7471.37,"id":3622149}]}]}
{"op":"mcm","clk":"1009563227","pt":1580666970192,"mc":[{"id":"1.168230754","rc":[{"batb":[[0,1.85,156.34],[1,1.83,528.35],[2,1.81,598.16]],"ltp":2.04,"tv":17210.78,"id":2263603}]}]}
{"op":"mcm","clk":"1009563343","pt":1580666971492,"mc":[{"id":"1.168230754","rc":[{"trd":[[2.04,2.97],[2.1,9.12]],"batb":[[1,1.72,2.8],[2,1.5,113.58]],"batl":[[0,2.1,3.54],[1,2.2,12.6],[2,2.5,8.4]],"ltp":2.04,"tv":17220.06,"id":2263603},{"trd":[[1.9,10.09],[1.95,93.4]],"batl":[[0,1.97,18.36]],"ltp":1.95,"tv":7481.62,"id":3622149}],"tv":24701.68}]}
{"op":"mcm","clk":"1009563514","pt":1580666973294,"mc":[{"id":"1.168230754","rc":[{"batb":[[2,1.4,75.73]],"ltp":2.04,"tv":17220.06,"id":2263603},{"trd":[[1.95,94.58],[1.97,64.21],[1.98,2656.45]],"batb":[[0,2.02,429.45],[1,1.86,148.08],[2,1.72,2.8]],"batl":[[0,2.04,11.38],[1,2.1,50.41],[2,2.32,1.66]],"ltp":1.98,"tv":7522.73,"id":3622149}],"tv":24742.79}]}
{"op":"mcm","clk":"1009563615","pt":1580666974494,"mc":[{"id":"1.168230754","rc":[{"trd":[[1.9,167.64],[1.96,1848.56]],"batb":[[0,1.86,458.24],[1,1.85,156.34],[2,1.83,2459.02]],"batl":[[0,1.9,2312.7],[1,1.92,16.1],[2,2.04,1282.87]],"ltp":1.9,"tv":17287.62,"id":2263603},{"trd":[[2.04,398.53],[2.1,50.41]],"batb":[[0,1.86,148.36],[1,1.72,2.8],[2,1.71,37.87]],"batl":[[0,2.16,10.8],[1,2.32,1.66],[2,2.4,22.41]],"ltp":2.1,"tv":7584.52,"id":3622149}],"tv":24872.14}]}
{"op":"mcm","clk":"1009563710","pt":1580666975617,"mc":[{"id":"1.168230754","rc":[{"trd":[[1.9,168.13]],"batb":[[2,1.83,2987.37]],"batl":[[0,1.9,2895.74],[1,1.92,520.37]],"ltp":1.9,"tv":17288.11,"id":2263603},{"trd":[[2.1,50.85]],"batb":[[0,2.08,208.03],[1,1.96,251.59],[2,1.72,2.8]],"ltp":2.1,"tv":7584.96,"id":3622149}],"tv":24873.07}]}
{"op":"mcm","clk":"1009563764","pt":1580666976101,"mc":[{"id":"1.168230754","rc":[{"batb":[[1,2.02,55.01],[2,1.96,251.59]],"ltp":2.1,"tv":7584.96,"id":3622149}]}]}
{"op":"mcm","clk":"1009563977","pt":1580666978409,"mc":[{"id":"1.168230754","rc":[{"batb":[[1,1.96,251.59],[2,1.72,2.8]],"ltp":2.1,"tv":7584.96,"id":3622149}]}]}
{"op":"mcm","clk":"1009564005","pt":1580666978815,"mc":[{"id":"1.168230754","rc":[{"trd":[[1.9,210.53]],"batl":[[0,1.9,2874.54]],"ltp":1.9,"tv":17330.51,"id":2263603}],"tv":24915.47}]}
{"op":"mcm","clk":"1009564333","pt":1580666982194,"mc":[{"id":"1.168230754","rc":[{"trd":[[1.9,238.39]],"batl":[[0,1.9,2846.68]],"ltp":1.9,"tv":17358.37,"id":2263603},{"trd":[[2.1,76.06]],"ltp":2.1,"tv":7610.17,"id":3622149}],"tv":24968.54}]}
{"op":"mcm","clk":"1009564404","pt":1580666982993,"mc":[{"id":"1.168230754","rc":[{"trd":[[1.9,245.82]],"batl":[[0,1.9,2839.25],[2,1.95,9.65]],"ltp":1.9,"tv":17365.8,"id":2263603},{"trd":[[2.1,82.78]],"ltp":2.1,"tv":7616.89,"id":3622149}],"tv":24982.69}]}
{"op":"mcm","clk":"1009564514","pt":1580666984400,"mc":[{"id":"1.168230754","rc":[{"trd":[[1.9,248.02]],"batl":[[0,1.9,2838.15]],"ltp":1.9,"tv":17367.99,"id":2263603}],"tv":24984.89}]}
{"op":"mcm","clk":"1009564630","pt":1580666985615,"mc":[{"id":"1.168230754","rc":[{"trd":[[1.9,308.81]],"batb":[[0,1.85,156.34],[1,1.83,528.35],[2,1.81,598.16]],"batl":[[0,1.9,522.74],[1,1.92,504.27]],"ltp":1.9,"tv":17428.78,"id":2263603},{"trd":[[2.1,137.78]],"batl":[[0,2.32,1.66],[1,2.4,22.41],[2,1000,0.12]],"ltp":2.1,"tv":7671.89,"id":3622149}],"tv":25100.68}]}
{"op":"mcm","clk":"1009564665","pt":1580666986035,"mc":[{"id":"1.168230754","rc":[{"trd":[[1.9,309.8]],"batb":[[0,1.76,182.7],[1,1.72,2.8],[2,1.4,75.73]],"batl":[[0,1.95,9.65],[1,2.1,3.54],[2,2.2,12.6]],"ltp":1.9,"tv":17429.78,"id":2263603},{"batb":[[0,1.96,251.59],[1,1.72,2.8],[2,1.71,37.87]],"ltp":2.1,"tv":7671.89,"id":3622149}],"tv":25101.67}]}
{"op":"mcm","clk":"1009564752","pt":1580666986988,"mc":[{"id":"1.168230754","rc":[{"batl":[[0,1.95,9.66],[1,1.96,28.88],[2,2.1,3.54]],"ltp":1.9,"tv":17429.78,"id":2263603}]}]}
{"op":"mcm","clk":"1009564906","pt":1580666988609,"mc":[{"id":"1.168230754","rc":[{"trd":[[1.86,0.01]],"batl":[[0,1.95,9.65],[2,2.08,3.79]],"ltp":1.86,"tv":17429.79,"id":2263603},{"trd":[[2.16,0.01]],"batl":[[0,2.1,4.18],[1,2.32,1.66],[2,2.4,22.41]],"ltp":2.16,"tv":7671.9,"id":3622149}],"tv":25101.69}]}
{"op":"mcm","clk":"1009565067","pt":1580666990298,"mc":[{"id":"1.168230754","rc":[{"batb":[[0,1.77,700],[1,1.76,182.7],[2,1.72,2.8]],"ltp":1.86,"tv":17429.79,"id":2263603}]}]}
{"op":"mcm","clk":"1009565136","pt":1580666990941,"mc":[{"id":"1.168230754","rc":[{"trd":[[1.9,310.7]],"batb":[[2,1.74,582.47]],"batl":[[2,2.02,496.08]],"ltp":1.9,"tv":17430.68,"id":2263603},{"trd":[[2.1,138.59]],"batl":[[0,2.1,3.37]],"ltp":2.1,"tv":7672.7,"id":3622149}],"tv":25103.39}]}
{"op":"mcm","clk":"1009565281","pt":1580666992087,"mc":[{"id":"1.168230754","rc":[{"trd":[[1.9,311.59]],"ltp":1.9,"tv":17431.57,"id":2263603},{"trd":[[2.1,139.39]],"batl":[[0,2.1,2.57]],"ltp":2.1,"tv":7673.51,"id":3622149}],"tv":25105.09}]}
{"op":"mcm","clk":"1009565409","pt":1580666993407,"mc":[{"id":"1.168230754","rc":[{"trd":[[1.95,1604.78],[1.96,1877.44]],"batb":[[2,1.72,2.8]],"batl":[[0,2.02,496.08],[1,2.04,420.66],[2,2.08,3.79]],"ltp":1.96,"tv":17470.1,"id":2263603},{"trd":[[2.04,435.5]],"batl":[[0,2.04,165.69],[1,2.1,2.35],[2,2.32,1.66]],"ltp":2.04,"tv":7710.48,"id":3622149}],"tv":25180.58}]}
{"op":"mcm","clk":"1009565466","pt":1580666994005,"mc":[{"id":"1.168230754","rc":[{"trd":[[1.96,1879.45]],"ltp":1.96,"tv":17472.11,"id":2263603},{"trd":[[2.04,437.43]],"batl":[[0,2.04,163.75]],"ltp":2.04,"tv":7712.41,"id":3622149}],"tv":25184.52}]}
{"op":"mcm","clk":"1009565628","pt":1580666995620,"mc":[{"id":"1.168230754","rc":[{"batb":[[0,1.9,2.19],[1,1.77,700],[2,1.76,182.7]],"ltp":1.96,"tv":17472.11,"id":2263603},{"batl":[[1,2.1,3.69]],"ltp":2.04,"tv":7712.41,"id":3622149}]}]}
{"op":"mcm","clk":"1009565694","pt":1580666996328,"mc":[{"id":"1.168230754","rc":[{"batb":[[0,2,4.01],[1,1.94,1019.63],[2,1.92,495.58]],"batl":[[1,2.04,428.81]],"ltp":1.96,"tv":17472.11,"id":2263603},{"batl":[[0,2,4.01],[1,2.02,510.85],[2,2.04,163.75]],"ltp":2.04,"tv":7712.41,"id":3622149}]}]}
{"op":"mcm","clk":"1009565762","pt":1580666997152,"mc":[{"id":"1.168230754","rc":[{"batb":[[1,1.96,130.06],[2,1.94,569.63]],"ltp":1.96,"tv":17472.11,"id":2263603},{"batb":[[1,1.83,157.29],[2,1.72,2.8]],"ltp":2.04,"tv":7712.41,"id":3622149}]}]}
{"op":"mcm","clk":"1009565904","pt":1580666998602,"mc":[{"id":"1.168230754","rc":[{"trd":[[2,7821.44]],"batb":[[0,1.96,130.81],[1,1.94,569.63],[2,1.92,495.58]],"ltp":2.0,"tv":17478.63,"id":2263603}],"tv":25191.05}]}
{"op":"mcm","clk":"1009566008","pt":1580666999612,"mc":[{"id":"1.168230754","rc":[{"trd":[[1.98,637.18],[2,7826.95]],"batb":[[0,1.96,130.06]],"ltp":1.98,"tv":17486.33,"id":2263603},{"trd":[[2,2973.46],[2.02,906.89]],"batl":[[0,2.02,508.71],[1,2.04,172.16],[2,2.1,3.69]],"ltp":2.02,"tv":7718.56,"id":3622149}],"tv":25204.89}]}
{"op":"mcm","clk":"1009566057","pt":1580667000130,"mc":[{"id":"1.168230754","rc":[{"trd":[[1.98,1071.18]],"ltp":1.98,"tv":17920.33,"id":2263603},{"trd":[[2.02,1332.3]],"batl":[[0,2.02,83.3]],"ltp":2.02,"tv":8143.97,"id":3622149}],"tv":26064.3}]}
{"op":"mcm","clk":"1009566196","pt":1580667001408,"mc":[{"id":"1.168230754","rc":[{"trd":[[1.98,1071.37]],"ltp":1.98,"tv":17920.52,"id":2263603},{"trd":[[2.02,1332.48]],"batl":[[0,2.02,83.12]],"ltp":2.02,"tv":8144.15,"id":3622149}],"tv":26064.67}]}
{"op":"mcm","clk":"1009566229","pt":1580667001717,"mc":[{"id":"1.168230754","rc":[{"batl":[[2,2.1,1.34]],"ltp":2.02,"tv":8144.15,"id":3622149}]}]}
{"op":"mcm","clk":"1009566346","pt":1580667002835,"mc":[{"id":"1.168230754","rc":[{"batb":[[0,1.96,251.31]],"ltp":2.02,"tv":8144.15,"id":3622149}]}]}
{"op":"mcm","clk":"1009566540","pt":1580667004644,"mc":[{"id":"1.168230754","rc":[{"batb":[[0,1.9,2.19],[1,1.84,159.33],[2,1.72,2.8]],"batl":[[0,2.08,3.79],[1,2.1,3.54],[2,2.2,12.6]],"ltp":1.98,"tv":17920.52,"id":2263603},{"batb":[[0,1.83,157.29],[1,1.72,2.8],[2,1.71,37.87]],"batl":[[0,2.04,172.16],[1,2.1,1.34],[2,2.32,1.66]],"ltp":2.02,"tv":8144.15,"id":3622149}]}]}
{"op":"mcm","clk":"1009566862","pt":1580667007629,"mc":[{"id":"1.168230754","rc":[{"batb":[[2,1.81,576.15]],"batl":[[2,2.2,475.2]],"ltp":1.98,"tv":17920.52,"id":2263603}]}]}
{"op":"mcm","clk":"1009566876","pt":1580667007737,"mc":[{"id":"1.168230754","rc":[{"batl":[[0,1.98,2.29],[1,2.04,172.16],[2,2.1,1.34]],"ltp":2.02,"tv":8144.15,"id":3622149}]}]}
{"op":"mcm","clk":"1009567058","pt":1580667009538,"mc":[{"id":"1.168230754","rc":[{"trd":[[2.02,2620.99]],"ltp":2.02,"tv":17920.82,"id":2263603},{"trd":[[1.98,2656.76]],"batl":[[0,1.98,1.98]],"ltp":1.98,"tv":8144.46,"id":3622149}],"tv":26065.29}]}
{"op":"mcm","clk":"1009567210","pt":1580667011023,"mc":[{"id":"1.168230754","rc":[{"batl":[[0,1.98,9.52]],"ltp":1.98,"tv":8144.46,"id":3622149}]}]}
{"op":"mcm","clk":"1009567370","pt":1580667012553,"mc":[{"id":"1.168230754","rc":[{"trd":[[2.02,2621.43]],"batb":[[0,2.02,14.78],[1,1.9,2.19],[2,1.84,159.33]],"ltp":2.02,"tv":17921.26,"id":2263603},{"batl":[[0,1.98,7.55]],"ltp":1.98,"tv":8144.46,"id":3622149}],"tv":26065.73}]}
{"op":"mcm","clk":"1009567460","pt":1580667013448,"mc":[{"id":"1.168230754","rc":[{"batl":[[0,1.98,15.88]],"ltp":1.98,"tv":8144.46,"id":3622149}]}]}
{"op":"mcm","clk":"1009567488","pt":1580667013719,"mc":[{"id":"1.168230754","rc":[{"batb":[[0,1.9,2.19],[1,1.84,159.33],[2,1.81,576.15]],"ltp":2.02,"tv":17921.26,"id":2263603}]}]}
{"op":"mcm","clk":"1009567585","pt":1580667014722,"mc":[{"id":"1.168230754","rc":[{"trd":[[1.98,2673.56]],"batl":[[0,1.98,7.48]],"ltp":1.98,"tv":8161.27,"id":3622149}],"tv":26082.53}]}
{"op":"mcm","clk":"1009567676","pt":1580667015830,"mc":[{"id":"1.168230754","rc":[{"trd":[[1.96,1896.49],[2.02,2628.76]],"ltp":1.96,"tv":17945.64,"id":2263603},{"trd":[[1.98,2681.04],[2.04,453.81]],"batl":[[0,2.04,155.78],[1,2.1,1.34],[2,2.32,1.66]],"ltp":2.04,"tv":8185.13,"id":3622149}],"tv":26130.78}]}
{"op":"mcm","clk":"1009567782","pt":1580667016935,"mc":[{"id":"1.168230754","rc":[{"batb":[[0,1.84,159.33],[1,1.81,576.15],[2,1.79,620.42]],"ltp":1.96,"tv":17945.64,"id":2263603}]}]}
{"op":"mcm","clk":"1009567936","pt":1580667018632,"mc":[{"id":"1.168230754","rc":[{"trd":[[2.08,2.17]],"batl":[[0,2.08,1.62]],"ltp":2.08,"tv":17947.81,"id":2263603},{"trd":[[1.92,2.35]],"ltp":1.92,"tv":8187.48,"id":3622149}],"tv":26135.29}]}
{"op":"mcm","clk":"1009567976","pt":1580667019151,"mc":[{"id":"1.168230754","rc":[{"batb":[[0,1.83,157.5]],"ltp":1.92,"tv":8187.48,"id":3622149}]}]}
{"op":"mcm","clk":"1009568139","pt":1580667020644,"mc":[{"id":"1.168230754","rc":[{"trd":[[2.08,3.79]],"batb":[[0,2.08,20],[1,1.84,159.33],[2,1.81,576.15]],"batl":[[0,2.1,3.54],[1,2.2,475.2],[2,2.22,330.33]],"ltp":2.08,"tv":17949.43,"id":2263603},{"trd":[[1.92,4.11],[1.98,2690.26]],"batb":[[0,1.83,157.29]],"batl":[[0,1.92,5.63],[1,2.04,155.78],[2,2.1,1.34]],"ltp":1.92,"tv":8198.45,"id":3622149}],"tv":26147.89}]}
{"op":"mcm","clk":"1009568378","pt":1580667022966,"mc":[{"id":"1.168230754","rc":[{"trd":[[2.08,5.79]],"batb":[[0,2.08,19]],"ltp":2.08,"tv":17951.43,"id":2263603}],"tv":26149.89}]}
{"op":"mcm","clk":"1009568547","pt":1580667024662,"mc":[{"id":"1.168230754","rc":[{"batb":[[0,1.84,159.33],[1,1.81,576.15],[2,1.79,620.42]],"ltp":2.08,"tv":17951.43,"id":2263603}]}]}
