{"op":"mcm","clk":"1001501051","pt":1580587070468,"mc":[{"id":"1.168230757","marketDefinition":{"bspMarket":false,"turnInPlayEnabled":true,"persistenceEnabled":true,"marketBaseRate":5.0,"eventId":"29681775","eventTypeId":"2","numberOfWinners":1,"bettingType":"ODDS","marketType":"SET_WINNER","marketTime":"2020-02-02T18:00:00.000Z","suspendTime":"2020-02-02T18:00:00.000Z","bspReconciled":false,"complete":true,"inPlay":false,"crossMatching":false,"runnersVoidable":false,"numberOfActiveRunners":2,"betDelay":0,"status":"OPEN","runners":[{"status":"ACTIVE","sortPriority":1,"id":2263603,"name":"Madison Brengle"},{"status":"ACTIVE","sortPriority":2,"id":3622149,"name":"Stefanie Voegele"}],"regulators":["MR_INT"],"discountAllowed":false,"timezone":"UTC","openDate":"2020-02-02T18:00:00.000Z","version":3147219549,"name":"Set 1 Winner","eventName":"Brengle v Voegele"}}]}
{"op":"mcm","clk":"1001501273","pt":1580587071655,"mc":[{"id":"1.168230757","marketDefinition":{"bspMarket":false,"turnInPlayEnabled":true,"persistenceEnabled":true,"marketBaseRate":5.0,"eventId":"29681775","eventTypeId":"2","numberOfWinners":1,"bettingType":"ODDS","marketType":"SET_WINNER","marketTime":"2020-02-02T18:00:00.000Z","suspendTime":"2020-02-02T18:00:00.000Z","bspReconciled":false,"complete":true,"inPlay":false,"crossMatching":false,"runnersVoidable":false,"numberOfActiveRunners":2,"betDelay":0,"status":"OPEN","runners":[{"status":"ACTIVE","sortPriority":1,"id":2263603,"name":"Madison Brengle"},{"status":"ACTIVE","sortPriority":2,"id":3622149,"name":"Stefanie Voegele"}],"regulators":["MR_INT"],"discountAllowed":false,"timezone":"UTC","openDate":"2020-02-02T18:00:00.000Z","version":3147219549,"name":"Set 1 Winner","eventName":"Brengle v Voegele"}}]}
{"op":"mcm","clk":"1001501657","pt":1580587073688,"mc":[{"id":"1.168230757","marketDefinition":{"bspMarket":false,"turnInPlayEnabled":true,"persistenceEnabled":true,"marketBaseRate":5.0,"eventId":"29681775","eventTypeId":"2","numberOfWinners":1,"bettingType":"ODDS","marketType":"SET_WINNER","marketTime":"2020-02-02T18:00:00.000Z","suspendTime":"2020-02-02T18:00:00.000Z","bspReconciled":false,"complete":true,"inPlay":false,"crossMatching":false,"runnersVoidable":false,"numberOfActiveRunners":2,"betDelay":0,"status":"OPEN","runners":[{"status":"ACTIVE","sortPriority":1,"id":2263603,"name":"Madison Brengle"},{"status":"ACTIVE","sortPriority":2,"id":3622149,"name":"Stefanie Voegele"}],"regulators":["MR_INT"],"discountAllowed":true,"timezone":"UTC","openDate":"2020-02-02T18:00:00.000Z","version":3147219549,"name":"Set 1 Winner","eventName":"Brengle v Voegele"}}]}
{"op":"mcm","clk":"1001506585","pt":1580587103572,"mc":[{"id":"1.168230757","rc":[{"batb":[[0,1.01,20]],"ltp":0.0,"tv":0.0,"id":2263603},{"batb":[[0,1.01,20]],"ltp":0.0,"tv":0.0,"id":3622149}]}]}
{"op":"mcm","clk":"1003070449","pt":1580602599617,"mc":[{"id":"1.168230757","rc":[{"batb":[[0,1.01,22.53]],"ltp":0.0,"tv":0.0,"id":2263603},{"batb":[[0,1.01,22.53]],"ltp":0.0,"tv":0.0,"id":3622149}]}]}
{"op":"mcm","clk":"1003070537","pt":1580602600505,"mc":[{"id":"1.168230757","rc":[{"batb":[[0,1.01,20.51]],"ltp":0.0,"tv":0.0,"id":2263603},{"batb":[[0,1.01,20.51]],"ltp":0.0,"tv":0.0,"id":3622149}]}]}
{"op":"mcm","clk":"1003129839","pt":1580603365593,"mc":[{"id":"1.168230757","rc":[{"batb":[[0,1.01,23.04]],"ltp":0.0,"tv":0.0,"id":2263603},{"batb":[[0,1.01,23.04]],"ltp":0.0,"tv":0.0,"id":3622149}]}]}
{"op":"mcm","clk":"1003129911","pt":1580603366468,"mc":[{"id":"1.168230757","rc":[{"batb":[[0,1.01,21.01]],"ltp":0.0,"tv":0.0,"id":2263603},{"batb":[[0,1.01,21.01]],"ltp":0.0,"tv":0.0,"id":3622149}]}]}
{"op":"mcm","clk":"1003415667","pt":1580607443593,"mc":[{"id":"1.168230757","rc":[{"batb":[[0,1.75,8.88],[1,1.01,21.01]],"ltp":0.0,"tv":0.0,"id":2263603},{"batb":[[0,1.78,40.16],[1,1.75,8.88],[2,1.01,21.01]],"ltp":0.0,"tv":0.0,"id":3622149}]}]}
{"op":"mcm","clk":"1003415674","pt":1580607443696,"mc":[{"id":"1.168230757","rc":[{"batb":[[0,1.8,39.63],[1,1.75,8.88],[2,1.01,21.01]],"ltp":0.0,"tv":0.0,"id":2263603}]}]}
{"op":"mcm","clk":"1003417368","pt":1580607466939,"mc":[{"id":"1.168230757","marketDefinition":{"bspMarket":false,"turnInPlayEnabled":true,"persistenceEnabled":true,"marketBaseRate":5.0,"eventId":"29681775","eventTypeId":"2","numberOfWinners":1,"bettingType":"ODDS","marketType":"SET_WINNER","marketTime":"2020-02-02T18:00:00.000Z","suspendTime":"2020-02-02T18:00:00.000Z","bspReconciled":false,"complete":true,"inPlay":false,"crossMatching":true,"runnersVoidable":false,"numberOfActiveRunners":2,"betDelay":0,"status":"OPEN","runners":[{"status":"ACTIVE","sortPriority":1,"id":2263603,"name":"Madison Brengle"},{"status":"ACTIVE","sortPriority":2,"id":3622149,"name":"Stefanie Voegele"}],"regulators":["MR_INT"],"discountAllowed":true,"timezone":"UTC","openDate":"2020-02-02T18:00:00.000Z","version":3147399676,"name":"Set 1 Winner","eventName":"Brengle v Voegele"}}]}
{"op":"mcm","clk":"1003673080","pt":1580611043185,"mc":[{"id":"1.168230757","rc":[{"batb":[[0,1.85,38.57]],"ltp":0.0,"tv":0.0,"id":3622149}]}]}
{"op":"mcm","clk":"1003861876","pt":1580614643218,"mc":[{"id":"1.168230757","rc":[{"batb":[[0,1.75,8.88],[1,1.01,21.01],[2,1.01,0]],"ltp":0.0,"tv":0.0,"id":3622149}]}]}
{"op":"mcm","clk":"1003861933","pt":1580614644203,"mc":[{"id":"1.168230757","rc":[{"batb":[[0,1.75,8.88],[1,1.01,21.01],[2,1.01,0]],"ltp":0.0,"tv":0.0,"id":2263603},{"batb":[[0,1.8,39.63],[1,1.75,8.88],[2,1.01,21.01]],"ltp":0.0,"tv":0.0,"id":3622149}]}]}
{"op":"mcm","clk":"1004014905","pt":1580618244580,"mc":[{"id":"1.168230757","rc":[{"batb":[[0,1.82,39.42],[1,1.75,8.88],[2,1.01,21.01]],"ltp":0.0,"tv":0.0,"id":2263603},{"batb":[[0,1.75,8.88],[1,1.01,21.01],[2,1.01,0]],"ltp":0.0,"tv":0.0,"id":3622149}]}]}
{"op":"mcm","clk":"1004164459","pt":1580621845000,"mc":[{"id":"1.168230757","rc":[{"batb":[[0,1.85,38.57]],"ltp":0.0,"tv":0.0,"id":2263603},{"batb":[[0,1.78,40.16],[1,1.75,8.88],[2,1.01,21.01]],"ltp":0.0,"tv":0.0,"id":3622149}]}]}
{"op":"mcm","clk":"1004212461","pt":1580623329626,"mc":[{"id":"1.168230757","rc":[{"batb":[[0,1.85,54.97]],"ltp":0.0,"tv":0.0,"id":2263603},{"batb":[[0,1.78,57.16]],"ltp":0.0,"tv":0.0,"id":3622149}]}]}
{"op":"mcm","clk":"1004212555","pt":1580623332629,"mc":[{"id":"1.168230757","rc":[{"batb":[[1,1.75,12.72]],"ltp":0.0,"tv":0.0,"id":2263603},{"batb":[[1,1.75,12.72]],"ltp":0.0,"tv":0.0,"id":3622149}]}]}
{"op":"mcm","clk":"1004277159","pt":1580625446188,"mc":[{"id":"1.168230757","rc":[{"batb":[[0,1.8,56.73]],"ltp":0.0,"tv":0.0,"id":2263603},{"batb":[[0,1.85,55.17]],"ltp":0.0,"tv":0.0,"id":3622149}]}]}
{"op":"mcm","clk":"1004337042","pt":1580627364208,"mc":[{"id":"1.168230757","rc":[{"batb":[[1,1.01,21.01],[2,1.01,0]],"ltp":0.0,"tv":0.0,"id":2263603},{"batb":[[1,1.01,21.01],[2,1.01,0]],"ltp":0.0,"tv":0.0,"id":3622149}]}]}
{"op":"mcm","clk":"1004337092","pt":1580627365452,"mc":[{"id":"1.168230757","rc":[{"batb":[[1,1.73,13.07],[2,1.01,21.01]],"ltp":0.0,"tv":0.0,"id":2263603},{"batb":[[1,1.78,12.23],[2,1.01,21.01]],"ltp":0.0,"tv":0.0,"id":3622149}]}]}
{"op":"mcm","clk":"1004338265","pt":1580627399377,"mc":[{"id":"1.168230757","rc":[{"batb":[[0,1.73,13.07],[1,1.01,21.01],[2,1.01,0]],"ltp":0.0,"tv":0.0,"id":2263603},{"batb":[[0,1.78,12.23],[1,1.01,21.01],[2,1.01,0]],"ltp":0.0,"tv":0.0,"id":3622149}]}]}
{"op":"mcm","clk":"1004338310","pt":1580627400456,"mc":[{"id":"1.168230757","rc":[{"batb":[[0,1.8,63.73],[1,1.73,13.07],[2,1.01,21.01]],"ltp":0.0,"tv":0.0,"id":2263603},{"batb":[[0,1.81,71.45],[1,1.78,12.23],[2,1.01,21.01]],"ltp":0.0,"tv":0.0,"id":3622149}]}]}
{"op":"mcm","clk":"1004339465","pt":1580627431404,"mc":[{"id":"1.168230757","rc":[{"batb":[[1,1.72,13.25]],"ltp":0.0,"tv":0.0,"id":2263603}]}]}
{"op":"mcm","clk":"1004350339","pt":1580627709626,"mc":[{"id":"1.168230757","rc":[{"batb":[[0,1.72,13.25],[1,1.01,21.01],[2,1.01,0]],"ltp":0.0,"tv":0.0,"id":2263603},{"batb":[[0,1.78,12.23],[1,1.01,21.01],[2,1.01,0]],"ltp":0.0,"tv":0.0,"id":3622149}]}]}
{"op":"mcm","clk":"1004498596","pt":1580631180487,"mc":[{"id":"1.168230757","rc":[{"batb":[[0,1.83,62.68],[1,1.75,12.72],[2,1.01,21.01]],"ltp":0.0,"tv":0.0,"id":2263603},{"batb":[[0,1.79,56.93],[1,1.75,12.72],[2,1.01,21.01]],"ltp":0.0,"tv":0.0,"id":3622149}]}]}
{"op":"mcm","clk":"1004511681","pt":1580631490392,"mc":[{"id":"1.168230757","rc":[{"batb":[[0,1.77,64.98]],"ltp":0.0,"tv":0.0,"id":2263603}]}]}
{"op":"mcm","clk":"1004525193","pt":1580631800150,"mc":[{"id":"1.168230757","rc":[{"batb":[[0,1.75,12.72],[1,1.01,21.01],[2,1.01,0]],"ltp":0.0,"tv":0.0,"id":2263603}]}]}
{"op":"mcm","clk":"1004640123","pt":1580634261607,"mc":[{"id":"1.168230757","rc":[{"batb":[[0,1.01,21.01],[1,1.01,0]],"ltp":0.0,"tv":0.0,"id":2263603},{"batb":[[0,1.79,85.31],[1,1.01,21.01],[2,1.01,0]],"ltp":0.0,"tv":0.0,"id":3622149}]}]}
{"op":"mcm","clk":"1004640164","pt":1580634262591,"mc":[{"id":"1.168230757","rc":[{"batb":[[0,1.83,83.56],[1,1.78,18.25],[2,1.01,21.01]],"ltp":0.0,"tv":0.0,"id":2263603},{"batb":[[1,1.78,18.25],[2,1.01,21.01]],"ltp":0.0,"tv":0.0,"id":3622149}]}]}
{"op":"mcm","clk":"1004664316","pt":1580634780884,"mc":[{"id":"1.168230757","rc":[{"batb":[[0,1.83,83.56]],"ltp":0.0,"tv":0.0,"id":3622149}]}]}
{"op":"mcm","clk":"1004820128","pt":1580637862563,"mc":[{"id":"1.168230757","rc":[{"batb":[[0,1.78,18.25],[1,1.01,21.01],[2,1.01,0]],"ltp":0.0,"tv":0.0,"id":2263603}]}]}
{"op":"mcm","clk":"1004855846","pt":1580638381344,"mc":[{"id":"1.168230757","rc":[{"batb":[[0,1.87,81.81],[1,1.78,18.25],[2,1.01,21.01]],"ltp":0.0,"tv":0.0,"id":2263603},{"batb":[[0,1.78,18.25],[1,1.01,21.01],[2,1.01,0]],"ltp":0.0,"tv":0.0,"id":3622149}]}]}
{"op":"mcm","clk":"1004855870","pt":1580638381665,"mc":[{"id":"1.168230757","rc":[{"batb":[[0,1.82,84.03],[1,1.78,18.25],[2,1.01,21.01]],"ltp":0.0,"tv":0.0,"id":3622149}]}]}
{"op":"mcm","clk":"1004951073","pt":1580639423500,"mc":[{"id":"1.168230757","rc":[{"batb":[[1,1.79,18.02]],"ltp":0.0,"tv":0.0,"id":2263603},{"batb":[[1,1.79,18.02]],"ltp":0.0,"tv":0.0,"id":3622149}]}]}
{"op":"mcm","clk":"1004951805","pt":1580639431498,"mc":[{"id":"1.168230757","rc":[{"batb":[[1,1.01,21.01],[2,1.01,0]],"ltp":0.0,"tv":0.0,"id":2263603},{"batb":[[1,1.01,21.01],[2,1.01,0]],"ltp":0.0,"tv":0.0,"id":3622149}]}]}
{"op":"mcm","clk":"1004951877","pt":1580639432221,"mc":[{"id":"1.168230757","rc":[{"batb":[[1,1.79,18.02],[2,1.01,21.01]],"ltp":0.0,"tv":0.0,"id":2263603},{"batb":[[1,1.78,18.25],[2,1.01,21.01]],"ltp":0.0,"tv":0.0,"id":3622149}]}]}
{"op":"mcm","clk":"1005306903","pt":1580641981642,"mc":[{"id":"1.168230757","rc":[{"batb":[[0,1.79,18.02],[1,1.01,21.01],[2,1.01,0]],"ltp":0.0,"tv":0.0,"id":2263603},{"batb":[[0,1.78,18.25],[1,1.01,21.01],[2,1.01,0]],"ltp":0.0,"tv":0.0,"id":3622149}]}]}
{"op":"mcm","clk":"1005307036","pt":1580641982436,"mc":[{"id":"1.168230757","rc":[{"batb":[[0,1.8,84.83],[1,1.78,18.25],[2,1.01,21.01]],"ltp":0.0,"tv":0.0,"id":3622149}]}]}
{"op":"mcm","clk":"1005380097","pt":1580642379649,"mc":[{"id":"1.168230757","rc":[{"batb":[[0,1.82,83.14],[1,1.79,18.02],[2,1.01,21.01]],"ltp":0.0,"tv":0.0,"id":2263603}]}]}
{"op":"mcm","clk":"1005685734","pt":1580643966501,"mc":[{"id":"1.168230757","rc":[{"batb":[[1,1.01,21.01],[2,1.01,0]],"ltp":0.0,"tv":0.0,"id":2263603},{"batb":[[1,1.01,21.01],[2,1.01,0]],"ltp":0.0,"tv":0.0,"id":3622149}]}]}
{"op":"mcm","clk":"1005685854","pt":1580643967092,"mc":[{"id":"1.168230757","rc":[{"batb":[[1,1.79,18.02],[2,1.01,21.01]],"ltp":0.0,"tv":0.0,"id":2263603},{"batb":[[1,1.79,18.02],[2,1.01,21.01]],"ltp":0.0,"tv":0.0,"id":3622149}]}]}
{"op":"mcm","clk":"1005813665","pt":1580644896515,"mc":[{"id":"1.168230757","rc":[{"batb":[[0,1.82,111.53]],"ltp":0.0,"tv":0.0,"id":2263603},{"batb":[[0,1.8,112.63]],"ltp":0.0,"tv":0.0,"id":3622149}]}]}
{"op":"mcm","clk":"1005813882","pt":1580644898065,"mc":[{"id":"1.168230757","rc":[{"batb":[[1,1.01,21.01],[2,1.01,0]],"ltp":0.0,"tv":0.0,"id":2263603},{"batb":[[1,1.01,21.01],[2,1.01,0]],"ltp":0.0,"tv":0.0,"id":3622149}]}]}
{"op":"mcm","clk":"1005814108","pt":1580644899582,"mc":[{"id":"1.168230757","rc":[{"batb":[[1,1.79,23.97],[2,1.01,21.01]],"ltp":0.0,"tv":0.0,"id":2263603},{"batb":[[1,1.79,23.97],[2,1.01,21.01]],"ltp":0.0,"tv":0.0,"id":3622149}]}]}
{"op":"mcm","clk":"1005942478","pt":1580645583118,"mc":[{"id":"1.168230757","rc":[{"batb":[[0,1.86,109.11]],"ltp":0.0,"tv":0.0,"id":3622149}]}]}
{"op":"mcm","clk":"1006011931","pt":1580645980142,"mc":[{"id":"1.168230757","rc":[{"batb":[[0,1.83,110.74]],"ltp":0.0,"tv":0.0,"id":2263603}]}]}
{"op":"mcm","clk":"1006103991","pt":1580646508203,"mc":[{"id":"1.168230757","rc":[{"batb":[[1,1.01,21.01],[2,1.01,0]],"ltp":0.0,"tv":0.0,"id":2263603},{"batb":[[1,1.01,21.01],[2,1.01,0]],"ltp":0.0,"tv":0.0,"id":3622149}]}]}
{"op":"mcm","clk":"1006104097","pt":1580646508715,"mc":[{"id":"1.168230757","rc":[{"batb":[[1,1.79,23.97],[2,1.01,21.01]],"ltp":0.0,"tv":0.0,"id":2263603},{"batb":[[1,1.78,24.27],[2,1.01,21.01]],"ltp":0.0,"tv":0.0,"id":3622149}]}]}
{"op":"mcm","clk":"1006536476","pt":1580649183222,"mc":[{"id":"1.168230757","rc":[{"batb":[[0,1.78,24.27],[1,1.01,21.01],[2,1.01,0]],"ltp":0.0,"tv":0.0,"id":3622149}]}]}
{"op":"mcm","clk":"1006595959","pt":1580649580607,"mc":[{"id":"1.168230757","rc":[{"batb":[[0,1.79,23.97],[1,1.01,21.01],[2,1.01,0]],"ltp":0.0,"tv":0.0,"id":2263603}]}]}
{"op":"mcm","clk":"1006596050","pt":1580649581201,"mc":[{"id":"1.168230757","rc":[{"batb":[[0,1.82,111.03],[1,1.79,23.97],[2,1.01,21.01]],"ltp":0.0,"tv":0.0,"id":2263603},{"batb":[[0,1.79,113.93],[1,1.78,24.27],[2,1.01,21.01]],"ltp":0.0,"tv":0.0,"id":3622149}]}]}
{"op":"mcm","clk":"1006707243","pt":1580650355178,"mc":[{"id":"1.168230757","rc":[{"batb":[[1,1.01,21.01],[2,1.01,0]],"ltp":0.0,"tv":0.0,"id":2263603},{"batb":[[1,1.01,21.01],[2,1.01,0]],"ltp":0.0,"tv":0.0,"id":3622149}]}]}
{"op":"mcm","clk":"1006707334","pt":1580650355786,"mc":[{"id":"1.168230757","rc":[{"batb":[[1,1.79,23.97],[2,1.01,21.01]],"ltp":0.0,"tv":0.0,"id":2263603},{"batb":[[0,1.79,137.9]],"ltp":0.0,"tv":0.0,"id":3622149}]}]}
{"op":"mcm","clk":"1006707983","pt":1580650359606,"mc":[{"id":"1.168230757","rc":[{"batb":[[1,1.77,24.59]],"ltp":0.0,"tv":0.0,"id":2263603},{"batb":[[0,1.8,23.66]],"ltp":0.0,"tv":0.0,"id":3622149}]}]}
{"op":"mcm","clk":"1006708096","pt":1580650360088,"mc":[{"id":"1.168230757","rc":[{"batb":[[0,1.87,107.35],[1,1.8,23.66],[2,1.01,21.01]],"ltp":0.0,"tv":0.0,"id":3622149}]}]}
{"op":"mcm","clk":"1007141596","pt":1580653181172,"mc":[{"id":"1.168230757","rc":[{"batb":[[0,1.77,24.59],[1,1.01,21.01],[2,1.01,0]],"ltp":0.0,"tv":0.0,"id":2263603},{"batb":[[0,1.8,23.66],[1,1.01,21.01],[2,1.01,0]],"ltp":0.0,"tv":0.0,"id":3622149}]}]}
{"op":"mcm","clk":"1007141682","pt":1580653181671,"mc":[{"id":"1.168230757","rc":[{"batb":[[0,1.85,108.57],[1,1.8,23.66],[2,1.01,21.01]],"ltp":0.0,"tv":0.0,"id":3622149}]}]}
{"op":"mcm","clk":"1007205943","pt":1580653585035,"mc":[{"id":"1.168230757","rc":[{"batb":[[0,1.79,115.12],[1,1.77,24.59],[2,1.01,21.01]],"ltp":0.0,"tv":0.0,"id":2263603}]}]}
{"op":"mcm","clk":"1007206494","pt":1580653588442,"mc":[{"id":"1.168230757","rc":[{"batb":[[1,1.01,21.01],[2,1.01,0]],"ltp":0.0,"tv":0.0,"id":2263603},{"batb":[[1,1.01,21.01],[2,1.01,0]],"ltp":0.0,"tv":0.0,"id":3622149}]}]}
{"op":"mcm","clk":"1007206601","pt":1580653589062,"mc":[{"id":"1.168230757","rc":[{"batb":[[1,1.76,24.91],[2,1.01,21.01]],"ltp":0.0,"tv":0.0,"id":2263603},{"batb":[[1,1.81,23.37],[2,1.01,21.01]],"ltp":0.0,"tv":0.0,"id":3622149}]}]}
{"op":"mcm","clk":"1007668552","pt":1580656387512,"mc":[{"id":"1.168230757","rc":[{"batb":[[0,1.76,24.91],[1,1.01,21.01],[2,1.01,0]],"batl":[[0,2.18,3.79]],"ltp":0.0,"tv":0.0,"id":2263603},{"batl":[[0,2.26,3.79]],"ltp":0.0,"tv":0.0,"id":3622149}]}]}
{"op":"mcm","clk":"1007668600","pt":1580656387724,"mc":[{"id":"1.168230757","rc":[{"batl":[[0,2.22,92.75],[1,2.26,3.79]],"ltp":0.0,"tv":0.0,"id":3622149}]}]}
{"op":"mcm","clk":"1007669727","pt":1580656392518,"mc":[{"id":"1.168230757","rc":[{"batl":[[0,2.14,93.47],[1,2.16,3.79]],"ltp":0.0,"tv":0.0,"id":2263603},{"batb":[[0,1.81,23.37],[1,1.01,21.01],[2,1.01,0]],"ltp":0.0,"tv":0.0,"id":3622149}]}]}
{"op":"mcm","clk":"1007760168","pt":1580656782482,"mc":[{"id":"1.168230757","rc":[{"batl":[[0,2.16,3.79],[1,2.16,0]],"ltp":0.0,"tv":0.0,"id":2263603}]}]}
{"op":"mcm","clk":"1007850610","pt":1580657185549,"mc":[{"id":"1.168230757","rc":[{"batl":[[0,2.26,3.79],[1,2.26,0]],"ltp":0.0,"tv":0.0,"id":3622149}]}]}
{"op":"mcm","clk":"1007850747","pt":1580657186062,"mc":[{"id":"1.168230757","rc":[{"batl":[[0,2.14,93.47],[1,2.16,3.79]],"ltp":0.0,"tv":0.0,"id":2263603},{"batl":[[0,2.22,92.75],[1,2.26,3.79]],"ltp":0.0,"tv":0.0,"id":3622149}]}]}
{"op":"mcm","clk":"1008223752","pt":1580658957887,"mc":[{"id":"1.168230757","rc":[{"batl":[[0,2.12,3.79],[1,2.14,93.47]],"ltp":0.0,"tv":0.0,"id":2263603},{"batl":[[0,2.2,3.79],[1,2.22,92.75]],"ltp":0.0,"tv":0.0,"id":3622149}]}]}
{"op":"mcm","clk":"1008224132","pt":1580658960336,"mc":[{"id":"1.168230757","rc":[{"batl":[[1,2.14,0]],"ltp":0.0,"tv":0.0,"id":2263603},{"batl":[[1,2.22,0]],"ltp":0.0,"tv":0.0,"id":3622149}]}]}
{"op":"mcm","clk":"1008224256","pt":1580658961023,"mc":[{"id":"1.168230757","rc":[{"batl":[[0,2.1,95.05],[1,2.12,3.79]],"ltp":0.0,"tv":0.0,"id":2263603},{"batl":[[0,2.18,94.25],[1,2.2,3.79]],"ltp":0.0,"tv":0.0,"id":3622149}]}]}
{"op":"mcm","clk":"1008269622","pt":1580659241371,"mc":[{"id":"1.168230757","rc":[{"batl":[[1,2.22,3.79]],"ltp":0.0,"tv":0.0,"id":2263603},{"batl":[[1,2.3,3.79]],"ltp":0.0,"tv":0.0,"id":3622149}]}]}
{"op":"mcm","clk":"1008473401","pt":1580660197634,"mc":[{"id":"1.168230757","rc":[{"batb":[[0,1.01,21.01],[1,1.01,0]],"ltp":0.0,"tv":0.0,"id":2263603},{"batb":[[0,1.01,21.01],[1,1.01,0]],"ltp":0.0,"tv":0.0,"id":3622149}]}]}
{"op":"mcm","clk":"1008473461","pt":1580660197965,"mc":[{"id":"1.168230757","rc":[{"batb":[[0,1.77,24.59],[1,1.01,21.01]],"ltp":0.0,"tv":0.0,"id":2263603},{"batb":[[0,1.8,23.66],[1,1.01,21.01]],"ltp":0.0,"tv":0.0,"id":3622149}]}]}
{"op":"mcm","clk":"1008607220","pt":1580660786583,"mc":[{"id":"1.168230757","rc":[{"batl":[[0,2.22,3.79],[1,2.22,0]],"ltp":0.0,"tv":0.0,"id":2263603},{"batl":[[0,2.3,3.79],[1,2.3,0]],"ltp":0.0,"tv":0.0,"id":3622149}]}]}
{"op":"mcm","clk":"1008607307","pt":1580660787009,"mc":[{"id":"1.168230757","rc":[{"batb":[[0,1.79,114.55],[1,1.77,24.59],[2,1.01,21.01]],"batl":[[0,2.2,91.18],[1,2.22,3.79]],"ltp":0.0,"tv":0.0,"id":2263603}]}]}
{"op":"mcm","clk":"1008843292","pt":1580661884618,"mc":[{"id":"1.168230757","rc":[{"batb":[[1,1.01,21.01],[2,1.01,0]],"ltp":0.0,"tv":0.0,"id":2263603},{"batb":[[0,1.01,21.01],[1,1.01,0]],"ltp":0.0,"tv":0.0,"id":3622149}]}]}
{"op":"mcm","clk":"1008843461","pt":1580661885539,"mc":[{"id":"1.168230757","rc":[{"batb":[[1,1.76,24.91],[2,1.01,21.01]],"ltp":0.0,"tv":0.0,"id":2263603},{"batb":[[0,1.81,23.37],[1,1.01,21.01]],"ltp":0.0,"tv":0.0,"id":3622149}]}]}
{"op":"mcm","clk":"1008860233","pt":1580661967162,"mc":[{"id":"1.168230757","rc":[{"batb":[[1,1.01,21.01],[2,1.01,0]],"ltp":0.0,"tv":0.0,"id":2263603},{"batb":[[0,1.01,21.01],[1,1.01,0]],"ltp":0.0,"tv":0.0,"id":3622149}]}]}
{"op":"mcm","clk":"1008860514","pt":1580661968511,"mc":[{"id":"1.168230757","rc":[{"batb":[[1,1.77,24.59],[2,1.01,21.01]],"ltp":0.0,"tv":0.0,"id":2263603},{"batb":[[0,1.8,23.66],[1,1.01,21.01]],"ltp":0.0,"tv":0.0,"id":3622149}]}]}
{"op":"mcm","clk":"1008864549","pt":1580661988538,"mc":[{"id":"1.168230757","rc":[{"batb":[[1,1.01,21.01],[2,1.01,0]],"ltp":0.0,"tv":0.0,"id":2263603},{"batb":[[0,1.01,21.01],[1,1.01,0]],"ltp":0.0,"tv":0.0,"id":3622149}]}]}
{"op":"mcm","clk":"1008864679","pt":1580661989146,"mc":[{"id":"1.168230757","rc":[{"batb":[[1,1.78,24.27],[2,1.01,21.01]],"ltp":0.0,"tv":0.0,"id":2263603},{"batb":[[0,1.79,23.97],[1,1.01,21.01]],"ltp":0.0,"tv":0.0,"id":3622149}]}]}
{"op":"mcm","clk":"1008867953","pt":1580662006077,"mc":[{"id":"1.168230757","rc":[{"batb":[[1,1.01,21.01],[2,1.01,0]],"ltp":0.0,"tv":0.0,"id":2263603},{"batb":[[0,1.01,21.01],[1,1.01,0]],"ltp":0.0,"tv":0.0,"id":3622149}]}]}
{"op":"mcm","clk":"1008868228","pt":1580662007569,"mc":[{"id":"1.168230757","rc":[{"batb":[[0,1.79,138.52]],"ltp":0.0,"tv":0.0,"id":2263603},{"batb":[[0,1.79,23.97],[1,1.01,21.01]],"ltp":0.0,"tv":0.0,"id":3622149}]}]}
{"op":"mcm","clk":"1008871572","pt":1580662024413,"mc":[{"id":"1.168230757","rc":[{"batb":[[0,1.79,114.55]],"ltp":0.0,"tv":0.0,"id":2263603},{"batb":[[0,1.01,21.01],[1,1.01,0]],"ltp":0.0,"tv":0.0,"id":3622149}]}]}
{"op":"mcm","clk":"1008871694","pt":1580662025093,"mc":[{"id":"1.168230757","rc":[{"batb":[[0,1.79,138.52]],"ltp":0.0,"tv":0.0,"id":2263603},{"batb":[[0,1.78,24.27],[1,1.01,21.01]],"ltp":0.0,"tv":0.0,"id":3622149}]}]}
{"op":"mcm","clk":"1008887005","pt":1580662115593,"mc":[{"id":"1.168230757","rc":[{"batb":[[0,1.81,23.37],[1,1.79,114.55],[2,1.01,21.01]],"ltp":0.0,"tv":0.0,"id":2263603},{"batb":[[0,1.76,24.91]],"ltp":0.0,"tv":0.0,"id":3622149}]}]}
{"op":"mcm","clk":"1008887122","pt":1580662116284,"mc":[{"id":"1.168230757","rc":[{"batb":[[0,1.84,108.72],[1,1.81,23.37]],"ltp":0.0,"tv":0.0,"id":2263603}]}]}
{"op":"mcm","clk":"1008945357","pt":1580662527261,"mc":[{"id":"1.168230757","rc":[{"batb":[[1,1.79,23.97]],"ltp":0.0,"tv":0.0,"id":2263603},{"batb":[[0,1.79,23.97]],"ltp":0.0,"tv":0.0,"id":3622149}]}]}
{"op":"mcm","clk":"1008945896","pt":1580662531636,"mc":[{"id":"1.168230757","rc":[{"batb":[[1,1.01,21.01],[2,1.01,0]],"ltp":0.0,"tv":0.0,"id":2263603},{"batb":[[0,1.01,21.01],[1,1.01,0]],"ltp":0.0,"tv":0.0,"id":3622149}]}]}
{"op":"mcm","clk":"1008945955","pt":1580662532165,"mc":[{"id":"1.168230757","rc":[{"batb":[[1,1.76,24.91],[2,1.01,21.01]],"ltp":0.0,"tv":0.0,"id":2263603},{"batb":[[0,1.81,23.37],[1,1.01,21.01]],"ltp":0.0,"tv":0.0,"id":3622149}]}]}
{"op":"mcm","clk":"1008980526","pt":1580662805802,"mc":[{"id":"1.168230757","rc":[{"batb":[[1,1.01,21.01],[2,1.01,0]],"ltp":0.0,"tv":0.0,"id":2263603},{"batb":[[0,1.01,21.01],[1,1.01,0]],"ltp":0.0,"tv":0.0,"id":3622149}]}]}
{"op":"mcm","clk":"1009236254","pt":1580664387555,"mc":[{"id":"1.168230757","rc":[{"batb":[[0,1.01,21.01],[1,1.01,0]],"batl":[[0,2.22,3.79],[1,2.22,0]],"ltp":0.0,"tv":0.0,"id":2263603}]}]}
{"op":"mcm","clk":"1009236301","pt":1580664387876,"mc":[{"id":"1.168230757","rc":[{"batl":[[0,2.24,91.98],[1,2.3,3.79]],"ltp":0.0,"tv":0.0,"id":3622149}]}]}
{"op":"mcm","clk":"1009413277","pt":1580665519941,"mc":[{"id":"1.168230757","rc":[{"batl":[[0,2.18,91.25],[1,2.22,3.79]],"ltp":0.0,"tv":0.0,"id":2263603}]}]}
{"op":"mcm","clk":"1009414885","pt":1580665532424,"mc":[{"id":"1.168230757","rc":[{"batb":[[0,1.01,22.69]],"ltp":0.0,"tv":0.0,"id":2263603},{"batb":[[0,1.01,22.69]],"ltp":0.0,"tv":0.0,"id":3622149}]}]}
{"op":"mcm","clk":"1009415038","pt":1580665533504,"mc":[{"id":"1.168230757","rc":[{"batb":[[0,1.81,1.39],[1,1.01,21.01]],"ltp":0.0,"tv":0.0,"id":2263603},{"batb":[[0,1.85,1.36],[1,1.01,21.01]],"ltp":0.0,"tv":0.0,"id":3622149}]}]}
{"op":"mcm","clk":"1009415561","pt":1580665537604,"mc":[{"id":"1.168230757","rc":[{"batl":[[0,2.22,3.79],[1,2.22,0]],"ltp":0.0,"tv":0.0,"id":2263603},{"batb":[[0,1.86,107.04],[1,1.85,1.36],[2,1.01,21.01]],"ltp":0.0,"tv":0.0,"id":3622149}]}]}
{"op":"mcm","clk":"1009418905","pt":1580665564339,"mc":[{"id":"1.168230757","rc":[{"batb":[[1,1.01,22.69],[2,1.01,0]],"ltp":0.0,"tv":0.0,"id":3622149}]}]}
{"op":"mcm","clk":"1009419048","pt":1580665565556,"mc":[{"id":"1.168230757","rc":[{"batb":[[0,1.88,105.71],[1,1.87,1.34],[2,1.01,21.01]],"ltp":0.0,"tv":0.0,"id":3622149}]}]}
{"op":"mcm","clk":"1009422651","pt":1580665594452,"mc":[{"id":"1.168230757","rc":[{"batb":[[1,1.01,22.69],[2,1.01,0]],"ltp":0.0,"tv":0.0,"id":3622149}]}]}
{"op":"mcm","clk":"1009422784","pt":1580665595455,"mc":[{"id":"1.168230757","rc":[{"batb":[[0,1.9,104.56],[1,1.89,1.34],[2,1.01,21.01]],"ltp":0.0,"tv":0.0,"id":3622149}]}]}
{"op":"mcm","clk":"1009426087","pt":1580665624508,"mc":[{"id":"1.168230757","rc":[{"batb":[[0,1.91,1.32],[1,1.9,104.56]],"ltp":0.0,"tv":0.0,"id":3622149}]}]}
{"op":"mcm","clk":"1009426133","pt":1580665624929,"mc":[{"id":"1.168230757","rc":[{"batb":[[0,1.92,103.44],[1,1.91,1.32]],"ltp":0.0,"tv":0.0,"id":3622149}]}]}
{"op":"mcm","clk":"1009429655","pt":1580665655464,"mc":[{"id":"1.168230757","rc":[{"batb":[[1,1.01,22.32],[2,1.01,0]],"ltp":0.0,"tv":0.0,"id":3622149}]}]}
{"op":"mcm","clk":"1009429745","pt":1580665656278,"mc":[{"id":"1.168230757","rc":[{"batb":[[0,1.93,1.3],[1,1.01,21.01]],"ltp":0.0,"tv":0.0,"id":3622149}]}]}
{"op":"mcm","clk":"1009450364","pt":1580665851528,"mc":[{"id":"1.168230757","rc":[{"batl":[[0,2.36,3.79]],"ltp":0.0,"tv":0.0,"id":2263603}]}]}
{"op":"mcm","clk":"1009482816","pt":1580666180480,"mc":[{"id":"1.168230757","rc":[{"batl":[[0,2.3,3.79],[1,2.3,0]],"ltp":0.0,"tv":0.0,"id":3622149}]}]}
{"op":"mcm","clk":"1009484188","pt":1580666194850,"mc":[{"id":"1.168230757","rc":[{"batb":[[0,1.82,113.64],[1,1.81,1.39],[2,1.01,21.01]],"ltp":0.0,"tv":0.0,"id":2263603}]}]}
{"op":"mcm","clk":"1009487004","pt":1580666223520,"mc":[{"id":"1.168230757","rc":[{"batb":[[0,1.83,1.38],[1,1.82,113.64]],"ltp":0.0,"tv":0.0,"id":2263603}]}]}
{"op":"mcm","clk":"1009487041","pt":1580666223784,"mc":[{"id":"1.168230757","rc":[{"batb":[[0,1.84,112.47],[1,1.83,1.38]],"ltp":0.0,"tv":0.0,"id":2263603}]}]}
{"op":"mcm","clk":"1009490135","pt":1580666253340,"mc":[{"id":"1.168230757","rc":[{"batb":[[1,1.01,22.37],[2,1.01,0]],"ltp":0.0,"tv":0.0,"id":2263603}]}]}
{"op":"mcm","clk":"1009490209","pt":1580666254070,"mc":[{"id":"1.168230757","rc":[{"batb":[[0,1.86,111.18],[1,1.85,1.36],[2,1.01,21.01]],"ltp":0.0,"tv":0.0,"id":2263603}]}]}
{"op":"mcm","clk":"1009493253","pt":1580666283433,"mc":[{"id":"1.168230757","rc":[{"batb":[[1,1.01,22.69],[2,1.01,0]],"ltp":0.0,"tv":0.0,"id":2263603}]}]}
{"op":"mcm","clk":"1009493658","pt":1580666287397,"mc":[{"id":"1.168230757","rc":[{"batb":[[1,1.01,22.36]],"ltp":0.0,"tv":0.0,"id":2263603}]}]}
{"op":"mcm","clk":"1009493728","pt":1580666288011,"mc":[{"id":"1.168230757","rc":[{"batb":[[0,1.87,1.34],[1,1.01,21.01]],"ltp":0.0,"tv":0.0,"id":2263603}]}]}
{"op":"mcm","clk":"1009501465","pt":1580666365456,"mc":[{"id":"1.168230757","rc":[{"batb":[[0,1.88,108.46],[1,1.87,1.34],[2,1.01,21.01]],"ltp":0.0,"tv":0.0,"id":2263603}]}]}
{"op":"mcm","clk":"1009502249","pt":1580666373489,"mc":[{"id":"1.168230757","rc":[{"batb":[[1,1.01,22.35],[2,1.01,0]],"ltp":0.0,"tv":0.0,"id":2263603}]}]}
{"op":"mcm","clk":"1009502332","pt":1580666374062,"mc":[{"id":"1.168230757","rc":[{"batb":[[0,1.89,1.34],[1,1.01,21.01]],"ltp":0.0,"tv":0.0,"id":2263603}]}]}
{"op":"mcm","clk":"1009515467","pt":1580666510637,"mc":[{"id":"1.168230757","marketDefinition":{"bspMarket":false,"turnInPlayEnabled":true,"persistenceEnabled":true,"marketBaseRate":5.0,"eventId":"29681775","eventTypeId":"2","numberOfWinners":1,"bettingType":"ODDS","marketType":"SET_WINNER","marketTime":"2020-02-02T18:01:00.000Z","suspendTime":"2020-02-02T18:01:00.000Z","bspReconciled":false,"complete":true,"inPlay":false,"crossMatching":true,"runnersVoidable":false,"numberOfActiveRunners":2,"betDelay":0,"status":"OPEN","runners":[{"status":"ACTIVE","sortPriority":1,"id":2263603,"name":"Madison Brengle"},{"status":"ACTIVE","sortPriority":2,"id":3622149,"name":"Stefanie Voegele"}],"regulators":["MR_INT"],"discountAllowed":true,"timezone":"UTC","openDate":"2020-02-02T18:00:00.000Z","version":3150167969,"name":"Set 1 Winner","eventName":"Brengle v Voegele"}}]}
{"op":"mcm","clk":"1009515709","pt":1580666513126,"mc":[{"id":"1.168230757","marketDefinition":{"bspMarket":false,"turnInPlayEnabled":true,"persistenceEnabled":true,"marketBaseRate":5.0,"eventId":"29681775","eventTypeId":"2","numberOfWinners":1,"bettingType":"ODDS","marketType":"SET_WINNER","marketTime":"2020-02-02T18:01:00.000Z","suspendTime":"2020-02-02T18:01:00.000Z","bspReconciled":false,"complete":true,"inPlay":false,"crossMatching":true,"runnersVoidable":false,"numberOfActiveRunners":2,"betDelay":0,"status":"OPEN","runners":[{"status":"ACTIVE","sortPriority":1,"id":2263603,"name":"Madison Brengle"},{"status":"ACTIVE","sortPriority":2,"id":3622149,"name":"Stefanie Voegele"}],"regulators":["MR_INT"],"discountAllowed":true,"timezone":"UTC","openDate":"2020-02-02T18:01:00.000Z","version":3150167969,"name":"Set 1 Winner","eventName":"Brengle v Voegele"}}]}
{"op":"mcm","clk":"1009519906","pt":1580666557406,"mc":[{"id":"1.168230757","rc":[{"batb":[[0,1.91,33.6],[1,1.89,1.34],[2,1.01,21.01]],"ltp":0.0,"tv":0.0,"id":2263603},{"batb":[[0,1.97,60.82],[1,1.93,1.3],[2,1.01,21.01]],"ltp":0.0,"tv":0.0,"id":3622149}]}]}
{"op":"mcm","clk":"1009522716","pt":1580666585387,"mc":[{"id":"1.168230757","rc":[{"batb":[[1,1.01,21.01],[2,1.01,0]],"ltp":0.0,"tv":0.0,"id":3622149}]}]}
{"op":"mcm","clk":"1009522825","pt":1580666586501,"mc":[{"id":"1.168230757","rc":[{"batb":[[1,1.01,22.32],[2,1.01,0]],"ltp":0.0,"tv":0.0,"id":2263603},{"batb":[[1,1.01,22.29]],"ltp":0.0,"tv":0.0,"id":3622149}]}]}
{"op":"mcm","clk":"1009522872","pt":1580666586922,"mc":[{"id":"1.168230757","rc":[{"batb":[[0,1.92,1.31],[1,1.91,33.6],[2,1.01,21.01]],"ltp":0.0,"tv":0.0,"id":2263603},{"batb":[[0,1.98,1.28],[1,1.97,60.82],[2,1.01,21.01]],"ltp":0.0,"tv":0.0,"id":3622149}]}]}
{"op":"mcm","clk":"1009539312","pt":1580666745362,"mc":[{"id":"1.168230757","rc":[{"batl":[[0,2.02,85.96],[1,2.36,3.79]],"ltp":0.0,"tv":0.0,"id":2263603}]}]}
{"op":"mcm","clk":"1009555777","pt":1580666900444,"mc":[{"id":"1.168230757","marketDefinition":{"bspMarket":false,"turnInPlayEnabled":true,"persistenceEnabled":true,"marketBaseRate":5.0,"eventId":"29681775","eventTypeId":"2","numberOfWinners":1,"bettingType":"ODDS","marketType":"SET_WINNER","marketTime":"2020-02-02T18:01:00.000Z","suspendTime":"2020-02-02T18:01:00.000Z","bspReconciled":false,"complete":true,"inPlay":true,"crossMatching":true,"runnersVoidable":false,"numberOfActiveRunners":2,"betDelay":3,"status":"OPEN","runners":[{"status":"ACTIVE","sortPriority":1,"id":2263603,"name":"Madison Brengle"},{"status":"ACTIVE","sortPriority":2,"id":3622149,"name":"Stefanie Voegele"}],"regulators":["MR_INT"],"discountAllowed":true,"timezone":"UTC","openDate":"2020-02-02T18:01:00.000Z","version":3150176610,"name":"Set 1 Winner","eventName":"Brengle v Voegele"},"rc":[{"batb":[[0,1.01,20.51],[1,1.91,0],[2,1.01,0]],"ltp":0.0,"tv":0.0,"id":2263603},{"batb":[[0,1.01,20.51],[1,1.97,0],[2,1.01,0]],"ltp":0.0,"tv":0.0,"id":3622149}]}]}
{"op":"mcm","clk":"1009557095","pt":1580666913037,"mc":[{"id":"1.168230757","rc":[{"batb":[[0,1.81,366.11],[1,1.79,411.48],[2,1.01,20.51]],"batl":[[0,2.28,194.01],[1,2.3,198.5]],"ltp":0.0,"tv":0.0,"id":3622149}]}]}
{"op":"mcm","clk":"1009558456","pt":1580666926557,"mc":[{"id":"1.168230757","rc":[{"batl":[[0,1.89,334.43],[1,1.91,339.47]],"ltp":0.0,"tv":0.0,"id":3622149}]}]}
{"op":"mcm","clk":"1009558525","pt":1580666927252,"mc":[{"id":"1.168230757","rc":[{"batb":[[0,2.1,50.12],[1,1.92,32.73],[2,1.01,20.51]],"ltp":0.0,"tv":0.0,"id":2263603},{"batb":[[1,1.8,40.44],[2,1.79,411.48]],"ltp":0.0,"tv":0.0,"id":3622149}]}]}
{"op":"mcm","clk":"1009559496","pt":1580666936249,"mc":[{"id":"1.168230757","rc":[{"batb":[[0,1.92,32.73],[1,1.01,20.51],[2,1.01,0]],"ltp":0.0,"tv":0.0,"id":2263603},{"batb":[[1,1.79,411.48],[2,1.65,54.45]],"ltp":0.0,"tv":0.0,"id":3622149}]}]}
{"op":"mcm","clk":"1009559657","pt":1580666937582,"mc":[{"id":"1.168230757","rc":[{"batb":[[0,1.65,54.45],[1,1.01,20.51],[2,1.65,0]],"ltp":0.0,"tv":0.0,"id":3622149}]}]}
{"op":"mcm","clk":"1009560209","pt":1580666942564,"mc":[{"id":"1.168230757","rc":[{"batb":[[0,1.93,379.2],[1,1.92,32.73],[2,1.91,333.92]],"batl":[[0,2.02,252.34],[1,2.04,278.81]],"ltp":0.0,"tv":0.0,"id":2263603}]}]}
{"op":"mcm","clk":"1009560328","pt":1580666943594,"mc":[{"id":"1.168230757","rc":[{"batb":[[0,1.96,62.32],[1,1.77,43.04],[2,1.01,20.51]],"ltp":0.0,"tv":0.0,"id":3622149}]}]}
{"op":"mcm","clk":"1009561285","pt":1580666951476,"mc":[{"id":"1.168230757","rc":[{"batb":[[0,1.76,43.83],[1,1.01,20.51],[2,1.91,0]],"ltp":0.0,"tv":0.0,"id":2263603},{"batb":[[0,1.77,43.04],[1,1.01,20.51],[2,1.01,0]],"ltp":0.0,"tv":0.0,"id":3622149}]}]}
{"op":"mcm","clk":"1009561625","pt":1580666954487,"mc":[{"id":"1.168230757","rc":[{"batb":[[0,1.76,385.65],[1,1.74,452.34],[2,1.01,20.51]],"batl":[[0,2.28,275.05],[1,2.3,198.63]],"ltp":0.0,"tv":0.0,"id":2263603},{"batb":[[0,1.76,43.28]],"ltp":0.0,"tv":0.0,"id":3622149}]}]}
{"op":"mcm","clk":"1009561715","pt":1580666955391,"mc":[{"id":"1.168230757","rc":[{"batb":[[0,1.76,43.59],[1,1.01,20.51],[2,1.01,0]],"ltp":0.0,"tv":0.0,"id":2263603}]}]}
{"op":"mcm","clk":"1009562742","pt":1580666965279,"mc":[{"id":"1.168230757","rc":[{"batb":[[0,1.78,378.55],[1,1.76,478.61],[2,1.01,20.51]],"batl":[[0,2.32,300.26],[1,2.34,189.57]],"ltp":0.0,"tv":0.0,"id":3622149}]}]}
{"op":"mcm","clk":"1009563343","pt":1580666971492,"mc":[{"id":"1.168230757","rc":[{"batb":[[0,1.76,43.28],[1,1.01,20.51],[2,1.01,0]],"ltp":0.0,"tv":0.0,"id":3622149}]}]}
{"op":"mcm","clk":"1009563710","pt":1580666975617,"mc":[{"id":"1.168230757","rc":[{"batb":[[0,1.76,385.9],[1,1.74,452.34],[2,1.63,56.57]],"batl":[[0,1.83,281.11],[1,1.85,374.92]],"ltp":0.0,"tv":0.0,"id":2263603},{"batb":[[0,2.16,46.26],[1,1.94,31.94],[2,1.01,20.51]],"ltp":0.0,"tv":0.0,"id":3622149}]}]}
{"op":"mcm","clk":"1009564665","pt":1580666986035,"mc":[{"id":"1.168230757","rc":[{"batb":[[0,1.63,56.57],[1,1.01,20.51],[2,1.63,0]],"ltp":0.0,"tv":0.0,"id":2263603},{"batb":[[0,1.94,31.94],[1,1.01,20.51],[2,1.01,0]],"ltp":0.0,"tv":0.0,"id":3622149}]}]}
{"op":"mcm","clk":"1009565136","pt":1580666990941,"mc":[{"id":"1.168230757","rc":[{"batb":[[1,1.62,483.06],[2,1.61,299.76]],"batl":[[0,2.04,397.67],[1,2.06,270.97]],"ltp":0.0,"tv":0.0,"id":2263603}]}]}
{"op":"mcm","clk":"1009565409","pt":1580666993407,"mc":[{"id":"1.168230757","rc":[{"batb":[[1,1.01,20.51],[2,1.61,0]],"ltp":0.0,"tv":0.0,"id":2263603}]}]}
{"op":"mcm","clk":"1009565694","pt":1580666996328,"mc":[{"id":"1.168230757","rc":[{"batb":[[0,1.94,353.46],[1,1.92,328.48],[2,1.63,56.57]],"ltp":0.0,"tv":0.0,"id":2263603}]}]}
{"op":"mcm","clk":"1009565762","pt":1580666997152,"mc":[{"id":"1.168230757","rc":[{"batb":[[0,1.94,385.4],[2,1.73,45.79]],"ltp":0.0,"tv":0.0,"id":2263603},{"batb":[[1,1.71,48.47],[2,1.01,20.51]],"ltp":0.0,"tv":0.0,"id":3622149}]}]}
{"op":"mcm","clk":"1009566540","pt":1580667004644,"mc":[{"id":"1.168230757","rc":[{"batb":[[0,1.73,45.79],[1,1.01,20.51],[2,1.73,0]],"ltp":0.0,"tv":0.0,"id":2263603},{"batb":[[0,1.71,48.47],[1,1.01,20.51],[2,1.01,0]],"ltp":0.0,"tv":0.0,"id":3622149}]}]}
{"op":"mcm","clk":"1009566862","pt":1580667007629,"mc":[{"id":"1.168230757","rc":[{"batb":[[1,1.72,442.18],[2,1.7,490.24]],"batl":[[0,2.38,313.28],[1,2.42,349.24]],"ltp":0.0,"tv":0.0,"id":2263603}]}]}
{"op":"mcm","clk":"1009570693","pt":1580667045564,"mc":[{"id":"1.168230757","rc":[{"batl":[[0,1.79,276.52],[1,1.81,401.82]],"ltp":0.0,"tv":0.0,"id":2263603},{"batb":[[0,2.2,43.9],[1,1.94,32.18],[2,1.71,48.47]],"ltp":0.0,"tv":0.0,"id":3622149}]}]}
{"op":"mcm","clk":"1009570787","pt":1580667046464,"mc":[{"id":"1.168230757","rc":[{"batb":[[2,1.01,20.51]],"ltp":0.0,"tv":0.0,"id":3622149}]}]}
{"op":"mcm","clk":"1009571798","pt":1580667056782,"mc":[{"id":"1.168230757","rc":[{"trd":[[1.79,108.53]],"batl":[[0,1.79,167.99]],"ltp":1.79,"tv":108.53,"id":2263603},{"trd":[[2.26,85.96]],"ltp":2.26,"tv":85.96,"id":3622149}],"tv":194.49}]}
{"op":"mcm","clk":"1009572072","pt":1580667059570,"mc":[{"id":"1.168230757","rc":[{"batb":[[0,1.59,62.39],[1,1.01,20.51],[2,1.7,0]],"ltp":1.79,"tv":108.53,"id":2263603},{"batb":[[0,1.94,32.18],[1,1.01,20.51],[2,1.01,0]],"ltp":2.26,"tv":85.96,"id":3622149}]}]}
{"op":"mcm","clk":"1009572364","pt":1580667062451,"mc":[{"id":"1.168230757","rc":[{"batb":[[1,1.56,529.03],[2,1.55,346.11]],"batl":[[0,2.04,320.91],[1,2.06,270.94]],"ltp":1.79,"tv":108.53,"id":2263603}]}]}
{"op":"mcm","clk":"1009572539","pt":1580667064391,"mc":[{"id":"1.168230757","rc":[{"batb":[[1,1.01,20.51],[2,1.55,0]],"ltp":1.79,"tv":108.53,"id":2263603}]}]}
{"op":"mcm","clk":"1009572956","pt":1580667069578,"mc":[{"id":"1.168230757","rc":[{"batb":[[0,1.76,461.37],[1,1.74,452.6],[2,1.59,62.39]],"batl":[[0,1.84,356.25],[1,1.86,368.35]],"ltp":1.79,"tv":108.53,"id":2263603}]}]}
{"op":"mcm","clk":"1009573136","pt":1580667071699,"mc":[{"id":"1.168230757","rc":[{"batb":[[0,1.59,62.39],[1,1.01,20.51],[2,1.59,0]],"ltp":1.79,"tv":108.53,"id":2263603}]}]}
{"op":"mcm","clk":"1009573614","pt":1580667076633,"mc":[{"id":"1.168230757","rc":[{"batb":[[1,1.56,434.5],[2,1.55,345.98]],"batl":[[0,2.04,393.22],[1,2.06,271.05]],"ltp":1.79,"tv":108.53,"id":2263603}]}]}
{"op":"mcm","clk":"1009574087","pt":1580667081603,"mc":[{"id":"1.168230757","rc":[{"batl":[[0,1.62,517.79],[1,1.63,283.33]],"ltp":1.79,"tv":108.53,"id":2263603},{"batb":[[0,2.5,31],[1,2.26,40.6],[2,1.01,20.51]],"ltp":2.26,"tv":85.96,"id":3622149}]}]}
{"op":"mcm","clk":"1009575658","pt":1580667097615,"mc":[{"id":"1.168230757","rc":[{"batb":[[1,1.58,63.1],[2,1.56,434.5]],"ltp":1.79,"tv":108.53,"id":2263603}]}]}
{"op":"mcm","clk":"1009575704","pt":1580667098029,"mc":[{"id":"1.168230757","rc":[{"batb":[[0,1.58,63.1],[1,1.56,434.5],[2,1.55,345.98]],"ltp":1.79,"tv":108.53,"id":2263603},{"batb":[[0,2.5,30.61],[1,2.26,40.13]],"ltp":2.26,"tv":85.96,"id":3622149}]}]}
{"op":"mcm","clk":"1009577548","pt":1580667117855,"mc":[{"id":"1.168230757","rc":[{"batb":[[1,1.47,83.8],[2,1.01,20.51]],"ltp":1.79,"tv":108.53,"id":2263603}]}]}
{"op":"mcm","clk":"1009577874","pt":1580667121540,"mc":[{"id":"1.168230757","rc":[{"batb":[[2,1.45,749.44]],"batl":[[0,1.74,290.66],[1,1.76,439.94]],"ltp":1.79,"tv":108.53,"id":2263603}]}]}
{"op":"mcm","clk":"1009578430","pt":1580667127548,"mc":[{"id":"1.168230757","rc":[{"batb":[[0,1.47,83.8],[1,1.45,749.44],[2,1.44,469.49]],"ltp":1.79,"tv":108.53,"id":2263603},{"batb":[[0,2.26,40.13],[1,1.01,20.51],[2,1.01,0]],"ltp":2.26,"tv":85.96,"id":3622149}]}]}
{"op":"mcm","clk":"1009579423","pt":1580667138267,"mc":[{"id":"1.168230757","rc":[{"batb":[[1,1.01,20.51],[2,1.44,0]],"ltp":1.79,"tv":108.53,"id":2263603}]}]}
{"op":"mcm","clk":"1009579746","pt":1580667141600,"mc":[{"id":"1.168230757","rc":[{"batb":[[0,1.69,49.73],[1,1.68,301.46],[2,1.66,532.28]],"ltp":1.79,"tv":108.53,"id":2263603},{"batb":[[1,2.08,52.01],[2,1.01,20.51]],"ltp":2.26,"tv":85.96,"id":3622149}]}]}
{"op":"mcm","clk":"1009580465","pt":1580667148586,"mc":[{"id":"1.168230757","rc":[{"batb":[[1,1.68,415.99]],"batl":[[0,1.75,402.14],[1,1.77,430.94]],"ltp":1.79,"tv":108.53,"id":2263603}]}]}
{"op":"mcm","clk":"1009581121","pt":1580667155180,"mc":[{"id":"1.168230757","rc":[{"batb":[[0,1.57,64.68],[1,1.01,20.51],[2,1.66,0]],"ltp":1.79,"tv":108.53,"id":2263603},{"batb":[[0,2.08,52.01],[1,1.01,20.51],[2,1.01,0]],"ltp":2.26,"tv":85.96,"id":3622149}]}]}
{"op":"mcm","clk":"1009581474","pt":1580667158498,"mc":[{"id":"1.168230757","rc":[{"batb":[[0,1.58,63.81],[1,1.56,462.56],[2,1.55,345.47]],"batl":[[0,1.89,352.1],[1,1.91,339.16]],"ltp":1.79,"tv":108.53,"id":2263603},{"batb":[[0,2.06,52.72]],"ltp":2.26,"tv":85.96,"id":3622149}]}]}
{"op":"mcm","clk":"1009581836","pt":1580667162221,"mc":[{"id":"1.168230757","rc":[{"batb":[[1,1.01,20.51],[2,1.55,0]],"ltp":1.79,"tv":108.53,"id":2263603}]}]}
{"op":"mcm","clk":"1009582143","pt":1580667165102,"mc":[{"id":"1.168230757","rc":[{"batb":[[0,1.81,346.3],[1,1.79,411.13],[2,1.58,63.81]],"ltp":1.79,"tv":108.53,"id":2263603}]}]}
{"op":"mcm","clk":"1009582307","pt":1580667166586,"mc":[{"id":"1.168230757","rc":[{"batb":[[0,1.83,38.55],[1,1.81,346.3],[2,1.79,411.13]],"ltp":1.79,"tv":108.53,"id":2263603},{"batb":[[1,1.94,31.94],[2,1.01,20.51]],"ltp":2.26,"tv":85.96,"id":3622149}]}]}
{"op":"mcm","clk":"1009583531","pt":1580667177618,"mc":[{"id":"1.168230757","rc":[{"batb":[[0,1.71,48.31],[1,1.01,20.51],[2,1.79,0]],"ltp":1.79,"tv":108.53,"id":2263603},{"batb":[[0,1.94,31.94],[1,1.01,20.51],[2,1.01,0]],"ltp":2.26,"tv":85.96,"id":3622149}]}]}
{"op":"mcm","clk":"1009583817","pt":1580667180511,"mc":[{"id":"1.168230757","rc":[{"batb":[[1,1.7,261.87],[2,1.68,509.6]],"batl":[[0,2.02,342.26],[1,2.04,278.62]],"ltp":1.79,"tv":108.53,"id":2263603}]}]}
{"op":"mcm","clk":"1009584114","pt":1580667183317,"mc":[{"id":"1.168230757","rc":[{"batb":[[1,1.01,20.51],[2,1.68,0]],"ltp":1.79,"tv":108.53,"id":2263603}]}]}
{"op":"mcm","clk":"1009584452","pt":1580667186420,"mc":[{"id":"1.168230757","rc":[{"batb":[[0,1.79,265.71],[1,1.77,426.51],[2,1.71,48.31]],"batl":[[0,1.86,292.69],[1,1.88,356.21]],"ltp":1.79,"tv":108.53,"id":2263603}]}]}
{"op":"mcm","clk":"1009584943","pt":1580667190824,"mc":[{"id":"1.168230757","rc":[{"batb":[[0,1.71,48.31],[1,1.01,20.51],[2,1.71,0]],"ltp":1.79,"tv":108.53,"id":2263603}]}]}
{"op":"mcm","clk":"1009585347","pt":1580667194436,"mc":[{"id":"1.168230757","rc":[{"batb":[[1,1.7,261.87],[2,1.68,509.6]],"batl":[[0,2.02,342.26],[1,2.04,278.62]],"ltp":1.79,"tv":108.53,"id":2263603}]}]}
{"op":"mcm","clk":"1009586065","pt":1580667201432,"mc":[{"id":"1.168230757","rc":[{"batb":[[1,1.01,20.51],[2,1.68,0]],"ltp":1.79,"tv":108.53,"id":2263603}]}]}
{"op":"mcm","clk":"1009586425","pt":1580667204649,"mc":[{"id":"1.168230757","rc":[{"batb":[[1,1.7,261.87],[2,1.68,509.6]],"batl":[[0,1.76,282.05],[1,1.78,423.61]],"ltp":1.79,"tv":108.53,"id":2263603},{"batb":[[0,2.24,41.39],[1,2.04,54.68],[2,1.94,31.94]],"ltp":2.26,"tv":85.96,"id":3622149}]}]}
{"op":"mcm","clk":"1009586458","pt":1580667204930,"mc":[{"id":"1.168230757","rc":[{"batb":[[2,1.01,20.51]],"ltp":2.26,"tv":85.96,"id":3622149}]}]}
{"op":"mcm","clk":"1009587347","pt":1580667213365,"mc":[{"id":"1.168230757","rc":[{"trd":[[1.76,93.01]],"batl":[[0,1.76,189.04]],"ltp":1.76,"tv":201.54,"id":2263603},{"trd":[[2.3,71.15]],"ltp":2.3,"tv":157.1,"id":3622149}],"tv":358.64}]}
{"op":"mcm","clk":"1009587690","pt":1580667216342,"mc":[{"id":"1.168230757","rc":[{"batl":[[0,1.76,254.03]],"ltp":1.76,"tv":201.54,"id":2263603}]}]}
{"op":"mcm","clk":"1009587834","pt":1580667217541,"mc":[{"id":"1.168230757","rc":[{"batb":[[0,1.7,261.87],[1,1.68,509.6],[2,1.56,66.09]],"ltp":1.76,"tv":201.54,"id":2263603},{"batb":[[0,2.04,54.68],[1,1.01,20.51],[2,1.01,0]],"ltp":2.3,"tv":157.1,"id":3622149}]}]}
{"op":"mcm","clk":"1009587907","pt":1580667218267,"mc":[{"id":"1.168230757","rc":[{"batb":[[0,1.56,66.09],[1,1.01,20.51],[2,1.56,0]],"ltp":1.76,"tv":201.54,"id":2263603}]}]}
{"op":"mcm","clk":"1009588256","pt":1580667221449,"mc":[{"id":"1.168230757","rc":[{"batb":[[0,1.56,394.83],[1,1.55,344.69],[2,1.01,20.51]],"batl":[[0,1.93,280.3],[1,1.95,318.52]],"ltp":1.76,"tv":201.54,"id":2263603}]}]}
{"op":"mcm","clk":"1009588399","pt":1580667222769,"mc":[{"id":"1.168230757","rc":[{"batb":[[0,1.56,66.09],[1,1.01,20.51],[2,1.01,0]],"ltp":1.76,"tv":201.54,"id":2263603}]}]}
{"op":"mcm","clk":"1009589049","pt":1580667228447,"mc":[{"id":"1.168230757","rc":[{"batb":[[0,1.67,300.54],[1,1.66,267.44],[2,1.56,66.09]],"batl":[[0,1.73,313.33],[1,1.75,447.54]],"ltp":1.76,"tv":201.54,"id":2263603}]}]}
{"op":"mcm","clk":"1009589165","pt":1580667229765,"mc":[{"id":"1.168230757","rc":[{"batb":[[0,1.56,66.09],[1,1.01,20.51],[2,1.56,0]],"ltp":1.76,"tv":201.54,"id":2263603}]}]}
{"op":"mcm","clk":"1009589495","pt":1580667232841,"mc":[{"id":"1.168230757","rc":[{"batb":[[0,1.56,395.3],[1,1.55,344.69],[2,1.01,20.51]],"batl":[[0,1.93,279.92],[1,1.95,318.52]],"ltp":1.76,"tv":201.54,"id":2263603}]}]}
{"op":"mcm","clk":"1009591053","pt":1580667247397,"mc":[{"id":"1.168230757","rc":[{"batb":[[0,1.56,66.09],[1,1.01,20.51],[2,1.01,0]],"ltp":1.76,"tv":201.54,"id":2263603}]}]}
{"op":"mcm","clk":"1009591501","pt":1580667251578,"mc":[{"id":"1.168230757","rc":[{"batb":[[0,1.56,395.3],[1,1.55,344.69],[2,1.41,101.18]],"batl":[[0,1.61,324.52],[1,1.62,289.69]],"ltp":1.76,"tv":201.54,"id":2263603},{"batb":[[0,2.56,29.03],[1,2.2,43.43],[2,1.01,20.51]],"ltp":2.3,"tv":157.1,"id":3622149}]}]}
{"op":"mcm","clk":"1009591602","pt":1580667252507,"mc":[{"id":"1.168230757","rc":[{"batb":[[2,1.92,394.91]],"ltp":2.3,"tv":157.1,"id":3622149}]}]}
{"op":"mcm","clk":"1009593251","pt":1580667267609,"mc":[{"id":"1.168230757","rc":[{"batb":[[0,1.41,101.18],[1,1.4,451],[2,1.01,20.51]],"ltp":1.76,"tv":201.54,"id":2263603},{"batb":[[0,2.2,43.43],[1,1.92,394.91],[2,1.01,20.51]],"ltp":2.3,"tv":157.1,"id":3622149}]}]}
{"op":"mcm","clk":"1009593596","pt":1580667270519,"mc":[{"id":"1.168230757","rc":[{"batb":[[0,1.41,424],[1,1.4,977.68]],"batl":[[0,1.8,248.95],[1,1.82,394.43]],"ltp":1.76,"tv":201.54,"id":2263603}]}]}
{"op":"mcm","clk":"1009594895","pt":1580667282529,"mc":[{"id":"1.168230757","rc":[{"batb":[[1,1.4,526.68]],"ltp":1.76,"tv":201.54,"id":2263603},{"batb":[[1,1.01,20.51],[2,1.01,0]],"ltp":2.3,"tv":157.1,"id":3622149}]}]}
{"op":"mcm","clk":"1009594993","pt":1580667283600,"mc":[{"id":"1.168230757","rc":[{"batl":[[0,1.45,547.69],[1,1.46,429.11]],"ltp":1.76,"tv":201.54,"id":2263603}]}]}
{"op":"mcm","clk":"1009595096","pt":1580667284492,"mc":[{"id":"1.168230757","rc":[{"batb":[[2,1.27,167.91]],"ltp":1.76,"tv":201.54,"id":2263603},{"batb":[[0,3.1,43.35],[1,2.56,28.72],[2,1.01,20.51]],"ltp":2.3,"tv":157.1,"id":3622149}]}]}
{"op":"mcm","clk":"1009595251","pt":1580667285928,"mc":[{"id":"1.168230757","rc":[{"batb":[[2,1.31,477.51]],"ltp":1.76,"tv":201.54,"id":2263603},{"batb":[[2,2.12,388.65]],"ltp":2.3,"tv":157.1,"id":3622149}]}]}
{"op":"mcm","clk":"1009596085","pt":1580667293597,"mc":[{"id":"1.168230757","rc":[{"batb":[[0,1.31,477.51],[1,1.27,167.91],[2,1.01,20.51]],"ltp":1.76,"tv":201.54,"id":2263603},{"batb":[[0,2.56,28.72],[1,2.12,388.65],[2,1.01,20.51]],"ltp":2.3,"tv":157.1,"id":3622149}]}]}
{"op":"mcm","clk":"1009596294","pt":1580667295630,"mc":[{"id":"1.168230757","rc":[{"batl":[[0,1.41,373.05]],"ltp":1.76,"tv":201.54,"id":2263603}]}]}
{"op":"mcm","clk":"1009596409","pt":1580667296602,"mc":[{"id":"1.168230757","rc":[{"batb":[[1,1.28,523.6],[2,1.27,1035.33]],"batl":[[1,1.61,331.79],[2,1.62,289.66]],"ltp":1.76,"tv":201.54,"id":2263603}]}]}
{"op":"mcm","clk":"1009596504","pt":1580667297604,"mc":[{"id":"1.168230757","rc":[{"batl":[[0,1.61,331.79],[1,1.62,289.66],[2,1.62,0]],"ltp":1.76,"tv":201.54,"id":2263603}]}]}
{"op":"mcm","clk":"1009597589","pt":1580667308070,"mc":[{"id":"1.168230757","rc":[{"trd":[[1.31,746.09]],"batb":[[0,1.31,104.46]],"ltp":1.31,"tv":947.63,"id":2263603}],"tv":1104.74}]}
{"op":"mcm","clk":"1009597962","pt":1580667311431,"mc":[{"id":"1.168230757","rc":[{"batb":[[0,1.28,523.6],[1,1.27,1035.33],[2,1.01,20.51]],"ltp":1.31,"tv":947.63,"id":2263603},{"batb":[[1,1.01,20.51],[2,1.01,0]],"ltp":2.3,"tv":157.1,"id":3622149}]}]}
{"op":"mcm","clk":"1009598076","pt":1580667312549,"mc":[{"id":"1.168230757","rc":[{"batl":[[0,1.31,635.56],[1,1.32,676.52]],"ltp":1.31,"tv":947.63,"id":2263603}]}]}
{"op":"mcm","clk":"1009598152","pt":1580667313343,"mc":[{"id":"1.168230757","rc":[{"batb":[[0,1.28,416.52],[2,1.21,218.26]],"ltp":1.31,"tv":947.63,"id":2263603},{"batb":[[0,4.1,43.98],[1,3.5,32.73],[2,1.01,20.51]],"ltp":2.3,"tv":157.1,"id":3622149}]}]}
{"op":"mcm","clk":"1009598382","pt":1580667315355,"mc":[{"id":"1.168230757","rc":[{"batb":[[2,2.52,574.59]],"ltp":2.3,"tv":157.1,"id":3622149}]}]}
{"op":"mcm","clk":"1009598505","pt":1580667316529,"mc":[{"id":"1.168230757","rc":[{"batl":[[0,1.31,740.29]],"ltp":1.31,"tv":947.63,"id":2263603}]}]}
{"op":"mcm","clk":"1009600630","pt":1580667336464,"mc":[{"id":"1.168230757","rc":[{"batb":[[1,1.27,867.42]],"ltp":1.31,"tv":947.63,"id":2263603},{"batb":[[0,3.5,32.1],[1,2.52,574.59],[2,1.01,20.51]],"ltp":2.3,"tv":157.1,"id":3622149}]}]}
{"op":"mcm","clk":"1009600732","pt":1580667337572,"mc":[{"id":"1.168230757","rc":[{"batb":[[0,1.21,218.26],[1,1.2,119.77],[2,1.01,20.51]],"ltp":1.31,"tv":947.63,"id":2263603}]}]}
{"op":"mcm","clk":"1009600919","pt":1580667339565,"mc":[{"id":"1.168230757","rc":[{"batb":[[0,1.22,1005.63],[1,1.21,1409.02],[2,1.2,119.77]],"batl":[[0,1.39,829.2],[1,1.4,511.32]],"ltp":1.31,"tv":947.63,"id":2263603}]}]}
{"op":"mcm","clk":"1009601018","pt":1580667340570,"mc":[{"id":"1.168230757","rc":[{"batb":[[0,1.21,218.26],[1,1.01,20.51],[2,1.2,0]],"ltp":1.31,"tv":947.63,"id":2263603}]}]}
{"op":"mcm","clk":"1009601193","pt":1580667342261,"mc":[{"id":"1.168230757","rc":[{"batb":[[0,1.29,685.57],[1,1.28,834.76],[2,1.21,218.26]],"batl":[[0,1.32,410.51],[1,1.33,656.77]],"ltp":1.31,"tv":947.63,"id":2263603}]}]}
{"op":"mcm","clk":"1009601321","pt":1580667343548,"mc":[{"id":"1.168230757","rc":[{"batb":[[0,1.29,369.33]],"ltp":1.31,"tv":947.63,"id":2263603}]}]}
{"op":"mcm","clk":"1009601382","pt":1580667344174,"mc":[{"id":"1.168230757","rc":[{"batb":[[2,1.22,111.98]],"ltp":1.31,"tv":947.63,"id":2263603}]}]}
{"op":"mcm","clk":"1009601622","pt":1580667346556,"mc":[{"id":"1.168230757","rc":[{"batb":[[0,1.22,111.98],[1,1.21,218.26],[2,1.01,20.51]],"ltp":1.31,"tv":947.63,"id":2263603}]}]}
{"op":"mcm","clk":"1009601908","pt":1580667349555,"mc":[{"id":"1.168230757","rc":[{"batb":[[0,1.22,781.48],[1,1.21,1408.48]],"batl":[[0,1.38,592.93],[1,1.39,534.79]],"ltp":1.31,"tv":947.63,"id":2263603}]}]}
{"op":"mcm","clk":"1009602379","pt":1580667354583,"mc":[{"id":"1.168230757","rc":[{"batb":[[0,1.32,75.62],[1,1.22,781.48],[2,1.21,1408.48]],"ltp":1.31,"tv":947.63,"id":2263603}]}]}
{"op":"mcm","clk":"1009602415","pt":1580667354956,"mc":[{"id":"1.168230757","rc":[{"trd":[[1.32,11.88]],"batb":[[0,1.32,69.68]],"ltp":1.32,"tv":959.51,"id":2263603}],"tv":1116.61}]}
{"op":"mcm","clk":"1009602544","pt":1580667356474,"mc":[{"id":"1.168230757","rc":[{"batb":[[0,1.22,781.48],[1,1.21,1408.48],[2,1.01,20.51]],"ltp":1.32,"tv":959.51,"id":2263603}]}]}
{"op":"mcm","clk":"1009602731","pt":1580667358473,"mc":[{"id":"1.168230757","rc":[{"batl":[[0,8,1.68]],"ltp":2.3,"tv":157.1,"id":3622149}]}]}
{"op":"mcm","clk":"1009604084","pt":1580667372589,"mc":[{"id":"1.168230757","rc":[{"batb":[[0,1.22,669.5]],"ltp":1.32,"tv":959.51,"id":2263603}]}]}
{"op":"mcm","clk":"1009604234","pt":1580667374289,"mc":[{"id":"1.168230757","rc":[{"batl":[[0,1.25,1234.21],[1,1.26,866.94]],"ltp":1.32,"tv":959.51,"id":2263603}]}]}
{"op":"mcm","clk":"1009604334","pt":1580667375289,"mc":[{"id":"1.168230757","rc":[{"batb":[[2,1.17,285.14]],"ltp":1.32,"tv":959.51,"id":2263603},{"batb":[[0,4.9,29.27],[1,4,45.32],[2,2.52,574.59]],"batl":[[0,8,1.93]],"ltp":2.3,"tv":157.1,"id":3622149}]}]}
{"op":"mcm","clk":"1009604447","pt":1580667376424,"mc":[{"id":"1.168230757","rc":[{"batb":[[2,1.18,131.51]],"ltp":1.32,"tv":959.51,"id":2263603}]}]}
{"op":"mcm","clk":"1009604979","pt":1580667381307,"mc":[{"id":"1.168230757","rc":[{"batl":[[0,8,1.68]],"ltp":2.3,"tv":157.1,"id":3622149}]}]}
{"op":"mcm","clk":"1009605252","pt":1580667384410,"mc":[{"id":"1.168230757","rc":[{"trd":[[1.25,1.01]],"batl":[[0,1.25,1233.2]],"ltp":1.25,"tv":960.52,"id":2263603},{"trd":[[5,0.25]],"ltp":5.0,"tv":157.35,"id":3622149}],"tv":1117.87}]}
{"op":"mcm","clk":"1009605709","pt":1580667389327,"mc":[{"id":"1.168230757","rc":[{"trd":[[1.22,58.82]],"batb":[[0,1.22,640.09]],"ltp":1.22,"tv":1019.33,"id":2263603}],"tv":1176.69}]}
{"op":"mcm","clk":"1009605836","pt":1580667390590,"mc":[{"id":"1.168230757","rc":[{"batb":[[0,1.18,131.51],[1,1.17,285.14],[2,1.01,20.51]],"ltp":1.22,"tv":1019.33,"id":2263603},{"batb":[[0,4,45.32],[1,2.52,574.59],[2,1.01,20.51]],"ltp":5.0,"tv":157.35,"id":3622149}]}]}
{"op":"mcm","clk":"1009606136","pt":1580667393647,"mc":[{"id":"1.168230757","rc":[{"batb":[[1,1.17,1701.01],[2,1.16,1095.69]],"batl":[[0,1.31,797.53],[1,1.32,682.3]],"ltp":1.22,"tv":1019.33,"id":2263603},{"batb":[[0,4.1,44.38]],"ltp":5.0,"tv":157.35,"id":3622149}]}]}
{"op":"mcm","clk":"1009606223","pt":1580667394648,"mc":[{"id":"1.168230757","rc":[{"batb":[[1,1.17,285.14],[2,1.01,20.51]],"ltp":1.22,"tv":1019.33,"id":2263603}]}]}
{"op":"mcm","clk":"1009606407","pt":1580667396581,"mc":[{"id":"1.168230757","rc":[{"batb":[[0,1.23,710.85],[1,1.22,1129.2],[2,1.18,131.51]],"batl":[[0,1.26,1008.25],[1,1.27,833.98]],"ltp":1.22,"tv":1019.33,"id":2263603}]}]}
{"op":"mcm","clk":"1009606674","pt":1580667399571,"mc":[{"id":"1.168230757","rc":[{"batb":[[0,1.18,131.51],[1,1.17,285.14],[2,1.01,20.51]],"ltp":1.22,"tv":1019.33,"id":2263603}]}]}
{"op":"mcm","clk":"1009606941","pt":1580667402591,"mc":[{"id":"1.168230757","rc":[{"batb":[[1,1.17,1701.01],[2,1.16,1095.69]],"batl":[[0,1.31,797.53],[1,1.32,682.3]],"ltp":1.22,"tv":1019.33,"id":2263603}]}]}
{"op":"mcm","clk":"1009607601","pt":1580667409593,"mc":[{"id":"1.168230757","rc":[{"batb":[[0,1.17,1701.01],[1,1.16,1095.69],[2,1.01,20.51]],"ltp":1.22,"tv":1019.33,"id":2263603},{"batb":[[1,1.01,20.51],[2,1.01,0]],"ltp":5.0,"tv":157.35,"id":3622149}]}]}
{"op":"mcm","clk":"1009607677","pt":1580667410648,"mc":[{"id":"1.168230757","rc":[{"batl":[[0,1.2,1401.54],[1,1.21,1029.52]],"ltp":1.22,"tv":1019.33,"id":2263603}]}]}
{"op":"mcm","clk":"1009607746","pt":1580667411446,"mc":[{"id":"1.168230757","rc":[{"batb":[[0,1.17,1415.87],[2,1.13,363.27]],"ltp":1.22,"tv":1019.33,"id":2263603},{"batb":[[0,5.8,39.5],[1,4.9,28.48],[2,1.01,20.51]],"ltp":5.0,"tv":157.35,"id":3622149}]}]}
{"op":"mcm","clk":"1009607772","pt":1580667411761,"mc":[{"id":"1.168230757","rc":[{"batb":[[0,4.9,28.48],[1,1.01,20.51],[2,1.01,0]],"ltp":5.0,"tv":157.35,"id":3622149}]}]}
{"op":"mcm","clk":"1009607923","pt":1580667413571,"mc":[{"id":"1.168230757","rc":[{"batb":[[2,1.13,548.34]],"ltp":1.22,"tv":1019.33,"id":2263603},{"batb":[[1,2.9,543.26],[2,1.01,20.51]],"ltp":5.0,"tv":157.35,"id":3622149}]}]}
{"op":"mcm","clk":"1009608835","pt":1580667423471,"mc":[{"id":"1.168230757","rc":[{"batb":[[0,1.13,548.34],[1,1.01,20.51],[2,1.13,0]],"ltp":1.22,"tv":1019.33,"id":2263603}]}]}
{"op":"mcm","clk":"1009609117","pt":1580667426486,"mc":[{"id":"1.168230757","rc":[{"batl":[[0,1.17,300]],"ltp":1.22,"tv":1019.33,"id":2263603}]}]}
{"op":"mcm","clk":"1009609394","pt":1580667429395,"mc":[{"id":"1.168230757","rc":[{"trd":[[1.17,600]],"batb":[[0,1.18,746.47],[1,1.17,1446.78],[2,1.13,548.34]],"batl":[[0,1.2,370.26],[1,1.21,1142.3]],"ltp":1.17,"tv":1619.33,"id":2263603}],"tv":1776.69}]}
{"op":"mcm","clk":"1009609475","pt":1580667430495,"mc":[{"id":"1.168230757","rc":[{"batb":[[0,1.13,548.34],[1,1.01,20.51],[2,1.13,0]],"ltp":1.17,"tv":1619.33,"id":2263603}]}]}
{"op":"mcm","clk":"1009609658","pt":1580667432492,"mc":[{"id":"1.168230757","rc":[{"batl":[[0,6.8,37.86]],"ltp":5.0,"tv":157.35,"id":3622149}]}]}
{"op":"mcm","clk":"1009609915","pt":1580667435499,"mc":[{"id":"1.168230757","rc":[{"batb":[[0,1.14,1304.21],[1,1.13,1823.36],[2,1.01,2554.06]],"batl":[[0,1.24,893.21],[1,1.25,919.12]],"ltp":1.17,"tv":1619.33,"id":2263603}]}]}
{"op":"mcm","clk":"1009610530","pt":1580667442608,"mc":[{"id":"1.168230757","rc":[{"batb":[[2,1.02,1266.78]],"ltp":1.17,"tv":1619.33,"id":2263603}]}]}
{"op":"mcm","clk":"1009610955","pt":1580667447624,"mc":[{"id":"1.168230757","rc":[{"batb":[[1,1.13,1638.29]],"ltp":1.17,"tv":1619.33,"id":2263603}]}]}
{"op":"mcm","clk":"1009610991","pt":1580667447991,"mc":[{"id":"1.168230757","rc":[{"batl":[[0,1.16,887.17],[1,1.17,1438.82]],"ltp":1.17,"tv":1619.33,"id":2263603}]}]}
{"op":"mcm","clk":"1009611072","pt":1580667448989,"mc":[{"id":"1.168230757","rc":[{"batb":[[2,1.12,417.01]],"ltp":1.17,"tv":1619.33,"id":2263603},{"batb":[[0,6.8,27.46],[1,6,36.19],[2,2.9,543.26]],"ltp":5.0,"tv":157.35,"id":3622149}]}]}
{"op":"mcm","clk":"1009611395","pt":1580667452519,"mc":[{"id":"1.168230757","rc":[{"batl":[[2,1.3,2206.75]],"ltp":1.17,"tv":1619.33,"id":2263603}]}]}
{"op":"mcm","clk":"1009612174","pt":1580667460629,"mc":[{"id":"1.168230757","rc":[{"batb":[[1,1.13,1275.02],[2,1.12,415.13]],"batl":[[2,1.3,0]],"ltp":1.17,"tv":1619.33,"id":2263603},{"batb":[[0,6,36.19],[1,2.9,543.26],[2,1.01,20.51]],"ltp":5.0,"tv":157.35,"id":3622149}]}]}
{"op":"mcm","clk":"1009612247","pt":1580667461427,"mc":[{"id":"1.168230757","rc":[{"batb":[[0,1.12,415.13],[1,1.11,223.98],[2,1.03,844.52]],"ltp":1.17,"tv":1619.33,"id":2263603}]}]}
{"op":"mcm","clk":"1009612692","pt":1580667465605,"mc":[{"id":"1.168230757","rc":[{"batb":[[0,1.12,2831.37]],"batl":[[0,1.18,564.7],[1,1.19,1278.83]],"ltp":1.17,"tv":1619.33,"id":2263603}]}]}
{"op":"mcm","clk":"1009612700","pt":1580667465712,"mc":[{"id":"1.168230757","rc":[{"batb":[[0,1.12,415.13]],"ltp":1.17,"tv":1619.33,"id":2263603}]}]}
{"op":"mcm","clk":"1009612848","pt":1580667467543,"mc":[{"id":"1.168230757","rc":[{"batb":[[1,1.03,844.52],[2,1.02,1266.78]],"ltp":1.17,"tv":1619.33,"id":2263603}]}]}
{"op":"mcm","clk":"1009612934","pt":1580667468644,"mc":[{"id":"1.168230757","rc":[{"batb":[[0,1.16,1198.46],[1,1.15,1336.83],[2,1.12,415.13]],"ltp":1.17,"tv":1619.33,"id":2263603}]}]}
{"op":"mcm","clk":"1009613024","pt":1580667469643,"mc":[{"id":"1.168230757","rc":[{"batb":[[0,1.16,1502.09],[2,1.13,381.29]],"ltp":1.17,"tv":1619.33,"id":2263603},{"batb":[[1,5,26.99],[2,2.9,543.26]],"ltp":5.0,"tv":157.35,"id":3622149}]}]}
{"op":"mcm","clk":"1009613179","pt":1580667471427,"mc":[{"id":"1.168230757","rc":[{"batb":[[2,1.13,566.35]],"ltp":1.17,"tv":1619.33,"id":2263603}]}]}
{"op":"mcm","clk":"1009613586","pt":1580667476552,"mc":[{"id":"1.168230757","rc":[{"batb":[[2,1.13,381.29]],"ltp":1.17,"tv":1619.33,"id":2263603}]}]}
{"op":"mcm","clk":"1009613639","pt":1580667477347,"mc":[{"id":"1.168230757","rc":[{"batb":[[0,1.13,381.29],[1,1.03,844.52],[2,1.02,1266.78]],"ltp":1.17,"tv":1619.33,"id":2263603},{"batb":[[0,5,26.99],[1,2.9,543.26],[2,1.01,20.51]],"ltp":5.0,"tv":157.35,"id":3622149}]}]}
{"op":"mcm","clk":"1009613814","pt":1580667479618,"mc":[{"id":"1.168230757","rc":[{"batb":[[1,1.11,223.98],[2,1.03,844.52]],"ltp":1.17,"tv":1619.33,"id":2263603}]}]}
{"op":"mcm","clk":"1009613872","pt":1580667480353,"mc":[{"id":"1.168230757","rc":[{"batb":[[0,1.13,1732.71],[1,1.12,1250.42],[2,1.11,223.98]],"batl":[[0,1.23,1349.31],[1,1.24,952.52]],"ltp":1.17,"tv":1619.33,"id":2263603}]}]}
{"op":"mcm","clk":"1009615145","pt":1580667494589,"mc":[{"id":"1.168230757","rc":[{"batb":[[2,1.03,844.52]],"ltp":1.17,"tv":1619.33,"id":2263603},{"batb":[[1,1.01,20.51],[2,1.01,0]],"ltp":5.0,"tv":157.35,"id":3622149}]}]}
{"op":"mcm","clk":"1009615246","pt":1580667495649,"mc":[{"id":"1.168230757","rc":[{"batb":[[2,1.09,520.32]],"batl":[[0,1.15,1099],[1,1.16,1434.31]],"ltp":1.17,"tv":1619.33,"id":2263603},{"batb":[[0,7,25.41],[1,5.9,37.45],[2,5,26.99]],"ltp":5.0,"tv":157.35,"id":3622149}]}]}
{"op":"mcm","clk":"1009615314","pt":1580667496343,"mc":[{"id":"1.168230757","rc":[{"batb":[[2,1.01,20.51]],"ltp":5.0,"tv":157.35,"id":3622149}]}]}
{"op":"mcm","clk":"1009615479","pt":1580667498073,"mc":[{"id":"1.168230757","rc":[{"batb":[[2,3.25,522.54]],"ltp":5.0,"tv":157.35,"id":3622149}]}]}
{"op":"mcm","clk":"1009622910","pt":1580667578574,"mc":[{"id":"1.168230757","rc":[{"batb":[[0,1.09,520.32],[1,1.08,323.67],[2,1.03,844.52]],"ltp":1.17,"tv":1619.33,"id":2263603},{"batb":[[0,5.9,37.45],[1,3.25,522.54],[2,1.01,20.51]],"ltp":5.0,"tv":157.35,"id":3622149}]}]}
{"op":"mcm","clk":"1009623263","pt":1580667583378,"mc":[{"id":"1.168230757","rc":[{"batb":[[0,1.1,1338.61],[1,1.09,1855.34],[2,1.08,323.67]],"batl":[[0,1.19,1343.99],[1,1.2,1106.92]],"ltp":1.17,"tv":1619.33,"id":2263603}]}]}
{"op":"mcm","clk":"1009623596","pt":1580667588054,"mc":[{"id":"1.168230757","rc":[{"batb":[[0,1.09,520.32],[1,1.08,323.67],[2,1.03,844.52]],"ltp":1.17,"tv":1619.33,"id":2263603}]}]}
{"op":"mcm","clk":"1009623700","pt":1580667589574,"mc":[{"id":"1.168230757","rc":[{"batb":[[1,1.03,844.52],[2,1.02,1266.78]],"ltp":1.17,"tv":1619.33,"id":2263603}]}]}
{"op":"mcm","clk":"1009623930","pt":1580667591467,"mc":[{"id":"1.168230757","rc":[{"batb":[[0,1.1,1338.61],[1,1.09,1855.34],[2,1.03,844.52]],"batl":[[0,1.12,2132.34],[1,1.13,477.37]],"ltp":1.17,"tv":1619.33,"id":2263603}]}]}
{"op":"mcm","clk":"1009623964","pt":1580667591988,"mc":[{"id":"1.168230757","rc":[{"batb":[[2,1.06,750.39]],"ltp":1.17,"tv":1619.33,"id":2263603},{"batb":[[0,8.8,15.19],[1,7,24.71],[2,3.25,522.54]],"ltp":5.0,"tv":157.35,"id":3622149}]}]}
{"op":"mcm","clk":"1009624026","pt":1580667592782,"mc":[{"id":"1.168230757","rc":[{"batb":[[2,1.06,1209.6]],"ltp":1.17,"tv":1619.33,"id":2263603}]}]}
{"op":"mcm","clk":"1009625073","pt":1580667606567,"mc":[{"id":"1.168230757","rc":[{"batb":[[0,1.06,1209.6],[1,1.03,844.52],[2,1.02,1266.78]],"ltp":1.17,"tv":1619.33,"id":2263603},{"batb":[[0,7,24.71],[1,3.25,522.54],[2,1.01,20.51]],"ltp":5.0,"tv":157.35,"id":3622149}]}]}
{"op":"mcm","clk":"1009625324","pt":1580667609610,"mc":[{"id":"1.168230757","rc":[{"batb":[[0,1.07,2209.59],[1,1.06,1741.1],[2,1.03,844.52]],"batl":[[0,1.15,1085.57],[1,1.16,1447.63]],"ltp":1.17,"tv":1619.33,"id":2263603}]}]}
{"op":"mcm","clk":"1009626268","pt":1580667620406,"mc":[{"id":"1.168230757","rc":[{"batb":[[0,1.06,1209.6],[1,1.03,844.52],[2,1.02,1266.78]],"ltp":1.17,"tv":1619.33,"id":2263603}]}]}
{"op":"mcm","clk":"1009626653","pt":1580667625029,"mc":[{"id":"1.168230757","rc":[{"batb":[[0,1.09,2685.92],[1,1.06,1209.6],[2,1.03,844.52]],"batl":[[0,1.11,1458.88],[1,1.12,1168.12]],"ltp":1.17,"tv":1619.33,"id":2263603}]}]}
{"op":"mcm","clk":"1009626783","pt":1580667626628,"mc":[{"id":"1.168230757","rc":[{"batb":[[1,1.06,750.39]],"ltp":1.17,"tv":1619.33,"id":2263603},{"batb":[[1,1.01,20.51],[2,1.01,0]],"ltp":5.0,"tv":157.35,"id":3622149}]}]}
{"op":"mcm","clk":"1009626844","pt":1580667627518,"mc":[{"id":"1.168230757","rc":[{"batb":[[0,1.06,750.39],[1,1.03,844.52],[2,1.02,1266.78]],"ltp":1.17,"tv":1619.33,"id":2263603}]}]}
{"op":"mcm","clk":"1009627061","pt":1580667630221,"mc":[{"id":"1.168230757","rc":[{"batb":[[1,1.05,569.11],[2,1.03,844.52]],"ltp":1.17,"tv":1619.33,"id":2263603},{"batb":[[1,3.6,509.19],[2,1.01,20.51]],"ltp":5.0,"tv":157.35,"id":3622149}]}]}
{"op":"mcm","clk":"1009627248","pt":1580667632237,"mc":[{"id":"1.168230757","rc":[{"batb":[[0,1.07,2220.28],[1,1.06,1271.1],[2,1.05,569.11]],"batl":[[0,1.15,1075.76],[1,1.16,1457.35]],"ltp":1.17,"tv":1619.33,"id":2263603}]}]}
{"op":"mcm","clk":"1009627602","pt":1580667636603,"mc":[{"id":"1.168230757","rc":[{"batl":[[0,1.09,21.85],[1,1.15,1075.76],[2,1.16,1457.35]],"ltp":1.17,"tv":1619.33,"id":2263603}]}]}
{"op":"mcm","clk":"1009627792","pt":1580667639314,"mc":[{"id":"1.168230757","rc":[{"batl":[[0,1.15,1075.76],[1,1.16,1457.35],[2,1.16,0]],"ltp":1.17,"tv":1619.33,"id":2263603}]}]}
{"op":"mcm","clk":"1009628176","pt":1580667643931,"mc":[{"id":"1.168230757","rc":[{"batb":[[0,1.06,750.39],[1,1.05,569.11],[2,1.03,844.52]],"ltp":1.17,"tv":1619.33,"id":2263603}]}]}
{"op":"mcm","clk":"1009628396","pt":1580667646648,"mc":[{"id":"1.168230757","rc":[{"batb":[[1,1.03,844.52],[2,1.02,1266.78]],"ltp":1.17,"tv":1619.33,"id":2263603}]}]}
{"op":"mcm","clk":"1009628458","pt":1580667647439,"mc":[{"id":"1.168230757","rc":[{"batb":[[0,1.13,1756.41],[1,1.12,1232.85],[2,1.09,556.12]],"ltp":1.17,"tv":1619.33,"id":2263603},{"batb":[[1,5.8,39.03],[2,3.6,509.19]],"ltp":5.0,"tv":157.35,"id":3622149}]}]}
{"op":"mcm","clk":"1009629246","pt":1580667656548,"mc":[{"id":"1.168230757","rc":[{"trd":[[1.13,44.58]],"batb":[[0,1.13,1734.12]],"ltp":1.13,"tv":1663.91,"id":2263603}],"tv":1821.27}]}
{"op":"mcm","clk":"1009629358","pt":1580667657630,"mc":[{"id":"1.168230757","rc":[{"batb":[[0,1.09,556.12],[1,1.07,378.39],[2,1.05,506.71]],"ltp":1.13,"tv":1663.91,"id":2263603},{"batb":[[0,5.8,39.03],[1,3.6,509.19],[2,1.01,20.51]],"ltp":5.0,"tv":157.35,"id":3622149}]}]}
{"op":"mcm","clk":"1009630111","pt":1580667666034,"mc":[{"id":"1.168230757","rc":[{"batb":[[0,1.12,2014.33],[1,1.11,605.04],[2,1.09,556.12]],"batl":[[0,1.14,804.94],[1,1.15,1657.85]],"ltp":1.13,"tv":1663.91,"id":2263603}]}]}
{"op":"mcm","clk":"1009630398","pt":1580667668930,"mc":[{"id":"1.168230757","rc":[{"batb":[[0,1.09,556.12],[1,1.07,378.39],[2,1.05,506.71]],"ltp":1.13,"tv":1663.91,"id":2263603}]}]}
{"op":"mcm","clk":"1009630701","pt":1580667672242,"mc":[{"id":"1.168230757","rc":[{"batb":[[0,1.09,3242.04]],"batl":[[0,1.19,602.59],[1,1.2,1201.17]],"ltp":1.13,"tv":1663.91,"id":2263603}]}]}
{"op":"mcm","clk":"1009631492","pt":1580667681606,"mc":[{"id":"1.168230757","rc":[{"batb":[[1,1.05,506.71],[2,1.04,633.39]],"ltp":1.13,"tv":1663.91,"id":2263603}]}]}
{"op":"mcm","clk":"1009631568","pt":1580667682449,"mc":[{"id":"1.168230757","rc":[{"batb":[[1,1.05,1410.85]],"batl":[[0,1.11,1301.93],[1,1.12,1323.67]],"ltp":1.13,"tv":1663.91,"id":2263603},{"batb":[[0,9,35.09],[1,7.2,24.23],[2,3.6,509.19]],"ltp":5.0,"tv":157.35,"id":3622149}]}]}
{"op":"mcm","clk":"1009631811","pt":1580667684883,"mc":[{"id":"1.168230757","rc":[{"batb":[[1,1.05,1979.96]],"ltp":1.13,"tv":1663.91,"id":2263603}]}]}
{"op":"mcm","clk":"1009632378","pt":1580667690554,"mc":[{"id":"1.168230757","rc":[{"batb":[[1,1.05,1473.25]],"ltp":1.13,"tv":1663.91,"id":2263603}]}]}
{"op":"mcm","clk":"1009633371","pt":1580667701410,"mc":[{"id":"1.168230757","rc":[{"batb":[[0,1.05,1473.25],[1,1.04,633.39],[2,1.03,844.52]],"ltp":1.13,"tv":1663.91,"id":2263603},{"batb":[[0,7.2,24.23],[1,3.6,509.19],[2,1.01,20.51]],"ltp":5.0,"tv":157.35,"id":3622149}]}]}
{"op":"mcm","clk":"1009633999","pt":1580667708469,"mc":[{"id":"1.168230757","rc":[{"batb":[[0,1.09,784.99],[1,1.08,1918.54],[2,1.05,1473.25]],"batl":[[0,1.1,728.13],[1,1.11,1915.96]],"ltp":1.13,"tv":1663.91,"id":2263603}]}]}
{"op":"mcm","clk":"1009634362","pt":1580667713102,"mc":[{"id":"1.168230757","rc":[{"batb":[[0,1.05,1473.25],[1,1.04,633.39],[2,1.03,844.52]],"ltp":1.13,"tv":1663.91,"id":2263603}]}]}
{"op":"mcm","clk":"1009634727","pt":1580667717481,"mc":[{"id":"1.168230757","rc":[{"batb":[[0,1.06,2761.94],[1,1.05,1473.25],[2,1.04,633.39]],"batl":[[0,1.15,999.66],[1,1.16,1525.84]],"ltp":1.13,"tv":1663.91,"id":2263603}]}]}
{"op":"mcm","clk":"1009635395","pt":1580667725616,"mc":[{"id":"1.168230757","rc":[{"batb":[[0,1.1,11.49],[1,1.06,2761.94],[2,1.05,1473.25]],"ltp":1.13,"tv":1663.91,"id":2263603}]}]}
{"op":"mcm","clk":"1009636823","pt":1580667743321,"mc":[{"id":"1.168230757","rc":[{"batb":[[2,1.05,904.13]],"ltp":1.13,"tv":1663.91,"id":2263603}]}]}
{"op":"mcm","clk":"1009636988","pt":1580667745447,"mc":[{"id":"1.168230757","rc":[{"trd":[[1.1,22.99]],"batb":[[0,1.06,2761.94],[1,1.05,904.13],[2,1.04,633.39]],"batl":[[0,1.08,2699.3]],"ltp":1.1,"tv":1686.9,"id":2263603},{"batb":[[0,13,15.26],[1,10,28.64],[2,3.6,509.19]],"ltp":5.0,"tv":157.35,"id":3622149}],"tv":1844.26}]}
{"op":"mcm","clk":"1009637501","pt":1580667751631,"mc":[{"id":"1.168230757","rc":[{"batb":[[2,1.03,3349.26]],"ltp":1.1,"tv":1686.9,"id":2263603}]}]}
{"op":"mcm","clk":"1009638347","pt":1580667761547,"mc":[{"id":"1.168230757","rc":[{"trd":[[1.06,22]],"batb":[[0,1.06,2750.94]],"ltp":1.06,"tv":1708.9,"id":2263603}],"tv":1866.26}]}
{"op":"mcm","clk":"1009638449","pt":1580667762641,"mc":[{"id":"1.168230757","rc":[{"batb":[[1,1.03,3349.26],[2,1.02,1266.78]],"ltp":1.06,"tv":1708.9,"id":2263603},{"batb":[[0,10,28.64],[1,3.6,509.19],[2,1.01,20.51]],"ltp":5.0,"tv":157.35,"id":3622149}]}]}
{"op":"mcm","clk":"1009638529","pt":1580667763544,"mc":[{"id":"1.168230757","rc":[{"batb":[[0,1.03,3349.26],[1,1.02,1266.78],[2,1.01,2554.06]],"ltp":1.06,"tv":1708.9,"id":2263603}]}]}
{"op":"mcm","clk":"1009638619","pt":1580667764484,"mc":[{"id":"1.168230757","rc":[{"batl":[[0,1.06,1.68]],"ltp":1.06,"tv":1708.9,"id":2263603}]}]}
{"op":"mcm","clk":"1009638705","pt":1580667765464,"mc":[{"id":"1.168230757","rc":[{"batb":[[1,9.8,28.95],[2,3.6,509.19]],"ltp":5.0,"tv":157.35,"id":3622149}]}]}
{"op":"mcm","clk":"1009638778","pt":1580667766243,"mc":[{"id":"1.168230757","rc":[{"batb":[[0,1.03,3339.11]],"ltp":1.06,"tv":1708.9,"id":2263603},{"batb":[[0,9.8,28.95],[1,3.6,509.19],[2,1.01,20.51]],"ltp":5.0,"tv":157.35,"id":3622149}]}]}
{"op":"mcm","clk":"1009638928","pt":1580667768277,"mc":[{"id":"1.168230757","rc":[{"batb":[[0,1.04,2813.63],[1,1.03,3339.11],[2,1.02,1266.78]],"batl":[[0,1.1,1546.59],[1,1.11,1104.87]],"ltp":1.06,"tv":1708.9,"id":2263603}]}]}
{"op":"mcm","clk":"1009639516","pt":1580667775201,"mc":[{"id":"1.168230757","rc":[{"batb":[[0,1.03,3339.11],[1,1.02,1266.78],[2,1.01,2554.06]],"ltp":1.06,"tv":1708.9,"id":2263603}]}]}
{"op":"mcm","clk":"1009639716","pt":1580667777393,"mc":[{"id":"1.168230757","rc":[{"batb":[[0,1.03,2333.65]],"batl":[[0,1.04,83.3],[1,1.1,1546.59],[2,1.11,1104.87]],"ltp":1.06,"tv":1708.9,"id":2263603}]}]}
{"op":"mcm","clk":"1009639785","pt":1580667778168,"mc":[{"id":"1.168230757","rc":[{"trd":[[1.04,166.6]],"batb":[[0,1.08,2627.5],[1,1.03,2333.65],[2,1.02,1266.78]],"batl":[[0,1.1,1546.59],[1,1.11,1104.87],[2,1.11,0]],"ltp":1.04,"tv":1875.5,"id":2263603}],"tv":2032.86}]}
{"op":"mcm","clk":"1009639911","pt":1580667779557,"mc":[{"id":"1.168230757","rc":[{"trd":[[1.08,184.76]],"batb":[[0,1.08,3157.49],[1,1.03,2209.49]],"ltp":1.08,"tv":2060.26,"id":2263603},{"batb":[[1,7,25.26],[2,3.6,509.19]],"ltp":5.0,"tv":157.35,"id":3622149}],"tv":2217.62}]}
{"op":"mcm","clk":"1009640070","pt":1580667781377,"mc":[{"id":"1.168230757","rc":[{"batb":[[1,1.04,730.48],[2,1.03,2209.49]],"ltp":1.08,"tv":2060.26,"id":2263603}]}]}
{"op":"mcm","clk":"1009640170","pt":1580667782487,"mc":[{"id":"1.168230757","rc":[{"batb":[[0,1.08,3333.17],[1,1.05,1613.49],[2,1.04,730.48]],"ltp":1.08,"tv":2060.26,"id":2263603}]}]}
{"op":"mcm","clk":"1009641208","pt":1580667794495,"mc":[{"id":"1.168230757","rc":[{"batb":[[0,1.04,730.48],[1,1.03,2202.49],[2,1.02,1266.78]],"ltp":1.08,"tv":2060.26,"id":2263603},{"batb":[[0,7,25.26],[1,3.6,509.19],[2,1.01,20.51]],"ltp":5.0,"tv":157.35,"id":3622149}]}]}
{"op":"mcm","clk":"1009641381","pt":1580667796372,"mc":[{"id":"1.168230757","rc":[{"batb":[[0,1.03,2202.49],[1,1.02,1266.78],[2,1.01,2554.06]],"batl":[[0,1.08,1.68]],"ltp":1.08,"tv":2060.26,"id":2263603},{"batb":[[1,1.01,20.51],[2,1.01,0]],"ltp":5.0,"tv":157.35,"id":3622149}]}]}
{"op":"mcm","clk":"1009641603","pt":1580667799360,"mc":[{"id":"1.168230757","rc":[{"batb":[[0,1.04,2815.05],[1,1.03,2202.49],[2,1.02,1266.78]],"batl":[[0,1.15,941.25],[1,1.16,1533.93]],"ltp":1.08,"tv":2060.26,"id":2263603}]}]}
{"op":"mcm","clk":"1009643207","pt":1580667817392,"mc":[{"id":"1.168230757","rc":[{"batb":[[0,1.03,2202.49],[1,1.02,1266.78],[2,1.01,2554.06]],"ltp":1.08,"tv":2060.26,"id":2263603}]}]}
{"op":"mcm","clk":"1009643483","pt":1580667820609,"mc":[{"id":"1.168230757","rc":[{"batb":[[0,1.13,1897.85],[1,1.12,1081.58],[2,1.08,613.17]],"ltp":1.08,"tv":2060.26,"id":2263603},{"batb":[[1,5.5,21.72],[2,1.01,20.51]],"ltp":5.0,"tv":157.35,"id":3622149}]}]}
{"op":"mcm","clk":"1009643563","pt":1580667821498,"mc":[{"id":"1.168230757","rc":[{"batb":[[2,3.35,515.85]],"ltp":5.0,"tv":157.35,"id":3622149}]}]}
{"op":"mcm","clk":"1009644698","pt":1580667832617,"mc":[{"id":"1.168230757","rc":[{"batb":[[0,1.08,613.17],[1,1.07,378.39],[2,1.03,844.52]],"ltp":1.08,"tv":2060.26,"id":2263603},{"batb":[[0,5.5,21.72],[1,3.35,515.85],[2,1.01,20.51]],"ltp":5.0,"tv":157.35,"id":3622149}]}]}
{"op":"mcm","clk":"1009644969","pt":1580667835621,"mc":[{"id":"1.168230757","rc":[{"batb":[[0,5.6,21.48]],"ltp":5.0,"tv":157.35,"id":3622149}]}]}
{"op":"mcm","clk":"1009645159","pt":1580667837514,"mc":[{"id":"1.168230757","rc":[{"batl":[[0,1.21,1312.55],[1,1.22,1052.64]],"ltp":1.08,"tv":2060.26,"id":2263603}]}]}
{"op":"mcm","clk":"1009645239","pt":1580667838398,"mc":[{"id":"1.168230757","rc":[{"batb":[[1,1.03,844.52],[2,1.02,1266.78]],"ltp":1.08,"tv":2060.26,"id":2263603}]}]}
{"op":"mcm","clk":"1009645430","pt":1580667840597,"mc":[{"id":"1.168230757","rc":[{"batb":[[0,1.18,1267.93],[1,1.17,1223.5],[2,1.08,613.17]],"ltp":1.08,"tv":2060.26,"id":2263603}]}]}
{"op":"mcm","clk":"1009645509","pt":1580667841490,"mc":[{"id":"1.168230757","rc":[{"batb":[[1,1.17,1497.63],[2,1.13,386.17]],"ltp":1.08,"tv":2060.26,"id":2263603},{"batb":[[1,4.7,31.39],[2,3.35,515.85]],"ltp":5.0,"tv":157.35,"id":3622149}]}]}
{"op":"mcm","clk":"1009646534","pt":1580667853633,"mc":[{"id":"1.168230757","rc":[{"batb":[[0,1.13,384.68],[1,1.11,223.98],[2,1.03,844.52]],"ltp":1.08,"tv":2060.26,"id":2263603},{"batb":[[0,4.7,31.39],[1,3.35,515.85],[2,1.01,20.51]],"ltp":5.0,"tv":157.35,"id":3622149}]}]}
{"op":"mcm","clk":"1009646961","pt":1580667858540,"mc":[{"id":"1.168230757","rc":[{"batb":[[0,1.13,1978.43],[1,1.12,1005.99],[2,1.11,223.98]],"batl":[[0,1.26,414.19],[1,1.27,847.02]],"ltp":1.08,"tv":2060.26,"id":2263603}]}]}
{"op":"mcm","clk":"1009647669","pt":1580667866427,"mc":[{"id":"1.168230757","rc":[{"batb":[[0,1.13,384.68],[1,1.11,223.98],[2,1.03,844.52]],"ltp":1.08,"tv":2060.26,"id":2263603}]}]}
{"op":"mcm","clk":"1009647866","pt":1580667868531,"mc":[{"id":"1.168230757","rc":[{"batb":[[1,1.03,844.52],[2,1.02,1266.78]],"ltp":1.08,"tv":2060.26,"id":2263603}]}]}
{"op":"mcm","clk":"1009647962","pt":1580667869623,"mc":[{"id":"1.168230757","rc":[{"batb":[[0,1.23,1365.06],[1,1.22,1022.08],[2,1.13,384.68]],"ltp":1.08,"tv":2060.26,"id":2263603}]}]}
{"op":"mcm","clk":"1009648037","pt":1580667870511,"mc":[{"id":"1.168230757","rc":[{"batb":[[1,1.22,1232.4],[2,1.17,283.25]],"ltp":1.08,"tv":2060.26,"id":2263603},{"batb":[[1,3.8,52.4],[2,3.35,515.85]],"ltp":5.0,"tv":157.35,"id":3622149}]}]}
{"op":"mcm","clk":"1009648767","pt":1580667879224,"mc":[{"id":"1.168230757","rc":[{"trd":[[1.23,8.4]],"batb":[[0,1.23,1360.86]],"ltp":1.23,"tv":2068.66,"id":2263603}],"tv":2226.02}]}
{"op":"mcm","clk":"1009648879","pt":1580667880634,"mc":[{"id":"1.168230757","rc":[{"trd":[[1.26,4]],"batl":[[0,1.26,412.19]],"ltp":1.26,"tv":2072.66,"id":2263603}],"tv":2230.02}]}
{"op":"mcm","clk":"1009649007","pt":1580667882407,"mc":[{"id":"1.168230757","rc":[{"batb":[[0,1.23,1258.82]],"ltp":1.26,"tv":2072.66,"id":2263603}]}]}
{"op":"mcm","clk":"1009649251","pt":1580667885631,"mc":[{"id":"1.168230757","rc":[{"batb":[[1,1.22,1339.51]],"batl":[[0,1.26,517.65]],"ltp":1.26,"tv":2072.66,"id":2263603}]}]}
{"op":"mcm","clk":"1009649980","pt":1580667895645,"mc":[{"id":"1.168230757","rc":[{"batb":[[0,1.17,282.31],[1,1.14,169.61],[2,1.03,844.52]],"ltp":1.26,"tv":2072.66,"id":2263603},{"batb":[[0,3.8,52.4],[1,3.35,515.85],[2,1.01,20.51]],"ltp":5.0,"tv":157.35,"id":3622149}]}]}
{"op":"mcm","clk":"1009650340","pt":1580667900482,"mc":[{"id":"1.168230757","rc":[{"batb":[[0,1.18,1138.47],[1,1.17,1634.93],[2,1.14,169.61]],"batl":[[0,1.34,780.18],[1,1.35,612.87]],"ltp":1.26,"tv":2072.66,"id":2263603}]}]}
{"op":"mcm","clk":"1009651596","pt":1580667917555,"mc":[{"id":"1.168230757","rc":[{"batb":[[2,1.03,844.52]],"ltp":1.26,"tv":2072.66,"id":2263603},{"batb":[[1,1.01,20.51],[2,1.01,0]],"ltp":5.0,"tv":157.35,"id":3622149}]}]}
{"op":"mcm","clk":"1009651912","pt":1580667921596,"mc":[{"id":"1.168230757","rc":[{"batb":[[2,1.16,147.77]],"ltp":1.26,"tv":2072.66,"id":2263603},{"batb":[[1,2.72,556.93],[2,1.01,20.51]],"ltp":5.0,"tv":157.35,"id":3622149}]}]}
{"op":"mcm","clk":"1009652121","pt":1580667924571,"mc":[{"id":"1.168230757","rc":[{"batb":[[2,1.03,844.52]],"ltp":1.26,"tv":2072.66,"id":2263603}]}]}
{"op":"mcm","clk":"1009652210","pt":1580667925558,"mc":[{"id":"1.168230757","rc":[{"batb":[[0,1.18,1039.59]],"batl":[[0,1.21,1148.32]],"ltp":1.26,"tv":2072.66,"id":2263603}]}]}
{"op":"mcm","clk":"1009652254","pt":1580667926070,"mc":[{"id":"1.168230757","rc":[{"batb":[[2,1.13,377.99]],"ltp":1.26,"tv":2072.66,"id":2263603},{"batb":[[0,5.7,40.68],[1,4.6,33.99],[2,2.72,556.93]],"ltp":5.0,"tv":157.35,"id":3622149}]}]}
{"op":"mcm","clk":"1009652490","pt":1580667929484,"mc":[{"id":"1.168230757","rc":[{"batb":[[1,1.17,1734.65],[2,1.13,563.05]],"batl":[[0,1.2,391.43],[1,1.21,1148.32]],"ltp":1.26,"tv":2072.66,"id":2263603}]}]}
{"op":"mcm","clk":"1009652621","pt":1580667931400,"mc":[{"id":"1.168230757","rc":[{"batb":[[2,4,581.9]],"ltp":5.0,"tv":157.35,"id":3622149}]}]}
{"op":"mcm","clk":"1009653065","pt":1580667937567,"mc":[{"id":"1.168230757","rc":[{"batb":[[1,1.17,1452.34]],"ltp":1.26,"tv":2072.66,"id":2263603},{"batb":[[0,4.6,33.44],[1,2.72,556.93],[2,1.01,20.51]],"ltp":5.0,"tv":157.35,"id":3622149}]}]}
{"op":"mcm","clk":"1009653121","pt":1580667938297,"mc":[{"id":"1.168230757","rc":[{"batb":[[0,1.13,563.05],[1,1.03,844.52],[2,1.02,1266.78]],"ltp":1.26,"tv":2072.66,"id":2263603}]}]}
{"op":"mcm","clk":"1009653368","pt":1580667941277,"mc":[{"id":"1.168230757","rc":[{"batb":[[0,1.14,675.55],[1,1.13,2470.87],[2,1.03,844.52]],"batl":[[0,1.27,1048.81],[1,1.28,802.21]],"ltp":1.26,"tv":2072.66,"id":2263603}]}]}
{"op":"mcm","clk":"1009653439","pt":1580667942300,"mc":[{"id":"1.168230757","rc":[{"batb":[[0,1.13,563.05],[1,1.03,844.52],[2,1.02,1266.78]],"ltp":1.26,"tv":2072.66,"id":2263603}]}]}
{"op":"mcm","clk":"1009653672","pt":1580667945183,"mc":[{"id":"1.168230757","rc":[{"batb":[[0,1.19,1124.15],[1,1.18,1345.95],[2,1.13,563.05]],"batl":[[0,1.22,1268.25],[1,1.23,1007.52]],"ltp":1.26,"tv":2072.66,"id":2263603}]}]}
{"op":"mcm","clk":"1009653994","pt":1580667949418,"mc":[{"id":"1.168230757","rc":[{"batb":[[0,1.13,563.05],[1,1.03,844.52],[2,1.02,1266.78]],"ltp":1.26,"tv":2072.66,"id":2263603}]}]}
{"op":"mcm","clk":"1009654192","pt":1580667952495,"mc":[{"id":"1.168230757","rc":[{"batb":[[0,1.14,673.29],[1,1.13,2473.15],[2,1.03,844.52]],"batl":[[0,1.27,1050.82],[1,1.28,802.22]],"ltp":1.26,"tv":2072.66,"id":2263603}]}]}
{"op":"mcm","clk":"1009655060","pt":1580667962604,"mc":[{"id":"1.168230757","rc":[{"batb":[[1,1.13,2288.09]],"ltp":1.26,"tv":2072.66,"id":2263603},{"batb":[[1,1.01,20.51],[2,1.01,0]],"ltp":5.0,"tv":157.35,"id":3622149}]}]}
{"op":"mcm","clk":"1009655142","pt":1580667963605,"mc":[{"id":"1.168230757","rc":[{"batb":[[2,1.1,496.72]],"batl":[[0,1.16,1461],[1,1.17,1052.31]],"ltp":1.26,"tv":2072.66,"id":2263603},{"batb":[[0,7,25.1],[1,5.7,39.81],[2,4.6,33.44]],"ltp":5.0,"tv":157.35,"id":3622149}]}]}
{"op":"mcm","clk":"1009655158","pt":1580667963808,"mc":[{"id":"1.168230757","rc":[{"batb":[[2,1.01,20.51]],"ltp":5.0,"tv":157.35,"id":3622149}]}]}
{"op":"mcm","clk":"1009655299","pt":1580667965324,"mc":[{"id":"1.168230757","rc":[{"batb":[[2,3.15,527.59]],"ltp":5.0,"tv":157.35,"id":3622149}]}]}
{"op":"mcm","clk":"1009656115","pt":1580667975526,"mc":[{"id":"1.168230757","rc":[{"batb":[[0,1.1,496.72],[1,1.09,280.77],[2,1.03,844.52]],"ltp":1.26,"tv":2072.66,"id":2263603},{"batb":[[0,5.7,39.81],[1,3.15,527.59],[2,1.01,20.51]],"ltp":5.0,"tv":157.35,"id":3622149}]}]}
{"op":"mcm","clk":"1009656333","pt":1580667978612,"mc":[{"id":"1.168230757","rc":[{"batb":[[0,1.11,935.49],[1,1.1,2212.69],[2,1.09,280.77]],"batl":[[0,1.2,973.28],[1,1.21,1129.92]],"ltp":1.26,"tv":2072.66,"id":2263603}]}]}
{"op":"mcm","clk":"1009656402","pt":1580667979551,"mc":[{"id":"1.168230757","rc":[{"batb":[[0,1.1,496.72],[1,1.09,280.77],[2,1.03,844.52]],"ltp":1.26,"tv":2072.66,"id":2263603}]}]}
{"op":"mcm","clk":"1009656650","pt":1580667982605,"mc":[{"id":"1.168230757","rc":[{"batb":[[0,1.14,2104],[1,1.13,466.73],[2,1.1,496.72]],"batl":[[0,1.17,1659.57],[1,1.18,834.12]],"ltp":1.26,"tv":2072.66,"id":2263603}]}]}
{"op":"mcm","clk":"1009656793","pt":1580667984350,"mc":[{"id":"1.168230757","rc":[{"batb":[[0,1.1,496.72],[1,1.09,280.77],[2,1.03,844.52]],"ltp":1.26,"tv":2072.66,"id":2263603}]}]}
{"op":"mcm","clk":"1009657165","pt":1580667989530,"mc":[{"id":"1.168230757","rc":[{"batb":[[0,1.11,932.92],[1,1.1,2215.29],[2,1.09,280.77]],"batl":[[0,1.2,975.64],[1,1.21,1129.92]],"ltp":1.26,"tv":2072.66,"id":2263603}]}]}
{"op":"mcm","clk":"1009657458","pt":1580667993514,"mc":[{"id":"1.168230757","rc":[{"batb":[[2,1.03,844.52]],"batl":[[0,1.13,2106.12],[1,1.14,478.98]],"ltp":1.26,"tv":2072.66,"id":2263603},{"batb":[[1,1.01,20.51],[2,1.01,0]],"ltp":5.0,"tv":157.35,"id":3622149}]}]}
{"op":"mcm","clk":"1009657516","pt":1580667994349,"mc":[{"id":"1.168230757","rc":[{"batb":[[2,1.08,583.98]],"ltp":1.26,"tv":2072.66,"id":2263603},{"batb":[[0,8.4,16.44],[1,7.4,22.82],[2,1.01,20.51]],"ltp":5.0,"tv":157.35,"id":3622149}]}]}
{"op":"mcm","clk":"1009657694","pt":1580667996557,"mc":[{"id":"1.168230757","rc":[{"batl":[[2,1.21,9]],"ltp":1.26,"tv":2072.66,"id":2263603},{"batb":[[2,3.5,509.54]],"ltp":5.0,"tv":157.35,"id":3622149}]}]}
{"op":"mcm","clk":"1009657943","pt":1580667999553,"mc":[{"id":"1.168230757","rc":[{"trd":[[1.11,173.22]],"batb":[[0,1.11,846.31]],"ltp":1.11,"tv":2245.88,"id":2263603}],"tv":2403.24}]}
{"op":"mcm","clk":"1009658030","pt":1580668000557,"mc":[{"id":"1.168230757","rc":[{"batl":[[2,1.21,0]],"ltp":1.11,"tv":2245.88,"id":2263603}]}]}
{"op":"mcm","clk":"1009658372","pt":1580668004644,"mc":[{"id":"1.168230757","rc":[{"batb":[[0,1.08,583.98],[1,1.06,459.21],[2,1.03,844.52]],"ltp":1.11,"tv":2245.88,"id":2263603},{"batb":[[0,7.4,22.82],[1,3.5,509.54],[2,1.01,20.51]],"ltp":5.0,"tv":157.35,"id":3622149}]}]}
{"op":"mcm","clk":"1009658591","pt":1580668007344,"mc":[{"id":"1.168230757","rc":[{"batb":[[0,1.09,2684.37],[1,1.08,583.98],[2,1.06,459.21]],"batl":[[0,1.15,1887.8],[1,1.16,650.86]],"ltp":1.11,"tv":2245.88,"id":2263603}]}]}
{"op":"mcm","clk":"1009658670","pt":1580668008446,"mc":[{"id":"1.168230757","rc":[{"batb":[[0,1.08,583.98],[1,1.06,459.21],[2,1.03,844.52]],"ltp":1.11,"tv":2245.88,"id":2263603}]}]}
{"op":"mcm","clk":"1009658858","pt":1580668010546,"mc":[{"id":"1.168230757","rc":[{"batb":[[1,1.03,844.52],[2,1.02,1266.78]],"ltp":1.11,"tv":2245.88,"id":2263603}]}]}
{"op":"mcm","clk":"1009659173","pt":1580668014559,"mc":[{"id":"1.168230757","rc":[{"batb":[[1,1.07,378.39],[2,1.03,844.52]],"ltp":1.11,"tv":2245.88,"id":2263603}]}]}
{"op":"mcm","clk":"1009659245","pt":1580668015552,"mc":[{"id":"1.168230757","rc":[{"batb":[[0,1.09,2684.37],[1,1.08,583.98],[2,1.07,378.39]],"batl":[[0,1.11,9],[1,1.15,1887.8],[2,1.16,650.86]],"ltp":1.11,"tv":2245.88,"id":2263603}]}]}
{"op":"mcm","clk":"1009659326","pt":1580668016448,"mc":[{"id":"1.168230757","rc":[{"batl":[[1,1.15,0],[2,1.16,0]],"ltp":1.11,"tv":2245.88,"id":2263603}]}]}
{"op":"mcm","clk":"1009659495","pt":1580668018583,"mc":[{"id":"1.168230757","rc":[{"batb":[[2,1.03,844.52]],"ltp":1.11,"tv":2245.88,"id":2263603}]}]}
{"op":"mcm","clk":"1009659584","pt":1580668019542,"mc":[{"id":"1.168230757","rc":[{"batb":[[2,1.06,814.75]],"batl":[[0,1.11,1305.29],[1,1.12,1326.1]],"ltp":1.11,"tv":2245.88,"id":2263603},{"batb":[[0,9.4,32.26],[1,8,18.96],[2,3.5,509.54]],"ltp":5.0,"tv":157.35,"id":3622149}]}]}
{"op":"mcm","clk":"1009659805","pt":1580668022588,"mc":[{"id":"1.168230757","rc":[{"batb":[[2,1.06,1273.96]],"ltp":1.11,"tv":2245.88,"id":2263603}]}]}
{"op":"mcm","clk":"1009660136","pt":1580668026649,"mc":[{"id":"1.168230757","rc":[{"batl":[[0,1.11,1296.29]],"ltp":1.11,"tv":2245.88,"id":2263603}]}]}
{"op":"mcm","clk":"1009660198","pt":1580668027376,"mc":[{"id":"1.168230757","rc":[{"batb":[[1,1.08,576.58],[2,1.06,1263.65]],"ltp":1.11,"tv":2245.88,"id":2263603},{"batb":[[1,7.8,19.36]],"ltp":5.0,"tv":157.35,"id":3622149}]}]}
{"op":"mcm","clk":"1009660727","pt":1580668033564,"mc":[{"id":"1.168230757","rc":[{"trd":[[1.09,1.06]],"batb":[[0,1.09,2683.31]],"ltp":1.09,"tv":2246.94,"id":2263603},{"trd":[[12.5,0.09]],"ltp":12.5,"tv":157.45,"id":3622149}],"tv":2404.39}]}
{"op":"mcm","clk":"1009660885","pt":1580668035404,"mc":[{"id":"1.168230757","rc":[{"batl":[[0,1.1,300],[1,1.11,1296.29],[2,1.12,1326.1]],"ltp":1.09,"tv":2246.94,"id":2263603}]}]}
{"op":"mcm","clk":"1009661436","pt":1580668042194,"mc":[{"id":"1.168230757","rc":[{"batb":[[1,1.06,1263.65],[2,1.03,844.52]],"ltp":1.09,"tv":2246.94,"id":2263603},{"batb":[[0,7.8,19.36],[1,3.5,509.54],[2,1.01,20.51]],"ltp":12.5,"tv":157.45,"id":3622149}]}]}
{"op":"mcm","clk":"1009661864","pt":1580668048488,"mc":[{"id":"1.168230757","rc":[{"trd":[[1.09,1.24]],"batb":[[0,1.09,2683.22]],"ltp":1.09,"tv":2247.12,"id":2263603}],"tv":2404.57}]}
{"op":"mcm","clk":"1009664111","pt":1580668078640,"mc":[{"id":"1.168230757","rc":[{"batl":[[0,1.11,1296.29],[1,1.12,1326.1],[2,1.12,0]],"ltp":1.09,"tv":2247.12,"id":2263603}]}]}
{"op":"mcm","clk":"1009666575","pt":1580668110378,"mc":[{"id":"1.168230757","rc":[{"batb":[[0,1.06,459.21],[1,1.03,844.52],[2,1.02,1266.78]],"ltp":1.09,"tv":2247.12,"id":2263603},{"batb":[[0,3.5,509.54],[1,1.01,20.51],[2,1.01,0]],"ltp":12.5,"tv":157.45,"id":3622149}]}]}
{"op":"mcm","clk":"1009666884","pt":1580668113564,"mc":[{"id":"1.168230757","rc":[{"batb":[[0,1.07,1125.66],[1,1.06,2081.53],[2,1.03,844.52]],"batl":[[0,1.14,1256.42],[1,1.15,1297.21]],"ltp":1.09,"tv":2247.12,"id":2263603}]}]}
{"op":"mcm","clk":"1009667745","pt":1580668123086,"mc":[{"id":"1.168230757","rc":[{"batl":[[0,1.09,3.03],[1,1.15,0]],"ltp":1.09,"tv":2247.12,"id":2263603}]}]}
{"op":"mcm","clk":"1009667958","pt":1580668125564,"mc":[{"id":"1.168230757","rc":[{"batb":[[1,1.06,1622.32]],"ltp":1.09,"tv":2247.12,"id":2263603}]}]}
{"op":"mcm","clk":"1009668048","pt":1580668126487,"mc":[{"id":"1.168230757","rc":[{"batb":[[1,1.06,2426.69],[2,1.03,2174.32]],"batl":[[0,1.08,1206.7],[1,1.09,1490.07]],"ltp":1.09,"tv":2247.12,"id":2263603},{"batb":[[0,12,18.65],[1,9.6,31.24],[2,3.5,509.54]],"ltp":12.5,"tv":157.45,"id":3622149}]}]}
{"op":"mcm","clk":"1009668274","pt":1580668129273,"mc":[{"id":"1.168230757","rc":[{"batb":[[2,1.03,3179.78]],"ltp":1.09,"tv":2247.12,"id":2263603}]}]}
{"op":"mcm","clk":"1009668720","pt":1580668134556,"mc":[{"id":"1.168230757","rc":[{"trd":[[1.07,2200]],"batb":[[0,1.07,25.66]],"ltp":1.07,"tv":4447.12,"id":2263603}],"tv":4604.57}]}
{"op":"mcm","clk":"1009668794","pt":1580668135596,"mc":[{"id":"1.168230757","rc":[{"batl":[[1,1.09,1188.85]],"ltp":1.07,"tv":4447.12,"id":2263603}]}]}
{"op":"mcm","clk":"1009668861","pt":1580668136288,"mc":[{"id":"1.168230757","rc":[{"batb":[[0,1.03,3179.78],[1,1.02,1266.78],[2,1.01,2554.06]],"batl":[[0,1.09,3.03],[1,1.09,0]],"ltp":1.07,"tv":4447.12,"id":2263603},{"batb":[[0,9.6,31.24],[1,3.5,509.54],[2,1.01,20.51]],"ltp":12.5,"tv":157.45,"id":3622149}]}]}
{"op":"mcm","clk":"1009669216","pt":1580668140508,"mc":[{"id":"1.168230757","rc":[{"batb":[[0,1.04,2811.65],[1,1.03,3179.78],[2,1.02,1266.78]],"batl":[[1,1.11,1784.68],[2,1.12,842.07]],"ltp":1.07,"tv":4447.12,"id":2263603}]}]}
{"op":"mcm","clk":"1009669391","pt":1580668142496,"mc":[{"id":"1.168230757","rc":[{"batb":[[2,1.02,1274.65]],"ltp":1.07,"tv":4447.12,"id":2263603}]}]}
{"op":"mcm","clk":"1009669580","pt":1580668145292,"mc":[{"id":"1.168230757","rc":[{"batl":[[0,1.07,578.94],[1,1.09,3.03],[2,1.11,1784.68]],"ltp":1.07,"tv":4447.12,"id":2263603}]}]}
{"op":"mcm","clk":"1009671425","pt":1580668169646,"mc":[{"id":"1.168230757","rc":[{"batb":[[0,1.03,3179.78],[1,1.02,1274.65],[2,1.01,2561.93]],"batl":[[2,1.11,0]],"ltp":1.07,"tv":4447.12,"id":2263603}]}]}
{"op":"mcm","clk":"1009671509","pt":1580668170629,"mc":[{"id":"1.168230757","rc":[{"batb":[[0,1.03,2174.32]],"ltp":1.07,"tv":4447.12,"id":2263603}]}]}
{"op":"mcm","clk":"1009671664","pt":1580668172511,"mc":[{"id":"1.168230757","rc":[{"trd":[[1.07,3358.46]],"batl":[[0,1.09,3.03],[1,1.09,0]],"ltp":1.07,"tv":5605.59,"id":2263603}],"tv":5763.04}]}
{"op":"mcm","clk":"1009671744","pt":1580668173540,"mc":[{"id":"1.168230757","rc":[{"trd":[[1.09,7.3]],"batb":[[0,1.09,2411.69],[1,1.08,595.54],[2,1.05,908.07]],"batl":[[0,1.11,1784.68],[1,1.12,842.07]],"ltp":1.09,"tv":5611.65,"id":2263603},{"batb":[[1,7.8,20.06],[2,3.5,509.54]],"ltp":12.5,"tv":157.45,"id":3622149}],"tv":5769.1}]}
{"op":"mcm","clk":"1009671817","pt":1580668174637,"mc":[{"id":"1.168230757","rc":[{"batb":[[2,1.05,1477.18]],"ltp":1.09,"tv":5611.65,"id":2263603}]}]}
{"op":"mcm","clk":"1009672116","pt":1580668178635,"mc":[{"id":"1.168230757","rc":[{"trd":[[1.09,1145.08]],"batb":[[0,1.09,1842.8]],"batl":[[1,1.12,686.72]],"ltp":1.09,"tv":6749.42,"id":2263603}],"tv":6906.87}]}
{"op":"mcm","clk":"1009672396","pt":1580668182434,"mc":[{"id":"1.168230757","rc":[{"batb":[[0,1.09,2255.25],[1,1.08,1026.92]],"batl":[[0,1.11,1941.43]],"ltp":1.09,"tv":6749.42,"id":2263603}]}]}
{"op":"mcm","clk":"1009672530","pt":1580668183933,"mc":[{"id":"1.168230757","rc":[{"batl":[[0,1.1,1008.23],[1,1.11,1941.43],[2,1.12,686.72]],"ltp":1.09,"tv":6749.42,"id":2263603}]}]}
{"op":"mcm","clk":"1009673010","pt":1580668189539,"mc":[{"id":"1.168230757","rc":[{"batb":[[1,1.08,431.38]],"ltp":1.09,"tv":6749.42,"id":2263603},{"batb":[[0,7.8,20.06],[1,3.5,509.54],[2,1.01,20.51]],"ltp":12.5,"tv":157.45,"id":3622149}]}]}
{"op":"mcm","clk":"1009673090","pt":1580668190643,"mc":[{"id":"1.168230757","rc":[{"batb":[[0,1.05,1477.18],[1,1.03,844.52],[2,1.02,1274.65]],"batl":[[1,1.11,0],[2,1.12,0]],"ltp":1.09,"tv":6749.42,"id":2263603}]}]}
{"op":"mcm","clk":"1009673275","pt":1580668192870,"mc":[{"id":"1.168230757","rc":[{"batb":[[0,1.06,2758.6],[1,1.05,1477.18],[2,1.04,594.68]],"batl":[[1,1.14,941.12],[2,1.15,1609.77]],"ltp":1.09,"tv":6749.42,"id":2263603}]}]}
{"op":"mcm","clk":"1009673419","pt":1580668194433,"mc":[{"id":"1.168230757","rc":[{"batb":[[0,1.05,1477.18],[1,1.04,594.68],[2,1.03,844.52]],"ltp":1.09,"tv":6749.42,"id":2263603}]}]}
{"op":"mcm","clk":"1009673504","pt":1580668195572,"mc":[{"id":"1.168230757","rc":[{"batb":[[0,1.05,908.07]],"ltp":1.09,"tv":6749.42,"id":2263603}]}]}
{"op":"mcm","clk":"1009673638","pt":1580668197347,"mc":[{"id":"1.168230757","rc":[{"trd":[[1.1,2039.46]],"batb":[[0,1.12,3521.81],[1,1.05,908.07],[2,1.04,594.68]],"batl":[[0,1.14,941.12],[1,1.15,1609.77],[2,1.15,0]],"ltp":1.1,"tv":8765.89,"id":2263603}],"tv":8923.34}]}
{"op":"mcm","clk":"1009673723","pt":1580668198484,"mc":[{"id":"1.168230757","rc":[{"batb":[[0,1.12,5466.27],[1,1.11,1111.96],[2,1.08,609.63]],"ltp":1.1,"tv":8765.89,"id":2263603},{"batb":[[1,6.6,28.64],[2,3.5,509.54]],"ltp":12.5,"tv":157.45,"id":3622149}]}]}
{"op":"mcm","clk":"1009673826","pt":1580668199629,"mc":[{"id":"1.168230757","rc":[{"batb":[[0,1.12,1944.46]],"ltp":1.1,"tv":8765.89,"id":2263603}]}]}
{"op":"mcm","clk":"1009674126","pt":1580668202550,"mc":[{"id":"1.168230757","rc":[{"trd":[[1.12,1980.46]],"batb":[[0,1.12,954.23]],"ltp":1.12,"tv":10746.35,"id":2263603}],"tv":10903.8}]}
{"op":"mcm","clk":"1009674204","pt":1580668203494,"mc":[{"id":"1.168230757","rc":[{"batl":[[1,1.15,1340.76]],"ltp":1.12,"tv":10746.35,"id":2263603}]}]}
{"op":"mcm","clk":"1009674374","pt":1580668205251,"mc":[{"id":"1.168230757","rc":[{"trd":[[1.14,0.78]],"batl":[[0,1.14,940.73]],"ltp":1.14,"tv":10747.13,"id":2263603}],"tv":10904.58}]}
{"op":"mcm","clk":"1009674457","pt":1580668206348,"mc":[{"id":"1.168230757","rc":[{"batb":[[0,1.12,1668.34],[1,1.11,1390.56]],"batl":[[0,1.14,1212.1]],"ltp":1.14,"tv":10747.13,"id":2263603}]}]}
{"op":"mcm","clk":"1009675034","pt":1580668213371,"mc":[{"id":"1.168230757","rc":[{"batb":[[0,1.08,609.63],[1,1.07,378.39],[2,1.03,844.52]],"ltp":1.14,"tv":10747.13,"id":2263603},{"batb":[[0,6.6,28.64],[1,3.5,509.54],[2,1.01,20.51]],"ltp":12.5,"tv":157.45,"id":3622149}]}]}
{"op":"mcm","clk":"1009675292","pt":1580668216267,"mc":[{"id":"1.168230757","rc":[{"batb":[[0,1.09,1695.61],[1,1.08,1605.83],[2,1.07,378.39]],"batl":[[0,1.17,449.76],[1,1.18,1400.11]],"ltp":1.14,"tv":10747.13,"id":2263603}]}]}
{"op":"mcm","clk":"1009676720","pt":1580668234609,"mc":[{"id":"1.168230757","rc":[{"batb":[[2,1.03,844.52]],"batl":[[0,1.11,2449.25],[1,1.12,543.61]],"ltp":1.14,"tv":10747.13,"id":2263603}]}]}
{"op":"mcm","clk":"1009676766","pt":1580668235290,"mc":[{"id":"1.168230757","rc":[{"batb":[[2,1.04,1089.74]],"ltp":1.14,"tv":10747.13,"id":2263603},{"batb":[[0,9.8,29.98],[1,7.6,21.01],[2,3.5,509.54]],"ltp":12.5,"tv":157.45,"id":3622149}]}]}
{"op":"mcm","clk":"1009676925","pt":1580668237608,"mc":[{"id":"1.168230757","rc":[{"batb":[[2,1.05,569.11]],"batl":[[1,1.12,0]],"ltp":1.14,"tv":10747.13,"id":2263603}]}]}
{"op":"mcm","clk":"1009676967","pt":1580668238281,"mc":[{"id":"1.168230757","rc":[{"batl":[[1,1.17,1764.5]],"ltp":1.14,"tv":10747.13,"id":2263603}]}]}
{"op":"mcm","clk":"1009677492","pt":1580668245390,"mc":[{"id":"1.168230757","rc":[{"trd":[[1.09,1161.88]],"batb":[[0,1.09,1687.21]],"ltp":1.09,"tv":10763.93,"id":2263603}],"tv":10921.39}]}
{"op":"mcm","clk":"1009677956","pt":1580668251619,"mc":[{"id":"1.168230757","rc":[{"batb":[[0,1.05,569.11],[1,1.04,1684.42],[2,1.03,844.52]],"ltp":1.09,"tv":10763.93,"id":2263603},{"batb":[[0,7.6,21.01],[1,3.5,509.54],[2,1.01,20.51]],"ltp":12.5,"tv":157.45,"id":3622149}]}]}
{"op":"mcm","clk":"1009678209","pt":1580668254606,"mc":[{"id":"1.168230757","rc":[{"batb":[[0,1.05,3353.99]],"batl":[[0,1.15,1331.9],[1,1.16,1200.37]],"ltp":1.09,"tv":10763.93,"id":2263603}]}]}
{"op":"mcm","clk":"1009679023","pt":1580668265141,"mc":[{"id":"1.168230757","rc":[{"trd":[[1.05,200]],"batb":[[0,1.05,3253.99]],"ltp":1.05,"tv":10963.93,"id":2263603}],"tv":11121.39}]}
{"op":"mcm","clk":"1009679592","pt":1580668272419,"mc":[{"id":"1.168230757","rc":[{"batb":[[0,1.05,469.11]],"ltp":1.05,"tv":10963.93,"id":2263603}]}]}
{"op":"mcm","clk":"1009679630","pt":1580668272935,"mc":[{"id":"1.168230757","rc":[{"batl":[[0,1.14,9]],"ltp":1.05,"tv":10963.93,"id":2263603}]}]}
{"op":"mcm","clk":"1009679772","pt":1580668274647,"mc":[{"id":"1.168230757","rc":[{"batb":[[0,1.04,1684.42],[1,1.03,844.52],[2,1.02,1274.65]],"ltp":1.05,"tv":10963.93,"id":2263603}]}]}
{"op":"mcm","clk":"1009679809","pt":1580668275073,"mc":[{"id":"1.168230757","rc":[{"batb":[[0,1.08,2646.5],[1,1.04,1684.42],[2,1.03,844.52]],"batl":[[0,1.1,2267.8],[1,1.14,9]],"ltp":1.05,"tv":10963.93,"id":2263603}]}]}
{"op":"mcm","clk":"1009680054","pt":1580668278157,"mc":[{"id":"1.168230757","rc":[{"batb":[[0,1.04,2317.76],[1,1.03,844.52],[2,1.02,1274.65]],"batl":[[0,1.14,9],[1,1.14,0]],"ltp":1.05,"tv":10963.93,"id":2263603}]}]}
{"op":"mcm","clk":"1009680109","pt":1580668278835,"mc":[{"id":"1.168230757","rc":[{"batb":[[0,1.04,1684.42]],"ltp":1.05,"tv":10963.93,"id":2263603},{"batb":[[1,1.01,20.51],[2,1.01,0]],"ltp":12.5,"tv":157.45,"id":3622149}]}]}
{"op":"mcm","clk":"1009680288","pt":1580668281134,"mc":[{"id":"1.168230757","rc":[{"batb":[[0,1.05,2784.88],[1,1.04,1684.42],[2,1.03,844.52]],"batl":[[1,1.15,1331.9],[2,1.16,1200.37]],"ltp":1.05,"tv":10963.93,"id":2263603}]}]}
{"op":"mcm","clk":"1009681222","pt":1580668293360,"mc":[{"id":"1.168230757","rc":[{"batb":[[0,1.04,1684.42],[1,1.03,844.52],[2,1.02,1274.65]],"ltp":1.05,"tv":10963.93,"id":2263603}]}]}
{"op":"mcm","clk":"1009681507","pt":1580668296556,"mc":[{"id":"1.168230757","rc":[{"batb":[[0,1.11,5606.29],[1,1.08,622.22],[2,1.04,1684.42]],"ltp":1.05,"tv":10963.93,"id":2263603},{"batb":[[1,6.2,32.73],[2,1.01,20.51]],"ltp":12.5,"tv":157.45,"id":3622149}]}]}
{"op":"mcm","clk":"1009681595","pt":1580668297548,"mc":[{"id":"1.168230757","rc":[{"batb":[[0,1.13,1187.62],[1,1.12,1412.59],[2,1.11,5606.29]],"ltp":1.05,"tv":10963.93,"id":2263603}]}]}
{"op":"mcm","clk":"1009681648","pt":1580668298271,"mc":[{"id":"1.168230757","rc":[{"batb":[[2,3.35,546.81]],"ltp":12.5,"tv":157.45,"id":3622149}]}]}
{"op":"mcm","clk":"1009681693","pt":1580668298850,"mc":[{"id":"1.168230757","rc":[{"batb":[[2,1.11,427.64]],"ltp":1.05,"tv":10963.93,"id":2263603}]}]}
{"op":"mcm","clk":"1009682462","pt":1580668308550,"mc":[{"id":"1.168230757","rc":[{"batl":[[0,1.15,1331.9],[1,1.16,1200.37],[2,1.16,0]],"ltp":1.05,"tv":10963.93,"id":2263603}]}]}
{"op":"mcm","clk":"1009682612","pt":1580668310340,"mc":[{"id":"1.168230757","rc":[{"batb":[[0,1.08,622.22],[1,1.07,279.96],[2,1.04,594.68]],"ltp":1.05,"tv":10963.93,"id":2263603},{"batb":[[0,6.2,32.73],[1,3.35,546.81],[2,1.01,20.51]],"ltp":12.5,"tv":157.45,"id":3622149}]}]}
{"op":"mcm","clk":"1009682862","pt":1580668313550,"mc":[{"id":"1.168230757","rc":[{"batb":[[0,1.09,1774.81],[1,1.08,1538.49],[2,1.07,279.96]],"batl":[[0,1.19,726.27],[1,1.2,1229.62]],"ltp":1.05,"tv":10963.93,"id":2263603}]}]}
{"op":"mcm","clk":"1009682950","pt":1580668314650,"mc":[{"id":"1.168230757","rc":[{"batb":[[0,1.08,622.22],[1,1.07,279.96],[2,1.04,594.68]],"ltp":1.05,"tv":10963.93,"id":2263603}]}]}
{"op":"mcm","clk":"1009683347","pt":1580668319398,"mc":[{"id":"1.168230757","rc":[{"batb":[[0,1.12,1696.72],[1,1.11,922.33],[2,1.08,622.22]],"batl":[[0,1.14,1187.33],[1,1.15,1365.7]],"ltp":1.05,"tv":10963.93,"id":2263603}]}]}
{"op":"mcm","clk":"1009683574","pt":1580668322289,"mc":[{"id":"1.168230757","rc":[{"batb":[[0,1.08,622.22],[1,1.07,279.96],[2,1.04,594.68]],"ltp":1.05,"tv":10963.93,"id":2263603}]}]}
{"op":"mcm","clk":"1009683815","pt":1580668325187,"mc":[{"id":"1.168230757","rc":[{"batb":[[0,1.09,1774.81],[1,1.08,1538.49],[2,1.07,279.96]],"batl":[[0,1.19,726.27],[1,1.2,1229.62]],"ltp":1.05,"tv":10963.93,"id":2263603}]}]}
{"op":"mcm","clk":"1009684095","pt":1580668328584,"mc":[{"id":"1.168230757","rc":[{"batb":[[2,1.04,594.68]],"batl":[[0,1.12,569.65]],"ltp":1.05,"tv":10963.93,"id":2263603}]}]}
{"op":"mcm","clk":"1009684174","pt":1580668329581,"mc":[{"id":"1.168230757","rc":[{"batb":[[2,1.04,1714.4]],"batl":[[0,1.11,2382.69],[1,1.12,569.65]],"ltp":1.05,"tv":10963.93,"id":2263603},{"batb":[[0,9.8,28.95],[1,7.6,20.77],[2,3.35,546.81]],"ltp":12.5,"tv":157.45,"id":3622149}]}]}
{"op":"mcm","clk":"1009684356","pt":1580668331577,"mc":[{"id":"1.168230757","rc":[{"batb":[[2,1.05,476.26]],"ltp":1.05,"tv":10963.93,"id":2263603}]}]}
{"op":"mcm","clk":"1009684367","pt":1580668331683,"mc":[{"id":"1.168230757","rc":[{"batl":[[1,1.12,0]],"ltp":1.05,"tv":10963.93,"id":2263603}]}]}
{"op":"mcm","clk":"1009684895","pt":1580668338002,"mc":[{"id":"1.168230757","rc":[{"trd":[[1.11,341.26]],"batl":[[0,1.11,2298.67]],"ltp":1.11,"tv":11131.97,"id":2263603}],"tv":11289.43}]}
{"op":"mcm","clk":"1009685535","pt":1580668344585,"mc":[{"id":"1.168230757","rc":[{"batb":[[1,1.08,916.27]],"ltp":1.11,"tv":11131.97,"id":2263603},{"batb":[[0,7.6,20.77],[1,3.35,546.81],[2,1.01,20.51]],"ltp":12.5,"tv":157.45,"id":3622149}]}]}
{"op":"mcm","clk":"1009685560","pt":1580668344905,"mc":[{"id":"1.168230757","rc":[{"trd":[[1.09,1179.88]],"batb":[[0,1.05,476.26],[1,1.04,1714.4],[2,1.03,844.52]],"ltp":1.09,"tv":11149.97,"id":2263603}],"tv":11307.43}]}
{"op":"mcm","clk":"1009685914","pt":1580668348422,"mc":[{"id":"1.168230757","rc":[{"batb":[[0,1.05,3261.14]],"batl":[[0,1.09,1.68],[1,1.15,1251.68],[2,1.16,1279.9]],"ltp":1.09,"tv":11149.97,"id":2263603}]}]}
{"op":"mcm","clk":"1009685982","pt":1580668349106,"mc":[{"id":"1.168230757","rc":[{"batl":[[0,1.15,1251.68],[1,1.16,1279.9],[2,1.16,0]],"ltp":1.09,"tv":11149.97,"id":2263603}]}]}
{"op":"mcm","clk":"1009686219","pt":1580668351710,"mc":[{"id":"1.168230757","rc":[{"batb":[[0,1.11,20],[1,1.05,3261.14],[2,1.04,1714.4]],"ltp":1.09,"tv":11149.97,"id":2263603}]}]}
{"op":"mcm","clk":"1009686768","pt":1580668357416,"mc":[{"id":"1.168230757","rc":[{"batb":[[1,1.05,476.26]],"ltp":1.09,"tv":11149.97,"id":2263603}]}]}
{"op":"mcm","clk":"1009686970","pt":1580668359610,"mc":[{"id":"1.168230757","rc":[{"trd":[[1.11,381.25]],"batb":[[0,1.04,1714.4],[1,1.03,844.52],[2,1.02,1274.65]],"batl":[[0,1.08,549.66]],"ltp":1.11,"tv":11189.97,"id":2263603},{"batb":[[1,1.01,20.51],[2,1.01,0]],"ltp":12.5,"tv":157.45,"id":3622149}],"tv":11347.42}]}
{"op":"mcm","clk":"1009687055","pt":1580668360499,"mc":[{"id":"1.168230757","rc":[{"batb":[[0,1.05,2784.88],[1,1.04,1714.4],[2,1.03,844.52]],"batl":[[0,1.07,2732.82],[1,1.08,549.66]],"ltp":1.11,"tv":11189.97,"id":2263603},{"batb":[[0,15.5,10.54],[1,9.8,28.95],[2,1.01,20.51]],"ltp":12.5,"tv":157.45,"id":3622149}]}]}
{"op":"mcm","clk":"1009687236","pt":1580668362118,"mc":[{"id":"1.168230757","rc":[{"batl":[[1,1.08,0]],"ltp":1.11,"tv":11189.97,"id":2263603}]}]}
{"op":"mcm","clk":"1009687310","pt":1580668362798,"mc":[{"id":"1.168230757","rc":[{"batb":[[2,4,517.01]],"ltp":12.5,"tv":157.45,"id":3622149}]}]}
{"op":"mcm","clk":"1009687553","pt":1580668365101,"mc":[{"id":"1.168230757","rc":[{"trd":[[1.07,3399.95]],"batl":[[0,1.07,2712.08]],"ltp":1.07,"tv":11231.46,"id":2263603}],"tv":11388.91}]}
{"op":"mcm","clk":"1009687654","pt":1580668366515,"mc":[{"id":"1.168230757","rc":[{"batb":[[1,1.04,1119.72]],"ltp":1.07,"tv":11231.46,"id":2263603}]}]}
{"op":"mcm","clk":"1009687747","pt":1580668367516,"mc":[{"id":"1.168230757","rc":[{"batb":[[2,1.02,2731.88]],"ltp":1.07,"tv":11231.46,"id":2263603}]}]}
{"op":"mcm","clk":"1009687772","pt":1580668367826,"mc":[{"id":"1.168230757","rc":[{"batb":[[2,1.02,1465.1]],"ltp":1.07,"tv":11231.46,"id":2263603}]}]}
{"op":"mcm","clk":"1009688516","pt":1580668375646,"mc":[{"id":"1.168230757","rc":[{"batb":[[0,1.02,1465.1],[1,1.01,2561.93],[2,1.02,0]],"ltp":1.07,"tv":11231.46,"id":2263603},{"batb":[[0,9.8,28.95],[1,4,517.01],[2,1.01,20.51]],"ltp":12.5,"tv":157.45,"id":3622149}]}]}
{"op":"mcm","clk":"1009688626","pt":1580668376646,"mc":[{"id":"1.168230757","rc":[{"batb":[[0,1.02,7.87]],"ltp":1.07,"tv":11231.46,"id":2263603},{"batb":[[1,1.01,20.51],[2,1.01,0]],"ltp":12.5,"tv":157.45,"id":3622149}]}]}
{"op":"mcm","clk":"1009689289","pt":1580668383459,"mc":[{"id":"1.168230757","rc":[{"batb":[[0,1.04,2811.65],[1,1.02,7.87],[2,1.01,5658.14]],"batl":[[0,1.06,2758.6]],"ltp":1.07,"tv":11231.46,"id":2263603},{"batb":[[1,4.1,518.03],[2,1.01,20.51]],"ltp":12.5,"tv":157.45,"id":3622149}]}]}
{"op":"mcm","clk":"1009689591","pt":1580668386644,"mc":[{"id":"1.168230757","rc":[{"batb":[[0,1.02,7.87],[1,1.01,5658.14],[2,1.01,0]],"ltp":1.07,"tv":11231.46,"id":2263603}]}]}
{"op":"mcm","clk":"1009689632","pt":1580668387165,"mc":[{"id":"1.168230757","rc":[{"batb":[[1,1.01,2561.93]],"ltp":1.07,"tv":11231.46,"id":2263603},{"batb":[[1,1.01,20.51],[2,1.01,0]],"ltp":12.5,"tv":157.45,"id":3622149}]}]}
{"op":"mcm","clk":"1009690136","pt":1580668392566,"mc":[{"id":"1.168230757","rc":[{"batb":[[1,1.01,5457.1]],"batl":[[0,1.11,2278.1]],"ltp":1.07,"tv":11231.46,"id":2263603}]}]}
{"op":"mcm","clk":"1009690632","pt":1580668398348,"mc":[{"id":"1.168230757","rc":[{"batb":[[1,1.01,2561.93]],"ltp":1.07,"tv":11231.46,"id":2263603}]}]}
{"op":"mcm","clk":"1009690951","pt":1580668401633,"mc":[{"id":"1.168230757","rc":[{"batl":[[0,1.04,569.65],[1,1.05,22]],"ltp":1.07,"tv":11231.46,"id":2263603},{"batb":[[0,30,6.37],[1,25,9.21],[2,9.8,28.95]],"ltp":12.5,"tv":157.45,"id":3622149}]}]}
{"op":"mcm","clk":"1009691023","pt":1580668402467,"mc":[{"id":"1.168230757","rc":[{"batb":[[1,1.01,5456.88]],"batl":[[0,1.03,2838.74],[1,1.04,569.65],[2,1.05,22]],"ltp":1.07,"tv":11231.46,"id":2263603},{"batb":[[2,1.01,20.51]],"ltp":12.5,"tv":157.45,"id":3622149}]}]}
{"op":"mcm","clk":"1009691107","pt":1580668403352,"mc":[{"id":"1.168230757","rc":[{"batb":[[2,4.4,509.65]],"ltp":12.5,"tv":157.45,"id":3622149}]}]}
{"op":"mcm","clk":"1009691212","pt":1580668404447,"mc":[{"id":"1.168230757","rc":[{"batl":[[1,1.05,22],[2,1.05,0]],"ltp":1.07,"tv":11231.46,"id":2263603}]}]}
{"op":"mcm","clk":"1009691863","pt":1580668411446,"mc":[{"id":"1.168230757","rc":[{"trd":[[1.02,15.74]],"batb":[[0,1.01,5456.88],[1,1.01,0]],"batl":[[0,1.02,492.13],[1,1.03,2838.74],[2,1.05,22]],"ltp":1.02,"tv":11247.19,"id":2263603}],"tv":11404.65}]}
{"op":"mcm","clk":"1009692151","pt":1580668414546,"mc":[{"id":"1.168230757","rc":[{"batl":[[0,1.03,2838.74],[1,1.05,22],[2,1.05,0]],"ltp":1.02,"tv":11247.19,"id":2263603}]}]}
{"op":"mcm","clk":"1009692563","pt":1580668419553,"mc":[{"id":"1.168230757","rc":[{"batl":[[0,1.05,22],[1,1.05,0]],"ltp":1.02,"tv":11247.19,"id":2263603},{"batb":[[0,25,9.21],[1,4.4,509.65],[2,1.01,20.51]],"ltp":12.5,"tv":157.45,"id":3622149}]}]}
{"op":"mcm","clk":"1009692744","pt":1580668421591,"mc":[{"id":"1.168230757","rc":[{"batb":[[0,1.01,2561.93]],"ltp":1.02,"tv":11247.19,"id":2263603}]}]}
{"op":"mcm","clk":"1009692986","pt":1580668424377,"mc":[{"id":"1.168230757","rc":[{"trd":[[1.01,1600.05]],"batb":[[0,1.02,2624.73],[1,1.01,1761.89]],"batl":[[0,1.03,2838.74],[1,1.05,22]],"ltp":1.01,"tv":12847.24,"id":2263603}],"tv":13004.69}]}
{"op":"mcm","clk":"1009693242","pt":1580668426987,"mc":[{"id":"1.168230757","rc":[{"batb":[[1,1.01,7.87]],"ltp":1.01,"tv":12847.24,"id":2263603}]}]}
{"op":"mcm","clk":"1009693385","pt":1580668428501,"mc":[{"id":"1.168230757","rc":[{"trd":[[1.01,1615.78]],"batl":[[0,1.01,2.22]],"ltp":1.01,"tv":12862.97,"id":2263603}],"tv":13020.42}]}
{"op":"mcm","clk":"1009693607","pt":1580668431093,"mc":[{"id":"1.168230757","rc":[{"trd":[[1.01,1620.22]],"batb":[[0,1.01,2892.73]],"batl":[[0,1.04,2811.45]],"ltp":1.01,"tv":12867.41,"id":2263603}],"tv":13024.86}]}
{"op":"mcm","clk":"1009693736","pt":1580668432606,"mc":[{"id":"1.168230757","rc":[{"batl":[[0,1.05,22],[1,1.05,0]],"ltp":1.01,"tv":12867.41,"id":2263603}]}]}
{"op":"mcm","clk":"1009694010","pt":1580668435590,"mc":[{"id":"1.168230757","rc":[{"batl":[[0,1.04,569.65],[1,1.05,22]],"ltp":1.01,"tv":12867.41,"id":2263603},{"batb":[[0,30,2.91],[1,25,9.21],[2,4.4,509.65]],"ltp":12.5,"tv":157.45,"id":3622149}]}]}
{"op":"mcm","clk":"1009694091","pt":1580668436380,"mc":[{"id":"1.168230757","rc":[{"batl":[[0,1.02,2866.57],[1,1.04,569.65],[2,1.05,22]],"ltp":1.01,"tv":12867.41,"id":2263603},{"batb":[[1,4.4,509.65],[2,1.01,20.51]],"ltp":12.5,"tv":157.45,"id":3622149}]}]}
{"op":"mcm","clk":"1009694290","pt":1580668438579,"mc":[{"id":"1.168230757","rc":[{"batl":[[1,1.05,22],[2,1.05,0]],"ltp":1.01,"tv":12867.41,"id":2263603}]}]}
{"op":"mcm","clk":"1009694545","pt":1580668441600,"mc":[{"id":"1.168230757","rc":[{"trd":[[1.01,3179.24]],"batb":[[0,1.01,2113.24]],"ltp":1.01,"tv":14426.44,"id":2263603}],"tv":14583.89}]}
{"op":"mcm","clk":"1009694839","pt":1580668444500,"mc":[{"id":"1.168230757","rc":[{"batl":[[0,1.05,22],[1,1.05,0]],"ltp":1.01,"tv":14426.44,"id":2263603}]}]}
{"op":"mcm","clk":"1009694930","pt":1580668445331,"mc":[{"id":"1.168230757","rc":[{"batb":[[1,1.01,20.51],[2,1.01,0]],"ltp":12.5,"tv":157.45,"id":3622149}]}]}
{"op":"mcm","clk":"1009695110","pt":1580668447315,"mc":[{"id":"1.168230757","rc":[{"batl":[[0,1.03,2838.74],[1,1.05,22]],"ltp":1.01,"tv":14426.44,"id":2263603}]}]}
{"op":"mcm","clk":"1009695214","pt":1580668448521,"mc":[{"id":"1.168230757","rc":[{"batl":[[0,1.05,22],[1,1.05,0]],"ltp":1.01,"tv":14426.44,"id":2263603},{"batb":[[0,1.01,20.51],[1,1.01,0]],"ltp":12.5,"tv":157.45,"id":3622149}]}]}
{"op":"mcm","clk":"1009695436","pt":1580668450630,"mc":[{"id":"1.168230757","rc":[{"batl":[[0,1.01,11.36],[1,1.05,22]],"ltp":1.01,"tv":14426.44,"id":2263603}]}]}
{"op":"mcm","clk":"1009695627","pt":1580668452529,"mc":[{"id":"1.168230757","rc":[{"batl":[[0,1.01,2906.31]],"ltp":1.01,"tv":14426.44,"id":2263603}]}]}
{"op":"mcm","clk":"1009695716","pt":1580668453541,"mc":[{"id":"1.168230757","rc":[{"batb":[[0,4.7,499.71],[1,1.01,20.51]],"ltp":12.5,"tv":157.45,"id":3622149}]}]}
{"op":"mcm","clk":"1009695937","pt":1580668455532,"mc":[{"id":"1.168230757","rc":[{"batl":[[0,1.01,2894.95]],"ltp":1.01,"tv":14426.44,"id":2263603}]}]}
{"op":"mcm","clk":"1009696146","pt":1580668457627,"mc":[{"id":"1.168230757","rc":[{"batl":[[0,1.05,22],[1,1.05,0]],"ltp":1.01,"tv":14426.44,"id":2263603}]}]}
{"op":"mcm","clk":"1009696247","pt":1580668458516,"mc":[{"id":"1.168230757","rc":[{"batb":[[0,1.01,20.51],[1,1.01,0]],"ltp":12.5,"tv":157.45,"id":3622149}]}]}
{"op":"mcm","clk":"1009696455","pt":1580668460520,"mc":[{"id":"1.168230757","rc":[{"batl":[[0,1.02,2866.57],[1,1.05,22]],"ltp":1.01,"tv":14426.44,"id":2263603}]}]}
{"op":"mcm","clk":"1009697388","pt":1580668469614,"mc":[{"id":"1.168230757","rc":[{"batb":[[0,1.01,42.01]],"ltp":1.01,"tv":14426.44,"id":2263603}]}]}
{"op":"mcm","clk":"1009697589","pt":1580668471558,"mc":[{"id":"1.168230757","rc":[{"batl":[[0,1.05,22],[1,1.05,0]],"ltp":1.01,"tv":14426.44,"id":2263603}]}]}
{"op":"mcm","clk":"1009697666","pt":1580668472250,"mc":[{"id":"1.168230757","rc":[{"trd":[[1.01,3263.27]],"batl":[[0,1.01,744.81],[1,1.05,22]],"ltp":1.01,"tv":14510.46,"id":2263603}],"tv":14667.91}]}
{"op":"mcm","clk":"1009697995","pt":1580668475507,"mc":[{"id":"1.168230757","rc":[{"trd":[[1.01,4752.83]],"batb":[[0,1.01,2150.19]],"batl":[[0,1.02,2866.57]],"ltp":1.01,"tv":16000.03,"id":2263603},{"batb":[[0,30,3.27],[1,1.01,20.51]],"ltp":12.5,"tv":157.45,"id":3622149}],"tv":16157.48}]}
{"op":"mcm","clk":"1009698114","pt":1580668476630,"mc":[{"id":"1.168230757","rc":[{"batb":[[1,4.6,496.2],[2,1.01,20.51]],"ltp":12.5,"tv":157.45,"id":3622149}]}]}
{"op":"mcm","clk":"1009698375","pt":1580668479220,"mc":[{"id":"1.168230757","rc":[{"batb":[[0,1.01,2894.95]],"ltp":1.01,"tv":16000.03,"id":2263603}]}]}
{"op":"mcm","clk":"1009698797","pt":1580668483436,"mc":[{"id":"1.168230757","rc":[{"batl":[[0,1.05,22],[1,1.05,0]],"ltp":1.01,"tv":16000.03,"id":2263603}]}]}
{"op":"mcm","clk":"1009698911","pt":1580668484429,"mc":[{"id":"1.168230757","rc":[{"batb":[[1,1.01,20.51],[2,1.01,0]],"ltp":12.5,"tv":157.45,"id":3622149}]}]}
{"op":"mcm","clk":"1009699368","pt":1580668489549,"mc":[{"id":"1.168230757","rc":[{"batb":[[0,1.01,2894.95]],"batl":[[0,1.02,2866.57],[1,1.05,22]],"ltp":1.01,"tv":16000.03,"id":2263603}]}]}
{"op":"mcm","clk":"1009699734","pt":1580668493625,"mc":[{"id":"1.168230757","rc":[{"batl":[[0,1.05,22],[1,1.05,0]],"ltp":1.01,"tv":16000.03,"id":2263603}]}]}
{"op":"mcm","clk":"1009700137","pt":1580668498359,"mc":[{"id":"1.168230757","rc":[{"batl":[[0,1.03,2838.74],[1,1.05,22]],"ltp":1.01,"tv":16000.03,"id":2263603}]}]}
{"op":"mcm","clk":"1009700203","pt":1580668499047,"mc":[{"id":"1.168230757","rc":[{"batl":[[0,1.05,22],[1,1.05,0]],"ltp":1.01,"tv":16000.03,"id":2263603},{"batb":[[0,1.01,20.51],[1,1.01,0]],"ltp":12.5,"tv":157.45,"id":3622149}]}]}
{"op":"mcm","clk":"1009700418","pt":1580668501446,"mc":[{"id":"1.168230757","rc":[{"batl":[[0,1.02,569.65],[1,1.05,22]],"ltp":1.01,"tv":16000.03,"id":2263603}]}]}
{"op":"mcm","clk":"1009700530","pt":1580668502649,"mc":[{"id":"1.168230757","rc":[{"batl":[[0,1.01,2894.95],[1,1.02,569.65],[2,1.05,22]],"ltp":1.01,"tv":16000.03,"id":2263603}]}]}
{"op":"mcm","clk":"1009700611","pt":1580668503548,"mc":[{"id":"1.168230757","rc":[{"batb":[[0,4.8,490.06],[1,1.01,20.51]],"ltp":12.5,"tv":157.45,"id":3622149}]}]}
{"op":"mcm","clk":"1009700670","pt":1580668504234,"mc":[{"id":"1.168230757","rc":[{"batl":[[1,1.05,22],[2,1.05,0]],"ltp":1.01,"tv":16000.03,"id":2263603}]}]}
{"op":"mcm","clk":"1009701551","pt":1580668514355,"mc":[{"id":"1.168230757","rc":[{"batl":[[0,1.01,982.66]],"ltp":1.01,"tv":16000.03,"id":2263603}]}]}
{"op":"mcm","clk":"1009701753","pt":1580668516558,"mc":[{"id":"1.168230757","rc":[{"batb":[[0,1.01,20.51],[1,1.01,0]],"ltp":12.5,"tv":157.45,"id":3622149}]}]}
{"op":"mcm","clk":"1009701805","pt":1580668517238,"mc":[{"id":"1.168230757","rc":[{"batl":[[1,1.02,1893.55],[2,1.05,22]],"ltp":1.01,"tv":16000.03,"id":2263603}]}]}
{"op":"mcm","clk":"1009702337","pt":1580668523060,"mc":[{"id":"1.168230757","rc":[{"batl":[[1,1.05,22],[2,1.05,0]],"ltp":1.01,"tv":16000.03,"id":2263603}]}]}
{"op":"mcm","clk":"1009702662","pt":1580668526574,"mc":[{"id":"1.168230757","rc":[{"batb":[[0,30,3.74],[1,1.01,20.51]],"ltp":12.5,"tv":157.45,"id":3622149}]}]}
{"op":"mcm","clk":"1009702739","pt":1580668527347,"mc":[{"id":"1.168230757","rc":[{"batl":[[1,1.02,1893.55],[2,1.05,22]],"ltp":1.01,"tv":16000.03,"id":2263603}]}]}
{"op":"mcm","clk":"1009702930","pt":1580668529252,"mc":[{"id":"1.168230757","rc":[{"batb":[[1,4.6,502.02],[2,1.01,20.51]],"ltp":12.5,"tv":157.45,"id":3622149}]}]}
{"op":"mcm","clk":"1009703559","pt":1580668536366,"mc":[{"id":"1.168230757","rc":[{"batl":[[0,1.05,22],[1,1.02,0],[2,1.05,0]],"ltp":1.01,"tv":16000.03,"id":2263603}]}]}
{"op":"mcm","clk":"1009703675","pt":1580668537565,"mc":[{"id":"1.168230757","rc":[{"batb":[[1,1.01,20.51],[2,1.01,0]],"ltp":12.5,"tv":157.45,"id":3622149}]}]}
{"op":"mcm","clk":"1009703846","pt":1580668539576,"mc":[{"id":"1.168230757","rc":[{"batl":[[0,1.03,2838.74],[1,1.05,22]],"ltp":1.01,"tv":16000.03,"id":2263603}]}]}
{"op":"mcm","clk":"1009704966","pt":1580668551376,"mc":[{"id":"1.168230757","rc":[{"batl":[[0,1.05,22],[1,1.05,0]],"ltp":1.01,"tv":16000.03,"id":2263603}]}]}
{"op":"mcm","clk":"1009704996","pt":1580668551791,"mc":[{"id":"1.168230757","rc":[{"batb":[[0,1.01,20.51],[1,1.01,0]],"ltp":12.5,"tv":157.45,"id":3622149}]}]}
{"op":"mcm","clk":"1009705108","pt":1580668552948,"mc":[{"id":"1.168230757","marketDefinition":{"bspMarket":false,"turnInPlayEnabled":true,"persistenceEnabled":true,"marketBaseRate":5.0,"eventId":"29681775","eventTypeId":"2","numberOfWinners":1,"bettingType":"ODDS","marketType":"SET_WINNER","marketTime":"2020-02-02T18:01:00.000Z","suspendTime":"2020-02-02T18:01:00.000Z","bspReconciled":false,"complete":true,"inPlay":true,"crossMatching":true,"runnersVoidable":false,"numberOfActiveRunners":2,"betDelay":3,"status":"SUSPENDED","runners":[{"status":"ACTIVE","sortPriority":1,"id":2263603,"name":"Madison Brengle"},{"status":"ACTIVE","sortPriority":2,"id":3622149,"name":"Stefanie Voegele"}],"regulators":["MR_INT"],"discountAllowed":true,"timezone":"UTC","openDate":"2020-02-02T18:01:00.000Z","version":3150236344,"name":"Set 1 Winner","eventName":"Brengle v Voegele"}}]}
{"op":"mcm","clk":"1009708313","pt":1580668587517,"mc":[{"id":"1.168230757","tv":0.0}]}
{"op":"mcm","clk":"1009708517","pt":1580668589619,"mc":[{"id":"1.168230757","marketDefinition":{"bspMarket":false,"turnInPlayEnabled":true,"persistenceEnabled":true,"marketBaseRate":5.0,"eventId":"29681775","eventTypeId":"2","numberOfWinners":1,"bettingType":"ODDS","marketType":"SET_WINNER","marketTime":"2020-02-02T18:01:00.000Z","suspendTime":"2020-02-02T18:01:00.000Z","bspReconciled":false,"complete":true,"inPlay":true,"crossMatching":false,"runnersVoidable":false,"numberOfActiveRunners":0,"betDelay":3,"status":"CLOSED","settledTime":"2020-02-02T18:36:25.000Z","runners":[{"status":"WINNER","sortPriority":1,"id":2263603,"name":"Madison Brengle"},{"status":"LOSER","sortPriority":2,"id":3622149,"name":"Stefanie Voegele"}],"regulators":["MR_INT"],"discountAllowed":true,"timezone":"UTC","openDate":"2020-02-02T18:01:00.000Z","version":3150237248,"name":"Set 1 Winner","eventName":"Brengle v Voegele"}}]}
