{"op":"mcm","clk":"1001501051","pt":1580587070468,"mc":[{"id":"1.168230761","marketDefinition":{"bspMarket":false,"turnInPlayEnabled":true,"persistenceEnabled":true,"marketBaseRate":5.0,"eventId":"29681775","eventTypeId":"2","numberOfWinners":1,"bettingType":"ODDS","marketType":"PLAYER_B_WIN_A_SET","marketTime":"2020-02-02T18:00:00.000Z","suspendTime":"2020-02-02T18:00:00.000Z","bspReconciled":false,"complete":true,"inPlay":false,"crossMatching":true,"runnersVoidable":false,"numberOfActiveRunners":2,"betDelay":0,"status":"OPEN","runners":[{"status":"ACTIVE","sortPriority":1,"id":41364,"name":"Yes"},{"status":"ACTIVE","sortPriority":2,"id":41365,"name":"No"}],"regulators":["MR_INT"],"discountAllowed":false,"timezone":"UTC","openDate":"2020-02-02T18:00:00.000Z","version":3147219553,"name":"Voegele To Win A Set?","eventName":"Brengle v Voegele"}}]}
{"op":"mcm","clk":"1001501273","pt":1580587071655,"mc":[{"id":"1.168230761","marketDefinition":{"bspMarket":false,"turnInPlayEnabled":true,"persistenceEnabled":true,"marketBaseRate":5.0,"eventId":"29681775","eventTypeId":"2","numberOfWinners":1,"bettingType":"ODDS","marketType":"PLAYER_B_WIN_A_SET","marketTime":"2020-02-02T18:00:00.000Z","suspendTime":"2020-02-02T18:00:00.000Z","bspReconciled":false,"complete":true,"inPlay":false,"crossMatching":true,"runnersVoidable":false,"numberOfActiveRunners":2,"betDelay":0,"status":"OPEN","runners":[{"status":"ACTIVE","sortPriority":1,"id":41364,"name":"Yes"},{"status":"ACTIVE","sortPriority":2,"id":41365,"name":"No"}],"regulators":["MR_INT"],"discountAllowed":false,"timezone":"UTC","openDate":"2020-02-02T18:00:00.000Z","version":3147219553,"name":"Voegele To Win A Set?","eventName":"Brengle v Voegele"}}]}
{"op":"mcm","clk":"1001501657","pt":1580587073688,"mc":[{"id":"1.168230761","marketDefinition":{"bspMarket":false,"turnInPlayEnabled":true,"persistenceEnabled":true,"marketBaseRate":5.0,"eventId":"29681775","eventTypeId":"2","numberOfWinners":1,"bettingType":"ODDS","marketType":"PLAYER_B_WIN_A_SET","marketTime":"2020-02-02T18:00:00.000Z","suspendTime":"2020-02-02T18:00:00.000Z","bspReconciled":false,"complete":true,"inPlay":false,"crossMatching":true,"runnersVoidable":false,"numberOfActiveRunners":2,"betDelay":0,"status":"OPEN","runners":[{"status":"ACTIVE","sortPriority":1,"id":41364,"name":"Yes"},{"status":"ACTIVE","sortPriority":2,"id":41365,"name":"No"}],"regulators":["MR_INT"],"discountAllowed":true,"timezone":"UTC","openDate":"2020-02-02T18:00:00.000Z","version":3147219553,"name":"Voegele To Win A Set?","eventName":"Brengle v Voegele"}}]}
{"op":"mcm","clk":"1003070537","pt":1580602600505,"mc":[{"id":"1.168230761","rc":[{"batb":[[0,1.01,0.51]],"ltp":0.0,"tv":0.0,"id":41364},{"batb":[[0,1.01,0.51]],"ltp":0.0,"tv":0.0,"id":41365}]}]}
{"op":"mcm","clk":"1003129911","pt":1580603366468,"mc":[{"id":"1.168230761","rc":[{"batb":[[0,1.01,1.01]],"ltp":0.0,"tv":0.0,"id":41364},{"batb":[[0,1.01,1.01]],"ltp":0.0,"tv":0.0,"id":41365}]}]}
{"op":"mcm","clk":"1009515467","pt":1580666510637,"mc":[{"id":"1.168230761","marketDefinition":{"bspMarket":false,"turnInPlayEnabled":true,"persistenceEnabled":true,"marketBaseRate":5.0,"eventId":"29681775","eventTypeId":"2","numberOfWinners":1,"bettingType":"ODDS","marketType":"PLAYER_B_WIN_A_SET","marketTime":"2020-02-02T18:01:00.000Z","suspendTime":"2020-02-02T18:01:00.000Z","bspReconciled":false,"complete":true,"inPlay":false,"crossMatching":true,"runnersVoidable":false,"numberOfActiveRunners":2,"betDelay":0,"status":"OPEN","runners":[{"status":"ACTIVE","sortPriority":1,"id":41364,"name":"Yes"},{"status":"ACTIVE","sortPriority":2,"id":41365,"name":"No"}],"regulators":["MR_INT"],"discountAllowed":true,"timezone":"UTC","openDate":"2020-02-02T18:00:00.000Z","version":3150167977,"name":"Voegele To Win A Set?","eventName":"Brengle v Voegele"}}]}
{"op":"mcm","clk":"1009515709","pt":1580666513126,"mc":[{"id":"1.168230761","marketDefinition":{"bspMarket":false,"turnInPlayEnabled":true,"persistenceEnabled":true,"marketBaseRate":5.0,"eventId":"29681775","eventTypeId":"2","numberOfWinners":1,"bettingType":"ODDS","marketType":"PLAYER_B_WIN_A_SET","marketTime":"2020-02-02T18:01:00.000Z","suspendTime":"2020-02-02T18:01:00.000Z","bspReconciled":false,"complete":true,"inPlay":false,"crossMatching":true,"runnersVoidable":false,"numberOfActiveRunners":2,"betDelay":0,"status":"OPEN","runners":[{"status":"ACTIVE","sortPriority":1,"id":41364,"name":"Yes"},{"status":"ACTIVE","sortPriority":2,"id":41365,"name":"No"}],"regulators":["MR_INT"],"discountAllowed":true,"timezone":"UTC","openDate":"2020-02-02T18:01:00.000Z","version":3150167977,"name":"Voegele To Win A Set?","eventName":"Brengle v Voegele"}}]}
{"op":"mcm","clk":"1009519906","pt":1580666557406,"mc":[{"id":"1.168230761","rc":[{"batb":[[0,1.4,400.57],[1,1.01,1.01]],"ltp":0.0,"tv":0.0,"id":41364},{"batb":[[0,3,175.7],[1,1.01,1.01]],"ltp":0.0,"tv":0.0,"id":41365}]}]}
{"op":"mcm","clk":"1009542076","pt":1580666773182,"mc":[{"id":"1.168230761","rc":[{"batb":[[0,3,175.46]],"ltp":0.0,"tv":0.0,"id":41365}]}]}
{"op":"mcm","clk":"1009555777","pt":1580666900444,"mc":[{"id":"1.168230761","marketDefinition":{"bspMarket":false,"turnInPlayEnabled":true,"persistenceEnabled":true,"marketBaseRate":5.0,"eventId":"29681775","eventTypeId":"2","numberOfWinners":1,"bettingType":"ODDS","marketType":"PLAYER_B_WIN_A_SET","marketTime":"2020-02-02T18:01:00.000Z","suspendTime":"2020-02-02T18:01:00.000Z","bspReconciled":false,"complete":true,"inPlay":true,"crossMatching":true,"runnersVoidable":false,"numberOfActiveRunners":2,"betDelay":3,"status":"OPEN","runners":[{"status":"ACTIVE","sortPriority":1,"id":41364,"name":"Yes"},{"status":"ACTIVE","sortPriority":2,"id":41365,"name":"No"}],"regulators":["MR_INT"],"discountAllowed":true,"timezone":"UTC","openDate":"2020-02-02T18:01:00.000Z","version":3150176494,"name":"Voegele To Win A Set?","eventName":"Brengle v Voegele"},"rc":[{"batb":[[0,1.01,0.51],[1,1.01,0]],"ltp":0.0,"tv":0.0,"id":41364},{"batb":[[0,1.01,0.51],[1,1.01,0]],"ltp":0.0,"tv":0.0,"id":41365}]}]}
{"op":"mcm","clk":"1009558525","pt":1580666927252,"mc":[{"id":"1.168230761","rc":[{"batb":[[0,1.34,488.3],[1,1.29,594.28],[2,1.01,0.51]],"ltp":0.0,"tv":0.0,"id":41364},{"batb":[[0,3.35,135.25],[1,3.05,170.98],[2,1.01,0.51]],"ltp":0.0,"tv":0.0,"id":41365}]}]}
{"op":"mcm","clk":"1009559496","pt":1580666936249,"mc":[{"id":"1.168230761","rc":[{"batb":[[0,1.29,594.28],[1,1.01,0.51],[2,1.01,0]],"ltp":0.0,"tv":0.0,"id":41364},{"batb":[[0,3.05,170.98],[1,1.01,0.51],[2,1.01,0]],"ltp":0.0,"tv":0.0,"id":41365}]}]}
{"op":"mcm","clk":"1009560328","pt":1580666943594,"mc":[{"id":"1.168230761","rc":[{"batb":[[0,1.39,409.07],[1,1.33,506.48],[2,1.01,0.51]],"ltp":0.0,"tv":0.0,"id":41364},{"batb":[[1,2.82,85.37],[2,1.01,0.51]],"ltp":0.0,"tv":0.0,"id":41365}]}]}
{"op":"mcm","clk":"1009561285","pt":1580666951476,"mc":[{"id":"1.168230761","rc":[{"batb":[[0,1.33,506.48],[1,1.01,0.51],[2,1.01,0]],"ltp":0.0,"tv":0.0,"id":41364},{"batb":[[0,2.82,85.37],[1,1.01,0.51],[2,1.01,0]],"ltp":0.0,"tv":0.0,"id":41365}]}]}
{"op":"mcm","clk":"1009561625","pt":1580666954487,"mc":[{"id":"1.168230761","rc":[{"batb":[[0,2.8,85.84]],"ltp":0.0,"tv":0.0,"id":41365}]}]}
{"op":"mcm","clk":"1009563710","pt":1580666975617,"mc":[{"id":"1.168230761","rc":[{"batb":[[0,1.45,342.35],[1,1.38,419.93],[2,1.01,0.51]],"ltp":0.0,"tv":0.0,"id":41364},{"batb":[[1,2.62,103.7],[2,1.01,0.51]],"ltp":0.0,"tv":0.0,"id":41365}]}]}
{"op":"mcm","clk":"1009564665","pt":1580666986035,"mc":[{"id":"1.168230761","rc":[{"batb":[[0,1.38,419.93],[1,1.01,0.51],[2,1.01,0]],"ltp":0.0,"tv":0.0,"id":41364},{"batb":[[0,2.62,103.7],[1,1.01,0.51],[2,1.01,0]],"ltp":0.0,"tv":0.0,"id":41365}]}]}
{"op":"mcm","clk":"1009565762","pt":1580666997152,"mc":[{"id":"1.168230761","rc":[{"batb":[[1,1.31,549.12],[2,1.01,0.51]],"ltp":0.0,"tv":0.0,"id":41364},{"batb":[[0,3.1,165.23],[1,2.8,86.79],[2,1.01,0.51]],"ltp":0.0,"tv":0.0,"id":41365}]}]}
{"op":"mcm","clk":"1009566540","pt":1580667004644,"mc":[{"id":"1.168230761","rc":[{"batb":[[0,1.31,549.12],[1,1.01,0.51],[2,1.01,0]],"ltp":0.0,"tv":0.0,"id":41364},{"batb":[[0,2.8,86.79],[1,1.01,0.51],[2,1.01,0]],"ltp":0.0,"tv":0.0,"id":41365}]}]}
{"op":"mcm","clk":"1009570693","pt":1580667045564,"mc":[{"id":"1.168230761","rc":[{"batb":[[0,1.46,335.97],[1,1.38,424.41],[2,1.31,549.12]],"ltp":0.0,"tv":0.0,"id":41364},{"batb":[[1,2.56,110.47],[2,1.01,0.51]],"ltp":0.0,"tv":0.0,"id":41365}]}]}
{"op":"mcm","clk":"1009570787","pt":1580667046464,"mc":[{"id":"1.168230761","rc":[{"batb":[[2,1.01,0.51]],"ltp":0.0,"tv":0.0,"id":41364}]}]}
{"op":"mcm","clk":"1009572072","pt":1580667059570,"mc":[{"id":"1.168230761","rc":[{"batb":[[0,1.38,424.25],[1,1.01,0.51],[2,1.01,0]],"ltp":0.0,"tv":0.0,"id":41364},{"batb":[[0,2.56,110.47],[1,1.01,0.51],[2,1.01,0]],"ltp":0.0,"tv":0.0,"id":41365}]}]}
{"op":"mcm","clk":"1009574087","pt":1580667081603,"mc":[{"id":"1.168230761","rc":[{"batb":[[0,1.53,275.31],[1,1.47,324.25],[2,1.01,0.51]],"ltp":0.0,"tv":0.0,"id":41364},{"batb":[[1,2.36,136.2],[2,1.01,0.51]],"ltp":0.0,"tv":0.0,"id":41365}]}]}
{"op":"mcm","clk":"1009575658","pt":1580667097615,"mc":[{"id":"1.168230761","rc":[{"batb":[[0,1.54,271.85],[1,1.53,275.31],[2,1.47,324.25]],"ltp":0.0,"tv":0.0,"id":41364},{"batb":[[1,2.54,112.2],[2,2.36,136.2]],"ltp":0.0,"tv":0.0,"id":41365}]}]}
{"op":"mcm","clk":"1009575704","pt":1580667098029,"mc":[{"id":"1.168230761","rc":[{"batb":[[1,1.47,320.24],[2,1.01,0.51]],"ltp":0.0,"tv":0.0,"id":41364},{"batb":[[0,2.54,112.2],[1,2.36,136.2],[2,1.01,0.51]],"ltp":0.0,"tv":0.0,"id":41365}]}]}
{"op":"mcm","clk":"1009578430","pt":1580667127548,"mc":[{"id":"1.168230761","rc":[{"batb":[[0,1.47,320.24],[1,1.01,0.51],[2,1.01,0]],"ltp":0.0,"tv":0.0,"id":41364},{"batb":[[0,2.36,136.2],[1,1.01,0.51],[2,1.01,0]],"ltp":0.0,"tv":0.0,"id":41365}]}]}
{"op":"mcm","clk":"1009579746","pt":1580667141600,"mc":[{"id":"1.168230761","rc":[{"batb":[[1,1.42,371.22],[2,1.01,0.51]],"ltp":0.0,"tv":0.0,"id":41364},{"batb":[[0,2.74,92.06],[1,2.52,114.25],[2,1.01,0.51]],"ltp":0.0,"tv":0.0,"id":41365}]}]}
{"op":"mcm","clk":"1009581121","pt":1580667155180,"mc":[{"id":"1.168230761","rc":[{"batb":[[0,1.42,371.22],[1,1.01,0.51],[2,1.01,0]],"ltp":0.0,"tv":0.0,"id":41364},{"batb":[[0,2.52,114.25],[1,1.01,0.51],[2,1.01,0]],"ltp":0.0,"tv":0.0,"id":41365}]}]}
{"op":"mcm","clk":"1009581474","pt":1580667158498,"mc":[{"id":"1.168230761","rc":[{"batb":[[0,2.54,112.12]],"ltp":0.0,"tv":0.0,"id":41365}]}]}
{"op":"mcm","clk":"1009582307","pt":1580667166586,"mc":[{"id":"1.168230761","rc":[{"batb":[[1,1.37,430.39],[2,1.01,0.51]],"ltp":0.0,"tv":0.0,"id":41364},{"batb":[[0,2.94,189.94],[1,2.76,89.93],[2,1.01,0.51]],"ltp":0.0,"tv":0.0,"id":41365}]}]}
{"op":"mcm","clk":"1009583531","pt":1580667177618,"mc":[{"id":"1.168230761","rc":[{"batb":[[0,1.37,430.39],[1,1.01,0.51],[2,1.01,0]],"ltp":0.0,"tv":0.0,"id":41364},{"batb":[[0,2.76,89.93],[1,1.01,0.51],[2,1.01,0]],"ltp":0.0,"tv":0.0,"id":41365}]}]}
{"op":"mcm","clk":"1009586425","pt":1580667204649,"mc":[{"id":"1.168230761","rc":[{"batb":[[0,1.47,326.29],[1,1.41,385.62],[2,1.37,430.39]],"ltp":0.0,"tv":0.0,"id":41364},{"batb":[[1,2.52,114.25],[2,1.01,0.51]],"ltp":0.0,"tv":0.0,"id":41365}]}]}
{"op":"mcm","clk":"1009586458","pt":1580667204930,"mc":[{"id":"1.168230761","rc":[{"batb":[[2,1.01,0.51]],"ltp":0.0,"tv":0.0,"id":41364}]}]}
{"op":"mcm","clk":"1009587834","pt":1580667217541,"mc":[{"id":"1.168230761","rc":[{"batb":[[0,1.41,385.62],[1,1.01,0.51],[2,1.01,0]],"ltp":0.0,"tv":0.0,"id":41364},{"batb":[[0,2.52,114.25],[1,1.01,0.51],[2,1.01,0]],"ltp":0.0,"tv":0.0,"id":41365}]}]}
{"op":"mcm","clk":"1009591501","pt":1580667251578,"mc":[{"id":"1.168230761","rc":[{"batb":[[0,1.54,267.68],[1,1.46,330.78],[2,1.01,0.51]],"ltp":0.0,"tv":0.0,"id":41364},{"batb":[[1,2.28,152.49],[2,1.01,0.51]],"ltp":0.0,"tv":0.0,"id":41365}]}]}
{"op":"mcm","clk":"1009593251","pt":1580667267609,"mc":[{"id":"1.168230761","rc":[{"batb":[[0,1.46,330.78],[1,1.01,0.51],[2,1.01,0]],"ltp":0.0,"tv":0.0,"id":41364},{"batb":[[0,2.28,152.49],[1,1.01,0.51],[2,1.01,0]],"ltp":0.0,"tv":0.0,"id":41365}]}]}
{"op":"mcm","clk":"1009595096","pt":1580667284492,"mc":[{"id":"1.168230761","rc":[{"batb":[[0,1.65,208.27],[1,1.54,265.63],[2,1.01,0.51]],"ltp":0.0,"tv":0.0,"id":41364},{"batb":[[1,2.04,205.91],[2,1.01,0.51]],"ltp":0.0,"tv":0.0,"id":41365}]}]}
{"op":"mcm","clk":"1009596085","pt":1580667293597,"mc":[{"id":"1.168230761","rc":[{"batb":[[0,1.54,265.63],[1,1.01,0.51],[2,1.01,0]],"ltp":0.0,"tv":0.0,"id":41364},{"batb":[[0,2.04,205.91],[1,1.01,0.51],[2,1.01,0]],"ltp":0.0,"tv":0.0,"id":41365}]}]}
{"op":"mcm","clk":"1009598152","pt":1580667313343,"mc":[{"id":"1.168230761","rc":[{"batb":[[0,1.79,157.84],[1,1.7,187.18],[2,1.01,0.51]],"ltp":0.0,"tv":0.0,"id":41364},{"batb":[[1,1.96,236.28],[2,1.01,0.51]],"ltp":0.0,"tv":0.0,"id":41365}]}]}
{"op":"mcm","clk":"1009600732","pt":1580667337572,"mc":[{"id":"1.168230761","rc":[{"batb":[[0,1.7,187.18],[1,1.01,0.51],[2,1.01,0]],"ltp":0.0,"tv":0.0,"id":41364},{"batb":[[0,1.96,236.28],[1,1.01,0.51],[2,1.01,0]],"ltp":0.0,"tv":0.0,"id":41365}]}]}
{"op":"mcm","clk":"1009601018","pt":1580667340570,"mc":[{"id":"1.168230761","rc":[{"batb":[[0,1.71,183.72]],"ltp":0.0,"tv":0.0,"id":41364},{"batb":[[0,1.95,240.77]],"ltp":0.0,"tv":0.0,"id":41365}]}]}
{"op":"mcm","clk":"1009604334","pt":1580667375289,"mc":[{"id":"1.168230761","rc":[{"batb":[[0,1.88,135.65],[1,1.78,159.72],[2,1.01,0.51]],"ltp":0.0,"tv":0.0,"id":41364},{"batb":[[1,1.87,137.46],[2,1.01,0.51]],"ltp":0.0,"tv":0.0,"id":41365}]}]}
{"op":"mcm","clk":"1009605836","pt":1580667390590,"mc":[{"id":"1.168230761","rc":[{"batb":[[0,1.78,159.72],[1,1.01,0.51],[2,1.01,0]],"ltp":0.0,"tv":0.0,"id":41364},{"batb":[[0,1.87,137.46],[1,1.01,0.51],[2,1.01,0]],"ltp":0.0,"tv":0.0,"id":41365}]}]}
{"op":"mcm","clk":"1009606136","pt":1580667393647,"mc":[{"id":"1.168230761","rc":[{"batb":[[0,1.8,156.5]],"ltp":0.0,"tv":0.0,"id":41364},{"batb":[[0,1.86,140.13]],"ltp":0.0,"tv":0.0,"id":41365}]}]}
{"op":"mcm","clk":"1009607746","pt":1580667411446,"mc":[{"id":"1.168230761","rc":[{"batb":[[0,1.97,232.9],[1,1.89,133.68],[2,1.01,0.51]],"ltp":0.0,"tv":0.0,"id":41364},{"batb":[[0,1.79,157.68]],"ltp":0.0,"tv":0.0,"id":41365}]}]}
{"op":"mcm","clk":"1009607772","pt":1580667411761,"mc":[{"id":"1.168230761","rc":[{"batb":[[0,1.89,133.68],[1,1.01,0.51],[2,1.01,0]],"ltp":0.0,"tv":0.0,"id":41364}]}]}
{"op":"mcm","clk":"1009611072","pt":1580667448989,"mc":[{"id":"1.168230761","rc":[{"batb":[[0,2.04,206.07],[1,1.97,232.43],[2,1.01,0.51]],"ltp":0.0,"tv":0.0,"id":41364},{"batb":[[1,1.75,171.29],[2,1.01,0.51]],"ltp":0.0,"tv":0.0,"id":41365}]}]}
{"op":"mcm","clk":"1009612174","pt":1580667460629,"mc":[{"id":"1.168230761","rc":[{"batb":[[0,1.97,232.43],[1,1.01,0.51],[2,1.01,0]],"ltp":0.0,"tv":0.0,"id":41364},{"batb":[[0,1.75,170.58],[1,1.01,0.51],[2,1.01,0]],"ltp":0.0,"tv":0.0,"id":41365}]}]}
{"op":"mcm","clk":"1009613024","pt":1580667469643,"mc":[{"id":"1.168230761","rc":[{"batb":[[1,1.88,134.62],[2,1.01,0.51]],"ltp":0.0,"tv":0.0,"id":41364},{"batb":[[0,1.86,139.35],[1,1.8,154.45],[2,1.01,0.51]],"ltp":0.0,"tv":0.0,"id":41365}]}]}
{"op":"mcm","clk":"1009613639","pt":1580667477347,"mc":[{"id":"1.168230761","rc":[{"batb":[[0,1.88,134.62],[1,1.01,0.51],[2,1.01,0]],"ltp":0.0,"tv":0.0,"id":41364},{"batb":[[0,1.8,154.45],[1,1.01,0.51],[2,1.01,0]],"ltp":0.0,"tv":0.0,"id":41365}]}]}
{"op":"mcm","clk":"1009615246","pt":1580667495649,"mc":[{"id":"1.168230761","rc":[{"batb":[[0,2.04,210.63],[1,1.96,236.2],[2,1.88,134.62]],"ltp":0.0,"tv":0.0,"id":41364},{"batb":[[1,1.72,179.16],[2,1.01,0.51]],"ltp":0.0,"tv":0.0,"id":41365}]}]}
{"op":"mcm","clk":"1009615314","pt":1580667496343,"mc":[{"id":"1.168230761","rc":[{"batb":[[2,1.01,0.51]],"ltp":0.0,"tv":0.0,"id":41364}]}]}
{"op":"mcm","clk":"1009622910","pt":1580667578574,"mc":[{"id":"1.168230761","rc":[{"batb":[[0,1.96,236.2],[1,1.01,0.51],[2,1.01,0]],"ltp":0.0,"tv":0.0,"id":41364},{"batb":[[0,1.72,179.16],[1,1.01,0.51],[2,1.01,0]],"ltp":0.0,"tv":0.0,"id":41365}]}]}
{"op":"mcm","clk":"1009623964","pt":1580667591988,"mc":[{"id":"1.168230761","rc":[{"batb":[[0,2.14,179.87],[1,2.04,208.03],[2,1.01,0.51]],"ltp":0.0,"tv":0.0,"id":41364},{"batb":[[1,1.66,205.44],[2,1.01,0.51]],"ltp":0.0,"tv":0.0,"id":41365}]}]}
{"op":"mcm","clk":"1009625073","pt":1580667606567,"mc":[{"id":"1.168230761","rc":[{"batb":[[0,2.04,208.03],[1,1.01,0.51],[2,1.01,0]],"ltp":0.0,"tv":0.0,"id":41364},{"batb":[[0,1.66,205.44],[1,1.01,0.51],[2,1.01,0]],"ltp":0.0,"tv":0.0,"id":41365}]}]}
{"op":"mcm","clk":"1009628458","pt":1580667647439,"mc":[{"id":"1.168230761","rc":[{"batb":[[1,1.95,240.92],[2,1.01,0.51]],"ltp":0.0,"tv":0.0,"id":41364},{"batb":[[0,1.8,156.26],[1,1.72,181.36],[2,1.66,205.44]],"ltp":0.0,"tv":0.0,"id":41365}]}]}
{"op":"mcm","clk":"1009628524","pt":1580667648322,"mc":[{"id":"1.168230761","rc":[{"batb":[[2,1.01,0.51]],"ltp":0.0,"tv":0.0,"id":41365}]}]}
{"op":"mcm","clk":"1009629358","pt":1580667657630,"mc":[{"id":"1.168230761","rc":[{"batb":[[0,1.95,240.92],[1,1.01,0.51],[2,1.01,0]],"ltp":0.0,"tv":0.0,"id":41364},{"batb":[[0,1.72,181.36],[1,1.01,0.51],[2,1.01,0]],"ltp":0.0,"tv":0.0,"id":41365}]}]}
{"op":"mcm","clk":"1009631568","pt":1580667682449,"mc":[{"id":"1.168230761","rc":[{"batb":[[0,2.16,177.51],[1,2.04,205.99],[2,1.01,0.51]],"ltp":0.0,"tv":0.0,"id":41364},{"batb":[[1,1.64,211.18],[2,1.01,0.51]],"ltp":0.0,"tv":0.0,"id":41365}]}]}
{"op":"mcm","clk":"1009633371","pt":1580667701410,"mc":[{"id":"1.168230761","rc":[{"batb":[[0,2.04,205.99],[1,1.01,0.51],[2,1.01,0]],"ltp":0.0,"tv":0.0,"id":41364},{"batb":[[0,1.64,211.18],[1,1.01,0.51],[2,1.01,0]],"ltp":0.0,"tv":0.0,"id":41365}]}]}
{"op":"mcm","clk":"1009636988","pt":1580667745447,"mc":[{"id":"1.168230761","rc":[{"batb":[[0,2.28,150.05],[1,2.18,173.41],[2,1.01,0.51]],"ltp":0.0,"tv":0.0,"id":41364},{"batb":[[1,1.59,240.85],[2,1.01,0.51]],"ltp":0.0,"tv":0.0,"id":41365}]}]}
{"op":"mcm","clk":"1009638449","pt":1580667762641,"mc":[{"id":"1.168230761","rc":[{"batb":[[0,2.18,173.41],[1,1.01,0.51],[2,1.01,0]],"ltp":0.0,"tv":0.0,"id":41364},{"batb":[[0,1.59,240.85],[1,1.01,0.51],[2,1.01,0]],"ltp":0.0,"tv":0.0,"id":41365}]}]}
{"op":"mcm","clk":"1009638778","pt":1580667766243,"mc":[{"id":"1.168230761","rc":[{"batb":[[0,2.16,174.99]],"ltp":0.0,"tv":0.0,"id":41364},{"batb":[[0,1.59,239.04]],"ltp":0.0,"tv":0.0,"id":41365}]}]}
{"op":"mcm","clk":"1009639911","pt":1580667779557,"mc":[{"id":"1.168230761","rc":[{"batb":[[1,2.02,212.91],[2,1.01,0.51]],"ltp":0.0,"tv":0.0,"id":41364},{"batb":[[0,1.71,183.8],[1,1.62,222.98],[2,1.01,0.51]],"ltp":0.0,"tv":0.0,"id":41365}]}]}
{"op":"mcm","clk":"1009641208","pt":1580667794495,"mc":[{"id":"1.168230761","rc":[{"batb":[[0,2.02,212.91],[1,1.01,0.51],[2,1.01,0]],"ltp":0.0,"tv":0.0,"id":41364},{"batb":[[0,1.62,221.65],[1,1.01,0.51],[2,1.01,0]],"ltp":0.0,"tv":0.0,"id":41365}]}]}
{"op":"mcm","clk":"1009643483","pt":1580667820609,"mc":[{"id":"1.168230761","rc":[{"batb":[[1,1.92,251.94],[2,1.01,0.51]],"ltp":0.0,"tv":0.0,"id":41364},{"batb":[[0,1.82,150.99],[1,1.71,182.78],[2,1.01,0.51]],"ltp":0.0,"tv":0.0,"id":41365}]}]}
{"op":"mcm","clk":"1009644698","pt":1580667832617,"mc":[{"id":"1.168230761","rc":[{"batb":[[0,1.92,251.94],[1,1.01,0.51],[2,1.01,0]],"ltp":0.0,"tv":0.0,"id":41364},{"batb":[[0,1.71,182.78],[1,1.01,0.51],[2,1.01,0]],"ltp":0.0,"tv":0.0,"id":41365}]}]}
{"op":"mcm","clk":"1009644969","pt":1580667835621,"mc":[{"id":"1.168230761","rc":[{"batb":[[0,1.94,246.04]],"ltp":0.0,"tv":0.0,"id":41364},{"batb":[[0,1.7,186.79]],"ltp":0.0,"tv":0.0,"id":41365}]}]}
{"op":"mcm","clk":"1009645509","pt":1580667841490,"mc":[{"id":"1.168230761","rc":[{"batb":[[1,1.85,142.1],[2,1.01,0.51]],"ltp":0.0,"tv":0.0,"id":41364},{"batb":[[0,1.89,132.82],[1,1.8,156.1],[2,1.01,0.51]],"ltp":0.0,"tv":0.0,"id":41365}]}]}
{"op":"mcm","clk":"1009646534","pt":1580667853633,"mc":[{"id":"1.168230761","rc":[{"batb":[[0,1.85,142.1],[1,1.01,0.51],[2,1.01,0]],"ltp":0.0,"tv":0.0,"id":41364},{"batb":[[0,1.8,155.32],[1,1.01,0.51],[2,1.01,0]],"ltp":0.0,"tv":0.0,"id":41365}]}]}
{"op":"mcm","clk":"1009648037","pt":1580667870511,"mc":[{"id":"1.168230761","rc":[{"batb":[[1,1.73,175.46],[2,1.01,0.51]],"ltp":0.0,"tv":0.0,"id":41364},{"batb":[[0,1.98,228.33],[1,1.89,132.11],[2,1.01,0.51]],"ltp":0.0,"tv":0.0,"id":41365}]}]}
{"op":"mcm","clk":"1009649980","pt":1580667895645,"mc":[{"id":"1.168230761","rc":[{"batb":[[0,1.73,175.46],[1,1.01,0.51],[2,1.01,0]],"ltp":0.0,"tv":0.0,"id":41364},{"batb":[[0,1.89,132.11],[1,1.01,0.51],[2,1.01,0]],"ltp":0.0,"tv":0.0,"id":41365}]}]}
{"op":"mcm","clk":"1009650170","pt":1580667898143,"mc":[{"id":"1.168230761","rc":[{"batb":[[0,1.9,131.56]],"ltp":0.0,"tv":0.0,"id":41365}]}]}
{"op":"mcm","clk":"1009652043","pt":1580667923371,"mc":[{"id":"1.168230761","rc":[{"batb":[[0,1.01,0.51],[1,1.01,0]],"ltp":0.0,"tv":0.0,"id":41365}]}]}
{"op":"mcm","clk":"1009652254","pt":1580667926070,"mc":[{"id":"1.168230761","rc":[{"batb":[[0,1.94,246.59],[1,1.82,148.94],[2,1.01,0.51]],"ltp":0.0,"tv":0.0,"id":41364},{"batb":[[0,1.89,132.5],[1,1.81,152.17],[2,1.01,0.51]],"ltp":0.0,"tv":0.0,"id":41365}]}]}
{"op":"mcm","clk":"1009653065","pt":1580667937567,"mc":[{"id":"1.168230761","rc":[{"batb":[[0,1.82,148.94],[1,1.01,0.51],[2,1.01,0]],"ltp":0.0,"tv":0.0,"id":41364},{"batb":[[0,1.81,152.17],[1,1.01,0.51],[2,1.01,0]],"ltp":0.0,"tv":0.0,"id":41365}]}]}
{"op":"mcm","clk":"1009653298","pt":1580667940593,"mc":[{"id":"1.168230761","rc":[{"batb":[[0,1.83,146.9],[1,1.82,148.94],[2,1.01,0.51]],"ltp":0.0,"tv":0.0,"id":41364},{"batb":[[1,1.8,154.22],[2,1.01,0.51]],"ltp":0.0,"tv":0.0,"id":41365}]}]}
{"op":"mcm","clk":"1009653368","pt":1580667941277,"mc":[{"id":"1.168230761","rc":[{"batb":[[1,1.01,0.51],[2,1.01,0]],"ltp":0.0,"tv":0.0,"id":41364},{"batb":[[0,1.8,154.22],[1,1.01,0.51],[2,1.01,0]],"ltp":0.0,"tv":0.0,"id":41365}]}]}
{"op":"mcm","clk":"1009655142","pt":1580667963605,"mc":[{"id":"1.168230761","rc":[{"batb":[[0,2.04,208.98],[1,1.93,247.38],[2,1.83,146.9]],"ltp":0.0,"tv":0.0,"id":41364},{"batb":[[1,1.74,173.73],[2,1.01,0.51]],"ltp":0.0,"tv":0.0,"id":41365}]}]}
{"op":"mcm","clk":"1009655158","pt":1580667963808,"mc":[{"id":"1.168230761","rc":[{"batb":[[2,1.01,0.51]],"ltp":0.0,"tv":0.0,"id":41364}]}]}
{"op":"mcm","clk":"1009656115","pt":1580667975526,"mc":[{"id":"1.168230761","rc":[{"batb":[[0,1.93,247.38],[1,1.01,0.51],[2,1.01,0]],"ltp":0.0,"tv":0.0,"id":41364},{"batb":[[0,1.74,173.73],[1,1.01,0.51],[2,1.01,0]],"ltp":0.0,"tv":0.0,"id":41365}]}]}
{"op":"mcm","clk":"1009657516","pt":1580667994349,"mc":[{"id":"1.168230761","rc":[{"batb":[[0,2.12,185.93],[1,2.04,211.26],[2,1.01,0.51]],"ltp":0.0,"tv":0.0,"id":41364},{"batb":[[1,1.7,189.39],[2,1.01,0.51]],"ltp":0.0,"tv":0.0,"id":41365}]}]}
{"op":"mcm","clk":"1009658372","pt":1580668004644,"mc":[{"id":"1.168230761","rc":[{"batb":[[0,2.04,211.26],[1,1.01,0.51],[2,1.01,0]],"ltp":0.0,"tv":0.0,"id":41364},{"batb":[[0,1.7,189.39],[1,1.01,0.51],[2,1.01,0]],"ltp":0.0,"tv":0.0,"id":41365}]}]}
{"op":"mcm","clk":"1009659584","pt":1580668019542,"mc":[{"id":"1.168230761","rc":[{"batb":[[0,2.2,169.4],[1,2.1,191.98],[2,1.01,0.51]],"ltp":0.0,"tv":0.0,"id":41364},{"batb":[[1,1.63,215.98],[2,1.01,0.51]],"ltp":0.0,"tv":0.0,"id":41365}]}]}
{"op":"mcm","clk":"1009660198","pt":1580668027376,"mc":[{"id":"1.168230761","rc":[{"batb":[[0,2.18,172.31],[1,2.08,195.37]],"ltp":0.0,"tv":0.0,"id":41364},{"batb":[[0,1.7,186.32],[1,1.64,212.68]],"ltp":0.0,"tv":0.0,"id":41365}]}]}
{"op":"mcm","clk":"1009661436","pt":1580668042194,"mc":[{"id":"1.168230761","rc":[{"batb":[[0,2.08,195.37],[1,1.01,0.51],[2,1.01,0]],"ltp":0.0,"tv":0.0,"id":41364},{"batb":[[0,1.64,212.68],[1,1.01,0.51],[2,1.01,0]],"ltp":0.0,"tv":0.0,"id":41365}]}]}
{"op":"mcm","clk":"1009666575","pt":1580668110378,"mc":[{"id":"1.168230761","rc":[{"batb":[[0,1.01,0.51],[1,1.01,0]],"ltp":0.0,"tv":0.0,"id":41364},{"batb":[[0,1.01,0.51],[1,1.01,0]],"ltp":0.0,"tv":0.0,"id":41365}]}]}
{"op":"mcm","clk":"1009668048","pt":1580668126487,"mc":[{"id":"1.168230761","rc":[{"batb":[[0,2.3,148.87],[1,2.2,169.24],[2,1.01,0.51]],"ltp":0.0,"tv":0.0,"id":41364},{"batb":[[0,1.64,212.68],[1,1.58,245.88],[2,1.01,0.51]],"ltp":0.0,"tv":0.0,"id":41365}]}]}
{"op":"mcm","clk":"1009668861","pt":1580668136288,"mc":[{"id":"1.168230761","rc":[{"batb":[[0,2.2,169.24],[1,1.01,0.51],[2,1.01,0]],"ltp":0.0,"tv":0.0,"id":41364},{"batb":[[0,1.58,245.88],[1,1.01,0.51],[2,1.01,0]],"ltp":0.0,"tv":0.0,"id":41365}]}]}
{"op":"mcm","clk":"1009671744","pt":1580668173540,"mc":[{"id":"1.168230761","rc":[{"batb":[[1,2.08,196.08],[2,1.01,0.51]],"ltp":0.0,"tv":0.0,"id":41364},{"batb":[[0,1.7,189.47],[1,1.63,218.97],[2,1.01,0.51]],"ltp":0.0,"tv":0.0,"id":41365}]}]}
{"op":"mcm","clk":"1009673010","pt":1580668189539,"mc":[{"id":"1.168230761","rc":[{"batb":[[0,2.08,196.08],[1,1.01,0.51],[2,1.01,0]],"ltp":0.0,"tv":0.0,"id":41364},{"batb":[[0,1.63,218.97],[1,1.01,0.51],[2,1.01,0]],"ltp":0.0,"tv":0.0,"id":41365}]}]}
{"op":"mcm","clk":"1009673723","pt":1580668198484,"mc":[{"id":"1.168230761","rc":[{"batb":[[1,2,222.59],[2,1.01,0.51]],"ltp":0.0,"tv":0.0,"id":41364},{"batb":[[0,1.77,165.31],[1,1.69,191.98],[2,1.01,0.51]],"ltp":0.0,"tv":0.0,"id":41365}]}]}
{"op":"mcm","clk":"1009675034","pt":1580668213371,"mc":[{"id":"1.168230761","rc":[{"batb":[[0,2,222.59],[1,1.01,0.51],[2,1.01,0]],"ltp":0.0,"tv":0.0,"id":41364},{"batb":[[0,1.69,191.98],[1,1.01,0.51],[2,1.01,0]],"ltp":0.0,"tv":0.0,"id":41365}]}]}
{"op":"mcm","clk":"1009676766","pt":1580668235290,"mc":[{"id":"1.168230761","rc":[{"batb":[[0,2.2,166.81],[1,2.08,196],[2,1.01,0.51]],"ltp":0.0,"tv":0.0,"id":41364},{"batb":[[1,1.61,226.68],[2,1.01,0.51]],"ltp":0.0,"tv":0.0,"id":41365}]}]}
{"op":"mcm","clk":"1009677956","pt":1580668251619,"mc":[{"id":"1.168230761","rc":[{"batb":[[0,2.08,196],[1,1.01,0.51],[2,1.01,0]],"ltp":0.0,"tv":0.0,"id":41364},{"batb":[[0,1.61,226.68],[1,1.01,0.51],[2,1.01,0]],"ltp":0.0,"tv":0.0,"id":41365}]}]}
{"op":"mcm","clk":"1009681507","pt":1580668296556,"mc":[{"id":"1.168230761","rc":[{"batb":[[1,1.98,231.09],[2,1.01,0.51]],"ltp":0.0,"tv":0.0,"id":41364},{"batb":[[0,1.77,165.39],[1,1.68,194.74],[2,1.61,226.68]],"ltp":0.0,"tv":0.0,"id":41365}]}]}
{"op":"mcm","clk":"1009681595","pt":1580668297548,"mc":[{"id":"1.168230761","rc":[{"batb":[[2,1.01,0.51]],"ltp":0.0,"tv":0.0,"id":41365}]}]}
{"op":"mcm","clk":"1009682612","pt":1580668310340,"mc":[{"id":"1.168230761","rc":[{"batb":[[0,1.98,231.09],[1,1.01,0.51],[2,1.01,0]],"ltp":0.0,"tv":0.0,"id":41364},{"batb":[[0,1.68,194.74],[1,1.01,0.51],[2,1.01,0]],"ltp":0.0,"tv":0.0,"id":41365}]}]}
{"op":"mcm","clk":"1009684174","pt":1580668329581,"mc":[{"id":"1.168230761","rc":[{"batb":[[0,2.22,164.21],[1,2.08,194.97],[2,1.01,0.51]],"ltp":0.0,"tv":0.0,"id":41364},{"batb":[[1,1.6,231.8],[2,1.01,0.51]],"ltp":0.0,"tv":0.0,"id":41365}]}]}
{"op":"mcm","clk":"1009685535","pt":1580668344585,"mc":[{"id":"1.168230761","rc":[{"batb":[[0,2.08,194.97],[1,1.01,0.51],[2,1.01,0]],"ltp":0.0,"tv":0.0,"id":41364},{"batb":[[0,1.6,231.8],[1,1.01,0.51],[2,1.01,0]],"ltp":0.0,"tv":0.0,"id":41365}]}]}
{"op":"mcm","clk":"1009687055","pt":1580668360499,"mc":[{"id":"1.168230761","rc":[{"batb":[[0,2.38,135.1],[1,2.22,163.5],[2,1.01,0.51]],"ltp":0.0,"tv":0.0,"id":41364},{"batb":[[1,1.52,279.4],[2,1.01,0.51]],"ltp":0.0,"tv":0.0,"id":41365}]}]}
{"op":"mcm","clk":"1009688516","pt":1580668375646,"mc":[{"id":"1.168230761","rc":[{"batb":[[0,2.22,163.5],[1,1.01,0.51],[2,1.01,0]],"ltp":0.0,"tv":0.0,"id":41364},{"batb":[[0,1.52,279.4],[1,1.01,0.51],[2,1.01,0]],"ltp":0.0,"tv":0.0,"id":41365}]}]}
{"op":"mcm","clk":"1009690951","pt":1580668401633,"mc":[{"id":"1.168230761","rc":[{"batb":[[0,2.58,108.58],[1,2.44,125.26],[2,2.22,163.5]],"ltp":0.0,"tv":0.0,"id":41364},{"batb":[[1,1.49,304.18],[2,1.01,0.51]],"ltp":0.0,"tv":0.0,"id":41365}]}]}
{"op":"mcm","clk":"1009691023","pt":1580668402467,"mc":[{"id":"1.168230761","rc":[{"batb":[[2,1.01,0.51]],"ltp":0.0,"tv":0.0,"id":41364}]}]}
{"op":"mcm","clk":"1009692563","pt":1580668419553,"mc":[{"id":"1.168230761","rc":[{"batb":[[0,2.44,125.26],[1,1.01,0.51],[2,1.01,0]],"ltp":0.0,"tv":0.0,"id":41364},{"batb":[[0,1.49,304.18],[1,1.01,0.51],[2,1.01,0]],"ltp":0.0,"tv":0.0,"id":41365}]}]}
{"op":"mcm","clk":"1009692809","pt":1580668422377,"mc":[{"id":"1.168230761","rc":[{"batb":[[0,2.42,127.31]],"ltp":0.0,"tv":0.0,"id":41364},{"batb":[[0,1.5,300.25]],"ltp":0.0,"tv":0.0,"id":41365}]}]}
{"op":"mcm","clk":"1009694010","pt":1580668435590,"mc":[{"id":"1.168230761","rc":[{"batb":[[0,2.66,99.61],[1,2.5,116.37],[2,2.42,127.31]],"ltp":0.0,"tv":0.0,"id":41364},{"batb":[[1,1.47,323.23],[2,1.01,0.51]],"ltp":0.0,"tv":0.0,"id":41365}]}]}
{"op":"mcm","clk":"1009694091","pt":1580668436380,"mc":[{"id":"1.168230761","rc":[{"batb":[[2,1.01,0.51]],"ltp":0.0,"tv":0.0,"id":41364}]}]}
{"op":"mcm","clk":"1009694839","pt":1580668444500,"mc":[{"id":"1.168230761","rc":[{"batb":[[0,2.5,116.37],[1,1.01,0.51],[2,1.01,0]],"ltp":0.0,"tv":0.0,"id":41364},{"batb":[[0,1.47,323.23],[1,1.01,0.51],[2,1.01,0]],"ltp":0.0,"tv":0.0,"id":41365}]}]}
{"op":"mcm","clk":"1009695532","pt":1580668451530,"mc":[{"id":"1.168230761","rc":[{"batb":[[0,2.74,91.03],[1,2.6,104.65],[2,2.5,116.37]],"ltp":0.0,"tv":0.0,"id":41364},{"batb":[[1,1.44,351.08],[2,1.01,0.51]],"ltp":0.0,"tv":0.0,"id":41365}]}]}
{"op":"mcm","clk":"1009695627","pt":1580668452529,"mc":[{"id":"1.168230761","rc":[{"batb":[[2,1.01,0.51]],"ltp":0.0,"tv":0.0,"id":41364}]}]}
{"op":"mcm","clk":"1009696146","pt":1580668457627,"mc":[{"id":"1.168230761","rc":[{"batb":[[0,2.6,104.65],[1,1.01,0.51],[2,1.01,0]],"ltp":0.0,"tv":0.0,"id":41364},{"batb":[[0,1.44,350.92],[1,1.01,0.51],[2,1.01,0]],"ltp":0.0,"tv":0.0,"id":41365}]}]}
{"op":"mcm","clk":"1009697995","pt":1580668475507,"mc":[{"id":"1.168230761","rc":[{"batb":[[1,2.46,121.33],[2,1.01,0.51]],"ltp":0.0,"tv":0.0,"id":41364},{"batb":[[0,1.51,287.98],[1,1.48,316.93],[2,1.01,0.51]],"ltp":0.0,"tv":0.0,"id":41365}]}]}
{"op":"mcm","clk":"1009698797","pt":1580668483436,"mc":[{"id":"1.168230761","rc":[{"batb":[[0,2.46,121.33],[1,1.01,0.51],[2,1.01,0]],"ltp":0.0,"tv":0.0,"id":41364},{"batb":[[0,1.48,316.93],[1,1.01,0.51],[2,1.01,0]],"ltp":0.0,"tv":0.0,"id":41365}]}]}
{"op":"mcm","clk":"1009700530","pt":1580668502649,"mc":[{"id":"1.168230761","rc":[{"batb":[[0,2.72,93.24],[1,2.58,108.58],[2,1.01,0.51]],"ltp":0.0,"tv":0.0,"id":41364},{"batb":[[1,1.44,347.14],[2,1.01,0.51]],"ltp":0.0,"tv":0.0,"id":41365}]}]}
{"op":"mcm","clk":"1009701551","pt":1580668514355,"mc":[{"id":"1.168230761","rc":[{"batb":[[0,2.58,108.58],[1,1.01,0.51],[2,1.01,0]],"ltp":0.0,"tv":0.0,"id":41364},{"batb":[[0,1.44,347.14],[1,1.01,0.51],[2,1.01,0]],"ltp":0.0,"tv":0.0,"id":41365}]}]}
{"op":"mcm","clk":"1009702662","pt":1580668526574,"mc":[{"id":"1.168230761","rc":[{"batb":[[1,2.42,128.09],[2,1.01,0.51]],"ltp":0.0,"tv":0.0,"id":41364},{"batb":[[0,1.52,279.4],[1,1.48,311.11],[2,1.44,347.14]],"ltp":0.0,"tv":0.0,"id":41365}]}]}
{"op":"mcm","clk":"1009702739","pt":1580668527347,"mc":[{"id":"1.168230761","rc":[{"batb":[[2,1.01,0.51]],"ltp":0.0,"tv":0.0,"id":41365}]}]}
{"op":"mcm","clk":"1009703494","pt":1580668535568,"mc":[{"id":"1.168230761","rc":[{"batb":[[0,2.42,128.09],[1,1.01,0.51],[2,1.01,0]],"ltp":0.0,"tv":0.0,"id":41364},{"batb":[[0,1.48,311.11],[1,1.01,0.51],[2,1.01,0]],"ltp":0.0,"tv":0.0,"id":41365}]}]}
{"op":"mcm","clk":"1009705338","pt":1580668554999,"mc":[{"id":"1.168230761","rc":[{"batb":[[0,2.7,95.36],[1,2.42,126.91],[2,1.01,0.51]],"ltp":0.0,"tv":0.0,"id":41364},{"batb":[[1,1.39,406.39],[2,1.01,0.51]],"ltp":0.0,"tv":0.0,"id":41365}]}]}
{"op":"mcm","clk":"1009705842","pt":1580668560191,"mc":[{"id":"1.168230761","rc":[{"batb":[[0,1.48,310.4],[1,1.39,405.45]],"ltp":0.0,"tv":0.0,"id":41365}]}]}
{"op":"mcm","clk":"1009706806","pt":1580668571537,"mc":[{"id":"1.168230761","rc":[{"batb":[[0,2.68,97.41],[1,2.4,129.59]],"ltp":0.0,"tv":0.0,"id":41364},{"batb":[[0,1.49,305.76],[1,1.4,399.55]],"ltp":0.0,"tv":0.0,"id":41365}]}]}
{"op":"mcm","clk":"1009706906","pt":1580668572602,"mc":[{"id":"1.168230761","rc":[{"batb":[[0,2.4,129.59],[1,1.01,0.51],[2,1.01,0]],"ltp":0.0,"tv":0.0,"id":41364},{"batb":[[0,1.4,399.55],[1,1.01,0.51],[2,1.01,0]],"ltp":0.0,"tv":0.0,"id":41365}]}]}
{"op":"mcm","clk":"1009716119","pt":1580668669121,"mc":[{"id":"1.168230761","rc":[{"batb":[[0,1.01,0.51],[1,1.01,0]],"ltp":0.0,"tv":0.0,"id":41364},{"batb":[[0,1.01,0.51],[1,1.01,0]],"ltp":0.0,"tv":0.0,"id":41365}]}]}
{"op":"mcm","clk":"1009718176","pt":1580668693640,"mc":[{"id":"1.168230761","rc":[{"batb":[[0,2.4,129.59],[1,2.2,167.91],[2,1.01,0.51]],"ltp":0.0,"tv":0.0,"id":41364},{"batb":[[0,1.59,240.22],[1,1.48,310.09],[2,1.01,0.51]],"ltp":0.0,"tv":0.0,"id":41365}]}]}
{"op":"mcm","clk":"1009719334","pt":1580668707323,"mc":[{"id":"1.168230761","rc":[{"batb":[[0,2.2,167.91],[1,1.01,0.51],[2,1.01,0]],"ltp":0.0,"tv":0.0,"id":41364},{"batb":[[0,1.48,310.09],[1,1.01,0.51],[2,1.01,0]],"ltp":0.0,"tv":0.0,"id":41365}]}]}
{"op":"mcm","clk":"1009722401","pt":1580668740284,"mc":[{"id":"1.168230761","rc":[{"batb":[[0,2.7,95.76],[1,2.38,133.76],[2,1.01,0.51]],"ltp":0.0,"tv":0.0,"id":41364},{"batb":[[1,1.38,423.86],[2,1.01,0.51]],"ltp":0.0,"tv":0.0,"id":41365}]}]}
{"op":"mcm","clk":"1009724261","pt":1580668760597,"mc":[{"id":"1.168230761","rc":[{"batb":[[0,2.38,133.76],[1,1.01,0.51],[2,1.01,0]],"ltp":0.0,"tv":0.0,"id":41364},{"batb":[[0,1.38,423.86],[1,1.01,0.51],[2,1.01,0]],"ltp":0.0,"tv":0.0,"id":41365}]}]}
{"op":"mcm","clk":"1009724361","pt":1580668761603,"mc":[{"id":"1.168230761","rc":[{"batb":[[0,1.38,422.36]],"ltp":0.0,"tv":0.0,"id":41365}]}]}
{"op":"mcm","clk":"1009726862","pt":1580668788332,"mc":[{"id":"1.168230761","rc":[{"batb":[[1,2.14,179.32],[2,1.01,0.51]],"ltp":0.0,"tv":0.0,"id":41364},{"batb":[[0,1.6,232.82],[1,1.48,312.84],[2,1.01,0.51]],"ltp":0.0,"tv":0.0,"id":41365}]}]}
{"op":"mcm","clk":"1009728493","pt":1580668806572,"mc":[{"id":"1.168230761","rc":[{"batb":[[0,2.14,179.32],[1,1.01,0.51],[2,1.01,0]],"ltp":0.0,"tv":0.0,"id":41364},{"batb":[[0,1.48,312.84],[1,1.01,0.51],[2,1.01,0]],"ltp":0.0,"tv":0.0,"id":41365}]}]}
{"op":"mcm","clk":"1009730071","pt":1580668825162,"mc":[{"id":"1.168230761","rc":[{"batb":[[1,2,218.81],[2,1.01,0.51]],"ltp":0.0,"tv":0.0,"id":41364},{"batb":[[0,1.72,179.63],[1,1.62,220.86],[2,1.01,0.51]],"ltp":0.0,"tv":0.0,"id":41365}]}]}
{"op":"mcm","clk":"1009731244","pt":1580668838321,"mc":[{"id":"1.168230761","rc":[{"batb":[[0,2,218.81],[1,1.01,0.51],[2,1.01,0]],"ltp":0.0,"tv":0.0,"id":41364},{"batb":[[0,1.62,220.86],[1,1.01,0.51],[2,1.01,0]],"ltp":0.0,"tv":0.0,"id":41365}]}]}
{"op":"mcm","clk":"1009733983","pt":1580668865610,"mc":[{"id":"1.168230761","rc":[{"batb":[[1,1.82,150.44],[2,1.01,0.51]],"ltp":0.0,"tv":0.0,"id":41364},{"batb":[[0,1.82,148.94],[1,1.7,186.4],[2,1.01,0.51]],"ltp":0.0,"tv":0.0,"id":41365}]}]}
{"op":"mcm","clk":"1009737438","pt":1580668902416,"mc":[{"id":"1.168230761","rc":[{"batb":[[0,1.82,150.44],[1,1.01,0.51],[2,1.01,0]],"ltp":0.0,"tv":0.0,"id":41364},{"batb":[[0,1.7,186.4],[1,1.01,0.51],[2,1.01,0]],"ltp":0.0,"tv":0.0,"id":41365}]}]}
{"op":"mcm","clk":"1009738829","pt":1580668917447,"mc":[{"id":"1.168230761","rc":[{"batb":[[1,1.63,216.61],[2,1.01,0.51]],"ltp":0.0,"tv":0.0,"id":41364},{"batb":[[0,2.02,216.53],[1,1.86,139.9],[2,1.01,0.51]],"ltp":0.0,"tv":0.0,"id":41365}]}]}
{"op":"mcm","clk":"1009739643","pt":1580668925636,"mc":[{"id":"1.168230761","rc":[{"batb":[[0,1.63,216.61],[1,1.01,0.51],[2,1.01,0]],"ltp":0.0,"tv":0.0,"id":41364},{"batb":[[0,1.86,139.9],[1,1.01,0.51],[2,1.01,0]],"ltp":0.0,"tv":0.0,"id":41365}]}]}
{"op":"mcm","clk":"1009741421","pt":1580668943559,"mc":[{"id":"1.168230761","rc":[{"batb":[[1,1.49,303.55],[2,1.01,0.51]],"ltp":0.0,"tv":0.0,"id":41364},{"batb":[[0,2.3,145.88],[1,2.1,193.87],[2,1.86,139.9]],"ltp":0.0,"tv":0.0,"id":41365}]}]}
{"op":"mcm","clk":"1009741511","pt":1580668944555,"mc":[{"id":"1.168230761","rc":[{"batb":[[2,1.01,0.51]],"ltp":0.0,"tv":0.0,"id":41365}]}]}
{"op":"mcm","clk":"1009742317","pt":1580668952362,"mc":[{"id":"1.168230761","rc":[{"batb":[[0,1.49,303.55],[1,1.01,0.51],[2,1.01,0]],"ltp":0.0,"tv":0.0,"id":41364},{"batb":[[0,2.1,193.87],[1,1.01,0.51],[2,1.01,0]],"ltp":0.0,"tv":0.0,"id":41365}]}]}
{"op":"mcm","clk":"1009744198","pt":1580668970569,"mc":[{"id":"1.168230761","rc":[{"batb":[[1,1.41,389.55],[2,1.01,0.51]],"ltp":0.0,"tv":0.0,"id":41364},{"batb":[[0,2.66,98.27],[1,2.48,120.86],[2,1.01,0.51]],"ltp":0.0,"tv":0.0,"id":41365}]}]}
{"op":"mcm","clk":"1009745170","pt":1580668980373,"mc":[{"id":"1.168230761","rc":[{"batb":[[0,1.41,389.55],[1,1.01,0.51],[2,1.01,0]],"ltp":0.0,"tv":0.0,"id":41364},{"batb":[[0,2.48,120.86],[1,1.01,0.51],[2,1.01,0]],"ltp":0.0,"tv":0.0,"id":41365}]}]}
{"op":"mcm","clk":"1009745458","pt":1580668983307,"mc":[{"id":"1.168230761","rc":[{"batb":[[0,1.4,392.39]],"ltp":0.0,"tv":0.0,"id":41364},{"batb":[[0,2.48,119.75]],"ltp":0.0,"tv":0.0,"id":41365}]}]}
{"op":"mcm","clk":"1009746469","pt":1580668994200,"mc":[{"id":"1.168230761","rc":[{"batb":[[1,1.32,515.05],[2,1.01,0.51]],"ltp":0.0,"tv":0.0,"id":41364},{"batb":[[0,3,180.42],[1,2.62,104.33],[2,1.01,0.51]],"ltp":0.0,"tv":0.0,"id":41365}]}]}
{"op":"mcm","clk":"1009749660","pt":1580669024616,"mc":[{"id":"1.168230761","rc":[{"batb":[[0,1.32,515.05],[1,1.01,0.51],[2,1.01,0]],"ltp":0.0,"tv":0.0,"id":41364},{"batb":[[0,2.62,104.33],[1,1.01,0.51],[2,1.01,0]],"ltp":0.0,"tv":0.0,"id":41365}]}]}
{"op":"mcm","clk":"1009750035","pt":1580669027630,"mc":[{"id":"1.168230761","rc":[{"batb":[[1,2.6,105.12],[2,1.01,0.51]],"ltp":0.0,"tv":0.0,"id":41365}]}]}
{"op":"mcm","clk":"1009750132","pt":1580669028633,"mc":[{"id":"1.168230761","rc":[{"batb":[[0,2.6,105.12],[1,1.01,0.51],[2,1.01,0]],"ltp":0.0,"tv":0.0,"id":41365}]}]}
{"op":"mcm","clk":"1009751796","pt":1580669044534,"mc":[{"id":"1.168230761","rc":[{"batb":[[0,1.32,514.58],[1,1.26,668.72],[2,1.01,0.51]],"ltp":0.0,"tv":0.0,"id":41364},{"batb":[[0,3.45,125.97],[1,2.96,186.55],[2,1.01,0.51]],"ltp":0.0,"tv":0.0,"id":41365}]}]}
{"op":"mcm","clk":"1009753324","pt":1580669058648,"mc":[{"id":"1.168230761","rc":[{"batb":[[0,1.26,668.72],[1,1.01,0.51],[2,1.01,0]],"ltp":0.0,"tv":0.0,"id":41364},{"batb":[[0,2.96,186.55],[1,1.01,0.51],[2,1.01,0]],"ltp":0.0,"tv":0.0,"id":41365}]}]}
{"op":"mcm","clk":"1009753622","pt":1580669061455,"mc":[{"id":"1.168230761","rc":[{"batb":[[0,2.98,184.43]],"ltp":0.0,"tv":0.0,"id":41365}]}]}
{"op":"mcm","clk":"1009754240","pt":1580669068620,"mc":[{"id":"1.168230761","rc":[{"batb":[[1,1.21,849.84],[2,1.01,0.51]],"ltp":0.0,"tv":0.0,"id":41364},{"batb":[[0,4,174.99],[1,3.5,122.59],[2,2.98,184.43]],"ltp":0.0,"tv":0.0,"id":41365}]}]}
{"op":"mcm","clk":"1009754320","pt":1580669069561,"mc":[{"id":"1.168230761","rc":[{"batb":[[2,1.01,0.51]],"ltp":0.0,"tv":0.0,"id":41365}]}]}
{"op":"mcm","clk":"1009755232","pt":1580669079553,"mc":[{"id":"1.168230761","rc":[{"batb":[[0,1.21,849.84],[1,1.01,0.51],[2,1.01,0]],"ltp":0.0,"tv":0.0,"id":41364},{"batb":[[0,3.5,122.59],[1,1.01,0.51],[2,1.01,0]],"ltp":0.0,"tv":0.0,"id":41365}]}]}
{"op":"mcm","clk":"1009756197","pt":1580669090559,"mc":[{"id":"1.168230761","rc":[{"batb":[[0,1.32,524.89],[1,1.24,714.04],[2,1.21,849.84]],"ltp":0.0,"tv":0.0,"id":41364},{"batb":[[1,2.92,192.22],[2,1.01,0.51]],"ltp":0.0,"tv":0.0,"id":41365}]}]}
{"op":"mcm","clk":"1009756278","pt":1580669091549,"mc":[{"id":"1.168230761","rc":[{"batb":[[2,1.01,0.51]],"ltp":0.0,"tv":0.0,"id":41364}]}]}
{"op":"mcm","clk":"1009757589","pt":1580669106597,"mc":[{"id":"1.168230761","rc":[{"batb":[[0,1.24,714.04],[1,1.01,0.51],[2,1.01,0]],"ltp":0.0,"tv":0.0,"id":41364},{"batb":[[0,2.92,192.22],[1,1.01,0.51],[2,1.01,0]],"ltp":0.0,"tv":0.0,"id":41365}]}]}
{"op":"mcm","clk":"1009757862","pt":1580669109607,"mc":[{"id":"1.168230761","rc":[{"batb":[[0,2.94,190.57]],"ltp":0.0,"tv":0.0,"id":41365}]}]}
{"op":"mcm","clk":"1009758861","pt":1580669121509,"mc":[{"id":"1.168230761","rc":[{"batb":[[0,1.42,376.73],[1,1.3,562.1],[2,1.01,0.51]],"ltp":0.0,"tv":0.0,"id":41364},{"batb":[[0,2.94,190.1],[1,2.42,127.46],[2,1.01,0.51]],"ltp":0.0,"tv":0.0,"id":41365}]}]}
{"op":"mcm","clk":"1009760278","pt":1580669137615,"mc":[{"id":"1.168230761","rc":[{"batb":[[0,1.3,562.1],[1,1.01,0.51],[2,1.01,0]],"ltp":0.0,"tv":0.0,"id":41364},{"batb":[[0,2.42,127.46],[1,1.01,0.51],[2,1.01,0]],"ltp":0.0,"tv":0.0,"id":41365}]}]}
{"op":"mcm","clk":"1009760952","pt":1580669145524,"mc":[{"id":"1.168230761","rc":[{"batb":[[1,1.21,846.77],[2,1.01,0.51]],"ltp":0.0,"tv":0.0,"id":41364},{"batb":[[0,3.6,111.57],[1,2.92,192.53],[2,2.42,127.46]],"ltp":0.0,"tv":0.0,"id":41365}]}]}
{"op":"mcm","clk":"1009761060","pt":1580669146632,"mc":[{"id":"1.168230761","rc":[{"batb":[[2,1.01,0.51]],"ltp":0.0,"tv":0.0,"id":41365}]}]}
{"op":"mcm","clk":"1009762273","pt":1580669161479,"mc":[{"id":"1.168230761","rc":[{"batb":[[0,1.21,846.77],[1,1.01,0.51],[2,1.01,0]],"ltp":0.0,"tv":0.0,"id":41364},{"batb":[[0,2.92,192.53],[1,1.01,0.51],[2,1.01,0]],"ltp":0.0,"tv":0.0,"id":41365}]}]}
{"op":"mcm","clk":"1009764518","pt":1580669187166,"mc":[{"id":"1.168230761","rc":[{"batb":[[0,1.42,372.32],[1,1.3,557.78],[2,1.01,0.51]],"ltp":0.0,"tv":0.0,"id":41364},{"batb":[[1,2.4,129.83],[2,1.01,0.51]],"ltp":0.0,"tv":0.0,"id":41365}]}]}
{"op":"mcm","clk":"1009766573","pt":1580669210610,"mc":[{"id":"1.168230761","rc":[{"batb":[[0,1.3,556.91],[1,1.01,0.51],[2,1.01,0]],"ltp":0.0,"tv":0.0,"id":41364},{"batb":[[0,2.4,129.83],[1,1.01,0.51],[2,1.01,0]],"ltp":0.0,"tv":0.0,"id":41365}]}]}
{"op":"mcm","clk":"1009767810","pt":1580669224598,"mc":[{"id":"1.168230761","rc":[{"batb":[[0,1.59,239.59],[1,1.42,369.1],[2,1.01,0.51]],"ltp":0.0,"tv":0.0,"id":41364},{"batb":[[1,2,218.81],[2,1.01,0.51]],"ltp":0.0,"tv":0.0,"id":41365}]}]}
{"op":"mcm","clk":"1009768924","pt":1580669238637,"mc":[{"id":"1.168230761","rc":[{"batb":[[0,1.42,369.1],[1,1.01,0.51],[2,1.01,0]],"ltp":0.0,"tv":0.0,"id":41364},{"batb":[[0,2,218.81],[1,1.01,0.51],[2,1.01,0]],"ltp":0.0,"tv":0.0,"id":41365}]}]}
{"op":"mcm","clk":"1009770618","pt":1580669259342,"mc":[{"id":"1.168230761","rc":[{"batb":[[0,1.82,148.94],[1,1.65,210.16],[2,1.01,0.51]],"ltp":0.0,"tv":0.0,"id":41364},{"batb":[[1,1.85,141.78],[2,1.01,0.51]],"ltp":0.0,"tv":0.0,"id":41365}]}]}
{"op":"mcm","clk":"1009771358","pt":1580669267363,"mc":[{"id":"1.168230761","rc":[{"batb":[[0,1.84,145.88],[1,1.66,206.07]],"ltp":0.0,"tv":0.0,"id":41364},{"batb":[[1,1.84,144.77]],"ltp":0.0,"tv":0.0,"id":41365}]}]}
{"op":"mcm","clk":"1009772980","pt":1580669284588,"mc":[{"id":"1.168230761","rc":[{"batb":[[0,1.84,145.56],[1,1.66,205.6]],"ltp":0.0,"tv":0.0,"id":41364}]}]}
{"op":"mcm","clk":"1009775655","pt":1580669313613,"mc":[{"id":"1.168230761","rc":[{"batb":[[1,1.66,205.44]],"ltp":0.0,"tv":0.0,"id":41364}]}]}
{"op":"mcm","clk":"1009778191","pt":1580669340305,"mc":[{"id":"1.168230761","rc":[{"batb":[[0,1.66,205.44],[1,1.01,0.51],[2,1.01,0]],"ltp":0.0,"tv":0.0,"id":41364},{"batb":[[0,1.84,144.77],[1,1.01,0.51],[2,1.01,0]],"ltp":0.0,"tv":0.0,"id":41365}]}]}
{"op":"mcm","clk":"1009779356","pt":1580669351474,"mc":[{"id":"1.168230761","rc":[{"batb":[[0,2,224.64],[1,1.81,151.78],[2,1.01,0.51]],"ltp":0.0,"tv":0.0,"id":41364},{"batb":[[1,1.7,189.86],[2,1.01,0.51]],"ltp":0.0,"tv":0.0,"id":41365}]}]}
{"op":"mcm","clk":"1009780293","pt":1580669360594,"mc":[{"id":"1.168230761","rc":[{"batb":[[0,1.81,151.78],[1,1.01,0.51],[2,1.01,0]],"ltp":0.0,"tv":0.0,"id":41364},{"batb":[[0,1.7,189.86],[1,1.01,0.51],[2,1.01,0]],"ltp":0.0,"tv":0.0,"id":41365}]}]}
{"op":"mcm","clk":"1009783307","pt":1580669391639,"mc":[{"id":"1.168230761","rc":[{"batb":[[1,1.61,227],[2,1.01,0.51]],"ltp":0.0,"tv":0.0,"id":41364},{"batb":[[0,2.02,214.49],[1,1.83,147.14],[2,1.7,189.86]],"ltp":0.0,"tv":0.0,"id":41365}]}]}
{"op":"mcm","clk":"1009783347","pt":1580669392057,"mc":[{"id":"1.168230761","rc":[{"batb":[[2,1.01,0.51]],"ltp":0.0,"tv":0.0,"id":41365}]}]}
{"op":"mcm","clk":"1009784204","pt":1580669401541,"mc":[{"id":"1.168230761","rc":[{"batb":[[0,1.61,227],[1,1.01,0.51],[2,1.01,0]],"ltp":0.0,"tv":0.0,"id":41364},{"batb":[[0,1.83,147.14],[1,1.01,0.51],[2,1.01,0]],"ltp":0.0,"tv":0.0,"id":41365}]}]}
{"op":"mcm","clk":"1009785047","pt":1580669410452,"mc":[{"id":"1.168230761","rc":[{"batb":[[0,2,221.02],[1,1.79,158.15],[2,1.01,0.51]],"ltp":0.0,"tv":0.0,"id":41364},{"batb":[[1,1.68,197.89],[2,1.01,0.51]],"ltp":0.0,"tv":0.0,"id":41365}]}]}
{"op":"mcm","clk":"1009785872","pt":1580669418483,"mc":[{"id":"1.168230761","rc":[{"batb":[[0,1.79,158.15],[1,1.01,0.51],[2,1.01,0]],"ltp":0.0,"tv":0.0,"id":41364},{"batb":[[0,1.68,197.41],[1,1.01,0.51],[2,1.01,0]],"ltp":0.0,"tv":0.0,"id":41365}]}]}
{"op":"mcm","clk":"1009788379","pt":1580669442292,"mc":[{"id":"1.168230761","rc":[{"batb":[[0,2.22,161.77],[1,2.04,211.02],[2,1.01,0.51]],"ltp":0.0,"tv":0.0,"id":41364},{"batb":[[1,1.59,235.73],[2,1.01,0.51]],"ltp":0.0,"tv":0.0,"id":41365}]}]}
{"op":"mcm","clk":"1009789297","pt":1580669452114,"mc":[{"id":"1.168230761","rc":[{"batb":[[0,2.04,211.02],[1,1.01,0.51],[2,1.01,0]],"ltp":0.0,"tv":0.0,"id":41364},{"batb":[[0,1.59,235.73],[1,1.01,0.51],[2,1.01,0]],"ltp":0.0,"tv":0.0,"id":41365}]}]}
{"op":"mcm","clk":"1009790914","pt":1580669468540,"mc":[{"id":"1.168230761","rc":[{"batb":[[1,1.77,163.58],[2,1.01,0.51]],"ltp":0.0,"tv":0.0,"id":41364},{"batb":[[0,1.8,154.14],[1,1.63,216.3],[2,1.01,0.51]],"ltp":0.0,"tv":0.0,"id":41365}]}]}
{"op":"mcm","clk":"1009791591","pt":1580669475623,"mc":[{"id":"1.168230761","rc":[{"batb":[[0,1.77,163.58],[1,1.01,0.51],[2,1.01,0]],"ltp":0.0,"tv":0.0,"id":41364},{"batb":[[0,1.63,216.3],[1,1.01,0.51],[2,1.01,0]],"ltp":0.0,"tv":0.0,"id":41365}]}]}
{"op":"mcm","clk":"1009791910","pt":1580669479221,"mc":[{"id":"1.168230761","rc":[{"batb":[[0,1.78,159.72]],"ltp":0.0,"tv":0.0,"id":41364},{"batb":[[0,1.62,221.33]],"ltp":0.0,"tv":0.0,"id":41365}]}]}
{"op":"mcm","clk":"1009793105","pt":1580669492541,"mc":[{"id":"1.168230761","rc":[{"batb":[[1,1.55,261.77],[2,1.01,0.51]],"ltp":0.0,"tv":0.0,"id":41364},{"batb":[[0,2.06,203.31],[1,1.8,154.61],[2,1.01,0.51]],"ltp":0.0,"tv":0.0,"id":41365}]}]}
{"op":"mcm","clk":"1009793975","pt":1580669502339,"mc":[{"id":"1.168230761","rc":[{"batb":[[0,1.55,261.77],[1,1.01,0.51],[2,1.01,0]],"ltp":0.0,"tv":0.0,"id":41364},{"batb":[[0,1.8,154.61],[1,1.01,0.51],[2,1.01,0]],"ltp":0.0,"tv":0.0,"id":41365}]}]}
{"op":"mcm","clk":"1009796144","pt":1580669526559,"mc":[{"id":"1.168230761","rc":[{"batb":[[1,1.35,473.43],[2,1.01,0.51]],"ltp":0.0,"tv":0.0,"id":41364},{"batb":[[0,2.5,116.76],[1,2.06,201.74],[2,1.01,0.51]],"ltp":0.0,"tv":0.0,"id":41365}]}]}
{"op":"mcm","clk":"1009796985","pt":1580669535586,"mc":[{"id":"1.168230761","rc":[{"batb":[[0,1.35,473.43],[1,1.01,0.51],[2,1.01,0]],"ltp":0.0,"tv":0.0,"id":41364},{"batb":[[0,2.06,200.64],[1,1.01,0.51],[2,1.01,0]],"ltp":0.0,"tv":0.0,"id":41365}]}]}
{"op":"mcm","clk":"1009798385","pt":1580669551391,"mc":[{"id":"1.168230761","rc":[{"batb":[[0,1.78,161.77],[1,1.54,266.81],[2,1.01,0.51]],"ltp":0.0,"tv":0.0,"id":41364},{"batb":[[1,1.81,151.62],[2,1.01,0.51]],"ltp":0.0,"tv":0.0,"id":41365}]}]}
{"op":"mcm","clk":"1009799472","pt":1580669563306,"mc":[{"id":"1.168230761","rc":[{"batb":[[0,1.54,266.81],[1,1.01,0.51],[2,1.01,0]],"ltp":0.0,"tv":0.0,"id":41364},{"batb":[[0,1.81,151.62],[1,1.01,0.51],[2,1.01,0]],"ltp":0.0,"tv":0.0,"id":41365}]}]}
{"op":"mcm","clk":"1009799696","pt":1580669565605,"mc":[{"id":"1.168230761","rc":[{"batb":[[0,1.55,260.67],[1,1.54,266.81],[2,1.01,0.51]],"ltp":0.0,"tv":0.0,"id":41364},{"batb":[[1,1.8,155.48],[2,1.01,0.51]],"ltp":0.0,"tv":0.0,"id":41365}]}]}
{"op":"mcm","clk":"1009799767","pt":1580669566532,"mc":[{"id":"1.168230761","rc":[{"batb":[[1,1.01,0.51],[2,1.01,0]],"ltp":0.0,"tv":0.0,"id":41364},{"batb":[[0,1.8,155.48],[1,1.01,0.51],[2,1.01,0]],"ltp":0.0,"tv":0.0,"id":41365}]}]}
{"op":"mcm","clk":"1009800755","pt":1580669578614,"mc":[{"id":"1.168230761","rc":[{"batb":[[0,2.04,209.22],[1,1.78,161.77],[2,1.01,0.51]],"ltp":0.0,"tv":0.0,"id":41364},{"batb":[[1,1.63,219.21],[2,1.01,0.51]],"ltp":0.0,"tv":0.0,"id":41365}]}]}
{"op":"mcm","clk":"1009801774","pt":1580669589727,"mc":[{"id":"1.168230761","rc":[{"batb":[[0,1.78,161.38],[1,1.01,0.51],[2,1.01,0]],"ltp":0.0,"tv":0.0,"id":41364},{"batb":[[0,1.63,219.21],[1,1.01,0.51],[2,1.01,0]],"ltp":0.0,"tv":0.0,"id":41365}]}]}
{"op":"mcm","clk":"1009803264","pt":1580669606272,"mc":[{"id":"1.168230761","rc":[{"batb":[[1,1.55,264.76],[2,1.01,0.51]],"ltp":0.0,"tv":0.0,"id":41364},{"batb":[[0,2.06,201.11],[1,1.81,152.88],[2,1.01,0.51]],"ltp":0.0,"tv":0.0,"id":41365}]}]}
{"op":"mcm","clk":"1009804271","pt":1580669617564,"mc":[{"id":"1.168230761","rc":[{"batb":[[0,1.55,264.76],[1,1.01,0.51],[2,1.01,0]],"ltp":0.0,"tv":0.0,"id":41364},{"batb":[[0,1.81,152.88],[1,1.01,0.51],[2,1.01,0]],"ltp":0.0,"tv":0.0,"id":41365}]}]}
{"op":"mcm","clk":"1009806108","pt":1580669636482,"mc":[{"id":"1.168230761","rc":[{"batb":[[1,1.35,474.69],[2,1.01,0.51]],"ltp":0.0,"tv":0.0,"id":41364},{"batb":[[0,2.52,115.74],[1,2.08,196.39],[2,1.01,0.51]],"ltp":0.0,"tv":0.0,"id":41365}]}]}
{"op":"mcm","clk":"1009807415","pt":1580669649616,"mc":[{"id":"1.168230761","rc":[{"batb":[[0,1.35,474.69],[1,1.01,0.51],[2,1.01,0]],"ltp":0.0,"tv":0.0,"id":41364},{"batb":[[0,2.08,196.39],[1,1.01,0.51],[2,1.01,0]],"ltp":0.0,"tv":0.0,"id":41365}]}]}
{"op":"mcm","clk":"1009809380","pt":1580669670522,"mc":[{"id":"1.168230761","rc":[{"batb":[[1,1.27,649.99],[2,1.01,0.51]],"ltp":0.0,"tv":0.0,"id":41364},{"batb":[[0,3.3,140.45],[1,2.82,84.35],[2,1.01,0.51]],"ltp":0.0,"tv":0.0,"id":41365}]}]}
{"op":"mcm","clk":"1009812683","pt":1580669704164,"mc":[{"id":"1.168230761","rc":[{"batb":[[0,1.27,649.99],[1,1.01,0.51],[2,1.01,0]],"ltp":0.0,"tv":0.0,"id":41364},{"batb":[[0,2.82,84.35],[1,1.01,0.51],[2,1.01,0]],"ltp":0.0,"tv":0.0,"id":41365}]}]}
{"op":"mcm","clk":"1009813002","pt":1580669707483,"mc":[{"id":"1.168230761","rc":[{"batb":[[0,1.26,654.87]],"ltp":0.0,"tv":0.0,"id":41364},{"batb":[[0,2.84,208.74]],"ltp":0.0,"tv":0.0,"id":41365}]}]}
{"op":"mcm","clk":"1009813895","pt":1580669716573,"mc":[{"id":"1.168230761","rc":[{"batb":[[1,1.2,907.6],[2,1.01,0.51]],"ltp":0.0,"tv":0.0,"id":41364},{"batb":[[0,3.95,182.54],[1,3.3,140.13],[2,1.01,0.51]],"ltp":0.0,"tv":0.0,"id":41365}]}]}
{"op":"mcm","clk":"1009815273","pt":1580669731477,"mc":[{"id":"1.168230761","rc":[{"batb":[[0,1.2,898],[1,1.01,0.51],[2,1.01,0]],"ltp":0.0,"tv":0.0,"id":41364},{"batb":[[0,3.3,140.13],[1,1.01,0.51],[2,1.01,0]],"ltp":0.0,"tv":0.0,"id":41365}]}]}
{"op":"mcm","clk":"1009816471","pt":1580669745586,"mc":[{"id":"1.168230761","rc":[{"batb":[[0,1.35,470.28],[1,1.26,677.69],[2,1.2,898]],"ltp":0.0,"tv":0.0,"id":41364},{"batb":[[1,2.76,90.17],[2,1.01,0.51]],"ltp":0.0,"tv":0.0,"id":41365}]}]}
{"op":"mcm","clk":"1009816494","pt":1580669745898,"mc":[{"id":"1.168230761","rc":[{"batb":[[2,1.01,0.51]],"ltp":0.0,"tv":0.0,"id":41364}]}]}
{"op":"mcm","clk":"1009817744","pt":1580669760595,"mc":[{"id":"1.168230761","rc":[{"batb":[[0,1.26,677.69],[1,1.01,0.51],[2,1.01,0]],"ltp":0.0,"tv":0.0,"id":41364},{"batb":[[0,2.76,90.17],[1,1.01,0.51],[2,1.01,0]],"ltp":0.0,"tv":0.0,"id":41365}]}]}
{"op":"mcm","clk":"1009818623","pt":1580669771328,"mc":[{"id":"1.168230761","rc":[{"batb":[[1,1.18,1003.82],[2,1.01,0.51]],"ltp":0.0,"tv":0.0,"id":41364},{"batb":[[0,4,173.65],[1,3.25,144.7],[2,1.01,0.51]],"ltp":0.0,"tv":0.0,"id":41365}]}]}
{"op":"mcm","clk":"1009819712","pt":1580669785564,"mc":[{"id":"1.168230761","rc":[{"batb":[[0,1.18,1003.82],[1,1.01,0.51],[2,1.01,0]],"ltp":0.0,"tv":0.0,"id":41364},{"batb":[[0,3.25,144.15],[1,1.01,0.51],[2,1.01,0]],"ltp":0.0,"tv":0.0,"id":41365}]}]}
{"op":"mcm","clk":"1009820483","pt":1580669794561,"mc":[{"id":"1.168230761","rc":[{"batb":[[1,1.13,1356.55],[2,1.01,0.51]],"ltp":0.0,"tv":0.0,"id":41364},{"batb":[[0,5.1,96.39],[1,4.2,151.23],[2,1.01,0.51]],"ltp":0.0,"tv":0.0,"id":41365}]}]}
{"op":"mcm","clk":"1009821793","pt":1580669809591,"mc":[{"id":"1.168230761","rc":[{"batb":[[0,1.13,1355.45],[1,1.01,0.51],[2,1.01,0]],"ltp":0.0,"tv":0.0,"id":41364},{"batb":[[0,4.2,151.23],[1,1.01,0.51],[2,1.01,0]],"ltp":0.0,"tv":0.0,"id":41365}]}]}
{"op":"mcm","clk":"1009824285","pt":1580669835575,"mc":[{"id":"1.168230761","rc":[{"batb":[[0,1.24,744.8],[1,1.15,1249.39],[2,1.01,0.51]],"ltp":0.0,"tv":0.0,"id":41364},{"batb":[[1,3.25,145.25],[2,1.01,0.51]],"ltp":0.0,"tv":0.0,"id":41365}]}]}
{"op":"mcm","clk":"1009825657","pt":1580669850499,"mc":[{"id":"1.168230761","rc":[{"batb":[[0,1.15,1249.39],[1,1.01,0.51],[2,1.01,0]],"ltp":0.0,"tv":0.0,"id":41364},{"batb":[[0,3.25,145.25],[1,1.01,0.51],[2,1.01,0]],"ltp":0.0,"tv":0.0,"id":41365}]}]}
{"op":"mcm","clk":"1009825939","pt":1580669853617,"mc":[{"id":"1.168230761","rc":[{"batb":[[0,1.14,1250.57]],"ltp":0.0,"tv":0.0,"id":41364},{"batb":[[0,3.25,145.01]],"ltp":0.0,"tv":0.0,"id":41365}]}]}
{"op":"mcm","clk":"1009826855","pt":1580669864634,"mc":[{"id":"1.168230761","rc":[{"batb":[[1,1.1,1794.26],[2,1.01,0.51]],"ltp":0.0,"tv":0.0,"id":41364},{"batb":[[0,5.8,139.74],[1,5,101.18],[2,1.01,0.51]],"ltp":0.0,"tv":0.0,"id":41365}]}]}
{"op":"mcm","clk":"1009828815","pt":1580669887568,"mc":[{"id":"1.168230761","rc":[{"batb":[[0,5.8,139.11],[1,5,100.71]],"ltp":0.0,"tv":0.0,"id":41365}]}]}
{"op":"mcm","clk":"1009829839","pt":1580669898535,"mc":[{"id":"1.168230761","rc":[{"batb":[[0,5.9,137.14],[1,5.8,139.11],[2,5,100.71]],"ltp":0.0,"tv":0.0,"id":41365}]}]}
{"op":"mcm","clk":"1009829914","pt":1580669899516,"mc":[{"id":"1.168230761","rc":[{"batb":[[1,5,99.38],[2,1.01,0.51]],"ltp":0.0,"tv":0.0,"id":41365}]}]}
{"op":"mcm","clk":"1009830986","pt":1580669912506,"mc":[{"id":"1.168230761","rc":[{"batb":[[0,5.9,136.83],[1,5,99.14]],"ltp":0.0,"tv":0.0,"id":41365}]}]}
{"op":"mcm","clk":"1009833269","pt":1580669939510,"mc":[{"id":"1.168230761","rc":[{"batb":[[0,1.1,1794.26],[1,1.01,0.51],[2,1.01,0]],"ltp":0.0,"tv":0.0,"id":41364},{"batb":[[0,5,98.27],[1,1.01,0.51],[2,1.01,0]],"ltp":0.0,"tv":0.0,"id":41365}]}]}
{"op":"mcm","clk":"1009834950","pt":1580669956644,"mc":[{"id":"1.168230761","rc":[{"batb":[[0,1.18,993.91],[1,1.14,1308.48],[2,1.01,0.51]],"ltp":0.0,"tv":0.0,"id":41364},{"batb":[[1,4.4,138.64],[2,1.01,0.51]],"ltp":0.0,"tv":0.0,"id":41365}]}]}
{"op":"mcm","clk":"1009835513","pt":1580669962569,"mc":[{"id":"1.168230761","rc":[{"batb":[[0,1.14,1308.48],[1,1.01,0.51],[2,1.01,0]],"ltp":0.0,"tv":0.0,"id":41364},{"batb":[[0,4.4,138.64],[1,1.01,0.51],[2,1.01,0]],"ltp":0.0,"tv":0.0,"id":41365}]}]}
{"op":"mcm","clk":"1009837939","pt":1580669986368,"mc":[{"id":"1.168230761","rc":[{"batb":[[0,1.22,790.91],[1,1.18,975.89],[2,1.01,0.51]],"ltp":0.0,"tv":0.0,"id":41364},{"batb":[[1,4,175.62],[2,1.01,0.51]],"ltp":0.0,"tv":0.0,"id":41365}]}]}
{"op":"mcm","clk":"1009839019","pt":1580669996617,"mc":[{"id":"1.168230761","rc":[{"batb":[[0,1.18,975.89],[1,1.01,0.51],[2,1.01,0]],"ltp":0.0,"tv":0.0,"id":41364},{"batb":[[0,4,174.04],[1,1.01,0.51],[2,1.01,0]],"ltp":0.0,"tv":0.0,"id":41365}]}]}
{"op":"mcm","clk":"1009841264","pt":1580670016413,"mc":[{"id":"1.168230761","rc":[{"batb":[[0,1.26,676.82],[1,1.23,767.62],[2,1.01,0.51]],"ltp":0.0,"tv":0.0,"id":41364},{"batb":[[1,3.75,201.35],[2,1.01,0.51]],"ltp":0.0,"tv":0.0,"id":41365}]}]}
{"op":"mcm","clk":"1009842427","pt":1580670027547,"mc":[{"id":"1.168230761","rc":[{"batb":[[0,1.23,767.62],[1,1.01,0.51],[2,1.01,0]],"ltp":0.0,"tv":0.0,"id":41364},{"batb":[[0,3.75,201.35],[1,1.01,0.51],[2,1.01,0]],"ltp":0.0,"tv":0.0,"id":41365}]}]}
{"op":"mcm","clk":"1009844233","pt":1580670044647,"mc":[{"id":"1.168230761","rc":[{"batb":[[1,1.19,945.99],[2,1.01,0.51]],"ltp":0.0,"tv":0.0,"id":41364},{"batb":[[0,4.3,144.93],[1,3.95,181.44],[2,1.01,0.51]],"ltp":0.0,"tv":0.0,"id":41365}]}]}
{"op":"mcm","clk":"1009845261","pt":1580670054451,"mc":[{"id":"1.168230761","rc":[{"batb":[[0,1.19,945.99],[1,1.01,0.51],[2,1.01,0]],"ltp":0.0,"tv":0.0,"id":41364},{"batb":[[0,3.95,181.44],[1,1.01,0.51],[2,1.01,0]],"ltp":0.0,"tv":0.0,"id":41365}]}]}
{"op":"mcm","clk":"1009845640","pt":1580670057560,"mc":[{"id":"1.168230761","rc":[{"batb":[[0,1.19,938.91]],"ltp":0.0,"tv":0.0,"id":41364},{"batb":[[0,3.9,183.41]],"ltp":0.0,"tv":0.0,"id":41365}]}]}
{"op":"mcm","clk":"1009847909","pt":1580670077297,"mc":[{"id":"1.168230761","rc":[{"batb":[[0,1.26,652.67],[1,1.19,938.91],[2,1.01,0.51]],"ltp":0.0,"tv":0.0,"id":41364},{"batb":[[1,3.2,153.12],[2,1.01,0.51]],"ltp":0.0,"tv":0.0,"id":41365}]}]}
{"op":"mcm","clk":"1009851507","pt":1580670106526,"mc":[{"id":"1.168230761","rc":[{"batb":[[0,1.19,938.91],[1,1.01,0.51],[2,1.01,0]],"ltp":0.0,"tv":0.0,"id":41364},{"batb":[[0,3.2,153.12],[1,1.01,0.51],[2,1.01,0]],"ltp":0.0,"tv":0.0,"id":41365}]}]}
{"op":"mcm","clk":"1009852833","pt":1580670116642,"mc":[{"id":"1.168230761","rc":[{"batb":[[0,1.36,445.02],[1,1.27,644.33],[2,1.01,0.51]],"ltp":0.0,"tv":0.0,"id":41364},{"batb":[[1,2.7,96.15],[2,1.01,0.51]],"ltp":0.0,"tv":0.0,"id":41365}]}]}
{"op":"mcm","clk":"1009854093","pt":1580670126632,"mc":[{"id":"1.168230761","rc":[{"batb":[[0,1.27,644.33],[1,1.01,0.51],[2,1.01,0]],"ltp":0.0,"tv":0.0,"id":41364},{"batb":[[0,2.7,95.76],[1,1.01,0.51],[2,1.01,0]],"ltp":0.0,"tv":0.0,"id":41365}]}]}
{"op":"mcm","clk":"1009858561","pt":1580670165487,"mc":[{"id":"1.168230761","rc":[{"batb":[[0,1.48,310.16],[1,1.39,414.89],[2,1.01,0.51]],"ltp":0.0,"tv":0.0,"id":41364},{"batb":[[1,2.36,138.48],[2,1.01,0.51]],"ltp":0.0,"tv":0.0,"id":41365}]}]}
{"op":"mcm","clk":"1009860086","pt":1580670178591,"mc":[{"id":"1.168230761","rc":[{"batb":[[0,1.39,414.89],[1,1.01,0.51],[2,1.01,0]],"ltp":0.0,"tv":0.0,"id":41364},{"batb":[[0,2.36,138.48],[1,1.01,0.51],[2,1.01,0]],"ltp":0.0,"tv":0.0,"id":41365}]}]}
{"op":"mcm","clk":"1009860427","pt":1580670181494,"mc":[{"id":"1.168230761","rc":[{"batb":[[0,1.38,416.38]],"ltp":0.0,"tv":0.0,"id":41364},{"batb":[[0,2.36,137.93]],"ltp":0.0,"tv":0.0,"id":41365}]}]}
{"op":"mcm","clk":"1009862593","pt":1580670199302,"mc":[{"id":"1.168230761","rc":[{"batb":[[0,1.61,227.63],[1,1.53,273.34],[2,1.01,0.51]],"ltp":0.0,"tv":0.0,"id":41364},{"batb":[[1,2.18,172.94],[2,1.01,0.51]],"ltp":0.0,"tv":0.0,"id":41365}]}]}
{"op":"mcm","clk":"1009863998","pt":1580670211620,"mc":[{"id":"1.168230761","rc":[{"batb":[[0,1.53,273.34],[1,1.01,0.51],[2,1.01,0]],"ltp":0.0,"tv":0.0,"id":41364},{"batb":[[0,2.18,172.55],[1,1.01,0.51],[2,1.01,0]],"ltp":0.0,"tv":0.0,"id":41365}]}]}
{"op":"mcm","clk":"1009866448","pt":1580670232142,"mc":[{"id":"1.168230761","rc":[{"batb":[[0,1.7,186.16],[1,1.5,296.55],[2,1.01,0.51]],"ltp":0.0,"tv":0.0,"id":41364},{"batb":[[1,1.92,126.91],[2,1.01,0.51]],"ltp":0.0,"tv":0.0,"id":41365}]}]}
{"op":"mcm","clk":"1009866972","pt":1580670236540,"mc":[{"id":"1.168230761","rc":[{"batb":[[0,1.5,296.55],[1,1.01,0.51],[2,1.01,0]],"ltp":0.0,"tv":0.0,"id":41364},{"batb":[[0,1.92,126.91],[1,1.01,0.51],[2,1.01,0]],"ltp":0.0,"tv":0.0,"id":41365}]}]}
{"op":"mcm","clk":"1009867315","pt":1580670239544,"mc":[{"id":"1.168230761","rc":[{"batb":[[0,1.71,184.98],[1,1.5,294.74],[2,1.01,0.51]],"ltp":0.0,"tv":0.0,"id":41364},{"batb":[[0,1.91,127.78]],"ltp":0.0,"tv":0.0,"id":41365}]}]}
{"op":"mcm","clk":"1009869133","pt":1580670255560,"mc":[{"id":"1.168230761","rc":[{"batb":[[0,2.18,173.57],[1,1.91,127.62],[2,1.01,0.51]],"ltp":0.0,"tv":0.0,"id":41365}]}]}
{"op":"mcm","clk":"1009869752","pt":1580670260582,"mc":[{"id":"1.168230761","rc":[{"batb":[[1,1.7,186.87],[2,1.5,294.74]],"ltp":0.0,"tv":0.0,"id":41364},{"batb":[[1,1.92,252.81],[2,1.91,127.62]],"ltp":0.0,"tv":0.0,"id":41365}]}]}
{"op":"mcm","clk":"1009869850","pt":1580670261375,"mc":[{"id":"1.168230761","rc":[{"batb":[[0,1.7,186.87],[1,1.5,294.74],[2,1.01,0.51]],"ltp":0.0,"tv":0.0,"id":41364},{"batb":[[0,2.18,171.84],[2,1.01,0.51]],"ltp":0.0,"tv":0.0,"id":41365}]}]}
{"op":"mcm","clk":"1009869985","pt":1580670262578,"mc":[{"id":"1.168230761","rc":[{"batb":[[0,2.18,171.21],[1,1.92,251.94]],"ltp":0.0,"tv":0.0,"id":41365}]}]}
{"op":"mcm","clk":"1009870854","pt":1580670270648,"mc":[{"id":"1.168230761","rc":[{"batb":[[2,1.49,302.22]],"ltp":0.0,"tv":0.0,"id":41364},{"batb":[[0,2.2,168.85],[1,2.18,171.21],[2,1.93,248.56]],"ltp":0.0,"tv":0.0,"id":41365}]}]}
{"op":"mcm","clk":"1009870980","pt":1580670271594,"mc":[{"id":"1.168230761","rc":[{"batb":[[1,1.49,302.22],[2,1.01,0.51]],"ltp":0.0,"tv":0.0,"id":41364},{"batb":[[1,1.93,248.56],[2,1.01,0.51]],"ltp":0.0,"tv":0.0,"id":41365}]}]}
{"op":"mcm","clk":"1009873865","pt":1580670297998,"mc":[{"id":"1.168230761","rc":[{"batb":[[0,1.49,302.22],[1,1.01,0.51],[2,1.01,0]],"ltp":0.0,"tv":0.0,"id":41364},{"batb":[[0,1.93,248.56],[1,1.01,0.51],[2,1.01,0]],"ltp":0.0,"tv":0.0,"id":41365}]}]}
{"op":"mcm","clk":"1009875943","pt":1580670314610,"mc":[{"id":"1.168230761","rc":[{"batb":[[0,1.01,0.51],[1,1.01,0]],"ltp":0.0,"tv":0.0,"id":41364},{"batb":[[0,1.01,0.51],[1,1.01,0]],"ltp":0.0,"tv":0.0,"id":41365}]}]}
{"op":"mcm","clk":"1009877799","pt":1580670330220,"mc":[{"id":"1.168230761","rc":[{"batb":[[0,1.49,302.22],[1,1.33,506.08],[2,1.01,0.51]],"ltp":0.0,"tv":0.0,"id":41364},{"batb":[[0,2.66,98.82],[1,2.24,160.51],[2,1.01,0.51]],"ltp":0.0,"tv":0.0,"id":41365}]}]}
{"op":"mcm","clk":"1009878655","pt":1580670337638,"mc":[{"id":"1.168230761","rc":[{"batb":[[0,1.33,506.08],[1,1.01,0.51],[2,1.01,0]],"ltp":0.0,"tv":0.0,"id":41364},{"batb":[[0,2.24,160.51],[1,1.01,0.51],[2,1.01,0]],"ltp":0.0,"tv":0.0,"id":41365}]}]}
{"op":"mcm","clk":"1009881065","pt":1580670358500,"mc":[{"id":"1.168230761","rc":[{"batb":[[1,1.21,844.89],[2,1.01,0.51]],"ltp":0.0,"tv":0.0,"id":41364},{"batb":[[0,3.4,128.88],[1,2.8,86.39],[2,1.01,0.51]],"ltp":0.0,"tv":0.0,"id":41365}]}]}
{"op":"mcm","clk":"1009882516","pt":1580670370587,"mc":[{"id":"1.168230761","rc":[{"batb":[[0,1.21,844.89],[1,1.01,0.51],[2,1.01,0]],"ltp":0.0,"tv":0.0,"id":41364},{"batb":[[0,2.8,86.39],[1,1.01,0.51],[2,1.01,0]],"ltp":0.0,"tv":0.0,"id":41365}]}]}
{"op":"mcm","clk":"1009884167","pt":1580670383631,"mc":[{"id":"1.168230761","rc":[{"batb":[[0,1.45,337.23],[1,1.27,640.47],[2,1.01,0.51]],"ltp":0.0,"tv":0.0,"id":41364},{"batb":[[1,2.26,155.4],[2,1.01,0.51]],"ltp":0.0,"tv":0.0,"id":41365}]}]}
{"op":"mcm","clk":"1009885329","pt":1580670393207,"mc":[{"id":"1.168230761","rc":[{"batb":[[0,1.27,640.47],[1,1.01,0.51],[2,1.01,0]],"ltp":0.0,"tv":0.0,"id":41364},{"batb":[[0,2.26,155.4],[1,1.01,0.51],[2,1.01,0]],"ltp":0.0,"tv":0.0,"id":41365}]}]}
{"op":"mcm","clk":"1009888954","pt":1580670422642,"mc":[{"id":"1.168230761","rc":[{"batb":[[1,1.16,1135.85],[2,1.01,0.51]],"ltp":0.0,"tv":0.0,"id":41364},{"batb":[[0,3.85,188.44],[1,3.05,169.01],[2,1.01,0.51]],"ltp":0.0,"tv":0.0,"id":41365}]}]}
{"op":"mcm","clk":"1009890849","pt":1580670438410,"mc":[{"id":"1.168230761","rc":[{"batb":[[0,1.16,1135.85],[1,1.01,0.51],[2,1.01,0]],"ltp":0.0,"tv":0.0,"id":41364},{"batb":[[0,3.05,168.54],[1,1.01,0.51],[2,1.01,0]],"ltp":0.0,"tv":0.0,"id":41365}]}]}
{"op":"mcm","clk":"1009892082","pt":1580670447575,"mc":[{"id":"1.168230761","rc":[{"batb":[[0,1.39,413.55],[1,1.17,1079.67],[2,1.16,1135.85]],"ltp":0.0,"tv":0.0,"id":41364},{"batb":[[1,2.28,152.8],[2,1.01,0.51]],"ltp":0.0,"tv":0.0,"id":41365}]}]}
{"op":"mcm","clk":"1009892109","pt":1580670447789,"mc":[{"id":"1.168230761","rc":[{"batb":[[2,1.01,0.51]],"ltp":0.0,"tv":0.0,"id":41364}]}]}
{"op":"mcm","clk":"1009893467","pt":1580670458518,"mc":[{"id":"1.168230761","rc":[{"batb":[[0,1.17,1079.67],[1,1.01,0.51],[2,1.01,0]],"ltp":0.0,"tv":0.0,"id":41364},{"batb":[[0,2.28,152.8],[1,1.01,0.51],[2,1.01,0]],"ltp":0.0,"tv":0.0,"id":41365}]}]}
{"op":"mcm","clk":"1009896760","pt":1580670484322,"mc":[{"id":"1.168230761","rc":[{"batb":[[1,1.1,1883.17],[2,1.01,0.51]],"ltp":0.0,"tv":0.0,"id":41364},{"batb":[[0,5.3,86.47],[1,4,168.62],[2,1.01,0.51]],"ltp":0.0,"tv":0.0,"id":41365}]}]}
{"op":"mcm","clk":"1009900573","pt":1580670514436,"mc":[{"id":"1.168230761","rc":[{"batb":[[0,1.1,1883.17],[1,1.01,0.51],[2,1.01,0]],"ltp":0.0,"tv":0.0,"id":41364},{"batb":[[0,4,168.62],[1,1.01,0.51],[2,1.01,0]],"ltp":0.0,"tv":0.0,"id":41365}]}]}
{"op":"mcm","clk":"1009900942","pt":1580670517552,"mc":[{"id":"1.168230761","rc":[{"batb":[[0,1.09,1993.01]],"ltp":0.0,"tv":0.0,"id":41364},{"batb":[[0,4.2,154.37]],"ltp":0.0,"tv":0.0,"id":41365}]}]}
{"op":"mcm","clk":"1009904116","pt":1580670543482,"mc":[{"id":"1.168230761","rc":[{"batb":[[1,1.03,4456.54],[2,1.01,0.51]],"ltp":0.0,"tv":0.0,"id":41364},{"batb":[[0,8,65.31],[1,5.5,158.62],[2,1.01,0.51]],"ltp":0.0,"tv":0.0,"id":41365}]}]}
{"op":"mcm","clk":"1009906068","pt":1580670560435,"mc":[{"id":"1.168230761","rc":[{"batb":[[0,1.03,4453.24],[1,1.01,0.51],[2,1.01,0]],"ltp":0.0,"tv":0.0,"id":41364},{"batb":[[0,5.5,158.62],[1,1.01,0.51],[2,1.01,0]],"ltp":0.0,"tv":0.0,"id":41365}]}]}
{"op":"mcm","clk":"1009909231","pt":1580670584570,"mc":[{"id":"1.168230761","rc":[{"batb":[[0,13.5,42.57],[1,8.4,56.73],[2,1.01,0.51]],"ltp":0.0,"tv":0.0,"id":41365}]}]}
{"op":"mcm","clk":"1009910812","pt":1580670597191,"mc":[{"id":"1.168230761","rc":[{"batb":[[0,1.01,0.51],[1,1.01,0]],"ltp":0.0,"tv":0.0,"id":41364},{"batb":[[0,8.4,56.73],[1,1.01,0.51],[2,1.01,0]],"ltp":0.0,"tv":0.0,"id":41365}]}]}
{"op":"mcm","clk":"1009913343","pt":1580670618509,"mc":[{"id":"1.168230761","rc":[{"batb":[[0,1.08,2203.02],[1,1.01,0.51]],"ltp":0.0,"tv":0.0,"id":41364},{"batb":[[1,5.5,160.2],[2,1.01,0.51]],"ltp":0.0,"tv":0.0,"id":41365}]}]}
{"op":"mcm","clk":"1009914968","pt":1580670632096,"mc":[{"id":"1.168230761","rc":[{"batb":[[0,1.01,0.51],[1,1.01,0]],"ltp":0.0,"tv":0.0,"id":41364},{"batb":[[0,5.5,159.88],[1,1.01,0.51],[2,1.01,0]],"ltp":0.0,"tv":0.0,"id":41365}]}]}
{"op":"mcm","clk":"1009916755","pt":1580670646523,"mc":[{"id":"1.168230761","rc":[{"batb":[[0,1.16,1148.99],[1,1.06,2961.67],[2,1.01,0.51]],"ltp":0.0,"tv":0.0,"id":41364},{"batb":[[1,3.7,209.14],[2,1.01,0.51]],"ltp":0.0,"tv":0.0,"id":41365}]}]}
{"op":"mcm","clk":"1009918797","pt":1580670662555,"mc":[{"id":"1.168230761","rc":[{"batb":[[0,1.06,2961.67],[1,1.01,0.51],[2,1.01,0]],"ltp":0.0,"tv":0.0,"id":41364},{"batb":[[0,3.7,209.14],[1,1.01,0.51],[2,1.01,0]],"ltp":0.0,"tv":0.0,"id":41365}]}]}
{"op":"mcm","clk":"1009919191","pt":1580670665563,"mc":[{"id":"1.168230761","rc":[{"batb":[[1,1.05,3076.7],[2,1.01,0.51]],"ltp":0.0,"tv":0.0,"id":41364},{"batb":[[0,3.8,197.02],[1,3.7,209.14],[2,1.01,0.51]],"ltp":0.0,"tv":0.0,"id":41365}]}]}
{"op":"mcm","clk":"1009919348","pt":1580670666578,"mc":[{"id":"1.168230761","rc":[{"batb":[[0,1.05,3076.7],[1,1.01,0.51],[2,1.01,0]],"ltp":0.0,"tv":0.0,"id":41364},{"batb":[[1,1.01,0.51],[2,1.01,0]],"ltp":0.0,"tv":0.0,"id":41365}]}]}
{"op":"mcm","clk":"1009920211","pt":1580670672549,"mc":[{"id":"1.168230761","rc":[{"batb":[[0,10.5,80.49],[1,5.6,150.99],[2,1.01,0.51]],"ltp":0.0,"tv":0.0,"id":41365}]}]}
{"op":"mcm","clk":"1009922316","pt":1580670687262,"mc":[{"id":"1.168230761","rc":[{"batb":[[0,1.01,0.51],[1,1.01,0]],"ltp":0.0,"tv":0.0,"id":41364},{"batb":[[0,5.6,150.99],[1,1.01,0.51],[2,1.01,0]],"ltp":0.0,"tv":0.0,"id":41365}]}]}
{"op":"mcm","clk":"1009925494","pt":1580670709111,"mc":[{"id":"1.168230761","rc":[{"batb":[[0,1.15,1191.4],[1,1.05,3114.7],[2,1.01,0.51]],"ltp":0.0,"tv":0.0,"id":41364},{"batb":[[1,3.8,195.76],[2,1.01,0.51]],"ltp":0.0,"tv":0.0,"id":41365}]}]}
{"op":"mcm","clk":"1009927911","pt":1580670726602,"mc":[{"id":"1.168230761","rc":[{"batb":[[0,1.05,3082.6],[1,1.01,0.51],[2,1.01,0]],"ltp":0.0,"tv":0.0,"id":41364},{"batb":[[0,3.8,195.76],[1,1.01,0.51],[2,1.01,0]],"ltp":0.0,"tv":0.0,"id":41365}]}]}
{"op":"mcm","clk":"1009930026","pt":1580670741622,"mc":[{"id":"1.168230761","rc":[{"batb":[[0,10.5,80.18],[1,5.6,150.28],[2,1.01,0.51]],"ltp":0.0,"tv":0.0,"id":41365}]}]}
{"op":"mcm","clk":"1009932388","pt":1580670758537,"mc":[{"id":"1.168230761","rc":[{"batb":[[0,1.01,0.51],[1,1.01,0]],"ltp":0.0,"tv":0.0,"id":41364},{"batb":[[0,5.6,150.28],[1,1.01,0.51],[2,1.01,0]],"ltp":0.0,"tv":0.0,"id":41365}]}]}
{"op":"mcm","clk":"1009935983","pt":1580670787571,"mc":[{"id":"1.168230761","rc":[{"batb":[[0,1.15,1190.38],[1,1.05,3078.98],[2,1.01,0.51]],"ltp":0.0,"tv":0.0,"id":41364},{"batb":[[1,3.8,198.44],[2,1.01,0.51]],"ltp":0.0,"tv":0.0,"id":41365}]}]}
{"op":"mcm","clk":"1009938334","pt":1580670805094,"mc":[{"id":"1.168230761","rc":[{"batb":[[0,1.05,3078.98],[1,1.01,0.51],[2,1.01,0]],"ltp":0.0,"tv":0.0,"id":41364},{"batb":[[0,3.8,198.44],[1,1.01,0.51],[2,1.01,0]],"ltp":0.0,"tv":0.0,"id":41365}]}]}
{"op":"mcm","clk":"1009940855","pt":1580670825517,"mc":[{"id":"1.168230761","rc":[{"batb":[[0,10.5,80.41],[1,5.7,150.2],[2,1.01,0.51]],"ltp":0.0,"tv":0.0,"id":41365}]}]}
{"op":"mcm","clk":"1009942644","pt":1580670839862,"mc":[{"id":"1.168230761","rc":[{"batb":[[0,1.01,0.51],[1,1.01,0]],"ltp":0.0,"tv":0.0,"id":41364},{"batb":[[0,5.7,150.2],[1,1.01,0.51],[2,1.01,0]],"ltp":0.0,"tv":0.0,"id":41365}]}]}
{"op":"mcm","clk":"1009945724","pt":1580670864082,"mc":[{"id":"1.168230761","rc":[{"batb":[[0,1.01,0.51],[1,1.01,0]],"ltp":0.0,"tv":0.0,"id":41365}]}]}
{"op":"mcm","clk":"1009945907","pt":1580670865262,"mc":[{"id":"1.168230761","marketDefinition":{"bspMarket":false,"turnInPlayEnabled":true,"persistenceEnabled":true,"marketBaseRate":5.0,"eventId":"29681775","eventTypeId":"2","numberOfWinners":1,"bettingType":"ODDS","marketType":"PLAYER_B_WIN_A_SET","marketTime":"2020-02-02T18:01:00.000Z","suspendTime":"2020-02-02T18:01:00.000Z","bspReconciled":false,"complete":true,"inPlay":true,"crossMatching":true,"runnersVoidable":false,"numberOfActiveRunners":2,"betDelay":3,"status":"SUSPENDED","runners":[{"status":"ACTIVE","sortPriority":1,"id":41364,"name":"Yes"},{"status":"ACTIVE","sortPriority":2,"id":41365,"name":"No"}],"regulators":["MR_INT"],"discountAllowed":true,"timezone":"UTC","openDate":"2020-02-02T18:01:00.000Z","version":3150346726,"name":"Voegele To Win A Set?","eventName":"Brengle v Voegele"}}]}
{"op":"mcm","clk":"1009950071","pt":1580670897570,"mc":[{"id":"1.168230761","marketDefinition":{"bspMarket":false,"turnInPlayEnabled":true,"persistenceEnabled":true,"marketBaseRate":5.0,"eventId":"29681775","eventTypeId":"2","numberOfWinners":1,"bettingType":"ODDS","marketType":"PLAYER_B_WIN_A_SET","marketTime":"2020-02-02T18:01:00.000Z","suspendTime":"2020-02-02T18:01:00.000Z","bspReconciled":false,"complete":true,"inPlay":true,"crossMatching":false,"runnersVoidable":false,"numberOfActiveRunners":0,"betDelay":3,"status":"CLOSED","settledTime":"2020-02-02T19:14:55.000Z","runners":[{"status":"WINNER","sortPriority":1,"id":41364,"name":"Yes"},{"status":"LOSER","sortPriority":2,"id":41365,"name":"No"}],"regulators":["MR_INT"],"discountAllowed":true,"timezone":"UTC","openDate":"2020-02-02T18:01:00.000Z","version":3150347713,"name":"Voegele To Win A Set?","eventName":"Brengle v Voegele"}}]}
