{"op":"mcm","clk":"1001501051","pt":1580587070468,"mc":[{"id":"1.168230758","marketDefinition":{"bspMarket":false,"turnInPlayEnabled":true,"persistenceEnabled":true,"marketBaseRate":5.0,"eventId":"29681775","eventTypeId":"2","numberOfWinners":1,"bettingType":"ODDS","marketType":"SET_WINNER","marketTime":"2020-02-02T18:00:00.000Z","suspendTime":"2020-02-02T18:00:00.000Z","bspReconciled":false,"complete":true,"inPlay":false,"crossMatching":false,"runnersVoidable":false,"numberOfActiveRunners":2,"betDelay":0,"status":"OPEN","runners":[{"status":"ACTIVE","sortPriority":1,"id":2263603,"name":"Madison Brengle"},{"status":"ACTIVE","sortPriority":2,"id":3622149,"name":"Stefanie Voegele"}],"regulators":["MR_INT"],"discountAllowed":false,"timezone":"UTC","openDate":"2020-02-02T18:00:00.000Z","version":3147219547,"name":"Set 2 Winner","eventName":"Brengle v Voegele"}}]}
{"op":"mcm","clk":"1001501273","pt":1580587071655,"mc":[{"id":"1.168230758","marketDefinition":{"bspMarket":false,"turnInPlayEnabled":true,"persistenceEnabled":true,"marketBaseRate":5.0,"eventId":"29681775","eventTypeId":"2","numberOfWinners":1,"bettingType":"ODDS","marketType":"SET_WINNER","marketTime":"2020-02-02T18:00:00.000Z","suspendTime":"2020-02-02T18:00:00.000Z","bspReconciled":false,"complete":true,"inPlay":false,"crossMatching":false,"runnersVoidable":false,"numberOfActiveRunners":2,"betDelay":0,"status":"OPEN","runners":[{"status":"ACTIVE","sortPriority":1,"id":2263603,"name":"Madison Brengle"},{"status":"ACTIVE","sortPriority":2,"id":3622149,"name":"Stefanie Voegele"}],"regulators":["MR_INT"],"discountAllowed":false,"timezone":"UTC","openDate":"2020-02-02T18:00:00.000Z","version":3147219547,"name":"Set 2 Winner","eventName":"Brengle v Voegele"}}]}
{"op":"mcm","clk":"1001501657","pt":1580587073688,"mc":[{"id":"1.168230758","marketDefinition":{"bspMarket":false,"turnInPlayEnabled":true,"persistenceEnabled":true,"marketBaseRate":5.0,"eventId":"29681775","eventTypeId":"2","numberOfWinners":1,"bettingType":"ODDS","marketType":"SET_WINNER","marketTime":"2020-02-02T18:00:00.000Z","suspendTime":"2020-02-02T18:00:00.000Z","bspReconciled":false,"complete":true,"inPlay":false,"crossMatching":false,"runnersVoidable":false,"numberOfActiveRunners":2,"betDelay":0,"status":"OPEN","runners":[{"status":"ACTIVE","sortPriority":1,"id":2263603,"name":"Madison Brengle"},{"status":"ACTIVE","sortPriority":2,"id":3622149,"name":"Stefanie Voegele"}],"regulators":["MR_INT"],"discountAllowed":true,"timezone":"UTC","openDate":"2020-02-02T18:00:00.000Z","version":3147219547,"name":"Set 2 Winner","eventName":"Brengle v Voegele"}}]}
{"op":"mcm","clk":"1001506585","pt":1580587103572,"mc":[{"id":"1.168230758","rc":[{"batb":[[0,1.01,20]],"ltp":0.0,"tv":0.0,"id":2263603},{"batb":[[0,1.01,20]],"ltp":0.0,"tv":0.0,"id":3622149}]}]}
{"op":"mcm","clk":"1003070449","pt":1580602599617,"mc":[{"id":"1.168230758","rc":[{"batb":[[0,1.01,20.51]],"ltp":0.0,"tv":0.0,"id":2263603},{"batb":[[0,1.01,20.51]],"ltp":0.0,"tv":0.0,"id":3622149}]}]}
{"op":"mcm","clk":"1003129839","pt":1580603365593,"mc":[{"id":"1.168230758","rc":[{"batb":[[0,1.01,21.01]],"ltp":0.0,"tv":0.0,"id":2263603},{"batb":[[0,1.01,21.01]],"ltp":0.0,"tv":0.0,"id":3622149}]}]}
{"op":"mcm","clk":"1009515467","pt":1580666510637,"mc":[{"id":"1.168230758","marketDefinition":{"bspMarket":false,"turnInPlayEnabled":true,"persistenceEnabled":true,"marketBaseRate":5.0,"eventId":"29681775","eventTypeId":"2","numberOfWinners":1,"bettingType":"ODDS","marketType":"SET_WINNER","marketTime":"2020-02-02T18:01:00.000Z","suspendTime":"2020-02-02T18:01:00.000Z","bspReconciled":false,"complete":true,"inPlay":false,"crossMatching":false,"runnersVoidable":false,"numberOfActiveRunners":2,"betDelay":0,"status":"OPEN","runners":[{"status":"ACTIVE","sortPriority":1,"id":2263603,"name":"Madison Brengle"},{"status":"ACTIVE","sortPriority":2,"id":3622149,"name":"Stefanie Voegele"}],"regulators":["MR_INT"],"discountAllowed":true,"timezone":"UTC","openDate":"2020-02-02T18:00:00.000Z","version":3150167971,"name":"Set 2 Winner","eventName":"Brengle v Voegele"}}]}
{"op":"mcm","clk":"1009515709","pt":1580666513126,"mc":[{"id":"1.168230758","marketDefinition":{"bspMarket":false,"turnInPlayEnabled":true,"persistenceEnabled":true,"marketBaseRate":5.0,"eventId":"29681775","eventTypeId":"2","numberOfWinners":1,"bettingType":"ODDS","marketType":"SET_WINNER","marketTime":"2020-02-02T18:01:00.000Z","suspendTime":"2020-02-02T18:01:00.000Z","bspReconciled":false,"complete":true,"inPlay":false,"crossMatching":false,"runnersVoidable":false,"numberOfActiveRunners":2,"betDelay":0,"status":"OPEN","runners":[{"status":"ACTIVE","sortPriority":1,"id":2263603,"name":"Madison Brengle"},{"status":"ACTIVE","sortPriority":2,"id":3622149,"name":"Stefanie Voegele"}],"regulators":["MR_INT"],"discountAllowed":true,"timezone":"UTC","openDate":"2020-02-02T18:01:00.000Z","version":3150167971,"name":"Set 2 Winner","eventName":"Brengle v Voegele"}}]}
{"op":"mcm","clk":"1009519906","pt":1580666557406,"mc":[{"id":"1.168230758","rc":[{"batb":[[0,1.91,33.44],[1,1.01,21.01]],"ltp":0.0,"tv":0.0,"id":2263603},{"batb":[[0,1.97,61.06],[1,1.01,21.01]],"ltp":0.0,"tv":0.0,"id":3622149}]}]}
{"op":"mcm","clk":"1009555777","pt":1580666900444,"mc":[{"id":"1.168230758","marketDefinition":{"bspMarket":false,"turnInPlayEnabled":true,"persistenceEnabled":true,"marketBaseRate":5.0,"eventId":"29681775","eventTypeId":"2","numberOfWinners":1,"bettingType":"ODDS","marketType":"SET_WINNER","marketTime":"2020-02-02T18:01:00.000Z","suspendTime":"2020-02-02T18:01:00.000Z","bspReconciled":false,"complete":true,"inPlay":true,"crossMatching":false,"runnersVoidable":false,"numberOfActiveRunners":2,"betDelay":3,"status":"OPEN","runners":[{"status":"ACTIVE","sortPriority":1,"id":2263603,"name":"Madison Brengle"},{"status":"ACTIVE","sortPriority":2,"id":3622149,"name":"Stefanie Voegele"}],"regulators":["MR_INT"],"discountAllowed":true,"timezone":"UTC","openDate":"2020-02-02T18:01:00.000Z","version":3150176493,"name":"Set 2 Winner","eventName":"Brengle v Voegele"},"rc":[{"batb":[[0,1.01,20.51],[1,1.01,0]],"ltp":0.0,"tv":0.0,"id":2263603},{"batb":[[0,1.01,20.51],[1,1.01,0]],"ltp":0.0,"tv":0.0,"id":3622149}]}]}
{"op":"mcm","clk":"1009558525","pt":1580666927252,"mc":[{"id":"1.168230758","rc":[{"batb":[[0,1.96,62.32],[1,1.92,32.97],[2,1.01,20.51]],"ltp":0.0,"tv":0.0,"id":2263603},{"batb":[[0,1.92,32.81],[1,1.89,34.78],[2,1.01,20.51]],"ltp":0.0,"tv":0.0,"id":3622149}]}]}
{"op":"mcm","clk":"1009559496","pt":1580666936249,"mc":[{"id":"1.168230758","rc":[{"batb":[[0,1.92,32.97],[1,1.01,20.51],[2,1.01,0]],"ltp":0.0,"tv":0.0,"id":2263603},{"batb":[[0,1.89,34.78],[1,1.01,20.51],[2,1.01,0]],"ltp":0.0,"tv":0.0,"id":3622149}]}]}
{"op":"mcm","clk":"1009560328","pt":1580666943594,"mc":[{"id":"1.168230758","rc":[{"batb":[[1,1.88,34.93],[2,1.01,20.51]],"ltp":0.0,"tv":0.0,"id":2263603},{"batb":[[0,1.96,61.92],[1,1.92,32.81],[2,1.01,20.51]],"ltp":0.0,"tv":0.0,"id":3622149}]}]}
{"op":"mcm","clk":"1009561285","pt":1580666951476,"mc":[{"id":"1.168230758","rc":[{"batb":[[0,1.88,34.93],[1,1.01,20.51],[2,1.01,0]],"ltp":0.0,"tv":0.0,"id":2263603},{"batb":[[0,1.92,32.81],[1,1.01,20.51],[2,1.01,0]],"ltp":0.0,"tv":0.0,"id":3622149}]}]}
{"op":"mcm","clk":"1009561625","pt":1580666954487,"mc":[{"id":"1.168230758","rc":[{"batb":[[0,1.89,34.78]],"ltp":0.0,"tv":0.0,"id":2263603}]}]}
{"op":"mcm","clk":"1009563710","pt":1580666975617,"mc":[{"id":"1.168230758","rc":[{"batb":[[1,1.85,37.06],[2,1.01,20.51]],"ltp":0.0,"tv":0.0,"id":2263603},{"batb":[[0,2,58.7],[1,1.95,62.95],[2,1.93,849.36]],"ltp":0.0,"tv":0.0,"id":3622149}]}]}
{"op":"mcm","clk":"1009563764","pt":1580666976101,"mc":[{"id":"1.168230758","rc":[{"batb":[[2,1.01,20.51]],"ltp":0.0,"tv":0.0,"id":3622149}]}]}
{"op":"mcm","clk":"1009564665","pt":1580666986035,"mc":[{"id":"1.168230758","rc":[{"batb":[[0,1.85,37.06],[1,1.01,20.51],[2,1.01,0]],"ltp":0.0,"tv":0.0,"id":2263603},{"batb":[[0,1.95,62.95],[1,1.01,20.51],[2,1.01,0]],"ltp":0.0,"tv":0.0,"id":3622149}]}]}
{"op":"mcm","clk":"1009565762","pt":1580666997152,"mc":[{"id":"1.168230758","rc":[{"batb":[[0,1.93,32.42],[1,1.89,34.62],[2,1.01,20.51]],"ltp":0.0,"tv":0.0,"id":2263603},{"batb":[[1,1.91,33.75],[2,1.01,20.51]],"ltp":0.0,"tv":0.0,"id":3622149}]}]}
{"op":"mcm","clk":"1009566540","pt":1580667004644,"mc":[{"id":"1.168230758","rc":[{"batb":[[0,1.89,34.62],[1,1.01,20.51],[2,1.01,0]],"ltp":0.0,"tv":0.0,"id":2263603},{"batb":[[0,1.91,33.75],[1,1.01,20.51],[2,1.01,0]],"ltp":0.0,"tv":0.0,"id":3622149}]}]}
{"op":"mcm","clk":"1009570693","pt":1580667045564,"mc":[{"id":"1.168230758","rc":[{"batb":[[1,1.85,37.3],[2,1.01,20.51]],"ltp":0.0,"tv":0.0,"id":2263603},{"batb":[[0,1.99,58.93],[1,1.94,31.71],[2,1.92,134.19]],"ltp":0.0,"tv":0.0,"id":3622149}]}]}
{"op":"mcm","clk":"1009570787","pt":1580667046464,"mc":[{"id":"1.168230758","rc":[{"batb":[[2,1.01,20.51]],"ltp":0.0,"tv":0.0,"id":3622149}]}]}
{"op":"mcm","clk":"1009572072","pt":1580667059570,"mc":[{"id":"1.168230758","rc":[{"batb":[[0,1.85,37.3],[1,1.01,20.51],[2,1.01,0]],"ltp":0.0,"tv":0.0,"id":2263603},{"batb":[[0,1.94,31.71],[1,1.01,20.51],[2,1.01,0]],"ltp":0.0,"tv":0.0,"id":3622149}]}]}
{"op":"mcm","clk":"1009572364","pt":1580667062451,"mc":[{"id":"1.168230758","rc":[{"batb":[[0,1.95,31.71]],"ltp":0.0,"tv":0.0,"id":3622149}]}]}
{"op":"mcm","clk":"1009574087","pt":1580667081603,"mc":[{"id":"1.168230758","rc":[{"batb":[[1,1.81,39.5],[2,1.01,20.51]],"ltp":0.0,"tv":0.0,"id":2263603},{"batb":[[0,2.04,54.53],[1,2,58.3],[2,1.98,114.76]],"ltp":0.0,"tv":0.0,"id":3622149}]}]}
{"op":"mcm","clk":"1009574175","pt":1580667082595,"mc":[{"id":"1.168230758","rc":[{"batb":[[2,1.01,20.51]],"ltp":0.0,"tv":0.0,"id":3622149}]}]}
{"op":"mcm","clk":"1009575658","pt":1580667097615,"mc":[{"id":"1.168230758","rc":[{"batb":[[1,1.84,37.77],[2,1.81,39.5]],"ltp":0.0,"tv":0.0,"id":2263603}]}]}
{"op":"mcm","clk":"1009575704","pt":1580667098029,"mc":[{"id":"1.168230758","rc":[{"batb":[[0,1.84,37.77],[1,1.81,39.5],[2,1.01,20.51]],"ltp":0.0,"tv":0.0,"id":2263603},{"batb":[[0,2.04,53.82],[1,2,57.6]],"ltp":0.0,"tv":0.0,"id":3622149}]}]}
{"op":"mcm","clk":"1009578430","pt":1580667127548,"mc":[{"id":"1.168230758","rc":[{"batb":[[0,1.81,39.5],[1,1.01,20.51],[2,1.01,0]],"ltp":0.0,"tv":0.0,"id":2263603},{"batb":[[0,2,57.6],[1,1.01,20.51],[2,1.01,0]],"ltp":0.0,"tv":0.0,"id":3622149}]}]}
{"op":"mcm","clk":"1009579746","pt":1580667141600,"mc":[{"id":"1.168230758","rc":[{"batb":[[0,1.88,35.41],[1,1.84,38],[2,1.01,20.51]],"ltp":0.0,"tv":0.0,"id":2263603},{"batb":[[1,1.97,60.9],[2,1.01,20.51]],"ltp":0.0,"tv":0.0,"id":3622149}]}]}
{"op":"mcm","clk":"1009581121","pt":1580667155180,"mc":[{"id":"1.168230758","rc":[{"batb":[[0,1.84,38],[1,1.01,20.51],[2,1.01,0]],"ltp":0.0,"tv":0.0,"id":2263603},{"batb":[[0,1.97,60.9],[1,1.01,20.51],[2,1.01,0]],"ltp":0.0,"tv":0.0,"id":3622149}]}]}
{"op":"mcm","clk":"1009581474","pt":1580667158498,"mc":[{"id":"1.168230758","rc":[{"batb":[[0,1.84,37.45]],"ltp":0.0,"tv":0.0,"id":2263603},{"batb":[[0,1.96,61.84]],"ltp":0.0,"tv":0.0,"id":3622149}]}]}
{"op":"mcm","clk":"1009582307","pt":1580667166586,"mc":[{"id":"1.168230758","rc":[{"batb":[[0,1.92,33.05],[1,1.88,35.09],[2,1.01,20.51]],"ltp":0.0,"tv":0.0,"id":2263603},{"batb":[[1,1.93,32.42],[2,1.01,20.51]],"ltp":0.0,"tv":0.0,"id":3622149}]}]}
{"op":"mcm","clk":"1009582695","pt":1580667170211,"mc":[{"id":"1.168230758","marketDefinition":{"bspMarket":false,"turnInPlayEnabled":true,"persistenceEnabled":true,"marketBaseRate":5.0,"eventId":"29681775","eventTypeId":"2","numberOfWinners":1,"bettingType":"ODDS","marketType":"SET_WINNER","marketTime":"2020-02-02T18:01:00.000Z","suspendTime":"2020-02-02T18:01:00.000Z","bspReconciled":false,"complete":true,"inPlay":true,"crossMatching":true,"runnersVoidable":false,"numberOfActiveRunners":2,"betDelay":3,"status":"OPEN","runners":[{"status":"ACTIVE","sortPriority":1,"id":2263603,"name":"Madison Brengle"},{"status":"ACTIVE","sortPriority":2,"id":3622149,"name":"Stefanie Voegele"}],"regulators":["MR_INT"],"discountAllowed":true,"timezone":"UTC","openDate":"2020-02-02T18:01:00.000Z","version":3150176493,"name":"Set 2 Winner","eventName":"Brengle v Voegele"}}]}
{"op":"mcm","clk":"1009583531","pt":1580667177618,"mc":[{"id":"1.168230758","rc":[{"batb":[[0,1.88,35.09],[1,1.01,20.51],[2,1.01,0]],"ltp":0.0,"tv":0.0,"id":2263603},{"batb":[[0,1.93,32.42],[1,1.01,20.51],[2,1.01,0]],"ltp":0.0,"tv":0.0,"id":3622149}]}]}
{"op":"mcm","clk":"1009586425","pt":1580667204649,"mc":[{"id":"1.168230758","rc":[{"batb":[[1,1.84,37.69],[2,1.01,20.51]],"ltp":0.0,"tv":0.0,"id":2263603},{"batb":[[0,2,58.15],[1,1.96,61.84],[2,1.93,32.42]],"ltp":0.0,"tv":0.0,"id":3622149}]}]}
{"op":"mcm","clk":"1009586458","pt":1580667204930,"mc":[{"id":"1.168230758","rc":[{"batb":[[2,1.01,20.51]],"ltp":0.0,"tv":0.0,"id":3622149}]}]}
{"op":"mcm","clk":"1009587834","pt":1580667217541,"mc":[{"id":"1.168230758","rc":[{"batb":[[0,1.84,37.69],[1,1.01,20.51],[2,1.01,0]],"ltp":0.0,"tv":0.0,"id":2263603},{"batb":[[0,1.96,61.84],[1,1.01,20.51],[2,1.01,0]],"ltp":0.0,"tv":0.0,"id":3622149}]}]}
{"op":"mcm","clk":"1009590708","pt":1580667243870,"mc":[{"id":"1.168230758","rc":[{"batl":[[0,2.52,270.1]],"ltp":0.0,"tv":0.0,"id":2263603},{"batl":[[0,2.7,245.56]],"ltp":0.0,"tv":0.0,"id":3622149}]}]}
{"op":"mcm","clk":"1009591501","pt":1580667251578,"mc":[{"id":"1.168230758","rc":[{"batb":[[1,1.8,40.84],[2,1.01,20.51]],"ltp":0.0,"tv":0.0,"id":2263603},{"batb":[[0,2.04,54.05],[1,2,57.52],[2,1.01,20.51]],"ltp":0.0,"tv":0.0,"id":3622149}]}]}
{"op":"mcm","clk":"1009593251","pt":1580667267609,"mc":[{"id":"1.168230758","rc":[{"batb":[[0,1.8,40.84],[1,1.01,20.51],[2,1.01,0]],"ltp":0.0,"tv":0.0,"id":2263603},{"batb":[[0,2,57.52],[1,1.01,20.51],[2,1.01,0]],"ltp":0.0,"tv":0.0,"id":3622149}]}]}
{"op":"mcm","clk":"1009595096","pt":1580667284492,"mc":[{"id":"1.168230758","rc":[{"batb":[[1,1.75,44.22],[2,1.01,20.51]],"ltp":0.0,"tv":0.0,"id":2263603},{"batb":[[0,2.1,49.73],[1,2.04,53.82],[2,1.01,20.51]],"ltp":0.0,"tv":0.0,"id":3622149}]}]}
{"op":"mcm","clk":"1009595251","pt":1580667285928,"mc":[{"id":"1.168230758","rc":[{"batl":[[0,2.4,289.78]],"ltp":0.0,"tv":0.0,"id":2263603}]}]}
{"op":"mcm","clk":"1009596085","pt":1580667293597,"mc":[{"id":"1.168230758","rc":[{"batb":[[0,1.75,44.22],[1,1.01,20.51],[2,1.01,0]],"ltp":0.0,"tv":0.0,"id":2263603},{"batb":[[0,2.04,53.82],[1,1.01,20.51],[2,1.01,0]],"ltp":0.0,"tv":0.0,"id":3622149}]}]}
{"op":"mcm","clk":"1009598152","pt":1580667313343,"mc":[{"id":"1.168230758","rc":[{"batb":[[1,1.73,46.42],[2,1.01,20.51]],"ltp":0.0,"tv":0.0,"id":2263603},{"batb":[[0,2.16,45.64],[1,2.12,48.78],[2,1.01,20.51]],"ltp":0.0,"tv":0.0,"id":3622149}]}]}
{"op":"mcm","clk":"1009598505","pt":1580667316529,"mc":[{"id":"1.168230758","rc":[{"batl":[[0,2.84,95.93]],"ltp":0.0,"tv":0.0,"id":3622149}]}]}
{"op":"mcm","clk":"1009600630","pt":1580667336464,"mc":[{"id":"1.168230758","rc":[{"batb":[[0,1.73,46.42],[1,1.01,20.51],[2,1.01,0]],"ltp":0.0,"tv":0.0,"id":2263603},{"batb":[[0,2.12,48.78],[1,1.01,20.51],[2,1.01,0]],"ltp":0.0,"tv":0.0,"id":3622149}]}]}
{"op":"mcm","clk":"1009600919","pt":1580667339565,"mc":[{"id":"1.168230758","rc":[{"batb":[[1,1.72,47.21],[2,1.01,20.51]],"ltp":0.0,"tv":0.0,"id":2263603},{"batb":[[0,2.14,47.92],[1,2.12,48.78],[2,1.01,20.51]],"ltp":0.0,"tv":0.0,"id":3622149}]}]}
{"op":"mcm","clk":"1009601018","pt":1580667340570,"mc":[{"id":"1.168230758","rc":[{"batb":[[0,1.72,47.21],[1,1.01,20.51],[2,1.01,0]],"ltp":0.0,"tv":0.0,"id":2263603},{"batb":[[1,1.01,20.51],[2,1.01,0]],"ltp":0.0,"tv":0.0,"id":3622149}]}]}
{"op":"mcm","clk":"1009604334","pt":1580667375289,"mc":[{"id":"1.168230758","rc":[{"batb":[[1,1.69,50.44],[2,1.01,20.51]],"ltp":0.0,"tv":0.0,"id":2263603},{"batb":[[0,2.22,42.41],[1,2.16,45.71],[2,1.01,20.51]],"ltp":0.0,"tv":0.0,"id":3622149}]}]}
{"op":"mcm","clk":"1009604447","pt":1580667376424,"mc":[{"id":"1.168230758","rc":[{"batl":[[0,2.3,474.5]],"ltp":0.0,"tv":0.0,"id":2263603}]}]}
{"op":"mcm","clk":"1009604621","pt":1580667378419,"mc":[{"id":"1.168230758","rc":[{"batb":[[1,2.18,71.58],[2,2.16,45.71]],"ltp":0.0,"tv":0.0,"id":3622149}]}]}
{"op":"mcm","clk":"1009605836","pt":1580667390590,"mc":[{"id":"1.168230758","rc":[{"batb":[[0,1.69,50.44],[1,1.01,20.51],[2,1.01,0]],"ltp":0.0,"tv":0.0,"id":2263603},{"batb":[[0,2.16,45.71],[1,1.01,20.51],[2,2.16,0]],"ltp":0.0,"tv":0.0,"id":3622149}]}]}
{"op":"mcm","clk":"1009606136","pt":1580667393647,"mc":[{"id":"1.168230758","rc":[{"batb":[[0,1.68,51.38]],"ltp":0.0,"tv":0.0,"id":2263603},{"batb":[[0,2.18,44.77]],"ltp":0.0,"tv":0.0,"id":3622149}]}]}
{"op":"mcm","clk":"1009607746","pt":1580667411446,"mc":[{"id":"1.168230758","rc":[{"batb":[[0,1.65,54.61]],"ltp":0.0,"tv":0.0,"id":2263603},{"batb":[[0,2.3,38.71],[1,2.24,41.86],[2,2.18,867.36]],"ltp":0.0,"tv":0.0,"id":3622149}]}]}
{"op":"mcm","clk":"1009607772","pt":1580667411761,"mc":[{"id":"1.168230758","rc":[{"batb":[[0,2.24,41.86],[1,2.18,867.36],[2,1.01,20.51]],"ltp":0.0,"tv":0.0,"id":3622149}]}]}
{"op":"mcm","clk":"1009608835","pt":1580667423471,"mc":[{"id":"1.168230758","rc":[{"batb":[[1,1.01,20.51],[2,1.01,0]],"ltp":0.0,"tv":0.0,"id":3622149}]}]}
{"op":"mcm","clk":"1009611072","pt":1580667448989,"mc":[{"id":"1.168230758","rc":[{"batb":[[1,1.62,57.6],[2,1.01,20.51]],"ltp":0.0,"tv":0.0,"id":2263603},{"batb":[[0,2.36,36.12],[1,2.28,39.18],[2,1.01,20.51]],"ltp":0.0,"tv":0.0,"id":3622149}]}]}
{"op":"mcm","clk":"1009611283","pt":1580667451292,"mc":[{"id":"1.168230758","rc":[{"batl":[[0,3.15,86.63]],"ltp":0.0,"tv":0.0,"id":3622149}]}]}
{"op":"mcm","clk":"1009612174","pt":1580667460629,"mc":[{"id":"1.168230758","rc":[{"batb":[[0,1.62,57.44],[1,1.01,20.51],[2,1.01,0]],"ltp":0.0,"tv":0.0,"id":2263603},{"batb":[[0,2.28,39.18],[1,1.01,20.51],[2,1.01,0]],"ltp":0.0,"tv":0.0,"id":3622149}]}]}
{"op":"mcm","clk":"1009613024","pt":1580667469643,"mc":[{"id":"1.168230758","rc":[{"batb":[[0,1.69,50.36],[1,1.66,52.64],[2,1.01,20.51]],"ltp":0.0,"tv":0.0,"id":2263603},{"batb":[[1,2.22,42.8],[2,1.01,20.51]],"ltp":0.0,"tv":0.0,"id":3622149}]}]}
{"op":"mcm","clk":"1009613179","pt":1580667471427,"mc":[{"id":"1.168230758","rc":[{"batl":[[0,3,94.09]],"ltp":0.0,"tv":0.0,"id":3622149}]}]}
{"op":"mcm","clk":"1009613639","pt":1580667477347,"mc":[{"id":"1.168230758","rc":[{"batb":[[0,1.66,52.64],[1,1.01,20.51],[2,1.01,0]],"ltp":0.0,"tv":0.0,"id":2263603},{"batb":[[0,2.22,42.8],[1,1.01,20.51],[2,1.01,0]],"ltp":0.0,"tv":0.0,"id":3622149}]}]}
{"op":"mcm","clk":"1009615246","pt":1580667495649,"mc":[{"id":"1.168230758","rc":[{"batb":[[1,1.63,57.2],[2,1.01,20.51]],"ltp":0.0,"tv":0.0,"id":2263603},{"batb":[[0,2.32,37.61],[1,2.28,39.81],[2,2.22,42.8]],"ltp":0.0,"tv":0.0,"id":3622149}]}]}
{"op":"mcm","clk":"1009615314","pt":1580667496343,"mc":[{"id":"1.168230758","rc":[{"batb":[[2,1.01,20.51]],"ltp":0.0,"tv":0.0,"id":3622149}]}]}
{"op":"mcm","clk":"1009622910","pt":1580667578574,"mc":[{"id":"1.168230758","rc":[{"batb":[[0,1.63,57.2],[1,1.01,20.51],[2,1.01,0]],"ltp":0.0,"tv":0.0,"id":2263603},{"batb":[[0,2.28,39.81],[1,1.01,20.51],[2,1.01,0]],"ltp":0.0,"tv":0.0,"id":3622149}]}]}
{"op":"mcm","clk":"1009623964","pt":1580667591988,"mc":[{"id":"1.168230758","rc":[{"batb":[[1,1.59,61.69],[2,1.01,20.51]],"ltp":0.0,"tv":0.0,"id":2263603},{"batb":[[0,2.4,34.23],[1,2.32,37.3],[2,1.01,20.51]],"ltp":0.0,"tv":0.0,"id":3622149}]}]}
{"op":"mcm","clk":"1009624026","pt":1580667592782,"mc":[{"id":"1.168230758","rc":[{"batl":[[0,2.16,499.75]],"ltp":0.0,"tv":0.0,"id":2263603}]}]}
{"op":"mcm","clk":"1009625073","pt":1580667606567,"mc":[{"id":"1.168230758","rc":[{"batb":[[0,1.59,61.69],[1,1.01,20.51],[2,1.01,0]],"ltp":0.0,"tv":0.0,"id":2263603},{"batb":[[0,2.32,37.3],[1,1.01,20.51],[2,1.01,0]],"ltp":0.0,"tv":0.0,"id":3622149}]}]}
{"op":"mcm","clk":"1009626896","pt":1580667628213,"mc":[{"id":"1.168230758","rc":[{"batl":[[0,3.45,79.05]],"ltp":0.0,"tv":0.0,"id":3622149}]}]}
{"op":"mcm","clk":"1009628458","pt":1580667647439,"mc":[{"id":"1.168230758","rc":[{"batb":[[0,1.66,53.03],[1,1.63,57.28],[2,1.59,61.69]],"ltp":0.0,"tv":0.0,"id":2263603},{"batb":[[1,2.26,40.13],[2,1.01,20.51]],"ltp":0.0,"tv":0.0,"id":3622149}]}]}
{"op":"mcm","clk":"1009628524","pt":1580667648322,"mc":[{"id":"1.168230758","rc":[{"batb":[[2,1.59,1338.11]],"ltp":0.0,"tv":0.0,"id":2263603}]}]}
{"op":"mcm","clk":"1009629358","pt":1580667657630,"mc":[{"id":"1.168230758","rc":[{"batb":[[0,1.63,57.28],[1,1.01,20.51],[2,1.59,0]],"ltp":0.0,"tv":0.0,"id":2263603},{"batb":[[0,2.26,40.13],[1,1.01,20.51],[2,1.01,0]],"ltp":0.0,"tv":0.0,"id":3622149}]}]}
{"op":"mcm","clk":"1009631568","pt":1580667682449,"mc":[{"id":"1.168230758","rc":[{"batb":[[1,1.59,61.77],[2,1.01,20.51]],"ltp":0.0,"tv":0.0,"id":2263603},{"batb":[[0,2.4,34.23],[1,2.34,89.2],[2,1.01,20.51]],"ltp":0.0,"tv":0.0,"id":3622149}]}]}
{"op":"mcm","clk":"1009633371","pt":1580667701410,"mc":[{"id":"1.168230758","rc":[{"batb":[[0,1.59,61.77],[1,1.01,20.51],[2,1.01,0]],"ltp":0.0,"tv":0.0,"id":2263603},{"batb":[[0,2.34,36.98],[1,1.01,20.51],[2,1.01,0]],"ltp":0.0,"tv":0.0,"id":3622149}]}]}
{"op":"mcm","clk":"1009636988","pt":1580667745447,"mc":[{"id":"1.168230758","rc":[{"batb":[[1,1.56,66.8],[2,1.01,20.51]],"ltp":0.0,"tv":0.0,"id":2263603},{"batb":[[0,2.48,31.39],[1,2.4,34.31],[2,2.36,108.93]],"ltp":0.0,"tv":0.0,"id":3622149}]}]}
{"op":"mcm","clk":"1009637091","pt":1580667746649,"mc":[{"id":"1.168230758","rc":[{"batl":[[0,2.04,551.4]],"ltp":0.0,"tv":0.0,"id":2263603}]}]}
{"op":"mcm","clk":"1009638449","pt":1580667762641,"mc":[{"id":"1.168230758","rc":[{"batb":[[0,1.56,66.33],[1,1.01,20.51],[2,1.01,0]],"ltp":0.0,"tv":0.0,"id":2263603},{"batb":[[0,2.4,34.31],[1,1.01,20.51],[2,2.36,0]],"ltp":0.0,"tv":0.0,"id":3622149}]}]}
{"op":"mcm","clk":"1009639911","pt":1580667779557,"mc":[{"id":"1.168230758","rc":[{"batb":[[0,1.63,56.65],[1,1.59,62.08],[2,1.01,20.51]],"ltp":0.0,"tv":0.0,"id":2263603},{"batb":[[1,2.32,38.08],[2,1.01,20.51]],"ltp":0.0,"tv":0.0,"id":3622149}]}]}
{"op":"mcm","clk":"1009641208","pt":1580667794495,"mc":[{"id":"1.168230758","rc":[{"batb":[[0,1.59,62.08],[1,1.01,20.51],[2,1.01,0]],"ltp":0.0,"tv":0.0,"id":2263603},{"batb":[[0,2.32,38.08],[1,1.01,20.51],[2,1.01,0]],"ltp":0.0,"tv":0.0,"id":3622149}]}]}
{"op":"mcm","clk":"1009641541","pt":1580667798468,"mc":[{"id":"1.168230758","rc":[{"batb":[[0,1.59,61.77]],"ltp":0.0,"tv":0.0,"id":2263603},{"batb":[[0,2.3,38.32]],"ltp":0.0,"tv":0.0,"id":3622149}]}]}
{"op":"mcm","clk":"1009641716","pt":1580667800254,"mc":[{"id":"1.168230758","rc":[{"batl":[[0,2.1,129.77]],"ltp":0.0,"tv":0.0,"id":2263603},{"batl":[[0,3.45,38.58]],"ltp":0.0,"tv":0.0,"id":3622149}]}]}
{"op":"mcm","clk":"1009643483","pt":1580667820609,"mc":[{"id":"1.168230758","rc":[{"batb":[[0,1.68,51.54],[1,1.63,56.41],[2,1.01,20.51]],"ltp":0.0,"tv":0.0,"id":2263603},{"batb":[[1,2.24,41.31],[2,1.01,20.51]],"ltp":0.0,"tv":0.0,"id":3622149}]}]}
{"op":"mcm","clk":"1009644698","pt":1580667832617,"mc":[{"id":"1.168230758","rc":[{"batb":[[0,1.63,56.41],[1,1.01,20.51],[2,1.01,0]],"ltp":0.0,"tv":0.0,"id":2263603},{"batb":[[0,2.24,41.31],[1,1.01,20.51],[2,1.01,0]],"ltp":0.0,"tv":0.0,"id":3622149}]}]}
{"op":"mcm","clk":"1009644969","pt":1580667835621,"mc":[{"id":"1.168230758","rc":[{"batb":[[0,1.62,57.6]],"ltp":0.0,"tv":0.0,"id":2263603},{"batb":[[0,2.26,40.29]],"ltp":0.0,"tv":0.0,"id":3622149}]}]}
{"op":"mcm","clk":"1009645509","pt":1580667841490,"mc":[{"id":"1.168230758","rc":[{"batb":[[0,1.7,49.49],[1,1.66,53.03],[2,1.01,20.51]],"ltp":0.0,"tv":0.0,"id":2263603},{"batb":[[1,2.2,43.51],[2,1.01,20.51]],"ltp":0.0,"tv":0.0,"id":3622149}]}]}
{"op":"mcm","clk":"1009645617","pt":1580667842534,"mc":[{"id":"1.168230758","rc":[{"batl":[[0,3.3,80.08]],"ltp":0.0,"tv":0.0,"id":3622149}]}]}
{"op":"mcm","clk":"1009646534","pt":1580667853633,"mc":[{"id":"1.168230758","rc":[{"batb":[[0,1.66,52.8],[1,1.01,20.51],[2,1.01,0]],"ltp":0.0,"tv":0.0,"id":2263603},{"batb":[[0,2.2,43.51],[1,1.01,20.51],[2,1.01,0]],"ltp":0.0,"tv":0.0,"id":3622149}]}]}
{"op":"mcm","clk":"1009648037","pt":1580667870511,"mc":[{"id":"1.168230758","rc":[{"batb":[[0,1.73,45.95],[1,1.7,48.78],[2,1.68,19.36]],"ltp":0.0,"tv":0.0,"id":2263603},{"batb":[[1,2.12,48.15],[2,1.01,20.51]],"ltp":0.0,"tv":0.0,"id":3622149}]}]}
{"op":"mcm","clk":"1009649980","pt":1580667895645,"mc":[{"id":"1.168230758","rc":[{"batb":[[0,1.7,48.63],[1,1.01,20.51],[2,1.68,0]],"ltp":0.0,"tv":0.0,"id":2263603},{"batb":[[0,2.12,48.15],[1,1.01,20.51],[2,1.01,0]],"ltp":0.0,"tv":0.0,"id":3622149}]}]}
{"op":"mcm","clk":"1009651912","pt":1580667921596,"mc":[{"id":"1.168230758","rc":[{"batl":[[0,2.3,470.85]],"ltp":0.0,"tv":0.0,"id":2263603},{"batl":[[0,3,89.65]],"ltp":0.0,"tv":0.0,"id":3622149}]}]}
{"op":"mcm","clk":"1009652254","pt":1580667926070,"mc":[{"id":"1.168230758","rc":[{"batb":[[1,1.67,52.24],[2,1.01,20.51]],"ltp":0.0,"tv":0.0,"id":2263603},{"batb":[[0,2.26,40.84],[1,2.18,45.01],[2,1.01,20.51]],"ltp":0.0,"tv":0.0,"id":3622149}]}]}
{"op":"mcm","clk":"1009653065","pt":1580667937567,"mc":[{"id":"1.168230758","rc":[{"batb":[[0,1.67,52.24],[1,1.01,20.51],[2,1.01,0]],"ltp":0.0,"tv":0.0,"id":2263603},{"batb":[[0,2.18,45.01],[1,1.01,20.51],[2,1.01,0]],"ltp":0.0,"tv":0.0,"id":3622149}]}]}
{"op":"mcm","clk":"1009653298","pt":1580667940593,"mc":[{"id":"1.168230758","rc":[{"batb":[[1,1.66,52.87],[2,1.01,20.51]],"ltp":0.0,"tv":0.0,"id":2263603}]}]}
{"op":"mcm","clk":"1009653368","pt":1580667941277,"mc":[{"id":"1.168230758","rc":[{"batb":[[0,1.66,52.87],[1,1.01,20.51],[2,1.01,0]],"ltp":0.0,"tv":0.0,"id":2263603},{"batb":[[0,2.18,44.38]],"ltp":0.0,"tv":0.0,"id":3622149}]}]}
{"op":"mcm","clk":"1009655142","pt":1580667963605,"mc":[{"id":"1.168230758","rc":[{"batb":[[1,1.63,56.26],[2,1.01,20.51]],"ltp":0.0,"tv":0.0,"id":2263603},{"batb":[[0,2.34,37.14],[1,2.24,41.23],[2,2.18,44.38]],"ltp":0.0,"tv":0.0,"id":3622149}]}]}
{"op":"mcm","clk":"1009655158","pt":1580667963808,"mc":[{"id":"1.168230758","rc":[{"batb":[[2,1.01,20.51]],"ltp":0.0,"tv":0.0,"id":3622149}]}]}
{"op":"mcm","clk":"1009656115","pt":1580667975526,"mc":[{"id":"1.168230758","rc":[{"batb":[[0,1.63,56.26],[1,1.01,20.51],[2,1.01,0]],"ltp":0.0,"tv":0.0,"id":2263603},{"batb":[[0,2.24,41.23],[1,1.01,20.51],[2,1.01,0]],"ltp":0.0,"tv":0.0,"id":3622149}]}]}
{"op":"mcm","clk":"1009657516","pt":1580667994349,"mc":[{"id":"1.168230758","rc":[{"batb":[[1,1.61,59.72],[2,1.01,20.51]],"ltp":0.0,"tv":0.0,"id":2263603},{"batb":[[0,2.38,34.93],[1,2.32,55.64],[2,2.3,38.24]],"ltp":0.0,"tv":0.0,"id":3622149}]}]}
{"op":"mcm","clk":"1009657694","pt":1580667996557,"mc":[{"id":"1.168230758","rc":[{"batl":[[0,2.16,499.75]],"ltp":0.0,"tv":0.0,"id":2263603}]}]}
{"op":"mcm","clk":"1009658372","pt":1580668004644,"mc":[{"id":"1.168230758","rc":[{"batb":[[0,1.61,59.72],[1,1.01,20.51],[2,1.01,0]],"ltp":0.0,"tv":0.0,"id":2263603},{"batb":[[0,2.3,38.24],[1,1.01,20.51],[2,2.3,0]],"ltp":0.0,"tv":0.0,"id":3622149}]}]}
{"op":"mcm","clk":"1009659584","pt":1580668019542,"mc":[{"id":"1.168230758","rc":[{"batb":[[1,1.57,64.6],[2,1.01,20.51]],"ltp":0.0,"tv":0.0,"id":2263603},{"batb":[[0,2.44,32.57],[1,2.38,35.25],[2,2.34,109.72]],"ltp":0.0,"tv":0.0,"id":3622149}]}]}
{"op":"mcm","clk":"1009660198","pt":1580668027376,"mc":[{"id":"1.168230758","rc":[{"batb":[[0,1.61,58.85],[1,1.58,63.65]],"ltp":0.0,"tv":0.0,"id":2263603},{"batb":[[1,2.36,35.88]],"ltp":0.0,"tv":0.0,"id":3622149}]}]}
{"op":"mcm","clk":"1009661436","pt":1580668042194,"mc":[{"id":"1.168230758","rc":[{"batb":[[0,1.58,63.65],[1,1.01,20.51],[2,1.01,0]],"ltp":0.0,"tv":0.0,"id":2263603},{"batb":[[0,2.36,35.88],[1,2.34,109.72],[2,1.01,20.51]],"ltp":0.0,"tv":0.0,"id":3622149}]}]}
{"op":"mcm","clk":"1009666497","pt":1580668109555,"mc":[{"id":"1.168230758","rc":[{"batb":[[1,1.01,20.51],[2,1.01,0]],"ltp":0.0,"tv":0.0,"id":3622149}]}]}
{"op":"mcm","clk":"1009666575","pt":1580668110378,"mc":[{"id":"1.168230758","rc":[{"batb":[[0,1.01,20.51],[1,1.01,0]],"ltp":0.0,"tv":0.0,"id":2263603},{"batb":[[0,1.01,20.51],[1,1.01,0]],"ltp":0.0,"tv":0.0,"id":3622149}]}]}
{"op":"mcm","clk":"1009668048","pt":1580668126487,"mc":[{"id":"1.168230758","rc":[{"batb":[[0,1.58,63.65],[1,1.54,69.32],[2,1.01,20.51]],"ltp":0.0,"tv":0.0,"id":2263603},{"batb":[[0,2.52,30.29],[1,2.44,32.81],[2,1.01,20.51]],"ltp":0.0,"tv":0.0,"id":3622149}]}]}
{"op":"mcm","clk":"1009668274","pt":1580668129273,"mc":[{"id":"1.168230758","rc":[{"batl":[[0,3.45,83.64]],"ltp":0.0,"tv":0.0,"id":3622149}]}]}
{"op":"mcm","clk":"1009668861","pt":1580668136288,"mc":[{"id":"1.168230758","rc":[{"batb":[[0,1.54,69.32],[1,1.01,20.51],[2,1.01,0]],"ltp":0.0,"tv":0.0,"id":2263603},{"batb":[[0,2.44,32.81],[1,1.01,20.51],[2,1.01,0]],"ltp":0.0,"tv":0.0,"id":3622149}]}]}
{"op":"mcm","clk":"1009671744","pt":1580668173540,"mc":[{"id":"1.168230758","rc":[{"batb":[[0,1.61,59.4],[1,1.57,64.44],[2,1.01,20.51]],"ltp":0.0,"tv":0.0,"id":2263603},{"batb":[[1,2.36,35.72],[2,1.01,20.51]],"ltp":0.0,"tv":0.0,"id":3622149}]}]}
{"op":"mcm","clk":"1009671825","pt":1580668174736,"mc":[{"id":"1.168230758","rc":[{"batl":[[0,3.3,89.78]],"ltp":0.0,"tv":0.0,"id":3622149}]}]}
{"op":"mcm","clk":"1009672870","pt":1580668187729,"mc":[{"id":"1.168230758","rc":[{"batb":[[2,2.34,109.72]],"ltp":0.0,"tv":0.0,"id":3622149}]}]}
{"op":"mcm","clk":"1009673010","pt":1580668189539,"mc":[{"id":"1.168230758","rc":[{"batb":[[0,1.57,64.44],[1,1.01,20.51],[2,1.01,0]],"ltp":0.0,"tv":0.0,"id":2263603},{"batb":[[0,2.36,35.72],[1,1.01,20.51],[2,2.34,0]],"ltp":0.0,"tv":0.0,"id":3622149}]}]}
{"op":"mcm","clk":"1009673723","pt":1580668198484,"mc":[{"id":"1.168230758","rc":[{"batb":[[0,1.64,55.16],[1,1.6,60.11],[2,1.01,20.51]],"ltp":0.0,"tv":0.0,"id":2263603},{"batb":[[1,2.3,38.55],[2,1.01,20.51]],"ltp":0.0,"tv":0.0,"id":3622149}]}]}
{"op":"mcm","clk":"1009675034","pt":1580668213371,"mc":[{"id":"1.168230758","rc":[{"batb":[[0,1.6,60.11],[1,1.01,20.51],[2,1.01,0]],"ltp":0.0,"tv":0.0,"id":2263603},{"batb":[[0,2.3,38.55],[1,1.01,20.51],[2,1.01,0]],"ltp":0.0,"tv":0.0,"id":3622149}]}]}
{"op":"mcm","clk":"1009676766","pt":1580668235290,"mc":[{"id":"1.168230758","rc":[{"batb":[[1,1.57,65.31],[2,1.01,20.51]],"ltp":0.0,"tv":0.0,"id":2263603},{"batb":[[0,2.46,32.34],[1,2.38,35.25],[2,2.32,110.64]],"ltp":0.0,"tv":0.0,"id":3622149}]}]}
{"op":"mcm","clk":"1009677956","pt":1580668251619,"mc":[{"id":"1.168230758","rc":[{"batb":[[0,1.57,65.31],[1,1.01,20.51],[2,1.01,0]],"ltp":0.0,"tv":0.0,"id":2263603},{"batb":[[0,2.38,35.25],[1,1.01,20.51],[2,2.32,0]],"ltp":0.0,"tv":0.0,"id":3622149}]}]}
{"op":"mcm","clk":"1009680418","pt":1580668283032,"mc":[{"id":"1.168230758","rc":[{"batl":[[0,2.16,68.68]],"ltp":0.0,"tv":0.0,"id":2263603},{"batl":[[0,3.3,10.36]],"ltp":0.0,"tv":0.0,"id":3622149}]}]}
{"op":"mcm","clk":"1009681507","pt":1580668296556,"mc":[{"id":"1.168230758","rc":[{"batb":[[0,1.64,55.79],[1,1.6,60.74],[2,1.57,65.31]],"ltp":0.0,"tv":0.0,"id":2263603},{"batb":[[1,2.28,39.1],[2,1.01,20.51]],"ltp":0.0,"tv":0.0,"id":3622149}]}]}
{"op":"mcm","clk":"1009681595","pt":1580668297548,"mc":[{"id":"1.168230758","rc":[{"batb":[[2,1.01,20.51]],"ltp":0.0,"tv":0.0,"id":2263603}]}]}
{"op":"mcm","clk":"1009682612","pt":1580668310340,"mc":[{"id":"1.168230758","rc":[{"batb":[[0,1.6,60.74],[1,1.01,20.51],[2,1.01,0]],"ltp":0.0,"tv":0.0,"id":2263603},{"batb":[[0,2.28,39.1],[1,1.01,20.51],[2,1.01,0]],"ltp":0.0,"tv":0.0,"id":3622149}]}]}
{"op":"mcm","clk":"1009684174","pt":1580668329581,"mc":[{"id":"1.168230758","rc":[{"batb":[[1,1.56,66.49],[2,1.01,20.51]],"ltp":0.0,"tv":0.0,"id":2263603},{"batb":[[0,2.46,31.94],[1,2.38,35.25],[2,2.36,108.93]],"ltp":0.0,"tv":0.0,"id":3622149}]}]}
{"op":"mcm","clk":"1009685535","pt":1580668344585,"mc":[{"id":"1.168230758","rc":[{"batb":[[0,1.56,66.49],[1,1.01,20.51],[2,1.01,0]],"ltp":0.0,"tv":0.0,"id":2263603},{"batb":[[0,2.38,35.25],[1,1.01,20.51],[2,2.36,0]],"ltp":0.0,"tv":0.0,"id":3622149}]}]}
{"op":"mcm","clk":"1009687055","pt":1580668360499,"mc":[{"id":"1.168230758","rc":[{"batb":[[1,1.52,73.1],[2,1.01,20.51]],"ltp":0.0,"tv":0.0,"id":2263603},{"batb":[[0,2.56,28.8],[1,2.46,31.87],[2,1.01,20.51]],"ltp":0.0,"tv":0.0,"id":3622149}]}]}
{"op":"mcm","clk":"1009688516","pt":1580668375646,"mc":[{"id":"1.168230758","rc":[{"batb":[[0,1.52,73.1],[1,1.01,20.51],[2,1.01,0]],"ltp":0.0,"tv":0.0,"id":2263603},{"batb":[[0,2.46,31.87],[1,1.01,20.51],[2,1.01,0]],"ltp":0.0,"tv":0.0,"id":3622149}]}]}
{"op":"mcm","clk":"1009690951","pt":1580668401633,"mc":[{"id":"1.168230758","rc":[{"batb":[[1,1.5,78.21],[2,1.01,20.51]],"ltp":0.0,"tv":0.0,"id":2263603},{"batb":[[0,2.68,25.73],[1,2.56,28.8],[2,2.46,31.87]],"ltp":0.0,"tv":0.0,"id":3622149}]}]}
{"op":"mcm","clk":"1009691023","pt":1580668402467,"mc":[{"id":"1.168230758","rc":[{"batb":[[2,1.01,20.51]],"ltp":0.0,"tv":0.0,"id":3622149}]}]}
{"op":"mcm","clk":"1009691212","pt":1580668404447,"mc":[{"id":"1.168230758","rc":[{"batl":[[0,2.04,574.95]],"ltp":0.0,"tv":0.0,"id":2263603},{"batl":[[0,3.65,62.84]],"ltp":0.0,"tv":0.0,"id":3622149}]}]}
{"op":"mcm","clk":"1009692563","pt":1580668419553,"mc":[{"id":"1.168230758","rc":[{"batb":[[0,1.5,78.21],[1,1.01,20.51],[2,1.01,0]],"ltp":0.0,"tv":0.0,"id":2263603},{"batb":[[0,2.56,28.8],[1,1.01,20.51],[2,1.01,0]],"ltp":0.0,"tv":0.0,"id":3622149}]}]}
{"op":"mcm","clk":"1009692809","pt":1580668422377,"mc":[{"id":"1.168230758","rc":[{"batb":[[0,1.5,77.19]],"ltp":0.0,"tv":0.0,"id":2263603},{"batb":[[0,2.54,29.27]],"ltp":0.0,"tv":0.0,"id":3622149}]}]}
{"op":"mcm","clk":"1009694010","pt":1580668435590,"mc":[{"id":"1.168230758","rc":[{"batb":[[1,1.48,81.91],[2,1.01,20.51]],"ltp":0.0,"tv":0.0,"id":2263603},{"batb":[[0,2.74,24.08],[1,2.6,27.46],[2,2.54,29.27]],"ltp":0.0,"tv":0.0,"id":3622149}]}]}
{"op":"mcm","clk":"1009694091","pt":1580668436380,"mc":[{"id":"1.168230758","rc":[{"batb":[[2,1.01,20.51]],"ltp":0.0,"tv":0.0,"id":3622149}]}]}
{"op":"mcm","clk":"1009694839","pt":1580668444500,"mc":[{"id":"1.168230758","rc":[{"batb":[[0,1.48,81.91],[1,1.01,20.51],[2,1.01,0]],"ltp":0.0,"tv":0.0,"id":2263603},{"batb":[[0,2.6,27.46],[1,1.01,20.51],[2,1.01,0]],"ltp":0.0,"tv":0.0,"id":3622149}]}]}
{"op":"mcm","clk":"1009695320","pt":1580668449623,"mc":[{"id":"1.168230758","rc":[{"batl":[[0,2.04,90.98]],"ltp":0.0,"tv":0.0,"id":2263603},{"batl":[[0,3.65,6.75]],"ltp":0.0,"tv":0.0,"id":3622149}]}]}
{"op":"mcm","clk":"1009695532","pt":1580668451530,"mc":[{"id":"1.168230758","rc":[{"batb":[[1,1.45,88.12],[2,1.01,20.51]],"ltp":0.0,"tv":0.0,"id":2263603},{"batb":[[0,2.82,22.35],[1,2.68,25.34],[2,2.6,27.46]],"ltp":0.0,"tv":0.0,"id":3622149}]}]}
{"op":"mcm","clk":"1009695627","pt":1580668452529,"mc":[{"id":"1.168230758","rc":[{"batb":[[2,1.01,20.51]],"ltp":0.0,"tv":0.0,"id":3622149}]}]}
{"op":"mcm","clk":"1009696146","pt":1580668457627,"mc":[{"id":"1.168230758","rc":[{"batb":[[0,1.45,88.12],[1,1.01,20.51],[2,1.01,0]],"ltp":0.0,"tv":0.0,"id":2263603},{"batb":[[0,2.68,25.34],[1,1.01,20.51],[2,1.01,0]],"ltp":0.0,"tv":0.0,"id":3622149}]}]}
{"op":"mcm","clk":"1009697995","pt":1580668475507,"mc":[{"id":"1.168230758","rc":[{"batb":[[0,1.52,73.88],[1,1.49,79.94],[2,1.47,661.67]],"ltp":0.0,"tv":0.0,"id":2263603},{"batb":[[1,2.58,28.48],[2,1.01,20.51]],"ltp":0.0,"tv":0.0,"id":3622149}]}]}
{"op":"mcm","clk":"1009698797","pt":1580668483436,"mc":[{"id":"1.168230758","rc":[{"batb":[[0,1.49,79.94],[1,1.01,20.51],[2,1.47,0]],"ltp":0.0,"tv":0.0,"id":2263603},{"batb":[[0,2.58,28.48],[1,1.01,20.51],[2,1.01,0]],"ltp":0.0,"tv":0.0,"id":3622149}]}]}
{"op":"mcm","clk":"1009700530","pt":1580668502649,"mc":[{"id":"1.168230758","rc":[{"batb":[[1,1.46,86.79],[2,1.01,20.51]],"ltp":0.0,"tv":0.0,"id":2263603},{"batb":[[0,2.78,23.05],[1,2.64,26.36],[2,1.01,20.51]],"ltp":0.0,"tv":0.0,"id":3622149}]}]}
{"op":"mcm","clk":"1009701551","pt":1580668514355,"mc":[{"id":"1.168230758","rc":[{"batb":[[0,1.46,86.79],[1,1.01,20.51],[2,1.01,0]],"ltp":0.0,"tv":0.0,"id":2263603},{"batb":[[0,2.64,26.36],[1,1.01,20.51],[2,1.01,0]],"ltp":0.0,"tv":0.0,"id":3622149}]}]}
{"op":"mcm","clk":"1009702662","pt":1580668526574,"mc":[{"id":"1.168230758","rc":[{"batb":[[0,1.53,71.6],[1,1.5,77.82],[2,1.46,86.79]],"ltp":0.0,"tv":0.0,"id":2263603},{"batb":[[1,2.52,30.06],[2,1.01,20.51]],"ltp":0.0,"tv":0.0,"id":3622149}]}]}
{"op":"mcm","clk":"1009702739","pt":1580668527347,"mc":[{"id":"1.168230758","rc":[{"batb":[[2,1.01,20.51]],"ltp":0.0,"tv":0.0,"id":2263603}]}]}
{"op":"mcm","clk":"1009703494","pt":1580668535568,"mc":[{"id":"1.168230758","rc":[{"batb":[[0,1.5,77.82],[1,1.01,20.51],[2,1.01,0]],"ltp":0.0,"tv":0.0,"id":2263603},{"batb":[[0,2.52,30.06],[1,1.01,20.51],[2,1.01,0]],"ltp":0.0,"tv":0.0,"id":3622149}]}]}
{"op":"mcm","clk":"1009705272","pt":1580668554380,"mc":[{"id":"1.168230758","rc":[{"batb":[[0,1.51,319.65],[1,1.5,471.03],[2,1.01,20.51]],"batl":[[0,1.56,510.36],[1,1.57,324.65],[2,2.04,90.98]],"ltp":0.0,"tv":0.0,"id":2263603}]}]}
{"op":"mcm","clk":"1009705338","pt":1580668554999,"mc":[{"id":"1.168230758","rc":[{"batb":[[2,1.41,101.58]],"ltp":0.0,"tv":0.0,"id":2263603},{"batb":[[0,2.76,23.84],[1,2.54,33.99],[2,2.48,31.71]],"ltp":0.0,"tv":0.0,"id":3622149}]}]}
{"op":"mcm","clk":"1009706110","pt":1580668563195,"mc":[{"id":"1.168230758","rc":[{"batb":[[1,1.5,470.79],[2,1.41,101.34]],"ltp":0.0,"tv":0.0,"id":2263603},{"batb":[[0,2.74,23.92],[2,2.46,31.79]],"ltp":0.0,"tv":0.0,"id":3622149}]}]}
{"op":"mcm","clk":"1009706543","pt":1580668568596,"mc":[{"id":"1.168230758","rc":[{"batl":[[0,3.45,8.23]],"ltp":0.0,"tv":0.0,"id":3622149}]}]}
{"op":"mcm","clk":"1009706806","pt":1580668571537,"mc":[{"id":"1.168230758","rc":[{"trd":[[1.51,15.14]],"batb":[[0,1.51,388.48],[1,1.5,393.21],[2,1.41,99.93]],"ltp":1.51,"tv":15.14,"id":2263603}],"tv":15.14}]}
{"op":"mcm","clk":"1009706906","pt":1580668572602,"mc":[{"id":"1.168230758","rc":[{"batb":[[0,1.51,312.08]],"ltp":1.51,"tv":15.14,"id":2263603},{"batb":[[0,2.46,31.79],[1,1.01,20.51],[2,2.46,0]],"ltp":0.0,"tv":0.0,"id":3622149}]}]}
{"op":"mcm","clk":"1009709657","pt":1580668600444,"mc":[{"id":"1.168230758","rc":[{"trd":[[1.56,14.97]],"batl":[[0,1.56,495.39]],"ltp":1.56,"tv":30.11,"id":2263603},{"trd":[[2.78,8.4]],"ltp":2.78,"tv":8.4,"id":3622149}],"tv":38.51}]}
{"op":"mcm","clk":"1009709847","pt":1580668602350,"mc":[{"id":"1.168230758","rc":[{"trd":[[1.56,90.69]],"batl":[[0,1.56,457.53]],"ltp":1.56,"tv":105.83,"id":2263603}],"tv":114.23}]}
{"op":"mcm","clk":"1009710269","pt":1580668606251,"mc":[{"id":"1.168230758","rc":[{"batl":[[0,1.56,372.32]],"ltp":1.56,"tv":105.83,"id":2263603}]}]}
{"op":"mcm","clk":"1009710598","pt":1580668609255,"mc":[{"id":"1.168230758","rc":[{"batb":[[0,1.51,462.61]],"ltp":1.56,"tv":105.83,"id":2263603}]}]}
{"op":"mcm","clk":"1009711522","pt":1580668618545,"mc":[{"id":"1.168230758","rc":[{"trd":[[1.56,116.43]],"batl":[[0,1.56,359.45]],"ltp":1.56,"tv":131.57,"id":2263603}],"tv":139.97}]}
{"op":"mcm","clk":"1009713143","pt":1580668634463,"mc":[{"id":"1.168230758","rc":[{"batl":[[0,1.57,324.65],[1,2.04,90.98],[2,2.04,0]],"ltp":1.56,"tv":131.57,"id":2263603}]}]}
{"op":"mcm","clk":"1009713405","pt":1580668637493,"mc":[{"id":"1.168230758","rc":[{"batb":[[0,1.51,585.14]],"batl":[[0,1.57,577.1],[1,1.58,315.56],[2,2.04,90.98]],"ltp":1.56,"tv":131.57,"id":2263603}]}]}
{"op":"mcm","clk":"1009716119","pt":1580668669121,"mc":[{"id":"1.168230758","rc":[{"batb":[[0,1.01,20.51],[1,1.5,0],[2,1.41,0]],"batl":[[0,2.04,90.98],[1,1.58,0],[2,2.04,0]],"ltp":1.56,"tv":131.57,"id":2263603},{"batb":[[0,1.01,20.51],[1,1.01,0]],"ltp":2.78,"tv":8.4,"id":3622149}]}]}
{"op":"mcm","clk":"1009716601","pt":1580668675602,"mc":[{"id":"1.168230758","rc":[{"batb":[[0,1.49,636.49],[1,1.48,415.99],[2,1.01,20.51]],"batl":[[0,1.54,284.98],[1,1.55,340.52],[2,2.04,90.98]],"ltp":1.56,"tv":131.57,"id":2263603}]}]}
{"op":"mcm","clk":"1009717053","pt":1580668680505,"mc":[{"id":"1.168230758","rc":[{"batb":[[0,1.01,20.51],[1,1.48,0],[2,1.01,0]],"batl":[[0,2.04,90.98],[1,1.55,0],[2,2.04,0]],"ltp":1.56,"tv":131.57,"id":2263603}]}]}
{"op":"mcm","clk":"1009717245","pt":1580668682746,"mc":[{"id":"1.168230758","rc":[{"batb":[[0,1.42,575.86],[1,1.41,512.52],[2,1.01,20.51]],"batl":[[0,1.68,335.28],[1,1.7,491.63],[2,2.04,90.98]],"ltp":1.56,"tv":131.57,"id":2263603}]}]}
{"op":"mcm","clk":"1009717830","pt":1580668689553,"mc":[{"id":"1.168230758","rc":[{"batb":[[0,1.01,20.51],[1,1.41,0],[2,1.01,0]],"ltp":1.56,"tv":131.57,"id":2263603}]}]}
{"op":"mcm","clk":"1009718076","pt":1580668692638,"mc":[{"id":"1.168230758","rc":[{"batb":[[0,1.62,416],[1,1.61,298.26],[2,1.57,1005.28]],"ltp":1.56,"tv":131.57,"id":2263603}]}]}
{"op":"mcm","clk":"1009718176","pt":1580668693640,"mc":[{"id":"1.168230758","rc":[{"batb":[[2,1.6,60.03]],"ltp":1.56,"tv":131.57,"id":2263603},{"batb":[[0,2.46,32.42],[1,2.24,41.94],[2,1.01,20.51]],"ltp":2.78,"tv":8.4,"id":3622149}]}]}
{"op":"mcm","clk":"1009718319","pt":1580668695434,"mc":[{"id":"1.168230758","rc":[{"batl":[[0,3.15,200.42]],"ltp":2.78,"tv":8.4,"id":3622149}]}]}
{"op":"mcm","clk":"1009719334","pt":1580668707323,"mc":[{"id":"1.168230758","rc":[{"batb":[[0,1.5,77.5],[1,1.01,20.51],[2,1.6,0]],"batl":[[0,2.04,90.98],[1,1.7,0],[2,2.04,0]],"ltp":1.56,"tv":131.57,"id":2263603},{"batb":[[0,2.24,41.94],[1,1.01,20.51],[2,1.01,0]],"ltp":2.78,"tv":8.4,"id":3622149}]}]}
{"op":"mcm","clk":"1009719572","pt":1580668710247,"mc":[{"id":"1.168230758","rc":[{"batb":[[0,1.51,542.22],[1,1.5,470.88],[2,1.01,20.51]],"batl":[[0,1.81,319.91],[1,1.83,386.12],[2,2.04,90.98]],"ltp":1.56,"tv":131.57,"id":2263603}]}]}
{"op":"mcm","clk":"1009722036","pt":1580668736387,"mc":[{"id":"1.168230758","rc":[{"batl":[[0,2.04,90.98],[1,1.83,0],[2,2.04,0]],"ltp":1.56,"tv":131.57,"id":2263603}]}]}
{"op":"mcm","clk":"1009722313","pt":1580668739386,"mc":[{"id":"1.168230758","rc":[{"batl":[[0,1.56,301.92],[1,1.57,324.72],[2,1.59,573.01]],"ltp":1.56,"tv":131.57,"id":2263603}]}]}
{"op":"mcm","clk":"1009722401","pt":1580668740284,"mc":[{"id":"1.168230758","rc":[{"batb":[[2,1.39,105.98]],"ltp":1.56,"tv":131.57,"id":2263603},{"batb":[[0,2.74,23.92],[1,2.42,33.44],[2,1.01,20.51]],"ltp":2.78,"tv":8.4,"id":3622149}]}]}
{"op":"mcm","clk":"1009722618","pt":1580668742478,"mc":[{"id":"1.168230758","rc":[{"batl":[[2,2.04,90.98]],"ltp":1.56,"tv":131.57,"id":2263603}]}]}
{"op":"mcm","clk":"1009724261","pt":1580668760597,"mc":[{"id":"1.168230758","rc":[{"batb":[[0,1.39,105.59],[1,1.01,20.51],[2,1.39,0]],"batl":[[0,2.04,90.98],[1,1.57,0],[2,2.04,0]],"ltp":1.56,"tv":131.57,"id":2263603},{"batb":[[0,2.42,33.44],[1,1.01,20.51],[2,1.01,0]],"ltp":2.78,"tv":8.4,"id":3622149}]}]}
{"op":"mcm","clk":"1009724361","pt":1580668761603,"mc":[{"id":"1.168230758","rc":[{"batb":[[1,2.38,8.88],[2,1.01,20.51]],"ltp":2.78,"tv":8.4,"id":3622149}]}]}
{"op":"mcm","clk":"1009724434","pt":1580668762300,"mc":[{"id":"1.168230758","rc":[{"batl":[[0,1.51,2.87],[1,2.04,90.98]],"ltp":1.56,"tv":131.57,"id":2263603},{"batb":[[1,1.01,20.51],[2,1.01,0]],"ltp":2.78,"tv":8.4,"id":3622149}]}]}
{"op":"mcm","clk":"1009724554","pt":1580668763499,"mc":[{"id":"1.168230758","rc":[{"batb":[[0,1.41,326.67],[1,1.4,527.54],[2,1.39,105.59]],"batl":[[1,1.7,389.3],[2,1.72,472.66]],"ltp":1.56,"tv":131.57,"id":2263603}]}]}
{"op":"mcm","clk":"1009724763","pt":1580668765597,"mc":[{"id":"1.168230758","rc":[{"batl":[[0,1.7,389.3],[1,1.72,472.66],[2,2.04,90.98]],"ltp":1.56,"tv":131.57,"id":2263603}]}]}
{"op":"mcm","clk":"1009724945","pt":1580668767621,"mc":[{"id":"1.168230758","rc":[{"batl":[[0,3.65,170.41]],"ltp":2.78,"tv":8.4,"id":3622149}]}]}
{"op":"mcm","clk":"1009726487","pt":1580668784347,"mc":[{"id":"1.168230758","rc":[{"batb":[[0,1.39,105.59],[1,1.01,20.51],[2,1.39,0]],"ltp":1.56,"tv":131.57,"id":2263603}]}]}
{"op":"mcm","clk":"1009726801","pt":1580668787549,"mc":[{"id":"1.168230758","rc":[{"batb":[[0,1.64,301.16],[1,1.63,284.89],[2,1.58,987.95]],"batl":[[2,2.04,0]],"ltp":1.56,"tv":131.57,"id":2263603}]}]}
{"op":"mcm","clk":"1009726862","pt":1580668788332,"mc":[{"id":"1.168230758","rc":[{"batb":[[2,1.62,58.22]],"ltp":1.56,"tv":131.57,"id":2263603},{"batb":[[1,2.18,44.85],[2,1.01,20.51]],"ltp":2.78,"tv":8.4,"id":3622149}]}]}
{"op":"mcm","clk":"1009727025","pt":1580668790318,"mc":[{"id":"1.168230758","rc":[{"batl":[[0,3.25,196.23]],"ltp":2.78,"tv":8.4,"id":3622149}]}]}
{"op":"mcm","clk":"1009727125","pt":1580668791421,"mc":[{"id":"1.168230758","rc":[{"batl":[[2,2.3,309.75]],"ltp":1.56,"tv":131.57,"id":2263603}]}]}
{"op":"mcm","clk":"1009728408","pt":1580668805563,"mc":[{"id":"1.168230758","rc":[{"batb":[[0,1.63,284.89],[1,1.62,58.22],[2,1.5,78.21]],"ltp":1.56,"tv":131.57,"id":2263603}]}]}
{"op":"mcm","clk":"1009728493","pt":1580668806572,"mc":[{"id":"1.168230758","rc":[{"batb":[[0,1.5,78.21],[1,1.01,20.51],[2,1.5,0]],"batl":[[0,1.64,2.87],[1,2.3,309.75],[2,2.3,0]],"ltp":1.56,"tv":131.57,"id":2263603},{"batb":[[0,2.18,44.85],[1,1.01,20.51],[2,1.01,0]],"ltp":2.78,"tv":8.4,"id":3622149}]}]}
{"op":"mcm","clk":"1009728893","pt":1580668810954,"mc":[{"id":"1.168230758","rc":[{"trd":[[1.64,2.87]],"batl":[[0,2.3,309.75],[1,2.3,0]],"ltp":1.64,"tv":134.44,"id":2263603},{"trd":[[2.56,1.84]],"batl":[[0,2.38,24.36]],"ltp":2.56,"tv":10.24,"id":3622149}],"tv":144.68}]}
{"op":"mcm","clk":"1009729028","pt":1580668812469,"mc":[{"id":"1.168230758","rc":[{"trd":[[1.72,33.7]],"batb":[[0,1.61,372.75],[1,1.6,305.46],[2,1.5,78.21]],"batl":[[0,1.67,374.13],[1,1.69,501.87],[2,2.3,309.75]],"ltp":1.72,"tv":168.14,"id":2263603},{"trd":[[2.38,24.36]],"ltp":2.38,"tv":34.6,"id":3622149}],"tv":202.74}]}
{"op":"mcm","clk":"1009729224","pt":1580668814562,"mc":[{"id":"1.168230758","rc":[{"batl":[[0,3.15,200.42]],"ltp":2.38,"tv":34.6,"id":3622149}]}]}
{"op":"mcm","clk":"1009729474","pt":1580668817559,"mc":[{"id":"1.168230758","rc":[{"batb":[[0,1.5,78.21],[1,1.01,20.51],[2,1.5,0]],"batl":[[0,2.3,309.75],[1,1.69,0],[2,2.3,0]],"ltp":1.72,"tv":168.14,"id":2263603}]}]}
{"op":"mcm","clk":"1009729787","pt":1580668821381,"mc":[{"id":"1.168230758","rc":[{"batl":[[0,1.86,412.34],[1,1.88,354.65],[2,2.3,309.75]],"ltp":1.72,"tv":168.14,"id":2263603}]}]}
{"op":"mcm","clk":"1009730023","pt":1580668824583,"mc":[{"id":"1.168230758","rc":[{"batb":[[0,1.78,348.77],[1,1.76,433.16],[2,1.72,795.85]],"ltp":1.72,"tv":168.14,"id":2263603}]}]}
{"op":"mcm","clk":"1009730071","pt":1580668825162,"mc":[{"id":"1.168230758","rc":[{"batb":[[2,1.74,44.93]],"ltp":1.72,"tv":168.14,"id":2263603},{"batb":[[1,2.04,54.68],[2,1.01,20.51]],"ltp":2.38,"tv":34.6,"id":3622149}]}]}
{"op":"mcm","clk":"1009730296","pt":1580668827556,"mc":[{"id":"1.168230758","rc":[{"batl":[[0,2.72,241.55]],"ltp":2.38,"tv":34.6,"id":3622149}]}]}
{"op":"mcm","clk":"1009731244","pt":1580668838321,"mc":[{"id":"1.168230758","rc":[{"batb":[[0,1.64,55.23],[1,1.01,20.51],[2,1.74,0]],"batl":[[0,2.3,309.75],[1,1.88,0],[2,2.3,0]],"ltp":1.72,"tv":168.14,"id":2263603},{"batb":[[0,2.04,54.68],[1,1.01,20.51],[2,1.01,0]],"ltp":2.38,"tv":34.6,"id":3622149}]}]}
{"op":"mcm","clk":"1009731562","pt":1580668841580,"mc":[{"id":"1.168230758","rc":[{"batb":[[0,1.67,471.43],[1,1.66,267.25],[2,1.64,55.23]],"batl":[[0,1.98,266.5],[1,2,294.26],[2,2.3,309.75]],"ltp":1.72,"tv":168.14,"id":2263603}]}]}
{"op":"mcm","clk":"1009731672","pt":1580668842580,"mc":[{"id":"1.168230758","rc":[{"batl":[[2,2.3,0]],"ltp":1.72,"tv":168.14,"id":2263603}]}]}
{"op":"mcm","clk":"1009731761","pt":1580668843479,"mc":[{"id":"1.168230758","rc":[{"batb":[[0,1.64,55.23],[1,1.01,20.51],[2,1.64,0]],"ltp":1.72,"tv":168.14,"id":2263603}]}]}
{"op":"mcm","clk":"1009732071","pt":1580668846467,"mc":[{"id":"1.168230758","rc":[{"batb":[[0,1.76,301.34],[1,1.74,450.12],[2,1.64,55.23]],"batl":[[0,1.83,317.13],[1,1.85,373.18]],"ltp":1.72,"tv":168.14,"id":2263603}]}]}
{"op":"mcm","clk":"1009732195","pt":1580668847622,"mc":[{"id":"1.168230758","rc":[{"batl":[[2,2.5,274.54]],"ltp":1.72,"tv":168.14,"id":2263603},{"batl":[[0,2.72,241.55]],"ltp":2.38,"tv":34.6,"id":3622149}]}]}
{"op":"mcm","clk":"1009732340","pt":1580668849088,"mc":[{"id":"1.168230758","rc":[{"batb":[[0,1.64,55.23],[1,1.01,20.51],[2,1.64,0]],"batl":[[0,2.5,274.54],[1,1.85,0],[2,2.5,0]],"ltp":1.72,"tv":168.14,"id":2263603}]}]}
{"op":"mcm","clk":"1009732667","pt":1580668852599,"mc":[{"id":"1.168230758","rc":[{"batb":[[0,1.67,471.43],[1,1.66,267.25],[2,1.64,55.23]],"batl":[[0,1.98,266.5],[1,2,294.26],[2,2.5,274.54]],"ltp":1.72,"tv":168.14,"id":2263603}]}]}
{"op":"mcm","clk":"1009733581","pt":1580668861887,"mc":[{"id":"1.168230758","rc":[{"batb":[[0,1.64,55.23],[1,1.01,20.51],[2,1.64,0]],"ltp":1.72,"tv":168.14,"id":2263603}]}]}
{"op":"mcm","clk":"1009733878","pt":1580668864612,"mc":[{"id":"1.168230758","rc":[{"batb":[[0,1.9,261.35],[1,1.88,348.93],[2,1.64,55.23]],"ltp":1.72,"tv":168.14,"id":2263603}]}]}
{"op":"mcm","clk":"1009733983","pt":1580668865610,"mc":[{"id":"1.168230758","rc":[{"batb":[[2,1.85,37.22]],"ltp":1.72,"tv":168.14,"id":2263603},{"batb":[[1,1.84,37.61],[2,1.01,20.51]],"ltp":2.38,"tv":34.6,"id":3622149}]}]}
{"op":"mcm","clk":"1009734120","pt":1580668867035,"mc":[{"id":"1.168230758","rc":[{"batl":[[0,2.6,257.57]],"ltp":2.38,"tv":34.6,"id":3622149}]}]}
{"op":"mcm","clk":"1009734852","pt":1580668874524,"mc":[{"id":"1.168230758","rc":[{"trd":[[1.9,53]],"batb":[[0,1.9,234.85]],"ltp":1.9,"tv":221.15,"id":2263603}],"tv":255.75}]}
{"op":"mcm","clk":"1009737438","pt":1580668902416,"mc":[{"id":"1.168230758","rc":[{"batb":[[0,1.73,46.58],[1,1.01,20.51],[2,1.85,0]],"batl":[[0,2.5,274.54],[1,2,0],[2,2.5,0]],"ltp":1.9,"tv":221.15,"id":2263603},{"batb":[[0,1.84,37.61],[1,1.01,20.51],[2,1.01,0]],"ltp":2.38,"tv":34.6,"id":3622149}]}]}
{"op":"mcm","clk":"1009737720","pt":1580668905343,"mc":[{"id":"1.168230758","rc":[{"batb":[[0,1.75,423.22],[1,1.73,506.23],[2,1.01,20.51]],"batl":[[0,2.22,315.57],[1,2.24,212.13],[2,2.5,274.54]],"ltp":1.9,"tv":221.15,"id":2263603}]}]}
{"op":"mcm","clk":"1009738552","pt":1580668914448,"mc":[{"id":"1.168230758","rc":[{"batb":[[0,1.73,46.58],[1,1.01,20.51],[2,1.01,0]],"batl":[[0,2.5,274.54],[1,2.24,0],[2,2.5,0]],"ltp":1.9,"tv":221.15,"id":2263603}]}]}
{"op":"mcm","clk":"1009738740","pt":1580668916554,"mc":[{"id":"1.168230758","rc":[{"batb":[[0,1.98,584.7],[1,1.73,46.58],[2,1.01,20.51]],"ltp":1.9,"tv":221.15,"id":2263603}]}]}
{"op":"mcm","clk":"1009738829","pt":1580668917447,"mc":[{"id":"1.168230758","rc":[{"batb":[[0,2.04,54.13],[1,1.98,584.7],[2,1.88,34.93]],"ltp":1.9,"tv":221.15,"id":2263603},{"batb":[[1,1.82,378.51],[2,1.8,401.07]],"batl":[[0,1.9,295.52],[1,1.92,331.62]],"ltp":2.38,"tv":34.6,"id":3622149}]}]}
{"op":"mcm","clk":"1009739055","pt":1580668919647,"mc":[{"id":"1.168230758","rc":[{"batb":[[1,1.88,34.93],[2,1.01,20.51]],"ltp":1.9,"tv":221.15,"id":2263603}]}]}
{"op":"mcm","clk":"1009739120","pt":1580668920226,"mc":[{"id":"1.168230758","rc":[{"batl":[[0,2.92,221.26]],"ltp":1.9,"tv":221.15,"id":2263603},{"batl":[[2,2.36,299.17]],"ltp":2.38,"tv":34.6,"id":3622149}]}]}
{"op":"mcm","clk":"1009739744","pt":1580668926636,"mc":[{"id":"1.168230758","rc":[{"batb":[[0,1.88,34.93],[1,1.01,20.51],[2,1.01,0]],"ltp":1.9,"tv":221.15,"id":2263603},{"batb":[[0,1.65,54.13],[1,1.01,20.51],[2,1.8,0]],"batl":[[0,2.36,299.17],[1,1.92,0],[2,2.36,0]],"ltp":2.38,"tv":34.6,"id":3622149}]}]}
{"op":"mcm","clk":"1009740036","pt":1580668929573,"mc":[{"id":"1.168230758","rc":[{"batb":[[0,1.65,359.92],[1,1.64,277.06],[2,1.01,20.51]],"batl":[[0,2.1,387.39],[1,2.12,248.03],[2,2.36,299.17]],"ltp":2.38,"tv":34.6,"id":3622149}]}]}
{"op":"mcm","clk":"1009740138","pt":1580668930525,"mc":[{"id":"1.168230758","rc":[{"batl":[[0,2.1,292.58],[1,2.92,221.26]],"ltp":1.9,"tv":221.15,"id":2263603}]}]}
{"op":"mcm","clk":"1009740335","pt":1580668932564,"mc":[{"id":"1.168230758","rc":[{"batl":[[0,2.92,221.26],[1,2.92,0]],"ltp":1.9,"tv":221.15,"id":2263603}]}]}
{"op":"mcm","clk":"1009740519","pt":1580668934450,"mc":[{"id":"1.168230758","rc":[{"batl":[[0,1.82,50.41],[1,2.1,387.39],[2,2.12,248.03]],"ltp":2.38,"tv":34.6,"id":3622149}]}]}
{"op":"mcm","clk":"1009740746","pt":1580668936553,"mc":[{"id":"1.168230758","rc":[{"batl":[[0,2.1,387.39],[1,2.12,248.03],[2,2.36,299.17]],"ltp":2.38,"tv":34.6,"id":3622149}]}]}
{"op":"mcm","clk":"1009741137","pt":1580668940575,"mc":[{"id":"1.168230758","rc":[{"batl":[[0,2.36,299.17],[1,2.12,0],[2,2.36,0]],"ltp":2.38,"tv":34.6,"id":3622149}]}]}
{"op":"mcm","clk":"1009741324","pt":1580668942563,"mc":[{"id":"1.168230758","rc":[{"batb":[[0,2.32,434.1],[1,1.88,34.93],[2,1.01,20.51]],"ltp":1.9,"tv":221.15,"id":2263603}]}]}
{"op":"mcm","clk":"1009741421","pt":1580668943559,"mc":[{"id":"1.168230758","rc":[{"batb":[[0,2.34,36.43],[1,2.32,434.1],[2,2.12,48.47]],"ltp":1.9,"tv":221.15,"id":2263603},{"batb":[[2,1.51,75.85]],"batl":[[0,1.71,350.57],[1,1.73,460.87],[2,1.83,1064.5]],"ltp":2.38,"tv":34.6,"id":3622149}]}]}
{"op":"mcm","clk":"1009741511","pt":1580668944555,"mc":[{"id":"1.168230758","rc":[{"batl":[[2,1.83,0]],"ltp":2.38,"tv":34.6,"id":3622149}]}]}
{"op":"mcm","clk":"1009741594","pt":1580668945285,"mc":[{"id":"1.168230758","rc":[{"batl":[[0,3.3,191.92]],"ltp":1.9,"tv":221.15,"id":2263603},{"batl":[[2,2.16,342.82]],"ltp":2.38,"tv":34.6,"id":3622149}]}]}
{"op":"mcm","clk":"1009741744","pt":1580668946600,"mc":[{"id":"1.168230758","rc":[{"batb":[[1,2.12,48.47],[2,1.01,20.51]],"ltp":1.9,"tv":221.15,"id":2263603}]}]}
{"op":"mcm","clk":"1009742229","pt":1580668951371,"mc":[{"id":"1.168230758","rc":[{"batl":[[0,1.71,280.66]],"ltp":2.38,"tv":34.6,"id":3622149}]}]}
{"op":"mcm","clk":"1009742317","pt":1580668952362,"mc":[{"id":"1.168230758","rc":[{"batb":[[0,2.12,48.47],[1,1.01,20.51],[2,1.01,0]],"ltp":1.9,"tv":221.15,"id":2263603},{"batb":[[0,1.51,75.85],[1,1.01,20.51],[2,1.51,0]],"batl":[[0,2.16,342.82],[1,1.73,0],[2,2.16,0]],"ltp":2.38,"tv":34.6,"id":3622149}]}]}
{"op":"mcm","clk":"1009742427","pt":1580668953570,"mc":[{"id":"1.168230758","rc":[{"batl":[[0,1.63,50.41],[1,2.16,342.82]],"ltp":2.38,"tv":34.6,"id":3622149}]}]}
{"op":"mcm","clk":"1009742521","pt":1580668954556,"mc":[{"id":"1.168230758","rc":[{"trd":[[1.63,100.82]],"batl":[[0,2.16,342.82],[1,2.16,0]],"ltp":1.63,"tv":135.42,"id":3622149}],"tv":356.57}]}
{"op":"mcm","clk":"1009742603","pt":1580668955460,"mc":[{"id":"1.168230758","rc":[{"batb":[[0,1.52,392.99],[1,1.51,454.18],[2,1.01,20.51]],"batl":[[0,1.85,238.48],[1,1.87,359.45],[2,2.16,342.82]],"ltp":1.63,"tv":135.42,"id":3622149}]}]}
{"op":"mcm","clk":"1009742722","pt":1580668956503,"mc":[{"id":"1.168230758","rc":[{"batb":[[0,1.51,75.85],[1,1.01,20.51],[2,1.01,0]],"batl":[[0,2.16,342.82],[1,1.87,0],[2,2.16,0]],"ltp":1.63,"tv":135.42,"id":3622149}]}]}
{"op":"mcm","clk":"1009743326","pt":1580668962584,"mc":[{"id":"1.168230758","rc":[{"batb":[[0,1.52,429.03],[1,1.51,454.24],[2,1.01,20.51]],"batl":[[0,1.86,389.83],[1,1.88,353.09],[2,2.16,342.82]],"ltp":1.63,"tv":135.42,"id":3622149}]}]}
{"op":"mcm","clk":"1009743871","pt":1580668967577,"mc":[{"id":"1.168230758","rc":[{"batl":[[0,2.16,342.82],[1,1.88,0],[2,2.16,0]],"ltp":1.63,"tv":135.42,"id":3622149}]}]}
{"op":"mcm","clk":"1009744198","pt":1580668970569,"mc":[{"id":"1.168230758","rc":[{"batb":[[0,2.72,24.55],[1,2.52,30.21],[2,1.01,20.51]],"ltp":1.9,"tv":221.15,"id":2263603},{"batb":[[2,1.42,97.41]],"batl":[[0,1.57,348.33],[1,1.58,313.42],[2,1.6,573.01]],"ltp":1.63,"tv":135.42,"id":3622149}]}]}
{"op":"mcm","clk":"1009744494","pt":1580668973562,"mc":[{"id":"1.168230758","rc":[{"batl":[[0,3.9,158.24]],"ltp":1.9,"tv":221.15,"id":2263603},{"batl":[[2,1.95,409.86]],"ltp":1.63,"tv":135.42,"id":3622149}]}]}
{"op":"mcm","clk":"1009745084","pt":1580668979610,"mc":[{"id":"1.168230758","rc":[{"batb":[[0,1.51,75.85],[1,1.42,97.41],[2,1.01,20.51]],"batl":[[0,1.95,409.86],[1,1.58,0],[2,1.95,0]],"ltp":1.63,"tv":135.42,"id":3622149}]}]}
{"op":"mcm","clk":"1009745170","pt":1580668980373,"mc":[{"id":"1.168230758","rc":[{"batb":[[0,2.52,29.98],[1,1.01,20.51],[2,1.01,0]],"ltp":1.9,"tv":221.15,"id":2263603},{"batb":[[0,1.42,97.41],[1,1.01,20.51],[2,1.01,0]],"ltp":1.63,"tv":135.42,"id":3622149}]}]}
{"op":"mcm","clk":"1009745378","pt":1580668982512,"mc":[{"id":"1.168230758","rc":[{"batb":[[0,1.45,357.2],[1,1.44,461.12],[2,1.42,97.41]],"batl":[[0,1.65,520.46],[1,1.67,517.3],[2,1.95,409.86]],"ltp":1.63,"tv":135.42,"id":3622149}]}]}
{"op":"mcm","clk":"1009746125","pt":1580668990425,"mc":[{"id":"1.168230758","rc":[{"batl":[[0,1.95,409.86],[1,1.67,0],[2,1.95,0]],"ltp":1.63,"tv":135.42,"id":3622149}]}]}
{"op":"mcm","clk":"1009746422","pt":1580668993579,"mc":[{"id":"1.168230758","rc":[{"batl":[[0,1.49,329.26],[1,1.5,954.85]],"ltp":1.63,"tv":135.42,"id":3622149}]}]}
{"op":"mcm","clk":"1009746469","pt":1580668994200,"mc":[{"id":"1.168230758","rc":[{"batb":[[0,3.05,45.08],[1,2.66,26.04],[2,1.01,20.51]],"ltp":1.9,"tv":221.15,"id":2263603}]}]}
{"op":"mcm","clk":"1009746722","pt":1580668996611,"mc":[{"id":"1.168230758","rc":[{"batb":[[2,2.54,17.49]],"ltp":1.9,"tv":221.15,"id":2263603},{"batl":[[1,1.5,381.84]],"ltp":1.63,"tv":135.42,"id":3622149}]}]}
{"op":"mcm","clk":"1009746828","pt":1580668997612,"mc":[{"id":"1.168230758","rc":[{"batb":[[2,1.01,20.51]],"batl":[[0,4.6,136.05]],"ltp":1.9,"tv":221.15,"id":2263603},{"batl":[[2,1.82,469.11]],"ltp":1.63,"tv":135.42,"id":3622149}]}]}
{"op":"mcm","clk":"1009747601","pt":1580669005290,"mc":[{"id":"1.168230758","rc":[{"trd":[[1.49,105.52]],"batl":[[0,1.49,276.5]],"ltp":1.49,"tv":240.94,"id":3622149}],"tv":462.09}]}
{"op":"mcm","clk":"1009747724","pt":1580669006502,"mc":[{"id":"1.168230758","rc":[{"trd":[[1.45,68.16]],"batb":[[0,1.45,323.12]],"ltp":1.45,"tv":309.1,"id":3622149}],"tv":530.25}]}
{"op":"mcm","clk":"1009747948","pt":1580669008635,"mc":[{"id":"1.168230758","rc":[{"batl":[[0,1.49,351.24]],"ltp":1.45,"tv":309.1,"id":3622149}]}]}
{"op":"mcm","clk":"1009748478","pt":1580669013592,"mc":[{"id":"1.168230758","rc":[{"trd":[[1.49,106.22]],"batl":[[0,1.49,350.89]],"ltp":1.49,"tv":309.79,"id":3622149}],"tv":530.95}]}
{"op":"mcm","clk":"1009749660","pt":1580669024616,"mc":[{"id":"1.168230758","rc":[{"batb":[[0,2.66,26.04],[1,1.01,20.51],[2,1.01,0]],"ltp":1.9,"tv":221.15,"id":2263603},{"batb":[[0,1.34,128.72],[1,1.01,20.51],[2,1.42,0]],"batl":[[0,1.82,469.11],[1,1.5,0],[2,1.82,0]],"ltp":1.49,"tv":309.79,"id":3622149}]}]}
{"op":"mcm","clk":"1009750325","pt":1580669030442,"mc":[{"id":"1.168230758","rc":[{"batb":[[0,1.47,340.35],[1,1.46,433.84],[2,1.34,128.72]],"batl":[[0,1.52,632.48],[1,1.53,351.83],[2,1.82,469.11]],"ltp":1.49,"tv":309.79,"id":3622149}]}]}
{"op":"mcm","clk":"1009750775","pt":1580669034647,"mc":[{"id":"1.168230758","rc":[{"batb":[[0,1.34,128.72],[1,1.01,20.51],[2,1.34,0]],"batl":[[0,1.82,469.11],[1,1.53,0],[2,1.82,0]],"ltp":1.49,"tv":309.79,"id":3622149}]}]}
{"op":"mcm","clk":"1009751074","pt":1580669037537,"mc":[{"id":"1.168230758","rc":[{"batb":[[0,1.36,550.53],[1,1.35,620.74],[2,1.34,128.72]],"batl":[[0,1.61,396.33],[1,1.62,286.34],[2,1.82,469.11]],"ltp":1.49,"tv":309.79,"id":3622149}]}]}
{"op":"mcm","clk":"1009751468","pt":1580669041516,"mc":[{"id":"1.168230758","rc":[{"batl":[[0,1.82,469.11],[1,1.62,0],[2,1.82,0]],"ltp":1.49,"tv":309.79,"id":3622149}]}]}
{"op":"mcm","clk":"1009751672","pt":1580669043531,"mc":[{"id":"1.168230758","rc":[{"batl":[[0,1.4,598.23],[1,1.41,490.8],[2,1.42,573.01]],"ltp":1.49,"tv":309.79,"id":3622149}]}]}
{"op":"mcm","clk":"1009751796","pt":1580669044534,"mc":[{"id":"1.168230758","rc":[{"batb":[[0,3.55,31.47],[1,3,46.66],[2,1.01,20.51]],"ltp":1.9,"tv":221.15,"id":2263603}]}]}
{"op":"mcm","clk":"1009752013","pt":1580669046625,"mc":[{"id":"1.168230758","rc":[{"batl":[[0,5.5,115.06]],"ltp":1.9,"tv":221.15,"id":2263603},{"batl":[[2,1.71,542.06]],"ltp":1.49,"tv":309.79,"id":3622149}]}]}
{"op":"mcm","clk":"1009753324","pt":1580669058648,"mc":[{"id":"1.168230758","rc":[{"batb":[[0,3,46.66],[1,1.01,20.51],[2,1.01,0]],"ltp":1.9,"tv":221.15,"id":2263603},{"batb":[[0,1.27,167.2],[1,1.01,20.51],[2,1.34,0]],"batl":[[0,1.71,542.06],[1,1.41,0],[2,1.71,0]],"ltp":1.49,"tv":309.79,"id":3622149}]}]}
{"op":"mcm","clk":"1009753622","pt":1580669061455,"mc":[{"id":"1.168230758","rc":[{"batb":[[0,3.05,46.11]],"ltp":1.9,"tv":221.15,"id":2263603},{"batb":[[0,1.29,437.63],[1,1.28,818.66],[2,1.27,167.2]],"batl":[[0,1.5,624.7],[1,1.51,370.52],[2,1.71,542.06]],"ltp":1.49,"tv":309.79,"id":3622149}]}]}
{"op":"mcm","clk":"1009753965","pt":1580669065279,"mc":[{"id":"1.168230758","rc":[{"batl":[[0,1.71,542.06],[1,1.51,0],[2,1.71,0]],"ltp":1.49,"tv":309.79,"id":3622149}]}]}
{"op":"mcm","clk":"1009754240","pt":1580669068620,"mc":[{"id":"1.168230758","rc":[{"batb":[[0,4.1,43.75],[1,3.55,30.69],[2,3.05,46.11]],"ltp":1.9,"tv":221.15,"id":2263603},{"batl":[[0,1.32,619.35],[1,1.33,644.03],[2,1.34,573.01]],"ltp":1.49,"tv":309.79,"id":3622149}]}]}
{"op":"mcm","clk":"1009754320","pt":1580669069561,"mc":[{"id":"1.168230758","rc":[{"batb":[[2,1.01,20.51]],"ltp":1.9,"tv":221.15,"id":2263603}]}]}
{"op":"mcm","clk":"1009754534","pt":1580669071554,"mc":[{"id":"1.168230758","rc":[{"batl":[[0,6.6,98.95]],"ltp":1.9,"tv":221.15,"id":2263603},{"batl":[[2,1.62,614.4]],"ltp":1.49,"tv":309.79,"id":3622149}]}]}
{"op":"mcm","clk":"1009754834","pt":1580669075170,"mc":[{"id":"1.168230758","rc":[{"trd":[[1.29,17.86]],"batb":[[0,1.29,428.7]],"ltp":1.29,"tv":327.65,"id":3622149}],"tv":548.8}]}
{"op":"mcm","clk":"1009755232","pt":1580669079553,"mc":[{"id":"1.168230758","rc":[{"batb":[[0,3.55,30.69],[1,1.01,20.51],[2,1.01,0]],"ltp":1.9,"tv":221.15,"id":2263603},{"batb":[[0,1.22,212.44],[1,1.01,20.51],[2,1.27,0]],"batl":[[0,1.62,614.4],[1,1.33,0],[2,1.62,0]],"ltp":1.29,"tv":327.65,"id":3622149}]}]}
{"op":"mcm","clk":"1009755488","pt":1580669082462,"mc":[{"id":"1.168230758","rc":[{"batb":[[0,1.24,481.47],[1,1.23,1039.79],[2,1.22,212.44]],"batl":[[0,1.39,684.16],[1,1.4,505.98],[2,1.62,614.4]],"ltp":1.29,"tv":327.65,"id":3622149}]}]}
{"op":"mcm","clk":"1009755924","pt":1580669087402,"mc":[{"id":"1.168230758","rc":[{"trd":[[3.55,0.05]],"batb":[[0,3.55,30.66]],"ltp":3.55,"tv":221.19,"id":2263603},{"batb":[[0,1.22,212.44],[1,1.01,20.51],[2,1.22,0]],"ltp":1.29,"tv":327.65,"id":3622149}],"tv":548.85}]}
{"op":"mcm","clk":"1009756197","pt":1580669090559,"mc":[{"id":"1.168230758","rc":[{"batb":[[1,3,48.07],[2,1.01,20.51]],"ltp":3.55,"tv":221.19,"id":2263603},{"batb":[[0,1.35,459.66],[1,1.34,644.56],[2,1.33,131.24]],"ltp":1.29,"tv":327.65,"id":3622149}]}]}
{"op":"mcm","clk":"1009756461","pt":1580669093595,"mc":[{"id":"1.168230758","rc":[{"batl":[[0,5.5,115.06]],"ltp":3.55,"tv":221.19,"id":2263603}]}]}
{"op":"mcm","clk":"1009757589","pt":1580669106597,"mc":[{"id":"1.168230758","rc":[{"batb":[[0,3,48.07],[1,1.01,20.51],[2,1.01,0]],"ltp":3.55,"tv":221.19,"id":2263603},{"batb":[[0,1.26,178.53],[1,1.01,20.51],[2,1.33,0]],"batl":[[0,1.62,614.4],[1,1.4,0],[2,1.62,0]],"ltp":1.29,"tv":327.65,"id":3622149}]}]}
{"op":"mcm","clk":"1009757862","pt":1580669109607,"mc":[{"id":"1.168230758","rc":[{"batb":[[0,3,47.6]],"ltp":3.55,"tv":221.19,"id":2263603},{"batb":[[0,1.27,419.14],[1,1.26,897.54],[2,1.25,179.71]],"batl":[[0,1.5,516.75],[1,1.51,371.97],[2,1.62,614.4]],"ltp":1.29,"tv":327.65,"id":3622149}]}]}
{"op":"mcm","clk":"1009758496","pt":1580669117423,"mc":[{"id":"1.168230758","rc":[{"batb":[[0,1.25,179.71],[1,1.01,20.51],[2,1.25,0]],"ltp":1.29,"tv":327.65,"id":3622149}]}]}
{"op":"mcm","clk":"1009758672","pt":1580669119517,"mc":[{"id":"1.168230758","rc":[{"batl":[[2,1.62,0]],"ltp":1.29,"tv":327.65,"id":3622149}]}]}
{"op":"mcm","clk":"1009758771","pt":1580669120617,"mc":[{"id":"1.168230758","rc":[{"batb":[[0,1.45,569.98],[1,1.44,463.21],[2,1.41,1397.59]],"ltp":1.29,"tv":327.65,"id":3622149}]}]}
{"op":"mcm","clk":"1009758861","pt":1580669121509,"mc":[{"id":"1.168230758","rc":[{"batb":[[1,2.46,31.87],[2,1.01,20.51]],"ltp":3.55,"tv":221.19,"id":2263603},{"batb":[[2,1.43,94.18]],"ltp":1.29,"tv":327.65,"id":3622149}]}]}
{"op":"mcm","clk":"1009759046","pt":1580669123591,"mc":[{"id":"1.168230758","rc":[{"batl":[[0,4.6,136.05]],"ltp":3.55,"tv":221.19,"id":2263603},{"batl":[[2,1.82,469.11]],"ltp":1.29,"tv":327.65,"id":3622149}]}]}
{"op":"mcm","clk":"1009760278","pt":1580669137615,"mc":[{"id":"1.168230758","rc":[{"batb":[[0,2.46,31.87],[1,1.01,20.51],[2,1.01,0]],"ltp":3.55,"tv":221.19,"id":2263603},{"batb":[[0,1.31,140.53],[1,1.01,20.51],[2,1.43,0]],"batl":[[0,1.82,469.11],[1,1.51,0],[2,1.82,0]],"ltp":1.29,"tv":327.65,"id":3622149}]}]}
{"op":"mcm","clk":"1009760427","pt":1580669139635,"mc":[{"id":"1.168230758","rc":[{"batb":[[0,1.32,945.34],[1,1.31,872.37],[2,1.01,20.51]],"batl":[[0,1.68,339.85],[1,1.7,489.17],[2,1.82,469.11]],"ltp":1.29,"tv":327.65,"id":3622149}]}]}
{"op":"mcm","clk":"1009760661","pt":1580669142253,"mc":[{"id":"1.168230758","rc":[{"batl":[[0,1.82,469.11],[1,1.7,0],[2,1.82,0]],"ltp":1.29,"tv":327.65,"id":3622149}]}]}
{"op":"mcm","clk":"1009760952","pt":1580669145524,"mc":[{"id":"1.168230758","rc":[{"batb":[[0,3.7,27.93],[1,3,48.15],[2,2.46,31.87]],"ltp":3.55,"tv":221.19,"id":2263603},{"batb":[[2,1.22,211.65]],"batl":[[0,1.36,532.3],[1,1.37,561.35],[2,1.41,573.01]],"ltp":1.29,"tv":327.65,"id":3622149}]}]}
{"op":"mcm","clk":"1009761060","pt":1580669146632,"mc":[{"id":"1.168230758","rc":[{"batb":[[2,1.01,20.51]],"ltp":3.55,"tv":221.19,"id":2263603},{"batl":[[2,1.39,2194.86]],"ltp":1.29,"tv":327.65,"id":3622149}]}]}
{"op":"mcm","clk":"1009761217","pt":1580669148546,"mc":[{"id":"1.168230758","rc":[{"batl":[[0,6,106.18]],"ltp":3.55,"tv":221.19,"id":2263603}]}]}
{"op":"mcm","clk":"1009762273","pt":1580669161479,"mc":[{"id":"1.168230758","rc":[{"batb":[[0,3,48.15],[1,1.01,20.51],[2,1.01,0]],"ltp":3.55,"tv":221.19,"id":2263603},{"batb":[[0,1.22,211.65],[1,1.01,20.51],[2,1.22,0]],"batl":[[0,1.66,579.81],[1,1.37,0],[2,1.39,0]],"ltp":1.29,"tv":327.65,"id":3622149}]}]}
{"op":"mcm","clk":"1009762541","pt":1580669164565,"mc":[{"id":"1.168230758","rc":[{"batb":[[0,1.23,520.55],[1,1.22,1311.51],[2,1.01,20.51]],"batl":[[0,1.5,482.62],[1,1.51,372.29],[2,1.66,579.81]],"ltp":1.29,"tv":327.65,"id":3622149}]}]}
{"op":"mcm","clk":"1009764175","pt":1580669183364,"mc":[{"id":"1.168230758","rc":[{"batb":[[0,1.22,211.65],[1,1.01,20.51],[2,1.01,0]],"ltp":1.29,"tv":327.65,"id":3622149}]}]}
{"op":"mcm","clk":"1009764222","pt":1580669183990,"mc":[{"id":"1.168230758","rc":[{"batb":[[0,1.01,20.51],[1,1.01,0]],"ltp":3.55,"tv":221.19,"id":2263603}]}]}
{"op":"mcm","clk":"1009764366","pt":1580669185614,"mc":[{"id":"1.168230758","rc":[{"batl":[[2,1.66,0]],"ltp":1.29,"tv":327.65,"id":3622149}]}]}
{"op":"mcm","clk":"1009764444","pt":1580669186383,"mc":[{"id":"1.168230758","rc":[{"batb":[[0,1.45,607.09],[1,1.44,463.61],[2,1.39,1469.26]],"ltp":1.29,"tv":327.65,"id":3622149}]}]}
{"op":"mcm","clk":"1009764518","pt":1580669187166,"mc":[{"id":"1.168230758","rc":[{"batb":[[0,2.98,48.23],[1,2.46,32.42],[2,1.01,20.51]],"ltp":3.55,"tv":221.19,"id":2263603},{"batb":[[2,1.43,93.08]],"ltp":1.29,"tv":327.65,"id":3622149}]}]}
{"op":"mcm","clk":"1009764731","pt":1580669189558,"mc":[{"id":"1.168230758","rc":[{"batl":[[0,4.6,136.05]],"ltp":3.55,"tv":221.19,"id":2263603},{"batl":[[2,1.82,469.11]],"ltp":1.29,"tv":327.65,"id":3622149}]}]}
{"op":"mcm","clk":"1009766386","pt":1580669208621,"mc":[{"id":"1.168230758","rc":[{"trd":[[1.5,7.58]],"batl":[[0,1.5,478.83]],"ltp":1.5,"tv":335.23,"id":3622149}],"tv":556.43}]}
{"op":"mcm","clk":"1009766573","pt":1580669210610,"mc":[{"id":"1.168230758","rc":[{"batb":[[0,2.46,32.42],[1,1.01,20.51],[2,1.01,0]],"ltp":3.55,"tv":221.19,"id":2263603},{"batb":[[0,1.31,139.42],[1,1.01,20.51],[2,1.43,0]],"batl":[[0,1.82,469.11],[1,1.51,0],[2,1.82,0]],"ltp":1.5,"tv":335.23,"id":3622149}]}]}
{"op":"mcm","clk":"1009766807","pt":1580669213475,"mc":[{"id":"1.168230758","rc":[{"batb":[[0,1.32,1015.43],[1,1.31,872.13],[2,1.01,20.51]],"batl":[[0,1.68,294.58],[1,1.7,489.44],[2,1.82,469.11]],"ltp":1.5,"tv":335.23,"id":3622149}]}]}
{"op":"mcm","clk":"1009766847","pt":1580669213996,"mc":[{"id":"1.168230758","rc":[{"batb":[[0,2.44,32.5]],"ltp":3.55,"tv":221.19,"id":2263603},{"batb":[[1,1.31,871.98]],"ltp":1.5,"tv":335.23,"id":3622149}]}]}
{"op":"mcm","clk":"1009767501","pt":1580669221526,"mc":[{"id":"1.168230758","rc":[{"batb":[[0,1.31,139.27],[1,1.01,20.51],[2,1.01,0]],"ltp":1.5,"tv":335.23,"id":3622149}]}]}
{"op":"mcm","clk":"1009767701","pt":1580669223602,"mc":[{"id":"1.168230758","rc":[{"batl":[[2,1.82,0]],"ltp":1.5,"tv":335.23,"id":3622149}]}]}
{"op":"mcm","clk":"1009767810","pt":1580669224598,"mc":[{"id":"1.168230758","rc":[{"batb":[[1,2.04,54.68],[2,1.01,20.51]],"ltp":3.55,"tv":221.19,"id":2263603},{"batb":[[0,1.62,454.5],[1,1.61,356.93],[2,1.56,1023.23]],"ltp":1.5,"tv":335.23,"id":3622149}]}]}
{"op":"mcm","clk":"1009767912","pt":1580669225912,"mc":[{"id":"1.168230758","rc":[{"batl":[[0,3.65,170.41]],"ltp":3.55,"tv":221.19,"id":2263603},{"batl":[[2,2.04,383.01]],"ltp":1.5,"tv":335.23,"id":3622149}]}]}
{"op":"mcm","clk":"1009768035","pt":1580669227419,"mc":[{"id":"1.168230758","rc":[{"batb":[[2,1.44,92.29]],"ltp":1.5,"tv":335.23,"id":3622149}]}]}
{"op":"mcm","clk":"1009768276","pt":1580669230397,"mc":[{"id":"1.168230758","rc":[{"batl":[[0,2.04,383.01],[1,1.7,0],[2,2.04,0]],"ltp":1.5,"tv":335.23,"id":3622149}]}]}
{"op":"mcm","clk":"1009768477","pt":1580669233106,"mc":[{"id":"1.168230758","rc":[{"batl":[[0,1.69,485.6],[1,1.71,478.38],[2,2.04,383.01]],"ltp":1.5,"tv":335.23,"id":3622149}]}]}
{"op":"mcm","clk":"1009768841","pt":1580669237640,"mc":[{"id":"1.168230758","rc":[{"batb":[[0,1.61,59.88],[1,1.44,92.29],[2,1.01,20.51]],"batl":[[0,2.04,383.01],[1,1.71,0],[2,2.04,0]],"ltp":1.5,"tv":335.23,"id":3622149}]}]}
{"op":"mcm","clk":"1009768924","pt":1580669238637,"mc":[{"id":"1.168230758","rc":[{"batb":[[0,2.04,54.68],[1,1.01,20.51],[2,1.01,0]],"ltp":3.55,"tv":221.19,"id":2263603},{"batb":[[0,1.44,92.29],[1,1.01,20.51],[2,1.01,0]],"ltp":1.5,"tv":335.23,"id":3622149}]}]}
{"op":"mcm","clk":"1009768991","pt":1580669239520,"mc":[{"id":"1.168230758","rc":[{"batl":[[0,2.46,252.06],[1,3.65,170.41]],"ltp":3.55,"tv":221.19,"id":2263603}]}]}
{"op":"mcm","clk":"1009769145","pt":1580669241622,"mc":[{"id":"1.168230758","rc":[{"batl":[[0,3.65,170.41],[1,3.65,0]],"ltp":3.55,"tv":221.19,"id":2263603},{"batb":[[0,1.45,719.85],[1,1.44,556.27],[2,1.01,20.51]],"batl":[[0,1.93,235.4],[1,1.95,316.43],[2,2.04,383.01]],"ltp":1.5,"tv":335.23,"id":3622149}]}]}
{"op":"mcm","clk":"1009770235","pt":1580669255339,"mc":[{"id":"1.168230758","rc":[{"batb":[[0,1.44,92.29],[1,1.01,20.51],[2,1.01,0]],"ltp":1.5,"tv":335.23,"id":3622149}]}]}
{"op":"mcm","clk":"1009770528","pt":1580669258554,"mc":[{"id":"1.168230758","rc":[{"batb":[[0,1.78,734.62],[1,1.44,92.29],[2,1.01,20.51]],"ltp":1.5,"tv":335.23,"id":3622149}]}]}
{"op":"mcm","clk":"1009770618","pt":1580669259342,"mc":[{"id":"1.168230758","rc":[{"batb":[[1,1.88,35.49],[2,1.01,20.51]],"ltp":3.55,"tv":221.19,"id":2263603},{"batb":[[0,1.85,37.22],[1,1.78,734.62],[2,1.67,52.56]],"ltp":1.5,"tv":335.23,"id":3622149}]}]}
{"op":"mcm","clk":"1009770811","pt":1580669261439,"mc":[{"id":"1.168230758","rc":[{"batl":[[0,3,213.45]],"ltp":3.55,"tv":221.19,"id":2263603},{"batb":[[0,1.86,297.78],[1,1.85,37.22],[2,1.84,373]],"batl":[[0,1.94,298],[1,1.96,311.34],[2,2.3,309.75]],"ltp":1.5,"tv":335.23,"id":3622149}]}]}
{"op":"mcm","clk":"1009771358","pt":1580669267363,"mc":[{"id":"1.168230758","rc":[{"batb":[[0,2.02,55.86],[1,1.86,36.19]],"ltp":3.55,"tv":221.19,"id":2263603},{"batb":[[0,1.86,334.29],[1,1.84,373],[2,1.68,51.54]],"ltp":1.5,"tv":335.23,"id":3622149}]}]}
{"op":"mcm","clk":"1009772900","pt":1580669283549,"mc":[{"id":"1.168230758","rc":[{"trd":[[2.06,3]],"ltp":2.06,"tv":224.19,"id":2263603},{"trd":[[1.94,3.19]],"batl":[[0,1.94,294.81]],"ltp":1.94,"tv":338.42,"id":3622149}],"tv":562.62}]}
{"op":"mcm","clk":"1009772980","pt":1580669284588,"mc":[{"id":"1.168230758","rc":[{"batb":[[0,1.86,334.13],[2,1.68,51.38]],"ltp":1.94,"tv":338.42,"id":3622149}]}]}
{"op":"mcm","clk":"1009773058","pt":1580669285580,"mc":[{"id":"1.168230758","rc":[{"trd":[[1.94,171.23]],"batl":[[0,1.94,210.79]],"ltp":1.94,"tv":506.46,"id":3622149}],"tv":730.65}]}
{"op":"mcm","clk":"1009773341","pt":1580669288465,"mc":[{"id":"1.168230758","rc":[{"batb":[[0,1.86,390.69]],"ltp":1.94,"tv":506.46,"id":3622149}]}]}
{"op":"mcm","clk":"1009774227","pt":1580669297368,"mc":[{"id":"1.168230758","rc":[{"trd":[[2.06,6.86]],"ltp":2.06,"tv":228.06,"id":2263603},{"trd":[[1.94,175.33]],"batl":[[0,1.94,206.69]],"ltp":1.94,"tv":510.56,"id":3622149}],"tv":738.62}]}
{"op":"mcm","clk":"1009774745","pt":1580669303398,"mc":[{"id":"1.168230758","rc":[{"trd":[[2.06,18.22]],"ltp":2.06,"tv":239.42,"id":2263603},{"trd":[[1.94,187.39]],"batl":[[0,1.94,194.63]],"ltp":1.94,"tv":522.62,"id":3622149}],"tv":762.04}]}
{"op":"mcm","clk":"1009775135","pt":1580669308092,"mc":[{"id":"1.168230758","rc":[{"batb":[[0,1.86,36.35],[1,1.68,51.38],[2,1.01,20.51]],"batl":[[0,2.3,309.75],[1,1.96,0],[2,2.3,0]],"ltp":1.94,"tv":522.62,"id":3622149}]}]}
{"op":"mcm","clk":"1009775266","pt":1580669309527,"mc":[{"id":"1.168230758","rc":[{"batl":[[0,2.06,4.2],[1,3,213.45]],"ltp":2.06,"tv":239.42,"id":2263603}]}]}
{"op":"mcm","clk":"1009775419","pt":1580669311018,"mc":[{"id":"1.168230758","rc":[{"batb":[[0,1.87,270.74],[1,1.86,36.35],[2,1.85,366.36]],"batl":[[0,1.95,305.61],[1,1.97,306.45],[2,2.3,309.75]],"ltp":1.94,"tv":522.62,"id":3622149}]}]}
{"op":"mcm","clk":"1009775929","pt":1580669316593,"mc":[{"id":"1.168230758","rc":[{"batl":[[1,2.1,11.36],[2,3,213.45]],"ltp":2.06,"tv":239.42,"id":2263603}]}]}
{"op":"mcm","clk":"1009777075","pt":1580669328876,"mc":[{"id":"1.168230758","rc":[{"batl":[[1,3,213.45],[2,3,0]],"ltp":2.06,"tv":239.42,"id":2263603}]}]}
{"op":"mcm","clk":"1009777385","pt":1580669331977,"mc":[{"id":"1.168230758","rc":[{"trd":[[2.04,11.36]],"ltp":2.04,"tv":250.77,"id":2263603},{"trd":[[1.95,11.88]],"batl":[[0,1.95,293.73]],"ltp":1.95,"tv":534.5,"id":3622149}],"tv":785.28}]}
{"op":"mcm","clk":"1009778191","pt":1580669340305,"mc":[{"id":"1.168230758","rc":[{"batb":[[0,1.86,36.19],[1,1.01,20.51],[2,1.01,0]],"ltp":2.04,"tv":250.77,"id":2263603},{"batb":[[0,1.68,51.38],[1,1.01,20.51],[2,1.85,0]],"batl":[[0,2.3,309.75],[1,1.97,0],[2,2.3,0]],"ltp":1.95,"tv":534.5,"id":3622149}]}]}
{"op":"mcm","clk":"1009778531","pt":1580669343394,"mc":[{"id":"1.168230758","rc":[{"batb":[[0,1.69,348.66],[1,1.68,51.38],[2,1.67,516.17]],"batl":[[0,2.16,278.26],[1,2.18,228.73],[2,2.3,309.75]],"ltp":1.95,"tv":534.5,"id":3622149}]}]}
{"op":"mcm","clk":"1009778941","pt":1580669347584,"mc":[{"id":"1.168230758","rc":[{"batb":[[0,1.68,51.38],[1,1.01,20.51],[2,1.67,0]],"batl":[[0,2.3,309.75],[1,2.18,0],[2,2.3,0]],"ltp":1.95,"tv":534.5,"id":3622149}]}]}
{"op":"mcm","clk":"1009779258","pt":1580669350590,"mc":[{"id":"1.168230758","rc":[{"batb":[[0,1.86,397.01],[1,1.84,373.21],[2,1.01,20.51]],"batl":[[0,1.94,238.82],[1,1.96,311.74],[2,2.06,4.2]],"ltp":2.04,"tv":250.77,"id":2263603},{"batb":[[0,1.99,578.79],[1,1.68,51.38],[2,1.01,20.51]],"ltp":1.95,"tv":534.5,"id":3622149}]}]}
{"op":"mcm","clk":"1009779356","pt":1580669351474,"mc":[{"id":"1.168230758","rc":[{"batb":[[2,1.72,47.45]],"ltp":2.04,"tv":250.77,"id":2263603},{"batb":[[0,2.02,56.18],[1,1.99,578.79],[2,1.84,37.92]],"ltp":1.95,"tv":534.5,"id":3622149}]}]}
{"op":"mcm","clk":"1009779564","pt":1580669353414,"mc":[{"id":"1.168230758","rc":[{"batb":[[1,1.84,37.92],[2,1.01,20.51]],"batl":[[0,2.6,257.57]],"ltp":1.95,"tv":534.5,"id":3622149}]}]}
{"op":"mcm","clk":"1009779994","pt":1580669357614,"mc":[{"id":"1.168230758","rc":[{"trd":[[1.94,7.6]],"batl":[[0,1.94,235.02]],"ltp":1.94,"tv":258.37,"id":2263603}],"tv":792.87}]}
{"op":"mcm","clk":"1009780293","pt":1580669360594,"mc":[{"id":"1.168230758","rc":[{"trd":[[1.94,134.14]],"batb":[[0,1.72,47.45],[1,1.01,20.51],[2,1.72,0]],"batl":[[0,2.06,4.2],[1,2.6,257.57],[2,2.06,0]],"ltp":1.94,"tv":384.91,"id":2263603},{"batb":[[0,1.84,37.92],[1,1.01,20.51],[2,1.01,0]],"ltp":1.95,"tv":534.5,"id":3622149}],"tv":919.41}]}
{"op":"mcm","clk":"1009780627","pt":1580669363637,"mc":[{"id":"1.168230758","rc":[{"batb":[[0,1.72,378.5],[1,1.7,486.67],[2,1.01,20.51]],"batl":[[1,2.18,386.82],[2,2.2,222.85]],"ltp":1.94,"tv":384.91,"id":2263603}]}]}
{"op":"mcm","clk":"1009782997","pt":1580669388344,"mc":[{"id":"1.168230758","rc":[{"batb":[[0,1.72,47.45],[1,1.01,20.51],[2,1.01,0]],"batl":[[1,2.6,257.57],[2,2.2,0]],"ltp":1.94,"tv":384.91,"id":2263603}]}]}
{"op":"mcm","clk":"1009783307","pt":1580669391639,"mc":[{"id":"1.168230758","rc":[{"trd":[[2.06,22.42]],"batb":[[0,2.06,53.58],[1,1.85,36.82],[2,1.72,47.45]],"ltp":2.06,"tv":389.11,"id":2263603},{"trd":[[1.94,191.85]],"batb":[[0,1.85,390.12],[1,1.84,37.92],[2,1.83,379.55]],"batl":[[0,1.93,222.63],[1,1.95,316.02],[2,2,573.01]],"ltp":1.94,"tv":538.96,"id":3622149}],"tv":928.07}]}
{"op":"mcm","clk":"1009783347","pt":1580669392057,"mc":[{"id":"1.168230758","rc":[{"batb":[[2,1.01,20.51]],"ltp":2.06,"tv":389.11,"id":2263603}]}]}
{"op":"mcm","clk":"1009783535","pt":1580669394146,"mc":[{"id":"1.168230758","rc":[{"batl":[[2,2,0]],"ltp":1.94,"tv":538.96,"id":3622149}]}]}
{"op":"mcm","clk":"1009783623","pt":1580669394937,"mc":[{"id":"1.168230758","rc":[{"batl":[[0,2.92,221.26]],"ltp":2.06,"tv":389.11,"id":2263603},{"batl":[[2,2.36,299.17]],"ltp":1.94,"tv":538.96,"id":3622149}]}]}
{"op":"mcm","clk":"1009784204","pt":1580669401541,"mc":[{"id":"1.168230758","rc":[{"batb":[[0,1.85,36.82],[1,1.01,20.51],[2,1.01,0]],"ltp":2.06,"tv":389.11,"id":2263603},{"batb":[[0,1.63,56.73],[1,1.01,20.51],[2,1.83,0]],"batl":[[0,2.36,299.17],[1,1.95,0],[2,2.36,0]],"ltp":1.94,"tv":538.96,"id":3622149}]}]}
{"op":"mcm","clk":"1009784488","pt":1580669404559,"mc":[{"id":"1.168230758","rc":[{"batb":[[0,1.65,372.57],[1,1.64,277.04],[2,1.63,56.73]],"batl":[[0,2.18,305.69],[1,2.2,222.98],[2,2.36,299.17]],"ltp":1.94,"tv":538.96,"id":3622149}]}]}
{"op":"mcm","clk":"1009784660","pt":1580669406457,"mc":[{"id":"1.168230758","rc":[{"batb":[[0,1.63,56.73],[1,1.01,20.51],[2,1.63,0]],"batl":[[0,2.36,299.17],[1,2.2,0],[2,2.36,0]],"ltp":1.94,"tv":538.96,"id":3622149}]}]}
{"op":"mcm","clk":"1009784958","pt":1580669409451,"mc":[{"id":"1.168230758","rc":[{"batb":[[0,1.85,349.8],[1,1.83,379.81],[2,1.01,20.51]],"batl":[[0,1.93,302.69],[1,1.95,316.55]],"ltp":2.06,"tv":389.11,"id":2263603},{"batb":[[0,1.95,603.17],[1,1.63,56.73],[2,1.01,20.51]],"ltp":1.94,"tv":538.96,"id":3622149}]}]}
{"op":"mcm","clk":"1009785047","pt":1580669410452,"mc":[{"id":"1.168230758","rc":[{"batb":[[2,1.7,49.49]],"ltp":2.06,"tv":389.11,"id":2263603},{"batb":[[0,2.04,55.23],[1,1.95,603.17],[2,1.81,39.5]],"ltp":1.94,"tv":538.96,"id":3622149}]}]}
{"op":"mcm","clk":"1009785222","pt":1580669412485,"mc":[{"id":"1.168230758","rc":[{"batl":[[2,2.6,257.57]],"ltp":2.06,"tv":389.11,"id":2263603},{"batb":[[1,1.81,39.5],[2,1.01,20.51]],"batl":[[0,2.6,257.57]],"ltp":1.94,"tv":538.96,"id":3622149}]}]}
{"op":"mcm","clk":"1009785872","pt":1580669418483,"mc":[{"id":"1.168230758","rc":[{"batb":[[0,1.7,49.33],[1,1.01,20.51],[2,1.7,0]],"batl":[[0,2.6,257.57],[1,1.95,0],[2,2.6,0]],"ltp":2.06,"tv":389.11,"id":2263603},{"batb":[[0,1.81,39.5],[1,1.01,20.51],[2,1.01,0]],"ltp":1.94,"tv":538.96,"id":3622149}]}]}
{"op":"mcm","clk":"1009786223","pt":1580669421463,"mc":[{"id":"1.168230758","rc":[{"batb":[[1,1.69,297.17],[2,1.67,517.87]],"batl":[[0,2.2,359.93],[1,2.22,217.25],[2,2.6,257.57]],"ltp":2.06,"tv":389.11,"id":2263603}]}]}
{"op":"mcm","clk":"1009786355","pt":1580669422490,"mc":[{"id":"1.168230758","rc":[{"batb":[[1,1.01,20.51],[2,1.67,0]],"batl":[[0,2.6,257.57],[1,2.22,0],[2,2.6,0]],"ltp":2.06,"tv":389.11,"id":2263603}]}]}
{"op":"mcm","clk":"1009786705","pt":1580669425494,"mc":[{"id":"1.168230758","rc":[{"batb":[[0,1.89,358.73],[1,1.87,354.24],[2,1.7,49.33]],"batl":[[0,1.98,338.41],[1,2,293.36],[2,2.6,257.57]],"ltp":2.06,"tv":389.11,"id":2263603}]}]}
{"op":"mcm","clk":"1009786843","pt":1580669426868,"mc":[{"id":"1.168230758","rc":[{"trd":[[1.89,559.56]],"batb":[[0,1.7,49.33],[1,1.01,20.51],[2,1.7,0]],"batl":[[0,2.6,257.57],[1,2,0],[2,2.6,0]],"ltp":1.89,"tv":948.68,"id":2263603}],"tv":1487.64}]}
{"op":"mcm","clk":"1009787136","pt":1580669429563,"mc":[{"id":"1.168230758","rc":[{"batb":[[1,1.69,297.17],[2,1.67,517.87]],"batl":[[0,2.2,359.93],[1,2.22,217.25],[2,2.6,257.57]],"ltp":1.89,"tv":948.68,"id":2263603},{"batl":[[0,2.5,274.54]],"ltp":1.94,"tv":538.96,"id":3622149}]}]}
{"op":"mcm","clk":"1009787207","pt":1580669430464,"mc":[{"id":"1.168230758","rc":[{"batb":[[1,1.68,465.78],[2,1.67,261.06]],"batl":[[0,2.18,206.28],[1,2.2,222.58]],"ltp":1.89,"tv":948.68,"id":2263603}]}]}
{"op":"mcm","clk":"1009787997","pt":1580669438584,"mc":[{"id":"1.168230758","rc":[{"batl":[[0,2.6,257.57],[1,2.2,0],[2,2.6,0]],"ltp":1.89,"tv":948.68,"id":2263603}]}]}
{"op":"mcm","clk":"1009788299","pt":1580669441609,"mc":[{"id":"1.168230758","rc":[{"batl":[[0,1.75,354.64],[1,1.77,429.34]],"ltp":1.89,"tv":948.68,"id":2263603},{"batb":[[0,2.22,469.68],[1,1.81,39.5],[2,1.01,20.51]],"ltp":1.94,"tv":538.96,"id":3622149}]}]}
{"op":"mcm","clk":"1009788379","pt":1580669442292,"mc":[{"id":"1.168230758","rc":[{"batb":[[0,2.26,40.44],[1,2.22,469.68],[2,2.06,52.8]],"ltp":1.94,"tv":538.96,"id":3622149}]}]}
{"op":"mcm","clk":"1009788599","pt":1580669444592,"mc":[{"id":"1.168230758","rc":[{"batl":[[2,2.36,299.17]],"ltp":1.89,"tv":948.68,"id":2263603},{"batb":[[1,2.06,52.8],[2,1.01,20.51]],"batl":[[0,2.92,221.26]],"ltp":1.94,"tv":538.96,"id":3622149}]}]}
{"op":"mcm","clk":"1009789243","pt":1580669451628,"mc":[{"id":"1.168230758","rc":[{"batb":[[1,1.61,58.93],[2,1.01,20.51]],"batl":[[0,2.36,299.17],[1,1.77,0],[2,2.36,0]],"ltp":1.89,"tv":948.68,"id":2263603}]}]}
{"op":"mcm","clk":"1009789297","pt":1580669452114,"mc":[{"id":"1.168230758","rc":[{"batb":[[0,1.61,58.93],[1,1.01,20.51],[2,1.01,0]],"ltp":1.89,"tv":948.68,"id":2263603},{"batb":[[0,2.06,52.8],[1,1.01,20.51],[2,1.01,0]],"ltp":1.94,"tv":538.96,"id":3622149}]}]}
{"op":"mcm","clk":"1009789534","pt":1580669454518,"mc":[{"id":"1.168230758","rc":[{"batb":[[1,1.59,549.58],[2,1.58,321.04]],"batl":[[0,1.88,275.07],[1,1.9,342.86],[2,2.36,299.17]],"ltp":1.89,"tv":948.68,"id":2263603}]}]}
{"op":"mcm","clk":"1009789644","pt":1580669455619,"mc":[{"id":"1.168230758","rc":[{"batb":[[1,1.01,20.51],[2,1.58,0]],"batl":[[0,2.36,299.17],[1,1.9,0],[2,2.36,0]],"ltp":1.89,"tv":948.68,"id":2263603}]}]}
{"op":"mcm","clk":"1009789881","pt":1580669458325,"mc":[{"id":"1.168230758","rc":[{"batb":[[0,1.71,284.19],[1,1.69,496.77],[2,1.61,58.93]],"batl":[[0,1.78,448.24],[1,1.8,406.21],[2,2.36,299.17]],"ltp":1.89,"tv":948.68,"id":2263603}]}]}
{"op":"mcm","clk":"1009790088","pt":1580669460331,"mc":[{"id":"1.168230758","rc":[{"batb":[[0,1.61,58.93],[1,1.01,20.51],[2,1.61,0]],"batl":[[0,2.36,299.17],[1,1.8,0],[2,2.36,0]],"ltp":1.89,"tv":948.68,"id":2263603}]}]}
{"op":"mcm","clk":"1009790388","pt":1580669463420,"mc":[{"id":"1.168230758","rc":[{"batb":[[1,1.59,549.58],[2,1.58,321.04]],"batl":[[0,1.88,275.07],[1,1.9,342.86],[2,2.36,299.17]],"ltp":1.89,"tv":948.68,"id":2263603}]}]}
{"op":"mcm","clk":"1009790603","pt":1580669465450,"mc":[{"id":"1.168230758","rc":[{"batb":[[1,1.01,20.51],[2,1.58,0]],"ltp":1.89,"tv":948.68,"id":2263603}]}]}
{"op":"mcm","clk":"1009790806","pt":1580669467648,"mc":[{"id":"1.168230758","rc":[{"batb":[[0,1.75,764.01],[1,1.61,58.93],[2,1.01,20.51]],"ltp":1.89,"tv":948.68,"id":2263603}]}]}
{"op":"mcm","clk":"1009790914","pt":1580669468540,"mc":[{"id":"1.168230758","rc":[{"batb":[[0,1.83,38.55],[1,1.81,244.09],[2,1.79,408.38]],"ltp":1.89,"tv":948.68,"id":2263603},{"batb":[[1,1.79,40.91],[2,1.01,20.51]],"ltp":1.94,"tv":538.96,"id":3622149}]}]}
{"op":"mcm","clk":"1009791199","pt":1580669471626,"mc":[{"id":"1.168230758","rc":[{"batl":[[0,2.72,241.55]],"ltp":1.94,"tv":538.96,"id":3622149}]}]}
{"op":"mcm","clk":"1009791591","pt":1580669475623,"mc":[{"id":"1.168230758","rc":[{"batb":[[0,1.65,54.05],[1,1.01,20.51],[2,1.79,0]],"batl":[[0,2.36,299.17],[1,1.9,0],[2,2.36,0]],"ltp":1.89,"tv":948.68,"id":2263603},{"batb":[[0,1.79,40.91],[1,1.01,20.51],[2,1.01,0]],"ltp":1.94,"tv":538.96,"id":3622149}]}]}
{"op":"mcm","clk":"1009791910","pt":1580669479221,"mc":[{"id":"1.168230758","rc":[{"batb":[[0,1.64,55.31]],"ltp":1.89,"tv":948.68,"id":2263603},{"batb":[[0,1.81,39.89]],"ltp":1.94,"tv":538.96,"id":3622149}]}]}
{"op":"mcm","clk":"1009792117","pt":1580669481547,"mc":[{"id":"1.168230758","rc":[{"batb":[[0,1.86,254.44],[1,1.84,373.15],[2,1.64,55.31]],"batl":[[0,1.94,340.58],[1,1.96,311.73]],"ltp":1.89,"tv":948.68,"id":2263603}]}]}
{"op":"mcm","clk":"1009792213","pt":1580669482748,"mc":[{"id":"1.168230758","rc":[{"batb":[[0,1.64,55.31],[1,1.01,20.51],[2,1.64,0]],"ltp":1.89,"tv":948.68,"id":2263603}]}]}
{"op":"mcm","clk":"1009792366","pt":1580669484526,"mc":[{"id":"1.168230758","rc":[{"batl":[[0,1.83,9],[1,2.6,257.57]],"ltp":1.89,"tv":948.68,"id":2263603},{"batl":[[0,2.6,257.57]],"ltp":1.94,"tv":538.96,"id":3622149}]}]}
{"op":"mcm","clk":"1009792545","pt":1580669486341,"mc":[{"id":"1.168230758","rc":[{"batb":[[1,1.62,315.14],[2,1.61,298.41]],"batl":[[1,2.2,294.58],[2,2.22,217.13]],"ltp":1.89,"tv":948.68,"id":2263603}]}]}
{"op":"mcm","clk":"1009792746","pt":1580669488631,"mc":[{"id":"1.168230758","rc":[{"batb":[[1,1.01,20.51],[2,1.61,0]],"batl":[[1,2.6,257.57],[2,2.22,0]],"ltp":1.89,"tv":948.68,"id":2263603}]}]}
{"op":"mcm","clk":"1009792900","pt":1580669490354,"mc":[{"id":"1.168230758","rc":[{"trd":[[1.83,2.73]],"batl":[[0,1.83,6.27]],"ltp":1.83,"tv":951.41,"id":2263603},{"trd":[[2.2,2.27]],"ltp":2.2,"tv":541.23,"id":3622149}],"tv":1492.64}]}
{"op":"mcm","clk":"1009793012","pt":1580669491553,"mc":[{"id":"1.168230758","rc":[{"trd":[[1.83,15.27]],"batb":[[0,1.95,596.9],[1,1.64,55.31],[2,1.01,20.51]],"ltp":1.83,"tv":963.94,"id":2263603},{"batl":[[0,2.2,7.49]],"ltp":2.2,"tv":541.23,"id":3622149}],"tv":1505.18}]}
{"op":"mcm","clk":"1009793105","pt":1580669492541,"mc":[{"id":"1.168230758","rc":[{"batb":[[0,2.08,50.83],[1,1.95,596.9],[2,1.83,38.63]],"ltp":1.83,"tv":963.94,"id":2263603},{"batb":[[0,1.83,417.96],[1,1.81,433.24],[2,1.57,65.46]],"batl":[[0,1.91,238.09],[1,1.93,325.94]],"ltp":2.2,"tv":541.23,"id":3622149}]}]}
{"op":"mcm","clk":"1009793204","pt":1580669493634,"mc":[{"id":"1.168230758","rc":[{"batb":[[1,1.83,38.63],[2,1.01,20.51]],"ltp":1.83,"tv":963.94,"id":2263603},{"batl":[[2,1.97,5.3]],"ltp":2.2,"tv":541.23,"id":3622149}]}]}
{"op":"mcm","clk":"1009793250","pt":1580669494154,"mc":[{"id":"1.168230758","rc":[{"batl":[[2,1.97,0]],"ltp":2.2,"tv":541.23,"id":3622149}]}]}
{"op":"mcm","clk":"1009793384","pt":1580669495567,"mc":[{"id":"1.168230758","rc":[{"batl":[[0,3,213.45]],"ltp":1.83,"tv":963.94,"id":2263603},{"batl":[[2,2.3,309.75]],"ltp":2.2,"tv":541.23,"id":3622149}]}]}
{"op":"mcm","clk":"1009793454","pt":1580669496334,"mc":[{"id":"1.168230758","rc":[{"trd":[[2.08,11.02]],"batb":[[0,2.08,45.32]],"ltp":2.08,"tv":974.97,"id":2263603}],"tv":1516.2}]}
{"op":"mcm","clk":"1009793803","pt":1580669500350,"mc":[{"id":"1.168230758","rc":[{"batl":[[0,3,216.18]],"ltp":2.08,"tv":974.97,"id":2263603}]}]}
{"op":"mcm","clk":"1009793894","pt":1580669501345,"mc":[{"id":"1.168230758","rc":[{"batb":[[0,1.81,39.89],[1,1.57,65.46],[2,1.01,20.51]],"batl":[[0,2.3,309.75],[1,1.93,0],[2,2.3,0]],"ltp":2.2,"tv":541.23,"id":3622149}]}]}
{"op":"mcm","clk":"1009793975","pt":1580669502339,"mc":[{"id":"1.168230758","rc":[{"batb":[[0,1.83,38.63],[1,1.01,20.51],[2,1.01,0]],"ltp":2.08,"tv":974.97,"id":2263603},{"batb":[[0,1.57,65.46],[1,1.01,20.51],[2,1.01,0]],"ltp":2.2,"tv":541.23,"id":3622149}]}]}
{"op":"mcm","clk":"1009794163","pt":1580669504635,"mc":[{"id":"1.168230758","rc":[{"batb":[[0,1.58,588.28],[1,1.57,391.65],[2,1.01,20.51]],"batl":[[0,2.24,353.36],[1,2.26,207.08],[2,2.3,309.75]],"ltp":2.2,"tv":541.23,"id":3622149}]}]}
{"op":"mcm","clk":"1009795800","pt":1580669523161,"mc":[{"id":"1.168230758","rc":[{"batl":[[0,2.3,309.75],[1,2.26,0],[2,2.3,0]],"ltp":2.2,"tv":541.23,"id":3622149}]}]}
{"op":"mcm","clk":"1009796044","pt":1580669525560,"mc":[{"id":"1.168230758","rc":[{"batb":[[0,2.3,440.77],[1,1.83,38.63],[2,1.01,20.51]],"ltp":2.08,"tv":974.97,"id":2263603}]}]}
{"op":"mcm","clk":"1009796144","pt":1580669526559,"mc":[{"id":"1.168230758","rc":[{"batb":[[0,2.54,29.19],[1,2.3,440.77],[2,2.1,50.44]],"batl":[[0,3,2.73]],"ltp":2.08,"tv":974.97,"id":2263603},{"batb":[[2,1.36,118.34]],"batl":[[0,1.64,288.72],[1,1.65,268.9]],"ltp":2.2,"tv":541.23,"id":3622149}]}]}
{"op":"mcm","clk":"1009796338","pt":1580669528686,"mc":[{"id":"1.168230758","rc":[{"batb":[[1,2.1,50.44],[2,1.01,20.51]],"ltp":2.08,"tv":974.97,"id":2263603}]}]}
{"op":"mcm","clk":"1009796511","pt":1580669530576,"mc":[{"id":"1.168230758","rc":[{"batl":[[1,3.65,170.41]],"ltp":2.08,"tv":974.97,"id":2263603},{"batl":[[2,2.04,383.01]],"ltp":2.2,"tv":541.23,"id":3622149}]}]}
{"op":"mcm","clk":"1009796694","pt":1580669532593,"mc":[{"id":"1.168230758","rc":[{"batb":[[2,2,128.79]],"ltp":2.08,"tv":974.97,"id":2263603}]}]}
{"op":"mcm","clk":"1009796985","pt":1580669535586,"mc":[{"id":"1.168230758","rc":[{"batb":[[0,2.1,50.2],[1,1.01,20.51],[2,2,0]],"ltp":2.08,"tv":974.97,"id":2263603},{"batb":[[0,1.36,118.34],[1,1.01,20.51],[2,1.36,0]],"batl":[[0,2.04,383.01],[1,1.65,0],[2,2.04,0]],"ltp":2.2,"tv":541.23,"id":3622149}]}]}
{"op":"mcm","clk":"1009797218","pt":1580669538386,"mc":[{"id":"1.168230758","rc":[{"batb":[[0,1.38,524.71],[1,1.37,576.3],[2,1.36,118.34]],"batl":[[0,1.91,335.8],[1,1.93,325.77],[2,2.04,383.01]],"ltp":2.2,"tv":541.23,"id":3622149}]}]}
{"op":"mcm","clk":"1009798035","pt":1580669547487,"mc":[{"id":"1.168230758","rc":[{"batb":[[0,1.36,118.34],[1,1.01,20.51],[2,1.36,0]],"ltp":2.2,"tv":541.23,"id":3622149}]}]}
{"op":"mcm","clk":"1009798297","pt":1580669550398,"mc":[{"id":"1.168230758","rc":[{"batl":[[1,3.65,0]],"ltp":2.08,"tv":974.97,"id":2263603},{"batb":[[0,1.83,315.25],[1,1.81,393.11],[2,1.7,818.59]],"batl":[[2,2.04,0]],"ltp":2.2,"tv":541.23,"id":3622149}]}]}
{"op":"mcm","clk":"1009798385","pt":1580669551391,"mc":[{"id":"1.168230758","rc":[{"batb":[[1,1.84,37.92],[2,1.01,20.51]],"ltp":2.08,"tv":974.97,"id":2263603},{"batb":[[1,1.81,433.55]],"ltp":2.2,"tv":541.23,"id":3622149}]}]}
{"op":"mcm","clk":"1009798570","pt":1580669553420,"mc":[{"id":"1.168230758","rc":[{"batl":[[0,3,216.18]],"ltp":2.08,"tv":974.97,"id":2263603},{"batb":[[2,1.56,66.72]],"batl":[[2,2.3,309.75]],"ltp":2.2,"tv":541.23,"id":3622149}]}]}
{"op":"mcm","clk":"1009799404","pt":1580669562624,"mc":[{"id":"1.168230758","rc":[{"batb":[[0,1.81,40.44],[1,1.56,66.72],[2,1.01,20.51]],"batl":[[0,2.3,309.75],[1,1.93,0],[2,2.3,0]],"ltp":2.2,"tv":541.23,"id":3622149}]}]}
{"op":"mcm","clk":"1009799472","pt":1580669563306,"mc":[{"id":"1.168230758","rc":[{"batb":[[0,1.84,37.92],[1,1.01,20.51],[2,1.01,0]],"ltp":2.08,"tv":974.97,"id":2263603},{"batb":[[0,1.56,66.72],[1,1.01,20.51],[2,1.01,0]],"ltp":2.2,"tv":541.23,"id":3622149}]}]}
{"op":"mcm","clk":"1009799696","pt":1580669565605,"mc":[{"id":"1.168230758","rc":[{"batb":[[1,1.82,38.87],[2,1.01,20.51]],"ltp":2.08,"tv":974.97,"id":2263603},{"batb":[[0,1.58,548.86],[1,1.57,390.96],[2,1.56,66.72]],"batl":[[0,2.24,377.66],[1,2.26,207.1],[2,2.3,309.75]],"ltp":2.2,"tv":541.23,"id":3622149}]}]}
{"op":"mcm","clk":"1009799767","pt":1580669566532,"mc":[{"id":"1.168230758","rc":[{"batb":[[0,1.82,38.87],[1,1.01,20.51],[2,1.01,0]],"ltp":2.08,"tv":974.97,"id":2263603},{"batb":[[2,1.01,20.51]],"ltp":2.2,"tv":541.23,"id":3622149}]}]}
{"op":"mcm","clk":"1009800423","pt":1580669574647,"mc":[{"id":"1.168230758","rc":[{"batb":[[0,1.57,65.15],[1,1.01,20.51],[2,1.01,0]],"batl":[[0,2.3,309.75],[1,2.26,0],[2,2.3,0]],"ltp":2.2,"tv":541.23,"id":3622149}]}]}
{"op":"mcm","clk":"1009800667","pt":1580669577533,"mc":[{"id":"1.168230758","rc":[{"batb":[[1,1.81,376.27],[2,1.79,408.6]],"batl":[[0,1.89,321.28],[1,1.91,337.3],[2,3,2.73]],"ltp":2.08,"tv":974.97,"id":2263603}]}]}
{"op":"mcm","clk":"1009800755","pt":1580669578614,"mc":[{"id":"1.168230758","rc":[{"batb":[[0,2.08,52.32],[1,1.98,584.7],[2,1.81,40.44]],"ltp":2.2,"tv":541.23,"id":3622149}]}]}
{"op":"mcm","clk":"1009800901","pt":1580669580340,"mc":[{"id":"1.168230758","rc":[{"batl":[[2,2.5,274.54]],"ltp":2.08,"tv":974.97,"id":2263603},{"batl":[[0,2.72,241.55]],"ltp":2.2,"tv":541.23,"id":3622149}]}]}
{"op":"mcm","clk":"1009801036","pt":1580669581644,"mc":[{"id":"1.168230758","rc":[{"batb":[[1,1.81,40.44],[2,1.01,20.51]],"ltp":2.2,"tv":541.23,"id":3622149}]}]}
{"op":"mcm","clk":"1009801753","pt":1580669589562,"mc":[{"id":"1.168230758","rc":[{"batb":[[1,1.65,54.84],[2,1.01,20.51]],"batl":[[0,2.5,274.54],[1,3,2.73],[2,2.5,0]],"ltp":2.08,"tv":974.97,"id":2263603}]}]}
{"op":"mcm","clk":"1009801774","pt":1580669589727,"mc":[{"id":"1.168230758","rc":[{"batb":[[0,1.65,54.84],[1,1.01,20.51],[2,1.01,0]],"ltp":2.08,"tv":974.97,"id":2263603},{"batb":[[0,1.81,40.44],[1,1.01,20.51],[2,1.01,0]],"ltp":2.2,"tv":541.23,"id":3622149}]}]}
{"op":"mcm","clk":"1009802057","pt":1580669592641,"mc":[{"id":"1.168230758","rc":[{"batb":[[1,1.62,429.59],[2,1.61,298.88]],"batl":[[0,2.22,393.37],[1,2.24,211.84],[2,2.5,274.54]],"ltp":2.08,"tv":974.97,"id":2263603}]}]}
{"op":"mcm","clk":"1009802942","pt":1580669602628,"mc":[{"id":"1.168230758","rc":[{"batb":[[1,1.01,20.51],[2,1.61,0]],"batl":[[0,2.5,274.54],[1,3,2.73],[2,2.5,0]],"ltp":2.08,"tv":974.97,"id":2263603}]}]}
{"op":"mcm","clk":"1009803210","pt":1580669605546,"mc":[{"id":"1.168230758","rc":[{"batb":[[0,1.95,603.17],[1,1.65,54.84],[2,1.01,20.51]],"ltp":2.08,"tv":974.97,"id":2263603},{"batb":[[0,1.83,277.87],[1,1.81,433.31],[2,1.01,20.51]],"batl":[[0,1.91,370.78],[1,1.93,325.56],[2,2.72,241.55]],"ltp":2.2,"tv":541.23,"id":3622149}]}]}
{"op":"mcm","clk":"1009803264","pt":1580669606272,"mc":[{"id":"1.168230758","rc":[{"batb":[[0,2.1,50.28],[1,1.95,603.17],[2,1.83,38.24]],"batl":[[0,3,2.73],[1,3,0]],"ltp":2.08,"tv":974.97,"id":2263603},{"batb":[[2,1.57,66.17]],"batl":[[2,2.72,0]],"ltp":2.2,"tv":541.23,"id":3622149}]}]}
{"op":"mcm","clk":"1009803461","pt":1580669608450,"mc":[{"id":"1.168230758","rc":[{"batb":[[1,1.83,38.24],[2,1.01,20.51]],"ltp":2.08,"tv":974.97,"id":2263603}]}]}
{"op":"mcm","clk":"1009803606","pt":1580669609963,"mc":[{"id":"1.168230758","rc":[{"batl":[[0,3,216.18]],"ltp":2.08,"tv":974.97,"id":2263603},{"batl":[[2,2.3,309.75]],"ltp":2.2,"tv":541.23,"id":3622149}]}]}
{"op":"mcm","clk":"1009804271","pt":1580669617564,"mc":[{"id":"1.168230758","rc":[{"batb":[[0,1.83,38.24],[1,1.01,20.51],[2,1.01,0]],"ltp":2.08,"tv":974.97,"id":2263603},{"batb":[[0,1.57,66.17],[1,1.01,20.51],[2,1.57,0]],"batl":[[0,2.3,309.75],[1,1.93,0],[2,2.3,0]],"ltp":2.2,"tv":541.23,"id":3622149}]}]}
{"op":"mcm","clk":"1009804514","pt":1580669620574,"mc":[{"id":"1.168230758","rc":[{"batb":[[0,1.58,434.52],[1,1.57,391.37],[2,1.01,20.51]],"batl":[[0,2.22,244.39],[1,2.24,212.09],[2,2.3,309.75]],"ltp":2.2,"tv":541.23,"id":3622149}]}]}
{"op":"mcm","clk":"1009805705","pt":1580669632362,"mc":[{"id":"1.168230758","rc":[{"batl":[[0,2.3,309.75],[1,2.24,0],[2,2.3,0]],"ltp":2.2,"tv":541.23,"id":3622149}]}]}
{"op":"mcm","clk":"1009805818","pt":1580669633559,"mc":[{"id":"1.168230758","rc":[{"trd":[[1.58,0.04]],"batb":[[0,1.58,434.5]],"ltp":1.58,"tv":541.27,"id":3622149}],"tv":1516.24}]}
{"op":"mcm","clk":"1009805906","pt":1580669634599,"mc":[{"id":"1.168230758","rc":[{"batl":[[0,3,2.73]],"ltp":2.08,"tv":974.97,"id":2263603}]}]}
{"op":"mcm","clk":"1009805979","pt":1580669635282,"mc":[{"id":"1.168230758","rc":[{"batb":[[0,2.36,421.33],[1,1.83,38.24],[2,1.01,20.51]],"ltp":2.08,"tv":974.97,"id":2263603},{"batl":[[0,1.64,431.75],[1,1.65,268.09]],"ltp":1.58,"tv":541.27,"id":3622149}]}]}
{"op":"mcm","clk":"1009806108","pt":1580669636482,"mc":[{"id":"1.168230758","rc":[{"batb":[[0,2.56,28.95],[1,2.36,421.33],[2,2.12,49.1]],"ltp":2.08,"tv":974.97,"id":2263603},{"batb":[[2,1.36,118.65]],"ltp":1.58,"tv":541.27,"id":3622149}]}]}
{"op":"mcm","clk":"1009806244","pt":1580669638099,"mc":[{"id":"1.168230758","rc":[{"batb":[[1,2.12,49.1],[2,1.01,20.51]],"batl":[[1,3.65,170.41]],"ltp":2.08,"tv":974.97,"id":2263603},{"batl":[[2,2.04,383.01]],"ltp":1.58,"tv":541.27,"id":3622149}]}]}
{"op":"mcm","clk":"1009807415","pt":1580669649616,"mc":[{"id":"1.168230758","rc":[{"batb":[[0,2.12,49.1],[1,1.01,20.51],[2,1.01,0]],"ltp":2.08,"tv":974.97,"id":2263603},{"batb":[[0,1.36,118.65],[1,1.01,20.51],[2,1.36,0]],"batl":[[0,2.04,383.01],[1,1.65,0],[2,2.04,0]],"ltp":1.58,"tv":541.27,"id":3622149}]}]}
{"op":"mcm","clk":"1009807675","pt":1580669652503,"mc":[{"id":"1.168230758","rc":[{"batb":[[0,1.38,395.88],[1,1.37,573.97],[2,1.36,118.65]],"batl":[[0,1.9,294.96],[1,1.92,330.86],[2,2.04,383.01]],"ltp":1.58,"tv":541.27,"id":3622149}]}]}
{"op":"mcm","clk":"1009808951","pt":1580669666226,"mc":[{"id":"1.168230758","rc":[{"batl":[[0,2.04,383.01],[1,1.92,0],[2,2.04,0]],"ltp":1.58,"tv":541.27,"id":3622149}]}]}
{"op":"mcm","clk":"1009809167","pt":1580669668306,"mc":[{"id":"1.168230758","rc":[{"batl":[[1,3.65,0]],"ltp":2.08,"tv":974.97,"id":2263603}]}]}
{"op":"mcm","clk":"1009809268","pt":1580669669204,"mc":[{"id":"1.168230758","rc":[{"trd":[[3,2.73]],"ltp":3.0,"tv":977.69,"id":2263603},{"trd":[[1.5,13.03]],"batl":[[0,1.42,615.66],[1,1.43,461.37],[2,1.45,567.56]],"ltp":1.5,"tv":546.72,"id":3622149}],"tv":1524.42}]}
{"op":"mcm","clk":"1009809380","pt":1580669670522,"mc":[{"id":"1.168230758","rc":[{"batb":[[0,3.4,35.09],[1,2.88,21.09],[2,1.01,20.51]],"ltp":3.0,"tv":977.69,"id":2263603}]}]}
{"op":"mcm","clk":"1009809483","pt":1580669671352,"mc":[{"id":"1.168230758","rc":[{"batl":[[2,1.45,0]],"ltp":1.5,"tv":546.72,"id":3622149}]}]}
{"op":"mcm","clk":"1009809634","pt":1580669672625,"mc":[{"id":"1.168230758","rc":[{"batl":[[0,5.3,118.79]],"ltp":3.0,"tv":977.69,"id":2263603},{"batl":[[2,1.73,527.57]],"ltp":1.5,"tv":546.72,"id":3622149}]}]}
{"op":"mcm","clk":"1009809801","pt":1580669674346,"mc":[{"id":"1.168230758","rc":[{"trd":[[1.42,11.52]],"batl":[[0,1.42,609.9]],"ltp":1.42,"tv":558.24,"id":3622149}],"tv":1535.94}]}
{"op":"mcm","clk":"1009810024","pt":1580669676636,"mc":[{"id":"1.168230758","rc":[{"trd":[[1.42,11.56]],"batl":[[0,1.42,609.88]],"ltp":1.42,"tv":558.28,"id":3622149}],"tv":1535.98}]}
{"op":"mcm","clk":"1009810406","pt":1580669680449,"mc":[{"id":"1.168230758","rc":[{"trd":[[1.38,20]],"batb":[[0,1.38,385.88]],"ltp":1.38,"tv":578.28,"id":3622149}],"tv":1555.98}]}
{"op":"mcm","clk":"1009812635","pt":1580669703649,"mc":[{"id":"1.168230758","rc":[{"batb":[[0,1.36,118.65],[1,1.28,162.48],[2,1.01,20.51]],"batl":[[0,1.73,527.57],[1,1.43,0],[2,1.73,0]],"ltp":1.38,"tv":578.28,"id":3622149}]}]}
{"op":"mcm","clk":"1009812683","pt":1580669704164,"mc":[{"id":"1.168230758","rc":[{"batb":[[0,2.88,21.09],[1,1.01,20.51],[2,1.01,0]],"ltp":3.0,"tv":977.69,"id":2263603},{"batb":[[0,1.28,162.48],[1,1.01,20.51],[2,1.01,0]],"ltp":1.38,"tv":578.28,"id":3622149}]}]}
{"op":"mcm","clk":"1009812913","pt":1580669706536,"mc":[{"id":"1.168230758","rc":[{"batb":[[0,1.29,940.97],[1,1.28,988.64],[2,1.01,20.51]],"batl":[[0,1.53,540.11],[1,1.54,343.95],[2,1.73,527.57]],"ltp":1.38,"tv":578.28,"id":3622149}]}]}
{"op":"mcm","clk":"1009813002","pt":1580669707483,"mc":[{"id":"1.168230758","rc":[{"batb":[[0,2.9,52.17]],"ltp":3.0,"tv":977.69,"id":2263603}]}]}
{"op":"mcm","clk":"1009813508","pt":1580669712548,"mc":[{"id":"1.168230758","rc":[{"batl":[[0,1.73,527.57],[1,3,3.18],[2,1.73,0]],"ltp":1.38,"tv":578.28,"id":3622149}]}]}
{"op":"mcm","clk":"1009813805","pt":1580669715643,"mc":[{"id":"1.168230758","rc":[{"batl":[[0,1.33,790.98],[1,1.34,1188.99],[2,3,3.18]],"ltp":1.38,"tv":578.28,"id":3622149}]}]}
{"op":"mcm","clk":"1009813895","pt":1580669716573,"mc":[{"id":"1.168230758","rc":[{"batb":[[0,4,45.64],[1,3.4,35.01],[2,1.01,20.51]],"ltp":3.0,"tv":977.69,"id":2263603},{"trd":[[1.29,26.26]],"batb":[[0,1.29,936.77],[2,1.21,226.92]],"ltp":1.29,"tv":586.68,"id":3622149}],"tv":1564.38}]}
{"op":"mcm","clk":"1009814087","pt":1580669718568,"mc":[{"id":"1.168230758","rc":[{"batl":[[1,1.34,615.98]],"ltp":1.29,"tv":586.68,"id":3622149}]}]}
{"op":"mcm","clk":"1009814203","pt":1580669719557,"mc":[{"id":"1.168230758","rc":[{"batl":[[0,6.6,98.95]],"ltp":3.0,"tv":977.69,"id":2263603},{"batl":[[2,1.62,614.4]],"ltp":1.29,"tv":586.68,"id":3622149}]}]}
{"op":"mcm","clk":"1009814714","pt":1580669725575,"mc":[{"id":"1.168230758","rc":[{"trd":[[1.29,46.26]],"batb":[[0,1.29,926.77]],"ltp":1.29,"tv":606.68,"id":3622149}],"tv":1584.38}]}
{"op":"mcm","clk":"1009815183","pt":1580669730598,"mc":[{"id":"1.168230758","rc":[{"batb":[[0,1.28,162.48],[1,1.21,226.92],[2,1.01,20.51]],"batl":[[0,1.62,614.4],[1,3,3.18],[2,1.62,0]],"ltp":1.29,"tv":606.68,"id":3622149}]}]}
{"op":"mcm","clk":"1009815273","pt":1580669731477,"mc":[{"id":"1.168230758","rc":[{"batb":[[0,3.4,35.01],[1,1.01,20.51],[2,1.01,0]],"ltp":3.0,"tv":977.69,"id":2263603},{"batb":[[0,1.21,226.92],[1,1.01,20.51],[2,1.01,0]],"ltp":1.29,"tv":606.68,"id":3622149}]}]}
{"op":"mcm","clk":"1009815472","pt":1580669733592,"mc":[{"id":"1.168230758","rc":[{"batb":[[0,1.22,1133.51],[1,1.21,1400.2],[2,1.01,20.51]],"batl":[[0,1.42,523.31],[1,1.43,462.32],[2,1.62,614.4]],"ltp":1.29,"tv":606.68,"id":3622149}]}]}
{"op":"mcm","clk":"1009815544","pt":1580669734478,"mc":[{"id":"1.168230758","rc":[{"batb":[[0,3.35,35.56]],"ltp":3.0,"tv":977.69,"id":2263603},{"batb":[[1,1.21,1397.76]],"ltp":1.29,"tv":606.68,"id":3622149}]}]}
{"op":"mcm","clk":"1009816208","pt":1580669742302,"mc":[{"id":"1.168230758","rc":[{"batb":[[0,1.21,224.48],[1,1.01,20.51],[2,1.01,0]],"ltp":1.29,"tv":606.68,"id":3622149}]}]}
{"op":"mcm","clk":"1009816471","pt":1580669745586,"mc":[{"id":"1.168230758","rc":[{"batb":[[1,2.82,22.5],[2,1.01,20.51]],"ltp":3.0,"tv":977.69,"id":2263603},{"batb":[[0,1.38,496.65],[1,1.37,577.41],[2,1.36,117.55]],"ltp":1.29,"tv":606.68,"id":3622149}]}]}
{"op":"mcm","clk":"1009816710","pt":1580669748513,"mc":[{"id":"1.168230758","rc":[{"batl":[[0,5.5,115.06]],"ltp":3.0,"tv":977.69,"id":2263603}]}]}
{"op":"mcm","clk":"1009817744","pt":1580669760595,"mc":[{"id":"1.168230758","rc":[{"batb":[[0,2.82,22.5],[1,1.01,20.51],[2,1.01,0]],"ltp":3.0,"tv":977.69,"id":2263603},{"batb":[[0,1.27,169.4],[1,1.01,20.51],[2,1.36,0]],"batl":[[0,1.38,1.68],[1,1.62,614.4],[2,3,3.18]],"ltp":1.29,"tv":606.68,"id":3622149}]}]}
{"op":"mcm","clk":"1009817820","pt":1580669761540,"mc":[{"id":"1.168230758","rc":[{"batl":[[0,1.62,614.4],[1,3,3.18],[2,3,0]],"ltp":1.29,"tv":606.68,"id":3622149}]}]}
{"op":"mcm","clk":"1009817901","pt":1580669762419,"mc":[{"id":"1.168230758","rc":[{"batl":[[0,1.38,30.29],[1,1.62,614.4],[2,3,3.18]],"ltp":1.29,"tv":606.68,"id":3622149}]}]}
{"op":"mcm","clk":"1009817991","pt":1580669763511,"mc":[{"id":"1.168230758","rc":[{"batb":[[0,1.28,821.95],[1,1.27,1030.77],[2,1.01,20.51]],"batl":[[1,1.55,457.44],[2,1.56,328.33]],"ltp":1.29,"tv":606.68,"id":3622149}]}]}
{"op":"mcm","clk":"1009818329","pt":1580669767530,"mc":[{"id":"1.168230758","rc":[{"batl":[[1,1.62,614.4],[2,3,3.18]],"ltp":1.29,"tv":606.68,"id":3622149}]}]}
{"op":"mcm","clk":"1009818571","pt":1580669770598,"mc":[{"id":"1.168230758","rc":[{"batl":[[0,1.32,1001.48],[1,1.33,635.49],[2,1.36,573.01]],"ltp":1.29,"tv":606.68,"id":3622149}]}]}
{"op":"mcm","clk":"1009818623","pt":1580669771328,"mc":[{"id":"1.168230758","rc":[{"batb":[[0,4.1,43.43],[1,3.35,36.19],[2,1.01,20.51]],"ltp":3.0,"tv":977.69,"id":2263603},{"batb":[[2,1.19,251]],"ltp":1.29,"tv":606.68,"id":3622149}]}]}
{"op":"mcm","clk":"1009818775","pt":1580669773644,"mc":[{"id":"1.168230758","rc":[{"batl":[[0,6.6,98.95]],"ltp":3.0,"tv":977.69,"id":2263603},{"batl":[[2,1.38,30.29]],"ltp":1.29,"tv":606.68,"id":3622149}]}]}
{"op":"mcm","clk":"1009819552","pt":1580669783623,"mc":[{"id":"1.168230758","rc":[{"batl":[[2,1.62,614.4]],"ltp":1.29,"tv":606.68,"id":3622149}]}]}
{"op":"mcm","clk":"1009819712","pt":1580669785564,"mc":[{"id":"1.168230758","rc":[{"batb":[[0,3.35,36.04],[1,1.01,20.51],[2,1.01,0]],"ltp":3.0,"tv":977.69,"id":2263603},{"batb":[[0,1.19,251],[1,1.01,20.51],[2,1.19,0]],"batl":[[0,1.62,614.4],[1,3,3.18],[2,1.62,0]],"ltp":1.29,"tv":606.68,"id":3622149}]}]}
{"op":"mcm","clk":"1009819747","pt":1580669786056,"mc":[{"id":"1.168230758","rc":[{"batl":[[0,1.28,30.29],[1,1.62,614.4],[2,3,3.18]],"ltp":1.29,"tv":606.68,"id":3622149}]}]}
{"op":"mcm","clk":"1009819955","pt":1580669788625,"mc":[{"id":"1.168230758","rc":[{"batb":[[0,1.2,1063.63],[1,1.19,1568.03],[2,1.01,20.51]],"batl":[[1,1.42,441.25],[2,1.43,463.19]],"ltp":1.29,"tv":606.68,"id":3622149}]}]}
{"op":"mcm","clk":"1009820130","pt":1580669790567,"mc":[{"id":"1.168230758","rc":[{"batl":[[0,1.28,31.97],[1,1.62,614.4],[2,3,3.18]],"ltp":1.29,"tv":606.68,"id":3622149}]}]}
{"op":"mcm","clk":"1009820225","pt":1580669791546,"mc":[{"id":"1.168230758","rc":[{"batl":[[0,1.28,30.29]],"ltp":1.29,"tv":606.68,"id":3622149}]}]}
{"op":"mcm","clk":"1009820300","pt":1580669792439,"mc":[{"id":"1.168230758","rc":[{"batl":[[1,3,3.18],[2,3,0]],"ltp":1.29,"tv":606.68,"id":3622149}]}]}
{"op":"mcm","clk":"1009820392","pt":1580669793572,"mc":[{"id":"1.168230758","rc":[{"batl":[[0,1.23,1036.61],[1,1.24,928.74],[2,1.26,573.01]],"ltp":1.29,"tv":606.68,"id":3622149}]}]}
{"op":"mcm","clk":"1009820483","pt":1580669794561,"mc":[{"id":"1.168230758","rc":[{"batb":[[0,5.3,24.08],[1,4.4,37.77],[2,1.01,20.51]],"ltp":3.0,"tv":977.69,"id":2263603},{"batb":[[2,1.14,339.12]],"ltp":1.29,"tv":606.68,"id":3622149}]}]}
{"op":"mcm","clk":"1009820659","pt":1580669796635,"mc":[{"id":"1.168230758","rc":[{"batl":[[0,9.8,75.27]],"ltp":3.0,"tv":977.69,"id":2263603},{"batl":[[2,1.28,30.29]],"ltp":1.29,"tv":606.68,"id":3622149}]}]}
{"op":"mcm","clk":"1009820806","pt":1580669798367,"mc":[{"id":"1.168230758","rc":[{"batl":[[2,1.49,761.67]],"ltp":1.29,"tv":606.68,"id":3622149}]}]}
{"op":"mcm","clk":"1009821076","pt":1580669801640,"mc":[{"id":"1.168230758","rc":[{"batl":[[2,1.39,30.29]],"ltp":1.29,"tv":606.68,"id":3622149}]}]}
{"op":"mcm","clk":"1009821412","pt":1580669805546,"mc":[{"id":"1.168230758","rc":[{"trd":[[1.2,149.22]],"batb":[[0,1.2,989.02]],"ltp":1.2,"tv":755.9,"id":3622149}],"tv":1733.6}]}
{"op":"mcm","clk":"1009821684","pt":1580669808398,"mc":[{"id":"1.168230758","rc":[{"batb":[[0,1.19,251],[1,1.14,339.12],[2,1.01,20.51]],"batl":[[0,1.39,30.29],[1,1.49,761.67],[2,3,3.18]],"ltp":1.2,"tv":755.9,"id":3622149}]}]}
{"op":"mcm","clk":"1009821793","pt":1580669809591,"mc":[{"id":"1.168230758","rc":[{"batb":[[0,4.4,37.77],[1,1.01,20.51],[2,1.01,0]],"ltp":3.0,"tv":977.69,"id":2263603},{"batb":[[0,1.14,339.12],[1,1.01,20.51],[2,1.01,0]],"batl":[[0,1.49,761.67],[1,3,3.18],[2,3,0]],"ltp":1.2,"tv":755.9,"id":3622149}]}]}
{"op":"mcm","clk":"1009822001","pt":1580669811571,"mc":[{"id":"1.168230758","rc":[{"batb":[[1,4.3,37.85],[2,1.01,20.51]],"ltp":3.0,"tv":977.69,"id":2263603}]}]}
{"op":"mcm","clk":"1009822103","pt":1580669812557,"mc":[{"id":"1.168230758","rc":[{"batb":[[0,4.3,37.85],[1,1.01,20.51],[2,1.01,0]],"ltp":3.0,"tv":977.69,"id":2263603},{"batb":[[0,1.15,1809.87],[1,1.14,1070.13],[2,1.01,20.51]],"batl":[[0,1.29,808.31],[1,1.3,717.34],[2,1.49,761.67]],"ltp":1.2,"tv":755.9,"id":3622149}]}]}
{"op":"mcm","clk":"1009822176","pt":1580669813284,"mc":[{"id":"1.168230758","rc":[{"batb":[[0,1.14,338.88],[1,1.01,20.51],[2,1.01,0]],"batl":[[0,1.2,30.29],[1,1.49,761.67],[2,3,3.18]],"ltp":1.2,"tv":755.9,"id":3622149}]}]}
{"op":"mcm","clk":"1009822490","pt":1580669816559,"mc":[{"id":"1.168230758","rc":[{"trd":[[1.2,209.8]],"batb":[[0,1.21,1071.92],[1,1.2,1242.1],[2,1.14,338.88]],"batl":[[0,1.24,849.89],[1,1.25,890.47],[2,1.49,761.67]],"ltp":1.2,"tv":816.48,"id":3622149}],"tv":1794.17}]}
{"op":"mcm","clk":"1009822752","pt":1580669819466,"mc":[{"id":"1.168230758","rc":[{"batl":[[0,8.6,81.89]],"ltp":3.0,"tv":977.69,"id":2263603}]}]}
{"op":"mcm","clk":"1009822827","pt":1580669820302,"mc":[{"id":"1.168230758","rc":[{"batb":[[0,1.14,338.88],[1,1.01,20.51],[2,1.14,0]],"batl":[[0,1.49,761.67],[1,3,3.18],[2,1.49,0]],"ltp":1.2,"tv":816.48,"id":3622149}]}]}
{"op":"mcm","clk":"1009823116","pt":1580669823591,"mc":[{"id":"1.168230758","rc":[{"batb":[[0,1.15,1801.04],[1,1.14,1079.03],[2,1.01,20.51]],"batl":[[0,1.29,816.22],[1,1.3,717.35],[2,1.49,761.67]],"ltp":1.2,"tv":816.48,"id":3622149}]}]}
{"op":"mcm","clk":"1009823452","pt":1580669827302,"mc":[{"id":"1.168230758","rc":[{"batb":[[2,1.01,2554.06]],"ltp":1.2,"tv":816.48,"id":3622149}]}]}
{"op":"mcm","clk":"1009823857","pt":1580669831503,"mc":[{"id":"1.168230758","rc":[{"batb":[[0,1.14,338.88],[1,1.01,2554.06],[2,1.01,0]],"ltp":1.2,"tv":816.48,"id":3622149}]}]}
{"op":"mcm","clk":"1009824172","pt":1580669834484,"mc":[{"id":"1.168230758","rc":[{"batb":[[0,1.26,489.24],[1,1.25,938.21],[2,1.14,338.88]],"ltp":1.2,"tv":816.48,"id":3622149}]}]}
{"op":"mcm","clk":"1009824285","pt":1580669835575,"mc":[{"id":"1.168230758","rc":[{"batb":[[1,3.35,36.27],[2,1.01,20.51]],"ltp":3.0,"tv":977.69,"id":2263603},{"batb":[[1,1.25,1124.37],[2,1.23,2491.35]],"ltp":1.2,"tv":816.48,"id":3622149}]}]}
{"op":"mcm","clk":"1009824457","pt":1580669837394,"mc":[{"id":"1.168230758","rc":[{"batl":[[0,7.2,92.18]],"ltp":3.0,"tv":977.69,"id":2263603}]}]}
{"op":"mcm","clk":"1009824518","pt":1580669838069,"mc":[{"id":"1.168230758","rc":[{"batb":[[2,1.15,312.37]],"ltp":1.2,"tv":816.48,"id":3622149}]}]}
{"op":"mcm","clk":"1009825657","pt":1580669850499,"mc":[{"id":"1.168230758","rc":[{"batb":[[0,3.35,36.27],[1,1.01,20.51],[2,1.01,0]],"ltp":3.0,"tv":977.69,"id":2263603},{"batb":[[0,1.15,312.37],[1,1.03,844.52],[2,1.02,1266.78]],"batl":[[0,1.49,761.67],[1,3,3.18],[2,1.49,0]],"ltp":1.2,"tv":816.48,"id":3622149}]}]}
{"op":"mcm","clk":"1009825819","pt":1580669852213,"mc":[{"id":"1.168230758","rc":[{"batb":[[1,1.04,633.39],[2,1.03,844.52]],"ltp":1.2,"tv":816.48,"id":3622149}]}]}
{"op":"mcm","clk":"1009825939","pt":1580669853617,"mc":[{"id":"1.168230758","rc":[{"batb":[[0,1.16,1018.2],[1,1.15,1820.08],[2,1.04,633.39]],"batl":[[0,1.42,400.04],[1,1.43,463.87],[2,1.49,761.67]],"ltp":1.2,"tv":816.48,"id":3622149}]}]}
{"op":"mcm","clk":"1009826572","pt":1580669861624,"mc":[{"id":"1.168230758","rc":[{"batl":[[0,1.49,761.67],[1,3,3.18],[2,1.49,0]],"ltp":1.2,"tv":816.48,"id":3622149}]}]}
{"op":"mcm","clk":"1009826855","pt":1580669864634,"mc":[{"id":"1.168230758","rc":[{"batb":[[0,6,34.93],[1,5.2,25.26],[2,1.01,20.51]],"ltp":3.0,"tv":977.69,"id":2263603},{"batb":[[2,1.11,448.57]],"batl":[[0,1.18,639.47],[1,1.19,1232.39],[2,1.23,573.01]],"ltp":1.2,"tv":816.48,"id":3622149}]}]}
{"op":"mcm","clk":"1009827103","pt":1580669867551,"mc":[{"id":"1.168230758","rc":[{"batl":[[2,1.49,761.67]],"ltp":1.2,"tv":816.48,"id":3622149}]}]}
{"op":"mcm","clk":"1009827198","pt":1580669868541,"mc":[{"id":"1.168230758","rc":[{"batl":[[0,11.5,70.11]],"ltp":3.0,"tv":977.69,"id":2263603}]}]}
{"op":"mcm","clk":"1009827876","pt":1580669876625,"mc":[{"id":"1.168230758","rc":[{"trd":[[1.16,4]],"batb":[[0,1.16,1016.2]],"ltp":1.16,"tv":820.48,"id":3622149}],"tv":1798.17}]}
{"op":"mcm","clk":"1009828398","pt":1580669882544,"mc":[{"id":"1.168230758","rc":[{"trd":[[1.16,10]],"batb":[[0,1.16,1013.2]],"ltp":1.16,"tv":826.48,"id":3622149}],"tv":1804.17}]}
{"op":"mcm","clk":"1009828815","pt":1580669887568,"mc":[{"id":"1.168230758","rc":[{"batb":[[0,6,34.78]],"ltp":3.0,"tv":977.69,"id":2263603},{"trd":[[1.16,2036.4]],"batb":[[0,1.15,1820.08],[1,1.11,448.57],[2,1.04,633.39]],"batl":[[0,1.16,79.05],[1,1.18,639.47],[2,1.19,1232.39]],"ltp":1.16,"tv":2852.88,"id":3622149}],"tv":3830.57}]}
{"op":"mcm","clk":"1009829065","pt":1580669890565,"mc":[{"id":"1.168230758","rc":[{"trd":[[1.16,2194.5]],"batb":[[0,1.16,666.45],[1,1.15,2039.53],[2,1.11,448.57]],"batl":[[0,1.18,907.95],[1,1.19,1232.39],[2,1.49,761.67]],"ltp":1.16,"tv":3010.98,"id":3622149}],"tv":3988.68}]}
{"op":"mcm","clk":"1009829562","pt":1580669895572,"mc":[{"id":"1.168230758","rc":[{"batb":[[0,6,34.31],[1,5.2,24.86]],"ltp":3.0,"tv":977.69,"id":2263603}]}]}
{"op":"mcm","clk":"1009830078","pt":1580669901595,"mc":[{"id":"1.168230758","rc":[{"trd":[[1.16,2794.5]],"batb":[[0,1.16,366.45]],"ltp":1.16,"tv":3610.98,"id":3622149}],"tv":4588.68}]}
{"op":"mcm","clk":"1009830235","pt":1580669903460,"mc":[{"id":"1.168230758","rc":[{"batb":[[0,1.17,8.4],[1,1.16,366.45],[2,1.15,2039.53]],"ltp":1.16,"tv":3610.98,"id":3622149}]}]}
{"op":"mcm","clk":"1009830319","pt":1580669904497,"mc":[{"id":"1.168230758","rc":[{"batb":[[1,1.16,639.8]],"batl":[[0,1.18,1012.01]],"ltp":1.16,"tv":3610.98,"id":3622149}]}]}
{"op":"mcm","clk":"1009830919","pt":1580669911569,"mc":[{"id":"1.168230758","rc":[{"trd":[[1.16,3865.7],[1.17,16.8]],"batb":[[0,1.16,104.2],[1,1.15,2039.53],[2,1.11,448.57]],"ltp":1.16,"tv":4698.98,"id":3622149}],"tv":5676.68}]}
{"op":"mcm","clk":"1009831184","pt":1580669914589,"mc":[{"id":"1.168230758","rc":[{"batb":[[0,1.16,490.04]],"batl":[[0,1.18,1159.46]],"ltp":1.16,"tv":4698.98,"id":3622149}]}]}
{"op":"mcm","clk":"1009831247","pt":1580669915314,"mc":[{"id":"1.168230758","rc":[{"trd":[[1.18,0.78]],"batl":[[0,1.18,1159.07]],"ltp":1.18,"tv":4699.77,"id":3622149}],"tv":5677.46}]}
{"op":"mcm","clk":"1009833269","pt":1580669939510,"mc":[{"id":"1.168230758","rc":[{"batb":[[0,5.2,24.55],[1,1.01,20.51],[2,1.01,0]],"ltp":3.0,"tv":977.69,"id":2263603},{"batb":[[0,1.11,448.57],[1,1.04,633.39],[2,1.03,844.52]],"batl":[[0,1.49,761.67],[1,3,3.18],[2,1.49,0]],"ltp":1.18,"tv":4699.77,"id":3622149}]}]}
{"op":"mcm","clk":"1009833560","pt":1580669942350,"mc":[{"id":"1.168230758","rc":[{"batb":[[0,1.11,2945.69]],"batl":[[0,1.22,412.38],[1,1.23,1010.19],[2,1.49,761.67]],"ltp":1.18,"tv":4699.77,"id":3622149}]}]}
{"op":"mcm","clk":"1009833690","pt":1580669943546,"mc":[{"id":"1.168230758","rc":[{"batl":[[0,6.4,2.52],[1,11.5,70.11]],"ltp":3.0,"tv":977.69,"id":2263603}]}]}
{"op":"mcm","clk":"1009834629","pt":1580669953124,"mc":[{"id":"1.168230758","rc":[{"batb":[[0,1.11,448.57]],"batl":[[0,1.49,761.67],[1,3,3.18],[2,1.49,0]],"ltp":1.18,"tv":4699.77,"id":3622149}]}]}
{"op":"mcm","clk":"1009834788","pt":1580669954943,"mc":[{"id":"1.168230758","rc":[{"batl":[[1,11.5,0]],"ltp":3.0,"tv":977.69,"id":2263603}]}]}
{"op":"mcm","clk":"1009834950","pt":1580669956644,"mc":[{"id":"1.168230758","rc":[{"batb":[[1,4.5,34.62],[2,1.01,20.51]],"ltp":3.0,"tv":977.69,"id":2263603},{"batb":[[0,1.2,688.29],[1,1.19,1571.86],[2,1.18,3183.4]],"batl":[[0,1.22,412.38],[1,1.23,1010.19],[2,1.49,761.67]],"ltp":1.18,"tv":4699.77,"id":3622149}]}]}
{"op":"mcm","clk":"1009835221","pt":1580669959227,"mc":[{"id":"1.168230758","rc":[{"batl":[[1,9.8,75.27]],"ltp":3.0,"tv":977.69,"id":2263603},{"batb":[[2,1.15,327.16]],"ltp":1.18,"tv":4699.77,"id":3622149}]}]}
{"op":"mcm","clk":"1009835513","pt":1580669962569,"mc":[{"id":"1.168230758","rc":[{"batb":[[0,4.5,34.62],[1,1.01,20.51],[2,1.01,0]],"ltp":3.0,"tv":977.69,"id":2263603},{"batb":[[0,1.15,327.16],[1,1.04,633.39],[2,1.03,844.52]],"batl":[[0,1.49,761.67],[1,3,3.18],[2,1.49,0]],"ltp":1.18,"tv":4699.77,"id":3622149}]}]}
{"op":"mcm","clk":"1009836138","pt":1580669968469,"mc":[{"id":"1.168230758","rc":[{"batb":[[0,1.19,828.89],[1,1.18,1414.47],[2,1.15,327.16]],"batl":[[0,1.21,403.06],[1,1.22,1064.41],[2,1.49,761.67]],"ltp":1.18,"tv":4699.77,"id":3622149}]}]}
{"op":"mcm","clk":"1009836334","pt":1580669970340,"mc":[{"id":"1.168230758","rc":[{"batb":[[0,1.15,327.16],[1,1.04,633.39],[2,1.03,844.52]],"batl":[[0,1.49,761.67],[1,3,3.18],[2,1.49,0]],"ltp":1.18,"tv":4699.77,"id":3622149}]}]}
{"op":"mcm","clk":"1009836636","pt":1580669973476,"mc":[{"id":"1.168230758","rc":[{"batb":[[0,1.15,2153.76],[1,1.14,714.32],[2,1.04,633.39]],"batl":[[0,1.27,665.75],[1,1.28,794.3],[2,1.49,761.67]],"ltp":1.18,"tv":4699.77,"id":3622149}]}]}
{"op":"mcm","clk":"1009837552","pt":1580669982593,"mc":[{"id":"1.168230758","rc":[{"batb":[[0,1.15,327.16],[1,1.04,633.39],[2,1.03,844.52]],"ltp":1.18,"tv":4699.77,"id":3622149}]}]}
{"op":"mcm","clk":"1009837632","pt":1580669983484,"mc":[{"id":"1.168230758","rc":[{"batl":[[0,1.26,25],[1,1.27,665.75],[2,1.28,794.3]],"ltp":1.18,"tv":4699.77,"id":3622149}]}]}
{"op":"mcm","clk":"1009837715","pt":1580669984271,"mc":[{"id":"1.168230758","rc":[{"batl":[[0,1.27,665.75],[1,1.28,794.3],[2,1.49,761.67]],"ltp":1.18,"tv":4699.77,"id":3622149}]}]}
{"op":"mcm","clk":"1009837860","pt":1580669985582,"mc":[{"id":"1.168230758","rc":[{"batl":[[1,9.8,0]],"ltp":3.0,"tv":977.69,"id":2263603},{"batb":[[0,1.24,920.57],[1,1.23,3553.85],[2,1.15,327.16]],"ltp":1.18,"tv":4699.77,"id":3622149}]}]}
{"op":"mcm","clk":"1009837939","pt":1580669986368,"mc":[{"id":"1.168230758","rc":[{"batb":[[1,4.1,43.9],[2,1.01,20.51]],"ltp":3.0,"tv":977.69,"id":2263603},{"batb":[[1,1.23,3751.58],[2,1.19,243.99]],"ltp":1.18,"tv":4699.77,"id":3622149}]}]}
{"op":"mcm","clk":"1009838167","pt":1580669988462,"mc":[{"id":"1.168230758","rc":[{"batl":[[1,7.8,87.91]],"ltp":3.0,"tv":977.69,"id":2263603},{"batb":[[1,1.23,1260.23]],"ltp":1.18,"tv":4699.77,"id":3622149}]}]}
{"op":"mcm","clk":"1009839019","pt":1580669996617,"mc":[{"id":"1.168230758","rc":[{"batb":[[0,4.1,43.51],[1,1.01,20.51],[2,1.01,0]],"ltp":3.0,"tv":977.69,"id":2263603},{"batb":[[0,1.19,243.99],[1,1.04,633.39],[2,1.03,844.52]],"batl":[[0,1.49,761.67],[1,3,3.18],[2,1.49,0]],"ltp":1.18,"tv":4699.77,"id":3622149}]}]}
{"op":"mcm","clk":"1009839193","pt":1580669998584,"mc":[{"id":"1.168230758","rc":[{"batb":[[0,1.2,1250.54],[1,1.19,1432.45],[2,1.04,633.39]],"batl":[[0,1.31,660.99],[1,1.32,675.78],[2,1.49,761.67]],"ltp":1.18,"tv":4699.77,"id":3622149}]}]}
{"op":"mcm","clk":"1009839271","pt":1580669999502,"mc":[{"id":"1.168230758","rc":[{"batb":[[0,1.19,243.99],[1,1.04,633.39],[2,1.03,844.52]],"batl":[[0,1.49,761.67],[1,3,3.18],[2,1.49,0]],"ltp":1.18,"tv":4699.77,"id":3622149}]}]}
{"op":"mcm","clk":"1009839623","pt":1580670002324,"mc":[{"id":"1.168230758","rc":[{"batb":[[0,1.23,1169.25],[1,1.22,1127.43],[2,1.19,243.99]],"batl":[[0,1.26,560.31],[1,1.27,832.14],[2,1.49,761.67]],"ltp":1.18,"tv":4699.77,"id":3622149}]}]}
{"op":"mcm","clk":"1009839793","pt":1580670003640,"mc":[{"id":"1.168230758","rc":[{"batl":[[2,1.32,25]],"ltp":1.18,"tv":4699.77,"id":3622149}]}]}
{"op":"mcm","clk":"1009840008","pt":1580670005301,"mc":[{"id":"1.168230758","rc":[{"batb":[[0,1.19,243.99],[1,1.04,633.39],[2,1.03,844.52]],"batl":[[0,1.32,25],[1,1.49,761.67],[2,3,3.18]],"ltp":1.18,"tv":4699.77,"id":3622149}]}]}
{"op":"mcm","clk":"1009840363","pt":1580670008332,"mc":[{"id":"1.168230758","rc":[{"batb":[[0,1.2,1250.54],[1,1.19,1432.45],[2,1.04,633.39]],"batl":[[0,1.31,660.99],[1,1.32,700.78],[2,1.49,761.67]],"ltp":1.18,"tv":4699.77,"id":3622149}]}]}
{"op":"mcm","clk":"1009840758","pt":1580670012357,"mc":[{"id":"1.168230758","rc":[{"batb":[[0,1.19,243.99],[1,1.04,633.39],[2,1.03,844.52]],"ltp":1.18,"tv":4699.77,"id":3622149}]}]}
{"op":"mcm","clk":"1009840954","pt":1580670013636,"mc":[{"id":"1.168230758","rc":[{"batl":[[0,1.3,25],[1,1.31,660.99],[2,1.32,675.78]],"ltp":1.18,"tv":4699.77,"id":3622149}]}]}
{"op":"mcm","clk":"1009841069","pt":1580670014627,"mc":[{"id":"1.168230758","rc":[{"batl":[[0,1.31,660.99],[1,1.32,675.78],[2,1.49,761.67]],"ltp":1.18,"tv":4699.77,"id":3622149}]}]}
{"op":"mcm","clk":"1009841188","pt":1580670015621,"mc":[{"id":"1.168230758","rc":[{"batl":[[1,7.8,0]],"ltp":3.0,"tv":977.69,"id":2263603},{"batb":[[0,1.28,500.21],[1,1.27,2988.88],[2,1.19,243.99]],"ltp":1.18,"tv":4699.77,"id":3622149}]}]}
{"op":"mcm","clk":"1009841264","pt":1580670016413,"mc":[{"id":"1.168230758","rc":[{"batb":[[1,3.9,50.36],[2,1.01,20.51]],"ltp":3.0,"tv":977.69,"id":2263603},{"batb":[[1,1.27,3158.12],[2,1.24,191.91]],"ltp":1.18,"tv":4699.77,"id":3622149}]}]}
{"op":"mcm","clk":"1009841457","pt":1580670018233,"mc":[{"id":"1.168230758","rc":[{"batb":[[1,1.27,1035.85]],"ltp":1.18,"tv":4699.77,"id":3622149}]}]}
{"op":"mcm","clk":"1009841593","pt":1580670019341,"mc":[{"id":"1.168230758","rc":[{"batl":[[1,6.6,98.95]],"ltp":3.0,"tv":977.69,"id":2263603}]}]}
{"op":"mcm","clk":"1009842427","pt":1580670027547,"mc":[{"id":"1.168230758","rc":[{"batb":[[0,3.9,50.36],[1,1.01,20.51],[2,1.01,0]],"ltp":3.0,"tv":977.69,"id":2263603},{"batb":[[0,1.24,191.91],[1,1.04,633.39],[2,1.03,844.52]],"batl":[[0,1.49,761.67],[1,3,3.18],[2,1.49,0]],"ltp":1.18,"tv":4699.77,"id":3622149}]}]}
{"op":"mcm","clk":"1009842777","pt":1580670030641,"mc":[{"id":"1.168230758","rc":[{"batb":[[0,1.25,1064.12],[1,1.24,1205.29],[2,1.04,633.39]],"batl":[[0,1.33,366.95],[1,1.34,631.83],[2,1.49,761.67]],"ltp":1.18,"tv":4699.77,"id":3622149}]}]}
{"op":"mcm","clk":"1009842801","pt":1580670030848,"mc":[{"id":"1.168230758","rc":[{"batb":[[0,1.24,191.91],[1,1.04,633.39],[2,1.03,844.52]],"batl":[[0,1.49,761.67],[1,3,3.18],[2,1.49,0]],"ltp":1.18,"tv":4699.77,"id":3622149}]}]}
{"op":"mcm","clk":"1009843183","pt":1580670034525,"mc":[{"id":"1.168230758","rc":[{"batb":[[0,1.27,943.92],[1,1.26,917.1],[2,1.24,191.91]],"batl":[[0,1.3,338.66],[1,1.31,708.36],[2,1.49,761.67]],"ltp":1.18,"tv":4699.77,"id":3622149}]}]}
{"op":"mcm","clk":"1009843267","pt":1580670035364,"mc":[{"id":"1.168230758","rc":[{"batb":[[0,1.24,191.91],[1,1.04,633.39],[2,1.03,844.52]],"batl":[[0,1.49,761.67],[1,3,3.18],[2,1.49,0]],"ltp":1.18,"tv":4699.77,"id":3622149}]}]}
{"op":"mcm","clk":"1009843503","pt":1580670037758,"mc":[{"id":"1.168230758","rc":[{"batb":[[0,1.25,1064.12],[1,1.24,1205.29],[2,1.04,633.39]],"batl":[[0,1.33,366.95],[1,1.34,631.83],[2,1.49,761.67]],"ltp":1.18,"tv":4699.77,"id":3622149}]}]}
{"op":"mcm","clk":"1009843780","pt":1580670040439,"mc":[{"id":"1.168230758","rc":[{"batb":[[0,1.24,191.91],[1,1.04,633.39],[2,1.03,844.52]],"batl":[[0,1.49,761.67],[1,3,3.18],[2,1.49,0]],"ltp":1.18,"tv":4699.77,"id":3622149}]}]}
{"op":"mcm","clk":"1009844116","pt":1580670043551,"mc":[{"id":"1.168230758","rc":[{"batb":[[0,1.25,1064.12],[1,1.24,1205.29],[2,1.04,633.39]],"batl":[[0,1.28,425.02],[1,1.29,1339.48],[2,1.49,761.67]],"ltp":1.18,"tv":4699.77,"id":3622149}]}]}
{"op":"mcm","clk":"1009844233","pt":1580670044647,"mc":[{"id":"1.168230758","rc":[{"batb":[[0,4.4,36.19],[1,4,45.32],[2,1.01,20.51]],"ltp":3.0,"tv":977.69,"id":2263603},{"batb":[[2,1.2,236.52]],"ltp":1.18,"tv":4699.77,"id":3622149}]}]}
{"op":"mcm","clk":"1009844334","pt":1580670045648,"mc":[{"id":"1.168230758","rc":[{"batl":[[2,1.34,25]],"ltp":1.18,"tv":4699.77,"id":3622149}]}]}
{"op":"mcm","clk":"1009844429","pt":1580670046554,"mc":[{"id":"1.168230758","rc":[{"batl":[[1,1.29,766.47]],"ltp":1.18,"tv":4699.77,"id":3622149}]}]}
{"op":"mcm","clk":"1009844506","pt":1580670047259,"mc":[{"id":"1.168230758","rc":[{"batl":[[2,1.33,25]],"ltp":1.18,"tv":4699.77,"id":3622149}]}]}
{"op":"mcm","clk":"1009845162","pt":1580670053552,"mc":[{"id":"1.168230758","rc":[{"batb":[[0,1.24,191.91],[1,1.2,236.52],[2,1.04,633.39]],"batl":[[0,1.33,25],[1,1.34,25],[2,1.49,761.67]],"ltp":1.18,"tv":4699.77,"id":3622149}]}]}
{"op":"mcm","clk":"1009845261","pt":1580670054451,"mc":[{"id":"1.168230758","rc":[{"batb":[[0,4,45.32],[1,1.01,20.51],[2,1.01,0]],"ltp":3.0,"tv":977.69,"id":2263603},{"batb":[[0,1.2,234.71],[1,1.04,633.39],[2,1.03,844.52]],"ltp":1.18,"tv":4699.77,"id":3622149}]}]}
{"op":"mcm","clk":"1009845509","pt":1580670056602,"mc":[{"id":"1.168230758","rc":[{"batb":[[0,1.21,1425.03],[1,1.2,1226.91],[2,1.04,633.39]],"batl":[[0,1.32,430.15],[1,1.33,679.6],[2,1.34,25]],"ltp":1.18,"tv":4699.77,"id":3622149}]}]}
{"op":"mcm","clk":"1009846038","pt":1580670061177,"mc":[{"id":"1.168230758","rc":[{"batl":[[1,1.33,654.6],[2,1.49,761.67]],"ltp":1.18,"tv":4699.77,"id":3622149}]}]}
{"op":"mcm","clk":"1009846210","pt":1580670062667,"mc":[{"id":"1.168230758","rc":[{"batl":[[0,1.31,25],[1,1.32,430.15],[2,1.33,654.6]],"ltp":1.18,"tv":4699.77,"id":3622149}]}]}
{"op":"mcm","clk":"1009847438","pt":1580670073502,"mc":[{"id":"1.168230758","rc":[{"batb":[[0,1.2,234.71],[1,1.04,633.39],[2,1.03,844.52]],"ltp":1.18,"tv":4699.77,"id":3622149}]}]}
{"op":"mcm","clk":"1009847671","pt":1580670075392,"mc":[{"id":"1.168230758","rc":[{"batl":[[0,1.32,430.15],[1,1.33,654.6],[2,1.49,761.67]],"ltp":1.18,"tv":4699.77,"id":3622149}]}]}
{"op":"mcm","clk":"1009847821","pt":1580670076616,"mc":[{"id":"1.168230758","rc":[{"batb":[[0,1.29,663.84],[1,1.28,2878.68],[2,1.2,234.71]],"ltp":1.18,"tv":4699.77,"id":3622149}]}]}
{"op":"mcm","clk":"1009847909","pt":1580670077297,"mc":[{"id":"1.168230758","rc":[{"batb":[[1,3.25,38.24],[2,1.01,20.51]],"ltp":3.0,"tv":977.69,"id":2263603},{"batb":[[1,1.28,3041.87],[2,1.22,1628.93]],"ltp":1.18,"tv":4699.77,"id":3622149}]}]}
{"op":"mcm","clk":"1009848162","pt":1580670079405,"mc":[{"id":"1.168230758","rc":[{"batb":[[1,1.28,995.4]],"ltp":1.18,"tv":4699.77,"id":3622149}]}]}
{"op":"mcm","clk":"1009851507","pt":1580670106526,"mc":[{"id":"1.168230758","rc":[{"batb":[[0,3.25,38.24],[1,1.01,20.51],[2,1.01,0]],"ltp":3.0,"tv":977.69,"id":2263603},{"batb":[[0,1.2,234.71],[1,1.04,633.39],[2,1.03,844.52]],"batl":[[0,1.49,761.67],[1,3,3.18],[2,1.49,0]],"ltp":1.18,"tv":4699.77,"id":3622149}]}]}
{"op":"mcm","clk":"1009851896","pt":1580670109314,"mc":[{"id":"1.168230758","rc":[{"batb":[[0,1.21,1188.2],[1,1.2,1465.76],[2,1.04,633.39]],"batl":[[0,1.29,3.79],[1,1.43,599.92],[2,1.44,453.64]],"ltp":1.18,"tv":4699.77,"id":3622149}]}]}
{"op":"mcm","clk":"1009852339","pt":1580670112540,"mc":[{"id":"1.168230758","rc":[{"batb":[[0,1.2,234.71],[1,1.04,633.39],[2,1.03,844.52]],"ltp":1.18,"tv":4699.77,"id":3622149}]}]}
{"op":"mcm","clk":"1009852451","pt":1580670113501,"mc":[{"id":"1.168230758","rc":[{"batl":[[0,1.43,599.92],[1,1.44,453.64],[2,1.49,761.67]],"ltp":1.18,"tv":4699.77,"id":3622149}]}]}
{"op":"mcm","clk":"1009852578","pt":1580670114640,"mc":[{"id":"1.168230758","rc":[{"batb":[[0,1.22,113.63],[1,1.2,234.71],[2,1.04,633.39]],"ltp":1.18,"tv":4699.77,"id":3622149}]}]}
{"op":"mcm","clk":"1009852702","pt":1580670115640,"mc":[{"id":"1.168230758","rc":[{"batl":[[1,6.6,0]],"ltp":3.0,"tv":977.69,"id":2263603},{"batb":[[0,1.39,380.02],[1,1.38,563.08],[2,1.34,1685.33]],"batl":[[2,3,3.18]],"ltp":1.18,"tv":4699.77,"id":3622149}]}]}
{"op":"mcm","clk":"1009852833","pt":1580670116642,"mc":[{"id":"1.168230758","rc":[{"batb":[[1,2.74,24],[2,1.01,20.51]],"ltp":3.0,"tv":977.69,"id":2263603},{"batb":[[1,1.38,674.34]],"ltp":1.18,"tv":4699.77,"id":3622149}]}]}
{"op":"mcm","clk":"1009853070","pt":1580670118317,"mc":[{"id":"1.168230758","rc":[{"batb":[[2,1.28,161.06]],"ltp":1.18,"tv":4699.77,"id":3622149}]}]}
{"op":"mcm","clk":"1009853154","pt":1580670119037,"mc":[{"id":"1.168230758","rc":[{"batl":[[0,5.3,118.79],[1,6.4,2.52]],"ltp":3.0,"tv":977.69,"id":2263603},{"batl":[[2,1.73,527.57]],"ltp":1.18,"tv":4699.77,"id":3622149}]}]}
{"op":"mcm","clk":"1009853957","pt":1580670125514,"mc":[{"id":"1.168230758","rc":[{"batb":[[2,1.29,86.2]],"ltp":1.18,"tv":4699.77,"id":3622149}]}]}
{"op":"mcm","clk":"1009854093","pt":1580670126632,"mc":[{"id":"1.168230758","rc":[{"batb":[[0,2.74,24],[1,1.01,20.51],[2,1.01,0]],"ltp":3.0,"tv":977.69,"id":2263603},{"batb":[[0,1.29,86.2],[1,1.28,161.06],[2,1.04,633.39]],"batl":[[0,1.73,527.57],[1,3,3.18],[2,1.73,0]],"ltp":1.18,"tv":4699.77,"id":3622149}]}]}
{"op":"mcm","clk":"1009854218","pt":1580670127634,"mc":[{"id":"1.168230758","rc":[{"batl":[[0,1.39,3.79],[1,1.73,527.57],[2,3,3.18]],"ltp":1.18,"tv":4699.77,"id":3622149}]}]}
{"op":"mcm","clk":"1009854325","pt":1580670128533,"mc":[{"id":"1.168230758","rc":[{"batb":[[0,1.29,976.09],[1,1.28,996.35]],"batl":[[1,1.55,321.19],[2,1.56,332.66]],"ltp":1.18,"tv":4699.77,"id":3622149}]}]}
{"op":"mcm","clk":"1009855097","pt":1580670135558,"mc":[{"id":"1.168230758","rc":[{"batl":[[0,1.55,321.19],[1,1.56,332.66],[2,1.73,527.57]],"ltp":1.18,"tv":4699.77,"id":3622149}]}]}
{"op":"mcm","clk":"1009855456","pt":1580670138641,"mc":[{"id":"1.168230758","rc":[{"batb":[[0,1.29,889.89]],"ltp":1.18,"tv":4699.77,"id":3622149}]}]}
{"op":"mcm","clk":"1009855997","pt":1580670143149,"mc":[{"id":"1.168230758","rc":[{"batb":[[0,1.28,161.06],[1,1.04,633.39],[2,1.03,844.52]],"batl":[[0,1.73,527.57],[1,3,3.18],[2,1.73,0]],"ltp":1.18,"tv":4699.77,"id":3622149}]}]}
{"op":"mcm","clk":"1009856388","pt":1580670146465,"mc":[{"id":"1.168230758","rc":[{"batb":[[0,1.41,457.3],[1,1.4,527.91],[2,1.28,161.06]],"batl":[[0,1.45,425.33],[1,1.46,429.98],[2,1.73,527.57]],"ltp":1.18,"tv":4699.77,"id":3622149}]}]}
{"op":"mcm","clk":"1009856658","pt":1580670148641,"mc":[{"id":"1.168230758","rc":[{"batb":[[2,1.3,83.33]],"ltp":1.18,"tv":4699.77,"id":3622149}]}]}
{"op":"mcm","clk":"1009856896","pt":1580670150566,"mc":[{"id":"1.168230758","rc":[{"batb":[[0,1.3,83.33],[1,1.29,86.2],[2,1.28,161.06]],"batl":[[0,1.73,527.57],[1,3,3.18],[2,1.73,0]],"ltp":1.18,"tv":4699.77,"id":3622149}]}]}
{"op":"mcm","clk":"1009857272","pt":1580670153957,"mc":[{"id":"1.168230758","rc":[{"batb":[[1,1.29,1058.6],[2,1.28,996.63]],"batl":[[0,1.56,584.6],[1,1.57,323],[2,1.73,527.57]],"ltp":1.18,"tv":4699.77,"id":3622149}]}]}
{"op":"mcm","clk":"1009857545","pt":1580670156580,"mc":[{"id":"1.168230758","rc":[{"batb":[[0,1.29,1058.6],[1,1.28,996.63],[2,1.04,633.39]],"ltp":1.18,"tv":4699.77,"id":3622149}]}]}
{"op":"mcm","clk":"1009858198","pt":1580670162461,"mc":[{"id":"1.168230758","rc":[{"batb":[[0,1.29,86.2],[1,1.28,161.06]],"batl":[[0,1.55,25],[1,1.56,584.6],[2,1.57,323]],"ltp":1.18,"tv":4699.77,"id":3622149}]}]}
{"op":"mcm","clk":"1009858327","pt":1580670163572,"mc":[{"id":"1.168230758","rc":[{"batl":[[0,6.4,2.52],[1,6.4,0]],"ltp":3.0,"tv":977.69,"id":2263603},{"batl":[[0,1.56,584.6],[1,1.57,323],[2,1.73,527.57]],"ltp":1.18,"tv":4699.77,"id":3622149}]}]}
{"op":"mcm","clk":"1009858447","pt":1580670164579,"mc":[{"id":"1.168230758","rc":[{"batb":[[0,1.5,627.66],[1,1.49,404.84],[2,1.47,1219.17]],"ltp":1.18,"tv":4699.77,"id":3622149}]}]}
{"op":"mcm","clk":"1009858561","pt":1580670165487,"mc":[{"id":"1.168230758","rc":[{"batb":[[1,2.4,34.62],[2,1.01,20.51]],"ltp":3.0,"tv":977.69,"id":2263603},{"batb":[[0,1.5,705.16]],"ltp":1.18,"tv":4699.77,"id":3622149}]}]}
{"op":"mcm","clk":"1009858769","pt":1580670167372,"mc":[{"id":"1.168230758","rc":[{"batb":[[2,1.4,103.7]],"ltp":1.18,"tv":4699.77,"id":3622149}]}]}
{"op":"mcm","clk":"1009858862","pt":1580670168065,"mc":[{"id":"1.168230758","rc":[{"batl":[[0,4.2,148.03],[1,6.4,2.52]],"ltp":3.0,"tv":977.69,"id":2263603}]}]}
{"op":"mcm","clk":"1009859288","pt":1580670171582,"mc":[{"id":"1.168230758","rc":[{"trd":[[1.56,1.6]],"batl":[[0,1.56,583.8]],"ltp":1.56,"tv":4701.37,"id":3622149}],"tv":5679.06}]}
{"op":"mcm","clk":"1009859486","pt":1580670173297,"mc":[{"id":"1.168230758","rc":[{"trd":[[1.5,20.65]],"batb":[[0,1.5,701.35],[2,1.41,60.97]],"ltp":1.5,"tv":4708.98,"id":3622149}],"tv":5686.68}]}
{"op":"mcm","clk":"1009859967","pt":1580670177594,"mc":[{"id":"1.168230758","rc":[{"batb":[[0,1.5,77.5],[1,1.41,60.97],[2,1.4,103.7]],"batl":[[0,1.73,527.57],[1,3,3.18],[2,1.73,0]],"ltp":1.5,"tv":4708.98,"id":3622149}]}]}
{"op":"mcm","clk":"1009860086","pt":1580670178591,"mc":[{"id":"1.168230758","rc":[{"batb":[[0,2.4,34.46],[1,1.01,20.51],[2,1.01,0]],"ltp":3.0,"tv":977.69,"id":2263603},{"batb":[[0,1.41,60.97],[1,1.4,103.7],[2,1.04,633.39]],"ltp":1.5,"tv":4708.98,"id":3622149}]}]}
{"op":"mcm","clk":"1009860276","pt":1580670180276,"mc":[{"id":"1.168230758","rc":[{"batb":[[0,1.41,514.66],[1,1.4,630.85]],"batl":[[0,1.68,425.87],[1,1.7,492.51],[2,1.73,527.57]],"ltp":1.5,"tv":4708.98,"id":3622149}]}]}
{"op":"mcm","clk":"1009860427","pt":1580670181494,"mc":[{"id":"1.168230758","rc":[{"batb":[[0,1.41,60.97],[1,1.4,103.7]],"batl":[[0,1.73,527.57],[1,3,3.18],[2,1.73,0]],"ltp":1.5,"tv":4708.98,"id":3622149}]}]}
{"op":"mcm","clk":"1009860828","pt":1580670184496,"mc":[{"id":"1.168230758","rc":[{"batb":[[0,1.52,657.2],[1,1.51,383.81],[2,1.41,60.97]],"batl":[[0,1.58,467.41],[1,1.59,309.02],[2,1.73,527.57]],"ltp":1.5,"tv":4708.98,"id":3622149}]}]}
{"op":"mcm","clk":"1009861326","pt":1580670188615,"mc":[{"id":"1.168230758","rc":[{"batb":[[0,1.41,60.97],[1,1.4,103.7],[2,1.04,633.39]],"batl":[[0,1.73,527.57],[1,3,3.18],[2,1.73,0]],"ltp":1.5,"tv":4708.98,"id":3622149}]}]}
{"op":"mcm","clk":"1009861674","pt":1580670191618,"mc":[{"id":"1.168230758","rc":[{"batl":[[0,2.78,598],[1,4.2,148.03],[2,6.4,2.52]],"ltp":3.0,"tv":977.69,"id":2263603},{"batb":[[0,1.41,516],[1,1.4,630.85]],"batl":[[0,1.68,424.76],[1,1.7,492.51],[2,1.73,527.57]],"ltp":1.5,"tv":4708.98,"id":3622149}]}]}
{"op":"mcm","clk":"1009862149","pt":1580670195627,"mc":[{"id":"1.168230758","rc":[{"batb":[[0,1.41,60.97],[1,1.4,103.7]],"ltp":1.5,"tv":4708.98,"id":3622149}]}]}
{"op":"mcm","clk":"1009862260","pt":1580670196509,"mc":[{"id":"1.168230758","rc":[{"batb":[[0,1.4,103.7],[1,1.04,633.39],[2,1.03,844.52]],"ltp":1.5,"tv":4708.98,"id":3622149}]}]}
{"op":"mcm","clk":"1009862512","pt":1580670198629,"mc":[{"id":"1.168230758","rc":[{"batl":[[1,6.4,2.52],[2,6.4,0]],"ltp":3.0,"tv":977.69,"id":2263603},{"batb":[[0,1.62,327.26],[1,1.61,298.94],[2,1.6,955.02]],"batl":[[2,3,3.18]],"ltp":1.5,"tv":4708.98,"id":3622149}]}]}
{"op":"mcm","clk":"1009862593","pt":1580670199302,"mc":[{"id":"1.168230758","rc":[{"batb":[[1,2.2,43.2],[2,1.01,20.51]],"ltp":3.0,"tv":977.69,"id":2263603},{"batb":[[0,1.63,56.89],[1,1.62,327.26],[2,1.61,298.94]],"ltp":1.5,"tv":4708.98,"id":3622149}]}]}
{"op":"mcm","clk":"1009862840","pt":1580670201623,"mc":[{"id":"1.168230758","rc":[{"batl":[[1,3.9,158.24],[2,6.4,2.52]],"ltp":3.0,"tv":977.69,"id":2263603},{"batl":[[2,1.95,409.86]],"ltp":1.5,"tv":4708.98,"id":3622149}]}]}
{"op":"mcm","clk":"1009862856","pt":1580670201728,"mc":[{"id":"1.168230758","rc":[{"batl":[[2,6.4,0]],"ltp":3.0,"tv":977.69,"id":2263603}]}]}
{"op":"mcm","clk":"1009863880","pt":1580670210606,"mc":[{"id":"1.168230758","rc":[{"trd":[[2.6,3.37]],"ltp":2.6,"tv":981.07,"id":2263603},{"trd":[[1.63,106.2]],"batb":[[0,1.63,51.5]],"ltp":1.63,"tv":4714.37,"id":3622149}],"tv":5695.44}]}
{"op":"mcm","clk":"1009863998","pt":1580670211620,"mc":[{"id":"1.168230758","rc":[{"batb":[[0,2.2,43.2],[1,1.01,20.51],[2,1.01,0]],"ltp":2.6,"tv":981.07,"id":2263603},{"batb":[[0,1.55,68.37],[1,1.04,633.39],[2,1.03,844.52]],"batl":[[0,1.95,409.86],[1,3,3.18],[2,1.95,0]],"ltp":1.63,"tv":4714.37,"id":3622149}]}]}
{"op":"mcm","clk":"1009864257","pt":1580670213638,"mc":[{"id":"1.168230758","rc":[{"batl":[[0,3.9,158.24],[1,3.9,0]],"ltp":2.6,"tv":981.07,"id":2263603},{"batb":[[0,1.55,575.16],[1,1.54,354.24],[2,1.04,633.39]],"batl":[[0,1.76,377.85],[1,1.78,423.23],[2,1.95,409.86]],"ltp":1.63,"tv":4714.37,"id":3622149}]}]}
{"op":"mcm","clk":"1009864347","pt":1580670214230,"mc":[{"id":"1.168230758","rc":[{"batb":[[0,2.22,43.12]],"ltp":2.6,"tv":981.07,"id":2263603},{"batb":[[0,1.55,68.37],[1,1.04,633.39],[2,1.03,844.52]],"batl":[[0,1.95,409.86],[1,3,3.18],[2,1.95,0]],"ltp":1.63,"tv":4714.37,"id":3622149}]}]}
{"op":"mcm","clk":"1009864757","pt":1580670217580,"mc":[{"id":"1.168230758","rc":[{"batb":[[0,1.63,475.55],[1,1.62,292.68],[2,1.55,68.37]],"batl":[[0,1.7,498.99],[1,1.72,472.97],[2,1.95,409.86]],"ltp":1.63,"tv":4714.37,"id":3622149}]}]}
{"op":"mcm","clk":"1009864963","pt":1580670219314,"mc":[{"id":"1.168230758","rc":[{"batl":[[0,3.65,170.41]],"ltp":2.6,"tv":981.07,"id":2263603}]}]}
{"op":"mcm","clk":"1009865198","pt":1580670221216,"mc":[{"id":"1.168230758","rc":[{"batb":[[0,1.55,68.37],[1,1.04,633.39],[2,1.03,844.52]],"batl":[[0,1.95,409.86],[1,3,3.18],[2,1.95,0]],"ltp":1.63,"tv":4714.37,"id":3622149}]}]}
{"op":"mcm","clk":"1009865520","pt":1580670224244,"mc":[{"id":"1.168230758","rc":[{"batb":[[0,1.55,625.69],[1,1.54,354.3],[2,1.04,633.39]],"batl":[[0,1.76,334.43],[1,1.78,423.2],[2,1.95,409.86]],"ltp":1.63,"tv":4714.37,"id":3622149}]}]}
{"op":"mcm","clk":"1009865997","pt":1580670228452,"mc":[{"id":"1.168230758","rc":[{"batb":[[0,1.55,68.37],[1,1.04,633.39],[2,1.03,844.52]],"ltp":1.63,"tv":4714.37,"id":3622149}]}]}
{"op":"mcm","clk":"1009866135","pt":1580670229551,"mc":[{"id":"1.168230758","rc":[{"trd":[[2.22,25.3],[2.28,330.39],[2.3,254.96]],"batb":[[0,2.22,30.47]],"ltp":2.22,"tv":1591.72,"id":2263603},{"trd":[[1.76,335.68],[1.78,423.2]],"batl":[[0,1.95,409.86],[1,3,3.18],[2,1.95,0]],"ltp":1.78,"tv":5473.25,"id":3622149}],"tv":7064.97}]}
{"op":"mcm","clk":"1009866387","pt":1580670231647,"mc":[{"id":"1.168230758","rc":[{"batb":[[0,1.69,830.45],[1,1.55,1499.76],[2,1.04,633.39]],"ltp":1.78,"tv":5473.25,"id":3622149}]}]}
{"op":"mcm","clk":"1009866448","pt":1580670232142,"mc":[{"id":"1.168230758","rc":[{"batb":[[1,1.94,31.71],[2,1.01,20.51]],"ltp":2.22,"tv":1591.72,"id":2263603},{"batb":[[0,1.73,46.5],[1,1.69,830.45],[2,1.52,74.12]],"ltp":1.78,"tv":5473.25,"id":3622149}]}]}
{"op":"mcm","clk":"1009866605","pt":1580670233450,"mc":[{"id":"1.168230758","rc":[{"batl":[[0,3.45,180.4]],"ltp":2.22,"tv":1591.72,"id":2263603},{"batb":[[1,1.7,430.41],[2,1.69,830.45]],"batl":[[0,1.77,335.59],[1,1.79,414.81],[2,1.95,409.86]],"ltp":1.78,"tv":5473.25,"id":3622149}]}]}
{"op":"mcm","clk":"1009866729","pt":1580670234537,"mc":[{"id":"1.168230758","rc":[{"batb":[[2,1.68,509.45]],"ltp":1.78,"tv":5473.25,"id":3622149}]}]}
{"op":"mcm","clk":"1009866972","pt":1580670236540,"mc":[{"id":"1.168230758","rc":[{"batb":[[0,1.94,31.71],[1,1.01,20.51],[2,1.01,0]],"ltp":2.22,"tv":1591.72,"id":2263603},{"batb":[[0,1.7,430.41],[1,1.68,509.45],[2,1.52,74.12]],"ltp":1.78,"tv":5473.25,"id":3622149}]}]}
{"op":"mcm","clk":"1009867315","pt":1580670239544,"mc":[{"id":"1.168230758","rc":[{"batb":[[0,2.2,43.43],[1,1.94,31.71],[2,1.01,20.51]],"ltp":2.22,"tv":1591.72,"id":2263603},{"batb":[[0,1.74,46.26],[1,1.7,430.41],[2,1.68,509.45]],"ltp":1.78,"tv":5473.25,"id":3622149}]}]}
{"op":"mcm","clk":"1009868814","pt":1580670252462,"mc":[{"id":"1.168230758","rc":[{"trd":[[2.36,2.11]],"ltp":2.36,"tv":1593.83,"id":2263603},{"trd":[[1.74,2.86]],"batb":[[0,1.74,43.4]],"ltp":1.74,"tv":5476.11,"id":3622149}],"tv":7069.94}]}
{"op":"mcm","clk":"1009869752","pt":1580670260582,"mc":[{"id":"1.168230758","rc":[{"batb":[[0,2.22,42.96],[1,2.2,43.43],[2,1.95,63.18]],"ltp":2.36,"tv":1593.83,"id":2263603},{"batb":[[1,1.73,46.74],[2,1.7,430.41]],"ltp":1.74,"tv":5476.11,"id":3622149}]}]}
{"op":"mcm","clk":"1009869850","pt":1580670261375,"mc":[{"id":"1.168230758","rc":[{"batb":[[1,1.95,63.18],[2,1.01,20.51]],"ltp":2.36,"tv":1593.83,"id":2263603},{"batb":[[0,1.73,46.74],[1,1.7,430.41],[2,1.68,509.45]],"ltp":1.74,"tv":5476.11,"id":3622149}]}]}
{"op":"mcm","clk":"1009869985","pt":1580670262578,"mc":[{"id":"1.168230758","rc":[{"batb":[[0,2.22,42.8],[1,1.95,62.95]],"ltp":2.36,"tv":1593.83,"id":2263603}]}]}
{"op":"mcm","clk":"1009870854","pt":1580670270648,"mc":[{"id":"1.168230758","rc":[{"batb":[[1,1.96,62.16],[2,1.95,62.95]],"ltp":2.36,"tv":1593.83,"id":2263603}]}]}
{"op":"mcm","clk":"1009870980","pt":1580670271594,"mc":[{"id":"1.168230758","rc":[{"batb":[[0,2.22,42.17],[2,1.01,20.51]],"ltp":2.36,"tv":1593.83,"id":2263603}]}]}
{"op":"mcm","clk":"1009871496","pt":1580670276463,"mc":[{"id":"1.168230758","rc":[{"trd":[[2.28,430.39]],"ltp":2.28,"tv":1693.83,"id":2263603},{"trd":[[1.77,128.81]],"batl":[[0,1.77,206.78]],"ltp":1.77,"tv":5604.92,"id":3622149}],"tv":7298.75}]}
{"op":"mcm","clk":"1009871905","pt":1580670280193,"mc":[{"id":"1.168230758","rc":[{"batl":[[0,1.77,280.07]],"ltp":1.77,"tv":5604.92,"id":3622149}]}]}
{"op":"mcm","clk":"1009873865","pt":1580670297998,"mc":[{"id":"1.168230758","rc":[{"batb":[[0,1.96,62.16],[1,1.01,20.51],[2,1.01,0]],"ltp":2.28,"tv":1693.83,"id":2263603},{"batb":[[0,1.7,430.41],[1,1.68,509.45],[2,1.52,74.43]],"ltp":1.77,"tv":5604.92,"id":3622149}]}]}
{"op":"mcm","clk":"1009874247","pt":1580670301295,"mc":[{"id":"1.168230758","rc":[{"trd":[[2.28,480.39]],"ltp":2.28,"tv":1743.83,"id":2263603},{"trd":[[1.77,193.22]],"batl":[[0,1.77,215.66]],"ltp":1.77,"tv":5669.33,"id":3622149}],"tv":7413.16}]}
{"op":"mcm","clk":"1009874390","pt":1580670302402,"mc":[{"id":"1.168230758","rc":[{"batb":[[0,1.52,74.43],[1,1.01,20.51],[2,1.52,0]],"ltp":1.77,"tv":5669.33,"id":3622149}]}]}
{"op":"mcm","clk":"1009874678","pt":1580670304604,"mc":[{"id":"1.168230758","rc":[{"batb":[[0,1.71,260.08],[1,1.69,497.83],[2,1.52,74.43]],"ltp":1.77,"tv":5669.33,"id":3622149}]}]}
{"op":"mcm","clk":"1009875521","pt":1580670311215,"mc":[{"id":"1.168230758","rc":[{"trd":[[2.28,519.73]],"ltp":2.28,"tv":1783.17,"id":2263603},{"trd":[[1.77,243.89]],"batl":[[0,1.77,164.99]],"ltp":1.77,"tv":5720.0,"id":3622149}],"tv":7503.17}]}
{"op":"mcm","clk":"1009875796","pt":1580670313394,"mc":[{"id":"1.168230758","rc":[{"batl":[[0,2.5,29.41],[1,3.45,180.4]],"ltp":2.28,"tv":1783.17,"id":2263603}]}]}
{"op":"mcm","clk":"1009875943","pt":1580670314610,"mc":[{"id":"1.168230758","rc":[{"batb":[[0,1.01,20.51],[1,1.01,0]],"ltp":2.28,"tv":1783.17,"id":2263603},{"batb":[[0,1.01,20.51],[1,1.69,0],[2,1.52,0]],"batl":[[0,1.95,409.86],[1,3,3.18],[2,1.95,0]],"ltp":1.77,"tv":5720.0,"id":3622149}]}]}
{"op":"mcm","clk":"1009876317","pt":1580670317518,"mc":[{"id":"1.168230758","rc":[{"batb":[[0,1.51,463.48],[1,1.5,390.91],[2,1.01,20.51]],"batl":[[1,2.02,446.66],[2,2.04,278.49]],"ltp":1.77,"tv":5720.0,"id":3622149}]}]}
{"op":"mcm","clk":"1009877490","pt":1580670327540,"mc":[{"id":"1.168230758","rc":[{"batl":[[1,3,3.18],[2,2.04,0]],"ltp":1.77,"tv":5720.0,"id":3622149}]}]}
{"op":"mcm","clk":"1009877727","pt":1580670329644,"mc":[{"id":"1.168230758","rc":[{"trd":[[2.5,29.41]],"ltp":2.5,"tv":1812.57,"id":2263603},{"trd":[[1.66,44.29]],"batl":[[0,1.56,359.97],[1,1.57,322.44],[2,1.63,528.73]],"ltp":1.66,"tv":5764.28,"id":3622149}],"tv":7576.86}]}
{"op":"mcm","clk":"1009877799","pt":1580670330220,"mc":[{"id":"1.168230758","rc":[{"batb":[[0,2.72,24.71],[1,2.26,40.13],[2,1.01,20.51]],"ltp":2.5,"tv":1812.57,"id":2263603},{"batb":[[0,1.52,75.53],[1,1.51,463.48],[2,1.5,390.91]],"ltp":1.66,"tv":5764.28,"id":3622149}]}]}
{"op":"mcm","clk":"1009877896","pt":1580670331154,"mc":[{"id":"1.168230758","rc":[{"batl":[[2,1.58,25.75]],"ltp":1.66,"tv":5764.28,"id":3622149}]}]}
{"op":"mcm","clk":"1009878071","pt":1580670332628,"mc":[{"id":"1.168230758","rc":[{"batl":[[0,4.6,136.05]],"ltp":2.5,"tv":1812.57,"id":2263603},{"batl":[[2,1.82,469.11]],"ltp":1.66,"tv":5764.28,"id":3622149}]}]}
{"op":"mcm","clk":"1009878277","pt":1580670334412,"mc":[{"id":"1.168230758","rc":[{"trd":[[1.56,95.86]],"batl":[[0,1.56,312.84]],"ltp":1.56,"tv":5858.54,"id":3622149}],"tv":7671.12}]}
{"op":"mcm","clk":"1009878655","pt":1580670337638,"mc":[{"id":"1.168230758","rc":[{"batb":[[0,2.26,40.13],[1,1.01,20.51],[2,1.01,0]],"ltp":2.5,"tv":1812.57,"id":2263603},{"batb":[[0,1.34,126.52],[1,1.01,20.51],[2,1.5,0]],"batl":[[0,1.82,469.11],[1,3,3.18],[2,1.82,0]],"ltp":1.56,"tv":5858.54,"id":3622149}]}]}
{"op":"mcm","clk":"1009879026","pt":1580670340613,"mc":[{"id":"1.168230758","rc":[{"batb":[[0,1.35,420.6],[1,1.34,770.32],[2,1.01,20.51]],"batl":[[0,1.76,360.23],[1,1.78,421.76],[2,1.82,469.11]],"ltp":1.56,"tv":5858.54,"id":3622149}]}]}
{"op":"mcm","clk":"1009879116","pt":1580670341451,"mc":[{"id":"1.168230758","rc":[{"batb":[[0,1.34,126.52],[1,1.01,20.51],[2,1.01,0]],"batl":[[0,1.82,469.11],[1,3,3.18],[2,1.82,0]],"ltp":1.56,"tv":5858.54,"id":3622149}]}]}
{"op":"mcm","clk":"1009879501","pt":1580670344454,"mc":[{"id":"1.168230758","rc":[{"batb":[[0,1.47,688.24],[1,1.46,438.41],[2,1.34,126.52]],"batl":[[0,1.52,311.74],[1,1.53,355.36],[2,1.82,469.11]],"ltp":1.56,"tv":5858.54,"id":3622149}]}]}
{"op":"mcm","clk":"1009879697","pt":1580670346157,"mc":[{"id":"1.168230758","rc":[{"batb":[[0,1.34,126.52],[1,1.01,20.51],[2,1.34,0]],"batl":[[0,1.82,469.11],[1,3,3.18],[2,1.82,0]],"ltp":1.56,"tv":5858.54,"id":3622149}]}]}
{"op":"mcm","clk":"1009880065","pt":1580670349389,"mc":[{"id":"1.168230758","rc":[{"batb":[[0,1.35,420.6],[1,1.34,770.32],[2,1.01,20.51]],"batl":[[0,1.76,360.23],[1,1.78,421.76],[2,1.82,469.11]],"ltp":1.56,"tv":5858.54,"id":3622149}]}]}
{"op":"mcm","clk":"1009880607","pt":1580670354483,"mc":[{"id":"1.168230758","rc":[{"batl":[[0,3.4,8.4],[1,4.6,136.05]],"ltp":2.5,"tv":1812.57,"id":2263603}]}]}
{"op":"mcm","clk":"1009880737","pt":1580670355592,"mc":[{"id":"1.168230758","rc":[{"batl":[[0,1.82,469.11],[1,3,3.18],[2,1.82,0]],"ltp":1.56,"tv":5858.54,"id":3622149}]}]}
{"op":"mcm","clk":"1009880956","pt":1580670357595,"mc":[{"id":"1.168230758","rc":[{"trd":[[3.4,8.4]],"ltp":3.4,"tv":1820.98,"id":2263603},{"trd":[[1.41,20.26]],"batl":[[0,1.39,765.03],[1,1.4,505.38],[2,1.42,573.01]],"ltp":1.41,"tv":5878.8,"id":3622149}],"tv":7699.78}]}
{"op":"mcm","clk":"1009881065","pt":1580670358500,"mc":[{"id":"1.168230758","rc":[{"batb":[[0,3.5,32.18],[1,2.86,21.56],[2,1.01,20.51]],"ltp":3.4,"tv":1820.98,"id":2263603},{"batb":[[2,1.22,211.18]],"ltp":1.41,"tv":5878.8,"id":3622149}]}]}
{"op":"mcm","clk":"1009881295","pt":1580670360613,"mc":[{"id":"1.168230758","rc":[{"batl":[[2,3,3.18]],"ltp":1.41,"tv":5878.8,"id":3622149}]}]}
{"op":"mcm","clk":"1009881421","pt":1580670361580,"mc":[{"id":"1.168230758","rc":[{"batl":[[0,6,106.18]],"ltp":3.4,"tv":1820.98,"id":2263603},{"batl":[[2,1.66,579.81]],"ltp":1.41,"tv":5878.8,"id":3622149}]}]}
{"op":"mcm","clk":"1009882410","pt":1580670369631,"mc":[{"id":"1.168230758","rc":[{"batb":[[0,1.34,126.52],[1,1.22,211.18],[2,1.01,20.51]],"batl":[[0,1.66,579.81],[1,3,3.18],[2,1.66,0]],"ltp":1.41,"tv":5878.8,"id":3622149}]}]}
{"op":"mcm","clk":"1009882516","pt":1580670370587,"mc":[{"id":"1.168230758","rc":[{"batb":[[0,2.86,21.56],[1,1.01,20.51],[2,1.01,0]],"ltp":3.4,"tv":1820.98,"id":2263603},{"batb":[[0,1.22,211.18],[1,1.01,20.51],[2,1.01,0]],"ltp":1.41,"tv":5878.8,"id":3622149}]}]}
{"op":"mcm","clk":"1009882767","pt":1580670372606,"mc":[{"id":"1.168230758","rc":[{"batb":[[0,1.23,1065.08],[1,1.22,1327.13],[2,1.01,20.51]],"batl":[[0,1.52,513.73],[1,1.53,354.17],[2,1.66,579.81]],"ltp":1.41,"tv":5878.8,"id":3622149}]}]}
{"op":"mcm","clk":"1009882891","pt":1580670373612,"mc":[{"id":"1.168230758","rc":[{"batl":[[0,1.52,588.68]],"ltp":1.41,"tv":5878.8,"id":3622149}]}]}
{"op":"mcm","clk":"1009883637","pt":1580670379296,"mc":[{"id":"1.168230758","rc":[{"batb":[[0,1.22,211.18],[1,1.01,20.51],[2,1.01,0]],"ltp":1.41,"tv":5878.8,"id":3622149}]}]}
{"op":"mcm","clk":"1009884011","pt":1580670382305,"mc":[{"id":"1.168230758","rc":[{"batb":[[0,1.47,396.05],[1,1.46,437.02],[2,1.42,1364.31]],"ltp":1.41,"tv":5878.8,"id":3622149}]}]}
{"op":"mcm","clk":"1009884167","pt":1580670383631,"mc":[{"id":"1.168230758","rc":[{"batb":[[1,2.3,38.87],[2,1.01,20.51]],"ltp":3.4,"tv":1820.98,"id":2263603},{"batb":[[0,1.47,480.32]],"ltp":1.41,"tv":5878.8,"id":3622149}]}]}
{"op":"mcm","clk":"1009884412","pt":1580670385499,"mc":[{"id":"1.168230758","rc":[{"batl":[[0,4.9,126.27]],"ltp":3.4,"tv":1820.98,"id":2263603},{"batb":[[2,1.28,160.12]],"ltp":1.41,"tv":5878.8,"id":3622149}]}]}
{"op":"mcm","clk":"1009885104","pt":1580670391405,"mc":[{"id":"1.168230758","rc":[{"trd":[[3.15,3.37]],"ltp":3.15,"tv":1824.35,"id":2263603},{"trd":[[1.47,7.23]],"batb":[[0,1.47,473.09]],"ltp":1.47,"tv":5886.03,"id":3622149}],"tv":7710.39}]}
{"op":"mcm","clk":"1009885256","pt":1580670392620,"mc":[{"id":"1.168230758","rc":[{"batb":[[0,1.47,84.27],[1,1.28,160.12],[2,1.01,20.51]],"batl":[[0,1.66,579.81],[1,3,3.18],[2,1.66,0]],"ltp":1.47,"tv":5886.03,"id":3622149}]}]}
{"op":"mcm","clk":"1009885329","pt":1580670393207,"mc":[{"id":"1.168230758","rc":[{"batb":[[0,2.3,38.87],[1,1.01,20.51],[2,1.01,0]],"ltp":3.15,"tv":1824.35,"id":2263603},{"batb":[[0,1.28,160.12],[1,1.01,20.51],[2,1.01,0]],"ltp":1.47,"tv":5886.03,"id":3622149}]}]}
{"op":"mcm","clk":"1009885616","pt":1580670395537,"mc":[{"id":"1.168230758","rc":[{"batb":[[0,1.29,537],[1,1.28,983.47],[2,1.01,20.51]],"batl":[[1,1.74,323.36],[2,1.76,438.46]],"ltp":1.47,"tv":5886.03,"id":3622149}]}]}
{"op":"mcm","clk":"1009888462","pt":1580670418560,"mc":[{"id":"1.168230758","rc":[{"batl":[[1,3,3.18],[2,1.76,0]],"ltp":1.47,"tv":5886.03,"id":3622149}]}]}
{"op":"mcm","clk":"1009888803","pt":1580670421560,"mc":[{"id":"1.168230758","rc":[{"batl":[[0,1.32,529.95],[1,1.33,647.55],[2,1.36,573.01]],"ltp":1.47,"tv":5886.03,"id":3622149}]}]}
{"op":"mcm","clk":"1009888954","pt":1580670422642,"mc":[{"id":"1.168230758","rc":[{"batb":[[0,4,47.13],[1,3.15,42.25],[2,1.01,20.51]],"ltp":3.15,"tv":1824.35,"id":2263603},{"batb":[[2,1.17,283.96]],"ltp":1.47,"tv":5886.03,"id":3622149}]}]}
{"op":"mcm","clk":"1009889158","pt":1580670424336,"mc":[{"id":"1.168230758","rc":[{"batl":[[0,6.6,98.95]],"ltp":3.15,"tv":1824.35,"id":2263603},{"batl":[[2,1.66,579.81]],"ltp":1.47,"tv":5886.03,"id":3622149}]}]}
{"op":"mcm","clk":"1009890849","pt":1580670438410,"mc":[{"id":"1.168230758","rc":[{"batb":[[0,3.15,42.25],[1,1.01,20.51],[2,1.01,0]],"ltp":3.15,"tv":1824.35,"id":2263603},{"batb":[[0,1.17,283.96],[1,1.01,20.51],[2,1.17,0]],"batl":[[0,1.66,579.81],[1,3,3.18],[2,1.66,0]],"ltp":1.47,"tv":5886.03,"id":3622149}]}]}
{"op":"mcm","clk":"1009891239","pt":1580670441285,"mc":[{"id":"1.168230758","rc":[{"batb":[[0,1.18,1265.21],[1,1.17,1499.81],[2,1.01,20.51]],"batl":[[0,1.44,321.16],[1,1.45,441.42],[2,1.66,579.81]],"ltp":1.47,"tv":5886.03,"id":3622149}]}]}
{"op":"mcm","clk":"1009891656","pt":1580670444416,"mc":[{"id":"1.168230758","rc":[{"batb":[[0,1.17,283.96],[1,1.01,20.51],[2,1.01,0]],"ltp":1.47,"tv":5886.03,"id":3622149}]}]}
{"op":"mcm","clk":"1009892082","pt":1580670447575,"mc":[{"id":"1.168230758","rc":[{"batb":[[1,2.3,38.16],[2,1.01,20.51]],"ltp":3.15,"tv":1824.35,"id":2263603},{"batb":[[0,1.4,716.85],[1,1.39,2014.25],[2,1.18,269.88]],"ltp":1.47,"tv":5886.03,"id":3622149}]}]}
{"op":"mcm","clk":"1009892365","pt":1580670450008,"mc":[{"id":"1.168230758","rc":[{"batl":[[0,5.3,118.79]],"ltp":3.15,"tv":1824.35,"id":2263603},{"batb":[[1,1.39,544.99]],"ltp":1.47,"tv":5886.03,"id":3622149}]}]}
{"op":"mcm","clk":"1009893467","pt":1580670458518,"mc":[{"id":"1.168230758","rc":[{"batb":[[0,2.3,38.16],[1,1.01,20.51],[2,1.01,0]],"ltp":3.15,"tv":1824.35,"id":2263603},{"batb":[[0,1.18,269.88],[1,1.01,20.51],[2,1.18,0]],"batl":[[0,1.66,579.81],[1,3,3.18],[2,1.66,0]],"ltp":1.47,"tv":5886.03,"id":3622149}]}]}
{"op":"mcm","clk":"1009893728","pt":1580670460617,"mc":[{"id":"1.168230758","rc":[{"batl":[[0,3,3.18],[1,3,0]],"ltp":1.47,"tv":5886.03,"id":3622149}]}]}
{"op":"mcm","clk":"1009893815","pt":1580670461325,"mc":[{"id":"1.168230758","rc":[{"batb":[[0,1.19,584.4],[1,1.18,1664.29],[2,1.01,20.51]],"batl":[[0,1.74,469.53],[1,1.76,438.25],[2,3,3.18]],"ltp":1.47,"tv":5886.03,"id":3622149}]}]}
{"op":"mcm","clk":"1009893963","pt":1580670462498,"mc":[{"id":"1.168230758","rc":[{"batb":[[0,1.18,269.88],[1,1.01,20.51],[2,1.01,0]],"batl":[[0,3,3.18],[1,1.76,0],[2,3,0]],"ltp":1.47,"tv":5886.03,"id":3622149}]}]}
{"op":"mcm","clk":"1009894287","pt":1580670465146,"mc":[{"id":"1.168230758","rc":[{"batb":[[0,1.35,760.41],[1,1.34,651.17],[2,1.18,269.88]],"batl":[[0,1.39,480.47],[1,1.4,511.13],[2,3,3.18]],"ltp":1.47,"tv":5886.03,"id":3622149}]}]}
{"op":"mcm","clk":"1009894578","pt":1580670467545,"mc":[{"id":"1.168230758","rc":[{"batl":[[0,6,106.18]],"ltp":3.15,"tv":1824.35,"id":2263603},{"batb":[[0,1.18,269.88],[1,1.01,20.51],[2,1.18,0]],"batl":[[0,1.66,579.81],[1,3,3.18],[2,3,0]],"ltp":1.47,"tv":5886.03,"id":3622149}]}]}
{"op":"mcm","clk":"1009894836","pt":1580670469563,"mc":[{"id":"1.168230758","rc":[{"batl":[[0,3,3.18],[1,3,0]],"ltp":1.47,"tv":5886.03,"id":3622149}]}]}
{"op":"mcm","clk":"1009894946","pt":1580670470461,"mc":[{"id":"1.168230758","rc":[{"batb":[[0,1.19,584.4],[1,1.18,1664.29],[2,1.01,20.51]],"batl":[[0,1.74,469.53],[1,1.76,438.25],[2,3,3.18]],"ltp":1.47,"tv":5886.03,"id":3622149}]}]}
{"op":"mcm","clk":"1009896242","pt":1580670480630,"mc":[{"id":"1.168230758","rc":[{"batl":[[0,3,3.18],[1,1.76,0],[2,3,0]],"ltp":1.47,"tv":5886.03,"id":3622149}]}]}
{"op":"mcm","clk":"1009896648","pt":1580670483639,"mc":[{"id":"1.168230758","rc":[{"batl":[[0,1.21,609.8],[1,1.22,1050.79],[2,1.25,573.01]],"ltp":1.47,"tv":5886.03,"id":3622149}]}]}
{"op":"mcm","clk":"1009896760","pt":1580670484322,"mc":[{"id":"1.168230758","rc":[{"batb":[[0,5.5,21.64],[1,4.2,42.17],[2,1.01,20.51]],"ltp":3.15,"tv":1824.35,"id":2263603},{"batb":[[0,1.19,435.1],[2,1.1,470.75]],"ltp":1.47,"tv":5886.03,"id":3622149}]}]}
{"op":"mcm","clk":"1009897076","pt":1580670486632,"mc":[{"id":"1.168230758","rc":[{"batl":[[0,9.8,75.27]],"ltp":3.15,"tv":1824.35,"id":2263603},{"batl":[[2,1.49,761.67]],"ltp":1.47,"tv":5886.03,"id":3622149}]}]}
{"op":"mcm","clk":"1009897209","pt":1580670487633,"mc":[{"id":"1.168230758","rc":[{"batl":[[0,1.21,757.85]],"ltp":1.47,"tv":5886.03,"id":3622149}]}]}
{"op":"mcm","clk":"1009899696","pt":1580670507133,"mc":[{"id":"1.168230758","rc":[{"batl":[[0,6.8,2.52],[1,9.8,75.27]],"ltp":3.15,"tv":1824.35,"id":2263603}]}]}
{"op":"mcm","clk":"1009900573","pt":1580670514436,"mc":[{"id":"1.168230758","rc":[{"batb":[[0,4.2,42.17],[1,1.01,20.51],[2,1.01,0]],"ltp":3.15,"tv":1824.35,"id":2263603},{"batb":[[0,1.1,470.75],[1,1.01,20.51],[2,1.1,0]],"batl":[[0,1.49,761.67],[1,3,3.18],[2,1.49,0]],"ltp":1.47,"tv":5886.03,"id":3622149}]}]}
{"op":"mcm","clk":"1009900942","pt":1580670517552,"mc":[{"id":"1.168230758","rc":[{"batb":[[0,4.3,38.63]],"batl":[[0,6.8,6.72]],"ltp":3.15,"tv":1824.35,"id":2263603}]}]}
{"op":"mcm","clk":"1009901217","pt":1580670519568,"mc":[{"id":"1.168230758","rc":[{"batl":[[0,6.8,4.2]],"ltp":3.15,"tv":1824.35,"id":2263603}]}]}
{"op":"mcm","clk":"1009901442","pt":1580670521642,"mc":[{"id":"1.168230758","rc":[{"batb":[[0,1.2,1091.45],[1,1.19,1334.81],[2,1.1,470.75]],"batl":[[0,1.23,1051.76],[1,1.24,941.4],[2,1.49,761.67]],"ltp":1.47,"tv":5886.03,"id":3622149}]}]}
{"op":"mcm","clk":"1009901891","pt":1580670525485,"mc":[{"id":"1.168230758","rc":[{"batb":[[0,1.1,470.75],[1,1.01,20.51],[2,1.1,0]],"batl":[[0,1.49,761.67],[1,3,3.18],[2,1.49,0]],"ltp":1.47,"tv":5886.03,"id":3622149}]}]}
{"op":"mcm","clk":"1009902268","pt":1580670528471,"mc":[{"id":"1.168230758","rc":[{"batb":[[0,1.12,450.95],[1,1.11,2175.38],[2,1.1,470.75]],"batl":[[0,1.3,762.89],[1,1.31,699.4],[2,1.49,761.67]],"ltp":1.47,"tv":5886.03,"id":3622149}]}]}
{"op":"mcm","clk":"1009903674","pt":1580670539590,"mc":[{"id":"1.168230758","rc":[{"batl":[[0,1.49,761.67],[1,3,3.18],[2,1.49,0]],"ltp":1.47,"tv":5886.03,"id":3622149}]}]}
{"op":"mcm","clk":"1009904004","pt":1580670542588,"mc":[{"id":"1.168230758","rc":[{"trd":[[6.8,4.2]],"batl":[[0,9.8,75.27],[1,9.8,0]],"ltp":6.8,"tv":1828.55,"id":2263603},{"trd":[[1.17,41.22]],"batl":[[0,1.14,2096.39],[1,1.15,460.74],[2,1.17,548.6]],"ltp":1.17,"tv":5910.45,"id":3622149}],"tv":7739.0}]}
{"op":"mcm","clk":"1009904116","pt":1580670543482,"mc":[{"id":"1.168230758","rc":[{"batb":[[0,8.4,16.37],[1,5.8,39.66],[2,1.01,20.51]],"ltp":6.8,"tv":1828.55,"id":2263603}]}]}
{"op":"mcm","clk":"1009904158","pt":1580670543797,"mc":[{"id":"1.168230758","rc":[{"batl":[[2,3,3.18]],"ltp":1.17,"tv":5910.45,"id":3622149}]}]}
{"op":"mcm","clk":"1009904506","pt":1580670546595,"mc":[{"id":"1.168230758","rc":[{"batl":[[0,17,57.33]],"ltp":6.8,"tv":1828.55,"id":2263603},{"batl":[[2,1.4,927.7]],"ltp":1.17,"tv":5910.45,"id":3622149}]}]}
{"op":"mcm","clk":"1009904557","pt":1580670547002,"mc":[{"id":"1.168230758","rc":[{"trd":[[1.14,50.1]],"batl":[[0,1.14,2071.34]],"ltp":1.14,"tv":5960.55,"id":3622149}],"tv":7789.11}]}
{"op":"mcm","clk":"1009905974","pt":1580670559630,"mc":[{"id":"1.168230758","rc":[{"batb":[[0,1.1,470.75],[1,1.04,1114.14],[2,1.01,20.51]],"batl":[[0,1.4,927.7],[1,3,3.18],[2,1.4,0]],"ltp":1.14,"tv":5960.55,"id":3622149}]}]}
{"op":"mcm","clk":"1009906068","pt":1580670560435,"mc":[{"id":"1.168230758","rc":[{"batb":[[0,5.8,39.66],[1,1.01,20.51],[2,1.01,0]],"ltp":6.8,"tv":1828.55,"id":2263603},{"batb":[[0,1.04,1114.14],[1,1.01,20.51],[2,1.01,0]],"batl":[[0,1.12,3],[1,1.4,927.7],[2,3,3.18]],"ltp":1.14,"tv":5960.55,"id":3622149}]}]}
{"op":"mcm","clk":"1009906318","pt":1580670562406,"mc":[{"id":"1.168230758","rc":[{"batb":[[0,1.06,515.9],[1,1.05,2259.89],[2,1.04,1114.14]],"batl":[[1,1.21,794.43],[2,1.22,1050.48]],"ltp":1.14,"tv":5960.55,"id":3622149}]}]}
{"op":"mcm","clk":"1009906476","pt":1580670563634,"mc":[{"id":"1.168230758","rc":[{"batb":[[0,5.7,40.44]],"ltp":6.8,"tv":1828.55,"id":2263603},{"batb":[[0,1.04,1113.35],[1,1.01,20.51],[2,1.04,0]],"batl":[[1,3,3.18],[2,1.22,0]],"ltp":1.14,"tv":5960.55,"id":3622149}]}]}
{"op":"mcm","clk":"1009906809","pt":1580670566222,"mc":[{"id":"1.168230758","rc":[{"batb":[[0,1.13,1104.6],[1,1.12,1492.44],[2,1.04,1113.35]],"batl":[[0,1.15,1246.25],[1,1.16,1281.51],[2,3,3.18]],"ltp":1.14,"tv":5960.55,"id":3622149}]}]}
{"op":"mcm","clk":"1009907116","pt":1580670568616,"mc":[{"id":"1.168230758","rc":[{"batl":[[0,14,62.58]],"ltp":6.8,"tv":1828.55,"id":2263603},{"batl":[[2,1.43,872.38]],"ltp":1.14,"tv":5960.55,"id":3622149}]}]}
{"op":"mcm","clk":"1009907367","pt":1580670570421,"mc":[{"id":"1.168230758","rc":[{"batb":[[0,1.04,1113.35],[1,1.01,20.51],[2,1.04,0]],"batl":[[0,1.43,872.38],[1,3,3.18],[2,1.43,0]],"ltp":1.14,"tv":5960.55,"id":3622149}]}]}
{"op":"mcm","clk":"1009907769","pt":1580670573536,"mc":[{"id":"1.168230758","rc":[{"batb":[[0,1.06,515.9],[1,1.05,2259.89],[2,1.04,1113.35]],"batl":[[0,1.13,3],[1,1.21,794.43],[2,1.22,1050.48]],"ltp":1.14,"tv":5960.55,"id":3622149}]}]}
{"op":"mcm","clk":"1009907990","pt":1580670575143,"mc":[{"id":"1.168230758","rc":[{"batl":[[0,1.21,794.43],[1,1.22,1050.48],[2,3,3.18]],"ltp":1.14,"tv":5960.55,"id":3622149}]}]}
{"op":"mcm","clk":"1009908836","pt":1580670581346,"mc":[{"id":"1.168230758","rc":[{"batl":[[0,3,3.18],[1,1.22,0],[2,3,0]],"ltp":1.14,"tv":5960.55,"id":3622149}]}]}
{"op":"mcm","clk":"1009909231","pt":1580670584570,"mc":[{"id":"1.168230758","rc":[{"batb":[[0,15,10.62],[1,9,14.16],[2,1.01,20.51]],"ltp":6.8,"tv":1828.55,"id":2263603},{"batl":[[0,1.07,2199.79],[1,1.08,524.04],[2,1.1,573.01]],"ltp":1.14,"tv":5960.55,"id":3622149}]}]}
{"op":"mcm","clk":"1009909485","pt":1580670586570,"mc":[{"id":"1.168230758","rc":[{"batl":[[0,42,43.68]],"ltp":6.8,"tv":1828.55,"id":2263603}]}]}
{"op":"mcm","clk":"1009909601","pt":1580670587571,"mc":[{"id":"1.168230758","rc":[{"batl":[[2,1.34,1109.8]],"ltp":1.14,"tv":5960.55,"id":3622149}]}]}
{"op":"mcm","clk":"1009909970","pt":1580670590568,"mc":[{"id":"1.168230758","rc":[{"trd":[[1.06,6]],"batb":[[0,1.06,512.9]],"ltp":1.06,"tv":5966.55,"id":3622149}],"tv":7795.11}]}
{"op":"mcm","clk":"1009910812","pt":1580670597191,"mc":[{"id":"1.168230758","rc":[{"batb":[[0,9,14.16],[1,1.01,20.51],[2,1.01,0]],"ltp":6.8,"tv":1828.55,"id":2263603},{"batb":[[0,1.01,20.51],[1,1.05,0],[2,1.04,0]],"batl":[[0,1.34,1109.8],[1,3,3.18],[2,1.34,0]],"ltp":1.06,"tv":5966.55,"id":3622149}]}]}
{"op":"mcm","clk":"1009911053","pt":1580670599262,"mc":[{"id":"1.168230758","rc":[{"batl":[[0,3,3.18],[1,3,0]],"ltp":1.06,"tv":5966.55,"id":3622149}]}]}
{"op":"mcm","clk":"1009911603","pt":1580670603571,"mc":[{"id":"1.168230758","rc":[{"batb":[[0,1.06,2754.47],[1,1.01,20.51]],"batl":[[0,1.08,1960.33],[1,1.09,736.31],[2,3,3.18]],"ltp":1.06,"tv":5966.55,"id":3622149}]}]}
{"op":"mcm","clk":"1009911983","pt":1580670606597,"mc":[{"id":"1.168230758","rc":[{"batl":[[0,30,47.16]],"ltp":6.8,"tv":1828.55,"id":2263603},{"batl":[[2,1.35,1057.18]],"ltp":1.06,"tv":5966.55,"id":3622149}]}]}
{"op":"mcm","clk":"1009912210","pt":1580670608460,"mc":[{"id":"1.168230758","rc":[{"batb":[[0,1.01,20.51],[1,1.01,0]],"batl":[[0,1.35,1057.18],[1,3,3.18],[2,1.35,0]],"ltp":1.06,"tv":5966.55,"id":3622149}]}]}
{"op":"mcm","clk":"1009912388","pt":1580670609989,"mc":[{"id":"1.168230758","rc":[{"batl":[[0,3,3.18],[1,3,0]],"ltp":1.06,"tv":5966.55,"id":3622149}]}]}
{"op":"mcm","clk":"1009912569","pt":1580670611581,"mc":[{"id":"1.168230758","rc":[{"batb":[[0,1.01,2911.34]],"batl":[[0,1.12,995.6],[1,1.13,1597.05],[2,3,3.18]],"ltp":1.06,"tv":5966.55,"id":3622149}]}]}
{"op":"mcm","clk":"1009912794","pt":1580670613618,"mc":[{"id":"1.168230758","rc":[{"batb":[[0,1.01,20.51]],"ltp":1.06,"tv":5966.55,"id":3622149}]}]}
{"op":"mcm","clk":"1009913137","pt":1580670616584,"mc":[{"id":"1.168230758","rc":[{"batb":[[0,1.1,2586.54],[1,1.08,7162.65],[2,1.01,20.51]],"ltp":1.06,"tv":5966.55,"id":3622149}]}]}
{"op":"mcm","clk":"1009913343","pt":1580670618509,"mc":[{"id":"1.168230758","rc":[{"batb":[[1,5.7,40.05],[2,1.01,20.51]],"ltp":6.8,"tv":1828.55,"id":2263603},{"batb":[[1,1.09,550.77],[2,1.08,7162.65]],"ltp":1.06,"tv":5966.55,"id":3622149}]}]}
{"op":"mcm","clk":"1009913443","pt":1580670619408,"mc":[{"id":"1.168230758","rc":[{"batl":[[0,21,53.48]],"ltp":6.8,"tv":1828.55,"id":2263603},{"batb":[[2,1.02,1827.15]],"batl":[[2,1.38,972.97]],"ltp":1.06,"tv":5966.55,"id":3622149}]}]}
{"op":"mcm","clk":"1009914010","pt":1580670624101,"mc":[{"id":"1.168230758","rc":[{"trd":[[1.1,75.72]],"batb":[[0,1.1,2548.68]],"ltp":1.1,"tv":6042.27,"id":3622149}],"tv":7870.83}]}
{"op":"mcm","clk":"1009914424","pt":1580670627589,"mc":[{"id":"1.168230758","rc":[{"batb":[[2,1.03,1666.16]],"ltp":1.1,"tv":6042.27,"id":3622149}]}]}
{"op":"mcm","clk":"1009914907","pt":1580670631614,"mc":[{"id":"1.168230758","rc":[{"batb":[[0,1.09,550.77],[1,1.02,1827.15],[2,1.01,20.51]],"batl":[[0,1.38,972.97],[1,3,3.18],[2,1.38,0]],"ltp":1.1,"tv":6042.27,"id":3622149}]}]}
{"op":"mcm","clk":"1009914968","pt":1580670632096,"mc":[{"id":"1.168230758","rc":[{"batb":[[0,5.7,40.05],[1,1.01,20.51],[2,1.01,0]],"ltp":6.8,"tv":1828.55,"id":2263603},{"batb":[[0,1.02,1827.15],[1,1.01,20.51],[2,1.01,0]],"ltp":1.1,"tv":6042.27,"id":3622149}]}]}
{"op":"mcm","clk":"1009915265","pt":1580670634614,"mc":[{"id":"1.168230758","rc":[{"batb":[[0,1.03,2834.7],[1,1.02,1827.15],[2,1.01,20.51]],"batl":[[0,1.21,868.95],[1,1.22,1051.15],[2,3,3.18]],"ltp":1.1,"tv":6042.27,"id":3622149}]}]}
{"op":"mcm","clk":"1009916253","pt":1580670642533,"mc":[{"id":"1.168230758","rc":[{"batb":[[0,1.02,1827.15],[1,1.01,20.51],[2,1.01,0]],"ltp":1.1,"tv":6042.27,"id":3622149}]}]}
{"op":"mcm","clk":"1009916626","pt":1580670645619,"mc":[{"id":"1.168230758","rc":[{"batb":[[0,1.18,1722.18],[1,1.17,758.6],[2,1.14,4092.94]],"ltp":1.1,"tv":6042.27,"id":3622149}]}]}
{"op":"mcm","clk":"1009916755","pt":1580670646523,"mc":[{"id":"1.168230758","rc":[{"batb":[[1,3.8,52.32],[2,1.01,20.51]],"ltp":6.8,"tv":1828.55,"id":2263603},{"batb":[[1,1.17,1045.87]],"ltp":1.1,"tv":6042.27,"id":3622149}]}]}
{"op":"mcm","clk":"1009917002","pt":1580670648548,"mc":[{"id":"1.168230758","rc":[{"batl":[[0,9.8,75.27]],"ltp":6.8,"tv":1828.55,"id":2263603},{"batb":[[2,1.06,740.4]],"batl":[[2,1.49,761.67]],"ltp":1.1,"tv":6042.27,"id":3622149}]}]}
{"op":"mcm","clk":"1009918797","pt":1580670662555,"mc":[{"id":"1.168230758","rc":[{"batb":[[0,3.8,52.32],[1,1.01,20.51],[2,1.01,0]],"ltp":6.8,"tv":1828.55,"id":2263603},{"batb":[[0,1.06,740.4],[1,1.01,20.51],[2,1.06,0]],"batl":[[0,1.49,761.67],[1,3,3.18],[2,1.49,0]],"ltp":1.1,"tv":6042.27,"id":3622149}]}]}
{"op":"mcm","clk":"1009919063","pt":1580670664564,"mc":[{"id":"1.168230758","rc":[{"batl":[[0,3,3.18],[1,3,0]],"ltp":1.1,"tv":6042.27,"id":3622149}]}]}
{"op":"mcm","clk":"1009919191","pt":1580670665563,"mc":[{"id":"1.168230758","rc":[{"batb":[[0,3.9,49.25],[1,3.8,52.32],[2,1.01,20.51]],"ltp":6.8,"tv":1828.55,"id":2263603},{"batb":[[0,1.08,2076.52],[1,1.07,632.8],[2,1.06,740.4]],"batl":[[0,1.35,537.79],[1,1.36,586.66],[2,3,3.18]],"ltp":1.1,"tv":6042.27,"id":3622149}]}]}
{"op":"mcm","clk":"1009919348","pt":1580670666578,"mc":[{"id":"1.168230758","rc":[{"batb":[[1,1.01,20.51],[2,1.01,0]],"ltp":6.8,"tv":1828.55,"id":2263603}]}]}
{"op":"mcm","clk":"1009919751","pt":1580670669470,"mc":[{"id":"1.168230758","rc":[{"batl":[[0,3,3.18],[1,1.36,0],[2,3,0]],"ltp":1.1,"tv":6042.27,"id":3622149}]}]}
{"op":"mcm","clk":"1009920067","pt":1580670671642,"mc":[{"id":"1.168230758","rc":[{"batl":[[0,1.13,573.01],[1,3,3.18]],"ltp":1.1,"tv":6042.27,"id":3622149}]}]}
{"op":"mcm","clk":"1009920211","pt":1580670672549,"mc":[{"id":"1.168230758","rc":[{"batb":[[0,11.5,20.14],[1,5.9,37.77],[2,1.01,20.51]],"ltp":6.8,"tv":1828.55,"id":2263603},{"batl":[[0,1.1,2471.05],[1,1.13,573.01],[2,3,3.18]],"ltp":1.1,"tv":6042.27,"id":3622149}]}]}
{"op":"mcm","clk":"1009920636","pt":1580670675447,"mc":[{"id":"1.168230758","rc":[{"batl":[[0,24,50.52]],"ltp":6.8,"tv":1828.55,"id":2263603},{"batl":[[1,1.37,1010.69]],"ltp":1.1,"tv":6042.27,"id":3622149}]}]}
{"op":"mcm","clk":"1009922316","pt":1580670687262,"mc":[{"id":"1.168230758","rc":[{"batb":[[0,5.9,37.77],[1,1.01,20.51],[2,1.01,0]],"ltp":6.8,"tv":1828.55,"id":2263603},{"batb":[[0,1.01,20.51],[1,1.07,0],[2,1.06,0]],"batl":[[0,1.37,1010.69],[1,3,3.18],[2,3,0]],"ltp":1.1,"tv":6042.27,"id":3622149}]}]}
{"op":"mcm","clk":"1009922474","pt":1580670688382,"mc":[{"id":"1.168230758","rc":[{"batl":[[0,3,3.18],[1,3,0]],"ltp":1.1,"tv":6042.27,"id":3622149}]}]}
{"op":"mcm","clk":"1009922689","pt":1580670689806,"mc":[{"id":"1.168230758","rc":[{"batl":[[0,1.21,846.58],[1,1.22,1050.89],[2,3,3.18]],"ltp":1.1,"tv":6042.27,"id":3622149}]}]}
{"op":"mcm","clk":"1009925419","pt":1580670708585,"mc":[{"id":"1.168230758","rc":[{"batb":[[0,1.18,1744.17],[1,1.17,736.42],[2,1.14,4092.94]],"ltp":1.1,"tv":6042.27,"id":3622149}]}]}
{"op":"mcm","clk":"1009925494","pt":1580670709111,"mc":[{"id":"1.168230758","rc":[{"batb":[[1,3.9,48.94],[2,1.01,20.51]],"ltp":6.8,"tv":1828.55,"id":2263603},{"batb":[[2,1.16,297.81]],"ltp":1.1,"tv":6042.27,"id":3622149}]}]}
{"op":"mcm","clk":"1009925793","pt":1580670711203,"mc":[{"id":"1.168230758","rc":[{"batl":[[0,9.8,75.27]],"ltp":6.8,"tv":1828.55,"id":2263603},{"batl":[[2,1.49,761.67]],"ltp":1.1,"tv":6042.27,"id":3622149}]}]}
{"op":"mcm","clk":"1009927650","pt":1580670724632,"mc":[{"id":"1.168230758","rc":[{"trd":[[5.9,21.99]],"batb":[[0,5.9,26.77]],"ltp":5.9,"tv":1850.55,"id":2263603}],"tv":7892.82}]}
{"op":"mcm","clk":"1009927911","pt":1580670726602,"mc":[{"id":"1.168230758","rc":[{"batb":[[0,3.9,48.94],[1,1.01,20.51],[2,1.01,0]],"ltp":5.9,"tv":1850.55,"id":2263603},{"batb":[[0,1.06,770.69],[1,1.01,20.51],[2,1.16,0]],"batl":[[0,1.49,761.67],[1,3,3.18],[2,1.49,0]],"ltp":1.1,"tv":6042.27,"id":3622149}]}]}
{"op":"mcm","clk":"1009928142","pt":1580670728204,"mc":[{"id":"1.168230758","rc":[{"batl":[[0,3,3.18],[1,3,0]],"ltp":1.1,"tv":6042.27,"id":3622149}]}]}
{"op":"mcm","clk":"1009928351","pt":1580670729648,"mc":[{"id":"1.168230758","rc":[{"batb":[[0,1.08,2060.92],[1,1.07,648.55],[2,1.06,770.69]],"batl":[[0,1.35,542.52],[1,1.36,586.59],[2,3,3.18]],"ltp":1.1,"tv":6042.27,"id":3622149}]}]}
{"op":"mcm","clk":"1009929448","pt":1580670737550,"mc":[{"id":"1.168230758","rc":[{"batl":[[0,3,3.18],[1,1.36,0],[2,3,0]],"ltp":1.1,"tv":6042.27,"id":3622149}]}]}
{"op":"mcm","clk":"1009929837","pt":1580670740346,"mc":[{"id":"1.168230758","rc":[{"batl":[[0,1.1,2483.76],[1,1.13,573.01],[2,3,3.18]],"ltp":1.1,"tv":6042.27,"id":3622149}]}]}
{"op":"mcm","clk":"1009930026","pt":1580670741622,"mc":[{"id":"1.168230758","rc":[{"batb":[[0,11.5,20.06],[1,5.9,37.53],[2,1.01,20.51]],"ltp":5.9,"tv":1850.55,"id":2263603}]}]}
{"op":"mcm","clk":"1009930150","pt":1580670742520,"mc":[{"id":"1.168230758","rc":[{"batl":[[0,24,50.52]],"ltp":5.9,"tv":1850.55,"id":2263603},{"batl":[[2,1.37,1010.69]],"ltp":1.1,"tv":6042.27,"id":3622149}]}]}
{"op":"mcm","clk":"1009930313","pt":1580670743628,"mc":[{"id":"1.168230758","rc":[{"batl":[[1,1.37,1010.69],[2,3,3.18]],"ltp":1.1,"tv":6042.27,"id":3622149}]}]}
{"op":"mcm","clk":"1009931054","pt":1580670749217,"mc":[{"id":"1.168230758","rc":[{"trd":[[11.5,3.36]],"batb":[[0,11.5,18.38]],"ltp":11.5,"tv":1853.91,"id":2263603}],"tv":7896.18}]}
{"op":"mcm","clk":"1009932388","pt":1580670758537,"mc":[{"id":"1.168230758","rc":[{"batb":[[0,5.9,37.53],[1,1.01,20.51],[2,1.01,0]],"ltp":11.5,"tv":1853.91,"id":2263603},{"batb":[[0,1.01,20.51],[1,1.07,0],[2,1.06,0]],"batl":[[0,1.37,1010.69],[1,3,3.18],[2,3,0]],"ltp":1.1,"tv":6042.27,"id":3622149}]}]}
{"op":"mcm","clk":"1009932612","pt":1580670760230,"mc":[{"id":"1.168230758","rc":[{"batl":[[0,3,3.18],[1,3,0]],"ltp":1.1,"tv":6042.27,"id":3622149}]}]}
{"op":"mcm","clk":"1009933183","pt":1580670764645,"mc":[{"id":"1.168230758","rc":[{"batb":[[0,1.1,1558.92],[1,1.09,1105.43],[2,1.01,20.51]],"batl":[[0,1.12,1864.93],[1,1.13,735.41],[2,3,3.18]],"ltp":1.1,"tv":6042.27,"id":3622149}]}]}
{"op":"mcm","clk":"1009933509","pt":1580670767559,"mc":[{"id":"1.168230758","rc":[{"batl":[[0,21,53.48]],"ltp":11.5,"tv":1853.91,"id":2263603},{"batl":[[2,1.38,972.97]],"ltp":1.1,"tv":6042.27,"id":3622149}]}]}
{"op":"mcm","clk":"1009933631","pt":1580670768568,"mc":[{"id":"1.168230758","rc":[{"batb":[[0,1.01,20.51],[1,1.09,0],[2,1.01,0]],"batl":[[0,1.38,972.97],[1,3,3.18],[2,1.38,0]],"ltp":1.1,"tv":6042.27,"id":3622149}]}]}
{"op":"mcm","clk":"1009933729","pt":1580670769361,"mc":[{"id":"1.168230758","rc":[{"batl":[[0,3,3.18],[1,3,0]],"ltp":1.1,"tv":6042.27,"id":3622149}]}]}
{"op":"mcm","clk":"1009933955","pt":1580670771141,"mc":[{"id":"1.168230758","rc":[{"batl":[[0,1.21,855.4],[1,1.22,1050.62],[2,3,3.18]],"ltp":1.1,"tv":6042.27,"id":3622149}]}]}
{"op":"mcm","clk":"1009935851","pt":1580670786602,"mc":[{"id":"1.168230758","rc":[{"batb":[[0,1.15,3820.08],[1,1.01,20.51]],"ltp":1.1,"tv":6042.27,"id":3622149}]}]}
{"op":"mcm","clk":"1009935983","pt":1580670787571,"mc":[{"id":"1.168230758","rc":[{"batb":[[1,3.9,49.57],[2,1.01,20.51]],"ltp":11.5,"tv":1853.91,"id":2263603},{"batb":[[0,1.18,1734.14],[1,1.17,746.54],[2,1.16,297.58]],"ltp":1.1,"tv":6042.27,"id":3622149}]}]}
{"op":"mcm","clk":"1009936271","pt":1580670789887,"mc":[{"id":"1.168230758","rc":[{"batl":[[0,9.8,75.27]],"ltp":11.5,"tv":1853.91,"id":2263603},{"batl":[[2,1.49,761.67]],"ltp":1.1,"tv":6042.27,"id":3622149}]}]}
{"op":"mcm","clk":"1009938266","pt":1580670804616,"mc":[{"id":"1.168230758","rc":[{"batb":[[0,1.16,297.58],[1,1.06,769.75],[2,1.01,20.51]],"batl":[[0,1.49,761.67],[1,3,3.18],[2,1.49,0]],"ltp":1.1,"tv":6042.27,"id":3622149}]}]}
{"op":"mcm","clk":"1009938334","pt":1580670805094,"mc":[{"id":"1.168230758","rc":[{"batb":[[0,3.9,49.57],[1,1.01,20.51],[2,1.01,0]],"ltp":11.5,"tv":1853.91,"id":2263603},{"batb":[[0,1.06,769.75],[1,1.01,20.51],[2,1.01,0]],"ltp":1.1,"tv":6042.27,"id":3622149}]}]}
{"op":"mcm","clk":"1009938525","pt":1580670806511,"mc":[{"id":"1.168230758","rc":[{"batl":[[0,3,3.18],[1,3,0]],"ltp":1.1,"tv":6042.27,"id":3622149}]}]}
{"op":"mcm","clk":"1009938652","pt":1580670807615,"mc":[{"id":"1.168230758","rc":[{"batb":[[0,1.08,2046],[1,1.07,663.61],[2,1.06,769.75]],"batl":[[0,1.35,546.94],[1,1.36,586.53],[2,3,3.18]],"ltp":1.1,"tv":6042.27,"id":3622149}]}]}
{"op":"mcm","clk":"1009938774","pt":1580670808526,"mc":[{"id":"1.168230758","rc":[{"batb":[[0,1.06,769.75],[1,1.01,20.51],[2,1.06,0]],"batl":[[0,3,3.18],[1,1.36,0],[2,3,0]],"ltp":1.1,"tv":6042.27,"id":3622149}]}]}
{"op":"mcm","clk":"1009939170","pt":1580670811616,"mc":[{"id":"1.168230758","rc":[{"batb":[[0,1.21,791.75],[1,1.2,1250.09],[2,1.06,769.75]],"batl":[[0,1.24,1171.59],[1,1.25,896.43],[2,3,3.18]],"ltp":1.1,"tv":6042.27,"id":3622149}]}]}
{"op":"mcm","clk":"1009939371","pt":1580670813500,"mc":[{"id":"1.168230758","rc":[{"batl":[[0,8.6,81.89]],"ltp":11.5,"tv":1853.91,"id":2263603},{"batl":[[2,1.53,714.1]],"ltp":1.1,"tv":6042.27,"id":3622149}]}]}
{"op":"mcm","clk":"1009939771","pt":1580670816648,"mc":[{"id":"1.168230758","rc":[{"batb":[[0,1.06,769.75],[1,1.01,20.51],[2,1.06,0]],"batl":[[0,1.53,714.1],[1,3,3.18],[2,1.53,0]],"ltp":1.1,"tv":6042.27,"id":3622149}]}]}
{"op":"mcm","clk":"1009940016","pt":1580670818547,"mc":[{"id":"1.168230758","rc":[{"batl":[[0,3,3.18],[1,3,0]],"ltp":1.1,"tv":6042.27,"id":3622149}]}]}
{"op":"mcm","clk":"1009940127","pt":1580670819516,"mc":[{"id":"1.168230758","rc":[{"batb":[[0,1.08,2046],[1,1.07,663.61],[2,1.06,769.75]],"batl":[[0,1.35,546.94],[1,1.36,586.53],[2,3,3.18]],"ltp":1.1,"tv":6042.27,"id":3622149}]}]}
{"op":"mcm","clk":"1009940365","pt":1580670821616,"mc":[{"id":"1.168230758","rc":[{"batl":[[0,3,3.18],[1,1.36,0],[2,3,0]],"ltp":1.1,"tv":6042.27,"id":3622149}]}]}
{"op":"mcm","clk":"1009940733","pt":1580670824630,"mc":[{"id":"1.168230758","rc":[{"batl":[[0,1.1,2495.92],[1,1.12,573.01],[2,3,3.18]],"ltp":1.1,"tv":6042.27,"id":3622149}]}]}
{"op":"mcm","clk":"1009940855","pt":1580670825517,"mc":[{"id":"1.168230758","rc":[{"batb":[[0,11.5,20.06],[1,5.9,37.53],[2,1.01,20.51]],"ltp":11.5,"tv":1853.91,"id":2263603}]}]}
{"op":"mcm","clk":"1009940961","pt":1580670826410,"mc":[{"id":"1.168230758","rc":[{"batl":[[0,24,50.52]],"ltp":11.5,"tv":1853.91,"id":2263603},{"batl":[[2,1.37,1010.69]],"ltp":1.1,"tv":6042.27,"id":3622149}]}]}
{"op":"mcm","clk":"1009941090","pt":1580670827505,"mc":[{"id":"1.168230758","rc":[{"batl":[[1,1.37,1010.69],[2,3,3.18]],"ltp":1.1,"tv":6042.27,"id":3622149}]}]}
{"op":"mcm","clk":"1009942644","pt":1580670839862,"mc":[{"id":"1.168230758","rc":[{"batb":[[0,5.9,37.53],[1,1.01,20.51],[2,1.01,0]],"ltp":11.5,"tv":1853.91,"id":2263603},{"batb":[[0,1.01,20.51],[1,1.07,0],[2,1.06,0]],"batl":[[0,1.37,1010.69],[1,3,3.18],[2,3,0]],"ltp":1.1,"tv":6042.27,"id":3622149}]}]}
{"op":"mcm","clk":"1009942835","pt":1580670841554,"mc":[{"id":"1.168230758","rc":[{"batl":[[0,3,3.18],[1,3,0]],"ltp":1.1,"tv":6042.27,"id":3622149}]}]}
{"op":"mcm","clk":"1009943303","pt":1580670845229,"mc":[{"id":"1.168230758","rc":[{"batb":[[0,1.1,1546.03],[1,1.09,1118.44],[2,1.01,20.51]],"batl":[[0,1.12,1875.87],[1,1.13,724.56],[2,3,3.18]],"ltp":1.1,"tv":6042.27,"id":3622149}]}]}
{"op":"mcm","clk":"1009943746","pt":1580670848557,"mc":[{"id":"1.168230758","rc":[{"batl":[[0,21,53.48]],"ltp":11.5,"tv":1853.91,"id":2263603},{"batl":[[2,1.38,972.97]],"ltp":1.1,"tv":6042.27,"id":3622149}]}]}
{"op":"mcm","clk":"1009943899","pt":1580670849648,"mc":[{"id":"1.168230758","rc":[{"batb":[[0,1.01,20.51],[1,1.09,0],[2,1.01,0]],"batl":[[0,1.38,972.97],[1,3,3.18],[2,1.38,0]],"ltp":1.1,"tv":6042.27,"id":3622149}]}]}
{"op":"mcm","clk":"1009944157","pt":1580670851483,"mc":[{"id":"1.168230758","rc":[{"batl":[[0,3,3.18],[1,3,0]],"ltp":1.1,"tv":6042.27,"id":3622149}]}]}
{"op":"mcm","clk":"1009944254","pt":1580670852277,"mc":[{"id":"1.168230758","rc":[{"batl":[[0,1.21,863.78],[1,1.22,1050.36],[2,3,3.18]],"ltp":1.1,"tv":6042.27,"id":3622149}]}]}
{"op":"mcm","clk":"1009945670","pt":1580670863568,"mc":[{"id":"1.168230758","rc":[{"batl":[[0,3,3.18],[1,1.22,0],[2,3,0]],"ltp":1.1,"tv":6042.27,"id":3622149}]}]}
{"op":"mcm","clk":"1009945724","pt":1580670864082,"mc":[{"id":"1.168230758","rc":[{"batb":[[0,1.01,20.51],[1,1.01,0]],"ltp":11.5,"tv":1853.91,"id":2263603}]}]}
{"op":"mcm","clk":"1009945907","pt":1580670865262,"mc":[{"id":"1.168230758","marketDefinition":{"bspMarket":false,"turnInPlayEnabled":true,"persistenceEnabled":true,"marketBaseRate":5.0,"eventId":"29681775","eventTypeId":"2","numberOfWinners":1,"bettingType":"ODDS","marketType":"SET_WINNER","marketTime":"2020-02-02T18:01:00.000Z","suspendTime":"2020-02-02T18:01:00.000Z","bspReconciled":false,"complete":true,"inPlay":true,"crossMatching":true,"runnersVoidable":false,"numberOfActiveRunners":2,"betDelay":3,"status":"SUSPENDED","runners":[{"status":"ACTIVE","sortPriority":1,"id":2263603,"name":"Madison Brengle"},{"status":"ACTIVE","sortPriority":2,"id":3622149,"name":"Stefanie Voegele"}],"regulators":["MR_INT"],"discountAllowed":true,"timezone":"UTC","openDate":"2020-02-02T18:01:00.000Z","version":3150346723,"name":"Set 2 Winner","eventName":"Brengle v Voegele"}}]}
{"op":"mcm","clk":"1009949929","pt":1580670896568,"mc":[{"id":"1.168230758","tv":0.0}]}
{"op":"mcm","clk":"1009950071","pt":1580670897570,"mc":[{"id":"1.168230758","marketDefinition":{"bspMarket":false,"turnInPlayEnabled":true,"persistenceEnabled":true,"marketBaseRate":5.0,"eventId":"29681775","eventTypeId":"2","numberOfWinners":1,"bettingType":"ODDS","marketType":"SET_WINNER","marketTime":"2020-02-02T18:01:00.000Z","suspendTime":"2020-02-02T18:01:00.000Z","bspReconciled":false,"complete":true,"inPlay":true,"crossMatching":false,"runnersVoidable":false,"numberOfActiveRunners":0,"betDelay":3,"status":"CLOSED","settledTime":"2020-02-02T19:14:55.000Z","runners":[{"status":"LOSER","sortPriority":1,"id":2263603,"name":"Madison Brengle"},{"status":"WINNER","sortPriority":2,"id":3622149,"name":"Stefanie Voegele"}],"regulators":["MR_INT"],"discountAllowed":true,"timezone":"UTC","openDate":"2020-02-02T18:01:00.000Z","version":3150347705,"name":"Set 2 Winner","eventName":"Brengle v Voegele"}}]}
