{"op":"mcm","clk":"1001501051","pt":1580587070468,"mc":[{"id":"1.168230760","marketDefinition":{"bspMarket":false,"turnInPlayEnabled":true,"persistenceEnabled":true,"marketBaseRate":5.0,"eventId":"29681775","eventTypeId":"2","numberOfWinners":1,"bettingType":"ODDS","marketType":"PLAYER_A_WIN_A_SET","marketTime":"2020-02-02T18:00:00.000Z","suspendTime":"2020-02-02T18:00:00.000Z","bspReconciled":false,"complete":true,"inPlay":false,"crossMatching":true,"runnersVoidable":false,"numberOfActiveRunners":2,"betDelay":0,"status":"OPEN","runners":[{"status":"ACTIVE","sortPriority":1,"id":41364,"name":"Yes"},{"status":"ACTIVE","sortPriority":2,"id":41365,"name":"No"}],"regulators":["MR_INT"],"discountAllowed":false,"timezone":"UTC","openDate":"2020-02-02T18:00:00.000Z","version":3147219557,"name":"Brengle To Win A Set?","eventName":"Brengle v Voegele"}}]}
{"op":"mcm","clk":"1001501273","pt":1580587071655,"mc":[{"id":"1.168230760","marketDefinition":{"bspMarket":false,"turnInPlayEnabled":true,"persistenceEnabled":true,"marketBaseRate":5.0,"eventId":"29681775","eventTypeId":"2","numberOfWinners":1,"bettingType":"ODDS","marketType":"PLAYER_A_WIN_A_SET","marketTime":"2020-02-02T18:00:00.000Z","suspendTime":"2020-02-02T18:00:00.000Z","bspReconciled":false,"complete":true,"inPlay":false,"crossMatching":true,"runnersVoidable":false,"numberOfActiveRunners":2,"betDelay":0,"status":"OPEN","runners":[{"status":"ACTIVE","sortPriority":1,"id":41364,"name":"Yes"},{"status":"ACTIVE","sortPriority":2,"id":41365,"name":"No"}],"regulators":["MR_INT"],"discountAllowed":false,"timezone":"UTC","openDate":"2020-02-02T18:00:00.000Z","version":3147219557,"name":"Brengle To Win A Set?","eventName":"Brengle v Voegele"}}]}
{"op":"mcm","clk":"1001501657","pt":1580587073688,"mc":[{"id":"1.168230760","marketDefinition":{"bspMarket":false,"turnInPlayEnabled":true,"persistenceEnabled":true,"marketBaseRate":5.0,"eventId":"29681775","eventTypeId":"2","numberOfWinners":1,"bettingType":"ODDS","marketType":"PLAYER_A_WIN_A_SET","marketTime":"2020-02-02T18:00:00.000Z","suspendTime":"2020-02-02T18:00:00.000Z","bspReconciled":false,"complete":true,"inPlay":false,"crossMatching":true,"runnersVoidable":false,"numberOfActiveRunners":2,"betDelay":0,"status":"OPEN","runners":[{"status":"ACTIVE","sortPriority":1,"id":41364,"name":"Yes"},{"status":"ACTIVE","sortPriority":2,"id":41365,"name":"No"}],"regulators":["MR_INT"],"discountAllowed":true,"timezone":"UTC","openDate":"2020-02-02T18:00:00.000Z","version":3147219557,"name":"Brengle To Win A Set?","eventName":"Brengle v Voegele"}}]}
{"op":"mcm","clk":"1003070651","pt":1580602601594,"mc":[{"id":"1.168230760","rc":[{"batb":[[0,1.01,0.51]],"ltp":0.0,"tv":0.0,"id":41364},{"batb":[[0,1.01,0.51]],"ltp":0.0,"tv":0.0,"id":41365}]}]}
{"op":"mcm","clk":"1003129976","pt":1580603367494,"mc":[{"id":"1.168230760","rc":[{"batb":[[0,1.01,1.01]],"ltp":0.0,"tv":0.0,"id":41364},{"batb":[[0,1.01,1.01]],"ltp":0.0,"tv":0.0,"id":41365}]}]}
{"op":"mcm","clk":"1009515467","pt":1580666510637,"mc":[{"id":"1.168230760","marketDefinition":{"bspMarket":false,"turnInPlayEnabled":true,"persistenceEnabled":true,"marketBaseRate":5.0,"eventId":"29681775","eventTypeId":"2","numberOfWinners":1,"bettingType":"ODDS","marketType":"PLAYER_A_WIN_A_SET","marketTime":"2020-02-02T18:01:00.000Z","suspendTime":"2020-02-02T18:01:00.000Z","bspReconciled":false,"complete":true,"inPlay":false,"crossMatching":true,"runnersVoidable":false,"numberOfActiveRunners":2,"betDelay":0,"status":"OPEN","runners":[{"status":"ACTIVE","sortPriority":1,"id":41364,"name":"Yes"},{"status":"ACTIVE","sortPriority":2,"id":41365,"name":"No"}],"regulators":["MR_INT"],"discountAllowed":true,"timezone":"UTC","openDate":"2020-02-02T18:00:00.000Z","version":3150167975,"name":"Brengle To Win A Set?","eventName":"Brengle v Voegele"}}]}
{"op":"mcm","clk":"1009515709","pt":1580666513126,"mc":[{"id":"1.168230760","marketDefinition":{"bspMarket":false,"turnInPlayEnabled":true,"persistenceEnabled":true,"marketBaseRate":5.0,"eventId":"29681775","eventTypeId":"2","numberOfWinners":1,"bettingType":"ODDS","marketType":"PLAYER_A_WIN_A_SET","marketTime":"2020-02-02T18:01:00.000Z","suspendTime":"2020-02-02T18:01:00.000Z","bspReconciled":false,"complete":true,"inPlay":false,"crossMatching":true,"runnersVoidable":false,"numberOfActiveRunners":2,"betDelay":0,"status":"OPEN","runners":[{"status":"ACTIVE","sortPriority":1,"id":41364,"name":"Yes"},{"status":"ACTIVE","sortPriority":2,"id":41365,"name":"No"}],"regulators":["MR_INT"],"discountAllowed":true,"timezone":"UTC","openDate":"2020-02-02T18:01:00.000Z","version":3150167975,"name":"Brengle To Win A Set?","eventName":"Brengle v Voegele"}}]}
{"op":"mcm","clk":"1009519906","pt":1580666557406,"mc":[{"id":"1.168230760","rc":[{"batb":[[0,1.36,445.73],[1,1.01,1.01]],"ltp":0.0,"tv":0.0,"id":41364},{"batb":[[0,3.2,152.72],[1,1.01,1.01]],"ltp":0.0,"tv":0.0,"id":41365}]}]}
{"op":"mcm","clk":"1009542076","pt":1580666773182,"mc":[{"id":"1.168230760","rc":[{"batb":[[0,3.2,152.56]],"ltp":0.0,"tv":0.0,"id":41365}]}]}
{"op":"mcm","clk":"1009555777","pt":1580666900444,"mc":[{"id":"1.168230760","marketDefinition":{"bspMarket":false,"turnInPlayEnabled":true,"persistenceEnabled":true,"marketBaseRate":5.0,"eventId":"29681775","eventTypeId":"2","numberOfWinners":1,"bettingType":"ODDS","marketType":"PLAYER_A_WIN_A_SET","marketTime":"2020-02-02T18:01:00.000Z","suspendTime":"2020-02-02T18:01:00.000Z","bspReconciled":false,"complete":true,"inPlay":true,"crossMatching":true,"runnersVoidable":false,"numberOfActiveRunners":2,"betDelay":3,"status":"OPEN","runners":[{"status":"ACTIVE","sortPriority":1,"id":41364,"name":"Yes"},{"status":"ACTIVE","sortPriority":2,"id":41365,"name":"No"}],"regulators":["MR_INT"],"discountAllowed":true,"timezone":"UTC","openDate":"2020-02-02T18:01:00.000Z","version":3150176486,"name":"Brengle To Win A Set?","eventName":"Brengle v Voegele"},"rc":[{"batb":[[0,1.01,0.51],[1,1.01,0]],"ltp":0.0,"tv":0.0,"id":41364},{"batb":[[0,1.01,0.51],[1,1.01,0]],"ltp":0.0,"tv":0.0,"id":41365}]}]}
{"op":"mcm","clk":"1009558525","pt":1580666927252,"mc":[{"id":"1.168230760","rc":[{"batb":[[0,1.42,368.15],[1,1.37,437.24],[2,1.01,0.51]],"ltp":0.0,"tv":0.0,"id":41364},{"batb":[[0,2.9,195.84],[1,2.68,97.25],[2,1.01,0.51]],"ltp":0.0,"tv":0.0,"id":41365}]}]}
{"op":"mcm","clk":"1009559496","pt":1580666936249,"mc":[{"id":"1.168230760","rc":[{"batb":[[0,1.37,437.24],[1,1.01,0.51],[2,1.01,0]],"ltp":0.0,"tv":0.0,"id":41364},{"batb":[[0,2.68,97.25],[1,1.01,0.51],[2,1.01,0]],"ltp":0.0,"tv":0.0,"id":41365}]}]}
{"op":"mcm","clk":"1009560328","pt":1580666943594,"mc":[{"id":"1.168230760","rc":[{"batb":[[1,1.32,526.3],[2,1.01,0.51]],"ltp":0.0,"tv":0.0,"id":41364},{"batb":[[0,3.15,156.66],[1,2.86,203.79],[2,1.01,0.51]],"ltp":0.0,"tv":0.0,"id":41365}]}]}
{"op":"mcm","clk":"1009561285","pt":1580666951476,"mc":[{"id":"1.168230760","rc":[{"batb":[[0,1.32,523.31],[1,1.01,0.51],[2,1.01,0]],"ltp":0.0,"tv":0.0,"id":41364},{"batb":[[0,2.86,203.79],[1,1.01,0.51],[2,1.01,0]],"ltp":0.0,"tv":0.0,"id":41365}]}]}
{"op":"mcm","clk":"1009563710","pt":1580666975617,"mc":[{"id":"1.168230760","rc":[{"batb":[[1,1.27,629.46],[2,1.01,0.51]],"ltp":0.0,"tv":0.0,"id":41364},{"batb":[[0,3.5,123.06],[1,3.1,161.77],[2,1.01,0.51]],"ltp":0.0,"tv":0.0,"id":41365}]}]}
{"op":"mcm","clk":"1009564665","pt":1580666986035,"mc":[{"id":"1.168230760","rc":[{"batb":[[0,1.27,629.46],[1,1.01,0.51],[2,1.01,0]],"ltp":0.0,"tv":0.0,"id":41364},{"batb":[[0,3.1,161.77],[1,1.01,0.51],[2,1.01,0]],"ltp":0.0,"tv":0.0,"id":41365}]}]}
{"op":"mcm","clk":"1009565762","pt":1580666997152,"mc":[{"id":"1.168230760","rc":[{"batb":[[0,1.38,426.77],[1,1.31,539.05],[2,1.01,0.51]],"ltp":0.0,"tv":0.0,"id":41364},{"batb":[[1,2.78,88.44],[2,1.01,0.51]],"ltp":0.0,"tv":0.0,"id":41365}]}]}
{"op":"mcm","clk":"1009566540","pt":1580667004644,"mc":[{"id":"1.168230760","rc":[{"batb":[[0,1.31,539.05],[1,1.01,0.51],[2,1.01,0]],"ltp":0.0,"tv":0.0,"id":41364},{"batb":[[0,2.78,88.44],[1,1.01,0.51],[2,1.01,0]],"ltp":0.0,"tv":0.0,"id":41365}]}]}
{"op":"mcm","clk":"1009570693","pt":1580667045564,"mc":[{"id":"1.168230760","rc":[{"batb":[[1,1.26,670.76],[2,1.01,0.51]],"ltp":0.0,"tv":0.0,"id":41364},{"batb":[[0,3.55,118.18],[1,3.1,162.56],[2,2.78,88.44]],"ltp":0.0,"tv":0.0,"id":41365}]}]}
{"op":"mcm","clk":"1009570787","pt":1580667046464,"mc":[{"id":"1.168230760","rc":[{"batb":[[2,1.01,0.51]],"ltp":0.0,"tv":0.0,"id":41365}]}]}
{"op":"mcm","clk":"1009572072","pt":1580667059570,"mc":[{"id":"1.168230760","rc":[{"batb":[[0,1.26,670.76],[1,1.01,0.51],[2,1.01,0]],"ltp":0.0,"tv":0.0,"id":41364},{"batb":[[0,3.1,162.56],[1,1.01,0.51],[2,1.01,0]],"ltp":0.0,"tv":0.0,"id":41365}]}]}
{"op":"mcm","clk":"1009574087","pt":1580667081603,"mc":[{"id":"1.168230760","rc":[{"batb":[[1,1.21,827.03],[2,1.01,0.51]],"ltp":0.0,"tv":0.0,"id":41364},{"batb":[[0,4,176.25],[1,3.65,109.92],[2,1.01,0.51]],"ltp":0.0,"tv":0.0,"id":41365}]}]}
{"op":"mcm","clk":"1009575357","pt":1580667094616,"mc":[{"id":"1.168230760","rc":[{"batb":[[0,4,173.18],[1,3.65,108.03]],"ltp":0.0,"tv":0.0,"id":41365}]}]}
{"op":"mcm","clk":"1009578430","pt":1580667127548,"mc":[{"id":"1.168230760","rc":[{"batb":[[0,1.21,827.03],[1,1.01,0.51],[2,1.01,0]],"ltp":0.0,"tv":0.0,"id":41364},{"batb":[[0,3.65,108.03],[1,1.01,0.51],[2,1.01,0]],"ltp":0.0,"tv":0.0,"id":41365}]}]}
{"op":"mcm","clk":"1009579746","pt":1580667141600,"mc":[{"id":"1.168230760","rc":[{"batb":[[0,1.29,575.24],[1,1.25,691.46],[2,1.01,0.51]],"ltp":0.0,"tv":0.0,"id":41364},{"batb":[[1,3.35,135.96],[2,1.01,0.51]],"ltp":0.0,"tv":0.0,"id":41365}]}]}
{"op":"mcm","clk":"1009581121","pt":1580667155180,"mc":[{"id":"1.168230760","rc":[{"batb":[[0,1.25,691.46],[1,1.01,0.51],[2,1.01,0]],"ltp":0.0,"tv":0.0,"id":41364},{"batb":[[0,3.35,135.96],[1,1.01,0.51],[2,1.01,0]],"ltp":0.0,"tv":0.0,"id":41365}]}]}
{"op":"mcm","clk":"1009581474","pt":1580667158498,"mc":[{"id":"1.168230760","rc":[{"batb":[[0,1.25,680.91]],"ltp":0.0,"tv":0.0,"id":41364},{"batb":[[0,3.3,138.79]],"ltp":0.0,"tv":0.0,"id":41365}]}]}
{"op":"mcm","clk":"1009582307","pt":1580667166586,"mc":[{"id":"1.168230760","rc":[{"batb":[[0,1.34,478.86],[1,1.3,562.89],[2,1.01,0.51]],"ltp":0.0,"tv":0.0,"id":41364},{"batb":[[1,3.1,163.26],[2,1.01,0.51]],"ltp":0.0,"tv":0.0,"id":41365}]}]}
{"op":"mcm","clk":"1009583531","pt":1580667177618,"mc":[{"id":"1.168230760","rc":[{"batb":[[0,1.3,562.89],[1,1.01,0.51],[2,1.01,0]],"ltp":0.0,"tv":0.0,"id":41364},{"batb":[[0,3.1,163.26],[1,1.01,0.51],[2,1.01,0]],"ltp":0.0,"tv":0.0,"id":41365}]}]}
{"op":"mcm","clk":"1009586425","pt":1580667204649,"mc":[{"id":"1.168230760","rc":[{"batb":[[1,1.25,702.08],[2,1.01,0.51]],"ltp":0.0,"tv":0.0,"id":41364},{"batb":[[0,3.6,111.33],[1,3.3,141.39],[2,3.1,163.26]],"ltp":0.0,"tv":0.0,"id":41365}]}]}
{"op":"mcm","clk":"1009586458","pt":1580667204930,"mc":[{"id":"1.168230760","rc":[{"batb":[[2,1.01,0.51]],"ltp":0.0,"tv":0.0,"id":41365}]}]}
{"op":"mcm","clk":"1009587834","pt":1580667217541,"mc":[{"id":"1.168230760","rc":[{"batb":[[0,1.25,702.08],[1,1.01,0.51],[2,1.01,0]],"ltp":0.0,"tv":0.0,"id":41364},{"batb":[[0,3.3,141.39],[1,1.01,0.51],[2,1.01,0]],"ltp":0.0,"tv":0.0,"id":41365}]}]}
{"op":"mcm","clk":"1009591501","pt":1580667251578,"mc":[{"id":"1.168230760","rc":[{"batb":[[1,1.19,962.59],[2,1.01,0.51]],"ltp":0.0,"tv":0.0,"id":41364},{"batb":[[0,4.1,165.07],[1,3.55,114.95],[2,1.01,0.51]],"ltp":0.0,"tv":0.0,"id":41365}]}]}
{"op":"mcm","clk":"1009593251","pt":1580667267609,"mc":[{"id":"1.168230760","rc":[{"batb":[[0,1.19,962.59],[1,1.01,0.51],[2,1.01,0]],"ltp":0.0,"tv":0.0,"id":41364},{"batb":[[0,3.55,114.95],[1,1.01,0.51],[2,1.01,0]],"ltp":0.0,"tv":0.0,"id":41365}]}]}
{"op":"mcm","clk":"1009595096","pt":1580667284492,"mc":[{"id":"1.168230760","rc":[{"batb":[[1,1.13,1417.14],[2,1.01,0.51]],"ltp":0.0,"tv":0.0,"id":41364},{"batb":[[0,4.9,103.23],[1,4.1,163.58],[2,1.01,0.51]],"ltp":0.0,"tv":0.0,"id":41365}]}]}
{"op":"mcm","clk":"1009596085","pt":1580667293597,"mc":[{"id":"1.168230760","rc":[{"batb":[[0,1.13,1417.14],[1,1.01,0.51],[2,1.01,0]],"ltp":0.0,"tv":0.0,"id":41364},{"batb":[[0,4.1,163.58],[1,1.01,0.51],[2,1.01,0]],"ltp":0.0,"tv":0.0,"id":41365}]}]}
{"op":"mcm","clk":"1009598152","pt":1580667313343,"mc":[{"id":"1.168230760","rc":[{"batb":[[1,1.1,1779.39],[2,1.01,0.51]],"ltp":0.0,"tv":0.0,"id":41364},{"batb":[[0,6.2,114.32],[1,5.4,166.18],[2,1.01,0.51]],"ltp":0.0,"tv":0.0,"id":41365}]}]}
{"op":"mcm","clk":"1009600630","pt":1580667336464,"mc":[{"id":"1.168230760","rc":[{"batb":[[0,1.1,1779.39],[1,1.01,0.51],[2,1.01,0]],"ltp":0.0,"tv":0.0,"id":41364},{"batb":[[0,5.4,166.18],[1,1.01,0.51],[2,1.01,0]],"ltp":0.0,"tv":0.0,"id":41365}]}]}
{"op":"mcm","clk":"1009600919","pt":1580667339565,"mc":[{"id":"1.168230760","rc":[{"batb":[[0,5.5,161.61],[1,5.4,166.18],[2,1.01,0.51]],"ltp":0.0,"tv":0.0,"id":41365}]}]}
{"op":"mcm","clk":"1009601018","pt":1580667340570,"mc":[{"id":"1.168230760","rc":[{"batb":[[1,1.01,0.51],[2,1.01,0]],"ltp":0.0,"tv":0.0,"id":41365}]}]}
{"op":"mcm","clk":"1009604334","pt":1580667375289,"mc":[{"id":"1.168230760","rc":[{"batb":[[1,1.08,2272.41],[2,1.01,0.51]],"ltp":0.0,"tv":0.0,"id":41364},{"batb":[[0,7.4,76.64],[1,6.2,116.61],[2,1.01,0.51]],"ltp":0.0,"tv":0.0,"id":41365}]}]}
{"op":"mcm","clk":"1009605836","pt":1580667390590,"mc":[{"id":"1.168230760","rc":[{"batb":[[0,1.08,2272.41],[1,1.01,0.51],[2,1.01,0]],"ltp":0.0,"tv":0.0,"id":41364},{"batb":[[0,6.2,116.61],[1,1.01,0.51],[2,1.01,0]],"ltp":0.0,"tv":0.0,"id":41365}]}]}
{"op":"mcm","clk":"1009606136","pt":1580667393647,"mc":[{"id":"1.168230760","rc":[{"batb":[[0,6.4,112.99]],"ltp":0.0,"tv":0.0,"id":41365}]}]}
{"op":"mcm","clk":"1009607746","pt":1580667411446,"mc":[{"id":"1.168230760","rc":[{"batb":[[0,1.06,2862.37]],"ltp":0.0,"tv":0.0,"id":41364},{"batb":[[0,8.8,130.93],[1,7.6,73.65],[2,1.01,0.51]],"ltp":0.0,"tv":0.0,"id":41365}]}]}
{"op":"mcm","clk":"1009607772","pt":1580667411761,"mc":[{"id":"1.168230760","rc":[{"batb":[[0,7.6,73.65],[1,1.01,0.51],[2,1.01,0]],"ltp":0.0,"tv":0.0,"id":41365}]}]}
{"op":"mcm","clk":"1009611072","pt":1580667448989,"mc":[{"id":"1.168230760","rc":[{"batb":[[1,1.05,3292.6],[2,1.01,0.51]],"ltp":0.0,"tv":0.0,"id":41364},{"batb":[[0,10,91.11],[1,9,119.99],[2,1.01,0.51]],"ltp":0.0,"tv":0.0,"id":41365}]}]}
{"op":"mcm","clk":"1009612174","pt":1580667460629,"mc":[{"id":"1.168230760","rc":[{"batb":[[0,1.05,3269.86],[1,1.01,0.51],[2,1.01,0]],"ltp":0.0,"tv":0.0,"id":41364},{"batb":[[0,9,119.99],[1,1.01,0.51],[2,1.01,0]],"ltp":0.0,"tv":0.0,"id":41365}]}]}
{"op":"mcm","clk":"1009613024","pt":1580667469643,"mc":[{"id":"1.168230760","rc":[{"batb":[[0,1.07,2412.55],[1,1.06,2964.97],[2,1.01,0.51]],"ltp":0.0,"tv":0.0,"id":41364},{"batb":[[1,7.8,70.89],[2,1.01,0.51]],"ltp":0.0,"tv":0.0,"id":41365}]}]}
{"op":"mcm","clk":"1009613639","pt":1580667477347,"mc":[{"id":"1.168230760","rc":[{"batb":[[0,1.06,2964.97],[1,1.01,0.51],[2,1.01,0]],"ltp":0.0,"tv":0.0,"id":41364},{"batb":[[0,7.8,70.89],[1,1.01,0.51],[2,1.01,0]],"ltp":0.0,"tv":0.0,"id":41365}]}]}
{"op":"mcm","clk":"1009615246","pt":1580667495649,"mc":[{"id":"1.168230760","rc":[{"batb":[[1,1.04,3978.71],[2,1.01,0.51]],"ltp":0.0,"tv":0.0,"id":41364},{"batb":[[0,10.5,85.76],[1,8.8,125.97],[2,7.8,70.89]],"ltp":0.0,"tv":0.0,"id":41365}]}]}
{"op":"mcm","clk":"1009615314","pt":1580667496343,"mc":[{"id":"1.168230760","rc":[{"batb":[[2,1.01,0.51]],"ltp":0.0,"tv":0.0,"id":41365}]}]}
{"op":"mcm","clk":"1009622910","pt":1580667578574,"mc":[{"id":"1.168230760","rc":[{"batb":[[0,1.04,3978.71],[1,1.01,0.51],[2,1.01,0]],"ltp":0.0,"tv":0.0,"id":41364},{"batb":[[0,8.8,125.97],[1,1.01,0.51],[2,1.01,0]],"ltp":0.0,"tv":0.0,"id":41365}]}]}
{"op":"mcm","clk":"1009623964","pt":1580667591988,"mc":[{"id":"1.168230760","rc":[{"batb":[[1,1.02,5665.81],[2,1.01,0.51]],"ltp":0.0,"tv":0.0,"id":41364},{"batb":[[0,12.5,51.69],[1,10.5,84.03],[2,1.01,0.51]],"ltp":0.0,"tv":0.0,"id":41365}]}]}
{"op":"mcm","clk":"1009625073","pt":1580667606567,"mc":[{"id":"1.168230760","rc":[{"batb":[[0,1.02,5665.81],[1,1.01,0.51],[2,1.01,0]],"ltp":0.0,"tv":0.0,"id":41364},{"batb":[[0,10.5,84.03],[1,1.01,0.51],[2,1.01,0]],"ltp":0.0,"tv":0.0,"id":41365}]}]}
{"op":"mcm","clk":"1009628458","pt":1580667647439,"mc":[{"id":"1.168230760","rc":[{"batb":[[0,1.06,3000.14],[1,1.03,4262.36],[2,1.02,5665.81]],"ltp":0.0,"tv":0.0,"id":41364},{"batb":[[1,8.8,128.96],[2,1.01,0.51]],"ltp":0.0,"tv":0.0,"id":41365}]}]}
{"op":"mcm","clk":"1009628524","pt":1580667648322,"mc":[{"id":"1.168230760","rc":[{"batb":[[2,1.01,0.51]],"ltp":0.0,"tv":0.0,"id":41364}]}]}
{"op":"mcm","clk":"1009629358","pt":1580667657630,"mc":[{"id":"1.168230760","rc":[{"batb":[[0,1.03,4262.36],[1,1.01,0.51],[2,1.01,0]],"ltp":0.0,"tv":0.0,"id":41364},{"batb":[[0,8.8,128.96],[1,1.01,0.51],[2,1.01,0]],"ltp":0.0,"tv":0.0,"id":41365}]}]}
{"op":"mcm","clk":"1009631568","pt":1580667682449,"mc":[{"id":"1.168230760","rc":[{"batb":[[1,1.02,6821.88],[2,1.01,0.51]],"ltp":0.0,"tv":0.0,"id":41364},{"batb":[[0,13,45.95],[1,10.5,81.36],[2,1.01,0.51]],"ltp":0.0,"tv":0.0,"id":41365}]}]}
{"op":"mcm","clk":"1009633371","pt":1580667701410,"mc":[{"id":"1.168230760","rc":[{"batb":[[0,1.02,6821.88],[1,1.01,0.51],[2,1.01,0]],"ltp":0.0,"tv":0.0,"id":41364},{"batb":[[0,10.5,81.36],[1,1.01,0.51],[2,1.01,0]],"ltp":0.0,"tv":0.0,"id":41365}]}]}
{"op":"mcm","clk":"1009636988","pt":1580667745447,"mc":[{"id":"1.168230760","rc":[{"batb":[[0,18,42.09],[1,14,38.63],[2,1.01,0.51]],"ltp":0.0,"tv":0.0,"id":41365}]}]}
{"op":"mcm","clk":"1009638449","pt":1580667762641,"mc":[{"id":"1.168230760","rc":[{"batb":[[0,1.01,0.51],[1,1.01,0]],"ltp":0.0,"tv":0.0,"id":41364},{"batb":[[0,14,38.63],[1,1.01,0.51],[2,1.01,0]],"ltp":0.0,"tv":0.0,"id":41365}]}]}
{"op":"mcm","clk":"1009639911","pt":1580667779557,"mc":[{"id":"1.168230760","rc":[{"batb":[[0,1.03,4672.37],[1,1.01,0.51]],"ltp":0.0,"tv":0.0,"id":41364},{"batb":[[1,10.5,85.06],[2,1.01,0.51]],"ltp":0.0,"tv":0.0,"id":41365}]}]}
{"op":"mcm","clk":"1009641208","pt":1580667794495,"mc":[{"id":"1.168230760","rc":[{"batb":[[0,1.01,0.51],[1,1.01,0]],"ltp":0.0,"tv":0.0,"id":41364},{"batb":[[0,10.5,85.06],[1,1.01,0.51],[2,1.01,0]],"ltp":0.0,"tv":0.0,"id":41365}]}]}
{"op":"mcm","clk":"1009641481","pt":1580667797468,"mc":[{"id":"1.168230760","rc":[{"batb":[[1,10,86.08],[2,1.01,0.51]],"ltp":0.0,"tv":0.0,"id":41365}]}]}
{"op":"mcm","clk":"1009641541","pt":1580667798468,"mc":[{"id":"1.168230760","rc":[{"batb":[[0,10,86.08],[1,1.01,0.51],[2,1.01,0]],"ltp":0.0,"tv":0.0,"id":41365}]}]}
{"op":"mcm","clk":"1009643483","pt":1580667820609,"mc":[{"id":"1.168230760","rc":[{"batb":[[0,1.06,2941.68],[1,1.03,4581.1],[2,1.01,0.51]],"ltp":0.0,"tv":0.0,"id":41364},{"batb":[[1,8.4,58.93],[2,1.01,0.51]],"ltp":0.0,"tv":0.0,"id":41365}]}]}
{"op":"mcm","clk":"1009644698","pt":1580667832617,"mc":[{"id":"1.168230760","rc":[{"batb":[[0,1.03,4581.1],[1,1.01,0.51],[2,1.01,0]],"ltp":0.0,"tv":0.0,"id":41364},{"batb":[[0,8.4,56.65],[1,1.01,0.51],[2,1.01,0]],"ltp":0.0,"tv":0.0,"id":41365}]}]}
{"op":"mcm","clk":"1009645509","pt":1580667841490,"mc":[{"id":"1.168230760","rc":[{"batb":[[0,1.08,2211.51],[1,1.06,2997.23],[2,1.01,0.51]],"ltp":0.0,"tv":0.0,"id":41364},{"batb":[[1,7.4,79.94],[2,1.01,0.51]],"ltp":0.0,"tv":0.0,"id":41365}]}]}
{"op":"mcm","clk":"1009646534","pt":1580667853633,"mc":[{"id":"1.168230760","rc":[{"batb":[[0,1.06,2997.23],[1,1.01,0.51],[2,1.01,0]],"ltp":0.0,"tv":0.0,"id":41364},{"batb":[[0,7.4,79.94],[1,1.01,0.51],[2,1.01,0]],"ltp":0.0,"tv":0.0,"id":41365}]}]}
{"op":"mcm","clk":"1009646772","pt":1580667856341,"mc":[{"id":"1.168230760","rc":[{"batb":[[0,1.06,2981.34]],"ltp":0.0,"tv":0.0,"id":41364},{"batb":[[0,7.2,80.65]],"ltp":0.0,"tv":0.0,"id":41365}]}]}
{"op":"mcm","clk":"1009648037","pt":1580667870511,"mc":[{"id":"1.168230760","rc":[{"batb":[[0,1.1,1755.16],[1,1.08,2281.15],[2,1.01,0.51]],"ltp":0.0,"tv":0.0,"id":41364},{"batb":[[1,6,129.9],[2,1.01,0.51]],"ltp":0.0,"tv":0.0,"id":41365}]}]}
{"op":"mcm","clk":"1009649980","pt":1580667895645,"mc":[{"id":"1.168230760","rc":[{"batb":[[0,1.08,2271.15],[1,1.01,0.51],[2,1.01,0]],"ltp":0.0,"tv":0.0,"id":41364},{"batb":[[0,6,129.9],[1,1.01,0.51],[2,1.01,0]],"ltp":0.0,"tv":0.0,"id":41365}]}]}
{"op":"mcm","clk":"1009652254","pt":1580667926070,"mc":[{"id":"1.168230760","rc":[{"batb":[[1,1.06,2974.33],[2,1.01,0.51]],"ltp":0.0,"tv":0.0,"id":41364},{"batb":[[0,8.6,133.76],[1,7,86.24],[2,1.01,0.51]],"ltp":0.0,"tv":0.0,"id":41365}]}]}
{"op":"mcm","clk":"1009653065","pt":1580667937567,"mc":[{"id":"1.168230760","rc":[{"batb":[[0,1.06,2974.33],[1,1.01,0.51],[2,1.01,0]],"ltp":0.0,"tv":0.0,"id":41364},{"batb":[[0,7,86.24],[1,1.01,0.51],[2,1.01,0]],"ltp":0.0,"tv":0.0,"id":41365}]}]}
{"op":"mcm","clk":"1009653298","pt":1580667940593,"mc":[{"id":"1.168230760","rc":[{"batb":[[0,7.2,84.35],[1,7,86.24],[2,1.01,0.51]],"ltp":0.0,"tv":0.0,"id":41365}]}]}
{"op":"mcm","clk":"1009653368","pt":1580667941277,"mc":[{"id":"1.168230760","rc":[{"batb":[[1,1.01,0.51],[2,1.01,0]],"ltp":0.0,"tv":0.0,"id":41365}]}]}
{"op":"mcm","clk":"1009654908","pt":1580667960605,"mc":[{"id":"1.168230760","rc":[{"batb":[[0,1.01,0.51],[1,1.01,0]],"ltp":0.0,"tv":0.0,"id":41364}]}]}
{"op":"mcm","clk":"1009655142","pt":1580667963605,"mc":[{"id":"1.168230760","rc":[{"batb":[[0,1.05,3027.37],[1,1.04,3863.2],[2,1.01,0.51]],"ltp":0.0,"tv":0.0,"id":41364},{"batb":[[0,10.5,82.77],[1,8.8,132.11],[2,7.2,84.35]],"ltp":0.0,"tv":0.0,"id":41365}]}]}
{"op":"mcm","clk":"1009655158","pt":1580667963808,"mc":[{"id":"1.168230760","rc":[{"batb":[[2,1.01,0.51]],"ltp":0.0,"tv":0.0,"id":41365}]}]}
{"op":"mcm","clk":"1009656115","pt":1580667975526,"mc":[{"id":"1.168230760","rc":[{"batb":[[0,1.04,3863.2],[1,1.01,0.51],[2,1.01,0]],"ltp":0.0,"tv":0.0,"id":41364},{"batb":[[0,8.8,132.11],[1,1.01,0.51],[2,1.01,0]],"ltp":0.0,"tv":0.0,"id":41365}]}]}
{"op":"mcm","clk":"1009657516","pt":1580667994349,"mc":[{"id":"1.168230760","rc":[{"batb":[[1,1.03,4597.31],[2,1.01,0.51]],"ltp":0.0,"tv":0.0,"id":41364},{"batb":[[0,12.5,54.37],[1,11,75.85],[2,1.01,0.51]],"ltp":0.0,"tv":0.0,"id":41365}]}]}
{"op":"mcm","clk":"1009658372","pt":1580668004644,"mc":[{"id":"1.168230760","rc":[{"batb":[[0,1.03,4597.15],[1,1.01,0.51],[2,1.01,0]],"ltp":0.0,"tv":0.0,"id":41364},{"batb":[[0,11,75.85],[1,1.01,0.51],[2,1.01,0]],"ltp":0.0,"tv":0.0,"id":41365}]}]}
{"op":"mcm","clk":"1009659584","pt":1580668019542,"mc":[{"id":"1.168230760","rc":[{"batb":[[1,1.02,6388.19],[2,1.01,0.51]],"ltp":0.0,"tv":0.0,"id":41364},{"batb":[[0,14,40.36],[1,12,61.21],[2,1.01,0.51]],"ltp":0.0,"tv":0.0,"id":41365}]}]}
{"op":"mcm","clk":"1009660198","pt":1580668027376,"mc":[{"id":"1.168230760","rc":[{"batb":[[0,1.03,4516.34],[1,1.02,6272.68]],"ltp":0.0,"tv":0.0,"id":41364},{"batb":[[0,13.5,41.54],[1,11.5,63.1]],"ltp":0.0,"tv":0.0,"id":41365}]}]}
{"op":"mcm","clk":"1009661362","pt":1580668041162,"mc":[{"id":"1.168230760","rc":[{"batb":[[0,1.03,4516.11],[1,1.02,6272.29]],"ltp":0.0,"tv":0.0,"id":41364}]}]}
{"op":"mcm","clk":"1009661436","pt":1580668042194,"mc":[{"id":"1.168230760","rc":[{"batb":[[0,1.02,6272.29],[1,1.01,0.51],[2,1.01,0]],"ltp":0.0,"tv":0.0,"id":41364},{"batb":[[0,11.5,63.1],[1,1.01,0.51],[2,1.01,0]],"ltp":0.0,"tv":0.0,"id":41365}]}]}
{"op":"mcm","clk":"1009666575","pt":1580668110378,"mc":[{"id":"1.168230760","rc":[{"batb":[[0,1.01,0.51],[1,1.01,0]],"ltp":0.0,"tv":0.0,"id":41364},{"batb":[[0,1.01,0.51],[1,1.01,0]],"ltp":0.0,"tv":0.0,"id":41365}]}]}
{"op":"mcm","clk":"1009668048","pt":1580668126487,"mc":[{"id":"1.168230760","rc":[{"batb":[[0,1.02,6272.29],[1,1.01,0.51]],"ltp":0.0,"tv":0.0,"id":41364},{"batb":[[0,17,48.55],[1,14,39.89],[2,1.01,0.51]],"ltp":0.0,"tv":0.0,"id":41365}]}]}
{"op":"mcm","clk":"1009668861","pt":1580668136288,"mc":[{"id":"1.168230760","rc":[{"batb":[[0,1.01,0.51],[1,1.01,0]],"ltp":0.0,"tv":0.0,"id":41364},{"batb":[[0,14,39.89],[1,1.01,0.51],[2,1.01,0]],"ltp":0.0,"tv":0.0,"id":41365}]}]}
{"op":"mcm","clk":"1009671744","pt":1580668173540,"mc":[{"id":"1.168230760","rc":[{"batb":[[0,1.03,4627.05],[1,1.01,0.51]],"ltp":0.0,"tv":0.0,"id":41364},{"batb":[[1,11.5,64.68],[2,1.01,0.51]],"ltp":0.0,"tv":0.0,"id":41365}]}]}
{"op":"mcm","clk":"1009673010","pt":1580668189539,"mc":[{"id":"1.168230760","rc":[{"batb":[[0,1.01,0.51],[1,1.01,0]],"ltp":0.0,"tv":0.0,"id":41364},{"batb":[[0,11.5,64.68],[1,1.01,0.51],[2,1.01,0]],"ltp":0.0,"tv":0.0,"id":41365}]}]}
{"op":"mcm","clk":"1009673723","pt":1580668198484,"mc":[{"id":"1.168230760","rc":[{"batb":[[0,1.05,3492.22],[1,1.03,4803.14],[2,1.01,0.51]],"ltp":0.0,"tv":0.0,"id":41364},{"batb":[[1,10,91.19],[2,1.01,0.51]],"ltp":0.0,"tv":0.0,"id":41365}]}]}
{"op":"mcm","clk":"1009675034","pt":1580668213371,"mc":[{"id":"1.168230760","rc":[{"batb":[[0,1.03,4803.14],[1,1.01,0.51],[2,1.01,0]],"ltp":0.0,"tv":0.0,"id":41364},{"batb":[[0,10,91.19],[1,1.01,0.51],[2,1.01,0]],"ltp":0.0,"tv":0.0,"id":41365}]}]}
{"op":"mcm","clk":"1009676766","pt":1580668235290,"mc":[{"id":"1.168230760","rc":[{"batb":[[0,14.5,37.37],[1,11.5,65.94],[2,1.01,0.51]],"ltp":0.0,"tv":0.0,"id":41365}]}]}
{"op":"mcm","clk":"1009677956","pt":1580668251619,"mc":[{"id":"1.168230760","rc":[{"batb":[[0,1.01,0.51],[1,1.01,0]],"ltp":0.0,"tv":0.0,"id":41364},{"batb":[[0,11.5,65.94],[1,1.01,0.51],[2,1.01,0]],"ltp":0.0,"tv":0.0,"id":41365}]}]}
{"op":"mcm","clk":"1009681507","pt":1580668296556,"mc":[{"id":"1.168230760","rc":[{"batb":[[0,1.05,3454.92],[1,1.03,4898.5],[2,1.01,0.51]],"ltp":0.0,"tv":0.0,"id":41364},{"batb":[[1,9.6,102.92],[2,1.01,0.51]],"ltp":0.0,"tv":0.0,"id":41365}]}]}
{"op":"mcm","clk":"1009682612","pt":1580668310340,"mc":[{"id":"1.168230760","rc":[{"batb":[[0,1.03,4898.5],[1,1.01,0.51],[2,1.01,0]],"ltp":0.0,"tv":0.0,"id":41364},{"batb":[[0,9.6,102.92],[1,1.01,0.51],[2,1.01,0]],"ltp":0.0,"tv":0.0,"id":41365}]}]}
{"op":"mcm","clk":"1009684174","pt":1580668329581,"mc":[{"id":"1.168230760","rc":[{"batb":[[0,14.5,36.19],[1,11.5,65.94],[2,1.01,0.51]],"ltp":0.0,"tv":0.0,"id":41365}]}]}
{"op":"mcm","clk":"1009685535","pt":1580668344585,"mc":[{"id":"1.168230760","rc":[{"batb":[[0,1.01,0.51],[1,1.01,0]],"ltp":0.0,"tv":0.0,"id":41364},{"batb":[[0,11.5,65.94],[1,1.01,0.51],[2,1.01,0]],"ltp":0.0,"tv":0.0,"id":41365}]}]}
{"op":"mcm","clk":"1009687055","pt":1580668360499,"mc":[{"id":"1.168230760","rc":[{"batb":[[0,20,57.12],[1,14.5,36.67],[2,1.01,0.51]],"ltp":0.0,"tv":0.0,"id":41365}]}]}
{"op":"mcm","clk":"1009688516","pt":1580668375646,"mc":[{"id":"1.168230760","rc":[{"batb":[[0,14.5,36.67],[1,1.01,0.51],[2,1.01,0]],"ltp":0.0,"tv":0.0,"id":41365}]}]}
{"op":"mcm","clk":"1009690951","pt":1580668401633,"mc":[{"id":"1.168230760","rc":[{"batb":[[0,30,8.58],[1,29,24.11],[2,14.5,36.67]],"ltp":0.0,"tv":0.0,"id":41365}]}]}
{"op":"mcm","clk":"1009691023","pt":1580668402467,"mc":[{"id":"1.168230760","rc":[{"batb":[[2,1.01,0.51]],"ltp":0.0,"tv":0.0,"id":41365}]}]}
{"op":"mcm","clk":"1009692563","pt":1580668419553,"mc":[{"id":"1.168230760","rc":[{"batb":[[0,29,24.11],[1,1.01,0.51],[2,1.01,0]],"ltp":0.0,"tv":0.0,"id":41365}]}]}
{"op":"mcm","clk":"1009694010","pt":1580668435590,"mc":[{"id":"1.168230760","rc":[{"batb":[[0,30,10.54],[1,29,24.11],[2,1.01,0.51]],"ltp":0.0,"tv":0.0,"id":41365}]}]}
{"op":"mcm","clk":"1009694091","pt":1580668436380,"mc":[{"id":"1.168230760","rc":[{"trd":[[1.01,0.51]],"ltp":1.01,"tv":0.5,"id":41364},{"batb":[[1,1.01,0.51],[2,1.01,0]],"ltp":0.0,"tv":0.0,"id":41365}],"tv":0.5}]}
{"op":"mcm","clk":"1009695214","pt":1580668448521,"mc":[{"id":"1.168230760","rc":[{"batb":[[0,1.01,0.51],[1,1.01,0]],"ltp":0.0,"tv":0.0,"id":41365}]}]}
{"op":"mcm","clk":"1009697995","pt":1580668475507,"mc":[{"id":"1.168230760","rc":[{"batb":[[0,30,11.64],[1,1.01,0.51]],"ltp":0.0,"tv":0.0,"id":41365}]}]}
{"op":"mcm","clk":"1009700203","pt":1580668499047,"mc":[{"id":"1.168230760","rc":[{"batb":[[0,1.01,0.51],[1,1.01,0]],"ltp":0.0,"tv":0.0,"id":41365}]}]}
{"op":"mcm","clk":"1009702662","pt":1580668526574,"mc":[{"id":"1.168230760","rc":[{"batb":[[0,30,13.65],[1,1.01,0.51]],"ltp":0.0,"tv":0.0,"id":41365}]}]}
{"op":"mcm","clk":"1009704996","pt":1580668551791,"mc":[{"id":"1.168230760","rc":[{"batb":[[0,1.01,0.51],[1,1.01,0]],"ltp":0.0,"tv":0.0,"id":41365}]}]}
{"op":"mcm","clk":"1009705108","pt":1580668552948,"mc":[{"id":"1.168230760","marketDefinition":{"bspMarket":false,"turnInPlayEnabled":true,"persistenceEnabled":true,"marketBaseRate":5.0,"eventId":"29681775","eventTypeId":"2","numberOfWinners":1,"bettingType":"ODDS","marketType":"PLAYER_A_WIN_A_SET","marketTime":"2020-02-02T18:01:00.000Z","suspendTime":"2020-02-02T18:01:00.000Z","bspReconciled":false,"complete":true,"inPlay":true,"crossMatching":true,"runnersVoidable":false,"numberOfActiveRunners":2,"betDelay":3,"status":"SUSPENDED","runners":[{"status":"ACTIVE","sortPriority":1,"id":41364,"name":"Yes"},{"status":"ACTIVE","sortPriority":2,"id":41365,"name":"No"}],"regulators":["MR_INT"],"discountAllowed":true,"timezone":"UTC","openDate":"2020-02-02T18:01:00.000Z","version":3150236347,"name":"Brengle To Win A Set?","eventName":"Brengle v Voegele"}}]}
{"op":"mcm","clk":"1009708313","pt":1580668587517,"mc":[{"id":"1.168230760","tv":0.0}]}
{"op":"mcm","clk":"1009708419","pt":1580668588624,"mc":[{"id":"1.168230760","marketDefinition":{"bspMarket":false,"turnInPlayEnabled":true,"persistenceEnabled":true,"marketBaseRate":5.0,"eventId":"29681775","eventTypeId":"2","numberOfWinners":1,"bettingType":"ODDS","marketType":"PLAYER_A_WIN_A_SET","marketTime":"2020-02-02T18:01:00.000Z","suspendTime":"2020-02-02T18:01:00.000Z","bspReconciled":false,"complete":true,"inPlay":true,"crossMatching":false,"runnersVoidable":false,"numberOfActiveRunners":0,"betDelay":3,"status":"CLOSED","settledTime":"2020-02-02T18:36:25.000Z","runners":[{"status":"WINNER","sortPriority":1,"id":41364,"name":"Yes"},{"status":"LOSER","sortPriority":2,"id":41365,"name":"No"}],"regulators":["MR_INT"],"discountAllowed":true,"timezone":"UTC","openDate":"2020-02-02T18:01:00.000Z","version":3150237240,"name":"Brengle To Win A Set?","eventName":"Brengle v Voegele"}}]}
