{"op":"mcm","clk":"1001501051","pt":1580587070468,"mc":[{"id":"1.168230759","marketDefinition":{"bspMarket":false,"turnInPlayEnabled":true,"persistenceEnabled":true,"marketBaseRate":5.0,"eventId":"29681775","eventTypeId":"2","numberOfWinners":1,"bettingType":"ODDS","marketType":"NUMBER_OF_SETS","marketTime":"2020-02-02T18:00:00.000Z","suspendTime":"2020-02-02T18:00:00.000Z","bspReconciled":false,"complete":true,"inPlay":false,"crossMatching":true,"runnersVoidable":false,"numberOfActiveRunners":2,"betDelay":0,"status":"OPEN","runners":[{"status":"ACTIVE","sortPriority":1,"id":2996931,"name":"Two Sets"},{"status":"ACTIVE","sortPriority":2,"id":2996932,"name":"Three Sets"}],"regulators":["MR_INT"],"discountAllowed":false,"timezone":"UTC","openDate":"2020-02-02T18:00:00.000Z","version":3147219563,"name":"Number of Sets","eventName":"Brengle v Voegele"}}]}
{"op":"mcm","clk":"1001501273","pt":1580587071655,"mc":[{"id":"1.168230759","marketDefinition":{"bspMarket":false,"turnInPlayEnabled":true,"persistenceEnabled":true,"marketBaseRate":5.0,"eventId":"29681775","eventTypeId":"2","numberOfWinners":1,"bettingType":"ODDS","marketType":"NUMBER_OF_SETS","marketTime":"2020-02-02T18:00:00.000Z","suspendTime":"2020-02-02T18:00:00.000Z","bspReconciled":false,"complete":true,"inPlay":false,"crossMatching":true,"runnersVoidable":false,"numberOfActiveRunners":2,"betDelay":0,"status":"OPEN","runners":[{"status":"ACTIVE","sortPriority":1,"id":2996931,"name":"Two Sets"},{"status":"ACTIVE","sortPriority":2,"id":2996932,"name":"Three Sets"}],"regulators":["MR_INT"],"discountAllowed":false,"timezone":"UTC","openDate":"2020-02-02T18:00:00.000Z","version":3147219563,"name":"Number of Sets","eventName":"Brengle v Voegele"}}]}
{"op":"mcm","clk":"1001501657","pt":1580587073688,"mc":[{"id":"1.168230759","marketDefinition":{"bspMarket":false,"turnInPlayEnabled":true,"persistenceEnabled":true,"marketBaseRate":5.0,"eventId":"29681775","eventTypeId":"2","numberOfWinners":1,"bettingType":"ODDS","marketType":"NUMBER_OF_SETS","marketTime":"2020-02-02T18:00:00.000Z","suspendTime":"2020-02-02T18:00:00.000Z","bspReconciled":false,"complete":true,"inPlay":false,"crossMatching":true,"runnersVoidable":false,"numberOfActiveRunners":2,"betDelay":0,"status":"OPEN","runners":[{"status":"ACTIVE","sortPriority":1,"id":2996931,"name":"Two Sets"},{"status":"ACTIVE","sortPriority":2,"id":2996932,"name":"Three Sets"}],"regulators":["MR_INT"],"discountAllowed":true,"timezone":"UTC","openDate":"2020-02-02T18:00:00.000Z","version":3147219563,"name":"Number of Sets","eventName":"Brengle v Voegele"}}]}
{"op":"mcm","clk":"1003070651","pt":1580602601594,"mc":[{"id":"1.168230759","rc":[{"batb":[[0,1.01,2.53]],"ltp":0.0,"tv":0.0,"id":2996932},{"batb":[[0,1.01,2.53]],"ltp":0.0,"tv":0.0,"id":2996931}]}]}
{"op":"mcm","clk":"1003070756","pt":1580602602530,"mc":[{"id":"1.168230759","rc":[{"batb":[[0,1.01,0.51]],"ltp":0.0,"tv":0.0,"id":2996932},{"batb":[[0,1.01,0.51]],"ltp":0.0,"tv":0.0,"id":2996931}]}]}
{"op":"mcm","clk":"1003129976","pt":1580603367494,"mc":[{"id":"1.168230759","rc":[{"batb":[[0,1.01,3.04]],"ltp":0.0,"tv":0.0,"id":2996932},{"batb":[[0,1.01,3.04]],"ltp":0.0,"tv":0.0,"id":2996931}]}]}
{"op":"mcm","clk":"1003130056","pt":1580603368578,"mc":[{"id":"1.168230759","rc":[{"batb":[[0,1.01,1.01]],"ltp":0.0,"tv":0.0,"id":2996932},{"batb":[[0,1.01,1.01]],"ltp":0.0,"tv":0.0,"id":2996931}]}]}
{"op":"mcm","clk":"1009515467","pt":1580666510637,"mc":[{"id":"1.168230759","marketDefinition":{"bspMarket":false,"turnInPlayEnabled":true,"persistenceEnabled":true,"marketBaseRate":5.0,"eventId":"29681775","eventTypeId":"2","numberOfWinners":1,"bettingType":"ODDS","marketType":"NUMBER_OF_SETS","marketTime":"2020-02-02T18:01:00.000Z","suspendTime":"2020-02-02T18:01:00.000Z","bspReconciled":false,"complete":true,"inPlay":false,"crossMatching":true,"runnersVoidable":false,"numberOfActiveRunners":2,"betDelay":0,"status":"OPEN","runners":[{"status":"ACTIVE","sortPriority":1,"id":2996931,"name":"Two Sets"},{"status":"ACTIVE","sortPriority":2,"id":2996932,"name":"Three Sets"}],"regulators":["MR_INT"],"discountAllowed":true,"timezone":"UTC","openDate":"2020-02-02T18:00:00.000Z","version":3150167973,"name":"Number of Sets","eventName":"Brengle v Voegele"}}]}
{"op":"mcm","clk":"1009515709","pt":1580666513126,"mc":[{"id":"1.168230759","marketDefinition":{"bspMarket":false,"turnInPlayEnabled":true,"persistenceEnabled":true,"marketBaseRate":5.0,"eventId":"29681775","eventTypeId":"2","numberOfWinners":1,"bettingType":"ODDS","marketType":"NUMBER_OF_SETS","marketTime":"2020-02-02T18:01:00.000Z","suspendTime":"2020-02-02T18:01:00.000Z","bspReconciled":false,"complete":true,"inPlay":false,"crossMatching":true,"runnersVoidable":false,"numberOfActiveRunners":2,"betDelay":0,"status":"OPEN","runners":[{"status":"ACTIVE","sortPriority":1,"id":2996931,"name":"Two Sets"},{"status":"ACTIVE","sortPriority":2,"id":2996932,"name":"Three Sets"}],"regulators":["MR_INT"],"discountAllowed":true,"timezone":"UTC","openDate":"2020-02-02T18:01:00.000Z","version":3150167973,"name":"Number of Sets","eventName":"Brengle v Voegele"}}]}
{"op":"mcm","clk":"1009519906","pt":1580666557406,"mc":[{"id":"1.168230759","rc":[{"batb":[[0,2.38,34.62],[1,1.01,1.01]],"ltp":0.0,"tv":0.0,"id":2996932},{"batb":[[0,1.62,56.65],[1,1.01,1.01]],"ltp":0.0,"tv":0.0,"id":2996931}]}]}
{"op":"mcm","clk":"1009544477","pt":1580666794604,"mc":[{"id":"1.168230759","rc":[{"batb":[[0,1.63,1.55],[1,1.62,56.65],[2,1.01,1.01]],"ltp":0.0,"tv":0.0,"id":2996931}]}]}
{"op":"mcm","clk":"1009544491","pt":1580666794710,"mc":[{"id":"1.168230759","rc":[{"batb":[[0,2.4,1.05],[1,2.38,34.62],[2,1.01,1.01]],"ltp":0.0,"tv":0.0,"id":2996932}]}]}
{"op":"mcm","clk":"1009555777","pt":1580666900444,"mc":[{"id":"1.168230759","marketDefinition":{"bspMarket":false,"turnInPlayEnabled":true,"persistenceEnabled":true,"marketBaseRate":5.0,"eventId":"29681775","eventTypeId":"2","numberOfWinners":1,"bettingType":"ODDS","marketType":"NUMBER_OF_SETS","marketTime":"2020-02-02T18:01:00.000Z","suspendTime":"2020-02-02T18:01:00.000Z","bspReconciled":false,"complete":true,"inPlay":true,"crossMatching":true,"runnersVoidable":false,"numberOfActiveRunners":2,"betDelay":3,"status":"OPEN","runners":[{"status":"ACTIVE","sortPriority":1,"id":2996931,"name":"Two Sets"},{"status":"ACTIVE","sortPriority":2,"id":2996932,"name":"Three Sets"}],"regulators":["MR_INT"],"discountAllowed":true,"timezone":"UTC","openDate":"2020-02-02T18:01:00.000Z","version":3150176488,"name":"Number of Sets","eventName":"Brengle v Voegele"},"rc":[{"batb":[[0,1.01,0.51],[1,2.38,0],[2,1.01,0]],"ltp":0.0,"tv":0.0,"id":2996932},{"batb":[[0,1.01,0.51],[1,1.62,0],[2,1.01,0]],"ltp":0.0,"tv":0.0,"id":2996931}]}]}
{"op":"mcm","clk":"1009558525","pt":1580666927252,"mc":[{"id":"1.168230759","rc":[{"batb":[[0,2.38,34.78],[1,1.01,0.51]],"ltp":0.0,"tv":0.0,"id":2996932},{"batb":[[0,1.62,56.81],[1,1.01,0.51]],"ltp":0.0,"tv":0.0,"id":2996931}]}]}
{"op":"mcm","clk":"1009560328","pt":1580666943594,"mc":[{"id":"1.168230759","rc":[{"batb":[[0,2.36,34.86]],"ltp":0.0,"tv":0.0,"id":2996932}]}]}
{"op":"mcm","clk":"1009561625","pt":1580666954487,"mc":[{"id":"1.168230759","rc":[{"batb":[[0,2.38,34.86]],"ltp":0.0,"tv":0.0,"id":2996932}]}]}
{"op":"mcm","clk":"1009565466","pt":1580666994005,"mc":[{"id":"1.168230759","rc":[{"batb":[[0,1.62,56.49]],"ltp":0.0,"tv":0.0,"id":2996931}]}]}
{"op":"mcm","clk":"1009570693","pt":1580667045564,"mc":[{"id":"1.168230759","rc":[{"batb":[[1,2.36,35.01],[2,1.01,0.51]],"ltp":0.0,"tv":0.0,"id":2996932}]}]}
{"op":"mcm","clk":"1009570787","pt":1580667046464,"mc":[{"id":"1.168230759","rc":[{"batb":[[0,2.36,35.01],[1,1.01,0.51],[2,1.01,0]],"ltp":0.0,"tv":0.0,"id":2996932}]}]}
{"op":"mcm","clk":"1009574087","pt":1580667081603,"mc":[{"id":"1.168230759","rc":[{"batb":[[0,2.38,34.46],[1,2.36,35.01],[2,1.01,0.51]],"ltp":0.0,"tv":0.0,"id":2996932}]}]}
{"op":"mcm","clk":"1009575658","pt":1580667097615,"mc":[{"id":"1.168230759","rc":[{"batb":[[1,1.61,57.75],[2,1.01,0.51]],"ltp":0.0,"tv":0.0,"id":2996931}]}]}
{"op":"mcm","clk":"1009578430","pt":1580667127548,"mc":[{"id":"1.168230759","rc":[{"batb":[[0,2.36,35.01],[1,1.01,0.51],[2,1.01,0]],"ltp":0.0,"tv":0.0,"id":2996932},{"batb":[[0,1.61,57.75],[1,1.01,0.51],[2,1.01,0]],"ltp":0.0,"tv":0.0,"id":2996931}]}]}
{"op":"mcm","clk":"1009579746","pt":1580667141600,"mc":[{"id":"1.168230759","rc":[{"batb":[[0,1.62,57.04]],"ltp":0.0,"tv":0.0,"id":2996931}]}]}
{"op":"mcm","clk":"1009581121","pt":1580667155180,"mc":[{"id":"1.168230759","rc":[{"batb":[[0,1.62,56.89]],"ltp":0.0,"tv":0.0,"id":2996931}]}]}
{"op":"mcm","clk":"1009581977","pt":1580667163589,"mc":[{"id":"1.168230759","rc":[{"batb":[[0,1.62,56.49]],"ltp":0.0,"tv":0.0,"id":2996931}]}]}
{"op":"mcm","clk":"1009586425","pt":1580667204649,"mc":[{"id":"1.168230759","rc":[{"batb":[[0,1.63,56.34],[1,1.62,56.49],[2,1.01,0.51]],"ltp":0.0,"tv":0.0,"id":2996931}]}]}
{"op":"mcm","clk":"1009586458","pt":1580667204930,"mc":[{"id":"1.168230759","rc":[{"batb":[[1,1.01,0.51],[2,1.01,0]],"ltp":0.0,"tv":0.0,"id":2996931}]}]}
{"op":"mcm","clk":"1009591501","pt":1580667251578,"mc":[{"id":"1.168230759","rc":[{"batb":[[0,2.36,34.86]],"ltp":0.0,"tv":0.0,"id":2996932},{"batb":[[0,1.62,56.81]],"ltp":0.0,"tv":0.0,"id":2996931}]}]}
{"op":"mcm","clk":"1009595096","pt":1580667284492,"mc":[{"id":"1.168230759","rc":[{"batb":[[0,2.38,34.78]],"ltp":0.0,"tv":0.0,"id":2996932},{"batb":[[0,1.61,58.07]],"ltp":0.0,"tv":0.0,"id":2996931}]}]}
{"op":"mcm","clk":"1009597833","pt":1580667310232,"mc":[{"id":"1.168230759","rc":[{"batb":[[0,2.38,34.54]],"ltp":0.0,"tv":0.0,"id":2996932}]}]}
{"op":"mcm","clk":"1009600630","pt":1580667336464,"mc":[{"id":"1.168230759","rc":[{"batb":[[0,2.38,34.31]],"ltp":0.0,"tv":0.0,"id":2996932}]}]}
{"op":"mcm","clk":"1009604334","pt":1580667375289,"mc":[{"id":"1.168230759","rc":[{"batb":[[0,2.42,33.2],[1,2.4,33.91],[2,1.01,0.51]],"ltp":0.0,"tv":0.0,"id":2996932},{"batb":[[0,1.59,60.43]],"ltp":0.0,"tv":0.0,"id":2996931}]}]}
{"op":"mcm","clk":"1009605836","pt":1580667390590,"mc":[{"id":"1.168230759","rc":[{"batb":[[0,2.4,33.52],[1,1.01,0.51],[2,1.01,0]],"ltp":0.0,"tv":0.0,"id":2996932}]}]}
{"op":"mcm","clk":"1009607746","pt":1580667411446,"mc":[{"id":"1.168230759","rc":[{"batb":[[0,2.46,31.79],[1,2.42,33.13],[2,1.01,0.51]],"ltp":0.0,"tv":0.0,"id":2996932},{"batb":[[0,1.58,63.02]],"ltp":0.0,"tv":0.0,"id":2996931}]}]}
{"op":"mcm","clk":"1009607772","pt":1580667411761,"mc":[{"id":"1.168230759","rc":[{"batb":[[0,2.42,33.13],[1,1.01,0.51],[2,1.01,0]],"ltp":0.0,"tv":0.0,"id":2996932}]}]}
{"op":"mcm","clk":"1009611072","pt":1580667448989,"mc":[{"id":"1.168230759","rc":[{"batb":[[0,2.48,30.69],[1,2.44,32.5],[2,1.01,0.51]],"ltp":0.0,"tv":0.0,"id":2996932},{"batb":[[1,1.56,65.07],[2,1.01,0.51]],"ltp":0.0,"tv":0.0,"id":2996931}]}]}
{"op":"mcm","clk":"1009612174","pt":1580667460629,"mc":[{"id":"1.168230759","rc":[{"batb":[[0,2.44,32.5],[1,1.01,0.51],[2,1.01,0]],"ltp":0.0,"tv":0.0,"id":2996932},{"batb":[[0,1.56,65.07],[1,1.01,0.51],[2,1.01,0]],"ltp":0.0,"tv":0.0,"id":2996931}]}]}
{"op":"mcm","clk":"1009612465","pt":1580667463439,"mc":[{"id":"1.168230759","rc":[{"batb":[[0,2.42,32.57]],"ltp":0.0,"tv":0.0,"id":2996932},{"batb":[[0,1.56,64.91]],"ltp":0.0,"tv":0.0,"id":2996931}]}]}
{"op":"mcm","clk":"1009613024","pt":1580667469643,"mc":[{"id":"1.168230759","rc":[{"batb":[[1,2.4,33.83],[2,1.01,0.51]],"ltp":0.0,"tv":0.0,"id":2996932},{"batb":[[0,1.6,59.72],[1,1.59,60.9],[2,1.01,0.51]],"ltp":0.0,"tv":0.0,"id":2996931}]}]}
{"op":"mcm","clk":"1009613639","pt":1580667477347,"mc":[{"id":"1.168230759","rc":[{"batb":[[0,2.4,33.83],[1,1.01,0.51],[2,1.01,0]],"ltp":0.0,"tv":0.0,"id":2996932},{"batb":[[0,1.59,60.9],[1,1.01,0.51],[2,1.01,0]],"ltp":0.0,"tv":0.0,"id":2996931}]}]}
{"op":"mcm","clk":"1009615246","pt":1580667495649,"mc":[{"id":"1.168230759","rc":[{"batb":[[0,2.44,31.87],[1,2.42,32.65],[2,2.4,33.83]],"ltp":0.0,"tv":0.0,"id":2996932},{"batb":[[1,1.57,64.05],[2,1.01,0.51]],"ltp":0.0,"tv":0.0,"id":2996931}]}]}
{"op":"mcm","clk":"1009615314","pt":1580667496343,"mc":[{"id":"1.168230759","rc":[{"batb":[[2,1.01,0.51]],"ltp":0.0,"tv":0.0,"id":2996932}]}]}
{"op":"mcm","clk":"1009622910","pt":1580667578574,"mc":[{"id":"1.168230759","rc":[{"batb":[[0,2.42,32.65],[1,1.01,0.51],[2,1.01,0]],"ltp":0.0,"tv":0.0,"id":2996932},{"batb":[[0,1.57,64.05],[1,1.01,0.51],[2,1.01,0]],"ltp":0.0,"tv":0.0,"id":2996931}]}]}
{"op":"mcm","clk":"1009623964","pt":1580667591988,"mc":[{"id":"1.168230759","rc":[{"batb":[[0,2.5,30.06],[1,2.46,31.63],[2,1.01,0.51]],"ltp":0.0,"tv":0.0,"id":2996932},{"batb":[[1,1.55,67.19],[2,1.01,0.51]],"ltp":0.0,"tv":0.0,"id":2996931}]}]}
{"op":"mcm","clk":"1009625073","pt":1580667606567,"mc":[{"id":"1.168230759","rc":[{"batb":[[0,2.46,31.63],[1,1.01,0.51],[2,1.01,0]],"ltp":0.0,"tv":0.0,"id":2996932},{"batb":[[0,1.55,67.19],[1,1.01,0.51],[2,1.01,0]],"ltp":0.0,"tv":0.0,"id":2996931}]}]}
{"op":"mcm","clk":"1009628458","pt":1580667647439,"mc":[{"id":"1.168230759","rc":[{"batb":[[1,2.42,33.13],[2,1.01,0.51]],"ltp":0.0,"tv":0.0,"id":2996932},{"batb":[[0,1.59,61.37],[1,1.57,63.57],[2,1.55,67.19]],"ltp":0.0,"tv":0.0,"id":2996931}]}]}
{"op":"mcm","clk":"1009628524","pt":1580667648322,"mc":[{"id":"1.168230759","rc":[{"batb":[[2,1.01,0.51]],"ltp":0.0,"tv":0.0,"id":2996931}]}]}
{"op":"mcm","clk":"1009629358","pt":1580667657630,"mc":[{"id":"1.168230759","rc":[{"batb":[[0,2.42,33.13],[1,1.01,0.51],[2,1.01,0]],"ltp":0.0,"tv":0.0,"id":2996932},{"batb":[[0,1.57,63.57],[1,1.01,0.51],[2,1.01,0]],"ltp":0.0,"tv":0.0,"id":2996931}]}]}
{"op":"mcm","clk":"1009631568","pt":1580667682449,"mc":[{"id":"1.168230759","rc":[{"batb":[[0,2.5,30.29],[1,2.46,31.55],[2,1.01,0.51]],"ltp":0.0,"tv":0.0,"id":2996932},{"batb":[[1,1.55,66.49],[2,1.01,0.51]],"ltp":0.0,"tv":0.0,"id":2996931}]}]}
{"op":"mcm","clk":"1009633371","pt":1580667701410,"mc":[{"id":"1.168230759","rc":[{"batb":[[0,2.46,31.55],[1,1.01,0.51],[2,1.01,0]],"ltp":0.0,"tv":0.0,"id":2996932},{"batb":[[0,1.55,66.49],[1,1.01,0.51],[2,1.01,0]],"ltp":0.0,"tv":0.0,"id":2996931}]}]}
{"op":"mcm","clk":"1009636988","pt":1580667745447,"mc":[{"id":"1.168230759","rc":[{"batb":[[0,2.54,28.8],[1,2.48,30.53],[2,1.01,0.51]],"ltp":0.0,"tv":0.0,"id":2996932},{"batb":[[1,1.53,70.18],[2,1.01,0.51]],"ltp":0.0,"tv":0.0,"id":2996931}]}]}
{"op":"mcm","clk":"1009638449","pt":1580667762641,"mc":[{"id":"1.168230759","rc":[{"batb":[[0,2.48,30.53],[1,1.01,0.51],[2,1.01,0]],"ltp":0.0,"tv":0.0,"id":2996932},{"batb":[[0,1.53,69.71],[1,1.01,0.51],[2,1.01,0]],"ltp":0.0,"tv":0.0,"id":2996931}]}]}
{"op":"mcm","clk":"1009639911","pt":1580667779557,"mc":[{"id":"1.168230759","rc":[{"batb":[[1,2.44,32.34],[2,1.01,0.51]],"ltp":0.0,"tv":0.0,"id":2996932},{"batb":[[0,1.58,62.87],[1,1.56,66.01],[2,1.01,0.51]],"ltp":0.0,"tv":0.0,"id":2996931}]}]}
{"op":"mcm","clk":"1009641208","pt":1580667794495,"mc":[{"id":"1.168230759","rc":[{"batb":[[0,2.44,32.34],[1,1.01,0.51],[2,1.01,0]],"ltp":0.0,"tv":0.0,"id":2996932},{"batb":[[0,1.56,65.62],[1,1.01,0.51],[2,1.01,0]],"ltp":0.0,"tv":0.0,"id":2996931}]}]}
{"op":"mcm","clk":"1009643207","pt":1580667817392,"mc":[{"id":"1.168230759","rc":[{"batb":[[0,1.01,0.51],[1,1.01,0]],"ltp":0.0,"tv":0.0,"id":2996932}]}]}
{"op":"mcm","clk":"1009643483","pt":1580667820609,"mc":[{"id":"1.168230759","rc":[{"batb":[[0,2.42,32.65],[1,2.4,33.44],[2,1.01,0.51]],"ltp":0.0,"tv":0.0,"id":2996932},{"batb":[[0,1.6,59.72],[1,1.58,62.87],[2,1.01,0.51]],"ltp":0.0,"tv":0.0,"id":2996931}]}]}
{"op":"mcm","clk":"1009644698","pt":1580667832617,"mc":[{"id":"1.168230759","rc":[{"batb":[[0,2.4,33.44],[1,1.01,0.51],[2,1.01,0]],"ltp":0.0,"tv":0.0,"id":2996932},{"batb":[[0,1.58,62.87],[1,1.01,0.51],[2,1.01,0]],"ltp":0.0,"tv":0.0,"id":2996931}]}]}
{"op":"mcm","clk":"1009644969","pt":1580667835621,"mc":[{"id":"1.168230759","rc":[{"batb":[[0,1.01,0.51],[1,1.01,0]],"ltp":0.0,"tv":0.0,"id":2996932},{"batb":[[0,1.57,63.81]],"ltp":0.0,"tv":0.0,"id":2996931}]}]}
{"op":"mcm","clk":"1009645509","pt":1580667841490,"mc":[{"id":"1.168230759","rc":[{"batb":[[0,2.42,32.97],[1,2.38,34.46],[2,1.01,0.51]],"ltp":0.0,"tv":0.0,"id":2996932},{"batb":[[0,1.6,59.17],[1,1.59,61.29],[2,1.01,0.51]],"ltp":0.0,"tv":0.0,"id":2996931}]}]}
{"op":"mcm","clk":"1009646534","pt":1580667853633,"mc":[{"id":"1.168230759","rc":[{"batb":[[0,2.38,34.46],[1,1.01,0.51],[2,1.01,0]],"ltp":0.0,"tv":0.0,"id":2996932},{"batb":[[0,1.59,61.14],[1,1.01,0.51],[2,1.01,0]],"ltp":0.0,"tv":0.0,"id":2996931}]}]}
{"op":"mcm","clk":"1009648037","pt":1580667870511,"mc":[{"id":"1.168230759","rc":[{"batb":[[1,2.34,35.96],[2,1.01,0.51]],"ltp":0.0,"tv":0.0,"id":2996932},{"batb":[[0,1.62,56.81],[1,1.61,58.07],[2,1.01,0.51]],"ltp":0.0,"tv":0.0,"id":2996931}]}]}
{"op":"mcm","clk":"1009649980","pt":1580667895645,"mc":[{"id":"1.168230759","rc":[{"batb":[[0,2.34,35.96],[1,1.01,0.51],[2,1.01,0]],"ltp":0.0,"tv":0.0,"id":2996932},{"batb":[[0,1.61,57.91],[1,1.01,0.51],[2,1.01,0]],"ltp":0.0,"tv":0.0,"id":2996931}]}]}
{"op":"mcm","clk":"1009652254","pt":1580667926070,"mc":[{"id":"1.168230759","rc":[{"batb":[[0,2.4,33.6],[1,2.36,35.33],[2,1.01,0.51]],"ltp":0.0,"tv":0.0,"id":2996932},{"batb":[[1,1.6,59.96],[2,1.01,0.51]],"ltp":0.0,"tv":0.0,"id":2996931}]}]}
{"op":"mcm","clk":"1009653065","pt":1580667937567,"mc":[{"id":"1.168230759","rc":[{"batb":[[0,2.36,35.33],[1,1.01,0.51],[2,1.01,0]],"ltp":0.0,"tv":0.0,"id":2996932},{"batb":[[0,1.6,59.96],[1,1.01,0.51],[2,1.01,0]],"ltp":0.0,"tv":0.0,"id":2996931}]}]}
{"op":"mcm","clk":"1009653298","pt":1580667940593,"mc":[{"id":"1.168230759","rc":[{"batb":[[1,1.59,60.43],[2,1.01,0.51]],"ltp":0.0,"tv":0.0,"id":2996931}]}]}
{"op":"mcm","clk":"1009653368","pt":1580667941277,"mc":[{"id":"1.168230759","rc":[{"batb":[[0,2.36,35.01]],"ltp":0.0,"tv":0.0,"id":2996932},{"batb":[[0,1.59,60.43],[1,1.01,0.51],[2,1.01,0]],"ltp":0.0,"tv":0.0,"id":2996931}]}]}
{"op":"mcm","clk":"1009655142","pt":1580667963605,"mc":[{"id":"1.168230759","rc":[{"batb":[[0,2.44,31.87],[1,2.4,33.83],[2,2.36,35.01]],"ltp":0.0,"tv":0.0,"id":2996932},{"batb":[[1,1.58,62.71],[2,1.01,0.51]],"ltp":0.0,"tv":0.0,"id":2996931}]}]}
{"op":"mcm","clk":"1009655158","pt":1580667963808,"mc":[{"id":"1.168230759","rc":[{"batb":[[2,1.01,0.51]],"ltp":0.0,"tv":0.0,"id":2996932}]}]}
{"op":"mcm","clk":"1009656115","pt":1580667975526,"mc":[{"id":"1.168230759","rc":[{"batb":[[0,2.4,33.83],[1,1.01,0.51],[2,1.01,0]],"ltp":0.0,"tv":0.0,"id":2996932},{"batb":[[0,1.58,62.71],[1,1.01,0.51],[2,1.01,0]],"ltp":0.0,"tv":0.0,"id":2996931}]}]}
{"op":"mcm","clk":"1009657516","pt":1580667994349,"mc":[{"id":"1.168230759","rc":[{"batb":[[0,2.48,30.84],[1,2.42,32.97],[2,1.01,0.51]],"ltp":0.0,"tv":0.0,"id":2996932},{"batb":[[1,1.56,65.07],[2,1.01,0.51]],"ltp":0.0,"tv":0.0,"id":2996931}]}]}
{"op":"mcm","clk":"1009658372","pt":1580668004644,"mc":[{"id":"1.168230759","rc":[{"batb":[[0,2.42,32.97],[1,1.01,0.51],[2,1.01,0]],"ltp":0.0,"tv":0.0,"id":2996932},{"batb":[[0,1.56,65.07],[1,1.01,0.51],[2,1.01,0]],"ltp":0.0,"tv":0.0,"id":2996931}]}]}
{"op":"mcm","clk":"1009659584","pt":1580668019542,"mc":[{"id":"1.168230759","rc":[{"batb":[[0,2.52,29.51],[1,2.46,31.16],[2,1.01,0.51]],"ltp":0.0,"tv":0.0,"id":2996932},{"batb":[[1,1.54,68.85],[2,1.01,0.51]],"ltp":0.0,"tv":0.0,"id":2996931}]}]}
{"op":"mcm","clk":"1009660198","pt":1580668027376,"mc":[{"id":"1.168230759","rc":[{"batb":[[0,2.5,29.9]],"ltp":0.0,"tv":0.0,"id":2996932},{"batb":[[0,1.57,64.36],[1,1.54,68.06]],"ltp":0.0,"tv":0.0,"id":2996931}]}]}
{"op":"mcm","clk":"1009661436","pt":1580668042194,"mc":[{"id":"1.168230759","rc":[{"batb":[[0,2.46,31.16],[1,1.01,0.51],[2,1.01,0]],"ltp":0.0,"tv":0.0,"id":2996932},{"batb":[[0,1.54,68.06],[1,1.01,0.51],[2,1.01,0]],"ltp":0.0,"tv":0.0,"id":2996931}]}]}
{"op":"mcm","clk":"1009666575","pt":1580668110378,"mc":[{"id":"1.168230759","rc":[{"batb":[[0,1.01,0.51],[1,1.01,0]],"ltp":0.0,"tv":0.0,"id":2996932},{"batb":[[0,1.01,0.51],[1,1.01,0]],"ltp":0.0,"tv":0.0,"id":2996931}]}]}
{"op":"mcm","clk":"1009668048","pt":1580668126487,"mc":[{"id":"1.168230759","rc":[{"batb":[[0,2.56,28.01],[1,2.52,29.58],[2,1.01,0.51]],"ltp":0.0,"tv":0.0,"id":2996932},{"batb":[[0,1.54,68.06],[1,1.52,72.39],[2,1.01,0.51]],"ltp":0.0,"tv":0.0,"id":2996931}]}]}
{"op":"mcm","clk":"1009668861","pt":1580668136288,"mc":[{"id":"1.168230759","rc":[{"batb":[[0,2.52,29.58],[1,1.01,0.51],[2,1.01,0]],"ltp":0.0,"tv":0.0,"id":2996932},{"batb":[[0,1.52,72.39],[1,1.01,0.51],[2,1.01,0]],"ltp":0.0,"tv":0.0,"id":2996931}]}]}
{"op":"mcm","clk":"1009671744","pt":1580668173540,"mc":[{"id":"1.168230759","rc":[{"batb":[[1,2.46,31.47],[2,1.01,0.51]],"ltp":0.0,"tv":0.0,"id":2996932},{"batb":[[0,1.56,64.99],[1,1.54,68.53],[2,1.01,0.51]],"ltp":0.0,"tv":0.0,"id":2996931}]}]}
{"op":"mcm","clk":"1009673010","pt":1580668189539,"mc":[{"id":"1.168230759","rc":[{"batb":[[0,2.46,31.47],[1,1.01,0.51],[2,1.01,0]],"ltp":0.0,"tv":0.0,"id":2996932},{"batb":[[0,1.54,68.53],[1,1.01,0.51],[2,1.01,0]],"ltp":0.0,"tv":0.0,"id":2996931}]}]}
{"op":"mcm","clk":"1009673723","pt":1580668198484,"mc":[{"id":"1.168230759","rc":[{"batb":[[1,2.4,33.36],[2,1.01,0.51]],"ltp":0.0,"tv":0.0,"id":2996932},{"batb":[[0,1.59,61.53],[1,1.56,65.23],[2,1.01,0.51]],"ltp":0.0,"tv":0.0,"id":2996931}]}]}
{"op":"mcm","clk":"1009675034","pt":1580668213371,"mc":[{"id":"1.168230759","rc":[{"batb":[[0,2.4,33.36],[1,1.01,0.51],[2,1.01,0]],"ltp":0.0,"tv":0.0,"id":2996932},{"batb":[[0,1.56,65.23],[1,1.01,0.51],[2,1.01,0]],"ltp":0.0,"tv":0.0,"id":2996931}]}]}
{"op":"mcm","clk":"1009676766","pt":1580668235290,"mc":[{"id":"1.168230759","rc":[{"batb":[[0,2.52,29.43],[1,2.46,31.32],[2,1.01,0.51]],"ltp":0.0,"tv":0.0,"id":2996932},{"batb":[[1,1.54,68.61],[2,1.01,0.51]],"ltp":0.0,"tv":0.0,"id":2996931}]}]}
{"op":"mcm","clk":"1009677956","pt":1580668251619,"mc":[{"id":"1.168230759","rc":[{"batb":[[0,2.46,31.32],[1,1.01,0.51],[2,1.01,0]],"ltp":0.0,"tv":0.0,"id":2996932},{"batb":[[0,1.54,68.61],[1,1.01,0.51],[2,1.01,0]],"ltp":0.0,"tv":0.0,"id":2996931}]}]}
{"op":"mcm","clk":"1009681507","pt":1580668296556,"mc":[{"id":"1.168230759","rc":[{"batb":[[1,2.4,33.68],[2,1.01,0.51]],"ltp":0.0,"tv":0.0,"id":2996932},{"batb":[[0,1.58,61.77],[1,1.56,65.86],[2,1.54,68.61]],"ltp":0.0,"tv":0.0,"id":2996931}]}]}
{"op":"mcm","clk":"1009681595","pt":1580668297548,"mc":[{"id":"1.168230759","rc":[{"batb":[[2,1.01,0.51]],"ltp":0.0,"tv":0.0,"id":2996931}]}]}
{"op":"mcm","clk":"1009682612","pt":1580668310340,"mc":[{"id":"1.168230759","rc":[{"batb":[[0,2.4,33.68],[1,1.01,0.51],[2,1.01,0]],"ltp":0.0,"tv":0.0,"id":2996932},{"batb":[[0,1.56,65.86],[1,1.01,0.51],[2,1.01,0]],"ltp":0.0,"tv":0.0,"id":2996931}]}]}
{"op":"mcm","clk":"1009684174","pt":1580668329581,"mc":[{"id":"1.168230759","rc":[{"batb":[[0,2.54,29.11],[1,2.46,31.16],[2,1.01,0.51]],"ltp":0.0,"tv":0.0,"id":2996932},{"batb":[[1,1.53,69.95],[2,1.01,0.51]],"ltp":0.0,"tv":0.0,"id":2996931}]}]}
{"op":"mcm","clk":"1009685535","pt":1580668344585,"mc":[{"id":"1.168230759","rc":[{"batb":[[0,2.46,31.16],[1,1.01,0.51],[2,1.01,0]],"ltp":0.0,"tv":0.0,"id":2996932},{"batb":[[0,1.53,69.95],[1,1.01,0.51],[2,1.01,0]],"ltp":0.0,"tv":0.0,"id":2996931}]}]}
{"op":"mcm","clk":"1009687055","pt":1580668360499,"mc":[{"id":"1.168230759","rc":[{"batb":[[0,2.6,27.07],[1,2.54,28.88],[2,1.01,0.51]],"ltp":0.0,"tv":0.0,"id":2996932},{"batb":[[1,1.51,74.67],[2,1.01,0.51]],"ltp":0.0,"tv":0.0,"id":2996931}]}]}
{"op":"mcm","clk":"1009688516","pt":1580668375646,"mc":[{"id":"1.168230759","rc":[{"batb":[[0,2.54,28.88],[1,1.01,0.51],[2,1.01,0]],"ltp":0.0,"tv":0.0,"id":2996932},{"batb":[[0,1.51,74.67],[1,1.01,0.51],[2,1.01,0]],"ltp":0.0,"tv":0.0,"id":2996931}]}]}
{"op":"mcm","clk":"1009690951","pt":1580668401633,"mc":[{"id":"1.168230759","rc":[{"batb":[[0,2.68,25.02],[1,2.58,27.7],[2,2.54,28.88]],"ltp":0.0,"tv":0.0,"id":2996932},{"batb":[[1,1.49,79.23],[2,1.01,0.51]],"ltp":0.0,"tv":0.0,"id":2996931}]}]}
{"op":"mcm","clk":"1009691023","pt":1580668402467,"mc":[{"id":"1.168230759","rc":[{"batb":[[2,1.01,0.51]],"ltp":0.0,"tv":0.0,"id":2996932}]}]}
{"op":"mcm","clk":"1009692563","pt":1580668419553,"mc":[{"id":"1.168230759","rc":[{"batb":[[0,2.58,27.7],[1,1.01,0.51],[2,1.01,0]],"ltp":0.0,"tv":0.0,"id":2996932},{"batb":[[0,1.49,79.23],[1,1.01,0.51],[2,1.01,0]],"ltp":0.0,"tv":0.0,"id":2996931}]}]}
{"op":"mcm","clk":"1009692809","pt":1580668422377,"mc":[{"id":"1.168230759","rc":[{"batb":[[0,2.56,28.17]],"ltp":0.0,"tv":0.0,"id":2996932},{"batb":[[0,1.49,78.29]],"ltp":0.0,"tv":0.0,"id":2996931}]}]}
{"op":"mcm","clk":"1009694010","pt":1580668435590,"mc":[{"id":"1.168230759","rc":[{"batb":[[0,2.74,23.68],[1,2.62,26.67],[2,2.56,28.17]],"ltp":0.0,"tv":0.0,"id":2996932},{"batb":[[1,1.47,82.46],[2,1.01,0.51]],"ltp":0.0,"tv":0.0,"id":2996931}]}]}
{"op":"mcm","clk":"1009694091","pt":1580668436380,"mc":[{"id":"1.168230759","rc":[{"batb":[[2,1.01,0.51]],"ltp":0.0,"tv":0.0,"id":2996932}]}]}
{"op":"mcm","clk":"1009694839","pt":1580668444500,"mc":[{"id":"1.168230759","rc":[{"batb":[[0,2.62,26.67],[1,1.01,0.51],[2,1.01,0]],"ltp":0.0,"tv":0.0,"id":2996932},{"batb":[[0,1.47,82.46],[1,1.01,0.51],[2,1.01,0]],"ltp":0.0,"tv":0.0,"id":2996931}]}]}
{"op":"mcm","clk":"1009695532","pt":1580668451530,"mc":[{"id":"1.168230759","rc":[{"batb":[[0,2.8,22.19],[1,2.68,24.94],[2,2.62,26.67]],"ltp":0.0,"tv":0.0,"id":2996932},{"batb":[[1,1.45,88.28],[2,1.01,0.51]],"ltp":0.0,"tv":0.0,"id":2996931}]}]}
{"op":"mcm","clk":"1009695627","pt":1580668452529,"mc":[{"id":"1.168230759","rc":[{"batb":[[2,1.01,0.51]],"ltp":0.0,"tv":0.0,"id":2996932}]}]}
{"op":"mcm","clk":"1009696146","pt":1580668457627,"mc":[{"id":"1.168230759","rc":[{"batb":[[0,2.68,24.94],[1,1.01,0.51],[2,1.01,0]],"ltp":0.0,"tv":0.0,"id":2996932},{"batb":[[0,1.45,88.28],[1,1.01,0.51],[2,1.01,0]],"ltp":0.0,"tv":0.0,"id":2996931}]}]}
{"op":"mcm","clk":"1009697995","pt":1580668475507,"mc":[{"id":"1.168230759","rc":[{"batb":[[1,2.58,27.7],[2,1.01,0.51]],"ltp":0.0,"tv":0.0,"id":2996932},{"batb":[[0,1.51,74.91],[1,1.48,80.41],[2,1.01,0.51]],"ltp":0.0,"tv":0.0,"id":2996931}]}]}
{"op":"mcm","clk":"1009698797","pt":1580668483436,"mc":[{"id":"1.168230759","rc":[{"batb":[[0,2.58,27.7],[1,1.01,0.51],[2,1.01,0]],"ltp":0.0,"tv":0.0,"id":2996932},{"batb":[[0,1.48,80.41],[1,1.01,0.51],[2,1.01,0]],"ltp":0.0,"tv":0.0,"id":2996931}]}]}
{"op":"mcm","clk":"1009700530","pt":1580668502649,"mc":[{"id":"1.168230759","rc":[{"batb":[[0,2.78,22.9],[1,2.64,26.04],[2,1.01,0.51]],"ltp":0.0,"tv":0.0,"id":2996932},{"batb":[[1,1.45,86.79],[2,1.01,0.51]],"ltp":0.0,"tv":0.0,"id":2996931}]}]}
{"op":"mcm","clk":"1009701551","pt":1580668514355,"mc":[{"id":"1.168230759","rc":[{"batb":[[0,2.64,26.04],[1,1.01,0.51],[2,1.01,0]],"ltp":0.0,"tv":0.0,"id":2996932},{"batb":[[0,1.45,86.79],[1,1.01,0.51],[2,1.01,0]],"ltp":0.0,"tv":0.0,"id":2996931}]}]}
{"op":"mcm","clk":"1009702662","pt":1580668526574,"mc":[{"id":"1.168230759","rc":[{"batb":[[1,2.54,29.03],[2,1.01,0.51]],"ltp":0.0,"tv":0.0,"id":2996932},{"batb":[[0,1.52,72.31],[1,1.49,77.82],[2,1.45,86.79]],"ltp":0.0,"tv":0.0,"id":2996931}]}]}
{"op":"mcm","clk":"1009702739","pt":1580668527347,"mc":[{"id":"1.168230759","rc":[{"batb":[[2,1.01,0.51]],"ltp":0.0,"tv":0.0,"id":2996931}]}]}
{"op":"mcm","clk":"1009703494","pt":1580668535568,"mc":[{"id":"1.168230759","rc":[{"batb":[[0,2.54,29.03],[1,1.01,0.51],[2,1.01,0]],"ltp":0.0,"tv":0.0,"id":2996932},{"batb":[[0,1.49,77.82],[1,1.01,0.51],[2,1.01,0]],"ltp":0.0,"tv":0.0,"id":2996931}]}]}
{"op":"mcm","clk":"1009705338","pt":1580668554999,"mc":[{"id":"1.168230759","rc":[{"batb":[[0,2.72,23.84],[1,2.46,31.71],[2,1.01,0.51]],"ltp":0.0,"tv":0.0,"id":2996932},{"batb":[[1,1.4,101.58],[2,1.01,0.51]],"ltp":0.0,"tv":0.0,"id":2996931}]}]}
{"op":"mcm","clk":"1009706110","pt":1580668563195,"mc":[{"id":"1.168230759","rc":[{"batb":[[1,2.44,31.79]],"ltp":0.0,"tv":0.0,"id":2996932},{"batb":[[0,1.49,77.58],[1,1.4,101.34]],"ltp":0.0,"tv":0.0,"id":2996931}]}]}
{"op":"mcm","clk":"1009706806","pt":1580668571537,"mc":[{"id":"1.168230759","rc":[{"batb":[[0,2.7,24.39]],"ltp":0.0,"tv":0.0,"id":2996932},{"batb":[[0,1.5,76.4],[1,1.41,99.93]],"ltp":0.0,"tv":0.0,"id":2996931}]}]}
{"op":"mcm","clk":"1009706906","pt":1580668572602,"mc":[{"id":"1.168230759","rc":[{"batb":[[0,2.44,31.79],[1,1.01,0.51],[2,1.01,0]],"ltp":0.0,"tv":0.0,"id":2996932},{"batb":[[0,1.41,99.93],[1,1.01,0.51],[2,1.01,0]],"ltp":0.0,"tv":0.0,"id":2996931}]}]}
{"op":"mcm","clk":"1009716119","pt":1580668669121,"mc":[{"id":"1.168230759","rc":[{"batb":[[0,1.01,0.51],[1,1.01,0]],"ltp":0.0,"tv":0.0,"id":2996932},{"batb":[[0,1.01,0.51],[1,1.01,0]],"ltp":0.0,"tv":0.0,"id":2996931}]}]}
{"op":"mcm","clk":"1009718176","pt":1580668693640,"mc":[{"id":"1.168230759","rc":[{"batb":[[0,2.44,32.42],[1,2.22,41.94],[2,1.01,0.51]],"ltp":0.0,"tv":0.0,"id":2996932},{"batb":[[0,1.6,60.03],[1,1.49,77.5],[2,1.01,0.51]],"ltp":0.0,"tv":0.0,"id":2996931}]}]}
{"op":"mcm","clk":"1009719334","pt":1580668707323,"mc":[{"id":"1.168230759","rc":[{"batb":[[0,2.22,41.94],[1,1.01,0.51],[2,1.01,0]],"ltp":0.0,"tv":0.0,"id":2996932},{"batb":[[0,1.49,77.5],[1,1.01,0.51],[2,1.01,0]],"ltp":0.0,"tv":0.0,"id":2996931}]}]}
{"op":"mcm","clk":"1009722401","pt":1580668740284,"mc":[{"id":"1.168230759","rc":[{"batb":[[0,2.72,23.92],[1,2.4,33.44],[2,1.01,0.51]],"ltp":0.0,"tv":0.0,"id":2996932},{"batb":[[1,1.39,105.98],[2,1.01,0.51]],"ltp":0.0,"tv":0.0,"id":2996931}]}]}
{"op":"mcm","clk":"1009724261","pt":1580668760597,"mc":[{"id":"1.168230759","rc":[{"batb":[[0,2.4,33.44],[1,1.01,0.51],[2,1.01,0]],"ltp":0.0,"tv":0.0,"id":2996932},{"batb":[[0,1.39,105.98],[1,1.01,0.51],[2,1.01,0]],"ltp":0.0,"tv":0.0,"id":2996931}]}]}
{"op":"mcm","clk":"1009724361","pt":1580668761603,"mc":[{"id":"1.168230759","rc":[{"batb":[[0,1.39,105.59]],"ltp":0.0,"tv":0.0,"id":2996931}]}]}
{"op":"mcm","clk":"1009726862","pt":1580668788332,"mc":[{"id":"1.168230759","rc":[{"batb":[[1,2.16,44.85],[2,1.01,0.51]],"ltp":0.0,"tv":0.0,"id":2996932},{"batb":[[0,1.61,58.22],[1,1.49,78.21],[2,1.01,0.51]],"ltp":0.0,"tv":0.0,"id":2996931}]}]}
{"op":"mcm","clk":"1009728493","pt":1580668806572,"mc":[{"id":"1.168230759","rc":[{"batb":[[0,2.16,44.85],[1,1.01,0.51],[2,1.01,0]],"ltp":0.0,"tv":0.0,"id":2996932},{"batb":[[0,1.49,78.21],[1,1.01,0.51],[2,1.01,0]],"ltp":0.0,"tv":0.0,"id":2996931}]}]}
{"op":"mcm","clk":"1009730071","pt":1580668825162,"mc":[{"id":"1.168230759","rc":[{"batb":[[1,2.02,54.68],[2,1.01,0.51]],"ltp":0.0,"tv":0.0,"id":2996932},{"batb":[[0,1.74,44.93],[1,1.63,55.23],[2,1.01,0.51]],"ltp":0.0,"tv":0.0,"id":2996931}]}]}
{"op":"mcm","clk":"1009731244","pt":1580668838321,"mc":[{"id":"1.168230759","rc":[{"batb":[[0,2.02,54.68],[1,1.01,0.51],[2,1.01,0]],"ltp":0.0,"tv":0.0,"id":2996932},{"batb":[[0,1.63,55.23],[1,1.01,0.51],[2,1.01,0]],"ltp":0.0,"tv":0.0,"id":2996931}]}]}
{"op":"mcm","clk":"1009733983","pt":1580668865610,"mc":[{"id":"1.168230759","rc":[{"batb":[[1,1.83,37.61],[2,1.01,0.51]],"ltp":0.0,"tv":0.0,"id":2996932},{"batb":[[0,1.84,37.22],[1,1.72,46.58],[2,1.01,0.51]],"ltp":0.0,"tv":0.0,"id":2996931}]}]}
{"op":"mcm","clk":"1009737438","pt":1580668902416,"mc":[{"id":"1.168230759","rc":[{"batb":[[0,1.83,37.61],[1,1.01,0.51],[2,1.01,0]],"ltp":0.0,"tv":0.0,"id":2996932},{"batb":[[0,1.72,46.58],[1,1.01,0.51],[2,1.01,0]],"ltp":0.0,"tv":0.0,"id":2996931}]}]}
{"op":"mcm","clk":"1009738829","pt":1580668917447,"mc":[{"id":"1.168230759","rc":[{"batb":[[1,1.64,54.13],[2,1.01,0.51]],"ltp":0.0,"tv":0.0,"id":2996932},{"batb":[[0,2.04,54.13],[1,1.87,34.93],[2,1.01,0.51]],"ltp":0.0,"tv":0.0,"id":2996931}]}]}
{"op":"mcm","clk":"1009739643","pt":1580668925636,"mc":[{"id":"1.168230759","rc":[{"batb":[[0,1.64,54.13],[1,1.01,0.51],[2,1.01,0]],"ltp":0.0,"tv":0.0,"id":2996932},{"batb":[[0,1.87,34.93],[1,1.01,0.51],[2,1.01,0]],"ltp":0.0,"tv":0.0,"id":2996931}]}]}
{"op":"mcm","clk":"1009741421","pt":1580668943559,"mc":[{"id":"1.168230759","rc":[{"batb":[[1,1.5,75.85],[2,1.01,0.51]],"ltp":0.0,"tv":0.0,"id":2996932},{"batb":[[0,2.34,36.43],[1,2.1,48.47],[2,1.87,34.93]],"ltp":0.0,"tv":0.0,"id":2996931}]}]}
{"op":"mcm","clk":"1009741511","pt":1580668944555,"mc":[{"id":"1.168230759","rc":[{"batb":[[2,1.01,0.51]],"ltp":0.0,"tv":0.0,"id":2996931}]}]}
{"op":"mcm","clk":"1009742317","pt":1580668952362,"mc":[{"id":"1.168230759","rc":[{"batb":[[0,1.5,75.85],[1,1.01,0.51],[2,1.01,0]],"ltp":0.0,"tv":0.0,"id":2996932},{"batb":[[0,2.1,48.47],[1,1.01,0.51],[2,1.01,0]],"ltp":0.0,"tv":0.0,"id":2996931}]}]}
{"op":"mcm","clk":"1009744198","pt":1580668970569,"mc":[{"id":"1.168230759","rc":[{"batb":[[1,1.41,97.41],[2,1.01,0.51]],"ltp":0.0,"tv":0.0,"id":2996932},{"batb":[[0,2.7,24.55],[1,2.5,30.21],[2,1.01,0.51]],"ltp":0.0,"tv":0.0,"id":2996931}]}]}
{"op":"mcm","clk":"1009745170","pt":1580668980373,"mc":[{"id":"1.168230759","rc":[{"batb":[[0,1.41,97.41],[1,1.01,0.51],[2,1.01,0]],"ltp":0.0,"tv":0.0,"id":2996932},{"batb":[[0,2.5,29.98],[1,1.01,0.51],[2,1.01,0]],"ltp":0.0,"tv":0.0,"id":2996931}]}]}
{"op":"mcm","clk":"1009746469","pt":1580668994200,"mc":[{"id":"1.168230759","rc":[{"batb":[[1,1.33,128.72],[2,1.01,0.51]],"ltp":0.0,"tv":0.0,"id":2996932},{"batb":[[0,3.05,45.08],[1,2.64,26.04],[2,1.01,0.51]],"ltp":0.0,"tv":0.0,"id":2996931}]}]}
{"op":"mcm","clk":"1009749660","pt":1580669024616,"mc":[{"id":"1.168230759","rc":[{"batb":[[0,1.33,128.72],[1,1.01,0.51],[2,1.01,0]],"ltp":0.0,"tv":0.0,"id":2996932},{"batb":[[0,2.64,26.04],[1,1.01,0.51],[2,1.01,0]],"ltp":0.0,"tv":0.0,"id":2996931}]}]}
{"op":"mcm","clk":"1009751796","pt":1580669044534,"mc":[{"id":"1.168230759","rc":[{"batb":[[1,1.27,167.2],[2,1.01,0.51]],"ltp":0.0,"tv":0.0,"id":2996932},{"batb":[[0,3.5,31.47],[1,3,46.66],[2,1.01,0.51]],"ltp":0.0,"tv":0.0,"id":2996931}]}]}
{"op":"mcm","clk":"1009753324","pt":1580669058648,"mc":[{"id":"1.168230759","rc":[{"batb":[[0,1.27,167.2],[1,1.01,0.51],[2,1.01,0]],"ltp":0.0,"tv":0.0,"id":2996932},{"batb":[[0,3,46.66],[1,1.01,0.51],[2,1.01,0]],"ltp":0.0,"tv":0.0,"id":2996931}]}]}
{"op":"mcm","clk":"1009753622","pt":1580669061455,"mc":[{"id":"1.168230759","rc":[{"batb":[[0,1.26,168.62]],"ltp":0.0,"tv":0.0,"id":2996932},{"batb":[[0,3,46.11]],"ltp":0.0,"tv":0.0,"id":2996931}]}]}
{"op":"mcm","clk":"1009754240","pt":1580669068620,"mc":[{"id":"1.168230759","rc":[{"batb":[[1,1.21,212.44],[2,1.01,0.51]],"ltp":0.0,"tv":0.0,"id":2996932},{"batb":[[0,4,43.75],[1,3.55,30.69],[2,3,46.11]],"ltp":0.0,"tv":0.0,"id":2996931}]}]}
{"op":"mcm","clk":"1009754320","pt":1580669069561,"mc":[{"id":"1.168230759","rc":[{"batb":[[2,1.01,0.51]],"ltp":0.0,"tv":0.0,"id":2996931}]}]}
{"op":"mcm","clk":"1009755232","pt":1580669079553,"mc":[{"id":"1.168230759","rc":[{"batb":[[0,1.21,212.44],[1,1.01,0.51],[2,1.01,0]],"ltp":0.0,"tv":0.0,"id":2996932},{"batb":[[0,3.55,30.69],[1,1.01,0.51],[2,1.01,0]],"ltp":0.0,"tv":0.0,"id":2996931}]}]}
{"op":"mcm","clk":"1009756197","pt":1580669090559,"mc":[{"id":"1.168230759","rc":[{"batb":[[0,1.33,131.24],[1,1.25,178.53],[2,1.21,212.44]],"ltp":0.0,"tv":0.0,"id":2996932},{"batb":[[1,2.96,48.07],[2,1.01,0.51]],"ltp":0.0,"tv":0.0,"id":2996931}]}]}
{"op":"mcm","clk":"1009756278","pt":1580669091549,"mc":[{"id":"1.168230759","rc":[{"batb":[[2,1.01,0.51]],"ltp":0.0,"tv":0.0,"id":2996932}]}]}
{"op":"mcm","clk":"1009757589","pt":1580669106597,"mc":[{"id":"1.168230759","rc":[{"batb":[[0,1.25,178.53],[1,1.01,0.51],[2,1.01,0]],"ltp":0.0,"tv":0.0,"id":2996932},{"batb":[[0,2.96,48.07],[1,1.01,0.51],[2,1.01,0]],"ltp":0.0,"tv":0.0,"id":2996931}]}]}
{"op":"mcm","clk":"1009757862","pt":1580669109607,"mc":[{"id":"1.168230759","rc":[{"batb":[[0,2.98,47.6],[1,2.96,48.07],[2,1.01,0.51]],"ltp":0.0,"tv":0.0,"id":2996931}]}]}
{"op":"mcm","clk":"1009757950","pt":1580669110500,"mc":[{"id":"1.168230759","rc":[{"batb":[[1,1.01,0.51],[2,1.01,0]],"ltp":0.0,"tv":0.0,"id":2996931}]}]}
{"op":"mcm","clk":"1009758861","pt":1580669121509,"mc":[{"id":"1.168230759","rc":[{"batb":[[0,1.42,94.18],[1,1.31,140.53],[2,1.01,0.51]],"ltp":0.0,"tv":0.0,"id":2996932},{"batb":[[1,2.44,31.87],[2,1.01,0.51]],"ltp":0.0,"tv":0.0,"id":2996931}]}]}
{"op":"mcm","clk":"1009760278","pt":1580669137615,"mc":[{"id":"1.168230759","rc":[{"batb":[[0,1.31,140.53],[1,1.01,0.51],[2,1.01,0]],"ltp":0.0,"tv":0.0,"id":2996932},{"batb":[[0,2.44,31.87],[1,1.01,0.51],[2,1.01,0]],"ltp":0.0,"tv":0.0,"id":2996931}]}]}
{"op":"mcm","clk":"1009760952","pt":1580669145524,"mc":[{"id":"1.168230759","rc":[{"batb":[[1,1.22,211.65],[2,1.01,0.51]],"ltp":0.0,"tv":0.0,"id":2996932},{"batb":[[0,3.65,27.93],[1,2.96,48.15],[2,2.44,31.87]],"ltp":0.0,"tv":0.0,"id":2996931}]}]}
{"op":"mcm","clk":"1009761060","pt":1580669146632,"mc":[{"id":"1.168230759","rc":[{"batb":[[2,1.01,0.51]],"ltp":0.0,"tv":0.0,"id":2996931}]}]}
{"op":"mcm","clk":"1009762273","pt":1580669161479,"mc":[{"id":"1.168230759","rc":[{"batb":[[0,1.22,211.65],[1,1.01,0.51],[2,1.01,0]],"ltp":0.0,"tv":0.0,"id":2996932},{"batb":[[0,2.96,48.15],[1,1.01,0.51],[2,1.01,0]],"ltp":0.0,"tv":0.0,"id":2996931}]}]}
{"op":"mcm","clk":"1009764518","pt":1580669187166,"mc":[{"id":"1.168230759","rc":[{"batb":[[0,1.43,93.08],[1,1.31,139.42],[2,1.01,0.51]],"ltp":0.0,"tv":0.0,"id":2996932},{"batb":[[1,2.44,32.42],[2,1.01,0.51]],"ltp":0.0,"tv":0.0,"id":2996931}]}]}
{"op":"mcm","clk":"1009766573","pt":1580669210610,"mc":[{"id":"1.168230759","rc":[{"batb":[[0,1.31,139.27],[1,1.01,0.51],[2,1.01,0]],"ltp":0.0,"tv":0.0,"id":2996932},{"batb":[[0,2.44,32.42],[1,1.01,0.51],[2,1.01,0]],"ltp":0.0,"tv":0.0,"id":2996931}]}]}
{"op":"mcm","clk":"1009767810","pt":1580669224598,"mc":[{"id":"1.168230759","rc":[{"batb":[[0,1.6,59.88],[1,1.43,92.29],[2,1.01,0.51]],"ltp":0.0,"tv":0.0,"id":2996932},{"batb":[[1,2.02,54.68],[2,1.01,0.51]],"ltp":0.0,"tv":0.0,"id":2996931}]}]}
{"op":"mcm","clk":"1009768924","pt":1580669238637,"mc":[{"id":"1.168230759","rc":[{"batb":[[0,1.43,92.29],[1,1.01,0.51],[2,1.01,0]],"ltp":0.0,"tv":0.0,"id":2996932},{"batb":[[0,2.02,54.68],[1,1.01,0.51],[2,1.01,0]],"ltp":0.0,"tv":0.0,"id":2996931}]}]}
{"op":"mcm","clk":"1009770618","pt":1580669259342,"mc":[{"id":"1.168230759","rc":[{"batb":[[0,1.84,37.22],[1,1.66,52.56],[2,1.01,0.51]],"ltp":0.0,"tv":0.0,"id":2996932},{"batb":[[1,1.87,35.49],[2,1.01,0.51]],"ltp":0.0,"tv":0.0,"id":2996931}]}]}
{"op":"mcm","clk":"1009771358","pt":1580669267363,"mc":[{"id":"1.168230759","rc":[{"batb":[[0,1.85,36.51],[1,1.67,51.54]],"ltp":0.0,"tv":0.0,"id":2996932},{"batb":[[1,1.85,36.19]],"ltp":0.0,"tv":0.0,"id":2996931}]}]}
{"op":"mcm","clk":"1009773234","pt":1580669287465,"mc":[{"id":"1.168230759","rc":[{"batb":[[1,2,56.02],[2,1.85,36.19]],"ltp":0.0,"tv":0.0,"id":2996931}]}]}
{"op":"mcm","clk":"1009773341","pt":1580669288465,"mc":[{"id":"1.168230759","rc":[{"batb":[[0,1.85,36.35],[1,1.67,51.38]],"ltp":0.0,"tv":0.0,"id":2996932},{"batb":[[0,2,56.02],[1,1.85,36.19],[2,1.01,0.51]],"ltp":0.0,"tv":0.0,"id":2996931}]}]}
{"op":"mcm","clk":"1009778191","pt":1580669340305,"mc":[{"id":"1.168230759","rc":[{"batb":[[0,1.67,51.38],[1,1.01,0.51],[2,1.01,0]],"ltp":0.0,"tv":0.0,"id":2996932},{"batb":[[0,1.85,36.19],[1,1.01,0.51],[2,1.01,0]],"ltp":0.0,"tv":0.0,"id":2996931}]}]}
{"op":"mcm","clk":"1009779356","pt":1580669351474,"mc":[{"id":"1.168230759","rc":[{"batb":[[0,2,56.18],[1,1.83,37.92],[2,1.01,0.51]],"ltp":0.0,"tv":0.0,"id":2996932},{"batb":[[1,1.71,47.45],[2,1.01,0.51]],"ltp":0.0,"tv":0.0,"id":2996931}]}]}
{"op":"mcm","clk":"1009780293","pt":1580669360594,"mc":[{"id":"1.168230759","rc":[{"batb":[[0,1.83,37.92],[1,1.01,0.51],[2,1.01,0]],"ltp":0.0,"tv":0.0,"id":2996932},{"batb":[[0,1.71,47.45],[1,1.01,0.51],[2,1.01,0]],"ltp":0.0,"tv":0.0,"id":2996931}]}]}
{"op":"mcm","clk":"1009783307","pt":1580669391639,"mc":[{"id":"1.168230759","rc":[{"batb":[[1,1.62,56.73],[2,1.01,0.51]],"ltp":0.0,"tv":0.0,"id":2996932},{"batb":[[0,2.04,53.58],[1,1.84,36.82],[2,1.71,47.45]],"ltp":0.0,"tv":0.0,"id":2996931}]}]}
{"op":"mcm","clk":"1009783347","pt":1580669392057,"mc":[{"id":"1.168230759","rc":[{"batb":[[2,1.01,0.51]],"ltp":0.0,"tv":0.0,"id":2996931}]}]}
{"op":"mcm","clk":"1009784204","pt":1580669401541,"mc":[{"id":"1.168230759","rc":[{"batb":[[0,1.62,56.73],[1,1.01,0.51],[2,1.01,0]],"ltp":0.0,"tv":0.0,"id":2996932},{"batb":[[0,1.84,36.82],[1,1.01,0.51],[2,1.01,0]],"ltp":0.0,"tv":0.0,"id":2996931}]}]}
{"op":"mcm","clk":"1009785047","pt":1580669410452,"mc":[{"id":"1.168230759","rc":[{"batb":[[0,2.02,55.23],[1,1.8,39.5],[2,1.01,0.51]],"ltp":0.0,"tv":0.0,"id":2996932},{"batb":[[1,1.69,49.49],[2,1.01,0.51]],"ltp":0.0,"tv":0.0,"id":2996931}]}]}
{"op":"mcm","clk":"1009785872","pt":1580669418483,"mc":[{"id":"1.168230759","rc":[{"batb":[[0,1.8,39.5],[1,1.01,0.51],[2,1.01,0]],"ltp":0.0,"tv":0.0,"id":2996932},{"batb":[[0,1.69,49.33],[1,1.01,0.51],[2,1.01,0]],"ltp":0.0,"tv":0.0,"id":2996931}]}]}
{"op":"mcm","clk":"1009788379","pt":1580669442292,"mc":[{"id":"1.168230759","rc":[{"batb":[[0,2.24,40.44],[1,2.04,52.8],[2,1.01,0.51]],"ltp":0.0,"tv":0.0,"id":2996932},{"batb":[[1,1.61,58.93],[2,1.01,0.51]],"ltp":0.0,"tv":0.0,"id":2996931}]}]}
{"op":"mcm","clk":"1009789297","pt":1580669452114,"mc":[{"id":"1.168230759","rc":[{"batb":[[0,2.04,52.8],[1,1.01,0.51],[2,1.01,0]],"ltp":0.0,"tv":0.0,"id":2996932},{"batb":[[0,1.61,58.93],[1,1.01,0.51],[2,1.01,0]],"ltp":0.0,"tv":0.0,"id":2996931}]}]}
{"op":"mcm","clk":"1009790914","pt":1580669468540,"mc":[{"id":"1.168230759","rc":[{"batb":[[1,1.78,40.91],[2,1.01,0.51]],"ltp":0.0,"tv":0.0,"id":2996932},{"batb":[[0,1.82,38.55],[1,1.64,54.05],[2,1.01,0.51]],"ltp":0.0,"tv":0.0,"id":2996931}]}]}
{"op":"mcm","clk":"1009791591","pt":1580669475623,"mc":[{"id":"1.168230759","rc":[{"batb":[[0,1.78,40.91],[1,1.01,0.51],[2,1.01,0]],"ltp":0.0,"tv":0.0,"id":2996932},{"batb":[[0,1.64,54.05],[1,1.01,0.51],[2,1.01,0]],"ltp":0.0,"tv":0.0,"id":2996931}]}]}
{"op":"mcm","clk":"1009791910","pt":1580669479221,"mc":[{"id":"1.168230759","rc":[{"batb":[[0,1.8,39.89]],"ltp":0.0,"tv":0.0,"id":2996932},{"batb":[[0,1.63,55.31]],"ltp":0.0,"tv":0.0,"id":2996931}]}]}
{"op":"mcm","clk":"1009793105","pt":1580669492541,"mc":[{"id":"1.168230759","rc":[{"batb":[[1,1.56,65.46],[2,1.01,0.51]],"ltp":0.0,"tv":0.0,"id":2996932},{"batb":[[0,2.08,50.83],[1,1.82,38.63],[2,1.01,0.51]],"ltp":0.0,"tv":0.0,"id":2996931}]}]}
{"op":"mcm","clk":"1009793975","pt":1580669502339,"mc":[{"id":"1.168230759","rc":[{"batb":[[0,1.56,65.46],[1,1.01,0.51],[2,1.01,0]],"ltp":0.0,"tv":0.0,"id":2996932},{"batb":[[0,1.82,38.63],[1,1.01,0.51],[2,1.01,0]],"ltp":0.0,"tv":0.0,"id":2996931}]}]}
{"op":"mcm","clk":"1009796144","pt":1580669526559,"mc":[{"id":"1.168230759","rc":[{"batb":[[1,1.35,118.34],[2,1.01,0.51]],"ltp":0.0,"tv":0.0,"id":2996932},{"batb":[[0,2.52,29.19],[1,2.08,50.44],[2,1.01,0.51]],"ltp":0.0,"tv":0.0,"id":2996931}]}]}
{"op":"mcm","clk":"1009796985","pt":1580669535586,"mc":[{"id":"1.168230759","rc":[{"batb":[[0,1.35,118.34],[1,1.01,0.51],[2,1.01,0]],"ltp":0.0,"tv":0.0,"id":2996932},{"batb":[[0,2.08,50.2],[1,1.01,0.51],[2,1.01,0]],"ltp":0.0,"tv":0.0,"id":2996931}]}]}
{"op":"mcm","clk":"1009798385","pt":1580669551391,"mc":[{"id":"1.168230759","rc":[{"batb":[[0,1.79,40.44],[1,1.55,66.72],[2,1.01,0.51]],"ltp":0.0,"tv":0.0,"id":2996932},{"batb":[[1,1.83,37.92],[2,1.01,0.51]],"ltp":0.0,"tv":0.0,"id":2996931}]}]}
{"op":"mcm","clk":"1009799472","pt":1580669563306,"mc":[{"id":"1.168230759","rc":[{"batb":[[0,1.55,66.72],[1,1.01,0.51],[2,1.01,0]],"ltp":0.0,"tv":0.0,"id":2996932},{"batb":[[0,1.83,37.92],[1,1.01,0.51],[2,1.01,0]],"ltp":0.0,"tv":0.0,"id":2996931}]}]}
{"op":"mcm","clk":"1009799696","pt":1580669565605,"mc":[{"id":"1.168230759","rc":[{"batb":[[0,1.56,65.15],[1,1.55,66.72],[2,1.01,0.51]],"ltp":0.0,"tv":0.0,"id":2996932},{"batb":[[1,1.81,38.87],[2,1.01,0.51]],"ltp":0.0,"tv":0.0,"id":2996931}]}]}
{"op":"mcm","clk":"1009799767","pt":1580669566532,"mc":[{"id":"1.168230759","rc":[{"batb":[[1,1.01,0.51],[2,1.01,0]],"ltp":0.0,"tv":0.0,"id":2996932},{"batb":[[0,1.81,38.87],[1,1.01,0.51],[2,1.01,0]],"ltp":0.0,"tv":0.0,"id":2996931}]}]}
{"op":"mcm","clk":"1009800755","pt":1580669578614,"mc":[{"id":"1.168230759","rc":[{"batb":[[0,2.06,52.32],[1,1.79,40.44],[2,1.01,0.51]],"ltp":0.0,"tv":0.0,"id":2996932},{"batb":[[1,1.64,54.84],[2,1.01,0.51]],"ltp":0.0,"tv":0.0,"id":2996931}]}]}
{"op":"mcm","clk":"1009801774","pt":1580669589727,"mc":[{"id":"1.168230759","rc":[{"batb":[[0,1.79,40.44],[1,1.01,0.51],[2,1.01,0]],"ltp":0.0,"tv":0.0,"id":2996932},{"batb":[[0,1.64,54.84],[1,1.01,0.51],[2,1.01,0]],"ltp":0.0,"tv":0.0,"id":2996931}]}]}
{"op":"mcm","clk":"1009803264","pt":1580669606272,"mc":[{"id":"1.168230759","rc":[{"batb":[[1,1.56,66.17],[2,1.01,0.51]],"ltp":0.0,"tv":0.0,"id":2996932},{"batb":[[0,2.08,50.28],[1,1.82,38.24],[2,1.01,0.51]],"ltp":0.0,"tv":0.0,"id":2996931}]}]}
{"op":"mcm","clk":"1009804271","pt":1580669617564,"mc":[{"id":"1.168230759","rc":[{"batb":[[0,1.56,66.17],[1,1.01,0.51],[2,1.01,0]],"ltp":0.0,"tv":0.0,"id":2996932},{"batb":[[0,1.82,38.24],[1,1.01,0.51],[2,1.01,0]],"ltp":0.0,"tv":0.0,"id":2996931}]}]}
{"op":"mcm","clk":"1009806108","pt":1580669636482,"mc":[{"id":"1.168230759","rc":[{"batb":[[1,1.35,118.65],[2,1.01,0.51]],"ltp":0.0,"tv":0.0,"id":2996932},{"batb":[[0,2.54,28.95],[1,2.1,49.1],[2,1.01,0.51]],"ltp":0.0,"tv":0.0,"id":2996931}]}]}
{"op":"mcm","clk":"1009807415","pt":1580669649616,"mc":[{"id":"1.168230759","rc":[{"batb":[[0,1.35,118.65],[1,1.01,0.51],[2,1.01,0]],"ltp":0.0,"tv":0.0,"id":2996932},{"batb":[[0,2.1,49.1],[1,1.01,0.51],[2,1.01,0]],"ltp":0.0,"tv":0.0,"id":2996931}]}]}
{"op":"mcm","clk":"1009809380","pt":1580669670522,"mc":[{"id":"1.168230759","rc":[{"batb":[[1,1.27,162.48],[2,1.01,0.51]],"ltp":0.0,"tv":0.0,"id":2996932},{"batb":[[0,3.35,35.09],[1,2.86,21.09],[2,1.01,0.51]],"ltp":0.0,"tv":0.0,"id":2996931}]}]}
{"op":"mcm","clk":"1009812683","pt":1580669704164,"mc":[{"id":"1.168230759","rc":[{"batb":[[0,1.27,162.48],[1,1.01,0.51],[2,1.01,0]],"ltp":0.0,"tv":0.0,"id":2996932},{"batb":[[0,2.86,21.09],[1,1.01,0.51],[2,1.01,0]],"ltp":0.0,"tv":0.0,"id":2996931}]}]}
{"op":"mcm","clk":"1009813002","pt":1580669707483,"mc":[{"id":"1.168230759","rc":[{"batb":[[0,2.88,52.17]],"ltp":0.0,"tv":0.0,"id":2996931}]}]}
{"op":"mcm","clk":"1009813895","pt":1580669716573,"mc":[{"id":"1.168230759","rc":[{"batb":[[1,1.2,226.92],[2,1.01,0.51]],"ltp":0.0,"tv":0.0,"id":2996932},{"batb":[[0,4,45.64],[1,3.35,35.01],[2,1.01,0.51]],"ltp":0.0,"tv":0.0,"id":2996931}]}]}
{"op":"mcm","clk":"1009815273","pt":1580669731477,"mc":[{"id":"1.168230759","rc":[{"batb":[[0,1.2,224.48],[1,1.01,0.51],[2,1.01,0]],"ltp":0.0,"tv":0.0,"id":2996932},{"batb":[[0,3.35,35.01],[1,1.01,0.51],[2,1.01,0]],"ltp":0.0,"tv":0.0,"id":2996931}]}]}
{"op":"mcm","clk":"1009816471","pt":1580669745586,"mc":[{"id":"1.168230759","rc":[{"batb":[[0,1.36,117.55],[1,1.26,169.4],[2,1.2,224.48]],"ltp":0.0,"tv":0.0,"id":2996932},{"batb":[[1,2.78,22.5],[2,1.01,0.51]],"ltp":0.0,"tv":0.0,"id":2996931}]}]}
{"op":"mcm","clk":"1009816494","pt":1580669745898,"mc":[{"id":"1.168230759","rc":[{"batb":[[2,1.01,0.51]],"ltp":0.0,"tv":0.0,"id":2996932}]}]}
{"op":"mcm","clk":"1009817744","pt":1580669760595,"mc":[{"id":"1.168230759","rc":[{"batb":[[0,1.26,169.4],[1,1.01,0.51],[2,1.01,0]],"ltp":0.0,"tv":0.0,"id":2996932},{"batb":[[0,2.78,22.5],[1,1.01,0.51],[2,1.01,0]],"ltp":0.0,"tv":0.0,"id":2996931}]}]}
{"op":"mcm","clk":"1009818623","pt":1580669771328,"mc":[{"id":"1.168230759","rc":[{"batb":[[1,1.18,251],[2,1.01,0.51]],"ltp":0.0,"tv":0.0,"id":2996932},{"batb":[[0,4,43.43],[1,3.3,36.19],[2,1.01,0.51]],"ltp":0.0,"tv":0.0,"id":2996931}]}]}
{"op":"mcm","clk":"1009819712","pt":1580669785564,"mc":[{"id":"1.168230759","rc":[{"batb":[[0,1.18,251],[1,1.01,0.51],[2,1.01,0]],"ltp":0.0,"tv":0.0,"id":2996932},{"batb":[[0,3.3,36.04],[1,1.01,0.51],[2,1.01,0]],"ltp":0.0,"tv":0.0,"id":2996931}]}]}
{"op":"mcm","clk":"1009820483","pt":1580669794561,"mc":[{"id":"1.168230759","rc":[{"batb":[[1,1.14,339.12],[2,1.01,0.51]],"ltp":0.0,"tv":0.0,"id":2996932},{"batb":[[0,5.2,24.08],[1,4.3,37.77],[2,1.01,0.51]],"ltp":0.0,"tv":0.0,"id":2996931}]}]}
{"op":"mcm","clk":"1009821793","pt":1580669809591,"mc":[{"id":"1.168230759","rc":[{"batb":[[0,1.14,338.88],[1,1.01,0.51],[2,1.01,0]],"ltp":0.0,"tv":0.0,"id":2996932},{"batb":[[0,4.3,37.77],[1,1.01,0.51],[2,1.01,0]],"ltp":0.0,"tv":0.0,"id":2996931}]}]}
{"op":"mcm","clk":"1009824285","pt":1580669835575,"mc":[{"id":"1.168230759","rc":[{"batb":[[0,1.24,186.16],[1,1.15,312.37],[2,1.01,0.51]],"ltp":0.0,"tv":0.0,"id":2996932},{"batb":[[1,3.3,36.27],[2,1.01,0.51]],"ltp":0.0,"tv":0.0,"id":2996931}]}]}
{"op":"mcm","clk":"1009825657","pt":1580669850499,"mc":[{"id":"1.168230759","rc":[{"batb":[[0,1.15,312.37],[1,1.01,0.51],[2,1.01,0]],"ltp":0.0,"tv":0.0,"id":2996932},{"batb":[[0,3.3,36.27],[1,1.01,0.51],[2,1.01,0]],"ltp":0.0,"tv":0.0,"id":2996931}]}]}
{"op":"mcm","clk":"1009826855","pt":1580669864634,"mc":[{"id":"1.168230759","rc":[{"batb":[[1,1.11,448.57],[2,1.01,0.51]],"ltp":0.0,"tv":0.0,"id":2996932},{"batb":[[0,6,34.93],[1,5.1,25.26],[2,1.01,0.51]],"ltp":0.0,"tv":0.0,"id":2996931}]}]}
{"op":"mcm","clk":"1009829065","pt":1580669890565,"mc":[{"id":"1.168230759","rc":[{"batb":[[2,1.1,449.9]],"ltp":0.0,"tv":0.0,"id":2996932}]}]}
{"op":"mcm","clk":"1009829139","pt":1580669891553,"mc":[{"id":"1.168230759","rc":[{"batb":[[1,1.1,449.9],[2,1.01,0.51]],"ltp":0.0,"tv":0.0,"id":2996932},{"batb":[[0,6,34.78]],"ltp":0.0,"tv":0.0,"id":2996931}]}]}
{"op":"mcm","clk":"1009829562","pt":1580669895572,"mc":[{"id":"1.168230759","rc":[{"batb":[[0,6,34.31],[1,5.1,24.86]],"ltp":0.0,"tv":0.0,"id":2996931}]}]}
{"op":"mcm","clk":"1009833269","pt":1580669939510,"mc":[{"id":"1.168230759","rc":[{"batb":[[0,1.1,449.9],[1,1.01,0.51],[2,1.01,0]],"ltp":0.0,"tv":0.0,"id":2996932},{"batb":[[0,5.1,24.86],[1,1.01,0.51],[2,1.01,0]],"ltp":0.0,"tv":0.0,"id":2996931}]}]}
{"op":"mcm","clk":"1009833560","pt":1580669942350,"mc":[{"id":"1.168230759","rc":[{"batb":[[0,5.2,24.55]],"ltp":0.0,"tv":0.0,"id":2996931}]}]}
{"op":"mcm","clk":"1009834950","pt":1580669956644,"mc":[{"id":"1.168230759","rc":[{"batb":[[0,1.19,248.48],[1,1.14,327.16],[2,1.01,0.51]],"ltp":0.0,"tv":0.0,"id":2996932},{"batb":[[1,4.5,34.62],[2,1.01,0.51]],"ltp":0.0,"tv":0.0,"id":2996931}]}]}
{"op":"mcm","clk":"1009835513","pt":1580669962569,"mc":[{"id":"1.168230759","rc":[{"batb":[[0,1.14,327.16],[1,1.01,0.51],[2,1.01,0]],"ltp":0.0,"tv":0.0,"id":2996932},{"batb":[[0,4.5,34.62],[1,1.01,0.51],[2,1.01,0]],"ltp":0.0,"tv":0.0,"id":2996931}]}]}
{"op":"mcm","clk":"1009837939","pt":1580669986368,"mc":[{"id":"1.168230759","rc":[{"batb":[[0,1.23,197.73],[1,1.19,243.99],[2,1.01,0.51]],"ltp":0.0,"tv":0.0,"id":2996932},{"batb":[[1,4,43.9],[2,1.01,0.51]],"ltp":0.0,"tv":0.0,"id":2996931}]}]}
{"op":"mcm","clk":"1009839019","pt":1580669996617,"mc":[{"id":"1.168230759","rc":[{"batb":[[0,1.19,243.99],[1,1.01,0.51],[2,1.01,0]],"ltp":0.0,"tv":0.0,"id":2996932},{"batb":[[0,4,43.51],[1,1.01,0.51],[2,1.01,0]],"ltp":0.0,"tv":0.0,"id":2996931}]}]}
{"op":"mcm","clk":"1009841264","pt":1580670016413,"mc":[{"id":"1.168230759","rc":[{"batb":[[0,1.26,169.24],[1,1.24,191.91],[2,1.01,0.51]],"ltp":0.0,"tv":0.0,"id":2996932},{"batb":[[1,3.85,50.36],[2,1.01,0.51]],"ltp":0.0,"tv":0.0,"id":2996931}]}]}
{"op":"mcm","clk":"1009842427","pt":1580670027547,"mc":[{"id":"1.168230759","rc":[{"batb":[[0,1.24,191.91],[1,1.01,0.51],[2,1.01,0]],"ltp":0.0,"tv":0.0,"id":2996932},{"batb":[[0,3.85,50.36],[1,1.01,0.51],[2,1.01,0]],"ltp":0.0,"tv":0.0,"id":2996931}]}]}
{"op":"mcm","clk":"1009844233","pt":1580670044647,"mc":[{"id":"1.168230759","rc":[{"batb":[[1,1.2,236.52],[2,1.01,0.51]],"ltp":0.0,"tv":0.0,"id":2996932},{"batb":[[0,4.4,36.19],[1,4,45.32],[2,1.01,0.51]],"ltp":0.0,"tv":0.0,"id":2996931}]}]}
{"op":"mcm","clk":"1009845261","pt":1580670054451,"mc":[{"id":"1.168230759","rc":[{"batb":[[0,1.2,234.71],[1,1.01,0.51],[2,1.01,0]],"ltp":0.0,"tv":0.0,"id":2996932},{"batb":[[0,4,45.32],[1,1.01,0.51],[2,1.01,0]],"ltp":0.0,"tv":0.0,"id":2996931}]}]}
{"op":"mcm","clk":"1009847909","pt":1580670077297,"mc":[{"id":"1.168230759","rc":[{"batb":[[0,1.27,163.19],[1,1.19,237.38],[2,1.01,0.51]],"ltp":0.0,"tv":0.0,"id":2996932},{"batb":[[1,3.25,38.24],[2,1.01,0.51]],"ltp":0.0,"tv":0.0,"id":2996931}]}]}
{"op":"mcm","clk":"1009851507","pt":1580670106526,"mc":[{"id":"1.168230759","rc":[{"batb":[[0,1.19,237.38],[1,1.01,0.51],[2,1.01,0]],"ltp":0.0,"tv":0.0,"id":2996932},{"batb":[[0,3.25,38.24],[1,1.01,0.51],[2,1.01,0]],"ltp":0.0,"tv":0.0,"id":2996931}]}]}
{"op":"mcm","clk":"1009852833","pt":1580670116642,"mc":[{"id":"1.168230759","rc":[{"batb":[[0,1.37,111.26],[1,1.27,161.06],[2,1.01,0.51]],"ltp":0.0,"tv":0.0,"id":2996932},{"batb":[[1,2.72,24],[2,1.01,0.51]],"ltp":0.0,"tv":0.0,"id":2996931}]}]}
{"op":"mcm","clk":"1009854093","pt":1580670126632,"mc":[{"id":"1.168230759","rc":[{"batb":[[0,1.27,161.06],[1,1.01,0.51],[2,1.01,0]],"ltp":0.0,"tv":0.0,"id":2996932},{"batb":[[0,2.72,24],[1,1.01,0.51],[2,1.01,0]],"ltp":0.0,"tv":0.0,"id":2996931}]}]}
{"op":"mcm","clk":"1009858561","pt":1580670165487,"mc":[{"id":"1.168230759","rc":[{"batb":[[0,1.49,77.5],[1,1.39,103.7],[2,1.01,0.51]],"ltp":0.0,"tv":0.0,"id":2996932},{"batb":[[1,2.38,34.62],[2,1.01,0.51]],"ltp":0.0,"tv":0.0,"id":2996931}]}]}
{"op":"mcm","clk":"1009860086","pt":1580670178591,"mc":[{"id":"1.168230759","rc":[{"batb":[[0,1.39,103.7],[1,1.01,0.51],[2,1.01,0]],"ltp":0.0,"tv":0.0,"id":2996932},{"batb":[[0,2.38,34.46],[1,1.01,0.51],[2,1.01,0]],"ltp":0.0,"tv":0.0,"id":2996931}]}]}
{"op":"mcm","clk":"1009862593","pt":1580670199302,"mc":[{"id":"1.168230759","rc":[{"batb":[[0,1.62,56.89],[1,1.54,68.37],[2,1.01,0.51]],"ltp":0.0,"tv":0.0,"id":2996932},{"batb":[[1,2.2,43.2],[2,1.01,0.51]],"ltp":0.0,"tv":0.0,"id":2996931}]}]}
{"op":"mcm","clk":"1009863998","pt":1580670211620,"mc":[{"id":"1.168230759","rc":[{"batb":[[0,1.54,68.37],[1,1.01,0.51],[2,1.01,0]],"ltp":0.0,"tv":0.0,"id":2996932},{"batb":[[0,2.2,43.2],[1,1.01,0.51],[2,1.01,0]],"ltp":0.0,"tv":0.0,"id":2996931}]}]}
{"op":"mcm","clk":"1009866448","pt":1580670232142,"mc":[{"id":"1.168230759","rc":[{"batb":[[0,1.72,46.5],[1,1.51,74.12],[2,1.01,0.51]],"ltp":0.0,"tv":0.0,"id":2996932},{"batb":[[1,1.93,31.71],[2,1.01,0.51]],"ltp":0.0,"tv":0.0,"id":2996931}]}]}
{"op":"mcm","clk":"1009866972","pt":1580670236540,"mc":[{"id":"1.168230759","rc":[{"batb":[[0,1.51,73.65],[1,1.01,0.51],[2,1.01,0]],"ltp":0.0,"tv":0.0,"id":2996932},{"batb":[[0,1.93,31.71],[1,1.01,0.51],[2,1.01,0]],"ltp":0.0,"tv":0.0,"id":2996931}]}]}
{"op":"mcm","clk":"1009869133","pt":1580670255560,"mc":[{"id":"1.168230759","rc":[{"batb":[[0,1.72,46.26],[1,1.51,73.65],[2,1.01,0.51]],"ltp":0.0,"tv":0.0,"id":2996932},{"batb":[[0,2.2,43.35],[1,1.93,31.71],[2,1.01,0.51]],"ltp":0.0,"tv":0.0,"id":2996931}]}]}
{"op":"mcm","clk":"1009869752","pt":1580670260582,"mc":[{"id":"1.168230759","rc":[{"batb":[[1,1.94,63.18],[2,1.93,31.71]],"ltp":0.0,"tv":0.0,"id":2996931}]}]}
{"op":"mcm","clk":"1009869850","pt":1580670261375,"mc":[{"id":"1.168230759","rc":[{"batb":[[0,2.2,42.96],[2,1.01,0.51]],"ltp":0.0,"tv":0.0,"id":2996931}]}]}
{"op":"mcm","clk":"1009870311","pt":1580670265582,"mc":[{"id":"1.168230759","rc":[{"batb":[[1,1.71,46.89],[2,1.51,73.65]],"ltp":0.0,"tv":0.0,"id":2996932}]}]}
{"op":"mcm","clk":"1009870426","pt":1580670266578,"mc":[{"id":"1.168230759","rc":[{"batb":[[0,1.71,46.89],[1,1.51,73.65],[2,1.01,0.51]],"ltp":0.0,"tv":0.0,"id":2996932},{"batb":[[0,2.2,42.8],[1,1.94,62.95]],"ltp":0.0,"tv":0.0,"id":2996931}]}]}
{"op":"mcm","clk":"1009870854","pt":1580670270648,"mc":[{"id":"1.168230759","rc":[{"batb":[[2,1.5,75.53]],"ltp":0.0,"tv":0.0,"id":2996932},{"batb":[[0,2.22,42.17],[1,2.2,42.8],[2,1.95,62.16]],"ltp":0.0,"tv":0.0,"id":2996931}]}]}
{"op":"mcm","clk":"1009870980","pt":1580670271594,"mc":[{"id":"1.168230759","rc":[{"batb":[[1,1.5,75.53],[2,1.01,0.51]],"ltp":0.0,"tv":0.0,"id":2996932},{"batb":[[1,1.95,62.16],[2,1.01,0.51]],"ltp":0.0,"tv":0.0,"id":2996931}]}]}
{"op":"mcm","clk":"1009873865","pt":1580670297998,"mc":[{"id":"1.168230759","rc":[{"batb":[[0,1.5,75.53],[1,1.01,0.51],[2,1.01,0]],"ltp":0.0,"tv":0.0,"id":2996932},{"batb":[[0,1.95,62.16],[1,1.01,0.51],[2,1.01,0]],"ltp":0.0,"tv":0.0,"id":2996931}]}]}
{"op":"mcm","clk":"1009875943","pt":1580670314610,"mc":[{"id":"1.168230759","rc":[{"batb":[[0,1.01,0.51],[1,1.01,0]],"ltp":0.0,"tv":0.0,"id":2996932},{"batb":[[0,1.01,0.51],[1,1.01,0]],"ltp":0.0,"tv":0.0,"id":2996931}]}]}
{"op":"mcm","clk":"1009877799","pt":1580670330220,"mc":[{"id":"1.168230759","rc":[{"batb":[[0,1.5,75.53],[1,1.33,126.52],[2,1.01,0.51]],"ltp":0.0,"tv":0.0,"id":2996932},{"batb":[[0,2.7,24.71],[1,2.26,40.13],[2,1.01,0.51]],"ltp":0.0,"tv":0.0,"id":2996931}]}]}
{"op":"mcm","clk":"1009878655","pt":1580670337638,"mc":[{"id":"1.168230759","rc":[{"batb":[[0,1.33,126.52],[1,1.01,0.51],[2,1.01,0]],"ltp":0.0,"tv":0.0,"id":2996932},{"batb":[[0,2.26,40.13],[1,1.01,0.51],[2,1.01,0]],"ltp":0.0,"tv":0.0,"id":2996931}]}]}
{"op":"mcm","clk":"1009881065","pt":1580670358500,"mc":[{"id":"1.168230759","rc":[{"batb":[[1,1.22,211.18],[2,1.01,0.51]],"ltp":0.0,"tv":0.0,"id":2996932},{"batb":[[0,3.45,32.18],[1,2.84,21.56],[2,1.01,0.51]],"ltp":0.0,"tv":0.0,"id":2996931}]}]}
{"op":"mcm","clk":"1009882516","pt":1580670370587,"mc":[{"id":"1.168230759","rc":[{"batb":[[0,1.22,211.18],[1,1.01,0.51],[2,1.01,0]],"ltp":0.0,"tv":0.0,"id":2996932},{"batb":[[0,2.84,21.56],[1,1.01,0.51],[2,1.01,0]],"ltp":0.0,"tv":0.0,"id":2996931}]}]}
{"op":"mcm","clk":"1009884167","pt":1580670383631,"mc":[{"id":"1.168230759","rc":[{"batb":[[0,1.46,84.27],[1,1.28,160.12],[2,1.01,0.51]],"ltp":0.0,"tv":0.0,"id":2996932},{"batb":[[1,2.28,38.87],[2,1.01,0.51]],"ltp":0.0,"tv":0.0,"id":2996931}]}]}
{"op":"mcm","clk":"1009885329","pt":1580670393207,"mc":[{"id":"1.168230759","rc":[{"batb":[[0,1.28,160.12],[1,1.01,0.51],[2,1.01,0]],"ltp":0.0,"tv":0.0,"id":2996932},{"batb":[[0,2.28,38.87],[1,1.01,0.51],[2,1.01,0]],"ltp":0.0,"tv":0.0,"id":2996931}]}]}
{"op":"mcm","clk":"1009888954","pt":1580670422642,"mc":[{"id":"1.168230759","rc":[{"batb":[[1,1.16,283.96],[2,1.01,0.51]],"ltp":0.0,"tv":0.0,"id":2996932},{"batb":[[0,3.95,47.13],[1,3.1,42.25],[2,1.01,0.51]],"ltp":0.0,"tv":0.0,"id":2996931}]}]}
{"op":"mcm","clk":"1009890849","pt":1580670438410,"mc":[{"id":"1.168230759","rc":[{"batb":[[0,1.16,283.96],[1,1.01,0.51],[2,1.01,0]],"ltp":0.0,"tv":0.0,"id":2996932},{"batb":[[0,3.1,42.25],[1,1.01,0.51],[2,1.01,0]],"ltp":0.0,"tv":0.0,"id":2996931}]}]}
{"op":"mcm","clk":"1009892082","pt":1580670447575,"mc":[{"id":"1.168230759","rc":[{"batb":[[0,1.39,103.39],[1,1.17,269.88],[2,1.16,283.96]],"ltp":0.0,"tv":0.0,"id":2996932},{"batb":[[1,2.3,38.16],[2,1.01,0.51]],"ltp":0.0,"tv":0.0,"id":2996931}]}]}
{"op":"mcm","clk":"1009892109","pt":1580670447789,"mc":[{"id":"1.168230759","rc":[{"batb":[[2,1.01,0.51]],"ltp":0.0,"tv":0.0,"id":2996932}]}]}
{"op":"mcm","clk":"1009893467","pt":1580670458518,"mc":[{"id":"1.168230759","rc":[{"batb":[[0,1.17,269.88],[1,1.01,0.51],[2,1.01,0]],"ltp":0.0,"tv":0.0,"id":2996932},{"batb":[[0,2.3,38.16],[1,1.01,0.51],[2,1.01,0]],"ltp":0.0,"tv":0.0,"id":2996931}]}]}
{"op":"mcm","clk":"1009896760","pt":1580670484322,"mc":[{"id":"1.168230759","rc":[{"batb":[[1,1.1,470.75],[2,1.01,0.51]],"ltp":0.0,"tv":0.0,"id":2996932},{"batb":[[0,5.4,21.64],[1,4.1,42.17],[2,1.01,0.51]],"ltp":0.0,"tv":0.0,"id":2996931}]}]}
{"op":"mcm","clk":"1009900573","pt":1580670514436,"mc":[{"id":"1.168230759","rc":[{"batb":[[0,1.1,470.75],[1,1.01,0.51],[2,1.01,0]],"ltp":0.0,"tv":0.0,"id":2996932},{"batb":[[0,4.1,42.17],[1,1.01,0.51],[2,1.01,0]],"ltp":0.0,"tv":0.0,"id":2996931}]}]}
{"op":"mcm","clk":"1009900942","pt":1580670517552,"mc":[{"id":"1.168230759","rc":[{"batb":[[1,1.09,498.21],[2,1.01,0.51]],"ltp":0.0,"tv":0.0,"id":2996932},{"batb":[[0,4.3,38.63],[1,4.1,42.17],[2,1.01,0.51]],"ltp":0.0,"tv":0.0,"id":2996931}]}]}
{"op":"mcm","clk":"1009901078","pt":1580670518358,"mc":[{"id":"1.168230759","rc":[{"batb":[[0,1.09,498.21],[1,1.01,0.51],[2,1.01,0]],"ltp":0.0,"tv":0.0,"id":2996932},{"batb":[[1,1.01,0.51],[2,1.01,0]],"ltp":0.0,"tv":0.0,"id":2996931}]}]}
{"op":"mcm","clk":"1009904116","pt":1580670543482,"mc":[{"id":"1.168230759","rc":[{"batb":[[1,1.04,1114.14],[2,1.01,0.51]],"ltp":0.0,"tv":0.0,"id":2996932},{"batb":[[0,8.2,16.37],[1,5.7,39.66],[2,1.01,0.51]],"ltp":0.0,"tv":0.0,"id":2996931}]}]}
{"op":"mcm","clk":"1009906068","pt":1580670560435,"mc":[{"id":"1.168230759","rc":[{"batb":[[0,1.04,1114.14],[1,1.01,0.51],[2,1.01,0]],"ltp":0.0,"tv":0.0,"id":2996932},{"batb":[[0,5.7,39.66],[1,1.01,0.51],[2,1.01,0]],"ltp":0.0,"tv":0.0,"id":2996931}]}]}
{"op":"mcm","clk":"1009906476","pt":1580670563634,"mc":[{"id":"1.168230759","rc":[{"batb":[[0,1.04,1113.35]],"ltp":0.0,"tv":0.0,"id":2996932},{"batb":[[0,5.6,40.44]],"ltp":0.0,"tv":0.0,"id":2996931}]}]}
{"op":"mcm","clk":"1009909231","pt":1580670584570,"mc":[{"id":"1.168230759","rc":[{"batb":[[0,14.5,10.62],[1,8.8,14.16],[2,1.01,0.51]],"ltp":0.0,"tv":0.0,"id":2996931}]}]}
{"op":"mcm","clk":"1009910812","pt":1580670597191,"mc":[{"id":"1.168230759","rc":[{"batb":[[0,1.01,0.51],[1,1.01,0]],"ltp":0.0,"tv":0.0,"id":2996932},{"batb":[[0,8.8,14.16],[1,1.01,0.51],[2,1.01,0]],"ltp":0.0,"tv":0.0,"id":2996931}]}]}
{"op":"mcm","clk":"1009913343","pt":1580670618509,"mc":[{"id":"1.168230759","rc":[{"batb":[[0,1.08,550.77],[1,1.02,1827.15],[2,1.01,0.51]],"ltp":0.0,"tv":0.0,"id":2996932},{"batb":[[1,5.6,40.05],[2,1.01,0.51]],"ltp":0.0,"tv":0.0,"id":2996931}]}]}
{"op":"mcm","clk":"1009914968","pt":1580670632096,"mc":[{"id":"1.168230759","rc":[{"batb":[[0,1.02,1827.15],[1,1.01,0.51],[2,1.01,0]],"ltp":0.0,"tv":0.0,"id":2996932},{"batb":[[0,5.6,40.05],[1,1.01,0.51],[2,1.01,0]],"ltp":0.0,"tv":0.0,"id":2996931}]}]}
{"op":"mcm","clk":"1009916755","pt":1580670646523,"mc":[{"id":"1.168230759","rc":[{"batb":[[0,1.16,287.27],[1,1.06,740.4],[2,1.01,0.51]],"ltp":0.0,"tv":0.0,"id":2996932},{"batb":[[1,3.75,52.32],[2,1.01,0.51]],"ltp":0.0,"tv":0.0,"id":2996931}]}]}
{"op":"mcm","clk":"1009918797","pt":1580670662555,"mc":[{"id":"1.168230759","rc":[{"batb":[[0,1.06,740.4],[1,1.01,0.51],[2,1.01,0]],"ltp":0.0,"tv":0.0,"id":2996932},{"batb":[[0,3.75,52.32],[1,1.01,0.51],[2,1.01,0]],"ltp":0.0,"tv":0.0,"id":2996931}]}]}
{"op":"mcm","clk":"1009919348","pt":1580670666578,"mc":[{"id":"1.168230759","rc":[{"batb":[[0,3.85,49.25]],"ltp":0.0,"tv":0.0,"id":2996931}]}]}
{"op":"mcm","clk":"1009920211","pt":1580670672549,"mc":[{"id":"1.168230759","rc":[{"batb":[[0,11,20.14],[1,5.8,37.77],[2,1.01,0.51]],"ltp":0.0,"tv":0.0,"id":2996931}]}]}
{"op":"mcm","clk":"1009922316","pt":1580670687262,"mc":[{"id":"1.168230759","rc":[{"batb":[[0,1.01,0.51],[1,1.01,0]],"ltp":0.0,"tv":0.0,"id":2996932},{"batb":[[0,5.8,37.77],[1,1.01,0.51],[2,1.01,0]],"ltp":0.0,"tv":0.0,"id":2996931}]}]}
{"op":"mcm","clk":"1009925494","pt":1580670709111,"mc":[{"id":"1.168230759","rc":[{"batb":[[0,1.16,297.81],[1,1.06,778.71],[2,1.01,0.51]],"ltp":0.0,"tv":0.0,"id":2996932},{"batb":[[1,3.9,48.94],[2,1.01,0.51]],"ltp":0.0,"tv":0.0,"id":2996931}]}]}
{"op":"mcm","clk":"1009927911","pt":1580670726602,"mc":[{"id":"1.168230759","rc":[{"batb":[[0,1.06,778.71],[1,1.01,0.51],[2,1.01,0]],"ltp":0.0,"tv":0.0,"id":2996932},{"batb":[[0,3.9,48.94],[1,1.01,0.51],[2,1.01,0]],"ltp":0.0,"tv":0.0,"id":2996931}]}]}
{"op":"mcm","clk":"1009928351","pt":1580670729648,"mc":[{"id":"1.168230759","rc":[{"batb":[[0,1.06,770.69]],"ltp":0.0,"tv":0.0,"id":2996932},{"batb":[[0,3.85,49.73]],"ltp":0.0,"tv":0.0,"id":2996931}]}]}
{"op":"mcm","clk":"1009930026","pt":1580670741622,"mc":[{"id":"1.168230759","rc":[{"batb":[[0,11,20.06],[1,5.8,37.53],[2,1.01,0.51]],"ltp":0.0,"tv":0.0,"id":2996931}]}]}
{"op":"mcm","clk":"1009932388","pt":1580670758537,"mc":[{"id":"1.168230759","rc":[{"batb":[[0,1.01,0.51],[1,1.01,0]],"ltp":0.0,"tv":0.0,"id":2996932},{"batb":[[0,5.8,37.53],[1,1.01,0.51],[2,1.01,0]],"ltp":0.0,"tv":0.0,"id":2996931}]}]}
{"op":"mcm","clk":"1009935983","pt":1580670787571,"mc":[{"id":"1.168230759","rc":[{"batb":[[0,1.16,297.58],[1,1.06,769.75],[2,1.01,0.51]],"ltp":0.0,"tv":0.0,"id":2996932},{"batb":[[1,3.85,49.57],[2,1.01,0.51]],"ltp":0.0,"tv":0.0,"id":2996931}]}]}
{"op":"mcm","clk":"1009938334","pt":1580670805094,"mc":[{"id":"1.168230759","rc":[{"batb":[[0,1.06,769.75],[1,1.01,0.51],[2,1.01,0]],"ltp":0.0,"tv":0.0,"id":2996932},{"batb":[[0,3.85,49.57],[1,1.01,0.51],[2,1.01,0]],"ltp":0.0,"tv":0.0,"id":2996931}]}]}
{"op":"mcm","clk":"1009940855","pt":1580670825517,"mc":[{"id":"1.168230759","rc":[{"batb":[[0,11,20.06],[1,5.8,37.53],[2,1.01,0.51]],"ltp":0.0,"tv":0.0,"id":2996931}]}]}
{"op":"mcm","clk":"1009942644","pt":1580670839862,"mc":[{"id":"1.168230759","rc":[{"batb":[[0,1.01,0.51],[1,1.01,0]],"ltp":0.0,"tv":0.0,"id":2996932},{"batb":[[0,5.8,37.53],[1,1.01,0.51],[2,1.01,0]],"ltp":0.0,"tv":0.0,"id":2996931}]}]}
{"op":"mcm","clk":"1009945724","pt":1580670864082,"mc":[{"id":"1.168230759","rc":[{"batb":[[0,1.01,0.51],[1,1.01,0]],"ltp":0.0,"tv":0.0,"id":2996931}]}]}
{"op":"mcm","clk":"1009945907","pt":1580670865262,"mc":[{"id":"1.168230759","marketDefinition":{"bspMarket":false,"turnInPlayEnabled":true,"persistenceEnabled":true,"marketBaseRate":5.0,"eventId":"29681775","eventTypeId":"2","numberOfWinners":1,"bettingType":"ODDS","marketType":"NUMBER_OF_SETS","marketTime":"2020-02-02T18:01:00.000Z","suspendTime":"2020-02-02T18:01:00.000Z","bspReconciled":false,"complete":true,"inPlay":true,"crossMatching":true,"runnersVoidable":false,"numberOfActiveRunners":2,"betDelay":3,"status":"SUSPENDED","runners":[{"status":"ACTIVE","sortPriority":1,"id":2996931,"name":"Two Sets"},{"status":"ACTIVE","sortPriority":2,"id":2996932,"name":"Three Sets"}],"regulators":["MR_INT"],"discountAllowed":true,"timezone":"UTC","openDate":"2020-02-02T18:01:00.000Z","version":3150346720,"name":"Number of Sets","eventName":"Brengle v Voegele"}}]}
{"op":"mcm","clk":"1009950071","pt":1580670897570,"mc":[{"id":"1.168230759","marketDefinition":{"bspMarket":false,"turnInPlayEnabled":true,"persistenceEnabled":true,"marketBaseRate":5.0,"eventId":"29681775","eventTypeId":"2","numberOfWinners":1,"bettingType":"ODDS","marketType":"NUMBER_OF_SETS","marketTime":"2020-02-02T18:01:00.000Z","suspendTime":"2020-02-02T18:01:00.000Z","bspReconciled":false,"complete":true,"inPlay":true,"crossMatching":false,"runnersVoidable":false,"numberOfActiveRunners":0,"betDelay":3,"status":"CLOSED","settledTime":"2020-02-02T19:14:55.000Z","runners":[{"status":"LOSER","sortPriority":1,"id":2996931,"name":"Two Sets"},{"status":"WINNER","sortPriority":2,"id":2996932,"name":"Three Sets"}],"regulators":["MR_INT"],"discountAllowed":true,"timezone":"UTC","openDate":"2020-02-02T18:01:00.000Z","version":3150347709,"name":"Number of Sets","eventName":"Brengle v Voegele"}}]}
