{"op":"mcm","clk":"1001501051","pt":1580587070468,"mc":[{"id":"1.168230817","marketDefinition":{"bspMarket":false,"turnInPlayEnabled":true,"persistenceEnabled":true,"marketBaseRate":5.0,"eventId":"29681775","eventTypeId":"2","numberOfWinners":0,"bettingType":"ASIAN_HANDICAP_DOUBLE_LINE","marketType":"HANDICAP","marketTime":"2020-02-02T18:00:00.000Z","suspendTime":"2020-02-02T18:00:00.000Z","bspReconciled":false,"complete":true,"inPlay":false,"crossMatching":false,"runnersVoidable":false,"numberOfActiveRunners":48,"betDelay":0,"status":"OPEN","runners":[{"status":"ACTIVE","sortPriority":1,"id":2263600,"hc":-11.5,"name":"Brengle"},{"status":"ACTIVE","sortPriority":2,"id":3611581,"hc":11.5,"name":"Voegele"},{"status":"ACTIVE","sortPriority":3,"id":2263600,"hc":-10.5,"name":"Brengle"},{"status":"ACTIVE","sortPriority":4,"id":3611581,"hc":10.5,"name":"Voegele"},{"status":"ACTIVE","sortPriority":5,"id":2263600,"hc":-9.5,"name":"Brengle"},{"status":"ACTIVE","sortPriority":6,"id":3611581,"hc":9.5,"name":"Voegele"},{"status":"ACTIVE","sortPriority":7,"id":2263600,"hc":-8.5,"name":"Brengle"},{"status":"ACTIVE","sortPriority":8,"id":3611581,"hc":8.5,"name":"Voegele"},{"status":"ACTIVE","sortPriority":9,"id":2263600,"hc":-7.5,"name":"Brengle"},{"status":"ACTIVE","sortPriority":10,"id":3611581,"hc":7.5,"name":"Voegele"},{"status":"ACTIVE","sortPriority":11,"id":2263600,"hc":-6.5,"name":"Brengle"},{"status":"ACTIVE","sortPriority":12,"id":3611581,"hc":6.5,"name":"Voegele"},{"status":"ACTIVE","sortPriority":13,"id":2263600,"hc":-5.5,"name":"Brengle"},{"status":"ACTIVE","sortPriority":14,"id":3611581,"hc":5.5,"name":"Voegele"},{"status":"ACTIVE","sortPriority":15,"id":2263600,"hc":-4.5,"name":"Brengle"},{"status":"ACTIVE","sortPriority":16,"id":3611581,"hc":4.5,"name":"Voegele"},{"status":"ACTIVE","sortPriority":17,"id":2263600,"hc":-3.5,"name":"Brengle"},{"status":"ACTIVE","sortPriority":18,"id":3611581,"hc":3.5,"name":"Voegele"},{"status":"ACTIVE","sortPriority":19,"id":2263600,"hc":-2.5,"name":"Brengle"},{"status":"ACTIVE","sortPriority":20,"id":3611581,"hc":2.5,"name":"Voegele"},{"status":"ACTIVE","sortPriority":21,"id":2263600,"hc":-1.5,"name":"Brengle"},{"status":"ACTIVE","sortPriority":22,"id":3611581,"hc":1.5,"name":"Voegele"},{"status":"ACTIVE","sortPriority":23,"id":2263600,"hc":-0.5,"name":"Brengle"},{"status":"ACTIVE","sortPriority":24,"id":3611581,"hc":0.5,"name":"Voegele"},{"status":"ACTIVE","sortPriority":25,"id":2263600,"hc":0.5,"name":"Brengle"},{"status":"ACTIVE","sortPriority":26,"id":3611581,"hc":-0.5,"name":"Voegele"},{"status":"ACTIVE","sortPriority":27,"id":2263600,"hc":1.5,"name":"Brengle"},{"status":"ACTIVE","sortPriority":28,"id":3611581,"hc":-1.5,"name":"Voegele"},{"status":"ACTIVE","sortPriority":29,"id":2263600,"hc":2.5,"name":"Brengle"},{"status":"ACTIVE","sortPriority":30,"id":3611581,"hc":-2.5,"name":"Voegele"},{"status":"ACTIVE","sortPriority":31,"id":2263600,"hc":3.5,"name":"Brengle"},{"status":"ACTIVE","sortPriority":32,"id":3611581,"hc":-3.5,"name":"Voegele"},{"status":"ACTIVE","sortPriority":33,"id":2263600,"hc":4.5,"name":"Brengle"},{"status":"ACTIVE","sortPriority":34,"id":3611581,"hc":-4.5,"name":"Voegele"},{"status":"ACTIVE","sortPriority":35,"id":2263600,"hc":5.5,"name":"Brengle"},{"status":"ACTIVE","sortPriority":36,"id":3611581,"hc":-5.5,"name":"Voegele"},{"status":"ACTIVE","sortPriority":37,"id":2263600,"hc":6.5,"name":"Brengle"},{"status":"ACTIVE","sortPriority":38,"id":3611581,"hc":-6.5,"name":"Voegele"},{"status":"ACTIVE","sortPriority":39,"id":2263600,"hc":7.5,"name":"Brengle"},{"status":"ACTIVE","sortPriority":40,"id":3611581,"hc":-7.5,"name":"Voegele"},{"status":"ACTIVE","sortPriority":41,"id":2263600,"hc":8.5,"name":"Brengle"},{"status":"ACTIVE","sortPriority":42,"id":3611581,"hc":-8.5,"name":"Voegele"},{"status":"ACTIVE","sortPriority":43,"id":2263600,"hc":9.5,"name":"Brengle"},{"status":"ACTIVE","sortPriority":44,"id":3611581,"hc":-9.5,"name":"Voegele"},{"status":"ACTIVE","sortPriority":45,"id":2263600,"hc":10.5,"name":"Brengle"},{"status":"ACTIVE","sortPriority":46,"id":3611581,"hc":-10.5,"name":"Voegele"},{"status":"ACTIVE","sortPriority":47,"id":2263600,"hc":11.5,"name":"Brengle"},{"status":"ACTIVE","sortPriority":48,"id":3611581,"hc":-11.5,"name":"Voegele"}],"regulators":["MR_INT"],"discountAllowed":false,"timezone":"UTC","openDate":"2020-02-02T18:00:00.000Z","version":3147219617,"name":"Handicap","eventName":"Brengle v Voegele"}}]}
{"op":"mcm","clk":"1001501273","pt":1580587071655,"mc":[{"id":"1.168230817","marketDefinition":{"bspMarket":false,"turnInPlayEnabled":true,"persistenceEnabled":true,"marketBaseRate":5.0,"eventId":"29681775","eventTypeId":"2","numberOfWinners":0,"bettingType":"ASIAN_HANDICAP_DOUBLE_LINE","marketType":"HANDICAP","marketTime":"2020-02-02T18:00:00.000Z","suspendTime":"2020-02-02T18:00:00.000Z","bspReconciled":false,"complete":true,"inPlay":false,"crossMatching":false,"runnersVoidable":false,"numberOfActiveRunners":48,"betDelay":0,"status":"OPEN","runners":[{"status":"ACTIVE","sortPriority":1,"id":2263600,"hc":-11.5,"name":"Brengle"},{"status":"ACTIVE","sortPriority":2,"id":3611581,"hc":11.5,"name":"Voegele"},{"status":"ACTIVE","sortPriority":3,"id":2263600,"hc":-10.5,"name":"Brengle"},{"status":"ACTIVE","sortPriority":4,"id":3611581,"hc":10.5,"name":"Voegele"},{"status":"ACTIVE","sortPriority":5,"id":2263600,"hc":-9.5,"name":"Brengle"},{"status":"ACTIVE","sortPriority":6,"id":3611581,"hc":9.5,"name":"Voegele"},{"status":"ACTIVE","sortPriority":7,"id":2263600,"hc":-8.5,"name":"Brengle"},{"status":"ACTIVE","sortPriority":8,"id":3611581,"hc":8.5,"name":"Voegele"},{"status":"ACTIVE","sortPriority":9,"id":2263600,"hc":-7.5,"name":"Brengle"},{"status":"ACTIVE","sortPriority":10,"id":3611581,"hc":7.5,"name":"Voegele"},{"status":"ACTIVE","sortPriority":11,"id":2263600,"hc":-6.5,"name":"Brengle"},{"status":"ACTIVE","sortPriority":12,"id":3611581,"hc":6.5,"name":"Voegele"},{"status":"ACTIVE","sortPriority":13,"id":2263600,"hc":-5.5,"name":"Brengle"},{"status":"ACTIVE","sortPriority":14,"id":3611581,"hc":5.5,"name":"Voegele"},{"status":"ACTIVE","sortPriority":15,"id":2263600,"hc":-4.5,"name":"Brengle"},{"status":"ACTIVE","sortPriority":16,"id":3611581,"hc":4.5,"name":"Voegele"},{"status":"ACTIVE","sortPriority":17,"id":2263600,"hc":-3.5,"name":"Brengle"},{"status":"ACTIVE","sortPriority":18,"id":3611581,"hc":3.5,"name":"Voegele"},{"status":"ACTIVE","sortPriority":19,"id":2263600,"hc":-2.5,"name":"Brengle"},{"status":"ACTIVE","sortPriority":20,"id":3611581,"hc":2.5,"name":"Voegele"},{"status":"ACTIVE","sortPriority":21,"id":2263600,"hc":-1.5,"name":"Brengle"},{"status":"ACTIVE","sortPriority":22,"id":3611581,"hc":1.5,"name":"Voegele"},{"status":"ACTIVE","sortPriority":23,"id":2263600,"hc":-0.5,"name":"Brengle"},{"status":"ACTIVE","sortPriority":24,"id":3611581,"hc":0.5,"name":"Voegele"},{"status":"ACTIVE","sortPriority":25,"id":2263600,"hc":0.5,"name":"Brengle"},{"status":"ACTIVE","sortPriority":26,"id":3611581,"hc":-0.5,"name":"Voegele"},{"status":"ACTIVE","sortPriority":27,"id":2263600,"hc":1.5,"name":"Brengle"},{"status":"ACTIVE","sortPriority":28,"id":3611581,"hc":-1.5,"name":"Voegele"},{"status":"ACTIVE","sortPriority":29,"id":2263600,"hc":2.5,"name":"Brengle"},{"status":"ACTIVE","sortPriority":30,"id":3611581,"hc":-2.5,"name":"Voegele"},{"status":"ACTIVE","sortPriority":31,"id":2263600,"hc":3.5,"name":"Brengle"},{"status":"ACTIVE","sortPriority":32,"id":3611581,"hc":-3.5,"name":"Voegele"},{"status":"ACTIVE","sortPriority":33,"id":2263600,"hc":4.5,"name":"Brengle"},{"status":"ACTIVE","sortPriority":34,"id":3611581,"hc":-4.5,"name":"Voegele"},{"status":"ACTIVE","sortPriority":35,"id":2263600,"hc":5.5,"name":"Brengle"},{"status":"ACTIVE","sortPriority":36,"id":3611581,"hc":-5.5,"name":"Voegele"},{"status":"ACTIVE","sortPriority":37,"id":2263600,"hc":6.5,"name":"Brengle"},{"status":"ACTIVE","sortPriority":38,"id":3611581,"hc":-6.5,"name":"Voegele"},{"status":"ACTIVE","sortPriority":39,"id":2263600,"hc":7.5,"name":"Brengle"},{"status":"ACTIVE","sortPriority":40,"id":3611581,"hc":-7.5,"name":"Voegele"},{"status":"ACTIVE","sortPriority":41,"id":2263600,"hc":8.5,"name":"Brengle"},{"status":"ACTIVE","sortPriority":42,"id":3611581,"hc":-8.5,"name":"Voegele"},{"status":"ACTIVE","sortPriority":43,"id":2263600,"hc":9.5,"name":"Brengle"},{"status":"ACTIVE","sortPriority":44,"id":3611581,"hc":-9.5,"name":"Voegele"},{"status":"ACTIVE","sortPriority":45,"id":2263600,"hc":10.5,"name":"Brengle"},{"status":"ACTIVE","sortPriority":46,"id":3611581,"hc":-10.5,"name":"Voegele"},{"status":"ACTIVE","sortPriority":47,"id":2263600,"hc":11.5,"name":"Brengle"},{"status":"ACTIVE","sortPriority":48,"id":3611581,"hc":-11.5,"name":"Voegele"}],"regulators":["MR_INT"],"discountAllowed":false,"timezone":"UTC","openDate":"2020-02-02T18:00:00.000Z","version":3147219617,"name":"Handicap","eventName":"Brengle v Voegele"}}]}
{"op":"mcm","clk":"1001501657","pt":1580587073688,"mc":[{"id":"1.168230817","marketDefinition":{"bspMarket":false,"turnInPlayEnabled":true,"persistenceEnabled":true,"marketBaseRate":5.0,"eventId":"29681775","eventTypeId":"2","numberOfWinners":0,"bettingType":"ASIAN_HANDICAP_DOUBLE_LINE","marketType":"HANDICAP","marketTime":"2020-02-02T18:00:00.000Z","suspendTime":"2020-02-02T18:00:00.000Z","bspReconciled":false,"complete":true,"inPlay":false,"crossMatching":false,"runnersVoidable":false,"numberOfActiveRunners":48,"betDelay":0,"status":"OPEN","runners":[{"status":"ACTIVE","sortPriority":1,"id":2263600,"hc":-11.5,"name":"Brengle"},{"status":"ACTIVE","sortPriority":2,"id":3611581,"hc":11.5,"name":"Voegele"},{"status":"ACTIVE","sortPriority":3,"id":2263600,"hc":-10.5,"name":"Brengle"},{"status":"ACTIVE","sortPriority":4,"id":3611581,"hc":10.5,"name":"Voegele"},{"status":"ACTIVE","sortPriority":5,"id":2263600,"hc":-9.5,"name":"Brengle"},{"status":"ACTIVE","sortPriority":6,"id":3611581,"hc":9.5,"name":"Voegele"},{"status":"ACTIVE","sortPriority":7,"id":2263600,"hc":-8.5,"name":"Brengle"},{"status":"ACTIVE","sortPriority":8,"id":3611581,"hc":8.5,"name":"Voegele"},{"status":"ACTIVE","sortPriority":9,"id":2263600,"hc":-7.5,"name":"Brengle"},{"status":"ACTIVE","sortPriority":10,"id":3611581,"hc":7.5,"name":"Voegele"},{"status":"ACTIVE","sortPriority":11,"id":2263600,"hc":-6.5,"name":"Brengle"},{"status":"ACTIVE","sortPriority":12,"id":3611581,"hc":6.5,"name":"Voegele"},{"status":"ACTIVE","sortPriority":13,"id":2263600,"hc":-5.5,"name":"Brengle"},{"status":"ACTIVE","sortPriority":14,"id":3611581,"hc":5.5,"name":"Voegele"},{"status":"ACTIVE","sortPriority":15,"id":2263600,"hc":-4.5,"name":"Brengle"},{"status":"ACTIVE","sortPriority":16,"id":3611581,"hc":4.5,"name":"Voegele"},{"status":"ACTIVE","sortPriority":17,"id":2263600,"hc":-3.5,"name":"Brengle"},{"status":"ACTIVE","sortPriority":18,"id":3611581,"hc":3.5,"name":"Voegele"},{"status":"ACTIVE","sortPriority":19,"id":2263600,"hc":-2.5,"name":"Brengle"},{"status":"ACTIVE","sortPriority":20,"id":3611581,"hc":2.5,"name":"Voegele"},{"status":"ACTIVE","sortPriority":21,"id":2263600,"hc":-1.5,"name":"Brengle"},{"status":"ACTIVE","sortPriority":22,"id":3611581,"hc":1.5,"name":"Voegele"},{"status":"ACTIVE","sortPriority":23,"id":2263600,"hc":-0.5,"name":"Brengle"},{"status":"ACTIVE","sortPriority":24,"id":3611581,"hc":0.5,"name":"Voegele"},{"status":"ACTIVE","sortPriority":25,"id":2263600,"hc":0.5,"name":"Brengle"},{"status":"ACTIVE","sortPriority":26,"id":3611581,"hc":-0.5,"name":"Voegele"},{"status":"ACTIVE","sortPriority":27,"id":2263600,"hc":1.5,"name":"Brengle"},{"status":"ACTIVE","sortPriority":28,"id":3611581,"hc":-1.5,"name":"Voegele"},{"status":"ACTIVE","sortPriority":29,"id":2263600,"hc":2.5,"name":"Brengle"},{"status":"ACTIVE","sortPriority":30,"id":3611581,"hc":-2.5,"name":"Voegele"},{"status":"ACTIVE","sortPriority":31,"id":2263600,"hc":3.5,"name":"Brengle"},{"status":"ACTIVE","sortPriority":32,"id":3611581,"hc":-3.5,"name":"Voegele"},{"status":"ACTIVE","sortPriority":33,"id":2263600,"hc":4.5,"name":"Brengle"},{"status":"ACTIVE","sortPriority":34,"id":3611581,"hc":-4.5,"name":"Voegele"},{"status":"ACTIVE","sortPriority":35,"id":2263600,"hc":5.5,"name":"Brengle"},{"status":"ACTIVE","sortPriority":36,"id":3611581,"hc":-5.5,"name":"Voegele"},{"status":"ACTIVE","sortPriority":37,"id":2263600,"hc":6.5,"name":"Brengle"},{"status":"ACTIVE","sortPriority":38,"id":3611581,"hc":-6.5,"name":"Voegele"},{"status":"ACTIVE","sortPriority":39,"id":2263600,"hc":7.5,"name":"Brengle"},{"status":"ACTIVE","sortPriority":40,"id":3611581,"hc":-7.5,"name":"Voegele"},{"status":"ACTIVE","sortPriority":41,"id":2263600,"hc":8.5,"name":"Brengle"},{"status":"ACTIVE","sortPriority":42,"id":3611581,"hc":-8.5,"name":"Voegele"},{"status":"ACTIVE","sortPriority":43,"id":2263600,"hc":9.5,"name":"Brengle"},{"status":"ACTIVE","sortPriority":44,"id":3611581,"hc":-9.5,"name":"Voegele"},{"status":"ACTIVE","sortPriority":45,"id":2263600,"hc":10.5,"name":"Brengle"},{"status":"ACTIVE","sortPriority":46,"id":3611581,"hc":-10.5,"name":"Voegele"},{"status":"ACTIVE","sortPriority":47,"id":2263600,"hc":11.5,"name":"Brengle"},{"status":"ACTIVE","sortPriority":48,"id":3611581,"hc":-11.5,"name":"Voegele"}],"regulators":["MR_INT"],"discountAllowed":true,"timezone":"UTC","openDate":"2020-02-02T18:00:00.000Z","version":3147219617,"name":"Handicap","eventName":"Brengle v Voegele"}}]}
{"op":"mcm","clk":"1003055392","pt":1580602434601,"mc":[{"id":"1.168230817","rc":[{"batl":[[0,2.28,104.09]],"ltp":0.0,"tv":0.0,"id":3611581,"hc":1.5},{"batl":[[0,2.38,177.54]],"ltp":0.0,"tv":0.0,"id":2263600,"hc":-1.5},{"batl":[[0,2.7,95.45]],"ltp":0.0,"tv":0.0,"id":3611581,"hc":-0.5},{"batb":[[0,1.76,146.48]],"ltp":0.0,"tv":0.0,"id":3611581,"hc":0.5},{"batb":[[0,1.79,143.93]],"ltp":0.0,"tv":0.0,"id":2263600,"hc":-0.5},{"batl":[[0,2.36,109.07]],"ltp":0.0,"tv":0.0,"id":2263600,"hc":0.5}]}]}
{"op":"mcm","clk":"1003309908","pt":1580606034721,"mc":[{"id":"1.168230817","marketDefinition":{"bspMarket":false,"turnInPlayEnabled":true,"persistenceEnabled":true,"marketBaseRate":5.0,"eventId":"29681775","eventTypeId":"2","numberOfWinners":0,"bettingType":"ASIAN_HANDICAP_DOUBLE_LINE","marketType":"HANDICAP","marketTime":"2020-02-02T18:00:00.000Z","suspendTime":"2020-02-02T18:00:00.000Z","bspReconciled":false,"complete":true,"inPlay":false,"crossMatching":false,"runnersVoidable":false,"numberOfActiveRunners":48,"betDelay":0,"status":"OPEN","runners":[{"status":"ACTIVE","sortPriority":1,"id":2263600,"hc":-11.5,"name":"Brengle"},{"status":"ACTIVE","sortPriority":2,"id":3611581,"hc":11.5,"name":"Voegele"},{"status":"ACTIVE","sortPriority":3,"id":2263600,"hc":-10.5,"name":"Brengle"},{"status":"ACTIVE","sortPriority":4,"id":3611581,"hc":10.5,"name":"Voegele"},{"status":"ACTIVE","sortPriority":5,"id":2263600,"hc":-9.5,"name":"Brengle"},{"status":"ACTIVE","sortPriority":6,"id":3611581,"hc":9.5,"name":"Voegele"},{"status":"ACTIVE","sortPriority":7,"id":2263600,"hc":-8.5,"name":"Brengle"},{"status":"ACTIVE","sortPriority":8,"id":3611581,"hc":8.5,"name":"Voegele"},{"status":"ACTIVE","sortPriority":9,"id":2263600,"hc":-7.5,"name":"Brengle"},{"status":"ACTIVE","sortPriority":10,"id":3611581,"hc":7.5,"name":"Voegele"},{"status":"ACTIVE","sortPriority":11,"id":2263600,"hc":-6.5,"name":"Brengle"},{"status":"ACTIVE","sortPriority":12,"id":3611581,"hc":6.5,"name":"Voegele"},{"status":"ACTIVE","sortPriority":13,"id":2263600,"hc":-5.5,"name":"Brengle"},{"status":"ACTIVE","sortPriority":14,"id":3611581,"hc":5.5,"name":"Voegele"},{"status":"ACTIVE","sortPriority":15,"id":2263600,"hc":-4.5,"name":"Brengle"},{"status":"ACTIVE","sortPriority":16,"id":3611581,"hc":4.5,"name":"Voegele"},{"status":"ACTIVE","sortPriority":17,"id":2263600,"hc":-3.5,"name":"Brengle"},{"status":"ACTIVE","sortPriority":18,"id":3611581,"hc":3.5,"name":"Voegele"},{"status":"ACTIVE","sortPriority":19,"id":2263600,"hc":-2.5,"name":"Brengle"},{"status":"ACTIVE","sortPriority":20,"id":3611581,"hc":2.5,"name":"Voegele"},{"status":"ACTIVE","sortPriority":21,"id":2263600,"hc":-1.5,"name":"Brengle"},{"status":"ACTIVE","sortPriority":22,"id":3611581,"hc":1.5,"name":"Voegele"},{"status":"ACTIVE","sortPriority":23,"id":2263600,"hc":-0.5,"name":"Brengle"},{"status":"ACTIVE","sortPriority":24,"id":3611581,"hc":0.5,"name":"Voegele"},{"status":"ACTIVE","sortPriority":25,"id":2263600,"hc":0.5,"name":"Brengle"},{"status":"ACTIVE","sortPriority":26,"id":3611581,"hc":-0.5,"name":"Voegele"},{"status":"ACTIVE","sortPriority":27,"id":2263600,"hc":1.5,"name":"Brengle"},{"status":"ACTIVE","sortPriority":28,"id":3611581,"hc":-1.5,"name":"Voegele"},{"status":"ACTIVE","sortPriority":29,"id":2263600,"hc":2.5,"name":"Brengle"},{"status":"ACTIVE","sortPriority":30,"id":3611581,"hc":-2.5,"name":"Voegele"},{"status":"ACTIVE","sortPriority":31,"id":2263600,"hc":3.5,"name":"Brengle"},{"status":"ACTIVE","sortPriority":32,"id":3611581,"hc":-3.5,"name":"Voegele"},{"status":"ACTIVE","sortPriority":33,"id":2263600,"hc":4.5,"name":"Brengle"},{"status":"ACTIVE","sortPriority":34,"id":3611581,"hc":-4.5,"name":"Voegele"},{"status":"ACTIVE","sortPriority":35,"id":2263600,"hc":5.5,"name":"Brengle"},{"status":"ACTIVE","sortPriority":36,"id":3611581,"hc":-5.5,"name":"Voegele"},{"status":"ACTIVE","sortPriority":37,"id":2263600,"hc":6.5,"name":"Brengle"},{"status":"ACTIVE","sortPriority":38,"id":3611581,"hc":-6.5,"name":"Voegele"},{"status":"ACTIVE","sortPriority":39,"id":2263600,"hc":7.5,"name":"Brengle"},{"status":"ACTIVE","sortPriority":40,"id":3611581,"hc":-7.5,"name":"Voegele"},{"status":"ACTIVE","sortPriority":41,"id":2263600,"hc":8.5,"name":"Brengle"},{"status":"ACTIVE","sortPriority":42,"id":3611581,"hc":-8.5,"name":"Voegele"},{"status":"ACTIVE","sortPriority":43,"id":2263600,"hc":9.5,"name":"Brengle"},{"status":"ACTIVE","sortPriority":44,"id":3611581,"hc":-9.5,"name":"Voegele"},{"status":"ACTIVE","sortPriority":45,"id":2263600,"hc":10.5,"name":"Brengle"},{"status":"ACTIVE","sortPriority":46,"id":3611581,"hc":-10.5,"name":"Voegele"},{"status":"ACTIVE","sortPriority":47,"id":2263600,"hc":11.5,"name":"Brengle"},{"status":"ACTIVE","sortPriority":48,"id":3611581,"hc":-11.5,"name":"Voegele"}],"regulators":["MR_INT"],"discountAllowed":true,"timezone":"UTC","openDate":"2020-02-02T18:00:00.000Z","version":3147399796,"name":"Handicap","eventName":"Brengle v Voegele"},"rc":[{"batl":[[0,2.14,120.25]],"ltp":0.0,"tv":0.0,"id":2263600,"hc":0.5}]}]}
{"op":"mcm","clk":"1003411911","pt":1580607390633,"mc":[{"id":"1.168230817","rc":[{"batl":[[0,2.24,76.98]],"ltp":0.0,"tv":0.0,"id":3611581,"hc":1.5},{"batl":[[0,2.76,153.27]],"ltp":0.0,"tv":0.0,"id":2263600,"hc":-1.5},{"batb":[[0,1.73,149.02]],"ltp":0.0,"tv":0.0,"id":3611581,"hc":0.5},{"batb":[[0,1.82,95.14]],"ltp":0.0,"tv":0.0,"id":2263600,"hc":-0.5}]}]}
{"op":"mcm","clk":"1003568928","pt":1580609635312,"mc":[{"id":"1.168230817","marketDefinition":{"bspMarket":false,"turnInPlayEnabled":true,"persistenceEnabled":true,"marketBaseRate":5.0,"eventId":"29681775","eventTypeId":"2","numberOfWinners":0,"bettingType":"ASIAN_HANDICAP_DOUBLE_LINE","marketType":"HANDICAP","marketTime":"2020-02-02T18:00:00.000Z","suspendTime":"2020-02-02T18:00:00.000Z","bspReconciled":false,"complete":true,"inPlay":false,"crossMatching":false,"runnersVoidable":false,"numberOfActiveRunners":48,"betDelay":0,"status":"OPEN","runners":[{"status":"ACTIVE","sortPriority":1,"id":2263600,"hc":-11.5,"name":"Brengle"},{"status":"ACTIVE","sortPriority":2,"id":3611581,"hc":11.5,"name":"Voegele"},{"status":"ACTIVE","sortPriority":3,"id":2263600,"hc":-10.5,"name":"Brengle"},{"status":"ACTIVE","sortPriority":4,"id":3611581,"hc":10.5,"name":"Voegele"},{"status":"ACTIVE","sortPriority":5,"id":2263600,"hc":-9.5,"name":"Brengle"},{"status":"ACTIVE","sortPriority":6,"id":3611581,"hc":9.5,"name":"Voegele"},{"status":"ACTIVE","sortPriority":7,"id":2263600,"hc":-8.5,"name":"Brengle"},{"status":"ACTIVE","sortPriority":8,"id":3611581,"hc":8.5,"name":"Voegele"},{"status":"ACTIVE","sortPriority":9,"id":2263600,"hc":-7.5,"name":"Brengle"},{"status":"ACTIVE","sortPriority":10,"id":3611581,"hc":7.5,"name":"Voegele"},{"status":"ACTIVE","sortPriority":11,"id":2263600,"hc":-6.5,"name":"Brengle"},{"status":"ACTIVE","sortPriority":12,"id":3611581,"hc":6.5,"name":"Voegele"},{"status":"ACTIVE","sortPriority":13,"id":2263600,"hc":-5.5,"name":"Brengle"},{"status":"ACTIVE","sortPriority":14,"id":3611581,"hc":5.5,"name":"Voegele"},{"status":"ACTIVE","sortPriority":15,"id":2263600,"hc":-4.5,"name":"Brengle"},{"status":"ACTIVE","sortPriority":16,"id":3611581,"hc":4.5,"name":"Voegele"},{"status":"ACTIVE","sortPriority":17,"id":2263600,"hc":-3.5,"name":"Brengle"},{"status":"ACTIVE","sortPriority":18,"id":3611581,"hc":3.5,"name":"Voegele"},{"status":"ACTIVE","sortPriority":19,"id":2263600,"hc":-2.5,"name":"Brengle"},{"status":"ACTIVE","sortPriority":20,"id":3611581,"hc":2.5,"name":"Voegele"},{"status":"ACTIVE","sortPriority":21,"id":2263600,"hc":-1.5,"name":"Brengle"},{"status":"ACTIVE","sortPriority":22,"id":3611581,"hc":1.5,"name":"Voegele"},{"status":"ACTIVE","sortPriority":23,"id":2263600,"hc":-0.5,"name":"Brengle"},{"status":"ACTIVE","sortPriority":24,"id":3611581,"hc":0.5,"name":"Voegele"},{"status":"ACTIVE","sortPriority":25,"id":2263600,"hc":0.5,"name":"Brengle"},{"status":"ACTIVE","sortPriority":26,"id":3611581,"hc":-0.5,"name":"Voegele"},{"status":"ACTIVE","sortPriority":27,"id":2263600,"hc":1.5,"name":"Brengle"},{"status":"ACTIVE","sortPriority":28,"id":3611581,"hc":-1.5,"name":"Voegele"},{"status":"ACTIVE","sortPriority":29,"id":2263600,"hc":2.5,"name":"Brengle"},{"status":"ACTIVE","sortPriority":30,"id":3611581,"hc":-2.5,"name":"Voegele"},{"status":"ACTIVE","sortPriority":31,"id":2263600,"hc":3.5,"name":"Brengle"},{"status":"ACTIVE","sortPriority":32,"id":3611581,"hc":-3.5,"name":"Voegele"},{"status":"ACTIVE","sortPriority":33,"id":2263600,"hc":4.5,"name":"Brengle"},{"status":"ACTIVE","sortPriority":34,"id":3611581,"hc":-4.5,"name":"Voegele"},{"status":"ACTIVE","sortPriority":35,"id":2263600,"hc":5.5,"name":"Brengle"},{"status":"ACTIVE","sortPriority":36,"id":3611581,"hc":-5.5,"name":"Voegele"},{"status":"ACTIVE","sortPriority":37,"id":2263600,"hc":6.5,"name":"Brengle"},{"status":"ACTIVE","sortPriority":38,"id":3611581,"hc":-6.5,"name":"Voegele"},{"status":"ACTIVE","sortPriority":39,"id":2263600,"hc":7.5,"name":"Brengle"},{"status":"ACTIVE","sortPriority":40,"id":3611581,"hc":-7.5,"name":"Voegele"},{"status":"ACTIVE","sortPriority":41,"id":2263600,"hc":8.5,"name":"Brengle"},{"status":"ACTIVE","sortPriority":42,"id":3611581,"hc":-8.5,"name":"Voegele"},{"status":"ACTIVE","sortPriority":43,"id":2263600,"hc":9.5,"name":"Brengle"},{"status":"ACTIVE","sortPriority":44,"id":3611581,"hc":-9.5,"name":"Voegele"},{"status":"ACTIVE","sortPriority":45,"id":2263600,"hc":10.5,"name":"Brengle"},{"status":"ACTIVE","sortPriority":46,"id":3611581,"hc":-10.5,"name":"Voegele"},{"status":"ACTIVE","sortPriority":47,"id":2263600,"hc":11.5,"name":"Brengle"},{"status":"ACTIVE","sortPriority":48,"id":3611581,"hc":-11.5,"name":"Voegele"}],"regulators":["MR_INT"],"discountAllowed":true,"timezone":"UTC","openDate":"2020-02-02T18:00:00.000Z","version":3147399796,"name":"Handicap","eventName":"Brengle v Voegele"},"rc":[{"batl":[[0,2.4,107.29]],"ltp":0.0,"tv":0.0,"id":3611581,"hc":-0.5},{"batl":[[0,2.28,113.09]],"ltp":0.0,"tv":0.0,"id":2263600,"hc":0.5}]}]}
{"op":"mcm","clk":"1003669425","pt":1580610990559,"mc":[{"id":"1.168230817","marketDefinition":{"bspMarket":false,"turnInPlayEnabled":true,"persistenceEnabled":true,"marketBaseRate":5.0,"eventId":"29681775","eventTypeId":"2","numberOfWinners":0,"bettingType":"ASIAN_HANDICAP_DOUBLE_LINE","marketType":"HANDICAP","marketTime":"2020-02-02T18:00:00.000Z","suspendTime":"2020-02-02T18:00:00.000Z","bspReconciled":false,"complete":true,"inPlay":false,"crossMatching":false,"runnersVoidable":false,"numberOfActiveRunners":48,"betDelay":0,"status":"OPEN","runners":[{"status":"ACTIVE","sortPriority":1,"id":2263600,"hc":-11.5,"name":"Brengle"},{"status":"ACTIVE","sortPriority":2,"id":3611581,"hc":11.5,"name":"Voegele"},{"status":"ACTIVE","sortPriority":3,"id":2263600,"hc":-10.5,"name":"Brengle"},{"status":"ACTIVE","sortPriority":4,"id":3611581,"hc":10.5,"name":"Voegele"},{"status":"ACTIVE","sortPriority":5,"id":2263600,"hc":-9.5,"name":"Brengle"},{"status":"ACTIVE","sortPriority":6,"id":3611581,"hc":9.5,"name":"Voegele"},{"status":"ACTIVE","sortPriority":7,"id":2263600,"hc":-8.5,"name":"Brengle"},{"status":"ACTIVE","sortPriority":8,"id":3611581,"hc":8.5,"name":"Voegele"},{"status":"ACTIVE","sortPriority":9,"id":2263600,"hc":-7.5,"name":"Brengle"},{"status":"ACTIVE","sortPriority":10,"id":3611581,"hc":7.5,"name":"Voegele"},{"status":"ACTIVE","sortPriority":11,"id":2263600,"hc":-6.5,"name":"Brengle"},{"status":"ACTIVE","sortPriority":12,"id":3611581,"hc":6.5,"name":"Voegele"},{"status":"ACTIVE","sortPriority":13,"id":2263600,"hc":-5.5,"name":"Brengle"},{"status":"ACTIVE","sortPriority":14,"id":3611581,"hc":5.5,"name":"Voegele"},{"status":"ACTIVE","sortPriority":15,"id":2263600,"hc":-4.5,"name":"Brengle"},{"status":"ACTIVE","sortPriority":16,"id":3611581,"hc":4.5,"name":"Voegele"},{"status":"ACTIVE","sortPriority":17,"id":2263600,"hc":-3.5,"name":"Brengle"},{"status":"ACTIVE","sortPriority":18,"id":3611581,"hc":3.5,"name":"Voegele"},{"status":"ACTIVE","sortPriority":19,"id":2263600,"hc":-2.5,"name":"Brengle"},{"status":"ACTIVE","sortPriority":20,"id":3611581,"hc":2.5,"name":"Voegele"},{"status":"ACTIVE","sortPriority":21,"id":2263600,"hc":-1.5,"name":"Brengle"},{"status":"ACTIVE","sortPriority":22,"id":3611581,"hc":1.5,"name":"Voegele"},{"status":"ACTIVE","sortPriority":23,"id":2263600,"hc":-0.5,"name":"Brengle"},{"status":"ACTIVE","sortPriority":24,"id":3611581,"hc":0.5,"name":"Voegele"},{"status":"ACTIVE","sortPriority":25,"id":2263600,"hc":0.5,"name":"Brengle"},{"status":"ACTIVE","sortPriority":26,"id":3611581,"hc":-0.5,"name":"Voegele"},{"status":"ACTIVE","sortPriority":27,"id":2263600,"hc":1.5,"name":"Brengle"},{"status":"ACTIVE","sortPriority":28,"id":3611581,"hc":-1.5,"name":"Voegele"},{"status":"ACTIVE","sortPriority":29,"id":2263600,"hc":2.5,"name":"Brengle"},{"status":"ACTIVE","sortPriority":30,"id":3611581,"hc":-2.5,"name":"Voegele"},{"status":"ACTIVE","sortPriority":31,"id":2263600,"hc":3.5,"name":"Brengle"},{"status":"ACTIVE","sortPriority":32,"id":3611581,"hc":-3.5,"name":"Voegele"},{"status":"ACTIVE","sortPriority":33,"id":2263600,"hc":4.5,"name":"Brengle"},{"status":"ACTIVE","sortPriority":34,"id":3611581,"hc":-4.5,"name":"Voegele"},{"status":"ACTIVE","sortPriority":35,"id":2263600,"hc":5.5,"name":"Brengle"},{"status":"ACTIVE","sortPriority":36,"id":3611581,"hc":-5.5,"name":"Voegele"},{"status":"ACTIVE","sortPriority":37,"id":2263600,"hc":6.5,"name":"Brengle"},{"status":"ACTIVE","sortPriority":38,"id":3611581,"hc":-6.5,"name":"Voegele"},{"status":"ACTIVE","sortPriority":39,"id":2263600,"hc":7.5,"name":"Brengle"},{"status":"ACTIVE","sortPriority":40,"id":3611581,"hc":-7.5,"name":"Voegele"},{"status":"ACTIVE","sortPriority":41,"id":2263600,"hc":8.5,"name":"Brengle"},{"status":"ACTIVE","sortPriority":42,"id":3611581,"hc":-8.5,"name":"Voegele"},{"status":"ACTIVE","sortPriority":43,"id":2263600,"hc":9.5,"name":"Brengle"},{"status":"ACTIVE","sortPriority":44,"id":3611581,"hc":-9.5,"name":"Voegele"},{"status":"ACTIVE","sortPriority":45,"id":2263600,"hc":10.5,"name":"Brengle"},{"status":"ACTIVE","sortPriority":46,"id":3611581,"hc":-10.5,"name":"Voegele"},{"status":"ACTIVE","sortPriority":47,"id":2263600,"hc":11.5,"name":"Brengle"},{"status":"ACTIVE","sortPriority":48,"id":3611581,"hc":-11.5,"name":"Voegele"}],"regulators":["MR_INT"],"discountAllowed":true,"timezone":"UTC","openDate":"2020-02-02T18:00:00.000Z","version":3147399796,"name":"Handicap","eventName":"Brengle v Voegele"}}]}
{"op":"mcm","clk":"1003669460","pt":1580610991025,"mc":[{"id":"1.168230817","marketDefinition":{"bspMarket":false,"turnInPlayEnabled":true,"persistenceEnabled":true,"marketBaseRate":5.0,"eventId":"29681775","eventTypeId":"2","numberOfWinners":0,"bettingType":"ASIAN_HANDICAP_DOUBLE_LINE","marketType":"HANDICAP","marketTime":"2020-02-02T18:00:00.000Z","suspendTime":"2020-02-02T18:00:00.000Z","bspReconciled":false,"complete":true,"inPlay":false,"crossMatching":false,"runnersVoidable":false,"numberOfActiveRunners":48,"betDelay":0,"status":"OPEN","runners":[{"status":"ACTIVE","sortPriority":1,"id":2263600,"hc":-11.5,"name":"Brengle"},{"status":"ACTIVE","sortPriority":2,"id":3611581,"hc":11.5,"name":"Voegele"},{"status":"ACTIVE","sortPriority":3,"id":2263600,"hc":-10.5,"name":"Brengle"},{"status":"ACTIVE","sortPriority":4,"id":3611581,"hc":10.5,"name":"Voegele"},{"status":"ACTIVE","sortPriority":5,"id":2263600,"hc":-9.5,"name":"Brengle"},{"status":"ACTIVE","sortPriority":6,"id":3611581,"hc":9.5,"name":"Voegele"},{"status":"ACTIVE","sortPriority":7,"id":2263600,"hc":-8.5,"name":"Brengle"},{"status":"ACTIVE","sortPriority":8,"id":3611581,"hc":8.5,"name":"Voegele"},{"status":"ACTIVE","sortPriority":9,"id":2263600,"hc":-7.5,"name":"Brengle"},{"status":"ACTIVE","sortPriority":10,"id":3611581,"hc":7.5,"name":"Voegele"},{"status":"ACTIVE","sortPriority":11,"id":2263600,"hc":-6.5,"name":"Brengle"},{"status":"ACTIVE","sortPriority":12,"id":3611581,"hc":6.5,"name":"Voegele"},{"status":"ACTIVE","sortPriority":13,"id":2263600,"hc":-5.5,"name":"Brengle"},{"status":"ACTIVE","sortPriority":14,"id":3611581,"hc":5.5,"name":"Voegele"},{"status":"ACTIVE","sortPriority":15,"id":2263600,"hc":-4.5,"name":"Brengle"},{"status":"ACTIVE","sortPriority":16,"id":3611581,"hc":4.5,"name":"Voegele"},{"status":"ACTIVE","sortPriority":17,"id":2263600,"hc":-3.5,"name":"Brengle"},{"status":"ACTIVE","sortPriority":18,"id":3611581,"hc":3.5,"name":"Voegele"},{"status":"ACTIVE","sortPriority":19,"id":2263600,"hc":-2.5,"name":"Brengle"},{"status":"ACTIVE","sortPriority":20,"id":3611581,"hc":2.5,"name":"Voegele"},{"status":"ACTIVE","sortPriority":21,"id":2263600,"hc":-1.5,"name":"Brengle"},{"status":"ACTIVE","sortPriority":22,"id":3611581,"hc":1.5,"name":"Voegele"},{"status":"ACTIVE","sortPriority":23,"id":2263600,"hc":-0.5,"name":"Brengle"},{"status":"ACTIVE","sortPriority":24,"id":3611581,"hc":0.5,"name":"Voegele"},{"status":"ACTIVE","sortPriority":25,"id":2263600,"hc":0.5,"name":"Brengle"},{"status":"ACTIVE","sortPriority":26,"id":3611581,"hc":-0.5,"name":"Voegele"},{"status":"ACTIVE","sortPriority":27,"id":2263600,"hc":1.5,"name":"Brengle"},{"status":"ACTIVE","sortPriority":28,"id":3611581,"hc":-1.5,"name":"Voegele"},{"status":"ACTIVE","sortPriority":29,"id":2263600,"hc":2.5,"name":"Brengle"},{"status":"ACTIVE","sortPriority":30,"id":3611581,"hc":-2.5,"name":"Voegele"},{"status":"ACTIVE","sortPriority":31,"id":2263600,"hc":3.5,"name":"Brengle"},{"status":"ACTIVE","sortPriority":32,"id":3611581,"hc":-3.5,"name":"Voegele"},{"status":"ACTIVE","sortPriority":33,"id":2263600,"hc":4.5,"name":"Brengle"},{"status":"ACTIVE","sortPriority":34,"id":3611581,"hc":-4.5,"name":"Voegele"},{"status":"ACTIVE","sortPriority":35,"id":2263600,"hc":5.5,"name":"Brengle"},{"status":"ACTIVE","sortPriority":36,"id":3611581,"hc":-5.5,"name":"Voegele"},{"status":"ACTIVE","sortPriority":37,"id":2263600,"hc":6.5,"name":"Brengle"},{"status":"ACTIVE","sortPriority":38,"id":3611581,"hc":-6.5,"name":"Voegele"},{"status":"ACTIVE","sortPriority":39,"id":2263600,"hc":7.5,"name":"Brengle"},{"status":"ACTIVE","sortPriority":40,"id":3611581,"hc":-7.5,"name":"Voegele"},{"status":"ACTIVE","sortPriority":41,"id":2263600,"hc":8.5,"name":"Brengle"},{"status":"ACTIVE","sortPriority":42,"id":3611581,"hc":-8.5,"name":"Voegele"},{"status":"ACTIVE","sortPriority":43,"id":2263600,"hc":9.5,"name":"Brengle"},{"status":"ACTIVE","sortPriority":44,"id":3611581,"hc":-9.5,"name":"Voegele"},{"status":"ACTIVE","sortPriority":45,"id":2263600,"hc":10.5,"name":"Brengle"},{"status":"ACTIVE","sortPriority":46,"id":3611581,"hc":-10.5,"name":"Voegele"},{"status":"ACTIVE","sortPriority":47,"id":2263600,"hc":11.5,"name":"Brengle"},{"status":"ACTIVE","sortPriority":48,"id":3611581,"hc":-11.5,"name":"Voegele"}],"regulators":["MR_INT"],"discountAllowed":true,"timezone":"UTC","openDate":"2020-02-02T18:00:00.000Z","version":3147399796,"name":"Handicap","eventName":"Brengle v Voegele"},"rc":[{"batb":[[0,1.71,100.88]],"ltp":0.0,"tv":0.0,"id":3611581,"hc":0.5},{"batb":[[0,1.8,96.13]],"ltp":0.0,"tv":0.0,"id":2263600,"hc":-0.5}]}]}
{"op":"mcm","clk":"1003797111","pt":1580613235507,"mc":[{"id":"1.168230817","rc":[{"batl":[[0,2.46,104.91]],"ltp":0.0,"tv":0.0,"id":3611581,"hc":-0.5}]}]}
{"op":"mcm","clk":"1003797119","pt":1580613235713,"mc":[{"id":"1.168230817","rc":[{"batl":[[0,2.26,114.02]],"ltp":0.0,"tv":0.0,"id":2263600,"hc":0.5}]}]}
{"op":"mcm","clk":"1003859268","pt":1580614591466,"mc":[{"id":"1.168230817","marketDefinition":{"bspMarket":false,"turnInPlayEnabled":true,"persistenceEnabled":true,"marketBaseRate":5.0,"eventId":"29681775","eventTypeId":"2","numberOfWinners":0,"bettingType":"ASIAN_HANDICAP_DOUBLE_LINE","marketType":"HANDICAP","marketTime":"2020-02-02T18:00:00.000Z","suspendTime":"2020-02-02T18:00:00.000Z","bspReconciled":false,"complete":true,"inPlay":false,"crossMatching":false,"runnersVoidable":false,"numberOfActiveRunners":48,"betDelay":0,"status":"OPEN","runners":[{"status":"ACTIVE","sortPriority":1,"id":2263600,"hc":-11.5,"name":"Brengle"},{"status":"ACTIVE","sortPriority":2,"id":3611581,"hc":11.5,"name":"Voegele"},{"status":"ACTIVE","sortPriority":3,"id":2263600,"hc":-10.5,"name":"Brengle"},{"status":"ACTIVE","sortPriority":4,"id":3611581,"hc":10.5,"name":"Voegele"},{"status":"ACTIVE","sortPriority":5,"id":2263600,"hc":-9.5,"name":"Brengle"},{"status":"ACTIVE","sortPriority":6,"id":3611581,"hc":9.5,"name":"Voegele"},{"status":"ACTIVE","sortPriority":7,"id":2263600,"hc":-8.5,"name":"Brengle"},{"status":"ACTIVE","sortPriority":8,"id":3611581,"hc":8.5,"name":"Voegele"},{"status":"ACTIVE","sortPriority":9,"id":2263600,"hc":-7.5,"name":"Brengle"},{"status":"ACTIVE","sortPriority":10,"id":3611581,"hc":7.5,"name":"Voegele"},{"status":"ACTIVE","sortPriority":11,"id":2263600,"hc":-6.5,"name":"Brengle"},{"status":"ACTIVE","sortPriority":12,"id":3611581,"hc":6.5,"name":"Voegele"},{"status":"ACTIVE","sortPriority":13,"id":2263600,"hc":-5.5,"name":"Brengle"},{"status":"ACTIVE","sortPriority":14,"id":3611581,"hc":5.5,"name":"Voegele"},{"status":"ACTIVE","sortPriority":15,"id":2263600,"hc":-4.5,"name":"Brengle"},{"status":"ACTIVE","sortPriority":16,"id":3611581,"hc":4.5,"name":"Voegele"},{"status":"ACTIVE","sortPriority":17,"id":2263600,"hc":-3.5,"name":"Brengle"},{"status":"ACTIVE","sortPriority":18,"id":3611581,"hc":3.5,"name":"Voegele"},{"status":"ACTIVE","sortPriority":19,"id":2263600,"hc":-2.5,"name":"Brengle"},{"status":"ACTIVE","sortPriority":20,"id":3611581,"hc":2.5,"name":"Voegele"},{"status":"ACTIVE","sortPriority":21,"id":2263600,"hc":-1.5,"name":"Brengle"},{"status":"ACTIVE","sortPriority":22,"id":3611581,"hc":1.5,"name":"Voegele"},{"status":"ACTIVE","sortPriority":23,"id":2263600,"hc":-0.5,"name":"Brengle"},{"status":"ACTIVE","sortPriority":24,"id":3611581,"hc":0.5,"name":"Voegele"},{"status":"ACTIVE","sortPriority":25,"id":2263600,"hc":0.5,"name":"Brengle"},{"status":"ACTIVE","sortPriority":26,"id":3611581,"hc":-0.5,"name":"Voegele"},{"status":"ACTIVE","sortPriority":27,"id":2263600,"hc":1.5,"name":"Brengle"},{"status":"ACTIVE","sortPriority":28,"id":3611581,"hc":-1.5,"name":"Voegele"},{"status":"ACTIVE","sortPriority":29,"id":2263600,"hc":2.5,"name":"Brengle"},{"status":"ACTIVE","sortPriority":30,"id":3611581,"hc":-2.5,"name":"Voegele"},{"status":"ACTIVE","sortPriority":31,"id":2263600,"hc":3.5,"name":"Brengle"},{"status":"ACTIVE","sortPriority":32,"id":3611581,"hc":-3.5,"name":"Voegele"},{"status":"ACTIVE","sortPriority":33,"id":2263600,"hc":4.5,"name":"Brengle"},{"status":"ACTIVE","sortPriority":34,"id":3611581,"hc":-4.5,"name":"Voegele"},{"status":"ACTIVE","sortPriority":35,"id":2263600,"hc":5.5,"name":"Brengle"},{"status":"ACTIVE","sortPriority":36,"id":3611581,"hc":-5.5,"name":"Voegele"},{"status":"ACTIVE","sortPriority":37,"id":2263600,"hc":6.5,"name":"Brengle"},{"status":"ACTIVE","sortPriority":38,"id":3611581,"hc":-6.5,"name":"Voegele"},{"status":"ACTIVE","sortPriority":39,"id":2263600,"hc":7.5,"name":"Brengle"},{"status":"ACTIVE","sortPriority":40,"id":3611581,"hc":-7.5,"name":"Voegele"},{"status":"ACTIVE","sortPriority":41,"id":2263600,"hc":8.5,"name":"Brengle"},{"status":"ACTIVE","sortPriority":42,"id":3611581,"hc":-8.5,"name":"Voegele"},{"status":"ACTIVE","sortPriority":43,"id":2263600,"hc":9.5,"name":"Brengle"},{"status":"ACTIVE","sortPriority":44,"id":3611581,"hc":-9.5,"name":"Voegele"},{"status":"ACTIVE","sortPriority":45,"id":2263600,"hc":10.5,"name":"Brengle"},{"status":"ACTIVE","sortPriority":46,"id":3611581,"hc":-10.5,"name":"Voegele"},{"status":"ACTIVE","sortPriority":47,"id":2263600,"hc":11.5,"name":"Brengle"},{"status":"ACTIVE","sortPriority":48,"id":3611581,"hc":-11.5,"name":"Voegele"}],"regulators":["MR_INT"],"discountAllowed":true,"timezone":"UTC","openDate":"2020-02-02T18:00:00.000Z","version":3147399796,"name":"Handicap","eventName":"Brengle v Voegele"},"rc":[{"batb":[[0,1.7,101.42]],"ltp":0.0,"tv":0.0,"id":3611581,"hc":0.5},{"batb":[[0,1.67,103.96]],"ltp":0.0,"tv":0.0,"id":2263600,"hc":-0.5}]}]}
{"op":"mcm","clk":"1003948003","pt":1580616835720,"mc":[{"id":"1.168230817","marketDefinition":{"bspMarket":false,"turnInPlayEnabled":true,"persistenceEnabled":true,"marketBaseRate":5.0,"eventId":"29681775","eventTypeId":"2","numberOfWinners":0,"bettingType":"ASIAN_HANDICAP_DOUBLE_LINE","marketType":"HANDICAP","marketTime":"2020-02-02T18:00:00.000Z","suspendTime":"2020-02-02T18:00:00.000Z","bspReconciled":false,"complete":true,"inPlay":false,"crossMatching":false,"runnersVoidable":false,"numberOfActiveRunners":48,"betDelay":0,"status":"OPEN","runners":[{"status":"ACTIVE","sortPriority":1,"id":2263600,"hc":-11.5,"name":"Brengle"},{"status":"ACTIVE","sortPriority":2,"id":3611581,"hc":11.5,"name":"Voegele"},{"status":"ACTIVE","sortPriority":3,"id":2263600,"hc":-10.5,"name":"Brengle"},{"status":"ACTIVE","sortPriority":4,"id":3611581,"hc":10.5,"name":"Voegele"},{"status":"ACTIVE","sortPriority":5,"id":2263600,"hc":-9.5,"name":"Brengle"},{"status":"ACTIVE","sortPriority":6,"id":3611581,"hc":9.5,"name":"Voegele"},{"status":"ACTIVE","sortPriority":7,"id":2263600,"hc":-8.5,"name":"Brengle"},{"status":"ACTIVE","sortPriority":8,"id":3611581,"hc":8.5,"name":"Voegele"},{"status":"ACTIVE","sortPriority":9,"id":2263600,"hc":-7.5,"name":"Brengle"},{"status":"ACTIVE","sortPriority":10,"id":3611581,"hc":7.5,"name":"Voegele"},{"status":"ACTIVE","sortPriority":11,"id":2263600,"hc":-6.5,"name":"Brengle"},{"status":"ACTIVE","sortPriority":12,"id":3611581,"hc":6.5,"name":"Voegele"},{"status":"ACTIVE","sortPriority":13,"id":2263600,"hc":-5.5,"name":"Brengle"},{"status":"ACTIVE","sortPriority":14,"id":3611581,"hc":5.5,"name":"Voegele"},{"status":"ACTIVE","sortPriority":15,"id":2263600,"hc":-4.5,"name":"Brengle"},{"status":"ACTIVE","sortPriority":16,"id":3611581,"hc":4.5,"name":"Voegele"},{"status":"ACTIVE","sortPriority":17,"id":2263600,"hc":-3.5,"name":"Brengle"},{"status":"ACTIVE","sortPriority":18,"id":3611581,"hc":3.5,"name":"Voegele"},{"status":"ACTIVE","sortPriority":19,"id":2263600,"hc":-2.5,"name":"Brengle"},{"status":"ACTIVE","sortPriority":20,"id":3611581,"hc":2.5,"name":"Voegele"},{"status":"ACTIVE","sortPriority":21,"id":2263600,"hc":-1.5,"name":"Brengle"},{"status":"ACTIVE","sortPriority":22,"id":3611581,"hc":1.5,"name":"Voegele"},{"status":"ACTIVE","sortPriority":23,"id":2263600,"hc":-0.5,"name":"Brengle"},{"status":"ACTIVE","sortPriority":24,"id":3611581,"hc":0.5,"name":"Voegele"},{"status":"ACTIVE","sortPriority":25,"id":2263600,"hc":0.5,"name":"Brengle"},{"status":"ACTIVE","sortPriority":26,"id":3611581,"hc":-0.5,"name":"Voegele"},{"status":"ACTIVE","sortPriority":27,"id":2263600,"hc":1.5,"name":"Brengle"},{"status":"ACTIVE","sortPriority":28,"id":3611581,"hc":-1.5,"name":"Voegele"},{"status":"ACTIVE","sortPriority":29,"id":2263600,"hc":2.5,"name":"Brengle"},{"status":"ACTIVE","sortPriority":30,"id":3611581,"hc":-2.5,"name":"Voegele"},{"status":"ACTIVE","sortPriority":31,"id":2263600,"hc":3.5,"name":"Brengle"},{"status":"ACTIVE","sortPriority":32,"id":3611581,"hc":-3.5,"name":"Voegele"},{"status":"ACTIVE","sortPriority":33,"id":2263600,"hc":4.5,"name":"Brengle"},{"status":"ACTIVE","sortPriority":34,"id":3611581,"hc":-4.5,"name":"Voegele"},{"status":"ACTIVE","sortPriority":35,"id":2263600,"hc":5.5,"name":"Brengle"},{"status":"ACTIVE","sortPriority":36,"id":3611581,"hc":-5.5,"name":"Voegele"},{"status":"ACTIVE","sortPriority":37,"id":2263600,"hc":6.5,"name":"Brengle"},{"status":"ACTIVE","sortPriority":38,"id":3611581,"hc":-6.5,"name":"Voegele"},{"status":"ACTIVE","sortPriority":39,"id":2263600,"hc":7.5,"name":"Brengle"},{"status":"ACTIVE","sortPriority":40,"id":3611581,"hc":-7.5,"name":"Voegele"},{"status":"ACTIVE","sortPriority":41,"id":2263600,"hc":8.5,"name":"Brengle"},{"status":"ACTIVE","sortPriority":42,"id":3611581,"hc":-8.5,"name":"Voegele"},{"status":"ACTIVE","sortPriority":43,"id":2263600,"hc":9.5,"name":"Brengle"},{"status":"ACTIVE","sortPriority":44,"id":3611581,"hc":-9.5,"name":"Voegele"},{"status":"ACTIVE","sortPriority":45,"id":2263600,"hc":10.5,"name":"Brengle"},{"status":"ACTIVE","sortPriority":46,"id":3611581,"hc":-10.5,"name":"Voegele"},{"status":"ACTIVE","sortPriority":47,"id":2263600,"hc":11.5,"name":"Brengle"},{"status":"ACTIVE","sortPriority":48,"id":3611581,"hc":-11.5,"name":"Voegele"}],"regulators":["MR_INT"],"discountAllowed":true,"timezone":"UTC","openDate":"2020-02-02T18:00:00.000Z","version":3147399796,"name":"Handicap","eventName":"Brengle v Voegele"}}]}
{"op":"mcm","clk":"1004212489","pt":1580623330342,"mc":[{"id":"1.168230817","marketDefinition":{"bspMarket":false,"turnInPlayEnabled":true,"persistenceEnabled":true,"marketBaseRate":5.0,"eventId":"29681775","eventTypeId":"2","numberOfWinners":0,"bettingType":"ASIAN_HANDICAP_DOUBLE_LINE","marketType":"HANDICAP","marketTime":"2020-02-02T18:00:00.000Z","suspendTime":"2020-02-02T18:00:00.000Z","bspReconciled":false,"complete":true,"inPlay":false,"crossMatching":false,"runnersVoidable":false,"numberOfActiveRunners":48,"betDelay":0,"status":"OPEN","runners":[{"status":"ACTIVE","sortPriority":1,"id":2263600,"hc":-11.5,"name":"Brengle"},{"status":"ACTIVE","sortPriority":2,"id":3611581,"hc":11.5,"name":"Voegele"},{"status":"ACTIVE","sortPriority":3,"id":2263600,"hc":-10.5,"name":"Brengle"},{"status":"ACTIVE","sortPriority":4,"id":3611581,"hc":10.5,"name":"Voegele"},{"status":"ACTIVE","sortPriority":5,"id":2263600,"hc":-9.5,"name":"Brengle"},{"status":"ACTIVE","sortPriority":6,"id":3611581,"hc":9.5,"name":"Voegele"},{"status":"ACTIVE","sortPriority":7,"id":2263600,"hc":-8.5,"name":"Brengle"},{"status":"ACTIVE","sortPriority":8,"id":3611581,"hc":8.5,"name":"Voegele"},{"status":"ACTIVE","sortPriority":9,"id":2263600,"hc":-7.5,"name":"Brengle"},{"status":"ACTIVE","sortPriority":10,"id":3611581,"hc":7.5,"name":"Voegele"},{"status":"ACTIVE","sortPriority":11,"id":2263600,"hc":-6.5,"name":"Brengle"},{"status":"ACTIVE","sortPriority":12,"id":3611581,"hc":6.5,"name":"Voegele"},{"status":"ACTIVE","sortPriority":13,"id":2263600,"hc":-5.5,"name":"Brengle"},{"status":"ACTIVE","sortPriority":14,"id":3611581,"hc":5.5,"name":"Voegele"},{"status":"ACTIVE","sortPriority":15,"id":2263600,"hc":-4.5,"name":"Brengle"},{"status":"ACTIVE","sortPriority":16,"id":3611581,"hc":4.5,"name":"Voegele"},{"status":"ACTIVE","sortPriority":17,"id":2263600,"hc":-3.5,"name":"Brengle"},{"status":"ACTIVE","sortPriority":18,"id":3611581,"hc":3.5,"name":"Voegele"},{"status":"ACTIVE","sortPriority":19,"id":2263600,"hc":-2.5,"name":"Brengle"},{"status":"ACTIVE","sortPriority":20,"id":3611581,"hc":2.5,"name":"Voegele"},{"status":"ACTIVE","sortPriority":21,"id":2263600,"hc":-1.5,"name":"Brengle"},{"status":"ACTIVE","sortPriority":22,"id":3611581,"hc":1.5,"name":"Voegele"},{"status":"ACTIVE","sortPriority":23,"id":2263600,"hc":-0.5,"name":"Brengle"},{"status":"ACTIVE","sortPriority":24,"id":3611581,"hc":0.5,"name":"Voegele"},{"status":"ACTIVE","sortPriority":25,"id":2263600,"hc":0.5,"name":"Brengle"},{"status":"ACTIVE","sortPriority":26,"id":3611581,"hc":-0.5,"name":"Voegele"},{"status":"ACTIVE","sortPriority":27,"id":2263600,"hc":1.5,"name":"Brengle"},{"status":"ACTIVE","sortPriority":28,"id":3611581,"hc":-1.5,"name":"Voegele"},{"status":"ACTIVE","sortPriority":29,"id":2263600,"hc":2.5,"name":"Brengle"},{"status":"ACTIVE","sortPriority":30,"id":3611581,"hc":-2.5,"name":"Voegele"},{"status":"ACTIVE","sortPriority":31,"id":2263600,"hc":3.5,"name":"Brengle"},{"status":"ACTIVE","sortPriority":32,"id":3611581,"hc":-3.5,"name":"Voegele"},{"status":"ACTIVE","sortPriority":33,"id":2263600,"hc":4.5,"name":"Brengle"},{"status":"ACTIVE","sortPriority":34,"id":3611581,"hc":-4.5,"name":"Voegele"},{"status":"ACTIVE","sortPriority":35,"id":2263600,"hc":5.5,"name":"Brengle"},{"status":"ACTIVE","sortPriority":36,"id":3611581,"hc":-5.5,"name":"Voegele"},{"status":"ACTIVE","sortPriority":37,"id":2263600,"hc":6.5,"name":"Brengle"},{"status":"ACTIVE","sortPriority":38,"id":3611581,"hc":-6.5,"name":"Voegele"},{"status":"ACTIVE","sortPriority":39,"id":2263600,"hc":7.5,"name":"Brengle"},{"status":"ACTIVE","sortPriority":40,"id":3611581,"hc":-7.5,"name":"Voegele"},{"status":"ACTIVE","sortPriority":41,"id":2263600,"hc":8.5,"name":"Brengle"},{"status":"ACTIVE","sortPriority":42,"id":3611581,"hc":-8.5,"name":"Voegele"},{"status":"ACTIVE","sortPriority":43,"id":2263600,"hc":9.5,"name":"Brengle"},{"status":"ACTIVE","sortPriority":44,"id":3611581,"hc":-9.5,"name":"Voegele"},{"status":"ACTIVE","sortPriority":45,"id":2263600,"hc":10.5,"name":"Brengle"},{"status":"ACTIVE","sortPriority":46,"id":3611581,"hc":-10.5,"name":"Voegele"},{"status":"ACTIVE","sortPriority":47,"id":2263600,"hc":11.5,"name":"Brengle"},{"status":"ACTIVE","sortPriority":48,"id":3611581,"hc":-11.5,"name":"Voegele"}],"regulators":["MR_INT"],"discountAllowed":true,"timezone":"UTC","openDate":"2020-02-02T18:00:00.000Z","version":3147399796,"name":"Handicap","eventName":"Brengle v Voegele"},"rc":[{"batl":[[0,2.1,115.75]],"ltp":0.0,"tv":0.0,"id":3611581,"hc":1.5},{"batl":[[0,2.62,101.46]],"ltp":0.0,"tv":0.0,"id":2263600,"hc":-1.5},{"batb":[[0,1.7,143.22]],"ltp":0.0,"tv":0.0,"id":3611581,"hc":0.5},{"batb":[[0,1.74,140.79]],"ltp":0.0,"tv":0.0,"id":2263600,"hc":-0.5}]}]}
{"op":"mcm","clk":"1004214524","pt":1580623392533,"mc":[{"id":"1.168230817","rc":[{"batb":[[0,1.69,54.87]],"ltp":0.0,"tv":0.0,"id":3611581,"hc":1.5},{"batb":[[0,1.93,40.71]],"ltp":0.0,"tv":0.0,"id":2263600,"hc":-1.5},{"batb":[[0,1.82,46.18],[1,1.7,143.22]],"ltp":0.0,"tv":0.0,"id":3611581,"hc":0.5},{"batb":[[0,1.81,46.74],[1,1.74,140.79]],"ltp":0.0,"tv":0.0,"id":2263600,"hc":-0.5}]}]}
{"op":"mcm","clk":"1004214537","pt":1580623392838,"mc":[{"id":"1.168230817","rc":[{"batb":[[0,1.72,154.59],[1,1.69,54.87]],"ltp":0.0,"tv":0.0,"id":3611581,"hc":1.5},{"batb":[[0,1.97,123.51],[1,1.93,40.71]],"ltp":0.0,"tv":0.0,"id":2263600,"hc":-1.5},{"batb":[[0,1.84,132.22],[1,1.82,46.18]],"ltp":0.0,"tv":0.0,"id":3611581,"hc":0.5},{"batb":[[0,1.85,132.17],[1,1.81,46.74]],"ltp":0.0,"tv":0.0,"id":2263600,"hc":-0.5}]}]}
{"op":"mcm","clk":"1004323026","pt":1580626931177,"mc":[{"id":"1.168230817","rc":[{"batb":[[0,1.69,54.87],[1,1.69,0]],"ltp":0.0,"tv":0.0,"id":3611581,"hc":1.5},{"batb":[[0,1.93,40.71],[1,1.93,0]],"ltp":0.0,"tv":0.0,"id":2263600,"hc":-1.5},{"batb":[[0,1.82,46.18],[1,1.82,0]],"ltp":0.0,"tv":0.0,"id":3611581,"hc":0.5},{"batb":[[0,1.81,46.74],[1,1.81,0]],"ltp":0.0,"tv":0.0,"id":2263600,"hc":-0.5}]}]}
{"op":"mcm","clk":"1004336986","pt":1580627362510,"mc":[{"id":"1.168230817","rc":[{"batb":[[0,1.72,152.59],[1,1.69,54.87]],"ltp":0.0,"tv":0.0,"id":3611581,"hc":1.5},{"batb":[[0,1.94,123.59],[1,1.93,40.71]],"ltp":0.0,"tv":0.0,"id":2263600,"hc":-1.5},{"batb":[[0,1.89,126.96],[1,1.82,46.18]],"ltp":0.0,"tv":0.0,"id":3611581,"hc":0.5},{"batb":[[0,1.83,140.68],[1,1.81,46.74]],"ltp":0.0,"tv":0.0,"id":2263600,"hc":-0.5}]}]}
{"op":"mcm","clk":"1004337092","pt":1580627365452,"mc":[{"id":"1.168230817","rc":[{"batb":[[1,1.69,0]],"ltp":0.0,"tv":0.0,"id":3611581,"hc":1.5},{"batb":[[1,1.93,0]],"ltp":0.0,"tv":0.0,"id":2263600,"hc":-1.5},{"batb":[[1,1.82,0]],"ltp":0.0,"tv":0.0,"id":3611581,"hc":0.5},{"batb":[[1,1.81,0]],"ltp":0.0,"tv":0.0,"id":2263600,"hc":-0.5}]}]}
{"op":"mcm","clk":"1004337130","pt":1580627366123,"mc":[{"id":"1.168230817","rc":[{"batb":[[1,1.71,53.32]],"ltp":0.0,"tv":0.0,"id":3611581,"hc":1.5},{"batb":[[1,1.9,42.07]],"ltp":0.0,"tv":0.0,"id":2263600,"hc":-1.5},{"batb":[[1,1.84,45.07]],"ltp":0.0,"tv":0.0,"id":3611581,"hc":0.5},{"batb":[[1,1.79,47.93]],"ltp":0.0,"tv":0.0,"id":2263600,"hc":-0.5}]}]}
{"op":"mcm","clk":"1004338265","pt":1580627399377,"mc":[{"id":"1.168230817","rc":[{"batb":[[0,1.71,53.32],[1,1.71,0]],"ltp":0.0,"tv":0.0,"id":3611581,"hc":1.5},{"batb":[[0,1.9,42.07],[1,1.9,0]],"ltp":0.0,"tv":0.0,"id":2263600,"hc":-1.5},{"batb":[[0,1.84,45.07],[1,1.84,0]],"ltp":0.0,"tv":0.0,"id":3611581,"hc":0.5}]}]}
{"op":"mcm","clk":"1004338696","pt":1580627410407,"mc":[{"id":"1.168230817","marketDefinition":{"bspMarket":false,"turnInPlayEnabled":true,"persistenceEnabled":true,"marketBaseRate":5.0,"eventId":"29681775","eventTypeId":"2","numberOfWinners":0,"bettingType":"ASIAN_HANDICAP_DOUBLE_LINE","marketType":"HANDICAP","marketTime":"2020-02-02T18:00:00.000Z","suspendTime":"2020-02-02T18:00:00.000Z","bspReconciled":false,"complete":true,"inPlay":false,"crossMatching":false,"runnersVoidable":false,"numberOfActiveRunners":48,"betDelay":0,"status":"OPEN","runners":[{"status":"ACTIVE","sortPriority":1,"id":2263600,"hc":-11.5,"name":"Brengle"},{"status":"ACTIVE","sortPriority":2,"id":3611581,"hc":11.5,"name":"Voegele"},{"status":"ACTIVE","sortPriority":3,"id":2263600,"hc":-10.5,"name":"Brengle"},{"status":"ACTIVE","sortPriority":4,"id":3611581,"hc":10.5,"name":"Voegele"},{"status":"ACTIVE","sortPriority":5,"id":2263600,"hc":-9.5,"name":"Brengle"},{"status":"ACTIVE","sortPriority":6,"id":3611581,"hc":9.5,"name":"Voegele"},{"status":"ACTIVE","sortPriority":7,"id":2263600,"hc":-8.5,"name":"Brengle"},{"status":"ACTIVE","sortPriority":8,"id":3611581,"hc":8.5,"name":"Voegele"},{"status":"ACTIVE","sortPriority":9,"id":2263600,"hc":-7.5,"name":"Brengle"},{"status":"ACTIVE","sortPriority":10,"id":3611581,"hc":7.5,"name":"Voegele"},{"status":"ACTIVE","sortPriority":11,"id":2263600,"hc":-6.5,"name":"Brengle"},{"status":"ACTIVE","sortPriority":12,"id":3611581,"hc":6.5,"name":"Voegele"},{"status":"ACTIVE","sortPriority":13,"id":2263600,"hc":-5.5,"name":"Brengle"},{"status":"ACTIVE","sortPriority":14,"id":3611581,"hc":5.5,"name":"Voegele"},{"status":"ACTIVE","sortPriority":15,"id":2263600,"hc":-4.5,"name":"Brengle"},{"status":"ACTIVE","sortPriority":16,"id":3611581,"hc":4.5,"name":"Voegele"},{"status":"ACTIVE","sortPriority":17,"id":2263600,"hc":-3.5,"name":"Brengle"},{"status":"ACTIVE","sortPriority":18,"id":3611581,"hc":3.5,"name":"Voegele"},{"status":"ACTIVE","sortPriority":19,"id":2263600,"hc":-2.5,"name":"Brengle"},{"status":"ACTIVE","sortPriority":20,"id":3611581,"hc":2.5,"name":"Voegele"},{"status":"ACTIVE","sortPriority":21,"id":2263600,"hc":-1.5,"name":"Brengle"},{"status":"ACTIVE","sortPriority":22,"id":3611581,"hc":1.5,"name":"Voegele"},{"status":"ACTIVE","sortPriority":23,"id":2263600,"hc":-0.5,"name":"Brengle"},{"status":"ACTIVE","sortPriority":24,"id":3611581,"hc":0.5,"name":"Voegele"},{"status":"ACTIVE","sortPriority":25,"id":2263600,"hc":0.5,"name":"Brengle"},{"status":"ACTIVE","sortPriority":26,"id":3611581,"hc":-0.5,"name":"Voegele"},{"status":"ACTIVE","sortPriority":27,"id":2263600,"hc":1.5,"name":"Brengle"},{"status":"ACTIVE","sortPriority":28,"id":3611581,"hc":-1.5,"name":"Voegele"},{"status":"ACTIVE","sortPriority":29,"id":2263600,"hc":2.5,"name":"Brengle"},{"status":"ACTIVE","sortPriority":30,"id":3611581,"hc":-2.5,"name":"Voegele"},{"status":"ACTIVE","sortPriority":31,"id":2263600,"hc":3.5,"name":"Brengle"},{"status":"ACTIVE","sortPriority":32,"id":3611581,"hc":-3.5,"name":"Voegele"},{"status":"ACTIVE","sortPriority":33,"id":2263600,"hc":4.5,"name":"Brengle"},{"status":"ACTIVE","sortPriority":34,"id":3611581,"hc":-4.5,"name":"Voegele"},{"status":"ACTIVE","sortPriority":35,"id":2263600,"hc":5.5,"name":"Brengle"},{"status":"ACTIVE","sortPriority":36,"id":3611581,"hc":-5.5,"name":"Voegele"},{"status":"ACTIVE","sortPriority":37,"id":2263600,"hc":6.5,"name":"Brengle"},{"status":"ACTIVE","sortPriority":38,"id":3611581,"hc":-6.5,"name":"Voegele"},{"status":"ACTIVE","sortPriority":39,"id":2263600,"hc":7.5,"name":"Brengle"},{"status":"ACTIVE","sortPriority":40,"id":3611581,"hc":-7.5,"name":"Voegele"},{"status":"ACTIVE","sortPriority":41,"id":2263600,"hc":8.5,"name":"Brengle"},{"status":"ACTIVE","sortPriority":42,"id":3611581,"hc":-8.5,"name":"Voegele"},{"status":"ACTIVE","sortPriority":43,"id":2263600,"hc":9.5,"name":"Brengle"},{"status":"ACTIVE","sortPriority":44,"id":3611581,"hc":-9.5,"name":"Voegele"},{"status":"ACTIVE","sortPriority":45,"id":2263600,"hc":10.5,"name":"Brengle"},{"status":"ACTIVE","sortPriority":46,"id":3611581,"hc":-10.5,"name":"Voegele"},{"status":"ACTIVE","sortPriority":47,"id":2263600,"hc":11.5,"name":"Brengle"},{"status":"ACTIVE","sortPriority":48,"id":3611581,"hc":-11.5,"name":"Voegele"}],"regulators":["MR_INT"],"discountAllowed":true,"timezone":"UTC","openDate":"2020-02-02T18:00:00.000Z","version":3147399796,"name":"Handicap","eventName":"Brengle v Voegele"},"rc":[{"batb":[[1,1.79,0]],"ltp":0.0,"tv":0.0,"id":2263600,"hc":-0.5}]}]}
{"op":"mcm","clk":"1004338749","pt":1580627411596,"mc":[{"id":"1.168230817","marketDefinition":{"bspMarket":false,"turnInPlayEnabled":true,"persistenceEnabled":true,"marketBaseRate":5.0,"eventId":"29681775","eventTypeId":"2","numberOfWinners":0,"bettingType":"ASIAN_HANDICAP_DOUBLE_LINE","marketType":"HANDICAP","marketTime":"2020-02-02T18:00:00.000Z","suspendTime":"2020-02-02T18:00:00.000Z","bspReconciled":false,"complete":true,"inPlay":false,"crossMatching":false,"runnersVoidable":false,"numberOfActiveRunners":48,"betDelay":0,"status":"OPEN","runners":[{"status":"ACTIVE","sortPriority":1,"id":2263600,"hc":-11.5,"name":"Brengle"},{"status":"ACTIVE","sortPriority":2,"id":3611581,"hc":11.5,"name":"Voegele"},{"status":"ACTIVE","sortPriority":3,"id":2263600,"hc":-10.5,"name":"Brengle"},{"status":"ACTIVE","sortPriority":4,"id":3611581,"hc":10.5,"name":"Voegele"},{"status":"ACTIVE","sortPriority":5,"id":2263600,"hc":-9.5,"name":"Brengle"},{"status":"ACTIVE","sortPriority":6,"id":3611581,"hc":9.5,"name":"Voegele"},{"status":"ACTIVE","sortPriority":7,"id":2263600,"hc":-8.5,"name":"Brengle"},{"status":"ACTIVE","sortPriority":8,"id":3611581,"hc":8.5,"name":"Voegele"},{"status":"ACTIVE","sortPriority":9,"id":2263600,"hc":-7.5,"name":"Brengle"},{"status":"ACTIVE","sortPriority":10,"id":3611581,"hc":7.5,"name":"Voegele"},{"status":"ACTIVE","sortPriority":11,"id":2263600,"hc":-6.5,"name":"Brengle"},{"status":"ACTIVE","sortPriority":12,"id":3611581,"hc":6.5,"name":"Voegele"},{"status":"ACTIVE","sortPriority":13,"id":2263600,"hc":-5.5,"name":"Brengle"},{"status":"ACTIVE","sortPriority":14,"id":3611581,"hc":5.5,"name":"Voegele"},{"status":"ACTIVE","sortPriority":15,"id":2263600,"hc":-4.5,"name":"Brengle"},{"status":"ACTIVE","sortPriority":16,"id":3611581,"hc":4.5,"name":"Voegele"},{"status":"ACTIVE","sortPriority":17,"id":2263600,"hc":-3.5,"name":"Brengle"},{"status":"ACTIVE","sortPriority":18,"id":3611581,"hc":3.5,"name":"Voegele"},{"status":"ACTIVE","sortPriority":19,"id":2263600,"hc":-2.5,"name":"Brengle"},{"status":"ACTIVE","sortPriority":20,"id":3611581,"hc":2.5,"name":"Voegele"},{"status":"ACTIVE","sortPriority":21,"id":2263600,"hc":-1.5,"name":"Brengle"},{"status":"ACTIVE","sortPriority":22,"id":3611581,"hc":1.5,"name":"Voegele"},{"status":"ACTIVE","sortPriority":23,"id":2263600,"hc":-0.5,"name":"Brengle"},{"status":"ACTIVE","sortPriority":24,"id":3611581,"hc":0.5,"name":"Voegele"},{"status":"ACTIVE","sortPriority":25,"id":2263600,"hc":0.5,"name":"Brengle"},{"status":"ACTIVE","sortPriority":26,"id":3611581,"hc":-0.5,"name":"Voegele"},{"status":"ACTIVE","sortPriority":27,"id":2263600,"hc":1.5,"name":"Brengle"},{"status":"ACTIVE","sortPriority":28,"id":3611581,"hc":-1.5,"name":"Voegele"},{"status":"ACTIVE","sortPriority":29,"id":2263600,"hc":2.5,"name":"Brengle"},{"status":"ACTIVE","sortPriority":30,"id":3611581,"hc":-2.5,"name":"Voegele"},{"status":"ACTIVE","sortPriority":31,"id":2263600,"hc":3.5,"name":"Brengle"},{"status":"ACTIVE","sortPriority":32,"id":3611581,"hc":-3.5,"name":"Voegele"},{"status":"ACTIVE","sortPriority":33,"id":2263600,"hc":4.5,"name":"Brengle"},{"status":"ACTIVE","sortPriority":34,"id":3611581,"hc":-4.5,"name":"Voegele"},{"status":"ACTIVE","sortPriority":35,"id":2263600,"hc":5.5,"name":"Brengle"},{"status":"ACTIVE","sortPriority":36,"id":3611581,"hc":-5.5,"name":"Voegele"},{"status":"ACTIVE","sortPriority":37,"id":2263600,"hc":6.5,"name":"Brengle"},{"status":"ACTIVE","sortPriority":38,"id":3611581,"hc":-6.5,"name":"Voegele"},{"status":"ACTIVE","sortPriority":39,"id":2263600,"hc":7.5,"name":"Brengle"},{"status":"ACTIVE","sortPriority":40,"id":3611581,"hc":-7.5,"name":"Voegele"},{"status":"ACTIVE","sortPriority":41,"id":2263600,"hc":8.5,"name":"Brengle"},{"status":"ACTIVE","sortPriority":42,"id":3611581,"hc":-8.5,"name":"Voegele"},{"status":"ACTIVE","sortPriority":43,"id":2263600,"hc":9.5,"name":"Brengle"},{"status":"ACTIVE","sortPriority":44,"id":3611581,"hc":-9.5,"name":"Voegele"},{"status":"ACTIVE","sortPriority":45,"id":2263600,"hc":10.5,"name":"Brengle"},{"status":"ACTIVE","sortPriority":46,"id":3611581,"hc":-10.5,"name":"Voegele"},{"status":"ACTIVE","sortPriority":47,"id":2263600,"hc":11.5,"name":"Brengle"},{"status":"ACTIVE","sortPriority":48,"id":3611581,"hc":-11.5,"name":"Voegele"}],"regulators":["MR_INT"],"discountAllowed":true,"timezone":"UTC","openDate":"2020-02-02T18:00:00.000Z","version":3147399796,"name":"Handicap","eventName":"Brengle v Voegele"},"rc":[{"batb":[[0,1.75,241.27],[1,1.74,51.17]],"ltp":0.0,"tv":0.0,"id":3611581,"hc":1.5},{"batb":[[0,1.92,123.44],[1,1.88,43.03]],"ltp":0.0,"tv":0.0,"id":2263600,"hc":-1.5},{"batb":[[0,1.83,45.62]],"ltp":0.0,"tv":0.0,"id":3611581,"hc":0.5},{"batb":[[1,1.8,47.33]],"ltp":0.0,"tv":0.0,"id":2263600,"hc":-0.5}]}]}
{"op":"mcm","clk":"1004338790","pt":1580627412576,"mc":[{"id":"1.168230817","rc":[{"batb":[[0,1.85,51.97],[1,1.83,45.62]],"ltp":0.0,"tv":0.0,"id":3611581,"hc":0.5}]}]}
{"op":"mcm","clk":"1004375336","pt":1580628320986,"mc":[{"id":"1.168230817","rc":[{"batb":[[0,1.86,129.68]],"ltp":0.0,"tv":0.0,"id":3611581,"hc":0.5}]}]}
{"op":"mcm","clk":"1004490913","pt":1580631011336,"mc":[{"id":"1.168230817","rc":[{"batb":[[0,1.74,51.17],[1,1.74,0]],"ltp":0.0,"tv":0.0,"id":3611581,"hc":1.5},{"batb":[[0,1.88,43.03],[1,1.88,0]],"ltp":0.0,"tv":0.0,"id":2263600,"hc":-1.5}]}]}
{"op":"mcm","clk":"1004493790","pt":1580631071555,"mc":[{"id":"1.168230817","rc":[{"batb":[[0,1.8,142.38],[1,1.74,51.17]],"ltp":0.0,"tv":0.0,"id":3611581,"hc":1.5},{"batb":[[0,1.94,124.92],[1,1.88,43.03]],"ltp":0.0,"tv":0.0,"id":2263600,"hc":-1.5},{"batl":[[0,2.5,102.99]],"ltp":0.0,"tv":0.0,"id":3611581,"hc":-0.5},{"batl":[[0,2.34,109.99]],"ltp":0.0,"tv":0.0,"id":2263600,"hc":0.5}]}]}
{"op":"mcm","clk":"1004498454","pt":1580631177504,"mc":[{"id":"1.168230817","rc":[{"batb":[[0,1.75,149.15]],"ltp":0.0,"tv":0.0,"id":3611581,"hc":1.5}]}]}
{"op":"mcm","clk":"1004498655","pt":1580631181472,"mc":[{"id":"1.168230817","rc":[{"batb":[[1,1.71,53.32]],"ltp":0.0,"tv":0.0,"id":3611581,"hc":1.5},{"batb":[[1,1.91,41.61]],"ltp":0.0,"tv":0.0,"id":2263600,"hc":-1.5},{"batb":[[1,1.81,46.74]],"ltp":0.0,"tv":0.0,"id":3611581,"hc":0.5},{"batb":[[0,1.83,186.3],[1,1.8,0]],"ltp":0.0,"tv":0.0,"id":2263600,"hc":-0.5}]}]}
{"op":"mcm","clk":"1004530958","pt":1580631920962,"mc":[{"id":"1.168230817","rc":[{"batb":[[0,1.81,46.74],[1,1.81,0]],"ltp":0.0,"tv":0.0,"id":3611581,"hc":0.5}]}]}
{"op":"mcm","clk":"1004627427","pt":1580634014442,"mc":[{"id":"1.168230817","rc":[{"batb":[[0,1.82,134.53],[1,1.81,46.74]],"ltp":0.0,"tv":0.0,"id":3611581,"hc":0.5}]}]}
{"op":"mcm","clk":"1004631530","pt":1580634080551,"mc":[{"id":"1.168230817","rc":[{"batb":[[0,1.94,132.59]],"ltp":0.0,"tv":0.0,"id":2263600,"hc":-1.5}]}]}
{"op":"mcm","clk":"1004640164","pt":1580634262591,"mc":[{"id":"1.168230817","rc":[{"batb":[[0,1.75,223.87]],"ltp":0.0,"tv":0.0,"id":3611581,"hc":1.5},{"batb":[[0,1.82,201.64]],"ltp":0.0,"tv":0.0,"id":3611581,"hc":0.5}]}]}
{"op":"mcm","clk":"1004654332","pt":1580634562984,"mc":[{"id":"1.168230817","rc":[{"batb":[[0,1.84,196.72],[1,1.83,45.62]],"ltp":0.0,"tv":0.0,"id":2263600,"hc":-0.5}]}]}
{"op":"mcm","clk":"1004659022","pt":1580634672642,"mc":[{"id":"1.168230817","rc":[{"batb":[[0,1.74,225.29]],"ltp":0.0,"tv":0.0,"id":3611581,"hc":1.5},{"batb":[[0,1.95,184.51]],"ltp":0.0,"tv":0.0,"id":2263600,"hc":-1.5},{"batl":[[0,2.52,102.26]],"ltp":0.0,"tv":0.0,"id":3611581,"hc":-0.5}]}]}
{"op":"mcm","clk":"1004802021","pt":1580637614404,"mc":[{"id":"1.168230817","rc":[{"batb":[[0,1.81,46.74],[1,1.81,0]],"ltp":0.0,"tv":0.0,"id":3611581,"hc":0.5}]}]}
{"op":"mcm","clk":"1004839571","pt":1580638163636,"mc":[{"id":"1.168230817","rc":[{"batb":[[0,1.85,198.37],[1,1.81,46.74]],"ltp":0.0,"tv":0.0,"id":3611581,"hc":0.5}]}]}
{"op":"mcm","clk":"1004847152","pt":1580638272632,"mc":[{"id":"1.168230817","rc":[{"batb":[[0,1.71,53.32],[1,1.71,0]],"ltp":0.0,"tv":0.0,"id":3611581,"hc":1.5},{"batl":[[0,2.26,114.02]],"ltp":0.0,"tv":0.0,"id":2263600,"hc":0.5}]}]}
{"op":"mcm","clk":"1004847161","pt":1580638272687,"mc":[{"id":"1.168230817","rc":[{"batb":[[0,1.91,41.61],[1,1.91,0]],"ltp":0.0,"tv":0.0,"id":2263600,"hc":-1.5}]}]}
{"op":"mcm","clk":"1004951669","pt":1580639430020,"mc":[{"id":"1.168230817","rc":[{"batb":[[0,1.73,227.65],[1,1.71,53.32]],"ltp":0.0,"tv":0.0,"id":3611581,"hc":1.5},{"batb":[[0,1.93,187.36],[1,1.91,41.61]],"ltp":0.0,"tv":0.0,"id":2263600,"hc":-1.5}]}]}
{"op":"mcm","clk":"1004952014","pt":1580639433587,"mc":[{"id":"1.168230817","rc":[{"batb":[[1,1.72,78.88]],"ltp":0.0,"tv":0.0,"id":3611581,"hc":1.5},{"batb":[[0,1.93,248.43],[1,1.91,0]],"ltp":0.0,"tv":0.0,"id":2263600,"hc":-1.5},{"batb":[[1,1.81,70.11]],"ltp":0.0,"tv":0.0,"id":3611581,"hc":0.5},{"batb":[[0,1.85,66.82],[1,1.83,0]],"ltp":0.0,"tv":0.0,"id":2263600,"hc":-0.5}]}]}
{"op":"mcm","clk":"1004952024","pt":1580639433687,"mc":[{"id":"1.168230817","rc":[{"batb":[[0,1.9,189.36],[1,1.85,66.82]],"ltp":0.0,"tv":0.0,"id":2263600,"hc":-0.5}]}]}
{"op":"mcm","clk":"1004995273","pt":1580639880287,"mc":[{"id":"1.168230817","rc":[{"batb":[[0,1.02,4.99]],"ltp":0.0,"tv":0.0,"id":2263600,"hc":-9.5},{"batb":[[0,1.02,4.99]],"ltp":0.0,"tv":0.0,"id":2263600,"hc":-10.5},{"batb":[[0,1.02,4.99]],"ltp":0.0,"tv":0.0,"id":2263600,"hc":-11.5}]}]}
{"op":"mcm","clk":"1005014887","pt":1580640090303,"mc":[{"id":"1.168230817","rc":[{"batb":[[0,1.02,8.92]],"ltp":0.0,"tv":0.0,"id":2263600,"hc":-11.5}]}]}
{"op":"mcm","clk":"1005015271","pt":1580640094488,"mc":[{"id":"1.168230817","rc":[{"batl":[[0,1000,2.36]],"ltp":0.0,"tv":0.0,"id":2263600,"hc":-11.5}]}]}
{"op":"mcm","clk":"1005015348","pt":1580640095419,"mc":[{"id":"1.168230817","rc":[{"batl":[[0,990,0.01]],"ltp":0.0,"tv":0.0,"id":2263600,"hc":-11.5}]}]}
{"op":"mcm","clk":"1005016133","pt":1580640103625,"mc":[{"id":"1.168230817","rc":[{"batl":[[0,990,0.01]],"ltp":0.0,"tv":0.0,"id":2263600,"hc":-11.5}]}]}
{"op":"mcm","clk":"1005017111","pt":1580640113415,"mc":[{"id":"1.168230817","rc":[{"batl":[[0,1000,2.37]],"ltp":0.0,"tv":0.0,"id":2263600,"hc":-11.5}]}]}
{"op":"mcm","clk":"1005017231","pt":1580640114615,"mc":[{"id":"1.168230817","rc":[{"trd":[[1.02,0.02]],"batb":[[0,1.02,8.91]],"batl":[[0,990,0.01]],"ltp":1.02,"tv":0.01,"id":2263600,"hc":-11.5}],"tv":0.01}]}
{"op":"mcm","clk":"1005017686","pt":1580640118645,"mc":[{"id":"1.168230817","rc":[{"batl":[[0,1000,0.02]],"ltp":1.02,"tv":0.01,"id":2263600,"hc":-11.5}]}]}
{"op":"mcm","clk":"1005017809","pt":1580640119332,"mc":[{"id":"1.168230817","rc":[{"trd":[[1.02,0.03]],"batb":[[0,1.02,8.9]],"batl":[[0,990,0.01]],"ltp":1.02,"tv":0.03,"id":2263600,"hc":-11.5}],"tv":0.03}]}
{"op":"mcm","clk":"1005018318","pt":1580640123548,"mc":[{"id":"1.168230817","rc":[{"trd":[[1.02,0.05]],"batb":[[0,1.02,8.89]],"ltp":1.02,"tv":0.04,"id":2263600,"hc":-11.5}],"tv":0.04}]}
{"op":"mcm","clk":"1005018961","pt":1580640129537,"mc":[{"id":"1.168230817","rc":[{"batl":[[0,1000,0.02]],"ltp":1.02,"tv":0.04,"id":2263600,"hc":-11.5}]}]}
{"op":"mcm","clk":"1005019002","pt":1580640129946,"mc":[{"id":"1.168230817","rc":[{"trd":[[1.02,0.06]],"batb":[[0,1.02,8.88]],"batl":[[0,990,0.01]],"ltp":1.02,"tv":0.06,"id":2263600,"hc":-11.5}],"tv":0.06}]}
{"op":"mcm","clk":"1005019745","pt":1580640135351,"mc":[{"id":"1.168230817","rc":[{"trd":[[1.02,0.08]],"batb":[[0,1.02,8.87]],"ltp":1.02,"tv":0.07,"id":2263600,"hc":-11.5}],"tv":0.07}]}
{"op":"mcm","clk":"1005019997","pt":1580640137451,"mc":[{"id":"1.168230817","rc":[{"batb":[[0,1.02,8.92]],"ltp":0.0,"tv":0.0,"id":2263600,"hc":-10.5}]}]}
{"op":"mcm","clk":"1005020457","pt":1580640141243,"mc":[{"id":"1.168230817","rc":[{"trd":[[1.02,0.09]],"batb":[[0,1.02,8.86]],"ltp":1.02,"tv":0.09,"id":2263600,"hc":-11.5}],"tv":0.09}]}
{"op":"mcm","clk":"1005020597","pt":1580640142544,"mc":[{"id":"1.168230817","rc":[{"batl":[[0,990,0.01]],"ltp":0.0,"tv":0.0,"id":2263600,"hc":-10.5}]}]}
{"op":"mcm","clk":"1005021127","pt":1580640146547,"mc":[{"id":"1.168230817","rc":[{"batl":[[0,1000,0.02]],"ltp":1.02,"tv":0.09,"id":2263600,"hc":-11.5}]}]}
{"op":"mcm","clk":"1005021171","pt":1580640146855,"mc":[{"id":"1.168230817","rc":[{"trd":[[1.02,0.11]],"batb":[[0,1.02,8.85]],"batl":[[0,990,0.01]],"ltp":1.02,"tv":0.1,"id":2263600,"hc":-11.5}],"tv":0.1}]}
{"op":"mcm","clk":"1005021538","pt":1580640149585,"mc":[{"id":"1.168230817","rc":[{"batl":[[0,1000,2.37]],"ltp":0.0,"tv":0.0,"id":2263600,"hc":-10.5}]}]}
{"op":"mcm","clk":"1005021660","pt":1580640150480,"mc":[{"id":"1.168230817","rc":[{"batl":[[0,990,0.01]],"ltp":0.0,"tv":0.0,"id":2263600,"hc":-10.5}]}]}
{"op":"mcm","clk":"1005021785","pt":1580640151368,"mc":[{"id":"1.168230817","rc":[{"batl":[[0,990,0.01]],"ltp":0.0,"tv":0.0,"id":2263600,"hc":-10.5}]}]}
{"op":"mcm","clk":"1005021939","pt":1580640152475,"mc":[{"id":"1.168230817","rc":[{"trd":[[1.02,0.12]],"batb":[[0,1.02,8.84]],"ltp":1.02,"tv":0.12,"id":2263600,"hc":-11.5}],"tv":0.12}]}
{"op":"mcm","clk":"1005022556","pt":1580640157592,"mc":[{"id":"1.168230817","rc":[{"batl":[[0,1000,0.02]],"ltp":1.02,"tv":0.12,"id":2263600,"hc":-11.5}]}]}
{"op":"mcm","clk":"1005022602","pt":1580640157956,"mc":[{"id":"1.168230817","rc":[{"trd":[[1.02,0.14]],"batb":[[0,1.02,8.83]],"batl":[[0,990,0.01]],"ltp":1.02,"tv":0.13,"id":2263600,"hc":-11.5}],"tv":0.13}]}
{"op":"mcm","clk":"1005022771","pt":1580640159572,"mc":[{"id":"1.168230817","rc":[{"trd":[[1.02,0.02]],"batb":[[0,1.02,8.91]],"ltp":1.02,"tv":0.01,"id":2263600,"hc":-10.5}],"tv":0.15}]}
{"op":"mcm","clk":"1005023342","pt":1580640163467,"mc":[{"id":"1.168230817","rc":[{"batl":[[0,1000,0.02]],"ltp":1.02,"tv":0.01,"id":2263600,"hc":-10.5},{"trd":[[1.02,0.16]],"batb":[[0,1.02,8.82]],"ltp":1.02,"tv":0.15,"id":2263600,"hc":-11.5}],"tv":0.17}]}
{"op":"mcm","clk":"1005023380","pt":1580640163783,"mc":[{"id":"1.168230817","rc":[{"trd":[[1.02,0.03]],"batb":[[0,1.02,8.9]],"batl":[[0,990,0.01]],"ltp":1.02,"tv":0.03,"id":2263600,"hc":-10.5}],"tv":0.18}]}
{"op":"mcm","clk":"1005023766","pt":1580640166402,"mc":[{"id":"1.168230817","rc":[{"batl":[[0,1000,0.02]],"ltp":1.02,"tv":0.03,"id":2263600,"hc":-10.5}]}]}
{"op":"mcm","clk":"1005023881","pt":1580640167182,"mc":[{"id":"1.168230817","rc":[{"trd":[[1.02,0.05]],"batb":[[0,1.02,8.89]],"batl":[[0,990,0.01]],"ltp":1.02,"tv":0.04,"id":2263600,"hc":-10.5}],"tv":0.2}]}
{"op":"mcm","clk":"1005024172","pt":1580640169409,"mc":[{"id":"1.168230817","rc":[{"batl":[[0,1000,2.37]],"ltp":1.02,"tv":0.04,"id":2263600,"hc":-10.5},{"trd":[[1.02,0.17]],"batb":[[0,1.02,8.81]],"ltp":1.02,"tv":0.17,"id":2263600,"hc":-11.5}],"tv":0.21}]}
{"op":"mcm","clk":"1005024265","pt":1580640170097,"mc":[{"id":"1.168230817","rc":[{"trd":[[1.02,0.06]],"batb":[[0,1.02,8.88]],"batl":[[0,990,0.01]],"ltp":1.02,"tv":0.06,"id":2263600,"hc":-10.5}],"tv":0.23}]}
{"op":"mcm","clk":"1005024957","pt":1580640174625,"mc":[{"id":"1.168230817","rc":[{"trd":[[1.02,0.19]],"batb":[[0,1.02,8.8]],"ltp":1.02,"tv":0.18,"id":2263600,"hc":-11.5}],"tv":0.24}]}
{"op":"mcm","clk":"1005025129","pt":1580640175617,"mc":[{"id":"1.168230817","rc":[{"batb":[[0,1.02,8.92]],"ltp":0.0,"tv":0.0,"id":2263600,"hc":-9.5},{"trd":[[1.02,0.08]],"batb":[[0,1.02,8.87]],"ltp":1.02,"tv":0.07,"id":2263600,"hc":-10.5}],"tv":0.26}]}
{"op":"mcm","clk":"1005025639","pt":1580640179408,"mc":[{"id":"1.168230817","rc":[{"batl":[[0,990,0.01]],"ltp":0.0,"tv":0.0,"id":2263600,"hc":-9.5},{"batl":[[0,1000,0.02]],"ltp":1.02,"tv":0.18,"id":2263600,"hc":-11.5}]}]}
{"op":"mcm","clk":"1005025810","pt":1580640180606,"mc":[{"id":"1.168230817","rc":[{"batl":[[0,1000,2.37]],"ltp":1.02,"tv":0.07,"id":2263600,"hc":-10.5},{"trd":[[1.02,0.2]],"batb":[[0,1.02,8.79]],"batl":[[0,990,0.01]],"ltp":1.02,"tv":0.2,"id":2263600,"hc":-11.5}],"tv":0.27}]}
{"op":"mcm","clk":"1005025895","pt":1580640181300,"mc":[{"id":"1.168230817","rc":[{"trd":[[1.02,0.09]],"batb":[[0,1.02,8.86]],"batl":[[0,990,0.01]],"ltp":1.02,"tv":0.09,"id":2263600,"hc":-10.5}],"tv":0.29}]}
{"op":"mcm","clk":"1005026531","pt":1580640185597,"mc":[{"id":"1.168230817","rc":[{"batl":[[0,1000,2.37]],"ltp":1.02,"tv":0.09,"id":2263600,"hc":-10.5},{"trd":[[1.02,0.22]],"batb":[[0,1.02,8.78]],"ltp":1.02,"tv":0.21,"id":2263600,"hc":-11.5}],"tv":0.31}]}
{"op":"mcm","clk":"1005026666","pt":1580640186601,"mc":[{"id":"1.168230817","rc":[{"batl":[[0,1000,4.73]],"ltp":0.0,"tv":0.0,"id":2263600,"hc":-9.5},{"trd":[[1.02,0.11]],"batb":[[0,1.02,8.85]],"batl":[[0,990,0.01]],"ltp":1.02,"tv":0.1,"id":2263600,"hc":-10.5}],"tv":0.32}]}
{"op":"mcm","clk":"1005026744","pt":1580640187023,"mc":[{"id":"1.168230817","rc":[{"batl":[[0,990,0.01]],"ltp":0.0,"tv":0.0,"id":2263600,"hc":-9.5}]}]}
{"op":"mcm","clk":"1005027433","pt":1580640191516,"mc":[{"id":"1.168230817","rc":[{"batl":[[0,1000,2.37]],"ltp":1.02,"tv":0.1,"id":2263600,"hc":-10.5},{"trd":[[1.02,0.23]],"batb":[[0,1.02,8.77]],"ltp":1.02,"tv":0.23,"id":2263600,"hc":-11.5}],"tv":0.34}]}
{"op":"mcm","clk":"1005027518","pt":1580640192038,"mc":[{"id":"1.168230817","rc":[{"trd":[[1.02,0.12]],"batb":[[0,1.02,8.84]],"batl":[[0,990,0.01]],"ltp":1.02,"tv":0.12,"id":2263600,"hc":-10.5}],"tv":0.35}]}
{"op":"mcm","clk":"1005028191","pt":1580640196635,"mc":[{"id":"1.168230817","rc":[{"batl":[[0,1000,0.02]],"ltp":0.0,"tv":0.0,"id":2263600,"hc":-9.5},{"trd":[[1.02,0.25]],"batb":[[0,1.02,8.76]],"ltp":1.02,"tv":0.24,"id":2263600,"hc":-11.5}],"tv":0.37}]}
{"op":"mcm","clk":"1005028355","pt":1580640197526,"mc":[{"id":"1.168230817","rc":[{"trd":[[1.02,0.02]],"batb":[[0,1.02,8.91]],"batl":[[0,990,0.01]],"ltp":1.02,"tv":0.01,"id":2263600,"hc":-9.5},{"trd":[[1.02,0.14]],"batb":[[0,1.02,8.83]],"ltp":1.02,"tv":0.13,"id":2263600,"hc":-10.5}],"tv":0.4}]}
{"op":"mcm","clk":"1005029083","pt":1580640201617,"mc":[{"id":"1.168230817","rc":[{"batl":[[0,1000,2.37]],"ltp":1.02,"tv":0.24,"id":2263600,"hc":-11.5}]}]}
{"op":"mcm","clk":"1005029196","pt":1580640202405,"mc":[{"id":"1.168230817","rc":[{"trd":[[1.02,0.26]],"batb":[[0,1.02,8.75]],"batl":[[0,990,0.01]],"ltp":1.02,"tv":0.26,"id":2263600,"hc":-11.5}],"tv":0.41}]}
{"op":"mcm","clk":"1005029344","pt":1580640203603,"mc":[{"id":"1.168230817","rc":[{"batl":[[0,1000,2.37]],"ltp":1.02,"tv":0.01,"id":2263600,"hc":-9.5},{"trd":[[1.02,0.16]],"batb":[[0,1.02,8.82]],"ltp":1.02,"tv":0.15,"id":2263600,"hc":-10.5}],"tv":0.43}]}
{"op":"mcm","clk":"1005029433","pt":1580640204133,"mc":[{"id":"1.168230817","rc":[{"trd":[[1.02,0.03]],"batb":[[0,1.02,8.9]],"batl":[[0,990,0.01]],"ltp":1.02,"tv":0.03,"id":2263600,"hc":-9.5}],"tv":0.44}]}
{"op":"mcm","clk":"1005029971","pt":1580640207644,"mc":[{"id":"1.168230817","rc":[{"batl":[[0,1000,0.02]],"ltp":1.02,"tv":0.03,"id":2263600,"hc":-9.5},{"trd":[[1.02,0.28]],"batb":[[0,1.02,8.74]],"ltp":1.02,"tv":0.27,"id":2263600,"hc":-11.5}],"tv":0.46}]}
{"op":"mcm","clk":"1005030106","pt":1580640208643,"mc":[{"id":"1.168230817","rc":[{"trd":[[1.02,0.05]],"batb":[[0,1.02,8.89]],"batl":[[0,990,0.01]],"ltp":1.02,"tv":0.04,"id":2263600,"hc":-9.5},{"batl":[[0,1000,0.02]],"ltp":1.02,"tv":0.15,"id":2263600,"hc":-10.5}],"tv":0.48}]}
{"op":"mcm","clk":"1005030158","pt":1580640209015,"mc":[{"id":"1.168230817","rc":[{"trd":[[1.02,0.17]],"batb":[[0,1.02,8.81]],"batl":[[0,990,0.01]],"ltp":1.02,"tv":0.17,"id":2263600,"hc":-10.5}],"tv":0.49}]}
{"op":"mcm","clk":"1005030608","pt":1580640212450,"mc":[{"id":"1.168230817","rc":[{"batl":[[0,1000,2.37]],"ltp":1.02,"tv":0.27,"id":2263600,"hc":-11.5}]}]}
{"op":"mcm","clk":"1005030727","pt":1580640213355,"mc":[{"id":"1.168230817","rc":[{"trd":[[1.02,0.06]],"batb":[[0,1.02,8.88]],"ltp":1.02,"tv":0.06,"id":2263600,"hc":-9.5},{"trd":[[1.02,0.29]],"batb":[[0,1.02,8.73]],"batl":[[0,990,0.01]],"ltp":1.02,"tv":0.29,"id":2263600,"hc":-11.5}],"tv":0.52}]}
{"op":"mcm","clk":"1005031018","pt":1580640215449,"mc":[{"id":"1.168230817","rc":[{"trd":[[1.02,0.19]],"batb":[[0,1.02,8.8]],"ltp":1.02,"tv":0.18,"id":2263600,"hc":-10.5}],"tv":0.54}]}
{"op":"mcm","clk":"1005031261","pt":1580640217562,"mc":[{"id":"1.168230817","rc":[{"batl":[[0,1000,2.37]],"ltp":1.02,"tv":0.29,"id":2263600,"hc":-11.5}]}]}
{"op":"mcm","clk":"1005031382","pt":1580640218451,"mc":[{"id":"1.168230817","rc":[{"trd":[[1.02,0.08]],"batb":[[0,1.02,8.87]],"ltp":1.02,"tv":0.07,"id":2263600,"hc":-9.5},{"trd":[[1.02,0.31]],"batb":[[0,1.02,8.72]],"batl":[[0,990,0.01]],"ltp":1.02,"tv":0.31,"id":2263600,"hc":-11.5}],"tv":0.57}]}
{"op":"mcm","clk":"1005031673","pt":1580640220644,"mc":[{"id":"1.168230817","rc":[{"trd":[[1.02,0.2]],"batb":[[0,1.02,8.79]],"ltp":1.02,"tv":0.2,"id":2263600,"hc":-10.5}],"tv":0.58}]}
{"op":"mcm","clk":"1005032097","pt":1580640223447,"mc":[{"id":"1.168230817","rc":[{"trd":[[1.02,0.33]],"batb":[[0,1.02,8.71]],"ltp":1.02,"tv":0.32,"id":2263600,"hc":-11.5}],"tv":0.6}]}
{"op":"mcm","clk":"1005032193","pt":1580640224234,"mc":[{"id":"1.168230817","rc":[{"trd":[[1.02,0.09]],"batb":[[0,1.02,8.86]],"ltp":1.02,"tv":0.09,"id":2263600,"hc":-9.5}],"tv":0.62}]}
{"op":"mcm","clk":"1005032382","pt":1580640225436,"mc":[{"id":"1.168230817","rc":[{"batl":[[0,1000,2.37]],"ltp":1.02,"tv":0.2,"id":2263600,"hc":-10.5}]}]}
{"op":"mcm","clk":"1005032464","pt":1580640226069,"mc":[{"id":"1.168230817","rc":[{"trd":[[1.02,0.22]],"batb":[[0,1.02,8.78]],"batl":[[0,990,0.01]],"ltp":1.02,"tv":0.21,"id":2263600,"hc":-10.5}],"tv":0.63}]}
{"op":"mcm","clk":"1005032818","pt":1580640228529,"mc":[{"id":"1.168230817","rc":[{"batl":[[0,1000,0.02]],"ltp":1.02,"tv":0.32,"id":2263600,"hc":-11.5}]}]}
{"op":"mcm","clk":"1005032941","pt":1580640229566,"mc":[{"id":"1.168230817","rc":[{"trd":[[1.02,0.11]],"batb":[[0,1.02,8.85]],"ltp":1.02,"tv":0.1,"id":2263600,"hc":-9.5},{"trd":[[1.02,0.34]],"batb":[[0,1.02,8.7]],"batl":[[0,990,0.01]],"ltp":1.02,"tv":0.34,"id":2263600,"hc":-11.5}],"tv":0.66}]}
{"op":"mcm","clk":"1005033067","pt":1580640230465,"mc":[{"id":"1.168230817","rc":[{"batl":[[0,1000,2.37]],"ltp":1.02,"tv":0.21,"id":2263600,"hc":-10.5}]}]}
{"op":"mcm","clk":"1005033147","pt":1580640231044,"mc":[{"id":"1.168230817","rc":[{"trd":[[1.02,0.23]],"batb":[[0,1.02,8.77]],"batl":[[0,990,0.01]],"ltp":1.02,"tv":0.23,"id":2263600,"hc":-10.5}],"tv":0.68}]}
{"op":"mcm","clk":"1005033445","pt":1580640233557,"mc":[{"id":"1.168230817","rc":[{"batl":[[0,1000,2.37]],"ltp":1.02,"tv":0.34,"id":2263600,"hc":-11.5}]}]}
{"op":"mcm","clk":"1005033577","pt":1580640234456,"mc":[{"id":"1.168230817","rc":[{"batl":[[0,1000,0.02]],"ltp":1.02,"tv":0.1,"id":2263600,"hc":-9.5},{"trd":[[1.02,0.36]],"batb":[[0,1.02,8.69]],"batl":[[0,990,0.01]],"ltp":1.02,"tv":0.35,"id":2263600,"hc":-11.5}],"tv":0.69}]}
{"op":"mcm","clk":"1005033719","pt":1580640235553,"mc":[{"id":"1.168230817","rc":[{"trd":[[1.02,0.12]],"batb":[[0,1.02,8.84]],"batl":[[0,990,0.01]],"ltp":1.02,"tv":0.12,"id":2263600,"hc":-9.5},{"batl":[[0,1000,2.37]],"ltp":1.02,"tv":0.23,"id":2263600,"hc":-10.5}],"tv":0.71}]}
{"op":"mcm","clk":"1005033786","pt":1580640236184,"mc":[{"id":"1.168230817","rc":[{"trd":[[1.02,0.25]],"batb":[[0,1.02,8.76]],"batl":[[0,990,0.01]],"ltp":1.02,"tv":0.24,"id":2263600,"hc":-10.5}],"tv":0.72}]}
{"op":"mcm","clk":"1005034271","pt":1580640239555,"mc":[{"id":"1.168230817","rc":[{"batl":[[0,1000,0.02]],"ltp":1.02,"tv":0.12,"id":2263600,"hc":-9.5},{"trd":[[1.02,0.37]],"batb":[[0,1.02,8.68]],"ltp":1.02,"tv":0.37,"id":2263600,"hc":-11.5}],"tv":0.74}]}
{"op":"mcm","clk":"1005034311","pt":1580640239862,"mc":[{"id":"1.168230817","rc":[{"trd":[[1.02,0.14]],"batb":[[0,1.02,8.83]],"batl":[[0,990,0.01]],"ltp":1.02,"tv":0.13,"id":2263600,"hc":-9.5}],"tv":0.75}]}
{"op":"mcm","clk":"1005034559","pt":1580640241589,"mc":[{"id":"1.168230817","rc":[{"batl":[[0,1000,0.02]],"ltp":1.02,"tv":0.24,"id":2263600,"hc":-10.5}]}]}
{"op":"mcm","clk":"1005034605","pt":1580640241852,"mc":[{"id":"1.168230817","rc":[{"trd":[[1.02,0.26]],"batb":[[0,1.02,8.75]],"batl":[[0,990,0.01]],"ltp":1.02,"tv":0.26,"id":2263600,"hc":-10.5}],"tv":0.77}]}
{"op":"mcm","clk":"1005034995","pt":1580640244364,"mc":[{"id":"1.168230817","rc":[{"batl":[[0,1000,0.02]],"ltp":1.02,"tv":0.37,"id":2263600,"hc":-11.5}]}]}
{"op":"mcm","clk":"1005035117","pt":1580640245296,"mc":[{"id":"1.168230817","rc":[{"trd":[[1.02,0.16]],"batb":[[0,1.02,8.82]],"ltp":1.02,"tv":0.15,"id":2263600,"hc":-9.5},{"trd":[[1.02,0.39]],"batb":[[0,1.02,8.67]],"batl":[[0,990,0.01]],"ltp":1.02,"tv":0.38,"id":2263600,"hc":-11.5}],"tv":0.8}]}
{"op":"mcm","clk":"1005035386","pt":1580640247493,"mc":[{"id":"1.168230817","rc":[{"trd":[[1.02,0.28]],"batb":[[0,1.02,8.74]],"ltp":1.02,"tv":0.27,"id":2263600,"hc":-10.5}],"tv":0.82}]}
{"op":"mcm","clk":"1005035634","pt":1580640249578,"mc":[{"id":"1.168230817","rc":[{"batl":[[0,1000,2.37]],"ltp":1.02,"tv":0.38,"id":2263600,"hc":-11.5}]}]}
{"op":"mcm","clk":"1005035729","pt":1580640250406,"mc":[{"id":"1.168230817","rc":[{"trd":[[1.02,0.17]],"batb":[[0,1.02,8.81]],"ltp":1.02,"tv":0.17,"id":2263600,"hc":-9.5},{"trd":[[1.02,0.4]],"batb":[[0,1.02,8.66]],"batl":[[0,990,0.01]],"ltp":1.02,"tv":0.4,"id":2263600,"hc":-11.5}],"tv":0.85}]}
{"op":"mcm","clk":"1005035987","pt":1580640252503,"mc":[{"id":"1.168230817","rc":[{"batl":[[0,1000,0.02]],"ltp":1.02,"tv":0.27,"id":2263600,"hc":-10.5}]}]}
{"op":"mcm","clk":"1005036124","pt":1580640253608,"mc":[{"id":"1.168230817","rc":[{"trd":[[1.02,0.29]],"batb":[[0,1.02,8.73]],"batl":[[0,990,0.01]],"ltp":1.02,"tv":0.29,"id":2263600,"hc":-10.5}],"tv":0.86}]}
{"op":"mcm","clk":"1005036356","pt":1580640255477,"mc":[{"id":"1.168230817","rc":[{"batl":[[0,1000,0.02]],"ltp":1.02,"tv":0.17,"id":2263600,"hc":-9.5},{"trd":[[1.02,0.42]],"batb":[[0,1.02,8.65]],"ltp":1.02,"tv":0.41,"id":2263600,"hc":-11.5}],"tv":0.88}]}
{"op":"mcm","clk":"1005036479","pt":1580640256583,"mc":[{"id":"1.168230817","rc":[{"trd":[[1.02,0.19]],"batb":[[0,1.02,8.8]],"batl":[[0,990,0.01]],"ltp":1.02,"tv":0.18,"id":2263600,"hc":-9.5}],"tv":0.89}]}
{"op":"mcm","clk":"1005036592","pt":1580640257623,"mc":[{"id":"1.168230817","rc":[{"batl":[[0,1000,0.02]],"ltp":1.02,"tv":0.29,"id":2263600,"hc":-10.5}]}]}
{"op":"mcm","clk":"1005036744","pt":1580640258574,"mc":[{"id":"1.168230817","rc":[{"trd":[[1.02,0.31]],"batb":[[0,1.02,8.72]],"batl":[[0,990,0.01]],"ltp":1.02,"tv":0.31,"id":2263600,"hc":-10.5}],"tv":0.91}]}
{"op":"mcm","clk":"1005036964","pt":1580640260614,"mc":[{"id":"1.168230817","rc":[{"batl":[[0,1000,0.02]],"ltp":1.02,"tv":0.18,"id":2263600,"hc":-9.5},{"batl":[[0,1000,0.02]],"ltp":1.02,"tv":0.41,"id":2263600,"hc":-11.5}]}]}
{"op":"mcm","clk":"1005037002","pt":1580640260924,"mc":[{"id":"1.168230817","rc":[{"trd":[[1.02,0.2]],"batb":[[0,1.02,8.79]],"batl":[[0,990,0.01]],"ltp":1.02,"tv":0.2,"id":2263600,"hc":-9.5},{"trd":[[1.02,0.43]],"batb":[[0,1.02,8.64]],"batl":[[0,990,0.01]],"ltp":1.02,"tv":0.43,"id":2263600,"hc":-11.5}],"tv":0.94}]}
{"op":"mcm","clk":"1005037356","pt":1580640264026,"mc":[{"id":"1.168230817","rc":[{"trd":[[1.02,0.33]],"batb":[[0,1.02,8.71]],"ltp":1.02,"tv":0.32,"id":2263600,"hc":-10.5}],"tv":0.96}]}
{"op":"mcm","clk":"1005037650","pt":1580640266423,"mc":[{"id":"1.168230817","rc":[{"trd":[[1.02,0.22]],"batb":[[0,1.02,8.78]],"ltp":1.02,"tv":0.21,"id":2263600,"hc":-9.5},{"trd":[[1.02,0.45]],"batb":[[0,1.02,8.63]],"ltp":1.02,"tv":0.44,"id":2263600,"hc":-11.5}],"tv":0.99}]}
{"op":"mcm","clk":"1005037920","pt":1580640268621,"mc":[{"id":"1.168230817","rc":[{"batl":[[0,1000,2.37]],"ltp":1.02,"tv":0.32,"id":2263600,"hc":-10.5}]}]}
{"op":"mcm","clk":"1005038034","pt":1580640269550,"mc":[{"id":"1.168230817","rc":[{"trd":[[1.02,0.34]],"batb":[[0,1.02,8.7]],"batl":[[0,990,0.01]],"ltp":1.02,"tv":0.34,"id":2263600,"hc":-10.5}],"tv":1.0}]}
{"op":"mcm","clk":"1005038301","pt":1580640271638,"mc":[{"id":"1.168230817","rc":[{"batl":[[0,1000,0.02]],"ltp":1.02,"tv":0.21,"id":2263600,"hc":-9.5}]}]}
{"op":"mcm","clk":"1005038409","pt":1580640272631,"mc":[{"id":"1.168230817","rc":[{"trd":[[1.02,0.23]],"batb":[[0,1.02,8.77]],"batl":[[0,990,0.01]],"ltp":1.02,"tv":0.23,"id":2263600,"hc":-9.5},{"trd":[[1.02,0.47]],"batb":[[0,1.02,8.62]],"ltp":1.02,"tv":0.46,"id":2263600,"hc":-11.5}],"tv":1.03}]}
{"op":"mcm","clk":"1005038665","pt":1580640274625,"mc":[{"id":"1.168230817","rc":[{"trd":[[1.02,0.36]],"batb":[[0,1.02,8.69]],"ltp":1.02,"tv":0.35,"id":2263600,"hc":-10.5}],"tv":1.05}]}
{"op":"mcm","clk":"1005038985","pt":1580640277228,"mc":[{"id":"1.168230817","rc":[{"trd":[[1.02,0.25]],"batb":[[0,1.02,8.76]],"ltp":1.02,"tv":0.24,"id":2263600,"hc":-9.5},{"trd":[[1.02,0.48]],"batb":[[0,1.02,8.61]],"ltp":1.02,"tv":0.48,"id":2263600,"hc":-11.5}],"tv":1.08}]}
{"op":"mcm","clk":"1005039431","pt":1580640280634,"mc":[{"id":"1.168230817","rc":[{"trd":[[1.02,0.37]],"batb":[[0,1.02,8.68]],"ltp":1.02,"tv":0.37,"id":2263600,"hc":-10.5}],"tv":1.1}]}
{"op":"mcm","clk":"1005039679","pt":1580640282560,"mc":[{"id":"1.168230817","rc":[{"trd":[[1.02,0.26]],"batb":[[0,1.02,8.75]],"ltp":1.02,"tv":0.26,"id":2263600,"hc":-9.5},{"batl":[[0,1000,0.02]],"ltp":1.02,"tv":0.48,"id":2263600,"hc":-11.5}],"tv":1.11}]}
{"op":"mcm","clk":"1005039716","pt":1580640282845,"mc":[{"id":"1.168230817","rc":[{"trd":[[1.02,0.5]],"batb":[[0,1.02,8.6]],"batl":[[0,990,0.01]],"ltp":1.02,"tv":0.49,"id":2263600,"hc":-11.5}],"tv":1.13}]}
{"op":"mcm","clk":"1005040040","pt":1580640285570,"mc":[{"id":"1.168230817","rc":[{"batl":[[0,1000,0.02]],"ltp":1.02,"tv":0.37,"id":2263600,"hc":-10.5}]}]}
{"op":"mcm","clk":"1005040294","pt":1580640287557,"mc":[{"id":"1.168230817","rc":[{"batl":[[0,1000,0.02]],"ltp":1.02,"tv":0.26,"id":2263600,"hc":-9.5},{"trd":[[1.02,0.39]],"batb":[[0,1.02,8.67]],"batl":[[0,990,0.01]],"ltp":1.02,"tv":0.38,"id":2263600,"hc":-10.5},{"batl":[[0,1000,2.37]],"ltp":1.02,"tv":0.49,"id":2263600,"hc":-11.5}],"tv":1.14}]}
{"op":"mcm","clk":"1005040354","pt":1580640288082,"mc":[{"id":"1.168230817","rc":[{"trd":[[1.02,0.28]],"batb":[[0,1.02,8.74]],"batl":[[0,990,0.01]],"ltp":1.02,"tv":0.27,"id":2263600,"hc":-9.5},{"trd":[[1.02,0.51]],"batb":[[0,1.02,8.59]],"batl":[[0,990,0.01]],"ltp":1.02,"tv":0.51,"id":2263600,"hc":-11.5}],"tv":1.17}]}
{"op":"mcm","clk":"1005040822","pt":1580640291476,"mc":[{"id":"1.168230817","rc":[{"batl":[[0,1000,2.37]],"ltp":1.02,"tv":0.38,"id":2263600,"hc":-10.5}]}]}
{"op":"mcm","clk":"1005041005","pt":1580640292576,"mc":[{"id":"1.168230817","rc":[{"trd":[[1.02,0.29]],"batb":[[0,1.02,8.73]],"ltp":1.02,"tv":0.29,"id":2263600,"hc":-9.5},{"trd":[[1.02,0.4]],"batb":[[0,1.02,8.66]],"batl":[[0,990,0.01]],"ltp":1.02,"tv":0.4,"id":2263600,"hc":-10.5}],"tv":1.2}]}
{"op":"mcm","clk":"1005041110","pt":1580640293359,"mc":[{"id":"1.168230817","rc":[{"trd":[[1.02,0.53]],"batb":[[0,1.02,8.58]],"ltp":1.02,"tv":0.52,"id":2263600,"hc":-11.5}],"tv":1.22}]}
{"op":"mcm","clk":"1005041655","pt":1580640297458,"mc":[{"id":"1.168230817","rc":[{"batl":[[0,1000,0.02]],"ltp":1.02,"tv":0.29,"id":2263600,"hc":-9.5},{"batl":[[0,1000,0.02]],"ltp":1.02,"tv":0.4,"id":2263600,"hc":-10.5}]}]}
{"op":"mcm","clk":"1005041801","pt":1580640298554,"mc":[{"id":"1.168230817","rc":[{"trd":[[1.02,0.31]],"batb":[[0,1.02,8.72]],"batl":[[0,990,0.01]],"ltp":1.02,"tv":0.31,"id":2263600,"hc":-9.5},{"trd":[[1.02,0.42]],"batb":[[0,1.02,8.65]],"batl":[[0,990,0.01]],"ltp":1.02,"tv":0.41,"id":2263600,"hc":-10.5},{"trd":[[1.02,0.54]],"batb":[[0,1.02,8.57]],"ltp":1.02,"tv":0.54,"id":2263600,"hc":-11.5}],"tv":1.27}]}
{"op":"mcm","clk":"1005042351","pt":1580640302595,"mc":[{"id":"1.168230817","rc":[{"batl":[[0,1000,2.37]],"ltp":1.02,"tv":0.31,"id":2263600,"hc":-9.5}]}]}
{"op":"mcm","clk":"1005042531","pt":1580640303604,"mc":[{"id":"1.168230817","rc":[{"trd":[[1.02,0.33]],"batb":[[0,1.02,8.71]],"batl":[[0,990,0.01]],"ltp":1.02,"tv":0.32,"id":2263600,"hc":-9.5},{"trd":[[1.02,0.43]],"batb":[[0,1.02,8.64]],"ltp":1.02,"tv":0.43,"id":2263600,"hc":-10.5},{"batl":[[0,1000,0.02]],"ltp":1.02,"tv":0.54,"id":2263600,"hc":-11.5}],"tv":1.3}]}
{"op":"mcm","clk":"1005042583","pt":1580640303874,"mc":[{"id":"1.168230817","rc":[{"trd":[[1.02,0.56]],"batb":[[0,1.02,8.56]],"batl":[[0,990,0.01]],"ltp":1.02,"tv":0.55,"id":2263600,"hc":-11.5}],"tv":1.31}]}
{"op":"mcm","clk":"1005043352","pt":1580640308556,"mc":[{"id":"1.168230817","rc":[{"trd":[[1.02,0.34]],"batb":[[0,1.02,8.7]],"ltp":1.02,"tv":0.34,"id":2263600,"hc":-9.5},{"batl":[[0,1000,0.02]],"ltp":1.02,"tv":0.43,"id":2263600,"hc":-10.5}],"tv":1.33}]}
{"op":"mcm","clk":"1005043520","pt":1580640309497,"mc":[{"id":"1.168230817","rc":[{"trd":[[1.02,0.45]],"batb":[[0,1.02,8.63]],"batl":[[0,990,0.01]],"ltp":1.02,"tv":0.44,"id":2263600,"hc":-10.5},{"trd":[[1.02,0.57]],"batb":[[0,1.02,8.55]],"ltp":1.02,"tv":0.57,"id":2263600,"hc":-11.5}],"tv":1.36}]}
{"op":"mcm","clk":"1005044089","pt":1580640313488,"mc":[{"id":"1.168230817","rc":[{"batl":[[0,1000,0.02]],"ltp":1.02,"tv":0.34,"id":2263600,"hc":-9.5}]}]}
{"op":"mcm","clk":"1005044273","pt":1580640314596,"mc":[{"id":"1.168230817","rc":[{"trd":[[1.02,0.36]],"batb":[[0,1.02,8.69]],"batl":[[0,990,0.01]],"ltp":1.02,"tv":0.35,"id":2263600,"hc":-9.5},{"batl":[[0,1000,0.02]],"ltp":1.02,"tv":0.57,"id":2263600,"hc":-11.5}],"tv":1.38}]}
{"op":"mcm","clk":"1005044325","pt":1580640314908,"mc":[{"id":"1.168230817","rc":[{"trd":[[1.02,0.47]],"batb":[[0,1.02,8.62]],"ltp":1.02,"tv":0.46,"id":2263600,"hc":-10.5},{"trd":[[1.02,0.59]],"batb":[[0,1.02,8.54]],"batl":[[0,990,0.01]],"ltp":1.02,"tv":0.58,"id":2263600,"hc":-11.5}],"tv":1.41}]}
{"op":"mcm","clk":"1005044870","pt":1580640318623,"mc":[{"id":"1.168230817","rc":[{"batl":[[0,1000,2.37]],"ltp":1.02,"tv":0.35,"id":2263600,"hc":-9.5}]}]}
{"op":"mcm","clk":"1005044997","pt":1580640319504,"mc":[{"id":"1.168230817","rc":[{"trd":[[1.02,0.37]],"batb":[[0,1.02,8.68]],"batl":[[0,990,0.01]],"ltp":1.02,"tv":0.37,"id":2263600,"hc":-9.5},{"batl":[[0,1000,2.37]],"ltp":1.02,"tv":0.46,"id":2263600,"hc":-10.5},{"batl":[[0,1000,2.37]],"ltp":1.02,"tv":0.58,"id":2263600,"hc":-11.5}],"tv":1.42}]}
{"op":"mcm","clk":"1005045069","pt":1580640320112,"mc":[{"id":"1.168230817","rc":[{"trd":[[1.02,0.48]],"batb":[[0,1.02,8.61]],"batl":[[0,990,0.01]],"ltp":1.02,"tv":0.48,"id":2263600,"hc":-10.5},{"trd":[[1.02,0.6]],"batb":[[0,1.02,8.53]],"batl":[[0,990,0.01]],"ltp":1.02,"tv":0.6,"id":2263600,"hc":-11.5}],"tv":1.45}]}
{"op":"mcm","clk":"1005045742","pt":1580640324621,"mc":[{"id":"1.168230817","rc":[{"trd":[[1.02,0.39]],"batb":[[0,1.02,8.67]],"ltp":1.02,"tv":0.38,"id":2263600,"hc":-9.5},{"batl":[[0,1000,2.37]],"ltp":1.02,"tv":0.48,"id":2263600,"hc":-10.5}],"tv":1.47}]}
{"op":"mcm","clk":"1005045856","pt":1580640325294,"mc":[{"id":"1.168230817","rc":[{"trd":[[1.02,0.5]],"batb":[[0,1.02,8.6]],"batl":[[0,990,0.01]],"ltp":1.02,"tv":0.49,"id":2263600,"hc":-10.5},{"trd":[[1.02,0.62]],"batb":[[0,1.02,8.52]],"ltp":1.02,"tv":0.62,"id":2263600,"hc":-11.5}],"tv":1.5}]}
{"op":"mcm","clk":"1005046423","pt":1580640329544,"mc":[{"id":"1.168230817","rc":[{"trd":[[1.02,0.4]],"batb":[[0,1.02,8.66]],"ltp":1.02,"tv":0.4,"id":2263600,"hc":-9.5}],"tv":1.51}]}
{"op":"mcm","clk":"1005046579","pt":1580640330649,"mc":[{"id":"1.168230817","rc":[{"trd":[[1.02,0.51]],"batb":[[0,1.02,8.59]],"ltp":1.02,"tv":0.51,"id":2263600,"hc":-10.5},{"trd":[[1.02,0.64]],"batb":[[0,1.02,8.51]],"ltp":1.02,"tv":0.63,"id":2263600,"hc":-11.5}],"tv":1.55}]}
{"op":"mcm","clk":"1005047261","pt":1580640335624,"mc":[{"id":"1.168230817","rc":[{"trd":[[1.02,0.42]],"batb":[[0,1.02,8.65]],"ltp":1.02,"tv":0.41,"id":2263600,"hc":-9.5},{"batl":[[0,1000,2.37]],"ltp":1.02,"tv":0.51,"id":2263600,"hc":-10.5},{"batl":[[0,1000,0.02]],"ltp":1.02,"tv":0.63,"id":2263600,"hc":-11.5}],"tv":1.56}]}
{"op":"mcm","clk":"1005047325","pt":1580640336138,"mc":[{"id":"1.168230817","rc":[{"trd":[[1.02,0.53]],"batb":[[0,1.02,8.58]],"batl":[[0,990,0.01]],"ltp":1.02,"tv":0.52,"id":2263600,"hc":-10.5},{"trd":[[1.02,0.65]],"batb":[[0,1.02,8.5]],"batl":[[0,990,0.01]],"ltp":1.02,"tv":0.65,"id":2263600,"hc":-11.5}],"tv":1.59}]}
{"op":"mcm","clk":"1005047755","pt":1580640339642,"mc":[{"id":"1.168230817","rc":[{"trd":[[1.02,0.43]],"batb":[[0,1.02,8.64]],"ltp":1.02,"tv":0.43,"id":2263600,"hc":-9.5}],"tv":1.61}]}
{"op":"mcm","clk":"1005048042","pt":1580640341528,"mc":[{"id":"1.168230817","rc":[{"trd":[[1.02,0.54]],"batb":[[0,1.02,8.57]],"ltp":1.02,"tv":0.54,"id":2263600,"hc":-10.5},{"batl":[[0,1000,0.02]],"ltp":1.02,"tv":0.65,"id":2263600,"hc":-11.5}],"tv":1.62}]}
{"op":"mcm","clk":"1005048084","pt":1580640341841,"mc":[{"id":"1.168230817","rc":[{"trd":[[1.02,0.67]],"batb":[[0,1.02,8.49]],"batl":[[0,990,0.01]],"ltp":1.02,"tv":0.66,"id":2263600,"hc":-11.5}],"tv":1.64}]}
{"op":"mcm","clk":"1005048458","pt":1580640344535,"mc":[{"id":"1.168230817","rc":[{"batl":[[0,1000,0.02]],"ltp":1.02,"tv":0.43,"id":2263600,"hc":-9.5}]}]}
{"op":"mcm","clk":"1005048485","pt":1580640344834,"mc":[{"id":"1.168230817","rc":[{"trd":[[1.02,0.45]],"batb":[[0,1.02,8.63]],"batl":[[0,990,0.01]],"ltp":1.02,"tv":0.44,"id":2263600,"hc":-9.5}],"tv":1.65}]}
{"op":"mcm","clk":"1005048706","pt":1580640346631,"mc":[{"id":"1.168230817","rc":[{"batl":[[0,1000,0.02]],"ltp":1.02,"tv":0.66,"id":2263600,"hc":-11.5}]}]}
{"op":"mcm","clk":"1005048831","pt":1580640347601,"mc":[{"id":"1.168230817","rc":[{"trd":[[1.02,0.56]],"batb":[[0,1.02,8.56]],"ltp":1.02,"tv":0.55,"id":2263600,"hc":-10.5},{"trd":[[1.02,0.68]],"batb":[[0,1.02,8.48]],"batl":[[0,990,0.01]],"ltp":1.02,"tv":0.68,"id":2263600,"hc":-11.5}],"tv":1.69}]}
{"op":"mcm","clk":"1005049088","pt":1580640349631,"mc":[{"id":"1.168230817","rc":[{"batl":[[0,1000,2.37]],"ltp":1.02,"tv":0.44,"id":2263600,"hc":-9.5}]}]}
{"op":"mcm","clk":"1005049149","pt":1580640350151,"mc":[{"id":"1.168230817","rc":[{"trd":[[1.02,0.47]],"batb":[[0,1.02,8.62]],"batl":[[0,990,0.01]],"ltp":1.02,"tv":0.46,"id":2263600,"hc":-9.5}],"tv":1.7}]}
{"op":"mcm","clk":"1005049303","pt":1580640351615,"mc":[{"id":"1.168230817","rc":[{"batl":[[0,1000,2.37]],"ltp":1.02,"tv":0.68,"id":2263600,"hc":-11.5}]}]}
{"op":"mcm","clk":"1005049402","pt":1580640352454,"mc":[{"id":"1.168230817","rc":[{"batl":[[0,1000,2.37]],"ltp":1.02,"tv":0.55,"id":2263600,"hc":-10.5},{"trd":[[1.02,0.7]],"batb":[[0,1.02,8.47]],"batl":[[0,990,0.01]],"ltp":1.02,"tv":0.69,"id":2263600,"hc":-11.5}],"tv":1.72}]}
{"op":"mcm","clk":"1005049468","pt":1580640353033,"mc":[{"id":"1.168230817","rc":[{"trd":[[1.02,0.57]],"batb":[[0,1.02,8.55]],"batl":[[0,990,0.01]],"ltp":1.02,"tv":0.57,"id":2263600,"hc":-10.5}],"tv":1.73}]}
{"op":"mcm","clk":"1005049798","pt":1580640355547,"mc":[{"id":"1.168230817","rc":[{"trd":[[1.02,0.48]],"batb":[[0,1.02,8.61]],"ltp":1.02,"tv":0.48,"id":2263600,"hc":-9.5}],"tv":1.75}]}
{"op":"mcm","clk":"1005050138","pt":1580640358325,"mc":[{"id":"1.168230817","rc":[{"trd":[[1.02,0.59]],"batb":[[0,1.02,8.54]],"ltp":1.02,"tv":0.58,"id":2263600,"hc":-10.5},{"trd":[[1.02,0.71]],"batb":[[0,1.02,8.46]],"ltp":1.02,"tv":0.71,"id":2263600,"hc":-11.5}],"tv":1.78}]}
{"op":"mcm","clk":"1005050401","pt":1580640360329,"mc":[{"id":"1.168230817","rc":[{"batl":[[0,1000,2.37]],"ltp":1.02,"tv":0.48,"id":2263600,"hc":-9.5}]}]}
{"op":"mcm","clk":"1005050497","pt":1580640361035,"mc":[{"id":"1.168230817","rc":[{"trd":[[1.02,0.5]],"batb":[[0,1.02,8.6]],"batl":[[0,990,0.01]],"ltp":1.02,"tv":0.49,"id":2263600,"hc":-9.5}],"tv":1.79}]}
{"op":"mcm","clk":"1005050782","pt":1580640363342,"mc":[{"id":"1.168230817","rc":[{"trd":[[1.02,0.73]],"batb":[[0,1.02,8.45]],"ltp":1.02,"tv":0.72,"id":2263600,"hc":-11.5}],"tv":1.81}]}
{"op":"mcm","clk":"1005050932","pt":1580640364340,"mc":[{"id":"1.168230817","rc":[{"trd":[[1.02,0.6]],"batb":[[0,1.02,8.53]],"ltp":1.02,"tv":0.6,"id":2263600,"hc":-10.5}],"tv":1.82}]}
{"op":"mcm","clk":"1005051248","pt":1580640366338,"mc":[{"id":"1.168230817","rc":[{"trd":[[1.02,0.51]],"batb":[[0,1.02,8.59]],"ltp":1.02,"tv":0.51,"id":2263600,"hc":-9.5}],"tv":1.84}]}
{"op":"mcm","clk":"1005051740","pt":1580640369630,"mc":[{"id":"1.168230817","rc":[{"trd":[[1.02,0.74]],"batb":[[0,1.02,8.44]],"ltp":1.02,"tv":0.74,"id":2263600,"hc":-11.5}],"tv":1.86}]}
{"op":"mcm","clk":"1005051840","pt":1580640370361,"mc":[{"id":"1.168230817","rc":[{"trd":[[1.02,0.62]],"batb":[[0,1.02,8.52]],"ltp":1.02,"tv":0.62,"id":2263600,"hc":-10.5}],"tv":1.87}]}
{"op":"mcm","clk":"1005051978","pt":1580640371358,"mc":[{"id":"1.168230817","rc":[{"trd":[[1.02,0.53]],"batb":[[0,1.02,8.58]],"ltp":1.02,"tv":0.52,"id":2263600,"hc":-9.5}],"tv":1.89}]}
{"op":"mcm","clk":"1005052435","pt":1580640374541,"mc":[{"id":"1.168230817","rc":[{"trd":[[1.02,0.76]],"batb":[[0,1.02,8.43]],"ltp":1.02,"tv":0.75,"id":2263600,"hc":-11.5}],"tv":1.9}]}
{"op":"mcm","clk":"1005052582","pt":1580640375448,"mc":[{"id":"1.168230817","rc":[{"trd":[[1.02,0.64]],"batb":[[0,1.02,8.51]],"ltp":1.02,"tv":0.63,"id":2263600,"hc":-10.5}],"tv":1.92}]}
{"op":"mcm","clk":"1005052752","pt":1580640376653,"mc":[{"id":"1.168230817","rc":[{"trd":[[1.02,0.54]],"batb":[[0,1.02,8.57]],"ltp":1.02,"tv":0.54,"id":2263600,"hc":-9.5}],"tv":1.93}]}
{"op":"mcm","clk":"1005053100","pt":1580640379542,"mc":[{"id":"1.168230817","rc":[{"batl":[[0,1000,0.02]],"ltp":1.02,"tv":0.75,"id":2263600,"hc":-11.5}]}]}
{"op":"mcm","clk":"1005053248","pt":1580640380563,"mc":[{"id":"1.168230817","rc":[{"batl":[[0,1000,0.02]],"ltp":1.02,"tv":0.63,"id":2263600,"hc":-10.5},{"trd":[[1.02,0.78]],"batb":[[0,1.02,8.42]],"batl":[[0,990,0.01]],"ltp":1.02,"tv":0.77,"id":2263600,"hc":-11.5}],"tv":1.95}]}
{"op":"mcm","clk":"1005053385","pt":1580640381556,"mc":[{"id":"1.168230817","rc":[{"batl":[[0,1000,2.37]],"ltp":1.02,"tv":0.54,"id":2263600,"hc":-9.5},{"trd":[[1.02,0.65]],"batb":[[0,1.02,8.5]],"batl":[[0,990,0.01]],"ltp":1.02,"tv":0.65,"id":2263600,"hc":-10.5}],"tv":1.96}]}
{"op":"mcm","clk":"1005053454","pt":1580640382174,"mc":[{"id":"1.168230817","rc":[{"trd":[[1.02,0.56]],"batb":[[0,1.02,8.56]],"batl":[[0,990,0.01]],"ltp":1.02,"tv":0.55,"id":2263600,"hc":-9.5}],"tv":1.98}]}
{"op":"mcm","clk":"1005053760","pt":1580640384583,"mc":[{"id":"1.168230817","rc":[{"batl":[[0,1000,2.37]],"ltp":1.02,"tv":0.77,"id":2263600,"hc":-11.5}]}]}
{"op":"mcm","clk":"1005053915","pt":1580640385478,"mc":[{"id":"1.168230817","rc":[{"trd":[[1.02,0.79]],"batb":[[0,1.02,8.41]],"batl":[[0,990,0.01]],"ltp":1.02,"tv":0.79,"id":2263600,"hc":-11.5}],"tv":2.0}]}
{"op":"mcm","clk":"1005054053","pt":1580640386586,"mc":[{"id":"1.168230817","rc":[{"trd":[[1.02,0.67]],"batb":[[0,1.02,8.49]],"ltp":1.02,"tv":0.66,"id":2263600,"hc":-10.5}],"tv":2.01}]}
{"op":"mcm","clk":"1005054144","pt":1580640387274,"mc":[{"id":"1.168230817","rc":[{"trd":[[1.02,0.57]],"batb":[[0,1.02,8.55]],"ltp":1.02,"tv":0.57,"id":2263600,"hc":-9.5}],"tv":2.03}]}
{"op":"mcm","clk":"1005054581","pt":1580640390474,"mc":[{"id":"1.168230817","rc":[{"batl":[[0,1000,0.02]],"ltp":1.02,"tv":0.79,"id":2263600,"hc":-11.5}]}]}
{"op":"mcm","clk":"1005054744","pt":1580640391582,"mc":[{"id":"1.168230817","rc":[{"trd":[[1.02,0.81]],"batb":[[0,1.02,8.4]],"batl":[[0,990,0.01]],"ltp":1.02,"tv":0.8,"id":2263600,"hc":-11.5}],"tv":2.04}]}
{"op":"mcm","clk":"1005054853","pt":1580640392568,"mc":[{"id":"1.168230817","rc":[{"trd":[[1.02,0.68]],"batb":[[0,1.02,8.48]],"ltp":1.02,"tv":0.68,"id":2263600,"hc":-10.5}],"tv":2.06}]}
{"op":"mcm","clk":"1005054863","pt":1580640392680,"mc":[{"id":"1.168230817","rc":[{"trd":[[1.02,0.59]],"batb":[[0,1.02,8.54]],"ltp":1.02,"tv":0.58,"id":2263600,"hc":-9.5}],"tv":2.07}]}
{"op":"mcm","clk":"1005055237","pt":1580640395580,"mc":[{"id":"1.168230817","rc":[{"batl":[[0,1000,0.02]],"ltp":1.02,"tv":0.8,"id":2263600,"hc":-11.5}]}]}
{"op":"mcm","clk":"1005055359","pt":1580640396474,"mc":[{"id":"1.168230817","rc":[{"trd":[[1.02,0.82]],"batb":[[0,1.02,8.39]],"batl":[[0,990,0.01]],"ltp":1.02,"tv":0.82,"id":2263600,"hc":-11.5}],"tv":2.09}]}
{"op":"mcm","clk":"1005055492","pt":1580640397462,"mc":[{"id":"1.168230817","rc":[{"batl":[[0,1000,0.02]],"ltp":1.02,"tv":0.58,"id":2263600,"hc":-9.5},{"trd":[[1.02,0.7]],"batb":[[0,1.02,8.47]],"ltp":1.02,"tv":0.69,"id":2263600,"hc":-10.5}],"tv":2.1}]}
{"op":"mcm","clk":"1005055544","pt":1580640397888,"mc":[{"id":"1.168230817","rc":[{"trd":[[1.02,0.6]],"batb":[[0,1.02,8.53]],"batl":[[0,990,0.01]],"ltp":1.02,"tv":0.6,"id":2263600,"hc":-9.5}],"tv":2.12}]}
{"op":"mcm","clk":"1005055924","pt":1580640401182,"mc":[{"id":"1.168230817","rc":[{"trd":[[1.02,0.84]],"batb":[[0,1.02,8.38]],"ltp":1.02,"tv":0.83,"id":2263600,"hc":-11.5}],"tv":2.14}]}
{"op":"mcm","clk":"1005056081","pt":1580640402506,"mc":[{"id":"1.168230817","rc":[{"trd":[[1.02,0.71]],"batb":[[0,1.02,8.46]],"ltp":1.02,"tv":0.71,"id":2263600,"hc":-10.5}],"tv":2.15}]}
{"op":"mcm","clk":"1005056223","pt":1580640403498,"mc":[{"id":"1.168230817","rc":[{"trd":[[1.02,0.62]],"batb":[[0,1.02,8.52]],"ltp":1.02,"tv":0.62,"id":2263600,"hc":-9.5}],"tv":2.17}]}
{"op":"mcm","clk":"1005056621","pt":1580640406607,"mc":[{"id":"1.168230817","rc":[{"batl":[[0,1000,0.02]],"ltp":1.02,"tv":0.83,"id":2263600,"hc":-11.5}]}]}
{"op":"mcm","clk":"1005056748","pt":1580640407604,"mc":[{"id":"1.168230817","rc":[{"batl":[[0,1000,0.02]],"ltp":1.02,"tv":0.71,"id":2263600,"hc":-10.5},{"trd":[[1.02,0.85]],"batb":[[0,1.02,8.37]],"batl":[[0,990,0.01]],"ltp":1.02,"tv":0.85,"id":2263600,"hc":-11.5}],"tv":2.18}]}
{"op":"mcm","clk":"1005056876","pt":1580640408395,"mc":[{"id":"1.168230817","rc":[{"trd":[[1.02,0.64]],"batb":[[0,1.02,8.51]],"ltp":1.02,"tv":0.63,"id":2263600,"hc":-9.5},{"trd":[[1.02,0.73]],"batb":[[0,1.02,8.45]],"batl":[[0,990,0.01]],"ltp":1.02,"tv":0.72,"id":2263600,"hc":-10.5}],"tv":2.21}]}
{"op":"mcm","clk":"1005057472","pt":1580640412615,"mc":[{"id":"1.168230817","rc":[{"batl":[[0,1000,0.02]],"ltp":1.02,"tv":0.85,"id":2263600,"hc":-11.5}]}]}
{"op":"mcm","clk":"1005057613","pt":1580640413604,"mc":[{"id":"1.168230817","rc":[{"trd":[[1.02,0.87]],"batb":[[0,1.02,8.36]],"batl":[[0,990,0.01]],"ltp":1.02,"tv":0.86,"id":2263600,"hc":-11.5}],"tv":2.23}]}
{"op":"mcm","clk":"1005057704","pt":1580640414292,"mc":[{"id":"1.168230817","rc":[{"trd":[[1.02,0.65]],"batb":[[0,1.02,8.5]],"ltp":1.02,"tv":0.65,"id":2263600,"hc":-9.5},{"trd":[[1.02,0.74]],"batb":[[0,1.02,8.44]],"ltp":1.02,"tv":0.74,"id":2263600,"hc":-10.5}],"tv":2.26}]}
{"op":"mcm","clk":"1005058263","pt":1580640418609,"mc":[{"id":"1.168230817","rc":[{"batl":[[0,1000,2.37]],"ltp":1.02,"tv":0.74,"id":2263600,"hc":-10.5},{"trd":[[1.02,0.88]],"batb":[[0,1.02,8.35]],"ltp":1.02,"tv":0.88,"id":2263600,"hc":-11.5}],"tv":2.27}]}
{"op":"mcm","clk":"1005058354","pt":1580640419396,"mc":[{"id":"1.168230817","rc":[{"batl":[[0,1000,0.02]],"ltp":1.02,"tv":0.65,"id":2263600,"hc":-9.5},{"trd":[[1.02,0.76]],"batb":[[0,1.02,8.43]],"batl":[[0,990,0.01]],"ltp":1.02,"tv":0.75,"id":2263600,"hc":-10.5}],"tv":2.29}]}
{"op":"mcm","clk":"1005058439","pt":1580640419822,"mc":[{"id":"1.168230817","rc":[{"trd":[[1.02,0.67]],"batb":[[0,1.02,8.49]],"batl":[[0,990,0.01]],"ltp":1.02,"tv":0.66,"id":2263600,"hc":-9.5}],"tv":2.31}]}
{"op":"mcm","clk":"1005059069","pt":1580640424629,"mc":[{"id":"1.168230817","rc":[{"trd":[[1.02,0.9]],"batb":[[0,1.02,8.34]],"ltp":1.02,"tv":0.89,"id":2263600,"hc":-11.5}],"tv":2.32}]}
{"op":"mcm","clk":"1005059184","pt":1580640425407,"mc":[{"id":"1.168230817","rc":[{"trd":[[1.02,0.68]],"batb":[[0,1.02,8.48]],"ltp":1.02,"tv":0.68,"id":2263600,"hc":-9.5},{"trd":[[1.02,0.78]],"batb":[[0,1.02,8.42]],"ltp":1.02,"tv":0.77,"id":2263600,"hc":-10.5}],"tv":2.35}]}
{"op":"mcm","clk":"1005059573","pt":1580640428619,"mc":[{"id":"1.168230817","rc":[{"batl":[[0,1000,2.37]],"ltp":1.02,"tv":0.89,"id":2263600,"hc":-11.5}]}]}
{"op":"mcm","clk":"1005059696","pt":1580640429512,"mc":[{"id":"1.168230817","rc":[{"batl":[[0,1000,2.37]],"ltp":1.02,"tv":0.77,"id":2263600,"hc":-10.5},{"trd":[[1.02,0.91]],"batb":[[0,1.02,8.33]],"batl":[[0,990,0.01]],"ltp":1.02,"tv":0.91,"id":2263600,"hc":-11.5}],"tv":2.37}]}
{"op":"mcm","clk":"1005059803","pt":1580640430311,"mc":[{"id":"1.168230817","rc":[{"trd":[[1.02,0.7]],"batb":[[0,1.02,8.47]],"ltp":1.02,"tv":0.69,"id":2263600,"hc":-9.5},{"trd":[[1.02,0.79]],"batb":[[0,1.02,8.41]],"batl":[[0,990,0.01]],"ltp":1.02,"tv":0.79,"id":2263600,"hc":-10.5}],"tv":2.4}]}
{"op":"mcm","clk":"1005060333","pt":1580640434643,"mc":[{"id":"1.168230817","rc":[{"batl":[[0,1000,2.37]],"ltp":1.02,"tv":0.79,"id":2263600,"hc":-10.5},{"trd":[[1.02,0.93]],"batb":[[0,1.02,8.32]],"ltp":1.02,"tv":0.93,"id":2263600,"hc":-11.5}],"tv":2.41}]}
{"op":"mcm","clk":"1005060463","pt":1580640435640,"mc":[{"id":"1.168230817","rc":[{"trd":[[1.02,0.71]],"batb":[[0,1.02,8.46]],"ltp":1.02,"tv":0.71,"id":2263600,"hc":-9.5},{"trd":[[1.02,0.81]],"batb":[[0,1.02,8.4]],"batl":[[0,990,0.01]],"ltp":1.02,"tv":0.8,"id":2263600,"hc":-10.5}],"tv":2.45}]}
{"op":"mcm","clk":"1005060972","pt":1580640439639,"mc":[{"id":"1.168230817","rc":[{"batl":[[0,1000,2.37]],"ltp":1.02,"tv":0.93,"id":2263600,"hc":-11.5}]}]}
{"op":"mcm","clk":"1005061085","pt":1580640440631,"mc":[{"id":"1.168230817","rc":[{"trd":[[1.02,0.82]],"batb":[[0,1.02,8.39]],"ltp":1.02,"tv":0.82,"id":2263600,"hc":-10.5},{"trd":[[1.02,0.95]],"batb":[[0,1.02,8.31]],"batl":[[0,990,0.01]],"ltp":1.02,"tv":0.94,"id":2263600,"hc":-11.5}],"tv":2.48}]}
{"op":"mcm","clk":"1005061100","pt":1580640440736,"mc":[{"id":"1.168230817","rc":[{"trd":[[1.02,0.73]],"batb":[[0,1.02,8.45]],"ltp":1.02,"tv":0.72,"id":2263600,"hc":-9.5}],"tv":2.49}]}
{"op":"mcm","clk":"1005061688","pt":1580640445451,"mc":[{"id":"1.168230817","rc":[{"batl":[[0,1000,2.37]],"ltp":1.02,"tv":0.72,"id":2263600,"hc":-9.5},{"batl":[[0,1000,2.37]],"ltp":1.02,"tv":0.82,"id":2263600,"hc":-10.5},{"trd":[[1.02,0.96]],"batb":[[0,1.02,8.3]],"ltp":1.02,"tv":0.96,"id":2263600,"hc":-11.5}],"tv":2.51}]}
{"op":"mcm","clk":"1005061771","pt":1580640446025,"mc":[{"id":"1.168230817","rc":[{"trd":[[1.02,0.74]],"batb":[[0,1.02,8.44]],"batl":[[0,990,0.01]],"ltp":1.02,"tv":0.74,"id":2263600,"hc":-9.5},{"trd":[[1.02,0.84]],"batb":[[0,1.02,8.38]],"batl":[[0,990,0.01]],"ltp":1.02,"tv":0.83,"id":2263600,"hc":-10.5}],"tv":2.54}]}
{"op":"mcm","clk":"1005062298","pt":1580640450557,"mc":[{"id":"1.168230817","rc":[{"trd":[[1.02,0.98]],"batb":[[0,1.02,8.29]],"ltp":1.02,"tv":0.97,"id":2263600,"hc":-11.5}],"tv":2.55}]}
{"op":"mcm","clk":"1005062415","pt":1580640451445,"mc":[{"id":"1.168230817","rc":[{"trd":[[1.02,0.76]],"batb":[[0,1.02,8.43]],"ltp":1.02,"tv":0.75,"id":2263600,"hc":-9.5},{"trd":[[1.02,0.85]],"batb":[[0,1.02,8.37]],"ltp":1.02,"tv":0.85,"id":2263600,"hc":-10.5}],"tv":2.58}]}
{"op":"mcm","clk":"1005062855","pt":1580640455536,"mc":[{"id":"1.168230817","rc":[{"batl":[[0,1000,0.02]],"ltp":1.02,"tv":0.97,"id":2263600,"hc":-11.5}]}]}
{"op":"mcm","clk":"1005062981","pt":1580640456632,"mc":[{"id":"1.168230817","rc":[{"batl":[[0,1000,0.02]],"ltp":1.02,"tv":0.75,"id":2263600,"hc":-9.5},{"trd":[[1.02,0.87]],"batb":[[0,1.02,8.36]],"ltp":1.02,"tv":0.86,"id":2263600,"hc":-10.5},{"trd":[[1.02,0.99]],"batb":[[0,1.02,8.28]],"batl":[[0,990,0.01]],"ltp":1.02,"tv":0.99,"id":2263600,"hc":-11.5}],"tv":2.62}]}
{"op":"mcm","clk":"1005063008","pt":1580640456840,"mc":[{"id":"1.168230817","rc":[{"trd":[[1.02,0.78]],"batb":[[0,1.02,8.42]],"batl":[[0,990,0.01]],"ltp":1.02,"tv":0.77,"id":2263600,"hc":-9.5}],"tv":2.63}]}
{"op":"mcm","clk":"1005063599","pt":1580640461648,"mc":[{"id":"1.168230817","rc":[{"batl":[[0,1000,0.02]],"ltp":1.02,"tv":0.77,"id":2263600,"hc":-9.5},{"batl":[[0,1000,2.37]],"ltp":1.02,"tv":0.86,"id":2263600,"hc":-10.5},{"trd":[[1.02,1.01]],"batb":[[0,1.02,8.27]],"ltp":1.02,"tv":1.0,"id":2263600,"hc":-11.5}],"tv":2.65}]}
{"op":"mcm","clk":"1005063656","pt":1580640462172,"mc":[{"id":"1.168230817","rc":[{"trd":[[1.02,0.79]],"batb":[[0,1.02,8.41]],"batl":[[0,990,0.01]],"ltp":1.02,"tv":0.79,"id":2263600,"hc":-9.5},{"trd":[[1.02,0.88]],"batb":[[0,1.02,8.35]],"batl":[[0,990,0.01]],"ltp":1.02,"tv":0.88,"id":2263600,"hc":-10.5}],"tv":2.68}]}
{"op":"mcm","clk":"1005064149","pt":1580640466557,"mc":[{"id":"1.168230817","rc":[{"batl":[[0,1000,2.37]],"ltp":1.02,"tv":0.79,"id":2263600,"hc":-9.5},{"batl":[[0,1000,2.37]],"ltp":1.02,"tv":1.0,"id":2263600,"hc":-11.5}]}]}
{"op":"mcm","clk":"1005064290","pt":1580640467648,"mc":[{"id":"1.168230817","rc":[{"trd":[[1.02,0.81]],"batb":[[0,1.02,8.4]],"batl":[[0,990,0.01]],"ltp":1.02,"tv":0.8,"id":2263600,"hc":-9.5},{"batl":[[0,1000,0.02]],"ltp":1.02,"tv":0.88,"id":2263600,"hc":-10.5},{"trd":[[1.02,1.02]],"batb":[[0,1.02,8.26]],"batl":[[0,990,0.01]],"ltp":1.02,"tv":1.02,"id":2263600,"hc":-11.5}],"tv":2.71}]}
{"op":"mcm","clk":"1005064439","pt":1580640468864,"mc":[{"id":"1.168230817","rc":[{"trd":[[1.02,0.9]],"batb":[[0,1.02,8.34]],"batl":[[0,990,0.01]],"ltp":1.02,"tv":0.89,"id":2263600,"hc":-10.5}],"tv":2.72}]}
{"op":"mcm","clk":"1005064844","pt":1580640472558,"mc":[{"id":"1.168230817","rc":[{"trd":[[1.02,0.82]],"batb":[[0,1.02,8.39]],"ltp":1.02,"tv":0.82,"id":2263600,"hc":-9.5},{"trd":[[1.02,1.04]],"batb":[[0,1.02,8.25]],"ltp":1.02,"tv":1.03,"id":2263600,"hc":-11.5}],"tv":2.76}]}
{"op":"mcm","clk":"1005064965","pt":1580640473563,"mc":[{"id":"1.168230817","rc":[{"batl":[[0,1000,0.02]],"ltp":1.02,"tv":0.89,"id":2263600,"hc":-10.5}]}]}
{"op":"mcm","clk":"1005065004","pt":1580640473874,"mc":[{"id":"1.168230817","rc":[{"trd":[[1.02,0.91]],"batb":[[0,1.02,8.33]],"batl":[[0,990,0.01]],"ltp":1.02,"tv":0.91,"id":2263600,"hc":-10.5}],"tv":2.77}]}
{"op":"mcm","clk":"1005065390","pt":1580640477487,"mc":[{"id":"1.168230817","rc":[{"batl":[[0,1000,2.37]],"ltp":1.02,"tv":0.82,"id":2263600,"hc":-9.5},{"batl":[[0,1000,0.02]],"ltp":1.02,"tv":1.03,"id":2263600,"hc":-11.5}]}]}
{"op":"mcm","clk":"1005065500","pt":1580640478371,"mc":[{"id":"1.168230817","rc":[{"trd":[[1.02,0.84]],"batb":[[0,1.02,8.38]],"batl":[[0,990,0.01]],"ltp":1.02,"tv":0.83,"id":2263600,"hc":-9.5},{"batl":[[0,1000,0.02]],"ltp":1.02,"tv":0.91,"id":2263600,"hc":-10.5},{"trd":[[1.02,1.05]],"batb":[[0,1.02,8.24]],"batl":[[0,990,0.01]],"ltp":1.02,"tv":1.05,"id":2263600,"hc":-11.5}],"tv":2.8}]}
{"op":"mcm","clk":"1005065556","pt":1580640478801,"mc":[{"id":"1.168230817","rc":[{"trd":[[1.02,0.93]],"batb":[[0,1.02,8.32]],"batl":[[0,990,0.01]],"ltp":1.02,"tv":0.93,"id":2263600,"hc":-10.5}],"tv":2.82}]}
{"op":"mcm","clk":"1005066031","pt":1580640482591,"mc":[{"id":"1.168230817","rc":[{"batl":[[0,1000,2.37]],"ltp":1.02,"tv":1.05,"id":2263600,"hc":-11.5}]}]}
{"op":"mcm","clk":"1005066165","pt":1580640483582,"mc":[{"id":"1.168230817","rc":[{"trd":[[1.02,0.85]],"batb":[[0,1.02,8.37]],"ltp":1.02,"tv":0.85,"id":2263600,"hc":-9.5},{"batl":[[0,1000,2.37]],"ltp":1.02,"tv":0.93,"id":2263600,"hc":-10.5},{"trd":[[1.02,1.07]],"batb":[[0,1.02,8.23]],"batl":[[0,990,0.01]],"ltp":1.02,"tv":1.07,"id":2263600,"hc":-11.5}],"tv":2.85}]}
{"op":"mcm","clk":"1005066244","pt":1580640484207,"mc":[{"id":"1.168230817","rc":[{"trd":[[1.02,0.95]],"batb":[[0,1.02,8.31]],"batl":[[0,990,0.01]],"ltp":1.02,"tv":0.94,"id":2263600,"hc":-10.5}],"tv":2.86}]}
{"op":"mcm","clk":"1005066798","pt":1580640488600,"mc":[{"id":"1.168230817","rc":[{"trd":[[1.02,0.87]],"batb":[[0,1.02,8.36]],"ltp":1.02,"tv":0.86,"id":2263600,"hc":-9.5},{"batl":[[0,1000,0.02]],"ltp":1.02,"tv":1.07,"id":2263600,"hc":-11.5}],"tv":2.88}]}
{"op":"mcm","clk":"1005066935","pt":1580640489595,"mc":[{"id":"1.168230817","rc":[{"batl":[[0,1000,0.02]],"ltp":1.02,"tv":0.94,"id":2263600,"hc":-10.5},{"trd":[[1.02,1.09]],"batb":[[0,1.02,8.22]],"batl":[[0,990,0.01]],"ltp":1.02,"tv":1.08,"id":2263600,"hc":-11.5}],"tv":2.89}]}
{"op":"mcm","clk":"1005066961","pt":1580640489803,"mc":[{"id":"1.168230817","rc":[{"trd":[[1.02,0.96]],"batb":[[0,1.02,8.3]],"batl":[[0,990,0.01]],"ltp":1.02,"tv":0.96,"id":2263600,"hc":-10.5}],"tv":2.91}]}
{"op":"mcm","clk":"1005067392","pt":1580640493607,"mc":[{"id":"1.168230817","rc":[{"batl":[[0,1000,2.37]],"ltp":1.02,"tv":0.86,"id":2263600,"hc":-9.5},{"batl":[[0,1000,2.37]],"ltp":1.02,"tv":1.08,"id":2263600,"hc":-11.5}]}]}
{"op":"mcm","clk":"1005067509","pt":1580640494592,"mc":[{"id":"1.168230817","rc":[{"trd":[[1.02,0.88]],"batb":[[0,1.02,8.35]],"batl":[[0,990,0.01]],"ltp":1.02,"tv":0.88,"id":2263600,"hc":-9.5},{"trd":[[1.02,1.1]],"batb":[[0,1.02,8.21]],"batl":[[0,990,0.01]],"ltp":1.02,"tv":1.1,"id":2263600,"hc":-11.5}],"tv":2.94}]}
{"op":"mcm","clk":"1005067597","pt":1580640495319,"mc":[{"id":"1.168230817","rc":[{"trd":[[1.02,0.98]],"batb":[[0,1.02,8.29]],"ltp":1.02,"tv":0.97,"id":2263600,"hc":-10.5}],"tv":2.96}]}
{"op":"mcm","clk":"1005068117","pt":1580640499613,"mc":[{"id":"1.168230817","rc":[{"trd":[[1.02,0.9]],"batb":[[0,1.02,8.34]],"ltp":1.02,"tv":0.89,"id":2263600,"hc":-9.5}],"tv":2.97}]}
{"op":"mcm","clk":"1005068232","pt":1580640500510,"mc":[{"id":"1.168230817","rc":[{"trd":[[1.02,0.99]],"batb":[[0,1.02,8.28]],"ltp":1.02,"tv":0.99,"id":2263600,"hc":-10.5},{"trd":[[1.02,1.12]],"batb":[[0,1.02,8.2]],"ltp":1.02,"tv":1.11,"id":2263600,"hc":-11.5}],"tv":3.0}]}
{"op":"mcm","clk":"1005068638","pt":1580640504416,"mc":[{"id":"1.168230817","rc":[{"batl":[[0,1000,2.37]],"ltp":1.02,"tv":0.89,"id":2263600,"hc":-9.5}]}]}
{"op":"mcm","clk":"1005068792","pt":1580640505617,"mc":[{"id":"1.168230817","rc":[{"trd":[[1.02,0.91]],"batb":[[0,1.02,8.33]],"batl":[[0,990,0.01]],"ltp":1.02,"tv":0.91,"id":2263600,"hc":-9.5},{"batl":[[0,1000,2.37]],"ltp":1.02,"tv":0.99,"id":2263600,"hc":-10.5},{"trd":[[1.02,1.13]],"batb":[[0,1.02,8.19]],"ltp":1.02,"tv":1.13,"id":2263600,"hc":-11.5}],"tv":3.03}]}
{"op":"mcm","clk":"1005068902","pt":1580640506511,"mc":[{"id":"1.168230817","rc":[{"trd":[[1.02,1.01]],"batb":[[0,1.02,8.27]],"batl":[[0,990,0.01]],"ltp":1.02,"tv":1.0,"id":2263600,"hc":-10.5}],"tv":3.05}]}
{"op":"mcm","clk":"1005069368","pt":1580640510517,"mc":[{"id":"1.168230817","rc":[{"trd":[[1.02,0.93]],"batb":[[0,1.02,8.32]],"ltp":1.02,"tv":0.93,"id":2263600,"hc":-9.5},{"batl":[[0,1000,0.02]],"ltp":1.02,"tv":1.13,"id":2263600,"hc":-11.5}],"tv":3.07}]}
{"op":"mcm","clk":"1005069498","pt":1580640511549,"mc":[{"id":"1.168230817","rc":[{"batl":[[0,1000,0.02]],"ltp":1.02,"tv":1.0,"id":2263600,"hc":-10.5},{"trd":[[1.02,1.15]],"batb":[[0,1.02,8.18]],"batl":[[0,990,0.01]],"ltp":1.02,"tv":1.14,"id":2263600,"hc":-11.5}],"tv":3.08}]}
{"op":"mcm","clk":"1005069564","pt":1580640511932,"mc":[{"id":"1.168230817","rc":[{"trd":[[1.02,1.02]],"batb":[[0,1.02,8.26]],"batl":[[0,990,0.01]],"ltp":1.02,"tv":1.02,"id":2263600,"hc":-10.5}],"tv":3.1}]}
{"op":"mcm","clk":"1005070009","pt":1580640515624,"mc":[{"id":"1.168230817","rc":[{"batl":[[0,1000,2.37]],"ltp":1.02,"tv":0.93,"id":2263600,"hc":-9.5},{"batl":[[0,1000,2.37]],"ltp":1.02,"tv":1.14,"id":2263600,"hc":-11.5}]}]}
{"op":"mcm","clk":"1005070089","pt":1580640516353,"mc":[{"id":"1.168230817","rc":[{"trd":[[1.02,0.95]],"batb":[[0,1.02,8.31]],"batl":[[0,990,0.01]],"ltp":1.02,"tv":0.94,"id":2263600,"hc":-9.5},{"trd":[[1.02,1.16]],"batb":[[0,1.02,8.17]],"batl":[[0,990,0.01]],"ltp":1.02,"tv":1.16,"id":2263600,"hc":-11.5}],"tv":3.13}]}
{"op":"mcm","clk":"1005070240","pt":1580640517558,"mc":[{"id":"1.168230817","rc":[{"batl":[[0,1000,0.02]],"ltp":1.02,"tv":1.02,"id":2263600,"hc":-10.5}]}]}
{"op":"mcm","clk":"1005070287","pt":1580640517930,"mc":[{"id":"1.168230817","rc":[{"trd":[[1.02,1.04]],"batb":[[0,1.02,8.25]],"batl":[[0,990,0.01]],"ltp":1.02,"tv":1.03,"id":2263600,"hc":-10.5}],"tv":3.14}]}
{"op":"mcm","clk":"1005070703","pt":1580640521551,"mc":[{"id":"1.168230817","rc":[{"batl":[[0,1000,0.02]],"ltp":1.02,"tv":0.94,"id":2263600,"hc":-9.5},{"batl":[[0,1000,0.02]],"ltp":1.02,"tv":1.16,"id":2263600,"hc":-11.5}]}]}
{"op":"mcm","clk":"1005070829","pt":1580640522448,"mc":[{"id":"1.168230817","rc":[{"trd":[[1.02,0.96]],"batb":[[0,1.02,8.3]],"batl":[[0,990,0.01]],"ltp":1.02,"tv":0.96,"id":2263600,"hc":-9.5},{"trd":[[1.02,1.18]],"batb":[[0,1.02,8.16]],"batl":[[0,990,0.01]],"ltp":1.02,"tv":1.17,"id":2263600,"hc":-11.5}],"tv":3.17}]}
{"op":"mcm","clk":"1005070969","pt":1580640523538,"mc":[{"id":"1.168230817","rc":[{"batl":[[0,1000,0.02]],"ltp":1.02,"tv":1.03,"id":2263600,"hc":-10.5}]}]}
{"op":"mcm","clk":"1005071028","pt":1580640523956,"mc":[{"id":"1.168230817","rc":[{"trd":[[1.02,1.05]],"batb":[[0,1.02,8.24]],"batl":[[0,990,0.01]],"ltp":1.02,"tv":1.05,"id":2263600,"hc":-10.5}],"tv":3.19}]}
{"op":"mcm","clk":"1005071536","pt":1580640527435,"mc":[{"id":"1.168230817","rc":[{"trd":[[1.02,0.98]],"batb":[[0,1.02,8.29]],"ltp":1.02,"tv":0.97,"id":2263600,"hc":-9.5},{"trd":[[1.02,1.19]],"batb":[[0,1.02,8.15]],"ltp":1.02,"tv":1.19,"id":2263600,"hc":-11.5}],"tv":3.22}]}
{"op":"mcm","clk":"1005071784","pt":1580640529576,"mc":[{"id":"1.168230817","rc":[{"trd":[[1.02,1.07]],"batb":[[0,1.02,8.23]],"ltp":1.02,"tv":1.07,"id":2263600,"hc":-10.5}],"tv":3.24}]}
{"op":"mcm","clk":"1005072129","pt":1580640532551,"mc":[{"id":"1.168230817","rc":[{"trd":[[1.02,0.99]],"batb":[[0,1.02,8.28]],"ltp":1.02,"tv":0.99,"id":2263600,"hc":-9.5},{"batl":[[0,1000,0.02]],"ltp":1.02,"tv":1.19,"id":2263600,"hc":-11.5}],"tv":3.25}]}
{"op":"mcm","clk":"1005072254","pt":1580640533578,"mc":[{"id":"1.168230817","rc":[{"trd":[[1.02,1.21]],"batb":[[0,1.02,8.14]],"batl":[[0,990,0.01]],"ltp":1.02,"tv":1.2,"id":2263600,"hc":-11.5}],"tv":3.27}]}
{"op":"mcm","clk":"1005072368","pt":1580640534472,"mc":[{"id":"1.168230817","rc":[{"batl":[[0,1000,2.37]],"ltp":1.02,"tv":1.07,"id":2263600,"hc":-10.5}]}]}
{"op":"mcm","clk":"1005072454","pt":1580640535149,"mc":[{"id":"1.168230817","rc":[{"trd":[[1.02,1.09]],"batb":[[0,1.02,8.22]],"batl":[[0,990,0.01]],"ltp":1.02,"tv":1.08,"id":2263600,"hc":-10.5}],"tv":3.28}]}
{"op":"mcm","clk":"1005072729","pt":1580640537459,"mc":[{"id":"1.168230817","rc":[{"trd":[[1.02,1.01]],"batb":[[0,1.02,8.27]],"ltp":1.02,"tv":1.0,"id":2263600,"hc":-9.5},{"batl":[[0,1000,2.37]],"ltp":1.02,"tv":1.2,"id":2263600,"hc":-11.5}],"tv":3.3}]}
{"op":"mcm","clk":"1005072835","pt":1580640538181,"mc":[{"id":"1.168230817","rc":[{"trd":[[1.02,1.23]],"batb":[[0,1.02,8.13]],"batl":[[0,990,0.01]],"ltp":1.02,"tv":1.22,"id":2263600,"hc":-11.5}],"tv":3.31}]}
{"op":"mcm","clk":"1005073173","pt":1580640540470,"mc":[{"id":"1.168230817","rc":[{"trd":[[1.02,1.1]],"batb":[[0,1.02,8.21]],"ltp":1.02,"tv":1.1,"id":2263600,"hc":-10.5}],"tv":3.33}]}
{"op":"mcm","clk":"1005073418","pt":1580640542402,"mc":[{"id":"1.168230817","rc":[{"batl":[[0,1000,0.02]],"ltp":1.02,"tv":1.0,"id":2263600,"hc":-9.5}]}]}
{"op":"mcm","clk":"1005073579","pt":1580640543562,"mc":[{"id":"1.168230817","rc":[{"trd":[[1.02,1.02]],"batb":[[0,1.02,8.26]],"batl":[[0,990,0.01]],"ltp":1.02,"tv":1.02,"id":2263600,"hc":-9.5},{"trd":[[1.02,1.24]],"batb":[[0,1.02,8.12]],"ltp":1.02,"tv":1.24,"id":2263600,"hc":-11.5}],"tv":3.36}]}
{"op":"mcm","clk":"1005073843","pt":1580640545477,"mc":[{"id":"1.168230817","rc":[{"batl":[[0,1000,2.37]],"ltp":1.02,"tv":1.1,"id":2263600,"hc":-10.5}]}]}
{"op":"mcm","clk":"1005073917","pt":1580640546102,"mc":[{"id":"1.168230817","rc":[{"trd":[[1.02,1.12]],"batb":[[0,1.02,8.2]],"batl":[[0,990,0.01]],"ltp":1.02,"tv":1.11,"id":2263600,"hc":-10.5}],"tv":3.38}]}
{"op":"mcm","clk":"1005074083","pt":1580640547502,"mc":[{"id":"1.168230817","rc":[{"batl":[[0,1000,2.37]],"ltp":1.02,"tv":1.02,"id":2263600,"hc":-9.5}]}]}
{"op":"mcm","clk":"1005074238","pt":1580640548597,"mc":[{"id":"1.168230817","rc":[{"trd":[[1.02,1.04]],"batb":[[0,1.02,8.25]],"batl":[[0,990,0.01]],"ltp":1.02,"tv":1.03,"id":2263600,"hc":-9.5},{"batl":[[0,1000,2.37]],"ltp":1.02,"tv":1.24,"id":2263600,"hc":-11.5}],"tv":3.39}]}
{"op":"mcm","clk":"1005074293","pt":1580640549013,"mc":[{"id":"1.168230817","rc":[{"trd":[[1.02,1.26]],"batb":[[0,1.02,8.11]],"batl":[[0,990,0.01]],"ltp":1.02,"tv":1.25,"id":2263600,"hc":-11.5}],"tv":3.41}]}
{"op":"mcm","clk":"1005074525","pt":1580640550676,"mc":[{"id":"1.168230817","rc":[{"trd":[[1.02,1.13]],"batb":[[0,1.02,8.19]],"ltp":1.02,"tv":1.13,"id":2263600,"hc":-10.5}],"tv":3.42}]}
{"op":"mcm","clk":"1005074775","pt":1580640552512,"mc":[{"id":"1.168230817","rc":[{"batl":[[0,1000,2.37]],"ltp":1.02,"tv":1.03,"id":2263600,"hc":-9.5}]}]}
{"op":"mcm","clk":"1005074942","pt":1580640553613,"mc":[{"id":"1.168230817","rc":[{"trd":[[1.02,1.05]],"batb":[[0,1.02,8.24]],"batl":[[0,990,0.01]],"ltp":1.02,"tv":1.05,"id":2263600,"hc":-9.5},{"batl":[[0,1000,2.37]],"ltp":1.02,"tv":1.25,"id":2263600,"hc":-11.5}],"tv":3.44}]}
{"op":"mcm","clk":"1005075015","pt":1580640554087,"mc":[{"id":"1.168230817","rc":[{"trd":[[1.02,1.27]],"batb":[[0,1.02,8.1]],"batl":[[0,990,0.01]],"ltp":1.02,"tv":1.27,"id":2263600,"hc":-11.5}],"tv":3.45}]}
{"op":"mcm","clk":"1005075209","pt":1580640555595,"mc":[{"id":"1.168230817","rc":[{"batl":[[0,1000,2.37]],"ltp":1.02,"tv":1.13,"id":2263600,"hc":-10.5}]}]}
{"op":"mcm","clk":"1005075289","pt":1580640556115,"mc":[{"id":"1.168230817","rc":[{"trd":[[1.02,1.15]],"batb":[[0,1.02,8.18]],"batl":[[0,990,0.01]],"ltp":1.02,"tv":1.14,"id":2263600,"hc":-10.5}],"tv":3.47}]}
{"op":"mcm","clk":"1005075619","pt":1580640558505,"mc":[{"id":"1.168230817","rc":[{"trd":[[1.02,1.07]],"batb":[[0,1.02,8.23]],"ltp":1.02,"tv":1.07,"id":2263600,"hc":-9.5}],"tv":3.48}]}
{"op":"mcm","clk":"1005075784","pt":1580640559709,"mc":[{"id":"1.168230817","rc":[{"trd":[[1.02,1.29]],"batb":[[0,1.02,8.09]],"ltp":1.02,"tv":1.28,"id":2263600,"hc":-11.5}],"tv":3.5}]}
{"op":"mcm","clk":"1005076003","pt":1580640561600,"mc":[{"id":"1.168230817","rc":[{"trd":[[1.02,1.16]],"batb":[[0,1.02,8.17]],"ltp":1.02,"tv":1.16,"id":2263600,"hc":-10.5}],"tv":3.52}]}
{"op":"mcm","clk":"1005076222","pt":1580640563624,"mc":[{"id":"1.168230817","rc":[{"batl":[[0,1000,0.02]],"ltp":1.02,"tv":1.07,"id":2263600,"hc":-9.5}]}]}
{"op":"mcm","clk":"1005076334","pt":1580640564610,"mc":[{"id":"1.168230817","rc":[{"trd":[[1.02,1.09]],"batb":[[0,1.02,8.22]],"batl":[[0,990,0.01]],"ltp":1.02,"tv":1.08,"id":2263600,"hc":-9.5},{"batl":[[0,1000,0.02]],"ltp":1.02,"tv":1.28,"id":2263600,"hc":-11.5}],"tv":3.53}]}
{"op":"mcm","clk":"1005076373","pt":1580640564919,"mc":[{"id":"1.168230817","rc":[{"trd":[[1.02,1.3]],"batb":[[0,1.02,8.08]],"batl":[[0,990,0.01]],"ltp":1.02,"tv":1.3,"id":2263600,"hc":-11.5}],"tv":3.55}]}
{"op":"mcm","clk":"1005076570","pt":1580640566530,"mc":[{"id":"1.168230817","rc":[{"batl":[[0,1000,2.37]],"ltp":1.02,"tv":1.16,"id":2263600,"hc":-10.5}]}]}
{"op":"mcm","clk":"1005076652","pt":1580640567103,"mc":[{"id":"1.168230817","rc":[{"trd":[[1.02,1.18]],"batb":[[0,1.02,8.16]],"batl":[[0,990,0.01]],"ltp":1.02,"tv":1.17,"id":2263600,"hc":-10.5}],"tv":3.56}]}
{"op":"mcm","clk":"1005076843","pt":1580640568616,"mc":[{"id":"1.168230817","rc":[{"batl":[[0,1000,2.37]],"ltp":1.02,"tv":1.08,"id":2263600,"hc":-9.5}]}]}
{"op":"mcm","clk":"1005076897","pt":1580640569001,"mc":[{"id":"1.168230817","rc":[{"trd":[[1.02,1.1]],"batb":[[0,1.02,8.21]],"batl":[[0,990,0.01]],"ltp":1.02,"tv":1.1,"id":2263600,"hc":-9.5}],"tv":3.58}]}
{"op":"mcm","clk":"1005077126","pt":1580640570823,"mc":[{"id":"1.168230817","rc":[{"trd":[[1.02,1.32]],"batb":[[0,1.02,8.07]],"ltp":1.02,"tv":1.31,"id":2263600,"hc":-11.5}],"tv":3.59}]}
{"op":"mcm","clk":"1005077344","pt":1580640572442,"mc":[{"id":"1.168230817","rc":[{"trd":[[1.02,1.19]],"batb":[[0,1.02,8.15]],"ltp":1.02,"tv":1.19,"id":2263600,"hc":-10.5}],"tv":3.61}]}
{"op":"mcm","clk":"1005077473","pt":1580640573648,"mc":[{"id":"1.168230817","rc":[{"batl":[[0,1000,2.37]],"ltp":1.02,"tv":1.1,"id":2263600,"hc":-9.5}]}]}
{"op":"mcm","clk":"1005077554","pt":1580640574228,"mc":[{"id":"1.168230817","rc":[{"trd":[[1.02,1.12]],"batb":[[0,1.02,8.2]],"batl":[[0,990,0.01]],"ltp":1.02,"tv":1.11,"id":2263600,"hc":-9.5}],"tv":3.62}]}
{"op":"mcm","clk":"1005077714","pt":1580640575638,"mc":[{"id":"1.168230817","rc":[{"batl":[[0,1000,0.02]],"ltp":1.02,"tv":1.31,"id":2263600,"hc":-11.5}]}]}
{"op":"mcm","clk":"1005077768","pt":1580640576006,"mc":[{"id":"1.168230817","rc":[{"trd":[[1.02,1.33]],"batb":[[0,1.02,8.06]],"batl":[[0,990,0.01]],"ltp":1.02,"tv":1.33,"id":2263600,"hc":-11.5}],"tv":3.64}]}
{"op":"mcm","clk":"1005078078","pt":1580640578516,"mc":[{"id":"1.168230817","rc":[{"trd":[[1.02,1.21]],"batb":[[0,1.02,8.14]],"ltp":1.02,"tv":1.2,"id":2263600,"hc":-10.5}],"tv":3.65}]}
{"op":"mcm","clk":"1005078206","pt":1580640579618,"mc":[{"id":"1.168230817","rc":[{"trd":[[1.02,1.13]],"batb":[[0,1.02,8.19]],"ltp":1.02,"tv":1.13,"id":2263600,"hc":-9.5}],"tv":3.67}]}
{"op":"mcm","clk":"1005078416","pt":1580640581354,"mc":[{"id":"1.168230817","rc":[{"trd":[[1.02,1.35]],"batb":[[0,1.02,8.05]],"ltp":1.02,"tv":1.34,"id":2263600,"hc":-11.5}],"tv":3.69}]}
{"op":"mcm","clk":"1005078590","pt":1580640582550,"mc":[{"id":"1.168230817","rc":[{"batl":[[0,1000,2.37]],"ltp":1.02,"tv":1.2,"id":2263600,"hc":-10.5}]}]}
{"op":"mcm","clk":"1005078653","pt":1580640583019,"mc":[{"id":"1.168230817","rc":[{"trd":[[1.02,1.23]],"batb":[[0,1.02,8.13]],"batl":[[0,990,0.01]],"ltp":1.02,"tv":1.22,"id":2263600,"hc":-10.5}],"tv":3.7}]}
{"op":"mcm","clk":"1005078841","pt":1580640584648,"mc":[{"id":"1.168230817","rc":[{"trd":[[1.02,1.15]],"batb":[[0,1.02,8.18]],"ltp":1.02,"tv":1.14,"id":2263600,"hc":-9.5}],"tv":3.72}]}
{"op":"mcm","clk":"1005079085","pt":1580640586542,"mc":[{"id":"1.168230817","rc":[{"batl":[[0,1000,0.02]],"ltp":1.02,"tv":1.34,"id":2263600,"hc":-11.5}]}]}
{"op":"mcm","clk":"1005079162","pt":1580640587169,"mc":[{"id":"1.168230817","rc":[{"trd":[[1.02,1.36]],"batb":[[0,1.02,8.04]],"batl":[[0,990,0.01]],"ltp":1.02,"tv":1.36,"id":2263600,"hc":-11.5}],"tv":3.73}]}
{"op":"mcm","clk":"1005079360","pt":1580640588534,"mc":[{"id":"1.168230817","rc":[{"batl":[[0,1000,0.02]],"ltp":1.02,"tv":1.22,"id":2263600,"hc":-10.5}]}]}
{"op":"mcm","clk":"1005079508","pt":1580640589630,"mc":[{"id":"1.168230817","rc":[{"batl":[[0,1000,0.02]],"ltp":1.02,"tv":1.14,"id":2263600,"hc":-9.5},{"trd":[[1.02,1.24]],"batb":[[0,1.02,8.12]],"batl":[[0,990,0.01]],"ltp":1.02,"tv":1.24,"id":2263600,"hc":-10.5}],"tv":3.75}]}
{"op":"mcm","clk":"1005079551","pt":1580640589942,"mc":[{"id":"1.168230817","rc":[{"trd":[[1.02,1.16]],"batb":[[0,1.02,8.17]],"batl":[[0,990,0.01]],"ltp":1.02,"tv":1.16,"id":2263600,"hc":-9.5}],"tv":3.76}]}
{"op":"mcm","clk":"1005079856","pt":1580640592349,"mc":[{"id":"1.168230817","rc":[{"trd":[[1.02,1.38]],"batb":[[0,1.02,8.03]],"ltp":1.02,"tv":1.38,"id":2263600,"hc":-11.5}],"tv":3.78}]}
{"op":"mcm","clk":"1005080005","pt":1580640593548,"mc":[{"id":"1.168230817","rc":[{"batl":[[0,1000,0.02]],"ltp":1.02,"tv":1.24,"id":2263600,"hc":-10.5}]}]}
{"op":"mcm","clk":"1005080158","pt":1580640594647,"mc":[{"id":"1.168230817","rc":[{"batl":[[0,1000,2.37]],"ltp":1.02,"tv":1.16,"id":2263600,"hc":-9.5},{"trd":[[1.02,1.26]],"batb":[[0,1.02,8.11]],"batl":[[0,990,0.01]],"ltp":1.02,"tv":1.25,"id":2263600,"hc":-10.5}],"tv":3.79}]}
{"op":"mcm","clk":"1005080234","pt":1580640595270,"mc":[{"id":"1.168230817","rc":[{"trd":[[1.02,1.18]],"batb":[[0,1.02,8.16]],"batl":[[0,990,0.01]],"ltp":1.02,"tv":1.17,"id":2263600,"hc":-9.5}],"tv":3.81}]}
{"op":"mcm","clk":"1005080549","pt":1580640597573,"mc":[{"id":"1.168230817","rc":[{"trd":[[1.02,1.4]],"batb":[[0,1.02,8.02]],"ltp":1.02,"tv":1.39,"id":2263600,"hc":-11.5}],"tv":3.83}]}
{"op":"mcm","clk":"1005080796","pt":1580640599153,"mc":[{"id":"1.168230817","rc":[{"trd":[[1.02,1.27]],"batb":[[0,1.02,8.1]],"ltp":1.02,"tv":1.27,"id":2263600,"hc":-10.5}],"tv":3.84}]}
{"op":"mcm","clk":"1005080976","pt":1580640600476,"mc":[{"id":"1.168230817","rc":[{"trd":[[1.02,1.19]],"batb":[[0,1.02,8.15]],"ltp":1.02,"tv":1.19,"id":2263600,"hc":-9.5}],"tv":3.86}]}
{"op":"mcm","clk":"1005081256","pt":1580640602465,"mc":[{"id":"1.168230817","rc":[{"batl":[[0,1000,2.37]],"ltp":1.02,"tv":1.39,"id":2263600,"hc":-11.5}]}]}
{"op":"mcm","clk":"1005081340","pt":1580640603089,"mc":[{"id":"1.168230817","rc":[{"trd":[[1.02,1.41]],"batb":[[0,1.02,8.01]],"batl":[[0,990,0.01]],"ltp":1.02,"tv":1.41,"id":2263600,"hc":-11.5}],"tv":3.87}]}
{"op":"mcm","clk":"1005081508","pt":1580640604365,"mc":[{"id":"1.168230817","rc":[{"batl":[[0,1000,0.02]],"ltp":1.02,"tv":1.27,"id":2263600,"hc":-10.5}]}]}
{"op":"mcm","clk":"1005081683","pt":1580640605563,"mc":[{"id":"1.168230817","rc":[{"batl":[[0,1000,0.02]],"ltp":1.02,"tv":1.19,"id":2263600,"hc":-9.5},{"trd":[[1.02,1.29]],"batb":[[0,1.02,8.09]],"batl":[[0,990,0.01]],"ltp":1.02,"tv":1.28,"id":2263600,"hc":-10.5}],"tv":3.89}]}
{"op":"mcm","clk":"1005081730","pt":1580640605986,"mc":[{"id":"1.168230817","rc":[{"trd":[[1.02,1.21]],"batb":[[0,1.02,8.14]],"batl":[[0,990,0.01]],"ltp":1.02,"tv":1.2,"id":2263600,"hc":-9.5}],"tv":3.9}]}
{"op":"mcm","clk":"1005082247","pt":1580640609552,"mc":[{"id":"1.168230817","rc":[{"batl":[[0,1000,2.37]],"ltp":1.02,"tv":1.28,"id":2263600,"hc":-10.5},{"trd":[[1.02,1.43]],"batb":[[0,1.02,8]],"ltp":1.02,"tv":1.42,"id":2263600,"hc":-11.5}],"tv":3.92}]}
{"op":"mcm","clk":"1005082390","pt":1580640610595,"mc":[{"id":"1.168230817","rc":[{"trd":[[1.02,1.3]],"batb":[[0,1.02,8.08]],"batl":[[0,990,0.01]],"ltp":1.02,"tv":1.3,"id":2263600,"hc":-10.5}],"tv":3.93}]}
{"op":"mcm","clk":"1005082484","pt":1580640611379,"mc":[{"id":"1.168230817","rc":[{"trd":[[1.02,1.23]],"batb":[[0,1.02,8.13]],"ltp":1.02,"tv":1.22,"id":2263600,"hc":-9.5}],"tv":3.95}]}
{"op":"mcm","clk":"1005082749","pt":1580640613479,"mc":[{"id":"1.168230817","rc":[{"batl":[[0,1000,0.02]],"ltp":1.02,"tv":1.42,"id":2263600,"hc":-11.5}]}]}
{"op":"mcm","clk":"1005082794","pt":1580640613787,"mc":[{"id":"1.168230817","rc":[{"trd":[[1.02,1.44]],"batb":[[0,1.02,7.99]],"batl":[[0,990,0.01]],"ltp":1.02,"tv":1.44,"id":2263600,"hc":-11.5}],"tv":3.96}]}
{"op":"mcm","clk":"1005083059","pt":1580640615557,"mc":[{"id":"1.168230817","rc":[{"batl":[[0,1000,0.02]],"ltp":1.02,"tv":1.3,"id":2263600,"hc":-10.5}]}]}
{"op":"mcm","clk":"1005083192","pt":1580640616498,"mc":[{"id":"1.168230817","rc":[{"trd":[[1.02,1.24]],"batb":[[0,1.02,8.12]],"ltp":1.02,"tv":1.24,"id":2263600,"hc":-9.5},{"trd":[[1.02,1.32]],"batb":[[0,1.02,8.07]],"batl":[[0,990,0.01]],"ltp":1.02,"tv":1.31,"id":2263600,"hc":-10.5}],"tv":4.0}]}
{"op":"mcm","clk":"1005083478","pt":1580640618590,"mc":[{"id":"1.168230817","rc":[{"batl":[[0,1000,2.37]],"ltp":1.02,"tv":1.44,"id":2263600,"hc":-11.5}]}]}
{"op":"mcm","clk":"1005083598","pt":1580640619268,"mc":[{"id":"1.168230817","rc":[{"trd":[[1.02,1.46]],"batb":[[0,1.02,7.98]],"batl":[[0,990,0.01]],"ltp":1.02,"tv":1.45,"id":2263600,"hc":-11.5}],"tv":4.01}]}
{"op":"mcm","clk":"1005083919","pt":1580640621611,"mc":[{"id":"1.168230817","rc":[{"batl":[[0,1000,0.02]],"ltp":1.02,"tv":1.24,"id":2263600,"hc":-9.5},{"trd":[[1.02,1.33]],"batb":[[0,1.02,8.06]],"ltp":1.02,"tv":1.33,"id":2263600,"hc":-10.5}],"tv":4.03}]}
{"op":"mcm","clk":"1005083973","pt":1580640621979,"mc":[{"id":"1.168230817","rc":[{"trd":[[1.02,1.26]],"batb":[[0,1.02,8.11]],"batl":[[0,990,0.01]],"ltp":1.02,"tv":1.25,"id":2263600,"hc":-9.5}],"tv":4.04}]}
{"op":"mcm","clk":"1005084262","pt":1580640624415,"mc":[{"id":"1.168230817","rc":[{"trd":[[1.02,1.47]],"batb":[[0,1.02,7.97]],"ltp":1.02,"tv":1.47,"id":2263600,"hc":-11.5}],"tv":4.06}]}
{"op":"mcm","clk":"1005084568","pt":1580640626594,"mc":[{"id":"1.168230817","rc":[{"batl":[[0,1000,2.37]],"ltp":1.02,"tv":1.25,"id":2263600,"hc":-9.5},{"trd":[[1.02,1.35]],"batb":[[0,1.02,8.05]],"ltp":1.02,"tv":1.34,"id":2263600,"hc":-10.5}],"tv":4.07}]}
{"op":"mcm","clk":"1005084653","pt":1580640627222,"mc":[{"id":"1.168230817","rc":[{"trd":[[1.02,1.27]],"batb":[[0,1.02,8.1]],"batl":[[0,990,0.01]],"ltp":1.02,"tv":1.27,"id":2263600,"hc":-9.5}],"tv":4.09}]}
{"op":"mcm","clk":"1005084943","pt":1580640629426,"mc":[{"id":"1.168230817","rc":[{"batl":[[0,1000,0.02]],"ltp":1.02,"tv":1.47,"id":2263600,"hc":-11.5}]}]}
{"op":"mcm","clk":"1005084999","pt":1580640629791,"mc":[{"id":"1.168230817","rc":[{"trd":[[1.02,1.49]],"batb":[[0,1.02,7.96]],"batl":[[0,990,0.01]],"ltp":1.02,"tv":1.48,"id":2263600,"hc":-11.5}],"tv":4.1}]}
{"op":"mcm","clk":"1005085236","pt":1580640631422,"mc":[{"id":"1.168230817","rc":[{"batl":[[0,1000,0.02]],"ltp":1.02,"tv":1.34,"id":2263600,"hc":-10.5}]}]}
{"op":"mcm","clk":"1005085374","pt":1580640632410,"mc":[{"id":"1.168230817","rc":[{"batl":[[0,1000,0.02]],"ltp":1.02,"tv":1.27,"id":2263600,"hc":-9.5},{"trd":[[1.02,1.36]],"batb":[[0,1.02,8.04]],"batl":[[0,990,0.01]],"ltp":1.02,"tv":1.36,"id":2263600,"hc":-10.5}],"tv":4.12}]}
{"op":"mcm","clk":"1005085421","pt":1580640632830,"mc":[{"id":"1.168230817","rc":[{"trd":[[1.02,1.29]],"batb":[[0,1.02,8.09]],"batl":[[0,990,0.01]],"ltp":1.02,"tv":1.28,"id":2263600,"hc":-9.5}],"tv":4.14}]}
{"op":"mcm","clk":"1005085742","pt":1580640635303,"mc":[{"id":"1.168230817","rc":[{"trd":[[1.02,1.5]],"batb":[[0,1.02,7.95]],"ltp":1.02,"tv":1.5,"id":2263600,"hc":-11.5}],"tv":4.15}]}
{"op":"mcm","clk":"1005086078","pt":1580640637488,"mc":[{"id":"1.168230817","rc":[{"trd":[[1.02,1.3]],"batb":[[0,1.02,8.08]],"ltp":1.02,"tv":1.3,"id":2263600,"hc":-9.5},{"trd":[[1.02,1.38]],"batb":[[0,1.02,8.03]],"ltp":1.02,"tv":1.38,"id":2263600,"hc":-10.5}],"tv":4.18}]}
{"op":"mcm","clk":"1005086493","pt":1580640640417,"mc":[{"id":"1.168230817","rc":[{"trd":[[1.02,1.52]],"batb":[[0,1.02,7.94]],"ltp":1.02,"tv":1.51,"id":2263600,"hc":-11.5}],"tv":4.2}]}
{"op":"mcm","clk":"1005086790","pt":1580640642509,"mc":[{"id":"1.168230817","rc":[{"trd":[[1.02,1.32]],"batb":[[0,1.02,8.07]],"ltp":1.02,"tv":1.31,"id":2263600,"hc":-9.5},{"batl":[[0,1000,0.02]],"ltp":1.02,"tv":1.38,"id":2263600,"hc":-10.5}],"tv":4.21}]}
{"op":"mcm","clk":"1005086828","pt":1580640642819,"mc":[{"id":"1.168230817","rc":[{"trd":[[1.02,1.4]],"batb":[[0,1.02,8.02]],"batl":[[0,990,0.01]],"ltp":1.02,"tv":1.39,"id":2263600,"hc":-10.5}],"tv":4.23}]}
{"op":"mcm","clk":"1005087168","pt":1580640645642,"mc":[{"id":"1.168230817","rc":[{"batl":[[0,1000,0.02]],"ltp":1.02,"tv":1.51,"id":2263600,"hc":-11.5}]}]}
{"op":"mcm","clk":"1005087211","pt":1580640645951,"mc":[{"id":"1.168230817","rc":[{"trd":[[1.02,1.54]],"batb":[[0,1.02,7.93]],"batl":[[0,990,0.01]],"ltp":1.02,"tv":1.53,"id":2263600,"hc":-11.5}],"tv":4.24}]}
{"op":"mcm","clk":"1005087397","pt":1580640647624,"mc":[{"id":"1.168230817","rc":[{"batl":[[0,1000,0.02]],"ltp":1.02,"tv":1.31,"id":2263600,"hc":-9.5},{"batl":[[0,1000,2.37]],"ltp":1.02,"tv":1.39,"id":2263600,"hc":-10.5}]}]}
{"op":"mcm","clk":"1005087482","pt":1580640648455,"mc":[{"id":"1.168230817","rc":[{"trd":[[1.02,1.33]],"batb":[[0,1.02,8.06]],"batl":[[0,990,0.01]],"ltp":1.02,"tv":1.33,"id":2263600,"hc":-9.5},{"trd":[[1.02,1.41]],"batb":[[0,1.02,8.01]],"batl":[[0,990,0.01]],"ltp":1.02,"tv":1.41,"id":2263600,"hc":-10.5}],"tv":4.28}]}
{"op":"mcm","clk":"1005087826","pt":1580640651427,"mc":[{"id":"1.168230817","rc":[{"trd":[[1.02,1.55]],"batb":[[0,1.02,7.92]],"ltp":1.02,"tv":1.55,"id":2263600,"hc":-11.5}],"tv":4.29}]}
{"op":"mcm","clk":"1005088058","pt":1580640653643,"mc":[{"id":"1.168230817","rc":[{"trd":[[1.02,1.35]],"batb":[[0,1.02,8.05]],"ltp":1.02,"tv":1.34,"id":2263600,"hc":-9.5},{"batl":[[0,1000,0.02]],"ltp":1.02,"tv":1.41,"id":2263600,"hc":-10.5}],"tv":4.31}]}
{"op":"mcm","clk":"1005088115","pt":1580640654056,"mc":[{"id":"1.168230817","rc":[{"trd":[[1.02,1.43]],"batb":[[0,1.02,8]],"batl":[[0,990,0.01]],"ltp":1.02,"tv":1.42,"id":2263600,"hc":-10.5}],"tv":4.32}]}
{"op":"mcm","clk":"1005088399","pt":1580640656558,"mc":[{"id":"1.168230817","rc":[{"batl":[[0,1000,0.02]],"ltp":1.02,"tv":1.55,"id":2263600,"hc":-11.5}]}]}
{"op":"mcm","clk":"1005088442","pt":1580640656922,"mc":[{"id":"1.168230817","rc":[{"trd":[[1.02,1.57]],"batb":[[0,1.02,7.91]],"batl":[[0,990,0.01]],"ltp":1.02,"tv":1.56,"id":2263600,"hc":-11.5}],"tv":4.34}]}
{"op":"mcm","clk":"1005088631","pt":1580640658528,"mc":[{"id":"1.168230817","rc":[{"trd":[[1.02,1.36]],"batb":[[0,1.02,8.04]],"ltp":1.02,"tv":1.36,"id":2263600,"hc":-9.5}],"tv":4.35}]}
{"op":"mcm","clk":"1005088747","pt":1580640659418,"mc":[{"id":"1.168230817","rc":[{"trd":[[1.02,1.44]],"batb":[[0,1.02,7.99]],"ltp":1.02,"tv":1.44,"id":2263600,"hc":-10.5}],"tv":4.37}]}
{"op":"mcm","clk":"1005089062","pt":1580640662345,"mc":[{"id":"1.168230817","rc":[{"batl":[[0,1000,0.02]],"ltp":1.02,"tv":1.56,"id":2263600,"hc":-11.5}]}]}
{"op":"mcm","clk":"1005089219","pt":1580640663540,"mc":[{"id":"1.168230817","rc":[{"batl":[[0,1000,0.02]],"ltp":1.02,"tv":1.36,"id":2263600,"hc":-9.5},{"trd":[[1.02,1.58]],"batb":[[0,1.02,7.9]],"batl":[[0,990,0.01]],"ltp":1.02,"tv":1.58,"id":2263600,"hc":-11.5}],"tv":4.38}]}
{"op":"mcm","clk":"1005089328","pt":1580640664424,"mc":[{"id":"1.168230817","rc":[{"trd":[[1.02,1.38]],"batb":[[0,1.02,8.03]],"batl":[[0,990,0.01]],"ltp":1.02,"tv":1.38,"id":2263600,"hc":-9.5},{"batl":[[0,1000,0.02]],"ltp":1.02,"tv":1.44,"id":2263600,"hc":-10.5}],"tv":4.4}]}
{"op":"mcm","clk":"1005089383","pt":1580640664876,"mc":[{"id":"1.168230817","rc":[{"trd":[[1.02,1.46]],"batb":[[0,1.02,7.98]],"batl":[[0,990,0.01]],"ltp":1.02,"tv":1.45,"id":2263600,"hc":-10.5}],"tv":4.41}]}
{"op":"mcm","clk":"1005089698","pt":1580640667549,"mc":[{"id":"1.168230817","rc":[{"batl":[[0,1000,2.37]],"ltp":1.02,"tv":1.58,"id":2263600,"hc":-11.5}]}]}
{"op":"mcm","clk":"1005089757","pt":1580640668066,"mc":[{"id":"1.168230817","rc":[{"trd":[[1.02,1.6]],"batb":[[0,1.02,7.89]],"batl":[[0,990,0.01]],"ltp":1.02,"tv":1.59,"id":2263600,"hc":-11.5}],"tv":4.43}]}
{"op":"mcm","clk":"1005089925","pt":1580640669236,"mc":[{"id":"1.168230817","rc":[{"trd":[[1.02,1.4]],"batb":[[0,1.02,8.02]],"ltp":1.02,"tv":1.39,"id":2263600,"hc":-9.5}],"tv":4.45}]}
{"op":"mcm","clk":"1005090108","pt":1580640670445,"mc":[{"id":"1.168230817","rc":[{"trd":[[1.02,1.47]],"batb":[[0,1.02,7.97]],"ltp":1.02,"tv":1.47,"id":2263600,"hc":-10.5}],"tv":4.46}]}
{"op":"mcm","clk":"1005090421","pt":1580640673393,"mc":[{"id":"1.168230817","rc":[{"trd":[[1.02,1.61]],"batb":[[0,1.02,7.88]],"ltp":1.02,"tv":1.61,"id":2263600,"hc":-11.5}],"tv":4.48}]}
{"op":"mcm","clk":"1005090590","pt":1580640674639,"mc":[{"id":"1.168230817","rc":[{"trd":[[1.02,1.41]],"batb":[[0,1.02,8.01]],"ltp":1.02,"tv":1.41,"id":2263600,"hc":-9.5}],"tv":4.49}]}
{"op":"mcm","clk":"1005090699","pt":1580640675466,"mc":[{"id":"1.168230817","rc":[{"batl":[[0,1000,2.37]],"ltp":1.02,"tv":1.47,"id":2263600,"hc":-10.5}]}]}
{"op":"mcm","clk":"1005090776","pt":1580640676042,"mc":[{"id":"1.168230817","rc":[{"trd":[[1.02,1.49]],"batb":[[0,1.02,7.96]],"batl":[[0,990,0.01]],"ltp":1.02,"tv":1.48,"id":2263600,"hc":-10.5}],"tv":4.51}]}
{"op":"mcm","clk":"1005091058","pt":1580640678581,"mc":[{"id":"1.168230817","rc":[{"batl":[[0,1000,0.02]],"ltp":1.02,"tv":1.61,"id":2263600,"hc":-11.5}]}]}
{"op":"mcm","clk":"1005091173","pt":1580640679477,"mc":[{"id":"1.168230817","rc":[{"batl":[[0,1000,2.37]],"ltp":1.02,"tv":1.41,"id":2263600,"hc":-9.5},{"trd":[[1.02,1.63]],"batb":[[0,1.02,7.87]],"batl":[[0,990,0.01]],"ltp":1.02,"tv":1.62,"id":2263600,"hc":-11.5}],"tv":4.52}]}
{"op":"mcm","clk":"1005091245","pt":1580640680058,"mc":[{"id":"1.168230817","rc":[{"trd":[[1.02,1.43]],"batb":[[0,1.02,8]],"batl":[[0,990,0.01]],"ltp":1.02,"tv":1.42,"id":2263600,"hc":-9.5}],"tv":4.54}]}
{"op":"mcm","clk":"1005091420","pt":1580640681370,"mc":[{"id":"1.168230817","rc":[{"trd":[[1.02,1.5]],"batb":[[0,1.02,7.95]],"ltp":1.02,"tv":1.5,"id":2263600,"hc":-10.5}],"tv":4.55}]}
{"op":"mcm","clk":"1005091650","pt":1580640683476,"mc":[{"id":"1.168230817","rc":[{"batl":[[0,1000,2.37]],"ltp":1.02,"tv":1.62,"id":2263600,"hc":-11.5}]}]}
{"op":"mcm","clk":"1005091749","pt":1580640684168,"mc":[{"id":"1.168230817","rc":[{"trd":[[1.02,1.64]],"batb":[[0,1.02,7.86]],"batl":[[0,990,0.01]],"ltp":1.02,"tv":1.64,"id":2263600,"hc":-11.5}],"tv":4.57}]}
{"op":"mcm","clk":"1005091904","pt":1580640685469,"mc":[{"id":"1.168230817","rc":[{"trd":[[1.02,1.44]],"batb":[[0,1.02,7.99]],"ltp":1.02,"tv":1.44,"id":2263600,"hc":-9.5}],"tv":4.59}]}
{"op":"mcm","clk":"1005092021","pt":1580640686459,"mc":[{"id":"1.168230817","rc":[{"batl":[[0,1000,0.02]],"ltp":1.02,"tv":1.5,"id":2263600,"hc":-10.5}]}]}
{"op":"mcm","clk":"1005092059","pt":1580640686775,"mc":[{"id":"1.168230817","rc":[{"trd":[[1.02,1.52]],"batb":[[0,1.02,7.94]],"batl":[[0,990,0.01]],"ltp":1.02,"tv":1.51,"id":2263600,"hc":-10.5}],"tv":4.6}]}
{"op":"mcm","clk":"1005092345","pt":1580640689606,"mc":[{"id":"1.168230817","rc":[{"batl":[[0,1000,0.02]],"ltp":1.02,"tv":1.64,"id":2263600,"hc":-11.5}]}]}
{"op":"mcm","clk":"1005092465","pt":1580640690599,"mc":[{"id":"1.168230817","rc":[{"batl":[[0,1000,0.02]],"ltp":1.02,"tv":1.44,"id":2263600,"hc":-9.5},{"trd":[[1.02,1.66]],"batb":[[0,1.02,7.85]],"batl":[[0,990,0.01]],"ltp":1.02,"tv":1.65,"id":2263600,"hc":-11.5}],"tv":4.62}]}
{"op":"mcm","clk":"1005092512","pt":1580640690975,"mc":[{"id":"1.168230817","rc":[{"trd":[[1.02,1.46]],"batb":[[0,1.02,7.98]],"batl":[[0,990,0.01]],"ltp":1.02,"tv":1.45,"id":2263600,"hc":-9.5}],"tv":4.63}]}
{"op":"mcm","clk":"1005092699","pt":1580640692489,"mc":[{"id":"1.168230817","rc":[{"trd":[[1.02,1.54]],"batb":[[0,1.02,7.93]],"ltp":1.02,"tv":1.53,"id":2263600,"hc":-10.5}],"tv":4.65}]}
{"op":"mcm","clk":"1005092900","pt":1580640694588,"mc":[{"id":"1.168230817","rc":[{"batl":[[0,1000,0.02]],"ltp":1.02,"tv":1.65,"id":2263600,"hc":-11.5}]}]}
{"op":"mcm","clk":"1005092996","pt":1580640695581,"mc":[{"id":"1.168230817","rc":[{"batl":[[0,1000,2.37]],"ltp":1.02,"tv":1.45,"id":2263600,"hc":-9.5},{"trd":[[1.02,1.67]],"batb":[[0,1.02,7.84]],"batl":[[0,990,0.01]],"ltp":1.02,"tv":1.67,"id":2263600,"hc":-11.5}],"tv":4.66}]}
{"op":"mcm","clk":"1005093071","pt":1580640696280,"mc":[{"id":"1.168230817","rc":[{"trd":[[1.02,1.47]],"batb":[[0,1.02,7.97]],"batl":[[0,990,0.01]],"ltp":1.02,"tv":1.47,"id":2263600,"hc":-9.5}],"tv":4.68}]}
{"op":"mcm","clk":"1005093226","pt":1580640697583,"mc":[{"id":"1.168230817","rc":[{"batl":[[0,1000,0.02]],"ltp":1.02,"tv":1.53,"id":2263600,"hc":-10.5}]}]}
{"op":"mcm","clk":"1005093266","pt":1580640698003,"mc":[{"id":"1.168230817","rc":[{"trd":[[1.02,1.55]],"batb":[[0,1.02,7.92]],"batl":[[0,990,0.01]],"ltp":1.02,"tv":1.55,"id":2263600,"hc":-10.5}],"tv":4.69}]}
{"op":"mcm","clk":"1005093448","pt":1580640699577,"mc":[{"id":"1.168230817","rc":[{"batl":[[0,1000,2.37]],"ltp":1.02,"tv":1.67,"id":2263600,"hc":-11.5}]}]}
{"op":"mcm","clk":"1005093518","pt":1580640700305,"mc":[{"id":"1.168230817","rc":[{"trd":[[1.02,1.69]],"batb":[[0,1.02,7.83]],"batl":[[0,990,0.01]],"ltp":1.02,"tv":1.69,"id":2263600,"hc":-11.5}],"tv":4.71}]}
{"op":"mcm","clk":"1005093671","pt":1580640701614,"mc":[{"id":"1.168230817","rc":[{"trd":[[1.02,1.49]],"batb":[[0,1.02,7.96]],"ltp":1.02,"tv":1.48,"id":2263600,"hc":-9.5}],"tv":4.72}]}
{"op":"mcm","clk":"1005093790","pt":1580640702508,"mc":[{"id":"1.168230817","rc":[{"batl":[[0,1000,2.37]],"ltp":1.02,"tv":1.55,"id":2263600,"hc":-10.5}]}]}
{"op":"mcm","clk":"1005093937","pt":1580640703601,"mc":[{"id":"1.168230817","rc":[{"trd":[[1.02,1.57]],"batb":[[0,1.02,7.91]],"batl":[[0,990,0.01]],"ltp":1.02,"tv":1.56,"id":2263600,"hc":-10.5}],"tv":4.74}]}
{"op":"mcm","clk":"1005094184","pt":1580640705596,"mc":[{"id":"1.168230817","rc":[{"batl":[[0,1000,2.37]],"ltp":1.02,"tv":1.69,"id":2263600,"hc":-11.5}]}]}
{"op":"mcm","clk":"1005094300","pt":1580640706587,"mc":[{"id":"1.168230817","rc":[{"batl":[[0,1000,0.02]],"ltp":1.02,"tv":1.48,"id":2263600,"hc":-9.5},{"trd":[[1.02,1.71]],"batb":[[0,1.02,7.82]],"batl":[[0,990,0.01]],"ltp":1.02,"tv":1.7,"id":2263600,"hc":-11.5}],"tv":4.76}]}
{"op":"mcm","clk":"1005094339","pt":1580640707008,"mc":[{"id":"1.168230817","rc":[{"trd":[[1.02,1.5]],"batb":[[0,1.02,7.95]],"batl":[[0,990,0.01]],"ltp":1.02,"tv":1.5,"id":2263600,"hc":-9.5}],"tv":4.77}]}
{"op":"mcm","clk":"1005094523","pt":1580640708619,"mc":[{"id":"1.168230817","rc":[{"batl":[[0,1000,2.37]],"ltp":1.02,"tv":1.56,"id":2263600,"hc":-10.5}]}]}
{"op":"mcm","clk":"1005094633","pt":1580640709507,"mc":[{"id":"1.168230817","rc":[{"trd":[[1.02,1.58]],"batb":[[0,1.02,7.9]],"batl":[[0,990,0.01]],"ltp":1.02,"tv":1.58,"id":2263600,"hc":-10.5}],"tv":4.79}]}
{"op":"mcm","clk":"1005094862","pt":1580640711591,"mc":[{"id":"1.168230817","rc":[{"batl":[[0,1000,0.02]],"ltp":1.02,"tv":1.7,"id":2263600,"hc":-11.5}]}]}
{"op":"mcm","clk":"1005094954","pt":1580640712420,"mc":[{"id":"1.168230817","rc":[{"trd":[[1.02,1.52]],"batb":[[0,1.02,7.94]],"ltp":1.02,"tv":1.51,"id":2263600,"hc":-9.5},{"trd":[[1.02,1.72]],"batb":[[0,1.02,7.81]],"batl":[[0,990,0.01]],"ltp":1.02,"tv":1.72,"id":2263600,"hc":-11.5}],"tv":4.82}]}
{"op":"mcm","clk":"1005095209","pt":1580640714501,"mc":[{"id":"1.168230817","rc":[{"batl":[[0,1000,2.37]],"ltp":1.02,"tv":1.58,"id":2263600,"hc":-10.5}]}]}
{"op":"mcm","clk":"1005095351","pt":1580640715387,"mc":[{"id":"1.168230817","rc":[{"trd":[[1.02,1.6]],"batb":[[0,1.02,7.89]],"batl":[[0,990,0.01]],"ltp":1.02,"tv":1.59,"id":2263600,"hc":-10.5}],"tv":4.83}]}
{"op":"mcm","clk":"1005095467","pt":1580640716628,"mc":[{"id":"1.168230817","rc":[{"batl":[[0,1000,0.02]],"ltp":1.02,"tv":1.72,"id":2263600,"hc":-11.5}]}]}
{"op":"mcm","clk":"1005095606","pt":1580640717615,"mc":[{"id":"1.168230817","rc":[{"batl":[[0,1000,2.37]],"ltp":1.02,"tv":1.51,"id":2263600,"hc":-9.5},{"trd":[[1.02,1.74]],"batb":[[0,1.02,7.8]],"batl":[[0,990,0.01]],"ltp":1.02,"tv":1.73,"id":2263600,"hc":-11.5}],"tv":4.85}]}
{"op":"mcm","clk":"1005095714","pt":1580640718297,"mc":[{"id":"1.168230817","rc":[{"trd":[[1.02,1.54]],"batb":[[0,1.02,7.93]],"batl":[[0,990,0.01]],"ltp":1.02,"tv":1.53,"id":2263600,"hc":-9.5}],"tv":4.86}]}
{"op":"mcm","clk":"1005095992","pt":1580640720441,"mc":[{"id":"1.168230817","rc":[{"batl":[[0,1000,0.02]],"ltp":1.02,"tv":1.59,"id":2263600,"hc":-10.5}]}]}
{"op":"mcm","clk":"1005096037","pt":1580640720807,"mc":[{"id":"1.168230817","rc":[{"trd":[[1.02,1.61]],"batb":[[0,1.02,7.88]],"batl":[[0,990,0.01]],"ltp":1.02,"tv":1.61,"id":2263600,"hc":-10.5}],"tv":4.88}]}
{"op":"mcm","clk":"1005096259","pt":1580640722643,"mc":[{"id":"1.168230817","rc":[{"trd":[[1.02,1.75]],"batb":[[0,1.02,7.79]],"ltp":1.02,"tv":1.75,"id":2263600,"hc":-11.5}],"tv":4.9}]}
{"op":"mcm","clk":"1005096382","pt":1580640723640,"mc":[{"id":"1.168230817","rc":[{"trd":[[1.02,1.55]],"batb":[[0,1.02,7.92]],"ltp":1.02,"tv":1.55,"id":2263600,"hc":-9.5}],"tv":4.91}]}
{"op":"mcm","clk":"1005096606","pt":1580640725622,"mc":[{"id":"1.168230817","rc":[{"batl":[[0,1000,2.37]],"ltp":1.02,"tv":1.61,"id":2263600,"hc":-10.5}]}]}
{"op":"mcm","clk":"1005096686","pt":1580640726304,"mc":[{"id":"1.168230817","rc":[{"trd":[[1.02,1.63]],"batb":[[0,1.02,7.87]],"batl":[[0,990,0.01]],"ltp":1.02,"tv":1.62,"id":2263600,"hc":-10.5}],"tv":4.93}]}
{"op":"mcm","clk":"1005096820","pt":1580640727621,"mc":[{"id":"1.168230817","rc":[{"batl":[[0,1000,0.02]],"ltp":1.02,"tv":1.75,"id":2263600,"hc":-11.5}]}]}
{"op":"mcm","clk":"1005096919","pt":1580640728600,"mc":[{"id":"1.168230817","rc":[{"trd":[[1.02,1.77]],"batb":[[0,1.02,7.78]],"batl":[[0,990,0.01]],"ltp":1.02,"tv":1.76,"id":2263600,"hc":-11.5}],"tv":4.94}]}
{"op":"mcm","clk":"1005097014","pt":1580640729429,"mc":[{"id":"1.168230817","rc":[{"trd":[[1.02,1.57]],"batb":[[0,1.02,7.91]],"ltp":1.02,"tv":1.56,"id":2263600,"hc":-9.5}],"tv":4.96}]}
{"op":"mcm","clk":"1005097228","pt":1580640731408,"mc":[{"id":"1.168230817","rc":[{"batl":[[0,1000,0.02]],"ltp":1.02,"tv":1.62,"id":2263600,"hc":-10.5}]}]}
{"op":"mcm","clk":"1005097263","pt":1580640731730,"mc":[{"id":"1.168230817","rc":[{"trd":[[1.02,1.64]],"batb":[[0,1.02,7.86]],"batl":[[0,990,0.01]],"ltp":1.02,"tv":1.64,"id":2263600,"hc":-10.5}],"tv":4.97}]}
{"op":"mcm","clk":"1005097449","pt":1580640733523,"mc":[{"id":"1.168230817","rc":[{"trd":[[1.02,1.78]],"batb":[[0,1.02,7.77]],"ltp":1.02,"tv":1.78,"id":2263600,"hc":-11.5}],"tv":4.99}]}
{"op":"mcm","clk":"1005097582","pt":1580640734618,"mc":[{"id":"1.168230817","rc":[{"batl":[[0,1000,0.02]],"ltp":1.02,"tv":1.56,"id":2263600,"hc":-9.5}]}]}
{"op":"mcm","clk":"1005097602","pt":1580640734825,"mc":[{"id":"1.168230817","rc":[{"trd":[[1.02,1.58]],"batb":[[0,1.02,7.9]],"batl":[[0,990,0.01]],"ltp":1.02,"tv":1.58,"id":2263600,"hc":-9.5}],"tv":5.0}]}
{"op":"mcm","clk":"1005097892","pt":1580640737224,"mc":[{"id":"1.168230817","rc":[{"trd":[[1.02,1.66]],"batb":[[0,1.02,7.85]],"ltp":1.02,"tv":1.65,"id":2263600,"hc":-10.5}],"tv":5.02}]}
{"op":"mcm","clk":"1005098040","pt":1580640738534,"mc":[{"id":"1.168230817","rc":[{"batl":[[0,1000,0.02]],"ltp":1.02,"tv":1.78,"id":2263600,"hc":-11.5}]}]}
{"op":"mcm","clk":"1005098141","pt":1580640739421,"mc":[{"id":"1.168230817","rc":[{"batl":[[0,1000,2.37]],"ltp":1.02,"tv":1.58,"id":2263600,"hc":-9.5},{"trd":[[1.02,1.8]],"batb":[[0,1.02,7.76]],"batl":[[0,990,0.01]],"ltp":1.02,"tv":1.79,"id":2263600,"hc":-11.5}],"tv":5.04}]}
{"op":"mcm","clk":"1005098210","pt":1580640740143,"mc":[{"id":"1.168230817","rc":[{"trd":[[1.02,1.6]],"batb":[[0,1.02,7.89]],"batl":[[0,990,0.01]],"ltp":1.02,"tv":1.59,"id":2263600,"hc":-9.5}],"tv":5.05}]}
{"op":"mcm","clk":"1005098463","pt":1580640742643,"mc":[{"id":"1.168230817","rc":[{"trd":[[1.02,1.67]],"batb":[[0,1.02,7.84]],"ltp":1.02,"tv":1.67,"id":2263600,"hc":-10.5}],"tv":5.07}]}
{"op":"mcm","clk":"1005098654","pt":1580640744355,"mc":[{"id":"1.168230817","rc":[{"trd":[[1.02,1.81]],"batb":[[0,1.02,7.75]],"ltp":1.02,"tv":1.81,"id":2263600,"hc":-11.5}],"tv":5.08}]}
{"op":"mcm","clk":"1005098801","pt":1580640745658,"mc":[{"id":"1.168230817","rc":[{"trd":[[1.02,1.61]],"batb":[[0,1.02,7.88]],"ltp":1.02,"tv":1.61,"id":2263600,"hc":-9.5}],"tv":5.1}]}
{"op":"mcm","clk":"1005099031","pt":1580640747551,"mc":[{"id":"1.168230817","rc":[{"batl":[[0,1000,2.37]],"ltp":1.02,"tv":1.67,"id":2263600,"hc":-10.5}]}]}
{"op":"mcm","clk":"1005099109","pt":1580640748268,"mc":[{"id":"1.168230817","rc":[{"trd":[[1.02,1.69]],"batb":[[0,1.02,7.83]],"batl":[[0,990,0.01]],"ltp":1.02,"tv":1.69,"id":2263600,"hc":-10.5}],"tv":5.11}]}
{"op":"mcm","clk":"1005099394","pt":1580640750573,"mc":[{"id":"1.168230817","rc":[{"batl":[[0,1000,0.02]],"ltp":1.02,"tv":1.61,"id":2263600,"hc":-9.5},{"trd":[[1.02,1.83]],"batb":[[0,1.02,7.74]],"ltp":1.02,"tv":1.82,"id":2263600,"hc":-11.5}],"tv":5.13}]}
{"op":"mcm","clk":"1005099430","pt":1580640750843,"mc":[{"id":"1.168230817","rc":[{"trd":[[1.02,1.63]],"batb":[[0,1.02,7.87]],"batl":[[0,990,0.01]],"ltp":1.02,"tv":1.62,"id":2263600,"hc":-9.5}],"tv":5.14}]}
{"op":"mcm","clk":"1005099722","pt":1580640753550,"mc":[{"id":"1.168230817","rc":[{"trd":[[1.02,1.71]],"batb":[[0,1.02,7.82]],"ltp":1.02,"tv":1.7,"id":2263600,"hc":-10.5}],"tv":5.16}]}
{"op":"mcm","clk":"1005099844","pt":1580640754472,"mc":[{"id":"1.168230817","rc":[{"batl":[[0,1000,2.37]],"ltp":1.02,"tv":1.82,"id":2263600,"hc":-11.5}]}]}
{"op":"mcm","clk":"1005099972","pt":1580640755579,"mc":[{"id":"1.168230817","rc":[{"trd":[[1.02,1.85]],"batb":[[0,1.02,7.73]],"batl":[[0,990,0.01]],"ltp":1.02,"tv":1.84,"id":2263600,"hc":-11.5}],"tv":5.17}]}
{"op":"mcm","clk":"1005100056","pt":1580640756154,"mc":[{"id":"1.168230817","rc":[{"trd":[[1.02,1.64]],"batb":[[0,1.02,7.86]],"ltp":1.02,"tv":1.64,"id":2263600,"hc":-9.5}],"tv":5.19}]}
{"op":"mcm","clk":"1005100332","pt":1580640758597,"mc":[{"id":"1.168230817","rc":[{"batl":[[0,1000,0.02]],"ltp":1.02,"tv":1.7,"id":2263600,"hc":-10.5}]}]}
{"op":"mcm","clk":"1005100387","pt":1580640758963,"mc":[{"id":"1.168230817","rc":[{"trd":[[1.02,1.72]],"batb":[[0,1.02,7.81]],"batl":[[0,990,0.01]],"ltp":1.02,"tv":1.72,"id":2263600,"hc":-10.5}],"tv":5.21}]}
{"op":"mcm","clk":"1005100581","pt":1580640760584,"mc":[{"id":"1.168230817","rc":[{"trd":[[1.02,1.86]],"batb":[[0,1.02,7.72]],"ltp":1.02,"tv":1.86,"id":2263600,"hc":-11.5}],"tv":5.22}]}
{"op":"mcm","clk":"1005100706","pt":1580640761577,"mc":[{"id":"1.168230817","rc":[{"trd":[[1.02,1.66]],"batb":[[0,1.02,7.85]],"ltp":1.02,"tv":1.65,"id":2263600,"hc":-9.5}],"tv":5.24}]}
{"op":"mcm","clk":"1005101055","pt":1580640764364,"mc":[{"id":"1.168230817","rc":[{"trd":[[1.02,1.74]],"batb":[[0,1.02,7.8]],"ltp":1.02,"tv":1.73,"id":2263600,"hc":-10.5}],"tv":5.25}]}
{"op":"mcm","clk":"1005101183","pt":1580640765362,"mc":[{"id":"1.168230817","rc":[{"batl":[[0,1000,0.02]],"ltp":1.02,"tv":1.86,"id":2263600,"hc":-11.5}]}]}
{"op":"mcm","clk":"1005101334","pt":1580640766597,"mc":[{"id":"1.168230817","rc":[{"batl":[[0,1000,0.02]],"ltp":1.02,"tv":1.65,"id":2263600,"hc":-9.5},{"trd":[[1.02,1.88]],"batb":[[0,1.02,7.71]],"batl":[[0,990,0.01]],"ltp":1.02,"tv":1.87,"id":2263600,"hc":-11.5}],"tv":5.27}]}
{"op":"mcm","clk":"1005101377","pt":1580640766964,"mc":[{"id":"1.168230817","rc":[{"trd":[[1.02,1.67]],"batb":[[0,1.02,7.84]],"batl":[[0,990,0.01]],"ltp":1.02,"tv":1.67,"id":2263600,"hc":-9.5}],"tv":5.28}]}
{"op":"mcm","clk":"1005101840","pt":1580640770563,"mc":[{"id":"1.168230817","rc":[{"trd":[[1.02,1.75]],"batb":[[0,1.02,7.79]],"ltp":1.02,"tv":1.75,"id":2263600,"hc":-10.5}],"tv":5.3}]}
{"op":"mcm","clk":"1005101991","pt":1580640771493,"mc":[{"id":"1.168230817","rc":[{"trd":[[1.02,1.89]],"batb":[[0,1.02,7.7]],"ltp":1.02,"tv":1.89,"id":2263600,"hc":-11.5}],"tv":5.31}]}
{"op":"mcm","clk":"1005102104","pt":1580640772483,"mc":[{"id":"1.168230817","rc":[{"trd":[[1.02,1.69]],"batb":[[0,1.02,7.83]],"ltp":1.02,"tv":1.69,"id":2263600,"hc":-9.5}],"tv":5.33}]}
{"op":"mcm","clk":"1005102385","pt":1580640775383,"mc":[{"id":"1.168230817","rc":[{"trd":[[1.02,1.77]],"batb":[[0,1.02,7.78]],"ltp":1.02,"tv":1.76,"id":2263600,"hc":-10.5}],"tv":5.35}]}
{"op":"mcm","clk":"1005102492","pt":1580640776485,"mc":[{"id":"1.168230817","rc":[{"batl":[[0,1000,2.37]],"ltp":1.02,"tv":1.89,"id":2263600,"hc":-11.5}]}]}
{"op":"mcm","clk":"1005102632","pt":1580640777617,"mc":[{"id":"1.168230817","rc":[{"batl":[[0,1000,2.37]],"ltp":1.02,"tv":1.69,"id":2263600,"hc":-9.5},{"trd":[[1.02,1.91]],"batb":[[0,1.02,7.69]],"batl":[[0,990,0.01]],"ltp":1.02,"tv":1.9,"id":2263600,"hc":-11.5}],"tv":5.36}]}
{"op":"mcm","clk":"1005102688","pt":1580640777990,"mc":[{"id":"1.168230817","rc":[{"trd":[[1.02,1.71]],"batb":[[0,1.02,7.82]],"batl":[[0,990,0.01]],"ltp":1.02,"tv":1.7,"id":2263600,"hc":-9.5}],"tv":5.38}]}
{"op":"mcm","clk":"1005102977","pt":1580640780491,"mc":[{"id":"1.168230817","rc":[{"batl":[[0,1000,2.37]],"ltp":1.02,"tv":1.76,"id":2263600,"hc":-10.5}]}]}
{"op":"mcm","clk":"1005103055","pt":1580640781108,"mc":[{"id":"1.168230817","rc":[{"trd":[[1.02,1.78]],"batb":[[0,1.02,7.77]],"batl":[[0,990,0.01]],"ltp":1.02,"tv":1.78,"id":2263600,"hc":-10.5}],"tv":5.39}]}
{"op":"mcm","clk":"1005103217","pt":1580640782585,"mc":[{"id":"1.168230817","rc":[{"trd":[[1.02,1.92]],"batb":[[0,1.02,7.68]],"ltp":1.02,"tv":1.92,"id":2263600,"hc":-11.5}],"tv":5.41}]}
{"op":"mcm","clk":"1005103348","pt":1580640783624,"mc":[{"id":"1.168230817","rc":[{"trd":[[1.02,1.72]],"batb":[[0,1.02,7.81]],"ltp":1.02,"tv":1.72,"id":2263600,"hc":-9.5}],"tv":5.42}]}
{"op":"mcm","clk":"1005103835","pt":1580640787592,"mc":[{"id":"1.168230817","rc":[{"trd":[[1.02,1.8]],"batb":[[0,1.02,7.76]],"ltp":1.02,"tv":1.79,"id":2263600,"hc":-10.5},{"batl":[[0,1000,2.37]],"ltp":1.02,"tv":1.92,"id":2263600,"hc":-11.5}],"tv":5.44}]}
{"op":"mcm","clk":"1005103946","pt":1580640788631,"mc":[{"id":"1.168230817","rc":[{"batl":[[0,1000,2.37]],"ltp":1.02,"tv":1.72,"id":2263600,"hc":-9.5},{"trd":[[1.02,1.94]],"batb":[[0,1.02,7.67]],"batl":[[0,990,0.01]],"ltp":1.02,"tv":1.93,"id":2263600,"hc":-11.5}],"tv":5.45}]}
{"op":"mcm","clk":"1005104015","pt":1580640789197,"mc":[{"id":"1.168230817","rc":[{"trd":[[1.02,1.74]],"batb":[[0,1.02,7.8]],"batl":[[0,990,0.01]],"ltp":1.02,"tv":1.73,"id":2263600,"hc":-9.5}],"tv":5.47}]}
{"op":"mcm","clk":"1005104277","pt":1580640791589,"mc":[{"id":"1.168230817","rc":[{"batl":[[0,1000,2.37]],"ltp":1.02,"tv":1.79,"id":2263600,"hc":-10.5}]}]}
{"op":"mcm","clk":"1005104358","pt":1580640792214,"mc":[{"id":"1.168230817","rc":[{"trd":[[1.02,1.81]],"batb":[[0,1.02,7.75]],"batl":[[0,990,0.01]],"ltp":1.02,"tv":1.81,"id":2263600,"hc":-10.5}],"tv":5.48}]}
{"op":"mcm","clk":"1005104491","pt":1580640793610,"mc":[{"id":"1.168230817","rc":[{"batl":[[0,1000,0.02]],"ltp":1.02,"tv":1.93,"id":2263600,"hc":-11.5}]}]}
{"op":"mcm","clk":"1005104628","pt":1580640794601,"mc":[{"id":"1.168230817","rc":[{"trd":[[1.02,1.95]],"batb":[[0,1.02,7.66]],"batl":[[0,990,0.01]],"ltp":1.02,"tv":1.95,"id":2263600,"hc":-11.5}],"tv":5.5}]}
{"op":"mcm","clk":"1005104735","pt":1580640795533,"mc":[{"id":"1.168230817","rc":[{"trd":[[1.02,1.75]],"batb":[[0,1.02,7.79]],"ltp":1.02,"tv":1.75,"id":2263600,"hc":-9.5}],"tv":5.52}]}
{"op":"mcm","clk":"1005104979","pt":1580640797615,"mc":[{"id":"1.168230817","rc":[{"batl":[[0,1000,0.02]],"ltp":1.02,"tv":1.81,"id":2263600,"hc":-10.5}]}]}
{"op":"mcm","clk":"1005105086","pt":1580640798603,"mc":[{"id":"1.168230817","rc":[{"trd":[[1.02,1.83]],"batb":[[0,1.02,7.74]],"batl":[[0,990,0.01]],"ltp":1.02,"tv":1.82,"id":2263600,"hc":-10.5},{"batl":[[0,1000,2.37]],"ltp":1.02,"tv":1.95,"id":2263600,"hc":-11.5}],"tv":5.53}]}
{"op":"mcm","clk":"1005105194","pt":1580640799545,"mc":[{"id":"1.168230817","rc":[{"batl":[[0,1000,2.37]],"ltp":1.02,"tv":1.75,"id":2263600,"hc":-9.5},{"trd":[[1.02,1.97]],"batb":[[0,1.02,7.65]],"batl":[[0,990,0.01]],"ltp":1.02,"tv":1.96,"id":2263600,"hc":-11.5}],"tv":5.55}]}
{"op":"mcm","clk":"1005105270","pt":1580640800107,"mc":[{"id":"1.168230817","rc":[{"trd":[[1.02,1.77]],"batb":[[0,1.02,7.78]],"batl":[[0,990,0.01]],"ltp":1.02,"tv":1.76,"id":2263600,"hc":-9.5}],"tv":5.56}]}
{"op":"mcm","clk":"1005105640","pt":1580640803524,"mc":[{"id":"1.168230817","rc":[{"trd":[[1.02,1.85]],"batb":[[0,1.02,7.73]],"ltp":1.02,"tv":1.84,"id":2263600,"hc":-10.5}],"tv":5.58}]}
{"op":"mcm","clk":"1005105758","pt":1580640804624,"mc":[{"id":"1.168230817","rc":[{"batl":[[0,1000,0.02]],"ltp":1.02,"tv":1.96,"id":2263600,"hc":-11.5}]}]}
{"op":"mcm","clk":"1005105870","pt":1580640805453,"mc":[{"id":"1.168230817","rc":[{"batl":[[0,1000,0.02]],"ltp":1.02,"tv":1.76,"id":2263600,"hc":-9.5},{"trd":[[1.02,1.98]],"batb":[[0,1.02,7.64]],"batl":[[0,990,0.01]],"ltp":1.02,"tv":1.98,"id":2263600,"hc":-11.5}],"tv":5.59}]}
{"op":"mcm","clk":"1005105917","pt":1580640805812,"mc":[{"id":"1.168230817","rc":[{"trd":[[1.02,1.78]],"batb":[[0,1.02,7.77]],"batl":[[0,990,0.01]],"ltp":1.02,"tv":1.78,"id":2263600,"hc":-9.5}],"tv":5.61}]}
{"op":"mcm","clk":"1005106199","pt":1580640808526,"mc":[{"id":"1.168230817","rc":[{"batl":[[0,1000,0.02]],"ltp":1.02,"tv":1.84,"id":2263600,"hc":-10.5}]}]}
{"op":"mcm","clk":"1005106246","pt":1580640808942,"mc":[{"id":"1.168230817","rc":[{"trd":[[1.02,1.86]],"batb":[[0,1.02,7.72]],"batl":[[0,990,0.01]],"ltp":1.02,"tv":1.86,"id":2263600,"hc":-10.5}],"tv":5.62}]}
{"op":"mcm","clk":"1005106420","pt":1580640810628,"mc":[{"id":"1.168230817","rc":[{"batl":[[0,1000,0.02]],"ltp":1.02,"tv":1.78,"id":2263600,"hc":-9.5},{"trd":[[1.02,2]],"batb":[[0,1.02,7.63]],"ltp":1.02,"tv":2.0,"id":2263600,"hc":-11.5}],"tv":5.64}]}
{"op":"mcm","clk":"1005106462","pt":1580640811048,"mc":[{"id":"1.168230817","rc":[{"trd":[[1.02,1.8]],"batb":[[0,1.02,7.76]],"batl":[[0,990,0.01]],"ltp":1.02,"tv":1.79,"id":2263600,"hc":-9.5}],"tv":5.66}]}
{"op":"mcm","clk":"1005106842","pt":1580640814336,"mc":[{"id":"1.168230817","rc":[{"batl":[[0,1000,0.02]],"ltp":1.02,"tv":1.86,"id":2263600,"hc":-10.5}]}]}
{"op":"mcm","clk":"1005106886","pt":1580640814756,"mc":[{"id":"1.168230817","rc":[{"trd":[[1.02,1.88]],"batb":[[0,1.02,7.71]],"batl":[[0,990,0.01]],"ltp":1.02,"tv":1.87,"id":2263600,"hc":-10.5}],"tv":5.67}]}
{"op":"mcm","clk":"1005107107","pt":1580640816642,"mc":[{"id":"1.168230817","rc":[{"trd":[[1.02,2.02]],"batb":[[0,1.02,7.62]],"ltp":1.02,"tv":2.01,"id":2263600,"hc":-11.5}],"tv":5.69}]}
{"op":"mcm","clk":"1005107139","pt":1580640816953,"mc":[{"id":"1.168230817","rc":[{"trd":[[1.02,1.81]],"batb":[[0,1.02,7.75]],"ltp":1.02,"tv":1.81,"id":2263600,"hc":-9.5}],"tv":5.7}]}
{"op":"mcm","clk":"1005107577","pt":1580640820548,"mc":[{"id":"1.168230817","rc":[{"trd":[[1.02,1.89]],"batb":[[0,1.02,7.7]],"ltp":1.02,"tv":1.89,"id":2263600,"hc":-10.5}],"tv":5.72}]}
{"op":"mcm","clk":"1005107716","pt":1580640821647,"mc":[{"id":"1.168230817","rc":[{"batl":[[0,1000,0.02]],"ltp":1.02,"tv":1.81,"id":2263600,"hc":-9.5}]}]}
{"op":"mcm","clk":"1005107755","pt":1580640821965,"mc":[{"id":"1.168230817","rc":[{"trd":[[1.02,1.83]],"batb":[[0,1.02,7.74]],"batl":[[0,990,0.01]],"ltp":1.02,"tv":1.82,"id":2263600,"hc":-9.5},{"trd":[[1.02,2.03]],"batb":[[0,1.02,7.61]],"ltp":1.02,"tv":2.03,"id":2263600,"hc":-11.5}],"tv":5.75}]}
{"op":"mcm","clk":"1005108216","pt":1580640825462,"mc":[{"id":"1.168230817","rc":[{"batl":[[0,1000,2.37]],"ltp":1.02,"tv":1.89,"id":2263600,"hc":-10.5}]}]}
{"op":"mcm","clk":"1005108347","pt":1580640826554,"mc":[{"id":"1.168230817","rc":[{"trd":[[1.02,1.91]],"batb":[[0,1.02,7.69]],"batl":[[0,990,0.01]],"ltp":1.02,"tv":1.9,"id":2263600,"hc":-10.5},{"batl":[[0,1000,2.37]],"ltp":1.02,"tv":2.03,"id":2263600,"hc":-11.5}],"tv":5.76}]}
{"op":"mcm","clk":"1005108468","pt":1580640827492,"mc":[{"id":"1.168230817","rc":[{"trd":[[1.02,1.85]],"batb":[[0,1.02,7.73]],"ltp":1.02,"tv":1.84,"id":2263600,"hc":-9.5},{"trd":[[1.02,2.05]],"batb":[[0,1.02,7.6]],"batl":[[0,990,0.01]],"ltp":1.02,"tv":2.04,"id":2263600,"hc":-11.5}],"tv":5.79}]}
{"op":"mcm","clk":"1005108931","pt":1580640831459,"mc":[{"id":"1.168230817","rc":[{"trd":[[1.02,1.92]],"batb":[[0,1.02,7.68]],"ltp":1.02,"tv":1.92,"id":2263600,"hc":-10.5}],"tv":5.81}]}
{"op":"mcm","clk":"1005109085","pt":1580640832553,"mc":[{"id":"1.168230817","rc":[{"batl":[[0,1000,0.02]],"ltp":1.02,"tv":1.84,"id":2263600,"hc":-9.5},{"batl":[[0,1000,0.02]],"ltp":1.02,"tv":2.04,"id":2263600,"hc":-11.5}]}]}
{"op":"mcm","clk":"1005109115","pt":1580640832861,"mc":[{"id":"1.168230817","rc":[{"trd":[[1.02,1.86]],"batb":[[0,1.02,7.72]],"batl":[[0,990,0.01]],"ltp":1.02,"tv":1.86,"id":2263600,"hc":-9.5},{"trd":[[1.02,2.06]],"batb":[[0,1.02,7.59]],"batl":[[0,990,0.01]],"ltp":1.02,"tv":2.06,"id":2263600,"hc":-11.5}],"tv":5.84}]}
{"op":"mcm","clk":"1005109712","pt":1580640837574,"mc":[{"id":"1.168230817","rc":[{"trd":[[1.02,1.94]],"batb":[[0,1.02,7.67]],"ltp":1.02,"tv":1.93,"id":2263600,"hc":-10.5}],"tv":5.86}]}
{"op":"mcm","clk":"1005109825","pt":1580640838566,"mc":[{"id":"1.168230817","rc":[{"trd":[[1.02,1.88]],"batb":[[0,1.02,7.71]],"ltp":1.02,"tv":1.87,"id":2263600,"hc":-9.5}],"tv":5.87}]}
{"op":"mcm","clk":"1005109838","pt":1580640838670,"mc":[{"id":"1.168230817","rc":[{"trd":[[1.02,2.08]],"batb":[[0,1.02,7.58]],"ltp":1.02,"tv":2.07,"id":2263600,"hc":-11.5}],"tv":5.89}]}
{"op":"mcm","clk":"1005110288","pt":1580640842578,"mc":[{"id":"1.168230817","rc":[{"trd":[[1.02,1.95]],"batb":[[0,1.02,7.66]],"ltp":1.02,"tv":1.95,"id":2263600,"hc":-10.5}],"tv":5.9}]}
{"op":"mcm","clk":"1005110400","pt":1580640843577,"mc":[{"id":"1.168230817","rc":[{"batl":[[0,1000,2.37]],"ltp":1.02,"tv":1.87,"id":2263600,"hc":-9.5},{"batl":[[0,1000,2.37]],"ltp":1.02,"tv":2.07,"id":2263600,"hc":-11.5}]}]}
{"op":"mcm","clk":"1005110475","pt":1580640844205,"mc":[{"id":"1.168230817","rc":[{"trd":[[1.02,1.89]],"batb":[[0,1.02,7.7]],"batl":[[0,990,0.01]],"ltp":1.02,"tv":1.89,"id":2263600,"hc":-9.5},{"trd":[[1.02,2.09]],"batb":[[0,1.02,7.57]],"batl":[[0,990,0.01]],"ltp":1.02,"tv":2.09,"id":2263600,"hc":-11.5}],"tv":5.93}]}
{"op":"mcm","clk":"1005110834","pt":1580640847482,"mc":[{"id":"1.168230817","rc":[{"batl":[[0,1000,0.02]],"ltp":1.02,"tv":1.95,"id":2263600,"hc":-10.5}]}]}
{"op":"mcm","clk":"1005110864","pt":1580640847796,"mc":[{"id":"1.168230817","rc":[{"trd":[[1.02,1.97]],"batb":[[0,1.02,7.65]],"batl":[[0,990,0.01]],"ltp":1.02,"tv":1.96,"id":2263600,"hc":-10.5}],"tv":5.95}]}
{"op":"mcm","clk":"1005111098","pt":1580640849581,"mc":[{"id":"1.168230817","rc":[{"trd":[[1.02,1.91]],"batb":[[0,1.02,7.69]],"ltp":1.02,"tv":1.9,"id":2263600,"hc":-9.5},{"trd":[[1.02,2.11]],"batb":[[0,1.02,7.56]],"ltp":1.02,"tv":2.1,"id":2263600,"hc":-11.5}],"tv":5.98}]}
{"op":"mcm","clk":"1005111563","pt":1580640853596,"mc":[{"id":"1.168230817","rc":[{"trd":[[1.02,1.98]],"batb":[[0,1.02,7.64]],"ltp":1.02,"tv":1.98,"id":2263600,"hc":-10.5}],"tv":6.0}]}
{"op":"mcm","clk":"1005111695","pt":1580640854602,"mc":[{"id":"1.168230817","rc":[{"batl":[[0,1000,0.02]],"ltp":1.02,"tv":1.9,"id":2263600,"hc":-9.5}]}]}
{"op":"mcm","clk":"1005111794","pt":1580640855382,"mc":[{"id":"1.168230817","rc":[{"trd":[[1.02,1.92]],"batb":[[0,1.02,7.68]],"batl":[[0,990,0.01]],"ltp":1.02,"tv":1.92,"id":2263600,"hc":-9.5},{"trd":[[1.02,2.12]],"batb":[[0,1.02,7.55]],"ltp":1.02,"tv":2.12,"id":2263600,"hc":-11.5}],"tv":6.03}]}
{"op":"mcm","clk":"1005112159","pt":1580640858505,"mc":[{"id":"1.168230817","rc":[{"batl":[[0,1000,2.37]],"ltp":1.02,"tv":1.98,"id":2263600,"hc":-10.5}]}]}
{"op":"mcm","clk":"1005112287","pt":1580640859605,"mc":[{"id":"1.168230817","rc":[{"batl":[[0,1000,0.02]],"ltp":1.02,"tv":1.92,"id":2263600,"hc":-9.5},{"trd":[[1.02,2]],"batb":[[0,1.02,7.63]],"batl":[[0,990,0.01]],"ltp":1.02,"tv":2.0,"id":2263600,"hc":-10.5}],"tv":6.04}]}
{"op":"mcm","clk":"1005112383","pt":1580640860387,"mc":[{"id":"1.168230817","rc":[{"trd":[[1.02,1.94]],"batb":[[0,1.02,7.67]],"batl":[[0,990,0.01]],"ltp":1.02,"tv":1.93,"id":2263600,"hc":-9.5},{"batl":[[0,1000,2.37]],"ltp":1.02,"tv":2.12,"id":2263600,"hc":-11.5}],"tv":6.06}]}
{"op":"mcm","clk":"1005112490","pt":1580640861112,"mc":[{"id":"1.168230817","rc":[{"trd":[[1.02,2.14]],"batb":[[0,1.02,7.54]],"batl":[[0,990,0.01]],"ltp":1.02,"tv":2.14,"id":2263600,"hc":-11.5}],"tv":6.07}]}
{"op":"mcm","clk":"1005112882","pt":1580640864618,"mc":[{"id":"1.168230817","rc":[{"trd":[[1.02,2.02]],"batb":[[0,1.02,7.62]],"ltp":1.02,"tv":2.01,"id":2263600,"hc":-10.5}],"tv":6.09}]}
{"op":"mcm","clk":"1005112974","pt":1580640865297,"mc":[{"id":"1.168230817","rc":[{"trd":[[1.02,1.95]],"batb":[[0,1.02,7.66]],"ltp":1.02,"tv":1.95,"id":2263600,"hc":-9.5}],"tv":6.11}]}
{"op":"mcm","clk":"1005113098","pt":1580640866227,"mc":[{"id":"1.168230817","rc":[{"trd":[[1.02,2.16]],"batb":[[0,1.02,7.53]],"ltp":1.02,"tv":2.15,"id":2263600,"hc":-11.5}],"tv":6.12}]}
{"op":"mcm","clk":"1005113480","pt":1580640869521,"mc":[{"id":"1.168230817","rc":[{"batl":[[0,1000,2.37]],"ltp":1.02,"tv":2.01,"id":2263600,"hc":-10.5}]}]}
{"op":"mcm","clk":"1005113606","pt":1580640870609,"mc":[{"id":"1.168230817","rc":[{"trd":[[1.02,2.03]],"batb":[[0,1.02,7.61]],"batl":[[0,990,0.01]],"ltp":1.02,"tv":2.03,"id":2263600,"hc":-10.5}],"tv":6.14}]}
{"op":"mcm","clk":"1005113730","pt":1580640871646,"mc":[{"id":"1.168230817","rc":[{"trd":[[1.02,1.97]],"batb":[[0,1.02,7.65]],"ltp":1.02,"tv":1.96,"id":2263600,"hc":-9.5}],"tv":6.15}]}
{"op":"mcm","clk":"1005113744","pt":1580640871705,"mc":[{"id":"1.168230817","rc":[{"trd":[[1.02,2.17]],"batb":[[0,1.02,7.52]],"ltp":1.02,"tv":2.17,"id":2263600,"hc":-11.5}],"tv":6.17}]}
{"op":"mcm","clk":"1005114218","pt":1580640875601,"mc":[{"id":"1.168230817","rc":[{"batl":[[0,1000,2.37]],"ltp":1.02,"tv":2.03,"id":2263600,"hc":-10.5}]}]}
{"op":"mcm","clk":"1005114298","pt":1580640876225,"mc":[{"id":"1.168230817","rc":[{"trd":[[1.02,1.98]],"batb":[[0,1.02,7.64]],"ltp":1.02,"tv":1.98,"id":2263600,"hc":-9.5},{"trd":[[1.02,2.05]],"batb":[[0,1.02,7.6]],"batl":[[0,990,0.01]],"ltp":1.02,"tv":2.04,"id":2263600,"hc":-10.5}],"tv":6.2}]}
{"op":"mcm","clk":"1005114467","pt":1580640877643,"mc":[{"id":"1.168230817","rc":[{"trd":[[1.02,2.19]],"batb":[[0,1.02,7.51]],"ltp":1.02,"tv":2.18,"id":2263600,"hc":-11.5}],"tv":6.21}]}
{"op":"mcm","clk":"1005114903","pt":1580640881552,"mc":[{"id":"1.168230817","rc":[{"trd":[[1.02,2]],"batb":[[0,1.02,7.63]],"ltp":1.02,"tv":2.0,"id":2263600,"hc":-9.5},{"trd":[[1.02,2.06]],"batb":[[0,1.02,7.59]],"ltp":1.02,"tv":2.06,"id":2263600,"hc":-10.5}],"tv":6.24}]}
{"op":"mcm","clk":"1005115020","pt":1580640882616,"mc":[{"id":"1.168230817","rc":[{"batl":[[0,1000,0.02]],"ltp":1.02,"tv":2.18,"id":2263600,"hc":-11.5}]}]}
{"op":"mcm","clk":"1005115070","pt":1580640883036,"mc":[{"id":"1.168230817","rc":[{"trd":[[1.02,2.2]],"batb":[[0,1.02,7.5]],"batl":[[0,990,0.01]],"ltp":1.02,"tv":2.2,"id":2263600,"hc":-11.5}],"tv":6.26}]}
{"op":"mcm","clk":"1005115484","pt":1580640886639,"mc":[{"id":"1.168230817","rc":[{"batl":[[0,1000,0.02]],"ltp":1.02,"tv":2.0,"id":2263600,"hc":-9.5},{"batl":[[0,1000,0.02]],"ltp":1.02,"tv":2.06,"id":2263600,"hc":-10.5}]}]}
{"op":"mcm","clk":"1005115610","pt":1580640887630,"mc":[{"id":"1.168230817","rc":[{"trd":[[1.02,2.02]],"batb":[[0,1.02,7.62]],"batl":[[0,990,0.01]],"ltp":1.02,"tv":2.01,"id":2263600,"hc":-9.5},{"trd":[[1.02,2.08]],"batb":[[0,1.02,7.58]],"batl":[[0,990,0.01]],"ltp":1.02,"tv":2.07,"id":2263600,"hc":-10.5}],"tv":6.29}]}
{"op":"mcm","clk":"1005115694","pt":1580640888351,"mc":[{"id":"1.168230817","rc":[{"trd":[[1.02,2.22]],"batb":[[0,1.02,7.49]],"ltp":1.02,"tv":2.21,"id":2263600,"hc":-11.5}],"tv":6.31}]}
{"op":"mcm","clk":"1005116082","pt":1580640891638,"mc":[{"id":"1.168230817","rc":[{"batl":[[0,1000,2.37]],"ltp":1.02,"tv":2.01,"id":2263600,"hc":-9.5}]}]}
{"op":"mcm","clk":"1005116228","pt":1580640892625,"mc":[{"id":"1.168230817","rc":[{"trd":[[1.02,2.03]],"batb":[[0,1.02,7.61]],"batl":[[0,990,0.01]],"ltp":1.02,"tv":2.03,"id":2263600,"hc":-9.5},{"trd":[[1.02,2.09]],"batb":[[0,1.02,7.57]],"ltp":1.02,"tv":2.09,"id":2263600,"hc":-10.5}],"tv":6.34}]}
{"op":"mcm","clk":"1005116437","pt":1580640894243,"mc":[{"id":"1.168230817","rc":[{"trd":[[1.02,2.23]],"batb":[[0,1.02,7.48]],"ltp":1.02,"tv":2.23,"id":2263600,"hc":-11.5}],"tv":6.35}]}
{"op":"mcm","clk":"1005116808","pt":1580640897436,"mc":[{"id":"1.168230817","rc":[{"batl":[[0,1000,0.02]],"ltp":1.02,"tv":2.03,"id":2263600,"hc":-9.5},{"batl":[[0,1000,2.37]],"ltp":1.02,"tv":2.09,"id":2263600,"hc":-10.5}]}]}
{"op":"mcm","clk":"1005116885","pt":1580640898261,"mc":[{"id":"1.168230817","rc":[{"trd":[[1.02,2.05]],"batb":[[0,1.02,7.6]],"batl":[[0,990,0.01]],"ltp":1.02,"tv":2.04,"id":2263600,"hc":-9.5},{"trd":[[1.02,2.11]],"batb":[[0,1.02,7.56]],"batl":[[0,990,0.01]],"ltp":1.02,"tv":2.1,"id":2263600,"hc":-10.5}],"tv":6.38}]}
{"op":"mcm","clk":"1005117030","pt":1580640899567,"mc":[{"id":"1.168230817","rc":[{"batl":[[0,1000,2.37]],"ltp":1.02,"tv":2.23,"id":2263600,"hc":-11.5}]}]}
{"op":"mcm","clk":"1005117090","pt":1580640899983,"mc":[{"id":"1.168230817","rc":[{"trd":[[1.02,2.25]],"batb":[[0,1.02,7.47]],"batl":[[0,990,0.01]],"ltp":1.02,"tv":2.24,"id":2263600,"hc":-11.5}],"tv":6.4}]}
{"op":"mcm","clk":"1005117580","pt":1580640903367,"mc":[{"id":"1.168230817","rc":[{"trd":[[1.02,2.06]],"batb":[[0,1.02,7.59]],"ltp":1.02,"tv":2.06,"id":2263600,"hc":-9.5},{"batl":[[0,1000,2.37]],"ltp":1.02,"tv":2.1,"id":2263600,"hc":-10.5}],"tv":6.42}]}
{"op":"mcm","clk":"1005117761","pt":1580640904581,"mc":[{"id":"1.168230817","rc":[{"trd":[[1.02,2.12]],"batb":[[0,1.02,7.55]],"batl":[[0,990,0.01]],"ltp":1.02,"tv":2.12,"id":2263600,"hc":-10.5},{"batl":[[0,1000,2.37]],"ltp":1.02,"tv":2.24,"id":2263600,"hc":-11.5}],"tv":6.43}]}
{"op":"mcm","clk":"1005117867","pt":1580640905257,"mc":[{"id":"1.168230817","rc":[{"trd":[[1.02,2.26]],"batb":[[0,1.02,7.46]],"batl":[[0,990,0.01]],"ltp":1.02,"tv":2.26,"id":2263600,"hc":-11.5}],"tv":6.45}]}
{"op":"mcm","clk":"1005118287","pt":1580640908587,"mc":[{"id":"1.168230817","rc":[{"batl":[[0,1000,2.37]],"ltp":1.02,"tv":2.06,"id":2263600,"hc":-9.5}]}]}
{"op":"mcm","clk":"1005118409","pt":1580640909580,"mc":[{"id":"1.168230817","rc":[{"trd":[[1.02,2.08]],"batb":[[0,1.02,7.58]],"batl":[[0,990,0.01]],"ltp":1.02,"tv":2.07,"id":2263600,"hc":-9.5}],"tv":6.46}]}
{"op":"mcm","clk":"1005118533","pt":1580640910588,"mc":[{"id":"1.168230817","rc":[{"trd":[[1.02,2.14]],"batb":[[0,1.02,7.54]],"ltp":1.02,"tv":2.14,"id":2263600,"hc":-10.5}],"tv":6.48}]}
{"op":"mcm","clk":"1005118642","pt":1580640911350,"mc":[{"id":"1.168230817","rc":[{"trd":[[1.02,2.28]],"batb":[[0,1.02,7.45]],"ltp":1.02,"tv":2.27,"id":2263600,"hc":-11.5}],"tv":6.49}]}
{"op":"mcm","clk":"1005119037","pt":1580640914576,"mc":[{"id":"1.168230817","rc":[{"batl":[[0,1000,0.02]],"ltp":1.02,"tv":2.07,"id":2263600,"hc":-9.5}]}]}
{"op":"mcm","clk":"1005119145","pt":1580640915457,"mc":[{"id":"1.168230817","rc":[{"trd":[[1.02,2.09]],"batb":[[0,1.02,7.57]],"batl":[[0,990,0.01]],"ltp":1.02,"tv":2.09,"id":2263600,"hc":-9.5},{"batl":[[0,1000,0.02]],"ltp":1.02,"tv":2.14,"id":2263600,"hc":-10.5}],"tv":6.51}]}
{"op":"mcm","clk":"1005119302","pt":1580640916493,"mc":[{"id":"1.168230817","rc":[{"trd":[[1.02,2.16]],"batb":[[0,1.02,7.53]],"batl":[[0,990,0.01]],"ltp":1.02,"tv":2.15,"id":2263600,"hc":-10.5},{"batl":[[0,1000,0.02]],"ltp":1.02,"tv":2.27,"id":2263600,"hc":-11.5}],"tv":6.52}]}
{"op":"mcm","clk":"1005119361","pt":1580640916868,"mc":[{"id":"1.168230817","rc":[{"trd":[[1.02,2.3]],"batb":[[0,1.02,7.44]],"batl":[[0,990,0.01]],"ltp":1.02,"tv":2.29,"id":2263600,"hc":-11.5}],"tv":6.54}]}
{"op":"mcm","clk":"1005119811","pt":1580640920492,"mc":[{"id":"1.168230817","rc":[{"batl":[[0,1000,0.02]],"ltp":1.02,"tv":2.09,"id":2263600,"hc":-9.5}]}]}
{"op":"mcm","clk":"1005119968","pt":1580640921584,"mc":[{"id":"1.168230817","rc":[{"trd":[[1.02,2.11]],"batb":[[0,1.02,7.56]],"batl":[[0,990,0.01]],"ltp":1.02,"tv":2.1,"id":2263600,"hc":-9.5},{"trd":[[1.02,2.17]],"batb":[[0,1.02,7.52]],"ltp":1.02,"tv":2.17,"id":2263600,"hc":-10.5}],"tv":6.57}]}
{"op":"mcm","clk":"1005120102","pt":1580640922571,"mc":[{"id":"1.168230817","rc":[{"trd":[[1.02,2.31]],"batb":[[0,1.02,7.43]],"ltp":1.02,"tv":2.31,"id":2263600,"hc":-11.5}],"tv":6.59}]}
{"op":"mcm","clk":"1005120460","pt":1580640925590,"mc":[{"id":"1.168230817","rc":[{"batl":[[0,1000,0.02]],"ltp":1.02,"tv":2.1,"id":2263600,"hc":-9.5}]}]}
{"op":"mcm","clk":"1005120571","pt":1580640926482,"mc":[{"id":"1.168230817","rc":[{"trd":[[1.02,2.12]],"batb":[[0,1.02,7.55]],"batl":[[0,990,0.01]],"ltp":1.02,"tv":2.12,"id":2263600,"hc":-9.5},{"batl":[[0,1000,2.37]],"ltp":1.02,"tv":2.17,"id":2263600,"hc":-10.5}],"tv":6.6}]}
{"op":"mcm","clk":"1005120668","pt":1580640927506,"mc":[{"id":"1.168230817","rc":[{"trd":[[1.02,2.19]],"batb":[[0,1.02,7.51]],"batl":[[0,990,0.01]],"ltp":1.02,"tv":2.18,"id":2263600,"hc":-10.5},{"batl":[[0,1000,2.37]],"ltp":1.02,"tv":2.31,"id":2263600,"hc":-11.5}],"tv":6.62}]}
{"op":"mcm","clk":"1005120753","pt":1580640928094,"mc":[{"id":"1.168230817","rc":[{"trd":[[1.02,2.33]],"batb":[[0,1.02,7.42]],"batl":[[0,990,0.01]],"ltp":1.02,"tv":2.32,"id":2263600,"hc":-11.5}],"tv":6.63}]}
{"op":"mcm","clk":"1005121124","pt":1580640931475,"mc":[{"id":"1.168230817","rc":[{"trd":[[1.02,2.14]],"batb":[[0,1.02,7.54]],"ltp":1.02,"tv":2.14,"id":2263600,"hc":-9.5}],"tv":6.65}]}
{"op":"mcm","clk":"1005121350","pt":1580640933396,"mc":[{"id":"1.168230817","rc":[{"trd":[[1.02,2.2]],"batb":[[0,1.02,7.5]],"ltp":1.02,"tv":2.2,"id":2263600,"hc":-10.5},{"batl":[[0,1000,0.02]],"ltp":1.02,"tv":2.32,"id":2263600,"hc":-11.5}],"tv":6.66}]}
{"op":"mcm","clk":"1005121403","pt":1580640933809,"mc":[{"id":"1.168230817","rc":[{"trd":[[1.02,2.34]],"batb":[[0,1.02,7.41]],"batl":[[0,990,0.01]],"ltp":1.02,"tv":2.34,"id":2263600,"hc":-11.5}],"tv":6.68}]}
{"op":"mcm","clk":"1005121727","pt":1580640936500,"mc":[{"id":"1.168230817","rc":[{"batl":[[0,1000,0.02]],"ltp":1.02,"tv":2.14,"id":2263600,"hc":-9.5}]}]}
{"op":"mcm","clk":"1005121843","pt":1580640937597,"mc":[{"id":"1.168230817","rc":[{"trd":[[1.02,2.16]],"batb":[[0,1.02,7.53]],"batl":[[0,990,0.01]],"ltp":1.02,"tv":2.15,"id":2263600,"hc":-9.5},{"batl":[[0,1000,2.37]],"ltp":1.02,"tv":2.2,"id":2263600,"hc":-10.5}],"tv":6.69}]}
{"op":"mcm","clk":"1005121925","pt":1580640938210,"mc":[{"id":"1.168230817","rc":[{"trd":[[1.02,2.22]],"batb":[[0,1.02,7.49]],"batl":[[0,990,0.01]],"ltp":1.02,"tv":2.21,"id":2263600,"hc":-10.5}],"tv":6.71}]}
{"op":"mcm","clk":"1005122066","pt":1580640939409,"mc":[{"id":"1.168230817","rc":[{"batl":[[0,1000,0.02]],"ltp":1.02,"tv":2.34,"id":2263600,"hc":-11.5}]}]}
{"op":"mcm","clk":"1005122121","pt":1580640939794,"mc":[{"id":"1.168230817","rc":[{"trd":[[1.02,2.36]],"batb":[[0,1.02,7.4]],"batl":[[0,990,0.01]],"ltp":1.02,"tv":2.35,"id":2263600,"hc":-11.5}],"tv":6.73}]}
{"op":"mcm","clk":"1005122458","pt":1580640942601,"mc":[{"id":"1.168230817","rc":[{"trd":[[1.02,2.17]],"batb":[[0,1.02,7.52]],"ltp":1.02,"tv":2.17,"id":2263600,"hc":-9.5}],"tv":6.74}]}
{"op":"mcm","clk":"1005122569","pt":1580640943579,"mc":[{"id":"1.168230817","rc":[{"batl":[[0,1000,2.37]],"ltp":1.02,"tv":2.21,"id":2263600,"hc":-10.5}]}]}
{"op":"mcm","clk":"1005122686","pt":1580640944414,"mc":[{"id":"1.168230817","rc":[{"trd":[[1.02,2.23]],"batb":[[0,1.02,7.48]],"batl":[[0,990,0.01]],"ltp":1.02,"tv":2.23,"id":2263600,"hc":-10.5}],"tv":6.76}]}
{"op":"mcm","clk":"1005122864","pt":1580640945710,"mc":[{"id":"1.168230817","rc":[{"trd":[[1.02,2.37]],"batb":[[0,1.02,7.39]],"ltp":1.02,"tv":2.37,"id":2263600,"hc":-11.5}],"tv":6.77}]}
{"op":"mcm","clk":"1005123039","pt":1580640947419,"mc":[{"id":"1.168230817","rc":[{"batl":[[0,1000,2.37]],"ltp":1.02,"tv":2.17,"id":2263600,"hc":-9.5}]}]}
{"op":"mcm","clk":"1005123128","pt":1580640948099,"mc":[{"id":"1.168230817","rc":[{"trd":[[1.02,2.19]],"batb":[[0,1.02,7.51]],"batl":[[0,990,0.01]],"ltp":1.02,"tv":2.18,"id":2263600,"hc":-9.5}],"tv":6.79}]}
{"op":"mcm","clk":"1005123297","pt":1580640949503,"mc":[{"id":"1.168230817","rc":[{"batl":[[0,1000,0.02]],"ltp":1.02,"tv":2.23,"id":2263600,"hc":-10.5}]}]}
{"op":"mcm","clk":"1005123433","pt":1580640950592,"mc":[{"id":"1.168230817","rc":[{"trd":[[1.02,2.25]],"batb":[[0,1.02,7.47]],"batl":[[0,990,0.01]],"ltp":1.02,"tv":2.24,"id":2263600,"hc":-10.5},{"batl":[[0,1000,2.37]],"ltp":1.02,"tv":2.37,"id":2263600,"hc":-11.5}],"tv":6.8}]}
{"op":"mcm","clk":"1005123488","pt":1580640951003,"mc":[{"id":"1.168230817","rc":[{"trd":[[1.02,2.39]],"batb":[[0,1.02,7.38]],"batl":[[0,990,0.01]],"ltp":1.02,"tv":2.38,"id":2263600,"hc":-11.5}],"tv":6.82}]}
{"op":"mcm","clk":"1005123804","pt":1580640953607,"mc":[{"id":"1.168230817","rc":[{"trd":[[1.02,2.2]],"batb":[[0,1.02,7.5]],"ltp":1.02,"tv":2.2,"id":2263600,"hc":-9.5}],"tv":6.83}]}
{"op":"mcm","clk":"1005124025","pt":1580640955416,"mc":[{"id":"1.168230817","rc":[{"trd":[[1.02,2.26]],"batb":[[0,1.02,7.46]],"ltp":1.02,"tv":2.26,"id":2263600,"hc":-10.5}],"tv":6.85}]}
{"op":"mcm","clk":"1005124194","pt":1580640956723,"mc":[{"id":"1.168230817","rc":[{"trd":[[1.02,2.4]],"batb":[[0,1.02,7.37]],"ltp":1.02,"tv":2.4,"id":2263600,"hc":-11.5}],"tv":6.86}]}
{"op":"mcm","clk":"1005124418","pt":1580640958636,"mc":[{"id":"1.168230817","rc":[{"batl":[[0,1000,2.37]],"ltp":1.02,"tv":2.2,"id":2263600,"hc":-9.5}]}]}
{"op":"mcm","clk":"1005124510","pt":1580640959218,"mc":[{"id":"1.168230817","rc":[{"trd":[[1.02,2.22]],"batb":[[0,1.02,7.49]],"batl":[[0,990,0.01]],"ltp":1.02,"tv":2.21,"id":2263600,"hc":-9.5}],"tv":6.88}]}
{"op":"mcm","clk":"1005124793","pt":1580640961407,"mc":[{"id":"1.168230817","rc":[{"trd":[[1.02,2.28]],"batb":[[0,1.02,7.45]],"ltp":1.02,"tv":2.27,"id":2263600,"hc":-10.5}],"tv":6.9}]}
{"op":"mcm","clk":"1005124935","pt":1580640962615,"mc":[{"id":"1.168230817","rc":[{"trd":[[1.02,2.42]],"batb":[[0,1.02,7.36]],"ltp":1.02,"tv":2.41,"id":2263600,"hc":-11.5}],"tv":6.91}]}
{"op":"mcm","clk":"1005125184","pt":1580640964427,"mc":[{"id":"1.168230817","rc":[{"batl":[[0,1000,0.02]],"ltp":1.02,"tv":2.21,"id":2263600,"hc":-9.5}]}]}
{"op":"mcm","clk":"1005125232","pt":1580640964838,"mc":[{"id":"1.168230817","rc":[{"trd":[[1.02,2.23]],"batb":[[0,1.02,7.48]],"batl":[[0,990,0.01]],"ltp":1.02,"tv":2.23,"id":2263600,"hc":-9.5}],"tv":6.93}]}
{"op":"mcm","clk":"1005125593","pt":1580640967642,"mc":[{"id":"1.168230817","rc":[{"trd":[[1.02,2.3]],"batb":[[0,1.02,7.44]],"ltp":1.02,"tv":2.29,"id":2263600,"hc":-10.5},{"batl":[[0,1000,0.02]],"ltp":1.02,"tv":2.41,"id":2263600,"hc":-11.5}],"tv":6.94}]}
{"op":"mcm","clk":"1005125638","pt":1580640968055,"mc":[{"id":"1.168230817","rc":[{"trd":[[1.02,2.43]],"batb":[[0,1.02,7.35]],"batl":[[0,990,0.01]],"ltp":1.02,"tv":2.43,"id":2263600,"hc":-11.5}],"tv":6.96}]}
{"op":"mcm","clk":"1005125883","pt":1580640970345,"mc":[{"id":"1.168230817","rc":[{"trd":[[1.02,2.25]],"batb":[[0,1.02,7.47]],"ltp":1.02,"tv":2.24,"id":2263600,"hc":-9.5}],"tv":6.97}]}
{"op":"mcm","clk":"1005126132","pt":1580640972626,"mc":[{"id":"1.168230817","rc":[{"batl":[[0,1000,0.02]],"ltp":1.02,"tv":2.29,"id":2263600,"hc":-10.5}]}]}
{"op":"mcm","clk":"1005126235","pt":1580640973569,"mc":[{"id":"1.168230817","rc":[{"trd":[[1.02,2.31]],"batb":[[0,1.02,7.43]],"batl":[[0,990,0.01]],"ltp":1.02,"tv":2.31,"id":2263600,"hc":-10.5},{"batl":[[0,1000,0.02]],"ltp":1.02,"tv":2.43,"id":2263600,"hc":-11.5}],"tv":6.99}]}
{"op":"mcm","clk":"1005126285","pt":1580640973932,"mc":[{"id":"1.168230817","rc":[{"trd":[[1.02,2.45]],"batb":[[0,1.02,7.34]],"batl":[[0,990,0.01]],"ltp":1.02,"tv":2.45,"id":2263600,"hc":-11.5}],"tv":7.0}]}
{"op":"mcm","clk":"1005126547","pt":1580640975448,"mc":[{"id":"1.168230817","rc":[{"batl":[[0,1000,2.37]],"ltp":1.02,"tv":2.24,"id":2263600,"hc":-9.5}]}]}
{"op":"mcm","clk":"1005126626","pt":1580640976072,"mc":[{"id":"1.168230817","rc":[{"trd":[[1.02,2.26]],"batb":[[0,1.02,7.46]],"batl":[[0,990,0.01]],"ltp":1.02,"tv":2.26,"id":2263600,"hc":-9.5}],"tv":7.02}]}
{"op":"mcm","clk":"1005126913","pt":1580640978565,"mc":[{"id":"1.168230817","rc":[{"trd":[[1.02,2.33]],"batb":[[0,1.02,7.42]],"ltp":1.02,"tv":2.32,"id":2263600,"hc":-10.5}],"tv":7.04}]}
{"op":"mcm","clk":"1005127006","pt":1580640979353,"mc":[{"id":"1.168230817","rc":[{"trd":[[1.02,2.47]],"batb":[[0,1.02,7.33]],"ltp":1.02,"tv":2.46,"id":2263600,"hc":-11.5}],"tv":7.05}]}
{"op":"mcm","clk":"1005127301","pt":1580640981745,"mc":[{"id":"1.168230817","rc":[{"trd":[[1.02,2.28]],"batb":[[0,1.02,7.45]],"ltp":1.02,"tv":2.27,"id":2263600,"hc":-9.5}],"tv":7.07}]}
{"op":"mcm","clk":"1005127641","pt":1580640984572,"mc":[{"id":"1.168230817","rc":[{"trd":[[1.02,2.34]],"batb":[[0,1.02,7.41]],"ltp":1.02,"tv":2.34,"id":2263600,"hc":-10.5},{"batl":[[0,1000,2.37]],"ltp":1.02,"tv":2.46,"id":2263600,"hc":-11.5}],"tv":7.08}]}
{"op":"mcm","clk":"1005127715","pt":1580640985142,"mc":[{"id":"1.168230817","rc":[{"trd":[[1.02,2.48]],"batb":[[0,1.02,7.32]],"batl":[[0,990,0.01]],"ltp":1.02,"tv":2.48,"id":2263600,"hc":-11.5}],"tv":7.1}]}
{"op":"mcm","clk":"1005127868","pt":1580640986587,"mc":[{"id":"1.168230817","rc":[{"batl":[[0,1000,2.37]],"ltp":1.02,"tv":2.27,"id":2263600,"hc":-9.5}]}]}
{"op":"mcm","clk":"1005127937","pt":1580640987170,"mc":[{"id":"1.168230817","rc":[{"trd":[[1.02,2.3]],"batb":[[0,1.02,7.44]],"batl":[[0,990,0.01]],"ltp":1.02,"tv":2.29,"id":2263600,"hc":-9.5}],"tv":7.11}]}
{"op":"mcm","clk":"1005128220","pt":1580640989566,"mc":[{"id":"1.168230817","rc":[{"batl":[[0,1000,0.02]],"ltp":1.02,"tv":2.34,"id":2263600,"hc":-10.5}]}]}
{"op":"mcm","clk":"1005128370","pt":1580640990604,"mc":[{"id":"1.168230817","rc":[{"trd":[[1.02,2.36]],"batb":[[0,1.02,7.4]],"batl":[[0,990,0.01]],"ltp":1.02,"tv":2.35,"id":2263600,"hc":-10.5}],"tv":7.13}]}
{"op":"mcm","clk":"1005128385","pt":1580640990657,"mc":[{"id":"1.168230817","rc":[{"trd":[[1.02,2.5]],"batb":[[0,1.02,7.31]],"ltp":1.02,"tv":2.49,"id":2263600,"hc":-11.5}],"tv":7.14}]}
{"op":"mcm","clk":"1005128682","pt":1580640992588,"mc":[{"id":"1.168230817","rc":[{"batl":[[0,1000,0.02]],"ltp":1.02,"tv":2.29,"id":2263600,"hc":-9.5}]}]}
{"op":"mcm","clk":"1005128707","pt":1580640992752,"mc":[{"id":"1.168230817","rc":[{"trd":[[1.02,2.31]],"batb":[[0,1.02,7.43]],"batl":[[0,990,0.01]],"ltp":1.02,"tv":2.31,"id":2263600,"hc":-9.5}],"tv":7.16}]}
{"op":"mcm","clk":"1005129043","pt":1580640995568,"mc":[{"id":"1.168230817","rc":[{"batl":[[0,1000,0.02]],"ltp":1.02,"tv":2.35,"id":2263600,"hc":-10.5}]}]}
{"op":"mcm","clk":"1005129129","pt":1580640996286,"mc":[{"id":"1.168230817","rc":[{"trd":[[1.02,2.37]],"batb":[[0,1.02,7.39]],"batl":[[0,990,0.01]],"ltp":1.02,"tv":2.37,"id":2263600,"hc":-10.5},{"trd":[[1.02,2.51]],"batb":[[0,1.02,7.3]],"ltp":1.02,"tv":2.51,"id":2263600,"hc":-11.5}],"tv":7.19}]}
{"op":"mcm","clk":"1005129283","pt":1580640997587,"mc":[{"id":"1.168230817","rc":[{"batl":[[0,1000,2.37]],"ltp":1.02,"tv":2.31,"id":2263600,"hc":-9.5}]}]}
{"op":"mcm","clk":"1005129356","pt":1580640998310,"mc":[{"id":"1.168230817","rc":[{"trd":[[1.02,2.33]],"batb":[[0,1.02,7.42]],"batl":[[0,990,0.01]],"ltp":1.02,"tv":2.32,"id":2263600,"hc":-9.5}],"tv":7.21}]}
{"op":"mcm","clk":"1005129701","pt":1580641001376,"mc":[{"id":"1.168230817","rc":[{"batl":[[0,1000,0.02]],"ltp":1.02,"tv":2.37,"id":2263600,"hc":-10.5},{"batl":[[0,1000,2.37]],"ltp":1.02,"tv":2.51,"id":2263600,"hc":-11.5}]}]}
{"op":"mcm","clk":"1005129818","pt":1580641002101,"mc":[{"id":"1.168230817","rc":[{"trd":[[1.02,2.39]],"batb":[[0,1.02,7.38]],"batl":[[0,990,0.01]],"ltp":1.02,"tv":2.38,"id":2263600,"hc":-10.5},{"trd":[[1.02,2.53]],"batb":[[0,1.02,7.29]],"batl":[[0,990,0.01]],"ltp":1.02,"tv":2.52,"id":2263600,"hc":-11.5}],"tv":7.24}]}
{"op":"mcm","clk":"1005130055","pt":1580641003470,"mc":[{"id":"1.168230817","rc":[{"batl":[[0,1000,2.37]],"ltp":1.02,"tv":2.32,"id":2263600,"hc":-9.5}]}]}
{"op":"mcm","clk":"1005130125","pt":1580641003988,"mc":[{"id":"1.168230817","rc":[{"trd":[[1.02,2.34]],"batb":[[0,1.02,7.41]],"batl":[[0,990,0.01]],"ltp":1.02,"tv":2.34,"id":2263600,"hc":-9.5}],"tv":7.25}]}
{"op":"mcm","clk":"1005130427","pt":1580641006582,"mc":[{"id":"1.168230817","rc":[{"batl":[[0,1000,2.37]],"ltp":1.02,"tv":2.38,"id":2263600,"hc":-10.5}]}]}
{"op":"mcm","clk":"1005130542","pt":1580641007613,"mc":[{"id":"1.168230817","rc":[{"trd":[[1.02,2.4]],"batb":[[0,1.02,7.37]],"batl":[[0,990,0.01]],"ltp":1.02,"tv":2.4,"id":2263600,"hc":-10.5}],"tv":7.27}]}
{"op":"mcm","clk":"1005130552","pt":1580641007717,"mc":[{"id":"1.168230817","rc":[{"trd":[[1.02,2.54]],"batb":[[0,1.02,7.28]],"ltp":1.02,"tv":2.54,"id":2263600,"hc":-11.5}],"tv":7.28}]}
{"op":"mcm","clk":"1005130778","pt":1580641009701,"mc":[{"id":"1.168230817","rc":[{"trd":[[1.02,2.36]],"batb":[[0,1.02,7.4]],"ltp":1.02,"tv":2.35,"id":2263600,"hc":-9.5}],"tv":7.3}]}
{"op":"mcm","clk":"1005131077","pt":1580641012505,"mc":[{"id":"1.168230817","rc":[{"batl":[[0,1000,2.37]],"ltp":1.02,"tv":2.4,"id":2263600,"hc":-10.5}]}]}
{"op":"mcm","clk":"1005131202","pt":1580641013600,"mc":[{"id":"1.168230817","rc":[{"trd":[[1.02,2.42]],"batb":[[0,1.02,7.36]],"batl":[[0,990,0.01]],"ltp":1.02,"tv":2.41,"id":2263600,"hc":-10.5},{"batl":[[0,1000,0.02]],"ltp":1.02,"tv":2.54,"id":2263600,"hc":-11.5}],"tv":7.31}]}
{"op":"mcm","clk":"1005131309","pt":1580641014604,"mc":[{"id":"1.168230817","rc":[{"batl":[[0,1000,2.37]],"ltp":1.02,"tv":2.35,"id":2263600,"hc":-9.5},{"trd":[[1.02,2.56]],"batb":[[0,1.02,7.27]],"batl":[[0,990,0.01]],"ltp":1.02,"tv":2.55,"id":2263600,"hc":-11.5}],"tv":7.33}]}
{"op":"mcm","clk":"1005131390","pt":1580641015281,"mc":[{"id":"1.168230817","rc":[{"trd":[[1.02,2.37]],"batb":[[0,1.02,7.39]],"batl":[[0,990,0.01]],"ltp":1.02,"tv":2.37,"id":2263600,"hc":-9.5}],"tv":7.35}]}
{"op":"mcm","clk":"1005131790","pt":1580641018578,"mc":[{"id":"1.168230817","rc":[{"batl":[[0,1000,0.02]],"ltp":1.02,"tv":2.41,"id":2263600,"hc":-10.5},{"batl":[[0,1000,2.37]],"ltp":1.02,"tv":2.55,"id":2263600,"hc":-11.5}]}]}
{"op":"mcm","clk":"1005131884","pt":1580641019329,"mc":[{"id":"1.168230817","rc":[{"trd":[[1.02,2.43]],"batb":[[0,1.02,7.35]],"batl":[[0,990,0.01]],"ltp":1.02,"tv":2.43,"id":2263600,"hc":-10.5},{"trd":[[1.02,2.57]],"batb":[[0,1.02,7.26]],"batl":[[0,990,0.01]],"ltp":1.02,"tv":2.57,"id":2263600,"hc":-11.5}],"tv":7.38}]}
{"op":"mcm","clk":"1005132090","pt":1580641020594,"mc":[{"id":"1.168230817","rc":[{"trd":[[1.02,2.39]],"batb":[[0,1.02,7.38]],"ltp":1.02,"tv":2.38,"id":2263600,"hc":-9.5}],"tv":7.39}]}
{"op":"mcm","clk":"1005132618","pt":1580641024629,"mc":[{"id":"1.168230817","rc":[{"batl":[[0,1000,2.37]],"ltp":1.02,"tv":2.43,"id":2263600,"hc":-10.5},{"batl":[[0,1000,0.02]],"ltp":1.02,"tv":2.57,"id":2263600,"hc":-11.5}]}]}
{"op":"mcm","clk":"1005132789","pt":1580641025621,"mc":[{"id":"1.168230817","rc":[{"trd":[[1.02,2.45]],"batb":[[0,1.02,7.34]],"batl":[[0,990,0.01]],"ltp":1.02,"tv":2.45,"id":2263600,"hc":-10.5},{"trd":[[1.02,2.59]],"batb":[[0,1.02,7.25]],"batl":[[0,990,0.01]],"ltp":1.02,"tv":2.58,"id":2263600,"hc":-11.5}],"tv":7.42}]}
{"op":"mcm","clk":"1005132907","pt":1580641026295,"mc":[{"id":"1.168230817","rc":[{"trd":[[1.02,2.4]],"batb":[[0,1.02,7.37]],"ltp":1.02,"tv":2.4,"id":2263600,"hc":-9.5}],"tv":7.44}]}
{"op":"mcm","clk":"1005133490","pt":1580641030622,"mc":[{"id":"1.168230817","rc":[{"batl":[[0,1000,0.02]],"ltp":1.02,"tv":2.45,"id":2263600,"hc":-10.5},{"trd":[[1.02,2.61]],"batb":[[0,1.02,7.24]],"ltp":1.02,"tv":2.6,"id":2263600,"hc":-11.5}],"tv":7.45}]}
{"op":"mcm","clk":"1005133567","pt":1580641031400,"mc":[{"id":"1.168230817","rc":[{"batl":[[0,1000,2.37]],"ltp":1.02,"tv":2.4,"id":2263600,"hc":-9.5},{"trd":[[1.02,2.47]],"batb":[[0,1.02,7.33]],"batl":[[0,990,0.01]],"ltp":1.02,"tv":2.46,"id":2263600,"hc":-10.5}],"tv":7.47}]}
{"op":"mcm","clk":"1005133651","pt":1580641032127,"mc":[{"id":"1.168230817","rc":[{"trd":[[1.02,2.42]],"batb":[[0,1.02,7.36]],"batl":[[0,990,0.01]],"ltp":1.02,"tv":2.41,"id":2263600,"hc":-9.5}],"tv":7.49}]}
{"op":"mcm","clk":"1005134146","pt":1580641035617,"mc":[{"id":"1.168230817","rc":[{"batl":[[0,1000,2.37]],"ltp":1.02,"tv":2.46,"id":2263600,"hc":-10.5},{"batl":[[0,1000,0.02]],"ltp":1.02,"tv":2.6,"id":2263600,"hc":-11.5}]}]}
{"op":"mcm","clk":"1005134230","pt":1580641036237,"mc":[{"id":"1.168230817","rc":[{"trd":[[1.02,2.48]],"batb":[[0,1.02,7.32]],"batl":[[0,990,0.01]],"ltp":1.02,"tv":2.48,"id":2263600,"hc":-10.5},{"trd":[[1.02,2.62]],"batb":[[0,1.02,7.23]],"batl":[[0,990,0.01]],"ltp":1.02,"tv":2.62,"id":2263600,"hc":-11.5}],"tv":7.52}]}
{"op":"mcm","clk":"1005134409","pt":1580641037436,"mc":[{"id":"1.168230817","rc":[{"trd":[[1.02,2.43]],"batb":[[0,1.02,7.35]],"ltp":1.02,"tv":2.43,"id":2263600,"hc":-9.5}],"tv":7.53}]}
{"op":"mcm","clk":"1005135028","pt":1580641041514,"mc":[{"id":"1.168230817","rc":[{"trd":[[1.02,2.5]],"batb":[[0,1.02,7.31]],"ltp":1.02,"tv":2.49,"id":2263600,"hc":-10.5},{"trd":[[1.02,2.64]],"batb":[[0,1.02,7.22]],"ltp":1.02,"tv":2.63,"id":2263600,"hc":-11.5}],"tv":7.56}]}
{"op":"mcm","clk":"1005135162","pt":1580641042446,"mc":[{"id":"1.168230817","rc":[{"batl":[[0,1000,0.02]],"ltp":1.02,"tv":2.43,"id":2263600,"hc":-9.5}]}]}
{"op":"mcm","clk":"1005135224","pt":1580641042918,"mc":[{"id":"1.168230817","rc":[{"trd":[[1.02,2.45]],"batb":[[0,1.02,7.34]],"batl":[[0,990,0.01]],"ltp":1.02,"tv":2.45,"id":2263600,"hc":-9.5}],"tv":7.58}]}
{"op":"mcm","clk":"1005135680","pt":1580641046614,"mc":[{"id":"1.168230817","rc":[{"batl":[[0,1000,0.02]],"ltp":1.02,"tv":2.63,"id":2263600,"hc":-11.5}]}]}
{"op":"mcm","clk":"1005135762","pt":1580641047345,"mc":[{"id":"1.168230817","rc":[{"trd":[[1.02,2.51]],"batb":[[0,1.02,7.3]],"ltp":1.02,"tv":2.51,"id":2263600,"hc":-10.5},{"trd":[[1.02,2.65]],"batb":[[0,1.02,7.21]],"batl":[[0,990,0.01]],"ltp":1.02,"tv":2.65,"id":2263600,"hc":-11.5}],"tv":7.61}]}
{"op":"mcm","clk":"1005135923","pt":1580641048549,"mc":[{"id":"1.168230817","rc":[{"trd":[[1.02,2.47]],"batb":[[0,1.02,7.33]],"ltp":1.02,"tv":2.46,"id":2263600,"hc":-9.5}],"tv":7.62}]}
{"op":"mcm","clk":"1005136339","pt":1580641051619,"mc":[{"id":"1.168230817","rc":[{"batl":[[0,1000,2.37]],"ltp":1.02,"tv":2.65,"id":2263600,"hc":-11.5}]}]}
{"op":"mcm","clk":"1005136437","pt":1580641052547,"mc":[{"id":"1.168230817","rc":[{"trd":[[1.02,2.67]],"batb":[[0,1.02,7.2]],"batl":[[0,990,0.01]],"ltp":1.02,"tv":2.66,"id":2263600,"hc":-11.5}],"tv":7.64}]}
{"op":"mcm","clk":"1005136566","pt":1580641053646,"mc":[{"id":"1.168230817","rc":[{"trd":[[1.02,2.53]],"batb":[[0,1.02,7.29]],"ltp":1.02,"tv":2.52,"id":2263600,"hc":-10.5}],"tv":7.66}]}
{"op":"mcm","clk":"1005136579","pt":1580641053751,"mc":[{"id":"1.168230817","rc":[{"trd":[[1.02,2.48]],"batb":[[0,1.02,7.32]],"ltp":1.02,"tv":2.48,"id":2263600,"hc":-9.5}],"tv":7.67}]}
{"op":"mcm","clk":"1005137128","pt":1580641057520,"mc":[{"id":"1.168230817","rc":[{"batl":[[0,1000,2.37]],"ltp":1.02,"tv":2.52,"id":2263600,"hc":-10.5},{"batl":[[0,1000,2.37]],"ltp":1.02,"tv":2.66,"id":2263600,"hc":-11.5}]}]}
{"op":"mcm","clk":"1005137228","pt":1580641058144,"mc":[{"id":"1.168230817","rc":[{"trd":[[1.02,2.54]],"batb":[[0,1.02,7.28]],"batl":[[0,990,0.01]],"ltp":1.02,"tv":2.54,"id":2263600,"hc":-10.5},{"trd":[[1.02,2.68]],"batb":[[0,1.02,7.19]],"batl":[[0,990,0.01]],"ltp":1.02,"tv":2.68,"id":2263600,"hc":-11.5}],"tv":7.7}]}
{"op":"mcm","clk":"1005137385","pt":1580641059542,"mc":[{"id":"1.168230817","rc":[{"trd":[[1.02,2.5]],"batb":[[0,1.02,7.31]],"ltp":1.02,"tv":2.49,"id":2263600,"hc":-9.5}],"tv":7.72}]}
{"op":"mcm","clk":"1005137870","pt":1580641063562,"mc":[{"id":"1.168230817","rc":[{"trd":[[1.02,2.7]],"batb":[[0,1.02,7.18]],"ltp":1.02,"tv":2.69,"id":2263600,"hc":-11.5}],"tv":7.73}]}
{"op":"mcm","clk":"1005137981","pt":1580641064546,"mc":[{"id":"1.168230817","rc":[{"batl":[[0,1000,0.02]],"ltp":1.02,"tv":2.49,"id":2263600,"hc":-9.5},{"trd":[[1.02,2.56]],"batb":[[0,1.02,7.27]],"ltp":1.02,"tv":2.55,"id":2263600,"hc":-10.5}],"tv":7.75}]}
{"op":"mcm","clk":"1005138024","pt":1580641064962,"mc":[{"id":"1.168230817","rc":[{"trd":[[1.02,2.51]],"batb":[[0,1.02,7.3]],"batl":[[0,990,0.01]],"ltp":1.02,"tv":2.51,"id":2263600,"hc":-9.5}],"tv":7.76}]}
{"op":"mcm","clk":"1005138447","pt":1580641068343,"mc":[{"id":"1.168230817","rc":[{"batl":[[0,1000,0.02]],"ltp":1.02,"tv":2.69,"id":2263600,"hc":-11.5}]}]}
{"op":"mcm","clk":"1005138583","pt":1580641069646,"mc":[{"id":"1.168230817","rc":[{"trd":[[1.02,2.57]],"batb":[[0,1.02,7.26]],"ltp":1.02,"tv":2.57,"id":2263600,"hc":-10.5},{"trd":[[1.02,2.71]],"batb":[[0,1.02,7.17]],"batl":[[0,990,0.01]],"ltp":1.02,"tv":2.71,"id":2263600,"hc":-11.5}],"tv":7.8}]}
{"op":"mcm","clk":"1005138661","pt":1580641070373,"mc":[{"id":"1.168230817","rc":[{"trd":[[1.02,2.53]],"batb":[[0,1.02,7.29]],"ltp":1.02,"tv":2.52,"id":2263600,"hc":-9.5}],"tv":7.81}]}
{"op":"mcm","clk":"1005139176","pt":1580641074646,"mc":[{"id":"1.168230817","rc":[{"batl":[[0,1000,0.02]],"ltp":1.02,"tv":2.57,"id":2263600,"hc":-10.5},{"batl":[[0,1000,0.02]],"ltp":1.02,"tv":2.71,"id":2263600,"hc":-11.5}]}]}
{"op":"mcm","clk":"1005139297","pt":1580641075484,"mc":[{"id":"1.168230817","rc":[{"batl":[[0,1000,2.37]],"ltp":1.02,"tv":2.52,"id":2263600,"hc":-9.5},{"trd":[[1.02,2.59]],"batb":[[0,1.02,7.25]],"batl":[[0,990,0.01]],"ltp":1.02,"tv":2.58,"id":2263600,"hc":-10.5},{"trd":[[1.02,2.73]],"batb":[[0,1.02,7.16]],"batl":[[0,990,0.01]],"ltp":1.02,"tv":2.72,"id":2263600,"hc":-11.5}],"tv":7.84}]}
{"op":"mcm","clk":"1005139361","pt":1580641076058,"mc":[{"id":"1.168230817","rc":[{"trd":[[1.02,2.54]],"batb":[[0,1.02,7.28]],"batl":[[0,990,0.01]],"ltp":1.02,"tv":2.54,"id":2263600,"hc":-9.5}],"tv":7.86}]}
{"op":"mcm","clk":"1005139775","pt":1580641079592,"mc":[{"id":"1.168230817","rc":[{"batl":[[0,1000,2.37]],"ltp":1.02,"tv":2.72,"id":2263600,"hc":-11.5}]}]}
{"op":"mcm","clk":"1005139878","pt":1580641080474,"mc":[{"id":"1.168230817","rc":[{"batl":[[0,1000,0.02]],"ltp":1.02,"tv":2.58,"id":2263600,"hc":-10.5},{"trd":[[1.02,2.74]],"batb":[[0,1.02,7.15]],"batl":[[0,990,0.01]],"ltp":1.02,"tv":2.74,"id":2263600,"hc":-11.5}],"tv":7.87}]}
{"op":"mcm","clk":"1005140002","pt":1580641081460,"mc":[{"id":"1.168230817","rc":[{"trd":[[1.02,2.56]],"batb":[[0,1.02,7.27]],"ltp":1.02,"tv":2.55,"id":2263600,"hc":-9.5},{"trd":[[1.02,2.61]],"batb":[[0,1.02,7.24]],"batl":[[0,990,0.01]],"ltp":1.02,"tv":2.6,"id":2263600,"hc":-10.5}],"tv":7.9}]}
{"op":"mcm","clk":"1005140511","pt":1580641085590,"mc":[{"id":"1.168230817","rc":[{"batl":[[0,1000,2.37]],"ltp":1.02,"tv":2.74,"id":2263600,"hc":-11.5}]}]}
{"op":"mcm","clk":"1005140647","pt":1580641086578,"mc":[{"id":"1.168230817","rc":[{"batl":[[0,1000,0.02]],"ltp":1.02,"tv":2.6,"id":2263600,"hc":-10.5},{"trd":[[1.02,2.76]],"batb":[[0,1.02,7.14]],"batl":[[0,990,0.01]],"ltp":1.02,"tv":2.76,"id":2263600,"hc":-11.5}],"tv":7.92}]}
{"op":"mcm","clk":"1005140737","pt":1580641087412,"mc":[{"id":"1.168230817","rc":[{"trd":[[1.02,2.57]],"batb":[[0,1.02,7.26]],"ltp":1.02,"tv":2.57,"id":2263600,"hc":-9.5},{"trd":[[1.02,2.62]],"batb":[[0,1.02,7.23]],"batl":[[0,990,0.01]],"ltp":1.02,"tv":2.62,"id":2263600,"hc":-10.5}],"tv":7.95}]}
{"op":"mcm","clk":"1005141301","pt":1580641091592,"mc":[{"id":"1.168230817","rc":[{"batl":[[0,1000,2.37]],"ltp":1.02,"tv":2.62,"id":2263600,"hc":-10.5}]}]}
{"op":"mcm","clk":"1005141437","pt":1580641092585,"mc":[{"id":"1.168230817","rc":[{"trd":[[1.02,2.64]],"batb":[[0,1.02,7.22]],"batl":[[0,990,0.01]],"ltp":1.02,"tv":2.63,"id":2263600,"hc":-10.5},{"trd":[[1.02,2.78]],"batb":[[0,1.02,7.13]],"ltp":1.02,"tv":2.77,"id":2263600,"hc":-11.5}],"tv":7.98}]}
{"op":"mcm","clk":"1005141451","pt":1580641092689,"mc":[{"id":"1.168230817","rc":[{"trd":[[1.02,2.59]],"batb":[[0,1.02,7.25]],"ltp":1.02,"tv":2.58,"id":2263600,"hc":-9.5}],"tv":8.0}]}
{"op":"mcm","clk":"1005141890","pt":1580641096492,"mc":[{"id":"1.168230817","rc":[{"batl":[[0,1000,2.37]],"ltp":1.02,"tv":2.77,"id":2263600,"hc":-11.5}]}]}
{"op":"mcm","clk":"1005142047","pt":1580641097593,"mc":[{"id":"1.168230817","rc":[{"batl":[[0,1000,2.37]],"ltp":1.02,"tv":2.63,"id":2263600,"hc":-10.5},{"trd":[[1.02,2.79]],"batb":[[0,1.02,7.12]],"batl":[[0,990,0.01]],"ltp":1.02,"tv":2.79,"id":2263600,"hc":-11.5}],"tv":8.01}]}
{"op":"mcm","clk":"1005142165","pt":1580641098528,"mc":[{"id":"1.168230817","rc":[{"trd":[[1.02,2.61]],"batb":[[0,1.02,7.24]],"ltp":1.02,"tv":2.6,"id":2263600,"hc":-9.5},{"trd":[[1.02,2.65]],"batb":[[0,1.02,7.21]],"batl":[[0,990,0.01]],"ltp":1.02,"tv":2.65,"id":2263600,"hc":-10.5}],"tv":8.04}]}
{"op":"mcm","clk":"1005142658","pt":1580641102530,"mc":[{"id":"1.168230817","rc":[{"batl":[[0,1000,0.02]],"ltp":1.02,"tv":2.79,"id":2263600,"hc":-11.5}]}]}
{"op":"mcm","clk":"1005142807","pt":1580641103626,"mc":[{"id":"1.168230817","rc":[{"batl":[[0,1000,2.37]],"ltp":1.02,"tv":2.6,"id":2263600,"hc":-9.5},{"trd":[[1.02,2.81]],"batb":[[0,1.02,7.11]],"batl":[[0,990,0.01]],"ltp":1.02,"tv":2.8,"id":2263600,"hc":-11.5}],"tv":8.06}]}
{"op":"mcm","clk":"1005142889","pt":1580641104201,"mc":[{"id":"1.168230817","rc":[{"trd":[[1.02,2.62]],"batb":[[0,1.02,7.23]],"batl":[[0,990,0.01]],"ltp":1.02,"tv":2.62,"id":2263600,"hc":-9.5},{"trd":[[1.02,2.67]],"batb":[[0,1.02,7.2]],"ltp":1.02,"tv":2.66,"id":2263600,"hc":-10.5}],"tv":8.09}]}
{"op":"mcm","clk":"1005143591","pt":1580641109623,"mc":[{"id":"1.168230817","rc":[{"batl":[[0,1000,0.02]],"ltp":1.02,"tv":2.62,"id":2263600,"hc":-9.5},{"trd":[[1.02,2.68]],"batb":[[0,1.02,7.19]],"ltp":1.02,"tv":2.68,"id":2263600,"hc":-10.5},{"trd":[[1.02,2.82]],"batb":[[0,1.02,7.1]],"ltp":1.02,"tv":2.82,"id":2263600,"hc":-11.5}],"tv":8.12}]}
{"op":"mcm","clk":"1005143618","pt":1580641109829,"mc":[{"id":"1.168230817","rc":[{"trd":[[1.02,2.64]],"batb":[[0,1.02,7.22]],"batl":[[0,990,0.01]],"ltp":1.02,"tv":2.63,"id":2263600,"hc":-9.5}],"tv":8.14}]}
{"op":"mcm","clk":"1005144365","pt":1580641115647,"mc":[{"id":"1.168230817","rc":[{"trd":[[1.02,2.65]],"batb":[[0,1.02,7.21]],"ltp":1.02,"tv":2.65,"id":2263600,"hc":-9.5},{"trd":[[1.02,2.84]],"batb":[[0,1.02,7.09]],"ltp":1.02,"tv":2.83,"id":2263600,"hc":-11.5}],"tv":8.17}]}
{"op":"mcm","clk":"1005144380","pt":1580641115750,"mc":[{"id":"1.168230817","rc":[{"trd":[[1.02,2.7]],"batb":[[0,1.02,7.18]],"ltp":1.02,"tv":2.69,"id":2263600,"hc":-10.5}],"tv":8.18}]}
{"op":"mcm","clk":"1005144756","pt":1580641118417,"mc":[{"id":"1.168230817","rc":[{"batl":[[0,1000,0.02]],"ltp":1.02,"tv":2.83,"id":2263600,"hc":-11.5}]}]}
{"op":"mcm","clk":"1005144814","pt":1580641118833,"mc":[{"id":"1.168230817","rc":[{"trd":[[1.02,2.85]],"batb":[[0,1.02,7.08]],"batl":[[0,990,0.01]],"ltp":1.02,"tv":2.85,"id":2263600,"hc":-11.5}],"tv":8.2}]}
{"op":"mcm","clk":"1005145061","pt":1580641120617,"mc":[{"id":"1.168230817","rc":[{"trd":[[1.02,2.67]],"batb":[[0,1.02,7.2]],"ltp":1.02,"tv":2.66,"id":2263600,"hc":-9.5}],"tv":8.21}]}
{"op":"mcm","clk":"1005145181","pt":1580641121441,"mc":[{"id":"1.168230817","rc":[{"trd":[[1.02,2.71]],"batb":[[0,1.02,7.17]],"ltp":1.02,"tv":2.71,"id":2263600,"hc":-10.5}],"tv":8.23}]}
{"op":"mcm","clk":"1005145673","pt":1580641125548,"mc":[{"id":"1.168230817","rc":[{"batl":[[0,1000,2.37]],"ltp":1.02,"tv":2.85,"id":2263600,"hc":-11.5}]}]}
{"op":"mcm","clk":"1005145820","pt":1580641126642,"mc":[{"id":"1.168230817","rc":[{"trd":[[1.02,2.68]],"batb":[[0,1.02,7.19]],"ltp":1.02,"tv":2.68,"id":2263600,"hc":-9.5},{"batl":[[0,1000,2.37]],"ltp":1.02,"tv":2.71,"id":2263600,"hc":-10.5},{"trd":[[1.02,2.87]],"batb":[[0,1.02,7.07]],"batl":[[0,990,0.01]],"ltp":1.02,"tv":2.86,"id":2263600,"hc":-11.5}],"tv":8.26}]}
{"op":"mcm","clk":"1005145918","pt":1580641127269,"mc":[{"id":"1.168230817","rc":[{"trd":[[1.02,2.73]],"batb":[[0,1.02,7.16]],"batl":[[0,990,0.01]],"ltp":1.02,"tv":2.72,"id":2263600,"hc":-10.5}],"tv":8.28}]}
{"op":"mcm","clk":"1005146453","pt":1580641131643,"mc":[{"id":"1.168230817","rc":[{"batl":[[0,1000,0.02]],"ltp":1.02,"tv":2.68,"id":2263600,"hc":-9.5},{"trd":[[1.02,2.88]],"batb":[[0,1.02,7.06]],"ltp":1.02,"tv":2.88,"id":2263600,"hc":-11.5}],"tv":8.29}]}
{"op":"mcm","clk":"1005146562","pt":1580641132531,"mc":[{"id":"1.168230817","rc":[{"trd":[[1.02,2.7]],"batb":[[0,1.02,7.18]],"batl":[[0,990,0.01]],"ltp":1.02,"tv":2.69,"id":2263600,"hc":-9.5},{"batl":[[0,1000,2.37]],"ltp":1.02,"tv":2.72,"id":2263600,"hc":-10.5}],"tv":8.31}]}
{"op":"mcm","clk":"1005146661","pt":1580641133252,"mc":[{"id":"1.168230817","rc":[{"trd":[[1.02,2.74]],"batb":[[0,1.02,7.15]],"batl":[[0,990,0.01]],"ltp":1.02,"tv":2.74,"id":2263600,"hc":-10.5}],"tv":8.32}]}
{"op":"mcm","clk":"1005147250","pt":1580641137645,"mc":[{"id":"1.168230817","rc":[{"trd":[[1.02,2.71]],"batb":[[0,1.02,7.17]],"ltp":1.02,"tv":2.71,"id":2263600,"hc":-9.5},{"trd":[[1.02,2.9]],"batb":[[0,1.02,7.05]],"ltp":1.02,"tv":2.89,"id":2263600,"hc":-11.5}],"tv":8.35}]}
{"op":"mcm","clk":"1005147500","pt":1580641139566,"mc":[{"id":"1.168230817","rc":[{"trd":[[1.02,2.76]],"batb":[[0,1.02,7.14]],"ltp":1.02,"tv":2.76,"id":2263600,"hc":-10.5}],"tv":8.37}]}
{"op":"mcm","clk":"1005148079","pt":1580641143465,"mc":[{"id":"1.168230817","rc":[{"trd":[[1.02,2.73]],"batb":[[0,1.02,7.16]],"ltp":1.02,"tv":2.72,"id":2263600,"hc":-9.5},{"trd":[[1.02,2.92]],"batb":[[0,1.02,7.04]],"ltp":1.02,"tv":2.91,"id":2263600,"hc":-11.5}],"tv":8.4}]}
{"op":"mcm","clk":"1005148452","pt":1580641145553,"mc":[{"id":"1.168230817","rc":[{"batl":[[0,1000,0.02]],"ltp":1.02,"tv":2.76,"id":2263600,"hc":-10.5}]}]}
{"op":"mcm","clk":"1005148502","pt":1580641145869,"mc":[{"id":"1.168230817","rc":[{"trd":[[1.02,2.78]],"batb":[[0,1.02,7.13]],"batl":[[0,990,0.01]],"ltp":1.02,"tv":2.77,"id":2263600,"hc":-10.5}],"tv":8.42}]}
{"op":"mcm","clk":"1005148902","pt":1580641148554,"mc":[{"id":"1.168230817","rc":[{"batl":[[0,1000,0.02]],"ltp":1.02,"tv":2.72,"id":2263600,"hc":-9.5},{"batl":[[0,1000,2.37]],"ltp":1.02,"tv":2.91,"id":2263600,"hc":-11.5}]}]}
{"op":"mcm","clk":"1005148985","pt":1580641149175,"mc":[{"id":"1.168230817","rc":[{"trd":[[1.02,2.74]],"batb":[[0,1.02,7.15]],"batl":[[0,990,0.01]],"ltp":1.02,"tv":2.74,"id":2263600,"hc":-9.5},{"trd":[[1.02,2.93]],"batb":[[0,1.02,7.03]],"batl":[[0,990,0.01]],"ltp":1.02,"tv":2.93,"id":2263600,"hc":-11.5}],"tv":8.45}]}
{"op":"mcm","clk":"1005149175","pt":1580641150468,"mc":[{"id":"1.168230817","rc":[{"batl":[[0,1000,2.37]],"ltp":1.02,"tv":2.77,"id":2263600,"hc":-10.5}]}]}
{"op":"mcm","clk":"1005149259","pt":1580641151084,"mc":[{"id":"1.168230817","rc":[{"trd":[[1.02,2.79]],"batb":[[0,1.02,7.12]],"batl":[[0,990,0.01]],"ltp":1.02,"tv":2.79,"id":2263600,"hc":-10.5}],"tv":8.46}]}
{"op":"mcm","clk":"1005149702","pt":1580641154494,"mc":[{"id":"1.168230817","rc":[{"trd":[[1.02,2.76]],"batb":[[0,1.02,7.14]],"ltp":1.02,"tv":2.76,"id":2263600,"hc":-9.5},{"trd":[[1.02,2.95]],"batb":[[0,1.02,7.02]],"ltp":1.02,"tv":2.94,"id":2263600,"hc":-11.5}],"tv":8.49}]}
{"op":"mcm","clk":"1005149985","pt":1580641156656,"mc":[{"id":"1.168230817","rc":[{"trd":[[1.02,2.81]],"batb":[[0,1.02,7.11]],"ltp":1.02,"tv":2.8,"id":2263600,"hc":-10.5}],"tv":8.51}]}
{"op":"mcm","clk":"1005150330","pt":1580641159485,"mc":[{"id":"1.168230817","rc":[{"batl":[[0,1000,0.02]],"ltp":1.02,"tv":2.76,"id":2263600,"hc":-9.5}]}]}
{"op":"mcm","clk":"1005150468","pt":1580641160500,"mc":[{"id":"1.168230817","rc":[{"trd":[[1.02,2.78]],"batb":[[0,1.02,7.13]],"batl":[[0,990,0.01]],"ltp":1.02,"tv":2.77,"id":2263600,"hc":-9.5},{"trd":[[1.02,2.96]],"batb":[[0,1.02,7.01]],"ltp":1.02,"tv":2.96,"id":2263600,"hc":-11.5}],"tv":8.54}]}
