{"op":"mcm","clk":"1002227598","pt":1580591606373,"mc":[{"id":"1.168237330","marketDefinition":{"bspMarket":false,"turnInPlayEnabled":true,"persistenceEnabled":true,"marketBaseRate":5.0,"eventId":"29681784","eventTypeId":"2","numberOfWinners":1,"bettingType":"ODDS","marketType":"MATCH_ODDS","marketTime":"2020-02-01T23:00:00.000Z","suspendTime":"2020-02-01T23:00:00.000Z","bspReconciled":false,"complete":true,"inPlay":false,"crossMatching":false,"runnersVoidable":false,"numberOfActiveRunners":2,"betDelay":0,"status":"OPEN","runners":[{"status":"ACTIVE","sortPriority":1,"id":6596286,"name":"Sachia Vickery"},{"status":"ACTIVE","sortPriority":2,"id":8196374,"name":"Maddison Inglis"}],"regulators":["MR_INT"],"countryCode":"AU","discountAllowed":false,"timezone":"GMT","openDate":"2020-02-01T23:00:00.000Z","version":3147513324,"name":"Match Odds","eventName":"S Vickery v M Inglis"},"rc":[{"batb":[[0,1.05,152.2],[1,1.04,168.86],[2,1.03,237.77]],"ltp":0.0,"tv":0.0,"id":6596286},{"batb":[[0,1.05,152.2],[1,1.04,168.86],[2,1.03,237.77]],"ltp":0.0,"tv":0.0,"id":8196374}]}]}
{"op":"mcm","clk":"1002227759","pt":1580591607990,"mc":[{"id":"1.168237330","marketDefinition":{"bspMarket":false,"turnInPlayEnabled":true,"persistenceEnabled":true,"marketBaseRate":5.0,"eventId":"29681784","eventTypeId":"2","numberOfWinners":1,"bettingType":"ODDS","marketType":"MATCH_ODDS","marketTime":"2020-02-01T23:00:00.000Z","suspendTime":"2020-02-01T23:00:00.000Z","bspReconciled":false,"complete":true,"inPlay":false,"crossMatching":false,"runnersVoidable":false,"numberOfActiveRunners":2,"betDelay":0,"status":"OPEN","runners":[{"status":"ACTIVE","sortPriority":1,"id":6596286,"name":"Sachia Vickery"},{"status":"ACTIVE","sortPriority":2,"id":8196374,"name":"Maddison Inglis"}],"regulators":["MR_INT"],"countryCode":"AU","discountAllowed":true,"timezone":"GMT","openDate":"2020-02-01T23:00:00.000Z","version":3147513324,"name":"Match Odds","eventName":"S Vickery v M Inglis"}}]}
{"op":"mcm","clk":"1002228240","pt":1580591613034,"mc":[{"id":"1.168237330","marketDefinition":{"bspMarket":false,"turnInPlayEnabled":true,"persistenceEnabled":true,"marketBaseRate":5.0,"eventId":"29681784","eventTypeId":"2","numberOfWinners":1,"bettingType":"ODDS","marketType":"MATCH_ODDS","marketTime":"2020-02-01T23:00:00.000Z","suspendTime":"2020-02-01T23:00:00.000Z","bspReconciled":false,"complete":true,"inPlay":false,"crossMatching":true,"runnersVoidable":false,"numberOfActiveRunners":2,"betDelay":0,"status":"OPEN","runners":[{"status":"ACTIVE","sortPriority":1,"id":6596286,"name":"Sachia Vickery"},{"status":"ACTIVE","sortPriority":2,"id":8196374,"name":"Maddison Inglis"}],"regulators":["MR_INT"],"countryCode":"AU","discountAllowed":true,"timezone":"GMT","openDate":"2020-02-01T23:00:00.000Z","version":3147513324,"name":"Match Odds","eventName":"S Vickery v M Inglis"}}]}
{"op":"mcm","clk":"1002236107","pt":1580591696598,"mc":[{"id":"1.168237330","rc":[{"batb":[[0,1.26,234.48],[1,1.05,152.2],[2,1.04,168.86]],"ltp":0.0,"tv":0.0,"id":6596286},{"batb":[[0,1.87,130.04],[1,1.05,152.2],[2,1.04,168.86]],"ltp":0.0,"tv":0.0,"id":8196374}]}]}
{"op":"mcm","clk":"1002236406","pt":1580591699925,"mc":[{"id":"1.168237330","rc":[{"batb":[[0,1.45,203.41],[1,1.44,18.93],[2,1.05,152.2]],"ltp":0.0,"tv":0.0,"id":6596286},{"batb":[[0,2.3,12.12],[1,1.87,130.04],[2,1.05,152.2]],"ltp":0.0,"tv":0.0,"id":8196374}]}]}
{"op":"mcm","clk":"1002236446","pt":1580591700241,"mc":[{"id":"1.168237330","rc":[{"batb":[[0,2.32,104.39],[1,2.3,12.12]],"ltp":0.0,"tv":0.0,"id":8196374}]}]}
{"op":"mcm","clk":"1002241588","pt":1580591752052,"mc":[{"id":"1.168237330","rc":[{"batb":[[2,1.43,220.13]],"ltp":0.0,"tv":0.0,"id":6596286},{"batb":[[2,2.24,76.34]],"ltp":0.0,"tv":0.0,"id":8196374}]}]}
{"op":"mcm","clk":"1002243497","pt":1580591773866,"mc":[{"id":"1.168237330","rc":[{"batb":[[0,1.45,203.42]],"ltp":0.0,"tv":0.0,"id":6596286}]}]}
{"op":"mcm","clk":"1002290695","pt":1580592185694,"mc":[{"id":"1.168237330","rc":[{"batb":[[0,1.47,200.68],[1,1.46,18.93]],"ltp":0.0,"tv":0.0,"id":6596286},{"batb":[[0,2.36,102.68],[1,2.34,12.12]],"ltp":0.0,"tv":0.0,"id":8196374}]}]}
{"op":"mcm","clk":"1002293811","pt":1580592213518,"mc":[{"id":"1.168237330","rc":[{"batb":[[0,1.5,109.52],[1,1.46,18.94]],"ltp":0.0,"tv":0.0,"id":6596286},{"batb":[[0,2.5,36.5]],"ltp":0.0,"tv":0.0,"id":8196374}]}]}
{"op":"mcm","clk":"1002294620","pt":1580592220907,"mc":[{"id":"1.168237330","rc":[{"batb":[[1,1.43,220.14],[2,1.05,152.2]],"ltp":0.0,"tv":0.0,"id":6596286}]}]}
{"op":"mcm","clk":"1002294702","pt":1580592221650,"mc":[{"id":"1.168237330","rc":[{"batb":[[1,1.46,37.87],[2,1.43,220.13]],"ltp":0.0,"tv":0.0,"id":6596286},{"batb":[[1,2.34,22.72]],"ltp":0.0,"tv":0.0,"id":8196374}]}]}
{"op":"mcm","clk":"1002299706","pt":1580592269441,"mc":[{"id":"1.168237330","rc":[{"batb":[[0,1.51,7.44],[1,1.5,109.52],[2,1.46,37.87]],"ltp":0.0,"tv":0.0,"id":6596286}]}]}
{"op":"mcm","clk":"1002360882","pt":1580592872918,"mc":[{"id":"1.168237330","rc":[{"batb":[[1,2.24,76.34],[2,1.05,152.21]],"ltp":0.0,"tv":0.0,"id":8196374}]}]}
{"op":"mcm","clk":"1002360896","pt":1580592872983,"mc":[{"id":"1.168237330","rc":[{"batb":[[1,2.36,22.72],[2,2.24,76.34]],"ltp":0.0,"tv":0.0,"id":8196374}]}]}
{"op":"mcm","clk":"1002365034","pt":1580592912252,"mc":[{"id":"1.168237330","rc":[{"batb":[[1,2.34,22.72]],"ltp":0.0,"tv":0.0,"id":8196374}]}]}
{"op":"mcm","clk":"1002492170","pt":1580594404828,"mc":[{"id":"1.168237330","rc":[{"batb":[[1,1.5,159.93]],"ltp":0.0,"tv":0.0,"id":6596286},{"batb":[[0,2.5,53.3]],"ltp":0.0,"tv":0.0,"id":8196374}]}]}
{"op":"mcm","clk":"1002493237","pt":1580594420817,"mc":[{"id":"1.168237330","rc":[{"batb":[[2,1.43,220.14]],"ltp":0.0,"tv":0.0,"id":6596286},{"batb":[[1,2.24,76.34],[2,1.05,152.21]],"ltp":0.0,"tv":0.0,"id":8196374}]}]}
{"op":"mcm","clk":"1002494324","pt":1580594434211,"mc":[{"id":"1.168237330","rc":[{"batb":[[2,1.35,25.01]],"ltp":0.0,"tv":0.0,"id":6596286},{"batb":[[1,1.05,152.21],[2,1.04,168.86]],"ltp":0.0,"tv":0.0,"id":8196374}]}]}
{"op":"mcm","clk":"1002510554","pt":1580594671912,"mc":[{"id":"1.168237330","rc":[{"trd":[[1.51,14.87]],"batb":[[0,1.5,109.52],[1,1.45,56.03],[2,1.35,25]],"batl":[[0,1.51,48.02]],"ltp":1.51,"tv":14.87,"id":6596286},{"batb":[[0,2.84,13.7],[1,2.5,36.5],[2,1.05,152.21]],"ltp":0.0,"tv":0.0,"id":8196374}],"tv":14.87}]}
{"op":"mcm","clk":"1002510599","pt":1580594672745,"mc":[{"id":"1.168237330","rc":[{"trd":[[1.51,110.85]],"batl":[[0,1.51,0.03]],"ltp":1.51,"tv":110.85,"id":6596286}],"tv":110.85}]}
{"op":"mcm","clk":"1002510694","pt":1580594673894,"mc":[{"id":"1.168237330","rc":[{"batb":[[1,1.49,51.44],[2,1.45,56.03]],"ltp":1.51,"tv":110.85,"id":6596286},{"batb":[[0,2.5,53.3],[1,1.05,152.21],[2,1.04,168.86]],"ltp":0.0,"tv":0.0,"id":8196374}]}]}
{"op":"mcm","clk":"1002510809","pt":1580594674839,"mc":[{"id":"1.168237330","rc":[{"batb":[[0,1.5,159.93]],"ltp":1.51,"tv":110.85,"id":6596286}]}]}
{"op":"mcm","clk":"1002515593","pt":1580594746527,"mc":[{"id":"1.168237330","rc":[{"trd":[[1.5,20]],"batb":[[0,1.5,149.93]],"ltp":1.5,"tv":130.85,"id":6596286}],"tv":130.85}]}
{"op":"mcm","clk":"1002515704","pt":1580594748810,"mc":[{"id":"1.168237330","rc":[{"batb":[[0,1.5,159.93]],"ltp":1.5,"tv":130.85,"id":6596286}]}]}
{"op":"mcm","clk":"1002519144","pt":1580594809892,"mc":[{"id":"1.168237330","rc":[{"batb":[[0,2.52,4.45],[1,2.5,53.3],[2,1.05,152.21]],"ltp":0.0,"tv":0.0,"id":8196374}]}]}
{"op":"mcm","clk":"1002520065","pt":1580594825211,"mc":[{"id":"1.168237330","rc":[{"batl":[[0,1.65,2.3]],"ltp":1.5,"tv":130.85,"id":6596286}]}]}
{"op":"mcm","clk":"1002520283","pt":1580594828801,"mc":[{"id":"1.168237330","rc":[{"batl":[[0,1.63,2.3]],"ltp":1.5,"tv":130.85,"id":6596286}]}]}
{"op":"mcm","clk":"1002521004","pt":1580594838753,"mc":[{"id":"1.168237330","rc":[{"batl":[[0,1.6,2.3]],"ltp":1.5,"tv":130.85,"id":6596286}]}]}
{"op":"mcm","clk":"1002524825","pt":1580594898946,"mc":[{"id":"1.168237330","rc":[{"trd":[[1.51,110.88]],"batb":[[0,1.54,46.68],[1,1.5,159.93],[2,1.49,51.44]],"batl":[[0,1.6,2.27]],"ltp":1.51,"tv":130.87,"id":6596286},{"trd":[[2.96,0.02]],"batl":[[0,2.8,81.53]],"ltp":2.96,"tv":0.01,"id":8196374}],"tv":130.89}]}
{"op":"mcm","clk":"1002525860","pt":1580594915359,"mc":[{"id":"1.168237330","rc":[{"trd":[[1.55,2.27]],"ltp":1.55,"tv":133.15,"id":6596286},{"trd":[[2.8,1.26]],"batl":[[0,2.8,80.28]],"ltp":2.8,"tv":1.27,"id":8196374}],"tv":134.42}]}
{"op":"mcm","clk":"1002527692","pt":1580594940507,"mc":[{"id":"1.168237330","rc":[{"batl":[[0,2.7,5.07],[1,2.8,80.28]],"ltp":2.8,"tv":1.27,"id":8196374}]}]}
{"op":"mcm","clk":"1002550720","pt":1580595226870,"mc":[{"id":"1.168237330","rc":[{"trd":[[1.58,4.2]],"ltp":1.58,"tv":137.35,"id":6596286},{"trd":[[2.7,2.46]],"batl":[[0,2.7,2.61]],"ltp":2.7,"tv":3.72,"id":8196374}],"tv":141.07}]}
{"op":"mcm","clk":"1002557198","pt":1580595303474,"mc":[{"id":"1.168237330","rc":[{"batl":[[0,2.68,22],[1,2.7,2.61],[2,2.8,80.28]],"ltp":2.7,"tv":3.72,"id":8196374}]}]}
{"op":"mcm","clk":"1002557268","pt":1580595304109,"mc":[{"id":"1.168237330","rc":[{"batb":[[1,2.5,36.5],[2,2.46,17.27]],"ltp":2.7,"tv":3.72,"id":8196374}]}]}
{"op":"mcm","clk":"1002606949","pt":1580595993974,"mc":[{"id":"1.168237330","rc":[{"batl":[[2,2.8,0]],"ltp":2.7,"tv":3.72,"id":8196374}]}]}
{"op":"mcm","clk":"1002606983","pt":1580595994393,"mc":[{"id":"1.168237330","rc":[{"trd":[[1.6,2.27]],"ltp":1.6,"tv":139.62,"id":6596286},{"trd":[[2.66,1.37]],"batl":[[0,2.64,78.91],[1,2.68,22],[2,2.7,2.61]],"ltp":2.66,"tv":5.09,"id":8196374}],"tv":144.71}]}
{"op":"mcm","clk":"1002607048","pt":1580595995278,"mc":[{"id":"1.168237330","rc":[{"batb":[[0,1.58,43.45],[1,1.54,46.68],[2,1.5,159.93]],"ltp":1.6,"tv":139.62,"id":6596286}]}]}
{"op":"mcm","clk":"1002621761","pt":1580596201969,"mc":[{"id":"1.168237330","rc":[{"batb":[[2,1.5,160.41]],"ltp":1.6,"tv":139.62,"id":6596286}]}]}
{"op":"mcm","clk":"1002630062","pt":1580596319405,"mc":[{"id":"1.168237330","rc":[{"trd":[[1.6,4.8]],"ltp":1.6,"tv":142.15,"id":6596286},{"trd":[[2.64,1.53]],"batl":[[0,2.64,77.37]],"ltp":2.64,"tv":6.63,"id":8196374}],"tv":148.78}]}
{"op":"mcm","clk":"1002656166","pt":1580596732189,"mc":[{"id":"1.168237330","rc":[{"trd":[[1.6,5]],"batb":[[1,1.54,46.88]],"ltp":1.6,"tv":142.35,"id":6596286},{"trd":[[2.52,0.39],[2.64,1.65]],"batb":[[0,2.52,4.26]],"batl":[[0,2.64,77.26]],"ltp":2.52,"tv":7.13,"id":8196374}],"tv":149.48}]}
{"op":"mcm","clk":"1002658186","pt":1580596769261,"mc":[{"id":"1.168237330","rc":[{"trd":[[1.6,11.33]],"ltp":1.6,"tv":148.68,"id":6596286},{"trd":[[2.64,5.49]],"batl":[[0,2.64,73.42]],"ltp":2.64,"tv":10.97,"id":8196374}],"tv":159.66}]}
{"op":"mcm","clk":"1002662169","pt":1580596833663,"mc":[{"id":"1.168237330","rc":[{"trd":[[2.52,8.9]],"batb":[[0,2.5,36.5],[1,2.4,18.2],[2,1.05,152.4]],"batl":[[0,2.52,353.12],[1,2.64,73.42],[2,2.68,22]],"ltp":2.52,"tv":19.48,"id":8196374}],"tv":168.17}]}
{"op":"mcm","clk":"1002662245","pt":1580596834545,"mc":[{"id":"1.168237330","rc":[{"batb":[[0,1.6,42.01],[1,1.58,43.45],[2,1.54,46.88]],"ltp":1.6,"tv":148.68,"id":6596286}]}]}
{"op":"mcm","clk":"1002664117","pt":1580596864473,"mc":[{"id":"1.168237330","rc":[{"batl":[[0,2.64,73.42],[1,2.68,22],[2,2.7,2.61]],"ltp":2.52,"tv":19.48,"id":8196374}]}]}
{"op":"mcm","clk":"1002664229","pt":1580596865615,"mc":[{"id":"1.168237330","rc":[{"batb":[[0,1.58,43.45],[1,1.54,46.88],[2,1.5,160.41]],"ltp":1.6,"tv":148.68,"id":6596286},{"batb":[[1,2.46,17.27],[2,2.4,18.2]],"ltp":2.52,"tv":19.48,"id":8196374}]}]}
{"op":"mcm","clk":"1002687328","pt":1580597260828,"mc":[{"id":"1.168237330","rc":[{"trd":[[2.64,15.48]],"batl":[[0,2.64,68.42]],"ltp":2.64,"tv":29.48,"id":8196374}],"tv":178.16}]}
{"op":"mcm","clk":"1002694473","pt":1580597383784,"mc":[{"id":"1.168237330","rc":[{"batb":[[0,1.59,42.72],[1,1.58,43.45],[2,1.54,46.88]],"ltp":1.6,"tv":148.68,"id":6596286},{"batb":[[1,2.42,17.75]],"batl":[[0,2.58,68.42]],"ltp":2.64,"tv":29.48,"id":8196374}]}]}
{"op":"mcm","clk":"1002697238","pt":1580597428763,"mc":[{"id":"1.168237330","rc":[{"batl":[[0,1000,0.02]],"ltp":1.6,"tv":148.68,"id":6596286}]}]}
{"op":"mcm","clk":"1002697265","pt":1580597429125,"mc":[{"id":"1.168237330","rc":[{"trd":[[1.63,0.02]],"ltp":1.63,"tv":148.69,"id":6596286},{"trd":[[2.58,0.01]],"batl":[[0,2.58,68.41]],"ltp":2.58,"tv":29.49,"id":8196374}],"tv":178.19}]}
{"op":"mcm","clk":"1002699244","pt":1580597462309,"mc":[{"id":"1.168237330","rc":[{"batb":[[0,1.59,42.74]],"ltp":1.63,"tv":148.69,"id":6596286}]}]}
{"op":"mcm","clk":"1002713224","pt":1580597687585,"mc":[{"id":"1.168237330","rc":[{"trd":[[1.63,2.95]],"batb":[[0,1.59,42.72]],"ltp":1.63,"tv":151.62,"id":6596286},{"trd":[[2.58,1.84]],"batl":[[0,2.58,66.59]],"ltp":2.58,"tv":31.32,"id":8196374}],"tv":182.95}]}
{"op":"mcm","clk":"1002717412","pt":1580597751281,"mc":[{"id":"1.168237330","rc":[{"trd":[[2.58,22.53]],"batl":[[0,2.58,56.25]],"ltp":2.58,"tv":52.01,"id":8196374}],"tv":203.63}]}
{"op":"mcm","clk":"1002730873","pt":1580597959205,"mc":[{"id":"1.168237330","rc":[{"trd":[[1.63,92.07]],"batl":[[0,1.63,10.88]],"ltp":1.63,"tv":240.74,"id":6596286},{"trd":[[2.58,78.77]],"batl":[[0,2.68,22],[1,2.7,2.61],[2,2.7,0]],"ltp":2.58,"tv":108.25,"id":8196374}],"tv":349.0}]}
{"op":"mcm","clk":"1002730928","pt":1580597959983,"mc":[{"id":"1.168237330","rc":[{"batb":[[0,1.57,44.22],[1,1.54,46.88],[2,1.5,160.41]],"ltp":1.63,"tv":240.74,"id":6596286},{"batb":[[1,2.46,17.27],[2,2.42,17.75]],"ltp":2.58,"tv":108.25,"id":8196374}]}]}
{"op":"mcm","clk":"1002736474","pt":1580598036931,"mc":[{"id":"1.168237330","rc":[{"trd":[[1.59,10.88]],"ltp":1.59,"tv":251.62,"id":6596286},{"trd":[[2.68,6.45]],"batl":[[0,2.68,15.55]],"ltp":2.68,"tv":114.7,"id":8196374}],"tv":366.33}]}
{"op":"mcm","clk":"1002736573","pt":1580598038021,"mc":[{"id":"1.168237330","rc":[{"batb":[[0,1.5,160.61],[1,1.45,25.01],[2,1.05,152.2]],"ltp":1.59,"tv":251.62,"id":6596286}]}]}
{"op":"mcm","clk":"1002736637","pt":1580598039009,"mc":[{"id":"1.168237330","rc":[{"batb":[[0,2.5,53.3]],"ltp":2.68,"tv":114.7,"id":8196374}]}]}
{"op":"mcm","clk":"1002739662","pt":1580598079993,"mc":[{"id":"1.168237330","rc":[{"batl":[[0,1.65,28.21]],"ltp":1.59,"tv":251.62,"id":6596286}]}]}
{"op":"mcm","clk":"1002739757","pt":1580598081074,"mc":[{"id":"1.168237330","rc":[{"batb":[[2,1.4,101.7]],"ltp":2.68,"tv":114.7,"id":8196374}]}]}
{"op":"mcm","clk":"1002739803","pt":1580598082023,"mc":[{"id":"1.168237330","rc":[{"batb":[[0,2.52,16.59],[1,2.5,53.3],[2,2.46,17.27]],"ltp":2.68,"tv":114.7,"id":8196374}]}]}
{"op":"mcm","clk":"1002741720","pt":1580598110103,"mc":[{"id":"1.168237330","rc":[{"batb":[[0,2.5,53.3],[1,2.46,17.27],[2,1.4,101.7]],"ltp":2.68,"tv":114.7,"id":8196374}]}]}
{"op":"mcm","clk":"1002754131","pt":1580598299388,"mc":[{"id":"1.168237330","rc":[{"trd":[[1.59,37.09]],"batl":[[0,1.59,73.79]],"ltp":1.59,"tv":277.83,"id":6596286},{"trd":[[2.68,22]],"batl":[[0,2.7,2.61],[1,2.7,0]],"ltp":2.68,"tv":130.25,"id":8196374}],"tv":408.09}]}
{"op":"mcm","clk":"1002754166","pt":1580598300073,"mc":[{"id":"1.168237330","rc":[{"batb":[[0,1.5,110.2],[1,1.49,51.44],[2,1.45,25.01]],"ltp":1.59,"tv":277.83,"id":6596286},{"batb":[[0,2.58,15.96],[1,2.5,53.3],[2,2.46,17.27]],"ltp":2.68,"tv":130.25,"id":8196374}]}]}
{"op":"mcm","clk":"1002754581","pt":1580598306117,"mc":[{"id":"1.168237330","rc":[{"batb":[[0,1.5,160.61]],"ltp":1.59,"tv":277.83,"id":6596286},{"batb":[[0,2.5,53.3],[1,2.46,17.27],[2,1.4,101.7]],"ltp":2.68,"tv":130.25,"id":8196374}]}]}
{"op":"mcm","clk":"1002755211","pt":1580598316611,"mc":[{"id":"1.168237330","rc":[{"trd":[[1.58,8.66]],"batl":[[0,1.58,71.54]],"ltp":1.58,"tv":282.29,"id":6596286},{"trd":[[2.7,5.07]],"ltp":2.7,"tv":132.86,"id":8196374}],"tv":415.16}]}
{"op":"mcm","clk":"1002755248","pt":1580598317223,"mc":[{"id":"1.168237330","rc":[{"batb":[[0,1.5,110.2],[1,1.48,52.52],[2,1.45,25]],"ltp":1.58,"tv":282.29,"id":6596286},{"batb":[[0,2.7,14.83],[1,2.5,53.3],[2,2.46,17.27]],"ltp":2.7,"tv":132.86,"id":8196374}]}]}
{"op":"mcm","clk":"1002755494","pt":1580598322148,"mc":[{"id":"1.168237330","rc":[{"batb":[[0,1.5,160.61]],"ltp":1.58,"tv":282.29,"id":6596286},{"batb":[[0,2.5,53.3],[1,2.46,17.27],[2,1.4,101.7]],"ltp":2.7,"tv":132.86,"id":8196374}]}]}
{"op":"mcm","clk":"1002756099","pt":1580598331738,"mc":[{"id":"1.168237330","rc":[{"trd":[[1.5,160.64],[1.52,0.96],[1.55,2.67]],"batb":[[0,1.5,50.41]],"ltp":1.5,"tv":424.29,"id":6596286}],"tv":557.15}]}
{"op":"mcm","clk":"1002756127","pt":1580598332254,"mc":[{"id":"1.168237330","rc":[{"batb":[[0,1.45,25.01],[1,1.42,130.38],[2,1.05,152.2]],"ltp":1.5,"tv":424.29,"id":6596286},{"batb":[[0,2.5,36.5],[1,1.4,101.7],[2,1.05,152.2]],"ltp":2.7,"tv":132.86,"id":8196374}]}]}
{"op":"mcm","clk":"1002759756","pt":1580598386795,"mc":[{"id":"1.168237330","rc":[{"batb":[[0,1.46,1.73],[1,1.45,25],[2,1.42,130.38]],"ltp":1.5,"tv":424.29,"id":6596286},{"batb":[[0,2.52,1],[1,2.5,36.5],[2,1.4,101.7]],"ltp":2.7,"tv":132.86,"id":8196374}]}]}
{"op":"mcm","clk":"1002783744","pt":1580598718370,"mc":[{"id":"1.168237330","rc":[{"trd":[[1.45,50],[1.46,3.44],[1.48,0.02]],"batb":[[0,1.42,130.38],[1,1.38,66.33],[2,1.05,152.2]],"batl":[[0,1.45,1487.73]],"ltp":1.45,"tv":477.75,"id":6596286},{"batb":[[0,3.1,12.01],[1,2.52,1],[2,2.5,36.5]],"ltp":2.7,"tv":132.86,"id":8196374}],"tv":610.62}]}
{"op":"mcm","clk":"1002785543","pt":1580598739796,"mc":[{"id":"1.168237330","rc":[{"trd":[[1.42,0.08]],"batb":[[0,1.42,130.34]],"ltp":1.42,"tv":477.83,"id":6596286}],"tv":610.7}]}
{"op":"mcm","clk":"1002785785","pt":1580598742562,"mc":[{"id":"1.168237330","rc":[{"batb":[[0,1.42,130.38]],"ltp":1.42,"tv":477.83,"id":6596286}]}]}
{"op":"mcm","clk":"1002787298","pt":1580598762326,"mc":[{"id":"1.168237330","rc":[{"batb":[[1,1.05,152.2],[2,1.04,168.86]],"ltp":1.42,"tv":477.83,"id":6596286},{"batb":[[0,2.52,1],[1,2.5,36.5],[2,1.4,101.7]],"ltp":2.7,"tv":132.86,"id":8196374}]}]}
{"op":"mcm","clk":"1002789109","pt":1580598786193,"mc":[{"id":"1.168237330","rc":[{"batl":[[0,3.2,130.22]],"ltp":2.7,"tv":132.86,"id":8196374}]}]}
{"op":"mcm","clk":"1002789196","pt":1580598787288,"mc":[{"id":"1.168237330","rc":[{"batb":[[0,1.45,56.02],[1,1.42,130.38],[2,1.05,152.2]],"ltp":1.42,"tv":477.83,"id":6596286},{"batb":[[1,2.5,53.3]],"ltp":2.7,"tv":132.86,"id":8196374}]}]}
{"op":"mcm","clk":"1002790913","pt":1580598808698,"mc":[{"id":"1.168237330","rc":[{"trd":[[1.45,449.39]],"batb":[[0,1.42,130.38],[1,1.05,152.2],[2,1.04,168.86]],"batl":[[0,1.45,1171.09]],"ltp":1.45,"tv":877.22,"id":6596286},{"trd":[[3.2,130.22]],"ltp":3.2,"tv":263.08,"id":8196374}],"tv":1140.31}]}
{"op":"mcm","clk":"1002790966","pt":1580598809311,"mc":[{"id":"1.168237330","rc":[{"batb":[[1,1.38,66.33],[2,1.05,152.2]],"ltp":1.45,"tv":877.22,"id":6596286},{"batb":[[0,3.1,12.01],[1,2.52,1],[2,2.5,36.5]],"ltp":3.2,"tv":263.08,"id":8196374}]}]}
{"op":"mcm","clk":"1002791231","pt":1580598812694,"mc":[{"id":"1.168237330","rc":[{"batl":[[1,1000,0.5]],"ltp":1.45,"tv":877.22,"id":6596286}]}]}
{"op":"mcm","clk":"1002791269","pt":1580598813113,"mc":[{"id":"1.168237330","rc":[{"trd":[[1.42,1.08]],"batb":[[0,1.42,129.88]],"batl":[[1,1000,0]],"ltp":1.42,"tv":878.22,"id":6596286}],"tv":1141.31}]}
{"op":"mcm","clk":"1002791671","pt":1580598817805,"mc":[{"id":"1.168237330","rc":[{"batb":[[0,1.42,130.38]],"ltp":1.42,"tv":878.22,"id":6596286}]}]}
{"op":"mcm","clk":"1002792131","pt":1580598823321,"mc":[{"id":"1.168237330","rc":[{"batb":[[1,1.05,152.2],[2,1.04,168.86]],"ltp":1.42,"tv":878.22,"id":6596286},{"batb":[[0,2.52,1],[1,2.5,36.5],[2,1.4,101.7]],"ltp":3.2,"tv":263.08,"id":8196374}]}]}
{"op":"mcm","clk":"1002797295","pt":1580598888884,"mc":[{"id":"1.168237330","rc":[{"batl":[[0,1.45,1135.85]],"ltp":1.42,"tv":878.22,"id":6596286}]}]}
{"op":"mcm","clk":"1002797333","pt":1580598889259,"mc":[{"id":"1.168237330","rc":[{"batb":[[1,1.38,66.33],[2,1.05,152.2]],"ltp":1.42,"tv":878.22,"id":6596286},{"batb":[[0,3.1,12.01],[1,2.52,1],[2,2.5,36.5]],"ltp":3.2,"tv":263.08,"id":8196374}]}]}
{"op":"mcm","clk":"1002800917","pt":1580598938331,"mc":[{"id":"1.168237330","rc":[{"batb":[[1,1.05,152.2],[2,1.04,168.86]],"ltp":1.42,"tv":878.22,"id":6596286},{"batb":[[0,2.52,1],[1,2.5,36.5],[2,1.4,101.7]],"ltp":3.2,"tv":263.08,"id":8196374}]}]}
{"op":"mcm","clk":"1002806217","pt":1580599012616,"mc":[{"id":"1.168237330","rc":[{"batl":[[0,3.2,143.44]],"ltp":3.2,"tv":263.08,"id":8196374}]}]}
{"op":"mcm","clk":"1002806258","pt":1580599013344,"mc":[{"id":"1.168237330","rc":[{"batb":[[0,1.45,56.02],[1,1.42,130.38],[2,1.05,152.2]],"ltp":1.42,"tv":878.22,"id":6596286},{"batb":[[1,2.5,53.3]],"ltp":3.2,"tv":263.08,"id":8196374}]}]}
{"op":"mcm","clk":"1002809852","pt":1580599070301,"mc":[{"id":"1.168237330","rc":[{"trd":[[1.45,877.95]],"batb":[[0,1.42,130.38],[1,1.38,66.33]],"batl":[[0,1.45,763.3]],"ltp":1.45,"tv":1306.78,"id":6596286},{"trd":[[3.2,273.66]],"batb":[[0,3.1,12.01],[1,2.52,1],[2,2.5,36.5]],"ltp":3.2,"tv":406.52,"id":8196374}],"tv":1713.3}]}
{"op":"mcm","clk":"1002813794","pt":1580599125500,"mc":[{"id":"1.168237330","rc":[{"batb":[[1,1.05,152.2],[2,1.04,168.86]],"ltp":1.45,"tv":1306.78,"id":6596286},{"batb":[[0,2.52,1],[1,2.5,36.5],[2,1.4,101.7]],"ltp":3.2,"tv":406.52,"id":8196374}]}]}
{"op":"mcm","clk":"1002819172","pt":1580599196275,"mc":[{"id":"1.168237330","rc":[{"batl":[[0,3.1,2.71]],"ltp":3.2,"tv":406.52,"id":8196374}]}]}
{"op":"mcm","clk":"1002830603","pt":1580599346443,"mc":[{"id":"1.168237330","rc":[{"batb":[[0,1.43,1.76],[1,1.42,130.38],[2,1.05,152.2]],"ltp":1.45,"tv":1306.78,"id":6596286}]}]}
{"op":"mcm","clk":"1002835648","pt":1580599421521,"mc":[{"id":"1.168237330","rc":[{"batl":[[0,1000,3.03]],"ltp":1.45,"tv":1306.78,"id":6596286}]}]}
{"op":"mcm","clk":"1002835727","pt":1580599422672,"mc":[{"id":"1.168237330","rc":[{"batl":[[0,1000,1.51]],"ltp":1.45,"tv":1306.78,"id":6596286}]}]}
{"op":"mcm","clk":"1002835792","pt":1580599423559,"mc":[{"id":"1.168237330","rc":[{"trd":[[1.43,3.03]],"batb":[[0,1.42,130.63],[1,1.05,152.2],[2,1.04,168.86]],"ltp":1.43,"tv":1309.81,"id":6596286}],"tv":1716.33}]}
{"op":"mcm","clk":"1002871033","pt":1580599878397,"mc":[{"id":"1.168237330","rc":[{"batb":[[1,1.38,19.69],[2,1.05,152.2]],"ltp":1.43,"tv":1309.81,"id":6596286},{"batb":[[2,2.14,12.5]],"ltp":3.2,"tv":406.52,"id":8196374}]}]}
{"op":"mcm","clk":"1002871845","pt":1580599888354,"mc":[{"id":"1.168237330","rc":[{"batb":[[1,1.05,152.2],[2,1.04,168.86]],"ltp":1.43,"tv":1309.81,"id":6596286},{"batb":[[2,1.4,101.7]],"ltp":3.2,"tv":406.52,"id":8196374}]}]}
{"op":"mcm","clk":"1002872500","pt":1580599896833,"mc":[{"id":"1.168237330","rc":[{"batb":[[1,1.38,19.69],[2,1.05,152.2]],"ltp":1.43,"tv":1309.81,"id":6596286}]}]}
{"op":"mcm","clk":"1002872530","pt":1580599897253,"mc":[{"id":"1.168237330","rc":[{"batb":[[2,2.14,12.5]],"ltp":3.2,"tv":406.52,"id":8196374}]}]}
{"op":"mcm","clk":"1002876394","pt":1580599948769,"mc":[{"id":"1.168237330","rc":[{"batb":[[1,1.05,152.2],[2,1.04,168.86]],"ltp":1.43,"tv":1309.81,"id":6596286},{"batb":[[2,1.4,101.7]],"ltp":3.2,"tv":406.52,"id":8196374}]}]}
{"op":"mcm","clk":"1002876664","pt":1580599951965,"mc":[{"id":"1.168237330","rc":[{"batb":[[1,1.38,19.69],[2,1.05,152.2]],"ltp":1.43,"tv":1309.81,"id":6596286},{"batb":[[2,2.14,12.5]],"ltp":3.2,"tv":406.52,"id":8196374}]}]}
{"op":"mcm","clk":"1002880606","pt":1580600009123,"mc":[{"id":"1.168237330","rc":[{"batb":[[1,1.05,152.2],[2,1.04,168.86]],"ltp":1.43,"tv":1309.81,"id":6596286},{"batb":[[2,1.4,101.7]],"ltp":3.2,"tv":406.52,"id":8196374}]}]}
{"op":"mcm","clk":"1002881215","pt":1580600016631,"mc":[{"id":"1.168237330","rc":[{"batb":[[1,1.38,19.69],[2,1.05,152.2]],"ltp":1.43,"tv":1309.81,"id":6596286}]}]}
{"op":"mcm","clk":"1002881290","pt":1580600017625,"mc":[{"id":"1.168237330","rc":[{"trd":[[1.42,261.84],[1.43,3.53]],"batb":[[0,1.38,19.69],[1,1.05,152.2],[2,1.04,168.86]],"batl":[[0,1.42,626.6]],"ltp":1.42,"tv":1571.07,"id":6596286},{"batb":[[2,2.14,12.5]],"ltp":3.2,"tv":406.52,"id":8196374}],"tv":1977.59}]}
{"op":"mcm","clk":"1002881480","pt":1580600020648,"mc":[{"id":"1.168237330","rc":[{"batb":[[1,1.34,161.06],[2,1.05,152.2]],"ltp":1.42,"tv":1571.07,"id":6596286}]}]}
{"op":"mcm","clk":"1002883563","pt":1580600051980,"mc":[{"id":"1.168237330","rc":[{"trd":[[1.42,344.41]],"batl":[[0,1.42,544.03]],"ltp":1.42,"tv":1653.64,"id":6596286},{"trd":[[3.35,35]],"ltp":3.35,"tv":441.52,"id":8196374}],"tv":2095.16}]}
{"op":"mcm","clk":"1002884752","pt":1580600069483,"mc":[{"id":"1.168237330","rc":[{"batb":[[0,1.34,161.06],[1,1.05,152.2],[2,1.04,168.86]],"ltp":1.42,"tv":1653.64,"id":6596286},{"batb":[[2,1.4,101.7]],"ltp":3.35,"tv":441.52,"id":8196374}]}]}
{"op":"mcm","clk":"1002884893","pt":1580600071509,"mc":[{"id":"1.168237330","rc":[{"batb":[[0,1.34,180.75]],"ltp":1.42,"tv":1653.64,"id":6596286},{"batb":[[2,2.14,12.5]],"ltp":3.35,"tv":441.52,"id":8196374}]}]}
{"op":"mcm","clk":"1002885459","pt":1580600080890,"mc":[{"id":"1.168237330","rc":[{"batb":[[0,1.34,161.06]],"ltp":1.42,"tv":1653.64,"id":6596286}]}]}
{"op":"mcm","clk":"1002885469","pt":1580600080997,"mc":[{"id":"1.168237330","rc":[{"batb":[[0,1.38,19.69],[1,1.34,161.06],[2,1.05,152.2]],"ltp":1.42,"tv":1653.64,"id":6596286}]}]}
{"op":"mcm","clk":"1002888734","pt":1580600129789,"mc":[{"id":"1.168237330","rc":[{"batb":[[0,1.34,161.06],[1,1.05,152.2],[2,1.04,168.86]],"ltp":1.42,"tv":1653.64,"id":6596286},{"batb":[[2,1.4,101.7]],"ltp":3.35,"tv":441.52,"id":8196374}]}]}
{"op":"mcm","clk":"1002889076","pt":1580600134919,"mc":[{"id":"1.168237330","rc":[{"batb":[[0,1.34,180.75]],"ltp":1.42,"tv":1653.64,"id":6596286},{"batb":[[2,2.14,12.5]],"ltp":3.35,"tv":441.52,"id":8196374}]}]}
{"op":"mcm","clk":"1002889718","pt":1580600144295,"mc":[{"id":"1.168237330","rc":[{"batb":[[0,1.38,19.69],[1,1.34,161.06],[2,1.05,152.2]],"ltp":1.42,"tv":1653.64,"id":6596286}]}]}
{"op":"mcm","clk":"1002890194","pt":1580600150837,"mc":[{"id":"1.168237330","rc":[{"batl":[[1,1000,2.17]],"ltp":1.42,"tv":1653.64,"id":6596286}]}]}
{"op":"mcm","clk":"1002890232","pt":1580600151412,"mc":[{"id":"1.168237330","rc":[{"trd":[[1.38,0.34]],"batb":[[0,1.38,19.52]],"batl":[[1,1000,0]],"ltp":1.38,"tv":1653.97,"id":6596286}],"tv":2095.5}]}
{"op":"mcm","clk":"1002892332","pt":1580600186978,"mc":[{"id":"1.168237330","rc":[{"batl":[[0,90,2]],"ltp":3.35,"tv":441.52,"id":8196374}]}]}
{"op":"mcm","clk":"1002892581","pt":1580600190970,"mc":[{"id":"1.168237330","rc":[{"batb":[[0,1.34,180.75],[1,1.05,152.2],[2,1.04,168.86]],"ltp":1.38,"tv":1653.97,"id":6596286},{"batb":[[2,1.4,101.7]],"batl":[[0,90,3]],"ltp":3.35,"tv":441.52,"id":8196374}]}]}
{"op":"mcm","clk":"1002892594","pt":1580600191173,"mc":[{"id":"1.168237330","rc":[{"batb":[[2,2.14,12.5]],"ltp":3.35,"tv":441.52,"id":8196374}]}]}
{"op":"mcm","clk":"1002892906","pt":1580600195891,"mc":[{"id":"1.168237330","rc":[{"batl":[[0,3.55,1],[1,90,2]],"ltp":3.35,"tv":441.52,"id":8196374}]}]}
{"op":"mcm","clk":"1002893217","pt":1580600200547,"mc":[{"id":"1.168237330","rc":[{"batb":[[0,1.38,19.69],[1,1.34,161.06],[2,1.05,152.2]],"ltp":1.38,"tv":1653.97,"id":6596286},{"batl":[[1,90,0]],"ltp":3.35,"tv":441.52,"id":8196374}]}]}
{"op":"mcm","clk":"1002893895","pt":1580600210843,"mc":[{"id":"1.168237330","rc":[{"batb":[[0,1.4,2],[1,1.38,19.69],[2,1.34,161.06]],"ltp":1.38,"tv":1653.97,"id":6596286}]}]}
{"op":"mcm","clk":"1002895053","pt":1580600227477,"mc":[{"id":"1.168237330","rc":[{"trd":[[1.42,346.77]],"batl":[[0,1.42,541.67]],"ltp":1.42,"tv":1656.34,"id":6596286},{"trd":[[3.35,36]],"ltp":3.35,"tv":442.52,"id":8196374}],"tv":2098.86}]}
{"op":"mcm","clk":"1002896755","pt":1580600250466,"mc":[{"id":"1.168237330","rc":[{"batb":[[1,1.34,161.06],[2,1.05,152.2]],"ltp":1.42,"tv":1656.34,"id":6596286},{"batb":[[2,1.4,101.7]],"ltp":3.35,"tv":442.52,"id":8196374}]}]}
{"op":"mcm","clk":"1002896951","pt":1580600253782,"mc":[{"id":"1.168237330","rc":[{"batb":[[0,1.34,161.06],[1,1.05,152.2],[2,1.04,168.86]],"ltp":1.42,"tv":1656.34,"id":6596286}]}]}
{"op":"mcm","clk":"1002897033","pt":1580600254862,"mc":[{"id":"1.168237330","rc":[{"batb":[[0,1.34,180.75]],"ltp":1.42,"tv":1656.34,"id":6596286},{"batb":[[2,2.14,12.5]],"ltp":3.35,"tv":442.52,"id":8196374}]}]}
{"op":"mcm","clk":"1002897663","pt":1580600264401,"mc":[{"id":"1.168237330","rc":[{"batb":[[0,1.38,19.69],[1,1.34,161.06],[2,1.05,152.2]],"ltp":1.42,"tv":1656.34,"id":6596286}]}]}
{"op":"mcm","clk":"1002898829","pt":1580600282794,"mc":[{"id":"1.168237330","rc":[{"batb":[[0,1.39,19.69]],"ltp":1.42,"tv":1656.34,"id":6596286},{"batb":[[2,2.1,12.5]],"ltp":3.35,"tv":442.52,"id":8196374}]}]}
{"op":"mcm","clk":"1002899188","pt":1580600288498,"mc":[{"id":"1.168237330","rc":[{"trd":[[1.42,351.01]],"batl":[[0,1.42,539.55]],"ltp":1.42,"tv":1660.58,"id":6596286}],"tv":2103.1}]}
{"op":"mcm","clk":"1002900596","pt":1580600310812,"mc":[{"id":"1.168237330","rc":[{"batb":[[0,1.34,161.06],[1,1.05,152.2],[2,1.04,168.86]],"ltp":1.42,"tv":1660.58,"id":6596286},{"batb":[[2,1.4,101.7]],"ltp":3.35,"tv":442.52,"id":8196374}]}]}
{"op":"mcm","clk":"1002901005","pt":1580600318946,"mc":[{"id":"1.168237330","rc":[{"batb":[[0,1.34,180.75]],"ltp":1.42,"tv":1660.58,"id":6596286},{"batb":[[2,2.1,12.5]],"ltp":3.35,"tv":442.52,"id":8196374}]}]}
{"op":"mcm","clk":"1002901505","pt":1580600328258,"mc":[{"id":"1.168237330","rc":[{"batb":[[0,1.39,19.69],[1,1.34,161.06],[2,1.05,152.2]],"ltp":1.42,"tv":1660.58,"id":6596286}]}]}
{"op":"mcm","clk":"1002904210","pt":1580600371211,"mc":[{"id":"1.168237330","rc":[{"batb":[[0,1.34,161.06],[1,1.05,152.2],[2,1.04,168.86]],"ltp":1.42,"tv":1660.58,"id":6596286},{"batb":[[2,1.4,101.7]],"ltp":3.35,"tv":442.52,"id":8196374}]}]}
{"op":"mcm","clk":"1002904364","pt":1580600373813,"mc":[{"id":"1.168237330","rc":[{"batb":[[0,1.34,180.75]],"ltp":1.42,"tv":1660.58,"id":6596286}]}]}
{"op":"mcm","clk":"1002904377","pt":1580600374017,"mc":[{"id":"1.168237330","rc":[{"batb":[[2,2.1,12.5]],"ltp":3.35,"tv":442.52,"id":8196374}]}]}
{"op":"mcm","clk":"1002904943","pt":1580600383424,"mc":[{"id":"1.168237330","rc":[{"batb":[[0,1.39,19.69],[1,1.34,161.06],[2,1.05,152.2]],"ltp":1.42,"tv":1660.58,"id":6596286}]}]}
{"op":"mcm","clk":"1002908201","pt":1580600431468,"mc":[{"id":"1.168237330","rc":[{"batb":[[0,1.34,161.06],[1,1.05,152.2],[2,1.04,168.86]],"ltp":1.42,"tv":1660.58,"id":6596286},{"batb":[[2,1.4,101.7]],"ltp":3.35,"tv":442.52,"id":8196374}]}]}
{"op":"mcm","clk":"1002908646","pt":1580600437781,"mc":[{"id":"1.168237330","rc":[{"batb":[[0,1.34,180.75]],"ltp":1.42,"tv":1660.58,"id":6596286}]}]}
{"op":"mcm","clk":"1002908655","pt":1580600437987,"mc":[{"id":"1.168237330","rc":[{"batb":[[2,2.1,12.5]],"ltp":3.35,"tv":442.52,"id":8196374}]}]}
{"op":"mcm","clk":"1002909333","pt":1580600447389,"mc":[{"id":"1.168237330","rc":[{"batb":[[0,1.39,19.69],[1,1.34,161.06],[2,1.05,152.2]],"ltp":1.42,"tv":1660.58,"id":6596286}]}]}
{"op":"mcm","clk":"1002912438","pt":1580600491961,"mc":[{"id":"1.168237330","rc":[{"batb":[[0,1.34,161.06],[1,1.05,152.2],[2,1.04,168.86]],"ltp":1.42,"tv":1660.58,"id":6596286},{"batb":[[2,1.4,101.7]],"ltp":3.35,"tv":442.52,"id":8196374}]}]}
{"op":"mcm","clk":"1002912509","pt":1580600492948,"mc":[{"id":"1.168237330","rc":[{"batb":[[0,1.39,19.69],[1,1.34,161.06],[2,1.05,152.2]],"ltp":1.42,"tv":1660.58,"id":6596286},{"batb":[[2,2.1,12.5]],"ltp":3.35,"tv":442.52,"id":8196374}]}]}
{"op":"mcm","clk":"1002916410","pt":1580600552239,"mc":[{"id":"1.168237330","rc":[{"batb":[[0,1.34,161.06],[1,1.05,152.2],[2,1.04,168.86]],"ltp":1.42,"tv":1660.58,"id":6596286},{"batb":[[2,1.4,101.7]],"ltp":3.35,"tv":442.52,"id":8196374}]}]}
{"op":"mcm","clk":"1002916778","pt":1580600556756,"mc":[{"id":"1.168237330","rc":[{"batb":[[0,1.39,19.69],[1,1.34,161.06],[2,1.05,152.2]],"ltp":1.42,"tv":1660.58,"id":6596286},{"batb":[[2,2.1,12.5]],"ltp":3.35,"tv":442.52,"id":8196374}]}]}
{"op":"mcm","clk":"1002920613","pt":1580600612569,"mc":[{"id":"1.168237330","rc":[{"batb":[[0,1.34,161.06],[1,1.05,152.2],[2,1.04,168.86]],"ltp":1.42,"tv":1660.58,"id":6596286},{"batb":[[2,1.4,101.7]],"ltp":3.35,"tv":442.52,"id":8196374}]}]}
{"op":"mcm","clk":"1002921166","pt":1580600620771,"mc":[{"id":"1.168237330","rc":[{"batb":[[0,1.39,19.69],[1,1.34,161.06],[2,1.05,152.2]],"ltp":1.42,"tv":1660.58,"id":6596286},{"batb":[[2,2.1,12.5]],"ltp":3.35,"tv":442.52,"id":8196374}]}]}
{"op":"mcm","clk":"1002923743","pt":1580600665338,"mc":[{"id":"1.168237330","rc":[{"batb":[[0,1.41,53.76],[1,1.39,19.69],[2,1.34,161.06]],"ltp":1.42,"tv":1660.58,"id":6596286}]}]}
{"op":"mcm","clk":"1002923876","pt":1580600667218,"mc":[{"id":"1.168237330","rc":[{"batb":[[0,1.42,1.77],[1,1.41,53.76],[2,1.39,19.69]],"ltp":1.42,"tv":1660.58,"id":6596286}]}]}
{"op":"mcm","clk":"1002924082","pt":1580600670571,"mc":[{"id":"1.168237330","rc":[{"batl":[[0,1.65,22.72]],"ltp":1.42,"tv":1660.58,"id":6596286}]}]}
{"op":"mcm","clk":"1002924224","pt":1580600672849,"mc":[{"id":"1.168237330","rc":[{"batb":[[2,1.34,161.06]],"ltp":1.42,"tv":1660.58,"id":6596286},{"batb":[[2,1.4,101.7]],"ltp":3.35,"tv":442.52,"id":8196374}]}]}
{"op":"mcm","clk":"1002924341","pt":1580600674918,"mc":[{"id":"1.168237330","rc":[{"batb":[[2,1.39,19.69]],"ltp":1.42,"tv":1660.58,"id":6596286},{"batb":[[2,2.1,12.5]],"ltp":3.35,"tv":442.52,"id":8196374}]}]}
{"op":"mcm","clk":"1002927681","pt":1580600733175,"mc":[{"id":"1.168237330","rc":[{"batb":[[2,1.34,161.06]],"ltp":1.42,"tv":1660.58,"id":6596286},{"batb":[[2,1.4,101.7]],"ltp":3.35,"tv":442.52,"id":8196374}]}]}
{"op":"mcm","clk":"1002928074","pt":1580600739689,"mc":[{"id":"1.168237330","rc":[{"batb":[[2,1.39,19.69]],"ltp":1.42,"tv":1660.58,"id":6596286},{"batb":[[2,2.1,12.5]],"ltp":3.35,"tv":442.52,"id":8196374}]}]}
{"op":"mcm","clk":"1002931553","pt":1580600793494,"mc":[{"id":"1.168237330","rc":[{"batb":[[2,1.34,161.06]],"ltp":1.42,"tv":1660.58,"id":6596286},{"batb":[[2,1.4,101.7]],"ltp":3.35,"tv":442.52,"id":8196374}]}]}
{"op":"mcm","clk":"1002932229","pt":1580600802685,"mc":[{"id":"1.168237330","rc":[{"batb":[[2,1.39,19.69]],"ltp":1.42,"tv":1660.58,"id":6596286}]}]}
{"op":"mcm","clk":"1002932247","pt":1580600802990,"mc":[{"id":"1.168237330","rc":[{"batb":[[2,2.1,12.5]],"ltp":3.35,"tv":442.52,"id":8196374}]}]}
{"op":"mcm","clk":"1002935553","pt":1580600853737,"mc":[{"id":"1.168237330","rc":[{"batb":[[2,1.34,161.06]],"ltp":1.42,"tv":1660.58,"id":6596286},{"batb":[[2,1.4,101.7]],"ltp":3.35,"tv":442.52,"id":8196374}]}]}
{"op":"mcm","clk":"1002935800","pt":1580600856837,"mc":[{"id":"1.168237330","rc":[{"batb":[[2,1.39,19.69]],"ltp":1.42,"tv":1660.58,"id":6596286},{"batb":[[2,2.1,12.5]],"ltp":3.35,"tv":442.52,"id":8196374}]}]}
{"op":"mcm","clk":"1002939613","pt":1580600914108,"mc":[{"id":"1.168237330","rc":[{"batb":[[2,1.34,161.06]],"ltp":1.42,"tv":1660.58,"id":6596286},{"batb":[[2,1.4,101.7]],"ltp":3.35,"tv":442.52,"id":8196374}]}]}
{"op":"mcm","clk":"1002939940","pt":1580600918896,"mc":[{"id":"1.168237330","rc":[{"batb":[[2,1.39,19.69]],"ltp":1.42,"tv":1660.58,"id":6596286},{"batb":[[2,2.1,12.5]],"ltp":3.35,"tv":442.52,"id":8196374}]}]}
{"op":"mcm","clk":"1002943842","pt":1580600974387,"mc":[{"id":"1.168237330","rc":[{"batb":[[2,1.34,161.06]],"ltp":1.42,"tv":1660.58,"id":6596286},{"batb":[[2,1.4,101.7]],"ltp":3.35,"tv":442.52,"id":8196374}]}]}
{"op":"mcm","clk":"1002944182","pt":1580600980257,"mc":[{"id":"1.168237330","rc":[{"batb":[[2,1.39,19.69]],"ltp":1.42,"tv":1660.58,"id":6596286},{"batb":[[2,2.1,12.5]],"ltp":3.35,"tv":442.52,"id":8196374}]}]}
{"op":"mcm","clk":"1002947883","pt":1580601034717,"mc":[{"id":"1.168237330","rc":[{"batb":[[2,1.34,161.06]],"ltp":1.42,"tv":1660.58,"id":6596286},{"batb":[[2,1.4,101.7]],"ltp":3.35,"tv":442.52,"id":8196374}]}]}
{"op":"mcm","clk":"1002948400","pt":1580601042470,"mc":[{"id":"1.168237330","rc":[{"batb":[[2,1.39,19.69]],"ltp":1.42,"tv":1660.58,"id":6596286},{"batb":[[2,2.1,12.5]],"ltp":3.35,"tv":442.52,"id":8196374}]}]}
{"op":"mcm","clk":"1002949298","pt":1580601056191,"mc":[{"id":"1.168237330","rc":[{"trd":[[1.41,1],[1.42,354.56]],"batb":[[0,1.41,53.26],[1,1.39,19.69],[2,1.34,161.06]],"ltp":1.41,"tv":1665.12,"id":6596286}],"tv":2107.64}]}
{"op":"mcm","clk":"1002952140","pt":1580601095063,"mc":[{"id":"1.168237330","rc":[{"batb":[[1,1.34,161.06],[2,1.05,152.2]],"ltp":1.41,"tv":1665.12,"id":6596286},{"batb":[[2,1.4,101.7]],"ltp":3.35,"tv":442.52,"id":8196374}]}]}
{"op":"mcm","clk":"1002962951","pt":1580601248933,"mc":[{"id":"1.168237330","rc":[{"batb":[[1,1.39,19.69],[2,1.34,161.06]],"ltp":1.41,"tv":1665.12,"id":6596286},{"batb":[[2,2.1,12.5]],"ltp":3.35,"tv":442.52,"id":8196374}]}]}
{"op":"mcm","clk":"1002964690","pt":1580601275351,"mc":[{"id":"1.168237330","rc":[{"batb":[[1,1.34,161.06],[2,1.05,152.2]],"ltp":1.41,"tv":1665.12,"id":6596286},{"batb":[[2,1.4,101.7]],"ltp":3.35,"tv":442.52,"id":8196374}]}]}
{"op":"mcm","clk":"1002965334","pt":1580601284675,"mc":[{"id":"1.168237330","rc":[{"batb":[[1,1.39,19.69],[2,1.34,161.06]],"ltp":1.41,"tv":1665.12,"id":6596286},{"batb":[[2,2.1,12.5]],"ltp":3.35,"tv":442.52,"id":8196374}]}]}
{"op":"mcm","clk":"1002966952","pt":1580601308431,"mc":[{"id":"1.168237330","rc":[{"trd":[[1.65,45.42]],"batb":[[0,1.65,4.49],[1,1.41,53.26],[2,1.39,19.69]],"ltp":1.65,"tv":1710.54,"id":6596286}],"tv":2153.06}]}
{"op":"mcm","clk":"1002967149","pt":1580601311414,"mc":[{"id":"1.168237330","rc":[{"batb":[[0,1.41,53.26],[1,1.39,19.69],[2,1.34,161.06]],"ltp":1.65,"tv":1710.54,"id":6596286}]}]}
{"op":"mcm","clk":"1002968745","pt":1580601335649,"mc":[{"id":"1.168237330","rc":[{"batb":[[1,1.34,161.06],[2,1.05,152.2]],"ltp":1.65,"tv":1710.54,"id":6596286},{"batb":[[2,1.4,101.7]],"ltp":3.35,"tv":442.52,"id":8196374}]}]}
{"op":"mcm","clk":"1002969010","pt":1580601338926,"mc":[{"id":"1.168237330","rc":[{"batb":[[1,1.39,19.69],[2,1.34,161.06]],"ltp":1.65,"tv":1710.54,"id":6596286},{"batb":[[2,2.1,12.5]],"ltp":3.35,"tv":442.52,"id":8196374}]}]}
{"op":"mcm","clk":"1002969769","pt":1580601349247,"mc":[{"id":"1.168237330","rc":[{"trd":[[2.5,3.84],[2.52,10.9]],"batb":[[0,2.5,34.58],[1,2.1,12.5],[2,1.4,101.31]],"ltp":2.5,"tv":448.36,"id":8196374}],"tv":2158.91}]}
{"op":"mcm","clk":"1002970078","pt":1580601353539,"mc":[{"id":"1.168237330","rc":[{"batb":[[0,2.5,36.5]],"ltp":2.5,"tv":448.36,"id":8196374}]}]}
{"op":"mcm","clk":"1002971497","pt":1580601373494,"mc":[{"id":"1.168237330","rc":[{"batl":[[0,1.65,37.86]],"ltp":1.65,"tv":1710.54,"id":6596286}]}]}
{"op":"mcm","clk":"1002971943","pt":1580601378795,"mc":[{"id":"1.168237330","rc":[{"batb":[[0,1.49,24.69],[1,1.41,53.26],[2,1.39,19.69]],"ltp":1.65,"tv":1710.54,"id":6596286}]}]}
{"op":"mcm","clk":"1002973136","pt":1580601395714,"mc":[{"id":"1.168237330","rc":[{"batb":[[0,1.5,20],[1,1.49,24.69],[2,1.41,53.26]],"ltp":1.65,"tv":1710.54,"id":6596286}]}]}
{"op":"mcm","clk":"1002973156","pt":1580601396026,"mc":[{"id":"1.168237330","rc":[{"batb":[[1,1.4,101.7],[2,1.05,152.2]],"ltp":2.5,"tv":448.36,"id":8196374}]}]}
{"op":"mcm","clk":"1002973776","pt":1580601405335,"mc":[{"id":"1.168237330","rc":[{"batb":[[1,2.1,12.5],[2,1.4,101.31]],"ltp":2.5,"tv":448.36,"id":8196374}]}]}
{"op":"mcm","clk":"1002977688","pt":1580601456270,"mc":[{"id":"1.168237330","rc":[{"batb":[[1,1.4,101.7],[2,1.05,152.2]],"ltp":2.5,"tv":448.36,"id":8196374}]}]}
{"op":"mcm","clk":"1002977961","pt":1580601460188,"mc":[{"id":"1.168237330","rc":[{"batb":[[1,2.1,12.5],[2,1.4,101.31]],"ltp":2.5,"tv":448.36,"id":8196374}]}]}
{"op":"mcm","clk":"1002982068","pt":1580601516711,"mc":[{"id":"1.168237330","rc":[{"batb":[[1,1.4,101.7],[2,1.05,152.2]],"ltp":2.5,"tv":448.36,"id":8196374}]}]}
{"op":"mcm","clk":"1002982673","pt":1580601524305,"mc":[{"id":"1.168237330","rc":[{"batb":[[1,2.08,13.26],[2,1.4,101.31]],"ltp":2.5,"tv":448.36,"id":8196374}]}]}
{"op":"mcm","clk":"1002984540","pt":1580601550921,"mc":[{"id":"1.168237330","rc":[{"batl":[[1,1000,0.02]],"ltp":1.65,"tv":1710.54,"id":6596286},{"batl":[[0,1000,0.02]],"ltp":2.5,"tv":448.36,"id":8196374}]}]}
{"op":"mcm","clk":"1002986593","pt":1580601576973,"mc":[{"id":"1.168237330","rc":[{"batb":[[1,1.4,101.7],[2,1.05,152.3]],"ltp":2.5,"tv":448.36,"id":8196374}]}]}
{"op":"mcm","clk":"1002986685","pt":1580601578054,"mc":[{"id":"1.168237330","rc":[{"batb":[[1,2.08,13.26],[2,1.4,101.31]],"ltp":2.5,"tv":448.36,"id":8196374}]}]}
{"op":"mcm","clk":"1002987159","pt":1580601584421,"mc":[{"id":"1.168237330","rc":[{"trd":[[1.65,83.28]],"batl":[[0,1000,0.02],[1,1000,0]],"ltp":1.65,"tv":1748.4,"id":6596286},{"trd":[[2.52,35.69]],"batl":[[0,2.52,14.89],[1,1000,0.02]],"ltp":2.52,"tv":473.15,"id":8196374}],"tv":2221.56}]}
{"op":"mcm","clk":"1002989280","pt":1580601614422,"mc":[{"id":"1.168237330","rc":[{"trd":[[1.65,106.02]],"batl":[[0,1.65,15.12],[1,1000,0.02]],"ltp":1.65,"tv":1771.14,"id":6596286},{"trd":[[2.52,50.58]],"batl":[[0,1000,0.02],[1,1000,0]],"ltp":2.52,"tv":488.04,"id":8196374}],"tv":2259.19}]}
{"op":"mcm","clk":"1002989562","pt":1580601618935,"mc":[{"id":"1.168237330","rc":[{"batb":[[1,1.41,53.26],[2,1.4,19.69]],"ltp":1.65,"tv":1771.14,"id":6596286}]}]}
{"op":"mcm","clk":"1002990886","pt":1580601637277,"mc":[{"id":"1.168237330","rc":[{"batb":[[2,1.34,161.06]],"ltp":1.65,"tv":1771.14,"id":6596286},{"batb":[[1,1.4,101.7],[2,1.05,152.4]],"ltp":2.52,"tv":488.04,"id":8196374}]}]}
{"op":"mcm","clk":"1002991110","pt":1580601641085,"mc":[{"id":"1.168237330","rc":[{"batb":[[0,1.5,73.76]],"ltp":1.65,"tv":1771.14,"id":6596286}]}]}
{"op":"mcm","clk":"1002991456","pt":1580601647354,"mc":[{"id":"1.168237330","rc":[{"batb":[[2,1.4,19.69]],"ltp":1.65,"tv":1771.14,"id":6596286},{"batb":[[1,2.08,13.26],[2,1.4,101.31]],"ltp":2.52,"tv":488.04,"id":8196374}]}]}
{"op":"mcm","clk":"1002993980","pt":1580601687554,"mc":[{"id":"1.168237330","rc":[{"batb":[[0,1.51,1.67],[1,1.5,73.76],[2,1.41,53.26]],"ltp":1.65,"tv":1771.14,"id":6596286}]}]}
{"op":"mcm","clk":"1002994622","pt":1580601697941,"mc":[{"id":"1.168237330","rc":[{"batb":[[1,1.4,101.7],[2,1.05,152.4]],"ltp":2.52,"tv":488.04,"id":8196374}]}]}
{"op":"mcm","clk":"1002994955","pt":1580601703077,"mc":[{"id":"1.168237330","rc":[{"batb":[[1,2.08,13.26],[2,1.4,101.31]],"ltp":2.52,"tv":488.04,"id":8196374}]}]}
{"op":"mcm","clk":"1002995677","pt":1580601714277,"mc":[{"id":"1.168237330","rc":[{"batb":[[1,1.5,53.76]],"ltp":1.65,"tv":1771.14,"id":6596286}]}]}
{"op":"mcm","clk":"1002998573","pt":1580601758542,"mc":[{"id":"1.168237330","rc":[{"batb":[[1,1.4,101.7],[2,1.05,152.4]],"ltp":2.52,"tv":488.04,"id":8196374}]}]}
{"op":"mcm","clk":"1002999257","pt":1580601768454,"mc":[{"id":"1.168237330","rc":[{"batb":[[1,2.08,13.26],[2,1.4,101.31]],"ltp":2.52,"tv":488.04,"id":8196374}]}]}
{"op":"mcm","clk":"1003002731","pt":1580601819180,"mc":[{"id":"1.168237330","rc":[{"batb":[[1,1.4,101.7],[2,1.05,152.4]],"ltp":2.52,"tv":488.04,"id":8196374}]}]}
{"op":"mcm","clk":"1003003035","pt":1580601823634,"mc":[{"id":"1.168237330","rc":[{"batb":[[1,2.08,13.26],[2,1.4,101.31]],"ltp":2.52,"tv":488.04,"id":8196374}]}]}
{"op":"mcm","clk":"1003006691","pt":1580601879767,"mc":[{"id":"1.168237330","rc":[{"batb":[[1,1.4,101.7],[2,1.05,152.4]],"ltp":2.52,"tv":488.04,"id":8196374}]}]}
{"op":"mcm","clk":"1003007372","pt":1580601890448,"mc":[{"id":"1.168237330","rc":[{"batb":[[1,2.08,13.26],[2,1.4,101.31]],"ltp":2.52,"tv":488.04,"id":8196374}]}]}
{"op":"mcm","clk":"1003010288","pt":1580601940313,"mc":[{"id":"1.168237330","rc":[{"batb":[[1,1.4,101.7],[2,1.05,152.4]],"ltp":2.52,"tv":488.04,"id":8196374}]}]}
{"op":"mcm","clk":"1003010892","pt":1580601949449,"mc":[{"id":"1.168237330","rc":[{"batb":[[1,2.08,13.26],[2,1.4,101.31]],"ltp":2.52,"tv":488.04,"id":8196374}]}]}
{"op":"mcm","clk":"1003011429","pt":1580601957848,"mc":[{"id":"1.168237330","rc":[{"batb":[[0,2.54,1.98],[1,2.5,36.5],[2,2.08,13.26]],"ltp":2.52,"tv":488.04,"id":8196374}]}]}
{"op":"mcm","clk":"1003015037","pt":1580602000936,"mc":[{"id":"1.168237330","rc":[{"batb":[[2,1.4,101.7]],"ltp":2.52,"tv":488.04,"id":8196374}]}]}
{"op":"mcm","clk":"1003015802","pt":1580602009345,"mc":[{"id":"1.168237330","rc":[{"batb":[[2,2.08,13.26]],"ltp":2.52,"tv":488.04,"id":8196374}]}]}
{"op":"mcm","clk":"1003020745","pt":1580602061256,"mc":[{"id":"1.168237330","rc":[{"batb":[[2,1.4,101.7]],"ltp":2.52,"tv":488.04,"id":8196374}]}]}
{"op":"mcm","clk":"1003021008","pt":1580602063764,"mc":[{"id":"1.168237330","rc":[{"batb":[[2,2.08,13.26]],"ltp":2.52,"tv":488.04,"id":8196374}]}]}
{"op":"mcm","clk":"1003026695","pt":1580602121529,"mc":[{"id":"1.168237330","rc":[{"batb":[[2,1.4,101.7]],"ltp":2.52,"tv":488.04,"id":8196374}]}]}
{"op":"mcm","clk":"1003031633","pt":1580602176541,"mc":[{"id":"1.168237330","rc":[{"batb":[[2,2.08,13.26]],"ltp":2.52,"tv":488.04,"id":8196374}]}]}
{"op":"mcm","clk":"1003032171","pt":1580602181838,"mc":[{"id":"1.168237330","rc":[{"batb":[[2,1.4,101.7]],"ltp":2.52,"tv":488.04,"id":8196374}]}]}
{"op":"mcm","clk":"1003032556","pt":1580602185934,"mc":[{"id":"1.168237330","rc":[{"batb":[[2,2.08,13.26]],"ltp":2.52,"tv":488.04,"id":8196374}]}]}
{"op":"mcm","clk":"1003037642","pt":1580602242129,"mc":[{"id":"1.168237330","rc":[{"batb":[[2,1.4,101.7]],"ltp":2.52,"tv":488.04,"id":8196374}]}]}
{"op":"mcm","clk":"1003038261","pt":1580602248651,"mc":[{"id":"1.168237330","rc":[{"batb":[[2,2.08,13.26]],"ltp":2.52,"tv":488.04,"id":8196374}]}]}
{"op":"mcm","clk":"1003043109","pt":1580602302405,"mc":[{"id":"1.168237330","rc":[{"batb":[[2,1.4,101.7]],"ltp":2.52,"tv":488.04,"id":8196374}]}]}
{"op":"mcm","clk":"1003043877","pt":1580602311053,"mc":[{"id":"1.168237330","rc":[{"batb":[[2,2.08,13.26]],"ltp":2.52,"tv":488.04,"id":8196374}]}]}
{"op":"mcm","clk":"1003048535","pt":1580602362653,"mc":[{"id":"1.168237330","rc":[{"batb":[[2,1.4,101.7]],"ltp":2.52,"tv":488.04,"id":8196374}]}]}
{"op":"mcm","clk":"1003048790","pt":1580602365760,"mc":[{"id":"1.168237330","rc":[{"batb":[[2,2.08,13.26]],"ltp":2.52,"tv":488.04,"id":8196374}]}]}
{"op":"mcm","clk":"1003054161","pt":1580602422857,"mc":[{"id":"1.168237330","rc":[{"batb":[[2,1.4,101.7]],"ltp":2.52,"tv":488.04,"id":8196374}]}]}
{"op":"mcm","clk":"1003054663","pt":1580602428359,"mc":[{"id":"1.168237330","rc":[{"batb":[[2,2.08,13.26]],"ltp":2.52,"tv":488.04,"id":8196374}]}]}
{"op":"mcm","clk":"1003059993","pt":1580602483148,"mc":[{"id":"1.168237330","rc":[{"batb":[[2,1.4,101.7]],"ltp":2.52,"tv":488.04,"id":8196374}]}]}
{"op":"mcm","clk":"1003060680","pt":1580602490657,"mc":[{"id":"1.168237330","rc":[{"batb":[[2,2.08,13.26]],"ltp":2.52,"tv":488.04,"id":8196374}]}]}
{"op":"mcm","clk":"1003061842","pt":1580602503105,"mc":[{"id":"1.168237330","rc":[{"trd":[[1.51,110.9]],"batb":[[0,1.51,1.66]],"ltp":1.51,"tv":1771.16,"id":6596286}],"tv":2259.21}]}
{"op":"mcm","clk":"1003065399","pt":1580602543439,"mc":[{"id":"1.168237330","rc":[{"batb":[[2,1.4,101.7]],"ltp":2.52,"tv":488.04,"id":8196374}]}]}
{"op":"mcm","clk":"1003065485","pt":1580602544358,"mc":[{"id":"1.168237330","rc":[{"batb":[[2,2.08,13.26]],"ltp":2.52,"tv":488.04,"id":8196374}]}]}
{"op":"mcm","clk":"1003070857","pt":1580602603729,"mc":[{"id":"1.168237330","rc":[{"batb":[[2,1.4,101.7]],"ltp":2.52,"tv":488.04,"id":8196374}]}]}
{"op":"mcm","clk":"1003071221","pt":1580602607432,"mc":[{"id":"1.168237330","rc":[{"batb":[[2,2.08,13.26]],"ltp":2.52,"tv":488.04,"id":8196374}]}]}
{"op":"mcm","clk":"1003076413","pt":1580602663954,"mc":[{"id":"1.168237330","rc":[{"batb":[[2,1.4,101.7]],"ltp":2.52,"tv":488.04,"id":8196374}]}]}
{"op":"mcm","clk":"1003077195","pt":1580602672796,"mc":[{"id":"1.168237330","rc":[{"batb":[[2,2.08,13.26]],"ltp":2.52,"tv":488.04,"id":8196374}]}]}
{"op":"mcm","clk":"1003081337","pt":1580602724189,"mc":[{"id":"1.168237330","rc":[{"batb":[[2,1.4,101.7]],"ltp":2.52,"tv":488.04,"id":8196374}]}]}
{"op":"mcm","clk":"1003081723","pt":1580602729217,"mc":[{"id":"1.168237330","rc":[{"batb":[[2,2.08,13.26]],"ltp":2.52,"tv":488.04,"id":8196374}]}]}
{"op":"mcm","clk":"1003085949","pt":1580602784476,"mc":[{"id":"1.168237330","rc":[{"batb":[[2,1.4,101.7]],"ltp":2.52,"tv":488.04,"id":8196374}]}]}
{"op":"mcm","clk":"1003086052","pt":1580602785817,"mc":[{"id":"1.168237330","rc":[{"batb":[[2,2.08,13.26]],"ltp":2.52,"tv":488.04,"id":8196374}]}]}
{"op":"mcm","clk":"1003090164","pt":1580602844777,"mc":[{"id":"1.168237330","rc":[{"batb":[[2,1.4,101.7]],"ltp":2.52,"tv":488.04,"id":8196374}]}]}
{"op":"mcm","clk":"1003108342","pt":1580603101972,"mc":[{"id":"1.168237330","rc":[{"trd":[[1.65,121.14]],"batl":[[0,1000,0.02],[1,1000,0]],"ltp":1.65,"tv":1786.28,"id":6596286},{"trd":[[2.5,81.44],[2.52,60.47],[2.54,3.96]],"batb":[[0,1.4,101.7],[1,1.05,152.4],[2,1.04,169.36]],"ltp":2.5,"tv":579.49,"id":8196374}],"tv":2365.78}]}
{"op":"mcm","clk":"1003108423","pt":1580603102855,"mc":[{"id":"1.168237330","rc":[{"batb":[[0,2.34,41.25],[1,1.4,101.31],[2,1.05,152.4]],"ltp":2.5,"tv":579.49,"id":8196374}]}]}
{"op":"mcm","clk":"1003112168","pt":1580603151052,"mc":[{"id":"1.168237330","rc":[{"batl":[[0,1.72,45.43],[1,1000,0.02]],"ltp":1.65,"tv":1786.28,"id":6596286}]}]}
{"op":"mcm","clk":"1003112685","pt":1580603157728,"mc":[{"id":"1.168237330","rc":[{"trd":[[1.72,4]],"batl":[[0,1.72,43.43]],"ltp":1.72,"tv":1790.28,"id":6596286}],"tv":2369.78}]}
{"op":"mcm","clk":"1003118247","pt":1580603233271,"mc":[{"id":"1.168237330","rc":[{"trd":[[1.72,47.43]],"batl":[[0,1000,0.02],[1,1000,0]],"ltp":1.72,"tv":1833.72,"id":6596286},{"trd":[[2.38,69.58],[2.4,0.39]],"batb":[[0,2.34,41.05]],"ltp":2.38,"tv":649.46,"id":8196374}],"tv":2483.18}]}
{"op":"mcm","clk":"1003119445","pt":1580603248154,"mc":[{"id":"1.168237330","rc":[{"trd":[[2.34,82.06]],"batb":[[0,1.4,101.31],[1,1.05,152.4],[2,1.04,169.36]],"batl":[[0,2.34,9.64],[1,1000,0.02]],"ltp":2.34,"tv":731.52,"id":8196374}],"tv":2565.24}]}
{"op":"mcm","clk":"1003119783","pt":1580603253163,"mc":[{"id":"1.168237330","rc":[{"batb":[[0,2.18,46.4],[1,1.4,101.31],[2,1.05,152.4]],"ltp":2.34,"tv":731.52,"id":8196374}]}]}
{"op":"mcm","clk":"1003122646","pt":1580603284722,"mc":[{"id":"1.168237330","rc":[{"batl":[[0,1000,0.02],[1,1000,0]],"ltp":2.34,"tv":731.52,"id":8196374}]}]}
{"op":"mcm","clk":"1003133112","pt":1580603406887,"mc":[{"id":"1.168237330","rc":[{"trd":[[2.18,92.75]],"batb":[[0,1.4,101.31],[1,1.05,152.4],[2,1.04,169.36]],"batl":[[0,2.18,4.3],[1,1000,0.02]],"ltp":2.18,"tv":824.27,"id":8196374}],"tv":2657.99}]}
{"op":"mcm","clk":"1003133259","pt":1580603408594,"mc":[{"id":"1.168237330","rc":[{"batb":[[0,2.02,53.68],[1,1.4,101.31],[2,1.05,152.4]],"ltp":2.18,"tv":824.27,"id":8196374}]}]}
{"op":"mcm","clk":"1003134005","pt":1580603418034,"mc":[{"id":"1.168237330","rc":[{"batl":[[0,1000,0.02],[1,1000,0]],"ltp":2.18,"tv":824.27,"id":8196374}]}]}
{"op":"mcm","clk":"1003134625","pt":1580603425485,"mc":[{"id":"1.168237330","rc":[{"trd":[[2.02,101.35]],"batb":[[0,2.02,2.98]],"ltp":2.02,"tv":925.62,"id":8196374}],"tv":2759.34}]}
{"op":"mcm","clk":"1003134841","pt":1580603428731,"mc":[{"id":"1.168237330","rc":[{"batb":[[0,1.4,101.31],[1,1.05,152.4],[2,1.04,169.36]],"ltp":2.02,"tv":925.62,"id":8196374}]}]}
{"op":"mcm","clk":"1003144644","pt":1580603541818,"mc":[{"id":"1.168237330","rc":[{"batl":[[0,2,53.76],[1,1000,0.02]],"ltp":1.72,"tv":1833.72,"id":6596286}]}]}
{"op":"mcm","clk":"1003145286","pt":1580603549540,"mc":[{"id":"1.168237330","rc":[{"batl":[[0,1.98,53.76]],"ltp":1.72,"tv":1833.72,"id":6596286}]}]}
{"op":"mcm","clk":"1003146407","pt":1580603563970,"mc":[{"id":"1.168237330","rc":[{"batl":[[1,2.06,53.76],[2,1000,0.02]],"ltp":1.72,"tv":1833.72,"id":6596286}]}]}
{"op":"mcm","clk":"1003146582","pt":1580603566253,"mc":[{"id":"1.168237330","rc":[{"batl":[[0,1.6,1000],[1,1.98,53.76],[2,2.06,53.76]],"ltp":1.72,"tv":1833.72,"id":6596286}]}]}
{"op":"mcm","clk":"1003146748","pt":1580603568282,"mc":[{"id":"1.168237330","rc":[{"trd":[[1.6,95.62]],"batl":[[0,1.6,915.71]],"ltp":1.6,"tv":1918.01,"id":6596286},{"trd":[[2.66,52.02]],"ltp":2.66,"tv":976.27,"id":8196374}],"tv":2894.28}]}
{"op":"mcm","clk":"1003146927","pt":1580603570306,"mc":[{"id":"1.168237330","rc":[{"trd":[[1.51,111.9]],"batb":[[0,1.51,1.16]],"batl":[[1,1.8,226.3],[2,1.98,53.76]],"ltp":1.51,"tv":1919.01,"id":6596286}],"tv":2895.29}]}
{"op":"mcm","clk":"1003147087","pt":1580603572181,"mc":[{"id":"1.168237330","rc":[{"batl":[[0,1.59,8.4],[1,1.6,915.71],[2,1.8,226.3]],"ltp":1.51,"tv":1919.01,"id":6596286}]}]}
{"op":"mcm","clk":"1003147876","pt":1580603581796,"mc":[{"id":"1.168237330","rc":[{"trd":[[1.59,53.9],[1.6,378.64]],"batl":[[0,1.6,774.2],[1,1.8,226.3],[2,1.98,53.76]],"ltp":1.6,"tv":2218.84,"id":6596286}],"tv":3195.11}]}
{"op":"mcm","clk":"1003148535","pt":1580603589340,"mc":[{"id":"1.168237330","rc":[{"trd":[[1.6,436.23]],"batl":[[0,1.6,716.61]],"ltp":1.6,"tv":2276.43,"id":6596286},{"trd":[[2.66,86.62]],"ltp":2.66,"tv":1010.87,"id":8196374}],"tv":3287.31}]}
{"op":"mcm","clk":"1003148603","pt":1580603590218,"mc":[{"id":"1.168237330","rc":[{"batb":[[1,1.41,53.26],[2,1.34,161.06]],"ltp":1.6,"tv":2276.43,"id":6596286}]}]}
{"op":"mcm","clk":"1003148923","pt":1580603593902,"mc":[{"id":"1.168237330","rc":[{"batl":[[1,1.72,53.76],[2,1.8,226.3]],"ltp":1.6,"tv":2276.43,"id":6596286}]}]}
{"op":"mcm","clk":"1003156548","pt":1580603681140,"mc":[{"id":"1.168237330","rc":[{"batl":[[2,1.98,53.76]],"ltp":1.6,"tv":2276.43,"id":6596286}]}]}
{"op":"mcm","clk":"1003156879","pt":1580603685029,"mc":[{"id":"1.168237330","rc":[{"batl":[[0,3.25,226.3],[1,1000,0.02]],"ltp":2.66,"tv":1010.87,"id":8196374}]}]}
{"op":"mcm","clk":"1003162846","pt":1580603756103,"mc":[{"id":"1.168237330","rc":[{"batb":[[0,1.4,102.25]],"ltp":2.66,"tv":1010.87,"id":8196374}]}]}
{"op":"mcm","clk":"1003203917","pt":1580604393345,"mc":[{"id":"1.168237330","rc":[{"batb":[[1,1.45,53.76],[2,1.41,53.26]],"ltp":1.6,"tv":2276.43,"id":6596286}]}]}
{"op":"mcm","clk":"1003204643","pt":1580604406985,"mc":[{"id":"1.168237330","rc":[{"batl":[[1,1.98,53.76],[2,1000,0.02]],"ltp":1.6,"tv":2276.43,"id":6596286}]}]}
{"op":"mcm","clk":"1003204805","pt":1580604409603,"mc":[{"id":"1.168237330","rc":[{"batl":[[0,1.98,53.76],[1,1000,0.02],[2,1000,0]],"ltp":1.6,"tv":2276.43,"id":6596286}]}]}
{"op":"mcm","clk":"1003204863","pt":1580604410792,"mc":[{"id":"1.168237330","rc":[{"batl":[[0,1.72,22.72],[1,1.98,53.76],[2,1000,0.02]],"ltp":1.6,"tv":2276.43,"id":6596286}]}]}
{"op":"mcm","clk":"1003204989","pt":1580604412996,"mc":[{"id":"1.168237330","rc":[{"batl":[[0,1.98,53.76],[1,1000,0.02],[2,1000,0]],"ltp":1.6,"tv":2276.43,"id":6596286}]}]}
{"op":"mcm","clk":"1003207874","pt":1580604466376,"mc":[{"id":"1.168237330","rc":[{"batl":[[0,3.25,67.55]],"ltp":2.66,"tv":1010.87,"id":8196374}]}]}
{"op":"mcm","clk":"1003240282","pt":1580604993018,"mc":[{"id":"1.168237330","rc":[{"trd":[[1.98,0.76]],"batl":[[0,1.98,53.01]],"ltp":1.98,"tv":2277.19,"id":6596286},{"trd":[[2.02,102.09],[2.68,23.88]],"batb":[[0,1.4,101.31]],"ltp":2.02,"tv":1013.49,"id":8196374}],"tv":3290.69}]}
{"op":"mcm","clk":"1003281337","pt":1580605618069,"mc":[{"id":"1.168237330","rc":[{"batb":[[0,2.04,1.24],[1,1.4,101.31],[2,1.05,152.4]],"ltp":2.02,"tv":1013.49,"id":8196374}]}]}
{"op":"mcm","clk":"1003456986","pt":1580607992085,"mc":[{"id":"1.168237330","rc":[{"trd":[[1.44,131.6],[1.45,985.48],[1.51,114.22]],"batb":[[0,1.41,53.26],[1,1.13,11.92],[2,1.05,152.3]],"ltp":1.44,"tv":2518.63,"id":6596286},{"trd":[[3.25,58.31]],"batl":[[0,3.25,9.24]],"ltp":3.25,"tv":1071.81,"id":8196374}],"tv":3590.45}]}
{"op":"mcm","clk":"1003458695","pt":1580608016889,"mc":[{"id":"1.168237330","rc":[{"batb":[[0,1.45,22.72],[1,1.41,53.26],[2,1.13,11.92]],"ltp":1.44,"tv":2518.63,"id":6596286}]}]}
{"op":"mcm","clk":"1003459192","pt":1580608023027,"mc":[{"id":"1.168237330","rc":[{"batb":[[0,1.45,83.3]],"ltp":1.44,"tv":2518.63,"id":6596286}]}]}
{"op":"mcm","clk":"1003459460","pt":1580608026595,"mc":[{"id":"1.168237330","rc":[{"batl":[[0,1.72,44.4],[1,1.98,53.01],[2,1000,0.02]],"ltp":1.44,"tv":2518.63,"id":6596286}]}]}
{"op":"mcm","clk":"1003465352","pt":1580608107627,"mc":[{"id":"1.168237330","rc":[{"batb":[[0,2.4,1.05]],"ltp":3.25,"tv":1071.81,"id":8196374}]}]}
{"op":"mcm","clk":"1003477700","pt":1580608281958,"mc":[{"id":"1.168237330","rc":[{"batl":[[1,1000,0.02],[2,1000,0]],"ltp":1.44,"tv":2518.63,"id":6596286}]}]}
{"op":"mcm","clk":"1003477858","pt":1580608284074,"mc":[{"id":"1.168237330","rc":[{"batl":[[1,1.98,22.72],[2,1000,0.02]],"ltp":1.44,"tv":2518.63,"id":6596286}]}]}
{"op":"mcm","clk":"1003480051","pt":1580608320463,"mc":[{"id":"1.168237330","rc":[{"trd":[[1.45,1172]],"batb":[[0,1.41,53.26],[1,1.13,11.92],[2,1.05,152.3]],"ltp":1.45,"tv":2705.15,"id":6596286}],"tv":3776.96}]}
{"op":"mcm","clk":"1003495419","pt":1580608544620,"mc":[{"id":"1.168237330","rc":[{"batl":[[0,1.55,60.58],[1,1.72,44.4],[2,1.98,22.72]],"ltp":1.45,"tv":2705.15,"id":6596286}]}]}
{"op":"mcm","clk":"1003500229","pt":1580608619869,"mc":[{"id":"1.168237330","rc":[{"batb":[[0,1.45,1.74],[1,1.41,53.26],[2,1.13,11.92]],"ltp":1.45,"tv":2705.15,"id":6596286},{"batb":[[0,1.4,102.2],[1,1.05,152.4],[2,1.04,169.36]],"ltp":3.25,"tv":1071.81,"id":8196374}]}]}
{"op":"mcm","clk":"1003635225","pt":1580610516649,"mc":[{"id":"1.168237330","rc":[{"batb":[[0,1.45,178.54]],"ltp":1.45,"tv":2705.15,"id":6596286}]}]}
{"op":"mcm","clk":"1003654276","pt":1580610767740,"mc":[{"id":"1.168237330","rc":[{"trd":[[1.55,25.46]],"batl":[[0,1.55,37.79]],"ltp":1.55,"tv":2727.94,"id":6596286},{"trd":[[2.8,13.87],[2.82,1.78]],"batb":[[0,1.4,101.31]],"ltp":2.8,"tv":1086.2,"id":8196374}],"tv":3814.15}]}
{"op":"mcm","clk":"1003657890","pt":1580610822459,"mc":[{"id":"1.168237330","rc":[{"batl":[[0,1.55,75.65]],"ltp":1.55,"tv":2727.94,"id":6596286}]}]}
{"op":"mcm","clk":"1003671331","pt":1580611019937,"mc":[{"id":"1.168237330","rc":[{"batb":[[0,1.45,1.74]],"ltp":1.55,"tv":2727.94,"id":6596286}]}]}
{"op":"mcm","clk":"1003695232","pt":1580611383616,"mc":[{"id":"1.168237330","rc":[{"batb":[[0,1.4,102.2]],"ltp":2.8,"tv":1086.2,"id":8196374}]}]}
{"op":"mcm","clk":"1003710147","pt":1580611642769,"mc":[{"id":"1.168237330","rc":[{"trd":[[1.55,178.11]],"batl":[[0,1.72,44.4],[1,1.98,22.72],[2,1000,0.02]],"ltp":1.55,"tv":2880.59,"id":6596286},{"trd":[[2.82,2.52]],"batb":[[0,1.4,101.46]],"ltp":2.82,"tv":1086.94,"id":8196374}],"tv":3967.54}]}
{"op":"mcm","clk":"1003710558","pt":1580611649747,"mc":[{"id":"1.168237330","rc":[{"trd":[[1.72,91.5]],"batl":[[0,1.98,23.05],[1,1000,0.02],[2,1000,0]],"ltp":1.72,"tv":2924.66,"id":6596286},{"trd":[[2.38,101.43],[2.82,2.82]],"batb":[[0,1.4,101.31]],"ltp":2.38,"tv":1119.1,"id":8196374}],"tv":4043.76}]}
{"op":"mcm","clk":"1003718008","pt":1580611792410,"mc":[{"id":"1.168237330","rc":[{"batb":[[0,1.48,162],[1,1.45,1.74],[2,1.41,53.26]],"ltp":1.72,"tv":2924.66,"id":6596286}]}]}
{"op":"mcm","clk":"1003718333","pt":1580611798776,"mc":[{"id":"1.168237330","rc":[{"batb":[[0,1.49,1.69],[1,1.48,162]],"ltp":1.72,"tv":2924.66,"id":6596286}]}]}
{"op":"mcm","clk":"1003728745","pt":1580611989088,"mc":[{"id":"1.168237330","rc":[{"batl":[[0,1000,0.02],[1,1000,0]],"ltp":2.38,"tv":1119.1,"id":8196374}]}]}
{"op":"mcm","clk":"1003729786","pt":1580612005038,"mc":[{"id":"1.168237330","rc":[{"batb":[[0,2.3,82.41],[1,1.4,101.31],[2,1.05,152.4]],"ltp":2.38,"tv":1119.1,"id":8196374}]}]}
{"op":"mcm","clk":"1003732396","pt":1580612047895,"mc":[{"id":"1.168237330","rc":[{"trd":[[1.72,91.84],[1.98,23.47]],"batb":[[1,1.41,53.26],[2,1.13,11.92]],"batl":[[0,1000,0.02],[1,1000,0]],"ltp":1.98,"tv":2947.71,"id":6596286},{"trd":[[1.4,32.79],[1.48,0.02],[2.02,124.36],[2.3,164.82],[2.38,101.67]],"batb":[[0,1.4,84.92],[1,1.05,152.4],[2,1.04,169.36]],"ltp":1.4,"tv":1339.23,"id":8196374}],"tv":4286.95}]}
{"op":"mcm","clk":"1003736894","pt":1580612118359,"mc":[{"id":"1.168237330","rc":[{"trd":[[1.4,38]],"batb":[[0,1.4,82.31],[1,1.38,2.63],[2,1.05,152.4]],"ltp":1.4,"tv":1344.45,"id":8196374}],"tv":4292.17}]}
{"op":"mcm","clk":"1003737059","pt":1580612120984,"mc":[{"id":"1.168237330","rc":[{"batb":[[1,1.45,176.8],[2,1.41,53.26]],"ltp":1.98,"tv":2947.71,"id":6596286}]}]}
{"op":"mcm","clk":"1003740763","pt":1580612174002,"mc":[{"id":"1.168237330","rc":[{"batb":[[0,2.2,135.1],[1,1.4,82.31],[2,1.38,2.63]],"ltp":1.4,"tv":1344.45,"id":8196374}]}]}
{"op":"mcm","clk":"1003744620","pt":1580612232381,"mc":[{"id":"1.168237330","rc":[{"batb":[[1,1.41,53.26],[2,1.13,11.92]],"ltp":1.98,"tv":2947.71,"id":6596286}]}]}
{"op":"mcm","clk":"1003750566","pt":1580612338062,"mc":[{"id":"1.168237330","rc":[{"batl":[[0,1.8,53.76],[1,1000,0.02]],"ltp":1.98,"tv":2947.71,"id":6596286}]}]}
{"op":"mcm","clk":"1003750784","pt":1580612341146,"mc":[{"id":"1.168237330","rc":[{"batb":[[0,1.5,51.19],[1,1.49,1.69],[2,1.41,53.26]],"ltp":1.98,"tv":2947.71,"id":6596286}]}]}
{"op":"mcm","clk":"1003752747","pt":1580612369963,"mc":[{"id":"1.168237330","rc":[{"batb":[[1,1.41,53.26],[2,1.13,11.92]],"ltp":1.98,"tv":2947.71,"id":6596286}]}]}
{"op":"mcm","clk":"1003752768","pt":1580612370169,"mc":[{"id":"1.168237330","rc":[{"batb":[[0,1.51,1.67],[1,1.5,51.19],[2,1.41,53.26]],"ltp":1.98,"tv":2947.71,"id":6596286},{"batb":[[0,2.26,1.12],[1,2.2,135.1],[2,1.4,82.31]],"ltp":1.4,"tv":1344.45,"id":8196374}]}]}
{"op":"mcm","clk":"1003770546","pt":1580612645783,"mc":[{"id":"1.168237330","rc":[{"trd":[[1.5,262.97],[1.51,117.57]],"batb":[[0,1.41,53.26],[1,1.13,11.92],[2,1.05,152.3]],"batl":[[0,1.5,251.1],[1,1.8,53.76],[2,1000,0.02]],"ltp":1.5,"tv":3053.38,"id":6596286}],"tv":4397.84}]}
{"op":"mcm","clk":"1003773682","pt":1580612699206,"mc":[{"id":"1.168237330","rc":[{"batl":[[0,1.8,53.76],[1,1000,0.02],[2,1000,0]],"ltp":1.5,"tv":3053.38,"id":6596286}]}]}
{"op":"mcm","clk":"1003776824","pt":1580612756148,"mc":[{"id":"1.168237330","rc":[{"batb":[[0,2.3,135.1],[1,2.26,1.12]],"ltp":1.4,"tv":1344.45,"id":8196374}]}]}
{"op":"mcm","clk":"1003777097","pt":1580612760789,"mc":[{"id":"1.168237330","rc":[{"batb":[[1,1.4,82.31],[2,1.38,2.63]],"ltp":1.4,"tv":1344.45,"id":8196374}]}]}
{"op":"mcm","clk":"1003777118","pt":1580612761102,"mc":[{"id":"1.168237330","rc":[{"batb":[[0,2.32,1.08],[1,2.3,135.1],[2,1.4,82.31]],"ltp":1.4,"tv":1344.45,"id":8196374}]}]}
{"op":"mcm","clk":"1003786916","pt":1580612964265,"mc":[{"id":"1.168237330","rc":[{"batl":[[0,3.25,101.33],[1,1000,0.02]],"ltp":1.4,"tv":1344.45,"id":8196374}]}]}
{"op":"mcm","clk":"1003795878","pt":1580613203217,"mc":[{"id":"1.168237330","rc":[{"batl":[[0,1.73,37.86],[1,1.8,53.76],[2,1000,0.02]],"ltp":1.5,"tv":3053.38,"id":6596286}]}]}
{"op":"mcm","clk":"1003795951","pt":1580613204874,"mc":[{"id":"1.168237330","rc":[{"batb":[[0,1.45,37.86],[1,1.41,53.26],[2,1.13,11.92]],"ltp":1.5,"tv":3053.38,"id":6596286}]}]}
{"op":"mcm","clk":"1003796101","pt":1580613209387,"mc":[{"id":"1.168237330","rc":[{"batb":[[0,2.38,1.06]],"ltp":1.4,"tv":1344.45,"id":8196374}]}]}
{"op":"mcm","clk":"1003796423","pt":1580613217408,"mc":[{"id":"1.168237330","marketDefinition":{"bspMarket":false,"turnInPlayEnabled":true,"persistenceEnabled":true,"marketBaseRate":5.0,"eventId":"29681784","eventTypeId":"2","numberOfWinners":1,"bettingType":"ODDS","marketType":"MATCH_ODDS","marketTime":"2020-02-01T23:00:00.000Z","suspendTime":"2020-02-01T23:00:00.000Z","bspReconciled":false,"complete":true,"inPlay":true,"crossMatching":true,"runnersVoidable":false,"numberOfActiveRunners":2,"betDelay":5,"status":"OPEN","runners":[{"status":"ACTIVE","sortPriority":1,"id":6596286,"name":"Sachia Vickery"},{"status":"ACTIVE","sortPriority":2,"id":8196374,"name":"Maddison Inglis"}],"regulators":["MR_INT"],"countryCode":"GB","discountAllowed":true,"timezone":"GMT","openDate":"2020-02-01T23:00:00.000Z","version":3148100173,"name":"Match Odds","eventName":"S Vickery v M Inglis"},"rc":[{"batb":[[0,1.05,152.4],[1,1.04,169.36],[2,1.03,237.77]],"batl":[[0,1000,0.02],[1,1.8,0],[2,1000,0]],"ltp":1.5,"tv":3053.38,"id":6596286},{"batb":[[0,1.38,2.63],[1,1.05,152.4],[2,1.04,169.36]],"batl":[[0,1000,0.02],[1,1000,0]],"ltp":1.4,"tv":1344.45,"id":8196374}]}]}
{"op":"mcm","clk":"1003797207","pt":1580613238497,"mc":[{"id":"1.168237330","rc":[{"batl":[[0,1.72,37.86],[1,1000,0.02]],"ltp":1.5,"tv":3053.38,"id":6596286}]}]}
{"op":"mcm","clk":"1003797318","pt":1580613241807,"mc":[{"id":"1.168237330","rc":[{"batb":[[0,1.31,37.86],[1,1.05,152.4],[2,1.04,169.36]],"ltp":1.5,"tv":3053.38,"id":6596286}]}]}
{"op":"mcm","clk":"1003797415","pt":1580613244547,"mc":[{"id":"1.168237330","rc":[{"batl":[[1,1.97,37.86],[2,1000,0.02]],"ltp":1.5,"tv":3053.38,"id":6596286}]}]}
{"op":"mcm","clk":"1003797829","pt":1580613255949,"mc":[{"id":"1.168237330","rc":[{"batb":[[1,1.03,48.41],[2,1.02,54.52]],"ltp":1.5,"tv":3053.38,"id":6596286},{"batb":[[1,1.03,48.41],[2,1.02,54.52]],"ltp":1.4,"tv":1344.45,"id":8196374}]}]}
{"op":"mcm","clk":"1003797901","pt":1580613257859,"mc":[{"id":"1.168237330","rc":[{"batb":[[1,1.01,13.21],[2,1.02,0]],"ltp":1.5,"tv":3053.38,"id":6596286},{"batb":[[1,1.01,13.21],[2,1.02,0]],"ltp":1.4,"tv":1344.45,"id":8196374}]}]}
{"op":"mcm","clk":"1003798572","pt":1580613275355,"mc":[{"id":"1.168237330","rc":[{"batb":[[1,1.2,60.68],[2,1.01,13.11]],"ltp":1.5,"tv":3053.38,"id":6596286}]}]}
{"op":"mcm","clk":"1003814460","pt":1580613696372,"mc":[{"id":"1.168237330","rc":[{"batb":[[0,1.4,176.8],[1,1.31,37.86],[2,1.2,60.68]],"ltp":1.5,"tv":3053.38,"id":6596286}]}]}
{"op":"mcm","clk":"1003816715","pt":1580613755345,"mc":[{"id":"1.168237330","rc":[{"batb":[[0,1.31,37.86],[1,1.2,60.68],[2,1.01,13.11]],"ltp":1.5,"tv":3053.38,"id":6596286}]}]}
{"op":"mcm","clk":"1003816945","pt":1580613760857,"mc":[{"id":"1.168237330","rc":[{"batb":[[0,1.44,176.8],[1,1.31,37.86],[2,1.2,60.68]],"ltp":1.5,"tv":3053.38,"id":6596286}]}]}
{"op":"mcm","clk":"1003817590","pt":1580613775683,"mc":[{"id":"1.168237330","rc":[{"batb":[[0,1.31,37.86],[1,1.2,60.68],[2,1.01,13.11]],"ltp":1.5,"tv":3053.38,"id":6596286}]}]}
{"op":"mcm","clk":"1003882338","pt":1580615134119,"mc":[{"id":"1.168237330","rc":[{"batl":[[0,2.5,8],[1,1000,0.02]],"ltp":1.4,"tv":1344.45,"id":8196374}]}]}
{"op":"mcm","clk":"1003882688","pt":1580615145517,"mc":[{"id":"1.168237330","rc":[{"trd":[[1.66,9.09]],"ltp":1.66,"tv":3062.47,"id":6596286},{"trd":[[2.5,87.47]],"batl":[[0,2.5,1.97]],"ltp":2.5,"tv":1350.48,"id":8196374}],"tv":4412.96}]}
{"op":"mcm","clk":"1003882850","pt":1580615150722,"mc":[{"id":"1.168237330","rc":[{"trd":[[1.66,12.06]],"batl":[[0,1.66,34.89],[1,1.72,37.86],[2,1.97,37.86]],"ltp":1.66,"tv":3065.44,"id":6596286},{"trd":[[2.5,89.44]],"batl":[[0,1000,0.02],[1,1000,0]],"ltp":2.5,"tv":1352.45,"id":8196374}],"tv":4417.89}]}
{"op":"mcm","clk":"1003882899","pt":1580615151911,"mc":[{"id":"1.168237330","rc":[{"batl":[[0,1.72,37.86],[1,1.97,37.86],[2,1000,0.02]],"ltp":1.66,"tv":3065.44,"id":6596286}]}]}
{"op":"mcm","clk":"1003883036","pt":1580615156924,"mc":[{"id":"1.168237330","rc":[{"batb":[[1,1.01,14.89]],"ltp":2.5,"tv":1352.45,"id":8196374}]}]}
{"op":"mcm","clk":"1003883063","pt":1580615157749,"mc":[{"id":"1.168237330","rc":[{"batb":[[1,1.01,13.21]],"ltp":2.5,"tv":1352.45,"id":8196374}]}]}
{"op":"mcm","clk":"1003883109","pt":1580615159450,"mc":[{"id":"1.168237330","rc":[{"batb":[[0,1.5,13.34],[1,1.31,37.86],[2,1.2,60.68]],"ltp":1.66,"tv":3065.44,"id":6596286}]}]}
{"op":"mcm","clk":"1003883240","pt":1580615162867,"mc":[{"id":"1.168237330","rc":[{"trd":[[1.5,263.19]],"batb":[[0,1.5,13.12]],"ltp":1.5,"tv":3065.66,"id":6596286},{"trd":[[3,0.11]],"ltp":3.0,"tv":1352.56,"id":8196374}],"tv":4418.22}]}
{"op":"mcm","clk":"1003883712","pt":1580615176841,"mc":[{"id":"1.168237330","rc":[{"batl":[[0,1.97,37.86],[1,1000,0.02],[2,1000,0]],"ltp":1.5,"tv":3065.66,"id":6596286}]}]}
{"op":"mcm","clk":"1003886462","pt":1580615264242,"mc":[{"id":"1.168237330","marketDefinition":{"bspMarket":false,"turnInPlayEnabled":true,"persistenceEnabled":true,"marketBaseRate":5.0,"eventId":"29681784","eventTypeId":"2","numberOfWinners":1,"bettingType":"ODDS","marketType":"MATCH_ODDS","marketTime":"2020-02-02T03:47:43.000Z","suspendTime":"2020-02-02T03:47:43.000Z","bspReconciled":false,"complete":true,"inPlay":true,"crossMatching":true,"runnersVoidable":false,"numberOfActiveRunners":2,"betDelay":5,"status":"OPEN","runners":[{"status":"ACTIVE","sortPriority":1,"id":6596286,"name":"Sachia Vickery"},{"status":"ACTIVE","sortPriority":2,"id":8196374,"name":"Maddison Inglis"}],"regulators":["MR_INT"],"countryCode":"GB","discountAllowed":true,"timezone":"GMT","openDate":"2020-02-01T23:00:00.000Z","version":3148132720,"name":"Match Odds","eventName":"S Vickery v M Inglis"}}]}
{"op":"mcm","clk":"1003887270","pt":1580615289294,"mc":[{"id":"1.168237330","marketDefinition":{"bspMarket":false,"turnInPlayEnabled":true,"persistenceEnabled":true,"marketBaseRate":5.0,"eventId":"29681784","eventTypeId":"2","numberOfWinners":1,"bettingType":"ODDS","marketType":"MATCH_ODDS","marketTime":"2020-02-02T03:47:43.000Z","suspendTime":"2020-02-02T03:47:43.000Z","bspReconciled":false,"complete":true,"inPlay":true,"crossMatching":true,"runnersVoidable":false,"numberOfActiveRunners":2,"betDelay":5,"status":"OPEN","runners":[{"status":"ACTIVE","sortPriority":1,"id":6596286,"name":"Sachia Vickery"},{"status":"ACTIVE","sortPriority":2,"id":8196374,"name":"Maddison Inglis"}],"regulators":["MR_INT"],"countryCode":"GB","discountAllowed":true,"timezone":"GMT","openDate":"2020-02-02T03:47:43.000Z","version":3148132720,"name":"Match Odds","eventName":"S Vickery v M Inglis"}}]}
{"op":"mcm","clk":"1003887324","pt":1580615290660,"mc":[{"id":"1.168237330","rc":[{"batb":[[0,1.59,1158.92],[1,1.58,767.38],[2,1.5,13.12]],"batl":[[0,1.82,1025.91],[1,1.84,911.61],[2,1.97,37.86]],"ltp":1.5,"tv":3065.66,"id":6596286}]}]}
{"op":"mcm","clk":"1003888218","pt":1580615321221,"mc":[{"id":"1.168237330","rc":[{"batb":[[0,1.6,12.31],[1,1.59,1158.92],[2,1.58,767.38]],"ltp":1.5,"tv":3065.66,"id":6596286}]}]}
{"op":"mcm","clk":"1003888311","pt":1580615323334,"mc":[{"id":"1.168237330","rc":[{"batb":[[1,1.5,13.12],[2,1.01,13.21]],"batl":[[0,1.97,37.86],[1,1000,0.02],[2,1.97,0]],"ltp":1.5,"tv":3065.66,"id":6596286}]}]}
{"op":"mcm","clk":"1003888453","pt":1580615328180,"mc":[{"id":"1.168237330","rc":[{"batb":[[0,1.66,1086.22],[1,1.65,654.29],[2,1.6,12.31]],"batl":[[0,1.72,1109.61],[1,1.74,1091.82],[2,1.97,37.86]],"ltp":1.5,"tv":3065.66,"id":6596286}]}]}
{"op":"mcm","clk":"1003888782","pt":1580615338294,"mc":[{"id":"1.168237330","rc":[{"batb":[[0,1.6,12.31],[1,1.5,13.12],[2,1.01,13.21]],"batl":[[0,1.97,37.86],[1,1000,0.02],[2,1.97,0]],"ltp":1.5,"tv":3065.66,"id":6596286}]}]}
{"op":"mcm","clk":"1003888949","pt":1580615343603,"mc":[{"id":"1.168237330","rc":[{"batb":[[1,1.59,1158.92],[2,1.58,767.38]],"batl":[[0,1.82,1025.91],[1,1.84,911.61],[2,1.97,37.86]],"ltp":1.5,"tv":3065.66,"id":6596286}]}]}
{"op":"mcm","clk":"1003889808","pt":1580615370066,"mc":[{"id":"1.168237330","rc":[{"batl":[[0,1.97,37.86],[1,1000,0.02],[2,1.97,0]],"ltp":1.5,"tv":3065.66,"id":6596286}]}]}
{"op":"mcm","clk":"1003889970","pt":1580615374981,"mc":[{"id":"1.168237330","rc":[{"batl":[[0,1.64,900.21],[1,1.65,651.09],[2,1.97,37.86]],"ltp":1.5,"tv":3065.66,"id":6596286}]}]}
{"op":"mcm","clk":"1003890271","pt":1580615383887,"mc":[{"id":"1.168237330","rc":[{"batb":[[1,1.01,13.21],[2,1.58,0]],"batl":[[0,1.97,37.86],[1,1000,0.02],[2,1.97,0]],"ltp":1.5,"tv":3065.66,"id":6596286}]}]}
{"op":"mcm","clk":"1003890428","pt":1580615388791,"mc":[{"id":"1.168237330","rc":[{"batb":[[1,1.52,1560.58],[2,1.51,917.22]],"batl":[[0,1.74,1021.13],[1,1.76,1051.82],[2,1.97,37.86]],"ltp":1.5,"tv":3065.66,"id":6596286}]}]}
{"op":"mcm","clk":"1003890550","pt":1580615392667,"mc":[{"id":"1.168237330","rc":[{"batb":[[1,1.01,13.21],[2,1.51,0]],"ltp":1.5,"tv":3065.66,"id":6596286}]}]}
{"op":"mcm","clk":"1003890694","pt":1580615397564,"mc":[{"id":"1.168237330","rc":[{"batb":[[0,1.68,1049.84],[1,1.66,1272.6],[2,1.6,12.31]],"ltp":1.5,"tv":3065.66,"id":6596286}]}]}
{"op":"mcm","clk":"1003890900","pt":1580615404104,"mc":[{"id":"1.168237330","rc":[{"batb":[[0,1.6,12.31],[1,1.01,13.21],[2,1.6,0]],"batl":[[0,1.97,37.86],[1,1000,0.02],[2,1.97,0]],"ltp":1.5,"tv":3065.66,"id":6596286}]}]}
{"op":"mcm","clk":"1003891054","pt":1580615409013,"mc":[{"id":"1.168237330","rc":[{"batb":[[0,1.6,960.41],[1,1.59,748.6],[2,1.01,13.21]],"batl":[[0,1.86,977.15],[1,1.88,852.41],[2,1.97,37.86]],"ltp":1.5,"tv":3065.66,"id":6596286}]}]}
{"op":"mcm","clk":"1003891185","pt":1580615413597,"mc":[{"id":"1.168237330","rc":[{"batb":[[0,1.6,12.31],[1,1.01,13.21],[2,1.01,0]],"ltp":1.5,"tv":3065.66,"id":6596286}]}]}
{"op":"mcm","clk":"1003891321","pt":1580615418500,"mc":[{"id":"1.168237330","rc":[{"batb":[[0,1.79,975.91],[1,1.77,1020.59],[2,1.6,12.31]],"batl":[[0,1.82,2.27],[1,1.86,977.15],[2,1.88,852.41]],"ltp":1.5,"tv":3065.66,"id":6596286}]}]}
{"op":"mcm","clk":"1003891551","pt":1580615426247,"mc":[{"id":"1.168237330","rc":[{"batb":[[0,1.6,12.31],[1,1.01,13.21],[2,1.6,0]],"batl":[[1,1.97,37.86],[2,1000,0.02]],"ltp":1.5,"tv":3065.66,"id":6596286}]}]}
{"op":"mcm","clk":"1003891616","pt":1580615428522,"mc":[{"id":"1.168237330","rc":[{"batl":[[1,1000,0.02],[2,1000,0]],"ltp":1.5,"tv":3065.66,"id":6596286}]}]}
{"op":"mcm","clk":"1003891694","pt":1580615431238,"mc":[{"id":"1.168237330","rc":[{"batb":[[0,1.71,1079.74],[1,1.69,1195.08],[2,1.6,12.31]],"ltp":1.5,"tv":3065.66,"id":6596286}]}]}
{"op":"mcm","clk":"1003891741","pt":1580615433349,"mc":[{"id":"1.168237330","rc":[{"batl":[[0,1.77,822.73],[1,1.79,996.21],[2,1.82,2.27]],"ltp":1.5,"tv":3065.66,"id":6596286}]}]}
{"op":"mcm","clk":"1003891865","pt":1580615438041,"mc":[{"id":"1.168237330","rc":[{"batb":[[0,1.73,11.38],[1,1.71,1079.74],[2,1.69,1195.08]],"ltp":1.5,"tv":3065.66,"id":6596286}]}]}
{"op":"mcm","clk":"1003891966","pt":1580615440777,"mc":[{"id":"1.168237330","rc":[{"batb":[[1,1.6,12.31],[2,1.01,13.21]],"batl":[[0,1.82,2.27],[1,1000,0.02],[2,1.82,0]],"ltp":1.5,"tv":3065.66,"id":6596286}]}]}
{"op":"mcm","clk":"1003891984","pt":1580615441135,"mc":[{"id":"1.168237330","rc":[{"batb":[[0,1.6,12.31],[1,1.01,13.21],[2,1.01,0]],"ltp":1.5,"tv":3065.66,"id":6596286}]}]}
{"op":"mcm","clk":"1003892049","pt":1580615444877,"mc":[{"id":"1.168237330","rc":[{"trd":[[1.71,3.22]],"batb":[[0,1.77,7.91],[1,1.6,12.31],[2,1.01,13.21]],"ltp":1.71,"tv":3068.88,"id":6596286},{"trd":[[2.42,2.27]],"ltp":2.42,"tv":1354.83,"id":8196374}],"tv":4423.71}]}
{"op":"mcm","clk":"1003892068","pt":1580615445650,"mc":[{"id":"1.168237330","rc":[{"batb":[[1,1.6,1184.35],[2,1.59,749.49]],"batl":[[1,1.93,559.41],[2,1.95,762.65]],"ltp":1.71,"tv":3068.88,"id":6596286}]}]}
{"op":"mcm","clk":"1003892101","pt":1580615447038,"mc":[{"id":"1.168237330","rc":[{"trd":[[1.82,2.27]],"batl":[[0,1.93,559.41],[1,1.95,762.65],[2,1000,0.02]],"ltp":1.82,"tv":3071.15,"id":6596286},{"trd":[[2.2,1.88]],"batl":[[0,2.2,3.19],[1,1000,0.02]],"ltp":2.2,"tv":1356.71,"id":8196374}],"tv":4427.86}]}
{"op":"mcm","clk":"1003892228","pt":1580615453879,"mc":[{"id":"1.168237330","rc":[{"batl":[[0,1000,0.02],[1,1.95,0],[2,1000,0]],"ltp":1.82,"tv":3071.15,"id":6596286},{"trd":[[2.2,8.25]],"batl":[[0,1000,0.02],[1,1000,0]],"ltp":2.2,"tv":1363.08,"id":8196374}],"tv":4434.24}]}
{"op":"mcm","clk":"1003892273","pt":1580615455576,"mc":[{"id":"1.168237330","rc":[{"batb":[[0,1.6,1184.35],[1,1.59,749.49],[2,1.01,13.21]],"ltp":1.82,"tv":3071.15,"id":6596286}]}]}
{"op":"mcm","clk":"1003892301","pt":1580615456858,"mc":[{"id":"1.168237330","rc":[{"batb":[[0,1.93,1.68],[1,1.6,1184.35],[2,1.59,749.49]],"ltp":1.82,"tv":3071.15,"id":6596286}]}]}
{"op":"mcm","clk":"1003892314","pt":1580615457268,"mc":[{"id":"1.168237330","rc":[{"batb":[[1,1.6,1172.04]],"ltp":1.82,"tv":3071.15,"id":6596286}]}]}
{"op":"mcm","clk":"1003892349","pt":1580615458759,"mc":[{"id":"1.168237330","rc":[{"trd":[[1.93,3.36]],"batb":[[0,1.6,1172.04],[1,1.59,749.49],[2,1.01,13.21]],"batl":[[0,1.65,818.79],[1,1.66,637.77],[2,1000,0.02]],"ltp":1.93,"tv":3074.51,"id":6596286}],"tv":4437.6}]}
{"op":"mcm","clk":"1003892607","pt":1580615468919,"mc":[{"id":"1.168237330","rc":[{"trd":[[1.65,197.5]],"batb":[[0,1.01,13.21],[1,1.59,0],[2,1.01,0]],"batl":[[0,1000,0.02],[1,1.66,0],[2,1000,0]],"ltp":1.65,"tv":3150.87,"id":6596286},{"trd":[[2.52,110.47]],"ltp":2.52,"tv":1413.08,"id":8196374}],"tv":4563.96}]}
{"op":"mcm","clk":"1003892744","pt":1580615474102,"mc":[{"id":"1.168237330","rc":[{"batb":[[0,1.52,1053.32],[1,1.51,913.82],[2,1.01,13.21]],"batl":[[0,1.78,1009.29],[1,1.8,977.47],[2,1000,0.02]],"ltp":1.65,"tv":3150.87,"id":6596286}]}]}
{"op":"mcm","clk":"1003892872","pt":1580615478922,"mc":[{"id":"1.168237330","rc":[{"batb":[[0,1.59,8.92],[1,1.52,1053.32],[2,1.51,913.82]],"ltp":1.65,"tv":3150.87,"id":6596286}]}]}
{"op":"mcm","clk":"1003893078","pt":1580615485704,"mc":[{"id":"1.168237330","rc":[{"batb":[[1,1.01,13.21],[2,1.51,0]],"ltp":1.65,"tv":3150.87,"id":6596286}]}]}
{"op":"mcm","clk":"1003893208","pt":1580615490621,"mc":[{"id":"1.168237330","rc":[{"batb":[[0,1.72,827.83],[1,1.7,1169.4],[2,1.59,8.92]],"ltp":1.65,"tv":3150.87,"id":6596286}]}]}
{"op":"mcm","clk":"1003893429","pt":1580615498341,"mc":[{"id":"1.168237330","rc":[{"batb":[[0,1.59,8.92],[1,1.01,13.21],[2,1.59,0]],"batl":[[0,1000,0.02],[1,1.8,0],[2,1000,0]],"ltp":1.65,"tv":3150.87,"id":6596286}]}]}
{"op":"mcm","clk":"1003893486","pt":1580615500137,"mc":[{"id":"1.168237330","rc":[{"batb":[[0,1.78,7.97],[1,1.59,8.92],[2,1.01,13.21]],"ltp":1.65,"tv":3150.87,"id":6596286}]}]}
{"op":"mcm","clk":"1003893573","pt":1580615503737,"mc":[{"id":"1.168237330","rc":[{"batb":[[0,1.61,792.8],[1,1.6,730.48],[2,1.59,8.92]],"batl":[[0,1.94,678.89],[1,1.96,750.63],[2,1000,0.02]],"ltp":1.65,"tv":3150.87,"id":6596286}]}]}
{"op":"mcm","clk":"1003893662","pt":1580615507530,"mc":[{"id":"1.168237330","rc":[{"batb":[[0,1.59,8.92],[1,1.01,13.21],[2,1.59,0]],"ltp":1.65,"tv":3150.87,"id":6596286}]}]}
{"op":"mcm","clk":"1003893789","pt":1580615512553,"mc":[{"id":"1.168237330","rc":[{"batb":[[0,1.87,920.24],[1,1.85,882.98],[2,1.59,8.92]],"ltp":1.65,"tv":3150.87,"id":6596286}]}]}
{"op":"mcm","clk":"1003894091","pt":1580615522734,"mc":[{"id":"1.168237330","rc":[{"batb":[[0,1.59,8.92],[1,1.01,13.21],[2,1.59,0]],"batl":[[0,1000,0.02],[1,1.96,0],[2,1000,0]],"ltp":1.65,"tv":3150.87,"id":6596286}]}]}
{"op":"mcm","clk":"1003894252","pt":1580615527660,"mc":[{"id":"1.168237330","rc":[{"batb":[[0,1.77,919.48],[1,1.75,1059.7],[2,1.59,8.92]],"batl":[[0,2.06,944.16],[1,2.08,629.81],[2,1000,0.02]],"ltp":1.65,"tv":3150.87,"id":6596286}]}]}
{"op":"mcm","clk":"1003894835","pt":1580615548586,"mc":[{"id":"1.168237330","rc":[{"batb":[[0,1.8,7.88],[1,1.77,919.48],[2,1.75,1059.7]],"ltp":1.65,"tv":3150.87,"id":6596286}]}]}
{"op":"mcm","clk":"1003895502","pt":1580615569924,"mc":[{"id":"1.168237330","rc":[{"batl":[[2,1000,3.05]],"ltp":1.65,"tv":3150.87,"id":6596286}]}]}
{"op":"mcm","clk":"1003895596","pt":1580615573403,"mc":[{"id":"1.168237330","rc":[{"batl":[[0,1000,3.05],[1,2.08,0],[2,1000,0]],"ltp":1.65,"tv":3150.87,"id":6596286}]}]}
{"op":"mcm","clk":"1003895697","pt":1580615576737,"mc":[{"id":"1.168237330","rc":[{"batb":[[0,1.77,919.48],[1,1.75,1059.7],[2,1.59,8.92]],"ltp":1.65,"tv":3150.87,"id":6596286}]}]}
{"op":"mcm","clk":"1003895750","pt":1580615578324,"mc":[{"id":"1.168237330","rc":[{"batl":[[0,1.83,680.98],[1,1.85,896.8],[2,1000,3.05]],"ltp":1.65,"tv":3150.87,"id":6596286}]}]}
{"op":"mcm","clk":"1003895828","pt":1580615580737,"mc":[{"id":"1.168237330","rc":[{"batl":[[2,1000,1.53]],"ltp":1.65,"tv":3150.87,"id":6596286}]}]}
{"op":"mcm","clk":"1003895847","pt":1580615581053,"mc":[{"id":"1.168237330","rc":[{"batb":[[0,1.7,83.3],[1,1.38,2.63],[2,1.01,13.21]],"ltp":2.52,"tv":1413.08,"id":8196374}]}]}
{"op":"mcm","clk":"1003895911","pt":1580615582444,"mc":[{"id":"1.168237330","rc":[{"batl":[[2,1000,0.02]],"ltp":1.65,"tv":3150.87,"id":6596286}]}]}
{"op":"mcm","clk":"1003895989","pt":1580615584906,"mc":[{"id":"1.168237330","rc":[{"batb":[[0,1.79,7.92],[1,1.77,919.48],[2,1.75,1059.7]],"ltp":1.65,"tv":3150.87,"id":6596286}]}]}
{"op":"mcm","clk":"1003896045","pt":1580615586853,"mc":[{"id":"1.168237330","rc":[{"trd":[[1.77,3.66],[1.79,15.84]],"batb":[[0,1.77,917.65],[1,1.75,1059.7],[2,1.59,8.92]],"ltp":1.77,"tv":3170.37,"id":6596286}],"tv":4583.46}]}
{"op":"mcm","clk":"1003896076","pt":1580615587519,"mc":[{"id":"1.168237330","rc":[{"trd":[[1.77,6.68]],"batb":[[0,1.77,916.14]],"ltp":1.77,"tv":3173.39,"id":6596286}],"tv":4586.48}]}
{"op":"mcm","clk":"1003896101","pt":1580615588440,"mc":[{"id":"1.168237330","rc":[{"batb":[[0,1.59,8.92],[1,1.01,13.21],[2,1.59,0]],"batl":[[0,1000,0.02],[1,1.85,0],[2,1000,0]],"ltp":1.77,"tv":3173.39,"id":6596286}]}]}
{"op":"mcm","clk":"1003896245","pt":1580615593356,"mc":[{"id":"1.168237330","rc":[{"batb":[[0,1.68,825.4],[1,1.66,1271],[2,1.59,8.92]],"batl":[[0,1.94,917.89],[1,1.96,750.41],[2,1000,0.02]],"ltp":1.77,"tv":3173.39,"id":6596286}]}]}
{"op":"mcm","clk":"1003896318","pt":1580615595936,"mc":[{"id":"1.168237330","rc":[{"batb":[[2,1.01,13.21]],"ltp":1.77,"tv":3173.39,"id":6596286}]}]}
{"op":"mcm","clk":"1003896929","pt":1580615612777,"mc":[{"id":"1.168237330","rc":[{"batb":[[0,1.01,13.21],[1,1.66,0],[2,1.01,0]],"batl":[[0,1000,0.02],[1,1.96,0],[2,1000,0]],"ltp":1.77,"tv":3173.39,"id":6596286}]}]}
{"op":"mcm","clk":"1003897106","pt":1580615617777,"mc":[{"id":"1.168237330","rc":[{"batb":[[0,1.68,825.4],[1,1.66,1271],[2,1.01,13.21]],"batl":[[0,1.73,693.83],[1,1.75,1072.84],[2,1000,0.02]],"ltp":1.77,"tv":3173.39,"id":6596286}]}]}
{"op":"mcm","clk":"1003897484","pt":1580615627758,"mc":[{"id":"1.168237330","rc":[{"batb":[[0,1.01,13.21],[1,1.66,0],[2,1.01,0]],"batl":[[0,1000,0.02],[1,1.75,0],[2,1000,0]],"ltp":1.77,"tv":3173.39,"id":6596286}]}]}
{"op":"mcm","clk":"1003897667","pt":1580615632943,"mc":[{"id":"1.168237330","rc":[{"batb":[[0,1.61,667.46],[1,1.6,730.01],[2,1.01,13.21]],"batl":[[0,1.81,594.33],[1,1.83,928.44],[2,1000,0.02]],"ltp":1.77,"tv":3173.39,"id":6596286}]}]}
{"op":"mcm","clk":"1003898215","pt":1580615649299,"mc":[{"id":"1.168237330","rc":[{"batb":[[0,1.01,13.21],[1,1.6,0],[2,1.01,0]],"ltp":1.77,"tv":3173.39,"id":6596286}]}]}
{"op":"mcm","clk":"1003898379","pt":1580615654271,"mc":[{"id":"1.168237330","rc":[{"batb":[[0,1.75,1105.89],[1,1.73,1102.36],[2,1.01,13.21]],"ltp":1.77,"tv":3173.39,"id":6596286}]}]}
{"op":"mcm","clk":"1003898689","pt":1580615664417,"mc":[{"id":"1.168237330","rc":[{"batb":[[0,1.01,13.21],[1,1.73,0],[2,1.01,0]],"batl":[[0,1000,0.02],[1,1.83,0],[2,1000,0]],"ltp":1.77,"tv":3173.39,"id":6596286}]}]}
{"op":"mcm","clk":"1003898773","pt":1580615666986,"mc":[{"id":"1.168237330","rc":[{"batl":[[0,1.75,6.96],[1,1000,0.02]],"ltp":1.77,"tv":3173.39,"id":6596286}]}]}
{"op":"mcm","clk":"1003898838","pt":1580615669399,"mc":[{"id":"1.168237330","rc":[{"batb":[[0,1.65,1044.83],[1,1.64,668.39],[2,1.01,13.21]],"batl":[[1,1.93,721.4],[2,1.95,762.29]],"ltp":1.77,"tv":3173.39,"id":6596286}]}]}
{"op":"mcm","clk":"1003899047","pt":1580615676127,"mc":[{"id":"1.168237330","rc":[{"batb":[[0,1.01,13.21],[1,1.64,0],[2,1.01,0]],"batl":[[1,1000,0.02],[2,1.95,0]],"ltp":1.77,"tv":3173.39,"id":6596286}]}]}
{"op":"mcm","clk":"1003899283","pt":1580615684136,"mc":[{"id":"1.168237330","rc":[{"batb":[[0,1.65,1044.83],[1,1.64,668.39],[2,1.01,13.21]],"batl":[[1,1.93,721.4],[2,1.95,762.29]],"ltp":1.77,"tv":3173.39,"id":6596286}]}]}
{"op":"mcm","clk":"1003899740","pt":1580615698350,"mc":[{"id":"1.168237330","rc":[{"batl":[[0,1.93,721.4],[1,1.95,762.29],[2,1000,0.02]],"ltp":1.77,"tv":3173.39,"id":6596286}]}]}
{"op":"mcm","clk":"1003899780","pt":1580615699533,"mc":[{"id":"1.168237330","rc":[{"batb":[[2,1.4,83.3]],"ltp":1.77,"tv":3173.39,"id":6596286}]}]}
{"op":"mcm","clk":"1003899844","pt":1580615701537,"mc":[{"id":"1.168237330","rc":[{"batb":[[0,1.4,83.3],[1,1.01,13.21],[2,1.4,0]],"batl":[[0,1000,0.02],[1,1.95,0],[2,1000,0]],"ltp":1.77,"tv":3173.39,"id":6596286}]}]}
{"op":"mcm","clk":"1003900015","pt":1580615706544,"mc":[{"id":"1.168237330","rc":[{"batb":[[0,1.65,1044.83],[1,1.64,668.39],[2,1.4,83.3]],"batl":[[0,1.7,639.61],[1,1.72,1136.8],[2,1000,0.02]],"ltp":1.77,"tv":3173.39,"id":6596286}]}]}
{"op":"mcm","clk":"1003900359","pt":1580615716643,"mc":[{"id":"1.168237330","rc":[{"batb":[[0,1.4,83.3],[1,1.01,13.21],[2,1.4,0]],"batl":[[0,1000,0.02],[1,1.72,0],[2,1000,0]],"ltp":1.77,"tv":3173.39,"id":6596286}]}]}
{"op":"mcm","clk":"1003900524","pt":1580615721985,"mc":[{"id":"1.168237330","rc":[{"batb":[[0,1.58,1067.44],[1,1.57,785.31],[2,1.4,83.3]],"batl":[[0,1.78,645.39],[1,1.8,978.75],[2,1000,0.02]],"ltp":1.77,"tv":3173.39,"id":6596286}]}]}
{"op":"mcm","clk":"1003900872","pt":1580615734192,"mc":[{"id":"1.168237330","rc":[{"batl":[[0,1000,0.02],[1,1.8,0],[2,1000,0]],"ltp":1.77,"tv":3173.39,"id":6596286}]}]}
{"op":"mcm","clk":"1003900998","pt":1580615739202,"mc":[{"id":"1.168237330","rc":[{"batl":[[0,1.63,1055.52],[1,1.64,664.28],[2,1000,0.02]],"ltp":1.77,"tv":3173.39,"id":6596286}]}]}
{"op":"mcm","clk":"1003901324","pt":1580615749287,"mc":[{"id":"1.168237330","rc":[{"batb":[[0,1.4,83.3],[1,1.01,13.21],[2,1.4,0]],"batl":[[0,1000,0.02],[1,1.64,0],[2,1000,0]],"ltp":1.77,"tv":3173.39,"id":6596286}]}]}
{"op":"mcm","clk":"1003901478","pt":1580615754200,"mc":[{"id":"1.168237330","rc":[{"batb":[[0,1.52,829.71],[1,1.51,912.51],[2,1.4,83.3]],"batl":[[0,1.72,1078.02],[1,1.74,1091.58],[2,1000,0.02]],"ltp":1.77,"tv":3173.39,"id":6596286}]}]}
{"op":"mcm","clk":"1003901579","pt":1580615757422,"mc":[{"id":"1.168237330","rc":[{"batb":[[2,1.01,13.21]],"ltp":1.77,"tv":3173.39,"id":6596286}]}]}
{"op":"mcm","clk":"1003901759","pt":1580615762609,"mc":[{"id":"1.168237330","rc":[{"batb":[[2,1.33,83.3]],"batl":[[0,1000,0.02],[1,1.74,0],[2,1000,0]],"ltp":1.77,"tv":3173.39,"id":6596286}]}]}
{"op":"mcm","clk":"1003901956","pt":1580615767644,"mc":[{"id":"1.168237330","rc":[{"batl":[[0,1.56,988.33],[1,1.57,778.1],[2,1000,0.02]],"ltp":1.77,"tv":3173.39,"id":6596286}]}]}
{"op":"mcm","clk":"1003902107","pt":1580615771747,"mc":[{"id":"1.168237330","rc":[{"batb":[[0,1.33,83.3],[1,1.01,13.21],[2,1.33,0]],"batl":[[0,1000,0.02],[1,1.57,0],[2,1000,0]],"ltp":1.77,"tv":3173.39,"id":6596286}]}]}
{"op":"mcm","clk":"1003902192","pt":1580615774210,"mc":[{"id":"1.168237330","rc":[{"batb":[[0,1.38,2.63],[1,1.01,13.21],[2,1.01,0]],"ltp":2.52,"tv":1413.08,"id":8196374}]}]}
{"op":"mcm","clk":"1003902278","pt":1580615776621,"mc":[{"id":"1.168237330","rc":[{"batb":[[0,1.46,1522.34],[1,1.45,1083.87],[2,1.33,83.3]],"batl":[[0,1.64,1213.43],[1,1.65,649.67],[2,1000,0.02]],"ltp":1.77,"tv":3173.39,"id":6596286}]}]}
{"op":"mcm","clk":"1003902377","pt":1580615779343,"mc":[{"id":"1.168237330","rc":[{"batb":[[0,2.02,83.3],[1,1.38,2.63],[2,1.01,13.21]],"ltp":2.52,"tv":1413.08,"id":8196374}]}]}
{"op":"mcm","clk":"1003903289","pt":1580615803437,"mc":[{"id":"1.168237330","rc":[{"batl":[[0,1000,0.02],[1,1.65,0],[2,1000,0]],"ltp":1.77,"tv":3173.39,"id":6596286}]}]}
{"op":"mcm","clk":"1003903509","pt":1580615808477,"mc":[{"id":"1.168237330","rc":[{"batl":[[0,1.5,831.04],[1,1.51,903.9],[2,1000,0.02]],"ltp":1.77,"tv":3173.39,"id":6596286}]}]}
{"op":"mcm","clk":"1003903939","pt":1580615818589,"mc":[{"id":"1.168237330","rc":[{"batb":[[0,1.33,83.3],[1,1.01,13.21],[2,1.33,0]],"batl":[[0,1000,0.02],[1,1.51,0],[2,1000,0]],"ltp":1.77,"tv":3173.39,"id":6596286}]}]}
{"op":"mcm","clk":"1003904156","pt":1580615823876,"mc":[{"id":"1.168237330","rc":[{"batb":[[0,1.42,1682.87],[1,1.41,1226.48],[2,1.33,83.3]],"batl":[[0,1.46,75.72],[1,1.56,1139.42],[2,1.57,777.31]],"ltp":1.77,"tv":3173.39,"id":6596286}]}]}
{"op":"mcm","clk":"1003904183","pt":1580615824491,"mc":[{"id":"1.168237330","rc":[{"batb":[[0,1.33,83.3],[1,1.01,13.21],[2,1.33,0]],"batl":[[1,1000,0.02],[2,1.57,0]],"ltp":1.77,"tv":3173.39,"id":6596286}]}]}
{"op":"mcm","clk":"1003904204","pt":1580615825103,"mc":[{"id":"1.168237330","rc":[{"batb":[[0,1.36,60.58],[1,1.33,83.3],[2,1.01,13.21]],"ltp":1.77,"tv":3173.39,"id":6596286}]}]}
{"op":"mcm","clk":"1003904247","pt":1580615826284,"mc":[{"id":"1.168237330","rc":[{"trd":[[1.46,7.98]],"batl":[[0,1.46,73.45]],"ltp":1.46,"tv":3177.94,"id":6596286}],"tv":4591.02}]}
{"op":"mcm","clk":"1003904314","pt":1580615827877,"mc":[{"id":"1.168237330","rc":[{"batl":[[0,1000,0.02],[1,1000,0]],"ltp":1.46,"tv":3177.94,"id":6596286}]}]}
{"op":"mcm","clk":"1003904370","pt":1580615829414,"mc":[{"id":"1.168237330","rc":[{"batb":[[0,1.46,1522.34],[1,1.45,1083.87],[2,1.36,60.58]],"batl":[[0,1.5,831.04],[1,1.51,903.9],[2,1000,0.02]],"ltp":1.46,"tv":3177.94,"id":6596286}]}]}
{"op":"mcm","clk":"1003904392","pt":1580615830078,"mc":[{"id":"1.168237330","rc":[{"batb":[[0,1.36,60.58],[1,1.33,83.3],[2,1.01,13.21]],"batl":[[0,1000,0.02],[1,1.51,0],[2,1000,0]],"ltp":1.46,"tv":3177.94,"id":6596286}]}]}
{"op":"mcm","clk":"1003904492","pt":1580615832793,"mc":[{"id":"1.168237330","rc":[{"batb":[[1,1.01,13.21],[2,1.01,0]],"ltp":1.46,"tv":3177.94,"id":6596286}]}]}
{"op":"mcm","clk":"1003904515","pt":1580615833406,"mc":[{"id":"1.168237330","rc":[{"batl":[[0,1.5,252.92],[1,1000,0.02]],"ltp":1.46,"tv":3177.94,"id":6596286}]}]}
{"op":"mcm","clk":"1003904574","pt":1580615835097,"mc":[{"id":"1.168237330","rc":[{"batb":[[0,1.42,1682.87],[1,1.41,1226.48],[2,1.36,60.58]],"batl":[[1,1.56,1139.42],[2,1.57,777.31]],"ltp":1.46,"tv":3177.94,"id":6596286}]}]}
{"op":"mcm","clk":"1003905064","pt":1580615847712,"mc":[{"id":"1.168237330","rc":[{"batb":[[0,1.36,60.58],[1,1.3,83.3],[2,1.01,13.21]],"ltp":1.46,"tv":3177.94,"id":6596286}]}]}
{"op":"mcm","clk":"1003905132","pt":1580615849613,"mc":[{"id":"1.168237330","rc":[{"batb":[[0,1.38,2.63],[1,1.01,13.21],[2,1.01,0]],"ltp":2.52,"tv":1413.08,"id":8196374}]}]}
{"op":"mcm","clk":"1003905248","pt":1580615852739,"mc":[{"id":"1.168237330","rc":[{"trd":[[1.5,769.02]],"batb":[[0,1.51,1334.39],[1,1.5,941.87],[2,1.36,60.58]],"batl":[[0,1.56,1139.42],[1,1.57,777.31],[2,1000,0.02]],"ltp":1.5,"tv":3683.77,"id":6596286}],"tv":5096.86}]}
{"op":"mcm","clk":"1003905316","pt":1580615854739,"mc":[{"id":"1.168237330","rc":[{"trd":[[1.51,269.01]],"batb":[[0,1.51,1258.67]],"ltp":1.51,"tv":3835.21,"id":6596286},{"batb":[[0,2.26,83.3],[1,1.38,2.63],[2,1.01,13.21]],"ltp":2.52,"tv":1413.08,"id":8196374}],"tv":5248.3}]}
{"op":"mcm","clk":"1003905445","pt":1580615857915,"mc":[{"id":"1.168237330","rc":[{"batl":[[0,1.56,1382.89]],"ltp":1.51,"tv":3835.21,"id":6596286}]}]}
{"op":"mcm","clk":"1003905530","pt":1580615860123,"mc":[{"id":"1.168237330","rc":[{"batl":[[0,1.56,1456.26]],"ltp":1.51,"tv":3835.21,"id":6596286}]}]}
{"op":"mcm","clk":"1003905625","pt":1580615862849,"mc":[{"id":"1.168237330","rc":[{"batb":[[0,1.36,60.58],[1,1.3,83.3],[2,1.01,13.21]],"batl":[[0,1000,0.02],[1,1.57,0],[2,1000,0]],"ltp":1.51,"tv":3835.21,"id":6596286}]}]}
{"op":"mcm","clk":"1003905725","pt":1580615865215,"mc":[{"id":"1.168237330","rc":[{"batb":[[1,1.35,9.75],[2,1.3,83.3]],"ltp":1.51,"tv":3835.21,"id":6596286}]}]}
{"op":"mcm","clk":"1003905810","pt":1580615867844,"mc":[{"id":"1.168237330","rc":[{"batb":[[0,1.45,1348.04],[1,1.44,1117.75],[2,1.36,60.58]],"batl":[[0,1.64,965.77],[1,1.65,651.92],[2,1000,0.02]],"ltp":1.51,"tv":3835.21,"id":6596286}]}]}
{"op":"mcm","clk":"1003906187","pt":1580615876326,"mc":[{"id":"1.168237330","rc":[{"batb":[[0,1.38,2.63],[1,1.01,13.21],[2,1.01,0]],"ltp":2.52,"tv":1413.08,"id":8196374}]}]}
{"op":"mcm","clk":"1003906412","pt":1580615881675,"mc":[{"id":"1.168237330","rc":[{"batb":[[0,1.36,60.58],[1,1.35,9.75],[2,1.3,83.3]],"batl":[[0,1000,0.02],[1,1.65,0],[2,1000,0]],"ltp":1.51,"tv":3835.21,"id":6596286},{"batb":[[0,2.1,83.3],[1,1.38,2.63],[2,1.01,13.21]],"ltp":2.52,"tv":1413.08,"id":8196374}]}]}
{"op":"mcm","clk":"1003907091","pt":1580615897875,"mc":[{"id":"1.168237330","rc":[{"batb":[[0,1.38,2.63],[1,1.01,13.21],[2,1.01,0]],"ltp":2.52,"tv":1413.08,"id":8196374}]}]}
{"op":"mcm","clk":"1003907253","pt":1580615902995,"mc":[{"id":"1.168237330","rc":[{"batb":[[0,2.02,83.3],[1,1.38,2.63],[2,1.01,13.21]],"ltp":2.52,"tv":1413.08,"id":8196374}]}]}
{"op":"mcm","clk":"1003907311","pt":1580615904892,"mc":[{"id":"1.168237330","rc":[{"batb":[[0,1.45,1348.04],[1,1.44,1117.75],[2,1.36,60.58]],"batl":[[0,1.64,965.77],[1,1.65,651.92],[2,1000,0.02]],"ltp":1.51,"tv":3835.21,"id":6596286}]}]}
{"op":"mcm","clk":"1003907367","pt":1580615906585,"mc":[{"id":"1.168237330","rc":[{"batb":[[0,1.36,60.58],[1,1.35,9.75],[2,1.3,83.3]],"ltp":1.51,"tv":3835.21,"id":6596286}]}]}
{"op":"mcm","clk":"1003907554","pt":1580615911609,"mc":[{"id":"1.168237330","rc":[{"batb":[[0,1.59,1095.78],[1,1.58,768.32],[2,1.36,60.58]],"ltp":1.51,"tv":3835.21,"id":6596286}]}]}
{"op":"mcm","clk":"1003907891","pt":1580615921718,"mc":[{"id":"1.168237330","rc":[{"batb":[[0,1.36,60.58],[1,1.35,9.75],[2,1.3,83.3]],"batl":[[0,1000,0.02],[1,1.65,0],[2,1000,0]],"ltp":1.51,"tv":3835.21,"id":6596286}]}]}
{"op":"mcm","clk":"1003908085","pt":1580615926810,"mc":[{"id":"1.168237330","rc":[{"batb":[[0,1.5,1176.25],[1,1.49,967.32],[2,1.36,60.58]],"batl":[[0,1.77,883.13],[1,1.79,997.39],[2,1000,0.02]],"ltp":1.51,"tv":3835.21,"id":6596286}]}]}
{"op":"mcm","clk":"1003908106","pt":1580615927323,"mc":[{"id":"1.168237330","rc":[{"batb":[[0,1.36,60.58],[1,1.35,9.75],[2,1.3,83.3]],"batl":[[0,1000,0.02],[1,1.79,0],[2,1000,0]],"ltp":1.51,"tv":3835.21,"id":6596286}]}]}
{"op":"mcm","clk":"1003908324","pt":1580615934219,"mc":[{"id":"1.168237330","rc":[{"batl":[[0,1.58,28.02],[1,1000,0.02]],"ltp":1.51,"tv":3835.21,"id":6596286}]}]}
{"op":"mcm","clk":"1003908371","pt":1580615935350,"mc":[{"id":"1.168237330","rc":[{"batb":[[0,1.5,1176.25],[1,1.49,967.32],[2,1.36,60.58]],"batl":[[1,1.77,883.13],[2,1.79,997.39]],"ltp":1.51,"tv":3835.21,"id":6596286}]}]}
{"op":"mcm","clk":"1003908434","pt":1580615936833,"mc":[{"id":"1.168237330","rc":[{"batl":[[0,1.77,883.13],[1,1.79,997.39],[2,1000,0.02]],"ltp":1.51,"tv":3835.21,"id":6596286}]}]}
{"op":"mcm","clk":"1003908617","pt":1580615939829,"mc":[{"id":"1.168237330","rc":[{"batb":[[0,1.38,2.63],[1,1.01,13.21],[2,1.01,0]],"ltp":2.52,"tv":1413.08,"id":8196374}]}]}
{"op":"mcm","clk":"1003909027","pt":1580615944962,"mc":[{"id":"1.168237330","rc":[{"batb":[[0,1.83,83.3],[1,1.38,2.63],[2,1.01,13.21]],"ltp":2.52,"tv":1413.08,"id":8196374}]}]}
{"op":"mcm","clk":"1003909172","pt":1580615946343,"mc":[{"id":"1.168237330","rc":[{"trd":[[1.77,138.14]],"batl":[[0,1.77,817.4]],"ltp":1.77,"tv":3966.67,"id":6596286}],"tv":5379.76}]}
{"op":"mcm","clk":"1003909269","pt":1580615947549,"mc":[{"id":"1.168237330","rc":[{"batb":[[0,1.36,60.58],[1,1.35,9.75],[2,1.3,83.3]],"ltp":1.77,"tv":3966.67,"id":6596286}]}]}
{"op":"mcm","clk":"1003909531","pt":1580615951946,"mc":[{"id":"1.168237330","rc":[{"batb":[[0,1.5,77.94],[1,1.36,60.58],[2,1.35,9.75]],"ltp":1.77,"tv":3966.67,"id":6596286}]}]}
{"op":"mcm","clk":"1003909560","pt":1580615952356,"mc":[{"id":"1.168237330","rc":[{"batb":[[0,1.71,1089.14],[1,1.69,1196.44],[2,1.36,60.58]],"ltp":1.77,"tv":3966.67,"id":6596286}]}]}
{"op":"mcm","clk":"1003909818","pt":1580615957045,"mc":[{"id":"1.168237330","rc":[{"batb":[[2,1.37,83.3]],"ltp":1.77,"tv":3966.67,"id":6596286}]}]}
{"op":"mcm","clk":"1003910011","pt":1580615960846,"mc":[{"id":"1.168237330","rc":[{"batb":[[0,1.37,83.3],[1,1.36,60.58],[2,1.35,9.75]],"batl":[[0,1000,0.02],[1,1.79,0],[2,1000,0]],"ltp":1.77,"tv":3966.67,"id":6596286}]}]}
{"op":"mcm","clk":"1003910258","pt":1580615965759,"mc":[{"id":"1.168237330","rc":[{"batb":[[0,1.6,660.76],[1,1.59,748.4],[2,1.37,83.3]],"batl":[[0,1.94,800.75],[1,1.96,751.45],[2,1000,0.02]],"ltp":1.77,"tv":3966.67,"id":6596286}]}]}
{"op":"mcm","clk":"1003910363","pt":1580615967660,"mc":[{"id":"1.168237330","rc":[{"batl":[[0,2.28,60.58],[1,1000,0.02]],"ltp":2.52,"tv":1413.08,"id":8196374}]}]}
{"op":"mcm","clk":"1003910643","pt":1580615974378,"mc":[{"id":"1.168237330","rc":[{"batb":[[0,1.37,83.3],[1,1.36,60.58],[2,1.35,9.75]],"ltp":1.77,"tv":3966.67,"id":6596286}]}]}
{"op":"mcm","clk":"1003910792","pt":1580615978259,"mc":[{"id":"1.168237330","rc":[{"batl":[[0,1000,0.02],[1,1000,0]],"ltp":2.52,"tv":1413.08,"id":8196374}]}]}
{"op":"mcm","clk":"1003910829","pt":1580615979136,"mc":[{"id":"1.168237330","rc":[{"batb":[[0,1.87,796.8],[1,1.85,883.86],[2,1.37,83.3]],"ltp":1.77,"tv":3966.67,"id":6596286}]}]}
{"op":"mcm","clk":"1003910998","pt":1580615983342,"mc":[{"id":"1.168237330","rc":[{"trd":[[1.94,64.33]],"batl":[[0,1.94,736.42]],"ltp":1.94,"tv":4031.0,"id":6596286},{"trd":[[2.06,60.58]],"ltp":2.06,"tv":1473.66,"id":8196374}],"tv":5504.67}]}
{"op":"mcm","clk":"1003911114","pt":1580615986680,"mc":[{"id":"1.168237330","rc":[{"batb":[[0,1.38,2.63],[1,1.01,13.21],[2,1.01,0]],"ltp":2.06,"tv":1473.66,"id":8196374}]}]}
{"op":"mcm","clk":"1003911178","pt":1580615988683,"mc":[{"id":"1.168237330","rc":[{"batb":[[0,1.87,863.59]],"ltp":1.94,"tv":4031.0,"id":6596286}]}]}
{"op":"mcm","clk":"1003911304","pt":1580615991752,"mc":[{"id":"1.168237330","rc":[{"batb":[[0,1.7,83.3],[1,1.38,2.63],[2,1.01,13.21]],"ltp":2.06,"tv":1473.66,"id":8196374}]}]}
{"op":"mcm","clk":"1003911645","pt":1580616000483,"mc":[{"id":"1.168237330","rc":[{"trd":[[1.94,80.41]],"batl":[[0,1.94,720.34]],"ltp":1.94,"tv":4047.08,"id":6596286},{"trd":[[2.06,75.72]],"ltp":2.06,"tv":1488.81,"id":8196374}],"tv":5535.89}]}
{"op":"mcm","clk":"1003911749","pt":1580616002390,"mc":[{"id":"1.168237330","rc":[{"batb":[[2,1.36,60.58]],"ltp":1.94,"tv":4047.08,"id":6596286}]}]}
{"op":"mcm","clk":"1003912032","pt":1580616007494,"mc":[{"id":"1.168237330","rc":[{"batb":[[2,1.5,83.3]],"ltp":1.94,"tv":4047.08,"id":6596286}]}]}
{"op":"mcm","clk":"1003913066","pt":1580616025601,"mc":[{"id":"1.168237330","rc":[{"trd":[[1.87,19.5]],"batb":[[0,1.87,853.84]],"ltp":1.87,"tv":4066.58,"id":6596286}],"tv":5555.39}]}
{"op":"mcm","clk":"1003914739","pt":1580616054287,"mc":[{"id":"1.168237330","rc":[{"batb":[[0,1.5,83.3],[1,1.36,60.58],[2,1.35,9.75]],"batl":[[0,1000,0.02],[1,1.96,0],[2,1000,0]],"ltp":1.87,"tv":4066.58,"id":6596286}]}]}
{"op":"mcm","clk":"1003914967","pt":1580616059393,"mc":[{"id":"1.168237330","rc":[{"batb":[[0,1.76,1110.4],[1,1.74,1082.31],[2,1.5,83.3]],"batl":[[0,2.06,574],[1,2.08,630.38],[2,1000,0.02]],"ltp":1.87,"tv":4066.58,"id":6596286}]}]}
{"op":"mcm","clk":"1003915265","pt":1580616066315,"mc":[{"id":"1.168237330","rc":[{"batb":[[0,1.5,83.3],[1,1.36,60.58],[2,1.35,9.75]],"batl":[[0,1000,0.02],[1,2.08,0],[2,1000,0]],"ltp":1.87,"tv":4066.58,"id":6596286}]}]}
{"op":"mcm","clk":"1003915496","pt":1580616071207,"mc":[{"id":"1.168237330","rc":[{"batb":[[0,1.87,870.54],[1,1.85,883.9],[2,1.5,83.3]],"batl":[[0,1.94,729.75],[1,1.96,751.45],[2,1000,0.02]],"ltp":1.87,"tv":4066.58,"id":6596286}]}]}
{"op":"mcm","clk":"1003915804","pt":1580616077333,"mc":[{"id":"1.168237330","rc":[{"batb":[[0,1.5,83.3],[1,1.36,60.58],[2,1.35,9.75]],"batl":[[0,1000,0.02],[1,1.96,0],[2,1000,0]],"ltp":1.87,"tv":4066.58,"id":6596286},{"batb":[[1,1.49,45.43],[2,1.38,2.63]],"ltp":2.06,"tv":1488.81,"id":8196374}]}]}
{"op":"mcm","clk":"1003915851","pt":1580616078621,"mc":[{"id":"1.168237330","rc":[{"batb":[[2,1.4,45.43]],"ltp":2.06,"tv":1488.81,"id":8196374}]}]}
{"op":"mcm","clk":"1003915995","pt":1580616081911,"mc":[{"id":"1.168237330","rc":[{"batb":[[0,1.76,1110.4],[1,1.74,1082.31],[2,1.5,83.3]],"batl":[[0,2.06,574],[1,2.08,630.38],[2,1000,0.02]],"ltp":1.87,"tv":4066.58,"id":6596286}]}]}
{"op":"mcm","clk":"1003916115","pt":1580616084837,"mc":[{"id":"1.168237330","rc":[{"batb":[[0,1.49,45.43],[1,1.4,45.43],[2,1.38,2.63]],"ltp":2.06,"tv":1488.81,"id":8196374}]}]}
{"op":"mcm","clk":"1003916292","pt":1580616088952,"mc":[{"id":"1.168237330","rc":[{"batb":[[0,1.5,83.3],[1,1.36,60.58],[2,1.35,9.75]],"batl":[[0,1000,0.02],[1,2.08,0],[2,1000,0]],"ltp":1.87,"tv":4066.58,"id":6596286}]}]}
{"op":"mcm","clk":"1003916338","pt":1580616089932,"mc":[{"id":"1.168237330","rc":[{"batb":[[0,1.6,83.3],[1,1.49,45.43],[2,1.4,45.43]],"ltp":2.06,"tv":1488.81,"id":8196374}]}]}
{"op":"mcm","clk":"1003916519","pt":1580616093852,"mc":[{"id":"1.168237330","rc":[{"batb":[[0,1.94,739.89],[1,1.92,785.89],[2,1.6,83.3]],"batl":[[0,2.02,944.67],[1,2.04,667.11],[2,1000,0.02]],"ltp":2.06,"tv":1488.81,"id":8196374}]}]}
{"op":"mcm","clk":"1003916944","pt":1580616103996,"mc":[{"id":"1.168237330","rc":[{"batb":[[0,1.6,83.3],[1,1.49,45.43],[2,1.4,45.43]],"batl":[[0,1000,0.02],[1,2.04,0],[2,1000,0]],"ltp":2.06,"tv":1488.81,"id":8196374}]}]}
{"op":"mcm","clk":"1003917129","pt":1580616108936,"mc":[{"id":"1.168237330","rc":[{"batb":[[0,1.83,985.25],[1,1.81,948.82],[2,1.6,83.3]],"batl":[[0,2.16,897.96],[1,2.18,551.45],[2,1000,0.02]],"ltp":2.06,"tv":1488.81,"id":8196374}]}]}
{"op":"mcm","clk":"1003917667","pt":1580616122052,"mc":[{"id":"1.168237330","rc":[{"batb":[[0,1.6,83.3],[1,1.49,45.43],[2,1.4,45.43]],"batl":[[0,1000,0.02],[1,2.18,0],[2,1000,0]],"ltp":2.06,"tv":1488.81,"id":8196374}]}]}
{"op":"mcm","clk":"1003917889","pt":1580616126950,"mc":[{"id":"1.168237330","rc":[{"batb":[[0,1.87,693.11],[1,1.85,883.68],[2,1.5,83.3]],"batl":[[0,1.94,900.11],[1,1.96,751.3],[2,1000,0.02]],"ltp":1.87,"tv":4066.58,"id":6596286}]}]}
{"op":"mcm","clk":"1003918316","pt":1580616137154,"mc":[{"id":"1.168237330","rc":[{"batb":[[0,1.5,83.3],[1,1.36,60.58],[2,1.35,9.75]],"batl":[[0,1000,0.02],[1,1.96,0],[2,1000,0]],"ltp":1.87,"tv":4066.58,"id":6596286}]}]}
{"op":"mcm","clk":"1003918406","pt":1580616139677,"mc":[{"id":"1.168237330","rc":[{"batb":[[2,1.01,13.21]],"ltp":1.87,"tv":4066.58,"id":6596286}]}]}
{"op":"mcm","clk":"1003918505","pt":1580616142045,"mc":[{"id":"1.168237330","rc":[{"batb":[[0,1.75,737.31],[1,1.73,1102.42],[2,1.5,83.3]],"batl":[[0,2.08,783.04],[1,2.1,613.26],[2,1000,0.02]],"ltp":1.87,"tv":4066.58,"id":6596286}]}]}
{"op":"mcm","clk":"1003918753","pt":1580616148061,"mc":[{"id":"1.168237330","rc":[{"batb":[[0,1.5,83.3],[1,1.4,9.75],[2,1.36,60.58]],"batl":[[0,1000,0.02],[1,2.1,0],[2,1000,0]],"ltp":1.87,"tv":4066.58,"id":6596286}]}]}
{"op":"mcm","clk":"1003918967","pt":1580616152976,"mc":[{"id":"1.168237330","rc":[{"batb":[[0,1.84,915.69],[1,1.82,931.9],[2,1.5,83.3]],"batl":[[0,1.91,808.91],[1,1.93,787.32],[2,1000,0.02]],"ltp":1.87,"tv":4066.58,"id":6596286}]}]}
{"op":"mcm","clk":"1003918976","pt":1580616153181,"mc":[{"id":"1.168237330","rc":[{"batb":[[0,1.5,83.3],[1,1.4,9.75],[2,1.36,60.58]],"batl":[[0,1000,0.02],[1,1.93,0],[2,1000,0]],"ltp":1.87,"tv":4066.58,"id":6596286}]}]}
{"op":"mcm","clk":"1003919101","pt":1580616155971,"mc":[{"id":"1.168237330","rc":[{"batb":[[0,1.75,737.31],[1,1.73,1102.42],[2,1.5,83.3]],"batl":[[0,2.08,783.04],[1,2.1,613.26],[2,1000,0.02]],"ltp":1.87,"tv":4066.58,"id":6596286}]}]}
{"op":"mcm","clk":"1003919402","pt":1580616162685,"mc":[{"id":"1.168237330","rc":[{"batb":[[0,1.5,83.3],[1,1.4,9.75],[2,1.36,60.58]],"batl":[[0,1000,0.02],[1,2.1,0],[2,1000,0]],"ltp":1.87,"tv":4066.58,"id":6596286}]}]}
{"op":"mcm","clk":"1003919589","pt":1580616167604,"mc":[{"id":"1.168237330","rc":[{"batb":[[0,1.93,684.3],[1,1.91,798.78],[2,1.6,83.3]],"batl":[[0,2,692.26],[1,2.02,686.77],[2,1000,0.02]],"ltp":2.06,"tv":1488.81,"id":8196374}]}]}
{"op":"mcm","clk":"1003919852","pt":1580616175536,"mc":[{"id":"1.168237330","rc":[{"batb":[[2,1.49,45.43]],"ltp":2.06,"tv":1488.81,"id":8196374}]}]}
{"op":"mcm","clk":"1003919919","pt":1580616177698,"mc":[{"id":"1.168237330","rc":[{"batb":[[0,1.49,45.43],[1,1.4,45.43],[2,1.38,2.63]],"batl":[[0,1000,0.02],[1,2.02,0],[2,1000,0]],"ltp":2.06,"tv":1488.81,"id":8196374}]}]}
{"op":"mcm","clk":"1003920021","pt":1580616180639,"mc":[{"id":"1.168237330","rc":[{"batb":[[0,1.55,83.3],[1,1.49,45.43],[2,1.4,45.43]],"ltp":2.06,"tv":1488.81,"id":8196374}]}]}
{"op":"mcm","clk":"1003920125","pt":1580616182915,"mc":[{"id":"1.168237330","rc":[{"batb":[[0,1.81,833.2],[1,1.79,983.73],[2,1.55,83.3]],"batl":[[0,2.16,745.75],[1,2.18,551.3],[2,1000,0.02]],"ltp":2.06,"tv":1488.81,"id":8196374}]}]}
{"op":"mcm","clk":"1003920378","pt":1580616188829,"mc":[{"id":"1.168237330","rc":[{"batb":[[0,1.55,83.3],[1,1.49,45.43],[2,1.4,45.43]],"batl":[[0,1000,0.02],[1,2.18,0],[2,1000,0]],"ltp":2.06,"tv":1488.81,"id":8196374}]}]}
{"op":"mcm","clk":"1003920537","pt":1580616192443,"mc":[{"id":"1.168237330","rc":[{"batl":[[0,1.93,3.03],[1,1000,0.02]],"ltp":2.06,"tv":1488.81,"id":8196374}]}]}
{"op":"mcm","clk":"1003920631","pt":1580616194458,"mc":[{"id":"1.168237330","rc":[{"trd":[[1.93,6.06]],"batl":[[0,1000,0.02],[1,1000,0]],"ltp":1.93,"tv":1494.86,"id":8196374}],"tv":5561.45}]}
{"op":"mcm","clk":"1003920719","pt":1580616196669,"mc":[{"id":"1.168237330","rc":[{"batb":[[0,1.81,833.2],[1,1.79,983.73],[2,1.55,83.3]],"batl":[[0,2.16,745.75],[1,2.18,551.3],[2,1000,0.02]],"ltp":1.93,"tv":1494.86,"id":8196374}]}]}
{"op":"mcm","clk":"1003921150","pt":1580616209393,"mc":[{"id":"1.168237330","rc":[{"batb":[[0,1.55,83.3],[1,1.49,45.43],[2,1.4,45.43]],"batl":[[0,1000,0.02],[1,2.18,0],[2,1000,0]],"ltp":1.93,"tv":1494.86,"id":8196374}]}]}
{"op":"mcm","clk":"1003921283","pt":1580616213142,"mc":[{"id":"1.168237330","rc":[{"batl":[[0,100,2.27],[1,1000,0.02]],"ltp":1.93,"tv":1494.86,"id":8196374}]}]}
{"op":"mcm","clk":"1003921317","pt":1580616214269,"mc":[{"id":"1.168237330","rc":[{"batb":[[0,1.86,959.97],[1,1.84,899.57],[2,1.5,83.3]],"batl":[[0,1.93,683.61],[1,1.95,763.2],[2,1000,0.02]],"ltp":1.87,"tv":4066.58,"id":6596286}]}]}
{"op":"mcm","clk":"1003921593","pt":1580616224489,"mc":[{"id":"1.168237330","rc":[{"batb":[[0,1.5,83.3],[1,1.4,9.75],[2,1.36,60.58]],"batl":[[0,1000,0.02],[1,1.95,0],[2,1000,0]],"ltp":1.87,"tv":4066.58,"id":6596286}]}]}
{"op":"mcm","clk":"1003921693","pt":1580616228387,"mc":[{"id":"1.168237330","rc":[{"batl":[[0,100,2.65]],"ltp":1.93,"tv":1494.86,"id":8196374}]}]}
{"op":"mcm","clk":"1003921722","pt":1580616229367,"mc":[{"id":"1.168237330","rc":[{"batb":[[0,1.72,756.52],[1,1.7,1170.6],[2,1.5,83.3]],"batl":[[0,2.12,997.25],[1,2.14,581.15],[2,1000,0.02]],"ltp":1.87,"tv":4066.58,"id":6596286}]}]}
{"op":"mcm","clk":"1003921753","pt":1580616230905,"mc":[{"id":"1.168237330","rc":[{"batl":[[0,1.86,28.02],[1,2.12,997.25],[2,2.14,581.15]],"ltp":1.87,"tv":4066.58,"id":6596286}]}]}
{"op":"mcm","clk":"1003921802","pt":1580616233365,"mc":[{"id":"1.168237330","rc":[{"batl":[[0,2.12,997.25],[1,2.14,581.15],[2,1000,0.02]],"ltp":1.87,"tv":4066.58,"id":6596286}]}]}
{"op":"mcm","clk":"1003922239","pt":1580616245190,"mc":[{"id":"1.168237330","rc":[{"batb":[[0,1.49,45.43],[1,1.4,45.43],[2,1.38,2.63]],"ltp":1.93,"tv":1494.86,"id":8196374}]}]}
{"op":"mcm","clk":"1003922280","pt":1580616246012,"mc":[{"id":"1.168237330","rc":[{"batl":[[0,100,2.27]],"ltp":1.93,"tv":1494.86,"id":8196374}]}]}
{"op":"mcm","clk":"1003922344","pt":1580616247510,"mc":[{"id":"1.168237330","rc":[{"batb":[[0,1.5,83.3],[1,1.4,9.75],[2,1.36,60.58]],"batl":[[0,1000,0.02],[1,2.14,0],[2,1000,0]],"ltp":1.87,"tv":4066.58,"id":6596286}]}]}
{"op":"mcm","clk":"1003922469","pt":1580616250308,"mc":[{"id":"1.168237330","rc":[{"batb":[[0,1.6,83.3],[1,1.49,45.43],[2,1.4,45.43]],"ltp":1.93,"tv":1494.86,"id":8196374}]}]}
{"op":"mcm","clk":"1003922504","pt":1580616251130,"mc":[{"id":"1.168237330","rc":[{"batl":[[0,100,2.65]],"ltp":1.93,"tv":1494.86,"id":8196374}]}]}
{"op":"mcm","clk":"1003922575","pt":1580616252718,"mc":[{"id":"1.168237330","rc":[{"trd":[[2.42,0.27]],"ltp":2.42,"tv":4066.85,"id":6596286},{"trd":[[1.7,0.38]],"batl":[[0,100,2.27]],"ltp":1.7,"tv":1495.24,"id":8196374}],"tv":5562.1}]}
{"op":"mcm","clk":"1003922681","pt":1580616255642,"mc":[{"id":"1.168237330","rc":[{"batb":[[0,1.72,756.52],[1,1.7,1170.6],[2,1.5,83.3]],"batl":[[0,2.12,997.25],[1,2.14,581.15],[2,1000,0.02]],"ltp":2.42,"tv":4066.85,"id":6596286}]}]}
{"op":"mcm","clk":"1003923076","pt":1580616266220,"mc":[{"id":"1.168237330","rc":[{"trd":[[2.12,0.44]],"batl":[[0,2.12,997.03]],"ltp":2.12,"tv":4067.29,"id":6596286}],"tv":5562.54}]}
{"op":"mcm","clk":"1003923203","pt":1580616269663,"mc":[{"id":"1.168237330","rc":[{"batl":[[0,1000,0.02],[1,2.14,0],[2,1000,0]],"ltp":2.12,"tv":4067.29,"id":6596286}]}]}
{"op":"mcm","clk":"1003923376","pt":1580616274554,"mc":[{"id":"1.168237330","rc":[{"batl":[[0,1.78,1080.82],[1,1.8,978.51],[2,1000,0.02]],"ltp":2.12,"tv":4067.29,"id":6596286}]}]}
{"op":"mcm","clk":"1003923484","pt":1580616277738,"mc":[{"id":"1.168237330","rc":[{"batl":[[0,1000,0.02],[1,1000,0]],"ltp":1.7,"tv":1495.24,"id":8196374}]}]}
{"op":"mcm","clk":"1003923550","pt":1580616279635,"mc":[{"id":"1.168237330","rc":[{"trd":[[1.72,273.8]],"batb":[[0,1.72,665.54]],"ltp":1.72,"tv":4249.25,"id":6596286}],"tv":5744.5}]}
{"op":"mcm","clk":"1003923570","pt":1580616280149,"mc":[{"id":"1.168237330","rc":[{"batl":[[0,1000,0.02],[1,1.8,0],[2,1000,0]],"ltp":1.72,"tv":4249.25,"id":6596286}]}]}
{"op":"mcm","clk":"1003923659","pt":1580616282873,"mc":[{"id":"1.168237330","rc":[{"trd":[[2.68,0.22]],"ltp":2.68,"tv":4249.47,"id":6596286},{"trd":[[1.6,0.36]],"batb":[[0,1.6,82.93]],"ltp":1.6,"tv":1495.61,"id":8196374}],"tv":5745.08}]}
{"op":"mcm","clk":"1003923717","pt":1580616284569,"mc":[{"id":"1.168237330","rc":[{"batb":[[0,1.4,9.75],[1,1.36,60.58],[2,1.01,13.21]],"ltp":2.68,"tv":4249.47,"id":6596286}]}]}
{"op":"mcm","clk":"1003923772","pt":1580616285963,"mc":[{"id":"1.168237330","rc":[{"batl":[[0,1.72,28.02],[1,1000,0.02]],"ltp":2.68,"tv":4249.47,"id":6596286}]}]}
{"op":"mcm","clk":"1003923823","pt":1580616287665,"mc":[{"id":"1.168237330","rc":[{"batl":[[0,1000,0.02],[1,1000,0]],"ltp":2.68,"tv":4249.47,"id":6596286}]}]}
{"op":"mcm","clk":"1003923890","pt":1580616289262,"mc":[{"id":"1.168237330","rc":[{"batb":[[0,1.41,83.3],[1,1.4,9.75],[2,1.36,60.58]],"ltp":2.68,"tv":4249.47,"id":6596286}]}]}
{"op":"mcm","clk":"1003923930","pt":1580616290082,"mc":[{"id":"1.168237330","rc":[{"batb":[[0,1.59,1113.69],[1,1.58,768.3],[2,1.41,83.3]],"batl":[[0,1.93,833.52],[1,1.95,763.24],[2,1000,0.02]],"ltp":2.68,"tv":4249.47,"id":6596286}]}]}
{"op":"mcm","clk":"1003924249","pt":1580616299290,"mc":[{"id":"1.168237330","rc":[{"trd":[[1.93,5.22]],"batl":[[0,1.93,832.59]],"ltp":1.93,"tv":4251.33,"id":6596286}],"tv":5746.94}]}
{"op":"mcm","clk":"1003924335","pt":1580616301500,"mc":[{"id":"1.168237330","rc":[{"batb":[[0,1.41,83.3],[1,1.4,9.75],[2,1.36,60.58]],"batl":[[0,1000,0.02],[1,1.95,0],[2,1000,0]],"ltp":1.93,"tv":4251.33,"id":6596286}]}]}
{"op":"mcm","clk":"1003924612","pt":1580616309517,"mc":[{"id":"1.168237330","rc":[{"batb":[[0,1.59,1114.83],[1,1.58,768.3],[2,1.41,83.3]],"batl":[[0,1.93,832.59],[1,1.95,763.24],[2,1000,0.02]],"ltp":1.93,"tv":4251.33,"id":6596286}]}]}
{"op":"mcm","clk":"1003925231","pt":1580616326916,"mc":[{"id":"1.168237330","rc":[{"batb":[[0,1.41,83.3],[1,1.4,9.75],[2,1.36,60.58]],"ltp":1.93,"tv":4251.33,"id":6596286}]}]}
{"op":"mcm","clk":"1003925384","pt":1580616331862,"mc":[{"id":"1.168237330","rc":[{"batb":[[0,1.86,805.43],[1,1.84,899.55],[2,1.41,83.3]],"ltp":1.93,"tv":4251.33,"id":6596286}]}]}
{"op":"mcm","clk":"1003925754","pt":1580616341836,"mc":[{"id":"1.168237330","rc":[{"batb":[[0,1.41,83.3],[1,1.4,9.75],[2,1.36,60.58]],"batl":[[0,1000,0.02],[1,1.95,0],[2,1000,0]],"ltp":1.93,"tv":4251.33,"id":6596286}]}]}
{"op":"mcm","clk":"1003925943","pt":1580616347170,"mc":[{"id":"1.168237330","rc":[{"batb":[[0,1.71,1169.28],[1,1.69,1196.99],[2,1.41,83.3]],"batl":[[0,2.1,539.47],[1,2.12,596.73],[2,1000,0.02]],"ltp":1.93,"tv":4251.33,"id":6596286}]}]}
{"op":"mcm","clk":"1003926082","pt":1580616350833,"mc":[{"id":"1.168237330","rc":[{"batl":[[0,1.86,28.02],[1,2.1,539.47],[2,2.12,596.73]],"ltp":1.93,"tv":4251.33,"id":6596286}]}]}
{"op":"mcm","clk":"1003926139","pt":1580616352476,"mc":[{"id":"1.168237330","rc":[{"batl":[[0,2.1,539.47],[1,2.12,596.73],[2,1000,0.02]],"ltp":1.93,"tv":4251.33,"id":6596286}]}]}
{"op":"mcm","clk":"1003926627","pt":1580616365659,"mc":[{"id":"1.168237330","rc":[{"batb":[[0,1.41,83.3],[1,1.4,9.75],[2,1.36,60.58]],"batl":[[0,1000,0.02],[1,2.12,0],[2,1000,0]],"ltp":1.93,"tv":4251.33,"id":6596286}]}]}
{"op":"mcm","clk":"1003926792","pt":1580616370584,"mc":[{"id":"1.168237330","rc":[{"batb":[[0,1.91,556.41],[1,1.89,825.61],[2,1.6,82.93]],"batl":[[0,1.98,883.98],[1,2,707.32],[2,1000,0.02]],"ltp":1.6,"tv":1495.61,"id":8196374}]}]}
{"op":"mcm","clk":"1003926904","pt":1580616373806,"mc":[{"id":"1.168237330","rc":[{"trd":[[2.02,30]],"ltp":2.02,"tv":4281.33,"id":6596286},{"trd":[[1.98,30.61]],"batl":[[0,1.98,853.37]],"ltp":1.98,"tv":1526.22,"id":8196374}],"tv":5807.55}]}
{"op":"mcm","clk":"1003927148","pt":1580616380796,"mc":[{"id":"1.168237330","rc":[{"batb":[[0,1.6,82.93],[1,1.49,45.43],[2,1.4,45.43]],"batl":[[0,1000,0.02],[1,2,0],[2,1000,0]],"ltp":1.98,"tv":1526.22,"id":8196374}]}]}
{"op":"mcm","clk":"1003927354","pt":1580616385731,"mc":[{"id":"1.168237330","rc":[{"batb":[[0,1.76,1094.71],[1,1.74,1082.1],[2,1.6,82.93]],"batl":[[0,2.18,1025.03],[1,2.2,537.75],[2,1000,0.02]],"ltp":1.98,"tv":1526.22,"id":8196374}]}]}
{"op":"mcm","clk":"1003927563","pt":1580616391213,"mc":[{"id":"1.168237330","rc":[{"batb":[[0,1.6,82.93],[1,1.49,45.43],[2,1.4,45.43]],"batl":[[0,1000,0.02],[1,2.2,0],[2,1000,0]],"ltp":1.98,"tv":1526.22,"id":8196374}]}]}
{"op":"mcm","clk":"1003927735","pt":1580616396094,"mc":[{"id":"1.168237330","rc":[{"batb":[[0,1.86,646.01],[1,1.84,899.34],[2,1.41,83.3]],"batl":[[0,1.92,596.74],[1,1.94,775.51],[2,1000,0.02]],"ltp":2.02,"tv":4281.33,"id":6596286}]}]}
{"op":"mcm","clk":"1003928187","pt":1580616406236,"mc":[{"id":"1.168237330","rc":[{"batb":[[0,1.41,83.3],[1,1.4,9.75],[2,1.36,60.58]],"batl":[[0,1000,0.02],[1,1.94,0],[2,1000,0]],"ltp":2.02,"tv":4281.33,"id":6596286}]}]}
{"op":"mcm","clk":"1003928302","pt":1580616408548,"mc":[{"id":"1.168237330","rc":[{"batl":[[0,1.86,75.72],[1,1000,0.02]],"ltp":2.02,"tv":4281.33,"id":6596286}]}]}
{"op":"mcm","clk":"1003928425","pt":1580616411224,"mc":[{"id":"1.168237330","rc":[{"batb":[[0,1.71,997.77],[1,1.69,1196.31],[2,1.41,83.3]],"batl":[[1,2.1,675.44],[2,2.12,596.82]],"ltp":2.02,"tv":4281.33,"id":6596286}]}]}
{"op":"mcm","clk":"1003928590","pt":1580616415027,"mc":[{"id":"1.168237330","rc":[{"batl":[[0,2.1,675.44],[1,2.12,596.82],[2,1000,0.02]],"ltp":2.02,"tv":4281.33,"id":6596286}]}]}
{"op":"mcm","clk":"1003928671","pt":1580616416765,"mc":[{"id":"1.168237330","rc":[{"batl":[[0,1000,0.02],[1,2.12,0],[2,1000,0]],"ltp":2.02,"tv":4281.33,"id":6596286}]}]}
{"op":"mcm","clk":"1003928836","pt":1580616420165,"mc":[{"id":"1.168237330","rc":[{"batl":[[0,1.84,75.72],[1,1000,0.02]],"ltp":2.02,"tv":4281.33,"id":6596286}]}]}
{"op":"mcm","clk":"1003928899","pt":1580616421659,"mc":[{"id":"1.168237330","rc":[{"batl":[[0,1.77,905.33],[1,1.79,997.31],[2,1.84,75.72]],"ltp":2.02,"tv":4281.33,"id":6596286}]}]}
{"op":"mcm","clk":"1003929368","pt":1580616430686,"mc":[{"id":"1.168237330","rc":[{"batl":[[2,1000,0.02]],"ltp":2.02,"tv":4281.33,"id":6596286}]}]}
{"op":"mcm","clk":"1003929431","pt":1580616431768,"mc":[{"id":"1.168237330","rc":[{"batb":[[0,1.41,83.3],[1,1.4,9.75],[2,1.36,60.58]],"batl":[[0,1000,0.02],[1,1.79,0],[2,1000,0]],"ltp":2.02,"tv":4281.33,"id":6596286}]}]}
{"op":"mcm","clk":"1003929642","pt":1580616435783,"mc":[{"id":"1.168237330","rc":[{"batl":[[0,1.71,75.72],[1,1000,0.02]],"ltp":2.02,"tv":4281.33,"id":6596286}]}]}
{"op":"mcm","clk":"1003929691","pt":1580616436663,"mc":[{"id":"1.168237330","rc":[{"batb":[[0,1.59,855.27],[1,1.58,767.29],[2,1.41,83.3]],"batl":[[1,1.92,662.39],[2,1.94,775.43]],"ltp":2.02,"tv":4281.33,"id":6596286}]}]}
{"op":"mcm","clk":"1003930291","pt":1580616451197,"mc":[{"id":"1.168237330","rc":[{"batl":[[1,1000,0.02],[2,1.94,0]],"ltp":2.02,"tv":4281.33,"id":6596286}]}]}
{"op":"mcm","clk":"1003930494","pt":1580616456116,"mc":[{"id":"1.168237330","rc":[{"batl":[[0,1.64,1194.38],[1,1.65,651.08],[2,1.71,75.72]],"ltp":2.02,"tv":4281.33,"id":6596286}]}]}
{"op":"mcm","clk":"1003930789","pt":1580616463515,"mc":[{"id":"1.168237330","rc":[{"batl":[[2,1000,0.02]],"ltp":2.02,"tv":4281.33,"id":6596286}]}]}
{"op":"mcm","clk":"1003930900","pt":1580616466292,"mc":[{"id":"1.168237330","rc":[{"batb":[[0,1.41,83.3],[1,1.4,9.75],[2,1.22,60.58]],"batl":[[0,1000,0.02],[1,1.65,0],[2,1000,0]],"ltp":2.02,"tv":4281.33,"id":6596286}]}]}
{"op":"mcm","clk":"1003931092","pt":1580616471115,"mc":[{"id":"1.168237330","rc":[{"batb":[[0,1.52,760.38],[1,1.51,914.05],[2,1.41,83.3]],"batl":[[0,1.73,692.6],[1,1.75,1074.77],[2,1000,0.02]],"ltp":2.02,"tv":4281.33,"id":6596286}]}]}
{"op":"mcm","clk":"1003931434","pt":1580616479440,"mc":[{"id":"1.168237330","rc":[{"batl":[[0,1.59,75.72],[1,1.73,692.6],[2,1.75,1074.77]],"ltp":2.02,"tv":4281.33,"id":6596286}]}]}
{"op":"mcm","clk":"1003931494","pt":1580616480625,"mc":[{"id":"1.168237330","rc":[{"batl":[[0,3,84.02],[1,1000,0.02]],"ltp":1.98,"tv":1526.22,"id":8196374}]}]}
{"op":"mcm","clk":"1003931787","pt":1580616487736,"mc":[{"id":"1.168237330","rc":[{"batl":[[0,1.73,692.6],[1,1.75,1074.77],[2,1000,0.02]],"ltp":2.02,"tv":4281.33,"id":6596286}]}]}
{"op":"mcm","clk":"1003932180","pt":1580616497540,"mc":[{"id":"1.168237330","rc":[{"batb":[[0,1.41,83.3],[1,1.4,9.75],[2,1.22,60.58]],"ltp":2.02,"tv":4281.33,"id":6596286}]}]}
{"op":"mcm","clk":"1003932296","pt":1580616500737,"mc":[{"id":"1.168237330","rc":[{"batb":[[1,1.5,84.02],[2,1.49,45.43]],"ltp":1.98,"tv":1526.22,"id":8196374}]}]}
{"op":"mcm","clk":"1003932376","pt":1580616502436,"mc":[{"id":"1.168237330","rc":[{"batb":[[0,1.68,831.94],[1,1.66,1273.21],[2,1.41,83.3]],"ltp":2.02,"tv":4281.33,"id":6596286}]}]}
{"op":"mcm","clk":"1003932648","pt":1580616508857,"mc":[{"id":"1.168237330","rc":[{"batb":[[0,1.73,147.03],[1,1.41,83.3],[2,1.4,9.75]],"batl":[[0,1000,0.02],[1,1.75,0],[2,1000,0]],"ltp":2.02,"tv":4281.33,"id":6596286}]}]}
{"op":"mcm","clk":"1003933127","pt":1580616519710,"mc":[{"id":"1.168237330","rc":[{"batb":[[1,1.59,1243.25],[2,1.58,768.89]],"batl":[[0,1.85,905.49],[1,1.87,867.94],[2,1000,0.02]],"ltp":2.02,"tv":4281.33,"id":6596286}]}]}
{"op":"mcm","clk":"1003933262","pt":1580616523211,"mc":[{"id":"1.168237330","rc":[{"batb":[[1,1.41,83.3],[2,1.4,9.75]],"ltp":2.02,"tv":4281.33,"id":6596286}]}]}
{"op":"mcm","clk":"1003933450","pt":1580616528097,"mc":[{"id":"1.168237330","rc":[{"batb":[[0,1.79,600.24],[1,1.77,1020.84],[2,1.73,147.03]],"ltp":2.02,"tv":4281.33,"id":6596286}]}]}
{"op":"mcm","clk":"1003933818","pt":1580616537027,"mc":[{"id":"1.168237330","rc":[{"batb":[[0,1.73,147.03],[1,1.4,9.75],[2,1.22,60.58]],"batl":[[0,1000,0.02],[1,1.87,0],[2,1000,0]],"ltp":2.02,"tv":4281.33,"id":6596286}]}]}
{"op":"mcm","clk":"1003933909","pt":1580616539089,"mc":[{"id":"1.168237330","rc":[{"batb":[[1,1.51,83.3],[2,1.4,9.75]],"ltp":2.02,"tv":4281.33,"id":6596286}]}]}
{"op":"mcm","clk":"1003934027","pt":1580616541874,"mc":[{"id":"1.168237330","rc":[{"batb":[[1,1.7,749.1],[2,1.68,1220.22]],"batl":[[0,1.96,684.77],[1,1.98,729.09],[2,1000,0.02]],"ltp":2.02,"tv":4281.33,"id":6596286}]}]}
{"op":"mcm","clk":"1003934532","pt":1580616552535,"mc":[{"id":"1.168237330","rc":[{"batl":[[0,1.94,37.86],[1,1.96,684.77],[2,1.98,729.09]],"ltp":2.02,"tv":4281.33,"id":6596286}]}]}
{"op":"mcm","clk":"1003934828","pt":1580616558448,"mc":[{"id":"1.168237330","rc":[{"trd":[[1.94,118.27],[1.96,41.7]],"batl":[[0,1.96,643.07],[1,1.98,729.09],[2,1000,0.02]],"ltp":1.96,"tv":4360.89,"id":6596286},{"trd":[[2.04,40.07],[2.06,111.38]],"ltp":2.04,"tv":1601.94,"id":8196374}],"tv":5962.84}]}
{"op":"mcm","clk":"1003934887","pt":1580616559737,"mc":[{"id":"1.168237330","rc":[{"batl":[[0,1000,0.02],[1,1.98,0],[2,1000,0]],"ltp":1.96,"tv":4360.89,"id":6596286}]}]}
{"op":"mcm","clk":"1003935126","pt":1580616564842,"mc":[{"id":"1.168237330","rc":[{"batb":[[1,1.7,797.33]],"batl":[[0,1.75,630.01],[1,1.77,1035.44],[2,1000,0.02]],"ltp":1.96,"tv":4360.89,"id":6596286}]}]}
{"op":"mcm","clk":"1003935396","pt":1580616570351,"mc":[{"id":"1.168237330","rc":[{"trd":[[1.73,0.3]],"batb":[[0,1.73,146.73]],"ltp":1.73,"tv":4361.2,"id":6596286},{"trd":[[2.38,101.89]],"ltp":2.38,"tv":1602.16,"id":8196374}],"tv":5963.36}]}
{"op":"mcm","clk":"1003935478","pt":1580616571946,"mc":[{"id":"1.168237330","rc":[{"trd":[[1.75,83.94]],"batl":[[0,1.75,588.04]],"ltp":1.75,"tv":4445.14,"id":6596286}],"tv":6047.3}]}
{"op":"mcm","clk":"1003935515","pt":1580616572822,"mc":[{"id":"1.168237330","rc":[{"batb":[[1,1.51,83.3],[2,1.4,9.75]],"batl":[[0,1000,0.02],[1,1.77,0],[2,1000,0]],"ltp":1.75,"tv":4445.14,"id":6596286}]}]}
{"op":"mcm","clk":"1003935724","pt":1580616577766,"mc":[{"id":"1.168237330","rc":[{"batb":[[1,1.6,909.68],[2,1.59,749.33]],"batl":[[0,1.89,710.66],[1,1.91,813.07],[2,1000,0.02]],"ltp":1.75,"tv":4445.14,"id":6596286}]}]}
{"op":"mcm","clk":"1003936063","pt":1580616585683,"mc":[{"id":"1.168237330","rc":[{"trd":[[1.73,6.1]],"batb":[[0,1.73,143.83]],"ltp":1.73,"tv":4450.94,"id":6596286}],"tv":6053.1}]}
{"op":"mcm","clk":"1003936110","pt":1580616586666,"mc":[{"id":"1.168237330","rc":[{"trd":[[1.73,6.4]],"batb":[[0,1.73,143.53]],"ltp":1.73,"tv":4451.24,"id":6596286},{"trd":[[2.38,102.11]],"ltp":2.38,"tv":1602.38,"id":8196374}],"tv":6053.62}]}
{"op":"mcm","clk":"1003936440","pt":1580616594355,"mc":[{"id":"1.168237330","rc":[{"batl":[[0,1000,0.02],[1,1.91,0],[2,1000,0]],"ltp":1.73,"tv":4451.24,"id":6596286}]}]}
{"op":"mcm","clk":"1003936641","pt":1580616599292,"mc":[{"id":"1.168237330","rc":[{"trd":[[1.73,293.46]],"batb":[[0,1.6,909.68],[1,1.59,749.33],[2,1.51,83.3]],"batl":[[0,1.65,930.8],[1,1.66,637.69],[2,1000,0.02]],"ltp":1.73,"tv":4738.3,"id":6596286}],"tv":6340.68}]}
{"op":"mcm","clk":"1003936764","pt":1580616601979,"mc":[{"id":"1.168237330","rc":[{"batl":[[2,1.71,37.86]],"ltp":1.73,"tv":4738.3,"id":6596286}]}]}
{"op":"mcm","clk":"1003936797","pt":1580616602810,"mc":[{"id":"1.168237330","rc":[{"trd":[[1.6,436.6]],"batb":[[0,1.6,909.31]],"batl":[[2,1000,0.02]],"ltp":1.6,"tv":4738.67,"id":6596286},{"trd":[[2.68,24.1]],"ltp":2.68,"tv":1602.6,"id":8196374}],"tv":6341.27}]}
{"op":"mcm","clk":"1003936876","pt":1580616604511,"mc":[{"id":"1.168237330","rc":[{"batb":[[0,1.6,1064.79]],"ltp":1.6,"tv":4738.67,"id":6596286}]}]}
{"op":"mcm","clk":"1003937028","pt":1580616608481,"mc":[{"id":"1.168237330","rc":[{"trd":[[1.65,217]],"batl":[[0,1.65,921.05]],"ltp":1.65,"tv":4758.17,"id":6596286}],"tv":6360.77}]}
{"op":"mcm","clk":"1003937074","pt":1580616609506,"mc":[{"id":"1.168237330","rc":[{"batb":[[0,1.51,83.3],[1,1.4,9.75],[2,1.22,60.58]],"batl":[[0,1000,0.02],[1,1.66,0],[2,1000,0]],"ltp":1.65,"tv":4758.17,"id":6596286}]}]}
{"op":"mcm","clk":"1003937165","pt":1580616611889,"mc":[{"id":"1.168237330","rc":[{"batb":[[0,1.4,9.75],[1,1.22,60.58],[2,1.01,13.21]],"ltp":1.65,"tv":4758.17,"id":6596286},{"batl":[[0,2.52,2],[1,3,84.02],[2,1000,0.02]],"ltp":2.68,"tv":1602.6,"id":8196374}]}]}
{"op":"mcm","clk":"1003937183","pt":1580616612290,"mc":[{"id":"1.168237330","rc":[{"batl":[[0,3,84.02],[1,1000,0.02],[2,1000,0]],"ltp":2.68,"tv":1602.6,"id":8196374}]}]}
{"op":"mcm","clk":"1003937237","pt":1580616613524,"mc":[{"id":"1.168237330","rc":[{"batb":[[0,1.22,60.58],[1,1.01,13.21],[2,1.01,0]],"ltp":1.65,"tv":4758.17,"id":6596286}]}]}
{"op":"mcm","clk":"1003937369","pt":1580616616516,"mc":[{"id":"1.168237330","rc":[{"batb":[[0,1.41,83.3],[1,1.22,60.58],[2,1.01,13.21]],"ltp":1.65,"tv":4758.17,"id":6596286}]}]}
{"op":"mcm","clk":"1003937941","pt":1580616629921,"mc":[{"id":"1.168237330","rc":[{"batb":[[0,1.5,970.15],[1,1.49,964.7],[2,1.41,83.3]],"batl":[[0,1.8,1043.95],[1,1.82,944.23],[2,1000,0.02]],"ltp":1.65,"tv":4758.17,"id":6596286}]}]}
{"op":"mcm","clk":"1003938253","pt":1580616636622,"mc":[{"id":"1.168237330","rc":[{"batb":[[0,1.41,83.3],[1,1.22,60.58],[2,1.01,13.21]],"ltp":1.65,"tv":4758.17,"id":6596286}]}]}
{"op":"mcm","clk":"1003938518","pt":1580616641517,"mc":[{"id":"1.168237330","rc":[{"batb":[[0,1.74,689.1],[1,1.72,1123.79],[2,1.41,83.3]],"ltp":1.65,"tv":4758.17,"id":6596286}]}]}
{"op":"mcm","clk":"1003938879","pt":1580616649639,"mc":[{"id":"1.168237330","rc":[{"batb":[[0,1.41,83.3],[1,1.22,60.58],[2,1.01,13.21]],"batl":[[0,1000,0.02],[1,1.82,0],[2,1000,0]],"ltp":1.65,"tv":4758.17,"id":6596286}]}]}
{"op":"mcm","clk":"1003939268","pt":1580616656472,"mc":[{"id":"1.168237330","rc":[{"batl":[[0,2.24,97.09],[1,3,84.02],[2,1000,0.02]],"ltp":2.68,"tv":1602.6,"id":8196374}]}]}
{"op":"mcm","clk":"1003939478","pt":1580616660455,"mc":[{"id":"1.168237330","rc":[{"batb":[[0,1.6,1281.11],[1,1.59,750.29],[2,1.41,83.3]],"batl":[[0,1.98,652.65],[1,2,707.2],[2,1000,0.02]],"ltp":1.65,"tv":4758.17,"id":6596286}]}]}
{"op":"mcm","clk":"1003939660","pt":1580616663965,"mc":[{"id":"1.168237330","rc":[{"batb":[[2,1.22,60.58]],"ltp":1.65,"tv":4758.17,"id":6596286}]}]}
{"op":"mcm","clk":"1003939832","pt":1580616667738,"mc":[{"id":"1.168237330","rc":[{"trd":[[1.8,2]],"batl":[[0,1000,0.02],[1,2,0],[2,1000,0]],"ltp":1.8,"tv":4760.17,"id":6596286},{"trd":[[2.24,1.61]],"batl":[[0,2.24,95.49]],"ltp":2.24,"tv":1604.2,"id":8196374}],"tv":6364.38}]}
{"op":"mcm","clk":"1003939907","pt":1580616669135,"mc":[{"id":"1.168237330","rc":[{"batb":[[2,1.51,83.3]],"ltp":1.8,"tv":4760.17,"id":6596286}]}]}
{"op":"mcm","clk":"1003940043","pt":1580616671935,"mc":[{"id":"1.168237330","rc":[{"trd":[[1.8,120.82]],"batl":[[0,1.65,599.46],[1,1.66,638.43],[2,1000,0.02]],"ltp":1.8,"tv":4878.99,"id":6596286},{"trd":[[2.24,97.09]],"batl":[[0,3,84.02],[1,1000,0.02],[2,1000,0]],"ltp":2.24,"tv":1699.69,"id":8196374}],"tv":6578.68}]}
{"op":"mcm","clk":"1003940061","pt":1580616672196,"mc":[{"id":"1.168237330","rc":[{"batb":[[0,1.6,730.31],[1,1.51,83.3],[2,1.22,60.58]],"batl":[[0,1.66,638.43],[1,1000,0.02],[2,1000,0]],"ltp":1.8,"tv":4878.99,"id":6596286}]}]}
{"op":"mcm","clk":"1003940303","pt":1580616677151,"mc":[{"id":"1.168237330","rc":[{"batb":[[0,1.61,680.52],[1,1.6,730.31],[2,1.51,83.3]],"batl":[[0,1.66,1223.97],[1,1.68,1228.25],[2,1000,0.02]],"ltp":1.8,"tv":4878.99,"id":6596286}]}]}
{"op":"mcm","clk":"1003940482","pt":1580616680732,"mc":[{"id":"1.168237330","rc":[{"trd":[[1.61,34]],"batb":[[0,1.51,83.3],[1,1.22,60.58],[2,1.01,13.21]],"batl":[[0,1000,0.02],[1,1.68,0],[2,1000,0]],"ltp":1.61,"tv":4912.99,"id":6596286}],"tv":6612.68}]}
{"op":"mcm","clk":"1003940637","pt":1580616684331,"mc":[{"id":"1.168237330","rc":[{"batl":[[0,2.5,28.77],[1,3,84.02],[2,1000,0.02]],"ltp":2.24,"tv":1699.69,"id":8196374}]}]}
{"op":"mcm","clk":"1003940706","pt":1580616685819,"mc":[{"id":"1.168237330","rc":[{"batb":[[1,1.5,1329.86],[2,1.49,966.43]],"ltp":1.61,"tv":4912.99,"id":6596286}]}]}
{"op":"mcm","clk":"1003940718","pt":1580616686129,"mc":[{"id":"1.168237330","rc":[{"batb":[[0,1.5,1329.86],[1,1.49,966.43],[2,1.22,60.58]],"ltp":1.61,"tv":4912.99,"id":6596286}]}]}
{"op":"mcm","clk":"1003940920","pt":1580616690446,"mc":[{"id":"1.168237330","rc":[{"trd":[[1.54,18.44],[1.66,55.4]],"batl":[[0,1.55,818.4],[1,1000,0.02]],"ltp":1.54,"tv":4974.77,"id":6596286},{"trd":[[2.5,118.22],[2.84,10]],"batl":[[0,3,84.02],[1,1000,0.02],[2,1000,0]],"ltp":2.84,"tv":1738.46,"id":8196374}],"tv":6713.24}]}
{"op":"mcm","clk":"1003940962","pt":1580616691273,"mc":[{"id":"1.168237330","rc":[{"batb":[[2,1.32,83.3]],"ltp":1.54,"tv":4974.77,"id":6596286}]}]}
{"op":"mcm","clk":"1003941202","pt":1580616695648,"mc":[{"id":"1.168237330","rc":[{"batb":[[0,1.5,1378.61]],"batl":[[0,1.55,1450.54],[1,1.56,794.38],[2,1000,0.02]],"ltp":1.54,"tv":4974.77,"id":6596286}]}]}
{"op":"mcm","clk":"1003941269","pt":1580616697042,"mc":[{"id":"1.168237330","rc":[{"batb":[[0,1.32,83.3],[1,1.22,60.58],[2,1.01,13.21]],"batl":[[0,1000,0.02],[1,1.56,0],[2,1000,0]],"ltp":1.54,"tv":4974.77,"id":6596286}]}]}
{"op":"mcm","clk":"1003941699","pt":1580616701982,"mc":[{"id":"1.168237330","rc":[{"batb":[[0,1.42,1282.95],[1,1.41,1222.46],[2,1.32,83.3]],"batl":[[0,1.66,929.86],[1,1.68,1229.86],[2,1000,0.02]],"ltp":1.54,"tv":4974.77,"id":6596286}]}]}
{"op":"mcm","clk":"1003941812","pt":1580616703376,"mc":[{"id":"1.168237330","rc":[{"batl":[[0,1000,0.02],[1,1.68,0],[2,1000,0]],"ltp":1.54,"tv":4974.77,"id":6596286}]}]}
{"op":"mcm","clk":"1003941991","pt":1580616705795,"mc":[{"id":"1.168237330","rc":[{"batb":[[1,1.53,22.72],[2,1.5,84.02]],"ltp":2.84,"tv":1738.46,"id":8196374}]}]}
{"op":"mcm","clk":"1003942117","pt":1580616708288,"mc":[{"id":"1.168237330","rc":[{"trd":[[1.5,937.06]],"batl":[[0,1.46,1309.3],[1,1.47,1001.06],[2,1000,0.02]],"ltp":1.5,"tv":5142.81,"id":6596286},{"trd":[[3,84.13]],"batl":[[0,1000,0.02],[1,1000,0]],"ltp":3.0,"tv":1822.48,"id":8196374}],"tv":6965.3}]}
{"op":"mcm","clk":"1003942461","pt":1580616713493,"mc":[{"id":"1.168237330","rc":[{"batb":[[0,1.42,1460.7]],"batl":[[2,2.62,37.86]],"ltp":1.5,"tv":5142.81,"id":6596286}]}]}
{"op":"mcm","clk":"1003942588","pt":1580616715912,"mc":[{"id":"1.168237330","rc":[{"trd":[[1.46,27.48]],"batl":[[0,1.46,1299.55]],"ltp":1.46,"tv":5162.31,"id":6596286}],"tv":6984.8}]}
{"op":"mcm","clk":"1003942731","pt":1580616718386,"mc":[{"id":"1.168237330","rc":[{"trd":[[1.46,34.12]],"batl":[[0,1.46,1296.23]],"ltp":1.46,"tv":5168.95,"id":6596286}],"tv":6991.44}]}
{"op":"mcm","clk":"1003943344","pt":1580616729840,"mc":[{"id":"1.168237330","rc":[{"batb":[[0,1.53,22.72],[1,1.5,84.02],[2,1.49,45.43]],"ltp":3.0,"tv":1822.48,"id":8196374}]}]}
{"op":"mcm","clk":"1003943546","pt":1580616734945,"mc":[{"id":"1.168237330","rc":[{"batb":[[0,2.08,82.93],[1,1.53,22.72],[2,1.5,84.02]],"ltp":3.0,"tv":1822.48,"id":8196374}]}]}
{"op":"mcm","clk":"1003944208","pt":1580616747780,"mc":[{"id":"1.168237330","rc":[{"batb":[[2,1.22,60.58]],"ltp":1.46,"tv":5168.95,"id":6596286}]}]}
{"op":"mcm","clk":"1003944439","pt":1580616752878,"mc":[{"id":"1.168237330","rc":[{"batb":[[2,1.25,83.3]],"ltp":1.46,"tv":5168.95,"id":6596286}]}]}
{"op":"mcm","clk":"1003944955","pt":1580616763980,"mc":[{"id":"1.168237330","rc":[{"trd":[[1.46,39.02]],"batl":[[0,1.46,1291.33]],"ltp":1.46,"tv":5173.85,"id":6596286},{"trd":[[3.15,2.27]],"ltp":3.15,"tv":1824.75,"id":8196374}],"tv":6998.61}]}
{"op":"mcm","clk":"1003945172","pt":1580616768873,"mc":[{"id":"1.168237330","rc":[{"batb":[[0,1.53,22.72],[1,1.5,84.02],[2,1.49,45.43]],"ltp":3.15,"tv":1824.75,"id":8196374}]}]}
{"op":"mcm","clk":"1003945358","pt":1580616772793,"mc":[{"id":"1.168237330","rc":[{"trd":[[1.46,46.26]],"batl":[[0,1.46,1287.71]],"ltp":1.46,"tv":5181.09,"id":6596286}],"tv":7005.85}]}
{"op":"mcm","clk":"1003945420","pt":1580616774025,"mc":[{"id":"1.168237330","rc":[{"batb":[[0,2.14,82.93],[1,1.53,22.72],[2,1.5,84.02]],"ltp":3.15,"tv":1824.75,"id":8196374}]}]}
{"op":"mcm","clk":"1003945855","pt":1580616783429,"mc":[{"id":"1.168237330","rc":[{"batb":[[0,1.25,83.3],[1,1.22,60.58],[2,1.01,13.21]],"batl":[[0,2.62,37.86],[1,1000,0.02],[2,2.62,0]],"ltp":1.46,"tv":5181.09,"id":6596286}]}]}
{"op":"mcm","clk":"1003946067","pt":1580616788543,"mc":[{"id":"1.168237330","rc":[{"batb":[[0,1.36,2072.3],[1,1.35,1506.17],[2,1.25,83.3]],"batl":[[0,1.53,1399.66],[1,1.54,832.97],[2,2.62,37.86]],"ltp":1.46,"tv":5181.09,"id":6596286}]}]}
{"op":"mcm","clk":"1003947073","pt":1580616814708,"mc":[{"id":"1.168237330","rc":[{"batl":[[0,2.62,37.86],[1,1000,0.02],[2,2.62,0]],"ltp":1.46,"tv":5181.09,"id":6596286}]}]}
{"op":"mcm","clk":"1003947269","pt":1580616819592,"mc":[{"id":"1.168237330","rc":[{"batl":[[0,1.4,1553.7],[1,1.41,1191.03],[2,2.62,37.86]],"ltp":1.46,"tv":5181.09,"id":6596286}]}]}
{"op":"mcm","clk":"1003947687","pt":1580616829688,"mc":[{"id":"1.168237330","rc":[{"batb":[[0,1.25,83.3],[1,1.22,60.58],[2,1.01,13.21]],"batl":[[0,2.62,37.86],[1,1000,0.02],[2,2.62,0]],"ltp":1.46,"tv":5181.09,"id":6596286}]}]}
{"op":"mcm","clk":"1003947729","pt":1580616830620,"mc":[{"id":"1.168237330","rc":[{"batb":[[0,1.53,22.72],[1,1.5,84.02],[2,1.49,45.43]],"ltp":3.15,"tv":1824.75,"id":8196374}]}]}
{"op":"mcm","clk":"1003947945","pt":1580616834724,"mc":[{"id":"1.168237330","rc":[{"batb":[[0,1.31,2155.79],[1,1.3,1829.63],[2,1.25,83.3]],"batl":[[0,1.46,1261.13],[1,1.47,1001.3],[2,2.62,37.86]],"ltp":1.46,"tv":5181.09,"id":6596286}]}]}
{"op":"mcm","clk":"1003947998","pt":1580616835715,"mc":[{"id":"1.168237330","rc":[{"batb":[[0,2.26,82.93],[1,1.53,22.72],[2,1.5,84.02]],"ltp":3.15,"tv":1824.75,"id":8196374}]}]}
{"op":"mcm","clk":"1003948427","pt":1580616842909,"mc":[{"id":"1.168237330","rc":[{"batb":[[0,1.25,83.3],[1,1.22,60.58],[2,1.01,13.21]],"batl":[[0,2.62,37.86],[1,1000,0.02],[2,2.62,0]],"ltp":1.46,"tv":5181.09,"id":6596286}]}]}
{"op":"mcm","clk":"1003948738","pt":1580616847867,"mc":[{"id":"1.168237330","rc":[{"batb":[[0,1.35,2040.23],[1,1.34,1562.18],[2,1.25,83.3]],"batl":[[0,1.39,1748.8],[1,1.4,1226.8],[2,2.62,37.86]],"ltp":1.46,"tv":5181.09,"id":6596286}]}]}
{"op":"mcm","clk":"1003948747","pt":1580616848072,"mc":[{"id":"1.168237330","rc":[{"batb":[[0,1.25,83.3],[1,1.22,60.58],[2,1.01,13.21]],"batl":[[0,2.62,37.86],[1,1000,0.02],[2,2.62,0]],"ltp":1.46,"tv":5181.09,"id":6596286}]}]}
{"op":"mcm","clk":"1003948925","pt":1580616850831,"mc":[{"id":"1.168237330","rc":[{"batb":[[0,1.31,2155.79],[1,1.3,1829.63],[2,1.25,83.3]],"batl":[[0,1.46,1261.13],[1,1.47,1001.3],[2,2.62,37.86]],"ltp":1.46,"tv":5181.09,"id":6596286}]}]}
{"op":"mcm","clk":"1003949529","pt":1580616861379,"mc":[{"id":"1.168237330","rc":[{"batb":[[2,1.22,60.58]],"ltp":1.46,"tv":5181.09,"id":6596286}]}]}
{"op":"mcm","clk":"1003949867","pt":1580616866473,"mc":[{"id":"1.168237330","rc":[{"batb":[[2,1.23,83.3]],"ltp":1.46,"tv":5181.09,"id":6596286}]}]}
{"op":"mcm","clk":"1003949979","pt":1580616868589,"mc":[{"id":"1.168237330","rc":[{"batb":[[0,1.23,83.3],[1,1.22,60.58],[2,1.01,13.21]],"ltp":1.46,"tv":5181.09,"id":6596286}]}]}
{"op":"mcm","clk":"1003950324","pt":1580616873572,"mc":[{"id":"1.168237330","rc":[{"batb":[[0,1.42,1506.52],[1,1.41,1222.86],[2,1.23,83.3]],"ltp":1.46,"tv":5181.09,"id":6596286}]}]}
{"op":"mcm","clk":"1003951024","pt":1580616883564,"mc":[{"id":"1.168237330","rc":[{"batb":[[0,1.23,83.3],[1,1.22,60.58],[2,1.01,13.21]],"batl":[[0,2.62,37.86],[1,1000,0.02],[2,2.62,0]],"ltp":1.46,"tv":5181.09,"id":6596286}]}]}
{"op":"mcm","clk":"1003951429","pt":1580616888857,"mc":[{"id":"1.168237330","rc":[{"batb":[[0,1.36,989.57],[1,1.35,1491.94],[2,1.23,83.3]],"batl":[[0,1.54,1373.86],[1,1.55,812.98],[2,2.62,37.86]],"ltp":1.46,"tv":5181.09,"id":6596286}]}]}
{"op":"mcm","clk":"1003951824","pt":1580616893960,"mc":[{"id":"1.168237330","rc":[{"batb":[[0,1.46,8.74],[1,1.36,989.57],[2,1.35,1491.94]],"ltp":1.46,"tv":5181.09,"id":6596286}]}]}
{"op":"mcm","clk":"1003952650","pt":1580616905597,"mc":[{"id":"1.168237330","rc":[{"batb":[[1,1.23,83.3],[2,1.22,60.58]],"ltp":1.46,"tv":5181.09,"id":6596286}]}]}
{"op":"mcm","clk":"1003952996","pt":1580616910595,"mc":[{"id":"1.168237330","rc":[{"batb":[[0,1.49,1542.04],[1,1.48,993.4],[2,1.46,8.74]],"ltp":1.46,"tv":5181.09,"id":6596286}]}]}
{"op":"mcm","clk":"1003953327","pt":1580616916128,"mc":[{"id":"1.168237330","rc":[{"trd":[[1.49,4.54]],"batb":[[0,1.49,1539.77]],"ltp":1.49,"tv":5185.63,"id":6596286}],"tv":7010.39}]}
{"op":"mcm","clk":"1003953661","pt":1580616920737,"mc":[{"id":"1.168237330","rc":[{"batb":[[0,1.46,8.74],[1,1.23,83.3],[2,1.22,60.58]],"batl":[[0,2.62,37.86],[1,1000,0.02],[2,2.62,0]],"ltp":1.49,"tv":5185.63,"id":6596286}]}]}
{"op":"mcm","clk":"1003953993","pt":1580616925628,"mc":[{"id":"1.168237330","rc":[{"batb":[[1,1.42,1444.91],[2,1.41,1222.29]],"batl":[[0,1.62,913.17],[1,1.63,678.57],[2,2.62,37.86]],"ltp":1.49,"tv":5185.63,"id":6596286}]}]}
{"op":"mcm","clk":"1003954217","pt":1580616929412,"mc":[{"id":"1.168237330","rc":[{"batb":[[1,1.23,83.3],[2,1.22,60.58]],"batl":[[0,2.62,37.86],[1,1000,0.02],[2,2.62,0]],"ltp":1.49,"tv":5185.63,"id":6596286}]}]}
{"op":"mcm","clk":"1003954281","pt":1580616930350,"mc":[{"id":"1.168237330","rc":[{"batb":[[1,1.5,84.02],[2,1.38,2.63]],"ltp":3.15,"tv":1824.75,"id":8196374}]}]}
{"op":"mcm","clk":"1003954354","pt":1580616931435,"mc":[{"id":"1.168237330","rc":[{"batl":[[0,1000,0.02],[1,1000,0]],"ltp":1.49,"tv":5185.63,"id":6596286}]}]}
{"op":"mcm","clk":"1003954444","pt":1580616932930,"mc":[{"id":"1.168237330","rc":[{"batb":[[2,1.01,13.21]],"ltp":1.49,"tv":5185.63,"id":6596286}]}]}
{"op":"mcm","clk":"1003954526","pt":1580616934433,"mc":[{"id":"1.168237330","rc":[{"batb":[[0,1.49,1539.77],[1,1.48,993.4],[2,1.46,8.74]],"batl":[[0,1.54,1376.06],[1,1.55,812.98],[2,1000,0.02]],"ltp":1.49,"tv":5185.63,"id":6596286}]}]}
{"op":"mcm","clk":"1003955124","pt":1580616944625,"mc":[{"id":"1.168237330","rc":[{"batb":[[0,1.46,8.74],[1,1.23,83.3],[2,1.01,13.21]],"batl":[[0,1000,0.02],[1,1.55,0],[2,1000,0]],"ltp":1.49,"tv":5185.63,"id":6596286}]}]}
{"op":"mcm","clk":"1003955499","pt":1580616951753,"mc":[{"id":"1.168237330","rc":[{"batb":[[0,1.55,67.22],[1,1.46,8.74],[2,1.23,83.3]],"ltp":1.49,"tv":5185.63,"id":6596286}]}]}
{"op":"mcm","clk":"1003955548","pt":1580616952882,"mc":[{"id":"1.168237330","rc":[{"trd":[[1.55,312.54]],"batb":[[0,1.46,8.74],[1,1.23,83.3],[2,1.01,13.21]],"ltp":1.55,"tv":5320.06,"id":6596286}],"tv":7144.82}]}
{"op":"mcm","clk":"1003955721","pt":1580616955876,"mc":[{"id":"1.168237330","rc":[{"batb":[[1,1.42,1444.91],[2,1.41,1222.29]],"batl":[[0,1.62,913.17],[1,1.63,678.57],[2,1000,0.02]],"ltp":1.55,"tv":5320.06,"id":6596286}]}]}
{"op":"mcm","clk":"1003955736","pt":1580616956080,"mc":[{"id":"1.168237330","rc":[{"batl":[[0,1.62,848.77]],"ltp":1.55,"tv":5320.06,"id":6596286}]}]}
{"op":"mcm","clk":"1003955843","pt":1580616958395,"mc":[{"id":"1.168237330","rc":[{"batb":[[1,1.42,1518.45]],"ltp":1.55,"tv":5320.06,"id":6596286}]}]}
{"op":"mcm","clk":"1003956171","pt":1580616966973,"mc":[{"id":"1.168237330","rc":[{"batl":[[0,1000,0.02],[1,1.63,0],[2,1000,0]],"ltp":1.55,"tv":5320.06,"id":6596286}]}]}
{"op":"mcm","clk":"1003956347","pt":1580616971970,"mc":[{"id":"1.168237330","rc":[{"trd":[[1.46,63.74]],"batb":[[0,1.42,1518.45],[1,1.41,1222.29],[2,1.23,83.3]],"batl":[[0,1.46,1239.08],[1,1.47,1000.9],[2,1000,0.02]],"ltp":1.46,"tv":5337.54,"id":6596286}],"tv":7162.3}]}
{"op":"mcm","clk":"1003956762","pt":1580616982115,"mc":[{"id":"1.168237330","rc":[{"batb":[[0,1.23,83.3],[1,1.01,13.21],[2,1.23,0]],"batl":[[0,1000,0.02],[1,1.47,0],[2,1000,0]],"ltp":1.46,"tv":5337.54,"id":6596286}]}]}
{"op":"mcm","clk":"1003956916","pt":1580616987111,"mc":[{"id":"1.168237330","rc":[{"batb":[[0,1.34,1794.26],[1,1.33,1617.66],[2,1.23,83.3]],"batl":[[0,1.56,1302.32],[1,1.57,774.96],[2,1000,0.02]],"ltp":1.46,"tv":5337.54,"id":6596286}]}]}
{"op":"mcm","clk":"1003957719","pt":1580617005710,"mc":[{"id":"1.168237330","rc":[{"trd":[[1.56,453.15]],"batl":[[0,1.56,849.17]],"ltp":1.56,"tv":5790.69,"id":6596286},{"trd":[[2.78,254.3]],"ltp":2.78,"tv":2079.05,"id":8196374}],"tv":7869.75}]}
{"op":"mcm","clk":"1003957743","pt":1580617006332,"mc":[{"id":"1.168237330","rc":[{"batb":[[0,1.34,1537.91],[1,1.23,83.3],[2,1.01,13.21]],"ltp":1.56,"tv":5790.69,"id":6596286}]}]}
{"op":"mcm","clk":"1003958024","pt":1580617011253,"mc":[{"id":"1.168237330","rc":[{"batb":[[0,1.35,780.13],[1,1.34,1537.91],[2,1.23,83.3]],"ltp":1.56,"tv":5790.69,"id":6596286}]}]}
{"op":"mcm","clk":"1003958350","pt":1580617017248,"mc":[{"id":"1.168237330","rc":[{"batb":[[0,1.23,83.3],[1,1.01,13.21],[2,1.23,0]],"ltp":1.56,"tv":5790.69,"id":6596286}]}]}
{"op":"mcm","clk":"1003958635","pt":1580617022274,"mc":[{"id":"1.168237330","rc":[{"batb":[[0,1.52,959.11],[1,1.51,909.01],[2,1.23,83.3]],"ltp":1.56,"tv":5790.69,"id":6596286}]}]}
{"op":"mcm","clk":"1003959068","pt":1580617032376,"mc":[{"id":"1.168237330","rc":[{"batb":[[0,1.23,83.3],[1,1.01,13.21],[2,1.23,0]],"batl":[[0,1000,0.02],[1,1.57,0],[2,1000,0]],"ltp":1.56,"tv":5790.69,"id":6596286}]}]}
{"op":"mcm","clk":"1003959230","pt":1580617037411,"mc":[{"id":"1.168237330","rc":[{"batb":[[0,1.43,868.81],[1,1.42,1174.5],[2,1.23,83.3]],"batl":[[0,1.67,753.18],[1,1.69,1201.1],[2,1000,0.02]],"ltp":1.56,"tv":5790.69,"id":6596286}]}]}
{"op":"mcm","clk":"1003959584","pt":1580617046521,"mc":[{"id":"1.168237330","rc":[{"batb":[[2,1.01,13.21]],"ltp":1.56,"tv":5790.69,"id":6596286},{"batb":[[0,1.5,84.02],[1,1.38,2.63],[2,1.01,13.21]],"ltp":2.78,"tv":2079.05,"id":8196374}]}]}
{"op":"mcm","clk":"1003959713","pt":1580617050128,"mc":[{"id":"1.168237330","rc":[{"batl":[[0,1000,0.02],[1,1.69,0],[2,1000,0]],"ltp":1.56,"tv":5790.69,"id":6596286}]}]}
{"op":"mcm","clk":"1003959785","pt":1580617051625,"mc":[{"id":"1.168237330","rc":[{"batb":[[2,1.3,83.3]],"ltp":1.56,"tv":5790.69,"id":6596286},{"batb":[[0,2.06,82.93],[1,1.5,84.02],[2,1.38,2.63]],"ltp":2.78,"tv":2079.05,"id":8196374}]}]}
{"op":"mcm","clk":"1003959916","pt":1580617055123,"mc":[{"id":"1.168237330","rc":[{"batl":[[0,1.46,734.29],[1,1.47,1001.53],[2,1000,0.02]],"ltp":1.56,"tv":5790.69,"id":6596286}]}]}
{"op":"mcm","clk":"1003960413","pt":1580617065152,"mc":[{"id":"1.168237330","rc":[{"batb":[[0,1.3,83.3],[1,1.01,13.21],[2,1.3,0]],"batl":[[0,1000,0.02],[1,1.47,0],[2,1000,0]],"ltp":1.56,"tv":5790.69,"id":6596286}]}]}
{"op":"mcm","clk":"1003960671","pt":1580617070152,"mc":[{"id":"1.168237330","rc":[{"batb":[[0,1.35,800.32],[1,1.34,1538.2],[2,1.3,83.3]],"batl":[[0,1.56,832.66],[1,1.57,775.05],[2,1000,0.02]],"ltp":1.56,"tv":5790.69,"id":6596286}]}]}
{"op":"mcm","clk":"1003961186","pt":1580617081185,"mc":[{"id":"1.168237330","rc":[{"batb":[[0,1.3,83.3],[1,1.01,13.21],[2,1.3,0]],"batl":[[0,1000,0.02],[1,1.57,0],[2,1000,0]],"ltp":1.56,"tv":5790.69,"id":6596286}]}]}
{"op":"mcm","clk":"1003961356","pt":1580617084654,"mc":[{"id":"1.168237330","rc":[{"batb":[[0,1.01,13.21],[1,1.01,0]],"ltp":1.56,"tv":5790.69,"id":6596286}]}]}
{"op":"mcm","clk":"1003961408","pt":1580617086210,"mc":[{"id":"1.168237330","rc":[{"batb":[[0,1.35,800.32],[1,1.34,1538.2],[2,1.01,13.21]],"batl":[[0,1.38,1618.89],[1,1.39,1262.4],[2,1000,0.02]],"ltp":1.56,"tv":5790.69,"id":6596286}]}]}
{"op":"mcm","clk":"1003961559","pt":1580617089778,"mc":[{"id":"1.168237330","rc":[{"batb":[[2,1.25,83.3]],"ltp":1.56,"tv":5790.69,"id":6596286}]}]}
{"op":"mcm","clk":"1003961852","pt":1580617096192,"mc":[{"id":"1.168237330","rc":[{"batb":[[0,1.25,83.3],[1,1.01,13.21],[2,1.25,0]],"batl":[[0,1000,0.02],[1,1.39,0],[2,1000,0]],"ltp":1.56,"tv":5790.69,"id":6596286}]}]}
{"op":"mcm","clk":"1003961883","pt":1580617097169,"mc":[{"id":"1.168237330","rc":[{"batl":[[0,1.35,9.75],[1,1000,0.02]],"ltp":1.56,"tv":5790.69,"id":6596286}]}]}
{"op":"mcm","clk":"1003962088","pt":1580617101907,"mc":[{"id":"1.168237330","rc":[{"batb":[[0,1.27,2670.66],[1,1.26,2182.33],[2,1.25,83.3]],"batl":[[0,1.47,1639.89],[1,1.48,967.1],[2,1000,0.02]],"ltp":1.56,"tv":5790.69,"id":6596286}]}]}
{"op":"mcm","clk":"1003962233","pt":1580617105326,"mc":[{"id":"1.168237330","rc":[{"batb":[[2,1.01,13.21]],"ltp":1.56,"tv":5790.69,"id":6596286}]}]}
{"op":"mcm","clk":"1003962430","pt":1580617110431,"mc":[{"id":"1.168237330","rc":[{"batb":[[2,1.2,83.4]],"ltp":1.56,"tv":5790.69,"id":6596286}]}]}
{"op":"mcm","clk":"1003962599","pt":1580617114417,"mc":[{"id":"1.168237330","rc":[{"batb":[[0,1.2,83.4],[1,1.01,13.11],[2,1.2,0]],"ltp":1.56,"tv":5790.69,"id":6596286}]}]}
{"op":"mcm","clk":"1003962819","pt":1580617119469,"mc":[{"id":"1.168237330","rc":[{"batb":[[0,1.43,965.81],[1,1.42,1175.41],[2,1.2,83.4]],"ltp":1.56,"tv":5790.69,"id":6596286}]}]}
{"op":"mcm","clk":"1003963172","pt":1580617127954,"mc":[{"id":"1.168237330","rc":[{"batb":[[0,1.5,84.02],[1,1.38,2.63],[2,1.01,13.21]],"ltp":2.78,"tv":2079.05,"id":8196374}]}]}
{"op":"mcm","clk":"1003963246","pt":1580617129572,"mc":[{"id":"1.168237330","rc":[{"batb":[[0,1.2,83.4],[1,1.01,13.11],[2,1.2,0]],"batl":[[0,1000,0.02],[1,1.48,0],[2,1000,0]],"ltp":1.56,"tv":5790.69,"id":6596286}]}]}
{"op":"mcm","clk":"1003963358","pt":1580617131957,"mc":[{"id":"1.168237330","rc":[{"batl":[[0,1.43,9.75],[1,1000,0.02]],"ltp":1.56,"tv":5790.69,"id":6596286}]}]}
{"op":"mcm","clk":"1003963400","pt":1580617133091,"mc":[{"id":"1.168237330","rc":[{"batb":[[0,2.1,82.93],[1,1.5,84.02],[2,1.38,2.63]],"ltp":2.78,"tv":2079.05,"id":8196374}]}]}
{"op":"mcm","clk":"1003963470","pt":1580617134564,"mc":[{"id":"1.168237330","rc":[{"batb":[[0,1.35,895.71],[1,1.34,1539.55],[2,1.2,83.4]],"batl":[[1,1.56,754.35],[2,1.57,775.47]],"ltp":1.56,"tv":5790.69,"id":6596286}]}]}
{"op":"mcm","clk":"1003963718","pt":1580617140281,"mc":[{"id":"1.168237330","rc":[{"batb":[[0,1.2,83.4],[1,1.01,13.11],[2,1.2,0]],"batl":[[1,1000,0.02],[2,1.57,0]],"ltp":1.56,"tv":5790.69,"id":6596286}]}]}
{"op":"mcm","clk":"1003964063","pt":1580617148313,"mc":[{"id":"1.168237330","rc":[{"batb":[[0,1.35,895.71],[1,1.34,1539.55],[2,1.2,83.4]],"batl":[[1,1.56,754.35],[2,1.57,775.47]],"ltp":1.56,"tv":5790.69,"id":6596286}]}]}
{"op":"mcm","clk":"1003964543","pt":1580617158410,"mc":[{"id":"1.168237330","rc":[{"batb":[[0,1.2,83.4],[1,1.01,13.11],[2,1.2,0]],"ltp":1.56,"tv":5790.69,"id":6596286}]}]}
{"op":"mcm","clk":"1003964842","pt":1580617163333,"mc":[{"id":"1.168237330","rc":[{"trd":[[1.43,23.03]],"batb":[[0,1.52,1048.88],[1,1.51,909.63],[2,1.2,83.4]],"batl":[[0,1.56,754.35],[1,1.57,775.47],[2,1000,0.02]],"ltp":1.43,"tv":5810.19,"id":6596286}],"tv":7889.25}]}
{"op":"mcm","clk":"1003965091","pt":1580617167741,"mc":[{"id":"1.168237330","rc":[{"batl":[[0,3.3,4.22],[1,1000,0.02]],"ltp":2.78,"tv":2079.05,"id":8196374}]}]}
{"op":"mcm","clk":"1003965102","pt":1580617168002,"mc":[{"id":"1.168237330","rc":[{"batl":[[0,1000,0.02],[1,1000,0]],"ltp":2.78,"tv":2079.05,"id":8196374}]}]}
{"op":"mcm","clk":"1003965368","pt":1580617173546,"mc":[{"id":"1.168237330","rc":[{"batb":[[0,1.2,83.4],[1,1.01,13.11],[2,1.2,0]],"batl":[[0,1000,0.02],[1,1.57,0],[2,1000,0]],"ltp":1.43,"tv":5810.19,"id":6596286}]}]}
{"op":"mcm","clk":"1003965870","pt":1580617183967,"mc":[{"id":"1.168237330","rc":[{"batb":[[0,1.5,1140.01],[1,1.49,960.39],[2,1.2,83.4]],"batl":[[0,1.54,827.64],[1,1.55,813.18],[2,1000,0.02]],"ltp":1.43,"tv":5810.19,"id":6596286}]}]}
{"op":"mcm","clk":"1003965878","pt":1580617184175,"mc":[{"id":"1.168237330","rc":[{"batb":[[0,1.2,83.4],[1,1.01,13.11],[2,1.2,0]],"batl":[[0,1000,0.02],[1,1.55,0],[2,1000,0]],"ltp":1.43,"tv":5810.19,"id":6596286}]}]}
{"op":"mcm","clk":"1003966037","pt":1580617187073,"mc":[{"id":"1.168237330","rc":[{"batb":[[0,1.43,971.28],[1,1.42,1175.56],[2,1.2,83.4]],"batl":[[0,1.67,695.27],[1,1.69,1201.55],[2,1000,0.02]],"ltp":1.43,"tv":5810.19,"id":6596286}]}]}
{"op":"mcm","clk":"1003967275","pt":1580617213536,"mc":[{"id":"1.168237330","rc":[{"batl":[[0,1000,0.02],[1,1.69,0],[2,1000,0]],"ltp":1.43,"tv":5810.19,"id":6596286}]}]}
{"op":"mcm","clk":"1003967494","pt":1580617218443,"mc":[{"id":"1.168237330","rc":[{"batl":[[0,1.47,1635.08],[1,1.48,967.21],[2,1000,0.02]],"ltp":1.43,"tv":5810.19,"id":6596286}]}]}
{"op":"mcm","clk":"1003968060","pt":1580617228686,"mc":[{"id":"1.168237330","rc":[{"batb":[[0,1.2,83.4],[1,1.01,13.11],[2,1.2,0]],"batl":[[0,1000,0.02],[1,1.48,0],[2,1000,0]],"ltp":1.43,"tv":5810.19,"id":6596286}]}]}
{"op":"mcm","clk":"1003968258","pt":1580617233581,"mc":[{"id":"1.168237330","rc":[{"batb":[[0,1.35,897.91],[1,1.34,1539.71],[2,1.2,83.4]],"batl":[[0,1.56,753.15],[1,1.57,775.53],[2,1000,0.02]],"ltp":1.43,"tv":5810.19,"id":6596286}]}]}
{"op":"mcm","clk":"1003968840","pt":1580617247898,"mc":[{"id":"1.168237330","rc":[{"batb":[[2,1.01,13.21]],"ltp":1.43,"tv":5810.19,"id":6596286},{"batb":[[0,1.5,84.02],[1,1.38,2.63],[2,1.01,13.21]],"ltp":2.78,"tv":2079.05,"id":8196374}]}]}
{"op":"mcm","clk":"1003968873","pt":1580617249026,"mc":[{"id":"1.168237330","rc":[{"batb":[[0,1.01,13.21],[1,1.34,0],[2,1.01,0]],"batl":[[0,1000,0.02],[1,1.57,0],[2,1000,0]],"ltp":1.43,"tv":5810.19,"id":6596286}]}]}
{"op":"mcm","clk":"1003969095","pt":1580617253928,"mc":[{"id":"1.168237330","rc":[{"trd":[[1.35,37.86]],"batb":[[0,1.43,952.35],[1,1.42,1175.56],[2,1.01,13.21]],"batl":[[0,1.47,1635.08],[1,1.48,967.21],[2,1000,0.02]],"ltp":1.35,"tv":5848.05,"id":6596286}],"tv":7927.11}]}
{"op":"mcm","clk":"1003969396","pt":1580617260329,"mc":[{"id":"1.168237330","rc":[{"batb":[[0,1.01,13.21],[1,1.42,0],[2,1.01,0]],"batl":[[0,1000,0.02],[1,1.48,0],[2,1000,0]],"ltp":1.35,"tv":5848.05,"id":6596286}]}]}
{"op":"mcm","clk":"1003969617","pt":1580617265236,"mc":[{"id":"1.168237330","rc":[{"batb":[[0,1.35,878.99],[1,1.34,1539.7],[2,1.01,13.21]],"batl":[[0,1.56,769.62],[1,1.57,775.56],[2,1000,0.02]],"ltp":1.35,"tv":5848.05,"id":6596286}]}]}
{"op":"mcm","clk":"1003969667","pt":1580617266322,"mc":[{"id":"1.168237330","rc":[{"batl":[[0,1000,0.02],[1,1.57,0],[2,1000,0]],"ltp":1.35,"tv":5848.05,"id":6596286}]}]}
{"op":"mcm","clk":"1003969863","pt":1580617271233,"mc":[{"id":"1.168237330","rc":[{"batl":[[0,1.38,1545.93],[1,1.39,1263.64],[2,1000,0.02]],"ltp":1.35,"tv":5848.05,"id":6596286}]}]}
{"op":"mcm","clk":"1003970171","pt":1580617278455,"mc":[{"id":"1.168237330","rc":[{"trd":[[1.38,19.84]],"batl":[[0,1.38,1536.18]],"ltp":1.38,"tv":5867.55,"id":6596286}],"tv":7946.61}]}
{"op":"mcm","clk":"1003970300","pt":1580617281285,"mc":[{"id":"1.168237330","rc":[{"batb":[[0,1.01,13.21],[1,1.34,0],[2,1.01,0]],"batl":[[0,1000,0.02],[1,1.39,0],[2,1000,0]],"ltp":1.38,"tv":5867.55,"id":6596286}]}]}
{"op":"mcm","clk":"1003970518","pt":1580617286346,"mc":[{"id":"1.168237330","rc":[{"batb":[[0,1.27,2730.17],[1,1.26,2184],[2,1.01,13.21]],"batl":[[0,1.47,1558.93],[1,1.48,967.91],[2,1000,0.02]],"ltp":1.38,"tv":5867.55,"id":6596286}]}]}
{"op":"mcm","clk":"1003972535","pt":1580617330544,"mc":[{"id":"1.168237330","rc":[{"trd":[[1.47,0.7]],"batl":[[0,1.47,1558.58]],"ltp":1.47,"tv":5868.25,"id":6596286}],"tv":7947.31}]}
{"op":"mcm","clk":"1003972916","pt":1580617338965,"mc":[{"id":"1.168237330","rc":[{"batl":[[0,1000,0.02],[1,1.48,0],[2,1000,0]],"ltp":1.47,"tv":5868.25,"id":6596286}]}]}
{"op":"mcm","clk":"1003973152","pt":1580617343864,"mc":[{"id":"1.168237330","rc":[{"batl":[[0,1.3,1174.91],[1,1.31,1686.99],[2,1000,0.02]],"ltp":1.47,"tv":5868.25,"id":6596286}]}]}
{"op":"mcm","clk":"1003973597","pt":1580617354145,"mc":[{"id":"1.168237330","rc":[{"batb":[[0,1.01,13.21],[1,1.26,0],[2,1.01,0]],"batl":[[0,1000,0.02],[1,1.31,0],[2,1000,0]],"ltp":1.47,"tv":5868.25,"id":6596286}]}]}
{"op":"mcm","clk":"1003973825","pt":1580617359088,"mc":[{"id":"1.168237330","rc":[{"batb":[[0,1.24,2621.64],[1,1.23,2529.33],[2,1.01,13.21]],"batl":[[0,1.35,1948.16],[1,1.36,1391.41],[2,1000,0.02]],"ltp":1.47,"tv":5868.25,"id":6596286}]}]}
{"op":"mcm","clk":"1003974493","pt":1580617374405,"mc":[{"id":"1.168237330","rc":[{"batl":[[0,1000,0.02],[1,1.36,0],[2,1000,0]],"ltp":1.47,"tv":5868.25,"id":6596286}]}]}
{"op":"mcm","clk":"1003974704","pt":1580617379225,"mc":[{"id":"1.168237330","rc":[{"batl":[[0,1.27,2023.75],[1,1.28,1890.96],[2,1000,0.02]],"ltp":1.47,"tv":5868.25,"id":6596286}]}]}
{"op":"mcm","clk":"1003975076","pt":1580617387512,"mc":[{"id":"1.168237330","rc":[{"batb":[[0,1.01,13.21],[1,1.23,0],[2,1.01,0]],"batl":[[0,1000,0.02],[1,1.28,0],[2,1000,0]],"ltp":1.47,"tv":5868.25,"id":6596286}]}]}
{"op":"mcm","clk":"1003975206","pt":1580617389632,"mc":[{"id":"1.168237330","rc":[{"batl":[[0,1.24,9.75],[1,1000,0.02]],"ltp":1.47,"tv":5868.25,"id":6596286}]}]}
{"op":"mcm","clk":"1003975347","pt":1580617392525,"mc":[{"id":"1.168237330","rc":[{"batb":[[0,1.22,932.89],[1,1.21,2767.23],[2,1.01,13.21]],"batl":[[1,1.31,2078.46],[2,1.32,1607.11]],"ltp":1.47,"tv":5868.25,"id":6596286}]}]}
{"op":"mcm","clk":"1003975594","pt":1580617397965,"mc":[{"id":"1.168237330","rc":[{"batl":[[1,1000,0.02],[2,1.32,0]],"ltp":1.47,"tv":5868.25,"id":6596286}]}]}
{"op":"mcm","clk":"1003975815","pt":1580617402874,"mc":[{"id":"1.168237330","rc":[{"batl":[[0,1.24,2012.69],[1,1.25,2165.48],[2,1000,0.02]],"ltp":1.47,"tv":5868.25,"id":6596286}]}]}
{"op":"mcm","clk":"1003975921","pt":1580617405053,"mc":[{"id":"1.168237330","rc":[{"batl":[[0,1.24,2002.94]],"ltp":1.47,"tv":5868.25,"id":6596286}]}]}
{"op":"mcm","clk":"1003976322","pt":1580617412966,"mc":[{"id":"1.168237330","rc":[{"trd":[[1.22,19.5]],"batb":[[0,1.01,13.21],[1,1.21,0],[2,1.01,0]],"batl":[[0,1000,0.02],[1,1.25,0],[2,1000,0]],"ltp":1.22,"tv":5887.75,"id":6596286}],"tv":7966.81}]}
{"op":"mcm","clk":"1003976587","pt":1580617417889,"mc":[{"id":"1.168237330","rc":[{"batb":[[0,1.2,888.24],[1,1.19,3109.31],[2,1.01,13.11]],"batl":[[0,1.27,2071.51],[1,1.28,1889.94],[2,1000,0.02]],"ltp":1.22,"tv":5887.75,"id":6596286}]}]}
{"op":"mcm","clk":"1003977055","pt":1580617427625,"mc":[{"id":"1.168237330","rc":[{"batb":[[0,1.01,13.21],[1,1.19,0],[2,1.01,0]],"batl":[[0,1000,0.02],[1,1.28,0],[2,1000,0]],"ltp":1.22,"tv":5887.75,"id":6596286}]}]}
{"op":"mcm","clk":"1003977442","pt":1580617435644,"mc":[{"id":"1.168237330","rc":[{"batb":[[0,1.2,878.32],[1,1.19,3109.31],[2,1.01,13.11]],"batl":[[0,1.27,2080.9],[1,1.28,1889.95],[2,1000,0.02]],"ltp":1.22,"tv":5887.75,"id":6596286}]}]}
{"op":"mcm","clk":"1003977925","pt":1580617445546,"mc":[{"id":"1.168237330","rc":[{"batl":[[0,1000,0.02],[1,1.28,0],[2,1000,0]],"ltp":1.22,"tv":5887.75,"id":6596286}]}]}
{"op":"mcm","clk":"1003978140","pt":1580617450468,"mc":[{"id":"1.168237330","rc":[{"batl":[[0,1.22,2553.13],[1,1.23,2373.75],[2,1000,0.02]],"ltp":1.22,"tv":5887.75,"id":6596286}]}]}
{"op":"mcm","clk":"1003978573","pt":1580617460589,"mc":[{"id":"1.168237330","rc":[{"batb":[[0,1.01,13.21],[1,1.19,0],[2,1.01,0]],"batl":[[0,1000,0.02],[1,1.23,0],[2,1000,0]],"ltp":1.22,"tv":5887.75,"id":6596286}]}]}
{"op":"mcm","clk":"1003978844","pt":1580617465600,"mc":[{"id":"1.168237330","rc":[{"batb":[[0,1.18,3201.39],[1,1.17,2754.25],[2,1.01,13.11]],"batl":[[0,1.24,2911.87],[1,1.25,2142.62],[2,1000,0.02]],"ltp":1.22,"tv":5887.75,"id":6596286}]}]}
{"op":"mcm","clk":"1003981174","pt":1580617515669,"mc":[{"id":"1.168237330","rc":[{"batb":[[0,1.01,13.21],[1,1.17,0],[2,1.01,0]],"batl":[[0,1000,0.02],[1,1.25,0],[2,1000,0]],"ltp":1.22,"tv":5887.75,"id":6596286}]}]}
{"op":"mcm","clk":"1003981527","pt":1580617523556,"mc":[{"id":"1.168237330","rc":[{"batb":[[0,1.18,3201.39],[1,1.17,2754.25],[2,1.01,13.11]],"batl":[[0,1.24,2911.87],[1,1.25,2142.62],[2,1000,0.02]],"ltp":1.22,"tv":5887.75,"id":6596286}]}]}
{"op":"mcm","clk":"1003983661","pt":1580617570380,"mc":[{"id":"1.168237330","rc":[{"batb":[[0,1.01,13.21],[1,1.17,0],[2,1.01,0]],"batl":[[0,1000,0.02],[1,1.25,0],[2,1000,0]],"ltp":1.22,"tv":5887.75,"id":6596286}]}]}
{"op":"mcm","clk":"1003984133","pt":1580617578503,"mc":[{"id":"1.168237330","rc":[{"batb":[[0,1.18,3201.39],[1,1.17,2754.25],[2,1.01,13.11]],"batl":[[0,1.24,2911.87],[1,1.25,2142.62],[2,1000,0.02]],"ltp":1.22,"tv":5887.75,"id":6596286}]}]}
{"op":"mcm","clk":"1003984576","pt":1580617586600,"mc":[{"id":"1.168237330","rc":[{"batb":[[0,1.01,13.21],[1,1.17,0],[2,1.01,0]],"ltp":1.22,"tv":5887.75,"id":6596286}]}]}
{"op":"mcm","clk":"1003984862","pt":1580617591580,"mc":[{"id":"1.168237330","rc":[{"batb":[[0,1.21,2695.04],[1,1.2,2987.71],[2,1.01,13.11]],"ltp":1.22,"tv":5887.75,"id":6596286}]}]}
{"op":"mcm","clk":"1003985159","pt":1580617598601,"mc":[{"id":"1.168237330","rc":[{"batb":[[0,1.01,13.21],[1,1.2,0],[2,1.01,0]],"batl":[[0,1000,0.02],[1,1.25,0],[2,1000,0]],"ltp":1.22,"tv":5887.75,"id":6596286}]}]}
{"op":"mcm","clk":"1003985368","pt":1580617603465,"mc":[{"id":"1.168237330","rc":[{"batb":[[0,1.19,2731.23],[1,1.18,3177.92],[2,1.01,13.11]],"batl":[[0,1.26,1020.88],[1,1.27,1998.03],[2,1000,0.02]],"ltp":1.22,"tv":5887.75,"id":6596286}]}]}
{"op":"mcm","clk":"1003985854","pt":1580617614225,"mc":[{"id":"1.168237330","rc":[{"batb":[[0,1.01,13.21],[1,1.18,0],[2,1.01,0]],"ltp":1.22,"tv":5887.75,"id":6596286}]}]}
{"op":"mcm","clk":"1003986039","pt":1580617618301,"mc":[{"id":"1.168237330","rc":[{"batb":[[0,1.05,3.23],[1,1.01,13.01]],"ltp":1.22,"tv":5887.75,"id":6596286}]}]}
{"op":"mcm","clk":"1003986075","pt":1580617619232,"mc":[{"id":"1.168237330","rc":[{"batb":[[0,1.24,1537.03],[1,1.23,2501.04],[2,1.05,3.23]],"ltp":1.22,"tv":5887.75,"id":6596286}]}]}
{"op":"mcm","clk":"1003986569","pt":1580617629543,"mc":[{"id":"1.168237330","rc":[{"batb":[[0,1.05,3.23],[1,1.01,13.01],[2,1.05,0]],"batl":[[0,1000,0.02],[1,1.27,0],[2,1000,0]],"ltp":1.22,"tv":5887.75,"id":6596286}]}]}
{"op":"mcm","clk":"1003986783","pt":1580617634448,"mc":[{"id":"1.168237330","rc":[{"batb":[[0,1.2,2376.64],[1,1.19,3161.53],[2,1.05,3.13]],"batl":[[0,1.32,2190.23],[1,1.33,1545.89],[2,1000,0.02]],"ltp":1.22,"tv":5887.75,"id":6596286}]}]}
{"op":"mcm","clk":"1003987845","pt":1580617660888,"mc":[{"id":"1.168237330","rc":[{"batb":[[0,1.05,3.23],[1,1.01,13.01],[2,1.05,0]],"ltp":1.22,"tv":5887.75,"id":6596286}]}]}
{"op":"mcm","clk":"1003988007","pt":1580617665872,"mc":[{"id":"1.168237330","rc":[{"batb":[[0,1.29,1188.28],[1,1.28,1965.04],[2,1.05,3.23]],"ltp":1.22,"tv":5887.75,"id":6596286}]}]}
{"op":"mcm","clk":"1003988393","pt":1580617675913,"mc":[{"id":"1.168237330","rc":[{"batb":[[0,1.05,3.23],[1,1.01,13.01],[2,1.05,0]],"batl":[[0,1000,0.02],[1,1.33,0],[2,1000,0]],"ltp":1.22,"tv":5887.75,"id":6596286}]}]}
{"op":"mcm","clk":"1003988606","pt":1580617680805,"mc":[{"id":"1.168237330","rc":[{"batb":[[0,1.24,2099.58],[1,1.23,2515.88],[2,1.05,3.23]],"batl":[[0,1.38,1210.28],[1,1.39,1267.71],[2,1000,0.02]],"ltp":1.22,"tv":5887.75,"id":6596286}]}]}
{"op":"mcm","clk":"1003988817","pt":1580617686215,"mc":[{"id":"1.168237330","rc":[{"batl":[[0,1000,0.02],[1,1.39,0],[2,1000,0]],"ltp":1.22,"tv":5887.75,"id":6596286}]}]}
{"op":"mcm","clk":"1003989027","pt":1580617691221,"mc":[{"id":"1.168237330","rc":[{"batl":[[0,1.27,2499.51],[1,1.28,1881],[2,1000,0.02]],"ltp":1.22,"tv":5887.75,"id":6596286}]}]}
{"op":"mcm","clk":"1003989406","pt":1580617701434,"mc":[{"id":"1.168237330","rc":[{"batb":[[0,1.05,3.23],[1,1.01,13.01],[2,1.05,0]],"batl":[[0,1000,0.02],[1,1.28,0],[2,1000,0]],"ltp":1.22,"tv":5887.75,"id":6596286}]}]}
{"op":"mcm","clk":"1003989450","pt":1580617702564,"mc":[{"id":"1.168237330","rc":[{"batb":[[0,1.01,13.21],[1,1.01,0]],"ltp":1.22,"tv":5887.75,"id":6596286}]}]}
{"op":"mcm","clk":"1003989615","pt":1580617706338,"mc":[{"id":"1.168237330","rc":[{"batb":[[0,1.2,2918.73],[1,1.19,2939.19],[2,1.01,13.11]],"batl":[[0,1.32,1690.79],[1,1.33,1554.05],[2,1000,0.02]],"ltp":1.22,"tv":5887.75,"id":6596286}]}]}
{"op":"mcm","clk":"1003990584","pt":1580617732006,"mc":[{"id":"1.168237330","rc":[{"batb":[[0,1.01,13.21],[1,1.19,0],[2,1.01,0]],"ltp":1.22,"tv":5887.75,"id":6596286}]}]}
{"op":"mcm","clk":"1003990816","pt":1580617737006,"mc":[{"id":"1.168237330","rc":[{"batb":[[0,1.29,1727.06],[1,1.28,1975.53],[2,1.01,13.21]],"ltp":1.22,"tv":5887.75,"id":6596286}]}]}
{"op":"mcm","clk":"1003991277","pt":1580617747307,"mc":[{"id":"1.168237330","rc":[{"batb":[[0,1.01,13.21],[1,1.28,0],[2,1.01,0]],"batl":[[0,1000,0.02],[1,1.33,0],[2,1000,0]],"ltp":1.22,"tv":5887.75,"id":6596286}]}]}
{"op":"mcm","clk":"1003991506","pt":1580617752139,"mc":[{"id":"1.168237330","rc":[{"batb":[[0,1.24,2648.45],[1,1.23,2530.29],[2,1.01,13.21]],"batl":[[0,1.39,2016.95],[1,1.4,1218.34],[2,1000,0.02]],"ltp":1.22,"tv":5887.75,"id":6596286}]}]}
{"op":"mcm","clk":"1003992001","pt":1580617762753,"mc":[{"id":"1.168237330","rc":[{"batl":[[0,1000,0.02],[1,1.4,0],[2,1000,0]],"ltp":1.22,"tv":5887.75,"id":6596286}]}]}
{"op":"mcm","clk":"1003992233","pt":1580617767656,"mc":[{"id":"1.168237330","rc":[{"batl":[[0,1.27,2000.02],[1,1.28,1891.67],[2,1000,0.02]],"ltp":1.22,"tv":5887.75,"id":6596286}]}]}
{"op":"mcm","clk":"1003992635","pt":1580617777795,"mc":[{"id":"1.168237330","rc":[{"batb":[[0,1.01,13.21],[1,1.23,0],[2,1.01,0]],"batl":[[0,1000,0.02],[1,1.28,0],[2,1000,0]],"ltp":1.22,"tv":5887.75,"id":6596286}]}]}
{"op":"mcm","clk":"1003992856","pt":1580617782686,"mc":[{"id":"1.168237330","rc":[{"batb":[[0,1.2,3448.33],[1,1.19,2405.14],[2,1.01,13.11]],"batl":[[0,1.32,1203.89],[1,1.33,1561.95],[2,1000,0.02]],"ltp":1.22,"tv":5887.75,"id":6596286}]}]}
{"op":"mcm","clk":"1003993788","pt":1580617801843,"mc":[{"id":"1.168237330","rc":[{"batb":[[0,1.01,13.21],[1,1.19,0],[2,1.01,0]],"ltp":1.22,"tv":5887.75,"id":6596286}]}]}
{"op":"mcm","clk":"1003993910","pt":1580617804345,"mc":[{"id":"1.168237330","rc":[{"trd":[[1.2,0.2]],"batb":[[0,1.01,13.11]],"batl":[[0,1.2,171.51],[1,1.32,1203.89],[2,1.33,1561.95]],"ltp":1.2,"tv":5887.95,"id":6596286}],"tv":7967.01}]}
{"op":"mcm","clk":"1003994024","pt":1580617806723,"mc":[{"id":"1.168237330","rc":[{"trd":[[1.2,343.2]],"batb":[[0,1.29,2080.82],[1,1.28,1985.7],[2,1.01,13.11]],"batl":[[0,1.32,1203.89],[1,1.33,1561.95],[2,1000,0.02]],"ltp":1.2,"tv":6230.95,"id":6596286}],"tv":8310.01}]}
{"op":"mcm","clk":"1003994269","pt":1580617811976,"mc":[{"id":"1.168237330","rc":[{"batl":[[0,1.32,1360.5]],"ltp":1.2,"tv":6230.95,"id":6596286},{"batl":[[0,4.8,37.86],[1,1000,0.02]],"ltp":2.78,"tv":2079.05,"id":8196374}]}]}
{"op":"mcm","clk":"1003994276","pt":1580617812185,"mc":[{"id":"1.168237330","rc":[{"batl":[[0,1000,0.02],[1,1000,0]],"ltp":2.78,"tv":2079.05,"id":8196374}]}]}
{"op":"mcm","clk":"1003994510","pt":1580617816356,"mc":[{"id":"1.168237330","rc":[{"batb":[[0,1.01,13.11],[1,1.28,0],[2,1.01,0]],"batl":[[0,1000,0.02],[1,1.33,0],[2,1000,0]],"ltp":1.2,"tv":6230.95,"id":6596286}]}]}
{"op":"mcm","clk":"1003994718","pt":1580617821462,"mc":[{"id":"1.168237330","rc":[{"batb":[[0,1.24,3018.27],[1,1.23,2544.47],[2,1.01,13.11]],"batl":[[0,1.39,1724.63],[1,1.4,1223.87],[2,1000,0.02]],"ltp":1.2,"tv":6230.95,"id":6596286}]}]}
{"op":"mcm","clk":"1003995654","pt":1580617840011,"mc":[{"id":"1.168237330","rc":[{"batl":[[0,1000,0.02],[1,1.4,0],[2,1000,0]],"ltp":1.2,"tv":6230.95,"id":6596286}]}]}
{"op":"mcm","clk":"1003995875","pt":1580617844981,"mc":[{"id":"1.168237330","rc":[{"batl":[[0,1.27,1675.17],[1,1.28,1902.28],[2,1000,0.02]],"ltp":1.2,"tv":6230.95,"id":6596286}]}]}
{"op":"mcm","clk":"1003996397","pt":1580617855324,"mc":[{"id":"1.168237330","rc":[{"batb":[[0,1.01,13.11],[1,1.23,0],[2,1.01,0]],"batl":[[0,1000,0.02],[1,1.28,0],[2,1000,0]],"ltp":1.2,"tv":6230.95,"id":6596286}]}]}
{"op":"mcm","clk":"1003996635","pt":1580617860107,"mc":[{"id":"1.168237330","rc":[{"batb":[[0,1.2,3794.16],[1,1.19,2056.3],[2,1.01,13.11]],"batl":[[0,1.32,885.69],[1,1.33,1569.96],[2,1000,0.02]],"ltp":1.2,"tv":6230.95,"id":6596286}]}]}
{"op":"mcm","clk":"1003997160","pt":1580617870716,"mc":[{"id":"1.168237330","rc":[{"batl":[[0,1000,0.02],[1,1.33,0],[2,1000,0]],"ltp":1.2,"tv":6230.95,"id":6596286}]}]}
{"op":"mcm","clk":"1003997381","pt":1580617875757,"mc":[{"id":"1.168237330","rc":[{"batl":[[0,1.23,2325.08],[1,1.24,2268.81],[2,1000,0.02]],"ltp":1.2,"tv":6230.95,"id":6596286}]}]}
{"op":"mcm","clk":"1003998198","pt":1580617891843,"mc":[{"id":"1.168237330","rc":[{"trd":[[1.23,12]],"batl":[[0,1.23,2319.08]],"ltp":1.23,"tv":6242.95,"id":6596286}],"tv":8322.01}]}
{"op":"mcm","clk":"1004001201","pt":1580617950815,"mc":[{"id":"1.168237330","rc":[{"batb":[[0,1.19,1552.37],[1,1.01,13.11],[2,1.01,0]],"batl":[[0,1000,0.02],[1,1.24,0],[2,1000,0]],"ltp":1.23,"tv":6242.95,"id":6596286}]}]}
{"op":"mcm","clk":"1004001451","pt":1580617955855,"mc":[{"id":"1.168237330","rc":[{"batb":[[1,1.18,3341.96],[2,1.01,13.11]],"batl":[[0,1.25,2043.94],[1,1.26,2070.11],[2,1000,0.02]],"ltp":1.23,"tv":6242.95,"id":6596286}]}]}
{"op":"mcm","clk":"1004003407","pt":1580617991652,"mc":[{"id":"1.168237330","rc":[{"batl":[[0,1000,0.02],[1,1.26,0],[2,1000,0]],"ltp":1.23,"tv":6242.95,"id":6596286}]}]}
{"op":"mcm","clk":"1004003686","pt":1580617996627,"mc":[{"id":"1.168237330","rc":[{"batl":[[0,1.21,2231.85],[1,1.22,2515.21],[2,1000,0.02]],"ltp":1.23,"tv":6242.95,"id":6596286}]}]}
{"op":"mcm","clk":"1004004158","pt":1580618006737,"mc":[{"id":"1.168237330","rc":[{"batb":[[0,1.01,13.11],[1,1.18,0],[2,1.01,0]],"batl":[[0,1000,0.02],[1,1.22,0],[2,1000,0]],"ltp":1.23,"tv":6242.95,"id":6596286}]}]}
{"op":"mcm","clk":"1004004381","pt":1580618011638,"mc":[{"id":"1.168237330","rc":[{"batb":[[0,1.17,2849.2],[1,1.16,3160.72],[2,1.01,13.11]],"batl":[[0,1.23,2169.15],[1,1.24,2272.85],[2,1000,0.02]],"ltp":1.23,"tv":6242.95,"id":6596286}]}]}
{"op":"mcm","clk":"1004005182","pt":1580618028259,"mc":[{"id":"1.168237330","rc":[{"trd":[[1.17,391.54]],"batb":[[0,1.17,2653.43]],"ltp":1.17,"tv":6634.49,"id":6596286}],"tv":8713.55}]}
{"op":"mcm","clk":"1004005472","pt":1580618033699,"mc":[{"id":"1.168237330","rc":[{"batb":[[1,1.16,3358.17]],"batl":[[0,1.23,2355.94]],"ltp":1.17,"tv":6634.49,"id":6596286}]}]}
{"op":"mcm","clk":"1004005565","pt":1580618035613,"mc":[{"id":"1.168237330","rc":[{"batb":[[0,1.01,13.11],[1,1.16,0],[2,1.01,0]],"ltp":1.17,"tv":6634.49,"id":6596286}]}]}
{"op":"mcm","clk":"1004005739","pt":1580618039389,"mc":[{"id":"1.168237330","rc":[{"batl":[[0,1.22,36.07],[1,1.23,2355.94],[2,1.24,2272.85]],"ltp":1.17,"tv":6634.49,"id":6596286}]}]}
{"op":"mcm","clk":"1004005779","pt":1580618040480,"mc":[{"id":"1.168237330","rc":[{"batb":[[0,1.2,3777.99],[1,1.19,2072.61],[2,1.01,13.11]],"ltp":1.17,"tv":6634.49,"id":6596286}]}]}
{"op":"mcm","clk":"1004005832","pt":1580618041720,"mc":[{"id":"1.168237330","rc":[{"trd":[[1.2,861.14]],"batb":[[0,1.2,3519.02]],"ltp":1.2,"tv":7152.44,"id":6596286}],"tv":9231.5}]}
{"op":"mcm","clk":"1004006079","pt":1580618047098,"mc":[{"id":"1.168237330","rc":[{"batb":[[1,1.19,2333.76]],"batl":[[1,1.23,2608.96]],"ltp":1.2,"tv":7152.44,"id":6596286}]}]}
{"op":"mcm","clk":"1004006268","pt":1580618050615,"mc":[{"id":"1.168237330","rc":[{"batb":[[0,1.01,13.11],[1,1.19,0],[2,1.01,0]],"batl":[[1,1000,0.02],[2,1.24,0]],"ltp":1.2,"tv":7152.44,"id":6596286}]}]}
{"op":"mcm","clk":"1004006535","pt":1580618055632,"mc":[{"id":"1.168237330","rc":[{"batb":[[0,1.18,4007.18],[1,1.17,1941.47],[2,1.07,2.37]],"batl":[[1,1.25,1857.48],[2,1.26,2085.52]],"ltp":1.2,"tv":7152.44,"id":6596286}]}]}
{"op":"mcm","clk":"1004007374","pt":1580618070444,"mc":[{"id":"1.168237330","rc":[{"batb":[[0,1.07,2.37],[1,1.01,13.01],[2,1.07,0]],"batl":[[1,1000,0.02],[2,1.26,0]],"ltp":1.2,"tv":7152.44,"id":6596286}]}]}
{"op":"mcm","clk":"1004007783","pt":1580618078465,"mc":[{"id":"1.168237330","rc":[{"batb":[[0,1.18,4007.18],[1,1.17,1941.47],[2,1.07,2.37]],"batl":[[1,1.25,1857.48],[2,1.26,2085.52]],"ltp":1.2,"tv":7152.44,"id":6596286}]}]}
{"op":"mcm","clk":"1004008153","pt":1580618086759,"mc":[{"id":"1.168237330","rc":[{"batl":[[1,1000,0.02],[2,1.26,0]],"ltp":1.2,"tv":7152.44,"id":6596286}]}]}
{"op":"mcm","clk":"1004008378","pt":1580618091700,"mc":[{"id":"1.168237330","rc":[{"batl":[[0,1.21,3068.28],[1,1.22,2539.67],[2,1000,0.02]],"ltp":1.2,"tv":7152.44,"id":6596286}]}]}
{"op":"mcm","clk":"1004008841","pt":1580618101879,"mc":[{"id":"1.168237330","rc":[{"batb":[[0,1.17,1275.46],[1,1.07,2.37],[2,1.01,13.01]],"batl":[[0,1.22,36.07],[1,1000,0.02],[2,1000,0]],"ltp":1.2,"tv":7152.44,"id":6596286}]}]}
{"op":"mcm","clk":"1004009069","pt":1580618106743,"mc":[{"id":"1.168237330","rc":[{"batb":[[1,1.16,3834.3],[2,1.07,2.37]],"batl":[[1,1.23,2459.02],[2,1.24,2277.4]],"ltp":1.2,"tv":7152.44,"id":6596286}]}]}
{"op":"mcm","clk":"1004010047","pt":1580618129576,"mc":[{"id":"1.168237330","rc":[{"batb":[[0,1.07,2.37],[1,1.01,13.01],[2,1.07,0]],"ltp":1.2,"tv":7152.44,"id":6596286}]}]}
{"op":"mcm","clk":"1004010235","pt":1580618134504,"mc":[{"id":"1.168237330","rc":[{"batb":[[0,1.2,3687.28],[1,1.19,2164.08],[2,1.07,2.37]],"ltp":1.2,"tv":7152.44,"id":6596286}]}]}
{"op":"mcm","clk":"1004010598","pt":1580618144621,"mc":[{"id":"1.168237330","rc":[{"batb":[[0,1.07,2.37],[1,1.01,13.01],[2,1.07,0]],"batl":[[1,1000,0.02],[2,1.24,0]],"ltp":1.2,"tv":7152.44,"id":6596286}]}]}
{"op":"mcm","clk":"1004010774","pt":1580618149508,"mc":[{"id":"1.168237330","rc":[{"batb":[[0,1.18,2960.11],[1,1.17,2997.49],[2,1.07,2.37]],"batl":[[1,1.26,2869.79],[2,1.27,1970.66]],"ltp":1.2,"tv":7152.44,"id":6596286}]}]}
{"op":"mcm","clk":"1004010822","pt":1580618150793,"mc":[{"id":"1.168237330","rc":[{"trd":[[1.22,23.5]],"batl":[[0,1.22,34.07]],"ltp":1.22,"tv":7156.44,"id":6596286}],"tv":9235.5}]}
{"op":"mcm","clk":"1004011361","pt":1580618162125,"mc":[{"id":"1.168237330","rc":[{"batl":[[1,1000,0.02],[2,1.27,0]],"ltp":1.22,"tv":7156.44,"id":6596286}]}]}
{"op":"mcm","clk":"1004011566","pt":1580618167015,"mc":[{"id":"1.168237330","rc":[{"batl":[[0,1.2,1298.05],[1,1.21,2700.22],[2,1.22,34.07]],"ltp":1.22,"tv":7156.44,"id":6596286}]}]}
{"op":"mcm","clk":"1004012019","pt":1580618177149,"mc":[{"id":"1.168237330","rc":[{"batb":[[0,1.07,2.37],[1,1.01,13.01],[2,1.07,0]],"batl":[[0,1.22,34.07],[1,1000,0.02],[2,1.22,0]],"ltp":1.22,"tv":7156.44,"id":6596286}]}]}
{"op":"mcm","clk":"1004012256","pt":1580618182041,"mc":[{"id":"1.168237330","rc":[{"batb":[[0,1.16,1890.93],[1,1.15,4156.12],[2,1.07,2.37]],"batl":[[1,1.23,2220.79],[2,1.24,2283.79]],"ltp":1.22,"tv":7156.44,"id":6596286}]}]}
{"op":"mcm","clk":"1004012756","pt":1580618193468,"mc":[{"id":"1.168237330","rc":[{"batl":[[1,1000,0.02],[2,1.24,0]],"ltp":1.22,"tv":7156.44,"id":6596286}]}]}
{"op":"mcm","clk":"1004012944","pt":1580618198354,"mc":[{"id":"1.168237330","rc":[{"batl":[[0,1.18,3046.37],[1,1.19,2861.58],[2,1.22,34.07]],"ltp":1.22,"tv":7156.44,"id":6596286}]}]}
{"op":"mcm","clk":"1004013477","pt":1580618210891,"mc":[{"id":"1.168237330","rc":[{"trd":[[1.16,1.32]],"batb":[[0,1.16,1890.27]],"ltp":1.16,"tv":7157.76,"id":6596286}],"tv":9236.82}]}
{"op":"mcm","clk":"1004013988","pt":1580618223568,"mc":[{"id":"1.168237330","rc":[{"trd":[[1.16,20.82]],"batb":[[0,1.16,1880.52]],"ltp":1.16,"tv":7177.26,"id":6596286}],"tv":9256.32}]}
{"op":"mcm","clk":"1004014066","pt":1580618224913,"mc":[{"id":"1.168237330","rc":[{"trd":[[1.18,0.78]],"batl":[[0,1.18,3045.98]],"ltp":1.18,"tv":7178.04,"id":6596286}],"tv":9257.1}]}
{"op":"mcm","clk":"1004014423","pt":1580618232717,"mc":[{"id":"1.168237330","rc":[{"trd":[[1.18,8.78]],"batl":[[0,1.18,3041.98]],"ltp":1.18,"tv":7186.04,"id":6596286}],"tv":9265.1}]}
{"op":"mcm","clk":"1004014558","pt":1580618236207,"mc":[{"id":"1.168237330","rc":[{"trd":[[1.18,160.34]],"batl":[[0,1.18,2966.2]],"ltp":1.18,"tv":7337.59,"id":6596286}],"tv":9416.65}]}
{"op":"mcm","clk":"1004014793","pt":1580618241648,"mc":[{"id":"1.168237330","rc":[{"batb":[[0,1.16,1962.12]],"batl":[[1,1.19,2930.92]],"ltp":1.18,"tv":7337.59,"id":6596286}]}]}
{"op":"mcm","clk":"1004015948","pt":1580618267478,"mc":[{"id":"1.168237330","rc":[{"trd":[[1.18,1336.62]],"batb":[[1,1.15,3503.94]],"batl":[[0,1.18,2378.06]],"ltp":1.18,"tv":8513.87,"id":6596286}],"tv":10592.93}]}
{"op":"mcm","clk":"1004016145","pt":1580618272363,"mc":[{"id":"1.168237330","rc":[{"batb":[[0,1.16,2560.74]],"ltp":1.18,"tv":8513.87,"id":6596286}]}]}
{"op":"mcm","clk":"1004016586","pt":1580618283408,"mc":[{"id":"1.168237330","rc":[{"batb":[[2,1.01,13.11]],"ltp":1.18,"tv":8513.87,"id":6596286}]}]}
{"op":"mcm","clk":"1004016715","pt":1580618286907,"mc":[{"id":"1.168237330","rc":[{"batl":[[2,1000,0.02]],"ltp":1.18,"tv":8513.87,"id":6596286}]}]}
{"op":"mcm","clk":"1004016925","pt":1580618292008,"mc":[{"id":"1.168237330","rc":[{"trd":[[1.16,88.97]],"batb":[[0,1.16,2526.65]],"ltp":1.16,"tv":8582.03,"id":6596286}],"tv":10661.09}]}
{"op":"mcm","clk":"1004017947","pt":1580618320915,"mc":[{"id":"1.168237330","rc":[{"trd":[[1.16,98.06]],"batb":[[0,1.16,2522.11]],"ltp":1.16,"tv":8591.11,"id":6596286}],"tv":10670.17}]}
{"op":"mcm","clk":"1004018592","pt":1580618337433,"mc":[{"id":"1.168237330","rc":[{"batb":[[2,1.02,5.9]],"ltp":1.16,"tv":8591.11,"id":6596286}]}]}
{"op":"mcm","clk":"1004023937","pt":1580618454643,"mc":[{"id":"1.168237330","rc":[{"trd":[[1.16,101.42]],"batb":[[0,1.16,2520.43]],"ltp":1.16,"tv":8594.47,"id":6596286}],"tv":10673.53}]}
{"op":"mcm","clk":"1004024706","pt":1580618470518,"mc":[{"id":"1.168237330","rc":[{"batb":[[0,1.02,5.9],[1,1.01,12.51],[2,1.02,0]],"batl":[[0,1000,0.02],[1,1.19,0],[2,1000,0]],"ltp":1.16,"tv":8594.47,"id":6596286}]}]}
{"op":"mcm","clk":"1004024930","pt":1580618475404,"mc":[{"id":"1.168237330","rc":[{"batb":[[0,1.14,1681.29],[1,1.13,4498.52],[2,1.02,5.9]],"batl":[[0,1.21,1744.92],[1,1.22,2525.04],[2,1000,0.02]],"ltp":1.16,"tv":8594.47,"id":6596286}]}]}
{"op":"mcm","clk":"1004025474","pt":1580618486351,"mc":[{"id":"1.168237330","rc":[{"batl":[[0,1000,0.02],[1,1.22,0],[2,1000,0]],"ltp":1.16,"tv":8594.47,"id":6596286}]}]}
{"op":"mcm","clk":"1004025706","pt":1580618491238,"mc":[{"id":"1.168237330","rc":[{"batl":[[0,1.16,4149.65],[1,1.17,1868.72],[2,1000,0.02]],"ltp":1.16,"tv":8594.47,"id":6596286}]}]}
{"op":"mcm","clk":"1004025949","pt":1580618496274,"mc":[{"id":"1.168237330","rc":[{"batb":[[0,1.02,5.9],[1,1.01,12.51],[2,1.02,0]],"batl":[[0,1000,0.02],[1,1.17,0],[2,1000,0]],"ltp":1.16,"tv":8594.47,"id":6596286}]}]}
{"op":"mcm","clk":"1004026223","pt":1580618501271,"mc":[{"id":"1.168237330","rc":[{"batb":[[0,1.12,2258.26],[1,1.11,4027.7],[2,1.02,5.9]],"batl":[[0,1.18,1346.2],[1,1.19,3007.24],[2,1000,0.02]],"ltp":1.16,"tv":8594.47,"id":6596286}]}]}
{"op":"mcm","clk":"1004026456","pt":1580618505077,"mc":[{"id":"1.168237330","rc":[{"batl":[[0,1000,0.02],[1,1.19,0],[2,1000,0]],"ltp":1.16,"tv":8594.47,"id":6596286}]}]}
{"op":"mcm","clk":"1004026710","pt":1580618509907,"mc":[{"id":"1.168237330","rc":[{"batl":[[0,1.14,4899.14],[1,1.15,1230.41],[2,1000,0.02]],"ltp":1.16,"tv":8594.47,"id":6596286}]}]}
{"op":"mcm","clk":"1004027222","pt":1580618519415,"mc":[{"id":"1.168237330","rc":[{"batb":[[0,1.02,5.9],[1,1.01,12.51],[2,1.02,0]],"batl":[[0,1000,0.02],[1,1.15,0],[2,1000,0]],"ltp":1.16,"tv":8594.47,"id":6596286}]}]}
{"op":"mcm","clk":"1004027534","pt":1580618524407,"mc":[{"id":"1.168237330","rc":[{"batb":[[0,1.1,6363.73],[1,1.02,5.8],[2,1.01,12.51]],"batl":[[0,1.16,4259.35],[1,1.17,1759.96],[2,1000,0.02]],"ltp":1.16,"tv":8594.47,"id":6596286}]}]}
{"op":"mcm","clk":"1004027672","pt":1580618526620,"mc":[{"id":"1.168237330","rc":[{"batb":[[0,1.02,5.9],[1,1.01,12.51],[2,1.01,0]],"ltp":1.16,"tv":8594.47,"id":6596286}]}]}
{"op":"mcm","clk":"1004027924","pt":1580618531503,"mc":[{"id":"1.168237330","rc":[{"batb":[[0,1.14,1558.05],[1,1.13,4622.85],[2,1.02,5.9]],"ltp":1.16,"tv":8594.47,"id":6596286}]}]}
{"op":"mcm","clk":"1004028520","pt":1580618541625,"mc":[{"id":"1.168237330","rc":[{"batb":[[0,1.02,5.9],[1,1.01,12.51],[2,1.02,0]],"batl":[[0,1000,0.02],[1,1.17,0],[2,1000,0]],"ltp":1.16,"tv":8594.47,"id":6596286}]}]}
{"op":"mcm","clk":"1004029140","pt":1580618553646,"mc":[{"id":"1.168237330","rc":[{"batb":[[0,1.11,6306.3],[1,1.02,5.9],[2,1.01,12.51]],"batl":[[0,1.19,3223.89],[1,1.2,2636.3],[2,1000,0.02]],"ltp":1.16,"tv":8594.47,"id":6596286}]}]}
{"op":"mcm","clk":"1004029838","pt":1580618566449,"mc":[{"id":"1.168237330","rc":[{"batb":[[0,1.02,5.9],[1,1.01,12.51],[2,1.01,0]],"ltp":1.16,"tv":8594.47,"id":6596286}]}]}
{"op":"mcm","clk":"1004030079","pt":1580618571387,"mc":[{"id":"1.168237330","rc":[{"batb":[[0,1.17,1198.62],[1,1.16,3803.72],[2,1.02,5.9]],"ltp":1.16,"tv":8594.47,"id":6596286}]}]}
{"op":"mcm","clk":"1004030616","pt":1580618581309,"mc":[{"id":"1.168237330","rc":[{"batb":[[0,1.02,5.9],[1,1.01,12.51],[2,1.02,0]],"batl":[[0,1000,0.02],[1,1.2,0],[2,1000,0]],"ltp":1.16,"tv":8594.47,"id":6596286}]}]}
{"op":"mcm","clk":"1004030869","pt":1580618586296,"mc":[{"id":"1.168237330","rc":[{"batb":[[0,1.13,4568.3],[1,1.12,1640.91],[2,1.02,5.9]],"batl":[[0,1.23,1053.47],[1,1.24,2298.31],[2,1000,0.02]],"ltp":1.16,"tv":8594.47,"id":6596286}]}]}
{"op":"mcm","clk":"1004031299","pt":1580618593112,"mc":[{"id":"1.168237330","rc":[{"batb":[[0,1.02,5.9],[1,1.01,12.51],[2,1.02,0]],"batl":[[0,1000,0.02],[1,1.24,0],[2,1000,0]],"ltp":1.16,"tv":8594.47,"id":6596286}]}]}
{"op":"mcm","clk":"1004031682","pt":1580618601107,"mc":[{"id":"1.168237330","rc":[{"batb":[[0,1.13,4568.3],[1,1.12,1640.91],[2,1.02,5.9]],"batl":[[0,1.23,1053.47],[1,1.24,2298.31],[2,1000,0.02]],"ltp":1.16,"tv":8594.47,"id":6596286}]}]}
{"op":"mcm","clk":"1004032102","pt":1580618609504,"mc":[{"id":"1.168237330","rc":[{"trd":[[1.23,119.72]],"batl":[[0,1.23,945.75]],"ltp":1.23,"tv":8702.19,"id":6596286},{"trd":[[5.3,25]],"ltp":5.3,"tv":2104.05,"id":8196374}],"tv":10806.25}]}
{"op":"mcm","clk":"1004032133","pt":1580618610025,"mc":[{"id":"1.168237330","rc":[{"batb":[[1,1.12,1522]],"ltp":1.23,"tv":8702.19,"id":6596286}]}]}
{"op":"mcm","clk":"1004032321","pt":1580618613434,"mc":[{"id":"1.168237330","rc":[{"trd":[[1.23,120.7]],"batl":[[0,1.23,945.26]],"ltp":1.23,"tv":8703.17,"id":6596286}],"tv":10807.23}]}
{"op":"mcm","clk":"1004032404","pt":1580618614925,"mc":[{"id":"1.168237330","rc":[{"batb":[[0,1.13,4686.15]],"ltp":1.23,"tv":8703.17,"id":6596286}]}]}
{"op":"mcm","clk":"1004032449","pt":1580618615695,"mc":[{"id":"1.168237330","rc":[{"batl":[[0,1000,0.02],[1,1.24,0],[2,1000,0]],"ltp":1.23,"tv":8703.17,"id":6596286}]}]}
{"op":"mcm","clk":"1004032717","pt":1580618620738,"mc":[{"id":"1.168237330","rc":[{"batl":[[0,1.15,2071.71],[1,1.16,3618.53],[2,1000,0.02]],"ltp":1.23,"tv":8703.17,"id":6596286}]}]}
{"op":"mcm","clk":"1004033269","pt":1580618630919,"mc":[{"id":"1.168237330","rc":[{"batb":[[0,1.02,5.9],[1,1.01,12.51],[2,1.02,0]],"batl":[[0,1000,0.02],[1,1.16,0],[2,1000,0]],"ltp":1.23,"tv":8703.17,"id":6596286},{"batl":[[0,7.6,5],[1,1000,0.02]],"ltp":5.3,"tv":2104.05,"id":8196374}]}]}
{"op":"mcm","clk":"1004033455","pt":1580618634730,"mc":[{"id":"1.168237330","rc":[{"batl":[[0,1000,0.02],[1,1000,0]],"ltp":5.3,"tv":2104.05,"id":8196374}]}]}
{"op":"mcm","clk":"1004033504","pt":1580618635756,"mc":[{"id":"1.168237330","rc":[{"batb":[[0,1.11,1156.3],[1,1.1,5196.92],[2,1.02,5.8]],"batl":[[0,1.19,2364.9],[1,1.2,2795.28],[2,1000,0.02]],"ltp":1.23,"tv":8703.17,"id":6596286}]}]}
{"op":"mcm","clk":"1004034477","pt":1580618654879,"mc":[{"id":"1.168237330","rc":[{"batl":[[0,1000,0.02],[1,1.2,0],[2,1000,0]],"ltp":1.23,"tv":8703.17,"id":6596286}]}]}
{"op":"mcm","clk":"1004034695","pt":1580618659877,"mc":[{"id":"1.168237330","rc":[{"batl":[[0,1.12,2071.45],[1,1.13,4141.57],[2,1000,0.02]],"ltp":1.23,"tv":8703.17,"id":6596286}]}]}
{"op":"mcm","clk":"1004035152","pt":1580618669980,"mc":[{"id":"1.168237330","rc":[{"batb":[[0,1.02,5.9],[1,1.01,12.51],[2,1.02,0]],"batl":[[0,1000,0.02],[1,1.13,0],[2,1000,0]],"ltp":1.23,"tv":8703.17,"id":6596286}]}]}
{"op":"mcm","clk":"1004035404","pt":1580618674878,"mc":[{"id":"1.168237330","rc":[{"batb":[[0,1.09,1998.3],[1,1.08,4464.77],[2,1.02,5.8]],"batl":[[0,1.15,4546.68],[1,1.16,1526.99],[2,1000,0.02]],"ltp":1.23,"tv":8703.17,"id":6596286}]}]}
{"op":"mcm","clk":"1004036359","pt":1580618695912,"mc":[{"id":"1.168237330","rc":[{"trd":[[1.15,600]],"batb":[[1,1.08,4144.94]],"batl":[[0,1.15,4246.68]],"ltp":1.15,"tv":9303.17,"id":6596286}],"tv":11407.23}]}
{"op":"mcm","clk":"1004036589","pt":1580618700909,"mc":[{"id":"1.168237330","rc":[{"batb":[[0,1.09,2315.2]],"batl":[[1,1.16,1824.41]],"ltp":1.15,"tv":9303.17,"id":6596286}]}]}
{"op":"mcm","clk":"1004036671","pt":1580618702616,"mc":[{"id":"1.168237330","rc":[{"batl":[[0,11,20],[1,1000,0.02]],"ltp":5.3,"tv":2104.05,"id":8196374}]}]}
{"op":"mcm","clk":"1004037705","pt":1580618723354,"mc":[{"id":"1.168237330","rc":[{"trd":[[1.15,617.5]],"batl":[[0,1.15,4237.93]],"ltp":1.15,"tv":9320.67,"id":6596286}],"tv":11424.73}]}
{"op":"mcm","clk":"1004038126","pt":1580618731562,"mc":[{"id":"1.168237330","rc":[{"batl":[[0,1000,0.02],[1,1.16,0],[2,1000,0]],"ltp":1.15,"tv":9320.67,"id":6596286}]}]}
{"op":"mcm","clk":"1004038352","pt":1580618736953,"mc":[{"id":"1.168237330","rc":[{"trd":[[1.1,225.94]],"batb":[[0,1.09,2315.1],[1,1.08,3931.76]],"batl":[[0,1.1,1923.12],[1,1.11,4189.46],[2,1000,0.02]],"ltp":1.1,"tv":9546.61,"id":6596286},{"trd":[[11,20]],"batl":[[0,1000,0.02],[1,1000,0]],"ltp":11.0,"tv":2124.05,"id":8196374}],"tv":11670.67}]}
{"op":"mcm","clk":"1004038591","pt":1580618741639,"mc":[{"id":"1.168237330","rc":[{"batb":[[0,1.09,2526.32]],"batl":[[1,1.11,4387.75]],"ltp":1.1,"tv":9546.61,"id":6596286}]}]}
{"op":"mcm","clk":"1004038808","pt":1580618746571,"mc":[{"id":"1.168237330","rc":[{"batb":[[0,1.02,5.8],[1,1.01,12.51],[2,1.02,0]],"batl":[[0,1000,0.02],[1,1.11,0],[2,1000,0]],"ltp":1.1,"tv":9546.61,"id":6596286}]}]}
{"op":"mcm","clk":"1004038949","pt":1580618749340,"mc":[{"id":"1.168237330","rc":[{"batb":[[0,1.02,6.09]],"ltp":1.1,"tv":9546.61,"id":6596286}]}]}
{"op":"mcm","clk":"1004039058","pt":1580618751447,"mc":[{"id":"1.168237330","rc":[{"batb":[[0,1.07,5754.23],[1,1.02,5.8],[2,1.01,12.51]],"batl":[[0,1.12,1094.46],[1,1.13,4590.69],[2,1000,0.02]],"ltp":1.1,"tv":9546.61,"id":6596286}]}]}
{"op":"mcm","clk":"1004039577","pt":1580618761244,"mc":[{"id":"1.168237330","rc":[{"batb":[[0,1.02,6.09],[1,1.01,12.51],[2,1.01,0]],"batl":[[0,1000,0.02],[1,1.13,0],[2,1000,0]],"ltp":1.1,"tv":9546.61,"id":6596286}]}]}
{"op":"mcm","clk":"1004039840","pt":1580618766180,"mc":[{"id":"1.168237330","rc":[{"trd":[[1.1,226.53]],"batb":[[0,1.02,5.8]],"ltp":1.1,"tv":9547.19,"id":6596286}],"tv":11671.25}]}
{"op":"mcm","clk":"1004040001","pt":1580618769067,"mc":[{"id":"1.168237330","rc":[{"batb":[[0,1.07,5753.94],[1,1.02,5.8],[2,1.01,12.51]],"batl":[[0,1.12,1094.46],[1,1.13,4590.69],[2,1000,0.02]],"ltp":1.1,"tv":9547.19,"id":6596286}]}]}
{"op":"mcm","clk":"1004040501","pt":1580618778278,"mc":[{"id":"1.168237330","rc":[{"batb":[[0,1.1,300],[1,1.07,5753.94],[2,1.02,5.8]],"ltp":1.1,"tv":9547.19,"id":6596286}]}]}
{"op":"mcm","clk":"1004040633","pt":1580618780487,"mc":[{"id":"1.168237330","rc":[{"batb":[[1,1.02,5.8],[2,1.01,12.51]],"ltp":1.1,"tv":9547.19,"id":6596286}]}]}
{"op":"mcm","clk":"1004040888","pt":1580618785414,"mc":[{"id":"1.168237330","rc":[{"batb":[[0,1.11,2175.45],[1,1.1,4468.4],[2,1.02,5.8]],"ltp":1.1,"tv":9547.19,"id":6596286}]}]}
{"op":"mcm","clk":"1004040954","pt":1580618786496,"mc":[{"id":"1.168237330","rc":[{"trd":[[1.12,41.07]],"batl":[[0,1.12,1053.39]],"ltp":1.12,"tv":9588.26,"id":6596286},{"trd":[[9.2,5]],"ltp":9.2,"tv":2129.05,"id":8196374}],"tv":11717.32}]}
{"op":"mcm","clk":"1004041126","pt":1580618790418,"mc":[{"id":"1.168237330","rc":[{"trd":[[1.12,41.27]],"batl":[[0,1.12,1053.29]],"ltp":1.12,"tv":9588.46,"id":6596286}],"tv":11717.52}]}
{"op":"mcm","clk":"1004041363","pt":1580618795610,"mc":[{"id":"1.168237330","rc":[{"batb":[[0,1.1,300],[1,1.02,5.8],[2,1.01,12.51]],"batl":[[0,1000,0.02],[1,1.13,0],[2,1000,0]],"ltp":1.12,"tv":9588.46,"id":6596286}]}]}
{"op":"mcm","clk":"1004041585","pt":1580618800493,"mc":[{"id":"1.168237330","rc":[{"batb":[[1,1.09,1115.76],[2,1.08,5355.39]],"batl":[[0,1.15,2251.39],[1,1.16,3583.4],[2,1000,0.02]],"ltp":1.12,"tv":9588.46,"id":6596286}]}]}
{"op":"mcm","clk":"1004041996","pt":1580618810137,"mc":[{"id":"1.168237330","rc":[{"batl":[[0,1000,0.02],[1,1.16,0],[2,1000,0]],"ltp":1.12,"tv":9588.46,"id":6596286}]}]}
{"op":"mcm","clk":"1004042216","pt":1580618815212,"mc":[{"id":"1.168237330","rc":[{"trd":[[1.1,826.53]],"batb":[[0,1.09,1115.76],[1,1.08,5049.83],[2,1.02,5.8]],"batl":[[0,1.1,2912.28],[1,1.11,3122.96],[2,1000,0.02]],"ltp":1.1,"tv":10188.46,"id":6596286}],"tv":12317.52}]}
{"op":"mcm","clk":"1004042494","pt":1580618820148,"mc":[{"id":"1.168237330","rc":[{"batb":[[0,1.09,1418.51]],"batl":[[1,1.11,3420.26]],"ltp":1.1,"tv":10188.46,"id":6596286}]}]}
{"op":"mcm","clk":"1004042653","pt":1580618823131,"mc":[{"id":"1.168237330","rc":[{"batl":[[2,1.14,3.2]],"ltp":1.1,"tv":10188.46,"id":6596286}]}]}
{"op":"mcm","clk":"1004042752","pt":1580618825245,"mc":[{"id":"1.168237330","rc":[{"batb":[[0,1.02,5.8],[1,1.01,12.51],[2,1.02,0]],"batl":[[0,1.14,3.2],[1,1000,0.02],[2,1.14,0]],"ltp":1.1,"tv":10188.46,"id":6596286}]}]}
{"op":"mcm","clk":"1004043011","pt":1580618830129,"mc":[{"id":"1.168237330","rc":[{"batb":[[0,1.07,1861.79],[1,1.06,4724.41],[2,1.02,5.8]],"batl":[[0,1.13,4932.19],[1,1.14,1254.62],[2,1000,0.02]],"ltp":1.1,"tv":10188.46,"id":6596286}]}]}
{"op":"mcm","clk":"1004044335","pt":1580618862315,"mc":[{"id":"1.168237330","rc":[{"batb":[[0,1.02,5.8],[1,1.01,12.51],[2,1.02,0]],"ltp":1.1,"tv":10188.46,"id":6596286}]}]}
{"op":"mcm","clk":"1004044508","pt":1580618867204,"mc":[{"id":"1.168237330","rc":[{"batb":[[0,1.11,2990.86],[1,1.1,3345.58],[2,1.02,5.8]],"ltp":1.1,"tv":10188.46,"id":6596286}]}]}
{"op":"mcm","clk":"1004044926","pt":1580618877229,"mc":[{"id":"1.168237330","rc":[{"batb":[[0,1.02,5.8],[1,1.01,12.51],[2,1.02,0]],"batl":[[0,1.14,3.2],[1,1000,0.02],[2,1000,0]],"ltp":1.1,"tv":10188.46,"id":6596286}]}]}
{"op":"mcm","clk":"1004045152","pt":1580618882124,"mc":[{"id":"1.168237330","rc":[{"batb":[[0,1.08,5657.99],[1,1.02,5.8],[2,1.01,12.51]],"batl":[[0,1.11,9.75],[1,1.14,3.2],[2,1.16,2594.73]],"ltp":1.1,"tv":10188.46,"id":6596286}]}]}
{"op":"mcm","clk":"1004045455","pt":1580618888326,"mc":[{"id":"1.168237330","rc":[{"batl":[[0,1.14,3.2],[1,1.16,2594.73],[2,1.17,3318.03]],"ltp":1.1,"tv":10188.46,"id":6596286}]}]}
{"op":"mcm","clk":"1004045535","pt":1580618889562,"mc":[{"id":"1.168237330","rc":[{"batb":[[0,1.02,5.8],[1,1.01,12.51],[2,1.01,0]],"batl":[[1,1000,0.02],[2,1.17,0]],"ltp":1.1,"tv":10188.46,"id":6596286}]}]}
{"op":"mcm","clk":"1004045940","pt":1580618897462,"mc":[{"id":"1.168237330","rc":[{"batb":[[0,1.08,5657.99],[1,1.02,5.8],[2,1.01,12.51]],"batl":[[1,1.16,2594.73],[2,1.17,3318.03]],"ltp":1.1,"tv":10188.46,"id":6596286}]}]}
{"op":"mcm","clk":"1004046120","pt":1580618901379,"mc":[{"id":"1.168237330","rc":[{"batl":[[1,1000,0.02],[2,1.17,0]],"ltp":1.1,"tv":10188.46,"id":6596286}]}]}
{"op":"mcm","clk":"1004046376","pt":1580618906177,"mc":[{"id":"1.168237330","rc":[{"batl":[[0,1.1,6072.56],[1,1.14,3.2],[2,1000,0.02]],"ltp":1.1,"tv":10188.46,"id":6596286}]}]}
{"op":"mcm","clk":"1004046866","pt":1580618916331,"mc":[{"id":"1.168237330","rc":[{"batb":[[0,1.02,5.8],[1,1.01,12.51],[2,1.01,0]],"batl":[[0,1.14,3.2],[1,1000,0.02],[2,1000,0]],"ltp":1.1,"tv":10188.46,"id":6596286}]}]}
{"op":"mcm","clk":"1004047000","pt":1580618919118,"mc":[{"id":"1.168237330","rc":[{"batl":[[0,1000,0.02],[1,1000,0]],"ltp":1.1,"tv":10188.46,"id":6596286}]}]}
{"op":"mcm","clk":"1004047096","pt":1580618921225,"mc":[{"id":"1.168237330","rc":[{"batb":[[0,1.06,1134.64],[1,1.05,5521.22],[2,1.02,5.8]],"batl":[[0,1.13,4444.05],[1,1.14,1735.28],[2,1000,0.02]],"ltp":1.1,"tv":10188.46,"id":6596286}]}]}
{"op":"mcm","clk":"1004047223","pt":1580618924420,"mc":[{"id":"1.168237330","rc":[{"batb":[[0,1.02,5.8],[1,1.01,12.51],[2,1.02,0]],"batl":[[0,1.09,3.2],[1,1000,0.02],[2,1000,0]],"ltp":1.1,"tv":10188.46,"id":6596286}]}]}
{"op":"mcm","clk":"1004047574","pt":1580618932459,"mc":[{"id":"1.168237330","rc":[{"batb":[[0,1.06,1134.64],[1,1.05,5521.22],[2,1.02,5.8]],"batl":[[1,1.13,4444.05],[2,1.14,1735.28]],"ltp":1.1,"tv":10188.46,"id":6596286}]}]}
{"op":"mcm","clk":"1004049139","pt":1580618966419,"mc":[{"id":"1.168237330","rc":[{"batb":[[0,1.02,5.8],[1,1.01,12.51],[2,1.02,0]],"ltp":1.1,"tv":10188.46,"id":6596286}]}]}
{"op":"mcm","clk":"1004049277","pt":1580618969619,"mc":[{"id":"1.168237330","rc":[{"batl":[[0,1.06,126.63],[1,1.09,3.2],[2,1.13,4444.05]],"ltp":1.1,"tv":10188.46,"id":6596286}]}]}
{"op":"mcm","clk":"1004049344","pt":1580618971628,"mc":[{"id":"1.168237330","rc":[{"trd":[[1.06,253.39],[1.09,6.4]],"batb":[[0,1.11,3427.91],[1,1.1,2773.42],[2,1.02,5.8]],"batl":[[0,1.13,4444.05],[1,1.14,1613.49],[2,1000,0.02]],"ltp":1.09,"tv":10448.24,"id":6596286}],"tv":12577.3}]}
{"op":"mcm","clk":"1004049372","pt":1580618972296,"mc":[{"id":"1.168237330","rc":[{"batb":[[2,1.02,5.9]],"ltp":1.09,"tv":10448.24,"id":6596286}]}]}
{"op":"mcm","clk":"1004049540","pt":1580618976523,"mc":[{"id":"1.168237330","rc":[{"batb":[[1,1.1,2898.54]],"batl":[[0,1.13,4566.92]],"ltp":1.09,"tv":10448.24,"id":6596286}]}]}
{"op":"mcm","clk":"1004049673","pt":1580618980630,"mc":[{"id":"1.168237330","rc":[{"trd":[[1.11,19.5]],"batb":[[0,1.11,3418.16]],"ltp":1.11,"tv":10467.74,"id":6596286}],"tv":12596.8}]}
{"op":"mcm","clk":"1004049722","pt":1580618981601,"mc":[{"id":"1.168237330","rc":[{"batb":[[0,1.02,5.9],[1,1.01,12.51],[2,1.02,0]],"batl":[[0,1000,0.02],[1,1.14,0],[2,1000,0]],"ltp":1.11,"tv":10467.74,"id":6596286}]}]}
{"op":"mcm","clk":"1004049890","pt":1580618986531,"mc":[{"id":"1.168237330","rc":[{"batb":[[0,1.08,6115.62],[1,1.02,5.8],[2,1.01,12.51]],"batl":[[0,1.16,2281.65],[1,1.17,3337.94],[2,1000,0.02]],"ltp":1.11,"tv":10467.74,"id":6596286}]}]}
{"op":"mcm","clk":"1004050140","pt":1580618993614,"mc":[{"id":"1.168237330","rc":[{"batb":[[0,1.02,5.9],[1,1.01,12.51],[2,1.01,0]],"batl":[[0,1000,0.02],[1,1.17,0],[2,1000,0]],"ltp":1.11,"tv":10467.74,"id":6596286}]}]}
{"op":"mcm","clk":"1004050436","pt":1580619001462,"mc":[{"id":"1.168237330","rc":[{"batb":[[0,1.08,6115.62],[1,1.02,5.8],[2,1.01,12.51]],"batl":[[0,1.16,2281.65],[1,1.17,3337.94],[2,1000,0.02]],"ltp":1.11,"tv":10467.74,"id":6596286}]}]}
{"op":"mcm","clk":"1004051240","pt":1580619024390,"mc":[{"id":"1.168237330","rc":[{"batb":[[0,1.02,5.9],[1,1.01,12.51],[2,1.01,0]],"ltp":1.11,"tv":10467.74,"id":6596286}]}]}
{"op":"mcm","clk":"1004051407","pt":1580619029256,"mc":[{"id":"1.168237330","rc":[{"batb":[[0,1.14,3692.19],[1,1.13,2469.82],[2,1.02,5.9]],"ltp":1.11,"tv":10467.74,"id":6596286}]}]}
{"op":"mcm","clk":"1004051841","pt":1580619039389,"mc":[{"id":"1.168237330","rc":[{"batb":[[0,1.02,5.9],[1,1.01,12.51],[2,1.02,0]],"batl":[[0,1000,0.02],[1,1.17,0],[2,1000,0]],"ltp":1.11,"tv":10467.74,"id":6596286}]}]}
{"op":"mcm","clk":"1004052029","pt":1580619044313,"mc":[{"id":"1.168237330","rc":[{"batb":[[0,1.11,3851.82],[1,1.1,2476.79],[2,1.02,5.9]],"batl":[[0,1.2,2659.42],[1,1.21,2608.25],[2,1000,0.02]],"ltp":1.11,"tv":10467.74,"id":6596286}]}]}
{"op":"mcm","clk":"1004052142","pt":1580619047189,"mc":[{"id":"1.168237330","rc":[{"batl":[[0,1.14,15.14],[1,1.2,2659.42],[2,1.21,2608.25]],"ltp":1.11,"tv":10467.74,"id":6596286}]}]}
{"op":"mcm","clk":"1004052318","pt":1580619051209,"mc":[{"id":"1.168237330","rc":[{"batb":[[0,1.02,5.9],[1,1.01,12.51],[2,1.02,0]],"batl":[[1,1000,0.02],[2,1.21,0]],"ltp":1.11,"tv":10467.74,"id":6596286}]}]}
{"op":"mcm","clk":"1004052473","pt":1580619056136,"mc":[{"id":"1.168237330","rc":[{"trd":[[1.14,30.28]],"batb":[[0,1.14,3677.05],[1,1.13,2469.82],[2,1.02,5.9]],"batl":[[0,1.16,2281.65],[1,1.17,3337.94],[2,1000,0.02]],"ltp":1.14,"tv":10498.03,"id":6596286}],"tv":12627.09}]}
{"op":"mcm","clk":"1004052651","pt":1580619062408,"mc":[{"id":"1.168237330","rc":[{"batb":[[0,1.02,5.9],[1,1.01,12.51],[2,1.02,0]],"batl":[[0,1000,0.02],[1,1.17,0],[2,1000,0]],"ltp":1.14,"tv":10498.03,"id":6596286}]}]}
{"op":"mcm","clk":"1004052678","pt":1580619063125,"mc":[{"id":"1.168237330","rc":[{"batl":[[0,1.15,2],[1,1000,0.02]],"ltp":1.14,"tv":10498.03,"id":6596286}]}]}
{"op":"mcm","clk":"1004052842","pt":1580619067342,"mc":[{"id":"1.168237330","rc":[{"batb":[[0,1.11,3836.26],[1,1.1,2492.5],[2,1.02,5.9]],"batl":[[1,1.2,2673.86],[2,1.21,2608.28]],"ltp":1.14,"tv":10498.03,"id":6596286}]}]}
{"op":"mcm","clk":"1004053131","pt":1580619074761,"mc":[{"id":"1.168237330","rc":[{"batb":[[0,1.02,5.9],[1,1.01,12.51],[2,1.02,0]],"ltp":1.14,"tv":10498.03,"id":6596286}]}]}
{"op":"mcm","clk":"1004053311","pt":1580619079554,"mc":[{"id":"1.168237330","rc":[{"trd":[[1.15,621.5]],"batb":[[0,1.18,1345.29],[1,1.17,3521.18],[2,1.02,5.9]],"batl":[[0,1.2,2673.86],[1,1.21,2608.28],[2,1000,0.02]],"ltp":1.15,"tv":10502.03,"id":6596286}],"tv":12631.09}]}
{"op":"mcm","clk":"1004053844","pt":1580619089666,"mc":[{"id":"1.168237330","rc":[{"trd":[[1.2,961.14]],"batb":[[0,1.02,5.9],[1,1.01,12.51],[2,1.02,0]],"batl":[[0,1000,0.02],[1,1.21,0],[2,1000,0]],"ltp":1.2,"tv":10602.03,"id":6596286},{"trd":[[6,20]],"ltp":6.0,"tv":2149.05,"id":8196374}],"tv":12751.09}]}
{"op":"mcm","clk":"1004053912","pt":1580619091366,"mc":[{"id":"1.168237330","rc":[{"batl":[[0,1000,0.12]],"ltp":1.2,"tv":10602.03,"id":6596286}]}]}
{"op":"mcm","clk":"1004054053","pt":1580619094767,"mc":[{"id":"1.168237330","rc":[{"batb":[[0,1.15,3113.88],[1,1.14,2893.75],[2,1.02,5.9]],"batl":[[0,1.24,2834.37],[1,1.25,2120.88],[2,1000,0.02]],"ltp":1.2,"tv":10602.03,"id":6596286}]}]}
{"op":"mcm","clk":"1004054065","pt":1580619095074,"mc":[{"id":"1.168237330","rc":[{"batb":[[0,1.15,3218.36]],"ltp":1.2,"tv":10602.03,"id":6596286}]}]}
{"op":"mcm","clk":"1004054718","pt":1580619111490,"mc":[{"id":"1.168237330","rc":[{"batb":[[0,1.02,5.9],[1,1.01,12.51],[2,1.02,0]],"batl":[[0,1000,0.12],[1,1.25,0],[2,1000,0]],"ltp":1.2,"tv":10602.03,"id":6596286}]}]}
{"op":"mcm","clk":"1004054802","pt":1580619113404,"mc":[{"id":"1.168237330","rc":[{"batb":[[0,1.12,2.09],[1,1.02,5.9],[2,1.01,12.51]],"ltp":1.2,"tv":10602.03,"id":6596286}]}]}
{"op":"mcm","clk":"1004054910","pt":1580619116596,"mc":[{"id":"1.168237330","rc":[{"trd":[[1.18,1336.81]],"batl":[[0,1000,0.02]],"ltp":1.18,"tv":10602.23,"id":6596286}],"tv":12751.29}]}
{"op":"mcm","clk":"1004054969","pt":1580619117989,"mc":[{"id":"1.168237330","rc":[{"batb":[[0,1.15,3218.36],[1,1.14,2893.75],[2,1.12,2.09]],"batl":[[0,1.24,2834.27],[1,1.25,2120.79],[2,1000,0.02]],"ltp":1.18,"tv":10602.23,"id":6596286}]}]}
{"op":"mcm","clk":"1004055036","pt":1580619119793,"mc":[{"id":"1.168237330","rc":[{"batb":[[0,1.12,2.09],[1,1.02,5.9],[2,1.01,12.51]],"ltp":1.18,"tv":10602.23,"id":6596286}]}]}
{"op":"mcm","clk":"1004055054","pt":1580619120466,"mc":[{"id":"1.168237330","rc":[{"batl":[[0,1.15,46.95],[1,1.24,2834.27],[2,1.25,2120.79]],"ltp":1.18,"tv":10602.23,"id":6596286}]}]}
{"op":"mcm","clk":"1004055232","pt":1580619124606,"mc":[{"id":"1.168237330","rc":[{"trd":[[1.15,715.4]],"batb":[[0,1.21,2650.43],[1,1.2,2957.82],[2,1.12,2.09]],"batl":[[0,1.24,2834.27],[1,1.25,2120.79],[2,1000,0.02]],"ltp":1.15,"tv":10696.12,"id":6596286}],"tv":12845.18}]}
{"op":"mcm","clk":"1004055391","pt":1580619127910,"mc":[{"id":"1.168237330","rc":[{"batl":[[0,6,37.86],[1,1000,0.02]],"ltp":6.0,"tv":2149.05,"id":8196374}]}]}
{"op":"mcm","clk":"1004055414","pt":1580619128420,"mc":[{"id":"1.168237330","rc":[{"batl":[[0,1000,0.02],[1,1000,0]],"ltp":6.0,"tv":2149.05,"id":8196374}]}]}
{"op":"mcm","clk":"1004055565","pt":1580619131612,"mc":[{"id":"1.168237330","rc":[{"batb":[[0,1.12,2.09],[1,1.02,5.9],[2,1.01,12.51]],"batl":[[0,1000,0.02],[1,1.25,0],[2,1000,0]],"ltp":1.15,"tv":10696.12,"id":6596286}]}]}
{"op":"mcm","clk":"1004055795","pt":1580619136716,"mc":[{"id":"1.168237330","rc":[{"batl":[[0,1.28,1701.63],[1,1.29,1801.22],[2,1000,0.02]],"ltp":1.15,"tv":10696.12,"id":6596286}]}]}
{"op":"mcm","clk":"1004055916","pt":1580619139193,"mc":[{"id":"1.168237330","rc":[{"batl":[[0,1.21,30.31],[1,1.28,1701.63],[2,1.29,1801.22]],"ltp":1.15,"tv":10696.12,"id":6596286}]}]}
{"op":"mcm","clk":"1004055990","pt":1580619141098,"mc":[{"id":"1.168237330","rc":[{"trd":[[1.21,60.62]],"batb":[[0,1.25,2587.75],[1,1.24,2381.66],[2,1.12,2.09]],"batl":[[0,1.28,1701.63],[1,1.29,1801.22],[2,1000,0.02]],"ltp":1.21,"tv":10756.75,"id":6596286}],"tv":12905.81}]}
{"op":"mcm","clk":"1004056249","pt":1580619146930,"mc":[{"id":"1.168237330","rc":[{"batb":[[0,1.12,2.09],[1,1.02,5.9],[2,1.01,12.51]],"batl":[[0,1000,0.02],[1,1.29,0],[2,1000,0]],"ltp":1.21,"tv":10756.75,"id":6596286}]}]}
{"op":"mcm","clk":"1004056478","pt":1580619151929,"mc":[{"id":"1.168237330","rc":[{"batb":[[0,1.22,2300.61],[1,1.21,2783.23],[2,1.12,2.09]],"batl":[[0,1.32,893.62],[1,1.33,1552.67],[2,1000,0.02]],"ltp":1.21,"tv":10756.75,"id":6596286}]}]}
{"op":"mcm","clk":"1004056490","pt":1580619152136,"mc":[{"id":"1.168237330","rc":[{"batl":[[0,1000,0.02],[1,1.33,0],[2,1000,0]],"ltp":1.21,"tv":10756.75,"id":6596286}]}]}
{"op":"mcm","clk":"1004056557","pt":1580619153836,"mc":[{"id":"1.168237330","rc":[{"batl":[[0,1.25,2],[1,1000,0.02]],"ltp":1.21,"tv":10756.75,"id":6596286}]}]}
{"op":"mcm","clk":"1004056638","pt":1580619156048,"mc":[{"id":"1.168237330","rc":[{"batl":[[0,1.25,2858.7],[1,1.26,2026],[2,1000,0.02]],"ltp":1.21,"tv":10756.75,"id":6596286}]}]}
{"op":"mcm","clk":"1004056951","pt":1580619165126,"mc":[{"id":"1.168237330","rc":[{"batb":[[0,1.12,2.09],[1,1.02,5.9],[2,1.01,12.51]],"batl":[[0,1.25,2],[1,1000,0.02],[2,1000,0]],"ltp":1.21,"tv":10756.75,"id":6596286}]}]}
{"op":"mcm","clk":"1004057151","pt":1580619170059,"mc":[{"id":"1.168237330","rc":[{"batb":[[0,1.18,3626.72],[1,1.17,2325.18],[2,1.12,2.09]],"batl":[[1,1.3,1949.13],[2,1.31,1657.34]],"ltp":1.21,"tv":10756.75,"id":6596286}]}]}
{"op":"mcm","clk":"1004057238","pt":1580619172722,"mc":[{"id":"1.168237330","rc":[{"batb":[[0,1.12,2.09],[1,1.02,5.9],[2,1.01,12.51]],"ltp":1.21,"tv":10756.75,"id":6596286}]}]}
{"op":"mcm","clk":"1004057368","pt":1580619177765,"mc":[{"id":"1.168237330","rc":[{"trd":[[1.25,4]],"batb":[[0,1.27,1834.36],[1,1.26,2145.77],[2,1.12,2.09]],"batl":[[0,1.3,1949.13],[1,1.31,1657.34],[2,1000,0.02]],"ltp":1.25,"tv":10760.75,"id":6596286}],"tv":12909.81}]}
{"op":"mcm","clk":"1004057669","pt":1580619187376,"mc":[{"id":"1.168237330","rc":[{"batb":[[0,1.12,2.09],[1,1.02,5.9],[2,1.01,12.51]],"batl":[[0,1000,0.02],[1,1.31,0],[2,1000,0]],"ltp":1.25,"tv":10760.75,"id":6596286}]}]}
{"op":"mcm","clk":"1004057819","pt":1580619192367,"mc":[{"id":"1.168237330","rc":[{"batb":[[0,1.24,960.25],[1,1.23,2462.98],[2,1.12,2.09]],"batl":[[0,1.35,2059.95],[1,1.36,1377.35],[2,1000,0.02]],"ltp":1.25,"tv":10760.75,"id":6596286}]}]}
{"op":"mcm","clk":"1004057941","pt":1580619196486,"mc":[{"id":"1.168237330","rc":[{"batb":[[2,1.18,2.16]],"batl":[[0,1000,0.02],[1,1.36,0],[2,1000,0]],"ltp":1.25,"tv":10760.75,"id":6596286}]}]}
{"op":"mcm","clk":"1004058069","pt":1580619201054,"mc":[{"id":"1.168237330","rc":[{"batl":[[0,1.26,1521.3],[1,1.27,1967.52],[2,1000,0.02]],"ltp":1.25,"tv":10760.75,"id":6596286}]}]}
{"op":"mcm","clk":"1004058338","pt":1580619209892,"mc":[{"id":"1.168237330","rc":[{"batb":[[0,1.18,2.16],[1,1.12,2.09],[2,1.02,5.9]],"batl":[[0,1000,0.02],[1,1.27,0],[2,1000,0]],"ltp":1.25,"tv":10760.75,"id":6596286}]}]}
{"op":"mcm","clk":"1004058444","pt":1580619212872,"mc":[{"id":"1.168237330","rc":[{"batb":[[0,1.3,25.21],[1,1.18,2.16],[2,1.12,2.09]],"ltp":1.25,"tv":10760.75,"id":6596286}]}]}
{"op":"mcm","clk":"1004058499","pt":1580619214776,"mc":[{"id":"1.168237330","rc":[{"batb":[[1,1.19,967.01],[2,1.18,3284.04]],"batl":[[0,1.33,805.51],[1,1.34,1497.85],[2,1000,0.02]],"ltp":1.25,"tv":10760.75,"id":6596286}]}]}
{"op":"mcm","clk":"1004058603","pt":1580619219608,"mc":[{"id":"1.168237330","rc":[{"trd":[[1.3,50.41]],"batb":[[0,1.19,967.01],[1,1.18,3284.04],[2,1.12,2.09]],"batl":[[0,1.28,21.96],[1,1.33,805.51],[2,1.34,1497.85]],"ltp":1.3,"tv":10811.16,"id":6596286}],"tv":12960.22}]}
{"op":"mcm","clk":"1004058614","pt":1580619220122,"mc":[{"id":"1.168237330","rc":[{"batl":[[0,1.33,805.51],[1,1.34,1497.85],[2,1000,0.02]],"ltp":1.3,"tv":10811.16,"id":6596286}]}]}
{"op":"mcm","clk":"1004058698","pt":1580619222491,"mc":[{"id":"1.168237330","rc":[{"batl":[[0,1000,0.02],[1,1.34,0],[2,1000,0]],"ltp":1.3,"tv":10811.16,"id":6596286}]}]}
{"op":"mcm","clk":"1004058837","pt":1580619227416,"mc":[{"id":"1.168237330","rc":[{"batl":[[0,1.21,2704.79],[1,1.22,2469.73],[2,1000,0.02]],"ltp":1.3,"tv":10811.16,"id":6596286}]}]}
{"op":"mcm","clk":"1004059001","pt":1580619234342,"mc":[{"id":"1.168237330","rc":[{"batb":[[0,1.18,2.16],[1,1.12,2.09],[2,1.02,5.9]],"batl":[[0,1000,0.02],[1,1.22,0],[2,1000,0]],"ltp":1.3,"tv":10811.16,"id":6596286}]}]}
{"op":"mcm","clk":"1004059188","pt":1580619239287,"mc":[{"id":"1.168237330","rc":[{"batb":[[1,1.15,1471.36],[2,1.14,4395.41]],"batl":[[0,1.26,935.5],[1,1.27,1980.74],[2,1000,0.02]],"ltp":1.3,"tv":10811.16,"id":6596286}]}]}
{"op":"mcm","clk":"1004060209","pt":1580619266764,"mc":[{"id":"1.168237330","rc":[{"batl":[[0,1000,0.02],[1,1.27,0],[2,1000,0]],"ltp":1.3,"tv":10811.16,"id":6596286}]}]}
{"op":"mcm","clk":"1004060395","pt":1580619271663,"mc":[{"id":"1.168237330","rc":[{"trd":[[1.18,1341.13]],"batb":[[0,1.15,1471.36],[1,1.14,4395.41],[2,1.12,2.09]],"batl":[[0,1.17,3751.72],[1,1.18,2210.13],[2,1000,0.02]],"ltp":1.18,"tv":10815.48,"id":6596286}],"tv":12964.54}]}
{"op":"mcm","clk":"1004060799","pt":1580619281762,"mc":[{"id":"1.168237330","rc":[{"batb":[[0,1.12,2.09],[1,1.02,5.9],[2,1.01,12.51]],"batl":[[0,1000,0.02],[1,1.18,0],[2,1000,0]],"ltp":1.18,"tv":10815.48,"id":6596286}]}]}
{"op":"mcm","clk":"1004060992","pt":1580619286663,"mc":[{"id":"1.168237330","rc":[{"batb":[[0,1.12,1174.94],[1,1.11,5122.89],[2,1.02,5.9]],"batl":[[0,1.21,1984.03],[1,1.22,2491.84],[2,1000,0.02]],"ltp":1.18,"tv":10815.48,"id":6596286}]}]}
{"op":"mcm","clk":"1004061236","pt":1580619293683,"mc":[{"id":"1.168237330","rc":[{"batb":[[0,1.12,2.09],[1,1.02,5.9],[2,1.01,12.51]],"batl":[[0,1000,0.02],[1,1.22,0],[2,1000,0]],"ltp":1.18,"tv":10815.48,"id":6596286}]}]}
{"op":"mcm","clk":"1004061515","pt":1580619301572,"mc":[{"id":"1.168237330","rc":[{"batb":[[0,1.12,1174.94],[1,1.11,5122.89],[2,1.02,5.9]],"batl":[[0,1.21,1984.03],[1,1.22,2491.84],[2,1000,0.02]],"ltp":1.18,"tv":10815.48,"id":6596286}]}]}
{"op":"mcm","clk":"1004061848","pt":1580619308885,"mc":[{"id":"1.168237330","rc":[{"batb":[[0,1.12,2.09],[1,1.02,5.9],[2,1.01,12.51]],"ltp":1.18,"tv":10815.48,"id":6596286}]}]}
{"op":"mcm","clk":"1004062026","pt":1580619313775,"mc":[{"id":"1.168237330","rc":[{"batb":[[0,1.19,1750.69],[1,1.18,3311.46],[2,1.12,2.09]],"ltp":1.18,"tv":10815.48,"id":6596286}]}]}
{"op":"mcm","clk":"1004062375","pt":1580619323905,"mc":[{"id":"1.168237330","rc":[{"batb":[[0,1.12,2.09],[1,1.02,5.9],[2,1.01,12.51]],"batl":[[0,1000,0.02],[1,1.22,0],[2,1000,0]],"ltp":1.18,"tv":10815.48,"id":6596286}]}]}
{"op":"mcm","clk":"1004062518","pt":1580619328793,"mc":[{"id":"1.168237330","rc":[{"batb":[[0,1.15,2274.09],[1,1.14,3846.31],[2,1.12,2.09]],"batl":[[0,1.27,2276.91],[1,1.28,1867.28],[2,1000,0.02]],"ltp":1.18,"tv":10815.48,"id":6596286}]}]}
{"op":"mcm","clk":"1004062548","pt":1580619329509,"mc":[{"id":"1.168237330","rc":[{"batl":[[0,5.7,6.72],[1,1000,0.02]],"ltp":6.0,"tv":2149.05,"id":8196374}]}]}
{"op":"mcm","clk":"1004062793","pt":1580619337729,"mc":[{"id":"1.168237330","rc":[{"batl":[[0,1000,0.02],[1,1000,0]],"ltp":6.0,"tv":2149.05,"id":8196374}]}]}
{"op":"mcm","clk":"1004063129","pt":1580619349022,"mc":[{"id":"1.168237330","rc":[{"batl":[[0,1000,0.02],[1,1.28,0],[2,1000,0]],"ltp":1.18,"tv":10815.48,"id":6596286}]}]}
{"op":"mcm","clk":"1004063262","pt":1580619354053,"mc":[{"id":"1.168237330","rc":[{"batl":[[0,1.17,3033.46],[1,1.18,2924.45],[2,1000,0.02]],"ltp":1.18,"tv":10815.48,"id":6596286}]}]}
{"op":"mcm","clk":"1004063390","pt":1580619355918,"mc":[{"id":"1.168237330","rc":[{"trd":[[1.17,583.33]],"batb":[[1,1.14,3649.42]],"batl":[[0,1.17,2841.67]],"ltp":1.17,"tv":11007.27,"id":6596286},{"trd":[[6.8,33]],"ltp":6.8,"tv":2182.05,"id":8196374}],"tv":13189.33}]}
{"op":"mcm","clk":"1004063506","pt":1580619359353,"mc":[{"id":"1.168237330","rc":[{"batb":[[0,1.12,2.09],[1,1.02,5.9],[2,1.01,12.51]],"batl":[[0,1000,0.02],[1,1.18,0],[2,1000,0]],"ltp":1.17,"tv":11007.27,"id":6596286}]}]}
