{"op":"mcm","clk":"1001739991","pt":1580639723620,"mc":[{"id":"1.168215938","rc":[{"batb":[[0,1.69,110.64],[1,1.67,182.01],[2,1.01,0.51]],"ltp":1.86,"tv":876.22,"id":13117454}]}]}
{"op":"mcm","clk":"1001740579","pt":1580639728922,"mc":[{"id":"1.168215938","rc":[{"batb":[[0,1.01,0.51],[1,4.1,0],[2,3.9,0]],"ltp":5.0,"tv":105.34,"id":13117455},{"batb":[[0,1.01,0.51],[1,4.9,0],[2,4.8,0]],"ltp":5.1,"tv":23.45,"id":13117503},{"batb":[[0,1.01,0.51],[1,1.67,0],[2,1.01,0]],"ltp":1.86,"tv":876.22,"id":13117454}]}]}
{"op":"mcm","clk":"1001740881","pt":1580639731434,"mc":[{"id":"1.168215938","rc":[{"batb":[[0,4,29.56],[1,3.95,28],[2,1.01,0.51]],"ltp":5.0,"tv":105.34,"id":13117455},{"batb":[[0,4.5,50.66],[1,4.4,43.97],[2,1.01,0.51]],"ltp":5.1,"tv":23.45,"id":13117503},{"batb":[[0,1.65,110.25],[1,1.64,64.35],[2,1.01,0.51]],"ltp":1.86,"tv":876.22,"id":13117454}]}]}
{"op":"mcm","clk":"1001741015","pt":1580639732941,"mc":[{"id":"1.168215938","rc":[{"batb":[[0,1.01,0.51],[1,1.64,0],[2,1.01,0]],"ltp":1.86,"tv":876.22,"id":13117454}]}]}
{"op":"mcm","clk":"1001741292","pt":1580639735931,"mc":[{"id":"1.168215938","rc":[{"batb":[[0,1.8,58.44],[1,1.78,96.09],[2,1.01,0.51]],"ltp":1.86,"tv":876.22,"id":13117454}]}]}
{"op":"mcm","clk":"1001741481","pt":1580639737648,"mc":[{"id":"1.168215938","rc":[{"batb":[[2,3.75,15.12]],"batl":[[0,4.3,12.6]],"ltp":5.0,"tv":105.34,"id":13117455},{"batb":[[0,4.6,10.92],[1,4.5,50.66],[2,4.4,43.97]],"batl":[[0,5.5,9.24]],"ltp":5.1,"tv":23.45,"id":13117503},{"batb":[[2,1.74,56.29]],"batl":[[0,1.89,42.01]],"ltp":1.86,"tv":876.22,"id":13117454}]}]}
{"op":"mcm","clk":"1001742308","pt":1580639745864,"mc":[{"id":"1.168215938","rc":[{"batb":[[0,3.75,15.12],[1,1.01,0.51],[2,3.75,0]],"ltp":5.0,"tv":105.34,"id":13117455},{"batb":[[1,1.01,0.51],[2,4.4,0]],"ltp":5.1,"tv":23.45,"id":13117503},{"batb":[[0,1.74,56.29],[1,1.01,0.51],[2,1.74,0]],"ltp":1.86,"tv":876.22,"id":13117454}]}]}
{"op":"mcm","clk":"1001742389","pt":1580639746801,"mc":[{"id":"1.168215938","rc":[{"batb":[[0,1.01,0.51],[1,1.01,0]],"ltp":5.0,"tv":105.34,"id":13117455},{"batb":[[0,1.01,0.51],[1,1.01,0]],"ltp":5.1,"tv":23.45,"id":13117503},{"batb":[[0,1.01,0.51],[1,1.01,0]],"ltp":1.86,"tv":876.22,"id":13117454}]}]}
{"op":"mcm","clk":"1001742563","pt":1580639748578,"mc":[{"id":"1.168215938","rc":[{"batb":[[0,3.5,37.76],[1,3.45,38.74],[2,1.01,0.51]],"ltp":5.0,"tv":105.34,"id":13117455},{"batb":[[0,3.85,56.13],[1,3.8,31.39],[2,1.01,0.51]],"ltp":5.1,"tv":23.45,"id":13117503},{"batb":[[0,1.7,71.57],[1,1.68,117.16],[2,1.01,0.51]],"ltp":1.86,"tv":876.22,"id":13117454}]}]}
{"op":"mcm","clk":"1001742647","pt":1580639749363,"mc":[{"id":"1.168215938","rc":[{"batb":[[0,1.01,0.51],[1,3.45,0],[2,1.01,0]],"ltp":5.0,"tv":105.34,"id":13117455},{"batb":[[0,1.01,0.51],[1,3.8,0],[2,1.01,0]],"ltp":5.1,"tv":23.45,"id":13117503},{"batb":[[0,1.01,0.51],[1,1.68,0],[2,1.01,0]],"ltp":1.86,"tv":876.22,"id":13117454}]}]}
{"op":"mcm","clk":"1001742974","pt":1580639752552,"mc":[{"id":"1.168215938","rc":[{"batb":[[0,3.85,54.89],[1,3.8,30.48],[2,1.01,0.51]],"ltp":5.0,"tv":105.34,"id":13117455},{"batb":[[0,4.4,30.2],[1,4.3,46.73],[2,1.01,0.51]],"ltp":5.1,"tv":23.45,"id":13117503},{"batb":[[0,1.84,87.49],[1,1.82,89.33],[2,1.01,0.51]],"ltp":1.86,"tv":876.22,"id":13117454}]}]}
{"op":"mcm","clk":"1001743153","pt":1580639754385,"mc":[{"id":"1.168215938","rc":[{"batb":[[0,1.01,0.51],[1,3.8,0],[2,1.01,0]],"ltp":5.0,"tv":105.34,"id":13117455},{"batb":[[0,1.01,0.51],[1,4.3,0],[2,1.01,0]],"ltp":5.1,"tv":23.45,"id":13117503},{"batb":[[0,1.01,0.51],[1,1.82,0],[2,1.01,0]],"ltp":1.86,"tv":876.22,"id":13117454}]}]}
{"op":"mcm","clk":"1001743507","pt":1580639757780,"mc":[{"id":"1.168215938","rc":[{"batb":[[0,1.7,71.57],[1,1.68,117.16],[2,1.01,0.51]],"ltp":1.86,"tv":876.22,"id":13117454}]}]}
{"op":"mcm","clk":"1001743856","pt":1580639760777,"mc":[{"id":"1.168215938","rc":[{"batb":[[0,4.2,63.86],[1,4.1,50],[2,1.01,0.51]],"ltp":5.0,"tv":105.34,"id":13117455},{"batb":[[0,4.9,38.12],[1,4.8,36.16],[2,1.01,0.51]],"ltp":5.1,"tv":23.45,"id":13117503}]}]}
{"op":"mcm","clk":"1001743952","pt":1580639761725,"mc":[{"id":"1.168215938","rc":[{"batb":[[2,3.95,13.44]],"batl":[[0,4.6,10.92]],"ltp":5.0,"tv":105.34,"id":13117455},{"batb":[[1,4.8,47.08]],"batl":[[0,5.8,8.4]],"ltp":5.1,"tv":23.45,"id":13117503},{"batb":[[2,1.67,62.17]],"batl":[[0,1.81,42.01]],"ltp":1.86,"tv":876.22,"id":13117454}]}]}
{"op":"mcm","clk":"1001745813","pt":1580639780784,"mc":[{"id":"1.168215938","rc":[{"batb":[[0,1.01,0.51],[1,4.1,0],[2,3.95,0]],"ltp":5.0,"tv":105.34,"id":13117455},{"batb":[[0,1.01,0.51],[1,4.8,0],[2,1.01,0]],"ltp":5.1,"tv":23.45,"id":13117503},{"batb":[[0,1.01,0.51],[1,1.68,0],[2,1.67,0]],"ltp":1.86,"tv":876.22,"id":13117454}]}]}
{"op":"mcm","clk":"1001746101","pt":1580639783861,"mc":[{"id":"1.168215938","rc":[{"batb":[[0,4,54.81],[1,3.95,27.77],[2,1.01,0.51]],"ltp":5.0,"tv":105.34,"id":13117455},{"batb":[[0,4.5,33.05],[1,4.4,44.24],[2,1.01,0.51]],"ltp":5.1,"tv":23.45,"id":13117503},{"batb":[[0,1.66,90.56],[1,1.65,63.01],[2,1.01,0.51]],"ltp":1.86,"tv":876.22,"id":13117454}]}]}
{"op":"mcm","clk":"1001746633","pt":1580639789590,"mc":[{"id":"1.168215938","rc":[{"batb":[[0,1.01,0.51],[1,3.95,0],[2,1.01,0]],"ltp":5.0,"tv":105.34,"id":13117455},{"batb":[[0,1.01,0.51],[1,4.4,0],[2,1.01,0]],"ltp":5.1,"tv":23.45,"id":13117503}]}]}
{"op":"mcm","clk":"1001746933","pt":1580639792686,"mc":[{"id":"1.168215938","rc":[{"batb":[[0,4.3,62.74],[1,4.2,47.24],[2,1.01,0.51]],"ltp":5.0,"tv":105.34,"id":13117455},{"batb":[[0,5.1,37.94],[1,5,32.95],[2,1.01,0.51]],"ltp":5.1,"tv":23.45,"id":13117503}]}]}
{"op":"mcm","clk":"1001747034","pt":1580639793686,"mc":[{"id":"1.168215938","rc":[{"batb":[[2,4,13.44]],"batl":[[0,4.7,10.92]],"ltp":5.0,"tv":105.34,"id":13117455},{"batb":[[1,5,43.03]],"batl":[[0,6,8.4]],"ltp":5.1,"tv":23.45,"id":13117503},{"batb":[[2,1.64,65.54]],"batl":[[0,1.77,42.01]],"ltp":1.86,"tv":876.22,"id":13117454}]}]}
{"op":"mcm","clk":"1001750552","pt":1580639829765,"mc":[{"id":"1.168215938","rc":[{"batb":[[0,4,13.44],[1,1.01,0.51],[2,4,0]],"ltp":5.0,"tv":105.34,"id":13117455},{"batb":[[0,5,10.08],[1,1.01,0.51],[2,1.01,0]],"ltp":5.1,"tv":23.45,"id":13117503},{"batb":[[0,1.64,65.54],[1,1.01,0.51],[2,1.64,0]],"ltp":1.86,"tv":876.22,"id":13117454}]}]}
{"op":"mcm","clk":"1001750910","pt":1580639832759,"mc":[{"id":"1.168215938","rc":[{"batb":[[0,4,38.67],[1,3.95,27.86],[2,1.01,0.51]],"ltp":5.0,"tv":105.34,"id":13117455},{"batb":[[0,4.6,61.04],[1,4.5,41.5],[2,1.01,0.51]],"ltp":5.1,"tv":23.45,"id":13117503},{"batb":[[0,1.49,95.16],[1,1.48,95.84],[2,1.01,0.51]],"ltp":1.86,"tv":876.22,"id":13117454}]}]}
{"op":"mcm","clk":"1001751145","pt":1580639835261,"mc":[{"id":"1.168215938","rc":[{"batb":[[0,1.01,0.51],[1,3.95,0],[2,1.01,0]],"ltp":5.0,"tv":105.34,"id":13117455},{"batb":[[0,1.01,0.51],[1,4.5,0],[2,1.01,0]],"ltp":5.1,"tv":23.45,"id":13117503}]}]}
{"op":"mcm","clk":"1001751471","pt":1580639838500,"mc":[{"id":"1.168215938","rc":[{"batb":[[0,5.2,32.09],[1,5.1,30.63],[2,1.01,0.51]],"ltp":5.0,"tv":105.34,"id":13117455},{"batb":[[0,6.2,30.7],[1,6,43.32],[2,1.01,0.51]],"ltp":5.1,"tv":23.45,"id":13117503}]}]}
{"op":"mcm","clk":"1001751613","pt":1580639839658,"mc":[{"id":"1.168215938","rc":[{"batb":[[2,4.7,10.92]],"batl":[[0,5.5,9.24]],"ltp":5.0,"tv":105.34,"id":13117455},{"batb":[[2,5.8,8.4]],"batl":[[0,7.2,6.72]],"ltp":5.1,"tv":23.45,"id":13117503},{"batb":[[0,1.49,180.86]],"batl":[[0,1.6,42.01]],"ltp":1.86,"tv":876.22,"id":13117454}]}]}
{"op":"mcm","clk":"1001753103","pt":1580639854901,"mc":[{"id":"1.168215938","rc":[{"batb":[[0,4.7,10.92],[1,1.01,0.51],[2,4.7,0]],"ltp":5.0,"tv":105.34,"id":13117455},{"batb":[[0,5.8,8.4],[1,1.01,0.51],[2,5.8,0]],"ltp":5.1,"tv":23.45,"id":13117503},{"batb":[[0,1.49,85.7],[1,1.01,0.51],[2,1.01,0]],"ltp":1.86,"tv":876.22,"id":13117454}]}]}
{"op":"mcm","clk":"1001753283","pt":1580639856784,"mc":[{"id":"1.168215938","rc":[{"batb":[[0,1.01,0.51],[1,1.01,0]],"ltp":5.0,"tv":105.34,"id":13117455},{"batb":[[0,1.01,0.51],[1,1.01,0]],"ltp":5.1,"tv":23.45,"id":13117503},{"batb":[[0,1.01,0.51],[1,1.01,0]],"ltp":1.86,"tv":876.22,"id":13117454}]}]}
{"op":"mcm","clk":"1001753386","pt":1580639857881,"mc":[{"id":"1.168215938","rc":[{"batb":[[0,4.5,29.97],[1,4.4,42.92],[2,1.01,0.51]],"ltp":5.0,"tv":105.34,"id":13117455},{"batb":[[0,5.3,43.41],[1,5.2,30.09],[2,1.01,0.51]],"ltp":5.1,"tv":23.45,"id":13117503},{"batb":[[0,1.3,185.18],[1,1.29,185.8],[2,1.01,0.51]],"ltp":1.86,"tv":876.22,"id":13117454}]}]}
{"op":"mcm","clk":"1001753435","pt":1580639858403,"mc":[{"id":"1.168215938","rc":[{"batb":[[0,1.01,0.51],[1,4.4,0],[2,1.01,0]],"ltp":5.0,"tv":105.34,"id":13117455},{"batb":[[0,1.01,0.51],[1,5.2,0],[2,1.01,0]],"ltp":5.1,"tv":23.45,"id":13117503},{"batb":[[0,1.01,0.51],[1,1.29,0],[2,1.01,0]],"ltp":1.86,"tv":876.22,"id":13117454}]}]}
{"op":"mcm","clk":"1001753840","pt":1580639861388,"mc":[{"id":"1.168215938","rc":[{"batb":[[0,5.5,33.46],[1,5.4,26.91],[2,1.01,0.51]],"ltp":5.0,"tv":105.34,"id":13117455},{"batb":[[0,6.6,25.67],[1,6.4,37.74],[2,1.01,0.51]],"ltp":5.1,"tv":23.45,"id":13117503},{"batb":[[0,1.45,81.41],[1,1.44,107.6],[2,1.01,0.51]],"ltp":1.86,"tv":876.22,"id":13117454}]}]}
{"op":"mcm","clk":"1001754368","pt":1580639865692,"mc":[{"id":"1.168215938","rc":[{"batb":[[0,1.01,0.51],[1,5.4,0],[2,1.01,0]],"ltp":5.0,"tv":105.34,"id":13117455},{"batb":[[0,1.01,0.51],[1,6.4,0],[2,1.01,0]],"ltp":5.1,"tv":23.45,"id":13117503},{"batb":[[0,1.01,0.51],[1,1.44,0],[2,1.01,0]],"ltp":1.86,"tv":876.22,"id":13117454}]}]}
{"op":"mcm","clk":"1001754907","pt":1580639868925,"mc":[{"id":"1.168215938","rc":[{"batb":[[0,4.5,29.97],[1,4.4,42.92],[2,1.01,0.51]],"ltp":5.0,"tv":105.34,"id":13117455},{"batb":[[0,5.3,43.41],[1,5.2,30.09],[2,1.01,0.51]],"ltp":5.1,"tv":23.45,"id":13117503},{"batb":[[0,1.3,185.18],[1,1.29,185.8],[2,1.01,0.51]],"ltp":1.86,"tv":876.22,"id":13117454}]}]}
{"op":"mcm","clk":"1001754925","pt":1580639869089,"mc":[{"id":"1.168215938","rc":[{"batb":[[0,1.01,0.51],[1,4.4,0],[2,1.01,0]],"ltp":5.0,"tv":105.34,"id":13117455},{"batb":[[0,1.01,0.51],[1,5.2,0],[2,1.01,0]],"ltp":5.1,"tv":23.45,"id":13117503}]}]}
{"op":"mcm","clk":"1001755223","pt":1580639872410,"mc":[{"id":"1.168215938","rc":[{"batb":[[0,7.2,29.79],[1,7,29.93],[2,1.01,0.51]],"ltp":5.0,"tv":105.34,"id":13117455},{"batb":[[0,8.8,15.1],[1,8.6,20.16],[2,1.01,0.51]],"ltp":5.1,"tv":23.45,"id":13117503}]}]}
{"op":"mcm","clk":"1001755331","pt":1580639873708,"mc":[{"id":"1.168215938","rc":[{"batb":[[2,6.2,7.56]],"batl":[[0,7.6,5.88]],"ltp":5.0,"tv":105.34,"id":13117455},{"batb":[[2,7.6,5.88]],"batl":[[0,9.6,4.2]],"ltp":5.1,"tv":23.45,"id":13117503},{"batb":[[0,1.32,131.07],[1,1.3,185.18],[2,1.29,185.8]],"batl":[[0,1.39,42.01]],"ltp":1.86,"tv":876.22,"id":13117454}]}]}
{"op":"mcm","clk":"1001756389","pt":1580639884124,"mc":[{"id":"1.168215938","rc":[{"batb":[[0,1.01,0.51],[1,1.01,0]],"ltp":3.8,"tv":32.93,"id":13117502}]}]}
{"op":"mcm","clk":"1001757183","pt":1580639893362,"mc":[{"id":"1.168215938","rc":[{"batb":[[0,6.2,7.56],[1,1.01,0.51],[2,6.2,0]],"ltp":5.0,"tv":105.34,"id":13117455},{"batb":[[0,7.6,5.88],[1,1.01,0.51],[2,7.6,0]],"ltp":5.1,"tv":23.45,"id":13117503},{"batb":[[1,1.01,0.51],[2,1.29,0]],"ltp":1.86,"tv":876.22,"id":13117454}]}]}
{"op":"mcm","clk":"1001757313","pt":1580639894831,"mc":[{"id":"1.168215938","rc":[{"batb":[[0,1.01,0.51],[1,1.01,0]],"ltp":5.0,"tv":105.34,"id":13117455},{"batb":[[0,1.01,0.51],[1,1.01,0]],"ltp":5.1,"tv":23.45,"id":13117503},{"batb":[[0,1.01,0.51],[1,1.01,0]],"ltp":1.86,"tv":876.22,"id":13117454}]}]}
{"op":"mcm","clk":"1001757405","pt":1580639896026,"mc":[{"id":"1.168215938","rc":[{"batb":[[0,5.7,35.09],[1,5.6,24.78],[2,1.01,0.51]],"ltp":5.0,"tv":105.34,"id":13117455},{"batb":[[0,6.8,43.09],[1,6.6,34.85],[2,1.01,0.51]],"ltp":5.1,"tv":23.45,"id":13117503},{"batb":[[0,1.14,306.63],[1,1.13,281.5],[2,1.01,0.51]],"ltp":1.86,"tv":876.22,"id":13117454}]}]}
{"op":"mcm","clk":"1001757856","pt":1580639901440,"mc":[{"id":"1.168215938","rc":[{"batb":[[0,1.01,0.51],[1,5.6,0],[2,1.01,0]],"ltp":5.0,"tv":105.34,"id":13117455},{"batb":[[0,1.01,0.51],[1,6.6,0],[2,1.01,0]],"ltp":5.1,"tv":23.45,"id":13117503}]}]}
{"op":"mcm","clk":"1001758158","pt":1580639904685,"mc":[{"id":"1.168215938","rc":[{"batb":[[0,13,25.27],[1,12.5,21.17],[2,1.01,0.51]],"ltp":5.0,"tv":105.34,"id":13117455},{"batb":[[0,16,13.9],[1,15.5,14.34],[2,1.01,0.51]],"ltp":5.1,"tv":23.45,"id":13117503}]}]}
{"op":"mcm","clk":"1001758297","pt":1580639905881,"mc":[{"id":"1.168215938","rc":[{"batb":[[2,11,4.2]],"ltp":5.0,"tv":105.34,"id":13117455},{"batb":[[2,13,3.36]],"ltp":5.1,"tv":23.45,"id":13117503},{"batb":[[0,1.15,168.04],[1,1.14,306.63],[2,1.13,281.5]],"batl":[[0,1.19,42.01]],"ltp":1.86,"tv":876.22,"id":13117454}]}]}
{"op":"mcm","clk":"1001759258","pt":1580639915748,"mc":[{"id":"1.168215938","rc":[{"batb":[[1,13,3.36],[2,1.01,0.51]],"ltp":5.1,"tv":23.45,"id":13117503},{"batb":[[1,1.14,254.8]],"ltp":1.86,"tv":876.22,"id":13117454}]}]}
{"op":"mcm","clk":"1001759465","pt":1580639918159,"mc":[{"id":"1.168215938","rc":[{"batb":[[0,16.5,8.19],[1,16,13.9],[2,13,3.36]],"ltp":5.1,"tv":23.45,"id":13117503},{"batb":[[2,1.13,333.79]],"ltp":1.86,"tv":876.22,"id":13117454}]}]}
{"op":"mcm","clk":"1001759624","pt":1580639919882,"mc":[{"id":"1.168215938","rc":[{"batb":[[0,7,15.12],[1,1.01,0.51]],"ltp":3.8,"tv":32.93,"id":13117502}]}]}
{"op":"mcm","clk":"1001759750","pt":1580639921141,"mc":[{"id":"1.168215938","rc":[{"batl":[[0,790,3.28]],"ltp":5.1,"tv":23.45,"id":13117503}]}]}
{"op":"mcm","clk":"1001760482","pt":1580639928774,"mc":[{"id":"1.168215938","rc":[{"batb":[[0,11,4.2],[1,1.01,0.51],[2,11,0]],"ltp":5.0,"tv":105.34,"id":13117455},{"batb":[[0,13,3.36],[1,1.01,0.51],[2,13,0]],"ltp":5.1,"tv":23.45,"id":13117503},{"batb":[[1,1.01,0.51],[2,1.13,0]],"ltp":1.86,"tv":876.22,"id":13117454}]}]}
{"op":"mcm","clk":"1001760732","pt":1580639932843,"mc":[{"id":"1.168215938","rc":[{"batb":[[0,9.6,24.75],[1,9.4,15.91],[2,1.01,0.51]],"ltp":5.0,"tv":105.34,"id":13117455},{"batb":[[0,12,12.96],[1,11.5,27.11],[2,1.01,0.51]],"ltp":5.1,"tv":23.45,"id":13117503},{"batb":[[0,1.04,641.98]],"ltp":1.86,"tv":876.22,"id":13117454}]}]}
{"op":"mcm","clk":"1001760945","pt":1580639933788,"mc":[{"id":"1.168215938","rc":[{"batb":[[0,9.6,15.51],[1,1.01,0.51],[2,1.01,0]],"ltp":5.0,"tv":105.34,"id":13117455}]}]}
{"op":"mcm","clk":"1001761217","pt":1580639936667,"mc":[{"id":"1.168215938","rc":[{"batb":[[0,9.8,12.7],[1,9.6,15.51],[2,1.01,0.51]],"ltp":5.0,"tv":105.34,"id":13117455},{"batb":[[0,12,15.97]],"ltp":5.1,"tv":23.45,"id":13117503}]}]}
{"op":"mcm","clk":"1001761333","pt":1580639938180,"mc":[{"id":"1.168215938","rc":[{"batb":[[0,1.01,0.51],[1,1.01,0]],"ltp":1.86,"tv":876.22,"id":13117454}]}]}
{"op":"mcm","clk":"1001761691","pt":1580639941802,"mc":[{"id":"1.168215938","rc":[{"batb":[[2,8.4,5.04]],"batl":[[0,10.5,4.2]],"ltp":5.0,"tv":105.34,"id":13117455},{"batb":[[2,10,4.2]],"batl":[[0,13.5,3.36]],"ltp":5.1,"tv":23.45,"id":13117503},{"batb":[[0,1.21,168.04],[1,1.2,311.5],[2,1.19,246.93]],"batl":[[0,1.27,42.01]],"ltp":1.86,"tv":876.22,"id":13117454}]}]}
{"op":"mcm","clk":"1001762410","pt":1580639949266,"mc":[{"id":"1.168215938","rc":[{"batb":[[0,1.01,0.51],[1,1.01,0]],"ltp":3.8,"tv":32.93,"id":13117502}]}]}
{"op":"mcm","clk":"1001762841","pt":1580639953791,"mc":[{"id":"1.168215938","rc":[{"batb":[[0,8.4,5.04],[1,1.01,0.51],[2,8.4,0]],"ltp":5.0,"tv":105.34,"id":13117455},{"batb":[[0,10,4.2],[1,1.01,0.51],[2,10,0]],"ltp":5.1,"tv":23.45,"id":13117503},{"batb":[[1,1.01,0.51],[2,1.19,0]],"ltp":1.86,"tv":876.22,"id":13117454}]}]}
{"op":"mcm","clk":"1001762935","pt":1580639954921,"mc":[{"id":"1.168215938","rc":[{"batb":[[0,1.01,0.51],[1,1.01,0]],"ltp":5.0,"tv":105.34,"id":13117455},{"batb":[[0,1.01,0.51],[1,1.01,0]],"ltp":5.1,"tv":23.45,"id":13117503},{"batb":[[0,1.01,0.51],[1,1.01,0]],"ltp":1.86,"tv":876.22,"id":13117454}]}]}
{"op":"mcm","clk":"1001763075","pt":1580639956647,"mc":[{"id":"1.168215938","rc":[{"batb":[[0,6.8,28.7],[1,6.6,34.14],[2,1.01,0.51]],"ltp":5.0,"tv":105.34,"id":13117455},{"batb":[[0,8.4,23.31],[1,8.2,22.53],[2,1.01,0.51]],"ltp":5.1,"tv":23.45,"id":13117503},{"batb":[[0,1.04,641.98],[1,1.01,0.51]],"ltp":1.86,"tv":876.22,"id":13117454}]}]}
{"op":"mcm","clk":"1001764150","pt":1580639968579,"mc":[{"id":"1.168215938","rc":[{"batb":[[0,1.01,0.51],[1,6.6,0],[2,1.01,0]],"ltp":5.0,"tv":105.34,"id":13117455},{"batb":[[0,1.01,0.51],[1,8.2,0],[2,1.01,0]],"ltp":5.1,"tv":23.45,"id":13117503}]}]}
{"op":"mcm","clk":"1001764488","pt":1580639971926,"mc":[{"id":"1.168215938","rc":[{"batb":[[0,34,13.14],[1,32,6.89],[2,1.01,0.51]],"ltp":5.0,"tv":105.34,"id":13117455},{"batb":[[0,42,7],[1,40,8.29],[2,1.01,0.51]],"ltp":5.1,"tv":23.45,"id":13117503}]}]}
{"op":"mcm","clk":"1001765839","pt":1580639987375,"mc":[{"id":"1.168215938","rc":[{"batb":[[0,42,5.71]],"ltp":5.1,"tv":23.45,"id":13117503}]}]}
{"op":"mcm","clk":"1001766165","pt":1580639990780,"mc":[{"id":"1.168215938","rc":[{"batl":[[0,650,3.85]],"ltp":5.1,"tv":23.45,"id":13117503}]}]}
{"op":"mcm","clk":"1001766231","pt":1580639991253,"mc":[{"id":"1.168215938","rc":[{"batb":[[0,1.04,544.83]],"ltp":1.86,"tv":876.22,"id":13117454}]}]}
{"op":"mcm","clk":"1001766624","pt":1580639995409,"mc":[{"id":"1.168215938","rc":[{"batb":[[0,1.04,641.98]],"ltp":1.86,"tv":876.22,"id":13117454}]}]}
{"op":"mcm","clk":"1001767220","pt":1580640001644,"mc":[{"id":"1.168215938","rc":[{"batb":[[1,1.01,0.51],[2,1.01,0]],"ltp":5.1,"tv":23.45,"id":13117503}]}]}
{"op":"mcm","clk":"1001767554","pt":1580640004728,"mc":[{"id":"1.168215938","rc":[{"batb":[[0,44,6.56],[1,42,7.87],[2,1.01,0.51]],"ltp":5.1,"tv":23.45,"id":13117503}]}]}
{"op":"mcm","clk":"1001768207","pt":1580640011232,"mc":[{"id":"1.168215938","rc":[{"batl":[[0,940,2.66]],"ltp":5.1,"tv":23.45,"id":13117503}]}]}
{"op":"mcm","clk":"1001771882","pt":1580640051922,"mc":[{"id":"1.168215938","rc":[{"batb":[[0,1.01,0.51],[1,32,0],[2,1.01,0]],"ltp":5.0,"tv":105.34,"id":13117455},{"batb":[[0,1.01,0.51],[1,42,0],[2,1.01,0]],"ltp":5.1,"tv":23.45,"id":13117503},{"batb":[[0,1.01,0.51],[1,1.01,0]],"ltp":1.86,"tv":876.22,"id":13117454}]}]}
{"op":"mcm","clk":"1001772485","pt":1580640058538,"mc":[{"id":"1.168215938","rc":[{"batb":[[0,29,6.89],[1,28,8.3],[2,1.01,0.51]],"ltp":5.0,"tv":105.34,"id":13117455},{"batb":[[0,36,10.35],[1,34,6.61],[2,1.01,0.51]],"ltp":5.1,"tv":23.45,"id":13117503},{"batb":[[0,1.05,635.86],[1,1.01,0.51]],"ltp":1.86,"tv":876.22,"id":13117454}]}]}
{"op":"mcm","clk":"1001772606","pt":1580640059841,"mc":[{"id":"1.168215938","rc":[{"batb":[[0,1.01,0.51],[1,28,0],[2,1.01,0]],"ltp":5.0,"tv":105.34,"id":13117455},{"batb":[[0,1.01,0.51],[1,34,0],[2,1.01,0]],"ltp":5.1,"tv":23.45,"id":13117503},{"batb":[[0,1.01,0.51],[1,1.01,0]],"ltp":1.86,"tv":876.22,"id":13117454}]}]}
{"op":"mcm","clk":"1001772926","pt":1580640062869,"mc":[{"id":"1.168215938","rc":[{"batb":[[0,17,10.07],[1,16.5,12.41],[2,1.01,0.51]],"ltp":5.0,"tv":105.34,"id":13117455},{"batb":[[0,22,4.83],[1,21,16.74],[2,1.01,0.51]],"ltp":5.1,"tv":23.45,"id":13117503},{"batb":[[0,1.02,654.57],[1,1.01,0.51]],"ltp":1.86,"tv":876.22,"id":13117454}]}]}
{"op":"mcm","clk":"1001773510","pt":1580640069834,"mc":[{"id":"1.168215938","rc":[{"batb":[[0,1.01,0.51],[1,1.01,0]],"ltp":1.86,"tv":876.22,"id":13117454}]}]}
{"op":"mcm","clk":"1001773790","pt":1580640072870,"mc":[{"id":"1.168215938","rc":[{"batb":[[0,1.1,559.06],[1,1.01,0.51]],"ltp":1.86,"tv":876.22,"id":13117454}]}]}
{"op":"mcm","clk":"1001773863","pt":1580640073853,"mc":[{"id":"1.168215938","rc":[{"batb":[[1,1.08,168.04],[2,1.01,0.51]],"batl":[[0,1.11,42.01]],"ltp":1.86,"tv":876.22,"id":13117454}]}]}
{"op":"mcm","clk":"1001774758","pt":1580640082567,"mc":[{"id":"1.168215938","rc":[{"batb":[[0,11,16.8],[1,1.01,0.51]],"ltp":3.8,"tv":32.93,"id":13117502}]}]}
{"op":"mcm","clk":"1001775147","pt":1580640086850,"mc":[{"id":"1.168215938","rc":[{"batb":[[0,1.01,0.51],[1,16.5,0],[2,1.01,0]],"ltp":5.0,"tv":105.34,"id":13117455},{"batb":[[0,1.01,0.51],[1,21,0],[2,1.01,0]],"ltp":5.1,"tv":23.45,"id":13117503},{"batb":[[0,1.08,168.04],[1,1.01,0.51],[2,1.01,0]],"ltp":1.86,"tv":876.22,"id":13117454}]}]}
{"op":"mcm","clk":"1001775344","pt":1580640088889,"mc":[{"id":"1.168215938","rc":[{"batb":[[0,1.01,0.51],[1,1.01,0]],"ltp":1.86,"tv":876.22,"id":13117454}]}]}
{"op":"mcm","clk":"1001775424","pt":1580640089778,"mc":[{"id":"1.168215938","rc":[{"batb":[[0,9,22.14],[1,8.8,18.65],[2,1.01,0.51]],"ltp":5.0,"tv":105.34,"id":13117455},{"batb":[[0,11.5,19.84],[1,11,31.49],[2,1.01,0.51]],"ltp":5.1,"tv":23.45,"id":13117503},{"batb":[[0,1.06,268.22],[1,1.05,365.08],[2,1.01,0.51]],"ltp":1.86,"tv":876.22,"id":13117454}]}]}
{"op":"mcm","clk":"1001775827","pt":1580640093970,"mc":[{"id":"1.168215938","rc":[{"batb":[[0,1.01,0.51],[1,8.8,0],[2,1.01,0]],"ltp":5.0,"tv":105.34,"id":13117455},{"batb":[[0,1.01,0.51],[1,11,0],[2,1.01,0]],"ltp":5.1,"tv":23.45,"id":13117503}]}]}
{"op":"mcm","clk":"1001776115","pt":1580640096881,"mc":[{"id":"1.168215938","rc":[{"batb":[[0,28,8.81],[1,27,8.87],[2,1.01,0.51]],"ltp":5.0,"tv":105.34,"id":13117455},{"batb":[[0,36,6.58],[1,34,12.21],[2,1.01,0.51]],"ltp":5.1,"tv":23.45,"id":13117503}]}]}
{"op":"mcm","clk":"1001777010","pt":1580640105718,"mc":[{"id":"1.168215938","rc":[{"batb":[[0,1.01,0.51],[1,27,0],[2,1.01,0]],"ltp":5.0,"tv":105.34,"id":13117455},{"batb":[[0,1.01,0.51],[1,34,0],[2,1.01,0]],"ltp":5.1,"tv":23.45,"id":13117503},{"batb":[[0,1.01,0.51],[1,1.05,0],[2,1.01,0]],"ltp":1.86,"tv":876.22,"id":13117454}]}]}
{"op":"mcm","clk":"1001777331","pt":1580640108592,"mc":[{"id":"1.168215938","rc":[{"batb":[[0,13,8.65],[1,12.5,22.07],[2,1.01,0.51]],"ltp":5.0,"tv":105.34,"id":13117455},{"batb":[[0,16.5,12.32],[1,16,14.69],[2,1.01,0.51]],"ltp":5.1,"tv":23.45,"id":13117503},{"batb":[[0,1.02,654.57],[1,1.01,0.51]],"ltp":1.86,"tv":876.22,"id":13117454}]}]}
{"op":"mcm","clk":"1001777427","pt":1580640109634,"mc":[{"id":"1.168215938","rc":[{"batb":[[0,1.01,0.51],[1,12.5,0],[2,1.01,0]],"ltp":5.0,"tv":105.34,"id":13117455},{"batb":[[0,1.01,0.51],[1,16,0],[2,1.01,0]],"ltp":5.1,"tv":23.45,"id":13117503},{"batb":[[0,1.01,0.51],[1,1.01,0]],"ltp":1.86,"tv":876.22,"id":13117454}]}]}
{"op":"mcm","clk":"1001777766","pt":1580640112835,"mc":[{"id":"1.168215938","rc":[{"batb":[[0,23,5.84],[1,22,13.6],[2,1.01,0.51]],"ltp":5.0,"tv":105.34,"id":13117455},{"batb":[[0,29,9.14],[1,28,9.23],[2,1.01,0.51]],"ltp":5.1,"tv":23.45,"id":13117503},{"batb":[[0,1.07,623.98],[1,1.01,0.51]],"ltp":1.86,"tv":876.22,"id":13117454}]}]}
{"op":"mcm","clk":"1001777992","pt":1580640114931,"mc":[{"id":"1.168215938","rc":[{"batb":[[0,1.01,0.51],[1,22,0],[2,1.01,0]],"ltp":5.0,"tv":105.34,"id":13117455},{"batb":[[0,1.01,0.51],[1,28,0],[2,1.01,0]],"ltp":5.1,"tv":23.45,"id":13117503},{"batb":[[0,1.01,0.51],[1,1.01,0]],"ltp":1.86,"tv":876.22,"id":13117454}]}]}
{"op":"mcm","clk":"1001778307","pt":1580640117812,"mc":[{"id":"1.168215938","rc":[{"batb":[[0,13,8.65],[1,12.5,22.07],[2,1.01,0.51]],"ltp":5.0,"tv":105.34,"id":13117455},{"batb":[[0,16.5,12.32],[1,16,14.69],[2,1.01,0.51]],"ltp":5.1,"tv":23.45,"id":13117503},{"batb":[[0,1.02,654.57],[1,1.01,0.51]],"ltp":1.86,"tv":876.22,"id":13117454}]}]}
{"op":"mcm","clk":"1001780056","pt":1580640130521,"mc":[{"id":"1.168215938","rc":[{"batb":[[0,1.01,0.51],[1,12.5,0],[2,1.01,0]],"ltp":5.0,"tv":105.34,"id":13117455},{"batb":[[0,1.01,0.51],[1,16,0],[2,1.01,0]],"ltp":5.1,"tv":23.45,"id":13117503}]}]}
{"op":"mcm","clk":"1001780431","pt":1580640133929,"mc":[{"id":"1.168215938","rc":[{"batb":[[0,60,4.94],[1,55,6.74],[2,1.01,0.51]],"ltp":5.0,"tv":105.34,"id":13117455},{"batb":[[0,75,6.09],[1,70,3],[2,1.01,0.51]],"ltp":5.1,"tv":23.45,"id":13117503},{"batb":[[0,1.02,822.61]],"ltp":1.86,"tv":876.22,"id":13117454}]}]}
{"op":"mcm","clk":"1001782800","pt":1580640150894,"mc":[{"id":"1.168215938","rc":[{"batb":[[0,1.01,0.51],[1,55,0],[2,1.01,0]],"ltp":5.0,"tv":105.34,"id":13117455},{"batb":[[0,1.01,0.51],[1,70,0],[2,1.01,0]],"ltp":5.1,"tv":23.45,"id":13117503},{"batb":[[0,1.02,168.04]],"ltp":1.86,"tv":876.22,"id":13117454}]}]}
{"op":"mcm","clk":"1001782856","pt":1580640151270,"mc":[{"id":"1.168215938","rc":[{"batb":[[0,1.01,0.51],[1,1.01,0]],"ltp":1.86,"tv":876.22,"id":13117454}]}]}
{"op":"mcm","clk":"1001783225","pt":1580640153674,"mc":[{"id":"1.168215938","rc":[{"batb":[[0,23,7.5],[1,22,13.52],[2,1.01,0.51]],"ltp":5.0,"tv":105.34,"id":13117455},{"batb":[[0,29,9.92],[1,28,9.2],[2,1.01,0.51]],"ltp":5.1,"tv":23.45,"id":13117503}]}]}
{"op":"mcm","clk":"1001783306","pt":1580640154398,"mc":[{"id":"1.168215938","rc":[{"batb":[[0,1.01,0.51],[1,22,0],[2,1.01,0]],"ltp":5.0,"tv":105.34,"id":13117455},{"batb":[[0,1.01,0.51],[1,28,0],[2,1.01,0]],"ltp":5.1,"tv":23.45,"id":13117503}]}]}
{"op":"mcm","clk":"1001785369","pt":1580640168723,"mc":[{"id":"1.168215938","rc":[{"batb":[[0,70,3.9],[1,65,6.06],[2,1.01,0.51]],"ltp":5.0,"tv":105.34,"id":13117455},{"batb":[[0,85,5.76],[1,80,2.22],[2,1.01,0.51]],"ltp":5.1,"tv":23.45,"id":13117503}]}]}
{"op":"mcm","clk":"1001785702","pt":1580640170930,"mc":[{"id":"1.168215938","marketDefinition":{"bspMarket":false,"turnInPlayEnabled":true,"persistenceEnabled":true,"marketBaseRate":5.0,"eventId":"29681228","eventTypeId":"2","numberOfWinners":1,"bettingType":"ODDS","marketType":"SET_BETTING","marketTime":"2020-02-02T09:23:00.000Z","suspendTime":"2020-02-02T09:23:00.000Z","bspReconciled":false,"complete":true,"inPlay":true,"crossMatching":true,"runnersVoidable":false,"numberOfActiveRunners":4,"betDelay":3,"status":"SUSPENDED","runners":[{"status":"ACTIVE","sortPriority":1,"id":13117502,"name":"Ebden 2-0"},{"status":"ACTIVE","sortPriority":2,"id":13117503,"name":"Ebden 2-1"},{"status":"ACTIVE","sortPriority":3,"id":13117454,"name":"Rosol 2-0"},{"status":"ACTIVE","sortPriority":4,"id":13117455,"name":"Rosol 2-1"}],"regulators":["MR_INT"],"countryCode":"IN","discountAllowed":true,"timezone":"UTC","openDate":"2020-02-02T09:23:00.000Z","version":3148430936,"name":"Set Betting","eventName":"Ebden v Rosol"},"rc":[{"batb":[[0,1.01,0.51],[1,65,0],[2,1.01,0]],"ltp":5.0,"tv":105.34,"id":13117455},{"batb":[[0,1.01,0.51],[1,80,0],[2,1.01,0]],"ltp":5.1,"tv":23.45,"id":13117503}]}]}
{"op":"mcm","clk":"1001790989","pt":1580640204993,"mc":[{"id":"1.168215938","tv":0.0}]}
{"op":"mcm","clk":"1001791154","pt":1580640205996,"mc":[{"id":"1.168215938","marketDefinition":{"bspMarket":false,"turnInPlayEnabled":true,"persistenceEnabled":true,"marketBaseRate":5.0,"eventId":"29681228","eventTypeId":"2","numberOfWinners":1,"bettingType":"ODDS","marketType":"SET_BETTING","marketTime":"2020-02-02T09:23:00.000Z","suspendTime":"2020-02-02T09:23:00.000Z","bspReconciled":false,"complete":true,"inPlay":true,"crossMatching":false,"runnersVoidable":false,"numberOfActiveRunners":0,"betDelay":3,"status":"CLOSED","settledTime":"2020-02-02T10:43:23.000Z","runners":[{"status":"LOSER","sortPriority":1,"id":13117502,"name":"Ebden 2-0"},{"status":"LOSER","sortPriority":2,"id":13117503,"name":"Ebden 2-1"},{"status":"WINNER","sortPriority":3,"id":13117454,"name":"Rosol 2-0"},{"status":"LOSER","sortPriority":4,"id":13117455,"name":"Rosol 2-1"}],"regulators":["MR_INT"],"countryCode":"IN","discountAllowed":true,"timezone":"UTC","openDate":"2020-02-02T09:23:00.000Z","version":3148431230,"name":"Set Betting","eventName":"Ebden v Rosol"}}]}
