{"op":"mcm","clk":"994279932","pt":1580566029164,"mc":[{"id":"1.168215938","marketDefinition":{"bspMarket":false,"turnInPlayEnabled":true,"persistenceEnabled":true,"marketBaseRate":5.0,"eventId":"29681228","eventTypeId":"2","numberOfWinners":1,"bettingType":"ODDS","marketType":"SET_BETTING","marketTime":"2020-02-02T04:00:00.000Z","suspendTime":"2020-02-02T04:00:00.000Z","bspReconciled":false,"complete":true,"inPlay":false,"crossMatching":false,"runnersVoidable":false,"numberOfActiveRunners":4,"betDelay":0,"status":"OPEN","runners":[{"status":"ACTIVE","sortPriority":1,"id":13117502,"name":"Ebden 2-0"},{"status":"ACTIVE","sortPriority":2,"id":13117503,"name":"Ebden 2-1"},{"status":"ACTIVE","sortPriority":3,"id":13117454,"name":"Rosol 2-0"},{"status":"ACTIVE","sortPriority":4,"id":13117455,"name":"Rosol 2-1"}],"regulators":["MR_INT"],"countryCode":"IN","discountAllowed":false,"timezone":"UTC","openDate":"2020-02-02T04:00:00.000Z","version":3145381966,"name":"Set Betting","eventName":"Ebden v Rosol"}}]}
{"op":"mcm","clk":"994280373","pt":1580566030955,"mc":[{"id":"1.168215938","marketDefinition":{"bspMarket":false,"turnInPlayEnabled":true,"persistenceEnabled":true,"marketBaseRate":5.0,"eventId":"29681228","eventTypeId":"2","numberOfWinners":1,"bettingType":"ODDS","marketType":"SET_BETTING","marketTime":"2020-02-02T04:00:00.000Z","suspendTime":"2020-02-02T04:00:00.000Z","bspReconciled":false,"complete":true,"inPlay":false,"crossMatching":false,"runnersVoidable":false,"numberOfActiveRunners":4,"betDelay":0,"status":"OPEN","runners":[{"status":"ACTIVE","sortPriority":1,"id":13117502,"name":"Ebden 2-0"},{"status":"ACTIVE","sortPriority":2,"id":13117503,"name":"Ebden 2-1"},{"status":"ACTIVE","sortPriority":3,"id":13117454,"name":"Rosol 2-0"},{"status":"ACTIVE","sortPriority":4,"id":13117455,"name":"Rosol 2-1"}],"regulators":["MR_INT"],"countryCode":"IN","discountAllowed":false,"timezone":"UTC","openDate":"2020-02-02T04:00:00.000Z","version":3145381966,"name":"Set Betting","eventName":"Ebden v Rosol"}}]}
{"op":"mcm","clk":"994280889","pt":1580566032994,"mc":[{"id":"1.168215938","marketDefinition":{"bspMarket":false,"turnInPlayEnabled":true,"persistenceEnabled":true,"marketBaseRate":5.0,"eventId":"29681228","eventTypeId":"2","numberOfWinners":1,"bettingType":"ODDS","marketType":"SET_BETTING","marketTime":"2020-02-02T04:00:00.000Z","suspendTime":"2020-02-02T04:00:00.000Z","bspReconciled":false,"complete":true,"inPlay":false,"crossMatching":false,"runnersVoidable":false,"numberOfActiveRunners":4,"betDelay":0,"status":"OPEN","runners":[{"status":"ACTIVE","sortPriority":1,"id":13117502,"name":"Ebden 2-0"},{"status":"ACTIVE","sortPriority":2,"id":13117503,"name":"Ebden 2-1"},{"status":"ACTIVE","sortPriority":3,"id":13117454,"name":"Rosol 2-0"},{"status":"ACTIVE","sortPriority":4,"id":13117455,"name":"Rosol 2-1"}],"regulators":["MR_INT"],"countryCode":"IN","discountAllowed":true,"timezone":"UTC","openDate":"2020-02-02T04:00:00.000Z","version":3145381966,"name":"Set Betting","eventName":"Ebden v Rosol"}}]}
{"op":"mcm","clk":"994366936","pt":1580566356346,"mc":[{"id":"1.168215938","rc":[{"batb":[[0,1.02,2]],"ltp":0.0,"tv":0.0,"id":13117455},{"batb":[[0,1.02,2]],"ltp":0.0,"tv":0.0,"id":13117503},{"batb":[[0,1.02,2]],"ltp":0.0,"tv":0.0,"id":13117454},{"batb":[[0,1.02,2]],"ltp":0.0,"tv":0.0,"id":13117502}]}]}
{"op":"mcm","clk":"994665394","pt":1580567442352,"mc":[{"id":"1.168215938","marketDefinition":{"bspMarket":false,"turnInPlayEnabled":true,"persistenceEnabled":true,"marketBaseRate":5.0,"eventId":"29681228","eventTypeId":"2","numberOfWinners":1,"bettingType":"ODDS","marketType":"SET_BETTING","marketTime":"2020-02-02T09:30:00.000Z","suspendTime":"2020-02-02T09:30:00.000Z","bspReconciled":false,"complete":true,"inPlay":false,"crossMatching":false,"runnersVoidable":false,"numberOfActiveRunners":4,"betDelay":0,"status":"OPEN","runners":[{"status":"ACTIVE","sortPriority":1,"id":13117502,"name":"Ebden 2-0"},{"status":"ACTIVE","sortPriority":2,"id":13117503,"name":"Ebden 2-1"},{"status":"ACTIVE","sortPriority":3,"id":13117454,"name":"Rosol 2-0"},{"status":"ACTIVE","sortPriority":4,"id":13117455,"name":"Rosol 2-1"}],"regulators":["MR_INT"],"countryCode":"IN","discountAllowed":true,"timezone":"UTC","openDate":"2020-02-02T04:00:00.000Z","version":3145478873,"name":"Set Betting","eventName":"Ebden v Rosol"}}]}
{"op":"mcm","clk":"994666152","pt":1580567445352,"mc":[{"id":"1.168215938","marketDefinition":{"bspMarket":false,"turnInPlayEnabled":true,"persistenceEnabled":true,"marketBaseRate":5.0,"eventId":"29681228","eventTypeId":"2","numberOfWinners":1,"bettingType":"ODDS","marketType":"SET_BETTING","marketTime":"2020-02-02T09:30:00.000Z","suspendTime":"2020-02-02T09:30:00.000Z","bspReconciled":false,"complete":true,"inPlay":false,"crossMatching":false,"runnersVoidable":false,"numberOfActiveRunners":4,"betDelay":0,"status":"OPEN","runners":[{"status":"ACTIVE","sortPriority":1,"id":13117502,"name":"Ebden 2-0"},{"status":"ACTIVE","sortPriority":2,"id":13117503,"name":"Ebden 2-1"},{"status":"ACTIVE","sortPriority":3,"id":13117454,"name":"Rosol 2-0"},{"status":"ACTIVE","sortPriority":4,"id":13117455,"name":"Rosol 2-1"}],"regulators":["MR_INT"],"countryCode":"IN","discountAllowed":true,"timezone":"UTC","openDate":"2020-02-02T09:30:00.000Z","version":3145478873,"name":"Set Betting","eventName":"Ebden v Rosol"}}]}
{"op":"mcm","clk":"997467351","pt":1580581062288,"mc":[{"id":"1.168215938","rc":[{"batb":[[0,2.36,30.29],[1,1.02,2]],"ltp":0.0,"tv":0.0,"id":13117454}]}]}
{"op":"mcm","clk":"999519288","pt":1580596406654,"mc":[{"id":"1.168215938","rc":[{"batb":[[0,1.02,2],[1,1.02,0]],"ltp":0.0,"tv":0.0,"id":13117454}]}]}
{"op":"mcm","clk":"999533681","pt":1580596606953,"mc":[{"id":"1.168215938","rc":[{"batb":[[0,2.36,30.29],[1,1.02,2]],"ltp":0.0,"tv":0.0,"id":13117454}]}]}
{"op":"mcm","clk":"999906507","pt":1580602464808,"mc":[{"id":"1.168215938","rc":[{"batb":[[1,1.01,0.51]],"ltp":0.0,"tv":0.0,"id":13117455},{"batb":[[1,1.01,0.51]],"ltp":0.0,"tv":0.0,"id":13117503},{"batb":[[2,1.01,0.51]],"ltp":0.0,"tv":0.0,"id":13117454},{"batb":[[1,1.01,0.51]],"ltp":0.0,"tv":0.0,"id":13117502}]}]}
{"op":"mcm","clk":"999922260","pt":1580602690875,"mc":[{"id":"1.168215938","rc":[{"batb":[[0,2.5,30.29]],"ltp":0.0,"tv":0.0,"id":13117454}]}]}
{"op":"mcm","clk":"999995787","pt":1580603997874,"mc":[{"id":"1.168215938","rc":[{"batb":[[1,1.01,1.01]],"ltp":0.0,"tv":0.0,"id":13117455},{"batb":[[1,1.01,1.01]],"ltp":0.0,"tv":0.0,"id":13117503},{"batb":[[2,1.01,1.01]],"ltp":0.0,"tv":0.0,"id":13117454},{"batb":[[1,1.01,1.01]],"ltp":0.0,"tv":0.0,"id":13117502}]}]}
{"op":"mcm","clk":"1001392233","pt":1580634946709,"mc":[{"id":"1.168215938","rc":[{"batb":[[0,1.02,2],[1,1.01,1.01],[2,1.01,0]],"ltp":0.0,"tv":0.0,"id":13117454}]}]}
{"op":"mcm","clk":"1001403975","pt":1580635181967,"mc":[{"id":"1.168215938","rc":[{"batl":[[0,5,18.23]],"ltp":0.0,"tv":0.0,"id":13117455},{"batl":[[0,5.1,17.73]],"ltp":0.0,"tv":0.0,"id":13117503}]}]}
{"op":"mcm","clk":"1001416193","pt":1580635444714,"mc":[{"id":"1.168215938","rc":[{"batb":[[0,4.4,17.31],[1,1.02,2],[2,1.01,1.01]],"batl":[[1,5.2,16.52]],"ltp":0.0,"tv":0.0,"id":13117455},{"batb":[[0,4.8,14.63],[1,1.02,2],[2,1.01,1.01]],"batl":[[1,5.6,14.01]],"ltp":0.0,"tv":0.0,"id":13117503},{"batb":[[0,2.96,23.84],[1,1.02,2],[2,1.01,1.01]],"batl":[[0,3.3,22.9]],"ltp":0.0,"tv":0.0,"id":13117454},{"batb":[[0,3.4,16.68],[1,1.02,2],[2,1.01,1.01]],"batl":[[0,3.8,16.13]],"ltp":0.0,"tv":0.0,"id":13117502}]}]}
{"op":"mcm","clk":"1001417670","pt":1580635475129,"mc":[{"id":"1.168215938","marketDefinition":{"bspMarket":false,"turnInPlayEnabled":true,"persistenceEnabled":true,"marketBaseRate":5.0,"eventId":"29681228","eventTypeId":"2","numberOfWinners":1,"bettingType":"ODDS","marketType":"SET_BETTING","marketTime":"2020-02-02T09:30:00.000Z","suspendTime":"2020-02-02T09:30:00.000Z","bspReconciled":false,"complete":true,"inPlay":false,"crossMatching":true,"runnersVoidable":false,"numberOfActiveRunners":4,"betDelay":0,"status":"OPEN","runners":[{"status":"ACTIVE","sortPriority":1,"id":13117502,"name":"Ebden 2-0"},{"status":"ACTIVE","sortPriority":2,"id":13117503,"name":"Ebden 2-1"},{"status":"ACTIVE","sortPriority":3,"id":13117454,"name":"Rosol 2-0"},{"status":"ACTIVE","sortPriority":4,"id":13117455,"name":"Rosol 2-1"}],"regulators":["MR_INT"],"countryCode":"IN","discountAllowed":true,"timezone":"UTC","openDate":"2020-02-02T09:30:00.000Z","version":3146887645,"name":"Set Betting","eventName":"Ebden v Rosol"}}]}
{"op":"mcm","clk":"1001420402","pt":1580635526779,"mc":[{"id":"1.168215938","rc":[{"trd":[[5,12.25]],"batb":[[0,4.5,17.23],[1,4.4,17.31],[2,1.02,2]],"batl":[[0,5,5.99]],"ltp":5.0,"tv":12.24,"id":13117455},{"trd":[[5.1,12]],"batl":[[0,5.1,5.72]],"ltp":5.1,"tv":12.0,"id":13117503},{"trd":[[2.92,20.99],[2.96,47.68]],"batb":[[0,2.9,25.02],[2,1.01,2.38]],"batl":[[0,2.92,103.78],[1,3.25,24.08],[2,3.3,22.9]],"ltp":2.92,"tv":68.67,"id":13117454},{"trd":[[3.8,16.13]],"batb":[[0,3.45,15.89],[1,3.4,16.68],[2,1.02,2]],"batl":[[0,3.9,15.34]],"ltp":3.8,"tv":16.12,"id":13117502}],"tv":109.05}]}
{"op":"mcm","clk":"1001420468","pt":1580635527803,"mc":[{"id":"1.168215938","rc":[{"trd":[[5,24.22]],"batb":[[1,1.02,2],[2,1.01,1.01]],"batl":[[0,5.2,16.52],[1,5.2,0]],"ltp":5.0,"tv":24.22,"id":13117455},{"trd":[[2.92,41.53]],"batb":[[2,1.01,1.01]],"batl":[[0,2.92,93.52],[2,3.3,0]],"ltp":2.92,"tv":89.2,"id":13117454},{"batb":[[1,1.02,2],[2,1.01,1.01]],"ltp":3.8,"tv":16.12,"id":13117502}],"tv":141.56}]}
{"op":"mcm","clk":"1001422668","pt":1580635569933,"mc":[{"id":"1.168215938","rc":[{"trd":[[5.2,33.05]],"batl":[[0,5.2,16.13]],"ltp":5.2,"tv":57.27,"id":13117455},{"batl":[[1,5.5,14.01],[2,5.6,14.01]],"ltp":5.1,"tv":12.0,"id":13117503},{"trd":[[2.92,100.36]],"batl":[[0,2.92,64.1],[1,3.15,24.16],[2,3.25,24.08]],"ltp":2.92,"tv":148.04,"id":13117454},{"batb":[[0,3.55,15.97],[1,3.45,15.89],[2,1.02,2]],"ltp":3.8,"tv":16.12,"id":13117502}],"tv":233.44}]}
{"op":"mcm","clk":"1001422686","pt":1580635570241,"mc":[{"id":"1.168215938","rc":[{"trd":[[5.2,65.3]],"batb":[[0,4.5,16.92]],"ltp":5.2,"tv":89.52,"id":13117455},{"batl":[[2,5.6,0]],"ltp":5.1,"tv":12.0,"id":13117503},{"trd":[[2.92,157.81]],"batl":[[0,2.92,35.37],[2,3.25,0]],"ltp":2.92,"tv":205.48,"id":13117454},{"batb":[[1,1.02,2],[2,1.01,1.01]],"ltp":3.8,"tv":16.12,"id":13117502}],"tv":323.15}]}
{"op":"mcm","clk":"1001423396","pt":1580635580949,"mc":[{"id":"1.168215938","rc":[{"batb":[[0,4.8,15.58]],"batl":[[0,5.4,14.87]],"ltp":5.2,"tv":89.52,"id":13117455},{"batb":[[0,2.88,10.31]],"batl":[[1,3.1,24.71]],"ltp":2.92,"tv":205.48,"id":13117454},{"batb":[[0,3.5,16.29]],"batl":[[0,3.85,15.82]],"ltp":3.8,"tv":16.12,"id":13117502}]}]}
{"op":"mcm","clk":"1001423744","pt":1580635588403,"mc":[{"id":"1.168215938","rc":[{"batl":[[0,2.92,35.38]],"ltp":2.92,"tv":205.48,"id":13117454}]}]}
{"op":"mcm","clk":"1001425451","pt":1580635608319,"mc":[{"id":"1.168215938","marketDefinition":{"bspMarket":false,"turnInPlayEnabled":true,"persistenceEnabled":true,"marketBaseRate":5.0,"eventId":"29681228","eventTypeId":"2","numberOfWinners":1,"bettingType":"ODDS","marketType":"SET_BETTING","marketTime":"2020-02-02T09:23:00.000Z","suspendTime":"2020-02-02T09:23:00.000Z","bspReconciled":false,"complete":true,"inPlay":false,"crossMatching":true,"runnersVoidable":false,"numberOfActiveRunners":4,"betDelay":0,"status":"OPEN","runners":[{"status":"ACTIVE","sortPriority":1,"id":13117502,"name":"Ebden 2-0"},{"status":"ACTIVE","sortPriority":2,"id":13117503,"name":"Ebden 2-1"},{"status":"ACTIVE","sortPriority":3,"id":13117454,"name":"Rosol 2-0"},{"status":"ACTIVE","sortPriority":4,"id":13117455,"name":"Rosol 2-1"}],"regulators":["MR_INT"],"countryCode":"IN","discountAllowed":true,"timezone":"UTC","openDate":"2020-02-02T09:30:00.000Z","version":3148345273,"name":"Set Betting","eventName":"Ebden v Rosol"}}]}
{"op":"mcm","clk":"1001425695","pt":1580635610399,"mc":[{"id":"1.168215938","marketDefinition":{"bspMarket":false,"turnInPlayEnabled":true,"persistenceEnabled":true,"marketBaseRate":5.0,"eventId":"29681228","eventTypeId":"2","numberOfWinners":1,"bettingType":"ODDS","marketType":"SET_BETTING","marketTime":"2020-02-02T09:23:00.000Z","suspendTime":"2020-02-02T09:23:00.000Z","bspReconciled":false,"complete":true,"inPlay":false,"crossMatching":true,"runnersVoidable":false,"numberOfActiveRunners":4,"betDelay":0,"status":"OPEN","runners":[{"status":"ACTIVE","sortPriority":1,"id":13117502,"name":"Ebden 2-0"},{"status":"ACTIVE","sortPriority":2,"id":13117503,"name":"Ebden 2-1"},{"status":"ACTIVE","sortPriority":3,"id":13117454,"name":"Rosol 2-0"},{"status":"ACTIVE","sortPriority":4,"id":13117455,"name":"Rosol 2-1"}],"regulators":["MR_INT"],"countryCode":"IN","discountAllowed":true,"timezone":"UTC","openDate":"2020-02-02T09:23:00.000Z","version":3148345273,"name":"Set Betting","eventName":"Ebden v Rosol"}}]}
{"op":"mcm","clk":"1001440408","pt":1580635860950,"mc":[{"id":"1.168215938","rc":[{"trd":[[5,36.44]],"batb":[[1,4.3,12.6],[2,1.02,2]],"batl":[[0,5,3.97],[1,5.4,14.87]],"ltp":5.0,"tv":101.74,"id":13117455},{"batb":[[1,4.5,11.76],[2,1.02,2]],"batl":[[1,5.2,9.24],[2,5.5,14.01]],"ltp":5.1,"tv":12.0,"id":13117503},{"trd":[[2.92,222.41]],"batl":[[0,2.92,3.07],[2,3.4,16.8]],"ltp":2.92,"tv":270.09,"id":13117454},{"batb":[[0,3.5,33.09]],"batl":[[1,3.95,13.44]],"ltp":3.8,"tv":16.12,"id":13117502}],"tv":399.97}]}
{"op":"mcm","clk":"1001440453","pt":1580635861571,"mc":[{"id":"1.168215938","rc":[{"trd":[[5,40.04]],"batl":[[0,5,8.06]],"ltp":5.0,"tv":105.34,"id":13117455},{"batl":[[1,5.3,9.24]],"ltp":5.1,"tv":12.0,"id":13117503},{"trd":[[2.92,228.56]],"batb":[[0,2.92,21.85],[1,2.88,10.31],[2,1.02,2]],"batl":[[0,3.1,24.71],[1,3.4,16.8],[2,3.4,0]],"ltp":2.92,"tv":276.24,"id":13117454}],"tv":409.71}]}
{"op":"mcm","clk":"1001440488","pt":1580635862034,"mc":[{"id":"1.168215938","rc":[{"batb":[[0,3,21]],"ltp":2.92,"tv":276.24,"id":13117454},{"batb":[[0,3.5,16.29],[1,3.45,16.8],[2,1.02,2]],"ltp":3.8,"tv":16.12,"id":13117502}]}]}
{"op":"mcm","clk":"1001444277","pt":1580635931241,"mc":[{"id":"1.168215938","rc":[{"batl":[[2,5.4,14.4]],"ltp":5.1,"tv":12.0,"id":13117503},{"batb":[[1,2.9,25.57]],"batl":[[0,3.15,24.55]],"ltp":2.92,"tv":276.24,"id":13117454}]}]}
{"op":"mcm","clk":"1001444827","pt":1580635942931,"mc":[{"id":"1.168215938","rc":[{"batb":[[0,4.8,15.26]],"batl":[[1,5.4,14.63]],"ltp":5.0,"tv":105.34,"id":13117455},{"batb":[[0,4.7,15.26]],"ltp":5.1,"tv":12.0,"id":13117503},{"batb":[[1,2.92,25.26]],"batl":[[0,3.15,24.23]],"ltp":2.92,"tv":276.24,"id":13117454},{"batl":[[0,3.8,16.13]],"ltp":3.8,"tv":16.12,"id":13117502}]}]}
{"op":"mcm","clk":"1001447160","pt":1580636000789,"mc":[{"id":"1.168215938","rc":[{"batl":[[2,5.5,14.56]],"ltp":5.0,"tv":105.34,"id":13117455}]}]}
{"op":"mcm","clk":"1001447177","pt":1580636001509,"mc":[{"id":"1.168215938","rc":[{"batl":[[1,5.5,14.56],[2,5.5,0]],"ltp":5.0,"tv":105.34,"id":13117455},{"batb":[[1,2.92,25.1]],"batl":[[0,3.15,24.08]],"ltp":2.92,"tv":276.24,"id":13117454}]}]}
{"op":"mcm","clk":"1001447506","pt":1580636012809,"mc":[{"id":"1.168215938","rc":[{"batl":[[1,5.4,14.63],[2,5.5,14.56]],"ltp":5.0,"tv":105.34,"id":13117455},{"batb":[[2,2.9,25.26]],"ltp":2.92,"tv":276.24,"id":13117454},{"trd":[[3.8,32.93]],"batl":[[0,3.8,15.99]],"ltp":3.8,"tv":32.93,"id":13117502}],"tv":426.52}]}
{"op":"mcm","clk":"1001447515","pt":1580636013017,"mc":[{"id":"1.168215938","rc":[{"batl":[[2,5.5,0]],"ltp":5.0,"tv":105.34,"id":13117455},{"batb":[[1,2.9,25.26],[2,1.02,2]],"ltp":2.92,"tv":276.24,"id":13117454}]}]}
{"op":"mcm","clk":"1001448586","pt":1580636043947,"mc":[{"id":"1.168215938","rc":[{"batb":[[0,2.9,25.26],[1,1.02,2],[2,1.01,1.01]],"batl":[[1,3.4,0]],"ltp":2.92,"tv":276.24,"id":13117454}]}]}
{"op":"mcm","clk":"1001448622","pt":1580636044770,"mc":[{"id":"1.168215938","rc":[{"batb":[[0,3.05,20.16],[1,2.94,24.78],[2,1.02,2]],"batl":[[0,3.15,23.76],[1,3.45,16.8]],"ltp":2.92,"tv":276.24,"id":13117454}]}]}
{"op":"mcm","clk":"1001448914","pt":1580636054847,"mc":[{"id":"1.168215938","rc":[{"batb":[[1,2.94,24.55]],"batl":[[0,3.2,23.53]],"ltp":2.92,"tv":276.24,"id":13117454},{"batb":[[0,3.45,33.8],[1,1.02,2],[2,1.01,1.01]],"batl":[[0,3.75,16.44]],"ltp":3.8,"tv":32.93,"id":13117502}]}]}
{"op":"mcm","clk":"1001449615","pt":1580636074246,"mc":[{"id":"1.168215938","rc":[{"batb":[[1,1.02,2],[2,1.01,1.01]],"batl":[[0,5.4,14.63],[1,5.4,0]],"ltp":5.0,"tv":105.34,"id":13117455},{"batb":[[1,1.02,2],[2,1.01,1.01]],"batl":[[1,5.4,14.4],[2,5.4,0]],"ltp":5.1,"tv":12.0,"id":13117503},{"batb":[[0,2.94,24.55],[1,1.02,2],[2,1.01,1.01]],"batl":[[1,3.45,0]],"ltp":2.92,"tv":276.24,"id":13117454},{"batb":[[0,3.45,17]],"batl":[[1,3.95,0]],"ltp":3.8,"tv":32.93,"id":13117502}]}]}
{"op":"mcm","clk":"1001451529","pt":1580636130732,"mc":[{"id":"1.168215938","rc":[{"batb":[[0,4.3,12.6]],"batl":[[0,5.1,10.08]],"ltp":5.0,"tv":105.34,"id":13117455},{"batb":[[0,4.5,11.76]],"batl":[[1,5.2,9.24]],"ltp":5.1,"tv":12.0,"id":13117503},{"batb":[[0,3.05,20.16]],"batl":[[0,3.45,16.8]],"ltp":2.92,"tv":276.24,"id":13117454},{"batb":[[0,3.45,16.8]],"batl":[[0,3.9,14.28]],"ltp":3.8,"tv":32.93,"id":13117502}]}]}
{"op":"mcm","clk":"1001451552","pt":1580636131258,"mc":[{"id":"1.168215938","marketDefinition":{"bspMarket":false,"turnInPlayEnabled":true,"persistenceEnabled":true,"marketBaseRate":5.0,"eventId":"29681228","eventTypeId":"2","numberOfWinners":1,"bettingType":"ODDS","marketType":"SET_BETTING","marketTime":"2020-02-02T09:23:00.000Z","suspendTime":"2020-02-02T09:23:00.000Z","bspReconciled":false,"complete":true,"inPlay":true,"crossMatching":true,"runnersVoidable":false,"numberOfActiveRunners":4,"betDelay":3,"status":"OPEN","runners":[{"status":"ACTIVE","sortPriority":1,"id":13117502,"name":"Ebden 2-0"},{"status":"ACTIVE","sortPriority":2,"id":13117503,"name":"Ebden 2-1"},{"status":"ACTIVE","sortPriority":3,"id":13117454,"name":"Rosol 2-0"},{"status":"ACTIVE","sortPriority":4,"id":13117455,"name":"Rosol 2-1"}],"regulators":["MR_INT"],"countryCode":"IN","discountAllowed":true,"timezone":"UTC","openDate":"2020-02-02T09:23:00.000Z","version":3148350936,"name":"Set Betting","eventName":"Ebden v Rosol"},"rc":[{"batb":[[0,1.01,0.51],[1,1.02,0],[2,1.01,0]],"ltp":5.0,"tv":105.34,"id":13117455},{"batb":[[0,1.01,0.51],[1,1.02,0],[2,1.01,0]],"batl":[[1,5.2,0]],"ltp":5.1,"tv":12.0,"id":13117503},{"batb":[[0,1.01,0.51],[1,1.02,0],[2,1.01,0]],"ltp":2.92,"tv":276.24,"id":13117454},{"batb":[[0,1.01,0.51],[1,1.02,0],[2,1.01,0]],"ltp":3.8,"tv":32.93,"id":13117502}]}]}
{"op":"mcm","clk":"1001451685","pt":1580636134723,"mc":[{"id":"1.168215938","rc":[{"batb":[[0,4.3,12.6],[1,1.01,0.51]],"batl":[[0,5.1,10.08]],"ltp":5.0,"tv":105.34,"id":13117455},{"batb":[[0,4.5,11.76],[1,1.01,0.51]],"batl":[[1,5.2,9.24]],"ltp":5.1,"tv":12.0,"id":13117503},{"batb":[[0,3.05,20.16],[1,1.01,0.51]],"batl":[[0,3.45,16.8]],"ltp":2.92,"tv":276.24,"id":13117454},{"batb":[[0,3.4,16.8],[1,1.01,0.51]],"batl":[[0,3.9,14.28]],"ltp":3.8,"tv":32.93,"id":13117502}]}]}
{"op":"mcm","clk":"1001451703","pt":1580636135132,"mc":[{"id":"1.168215938","rc":[{"batb":[[0,1.01,0.51],[1,1.01,0]],"ltp":5.0,"tv":105.34,"id":13117455},{"batb":[[0,1.01,0.51],[1,1.01,0]],"batl":[[1,5.2,0]],"ltp":5.1,"tv":12.0,"id":13117503},{"batb":[[0,1.01,0.51],[1,1.01,0]],"ltp":2.92,"tv":276.24,"id":13117454},{"batb":[[0,1.01,0.51],[1,1.01,0]],"ltp":3.8,"tv":32.93,"id":13117502}]}]}
{"op":"mcm","clk":"1001451997","pt":1580636142644,"mc":[{"id":"1.168215938","rc":[{"batb":[[0,4.9,14.79],[1,4.8,15.5],[2,1.01,0.51]],"batl":[[0,5.5,14.16],[1,5.7,13.38]],"ltp":5.0,"tv":105.34,"id":13117455},{"batb":[[0,4.7,15.34],[1,1.01,0.51]],"batl":[[1,5.4,14.56]],"ltp":5.1,"tv":12.0,"id":13117503},{"batb":[[0,2.68,12.51],[1,2.38,17.15],[2,1.01,0.51]],"batl":[[0,2.84,12.35],[1,3.1,25.02]],"ltp":2.92,"tv":276.24,"id":13117454},{"batb":[[0,3.85,13.06],[1,3.55,15.82],[2,1.01,0.51]],"batl":[[0,4.3,24.71],[1,5.2,16.37]],"ltp":3.8,"tv":32.93,"id":13117502}]}]}
{"op":"mcm","clk":"1001452037","pt":1580636143656,"mc":[{"id":"1.168215938","rc":[{"batb":[[2,4.3,12.6]],"batl":[[0,5.1,10.08],[1,5.5,14.16],[2,5.7,13.38]],"ltp":5.0,"tv":105.34,"id":13117455},{"batb":[[1,4.5,11.76],[2,1.01,0.51]],"batl":[[1,5.3,9.24],[2,5.4,14.56]],"ltp":5.1,"tv":12.0,"id":13117503},{"batb":[[0,2.78,23.53],[1,2.68,12.51],[2,2.38,17.15]],"batl":[[2,3.15,19.32]],"ltp":2.92,"tv":276.24,"id":13117454},{"batb":[[1,3.75,15.12],[2,3.55,15.82]],"batl":[[1,4.4,11.76],[2,5.2,16.37]],"ltp":3.8,"tv":32.93,"id":13117502}]}]}
{"op":"mcm","clk":"1001452099","pt":1580636144938,"mc":[{"id":"1.168215938","rc":[{"batb":[[2,4.5,56.42]],"ltp":5.0,"tv":105.34,"id":13117455},{"batb":[[0,4.9,32.03],[1,4.8,35.2],[2,4.7,15.34]],"ltp":5.1,"tv":12.0,"id":13117503},{"batb":[[0,2.78,65.52],[1,2.74,55.14],[2,2.68,12.51]],"ltp":2.92,"tv":276.24,"id":13117454},{"batb":[[0,4,26.3],[1,3.95,28.01],[2,3.85,13.06]],"ltp":3.8,"tv":32.93,"id":13117502}]}]}
{"op":"mcm","clk":"1001452347","pt":1580636152336,"mc":[{"id":"1.168215938","rc":[{"batb":[[0,4.8,15.5],[1,4.5,40.28],[2,4.4,42.56]],"batl":[[0,5.7,13.38],[1,5.5,0],[2,5.7,0]],"ltp":5.0,"tv":105.34,"id":13117455},{"batl":[[1,5.4,14.56],[2,5.4,0]],"ltp":5.1,"tv":12.0,"id":13117503},{"batb":[[0,2.38,17.15],[1,1.01,0.51],[2,2.68,0]],"batl":[[0,3.1,25.02],[1,3.1,0],[2,3.15,0]],"ltp":2.92,"tv":276.24,"id":13117454},{"batb":[[0,3.55,15.82],[1,1.01,0.51],[2,3.85,0]],"batl":[[0,5.2,16.37],[1,4.4,0],[2,5.2,0]],"ltp":3.8,"tv":32.93,"id":13117502}]}]}
{"op":"mcm","clk":"1001452559","pt":1580636157250,"mc":[{"id":"1.168215938","rc":[{"batb":[[1,4.5,62.2]],"ltp":5.0,"tv":105.34,"id":13117455},{"batb":[[0,2.7,59.45],[1,2.66,59.46],[2,2.38,17.15]],"ltp":2.92,"tv":276.24,"id":13117454},{"batb":[[0,4.1,45.77],[1,4,53.38],[2,3.55,15.82]],"ltp":3.8,"tv":32.93,"id":13117502}]}]}
{"op":"mcm","clk":"1001452631","pt":1580636158567,"mc":[{"id":"1.168215938","rc":[{"batb":[[1,4.5,40.28]],"ltp":5.0,"tv":105.34,"id":13117455},{"batb":[[0,2.38,17.15],[1,1.01,0.51],[2,2.38,0]],"ltp":2.92,"tv":276.24,"id":13117454},{"batb":[[0,3.55,15.82],[1,1.01,0.51],[2,3.55,0]],"ltp":3.8,"tv":32.93,"id":13117502}]}]}
{"op":"mcm","clk":"1001452770","pt":1580636161457,"mc":[{"id":"1.168215938","rc":[{"batb":[[0,2.46,60.35],[1,2.42,76.59],[2,2.38,17.15]],"ltp":2.92,"tv":276.24,"id":13117454},{"batb":[[0,3.65,34.22],[1,3.6,34.85],[2,3.55,15.82]],"ltp":3.8,"tv":32.93,"id":13117502}]}]}
{"op":"mcm","clk":"1001453566","pt":1580636178711,"mc":[{"id":"1.168215938","rc":[{"batb":[[0,2.38,17.15],[1,1.01,0.51],[2,2.38,0]],"ltp":2.92,"tv":276.24,"id":13117454}]}]}
{"op":"mcm","clk":"1001453733","pt":1580636181608,"mc":[{"id":"1.168215938","rc":[{"batb":[[0,2.98,52.59],[1,2.94,45.94],[2,2.38,17.15]],"ltp":2.92,"tv":276.24,"id":13117454}]}]}
{"op":"mcm","clk":"1001453778","pt":1580636182794,"mc":[{"id":"1.168215938","rc":[{"batl":[[0,5.5,14.24]],"ltp":5.0,"tv":105.34,"id":13117455},{"batb":[[2,2.88,10.46]],"batl":[[1,3.35,21.01]],"ltp":2.92,"tv":276.24,"id":13117454},{"batl":[[0,3.9,15.34],[1,4.6,21.17]],"ltp":3.8,"tv":32.93,"id":13117502}]}]}
{"op":"mcm","clk":"1001453802","pt":1580636183202,"mc":[{"id":"1.168215938","rc":[{"batl":[[0,5,10.08],[1,5.5,14.24]],"ltp":5.0,"tv":105.34,"id":13117455},{"batl":[[1,5.3,9.24],[2,5.4,14.56]],"ltp":5.1,"tv":12.0,"id":13117503},{"batb":[[1,2.94,66.94]],"batl":[[1,3.35,38.65]],"ltp":2.92,"tv":276.24,"id":13117454},{"batb":[[2,3.55,31.78]],"batl":[[1,4.1,13.44],[2,4.6,21.17]],"ltp":3.8,"tv":32.93,"id":13117502}]}]}
{"op":"mcm","clk":"1001454085","pt":1580636189305,"mc":[{"id":"1.168215938","rc":[{"batb":[[1,4.5,27.28]],"ltp":5.0,"tv":105.34,"id":13117455},{"batb":[[0,2.94,21],[1,2.58,13.93],[2,1.01,0.51]],"batl":[[0,3.35,38.65],[1,3.35,0]],"ltp":2.92,"tv":276.24,"id":13117454},{"batb":[[0,3.55,15.96],[1,3.3,19.28],[2,1.01,0.51]],"batl":[[0,4.1,13.44],[1,4.6,21.17],[2,4.6,0]],"ltp":3.8,"tv":32.93,"id":13117502}]}]}
{"op":"mcm","clk":"1001454121","pt":1580636190231,"mc":[{"id":"1.168215938","rc":[{"batl":[[0,5.5,14.24],[1,5.5,0]],"ltp":5.0,"tv":105.34,"id":13117455},{"batl":[[1,5.4,14.56],[2,5.4,0]],"ltp":5.1,"tv":12.0,"id":13117503},{"batb":[[0,2.58,13.93],[1,1.01,0.51],[2,1.01,0]],"batl":[[0,3.35,21.01]],"ltp":2.92,"tv":276.24,"id":13117454},{"batb":[[0,3.3,19.28],[1,1.01,0.51],[2,1.01,0]],"batl":[[0,4.6,21.17],[1,4.6,0]],"ltp":3.8,"tv":32.93,"id":13117502}]}]}
{"op":"mcm","clk":"1001454201","pt":1580636192235,"mc":[{"id":"1.168215938","rc":[{"batb":[[0,2.66,45.54],[1,2.62,61.97],[2,2.58,13.93]],"ltp":2.92,"tv":276.24,"id":13117454},{"batb":[[0,3.35,69.59],[1,3.3,62.01],[2,1.01,0.51]],"ltp":3.8,"tv":32.93,"id":13117502}]}]}
{"op":"mcm","clk":"1001454302","pt":1580636194634,"mc":[{"id":"1.168215938","rc":[{"batb":[[0,2.58,13.93],[1,1.01,0.51],[2,2.58,0]],"ltp":2.92,"tv":276.24,"id":13117454},{"batb":[[0,3.3,19.28],[1,1.01,0.51],[2,1.01,0]],"ltp":3.8,"tv":32.93,"id":13117502}]}]}
{"op":"mcm","clk":"1001454382","pt":1580636197615,"mc":[{"id":"1.168215938","rc":[{"batb":[[1,4.5,45.03]],"ltp":5.0,"tv":105.34,"id":13117455},{"batb":[[0,2.92,39.11],[1,2.88,48.52],[2,2.58,13.93]],"ltp":2.92,"tv":276.24,"id":13117454},{"batb":[[0,3.75,36.82],[1,3.7,32.61],[2,3.3,19.28]],"ltp":3.8,"tv":32.93,"id":13117502}]}]}
{"op":"mcm","clk":"1001454407","pt":1580636198546,"mc":[{"id":"1.168215938","rc":[{"batb":[[1,4.5,27.28]],"ltp":5.0,"tv":105.34,"id":13117455},{"batb":[[0,2.58,13.93],[1,1.01,0.51],[2,2.58,0]],"ltp":2.92,"tv":276.24,"id":13117454},{"batb":[[0,3.3,19.28],[1,1.01,0.51],[2,3.3,0]],"ltp":3.8,"tv":32.93,"id":13117502}]}]}
{"op":"mcm","clk":"1001454503","pt":1580636200826,"mc":[{"id":"1.168215938","rc":[{"batb":[[2,1.01,0.51]],"ltp":5.0,"tv":105.34,"id":13117455}]}]}
{"op":"mcm","clk":"1001454531","pt":1580636201657,"mc":[{"id":"1.168215938","rc":[{"batb":[[0,2.66,45.54],[1,2.62,61.97],[2,2.58,13.93]],"ltp":2.92,"tv":276.24,"id":13117454}]}]}
{"op":"mcm","clk":"1001454605","pt":1580636203927,"mc":[{"id":"1.168215938","rc":[{"batb":[[0,4.9,14.87],[1,4.8,15.5],[2,4.6,22.57]],"batl":[[1,5.7,13.14]],"ltp":5.0,"tv":105.34,"id":13117455},{"batl":[[0,2.72,13.69],[1,3,10.86],[2,3.35,21.01]],"ltp":2.92,"tv":276.24,"id":13117454},{"batb":[[0,4.2,52.71],[1,4.1,72.6],[2,3.65,14.79]],"batl":[[1,5.9,12.51]],"ltp":3.8,"tv":32.93,"id":13117502}]}]}
{"op":"mcm","clk":"1001454619","pt":1580636204341,"mc":[{"id":"1.168215938","rc":[{"batb":[[1,4.8,15.34]],"ltp":5.0,"tv":105.34,"id":13117455},{"batl":[[2,3.35,0]],"ltp":2.92,"tv":276.24,"id":13117454}]}]}
{"op":"mcm","clk":"1001454662","pt":1580636205319,"mc":[{"id":"1.168215938","rc":[{"batl":[[0,5.1,10.08],[1,5.5,14.24],[2,5.7,13.14]],"ltp":5.0,"tv":105.34,"id":13117455},{"batl":[[1,5.3,9.24],[2,5.4,14.56]],"ltp":5.1,"tv":12.0,"id":13117503},{"batb":[[0,2.66,70.75]],"batl":[[1,3,31.86]],"ltp":2.92,"tv":276.24,"id":13117454},{"batb":[[2,4,13.44]],"batl":[[1,4.7,10.92],[2,5.9,12.51]],"ltp":3.8,"tv":32.93,"id":13117502}]}]}
{"op":"mcm","clk":"1001455465","pt":1580636223586,"mc":[{"id":"1.168215938","rc":[{"batb":[[2,4.3,12.6]],"ltp":5.0,"tv":105.34,"id":13117455},{"batb":[[0,4.7,15.34],[1,4.5,11.76],[2,1.01,0.51]],"ltp":5.1,"tv":12.0,"id":13117503},{"batb":[[0,2.66,25.21],[1,2.58,13.93],[2,2.24,20.38]],"ltp":2.92,"tv":276.24,"id":13117454},{"batb":[[0,4.1,22.35],[1,4,13.44],[2,3.65,14.79]],"ltp":3.8,"tv":32.93,"id":13117502}]}]}
{"op":"mcm","clk":"1001455510","pt":1580636224262,"mc":[{"id":"1.168215938","rc":[{"batb":[[2,1.01,0.51]],"batl":[[0,5.5,14.24],[1,5.7,13.14],[2,5.7,0]],"ltp":5.0,"tv":105.34,"id":13117455},{"batb":[[1,1.01,0.51],[2,1.01,0]],"batl":[[1,5.4,14.56],[2,5.4,0]],"ltp":5.1,"tv":12.0,"id":13117503},{"batb":[[0,2.58,13.93],[1,2.24,20.38],[2,1.01,0.51]],"batl":[[1,3,10.86]],"ltp":2.92,"tv":276.24,"id":13117454},{"batb":[[1,3.65,14.79],[2,1.01,0.51]],"batl":[[1,5.9,12.51],[2,5.9,0]],"ltp":3.8,"tv":32.93,"id":13117502}]}]}
{"op":"mcm","clk":"1001455547","pt":1580636225141,"mc":[{"id":"1.168215938","rc":[{"batb":[[0,1.01,0.51],[1,4.8,0],[2,1.01,0]],"ltp":5.0,"tv":105.34,"id":13117455},{"batb":[[0,1.01,0.51],[1,1.01,0]],"batl":[[1,5.4,0]],"ltp":5.1,"tv":12.0,"id":13117503},{"batb":[[0,1.01,0.51],[1,2.24,0],[2,1.01,0]],"ltp":2.92,"tv":276.24,"id":13117454},{"batb":[[0,1.01,0.51],[1,3.65,0],[2,1.01,0]],"ltp":3.8,"tv":32.93,"id":13117502}]}]}
{"op":"mcm","clk":"1001458081","pt":1580636281948,"mc":[{"id":"1.168215938","rc":[{"batb":[[0,4.7,22.95],[1,4.6,38.94],[2,4.4,11.76]],"batl":[[0,5.2,9.24]],"ltp":5.0,"tv":105.34,"id":13117455},{"batb":[[0,4.9,37.75],[1,4.8,35.11],[2,4.5,11.76]],"batl":[[1,5.3,9.24]],"ltp":5.1,"tv":12.0,"id":13117503},{"batb":[[0,2.32,31.09],[1,2.3,66.12],[2,2.28,45.55]],"batl":[[0,2.6,26.05]],"ltp":2.92,"tv":276.24,"id":13117454},{"batb":[[0,5.5,22.02],[1,5.4,27.12],[2,5.1,10.08]],"batl":[[0,6.2,7.56]],"ltp":3.8,"tv":32.93,"id":13117502}]}]}
{"op":"mcm","clk":"1001458135","pt":1580636283041,"mc":[{"id":"1.168215938","rc":[{"batb":[[1,1.01,0.51],[2,2.28,0]],"ltp":2.92,"tv":276.24,"id":13117454},{"batb":[[0,5.1,10.08],[1,1.01,0.51],[2,5.1,0]],"ltp":3.8,"tv":32.93,"id":13117502}]}]}
{"op":"mcm","clk":"1001458206","pt":1580636284747,"mc":[{"id":"1.168215938","rc":[{"batb":[[2,1.01,0.51]],"ltp":5.0,"tv":105.34,"id":13117455},{"batb":[[2,1.01,0.51]],"batl":[[1,5.3,0]],"ltp":5.1,"tv":12.0,"id":13117503},{"batb":[[0,1.01,0.51],[1,1.01,0]],"ltp":2.92,"tv":276.24,"id":13117454},{"batb":[[0,1.01,0.51],[1,1.01,0]],"ltp":3.8,"tv":32.93,"id":13117502}]}]}
{"op":"mcm","clk":"1001458239","pt":1580636285942,"mc":[{"id":"1.168215938","rc":[{"batb":[[0,4.7,31.99]],"ltp":5.0,"tv":105.34,"id":13117455},{"batb":[[0,2.24,59.53],[1,2.22,49.14],[2,1.01,0.51]],"ltp":2.92,"tv":276.24,"id":13117454},{"batb":[[0,5.8,36.45],[1,5.7,23.88],[2,1.01,0.51]],"ltp":3.8,"tv":32.93,"id":13117502}]}]}
{"op":"mcm","clk":"1001458402","pt":1580636290437,"mc":[{"id":"1.168215938","rc":[{"batb":[[0,2.22,49.14],[1,1.01,0.51],[2,1.01,0]],"ltp":2.92,"tv":276.24,"id":13117454},{"batb":[[0,5.8,23.3],[1,1.01,0.51],[2,1.01,0]],"ltp":3.8,"tv":32.93,"id":13117502}]}]}
{"op":"mcm","clk":"1001458494","pt":1580636292868,"mc":[{"id":"1.168215938","rc":[{"batb":[[0,4.6,29.7],[1,1.01,0.51],[2,1.01,0]],"ltp":5.0,"tv":105.34,"id":13117455},{"batb":[[0,1.01,0.51],[1,1.01,0]],"ltp":2.92,"tv":276.24,"id":13117454},{"batb":[[0,1.01,0.51],[1,1.01,0]],"ltp":3.8,"tv":32.93,"id":13117502}]}]}
{"op":"mcm","clk":"1001458545","pt":1580636293538,"mc":[{"id":"1.168215938","rc":[{"batb":[[0,4.9,49.34]],"ltp":5.1,"tv":12.0,"id":13117503}]}]}
{"op":"mcm","clk":"1001458643","pt":1580636295864,"mc":[{"id":"1.168215938","rc":[{"batb":[[1,4.5,40.75],[2,1.01,0.51]],"ltp":5.0,"tv":105.34,"id":13117455},{"batb":[[0,2.02,58.47],[1,2,66.75],[2,1.01,0.51]],"ltp":2.92,"tv":276.24,"id":13117454},{"batb":[[0,4.7,29.72],[1,4.6,39.07],[2,1.01,0.51]],"ltp":3.8,"tv":32.93,"id":13117502}]}]}
{"op":"mcm","clk":"1001459222","pt":1580636308776,"mc":[{"id":"1.168215938","rc":[{"batb":[[0,1.01,0.51],[1,4.5,0],[2,1.01,0]],"ltp":5.0,"tv":105.34,"id":13117455},{"batb":[[0,1.01,0.51],[1,4.8,0],[2,1.01,0]],"ltp":5.1,"tv":12.0,"id":13117503},{"batb":[[0,1.01,0.51],[1,2,0],[2,1.01,0]],"ltp":2.92,"tv":276.24,"id":13117454},{"batb":[[0,1.01,0.51],[1,4.6,0],[2,1.01,0]],"ltp":3.8,"tv":32.93,"id":13117502}]}]}
{"op":"mcm","clk":"1001471064","pt":1580636550658,"mc":[{"id":"1.168215938","rc":[{"batb":[[0,4.7,40.8],[1,4.6,38.59],[2,1.01,0.51]],"ltp":5.0,"tv":105.34,"id":13117455},{"batb":[[0,4.8,43.39],[1,4.7,36.95],[2,1.01,0.51]],"ltp":5.1,"tv":12.0,"id":13117503},{"batb":[[0,1.93,67.27],[1,1.91,76.92],[2,1.01,0.51]],"ltp":2.92,"tv":276.24,"id":13117454},{"batb":[[0,6.8,18.45],[1,6.6,34.65],[2,1.01,0.51]],"ltp":3.8,"tv":32.93,"id":13117502}]}]}
{"op":"mcm","clk":"1001471119","pt":1580636551793,"mc":[{"id":"1.168215938","rc":[{"batb":[[0,6.6,34.65],[1,1.01,0.51],[2,1.01,0]],"ltp":3.8,"tv":32.93,"id":13117502}]}]}
{"op":"mcm","clk":"1001471231","pt":1580636554956,"mc":[{"id":"1.168215938","rc":[{"batb":[[0,4.8,35.95]],"ltp":5.1,"tv":12.0,"id":13117503},{"batb":[[0,1.01,0.51],[1,1.91,0],[2,1.01,0]],"ltp":2.92,"tv":276.24,"id":13117454},{"batb":[[0,6.6,49.46],[1,6.4,36.13],[2,1.01,0.51]],"ltp":3.8,"tv":32.93,"id":13117502}]}]}
{"op":"mcm","clk":"1001471379","pt":1580636557898,"mc":[{"id":"1.168215938","rc":[{"batb":[[1,4.4,11.76]],"batl":[[0,5.2,9.24]],"ltp":5.0,"tv":105.34,"id":13117455},{"batb":[[0,4.7,36.95],[1,4.4,11.76]],"batl":[[1,5.2,9.24]],"ltp":5.1,"tv":12.0,"id":13117503},{"batb":[[0,2.14,54.72],[1,1.01,0.51]],"batl":[[0,2.26,32.77]],"ltp":2.92,"tv":276.24,"id":13117454},{"batb":[[0,7.4,5.88],[1,6.6,34.65],[2,6.4,36.13]],"ltp":3.8,"tv":32.93,"id":13117502}]}]}
{"op":"mcm","clk":"1001471518","pt":1580636560687,"mc":[{"id":"1.168215938","rc":[{"batb":[[0,4.8,21.43],[1,4.7,40.8],[2,4.4,11.76]],"ltp":5.0,"tv":105.34,"id":13117455},{"batb":[[0,4.7,46.37],[1,4.6,38.21],[2,4.4,11.76]],"ltp":5.1,"tv":12.0,"id":13117503},{"batb":[[0,2.16,75.47],[1,2.14,54.72],[2,2.06,39.49]],"ltp":2.92,"tv":276.24,"id":13117454}]}]}
{"op":"mcm","clk":"1001471591","pt":1580636561777,"mc":[{"id":"1.168215938","rc":[{"batl":[[0,9.2,5.04]],"ltp":3.8,"tv":32.93,"id":13117502}]}]}
{"op":"mcm","clk":"1001472028","pt":1580636571229,"mc":[{"id":"1.168215938","rc":[{"batb":[[0,4.7,40.8],[1,4.4,11.76],[2,1.01,0.51]],"ltp":5.0,"tv":105.34,"id":13117455},{"batb":[[0,2.16,54.22]],"ltp":2.92,"tv":276.24,"id":13117454}]}]}
{"op":"mcm","clk":"1001472103","pt":1580636572685,"mc":[{"id":"1.168215938","rc":[{"batb":[[0,4.7,36.97],[1,4.4,11.76],[2,1.01,0.51]],"ltp":5.1,"tv":12.0,"id":13117503},{"batb":[[0,2.14,54.72],[1,2.06,39.49],[2,1.01,0.51]],"ltp":2.92,"tv":276.24,"id":13117454}]}]}
{"op":"mcm","clk":"1001472214","pt":1580636574602,"mc":[{"id":"1.168215938","rc":[{"batb":[[0,4.6,38.61],[1,1.01,0.51],[2,1.01,0]],"ltp":5.0,"tv":105.34,"id":13117455},{"batb":[[0,4.7,36.95],[1,1.01,0.51],[2,1.01,0]],"batl":[[1,5.2,0]],"ltp":5.1,"tv":12.0,"id":13117503},{"batb":[[0,1.01,0.51],[1,2.06,0],[2,1.01,0]],"ltp":2.92,"tv":276.24,"id":13117454},{"batb":[[0,1.01,0.51],[1,6.6,0],[2,6.4,0]],"ltp":3.8,"tv":32.93,"id":13117502}]}]}
{"op":"mcm","clk":"1001472274","pt":1580636575791,"mc":[{"id":"1.168215938","rc":[{"batb":[[0,4.8,24.31],[1,4.7,36.95],[2,1.01,0.51]],"ltp":5.1,"tv":12.0,"id":13117503}]}]}
{"op":"mcm","clk":"1001472367","pt":1580636577186,"mc":[{"id":"1.168215938","rc":[{"batb":[[0,4.6,60.98],[1,4.5,40.63],[2,1.01,0.51]],"ltp":5.0,"tv":105.34,"id":13117455},{"batb":[[0,2.02,85.81],[1,2,66.72],[2,1.01,0.51]],"ltp":2.92,"tv":276.24,"id":13117454},{"batb":[[0,5,23.77],[1,4.9,33.97],[2,1.01,0.51]],"ltp":3.8,"tv":32.93,"id":13117502}]}]}
{"op":"mcm","clk":"1001472528","pt":1580636580595,"mc":[{"id":"1.168215938","rc":[{"batb":[[0,1.01,0.51],[1,4.5,0],[2,1.01,0]],"ltp":5.0,"tv":105.34,"id":13117455},{"batb":[[0,1.01,0.51],[1,2,0],[2,1.01,0]],"ltp":2.92,"tv":276.24,"id":13117454},{"batb":[[0,1.01,0.51],[1,4.9,0],[2,1.01,0]],"ltp":3.8,"tv":32.93,"id":13117502}]}]}
{"op":"mcm","clk":"1001472763","pt":1580636583600,"mc":[{"id":"1.168215938","rc":[{"batb":[[0,4.8,29.6],[1,4.7,37.01],[2,4.4,11.76]],"batl":[[0,5.2,9.24]],"ltp":5.0,"tv":105.34,"id":13117455},{"batb":[[2,4.4,11.76]],"batl":[[1,5.2,9.24]],"ltp":5.1,"tv":12.0,"id":13117503},{"batb":[[0,2.02,85.81],[1,2,66.72],[2,1.97,42.85]],"batl":[[0,2.16,36.13]],"ltp":2.92,"tv":276.24,"id":13117454},{"batb":[[0,8.6,5.04],[1,8.2,29.43],[2,8,22.44]],"batl":[[0,11.5,3.36]],"ltp":3.8,"tv":32.93,"id":13117502}]}]}
{"op":"mcm","clk":"1001473077","pt":1580636589326,"mc":[{"id":"1.168215938","rc":[{"batb":[[1,8.2,21.75],[2,1.01,0.51]],"ltp":3.8,"tv":32.93,"id":13117502}]}]}
{"op":"mcm","clk":"1001473248","pt":1580636592637,"mc":[{"id":"1.168215938","rc":[{"batb":[[1,8.4,12.27],[2,8.2,21.75]],"batl":[[0,11,248.68],[1,11.5,3.36]],"ltp":3.8,"tv":32.93,"id":13117502}]}]}
{"op":"mcm","clk":"1001473266","pt":1580636593058,"mc":[{"id":"1.168215938","rc":[{"batl":[[1,11.5,0]],"ltp":3.8,"tv":32.93,"id":13117502}]}]}
{"op":"mcm","clk":"1001473439","pt":1580636596011,"mc":[{"id":"1.168215938","rc":[{"batl":[[0,11,252.88]],"ltp":3.8,"tv":32.93,"id":13117502}]}]}
{"op":"mcm","clk":"1001473924","pt":1580636606841,"mc":[{"id":"1.168215938","rc":[{"batb":[[0,4.7,37.01],[1,4.4,11.76],[2,1.01,0.51]],"ltp":5.0,"tv":105.34,"id":13117455},{"batb":[[0,4.7,36.95],[1,4.4,11.76],[2,1.01,0.51]],"ltp":5.1,"tv":12.0,"id":13117503},{"batb":[[0,1.97,42.85],[1,1.01,0.51],[2,1.97,0]],"ltp":2.92,"tv":276.24,"id":13117454},{"batb":[[1,1.01,0.51],[2,8.2,0]],"batl":[[0,11,4.2]],"ltp":3.8,"tv":32.93,"id":13117502}]}]}
{"op":"mcm","clk":"1001474012","pt":1580636608644,"mc":[{"id":"1.168215938","rc":[{"batb":[[1,1.01,0.51],[2,1.01,0]],"ltp":5.0,"tv":105.34,"id":13117455},{"batb":[[1,1.01,0.51],[2,1.01,0]],"batl":[[1,5.2,0]],"ltp":5.1,"tv":12.0,"id":13117503},{"batb":[[0,1.01,0.51],[1,1.01,0]],"ltp":2.92,"tv":276.24,"id":13117454},{"batb":[[0,1.01,0.51],[1,1.01,0]],"ltp":3.8,"tv":32.93,"id":13117502}]}]}
{"op":"mcm","clk":"1001474064","pt":1580636609934,"mc":[{"id":"1.168215938","rc":[{"batb":[[0,4.7,49.1],[1,4.6,38.67],[2,1.01,0.51]],"ltp":5.0,"tv":105.34,"id":13117455},{"batb":[[0,4.7,51.04],[1,4.6,38.41],[2,1.01,0.51]],"ltp":5.1,"tv":12.0,"id":13117503},{"batb":[[0,1.95,77.3],[1,1.93,74.52],[2,1.01,0.51]],"ltp":2.92,"tv":276.24,"id":13117454},{"batb":[[0,6.6,22.33],[1,6.4,36.94],[2,1.01,0.51]],"ltp":3.8,"tv":32.93,"id":13117502}]}]}
{"op":"mcm","clk":"1001474145","pt":1580636611837,"mc":[{"id":"1.168215938","rc":[{"batb":[[0,4.7,37.01],[1,1.01,0.51],[2,1.01,0]],"ltp":5.0,"tv":105.34,"id":13117455},{"batb":[[0,4.7,36.95],[1,1.01,0.51],[2,1.01,0]],"ltp":5.1,"tv":12.0,"id":13117503},{"batb":[[0,1.01,0.51],[1,6.4,0],[2,1.01,0]],"ltp":3.8,"tv":32.93,"id":13117502}]}]}
{"op":"mcm","clk":"1001474259","pt":1580636614666,"mc":[{"id":"1.168215938","rc":[{"batb":[[0,4.8,39.48],[1,4.7,37.01],[2,1.01,0.51]],"ltp":5.0,"tv":105.34,"id":13117455},{"batb":[[0,4.8,28.81],[1,4.7,36.95],[2,1.01,0.51]],"ltp":5.1,"tv":12.0,"id":13117503},{"batb":[[0,9.6,24.34],[1,9.4,15.99],[2,1.01,0.51]],"ltp":3.8,"tv":32.93,"id":13117502}]}]}
{"op":"mcm","clk":"1001474300","pt":1580636615643,"mc":[{"id":"1.168215938","rc":[{"batb":[[2,4.5,11.76]],"batl":[[0,5.2,9.24]],"ltp":5.0,"tv":105.34,"id":13117455},{"batb":[[2,4.5,11.76]],"batl":[[1,5.3,9.24]],"ltp":5.1,"tv":12.0,"id":13117503},{"batb":[[2,1.91,45.37]],"batl":[[0,2.1,37.81]],"ltp":2.92,"tv":276.24,"id":13117454},{"batb":[[0,9.8,4.2],[1,9.6,24.34],[2,9.4,15.99]],"batl":[[0,13,3.36]],"ltp":3.8,"tv":32.93,"id":13117502}]}]}
{"op":"mcm","clk":"1001474400","pt":1580636617757,"mc":[{"id":"1.168215938","rc":[{"batb":[[0,9.6,24.34],[1,9.4,15.99],[2,1.01,0.51]],"ltp":3.8,"tv":32.93,"id":13117502}]}]}
{"op":"mcm","clk":"1001474487","pt":1580636620186,"mc":[{"id":"1.168215938","rc":[{"batl":[[0,2.08,38.65]],"ltp":2.92,"tv":276.24,"id":13117454},{"batb":[[0,10,4.2],[1,9.6,24.34],[2,9.4,15.99]],"ltp":3.8,"tv":32.93,"id":13117502}]}]}
{"op":"mcm","clk":"1001475422","pt":1580636640787,"mc":[{"id":"1.168215938","rc":[{"batb":[[0,4.8,27.91],[2,1.01,0.51]],"ltp":5.0,"tv":105.34,"id":13117455},{"batb":[[0,4.7,36.95],[1,1.01,0.51],[2,4.5,0]],"batl":[[1,5.3,0]],"ltp":5.1,"tv":12.0,"id":13117503},{"batb":[[0,1.01,0.51],[1,1.93,0],[2,1.91,0]],"ltp":2.92,"tv":276.24,"id":13117454},{"batb":[[0,1.01,0.51],[1,9.6,0],[2,9.4,0]],"ltp":3.8,"tv":32.93,"id":13117502}]}]}
{"op":"mcm","clk":"1001475747","pt":1580636647579,"mc":[{"id":"1.168215938","rc":[{"batb":[[0,4.8,42.74]],"ltp":5.0,"tv":105.34,"id":13117455},{"batb":[[0,4.8,35.28],[1,4.7,36.95],[2,1.01,0.51]],"ltp":5.1,"tv":12.0,"id":13117503},{"batb":[[0,1.94,52.3],[1,1.92,75.57],[2,1.01,0.51]],"ltp":2.92,"tv":276.24,"id":13117454},{"batb":[[0,10,18.49],[1,9.8,14.75],[2,1.01,0.51]],"ltp":3.8,"tv":32.93,"id":13117502}]}]}
{"op":"mcm","clk":"1001475918","pt":1580636651591,"mc":[{"id":"1.168215938","rc":[{"batb":[[0,4.8,27.91]],"ltp":5.0,"tv":105.34,"id":13117455},{"batb":[[0,4.7,36.95],[1,1.01,0.51],[2,1.01,0]],"ltp":5.1,"tv":12.0,"id":13117503},{"batb":[[0,1.01,0.51],[1,1.92,0],[2,1.01,0]],"ltp":2.92,"tv":276.24,"id":13117454},{"batb":[[0,1.01,0.51],[1,9.8,0],[2,1.01,0]],"ltp":3.8,"tv":32.93,"id":13117502}]}]}
{"op":"mcm","clk":"1001476130","pt":1580636654946,"mc":[{"id":"1.168215938","rc":[{"batb":[[0,4.7,51.86],[1,4.6,38.27],[2,1.01,0.51]],"ltp":5.1,"tv":12.0,"id":13117503},{"batb":[[0,1.87,84.36],[1,1.85,85.01],[2,1.01,0.51]],"ltp":2.92,"tv":276.24,"id":13117454},{"batb":[[0,8.8,23.05],[1,8.6,19.39],[2,1.01,0.51]],"ltp":3.8,"tv":32.93,"id":13117502}]}]}
{"op":"mcm","clk":"1001477254","pt":1580636673676,"mc":[{"id":"1.168215938","rc":[{"batb":[[0,1.01,0.51],[1,4.7,0],[2,1.01,0]],"ltp":5.0,"tv":105.34,"id":13117455},{"batb":[[0,1.01,0.51],[1,4.6,0],[2,1.01,0]],"ltp":5.1,"tv":12.0,"id":13117503},{"batb":[[0,1.01,0.51],[1,1.85,0],[2,1.01,0]],"ltp":2.92,"tv":276.24,"id":13117454},{"batb":[[0,1.01,0.51],[1,8.6,0],[2,1.01,0]],"ltp":3.8,"tv":32.93,"id":13117502}]}]}
{"op":"mcm","clk":"1001491565","pt":1580636940936,"mc":[{"id":"1.168215938","rc":[{"batb":[[0,4.7,28.55],[1,4.6,38.89],[2,1.01,0.51]],"ltp":5.0,"tv":105.34,"id":13117455},{"batb":[[0,4.7,41.08],[1,4.6,38.5],[2,1.01,0.51]],"ltp":5.1,"tv":12.0,"id":13117503},{"batb":[[0,1.98,84.7],[1,1.96,70.9],[2,1.01,0.51]],"ltp":2.92,"tv":276.24,"id":13117454},{"batb":[[0,5.8,35.02],[1,5.7,23.94],[2,1.01,0.51]],"ltp":3.8,"tv":32.93,"id":13117502}]}]}
{"op":"mcm","clk":"1001491608","pt":1580636941610,"mc":[{"id":"1.168215938","rc":[{"batb":[[0,1.01,0.51],[1,1.96,0],[2,1.01,0]],"ltp":2.92,"tv":276.24,"id":13117454},{"batb":[[0,1.01,0.51],[1,5.7,0],[2,1.01,0]],"ltp":3.8,"tv":32.93,"id":13117502}]}]}
{"op":"mcm","clk":"1001491834","pt":1580636944919,"mc":[{"id":"1.168215938","rc":[{"batb":[[0,4.7,47.06]],"ltp":5.0,"tv":105.34,"id":13117455},{"batb":[[0,2.12,55.2],[1,2.1,57.64],[2,1.01,0.51]],"ltp":2.92,"tv":276.24,"id":13117454},{"batb":[[0,7.2,26.12],[1,7,30.16],[2,1.01,0.51]],"ltp":3.8,"tv":32.93,"id":13117502}]}]}
{"op":"mcm","clk":"1001491848","pt":1580636945129,"mc":[{"id":"1.168215938","rc":[{"batb":[[0,4.7,28.55]],"ltp":5.0,"tv":105.34,"id":13117455},{"batb":[[0,1.01,0.51],[1,2.1,0],[2,1.01,0]],"ltp":2.92,"tv":276.24,"id":13117454},{"batb":[[0,1.01,0.51],[1,7,0],[2,1.01,0]],"ltp":3.8,"tv":32.93,"id":13117502}]}]}
{"op":"mcm","clk":"1001492136","pt":1580636949112,"mc":[{"id":"1.168215938","rc":[{"batb":[[0,1.98,74.9],[1,1.96,70.89],[2,1.01,0.51]],"ltp":2.92,"tv":276.24,"id":13117454},{"batb":[[0,5.8,39.23],[1,5.7,23.94],[2,1.01,0.51]],"ltp":3.8,"tv":32.93,"id":13117502}]}]}
{"op":"mcm","clk":"1001492888","pt":1580636959858,"mc":[{"id":"1.168215938","rc":[{"batb":[[1,1.01,0.51],[2,1.01,0]],"ltp":5.0,"tv":105.34,"id":13117455},{"batb":[[0,1.01,0.51],[1,5.7,0],[2,1.01,0]],"ltp":3.8,"tv":32.93,"id":13117502}]}]}
{"op":"mcm","clk":"1001493111","pt":1580636962848,"mc":[{"id":"1.168215938","rc":[{"batb":[[0,4.7,37.01]],"ltp":5.0,"tv":105.34,"id":13117455},{"batb":[[1,1.01,0.51],[2,1.01,0]],"ltp":5.1,"tv":12.0,"id":13117503},{"batb":[[0,1.01,0.51],[1,1.96,0],[2,1.01,0]],"ltp":2.92,"tv":276.24,"id":13117454},{"batb":[[0,9.2,17.17],[1,1.01,0.51]],"ltp":3.8,"tv":32.93,"id":13117502}]}]}
{"op":"mcm","clk":"1001493211","pt":1580636963948,"mc":[{"id":"1.168215938","rc":[{"batb":[[1,4.5,11.76],[2,1.01,0.51]],"batl":[[0,5.3,9.24]],"ltp":5.0,"tv":105.34,"id":13117455},{"batb":[[1,4.2,12.6],[2,1.01,0.51]],"batl":[[0,5,10.08],[1,5.1,5.72]],"ltp":5.1,"tv":12.0,"id":13117503},{"batb":[[0,1.98,42.85],[1,1.01,0.51]],"batl":[[0,2.18,35.29]],"ltp":2.92,"tv":276.24,"id":13117454},{"batb":[[0,9.2,22.21]],"batl":[[0,12,3.36]],"ltp":3.8,"tv":32.93,"id":13117502}]}]}
{"op":"mcm","clk":"1001493330","pt":1580636965960,"mc":[{"id":"1.168215938","rc":[{"batb":[[0,4.7,55.21],[1,4.6,38.25],[2,4.5,11.76]],"ltp":5.0,"tv":105.34,"id":13117455},{"batb":[[0,4.8,33.06],[1,4.7,41.08],[2,4.2,12.6]],"ltp":5.1,"tv":12.0,"id":13117503},{"batb":[[1,1.97,86.03],[2,1.95,72.01]],"ltp":2.92,"tv":276.24,"id":13117454},{"batb":[[0,9.4,12.18],[1,9.2,22.21],[2,1.01,0.51]],"ltp":3.8,"tv":32.93,"id":13117502}]}]}
{"op":"mcm","clk":"1001494058","pt":1580636977955,"mc":[{"id":"1.168215938","rc":[{"batb":[[0,4.7,37.01]],"ltp":5.0,"tv":105.34,"id":13117455},{"batb":[[0,4.7,41.08],[1,4.2,12.6],[2,1.01,0.51]],"ltp":5.1,"tv":12.0,"id":13117503},{"batb":[[1,1.01,0.51],[2,1.95,0]],"ltp":2.92,"tv":276.24,"id":13117454},{"batb":[[0,9.2,5.04],[1,1.01,0.51],[2,1.01,0]],"ltp":3.8,"tv":32.93,"id":13117502}]}]}
{"op":"mcm","clk":"1001494104","pt":1580636978987,"mc":[{"id":"1.168215938","rc":[{"batb":[[2,1.01,0.51]],"ltp":5.0,"tv":105.34,"id":13117455},{"batb":[[1,1.01,0.51],[2,1.01,0]],"batl":[[0,5.1,5.72],[1,5.1,0]],"ltp":5.1,"tv":12.0,"id":13117503},{"batb":[[0,1.01,0.51],[1,1.01,0]],"ltp":2.92,"tv":276.24,"id":13117454},{"batb":[[0,1.01,0.51],[1,1.01,0]],"ltp":3.8,"tv":32.93,"id":13117502}]}]}
{"op":"mcm","clk":"1001494209","pt":1580636980788,"mc":[{"id":"1.168215938","rc":[{"batb":[[0,4.7,58.21],[1,4.6,38.59],[2,1.01,0.51]],"ltp":5.1,"tv":12.0,"id":13117503},{"batb":[[0,1.91,67.28],[1,1.89,79.38],[2,1.01,0.51]],"ltp":2.92,"tv":276.24,"id":13117454},{"batb":[[0,7.2,37.74],[1,7,30.22],[2,1.01,0.51]],"ltp":3.8,"tv":32.93,"id":13117502}]}]}
{"op":"mcm","clk":"1001494226","pt":1580636980990,"mc":[{"id":"1.168215938","rc":[{"batb":[[0,4.7,41.08],[1,1.01,0.51],[2,1.01,0]],"ltp":5.1,"tv":12.0,"id":13117503},{"batb":[[0,1.01,0.51],[1,1.89,0],[2,1.01,0]],"ltp":2.92,"tv":276.24,"id":13117454},{"batb":[[0,1.01,0.51],[1,7,0],[2,1.01,0]],"ltp":3.8,"tv":32.93,"id":13117502}]}]}
{"op":"mcm","clk":"1001494381","pt":1580636983273,"mc":[{"id":"1.168215938","rc":[{"batb":[[0,4.7,49.76]],"ltp":5.0,"tv":105.34,"id":13117455},{"batb":[[0,4.8,33.02],[1,4.7,41.08],[2,1.01,0.51]],"ltp":5.1,"tv":12.0,"id":13117503},{"batb":[[0,2,66.22],[1,1.98,68.71],[2,1.01,0.51]],"ltp":2.92,"tv":276.24,"id":13117454},{"batb":[[0,8.8,24.08],[1,8.6,19.6],[2,1.01,0.51]],"ltp":3.8,"tv":32.93,"id":13117502}]}]}
{"op":"mcm","clk":"1001494598","pt":1580636986595,"mc":[{"id":"1.168215938","rc":[{"batb":[[0,4.7,37.01]],"ltp":5.0,"tv":105.34,"id":13117455},{"batb":[[0,4.7,41.08],[1,1.01,0.51],[2,1.01,0]],"ltp":5.1,"tv":12.0,"id":13117503},{"batb":[[0,1.01,0.51],[1,1.98,0],[2,1.01,0]],"ltp":2.92,"tv":276.24,"id":13117454},{"batb":[[0,1.01,0.51],[1,8.6,0],[2,1.01,0]],"ltp":3.8,"tv":32.93,"id":13117502}]}]}
{"op":"mcm","clk":"1001494766","pt":1580636989490,"mc":[{"id":"1.168215938","rc":[{"batb":[[0,4.7,58.21],[1,4.6,38.59],[2,1.01,0.51]],"ltp":5.1,"tv":12.0,"id":13117503},{"batb":[[0,1.91,67.28],[1,1.89,79.38],[2,1.01,0.51]],"ltp":2.92,"tv":276.24,"id":13117454},{"batb":[[0,7.2,37.74],[1,7,30.22],[2,1.01,0.51]],"ltp":3.8,"tv":32.93,"id":13117502}]}]}
{"op":"mcm","clk":"1001494797","pt":1580636990060,"mc":[{"id":"1.168215938","rc":[{"batb":[[1,1.01,0.51],[2,1.01,0]],"ltp":5.0,"tv":105.34,"id":13117455},{"batb":[[0,4.7,41.08],[1,1.01,0.51],[2,1.01,0]],"ltp":5.1,"tv":12.0,"id":13117503},{"batb":[[0,1.01,0.51],[1,7,0],[2,1.01,0]],"ltp":3.8,"tv":32.93,"id":13117502}]}]}
{"op":"mcm","clk":"1001495029","pt":1580636993904,"mc":[{"id":"1.168215938","rc":[{"batb":[[0,4.8,27.07],[1,4.7,37.01],[2,4.5,11.76]],"batl":[[0,5.3,9.24]],"ltp":5.0,"tv":105.34,"id":13117455},{"batb":[[0,4.8,44.2],[1,4.7,41.08],[2,4.3,12.6]],"batl":[[0,5,10.08],[1,5.1,5.72]],"ltp":5.1,"tv":12.0,"id":13117503},{"batb":[[0,1.93,44.53],[1,1.91,67.28],[2,1.89,79.38]],"batl":[[0,2.12,36.97]],"ltp":2.92,"tv":276.24,"id":13117454},{"batb":[[0,11,11.47],[1,10.5,35.84],[2,1.01,0.51]],"ltp":3.8,"tv":32.93,"id":13117502}]}]}
{"op":"mcm","clk":"1001495792","pt":1580637004319,"mc":[{"id":"1.168215938","rc":[{"batb":[[0,4.7,37.01],[1,4.5,11.76],[2,1.01,0.51]],"ltp":5.0,"tv":105.34,"id":13117455},{"batb":[[0,4.7,41.08],[1,4.3,12.6],[2,1.01,0.51]],"ltp":5.1,"tv":12.0,"id":13117503},{"batb":[[1,1.01,0.51],[2,1.89,0]],"ltp":2.92,"tv":276.24,"id":13117454},{"batb":[[0,10.5,4.2],[1,1.01,0.51],[2,1.01,0]],"ltp":3.8,"tv":32.93,"id":13117502}]}]}
{"op":"mcm","clk":"1001495856","pt":1580637005454,"mc":[{"id":"1.168215938","rc":[{"batb":[[1,1.01,0.51],[2,1.01,0]],"ltp":5.0,"tv":105.34,"id":13117455},{"batb":[[1,1.01,0.51],[2,1.01,0]],"batl":[[0,5.1,5.72],[1,5.1,0]],"ltp":5.1,"tv":12.0,"id":13117503},{"batb":[[0,1.01,0.51],[1,1.01,0]],"ltp":2.92,"tv":276.24,"id":13117454},{"batb":[[0,1.01,0.51],[1,1.01,0]],"ltp":3.8,"tv":32.93,"id":13117502}]}]}
{"op":"mcm","clk":"1001495975","pt":1580637007313,"mc":[{"id":"1.168215938","rc":[{"batb":[[0,4.7,50.62],[1,4.6,38.31],[2,1.01,0.51]],"ltp":5.0,"tv":105.34,"id":13117455},{"batb":[[0,4.7,55.65],[1,4.6,38.6],[2,1.01,0.51]],"ltp":5.1,"tv":12.0,"id":13117503},{"batb":[[0,1.87,88.27],[1,1.85,85],[2,1.01,0.51]],"ltp":2.92,"tv":276.24,"id":13117454},{"batb":[[0,9.4,14.95],[1,9.2,17.14],[2,1.01,0.51]],"ltp":3.8,"tv":32.93,"id":13117502}]}]}
{"op":"mcm","clk":"1001496411","pt":1580637014646,"mc":[{"id":"1.168215938","rc":[{"batb":[[0,4.7,37.01],[1,1.01,0.51],[2,1.01,0]],"ltp":5.0,"tv":105.34,"id":13117455},{"batb":[[0,1.01,0.51],[1,4.6,0],[2,1.01,0]],"ltp":5.1,"tv":12.0,"id":13117503},{"batb":[[0,1.01,0.51],[1,9.2,0],[2,1.01,0]],"ltp":3.8,"tv":32.93,"id":13117502}]}]}
{"op":"mcm","clk":"1001496629","pt":1580637017958,"mc":[{"id":"1.168215938","rc":[{"batb":[[0,4.8,34.31],[1,4.7,37.01],[2,4.5,11.76]],"batl":[[0,5.3,9.24]],"ltp":5.0,"tv":105.34,"id":13117455},{"batb":[[0,4.9,21.68],[1,4.8,35.53],[2,4.3,12.6]],"batl":[[0,5.1,15.81]],"ltp":5.1,"tv":12.0,"id":13117503},{"batb":[[0,1.89,47.05],[1,1.87,88.27],[2,1.85,85]],"batl":[[0,2.08,38.65]],"ltp":2.92,"tv":276.24,"id":13117454},{"batb":[[0,12,11.57],[1,11.5,29.54],[2,1.01,0.51]],"ltp":3.8,"tv":32.93,"id":13117502}]}]}
{"op":"mcm","clk":"1001497961","pt":1580637041174,"mc":[{"id":"1.168215938","rc":[{"batb":[[0,4.8,21.46],[2,1.01,0.51]],"ltp":5.0,"tv":105.34,"id":13117455},{"batb":[[0,4.8,35.53],[1,1.01,0.51],[2,4.3,0]],"batl":[[0,5.1,5.72]],"ltp":5.1,"tv":12.0,"id":13117503},{"batb":[[0,1.01,0.51],[1,1.87,0],[2,1.85,0]],"ltp":2.92,"tv":276.24,"id":13117454},{"batb":[[0,1.01,0.51],[1,11.5,0],[2,1.01,0]],"ltp":3.8,"tv":32.93,"id":13117502}]}]}
{"op":"mcm","clk":"1001498157","pt":1580637044080,"mc":[{"id":"1.168215938","rc":[{"batb":[[1,4.7,37.01],[2,1.01,0.51]],"ltp":5.1,"tv":12.0,"id":13117503},{"batb":[[0,1.8,90.85],[1,1.78,96.41],[2,1.01,0.51]],"ltp":2.92,"tv":276.24,"id":13117454},{"batb":[[0,10.5,40.65],[1,10,24.65],[2,1.01,0.51]],"ltp":3.8,"tv":32.93,"id":13117502}]}]}
{"op":"mcm","clk":"1001498255","pt":1580637045783,"mc":[{"id":"1.168215938","rc":[{"batb":[[1,1.01,0.51],[2,1.01,0]],"ltp":5.0,"tv":105.34,"id":13117455},{"batb":[[0,1.01,0.51],[1,4.7,0],[2,1.01,0]],"ltp":5.1,"tv":12.0,"id":13117503},{"batb":[[0,1.01,0.51],[1,10,0],[2,1.01,0]],"ltp":3.8,"tv":32.93,"id":13117502}]}]}
{"op":"mcm","clk":"1001498446","pt":1580637048774,"mc":[{"id":"1.168215938","rc":[{"batb":[[0,4.9,21.31],[1,4.8,35.17],[2,1.01,0.51]],"ltp":5.0,"tv":105.34,"id":13117455},{"batb":[[0,5,20.38],[1,4.9,33.92],[2,1.01,0.51]],"ltp":5.1,"tv":12.0,"id":13117503},{"batb":[[0,14.5,13.84],[1,14,17.41],[2,1.01,0.51]],"ltp":3.8,"tv":32.93,"id":13117502}]}]}
{"op":"mcm","clk":"1001498537","pt":1580637049963,"mc":[{"id":"1.168215938","rc":[{"batb":[[2,4.5,11.76]],"batl":[[0,5.3,9.24]],"ltp":5.0,"tv":105.34,"id":13117455},{"batb":[[2,4.5,11.76]],"batl":[[1,5.3,9.24]],"ltp":5.1,"tv":12.0,"id":13117503},{"batb":[[0,1.83,50.41],[1,1.8,90.85],[2,1.78,96.41]],"batl":[[0,2,42.01]],"ltp":2.92,"tv":276.24,"id":13117454},{"batb":[[2,13,3.36]],"ltp":3.8,"tv":32.93,"id":13117502}]}]}
{"op":"mcm","clk":"1001498998","pt":1580637057813,"mc":[{"id":"1.168215938","rc":[{"batb":[[0,4.8,35.17],[1,4.5,11.76],[2,1.01,0.51]],"ltp":5.0,"tv":105.34,"id":13117455},{"batb":[[0,4.9,33.92],[1,4.5,11.76],[2,1.01,0.51]],"ltp":5.1,"tv":12.0,"id":13117503},{"batb":[[1,1.01,0.51],[2,1.78,0]],"ltp":2.92,"tv":276.24,"id":13117454},{"batb":[[0,13,3.36],[1,1.01,0.51],[2,13,0]],"ltp":3.8,"tv":32.93,"id":13117502}]}]}
{"op":"mcm","clk":"1001499053","pt":1580637059000,"mc":[{"id":"1.168215938","rc":[{"batb":[[1,1.01,0.51],[2,1.01,0]],"ltp":5.0,"tv":105.34,"id":13117455},{"batb":[[1,1.01,0.51],[2,1.01,0]],"batl":[[1,5.3,0]],"ltp":5.1,"tv":12.0,"id":13117503},{"batb":[[0,1.01,0.51],[1,1.01,0]],"ltp":2.92,"tv":276.24,"id":13117454},{"batb":[[0,1.01,0.51],[1,1.01,0]],"ltp":3.8,"tv":32.93,"id":13117502}]}]}
{"op":"mcm","clk":"1001499126","pt":1580637060798,"mc":[{"id":"1.168215938","rc":[{"batb":[[1,4.7,36.6],[2,1.01,0.51]],"ltp":5.0,"tv":105.34,"id":13117455},{"batb":[[1,4.8,35.32],[2,1.01,0.51]],"ltp":5.1,"tv":12.0,"id":13117503},{"batb":[[0,1.72,103.48],[1,1.7,112.71],[2,1.01,0.51]],"ltp":2.92,"tv":276.24,"id":13117454},{"batb":[[0,12.5,13.5],[1,12,23.99],[2,1.01,0.51]],"ltp":3.8,"tv":32.93,"id":13117502}]}]}
{"op":"mcm","clk":"1001499270","pt":1580637063112,"mc":[{"id":"1.168215938","rc":[{"batb":[[1,1.01,0.51],[2,1.01,0]],"ltp":5.0,"tv":105.34,"id":13117455},{"batb":[[1,1.01,0.51],[2,1.01,0]],"ltp":5.1,"tv":12.0,"id":13117503},{"batb":[[0,1.01,0.51],[1,1.7,0],[2,1.01,0]],"ltp":2.92,"tv":276.24,"id":13117454},{"batb":[[0,1.01,0.51],[1,12,0],[2,1.01,0]],"ltp":3.8,"tv":32.93,"id":13117502}]}]}
{"op":"mcm","clk":"1001499449","pt":1580637066095,"mc":[{"id":"1.168215938","rc":[{"batb":[[0,4.9,26.82],[1,4.8,35.17],[2,1.01,0.51]],"ltp":5.0,"tv":105.34,"id":13117455},{"batb":[[0,5,27.06],[1,4.9,33.92],[2,1.01,0.51]],"ltp":5.1,"tv":12.0,"id":13117503},{"batb":[[0,1.79,61.29],[1,1.77,98.16],[2,1.01,0.51]],"ltp":2.92,"tv":276.24,"id":13117454},{"batb":[[0,15.5,8.58],[1,15,15.25],[2,1.01,0.51]],"ltp":3.8,"tv":32.93,"id":13117502}]}]}
{"op":"mcm","clk":"1001499484","pt":1580637067119,"mc":[{"id":"1.168215938","rc":[{"batb":[[0,4.8,35.17],[1,1.01,0.51],[2,1.01,0]],"ltp":5.0,"tv":105.34,"id":13117455},{"batb":[[0,4.9,33.92],[1,1.01,0.51],[2,1.01,0]],"ltp":5.1,"tv":12.0,"id":13117503},{"batb":[[0,1.01,0.51],[1,1.77,0],[2,1.01,0]],"ltp":2.92,"tv":276.24,"id":13117454},{"batb":[[0,1.01,0.51],[1,15,0],[2,1.01,0]],"ltp":3.8,"tv":32.93,"id":13117502}]}]}
{"op":"mcm","clk":"1001499642","pt":1580637070823,"mc":[{"id":"1.168215938","rc":[{"batb":[[1,4.7,36.6],[2,1.01,0.51]],"ltp":5.0,"tv":105.34,"id":13117455},{"batb":[[1,4.8,35.32],[2,1.01,0.51]],"ltp":5.1,"tv":12.0,"id":13117503},{"batb":[[0,1.72,103.48],[1,1.7,112.71],[2,1.01,0.51]],"ltp":2.92,"tv":276.24,"id":13117454},{"batb":[[0,12.5,13.5],[1,12,23.99],[2,1.01,0.51]],"ltp":3.8,"tv":32.93,"id":13117502}]}]}
{"op":"mcm","clk":"1001499911","pt":1580637075914,"mc":[{"id":"1.168215938","rc":[{"batb":[[1,1.01,0.51],[2,1.01,0]],"ltp":5.0,"tv":105.34,"id":13117455},{"batb":[[0,1.01,0.51],[1,4.8,0],[2,1.01,0]],"ltp":5.1,"tv":12.0,"id":13117503},{"batb":[[0,1.01,0.51],[1,12,0],[2,1.01,0]],"ltp":3.8,"tv":32.93,"id":13117502}]}]}
{"op":"mcm","clk":"1001500061","pt":1580637078897,"mc":[{"id":"1.168215938","rc":[{"batb":[[0,4.9,49.01],[1,4.8,35.17],[2,1.01,0.51]],"ltp":5.0,"tv":105.34,"id":13117455},{"trd":[[5.1,23.46]],"batb":[[0,5.1,15.25],[1,5,32.37],[2,1.01,0.51]],"ltp":5.1,"tv":23.45,"id":13117503},{"batb":[[0,20,11.33],[1,19.5,8.82],[2,1.01,0.51]],"ltp":3.8,"tv":32.93,"id":13117502}],"tv":437.97}]}
{"op":"mcm","clk":"1001500106","pt":1580637080215,"mc":[{"id":"1.168215938","rc":[{"batb":[[2,4.5,11.76]],"batl":[[0,5.3,9.24]],"ltp":5.0,"tv":105.34,"id":13117455},{"batb":[[2,4.6,10.92]],"batl":[[0,5.3,9.24]],"ltp":5.1,"tv":23.45,"id":13117503},{"batb":[[0,1.77,53.77],[1,1.72,103.48],[2,1.7,112.71]],"batl":[[0,1.93,42.01]],"ltp":2.92,"tv":276.24,"id":13117454}]}]}
{"op":"mcm","clk":"1001500922","pt":1580637097370,"mc":[{"id":"1.168215938","rc":[{"batb":[[0,4.9,30.13]],"ltp":5.0,"tv":105.34,"id":13117455},{"batb":[[0,5,32.37],[1,4.6,10.92],[2,1.01,0.51]],"ltp":5.1,"tv":23.45,"id":13117503},{"batb":[[1,1.01,0.51],[2,1.7,0]],"ltp":2.92,"tv":276.24,"id":13117454},{"batb":[[0,1.01,0.51],[1,19.5,0],[2,1.01,0]],"ltp":3.8,"tv":32.93,"id":13117502}]}]}
{"op":"mcm","clk":"1001501025","pt":1580637099634,"mc":[{"id":"1.168215938","rc":[{"batb":[[2,1.01,0.51]],"ltp":5.0,"tv":105.34,"id":13117455},{"batb":[[1,1.01,0.51],[2,1.01,0]],"ltp":5.1,"tv":23.45,"id":13117503},{"batb":[[0,1.01,0.51],[1,1.01,0]],"ltp":2.92,"tv":276.24,"id":13117454}]}]}
{"op":"mcm","clk":"1001501052","pt":1580637100361,"mc":[{"id":"1.168215938","rc":[{"batb":[[1,4.9,33.73],[2,1.01,0.51]],"ltp":5.1,"tv":23.45,"id":13117503},{"batb":[[0,1.65,63.35],[1,1.64,64.23],[2,1.01,0.51]],"ltp":2.92,"tv":276.24,"id":13117454},{"batb":[[0,16,12.67],[1,15.5,14.13],[2,1.01,0.51]],"ltp":3.8,"tv":32.93,"id":13117502}]}]}
{"op":"mcm","clk":"1001502017","pt":1580637118672,"mc":[{"id":"1.168215938","rc":[{"batb":[[0,1.01,0.51],[1,1.64,0],[2,1.01,0]],"ltp":2.92,"tv":276.24,"id":13117454}]}]}
{"op":"mcm","clk":"1001502153","pt":1580637121596,"mc":[{"id":"1.168215938","rc":[{"batb":[[0,1.78,58.57],[1,1.76,100.02],[2,1.01,0.51]],"ltp":2.92,"tv":276.24,"id":13117454}]}]}
{"op":"mcm","clk":"1001502202","pt":1580637122422,"mc":[{"id":"1.168215938","rc":[{"batb":[[2,4.5,11.76]],"batl":[[0,5.3,9.24]],"ltp":5.0,"tv":105.34,"id":13117455},{"batb":[[2,4.5,11.76]],"batl":[[0,5.3,9.24]],"ltp":5.1,"tv":23.45,"id":13117503},{"batb":[[0,1.8,52.09],[1,1.78,58.57],[2,1.76,100.02]],"batl":[[0,1.97,42.01]],"ltp":2.92,"tv":276.24,"id":13117454}]}]}
{"op":"mcm","clk":"1001503307","pt":1580637142149,"mc":[{"id":"1.168215938","rc":[{"batb":[[0,4.8,35.17],[1,4.5,11.76],[2,1.01,0.51]],"ltp":5.0,"tv":105.34,"id":13117455},{"batb":[[0,4.9,33.73],[1,4.5,11.76],[2,1.01,0.51]],"ltp":5.1,"tv":23.45,"id":13117503},{"batb":[[1,1.01,0.51],[2,1.76,0]],"ltp":2.92,"tv":276.24,"id":13117454},{"batb":[[0,1.01,0.51],[1,15.5,0],[2,1.01,0]],"ltp":3.8,"tv":32.93,"id":13117502}]}]}
{"op":"mcm","clk":"1001503378","pt":1580637143151,"mc":[{"id":"1.168215938","rc":[{"batb":[[1,1.01,0.51],[2,1.01,0]],"ltp":5.0,"tv":105.34,"id":13117455},{"batb":[[1,1.01,0.51],[2,1.01,0]],"ltp":5.1,"tv":23.45,"id":13117503},{"batb":[[0,1.01,0.51],[1,1.01,0]],"ltp":2.92,"tv":276.24,"id":13117454}]}]}
{"op":"mcm","clk":"1001503667","pt":1580637147517,"mc":[{"id":"1.168215938","rc":[{"batb":[[0,4.9,36.53],[1,4.8,35.17],[2,1.01,0.51]],"ltp":5.0,"tv":105.34,"id":13117455},{"batb":[[0,5,37.24],[1,4.9,33.73],[2,1.01,0.51]],"ltp":5.1,"tv":23.45,"id":13117503},{"batb":[[0,1.76,63.56],[1,1.74,103.95],[2,1.01,0.51]],"ltp":2.92,"tv":276.24,"id":13117454},{"batb":[[0,17.5,7.91],[1,17,11.81],[2,1.01,0.51]],"ltp":3.8,"tv":32.93,"id":13117502}]}]}
{"op":"mcm","clk":"1001503796","pt":1580637149734,"mc":[{"id":"1.168215938","rc":[{"batb":[[0,4.8,35.17],[1,1.01,0.51],[2,1.01,0]],"ltp":5.0,"tv":105.34,"id":13117455},{"batb":[[0,4.9,33.73],[1,1.01,0.51],[2,1.01,0]],"ltp":5.1,"tv":23.45,"id":13117503},{"batb":[[0,1.01,0.51],[1,1.74,0],[2,1.01,0]],"ltp":2.92,"tv":276.24,"id":13117454},{"batb":[[0,1.01,0.51],[1,17,0],[2,1.01,0]],"ltp":3.8,"tv":32.93,"id":13117502}]}]}
{"op":"mcm","clk":"1001503946","pt":1580637152741,"mc":[{"id":"1.168215938","rc":[{"batb":[[0,4.8,46.57],[1,4.7,36.5],[2,1.01,0.51]],"ltp":5.0,"tv":105.34,"id":13117455},{"batb":[[0,4.9,45.08],[1,4.8,35.14],[2,1.01,0.51]],"ltp":5.1,"tv":23.45,"id":13117503},{"batb":[[0,1.68,111.26],[1,1.66,122.54],[2,1.01,0.51]],"ltp":2.92,"tv":276.24,"id":13117454},{"batb":[[0,13,14.92],[1,12.5,21.98],[2,1.01,0.51]],"ltp":3.8,"tv":32.93,"id":13117502}]}]}
{"op":"mcm","clk":"1001504123","pt":1580637155838,"mc":[{"id":"1.168215938","rc":[{"batb":[[0,1.01,0.51],[1,4.7,0],[2,1.01,0]],"ltp":5.0,"tv":105.34,"id":13117455},{"batb":[[0,1.01,0.51],[1,4.8,0],[2,1.01,0]],"ltp":5.1,"tv":23.45,"id":13117503},{"batb":[[0,1.01,0.51],[1,12.5,0],[2,1.01,0]],"ltp":3.8,"tv":32.93,"id":13117502}]}]}
{"op":"mcm","clk":"1001504307","pt":1580637158833,"mc":[{"id":"1.168215938","rc":[{"batb":[[0,5,28.17],[1,4.9,33.43],[2,1.01,0.51]],"ltp":5.0,"tv":105.34,"id":13117455},{"batb":[[0,5.1,30.67],[1,5,32.19],[2,1.01,0.51]],"ltp":5.1,"tv":23.45,"id":13117503},{"batb":[[0,26,8.61],[1,25,10.45],[2,1.01,0.51]],"ltp":3.8,"tv":32.93,"id":13117502}]}]}
{"op":"mcm","clk":"1001504392","pt":1580637160571,"mc":[{"id":"1.168215938","rc":[{"batb":[[2,4.5,11.76]],"batl":[[0,5.3,9.24]],"ltp":5.0,"tv":105.34,"id":13117455},{"batb":[[2,4.6,10.92]],"batl":[[0,5.4,9.24]],"ltp":5.1,"tv":23.45,"id":13117503},{"batb":[[0,1.73,57.13],[1,1.68,111.26],[2,1.66,122.54]],"batl":[[0,1.88,42.01]],"ltp":2.92,"tv":276.24,"id":13117454}]}]}
{"op":"mcm","clk":"1001505135","pt":1580637173961,"mc":[{"id":"1.168215938","rc":[{"batb":[[1,1.68,76.97]],"ltp":2.92,"tv":276.24,"id":13117454}]}]}
{"op":"mcm","clk":"1001505350","pt":1580637176858,"mc":[{"id":"1.168215938","rc":[{"batb":[[0,5.1,51.02]],"ltp":5.1,"tv":23.45,"id":13117503},{"batb":[[0,26,11.98]],"ltp":3.8,"tv":32.93,"id":13117502}]}]}
{"op":"mcm","clk":"1001505389","pt":1580637177269,"mc":[{"id":"1.168215938","rc":[{"batl":[[0,1.86,135.25],[1,1.88,42.01]],"ltp":2.92,"tv":276.24,"id":13117454}]}]}
{"op":"mcm","clk":"1001505603","pt":1580637180873,"mc":[{"id":"1.168215938","rc":[{"batl":[[0,490,5.17]],"ltp":3.8,"tv":32.93,"id":13117502}]}]}
{"op":"mcm","clk":"1001505622","pt":1580637181174,"mc":[{"id":"1.168215938","rc":[{"batb":[[0,4.9,33.43],[1,1.01,0.51],[2,4.5,0]],"ltp":5.0,"tv":105.34,"id":13117455},{"batb":[[0,5.1,30.67],[2,1.01,0.51]],"ltp":5.1,"tv":23.45,"id":13117503},{"batb":[[0,1.01,0.51],[1,1.68,0],[2,1.66,0]],"ltp":2.92,"tv":276.24,"id":13117454},{"batb":[[0,1.01,0.51],[1,25,0],[2,1.01,0]],"ltp":3.8,"tv":32.93,"id":13117502}]}]}
{"op":"mcm","clk":"1001505793","pt":1580637184071,"mc":[{"id":"1.168215938","rc":[{"batb":[[1,4.8,34.85],[2,1.01,0.51]],"ltp":5.0,"tv":105.34,"id":13117455},{"batb":[[0,1.6,67.15],[1,1.59,72.02],[2,1.01,0.51]],"ltp":2.92,"tv":276.24,"id":13117454},{"batb":[[0,19,13.66],[1,18.5,9.91],[2,1.01,0.51]],"ltp":3.8,"tv":32.93,"id":13117502}]}]}
{"op":"mcm","clk":"1001505875","pt":1580637185465,"mc":[{"id":"1.168215938","rc":[{"batb":[[1,1.01,0.51],[2,1.01,0]],"ltp":5.0,"tv":105.34,"id":13117455},{"batb":[[1,1.01,0.51],[2,1.01,0]],"ltp":5.1,"tv":23.45,"id":13117503},{"batb":[[0,1.01,0.51],[1,1.59,0],[2,1.01,0]],"ltp":2.92,"tv":276.24,"id":13117454},{"batb":[[0,1.01,0.51],[1,18.5,0],[2,1.01,0]],"ltp":3.8,"tv":32.93,"id":13117502}]}]}
{"op":"mcm","clk":"1001506028","pt":1580637188500,"mc":[{"id":"1.168215938","rc":[{"batb":[[0,5,29.34],[1,4.9,33.43],[2,1.01,0.51]],"ltp":5.0,"tv":105.34,"id":13117455},{"batb":[[0,5.2,26.82],[1,5.1,30.67],[2,1.01,0.51]],"ltp":5.1,"tv":23.45,"id":13117503},{"batb":[[0,1.66,95.16],[1,1.65,63.02],[2,1.01,0.51]],"ltp":2.92,"tv":276.24,"id":13117454},{"batb":[[0,30,8.13],[1,29,7.85],[2,1.01,0.51]],"ltp":3.8,"tv":32.93,"id":13117502}]}]}
{"op":"mcm","clk":"1001506426","pt":1580637195331,"mc":[{"id":"1.168215938","rc":[{"batb":[[0,4.9,33.43],[1,1.01,0.51],[2,1.01,0]],"ltp":5.0,"tv":105.34,"id":13117455},{"batb":[[0,5.1,30.67],[1,1.01,0.51],[2,1.01,0]],"ltp":5.1,"tv":23.45,"id":13117503},{"batb":[[0,1.01,0.51],[1,1.65,0],[2,1.01,0]],"ltp":2.92,"tv":276.24,"id":13117454},{"batb":[[0,1.01,0.51],[1,29,0],[2,1.01,0]],"ltp":3.8,"tv":32.93,"id":13117502}]}]}
{"op":"mcm","clk":"1001506588","pt":1580637198329,"mc":[{"id":"1.168215938","rc":[{"batb":[[1,4.8,34.85],[2,1.01,0.51]],"ltp":5.0,"tv":105.34,"id":13117455},{"batb":[[1,5,32.58],[2,1.01,0.51]],"ltp":5.1,"tv":23.45,"id":13117503},{"batb":[[0,1.6,67.15],[1,1.59,72.02],[2,1.01,0.51]],"ltp":2.92,"tv":276.24,"id":13117454},{"batb":[[0,19,13.66],[1,18.5,9.91],[2,1.01,0.51]],"ltp":3.8,"tv":32.93,"id":13117502}]}]}
{"op":"mcm","clk":"1001506824","pt":1580637202875,"mc":[{"id":"1.168215938","rc":[{"batb":[[0,1.01,0.51],[1,4.8,0],[2,1.01,0]],"ltp":5.0,"tv":105.34,"id":13117455},{"batb":[[0,1.01,0.51],[1,5,0],[2,1.01,0]],"ltp":5.1,"tv":23.45,"id":13117503},{"batb":[[0,1.01,0.51],[1,18.5,0],[2,1.01,0]],"ltp":3.8,"tv":32.93,"id":13117502}]}]}
{"op":"mcm","clk":"1001506966","pt":1580637205876,"mc":[{"id":"1.168215938","rc":[{"batb":[[0,5.1,25.27],[1,5,31.85],[2,1.01,0.51]],"ltp":5.0,"tv":105.34,"id":13117455},{"batb":[[0,5.3,26.07],[1,5.2,29.8],[2,1.01,0.51]],"ltp":5.1,"tv":23.45,"id":13117503}]}]}
{"op":"mcm","clk":"1001506989","pt":1580637206341,"mc":[{"id":"1.168215938","rc":[{"batb":[[2,4.5,11.76]],"batl":[[0,5.3,9.24]],"ltp":5.0,"tv":105.34,"id":13117455},{"batb":[[2,4.8,10.92]],"batl":[[0,5.8,8.4]],"ltp":5.1,"tv":23.45,"id":13117503},{"batb":[[0,1.62,67.22],[1,1.6,67.15],[2,1.59,72.02]],"batl":[[0,1.75,42.01]],"ltp":2.92,"tv":276.24,"id":13117454}]}]}
{"op":"mcm","clk":"1001510727","pt":1580637279524,"mc":[{"id":"1.168215938","rc":[{"batb":[[0,70,2.03],[1,65,7.5],[2,1.01,0.51]],"ltp":3.8,"tv":32.93,"id":13117502}]}]}
{"op":"mcm","clk":"1001510891","pt":1580637282853,"mc":[{"id":"1.168215938","rc":[{"batl":[[0,580,4.28]],"ltp":3.8,"tv":32.93,"id":13117502}]}]}
{"op":"mcm","clk":"1001511257","pt":1580637289459,"mc":[{"id":"1.168215938","rc":[{"batb":[[0,5,31.85],[1,1.01,0.51],[2,4.5,0]],"ltp":5.0,"tv":105.34,"id":13117455},{"batb":[[0,1.01,0.51],[1,5.2,0],[2,4.8,0]],"ltp":5.1,"tv":23.45,"id":13117503},{"batb":[[0,1.01,0.51],[1,1.6,0],[2,1.59,0]],"ltp":2.92,"tv":276.24,"id":13117454},{"batb":[[0,1.01,0.51],[1,65,0],[2,1.01,0]],"ltp":3.8,"tv":32.93,"id":13117502}]}]}
{"op":"mcm","clk":"1001511417","pt":1580637292954,"mc":[{"id":"1.168215938","rc":[{"batb":[[1,4.9,33.25],[2,1.01,0.51]],"ltp":5.0,"tv":105.34,"id":13117455},{"batb":[[0,5.1,43.19],[1,5,32.32],[2,1.01,0.51]],"ltp":5.1,"tv":23.45,"id":13117503},{"batb":[[0,1.57,133.03],[1,1.56,77.69],[2,1.01,0.51]],"ltp":2.92,"tv":276.24,"id":13117454},{"batb":[[0,42,7.47],[1,40,8.12],[2,1.01,0.51]],"ltp":3.8,"tv":32.93,"id":13117502}]}]}
{"op":"mcm","clk":"1001511955","pt":1580637302787,"mc":[{"id":"1.168215938","rc":[{"batb":[[0,1.01,0.51],[1,1.56,0],[2,1.01,0]],"ltp":2.92,"tv":276.24,"id":13117454}]}]}
{"op":"mcm","clk":"1001512091","pt":1580637305776,"mc":[{"id":"1.168215938","rc":[{"batb":[[0,1.64,91.07],[1,1.63,65.87],[2,1.01,0.51]],"ltp":2.92,"tv":276.24,"id":13117454}]}]}
{"op":"mcm","clk":"1001512142","pt":1580637306806,"mc":[{"id":"1.168215938","rc":[{"batb":[[2,4.5,11.76]],"batl":[[0,5.3,9.24]],"ltp":5.0,"tv":105.34,"id":13117455},{"batb":[[2,4.7,10.92]],"batl":[[0,5.6,8.4]],"ltp":5.1,"tv":23.45,"id":13117503},{"batb":[[0,1.66,63.01],[1,1.64,91.07],[2,1.63,65.87]],"batl":[[0,1.79,42.01]],"ltp":2.92,"tv":276.24,"id":13117454}]}]}
{"op":"mcm","clk":"1001512808","pt":1580637317909,"mc":[{"id":"1.168215938","rc":[{"batb":[[0,4.9,33.25],[1,4.5,11.76],[2,1.01,0.51]],"ltp":5.0,"tv":105.34,"id":13117455},{"batb":[[0,5,32.32],[1,4.7,10.92],[2,1.01,0.51]],"ltp":5.1,"tv":23.45,"id":13117503},{"batb":[[1,1.01,0.51],[2,1.63,0]],"ltp":2.92,"tv":276.24,"id":13117454},{"batb":[[0,1.01,0.51],[1,40,0],[2,1.01,0]],"ltp":3.8,"tv":32.93,"id":13117502}]}]}
{"op":"mcm","clk":"1001512873","pt":1580637319410,"mc":[{"id":"1.168215938","rc":[{"batb":[[1,1.01,0.51],[2,1.01,0]],"ltp":5.0,"tv":105.34,"id":13117455},{"batb":[[1,1.01,0.51],[2,1.01,0]],"ltp":5.1,"tv":23.45,"id":13117503},{"batb":[[0,1.01,0.51],[1,1.01,0]],"ltp":2.92,"tv":276.24,"id":13117454}]}]}
{"op":"mcm","clk":"1001512934","pt":1580637320804,"mc":[{"id":"1.168215938","rc":[{"batb":[[1,4.8,34.78],[2,1.01,0.51]],"ltp":5.0,"tv":105.34,"id":13117455},{"batb":[[1,4.9,34.03],[2,1.01,0.51]],"ltp":5.1,"tv":23.45,"id":13117503},{"batb":[[0,1.61,105.16],[1,1.6,70.54],[2,1.01,0.51]],"ltp":2.92,"tv":276.24,"id":13117454},{"batb":[[0,26,13.18],[1,25,10.64],[2,1.01,0.51]],"ltp":3.8,"tv":32.93,"id":13117502}]}]}
{"op":"mcm","clk":"1001512961","pt":1580637321402,"mc":[{"id":"1.168215938","rc":[{"batb":[[1,1.01,0.51],[2,1.01,0]],"ltp":5.0,"tv":105.34,"id":13117455},{"batb":[[0,1.01,0.51],[1,4.9,0],[2,1.01,0]],"ltp":5.1,"tv":23.45,"id":13117503},{"batb":[[0,1.01,0.51],[1,25,0],[2,1.01,0]],"ltp":3.8,"tv":32.93,"id":13117502}]}]}
{"op":"mcm","clk":"1001513104","pt":1580637324517,"mc":[{"id":"1.168215938","rc":[{"batb":[[0,5,45.22],[1,4.9,33.25],[2,4.5,11.76]],"batl":[[0,5.3,9.24]],"ltp":5.0,"tv":105.34,"id":13117455},{"batb":[[0,5.2,32.12],[1,5.1,31.06],[2,4.8,10.92]],"batl":[[0,5.7,8.4]],"ltp":5.1,"tv":23.45,"id":13117503},{"batb":[[0,1.63,66.38],[1,1.61,105.16],[2,1.6,70.54]],"batl":[[0,1.77,42.01]],"ltp":2.92,"tv":276.24,"id":13117454},{"batb":[[0,60,5.99],[1,55,5.7],[2,1.01,0.51]],"ltp":3.8,"tv":32.93,"id":13117502}]}]}
{"op":"mcm","clk":"1001513405","pt":1580637331020,"mc":[{"id":"1.168215938","rc":[{"batl":[[0,1.75,42.01]],"ltp":2.92,"tv":276.24,"id":13117454}]}]}
{"op":"mcm","clk":"1001513661","pt":1580637336339,"mc":[{"id":"1.168215938","rc":[{"batb":[[0,4.9,33.25],[1,4.5,11.76],[2,1.01,0.51]],"ltp":5.0,"tv":105.34,"id":13117455},{"batb":[[0,4.8,10.92],[1,1.01,0.51],[2,4.8,0]],"ltp":5.1,"tv":23.45,"id":13117503},{"batb":[[1,1.01,0.51],[2,1.6,0]],"ltp":2.92,"tv":276.24,"id":13117454},{"batb":[[0,1.01,0.51],[1,55,0],[2,1.01,0]],"ltp":3.8,"tv":32.93,"id":13117502}]}]}
{"op":"mcm","clk":"1001513759","pt":1580637337944,"mc":[{"id":"1.168215938","rc":[{"batb":[[1,1.01,0.51],[2,1.01,0]],"ltp":5.0,"tv":105.34,"id":13117455},{"batb":[[0,1.01,0.51],[1,1.01,0]],"ltp":5.1,"tv":23.45,"id":13117503},{"batb":[[0,1.01,0.51],[1,1.01,0]],"ltp":2.92,"tv":276.24,"id":13117454}]}]}
{"op":"mcm","clk":"1001513842","pt":1580637339937,"mc":[{"id":"1.168215938","rc":[{"batb":[[0,4.9,52.55],[1,4.8,34.54],[2,1.01,0.51]],"ltp":5.0,"tv":105.34,"id":13117455},{"batb":[[0,5,52.2],[1,4.9,33.72],[2,1.01,0.51]],"ltp":5.1,"tv":23.45,"id":13117503},{"batb":[[0,1.59,71.69],[1,1.58,73.76],[2,1.01,0.51]],"ltp":2.92,"tv":276.24,"id":13117454},{"batb":[[0,34,13.24],[1,32,6.97],[2,1.01,0.51]],"ltp":3.8,"tv":32.93,"id":13117502}]}]}
{"op":"mcm","clk":"1001514108","pt":1580637345036,"mc":[{"id":"1.168215938","rc":[{"batb":[[0,1.01,0.51],[1,4.8,0],[2,1.01,0]],"ltp":5.0,"tv":105.34,"id":13117455},{"batb":[[0,1.01,0.51],[1,4.9,0],[2,1.01,0]],"ltp":5.1,"tv":23.45,"id":13117503},{"batb":[[0,1.01,0.51],[1,32,0],[2,1.01,0]],"ltp":3.8,"tv":32.93,"id":13117502}]}]}
{"op":"mcm","clk":"1001514275","pt":1580637348644,"mc":[{"id":"1.168215938","rc":[{"batb":[[0,5.1,26.06],[1,5,31.83],[2,4.6,10.92]],"batl":[[0,5.3,9.24]],"ltp":5.0,"tv":105.34,"id":13117455},{"batb":[[0,5.3,23.5],[1,5.2,29.85],[2,4.9,10.08]],"batl":[[0,5.8,8.4]],"ltp":5.1,"tv":23.45,"id":13117503},{"batb":[[0,1.6,69.74],[1,1.59,71.69],[2,1.58,73.76]],"batl":[[0,1.73,42.01]],"ltp":2.92,"tv":276.24,"id":13117454},{"batb":[[0,95,3.57],[1,90,3.71],[2,1.01,0.51]],"ltp":3.8,"tv":32.93,"id":13117502}]}]}
{"op":"mcm","clk":"1001515256","pt":1580637368083,"mc":[{"id":"1.168215938","rc":[{"batl":[[0,1.72,42.01]],"ltp":2.92,"tv":276.24,"id":13117454}]}]}
{"op":"mcm","clk":"1001515935","pt":1580637379609,"mc":[{"id":"1.168215938","rc":[{"batb":[[0,5,31.83],[1,1.01,0.51],[2,4.6,0]],"ltp":5.0,"tv":105.34,"id":13117455},{"batb":[[0,1.01,0.51],[1,5.2,0],[2,4.9,0]],"ltp":5.1,"tv":23.45,"id":13117503},{"batb":[[0,1.01,0.51],[1,1.59,0],[2,1.58,0]],"ltp":2.92,"tv":276.24,"id":13117454},{"batb":[[0,1.01,0.51],[1,90,0],[2,1.01,0]],"ltp":3.8,"tv":32.93,"id":13117502}]}]}
{"op":"mcm","clk":"1001516059","pt":1580637382826,"mc":[{"id":"1.168215938","rc":[{"batb":[[1,4.9,33.24],[2,1.01,0.51]],"ltp":5.0,"tv":105.34,"id":13117455},{"batb":[[0,5.1,37.29],[1,5,32.41],[2,1.01,0.51]],"ltp":5.1,"tv":23.45,"id":13117503},{"batb":[[0,1.57,73.14],[1,1.56,77.39],[2,1.01,0.51]],"ltp":2.92,"tv":276.24,"id":13117454},{"batb":[[0,50,13.45],[1,1.01,0.51]],"ltp":3.8,"tv":32.93,"id":13117502}]}]}
{"op":"mcm","clk":"1001516375","pt":1580637388615,"mc":[{"id":"1.168215938","rc":[{"batb":[[1,1.01,0.51],[2,1.01,0]],"ltp":5.0,"tv":105.34,"id":13117455},{"batb":[[0,1.01,0.51],[1,5,0],[2,1.01,0]],"ltp":5.1,"tv":23.45,"id":13117503},{"batb":[[0,1.01,0.51],[1,1.01,0]],"ltp":3.8,"tv":32.93,"id":13117502}]}]}
{"op":"mcm","clk":"1001516665","pt":1580637391626,"mc":[{"id":"1.168215938","rc":[{"batb":[[0,5.1,38.61],[1,5,31.83],[2,1.01,0.51]],"ltp":5.0,"tv":105.34,"id":13117455},{"batb":[[0,5.3,46.37],[1,5.2,29.5],[2,1.01,0.51]],"ltp":5.1,"tv":23.45,"id":13117503}]}]}
{"op":"mcm","clk":"1001516780","pt":1580637392512,"mc":[{"id":"1.168215938","rc":[{"batb":[[2,4.6,10.92]],"batl":[[0,5.4,9.24]],"ltp":5.0,"tv":105.34,"id":13117455},{"batl":[[0,6,8.4]],"ltp":5.1,"tv":23.45,"id":13117503},{"batb":[[0,1.58,72.26],[1,1.57,73.14],[2,1.56,77.39]],"batl":[[0,1.7,42.01]],"ltp":2.92,"tv":276.24,"id":13117454}]}]}
{"op":"mcm","clk":"1001517031","pt":1580637394920,"mc":[{"id":"1.168215938","rc":[{"batb":[[2,5,10.08]],"ltp":5.1,"tv":23.45,"id":13117503}]}]}
{"op":"mcm","clk":"1001517656","pt":1580637403714,"mc":[{"id":"1.168215938","rc":[{"batb":[[0,5,31.83],[1,4.6,10.92],[2,1.01,0.51]],"ltp":5.0,"tv":105.34,"id":13117455},{"batb":[[0,5.2,29.5],[1,5,10.08],[2,1.01,0.51]],"ltp":5.1,"tv":23.45,"id":13117503},{"batb":[[1,1.01,0.51],[2,1.56,0]],"ltp":2.92,"tv":276.24,"id":13117454}]}]}
{"op":"mcm","clk":"1001517730","pt":1580637405359,"mc":[{"id":"1.168215938","rc":[{"batb":[[1,1.01,0.51],[2,1.01,0]],"ltp":5.0,"tv":105.34,"id":13117455},{"batb":[[1,1.01,0.51],[2,1.01,0]],"ltp":5.1,"tv":23.45,"id":13117503},{"batb":[[0,1.01,0.51],[1,1.01,0]],"ltp":2.92,"tv":276.24,"id":13117454}]}]}
{"op":"mcm","clk":"1001517798","pt":1580637406539,"mc":[{"id":"1.168215938","rc":[{"batb":[[0,5,46.72],[1,4.9,32.99],[2,1.01,0.51]],"ltp":5.0,"tv":105.34,"id":13117455},{"batb":[[1,5.1,31.15],[2,1.01,0.51]],"ltp":5.1,"tv":23.45,"id":13117503},{"batb":[[0,1.55,118.71],[1,1.54,81.56],[2,1.01,0.51]],"ltp":2.92,"tv":276.24,"id":13117454},{"batb":[[0,100,2.62],[1,95,3.56],[2,1.01,0.51]],"ltp":3.8,"tv":32.93,"id":13117502}]}]}
{"op":"mcm","clk":"1001517942","pt":1580637408745,"mc":[{"id":"1.168215938","rc":[{"batb":[[0,1.01,0.51],[1,4.9,0],[2,1.01,0]],"ltp":5.0,"tv":105.34,"id":13117455},{"batb":[[0,1.01,0.51],[1,5.1,0],[2,1.01,0]],"ltp":5.1,"tv":23.45,"id":13117503},{"batb":[[0,1.01,0.51],[1,95,0],[2,1.01,0]],"ltp":3.8,"tv":32.93,"id":13117502}]}]}
{"op":"mcm","clk":"1001518110","pt":1580637411673,"mc":[{"id":"1.168215938","rc":[{"batb":[[0,5.2,19.47],[1,5.1,30.52],[2,1.01,0.51]],"ltp":5.0,"tv":105.34,"id":13117455},{"batb":[[0,5.4,41.58],[1,5.3,28.32],[2,1.01,0.51]],"ltp":5.1,"tv":23.45,"id":13117503}]}]}
{"op":"mcm","clk":"1001518152","pt":1580637412241,"mc":[{"id":"1.168215938","rc":[{"batb":[[2,4.6,10.92]],"batl":[[0,5.4,9.24]],"ltp":5.0,"tv":105.34,"id":13117455},{"batb":[[2,5.1,10.08]],"batl":[[0,6.2,7.56]],"ltp":5.1,"tv":23.45,"id":13117503},{"batb":[[0,1.56,74.78],[1,1.55,118.71],[2,1.54,81.56]],"batl":[[0,1.68,42.01]],"ltp":2.92,"tv":276.24,"id":13117454}]}]}
{"op":"mcm","clk":"1001519205","pt":1580637423758,"mc":[{"id":"1.168215938","rc":[{"batb":[[0,5.1,30.52],[1,4.6,10.92],[2,1.01,0.51]],"ltp":5.0,"tv":105.34,"id":13117455}]}]}
{"op":"mcm","clk":"1001519426","pt":1580637426386,"mc":[{"id":"1.168215938","rc":[{"batb":[[0,5.1,50.22],[1,5,31.43],[2,4.6,10.92]],"ltp":5.0,"tv":105.34,"id":13117455}]}]}
{"op":"mcm","clk":"1001520280","pt":1580637439865,"mc":[{"id":"1.168215938","rc":[{"batb":[[0,5.1,30.52]],"ltp":5.0,"tv":105.34,"id":13117455},{"batb":[[0,5.3,28.32],[1,5.1,10.08],[2,1.01,0.51]],"ltp":5.1,"tv":23.45,"id":13117503},{"batb":[[1,1.01,0.51],[2,1.54,0]],"ltp":2.92,"tv":276.24,"id":13117454}]}]}
{"op":"mcm","clk":"1001520365","pt":1580637441269,"mc":[{"id":"1.168215938","rc":[{"batb":[[2,1.01,0.51]],"ltp":5.0,"tv":105.34,"id":13117455},{"batb":[[1,1.01,0.51],[2,1.01,0]],"ltp":5.1,"tv":23.45,"id":13117503},{"batb":[[0,1.01,0.51],[1,1.01,0]],"ltp":2.92,"tv":276.24,"id":13117454}]}]}
{"op":"mcm","clk":"1001520439","pt":1580637442499,"mc":[{"id":"1.168215938","rc":[{"batb":[[0,5.3,37.35],[1,5.2,29.64],[2,1.01,0.51]],"ltp":5.1,"tv":23.45,"id":13117503},{"batb":[[0,1.53,68.49],[1,1.52,85.6],[2,1.01,0.51]],"ltp":2.92,"tv":276.24,"id":13117454}]}]}
{"op":"mcm","clk":"1001520515","pt":1580637443479,"mc":[{"id":"1.168215938","rc":[{"batb":[[0,1.01,0.51],[1,1.52,0],[2,1.01,0]],"ltp":2.92,"tv":276.24,"id":13117454}]}]}
{"op":"mcm","clk":"1001520693","pt":1580637446487,"mc":[{"id":"1.168215938","rc":[{"batb":[[0,1.57,92.69],[1,1.56,77.48],[2,1.01,0.51]],"ltp":2.92,"tv":276.24,"id":13117454}]}]}
{"op":"mcm","clk":"1001520830","pt":1580637448299,"mc":[{"id":"1.168215938","rc":[{"batb":[[2,4.6,10.92]],"batl":[[0,5.4,9.24]],"ltp":5.0,"tv":105.34,"id":13117455},{"batb":[[2,5,10.08]],"batl":[[0,6,8.4]],"ltp":5.1,"tv":23.45,"id":13117503},{"batb":[[0,1.57,165.79]],"batl":[[0,1.69,42.01]],"ltp":2.92,"tv":276.24,"id":13117454}]}]}
{"op":"mcm","clk":"1001521611","pt":1580637458532,"mc":[{"id":"1.168215938","rc":[{"batb":[[0,5,31.43],[1,4.6,10.92],[2,1.01,0.51]],"ltp":5.0,"tv":105.34,"id":13117455},{"batb":[[0,5.2,29.64],[1,5,10.08],[2,1.01,0.51]],"ltp":5.1,"tv":23.45,"id":13117503},{"batb":[[0,1.57,73.1],[1,1.01,0.51],[2,1.01,0]],"ltp":2.92,"tv":276.24,"id":13117454}]}]}
{"op":"mcm","clk":"1001521666","pt":1580637459311,"mc":[{"id":"1.168215938","rc":[{"batb":[[1,1.01,0.51],[2,1.01,0]],"ltp":5.0,"tv":105.34,"id":13117455},{"batb":[[1,1.01,0.51],[2,1.01,0]],"ltp":5.1,"tv":23.45,"id":13117503},{"batb":[[0,1.01,0.51],[1,1.01,0]],"ltp":2.92,"tv":276.24,"id":13117454}]}]}
{"op":"mcm","clk":"1001521870","pt":1580637461836,"mc":[{"id":"1.168215938","rc":[{"batb":[[0,5,44.23],[1,4.9,33.02],[2,1.01,0.51]],"ltp":5.0,"tv":105.34,"id":13117455},{"batb":[[1,5.1,31],[2,1.01,0.51]],"ltp":5.1,"tv":23.45,"id":13117503},{"batb":[[0,170,2.22],[1,1.01,0.51]],"ltp":3.8,"tv":32.93,"id":13117502}]}]}
{"op":"mcm","clk":"1001522015","pt":1580637463902,"mc":[{"id":"1.168215938","rc":[{"batb":[[0,1.59,63.54],[1,1.58,73.69],[2,1.01,0.51]],"ltp":2.92,"tv":276.24,"id":13117454}]}]}
{"op":"mcm","clk":"1001522078","pt":1580637464829,"mc":[{"id":"1.168215938","rc":[{"batb":[[2,4.6,10.92]],"batl":[[0,5.4,9.24]],"ltp":5.0,"tv":105.34,"id":13117455},{"batb":[[2,5,10.08]],"batl":[[0,6,8.4]],"ltp":5.1,"tv":23.45,"id":13117503},{"batb":[[0,1.58,145.95],[1,1.01,0.51],[2,1.01,0]],"batl":[[0,1.7,42.01]],"ltp":2.92,"tv":276.24,"id":13117454}]}]}
{"op":"mcm","clk":"1001522262","pt":1580637467820,"mc":[{"id":"1.168215938","rc":[{"batb":[[0,1.58,209.91],[1,1.57,75.8],[2,1.01,0.51]],"ltp":2.92,"tv":276.24,"id":13117454}]}]}
{"op":"mcm","clk":"1001522658","pt":1580637474418,"mc":[{"id":"1.168215938","rc":[{"batb":[[0,5,31.43]],"ltp":5.0,"tv":105.34,"id":13117455},{"batb":[[0,5.1,31],[1,5,10.08],[2,1.01,0.51]],"ltp":5.1,"tv":23.45,"id":13117503},{"batb":[[0,1.58,72.26],[1,1.01,0.51],[2,1.01,0]],"ltp":2.92,"tv":276.24,"id":13117454},{"batb":[[0,1.01,0.51],[1,1.01,0]],"ltp":3.8,"tv":32.93,"id":13117502}]}]}
{"op":"mcm","clk":"1001522742","pt":1580637475755,"mc":[{"id":"1.168215938","rc":[{"batb":[[2,1.01,0.51]],"ltp":5.0,"tv":105.34,"id":13117455},{"batb":[[1,1.01,0.51],[2,1.01,0]],"ltp":5.1,"tv":23.45,"id":13117503},{"batb":[[0,1.01,0.51],[1,1.01,0]],"ltp":2.92,"tv":276.24,"id":13117454}]}]}
{"op":"mcm","clk":"1001522882","pt":1580637477925,"mc":[{"id":"1.168215938","rc":[{"batb":[[1,5,32.42],[2,1.01,0.51]],"ltp":5.1,"tv":23.45,"id":13117503},{"batb":[[0,1.56,108.58],[1,1.55,79.5],[2,1.01,0.51]],"ltp":2.92,"tv":276.24,"id":13117454},{"batb":[[0,160,2.26],[1,150,2.07],[2,1.01,0.51]],"ltp":3.8,"tv":32.93,"id":13117502}]}]}
{"op":"mcm","clk":"1001522888","pt":1580637478026,"mc":[{"id":"1.168215938","rc":[{"batb":[[1,1.01,0.51],[2,1.01,0]],"ltp":5.1,"tv":23.45,"id":13117503},{"batb":[[0,1.01,0.51],[1,1.55,0],[2,1.01,0]],"ltp":2.92,"tv":276.24,"id":13117454},{"batb":[[0,1.01,0.51],[1,150,0],[2,1.01,0]],"ltp":3.8,"tv":32.93,"id":13117502}]}]}
{"op":"mcm","clk":"1001523385","pt":1580637486552,"mc":[{"id":"1.168215938","rc":[{"batb":[[1,1.01,0.51],[2,1.01,0]],"ltp":5.0,"tv":105.34,"id":13117455},{"batb":[[0,1.01,0.51],[1,1.01,0]],"ltp":5.1,"tv":23.45,"id":13117503},{"batb":[[0,1.56,108.58],[1,1.55,79.5],[2,1.01,0.51]],"ltp":2.92,"tv":276.24,"id":13117454}]}]}
{"op":"mcm","clk":"1001523538","pt":1580637489233,"mc":[{"id":"1.168215938","rc":[{"batb":[[0,5.1,39.23],[1,5,31.43],[2,1.01,0.51]],"ltp":5.0,"tv":105.34,"id":13117455},{"batb":[[0,5.4,26.53],[1,5.3,28.56],[2,1.01,0.51]],"ltp":5.1,"tv":23.45,"id":13117503},{"batb":[[0,190,2.04],[1,1.01,0.51]],"ltp":3.8,"tv":32.93,"id":13117502}]}]}
{"op":"mcm","clk":"1001523599","pt":1580637490376,"mc":[{"id":"1.168215938","rc":[{"batb":[[2,4.6,10.92]],"batl":[[0,5.4,9.24]],"ltp":5.0,"tv":105.34,"id":13117455},{"batb":[[2,5.1,10.08]],"batl":[[0,6.2,7.56]],"ltp":5.1,"tv":23.45,"id":13117503},{"batb":[[0,1.56,183.36]],"batl":[[0,1.68,42.01]],"ltp":2.92,"tv":276.24,"id":13117454}]}]}
{"op":"mcm","clk":"1001523784","pt":1580637493354,"mc":[{"id":"1.168215938","rc":[{"batb":[[0,1.01,0.51],[1,1.01,0]],"ltp":3.8,"tv":32.93,"id":13117502}]}]}
{"op":"mcm","clk":"1001524400","pt":1580637506062,"mc":[{"id":"1.168215938","rc":[{"batb":[[0,5.1,20.06]],"ltp":5.0,"tv":105.34,"id":13117455},{"batb":[[0,5.3,28.56],[1,5.1,10.08],[2,1.01,0.51]],"ltp":5.1,"tv":23.45,"id":13117503},{"batb":[[0,1.56,74.78],[1,1.01,0.51],[2,1.01,0]],"ltp":2.92,"tv":276.24,"id":13117454}]}]}
{"op":"mcm","clk":"1001524473","pt":1580637507289,"mc":[{"id":"1.168215938","rc":[{"batb":[[2,1.01,0.51]],"ltp":5.0,"tv":105.34,"id":13117455},{"batb":[[1,1.01,0.51],[2,1.01,0]],"ltp":5.1,"tv":23.45,"id":13117503},{"batb":[[0,1.01,0.51],[1,1.01,0]],"ltp":2.92,"tv":276.24,"id":13117454}]}]}
{"op":"mcm","clk":"1001524585","pt":1580637509300,"mc":[{"id":"1.168215938","rc":[{"batb":[[1,5.2,29.87],[2,1.01,0.51]],"ltp":5.1,"tv":23.45,"id":13117503},{"batb":[[0,1.53,145.46],[1,1.52,86.04],[2,1.01,0.51]],"ltp":2.92,"tv":276.24,"id":13117454},{"batb":[[0,170,2.56],[1,1.01,0.51]],"ltp":3.8,"tv":32.93,"id":13117502}]}]}
{"op":"mcm","clk":"1001524909","pt":1580637514774,"mc":[{"id":"1.168215938","rc":[{"batb":[[0,1.01,0.51],[1,1.52,0],[2,1.01,0]],"ltp":2.92,"tv":276.24,"id":13117454}]}]}
{"op":"mcm","clk":"1001525107","pt":1580637517762,"mc":[{"id":"1.168215938","rc":[{"batb":[[0,1.58,80.64],[1,1.57,75.57],[2,1.01,0.51]],"ltp":2.92,"tv":276.24,"id":13117454}]}]}
{"op":"mcm","clk":"1001525138","pt":1580637518277,"mc":[{"id":"1.168215938","rc":[{"batb":[[2,4.6,10.92]],"batl":[[0,5.4,9.24]],"ltp":5.0,"tv":105.34,"id":13117455},{"batb":[[2,5,10.08]],"batl":[[0,6,8.4]],"ltp":5.1,"tv":23.45,"id":13117503},{"batb":[[1,1.57,148.67]],"batl":[[0,1.69,42.01]],"ltp":2.92,"tv":276.24,"id":13117454}]}]}
{"op":"mcm","clk":"1001525485","pt":1580637524508,"mc":[{"id":"1.168215938","rc":[{"batb":[[0,5,31.43],[1,4.6,10.92],[2,1.01,0.51]],"ltp":5.0,"tv":105.34,"id":13117455}]}]}
{"op":"mcm","clk":"1001525682","pt":1580637527394,"mc":[{"id":"1.168215938","rc":[{"batb":[[0,5,51.13],[1,4.9,32.89],[2,4.6,10.92]],"ltp":5.0,"tv":105.34,"id":13117455}]}]}
{"op":"mcm","clk":"1001525957","pt":1580637532813,"mc":[{"id":"1.168215938","rc":[{"batb":[[0,5,34.86]],"ltp":5.0,"tv":105.34,"id":13117455},{"batb":[[0,5.2,29.87],[1,5,10.08],[2,1.01,0.51]],"ltp":5.1,"tv":23.45,"id":13117503},{"batb":[[0,1.57,73.1],[1,1.01,0.51],[2,1.01,0]],"ltp":2.92,"tv":276.24,"id":13117454},{"batb":[[0,1.01,0.51],[1,1.01,0]],"ltp":3.8,"tv":32.93,"id":13117502}]}]}
{"op":"mcm","clk":"1001525996","pt":1580637533429,"mc":[{"id":"1.168215938","rc":[{"batb":[[2,1.01,0.51]],"ltp":5.0,"tv":105.34,"id":13117455},{"batb":[[1,1.01,0.51],[2,1.01,0]],"ltp":5.1,"tv":23.45,"id":13117503},{"batb":[[0,1.01,0.51],[1,1.01,0]],"ltp":2.92,"tv":276.24,"id":13117454}]}]}
{"op":"mcm","clk":"1001526122","pt":1580637535484,"mc":[{"id":"1.168215938","rc":[{"batb":[[1,5.1,31.21],[2,1.01,0.51]],"ltp":5.1,"tv":23.45,"id":13117503},{"batb":[[0,1.55,125.85],[1,1.54,81.66],[2,1.01,0.51]],"ltp":2.92,"tv":276.24,"id":13117454},{"batb":[[0,160,2.92],[1,1.01,0.51]],"ltp":3.8,"tv":32.93,"id":13117502}]}]}
{"op":"mcm","clk":"1001526183","pt":1580637536407,"mc":[{"id":"1.168215938","rc":[{"batb":[[1,1.01,0.51],[2,1.01,0]],"ltp":5.0,"tv":105.34,"id":13117455},{"batb":[[1,1.01,0.51],[2,1.01,0]],"ltp":5.1,"tv":23.45,"id":13117503},{"batb":[[0,1.01,0.51],[1,1.54,0],[2,1.01,0]],"ltp":2.92,"tv":276.24,"id":13117454},{"batb":[[0,1.01,0.51],[1,1.01,0]],"ltp":3.8,"tv":32.93,"id":13117502}]}]}
{"op":"mcm","clk":"1001526710","pt":1580637544312,"mc":[{"id":"1.168215938","rc":[{"batb":[[1,4.9,33.15],[2,1.01,0.51]],"ltp":5.0,"tv":105.34,"id":13117455},{"batb":[[1,5.1,31.21],[2,1.01,0.51]],"ltp":5.1,"tv":23.45,"id":13117503},{"batb":[[0,1.55,121.29],[1,1.54,81.65],[2,1.01,0.51]],"ltp":2.92,"tv":276.24,"id":13117454},{"batb":[[0,160,3],[1,1.01,0.51]],"ltp":3.8,"tv":32.93,"id":13117502}]}]}
{"op":"mcm","clk":"1001526935","pt":1580637548636,"mc":[{"id":"1.168215938","rc":[{"batb":[[1,1.01,0.51],[2,1.01,0]],"ltp":5.0,"tv":105.34,"id":13117455},{"batb":[[0,1.01,0.51],[1,5.1,0],[2,1.01,0]],"ltp":5.1,"tv":23.45,"id":13117503},{"batb":[[0,1.01,0.51],[1,1.01,0]],"ltp":3.8,"tv":32.93,"id":13117502}]}]}
{"op":"mcm","clk":"1001527111","pt":1580637551531,"mc":[{"id":"1.168215938","rc":[{"batb":[[0,5.1,45.05],[1,5,34.86],[2,1.01,0.51]],"ltp":5.0,"tv":105.34,"id":13117455},{"batb":[[0,5.5,22.68],[1,5.4,27.56],[2,1.01,0.51]],"ltp":5.1,"tv":23.45,"id":13117503},{"batb":[[0,190,2.25],[1,1.01,0.51]],"ltp":3.8,"tv":32.93,"id":13117502}]}]}
{"op":"mcm","clk":"1001527171","pt":1580637552508,"mc":[{"id":"1.168215938","rc":[{"batb":[[2,4.6,10.92]],"batl":[[0,5.4,9.24]],"ltp":5.0,"tv":105.34,"id":13117455},{"batb":[[2,5.2,9.24]],"batl":[[0,6.2,7.56]],"ltp":5.1,"tv":23.45,"id":13117503},{"batb":[[0,1.56,74.78],[1,1.55,121.29],[2,1.54,81.65]],"batl":[[0,1.67,42.01]],"ltp":2.92,"tv":276.24,"id":13117454}]}]}
{"op":"mcm","clk":"1001527892","pt":1580637564852,"mc":[{"id":"1.168215938","rc":[{"batb":[[0,5.1,25.99]],"ltp":5.0,"tv":105.34,"id":13117455},{"batb":[[0,5.4,19.13],[1,5.2,9.24],[2,1.01,0.51]],"ltp":5.1,"tv":23.45,"id":13117503},{"batb":[[1,1.01,0.51],[2,1.54,0]],"ltp":2.92,"tv":276.24,"id":13117454},{"batb":[[0,1.01,0.51],[1,1.01,0]],"ltp":3.8,"tv":32.93,"id":13117502}]}]}
{"op":"mcm","clk":"1001527926","pt":1580637565474,"mc":[{"id":"1.168215938","rc":[{"batb":[[2,1.01,0.51]],"ltp":5.0,"tv":105.34,"id":13117455},{"batb":[[1,1.01,0.51],[2,1.01,0]],"ltp":5.1,"tv":23.45,"id":13117503},{"batb":[[0,1.01,0.51],[1,1.01,0]],"ltp":2.92,"tv":276.24,"id":13117454}]}]}
{"op":"mcm","clk":"1001528120","pt":1580637567876,"mc":[{"id":"1.168215938","rc":[{"batb":[[1,1.01,0.51],[2,1.01,0]],"ltp":5.0,"tv":105.34,"id":13117455},{"batb":[[1,5.3,28.79],[2,1.01,0.51]],"ltp":5.1,"tv":23.45,"id":13117503},{"batb":[[0,1.53,81.6],[1,1.52,85.75],[2,1.01,0.51]],"ltp":2.92,"tv":276.24,"id":13117454}]}]}
{"op":"mcm","clk":"1001528180","pt":1580637568565,"mc":[{"id":"1.168215938","rc":[{"batb":[[1,1.01,0.51],[2,1.01,0]],"ltp":5.1,"tv":23.45,"id":13117503},{"batb":[[0,1.01,0.51],[1,1.52,0],[2,1.01,0]],"ltp":2.92,"tv":276.24,"id":13117454}]}]}
{"op":"mcm","clk":"1001528370","pt":1580637570873,"mc":[{"id":"1.168215938","rc":[{"batb":[[0,5.2,20.19],[1,5.1,25.99],[2,1.01,0.51]],"ltp":5.0,"tv":105.34,"id":13117455},{"batb":[[0,5.5,32.88],[1,5.4,27.41],[2,1.01,0.51]],"ltp":5.1,"tv":23.45,"id":13117503},{"batb":[[0,1.55,80.41],[1,1.54,81.45],[2,1.01,0.51]],"ltp":2.92,"tv":276.24,"id":13117454}]}]}
{"op":"mcm","clk":"1001528570","pt":1580637573357,"mc":[{"id":"1.168215938","rc":[{"batb":[[0,5.1,25.99],[1,1.01,0.51],[2,1.01,0]],"ltp":5.0,"tv":105.34,"id":13117455},{"batb":[[0,5.4,19.13],[1,1.01,0.51],[2,1.01,0]],"ltp":5.1,"tv":23.45,"id":13117503},{"batb":[[0,1.01,0.51],[1,1.54,0],[2,1.01,0]],"ltp":2.92,"tv":276.24,"id":13117454}]}]}
{"op":"mcm","clk":"1001528768","pt":1580637575058,"mc":[{"id":"1.168215938","rc":[{"batb":[[0,1.01,0.51],[1,1.01,0]],"ltp":5.1,"tv":23.45,"id":13117503}]}]}
{"op":"mcm","clk":"1001528868","pt":1580637576761,"mc":[{"id":"1.168215938","rc":[{"batb":[[0,1.53,81.6],[1,1.52,85.75],[2,1.01,0.51]],"ltp":2.92,"tv":276.24,"id":13117454}]}]}
{"op":"mcm","clk":"1001528945","pt":1580637577949,"mc":[{"id":"1.168215938","rc":[{"batb":[[0,5.2,44.53],[1,5.1,25.99],[2,1.01,0.51]],"ltp":5.0,"tv":105.34,"id":13117455},{"batb":[[0,5.7,19.85],[1,5.6,25.45],[2,1.01,0.51]],"ltp":5.1,"tv":23.45,"id":13117503}]}]}
{"op":"mcm","clk":"1001529004","pt":1580637578775,"mc":[{"id":"1.168215938","rc":[{"batb":[[2,4.6,10.92]],"batl":[[0,5.4,9.24]],"ltp":5.0,"tv":105.34,"id":13117455},{"batb":[[2,5.3,9.24]],"batl":[[0,6.4,7.56]],"ltp":5.1,"tv":23.45,"id":13117503},{"batb":[[0,1.54,77.3],[1,1.53,81.6],[2,1.52,85.75]],"batl":[[0,1.66,42.01]],"ltp":2.92,"tv":276.24,"id":13117454}]}]}
{"op":"mcm","clk":"1001530533","pt":1580637600812,"mc":[{"id":"1.168215938","rc":[{"batb":[[0,5.2,20.43]],"ltp":5.0,"tv":105.34,"id":13117455},{"batb":[[0,5.3,9.24],[1,1.01,0.51],[2,5.3,0]],"ltp":5.1,"tv":23.45,"id":13117503},{"batb":[[1,1.01,0.51],[2,1.52,0]],"ltp":2.92,"tv":276.24,"id":13117454}]}]}
{"op":"mcm","clk":"1001530619","pt":1580637601571,"mc":[{"id":"1.168215938","rc":[{"batb":[[2,1.01,0.51]],"ltp":5.0,"tv":105.34,"id":13117455},{"batb":[[0,1.01,0.51],[1,1.01,0]],"ltp":5.1,"tv":23.45,"id":13117503},{"batb":[[0,1.01,0.51],[1,1.01,0]],"ltp":2.92,"tv":276.24,"id":13117454}]}]}
{"op":"mcm","clk":"1001530871","pt":1580637603826,"mc":[{"id":"1.168215938","rc":[{"batb":[[0,5.5,35.21],[1,5.4,27.38],[2,1.01,0.51]],"ltp":5.1,"tv":23.45,"id":13117503},{"batb":[[0,1.5,89.43],[1,1.49,92.95],[2,1.01,0.51]],"ltp":2.92,"tv":276.24,"id":13117454}]}]}
{"op":"mcm","clk":"1001530957","pt":1580637604623,"mc":[{"id":"1.168215938","rc":[{"batb":[[1,1.01,0.51],[2,1.01,0]],"ltp":5.0,"tv":105.34,"id":13117455},{"batb":[[0,1.01,0.51],[1,5.4,0],[2,1.01,0]],"ltp":5.1,"tv":23.45,"id":13117503},{"batb":[[0,1.01,0.51],[1,1.49,0],[2,1.01,0]],"ltp":2.92,"tv":276.24,"id":13117454}]}]}
{"op":"mcm","clk":"1001531239","pt":1580637607811,"mc":[{"id":"1.168215938","rc":[{"batb":[[0,5.3,22.4],[1,5.2,29.14],[2,1.01,0.51]],"ltp":5.0,"tv":105.34,"id":13117455},{"batb":[[0,5.7,31.33],[1,5.6,25.29],[2,1.01,0.51]],"ltp":5.1,"tv":23.45,"id":13117503},{"batb":[[0,1.52,116.93],[1,1.51,88.24],[2,1.01,0.51]],"ltp":2.92,"tv":276.24,"id":13117454}]}]}
{"op":"mcm","clk":"1001531399","pt":1580637609829,"mc":[{"id":"1.168215938","rc":[{"batb":[[0,5.2,20.43],[1,1.01,0.51],[2,1.01,0]],"ltp":5.0,"tv":105.34,"id":13117455},{"batb":[[0,1.01,0.51],[1,5.6,0],[2,1.01,0]],"ltp":5.1,"tv":23.45,"id":13117503},{"batb":[[0,1.01,0.51],[1,1.51,0],[2,1.01,0]],"ltp":2.92,"tv":276.24,"id":13117454}]}]}
{"op":"mcm","clk":"1001531614","pt":1580637612587,"mc":[{"id":"1.168215938","rc":[{"batb":[[1,5.1,30.48],[2,1.01,0.51]],"ltp":5.0,"tv":105.34,"id":13117455},{"batb":[[0,5.5,35.21],[1,5.4,27.38],[2,1.01,0.51]],"ltp":5.1,"tv":23.45,"id":13117503},{"batb":[[0,1.5,89.43],[1,1.49,92.95],[2,1.01,0.51]],"ltp":2.92,"tv":276.24,"id":13117454}]}]}
{"op":"mcm","clk":"1001531977","pt":1580637617910,"mc":[{"id":"1.168215938","rc":[{"batb":[[0,1.01,0.51],[1,1.49,0],[2,1.01,0]],"ltp":2.92,"tv":276.24,"id":13117454}]}]}
{"op":"mcm","clk":"1001532175","pt":1580637620944,"mc":[{"id":"1.168215938","rc":[{"batb":[[0,1.55,77.44],[1,1.54,81.44],[2,1.01,0.51]],"ltp":2.92,"tv":276.24,"id":13117454}]}]}
{"op":"mcm","clk":"1001532289","pt":1580637622444,"mc":[{"id":"1.168215938","rc":[{"batb":[[2,4.6,10.92]],"batl":[[0,5.4,9.24]],"ltp":5.0,"tv":105.34,"id":13117455},{"batb":[[2,5.2,9.24]],"batl":[[0,6.4,7.56]],"ltp":5.1,"tv":23.45,"id":13117503},{"batb":[[0,1.55,153.06]],"batl":[[0,1.66,42.01]],"ltp":2.92,"tv":276.24,"id":13117454}]}]}
{"op":"mcm","clk":"1001533372","pt":1580637635861,"mc":[{"id":"1.168215938","rc":[{"batb":[[0,5.1,30.48],[1,4.6,10.92],[2,1.01,0.51]],"ltp":5.0,"tv":105.34,"id":13117455},{"batb":[[0,5.4,27.38],[1,5.2,9.24],[2,1.01,0.51]],"ltp":5.1,"tv":23.45,"id":13117503},{"batb":[[0,1.55,75.62],[1,1.01,0.51],[2,1.01,0]],"ltp":2.92,"tv":276.24,"id":13117454}]}]}
{"op":"mcm","clk":"1001533491","pt":1580637637420,"mc":[{"id":"1.168215938","rc":[{"batb":[[1,1.01,0.51],[2,1.01,0]],"ltp":5.0,"tv":105.34,"id":13117455},{"batb":[[1,1.01,0.51],[2,1.01,0]],"ltp":5.1,"tv":23.45,"id":13117503},{"batb":[[0,1.01,0.51],[1,1.01,0]],"ltp":2.92,"tv":276.24,"id":13117454}]}]}
{"op":"mcm","clk":"1001533573","pt":1580637638460,"mc":[{"id":"1.168215938","rc":[{"batb":[[1,5,31.69],[2,1.01,0.51]],"ltp":5.0,"tv":105.34,"id":13117455},{"batb":[[1,5.3,28.61],[2,1.01,0.51]],"ltp":5.1,"tv":23.45,"id":13117503},{"batb":[[0,1.52,123.87],[1,1.51,88.28],[2,1.01,0.51]],"ltp":2.92,"tv":276.24,"id":13117454},{"batb":[[0,170,2.28],[1,1.01,0.51]],"ltp":3.8,"tv":32.93,"id":13117502}]}]}
{"op":"mcm","clk":"1001533813","pt":1580637641457,"mc":[{"id":"1.168215938","rc":[{"batb":[[0,1.01,0.51],[1,5,0],[2,1.01,0]],"ltp":5.0,"tv":105.34,"id":13117455},{"batb":[[0,1.01,0.51],[1,5.3,0],[2,1.01,0]],"ltp":5.1,"tv":23.45,"id":13117503},{"batb":[[0,1.01,0.51],[1,1.51,0],[2,1.01,0]],"ltp":2.92,"tv":276.24,"id":13117454},{"batb":[[0,1.01,0.51],[1,1.01,0]],"ltp":3.8,"tv":32.93,"id":13117502}]}]}
{"op":"mcm","clk":"1001534043","pt":1580637644659,"mc":[{"id":"1.168215938","rc":[{"batb":[[0,5.3,21.27],[1,5.2,29.16],[2,4.6,10.92]],"batl":[[0,5.4,9.24]],"ltp":5.0,"tv":105.34,"id":13117455},{"batb":[[0,5.7,31.65],[1,5.6,25.29],[2,5.4,9.24]],"batl":[[0,6.4,7.56]],"ltp":5.1,"tv":23.45,"id":13117503},{"batb":[[0,1.54,77.3],[1,1.52,123.87],[2,1.51,88.28]],"batl":[[0,1.65,42.01]],"ltp":2.92,"tv":276.24,"id":13117454}]}]}
{"op":"mcm","clk":"1001535138","pt":1580637658807,"mc":[{"id":"1.168215938","rc":[{"batb":[[0,5.2,29.16],[1,4.6,10.92],[2,1.01,0.51]],"ltp":5.0,"tv":105.34,"id":13117455},{"batb":[[0,5.6,25.29],[1,5.4,9.24],[2,1.01,0.51]],"ltp":5.1,"tv":23.45,"id":13117503},{"batb":[[1,1.01,0.51],[2,1.51,0]],"ltp":2.92,"tv":276.24,"id":13117454}]}]}
{"op":"mcm","clk":"1001535205","pt":1580637659538,"mc":[{"id":"1.168215938","rc":[{"batb":[[1,1.01,0.51],[2,1.01,0]],"ltp":5.0,"tv":105.34,"id":13117455},{"batb":[[1,1.01,0.51],[2,1.01,0]],"ltp":5.1,"tv":23.45,"id":13117503},{"batb":[[0,1.01,0.51],[1,1.01,0]],"ltp":2.92,"tv":276.24,"id":13117454}]}]}
{"op":"mcm","clk":"1001535431","pt":1580637661936,"mc":[{"id":"1.168215938","rc":[{"batb":[[1,5.1,30.38],[2,1.01,0.51]],"ltp":5.0,"tv":105.34,"id":13117455},{"batb":[[1,5.5,26.49],[2,1.01,0.51]],"ltp":5.1,"tv":23.45,"id":13117503},{"batb":[[0,1.49,137.34],[1,1.48,95.88],[2,1.01,0.51]],"ltp":2.92,"tv":276.24,"id":13117454}]}]}
{"op":"mcm","clk":"1001536731","pt":1580637677759,"mc":[{"id":"1.168215938","rc":[{"batb":[[0,1.01,0.51],[1,1.48,0],[2,1.01,0]],"ltp":2.92,"tv":276.24,"id":13117454}]}]}
{"op":"mcm","clk":"1001536919","pt":1580637680533,"mc":[{"id":"1.168215938","rc":[{"batb":[[2,4.6,10.92]],"batl":[[0,5.4,9.24]],"ltp":5.0,"tv":105.34,"id":13117455},{"batb":[[2,5.4,9.24]],"batl":[[0,6.4,7.56]],"ltp":5.1,"tv":23.45,"id":13117503},{"batb":[[0,1.54,193.71],[1,1.53,83.75],[2,1.01,0.51]],"batl":[[0,1.66,42.01]],"ltp":2.92,"tv":276.24,"id":13117454}]}]}
{"op":"mcm","clk":"1001538439","pt":1580637699656,"mc":[{"id":"1.168215938","rc":[{"batb":[[0,1.01,0.51],[1,5.1,0],[2,4.6,0]],"ltp":5.0,"tv":105.34,"id":13117455},{"batb":[[0,1.01,0.51],[1,5.5,0],[2,5.4,0]],"ltp":5.1,"tv":23.45,"id":13117503},{"batb":[[0,1.01,0.51],[1,1.53,0],[2,1.01,0]],"ltp":2.92,"tv":276.24,"id":13117454}]}]}
{"op":"mcm","clk":"1001538743","pt":1580637703561,"mc":[{"id":"1.168215938","rc":[{"batb":[[0,5.1,30.29],[1,1.01,0.51]],"ltp":5.0,"tv":105.34,"id":13117455}]}]}
{"op":"mcm","clk":"1001538916","pt":1580637705851,"mc":[{"id":"1.168215938","rc":[{"batb":[[0,5.2,32.55],[1,5.1,30.29],[2,1.01,0.51]],"ltp":5.0,"tv":105.34,"id":13117455},{"batb":[[0,5.6,30.23],[1,5.5,26.35],[2,1.01,0.51]],"ltp":5.1,"tv":23.45,"id":13117503},{"batb":[[0,1.54,75.86],[1,1.53,83.53],[2,1.01,0.51]],"ltp":2.92,"tv":276.24,"id":13117454}]}]}
{"op":"mcm","clk":"1001539068","pt":1580637707957,"mc":[{"id":"1.168215938","rc":[{"batb":[[0,5.1,30.29],[1,1.01,0.51],[2,1.01,0]],"ltp":5.0,"tv":105.34,"id":13117455},{"batb":[[0,1.01,0.51],[1,5.5,0],[2,1.01,0]],"ltp":5.1,"tv":23.45,"id":13117503},{"batb":[[0,1.01,0.51],[1,1.53,0],[2,1.01,0]],"ltp":2.92,"tv":276.24,"id":13117454}]}]}
{"op":"mcm","clk":"1001539263","pt":1580637710765,"mc":[{"id":"1.168215938","rc":[{"batb":[[0,5.1,38.2],[1,5,31.6],[2,1.01,0.51]],"ltp":5.0,"tv":105.34,"id":13117455},{"batb":[[0,5.4,43.44],[1,5.3,28.44],[2,1.01,0.51]],"ltp":5.1,"tv":23.45,"id":13117503},{"batb":[[0,1.52,81.2],[1,1.51,88.03],[2,1.01,0.51]],"ltp":2.92,"tv":276.24,"id":13117454},{"batb":[[0,170,2.72],[1,1.01,0.51]],"ltp":3.8,"tv":32.93,"id":13117502}]}]}
{"op":"mcm","clk":"1001539581","pt":1580637714659,"mc":[{"id":"1.168215938","rc":[{"batb":[[0,1.01,0.51],[1,1.51,0],[2,1.01,0]],"ltp":2.92,"tv":276.24,"id":13117454}]}]}
{"op":"mcm","clk":"1001539814","pt":1580637717367,"mc":[{"id":"1.168215938","rc":[{"batb":[[0,1.56,83.6],[1,1.55,79.45],[2,1.01,0.51]],"ltp":2.92,"tv":276.24,"id":13117454}]}]}
{"op":"mcm","clk":"1001539899","pt":1580637718502,"mc":[{"id":"1.168215938","rc":[{"batb":[[2,4.6,10.92]],"batl":[[0,5.4,9.24]],"ltp":5.0,"tv":105.34,"id":13117455},{"batb":[[2,5.2,9.24]],"batl":[[0,6.2,7.56]],"ltp":5.1,"tv":23.45,"id":13117503},{"batb":[[1,1.55,155.07]],"batl":[[0,1.67,42.01]],"ltp":2.92,"tv":276.24,"id":13117454}]}]}
{"op":"mcm","clk":"1001546797","pt":1580637795822,"mc":[{"id":"1.168215938","rc":[{"batb":[[0,5,31.6],[1,4.6,10.92],[2,1.01,0.51]],"ltp":5.0,"tv":105.34,"id":13117455},{"batb":[[0,5.2,9.24],[1,1.01,0.51],[2,5.2,0]],"ltp":5.1,"tv":23.45,"id":13117503},{"batb":[[0,1.55,75.62],[1,1.01,0.51],[2,1.01,0]],"ltp":2.92,"tv":276.24,"id":13117454},{"batb":[[0,1.01,0.51],[1,1.01,0]],"ltp":3.8,"tv":32.93,"id":13117502}]}]}
{"op":"mcm","clk":"1001546975","pt":1580637797897,"mc":[{"id":"1.168215938","rc":[{"batb":[[1,1.01,0.51],[2,1.01,0]],"ltp":5.0,"tv":105.34,"id":13117455},{"batb":[[0,1.01,0.51],[1,1.01,0]],"ltp":5.1,"tv":23.45,"id":13117503},{"batb":[[0,1.01,0.51],[1,1.01,0]],"ltp":2.92,"tv":276.24,"id":13117454}]}]}
{"op":"mcm","clk":"1001547043","pt":1580637798926,"mc":[{"id":"1.168215938","rc":[{"batb":[[0,5,11.96],[1,4.9,33.08],[2,1.01,0.51]],"ltp":5.0,"tv":105.34,"id":13117455},{"batb":[[0,5.2,48.62],[1,5.1,31.01],[2,1.01,0.51]],"ltp":5.1,"tv":23.45,"id":13117503},{"batb":[[0,1.54,110],[1,1.53,83.62],[2,1.01,0.51]],"ltp":2.92,"tv":276.24,"id":13117454}]}]}
{"op":"mcm","clk":"1001547120","pt":1580637799919,"mc":[{"id":"1.168215938","rc":[{"batb":[[0,1.01,0.51],[1,4.9,0],[2,1.01,0]],"ltp":5.0,"tv":105.34,"id":13117455},{"batb":[[0,1.01,0.51],[1,5.1,0],[2,1.01,0]],"ltp":5.1,"tv":23.45,"id":13117503}]}]}
{"op":"mcm","clk":"1001547216","pt":1580637801417,"mc":[{"id":"1.168215938","rc":[{"batb":[[0,5.2,20.29],[1,5.1,30.45],[2,1.01,0.51]],"ltp":5.0,"tv":105.34,"id":13117455},{"batb":[[0,5.5,40.85],[1,5.4,27.27],[2,1.01,0.51]],"ltp":5.1,"tv":23.45,"id":13117503}]}]}
{"op":"mcm","clk":"1001547310","pt":1580637802716,"mc":[{"id":"1.168215938","rc":[{"batb":[[2,4.7,10.92]],"batl":[[0,5.5,9.24]],"ltp":5.0,"tv":105.34,"id":13117455},{"batb":[[2,5.3,9.24]],"batl":[[0,6.4,7.56]],"ltp":5.1,"tv":23.45,"id":13117503},{"batb":[[0,1.54,187.3]],"batl":[[0,1.65,42.01]],"ltp":2.92,"tv":276.24,"id":13117454}]}]}
{"op":"mcm","clk":"1001547763","pt":1580637808937,"mc":[{"id":"1.168215938","rc":[{"batb":[[0,5.1,30.45],[1,4.7,10.92],[2,1.01,0.51]],"ltp":5.0,"tv":105.34,"id":13117455},{"batb":[[0,5.3,9.24],[1,1.01,0.51],[2,5.3,0]],"ltp":5.1,"tv":23.45,"id":13117503},{"batb":[[0,1.54,77.3]],"ltp":2.92,"tv":276.24,"id":13117454}]}]}
{"op":"mcm","clk":"1001547835","pt":1580637809927,"mc":[{"id":"1.168215938","rc":[{"batb":[[1,1.01,0.51],[2,1.01,0]],"ltp":5.0,"tv":105.34,"id":13117455},{"batb":[[0,1.01,0.51],[1,1.01,0]],"ltp":5.1,"tv":23.45,"id":13117503},{"batb":[[0,1.53,83.62],[1,1.01,0.51],[2,1.01,0]],"ltp":2.92,"tv":276.24,"id":13117454}]}]}
{"op":"mcm","clk":"1001548003","pt":1580637811826,"mc":[{"id":"1.168215938","rc":[{"batb":[[1,5,31.84],[2,1.01,0.51]],"ltp":5.0,"tv":105.34,"id":13117455},{"batb":[[0,5.3,41.71],[1,5.2,29.73],[2,1.01,0.51]],"ltp":5.1,"tv":23.45,"id":13117503},{"batb":[[1,1.52,85.53],[2,1.01,0.51]],"ltp":2.92,"tv":276.24,"id":13117454},{"batb":[[0,140,3.38],[1,1.01,0.51]],"ltp":3.8,"tv":32.93,"id":13117502}]}]}
{"op":"mcm","clk":"1001548107","pt":1580637812841,"mc":[{"id":"1.168215938","rc":[{"batb":[[1,1.01,0.51],[2,1.01,0]],"ltp":5.0,"tv":105.34,"id":13117455},{"batb":[[0,1.01,0.51],[1,5.2,0],[2,1.01,0]],"ltp":5.1,"tv":23.45,"id":13117503},{"batb":[[0,1.01,0.51],[1,1.52,0],[2,1.01,0]],"ltp":2.92,"tv":276.24,"id":13117454},{"batb":[[0,1.01,0.51],[1,1.01,0]],"ltp":3.8,"tv":32.93,"id":13117502}]}]}
{"op":"mcm","clk":"1001548394","pt":1580637816532,"mc":[{"id":"1.168215938","rc":[{"batb":[[0,5.1,45.73],[1,5,31.45],[2,1.01,0.51]],"ltp":5.0,"tv":105.34,"id":13117455},{"batb":[[0,5.5,29.81],[1,5.4,27.44],[2,1.01,0.51]],"ltp":5.1,"tv":23.45,"id":13117503},{"batb":[[0,1.55,80],[1,1.54,81.39],[2,1.01,0.51]],"ltp":2.92,"tv":276.24,"id":13117454}]}]}
{"op":"mcm","clk":"1001548480","pt":1580637817362,"mc":[{"id":"1.168215938","rc":[{"batb":[[0,5.1,30.45]],"ltp":5.0,"tv":105.34,"id":13117455},{"batb":[[0,1.01,0.51],[1,5.4,0],[2,1.01,0]],"ltp":5.1,"tv":23.45,"id":13117503},{"batb":[[0,1.01,0.51],[1,1.54,0],[2,1.01,0]],"ltp":2.92,"tv":276.24,"id":13117454}]}]}
{"op":"mcm","clk":"1001548734","pt":1580637820326,"mc":[{"id":"1.168215938","rc":[{"batb":[[0,5.3,41.71],[1,5.2,29.73],[2,1.01,0.51]],"ltp":5.1,"tv":23.45,"id":13117503},{"batb":[[0,1.53,71.43],[1,1.52,85.53],[2,1.01,0.51]],"ltp":2.92,"tv":276.24,"id":13117454},{"batb":[[0,140,3.38],[1,1.01,0.51]],"ltp":3.8,"tv":32.93,"id":13117502}]}]}
{"op":"mcm","clk":"1001548869","pt":1580637821943,"mc":[{"id":"1.168215938","rc":[{"batb":[[1,1.01,0.51],[2,1.01,0]],"ltp":5.0,"tv":105.34,"id":13117455},{"batb":[[0,1.01,0.51],[1,5.2,0],[2,1.01,0]],"ltp":5.1,"tv":23.45,"id":13117503},{"batb":[[0,1.01,0.51],[1,1.01,0]],"ltp":3.8,"tv":32.93,"id":13117502}]}]}
{"op":"mcm","clk":"1001549104","pt":1580637824758,"mc":[{"id":"1.168215938","rc":[{"batb":[[0,5.2,33.03],[1,5.1,30.45],[2,4.7,10.92]],"batl":[[0,5.5,9.24]],"ltp":5.0,"tv":105.34,"id":13117455},{"batb":[[0,5.6,39.61],[1,5.5,26.17],[2,5.4,9.24]],"batl":[[0,6.6,6.72]],"ltp":5.1,"tv":23.45,"id":13117503},{"batb":[[0,1.53,150.41]],"batl":[[0,1.64,42.01]],"ltp":2.92,"tv":276.24,"id":13117454}]}]}
{"op":"mcm","clk":"1001550041","pt":1580637835686,"mc":[{"id":"1.168215938","rc":[{"batb":[[0,5.1,30.45],[1,1.01,0.51],[2,4.7,0]],"ltp":5.0,"tv":105.34,"id":13117455},{"batb":[[0,1.01,0.51],[1,5.5,0],[2,5.4,0]],"ltp":5.1,"tv":23.45,"id":13117503},{"batb":[[0,1.01,0.51],[1,1.52,0],[2,1.01,0]],"ltp":2.92,"tv":276.24,"id":13117454}]}]}
{"op":"mcm","clk":"1001550287","pt":1580637838446,"mc":[{"id":"1.168215938","rc":[{"batb":[[1,5,31.59],[2,1.01,0.51]],"ltp":5.0,"tv":105.34,"id":13117455},{"batb":[[0,5.4,37],[1,5.3,28.5],[2,1.01,0.51]],"ltp":5.1,"tv":23.45,"id":13117503},{"batb":[[0,1.51,136.03],[1,1.5,90.54],[2,1.01,0.51]],"ltp":2.92,"tv":276.24,"id":13117454}]}]}
{"op":"mcm","clk":"1001550421","pt":1580637839848,"mc":[{"id":"1.168215938","rc":[{"batb":[[0,1.01,0.51],[1,1.5,0],[2,1.01,0]],"ltp":2.92,"tv":276.24,"id":13117454}]}]}
{"op":"mcm","clk":"1001550712","pt":1580637842851,"mc":[{"id":"1.168215938","rc":[{"batb":[[0,1.55,137.93],[1,1.54,81.65],[2,1.01,0.51]],"ltp":2.92,"tv":276.24,"id":13117454}]}]}
{"op":"mcm","clk":"1001550871","pt":1580637844883,"mc":[{"id":"1.168215938","rc":[{"batb":[[2,4.6,10.92]],"batl":[[0,5.4,9.24]],"ltp":5.0,"tv":105.34,"id":13117455},{"batb":[[2,5.2,9.24]],"batl":[[0,6.2,7.56]],"ltp":5.1,"tv":23.45,"id":13117503},{"batb":[[0,1.55,213.55]],"batl":[[0,1.67,42.01]],"ltp":2.92,"tv":276.24,"id":13117454}]}]}
{"op":"mcm","clk":"1001551711","pt":1580637854573,"mc":[{"id":"1.168215938","rc":[{"batb":[[0,5,31.59],[1,4.6,10.92],[2,1.01,0.51]],"ltp":5.0,"tv":105.34,"id":13117455},{"batb":[[0,5.2,9.24],[1,1.01,0.51],[2,5.2,0]],"ltp":5.1,"tv":23.45,"id":13117503},{"batb":[[0,1.55,75.62]],"ltp":2.92,"tv":276.24,"id":13117454}]}]}
{"op":"mcm","clk":"1001551813","pt":1580637855664,"mc":[{"id":"1.168215938","rc":[{"batb":[[1,1.01,0.51],[2,1.01,0]],"ltp":5.0,"tv":105.34,"id":13117455},{"batb":[[0,1.01,0.51],[1,1.01,0]],"ltp":5.1,"tv":23.45,"id":13117503},{"batb":[[0,1.54,81.65],[1,1.01,0.51],[2,1.01,0]],"ltp":2.92,"tv":276.24,"id":13117454}]}]}
{"op":"mcm","clk":"1001551872","pt":1580637856390,"mc":[{"id":"1.168215938","rc":[{"batb":[[0,1.01,0.51],[1,1.01,0]],"ltp":2.92,"tv":276.24,"id":13117454}]}]}
{"op":"mcm","clk":"1001551958","pt":1580637857479,"mc":[{"id":"1.168215938","rc":[{"batb":[[0,5,31.69]],"ltp":5.0,"tv":105.34,"id":13117455}]}]}
{"op":"mcm","clk":"1001552166","pt":1580637859808,"mc":[{"id":"1.168215938","rc":[{"batb":[[0,5.1,31.4],[1,5,31.69],[2,1.01,0.51]],"ltp":5.0,"tv":105.34,"id":13117455},{"batb":[[0,5.4,25.86],[1,5.3,28.67],[2,1.01,0.51]],"ltp":5.1,"tv":23.45,"id":13117503},{"batb":[[0,1.56,113.27],[1,1.55,79.54],[2,1.01,0.51]],"ltp":2.92,"tv":276.24,"id":13117454}]}]}
{"op":"mcm","clk":"1001552368","pt":1580637861789,"mc":[{"id":"1.168215938","rc":[{"batb":[[0,5,31.69],[1,1.01,0.51],[2,1.01,0]],"ltp":5.0,"tv":105.34,"id":13117455},{"batb":[[0,1.01,0.51],[1,5.3,0],[2,1.01,0]],"ltp":5.1,"tv":23.45,"id":13117503},{"batb":[[0,1.01,0.51],[1,1.55,0],[2,1.01,0]],"ltp":2.92,"tv":276.24,"id":13117454}]}]}
{"op":"mcm","clk":"1001552648","pt":1580637864799,"mc":[{"id":"1.168215938","rc":[{"batb":[[0,5,41.78],[1,4.9,33.07],[2,1.01,0.51]],"ltp":5.0,"tv":105.34,"id":13117455},{"batb":[[0,5.2,39.86],[1,5.1,31.1],[2,1.01,0.51]],"ltp":5.1,"tv":23.45,"id":13117503},{"batb":[[0,1.54,85.96],[1,1.53,83.41],[2,1.01,0.51]],"ltp":2.92,"tv":276.24,"id":13117454},{"batb":[[0,120,2.31],[1,110,3.6],[2,1.01,0.51]],"ltp":3.8,"tv":32.93,"id":13117502}]}]}
{"op":"mcm","clk":"1001553441","pt":1580637873791,"mc":[{"id":"1.168215938","rc":[{"batb":[[0,5,31.59],[1,1.01,0.51],[2,1.01,0]],"ltp":5.0,"tv":105.34,"id":13117455},{"batb":[[0,1.01,0.51],[1,5.1,0],[2,1.01,0]],"ltp":5.1,"tv":23.45,"id":13117503},{"batb":[[0,1.01,0.51],[1,110,0],[2,1.01,0]],"ltp":3.8,"tv":32.93,"id":13117502}]}]}
{"op":"mcm","clk":"1001553724","pt":1580637876805,"mc":[{"id":"1.168215938","rc":[{"batb":[[0,5.1,50.06],[1,5,31.59],[2,1.01,0.51]],"ltp":5.0,"tv":105.34,"id":13117455},{"batb":[[0,5.5,35.47],[1,5.4,27.32],[2,1.01,0.51]],"ltp":5.1,"tv":23.45,"id":13117503}]}]}
{"op":"mcm","clk":"1001553903","pt":1580637878886,"mc":[{"id":"1.168215938","rc":[{"batb":[[2,4.7,10.92]],"batl":[[0,5.5,9.24]],"ltp":5.0,"tv":105.34,"id":13117455},{"batb":[[2,5.3,9.24]],"batl":[[0,6.4,7.56]],"ltp":5.1,"tv":23.45,"id":13117503},{"batb":[[0,1.54,163.26]],"batl":[[0,1.65,42.01]],"ltp":2.92,"tv":276.24,"id":13117454}]}]}
{"op":"mcm","clk":"1001555735","pt":1580637899682,"mc":[{"id":"1.168215938","rc":[{"batb":[[0,5.1,23.3],[2,1.01,0.51]],"ltp":5.0,"tv":105.34,"id":13117455},{"batb":[[0,1.01,0.51],[1,5.4,0],[2,5.3,0]],"ltp":5.1,"tv":23.45,"id":13117503},{"batb":[[0,1.01,0.51],[1,1.53,0],[2,1.01,0]],"ltp":2.92,"tv":276.24,"id":13117454}]}]}
{"op":"mcm","clk":"1001556220","pt":1580637904471,"mc":[{"id":"1.168215938","rc":[{"batb":[[0,5.1,44.67]],"ltp":5.0,"tv":105.34,"id":13117455},{"batb":[[0,5.5,23.91],[1,5.4,27.5],[2,1.01,0.51]],"ltp":5.1,"tv":23.45,"id":13117503},{"batb":[[0,1.54,132.1],[1,1.53,83.67],[2,1.01,0.51]],"ltp":2.92,"tv":276.24,"id":13117454}]}]}
{"op":"mcm","clk":"1001556406","pt":1580637906652,"mc":[{"id":"1.168215938","rc":[{"batb":[[0,5.1,23.3]],"ltp":5.0,"tv":105.34,"id":13117455},{"batb":[[0,1.01,0.51],[1,5.4,0],[2,1.01,0]],"ltp":5.1,"tv":23.45,"id":13117503},{"batb":[[0,1.01,0.51],[1,1.53,0],[2,1.01,0]],"ltp":2.92,"tv":276.24,"id":13117454}]}]}
{"op":"mcm","clk":"1001556699","pt":1580637909698,"mc":[{"id":"1.168215938","rc":[{"batb":[[0,5.3,33.86],[1,5.2,29.79],[2,1.01,0.51]],"ltp":5.1,"tv":23.45,"id":13117503},{"batb":[[0,1.52,147.04],[1,1.51,88.68],[2,1.01,0.51]],"ltp":2.92,"tv":276.24,"id":13117454}]}]}
{"op":"mcm","clk":"1001556863","pt":1580637911580,"mc":[{"id":"1.168215938","rc":[{"batb":[[0,1.01,0.51],[1,1.51,0],[2,1.01,0]],"ltp":2.92,"tv":276.24,"id":13117454}]}]}
{"op":"mcm","clk":"1001557073","pt":1580637914580,"mc":[{"id":"1.168215938","rc":[{"batb":[[0,1.57,75.54],[1,1.56,77.37],[2,1.01,0.51]],"ltp":2.92,"tv":276.24,"id":13117454}]}]}
{"op":"mcm","clk":"1001557252","pt":1580637916665,"mc":[{"id":"1.168215938","rc":[{"batb":[[2,4.6,10.92]],"batl":[[0,5.4,9.24]],"ltp":5.0,"tv":105.34,"id":13117455},{"batb":[[2,5.1,10.08]],"batl":[[0,6.2,7.56]],"ltp":5.1,"tv":23.45,"id":13117503},{"batb":[[1,1.56,152.15]],"batl":[[0,1.68,42.01]],"ltp":2.92,"tv":276.24,"id":13117454}]}]}
{"op":"mcm","clk":"1001558504","pt":1580637931937,"mc":[{"id":"1.168215938","rc":[{"batb":[[0,5,31.59],[1,4.6,10.92],[2,1.01,0.51]],"ltp":5.0,"tv":105.34,"id":13117455},{"batb":[[0,5.1,10.08],[1,1.01,0.51],[2,5.1,0]],"ltp":5.1,"tv":23.45,"id":13117503},{"batb":[[0,1.56,74.78],[1,1.01,0.51],[2,1.01,0]],"ltp":2.92,"tv":276.24,"id":13117454}]}]}
{"op":"mcm","clk":"1001558647","pt":1580637933703,"mc":[{"id":"1.168215938","rc":[{"batb":[[1,1.01,0.51],[2,1.01,0]],"ltp":5.0,"tv":105.34,"id":13117455},{"batb":[[0,1.01,0.51],[1,1.01,0]],"ltp":5.1,"tv":23.45,"id":13117503},{"batb":[[0,1.01,0.51],[1,1.01,0]],"ltp":2.92,"tv":276.24,"id":13117454}]}]}
{"op":"mcm","clk":"1001558741","pt":1580637934905,"mc":[{"id":"1.168215938","rc":[{"batb":[[1,4.9,33.29],[2,1.01,0.51]],"ltp":5.0,"tv":105.34,"id":13117455},{"batb":[[0,5.1,38.3],[1,5,32.55],[2,1.01,0.51]],"ltp":5.1,"tv":23.45,"id":13117503},{"batb":[[0,1.55,89.95],[1,1.54,81.74],[2,1.01,0.51]],"ltp":2.92,"tv":276.24,"id":13117454},{"batb":[[0,110,3.78],[1,100,2.56],[2,1.01,0.51]],"ltp":3.8,"tv":32.93,"id":13117502}]}]}
{"op":"mcm","clk":"1001558885","pt":1580637936423,"mc":[{"id":"1.168215938","rc":[{"batb":[[1,1.01,0.51],[2,1.01,0]],"ltp":5.0,"tv":105.34,"id":13117455},{"batb":[[0,1.01,0.51],[1,5,0],[2,1.01,0]],"ltp":5.1,"tv":23.45,"id":13117503},{"batb":[[0,1.01,0.51],[1,100,0],[2,1.01,0]],"ltp":3.8,"tv":32.93,"id":13117502}]}]}
{"op":"mcm","clk":"1001559144","pt":1580637939532,"mc":[{"id":"1.168215938","rc":[{"batb":[[0,5.1,37.03],[1,5,31.59],[2,1.01,0.51]],"ltp":5.0,"tv":105.34,"id":13117455},{"batb":[[0,5.4,32.37],[1,5.3,28.53],[2,1.01,0.51]],"ltp":5.1,"tv":23.45,"id":13117503}]}]}
{"op":"mcm","clk":"1001559237","pt":1580637940633,"mc":[{"id":"1.168215938","rc":[{"batb":[[2,4.6,10.92]],"batl":[[0,5.4,9.24]],"ltp":5.0,"tv":105.34,"id":13117455},{"batb":[[2,5.2,9.24]],"batl":[[0,6.2,7.56]],"ltp":5.1,"tv":23.45,"id":13117503},{"batb":[[0,1.55,165.57]],"batl":[[0,1.66,42.01]],"ltp":2.92,"tv":276.24,"id":13117454}]}]}
{"op":"mcm","clk":"1001561992","pt":1580637970699,"mc":[{"id":"1.168215938","rc":[{"batb":[[0,20,14.28],[1,1.01,0.51]],"ltp":3.8,"tv":32.93,"id":13117502}]}]}
{"op":"mcm","clk":"1001563273","pt":1580637985755,"mc":[{"id":"1.168215938","rc":[{"batb":[[2,1.01,0.51]],"ltp":5.0,"tv":105.34,"id":13117455},{"batb":[[2,1.01,0.51]],"ltp":5.1,"tv":23.45,"id":13117503},{"batb":[[0,1.55,89.95]],"ltp":2.92,"tv":276.24,"id":13117454}]}]}
{"op":"mcm","clk":"1001563581","pt":1580637989932,"mc":[{"id":"1.168215938","rc":[{"batl":[[0,14.5,203.55]],"ltp":5.0,"tv":105.34,"id":13117455},{"batl":[[0,13.5,217.36]],"ltp":5.1,"tv":23.45,"id":13117503},{"batl":[[0,2,82.75]],"ltp":2.92,"tv":276.24,"id":13117454}]}]}
{"op":"mcm","clk":"1001578769","pt":1580638165790,"mc":[{"id":"1.168215938","rc":[{"batb":[[0,5.3,28.53],[1,1.01,0.51],[2,1.01,0]],"ltp":5.1,"tv":23.45,"id":13117503}]}]}
{"op":"mcm","clk":"1001578981","pt":1580638168514,"mc":[{"id":"1.168215938","rc":[{"batb":[[0,5.1,44.8]],"ltp":5.0,"tv":105.34,"id":13117455},{"batb":[[0,5.3,44.17],[1,5.2,29.34],[2,1.01,0.51]],"ltp":5.1,"tv":23.45,"id":13117503}]}]}
{"op":"mcm","clk":"1001589093","pt":1580638278802,"mc":[{"id":"1.168215938","rc":[{"batb":[[0,1.01,0.51],[1,5,0],[2,1.01,0]],"ltp":5.0,"tv":105.34,"id":13117455},{"batb":[[0,1.01,0.51],[1,5.2,0],[2,1.01,0]],"ltp":5.1,"tv":23.45,"id":13117503},{"batb":[[0,1.01,0.51],[1,1.54,0],[2,1.01,0]],"ltp":2.92,"tv":276.24,"id":13117454}]}]}
{"op":"mcm","clk":"1001589312","pt":1580638281400,"mc":[{"id":"1.168215938","rc":[{"batb":[[0,4.7,54.18],[1,4.6,38.03],[2,1.01,0.51]],"ltp":5.0,"tv":105.34,"id":13117455},{"batb":[[0,4.9,42.48],[1,4.8,35.21],[2,1.01,0.51]],"ltp":5.1,"tv":23.45,"id":13117503},{"batb":[[0,1.44,133.32],[1,1.43,110.69],[2,1.01,0.51]],"ltp":2.92,"tv":276.24,"id":13117454}]}]}
{"op":"mcm","clk":"1001589480","pt":1580638282969,"mc":[{"id":"1.168215938","rc":[{"batb":[[0,1.01,0.51],[1,1.43,0],[2,1.01,0]],"ltp":2.92,"tv":276.24,"id":13117454}]}]}
{"op":"mcm","clk":"1001590042","pt":1580638286797,"mc":[{"id":"1.168215938","rc":[{"batb":[[2,4.4,11.76]],"batl":[[0,5.1,10.08]],"ltp":5.0,"tv":105.34,"id":13117455},{"batb":[[0,4.9,52.56]],"batl":[[0,5.9,8.4]],"ltp":5.1,"tv":23.45,"id":13117503},{"batb":[[0,1.63,83.97],[1,1.62,67.03],[2,1.6,69.74]],"batl":[[0,1.72,42.01]],"ltp":2.92,"tv":276.24,"id":13117454}]}]}
{"op":"mcm","clk":"1001590777","pt":1580638294695,"mc":[{"id":"1.168215938","rc":[{"batb":[[0,4.4,11.76],[1,1.01,0.51],[2,4.4,0]],"ltp":5.0,"tv":105.34,"id":13117455},{"batb":[[0,4.9,10.08],[1,1.01,0.51],[2,1.01,0]],"ltp":5.1,"tv":23.45,"id":13117503},{"batb":[[0,1.6,69.74],[1,1.01,0.51],[2,1.6,0]],"ltp":2.92,"tv":276.24,"id":13117454}]}]}
{"op":"mcm","clk":"1001590891","pt":1580638295888,"mc":[{"id":"1.168215938","rc":[{"batb":[[0,1.01,0.51],[1,1.01,0]],"ltp":5.0,"tv":105.34,"id":13117455},{"batb":[[0,1.01,0.51],[1,1.01,0]],"ltp":5.1,"tv":23.45,"id":13117503},{"batb":[[0,1.01,0.51],[1,1.01,0]],"ltp":2.92,"tv":276.24,"id":13117454}]}]}
{"op":"mcm","clk":"1001591418","pt":1580638301897,"mc":[{"id":"1.168215938","rc":[{"batb":[[0,4.8,50.46],[1,4.7,36.25],[2,1.01,0.51]],"ltp":5.0,"tv":105.34,"id":13117455},{"batb":[[0,5,43.3],[1,4.9,33.58],[2,1.01,0.51]],"ltp":5.1,"tv":23.45,"id":13117503},{"batb":[[0,1.61,77.89],[1,1.6,70.16],[2,1.01,0.51]],"ltp":2.92,"tv":276.24,"id":13117454}]}]}
{"op":"mcm","clk":"1001591500","pt":1580638302842,"mc":[{"id":"1.168215938","rc":[{"batb":[[0,1.01,0.51],[1,4.7,0],[2,1.01,0]],"ltp":5.0,"tv":105.34,"id":13117455},{"batb":[[0,1.01,0.51],[1,4.9,0],[2,1.01,0]],"ltp":5.1,"tv":23.45,"id":13117503},{"batb":[[0,1.01,0.51],[1,1.6,0],[2,1.01,0]],"ltp":2.92,"tv":276.24,"id":13117454}]}]}
{"op":"mcm","clk":"1001592021","pt":1580638305843,"mc":[{"id":"1.168215938","rc":[{"batb":[[0,4.5,30.77],[1,4.4,42.54],[2,1.01,0.51]],"ltp":5.0,"tv":105.34,"id":13117455},{"batb":[[0,4.6,47.04],[1,4.5,40.73],[2,1.01,0.51]],"ltp":5.1,"tv":23.45,"id":13117503},{"batb":[[0,1.53,89.67],[1,1.52,85.51],[2,1.01,0.51]],"ltp":2.92,"tv":276.24,"id":13117454}]}]}
{"op":"mcm","clk":"1001592240","pt":1580638307600,"mc":[{"id":"1.168215938","rc":[{"batb":[[0,1.01,0.51],[1,4.4,0],[2,1.01,0]],"ltp":5.0,"tv":105.34,"id":13117455},{"batb":[[0,1.01,0.51],[1,4.5,0],[2,1.01,0]],"ltp":5.1,"tv":23.45,"id":13117503}]}]}
{"op":"mcm","clk":"1001592662","pt":1580638310942,"mc":[{"id":"1.168215938","rc":[{"batb":[[0,5.3,20.62],[1,5.2,29.23],[2,4.7,10.92]],"batl":[[0,5.6,8.4]],"ltp":5.0,"tv":105.34,"id":13117455},{"batb":[[0,5.5,31.51],[1,5.4,27.13],[2,5.3,9.24]],"batl":[[0,6.4,7.56]],"ltp":5.1,"tv":23.45,"id":13117503},{"batb":[[0,1.53,168.65]],"batl":[[0,1.64,42.01]],"ltp":2.92,"tv":276.24,"id":13117454}]}]}
{"op":"mcm","clk":"1001594087","pt":1580638322576,"mc":[{"id":"1.168215938","rc":[{"batb":[[0,4.7,10.92],[1,1.01,0.51],[2,4.7,0]],"ltp":5.0,"tv":105.34,"id":13117455},{"batb":[[0,5.3,9.24],[1,1.01,0.51],[2,5.3,0]],"ltp":5.1,"tv":23.45,"id":13117503},{"batb":[[0,1.53,78.98],[1,1.01,0.51],[2,1.01,0]],"ltp":2.92,"tv":276.24,"id":13117454}]}]}
{"op":"mcm","clk":"1001594261","pt":1580638323879,"mc":[{"id":"1.168215938","rc":[{"batb":[[0,1.01,0.51],[1,1.01,0]],"ltp":5.0,"tv":105.34,"id":13117455},{"batb":[[0,1.01,0.51],[1,1.01,0]],"ltp":5.1,"tv":23.45,"id":13117503},{"batb":[[0,1.01,0.51],[1,1.01,0]],"ltp":2.92,"tv":276.24,"id":13117454}]}]}
{"op":"mcm","clk":"1001594413","pt":1580638325180,"mc":[{"id":"1.168215938","rc":[{"batb":[[0,4.8,22.94],[1,4.7,36.7],[2,1.01,0.51]],"ltp":5.0,"tv":105.34,"id":13117455},{"batb":[[0,5,27.06],[1,4.9,33.83],[2,1.01,0.51]],"ltp":5.1,"tv":23.45,"id":13117503},{"batb":[[0,1.4,141.57],[1,1.39,125.89],[2,1.01,0.51]],"ltp":2.92,"tv":276.24,"id":13117454}]}]}
{"op":"mcm","clk":"1001594612","pt":1580638326600,"mc":[{"id":"1.168215938","rc":[{"batb":[[0,1.01,0.51],[1,1.39,0],[2,1.01,0]],"ltp":2.92,"tv":276.24,"id":13117454}]}]}
{"op":"mcm","clk":"1001594968","pt":1580638329651,"mc":[{"id":"1.168215938","rc":[{"batb":[[0,1.62,100.22],[1,1.61,68.63],[2,1.01,0.51]],"ltp":2.92,"tv":276.24,"id":13117454}]}]}
{"op":"mcm","clk":"1001595085","pt":1580638330861,"mc":[{"id":"1.168215938","rc":[{"batb":[[2,4.4,11.76]],"batl":[[0,5.1,10.08]],"ltp":5.0,"tv":105.34,"id":13117455},{"batb":[[0,5,37.14]],"batl":[[0,6,8.4]],"ltp":5.1,"tv":23.45,"id":13117503},{"batb":[[2,1.59,70.58]],"batl":[[0,1.71,42.01]],"ltp":2.92,"tv":276.24,"id":13117454}]}]}
{"op":"mcm","clk":"1001595905","pt":1580638337867,"mc":[{"id":"1.168215938","rc":[{"batb":[[0,1.01,0.51],[1,4.7,0],[2,4.4,0]],"ltp":5.0,"tv":105.34,"id":13117455},{"batb":[[0,1.01,0.51],[1,4.9,0],[2,1.01,0]],"ltp":5.1,"tv":23.45,"id":13117503},{"batb":[[0,1.01,0.51],[1,1.61,0],[2,1.59,0]],"ltp":2.92,"tv":276.24,"id":13117454}]}]}
{"op":"mcm","clk":"1001596590","pt":1580638343679,"mc":[{"id":"1.168215938","rc":[{"batb":[[0,4.9,27.31],[1,4.8,34.91],[2,1.01,0.51]],"ltp":5.0,"tv":105.34,"id":13117455},{"batb":[[0,5.1,34.55],[1,5,32.21],[2,1.01,0.51]],"ltp":5.1,"tv":23.45,"id":13117503},{"batb":[[0,1.6,71.43],[1,1.59,71.79],[2,1.01,0.51]],"ltp":2.92,"tv":276.24,"id":13117454}]}]}
{"op":"mcm","clk":"1001597130","pt":1580638347683,"mc":[{"id":"1.168215938","rc":[{"batb":[[0,1.01,0.51],[1,4.8,0],[2,1.01,0]],"ltp":5.0,"tv":105.34,"id":13117455},{"batb":[[0,1.01,0.51],[1,5,0],[2,1.01,0]],"ltp":5.1,"tv":23.45,"id":13117503},{"batb":[[0,1.01,0.51],[1,1.59,0],[2,1.01,0]],"ltp":2.92,"tv":276.24,"id":13117454}]}]}
{"op":"mcm","clk":"1001597546","pt":1580638350713,"mc":[{"id":"1.168215938","rc":[{"batb":[[0,4.4,58.93],[1,4.3,44.38],[2,1.01,0.51]],"ltp":5.0,"tv":105.34,"id":13117455},{"batb":[[0,4.6,48.73],[1,4.5,40.7],[2,1.01,0.51]],"ltp":5.1,"tv":23.45,"id":13117503},{"batb":[[0,1.51,70.16],[1,1.5,90.07],[2,1.01,0.51]],"ltp":2.92,"tv":276.24,"id":13117454}]}]}
{"op":"mcm","clk":"1001597882","pt":1580638353423,"mc":[{"id":"1.168215938","rc":[{"batb":[[0,1.01,0.51],[1,4.3,0],[2,1.01,0]],"ltp":5.0,"tv":105.34,"id":13117455},{"batb":[[0,1.01,0.51],[1,4.5,0],[2,1.01,0]],"ltp":5.1,"tv":23.45,"id":13117503},{"batb":[[0,1.01,0.51],[1,1.5,0],[2,1.01,0]],"ltp":2.92,"tv":276.24,"id":13117454}]}]}
{"op":"mcm","clk":"1001598257","pt":1580638356807,"mc":[{"id":"1.168215938","rc":[{"batb":[[0,4.4,58.93],[1,4.3,44.38],[2,4.2,12.6]],"batl":[[0,4.9,10.08]],"ltp":5.0,"tv":105.34,"id":13117455},{"batb":[[0,4.8,10.92],[1,4.6,48.73],[2,4.5,40.7]],"batl":[[0,5.7,8.4]],"ltp":5.1,"tv":23.45,"id":13117503},{"batb":[[0,1.7,94.34],[1,1.68,116.94],[2,1.64,65.54]],"batl":[[0,1.78,42.01]],"ltp":2.92,"tv":276.24,"id":13117454}]}]}
{"op":"mcm","clk":"1001599000","pt":1580638364809,"mc":[{"id":"1.168215938","rc":[{"batb":[[0,4.3,44.38],[1,4.2,12.6],[2,1.01,0.51]],"ltp":5.0,"tv":105.34,"id":13117455},{"batb":[[1,1.01,0.51],[2,4.5,0]],"ltp":5.1,"tv":23.45,"id":13117503},{"batb":[[0,1.64,65.54],[1,1.01,0.51],[2,1.64,0]],"ltp":2.92,"tv":276.24,"id":13117454}]}]}
{"op":"mcm","clk":"1001599094","pt":1580638365850,"mc":[{"id":"1.168215938","rc":[{"batb":[[1,1.01,0.51],[2,1.01,0]],"ltp":5.0,"tv":105.34,"id":13117455},{"batb":[[0,1.01,0.51],[1,1.01,0]],"ltp":5.1,"tv":23.45,"id":13117503},{"batb":[[0,1.01,0.51],[1,1.01,0]],"ltp":2.92,"tv":276.24,"id":13117454}]}]}
{"op":"mcm","clk":"1001599252","pt":1580638367465,"mc":[{"id":"1.168215938","rc":[{"batb":[[1,4.2,47.23],[2,1.01,0.51]],"ltp":5.0,"tv":105.34,"id":13117455},{"batb":[[0,4.4,58.9],[1,4.3,45.07],[2,1.01,0.51]],"ltp":5.1,"tv":23.45,"id":13117503},{"batb":[[0,1.63,83.55],[1,1.62,67.02],[2,1.01,0.51]],"ltp":2.92,"tv":276.24,"id":13117454}]}]}
{"op":"mcm","clk":"1001599367","pt":1580638368571,"mc":[{"id":"1.168215938","rc":[{"batb":[[0,1.01,0.51],[1,1.62,0],[2,1.01,0]],"ltp":2.92,"tv":276.24,"id":13117454}]}]}
{"op":"mcm","clk":"1001599670","pt":1580638371869,"mc":[{"id":"1.168215938","rc":[{"batb":[[0,1.75,76.74],[1,1.73,105.56],[2,1.01,0.51]],"ltp":2.92,"tv":276.24,"id":13117454}]}]}
{"op":"mcm","clk":"1001599758","pt":1580638372861,"mc":[{"id":"1.168215938","rc":[{"batb":[[2,4.1,13.44]],"batl":[[0,4.8,10.92]],"ltp":5.0,"tv":105.34,"id":13117455},{"batb":[[0,4.6,10.92],[1,4.4,58.9],[2,4.3,45.07]],"batl":[[0,5.5,9.24]],"ltp":5.1,"tv":23.45,"id":13117503},{"batb":[[2,1.67,62.17]],"batl":[[0,1.81,42.01]],"ltp":2.92,"tv":276.24,"id":13117454}]}]}
{"op":"mcm","clk":"1001602782","pt":1580638402891,"mc":[{"id":"1.168215938","rc":[{"batb":[[1,4.4,43.43],[2,1.01,0.51]],"ltp":5.1,"tv":23.45,"id":13117503},{"trd":[[1.73,146.52],[1.75,153.48]],"batb":[[0,1.67,62.17],[1,1.01,0.51],[2,1.67,0]],"ltp":1.73,"tv":576.24,"id":13117454}],"tv":737.97}]}
{"op":"mcm","clk":"1001603041","pt":1580638405798,"mc":[{"id":"1.168215938","rc":[{"batb":[[1,4.5,23.39],[2,4.4,43.43]],"ltp":5.1,"tv":23.45,"id":13117503},{"batb":[[0,1.74,99.98],[1,1.72,107.85],[2,1.67,62.17]],"ltp":1.73,"tv":576.24,"id":13117454}]}]}
{"op":"mcm","clk":"1001603090","pt":1580638406314,"mc":[{"id":"1.168215938","rc":[{"batl":[[0,5.4,564.54],[1,5.5,9.24]],"ltp":5.1,"tv":23.45,"id":13117503}]}]}
{"op":"mcm","clk":"1001603366","pt":1580638408803,"mc":[{"id":"1.168215938","rc":[{"batb":[[0,4.1,13.44],[1,1.01,0.51],[2,4.1,0]],"ltp":5.0,"tv":105.34,"id":13117455},{"batb":[[1,1.01,0.51],[2,4.4,0]],"batl":[[0,5.5,9.24],[1,5.5,0]],"ltp":5.1,"tv":23.45,"id":13117503},{"batb":[[0,1.67,62.17],[1,1.01,0.51],[2,1.67,0]],"ltp":1.73,"tv":576.24,"id":13117454}]}]}
{"op":"mcm","clk":"1001603459","pt":1580638409893,"mc":[{"id":"1.168215938","rc":[{"batb":[[0,1.01,0.51],[1,1.01,0]],"ltp":5.0,"tv":105.34,"id":13117455},{"batb":[[0,1.01,0.51],[1,1.01,0]],"ltp":5.1,"tv":23.45,"id":13117503},{"batb":[[0,1.01,0.51],[1,1.01,0]],"ltp":1.73,"tv":576.24,"id":13117454}]}]}
{"op":"mcm","clk":"1001603622","pt":1580638411569,"mc":[{"id":"1.168215938","rc":[{"batb":[[0,3.85,54.27],[1,3.8,30.24],[2,1.01,0.51]],"ltp":5.0,"tv":105.34,"id":13117455},{"batb":[[0,3.95,44.4],[1,3.9,28.9],[2,1.01,0.51]],"ltp":5.1,"tv":23.45,"id":13117503},{"batb":[[0,1.66,121.77],[1,1.65,62.86],[2,1.01,0.51]],"ltp":1.73,"tv":576.24,"id":13117454}]}]}
{"op":"mcm","clk":"1001604176","pt":1580638416834,"mc":[{"id":"1.168215938","rc":[{"batb":[[0,1.01,0.51],[1,1.65,0],[2,1.01,0]],"ltp":1.73,"tv":576.24,"id":13117454}]}]}
{"op":"mcm","clk":"1001604539","pt":1580638419909,"mc":[{"id":"1.168215938","rc":[{"batb":[[0,1.93,62.12],[1,1.91,76.4],[2,1.01,0.51]],"ltp":1.73,"tv":576.24,"id":13117454}]}]}
{"op":"mcm","clk":"1001604665","pt":1580638420920,"mc":[{"id":"1.168215938","rc":[{"batb":[[2,3.75,15.12]],"batl":[[0,4.3,12.6]],"ltp":5.0,"tv":105.34,"id":13117455},{"batb":[[0,4.2,12.6],[1,3.95,44.4],[2,3.9,28.9]],"batl":[[0,4.9,10.08]],"ltp":5.1,"tv":23.45,"id":13117503},{"batb":[[2,1.81,51.25]],"batl":[[0,1.98,42.01]],"ltp":1.73,"tv":576.24,"id":13117454}]}]}
{"op":"mcm","clk":"1001605101","pt":1580638425244,"mc":[{"id":"1.168215938","rc":[{"batb":[[2,1.01,0.51]],"ltp":5.0,"tv":105.34,"id":13117455},{"batb":[[0,3.95,44.4],[1,3.9,28.9],[2,1.01,0.51]],"ltp":5.1,"tv":23.45,"id":13117503},{"batb":[[2,1.01,0.51]],"ltp":1.73,"tv":576.24,"id":13117454}]}]}
{"op":"mcm","clk":"1001605476","pt":1580638428852,"mc":[{"id":"1.168215938","rc":[{"batb":[[2,3.7,15.12]],"batl":[[0,4.2,12.6]],"ltp":5.0,"tv":105.34,"id":13117455},{"batb":[[0,4.1,13.44],[1,3.95,44.4],[2,3.9,28.9]],"batl":[[0,4.8,10.92]],"ltp":5.1,"tv":23.45,"id":13117503},{"batb":[[2,1.83,50.41]],"ltp":1.73,"tv":576.24,"id":13117454}]}]}
{"op":"mcm","clk":"1001605797","pt":1580638431941,"mc":[{"id":"1.168215938","rc":[{"batl":[[0,4.7,671.4],[1,4.8,10.92]],"ltp":5.1,"tv":23.45,"id":13117503}]}]}
{"op":"mcm","clk":"1001605816","pt":1580638432047,"mc":[{"id":"1.168215938","rc":[{"batb":[[0,3.7,15.12],[1,1.01,0.51],[2,3.7,0]],"ltp":5.0,"tv":105.34,"id":13117455},{"batb":[[1,1.01,0.51],[2,3.9,0]],"batl":[[0,4.8,10.92],[1,4.8,0]],"ltp":5.1,"tv":23.45,"id":13117503},{"batb":[[0,1.83,50.41],[1,1.01,0.51],[2,1.83,0]],"ltp":1.73,"tv":576.24,"id":13117454}]}]}
{"op":"mcm","clk":"1001606028","pt":1580638433962,"mc":[{"id":"1.168215938","rc":[{"batb":[[0,1.01,0.51],[1,1.01,0]],"ltp":5.0,"tv":105.34,"id":13117455},{"batb":[[0,1.01,0.51],[1,1.01,0]],"ltp":5.1,"tv":23.45,"id":13117503},{"batb":[[0,1.01,0.51],[1,1.01,0]],"ltp":1.73,"tv":576.24,"id":13117454}]}]}
{"op":"mcm","clk":"1001606131","pt":1580638434947,"mc":[{"id":"1.168215938","rc":[{"batb":[[0,3.35,43.35],[1,3.3,42.69],[2,1.01,0.51]],"ltp":5.0,"tv":105.34,"id":13117455},{"batb":[[0,3.4,50.22],[1,3.35,41.59],[2,1.01,0.51]],"ltp":5.1,"tv":23.45,"id":13117503},{"batb":[[0,1.79,70.53],[1,1.77,97.78],[2,1.01,0.51]],"ltp":1.73,"tv":576.24,"id":13117454}]}]}
{"op":"mcm","clk":"1001606397","pt":1580638437729,"mc":[{"id":"1.168215938","rc":[{"batb":[[0,1.01,0.51],[1,3.3,0],[2,1.01,0]],"ltp":5.0,"tv":105.34,"id":13117455},{"batb":[[0,1.01,0.51],[1,3.35,0],[2,1.01,0]],"ltp":5.1,"tv":23.45,"id":13117503}]}]}
{"op":"mcm","clk":"1001606722","pt":1580638440856,"mc":[{"id":"1.168215938","rc":[{"batb":[[0,4.2,42.01],[1,4.1,50.07],[2,3.95,13.44]],"batl":[[0,4.6,10.92]],"ltp":5.0,"tv":105.34,"id":13117455},{"batb":[[0,4.4,11.76],[1,4.3,42.63],[2,4.2,48.01]],"batl":[[0,5.2,9.24]],"ltp":5.1,"tv":23.45,"id":13117503},{"batb":[[2,1.74,56.29]],"batl":[[0,1.87,42.01]],"ltp":1.73,"tv":576.24,"id":13117454}]}]}
{"op":"mcm","clk":"1001607971","pt":1580638451885,"mc":[{"id":"1.168215938","rc":[{"batb":[[0,1.01,0.51],[1,4.1,0],[2,3.95,0]],"ltp":5.0,"tv":105.34,"id":13117455},{"batb":[[0,1.01,0.51],[1,4.3,0],[2,4.2,0]],"ltp":5.1,"tv":23.45,"id":13117503},{"batb":[[0,1.01,0.51],[1,1.77,0],[2,1.74,0]],"ltp":1.73,"tv":576.24,"id":13117454}]}]}
{"op":"mcm","clk":"1001608288","pt":1580638454613,"mc":[{"id":"1.168215938","rc":[{"batb":[[0,1.68,107.16],[1,1.67,60.17],[2,1.01,0.51]],"ltp":1.73,"tv":576.24,"id":13117454}]}]}
{"op":"mcm","clk":"1001608570","pt":1580638456960,"mc":[{"id":"1.168215938","rc":[{"batb":[[0,4.5,54.85],[1,4.4,42.27],[2,1.01,0.51]],"ltp":5.0,"tv":105.34,"id":13117455},{"batb":[[0,4.7,25.43],[1,4.6,39.2],[2,1.01,0.51]],"ltp":5.1,"tv":23.45,"id":13117503}]}]}
{"op":"mcm","clk":"1001608804","pt":1580638458893,"mc":[{"id":"1.168215938","rc":[{"batb":[[2,4.2,12.6]],"batl":[[0,4.9,10.08]],"ltp":5.0,"tv":105.34,"id":13117455},{"batb":[[0,4.7,36.35]],"batl":[[0,5.6,8.4]],"ltp":5.1,"tv":23.45,"id":13117503},{"batb":[[2,1.65,63.85]],"batl":[[0,1.78,42.01]],"ltp":1.73,"tv":576.24,"id":13117454}]}]}
{"op":"mcm","clk":"1001610013","pt":1580638469943,"mc":[{"id":"1.168215938","rc":[{"batb":[[0,1.01,0.51],[1,4.4,0],[2,4.2,0]],"ltp":5.0,"tv":105.34,"id":13117455},{"batb":[[0,1.01,0.51],[1,4.6,0],[2,1.01,0]],"ltp":5.1,"tv":23.45,"id":13117503},{"batb":[[0,1.01,0.51],[1,1.67,0],[2,1.65,0]],"ltp":1.73,"tv":576.24,"id":13117454}]}]}
{"op":"mcm","clk":"1001610308","pt":1580638472841,"mc":[{"id":"1.168215938","rc":[{"batb":[[0,1.62,66.28],[1,1.61,68.58],[2,1.01,0.51]],"ltp":1.73,"tv":576.24,"id":13117454}]}]}
{"op":"mcm","clk":"1001610700","pt":1580638475953,"mc":[{"id":"1.168215938","rc":[{"batb":[[0,4.8,38.74],[1,4.7,36.55],[2,1.01,0.51]],"ltp":5.0,"tv":105.34,"id":13117455},{"batb":[[0,5,28.17],[1,4.9,33.92],[2,1.01,0.51]],"ltp":5.1,"tv":23.45,"id":13117503}]}]}
{"op":"mcm","clk":"1001610829","pt":1580638477164,"mc":[{"id":"1.168215938","rc":[{"batb":[[2,4.4,11.76]],"batl":[[0,5.2,9.24]],"ltp":5.0,"tv":105.34,"id":13117455},{"batb":[[1,4.9,44]],"batl":[[0,5.9,8.4]],"ltp":5.1,"tv":23.45,"id":13117503},{"batb":[[2,1.6,69.74]],"batl":[[0,1.72,42.01]],"ltp":1.73,"tv":576.24,"id":13117454}]}]}
{"op":"mcm","clk":"1001611698","pt":1580638484258,"mc":[{"id":"1.168215938","rc":[{"batb":[[0,4.4,11.76],[1,1.01,0.51],[2,4.4,0]],"ltp":5.0,"tv":105.34,"id":13117455},{"batb":[[0,4.9,10.08],[1,1.01,0.51],[2,1.01,0]],"ltp":5.1,"tv":23.45,"id":13117503},{"batb":[[0,1.6,69.74],[1,1.01,0.51],[2,1.6,0]],"ltp":1.73,"tv":576.24,"id":13117454}]}]}
{"op":"mcm","clk":"1001611981","pt":1580638486964,"mc":[{"id":"1.168215938","rc":[{"batb":[[0,1.01,0.51],[1,1.01,0]],"ltp":5.0,"tv":105.34,"id":13117455},{"batb":[[0,1.01,0.51],[1,1.01,0]],"ltp":5.1,"tv":23.45,"id":13117503},{"batb":[[0,1.01,0.51],[1,1.01,0]],"ltp":1.73,"tv":576.24,"id":13117454}]}]}
{"op":"mcm","clk":"1001612028","pt":1580638487330,"mc":[{"id":"1.168215938","rc":[{"batb":[[0,1.58,134.64],[1,1.57,75.64],[2,1.01,0.51]],"ltp":1.73,"tv":576.24,"id":13117454}]}]}
{"op":"mcm","clk":"1001612446","pt":1580638490866,"mc":[{"id":"1.168215938","rc":[{"batb":[[0,4.9,46.34],[1,4.8,34.7],[2,4.5,11.76]],"batl":[[0,5.3,9.24]],"ltp":5.0,"tv":105.34,"id":13117455},{"batb":[[0,5.2,23.22],[1,5.1,41.14],[2,1.01,0.51]],"batl":[[0,6.2,7.56]],"ltp":5.1,"tv":23.45,"id":13117503},{"batb":[[1,1.57,148.74]],"batl":[[0,1.69,42.01]],"ltp":1.73,"tv":576.24,"id":13117454}]}]}
{"op":"mcm","clk":"1001614962","pt":1580638513893,"mc":[{"id":"1.168215938","rc":[{"batb":[[0,1.01,0.51],[1,4.8,0],[2,4.5,0]],"ltp":5.0,"tv":105.34,"id":13117455},{"batb":[[0,1.01,0.51],[1,5.1,0],[2,1.01,0]],"ltp":5.1,"tv":23.45,"id":13117503},{"batb":[[0,1.01,0.51],[1,1.57,0],[2,1.01,0]],"ltp":1.73,"tv":576.24,"id":13117454}]}]}
{"op":"mcm","clk":"1001615289","pt":1580638516771,"mc":[{"id":"1.168215938","rc":[{"batb":[[0,4.6,21.92],[1,4.5,40.65],[2,1.01,0.51]],"ltp":5.0,"tv":105.34,"id":13117455},{"batb":[[0,4.8,21.24],[1,4.7,37.37],[2,1.01,0.51]],"ltp":5.1,"tv":23.45,"id":13117503},{"batb":[[0,1.46,138.52],[1,1.45,104.38],[2,1.01,0.51]],"ltp":1.73,"tv":576.24,"id":13117454}]}]}
{"op":"mcm","clk":"1001616528","pt":1580638528795,"mc":[{"id":"1.168215938","rc":[{"batb":[[0,1.01,0.51],[1,1.45,0],[2,1.01,0]],"ltp":1.73,"tv":576.24,"id":13117454}]}]}
{"op":"mcm","clk":"1001616863","pt":1580638531930,"mc":[{"id":"1.168215938","rc":[{"batb":[[0,1.67,86.68],[1,1.66,61.4],[2,1.01,0.51]],"ltp":1.73,"tv":576.24,"id":13117454}]}]}
{"op":"mcm","clk":"1001616984","pt":1580638532920,"mc":[{"id":"1.168215938","rc":[{"batb":[[2,4.2,12.6]],"batl":[[0,4.9,10.08]],"ltp":5.0,"tv":105.34,"id":13117455},{"batb":[[0,4.8,32.16]],"batl":[[0,5.8,8.4]],"ltp":5.1,"tv":23.45,"id":13117503},{"batb":[[2,1.63,66.38]],"batl":[[0,1.76,42.01]],"ltp":1.73,"tv":576.24,"id":13117454}]}]}
{"op":"mcm","clk":"1001617589","pt":1580638537946,"mc":[{"id":"1.168215938","rc":[{"batb":[[0,4.8,10.92]],"ltp":5.1,"tv":23.45,"id":13117503}]}]}
{"op":"mcm","clk":"1001617824","pt":1580638539935,"mc":[{"id":"1.168215938","rc":[{"batb":[[1,4.7,58.2],[2,4.6,38.64]],"ltp":5.1,"tv":23.45,"id":13117503}]}]}
{"op":"mcm","clk":"1001618106","pt":1580638542817,"mc":[{"id":"1.168215938","rc":[{"batb":[[0,4.2,12.6],[1,1.01,0.51],[2,4.2,0]],"ltp":5.0,"tv":105.34,"id":13117455},{"batb":[[1,1.01,0.51],[2,4.6,0]],"ltp":5.1,"tv":23.45,"id":13117503},{"batb":[[0,1.63,66.38],[1,1.01,0.51],[2,1.63,0]],"ltp":1.73,"tv":576.24,"id":13117454}]}]}
{"op":"mcm","clk":"1001618213","pt":1580638543909,"mc":[{"id":"1.168215938","rc":[{"batb":[[0,1.01,0.51],[1,1.01,0]],"ltp":5.0,"tv":105.34,"id":13117455},{"batb":[[0,1.01,0.51],[1,1.01,0]],"ltp":5.1,"tv":23.45,"id":13117503},{"batb":[[0,1.01,0.51],[1,1.01,0]],"ltp":1.73,"tv":576.24,"id":13117454}]}]}
{"op":"mcm","clk":"1001618586","pt":1580638547556,"mc":[{"id":"1.168215938","rc":[{"batb":[[0,4.6,57.86],[1,4.5,40.06],[2,1.01,0.51]],"ltp":5.0,"tv":105.34,"id":13117455},{"batb":[[0,4.9,22.23],[1,4.8,35.61],[2,1.01,0.51]],"ltp":5.1,"tv":23.45,"id":13117503},{"batb":[[0,1.65,67.44],[1,1.64,64.08],[2,1.01,0.51]],"ltp":1.73,"tv":576.24,"id":13117454}]}]}
{"op":"mcm","clk":"1001618876","pt":1580638550422,"mc":[{"id":"1.168215938","rc":[{"batb":[[0,1.01,0.51],[1,4.5,0],[2,1.01,0]],"ltp":5.0,"tv":105.34,"id":13117455},{"batb":[[0,1.01,0.51],[1,4.8,0],[2,1.01,0]],"ltp":5.1,"tv":23.45,"id":13117503},{"batb":[[0,1.01,0.51],[1,1.64,0],[2,1.01,0]],"ltp":1.73,"tv":576.24,"id":13117454}]}]}
{"op":"mcm","clk":"1001619177","pt":1580638553444,"mc":[{"id":"1.168215938","rc":[{"batb":[[0,4.3,45.44],[1,4.2,47.25],[2,1.01,0.51]],"ltp":5.0,"tv":105.34,"id":13117455},{"batb":[[0,4.5,26.22],[1,4.4,43.34],[2,1.01,0.51]],"ltp":5.1,"tv":23.45,"id":13117503},{"batb":[[0,1.56,88.5],[1,1.55,79.25],[2,1.01,0.51]],"ltp":1.73,"tv":576.24,"id":13117454}]}]}
{"op":"mcm","clk":"1001620150","pt":1580638562772,"mc":[{"id":"1.168215938","rc":[{"batb":[[0,1.01,0.51],[1,4.2,0],[2,1.01,0]],"ltp":5.0,"tv":105.34,"id":13117455},{"batb":[[0,1.01,0.51],[1,4.4,0],[2,1.01,0]],"ltp":5.1,"tv":23.45,"id":13117503}]}]}
{"op":"mcm","clk":"1001620413","pt":1580638565544,"mc":[{"id":"1.168215938","rc":[{"batb":[[0,5.1,20.66],[1,5,32.01],[2,1.01,0.51]],"ltp":5.0,"tv":105.34,"id":13117455},{"batb":[[0,5.3,42.99],[1,5.2,29.43],[2,1.01,0.51]],"ltp":5.1,"tv":23.45,"id":13117503}]}]}
{"op":"mcm","clk":"1001620561","pt":1580638566956,"mc":[{"id":"1.168215938","rc":[{"batb":[[2,4.6,10.92]],"batl":[[0,5.4,9.24]],"ltp":5.0,"tv":105.34,"id":13117455},{"batb":[[1,5.2,38.67]],"batl":[[0,6.4,7.56]],"ltp":5.1,"tv":23.45,"id":13117503},{"batb":[[1,1.55,154.87]],"batl":[[0,1.66,42.01]],"ltp":1.73,"tv":576.24,"id":13117454}]}]}
{"op":"mcm","clk":"1001622372","pt":1580638584403,"mc":[{"id":"1.168215938","rc":[{"batb":[[0,4.6,10.92],[1,1.01,0.51],[2,4.6,0]],"ltp":5.0,"tv":105.34,"id":13117455},{"batb":[[0,5.2,9.24],[1,1.01,0.51],[2,1.01,0]],"ltp":5.1,"tv":23.45,"id":13117503},{"batb":[[0,1.55,75.62],[1,1.01,0.51],[2,1.01,0]],"ltp":1.73,"tv":576.24,"id":13117454}]}]}
{"op":"mcm","clk":"1001622512","pt":1580638585932,"mc":[{"id":"1.168215938","rc":[{"batb":[[0,1.01,0.51],[1,1.01,0]],"ltp":5.0,"tv":105.34,"id":13117455},{"batb":[[0,1.01,0.51],[1,1.01,0]],"ltp":5.1,"tv":23.45,"id":13117503},{"batb":[[0,1.01,0.51],[1,1.01,0]],"ltp":1.73,"tv":576.24,"id":13117454}]}]}
{"op":"mcm","clk":"1001622668","pt":1580638587300,"mc":[{"id":"1.168215938","rc":[{"batb":[[0,4.6,28.54],[1,4.5,40.54],[2,1.01,0.51]],"ltp":5.0,"tv":105.34,"id":13117455},{"batb":[[0,4.8,42.97],[1,4.7,37.02],[2,1.01,0.51]],"ltp":5.1,"tv":23.45,"id":13117503},{"batb":[[0,1.42,76.85],[1,1.41,117.47],[2,1.01,0.51]],"ltp":1.73,"tv":576.24,"id":13117454}]}]}
{"op":"mcm","clk":"1001623104","pt":1580638591696,"mc":[{"id":"1.168215938","rc":[{"batb":[[0,1.01,0.51],[1,1.41,0],[2,1.01,0]],"ltp":1.73,"tv":576.24,"id":13117454}]}]}
{"op":"mcm","clk":"1001623452","pt":1580638594907,"mc":[{"id":"1.168215938","rc":[{"batb":[[2,4.3,12.6]],"batl":[[0,4.9,10.08]],"ltp":5.0,"tv":105.34,"id":13117455},{"batb":[[0,4.9,10.08],[1,4.8,42.97],[2,4.7,37.02]],"batl":[[0,5.9,8.4]],"ltp":5.1,"tv":23.45,"id":13117503},{"batb":[[0,1.66,92.82],[1,1.65,62.76],[2,1.62,67.22]],"batl":[[0,1.75,42.01]],"ltp":1.73,"tv":576.24,"id":13117454}]}]}
{"op":"mcm","clk":"1001625323","pt":1580638614598,"mc":[{"id":"1.168215938","rc":[{"batb":[[0,4.3,12.6],[1,1.01,0.51],[2,4.3,0]],"ltp":5.0,"tv":105.34,"id":13117455},{"batb":[[1,1.01,0.51],[2,4.7,0]],"ltp":5.1,"tv":23.45,"id":13117503},{"batb":[[0,1.62,67.22],[1,1.01,0.51],[2,1.62,0]],"ltp":1.73,"tv":576.24,"id":13117454}]}]}
{"op":"mcm","clk":"1001625453","pt":1580638615978,"mc":[{"id":"1.168215938","rc":[{"batb":[[0,1.01,0.51],[1,1.01,0]],"ltp":5.0,"tv":105.34,"id":13117455},{"batb":[[0,1.01,0.51],[1,1.01,0]],"ltp":5.1,"tv":23.45,"id":13117503},{"batb":[[0,1.01,0.51],[1,1.01,0]],"ltp":1.73,"tv":576.24,"id":13117454}]}]}
{"op":"mcm","clk":"1001625608","pt":1580638617594,"mc":[{"id":"1.168215938","rc":[{"batb":[[0,4.3,28.65],[1,4.2,47.53],[2,1.01,0.51]],"ltp":5.0,"tv":105.34,"id":13117455},{"batb":[[0,4.5,30.01],[1,4.4,43.27],[2,1.01,0.51]],"ltp":5.1,"tv":23.45,"id":13117503},{"batb":[[0,1.53,122.42],[1,1.52,85.77],[2,1.01,0.51]],"ltp":1.73,"tv":576.24,"id":13117454}]}]}
{"op":"mcm","clk":"1001626045","pt":1580638621776,"mc":[{"id":"1.168215938","rc":[{"batb":[[0,1.01,0.51],[1,1.52,0],[2,1.01,0]],"ltp":1.73,"tv":576.24,"id":13117454}]}]}
{"op":"mcm","clk":"1001626338","pt":1580638624888,"mc":[{"id":"1.168215938","rc":[{"batb":[[2,4,13.44]],"batl":[[0,4.7,10.92]],"ltp":5.0,"tv":105.34,"id":13117455},{"batb":[[0,4.7,10.92],[1,4.5,30.01],[2,4.4,43.27]],"batl":[[0,5.5,9.24]],"ltp":5.1,"tv":23.45,"id":13117503},{"batb":[[0,1.75,72.77],[1,1.73,105.57],[2,1.67,62.17]],"batl":[[0,1.82,42.01]],"ltp":1.73,"tv":576.24,"id":13117454}]}]}
{"op":"mcm","clk":"1001627596","pt":1580638638382,"mc":[{"id":"1.168215938","rc":[{"batb":[[0,4,13.44],[1,1.01,0.51],[2,4,0]],"ltp":5.0,"tv":105.34,"id":13117455},{"batb":[[1,1.01,0.51],[2,4.4,0]],"ltp":5.1,"tv":23.45,"id":13117503},{"batb":[[0,1.67,62.17],[1,1.01,0.51],[2,1.67,0]],"ltp":1.73,"tv":576.24,"id":13117454}]}]}
{"op":"mcm","clk":"1001627743","pt":1580638640009,"mc":[{"id":"1.168215938","rc":[{"batb":[[0,1.01,0.51],[1,1.01,0]],"ltp":5.0,"tv":105.34,"id":13117455},{"batb":[[0,1.01,0.51],[1,1.01,0]],"ltp":5.1,"tv":23.45,"id":13117503},{"batb":[[0,1.01,0.51],[1,1.01,0]],"ltp":1.73,"tv":576.24,"id":13117454}]}]}
{"op":"mcm","clk":"1001628035","pt":1580638643908,"mc":[{"id":"1.168215938","rc":[{"batb":[[0,4.3,50.1],[1,4.2,47.17],[2,1.01,0.51]],"ltp":5.0,"tv":105.34,"id":13117455},{"batb":[[0,4.5,56.25],[1,4.4,42.84],[2,1.01,0.51]],"ltp":5.1,"tv":23.45,"id":13117503},{"batb":[[0,1.73,92.49],[1,1.71,109.95],[2,1.01,0.51]],"ltp":1.73,"tv":576.24,"id":13117454}]}]}
{"op":"mcm","clk":"1001628182","pt":1580638645936,"mc":[{"id":"1.168215938","rc":[{"batb":[[0,1.01,0.51],[1,4.2,0],[2,1.01,0]],"ltp":5.0,"tv":105.34,"id":13117455},{"batb":[[0,1.01,0.51],[1,4.4,0],[2,1.01,0]],"ltp":5.1,"tv":23.45,"id":13117503},{"batb":[[0,1.01,0.51],[1,1.71,0],[2,1.01,0]],"ltp":1.73,"tv":576.24,"id":13117454}]}]}
{"op":"mcm","clk":"1001628382","pt":1580638648693,"mc":[{"id":"1.168215938","rc":[{"batb":[[0,4.1,65.75],[1,4,52.64],[2,1.01,0.51]],"ltp":5.0,"tv":105.34,"id":13117455},{"batb":[[0,4.3,43.85],[1,4.2,47.98],[2,1.01,0.51]],"ltp":5.1,"tv":23.45,"id":13117503},{"batb":[[0,1.67,80.87],[1,1.66,61.38],[2,1.01,0.51]],"ltp":1.73,"tv":576.24,"id":13117454}]}]}
{"op":"mcm","clk":"1001628521","pt":1580638650819,"mc":[{"id":"1.168215938","rc":[{"batb":[[0,1.01,0.51],[1,1.66,0],[2,1.01,0]],"ltp":1.73,"tv":576.24,"id":13117454}]}]}
{"op":"mcm","clk":"1001628700","pt":1580638652942,"mc":[{"id":"1.168215938","rc":[{"batl":[[0,4.8,168.23]],"ltp":5.1,"tv":23.45,"id":13117503}]}]}
{"op":"mcm","clk":"1001628772","pt":1580638653730,"mc":[{"id":"1.168215938","rc":[{"batb":[[0,1.8,67.52],[1,1.78,95.88],[2,1.01,0.51]],"ltp":1.73,"tv":576.24,"id":13117454}]}]}
{"op":"mcm","clk":"1001628952","pt":1580638654936,"mc":[{"id":"1.168215938","rc":[{"batb":[[2,3.95,13.44]],"batl":[[0,4.6,10.92]],"ltp":5.0,"tv":105.34,"id":13117455},{"batb":[[0,4.5,11.76],[1,4.3,43.85],[2,4.2,47.98]],"batl":[[0,5.3,9.24]],"ltp":5.1,"tv":23.45,"id":13117503},{"batb":[[2,1.71,58.81]],"batl":[[0,1.85,42.01]],"ltp":1.73,"tv":576.24,"id":13117454}]}]}
{"op":"mcm","clk":"1001633271","pt":1580638694890,"mc":[{"id":"1.168215938","rc":[{"batb":[[2,1.01,0.51]],"ltp":1.73,"tv":576.24,"id":13117454}]}]}
{"op":"mcm","clk":"1001633621","pt":1580638697901,"mc":[{"id":"1.168215938","rc":[{"batb":[[0,4.3,43.85],[1,4.2,47.98],[2,1.01,0.51]],"ltp":5.1,"tv":23.45,"id":13117503},{"batb":[[2,1.73,57.13]],"ltp":1.73,"tv":576.24,"id":13117454}]}]}
{"op":"mcm","clk":"1001633873","pt":1580638700894,"mc":[{"id":"1.168215938","rc":[{"batb":[[0,4.4,11.76],[1,4.3,43.85],[2,4.2,47.98]],"ltp":5.1,"tv":23.45,"id":13117503}]}]}
{"op":"mcm","clk":"1001633911","pt":1580638701304,"mc":[{"id":"1.168215938","rc":[{"batl":[[0,5.1,603.95],[1,5.3,9.24]],"ltp":5.1,"tv":23.45,"id":13117503}]}]}
{"op":"mcm","clk":"1001636279","pt":1580638727247,"mc":[{"id":"1.168215938","rc":[{"batb":[[0,1.01,0.51],[1,1.01,0]],"ltp":3.8,"tv":32.93,"id":13117502}]}]}
{"op":"mcm","clk":"1001636445","pt":1580638729745,"mc":[{"id":"1.168215938","rc":[{"batb":[[0,3.95,13.44],[1,1.01,0.51],[2,3.95,0]],"ltp":5.0,"tv":105.34,"id":13117455},{"batb":[[1,1.01,0.51],[2,4.2,0]],"batl":[[0,5.3,9.24],[1,5.3,0]],"ltp":5.1,"tv":23.45,"id":13117503},{"batb":[[0,1.73,57.13],[1,1.01,0.51],[2,1.73,0]],"ltp":1.73,"tv":576.24,"id":13117454}]}]}
{"op":"mcm","clk":"1001636473","pt":1580638730121,"mc":[{"id":"1.168215938","rc":[{"batb":[[0,1.01,0.51],[1,1.01,0]],"ltp":5.0,"tv":105.34,"id":13117455},{"batb":[[0,1.01,0.51],[1,1.01,0]],"ltp":5.1,"tv":23.45,"id":13117503},{"batb":[[0,1.01,0.51],[1,1.01,0]],"ltp":1.73,"tv":576.24,"id":13117454}]}]}
{"op":"mcm","clk":"1001636898","pt":1580638735560,"mc":[{"id":"1.168215938","rc":[{"batb":[[0,4,66.08],[1,3.95,27.42],[2,1.01,0.51]],"ltp":5.0,"tv":105.34,"id":13117455},{"batb":[[0,4.2,35.43],[1,4.1,50.8],[2,1.01,0.51]],"ltp":5.1,"tv":23.45,"id":13117503},{"batb":[[0,1.84,70.81],[1,1.82,89.1],[2,1.01,0.51]],"ltp":1.73,"tv":576.24,"id":13117454}]}]}
{"op":"mcm","clk":"1001637024","pt":1580638737221,"mc":[{"id":"1.168215938","rc":[{"batb":[[0,1.01,0.51],[1,3.95,0],[2,1.01,0]],"ltp":5.0,"tv":105.34,"id":13117455},{"batb":[[0,1.01,0.51],[1,4.1,0],[2,1.01,0]],"ltp":5.1,"tv":23.45,"id":13117503},{"batb":[[0,1.01,0.51],[1,1.82,0],[2,1.01,0]],"ltp":1.73,"tv":576.24,"id":13117454}]}]}
{"op":"mcm","clk":"1001637247","pt":1580638740260,"mc":[{"id":"1.168215938","rc":[{"batb":[[0,3.7,43.45],[1,3.65,33.35],[2,1.01,0.51]],"ltp":5.0,"tv":105.34,"id":13117455},{"batb":[[0,3.8,39.57],[1,3.75,31.7],[2,1.01,0.51]],"ltp":5.1,"tv":23.45,"id":13117503},{"batb":[[0,1.71,96.82],[1,1.69,114.52],[2,1.01,0.51]],"ltp":1.73,"tv":576.24,"id":13117454}]}]}
{"op":"mcm","clk":"1001637814","pt":1580638746967,"mc":[{"id":"1.168215938","rc":[{"batb":[[0,1.01,0.51],[1,3.65,0],[2,1.01,0]],"ltp":5.0,"tv":105.34,"id":13117455},{"batb":[[0,1.01,0.51],[1,3.75,0],[2,1.01,0]],"ltp":5.1,"tv":23.45,"id":13117503}]}]}
{"op":"mcm","clk":"1001638071","pt":1580638749950,"mc":[{"id":"1.168215938","rc":[{"batb":[[0,4.4,38.05],[1,4.3,44.8],[2,1.01,0.51]],"ltp":5.0,"tv":105.34,"id":13117455},{"batb":[[0,4.6,38.33],[1,4.5,40.92],[2,1.01,0.51]],"ltp":5.1,"tv":23.45,"id":13117503}]}]}
{"op":"mcm","clk":"1001638181","pt":1580638751356,"mc":[{"id":"1.168215938","rc":[{"batb":[[2,4.2,12.6]],"ltp":5.0,"tv":105.34,"id":13117455},{"batl":[[0,5.5,9.24]],"ltp":5.1,"tv":23.45,"id":13117503},{"batb":[[2,1.66,63.01]],"ltp":1.73,"tv":576.24,"id":13117454}]}]}
{"op":"mcm","clk":"1001638333","pt":1580638753173,"mc":[{"id":"1.168215938","rc":[{"batl":[[0,4.8,10.92]],"ltp":5.0,"tv":105.34,"id":13117455},{"batb":[[0,4.7,10.92],[1,4.6,38.33],[2,4.5,40.92]],"ltp":5.1,"tv":23.45,"id":13117503},{"batl":[[0,1.79,42.01]],"ltp":1.73,"tv":576.24,"id":13117454}]}]}
{"op":"mcm","clk":"1001638964","pt":1580638760682,"mc":[{"id":"1.168215938","rc":[{"batb":[[0,4.2,12.6],[1,1.01,0.51],[2,4.2,0]],"ltp":5.0,"tv":105.34,"id":13117455},{"batb":[[1,1.01,0.51],[2,4.5,0]],"ltp":5.1,"tv":23.45,"id":13117503},{"batb":[[0,1.66,63.01],[1,1.01,0.51],[2,1.66,0]],"ltp":1.73,"tv":576.24,"id":13117454}]}]}
{"op":"mcm","clk":"1001639125","pt":1580638762673,"mc":[{"id":"1.168215938","rc":[{"batb":[[0,1.01,0.51],[1,1.01,0]],"ltp":5.0,"tv":105.34,"id":13117455},{"batb":[[0,1.01,0.51],[1,1.01,0]],"ltp":5.1,"tv":23.45,"id":13117503},{"batb":[[0,1.01,0.51],[1,1.01,0]],"ltp":1.73,"tv":576.24,"id":13117454},{"batb":[[0,20,15.96],[1,1.01,0.51]],"ltp":3.8,"tv":32.93,"id":13117502}]}]}
{"op":"mcm","clk":"1001639213","pt":1580638763870,"mc":[{"id":"1.168215938","rc":[{"batb":[[0,4,56.09],[1,3.95,27.51],[2,1.01,0.51]],"ltp":5.0,"tv":105.34,"id":13117455},{"batb":[[0,4.1,61.51],[1,4,53.36],[2,1.01,0.51]],"ltp":5.1,"tv":23.45,"id":13117503},{"batb":[[0,1.65,107.56],[1,1.64,64.15],[2,1.01,0.51]],"ltp":1.73,"tv":576.24,"id":13117454}]}]}
{"op":"mcm","clk":"1001639302","pt":1580638764901,"mc":[{"id":"1.168215938","rc":[{"batb":[[0,1.01,0.51],[1,3.95,0],[2,1.01,0]],"ltp":5.0,"tv":105.34,"id":13117455},{"batb":[[0,1.01,0.51],[1,4,0],[2,1.01,0]],"ltp":5.1,"tv":23.45,"id":13117503}]}]}
{"op":"mcm","clk":"1001639529","pt":1580638767613,"mc":[{"id":"1.168215938","rc":[{"batb":[[0,4.6,38.05],[1,4.5,40.33],[2,1.01,0.51]],"ltp":5.0,"tv":105.34,"id":13117455},{"batb":[[0,4.9,21.73],[1,4.8,35.57],[2,1.01,0.51]],"ltp":5.1,"tv":23.45,"id":13117503}]}]}
{"op":"mcm","clk":"1001639753","pt":1580638769919,"mc":[{"id":"1.168215938","rc":[{"batb":[[2,4.3,12.6]],"batl":[[0,5,10.08]],"ltp":5.0,"tv":105.34,"id":13117455},{"batb":[[1,4.8,46.49]],"batl":[[0,5.8,8.4]],"ltp":5.1,"tv":23.45,"id":13117503},{"batb":[[2,1.62,67.22]],"batl":[[0,1.75,42.01]],"ltp":1.73,"tv":576.24,"id":13117454}]}]}
{"op":"mcm","clk":"1001640297","pt":1580638775785,"mc":[{"id":"1.168215938","rc":[{"batb":[[0,4.3,12.6],[1,1.01,0.51],[2,4.3,0]],"ltp":5.0,"tv":105.34,"id":13117455},{"batb":[[0,4.8,10.92],[1,1.01,0.51],[2,1.01,0]],"ltp":5.1,"tv":23.45,"id":13117503},{"batb":[[0,1.62,67.22],[1,1.01,0.51],[2,1.62,0]],"ltp":1.73,"tv":576.24,"id":13117454}]}]}
{"op":"mcm","clk":"1001640320","pt":1580638776110,"mc":[{"id":"1.168215938","rc":[{"batb":[[0,1.01,0.51],[1,1.01,0]],"ltp":5.0,"tv":105.34,"id":13117455},{"batb":[[0,1.01,0.51],[1,1.01,0]],"ltp":5.1,"tv":23.45,"id":13117503},{"batb":[[0,1.01,0.51],[1,1.01,0]],"ltp":1.73,"tv":576.24,"id":13117454}]}]}
{"op":"mcm","clk":"1001641097","pt":1580638784937,"mc":[{"id":"1.168215938","rc":[{"batb":[[0,4.3,64.5],[1,4.2,46.87],[2,1.01,0.51]],"ltp":5.0,"tv":105.34,"id":13117455},{"batb":[[0,4.5,36.13],[1,4.4,43.13],[2,1.01,0.51]],"ltp":5.1,"tv":23.45,"id":13117503},{"batb":[[0,1.62,75.6],[1,1.61,68.53],[2,1.01,0.51]],"ltp":1.73,"tv":576.24,"id":13117454}]}]}
{"op":"mcm","clk":"1001641363","pt":1580638787928,"mc":[{"id":"1.168215938","rc":[{"batb":[[0,1.01,0.51],[1,1.61,0],[2,1.01,0]],"ltp":1.73,"tv":576.24,"id":13117454}]}]}
{"op":"mcm","clk":"1001641643","pt":1580638790937,"mc":[{"id":"1.168215938","rc":[{"batb":[[0,1.73,102.63],[1,1.71,109.95],[2,1.01,0.51]],"ltp":1.73,"tv":576.24,"id":13117454}]}]}
{"op":"mcm","clk":"1001641680","pt":1580638791248,"mc":[{"id":"1.168215938","rc":[{"batb":[[2,4.1,13.44]],"batl":[[0,4.8,10.92]],"ltp":5.0,"tv":105.34,"id":13117455},{"batb":[[0,4.5,47.89]],"batl":[[0,5.4,9.24]],"ltp":5.1,"tv":23.45,"id":13117503},{"batb":[[2,1.68,61.33]],"batl":[[0,1.82,42.01]],"ltp":1.73,"tv":576.24,"id":13117454}]}]}
{"op":"mcm","clk":"1001643270","pt":1580638809952,"mc":[{"id":"1.168215938","rc":[{"batb":[[0,4.1,13.44],[1,1.01,0.51],[2,4.1,0]],"ltp":5.0,"tv":105.34,"id":13117455},{"batb":[[0,4.5,11.76],[1,1.01,0.51],[2,1.01,0]],"ltp":5.1,"tv":23.45,"id":13117503},{"batb":[[0,1.68,61.33],[1,1.01,0.51],[2,1.68,0]],"ltp":1.73,"tv":576.24,"id":13117454}]}]}
{"op":"mcm","clk":"1001643299","pt":1580638810361,"mc":[{"id":"1.168215938","rc":[{"batb":[[0,1.01,0.51],[1,1.01,0]],"ltp":5.0,"tv":105.34,"id":13117455},{"batb":[[0,1.01,0.51],[1,1.01,0]],"ltp":5.1,"tv":23.45,"id":13117503},{"batb":[[0,1.01,0.51],[1,1.01,0]],"ltp":1.73,"tv":576.24,"id":13117454}]}]}
{"op":"mcm","clk":"1001643499","pt":1580638812665,"mc":[{"id":"1.168215938","rc":[{"batb":[[0,3.9,46.77],[1,3.85,29.32],[2,1.01,0.51]],"ltp":5.0,"tv":105.34,"id":13117455},{"batb":[[0,4,28.59],[1,3.95,28.12],[2,1.01,0.51]],"ltp":5.1,"tv":23.45,"id":13117503},{"batb":[[0,1.66,78.7],[1,1.65,62.68],[2,1.01,0.51]],"ltp":1.73,"tv":576.24,"id":13117454}]}]}
{"op":"mcm","clk":"1001643836","pt":1580638816964,"mc":[{"id":"1.168215938","rc":[{"batb":[[0,1.01,0.51],[1,3.85,0],[2,1.01,0]],"ltp":5.0,"tv":105.34,"id":13117455},{"batb":[[0,1.01,0.51],[1,3.95,0],[2,1.01,0]],"ltp":5.1,"tv":23.45,"id":13117503}]}]}
{"op":"mcm","clk":"1001644092","pt":1580638819874,"mc":[{"id":"1.168215938","rc":[{"batb":[[0,4.6,42.45],[1,4.5,40.26],[2,1.01,0.51]],"ltp":5.0,"tv":105.34,"id":13117455},{"batb":[[0,4.8,36.07],[1,4.7,37.08],[2,1.01,0.51]],"ltp":5.1,"tv":23.45,"id":13117503}]}]}
{"op":"mcm","clk":"1001644188","pt":1580638821283,"mc":[{"id":"1.168215938","rc":[{"batb":[[2,4.3,12.6]],"batl":[[0,5.1,10.08]],"ltp":5.0,"tv":105.34,"id":13117455},{"batb":[[0,4.8,46.99]],"batl":[[0,5.7,8.4]],"ltp":5.1,"tv":23.45,"id":13117503},{"batb":[[2,1.62,67.22]],"batl":[[0,1.75,42.01]],"ltp":1.73,"tv":576.24,"id":13117454}]}]}
{"op":"mcm","clk":"1001644947","pt":1580638830675,"mc":[{"id":"1.168215938","rc":[{"batb":[[0,4.3,12.6],[1,1.01,0.51],[2,4.3,0]],"ltp":5.0,"tv":105.34,"id":13117455},{"batb":[[0,4.8,10.92],[1,1.01,0.51],[2,1.01,0]],"ltp":5.1,"tv":23.45,"id":13117503},{"batb":[[0,1.62,67.22],[1,1.01,0.51],[2,1.62,0]],"ltp":1.73,"tv":576.24,"id":13117454}]}]}
{"op":"mcm","clk":"1001645063","pt":1580638832507,"mc":[{"id":"1.168215938","rc":[{"batb":[[0,1.01,0.51],[1,1.01,0]],"ltp":5.0,"tv":105.34,"id":13117455},{"batb":[[0,1.01,0.51],[1,1.01,0]],"ltp":5.1,"tv":23.45,"id":13117503},{"batb":[[0,1.01,0.51],[1,1.01,0]],"ltp":1.73,"tv":576.24,"id":13117454}]}]}
{"op":"mcm","clk":"1001645372","pt":1580638835916,"mc":[{"id":"1.168215938","rc":[{"batb":[[0,4.6,23.48],[1,4.5,40.58],[2,1.01,0.51]],"ltp":5.0,"tv":105.34,"id":13117455},{"batb":[[0,4.7,46.85],[1,4.6,38.77],[2,1.01,0.51]],"ltp":5.1,"tv":23.45,"id":13117503},{"batb":[[0,1.67,106.97],[1,1.66,61.41],[2,1.01,0.51]],"ltp":1.73,"tv":576.24,"id":13117454}]}]}
{"op":"mcm","clk":"1001645400","pt":1580638836190,"mc":[{"id":"1.168215938","rc":[{"batb":[[0,1.67,74.57]],"ltp":1.73,"tv":576.24,"id":13117454}]}]}
{"op":"mcm","clk":"1001645528","pt":1580638837704,"mc":[{"id":"1.168215938","rc":[{"batb":[[0,1.01,0.51],[1,4.5,0],[2,1.01,0]],"ltp":5.0,"tv":105.34,"id":13117455},{"batb":[[0,1.01,0.51],[1,4.6,0],[2,1.01,0]],"ltp":5.1,"tv":23.45,"id":13117503},{"batb":[[0,1.01,0.51],[1,1.66,0],[2,1.01,0]],"ltp":1.73,"tv":576.24,"id":13117454}]}]}
{"op":"mcm","clk":"1001645778","pt":1580638840907,"mc":[{"id":"1.168215938","rc":[{"batb":[[0,4.4,40.5],[1,4.3,44.93],[2,1.01,0.51]],"ltp":5.0,"tv":105.34,"id":13117455},{"batb":[[0,4.5,27.29],[1,4.4,43.43],[2,1.01,0.51]],"ltp":5.1,"tv":23.45,"id":13117503},{"batb":[[0,1.62,92.32],[1,1.61,68.69],[2,1.01,0.51]],"ltp":1.73,"tv":576.24,"id":13117454}]}]}
{"op":"mcm","clk":"1001645845","pt":1580638841695,"mc":[{"id":"1.168215938","rc":[{"batb":[[0,1.01,0.51],[1,4.3,0],[2,1.01,0]],"ltp":5.0,"tv":105.34,"id":13117455},{"batb":[[0,1.01,0.51],[1,4.4,0],[2,1.01,0]],"ltp":5.1,"tv":23.45,"id":13117503}]}]}
{"op":"mcm","clk":"1001646098","pt":1580638844592,"mc":[{"id":"1.168215938","rc":[{"batb":[[0,4.7,55.87],[1,4.6,38.2],[2,1.01,0.51]],"ltp":5.0,"tv":105.34,"id":13117455},{"batb":[[0,5,36.2],[1,4.9,33.85],[2,1.01,0.51]],"ltp":5.1,"tv":23.45,"id":13117503}]}]}
{"op":"mcm","clk":"1001646158","pt":1580638845319,"mc":[{"id":"1.168215938","rc":[{"batb":[[2,4.4,11.76]],"batl":[[0,5.2,9.24]],"ltp":5.0,"tv":105.34,"id":13117455},{"batb":[[1,4.9,43.93]],"batl":[[0,6,8.4]],"ltp":5.1,"tv":23.45,"id":13117503},{"batb":[[2,1.59,70.58]],"batl":[[0,1.72,42.01]],"ltp":1.73,"tv":576.24,"id":13117454}]}]}
{"op":"mcm","clk":"1001648771","pt":1580638874652,"mc":[{"id":"1.168215938","rc":[{"batb":[[0,4.4,11.76],[1,1.01,0.51],[2,4.4,0]],"ltp":5.0,"tv":105.34,"id":13117455},{"batb":[[0,4.9,10.08],[1,1.01,0.51],[2,1.01,0]],"ltp":5.1,"tv":23.45,"id":13117503},{"batb":[[0,1.59,70.58],[1,1.01,0.51],[2,1.59,0]],"ltp":1.73,"tv":576.24,"id":13117454}]}]}
{"op":"mcm","clk":"1001648970","pt":1580638876367,"mc":[{"id":"1.168215938","rc":[{"batb":[[0,1.01,0.51],[1,1.01,0]],"ltp":5.0,"tv":105.34,"id":13117455},{"batb":[[0,1.01,0.51],[1,1.01,0]],"ltp":5.1,"tv":23.45,"id":13117503},{"batb":[[0,1.01,0.51],[1,1.01,0]],"ltp":1.73,"tv":576.24,"id":13117454}]}]}
{"op":"mcm","clk":"1001649101","pt":1580638877837,"mc":[{"id":"1.168215938","rc":[{"batb":[[0,4.4,33.96],[1,4.3,45.04],[2,1.01,0.51]],"ltp":5.0,"tv":105.34,"id":13117455},{"batb":[[0,4.6,37.73],[1,4.5,41.08],[2,1.01,0.51]],"ltp":5.1,"tv":23.45,"id":13117503}]}]}
{"op":"mcm","clk":"1001649307","pt":1580638879922,"mc":[{"id":"1.168215938","rc":[{"batb":[[0,1.71,106.77],[1,1.69,114.71],[2,1.01,0.51]],"ltp":1.73,"tv":576.24,"id":13117454}]}]}
{"op":"mcm","clk":"1001649394","pt":1580638881126,"mc":[{"id":"1.168215938","rc":[{"batb":[[2,4.2,12.6]],"batl":[[0,4.8,10.92]],"ltp":5.0,"tv":105.34,"id":13117455},{"batb":[[0,4.7,10.92],[1,4.6,37.73],[2,4.5,41.08]],"batl":[[0,5.6,8.4]],"ltp":5.1,"tv":23.45,"id":13117503},{"batb":[[2,1.66,63.01]],"batl":[[0,1.8,42.01]],"ltp":1.73,"tv":576.24,"id":13117454}]}]}
{"op":"mcm","clk":"1001649971","pt":1580638888679,"mc":[{"id":"1.168215938","rc":[{"batb":[[0,4.2,12.6],[1,1.01,0.51],[2,4.2,0]],"ltp":5.0,"tv":105.34,"id":13117455},{"batb":[[1,1.01,0.51],[2,4.5,0]],"ltp":5.1,"tv":23.45,"id":13117503},{"batb":[[0,1.66,63.01],[1,1.01,0.51],[2,1.66,0]],"ltp":1.73,"tv":576.24,"id":13117454}]}]}
{"op":"mcm","clk":"1001650101","pt":1580638890146,"mc":[{"id":"1.168215938","rc":[{"batb":[[0,1.01,0.51],[1,1.01,0]],"ltp":5.0,"tv":105.34,"id":13117455},{"batb":[[0,1.01,0.51],[1,1.01,0]],"ltp":5.1,"tv":23.45,"id":13117503},{"batb":[[0,1.01,0.51],[1,1.01,0]],"ltp":1.73,"tv":576.24,"id":13117454}]}]}
{"op":"mcm","clk":"1001650285","pt":1580638891878,"mc":[{"id":"1.168215938","rc":[{"batb":[[0,4.1,67.09],[1,4,52.72],[2,1.01,0.51]],"ltp":5.0,"tv":105.34,"id":13117455},{"batb":[[0,4.3,49.65],[1,4.2,47.97],[2,1.01,0.51]],"ltp":5.1,"tv":23.45,"id":13117503},{"batb":[[0,1.59,88.26],[1,1.58,73.69],[2,1.01,0.51]],"ltp":1.73,"tv":576.24,"id":13117454}]}]}
{"op":"mcm","clk":"1001650569","pt":1580638895875,"mc":[{"id":"1.168215938","rc":[{"batb":[[0,1.01,0.51],[1,1.58,0],[2,1.01,0]],"ltp":1.73,"tv":576.24,"id":13117454}]}]}
{"op":"mcm","clk":"1001650763","pt":1580638898799,"mc":[{"id":"1.168215938","rc":[{"batb":[[0,1.8,56.19],[1,1.78,95.94],[2,1.01,0.51]],"ltp":1.73,"tv":576.24,"id":13117454}]}]}
{"op":"mcm","clk":"1001650847","pt":1580638899868,"mc":[{"id":"1.168215938","rc":[{"batb":[[2,3.95,13.44]],"batl":[[0,4.6,10.92]],"ltp":5.0,"tv":105.34,"id":13117455},{"batb":[[0,4.5,11.76],[1,4.3,49.65],[2,4.2,47.97]],"batl":[[0,5.3,9.24]],"ltp":5.1,"tv":23.45,"id":13117503},{"batb":[[2,1.71,58.81]],"batl":[[0,1.86,42.01]],"ltp":1.73,"tv":576.24,"id":13117454}]}]}
{"op":"mcm","clk":"1001651605","pt":1580638909920,"mc":[{"id":"1.168215938","rc":[{"batb":[[0,4,52.72],[1,3.95,13.44],[2,1.01,0.51]],"ltp":5.0,"tv":105.34,"id":13117455},{"batb":[[1,1.01,0.51],[2,4.2,0]],"ltp":5.1,"tv":23.45,"id":13117503},{"batb":[[0,1.71,58.81],[1,1.01,0.51],[2,1.71,0]],"ltp":1.73,"tv":576.24,"id":13117454}]}]}
{"op":"mcm","clk":"1001651627","pt":1580638910082,"mc":[{"id":"1.168215938","rc":[{"batb":[[1,1.01,0.51],[2,1.01,0]],"ltp":5.0,"tv":105.34,"id":13117455},{"batb":[[0,1.01,0.51],[1,1.01,0]],"ltp":5.1,"tv":23.45,"id":13117503},{"batb":[[0,1.01,0.51],[1,1.01,0]],"ltp":1.73,"tv":576.24,"id":13117454}]}]}
{"op":"mcm","clk":"1001651813","pt":1580638912521,"mc":[{"id":"1.168215938","rc":[{"batb":[[0,1.01,0.51],[1,1.01,0]],"ltp":5.0,"tv":105.34,"id":13117455}]}]}
{"op":"mcm","clk":"1001652099","pt":1580638915905,"mc":[{"id":"1.168215938","rc":[{"batb":[[0,4.2,39.9],[1,4.1,50.21],[2,1.01,0.51]],"ltp":5.0,"tv":105.34,"id":13117455},{"batb":[[0,4.4,33.22],[1,4.3,45.69],[2,1.01,0.51]],"ltp":5.1,"tv":23.45,"id":13117503},{"batb":[[0,1.78,59.59],[1,1.76,99.64],[2,1.01,0.51]],"ltp":1.73,"tv":576.24,"id":13117454}]}]}
{"op":"mcm","clk":"1001652504","pt":1580638920812,"mc":[{"id":"1.168215938","rc":[{"batb":[[0,1.01,0.51],[1,4.1,0],[2,1.01,0]],"ltp":5.0,"tv":105.34,"id":13117455},{"batb":[[0,1.01,0.51],[1,4.3,0],[2,1.01,0]],"ltp":5.1,"tv":23.45,"id":13117503},{"batb":[[0,1.01,0.51],[1,1.76,0],[2,1.01,0]],"ltp":1.73,"tv":576.24,"id":13117454}]}]}
{"op":"mcm","clk":"1001652767","pt":1580638923853,"mc":[{"id":"1.168215938","rc":[{"batb":[[0,4,53.25],[1,3.95,27.63],[2,1.01,0.51]],"ltp":5.0,"tv":105.34,"id":13117455},{"batb":[[0,4.1,65],[1,4,53.5],[2,1.01,0.51]],"ltp":5.1,"tv":23.45,"id":13117503},{"batb":[[0,1.7,99.06],[1,1.68,117.1],[2,1.01,0.51]],"ltp":1.73,"tv":576.24,"id":13117454}]}]}
{"op":"mcm","clk":"1001653061","pt":1580638927827,"mc":[{"id":"1.168215938","rc":[{"batb":[[0,1.01,0.51],[1,1.68,0],[2,1.01,0]],"ltp":1.73,"tv":576.24,"id":13117454}]}]}
{"op":"mcm","clk":"1001653281","pt":1580638930640,"mc":[{"id":"1.168215938","rc":[{"batb":[[0,1.85,85.66],[1,1.83,87.63],[2,1.01,0.51]],"ltp":1.73,"tv":576.24,"id":13117454}]}]}
{"op":"mcm","clk":"1001653343","pt":1580638931423,"mc":[{"id":"1.168215938","rc":[{"batb":[[2,3.85,14.28]],"batl":[[0,4.5,11.76]],"ltp":5.0,"tv":105.34,"id":13117455},{"batb":[[0,4.4,11.76],[1,4.1,65],[2,4,53.5]],"batl":[[0,5.2,9.24]],"ltp":5.1,"tv":23.45,"id":13117503},{"batb":[[2,1.75,55.45]],"batl":[[0,1.9,42.01]],"ltp":1.73,"tv":576.24,"id":13117454}]}]}
{"op":"mcm","clk":"1001654556","pt":1580638947763,"mc":[{"id":"1.168215938","rc":[{"batb":[[0,4,28.7]],"ltp":5.0,"tv":105.34,"id":13117455},{"batb":[[1,4,53.5],[2,1.01,0.51]],"ltp":5.1,"tv":23.45,"id":13117503},{"batb":[[0,1.75,55.45],[1,1.01,0.51],[2,1.75,0]],"ltp":1.73,"tv":576.24,"id":13117454}]}]}
{"op":"mcm","clk":"1001654600","pt":1580638948394,"mc":[{"id":"1.168215938","rc":[{"batb":[[2,1.01,0.51]],"ltp":5.0,"tv":105.34,"id":13117455},{"batb":[[0,4,53.5],[1,1.01,0.51],[2,1.01,0]],"ltp":5.1,"tv":23.45,"id":13117503},{"batb":[[0,1.01,0.51],[1,1.01,0]],"ltp":1.73,"tv":576.24,"id":13117454}]}]}
{"op":"mcm","clk":"1001654767","pt":1580638950793,"mc":[{"id":"1.168215938","rc":[{"batb":[[0,4,69.13],[1,3.95,27.87],[2,1.01,0.51]],"ltp":5.1,"tv":23.45,"id":13117503},{"batb":[[0,1.8,74.34],[1,1.78,95.97],[2,1.01,0.51]],"ltp":1.73,"tv":576.24,"id":13117454}]}]}
{"op":"mcm","clk":"1001654827","pt":1580638951683,"mc":[{"id":"1.168215938","rc":[{"batb":[[0,1.01,0.51],[1,1.78,0],[2,1.01,0]],"ltp":1.73,"tv":576.24,"id":13117454}]}]}
{"op":"mcm","clk":"1001655124","pt":1580638954898,"mc":[{"id":"1.168215938","rc":[{"batb":[[0,1.88,80.12],[1,1.86,83.13],[2,1.01,0.51]],"ltp":1.73,"tv":576.24,"id":13117454}]}]}
{"op":"mcm","clk":"1001655170","pt":1580638955170,"mc":[{"id":"1.168215938","rc":[{"batb":[[2,3.85,14.28]],"batl":[[0,4.5,11.76]],"ltp":5.0,"tv":105.34,"id":13117455},{"batb":[[0,4.2,12.6],[1,4,69.13],[2,3.95,27.87]],"batl":[[0,5,10.08]],"ltp":5.1,"tv":23.45,"id":13117503},{"batb":[[2,1.77,53.77]],"batl":[[0,1.93,42.01]],"ltp":1.73,"tv":576.24,"id":13117454}]}]}
{"op":"mcm","clk":"1001659606","pt":1580639003803,"mc":[{"id":"1.168215938","rc":[{"batb":[[1,4,54.37],[2,1.01,0.51]],"ltp":5.1,"tv":23.45,"id":13117503},{"trd":[[1.86,139.74],[1.88,160.24]],"batb":[[0,1.77,53.77],[1,1.01,0.51],[2,1.77,0]],"ltp":1.86,"tv":876.22,"id":13117454}],"tv":1037.95}]}
{"op":"mcm","clk":"1001660225","pt":1580639006649,"mc":[{"id":"1.168215938","rc":[{"batb":[[0,4,37.79]],"ltp":5.0,"tv":105.34,"id":13117455},{"batb":[[1,4.1,24.49],[2,4,54.37]],"ltp":5.1,"tv":23.45,"id":13117503},{"batb":[[0,1.87,91.62],[1,1.85,84.62],[2,1.77,53.77]],"ltp":1.86,"tv":876.22,"id":13117454}]}]}
{"op":"mcm","clk":"1001662856","pt":1580639029206,"mc":[{"id":"1.168215938","rc":[{"batb":[[0,1.87,58.12]],"ltp":1.86,"tv":876.22,"id":13117454}]}]}
{"op":"mcm","clk":"1001663267","pt":1580639032519,"mc":[{"id":"1.168215938","rc":[{"batb":[[0,4,48.75]],"ltp":5.0,"tv":105.34,"id":13117455},{"batb":[[1,4.1,35.05]],"ltp":5.1,"tv":23.45,"id":13117503},{"batb":[[0,1.77,53.77],[1,1.01,0.51],[2,1.77,0]],"ltp":1.86,"tv":876.22,"id":13117454}]}]}
{"op":"mcm","clk":"1001663637","pt":1580639035613,"mc":[{"id":"1.168215938","rc":[{"batb":[[0,1.86,81.41],[1,1.84,86.15],[2,1.77,53.77]],"ltp":1.86,"tv":876.22,"id":13117454}]}]}
{"op":"mcm","clk":"1001664139","pt":1580639039621,"mc":[{"id":"1.168215938","rc":[{"batb":[[0,3.85,14.28],[1,1.01,0.51],[2,3.85,0]],"ltp":5.0,"tv":105.34,"id":13117455},{"batb":[[1,1.01,0.51],[2,4,0]],"ltp":5.1,"tv":23.45,"id":13117503},{"batb":[[0,1.01,0.51],[1,1.84,0],[2,1.77,0]],"ltp":1.86,"tv":876.22,"id":13117454}]}]}
{"op":"mcm","clk":"1001664210","pt":1580639040200,"mc":[{"id":"1.168215938","rc":[{"batb":[[0,1.01,0.51],[1,1.01,0]],"ltp":5.0,"tv":105.34,"id":13117455},{"batb":[[0,1.01,0.51],[1,1.01,0]],"ltp":5.1,"tv":23.45,"id":13117503}]}]}
{"op":"mcm","clk":"1001664576","pt":1580639042919,"mc":[{"id":"1.168215938","rc":[{"batb":[[0,3.6,31.97],[1,3.55,36.19],[2,1.01,0.51]],"ltp":5.0,"tv":105.34,"id":13117455},{"batb":[[0,3.6,41.49],[1,3.55,36.56],[2,1.01,0.51]],"ltp":5.1,"tv":23.45,"id":13117503},{"batb":[[0,1.76,90.24],[1,1.74,103.82],[2,1.01,0.51]],"ltp":1.86,"tv":876.22,"id":13117454}]}]}
{"op":"mcm","clk":"1001664901","pt":1580639045686,"mc":[{"id":"1.168215938","rc":[{"batb":[[0,1.01,0.51],[1,3.55,0],[2,1.01,0]],"ltp":5.0,"tv":105.34,"id":13117455},{"batb":[[0,1.01,0.51],[1,3.55,0],[2,1.01,0]],"ltp":5.1,"tv":23.45,"id":13117503}]}]}
{"op":"mcm","clk":"1001665274","pt":1580639048727,"mc":[{"id":"1.168215938","rc":[{"batb":[[0,4.3,28.83],[1,4.2,48.05],[2,1.01,0.51]],"ltp":5.0,"tv":105.34,"id":13117455},{"batb":[[0,4.4,36.85],[1,4.3,46.03],[2,1.01,0.51]],"ltp":5.1,"tv":23.45,"id":13117503}]}]}
{"op":"mcm","clk":"1001665350","pt":1580639049417,"mc":[{"id":"1.168215938","rc":[{"batb":[[2,4.1,13.44]],"batl":[[0,4.7,10.92]],"ltp":5.0,"tv":105.34,"id":13117455},{"batb":[[0,4.4,48.61]],"batl":[[0,5.3,9.24]],"ltp":5.1,"tv":23.45,"id":13117503},{"batb":[[2,1.7,59.65]],"batl":[[0,1.85,42.01]],"ltp":1.86,"tv":876.22,"id":13117454}]}]}
{"op":"mcm","clk":"1001666259","pt":1580639057837,"mc":[{"id":"1.168215938","rc":[{"batb":[[0,4.1,13.44],[1,1.01,0.51],[2,4.1,0]],"ltp":5.0,"tv":105.34,"id":13117455},{"batb":[[0,4.4,11.76],[1,1.01,0.51],[2,1.01,0]],"ltp":5.1,"tv":23.45,"id":13117503},{"batb":[[0,1.7,59.65],[1,1.01,0.51],[2,1.7,0]],"ltp":1.86,"tv":876.22,"id":13117454}]}]}
{"op":"mcm","clk":"1001666304","pt":1580639058249,"mc":[{"id":"1.168215938","rc":[{"batb":[[0,1.01,0.51],[1,1.01,0]],"ltp":5.0,"tv":105.34,"id":13117455},{"batb":[[0,1.01,0.51],[1,1.01,0]],"ltp":5.1,"tv":23.45,"id":13117503},{"batb":[[0,1.01,0.51],[1,1.01,0]],"ltp":1.86,"tv":876.22,"id":13117454}]}]}
{"op":"mcm","clk":"1001666583","pt":1580639060547,"mc":[{"id":"1.168215938","rc":[{"batb":[[0,1.7,61.24],[1,1.68,117.18],[2,1.01,0.51]],"ltp":1.86,"tv":876.22,"id":13117454}]}]}
{"op":"mcm","clk":"1001666914","pt":1580639063770,"mc":[{"id":"1.168215938","rc":[{"batb":[[0,4.5,27.68],[1,4.4,43.17],[2,1.01,0.51]],"ltp":5.0,"tv":105.34,"id":13117455},{"batb":[[0,4.6,56.88],[1,4.5,41.14],[2,1.01,0.51]],"ltp":5.1,"tv":23.45,"id":13117503}]}]}
{"op":"mcm","clk":"1001667058","pt":1580639065264,"mc":[{"id":"1.168215938","rc":[{"batb":[[2,4.2,12.6]],"batl":[[0,4.9,10.08]],"ltp":5.0,"tv":105.34,"id":13117455},{"batb":[[0,4.6,67.8]],"batl":[[0,5.5,9.24]],"ltp":5.1,"tv":23.45,"id":13117503},{"batb":[[2,1.65,63.85]],"batl":[[0,1.79,42.01]],"ltp":1.86,"tv":876.22,"id":13117454}]}]}
{"op":"mcm","clk":"1001667886","pt":1580639072682,"mc":[{"id":"1.168215938","rc":[{"batb":[[0,4.2,12.6],[1,1.01,0.51],[2,4.2,0]],"ltp":5.0,"tv":105.34,"id":13117455},{"batb":[[0,4.6,10.92],[1,1.01,0.51],[2,1.01,0]],"ltp":5.1,"tv":23.45,"id":13117503},{"batb":[[0,1.65,63.85],[1,1.01,0.51],[2,1.65,0]],"ltp":1.86,"tv":876.22,"id":13117454}]}]}
{"op":"mcm","clk":"1001668062","pt":1580639074296,"mc":[{"id":"1.168215938","rc":[{"batb":[[0,1.01,0.51],[1,1.01,0]],"ltp":5.0,"tv":105.34,"id":13117455},{"batb":[[0,1.01,0.51],[1,1.01,0]],"ltp":5.1,"tv":23.45,"id":13117503},{"batb":[[0,1.01,0.51],[1,1.01,0]],"ltp":1.86,"tv":876.22,"id":13117454}]}]}
{"op":"mcm","clk":"1001668200","pt":1580639075817,"mc":[{"id":"1.168215938","rc":[{"batb":[[0,4.2,59.63],[1,4.1,50.29],[2,1.01,0.51]],"ltp":5.0,"tv":105.34,"id":13117455},{"batb":[[0,4.3,35.99],[1,4.2,48.62],[2,1.01,0.51]],"ltp":5.1,"tv":23.45,"id":13117503},{"batb":[[0,1.66,72.36],[1,1.65,62.9],[2,1.01,0.51]],"ltp":1.86,"tv":876.22,"id":13117454}]}]}
{"op":"mcm","clk":"1001668594","pt":1580639079669,"mc":[{"id":"1.168215938","rc":[{"batb":[[0,1.01,0.51],[1,4.1,0],[2,1.01,0]],"ltp":5.0,"tv":105.34,"id":13117455},{"batb":[[0,1.01,0.51],[1,4.2,0],[2,1.01,0]],"ltp":5.1,"tv":23.45,"id":13117503}]}]}
{"op":"mcm","clk":"1001668872","pt":1580639082664,"mc":[{"id":"1.168215938","rc":[{"batb":[[0,4.6,35.31],[1,4.5,40.88],[2,1.01,0.51]],"ltp":5.0,"tv":105.34,"id":13117455},{"batb":[[0,4.8,48.64],[1,4.7,37.36],[2,1.01,0.51]],"ltp":5.1,"tv":23.45,"id":13117503}]}]}
{"op":"mcm","clk":"1001668947","pt":1580639083439,"mc":[{"id":"1.168215938","rc":[{"batb":[[2,4.3,12.6]],"batl":[[0,5,10.08]],"ltp":5.0,"tv":105.34,"id":13117455},{"batb":[[0,4.8,59.56]],"batl":[[0,5.7,8.4]],"ltp":5.1,"tv":23.45,"id":13117503},{"batb":[[2,1.63,66.38]],"batl":[[0,1.76,42.01]],"ltp":1.86,"tv":876.22,"id":13117454}]}]}
{"op":"mcm","clk":"1001669785","pt":1580639091896,"mc":[{"id":"1.168215938","rc":[{"batb":[[0,4.5,40.88],[1,4.3,12.6],[2,1.01,0.51]],"ltp":5.0,"tv":105.34,"id":13117455},{"batb":[[0,4.8,10.92],[1,1.01,0.51],[2,1.01,0]],"ltp":5.1,"tv":23.45,"id":13117503},{"batb":[[0,1.63,66.38],[1,1.01,0.51],[2,1.63,0]],"ltp":1.86,"tv":876.22,"id":13117454}]}]}
{"op":"mcm","clk":"1001669838","pt":1580639092365,"mc":[{"id":"1.168215938","rc":[{"batb":[[1,1.01,0.51],[2,1.01,0]],"ltp":5.0,"tv":105.34,"id":13117455},{"batb":[[0,1.01,0.51],[1,1.01,0]],"ltp":5.1,"tv":23.45,"id":13117503},{"batb":[[0,1.01,0.51],[1,1.01,0]],"ltp":1.86,"tv":876.22,"id":13117454}]}]}
{"op":"mcm","clk":"1001670110","pt":1580639094867,"mc":[{"id":"1.168215938","rc":[{"batb":[[1,4.4,43.05],[2,1.01,0.51]],"ltp":5.0,"tv":105.34,"id":13117455},{"batb":[[0,4.6,32.64],[1,4.5,41.53],[2,1.01,0.51]],"ltp":5.1,"tv":23.45,"id":13117503},{"batb":[[0,1.64,88.3],[1,1.63,65.8],[2,1.01,0.51]],"ltp":1.86,"tv":876.22,"id":13117454}]}]}
{"op":"mcm","clk":"1001670464","pt":1580639098661,"mc":[{"id":"1.168215938","rc":[{"batb":[[1,1.01,0.51],[2,1.01,0]],"ltp":5.0,"tv":105.34,"id":13117455},{"batb":[[0,1.01,0.51],[1,4.5,0],[2,1.01,0]],"ltp":5.1,"tv":23.45,"id":13117503}]}]}
{"op":"mcm","clk":"1001670792","pt":1580639101579,"mc":[{"id":"1.168215938","rc":[{"batb":[[0,4.6,52.08],[1,4.5,40.88],[2,1.01,0.51]],"ltp":5.0,"tv":105.34,"id":13117455},{"batb":[[0,4.9,51.96],[1,4.8,35.55],[2,1.01,0.51]],"ltp":5.1,"tv":23.45,"id":13117503}]}]}
{"op":"mcm","clk":"1001670962","pt":1580639103296,"mc":[{"id":"1.168215938","rc":[{"batb":[[2,4.3,12.6]],"batl":[[0,5,10.08]],"ltp":5.0,"tv":105.34,"id":13117455},{"batb":[[0,4.9,62.04]],"batl":[[0,5.9,8.4]],"ltp":5.1,"tv":23.45,"id":13117503},{"batb":[[2,1.61,68.06]],"batl":[[0,1.74,42.01]],"ltp":1.86,"tv":876.22,"id":13117454}]}]}
{"op":"mcm","clk":"1001673981","pt":1580639132553,"mc":[{"id":"1.168215938","rc":[{"batb":[[0,1.01,0.51],[1,4.5,0],[2,4.3,0]],"ltp":5.0,"tv":105.34,"id":13117455},{"batb":[[0,1.01,0.51],[1,4.8,0],[2,1.01,0]],"ltp":5.1,"tv":23.45,"id":13117503},{"batb":[[0,1.01,0.51],[1,1.63,0],[2,1.61,0]],"ltp":1.86,"tv":876.22,"id":13117454}]}]}
{"op":"mcm","clk":"1001674300","pt":1580639135933,"mc":[{"id":"1.168215938","rc":[{"batb":[[0,4.3,29.02],[1,4.2,48.05],[2,1.01,0.51]],"ltp":5.0,"tv":105.34,"id":13117455},{"batb":[[0,4.5,54.12],[1,4.4,43.38],[2,1.01,0.51]],"ltp":5.1,"tv":23.45,"id":13117503},{"batb":[[0,1.49,79.35],[1,1.48,95.76],[2,1.01,0.51]],"ltp":1.86,"tv":876.22,"id":13117454}]}]}
{"op":"mcm","clk":"1001674366","pt":1580639136659,"mc":[{"id":"1.168215938","rc":[{"batb":[[0,1.01,0.51],[1,4.2,0],[2,1.01,0]],"ltp":5.0,"tv":105.34,"id":13117455},{"batb":[[0,1.01,0.51],[1,4.4,0],[2,1.01,0]],"ltp":5.1,"tv":23.45,"id":13117503},{"batb":[[0,1.01,0.51],[1,1.48,0],[2,1.01,0]],"ltp":1.86,"tv":876.22,"id":13117454}]}]}
{"op":"mcm","clk":"1001674709","pt":1580639139853,"mc":[{"id":"1.168215938","rc":[{"batb":[[0,4.8,29.1],[1,4.7,37.1],[2,1.01,0.51]],"ltp":5.0,"tv":105.34,"id":13117455},{"batb":[[0,5.1,38.22],[1,5,32.6],[2,1.01,0.51]],"ltp":5.1,"tv":23.45,"id":13117503},{"batb":[[0,1.61,69.35],[1,1.6,70.42],[2,1.01,0.51]],"ltp":1.86,"tv":876.22,"id":13117454}]}]}
{"op":"mcm","clk":"1001674737","pt":1580639140057,"mc":[{"id":"1.168215938","rc":[{"batb":[[0,1.01,0.51],[1,4.7,0],[2,1.01,0]],"ltp":5.0,"tv":105.34,"id":13117455},{"batb":[[0,1.01,0.51],[1,5,0],[2,1.01,0]],"ltp":5.1,"tv":23.45,"id":13117503},{"batb":[[0,1.01,0.51],[1,1.6,0],[2,1.01,0]],"ltp":1.86,"tv":876.22,"id":13117454}]}]}
{"op":"mcm","clk":"1001675125","pt":1580639143509,"mc":[{"id":"1.168215938","rc":[{"batb":[[0,4.3,29.01],[1,4.2,48.05],[2,1.01,0.51]],"ltp":5.0,"tv":105.34,"id":13117455},{"batb":[[0,4.5,54.12],[1,4.4,43.38],[2,1.01,0.51]],"ltp":5.1,"tv":23.45,"id":13117503}]}]}
{"op":"mcm","clk":"1001675494","pt":1580639146563,"mc":[{"id":"1.168215938","rc":[{"batb":[[0,1.74,84.85],[1,1.72,108.01],[2,1.01,0.51]],"ltp":1.86,"tv":876.22,"id":13117454}]}]}
{"op":"mcm","clk":"1001675581","pt":1580639147243,"mc":[{"id":"1.168215938","rc":[{"batb":[[2,4,13.44]],"batl":[[0,4.7,10.92]],"ltp":5.0,"tv":105.34,"id":13117455},{"batb":[[0,4.6,10.92],[1,4.5,54.12],[2,4.4,43.38]],"batl":[[0,5.5,9.24]],"ltp":5.1,"tv":23.45,"id":13117503},{"batb":[[2,1.68,61.33]],"batl":[[0,1.83,42.01]],"ltp":1.86,"tv":876.22,"id":13117454}]}]}
{"op":"mcm","clk":"1001677276","pt":1580639161783,"mc":[{"id":"1.168215938","rc":[{"batb":[[0,4,13.44],[1,1.01,0.51],[2,4,0]],"ltp":5.0,"tv":105.34,"id":13117455},{"batb":[[1,1.01,0.51],[2,4.4,0]],"ltp":5.1,"tv":23.45,"id":13117503},{"batb":[[0,1.68,61.33],[1,1.01,0.51],[2,1.68,0]],"ltp":1.86,"tv":876.22,"id":13117454}]}]}
{"op":"mcm","clk":"1001677350","pt":1580639162412,"mc":[{"id":"1.168215938","rc":[{"batb":[[0,1.01,0.51],[1,1.01,0]],"ltp":5.0,"tv":105.34,"id":13117455},{"batb":[[0,1.01,0.51],[1,1.01,0]],"ltp":5.1,"tv":23.45,"id":13117503},{"batb":[[0,1.01,0.51],[1,1.01,0]],"ltp":1.86,"tv":876.22,"id":13117454}]}]}
{"op":"mcm","clk":"1001677538","pt":1580639164107,"mc":[{"id":"1.168215938","rc":[{"batb":[[0,4,67.8],[1,3.95,27.74],[2,1.01,0.51]],"ltp":5.0,"tv":105.34,"id":13117455},{"batb":[[0,4.2,69.83],[1,4.1,50.85],[2,1.01,0.51]],"ltp":5.1,"tv":23.45,"id":13117503},{"batb":[[0,1.6,123.19],[1,1.59,72.28],[2,1.01,0.51]],"ltp":1.86,"tv":876.22,"id":13117454}]}]}
{"op":"mcm","clk":"1001677724","pt":1580639165643,"mc":[{"id":"1.168215938","rc":[{"batb":[[0,1.01,0.51],[1,1.59,0],[2,1.01,0]],"ltp":1.86,"tv":876.22,"id":13117454}]}]}
{"op":"mcm","clk":"1001677981","pt":1580639167948,"mc":[{"id":"1.168215938","rc":[{"batl":[[0,4.6,173.25]],"ltp":5.1,"tv":23.45,"id":13117503}]}]}
{"op":"mcm","clk":"1001678054","pt":1580639168679,"mc":[{"id":"1.168215938","rc":[{"batb":[[0,1.83,59.89],[1,1.81,90.89],[2,1.01,0.51]],"ltp":1.86,"tv":876.22,"id":13117454}]}]}
{"op":"mcm","clk":"1001678131","pt":1580639169373,"mc":[{"id":"1.168215938","rc":[{"batb":[[2,3.85,14.28]],"batl":[[0,4.4,11.76]],"ltp":5.0,"tv":105.34,"id":13117455},{"batb":[[0,4.4,11.76],[1,4.2,69.83],[2,4.1,50.85]],"batl":[[0,5.2,9.24]],"ltp":5.1,"tv":23.45,"id":13117503},{"batb":[[2,1.74,56.29]],"batl":[[0,1.9,42.01]],"ltp":1.86,"tv":876.22,"id":13117454}]}]}
{"op":"mcm","clk":"1001679428","pt":1580639180876,"mc":[{"id":"1.168215938","rc":[{"batb":[[0,3.95,27.74],[1,3.85,14.28],[2,1.01,0.51]],"ltp":5.0,"tv":105.34,"id":13117455},{"batb":[[1,4.1,35.11],[2,1.01,0.51]],"ltp":5.1,"tv":23.45,"id":13117503},{"batb":[[0,1.74,56.29],[1,1.01,0.51],[2,1.74,0]],"ltp":1.86,"tv":876.22,"id":13117454}]}]}
{"op":"mcm","clk":"1001679594","pt":1580639182465,"mc":[{"id":"1.168215938","rc":[{"batb":[[1,1.01,0.51],[2,1.01,0]],"ltp":5.0,"tv":105.34,"id":13117455},{"batb":[[0,4.1,35.11],[1,1.01,0.51],[2,1.01,0]],"ltp":5.1,"tv":23.45,"id":13117503},{"batb":[[0,1.01,0.51],[1,1.01,0]],"ltp":1.86,"tv":876.22,"id":13117454}]}]}
{"op":"mcm","clk":"1001679795","pt":1580639183794,"mc":[{"id":"1.168215938","rc":[{"batb":[[1,3.9,28.93],[2,1.01,0.51]],"ltp":5.0,"tv":105.34,"id":13117455},{"batb":[[1,4,54.48],[2,1.01,0.51]],"ltp":5.1,"tv":23.45,"id":13117503},{"batb":[[0,1.73,68.33],[1,1.71,110.15],[2,1.01,0.51]],"ltp":1.86,"tv":876.22,"id":13117454}]}]}
{"op":"mcm","clk":"1001679960","pt":1580639184949,"mc":[{"id":"1.168215938","rc":[{"batb":[[0,1.01,0.51],[1,3.9,0],[2,1.01,0]],"ltp":5.0,"tv":105.34,"id":13117455},{"batb":[[0,1.01,0.51],[1,4,0],[2,1.01,0]],"ltp":5.1,"tv":23.45,"id":13117503},{"batb":[[0,1.01,0.51],[1,1.71,0],[2,1.01,0]],"ltp":1.86,"tv":876.22,"id":13117454}]}]}
{"op":"mcm","clk":"1001680284","pt":1580639187846,"mc":[{"id":"1.168215938","rc":[{"batb":[[0,4.1,37.97],[1,4,53.67],[2,1.01,0.51]],"ltp":5.0,"tv":105.34,"id":13117455},{"batb":[[0,4.3,52.19],[1,4.2,48.35],[2,1.01,0.51]],"ltp":5.1,"tv":23.45,"id":13117503},{"batb":[[0,1.81,57.08],[1,1.79,94.29],[2,1.01,0.51]],"ltp":1.86,"tv":876.22,"id":13117454}]}]}
{"op":"mcm","clk":"1001680646","pt":1580639190581,"mc":[{"id":"1.168215938","rc":[{"batb":[[0,1.01,0.51],[1,4,0],[2,1.01,0]],"ltp":5.0,"tv":105.34,"id":13117455},{"batb":[[0,1.01,0.51],[1,4.2,0],[2,1.01,0]],"ltp":5.1,"tv":23.45,"id":13117503},{"batb":[[0,1.01,0.51],[1,1.79,0],[2,1.01,0]],"ltp":1.86,"tv":876.22,"id":13117454}]}]}
{"op":"mcm","clk":"1001681271","pt":1580639193793,"mc":[{"id":"1.168215938","rc":[{"batb":[[0,3.95,29.01],[1,3.9,28.93],[2,1.01,0.51]],"ltp":5.0,"tv":105.34,"id":13117455},{"batb":[[0,4.1,35.11],[1,4,54.48],[2,1.01,0.51]],"ltp":5.1,"tv":23.45,"id":13117503},{"batb":[[0,1.73,68.33],[1,1.71,110.15],[2,1.01,0.51]],"ltp":1.86,"tv":876.22,"id":13117454}]}]}
{"op":"mcm","clk":"1001681721","pt":1580639197787,"mc":[{"id":"1.168215938","rc":[{"batb":[[0,1.01,0.51],[1,3.9,0],[2,1.01,0]],"ltp":5.0,"tv":105.34,"id":13117455},{"batb":[[0,1.01,0.51],[1,4,0],[2,1.01,0]],"ltp":5.1,"tv":23.45,"id":13117503}]}]}
{"op":"mcm","clk":"1001682051","pt":1580639200784,"mc":[{"id":"1.168215938","rc":[{"batb":[[0,4.3,35.81],[1,4.2,47.93],[2,1.01,0.51]],"ltp":5.0,"tv":105.34,"id":13117455},{"batb":[[0,4.6,43.73],[1,4.5,41.35],[2,1.01,0.51]],"ltp":5.1,"tv":23.45,"id":13117503}]}]}
{"op":"mcm","clk":"1001682120","pt":1580639201370,"mc":[{"id":"1.168215938","rc":[{"batb":[[2,4,13.44]],"batl":[[0,4.7,10.92]],"ltp":5.0,"tv":105.34,"id":13117455},{"batb":[[0,4.7,10.92],[1,4.6,43.73],[2,4.5,41.35]],"batl":[[0,5.6,8.4]],"ltp":5.1,"tv":23.45,"id":13117503},{"batb":[[2,1.67,62.17]],"batl":[[0,1.81,42.01]],"ltp":1.86,"tv":876.22,"id":13117454}]}]}
{"op":"mcm","clk":"1001686563","pt":1580639236595,"mc":[{"id":"1.168215938","rc":[{"batb":[[0,1.01,0.51],[1,4.2,0],[2,4,0]],"ltp":5.0,"tv":105.34,"id":13117455},{"batb":[[0,1.01,0.51],[1,4.6,0],[2,4.5,0]],"ltp":5.1,"tv":23.45,"id":13117503},{"batb":[[0,1.01,0.51],[1,1.71,0],[2,1.67,0]],"ltp":1.86,"tv":876.22,"id":13117454}]}]}
{"op":"mcm","clk":"1001687510","pt":1580639242760,"mc":[{"id":"1.168215938","rc":[{"batb":[[0,4,44.87],[1,3.95,27.93],[2,1.01,0.51]],"ltp":5.0,"tv":105.34,"id":13117455},{"batb":[[0,4.3,28.86],[1,4.2,48.74],[2,1.01,0.51]],"ltp":5.1,"tv":23.45,"id":13117503},{"batb":[[0,1.83,83.56],[1,1.81,90.92],[2,1.01,0.51]],"ltp":1.86,"tv":876.22,"id":13117454}]}]}
{"op":"mcm","clk":"1001687597","pt":1580639243387,"mc":[{"id":"1.168215938","rc":[{"batb":[[2,3.8,14.28]],"batl":[[0,4.4,11.76]],"ltp":5.0,"tv":105.34,"id":13117455},{"batb":[[0,4.4,11.76],[1,4.3,28.86],[2,4.2,48.74]],"batl":[[0,5.3,9.24]],"ltp":5.1,"tv":23.45,"id":13117503},{"batb":[[2,1.75,55.45]],"batl":[[0,1.9,42.01]],"ltp":1.86,"tv":876.22,"id":13117454}]}]}
{"op":"mcm","clk":"1001688724","pt":1580639251935,"mc":[{"id":"1.168215938","rc":[{"batb":[[0,3.8,14.28],[1,1.01,0.51],[2,3.8,0]],"ltp":5.0,"tv":105.34,"id":13117455},{"batb":[[1,1.01,0.51],[2,4.2,0]],"ltp":5.1,"tv":23.45,"id":13117503},{"batb":[[0,1.75,55.45],[1,1.01,0.51],[2,1.75,0]],"ltp":1.86,"tv":876.22,"id":13117454}]}]}
{"op":"mcm","clk":"1001688786","pt":1580639252454,"mc":[{"id":"1.168215938","rc":[{"batb":[[0,1.01,0.51],[1,1.01,0]],"ltp":5.0,"tv":105.34,"id":13117455},{"batb":[[0,1.01,0.51],[1,1.01,0]],"ltp":5.1,"tv":23.45,"id":13117503},{"batb":[[0,1.01,0.51],[1,1.01,0]],"ltp":1.86,"tv":876.22,"id":13117454}]}]}
{"op":"mcm","clk":"1001689017","pt":1580639254511,"mc":[{"id":"1.168215938","rc":[{"batb":[[0,3.9,42.34],[1,3.85,29.71],[2,1.01,0.51]],"ltp":5.0,"tv":105.34,"id":13117455},{"batb":[[0,4.1,50.74],[1,4,54.21],[2,1.01,0.51]],"ltp":5.1,"tv":23.45,"id":13117503},{"batb":[[0,1.74,72.6],[1,1.72,107.96],[2,1.01,0.51]],"ltp":1.86,"tv":876.22,"id":13117454}]}]}
{"op":"mcm","clk":"1001689140","pt":1580639255613,"mc":[{"id":"1.168215938","rc":[{"batb":[[0,1.01,0.51],[1,3.85,0],[2,1.01,0]],"ltp":5.0,"tv":105.34,"id":13117455},{"batb":[[0,1.01,0.51],[1,4,0],[2,1.01,0]],"ltp":5.1,"tv":23.45,"id":13117503}]}]}
{"op":"mcm","clk":"1001689494","pt":1580639258726,"mc":[{"id":"1.168215938","rc":[{"batb":[[0,4.2,53.11],[1,4.1,50.4],[2,1.01,0.51]],"ltp":5.0,"tv":105.34,"id":13117455},{"batb":[[0,4.6,43.14],[1,4.5,41.36],[2,1.01,0.51]],"ltp":5.1,"tv":23.45,"id":13117503}]}]}
{"op":"mcm","clk":"1001689602","pt":1580639259727,"mc":[{"id":"1.168215938","rc":[{"batb":[[2,3.95,13.44]],"batl":[[0,4.6,10.92]],"ltp":5.0,"tv":105.34,"id":13117455},{"batb":[[0,4.7,10.92],[1,4.6,43.14],[2,4.5,41.36]],"batl":[[0,5.6,8.4]],"ltp":5.1,"tv":23.45,"id":13117503},{"batb":[[2,1.69,60.49]],"ltp":1.86,"tv":876.22,"id":13117454}]}]}
{"op":"mcm","clk":"1001689823","pt":1580639261771,"mc":[{"id":"1.168215938","rc":[{"batl":[[0,1.82,42.01]],"ltp":1.86,"tv":876.22,"id":13117454}]}]}
{"op":"mcm","clk":"1001690561","pt":1580639268833,"mc":[{"id":"1.168215938","rc":[{"batb":[[0,3.95,13.44],[1,1.01,0.51],[2,3.95,0]],"ltp":5.0,"tv":105.34,"id":13117455},{"batb":[[1,1.01,0.51],[2,4.5,0]],"ltp":5.1,"tv":23.45,"id":13117503},{"batb":[[0,1.69,60.49],[1,1.01,0.51],[2,1.69,0]],"ltp":1.86,"tv":876.22,"id":13117454}]}]}
{"op":"mcm","clk":"1001690724","pt":1580639270438,"mc":[{"id":"1.168215938","rc":[{"batb":[[0,1.01,0.51],[1,1.01,0]],"ltp":5.0,"tv":105.34,"id":13117455},{"batb":[[0,1.01,0.51],[1,1.01,0]],"ltp":5.1,"tv":23.45,"id":13117503},{"batb":[[0,1.01,0.51],[1,1.01,0]],"ltp":1.86,"tv":876.22,"id":13117454}]}]}
{"op":"mcm","clk":"1001690871","pt":1580639271746,"mc":[{"id":"1.168215938","rc":[{"batb":[[0,3.9,47.67],[1,3.85,29.66],[2,1.01,0.51]],"ltp":5.0,"tv":105.34,"id":13117455},{"batb":[[0,4.2,63.3],[1,4.1,50.96],[2,1.01,0.51]],"ltp":5.1,"tv":23.45,"id":13117503},{"batb":[[0,1.56,86.65],[1,1.55,79.55],[2,1.01,0.51]],"ltp":1.86,"tv":876.22,"id":13117454}]}]}
{"op":"mcm","clk":"1001690986","pt":1580639272745,"mc":[{"id":"1.168215938","rc":[{"batb":[[0,1.01,0.51],[1,1.55,0],[2,1.01,0]],"ltp":1.86,"tv":876.22,"id":13117454}]}]}
{"op":"mcm","clk":"1001691311","pt":1580639275683,"mc":[{"id":"1.168215938","rc":[{"batb":[[2,3.75,15.12]],"batl":[[0,4.3,12.6]],"ltp":5.0,"tv":105.34,"id":13117455},{"batb":[[0,4.4,11.76],[1,4.2,63.3],[2,4.1,50.96]],"batl":[[0,5.2,9.24]],"ltp":5.1,"tv":23.45,"id":13117503},{"batb":[[0,1.86,65.93],[1,1.84,86.13],[2,1.77,53.77]],"batl":[[0,1.93,42.01]],"ltp":1.86,"tv":876.22,"id":13117454}]}]}
{"op":"mcm","clk":"1001703183","pt":1580639379853,"mc":[{"id":"1.168215938","rc":[{"batb":[[0,3.75,15.12],[1,1.01,0.51],[2,3.75,0]],"ltp":5.0,"tv":105.34,"id":13117455},{"batb":[[1,1.01,0.51],[2,4.1,0]],"ltp":5.1,"tv":23.45,"id":13117503},{"batb":[[0,1.01,0.51],[1,1.84,0],[2,1.77,0]],"ltp":1.86,"tv":876.22,"id":13117454}]}]}
{"op":"mcm","clk":"1001703247","pt":1580639380487,"mc":[{"id":"1.168215938","rc":[{"batb":[[0,1.01,0.51],[1,1.01,0]],"ltp":5.0,"tv":105.34,"id":13117455},{"batb":[[0,1.01,0.51],[1,1.01,0]],"ltp":5.1,"tv":23.45,"id":13117503}]}]}
{"op":"mcm","clk":"1001703522","pt":1580639382739,"mc":[{"id":"1.168215938","rc":[{"batb":[[0,3.45,31.34],[1,3.4,40.17],[2,1.01,0.51]],"ltp":5.0,"tv":105.34,"id":13117455},{"batb":[[0,3.7,30.6],[1,3.65,34.3],[2,1.01,0.51]],"ltp":5.1,"tv":23.45,"id":13117503},{"batb":[[0,1.79,52.93],[1,1.75,91.19],[2,1.73,105.88]],"ltp":1.86,"tv":876.22,"id":13117454}]}]}
{"op":"mcm","clk":"1001703570","pt":1580639383080,"mc":[{"id":"1.168215938","rc":[{"batb":[[0,1.01,0.51],[1,3.4,0],[2,1.01,0]],"ltp":5.0,"tv":105.34,"id":13117455},{"batb":[[0,1.01,0.51],[1,3.65,0],[2,1.01,0]],"ltp":5.1,"tv":23.45,"id":13117503},{"batb":[[0,1.75,91.19],[1,1.73,105.88],[2,1.01,0.51]],"ltp":1.86,"tv":876.22,"id":13117454}]}]}
{"op":"mcm","clk":"1001704079","pt":1580639386921,"mc":[{"id":"1.168215938","rc":[{"batb":[[0,4.2,29.83],[1,4.1,50.8],[2,1.01,0.51]],"ltp":5.0,"tv":105.34,"id":13117455},{"batb":[[0,4.6,26.49],[1,4.5,41.63],[2,1.01,0.51]],"ltp":5.1,"tv":23.45,"id":13117503}]}]}
{"op":"mcm","clk":"1001704129","pt":1580639387435,"mc":[{"id":"1.168215938","rc":[{"batb":[[2,3.9,14.28]],"batl":[[0,4.5,11.76]],"ltp":5.0,"tv":105.34,"id":13117455},{"batb":[[0,4.6,37.41]],"batl":[[0,5.6,8.4]],"ltp":5.1,"tv":23.45,"id":13117503},{"batb":[[2,1.71,58.81]],"batl":[[0,1.84,42.01]],"ltp":1.86,"tv":876.22,"id":13117454}]}]}
{"op":"mcm","clk":"1001704584","pt":1580639391851,"mc":[{"id":"1.168215938","rc":[{"batb":[[0,3.9,14.28],[1,1.01,0.51],[2,3.9,0]],"ltp":5.0,"tv":105.34,"id":13117455},{"batb":[[0,4.6,10.92],[1,1.01,0.51],[2,1.01,0]],"ltp":5.1,"tv":23.45,"id":13117503},{"batb":[[0,1.71,58.81],[1,1.01,0.51],[2,1.71,0]],"ltp":1.86,"tv":876.22,"id":13117454}]}]}
{"op":"mcm","clk":"1001704661","pt":1580639392543,"mc":[{"id":"1.168215938","rc":[{"batb":[[0,1.01,0.51],[1,1.01,0]],"ltp":5.0,"tv":105.34,"id":13117455},{"batb":[[0,1.01,0.51],[1,1.01,0]],"ltp":5.1,"tv":23.45,"id":13117503},{"batb":[[0,1.01,0.51],[1,1.01,0]],"ltp":1.86,"tv":876.22,"id":13117454}]}]}
{"op":"mcm","clk":"1001704882","pt":1580639394512,"mc":[{"id":"1.168215938","rc":[{"batb":[[0,1.68,105.77],[1,1.67,60.31],[2,1.01,0.51]],"ltp":1.86,"tv":876.22,"id":13117454}]}]}
{"op":"mcm","clk":"1001705119","pt":1580639396927,"mc":[{"id":"1.168215938","rc":[{"batb":[[0,4.4,33.69],[1,4.3,45.42],[2,1.01,0.51]],"ltp":5.0,"tv":105.34,"id":13117455},{"batb":[[0,4.8,54.57],[1,4.7,37.27],[2,1.01,0.51]],"ltp":5.1,"tv":23.45,"id":13117503}]}]}
{"op":"mcm","clk":"1001705172","pt":1580639397443,"mc":[{"id":"1.168215938","rc":[{"batb":[[2,4.1,13.44]],"batl":[[0,4.7,10.92]],"ltp":5.0,"tv":105.34,"id":13117455},{"batb":[[0,4.8,65.49]],"batl":[[0,5.8,8.4]],"ltp":5.1,"tv":23.45,"id":13117503},{"batb":[[2,1.65,63.85]],"batl":[[0,1.79,42.01]],"ltp":1.86,"tv":876.22,"id":13117454}]}]}
{"op":"mcm","clk":"1001705963","pt":1580639403875,"mc":[{"id":"1.168215938","rc":[{"batb":[[0,4.1,13.44],[1,1.01,0.51],[2,4.1,0]],"ltp":5.0,"tv":105.34,"id":13117455},{"batb":[[0,4.8,10.92],[1,1.01,0.51],[2,1.01,0]],"ltp":5.1,"tv":23.45,"id":13117503},{"batb":[[0,1.65,63.85],[1,1.01,0.51],[2,1.65,0]],"ltp":1.86,"tv":876.22,"id":13117454}]}]}
{"op":"mcm","clk":"1001706068","pt":1580639404546,"mc":[{"id":"1.168215938","rc":[{"batb":[[0,1.01,0.51],[1,1.01,0]],"ltp":5.0,"tv":105.34,"id":13117455},{"batb":[[0,1.01,0.51],[1,1.01,0]],"ltp":5.1,"tv":23.45,"id":13117503},{"batb":[[0,1.01,0.51],[1,1.01,0]],"ltp":1.86,"tv":876.22,"id":13117454}]}]}
{"op":"mcm","clk":"1001706339","pt":1580639406666,"mc":[{"id":"1.168215938","rc":[{"batb":[[0,4.1,61.16],[1,4,53.27],[2,1.01,0.51]],"ltp":5.0,"tv":105.34,"id":13117455},{"batb":[[0,4.4,62.87],[1,4.3,45.6],[2,1.01,0.51]],"ltp":5.1,"tv":23.45,"id":13117503},{"batb":[[0,1.64,118.55],[1,1.63,65.88],[2,1.01,0.51]],"ltp":1.86,"tv":876.22,"id":13117454}]}]}
{"op":"mcm","clk":"1001706921","pt":1580639411740,"mc":[{"id":"1.168215938","rc":[{"batb":[[0,1.01,0.51],[1,4,0],[2,1.01,0]],"ltp":5.0,"tv":105.34,"id":13117455},{"batb":[[0,1.01,0.51],[1,4.3,0],[2,1.01,0]],"ltp":5.1,"tv":23.45,"id":13117503}]}]}
{"op":"mcm","clk":"1001707338","pt":1580639414689,"mc":[{"id":"1.168215938","rc":[{"batb":[[0,4.5,43.01],[1,4.4,42.92],[2,1.01,0.51]],"ltp":5.0,"tv":105.34,"id":13117455},{"batb":[[0,5,52.28],[1,4.9,33.92],[2,1.01,0.51]],"ltp":5.1,"tv":23.45,"id":13117503}]}]}
{"op":"mcm","clk":"1001707459","pt":1580639415736,"mc":[{"id":"1.168215938","rc":[{"batb":[[2,4.1,13.44]],"batl":[[0,4.8,10.92]],"ltp":5.0,"tv":105.34,"id":13117455},{"batb":[[0,5,62.36]],"batl":[[0,6,8.4]],"ltp":5.1,"tv":23.45,"id":13117503},{"batb":[[1,1.63,132.26]],"ltp":1.86,"tv":876.22,"id":13117454}]}]}
{"op":"mcm","clk":"1001707658","pt":1580639417774,"mc":[{"id":"1.168215938","rc":[{"batl":[[0,1.75,42.01]],"ltp":1.86,"tv":876.22,"id":13117454}]}]}
{"op":"mcm","clk":"1001708595","pt":1580639427936,"mc":[{"id":"1.168215938","rc":[{"batb":[[0,4.4,42.92],[1,4.1,13.44],[2,1.01,0.51]],"ltp":5.0,"tv":105.34,"id":13117455},{"batb":[[0,5,10.08],[1,1.01,0.51],[2,1.01,0]],"ltp":5.1,"tv":23.45,"id":13117503},{"batb":[[0,1.63,132.26],[1,1.01,0.51],[2,1.01,0]],"ltp":1.86,"tv":876.22,"id":13117454}]}]}
{"op":"mcm","clk":"1001708653","pt":1580639428508,"mc":[{"id":"1.168215938","rc":[{"batb":[[1,1.01,0.51],[2,1.01,0]],"ltp":5.0,"tv":105.34,"id":13117455},{"batb":[[0,1.01,0.51],[1,1.01,0]],"ltp":5.1,"tv":23.45,"id":13117503},{"batb":[[0,1.63,65.88]],"ltp":1.86,"tv":876.22,"id":13117454}]}]}
{"op":"mcm","clk":"1001708860","pt":1580639430646,"mc":[{"id":"1.168215938","rc":[{"batb":[[1,4.3,45.26],[2,1.01,0.51]],"ltp":5.0,"tv":105.34,"id":13117455},{"batb":[[0,4.8,29.46],[1,4.7,37.66],[2,1.01,0.51]],"ltp":5.1,"tv":23.45,"id":13117503},{"batb":[[1,1.62,67.25],[2,1.01,0.51]],"ltp":1.86,"tv":876.22,"id":13117454}]}]}
{"op":"mcm","clk":"1001708977","pt":1580639431812,"mc":[{"id":"1.168215938","rc":[{"batb":[[1,1.01,0.51],[2,1.01,0]],"ltp":5.0,"tv":105.34,"id":13117455},{"batb":[[0,1.01,0.51],[1,4.7,0],[2,1.01,0]],"ltp":5.1,"tv":23.45,"id":13117503}]}]}
{"op":"mcm","clk":"1001709267","pt":1580639434727,"mc":[{"id":"1.168215938","rc":[{"batb":[[0,4.5,59.14],[1,4.4,42.92],[2,1.01,0.51]],"ltp":5.0,"tv":105.34,"id":13117455},{"batb":[[0,5.2,25.05],[1,5.1,31.38],[2,1.01,0.51]],"ltp":5.1,"tv":23.45,"id":13117503}]}]}
{"op":"mcm","clk":"1001709337","pt":1580639435519,"mc":[{"id":"1.168215938","rc":[{"batb":[[2,4.2,12.6]],"batl":[[0,4.8,10.92]],"ltp":5.0,"tv":105.34,"id":13117455},{"batb":[[1,5.1,41.46]],"batl":[[0,6.2,7.56]],"ltp":5.1,"tv":23.45,"id":13117503},{"batb":[[2,1.61,68.06]],"batl":[[0,1.74,42.01]],"ltp":1.86,"tv":876.22,"id":13117454}]}]}
{"op":"mcm","clk":"1001714104","pt":1580639471725,"mc":[{"id":"1.168215938","rc":[{"batb":[[0,4.2,12.6],[1,1.01,0.51],[2,4.2,0]],"ltp":5.0,"tv":105.34,"id":13117455},{"batb":[[0,5.1,10.08],[1,1.01,0.51],[2,1.01,0]],"ltp":5.1,"tv":23.45,"id":13117503},{"batb":[[0,1.61,68.06],[1,1.01,0.51],[2,1.61,0]],"ltp":1.86,"tv":876.22,"id":13117454}]}]}
{"op":"mcm","clk":"1001714390","pt":1580639474714,"mc":[{"id":"1.168215938","rc":[{"batb":[[1,4.1,72.09],[2,4,53.07]],"ltp":5.0,"tv":105.34,"id":13117455},{"batb":[[1,4.7,36.11],[2,4.6,39.45]],"ltp":5.1,"tv":23.45,"id":13117503},{"batb":[[1,1.46,148.18],[2,1.45,104.92]],"ltp":1.86,"tv":876.22,"id":13117454}]}]}
{"op":"mcm","clk":"1001714802","pt":1580639478735,"mc":[{"id":"1.168215938","rc":[{"batb":[[0,4.1,72.09],[1,4,53.07],[2,1.01,0.51]],"ltp":5.0,"tv":105.34,"id":13117455},{"batb":[[0,4.7,36.11],[1,4.6,39.45],[2,1.01,0.51]],"ltp":5.1,"tv":23.45,"id":13117503},{"batb":[[0,1.46,148.18],[1,1.45,104.92],[2,1.01,0.51]],"ltp":1.86,"tv":876.22,"id":13117454}]}]}
{"op":"mcm","clk":"1001715007","pt":1580639480839,"mc":[{"id":"1.168215938","rc":[{"batb":[[0,1.01,0.51],[1,4,0],[2,1.01,0]],"ltp":5.0,"tv":105.34,"id":13117455},{"batb":[[0,1.01,0.51],[1,4.6,0],[2,1.01,0]],"ltp":5.1,"tv":23.45,"id":13117503},{"batb":[[0,1.01,0.51],[1,1.45,0],[2,1.01,0]],"ltp":1.86,"tv":876.22,"id":13117454}]}]}
{"op":"mcm","clk":"1001715311","pt":1580639483821,"mc":[{"id":"1.168215938","rc":[{"batb":[[0,4.7,39.83],[1,4.6,38.79],[2,1.01,0.51]],"ltp":5.0,"tv":105.34,"id":13117455},{"batb":[[0,5.4,22.8],[1,5.3,28.82],[2,1.01,0.51]],"ltp":5.1,"tv":23.45,"id":13117503},{"batb":[[0,1.59,107.93],[1,1.58,73.97],[2,1.01,0.51]],"ltp":1.86,"tv":876.22,"id":13117454}]}]}
{"op":"mcm","clk":"1001715915","pt":1580639488948,"mc":[{"id":"1.168215938","rc":[{"batb":[[0,1.01,0.51],[1,4.6,0],[2,1.01,0]],"ltp":5.0,"tv":105.34,"id":13117455},{"batb":[[0,1.01,0.51],[1,5.3,0],[2,1.01,0]],"ltp":5.1,"tv":23.45,"id":13117503},{"batb":[[0,1.01,0.51],[1,1.58,0],[2,1.01,0]],"ltp":1.86,"tv":876.22,"id":13117454}]}]}
{"op":"mcm","clk":"1001716182","pt":1580639491932,"mc":[{"id":"1.168215938","rc":[{"batb":[[0,4.1,72.2],[1,4,53.07],[2,1.01,0.51]],"ltp":5.0,"tv":105.34,"id":13117455},{"batb":[[0,4.7,35.73],[1,4.6,39.45],[2,1.01,0.51]],"ltp":5.1,"tv":23.45,"id":13117503}]}]}
{"op":"mcm","clk":"1001716454","pt":1580639494913,"mc":[{"id":"1.168215938","rc":[{"batb":[[0,1.74,71.11],[1,1.72,107.95],[2,1.01,0.51]],"ltp":1.86,"tv":876.22,"id":13117454}]}]}
{"op":"mcm","clk":"1001716533","pt":1580639495599,"mc":[{"id":"1.168215938","rc":[{"batb":[[2,3.9,14.28]],"batl":[[0,4.5,11.76]],"ltp":5.0,"tv":105.34,"id":13117455},{"batb":[[0,4.8,10.92],[1,4.7,35.73],[2,4.6,39.45]],"batl":[[0,5.8,8.4]],"ltp":5.1,"tv":23.45,"id":13117503},{"batb":[[2,1.69,60.49]],"batl":[[0,1.83,42.01]],"ltp":1.86,"tv":876.22,"id":13117454}]}]}
{"op":"mcm","clk":"1001717517","pt":1580639506762,"mc":[{"id":"1.168215938","rc":[{"batb":[[0,1.01,0.51],[1,4,0],[2,3.9,0]],"ltp":5.0,"tv":105.34,"id":13117455},{"batb":[[0,1.01,0.51],[1,4.7,0],[2,4.6,0]],"ltp":5.1,"tv":23.45,"id":13117503},{"batb":[[0,1.01,0.51],[1,1.72,0],[2,1.69,0]],"ltp":1.86,"tv":876.22,"id":13117454}]}]}
{"op":"mcm","clk":"1001718056","pt":1580639512818,"mc":[{"id":"1.168215938","rc":[{"batb":[[0,4.2,67.98],[1,4.1,50.14],[2,1.01,0.51]],"ltp":5.0,"tv":105.34,"id":13117455},{"batb":[[0,4.8,44.44],[1,4.7,37.42],[2,1.01,0.51]],"ltp":5.1,"tv":23.45,"id":13117503},{"batb":[[0,1.71,63.32],[1,1.69,114.74],[2,1.01,0.51]],"ltp":1.86,"tv":876.22,"id":13117454}]}]}
{"op":"mcm","clk":"1001718879","pt":1580639518916,"mc":[{"id":"1.168215938","rc":[{"batb":[[0,1.01,0.51],[1,4.1,0],[2,1.01,0]],"ltp":5.0,"tv":105.34,"id":13117455},{"batb":[[0,1.01,0.51],[1,4.7,0],[2,1.01,0]],"ltp":5.1,"tv":23.45,"id":13117503},{"batb":[[0,1.01,0.51],[1,1.69,0],[2,1.01,0]],"ltp":1.86,"tv":876.22,"id":13117454}]}]}
{"op":"mcm","clk":"1001719259","pt":1580639521798,"mc":[{"id":"1.168215938","rc":[{"batb":[[0,3.9,52.24],[1,3.85,29.62],[2,1.01,0.51]],"ltp":5.0,"tv":105.34,"id":13117455},{"batb":[[0,4.4,31.2],[1,4.3,46.13],[2,1.01,0.51]],"ltp":5.1,"tv":23.45,"id":13117503},{"batb":[[0,1.59,99.55],[1,1.58,73.94],[2,1.01,0.51]],"ltp":1.86,"tv":876.22,"id":13117454}]}]}
{"op":"mcm","clk":"1001720341","pt":1580639532815,"mc":[{"id":"1.168215938","rc":[{"batb":[[0,1.01,0.51],[1,3.85,0],[2,1.01,0]],"ltp":5.0,"tv":105.34,"id":13117455},{"batb":[[0,1.01,0.51],[1,4.3,0],[2,1.01,0]],"ltp":5.1,"tv":23.45,"id":13117503}]}]}
{"op":"mcm","clk":"1001720642","pt":1580639535919,"mc":[{"id":"1.168215938","rc":[{"batb":[[0,4.7,33.73],[1,4.6,38.89],[2,1.01,0.51]],"ltp":5.0,"tv":105.34,"id":13117455},{"batb":[[0,5.4,32.68],[1,5.3,28.67],[2,1.01,0.51]],"ltp":5.1,"tv":23.45,"id":13117503}]}]}
{"op":"mcm","clk":"1001720800","pt":1580639537638,"mc":[{"id":"1.168215938","rc":[{"batb":[[2,4.3,12.6]],"batl":[[0,5,10.08]],"ltp":5.0,"tv":105.34,"id":13117455},{"batb":[[1,5.3,37.91]],"batl":[[0,6.4,7.56]],"ltp":5.1,"tv":23.45,"id":13117503},{"batb":[[1,1.58,146.2]],"batl":[[0,1.7,42.01]],"ltp":1.86,"tv":876.22,"id":13117454}]}]}
{"op":"mcm","clk":"1001722444","pt":1580639550832,"mc":[{"id":"1.168215938","rc":[{"batb":[[0,4.3,12.6],[1,1.01,0.51],[2,4.3,0]],"ltp":5.0,"tv":105.34,"id":13117455},{"batb":[[0,5.3,9.24],[1,1.01,0.51],[2,1.01,0]],"ltp":5.1,"tv":23.45,"id":13117503},{"batb":[[0,1.58,72.26],[1,1.01,0.51],[2,1.01,0]],"ltp":1.86,"tv":876.22,"id":13117454}]}]}
{"op":"mcm","clk":"1001722707","pt":1580639552635,"mc":[{"id":"1.168215938","rc":[{"batb":[[0,1.01,0.51],[1,1.01,0]],"ltp":5.0,"tv":105.34,"id":13117455},{"batb":[[0,1.01,0.51],[1,1.01,0]],"ltp":5.1,"tv":23.45,"id":13117503},{"batb":[[0,1.01,0.51],[1,1.01,0]],"ltp":1.86,"tv":876.22,"id":13117454}]}]}
{"op":"mcm","clk":"1001722808","pt":1580639553527,"mc":[{"id":"1.168215938","rc":[{"batb":[[0,4.2,24.63],[1,4.1,50.88],[2,1.01,0.51]],"ltp":5.0,"tv":105.34,"id":13117455},{"batb":[[0,4.8,26.32],[1,4.7,37.71],[2,1.01,0.51]],"ltp":5.1,"tv":23.45,"id":13117503}]}]}
{"op":"mcm","clk":"1001723029","pt":1580639555935,"mc":[{"id":"1.168215938","rc":[{"batl":[[0,5.1,162.8]],"ltp":5.1,"tv":23.45,"id":13117503}]}]}
{"op":"mcm","clk":"1001723070","pt":1580639556303,"mc":[{"id":"1.168215938","rc":[{"batb":[[0,1.73,65.13],[1,1.71,110.13],[2,1.01,0.51]],"ltp":1.86,"tv":876.22,"id":13117454}]}]}
{"op":"mcm","clk":"1001723178","pt":1580639557620,"mc":[{"id":"1.168215938","rc":[{"batb":[[2,3.9,14.28]],"batl":[[0,4.4,11.76]],"ltp":5.0,"tv":105.34,"id":13117455},{"batb":[[0,5,10.08],[1,4.8,26.32],[2,4.7,37.71]],"batl":[[0,6,8.4]],"ltp":5.1,"tv":23.45,"id":13117503},{"batb":[[2,1.67,62.17]],"batl":[[0,1.81,42.01]],"ltp":1.86,"tv":876.22,"id":13117454}]}]}
{"op":"mcm","clk":"1001723629","pt":1580639560837,"mc":[{"id":"1.168215938","rc":[{"batb":[[0,4.8,26.32],[1,4.7,37.71],[2,1.01,0.51]],"ltp":5.1,"tv":23.45,"id":13117503},{"batb":[[2,1.01,0.51]],"ltp":1.86,"tv":876.22,"id":13117454}]}]}
{"op":"mcm","clk":"1001724002","pt":1580639563527,"mc":[{"id":"1.168215938","rc":[{"batl":[[0,4.5,11.76]],"ltp":5.0,"tv":105.34,"id":13117455},{"batb":[[0,4.8,37.24]],"batl":[[0,5.8,8.4]],"ltp":5.1,"tv":23.45,"id":13117503},{"batb":[[2,1.68,61.33]],"ltp":1.86,"tv":876.22,"id":13117454}]}]}
{"op":"mcm","clk":"1001724350","pt":1580639566922,"mc":[{"id":"1.168215938","rc":[{"batb":[[0,3.9,14.28],[1,1.01,0.51],[2,3.9,0]],"ltp":5.0,"tv":105.34,"id":13117455},{"batb":[[0,4.8,10.92],[1,1.01,0.51],[2,1.01,0]],"ltp":5.1,"tv":23.45,"id":13117503},{"batb":[[0,1.68,61.33],[1,1.01,0.51],[2,1.68,0]],"ltp":1.86,"tv":876.22,"id":13117454}]}]}
{"op":"mcm","clk":"1001724555","pt":1580639568662,"mc":[{"id":"1.168215938","rc":[{"batb":[[0,1.01,0.51],[1,1.01,0]],"ltp":5.0,"tv":105.34,"id":13117455},{"batb":[[0,1.01,0.51],[1,1.01,0]],"ltp":5.1,"tv":23.45,"id":13117503},{"batb":[[0,1.01,0.51],[1,1.01,0]],"ltp":1.86,"tv":876.22,"id":13117454}]}]}
{"op":"mcm","clk":"1001724639","pt":1580639569549,"mc":[{"id":"1.168215938","rc":[{"batb":[[0,3.85,51.78],[1,3.8,30.56],[2,1.01,0.51]],"ltp":5.0,"tv":105.34,"id":13117455},{"batb":[[0,4.4,34.7],[1,4.3,46.08],[2,1.01,0.51]],"ltp":5.1,"tv":23.45,"id":13117503},{"batb":[[0,1.55,129.75],[1,1.54,81.78],[2,1.01,0.51]],"ltp":1.86,"tv":876.22,"id":13117454}]}]}
{"op":"mcm","clk":"1001724692","pt":1580639570071,"mc":[{"id":"1.168215938","rc":[{"batb":[[0,1.01,0.51],[1,3.8,0],[2,1.01,0]],"ltp":5.0,"tv":105.34,"id":13117455},{"batb":[[0,1.01,0.51],[1,4.3,0],[2,1.01,0]],"ltp":5.1,"tv":23.45,"id":13117503},{"batb":[[0,1.01,0.51],[1,1.54,0],[2,1.01,0]],"ltp":1.86,"tv":876.22,"id":13117454}]}]}
{"op":"mcm","clk":"1001725016","pt":1580639573429,"mc":[{"id":"1.168215938","rc":[{"batb":[[0,4.3,34.57],[1,4.2,47.95],[2,1.01,0.51]],"ltp":5.0,"tv":105.34,"id":13117455},{"batb":[[0,4.9,44.99],[1,4.8,35.66],[2,1.01,0.51]],"ltp":5.1,"tv":23.45,"id":13117503},{"batb":[[0,1.69,79.9],[1,1.67,119.74],[2,1.01,0.51]],"ltp":1.86,"tv":876.22,"id":13117454}]}]}
{"op":"mcm","clk":"1001725249","pt":1580639575959,"mc":[{"id":"1.168215938","rc":[{"batb":[[0,1.01,0.51],[1,4.2,0],[2,1.01,0]],"ltp":5.0,"tv":105.34,"id":13117455},{"batb":[[0,1.01,0.51],[1,4.8,0],[2,1.01,0]],"ltp":5.1,"tv":23.45,"id":13117503},{"batb":[[0,1.01,0.51],[1,1.67,0],[2,1.01,0]],"ltp":1.86,"tv":876.22,"id":13117454}]}]}
{"op":"mcm","clk":"1001725532","pt":1580639578744,"mc":[{"id":"1.168215938","rc":[{"batb":[[0,3.85,51.78],[1,3.8,30.56],[2,1.01,0.51]],"ltp":5.0,"tv":105.34,"id":13117455},{"batb":[[0,4.4,34.7],[1,4.3,46.08],[2,1.01,0.51]],"ltp":5.1,"tv":23.45,"id":13117503},{"batb":[[0,1.55,129.75],[1,1.54,81.78],[2,1.01,0.51]],"ltp":1.86,"tv":876.22,"id":13117454}]}]}
{"op":"mcm","clk":"1001725646","pt":1580639579953,"mc":[{"id":"1.168215938","rc":[{"batb":[[0,1.01,0.51],[1,1.54,0],[2,1.01,0]],"ltp":1.86,"tv":876.22,"id":13117454}]}]}
{"op":"mcm","clk":"1001726000","pt":1580639582861,"mc":[{"id":"1.168215938","rc":[{"batl":[[0,4.7,170.73]],"ltp":5.1,"tv":23.45,"id":13117503}]}]}
{"op":"mcm","clk":"1001726086","pt":1580639583751,"mc":[{"id":"1.168215938","rc":[{"batb":[[2,3.7,15.12]],"batl":[[0,4.2,12.6]],"ltp":5.0,"tv":105.34,"id":13117455},{"batb":[[0,4.5,11.76],[1,4.4,34.7],[2,4.3,46.08]],"batl":[[0,5.4,9.24]],"ltp":5.1,"tv":23.45,"id":13117503},{"batb":[[0,1.84,83.87],[1,1.82,89.28],[2,1.77,53.77]],"batl":[[0,1.93,42.01]],"ltp":1.86,"tv":876.22,"id":13117454}]}]}
{"op":"mcm","clk":"1001727166","pt":1580639594816,"mc":[{"id":"1.168215938","rc":[{"batb":[[0,1.01,0.51],[1,3.8,0],[2,3.7,0]],"ltp":5.0,"tv":105.34,"id":13117455},{"batb":[[0,1.01,0.51],[1,4.4,0],[2,4.3,0]],"ltp":5.1,"tv":23.45,"id":13117503},{"batb":[[0,1.01,0.51],[1,1.82,0],[2,1.77,0]],"ltp":1.86,"tv":876.22,"id":13117454}]}]}
{"op":"mcm","clk":"1001727452","pt":1580639597920,"mc":[{"id":"1.168215938","rc":[{"batb":[[0,3.75,48.43],[1,3.7,32.61],[2,1.01,0.51]],"ltp":5.0,"tv":105.34,"id":13117455},{"batb":[[0,4.2,49.24],[1,4.1,51.2],[2,1.01,0.51]],"ltp":5.1,"tv":23.45,"id":13117503},{"batb":[[0,1.74,92.13],[1,1.72,108.01],[2,1.01,0.51]],"ltp":1.86,"tv":876.22,"id":13117454}]}]}
{"op":"mcm","clk":"1001727795","pt":1580639601336,"mc":[{"id":"1.168215938","rc":[{"batb":[[0,1.01,0.51],[1,1.72,0],[2,1.01,0]],"ltp":1.86,"tv":876.22,"id":13117454}]}]}
{"op":"mcm","clk":"1001728030","pt":1580639603920,"mc":[{"id":"1.168215938","rc":[{"batl":[[0,4.6,173.13]],"ltp":5.1,"tv":23.45,"id":13117503}]}]}
{"op":"mcm","clk":"1001728057","pt":1580639604239,"mc":[{"id":"1.168215938","rc":[{"batb":[[0,1.9,69.21],[1,1.88,80.36],[2,1.01,0.51]],"ltp":1.86,"tv":876.22,"id":13117454}]}]}
{"op":"mcm","clk":"1001728182","pt":1580639605706,"mc":[{"id":"1.168215938","rc":[{"batb":[[2,3.6,15.96]],"batl":[[0,4.1,13.44]],"ltp":5.0,"tv":105.34,"id":13117455},{"batb":[[0,4.4,11.76],[1,4.2,49.24],[2,4.1,51.2]],"batl":[[0,5.2,9.24]],"ltp":5.1,"tv":23.45,"id":13117503},{"batb":[[2,1.81,51.25]],"batl":[[0,1.98,42.01]],"ltp":1.86,"tv":876.22,"id":13117454}]}]}
{"op":"mcm","clk":"1001735775","pt":1580639684931,"mc":[{"id":"1.168215938","rc":[{"batb":[[0,3.6,15.96],[1,1.01,0.51],[2,3.6,0]],"ltp":5.0,"tv":105.34,"id":13117455},{"batb":[[1,1.01,0.51],[2,4.1,0]],"ltp":5.1,"tv":23.45,"id":13117503},{"batb":[[0,1.81,51.25],[1,1.01,0.51],[2,1.81,0]],"ltp":1.86,"tv":876.22,"id":13117454}]}]}
{"op":"mcm","clk":"1001735928","pt":1580639686670,"mc":[{"id":"1.168215938","rc":[{"batb":[[0,1.01,0.51],[1,1.01,0]],"ltp":5.0,"tv":105.34,"id":13117455},{"batb":[[0,1.01,0.51],[1,1.01,0]],"ltp":5.1,"tv":23.45,"id":13117503},{"batb":[[0,1.01,0.51],[1,1.01,0]],"ltp":1.86,"tv":876.22,"id":13117454}]}]}
{"op":"mcm","clk":"1001736080","pt":1580639687959,"mc":[{"id":"1.168215938","rc":[{"batb":[[0,3.3,31.88],[1,3.25,45.04],[2,1.01,0.51]],"ltp":5.0,"tv":105.34,"id":13117455},{"batb":[[0,3.6,44.61],[1,3.55,36.7],[2,1.01,0.51]],"ltp":5.1,"tv":23.45,"id":13117503},{"batb":[[0,1.78,60.04],[1,1.76,99.71],[2,1.01,0.51]],"ltp":1.86,"tv":876.22,"id":13117454}]}]}
{"op":"mcm","clk":"1001736852","pt":1580639695638,"mc":[{"id":"1.168215938","rc":[{"batb":[[0,1.01,0.51],[1,3.25,0],[2,1.01,0]],"ltp":5.0,"tv":105.34,"id":13117455},{"batb":[[0,1.01,0.51],[1,3.55,0],[2,1.01,0]],"ltp":5.1,"tv":23.45,"id":13117503}]}]}
{"op":"mcm","clk":"1001737197","pt":1580639698942,"mc":[{"id":"1.168215938","rc":[{"batb":[[0,4,59.63],[1,3.95,27.8],[2,1.01,0.51]],"ltp":5.0,"tv":105.34,"id":13117455},{"batb":[[0,4.6,32.9],[1,4.5,41.54],[2,1.01,0.51]],"ltp":5.1,"tv":23.45,"id":13117503}]}]}
{"op":"mcm","clk":"1001737291","pt":1580639699692,"mc":[{"id":"1.168215938","rc":[{"batb":[[2,3.75,15.12]],"batl":[[0,4.4,11.76]],"ltp":5.0,"tv":105.34,"id":13117455},{"batb":[[0,4.6,43.82]],"batl":[[0,5.6,8.4]],"ltp":5.1,"tv":23.45,"id":13117503},{"batb":[[2,1.72,57.97]],"batl":[[0,1.88,42.01]],"ltp":1.86,"tv":876.22,"id":13117454}]}]}
{"op":"mcm","clk":"1001738356","pt":1580639708727,"mc":[{"id":"1.168215938","rc":[{"batb":[[0,1.01,0.51],[1,3.95,0],[2,3.75,0]],"ltp":5.0,"tv":105.34,"id":13117455},{"batb":[[0,1.01,0.51],[1,4.5,0],[2,1.01,0]],"ltp":5.1,"tv":23.45,"id":13117503},{"batb":[[0,1.01,0.51],[1,1.76,0],[2,1.72,0]],"ltp":1.86,"tv":876.22,"id":13117454}]}]}
{"op":"mcm","clk":"1001738721","pt":1580639711880,"mc":[{"id":"1.168215938","rc":[{"batb":[[0,3.6,35.01],[1,1.01,0.51]],"ltp":5.0,"tv":105.34,"id":13117455},{"batb":[[0,4,53.66],[1,1.01,0.51]],"ltp":5.1,"tv":23.45,"id":13117503},{"batb":[[0,1.7,59.47],[1,1.68,117.11],[2,1.01,0.51]],"ltp":1.86,"tv":876.22,"id":13117454}]}]}
{"op":"mcm","clk":"1001738978","pt":1580639714499,"mc":[{"id":"1.168215938","rc":[{"batb":[[0,3.6,62.73],[1,3.55,35.91],[2,1.01,0.51]],"ltp":5.0,"tv":105.34,"id":13117455},{"batb":[[0,4.1,24.91],[1,4,53.66],[2,1.01,0.51]],"ltp":5.1,"tv":23.45,"id":13117503}]}]}
{"op":"mcm","clk":"1001739085","pt":1580639715499,"mc":[{"id":"1.168215938","rc":[{"batb":[[0,1.01,0.51],[1,3.55,0],[2,1.01,0]],"ltp":5.0,"tv":105.34,"id":13117455},{"batb":[[0,1.01,0.51],[1,4,0],[2,1.01,0]],"ltp":5.1,"tv":23.45,"id":13117503}]}]}
{"op":"mcm","clk":"1001739345","pt":1580639717899,"mc":[{"id":"1.168215938","rc":[{"batb":[[0,4.2,52.25],[1,4.1,50.24],[2,1.01,0.51]],"ltp":5.0,"tv":105.34,"id":13117455},{"batb":[[0,5,20.78],[1,4.9,34.7],[2,1.01,0.51]],"ltp":5.1,"tv":23.45,"id":13117503}]}]}
{"op":"mcm","clk":"1001739547","pt":1580639719693,"mc":[{"id":"1.168215938","rc":[{"batb":[[2,3.9,14.28]],"batl":[[0,4.5,11.76]],"ltp":5.0,"tv":105.34,"id":13117455},{"batb":[[2,4.8,10.92]],"batl":[[0,5.9,8.4]],"ltp":5.1,"tv":23.45,"id":13117503},{"batb":[[2,1.67,62.17]],"batl":[[0,1.81,42.01]],"ltp":1.86,"tv":876.22,"id":13117454}]}]}
{"op":"mcm","clk":"1001739651","pt":1580639720645,"mc":[{"id":"1.168215938","rc":[{"batb":[[0,1.67,62.17],[1,1.01,0.51],[2,1.67,0]],"ltp":1.86,"tv":876.22,"id":13117454}]}]}
