{"op":"mcm","clk":"994279932","pt":1580566029164,"mc":[{"id":"1.168215940","marketDefinition":{"bspMarket":false,"turnInPlayEnabled":true,"persistenceEnabled":true,"marketBaseRate":5.0,"eventId":"29681228","eventTypeId":"2","numberOfWinners":1,"bettingType":"ODDS","marketType":"SET_WINNER","marketTime":"2020-02-02T04:00:00.000Z","suspendTime":"2020-02-02T04:00:00.000Z","bspReconciled":false,"complete":true,"inPlay":false,"crossMatching":false,"runnersVoidable":false,"numberOfActiveRunners":2,"betDelay":0,"status":"OPEN","runners":[{"status":"ACTIVE","sortPriority":1,"id":4423910,"name":"Matthew Ebden"},{"status":"ACTIVE","sortPriority":2,"id":2258415,"name":"Lukas Rosol"}],"regulators":["MR_INT"],"countryCode":"IN","discountAllowed":false,"timezone":"UTC","openDate":"2020-02-02T04:00:00.000Z","version":3145381986,"name":"Set 2 Winner","eventName":"Ebden v Rosol"},"rc":[{"batb":[[0,1.01,20]],"ltp":0.0,"tv":0.0,"id":4423910},{"batb":[[0,1.01,20]],"ltp":0.0,"tv":0.0,"id":2258415}]}]}
{"op":"mcm","clk":"994280373","pt":1580566030955,"mc":[{"id":"1.168215940","marketDefinition":{"bspMarket":false,"turnInPlayEnabled":true,"persistenceEnabled":true,"marketBaseRate":5.0,"eventId":"29681228","eventTypeId":"2","numberOfWinners":1,"bettingType":"ODDS","marketType":"SET_WINNER","marketTime":"2020-02-02T04:00:00.000Z","suspendTime":"2020-02-02T04:00:00.000Z","bspReconciled":false,"complete":true,"inPlay":false,"crossMatching":false,"runnersVoidable":false,"numberOfActiveRunners":2,"betDelay":0,"status":"OPEN","runners":[{"status":"ACTIVE","sortPriority":1,"id":4423910,"name":"Matthew Ebden"},{"status":"ACTIVE","sortPriority":2,"id":2258415,"name":"Lukas Rosol"}],"regulators":["MR_INT"],"countryCode":"IN","discountAllowed":false,"timezone":"UTC","openDate":"2020-02-02T04:00:00.000Z","version":3145381986,"name":"Set 2 Winner","eventName":"Ebden v Rosol"}}]}
{"op":"mcm","clk":"994280889","pt":1580566032994,"mc":[{"id":"1.168215940","marketDefinition":{"bspMarket":false,"turnInPlayEnabled":true,"persistenceEnabled":true,"marketBaseRate":5.0,"eventId":"29681228","eventTypeId":"2","numberOfWinners":1,"bettingType":"ODDS","marketType":"SET_WINNER","marketTime":"2020-02-02T04:00:00.000Z","suspendTime":"2020-02-02T04:00:00.000Z","bspReconciled":false,"complete":true,"inPlay":false,"crossMatching":false,"runnersVoidable":false,"numberOfActiveRunners":2,"betDelay":0,"status":"OPEN","runners":[{"status":"ACTIVE","sortPriority":1,"id":4423910,"name":"Matthew Ebden"},{"status":"ACTIVE","sortPriority":2,"id":2258415,"name":"Lukas Rosol"}],"regulators":["MR_INT"],"countryCode":"IN","discountAllowed":true,"timezone":"UTC","openDate":"2020-02-02T04:00:00.000Z","version":3145381986,"name":"Set 2 Winner","eventName":"Ebden v Rosol"}}]}
{"op":"mcm","clk":"994413113","pt":1580566512387,"mc":[{"id":"1.168215940","rc":[{"batb":[[0,1.01,10]],"ltp":0.0,"tv":0.0,"id":4423910},{"batb":[[0,1.01,10]],"ltp":0.0,"tv":0.0,"id":2258415}]}]}
{"op":"mcm","clk":"994665394","pt":1580567442352,"mc":[{"id":"1.168215940","marketDefinition":{"bspMarket":false,"turnInPlayEnabled":true,"persistenceEnabled":true,"marketBaseRate":5.0,"eventId":"29681228","eventTypeId":"2","numberOfWinners":1,"bettingType":"ODDS","marketType":"SET_WINNER","marketTime":"2020-02-02T09:30:00.000Z","suspendTime":"2020-02-02T09:30:00.000Z","bspReconciled":false,"complete":true,"inPlay":false,"crossMatching":false,"runnersVoidable":false,"numberOfActiveRunners":2,"betDelay":0,"status":"OPEN","runners":[{"status":"ACTIVE","sortPriority":1,"id":4423910,"name":"Matthew Ebden"},{"status":"ACTIVE","sortPriority":2,"id":2258415,"name":"Lukas Rosol"}],"regulators":["MR_INT"],"countryCode":"IN","discountAllowed":true,"timezone":"UTC","openDate":"2020-02-02T04:00:00.000Z","version":3145478877,"name":"Set 2 Winner","eventName":"Ebden v Rosol"}}]}
{"op":"mcm","clk":"994666152","pt":1580567445352,"mc":[{"id":"1.168215940","marketDefinition":{"bspMarket":false,"turnInPlayEnabled":true,"persistenceEnabled":true,"marketBaseRate":5.0,"eventId":"29681228","eventTypeId":"2","numberOfWinners":1,"bettingType":"ODDS","marketType":"SET_WINNER","marketTime":"2020-02-02T09:30:00.000Z","suspendTime":"2020-02-02T09:30:00.000Z","bspReconciled":false,"complete":true,"inPlay":false,"crossMatching":false,"runnersVoidable":false,"numberOfActiveRunners":2,"betDelay":0,"status":"OPEN","runners":[{"status":"ACTIVE","sortPriority":1,"id":4423910,"name":"Matthew Ebden"},{"status":"ACTIVE","sortPriority":2,"id":2258415,"name":"Lukas Rosol"}],"regulators":["MR_INT"],"countryCode":"IN","discountAllowed":true,"timezone":"UTC","openDate":"2020-02-02T09:30:00.000Z","version":3145478877,"name":"Set 2 Winner","eventName":"Ebden v Rosol"}}]}
{"op":"mcm","clk":"999906337","pt":1580602462573,"mc":[{"id":"1.168215940","rc":[{"batb":[[0,1.01,12.53]],"ltp":0.0,"tv":0.0,"id":4423910},{"batb":[[0,1.01,12.53]],"ltp":0.0,"tv":0.0,"id":2258415}]}]}
{"op":"mcm","clk":"999906417","pt":1580602463662,"mc":[{"id":"1.168215940","rc":[{"batb":[[0,1.01,10.51]],"ltp":0.0,"tv":0.0,"id":4423910},{"batb":[[0,1.01,10.51]],"ltp":0.0,"tv":0.0,"id":2258415}]}]}
{"op":"mcm","clk":"999995732","pt":1580603996748,"mc":[{"id":"1.168215940","rc":[{"batb":[[0,1.01,13.04]],"ltp":0.0,"tv":0.0,"id":4423910},{"batb":[[0,1.01,13.04]],"ltp":0.0,"tv":0.0,"id":2258415}]}]}
{"op":"mcm","clk":"999995787","pt":1580603997874,"mc":[{"id":"1.168215940","rc":[{"batb":[[0,1.01,11.01]],"ltp":0.0,"tv":0.0,"id":4423910},{"batb":[[0,1.01,11.01]],"ltp":0.0,"tv":0.0,"id":2258415}]}]}
{"op":"mcm","clk":"1000104042","pt":1580607068936,"mc":[{"id":"1.168215940","rc":[{"batb":[[0,1.01,11.02]],"ltp":0.0,"tv":0.0,"id":4423910},{"batb":[[0,1.01,11.02]],"ltp":0.0,"tv":0.0,"id":2258415}]}]}
{"op":"mcm","clk":"1001416193","pt":1580635444714,"mc":[{"id":"1.168215940","rc":[{"batb":[[0,2.02,27.22],[1,1.01,11.02]],"ltp":0.0,"tv":0.0,"id":4423910},{"batb":[[0,1.86,17.78],[1,1.01,11.02]],"ltp":0.0,"tv":0.0,"id":2258415}]}]}
{"op":"mcm","clk":"1001417670","pt":1580635475129,"mc":[{"id":"1.168215940","marketDefinition":{"bspMarket":false,"turnInPlayEnabled":true,"persistenceEnabled":true,"marketBaseRate":5.0,"eventId":"29681228","eventTypeId":"2","numberOfWinners":1,"bettingType":"ODDS","marketType":"SET_WINNER","marketTime":"2020-02-02T09:30:00.000Z","suspendTime":"2020-02-02T09:30:00.000Z","bspReconciled":false,"complete":true,"inPlay":false,"crossMatching":true,"runnersVoidable":false,"numberOfActiveRunners":2,"betDelay":0,"status":"OPEN","runners":[{"status":"ACTIVE","sortPriority":1,"id":4423910,"name":"Matthew Ebden"},{"status":"ACTIVE","sortPriority":2,"id":2258415,"name":"Lukas Rosol"}],"regulators":["MR_INT"],"countryCode":"IN","discountAllowed":true,"timezone":"UTC","openDate":"2020-02-02T09:30:00.000Z","version":3146887649,"name":"Set 2 Winner","eventName":"Ebden v Rosol"}}]}
{"op":"mcm","clk":"1001420402","pt":1580635526779,"mc":[{"id":"1.168215940","rc":[{"batb":[[0,2.04,26.2],[1,2.02,27.22],[2,1.01,11.02]],"ltp":0.0,"tv":0.0,"id":4423910},{"batb":[[1,1.83,18.49],[2,1.01,11.02]],"ltp":0.0,"tv":0.0,"id":2258415}]}]}
{"op":"mcm","clk":"1001420468","pt":1580635527803,"mc":[{"id":"1.168215940","rc":[{"batb":[[1,1.01,11.02],[2,1.01,0]],"ltp":0.0,"tv":0.0,"id":4423910},{"batb":[[0,1.83,18.49],[1,1.01,11.02],[2,1.01,0]],"ltp":0.0,"tv":0.0,"id":2258415}]}]}
{"op":"mcm","clk":"1001423396","pt":1580635580949,"mc":[{"id":"1.168215940","rc":[{"batb":[[0,1.84,18.41]],"ltp":0.0,"tv":0.0,"id":2258415}]}]}
{"op":"mcm","clk":"1001424694","pt":1580635599924,"mc":[{"id":"1.168215940","rc":[{"batb":[[0,2.06,1.23],[1,2.04,26.2],[2,1.01,11.02]],"ltp":0.0,"tv":0.0,"id":4423910},{"batb":[[0,1.85,1.36],[1,1.84,18.41],[2,1.01,11.02]],"ltp":0.0,"tv":0.0,"id":2258415}]}]}
{"op":"mcm","clk":"1001425451","pt":1580635608319,"mc":[{"id":"1.168215940","marketDefinition":{"bspMarket":false,"turnInPlayEnabled":true,"persistenceEnabled":true,"marketBaseRate":5.0,"eventId":"29681228","eventTypeId":"2","numberOfWinners":1,"bettingType":"ODDS","marketType":"SET_WINNER","marketTime":"2020-02-02T09:23:00.000Z","suspendTime":"2020-02-02T09:23:00.000Z","bspReconciled":false,"complete":true,"inPlay":false,"crossMatching":true,"runnersVoidable":false,"numberOfActiveRunners":2,"betDelay":0,"status":"OPEN","runners":[{"status":"ACTIVE","sortPriority":1,"id":4423910,"name":"Matthew Ebden"},{"status":"ACTIVE","sortPriority":2,"id":2258415,"name":"Lukas Rosol"}],"regulators":["MR_INT"],"countryCode":"IN","discountAllowed":true,"timezone":"UTC","openDate":"2020-02-02T09:30:00.000Z","version":3148345277,"name":"Set 2 Winner","eventName":"Ebden v Rosol"}}]}
{"op":"mcm","clk":"1001425695","pt":1580635610399,"mc":[{"id":"1.168215940","marketDefinition":{"bspMarket":false,"turnInPlayEnabled":true,"persistenceEnabled":true,"marketBaseRate":5.0,"eventId":"29681228","eventTypeId":"2","numberOfWinners":1,"bettingType":"ODDS","marketType":"SET_WINNER","marketTime":"2020-02-02T09:23:00.000Z","suspendTime":"2020-02-02T09:23:00.000Z","bspReconciled":false,"complete":true,"inPlay":false,"crossMatching":true,"runnersVoidable":false,"numberOfActiveRunners":2,"betDelay":0,"status":"OPEN","runners":[{"status":"ACTIVE","sortPriority":1,"id":4423910,"name":"Matthew Ebden"},{"status":"ACTIVE","sortPriority":2,"id":2258415,"name":"Lukas Rosol"}],"regulators":["MR_INT"],"countryCode":"IN","discountAllowed":true,"timezone":"UTC","openDate":"2020-02-02T09:23:00.000Z","version":3148345277,"name":"Set 2 Winner","eventName":"Ebden v Rosol"}}]}
{"op":"mcm","clk":"1001440408","pt":1580635860950,"mc":[{"id":"1.168215940","rc":[{"batb":[[2,1.98,42.85]],"batl":[[0,2.2,34.45]],"ltp":0.0,"tv":0.0,"id":4423910},{"batb":[[0,1.85,50.09]],"batl":[[0,2.04,40.33]],"ltp":0.0,"tv":0.0,"id":2258415}]}]}
{"op":"mcm","clk":"1001440453","pt":1580635861571,"mc":[{"id":"1.168215940","rc":[{"batb":[[0,1.85,1.36],[1,1.84,67.98]],"batl":[[0,2.02,41.17]],"ltp":0.0,"tv":0.0,"id":2258415}]}]}
{"op":"mcm","clk":"1001444827","pt":1580635942931,"mc":[{"id":"1.168215940","rc":[{"batb":[[1,1.84,67.67]],"ltp":0.0,"tv":0.0,"id":2258415}]}]}
{"op":"mcm","clk":"1001447160","pt":1580636000789,"mc":[{"id":"1.168215940","rc":[{"batb":[[0,1.85,19.46]],"ltp":0.0,"tv":0.0,"id":2258415}]}]}
{"op":"mcm","clk":"1001447177","pt":1580636001509,"mc":[{"id":"1.168215940","rc":[{"batb":[[1,1.84,49.57]],"ltp":0.0,"tv":0.0,"id":2258415}]}]}
{"op":"mcm","clk":"1001447506","pt":1580636012809,"mc":[{"id":"1.168215940","rc":[{"batb":[[1,1.84,67.83]],"ltp":0.0,"tv":0.0,"id":2258415}]}]}
{"op":"mcm","clk":"1001447515","pt":1580636013017,"mc":[{"id":"1.168215940","rc":[{"batb":[[0,1.85,1.36]],"ltp":0.0,"tv":0.0,"id":2258415}]}]}
{"op":"mcm","clk":"1001448622","pt":1580636044770,"mc":[{"id":"1.168215940","rc":[{"batb":[[1,1.84,67.67]],"ltp":0.0,"tv":0.0,"id":2258415}]}]}
{"op":"mcm","clk":"1001448914","pt":1580636054847,"mc":[{"id":"1.168215940","rc":[{"batb":[[0,1.85,19.46],[1,1.84,49.57]],"ltp":0.0,"tv":0.0,"id":2258415}]}]}
{"op":"mcm","clk":"1001449615","pt":1580636074246,"mc":[{"id":"1.168215940","rc":[{"batb":[[2,1.01,11.02]],"ltp":0.0,"tv":0.0,"id":4423910},{"batb":[[1,1.01,11.02],[2,1.01,0]],"ltp":0.0,"tv":0.0,"id":2258415}]}]}
{"op":"mcm","clk":"1001451529","pt":1580636130732,"mc":[{"id":"1.168215940","rc":[{"batb":[[1,1.98,42.85]],"batl":[[0,2.2,34.45]],"ltp":0.0,"tv":0.0,"id":4423910},{"batb":[[0,1.85,50.09]],"batl":[[0,2.04,40.33]],"ltp":0.0,"tv":0.0,"id":2258415}]}]}
{"op":"mcm","clk":"1001451552","pt":1580636131258,"mc":[{"id":"1.168215940","marketDefinition":{"bspMarket":false,"turnInPlayEnabled":true,"persistenceEnabled":true,"marketBaseRate":5.0,"eventId":"29681228","eventTypeId":"2","numberOfWinners":1,"bettingType":"ODDS","marketType":"SET_WINNER","marketTime":"2020-02-02T09:23:00.000Z","suspendTime":"2020-02-02T09:23:00.000Z","bspReconciled":false,"complete":true,"inPlay":true,"crossMatching":true,"runnersVoidable":false,"numberOfActiveRunners":2,"betDelay":3,"status":"OPEN","runners":[{"status":"ACTIVE","sortPriority":1,"id":4423910,"name":"Matthew Ebden"},{"status":"ACTIVE","sortPriority":2,"id":2258415,"name":"Lukas Rosol"}],"regulators":["MR_INT"],"countryCode":"IN","discountAllowed":true,"timezone":"UTC","openDate":"2020-02-02T09:23:00.000Z","version":3148350922,"name":"Set 2 Winner","eventName":"Ebden v Rosol"},"rc":[{"batb":[[0,1.01,10.52],[1,1.98,0],[2,1.01,0]],"ltp":0.0,"tv":0.0,"id":4423910},{"batb":[[0,1.01,10.52],[1,1.01,0]],"ltp":0.0,"tv":0.0,"id":2258415}]}]}
{"op":"mcm","clk":"1001451685","pt":1580636134723,"mc":[{"id":"1.168215940","rc":[{"batb":[[0,1.98,42.85],[1,1.01,10.52]],"batl":[[0,2.2,34.45]],"ltp":0.0,"tv":0.0,"id":4423910},{"batb":[[0,1.85,48.73],[1,1.01,10.52]],"batl":[[0,2.04,40.33]],"ltp":0.0,"tv":0.0,"id":2258415}]}]}
{"op":"mcm","clk":"1001451703","pt":1580636135132,"mc":[{"id":"1.168215940","rc":[{"batb":[[0,1.01,10.52],[1,1.01,0]],"ltp":0.0,"tv":0.0,"id":4423910},{"batb":[[0,1.01,10.52],[1,1.01,0]],"ltp":0.0,"tv":0.0,"id":2258415}]}]}
{"op":"mcm","clk":"1001451997","pt":1580636142644,"mc":[{"id":"1.168215940","rc":[{"batb":[[0,2.08,24.71],[1,2.06,26.04],[2,1.01,10.52]],"ltp":0.0,"tv":0.0,"id":4423910},{"batb":[[0,1.8,19.51],[1,1.75,21.4],[2,1.01,10.52]],"ltp":0.0,"tv":0.0,"id":2258415}]}]}
{"op":"mcm","clk":"1001452037","pt":1580636143656,"mc":[{"id":"1.168215940","rc":[{"batb":[[2,2,42.01]],"batl":[[0,2.24,33.61]],"ltp":0.0,"tv":0.0,"id":4423910},{"batl":[[0,2,42.01]],"ltp":0.0,"tv":0.0,"id":2258415}]}]}
{"op":"mcm","clk":"1001452099","pt":1580636144938,"mc":[{"id":"1.168215940","rc":[{"batb":[[0,1.81,51.25],[1,1.8,19.51],[2,1.75,21.4]],"ltp":0.0,"tv":0.0,"id":2258415}]}]}
{"op":"mcm","clk":"1001452347","pt":1580636152336,"mc":[{"id":"1.168215940","rc":[{"batb":[[0,2.06,26.04],[1,1.01,10.52],[2,2,0]],"ltp":0.0,"tv":0.0,"id":4423910},{"batb":[[0,1.75,21.4],[1,1.01,10.52],[2,1.75,0]],"ltp":0.0,"tv":0.0,"id":2258415}]}]}
{"op":"mcm","clk":"1001453778","pt":1580636182794,"mc":[{"id":"1.168215940","rc":[{"batb":[[1,2.02,27.54],[2,1.01,10.52]],"ltp":0.0,"tv":0.0,"id":4423910},{"batb":[[0,1.83,18.57],[1,1.78,20.22],[2,1.01,10.52]],"ltp":0.0,"tv":0.0,"id":2258415}]}]}
{"op":"mcm","clk":"1001453802","pt":1580636183202,"mc":[{"id":"1.168215940","rc":[{"batb":[[2,2,42.01]],"batl":[[0,2.22,33.61]],"ltp":0.0,"tv":0.0,"id":4423910},{"batb":[[1,1.81,51.25],[2,1.78,20.22]],"batl":[[0,2.02,41.17]],"ltp":0.0,"tv":0.0,"id":2258415}]}]}
{"op":"mcm","clk":"1001454085","pt":1580636189305,"mc":[{"id":"1.168215940","rc":[{"batb":[[0,2.02,27.54],[1,2,42.01],[2,1.01,10.52]],"ltp":0.0,"tv":0.0,"id":4423910},{"batb":[[0,1.81,51.25],[1,1.78,20.22],[2,1.01,10.52]],"ltp":0.0,"tv":0.0,"id":2258415}]}]}
{"op":"mcm","clk":"1001454121","pt":1580636190231,"mc":[{"id":"1.168215940","rc":[{"batb":[[1,1.01,10.52],[2,1.01,0]],"ltp":0.0,"tv":0.0,"id":4423910},{"batb":[[0,1.78,20.22],[1,1.01,10.52],[2,1.01,0]],"ltp":0.0,"tv":0.0,"id":2258415}]}]}
{"op":"mcm","clk":"1001454605","pt":1580636203927,"mc":[{"id":"1.168215940","rc":[{"batb":[[0,2.12,23.84],[1,2.06,25.57],[2,2.02,27.54]],"ltp":0.0,"tv":0.0,"id":4423910},{"batb":[[1,1.73,22.42],[2,1.01,10.52]],"ltp":0.0,"tv":0.0,"id":2258415}]}]}
{"op":"mcm","clk":"1001454619","pt":1580636204341,"mc":[{"id":"1.168215940","rc":[{"batb":[[2,2.02,172.74]],"ltp":0.0,"tv":0.0,"id":4423910}]}]}
{"op":"mcm","clk":"1001454662","pt":1580636205319,"mc":[{"id":"1.168215940","rc":[{"batb":[[2,2.04,40.33]],"batl":[[0,2.28,32.77]],"ltp":0.0,"tv":0.0,"id":4423910},{"batb":[[0,1.78,73.99]],"batl":[[0,1.98,42.01]],"ltp":0.0,"tv":0.0,"id":2258415}]}]}
{"op":"mcm","clk":"1001455510","pt":1580636224262,"mc":[{"id":"1.168215940","rc":[{"batb":[[2,1.01,10.52]],"ltp":0.0,"tv":0.0,"id":4423910},{"batb":[[0,1.78,20.22]],"ltp":0.0,"tv":0.0,"id":2258415}]}]}
{"op":"mcm","clk":"1001455547","pt":1580636225141,"mc":[{"id":"1.168215940","rc":[{"batb":[[0,1.01,10.52],[1,2.06,0],[2,1.01,0]],"ltp":0.0,"tv":0.0,"id":4423910},{"batb":[[0,1.01,10.52],[1,1.73,0],[2,1.01,0]],"ltp":0.0,"tv":0.0,"id":2258415}]}]}
{"op":"mcm","clk":"1001458081","pt":1580636281948,"mc":[{"id":"1.168215940","rc":[{"batb":[[0,2.06,39.49],[1,1.6,237.99],[2,1.01,10.52]],"batl":[[0,2.32,31.09]],"ltp":0.0,"tv":0.0,"id":4423910},{"batb":[[0,1.76,54.61],[1,1.01,10.52]],"batl":[[0,1.94,42.01]],"ltp":0.0,"tv":0.0,"id":2258415}]}]}
{"op":"mcm","clk":"1001458098","pt":1580636282318,"mc":[{"id":"1.168215940","rc":[{"batb":[[1,1.01,10.52],[2,1.01,0]],"ltp":0.0,"tv":0.0,"id":4423910}]}]}
{"op":"mcm","clk":"1001458206","pt":1580636284747,"mc":[{"id":"1.168215940","rc":[{"batb":[[0,1.01,10.52],[1,1.01,0]],"ltp":0.0,"tv":0.0,"id":4423910},{"batb":[[0,1.01,10.52],[1,1.01,0]],"ltp":0.0,"tv":0.0,"id":2258415}]}]}
{"op":"mcm","clk":"1001471379","pt":1580636557898,"mc":[{"id":"1.168215940","rc":[{"batb":[[0,2.12,36.97],[1,1.01,10.52]],"ltp":0.0,"tv":0.0,"id":4423910},{"batl":[[0,1.9,42.01]],"ltp":0.0,"tv":0.0,"id":2258415}]}]}
{"op":"mcm","clk":"1001471518","pt":1580636560687,"mc":[{"id":"1.168215940","rc":[{"batl":[[0,2.38,30.25]],"ltp":0.0,"tv":0.0,"id":4423910},{"batb":[[0,1.73,57.13],[1,1.01,10.52]],"ltp":0.0,"tv":0.0,"id":2258415}]}]}
{"op":"mcm","clk":"1001471591","pt":1580636561777,"mc":[{"id":"1.168215940","rc":[{"batl":[[1,3,213.45]],"ltp":0.0,"tv":0.0,"id":4423910},{"batl":[[1,2.3,309.75]],"ltp":0.0,"tv":0.0,"id":2258415}]}]}
{"op":"mcm","clk":"1001471677","pt":1580636563478,"mc":[{"id":"1.168215940","rc":[{"batb":[[0,2.12,475.01]],"ltp":0.0,"tv":0.0,"id":4423910}]}]}
{"op":"mcm","clk":"1001472214","pt":1580636574602,"mc":[{"id":"1.168215940","rc":[{"batb":[[0,1.01,10.52],[1,1.01,0]],"batl":[[0,3,213.45],[1,3,0]],"ltp":0.0,"tv":0.0,"id":4423910},{"batb":[[0,1.01,10.52],[1,1.01,0]],"batl":[[0,2.3,309.75],[1,2.3,0]],"ltp":0.0,"tv":0.0,"id":2258415}]}]}
{"op":"mcm","clk":"1001472763","pt":1580636583600,"mc":[{"id":"1.168215940","rc":[{"batb":[[0,2.14,36.13],[1,1.01,10.52]],"batl":[[0,2.42,29.41],[1,3,213.45]],"ltp":0.0,"tv":0.0,"id":4423910},{"batb":[[0,1.71,58.81],[1,1.01,10.52]],"batl":[[0,1.89,42.01],[1,2.3,309.75]],"ltp":0.0,"tv":0.0,"id":2258415}]}]}
{"op":"mcm","clk":"1001473572","pt":1580636598858,"mc":[{"id":"1.168215940","rc":[{"batb":[[0,2.14,476.09]],"ltp":0.0,"tv":0.0,"id":4423910}]}]}
{"op":"mcm","clk":"1001473924","pt":1580636606841,"mc":[{"id":"1.168215940","rc":[{"batb":[[0,2.14,36.13]],"ltp":0.0,"tv":0.0,"id":4423910}]}]}
{"op":"mcm","clk":"1001474012","pt":1580636608644,"mc":[{"id":"1.168215940","rc":[{"batb":[[0,1.01,10.52],[1,1.01,0]],"batl":[[0,3,213.45],[1,3,0]],"ltp":0.0,"tv":0.0,"id":4423910},{"batb":[[0,1.01,10.52],[1,1.01,0]],"batl":[[0,2.3,309.75],[1,2.3,0]],"ltp":0.0,"tv":0.0,"id":2258415}]}]}
{"op":"mcm","clk":"1001474300","pt":1580636615643,"mc":[{"id":"1.168215940","rc":[{"batb":[[0,2.16,36.13],[1,1.01,10.52]],"batl":[[0,2.44,28.57],[1,3,213.45]],"ltp":0.0,"tv":0.0,"id":4423910},{"batb":[[0,1.69,60.49],[1,1.01,10.52]],"batl":[[0,1.86,42.01],[1,2.3,309.75]],"ltp":0.0,"tv":0.0,"id":2258415}]}]}
{"op":"mcm","clk":"1001475422","pt":1580636640787,"mc":[{"id":"1.168215940","rc":[{"batb":[[0,1.01,10.52],[1,1.01,0]],"batl":[[0,3,213.45],[1,3,0]],"ltp":0.0,"tv":0.0,"id":4423910},{"batb":[[0,1.01,10.52],[1,1.01,0]],"batl":[[0,2.3,309.75],[1,2.3,0]],"ltp":0.0,"tv":0.0,"id":2258415}]}]}
{"op":"mcm","clk":"1001492916","pt":1580636960219,"mc":[{"id":"1.168215940","rc":[{"batl":[[0,3,213.45]],"ltp":0.0,"tv":0.0,"id":4423910},{"batl":[[0,2.3,309.75]],"ltp":0.0,"tv":0.0,"id":2258415}]}]}
{"op":"mcm","clk":"1001493218","pt":1580636964063,"mc":[{"id":"1.168215940","rc":[{"batb":[[0,2.08,38.65],[1,1.01,10.52]],"batl":[[0,2.34,31.09],[1,3,213.45]],"ltp":0.0,"tv":0.0,"id":4423910},{"batb":[[0,1.74,56.29],[1,1.01,10.52]],"batl":[[0,1.93,42.01],[1,2.3,309.75]],"ltp":0.0,"tv":0.0,"id":2258415}]}]}
{"op":"mcm","clk":"1001493585","pt":1580636969850,"mc":[{"id":"1.168215940","rc":[{"batb":[[0,2.1,132.24],[1,2.08,38.65],[2,1.01,10.52]],"ltp":0.0,"tv":0.0,"id":4423910}]}]}
{"op":"mcm","clk":"1001494058","pt":1580636977955,"mc":[{"id":"1.168215940","rc":[{"batb":[[0,2.08,38.65],[1,1.01,10.52],[2,1.01,0]],"ltp":0.0,"tv":0.0,"id":4423910}]}]}
{"op":"mcm","clk":"1001494104","pt":1580636978987,"mc":[{"id":"1.168215940","rc":[{"batb":[[0,1.01,10.52],[1,1.01,0]],"batl":[[0,3,213.45],[1,3,0]],"ltp":0.0,"tv":0.0,"id":4423910},{"batb":[[0,1.01,10.52],[1,1.01,0]],"batl":[[0,2.3,309.75],[1,2.3,0]],"ltp":0.0,"tv":0.0,"id":2258415}]}]}
{"op":"mcm","clk":"1001495029","pt":1580636993904,"mc":[{"id":"1.168215940","rc":[{"batb":[[0,2.1,37.81],[1,1.01,10.52]],"batl":[[0,2.36,30.25],[1,3,213.45]],"ltp":0.0,"tv":0.0,"id":4423910},{"batb":[[0,1.73,57.13],[1,1.01,10.52]],"batl":[[0,1.91,42.01],[1,1.97,204.83],[2,2.3,309.75]],"ltp":0.0,"tv":0.0,"id":2258415}]}]}
{"op":"mcm","clk":"1001495040","pt":1580636994107,"mc":[{"id":"1.168215940","rc":[{"batl":[[1,2.3,309.75],[2,2.3,0]],"ltp":0.0,"tv":0.0,"id":2258415}]}]}
{"op":"mcm","clk":"1001495277","pt":1580636997300,"mc":[{"id":"1.168215940","rc":[{"batb":[[0,2.14,188.46],[1,2.1,37.81],[2,1.01,10.52]],"ltp":0.0,"tv":0.0,"id":4423910}]}]}
{"op":"mcm","clk":"1001495792","pt":1580637004319,"mc":[{"id":"1.168215940","rc":[{"batb":[[0,2.1,37.81],[1,1.01,10.52],[2,1.01,0]],"ltp":0.0,"tv":0.0,"id":4423910}]}]}
{"op":"mcm","clk":"1001495856","pt":1580637005454,"mc":[{"id":"1.168215940","rc":[{"batb":[[0,1.01,10.52],[1,1.01,0]],"batl":[[0,3,213.45],[1,3,0]],"ltp":0.0,"tv":0.0,"id":4423910},{"batb":[[0,1.01,10.52],[1,1.01,0]],"batl":[[0,2.3,309.75],[1,2.3,0]],"ltp":0.0,"tv":0.0,"id":2258415}]}]}
{"op":"mcm","clk":"1001496629","pt":1580637017958,"mc":[{"id":"1.168215940","rc":[{"batb":[[0,2.14,36.13],[1,1.01,10.52]],"batl":[[0,2.42,29.41],[1,3,213.45]],"ltp":0.0,"tv":0.0,"id":4423910},{"batb":[[0,1.71,58.81],[1,1.01,10.52]],"batl":[[0,1.89,42.01],[1,2.3,309.75]],"ltp":0.0,"tv":0.0,"id":2258415}]}]}
{"op":"mcm","clk":"1001496858","pt":1580637021337,"mc":[{"id":"1.168215940","rc":[{"batb":[[0,2.16,116.53],[1,2.14,36.13],[2,1.01,10.52]],"ltp":0.0,"tv":0.0,"id":4423910}]}]}
{"op":"mcm","clk":"1001497961","pt":1580637041174,"mc":[{"id":"1.168215940","rc":[{"batb":[[0,1.01,10.52],[1,2.14,0],[2,1.01,0]],"batl":[[0,3,213.45],[1,3,0]],"ltp":0.0,"tv":0.0,"id":4423910},{"batb":[[0,1.01,10.52],[1,1.01,0]],"batl":[[0,2.3,309.75],[1,2.3,0]],"ltp":0.0,"tv":0.0,"id":2258415}]}]}
{"op":"mcm","clk":"1001498537","pt":1580637049963,"mc":[{"id":"1.168215940","rc":[{"batb":[[0,2.18,35.29],[1,1.01,10.52]],"batl":[[0,2.46,28.57],[1,3,213.45]],"ltp":0.0,"tv":0.0,"id":4423910},{"batb":[[0,1.68,61.33],[1,1.01,10.52]],"batl":[[0,1.85,42.01]],"ltp":0.0,"tv":0.0,"id":2258415}]}]}
{"op":"mcm","clk":"1001498615","pt":1580637051201,"mc":[{"id":"1.168215940","rc":[{"batl":[[1,2.16,342.82]],"ltp":0.0,"tv":0.0,"id":2258415}]}]}
{"op":"mcm","clk":"1001499053","pt":1580637059000,"mc":[{"id":"1.168215940","rc":[{"batb":[[0,1.01,10.52],[1,1.01,0]],"batl":[[0,3,213.45],[1,3,0]],"ltp":0.0,"tv":0.0,"id":4423910},{"batb":[[0,1.01,10.52],[1,1.01,0]],"batl":[[0,2.16,342.82],[1,2.16,0]],"ltp":0.0,"tv":0.0,"id":2258415}]}]}
{"op":"mcm","clk":"1001500082","pt":1580637079517,"mc":[{"id":"1.168215940","rc":[{"batl":[[0,2.04,102.63],[1,2.16,342.82]],"ltp":0.0,"tv":0.0,"id":2258415}]}]}
{"op":"mcm","clk":"1001500106","pt":1580637080215,"mc":[{"id":"1.168215940","rc":[{"batb":[[0,2.22,33.61],[1,1.01,10.52]],"batl":[[0,2.52,26.89]],"ltp":0.0,"tv":0.0,"id":4423910},{"batb":[[0,1.66,63.01],[1,1.01,10.52]],"batl":[[0,1.83,42.01]],"ltp":0.0,"tv":0.0,"id":2258415}]}]}
{"op":"mcm","clk":"1001500231","pt":1580637082936,"mc":[{"id":"1.168215940","rc":[{"batl":[[1,3.45,180.4]],"ltp":0.0,"tv":0.0,"id":4423910}]}]}
{"op":"mcm","clk":"1001500242","pt":1580637083300,"mc":[{"id":"1.168215940","rc":[{"batb":[[0,2.28,91.66],[1,2.22,33.61],[2,1.01,10.52]],"ltp":0.0,"tv":0.0,"id":4423910}]}]}
{"op":"mcm","clk":"1001500922","pt":1580637097370,"mc":[{"id":"1.168215940","rc":[{"batb":[[0,2.22,33.61],[1,1.01,10.52],[2,1.01,0]],"ltp":0.0,"tv":0.0,"id":4423910}]}]}
{"op":"mcm","clk":"1001501025","pt":1580637099634,"mc":[{"id":"1.168215940","rc":[{"batb":[[0,1.01,10.52],[1,1.01,0]],"batl":[[0,3.45,180.4],[1,3.45,0]],"ltp":0.0,"tv":0.0,"id":4423910},{"batb":[[0,1.01,10.52],[1,1.01,0]],"batl":[[0,2.16,342.82],[1,2.16,0]],"ltp":0.0,"tv":0.0,"id":2258415}]}]}
{"op":"mcm","clk":"1001502202","pt":1580637122422,"mc":[{"id":"1.168215940","rc":[{"batb":[[0,2.2,34.45],[1,1.01,10.52]],"batl":[[0,2.5,27.73],[1,3.45,180.4]],"ltp":0.0,"tv":0.0,"id":4423910},{"batb":[[0,1.67,62.17],[1,1.01,10.52]],"batl":[[0,1.84,42.01],[1,2.16,342.82]],"ltp":0.0,"tv":0.0,"id":2258415}]}]}
{"op":"mcm","clk":"1001503378","pt":1580637143151,"mc":[{"id":"1.168215940","rc":[{"batb":[[0,1.01,10.52],[1,1.01,0]],"batl":[[0,3.45,180.4],[1,3.45,0]],"ltp":0.0,"tv":0.0,"id":4423910},{"batb":[[0,1.01,10.52],[1,1.01,0]],"batl":[[0,2.16,342.82],[1,2.16,0]],"ltp":0.0,"tv":0.0,"id":2258415}]}]}
{"op":"mcm","clk":"1001504338","pt":1580637159443,"mc":[{"id":"1.168215940","rc":[{"batl":[[0,1.81,222.99]],"ltp":0.0,"tv":0.0,"id":2258415}]}]}
{"op":"mcm","clk":"1001504392","pt":1580637160571,"mc":[{"id":"1.168215940","rc":[{"batb":[[0,2.24,33.61],[1,1.01,10.52]],"batl":[[0,2.54,26.89],[1,3.45,180.4]],"ltp":0.0,"tv":0.0,"id":4423910},{"batb":[[0,1.65,63.85],[1,1.01,10.52]],"batl":[[0,1.81,265]],"ltp":0.0,"tv":0.0,"id":2258415}]}]}
{"op":"mcm","clk":"1001504445","pt":1580637161450,"mc":[{"id":"1.168215940","rc":[{"batl":[[1,2.04,383.01]],"ltp":0.0,"tv":0.0,"id":2258415}]}]}
{"op":"mcm","clk":"1001505622","pt":1580637181174,"mc":[{"id":"1.168215940","rc":[{"batb":[[0,1.01,10.52],[1,1.01,0]],"batl":[[0,3.45,180.4],[1,3.45,0]],"ltp":0.0,"tv":0.0,"id":4423910},{"batb":[[0,1.01,10.52],[1,1.01,0]],"batl":[[0,2.04,383.01],[1,2.04,0]],"ltp":0.0,"tv":0.0,"id":2258415}]}]}
{"op":"mcm","clk":"1001506966","pt":1580637205876,"mc":[{"id":"1.168215940","rc":[{"batl":[[0,2,202.02],[1,2.04,383.01]],"ltp":0.0,"tv":0.0,"id":2258415}]}]}
{"op":"mcm","clk":"1001506989","pt":1580637206341,"mc":[{"id":"1.168215940","rc":[{"batb":[[0,2.34,31.09],[1,1.01,10.52]],"batl":[[0,2.68,24.37]],"ltp":0.0,"tv":0.0,"id":4423910},{"batb":[[0,1.6,69.74],[1,1.01,10.52]],"batl":[[0,1.75,42.01]],"ltp":0.0,"tv":0.0,"id":2258415}]}]}
{"op":"mcm","clk":"1001507074","pt":1580637208040,"mc":[{"id":"1.168215940","rc":[{"batl":[[1,3.9,158.24]],"ltp":0.0,"tv":0.0,"id":4423910}]}]}
{"op":"mcm","clk":"1001507136","pt":1580637209480,"mc":[{"id":"1.168215940","rc":[{"batb":[[0,2.36,170.93],[1,2.34,31.09],[2,1.01,10.52]],"ltp":0.0,"tv":0.0,"id":4423910}]}]}
{"op":"mcm","clk":"1001511223","pt":1580637288951,"mc":[{"id":"1.168215940","rc":[{"batb":[[0,2.34,31.09],[1,1.01,10.52],[2,1.01,0]],"ltp":0.0,"tv":0.0,"id":4423910}]}]}
{"op":"mcm","clk":"1001511257","pt":1580637289459,"mc":[{"id":"1.168215940","rc":[{"batb":[[0,1.01,10.52],[1,1.01,0]],"batl":[[0,3.9,158.24],[1,3.9,0]],"ltp":0.0,"tv":0.0,"id":4423910},{"batb":[[0,1.01,10.52],[1,1.01,0]],"batl":[[0,2.04,383.01],[1,2.04,0]],"ltp":0.0,"tv":0.0,"id":2258415}]}]}
{"op":"mcm","clk":"1001512142","pt":1580637306806,"mc":[{"id":"1.168215940","rc":[{"batb":[[0,2.3,31.93],[1,1.01,10.52]],"batl":[[0,2.62,25.21]],"ltp":0.0,"tv":0.0,"id":4423910},{"batb":[[0,1.62,67.22],[1,1.01,10.52]],"batl":[[0,1.78,42.01],[1,2.04,383.01]],"ltp":0.0,"tv":0.0,"id":2258415}]}]}
{"op":"mcm","clk":"1001512218","pt":1580637307992,"mc":[{"id":"1.168215940","rc":[{"batl":[[1,3.65,170.41]],"ltp":0.0,"tv":0.0,"id":4423910}]}]}
{"op":"mcm","clk":"1001512873","pt":1580637319410,"mc":[{"id":"1.168215940","rc":[{"batb":[[0,1.01,10.52],[1,1.01,0]],"batl":[[0,3.65,170.41],[1,3.65,0]],"ltp":0.0,"tv":0.0,"id":4423910},{"batb":[[0,1.01,10.52],[1,1.01,0]],"batl":[[0,2.04,383.01],[1,2.04,0]],"ltp":0.0,"tv":0.0,"id":2258415}]}]}
{"op":"mcm","clk":"1001513104","pt":1580637324517,"mc":[{"id":"1.168215940","rc":[{"batb":[[0,2.32,31.09],[1,1.01,10.52]],"batl":[[0,2.64,25.21],[1,3.65,170.41]],"ltp":0.0,"tv":0.0,"id":4423910},{"batb":[[0,1.61,68.06],[1,1.01,10.52]],"batl":[[0,1.76,42.01],[1,2.04,383.01]],"ltp":0.0,"tv":0.0,"id":2258415}]}]}
{"op":"mcm","clk":"1001513251","pt":1580637327716,"mc":[{"id":"1.168215940","rc":[{"trd":[[1.61,135.82]],"batb":[[0,1.01,10.66],[1,1.01,0]],"ltp":1.61,"tv":135.82,"id":2258415}],"tv":135.82}]}
{"op":"mcm","clk":"1001513278","pt":1580637328127,"mc":[{"id":"1.168215940","rc":[{"batb":[[0,1.01,10.52],[1,1.01,0]],"ltp":0.0,"tv":0.0,"id":4423910},{"batl":[[0,2.04,383.01],[1,2.04,0]],"ltp":1.61,"tv":135.82,"id":2258415}]}]}
{"op":"mcm","clk":"1001513405","pt":1580637331020,"mc":[{"id":"1.168215940","rc":[{"batb":[[0,2.4,29.41],[1,1.01,10.52]],"ltp":0.0,"tv":0.0,"id":4423910},{"batb":[[0,1.61,67.36],[1,1.01,10.52]],"batl":[[0,1.72,42.01],[1,2.04,383.01]],"ltp":1.61,"tv":135.82,"id":2258415}]}]}
{"op":"mcm","clk":"1001513759","pt":1580637337944,"mc":[{"id":"1.168215940","rc":[{"batb":[[0,1.01,10.52],[1,1.01,0]],"batl":[[0,3.65,170.41],[1,3.65,0]],"ltp":0.0,"tv":0.0,"id":4423910},{"batb":[[0,1.01,10.52],[1,1.01,0]],"batl":[[0,2.04,383.01],[1,2.04,0]],"ltp":1.61,"tv":135.82,"id":2258415}]}]}
{"op":"mcm","clk":"1001514275","pt":1580637348644,"mc":[{"id":"1.168215940","rc":[{"batb":[[0,2.42,29.41],[1,1.01,10.52]],"batl":[[0,2.7,24.37],[1,3.65,170.41]],"ltp":0.0,"tv":0.0,"id":4423910},{"batb":[[0,1.59,70.58],[1,1.01,10.52]],"batl":[[0,1.71,42.01],[1,2.04,383.01]],"ltp":1.61,"tv":135.82,"id":2258415}]}]}
{"op":"mcm","clk":"1001514584","pt":1580637354996,"mc":[{"id":"1.168215940","rc":[{"batb":[[0,2.44,445.17],[1,2.42,29.41],[2,1.01,10.52]],"ltp":0.0,"tv":0.0,"id":4423910}]}]}
{"op":"mcm","clk":"1001515085","pt":1580637364766,"mc":[{"id":"1.168215940","rc":[{"trd":[[1.59,79.34]],"batb":[[0,1.59,30.9]],"ltp":1.59,"tv":215.16,"id":2258415}],"tv":215.16}]}
{"op":"mcm","clk":"1001515096","pt":1580637365074,"mc":[{"id":"1.168215940","rc":[{"batl":[[0,2.04,383.01],[1,2.04,0]],"ltp":1.59,"tv":215.16,"id":2258415}]}]}
{"op":"mcm","clk":"1001515256","pt":1580637368083,"mc":[{"id":"1.168215940","rc":[{"batb":[[0,1.59,70.39]],"batl":[[0,1.7,42.01],[1,2.04,383.01]],"ltp":1.59,"tv":215.16,"id":2258415}]}]}
{"op":"mcm","clk":"1001515935","pt":1580637379609,"mc":[{"id":"1.168215940","rc":[{"batb":[[0,1.01,10.52],[1,2.42,0],[2,1.01,0]],"batl":[[0,3.65,170.41],[1,3.65,0]],"ltp":0.0,"tv":0.0,"id":4423910},{"batb":[[0,1.01,10.52],[1,1.01,0]],"batl":[[0,2.04,383.01],[1,2.04,0]],"ltp":1.59,"tv":215.16,"id":2258415}]}]}
{"op":"mcm","clk":"1001516780","pt":1580637392512,"mc":[{"id":"1.168215940","rc":[{"batb":[[0,2.46,28.57],[1,1.01,10.52]],"batl":[[0,2.74,23.53],[1,3.65,170.41]],"ltp":0.0,"tv":0.0,"id":4423910},{"batb":[[0,1.57,73.1],[1,1.01,10.52]],"batl":[[0,1.69,42.01],[1,2.04,383.01]],"ltp":1.59,"tv":215.16,"id":2258415}]}]}
{"op":"mcm","clk":"1001517070","pt":1580637395644,"mc":[{"id":"1.168215940","rc":[{"batb":[[0,2.46,476.95]],"ltp":0.0,"tv":0.0,"id":4423910}]}]}
{"op":"mcm","clk":"1001517656","pt":1580637403714,"mc":[{"id":"1.168215940","rc":[{"batb":[[0,2.46,28.57]],"ltp":0.0,"tv":0.0,"id":4423910}]}]}
{"op":"mcm","clk":"1001517730","pt":1580637405359,"mc":[{"id":"1.168215940","rc":[{"batb":[[0,1.01,10.52],[1,1.01,0]],"batl":[[0,3.65,170.41],[1,3.65,0]],"ltp":0.0,"tv":0.0,"id":4423910},{"batb":[[0,1.01,10.52],[1,1.01,0]],"batl":[[0,2.04,383.01],[1,2.04,0]],"ltp":1.59,"tv":215.16,"id":2258415}]}]}
{"op":"mcm","clk":"1001518152","pt":1580637412241,"mc":[{"id":"1.168215940","rc":[{"batb":[[0,2.5,27.73],[1,1.01,10.52]],"batl":[[0,2.8,22.69],[1,3.65,170.41]],"ltp":0.0,"tv":0.0,"id":4423910},{"batb":[[0,1.56,74.78],[1,1.01,10.52]],"batl":[[0,1.67,42.01],[1,2.04,383.01]],"ltp":1.59,"tv":215.16,"id":2258415}]}]}
{"op":"mcm","clk":"1001519205","pt":1580637423758,"mc":[{"id":"1.168215940","rc":[{"batb":[[0,2.52,445.99],[1,2.5,27.73],[2,1.01,10.52]],"ltp":0.0,"tv":0.0,"id":4423910}]}]}
{"op":"mcm","clk":"1001520280","pt":1580637439865,"mc":[{"id":"1.168215940","rc":[{"batb":[[0,2.5,27.73],[1,1.01,10.52],[2,1.01,0]],"ltp":0.0,"tv":0.0,"id":4423910}]}]}
{"op":"mcm","clk":"1001520365","pt":1580637441269,"mc":[{"id":"1.168215940","rc":[{"batb":[[0,1.01,10.52],[1,1.01,0]],"batl":[[0,3.65,170.41],[1,3.65,0]],"ltp":0.0,"tv":0.0,"id":4423910},{"batb":[[0,1.01,10.52],[1,1.01,0]],"batl":[[0,2.04,383.01],[1,2.04,0]],"ltp":1.59,"tv":215.16,"id":2258415}]}]}
{"op":"mcm","clk":"1001520746","pt":1580637447206,"mc":[{"id":"1.168215940","rc":[{"batl":[[0,3.25,422.3],[1,3.65,170.41]],"ltp":0.0,"tv":0.0,"id":4423910}]}]}
{"op":"mcm","clk":"1001520830","pt":1580637448299,"mc":[{"id":"1.168215940","rc":[{"batb":[[0,2.48,27.73],[1,1.01,10.52]],"batl":[[0,2.78,23.53],[1,3.25,422.3],[2,3.65,170.41]],"ltp":0.0,"tv":0.0,"id":4423910},{"batb":[[0,1.56,74.78],[1,1.01,10.52]],"batl":[[0,1.68,42.01],[1,2.04,383.01]],"ltp":1.59,"tv":215.16,"id":2258415}]}]}
{"op":"mcm","clk":"1001521611","pt":1580637458532,"mc":[{"id":"1.168215940","rc":[{"batl":[[1,3.65,170.41],[2,3.65,0]],"ltp":0.0,"tv":0.0,"id":4423910}]}]}
{"op":"mcm","clk":"1001521666","pt":1580637459311,"mc":[{"id":"1.168215940","rc":[{"batb":[[0,1.01,10.52],[1,1.01,0]],"batl":[[0,3.65,170.41],[1,3.65,0]],"ltp":0.0,"tv":0.0,"id":4423910},{"batb":[[0,1.01,10.52],[1,1.01,0]],"batl":[[0,2.04,383.01],[1,2.04,0]],"ltp":1.59,"tv":215.16,"id":2258415}]}]}
{"op":"mcm","clk":"1001522078","pt":1580637464829,"mc":[{"id":"1.168215940","rc":[{"batb":[[0,2.46,28.57],[1,1.01,10.52]],"batl":[[0,2.76,23.53],[1,3.65,170.41]],"ltp":0.0,"tv":0.0,"id":4423910},{"batb":[[0,1.57,73.1],[1,1.01,10.52]],"batl":[[0,1.69,42.01],[1,2.04,383.01]],"ltp":1.59,"tv":215.16,"id":2258415}]}]}
{"op":"mcm","clk":"1001522742","pt":1580637475755,"mc":[{"id":"1.168215940","rc":[{"batb":[[0,1.01,10.52],[1,1.01,0]],"batl":[[0,3.65,170.41],[1,3.65,0]],"ltp":0.0,"tv":0.0,"id":4423910},{"batb":[[0,1.01,10.52],[1,1.01,0]],"batl":[[0,2.04,383.01],[1,2.04,0]],"ltp":1.59,"tv":215.16,"id":2258415}]}]}
{"op":"mcm","clk":"1001523599","pt":1580637490376,"mc":[{"id":"1.168215940","rc":[{"batb":[[0,2.5,27.73],[1,1.01,10.52]],"batl":[[0,2.8,22.69],[1,3.65,170.41]],"ltp":0.0,"tv":0.0,"id":4423910},{"batb":[[0,1.56,74.78],[1,1.01,10.52]],"batl":[[0,1.67,42.01],[1,2.04,383.01]],"ltp":1.59,"tv":215.16,"id":2258415}]}]}
{"op":"mcm","clk":"1001523784","pt":1580637493354,"mc":[{"id":"1.168215940","rc":[{"batb":[[0,2.5,474.17]],"ltp":0.0,"tv":0.0,"id":4423910}]}]}
{"op":"mcm","clk":"1001524387","pt":1580637505853,"mc":[{"id":"1.168215940","rc":[{"batb":[[0,2.5,27.73]],"ltp":0.0,"tv":0.0,"id":4423910}]}]}
{"op":"mcm","clk":"1001524473","pt":1580637507289,"mc":[{"id":"1.168215940","rc":[{"batb":[[0,1.01,10.52],[1,1.01,0]],"batl":[[0,3.65,170.41],[1,3.65,0]],"ltp":0.0,"tv":0.0,"id":4423910},{"batb":[[0,1.01,10.52],[1,1.01,0]],"batl":[[0,2.04,383.01],[1,2.04,0]],"ltp":1.59,"tv":215.16,"id":2258415}]}]}
{"op":"mcm","clk":"1001525138","pt":1580637518277,"mc":[{"id":"1.168215940","rc":[{"batb":[[0,2.48,27.73],[1,1.01,10.52]],"batl":[[0,2.78,23.53],[1,3.65,170.41]],"ltp":0.0,"tv":0.0,"id":4423910},{"batb":[[0,1.56,74.78],[1,1.01,10.52]],"batl":[[0,1.68,42.01],[1,2.04,383.01]],"ltp":1.59,"tv":215.16,"id":2258415}]}]}
{"op":"mcm","clk":"1001525996","pt":1580637533429,"mc":[{"id":"1.168215940","rc":[{"batb":[[0,1.01,10.52],[1,1.01,0]],"batl":[[0,3.65,170.41],[1,3.65,0]],"ltp":0.0,"tv":0.0,"id":4423910},{"batb":[[0,1.01,10.52],[1,1.01,0]],"batl":[[0,2.04,383.01],[1,2.04,0]],"ltp":1.59,"tv":215.16,"id":2258415}]}]}
{"op":"mcm","clk":"1001527171","pt":1580637552508,"mc":[{"id":"1.168215940","rc":[{"batb":[[0,2.52,26.89],[1,1.01,10.52]],"batl":[[0,2.82,22.69],[1,3.65,170.41]],"ltp":0.0,"tv":0.0,"id":4423910},{"batb":[[0,1.55,75.62],[1,1.01,10.52]],"batl":[[0,1.66,42.01],[1,2.04,383.01]],"ltp":1.59,"tv":215.16,"id":2258415}]}]}
{"op":"mcm","clk":"1001527350","pt":1580637555652,"mc":[{"id":"1.168215940","rc":[{"batb":[[1,2.5,449.8],[2,1.01,10.52]],"ltp":0.0,"tv":0.0,"id":4423910}]}]}
{"op":"mcm","clk":"1001527892","pt":1580637564852,"mc":[{"id":"1.168215940","rc":[{"batb":[[1,1.01,10.52],[2,1.01,0]],"ltp":0.0,"tv":0.0,"id":4423910}]}]}
{"op":"mcm","clk":"1001527926","pt":1580637565474,"mc":[{"id":"1.168215940","rc":[{"batb":[[0,1.01,10.52],[1,1.01,0]],"batl":[[0,3.65,170.41],[1,3.65,0]],"ltp":0.0,"tv":0.0,"id":4423910},{"batb":[[0,1.01,10.52],[1,1.01,0]],"batl":[[0,2.04,383.01],[1,2.04,0]],"ltp":1.59,"tv":215.16,"id":2258415}]}]}
{"op":"mcm","clk":"1001529004","pt":1580637578775,"mc":[{"id":"1.168215940","rc":[{"batb":[[0,2.54,26.89],[1,2.52,459.74],[2,1.01,10.52]],"batl":[[0,2.86,21.85]],"ltp":0.0,"tv":0.0,"id":4423910},{"batb":[[0,1.54,77.3],[1,1.01,10.52]],"batl":[[0,1.65,42.01]],"ltp":1.59,"tv":215.16,"id":2258415}]}]}
{"op":"mcm","clk":"1001529134","pt":1580637580479,"mc":[{"id":"1.168215940","rc":[{"batl":[[1,4.2,148.03]],"ltp":0.0,"tv":0.0,"id":4423910},{"batl":[[1,1.89,435.28]],"ltp":1.59,"tv":215.16,"id":2258415}]}]}
{"op":"mcm","clk":"1001530533","pt":1580637600812,"mc":[{"id":"1.168215940","rc":[{"batb":[[1,1.01,10.52],[2,1.01,0]],"ltp":0.0,"tv":0.0,"id":4423910}]}]}
{"op":"mcm","clk":"1001530619","pt":1580637601571,"mc":[{"id":"1.168215940","rc":[{"batb":[[0,1.01,10.52],[1,1.01,0]],"batl":[[0,4.2,148.03],[1,4.2,0]],"ltp":0.0,"tv":0.0,"id":4423910},{"batb":[[0,1.01,10.52],[1,1.01,0]],"batl":[[0,1.89,435.28],[1,1.89,0]],"ltp":1.59,"tv":215.16,"id":2258415}]}]}
{"op":"mcm","clk":"1001532289","pt":1580637622444,"mc":[{"id":"1.168215940","rc":[{"batb":[[0,2.54,26.89],[1,1.01,10.52]],"batl":[[0,2.84,22.69],[1,4.2,148.03]],"ltp":0.0,"tv":0.0,"id":4423910},{"batb":[[0,1.54,77.3],[1,1.01,10.52]],"batl":[[0,1.65,42.01],[1,1.89,435.28]],"ltp":1.59,"tv":215.16,"id":2258415}]}]}
{"op":"mcm","clk":"1001533491","pt":1580637637420,"mc":[{"id":"1.168215940","rc":[{"batb":[[0,1.01,10.52],[1,1.01,0]],"batl":[[0,4.2,148.03],[1,4.2,0]],"ltp":0.0,"tv":0.0,"id":4423910},{"batb":[[0,1.01,10.52],[1,1.01,0]],"batl":[[0,1.89,435.28],[1,1.89,0]],"ltp":1.59,"tv":215.16,"id":2258415}]}]}
{"op":"mcm","clk":"1001534043","pt":1580637644659,"mc":[{"id":"1.168215940","rc":[{"batb":[[0,2.56,26.89],[1,1.01,10.52]],"batl":[[0,2.88,21.85],[1,4.2,148.03]],"ltp":0.0,"tv":0.0,"id":4423910},{"batb":[[0,1.53,78.98],[1,1.01,10.52]],"batl":[[0,1.64,42.01],[1,1.89,435.28]],"ltp":1.59,"tv":215.16,"id":2258415}]}]}
{"op":"mcm","clk":"1001535205","pt":1580637659538,"mc":[{"id":"1.168215940","rc":[{"batb":[[0,1.01,10.52],[1,1.01,0]],"batl":[[0,4.2,148.03],[1,4.2,0]],"ltp":0.0,"tv":0.0,"id":4423910},{"batb":[[0,1.01,10.52],[1,1.01,0]],"batl":[[0,1.89,435.28],[1,1.89,0]],"ltp":1.59,"tv":215.16,"id":2258415}]}]}
{"op":"mcm","clk":"1001536731","pt":1580637677759,"mc":[{"id":"1.168215940","rc":[{"batl":[[0,3.9,158.24]],"ltp":0.0,"tv":0.0,"id":4423910}]}]}
{"op":"mcm","clk":"1001536919","pt":1580637680533,"mc":[{"id":"1.168215940","rc":[{"batb":[[0,2.54,26.89],[1,1.01,10.52]],"batl":[[0,2.86,21.85],[1,3.9,158.24]],"ltp":0.0,"tv":0.0,"id":4423910},{"batb":[[0,1.54,77.3],[1,1.01,10.52]],"batl":[[0,1.65,42.01],[1,1.89,435.28]],"ltp":1.59,"tv":215.16,"id":2258415}]}]}
{"op":"mcm","clk":"1001538439","pt":1580637699656,"mc":[{"id":"1.168215940","rc":[{"batb":[[0,1.01,10.52],[1,1.01,0]],"batl":[[0,3.9,158.24],[1,3.9,0]],"ltp":0.0,"tv":0.0,"id":4423910},{"batb":[[0,1.01,10.52],[1,1.01,0]],"batl":[[0,1.89,435.28],[1,1.89,0]],"ltp":1.59,"tv":215.16,"id":2258415}]}]}
{"op":"mcm","clk":"1001539899","pt":1580637718502,"mc":[{"id":"1.168215940","rc":[{"batb":[[0,2.52,26.89],[1,1.01,10.52]],"batl":[[0,2.84,22.69]],"ltp":0.0,"tv":0.0,"id":4423910},{"batb":[[0,1.55,75.62],[1,1.01,10.52]],"batl":[[0,1.66,42.01],[1,1.89,435.28]],"ltp":1.59,"tv":215.16,"id":2258415}]}]}
{"op":"mcm","clk":"1001539957","pt":1580637719381,"mc":[{"id":"1.168215940","rc":[{"batl":[[1,3.65,170.41]],"ltp":0.0,"tv":0.0,"id":4423910}]}]}
{"op":"mcm","clk":"1001546975","pt":1580637797897,"mc":[{"id":"1.168215940","rc":[{"batb":[[0,1.01,10.52],[1,1.01,0]],"batl":[[0,3.65,170.41],[1,3.65,0]],"ltp":0.0,"tv":0.0,"id":4423910},{"batb":[[0,1.01,10.52],[1,1.01,0]],"batl":[[0,1.89,435.28],[1,1.89,0]],"ltp":1.59,"tv":215.16,"id":2258415}]}]}
{"op":"mcm","clk":"1001547310","pt":1580637802716,"mc":[{"id":"1.168215940","rc":[{"batb":[[0,2.54,26.89],[1,1.01,10.52]],"batl":[[0,2.86,21.85],[1,3.65,170.41]],"ltp":0.0,"tv":0.0,"id":4423910},{"batb":[[0,1.54,77.3],[1,1.01,10.52]],"batl":[[0,1.64,42.01],[1,1.89,435.28]],"ltp":1.59,"tv":215.16,"id":2258415}]}]}
{"op":"mcm","clk":"1001547835","pt":1580637809927,"mc":[{"id":"1.168215940","rc":[{"batb":[[0,1.01,10.52],[1,1.01,0]],"batl":[[0,3.65,170.41],[1,3.65,0]],"ltp":0.0,"tv":0.0,"id":4423910},{"batb":[[0,1.01,10.52],[1,1.01,0]],"batl":[[0,1.89,435.28],[1,1.89,0]],"ltp":1.59,"tv":215.16,"id":2258415}]}]}
{"op":"mcm","clk":"1001549104","pt":1580637824758,"mc":[{"id":"1.168215940","rc":[{"batb":[[0,2.58,26.05],[1,2.52,449.49],[2,1.01,10.52]],"batl":[[0,2.9,21.85],[1,3.65,170.41]],"ltp":0.0,"tv":0.0,"id":4423910},{"batb":[[0,1.53,78.98],[1,1.01,10.52]],"batl":[[0,1.63,42.01],[1,1.89,435.28]],"ltp":1.59,"tv":215.16,"id":2258415}]}]}
{"op":"mcm","clk":"1001549182","pt":1580637825661,"mc":[{"id":"1.168215940","rc":[{"batb":[[1,1.01,10.52],[2,1.01,0]],"ltp":0.0,"tv":0.0,"id":4423910}]}]}
{"op":"mcm","clk":"1001549387","pt":1580637828164,"mc":[{"id":"1.168215940","rc":[{"batb":[[1,2.52,459.74],[2,1.01,10.52]],"ltp":0.0,"tv":0.0,"id":4423910}]}]}
{"op":"mcm","clk":"1001550041","pt":1580637835686,"mc":[{"id":"1.168215940","rc":[{"batb":[[0,1.01,10.52],[1,2.52,0],[2,1.01,0]],"batl":[[0,3.65,170.41],[1,3.65,0]],"ltp":0.0,"tv":0.0,"id":4423910},{"batb":[[0,1.01,10.52],[1,1.01,0]],"batl":[[0,1.89,435.28],[1,1.89,0]],"ltp":1.59,"tv":215.16,"id":2258415}]}]}
{"op":"mcm","clk":"1001550871","pt":1580637844883,"mc":[{"id":"1.168215940","rc":[{"batb":[[0,2.52,26.89],[1,1.01,10.52]],"batl":[[0,2.82,22.69],[1,3.65,170.41]],"ltp":0.0,"tv":0.0,"id":4423910},{"batb":[[0,1.55,75.62],[1,1.01,10.52]],"batl":[[0,1.66,42.01],[1,1.89,435.28]],"ltp":1.59,"tv":215.16,"id":2258415}]}]}
{"op":"mcm","clk":"1001551813","pt":1580637855664,"mc":[{"id":"1.168215940","rc":[{"batb":[[0,1.01,10.52],[1,1.01,0]],"batl":[[0,3.65,170.41],[1,3.65,0]],"ltp":0.0,"tv":0.0,"id":4423910},{"batb":[[0,1.01,10.52],[1,1.01,0]],"batl":[[0,1.89,435.28],[1,1.89,0]],"ltp":1.59,"tv":215.16,"id":2258415}]}]}
{"op":"mcm","clk":"1001553785","pt":1580637877690,"mc":[{"id":"1.168215940","rc":[{"batb":[[0,2.5,456.64],[1,1.01,10.52]],"ltp":0.0,"tv":0.0,"id":4423910}]}]}
{"op":"mcm","clk":"1001553903","pt":1580637878886,"mc":[{"id":"1.168215940","rc":[{"batb":[[0,2.54,26.89],[1,2.5,456.64],[2,1.01,10.52]],"batl":[[0,2.86,21.85],[1,3.65,170.41]],"ltp":0.0,"tv":0.0,"id":4423910},{"batb":[[0,1.54,77.3],[1,1.01,10.52]],"batl":[[0,1.65,42.01],[1,1.89,435.28]],"ltp":1.59,"tv":215.16,"id":2258415}]}]}
{"op":"mcm","clk":"1001555735","pt":1580637899682,"mc":[{"id":"1.168215940","rc":[{"batb":[[0,1.01,10.52],[1,2.5,0],[2,1.01,0]],"batl":[[0,3.65,170.41],[1,3.65,0]],"ltp":0.0,"tv":0.0,"id":4423910},{"batb":[[0,1.01,10.52],[1,1.01,0]],"batl":[[0,1.89,435.28],[1,1.89,0]],"ltp":1.59,"tv":215.16,"id":2258415}]}]}
{"op":"mcm","clk":"1001557252","pt":1580637916665,"mc":[{"id":"1.168215940","rc":[{"batb":[[0,2.48,27.73],[1,1.01,10.52]],"batl":[[0,2.8,22.69],[1,3.65,170.41]],"ltp":0.0,"tv":0.0,"id":4423910},{"batb":[[0,1.56,74.78],[1,1.01,10.52]],"batl":[[0,1.67,42.01],[1,1.89,435.28]],"ltp":1.59,"tv":215.16,"id":2258415}]}]}
{"op":"mcm","clk":"1001557984","pt":1580637925789,"mc":[{"id":"1.168215940","rc":[{"batb":[[0,1.01,10.52],[1,1.01,0]],"ltp":0.0,"tv":0.0,"id":4423910}]}]}
{"op":"mcm","clk":"1001558237","pt":1580637928707,"mc":[{"id":"1.168215940","rc":[{"batb":[[0,2.5,27.73],[1,1.01,10.52]],"ltp":0.0,"tv":0.0,"id":4423910}]}]}
{"op":"mcm","clk":"1001558647","pt":1580637933703,"mc":[{"id":"1.168215940","rc":[{"batb":[[0,1.01,10.52],[1,1.01,0]],"batl":[[0,3.65,170.41],[1,3.65,0]],"ltp":0.0,"tv":0.0,"id":4423910},{"batb":[[0,1.01,10.52],[1,1.01,0]],"batl":[[0,1.89,435.28],[1,1.89,0]],"ltp":1.59,"tv":215.16,"id":2258415}]}]}
{"op":"mcm","clk":"1001559144","pt":1580637939532,"mc":[{"id":"1.168215940","rc":[{"batb":[[0,1.55,168.65],[1,1.54,154.42],[2,1.01,10.52]],"batl":[[0,1.6,133.51],[1,1.61,129.36],[2,1.89,435.28]],"ltp":1.59,"tv":215.16,"id":2258415}]}]}
{"op":"mcm","clk":"1001559237","pt":1580637940633,"mc":[{"id":"1.168215940","rc":[{"batb":[[0,2.52,26.89],[1,1.01,10.52]],"batl":[[0,2.82,22.69],[1,3.65,170.41]],"ltp":0.0,"tv":0.0,"id":4423910},{"batb":[[0,1.55,244.27]],"batl":[[2,1.66,42.01]],"ltp":1.59,"tv":215.16,"id":2258415}]}]}
{"op":"mcm","clk":"1001559406","pt":1580637942399,"mc":[{"id":"1.168215940","rc":[{"batb":[[1,2.5,449.8],[2,1.01,10.52]],"ltp":0.0,"tv":0.0,"id":4423910}]}]}
{"op":"mcm","clk":"1001561992","pt":1580637970699,"mc":[{"id":"1.168215940","rc":[{"trd":[[1.55,168.04]],"batb":[[0,1.55,160.25]],"ltp":1.55,"tv":383.2,"id":2258415}],"tv":383.2}]}
{"op":"mcm","clk":"1001562302","pt":1580637974110,"mc":[{"id":"1.168215940","rc":[{"batb":[[0,1.55,219.49]],"batl":[[0,1.6,157.55]],"ltp":1.55,"tv":383.2,"id":2258415}]}]}
{"op":"mcm","clk":"1001563273","pt":1580637985755,"mc":[{"id":"1.168215940","rc":[{"batb":[[0,2.5,449.8],[1,1.01,10.52],[2,1.01,0]],"batl":[[0,3.65,170.41],[1,3.65,0]],"ltp":0.0,"tv":0.0,"id":4423910},{"batb":[[0,1.55,143.87]],"batl":[[2,1.89,435.28]],"ltp":1.55,"tv":383.2,"id":2258415}]}]}
{"op":"mcm","clk":"1001578769","pt":1580638165790,"mc":[{"id":"1.168215940","rc":[{"batb":[[0,1.01,10.52],[1,1.01,0]],"ltp":0.0,"tv":0.0,"id":4423910},{"batl":[[0,1.61,129.36],[1,1.89,435.28],[2,1.89,0]],"ltp":1.55,"tv":383.2,"id":2258415}]}]}
{"op":"mcm","clk":"1001578981","pt":1580638168514,"mc":[{"id":"1.168215940","rc":[{"batb":[[0,1.55,207.99]],"batl":[[0,1.61,224.37],[1,1.62,126.01],[2,1.89,435.28]],"ltp":1.55,"tv":383.2,"id":2258415}]}]}
{"op":"mcm","clk":"1001589093","pt":1580638278802,"mc":[{"id":"1.168215940","rc":[{"batb":[[0,1.01,10.52],[1,1.54,0],[2,1.01,0]],"batl":[[0,1.89,435.28],[1,1.62,0],[2,1.89,0]],"ltp":1.55,"tv":383.2,"id":2258415}]}]}
{"op":"mcm","clk":"1001589312","pt":1580638281400,"mc":[{"id":"1.168215940","rc":[{"batb":[[0,1.44,252.83],[1,1.43,210.24],[2,1.01,10.51]],"batl":[[0,1.69,156.01],[1,1.71,210.53],[2,1.89,435.28]],"ltp":1.55,"tv":383.2,"id":2258415}]}]}
{"op":"mcm","clk":"1001589480","pt":1580638282969,"mc":[{"id":"1.168215940","rc":[{"batb":[[0,1.01,10.52],[1,1.43,0],[2,1.01,0]],"ltp":1.55,"tv":383.2,"id":2258415}]}]}
{"op":"mcm","clk":"1001589947","pt":1580638285916,"mc":[{"id":"1.168215940","rc":[{"batl":[[2,1.89,0]],"ltp":1.55,"tv":383.2,"id":2258415}]}]}
{"op":"mcm","clk":"1001590042","pt":1580638286797,"mc":[{"id":"1.168215940","rc":[{"batb":[[0,2.38,30.25],[1,1.01,10.52]],"batl":[[0,2.66,25.21]],"ltp":0.0,"tv":0.0,"id":4423910},{"batb":[[0,1.63,159.14],[1,1.62,127.31],[2,1.6,69.74]],"batl":[[1,1.71,252.54]],"ltp":1.55,"tv":383.2,"id":2258415}]}]}
{"op":"mcm","clk":"1001590326","pt":1580638289827,"mc":[{"id":"1.168215940","rc":[{"batl":[[1,3.3,191.92]],"ltp":0.0,"tv":0.0,"id":4423910},{"batl":[[2,2.16,342.82]],"ltp":1.55,"tv":383.2,"id":2258415}]}]}
{"op":"mcm","clk":"1001590777","pt":1580638294695,"mc":[{"id":"1.168215940","rc":[{"batb":[[0,1.6,69.74],[1,1.01,10.52],[2,1.6,0]],"batl":[[0,1.71,42.01],[1,2.16,342.82],[2,2.16,0]],"ltp":1.55,"tv":383.2,"id":2258415}]}]}
{"op":"mcm","clk":"1001590891","pt":1580638295888,"mc":[{"id":"1.168215940","rc":[{"batb":[[0,1.01,10.52],[1,1.01,0]],"batl":[[0,3.3,191.92],[1,3.3,0]],"ltp":0.0,"tv":0.0,"id":4423910},{"batb":[[0,1.01,10.52],[1,1.01,0]],"batl":[[0,2.16,342.82],[1,2.16,0]],"ltp":1.55,"tv":383.2,"id":2258415}]}]}
{"op":"mcm","clk":"1001591418","pt":1580638301897,"mc":[{"id":"1.168215940","rc":[{"batb":[[0,1.61,147.58],[1,1.6,133.24],[2,1.01,10.52]],"batl":[[0,1.67,192.28],[1,1.69,218.91],[2,2.16,342.82]],"ltp":1.55,"tv":383.2,"id":2258415}]}]}
{"op":"mcm","clk":"1001591500","pt":1580638302842,"mc":[{"id":"1.168215940","rc":[{"batb":[[0,1.01,10.52],[1,1.6,0],[2,1.01,0]],"batl":[[0,2.16,342.82],[1,1.69,0],[2,2.16,0]],"ltp":1.55,"tv":383.2,"id":2258415}]}]}
{"op":"mcm","clk":"1001592021","pt":1580638305843,"mc":[{"id":"1.168215940","rc":[{"batb":[[0,1.53,169.93],[1,1.52,162.42],[2,1.01,10.52]],"batl":[[0,1.77,200.19],[1,1.79,180.82],[2,2.16,342.82]],"ltp":1.55,"tv":383.2,"id":2258415}]}]}
{"op":"mcm","clk":"1001592240","pt":1580638307600,"mc":[{"id":"1.168215940","rc":[{"batl":[[0,2.16,342.82],[1,1.79,0],[2,2.16,0]],"ltp":1.55,"tv":383.2,"id":2258415}]}]}
{"op":"mcm","clk":"1001592662","pt":1580638310942,"mc":[{"id":"1.168215940","rc":[{"batb":[[0,2.58,26.05],[1,1.01,10.52]],"batl":[[0,2.9,21.85]],"ltp":0.0,"tv":0.0,"id":4423910},{"batb":[[0,1.53,248.91]],"batl":[[0,1.58,160.47],[1,1.59,135.1],[2,1.63,42.01]],"ltp":1.55,"tv":383.2,"id":2258415}]}]}
{"op":"mcm","clk":"1001592954","pt":1580638313541,"mc":[{"id":"1.168215940","rc":[{"batl":[[1,3.65,170.41]],"ltp":0.0,"tv":0.0,"id":4423910}]}]}
{"op":"mcm","clk":"1001594087","pt":1580638322576,"mc":[{"id":"1.168215940","rc":[{"batb":[[0,1.53,78.98],[1,1.01,10.52],[2,1.01,0]],"batl":[[0,1.63,42.01],[1,2.04,383.01],[2,1.63,0]],"ltp":1.55,"tv":383.2,"id":2258415}]}]}
{"op":"mcm","clk":"1001594261","pt":1580638323879,"mc":[{"id":"1.168215940","rc":[{"batb":[[0,1.01,10.52],[1,1.01,0]],"batl":[[0,3.65,170.41],[1,3.65,0]],"ltp":0.0,"tv":0.0,"id":4423910},{"batb":[[0,1.01,10.52],[1,1.01,0]],"batl":[[0,2.04,383.01],[1,2.04,0]],"ltp":1.55,"tv":383.2,"id":2258415}]}]}
{"op":"mcm","clk":"1001594413","pt":1580638325180,"mc":[{"id":"1.168215940","rc":[{"batb":[[0,1.4,268.47],[1,1.39,239.12],[2,1.01,10.51]],"batl":[[0,1.68,139.23],[1,1.7,214.84],[2,2.04,383.01]],"ltp":1.55,"tv":383.2,"id":2258415}]}]}
{"op":"mcm","clk":"1001594612","pt":1580638326600,"mc":[{"id":"1.168215940","rc":[{"batb":[[0,1.01,10.52],[1,1.39,0],[2,1.01,0]],"ltp":1.55,"tv":383.2,"id":2258415}]}]}
{"op":"mcm","clk":"1001594968","pt":1580638329651,"mc":[{"id":"1.168215940","rc":[{"batb":[[0,1.62,189.99],[1,1.61,130.35],[2,1.01,10.52]],"ltp":1.55,"tv":383.2,"id":2258415}]}]}
{"op":"mcm","clk":"1001595085","pt":1580638330861,"mc":[{"id":"1.168215940","rc":[{"batb":[[0,2.4,29.41],[1,1.01,10.52]],"batl":[[0,2.68,24.37]],"ltp":0.0,"tv":0.0,"id":4423910},{"batb":[[2,1.59,70.58]],"batl":[[2,1.71,42.01]],"ltp":1.55,"tv":383.2,"id":2258415}]}]}
{"op":"mcm","clk":"1001595290","pt":1580638332785,"mc":[{"id":"1.168215940","rc":[{"batl":[[1,3.3,191.92]],"ltp":0.0,"tv":0.0,"id":4423910}]}]}
{"op":"mcm","clk":"1001595905","pt":1580638337867,"mc":[{"id":"1.168215940","rc":[{"batb":[[0,1.01,10.52],[1,1.01,0]],"batl":[[0,3.3,191.92],[1,3.3,0]],"ltp":0.0,"tv":0.0,"id":4423910},{"batb":[[0,1.01,10.52],[1,1.61,0],[2,1.59,0]],"batl":[[0,2.04,383.01],[1,1.7,0],[2,1.71,0]],"ltp":1.55,"tv":383.2,"id":2258415}]}]}
{"op":"mcm","clk":"1001596590","pt":1580638343679,"mc":[{"id":"1.168215940","rc":[{"batb":[[0,1.6,135.3],[1,1.59,136.35],[2,1.01,10.52]],"batl":[[0,1.66,217.22],[1,1.68,223.23],[2,2.04,383.01]],"ltp":1.55,"tv":383.2,"id":2258415}]}]}
{"op":"mcm","clk":"1001597130","pt":1580638347683,"mc":[{"id":"1.168215940","rc":[{"batb":[[0,1.01,10.52],[1,1.59,0],[2,1.01,0]],"batl":[[0,2.04,383.01],[1,1.68,0],[2,2.04,0]],"ltp":1.55,"tv":383.2,"id":2258415}]}]}
{"op":"mcm","clk":"1001597546","pt":1580638350713,"mc":[{"id":"1.168215940","rc":[{"batb":[[0,1.51,132.87],[1,1.5,171.08],[2,1.01,10.52]],"batl":[[0,1.77,154.76],[1,1.79,180.97],[2,2.04,383.01]],"ltp":1.55,"tv":383.2,"id":2258415}]}]}
{"op":"mcm","clk":"1001597882","pt":1580638353423,"mc":[{"id":"1.168215940","rc":[{"batb":[[0,1.01,10.52],[1,1.5,0],[2,1.01,0]],"batl":[[0,2.04,383.01],[1,1.79,0],[2,2.04,0]],"ltp":1.55,"tv":383.2,"id":2258415}]}]}
{"op":"mcm","clk":"1001598257","pt":1580638356807,"mc":[{"id":"1.168215940","rc":[{"batb":[[0,2.3,31.93],[1,1.01,10.52]],"batl":[[0,2.56,26.89],[1,3.3,191.92]],"ltp":0.0,"tv":0.0,"id":4423910},{"batb":[[0,1.7,178.84],[1,1.68,222.1],[2,1.64,65.54]],"batl":[[0,1.77,196.77],[1,1.79,180.97],[2,2.04,383.01]],"ltp":1.55,"tv":383.2,"id":2258415}]}]}
{"op":"mcm","clk":"1001599000","pt":1580638364809,"mc":[{"id":"1.168215940","rc":[{"batb":[[0,1.64,65.54],[1,1.01,10.52],[2,1.64,0]],"batl":[[0,1.77,42.01],[1,2.04,383.01],[2,2.04,0]],"ltp":1.55,"tv":383.2,"id":2258415}]}]}
{"op":"mcm","clk":"1001599094","pt":1580638365850,"mc":[{"id":"1.168215940","rc":[{"batb":[[0,1.01,10.52],[1,1.01,0]],"batl":[[0,3.3,191.92],[1,3.3,0]],"ltp":0.0,"tv":0.0,"id":4423910},{"batb":[[0,1.01,10.52],[1,1.01,0]],"batl":[[0,2.04,383.01],[1,2.04,0]],"ltp":1.55,"tv":383.2,"id":2258415}]}]}
{"op":"mcm","clk":"1001599252","pt":1580638367465,"mc":[{"id":"1.168215940","rc":[{"batb":[[0,1.63,158.32],[1,1.62,127.29],[2,1.01,10.52]],"batl":[[0,1.82,135.21],[1,1.84,165.86],[2,2.04,383.01]],"ltp":1.55,"tv":383.2,"id":2258415}]}]}
{"op":"mcm","clk":"1001599367","pt":1580638368571,"mc":[{"id":"1.168215940","rc":[{"batb":[[0,1.01,10.52],[1,1.62,0],[2,1.01,0]],"ltp":1.55,"tv":383.2,"id":2258415}]}]}
{"op":"mcm","clk":"1001599555","pt":1580638370668,"mc":[{"id":"1.168215940","rc":[{"batl":[[2,2.04,0]],"ltp":1.55,"tv":383.2,"id":2258415}]}]}
{"op":"mcm","clk":"1001599670","pt":1580638371869,"mc":[{"id":"1.168215940","rc":[{"batb":[[0,1.75,145.42],[1,1.73,200.49],[2,1.01,10.52]],"ltp":1.55,"tv":383.2,"id":2258415}]}]}
{"op":"mcm","clk":"1001599758","pt":1580638372861,"mc":[{"id":"1.168215940","rc":[{"batb":[[0,2.24,33.61],[1,1.01,10.52]],"batl":[[0,2.48,27.73]],"ltp":0.0,"tv":0.0,"id":4423910},{"batb":[[2,1.67,62.17]],"batl":[[0,1.81,42.01],[1,1.82,135.21],[2,1.84,165.86]],"ltp":1.55,"tv":383.2,"id":2258415}]}]}
{"op":"mcm","clk":"1001599899","pt":1580638374262,"mc":[{"id":"1.168215940","rc":[{"batl":[[1,3,213.45]],"ltp":0.0,"tv":0.0,"id":4423910}]}]}
{"op":"mcm","clk":"1001602782","pt":1580638402891,"mc":[{"id":"1.168215940","rc":[{"batb":[[0,1.67,62.17],[1,1.01,10.52],[2,1.67,0]],"ltp":1.55,"tv":383.2,"id":2258415}]}]}
{"op":"mcm","clk":"1001603041","pt":1580638405798,"mc":[{"id":"1.168215940","rc":[{"batb":[[0,1.74,189.55],[1,1.72,204.85],[2,1.67,62.17]],"batl":[[1,1.82,188.34]],"ltp":1.55,"tv":383.2,"id":2258415}]}]}
{"op":"mcm","clk":"1001603366","pt":1580638408803,"mc":[{"id":"1.168215940","rc":[{"batb":[[0,1.67,62.17],[1,1.01,10.52],[2,1.67,0]],"batl":[[1,2.3,309.75],[2,1.84,0]],"ltp":1.55,"tv":383.2,"id":2258415}]}]}
{"op":"mcm","clk":"1001603459","pt":1580638409893,"mc":[{"id":"1.168215940","rc":[{"batb":[[0,1.01,10.52],[1,1.01,0]],"batl":[[0,3,213.45],[1,3,0]],"ltp":0.0,"tv":0.0,"id":4423910},{"batb":[[0,1.01,10.52],[1,1.01,0]],"batl":[[0,2.3,309.75],[1,2.3,0]],"ltp":1.55,"tv":383.2,"id":2258415}]}]}
{"op":"mcm","clk":"1001603622","pt":1580638411569,"mc":[{"id":"1.168215940","rc":[{"batb":[[0,1.66,230.93],[1,1.65,119.4],[2,1.01,10.52]],"batl":[[0,2.02,154.99],[1,2.04,121.19],[2,2.3,309.75]],"ltp":1.55,"tv":383.2,"id":2258415}]}]}
{"op":"mcm","clk":"1001604176","pt":1580638416834,"mc":[{"id":"1.168215940","rc":[{"batb":[[0,1.01,10.52],[1,1.65,0],[2,1.01,0]],"ltp":1.55,"tv":383.2,"id":2258415}]}]}
{"op":"mcm","clk":"1001604384","pt":1580638418612,"mc":[{"id":"1.168215940","rc":[{"batl":[[2,2.3,0]],"ltp":1.55,"tv":383.2,"id":2258415}]}]}
{"op":"mcm","clk":"1001604539","pt":1580638419909,"mc":[{"id":"1.168215940","rc":[{"batb":[[0,1.93,117.68],[1,1.91,145.1],[2,1.01,10.52]],"ltp":1.55,"tv":383.2,"id":2258415}]}]}
{"op":"mcm","clk":"1001604665","pt":1580638420920,"mc":[{"id":"1.168215940","rc":[{"batb":[[0,2.02,41.17],[1,1.01,10.52]],"batl":[[0,2.22,33.61]],"ltp":0.0,"tv":0.0,"id":4423910},{"batb":[[2,1.81,51.25]],"batl":[[0,1.98,42.01],[1,2.02,154.99],[2,2.04,121.19]],"ltp":1.55,"tv":383.2,"id":2258415}]}]}
{"op":"mcm","clk":"1001604863","pt":1580638422864,"mc":[{"id":"1.168215940","rc":[{"batl":[[1,2.6,257.57]],"ltp":0.0,"tv":0.0,"id":4423910}]}]}
{"op":"mcm","clk":"1001605075","pt":1580638424930,"mc":[{"id":"1.168215940","rc":[{"trd":[[2.02,107.26]],"batb":[[0,1.01,10.52],[1,1.01,0]],"ltp":2.02,"tv":107.25,"id":4423910},{"trd":[[1.98,25.42]],"batl":[[0,1.98,16.59]],"ltp":1.98,"tv":408.62,"id":2258415}],"tv":515.87}]}
{"op":"mcm","clk":"1001605101","pt":1580638425244,"mc":[{"id":"1.168215940","rc":[{"batl":[[0,2.6,257.57],[1,2.6,0]],"ltp":2.02,"tv":107.25,"id":4423910},{"batb":[[2,1.01,10.52]],"batl":[[0,2.02,154.99],[1,2.04,121.19],[2,2.6,257.57]],"ltp":1.98,"tv":408.62,"id":2258415}]}]}
{"op":"mcm","clk":"1001605476","pt":1580638428852,"mc":[{"id":"1.168215940","rc":[{"batb":[[0,1.98,42.85],[1,1.01,10.52]],"batl":[[0,2.2,34.45],[1,2.6,257.57]],"ltp":2.02,"tv":107.25,"id":4423910},{"batb":[[2,1.83,50.41]],"batl":[[0,2.02,196.16]],"ltp":1.98,"tv":408.62,"id":2258415}]}]}
{"op":"mcm","clk":"1001605816","pt":1580638432047,"mc":[{"id":"1.168215940","rc":[{"batb":[[0,1.83,50.41],[1,1.01,10.52],[2,1.83,0]],"batl":[[0,2.02,41.17],[1,2.6,257.57],[2,2.6,0]],"ltp":1.98,"tv":408.62,"id":2258415}]}]}
{"op":"mcm","clk":"1001606028","pt":1580638433962,"mc":[{"id":"1.168215940","rc":[{"batb":[[0,1.01,10.52],[1,1.01,0]],"batl":[[0,2.6,257.57],[1,2.6,0]],"ltp":2.02,"tv":107.25,"id":4423910},{"batb":[[0,1.01,10.52],[1,1.01,0]],"batl":[[0,2.6,257.57],[1,2.6,0]],"ltp":1.98,"tv":408.62,"id":2258415}]}]}
{"op":"mcm","clk":"1001606131","pt":1580638434947,"mc":[{"id":"1.168215940","rc":[{"batb":[[0,1.79,133.62],[1,1.77,185.72],[2,1.01,10.52]],"batl":[[0,2.4,103.28],[1,2.44,148.13],[2,2.6,257.57]],"ltp":1.98,"tv":408.62,"id":2258415}]}]}
{"op":"mcm","clk":"1001606397","pt":1580638437729,"mc":[{"id":"1.168215940","rc":[{"batl":[[0,2.6,257.57],[1,2.44,0],[2,2.6,0]],"ltp":1.98,"tv":408.62,"id":2258415}]}]}
{"op":"mcm","clk":"1001606722","pt":1580638440856,"mc":[{"id":"1.168215940","rc":[{"batb":[[0,2.12,36.97],[1,1.01,10.52]],"batl":[[0,2.38,30.25],[1,2.6,257.57]],"ltp":2.02,"tv":107.25,"id":4423910},{"batb":[[2,1.74,56.29]],"batl":[[0,1.86,111.24],[1,1.88,155.14],[2,1.89,42.01]],"ltp":1.98,"tv":408.62,"id":2258415}]}]}
{"op":"mcm","clk":"1001607971","pt":1580638451885,"mc":[{"id":"1.168215940","rc":[{"batb":[[0,1.01,10.52],[1,1.01,0]],"batl":[[0,2.6,257.57],[1,2.6,0]],"ltp":2.02,"tv":107.25,"id":4423910},{"batb":[[0,1.01,10.52],[1,1.77,0],[2,1.74,0]],"batl":[[0,2.42,286.52],[1,1.88,0],[2,1.89,0]],"ltp":1.98,"tv":408.62,"id":2258415}]}]}
{"op":"mcm","clk":"1001608288","pt":1580638454613,"mc":[{"id":"1.168215940","rc":[{"batb":[[0,1.68,203.18],[1,1.67,114.3],[2,1.01,10.52]],"ltp":1.98,"tv":408.62,"id":2258415}]}]}
{"op":"mcm","clk":"1001608570","pt":1580638456960,"mc":[{"id":"1.168215940","rc":[{"batl":[[0,1.75,155.9],[1,1.77,187.91]],"ltp":1.98,"tv":408.62,"id":2258415}]}]}
{"op":"mcm","clk":"1001608804","pt":1580638458893,"mc":[{"id":"1.168215940","rc":[{"batb":[[0,2.26,32.77],[1,1.01,10.52]],"batl":[[0,2.54,26.89]],"ltp":2.02,"tv":107.25,"id":4423910},{"batb":[[2,1.66,63.01]],"batl":[[2,1.79,42.01]],"ltp":1.98,"tv":408.62,"id":2258415}]}]}
{"op":"mcm","clk":"1001608958","pt":1580638460187,"mc":[{"id":"1.168215940","rc":[{"batl":[[1,3.15,200.42]],"ltp":2.02,"tv":107.25,"id":4423910}]}]}
{"op":"mcm","clk":"1001610013","pt":1580638469943,"mc":[{"id":"1.168215940","rc":[{"batb":[[0,1.01,10.52],[1,1.01,0]],"batl":[[0,3.15,200.42],[1,3.15,0]],"ltp":2.02,"tv":107.25,"id":4423910},{"batb":[[0,1.01,10.52],[1,1.67,0],[2,1.66,0]],"batl":[[0,2.22,329.01],[1,1.77,0],[2,1.79,0]],"ltp":1.98,"tv":408.62,"id":2258415}]}]}
{"op":"mcm","clk":"1001610308","pt":1580638472841,"mc":[{"id":"1.168215940","rc":[{"batb":[[0,1.62,125.52],[1,1.61,130.25],[2,1.01,10.52]],"ltp":1.98,"tv":408.62,"id":2258415}]}]}
{"op":"mcm","clk":"1001610700","pt":1580638475953,"mc":[{"id":"1.168215940","rc":[{"batl":[[0,1.68,201.18],[1,1.7,214.72],[2,2.22,329.01]],"ltp":1.98,"tv":408.62,"id":2258415}]}]}
{"op":"mcm","clk":"1001610802","pt":1580638476953,"mc":[{"id":"1.168215940","rc":[{"batb":[[0,2.36,30.25],[1,1.01,10.52]],"batl":[[0,2.68,24.37],[1,3.15,200.42]],"ltp":2.02,"tv":107.25,"id":4423910},{"batb":[[2,1.6,69.74]],"batl":[[2,1.73,42.01]],"ltp":1.98,"tv":408.62,"id":2258415}]}]}
{"op":"mcm","clk":"1001611698","pt":1580638484258,"mc":[{"id":"1.168215940","rc":[{"batb":[[0,1.6,69.74],[1,1.01,10.52],[2,1.6,0]],"batl":[[0,1.73,42.01],[1,2.22,329.01],[2,1.73,0]],"ltp":1.98,"tv":408.62,"id":2258415}]}]}
{"op":"mcm","clk":"1001611981","pt":1580638486964,"mc":[{"id":"1.168215940","rc":[{"batb":[[0,1.01,10.52],[1,1.01,0]],"batl":[[0,3.15,200.42],[1,3.15,0]],"ltp":2.02,"tv":107.25,"id":4423910},{"batb":[[0,1.01,10.52],[1,1.01,0]],"batl":[[0,2.22,329.01],[1,2.22,0]],"ltp":1.98,"tv":408.62,"id":2258415}]}]}
{"op":"mcm","clk":"1001612028","pt":1580638487330,"mc":[{"id":"1.168215940","rc":[{"batb":[[0,1.58,255.36],[1,1.57,143.65],[2,1.01,10.52]],"ltp":1.98,"tv":408.62,"id":2258415}]}]}
{"op":"mcm","clk":"1001612446","pt":1580638490866,"mc":[{"id":"1.168215940","rc":[{"batl":[[0,1.64,133.48],[1,1.65,118.52]],"ltp":1.98,"tv":408.62,"id":2258415}]}]}
{"op":"mcm","clk":"1001612501","pt":1580638491388,"mc":[{"id":"1.168215940","rc":[{"batb":[[0,2.42,29.41],[1,1.01,10.52]],"batl":[[0,2.76,23.53],[1,3.15,200.42]],"ltp":2.02,"tv":107.25,"id":4423910},{"batb":[[1,1.57,216.75]],"batl":[[2,1.7,42.01]],"ltp":1.98,"tv":408.62,"id":2258415}]}]}
{"op":"mcm","clk":"1001614962","pt":1580638513893,"mc":[{"id":"1.168215940","rc":[{"batb":[[0,1.01,10.52],[1,1.01,0]],"batl":[[0,3.15,200.42],[1,3.15,0]],"ltp":2.02,"tv":107.25,"id":4423910},{"batb":[[0,1.01,10.52],[1,1.57,0],[2,1.01,0]],"batl":[[0,2.1,363.31],[1,1.65,0],[2,1.7,0]],"ltp":1.98,"tv":408.62,"id":2258415}]}]}
{"op":"mcm","clk":"1001615289","pt":1580638516771,"mc":[{"id":"1.168215940","rc":[{"batb":[[0,1.46,262.7],[1,1.45,198.25],[2,1.01,10.51]],"batl":[[0,1.74,204.55],[1,1.76,191.15],[2,2.1,363.31]],"ltp":1.98,"tv":408.62,"id":2258415}]}]}
{"op":"mcm","clk":"1001616528","pt":1580638528795,"mc":[{"id":"1.168215940","rc":[{"batb":[[0,1.01,10.52],[1,1.45,0],[2,1.01,0]],"ltp":1.98,"tv":408.62,"id":2258415}]}]}
{"op":"mcm","clk":"1001616863","pt":1580638531930,"mc":[{"id":"1.168215940","rc":[{"batb":[[0,1.67,164.28],[1,1.66,116.62],[2,1.01,10.52]],"ltp":1.98,"tv":408.62,"id":2258415}]}]}
{"op":"mcm","clk":"1001616984","pt":1580638532920,"mc":[{"id":"1.168215940","rc":[{"batb":[[0,2.3,31.93],[1,1.01,10.52]],"batl":[[0,2.6,26.05],[1,3.15,200.42]],"ltp":2.02,"tv":107.25,"id":4423910},{"batb":[[2,1.63,66.38]],"batl":[[2,1.77,42.01]],"ltp":1.98,"tv":408.62,"id":2258415}]}]}
{"op":"mcm","clk":"1001618106","pt":1580638542817,"mc":[{"id":"1.168215940","rc":[{"batb":[[0,1.63,66.38],[1,1.01,10.52],[2,1.63,0]],"batl":[[0,1.77,42.01],[1,2.1,363.31],[2,1.77,0]],"ltp":1.98,"tv":408.62,"id":2258415}]}]}
{"op":"mcm","clk":"1001618213","pt":1580638543909,"mc":[{"id":"1.168215940","rc":[{"batb":[[0,1.01,10.52],[1,1.01,0]],"batl":[[0,3.15,200.42],[1,3.15,0]],"ltp":2.02,"tv":107.25,"id":4423910},{"batb":[[0,1.01,10.52],[1,1.01,0]],"batl":[[0,2.1,363.31],[1,2.1,0]],"ltp":1.98,"tv":408.62,"id":2258415}]}]}
{"op":"mcm","clk":"1001618586","pt":1580638547556,"mc":[{"id":"1.168215940","rc":[{"batb":[[0,1.65,127.75],[1,1.64,121.71],[2,1.01,10.52]],"batl":[[0,1.71,162.87],[1,1.73,202.55],[2,2.1,363.31]],"ltp":1.98,"tv":408.62,"id":2258415}]}]}
{"op":"mcm","clk":"1001618876","pt":1580638550422,"mc":[{"id":"1.168215940","rc":[{"batb":[[0,1.01,10.52],[1,1.64,0],[2,1.01,0]],"batl":[[0,2.1,363.31],[1,1.73,0],[2,2.1,0]],"ltp":1.98,"tv":408.62,"id":2258415}]}]}
{"op":"mcm","clk":"1001619177","pt":1580638553444,"mc":[{"id":"1.168215940","rc":[{"batb":[[0,1.56,167.74],[1,1.55,150.53],[2,1.01,10.52]],"batl":[[0,1.82,184.57],[1,1.84,165.69],[2,2.1,363.31]],"ltp":1.98,"tv":408.62,"id":2258415}]}]}
{"op":"mcm","clk":"1001620150","pt":1580638562772,"mc":[{"id":"1.168215940","rc":[{"batl":[[0,2.1,363.31],[1,1.84,0],[2,2.1,0]],"ltp":1.98,"tv":408.62,"id":2258415}]}]}
{"op":"mcm","clk":"1001620413","pt":1580638565544,"mc":[{"id":"1.168215940","rc":[{"batl":[[0,1.61,120.86],[1,1.62,126.53],[2,2.1,363.31]],"ltp":1.98,"tv":408.62,"id":2258415}]}]}
{"op":"mcm","clk":"1001620561","pt":1580638566956,"mc":[{"id":"1.168215940","rc":[{"batb":[[0,2.48,27.73],[1,1.01,10.52]],"batl":[[0,2.84,22.69]],"ltp":2.02,"tv":107.25,"id":4423910},{"batb":[[1,1.55,226.15]],"batl":[[2,1.67,42.01]],"ltp":1.98,"tv":408.62,"id":2258415}]}]}
{"op":"mcm","clk":"1001620836","pt":1580638569386,"mc":[{"id":"1.168215940","rc":[{"batl":[[1,3.65,170.41]],"ltp":2.02,"tv":107.25,"id":4423910}]}]}
{"op":"mcm","clk":"1001622372","pt":1580638584403,"mc":[{"id":"1.168215940","rc":[{"batb":[[0,1.55,75.62],[1,1.01,10.52],[2,1.01,0]],"batl":[[0,1.67,42.01],[1,2.1,363.31],[2,1.67,0]],"ltp":1.98,"tv":408.62,"id":2258415}]}]}
{"op":"mcm","clk":"1001622512","pt":1580638585932,"mc":[{"id":"1.168215940","rc":[{"batb":[[0,1.01,10.52],[1,1.01,0]],"batl":[[0,3.65,170.41],[1,3.65,0]],"ltp":2.02,"tv":107.25,"id":4423910},{"batb":[[0,1.01,10.52],[1,1.01,0]],"batl":[[0,2.1,363.31],[1,2.1,0]],"ltp":1.98,"tv":408.62,"id":2258415}]}]}
{"op":"mcm","clk":"1001622668","pt":1580638587300,"mc":[{"id":"1.168215940","rc":[{"batb":[[0,1.42,145.59],[1,1.41,223.12],[2,1.01,10.51]],"batl":[[0,1.73,206.1],[1,1.75,194.75],[2,2.1,363.31]],"ltp":1.98,"tv":408.62,"id":2258415}]}]}
{"op":"mcm","clk":"1001623104","pt":1580638591696,"mc":[{"id":"1.168215940","rc":[{"batb":[[0,1.01,10.52],[1,1.41,0],[2,1.01,0]],"ltp":1.98,"tv":408.62,"id":2258415}]}]}
{"op":"mcm","clk":"1001623452","pt":1580638594907,"mc":[{"id":"1.168215940","rc":[{"batb":[[0,2.32,31.09],[1,1.01,10.52]],"ltp":2.02,"tv":107.25,"id":4423910},{"batb":[[0,1.66,175.97],[1,1.65,119.2],[2,1.01,10.52]],"batl":[[1,1.75,236.76]],"ltp":1.98,"tv":408.62,"id":2258415}]}]}
{"op":"mcm","clk":"1001623530","pt":1580638595632,"mc":[{"id":"1.168215940","rc":[{"batl":[[0,2.62,25.21]],"ltp":2.02,"tv":107.25,"id":4423910},{"batb":[[2,1.62,67.22]],"ltp":1.98,"tv":408.62,"id":2258415}]}]}
{"op":"mcm","clk":"1001623736","pt":1580638597420,"mc":[{"id":"1.168215940","rc":[{"batl":[[1,3.15,200.42]],"ltp":2.02,"tv":107.25,"id":4423910}]}]}
{"op":"mcm","clk":"1001625323","pt":1580638614598,"mc":[{"id":"1.168215940","rc":[{"batb":[[0,1.62,67.22],[1,1.01,10.52],[2,1.62,0]],"batl":[[0,1.75,42.01],[1,2.1,363.31],[2,2.1,0]],"ltp":1.98,"tv":408.62,"id":2258415}]}]}
{"op":"mcm","clk":"1001625453","pt":1580638615978,"mc":[{"id":"1.168215940","rc":[{"batb":[[0,1.01,10.52],[1,1.01,0]],"batl":[[0,3.15,200.42],[1,3.15,0]],"ltp":2.02,"tv":107.25,"id":4423910},{"batb":[[0,1.01,10.52],[1,1.01,0]],"batl":[[0,2.1,363.31],[1,2.1,0]],"ltp":1.98,"tv":408.62,"id":2258415}]}]}
{"op":"mcm","clk":"1001625608","pt":1580638617594,"mc":[{"id":"1.168215940","rc":[{"batb":[[0,1.53,232.16],[1,1.52,162.9],[2,1.01,10.52]],"batl":[[0,1.82,142.45],[1,1.84,165.78],[2,2.1,363.31]],"ltp":1.98,"tv":408.62,"id":2258415}]}]}
{"op":"mcm","clk":"1001626045","pt":1580638621776,"mc":[{"id":"1.168215940","rc":[{"batb":[[0,1.01,10.52],[1,1.52,0],[2,1.01,0]],"ltp":1.98,"tv":408.62,"id":2258415}]}]}
{"op":"mcm","clk":"1001626223","pt":1580638623680,"mc":[{"id":"1.168215940","rc":[{"batl":[[2,2.1,0]],"ltp":1.98,"tv":408.62,"id":2258415}]}]}
{"op":"mcm","clk":"1001626338","pt":1580638624888,"mc":[{"id":"1.168215940","rc":[{"batb":[[0,2.2,34.45],[1,1.01,10.52]],"batl":[[0,2.48,27.73]],"ltp":2.02,"tv":107.25,"id":4423910},{"batb":[[0,1.75,137.9],[1,1.73,200.51],[2,1.68,61.33]],"batl":[[1,1.83,42.01],[2,1.84,165.78]],"ltp":1.98,"tv":408.62,"id":2258415}]}]}
{"op":"mcm","clk":"1001626619","pt":1580638627701,"mc":[{"id":"1.168215940","rc":[{"batl":[[1,3,213.45]],"ltp":2.02,"tv":107.25,"id":4423910}]}]}
{"op":"mcm","clk":"1001627596","pt":1580638638382,"mc":[{"id":"1.168215940","rc":[{"batb":[[0,1.68,61.33],[1,1.01,10.52],[2,1.68,0]],"batl":[[0,1.83,42.01],[1,2.3,309.75],[2,1.84,0]],"ltp":1.98,"tv":408.62,"id":2258415}]}]}
{"op":"mcm","clk":"1001627743","pt":1580638640009,"mc":[{"id":"1.168215940","rc":[{"batb":[[0,1.01,10.52],[1,1.01,0]],"batl":[[0,3,213.45],[1,3,0]],"ltp":2.02,"tv":107.25,"id":4423910},{"batb":[[0,1.01,10.52],[1,1.01,0]],"batl":[[0,2.3,309.75],[1,2.3,0]],"ltp":1.98,"tv":408.62,"id":2258415}]}]}
{"op":"mcm","clk":"1001628035","pt":1580638643908,"mc":[{"id":"1.168215940","rc":[{"batb":[[0,1.73,175.35],[1,1.71,208.83],[2,1.01,10.52]],"batl":[[0,1.8,126.51],[1,1.82,171.7],[2,2.3,309.75]],"ltp":1.98,"tv":408.62,"id":2258415}]}]}
{"op":"mcm","clk":"1001628182","pt":1580638645936,"mc":[{"id":"1.168215940","rc":[{"batb":[[0,1.01,10.52],[1,1.71,0],[2,1.01,0]],"batl":[[0,2.3,309.75],[1,1.82,0],[2,2.3,0]],"ltp":1.98,"tv":408.62,"id":2258415}]}]}
{"op":"mcm","clk":"1001628382","pt":1580638648693,"mc":[{"id":"1.168215940","rc":[{"batb":[[0,1.67,153.27],[1,1.66,116.57],[2,1.01,10.52]],"batl":[[0,1.87,108.3],[1,1.89,152.59],[2,2.3,309.75]],"ltp":1.98,"tv":408.62,"id":2258415}]}]}
{"op":"mcm","clk":"1001628521","pt":1580638650819,"mc":[{"id":"1.168215940","rc":[{"batb":[[0,1.01,10.52],[1,1.66,0],[2,1.01,0]],"ltp":1.98,"tv":408.62,"id":2258415}]}]}
{"op":"mcm","clk":"1001628772","pt":1580638653730,"mc":[{"id":"1.168215940","rc":[{"batb":[[0,1.8,127.93],[1,1.78,182.1],[2,1.01,10.52]],"ltp":1.98,"tv":408.62,"id":2258415}]}]}
{"op":"mcm","clk":"1001628952","pt":1580638654936,"mc":[{"id":"1.168215940","rc":[{"batb":[[0,2.16,36.13],[1,1.01,10.52]],"batl":[[0,2.4,29.41],[1,3,213.45]],"ltp":2.02,"tv":107.25,"id":4423910},{"batb":[[2,1.71,58.81]],"batl":[[0,1.87,150.31]],"ltp":1.98,"tv":408.62,"id":2258415}]}]}
{"op":"mcm","clk":"1001630285","pt":1580638669727,"mc":[{"id":"1.168215940","rc":[{"trd":[[1.87,100.82]],"batl":[[0,1.87,42.01],[1,2.3,309.75],[2,2.3,0]],"ltp":1.87,"tv":509.44,"id":2258415}],"tv":616.7}]}
{"op":"mcm","clk":"1001630526","pt":1580638672755,"mc":[{"id":"1.168215940","rc":[{"batl":[[1,1.88,166.4],[2,1.9,149.89]],"ltp":1.87,"tv":509.44,"id":2258415}]}]}
{"op":"mcm","clk":"1001631069","pt":1580638676955,"mc":[{"id":"1.168215940","rc":[{"trd":[[1.87,109.22]],"batl":[[0,1.87,37.81]],"ltp":1.87,"tv":517.84,"id":2258415}],"tv":625.1}]}
{"op":"mcm","clk":"1001631509","pt":1580638680282,"mc":[{"id":"1.168215940","rc":[{"batl":[[0,1.87,42.01]],"ltp":1.87,"tv":517.84,"id":2258415}]}]}
{"op":"mcm","clk":"1001632839","pt":1580638691995,"mc":[{"id":"1.168215940","rc":[{"batb":[[0,1.8,147.66]],"ltp":1.87,"tv":517.84,"id":2258415}]}]}
{"op":"mcm","clk":"1001633271","pt":1580638694890,"mc":[{"id":"1.168215940","rc":[{"batl":[[0,3,213.45],[1,3,0]],"ltp":2.02,"tv":107.25,"id":4423910},{"batb":[[2,1.01,10.52]],"ltp":1.87,"tv":517.84,"id":2258415}]}]}
{"op":"mcm","clk":"1001633621","pt":1580638697901,"mc":[{"id":"1.168215940","rc":[{"batb":[[0,1.01,10.52],[1,1.01,0]],"batl":[[0,2.38,30.25],[1,3,213.45]],"ltp":2.02,"tv":107.25,"id":4423910},{"batb":[[2,1.73,57.13]],"ltp":1.87,"tv":517.84,"id":2258415}]}]}
{"op":"mcm","clk":"1001633873","pt":1580638700894,"mc":[{"id":"1.168215940","rc":[{"batb":[[0,2.14,36.13],[1,1.01,10.52]],"ltp":2.02,"tv":107.25,"id":4423910}]}]}
{"op":"mcm","clk":"1001636445","pt":1580638729745,"mc":[{"id":"1.168215940","rc":[{"batb":[[0,1.73,57.13],[1,1.01,10.52],[2,1.73,0]],"batl":[[1,2.3,309.75],[2,1.9,0]],"ltp":1.87,"tv":517.84,"id":2258415}]}]}
{"op":"mcm","clk":"1001636473","pt":1580638730121,"mc":[{"id":"1.168215940","rc":[{"batb":[[0,1.01,10.52],[1,1.01,0]],"batl":[[0,3,213.45],[1,3,0]],"ltp":2.02,"tv":107.25,"id":4423910},{"batb":[[0,1.01,10.52],[1,1.01,0]],"batl":[[0,2.3,309.75],[1,2.3,0]],"ltp":1.87,"tv":517.84,"id":2258415}]}]}
{"op":"mcm","clk":"1001636898","pt":1580638735560,"mc":[{"id":"1.168215940","rc":[{"batb":[[0,1.84,134.19],[1,1.82,169.22],[2,1.01,10.52]],"batl":[[0,1.92,143.42],[1,1.94,140.67],[2,2.3,309.75]],"ltp":1.87,"tv":517.84,"id":2258415}]}]}
{"op":"mcm","clk":"1001637024","pt":1580638737221,"mc":[{"id":"1.168215940","rc":[{"batb":[[0,1.01,10.52],[1,1.82,0],[2,1.01,0]],"batl":[[0,2.3,309.75],[1,1.94,0],[2,2.3,0]],"ltp":1.87,"tv":517.84,"id":2258415}]}]}
{"op":"mcm","clk":"1001637152","pt":1580638739041,"mc":[{"id":"1.168215940","rc":[{"batl":[[0,2.82,231.28]],"ltp":2.02,"tv":107.25,"id":4423910}]}]}
{"op":"mcm","clk":"1001637247","pt":1580638740260,"mc":[{"id":"1.168215940","rc":[{"batb":[[0,1.71,183.57],[1,1.69,217.52],[2,1.01,10.52]],"batl":[[0,2.12,178.33],[1,2.14,105.47],[2,2.3,309.75]],"ltp":1.87,"tv":517.84,"id":2258415}]}]}
{"op":"mcm","clk":"1001637814","pt":1580638746967,"mc":[{"id":"1.168215940","rc":[{"batl":[[0,2.3,309.75],[1,2.14,0],[2,2.3,0]],"ltp":1.87,"tv":517.84,"id":2258415}]}]}
{"op":"mcm","clk":"1001638071","pt":1580638749950,"mc":[{"id":"1.168215940","rc":[{"batl":[[0,1.78,139.71],[1,1.8,177.79],[2,2.3,309.75]],"ltp":1.87,"tv":517.84,"id":2258415}]}]}
{"op":"mcm","clk":"1001638181","pt":1580638751356,"mc":[{"id":"1.168215940","rc":[{"batb":[[0,2.24,33.61],[1,1.01,10.52]],"batl":[[0,2.5,27.73]],"ltp":2.02,"tv":107.25,"id":4423910},{"batb":[[2,1.66,63.01]],"batl":[[2,1.81,42.01]],"ltp":1.87,"tv":517.84,"id":2258415}]}]}
{"op":"mcm","clk":"1001638333","pt":1580638753173,"mc":[{"id":"1.168215940","rc":[{"batl":[[1,3.15,200.42]],"ltp":2.02,"tv":107.25,"id":4423910}]}]}
{"op":"mcm","clk":"1001638964","pt":1580638760682,"mc":[{"id":"1.168215940","rc":[{"batb":[[0,1.66,63.01],[1,1.01,10.52],[2,1.66,0]],"batl":[[0,1.81,42.01],[1,2.3,309.75],[2,1.81,0]],"ltp":1.87,"tv":517.84,"id":2258415}]}]}
{"op":"mcm","clk":"1001639125","pt":1580638762673,"mc":[{"id":"1.168215940","rc":[{"batb":[[0,1.01,10.52],[1,1.01,0]],"batl":[[0,3.15,200.42],[1,3.15,0]],"ltp":2.02,"tv":107.25,"id":4423910},{"batb":[[0,1.01,10.52],[1,1.01,0]],"batl":[[0,2.3,309.75],[1,2.3,0]],"ltp":1.87,"tv":517.84,"id":2258415}]}]}
{"op":"mcm","clk":"1001639213","pt":1580638763870,"mc":[{"id":"1.168215940","rc":[{"batb":[[0,1.65,203.96],[1,1.64,121.85],[2,1.01,10.52]],"batl":[[0,1.93,108.83],[1,1.95,138.53],[2,2.3,309.75]],"ltp":1.87,"tv":517.84,"id":2258415}]}]}
{"op":"mcm","clk":"1001639302","pt":1580638764901,"mc":[{"id":"1.168215940","rc":[{"batl":[[0,2.3,309.75],[1,1.95,0],[2,2.3,0]],"ltp":1.87,"tv":517.84,"id":2258415}]}]}
{"op":"mcm","clk":"1001639529","pt":1580638767613,"mc":[{"id":"1.168215940","rc":[{"batl":[[0,1.72,192.59],[1,1.74,198.41]],"ltp":1.87,"tv":517.84,"id":2258415}]}]}
{"op":"mcm","clk":"1001639753","pt":1580638769919,"mc":[{"id":"1.168215940","rc":[{"batb":[[0,2.32,31.09],[1,1.01,10.52]],"batl":[[0,2.6,26.05],[1,3.15,200.42]],"ltp":2.02,"tv":107.25,"id":4423910},{"batb":[[2,1.63,66.38]],"batl":[[2,1.76,42.01]],"ltp":1.87,"tv":517.84,"id":2258415}]}]}
{"op":"mcm","clk":"1001640297","pt":1580638775785,"mc":[{"id":"1.168215940","rc":[{"batb":[[0,1.63,66.38],[1,1.01,10.52],[2,1.63,0]],"batl":[[0,1.76,42.01],[1,2.16,342.82],[2,1.76,0]],"ltp":1.87,"tv":517.84,"id":2258415}]}]}
{"op":"mcm","clk":"1001640320","pt":1580638776110,"mc":[{"id":"1.168215940","rc":[{"batb":[[0,1.01,10.52],[1,1.01,0]],"batl":[[0,3.15,200.42],[1,3.15,0]],"ltp":2.02,"tv":107.25,"id":4423910},{"batb":[[0,1.01,10.52],[1,1.01,0]],"batl":[[0,2.16,342.82],[1,2.16,0]],"ltp":1.87,"tv":517.84,"id":2258415}]}]}
{"op":"mcm","clk":"1001641171","pt":1580638785826,"mc":[{"id":"1.168215940","rc":[{"batb":[[0,1.62,143.25],[1,1.61,130.16],[2,1.01,10.52]],"batl":[[0,1.8,108.27],[1,1.82,171.69],[2,2.16,342.82]],"ltp":1.87,"tv":517.84,"id":2258415}]}]}
{"op":"mcm","clk":"1001641363","pt":1580638787928,"mc":[{"id":"1.168215940","rc":[{"batb":[[0,1.01,10.52],[1,1.61,0],[2,1.01,0]],"ltp":1.87,"tv":517.84,"id":2258415}]}]}
{"op":"mcm","clk":"1001641643","pt":1580638790937,"mc":[{"id":"1.168215940","rc":[{"batb":[[0,1.73,194.6],[1,1.71,208.83],[2,1.01,10.52]],"ltp":1.87,"tv":517.84,"id":2258415}]}]}
{"op":"mcm","clk":"1001641680","pt":1580638791248,"mc":[{"id":"1.168215940","rc":[{"batb":[[0,2.2,34.45],[1,1.01,10.52]],"batl":[[0,2.48,27.73]],"ltp":2.02,"tv":107.25,"id":4423910},{"batb":[[2,1.68,61.33]],"batl":[[2,1.83,42.01]],"ltp":1.87,"tv":517.84,"id":2258415}]}]}
{"op":"mcm","clk":"1001641889","pt":1580638793714,"mc":[{"id":"1.168215940","rc":[{"batl":[[1,3,213.45]],"ltp":2.02,"tv":107.25,"id":4423910}]}]}
{"op":"mcm","clk":"1001643270","pt":1580638809952,"mc":[{"id":"1.168215940","rc":[{"batb":[[0,1.68,61.33],[1,1.01,10.52],[2,1.68,0]],"batl":[[0,1.83,42.01],[1,2.16,342.82],[2,1.83,0]],"ltp":1.87,"tv":517.84,"id":2258415}]}]}
{"op":"mcm","clk":"1001643299","pt":1580638810361,"mc":[{"id":"1.168215940","rc":[{"batb":[[0,1.01,10.52],[1,1.01,0]],"batl":[[0,3,213.45],[1,3,0]],"ltp":2.02,"tv":107.25,"id":4423910},{"batb":[[0,1.01,10.52],[1,1.01,0]],"batl":[[0,2.16,342.82],[1,2.16,0]],"ltp":1.87,"tv":517.84,"id":2258415}]}]}
{"op":"mcm","clk":"1001643499","pt":1580638812665,"mc":[{"id":"1.168215940","rc":[{"batb":[[0,1.66,149.14],[1,1.65,119.06],[2,1.01,10.52]],"batl":[[0,2,129.96],[1,2.02,124.65],[2,2.16,342.82]],"ltp":1.87,"tv":517.84,"id":2258415}]}]}
{"op":"mcm","clk":"1001643836","pt":1580638816964,"mc":[{"id":"1.168215940","rc":[{"batl":[[0,2.16,342.82],[1,2.02,0],[2,2.16,0]],"ltp":1.87,"tv":517.84,"id":2258415}]}]}
{"op":"mcm","clk":"1001644092","pt":1580638819874,"mc":[{"id":"1.168215940","rc":[{"batl":[[0,1.72,131.25],[1,1.74,198.71],[2,2.16,342.82]],"ltp":1.87,"tv":517.84,"id":2258415}]}]}
{"op":"mcm","clk":"1001644188","pt":1580638821283,"mc":[{"id":"1.168215940","rc":[{"batb":[[0,2.3,31.93],[1,1.01,10.52]],"batl":[[0,2.6,26.05],[1,3,213.45]],"ltp":2.02,"tv":107.25,"id":4423910},{"batb":[[2,1.62,67.22]],"batl":[[2,1.76,42.01]],"ltp":1.87,"tv":517.84,"id":2258415}]}]}
{"op":"mcm","clk":"1001644947","pt":1580638830675,"mc":[{"id":"1.168215940","rc":[{"batb":[[0,1.62,67.22],[1,1.01,10.52],[2,1.62,0]],"batl":[[0,1.76,42.01],[1,2.16,342.82],[2,1.76,0]],"ltp":1.87,"tv":517.84,"id":2258415}]}]}
{"op":"mcm","clk":"1001645063","pt":1580638832507,"mc":[{"id":"1.168215940","rc":[{"batb":[[0,1.01,10.52],[1,1.01,0]],"batl":[[0,3,213.45],[1,3,0]],"ltp":2.02,"tv":107.25,"id":4423910},{"batb":[[0,1.01,10.52],[1,1.01,0]],"batl":[[0,2.16,342.82],[1,2.16,0]],"ltp":1.87,"tv":517.84,"id":2258415}]}]}
{"op":"mcm","clk":"1001645372","pt":1580638835916,"mc":[{"id":"1.168215940","rc":[{"trd":[[1.67,336.08]],"batb":[[0,1.67,34.8],[1,1.66,116.65],[2,1.01,10.52]],"batl":[[0,1.74,167.97],[1,1.76,191.18],[2,2.16,342.82]],"ltp":1.67,"tv":853.92,"id":2258415}],"tv":961.18}]}
{"op":"mcm","clk":"1001645400","pt":1580638836190,"mc":[{"id":"1.168215940","rc":[{"batl":[[0,2.16,342.82],[1,1.76,0],[2,2.16,0]],"ltp":1.67,"tv":853.92,"id":2258415}]}]}
{"op":"mcm","clk":"1001645528","pt":1580638837704,"mc":[{"id":"1.168215940","rc":[{"batb":[[0,1.01,10.52],[1,1.66,0],[2,1.01,0]],"ltp":1.67,"tv":853.92,"id":2258415}]}]}
{"op":"mcm","clk":"1001645778","pt":1580638840907,"mc":[{"id":"1.168215940","rc":[{"batb":[[0,1.62,175],[1,1.61,130.47],[2,1.01,10.52]],"batl":[[0,1.8,149.4],[1,1.82,171.81],[2,2.16,342.82]],"ltp":1.67,"tv":853.92,"id":2258415}]}]}
{"op":"mcm","clk":"1001645845","pt":1580638841695,"mc":[{"id":"1.168215940","rc":[{"batl":[[0,2.16,342.82],[1,1.82,0],[2,2.16,0]],"ltp":1.67,"tv":853.92,"id":2258415}]}]}
{"op":"mcm","clk":"1001646098","pt":1580638844592,"mc":[{"id":"1.168215940","rc":[{"batl":[[0,1.68,154.93],[1,1.7,215.09],[2,2.16,342.82]],"ltp":1.67,"tv":853.92,"id":2258415}]}]}
{"op":"mcm","clk":"1001646158","pt":1580638845319,"mc":[{"id":"1.168215940","rc":[{"batb":[[0,2.38,30.25],[1,1.01,10.52]],"batl":[[0,2.68,24.37],[1,3,213.45]],"ltp":2.02,"tv":107.25,"id":4423910},{"batb":[[2,1.59,70.58]],"batl":[[2,1.73,42.01]],"ltp":1.67,"tv":853.92,"id":2258415}]}]}
{"op":"mcm","clk":"1001648771","pt":1580638874652,"mc":[{"id":"1.168215940","rc":[{"batb":[[0,1.59,70.58],[1,1.01,10.52],[2,1.59,0]],"batl":[[0,1.73,42.02],[1,2.16,342.82],[2,1.73,0]],"ltp":1.67,"tv":853.92,"id":2258415}]}]}
{"op":"mcm","clk":"1001648970","pt":1580638876367,"mc":[{"id":"1.168215940","rc":[{"batb":[[0,1.01,10.52],[1,1.01,0]],"batl":[[0,3,213.45],[1,3,0]],"ltp":2.02,"tv":107.25,"id":4423910},{"batb":[[0,1.01,10.52],[1,1.01,0]],"batl":[[0,2.16,342.83],[1,2.16,0]],"ltp":1.67,"tv":853.92,"id":2258415}]}]}
{"op":"mcm","clk":"1001649101","pt":1580638877837,"mc":[{"id":"1.168215940","rc":[{"batl":[[0,1.78,122.68],[1,1.8,178.09],[2,2.16,342.82]],"ltp":1.67,"tv":853.92,"id":2258415}]}]}
{"op":"mcm","clk":"1001649307","pt":1580638879922,"mc":[{"id":"1.168215940","rc":[{"trd":[[1.67,336.11]],"batb":[[0,1.71,202.45],[1,1.69,217.87],[2,1.01,10.52]],"batl":[[0,1.78,122.66]],"ltp":1.67,"tv":853.96,"id":2258415}],"tv":961.21}]}
{"op":"mcm","clk":"1001649394","pt":1580638881126,"mc":[{"id":"1.168215940","rc":[{"batb":[[0,2.24,33.61],[1,1.01,10.52]],"batl":[[0,2.52,26.89],[1,3,213.45]],"ltp":2.02,"tv":107.25,"id":4423910},{"batb":[[2,1.66,63.01]],"batl":[[1,1.8,220.1]],"ltp":1.67,"tv":853.96,"id":2258415}]}]}
{"op":"mcm","clk":"1001649971","pt":1580638888679,"mc":[{"id":"1.168215940","rc":[{"batb":[[0,1.66,63.01],[1,1.01,10.52],[2,1.66,0]],"batl":[[0,1.8,42.01],[1,2.16,342.82],[2,2.16,0]],"ltp":1.67,"tv":853.96,"id":2258415}]}]}
{"op":"mcm","clk":"1001650101","pt":1580638890146,"mc":[{"id":"1.168215940","rc":[{"batb":[[0,1.01,10.52],[1,1.01,0]],"batl":[[0,3,213.45],[1,3,0]],"ltp":2.02,"tv":107.25,"id":4423910},{"batb":[[0,1.01,10.52],[1,1.01,0]],"batl":[[0,2.16,342.82],[1,2.16,0]],"ltp":1.67,"tv":853.96,"id":2258415}]}]}
{"op":"mcm","clk":"1001650285","pt":1580638891878,"mc":[{"id":"1.168215940","rc":[{"batb":[[0,1.59,167.29],[1,1.58,139.96],[2,1.01,10.52]],"batl":[[0,1.87,129.29],[1,1.89,152.6],[2,2.16,342.82]],"ltp":1.67,"tv":853.96,"id":2258415}]}]}
{"op":"mcm","clk":"1001650569","pt":1580638895875,"mc":[{"id":"1.168215940","rc":[{"batb":[[0,1.01,10.52],[1,1.58,0],[2,1.01,0]],"ltp":1.67,"tv":853.96,"id":2258415}]}]}
{"op":"mcm","clk":"1001650763","pt":1580638898799,"mc":[{"id":"1.168215940","rc":[{"batb":[[0,1.8,106.42],[1,1.78,182.22],[2,1.01,10.53]],"ltp":1.67,"tv":853.96,"id":2258415}]}]}
{"op":"mcm","clk":"1001650847","pt":1580638899868,"mc":[{"id":"1.168215940","rc":[{"batb":[[0,2.14,36.13],[1,1.01,10.52]],"batl":[[0,2.4,29.41],[1,3,213.45]],"ltp":2.02,"tv":107.25,"id":4423910},{"batb":[[2,1.71,58.81]],"batl":[[1,1.88,42.01],[2,1.89,152.6]],"ltp":1.67,"tv":853.96,"id":2258415}]}]}
{"op":"mcm","clk":"1001651605","pt":1580638909920,"mc":[{"id":"1.168215940","rc":[{"batb":[[0,1.71,58.81],[1,1.01,10.53],[2,1.71,0]],"batl":[[0,1.88,42.01],[1,2.16,342.82],[2,1.89,0]],"ltp":1.67,"tv":853.96,"id":2258415}]}]}
{"op":"mcm","clk":"1001651627","pt":1580638910082,"mc":[{"id":"1.168215940","rc":[{"batb":[[0,1.01,10.52],[1,1.01,0]],"batl":[[0,3,213.45],[1,3,0]],"ltp":2.02,"tv":107.25,"id":4423910},{"batb":[[0,1.01,10.53],[1,1.01,0]],"batl":[[0,2.16,342.82],[1,2.16,0]],"ltp":1.67,"tv":853.96,"id":2258415}]}]}
{"op":"mcm","clk":"1001652099","pt":1580638915905,"mc":[{"id":"1.168215940","rc":[{"batb":[[0,1.78,112.88],[1,1.76,189.26],[2,1.01,10.53]],"batl":[[0,1.85,139.87],[1,1.87,157.72],[2,2.16,342.82]],"ltp":1.67,"tv":853.96,"id":2258415}]}]}
{"op":"mcm","clk":"1001652504","pt":1580638920812,"mc":[{"id":"1.168215940","rc":[{"batb":[[0,1.01,10.53],[1,1.76,0],[2,1.01,0]],"batl":[[0,2.16,342.82],[1,1.87,0],[2,2.16,0]],"ltp":1.67,"tv":853.96,"id":2258415}]}]}
{"op":"mcm","clk":"1001652767","pt":1580638923853,"mc":[{"id":"1.168215940","rc":[{"batb":[[0,1.7,187.83],[1,1.68,222.4],[2,1.01,10.53]],"batl":[[0,1.93,108.9],[1,1.95,138.67],[2,2.16,342.82]],"ltp":1.67,"tv":853.96,"id":2258415}]}]}
{"op":"mcm","clk":"1001653061","pt":1580638927827,"mc":[{"id":"1.168215940","rc":[{"batb":[[0,1.01,10.53],[1,1.68,0],[2,1.01,0]],"ltp":1.67,"tv":853.96,"id":2258415}]}]}
{"op":"mcm","clk":"1001653211","pt":1580638929862,"mc":[{"id":"1.168215940","rc":[{"batl":[[2,2.16,0]],"ltp":1.67,"tv":853.96,"id":2258415}]}]}
{"op":"mcm","clk":"1001653281","pt":1580638930640,"mc":[{"id":"1.168215940","rc":[{"batb":[[0,1.85,162.39],[1,1.83,166.43],[2,1.01,10.53]],"ltp":1.67,"tv":853.96,"id":2258415}]}]}
{"op":"mcm","clk":"1001653343","pt":1580638931423,"mc":[{"id":"1.168215940","rc":[{"batb":[[0,2.1,37.81],[1,1.01,10.52]],"batl":[[0,2.34,31.09]],"ltp":2.02,"tv":107.25,"id":4423910},{"batb":[[2,1.76,54.61]],"batl":[[0,1.92,42.01],[1,1.93,108.9],[2,1.95,138.67]],"ltp":1.67,"tv":853.96,"id":2258415}]}]}
{"op":"mcm","clk":"1001653577","pt":1580638934462,"mc":[{"id":"1.168215940","rc":[{"batl":[[1,2.82,231.28]],"ltp":2.02,"tv":107.25,"id":4423910}]}]}
{"op":"mcm","clk":"1001654556","pt":1580638947763,"mc":[{"id":"1.168215940","rc":[{"batb":[[0,1.76,54.61],[1,1.01,10.53],[2,1.76,0]],"batl":[[1,2.42,286.52],[2,1.95,0]],"ltp":1.67,"tv":853.96,"id":2258415}]}]}
{"op":"mcm","clk":"1001654600","pt":1580638948394,"mc":[{"id":"1.168215940","rc":[{"batb":[[0,1.01,10.52],[1,1.01,0]],"batl":[[0,2.82,231.28],[1,2.82,0]],"ltp":2.02,"tv":107.25,"id":4423910},{"batb":[[0,1.01,10.53],[1,1.01,0]],"batl":[[0,2.42,286.52],[1,2.42,0]],"ltp":1.67,"tv":853.96,"id":2258415}]}]}
{"op":"mcm","clk":"1001654767","pt":1580638950793,"mc":[{"id":"1.168215940","rc":[{"batb":[[0,1.8,140.89],[1,1.78,182.29],[2,1.01,10.53]],"batl":[[0,1.97,162.03],[1,1.99,130.43],[2,2.42,286.52]],"ltp":1.67,"tv":853.96,"id":2258415}]}]}
{"op":"mcm","clk":"1001654827","pt":1580638951683,"mc":[{"id":"1.168215940","rc":[{"batb":[[0,1.01,10.53],[1,1.78,0],[2,1.01,0]],"ltp":1.67,"tv":853.96,"id":2258415}]}]}
{"op":"mcm","clk":"1001655124","pt":1580638954898,"mc":[{"id":"1.168215940","rc":[{"batb":[[0,1.88,151.88],[1,1.86,157.89],[2,1.01,10.53]],"ltp":1.67,"tv":853.96,"id":2258415}]}]}
{"op":"mcm","clk":"1001655170","pt":1580638955170,"mc":[{"id":"1.168215940","rc":[{"batb":[[0,2.06,39.49],[1,1.01,10.52]],"batl":[[0,2.3,31.93],[1,2.82,231.28]],"ltp":2.02,"tv":107.25,"id":4423910},{"batb":[[2,1.78,53.77]],"batl":[[0,1.95,42.01],[1,1.97,162.03],[2,1.99,130.43]],"ltp":1.67,"tv":853.96,"id":2258415}]}]}
{"op":"mcm","clk":"1001657875","pt":1580638986706,"mc":[{"id":"1.168215940","rc":[{"batl":[[0,2.82,231.28],[1,2.82,0]],"ltp":2.02,"tv":107.25,"id":4423910}]}]}
{"op":"mcm","clk":"1001658176","pt":1580638989723,"mc":[{"id":"1.168215940","rc":[{"batl":[[0,2.28,32.77],[1,2.82,231.28]],"ltp":2.02,"tv":107.25,"id":4423910}]}]}
{"op":"mcm","clk":"1001658273","pt":1580638990922,"mc":[{"id":"1.168215940","rc":[{"batl":[[1,2.42,286.52],[2,1.99,0]],"ltp":1.67,"tv":853.96,"id":2258415}]}]}
{"op":"mcm","clk":"1001658596","pt":1580638993976,"mc":[{"id":"1.168215940","rc":[{"batl":[[1,1.96,97.62],[2,1.98,132.44]],"ltp":1.67,"tv":853.96,"id":2258415}]}]}
{"op":"mcm","clk":"1001659606","pt":1580639003803,"mc":[{"id":"1.168215940","rc":[{"batb":[[0,1.78,53.77],[1,1.01,10.53],[2,1.78,0]],"ltp":1.67,"tv":853.96,"id":2258415}]}]}
{"op":"mcm","clk":"1001660225","pt":1580639006649,"mc":[{"id":"1.168215940","rc":[{"batb":[[0,1.87,173.7],[1,1.85,160.72],[2,1.78,53.77]],"batl":[[1,1.96,150.06]],"ltp":1.67,"tv":853.96,"id":2258415}]}]}
{"op":"mcm","clk":"1001662823","pt":1580639028903,"mc":[{"id":"1.168215940","rc":[{"trd":[[1.87,456.63]],"batb":[[0,1.85,160.72],[1,1.78,53.77],[2,1.01,10.53]],"batl":[[0,1.87,97.27],[1,1.95,42.01],[2,1.96,150.06]],"ltp":1.87,"tv":1201.37,"id":2258415}],"tv":1308.62}]}
{"op":"mcm","clk":"1001662856","pt":1580639029206,"mc":[{"id":"1.168215940","rc":[{"batl":[[2,2.42,286.52]],"ltp":1.87,"tv":1201.37,"id":2258415}]}]}
{"op":"mcm","clk":"1001663267","pt":1580639032519,"mc":[{"id":"1.168215940","rc":[{"trd":[[1.87,651.16]],"batb":[[0,1.78,53.77],[1,1.01,10.53],[2,1.01,0]],"batl":[[0,1.95,42.01],[1,2.42,286.52],[2,2.42,0]],"ltp":1.87,"tv":1395.9,"id":2258415}],"tv":1503.15}]}
{"op":"mcm","clk":"1001663637","pt":1580639035613,"mc":[{"id":"1.168215940","rc":[{"batb":[[0,1.86,154.32],[1,1.84,163.64],[2,1.78,53.77]],"batl":[[0,1.94,109.18],[1,1.95,42.01],[2,1.96,136.69]],"ltp":1.87,"tv":1395.9,"id":2258415}]}]}
{"op":"mcm","clk":"1001664139","pt":1580639039621,"mc":[{"id":"1.168215940","rc":[{"batb":[[0,1.78,53.77],[1,1.01,10.53],[2,1.78,0]],"batl":[[0,1.95,42.01],[1,2.42,286.52],[2,1.96,0]],"ltp":1.87,"tv":1395.9,"id":2258415}]}]}
{"op":"mcm","clk":"1001664210","pt":1580639040200,"mc":[{"id":"1.168215940","rc":[{"batb":[[0,1.01,10.52],[1,1.01,0]],"batl":[[0,2.82,231.28],[1,2.82,0]],"ltp":2.02,"tv":107.25,"id":4423910},{"batb":[[0,1.01,10.53],[1,1.01,0]],"batl":[[0,2.42,286.52],[1,2.42,0]],"ltp":1.87,"tv":1395.9,"id":2258415}]}]}
{"op":"mcm","clk":"1001664576","pt":1580639042919,"mc":[{"id":"1.168215940","rc":[{"batb":[[0,1.76,171.08],[1,1.74,197.19],[2,1.01,10.53]],"batl":[[0,2.22,126.01],[1,2.24,92.73],[2,2.42,286.52]],"ltp":1.87,"tv":1395.9,"id":2258415}]}]}
{"op":"mcm","clk":"1001664901","pt":1580639045686,"mc":[{"id":"1.168215940","rc":[{"batl":[[0,2.42,286.52],[1,2.24,0],[2,2.42,0]],"ltp":1.87,"tv":1395.9,"id":2258415}]}]}
{"op":"mcm","clk":"1001665274","pt":1580639048727,"mc":[{"id":"1.168215940","rc":[{"batl":[[0,1.84,185.48],[1,1.86,160.59],[2,2.42,286.52]],"ltp":1.87,"tv":1395.9,"id":2258415}]}]}
{"op":"mcm","clk":"1001665350","pt":1580639049417,"mc":[{"id":"1.168215940","rc":[{"batb":[[0,2.16,36.13],[1,1.01,10.52]],"batl":[[0,2.42,29.41],[1,2.82,231.28]],"ltp":2.02,"tv":107.25,"id":4423910},{"batb":[[2,1.71,58.81]],"batl":[[1,1.86,202.6]],"ltp":1.87,"tv":1395.9,"id":2258415}]}]}
{"op":"mcm","clk":"1001666259","pt":1580639057837,"mc":[{"id":"1.168215940","rc":[{"batb":[[0,1.71,58.81],[1,1.01,10.53],[2,1.71,0]],"batl":[[0,1.86,42.01],[1,2.42,286.52],[2,2.42,0]],"ltp":1.87,"tv":1395.9,"id":2258415}]}]}
{"op":"mcm","clk":"1001666304","pt":1580639058249,"mc":[{"id":"1.168215940","rc":[{"batb":[[0,1.01,10.52],[1,1.01,0]],"batl":[[0,2.82,231.28],[1,2.82,0]],"ltp":2.02,"tv":107.25,"id":4423910},{"batb":[[0,1.01,10.53],[1,1.01,0]],"batl":[[0,2.42,286.52],[1,2.42,0]],"ltp":1.87,"tv":1395.9,"id":2258415}]}]}
{"op":"mcm","clk":"1001666583","pt":1580639060547,"mc":[{"id":"1.168215940","rc":[{"batb":[[0,1.7,115.99],[1,1.68,222.56],[2,1.01,10.53]],"ltp":1.87,"tv":1395.9,"id":2258415}]}]}
{"op":"mcm","clk":"1001666914","pt":1580639063770,"mc":[{"id":"1.168215940","rc":[{"batl":[[0,1.76,124.1],[1,1.78,185.09]],"ltp":1.87,"tv":1395.9,"id":2258415}]}]}
{"op":"mcm","clk":"1001667058","pt":1580639065264,"mc":[{"id":"1.168215940","rc":[{"batb":[[0,2.24,33.61],[1,1.01,10.52]],"batl":[[0,2.52,26.89]],"ltp":2.02,"tv":107.25,"id":4423910},{"batb":[[2,1.67,62.19]],"batl":[[2,1.81,42.01]],"ltp":1.87,"tv":1395.9,"id":2258415}]}]}
{"op":"mcm","clk":"1001667164","pt":1580639066258,"mc":[{"id":"1.168215940","rc":[{"batl":[[1,3.15,200.42]],"ltp":2.02,"tv":107.25,"id":4423910}]}]}
{"op":"mcm","clk":"1001667886","pt":1580639072682,"mc":[{"id":"1.168215940","rc":[{"batb":[[0,1.67,62.19],[1,1.01,10.52],[2,1.67,0]],"batl":[[0,1.81,42.01],[1,2.22,329.01],[2,1.81,0]],"ltp":1.87,"tv":1395.9,"id":2258415}]}]}
{"op":"mcm","clk":"1001668062","pt":1580639074296,"mc":[{"id":"1.168215940","rc":[{"batb":[[0,1.01,10.52],[1,1.01,0]],"batl":[[0,3.15,200.42],[1,3.15,0]],"ltp":2.02,"tv":107.25,"id":4423910},{"batb":[[0,1.01,10.53],[1,1.01,0]],"batl":[[0,2.22,329.01],[1,2.22,0]],"ltp":1.87,"tv":1395.9,"id":2258415}]}]}
{"op":"mcm","clk":"1001668200","pt":1580639075817,"mc":[{"id":"1.168215940","rc":[{"batb":[[0,1.66,137.12],[1,1.65,119.47],[2,1.01,10.52]],"batl":[[0,1.86,140.87],[1,1.88,155.38],[2,2.22,329.01]],"ltp":1.87,"tv":1395.9,"id":2258415}]}]}
{"op":"mcm","clk":"1001668594","pt":1580639079669,"mc":[{"id":"1.168215940","rc":[{"batl":[[0,2.22,329.01],[1,1.88,0],[2,2.22,0]],"ltp":1.87,"tv":1395.9,"id":2258415}]}]}
{"op":"mcm","clk":"1001668872","pt":1580639082664,"mc":[{"id":"1.168215940","rc":[{"batl":[[0,1.72,145.18],[1,1.74,199.46],[2,2.22,329.01]],"ltp":1.87,"tv":1395.9,"id":2258415}]}]}
{"op":"mcm","clk":"1001668947","pt":1580639083439,"mc":[{"id":"1.168215940","rc":[{"batb":[[0,2.3,31.93],[1,1.01,10.52]],"batl":[[0,2.58,26.05],[1,3.15,200.42]],"ltp":2.02,"tv":107.25,"id":4423910},{"batb":[[2,1.64,65.54]],"batl":[[2,1.77,42.01]],"ltp":1.87,"tv":1395.9,"id":2258415}]}]}
{"op":"mcm","clk":"1001669785","pt":1580639091896,"mc":[{"id":"1.168215940","rc":[{"batb":[[0,1.64,65.55],[1,1.01,10.52],[2,1.64,0]],"batl":[[0,1.77,42.01],[1,2.22,329.01],[2,1.77,0]],"ltp":1.87,"tv":1395.9,"id":2258415}]}]}
{"op":"mcm","clk":"1001669838","pt":1580639092365,"mc":[{"id":"1.168215940","rc":[{"batb":[[0,1.01,10.52],[1,1.01,0]],"batl":[[0,3.15,200.42],[1,3.15,0]],"ltp":2.02,"tv":107.25,"id":4423910},{"batb":[[0,1.01,10.53],[1,1.01,0]],"batl":[[0,2.22,329.01],[1,2.22,0]],"ltp":1.87,"tv":1395.9,"id":2258415}]}]}
{"op":"mcm","clk":"1001670110","pt":1580639094867,"mc":[{"id":"1.168215940","rc":[{"batb":[[0,1.64,167.37],[1,1.63,124.97],[2,1.01,10.52]],"batl":[[0,1.77,161.62],[1,1.79,181.62],[2,2.22,329.01]],"ltp":1.87,"tv":1395.9,"id":2258415}]}]}
{"op":"mcm","clk":"1001670464","pt":1580639098661,"mc":[{"id":"1.168215940","rc":[{"batl":[[0,2.22,329.01],[1,1.79,0],[2,2.22,0]],"ltp":1.87,"tv":1395.9,"id":2258415}]}]}
{"op":"mcm","clk":"1001670792","pt":1580639101579,"mc":[{"id":"1.168215940","rc":[{"batl":[[0,1.7,139.37],[1,1.72,207.38],[2,2.22,329.01]],"ltp":1.87,"tv":1395.9,"id":2258415}]}]}
{"op":"mcm","clk":"1001670962","pt":1580639103296,"mc":[{"id":"1.168215940","rc":[{"batb":[[0,2.34,31.09],[1,1.01,10.52]],"batl":[[0,2.62,25.21],[1,3.15,200.42]],"ltp":2.02,"tv":107.25,"id":4423910},{"batb":[[2,1.62,67.22]],"batl":[[2,1.75,42.01]],"ltp":1.87,"tv":1395.9,"id":2258415}]}]}
{"op":"mcm","clk":"1001673981","pt":1580639132553,"mc":[{"id":"1.168215940","rc":[{"batb":[[0,1.01,10.52],[1,1.01,0]],"batl":[[0,3.15,200.42],[1,3.15,0]],"ltp":2.02,"tv":107.25,"id":4423910},{"batb":[[0,1.01,10.53],[1,1.63,0],[2,1.62,0]],"batl":[[0,2.22,329.01],[1,1.72,0],[2,1.75,0]],"ltp":1.87,"tv":1395.9,"id":2258415}]}]}
{"op":"mcm","clk":"1001674300","pt":1580639135933,"mc":[{"id":"1.168215940","rc":[{"batb":[[0,1.49,150.34],[1,1.48,181.9],[2,1.01,10.51]],"batl":[[0,1.81,132.25],[1,1.83,169.19],[2,2.22,329.01]],"ltp":1.87,"tv":1395.9,"id":2258415}]}]}
{"op":"mcm","clk":"1001674366","pt":1580639136659,"mc":[{"id":"1.168215940","rc":[{"batb":[[0,1.01,10.53],[1,1.48,0],[2,1.01,0]],"batl":[[0,2.22,329.01],[1,1.83,0],[2,2.22,0]],"ltp":1.87,"tv":1395.9,"id":2258415}]}]}
{"op":"mcm","clk":"1001674709","pt":1580639139853,"mc":[{"id":"1.168215940","rc":[{"trd":[[1.67,336.15]],"batb":[[0,1.61,131.37],[1,1.6,133.74],[2,1.01,10.52]],"batl":[[0,1.67,211.16],[1,1.69,219.81],[2,2.22,329.01]],"ltp":1.67,"tv":1395.93,"id":2258415}],"tv":1503.19}]}
{"op":"mcm","clk":"1001674737","pt":1580639140057,"mc":[{"id":"1.168215940","rc":[{"batb":[[0,1.01,10.52],[1,1.6,0],[2,1.01,0]],"batl":[[0,2.22,329.01],[1,1.69,0],[2,2.22,0]],"ltp":1.67,"tv":1395.93,"id":2258415}]}]}
{"op":"mcm","clk":"1001675125","pt":1580639143509,"mc":[{"id":"1.168215940","rc":[{"batl":[[0,1.81,132.24],[1,1.83,169.19],[2,2.22,329.01]],"ltp":1.67,"tv":1395.93,"id":2258415}]}]}
{"op":"mcm","clk":"1001675494","pt":1580639146563,"mc":[{"id":"1.168215940","rc":[{"batb":[[0,1.74,160.83],[1,1.72,205.14],[2,1.01,10.52]],"ltp":1.67,"tv":1395.93,"id":2258415}]}]}
{"op":"mcm","clk":"1001675581","pt":1580639147243,"mc":[{"id":"1.168215940","rc":[{"batb":[[0,2.18,35.29],[1,1.01,10.52]],"batl":[[0,2.46,28.57]],"ltp":2.02,"tv":107.25,"id":4423910},{"batb":[[2,1.7,59.65]],"batl":[[2,1.84,42.01]],"ltp":1.67,"tv":1395.93,"id":2258415}]}]}
{"op":"mcm","clk":"1001675762","pt":1580639148770,"mc":[{"id":"1.168215940","rc":[{"batl":[[1,3,213.45]],"ltp":2.02,"tv":107.25,"id":4423910}]}]}
{"op":"mcm","clk":"1001677276","pt":1580639161783,"mc":[{"id":"1.168215940","rc":[{"batb":[[0,1.7,59.65],[1,1.01,10.52],[2,1.7,0]],"batl":[[0,1.84,42.01],[1,2.22,329.01],[2,1.84,0]],"ltp":1.67,"tv":1395.93,"id":2258415}]}]}
{"op":"mcm","clk":"1001677350","pt":1580639162412,"mc":[{"id":"1.168215940","rc":[{"batb":[[0,1.01,10.52],[1,1.01,0]],"batl":[[0,3,213.45],[1,3,0]],"ltp":2.02,"tv":107.25,"id":4423910},{"batb":[[0,1.01,10.52],[1,1.01,0]],"batl":[[0,2.22,329.01],[1,2.22,0]],"ltp":1.67,"tv":1395.93,"id":2258415}]}]}
{"op":"mcm","clk":"1001677538","pt":1580639164107,"mc":[{"id":"1.168215940","rc":[{"batb":[[0,1.6,233.62],[1,1.59,137.29],[2,1.01,10.52]],"batl":[[0,1.91,172.97],[1,1.93,143.21],[2,2.22,329.01]],"ltp":1.67,"tv":1395.93,"id":2258415}]}]}
{"op":"mcm","clk":"1001677724","pt":1580639165643,"mc":[{"id":"1.168215940","rc":[{"batb":[[0,1.01,10.52],[1,1.59,0],[2,1.01,0]],"ltp":1.67,"tv":1395.93,"id":2258415}]}]}
{"op":"mcm","clk":"1001678054","pt":1580639168679,"mc":[{"id":"1.168215940","rc":[{"batb":[[0,1.83,113.43],[1,1.81,172.63],[2,1.01,10.52]],"ltp":1.67,"tv":1395.93,"id":2258415}]}]}
{"op":"mcm","clk":"1001678131","pt":1580639169373,"mc":[{"id":"1.168215940","rc":[{"batb":[[0,2.1,37.81],[1,1.01,10.52]],"batl":[[0,2.34,31.09]],"ltp":2.02,"tv":107.25,"id":4423910},{"batb":[[2,1.75,55.45]],"batl":[[1,1.92,42.01],[2,1.93,143.21]],"ltp":1.67,"tv":1395.93,"id":2258415}]}]}
{"op":"mcm","clk":"1001678348","pt":1580639171314,"mc":[{"id":"1.168215940","rc":[{"batl":[[1,2.82,231.28]],"ltp":2.02,"tv":107.25,"id":4423910}]}]}
{"op":"mcm","clk":"1001679428","pt":1580639180876,"mc":[{"id":"1.168215940","rc":[{"batb":[[0,1.75,55.45],[1,1.01,10.52],[2,1.75,0]],"batl":[[0,1.92,42.01],[1,2.22,329.01],[2,1.93,0]],"ltp":1.67,"tv":1395.93,"id":2258415}]}]}
{"op":"mcm","clk":"1001679594","pt":1580639182465,"mc":[{"id":"1.168215940","rc":[{"batb":[[0,1.01,10.52],[1,1.01,0]],"batl":[[0,2.82,231.28],[1,2.82,0]],"ltp":2.02,"tv":107.25,"id":4423910},{"batb":[[0,1.01,10.52],[1,1.01,0]],"batl":[[0,2.22,329.01],[1,2.22,0]],"ltp":1.67,"tv":1395.93,"id":2258415}]}]}
{"op":"mcm","clk":"1001679795","pt":1580639183794,"mc":[{"id":"1.168215940","rc":[{"batb":[[0,1.73,129.45],[1,1.71,209.21],[2,1.01,10.52]],"batl":[[0,1.97,138.07],[1,1.99,130.55],[2,2.22,329.01]],"ltp":1.67,"tv":1395.93,"id":2258415}]}]}
{"op":"mcm","clk":"1001679960","pt":1580639184949,"mc":[{"id":"1.168215940","rc":[{"batb":[[0,1.01,10.52],[1,1.71,0],[2,1.01,0]],"batl":[[0,2.22,329.01],[1,1.99,0],[2,2.22,0]],"ltp":1.67,"tv":1395.93,"id":2258415}]}]}
{"op":"mcm","clk":"1001680284","pt":1580639187846,"mc":[{"id":"1.168215940","rc":[{"batb":[[0,1.81,108.1],[1,1.79,179.08],[2,1.01,10.52]],"batl":[[0,1.88,120.41],[1,1.9,150.35],[2,2.22,329.01]],"ltp":1.67,"tv":1395.93,"id":2258415}]}]}
{"op":"mcm","clk":"1001680646","pt":1580639190581,"mc":[{"id":"1.168215940","rc":[{"batb":[[0,1.01,10.52],[1,1.79,0],[2,1.01,0]],"batl":[[0,2.22,329.01],[1,1.9,0],[2,2.22,0]],"ltp":1.67,"tv":1395.93,"id":2258415}]}]}
{"op":"mcm","clk":"1001681271","pt":1580639193793,"mc":[{"id":"1.168215940","rc":[{"batb":[[0,1.73,129.45],[1,1.71,209.21],[2,1.01,10.52]],"batl":[[0,1.97,138.07],[1,1.99,130.55],[2,2.22,329.01]],"ltp":1.67,"tv":1395.93,"id":2258415}]}]}
{"op":"mcm","clk":"1001681721","pt":1580639197787,"mc":[{"id":"1.168215940","rc":[{"batl":[[0,2.22,329.01],[1,1.99,0],[2,2.22,0]],"ltp":1.67,"tv":1395.93,"id":2258415}]}]}
{"op":"mcm","clk":"1001682051","pt":1580639200784,"mc":[{"id":"1.168215940","rc":[{"batl":[[0,1.8,171.35],[1,1.82,172.08],[2,2.22,329.01]],"ltp":1.67,"tv":1395.93,"id":2258415}]}]}
{"op":"mcm","clk":"1001682120","pt":1580639201370,"mc":[{"id":"1.168215940","rc":[{"batb":[[0,2.2,34.45],[1,1.01,10.52]],"batl":[[0,2.48,27.73],[1,2.82,231.28]],"ltp":2.02,"tv":107.25,"id":4423910},{"batb":[[2,1.68,61.33]],"batl":[[2,1.83,42.01]],"ltp":1.67,"tv":1395.93,"id":2258415}]}]}
{"op":"mcm","clk":"1001686563","pt":1580639236595,"mc":[{"id":"1.168215940","rc":[{"batb":[[0,1.01,10.52],[1,1.01,0]],"batl":[[0,2.82,231.28],[1,2.82,0]],"ltp":2.02,"tv":107.25,"id":4423910},{"batb":[[0,1.01,10.52],[1,1.71,0],[2,1.68,0]],"batl":[[0,2.22,329.01],[1,1.82,0],[2,1.83,0]],"ltp":1.67,"tv":1395.93,"id":2258415}]}]}
{"op":"mcm","clk":"1001687510","pt":1580639242760,"mc":[{"id":"1.168215940","rc":[{"batb":[[0,1.83,158.41],[1,1.81,172.68],[2,1.01,10.52]],"batl":[[0,1.91,130.08],[1,1.93,143.24],[2,2.22,329.01]],"ltp":1.67,"tv":1395.93,"id":2258415}]}]}
{"op":"mcm","clk":"1001687597","pt":1580639243387,"mc":[{"id":"1.168215940","rc":[{"batb":[[0,2.1,37.81],[1,1.01,10.52]],"batl":[[0,2.34,31.09],[1,2.82,231.28]],"ltp":2.02,"tv":107.25,"id":4423910},{"batb":[[2,1.76,54.61]],"batl":[[1,1.92,42.01],[2,1.93,143.24]],"ltp":1.67,"tv":1395.93,"id":2258415}]}]}
{"op":"mcm","clk":"1001688724","pt":1580639251935,"mc":[{"id":"1.168215940","rc":[{"batb":[[0,1.76,54.61],[1,1.01,10.52],[2,1.76,0]],"batl":[[0,1.92,42.01],[1,2.22,329.01],[2,1.93,0]],"ltp":1.67,"tv":1395.93,"id":2258415}]}]}
{"op":"mcm","clk":"1001688786","pt":1580639252454,"mc":[{"id":"1.168215940","rc":[{"batb":[[0,1.01,10.52],[1,1.01,0]],"batl":[[0,2.82,231.28],[1,2.82,0]],"ltp":2.02,"tv":107.25,"id":4423910},{"batb":[[0,1.01,10.52],[1,1.01,0]],"batl":[[0,2.22,329.01],[1,2.22,0]],"ltp":1.67,"tv":1395.93,"id":2258415}]}]}
{"op":"mcm","clk":"1001689017","pt":1580639254511,"mc":[{"id":"1.168215940","rc":[{"batb":[[0,1.74,137.56],[1,1.72,205.05],[2,1.01,10.52]],"batl":[[0,1.97,137.22],[1,1.99,130.54],[2,2.22,329.01]],"ltp":1.67,"tv":1395.93,"id":2258415}]}]}
{"op":"mcm","clk":"1001689140","pt":1580639255613,"mc":[{"id":"1.168215940","rc":[{"batl":[[0,2.22,329.01],[1,1.99,0],[2,2.22,0]],"ltp":1.67,"tv":1395.93,"id":2258415}]}]}
{"op":"mcm","clk":"1001689494","pt":1580639258726,"mc":[{"id":"1.168215940","rc":[{"batl":[[0,1.81,154.33],[1,1.83,169.12],[2,2.22,329.01]],"ltp":1.67,"tv":1395.93,"id":2258415}]}]}
{"op":"mcm","clk":"1001689602","pt":1580639259727,"mc":[{"id":"1.168215940","rc":[{"batl":[[0,2.46,28.57],[1,2.82,231.28]],"ltp":2.02,"tv":107.25,"id":4423910},{"batb":[[2,1.69,60.49]],"batl":[[2,1.84,42.01]],"ltp":1.67,"tv":1395.93,"id":2258415}]}]}
{"op":"mcm","clk":"1001689823","pt":1580639261771,"mc":[{"id":"1.168215940","rc":[{"batb":[[0,2.2,34.45],[1,1.01,10.52]],"ltp":2.02,"tv":107.25,"id":4423910}]}]}
{"op":"mcm","clk":"1001690561","pt":1580639268833,"mc":[{"id":"1.168215940","rc":[{"batb":[[0,1.69,60.49],[1,1.01,10.52],[2,1.69,0]],"batl":[[0,1.84,42.01],[1,2.22,329.01],[2,1.84,0]],"ltp":1.67,"tv":1395.93,"id":2258415}]}]}
{"op":"mcm","clk":"1001690724","pt":1580639270438,"mc":[{"id":"1.168215940","rc":[{"batb":[[0,1.01,10.52],[1,1.01,0]],"batl":[[0,2.82,231.28],[1,2.82,0]],"ltp":2.02,"tv":107.25,"id":4423910},{"batb":[[0,1.01,10.52],[1,1.01,0]],"batl":[[0,2.22,329.01],[1,2.22,0]],"ltp":1.67,"tv":1395.93,"id":2258415}]}]}
{"op":"mcm","clk":"1001690871","pt":1580639271746,"mc":[{"id":"1.168215940","rc":[{"batb":[[0,1.56,164.21],[1,1.55,151.08],[2,1.01,10.52]],"batl":[[0,1.94,137.17],[1,1.96,136.65],[2,2.22,329.01]],"ltp":1.67,"tv":1395.93,"id":2258415}]}]}
{"op":"mcm","clk":"1001690986","pt":1580639272745,"mc":[{"id":"1.168215940","rc":[{"batb":[[0,1.01,10.52],[1,1.55,0],[2,1.01,0]],"ltp":1.67,"tv":1395.93,"id":2258415}]}]}
{"op":"mcm","clk":"1001691311","pt":1580639275683,"mc":[{"id":"1.168215940","rc":[{"batb":[[0,2.06,39.49],[1,1.01,10.52]],"ltp":2.02,"tv":107.25,"id":4423910},{"batb":[[0,1.86,124.92],[1,1.84,163.59],[2,1.77,53.77]],"batl":[[0,1.94,179.18]],"ltp":1.67,"tv":1395.93,"id":2258415}]}]}
{"op":"mcm","clk":"1001691591","pt":1580639278457,"mc":[{"id":"1.168215940","rc":[{"batl":[[0,2.28,32.77],[1,2.82,231.28]],"ltp":2.02,"tv":107.25,"id":4423910}]}]}
{"op":"mcm","clk":"1001701403","pt":1580639364340,"mc":[{"id":"1.168215940","rc":[{"trd":[[1.86,6.06]],"batb":[[0,1.86,121.89]],"ltp":1.86,"tv":1401.99,"id":2258415}],"tv":1509.25}]}
{"op":"mcm","clk":"1001703183","pt":1580639379853,"mc":[{"id":"1.168215940","rc":[{"batb":[[0,1.77,53.77],[1,1.01,10.52],[2,1.77,0]],"batl":[[0,1.94,42.01],[1,2.22,329.01],[2,2.22,0]],"ltp":1.86,"tv":1401.99,"id":2258415}]}]}
{"op":"mcm","clk":"1001703247","pt":1580639380487,"mc":[{"id":"1.168215940","rc":[{"batb":[[0,1.01,10.52],[1,1.01,0]],"batl":[[0,2.82,231.28],[1,2.82,0]],"ltp":2.02,"tv":107.25,"id":4423910},{"batb":[[0,1.01,10.52],[1,1.01,0]],"batl":[[0,2.22,329.01],[1,2.22,0]],"ltp":1.86,"tv":1401.99,"id":2258415}]}]}
{"op":"mcm","clk":"1001703522","pt":1580639382739,"mc":[{"id":"1.168215940","rc":[{"batb":[[0,1.75,172.88],[1,1.73,201.1],[2,1.01,10.52]],"batl":[[1,2.24,85.33],[2,2.26,90.37]],"ltp":1.86,"tv":1401.99,"id":2258415}]}]}
{"op":"mcm","clk":"1001703570","pt":1580639383080,"mc":[{"id":"1.168215940","rc":[{"batl":[[1,2.24,0],[2,2.26,0]],"ltp":1.86,"tv":1401.99,"id":2258415}]}]}
{"op":"mcm","clk":"1001704079","pt":1580639386921,"mc":[{"id":"1.168215940","rc":[{"batl":[[0,1.82,110.98],[1,1.84,166.31],[2,2.22,329.01]],"ltp":1.86,"tv":1401.99,"id":2258415}]}]}
{"op":"mcm","clk":"1001704129","pt":1580639387435,"mc":[{"id":"1.168215940","rc":[{"batb":[[0,2.16,36.13],[1,1.01,10.52]],"batl":[[0,2.42,29.41],[1,2.82,231.28]],"ltp":2.02,"tv":107.25,"id":4423910},{"batb":[[2,1.71,58.81]],"batl":[[2,1.86,42.01]],"ltp":1.86,"tv":1401.99,"id":2258415}]}]}
{"op":"mcm","clk":"1001704584","pt":1580639391851,"mc":[{"id":"1.168215940","rc":[{"batb":[[0,1.71,58.81],[1,1.01,10.52],[2,1.71,0]],"batl":[[0,1.86,42.01],[1,2.22,329.01],[2,1.86,0]],"ltp":1.86,"tv":1401.99,"id":2258415}]}]}
{"op":"mcm","clk":"1001704661","pt":1580639392543,"mc":[{"id":"1.168215940","rc":[{"batb":[[0,1.01,10.52],[1,1.01,0]],"batl":[[0,2.82,231.28],[1,2.82,0]],"ltp":2.02,"tv":107.25,"id":4423910},{"batb":[[0,1.01,10.52],[1,1.01,0]],"batl":[[0,2.22,329.01],[1,2.22,0]],"ltp":1.86,"tv":1401.99,"id":2258415}]}]}
{"op":"mcm","clk":"1001704882","pt":1580639394512,"mc":[{"id":"1.168215940","rc":[{"batb":[[0,1.68,200.57],[1,1.67,114.55],[2,1.01,10.52]],"ltp":1.86,"tv":1401.99,"id":2258415}]}]}
{"op":"mcm","clk":"1001705119","pt":1580639396927,"mc":[{"id":"1.168215940","rc":[{"batl":[[0,1.75,160.39],[1,1.77,188.39],[2,2.22,329.01]],"ltp":1.86,"tv":1401.99,"id":2258415}]}]}
{"op":"mcm","clk":"1001705172","pt":1580639397443,"mc":[{"id":"1.168215940","rc":[{"batb":[[0,2.26,32.77],[1,1.01,10.52]],"batl":[[0,2.54,26.89]],"ltp":2.02,"tv":107.25,"id":4423910},{"batb":[[2,1.66,63.01]],"batl":[[2,1.8,42.01]],"ltp":1.86,"tv":1401.99,"id":2258415}]}]}
{"op":"mcm","clk":"1001705429","pt":1580639399928,"mc":[{"id":"1.168215940","rc":[{"batl":[[1,3.15,200.42]],"ltp":2.02,"tv":107.25,"id":4423910}]}]}
{"op":"mcm","clk":"1001705963","pt":1580639403875,"mc":[{"id":"1.168215940","rc":[{"batb":[[0,1.66,63.01],[1,1.01,10.52],[2,1.66,0]],"batl":[[0,1.8,42.01],[1,2.22,329.01],[2,1.8,0]],"ltp":1.86,"tv":1401.99,"id":2258415}]}]}
{"op":"mcm","clk":"1001706068","pt":1580639404546,"mc":[{"id":"1.168215940","rc":[{"batb":[[0,1.01,10.52],[1,1.01,0]],"batl":[[0,3.15,200.42],[1,3.15,0]],"ltp":2.02,"tv":107.25,"id":4423910},{"batb":[[0,1.01,10.52],[1,1.01,0]],"batl":[[0,2.22,329.01],[1,2.22,0]],"ltp":1.86,"tv":1401.99,"id":2258415}]}]}
{"op":"mcm","clk":"1001706339","pt":1580639406666,"mc":[{"id":"1.168215940","rc":[{"batb":[[0,1.64,224.83],[1,1.63,125.12],[2,1.01,10.52]],"batl":[[0,1.85,134.92],[1,1.87,157.98],[2,2.22,329.01]],"ltp":1.86,"tv":1401.99,"id":2258415}]}]}
{"op":"mcm","clk":"1001706921","pt":1580639411740,"mc":[{"id":"1.168215940","rc":[{"batl":[[0,2.22,329.01],[1,1.87,0],[2,2.22,0]],"ltp":1.86,"tv":1401.99,"id":2258415}]}]}
{"op":"mcm","clk":"1001707338","pt":1580639414689,"mc":[{"id":"1.168215940","rc":[{"batl":[[0,1.71,189.58],[1,1.73,203.13],[2,2.22,329.01]],"ltp":1.86,"tv":1401.99,"id":2258415}]}]}
{"op":"mcm","clk":"1001707459","pt":1580639415736,"mc":[{"id":"1.168215940","rc":[{"batb":[[0,2.3,31.93],[1,1.01,10.52]],"batl":[[0,2.58,26.05],[1,3.15,200.42]],"ltp":2.02,"tv":107.25,"id":4423910},{"batb":[[1,1.63,191.5]],"batl":[[2,1.77,42.01]],"ltp":1.86,"tv":1401.99,"id":2258415}]}]}
{"op":"mcm","clk":"1001708595","pt":1580639427936,"mc":[{"id":"1.168215940","rc":[{"batb":[[0,1.63,191.5],[1,1.01,10.52],[2,1.01,0]],"batl":[[0,1.77,42.01],[1,2.22,329.01],[2,1.77,0]],"ltp":1.86,"tv":1401.99,"id":2258415}]}]}
{"op":"mcm","clk":"1001708653","pt":1580639428508,"mc":[{"id":"1.168215940","rc":[{"batb":[[0,1.01,10.52],[1,1.01,0]],"batl":[[0,3.15,200.42],[1,3.15,0]],"ltp":2.02,"tv":107.25,"id":4423910},{"batb":[[0,1.63,125.12]],"batl":[[0,2.22,329.01],[1,2.22,0]],"ltp":1.86,"tv":1401.99,"id":2258415}]}]}
{"op":"mcm","clk":"1001708860","pt":1580639430646,"mc":[{"id":"1.168215940","rc":[{"batb":[[1,1.62,127.73],[2,1.01,10.52]],"batl":[[0,1.76,203.4],[1,1.78,184.82],[2,2.22,329.01]],"ltp":1.86,"tv":1401.99,"id":2258415}]}]}
{"op":"mcm","clk":"1001708977","pt":1580639431812,"mc":[{"id":"1.168215940","rc":[{"batl":[[0,2.22,329.01],[1,1.78,0],[2,2.22,0]],"ltp":1.86,"tv":1401.99,"id":2258415}]}]}
{"op":"mcm","clk":"1001709267","pt":1580639434727,"mc":[{"id":"1.168215940","rc":[{"batl":[[0,1.69,174.09],[1,1.71,211.33],[2,2.22,329.01]],"ltp":1.86,"tv":1401.99,"id":2258415}]}]}
{"op":"mcm","clk":"1001709337","pt":1580639435519,"mc":[{"id":"1.168215940","rc":[{"batb":[[0,2.34,31.09],[1,1.01,10.52]],"batl":[[0,2.64,25.21],[1,3.15,200.42]],"ltp":2.02,"tv":107.25,"id":4423910},{"batb":[[1,1.62,194.95]],"batl":[[2,1.75,42.01]],"ltp":1.86,"tv":1401.99,"id":2258415}]}]}
{"op":"mcm","clk":"1001714104","pt":1580639471725,"mc":[{"id":"1.168215940","rc":[{"batb":[[0,1.62,67.22],[1,1.01,10.52],[2,1.01,0]],"batl":[[0,1.75,42.01],[1,2.22,329.01],[2,1.75,0]],"ltp":1.86,"tv":1401.99,"id":2258415}]}]}
{"op":"mcm","clk":"1001714390","pt":1580639474714,"mc":[{"id":"1.168215940","rc":[{"batb":[[1,1.46,281.07],[2,1.45,199.28]],"batl":[[1,1.81,157.86],[2,1.83,169.11]],"ltp":1.86,"tv":1401.99,"id":2258415}]}]}
{"op":"mcm","clk":"1001714417","pt":1580639475031,"mc":[{"id":"1.168215940","rc":[{"batb":[[0,2.36,436.68],[1,2.34,31.09],[2,1.01,10.52]],"ltp":2.02,"tv":107.25,"id":4423910}]}]}
{"op":"mcm","clk":"1001714706","pt":1580639477832,"mc":[{"id":"1.168215940","rc":[{"batb":[[0,2.34,31.09],[1,1.01,10.52],[2,1.01,0]],"ltp":2.02,"tv":107.25,"id":4423910}]}]}
{"op":"mcm","clk":"1001714802","pt":1580639478735,"mc":[{"id":"1.168215940","rc":[{"batb":[[0,1.01,10.52],[1,1.01,0]],"batl":[[0,3.15,200.42],[1,3.15,0]],"ltp":2.02,"tv":107.25,"id":4423910},{"batb":[[0,1.46,281.07],[1,1.45,199.28],[2,1.01,10.51]],"batl":[[0,1.81,157.86],[1,1.83,169.11],[2,2.22,329.01]],"ltp":1.86,"tv":1401.99,"id":2258415}]}]}
{"op":"mcm","clk":"1001715007","pt":1580639480839,"mc":[{"id":"1.168215940","rc":[{"batb":[[0,1.01,10.52],[1,1.45,0],[2,1.01,0]],"batl":[[0,2.22,329.01],[1,1.83,0],[2,2.22,0]],"ltp":1.86,"tv":1401.99,"id":2258415}]}]}
{"op":"mcm","clk":"1001715311","pt":1580639483821,"mc":[{"id":"1.168215940","rc":[{"batb":[[0,1.59,204.64],[1,1.58,140.5],[2,1.01,10.52]],"batl":[[0,1.65,169.56],[1,1.66,116.36]],"ltp":1.86,"tv":1401.99,"id":2258415}]}]}
{"op":"mcm","clk":"1001715643","pt":1580639486537,"mc":[{"id":"1.168215940","rc":[{"batl":[[2,2.1,363.31]],"ltp":1.86,"tv":1401.99,"id":2258415}]}]}
{"op":"mcm","clk":"1001715915","pt":1580639488948,"mc":[{"id":"1.168215940","rc":[{"batb":[[0,1.01,10.52],[1,1.58,0],[2,1.01,0]],"batl":[[0,2.1,363.31],[1,1.66,0],[2,2.1,0]],"ltp":1.86,"tv":1401.99,"id":2258415}]}]}
{"op":"mcm","clk":"1001716182","pt":1580639491932,"mc":[{"id":"1.168215940","rc":[{"batl":[[0,1.81,156.98],[1,1.83,169.12],[2,2.1,363.31]],"ltp":1.86,"tv":1401.99,"id":2258415}]}]}
{"op":"mcm","clk":"1001716454","pt":1580639494913,"mc":[{"id":"1.168215940","rc":[{"batb":[[0,1.74,134.75],[1,1.72,205.03],[2,1.01,10.52]],"batl":[[2,2.1,0]],"ltp":1.86,"tv":1401.99,"id":2258415}]}]}
{"op":"mcm","clk":"1001716533","pt":1580639495599,"mc":[{"id":"1.168215940","rc":[{"batb":[[0,2.18,35.29],[1,1.01,10.52]],"batl":[[0,2.44,28.57]],"ltp":2.02,"tv":107.25,"id":4423910},{"batb":[[2,1.69,60.49]],"batl":[[1,1.83,211.13]],"ltp":1.86,"tv":1401.99,"id":2258415}]}]}
{"op":"mcm","clk":"1001716765","pt":1580639498143,"mc":[{"id":"1.168215940","rc":[{"batl":[[1,3,213.45]],"ltp":2.02,"tv":107.25,"id":4423910},{"batl":[[2,2.3,309.75]],"ltp":1.86,"tv":1401.99,"id":2258415}]}]}
{"op":"mcm","clk":"1001717517","pt":1580639506762,"mc":[{"id":"1.168215940","rc":[{"batb":[[0,1.01,10.52],[1,1.01,0]],"batl":[[0,3,213.45],[1,3,0]],"ltp":2.02,"tv":107.25,"id":4423910},{"batb":[[0,1.01,10.52],[1,1.72,0],[2,1.69,0]],"batl":[[0,2.3,309.75],[1,1.83,0],[2,2.3,0]],"ltp":1.86,"tv":1401.99,"id":2258415}]}]}
{"op":"mcm","clk":"1001718056","pt":1580639512818,"mc":[{"id":"1.168215940","rc":[{"batb":[[0,1.71,119.94],[1,1.69,217.94],[2,1.01,10.52]],"batl":[[0,1.77,110.78],[1,1.79,181.74],[2,2.3,309.75]],"ltp":1.86,"tv":1401.99,"id":2258415}]}]}
{"op":"mcm","clk":"1001718879","pt":1580639518916,"mc":[{"id":"1.168215940","rc":[{"batb":[[0,1.01,10.52],[1,1.69,0],[2,1.01,0]],"batl":[[0,2.3,309.75],[1,1.79,0],[2,2.3,0]],"ltp":1.86,"tv":1401.99,"id":2258415}]}]}
{"op":"mcm","clk":"1001719259","pt":1580639521798,"mc":[{"id":"1.168215940","rc":[{"batb":[[0,1.59,188.72],[1,1.58,140.43],[2,1.01,10.52]],"batl":[[0,1.91,128.31],[1,1.93,143.24],[2,2.3,309.75]],"ltp":1.86,"tv":1401.99,"id":2258415}]}]}
{"op":"mcm","clk":"1001720341","pt":1580639532815,"mc":[{"id":"1.168215940","rc":[{"batl":[[0,2.3,309.75],[1,1.93,0],[2,2.3,0]],"ltp":1.86,"tv":1401.99,"id":2258415}]}]}
{"op":"mcm","clk":"1001720642","pt":1580639535919,"mc":[{"id":"1.168215940","rc":[{"batl":[[0,1.65,184.53],[1,1.66,116.31]],"ltp":1.86,"tv":1401.99,"id":2258415}]}]}
{"op":"mcm","clk":"1001720800","pt":1580639537638,"mc":[{"id":"1.168215940","rc":[{"batb":[[0,2.4,29.41],[1,1.01,10.52]],"batl":[[0,2.72,24.37]],"ltp":2.02,"tv":107.25,"id":4423910},{"batb":[[0,1.59,259.3]],"batl":[[2,1.71,42.01]],"ltp":1.86,"tv":1401.99,"id":2258415}]}]}
{"op":"mcm","clk":"1001720847","pt":1580639538214,"mc":[{"id":"1.168215940","rc":[{"batl":[[1,3.45,180.4]],"ltp":2.02,"tv":107.25,"id":4423910}]}]}
{"op":"mcm","clk":"1001722444","pt":1580639550832,"mc":[{"id":"1.168215940","rc":[{"batb":[[0,1.59,70.58],[1,1.01,10.52],[2,1.01,0]],"batl":[[0,1.71,42.01],[1,2.1,363.31],[2,1.71,0]],"ltp":1.86,"tv":1401.99,"id":2258415}]}]}
{"op":"mcm","clk":"1001722707","pt":1580639552635,"mc":[{"id":"1.168215940","rc":[{"batb":[[0,1.01,10.52],[1,1.01,0]],"batl":[[0,3.45,180.4],[1,3.45,0]],"ltp":2.02,"tv":107.25,"id":4423910},{"batb":[[0,1.01,10.52],[1,1.01,0]],"batl":[[0,2.1,363.31],[1,2.1,0]],"ltp":1.86,"tv":1401.99,"id":2258415}]}]}
{"op":"mcm","clk":"1001722808","pt":1580639553527,"mc":[{"id":"1.168215940","rc":[{"batl":[[0,1.8,177.81],[1,1.82,172.05],[2,2.1,363.31]],"ltp":1.86,"tv":1401.99,"id":2258415}]}]}
{"op":"mcm","clk":"1001723029","pt":1580639555935,"mc":[{"id":"1.168215940","rc":[{"batl":[[2,2.1,0]],"ltp":1.86,"tv":1401.99,"id":2258415}]}]}
{"op":"mcm","clk":"1001723070","pt":1580639556303,"mc":[{"id":"1.168215940","rc":[{"batb":[[0,1.73,123.38],[1,1.71,209.17],[2,1.01,10.52]],"ltp":1.86,"tv":1401.99,"id":2258415}]}]}
{"op":"mcm","clk":"1001723178","pt":1580639557620,"mc":[{"id":"1.168215940","rc":[{"batb":[[0,2.22,33.61],[1,1.01,10.52]],"batl":[[0,2.48,27.73]],"ltp":2.02,"tv":107.25,"id":4423910},{"batb":[[2,1.67,62.17]],"batl":[[1,1.81,42.01],[2,1.82,172.05]],"ltp":1.86,"tv":1401.99,"id":2258415}]}]}
{"op":"mcm","clk":"1001723398","pt":1580639559633,"mc":[{"id":"1.168215940","rc":[{"batl":[[1,3,213.45]],"ltp":2.02,"tv":107.25,"id":4423910}]}]}
{"op":"mcm","clk":"1001723629","pt":1580639560837,"mc":[{"id":"1.168215940","rc":[{"batb":[[0,1.01,10.52],[1,1.01,0]],"batl":[[0,3,213.45],[1,3,0]],"ltp":2.02,"tv":107.25,"id":4423910},{"batb":[[2,1.01,10.52]],"batl":[[1,1.82,172.05],[2,2.3,309.75]],"ltp":1.86,"tv":1401.99,"id":2258415}]}]}
{"op":"mcm","clk":"1001724002","pt":1580639563527,"mc":[{"id":"1.168215940","rc":[{"batb":[[0,2.2,34.45],[1,1.01,10.52]],"batl":[[0,2.46,28.57],[1,3,213.45]],"ltp":2.02,"tv":107.25,"id":4423910},{"batb":[[2,1.69,60.49]],"batl":[[2,1.83,42.01]],"ltp":1.86,"tv":1401.99,"id":2258415}]}]}
{"op":"mcm","clk":"1001724350","pt":1580639566922,"mc":[{"id":"1.168215940","rc":[{"batb":[[0,1.69,60.49],[1,1.01,10.52],[2,1.69,0]],"batl":[[0,1.83,42.01],[1,2.3,309.75],[2,1.83,0]],"ltp":1.86,"tv":1401.99,"id":2258415}]}]}
{"op":"mcm","clk":"1001724555","pt":1580639568662,"mc":[{"id":"1.168215940","rc":[{"batb":[[0,1.01,10.52],[1,1.01,0]],"batl":[[0,3,213.45],[1,3,0]],"ltp":2.02,"tv":107.25,"id":4423910},{"batb":[[0,1.01,10.52],[1,1.01,0]],"batl":[[0,2.3,309.75],[1,2.3,0]],"ltp":1.86,"tv":1401.99,"id":2258415}]}]}
{"op":"mcm","clk":"1001724639","pt":1580639569549,"mc":[{"id":"1.168215940","rc":[{"batb":[[0,1.55,246.09],[1,1.54,155.33],[2,1.01,10.52]],"batl":[[0,1.92,120.91],[1,1.94,140.99],[2,2.3,309.75]],"ltp":1.86,"tv":1401.99,"id":2258415}]}]}
{"op":"mcm","clk":"1001724692","pt":1580639570071,"mc":[{"id":"1.168215940","rc":[{"batb":[[0,1.01,10.52],[1,1.54,0],[2,1.01,0]],"batl":[[0,2.3,309.75],[1,1.94,0],[2,2.3,0]],"ltp":1.86,"tv":1401.99,"id":2258415}]}]}
{"op":"mcm","clk":"1001725016","pt":1580639573429,"mc":[{"id":"1.168215940","rc":[{"batb":[[0,1.69,151.43],[1,1.67,227.43],[2,1.01,10.52]],"batl":[[0,1.76,194.88],[1,1.78,184.82],[2,2.3,309.75]],"ltp":1.86,"tv":1401.99,"id":2258415}]}]}
{"op":"mcm","clk":"1001725249","pt":1580639575959,"mc":[{"id":"1.168215940","rc":[{"batb":[[0,1.01,10.52],[1,1.67,0],[2,1.01,0]],"batl":[[0,2.3,309.75],[1,1.78,0],[2,2.3,0]],"ltp":1.86,"tv":1401.99,"id":2258415}]}]}
{"op":"mcm","clk":"1001725532","pt":1580639578744,"mc":[{"id":"1.168215940","rc":[{"batb":[[0,1.55,246.09],[1,1.54,155.33],[2,1.01,10.52]],"batl":[[0,1.92,120.91],[1,1.94,140.99],[2,2.3,309.75]],"ltp":1.86,"tv":1401.99,"id":2258415}]}]}
{"op":"mcm","clk":"1001725646","pt":1580639579953,"mc":[{"id":"1.168215940","rc":[{"batb":[[0,1.01,10.52],[1,1.54,0],[2,1.01,0]],"ltp":1.86,"tv":1401.99,"id":2258415}]}]}
{"op":"mcm","clk":"1001726086","pt":1580639583751,"mc":[{"id":"1.168215940","rc":[{"batb":[[0,2.06,39.49],[1,1.01,10.52]],"batl":[[0,2.3,31.93],[1,2.8,383.64]],"ltp":2.02,"tv":107.25,"id":4423910},{"batb":[[0,1.84,159],[1,1.82,169.56],[2,1.77,53.77]],"batl":[[0,1.92,162.92]],"ltp":1.86,"tv":1401.99,"id":2258415}]}]}
{"op":"mcm","clk":"1001726102","pt":1580639583967,"mc":[{"id":"1.168215940","rc":[{"batl":[[1,2.8,0]],"ltp":2.02,"tv":107.25,"id":4423910}]}]}
{"op":"mcm","clk":"1001726379","pt":1580639586947,"mc":[{"id":"1.168215940","rc":[{"batl":[[1,2.82,231.28]],"ltp":2.02,"tv":107.25,"id":4423910}]}]}
{"op":"mcm","clk":"1001727166","pt":1580639594816,"mc":[{"id":"1.168215940","rc":[{"batb":[[0,1.01,10.52],[1,1.01,0]],"batl":[[0,2.82,231.28],[1,2.82,0]],"ltp":2.02,"tv":107.25,"id":4423910},{"batb":[[0,1.01,10.52],[1,1.82,0],[2,1.77,0]],"batl":[[0,2.3,309.75],[1,1.94,0],[2,2.3,0]],"ltp":1.86,"tv":1401.99,"id":2258415}]}]}
{"op":"mcm","clk":"1001727452","pt":1580639597920,"mc":[{"id":"1.168215940","rc":[{"batb":[[0,1.74,174.66],[1,1.72,205.14],[2,1.01,10.52]],"batl":[[0,1.98,101.2],[1,2,128.59],[2,2.3,309.75]],"ltp":1.86,"tv":1401.99,"id":2258415}]}]}
{"op":"mcm","clk":"1001727795","pt":1580639601336,"mc":[{"id":"1.168215940","rc":[{"batb":[[0,1.01,10.52],[1,1.72,0],[2,1.01,0]],"ltp":1.86,"tv":1401.99,"id":2258415}]}]}
{"op":"mcm","clk":"1001728057","pt":1580639604239,"mc":[{"id":"1.168215940","rc":[{"batb":[[0,1.9,131.17],[1,1.88,152.63],[2,1.01,10.52]],"ltp":1.86,"tv":1401.99,"id":2258415}]}]}
{"op":"mcm","clk":"1001728182","pt":1580639605706,"mc":[{"id":"1.168215940","rc":[{"batb":[[0,2,42.01],[1,1.01,10.52]],"ltp":2.02,"tv":107.25,"id":4423910},{"batl":[[1,1.99,42.01],[2,2,128.59]],"ltp":1.86,"tv":1401.99,"id":2258415}]}]}
{"op":"mcm","clk":"1001731810","pt":1580639645787,"mc":[{"id":"1.168215940","rc":[{"batb":[[0,1.9,103.57]],"ltp":1.86,"tv":1401.99,"id":2258415}]}]}
{"op":"mcm","clk":"1001732087","pt":1580639648767,"mc":[{"id":"1.168215940","rc":[{"batl":[[0,1.98,127.72]],"ltp":1.86,"tv":1401.99,"id":2258415}]}]}
{"op":"mcm","clk":"1001735775","pt":1580639684931,"mc":[{"id":"1.168215940","rc":[{"batb":[[0,1.01,10.52],[1,1.88,0],[2,1.01,0]],"batl":[[0,1.99,42.01],[1,2.3,309.75],[2,2,0]],"ltp":1.86,"tv":1401.99,"id":2258415}]}]}
{"op":"mcm","clk":"1001735928","pt":1580639686670,"mc":[{"id":"1.168215940","rc":[{"batb":[[0,1.01,10.52],[1,1.01,0]],"ltp":2.02,"tv":107.25,"id":4423910},{"batl":[[0,2.3,309.75],[1,2.3,0]],"ltp":1.86,"tv":1401.99,"id":2258415}]}]}
{"op":"mcm","clk":"1001736080","pt":1580639687959,"mc":[{"id":"1.168215940","rc":[{"batb":[[0,1.78,113.72],[1,1.76,189.38],[2,1.01,10.52]],"batl":[[1,2.34,83.3],[2,2.38,158.28]],"ltp":1.86,"tv":1401.99,"id":2258415}]}]}
{"op":"mcm","clk":"1001736852","pt":1580639695638,"mc":[{"id":"1.168215940","rc":[{"batl":[[1,2.34,0],[2,2.38,0]],"ltp":1.86,"tv":1401.99,"id":2258415}]}]}
{"op":"mcm","clk":"1001737197","pt":1580639698942,"mc":[{"id":"1.168215940","rc":[{"batl":[[0,1.85,139.49],[1,1.87,157.86],[2,2.3,309.75]],"ltp":1.86,"tv":1401.99,"id":2258415}]}]}
{"op":"mcm","clk":"1001737291","pt":1580639699692,"mc":[{"id":"1.168215940","rc":[{"batb":[[0,2.12,36.97],[1,1.01,10.52]],"batl":[[0,2.38,30.25],[1,2.82,231.28]],"ltp":2.02,"tv":107.25,"id":4423910},{"batb":[[2,1.73,57.13]],"batl":[[2,1.89,42.01]],"ltp":1.86,"tv":1401.99,"id":2258415}]}]}
{"op":"mcm","clk":"1001738356","pt":1580639708727,"mc":[{"id":"1.168215940","rc":[{"batb":[[0,1.01,10.52],[1,1.01,0]],"batl":[[0,2.82,231.28],[1,2.82,0]],"ltp":2.02,"tv":107.25,"id":4423910},{"batb":[[0,1.01,10.52],[1,1.76,0],[2,1.73,0]],"batl":[[0,2.3,309.75],[1,1.87,0],[2,1.89,0]],"ltp":1.86,"tv":1401.99,"id":2258415}]}]}
{"op":"mcm","clk":"1001738721","pt":1580639711880,"mc":[{"id":"1.168215940","rc":[{"batl":[[0,2.08,114.67],[1,2.3,309.75]],"ltp":1.86,"tv":1401.99,"id":2258415}]}]}
{"op":"mcm","clk":"1001738978","pt":1580639714499,"mc":[{"id":"1.168215940","rc":[{"batb":[[0,1.69,222.19],[1,1.67,227.66],[2,1.01,10.52]],"batl":[[0,2.06,136.22],[1,2.08,114.67],[2,2.3,309.75]],"ltp":1.86,"tv":1401.99,"id":2258415}]}]}
{"op":"mcm","clk":"1001739085","pt":1580639715499,"mc":[{"id":"1.168215940","rc":[{"batl":[[0,2.3,309.75],[1,2.08,0],[2,2.3,0]],"ltp":1.86,"tv":1401.99,"id":2258415}]}]}
{"op":"mcm","clk":"1001739345","pt":1580639717899,"mc":[{"id":"1.168215940","rc":[{"batl":[[0,1.76,127.73],[1,1.78,185],[2,2.3,309.75]],"ltp":1.86,"tv":1401.99,"id":2258415}]}]}
{"op":"mcm","clk":"1001739547","pt":1580639719693,"mc":[{"id":"1.168215940","rc":[{"batb":[[0,2.22,33.61],[1,1.01,10.52]],"batl":[[0,2.48,27.73]],"ltp":2.02,"tv":107.25,"id":4423910},{"batb":[[1,1.67,289.83]],"batl":[[2,1.83,42.01]],"ltp":1.86,"tv":1401.99,"id":2258415}]}]}
{"op":"mcm","clk":"1001739807","pt":1580639721919,"mc":[{"id":"1.168215940","rc":[{"batl":[[1,3.15,200.42]],"ltp":2.02,"tv":107.25,"id":4423910}]}]}
{"op":"mcm","clk":"1001740579","pt":1580639728922,"mc":[{"id":"1.168215940","rc":[{"batb":[[0,1.01,10.52],[1,1.01,0]],"batl":[[0,3.15,200.42],[1,3.15,0]],"ltp":2.02,"tv":107.25,"id":4423910},{"batb":[[0,1.01,10.52],[1,1.67,0],[2,1.01,0]],"batl":[[0,2.3,309.75],[1,1.78,0],[2,1.83,0]],"ltp":1.86,"tv":1401.99,"id":2258415}]}]}
{"op":"mcm","clk":"1001740881","pt":1580639731434,"mc":[{"id":"1.168215940","rc":[{"batb":[[0,1.65,208.08],[1,1.64,122.25],[2,1.01,10.52]],"batl":[[0,1.87,127.14],[1,1.89,152.91],[2,2.3,309.75]],"ltp":1.86,"tv":1401.99,"id":2258415}]}]}
{"op":"mcm","clk":"1001741015","pt":1580639732941,"mc":[{"id":"1.168215940","rc":[{"batb":[[0,1.01,10.52],[1,1.64,0],[2,1.01,0]],"ltp":1.86,"tv":1401.99,"id":2258415}]}]}
{"op":"mcm","clk":"1001741292","pt":1580639735931,"mc":[{"id":"1.168215940","rc":[{"batb":[[0,1.8,109.75],[1,1.78,182.54],[2,1.01,10.52]],"ltp":1.86,"tv":1401.99,"id":2258415}]}]}
{"op":"mcm","clk":"1001741481","pt":1580639737648,"mc":[{"id":"1.168215940","rc":[{"batb":[[0,2.1,37.81],[1,1.01,10.52]],"batl":[[0,2.34,31.09]],"ltp":2.02,"tv":107.25,"id":4423910},{"batb":[[2,1.74,56.29]],"batl":[[2,1.91,42.01]],"ltp":1.86,"tv":1401.99,"id":2258415}]}]}
{"op":"mcm","clk":"1001741608","pt":1580639738953,"mc":[{"id":"1.168215940","rc":[{"batl":[[1,2.92,221.26]],"ltp":2.02,"tv":107.25,"id":4423910}]}]}
{"op":"mcm","clk":"1001742308","pt":1580639745864,"mc":[{"id":"1.168215940","rc":[{"batb":[[0,1.74,56.29],[1,1.01,10.52],[2,1.74,0]],"batl":[[0,1.91,42.01],[1,2.3,309.75],[2,1.91,0]],"ltp":1.86,"tv":1401.99,"id":2258415}]}]}
{"op":"mcm","clk":"1001742389","pt":1580639746801,"mc":[{"id":"1.168215940","rc":[{"batb":[[0,1.01,10.52],[1,1.01,0]],"batl":[[0,2.92,221.26],[1,2.92,0]],"ltp":2.02,"tv":107.25,"id":4423910},{"batb":[[0,1.01,10.52],[1,1.01,0]],"batl":[[0,2.3,309.75],[1,2.3,0]],"ltp":1.86,"tv":1401.99,"id":2258415}]}]}
{"op":"mcm","clk":"1001742563","pt":1580639748578,"mc":[{"id":"1.168215940","rc":[{"batb":[[0,1.7,134.63],[1,1.68,222.58],[2,1.01,10.52]],"batl":[[0,2.16,119.63],[1,2.18,100.2],[2,2.3,309.75]],"ltp":1.86,"tv":1401.99,"id":2258415}]}]}
{"op":"mcm","clk":"1001742647","pt":1580639749363,"mc":[{"id":"1.168215940","rc":[{"batb":[[0,1.01,10.52],[1,1.68,0],[2,1.01,0]],"batl":[[0,2.3,309.75],[1,2.18,0],[2,2.3,0]],"ltp":1.86,"tv":1401.99,"id":2258415}]}]}
{"op":"mcm","clk":"1001742974","pt":1580639752552,"mc":[{"id":"1.168215940","rc":[{"batb":[[0,1.84,164.97],[1,1.82,169.69],[2,1.01,10.52]],"batl":[[0,1.92,115.71],[1,1.94,141.12],[2,2.3,309.75]],"ltp":1.86,"tv":1401.99,"id":2258415}]}]}
{"op":"mcm","clk":"1001743153","pt":1580639754385,"mc":[{"id":"1.168215940","rc":[{"batb":[[0,1.01,10.52],[1,1.82,0],[2,1.01,0]],"batl":[[0,2.3,309.75],[1,1.94,0],[2,2.3,0]],"ltp":1.86,"tv":1401.99,"id":2258415}]}]}
{"op":"mcm","clk":"1001743507","pt":1580639757780,"mc":[{"id":"1.168215940","rc":[{"batb":[[0,1.7,134.63],[1,1.68,222.58],[2,1.01,10.52]],"ltp":1.86,"tv":1401.99,"id":2258415}]}]}
{"op":"mcm","clk":"1001743856","pt":1580639760777,"mc":[{"id":"1.168215940","rc":[{"batl":[[0,1.77,199.29],[1,1.79,181.46],[2,2.3,309.75]],"ltp":1.86,"tv":1401.99,"id":2258415}]}]}
{"op":"mcm","clk":"1001743952","pt":1580639761725,"mc":[{"id":"1.168215940","rc":[{"batb":[[0,2.22,33.61],[1,1.01,10.52]],"batl":[[0,2.48,27.73],[1,2.92,221.26]],"ltp":2.02,"tv":107.25,"id":4423910},{"batb":[[2,1.67,62.17]],"batl":[[2,1.82,42.01]],"ltp":1.86,"tv":1401.99,"id":2258415}]}]}
{"op":"mcm","clk":"1001744952","pt":1580639772093,"mc":[{"id":"1.168215940","rc":[{"trd":[[1.7,0.34]],"batb":[[0,1.7,134.46]],"ltp":1.7,"tv":1402.33,"id":2258415}],"tv":1509.59}]}
{"op":"mcm","clk":"1001745813","pt":1580639780784,"mc":[{"id":"1.168215940","rc":[{"batb":[[0,1.01,10.52],[1,1.01,0]],"batl":[[0,2.92,221.26],[1,2.92,0]],"ltp":2.02,"tv":107.25,"id":4423910},{"batb":[[0,1.01,10.52],[1,1.68,0],[2,1.67,0]],"batl":[[0,2.3,309.75],[1,1.79,0],[2,1.82,0]],"ltp":1.7,"tv":1402.33,"id":2258415}]}]}
{"op":"mcm","clk":"1001746101","pt":1580639783861,"mc":[{"id":"1.168215940","rc":[{"batb":[[0,1.66,170.68],[1,1.65,119.7],[2,1.01,10.52]],"batl":[[0,1.87,150.14],[1,1.89,152.87],[2,2.3,309.75]],"ltp":1.7,"tv":1402.33,"id":2258415}]}]}
{"op":"mcm","clk":"1001746633","pt":1580639789590,"mc":[{"id":"1.168215940","rc":[{"batl":[[0,2.3,309.75],[1,1.89,0],[2,2.3,0]],"ltp":1.7,"tv":1402.33,"id":2258415}]}]}
{"op":"mcm","clk":"1001746933","pt":1580639792686,"mc":[{"id":"1.168215940","rc":[{"batl":[[0,1.72,113.85],[1,1.74,199.48],[2,2.3,309.75]],"ltp":1.7,"tv":1402.33,"id":2258415}]}]}
{"op":"mcm","clk":"1001747034","pt":1580639793686,"mc":[{"id":"1.168215940","rc":[{"batb":[[0,2.28,32.77],[1,1.01,10.52]],"batl":[[0,2.56,26.89],[1,2.92,221.26]],"ltp":2.02,"tv":107.25,"id":4423910},{"batb":[[2,1.64,65.54]],"batl":[[2,1.79,42.01]],"ltp":1.7,"tv":1402.33,"id":2258415}]}]}
{"op":"mcm","clk":"1001750552","pt":1580639829765,"mc":[{"id":"1.168215940","rc":[{"batb":[[0,1.64,65.54],[1,1.01,10.52],[2,1.64,0]],"batl":[[0,1.79,42.01],[1,2.3,309.75],[2,1.79,0]],"ltp":1.7,"tv":1402.33,"id":2258415}]}]}
{"op":"mcm","clk":"1001750910","pt":1580639832759,"mc":[{"id":"1.168215940","rc":[{"batb":[[0,1.01,10.52],[1,1.01,0]],"batl":[[0,2.92,221.26],[1,2.92,0]],"ltp":2.02,"tv":107.25,"id":4423910},{"batb":[[0,1.49,179.27],[1,1.48,182.08],[2,1.01,10.51]],"batl":[[0,1.85,162.98],[1,1.87,157.81],[2,2.3,309.75]],"ltp":1.7,"tv":1402.33,"id":2258415}]}]}
{"op":"mcm","clk":"1001751145","pt":1580639835261,"mc":[{"id":"1.168215940","rc":[{"batl":[[0,2.3,309.75],[1,1.87,0],[2,2.3,0]],"ltp":1.7,"tv":1402.33,"id":2258415}]}]}
{"op":"mcm","clk":"1001751471","pt":1580639838500,"mc":[{"id":"1.168215940","rc":[{"batl":[[0,1.54,223.57],[1,1.55,149.12]],"ltp":1.7,"tv":1402.33,"id":2258415}]}]}
{"op":"mcm","clk":"1001751613","pt":1580639839658,"mc":[{"id":"1.168215940","rc":[{"batb":[[0,2.64,25.21],[1,1.01,10.52]],"batl":[[0,2.98,21]],"ltp":2.02,"tv":107.25,"id":4423910},{"batb":[[0,1.5,84.02],[1,1.49,179.27],[2,1.48,182.08]],"batl":[[2,1.61,42.01]],"ltp":1.7,"tv":1402.33,"id":2258415}]}]}
{"op":"mcm","clk":"1001751782","pt":1580639841181,"mc":[{"id":"1.168215940","rc":[{"batl":[[1,3.9,158.24]],"ltp":2.02,"tv":107.25,"id":4423910}]}]}
{"op":"mcm","clk":"1001753103","pt":1580639854901,"mc":[{"id":"1.168215940","rc":[{"batb":[[1,1.01,10.52],[2,1.48,0]],"batl":[[0,1.61,42.01],[1,1.95,409.86],[2,1.61,0]],"ltp":1.7,"tv":1402.33,"id":2258415}]}]}
{"op":"mcm","clk":"1001753283","pt":1580639856784,"mc":[{"id":"1.168215940","rc":[{"batb":[[0,1.01,10.52],[1,1.01,0]],"batl":[[0,3.9,158.24],[1,3.9,0]],"ltp":2.02,"tv":107.25,"id":4423910},{"batb":[[0,1.01,10.52],[1,1.01,0]],"batl":[[0,1.95,409.86],[1,1.95,0]],"ltp":1.7,"tv":1402.33,"id":2258415}]}]}
{"op":"mcm","clk":"1001753386","pt":1580639857881,"mc":[{"id":"1.168215940","rc":[{"batb":[[0,1.3,350.05],[1,1.29,352.96],[2,1.01,10.51]],"batl":[[0,1.68,139.82],[1,1.7,215.71],[2,1.95,409.86]],"ltp":1.7,"tv":1402.33,"id":2258415}]}]}
{"op":"mcm","clk":"1001753435","pt":1580639858403,"mc":[{"id":"1.168215940","rc":[{"batb":[[0,1.01,10.52],[1,1.29,0],[2,1.01,0]],"batl":[[0,1.95,409.86],[1,1.7,0],[2,1.95,0]],"ltp":1.7,"tv":1402.33,"id":2258415}]}]}
{"op":"mcm","clk":"1001753840","pt":1580639861388,"mc":[{"id":"1.168215940","rc":[{"batb":[[0,1.45,153.12],[1,1.44,204.42],[2,1.01,10.51]],"batl":[[0,1.49,159.37],[1,1.5,169.84],[2,1.95,409.86]],"ltp":1.7,"tv":1402.33,"id":2258415}]}]}
{"op":"mcm","clk":"1001754368","pt":1580639865692,"mc":[{"id":"1.168215940","rc":[{"batb":[[0,1.01,10.52],[1,1.44,0],[2,1.01,0]],"batl":[[0,1.95,409.86],[1,1.5,0],[2,1.95,0]],"ltp":1.7,"tv":1402.33,"id":2258415}]}]}
{"op":"mcm","clk":"1001754907","pt":1580639868925,"mc":[{"id":"1.168215940","rc":[{"batb":[[0,1.3,350.05],[1,1.29,352.96],[2,1.01,10.51]],"batl":[[0,1.68,139.82],[1,1.7,215.71],[2,1.95,409.86]],"ltp":1.7,"tv":1402.33,"id":2258415}]}]}
{"op":"mcm","clk":"1001754925","pt":1580639869089,"mc":[{"id":"1.168215940","rc":[{"batl":[[0,1.95,409.86],[1,1.7,0],[2,1.95,0]],"ltp":1.7,"tv":1402.33,"id":2258415}]}]}
{"op":"mcm","clk":"1001755223","pt":1580639872410,"mc":[{"id":"1.168215940","rc":[{"trd":[[1.48,0.02]],"batb":[[0,1.3,350.04]],"batl":[[0,1.34,390.59],[1,1.35,266.22]],"ltp":1.48,"tv":1402.35,"id":2258415}],"tv":1509.61}]}
{"op":"mcm","clk":"1001755331","pt":1580639873708,"mc":[{"id":"1.168215940","rc":[{"batl":[[0,4.1,13.44]],"ltp":2.02,"tv":107.25,"id":4423910},{"batb":[[0,1.32,131.07],[1,1.3,350.04],[2,1.29,352.96]],"ltp":1.48,"tv":1402.35,"id":2258415}]}]}
{"op":"mcm","clk":"1001755524","pt":1580639875743,"mc":[{"id":"1.168215940","rc":[{"batb":[[0,3.5,16.8],[1,1.01,10.52]],"batl":[[1,6,106.18]],"ltp":2.02,"tv":107.25,"id":4423910},{"batl":[[2,1.4,42.01]],"ltp":1.48,"tv":1402.35,"id":2258415}]}]}
{"op":"mcm","clk":"1001757183","pt":1580639893362,"mc":[{"id":"1.168215940","rc":[{"batb":[[1,1.01,10.51],[2,1.29,0]],"batl":[[0,1.4,42.01],[1,1.66,579.81],[2,1.4,0]],"ltp":1.48,"tv":1402.35,"id":2258415}]}]}
{"op":"mcm","clk":"1001757313","pt":1580639894831,"mc":[{"id":"1.168215940","rc":[{"batb":[[0,1.01,10.52],[1,1.01,0]],"ltp":2.02,"tv":107.25,"id":4423910},{"batb":[[0,1.01,10.51],[1,1.01,0]],"ltp":1.48,"tv":1402.35,"id":2258415}]}]}
{"op":"mcm","clk":"1001757405","pt":1580639896026,"mc":[{"id":"1.168215940","rc":[{"batb":[[0,1.14,580.56],[1,1.13,536.41],[2,1.01,10.51]],"batl":[[0,1.46,140.88],[1,1.47,184.46]],"ltp":1.48,"tv":1402.35,"id":2258415}]}]}
{"op":"mcm","clk":"1001758158","pt":1580639904685,"mc":[{"id":"1.168215940","rc":[{"batl":[[0,1.16,385.54],[1,1.17,630.29]],"ltp":1.48,"tv":1402.35,"id":2258415}]}]}
{"op":"mcm","clk":"1001758297","pt":1580639905881,"mc":[{"id":"1.168215940","rc":[{"batb":[[0,6.2,7.56],[1,1.01,10.52]],"batl":[[0,7.6,5.88]],"ltp":2.02,"tv":107.25,"id":4423910},{"batb":[[0,1.15,168.04],[1,1.14,580.56],[2,1.13,536.41]],"batl":[[2,1.19,42.01]],"ltp":1.48,"tv":1402.35,"id":2258415}]}]}
{"op":"mcm","clk":"1001758400","pt":1580639906789,"mc":[{"id":"1.168215940","rc":[{"batl":[[1,12.5,65.97]],"ltp":2.02,"tv":107.25,"id":4423910}]}]}
{"op":"mcm","clk":"1001759188","pt":1580639914961,"mc":[{"id":"1.168215940","rc":[{"batb":[[1,1.14,529.37]],"ltp":1.48,"tv":1402.35,"id":2258415}]}]}
{"op":"mcm","clk":"1001759258","pt":1580639915748,"mc":[{"id":"1.168215940","rc":[{"batb":[[1,1.14,479.82]],"ltp":1.48,"tv":1402.35,"id":2258415}]}]}
{"op":"mcm","clk":"1001759432","pt":1580639917837,"mc":[{"id":"1.168215940","rc":[{"batb":[[2,1.13,588.04]],"batl":[[0,1.16,435.83]],"ltp":1.48,"tv":1402.35,"id":2258415}]}]}
{"op":"mcm","clk":"1001759465","pt":1580639918159,"mc":[{"id":"1.168215940","rc":[{"batb":[[2,1.13,638.04]],"batl":[[0,1.16,484.51]],"ltp":1.48,"tv":1402.35,"id":2258415}]}]}
{"op":"mcm","clk":"1001760482","pt":1580639928774,"mc":[{"id":"1.168215940","rc":[{"batb":[[1,1.01,10.51],[2,1.13,0]],"batl":[[0,1.19,42.01],[1,1.45,839.84],[2,1.19,0]],"ltp":1.48,"tv":1402.35,"id":2258415}]}]}
{"op":"mcm","clk":"1001760732","pt":1580639932843,"mc":[{"id":"1.168215940","rc":[{"batb":[[0,1.01,10.52],[1,1.01,0]],"ltp":2.02,"tv":107.25,"id":4423910},{"batb":[[0,1.04,1219.21]],"batl":[[0,1.23,342.71],[1,1.24,425.56]],"ltp":1.48,"tv":1402.35,"id":2258415}]}]}
{"op":"mcm","clk":"1001761217","pt":1580639936667,"mc":[{"id":"1.168215940","rc":[{"batl":[[0,1.23,403.84]],"ltp":1.48,"tv":1402.35,"id":2258415}]}]}
{"op":"mcm","clk":"1001761333","pt":1580639938180,"mc":[{"id":"1.168215940","rc":[{"batb":[[0,1.01,10.51],[1,1.01,0]],"ltp":1.48,"tv":1402.35,"id":2258415}]}]}
{"op":"mcm","clk":"1001761691","pt":1580639941802,"mc":[{"id":"1.168215940","rc":[{"batb":[[0,4.7,10.92],[1,1.01,10.52]],"batl":[[0,5.6,8.4]],"ltp":2.02,"tv":107.25,"id":4423910},{"batb":[[0,1.2,587.78],[1,1.19,472.8],[2,1.01,10.51]],"batl":[[2,1.27,42.01]],"ltp":1.48,"tv":1402.35,"id":2258415}]}]}
{"op":"mcm","clk":"1001761839","pt":1580639942966,"mc":[{"id":"1.168215940","rc":[{"batl":[[1,8.6,81.89]],"ltp":2.02,"tv":107.25,"id":4423910}]}]}
{"op":"mcm","clk":"1001762841","pt":1580639953791,"mc":[{"id":"1.168215940","rc":[{"batb":[[0,1.01,10.51],[1,1.19,0],[2,1.01,0]],"batl":[[0,1.27,42.01],[1,1.53,714.1],[2,1.27,0]],"ltp":1.48,"tv":1402.35,"id":2258415}]}]}
{"op":"mcm","clk":"1001762935","pt":1580639954921,"mc":[{"id":"1.168215940","rc":[{"batb":[[0,1.01,10.52],[1,1.01,0]],"batl":[[0,8.6,81.89],[1,8.6,0]],"ltp":2.02,"tv":107.25,"id":4423910},{"batl":[[0,1.53,714.1],[1,1.53,0]],"ltp":1.48,"tv":1402.35,"id":2258415}]}]}
{"op":"mcm","clk":"1001763075","pt":1580639956647,"mc":[{"id":"1.168215940","rc":[{"batb":[[0,1.04,1219.21],[1,1.01,10.51]],"batl":[[0,1.36,294.46],[1,1.37,251.3]],"ltp":1.48,"tv":1402.35,"id":2258415}]}]}
{"op":"mcm","clk":"1001764488","pt":1580639971926,"mc":[{"id":"1.168215940","rc":[{"batl":[[0,1.06,1196.21]],"ltp":1.48,"tv":1402.35,"id":2258415}]}]}
{"op":"mcm","clk":"1001764758","pt":1580639974949,"mc":[{"id":"1.168215940","rc":[{"batl":[[0,65,40.67]],"ltp":2.02,"tv":107.25,"id":4423910},{"batl":[[1,1.32,1159.8]],"ltp":1.48,"tv":1402.35,"id":2258415}]}]}
{"op":"mcm","clk":"1001765787","pt":1580639986754,"mc":[{"id":"1.168215940","rc":[{"batb":[[0,1.04,2392.08]],"ltp":1.48,"tv":1402.35,"id":2258415}]}]}
{"op":"mcm","clk":"1001771882","pt":1580640051922,"mc":[{"id":"1.168215940","rc":[{"batb":[[0,1.01,10.51],[1,1.01,0]],"batl":[[0,1.32,1159.8],[1,1.32,0]],"ltp":1.48,"tv":1402.35,"id":2258415}]}]}
{"op":"mcm","clk":"1001772485","pt":1580640058538,"mc":[{"id":"1.168215940","rc":[{"batb":[[0,1.05,1207.6],[1,1.01,10.51]],"batl":[[0,1.07,1145.45]],"ltp":1.48,"tv":1402.35,"id":2258415}]}]}
{"op":"mcm","clk":"1001772606","pt":1580640059841,"mc":[{"id":"1.168215940","rc":[{"batb":[[0,1.01,10.51],[1,1.01,0]],"ltp":1.48,"tv":1402.35,"id":2258415}]}]}
{"op":"mcm","clk":"1001772692","pt":1580640060834,"mc":[{"id":"1.168215940","rc":[{"batl":[[0,42,43.68]],"ltp":2.02,"tv":107.25,"id":4423910},{"batl":[[0,1.34,1109.8]],"ltp":1.48,"tv":1402.35,"id":2258415}]}]}
{"op":"mcm","clk":"1001772926","pt":1580640062869,"mc":[{"id":"1.168215940","rc":[{"batb":[[0,1.02,1243.12],[1,1.01,10.51]],"batl":[[0,1.12,641.98],[1,1.13,485.8]],"ltp":1.48,"tv":1402.35,"id":2258415}]}]}
{"op":"mcm","clk":"1001773510","pt":1580640069834,"mc":[{"id":"1.168215940","rc":[{"batb":[[0,1.01,10.51],[1,1.01,0]],"ltp":1.48,"tv":1402.35,"id":2258415}]}]}
{"op":"mcm","clk":"1001773790","pt":1580640072870,"mc":[{"id":"1.168215940","rc":[{"batb":[[0,1.1,1045.67],[1,1.01,10.51]],"ltp":1.48,"tv":1402.35,"id":2258415}]}]}
{"op":"mcm","clk":"1001773863","pt":1580640073853,"mc":[{"id":"1.168215940","rc":[{"batb":[[0,9.8,4.2],[1,1.01,10.52]],"batl":[[0,13,3.36]],"ltp":2.02,"tv":107.25,"id":4423910},{"batl":[[0,1.11,42.01],[1,1.12,641.98],[2,1.13,485.8]],"ltp":1.48,"tv":1402.35,"id":2258415}]}]}
{"op":"mcm","clk":"1001773948","pt":1580640074851,"mc":[{"id":"1.168215940","rc":[{"batl":[[0,1.12,641.98],[1,1.13,485.8],[2,1.13,0]],"ltp":1.48,"tv":1402.35,"id":2258415}]}]}
{"op":"mcm","clk":"1001774024","pt":1580640075743,"mc":[{"id":"1.168215940","rc":[{"batl":[[0,12.5,3.36],[1,17,57.33]],"ltp":2.02,"tv":107.25,"id":4423910},{"batl":[[2,1.4,927.7]],"ltp":1.48,"tv":1402.35,"id":2258415}]}]}
{"op":"mcm","clk":"1001775147","pt":1580640086850,"mc":[{"id":"1.168215940","rc":[{"batb":[[0,1.01,10.51],[1,1.01,0]],"batl":[[0,1.4,927.7],[1,1.13,0],[2,1.4,0]],"ltp":1.48,"tv":1402.35,"id":2258415}]}]}
{"op":"mcm","clk":"1001775344","pt":1580640088889,"mc":[{"id":"1.168215940","rc":[{"batb":[[0,1.01,10.52],[1,1.01,0]],"batl":[[0,17,57.33],[1,17,0]],"ltp":2.02,"tv":107.25,"id":4423910}]}]}
{"op":"mcm","clk":"1001775424","pt":1580640089778,"mc":[{"id":"1.168215940","rc":[{"batb":[[0,1.06,491.36],[1,1.05,711.56],[2,1.01,10.51]],"batl":[[0,1.25,527.48],[1,1.26,395.99]],"ltp":1.48,"tv":1402.35,"id":2258415}]}]}
{"op":"mcm","clk":"1001776115","pt":1580640096881,"mc":[{"id":"1.168215940","rc":[{"batl":[[0,1.07,855.66],[1,1.08,326.31]],"ltp":1.48,"tv":1402.35,"id":2258415}]}]}
{"op":"mcm","clk":"1001776202","pt":1580640097908,"mc":[{"id":"1.168215940","rc":[{"batl":[[0,1.07,897.67]],"ltp":1.48,"tv":1402.35,"id":2258415}]}]}
{"op":"mcm","clk":"1001776349","pt":1580640099524,"mc":[{"id":"1.168215940","rc":[{"batl":[[0,42,43.68]],"ltp":2.02,"tv":107.25,"id":4423910},{"batl":[[2,1.34,1109.8]],"ltp":1.48,"tv":1402.35,"id":2258415}]}]}
{"op":"mcm","clk":"1001777010","pt":1580640105718,"mc":[{"id":"1.168215940","rc":[{"batb":[[0,1.01,10.51],[1,1.05,0],[2,1.01,0]],"batl":[[0,1.07,42.01],[1,1.34,1109.8],[2,1.34,0]],"ltp":1.48,"tv":1402.35,"id":2258415}]}]}
{"op":"mcm","clk":"1001777154","pt":1580640106915,"mc":[{"id":"1.168215940","rc":[{"batl":[[0,1.34,1109.8],[1,1.34,0]],"ltp":1.48,"tv":1402.35,"id":2258415}]}]}
{"op":"mcm","clk":"1001777331","pt":1580640108592,"mc":[{"id":"1.168215940","rc":[{"batb":[[0,1.02,1243.12],[1,1.01,10.51]],"batl":[[0,1.16,340.5],[1,1.17,660.04]],"ltp":1.48,"tv":1402.35,"id":2258415}]}]}
{"op":"mcm","clk":"1001777427","pt":1580640109634,"mc":[{"id":"1.168215940","rc":[{"batb":[[0,1.01,10.51],[1,1.01,0]],"ltp":1.48,"tv":1402.35,"id":2258415}]}]}
{"op":"mcm","clk":"1001777766","pt":1580640112835,"mc":[{"id":"1.168215940","rc":[{"batb":[[0,1.07,1185.03],[1,1.01,10.51]],"batl":[[0,1.09,1099.32]],"ltp":1.48,"tv":1402.35,"id":2258415}]}]}
{"op":"mcm","clk":"1001777992","pt":1580640114931,"mc":[{"id":"1.168215940","rc":[{"batb":[[0,1.01,10.51],[1,1.01,0]],"ltp":1.48,"tv":1402.35,"id":2258415}]}]}
{"op":"mcm","clk":"1001778109","pt":1580640115917,"mc":[{"id":"1.168215940","rc":[{"batl":[[0,24,50.52]],"ltp":2.02,"tv":107.25,"id":4423910},{"batl":[[0,1.37,1010.69]],"ltp":1.48,"tv":1402.35,"id":2258415}]}]}
{"op":"mcm","clk":"1001778307","pt":1580640117812,"mc":[{"id":"1.168215940","rc":[{"batb":[[0,1.02,1243.12],[1,1.01,10.51]],"batl":[[0,1.16,340.5],[1,1.17,660.04]],"ltp":1.48,"tv":1402.35,"id":2258415}]}]}
{"op":"mcm","clk":"1001780431","pt":1580640133929,"mc":[{"id":"1.168215940","rc":[{"batb":[[0,1.02,1411.16]],"batl":[[0,1.03,326.55],[1,1.04,895.8]],"ltp":1.48,"tv":1402.35,"id":2258415}]}]}
{"op":"mcm","clk":"1001780792","pt":1580640136874,"mc":[{"id":"1.168215940","rc":[{"batl":[[0,520,35.52]],"ltp":2.02,"tv":107.25,"id":4423910},{"batl":[[2,1.3,1255.97]],"ltp":1.48,"tv":1402.35,"id":2258415}]}]}
{"op":"mcm","clk":"1001782800","pt":1580640150894,"mc":[{"id":"1.168215940","rc":[{"batb":[[0,1.02,168.04]],"batl":[[0,1.3,1255.97],[1,1.04,0],[2,1.3,0]],"ltp":1.48,"tv":1402.35,"id":2258415}]}]}
{"op":"mcm","clk":"1001782856","pt":1580640151270,"mc":[{"id":"1.168215940","rc":[{"batb":[[0,1.01,10.51],[1,1.01,0]],"ltp":1.48,"tv":1402.35,"id":2258415}]}]}
{"op":"mcm","clk":"1001783225","pt":1580640153674,"mc":[{"id":"1.168215940","rc":[{"batl":[[0,1.09,1153.84]],"ltp":1.48,"tv":1402.35,"id":2258415}]}]}
{"op":"mcm","clk":"1001783715","pt":1580640157695,"mc":[{"id":"1.168215940","rc":[{"trd":[[1.01,21.02]],"batl":[[0,1.01,1244.92]],"ltp":1.01,"tv":1423.37,"id":2258415}],"tv":1530.62}]}
{"op":"mcm","clk":"1001783928","pt":1580640159368,"mc":[{"id":"1.168215940","rc":[{"batl":[[1,1.27,1384.57]],"ltp":1.01,"tv":1423.37,"id":2258415}]}]}
{"op":"mcm","clk":"1001784898","pt":1580640165715,"mc":[{"id":"1.168215940","rc":[{"batl":[[0,1.27,1384.57],[1,1.27,0]],"ltp":1.01,"tv":1423.37,"id":2258415}]}]}
{"op":"mcm","clk":"1001785369","pt":1580640168723,"mc":[{"id":"1.168215940","rc":[{"batl":[[0,1.03,1231.05]],"ltp":1.01,"tv":1423.37,"id":2258415}]}]}
{"op":"mcm","clk":"1001785702","pt":1580640170930,"mc":[{"id":"1.168215940","marketDefinition":{"bspMarket":false,"turnInPlayEnabled":true,"persistenceEnabled":true,"marketBaseRate":5.0,"eventId":"29681228","eventTypeId":"2","numberOfWinners":1,"bettingType":"ODDS","marketType":"SET_WINNER","marketTime":"2020-02-02T09:23:00.000Z","suspendTime":"2020-02-02T09:23:00.000Z","bspReconciled":false,"complete":true,"inPlay":true,"crossMatching":true,"runnersVoidable":false,"numberOfActiveRunners":2,"betDelay":3,"status":"SUSPENDED","runners":[{"status":"ACTIVE","sortPriority":1,"id":4423910,"name":"Matthew Ebden"},{"status":"ACTIVE","sortPriority":2,"id":2258415,"name":"Lukas Rosol"}],"regulators":["MR_INT"],"countryCode":"IN","discountAllowed":true,"timezone":"UTC","openDate":"2020-02-02T09:23:00.000Z","version":3148430938,"name":"Set 2 Winner","eventName":"Ebden v Rosol"}}]}
{"op":"mcm","clk":"1001790852","pt":1580640204148,"mc":[{"id":"1.168215940","tv":0.0}]}
{"op":"mcm","clk":"1001790989","pt":1580640204993,"mc":[{"id":"1.168215940","marketDefinition":{"bspMarket":false,"turnInPlayEnabled":true,"persistenceEnabled":true,"marketBaseRate":5.0,"eventId":"29681228","eventTypeId":"2","numberOfWinners":1,"bettingType":"ODDS","marketType":"SET_WINNER","marketTime":"2020-02-02T09:23:00.000Z","suspendTime":"2020-02-02T09:23:00.000Z","bspReconciled":false,"complete":true,"inPlay":true,"crossMatching":false,"runnersVoidable":false,"numberOfActiveRunners":0,"betDelay":3,"status":"CLOSED","settledTime":"2020-02-02T10:43:23.000Z","runners":[{"status":"LOSER","sortPriority":1,"id":4423910,"name":"Matthew Ebden"},{"status":"WINNER","sortPriority":2,"id":2258415,"name":"Lukas Rosol"}],"regulators":["MR_INT"],"countryCode":"IN","discountAllowed":true,"timezone":"UTC","openDate":"2020-02-02T09:23:00.000Z","version":3148431222,"name":"Set 2 Winner","eventName":"Ebden v Rosol"}}]}
