{"op":"mcm","clk":"994279932","pt":1580566029164,"mc":[{"id":"1.168215939","marketDefinition":{"bspMarket":false,"turnInPlayEnabled":true,"persistenceEnabled":true,"marketBaseRate":5.0,"eventId":"29681228","eventTypeId":"2","numberOfWinners":1,"bettingType":"ODDS","marketType":"SET_WINNER","marketTime":"2020-02-02T04:00:00.000Z","suspendTime":"2020-02-02T04:00:00.000Z","bspReconciled":false,"complete":true,"inPlay":false,"crossMatching":false,"runnersVoidable":false,"numberOfActiveRunners":2,"betDelay":0,"status":"OPEN","runners":[{"status":"ACTIVE","sortPriority":1,"id":4423910,"name":"Matthew Ebden"},{"status":"ACTIVE","sortPriority":2,"id":2258415,"name":"Lukas Rosol"}],"regulators":["MR_INT"],"countryCode":"IN","discountAllowed":false,"timezone":"UTC","openDate":"2020-02-02T04:00:00.000Z","version":3145381965,"name":"Set 1 Winner","eventName":"Ebden v Rosol"},"rc":[{"batb":[[0,1.01,20]],"ltp":0.0,"tv":0.0,"id":4423910},{"batb":[[0,1.01,20]],"ltp":0.0,"tv":0.0,"id":2258415}]}]}
{"op":"mcm","clk":"994280373","pt":1580566030955,"mc":[{"id":"1.168215939","marketDefinition":{"bspMarket":false,"turnInPlayEnabled":true,"persistenceEnabled":true,"marketBaseRate":5.0,"eventId":"29681228","eventTypeId":"2","numberOfWinners":1,"bettingType":"ODDS","marketType":"SET_WINNER","marketTime":"2020-02-02T04:00:00.000Z","suspendTime":"2020-02-02T04:00:00.000Z","bspReconciled":false,"complete":true,"inPlay":false,"crossMatching":false,"runnersVoidable":false,"numberOfActiveRunners":2,"betDelay":0,"status":"OPEN","runners":[{"status":"ACTIVE","sortPriority":1,"id":4423910,"name":"Matthew Ebden"},{"status":"ACTIVE","sortPriority":2,"id":2258415,"name":"Lukas Rosol"}],"regulators":["MR_INT"],"countryCode":"IN","discountAllowed":false,"timezone":"UTC","openDate":"2020-02-02T04:00:00.000Z","version":3145381965,"name":"Set 1 Winner","eventName":"Ebden v Rosol"}}]}
{"op":"mcm","clk":"994280889","pt":1580566032994,"mc":[{"id":"1.168215939","marketDefinition":{"bspMarket":false,"turnInPlayEnabled":true,"persistenceEnabled":true,"marketBaseRate":5.0,"eventId":"29681228","eventTypeId":"2","numberOfWinners":1,"bettingType":"ODDS","marketType":"SET_WINNER","marketTime":"2020-02-02T04:00:00.000Z","suspendTime":"2020-02-02T04:00:00.000Z","bspReconciled":false,"complete":true,"inPlay":false,"crossMatching":false,"runnersVoidable":false,"numberOfActiveRunners":2,"betDelay":0,"status":"OPEN","runners":[{"status":"ACTIVE","sortPriority":1,"id":4423910,"name":"Matthew Ebden"},{"status":"ACTIVE","sortPriority":2,"id":2258415,"name":"Lukas Rosol"}],"regulators":["MR_INT"],"countryCode":"IN","discountAllowed":true,"timezone":"UTC","openDate":"2020-02-02T04:00:00.000Z","version":3145381965,"name":"Set 1 Winner","eventName":"Ebden v Rosol"}}]}
{"op":"mcm","clk":"994413113","pt":1580566512387,"mc":[{"id":"1.168215939","rc":[{"batb":[[0,1.01,10]],"ltp":0.0,"tv":0.0,"id":4423910},{"batb":[[0,1.01,10]],"ltp":0.0,"tv":0.0,"id":2258415}]}]}
{"op":"mcm","clk":"994665394","pt":1580567442352,"mc":[{"id":"1.168215939","marketDefinition":{"bspMarket":false,"turnInPlayEnabled":true,"persistenceEnabled":true,"marketBaseRate":5.0,"eventId":"29681228","eventTypeId":"2","numberOfWinners":1,"bettingType":"ODDS","marketType":"SET_WINNER","marketTime":"2020-02-02T09:30:00.000Z","suspendTime":"2020-02-02T09:30:00.000Z","bspReconciled":false,"complete":true,"inPlay":false,"crossMatching":false,"runnersVoidable":false,"numberOfActiveRunners":2,"betDelay":0,"status":"OPEN","runners":[{"status":"ACTIVE","sortPriority":1,"id":4423910,"name":"Matthew Ebden"},{"status":"ACTIVE","sortPriority":2,"id":2258415,"name":"Lukas Rosol"}],"regulators":["MR_INT"],"countryCode":"IN","discountAllowed":true,"timezone":"UTC","openDate":"2020-02-02T04:00:00.000Z","version":3145478875,"name":"Set 1 Winner","eventName":"Ebden v Rosol"}}]}
{"op":"mcm","clk":"994666152","pt":1580567445352,"mc":[{"id":"1.168215939","marketDefinition":{"bspMarket":false,"turnInPlayEnabled":true,"persistenceEnabled":true,"marketBaseRate":5.0,"eventId":"29681228","eventTypeId":"2","numberOfWinners":1,"bettingType":"ODDS","marketType":"SET_WINNER","marketTime":"2020-02-02T09:30:00.000Z","suspendTime":"2020-02-02T09:30:00.000Z","bspReconciled":false,"complete":true,"inPlay":false,"crossMatching":false,"runnersVoidable":false,"numberOfActiveRunners":2,"betDelay":0,"status":"OPEN","runners":[{"status":"ACTIVE","sortPriority":1,"id":4423910,"name":"Matthew Ebden"},{"status":"ACTIVE","sortPriority":2,"id":2258415,"name":"Lukas Rosol"}],"regulators":["MR_INT"],"countryCode":"IN","discountAllowed":true,"timezone":"UTC","openDate":"2020-02-02T09:30:00.000Z","version":3145478875,"name":"Set 1 Winner","eventName":"Ebden v Rosol"}}]}
{"op":"mcm","clk":"999039279","pt":1580591596136,"mc":[{"id":"1.168215939","rc":[{"batb":[[0,1.9,37.81],[1,1.01,10]],"ltp":0.0,"tv":0.0,"id":2258415}]}]}
{"op":"mcm","clk":"999432942","pt":1580595247900,"mc":[{"id":"1.168215939","rc":[{"batb":[[0,2,37.81]],"ltp":0.0,"tv":0.0,"id":2258415}]}]}
{"op":"mcm","clk":"999434459","pt":1580595265848,"mc":[{"id":"1.168215939","rc":[{"trd":[[2,4]],"batb":[[0,2,35.81]],"ltp":2.0,"tv":3.99,"id":2258415}],"tv":3.99}]}
{"op":"mcm","clk":"999434660","pt":1580595268216,"mc":[{"id":"1.168215939","rc":[{"trd":[[2,8]],"batb":[[0,2,33.81]],"ltp":2.0,"tv":7.99,"id":2258415}],"tv":7.99}]}
{"op":"mcm","clk":"999435027","pt":1580595273018,"mc":[{"id":"1.168215939","rc":[{"trd":[[2,12]],"batb":[[0,2,31.81]],"ltp":2.0,"tv":11.99,"id":2258415}],"tv":11.99}]}
{"op":"mcm","clk":"999437039","pt":1580595296241,"mc":[{"id":"1.168215939","rc":[{"batb":[[0,2,27.73]],"ltp":2.0,"tv":11.99,"id":2258415}]}]}
{"op":"mcm","clk":"999438179","pt":1580595308270,"mc":[{"id":"1.168215939","rc":[{"trd":[[2,16]],"batb":[[0,2,25.73]],"ltp":2.0,"tv":15.99,"id":2258415}],"tv":15.99}]}
{"op":"mcm","clk":"999578432","pt":1580597242584,"mc":[{"id":"1.168215939","rc":[{"batb":[[0,2,8.4]],"ltp":2.0,"tv":15.99,"id":2258415}]}]}
{"op":"mcm","clk":"999906417","pt":1580602463662,"mc":[{"id":"1.168215939","rc":[{"batb":[[0,1.01,12.53]],"ltp":0.0,"tv":0.0,"id":4423910},{"batb":[[1,1.01,12.53]],"ltp":2.0,"tv":15.99,"id":2258415}]}]}
{"op":"mcm","clk":"999906507","pt":1580602464808,"mc":[{"id":"1.168215939","rc":[{"batb":[[0,1.01,10.51]],"ltp":0.0,"tv":0.0,"id":4423910},{"batb":[[1,1.01,10.51]],"ltp":2.0,"tv":15.99,"id":2258415}]}]}
{"op":"mcm","clk":"999995787","pt":1580603997874,"mc":[{"id":"1.168215939","rc":[{"batb":[[0,1.01,13.04]],"ltp":0.0,"tv":0.0,"id":4423910},{"batb":[[1,1.01,13.04]],"ltp":2.0,"tv":15.99,"id":2258415}]}]}
{"op":"mcm","clk":"999995853","pt":1580603998855,"mc":[{"id":"1.168215939","rc":[{"batb":[[0,1.01,11.01]],"ltp":0.0,"tv":0.0,"id":4423910},{"batb":[[1,1.01,11.01]],"ltp":2.0,"tv":15.99,"id":2258415}]}]}
{"op":"mcm","clk":"1000104081","pt":1580607069924,"mc":[{"id":"1.168215939","rc":[{"batb":[[0,1.01,13.01]],"ltp":0.0,"tv":0.0,"id":4423910},{"batb":[[1,1.01,13.01]],"ltp":2.0,"tv":15.99,"id":2258415}]}]}
{"op":"mcm","clk":"1000104120","pt":1580607070643,"mc":[{"id":"1.168215939","rc":[{"batb":[[0,1.01,11.02]],"ltp":0.0,"tv":0.0,"id":4423910},{"batb":[[1,1.01,11.02]],"ltp":2.0,"tv":15.99,"id":2258415}]}]}
{"op":"mcm","clk":"1000104335","pt":1580607077093,"mc":[{"id":"1.168215939","marketDefinition":{"bspMarket":false,"turnInPlayEnabled":true,"persistenceEnabled":true,"marketBaseRate":5.0,"eventId":"29681228","eventTypeId":"2","numberOfWinners":1,"bettingType":"ODDS","marketType":"SET_WINNER","marketTime":"2020-02-02T09:30:00.000Z","suspendTime":"2020-02-02T09:30:00.000Z","bspReconciled":false,"complete":true,"inPlay":false,"crossMatching":true,"runnersVoidable":false,"numberOfActiveRunners":2,"betDelay":0,"status":"OPEN","runners":[{"status":"ACTIVE","sortPriority":1,"id":4423910,"name":"Matthew Ebden"},{"status":"ACTIVE","sortPriority":2,"id":2258415,"name":"Lukas Rosol"}],"regulators":["MR_INT"],"countryCode":"IN","discountAllowed":true,"timezone":"UTC","openDate":"2020-02-02T09:30:00.000Z","version":3146887647,"name":"Set 1 Winner","eventName":"Ebden v Rosol"}}]}
{"op":"mcm","clk":"1001298805","pt":1580632928623,"mc":[{"id":"1.168215939","rc":[{"batb":[[0,2.02,1.25],[1,2,8.4],[2,1.01,11.02]],"ltp":2.0,"tv":15.99,"id":2258415}]}]}
{"op":"mcm","clk":"1001372326","pt":1580634569181,"mc":[{"id":"1.168215939","rc":[{"batl":[[0,2.34,7.57]],"ltp":2.0,"tv":15.99,"id":2258415}]}]}
{"op":"mcm","clk":"1001375404","pt":1580634637947,"mc":[{"id":"1.168215939","rc":[{"batb":[[0,1.75,1.44],[1,1.01,11.02]],"ltp":0.0,"tv":0.0,"id":4423910}]}]}
{"op":"mcm","clk":"1001400377","pt":1580635108875,"mc":[{"id":"1.168215939","rc":[{"trd":[[2,17.5],[2.02,2.5]],"batb":[[0,2,7.65],[1,1.01,11.02],[2,1.01,0]],"ltp":2.0,"tv":19.99,"id":2258415}],"tv":19.99}]}
{"op":"mcm","clk":"1001400440","pt":1580635110067,"mc":[{"id":"1.168215939","rc":[{"trd":[[2,21.5]],"batb":[[0,2,5.65]],"ltp":2.0,"tv":23.99,"id":2258415}],"tv":23.99}]}
{"op":"mcm","clk":"1001416193","pt":1580635444714,"mc":[{"id":"1.168215939","rc":[{"trd":[[2,5.65]],"batb":[[0,2.02,21.88],[1,1.75,1.44],[2,1.01,11.02]],"ltp":2.0,"tv":5.65,"id":4423910},{"trd":[[2,27.15]],"batb":[[0,1.86,17.62]],"ltp":2.0,"tv":29.65,"id":2258415}],"tv":35.3}]}
{"op":"mcm","clk":"1001416570","pt":1580635452342,"mc":[{"id":"1.168215939","rc":[{"batb":[[0,2,27.7]],"ltp":2.0,"tv":5.65,"id":4423910},{"batb":[[0,1.88,17.55]],"ltp":2.0,"tv":29.65,"id":2258415}]}]}
{"op":"mcm","clk":"1001419417","pt":1580635509579,"mc":[{"id":"1.168215939","rc":[{"batb":[[0,2.02,1.25],[1,2,27.7]],"ltp":2.0,"tv":5.65,"id":4423910}]}]}
{"op":"mcm","clk":"1001420402","pt":1580635526779,"mc":[{"id":"1.168215939","rc":[{"batb":[[0,2.04,26.59],[1,2.02,1.25],[2,2,27.7]],"ltp":2.0,"tv":5.65,"id":4423910},{"batb":[[1,1.85,18.18],[2,1.01,11.02]],"ltp":2.0,"tv":29.65,"id":2258415}]}]}
{"op":"mcm","clk":"1001420468","pt":1580635527803,"mc":[{"id":"1.168215939","rc":[{"batb":[[2,1.01,11.02]],"ltp":2.0,"tv":5.65,"id":4423910},{"batb":[[0,1.85,18.18],[1,1.01,11.02],[2,1.01,0]],"ltp":2.0,"tv":29.65,"id":2258415}]}]}
{"op":"mcm","clk":"1001421099","pt":1580635539526,"mc":[{"id":"1.168215939","rc":[{"batb":[[0,2.06,1.23],[1,2.04,26.59]],"ltp":2.0,"tv":5.65,"id":4423910}]}]}
{"op":"mcm","clk":"1001423396","pt":1580635580949,"mc":[{"id":"1.168215939","rc":[{"batb":[[1,2.04,26.44]],"ltp":2.0,"tv":5.65,"id":4423910}]}]}
{"op":"mcm","clk":"1001425451","pt":1580635608319,"mc":[{"id":"1.168215939","marketDefinition":{"bspMarket":false,"turnInPlayEnabled":true,"persistenceEnabled":true,"marketBaseRate":5.0,"eventId":"29681228","eventTypeId":"2","numberOfWinners":1,"bettingType":"ODDS","marketType":"SET_WINNER","marketTime":"2020-02-02T09:23:00.000Z","suspendTime":"2020-02-02T09:23:00.000Z","bspReconciled":false,"complete":true,"inPlay":false,"crossMatching":true,"runnersVoidable":false,"numberOfActiveRunners":2,"betDelay":0,"status":"OPEN","runners":[{"status":"ACTIVE","sortPriority":1,"id":4423910,"name":"Matthew Ebden"},{"status":"ACTIVE","sortPriority":2,"id":2258415,"name":"Lukas Rosol"}],"regulators":["MR_INT"],"countryCode":"IN","discountAllowed":true,"timezone":"UTC","openDate":"2020-02-02T09:30:00.000Z","version":3148345275,"name":"Set 1 Winner","eventName":"Ebden v Rosol"}}]}
{"op":"mcm","clk":"1001425695","pt":1580635610399,"mc":[{"id":"1.168215939","marketDefinition":{"bspMarket":false,"turnInPlayEnabled":true,"persistenceEnabled":true,"marketBaseRate":5.0,"eventId":"29681228","eventTypeId":"2","numberOfWinners":1,"bettingType":"ODDS","marketType":"SET_WINNER","marketTime":"2020-02-02T09:23:00.000Z","suspendTime":"2020-02-02T09:23:00.000Z","bspReconciled":false,"complete":true,"inPlay":false,"crossMatching":true,"runnersVoidable":false,"numberOfActiveRunners":2,"betDelay":0,"status":"OPEN","runners":[{"status":"ACTIVE","sortPriority":1,"id":4423910,"name":"Matthew Ebden"},{"status":"ACTIVE","sortPriority":2,"id":2258415,"name":"Lukas Rosol"}],"regulators":["MR_INT"],"countryCode":"IN","discountAllowed":true,"timezone":"UTC","openDate":"2020-02-02T09:23:00.000Z","version":3148345275,"name":"Set 1 Winner","eventName":"Ebden v Rosol"}}]}
{"op":"mcm","clk":"1001440408","pt":1580635860950,"mc":[{"id":"1.168215939","rc":[{"batb":[[2,1.98,42.85]],"batl":[[0,2.2,34.45]],"ltp":2.0,"tv":5.65,"id":4423910},{"batb":[[0,1.85,66.91]],"batl":[[0,2.04,40.33],[1,2.34,7.57]],"ltp":2.0,"tv":29.65,"id":2258415}]}]}
{"op":"mcm","clk":"1001440453","pt":1580635861571,"mc":[{"id":"1.168215939","rc":[{"batb":[[0,1.85,18.18],[1,1.84,49.57],[2,1.01,11.02]],"batl":[[0,2.02,41.17]],"ltp":2.0,"tv":29.65,"id":2258415}]}]}
{"op":"mcm","clk":"1001444827","pt":1580635942931,"mc":[{"id":"1.168215939","rc":[{"batb":[[1,2.02,26.91]],"ltp":2.0,"tv":5.65,"id":4423910},{"batb":[[0,1.86,18.02]],"ltp":2.0,"tv":29.65,"id":2258415}]}]}
{"op":"mcm","clk":"1001447506","pt":1580636012809,"mc":[{"id":"1.168215939","rc":[{"batb":[[1,2.04,26.75],[2,2.02,26.91]],"ltp":2.0,"tv":5.65,"id":4423910}]}]}
{"op":"mcm","clk":"1001447515","pt":1580636013017,"mc":[{"id":"1.168215939","rc":[{"batb":[[2,1.98,42.85]],"ltp":2.0,"tv":5.65,"id":4423910}]}]}
{"op":"mcm","clk":"1001448586","pt":1580636043947,"mc":[{"id":"1.168215939","rc":[{"trd":[[2.04,26.75],[2.06,1.23]],"batb":[[0,1.98,42.85],[1,1.01,11.02],[2,1.98,0]],"ltp":2.04,"tv":33.63,"id":4423910},{"trd":[[1.95,1.29],[1.97,27.7],[2.02,84.84]],"batb":[[0,2.02,13.85],[1,1.86,18.02],[2,1.84,49.57]],"batl":[[0,2.34,7.57],[1,2.34,0]],"ltp":2.02,"tv":140.98,"id":2258415}],"tv":174.62}]}
{"op":"mcm","clk":"1001448622","pt":1580636044770,"mc":[{"id":"1.168215939","rc":[{"trd":[[1.99,14.06]],"batb":[[0,2.02,13.4],[1,1.97,42.85],[2,1.01,11.02]],"batl":[[0,2.14,36.13]],"ltp":1.99,"tv":47.69,"id":4423910},{"trd":[[2.02,98.7]],"batb":[[0,1.87,65.52],[1,1.01,11.02],[2,1.84,0]],"batl":[[0,2.06,39.49],[1,2.34,7.57]],"ltp":2.02,"tv":154.84,"id":2258415}],"tv":202.53}]}
{"op":"mcm","clk":"1001448914","pt":1580636054847,"mc":[{"id":"1.168215939","rc":[{"batb":[[0,2,27.85]],"ltp":1.99,"tv":47.69,"id":4423910},{"batb":[[0,1.91,17.39],[1,1.87,47.89],[2,1.01,11.02]],"ltp":2.02,"tv":154.84,"id":2258415}]}]}
{"op":"mcm","clk":"1001449615","pt":1580636074246,"mc":[{"id":"1.168215939","rc":[{"batb":[[1,1.01,11.02],[2,1.01,0]],"ltp":1.99,"tv":47.69,"id":4423910},{"batb":[[1,1.01,11.02],[2,1.01,0]],"batl":[[0,2.34,7.57],[1,2.34,0]],"ltp":2.02,"tv":154.84,"id":2258415}]}]}
{"op":"mcm","clk":"1001451529","pt":1580636130732,"mc":[{"id":"1.168215939","rc":[{"batb":[[0,1.97,42.85]],"batl":[[0,2.14,36.13]],"ltp":1.99,"tv":47.69,"id":4423910},{"batb":[[0,1.89,47.05]],"batl":[[0,2.06,39.49],[1,2.34,7.57]],"ltp":2.02,"tv":154.84,"id":2258415}]}]}
{"op":"mcm","clk":"1001451552","pt":1580636131258,"mc":[{"id":"1.168215939","marketDefinition":{"bspMarket":false,"turnInPlayEnabled":true,"persistenceEnabled":true,"marketBaseRate":5.0,"eventId":"29681228","eventTypeId":"2","numberOfWinners":1,"bettingType":"ODDS","marketType":"SET_WINNER","marketTime":"2020-02-02T09:23:00.000Z","suspendTime":"2020-02-02T09:23:00.000Z","bspReconciled":false,"complete":true,"inPlay":true,"crossMatching":true,"runnersVoidable":false,"numberOfActiveRunners":2,"betDelay":3,"status":"OPEN","runners":[{"status":"ACTIVE","sortPriority":1,"id":4423910,"name":"Matthew Ebden"},{"status":"ACTIVE","sortPriority":2,"id":2258415,"name":"Lukas Rosol"}],"regulators":["MR_INT"],"countryCode":"IN","discountAllowed":true,"timezone":"UTC","openDate":"2020-02-02T09:23:00.000Z","version":3148350800,"name":"Set 1 Winner","eventName":"Ebden v Rosol"},"rc":[{"batb":[[0,1.01,10.52],[1,1.01,0]],"ltp":1.99,"tv":47.69,"id":4423910},{"batb":[[0,1.01,10.52],[1,1.01,0]],"ltp":2.02,"tv":154.84,"id":2258415}]}]}
{"op":"mcm","clk":"1001451685","pt":1580636134723,"mc":[{"id":"1.168215939","rc":[{"batb":[[0,1.97,42.85],[1,1.01,10.52]],"batl":[[0,2.14,36.13]],"ltp":1.99,"tv":47.69,"id":4423910},{"batb":[[0,1.89,47.05],[1,1.01,10.52]],"batl":[[0,2.06,39.49]],"ltp":2.02,"tv":154.84,"id":2258415}]}]}
{"op":"mcm","clk":"1001451703","pt":1580636135132,"mc":[{"id":"1.168215939","rc":[{"batb":[[0,1.01,10.52],[1,1.01,0]],"ltp":1.99,"tv":47.69,"id":4423910},{"batb":[[0,1.01,10.52],[1,1.01,0]],"ltp":2.02,"tv":154.84,"id":2258415}]}]}
{"op":"mcm","clk":"1001451997","pt":1580636142644,"mc":[{"id":"1.168215939","rc":[{"batb":[[0,2.24,19.99],[1,2.06,25.81],[2,1.01,10.52]],"ltp":1.99,"tv":47.69,"id":4423910},{"batb":[[0,1.73,23.76],[1,1.54,36.27],[2,1.01,10.52]],"ltp":2.02,"tv":154.84,"id":2258415}]}]}
{"op":"mcm","clk":"1001452037","pt":1580636143656,"mc":[{"id":"1.168215939","rc":[{"batb":[[1,2.14,36.13],[2,2.06,25.81]],"ltp":1.99,"tv":47.69,"id":4423910},{"batl":[[0,1.87,42.01]],"ltp":2.02,"tv":154.84,"id":2258415}]}]}
{"op":"mcm","clk":"1001452099","pt":1580636144938,"mc":[{"id":"1.168215939","rc":[{"batl":[[0,2.36,30.25]],"ltp":1.99,"tv":47.69,"id":4423910},{"batb":[[0,1.73,80.9],[1,1.71,197.21],[2,1.69,219.11]],"batl":[[0,1.78,128.23],[1,1.8,179.06],[2,1.87,42.01]],"ltp":2.02,"tv":154.84,"id":2258415}]}]}
{"op":"mcm","clk":"1001452347","pt":1580636152336,"mc":[{"id":"1.168215939","rc":[{"batb":[[0,2.06,25.81],[1,1.01,10.52],[2,2.06,0]],"ltp":1.99,"tv":47.69,"id":4423910},{"batb":[[0,1.54,36.27],[1,1.01,10.52],[2,1.69,0]],"ltp":2.02,"tv":154.84,"id":2258415}]}]}
{"op":"mcm","clk":"1001452559","pt":1580636157250,"mc":[{"id":"1.168215939","rc":[{"batb":[[0,1.67,192.63],[1,1.66,117.41],[2,1.54,36.27]],"batl":[[0,1.74,179.12],[1,1.76,192.39]],"ltp":2.02,"tv":154.84,"id":2258415}]}]}
{"op":"mcm","clk":"1001452631","pt":1580636158567,"mc":[{"id":"1.168215939","rc":[{"batb":[[0,1.54,36.27],[1,1.01,10.52],[2,1.54,0]],"ltp":2.02,"tv":154.84,"id":2258415}]}]}
{"op":"mcm","clk":"1001452770","pt":1580636161457,"mc":[{"id":"1.168215939","rc":[{"batb":[[1,1.52,288.16],[2,1.51,168.37]],"batl":[[0,1.92,134.24],[1,1.94,141.75]],"ltp":2.02,"tv":154.84,"id":2258415}]}]}
{"op":"mcm","clk":"1001453566","pt":1580636178711,"mc":[{"id":"1.168215939","rc":[{"batb":[[1,1.01,10.52],[2,1.51,0]],"ltp":2.02,"tv":154.84,"id":2258415}]}]}
{"op":"mcm","clk":"1001453733","pt":1580636181608,"mc":[{"id":"1.168215939","rc":[{"batb":[[0,1.84,145.55],[1,1.82,170.56],[2,1.54,36.27]],"ltp":2.02,"tv":154.84,"id":2258415}]}]}
{"op":"mcm","clk":"1001453778","pt":1580636182794,"mc":[{"id":"1.168215939","rc":[{"batb":[[1,1.92,16.05],[2,1.01,10.52]],"ltp":1.99,"tv":47.69,"id":4423910},{"batb":[[0,1.86,18.73],[1,1.84,145.55],[2,1.82,170.56]],"ltp":2.02,"tv":154.84,"id":2258415}]}]}
{"op":"mcm","clk":"1001453802","pt":1580636183202,"mc":[{"id":"1.168215939","rc":[{"batb":[[1,2.02,41.17],[2,1.92,16.05]],"batl":[[0,2.2,34.45]],"ltp":1.99,"tv":47.69,"id":4423910},{"batb":[[2,1.83,50.41]],"batl":[[2,1.98,42.01]],"ltp":2.02,"tv":154.84,"id":2258415}]}]}
{"op":"mcm","clk":"1001454085","pt":1580636189305,"mc":[{"id":"1.168215939","rc":[{"batb":[[0,2.02,41.17],[1,1.92,16.05],[2,1.01,10.52]],"ltp":1.99,"tv":47.69,"id":4423910},{"batb":[[0,1.83,50.41],[1,1.65,27.62],[2,1.01,10.52]],"batl":[[0,1.98,42.01],[1,1.94,0],[2,1.98,0]],"ltp":2.02,"tv":154.84,"id":2258415}]}]}
{"op":"mcm","clk":"1001454121","pt":1580636190231,"mc":[{"id":"1.168215939","rc":[{"batb":[[0,1.92,16.05],[1,1.01,10.52],[2,1.01,0]],"ltp":1.99,"tv":47.69,"id":4423910},{"batb":[[0,1.65,27.62],[1,1.01,10.52],[2,1.01,0]],"ltp":2.02,"tv":154.84,"id":2258415}]}]}
{"op":"mcm","clk":"1001454201","pt":1580636192235,"mc":[{"id":"1.168215939","rc":[{"batb":[[1,1.64,206.37],[2,1.63,125.42]],"batl":[[0,2.06,111.05],[1,2.08,115.35]],"ltp":2.02,"tv":154.84,"id":2258415}]}]}
{"op":"mcm","clk":"1001454302","pt":1580636194634,"mc":[{"id":"1.168215939","rc":[{"batb":[[1,1.01,10.52],[2,1.63,0]],"ltp":2.02,"tv":154.84,"id":2258415}]}]}
{"op":"mcm","clk":"1001454382","pt":1580636197615,"mc":[{"id":"1.168215939","rc":[{"batb":[[0,1.8,121.31],[1,1.78,183.42],[2,1.65,27.62]],"batl":[[0,1.87,115.61],[1,1.89,153.56]],"ltp":2.02,"tv":154.84,"id":2258415}]}]}
{"op":"mcm","clk":"1001454407","pt":1580636198546,"mc":[{"id":"1.168215939","rc":[{"batb":[[0,1.65,27.62],[1,1.01,10.52],[2,1.65,0]],"ltp":2.02,"tv":154.84,"id":2258415}]}]}
{"op":"mcm","clk":"1001454531","pt":1580636201657,"mc":[{"id":"1.168215939","rc":[{"batb":[[1,1.64,206.37],[2,1.63,125.42]],"ltp":2.02,"tv":154.84,"id":2258415}]}]}
{"op":"mcm","clk":"1001454605","pt":1580636203927,"mc":[{"id":"1.168215939","rc":[{"batb":[[0,2.38,16.84],[1,2.12,23.76],[2,1.92,16.05]],"ltp":1.99,"tv":47.69,"id":4423910},{"batl":[[0,1.71,205.53],[1,1.73,203.48]],"ltp":2.02,"tv":154.84,"id":2258415}]}]}
{"op":"mcm","clk":"1001454619","pt":1580636204341,"mc":[{"id":"1.168215939","rc":[{"batb":[[2,2.1,483.04]],"ltp":1.99,"tv":47.69,"id":4423910}]}]}
{"op":"mcm","clk":"1001454662","pt":1580636205319,"mc":[{"id":"1.168215939","rc":[{"batb":[[1,2.28,32.77],[2,2.12,23.76]],"batl":[[0,2.54,26.89]],"ltp":1.99,"tv":47.69,"id":4423910},{"batb":[[0,1.65,91.47]],"batl":[[2,1.78,42.01]],"ltp":2.02,"tv":154.84,"id":2258415}]}]}
{"op":"mcm","clk":"1001455465","pt":1580636223586,"mc":[{"id":"1.168215939","rc":[{"batb":[[1,1.44,46.59],[2,1.01,10.51]],"batl":[[0,1.78,42.01],[1,1.73,0],[2,1.78,0]],"ltp":2.02,"tv":154.84,"id":2258415}]}]}
{"op":"mcm","clk":"1001455510","pt":1580636224262,"mc":[{"id":"1.168215939","rc":[{"batb":[[1,2.12,23.76],[2,1.01,10.52]],"ltp":1.99,"tv":47.69,"id":4423910},{"batb":[[0,1.65,27.62]],"ltp":2.02,"tv":154.84,"id":2258415}]}]}
{"op":"mcm","clk":"1001455547","pt":1580636225141,"mc":[{"id":"1.168215939","rc":[{"batb":[[0,1.01,10.52],[1,2.12,0],[2,1.01,0]],"ltp":1.99,"tv":47.69,"id":4423910},{"batb":[[0,1.01,10.52],[1,1.44,0],[2,1.01,0]],"ltp":2.02,"tv":154.84,"id":2258415}]}]}
{"op":"mcm","clk":"1001458081","pt":1580636281948,"mc":[{"id":"1.168215939","rc":[{"batb":[[0,2.92,21.85],[1,1.67,200.75],[2,1.01,10.52]],"batl":[[0,3.35,17.64]],"ltp":1.99,"tv":47.69,"id":4423910},{"trd":[[1.48,0.02]],"batb":[[0,1.42,316.97],[1,1.01,10.51]],"batl":[[0,1.47,188.37],[1,1.48,178.57],[2,1.52,42.01]],"ltp":1.48,"tv":154.86,"id":2258415}],"tv":202.55}]}
{"op":"mcm","clk":"1001458098","pt":1580636282318,"mc":[{"id":"1.168215939","rc":[{"batb":[[1,1.01,10.52],[2,1.01,0]],"ltp":1.99,"tv":47.69,"id":4423910}]}]}
{"op":"mcm","clk":"1001458135","pt":1580636283041,"mc":[{"id":"1.168215939","rc":[{"batb":[[0,1.42,99.98]],"batl":[[0,1.52,42.01],[1,1.48,0],[2,1.52,0]],"ltp":1.48,"tv":154.86,"id":2258415}]}]}
{"op":"mcm","clk":"1001458206","pt":1580636284747,"mc":[{"id":"1.168215939","rc":[{"batb":[[0,1.01,10.52],[1,1.01,0]],"ltp":1.99,"tv":47.69,"id":4423910},{"batb":[[0,1.01,10.51],[1,1.01,0]],"ltp":1.48,"tv":154.86,"id":2258415}]}]}
{"op":"mcm","clk":"1001458239","pt":1580636285942,"mc":[{"id":"1.168215939","rc":[{"batb":[[0,1.39,191.74],[1,1.38,247.82],[2,1.01,10.51]],"batl":[[0,1.43,240.75],[1,1.44,199.72]],"ltp":1.48,"tv":154.86,"id":2258415}]}]}
{"op":"mcm","clk":"1001458402","pt":1580636290437,"mc":[{"id":"1.168215939","rc":[{"batb":[[0,1.39,141.22]],"ltp":1.48,"tv":154.86,"id":2258415}]}]}
{"op":"mcm","clk":"1001458545","pt":1580636293538,"mc":[{"id":"1.168215939","rc":[{"batb":[[0,1.01,10.51],[1,1.38,0],[2,1.01,0]],"ltp":1.48,"tv":154.86,"id":2258415}]}]}
{"op":"mcm","clk":"1001458643","pt":1580636295864,"mc":[{"id":"1.168215939","rc":[{"batb":[[0,1.25,521.73],[1,1.24,448.5],[2,1.01,10.51]],"batl":[[0,1.6,188.44],[1,1.61,130.06]],"ltp":1.48,"tv":154.86,"id":2258415}]}]}
{"op":"mcm","clk":"1001459222","pt":1580636308776,"mc":[{"id":"1.168215939","rc":[{"batb":[[0,1.01,10.51],[1,1.24,0],[2,1.01,0]],"ltp":1.48,"tv":154.86,"id":2258415}]}]}
{"op":"mcm","clk":"1001471064","pt":1580636550658,"mc":[{"id":"1.168215939","rc":[{"batb":[[0,1.19,299.02],[1,1.18,621.68],[2,1.01,10.51]],"batl":[[0,1.34,187.73],[1,1.35,268.79]],"ltp":1.48,"tv":154.86,"id":2258415}]}]}
{"op":"mcm","clk":"1001471119","pt":1580636551793,"mc":[{"id":"1.168215939","rc":[{"batl":[[0,1.34,157.51]],"ltp":1.48,"tv":154.86,"id":2258415}]}]}
{"op":"mcm","clk":"1001471231","pt":1580636554956,"mc":[{"id":"1.168215939","rc":[{"batb":[[0,1.01,10.51],[1,1.18,0],[2,1.01,0]],"ltp":1.48,"tv":154.86,"id":2258415}]}]}
{"op":"mcm","clk":"1001471328","pt":1580636556868,"mc":[{"id":"1.168215939","rc":[{"batl":[[0,1.35,268.79],[1,1.35,0]],"ltp":1.48,"tv":154.86,"id":2258415}]}]}
{"op":"mcm","clk":"1001471379","pt":1580636557898,"mc":[{"id":"1.168215939","rc":[{"trd":[[4.3,12.6]],"batl":[[0,5,10.08]],"ltp":4.3,"tv":60.3,"id":4423910},{"trd":[[1.31,125.39]],"batb":[[0,1.31,176.1],[1,1.3,336.26],[2,1.24,168.04]],"ltp":1.31,"tv":280.25,"id":2258415}],"tv":340.55}]}
{"op":"mcm","clk":"1001471392","pt":1580636558104,"mc":[{"id":"1.168215939","rc":[{"batb":[[2,1.01,10.51]],"ltp":1.31,"tv":280.25,"id":2258415}]}]}
{"op":"mcm","clk":"1001471459","pt":1580636559504,"mc":[{"id":"1.168215939","rc":[{"batl":[[0,1.35,318.82],[1,1.36,255.82]],"ltp":1.31,"tv":280.25,"id":2258415}]}]}
{"op":"mcm","clk":"1001471518","pt":1580636560687,"mc":[{"id":"1.168215939","rc":[{"batb":[[0,1.31,316.64]],"ltp":1.31,"tv":280.25,"id":2258415}]}]}
{"op":"mcm","clk":"1001471591","pt":1580636561777,"mc":[{"id":"1.168215939","rc":[{"trd":[[1.31,209.41]],"batb":[[0,1.31,327.48],[2,1.26,161.32]],"batl":[[0,1.32,42.01],[1,1.35,318.82],[2,1.36,255.82]],"ltp":1.31,"tv":364.27,"id":2258415}],"tv":424.57}]}
{"op":"mcm","clk":"1001471719","pt":1580636564618,"mc":[{"id":"1.168215939","rc":[{"batb":[[0,4.1,13.44],[1,1.01,10.52]],"batl":[[0,4.8,10.92]],"ltp":4.3,"tv":60.3,"id":4423910},{"trd":[[1.31,293.43]],"batb":[[0,1.31,285.47]],"ltp":1.31,"tv":448.29,"id":2258415}],"tv":508.59}]}
{"op":"mcm","clk":"1001471882","pt":1580636568021,"mc":[{"id":"1.168215939","rc":[{"batb":[[0,1.31,338.72]],"batl":[[1,1.35,348.73]],"ltp":1.31,"tv":448.29,"id":2258415}]}]}
{"op":"mcm","clk":"1001472028","pt":1580636571229,"mc":[{"id":"1.168215939","rc":[{"batb":[[0,1.31,302.58]],"ltp":1.31,"tv":448.29,"id":2258415}]}]}
{"op":"mcm","clk":"1001472103","pt":1580636572685,"mc":[{"id":"1.168215939","rc":[{"batb":[[0,1.31,285.47]],"batl":[[1,1.35,268.93],[2,1.36,0]],"ltp":1.31,"tv":448.29,"id":2258415}]}]}
{"op":"mcm","clk":"1001472214","pt":1580636574602,"mc":[{"id":"1.168215939","rc":[{"batb":[[0,1.01,10.52],[1,1.01,0]],"ltp":4.3,"tv":60.3,"id":4423910},{"batb":[[0,1.01,10.51],[1,1.3,0],[2,1.26,0]],"ltp":1.31,"tv":448.29,"id":2258415}]}]}
{"op":"mcm","clk":"1001472367","pt":1580636577186,"mc":[{"id":"1.168215939","rc":[{"batb":[[0,1.23,545],[1,1.22,497.11],[2,1.01,10.51]],"batl":[[0,1.53,234.27],[1,1.54,153.7]],"ltp":1.31,"tv":448.29,"id":2258415}]}]}
{"op":"mcm","clk":"1001472528","pt":1580636580595,"mc":[{"id":"1.168215939","rc":[{"batb":[[0,1.01,10.51],[1,1.22,0],[2,1.01,0]],"ltp":1.31,"tv":448.29,"id":2258415}]}]}
{"op":"mcm","clk":"1001472763","pt":1580636583600,"mc":[{"id":"1.168215939","rc":[{"batl":[[0,6,8.4]],"ltp":4.3,"tv":60.3,"id":4423910},{"batb":[[0,1.23,545],[1,1.22,497.11],[2,1.2,168.04]],"batl":[[0,1.26,220.02],[1,1.27,367.04]],"ltp":1.31,"tv":448.29,"id":2258415}]}]}
{"op":"mcm","clk":"1001472795","pt":1580636584006,"mc":[{"id":"1.168215939","rc":[{"batb":[[0,5,10.08],[1,1.01,10.52]],"ltp":4.3,"tv":60.3,"id":4423910},{"batl":[[0,1.25,42.01],[1,1.26,220.02],[2,1.27,367.04]],"ltp":1.31,"tv":448.29,"id":2258415}]}]}
{"op":"mcm","clk":"1001472877","pt":1580636585138,"mc":[{"id":"1.168215939","rc":[{"batb":[[1,2.8,375.33],[2,1.01,10.52]],"ltp":4.3,"tv":60.3,"id":4423910}]}]}
{"op":"mcm","clk":"1001473060","pt":1580636588808,"mc":[{"id":"1.168215939","rc":[{"trd":[[1.23,373.04]],"batb":[[0,1.23,358.48]],"ltp":1.23,"tv":821.33,"id":2258415}],"tv":881.63}]}
{"op":"mcm","clk":"1001473248","pt":1580636592637,"mc":[{"id":"1.168215939","rc":[{"batb":[[0,1.23,476.7]],"batl":[[1,1.26,286.75]],"ltp":1.23,"tv":821.33,"id":2258415}]}]}
{"op":"mcm","clk":"1001473924","pt":1580636606841,"mc":[{"id":"1.168215939","rc":[{"batb":[[0,1.2,168.04],[1,1.14,627.92],[2,1.01,10.51]],"batl":[[1,1.26,0],[2,1.27,0]],"ltp":1.23,"tv":821.33,"id":2258415}]}]}
{"op":"mcm","clk":"1001474012","pt":1580636608644,"mc":[{"id":"1.168215939","rc":[{"batb":[[0,2.8,375.33],[1,1.01,10.52],[2,1.01,0]],"ltp":4.3,"tv":60.3,"id":4423910},{"batb":[[0,1.14,627.92],[1,1.01,10.51],[2,1.01,0]],"ltp":1.23,"tv":821.33,"id":2258415}]}]}
{"op":"mcm","clk":"1001474064","pt":1580636609934,"mc":[{"id":"1.168215939","rc":[{"batb":[[0,1.19,563.92],[1,1.18,517.49],[2,1.14,627.92]],"batl":[[0,1.35,219.69],[1,1.36,259.7]],"ltp":1.23,"tv":821.33,"id":2258415}]}]}
{"op":"mcm","clk":"1001474213","pt":1580636613583,"mc":[{"id":"1.168215939","rc":[{"batb":[[0,1.01,10.52],[1,1.01,0]],"ltp":4.3,"tv":60.3,"id":4423910},{"batb":[[2,1.01,10.51]],"ltp":1.23,"tv":821.33,"id":2258415}]}]}
{"op":"mcm","clk":"1001474259","pt":1580636614666,"mc":[{"id":"1.168215939","rc":[{"batl":[[0,1.22,475.77],[1,1.23,437.81]],"ltp":1.23,"tv":821.33,"id":2258415}]}]}
{"op":"mcm","clk":"1001474300","pt":1580636615643,"mc":[{"id":"1.168215939","rc":[{"batb":[[0,5.7,8.4],[1,1.01,10.52]],"batl":[[0,7,6.72]],"ltp":4.3,"tv":60.3,"id":4423910},{"batb":[[2,1.17,168.04]],"batl":[[0,1.21,42.01],[1,1.22,475.77],[2,1.23,437.81]],"ltp":1.23,"tv":821.33,"id":2258415}]}]}
{"op":"mcm","clk":"1001474400","pt":1580636617757,"mc":[{"id":"1.168215939","rc":[{"batb":[[1,3,380.84],[2,1.01,10.52]],"ltp":4.3,"tv":60.3,"id":4423910},{"batb":[[2,1.11,684.32]],"ltp":1.23,"tv":821.33,"id":2258415}]}]}
{"op":"mcm","clk":"1001475422","pt":1580636640787,"mc":[{"id":"1.168215939","rc":[{"batb":[[0,3,380.84],[1,1.01,10.52],[2,1.01,0]],"ltp":4.3,"tv":60.3,"id":4423910},{"batb":[[0,1.11,684.32],[1,1.01,10.51],[2,1.11,0]],"ltp":1.23,"tv":821.33,"id":2258415}]}]}
{"op":"mcm","clk":"1001475747","pt":1580636647579,"mc":[{"id":"1.168215939","rc":[{"batb":[[0,1.18,729.82],[1,1.17,357.16],[2,1.11,684.32]],"batl":[[0,1.21,414.12],[1,1.22,463.25]],"ltp":1.23,"tv":821.33,"id":2258415}]}]}
{"op":"mcm","clk":"1001475918","pt":1580636651591,"mc":[{"id":"1.168215939","rc":[{"batb":[[0,1.11,684.32],[1,1.01,10.51],[2,1.11,0]],"ltp":1.23,"tv":821.33,"id":2258415}]}]}
{"op":"mcm","clk":"1001476130","pt":1580636654946,"mc":[{"id":"1.168215939","rc":[{"batb":[[0,1.15,904.65],[1,1.14,209.4],[2,1.11,684.32]],"batl":[[0,1.24,239.52],[1,1.25,402.87]],"ltp":1.23,"tv":821.33,"id":2258415}]}]}
{"op":"mcm","clk":"1001477254","pt":1580636673676,"mc":[{"id":"1.168215939","rc":[{"batb":[[0,1.11,684.32],[1,1.01,10.51],[2,1.11,0]],"ltp":1.23,"tv":821.33,"id":2258415}]}]}
{"op":"mcm","clk":"1001477284","pt":1580636674350,"mc":[{"id":"1.168215939","rc":[{"batb":[[0,1.01,10.52],[1,1.01,0]],"ltp":4.3,"tv":60.3,"id":4423910},{"batb":[[0,1.01,10.51],[1,1.01,0]],"ltp":1.23,"tv":821.33,"id":2258415}]}]}
{"op":"mcm","clk":"1001482824","pt":1580636774681,"mc":[{"id":"1.168215939","rc":[{"batl":[[0,1.4,186.52]],"ltp":1.23,"tv":821.33,"id":2258415}]}]}
{"op":"mcm","clk":"1001491565","pt":1580636940936,"mc":[{"id":"1.168215939","rc":[{"batb":[[0,1.2,699.25],[1,1.19,369.72],[2,1.01,10.51]],"batl":[[0,1.42,270.66],[1,1.43,205.79]],"ltp":1.23,"tv":821.33,"id":2258415}]}]}
{"op":"mcm","clk":"1001491608","pt":1580636941610,"mc":[{"id":"1.168215939","rc":[{"batb":[[0,1.01,10.51],[1,1.19,0],[2,1.01,0]],"ltp":1.23,"tv":821.33,"id":2258415}]}]}
{"op":"mcm","clk":"1001491834","pt":1580636944919,"mc":[{"id":"1.168215939","rc":[{"batb":[[0,1.28,363.4],[1,1.27,384.87],[2,1.01,10.51]],"batl":[[0,1.31,161.56],[1,1.32,300.19]],"ltp":1.23,"tv":821.33,"id":2258415}]}]}
{"op":"mcm","clk":"1001491848","pt":1580636945129,"mc":[{"id":"1.168215939","rc":[{"batb":[[0,1.01,10.51],[1,1.27,0],[2,1.01,0]],"ltp":1.23,"tv":821.33,"id":2258415}]}]}
{"op":"mcm","clk":"1001492136","pt":1580636949112,"mc":[{"id":"1.168215939","rc":[{"batb":[[0,1.2,669.22],[1,1.19,400],[2,1.01,10.51]],"batl":[[0,1.42,295.98],[1,1.43,205.85]],"ltp":1.23,"tv":821.33,"id":2258415}]}]}
{"op":"mcm","clk":"1001493111","pt":1580636962848,"mc":[{"id":"1.168215939","rc":[{"batb":[[0,1.2,594.5]],"batl":[[0,1.23,307.16],[1,1.24,421.86]],"ltp":1.23,"tv":821.33,"id":2258415}]}]}
{"op":"mcm","clk":"1001493211","pt":1580636963948,"mc":[{"id":"1.168215939","rc":[{"batl":[[0,6.6,6.72]],"ltp":4.3,"tv":60.3,"id":4423910},{"batb":[[2,1.18,168.04]],"ltp":1.23,"tv":821.33,"id":2258415}]}]}
{"op":"mcm","clk":"1001493330","pt":1580636965960,"mc":[{"id":"1.168215939","rc":[{"batb":[[0,3,380.84],[1,1.01,10.52]],"ltp":4.3,"tv":60.3,"id":4423910},{"batb":[[1,1.19,475.35]],"batl":[[0,1.23,380.07]],"ltp":1.23,"tv":821.33,"id":2258415}]}]}
{"op":"mcm","clk":"1001493538","pt":1580636968964,"mc":[{"id":"1.168215939","rc":[{"batb":[[0,5.4,9.24],[1,3,380.84],[2,1.01,10.52]],"ltp":4.3,"tv":60.3,"id":4423910},{"batl":[[0,1.22,42.01],[1,1.23,380.07],[2,1.24,421.86]],"ltp":1.23,"tv":821.33,"id":2258415}]}]}
{"op":"mcm","clk":"1001494058","pt":1580636977955,"mc":[{"id":"1.168215939","rc":[{"batb":[[0,1.18,168.04],[1,1.11,684.32],[2,1.01,10.51]],"batl":[[1,1.23,0],[2,1.24,0]],"ltp":1.23,"tv":821.33,"id":2258415}]}]}
{"op":"mcm","clk":"1001494104","pt":1580636978987,"mc":[{"id":"1.168215939","rc":[{"batb":[[0,3,380.84],[1,1.01,10.52],[2,1.01,0]],"ltp":4.3,"tv":60.3,"id":4423910},{"batb":[[0,1.11,684.32],[1,1.01,10.51],[2,1.01,0]],"ltp":1.23,"tv":821.33,"id":2258415}]}]}
{"op":"mcm","clk":"1001494209","pt":1580636980788,"mc":[{"id":"1.168215939","rc":[{"batb":[[0,1.17,316.8],[1,1.16,718.81],[2,1.11,684.32]],"batl":[[0,1.31,273.41],[1,1.32,300.34]],"ltp":1.23,"tv":821.33,"id":2258415}]}]}
{"op":"mcm","clk":"1001494226","pt":1580636980990,"mc":[{"id":"1.168215939","rc":[{"batb":[[0,1.11,684.32],[1,1.01,10.51],[2,1.11,0]],"ltp":1.23,"tv":821.33,"id":2258415}]}]}
{"op":"mcm","clk":"1001494319","pt":1580636982389,"mc":[{"id":"1.168215939","rc":[{"batb":[[0,1.01,10.51],[1,1.01,0]],"ltp":1.23,"tv":821.33,"id":2258415}]}]}
{"op":"mcm","clk":"1001494381","pt":1580636983273,"mc":[{"id":"1.168215939","rc":[{"batb":[[0,1.22,249.07],[1,1.21,521.31],[2,1.01,10.51]],"batl":[[0,1.25,557.86],[1,1.26,379.79]],"ltp":1.23,"tv":821.33,"id":2258415}]}]}
{"op":"mcm","clk":"1001494598","pt":1580636986595,"mc":[{"id":"1.168215939","rc":[{"batb":[[0,1.13,629.97],[1,1.01,10.51],[2,1.01,0]],"ltp":1.23,"tv":821.33,"id":2258415}]}]}
{"op":"mcm","clk":"1001494766","pt":1580636989490,"mc":[{"id":"1.168215939","rc":[{"batb":[[0,1.17,316.8],[1,1.16,718.81],[2,1.13,629.97]],"batl":[[0,1.31,273.41],[1,1.32,300.34]],"ltp":1.23,"tv":821.33,"id":2258415}]}]}
{"op":"mcm","clk":"1001494864","pt":1580636991465,"mc":[{"id":"1.168215939","rc":[{"batb":[[2,1.01,10.51]],"ltp":1.23,"tv":821.33,"id":2258415}]}]}
{"op":"mcm","clk":"1001495029","pt":1580636993904,"mc":[{"id":"1.168215939","rc":[{"batb":[[0,6.2,7.56],[1,3,380.84],[2,1.01,10.52]],"batl":[[0,7.6,5.88]],"ltp":4.3,"tv":60.3,"id":4423910},{"batb":[[2,1.15,168.04]],"batl":[[0,1.19,402.93],[1,1.2,523.42]],"ltp":1.23,"tv":821.33,"id":2258415}]}]}
{"op":"mcm","clk":"1001495792","pt":1580637004319,"mc":[{"id":"1.168215939","rc":[{"batb":[[0,1.15,168.04],[1,1.09,779.05],[2,1.01,10.51]],"batl":[[0,1.19,42.01],[1,1.2,0]],"ltp":1.23,"tv":821.33,"id":2258415}]}]}
{"op":"mcm","clk":"1001495856","pt":1580637005454,"mc":[{"id":"1.168215939","rc":[{"batb":[[0,3,380.84],[1,1.01,10.52],[2,1.01,0]],"ltp":4.3,"tv":60.3,"id":4423910},{"batb":[[0,1.09,779.05],[1,1.01,10.51],[2,1.01,0]],"ltp":1.23,"tv":821.33,"id":2258415}]}]}
{"op":"mcm","clk":"1001495975","pt":1580637007313,"mc":[{"id":"1.168215939","rc":[{"batb":[[0,1.15,633.73],[1,1.14,482.7],[2,1.09,779.05]],"batl":[[0,1.23,487.32],[1,1.24,419.5]],"ltp":1.23,"tv":821.33,"id":2258415}]}]}
{"op":"mcm","clk":"1001496091","pt":1580637009530,"mc":[{"id":"1.168215939","rc":[{"batl":[[0,1.17,3.03],[1,1.23,487.32],[2,1.24,419.5]],"ltp":1.23,"tv":821.33,"id":2258415}]}]}
{"op":"mcm","clk":"1001496411","pt":1580637014646,"mc":[{"id":"1.168215939","rc":[{"trd":[[1.15,278.94]],"batb":[[0,1.15,494.26]],"batl":[[1,1.23,0],[2,1.24,0]],"ltp":1.15,"tv":1100.27,"id":2258415}],"tv":1160.57}]}
{"op":"mcm","clk":"1001496468","pt":1580637015636,"mc":[{"id":"1.168215939","rc":[{"batb":[[2,1.01,10.51]],"ltp":1.15,"tv":1100.27,"id":2258415}]}]}
{"op":"mcm","clk":"1001496629","pt":1580637017958,"mc":[{"id":"1.168215939","rc":[{"batb":[[0,6.8,6.72],[1,3,380.84],[2,1.01,10.52]],"batl":[[0,8.4,5.04]],"ltp":4.3,"tv":60.3,"id":4423910},{"batb":[[0,1.15,582.65],[1,1.14,534.22]],"batl":[[0,1.17,288.33],[1,1.18,595.91]],"ltp":1.15,"tv":1100.27,"id":2258415}]}]}
{"op":"mcm","clk":"1001496749","pt":1580637019835,"mc":[{"id":"1.168215939","rc":[{"batb":[[2,1.08,824.68]],"ltp":1.15,"tv":1100.27,"id":2258415}]}]}
{"op":"mcm","clk":"1001497961","pt":1580637041174,"mc":[{"id":"1.168215939","rc":[{"batb":[[0,3,380.84],[1,1.01,10.52],[2,1.01,0]],"ltp":4.3,"tv":60.3,"id":4423910},{"batb":[[0,1.08,824.68],[1,1.01,10.51],[2,1.08,0]],"batl":[[0,1.17,3.03],[1,1.18,0]],"ltp":1.15,"tv":1100.27,"id":2258415}]}]}
{"op":"mcm","clk":"1001498157","pt":1580637044080,"mc":[{"id":"1.168215939","rc":[{"batb":[[0,1.12,668.38],[1,1.11,477.91],[2,1.08,824.68]],"batl":[[1,1.19,270.72],[2,1.2,528.28]],"ltp":1.15,"tv":1100.27,"id":2258415}]}]}
{"op":"mcm","clk":"1001498255","pt":1580637045783,"mc":[{"id":"1.168215939","rc":[{"batl":[[1,1.19,0],[2,1.2,0]],"ltp":1.15,"tv":1100.27,"id":2258415}]}]}
{"op":"mcm","clk":"1001498330","pt":1580637046864,"mc":[{"id":"1.168215939","rc":[{"batb":[[0,1.01,10.52],[1,1.01,0]],"ltp":4.3,"tv":60.3,"id":4423910},{"batb":[[2,1.01,10.51]],"ltp":1.15,"tv":1100.27,"id":2258415}]}]}
{"op":"mcm","clk":"1001498446","pt":1580637048774,"mc":[{"id":"1.168215939","rc":[{"batl":[[0,1.14,548.08],[1,1.15,568.91],[2,1.17,3.03]],"ltp":1.15,"tv":1100.27,"id":2258415}]}]}
{"op":"mcm","clk":"1001498537","pt":1580637049963,"mc":[{"id":"1.168215939","rc":[{"batl":[[0,9.8,4.2]],"ltp":4.3,"tv":60.3,"id":4423910}]}]}
{"op":"mcm","clk":"1001498549","pt":1580637050167,"mc":[{"id":"1.168215939","rc":[{"batb":[[0,7.8,5.88],[1,1.01,10.52]],"ltp":4.3,"tv":60.3,"id":4423910},{"batl":[[1,1.15,610.92]],"ltp":1.15,"tv":1100.27,"id":2258415}]}]}
{"op":"mcm","clk":"1001498615","pt":1580637051201,"mc":[{"id":"1.168215939","rc":[{"batb":[[1,3.5,371.08],[2,1.01,10.52]],"ltp":4.3,"tv":60.3,"id":4423910},{"batb":[[2,1.06,955.61]],"ltp":1.15,"tv":1100.27,"id":2258415}]}]}
{"op":"mcm","clk":"1001498998","pt":1580637057813,"mc":[{"id":"1.168215939","rc":[{"batb":[[0,1.06,955.61],[1,1.01,10.51],[2,1.06,0]],"batl":[[0,1.15,42.01],[1,1.17,3.03],[2,1.17,0]],"ltp":1.15,"tv":1100.27,"id":2258415}]}]}
{"op":"mcm","clk":"1001499053","pt":1580637059000,"mc":[{"id":"1.168215939","rc":[{"batb":[[0,3.5,371.08],[1,1.01,10.52],[2,1.01,0]],"ltp":4.3,"tv":60.3,"id":4423910},{"batl":[[0,1.17,3.03],[1,1.17,0]],"ltp":1.15,"tv":1100.27,"id":2258415}]}]}
{"op":"mcm","clk":"1001499126","pt":1580637060798,"mc":[{"id":"1.168215939","rc":[{"batb":[[0,1.08,1184.32],[1,1.06,955.61],[2,1.01,10.51]],"batl":[[0,1.17,744.35],[1,1.18,348.91]],"ltp":1.15,"tv":1100.27,"id":2258415}]}]}
{"op":"mcm","clk":"1001499270","pt":1580637063112,"mc":[{"id":"1.168215939","rc":[{"batb":[[0,1.06,955.61],[1,1.01,10.51],[2,1.01,0]],"batl":[[0,1.17,3.03],[1,1.18,0]],"ltp":1.15,"tv":1100.27,"id":2258415}]}]}
{"op":"mcm","clk":"1001499449","pt":1580637066095,"mc":[{"id":"1.168215939","rc":[{"batb":[[0,1.11,963.9],[1,1.1,190.12],[2,1.06,955.61]],"batl":[[0,1.13,443.51],[1,1.14,682.37],[2,1.17,3.03]],"ltp":1.15,"tv":1100.27,"id":2258415}]}]}
{"op":"mcm","clk":"1001499484","pt":1580637067119,"mc":[{"id":"1.168215939","rc":[{"batb":[[0,1.06,955.61],[1,1.01,10.51],[2,1.06,0]],"batl":[[0,1.17,3.03],[1,1.14,0],[2,1.17,0]],"ltp":1.15,"tv":1100.27,"id":2258415}]}]}
{"op":"mcm","clk":"1001499642","pt":1580637070823,"mc":[{"id":"1.168215939","rc":[{"batb":[[0,1.08,1184.32],[1,1.06,955.61],[2,1.01,10.51]],"batl":[[0,1.17,744.35],[1,1.18,348.91]],"ltp":1.15,"tv":1100.27,"id":2258415}]}]}
{"op":"mcm","clk":"1001499911","pt":1580637075914,"mc":[{"id":"1.168215939","rc":[{"batl":[[0,1.17,3.03],[1,1.18,0]],"ltp":1.15,"tv":1100.27,"id":2258415}]}]}
{"op":"mcm","clk":"1001500061","pt":1580637078897,"mc":[{"id":"1.168215939","rc":[{"batb":[[1,1.01,10.51],[2,1.01,0]],"batl":[[0,1.1,820.97],[1,1.11,338.74],[2,1.17,3.03]],"ltp":1.15,"tv":1100.27,"id":2258415}]}]}
{"op":"mcm","clk":"1001500106","pt":1580637080215,"mc":[{"id":"1.168215939","rc":[{"batb":[[0,10,4.2],[1,3.5,371.08],[2,1.01,10.52]],"batl":[[0,13,3.36]],"ltp":4.3,"tv":60.3,"id":4423910},{"batb":[[0,1.08,1352.36]],"batl":[[1,1.11,380.75]],"ltp":1.15,"tv":1100.27,"id":2258415}]}]}
{"op":"mcm","clk":"1001500231","pt":1580637082936,"mc":[{"id":"1.168215939","rc":[{"batb":[[1,1.04,1263],[2,1.01,10.51]],"ltp":1.15,"tv":1100.27,"id":2258415}]}]}
{"op":"mcm","clk":"1001500922","pt":1580637097370,"mc":[{"id":"1.168215939","rc":[{"batb":[[0,1.08,168.04]],"batl":[[0,1.11,42.01],[1,1.17,3.03],[2,1.17,0]],"ltp":1.15,"tv":1100.27,"id":2258415}]}]}
{"op":"mcm","clk":"1001501025","pt":1580637099634,"mc":[{"id":"1.168215939","rc":[{"batb":[[0,1.01,10.52],[1,3.5,0],[2,1.01,0]],"ltp":4.3,"tv":60.3,"id":4423910},{"batb":[[0,1.01,10.51],[1,1.04,0],[2,1.01,0]],"batl":[[0,1.17,3.03],[1,1.17,0]],"ltp":1.15,"tv":1100.27,"id":2258415}]}]}
{"op":"mcm","clk":"1001501052","pt":1580637100361,"mc":[{"id":"1.168215939","rc":[{"batb":[[0,1.04,1229.88],[1,1.01,10.51]],"batl":[[0,1.13,917.48],[1,1.14,212.56],[2,1.17,3.03]],"ltp":1.15,"tv":1100.27,"id":2258415}]}]}
{"op":"mcm","clk":"1001502017","pt":1580637118672,"mc":[{"id":"1.168215939","rc":[{"batb":[[0,1.01,10.51],[1,1.01,0]],"ltp":1.15,"tv":1100.27,"id":2258415}]}]}
{"op":"mcm","clk":"1001502153","pt":1580637121596,"mc":[{"id":"1.168215939","rc":[{"batb":[[0,1.11,413.85],[1,1.1,745.18],[2,1.01,10.51]],"ltp":1.15,"tv":1100.27,"id":2258415}]}]}
{"op":"mcm","clk":"1001502202","pt":1580637122422,"mc":[{"id":"1.168215939","rc":[{"batb":[[0,8.4,5.04],[1,1.01,10.52]],"batl":[[0,10.5,4.2]],"ltp":4.3,"tv":60.3,"id":4423910},{"batb":[[1,1.1,913.22]],"ltp":1.15,"tv":1100.27,"id":2258415}]}]}
{"op":"mcm","clk":"1001502248","pt":1580637123096,"mc":[{"id":"1.168215939","rc":[{"batb":[[1,3.6,374.22],[2,1.01,10.52]],"ltp":4.3,"tv":60.3,"id":4423910},{"batb":[[2,1.05,1069.56]],"ltp":1.15,"tv":1100.27,"id":2258415}]}]}
{"op":"mcm","clk":"1001503307","pt":1580637142149,"mc":[{"id":"1.168215939","rc":[{"batb":[[0,1.1,168.04],[1,1.05,1069.56],[2,1.01,10.51]],"batl":[[0,1.17,3.03],[1,1.14,0],[2,1.17,0]],"ltp":1.15,"tv":1100.27,"id":2258415}]}]}
{"op":"mcm","clk":"1001503378","pt":1580637143151,"mc":[{"id":"1.168215939","rc":[{"batb":[[0,3.6,374.22],[1,1.01,10.52],[2,1.01,0]],"ltp":4.3,"tv":60.3,"id":4423910},{"batb":[[0,1.05,1069.56],[1,1.01,10.51],[2,1.01,0]],"ltp":1.15,"tv":1100.27,"id":2258415}]}]}
{"op":"mcm","clk":"1001503667","pt":1580637147517,"mc":[{"id":"1.168215939","rc":[{"batb":[[0,1.1,487.03],[1,1.09,681.96],[2,1.05,1069.56]],"batl":[[0,1.12,1028.31],[1,1.17,3.03]],"ltp":1.15,"tv":1100.27,"id":2258415}]}]}
{"op":"mcm","clk":"1001503796","pt":1580637149734,"mc":[{"id":"1.168215939","rc":[{"batb":[[0,1.05,1069.56],[1,1.01,10.51],[2,1.05,0]],"batl":[[0,1.17,3.03],[1,1.17,0]],"ltp":1.15,"tv":1100.27,"id":2258415}]}]}
{"op":"mcm","clk":"1001503877","pt":1580637151137,"mc":[{"id":"1.168215939","rc":[{"batb":[[0,1.01,10.52],[1,1.01,0]],"ltp":4.3,"tv":60.3,"id":4423910},{"batb":[[0,1.01,10.51],[1,1.01,0]],"ltp":1.15,"tv":1100.27,"id":2258415}]}]}
{"op":"mcm","clk":"1001503946","pt":1580637152741,"mc":[{"id":"1.168215939","rc":[{"batb":[[0,1.06,1206.67],[1,1.01,10.51]],"batl":[[0,1.16,583.22],[1,1.17,518.01]],"ltp":1.15,"tv":1100.27,"id":2258415}]}]}
{"op":"mcm","clk":"1001504123","pt":1580637155838,"mc":[{"id":"1.168215939","rc":[{"batl":[[0,1.1,55.45],[1,1.17,3.03]],"ltp":1.15,"tv":1100.27,"id":2258415}]}]}
{"op":"mcm","clk":"1001504307","pt":1580637158833,"mc":[{"id":"1.168215939","rc":[{"batl":[[0,1.08,1184.32],[1,1.1,55.45],[2,1.17,3.03]],"ltp":1.15,"tv":1100.27,"id":2258415}]}]}
{"op":"mcm","clk":"1001504392","pt":1580637160571,"mc":[{"id":"1.168215939","rc":[{"batb":[[0,13,3.36],[1,4,369.93],[2,1.01,10.52]],"ltp":4.3,"tv":60.3,"id":4423910},{"batb":[[0,1.06,1374.71],[1,1.02,2184.08],[2,1.01,10.51]],"ltp":1.15,"tv":1100.27,"id":2258415}]}]}
{"op":"mcm","clk":"1001505024","pt":1580637172294,"mc":[{"id":"1.168215939","rc":[{"batl":[[1,1.17,3.03],[2,1.17,0]],"ltp":1.15,"tv":1100.27,"id":2258415}]}]}
{"op":"mcm","clk":"1001505246","pt":1580637175356,"mc":[{"id":"1.168215939","rc":[{"trd":[[1.06,110.9]],"batb":[[0,1.06,1319.26]],"ltp":1.06,"tv":1211.17,"id":2258415}],"tv":1271.47}]}
{"op":"mcm","clk":"1001505496","pt":1580637178765,"mc":[{"id":"1.168215939","rc":[{"batb":[[0,1.06,1374.71]],"ltp":1.06,"tv":1211.17,"id":2258415}]}]}
{"op":"mcm","clk":"1001505622","pt":1580637181174,"mc":[{"id":"1.168215939","rc":[{"batb":[[0,4,369.93],[1,1.01,10.52],[2,1.01,0]],"ltp":4.3,"tv":60.3,"id":4423910},{"batb":[[0,1.02,2184.08],[1,1.01,10.51],[2,1.01,0]],"batl":[[0,1.17,3.03],[1,1.17,0]],"ltp":1.06,"tv":1211.17,"id":2258415}]}]}
{"op":"mcm","clk":"1001505683","pt":1580637182467,"mc":[{"id":"1.168215939","rc":[{"batb":[[0,1.01,10.52],[1,1.01,0]],"ltp":4.3,"tv":60.3,"id":4423910},{"batb":[[0,1.01,10.51],[1,1.01,0]],"ltp":1.06,"tv":1211.17,"id":2258415}]}]}
{"op":"mcm","clk":"1001505793","pt":1580637184071,"mc":[{"id":"1.168215939","rc":[{"batb":[[0,1.02,1253.99],[1,1.01,10.51]],"batl":[[0,1.1,180.42],[1,1.11,973.51],[2,1.17,3.03]],"ltp":1.06,"tv":1211.17,"id":2258415}]}]}
{"op":"mcm","clk":"1001505875","pt":1580637185465,"mc":[{"id":"1.168215939","rc":[{"batb":[[0,1.01,10.51],[1,1.01,0]],"batl":[[0,1.06,8.4],[1,1.17,3.03],[2,1.17,0]],"ltp":1.06,"tv":1211.17,"id":2258415}]}]}
{"op":"mcm","clk":"1001506028","pt":1580637188500,"mc":[{"id":"1.168215939","rc":[{"batb":[[0,1.05,1218.16],[1,1.01,10.51]],"batl":[[1,1.07,1195.39],[2,1.17,3.03]],"ltp":1.06,"tv":1211.17,"id":2258415}]}]}
{"op":"mcm","clk":"1001506426","pt":1580637195331,"mc":[{"id":"1.168215939","rc":[{"batb":[[0,1.01,10.51],[1,1.01,0]],"batl":[[1,1.17,3.03],[2,1.17,0]],"ltp":1.06,"tv":1211.17,"id":2258415}]}]}
{"op":"mcm","clk":"1001506588","pt":1580637198329,"mc":[{"id":"1.168215939","rc":[{"batb":[[0,1.02,1253.99],[1,1.01,10.51]],"batl":[[1,1.1,180.42],[2,1.11,973.51]],"ltp":1.06,"tv":1211.17,"id":2258415}]}]}
{"op":"mcm","clk":"1001506646","pt":1580637199364,"mc":[{"id":"1.168215939","rc":[{"batl":[[0,1.1,180.42],[1,1.11,973.51],[2,1.17,3.03]],"ltp":1.06,"tv":1211.17,"id":2258415}]}]}
{"op":"mcm","clk":"1001506824","pt":1580637202875,"mc":[{"id":"1.168215939","rc":[{"batl":[[0,1.05,8.4],[1,1.17,3.03],[2,1.17,0]],"ltp":1.06,"tv":1211.17,"id":2258415}]}]}
{"op":"mcm","clk":"1001506966","pt":1580637205876,"mc":[{"id":"1.168215939","rc":[{"batl":[[0,1.03,1241.81],[1,1.05,8.4],[2,1.17,3.03]],"ltp":1.06,"tv":1211.17,"id":2258415}]}]}
{"op":"mcm","clk":"1001507026","pt":1580637207060,"mc":[{"id":"1.168215939","rc":[{"batb":[[0,4.4,375.46],[1,1.01,10.52]],"ltp":4.3,"tv":60.3,"id":4423910}]}]}
{"op":"mcm","clk":"1001507723","pt":1580637220877,"mc":[{"id":"1.168215939","rc":[{"trd":[[1.02,20.58]],"batb":[[0,1.02,1243.7]],"ltp":1.02,"tv":1231.76,"id":2258415}],"tv":1292.06}]}
{"op":"mcm","clk":"1001509119","pt":1580637247992,"mc":[{"id":"1.168215939","rc":[{"trd":[[1.02,24.36]],"batb":[[0,1.02,1241.81]],"ltp":1.02,"tv":1235.54,"id":2258415}],"tv":1295.84}]}
{"op":"mcm","clk":"1001509281","pt":1580637250893,"mc":[{"id":"1.168215939","rc":[{"trd":[[1.02,190.96]],"batb":[[0,1.02,1158.51]],"ltp":1.02,"tv":1402.13,"id":2258415}],"tv":1462.43}]}
{"op":"mcm","clk":"1001509520","pt":1580637254392,"mc":[{"id":"1.168215939","rc":[{"trd":[[1.02,230.96]],"batb":[[0,1.02,1233.99]],"ltp":1.02,"tv":1442.13,"id":2258415}],"tv":1502.43}]}
{"op":"mcm","clk":"1001510447","pt":1580637274633,"mc":[{"id":"1.168215939","rc":[{"trd":[[1.02,354.96]],"batb":[[0,1.02,1171.99]],"ltp":1.02,"tv":1566.13,"id":2258415}],"tv":1626.43}]}
{"op":"mcm","clk":"1001510652","pt":1580637278028,"mc":[{"id":"1.168215939","rc":[{"batb":[[0,1.02,1253.99]],"ltp":1.02,"tv":1566.13,"id":2258415}]}]}
{"op":"mcm","clk":"1001510791","pt":1580637280745,"mc":[{"id":"1.168215939","rc":[{"trd":[[1.02,358.74]],"batb":[[0,1.02,1252.1]],"ltp":1.02,"tv":1569.91,"id":2258415}],"tv":1630.21}]}
{"op":"mcm","clk":"1001511257","pt":1580637289459,"mc":[{"id":"1.168215939","rc":[{"trd":[[1.02,1358.74]],"batb":[[0,1.01,10.51],[1,1.01,0]],"batl":[[0,1.05,8.4],[1,1.17,3.03],[2,1.17,0]],"ltp":1.02,"tv":2569.91,"id":2258415}],"tv":2630.21}]}
{"op":"mcm","clk":"1001511417","pt":1580637292954,"mc":[{"id":"1.168215939","rc":[{"batb":[[0,1.01,1276.92]],"batl":[[0,1.05,1226.56]],"ltp":1.02,"tv":2569.91,"id":2258415}]}]}
{"op":"mcm","clk":"1001511706","pt":1580637299398,"mc":[{"id":"1.168215939","rc":[{"batl":[[0,1.02,37.25],[1,1.05,1226.56],[2,1.17,3.03]],"ltp":1.02,"tv":2569.91,"id":2258415}]}]}
{"op":"mcm","clk":"1001511872","pt":1580637301697,"mc":[{"id":"1.168215939","rc":[{"batl":[[0,1.05,1226.56],[1,1.17,3.03],[2,1.17,0]],"ltp":1.02,"tv":2569.91,"id":2258415}]}]}
{"op":"mcm","clk":"1001511955","pt":1580637302787,"mc":[{"id":"1.168215939","rc":[{"batb":[[0,1.01,10.51]],"ltp":1.02,"tv":2569.91,"id":2258415}]}]}
{"op":"mcm","clk":"1001512091","pt":1580637305776,"mc":[{"id":"1.168215939","rc":[{"batb":[[0,1.03,1241.81],[1,1.01,10.51]],"ltp":1.02,"tv":2569.91,"id":2258415}]}]}
{"op":"mcm","clk":"1001512142","pt":1580637306806,"mc":[{"id":"1.168215939","rc":[{"batl":[[0,1.04,42.01],[1,1.05,1226.56],[2,1.17,3.03]],"ltp":1.02,"tv":2569.91,"id":2258415}]}]}
{"op":"mcm","clk":"1001512169","pt":1580637307218,"mc":[{"id":"1.168215939","rc":[{"batb":[[1,1.01,3887.94]],"ltp":1.02,"tv":2569.91,"id":2258415}]}]}
{"op":"mcm","clk":"1001512808","pt":1580637317909,"mc":[{"id":"1.168215939","rc":[{"batb":[[0,1.01,3887.94],[1,1.01,0]],"batl":[[1,1.05,8.4]],"ltp":1.02,"tv":2569.91,"id":2258415}]}]}
{"op":"mcm","clk":"1001512873","pt":1580637319410,"mc":[{"id":"1.168215939","rc":[{"batl":[[0,1.05,8.4],[1,1.17,3.03],[2,1.17,0]],"ltp":1.02,"tv":2569.91,"id":2258415}]}]}
{"op":"mcm","clk":"1001512934","pt":1580637320804,"mc":[{"id":"1.168215939","rc":[{"batb":[[0,1.02,1253.99],[1,1.01,3887.94]],"batl":[[0,1.03,37.25],[1,1.05,8.4],[2,1.07,311.08]],"ltp":1.02,"tv":2569.91,"id":2258415}]}]}
{"op":"mcm","clk":"1001512961","pt":1580637321402,"mc":[{"id":"1.168215939","rc":[{"batl":[[2,1.17,3.03]],"ltp":1.02,"tv":2569.91,"id":2258415}]}]}
{"op":"mcm","clk":"1001513077","pt":1580637323902,"mc":[{"id":"1.168215939","rc":[{"batb":[[1,1.01,10.51]],"ltp":1.02,"tv":2569.91,"id":2258415}]}]}
{"op":"mcm","clk":"1001513104","pt":1580637324517,"mc":[{"id":"1.168215939","rc":[{"batl":[[0,1.03,782.51],[1,1.04,533.38],[2,1.05,8.4]],"ltp":1.02,"tv":2569.91,"id":2258415}]}]}
{"op":"mcm","clk":"1001513251","pt":1580637327716,"mc":[{"id":"1.168215939","rc":[{"batl":[[0,520,35.52]],"ltp":4.3,"tv":60.3,"id":4423910}]}]}
{"op":"mcm","clk":"1001513325","pt":1580637329114,"mc":[{"id":"1.168215939","rc":[{"batl":[[0,1.03,745.26]],"ltp":1.02,"tv":2569.91,"id":2258415}]}]}
{"op":"mcm","clk":"1001513470","pt":1580637332417,"mc":[{"id":"1.168215939","rc":[{"batb":[[0,1.02,3715.53]],"ltp":1.02,"tv":2569.91,"id":2258415}]}]}
{"op":"mcm","clk":"1001513643","pt":1580637335927,"mc":[{"id":"1.168215939","rc":[{"batb":[[0,1.02,1253.99]],"ltp":1.02,"tv":2569.91,"id":2258415}]}]}
{"op":"mcm","clk":"1001513661","pt":1580637336339,"mc":[{"id":"1.168215939","rc":[{"batb":[[0,1.01,10.51],[1,1.01,0]],"batl":[[0,1.03,42.01],[1,1.05,8.4],[2,1.05,0]],"ltp":1.02,"tv":2569.91,"id":2258415}]}]}
{"op":"mcm","clk":"1001513759","pt":1580637337944,"mc":[{"id":"1.168215939","rc":[{"batl":[[0,1.05,8.4],[1,1.05,0]],"ltp":1.02,"tv":2569.91,"id":2258415}]}]}
{"op":"mcm","clk":"1001513842","pt":1580637339937,"mc":[{"id":"1.168215939","rc":[{"batb":[[0,1.01,1276.92]],"batl":[[1,1.06,1206.67]],"ltp":1.02,"tv":2569.91,"id":2258415}]}]}
{"op":"mcm","clk":"1001514108","pt":1580637345036,"mc":[{"id":"1.168215939","rc":[{"batl":[[1,1.06,0]],"ltp":1.02,"tv":2569.91,"id":2258415}]}]}
{"op":"mcm","clk":"1001514275","pt":1580637348644,"mc":[{"id":"1.168215939","rc":[{"batb":[[0,1.01,1444.96]],"batl":[[0,1.02,1296],[1,1.05,8.4]],"ltp":1.02,"tv":2569.91,"id":2258415}]}]}
{"op":"mcm","clk":"1001515885","pt":1580637378631,"mc":[{"id":"1.168215939","rc":[{"batb":[[0,1.01,3907.08]],"ltp":1.02,"tv":2569.91,"id":2258415}]}]}
{"op":"mcm","clk":"1001515935","pt":1580637379609,"mc":[{"id":"1.168215939","rc":[{"batb":[[0,1.01,288.76]],"batl":[[0,1.05,8.4],[1,1.05,0]],"ltp":1.02,"tv":2569.91,"id":2258415}]}]}
{"op":"mcm","clk":"1001516000","pt":1580637381330,"mc":[{"id":"1.168215939","rc":[{"batb":[[0,1.01,10.52],[1,1.01,0]],"ltp":4.3,"tv":60.3,"id":4423910}]}]}
{"op":"mcm","clk":"1001516059","pt":1580637382826,"mc":[{"id":"1.168215939","rc":[{"batl":[[0,1.04,1229.88],[1,1.05,8.4]],"ltp":1.02,"tv":2569.91,"id":2258415}]}]}
{"op":"mcm","clk":"1001516375","pt":1580637388615,"mc":[{"id":"1.168215939","rc":[{"batl":[[0,1.05,8.4],[1,1.05,0]],"ltp":1.02,"tv":2569.91,"id":2258415}]}]}
{"op":"mcm","clk":"1001516665","pt":1580637391626,"mc":[{"id":"1.168215939","rc":[{"batl":[[0,1.02,1253.99],[1,1.05,8.4]],"ltp":1.02,"tv":2569.91,"id":2258415}]}]}
{"op":"mcm","clk":"1001516935","pt":1580637393500,"mc":[{"id":"1.168215939","rc":[{"batb":[[0,4.7,367.67],[1,1.01,10.52]],"ltp":4.3,"tv":60.3,"id":4423910}]}]}
{"op":"mcm","clk":"1001517031","pt":1580637394920,"mc":[{"id":"1.168215939","rc":[{"batl":[[0,1.02,1646.24]],"ltp":1.02,"tv":2569.91,"id":2258415}]}]}
{"op":"mcm","clk":"1001517656","pt":1580637403714,"mc":[{"id":"1.168215939","rc":[{"batb":[[0,1.01,10.51]],"batl":[[0,1.02,1253.99]],"ltp":1.02,"tv":2569.91,"id":2258415}]}]}
{"op":"mcm","clk":"1001517942","pt":1580637408745,"mc":[{"id":"1.168215939","rc":[{"batl":[[0,1.05,8.4],[1,1.05,0]],"ltp":1.02,"tv":2569.91,"id":2258415}]}]}
{"op":"mcm","clk":"1001518110","pt":1580637411673,"mc":[{"id":"1.168215939","rc":[{"trd":[[1.01,21.02]],"batl":[[0,1.01,1255.9],[1,1.05,8.4]],"ltp":1.01,"tv":2590.93,"id":2258415}],"tv":2651.23}]}
{"op":"mcm","clk":"1001518362","pt":1580637414963,"mc":[{"id":"1.168215939","rc":[{"batl":[[0,1.01,1297.91]],"ltp":1.01,"tv":2590.93,"id":2258415}]}]}
{"op":"mcm","clk":"1001520365","pt":1580637441269,"mc":[{"id":"1.168215939","rc":[{"batl":[[0,1.01,1255.9]],"ltp":1.01,"tv":2590.93,"id":2258415}]}]}
{"op":"mcm","clk":"1001520830","pt":1580637448299,"mc":[{"id":"1.168215939","rc":[{"batl":[[0,1.01,1297.91]],"ltp":1.01,"tv":2590.93,"id":2258415}]}]}
{"op":"mcm","clk":"1001521553","pt":1580637457713,"mc":[{"id":"1.168215939","rc":[{"batl":[[0,1.01,2084.73]],"ltp":1.01,"tv":2590.93,"id":2258415}]}]}
{"op":"mcm","clk":"1001521611","pt":1580637458532,"mc":[{"id":"1.168215939","rc":[{"batl":[[0,1.01,1129.74]],"ltp":1.01,"tv":2590.93,"id":2258415}]}]}
{"op":"mcm","clk":"1001521666","pt":1580637459311,"mc":[{"id":"1.168215939","rc":[{"batl":[[0,1.01,1087.73]],"ltp":1.01,"tv":2590.93,"id":2258415}]}]}
{"op":"mcm","clk":"1001521870","pt":1580637461836,"mc":[{"id":"1.168215939","rc":[{"batl":[[1,1.02,956.02],[2,1.05,8.4]],"ltp":1.01,"tv":2590.93,"id":2258415}]}]}
{"op":"mcm","clk":"1001522658","pt":1580637474418,"mc":[{"id":"1.168215939","rc":[{"batl":[[0,1.01,786.82]],"ltp":1.01,"tv":2590.93,"id":2258415}]}]}
{"op":"mcm","clk":"1001522882","pt":1580637477925,"mc":[{"id":"1.168215939","rc":[{"batl":[[1,1.02,1253.99]],"ltp":1.01,"tv":2590.93,"id":2258415}]}]}
{"op":"mcm","clk":"1001522888","pt":1580637478026,"mc":[{"id":"1.168215939","rc":[{"batl":[[1,1.02,701.13]],"ltp":1.01,"tv":2590.93,"id":2258415}]}]}
{"op":"mcm","clk":"1001523385","pt":1580637486552,"mc":[{"id":"1.168215939","rc":[{"batl":[[1,1.05,8.4],[2,1.05,0]],"ltp":1.01,"tv":2590.93,"id":2258415}]}]}
{"op":"mcm","clk":"1001523538","pt":1580637489233,"mc":[{"id":"1.168215939","rc":[{"batl":[[0,1.01,2053.23]],"ltp":1.01,"tv":2590.93,"id":2258415}]}]}
{"op":"mcm","clk":"1001523599","pt":1580637490376,"mc":[{"id":"1.168215939","rc":[{"batl":[[0,1.01,2095.24]],"ltp":1.01,"tv":2590.93,"id":2258415}]}]}
{"op":"mcm","clk":"1001524400","pt":1580637506062,"mc":[{"id":"1.168215939","rc":[{"batl":[[0,1.01,1175.68]],"ltp":1.01,"tv":2590.93,"id":2258415}]}]}
{"op":"mcm","clk":"1001524473","pt":1580637507289,"mc":[{"id":"1.168215939","rc":[{"batl":[[0,1.01,1133.67]],"ltp":1.01,"tv":2590.93,"id":2258415}]}]}
{"op":"mcm","clk":"1001524585","pt":1580637509300,"mc":[{"id":"1.168215939","rc":[{"batl":[[1,1.02,910.53],[2,1.05,8.4]],"ltp":1.01,"tv":2590.93,"id":2258415}]}]}
{"op":"mcm","clk":"1001525957","pt":1580637532813,"mc":[{"id":"1.168215939","rc":[{"batl":[[0,1.01,786.82]],"ltp":1.01,"tv":2590.93,"id":2258415}]}]}
{"op":"mcm","clk":"1001526122","pt":1580637535484,"mc":[{"id":"1.168215939","rc":[{"batl":[[1,1.02,1253.99]],"ltp":1.01,"tv":2590.93,"id":2258415}]}]}
{"op":"mcm","clk":"1001526183","pt":1580637536407,"mc":[{"id":"1.168215939","rc":[{"batl":[[1,1.02,641.65]],"ltp":1.01,"tv":2590.93,"id":2258415}]}]}
{"op":"mcm","clk":"1001526710","pt":1580637544312,"mc":[{"id":"1.168215939","rc":[{"batl":[[1,1.02,1253.99]],"ltp":1.01,"tv":2590.93,"id":2258415}]}]}
{"op":"mcm","clk":"1001526935","pt":1580637548636,"mc":[{"id":"1.168215939","rc":[{"batl":[[1,1.05,8.4],[2,1.05,0]],"ltp":1.01,"tv":2590.93,"id":2258415}]}]}
{"op":"mcm","clk":"1001527111","pt":1580637551531,"mc":[{"id":"1.168215939","rc":[{"batl":[[0,1.01,2053.23]],"ltp":1.01,"tv":2590.93,"id":2258415}]}]}
{"op":"mcm","clk":"1001527171","pt":1580637552508,"mc":[{"id":"1.168215939","rc":[{"batl":[[0,1.01,2095.24]],"ltp":1.01,"tv":2590.93,"id":2258415}]}]}
{"op":"mcm","clk":"1001527892","pt":1580637564852,"mc":[{"id":"1.168215939","rc":[{"batl":[[0,1.01,828.83]],"ltp":1.01,"tv":2590.93,"id":2258415}]}]}
{"op":"mcm","clk":"1001527926","pt":1580637565474,"mc":[{"id":"1.168215939","rc":[{"batl":[[0,1.01,786.82]],"ltp":1.01,"tv":2590.93,"id":2258415}]}]}
{"op":"mcm","clk":"1001528120","pt":1580637567876,"mc":[{"id":"1.168215939","rc":[{"batl":[[1,1.02,1253.99],[2,1.05,8.4]],"ltp":1.01,"tv":2590.93,"id":2258415}]}]}
{"op":"mcm","clk":"1001528180","pt":1580637568565,"mc":[{"id":"1.168215939","rc":[{"batl":[[1,1.05,8.4],[2,1.05,0]],"ltp":1.01,"tv":2590.93,"id":2258415}]}]}
{"op":"mcm","clk":"1001528370","pt":1580637570873,"mc":[{"id":"1.168215939","rc":[{"batl":[[0,1.01,2053.23]],"ltp":1.01,"tv":2590.93,"id":2258415}]}]}
{"op":"mcm","clk":"1001528570","pt":1580637573357,"mc":[{"id":"1.168215939","rc":[{"batl":[[0,1.01,786.82]],"ltp":1.01,"tv":2590.93,"id":2258415}]}]}
{"op":"mcm","clk":"1001528945","pt":1580637577949,"mc":[{"id":"1.168215939","rc":[{"batl":[[0,1.01,2053.23]],"ltp":1.01,"tv":2590.93,"id":2258415}]}]}
{"op":"mcm","clk":"1001529004","pt":1580637578775,"mc":[{"id":"1.168215939","rc":[{"batl":[[0,1.01,2095.24]],"ltp":1.01,"tv":2590.93,"id":2258415}]}]}
{"op":"mcm","clk":"1001530619","pt":1580637601571,"mc":[{"id":"1.168215939","rc":[{"batl":[[0,1.01,2053.23]],"ltp":1.01,"tv":2590.93,"id":2258415}]}]}
{"op":"mcm","clk":"1001531468","pt":1580637610609,"mc":[{"id":"1.168215939","rc":[{"batb":[[0,1.01,10.52],[1,1.01,0]],"ltp":4.3,"tv":60.3,"id":4423910}]}]}
{"op":"mcm","clk":"1001532289","pt":1580637622444,"mc":[{"id":"1.168215939","rc":[{"batl":[[0,1.01,2095.24]],"ltp":1.01,"tv":2590.93,"id":2258415}]}]}
{"op":"mcm","clk":"1001533372","pt":1580637635861,"mc":[{"id":"1.168215939","rc":[{"batl":[[0,1.01,828.83]],"ltp":1.01,"tv":2590.93,"id":2258415}]}]}
{"op":"mcm","clk":"1001533491","pt":1580637637420,"mc":[{"id":"1.168215939","rc":[{"batl":[[0,1.01,786.82]],"ltp":1.01,"tv":2590.93,"id":2258415}]}]}
{"op":"mcm","clk":"1001533573","pt":1580637638460,"mc":[{"id":"1.168215939","rc":[{"batl":[[1,1.02,1253.99],[2,1.05,8.4]],"ltp":1.01,"tv":2590.93,"id":2258415}]}]}
{"op":"mcm","clk":"1001533813","pt":1580637641457,"mc":[{"id":"1.168215939","rc":[{"batl":[[1,1.05,8.4],[2,1.05,0]],"ltp":1.01,"tv":2590.93,"id":2258415}]}]}
{"op":"mcm","clk":"1001534043","pt":1580637644659,"mc":[{"id":"1.168215939","rc":[{"batl":[[0,1.01,2095.24]],"ltp":1.01,"tv":2590.93,"id":2258415}]}]}
{"op":"mcm","clk":"1001535205","pt":1580637659538,"mc":[{"id":"1.168215939","rc":[{"batl":[[0,1.01,2053.23]],"ltp":1.01,"tv":2590.93,"id":2258415}]}]}
{"op":"mcm","clk":"1001536919","pt":1580637680533,"mc":[{"id":"1.168215939","rc":[{"batl":[[0,1.01,2095.24]],"ltp":1.01,"tv":2590.93,"id":2258415}]}]}
{"op":"mcm","clk":"1001537010","pt":1580637681829,"mc":[{"id":"1.168215939","rc":[{"batb":[[0,4.7,367.67],[1,1.01,10.52]],"ltp":4.3,"tv":60.3,"id":4423910}]}]}
{"op":"mcm","clk":"1001538439","pt":1580637699656,"mc":[{"id":"1.168215939","rc":[{"batl":[[0,1.01,786.82]],"ltp":1.01,"tv":2590.93,"id":2258415}]}]}
{"op":"mcm","clk":"1001538743","pt":1580637703561,"mc":[{"id":"1.168215939","rc":[{"batl":[[0,1.01,1016.71]],"ltp":1.01,"tv":2590.93,"id":2258415}]}]}
{"op":"mcm","clk":"1001538916","pt":1580637705851,"mc":[{"id":"1.168215939","rc":[{"batl":[[0,1.01,2053.23]],"ltp":1.01,"tv":2590.93,"id":2258415}]}]}
{"op":"mcm","clk":"1001539068","pt":1580637707957,"mc":[{"id":"1.168215939","rc":[{"batl":[[0,1.01,1016.71]],"ltp":1.01,"tv":2590.93,"id":2258415}]}]}
{"op":"mcm","clk":"1001539263","pt":1580637710765,"mc":[{"id":"1.168215939","rc":[{"batl":[[1,1.02,1028],[2,1.05,8.4]],"ltp":1.01,"tv":2590.93,"id":2258415}]}]}
{"op":"mcm","clk":"1001541083","pt":1580637730334,"mc":[{"id":"1.168215939","rc":[{"batl":[[0,1.01,1100.73]],"ltp":1.01,"tv":2590.93,"id":2258415}]}]}
{"op":"mcm","clk":"1001546797","pt":1580637795822,"mc":[{"id":"1.168215939","rc":[{"batl":[[0,1.01,870.84],[1,1.02,263.28]],"ltp":1.01,"tv":2590.93,"id":2258415}]}]}
{"op":"mcm","clk":"1001547043","pt":1580637798926,"mc":[{"id":"1.168215939","rc":[{"batb":[[0,1.01,10.52],[1,1.01,0]],"ltp":4.3,"tv":60.3,"id":4423910},{"batl":[[1,1.03,981.09]],"ltp":1.01,"tv":2590.93,"id":2258415}]}]}
{"op":"mcm","clk":"1001547120","pt":1580637799919,"mc":[{"id":"1.168215939","rc":[{"batl":[[1,1.05,8.4],[2,1.05,0]],"ltp":1.01,"tv":2590.93,"id":2258415}]}]}
{"op":"mcm","clk":"1001547216","pt":1580637801417,"mc":[{"id":"1.168215939","rc":[{"batl":[[0,1.01,2137.25]],"ltp":1.01,"tv":2590.93,"id":2258415}]}]}
{"op":"mcm","clk":"1001547353","pt":1580637803391,"mc":[{"id":"1.168215939","rc":[{"batb":[[0,4.8,367.63],[1,1.01,10.52]],"ltp":4.3,"tv":60.3,"id":4423910}]}]}
{"op":"mcm","clk":"1001547763","pt":1580637808937,"mc":[{"id":"1.168215939","rc":[{"batl":[[0,1.01,870.84]],"ltp":1.01,"tv":2590.93,"id":2258415}]}]}
{"op":"mcm","clk":"1001547868","pt":1580637810302,"mc":[{"id":"1.168215939","rc":[{"batb":[[0,1.01,10.52],[1,1.01,0]],"ltp":4.3,"tv":60.3,"id":4423910}]}]}
{"op":"mcm","clk":"1001548003","pt":1580637811826,"mc":[{"id":"1.168215939","rc":[{"batl":[[1,1.02,1253.99],[2,1.05,8.4]],"ltp":1.01,"tv":2590.93,"id":2258415}]}]}
{"op":"mcm","clk":"1001548107","pt":1580637812841,"mc":[{"id":"1.168215939","rc":[{"batl":[[1,1.05,8.4],[2,1.05,0]],"ltp":1.01,"tv":2590.93,"id":2258415}]}]}
{"op":"mcm","clk":"1001548394","pt":1580637816532,"mc":[{"id":"1.168215939","rc":[{"batb":[[0,4.7,374.21],[1,1.01,10.52]],"ltp":4.3,"tv":60.3,"id":4423910},{"batl":[[0,1.01,2137.25]],"ltp":1.01,"tv":2590.93,"id":2258415}]}]}
{"op":"mcm","clk":"1001548480","pt":1580637817362,"mc":[{"id":"1.168215939","rc":[{"batl":[[0,1.01,870.84]],"ltp":1.01,"tv":2590.93,"id":2258415}]}]}
{"op":"mcm","clk":"1001548566","pt":1580637818344,"mc":[{"id":"1.168215939","rc":[{"batb":[[0,1.01,10.52],[1,1.01,0]],"ltp":4.3,"tv":60.3,"id":4423910}]}]}
{"op":"mcm","clk":"1001548734","pt":1580637820326,"mc":[{"id":"1.168215939","rc":[{"batl":[[1,1.02,1253.99],[2,1.05,8.4]],"ltp":1.01,"tv":2590.93,"id":2258415}]}]}
{"op":"mcm","clk":"1001548869","pt":1580637821943,"mc":[{"id":"1.168215939","rc":[{"batl":[[1,1.05,8.4],[2,1.05,0]],"ltp":1.01,"tv":2590.93,"id":2258415}]}]}
{"op":"mcm","clk":"1001549104","pt":1580637824758,"mc":[{"id":"1.168215939","rc":[{"batl":[[0,1.01,2137.25]],"ltp":1.01,"tv":2590.93,"id":2258415}]}]}
{"op":"mcm","clk":"1001549182","pt":1580637825661,"mc":[{"id":"1.168215939","rc":[{"batb":[[0,4.8,370.06],[1,1.01,10.52]],"ltp":4.3,"tv":60.3,"id":4423910}]}]}
{"op":"mcm","clk":"1001550132","pt":1580637836576,"mc":[{"id":"1.168215939","rc":[{"batb":[[0,1.01,10.52],[1,1.01,0]],"ltp":4.3,"tv":60.3,"id":4423910}]}]}
{"op":"mcm","clk":"1001550871","pt":1580637844883,"mc":[{"id":"1.168215939","rc":[{"batb":[[0,4.7,374.21],[1,1.01,10.52]],"ltp":4.3,"tv":60.3,"id":4423910}]}]}
{"op":"mcm","clk":"1001551711","pt":1580637854573,"mc":[{"id":"1.168215939","rc":[{"batl":[[0,1.01,870.84]],"ltp":1.01,"tv":2590.93,"id":2258415}]}]}
{"op":"mcm","clk":"1001551813","pt":1580637855664,"mc":[{"id":"1.168215939","rc":[{"batb":[[0,1.01,10.52],[1,1.01,0]],"ltp":4.3,"tv":60.3,"id":4423910}]}]}
{"op":"mcm","clk":"1001552166","pt":1580637859808,"mc":[{"id":"1.168215939","rc":[{"batl":[[0,1.01,2137.25]],"ltp":1.01,"tv":2590.93,"id":2258415}]}]}
{"op":"mcm","clk":"1001552368","pt":1580637861789,"mc":[{"id":"1.168215939","rc":[{"batl":[[0,1.01,870.84]],"ltp":1.01,"tv":2590.93,"id":2258415}]}]}
{"op":"mcm","clk":"1001552648","pt":1580637864799,"mc":[{"id":"1.168215939","rc":[{"batl":[[1,1.02,1253.99],[2,1.05,8.4]],"ltp":1.01,"tv":2590.93,"id":2258415}]}]}
{"op":"mcm","clk":"1001553441","pt":1580637873791,"mc":[{"id":"1.168215939","rc":[{"batl":[[1,1.05,8.4],[2,1.05,0]],"ltp":1.01,"tv":2590.93,"id":2258415}]}]}
{"op":"mcm","clk":"1001553724","pt":1580637876805,"mc":[{"id":"1.168215939","rc":[{"batl":[[0,1.01,2137.25]],"ltp":1.01,"tv":2590.93,"id":2258415}]}]}
{"op":"mcm","clk":"1001553914","pt":1580637878991,"mc":[{"id":"1.168215939","rc":[{"batb":[[0,4.8,370.06],[1,1.01,10.52]],"ltp":4.3,"tv":60.3,"id":4423910}]}]}
{"op":"mcm","clk":"1001555897","pt":1580637901035,"mc":[{"id":"1.168215939","rc":[{"batb":[[0,1.01,10.52],[1,1.01,0]],"ltp":4.3,"tv":60.3,"id":4423910}]}]}
{"op":"mcm","clk":"1001557319","pt":1580637917600,"mc":[{"id":"1.168215939","rc":[{"batb":[[0,4.8,367.63],[1,1.01,10.52]],"ltp":4.3,"tv":60.3,"id":4423910}]}]}
{"op":"mcm","clk":"1001558504","pt":1580637931937,"mc":[{"id":"1.168215939","rc":[{"batl":[[0,1.01,870.84]],"ltp":1.01,"tv":2590.93,"id":2258415}]}]}
{"op":"mcm","clk":"1001558741","pt":1580637934905,"mc":[{"id":"1.168215939","rc":[{"batb":[[0,1.01,10.52],[1,1.01,0]],"ltp":4.3,"tv":60.3,"id":4423910},{"batl":[[1,1.02,1253.99],[2,1.05,8.4]],"ltp":1.01,"tv":2590.93,"id":2258415}]}]}
{"op":"mcm","clk":"1001558885","pt":1580637936423,"mc":[{"id":"1.168215939","rc":[{"batl":[[1,1.05,8.4],[2,1.05,0]],"ltp":1.01,"tv":2590.93,"id":2258415}]}]}
{"op":"mcm","clk":"1001558991","pt":1580637937892,"mc":[{"id":"1.168215939","marketDefinition":{"bspMarket":false,"turnInPlayEnabled":true,"persistenceEnabled":true,"marketBaseRate":5.0,"eventId":"29681228","eventTypeId":"2","numberOfWinners":1,"bettingType":"ODDS","marketType":"SET_WINNER","marketTime":"2020-02-02T09:23:00.000Z","suspendTime":"2020-02-02T09:23:00.000Z","bspReconciled":false,"complete":true,"inPlay":true,"crossMatching":true,"runnersVoidable":false,"numberOfActiveRunners":2,"betDelay":3,"status":"SUSPENDED","runners":[{"status":"ACTIVE","sortPriority":1,"id":4423910,"name":"Matthew Ebden"},{"status":"ACTIVE","sortPriority":2,"id":2258415,"name":"Lukas Rosol"}],"regulators":["MR_INT"],"countryCode":"IN","discountAllowed":true,"timezone":"UTC","openDate":"2020-02-02T09:23:00.000Z","version":3148386378,"name":"Set 1 Winner","eventName":"Ebden v Rosol"}}]}
{"op":"mcm","clk":"1001562090","pt":1580637971745,"mc":[{"id":"1.168215939","tv":0.0}]}
{"op":"mcm","clk":"1001562200","pt":1580637972975,"mc":[{"id":"1.168215939","marketDefinition":{"bspMarket":false,"turnInPlayEnabled":true,"persistenceEnabled":true,"marketBaseRate":5.0,"eventId":"29681228","eventTypeId":"2","numberOfWinners":1,"bettingType":"ODDS","marketType":"SET_WINNER","marketTime":"2020-02-02T09:23:00.000Z","suspendTime":"2020-02-02T09:23:00.000Z","bspReconciled":false,"complete":true,"inPlay":true,"crossMatching":false,"runnersVoidable":false,"numberOfActiveRunners":0,"betDelay":3,"status":"CLOSED","settledTime":"2020-02-02T10:06:10.000Z","runners":[{"status":"LOSER","sortPriority":1,"id":4423910,"name":"Matthew Ebden"},{"status":"WINNER","sortPriority":2,"id":2258415,"name":"Lukas Rosol"}],"regulators":["MR_INT"],"countryCode":"IN","discountAllowed":true,"timezone":"UTC","openDate":"2020-02-02T09:23:00.000Z","version":3148387114,"name":"Set 1 Winner","eventName":"Ebden v Rosol"}}]}
