{"op":"mcm","clk":"994279932","pt":1580566029164,"mc":[{"id":"1.168215937","marketDefinition":{"bspMarket":false,"turnInPlayEnabled":true,"persistenceEnabled":true,"marketBaseRate":5.0,"eventId":"29681228","eventTypeId":"2","numberOfWinners":1,"bettingType":"ODDS","marketType":"MATCH_ODDS","marketTime":"2020-02-02T04:00:00.000Z","suspendTime":"2020-02-02T04:00:00.000Z","bspReconciled":false,"complete":true,"inPlay":false,"crossMatching":false,"runnersVoidable":false,"numberOfActiveRunners":2,"betDelay":0,"status":"OPEN","runners":[{"status":"ACTIVE","sortPriority":1,"id":4423910,"name":"Matthew Ebden"},{"status":"ACTIVE","sortPriority":2,"id":2258415,"name":"Lukas Rosol"}],"regulators":["MR_INT"],"countryCode":"IN","discountAllowed":false,"timezone":"UTC","openDate":"2020-02-02T04:00:00.000Z","version":3145381988,"name":"Match Odds","eventName":"Ebden v Rosol"},"rc":[{"batb":[[0,1.02,3786.16],[1,1.01,4132.68]],"ltp":0.0,"tv":0.0,"id":4423910},{"batb":[[0,1.05,152.2],[1,1.04,168.86],[2,1.03,237.77]],"ltp":0.0,"tv":0.0,"id":2258415}]}]}
{"op":"mcm","clk":"994280373","pt":1580566030955,"mc":[{"id":"1.168215937","marketDefinition":{"bspMarket":false,"turnInPlayEnabled":true,"persistenceEnabled":true,"marketBaseRate":5.0,"eventId":"29681228","eventTypeId":"2","numberOfWinners":1,"bettingType":"ODDS","marketType":"MATCH_ODDS","marketTime":"2020-02-02T04:00:00.000Z","suspendTime":"2020-02-02T04:00:00.000Z","bspReconciled":false,"complete":true,"inPlay":false,"crossMatching":false,"runnersVoidable":false,"numberOfActiveRunners":2,"betDelay":0,"status":"OPEN","runners":[{"status":"ACTIVE","sortPriority":1,"id":4423910,"name":"Matthew Ebden"},{"status":"ACTIVE","sortPriority":2,"id":2258415,"name":"Lukas Rosol"}],"regulators":["MR_INT"],"countryCode":"IN","discountAllowed":false,"timezone":"UTC","openDate":"2020-02-02T04:00:00.000Z","version":3145381988,"name":"Match Odds","eventName":"Ebden v Rosol"}}]}
{"op":"mcm","clk":"994280889","pt":1580566032994,"mc":[{"id":"1.168215937","marketDefinition":{"bspMarket":false,"turnInPlayEnabled":true,"persistenceEnabled":true,"marketBaseRate":5.0,"eventId":"29681228","eventTypeId":"2","numberOfWinners":1,"bettingType":"ODDS","marketType":"MATCH_ODDS","marketTime":"2020-02-02T04:00:00.000Z","suspendTime":"2020-02-02T04:00:00.000Z","bspReconciled":false,"complete":true,"inPlay":false,"crossMatching":false,"runnersVoidable":false,"numberOfActiveRunners":2,"betDelay":0,"status":"OPEN","runners":[{"status":"ACTIVE","sortPriority":1,"id":4423910,"name":"Matthew Ebden"},{"status":"ACTIVE","sortPriority":2,"id":2258415,"name":"Lukas Rosol"}],"regulators":["MR_INT"],"countryCode":"IN","discountAllowed":true,"timezone":"UTC","openDate":"2020-02-02T04:00:00.000Z","version":3145381988,"name":"Match Odds","eventName":"Ebden v Rosol"}}]}
{"op":"mcm","clk":"994283911","pt":1580566044998,"mc":[{"id":"1.168215937","marketDefinition":{"bspMarket":false,"turnInPlayEnabled":true,"persistenceEnabled":true,"marketBaseRate":5.0,"eventId":"29681228","eventTypeId":"2","numberOfWinners":1,"bettingType":"ODDS","marketType":"MATCH_ODDS","marketTime":"2020-02-02T04:00:00.000Z","suspendTime":"2020-02-02T04:00:00.000Z","bspReconciled":false,"complete":true,"inPlay":false,"crossMatching":true,"runnersVoidable":false,"numberOfActiveRunners":2,"betDelay":0,"status":"OPEN","runners":[{"status":"ACTIVE","sortPriority":1,"id":4423910,"name":"Matthew Ebden"},{"status":"ACTIVE","sortPriority":2,"id":2258415,"name":"Lukas Rosol"}],"regulators":["MR_INT"],"countryCode":"IN","discountAllowed":true,"timezone":"UTC","openDate":"2020-02-02T04:00:00.000Z","version":3145381988,"name":"Match Odds","eventName":"Ebden v Rosol"}}]}
{"op":"mcm","clk":"994284877","pt":1580566048642,"mc":[{"id":"1.168215937","rc":[{"batb":[[1,1.01,4432.68]],"ltp":0.0,"tv":0.0,"id":4423910}]}]}
{"op":"mcm","clk":"994285849","pt":1580566052458,"mc":[{"id":"1.168215937","rc":[{"batb":[[1,1.01,4132.68]],"ltp":0.0,"tv":0.0,"id":4423910}]}]}
{"op":"mcm","clk":"994321654","pt":1580566191294,"mc":[{"id":"1.168215937","rc":[{"batb":[[0,1.09,75.72],[1,1.02,3786.16],[2,1.01,4132.68]],"ltp":0.0,"tv":0.0,"id":4423910},{"batb":[[0,1.09,75.72],[1,1.05,152.2],[2,1.04,168.86]],"ltp":0.0,"tv":0.0,"id":2258415}]}]}
{"op":"mcm","clk":"994366936","pt":1580566356346,"mc":[{"id":"1.168215937","rc":[{"batl":[[0,990,2.2]],"ltp":0.0,"tv":0.0,"id":4423910},{"batl":[[0,990,2.2]],"ltp":0.0,"tv":0.0,"id":2258415}]}]}
{"op":"mcm","clk":"994413113","pt":1580566512387,"mc":[{"id":"1.168215937","rc":[{"batb":[[2,1.01,4112.68]],"ltp":0.0,"tv":0.0,"id":4423910}]}]}
{"op":"mcm","clk":"994665394","pt":1580567442352,"mc":[{"id":"1.168215937","marketDefinition":{"bspMarket":false,"turnInPlayEnabled":true,"persistenceEnabled":true,"marketBaseRate":5.0,"eventId":"29681228","eventTypeId":"2","numberOfWinners":1,"bettingType":"ODDS","marketType":"MATCH_ODDS","marketTime":"2020-02-02T09:30:00.000Z","suspendTime":"2020-02-02T09:30:00.000Z","bspReconciled":false,"complete":true,"inPlay":false,"crossMatching":true,"runnersVoidable":false,"numberOfActiveRunners":2,"betDelay":0,"status":"OPEN","runners":[{"status":"ACTIVE","sortPriority":1,"id":4423910,"name":"Matthew Ebden"},{"status":"ACTIVE","sortPriority":2,"id":2258415,"name":"Lukas Rosol"}],"regulators":["MR_INT"],"countryCode":"IN","discountAllowed":true,"timezone":"UTC","openDate":"2020-02-02T04:00:00.000Z","version":3145478871,"name":"Match Odds","eventName":"Ebden v Rosol"}}]}
{"op":"mcm","clk":"994666152","pt":1580567445352,"mc":[{"id":"1.168215937","marketDefinition":{"bspMarket":false,"turnInPlayEnabled":true,"persistenceEnabled":true,"marketBaseRate":5.0,"eventId":"29681228","eventTypeId":"2","numberOfWinners":1,"bettingType":"ODDS","marketType":"MATCH_ODDS","marketTime":"2020-02-02T09:30:00.000Z","suspendTime":"2020-02-02T09:30:00.000Z","bspReconciled":false,"complete":true,"inPlay":false,"crossMatching":true,"runnersVoidable":false,"numberOfActiveRunners":2,"betDelay":0,"status":"OPEN","runners":[{"status":"ACTIVE","sortPriority":1,"id":4423910,"name":"Matthew Ebden"},{"status":"ACTIVE","sortPriority":2,"id":2258415,"name":"Lukas Rosol"}],"regulators":["MR_INT"],"countryCode":"IN","discountAllowed":true,"timezone":"UTC","openDate":"2020-02-02T09:30:00.000Z","version":3145478871,"name":"Match Odds","eventName":"Ebden v Rosol"}}]}
{"op":"mcm","clk":"994907634","pt":1580568342810,"mc":[{"id":"1.168215937","rc":[{"batb":[[1,1.03,8.4],[2,1.02,3811.36]],"ltp":0.0,"tv":0.0,"id":4423910}]}]}
{"op":"mcm","clk":"996226154","pt":1580573975278,"mc":[{"id":"1.168215937","rc":[{"batl":[[0,1.8,58.81],[1,990,2.2]],"ltp":0.0,"tv":0.0,"id":2258415}]}]}
{"op":"mcm","clk":"996723345","pt":1580576334750,"mc":[{"id":"1.168215937","rc":[{"batb":[[0,1.1,15.12],[1,1.09,75.72],[2,1.03,8.4]],"ltp":0.0,"tv":0.0,"id":4423910}]}]}
{"op":"mcm","clk":"996723401","pt":1580576335126,"mc":[{"id":"1.168215937","rc":[{"batl":[[0,15,3.36],[1,990,2.2]],"ltp":0.0,"tv":0.0,"id":4423910},{"batb":[[0,1.1,15.12],[1,1.09,75.72],[2,1.05,152.2]],"ltp":0.0,"tv":0.0,"id":2258415}]}]}
{"op":"mcm","clk":"996771398","pt":1580576658099,"mc":[{"id":"1.168215937","rc":[{"batb":[[0,1.47,54.67],[1,1.1,15.12],[2,1.09,75.72]],"batl":[[0,1.79,39.26],[1,1.8,58.81],[2,990,2.2]],"ltp":0.0,"tv":0.0,"id":2258415}]}]}
{"op":"mcm","clk":"996771627","pt":1580576659395,"mc":[{"id":"1.168215937","rc":[{"batb":[[0,1.1,15.12],[1,1.09,75.72],[2,1.05,152.2]],"batl":[[0,1.8,58.81],[1,990,2.2],[2,990,0]],"ltp":0.0,"tv":0.0,"id":2258415}]}]}
{"op":"mcm","clk":"996772268","pt":1580576662994,"mc":[{"id":"1.168215937","rc":[{"batb":[[0,1.51,29.81],[1,1.1,15.12],[2,1.09,75.72]],"ltp":0.0,"tv":0.0,"id":2258415}]}]}
{"op":"mcm","clk":"996778483","pt":1580576700735,"mc":[{"id":"1.168215937","rc":[{"batb":[[1,1.09,75.72],[2,1.05,152.2]],"ltp":0.0,"tv":0.0,"id":2258415}]}]}
{"op":"mcm","clk":"996793432","pt":1580576795855,"mc":[{"id":"1.168215937","rc":[{"batb":[[0,1.8,35.59],[1,1.1,15.12],[2,1.09,75.72]],"ltp":0.0,"tv":0.0,"id":4423910},{"batb":[[0,1.53,35.59]],"ltp":0.0,"tv":0.0,"id":2258415}]}]}
{"op":"mcm","clk":"996793465","pt":1580576796051,"mc":[{"id":"1.168215937","rc":[{"batb":[[0,1.71,26.19],[1,1.53,35.59],[2,1.09,75.72]],"ltp":0.0,"tv":0.0,"id":2258415}]}]}
{"op":"mcm","clk":"996797635","pt":1580576821845,"mc":[{"id":"1.168215937","rc":[{"batb":[[1,1.09,75.72],[2,1.03,8.4]],"ltp":0.0,"tv":0.0,"id":4423910}]}]}
{"op":"mcm","clk":"996802256","pt":1580576851684,"mc":[{"id":"1.168215937","rc":[{"batb":[[0,1.94,35.59]],"ltp":0.0,"tv":0.0,"id":4423910},{"batb":[[1,1.63,35.59]],"ltp":0.0,"tv":0.0,"id":2258415}]}]}
{"op":"mcm","clk":"996807717","pt":1580576888712,"mc":[{"id":"1.168215937","rc":[{"batb":[[0,1.09,75.72],[1,1.03,8.4],[2,1.02,3811.36]],"ltp":0.0,"tv":0.0,"id":4423910}]}]}
{"op":"mcm","clk":"996807760","pt":1580576889085,"mc":[{"id":"1.168215937","rc":[{"batb":[[0,1.94,46.95],[1,1.09,75.72],[2,1.03,8.4]],"ltp":0.0,"tv":0.0,"id":4423910}]}]}
{"op":"mcm","clk":"996821458","pt":1580576979197,"mc":[{"id":"1.168215937","rc":[{"batb":[[1,1.64,35.59]],"ltp":0.0,"tv":0.0,"id":2258415}]}]}
{"op":"mcm","clk":"996853826","pt":1580577181117,"mc":[{"id":"1.168215937","rc":[{"batb":[[1,1.7,35.59]],"ltp":0.0,"tv":0.0,"id":2258415}]}]}
{"op":"mcm","clk":"996868546","pt":1580577279810,"mc":[{"id":"1.168215937","rc":[{"batb":[[0,1.7,35.59],[1,1.09,75.72],[2,1.05,152.2]],"ltp":0.0,"tv":0.0,"id":2258415}]}]}
{"op":"mcm","clk":"996868612","pt":1580577280227,"mc":[{"id":"1.168215937","rc":[{"batb":[[0,1.72,40.84],[1,1.7,35.59],[2,1.09,75.72]],"ltp":0.0,"tv":0.0,"id":2258415}]}]}
{"op":"mcm","clk":"997290402","pt":1580580059333,"mc":[{"id":"1.168215937","rc":[{"batb":[[0,1.97,46.95]],"ltp":0.0,"tv":0.0,"id":4423910},{"batb":[[1,1.69,35.59]],"ltp":0.0,"tv":0.0,"id":2258415}]}]}
{"op":"mcm","clk":"997350749","pt":1580580418622,"mc":[{"id":"1.168215937","rc":[{"batb":[[0,1.72,61.59]],"ltp":0.0,"tv":0.0,"id":2258415}]}]}
{"op":"mcm","clk":"997434976","pt":1580580882900,"mc":[{"id":"1.168215937","rc":[{"batb":[[0,1.69,35.59],[1,1.09,75.72],[2,1.05,152.2]],"ltp":0.0,"tv":0.0,"id":2258415}]}]}
{"op":"mcm","clk":"997435011","pt":1580580883064,"mc":[{"id":"1.168215937","rc":[{"batb":[[0,1.73,61.65],[1,1.69,35.59],[2,1.09,75.72]],"ltp":0.0,"tv":0.0,"id":2258415}]}]}
{"op":"mcm","clk":"997741182","pt":1580582598080,"mc":[{"id":"1.168215937","rc":[{"batb":[[1,1.88,32.7],[2,1.09,75.72]],"ltp":0.0,"tv":0.0,"id":4423910},{"batb":[[2,1.64,44.96]],"ltp":0.0,"tv":0.0,"id":2258415}]}]}
{"op":"mcm","clk":"997852249","pt":1580583389365,"mc":[{"id":"1.168215937","rc":[{"batb":[[1,1.69,53.76]],"ltp":0.0,"tv":0.0,"id":2258415}]}]}
{"op":"mcm","clk":"997924649","pt":1580583915618,"mc":[{"id":"1.168215937","rc":[{"batb":[[0,1.73,81.76]],"ltp":0.0,"tv":0.0,"id":2258415}]}]}
{"op":"mcm","clk":"997924744","pt":1580583916260,"mc":[{"id":"1.168215937","rc":[{"batb":[[1,1.09,75.72],[2,1.03,8.4]],"ltp":0.0,"tv":0.0,"id":4423910},{"batb":[[2,1.09,75.72]],"ltp":0.0,"tv":0.0,"id":2258415}]}]}
{"op":"mcm","clk":"997924843","pt":1580583916965,"mc":[{"id":"1.168215937","rc":[{"batb":[[1,1.88,43.03],[2,1.09,75.72]],"ltp":0.0,"tv":0.0,"id":4423910},{"batb":[[2,1.64,59.16]],"ltp":0.0,"tv":0.0,"id":2258415}]}]}
{"op":"mcm","clk":"998020105","pt":1580584483672,"mc":[{"id":"1.168215937","rc":[{"batb":[[0,1.69,53.76],[1,1.64,59.16],[2,1.09,75.72]],"ltp":0.0,"tv":0.0,"id":2258415}]}]}
{"op":"mcm","clk":"998020174","pt":1580584483976,"mc":[{"id":"1.168215937","rc":[{"batb":[[0,1.74,81.52],[1,1.69,53.76],[2,1.64,59.16]],"ltp":0.0,"tv":0.0,"id":2258415}]}]}
{"op":"mcm","clk":"998156870","pt":1580585286508,"mc":[{"id":"1.168215937","rc":[{"batl":[[1,95,15.9],[2,990,2.2]],"ltp":0.0,"tv":0.0,"id":4423910},{"batl":[[1,95,15.9],[2,990,2.2]],"ltp":0.0,"tv":0.0,"id":2258415}]}]}
{"op":"mcm","clk":"998529399","pt":1580587707521,"mc":[{"id":"1.168215937","rc":[{"batb":[[0,1.74,101.52]],"ltp":0.0,"tv":0.0,"id":2258415}]}]}
{"op":"mcm","clk":"998529557","pt":1580587708609,"mc":[{"id":"1.168215937","rc":[{"batb":[[1,1.09,75.72],[2,1.03,8.4]],"ltp":0.0,"tv":0.0,"id":4423910},{"batb":[[2,1.09,75.72]],"ltp":0.0,"tv":0.0,"id":2258415}]}]}
{"op":"mcm","clk":"998529658","pt":1580587709198,"mc":[{"id":"1.168215937","rc":[{"batb":[[1,1.88,54.21],[2,1.09,75.72]],"ltp":0.0,"tv":0.0,"id":4423910},{"batb":[[2,1.64,74.54]],"ltp":0.0,"tv":0.0,"id":2258415}]}]}
{"op":"mcm","clk":"998587301","pt":1580588084573,"mc":[{"id":"1.168215937","rc":[{"batb":[[0,1.74,102.02]],"ltp":0.0,"tv":0.0,"id":2258415}]}]}
{"op":"mcm","clk":"998914978","pt":1580590498598,"mc":[{"id":"1.168215937","rc":[{"batb":[[0,1.69,53.76],[1,1.64,74.54],[2,1.09,75.72]],"ltp":0.0,"tv":0.0,"id":2258415}]}]}
{"op":"mcm","clk":"998915057","pt":1580590499315,"mc":[{"id":"1.168215937","rc":[{"batb":[[0,1.74,102.02],[1,1.69,53.76],[2,1.64,74.54]],"ltp":0.0,"tv":0.0,"id":2258415}]}]}
{"op":"mcm","clk":"998919376","pt":1580590536782,"mc":[{"id":"1.168215937","rc":[{"batb":[[0,1.74,183.02]],"ltp":0.0,"tv":0.0,"id":2258415}]}]}
{"op":"mcm","clk":"998919588","pt":1580590538502,"mc":[{"id":"1.168215937","rc":[{"batb":[[1,1.09,75.72],[2,1.03,8.4]],"ltp":0.0,"tv":0.0,"id":4423910},{"batb":[[2,1.09,75.72]],"ltp":0.0,"tv":0.0,"id":2258415}]}]}
{"op":"mcm","clk":"998919671","pt":1580590539186,"mc":[{"id":"1.168215937","rc":[{"batb":[[1,1.91,94.03],[2,1.09,75.72]],"ltp":0.0,"tv":0.0,"id":4423910},{"batb":[[2,1.66,129.65]],"ltp":0.0,"tv":0.0,"id":2258415}]}]}
{"op":"mcm","clk":"999036977","pt":1580591578107,"mc":[{"id":"1.168215937","rc":[{"trd":[[1.8,84.02]],"batl":[[0,1.8,16.8]],"ltp":1.8,"tv":84.01,"id":2258415}],"tv":84.01}]}
{"op":"mcm","clk":"999112671","pt":1580592179876,"mc":[{"id":"1.168215937","rc":[{"batb":[[0,2.1,76.01],[1,1.97,46.95],[2,1.91,94.03]],"ltp":0.0,"tv":0.0,"id":4423910},{"trd":[[1.8,117.63]],"batb":[[0,1.75,91.39],[1,1.74,183.02],[2,1.69,53.76]],"batl":[[0,95,15.9],[1,990,2.2],[2,990,0]],"ltp":1.8,"tv":117.62,"id":2258415}],"tv":117.62}]}
{"op":"mcm","clk":"999117629","pt":1580592219210,"mc":[{"id":"1.168215937","rc":[{"batl":[[0,11.5,3.36],[1,95,15.9],[2,990,2.2]],"ltp":1.8,"tv":117.62,"id":2258415}]}]}
{"op":"mcm","clk":"999180691","pt":1580592731962,"mc":[{"id":"1.168215937","rc":[{"batb":[[1,1.69,53.76],[2,1.66,129.65]],"ltp":1.8,"tv":117.62,"id":2258415}]}]}
{"op":"mcm","clk":"999180874","pt":1580592733544,"mc":[{"id":"1.168215937","rc":[{"batb":[[2,1.94,125.67]],"ltp":0.0,"tv":0.0,"id":4423910},{"batb":[[2,1.68,173.72]],"ltp":1.8,"tv":117.62,"id":2258415}]}]}
{"op":"mcm","clk":"999285217","pt":1580593659801,"mc":[{"id":"1.168215937","rc":[{"batb":[[0,2.1,74.37]],"ltp":0.0,"tv":0.0,"id":4423910},{"batb":[[0,1.75,93.36]],"ltp":1.8,"tv":117.62,"id":2258415}]}]}
{"op":"mcm","clk":"999334182","pt":1580594158884,"mc":[{"id":"1.168215937","rc":[{"batb":[[0,1.76,6.8],[1,1.75,93.36],[2,1.69,53.76]],"ltp":1.8,"tv":117.62,"id":2258415}]}]}
{"op":"mcm","clk":"999343990","pt":1580594248250,"mc":[{"id":"1.168215937","rc":[{"trd":[[1.76,33.61]],"batb":[[0,1.75,93.36],[1,1.69,53.76],[2,1.68,173.72]],"ltp":1.76,"tv":151.24,"id":2258415}],"tv":151.24}]}
{"op":"mcm","clk":"999427442","pt":1580595184480,"mc":[{"id":"1.168215937","rc":[{"batb":[[0,1.76,243.73],[1,1.75,93.36],[2,1.69,53.76]],"ltp":1.76,"tv":151.24,"id":2258415}]}]}
{"op":"mcm","clk":"999427577","pt":1580595185947,"mc":[{"id":"1.168215937","rc":[{"batb":[[2,1.88,134.23]],"ltp":0.0,"tv":0.0,"id":4423910},{"batb":[[2,1.72,164.07]],"ltp":1.76,"tv":151.24,"id":2258415}]}]}
{"op":"mcm","clk":"999427632","pt":1580595186686,"mc":[{"id":"1.168215937","rc":[{"batb":[[1,1.88,134.23],[2,1.81,37.86]],"ltp":0.0,"tv":0.0,"id":4423910}]}]}
{"op":"mcm","clk":"999427679","pt":1580595187155,"mc":[{"id":"1.168215937","rc":[{"batb":[[1,1.75,147.13]],"ltp":1.76,"tv":151.24,"id":2258415}]}]}
{"op":"mcm","clk":"999428457","pt":1580595195425,"mc":[{"id":"1.168215937","rc":[{"batb":[[1,1.9,47.71],[2,1.88,134.23]],"ltp":0.0,"tv":0.0,"id":4423910},{"batb":[[1,1.75,93.36],[2,1.74,53.76]],"ltp":1.76,"tv":151.24,"id":2258415}]}]}
{"op":"mcm","clk":"999429659","pt":1580595209328,"mc":[{"id":"1.168215937","rc":[{"batb":[[0,1.78,240.98],[1,1.77,67.77]],"ltp":1.76,"tv":151.24,"id":2258415}]}]}
{"op":"mcm","clk":"999440807","pt":1580595342960,"mc":[{"id":"1.168215937","rc":[{"batb":[[0,1.79,282.79],[1,1.74,53.76],[2,1.72,164.07]],"ltp":1.76,"tv":151.24,"id":2258415}]}]}
{"op":"mcm","clk":"999530062","pt":1580596553847,"mc":[{"id":"1.168215937","rc":[{"batb":[[0,1.8,420.1],[1,1.79,43.24],[2,1.74,53.76]],"ltp":1.76,"tv":151.24,"id":2258415}]}]}
{"op":"mcm","clk":"999530184","pt":1580596555766,"mc":[{"id":"1.168215937","rc":[{"batb":[[0,1.81,19.74],[1,1.8,420.1],[2,1.79,420.1]],"ltp":1.76,"tv":151.24,"id":2258415}]}]}
{"op":"mcm","clk":"999530357","pt":1580596558148,"mc":[{"id":"1.168215937","rc":[{"batb":[[0,1.81,439.83]],"ltp":1.76,"tv":151.24,"id":2258415}]}]}
{"op":"mcm","clk":"999563287","pt":1580597020503,"mc":[{"id":"1.168215937","rc":[{"batb":[[0,1.82,230.14],[1,1.81,439.83],[2,1.8,420.1]],"ltp":1.76,"tv":151.24,"id":2258415}]}]}
{"op":"mcm","clk":"999563349","pt":1580597021496,"mc":[{"id":"1.168215937","rc":[{"batb":[[2,1.81,37.86]],"ltp":0.0,"tv":0.0,"id":4423910}]}]}
{"op":"mcm","clk":"999563438","pt":1580597022945,"mc":[{"id":"1.168215937","rc":[{"batb":[[1,1.86,137.36]],"ltp":0.0,"tv":0.0,"id":4423910}]}]}
{"op":"mcm","clk":"999563837","pt":1580597029331,"mc":[{"id":"1.168215937","rc":[{"batb":[[1,1.87,48.46],[2,1.86,137.36]],"ltp":0.0,"tv":0.0,"id":4423910}]}]}
{"op":"mcm","clk":"999568338","pt":1580597095648,"mc":[{"id":"1.168215937","rc":[{"batb":[[0,2.08,71.21]],"ltp":0.0,"tv":0.0,"id":4423910},{"batb":[[0,1.83,18.51],[1,1.82,230.14],[2,1.81,420.1]],"ltp":1.76,"tv":151.24,"id":2258415}]}]}
{"op":"mcm","clk":"999577539","pt":1580597229379,"mc":[{"id":"1.168215937","rc":[{"batb":[[1,1.81,420.1],[2,1.8,420.1]],"ltp":1.76,"tv":151.24,"id":2258415}]}]}
{"op":"mcm","clk":"999577863","pt":1580597233911,"mc":[{"id":"1.168215937","rc":[{"trd":[[2.08,33.61]],"batb":[[0,1.87,48.46],[1,1.86,137.36],[2,1.81,37.86]],"ltp":2.08,"tv":33.6,"id":4423910}],"tv":184.84}]}
{"op":"mcm","clk":"999577875","pt":1580597234012,"mc":[{"id":"1.168215937","rc":[{"batb":[[0,2.06,70.22],[1,1.87,48.46],[2,1.86,137.36]],"ltp":2.08,"tv":33.6,"id":4423910},{"batb":[[0,1.83,37.47]],"ltp":1.76,"tv":151.24,"id":2258415}]}]}
{"op":"mcm","clk":"999586015","pt":1580597360784,"mc":[{"id":"1.168215937","rc":[{"batb":[[0,1.82,278.9]],"ltp":1.76,"tv":151.24,"id":2258415}]}]}
{"op":"mcm","clk":"999620088","pt":1580597931870,"mc":[{"id":"1.168215937","rc":[{"trd":[[2.06,132.47]],"batb":[[0,1.97,79.74]],"ltp":2.06,"tv":166.07,"id":4423910},{"batb":[[0,1.85,88.35]],"ltp":1.76,"tv":151.24,"id":2258415}],"tv":317.31}]}
{"op":"mcm","clk":"999620187","pt":1580597933571,"mc":[{"id":"1.168215937","rc":[{"batb":[[2,1.81,37.86]],"ltp":2.06,"tv":166.07,"id":4423910}]}]}
{"op":"mcm","clk":"999620268","pt":1580597934958,"mc":[{"id":"1.168215937","rc":[{"batb":[[1,1.81,37.86],[2,1.73,161.82]],"ltp":2.06,"tv":166.07,"id":4423910},{"batb":[[0,1.88,134.23],[1,1.85,88.35],[2,1.81,420.1]],"ltp":1.76,"tv":151.24,"id":2258415}]}]}
{"op":"mcm","clk":"999620470","pt":1580597938494,"mc":[{"id":"1.168215937","rc":[{"batb":[[2,1.71,37.86]],"ltp":2.06,"tv":166.07,"id":4423910},{"batb":[[0,1.85,88.35],[1,1.81,420.1],[2,1.8,420.1]],"ltp":1.76,"tv":151.24,"id":2258415}]}]}
{"op":"mcm","clk":"999620502","pt":1580597939060,"mc":[{"id":"1.168215937","rc":[{"batb":[[2,1.75,157.5]],"ltp":2.06,"tv":166.07,"id":4423910},{"batb":[[0,1.87,135.78],[1,1.85,88.35],[2,1.81,420.1]],"ltp":1.76,"tv":151.24,"id":2258415}]}]}
{"op":"mcm","clk":"999620860","pt":1580597944858,"mc":[{"id":"1.168215937","rc":[{"batb":[[2,1.75,209]],"ltp":2.06,"tv":166.07,"id":4423910}]}]}
{"op":"mcm","clk":"999620869","pt":1580597945062,"mc":[{"id":"1.168215937","rc":[{"batb":[[0,1.9,205.16],[1,1.87,135.78],[2,1.85,88.35]],"ltp":1.76,"tv":151.24,"id":2258415}]}]}
{"op":"mcm","clk":"999621288","pt":1580597950901,"mc":[{"id":"1.168215937","rc":[{"trd":[[1.97,51.22]],"batb":[[0,1.97,54.13]],"ltp":1.97,"tv":217.29,"id":4423910}],"tv":368.53}]}
{"op":"mcm","clk":"999621362","pt":1580597951892,"mc":[{"id":"1.168215937","rc":[{"batb":[[0,1.87,88.56]],"ltp":1.97,"tv":217.29,"id":4423910},{"batb":[[0,1.95,77.42],[1,1.9,205.16],[2,1.87,135.78]],"ltp":1.76,"tv":151.24,"id":2258415}]}]}
{"op":"mcm","clk":"999622373","pt":1580597969805,"mc":[{"id":"1.168215937","rc":[{"batb":[[1,1.87,135.78],[2,1.81,457.96]],"ltp":1.76,"tv":151.24,"id":2258415}]}]}
{"op":"mcm","clk":"999622391","pt":1580597970118,"mc":[{"id":"1.168215937","rc":[{"batb":[[1,1.9,45.96],[2,1.87,135.78]],"ltp":1.76,"tv":151.24,"id":2258415}]}]}
{"op":"mcm","clk":"999622443","pt":1580597970994,"mc":[{"id":"1.168215937","rc":[{"batb":[[0,1.98,194.83],[1,1.87,88.56],[2,1.81,37.86]],"ltp":1.97,"tv":217.29,"id":4423910}]}]}
{"op":"mcm","clk":"999622572","pt":1580597973502,"mc":[{"id":"1.168215937","rc":[{"batb":[[1,1.93,51.49],[2,1.87,88.56]],"ltp":1.97,"tv":217.29,"id":4423910},{"batb":[[2,1.81,457.96]],"ltp":1.76,"tv":151.24,"id":2258415}]}]}
{"op":"mcm","clk":"999622594","pt":1580597974126,"mc":[{"id":"1.168215937","rc":[{"batb":[[2,1.9,131.25]],"ltp":1.97,"tv":217.29,"id":4423910}]}]}
{"op":"mcm","clk":"999622925","pt":1580597979516,"mc":[{"id":"1.168215937","rc":[{"batb":[[0,1.93,51.49],[1,1.9,131.25],[2,1.87,88.56]],"ltp":1.97,"tv":217.29,"id":4423910}]}]}
{"op":"mcm","clk":"999623070","pt":1580597981741,"mc":[{"id":"1.168215937","rc":[{"batb":[[1,1.88,134.23]],"ltp":1.97,"tv":217.29,"id":4423910}]}]}
{"op":"mcm","clk":"999623144","pt":1580597982736,"mc":[{"id":"1.168215937","rc":[{"batb":[[0,1.91,51.49]],"ltp":1.97,"tv":217.29,"id":4423910}]}]}
{"op":"mcm","clk":"999623237","pt":1580597983558,"mc":[{"id":"1.168215937","rc":[{"batb":[[0,1.88,134.23],[1,1.87,88.56],[2,1.81,37.86]],"ltp":1.97,"tv":217.29,"id":4423910}]}]}
{"op":"mcm","clk":"999623786","pt":1580597993550,"mc":[{"id":"1.168215937","rc":[{"batb":[[0,1.89,48.46],[1,1.88,134.23],[2,1.87,88.56]],"ltp":1.97,"tv":217.29,"id":4423910}]}]}
{"op":"mcm","clk":"999626379","pt":1580598032919,"mc":[{"id":"1.168215937","rc":[{"batb":[[0,1.9,57.75],[1,1.89,48.46],[2,1.88,134.23]],"ltp":1.97,"tv":217.29,"id":4423910},{"batb":[[1,1.81,457.96],[2,1.8,420.1]],"ltp":1.76,"tv":151.24,"id":2258415}]}]}
{"op":"mcm","clk":"999626385","pt":1580598033023,"mc":[{"id":"1.168215937","rc":[{"batb":[[1,1.9,56.86],[2,1.81,457.96]],"ltp":1.76,"tv":151.24,"id":2258415}]}]}
{"op":"mcm","clk":"999628749","pt":1580598070813,"mc":[{"id":"1.168215937","rc":[{"batb":[[0,1.97,83.2]],"ltp":1.97,"tv":217.29,"id":4423910},{"trd":[[1.9,113.72],[1.95,154.85]],"batb":[[0,1.85,84.67],[1,1.81,457.96],[2,1.8,420.1]],"ltp":1.9,"tv":419.8,"id":2258415}],"tv":637.09}]}
{"op":"mcm","clk":"999628829","pt":1580598071703,"mc":[{"id":"1.168215937","rc":[{"batb":[[0,1.98,195.89],[1,1.97,83.2],[2,1.89,48.46]],"ltp":1.97,"tv":217.29,"id":4423910},{"trd":[[1.85,169.35]],"batb":[[0,1.81,457.96],[1,1.8,420.1],[2,1.79,420.1]],"ltp":1.85,"tv":589.15,"id":2258415}],"tv":806.44}]}
{"op":"mcm","clk":"999628864","pt":1580598072317,"mc":[{"id":"1.168215937","rc":[{"batb":[[0,2.08,76.3],[1,1.98,195.89],[2,1.91,129.81]],"ltp":1.97,"tv":217.29,"id":4423910},{"batb":[[0,1.82,23.81],[1,1.81,457.96],[2,1.8,420.1]],"ltp":1.85,"tv":589.15,"id":2258415}]}]}
{"op":"mcm","clk":"999629141","pt":1580598076309,"mc":[{"id":"1.168215937","rc":[{"batb":[[2,1.94,48.46]],"ltp":1.97,"tv":217.29,"id":4423910}]}]}
{"op":"mcm","clk":"999629714","pt":1580598085848,"mc":[{"id":"1.168215937","rc":[{"batb":[[1,1.92,48.46],[2,1.91,129.81]],"ltp":1.97,"tv":217.29,"id":4423910}]}]}
{"op":"mcm","clk":"999630222","pt":1580598093886,"mc":[{"id":"1.168215937","rc":[{"batb":[[0,1.97,78.42],[1,1.81,37.86],[2,1.78,151.45]],"ltp":1.97,"tv":217.29,"id":4423910},{"batb":[[0,1.85,89.77],[1,1.83,142.32],[2,1.81,457.96]],"ltp":1.85,"tv":589.15,"id":2258415}]}]}
{"op":"mcm","clk":"999630261","pt":1580598094665,"mc":[{"id":"1.168215937","rc":[{"trd":[[2.18,4]],"batb":[[0,1.97,87.09]],"batl":[[0,2.18,6.4],[1,15,3.36],[2,95,15.9]],"ltp":2.18,"tv":221.29,"id":4423910},{"batb":[[0,1.86,9.77],[1,1.85,89.77],[2,1.83,142.32]],"batl":[[0,2.04,8.4],[1,11.5,3.36],[2,95,15.9]],"ltp":1.85,"tv":589.15,"id":2258415}],"tv":810.44}]}
{"op":"mcm","clk":"999630319","pt":1580598095708,"mc":[{"id":"1.168215937","rc":[{"batb":[[2,1.79,50.73]],"ltp":2.18,"tv":221.29,"id":4423910},{"batb":[[2,1.81,457.96]],"ltp":1.85,"tv":589.15,"id":2258415}]}]}
{"op":"mcm","clk":"999630339","pt":1580598096056,"mc":[{"id":"1.168215937","rc":[{"batb":[[2,1.8,147.66]],"ltp":2.18,"tv":221.29,"id":4423910},{"batb":[[2,1.81,603.79]],"ltp":1.85,"tv":589.15,"id":2258415}]}]}
{"op":"mcm","clk":"999630472","pt":1580598098177,"mc":[{"id":"1.168215937","rc":[{"batb":[[1,1.83,50.73],[2,1.81,37.86]],"ltp":2.18,"tv":221.29,"id":4423910}]}]}
{"op":"mcm","clk":"999630932","pt":1580598105807,"mc":[{"id":"1.168215937","rc":[{"batb":[[1,1.81,88.6],[2,1.8,147.66]],"ltp":2.18,"tv":221.29,"id":4423910},{"batb":[[0,1.87,215.81],[1,1.86,9.77],[2,1.85,89.77]],"ltp":1.85,"tv":589.15,"id":2258415}]}]}
{"op":"mcm","clk":"999631168","pt":1580598109788,"mc":[{"id":"1.168215937","rc":[{"batb":[[0,1.86,9.77],[1,1.85,89.77],[2,1.81,603.79]],"ltp":1.85,"tv":589.15,"id":2258415}]}]}
{"op":"mcm","clk":"999631344","pt":1580598112627,"mc":[{"id":"1.168215937","rc":[{"batb":[[1,1.83,142.32],[2,1.81,88.6]],"ltp":2.18,"tv":221.29,"id":4423910},{"batb":[[2,1.81,457.96]],"ltp":1.85,"tv":589.15,"id":2258415}]}]}
{"op":"mcm","clk":"999631482","pt":1580598114804,"mc":[{"id":"1.168215937","rc":[{"batb":[[1,1.88,50.73],[2,1.85,138.97]],"ltp":2.18,"tv":221.29,"id":4423910}]}]}
{"op":"mcm","clk":"999631567","pt":1580598116512,"mc":[{"id":"1.168215937","rc":[{"batb":[[1,1.86,50.73]],"ltp":2.18,"tv":221.29,"id":4423910}]}]}
{"op":"mcm","clk":"999631983","pt":1580598123434,"mc":[{"id":"1.168215937","rc":[{"batl":[[1,95,15.9],[2,990,2.2]],"ltp":2.18,"tv":221.29,"id":4423910},{"batl":[[1,95,15.9],[2,990,2.2]],"ltp":1.85,"tv":589.15,"id":2258415}]}]}
{"op":"mcm","clk":"999634907","pt":1580598166958,"mc":[{"id":"1.168215937","rc":[{"batb":[[0,1.87,68.32],[1,1.86,9.77]],"ltp":1.85,"tv":589.15,"id":2258415}]}]}
{"op":"mcm","clk":"999636655","pt":1580598187839,"mc":[{"id":"1.168215937","rc":[{"batl":[[0,95,15.9],[1,990,2.2],[2,990,0]],"ltp":2.18,"tv":221.29,"id":4423910}]}]}
{"op":"mcm","clk":"999636738","pt":1580598188924,"mc":[{"id":"1.168215937","rc":[{"batl":[[0,2.16,8.4],[1,95,15.9],[2,990,2.2]],"ltp":2.18,"tv":221.29,"id":4423910},{"batb":[[0,1.87,77.98],[1,1.81,457.96],[2,1.8,420.1]],"ltp":1.85,"tv":589.15,"id":2258415}]}]}
{"op":"mcm","clk":"999673639","pt":1580598664706,"mc":[{"id":"1.168215937","rc":[{"batb":[[0,1.98,6.04],[1,1.97,87.09],[2,1.86,50.73]],"ltp":2.18,"tv":221.29,"id":4423910},{"batb":[[1,1.82,6.78],[2,1.81,457.96]],"ltp":1.85,"tv":589.15,"id":2258415}]}]}
{"op":"mcm","clk":"999675374","pt":1580598687681,"mc":[{"id":"1.168215937","rc":[{"batb":[[1,1.97,78.42]],"ltp":2.18,"tv":221.29,"id":4423910}]}]}
{"op":"mcm","clk":"999675396","pt":1580598688092,"mc":[{"id":"1.168215937","rc":[{"batb":[[0,1.98,14.61]],"ltp":2.18,"tv":221.29,"id":4423910}]}]}
{"op":"mcm","clk":"999675781","pt":1580598692921,"mc":[{"id":"1.168215937","rc":[{"batb":[[1,1.86,50.73],[2,1.85,138.97]],"ltp":2.18,"tv":221.29,"id":4423910}]}]}
{"op":"mcm","clk":"999675812","pt":1580598693116,"mc":[{"id":"1.168215937","rc":[{"batb":[[0,1.99,60.75],[1,1.98,14.61],[2,1.86,50.73]],"ltp":2.18,"tv":221.29,"id":4423910}]}]}
{"op":"mcm","clk":"999678230","pt":1580598719787,"mc":[{"id":"1.168215937","rc":[{"batb":[[1,1.98,6.04]],"ltp":2.18,"tv":221.29,"id":4423910},{"batl":[[0,95,15.9],[1,990,2.2],[2,990,0]],"ltp":1.85,"tv":589.15,"id":2258415}]}]}
{"op":"mcm","clk":"999678295","pt":1580598720365,"mc":[{"id":"1.168215937","rc":[{"batb":[[0,1.99,69.23]],"ltp":2.18,"tv":221.29,"id":4423910},{"batl":[[0,2.02,8.4],[1,95,15.9],[2,990,2.2]],"ltp":1.85,"tv":589.15,"id":2258415}]}]}
{"op":"mcm","clk":"999844592","pt":1580601308486,"mc":[{"id":"1.168215937","rc":[{"batb":[[1,1.86,50.73],[2,1.85,138.97]],"ltp":2.18,"tv":221.29,"id":4423910}]}]}
{"op":"mcm","clk":"999844626","pt":1580601309001,"mc":[{"id":"1.168215937","rc":[{"batb":[[1,1.81,457.96],[2,1.8,420.1]],"ltp":1.85,"tv":589.15,"id":2258415}]}]}
{"op":"mcm","clk":"999969250","pt":1580603478666,"mc":[{"id":"1.168215937","rc":[{"batb":[[2,1.81,37.86]],"ltp":2.18,"tv":221.29,"id":4423910}]}]}
{"op":"mcm","clk":"999969284","pt":1580603479287,"mc":[{"id":"1.168215937","rc":[{"batb":[[1,1.87,135.78],[2,1.86,50.73]],"ltp":2.18,"tv":221.29,"id":4423910}]}]}
{"op":"mcm","clk":"999969673","pt":1580603485879,"mc":[{"id":"1.168215937","rc":[{"batb":[[1,1.88,50.73],[2,1.87,135.78]],"ltp":2.18,"tv":221.29,"id":4423910}]}]}
{"op":"mcm","clk":"999980357","pt":1580603664424,"mc":[{"id":"1.168215937","rc":[{"batb":[[2,1.81,37.86]],"ltp":2.18,"tv":221.29,"id":4423910}]}]}
{"op":"mcm","clk":"999980381","pt":1580603665042,"mc":[{"id":"1.168215937","rc":[{"batb":[[2,1.87,207.15]],"ltp":2.18,"tv":221.29,"id":4423910}]}]}
{"op":"mcm","clk":"1000131148","pt":1580607733922,"mc":[{"id":"1.168215937","rc":[{"trd":[[1.87,26.53]],"batb":[[0,1.87,64.71]],"ltp":1.87,"tv":615.68,"id":2258415}],"tv":836.97}]}
{"op":"mcm","clk":"1000131171","pt":1580607734492,"mc":[{"id":"1.168215937","rc":[{"batb":[[0,2,12.22],[1,1.99,69.23],[2,1.88,50.73]],"ltp":2.18,"tv":221.29,"id":4423910}]}]}
{"op":"mcm","clk":"1000131915","pt":1580607751641,"mc":[{"id":"1.168215937","rc":[{"batl":[[0,95,15.9],[1,990,2.2],[2,1000,0.02]],"ltp":1.87,"tv":615.68,"id":2258415}]}]}
{"op":"mcm","clk":"1000131965","pt":1580607752522,"mc":[{"id":"1.168215937","rc":[{"batb":[[0,2,20.62],[1,1.99,60.75]],"ltp":2.18,"tv":221.29,"id":4423910},{"batl":[[0,2,8.4],[1,95,15.9],[2,990,2.2]],"ltp":1.87,"tv":615.68,"id":2258415}]}]}
{"op":"mcm","clk":"1000135961","pt":1580607862689,"mc":[{"id":"1.168215937","rc":[{"batb":[[0,2.02,47.49],[1,2,20.62]],"ltp":2.18,"tv":221.29,"id":4423910}]}]}
{"op":"mcm","clk":"1000136541","pt":1580607877619,"mc":[{"id":"1.168215937","rc":[{"batl":[[0,95,15.9],[1,990,2.2],[2,1000,0.02]],"ltp":1.87,"tv":615.68,"id":2258415}]}]}
{"op":"mcm","clk":"1000136590","pt":1580607878911,"mc":[{"id":"1.168215937","rc":[{"batb":[[0,2.02,55.72],[1,2,12.22]],"ltp":2.18,"tv":221.29,"id":4423910},{"batl":[[0,1.99,8.4],[1,95,15.9],[2,990,2.2]],"ltp":1.87,"tv":615.68,"id":2258415}]}]}
{"op":"mcm","clk":"1000178081","pt":1580608932998,"mc":[{"id":"1.168215937","rc":[{"batb":[[2,1.88,255.53]],"ltp":2.18,"tv":221.29,"id":4423910}]}]}
{"op":"mcm","clk":"1000178221","pt":1580608936924,"mc":[{"id":"1.168215937","rc":[{"batb":[[2,1.89,50.73]],"ltp":2.18,"tv":221.29,"id":4423910}]}]}
{"op":"mcm","clk":"1000272573","pt":1580611153183,"mc":[{"id":"1.168215937","rc":[{"batb":[[2,1.88,255.53]],"ltp":2.18,"tv":221.29,"id":4423910}]}]}
{"op":"mcm","clk":"1000280400","pt":1580611356943,"mc":[{"id":"1.168215937","rc":[{"batb":[[2,1.88,204.79]],"ltp":2.18,"tv":221.29,"id":4423910}]}]}
{"op":"mcm","clk":"1000280407","pt":1580611357047,"mc":[{"id":"1.168215937","rc":[{"batb":[[2,1.89,50.73]],"ltp":2.18,"tv":221.29,"id":4423910}]}]}
{"op":"mcm","clk":"1000299890","pt":1580611827602,"mc":[{"id":"1.168215937","rc":[{"batb":[[0,2.02,53.79]],"ltp":2.18,"tv":221.29,"id":4423910},{"batb":[[0,1.88,2.3],[1,1.87,64.71],[2,1.81,457.96]],"ltp":1.87,"tv":615.68,"id":2258415}]}]}
{"op":"mcm","clk":"1000300558","pt":1580611841191,"mc":[{"id":"1.168215937","rc":[{"batl":[[0,95,15.9],[1,990,2.2],[2,1000,0.02]],"ltp":2.18,"tv":221.29,"id":4423910}]}]}
{"op":"mcm","clk":"1000300608","pt":1580611842728,"mc":[{"id":"1.168215937","rc":[{"batl":[[0,2.14,8.4],[1,95,15.9],[2,990,2.2]],"ltp":2.18,"tv":221.29,"id":4423910},{"batb":[[0,1.88,11.85],[1,1.87,55.06]],"ltp":1.87,"tv":615.68,"id":2258415}]}]}
{"op":"mcm","clk":"1000303152","pt":1580611901749,"mc":[{"id":"1.168215937","rc":[{"batb":[[0,1.89,36.79],[1,1.88,11.85]],"ltp":1.87,"tv":615.68,"id":2258415}]}]}
{"op":"mcm","clk":"1000303334","pt":1580611905862,"mc":[{"id":"1.168215937","rc":[{"batb":[[0,1.89,46.24],[1,1.88,2.3]],"ltp":1.87,"tv":615.68,"id":2258415}]}]}
{"op":"mcm","clk":"1000308486","pt":1580612024702,"mc":[{"id":"1.168215937","rc":[{"batb":[[0,1.89,9.44],[1,1.88,46.98]],"ltp":1.87,"tv":615.68,"id":2258415}]}]}
{"op":"mcm","clk":"1000387067","pt":1580613532324,"mc":[{"id":"1.168215937","rc":[{"batl":[[0,2.1,2.53],[1,2.14,8.4],[2,95,15.9]],"ltp":2.18,"tv":221.29,"id":4423910}]}]}
{"op":"mcm","clk":"1000388434","pt":1580613560862,"mc":[{"id":"1.168215937","rc":[{"batl":[[1,95,15.9],[2,990,2.2]],"ltp":2.18,"tv":221.29,"id":4423910},{"batb":[[0,1.88,46.98],[1,1.81,457.96],[2,1.8,420.1]],"ltp":1.87,"tv":615.68,"id":2258415}]}]}
{"op":"mcm","clk":"1000388450","pt":1580613561275,"mc":[{"id":"1.168215937","rc":[{"batl":[[0,2.1,10.93]],"ltp":2.18,"tv":221.29,"id":4423910},{"batb":[[0,1.9,9.33],[1,1.88,46.98],[2,1.81,457.96]],"ltp":1.87,"tv":615.68,"id":2258415}]}]}
{"op":"mcm","clk":"1000388526","pt":1580613562564,"mc":[{"id":"1.168215937","rc":[{"batb":[[1,1.84,89.75]],"ltp":1.87,"tv":615.68,"id":2258415}]}]}
{"op":"mcm","clk":"1000415646","pt":1580614102665,"mc":[{"id":"1.168215937","rc":[{"trd":[[1.9,118.76]],"batb":[[0,1.9,6.81]],"ltp":1.9,"tv":620.72,"id":2258415}],"tv":842.01}]}
{"op":"mcm","clk":"1000420789","pt":1580614218252,"mc":[{"id":"1.168215937","rc":[{"batb":[[2,1.89,317.05]],"ltp":2.18,"tv":221.29,"id":4423910}]}]}
{"op":"mcm","clk":"1000474366","pt":1580615110199,"mc":[{"id":"1.168215937","rc":[{"batl":[[1,990,2.2],[2,1000,0.02]],"ltp":2.18,"tv":221.29,"id":4423910},{"batl":[[1,990,2.2],[2,1000,0.02]],"ltp":1.9,"tv":620.72,"id":2258415}]}]}
{"op":"mcm","clk":"1000477122","pt":1580615146658,"mc":[{"id":"1.168215937","rc":[{"batb":[[0,2.02,51.86]],"ltp":2.18,"tv":221.29,"id":4423910},{"batb":[[1,1.85,80.84]],"ltp":1.9,"tv":620.72,"id":2258415}]}]}
{"op":"mcm","clk":"1000487628","pt":1580615300566,"mc":[{"id":"1.168215937","rc":[{"batl":[[1,95,2.27],[2,990,2.2]],"ltp":2.18,"tv":221.29,"id":4423910},{"batl":[[1,95,2.27],[2,990,2.2]],"ltp":1.9,"tv":620.72,"id":2258415}]}]}
{"op":"mcm","clk":"1000497584","pt":1580615494647,"mc":[{"id":"1.168215937","rc":[{"batl":[[1,4.1,153.72],[2,95,2.27]],"ltp":2.18,"tv":221.29,"id":4423910},{"batl":[[1,4.2,153.72],[2,95,2.27]],"ltp":1.9,"tv":620.72,"id":2258415}]}]}
{"op":"mcm","clk":"1000509874","pt":1580615787659,"mc":[{"id":"1.168215937","rc":[{"batl":[[1,4,3.03],[2,4.2,153.72]],"ltp":1.9,"tv":620.72,"id":2258415}]}]}
{"op":"mcm","clk":"1000510172","pt":1580615795030,"mc":[{"id":"1.168215937","rc":[{"batl":[[1,4,3.41]],"ltp":1.9,"tv":620.72,"id":2258415}]}]}
{"op":"mcm","clk":"1000510676","pt":1580615809344,"mc":[{"id":"1.168215937","rc":[{"batl":[[1,4.2,154.1],[2,95,2.27]],"ltp":1.9,"tv":620.72,"id":2258415}]}]}
{"op":"mcm","clk":"1000537720","pt":1580616415640,"mc":[{"id":"1.168215937","rc":[{"batl":[[1,2.1,10.51],[2,4.2,153.72]],"ltp":1.9,"tv":620.72,"id":2258415}]}]}
{"op":"mcm","clk":"1000543527","pt":1580616547074,"mc":[{"id":"1.168215937","rc":[{"batl":[[1,3,84.02],[2,4.1,153.72]],"ltp":2.18,"tv":221.29,"id":4423910}]}]}
{"op":"mcm","clk":"1000642511","pt":1580618009932,"mc":[{"id":"1.168215937","rc":[{"batb":[[0,1.9,10.14]],"ltp":1.9,"tv":620.72,"id":2258415}]}]}
{"op":"mcm","clk":"1000644497","pt":1580618050202,"mc":[{"id":"1.168215937","rc":[{"batb":[[0,1.91,19.06],[1,1.9,10.14]],"ltp":1.9,"tv":620.72,"id":2258415}]}]}
{"op":"mcm","clk":"1000644748","pt":1580618055476,"mc":[{"id":"1.168215937","rc":[{"batb":[[1,1.9,3.33]],"ltp":1.9,"tv":620.72,"id":2258415}]}]}
{"op":"mcm","clk":"1000645594","pt":1580618072516,"mc":[{"id":"1.168215937","rc":[{"batb":[[1,1.81,457.96],[2,1.8,420.1]],"ltp":1.9,"tv":620.72,"id":2258415}]}]}
{"op":"mcm","clk":"1000651635","pt":1580618177153,"mc":[{"id":"1.168215937","rc":[{"batb":[[0,1.85,80.84]],"ltp":1.9,"tv":620.72,"id":2258415}]}]}
{"op":"mcm","clk":"1000740582","pt":1580619842916,"mc":[{"id":"1.168215937","rc":[{"batb":[[2,1.9,263.35]],"ltp":2.18,"tv":221.29,"id":4423910}]}]}
{"op":"mcm","clk":"1000747803","pt":1580619984767,"mc":[{"id":"1.168215937","rc":[{"batb":[[2,1.9,314.08]],"ltp":2.18,"tv":221.29,"id":4423910}]}]}
{"op":"mcm","clk":"1000760091","pt":1580620236503,"mc":[{"id":"1.168215937","rc":[{"batl":[[2,2.5,15.14]],"ltp":1.9,"tv":620.72,"id":2258415}]}]}
{"op":"mcm","clk":"1000765649","pt":1580620341067,"mc":[{"id":"1.168215937","rc":[{"trd":[[2.1,0.18]],"batl":[[0,2.1,10.76]],"ltp":2.1,"tv":221.46,"id":4423910},{"trd":[[1.9,118.95]],"ltp":1.9,"tv":620.91,"id":2258415}],"tv":842.38}]}
{"op":"mcm","clk":"1000817528","pt":1580621400782,"mc":[{"id":"1.168215937","rc":[{"trd":[[2.1,10.93]],"batl":[[0,3,84.02],[1,4.1,153.72],[2,95,2.27]],"ltp":2.1,"tv":232.22,"id":4423910},{"trd":[[1.85,180.94],[1.9,130.84]],"batb":[[0,1.85,75.04]],"ltp":1.85,"tv":644.39,"id":2258415}],"tv":876.62}]}
{"op":"mcm","clk":"1000817562","pt":1580621401403,"mc":[{"id":"1.168215937","rc":[{"batb":[[0,2.02,57.09]],"ltp":2.1,"tv":232.22,"id":4423910},{"batb":[[0,1.84,86.15],[1,1.82,10.38],[2,1.81,457.96]],"ltp":1.85,"tv":644.39,"id":2258415}]}]}
{"op":"mcm","clk":"1000817652","pt":1580621402908,"mc":[{"id":"1.168215937","rc":[{"batl":[[0,2.22,8.4],[1,3,84.02],[2,4.1,153.72]],"ltp":2.1,"tv":232.22,"id":4423910},{"batb":[[1,1.81,457.96],[2,1.8,420.1]],"ltp":1.85,"tv":644.39,"id":2258415}]}]}
{"op":"mcm","clk":"1000817658","pt":1580621403007,"mc":[{"id":"1.168215937","rc":[{"batb":[[0,1.84,95.87]],"ltp":1.85,"tv":644.39,"id":2258415}]}]}
{"op":"mcm","clk":"1000818074","pt":1580621410414,"mc":[{"id":"1.168215937","rc":[{"batb":[[0,1.84,86.15]],"ltp":1.85,"tv":644.39,"id":2258415}]}]}
{"op":"mcm","clk":"1000827980","pt":1580621586998,"mc":[{"id":"1.168215937","rc":[{"batb":[[0,2.02,57.27]],"ltp":2.1,"tv":232.22,"id":4423910}]}]}
{"op":"mcm","clk":"1000831713","pt":1580621665030,"mc":[{"id":"1.168215937","rc":[{"batb":[[0,1.85,5.99],[1,1.84,86.15],[2,1.81,457.96]],"ltp":1.85,"tv":644.39,"id":2258415}]}]}
{"op":"mcm","clk":"1000835906","pt":1580621748761,"mc":[{"id":"1.168215937","rc":[{"batl":[[0,3,84.02],[1,4.1,153.72],[2,95,2.27]],"ltp":2.1,"tv":232.22,"id":4423910},{"batb":[[0,1.86,64.37],[1,1.85,5.99]],"ltp":1.85,"tv":644.39,"id":2258415}]}]}
{"op":"mcm","clk":"1000839961","pt":1580621833322,"mc":[{"id":"1.168215937","rc":[{"batl":[[0,2.16,1.68],[1,3,84.02],[2,4.1,153.72]],"ltp":2.1,"tv":232.22,"id":4423910}]}]}
{"op":"mcm","clk":"1000840164","pt":1580621836808,"mc":[{"id":"1.168215937","rc":[{"batl":[[0,2.14,1.68]],"ltp":2.1,"tv":232.22,"id":4423910}]}]}
{"op":"mcm","clk":"1000840329","pt":1580621839959,"mc":[{"id":"1.168215937","rc":[{"batl":[[0,3,84.02],[1,4.1,153.72],[2,95,2.27]],"ltp":2.1,"tv":232.22,"id":4423910}]}]}
{"op":"mcm","clk":"1000840339","pt":1580621840153,"mc":[{"id":"1.168215937","rc":[{"batl":[[0,2.12,1.68],[1,3,84.02],[2,4.1,153.72]],"ltp":2.1,"tv":232.22,"id":4423910}]}]}
{"op":"mcm","clk":"1000840642","pt":1580621845736,"mc":[{"id":"1.168215937","rc":[{"batl":[[0,2.1,1.68]],"ltp":2.1,"tv":232.22,"id":4423910}]}]}
{"op":"mcm","clk":"1000840870","pt":1580621850742,"mc":[{"id":"1.168215937","rc":[{"batl":[[0,2.08,1.68]],"ltp":2.1,"tv":232.22,"id":4423910}]}]}
{"op":"mcm","clk":"1000842381","pt":1580621886588,"mc":[{"id":"1.168215937","rc":[{"batb":[[0,1.86,64.56]],"ltp":1.85,"tv":644.39,"id":2258415}]}]}
{"op":"mcm","clk":"1000895968","pt":1580623448417,"mc":[{"id":"1.168215937","rc":[{"batl":[[1,2.14,15.74],[2,3,84.02]],"ltp":2.1,"tv":232.22,"id":4423910}]}]}
{"op":"mcm","clk":"1000896554","pt":1580623461908,"mc":[{"id":"1.168215937","rc":[{"batb":[[0,1.88,43.42],[1,1.85,6.18]],"ltp":1.85,"tv":644.39,"id":2258415}]}]}
{"op":"mcm","clk":"1000903459","pt":1580623624241,"mc":[{"id":"1.168215937","rc":[{"batb":[[1,1.85,5.99]],"ltp":1.85,"tv":644.39,"id":2258415}]}]}
{"op":"mcm","clk":"1000906081","pt":1580623684377,"mc":[{"id":"1.168215937","rc":[{"batb":[[0,1.88,43.61]],"ltp":1.85,"tv":644.39,"id":2258415}]}]}
{"op":"mcm","clk":"1000924607","pt":1580624047486,"mc":[{"id":"1.168215937","rc":[{"batb":[[2,1.9,263.35]],"ltp":2.1,"tv":232.22,"id":4423910}]}]}
{"op":"mcm","clk":"1000935917","pt":1580624286401,"mc":[{"id":"1.168215937","rc":[{"batb":[[1,1.81,457.96],[2,1.8,420.1]],"ltp":1.85,"tv":644.39,"id":2258415}]}]}
{"op":"mcm","clk":"1000945032","pt":1580624514924,"mc":[{"id":"1.168215937","rc":[{"trd":[[2.08,35.29]],"batb":[[1,1.9,263.35],[2,1.89,50.73]],"batl":[[0,2.14,15.74],[1,3,84.02],[2,4.1,153.72]],"ltp":2.08,"tv":233.9,"id":4423910},{"trd":[[1.88,0.53],[1.89,0.38],[1.92,1.82]],"batb":[[0,1.88,43.15]],"ltp":1.88,"tv":647.12,"id":2258415}],"tv":881.03}]}
{"op":"mcm","clk":"1000961476","pt":1580624947780,"mc":[{"id":"1.168215937","rc":[{"trd":[[2.14,15.74]],"batl":[[0,2.22,8.4]],"ltp":2.14,"tv":249.64,"id":4423910},{"trd":[[1.87,65.56],[1.88,86.84]],"batb":[[0,1.82,55.8]],"batl":[[0,1.87,85.69],[1,1.99,8.4],[2,2.1,10.51]],"ltp":1.87,"tv":772.46,"id":2258415}],"tv":1022.1}]}
{"op":"mcm","clk":"1000961500","pt":1580624948399,"mc":[{"id":"1.168215937","rc":[{"batb":[[0,2.04,81.52],[1,2.02,8.23],[2,1.9,263.35]],"ltp":2.14,"tv":249.64,"id":4423910},{"trd":[[1.87,133.56]],"batb":[[0,1.83,43],[1,1.82,10.38],[2,1.81,420.1]],"batl":[[0,1.87,51.69]],"ltp":1.87,"tv":840.46,"id":2258415}],"tv":1090.1}]}
{"op":"mcm","clk":"1000962380","pt":1580624970825,"mc":[{"id":"1.168215937","rc":[{"batl":[[1,2.1,10.51],[2,2.5,15.14]],"ltp":1.87,"tv":840.46,"id":2258415}]}]}
{"op":"mcm","clk":"1000962408","pt":1580624971646,"mc":[{"id":"1.168215937","rc":[{"batb":[[0,2.14,11.06],[1,2.04,81.52]],"ltp":2.14,"tv":249.64,"id":4423910},{"batl":[[0,1.87,64.29]],"ltp":1.87,"tv":840.46,"id":2258415}]}]}
{"op":"mcm","clk":"1000966681","pt":1580625081765,"mc":[{"id":"1.168215937","rc":[{"batl":[[0,1.85,78.68],[1,1.87,64.29],[2,2.1,10.51]],"ltp":1.87,"tv":840.46,"id":2258415}]}]}
{"op":"mcm","clk":"1000966696","pt":1580625082278,"mc":[{"id":"1.168215937","rc":[{"batb":[[2,2,37.86]],"ltp":2.14,"tv":249.64,"id":4423910},{"trd":[[1.85,262.94]],"batl":[[0,1.85,37.68]],"ltp":1.85,"tv":922.46,"id":2258415}],"tv":1172.11}]}
{"op":"mcm","clk":"1000967325","pt":1580625095857,"mc":[{"id":"1.168215937","rc":[{"batb":[[0,2.16,10.86]],"ltp":2.14,"tv":249.64,"id":4423910},{"batl":[[0,1.85,50.28],[1,1.87,51.69]],"ltp":1.85,"tv":922.46,"id":2258415}]}]}
{"op":"mcm","clk":"1000968448","pt":1580625122590,"mc":[{"id":"1.168215937","rc":[{"batb":[[1,2.04,81.35]],"ltp":2.14,"tv":249.64,"id":4423910}]}]}
{"op":"mcm","clk":"1000968462","pt":1580625123208,"mc":[{"id":"1.168215937","rc":[{"trd":[[1.85,350.94]],"batl":[[0,1.85,6.28]],"ltp":1.85,"tv":1010.46,"id":2258415}],"tv":1260.1}]}
{"op":"mcm","clk":"1000969756","pt":1580625157860,"mc":[{"id":"1.168215937","rc":[{"batl":[[0,1.87,51.69],[1,2.1,10.51],[2,2.5,15.14]],"ltp":1.85,"tv":1010.46,"id":2258415}]}]}
{"op":"mcm","clk":"1000969773","pt":1580625158219,"mc":[{"id":"1.168215937","rc":[{"batb":[[0,2.04,81.35],[1,2,37.86],[2,1.9,263.35]],"ltp":2.14,"tv":249.64,"id":4423910},{"trd":[[1.87,221.56]],"batl":[[0,1.87,7.68]],"ltp":1.87,"tv":1098.46,"id":2258415}],"tv":1348.11}]}
{"op":"mcm","clk":"1000970753","pt":1580625182959,"mc":[{"id":"1.168215937","rc":[{"batb":[[0,2.04,81.52]],"ltp":2.14,"tv":249.64,"id":4423910}]}]}
{"op":"mcm","clk":"1000970759","pt":1580625183061,"mc":[{"id":"1.168215937","rc":[{"trd":[[2.16,0.34]],"batb":[[0,2.04,81.35]],"ltp":2.16,"tv":249.98,"id":4423910}],"tv":1348.45}]}
{"op":"mcm","clk":"1000991202","pt":1580625722883,"mc":[{"id":"1.168215937","rc":[{"batb":[[0,2.1,2.04],[1,2.08,2.06],[2,2.06,2.08]],"batl":[[1,2.26,2.02],[2,2.28,2.09]],"ltp":2.16,"tv":249.98,"id":4423910},{"trd":[[1.87,233.9]],"batb":[[2,1.81,422.18]],"batl":[[0,1.87,1.51],[1,1.91,2.05],[2,1.92,2.06]],"ltp":1.87,"tv":1110.8,"id":2258415}],"tv":1360.79}]}
{"op":"mcm","clk":"1000991237","pt":1580625723904,"mc":[{"id":"1.168215937","rc":[{"batb":[[0,2.04,83.47],[1,2.02,2.21],[2,2,37.86]],"ltp":2.16,"tv":249.98,"id":4423910},{"batl":[[1,1.97,2.12],[2,1.98,2.2]],"ltp":1.87,"tv":1110.8,"id":2258415}]}]}
{"op":"mcm","clk":"1000991245","pt":1580625724161,"mc":[{"id":"1.168215937","rc":[{"batl":[[1,1.99,2.19],[2,2,2]],"ltp":1.87,"tv":1110.8,"id":2258415}]}]}
{"op":"mcm","clk":"1000991798","pt":1580625739817,"mc":[{"id":"1.168215937","rc":[{"batb":[[0,2.04,114.59],[1,2,37.86],[2,1.9,263.35]],"batl":[[2,3,84.02]],"ltp":2.16,"tv":249.98,"id":4423910},{"batl":[[2,2.1,10.51]],"ltp":1.87,"tv":1110.8,"id":2258415}]}]}
{"op":"mcm","clk":"1000991845","pt":1580625740894,"mc":[{"id":"1.168215937","rc":[{"batb":[[0,2.04,83.47],[1,2.02,2.24],[2,2,37.86]],"batl":[[2,2.28,2.02]],"ltp":2.16,"tv":249.98,"id":4423910},{"batl":[[1,1.96,9.27],[2,1.98,2.25]],"ltp":1.87,"tv":1110.8,"id":2258415}]}]}
{"op":"mcm","clk":"1000991850","pt":1580625740996,"mc":[{"id":"1.168215937","rc":[{"batl":[[1,1.96,41.64]],"ltp":1.87,"tv":1110.8,"id":2258415}]}]}
{"op":"mcm","clk":"1000992953","pt":1580625771910,"mc":[{"id":"1.168215937","rc":[{"batb":[[0,2.06,7.92],[1,2.04,83.47]],"batl":[[2,3,84.02]],"ltp":2.16,"tv":249.98,"id":4423910},{"batl":[[1,1.96,50.04],[2,1.97,2.06]],"ltp":1.87,"tv":1110.8,"id":2258415}]}]}
{"op":"mcm","clk":"1000992973","pt":1580625772421,"mc":[{"id":"1.168215937","rc":[{"batb":[[2,2.02,2.02]],"batl":[[2,2.28,2.09]],"ltp":2.16,"tv":249.98,"id":4423910}]}]}
{"op":"mcm","clk":"1000993262","pt":1580625778939,"mc":[{"id":"1.168215937","rc":[{"batb":[[2,2,37.86]],"batl":[[2,3,84.02]],"ltp":2.16,"tv":249.98,"id":4423910}]}]}
{"op":"mcm","clk":"1000993273","pt":1580625779141,"mc":[{"id":"1.168215937","rc":[{"batb":[[2,2.02,2.24]],"batl":[[2,2.28,2.09]],"ltp":2.16,"tv":249.98,"id":4423910}]}]}
{"op":"mcm","clk":"1000993918","pt":1580625794939,"mc":[{"id":"1.168215937","rc":[{"batb":[[0,2.08,49.92],[1,2.06,7.92],[2,2.04,2.12]],"batl":[[2,3,84.02]],"ltp":2.16,"tv":249.98,"id":4423910},{"batl":[[1,1.96,17.67]],"ltp":1.87,"tv":1110.8,"id":2258415}]}]}
{"op":"mcm","clk":"1000993930","pt":1580625795244,"mc":[{"id":"1.168215937","rc":[{"batl":[[2,2.28,2.09]],"ltp":2.16,"tv":249.98,"id":4423910},{"batl":[[1,1.95,2.1],[2,1.96,19.79]],"ltp":1.87,"tv":1110.8,"id":2258415}]}]}
{"op":"mcm","clk":"1000993996","pt":1580625796934,"mc":[{"id":"1.168215937","rc":[{"batl":[[2,1.96,10.52]],"ltp":1.87,"tv":1110.8,"id":2258415}]}]}
{"op":"mcm","clk":"1000994219","pt":1580625802774,"mc":[{"id":"1.168215937","rc":[{"batl":[[2,1.96,2.12]],"ltp":1.87,"tv":1110.8,"id":2258415}]}]}
{"op":"mcm","clk":"1000994247","pt":1580625803551,"mc":[{"id":"1.168215937","rc":[{"batb":[[0,2.08,57.7],[1,2.04,2.12],[2,2.02,2.02]],"ltp":2.16,"tv":249.98,"id":4423910},{"batl":[[1,1.93,8.4],[2,1.95,2.1]],"ltp":1.87,"tv":1110.8,"id":2258415}]}]}
{"op":"mcm","clk":"1001007330","pt":1580626186708,"mc":[{"id":"1.168215937","rc":[{"batb":[[2,2.02,2.14]],"batl":[[0,2.2,7.87],[1,2.22,8.4],[2,2.24,2.23]],"ltp":2.16,"tv":249.98,"id":4423910}]}]}
{"op":"mcm","clk":"1001036559","pt":1580627043496,"mc":[{"id":"1.168215937","rc":[{"batb":[[2,2.02,2.01]],"ltp":2.16,"tv":249.98,"id":4423910}]}]}
{"op":"mcm","clk":"1001048695","pt":1580627318586,"mc":[{"id":"1.168215937","rc":[{"batb":[[2,2.02,2.24]],"ltp":2.16,"tv":249.98,"id":4423910},{"batb":[[0,1.84,2.27],[1,1.83,43],[2,1.82,12.38]],"ltp":1.87,"tv":1110.8,"id":2258415}]}]}
{"op":"mcm","clk":"1001051318","pt":1580627373582,"mc":[{"id":"1.168215937","rc":[{"batb":[[2,2.02,2.13]],"ltp":2.16,"tv":249.98,"id":4423910}]}]}
{"op":"mcm","clk":"1001065813","pt":1580627678508,"mc":[{"id":"1.168215937","rc":[{"batb":[[2,2.02,2.16]],"ltp":2.16,"tv":249.98,"id":4423910}]}]}
{"op":"mcm","clk":"1001068831","pt":1580627750783,"mc":[{"id":"1.168215937","rc":[{"batb":[[2,2.02,2.24]],"ltp":2.16,"tv":249.98,"id":4423910}]}]}
{"op":"mcm","clk":"1001069105","pt":1580627757925,"mc":[{"id":"1.168215937","rc":[{"batb":[[2,2,37.86]],"ltp":2.16,"tv":249.98,"id":4423910}]}]}
{"op":"mcm","clk":"1001069116","pt":1580627758081,"mc":[{"id":"1.168215937","rc":[{"batb":[[2,2.02,2.09]],"ltp":2.16,"tv":249.98,"id":4423910}]}]}
{"op":"mcm","clk":"1001069428","pt":1580627766409,"mc":[{"id":"1.168215937","rc":[{"batb":[[2,2.02,2.17]],"ltp":2.16,"tv":249.98,"id":4423910},{"batl":[[1,1.93,9.16]],"ltp":1.87,"tv":1110.8,"id":2258415}]}]}
{"op":"mcm","clk":"1001069941","pt":1580627780819,"mc":[{"id":"1.168215937","rc":[{"batl":[[1,1.95,2.86],[2,1.96,2.12]],"ltp":1.87,"tv":1110.8,"id":2258415}]}]}
{"op":"mcm","clk":"1001069986","pt":1580627781951,"mc":[{"id":"1.168215937","rc":[{"batb":[[0,2.1,7.64],[1,2.08,49.92],[2,2.06,2.08]],"ltp":2.16,"tv":249.98,"id":4423910},{"batl":[[1,1.9,9.16],[2,1.92,2]],"ltp":1.87,"tv":1110.8,"id":2258415}]}]}
{"op":"mcm","clk":"1001071335","pt":1580627819910,"mc":[{"id":"1.168215937","rc":[{"batb":[[1,2.06,67.45],[2,2,37.86]],"ltp":2.16,"tv":249.98,"id":4423910}]}]}
{"op":"mcm","clk":"1001071347","pt":1580627820111,"mc":[{"id":"1.168215937","rc":[{"batb":[[2,2.04,2.12]],"ltp":2.16,"tv":249.98,"id":4423910}]}]}
{"op":"mcm","clk":"1001074818","pt":1580627909630,"mc":[{"id":"1.168215937","rc":[{"batb":[[2,2.04,2.07]],"ltp":2.16,"tv":249.98,"id":4423910},{"batb":[[0,1.83,43],[1,1.82,10.38],[2,1.81,422.18]],"ltp":1.87,"tv":1110.8,"id":2258415}]}]}
{"op":"mcm","clk":"1001081411","pt":1580628067286,"mc":[{"id":"1.168215937","rc":[{"batb":[[2,2.04,2.12]],"ltp":2.16,"tv":249.98,"id":4423910}]}]}
{"op":"mcm","clk":"1001086748","pt":1580628193943,"mc":[{"id":"1.168215937","rc":[{"batb":[[2,2,37.86]],"ltp":2.16,"tv":249.98,"id":4423910},{"batb":[[0,1.84,2.27],[1,1.83,43],[2,1.82,12.41]],"ltp":1.87,"tv":1110.8,"id":2258415}]}]}
{"op":"mcm","clk":"1001086772","pt":1580628194455,"mc":[{"id":"1.168215937","rc":[{"batb":[[2,2.04,4.24]],"ltp":2.16,"tv":249.98,"id":4423910}]}]}
{"op":"mcm","clk":"1001088299","pt":1580628226616,"mc":[{"id":"1.168215937","rc":[{"batb":[[2,2.04,2.12]],"ltp":2.16,"tv":249.98,"id":4423910}]}]}
{"op":"mcm","clk":"1001104865","pt":1580628575759,"mc":[{"id":"1.168215937","rc":[{"batl":[[1,2.24,2.23],[2,2.26,2.02]],"ltp":2.16,"tv":249.98,"id":4423910},{"batb":[[2,1.82,2.03]],"ltp":1.87,"tv":1110.8,"id":2258415}]}]}
{"op":"mcm","clk":"1001109276","pt":1580628668886,"mc":[{"id":"1.168215937","rc":[{"batb":[[2,2,37.86]],"batl":[[2,3,42.01]],"ltp":2.16,"tv":249.98,"id":4423910},{"batb":[[1,1.82,56.32],[2,1.81,420.1]],"ltp":1.87,"tv":1110.8,"id":2258415}]}]}
{"op":"mcm","clk":"1001109284","pt":1580628669103,"mc":[{"id":"1.168215937","rc":[{"batb":[[2,2.04,2.12]],"batl":[[2,2.26,2.02]],"ltp":2.16,"tv":249.98,"id":4423910},{"batb":[[2,1.81,422.18]],"ltp":1.87,"tv":1110.8,"id":2258415}]}]}
{"op":"mcm","clk":"1001116252","pt":1580628820323,"mc":[{"id":"1.168215937","rc":[{"batl":[[2,2.26,2]],"ltp":2.16,"tv":249.98,"id":4423910}]}]}
{"op":"mcm","clk":"1001116507","pt":1580628826857,"mc":[{"id":"1.168215937","rc":[{"batl":[[2,2.26,2.02]],"ltp":2.16,"tv":249.98,"id":4423910}]}]}
{"op":"mcm","clk":"1001150273","pt":1580629552605,"mc":[{"id":"1.168215937","rc":[{"batb":[[2,2.04,2.07]],"ltp":2.16,"tv":249.98,"id":4423910}]}]}
{"op":"mcm","clk":"1001167085","pt":1580629958574,"mc":[{"id":"1.168215937","rc":[{"trd":[[2.1,27.34],[2.14,17.06]],"batb":[[0,2.06,67.45],[1,2.04,2.11],[2,2.02,2.03]],"ltp":2.1,"tv":267.7,"id":4423910},{"trd":[[1.87,235.42],[1.9,132.08]],"batl":[[0,1.9,7.91],[1,1.92,2],[2,1.93,2.07]],"ltp":1.9,"tv":1113.56,"id":2258415}],"tv":1381.27}]}
{"op":"mcm","clk":"1001167432","pt":1580629968881,"mc":[{"id":"1.168215937","rc":[{"batl":[[1,2.22,2.03],[2,2.24,2.23]],"ltp":2.1,"tv":267.7,"id":4423910},{"batb":[[0,1.85,9.24],[1,1.84,2.27],[2,1.83,2.03]],"ltp":1.9,"tv":1113.56,"id":2258415}]}]}
{"op":"mcm","clk":"1001167460","pt":1580629969501,"mc":[{"id":"1.168215937","rc":[{"batb":[[1,2.04,2.12],[2,2,37.86]],"batl":[[2,2.24,2.07]],"ltp":2.1,"tv":267.7,"id":4423910}]}]}
{"op":"mcm","clk":"1001167826","pt":1580629980812,"mc":[{"id":"1.168215937","rc":[{"batl":[[0,2.18,8.4],[1,2.2,7.87],[2,2.22,2.03]],"ltp":2.1,"tv":267.7,"id":4423910}]}]}
{"op":"mcm","clk":"1001167859","pt":1580629981523,"mc":[{"id":"1.168215937","rc":[{"batb":[[0,2.1,7.64],[1,2.06,67.45],[2,2.04,2.12]],"ltp":2.1,"tv":267.7,"id":4423910},{"batb":[[0,1.85,19.12]],"ltp":1.9,"tv":1113.56,"id":2258415}]}]}
{"op":"mcm","clk":"1001181661","pt":1580630339662,"mc":[{"id":"1.168215937","rc":[{"trd":[[1.85,388.75]],"batb":[[0,1.84,2.49],[1,1.82,56.32],[2,1.81,422.18]],"ltp":1.85,"tv":1151.37,"id":2258415}],"tv":1419.07}]}
{"op":"mcm","clk":"1001181705","pt":1580630340479,"mc":[{"id":"1.168215937","rc":[{"trd":[[2.18,20.72]],"batl":[[0,2.2,7.91],[1,2.24,2.03],[2,2.26,2]],"ltp":2.18,"tv":284.42,"id":4423910}],"tv":1435.79}]}
{"op":"mcm","clk":"1001181811","pt":1580630341896,"mc":[{"id":"1.168215937","rc":[{"trd":[[1.86,4.5]],"batb":[[0,1.82,54.53],[1,1.81,422.18],[2,1.8,422.13]],"ltp":1.86,"tv":1155.87,"id":2258415}],"tv":1440.29}]}
{"op":"mcm","clk":"1001181890","pt":1580630342878,"mc":[{"id":"1.168215937","rc":[{"batb":[[1,2.08,2.06],[2,2.06,67.45]],"ltp":2.18,"tv":284.42,"id":4423910},{"trd":[[1.86,4.55]],"batb":[[0,1.82,54.51]],"batl":[[0,1.9,9.96],[1,1.91,2.05],[2,1.92,2]],"ltp":1.86,"tv":1155.91,"id":2258415}],"tv":1440.34}]}
{"op":"mcm","clk":"1001181919","pt":1580630343289,"mc":[{"id":"1.168215937","rc":[{"batb":[[1,2.06,67.38],[2,2.04,2.12]],"ltp":2.18,"tv":284.42,"id":4423910},{"batl":[[0,1.9,7.91],[1,1.92,2.06],[2,1.93,2.07]],"ltp":1.86,"tv":1155.91,"id":2258415}]}]}
{"op":"mcm","clk":"1001182460","pt":1580630356892,"mc":[{"id":"1.168215937","rc":[{"trd":[[2.18,20.9],[2.2,15.73],[2.22,0.03]],"batb":[[2,2,37.86]],"batl":[[0,2.24,2.03],[1,3,42.01],[2,4.1,153.72]],"ltp":2.22,"tv":300.37,"id":4423910},{"trd":[[1.82,0.04],[1.85,388.96]],"batb":[[0,1.82,54.25],[2,1.8,420.1]],"batl":[[2,2.1,10.51]],"ltp":1.82,"tv":1156.17,"id":2258415}],"tv":1456.55}]}
{"op":"mcm","clk":"1001182510","pt":1580630357921,"mc":[{"id":"1.168215937","rc":[{"batb":[[0,2.12,54.54],[1,2.1,7.64],[2,2.08,2.06]],"batl":[[0,2.28,2.02],[1,2.3,2.05],[2,3,42.01]],"ltp":2.22,"tv":300.37,"id":4423910},{"batb":[[0,1.81,445.97],[1,1.8,420.1],[2,1.79,422.1]],"batl":[[0,1.89,2.27],[1,1.9,7.91],[2,1.91,2.05]],"ltp":1.82,"tv":1156.17,"id":2258415}]}]}
{"op":"mcm","clk":"1001187039","pt":1580630446685,"mc":[{"id":"1.168215937","rc":[{"batb":[[0,1.81,913.26]],"ltp":1.82,"tv":1156.17,"id":2258415}]}]}
{"op":"mcm","clk":"1001187994","pt":1580630463795,"mc":[{"id":"1.168215937","rc":[{"batl":[[1,3,42.01],[2,4.1,153.72]],"ltp":2.22,"tv":300.37,"id":4423910}]}]}
{"op":"mcm","clk":"1001188005","pt":1580630463999,"mc":[{"id":"1.168215937","rc":[{"batl":[[1,2.3,2.05],[2,3,42.01]],"ltp":2.22,"tv":300.37,"id":4423910}]}]}
{"op":"mcm","clk":"1001188925","pt":1580630483777,"mc":[{"id":"1.168215937","rc":[{"batl":[[1,3,42.01],[2,4.1,153.72]],"ltp":2.22,"tv":300.37,"id":4423910},{"batb":[[0,1.81,912.85]],"ltp":1.82,"tv":1156.17,"id":2258415}]}]}
{"op":"mcm","clk":"1001188935","pt":1580630483982,"mc":[{"id":"1.168215937","rc":[{"batl":[[1,2.3,2.05],[2,3,42.01]],"ltp":2.22,"tv":300.37,"id":4423910}]}]}
{"op":"mcm","clk":"1001192391","pt":1580630546852,"mc":[{"id":"1.168215937","rc":[{"batb":[[1,2.08,2.06],[2,2.06,2.08]],"ltp":2.22,"tv":300.37,"id":4423910},{"batl":[[1,1.91,2.05],[2,1.92,2.06]],"ltp":1.82,"tv":1156.17,"id":2258415}]}]}
{"op":"mcm","clk":"1001192437","pt":1580630547470,"mc":[{"id":"1.168215937","rc":[{"batb":[[0,2.12,65.79]],"ltp":2.22,"tv":300.37,"id":4423910},{"batl":[[0,1.89,14.87]],"ltp":1.82,"tv":1156.17,"id":2258415}]}]}
{"op":"mcm","clk":"1001206611","pt":1580630787915,"mc":[{"id":"1.168215937","rc":[{"trd":[[2.12,24]],"batb":[[0,2.12,53.79]],"batl":[[1,2.3,2.02]],"ltp":2.12,"tv":324.37,"id":4423910}],"tv":1480.55}]}
{"op":"mcm","clk":"1001206749","pt":1580630789931,"mc":[{"id":"1.168215937","rc":[{"batb":[[0,2.12,11.25],[1,2.1,57.67],[2,2.08,2.06]],"batl":[[0,2.26,2.02],[1,2.28,2.02],[2,2.3,2.02]],"ltp":2.12,"tv":324.37,"id":4423910},{"batb":[[0,1.82,13.94],[1,1.81,445.56],[2,1.8,422.13]],"ltp":1.82,"tv":1156.17,"id":2258415}]}]}
{"op":"mcm","clk":"1001206770","pt":1580630790240,"mc":[{"id":"1.168215937","rc":[{"batl":[[1,2.28,2]],"ltp":2.12,"tv":324.37,"id":4423910}]}]}
{"op":"mcm","clk":"1001211448","pt":1580630865841,"mc":[{"id":"1.168215937","rc":[{"batb":[[0,2.14,28.94],[1,2.12,11.25],[2,2.1,2.01]],"batl":[[1,2.28,2.09],[2,3,42.01]],"ltp":2.12,"tv":324.37,"id":4423910},{"batl":[[1,1.9,2],[2,2.1,10.51]],"ltp":1.82,"tv":1156.17,"id":2258415}]}]}
{"op":"mcm","clk":"1001211464","pt":1580630866048,"mc":[{"id":"1.168215937","rc":[{"batl":[[2,1.91,2.03]],"ltp":1.82,"tv":1156.17,"id":2258415}]}]}
{"op":"mcm","clk":"1001212594","pt":1580630888869,"mc":[{"id":"1.168215937","rc":[{"batl":[[1,3,42.01],[2,4.1,153.72]],"ltp":2.12,"tv":324.37,"id":4423910},{"batl":[[0,1.89,2.27],[2,2.1,10.51]],"ltp":1.82,"tv":1156.17,"id":2258415}]}]}
{"op":"mcm","clk":"1001212629","pt":1580630889643,"mc":[{"id":"1.168215937","rc":[{"batb":[[0,2.14,40],[1,2.1,2.01],[2,2.08,2.06]],"batl":[[1,2.28,2.02],[2,3,42.01]],"ltp":2.12,"tv":324.37,"id":4423910},{"batl":[[0,1.88,12.6],[1,1.89,2.27],[2,1.9,2]],"ltp":1.82,"tv":1156.17,"id":2258415}]}]}
{"op":"mcm","clk":"1001217406","pt":1580630993564,"mc":[{"id":"1.168215937","rc":[{"batb":[[0,2.14,11.06],[2,2.08,74.8]],"batl":[[1,2.28,2.09]],"ltp":2.12,"tv":324.37,"id":4423910}]}]}
{"op":"mcm","clk":"1001218187","pt":1580631009779,"mc":[{"id":"1.168215937","rc":[{"batb":[[2,2.08,72.74]],"batl":[[1,3,42.01],[2,4.1,153.72]],"ltp":2.12,"tv":324.37,"id":4423910},{"batl":[[1,1.9,4.27],[2,2.1,10.51]],"ltp":1.82,"tv":1156.17,"id":2258415}]}]}
{"op":"mcm","clk":"1001218195","pt":1580631009985,"mc":[{"id":"1.168215937","rc":[{"batb":[[2,2.08,74.78]],"batl":[[1,2.28,2.09],[2,3,42.01]],"ltp":2.12,"tv":324.37,"id":4423910},{"batl":[[2,1.91,2.05]],"ltp":1.82,"tv":1156.17,"id":2258415}]}]}
{"op":"mcm","clk":"1001219704","pt":1580631042962,"mc":[{"id":"1.168215937","rc":[{"batl":[[0,2.18,25.33],[1,2.22,2.16],[2,2.24,2.07]],"ltp":2.12,"tv":324.37,"id":4423910}]}]}
{"op":"mcm","clk":"1001219740","pt":1580631043684,"mc":[{"id":"1.168215937","rc":[{"batb":[[2,2.08,74.75]],"ltp":2.12,"tv":324.37,"id":4423910},{"batb":[[0,1.82,15.97],[1,1.81,447.59],[2,1.8,420.1]],"batl":[[2,1.91,2]],"ltp":1.82,"tv":1156.17,"id":2258415}]}]}
{"op":"mcm","clk":"1001220769","pt":1580631067587,"mc":[{"id":"1.168215937","rc":[{"batb":[[1,2.12,5],[2,2.1,2.01]],"batl":[[0,2.18,29.33],[1,2.2,4.01],[2,2.22,2.16]],"ltp":2.12,"tv":324.37,"id":4423910},{"batb":[[0,1.85,6.01],[1,1.83,2.03],[2,1.82,15.97]],"batl":[[1,1.9,9.27],[2,2.1,10.51]],"ltp":1.82,"tv":1156.17,"id":2258415}]}]}
{"op":"mcm","clk":"1001220879","pt":1580631069901,"mc":[{"id":"1.168215937","rc":[{"batb":[[2,2.1,8.01]],"ltp":2.12,"tv":324.37,"id":4423910},{"batb":[[2,1.82,13.94]],"batl":[[1,1.89,6.04],[2,1.9,9.27]],"ltp":1.82,"tv":1156.17,"id":2258415}]}]}
{"op":"mcm","clk":"1001220893","pt":1580631070110,"mc":[{"id":"1.168215937","rc":[{"batb":[[2,1.82,15.97]],"ltp":1.82,"tv":1156.17,"id":2258415}]}]}
{"op":"mcm","clk":"1001223422","pt":1580631118956,"mc":[{"id":"1.168215937","rc":[{"batb":[[0,2.14,40]],"ltp":2.12,"tv":324.37,"id":4423910}]}]}
{"op":"mcm","clk":"1001260448","pt":1580632003904,"mc":[{"id":"1.168215937","rc":[{"trd":[[1.85,392.96]],"batb":[[0,1.85,4.01]],"ltp":1.85,"tv":1160.17,"id":2258415}],"tv":1484.55}]}
{"op":"mcm","clk":"1001263240","pt":1580632063937,"mc":[{"id":"1.168215937","rc":[{"batl":[[0,1.87,2.27],[1,1.88,12.6],[2,1.89,8.08]],"ltp":1.85,"tv":1160.17,"id":2258415}]}]}
{"op":"mcm","clk":"1001263389","pt":1580632067645,"mc":[{"id":"1.168215937","rc":[{"batl":[[0,1.87,14.87],[1,1.89,8.08],[2,1.9,7.05]],"ltp":1.85,"tv":1160.17,"id":2258415}]}]}
{"op":"mcm","clk":"1001263488","pt":1580632069540,"mc":[{"id":"1.168215937","rc":[{"trd":[[2.14,19.59]],"batb":[[0,2.14,38.73]],"ltp":2.14,"tv":326.91,"id":4423910}],"tv":1487.08}]}
{"op":"mcm","clk":"1001263743","pt":1580632075941,"mc":[{"id":"1.168215937","rc":[{"trd":[[1.87,262.34]],"batb":[[2,1.82,13.94]],"batl":[[0,1.87,1.41],[1,1.89,6.04]],"ltp":1.87,"tv":1187.1,"id":2258415}],"tv":1514.01}]}
{"op":"mcm","clk":"1001263750","pt":1580632076147,"mc":[{"id":"1.168215937","rc":[{"batb":[[2,1.82,15.97]],"ltp":1.87,"tv":1187.1,"id":2258415}]}]}
{"op":"mcm","clk":"1001264876","pt":1580632099880,"mc":[{"id":"1.168215937","rc":[{"batl":[[0,1.88,8.4]],"ltp":1.87,"tv":1187.1,"id":2258415}]}]}
{"op":"mcm","clk":"1001266589","pt":1580632136913,"mc":[{"id":"1.168215937","rc":[{"batb":[[0,2.14,45.73],[1,2.12,7.04]],"batl":[[0,2.18,25.33],[2,2.22,7.16]],"ltp":2.14,"tv":326.91,"id":4423910},{"trd":[[1.85,423.25]],"batb":[[0,1.84,7],[1,1.83,7],[2,1.82,20.94]],"batl":[[0,1.87,7.31],[1,1.88,15.4],[2,1.89,8.08]],"ltp":1.85,"tv":1217.39,"id":2258415}],"tv":1544.3}]}
{"op":"mcm","clk":"1001266607","pt":1580632137325,"mc":[{"id":"1.168215937","rc":[{"batb":[[1,2.12,5]],"ltp":2.14,"tv":326.91,"id":4423910},{"batb":[[2,1.82,22.97]],"batl":[[0,1.88,15.4],[1,1.89,6.04],[2,1.9,7.05]],"ltp":1.85,"tv":1217.39,"id":2258415}]}]}
{"op":"mcm","clk":"1001269408","pt":1580632206528,"mc":[{"id":"1.168215937","rc":[{"batb":[[0,1.84,12.95]],"ltp":1.85,"tv":1217.39,"id":2258415}]}]}
{"op":"mcm","clk":"1001271809","pt":1580632274949,"mc":[{"id":"1.168215937","rc":[{"batb":[[0,2.14,74.68]],"ltp":2.14,"tv":326.91,"id":4423910},{"batb":[[2,1.82,62.37]],"ltp":1.85,"tv":1217.39,"id":2258415}]}]}
{"op":"mcm","clk":"1001272239","pt":1580632288870,"mc":[{"id":"1.168215937","rc":[{"batb":[[0,2.14,67.68]],"batl":[[0,2.18,29.33]],"ltp":2.14,"tv":326.91,"id":4423910},{"batb":[[0,1.85,6.15],[1,1.84,433.05],[2,1.83,9.03]],"batl":[[0,1.88,8.4]],"ltp":1.85,"tv":1217.39,"id":2258415}]}]}
{"op":"mcm","clk":"1001272352","pt":1580632291967,"mc":[{"id":"1.168215937","rc":[{"batb":[[2,1.83,429.13]],"ltp":1.85,"tv":1217.39,"id":2258415}]}]}
{"op":"mcm","clk":"1001272758","pt":1580632302829,"mc":[{"id":"1.168215937","rc":[{"batl":[[0,2.16,4.23],[1,2.18,29.33],[2,2.2,6.04]],"ltp":2.14,"tv":326.91,"id":4423910},{"batb":[[0,1.85,426.25],[1,1.84,435.27],[2,1.83,427.1]],"ltp":1.85,"tv":1217.39,"id":2258415}]}]}
{"op":"mcm","clk":"1001272776","pt":1580632303194,"mc":[{"id":"1.168215937","rc":[{"batb":[[2,1.83,429.13]],"ltp":1.85,"tv":1217.39,"id":2258415}]}]}
{"op":"mcm","clk":"1001273594","pt":1580632322829,"mc":[{"id":"1.168215937","rc":[{"batb":[[0,1.86,6],[1,1.85,426.25],[2,1.84,435.27]],"ltp":1.85,"tv":1217.39,"id":2258415}]}]}
{"op":"mcm","clk":"1001276652","pt":1580632400861,"mc":[{"id":"1.168215937","rc":[{"trd":[[2.16,8.8]],"batb":[[1,2.12,9],[2,2.1,11.01]],"batl":[[0,2.16,4.11],[2,2.2,4.01]],"ltp":2.16,"tv":335.36,"id":4423910},{"trd":[[1.86,16.55]],"batb":[[0,1.85,426.25],[1,1.84,433.05],[2,1.83,429.13]],"batl":[[2,1.9,10.05]],"ltp":1.86,"tv":1229.38,"id":2258415}],"tv":1564.75}]}
{"op":"mcm","clk":"1001276661","pt":1580632401272,"mc":[{"id":"1.168215937","rc":[{"batb":[[0,2.14,9.79],[1,2.12,85.72]],"batl":[[2,2.2,6.04]],"ltp":2.16,"tv":335.36,"id":4423910},{"batb":[[1,1.84,435.15],[2,1.83,442.75]],"ltp":1.86,"tv":1229.38,"id":2258415}]}]}
{"op":"mcm","clk":"1001277395","pt":1580632420913,"mc":[{"id":"1.168215937","rc":[{"batb":[[0,1.86,6.11],[1,1.85,426.25],[2,1.84,435.15]],"ltp":1.86,"tv":1229.38,"id":2258415}]}]}
{"op":"mcm","clk":"1001279517","pt":1580632471822,"mc":[{"id":"1.168215937","rc":[{"trd":[[1.86,18.57]],"batb":[[0,1.86,5.1]],"ltp":1.86,"tv":1231.41,"id":2258415}],"tv":1566.77}]}
{"op":"mcm","clk":"1001281827","pt":1580632528908,"mc":[{"id":"1.168215937","rc":[{"trd":[[2.16,17.01]],"batb":[[1,2.12,73.02]],"batl":[[0,2.18,29.33],[1,2.2,4.01],[2,2.22,7.16]],"ltp":2.16,"tv":343.57,"id":4423910},{"trd":[[1.86,28.78]],"batb":[[0,1.85,426.25],[1,1.84,435.15],[2,1.83,442.75]],"ltp":1.86,"tv":1241.62,"id":2258415}],"tv":1585.19}]}
{"op":"mcm","clk":"1001281855","pt":1580632529632,"mc":[{"id":"1.168215937","rc":[{"batb":[[0,2.14,13.93]],"batl":[[0,2.16,5.15],[1,2.18,29.33],[2,2.2,6.04]],"ltp":2.16,"tv":343.57,"id":4423910},{"batb":[[1,1.84,435.21],[2,1.83,452.75]],"batl":[[1,1.89,11]],"ltp":1.86,"tv":1241.62,"id":2258415}]}]}
{"op":"mcm","clk":"1001282118","pt":1580632536937,"mc":[{"id":"1.168215937","rc":[{"batl":[[0,2.18,29.33],[1,2.2,6.04],[2,2.22,7.16]],"ltp":2.16,"tv":343.57,"id":4423910},{"batb":[[0,1.86,7],[1,1.85,426.25],[2,1.84,435.21]],"batl":[[0,1.87,23],[1,1.88,8.4],[2,1.89,13.04]],"ltp":1.86,"tv":1241.62,"id":2258415}]}]}
{"op":"mcm","clk":"1001282136","pt":1580632537348,"mc":[{"id":"1.168215937","rc":[{"batl":[[1,2.2,4.01]],"ltp":2.16,"tv":343.57,"id":4423910}]}]}
{"op":"mcm","clk":"1001283247","pt":1580632564873,"mc":[{"id":"1.168215937","rc":[{"trd":[[1.87,306.8]],"batl":[[0,1.89,13.81],[1,1.9,8],[2,2.1,10.51]],"ltp":1.87,"tv":1286.08,"id":2258415}],"tv":1629.65}]}
{"op":"mcm","clk":"1001283293","pt":1580632565798,"mc":[{"id":"1.168215937","rc":[{"batl":[[0,2.16,5.02],[1,2.18,29.33],[2,2.2,6.04]],"ltp":2.16,"tv":343.57,"id":4423910},{"batl":[[0,1.89,11.77],[1,1.9,10.05],[2,1.91,2.05]],"ltp":1.87,"tv":1286.08,"id":2258415}]}]}
{"op":"mcm","clk":"1001286925","pt":1580632657492,"mc":[{"id":"1.168215937","rc":[{"batb":[[0,2.14,9.79],[1,2.12,77.17]],"ltp":2.16,"tv":343.57,"id":4423910}]}]}
{"op":"mcm","clk":"1001298864","pt":1580632929912,"mc":[{"id":"1.168215937","rc":[{"trd":[[1.86,38.91]],"batb":[[0,1.86,1.93]],"ltp":1.86,"tv":1296.21,"id":2258415}],"tv":1639.79}]}
{"op":"mcm","clk":"1001298891","pt":1580632930427,"mc":[{"id":"1.168215937","rc":[{"batb":[[2,1.84,435.27]],"batl":[[2,1.91,2.02]],"ltp":1.86,"tv":1296.21,"id":2258415}]}]}
{"op":"mcm","clk":"1001299773","pt":1580632953869,"mc":[{"id":"1.168215937","rc":[{"trd":[[2.16,22.03]],"batb":[[0,2.14,22.79],[1,2.12,83.21],[2,2.1,16.01]],"batl":[[0,2.18,29.33],[1,2.2,4.01],[2,2.22,7]],"ltp":2.16,"tv":348.59,"id":4423910},{"trd":[[1.86,48.6]],"batb":[[0,1.85,426.25],[1,1.84,433.05],[2,1.83,452.72]],"batl":[[0,1.86,7.24],[1,1.88,2.81],[2,1.89,13.04]],"ltp":1.86,"tv":1305.9,"id":2258415}],"tv":1654.5}]}
{"op":"mcm","clk":"1001299853","pt":1580632954956,"mc":[{"id":"1.168215937","rc":[{"batb":[[0,2.14,9.79],[1,2.12,81.17],[2,2.1,16.04]],"batl":[[0,2.16,5.18],[1,2.18,29.33],[2,2.2,6.04]],"ltp":2.16,"tv":348.59,"id":4423910},{"trd":[[1.86,63.09]],"batb":[[0,1.86,7],[1,1.85,426.25],[2,1.84,435.09]],"batl":[[0,1.89,11.77],[1,1.9,15.05],[2,1.91,2.05]],"ltp":1.86,"tv":1320.38,"id":2258415}],"tv":1668.98}]}
{"op":"mcm","clk":"1001301413","pt":1580632987790,"mc":[{"id":"1.168215937","rc":[{"trd":[[2.14,29.38]],"batb":[[0,2.12,68.17],[1,2.1,14],[2,2.08,2.06]],"ltp":2.14,"tv":358.38,"id":4423910},{"trd":[[1.87,308.34],[1.88,97.98]],"batb":[[0,1.86,7.69]],"batl":[[0,1.91,13],[1,1.92,2.05],[2,1.93,2.07]],"ltp":1.88,"tv":1333.07,"id":2258415}],"tv":1691.45}]}
{"op":"mcm","clk":"1001301853","pt":1580632994856,"mc":[{"id":"1.168215937","rc":[{"batb":[[2,2.08,16.06]],"batl":[[0,2.16,9.97]],"ltp":2.14,"tv":358.38,"id":4423910},{"batl":[[2,2.1,10.51]],"ltp":1.88,"tv":1333.07,"id":2258415}]}]}
{"op":"mcm","clk":"1001301865","pt":1580632995063,"mc":[{"id":"1.168215937","rc":[{"batl":[[2,1.93,2.07]],"ltp":1.88,"tv":1333.07,"id":2258415}]}]}
{"op":"mcm","clk":"1001302835","pt":1580633011821,"mc":[{"id":"1.168215937","rc":[{"batb":[[0,1.87,7.86],[1,1.86,427.1],[2,1.85,430.46]],"batl":[[2,1.93,4.14]],"ltp":1.88,"tv":1333.07,"id":2258415}]}]}
{"op":"mcm","clk":"1001303686","pt":1580633030916,"mc":[{"id":"1.168215937","rc":[{"trd":[[2.12,24.61]],"batb":[[0,2.12,67.55]],"ltp":2.12,"tv":358.99,"id":4423910},{"trd":[[1.9,132.77]],"batb":[[0,1.87,7.17],[2,1.85,428.42]],"batl":[[2,2.1,10.51]],"ltp":1.9,"tv":1333.76,"id":2258415}],"tv":1692.76}]}
{"op":"mcm","clk":"1001303739","pt":1580633031940,"mc":[{"id":"1.168215937","rc":[{"batb":[[0,2.1,90.37],[1,2.08,14],[2,2.06,2.08]],"ltp":2.12,"tv":358.99,"id":4423910},{"trd":[[1.87,322.66]],"batb":[[0,1.87,7]],"batl":[[0,1.92,16.33],[1,1.93,2.07],[2,1.94,2.08]],"ltp":1.87,"tv":1348.08,"id":2258415}],"tv":1707.07}]}
{"op":"mcm","clk":"1001303763","pt":1580633032404,"mc":[{"id":"1.168215937","rc":[{"batl":[[0,1.92,14.28]],"ltp":1.87,"tv":1348.08,"id":2258415}]}]}
{"op":"mcm","clk":"1001304165","pt":1580633042939,"mc":[{"id":"1.168215937","rc":[{"batb":[[0,2.1,84.23],[2,2.06,18.09]],"batl":[[0,2.14,5],[1,2.16,9.97],[2,2.18,31.36]],"ltp":2.12,"tv":358.99,"id":4423910},{"trd":[[1.87,336.66]],"batb":[[0,1.87,7.01],[2,1.85,436.87]],"ltp":1.87,"tv":1362.08,"id":2258415}],"tv":1721.07}]}
{"op":"mcm","clk":"1001304812","pt":1580633056546,"mc":[{"id":"1.168215937","rc":[{"batl":[[0,2.14,9.84],[1,2.16,5.18]],"ltp":2.12,"tv":358.99,"id":4423910},{"batl":[[2,1.94,2]],"ltp":1.87,"tv":1362.08,"id":2258415}]}]}
{"op":"mcm","clk":"1001310715","pt":1580633168847,"mc":[{"id":"1.168215937","rc":[{"trd":[[2.14,49.06]],"batb":[[0,2.1,74.33]],"batl":[[0,2.14,4]],"ltp":2.14,"tv":378.67,"id":4423910},{"batb":[[2,1.85,448.24]],"batl":[[2,1.94,2.08]],"ltp":1.87,"tv":1362.08,"id":2258415}],"tv":1740.75}]}
{"op":"mcm","clk":"1001316774","pt":1580633296798,"mc":[{"id":"1.168215937","rc":[{"trd":[[2.14,57.06]],"batl":[[0,2.16,5.18],[1,2.18,31.36],[2,2.2,6.04]],"ltp":2.14,"tv":386.67,"id":4423910}],"tv":1748.75}]}
{"op":"mcm","clk":"1001316810","pt":1580633297718,"mc":[{"id":"1.168215937","rc":[{"batb":[[0,2.1,70.31]],"batl":[[0,2.14,5],[1,2.16,5.18],[2,2.18,31.36]],"ltp":2.14,"tv":386.67,"id":4423910},{"batb":[[2,1.85,452.85]],"ltp":1.87,"tv":1362.08,"id":2258415}]}]}
{"op":"mcm","clk":"1001318668","pt":1580633336607,"mc":[{"id":"1.168215937","rc":[{"batb":[[0,1.87,427.11]],"batl":[[2,1.94,2.01]],"ltp":1.87,"tv":1362.08,"id":2258415}]}]}
{"op":"mcm","clk":"1001330450","pt":1580633609850,"mc":[{"id":"1.168215937","rc":[{"trd":[[2.1,42.68]],"batb":[[0,2.1,54.97]],"ltp":2.1,"tv":402.01,"id":4423910},{"trd":[[1.91,16.87]],"batl":[[2,2.1,10.51]],"ltp":1.91,"tv":1378.94,"id":2258415}],"tv":1780.96}]}
{"op":"mcm","clk":"1001330461","pt":1580633610315,"mc":[{"id":"1.168215937","rc":[{"batb":[[1,1.86,461.51]],"batl":[[2,1.94,2.08]],"ltp":1.91,"tv":1378.94,"id":2258415}]}]}
{"op":"mcm","clk":"1001336101","pt":1580633752710,"mc":[{"id":"1.168215937","rc":[{"trd":[[2.1,44.19]],"batb":[[0,2.1,54.21]],"ltp":2.1,"tv":403.53,"id":4423910}],"tv":1782.47}]}
{"op":"mcm","clk":"1001339670","pt":1580633835707,"mc":[{"id":"1.168215937","rc":[{"batb":[[0,1.89,7.08],[1,1.88,3.8],[2,1.87,429.15]],"ltp":1.91,"tv":1378.94,"id":2258415}]}]}
{"op":"mcm","clk":"1001343131","pt":1580633941853,"mc":[{"id":"1.168215937","rc":[{"batb":[[0,2.1,48.05]],"ltp":2.1,"tv":403.53,"id":4423910},{"trd":[[1.89,14.54]],"batb":[[0,1.89,7],[1,1.88,10.88]],"batl":[[1,1.93,17.07],[2,1.94,2.02]],"ltp":1.89,"tv":1393.1,"id":2258415}],"tv":1796.64}]}
{"op":"mcm","clk":"1001345400","pt":1580634004909,"mc":[{"id":"1.168215937","rc":[{"trd":[[2.1,139.43]],"batb":[[0,2.06,16.44],[1,2.02,26.95],[2,2,2]],"batl":[[0,2.12,5.02],[1,2.14,5],[2,2.16,5.18]],"ltp":2.1,"tv":498.77,"id":4423910},{"batl":[[0,1.94,15.02],[1,1.95,2.04],[2,1.96,2.02]],"ltp":1.89,"tv":1393.1,"id":2258415}],"tv":1891.88}]}
{"op":"mcm","clk":"1001345471","pt":1580634005799,"mc":[{"id":"1.168215937","rc":[{"batb":[[0,2.04,17.45],[1,2.02,24.71]],"batl":[[2,2.16,7.34]],"ltp":2.1,"tv":498.77,"id":4423910},{"batl":[[0,1.95,15],[1,1.97,2.04],[2,1.98,2.2]],"ltp":1.89,"tv":1393.1,"id":2258415}]}]}
{"op":"mcm","clk":"1001345546","pt":1580634006801,"mc":[{"id":"1.168215937","rc":[{"batb":[[0,2.06,60.77],[1,2.04,17.02],[2,2.02,26.86]],"ltp":2.1,"tv":498.77,"id":4423910},{"batb":[[1,1.88,68.11]],"batl":[[0,1.96,15.03],[1,1.98,2.2],[2,1.99,2.35]],"ltp":1.89,"tv":1393.1,"id":2258415}]}]}
{"op":"mcm","clk":"1001345565","pt":1580634007011,"mc":[{"id":"1.168215937","rc":[{"batl":[[1,1.97,2.16],[2,1.98,2.2]],"ltp":1.89,"tv":1393.1,"id":2258415}]}]}
{"op":"mcm","clk":"1001345712","pt":1580634008917,"mc":[{"id":"1.168215937","rc":[{"batb":[[2,2.02,2.15]],"ltp":2.1,"tv":498.77,"id":4423910},{"batl":[[0,1.95,15],[1,1.96,15.03],[2,1.97,2.16]],"ltp":1.89,"tv":1393.1,"id":2258415}]}]}
{"op":"mcm","clk":"1001347934","pt":1580634054855,"mc":[{"id":"1.168215937","rc":[{"trd":[[1.89,28.08]],"batb":[[0,1.88,68.34],[1,1.87,429.15],[2,1.86,420.1]],"ltp":1.89,"tv":1406.64,"id":2258415}],"tv":1905.42}]}
{"op":"mcm","clk":"1001347944","pt":1580634055063,"mc":[{"id":"1.168215937","rc":[{"batb":[[2,1.86,422.14]],"ltp":1.89,"tv":1406.64,"id":2258415}]}]}
{"op":"mcm","clk":"1001348051","pt":1580634057756,"mc":[{"id":"1.168215937","rc":[{"trd":[[2.12,34.19]],"batl":[[0,2.14,5.23],[1,2.16,7.34],[2,2.18,31.36]],"ltp":2.12,"tv":508.35,"id":4423910}],"tv":1915.0}]}
{"op":"mcm","clk":"1001348115","pt":1580634058839,"mc":[{"id":"1.168215937","rc":[{"batl":[[1,2.16,5.18]],"ltp":2.12,"tv":508.35,"id":4423910},{"batb":[[1,1.87,427.11]],"ltp":1.89,"tv":1406.64,"id":2258415}]}]}
{"op":"mcm","clk":"1001358883","pt":1580634294910,"mc":[{"id":"1.168215937","rc":[{"trd":[[2.06,152.74]],"batb":[[0,2.06,50.63]],"ltp":2.06,"tv":528.62,"id":4423910},{"batb":[[0,1.88,79.36]],"ltp":1.89,"tv":1406.64,"id":2258415}],"tv":1935.27}]}
{"op":"mcm","clk":"1001361411","pt":1580634345942,"mc":[{"id":"1.168215937","rc":[{"batl":[[0,1.94,2.27],[1,1.95,15],[2,1.96,17.15]],"ltp":1.89,"tv":1406.64,"id":2258415}]}]}
{"op":"mcm","clk":"1001369616","pt":1580634508837,"mc":[{"id":"1.168215937","rc":[{"batl":[[0,1.94,44.28]],"ltp":1.89,"tv":1406.64,"id":2258415}]}]}
{"op":"mcm","clk":"1001384738","pt":1580634812942,"mc":[{"id":"1.168215937","rc":[{"batl":[[0,1.93,7.57],[1,1.94,44.28],[2,1.95,17.05]],"ltp":1.89,"tv":1406.64,"id":2258415}]}]}
{"op":"mcm","clk":"1001384794","pt":1580634813873,"mc":[{"id":"1.168215937","rc":[{"batb":[[0,2.06,66.63]],"batl":[[0,2.12,4],[1,2.14,5],[2,2.16,7.22]],"ltp":2.06,"tv":528.62,"id":4423910},{"batb":[[0,1.89,6],[1,1.88,79.13],[2,1.87,429.15]],"ltp":1.89,"tv":1406.64,"id":2258415}]}]}
{"op":"mcm","clk":"1001384844","pt":1580634814768,"mc":[{"id":"1.168215937","rc":[{"trd":[[2.12,41.77]],"batl":[[0,2.14,5.21],[1,2.16,5.18],[2,2.18,31.36]],"ltp":2.12,"tv":536.2,"id":4423910}],"tv":1942.85}]}
{"op":"mcm","clk":"1001384889","pt":1580634815582,"mc":[{"id":"1.168215937","rc":[{"trd":[[1.89,39.62]],"batb":[[0,1.88,79.36],[1,1.87,427.11],[2,1.86,422.21]],"ltp":1.89,"tv":1418.18,"id":2258415}],"tv":1954.39}]}
{"op":"mcm","clk":"1001386191","pt":1580634840909,"mc":[{"id":"1.168215937","rc":[{"batl":[[0,2.18,27.36],[1,3,42.01],[2,4.1,153.72]],"ltp":2.12,"tv":536.2,"id":4423910},{"batb":[[0,1.89,5],[1,1.88,79.13],[2,1.87,429.15]],"ltp":1.89,"tv":1418.18,"id":2258415}]}]}
{"op":"mcm","clk":"1001386237","pt":1580634841697,"mc":[{"id":"1.168215937","rc":[{"batl":[[1,2.2,2.03],[2,3,42.01]],"ltp":2.12,"tv":536.2,"id":4423910},{"trd":[[1.88,117.98],[1.89,49.62]],"batb":[[0,1.88,69.13],[1,1.87,427.11],[2,1.86,422.21]],"ltp":1.88,"tv":1448.18,"id":2258415}],"tv":1984.39}]}
{"op":"mcm","clk":"1001393272","pt":1580634967930,"mc":[{"id":"1.168215937","rc":[{"batb":[[0,2.06,63.15]],"ltp":2.12,"tv":536.2,"id":4423910},{"batb":[[0,1.88,73.04]],"ltp":1.88,"tv":1448.18,"id":2258415}]}]}
{"op":"mcm","clk":"1001394449","pt":1580634990884,"mc":[{"id":"1.168215937","rc":[{"trd":[[2.06,192.73]],"batb":[[0,2.06,43.16]],"batl":[[1,3,42.01],[2,4.1,153.72]],"ltp":2.06,"tv":576.2,"id":4423910}],"tv":2024.39}]}
{"op":"mcm","clk":"1001394484","pt":1580634991295,"mc":[{"id":"1.168215937","rc":[{"batb":[[0,2.06,16],[2,2.02,93.38]],"batl":[[1,2.2,2.03],[2,3,42.01]],"ltp":2.06,"tv":576.2,"id":4423910},{"batb":[[0,1.88,94.7]],"ltp":1.88,"tv":1448.18,"id":2258415}]}]}
{"op":"mcm","clk":"1001401480","pt":1580635131923,"mc":[{"id":"1.168215937","rc":[{"batb":[[0,2.06,61.35],[2,2.02,2.15]],"ltp":2.06,"tv":576.2,"id":4423910},{"batb":[[0,1.88,75]],"ltp":1.88,"tv":1448.18,"id":2258415}]}]}
{"op":"mcm","clk":"1001401907","pt":1580635139822,"mc":[{"id":"1.168215937","rc":[{"trd":[[1.88,119.68]],"batb":[[0,1.88,74.15]],"ltp":1.88,"tv":1449.88,"id":2258415}],"tv":2026.08}]}
{"op":"mcm","clk":"1001402485","pt":1580635150248,"mc":[{"id":"1.168215937","rc":[{"batl":[[0,1.93,8.33]],"ltp":1.88,"tv":1449.88,"id":2258415}]}]}
{"op":"mcm","clk":"1001403231","pt":1580635166846,"mc":[{"id":"1.168215937","rc":[{"batl":[[1,3,42.01],[2,4.1,153.72]],"ltp":2.06,"tv":576.2,"id":4423910},{"trd":[[1.88,121.2]],"batb":[[0,1.89,4.14],[1,1.88,73.39],[2,1.87,427.11]],"batl":[[0,1.93,7.57]],"ltp":1.88,"tv":1451.4,"id":2258415}],"tv":2027.6}]}
{"op":"mcm","clk":"1001403269","pt":1580635167467,"mc":[{"id":"1.168215937","rc":[{"batl":[[1,2.2,2.03],[2,3,42.01]],"ltp":2.06,"tv":576.2,"id":4423910},{"batb":[[2,1.87,426.14]],"ltp":1.88,"tv":1451.4,"id":2258415}]}]}
{"op":"mcm","clk":"1001405079","pt":1580635206880,"mc":[{"id":"1.168215937","rc":[{"batl":[[1,3,42.01],[2,4.1,153.72]],"ltp":2.06,"tv":576.2,"id":4423910}]}]}
{"op":"mcm","clk":"1001405085","pt":1580635207085,"mc":[{"id":"1.168215937","rc":[{"batl":[[1,2.2,2.03],[2,3,42.01]],"ltp":2.06,"tv":576.2,"id":4423910}]}]}
{"op":"mcm","clk":"1001405892","pt":1580635224800,"mc":[{"id":"1.168215937","rc":[{"trd":[[1.89,49.66]],"batb":[[0,1.89,4.12]],"ltp":1.89,"tv":1451.44,"id":2258415}],"tv":2027.64}]}
{"op":"mcm","clk":"1001406140","pt":1580635229850,"mc":[{"id":"1.168215937","rc":[{"batb":[[0,1.89,4.14]],"ltp":1.89,"tv":1451.44,"id":2258415}]}]}
{"op":"mcm","clk":"1001410946","pt":1580635330955,"mc":[{"id":"1.168215937","rc":[{"trd":[[2.06,243.41]],"batb":[[0,2.06,48],[1,2.04,12]],"batl":[[0,2.18,2.03],[1,3,42.01],[2,4.1,153.72]],"ltp":2.06,"tv":626.87,"id":4423910}],"tv":2078.31}]}
{"op":"mcm","clk":"1001410965","pt":1580635331366,"mc":[{"id":"1.168215937","rc":[{"batl":[[1,2.2,2.03],[2,3,42.01]],"ltp":2.06,"tv":626.87,"id":4423910},{"batb":[[1,1.88,83.54]],"ltp":1.89,"tv":1451.44,"id":2258415}]}]}
{"op":"mcm","clk":"1001416193","pt":1580635444714,"mc":[{"id":"1.168215937","rc":[{"batb":[[0,2.06,152.57]],"ltp":2.06,"tv":626.87,"id":4423910}]}]}
{"op":"mcm","clk":"1001418965","pt":1580635500896,"mc":[{"id":"1.168215937","rc":[{"batl":[[1,3,42.01],[2,4.1,153.72]],"ltp":2.06,"tv":626.87,"id":4423910},{"trd":[[1.89,53.72]],"batb":[[0,1.89,2.11]],"ltp":1.89,"tv":1455.5,"id":2258415}],"tv":2082.37}]}
{"op":"mcm","clk":"1001418980","pt":1580635501159,"mc":[{"id":"1.168215937","rc":[{"batl":[[1,2.2,2.03],[2,3,42.01]],"ltp":2.06,"tv":626.87,"id":4423910}]}]}
{"op":"mcm","clk":"1001419076","pt":1580635503063,"mc":[{"id":"1.168215937","rc":[{"trd":[[2.06,243.95]],"batb":[[0,2.06,152.3]],"ltp":2.06,"tv":627.41,"id":4423910}],"tv":2082.91}]}
{"op":"mcm","clk":"1001420402","pt":1580635526779,"mc":[{"id":"1.168215937","rc":[{"batb":[[0,2.08,100.79],[1,2.06,152.3],[2,2.04,12]],"ltp":2.06,"tv":627.41,"id":4423910},{"trd":[[1.89,57.93]],"batb":[[0,1.88,83.54],[1,1.87,426.14],[2,1.86,422.1]],"batl":[[0,1.93,7.58]],"ltp":1.89,"tv":1459.71,"id":2258415}],"tv":2087.12}]}
{"op":"mcm","clk":"1001420468","pt":1580635527803,"mc":[{"id":"1.168215937","rc":[{"trd":[[2.12,66.25]],"batb":[[1,2.06,47.73],[2,2.04,14.12]],"batl":[[0,2.12,6.62],[1,2.16,2.16],[2,2.18,2.03]],"ltp":2.12,"tv":651.89,"id":4423910},{"trd":[[1.89,57.93]],"batb":[[0,1.89,3.14],[1,1.88,83.54],[2,1.87,426.14]],"batl":[[0,1.93,7.57],[1,1.94,54.28],[2,1.95,12.05]],"ltp":1.89,"tv":1459.71,"id":2258415}],"tv":2111.61}]}
{"op":"mcm","clk":"1001421965","pt":1580635556864,"mc":[{"id":"1.168215937","rc":[{"trd":[[1.89,61.29]],"batb":[[0,1.89,1.46]],"batl":[[0,1.93,17.57]],"ltp":1.89,"tv":1463.07,"id":2258415}],"tv":2114.97}]}
{"op":"mcm","clk":"1001422668","pt":1580635569933,"mc":[{"id":"1.168215937","rc":[{"batl":[[2,2.18,2]],"ltp":2.12,"tv":651.89,"id":4423910},{"trd":[[1.9,223.11]],"batb":[[0,1.9,573.3],[1,1.89,1.46],[2,1.88,85.75]],"batl":[[0,1.93,7.57]],"ltp":1.9,"tv":1553.41,"id":2258415}],"tv":2205.31}]}
{"op":"mcm","clk":"1001422686","pt":1580635570241,"mc":[{"id":"1.168215937","rc":[{"trd":[[1.9,311.3]],"batb":[[0,1.9,529.2]],"ltp":1.9,"tv":1641.6,"id":2258415}],"tv":2293.5}]}
{"op":"mcm","clk":"1001423396","pt":1580635580949,"mc":[{"id":"1.168215937","rc":[{"batb":[[0,2.06,151.91],[1,2.04,12],[2,2.02,2.18]],"batl":[[1,2.14,2.25],[2,2.16,2]],"ltp":2.12,"tv":651.89,"id":4423910},{"batb":[[0,1.91,3.11],[1,1.9,529.2],[2,1.89,3.51]],"batl":[[1,1.94,44.28]],"ltp":1.9,"tv":1641.6,"id":2258415}]}]}
{"op":"mcm","clk":"1001423846","pt":1580635589954,"mc":[{"id":"1.168215937","rc":[{"batl":[[2,2.16,2.22]],"ltp":2.12,"tv":651.89,"id":4423910},{"batb":[[0,1.91,3.16],[1,1.9,526.2]],"ltp":1.9,"tv":1641.6,"id":2258415}]}]}
{"op":"mcm","clk":"1001425451","pt":1580635608319,"mc":[{"id":"1.168215937","marketDefinition":{"bspMarket":false,"turnInPlayEnabled":true,"persistenceEnabled":true,"marketBaseRate":5.0,"eventId":"29681228","eventTypeId":"2","numberOfWinners":1,"bettingType":"ODDS","marketType":"MATCH_ODDS","marketTime":"2020-02-02T09:23:00.000Z","suspendTime":"2020-02-02T09:23:00.000Z","bspReconciled":false,"complete":true,"inPlay":false,"crossMatching":true,"runnersVoidable":false,"numberOfActiveRunners":2,"betDelay":0,"status":"OPEN","runners":[{"status":"ACTIVE","sortPriority":1,"id":4423910,"name":"Matthew Ebden"},{"status":"ACTIVE","sortPriority":2,"id":2258415,"name":"Lukas Rosol"}],"regulators":["MR_INT"],"countryCode":"IN","discountAllowed":true,"timezone":"UTC","openDate":"2020-02-02T09:30:00.000Z","version":3148345271,"name":"Match Odds","eventName":"Ebden v Rosol"}}]}
{"op":"mcm","clk":"1001425695","pt":1580635610399,"mc":[{"id":"1.168215937","marketDefinition":{"bspMarket":false,"turnInPlayEnabled":true,"persistenceEnabled":true,"marketBaseRate":5.0,"eventId":"29681228","eventTypeId":"2","numberOfWinners":1,"bettingType":"ODDS","marketType":"MATCH_ODDS","marketTime":"2020-02-02T09:23:00.000Z","suspendTime":"2020-02-02T09:23:00.000Z","bspReconciled":false,"complete":true,"inPlay":false,"crossMatching":true,"runnersVoidable":false,"numberOfActiveRunners":2,"betDelay":0,"status":"OPEN","runners":[{"status":"ACTIVE","sortPriority":1,"id":4423910,"name":"Matthew Ebden"},{"status":"ACTIVE","sortPriority":2,"id":2258415,"name":"Lukas Rosol"}],"regulators":["MR_INT"],"countryCode":"IN","discountAllowed":true,"timezone":"UTC","openDate":"2020-02-02T09:23:00.000Z","version":3148345271,"name":"Match Odds","eventName":"Ebden v Rosol"}}]}
{"op":"mcm","clk":"1001425821","pt":1580635611928,"mc":[{"id":"1.168215937","rc":[{"batb":[[2,2,25.21]],"batl":[[2,3,42.01]],"ltp":2.12,"tv":651.89,"id":4423910},{"batl":[[2,1.95,10]],"ltp":1.9,"tv":1641.6,"id":2258415}]}]}
{"op":"mcm","clk":"1001425836","pt":1580635612032,"mc":[{"id":"1.168215937","rc":[{"batl":[[1,3,42.01],[2,4.1,153.72]],"ltp":2.12,"tv":651.89,"id":4423910},{"batb":[[2,1.89,1.46]],"ltp":1.9,"tv":1641.6,"id":2258415}]}]}
{"op":"mcm","clk":"1001429232","pt":1580635664513,"mc":[{"id":"1.168215937","rc":[{"batb":[[0,1.91,27.11],[1,1.9,529.2]],"ltp":1.9,"tv":1641.6,"id":2258415}]}]}
{"op":"mcm","clk":"1001429270","pt":1580635665279,"mc":[{"id":"1.168215937","rc":[{"batb":[[2,1.99,25.46]],"ltp":2.12,"tv":651.89,"id":4423910}]}]}
{"op":"mcm","clk":"1001434552","pt":1580635759305,"mc":[{"id":"1.168215937","rc":[{"batb":[[0,1.91,23.95]],"batl":[[0,1.93,433.64],[1,1.94,54.28]],"ltp":1.9,"tv":1641.6,"id":2258415}]}]}
{"op":"mcm","clk":"1001437099","pt":1580635799635,"mc":[{"id":"1.168215937","rc":[{"batb":[[0,2.06,155.92]],"ltp":2.12,"tv":651.89,"id":4423910},{"trd":[[1.91,23.99]],"batb":[[0,1.9,529.2],[1,1.89,1.46],[2,1.88,80.25]],"ltp":1.91,"tv":1648.73,"id":2258415}],"tv":2300.62}]}
{"op":"mcm","clk":"1001437139","pt":1580635800262,"mc":[{"id":"1.168215937","rc":[{"batb":[[2,2,25.21]],"ltp":2.12,"tv":651.89,"id":4423910}]}]}
{"op":"mcm","clk":"1001437477","pt":1580635804551,"mc":[{"id":"1.168215937","rc":[{"batl":[[0,1.93,426.07]],"ltp":1.91,"tv":1648.73,"id":2258415}]}]}
{"op":"mcm","clk":"1001437632","pt":1580635807277,"mc":[{"id":"1.168215937","rc":[{"batl":[[1,2.2,2.53],[2,3,42.01]],"ltp":2.12,"tv":651.89,"id":4423910}]}]}
{"op":"mcm","clk":"1001440408","pt":1580635860950,"mc":[{"id":"1.168215937","rc":[{"batb":[[2,2,67.22]],"batl":[[1,2.2,36.98]],"ltp":2.12,"tv":651.89,"id":4423910},{"trd":[[1.9,343.42]],"batb":[[0,1.9,513.14]],"ltp":1.9,"tv":1680.85,"id":2258415}],"tv":2332.74}]}
{"op":"mcm","clk":"1001440453","pt":1580635861571,"mc":[{"id":"1.168215937","rc":[{"batl":[[1,2.2,2.53],[2,2.22,33.61]],"ltp":2.12,"tv":651.89,"id":4423910},{"trd":[[1.9,352.86]],"batb":[[0,1.9,508.42]],"ltp":1.9,"tv":1690.28,"id":2258415}],"tv":2342.18}]}
{"op":"mcm","clk":"1001443744","pt":1580635920895,"mc":[{"id":"1.168215937","rc":[{"trd":[[2.12,79.33]],"batl":[[0,2.2,2.62],[1,2.22,33.61],[2,3,42.01]],"ltp":2.12,"tv":664.97,"id":4423910},{"trd":[[1.9,1369.68]],"batb":[[0,1.9,2]],"batl":[[0,1.93,10]],"ltp":1.9,"tv":2707.1,"id":2258415}],"tv":3372.07}]}
{"op":"mcm","clk":"1001443802","pt":1580635921924,"mc":[{"id":"1.168215937","rc":[{"trd":[[2.12,79.41]],"batb":[[0,2.08,10],[1,2.06,155.92],[2,2.04,12]],"batl":[[0,2.2,2.53]],"ltp":2.12,"tv":665.05,"id":4423910},{"trd":[[1.87,558.57],[1.88,281.7],[1.89,64.31],[1.9,1373.68]],"batb":[[0,1.88,2],[1,1.87,309.14],[2,1.86,420.1]],"batl":[[0,1.94,54.28],[1,1.95,10],[2,2,44.8]],"ltp":1.87,"tv":3096.53,"id":2258415}],"tv":3761.58}]}
{"op":"mcm","clk":"1001443843","pt":1580635922706,"mc":[{"id":"1.168215937","rc":[{"batb":[[0,2.08,72.35]],"ltp":2.12,"tv":665.05,"id":4423910},{"trd":[[1.87,1096.24],[1.88,289.7]],"batb":[[0,1.87,40.31],[1,1.86,461.96],[2,1.85,420.1]],"ltp":1.87,"tv":3642.19,"id":2258415}],"tv":4307.25}]}
{"op":"mcm","clk":"1001444200","pt":1580635929742,"mc":[{"id":"1.168215937","rc":[{"trd":[[2.08,186.89]],"batb":[[0,2.06,143.92],[1,2.04,12],[2,2.02,35.71]],"batl":[[0,2.08,99.36],[1,2.2,2.53],[2,2.22,33.61]],"ltp":2.08,"tv":816.65,"id":4423910},{"batb":[[0,1.91,2.05],[1,1.9,2.05],[2,1.87,40.31]],"batl":[[0,1.94,44.28]],"ltp":1.87,"tv":3642.19,"id":2258415}],"tv":4458.85}]}
{"op":"mcm","clk":"1001444244","pt":1580635930418,"mc":[{"id":"1.168215937","rc":[{"trd":[[2.06,382.05]],"batb":[[0,2.06,74.87],[2,2.02,11]],"ltp":2.06,"tv":954.75,"id":4423910},{"batb":[[2,1.88,80.05]],"ltp":1.87,"tv":3642.19,"id":2258415}],"tv":4596.95}]}
{"op":"mcm","clk":"1001444277","pt":1580635931241,"mc":[{"id":"1.168215937","rc":[{"batb":[[0,2.06,70.86],[2,2.02,79.05]],"ltp":2.06,"tv":954.75,"id":4423910},{"batb":[[2,1.88,118.69]],"ltp":1.87,"tv":3642.19,"id":2258415}]}]}
{"op":"mcm","clk":"1001444762","pt":1580635941338,"mc":[{"id":"1.168215937","rc":[{"batb":[[0,2.06,80.86]],"batl":[[0,2.2,2.53],[1,2.22,33.61],[2,3,42.01]],"ltp":2.06,"tv":954.75,"id":4423910},{"batb":[[0,1.89,2.11],[1,1.88,118.69],[2,1.87,40.31]],"ltp":1.87,"tv":3642.19,"id":2258415}]}]}
{"op":"mcm","clk":"1001444827","pt":1580635942931,"mc":[{"id":"1.168215937","rc":[{"trd":[[2.06,563.26]],"batb":[[0,2.04,119.09],[1,2.02,79.05],[2,2,67.22]],"ltp":2.06,"tv":1135.97,"id":4423910},{"trd":[[1.94,20.71]],"batb":[[2,1.87,112.62]],"batl":[[0,1.94,23.58]],"ltp":1.94,"tv":3662.9,"id":2258415}],"tv":4798.87}]}
{"op":"mcm","clk":"1001444834","pt":1580635943135,"mc":[{"id":"1.168215937","rc":[{"batb":[[0,2.06,11],[1,2.04,119.09],[2,2.02,79.05]],"ltp":2.06,"tv":1135.97,"id":4423910}]}]}
{"op":"mcm","clk":"1001447160","pt":1580636000789,"mc":[{"id":"1.168215937","rc":[{"trd":[[2.04,37.49],[2.06,574.26]],"batb":[[0,2.04,93.59],[1,2.02,79.05],[2,2,67.22]],"batl":[[0,2.12,3.11],[1,2.2,2.53],[2,2.22,33.61]],"ltp":2.04,"tv":1184.46,"id":4423910},{"trd":[[1.94,67.86],[1.95,186.47],[1.97,38.83]],"batb":[[0,1.89,76.03]],"batl":[[0,1.97,11],[1,2,44.8],[2,2.1,10.51]],"ltp":1.97,"tv":3780.49,"id":2258415}],"tv":4964.96}]}
{"op":"mcm","clk":"1001447177","pt":1580636001509,"mc":[{"id":"1.168215937","rc":[{"batb":[[2,2,42.01]],"ltp":2.04,"tv":1184.46,"id":4423910},{"batb":[[2,1.87,40.31]],"batl":[[0,1.96,11.11],[1,1.97,11],[2,2,44.8]],"ltp":1.97,"tv":3780.49,"id":2258415}]}]}
{"op":"mcm","clk":"1001447402","pt":1580636009727,"mc":[{"id":"1.168215937","rc":[{"batb":[[0,2.06,12.16],[1,2.04,93.59],[2,2.02,79.05]],"ltp":2.04,"tv":1184.46,"id":4423910},{"batl":[[0,1.92,111.43],[1,1.94,11.16],[2,1.96,11.11]],"ltp":1.97,"tv":3780.49,"id":2258415}]}]}
{"op":"mcm","clk":"1001448622","pt":1580636044770,"mc":[{"id":"1.168215937","rc":[{"batb":[[2,2.02,84.05]],"batl":[[1,2.14,4],[2,2.2,2.53]],"ltp":2.04,"tv":1184.46,"id":4423910},{"batb":[[0,1.9,71.44],[1,1.89,4.11],[2,1.88,124.69]],"batl":[[1,1.93,13.02],[2,1.94,11.16]],"ltp":1.97,"tv":3780.49,"id":2258415}]}]}
{"op":"mcm","clk":"1001448818","pt":1580636050864,"mc":[{"id":"1.168215937","rc":[{"trd":[[1.9,1393.68]],"batb":[[0,1.9,61.44]],"ltp":1.9,"tv":3800.49,"id":2258415}],"tv":4984.96}]}
{"op":"mcm","clk":"1001448823","pt":1580636051069,"mc":[{"id":"1.168215937","rc":[{"batb":[[0,2.08,15],[1,2.06,12.16],[2,2.04,93.59]],"ltp":2.04,"tv":1184.46,"id":4423910}]}]}
{"op":"mcm","clk":"1001448914","pt":1580636054847,"mc":[{"id":"1.168215937","rc":[{"batb":[[2,2.04,12]],"ltp":2.04,"tv":1184.46,"id":4423910}]}]}
{"op":"mcm","clk":"1001449191","pt":1580636064569,"mc":[{"id":"1.168215937","rc":[{"batl":[[0,1.92,112.32]],"ltp":1.9,"tv":3800.49,"id":2258415}]}]}
{"op":"mcm","clk":"1001449314","pt":1580636066897,"mc":[{"id":"1.168215937","rc":[{"trd":[[1.92,80.22]],"batl":[[0,1.92,73.14]],"ltp":1.92,"tv":3878.89,"id":2258415}],"tv":5063.36}]}
{"op":"mcm","clk":"1001449340","pt":1580636067468,"mc":[{"id":"1.168215937","rc":[{"batb":[[2,2.04,48.78]],"ltp":2.04,"tv":1184.46,"id":4423910},{"trd":[[1.9,1397.68]],"batb":[[0,1.9,59.44],[2,1.88,85.16]],"ltp":1.9,"tv":3882.89,"id":2258415}],"tv":5067.36}]}
{"op":"mcm","clk":"1001450838","pt":1580636107973,"mc":[{"id":"1.168215937","rc":[{"batl":[[0,2.12,3.95]],"ltp":2.04,"tv":1184.46,"id":4423910}]}]}
{"op":"mcm","clk":"1001451215","pt":1580636118293,"mc":[{"id":"1.168215937","rc":[{"trd":[[2.08,188.57]],"batb":[[0,2.08,14.16]],"batl":[[0,2.12,3.11]],"ltp":2.08,"tv":1186.14,"id":4423910},{"batb":[[0,1.9,65.44]],"ltp":1.9,"tv":3882.89,"id":2258415}],"tv":5069.04}]}
{"op":"mcm","clk":"1001451529","pt":1580636130732,"mc":[{"id":"1.168215937","rc":[{"batl":[[2,2.2,36.98]],"ltp":2.08,"tv":1186.14,"id":4423910},{"batb":[[0,1.9,6]],"ltp":1.9,"tv":3882.89,"id":2258415}]}]}
{"op":"mcm","clk":"1001451552","pt":1580636131258,"mc":[{"id":"1.168215937","marketDefinition":{"bspMarket":false,"turnInPlayEnabled":true,"persistenceEnabled":true,"marketBaseRate":5.0,"eventId":"29681228","eventTypeId":"2","numberOfWinners":1,"bettingType":"ODDS","marketType":"MATCH_ODDS","marketTime":"2020-02-02T09:23:00.000Z","suspendTime":"2020-02-02T09:23:00.000Z","bspReconciled":false,"complete":true,"inPlay":true,"crossMatching":true,"runnersVoidable":false,"numberOfActiveRunners":2,"betDelay":3,"status":"OPEN","runners":[{"status":"ACTIVE","sortPriority":1,"id":4423910,"name":"Matthew Ebden"},{"status":"ACTIVE","sortPriority":2,"id":2258415,"name":"Lukas Rosol"}],"regulators":["MR_INT"],"countryCode":"IN","discountAllowed":true,"timezone":"UTC","openDate":"2020-02-02T09:23:00.000Z","version":3148350954,"name":"Match Odds","eventName":"Ebden v Rosol"},"rc":[{"batb":[[0,1.11,37.97],[1,1.03,9],[2,1.02,25.41]],"batl":[[0,2.2,2.53],[1,3,42.01],[2,1000,0.02]],"ltp":2.08,"tv":1186.14,"id":4423910},{"batb":[[0,1.87,40.31],[1,1.86,420.1],[2,1.85,420.1]],"batl":[[0,2,2.79],[1,2.1,10.51],[2,1000,0.02]],"ltp":1.9,"tv":3882.89,"id":2258415}]}]}
{"op":"mcm","clk":"1001451685","pt":1580636134723,"mc":[{"id":"1.168215937","rc":[{"batb":[[0,1.99,42.01],[1,1.11,37.97],[2,1.1,378.72]],"batl":[[0,2.2,36.98]],"ltp":2.08,"tv":1186.14,"id":4423910},{"batl":[[1,2.02,41.17],[2,2.1,10.51]],"ltp":1.9,"tv":3882.89,"id":2258415}]}]}
{"op":"mcm","clk":"1001451703","pt":1580636135132,"mc":[{"id":"1.168215937","rc":[{"batb":[[0,1.11,37.97],[1,1.1,378.72],[2,1.03,8.9]],"batl":[[0,2.2,2.53]],"ltp":2.08,"tv":1186.14,"id":4423910},{"batl":[[1,2.1,10.51],[2,1000,0.02]],"ltp":1.9,"tv":3882.89,"id":2258415}]}]}
{"op":"mcm","clk":"1001451829","pt":1580636138439,"mc":[{"id":"1.168215937","rc":[{"batb":[[0,1.2,189.42],[1,1.11,37.86],[2,1.1,378.72]],"ltp":2.08,"tv":1186.14,"id":4423910}]}]}
{"op":"mcm","clk":"1001451919","pt":1580636140924,"mc":[{"id":"1.168215937","rc":[{"batb":[[0,1.91,42.56],[1,1.87,40.31],[2,1.86,420.1]],"ltp":1.9,"tv":3882.89,"id":2258415}]}]}
{"op":"mcm","clk":"1001451953","pt":1580636141951,"mc":[{"id":"1.168215937","rc":[{"trd":[[2.2,18.26]],"batb":[[0,1.4,75.73],[1,1.3,75.72],[2,1.2,189.41]],"batl":[[0,3,42.01],[1,1000,0.02],[2,1000,0]],"ltp":2.2,"tv":1188.67,"id":4423910},{"trd":[[1.83,843.24],[1.84,840.19],[1.85,1263.44],[1.86,903.27],[1.87,1176.86],[1.91,109.11]],"batb":[[0,1.81,420.1],[1,1.2,189.42],[2,1.11,37.86]],"ltp":1.83,"tv":7412.44,"id":2258415}],"tv":8601.12}]}
{"op":"mcm","clk":"1001451997","pt":1580636142644,"mc":[{"id":"1.168215937","rc":[{"batb":[[0,2.16,89.7],[1,2.06,103.39],[2,1.4,75.73]],"ltp":2.2,"tv":1188.67,"id":4423910},{"batb":[[1,1.79,85.53],[2,1.67,108.74]],"ltp":1.83,"tv":7412.44,"id":2258415}]}]}
{"op":"mcm","clk":"1001452037","pt":1580636143656,"mc":[{"id":"1.168215937","rc":[{"batl":[[0,1.92,42.01],[1,2,2.79],[2,2.1,10.51]],"ltp":1.83,"tv":7412.44,"id":2258415}]}]}
{"op":"mcm","clk":"1001452099","pt":1580636144938,"mc":[{"id":"1.168215937","rc":[{"batb":[[2,1.76,172.52]],"batl":[[0,1.82,279.02],[1,1.84,251.89],[2,1.92,42.01]],"ltp":1.83,"tv":7412.44,"id":2258415}]}]}
{"op":"mcm","clk":"1001452139","pt":1580636145917,"mc":[{"id":"1.168215937","rc":[{"batb":[[2,1.5,75.72]],"ltp":2.2,"tv":1188.67,"id":4423910},{"batb":[[0,1.79,85.53],[1,1.76,172.52],[2,1.74,298.33]],"ltp":1.83,"tv":7412.44,"id":2258415}]}]}
{"op":"mcm","clk":"1001452176","pt":1580636147363,"mc":[{"id":"1.168215937","rc":[{"batb":[[1,2.1,37.81],[2,2.06,103.39]],"batl":[[0,2.34,31.09],[1,3,42.01],[2,1000,0.02]],"ltp":2.2,"tv":1188.67,"id":4423910},{"batb":[[2,1.74,354.62]],"ltp":1.83,"tv":7412.44,"id":2258415}]}]}
{"op":"mcm","clk":"1001452203","pt":1580636148251,"mc":[{"id":"1.168215937","rc":[{"batb":[[1,1.78,914.13],[2,1.76,683.36]],"batl":[[2,1.86,480.59]],"ltp":1.83,"tv":7412.44,"id":2258415}]}]}
{"op":"mcm","clk":"1001452347","pt":1580636152336,"mc":[{"id":"1.168215937","rc":[{"batb":[[0,2.06,103.39],[1,1.6,75.72],[2,1.5,75.72]],"batl":[[0,3,42.01],[1,1000,0.02],[2,1000,0]],"ltp":2.2,"tv":1188.67,"id":4423910},{"batb":[[0,1.78,914.13],[1,1.76,510.84],[2,1.67,108.74]],"batl":[[0,1.86,480.59],[1,1.88,497.4],[2,2,2.79]],"ltp":1.83,"tv":7412.44,"id":2258415}]}]}
{"op":"mcm","clk":"1001452559","pt":1580636157250,"mc":[{"id":"1.168215937","rc":[{"batb":[[2,1.73,253.75]],"batl":[[0,1.79,241.08],[1,1.81,265.53],[2,1.86,480.59]],"ltp":1.83,"tv":7412.44,"id":2258415}]}]}
{"op":"mcm","clk":"1001452631","pt":1580636158567,"mc":[{"id":"1.168215937","rc":[{"batb":[[2,1.67,108.74]],"batl":[[0,1.86,480.59],[1,1.88,497.4],[2,2,2.79]],"ltp":1.83,"tv":7412.44,"id":2258415}]}]}
{"op":"mcm","clk":"1001452770","pt":1580636161457,"mc":[{"id":"1.168215937","rc":[{"batl":[[2,1.89,163.85]],"ltp":1.83,"tv":7412.44,"id":2258415}]}]}
{"op":"mcm","clk":"1001453580","pt":1580636179016,"mc":[{"id":"1.168215937","rc":[{"batl":[[0,1.89,163.85],[1,1.91,224.46],[2,2,2.79]],"ltp":1.83,"tv":7412.44,"id":2258415}]}]}
{"op":"mcm","clk":"1001453733","pt":1580636181608,"mc":[{"id":"1.168215937","rc":[{"trd":[[2.16,36.05]],"ltp":2.16,"tv":1202.69,"id":4423910},{"batb":[[0,1.83,209.33],[1,1.81,261.83],[2,1.8,10.49]],"batl":[[0,1.89,961.75]],"ltp":1.83,"tv":7412.44,"id":2258415}],"tv":8615.14}]}
{"op":"mcm","clk":"1001453778","pt":1580636182794,"mc":[{"id":"1.168215937","rc":[{"batb":[[1,1.97,119.05],[2,1.6,75.72]],"ltp":2.16,"tv":1202.69,"id":4423910},{"batb":[[0,1.87,74.83],[1,1.83,209.33],[2,1.81,261.83]],"ltp":1.83,"tv":7412.44,"id":2258415}]}]}
{"op":"mcm","clk":"1001453802","pt":1580636183202,"mc":[{"id":"1.168215937","rc":[{"batb":[[1,2.02,41.17],[2,1.97,119.05]],"batl":[[0,2.26,32.77],[1,3,42.01],[2,1000,0.02]],"ltp":2.16,"tv":1202.69,"id":4423910},{"batl":[[2,1.97,42.01]],"ltp":1.83,"tv":7412.44,"id":2258415}]}]}
{"op":"mcm","clk":"1001454048","pt":1580636188629,"mc":[{"id":"1.168215937","rc":[{"batb":[[1,1.84,494.03],[2,1.83,209.33]],"batl":[[2,1.93,480.59]],"ltp":1.83,"tv":7412.44,"id":2258415}]}]}
{"op":"mcm","clk":"1001454085","pt":1580636189305,"mc":[{"id":"1.168215937","rc":[{"batb":[[0,2.02,41.17],[1,1.97,119.05],[2,1.6,75.72]],"ltp":2.16,"tv":1202.69,"id":4423910},{"batb":[[0,1.84,494.03],[1,1.82,510.84],[2,1.8,52.09]],"batl":[[0,1.93,480.59],[1,1.95,497.4],[2,1.97,42.01]],"ltp":1.83,"tv":7412.44,"id":2258415}]}]}
{"op":"mcm","clk":"1001454121","pt":1580636190231,"mc":[{"id":"1.168215937","rc":[{"batb":[[0,1.97,119.05],[1,1.6,75.72],[2,1.5,75.72]],"batl":[[0,3,42.01],[1,1000,0.02],[2,1000,0]],"ltp":2.16,"tv":1202.69,"id":4423910},{"batb":[[2,1.78,420.1]],"batl":[[2,2,2.79]],"ltp":1.83,"tv":7412.44,"id":2258415}]}]}
{"op":"mcm","clk":"1001454201","pt":1580636192235,"mc":[{"id":"1.168215937","rc":[{"batl":[[2,1.97,189.68]],"ltp":1.83,"tv":7412.44,"id":2258415}]}]}
{"op":"mcm","clk":"1001454302","pt":1580636194634,"mc":[{"id":"1.168215937","rc":[{"batl":[[2,2,2.79]],"ltp":1.83,"tv":7412.44,"id":2258415}]}]}
{"op":"mcm","clk":"1001454338","pt":1580636196018,"mc":[{"id":"1.168215937","rc":[{"batl":[[0,1.86,29.41],[1,1.93,480.59],[2,1.95,497.4]],"ltp":1.83,"tv":7412.44,"id":2258415}]}]}
{"op":"mcm","clk":"1001454382","pt":1580636197615,"mc":[{"id":"1.168215937","rc":[{"batb":[[2,1.8,283.84]],"batl":[[1,1.87,243.05],[2,1.89,231.73]],"ltp":1.83,"tv":7412.44,"id":2258415}]}]}
{"op":"mcm","clk":"1001454407","pt":1580636198546,"mc":[{"id":"1.168215937","rc":[{"batb":[[2,1.78,420.1]],"batl":[[1,1.93,480.59],[2,1.95,497.4]],"ltp":1.83,"tv":7412.44,"id":2258415}]}]}
{"op":"mcm","clk":"1001454503","pt":1580636200826,"mc":[{"id":"1.168215937","rc":[{"batb":[[0,1.78,420.1],[1,1.74,93.87],[2,1.4,75.73]],"ltp":1.83,"tv":7412.44,"id":2258415}]}]}
{"op":"mcm","clk":"1001454531","pt":1580636201657,"mc":[{"id":"1.168215937","rc":[{"batb":[[2,1.71,269.68]],"ltp":1.83,"tv":7412.44,"id":2258415}]}]}
{"op":"mcm","clk":"1001454605","pt":1580636203927,"mc":[{"id":"1.168215937","rc":[{"trd":[[2.36,5.72]],"batl":[[0,2.46,8.71],[1,2.56,429.24],[2,3,42.01]],"ltp":2.36,"tv":1208.41,"id":4423910},{"trd":[[1.74,7.75],[1.78,840.21]],"batb":[[0,1.74,86.11],[1,1.71,269.68],[2,1.69,330.07]],"batl":[[0,1.77,254.66],[1,1.79,275.15],[2,1.86,2559.02]],"ltp":1.74,"tv":8260.4,"id":2258415}],"tv":9468.82}]}
{"op":"mcm","clk":"1001454619","pt":1580636204341,"mc":[{"id":"1.168215937","rc":[{"batb":[[0,2.24,81.12],[1,2.1,98.2],[2,1.6,75.72]],"ltp":2.36,"tv":1208.41,"id":4423910}]}]}
{"op":"mcm","clk":"1001454662","pt":1580636205319,"mc":[{"id":"1.168215937","rc":[{"batb":[[1,2.18,35.29],[2,2.1,98.2]],"batl":[[0,2.46,37.28]],"ltp":2.36,"tv":1208.41,"id":4423910},{"batb":[[2,1.69,390.56]],"batl":[[2,1.86,2601.03]],"ltp":1.74,"tv":8260.4,"id":2258415}]}]}
{"op":"mcm","clk":"1001454718","pt":1580636206921,"mc":[{"id":"1.168215937","rc":[{"batl":[[2,1.82,341.35]],"ltp":1.74,"tv":8260.4,"id":2258415}]}]}
{"op":"mcm","clk":"1001454797","pt":1580636209129,"mc":[{"id":"1.168215937","rc":[{"batl":[[2,1.86,2571.62]],"ltp":1.74,"tv":8260.4,"id":2258415}]}]}
{"op":"mcm","clk":"1001454822","pt":1580636210055,"mc":[{"id":"1.168215937","rc":[{"batb":[[1,1.71,763.71],[2,1.69,901.4]],"batl":[[2,1.81,480.59]],"ltp":1.74,"tv":8260.4,"id":2258415}]}]}
{"op":"mcm","clk":"1001454979","pt":1580636213454,"mc":[{"id":"1.168215937","rc":[{"batl":[[0,2.46,28.57]],"ltp":2.36,"tv":1208.41,"id":4423910}]}]}
{"op":"mcm","clk":"1001455137","pt":1580636216440,"mc":[{"id":"1.168215937","rc":[{"trd":[[2.36,15.88]],"ltp":2.36,"tv":1218.57,"id":4423910},{"trd":[[1.74,50.94]],"batb":[[0,1.74,57.63],[2,1.7,9.88]],"ltp":1.74,"tv":8303.59,"id":2258415}],"tv":9522.17}]}
{"op":"mcm","clk":"1001455465","pt":1580636223586,"mc":[{"id":"1.168215937","rc":[{"batl":[[1,3,42.01],[2,1000,0.02]],"ltp":2.36,"tv":1218.57,"id":4423910},{"batb":[[1,1.71,494.03],[2,1.69,571.33]],"batl":[[0,1.81,480.59],[1,1.83,497.4],[2,1.86,42.01]],"ltp":1.74,"tv":8303.59,"id":2258415}]}]}
{"op":"mcm","clk":"1001455510","pt":1580636224262,"mc":[{"id":"1.168215937","rc":[{"batb":[[1,2.1,98.2],[2,1.6,75.72]],"batl":[[0,3,42.01],[1,1000,0.02],[2,1000,0]],"ltp":2.36,"tv":1218.57,"id":4423910},{"batb":[[2,1.69,510.84]],"batl":[[2,2,2.79]],"ltp":1.74,"tv":8303.59,"id":2258415}]}]}
{"op":"mcm","clk":"1001455547","pt":1580636225141,"mc":[{"id":"1.168215937","rc":[{"batb":[[0,1.6,75.72],[1,1.5,75.72],[2,1.4,75.73]],"ltp":2.36,"tv":1218.57,"id":4423910},{"batb":[[0,1.71,494.03],[1,1.69,510.84],[2,1.31,756.19]],"ltp":1.74,"tv":8303.59,"id":2258415}]}]}
{"op":"mcm","clk":"1001455724","pt":1580636229566,"mc":[{"id":"1.168215937","rc":[{"batb":[[0,2.32,10.59],[1,1.6,75.72],[2,1.5,75.72]],"ltp":2.36,"tv":1218.57,"id":4423910},{"batb":[[0,1.72,10.11],[1,1.71,494.03],[2,1.69,510.84]],"ltp":1.74,"tv":8303.59,"id":2258415}]}]}
{"op":"mcm","clk":"1001455882","pt":1580636232768,"mc":[{"id":"1.168215937","rc":[{"batb":[[1,1.7,75.72],[2,1.6,75.72]],"ltp":2.36,"tv":1218.57,"id":4423910}]}]}
{"op":"mcm","clk":"1001456116","pt":1580636237884,"mc":[{"id":"1.168215937","rc":[{"trd":[[1.72,10.2]],"batb":[[0,1.72,5.01]],"ltp":1.72,"tv":8313.79,"id":2258415}],"tv":9532.36}]}
{"op":"mcm","clk":"1001456569","pt":1580636248095,"mc":[{"id":"1.168215937","rc":[{"batb":[[0,1.7,75.72],[1,1.6,75.72],[2,1.5,75.72]],"ltp":2.36,"tv":1218.57,"id":4423910},{"batb":[[0,1.71,494.03],[1,1.69,510.84],[2,1.31,756.19]],"ltp":1.72,"tv":8313.79,"id":2258415}]}]}
{"op":"mcm","clk":"1001456681","pt":1580636251083,"mc":[{"id":"1.168215937","rc":[{"batl":[[0,2.4,6.34],[1,3,42.01],[2,1000,0.02]],"ltp":2.36,"tv":1218.57,"id":4423910},{"batl":[[0,1.74,8.06],[1,1.81,480.59],[2,1.83,497.4]],"ltp":1.72,"tv":8313.79,"id":2258415}]}]}
{"op":"mcm","clk":"1001456913","pt":1580636256894,"mc":[{"id":"1.168215937","rc":[{"trd":[[1.71,835.29]],"batb":[[0,1.71,76.39]],"ltp":1.71,"tv":9149.08,"id":2258415}],"tv":10367.65}]}
{"op":"mcm","clk":"1001457070","pt":1580636260872,"mc":[{"id":"1.168215937","rc":[{"batb":[[0,1.31,756.19],[1,1.3,75.72],[2,1.25,378.62]],"ltp":1.71,"tv":9149.08,"id":2258415}]}]}
{"op":"mcm","clk":"1001457086","pt":1580636261288,"mc":[{"id":"1.168215937","rc":[{"trd":[[2.4,6.34]],"batl":[[0,3,42.01],[1,1000,0.02],[2,1000,0]],"ltp":2.4,"tv":1224.91,"id":4423910},{"trd":[[1.71,844.19]],"batl":[[0,1.71,5.81],[1,1.74,8.06],[2,1.81,480.59]],"ltp":1.71,"tv":9157.97,"id":2258415}],"tv":10382.89}]}
{"op":"mcm","clk":"1001457467","pt":1580636268707,"mc":[{"id":"1.168215937","rc":[{"batl":[[1,1000,2.03]],"ltp":2.4,"tv":1224.91,"id":4423910}]}]}
{"op":"mcm","clk":"1001457491","pt":1580636269221,"mc":[{"id":"1.168215937","rc":[{"batl":[[1,1000,0.02]],"ltp":2.4,"tv":1224.91,"id":4423910}]}]}
{"op":"mcm","clk":"1001457622","pt":1580636271604,"mc":[{"id":"1.168215937","rc":[{"trd":[[1.71,855.8]],"batb":[[0,1.71,18.56],[1,1.31,756.19],[2,1.3,75.72]],"batl":[[0,1.81,480.59],[1,1.83,497.4],[2,2,3.67]],"ltp":1.71,"tv":9169.58,"id":2258415}],"tv":10394.5}]}
{"op":"mcm","clk":"1001457652","pt":1580636272338,"mc":[{"id":"1.168215937","rc":[{"trd":[[2.22,0.04]],"ltp":2.22,"tv":1224.92,"id":4423910},{"trd":[[1.81,0.01]],"batl":[[0,1.81,480.58]],"ltp":1.81,"tv":9169.59,"id":2258415}],"tv":10394.52}]}
{"op":"mcm","clk":"1001457768","pt":1580636274444,"mc":[{"id":"1.168215937","rc":[{"batb":[[0,2.36,10.16],[1,1.7,75.72],[2,1.6,75.72]],"ltp":2.22,"tv":1224.92,"id":4423910},{"batb":[[1,1.7,9.87],[2,1.31,756.19]],"ltp":1.81,"tv":9169.59,"id":2258415}]}]}
{"op":"mcm","clk":"1001457893","pt":1580636277839,"mc":[{"id":"1.168215937","rc":[{"batb":[[0,1.7,75.72],[1,1.6,75.72],[2,1.5,75.72]],"ltp":2.22,"tv":1224.92,"id":4423910},{"batb":[[1,1.31,756.19],[2,1.3,75.72]],"ltp":1.81,"tv":9169.59,"id":2258415}]}]}
{"op":"mcm","clk":"1001457906","pt":1580636278043,"mc":[{"id":"1.168215937","rc":[{"batb":[[0,1.31,756.19],[1,1.3,75.72],[2,1.25,378.62]],"ltp":1.81,"tv":9169.59,"id":2258415}]}]}
{"op":"mcm","clk":"1001458036","pt":1580636280935,"mc":[{"id":"1.168215937","rc":[{"batl":[[0,2.84,8.27],[1,3,42.01],[2,3.05,539.76]],"ltp":2.22,"tv":1224.92,"id":4423910},{"batl":[[0,1.58,19.17],[1,1.6,1061],[2,1.72,8.54]],"ltp":1.81,"tv":9169.59,"id":2258415}]}]}
{"op":"mcm","clk":"1001458081","pt":1580636281948,"mc":[{"id":"1.168215937","rc":[{"batb":[[0,2.44,28.57],[1,1.7,75.72],[2,1.6,75.72]],"batl":[[0,2.8,22.69],[1,2.84,8.27],[2,3,42.01]],"ltp":2.22,"tv":1224.92,"id":4423910},{"trd":[[1.58,37.12]],"batb":[[0,1.57,349],[1,1.56,297.44],[2,1.31,756.19]],"batl":[[0,1.6,1061.61],[1,1.62,260.76],[2,1.63,187.75]],"ltp":1.58,"tv":9206.71,"id":2258415}],"tv":10431.64}]}
{"op":"mcm","clk":"1001458098","pt":1580636282318,"mc":[{"id":"1.168215937","rc":[{"batl":[[1,3,42.01],[2,1000,0.02]],"ltp":2.22,"tv":1224.92,"id":4423910},{"batl":[[0,1.62,260.76],[1,1.63,187.75],[2,1.69,42.01]],"ltp":1.58,"tv":9206.71,"id":2258415}]}]}
{"op":"mcm","clk":"1001458135","pt":1580636283041,"mc":[{"id":"1.168215937","rc":[{"batb":[[0,1.56,74.78],[1,1.31,756.19],[2,1.25,378.62]],"batl":[[0,1.69,42.01],[1,1.81,480.58],[2,1.83,497.4]],"ltp":1.58,"tv":9206.71,"id":2258415}]}]}
{"op":"mcm","clk":"1001458206","pt":1580636284747,"mc":[{"id":"1.168215937","rc":[{"batb":[[0,1.8,75.72]],"batl":[[0,3,42.01],[1,1000,0.02],[2,1000,0]],"ltp":2.22,"tv":1224.92,"id":4423910},{"batb":[[0,1.31,756.19],[1,1.25,378.62],[2,1.2,189.41]],"batl":[[0,1.81,480.58],[1,1.83,497.4],[2,2,3.67]],"ltp":1.58,"tv":9206.71,"id":2258415}]}]}
{"op":"mcm","clk":"1001458239","pt":1580636285942,"mc":[{"id":"1.168215937","rc":[{"batb":[[0,1.55,207.91],[1,1.54,233.43],[2,1.31,756.19]],"batl":[[0,1.59,237.91],[1,1.6,200.9],[2,1.81,480.58]],"ltp":1.58,"tv":9206.71,"id":2258415}]}]}
{"op":"mcm","clk":"1001458274","pt":1580636286657,"mc":[{"id":"1.168215937","rc":[{"batl":[[2,2,3.67]],"ltp":1.58,"tv":9206.71,"id":2258415}]}]}
{"op":"mcm","clk":"1001458375","pt":1580636289662,"mc":[{"id":"1.168215937","rc":[{"trd":[[1.55,415.82]],"batb":[[0,1.54,233.43],[1,1.31,756.19],[2,1.25,378.62]],"batl":[[0,1.55,252.84],[1,1.59,237.91],[2,1.6,200.9]],"ltp":1.55,"tv":9622.53,"id":2258415}],"tv":10847.46}]}
{"op":"mcm","clk":"1001458494","pt":1580636292868,"mc":[{"id":"1.168215937","rc":[{"batb":[[0,1.31,756.19],[1,1.25,378.62],[2,1.2,189.41]],"batl":[[1,2,3.67],[2,2.1,10.51]],"ltp":1.55,"tv":9622.53,"id":2258415}]}]}
{"op":"mcm","clk":"1001458643","pt":1580636295864,"mc":[{"id":"1.168215937","rc":[{"trd":[[3,42.01]],"batl":[[0,1000,0.02],[1,1000,0]],"ltp":3.0,"tv":1266.93,"id":4423910},{"trd":[[1.48,0.02],[1.5,84.02]],"batb":[[0,1.45,239.73],[1,1.44,308.23],[2,1.31,756.18]],"batl":[[0,1.46,4459.36],[1,1.55,252.84],[2,1.7,266.06]],"ltp":1.48,"tv":9706.57,"id":2258415}],"tv":10973.51}]}
{"op":"mcm","clk":"1001458799","pt":1580636300243,"mc":[{"id":"1.168215937","rc":[{"batl":[[1,1.55,252.85]],"ltp":1.48,"tv":9706.57,"id":2258415}]}]}
{"op":"mcm","clk":"1001459011","pt":1580636304870,"mc":[{"id":"1.168215937","rc":[{"trd":[[3.15,2]],"ltp":3.15,"tv":1268.93,"id":4423910},{"trd":[[1.46,109.45]],"batl":[[0,1.46,4402.48]],"ltp":1.46,"tv":9816.02,"id":2258415}],"tv":11084.96}]}
{"op":"mcm","clk":"1001459079","pt":1580636305945,"mc":[{"id":"1.168215937","rc":[{"trd":[[3.15,8]],"ltp":3.15,"tv":1274.93,"id":4423910},{"trd":[[1.46,122.4]],"batl":[[0,1.46,4389.53]],"ltp":1.46,"tv":9828.97,"id":2258415}],"tv":11103.91}]}
{"op":"mcm","clk":"1001459117","pt":1580636306766,"mc":[{"id":"1.168215937","rc":[{"trd":[[3.15,17]],"ltp":3.15,"tv":1283.93,"id":4423910},{"trd":[[1.46,141.82]],"batl":[[0,1.46,4370.1]],"ltp":1.46,"tv":9848.39,"id":2258415}],"tv":11132.33}]}
{"op":"mcm","clk":"1001459184","pt":1580636307952,"mc":[{"id":"1.168215937","rc":[{"trd":[[3.25,0.11]],"ltp":3.25,"tv":1284.04,"id":4423910},{"trd":[[1.45,0.24]],"batb":[[0,1.45,239.49]],"ltp":1.45,"tv":9848.63,"id":2258415}],"tv":11132.68}]}
{"op":"mcm","clk":"1001459222","pt":1580636308776,"mc":[{"id":"1.168215937","rc":[{"trd":[[3.15,64.86]],"ltp":3.15,"tv":1331.9,"id":4423910},{"trd":[[1.46,245.09]],"batb":[[0,1.31,756.18],[1,1.2,189.41],[2,1.11,37.86]],"batl":[[0,1.46,4266.84],[2,1.8,33.61]],"ltp":1.46,"tv":9951.9,"id":2258415}],"tv":11283.8}]}
{"op":"mcm","clk":"1001459245","pt":1580636309388,"mc":[{"id":"1.168215937","rc":[{"trd":[[1.46,350.22]],"batl":[[0,1.46,4214.27]],"ltp":1.46,"tv":10057.03,"id":2258415}],"tv":11388.94}]}
{"op":"mcm","clk":"1001459676","pt":1580636320679,"mc":[{"id":"1.168215937","rc":[{"batl":[[0,1.55,252.85],[1,1.8,33.61],[2,2,3.67]],"ltp":1.46,"tv":10057.03,"id":2258415}]}]}
{"op":"mcm","clk":"1001460181","pt":1580636331681,"mc":[{"id":"1.168215937","rc":[{"trd":[[1.5,84.04]],"batb":[[0,1.5,322.57],[1,1.31,756.18],[2,1.2,189.41]],"batl":[[0,1.55,252.84]],"ltp":1.5,"tv":10057.05,"id":2258415}],"tv":11388.95}]}
{"op":"mcm","clk":"1001460277","pt":1580636334314,"mc":[{"id":"1.168215937","rc":[{"batb":[[1,1.2,189.41],[2,1.11,37.86]],"ltp":1.5,"tv":10057.05,"id":2258415}]}]}
{"op":"mcm","clk":"1001460318","pt":1580636334990,"mc":[{"id":"1.168215937","rc":[{"batb":[[1,1.25,378.62],[2,1.2,189.41]],"ltp":1.5,"tv":10057.05,"id":2258415}]}]}
{"op":"mcm","clk":"1001460454","pt":1580636337891,"mc":[{"id":"1.168215937","rc":[{"batb":[[0,1.25,378.62],[1,1.21,756.18]],"ltp":1.5,"tv":10057.05,"id":2258415}]}]}
{"op":"mcm","clk":"1001460662","pt":1580636343307,"mc":[{"id":"1.168215937","rc":[{"trd":[[1.55,921.5]],"batb":[[0,1.55,59.33],[1,1.26,756.18],[2,1.25,378.62]],"batl":[[0,1.8,33.61],[1,2,3.67],[2,2.1,10.51]],"ltp":1.55,"tv":10562.73,"id":2258415}],"tv":11894.63}]}
{"op":"mcm","clk":"1001460859","pt":1580636347697,"mc":[{"id":"1.168215937","rc":[{"batb":[[0,1.26,756.18],[1,1.25,378.62],[2,1.21,756.18]],"ltp":1.55,"tv":10562.73,"id":2258415}]}]}
{"op":"mcm","clk":"1001461019","pt":1580636350426,"mc":[{"id":"1.168215937","rc":[{"batl":[[0,1.55,75.72],[1,1.8,33.61],[2,2,3.67]],"ltp":1.55,"tv":10562.73,"id":2258415}]}]}
{"op":"mcm","clk":"1001461331","pt":1580636356630,"mc":[{"id":"1.168215937","rc":[{"trd":[[1.55,1040.15]],"batl":[[0,1.55,16.39]],"ltp":1.55,"tv":10681.38,"id":2258415}],"tv":12013.29}]}
{"op":"mcm","clk":"1001461446","pt":1580636358796,"mc":[{"id":"1.168215937","rc":[{"batl":[[0,1.8,33.61],[1,2,3.67],[2,2.1,10.51]],"ltp":1.55,"tv":10681.38,"id":2258415}]}]}
{"op":"mcm","clk":"1001461943","pt":1580636371120,"mc":[{"id":"1.168215937","rc":[{"batl":[[0,4.2,21.9],[1,1000,0.02]],"ltp":3.15,"tv":1331.9,"id":4423910}]}]}
{"op":"mcm","clk":"1001462250","pt":1580636379331,"mc":[{"id":"1.168215937","rc":[{"batb":[[1,1.21,756.18],[2,1.2,189.41]],"ltp":1.55,"tv":10681.38,"id":2258415}]}]}
{"op":"mcm","clk":"1001463628","pt":1580636413286,"mc":[{"id":"1.168215937","rc":[{"batb":[[0,1.32,756.18],[1,1.26,756.18],[2,1.21,756.18]],"ltp":1.55,"tv":10681.38,"id":2258415}]}]}
{"op":"mcm","clk":"1001463676","pt":1580636414115,"mc":[{"id":"1.168215937","rc":[{"batb":[[0,1.32,824.33]],"ltp":1.55,"tv":10681.38,"id":2258415}]}]}
{"op":"mcm","clk":"1001463867","pt":1580636418428,"mc":[{"id":"1.168215937","rc":[{"batb":[[0,1.32,756.18]],"ltp":1.55,"tv":10681.38,"id":2258415}]}]}
{"op":"mcm","clk":"1001463893","pt":1580636418995,"mc":[{"id":"1.168215937","rc":[{"batb":[[0,1.2,189.41],[1,1.15,378.62],[2,1.11,37.86]],"ltp":1.55,"tv":10681.38,"id":2258415}]}]}
{"op":"mcm","clk":"1001464003","pt":1580636421525,"mc":[{"id":"1.168215937","rc":[{"batb":[[0,1.34,68.15],[1,1.2,189.41],[2,1.15,378.62]],"ltp":1.55,"tv":10681.38,"id":2258415}]}]}
{"op":"mcm","clk":"1001465180","pt":1580636446733,"mc":[{"id":"1.168215937","rc":[{"batl":[[0,1000,0.02],[1,1000,0]],"ltp":3.15,"tv":1331.9,"id":4423910}]}]}
{"op":"mcm","clk":"1001465421","pt":1580636452563,"mc":[{"id":"1.168215937","rc":[{"trd":[[1.34,136.3]],"batb":[[0,1.2,189.41],[1,1.15,378.62],[2,1.11,37.86]],"batl":[[0,1.3,5989.7],[1,1.8,33.61],[2,2,3.67]],"ltp":1.34,"tv":10817.68,"id":2258415}],"tv":12149.59}]}
{"op":"mcm","clk":"1001465448","pt":1580636453236,"mc":[{"id":"1.168215937","rc":[{"batb":[[0,1.11,37.96],[1,1.1,378.72],[2,1.05,530.82]],"ltp":1.34,"tv":10817.68,"id":2258415}]}]}
{"op":"mcm","clk":"1001465543","pt":1580636455762,"mc":[{"id":"1.168215937","rc":[{"batb":[[0,2.2,75.72],[1,1.8,75.72],[2,1.7,75.72]],"ltp":3.15,"tv":1331.9,"id":4423910}]}]}
{"op":"mcm","clk":"1001465622","pt":1580636457779,"mc":[{"id":"1.168215937","rc":[{"batl":[[0,1.8,33.61],[1,2,3.67],[2,2.1,10.51]],"ltp":1.34,"tv":10817.68,"id":2258415}]}]}
{"op":"mcm","clk":"1001465747","pt":1580636460661,"mc":[{"id":"1.168215937","rc":[{"batb":[[0,1.3,70.74],[1,1.11,37.96],[2,1.1,378.72]],"ltp":1.34,"tv":10817.68,"id":2258415}]}]}
{"op":"mcm","clk":"1001465969","pt":1580636465450,"mc":[{"id":"1.168215937","rc":[{"batb":[[0,1.8,75.72],[1,1.7,75.72],[2,1.6,75.72]],"ltp":3.15,"tv":1331.9,"id":4423910},{"trd":[[1.8,184.84]],"batb":[[0,1.8,17.13],[1,1.3,70.74],[2,1.11,37.96]],"batl":[[0,2,3.67],[1,2.1,10.51],[2,1000,0.02]],"ltp":1.8,"tv":10884.9,"id":2258415}],"tv":12216.81}]}
{"op":"mcm","clk":"1001465991","pt":1580636466172,"mc":[{"id":"1.168215937","rc":[{"batb":[[0,1.6,75.72],[1,1.5,75.72],[2,1.4,75.73]],"ltp":3.15,"tv":1331.9,"id":4423910}]}]}
{"op":"mcm","clk":"1001466039","pt":1580636467873,"mc":[{"id":"1.168215937","rc":[{"trd":[[1.8,219.1]],"batb":[[0,1.18,29.51],[1,1.11,37.86],[2,1.1,378.72]],"batl":[[0,1.4,48.1],[1,2,3.67],[2,2.1,10.51]],"ltp":1.8,"tv":10919.16,"id":2258415}],"tv":12251.06}]}
{"op":"mcm","clk":"1001466074","pt":1580636468855,"mc":[{"id":"1.168215937","rc":[{"batl":[[0,2,3.67],[1,2.1,10.51],[2,1000,0.02]],"ltp":1.8,"tv":10919.16,"id":2258415}]}]}
{"op":"mcm","clk":"1001466177","pt":1580636471063,"mc":[{"id":"1.168215937","rc":[{"batl":[[0,1.79,243.07],[1,2,3.67],[2,2.1,10.51]],"ltp":1.8,"tv":10919.16,"id":2258415}]}]}
{"op":"mcm","clk":"1001466595","pt":1580636478751,"mc":[{"id":"1.168215937","rc":[{"batl":[[0,1.7,35.58],[1,1.79,243.07],[2,2,3.67]],"ltp":1.8,"tv":10919.16,"id":2258415}]}]}
{"op":"mcm","clk":"1001467051","pt":1580636488394,"mc":[{"id":"1.168215937","rc":[{"batb":[[0,1.22,68.15],[1,1.18,29.51],[2,1.11,37.86]],"ltp":1.8,"tv":10919.16,"id":2258415}]}]}
{"op":"mcm","clk":"1001468059","pt":1580636504102,"mc":[{"id":"1.168215937","rc":[{"batb":[[0,1.03,9.11],[1,1.02,25.41],[2,1.01,329.03]],"ltp":3.15,"tv":1331.9,"id":4423910},{"batb":[[2,1.05,152.3]],"batl":[[1,2,3.67],[2,2.1,10.51]],"ltp":1.8,"tv":10919.16,"id":2258415}]}]}
{"op":"mcm","clk":"1001469536","pt":1580636529257,"mc":[{"id":"1.168215937","rc":[{"batb":[[0,1.3,70.74],[1,1.22,68.15],[2,1.18,29.51]],"ltp":1.8,"tv":10919.16,"id":2258415}]}]}
{"op":"mcm","clk":"1001469722","pt":1580636531876,"mc":[{"id":"1.168215937","rc":[{"trd":[[2.42,25]],"batl":[[0,2.52,151.01],[1,2.76,67.91],[2,1000,0.02]],"ltp":2.42,"tv":1356.9,"id":4423910},{"trd":[[1.7,35.58]],"batb":[[0,1.37,442.58],[1,1.3,70.74],[2,1.22,68.15]],"batl":[[0,2,3.67],[1,2.1,10.51],[2,1000,0.02]],"ltp":1.7,"tv":10954.74,"id":2258415}],"tv":12311.65}]}
{"op":"mcm","clk":"1001469798","pt":1580636532909,"mc":[{"id":"1.168215937","rc":[{"trd":[[2.52,5.17]],"batl":[[0,2.52,148.42]],"ltp":2.52,"tv":1362.08,"id":4423910},{"batb":[[0,1.43,2.64]],"ltp":1.7,"tv":10954.74,"id":2258415}],"tv":12316.82}]}
{"op":"mcm","clk":"1001470302","pt":1580636538094,"mc":[{"id":"1.168215937","rc":[{"trd":[[2.52,20.04]],"batl":[[0,2.52,133.55]],"ltp":2.52,"tv":1376.95,"id":4423910},{"trd":[[1.65,22.72]],"ltp":1.65,"tv":10977.46,"id":2258415}],"tv":12354.41}]}
{"op":"mcm","clk":"1001470932","pt":1580636547394,"mc":[{"id":"1.168215937","rc":[{"batl":[[0,2.76,67.91],[1,1000,0.02],[2,1000,0]],"ltp":2.52,"tv":1376.95,"id":4423910},{"batl":[[0,1.8,68.15],[1,2,3.67],[2,2.1,10.51]],"ltp":1.65,"tv":10977.46,"id":2258415}]}]}
{"op":"mcm","clk":"1001471064","pt":1580636550658,"mc":[{"id":"1.168215937","rc":[{"trd":[[2.76,67.91]],"batl":[[0,1000,0.02],[1,1000,0]],"ltp":2.76,"tv":1444.86,"id":4423910},{"trd":[[1.56,120.15]],"batb":[[1,1.4,497.62],[2,1.39,363.28]],"batl":[[0,1.55,273],[1,1.56,220.58],[2,1.65,238.57]],"ltp":1.56,"tv":11097.61,"id":2258415}],"tv":12542.47}]}
{"op":"mcm","clk":"1001471119","pt":1580636551793,"mc":[{"id":"1.168215937","rc":[{"batb":[[1,1.4,348.14],[2,1.3,70.74]],"ltp":1.56,"tv":11097.61,"id":2258415}]}]}
{"op":"mcm","clk":"1001471184","pt":1580636553865,"mc":[{"id":"1.168215937","rc":[{"trd":[[1.55,1088.53]],"batl":[[0,1.55,248.81]],"ltp":1.55,"tv":11145.98,"id":2258415}],"tv":12590.84}]}
{"op":"mcm","clk":"1001471231","pt":1580636554956,"mc":[{"id":"1.168215937","rc":[{"batb":[[1,1.22,68.15],[2,1.18,29.51]],"batl":[[0,1.55,302.15]],"ltp":1.55,"tv":11145.98,"id":2258415}]}]}
{"op":"mcm","clk":"1001471272","pt":1580636555782,"mc":[{"id":"1.168215937","rc":[{"trd":[[1.55,1207.19]],"batl":[[0,1.55,242.82]],"ltp":1.55,"tv":11264.64,"id":2258415}],"tv":12709.5}]}
{"op":"mcm","clk":"1001471328","pt":1580636556868,"mc":[{"id":"1.168215937","rc":[{"trd":[[2.74,9.29],[2.8,111.9]],"batl":[[0,3,4.19],[1,1000,0.02]],"ltp":2.74,"tv":1566.05,"id":4423910},{"trd":[[1.55,1490.69],[1.56,561.31],[1.58,1014.41]],"batb":[[0,1.5,8.38],[1,1.45,683.47],[2,1.43,2.64]],"batl":[[0,1.59,497.4],[1,1.6,2969.86],[2,1.8,68.15]],"ltp":1.58,"tv":12966.59,"id":2258415}],"tv":14532.64}]}
{"op":"mcm","clk":"1001471379","pt":1580636557898,"mc":[{"id":"1.168215937","rc":[{"batb":[[0,2.84,22.69],[1,1.03,9.11],[2,1.02,25.41]],"batl":[[1,3.3,17.64],[2,1000,0.02]],"ltp":2.74,"tv":1566.05,"id":4423910},{"batb":[[0,1.51,197.81],[1,1.5,8.38],[2,1.45,683.47]],"batl":[[0,1.54,42.01],[1,1.59,497.4],[2,1.6,2969.86]],"ltp":1.58,"tv":12966.59,"id":2258415}]}]}
{"op":"mcm","clk":"1001471392","pt":1580636558104,"mc":[{"id":"1.168215937","rc":[{"batb":[[0,1.03,9.11],[1,1.02,25.41],[2,1.01,329.03]],"batl":[[1,1000,0.02],[2,1000,0]],"ltp":2.74,"tv":1566.05,"id":4423910},{"batl":[[0,1.59,497.4],[1,1.6,2969.86],[2,1.8,68.15]],"ltp":1.58,"tv":12966.59,"id":2258415}]}]}
{"op":"mcm","clk":"1001471459","pt":1580636559504,"mc":[{"id":"1.168215937","rc":[{"batb":[[0,1.51,245.22]],"ltp":1.58,"tv":12966.59,"id":2258415}]}]}
{"op":"mcm","clk":"1001471518","pt":1580636560687,"mc":[{"id":"1.168215937","rc":[{"batb":[[0,2.84,22.69],[1,1.03,9.11],[2,1.02,25.41]],"ltp":2.74,"tv":1566.05,"id":4423910},{"batb":[[0,1.52,256.05],[1,1.51,245.22],[2,1.5,8.38]],"batl":[[0,1.54,42.01],[1,1.56,243.8],[2,1.57,214.23]],"ltp":1.58,"tv":12966.59,"id":2258415}]}]}
{"op":"mcm","clk":"1001471591","pt":1580636561777,"mc":[{"id":"1.168215937","rc":[{"batl":[[1,3.25,18.48],[2,1000,0.02]],"ltp":2.74,"tv":1566.05,"id":4423910},{"batb":[[0,1.52,227.04]],"batl":[[0,1.56,243.8],[1,1.57,214.23],[2,1.59,497.4]],"ltp":1.58,"tv":12966.59,"id":2258415}]}]}
{"op":"mcm","clk":"1001471719","pt":1580636564618,"mc":[{"id":"1.168215937","rc":[{"batl":[[0,1.55,42.01],[1,1.56,272.14],[2,1.57,214.23]],"ltp":1.58,"tv":12966.59,"id":2258415}]}]}
{"op":"mcm","clk":"1001471838","pt":1580636566885,"mc":[{"id":"1.168215937","rc":[{"batl":[[0,3.25,18.48],[1,1000,0.02],[2,1000,0]],"ltp":2.74,"tv":1566.05,"id":4423910},{"batb":[[2,1.45,683.47]],"ltp":1.58,"tv":12966.59,"id":2258415}]}]}
{"op":"mcm","clk":"1001471966","pt":1580636569881,"mc":[{"id":"1.168215937","rc":[{"batb":[[0,2.84,28.83]],"batl":[[0,2.92,5.84],[1,3.25,18.48],[2,1000,0.02]],"ltp":2.74,"tv":1566.05,"id":4423910}]}]}
{"op":"mcm","clk":"1001472008","pt":1580636570919,"mc":[{"id":"1.168215937","rc":[{"trd":[[1.52,288]],"batb":[[0,1.52,83.04]],"ltp":1.52,"tv":13254.59,"id":2258415}],"tv":14820.64}]}
{"op":"mcm","clk":"1001472028","pt":1580636571229,"mc":[{"id":"1.168215937","rc":[{"batb":[[0,1.51,245.22],[1,1.45,683.47],[2,1.44,94.94]],"ltp":1.52,"tv":13254.59,"id":2258415}]}]}
{"op":"mcm","clk":"1001472103","pt":1580636572685,"mc":[{"id":"1.168215937","rc":[{"trd":[[2.92,5.84]],"batl":[[0,3.25,18.48],[1,1000,0.02],[2,1000,0]],"ltp":2.92,"tv":1571.89,"id":4423910},{"trd":[[1.51,313.64],[1.52,299.22]],"batb":[[0,1.51,88.4]],"batl":[[1,1.56,220.66],[2,1.6,2969.86]],"ltp":1.51,"tv":13579.45,"id":2258415}],"tv":15151.34}]}
{"op":"mcm","clk":"1001472173","pt":1580636573926,"mc":[{"id":"1.168215937","rc":[{"batb":[[0,2.84,22.69]],"ltp":2.92,"tv":1571.89,"id":4423910},{"batb":[[1,1.44,94.94],[2,1.22,68.15]],"batl":[[2,1.8,68.15]],"ltp":1.51,"tv":13579.45,"id":2258415}]}]}
{"op":"mcm","clk":"1001472214","pt":1580636574602,"mc":[{"id":"1.168215937","rc":[{"batb":[[0,1.03,9.11],[1,1.02,25.41],[2,1.01,329.03]],"batl":[[0,1000,0.02],[1,1000,0]],"ltp":2.92,"tv":1571.89,"id":4423910},{"batb":[[0,1.22,68.15],[1,1.18,29.51],[2,1.05,152.3]],"batl":[[0,1.8,68.15],[1,2,3.67],[2,2.1,10.51]],"ltp":1.51,"tv":13579.45,"id":2258415}]}]}
{"op":"mcm","clk":"1001472367","pt":1580636577186,"mc":[{"id":"1.168215937","rc":[{"batb":[[0,1.45,398.19],[1,1.44,307.85],[2,1.22,68.15]],"batl":[[0,1.68,205.11],[1,1.7,328.3],[2,1.8,68.15]],"ltp":1.51,"tv":13579.45,"id":2258415}]}]}
{"op":"mcm","clk":"1001472528","pt":1580636580595,"mc":[{"id":"1.168215937","rc":[{"batb":[[0,1.22,68.15],[1,1.18,29.51],[2,1.05,152.3]],"batl":[[0,1.8,68.15],[1,2,3.67],[2,2.1,10.51]],"ltp":1.51,"tv":13579.45,"id":2258415}]}]}
{"op":"mcm","clk":"1001472763","pt":1580636583600,"mc":[{"id":"1.168215937","rc":[{"trd":[[3.2,1.17]],"batb":[[0,3.2,292.96],[1,2.98,21],[2,2.86,74.72]],"batl":[[0,3.5,16.8],[1,3.55,393.19],[2,1000,0.02]],"ltp":3.2,"tv":1573.06,"id":4423910},{"trd":[[1.46,352.77]],"batb":[[0,1.45,398.19],[1,1.44,307.85],[2,1.4,105.02]],"batl":[[0,1.49,276.13],[1,1.5,297.64],[2,1.8,68.15]],"ltp":1.46,"tv":13582.0,"id":2258415}],"tv":15155.06}]}
{"op":"mcm","clk":"1001472877","pt":1580636585138,"mc":[{"id":"1.168215937","rc":[{"batl":[[2,4.2,148.03]],"ltp":3.2,"tv":1573.06,"id":4423910}]}]}
{"op":"mcm","clk":"1001472920","pt":1580636586120,"mc":[{"id":"1.168215937","rc":[{"batb":[[0,1.45,412.4]],"batl":[[0,1.47,10.1],[1,1.49,276.13],[2,1.5,297.64]],"ltp":1.46,"tv":13582.0,"id":2258415}]}]}
{"op":"mcm","clk":"1001473060","pt":1580636588808,"mc":[{"id":"1.168215937","rc":[{"trd":[[3.2,232.14]],"batb":[[0,3.2,61.99]],"ltp":3.2,"tv":1804.03,"id":4423910},{"trd":[[1.46,859]],"ltp":1.46,"tv":14088.23,"id":2258415}],"tv":15892.26}]}
{"op":"mcm","clk":"1001473077","pt":1580636589326,"mc":[{"id":"1.168215937","rc":[{"batb":[[0,1.45,374.42]],"ltp":1.46,"tv":14088.23,"id":2258415}]}]}
{"op":"mcm","clk":"1001473181","pt":1580636591403,"mc":[{"id":"1.168215937","rc":[{"trd":[[3.2,238.47]],"batb":[[0,3.2,55.66]],"ltp":3.2,"tv":1810.36,"id":4423910},{"trd":[[1.46,872.86]],"ltp":1.46,"tv":14102.09,"id":2258415}],"tv":15912.45}]}
{"op":"mcm","clk":"1001473248","pt":1580636592637,"mc":[{"id":"1.168215937","rc":[{"batl":[[1,1.49,313.2]],"ltp":1.46,"tv":14102.09,"id":2258415}]}]}
{"op":"mcm","clk":"1001473924","pt":1580636606841,"mc":[{"id":"1.168215937","rc":[{"batb":[[0,2.98,21],[1,2.12,388.65],[2,1.03,387.73]],"batl":[[1,4.2,148.03],[2,1000,0.02]],"ltp":3.2,"tv":1810.36,"id":4423910},{"batb":[[0,1.4,105.02],[1,1.18,29.51],[2,1.05,152.3]],"batl":[[0,1.5,42.01],[1,2,3.67],[2,2.1,10.51]],"ltp":1.46,"tv":14102.09,"id":2258415}]}]}
{"op":"mcm","clk":"1001474012","pt":1580636608644,"mc":[{"id":"1.168215937","rc":[{"batb":[[0,2.12,388.65],[1,1.03,387.73],[2,1.02,25.41]],"batl":[[0,4.2,148.03],[1,1000,0.02],[2,1000,0]],"ltp":3.2,"tv":1810.36,"id":4423910},{"batb":[[0,1.18,29.51],[1,1.05,152.3],[2,1.04,169.36]],"batl":[[0,2,3.67],[1,2.1,10.51],[2,1000,0.02]],"ltp":1.46,"tv":14102.09,"id":2258415}]}]}
{"op":"mcm","clk":"1001474064","pt":1580636609934,"mc":[{"id":"1.168215937","rc":[{"batb":[[1,1.05,378.83],[2,1.03,387.52]],"ltp":3.2,"tv":1810.36,"id":4423910},{"batb":[[0,1.42,243.47],[1,1.41,336.68],[2,1.18,29.51]],"batl":[[0,1.56,217.83],[1,1.57,215.81],[2,2,3.67]],"ltp":1.46,"tv":14102.09,"id":2258415}]}]}
{"op":"mcm","clk":"1001474145","pt":1580636611837,"mc":[{"id":"1.168215937","rc":[{"batb":[[0,2.96,2.88],[1,2.88,2.71],[2,2.12,388.65]],"batl":[[0,3.4,2.24],[1,3.45,2.3],[2,4.2,148.03]],"ltp":3.2,"tv":1810.36,"id":4423910},{"batb":[[0,1.42,286.41],[1,1.41,383.57]],"batl":[[0,1.51,35.5],[1,1.53,36.5],[2,2,2.79]],"ltp":1.46,"tv":14102.09,"id":2258415}]}]}
{"op":"mcm","clk":"1001474157","pt":1580636612146,"mc":[{"id":"1.168215937","rc":[{"batb":[[0,2.88,2.71],[1,2.12,388.65],[2,1.05,378.83]],"ltp":3.2,"tv":1810.36,"id":4423910},{"batl":[[0,1.53,36.5],[1,2,2.79],[2,2.1,10.51]],"ltp":1.46,"tv":14102.09,"id":2258415}]}]}
{"op":"mcm","clk":"1001474259","pt":1580636614666,"mc":[{"id":"1.168215937","rc":[{"batb":[[0,3.3,4.52],[1,2.88,2.71],[2,2.12,388.65]],"batl":[[0,3.4,8.04]],"ltp":3.2,"tv":1810.36,"id":4423910},{"batb":[[2,1.38,769.13]],"batl":[[0,1.43,564.59],[1,1.45,227.38],[2,1.46,433.31]],"ltp":1.46,"tv":14102.09,"id":2258415}]}]}
{"op":"mcm","clk":"1001474300","pt":1580636615643,"mc":[{"id":"1.168215937","rc":[{"batl":[[2,3.65,15.12]],"ltp":3.2,"tv":1810.36,"id":4423910}]}]}
{"op":"mcm","clk":"1001474400","pt":1580636617757,"mc":[{"id":"1.168215937","rc":[{"batl":[[2,4.2,148.03]],"ltp":3.2,"tv":1810.36,"id":4423910}]}]}
{"op":"mcm","clk":"1001474487","pt":1580636620186,"mc":[{"id":"1.168215937","rc":[{"batb":[[1,3.15,19.32],[2,2.88,2.71]],"batl":[[2,3.7,15.12]],"ltp":3.2,"tv":1810.36,"id":4423910},{"batl":[[2,1.46,475.32]],"ltp":1.46,"tv":14102.09,"id":2258415}]}]}
{"op":"mcm","clk":"1001474530","pt":1580636621276,"mc":[{"id":"1.168215937","rc":[{"batb":[[1,3.2,2.82],[2,3.15,22.15]],"batl":[[2,3.6,2.06]],"ltp":3.2,"tv":1810.36,"id":4423910},{"batb":[[2,1.39,40.91]],"batl":[[1,1.45,266.08],[2,1.46,515.57]],"ltp":1.46,"tv":14102.09,"id":2258415}]}]}
{"op":"mcm","clk":"1001474782","pt":1580636626979,"mc":[{"id":"1.168215937","rc":[{"trd":[[3.4,14.8]],"batl":[[0,3.45,2.94],[1,3.6,2.06],[2,3.7,15.12]],"ltp":3.4,"tv":1825.16,"id":4423910}],"tv":15927.25}]}
{"op":"mcm","clk":"1001474865","pt":1580636628981,"mc":[{"id":"1.168215937","rc":[{"trd":[[1.42,45.44]],"batb":[[0,1.42,263.69]],"ltp":1.42,"tv":14147.53,"id":2258415}],"tv":15972.69}]}
{"op":"mcm","clk":"1001475209","pt":1580636636215,"mc":[{"id":"1.168215937","rc":[{"trd":[[1.42,48.8]],"batb":[[0,1.42,262.01]],"ltp":1.42,"tv":14150.89,"id":2258415}],"tv":15976.05}]}
{"op":"mcm","clk":"1001475257","pt":1580636637193,"mc":[{"id":"1.168215937","rc":[{"batb":[[0,3.2,2.82],[1,3.15,22.15],[2,2.88,2.71]],"batl":[[0,3.45,2.3]],"ltp":3.4,"tv":1825.16,"id":4423910}]}]}
{"op":"mcm","clk":"1001475422","pt":1580636640787,"mc":[{"id":"1.168215937","rc":[{"batb":[[0,3.15,2.83],[1,2.12,388.65],[2,2,75.72]],"batl":[[0,3.75,2.1],[1,4.2,148.03],[2,1000,0.02]],"ltp":3.4,"tv":1825.16,"id":4423910},{"batb":[[0,1.37,49.77],[1,1.18,29.51],[2,1.15,378.62]],"batl":[[0,1.46,40.25],[1,2,2.79],[2,2.1,10.51]],"ltp":1.42,"tv":14150.89,"id":2258415}]}]}
{"op":"mcm","clk":"1001475576","pt":1580636643877,"mc":[{"id":"1.168215937","rc":[{"batb":[[0,3.2,2.77],[1,3.15,2.83],[2,2.12,388.65]],"batl":[[0,3.6,2.46],[1,3.75,2.1],[2,4.2,148.03]],"ltp":3.4,"tv":1825.16,"id":4423910},{"batb":[[0,1.39,44.91],[1,1.37,49.77],[2,1.18,29.51]],"batl":[[0,1.45,37.1],[1,1.46,40.25],[2,2,2.79]],"ltp":1.42,"tv":14150.89,"id":2258415}]}]}
{"op":"mcm","clk":"1001475597","pt":1580636644084,"mc":[{"id":"1.168215937","rc":[{"batb":[[0,3.15,2.83],[1,2.12,388.65],[2,2,75.72]],"batl":[[0,3.75,2.1],[1,4.2,148.03],[2,1000,0.02]],"ltp":3.4,"tv":1825.16,"id":4423910},{"batb":[[0,1.37,49.77],[1,1.18,29.51],[2,1.15,378.62]],"batl":[[0,1.46,40.25],[1,2,2.79],[2,2.1,10.51]],"ltp":1.42,"tv":14150.89,"id":2258415}]}]}
{"op":"mcm","clk":"1001475713","pt":1580636646810,"mc":[{"id":"1.168215937","rc":[{"batb":[[0,3.35,21.07],[1,3.15,2.83],[2,2.12,388.65]],"batl":[[0,3.4,21.84],[1,3.75,2.1],[2,4.2,148.03]],"ltp":3.4,"tv":1825.16,"id":4423910},{"batb":[[0,1.41,21.89],[1,1.37,49.77],[2,1.18,29.51]],"batl":[[0,1.43,23.5],[1,1.46,40.25],[2,2,2.79]],"ltp":1.42,"tv":14150.89,"id":2258415}]}]}
{"op":"mcm","clk":"1001475747","pt":1580636647579,"mc":[{"id":"1.168215937","rc":[{"batb":[[0,3.15,2.83],[1,2.12,388.65],[2,2,75.72]],"batl":[[0,3.75,2.1],[1,4.2,148.03],[2,1000,0.02]],"ltp":3.4,"tv":1825.16,"id":4423910},{"batb":[[0,1.41,314.98],[1,1.4,347.76],[2,1.37,49.77]],"batl":[[0,1.45,476.76],[1,1.46,323.6]],"ltp":1.42,"tv":14150.89,"id":2258415}]}]}
{"op":"mcm","clk":"1001475868","pt":1580636650607,"mc":[{"id":"1.168215937","rc":[{"batb":[[0,3.2,2.87],[1,3.15,2.83],[2,2.12,388.65]],"batl":[[0,3.6,2.56],[1,3.75,2.1],[2,4.2,148.03]],"ltp":3.4,"tv":1825.16,"id":4423910},{"batb":[[2,1.39,45.91]],"batl":[[0,1.45,509.86]],"ltp":1.42,"tv":14150.89,"id":2258415}]}]}
{"op":"mcm","clk":"1001475918","pt":1580636651591,"mc":[{"id":"1.168215937","rc":[{"batb":[[0,3.15,2.83],[1,2.12,388.65],[2,2,75.72]],"batl":[[0,3.75,2.1],[1,4.2,148.03],[2,1000,0.02]],"ltp":3.4,"tv":1825.16,"id":4423910},{"batb":[[0,1.37,49.77],[1,1.18,29.51],[2,1.16,756.18]],"batl":[[0,1.46,40.25],[1,2,2.79],[2,2.1,10.51]],"ltp":1.42,"tv":14150.89,"id":2258415}]}]}
{"op":"mcm","clk":"1001476130","pt":1580636654946,"mc":[{"id":"1.168215937","rc":[{"batb":[[0,1.38,356.63],[1,1.37,434.63],[2,1.18,29.51]],"batl":[[1,1.48,391.58],[2,1.49,261.65]],"ltp":1.42,"tv":14150.89,"id":2258415}]}]}
{"op":"mcm","clk":"1001477154","pt":1580636671765,"mc":[{"id":"1.168215937","rc":[{"batb":[[0,3.2,2.62],[1,3.15,2.83],[2,2.12,388.65]],"batl":[[0,3.6,2.26],[1,3.75,2.1],[2,4.2,148.03]],"ltp":3.4,"tv":1825.16,"id":4423910},{"batb":[[0,1.39,38.91],[1,1.38,356.63],[2,1.37,434.63]],"batl":[[0,1.45,37.7],[1,1.46,40.25],[2,1.48,391.58]],"ltp":1.42,"tv":14150.89,"id":2258415}]}]}
{"op":"mcm","clk":"1001477172","pt":1580636671972,"mc":[{"id":"1.168215937","rc":[{"batb":[[0,3.15,2.83],[1,2.12,388.65],[2,2,75.72]],"batl":[[0,3.75,2.1],[1,4.2,148.03],[2,1000,0.02]],"ltp":3.4,"tv":1825.16,"id":4423910},{"batb":[[0,1.38,356.63],[1,1.37,434.63],[2,1.18,29.51]],"batl":[[0,1.46,40.25],[1,1.48,391.58],[2,1.49,261.65]],"ltp":1.42,"tv":14150.89,"id":2258415}]}]}
{"op":"mcm","clk":"1001477254","pt":1580636673676,"mc":[{"id":"1.168215937","rc":[{"batb":[[0,1.37,49.77],[1,1.18,29.51],[2,1.16,756.18]],"batl":[[1,1.99,756.18],[2,2,2.79]],"ltp":1.42,"tv":14150.89,"id":2258415}]}]}
{"op":"mcm","clk":"1001477284","pt":1580636674350,"mc":[{"id":"1.168215937","rc":[{"batb":[[1,2,75.72],[2,1.8,75.72]],"batl":[[1,1000,0.02],[2,1000,0]],"ltp":3.4,"tv":1825.16,"id":4423910}]}]}
{"op":"mcm","clk":"1001477980","pt":1580636687170,"mc":[{"id":"1.168215937","rc":[{"trd":[[3.75,7.1]],"batl":[[0,1000,0.02],[1,1000,0]],"ltp":3.75,"tv":1832.26,"id":4423910},{"trd":[[1.37,7.94]],"batb":[[0,1.37,41.83]],"ltp":1.37,"tv":14158.83,"id":2258415}],"tv":15991.09}]}
{"op":"mcm","clk":"1001478439","pt":1580636696194,"mc":[{"id":"1.168215937","rc":[{"trd":[[1.37,11.94]],"batb":[[0,1.37,39.83]],"ltp":1.37,"tv":14162.83,"id":2258415}],"tv":15995.09}]}
{"op":"mcm","clk":"1001480350","pt":1580636728937,"mc":[{"id":"1.168215937","rc":[{"batb":[[0,1.38,68.15],[1,1.37,39.83],[2,1.18,29.51]],"ltp":1.37,"tv":14162.83,"id":2258415}]}]}
{"op":"mcm","clk":"1001481180","pt":1580636744364,"mc":[{"id":"1.168215937","rc":[{"batl":[[1,1.7,68.15],[2,1.99,756.18]],"ltp":1.37,"tv":14162.83,"id":2258415}]}]}
{"op":"mcm","clk":"1001482914","pt":1580636776282,"mc":[{"id":"1.168215937","rc":[{"batl":[[0,1.46,59.35]],"ltp":1.37,"tv":14162.83,"id":2258415}]}]}
{"op":"mcm","clk":"1001483846","pt":1580636797337,"mc":[{"id":"1.168215937","rc":[{"batl":[[0,3.3,1.76],[1,1000,0.02]],"ltp":3.75,"tv":1832.26,"id":4423910}]}]}
{"op":"mcm","clk":"1001484228","pt":1580636804614,"mc":[{"id":"1.168215937","rc":[{"trd":[[3.3,3.52]],"batb":[[0,3.3,18.24],[1,3.15,2.83],[2,2,75.72]],"batl":[[0,1000,0.02],[1,1000,0]],"ltp":3.3,"tv":1835.77,"id":4423910}],"tv":15998.61}]}
{"op":"mcm","clk":"1001484406","pt":1580636808325,"mc":[{"id":"1.168215937","rc":[{"batl":[[0,3.6,1.76],[1,1000,0.02]],"ltp":3.3,"tv":1835.77,"id":4423910}]}]}
{"op":"mcm","clk":"1001484952","pt":1580636817419,"mc":[{"id":"1.168215937","rc":[{"batl":[[1,3.9,1.76],[2,1000,0.02]],"ltp":3.3,"tv":1835.77,"id":4423910},{"batl":[[2,2,2.79]],"ltp":1.37,"tv":14162.83,"id":2258415}]}]}
{"op":"mcm","clk":"1001485444","pt":1580636826124,"mc":[{"id":"1.168215937","rc":[{"trd":[[3.6,1.76]],"batl":[[0,3.9,1.76],[1,1000,0.02],[2,1000,0]],"ltp":3.6,"tv":1837.53,"id":4423910},{"trd":[[1.37,66.46],[1.38,140.89]],"batb":[[0,1.37,12.57],[1,1.18,29.51],[2,1.15,378.62]],"ltp":1.37,"tv":14358.24,"id":2258415}],"tv":16195.78}]}
{"op":"mcm","clk":"1001485909","pt":1580636835048,"mc":[{"id":"1.168215937","rc":[{"batb":[[1,1.3,24.81],[2,1.18,29.51]],"ltp":1.37,"tv":14358.24,"id":2258415}]}]}
{"op":"mcm","clk":"1001486018","pt":1580636837366,"mc":[{"id":"1.168215937","rc":[{"batl":[[0,1.43,68.15],[1,1.46,59.35],[2,1.7,68.15]],"ltp":1.37,"tv":14358.24,"id":2258415}]}]}
{"op":"mcm","clk":"1001486671","pt":1580636849570,"mc":[{"id":"1.168215937","rc":[{"batb":[[2,1.03,9.11]],"ltp":3.6,"tv":1837.53,"id":4423910}]}]}
{"op":"mcm","clk":"1001487066","pt":1580636857779,"mc":[{"id":"1.168215937","rc":[{"trd":[[1.37,73.68]],"batb":[[0,1.37,8.96]],"ltp":1.37,"tv":14365.46,"id":2258415}],"tv":16203.0}]}
{"op":"mcm","clk":"1001487153","pt":1580636859074,"mc":[{"id":"1.168215937","rc":[{"batb":[[2,1.26,68.15]],"ltp":1.37,"tv":14365.46,"id":2258415}]}]}
{"op":"mcm","clk":"1001487852","pt":1580636870193,"mc":[{"id":"1.168215937","rc":[{"batl":[[2,2,2.79]],"ltp":1.37,"tv":14365.46,"id":2258415}]}]}
{"op":"mcm","clk":"1001488057","pt":1580636874100,"mc":[{"id":"1.168215937","rc":[{"batl":[[0,1.46,59.35],[1,2,2.79],[2,2.1,10.51]],"ltp":1.37,"tv":14365.46,"id":2258415}]}]}
{"op":"mcm","clk":"1001488237","pt":1580636877190,"mc":[{"id":"1.168215937","rc":[{"batl":[[1,1.5,68.15],[2,2,2.79]],"ltp":1.37,"tv":14365.46,"id":2258415}]}]}
{"op":"mcm","clk":"1001488491","pt":1580636882227,"mc":[{"id":"1.168215937","rc":[{"batb":[[0,1.38,1630.43],[1,1.37,8.96],[2,1.3,24.81]],"batl":[[0,1.41,1595.74],[1,1.46,59.35],[2,1.5,68.15]],"ltp":1.37,"tv":14365.46,"id":2258415}]}]}
{"op":"mcm","clk":"1001488817","pt":1580636888954,"mc":[{"id":"1.168215937","rc":[{"batl":[[2,2,2.79]],"ltp":1.37,"tv":14365.46,"id":2258415}]}]}
{"op":"mcm","clk":"1001489298","pt":1580636898431,"mc":[{"id":"1.168215937","rc":[{"batl":[[0,1.4,67.18],[1,1.41,1595.74],[2,1.46,59.35]],"ltp":1.37,"tv":14365.46,"id":2258415}]}]}
{"op":"mcm","clk":"1001489532","pt":1580636903262,"mc":[{"id":"1.168215937","rc":[{"batl":[[2,1.42,7.56]],"ltp":1.37,"tv":14365.46,"id":2258415}]}]}
{"op":"mcm","clk":"1001490080","pt":1580636914092,"mc":[{"id":"1.168215937","rc":[{"batb":[[2,1.8,75.72]],"ltp":3.6,"tv":1837.53,"id":4423910}]}]}
{"op":"mcm","clk":"1001490236","pt":1580636916928,"mc":[{"id":"1.168215937","rc":[{"trd":[[1.38,474.89]],"batb":[[0,1.38,1463.43]],"ltp":1.38,"tv":14699.46,"id":2258415}],"tv":16537.0}]}
{"op":"mcm","clk":"1001490272","pt":1580636917397,"mc":[{"id":"1.168215937","rc":[{"batb":[[2,2,75.72]],"ltp":3.6,"tv":1837.53,"id":4423910}]}]}
{"op":"mcm","clk":"1001490655","pt":1580636924284,"mc":[{"id":"1.168215937","rc":[{"trd":[[1.38,476.91]],"batb":[[0,1.38,1462.42]],"ltp":1.38,"tv":14701.49,"id":2258415}],"tv":16539.02}]}
{"op":"mcm","clk":"1001490842","pt":1580636927588,"mc":[{"id":"1.168215937","rc":[{"batl":[[0,1.41,1595.74],[1,1.42,7.56],[2,1.46,59.35]],"ltp":1.38,"tv":14701.49,"id":2258415}]}]}
{"op":"mcm","clk":"1001490915","pt":1580636929083,"mc":[{"id":"1.168215937","rc":[{"trd":[[1.41,0.06]],"batl":[[0,1.41,1595.71]],"ltp":1.41,"tv":14701.54,"id":2258415}],"tv":16539.08}]}
{"op":"mcm","clk":"1001491256","pt":1580636935523,"mc":[{"id":"1.168215937","rc":[{"trd":[[1.38,480.27]],"batb":[[0,1.38,1460.74]],"ltp":1.38,"tv":14704.9,"id":2258415}],"tv":16542.44}]}
{"op":"mcm","clk":"1001491362","pt":1580636937689,"mc":[{"id":"1.168215937","rc":[{"batb":[[0,1.37,8.96],[1,1.3,24.81],[2,1.18,29.51]],"batl":[[0,1.42,7.56],[1,1.46,59.35],[2,2,2.79]],"ltp":1.38,"tv":14704.9,"id":2258415}]}]}
{"op":"mcm","clk":"1001491565","pt":1580636940936,"mc":[{"id":"1.168215937","rc":[{"trd":[[1.42,63.92]],"batb":[[0,1.43,346.92],[1,1.42,326.78],[2,1.37,8.96]],"batl":[[0,1.46,59.35],[1,1.61,213.82],[2,1.62,191.94]],"ltp":1.42,"tv":14720.02,"id":2258415}],"tv":16557.56}]}
{"op":"mcm","clk":"1001491608","pt":1580636941610,"mc":[{"id":"1.168215937","rc":[{"batl":[[0,3.45,2.44],[1,3.9,1.76],[2,1000,0.02]],"ltp":3.6,"tv":1837.53,"id":4423910},{"batb":[[0,1.37,8.96],[1,1.3,24.81],[2,1.18,29.51]],"batl":[[1,2,2.79],[2,2.1,10.51]],"ltp":1.42,"tv":14720.02,"id":2258415}]}]}
{"op":"mcm","clk":"1001491652","pt":1580636942330,"mc":[{"id":"1.168215937","rc":[{"batl":[[0,3.9,1.76],[1,1000,0.02],[2,1000,0]],"ltp":3.6,"tv":1837.53,"id":4423910}]}]}
{"op":"mcm","clk":"1001491834","pt":1580636944919,"mc":[{"id":"1.168215937","rc":[{"trd":[[3.15,67.69],[3.3,21.76]],"batb":[[0,1.8,75.72],[1,1.7,75.72],[2,1.6,75.72]],"ltp":3.15,"tv":1858.6,"id":4423910},{"trd":[[1.44,41.8],[1.46,991.56],[1.47,6.06]],"batb":[[0,1.49,249.97],[1,1.48,274.11],[2,1.37,8.96]],"batl":[[0,1.53,215.67],[1,1.54,231.31],[2,2,2.79]],"ltp":1.47,"tv":14886.58,"id":2258415}],"tv":16745.19}]}
{"op":"mcm","clk":"1001491848","pt":1580636945129,"mc":[{"id":"1.168215937","rc":[{"batb":[[0,1.37,8.96],[1,1.3,24.81],[2,1.18,29.51]],"batl":[[0,2,2.79],[1,2.1,10.51],[2,1000,0.02]],"ltp":1.47,"tv":14886.58,"id":2258415}]}]}
{"op":"mcm","clk":"1001491939","pt":1580636946528,"mc":[{"id":"1.168215937","rc":[{"batb":[[1,1.34,494.03],[2,1.32,510.84]],"batl":[[0,1.46,480.59],[1,1.48,497.4],[2,2,2.79]],"ltp":1.47,"tv":14886.58,"id":2258415}]}]}
{"op":"mcm","clk":"1001492067","pt":1580636948232,"mc":[{"id":"1.168215937","rc":[{"batl":[[2,1.5,4.2]],"ltp":1.47,"tv":14886.58,"id":2258415}]}]}
{"op":"mcm","clk":"1001492136","pt":1580636949112,"mc":[{"id":"1.168215937","rc":[{"batb":[[0,1.43,290.11],[1,1.42,326.77],[2,1.37,8.96]],"ltp":1.47,"tv":14886.58,"id":2258415}]}]}
{"op":"mcm","clk":"1001492888","pt":1580636959858,"mc":[{"id":"1.168215937","rc":[{"trd":[[1.43,29.3]],"batb":[[0,1.43,275.46]],"ltp":1.43,"tv":14915.89,"id":2258415}],"tv":16774.49}]}
{"op":"mcm","clk":"1001493111","pt":1580636962848,"mc":[{"id":"1.168215937","rc":[{"trd":[[3.35,117.58]],"batb":[[0,3.35,54.92],[1,3.3,230.17],[2,1.8,75.72]],"batl":[[0,3.4,5.15],[1,3.55,242.43],[2,3.9,1.76]],"ltp":3.35,"tv":1976.18,"id":4423910},{"trd":[[1.43,304.76]],"batb":[[0,1.42,326.77],[1,1.37,8.96],[2,1.3,24.81]],"batl":[[1,1.47,278.74],[2,1.48,497.4]],"ltp":1.43,"tv":15191.35,"id":2258415}],"tv":17167.53}]}
{"op":"mcm","clk":"1001493211","pt":1580636963948,"mc":[{"id":"1.168215937","rc":[{"batb":[[2,2.94,21]],"batl":[[1,3.45,16.8],[2,3.55,242.43]],"ltp":3.35,"tv":1976.18,"id":4423910},{"batb":[[1,1.41,101.66],[2,1.37,8.96]],"ltp":1.43,"tv":15191.35,"id":2258415}]}]}
{"op":"mcm","clk":"1001493330","pt":1580636965960,"mc":[{"id":"1.168215937","rc":[{"batb":[[0,1.42,457.53],[1,1.41,441.98]],"batl":[[0,1.46,798.7]],"ltp":1.43,"tv":15191.35,"id":2258415}]}]}
{"op":"mcm","clk":"1001493361","pt":1580636966424,"mc":[{"id":"1.168215937","rc":[{"batl":[[0,1.43,52.89],[1,1.46,798.7],[2,1.47,278.74]],"ltp":1.43,"tv":15191.35,"id":2258415}]}]}
{"op":"mcm","clk":"1001493459","pt":1580636967825,"mc":[{"id":"1.168215937","rc":[{"batl":[[1,1.46,318.11]],"ltp":1.43,"tv":15191.35,"id":2258415}]}]}
{"op":"mcm","clk":"1001493538","pt":1580636968964,"mc":[{"id":"1.168215937","rc":[{"batb":[[2,1.39,494.03]],"batl":[[1,1.45,480.59],[2,1.46,318.11]],"ltp":1.43,"tv":15191.35,"id":2258415}]}]}
{"op":"mcm","clk":"1001493585","pt":1580636969850,"mc":[{"id":"1.168215937","rc":[{"batl":[[0,1.45,480.59],[1,1.46,318.11],[2,1.47,776.14]],"ltp":1.43,"tv":15191.35,"id":2258415}]}]}
{"op":"mcm","clk":"1001493700","pt":1580636971544,"mc":[{"id":"1.168215937","rc":[{"trd":[[1.42,80.72]],"batb":[[0,1.42,449.13]],"ltp":1.42,"tv":15208.15,"id":2258415}],"tv":17184.33}]}
{"op":"mcm","clk":"1001493874","pt":1580636974343,"mc":[{"id":"1.168215937","rc":[{"trd":[[3.35,214.18]],"batb":[[0,3.35,6.62]],"ltp":3.35,"tv":2072.78,"id":4423910},{"trd":[[1.42,187.26]],"batb":[[0,1.42,395.86]],"ltp":1.42,"tv":15314.69,"id":2258415}],"tv":17387.47}]}
{"op":"mcm","clk":"1001494058","pt":1580636977955,"mc":[{"id":"1.168215937","rc":[{"batb":[[0,2.94,21],[1,2.22,384.52],[2,2,75.72]],"batl":[[0,3.45,16.8],[1,3.9,1.76],[2,4.6,136.05]],"ltp":3.35,"tv":2072.78,"id":4423910},{"batb":[[0,1.41,101.66],[1,1.39,494.03],[2,1.37,510.84]],"batl":[[1,1.47,497.4],[2,1.5,4.2]],"ltp":1.42,"tv":15314.69,"id":2258415}]}]}
{"op":"mcm","clk":"1001494104","pt":1580636978987,"mc":[{"id":"1.168215937","rc":[{"batb":[[0,2.22,384.52],[1,2,75.72],[2,1.8,75.72]],"batl":[[0,3.9,1.76],[1,4.6,136.05],[2,1000,0.02]],"ltp":3.35,"tv":2072.78,"id":4423910},{"batb":[[0,1.39,494.03],[1,1.37,510.84],[2,1.3,24.81]],"ltp":1.42,"tv":15314.69,"id":2258415}]}]}
{"op":"mcm","clk":"1001494209","pt":1580636980788,"mc":[{"id":"1.168215937","rc":[{"batb":[[0,1.39,921.54],[1,1.38,375.53],[2,1.37,510.84]],"ltp":1.42,"tv":15314.69,"id":2258415}]}]}
{"op":"mcm","clk":"1001494226","pt":1580636980990,"mc":[{"id":"1.168215937","rc":[{"batb":[[0,1.39,494.03],[1,1.37,510.84],[2,1.3,24.81]],"ltp":1.42,"tv":15314.69,"id":2258415}]}]}
{"op":"mcm","clk":"1001494381","pt":1580636983273,"mc":[{"id":"1.168215937","rc":[{"batb":[[0,1.43,485.52],[1,1.42,330.33],[2,1.39,494.03]],"batl":[[1,1.47,758.8],[2,1.48,271.88]],"ltp":1.42,"tv":15314.69,"id":2258415}]}]}
{"op":"mcm","clk":"1001494598","pt":1580636986595,"mc":[{"id":"1.168215937","rc":[{"batb":[[0,1.39,494.03],[1,1.37,510.84],[2,1.3,24.81]],"batl":[[1,1.47,497.4],[2,1.5,4.2]],"ltp":1.42,"tv":15314.69,"id":2258415}]}]}
{"op":"mcm","clk":"1001494766","pt":1580636989490,"mc":[{"id":"1.168215937","rc":[{"batb":[[0,1.39,921.54],[1,1.38,375.53],[2,1.37,510.84]],"ltp":1.42,"tv":15314.69,"id":2258415}]}]}
{"op":"mcm","clk":"1001494797","pt":1580636990060,"mc":[{"id":"1.168215937","rc":[{"batb":[[0,1.39,427.51],[2,1.3,24.81]],"ltp":1.42,"tv":15314.69,"id":2258415}]}]}
{"op":"mcm","clk":"1001494937","pt":1580636992760,"mc":[{"id":"1.168215937","rc":[{"batl":[[0,3.6,5.7],[1,3.9,1.76],[2,4.6,136.05]],"ltp":3.35,"tv":2072.78,"id":4423910},{"batb":[[2,1.36,709.49]],"batl":[[0,1.41,914.39],[1,1.45,480.59],[2,1.47,497.4]],"ltp":1.42,"tv":15314.69,"id":2258415}]}]}
{"op":"mcm","clk":"1001495029","pt":1580636993904,"mc":[{"id":"1.168215937","rc":[{"batb":[[0,3.1,19.32],[1,2.22,384.52],[2,2,75.72]],"batl":[[0,3.6,21.66]],"ltp":3.35,"tv":2072.78,"id":4423910},{"batb":[[1,1.38,485.6]],"batl":[[1,1.43,452.18],[2,1.44,302.7]],"ltp":1.42,"tv":15314.69,"id":2258415}]}]}
{"op":"mcm","clk":"1001495412","pt":1580636999010,"mc":[{"id":"1.168215937","rc":[{"batb":[[2,1.36,1203.52]],"batl":[[1,1.43,932.77]],"ltp":1.42,"tv":15314.69,"id":2258415}]}]}
{"op":"mcm","clk":"1001495763","pt":1580637003927,"mc":[{"id":"1.168215937","rc":[{"batl":[[0,3.6,15.96]],"ltp":3.35,"tv":2072.78,"id":4423910},{"batb":[[2,1.36,494.03]],"batl":[[0,1.41,146.13]],"ltp":1.42,"tv":15314.69,"id":2258415}]}]}
{"op":"mcm","clk":"1001495792","pt":1580637004319,"mc":[{"id":"1.168215937","rc":[{"batb":[[0,1.38,110.07],[1,1.36,494.03],[2,1.34,510.84]],"batl":[[0,1.43,480.59],[1,1.45,497.4],[2,1.48,42.01]],"ltp":1.42,"tv":15314.69,"id":2258415}]}]}
{"op":"mcm","clk":"1001495856","pt":1580637005454,"mc":[{"id":"1.168215937","rc":[{"batb":[[0,2.22,384.52],[1,2,75.72],[2,1.8,75.72]],"batl":[[0,3.9,1.76],[1,4.6,136.05],[2,1000,0.02]],"ltp":3.35,"tv":2072.78,"id":4423910},{"batb":[[0,1.36,494.03],[1,1.34,510.84],[2,1.3,24.81]],"batl":[[2,1.5,4.2]],"ltp":1.42,"tv":15314.69,"id":2258415}]}]}
{"op":"mcm","clk":"1001495975","pt":1580637007313,"mc":[{"id":"1.168215937","rc":[{"batb":[[0,1.37,551.38],[1,1.36,898.02],[2,1.34,510.84]],"batl":[[2,1.46,233.21]],"ltp":1.42,"tv":15314.69,"id":2258415}]}]}
{"op":"mcm","clk":"1001496143","pt":1580637010509,"mc":[{"id":"1.168215937","rc":[{"batb":[[0,1.41,1.68],[1,1.37,551.38],[2,1.36,898.02]],"ltp":1.42,"tv":15314.69,"id":2258415}]}]}
{"op":"mcm","clk":"1001496411","pt":1580637014646,"mc":[{"id":"1.168215937","rc":[{"batb":[[2,1.36,403.99]],"batl":[[2,1.5,4.2]],"ltp":1.42,"tv":15314.69,"id":2258415}]}]}
{"op":"mcm","clk":"1001496468","pt":1580637015636,"mc":[{"id":"1.168215937","rc":[{"batb":[[0,2,75.72],[1,1.8,75.72],[2,1.7,75.72]],"batl":[[1,1000,0.02],[2,1000,0]],"ltp":3.35,"tv":2072.78,"id":4423910}]}]}
{"op":"mcm","clk":"1001496629","pt":1580637017958,"mc":[{"id":"1.168215937","rc":[{"trd":[[3.45,0.69]],"batb":[[0,3.6,5.17],[1,3.45,60.49],[2,3.2,18.48]],"batl":[[0,3.75,22.44],[1,3.9,232.69],[2,1000,0.02]],"ltp":3.45,"tv":2073.47,"id":4423910},{"trd":[[1.41,1.74]],"batb":[[0,1.37,551.38],[1,1.36,519.94],[2,1.3,24.81]],"batl":[[0,1.39,753.35],[1,1.41,416.82],[2,1.42,321.7]],"ltp":1.41,"tv":15316.37,"id":2258415}],"tv":17389.85}]}
{"op":"mcm","clk":"1001496749","pt":1580637019835,"mc":[{"id":"1.168215937","rc":[{"batl":[[2,5.3,118.79]],"ltp":3.45,"tv":2073.47,"id":4423910}]}]}
{"op":"mcm","clk":"1001497002","pt":1580637023653,"mc":[{"id":"1.168215937","rc":[{"batl":[[1,1.41,416.99]],"ltp":1.41,"tv":15316.37,"id":2258415}]}]}
{"op":"mcm","clk":"1001497047","pt":1580637024369,"mc":[{"id":"1.168215937","rc":[{"trd":[[3.6,9.78]],"batb":[[0,3.6,1.16]],"ltp":3.6,"tv":2081.49,"id":4423910}],"tv":17397.86}]}
{"op":"mcm","clk":"1001497374","pt":1580637030472,"mc":[{"id":"1.168215937","rc":[{"trd":[[3.75,7.18]],"batl":[[0,3.75,22.4]],"ltp":3.75,"tv":2081.57,"id":4423910}],"tv":17397.95}]}
{"op":"mcm","clk":"1001497602","pt":1580637034555,"mc":[{"id":"1.168215937","rc":[{"batb":[[0,3.45,60.49],[1,3.2,18.48],[2,2.38,382.3]],"batl":[[0,3.75,15.12]],"ltp":3.75,"tv":2081.57,"id":4423910}]}]}
{"op":"mcm","clk":"1001497739","pt":1580637037448,"mc":[{"id":"1.168215937","rc":[{"batl":[[0,3.7,7.17],[1,3.75,15.12],[2,3.9,232.69]],"ltp":3.75,"tv":2081.57,"id":4423910},{"batl":[[0,1.39,764.56]],"ltp":1.41,"tv":15316.37,"id":2258415}]}]}
{"op":"mcm","clk":"1001497932","pt":1580637040658,"mc":[{"id":"1.168215937","rc":[{"batb":[[0,3.2,18.48],[1,2.38,382.3],[2,2,75.72]],"batl":[[0,3.75,15.12],[1,3.9,1.76],[2,5.3,118.79]],"ltp":3.75,"tv":2081.57,"id":4423910},{"batl":[[0,1.41,416.99],[1,1.42,321.7],[2,1.45,42.01]],"ltp":1.41,"tv":15316.37,"id":2258415}]}]}
{"op":"mcm","clk":"1001497961","pt":1580637041174,"mc":[{"id":"1.168215937","rc":[{"batb":[[0,2.38,382.3],[1,2,75.72],[2,1.8,75.72]],"batl":[[0,3.9,1.76],[1,5.3,118.79],[2,1000,0.02]],"ltp":3.75,"tv":2081.57,"id":4423910},{"batb":[[0,1.3,24.81],[1,1.18,29.51],[2,1.15,378.62]],"batl":[[0,1.5,4.37],[1,2,2.79],[2,2.1,10.51]],"ltp":1.41,"tv":15316.37,"id":2258415}]}]}
{"op":"mcm","clk":"1001498157","pt":1580637044080,"mc":[{"id":"1.168215937","rc":[{"batb":[[0,1.34,472.24],[1,1.33,450.29],[2,1.3,24.81]],"batl":[[0,1.43,397.46],[1,1.44,303.46],[2,1.5,4.2]],"ltp":1.41,"tv":15316.37,"id":2258415}]}]}
{"op":"mcm","clk":"1001498255","pt":1580637045783,"mc":[{"id":"1.168215937","rc":[{"batl":[[0,1.5,4.37],[1,2,2.79],[2,2.1,10.51]],"ltp":1.41,"tv":15316.37,"id":2258415}]}]}
{"op":"mcm","clk":"1001498330","pt":1580637046864,"mc":[{"id":"1.168215937","rc":[{"batb":[[0,2,75.72],[1,1.8,75.72],[2,1.7,75.72]],"batl":[[1,1000,0.02],[2,1000,0]],"ltp":3.75,"tv":2081.57,"id":4423910}]}]}
{"op":"mcm","clk":"1001498446","pt":1580637048774,"mc":[{"id":"1.168215937","rc":[{"batb":[[0,3.6,2],[1,2,75.72],[2,1.8,75.72]],"batl":[[1,4,7.56],[2,1000,0.02]],"ltp":3.75,"tv":2081.57,"id":4423910},{"batb":[[0,1.34,2151.34],[2,1.31,703.39]],"batl":[[0,1.36,1076.38],[1,1.37,1905.7],[2,1.38,369.43]],"ltp":1.41,"tv":15316.37,"id":2258415}]}]}
{"op":"mcm","clk":"1001498537","pt":1580637049963,"mc":[{"id":"1.168215937","rc":[{"batb":[[1,3.35,17.64],[2,2,75.72]],"batl":[[1,3.95,13.44],[2,4,7.56]],"ltp":3.75,"tv":2081.57,"id":4423910},{"batb":[[1,1.33,577.16]],"ltp":1.41,"tv":15316.37,"id":2258415}]}]}
{"op":"mcm","clk":"1001498615","pt":1580637051201,"mc":[{"id":"1.168215937","rc":[{"batb":[[2,2.52,381.46]],"ltp":3.75,"tv":2081.57,"id":4423910}]}]}
{"op":"mcm","clk":"1001498825","pt":1580637054814,"mc":[{"id":"1.168215937","rc":[{"batb":[[2,1.32,494.03]],"ltp":1.41,"tv":15316.37,"id":2258415}]}]}
{"op":"mcm","clk":"1001498998","pt":1580637057813,"mc":[{"id":"1.168215937","rc":[{"batb":[[1,3.5,2.64],[2,3.35,20.31]],"batl":[[2,4.3,2]],"ltp":3.75,"tv":2081.57,"id":4423910},{"trd":[[1.36,3.56]],"batb":[[0,1.33,126.87],[1,1.32,494.03],[2,1.31,63.79]],"batl":[[0,1.38,2],[1,1.39,480.59],[2,1.4,37.94]],"ltp":1.36,"tv":15319.93,"id":2258415}],"tv":17401.51}]}
{"op":"mcm","clk":"1001499053","pt":1580637059000,"mc":[{"id":"1.168215937","rc":[{"batb":[[2,3.35,2.67]],"batl":[[1,4.3,2],[2,4.5,2.01]],"ltp":3.75,"tv":2081.57,"id":4423910},{"batb":[[0,1.32,494.03],[1,1.31,63.79],[2,1.3,535.65]],"ltp":1.36,"tv":15319.93,"id":2258415}]}]}
{"op":"mcm","clk":"1001499126","pt":1580637060798,"mc":[{"id":"1.168215937","rc":[{"batb":[[2,1.3,1167.42]],"batl":[[2,1.4,459.02]],"ltp":1.36,"tv":15319.93,"id":2258415}]}]}
{"op":"mcm","clk":"1001499209","pt":1580637062087,"mc":[{"id":"1.168215937","rc":[{"batb":[[0,3.5,2.64],[1,3.35,2.67],[2,2.52,381.46]],"ltp":3.75,"tv":2081.57,"id":4423910},{"batl":[[0,1.39,480.59],[1,1.4,459.02],[2,1.41,829.52]],"ltp":1.36,"tv":15319.93,"id":2258415}]}]}
{"op":"mcm","clk":"1001499270","pt":1580637063112,"mc":[{"id":"1.168215937","rc":[{"batb":[[2,1.3,535.65]],"batl":[[1,1.4,37.94],[2,1.41,497.56]],"ltp":1.36,"tv":15319.93,"id":2258415}]}]}
{"op":"mcm","clk":"1001499435","pt":1580637065887,"mc":[{"id":"1.168215937","rc":[{"batb":[[0,3.85,10.57],[1,3.5,2.64],[2,3.35,2.67]],"batl":[[1,3.95,10.9],[2,4.3,2]],"ltp":3.75,"tv":2081.57,"id":4423910},{"batb":[[0,1.33,10.53],[1,1.32,494.03],[2,1.31,63.79]],"batl":[[0,1.36,10.32],[1,1.39,480.59],[2,1.4,37.94]],"ltp":1.36,"tv":15319.93,"id":2258415}]}]}
{"op":"mcm","clk":"1001499449","pt":1580637066095,"mc":[{"id":"1.168215937","rc":[{"batb":[[0,3.5,2.64],[1,3.35,2.67],[2,2.52,381.46]],"batl":[[1,4.3,2],[2,4.5,2.01]],"ltp":3.75,"tv":2081.57,"id":4423910},{"batb":[[0,1.33,584.41],[1,1.32,963.74]],"batl":[[0,1.37,577.35],[1,1.38,363.49],[2,1.39,480.59]],"ltp":1.36,"tv":15319.93,"id":2258415}]}]}
{"op":"mcm","clk":"1001499484","pt":1580637067119,"mc":[{"id":"1.168215937","rc":[{"batb":[[0,1.32,494.03],[1,1.31,63.79],[2,1.3,535.65]],"batl":[[0,1.39,480.59],[1,1.4,37.94],[2,1.41,497.56]],"ltp":1.36,"tv":15319.93,"id":2258415}]}]}
{"op":"mcm","clk":"1001499642","pt":1580637070823,"mc":[{"id":"1.168215937","rc":[{"batb":[[2,1.3,1167.42]],"batl":[[1,1.4,459.02],[2,1.41,829.52]],"ltp":1.36,"tv":15319.93,"id":2258415}]}]}
{"op":"mcm","clk":"1001499911","pt":1580637075914,"mc":[{"id":"1.168215937","rc":[{"batl":[[1,1.4,37.94],[2,1.41,497.56]],"ltp":1.36,"tv":15319.93,"id":2258415}]}]}
{"op":"mcm","clk":"1001499932","pt":1580637076224,"mc":[{"id":"1.168215937","rc":[{"batl":[[1,4.5,2.01],[2,6,106.18]],"ltp":3.75,"tv":2081.57,"id":4423910},{"batb":[[0,1.3,656.58],[1,1.29,598.46],[2,1.18,29.51]],"ltp":1.36,"tv":15319.93,"id":2258415}]}]}
{"op":"mcm","clk":"1001500061","pt":1580637078897,"mc":[{"id":"1.168215937","rc":[{"trd":[[3.9,1.76]],"batb":[[0,4.2,3.8],[1,3.85,2],[2,3.5,2.64]],"batl":[[0,4.5,2.01],[1,4.7,251.14]],"ltp":3.9,"tv":2083.33,"id":4423910},{"trd":[[1.34,141.42]],"batb":[[0,1.3,2400.48]],"batl":[[0,1.33,1976.54],[1,1.34,421.81],[2,1.35,2.02]],"ltp":1.34,"tv":15325.05,"id":2258415}],"tv":17408.38}]}
{"op":"mcm","clk":"1001500106","pt":1580637080215,"mc":[{"id":"1.168215937","rc":[{"batb":[[2,3.6,15.96]],"batl":[[0,4.3,12.6],[1,4.5,2.01],[2,4.7,251.14]],"ltp":3.9,"tv":2083.33,"id":4423910},{"batb":[[0,1.3,2539.96]],"ltp":1.34,"tv":15325.05,"id":2258415}]}]}
{"op":"mcm","clk":"1001500317","pt":1580637085049,"mc":[{"id":"1.168215937","rc":[{"batb":[[2,1.27,494.03]],"batl":[[2,1.35,482.61]],"ltp":1.34,"tv":15325.05,"id":2258415}]}]}
{"op":"mcm","clk":"1001500427","pt":1580637087113,"mc":[{"id":"1.168215937","rc":[{"batb":[[2,3.7,2.32]],"ltp":3.9,"tv":2083.33,"id":4423910},{"batb":[[2,1.27,558.9]],"ltp":1.34,"tv":15325.05,"id":2258415}]}]}
{"op":"mcm","clk":"1001500533","pt":1580637089322,"mc":[{"id":"1.168215937","rc":[{"trd":[[4.2,3.52]],"batb":[[0,4.2,2.04]],"ltp":4.2,"tv":2086.85,"id":4423910}],"tv":17411.9}]}
{"op":"mcm","clk":"1001500893","pt":1580637096958,"mc":[{"id":"1.168215937","rc":[{"batb":[[0,3.85,2],[1,3.7,2.32],[2,3.6,15.96]],"batl":[[2,4.8,2]],"ltp":4.2,"tv":2086.85,"id":4423910},{"batb":[[0,1.3,2526.83]],"ltp":1.34,"tv":15325.05,"id":2258415}]}]}
{"op":"mcm","clk":"1001500922","pt":1580637097370,"mc":[{"id":"1.168215937","rc":[{"batb":[[0,3.7,2.32],[1,3.6,15.96],[2,3.55,2.59]],"batl":[[1,4.8,2],[2,5,2]],"ltp":4.2,"tv":2086.85,"id":4423910},{"batb":[[0,1.3,164.29],[1,1.27,558.9],[2,1.25,577.97]],"batl":[[0,1.35,480.59],[1,1.37,541.9],[2,1.38,42.01]],"ltp":1.34,"tv":15325.05,"id":2258415}]}]}
{"op":"mcm","clk":"1001501025","pt":1580637099634,"mc":[{"id":"1.168215937","rc":[{"batb":[[1,3.55,2.59],[2,3.5,2.64]],"batl":[[0,4.8,2],[1,5,2],[2,6,106.18]],"ltp":4.2,"tv":2086.85,"id":4423910},{"batb":[[0,1.3,24.81]],"batl":[[2,1.39,43.5]],"ltp":1.34,"tv":15325.05,"id":2258415}]}]}
{"op":"mcm","clk":"1001501052","pt":1580637100361,"mc":[{"id":"1.168215937","rc":[{"batb":[[1,1.27,787.69],[2,1.26,598.51]],"batl":[[1,1.36,411.2],[2,1.37,919.82]],"ltp":1.34,"tv":15325.05,"id":2258415}]}]}
{"op":"mcm","clk":"1001501339","pt":1580637106069,"mc":[{"id":"1.168215937","rc":[{"trd":[[1.35,2.07]],"batl":[[0,1.35,479.56]],"ltp":1.35,"tv":15327.12,"id":2258415}],"tv":17413.97}]}
{"op":"mcm","clk":"1001501639","pt":1580637111880,"mc":[{"id":"1.168215937","rc":[{"batl":[[0,4.6,1.76],[1,4.8,2],[2,5,2]],"ltp":4.2,"tv":2086.85,"id":4423910}]}]}
{"op":"mcm","clk":"1001502017","pt":1580637118672,"mc":[{"id":"1.168215937","rc":[{"batb":[[1,1.27,558.9],[2,1.25,577.97]],"batl":[[0,1.36,411.2],[1,1.37,422.42],[2,1.39,43.5]],"ltp":1.35,"tv":15327.12,"id":2258415}]}]}
{"op":"mcm","clk":"1001502153","pt":1580637121596,"mc":[{"id":"1.168215937","rc":[{"batb":[[0,3.9,6.6],[1,3.7,2.32],[2,3.55,2.59]],"batl":[[0,4.1,6.84],[1,4.4,298.1],[2,4.6,1.76]],"ltp":4.2,"tv":2086.85,"id":4423910},{"batb":[[0,1.33,356.38],[1,1.32,466.08],[2,1.3,170.72]],"batl":[[0,1.34,924.99],[1,1.36,411.2],[2,1.37,422.42]],"ltp":1.35,"tv":15327.12,"id":2258415}]}]}
{"op":"mcm","clk":"1001502202","pt":1580637122422,"mc":[{"id":"1.168215937","rc":[{"batl":[[0,4.1,20.28]],"ltp":4.2,"tv":2086.85,"id":4423910},{"batb":[[1,1.32,597.15]],"ltp":1.35,"tv":15327.12,"id":2258415}]}]}
{"op":"mcm","clk":"1001502476","pt":1580637127725,"mc":[{"id":"1.168215937","rc":[{"batb":[[2,1.31,494.03]],"batl":[[2,1.37,903.01]],"ltp":1.35,"tv":15327.12,"id":2258415}]}]}
{"op":"mcm","clk":"1001502528","pt":1580637128602,"mc":[{"id":"1.168215937","rc":[{"batl":[[2,4.5,2.01]],"ltp":4.2,"tv":2086.85,"id":4423910}]}]}
{"op":"mcm","clk":"1001502831","pt":1580637133423,"mc":[{"id":"1.168215937","rc":[{"trd":[[1.34,143.5]],"batl":[[0,1.34,923.95]],"ltp":1.34,"tv":15329.2,"id":2258415}],"tv":17416.05}]}
{"op":"mcm","clk":"1001503286","pt":1580637141839,"mc":[{"id":"1.168215937","rc":[{"batb":[[0,3.7,2.32],[1,3.55,2.59],[2,3.5,19.44]],"batl":[[0,4.1,13.44],[1,4.4,48.09]],"ltp":4.2,"tv":2086.85,"id":4423910},{"batl":[[0,1.36,411.2],[1,1.37,903.01],[2,1.39,540.9]],"ltp":1.34,"tv":15329.2,"id":2258415}]}]}
{"op":"mcm","clk":"1001503307","pt":1580637142149,"mc":[{"id":"1.168215937","rc":[{"batb":[[0,3.55,2.59],[1,3.5,19.44],[2,3.4,2.26]],"batl":[[1,4.5,2.01],[2,4.6,1.76]],"ltp":4.2,"tv":2086.85,"id":4423910},{"batb":[[0,1.32,131.07],[1,1.31,494.03],[2,1.3,24.81]],"batl":[[0,1.37,480.59],[1,1.39,540.9],[2,1.4,79.95]],"ltp":1.34,"tv":15329.2,"id":2258415}]}]}
{"op":"mcm","clk":"1001503378","pt":1580637143151,"mc":[{"id":"1.168215937","rc":[{"batb":[[1,3.5,2.64]],"batl":[[0,4.5,2.01],[1,4.6,1.76],[2,4.8,2]],"ltp":4.2,"tv":2086.85,"id":4423910},{"batb":[[0,1.31,494.03],[1,1.3,24.81],[2,1.29,575.65]],"batl":[[2,1.4,37.94]],"ltp":1.34,"tv":15329.2,"id":2258415}]}]}
{"op":"mcm","clk":"1001503667","pt":1580637147517,"mc":[{"id":"1.168215937","rc":[{"batb":[[0,1.32,401.27],[1,1.31,979.61],[2,1.3,24.81]],"batl":[[0,1.35,411.14],[1,1.36,391.07],[2,1.37,480.59]],"ltp":1.34,"tv":15329.2,"id":2258415}]}]}
{"op":"mcm","clk":"1001503725","pt":1580637148543,"mc":[{"id":"1.168215937","rc":[{"batl":[[0,1.33,19.64],[1,1.35,411.14],[2,1.36,391.07]],"ltp":1.34,"tv":15329.2,"id":2258415}]}]}
{"op":"mcm","clk":"1001503796","pt":1580637149734,"mc":[{"id":"1.168215937","rc":[{"batb":[[0,1.31,494.03],[1,1.3,24.81],[2,1.29,575.65]],"batl":[[1,1.37,480.59],[2,1.39,540.9]],"ltp":1.34,"tv":15329.2,"id":2258415}]}]}
{"op":"mcm","clk":"1001503946","pt":1580637152741,"mc":[{"id":"1.168215937","rc":[{"batl":[[2,1.39,917.52]],"ltp":1.34,"tv":15329.2,"id":2258415}]}]}
{"op":"mcm","clk":"1001504044","pt":1580637154655,"mc":[{"id":"1.168215937","rc":[{"batl":[[0,1.37,480.59],[1,1.39,917.52],[2,1.4,380.91]],"ltp":1.34,"tv":15329.2,"id":2258415}]}]}
{"op":"mcm","clk":"1001504123","pt":1580637155838,"mc":[{"id":"1.168215937","rc":[{"batl":[[1,1.39,540.9],[2,1.4,37.94]],"ltp":1.34,"tv":15329.2,"id":2258415}]}]}
{"op":"mcm","clk":"1001504146","pt":1580637156259,"mc":[{"id":"1.168215937","rc":[{"batl":[[0,4.6,1.76],[1,4.8,2],[2,5,3.76]],"ltp":4.2,"tv":2086.85,"id":4423910},{"batb":[[0,1.3,24.81],[1,1.28,689.08],[2,1.27,646.1]],"ltp":1.34,"tv":15329.2,"id":2258415}]}]}
{"op":"mcm","clk":"1001504307","pt":1580637158833,"mc":[{"id":"1.168215937","rc":[{"trd":[[4.4,7.33]],"batb":[[0,4.4,266.73],[1,4.1,2],[2,3.55,2.59]],"batl":[[2,5,128.2]],"ltp":4.4,"tv":2094.18,"id":4423910},{"trd":[[1.3,24.81]],"batb":[[0,1.28,2463.47],[1,1.27,646.1],[2,1.25,564.91]],"batl":[[0,1.31,2061.09],[1,1.32,455.51],[2,1.37,480.59]],"ltp":1.3,"tv":15354.02,"id":2258415}],"tv":17448.2}]}
{"op":"mcm","clk":"1001504392","pt":1580637160571,"mc":[{"id":"1.168215937","rc":[{"batb":[[2,3.8,14.28]],"batl":[[0,4.6,12.68]],"ltp":4.4,"tv":2094.18,"id":4423910},{"batb":[[0,1.28,2613.02]],"batl":[[2,1.35,42.01]],"ltp":1.3,"tv":15354.02,"id":2258415}]}]}
{"op":"mcm","clk":"1001504685","pt":1580637165742,"mc":[{"id":"1.168215937","rc":[{"batb":[[2,3.9,2.06]],"ltp":4.4,"tv":2094.18,"id":4423910},{"batb":[[2,1.25,1067.35]],"batl":[[0,1.31,2550.08],[1,1.32,961.31],[2,1.34,49.75]],"ltp":1.3,"tv":15354.02,"id":2258415}]}]}
{"op":"mcm","clk":"1001505135","pt":1580637173961,"mc":[{"id":"1.168215937","rc":[{"trd":[[4.4,7.83]],"batb":[[0,4.4,266.23]],"ltp":4.4,"tv":2094.68,"id":4423910},{"trd":[[1.28,878.16],[1.3,26.49]],"batb":[[0,1.28,2173.95]],"ltp":1.28,"tv":16233.85,"id":2258415}],"tv":18328.53}]}
{"op":"mcm","clk":"1001505212","pt":1580637174943,"mc":[{"id":"1.168215937","rc":[{"trd":[[4.4,13.29]],"batb":[[0,4.4,260.77]],"ltp":4.4,"tv":2100.14,"id":4423910},{"trd":[[1.3,44.98]],"ltp":1.3,"tv":16252.34,"id":2258415}],"tv":18352.48}]}
{"op":"mcm","clk":"1001505350","pt":1580637176858,"mc":[{"id":"1.168215937","rc":[{"batb":[[0,1.28,2370.39]],"batl":[[0,1.31,2787.27]],"ltp":1.3,"tv":16252.34,"id":2258415}]}]}
{"op":"mcm","clk":"1001505603","pt":1580637180873,"mc":[{"id":"1.168215937","rc":[{"batb":[[0,3.9,2.06],[1,3.8,14.28],[2,3.75,2.47]],"batl":[[1,5,1.76],[2,5.2,2]],"ltp":4.4,"tv":2100.14,"id":4423910},{"batb":[[0,1.28,596],[1,1.27,581.23],[2,1.25,502.44]],"batl":[[0,1.31,1069.71],[1,1.32,959.2]],"ltp":1.3,"tv":16252.34,"id":2258415}]}]}
{"op":"mcm","clk":"1001505622","pt":1580637181174,"mc":[{"id":"1.168215937","rc":[{"batb":[[1,3.75,2.47],[2,3.55,2.59]],"batl":[[0,4.6,1.76]],"ltp":4.4,"tv":2100.14,"id":4423910},{"batb":[[0,1.25,502.44],[1,1.24,595.51],[2,1.22,77.84]],"batl":[[0,1.31,488.99],[1,1.32,505.8]],"ltp":1.3,"tv":16252.34,"id":2258415}]}]}
{"op":"mcm","clk":"1001505793","pt":1580637184071,"mc":[{"id":"1.168215937","rc":[{"batb":[[1,1.24,995.52],[2,1.23,703.71]],"batl":[[2,1.34,656.7]],"ltp":1.3,"tv":16252.34,"id":2258415}]}]}
{"op":"mcm","clk":"1001505875","pt":1580637185465,"mc":[{"id":"1.168215937","rc":[{"batb":[[1,1.24,595.51],[2,1.22,77.84]],"batl":[[2,1.34,49.75]],"ltp":1.3,"tv":16252.34,"id":2258415}]}]}
{"op":"mcm","clk":"1001506028","pt":1580637188500,"mc":[{"id":"1.168215937","rc":[{"batb":[[0,1.27,545.31],[1,1.26,610.72],[2,1.25,502.44]],"batl":[[0,1.3,549.49],[1,1.31,961.07],[2,1.32,505.8]],"ltp":1.3,"tv":16252.34,"id":2258415}]}]}
{"op":"mcm","clk":"1001506272","pt":1580637192905,"mc":[{"id":"1.168215937","rc":[{"batl":[[0,1.28,2],[1,1.3,549.49],[2,1.31,961.07]],"ltp":1.3,"tv":16252.34,"id":2258415}]}]}
{"op":"mcm","clk":"1001506426","pt":1580637195331,"mc":[{"id":"1.168215937","rc":[{"batb":[[0,1.25,502.44],[1,1.24,595.51],[2,1.22,77.84]],"batl":[[0,1.31,488.99],[1,1.32,505.8],[2,1.34,49.75]],"ltp":1.3,"tv":16252.34,"id":2258415}]}]}
{"op":"mcm","clk":"1001506588","pt":1580637198329,"mc":[{"id":"1.168215937","rc":[{"batb":[[1,1.24,995.52],[2,1.23,703.71]],"batl":[[2,1.34,656.7]],"ltp":1.3,"tv":16252.34,"id":2258415}]}]}
{"op":"mcm","clk":"1001506824","pt":1580637202875,"mc":[{"id":"1.168215937","rc":[{"trd":[[4.6,0.49]],"batb":[[2,2.72,378.25]],"batl":[[0,4.6,1.27]],"ltp":4.6,"tv":2100.63,"id":4423910},{"trd":[[1.27,1.78]],"batb":[[0,1.24,476.28],[1,1.23,703.71],[2,1.22,77.84]],"batl":[[2,1.34,49.75]],"ltp":1.27,"tv":16254.12,"id":2258415}],"tv":18354.75}]}
{"op":"mcm","clk":"1001506925","pt":1580637204944,"mc":[{"id":"1.168215937","rc":[{"trd":[[4.6,1.76],[5,1.76]],"batb":[[0,5,115.24],[1,3.9,2.06],[2,3.75,2.47]],"batl":[[0,5.2,2],[1,5.3,7.05],[2,5.5,1.76]],"ltp":5.0,"tv":2103.65,"id":4423910},{"trd":[[1.25,7.03],[1.27,6.37]],"batb":[[0,1.24,2290.8]],"batl":[[0,1.25,462.35],[1,1.26,1783.12],[2,1.31,488.99]],"ltp":1.25,"tv":16265.74,"id":2258415}],"tv":18369.39}]}
{"op":"mcm","clk":"1001506966","pt":1580637205876,"mc":[{"id":"1.168215937","rc":[{"batb":[[1,4.7,2],[2,3.9,2.06]],"ltp":5.0,"tv":2103.65,"id":4423910},{"batl":[[1,1.26,2113.21],[2,1.27,564.53]],"ltp":1.25,"tv":16265.74,"id":2258415}]}]}
{"op":"mcm","clk":"1001506989","pt":1580637206341,"mc":[{"id":"1.168215937","rc":[{"batb":[[2,4.5,11.76]],"batl":[[2,5.5,11]],"ltp":5.0,"tv":2103.65,"id":4423910},{"batb":[[2,1.22,245.88]],"ltp":1.25,"tv":16265.74,"id":2258415}]}]}
{"op":"mcm","clk":"1001507469","pt":1580637215873,"mc":[{"id":"1.168215937","rc":[{"trd":[[1.25,115.15]],"batl":[[0,1.25,408.29]],"ltp":1.25,"tv":16373.86,"id":2258415}],"tv":18477.51}]}
{"op":"mcm","clk":"1001507757","pt":1580637221650,"mc":[{"id":"1.168215937","rc":[{"trd":[[1.25,115.97]],"batl":[[0,1.25,407.88]],"ltp":1.25,"tv":16374.68,"id":2258415}],"tv":18478.33}]}
{"op":"mcm","clk":"1001508083","pt":1580637227662,"mc":[{"id":"1.168215937","rc":[{"trd":[[1.25,147.97]],"batl":[[0,1.25,391.88]],"ltp":1.25,"tv":16406.68,"id":2258415}],"tv":18510.33}]}
{"op":"mcm","clk":"1001508575","pt":1580637237894,"mc":[{"id":"1.168215937","rc":[{"trd":[[1.25,151.33]],"batl":[[0,1.25,390.2]],"ltp":1.25,"tv":16410.04,"id":2258415}],"tv":18513.69}]}
{"op":"mcm","clk":"1001509434","pt":1580637253001,"mc":[{"id":"1.168215937","rc":[{"trd":[[1.25,171.33]],"batl":[[0,1.25,380.2]],"ltp":1.25,"tv":16430.04,"id":2258415}],"tv":18533.69}]}
{"op":"mcm","clk":"1001510526","pt":1580637276013,"mc":[{"id":"1.168215937","rc":[{"trd":[[1.24,200]],"batb":[[0,1.24,2190.8]],"ltp":1.24,"tv":16630.04,"id":2258415}],"tv":18733.69}]}
{"op":"mcm","clk":"1001511223","pt":1580637288951,"mc":[{"id":"1.168215937","rc":[{"batb":[[0,4.7,2],[1,4.5,11.76],[2,3.9,2.06]],"batl":[[1,5.5,11],[2,5.6,2]],"ltp":5.0,"tv":2103.65,"id":4423910},{"batl":[[0,1.26,2113.21],[1,1.27,564.53],[2,1.28,42.01]],"ltp":1.24,"tv":16630.04,"id":2258415}]}]}
{"op":"mcm","clk":"1001511257","pt":1580637289459,"mc":[{"id":"1.168215937","rc":[{"batb":[[0,2.72,378.25],[1,2.6,75.72],[2,2.2,75.72]],"batl":[[0,5.5,1.76],[1,5.6,2],[2,6,1.76]],"ltp":5.0,"tv":2103.65,"id":4423910},{"batb":[[0,1.23,374.4],[1,1.22,77.84],[2,1.18,29.51]],"batl":[[0,1.49,756.18],[1,1.5,4.2],[2,1.6,756.18]],"ltp":1.24,"tv":16630.04,"id":2258415}]}]}
{"op":"mcm","clk":"1001511417","pt":1580637292954,"mc":[{"id":"1.168215937","rc":[{"batb":[[0,4.4,3.91],[1,4.2,3.92],[2,2.72,378.25]],"batl":[[0,5.4,2],[1,5.5,1.76],[2,5.6,2]],"ltp":5.0,"tv":2103.65,"id":4423910},{"batb":[[0,1.23,452.03],[1,1.22,819.44]],"batl":[[0,1.29,777.53],[1,1.3,488.97],[2,1.31,53.5]],"ltp":1.24,"tv":16630.04,"id":2258415}]}]}
{"op":"mcm","clk":"1001511955","pt":1580637302787,"mc":[{"id":"1.168215937","rc":[{"batb":[[0,1.23,77.63],[1,1.22,77.84]],"ltp":1.24,"tv":16630.04,"id":2258415}]}]}
{"op":"mcm","clk":"1001511969","pt":1580637302993,"mc":[{"id":"1.168215937","rc":[{"batl":[[0,5.5,1.76],[1,5.6,2],[2,6,1.76]],"ltp":5.0,"tv":2103.65,"id":4423910},{"batb":[[0,1.22,77.84],[1,1.18,29.51],[2,1.05,2397.83]],"ltp":1.24,"tv":16630.04,"id":2258415}]}]}
{"op":"mcm","clk":"1001512091","pt":1580637305776,"mc":[{"id":"1.168215937","rc":[{"batl":[[0,5.3,297.96],[1,5.4,34.85],[2,5.5,1.76]],"ltp":5.0,"tv":2103.65,"id":4423910},{"batb":[[0,1.26,454.74],[1,1.25,639.12],[2,1.24,152.53]],"batl":[[0,1.28,1290.05],[1,1.29,777.53],[2,1.3,488.97]],"ltp":1.24,"tv":16630.04,"id":2258415}]}]}
{"op":"mcm","clk":"1001512142","pt":1580637306806,"mc":[{"id":"1.168215937","rc":[{"batb":[[1,4.3,12.6],[2,4.2,3.92]],"batl":[[0,5.2,9.24],[1,5.3,297.96],[2,5.4,34.85]],"ltp":5.0,"tv":2103.65,"id":4423910},{"batb":[[2,1.24,471.84]],"ltp":1.24,"tv":16630.04,"id":2258415}]}]}
{"op":"mcm","clk":"1001512218","pt":1580637307992,"mc":[{"id":"1.168215937","rc":[{"batb":[[2,1.24,320.57]],"ltp":1.24,"tv":16630.04,"id":2258415}]}]}
{"op":"mcm","clk":"1001512356","pt":1580637310313,"mc":[{"id":"1.168215937","rc":[{"trd":[[1.26,0.72]],"batb":[[0,1.26,454.38]],"ltp":1.26,"tv":16630.76,"id":2258415}],"tv":18734.42}]}
{"op":"mcm","clk":"1001512589","pt":1580637313527,"mc":[{"id":"1.168215937","rc":[{"batl":[[0,5,2],[1,5.2,9.24],[2,5.3,297.96]],"ltp":5.0,"tv":2103.65,"id":4423910},{"batb":[[1,1.25,704.65]],"ltp":1.26,"tv":16630.76,"id":2258415}]}]}
{"op":"mcm","clk":"1001512808","pt":1580637317909,"mc":[{"id":"1.168215937","rc":[{"batb":[[0,4.3,12.6],[1,4.2,3.92],[2,4,4.23]],"batl":[[2,5.5,1.76]],"ltp":5.0,"tv":2103.65,"id":4423910},{"batb":[[0,1.25,65.53],[1,1.24,168.04],[2,1.22,77.84]],"batl":[[0,1.31,95.51],[1,1.33,51.5],[2,1.49,756.18]],"ltp":1.26,"tv":16630.76,"id":2258415}]}]}
{"op":"mcm","clk":"1001512817","pt":1580637318118,"mc":[{"id":"1.168215937","rc":[{"batb":[[1,4,4.23],[2,2.72,378.25]],"ltp":5.0,"tv":2103.65,"id":4423910},{"batl":[[0,1.31,42.01]],"ltp":1.26,"tv":16630.76,"id":2258415}]}]}
{"op":"mcm","clk":"1001512873","pt":1580637319410,"mc":[{"id":"1.168215937","rc":[{"batb":[[0,4,4.23],[1,2.72,378.25],[2,2.6,75.72]],"batl":[[1,5.5,1.76],[2,6,1.76]],"ltp":5.0,"tv":2103.65,"id":4423910},{"batb":[[1,1.18,29.51],[2,1.05,2397.83]],"batl":[[0,1.33,51.5],[1,1.49,756.18],[2,1.5,4.2]],"ltp":1.26,"tv":16630.76,"id":2258415}]}]}
{"op":"mcm","clk":"1001512934","pt":1580637320804,"mc":[{"id":"1.168215937","rc":[{"batb":[[1,1.24,856.81],[2,1.23,705.43]],"batl":[[0,1.32,603.08],[1,1.33,489.33],[2,1.49,756.18]],"ltp":1.26,"tv":16630.76,"id":2258415}]}]}
{"op":"mcm","clk":"1001512961","pt":1580637321402,"mc":[{"id":"1.168215937","rc":[{"batl":[[0,1.33,51.5],[1,1.49,756.18],[2,1.5,4.2]],"ltp":1.26,"tv":16630.76,"id":2258415}]}]}
{"op":"mcm","clk":"1001512999","pt":1580637322332,"mc":[{"id":"1.168215937","rc":[{"batl":[[0,1.26,226.85],[1,1.33,51.5],[2,1.49,756.18]],"ltp":1.26,"tv":16630.76,"id":2258415}]}]}
{"op":"mcm","clk":"1001513077","pt":1580637323902,"mc":[{"id":"1.168215937","rc":[{"batb":[[0,4.5,461.94],[1,4,4.23],[2,2.72,378.25]],"batl":[[1,5.1,6.06],[2,5.4,298]],"ltp":5.0,"tv":2103.65,"id":4423910},{"batl":[[0,1.26,243.21],[1,1.28,3514.02],[2,1.29,1626.34]],"ltp":1.26,"tv":16630.76,"id":2258415}]}]}
{"op":"mcm","clk":"1001513104","pt":1580637324517,"mc":[{"id":"1.168215937","rc":[{"batb":[[0,4.5,50.51],[1,4.4,11.76],[2,4,4.23]],"batl":[[2,5.4,307.24]],"ltp":5.0,"tv":2103.65,"id":4423910},{"batb":[[2,1.23,873.47]],"batl":[[1,1.27,477.31],[2,1.28,4095.55]],"ltp":1.26,"tv":16630.76,"id":2258415}]}]}
{"op":"mcm","clk":"1001513278","pt":1580637328127,"mc":[{"id":"1.168215937","rc":[{"batb":[[1,4,4.23],[2,2.72,378.25]],"ltp":5.0,"tv":2103.65,"id":4423910},{"batb":[[2,1.23,705.43]],"ltp":1.26,"tv":16630.76,"id":2258415}]}]}
{"op":"mcm","clk":"1001513405","pt":1580637331020,"mc":[{"id":"1.168215937","rc":[{"batb":[[0,4.5,62.27],[1,4.4,4.06],[2,4.2,4.07]],"batl":[[2,5.2,2]],"ltp":5.0,"tv":2103.65,"id":4423910},{"batb":[[1,1.24,924.83],[2,1.23,794.06]],"ltp":1.26,"tv":16630.76,"id":2258415}]}]}
{"op":"mcm","clk":"1001513533","pt":1580637333605,"mc":[{"id":"1.168215937","rc":[{"batb":[[1,1.24,1082.19]],"ltp":1.26,"tv":16630.76,"id":2258415}]}]}
{"op":"mcm","clk":"1001513643","pt":1580637335927,"mc":[{"id":"1.168215937","rc":[{"batb":[[0,4.5,16.08]],"batl":[[0,5.2,2],[1,5.4,11.24],[2,5.5,1.76]],"ltp":5.0,"tv":2103.65,"id":4423910},{"batb":[[0,1.24,1082.19],[1,1.23,794.06],[2,1.18,29.51]],"batl":[[0,1.26,226.85],[2,1.28,581.53]],"ltp":1.26,"tv":16630.76,"id":2258415}]}]}
{"op":"mcm","clk":"1001513661","pt":1580637336339,"mc":[{"id":"1.168215937","rc":[{"batl":[[0,5.4,11.24],[1,5.5,1.76],[2,6,1.76]],"ltp":5.0,"tv":2103.65,"id":4423910},{"batb":[[0,1.24,157.36]],"batl":[[1,1.28,45.34],[2,1.29,109.51]],"ltp":1.26,"tv":16630.76,"id":2258415}]}]}
{"op":"mcm","clk":"1001513759","pt":1580637337944,"mc":[{"id":"1.168215937","rc":[{"batb":[[0,4.2,4.07],[1,2.72,378.25],[2,2.6,75.72]],"batl":[[0,5.4,2]],"ltp":5.0,"tv":2103.65,"id":4423910},{"batl":[[0,1.31,53.5],[1,1.49,756.18],[2,1.5,4.2]],"ltp":1.26,"tv":16630.76,"id":2258415}]}]}
{"op":"mcm","clk":"1001513842","pt":1580637339937,"mc":[{"id":"1.168215937","rc":[{"batb":[[2,1.22,751.82]],"batl":[[0,1.3,570.63],[1,1.31,526.34],[2,1.49,756.18]],"ltp":1.26,"tv":16630.76,"id":2258415}]}]}
{"op":"mcm","clk":"1001513984","pt":1580637342830,"mc":[{"id":"1.168215937","rc":[{"batb":[[0,1.24,235.63]],"ltp":1.26,"tv":16630.76,"id":2258415}]}]}
{"op":"mcm","clk":"1001514040","pt":1580637343849,"mc":[{"id":"1.168215937","rc":[{"batb":[[0,1.24,157.36]],"ltp":1.26,"tv":16630.76,"id":2258415}]}]}
{"op":"mcm","clk":"1001514108","pt":1580637345036,"mc":[{"id":"1.168215937","rc":[{"batl":[[0,1.31,53.5],[1,1.49,756.18],[2,1.5,4.2]],"ltp":1.26,"tv":16630.76,"id":2258415}]}]}
{"op":"mcm","clk":"1001514195","pt":1580637346940,"mc":[{"id":"1.168215937","rc":[{"batb":[[0,4.4,4.06],[1,4.2,4.07],[2,2.72,378.25]],"ltp":5.0,"tv":2103.65,"id":4423910},{"batl":[[0,1.29,61.5],[1,1.31,53.5],[2,1.49,756.18]],"ltp":1.26,"tv":16630.76,"id":2258415}]}]}
{"op":"mcm","clk":"1001514230","pt":1580637347863,"mc":[{"id":"1.168215937","rc":[{"batb":[[0,5.1,182.58],[2,2.6,75.72]],"batl":[[0,5.3,5.29],[1,5.4,2],[2,5.5,1.76]],"ltp":5.0,"tv":2103.65,"id":4423910},{"batl":[[0,1.25,11.98],[1,1.26,2416.74],[2,1.27,1453.68]],"ltp":1.26,"tv":16630.76,"id":2258415}]}]}
{"op":"mcm","clk":"1001514275","pt":1580637348644,"mc":[{"id":"1.168215937","rc":[{"batb":[[1,4.8,4.08],[2,4.6,10.92]],"ltp":5.0,"tv":2103.65,"id":4423910},{"batl":[[1,1.26,1828.72],[2,1.27,700.75]],"ltp":1.26,"tv":16630.76,"id":2258415}]}]}
{"op":"mcm","clk":"1001514573","pt":1580637354790,"mc":[{"id":"1.168215937","rc":[{"batb":[[2,4.7,3.92]],"ltp":5.0,"tv":2103.65,"id":4423910},{"batb":[[2,1.22,829.16]],"batl":[[2,1.27,763.25]],"ltp":1.26,"tv":16630.76,"id":2258415}]}]}
{"op":"mcm","clk":"1001514774","pt":1580637358974,"mc":[{"id":"1.168215937","rc":[{"trd":[[1.24,400.01]],"batb":[[0,1.24,57.36]],"ltp":1.24,"tv":16830.77,"id":2258415}],"tv":18934.42}]}
{"op":"mcm","clk":"1001514875","pt":1580637361201,"mc":[{"id":"1.168215937","rc":[{"batl":[[1,1.26,1781.97]],"ltp":1.24,"tv":16830.77,"id":2258415}]}]}
{"op":"mcm","clk":"1001515256","pt":1580637368083,"mc":[{"id":"1.168215937","rc":[{"batl":[[2,1.27,805.26]],"ltp":1.24,"tv":16830.77,"id":2258415}]}]}
{"op":"mcm","clk":"1001515354","pt":1580637369790,"mc":[{"id":"1.168215937","rc":[{"batl":[[1,1.26,817.97]],"ltp":1.24,"tv":16830.77,"id":2258415}]}]}
{"op":"mcm","clk":"1001515935","pt":1580637379609,"mc":[{"id":"1.168215937","rc":[{"batb":[[0,4.5,4.2],[1,3,380.84],[2,2.6,75.72]],"batl":[[0,5.5,1.76],[1,5.6,2],[2,6,1.76]],"ltp":5.0,"tv":2103.65,"id":4423910},{"batb":[[1,1.22,829.16],[2,1.18,29.51]],"batl":[[0,1.28,60.59],[1,1.49,756.18],[2,1.5,4.2]],"ltp":1.24,"tv":16830.77,"id":2258415}]}]}
{"op":"mcm","clk":"1001516059","pt":1580637382826,"mc":[{"id":"1.168215937","rc":[{"batb":[[0,4.7,3.92],[1,4.5,4.2],[2,3,380.84]],"batl":[[0,5.4,2],[1,5.5,1.76],[2,5.6,2]],"ltp":5.0,"tv":2103.65,"id":4423910},{"batb":[[1,1.23,72.63],[2,1.22,866]],"batl":[[0,1.27,66.5],[1,1.28,598.24],[2,1.29,512.82]],"ltp":1.24,"tv":16830.77,"id":2258415}]}]}
{"op":"mcm","clk":"1001516076","pt":1580637383030,"mc":[{"id":"1.168215937","rc":[{"batb":[[0,4.5,4.2],[1,3,380.84],[2,2.6,75.72]],"batl":[[0,5.5,1.76],[1,5.6,2],[2,6,1.76]],"ltp":5.0,"tv":2103.65,"id":4423910},{"batb":[[1,1.22,866],[2,1.21,795.77]],"batl":[[0,1.28,598.24],[1,1.29,512.82],[2,1.49,756.18]],"ltp":1.24,"tv":16830.77,"id":2258415}]}]}
{"op":"mcm","clk":"1001516292","pt":1580637387019,"mc":[{"id":"1.168215937","rc":[{"batl":[[0,4.8,5.45],[1,5.5,1.76],[2,5.6,2]],"ltp":5.0,"tv":2103.65,"id":4423910}]}]}
{"op":"mcm","clk":"1001516375","pt":1580637388615,"mc":[{"id":"1.168215937","rc":[{"batl":[[0,1.28,60.59],[1,1.49,756.18],[2,1.5,4.2]],"ltp":1.24,"tv":16830.77,"id":2258415}]}]}
{"op":"mcm","clk":"1001516429","pt":1580637389806,"mc":[{"id":"1.168215937","rc":[{"batb":[[0,4.7,3.92],[1,4.5,4.2],[2,3,380.84]],"batl":[[1,5.4,2],[2,5.5,1.76]],"ltp":5.0,"tv":2103.65,"id":4423910},{"batb":[[1,1.23,71.63],[2,1.22,866]],"batl":[[0,1.27,67.5],[1,1.28,60.59],[2,1.49,756.18]],"ltp":1.24,"tv":16830.77,"id":2258415}]}]}
{"op":"mcm","clk":"1001516444","pt":1580637390012,"mc":[{"id":"1.168215937","rc":[{"batb":[[0,4.5,4.2],[1,3,380.84],[2,2.6,75.72]],"batl":[[1,5.5,1.76],[2,5.6,2]],"ltp":5.0,"tv":2103.65,"id":4423910},{"batb":[[1,1.22,866],[2,1.21,795.77]],"batl":[[0,1.28,60.59],[1,1.49,756.18],[2,1.5,4.2]],"ltp":1.24,"tv":16830.77,"id":2258415}]}]}
{"op":"mcm","clk":"1001516665","pt":1580637391626,"mc":[{"id":"1.168215937","rc":[{"trd":[[4.8,5.45],[5.2,7.6]],"batb":[[0,5.3,148.8],[1,4.8,3.88],[2,4.5,4.2]],"batl":[[0,5.5,7.22],[1,5.6,2],[2,5.9,238]],"ltp":5.2,"tv":2116.7,"id":4423910},{"trd":[[1.24,482.86],[1.26,21.49]],"batb":[[0,1.22,866],[1,1.21,795.77],[2,1.2,705.67]],"batl":[[0,1.25,2057.88],[1,1.26,782.32],[2,1.28,60.59]],"ltp":1.24,"tv":16934.39,"id":2258415}],"tv":19051.1}]}
{"op":"mcm","clk":"1001517031","pt":1580637394920,"mc":[{"id":"1.168215937","rc":[{"batb":[[1,4.8,14.8]],"batl":[[2,5.8,8.4]],"ltp":5.2,"tv":2116.7,"id":4423910},{"batl":[[1,1.26,824.33]],"ltp":1.24,"tv":16934.39,"id":2258415}]}]}
{"op":"mcm","clk":"1001517236","pt":1580637398441,"mc":[{"id":"1.168215937","rc":[{"batl":[[2,5.8,10.4]],"ltp":5.2,"tv":2116.7,"id":4423910},{"batb":[[1,1.21,882.46]],"ltp":1.24,"tv":16934.39,"id":2258415}]}]}
{"op":"mcm","clk":"1001517494","pt":1580637401437,"mc":[{"id":"1.168215937","rc":[{"batl":[[0,5.5,1.76]],"ltp":5.2,"tv":2116.7,"id":4423910}]}]}
{"op":"mcm","clk":"1001517656","pt":1580637403714,"mc":[{"id":"1.168215937","rc":[{"batb":[[0,4.8,14.8],[1,4.5,4.2],[2,3,456.56]],"ltp":5.2,"tv":2116.7,"id":4423910},{"batb":[[0,1.22,335.4],[2,1.18,29.51]],"batl":[[0,1.26,478.08],[1,1.28,60.59],[2,1.49,756.18]],"ltp":1.24,"tv":16934.39,"id":2258415}]}]}
{"op":"mcm","clk":"1001517730","pt":1580637405359,"mc":[{"id":"1.168215937","rc":[{"batb":[[0,4.8,3.88]],"batl":[[2,5.8,2]],"ltp":5.2,"tv":2116.7,"id":4423910},{"batl":[[0,1.26,436.07]],"ltp":1.24,"tv":16934.39,"id":2258415}]}]}
{"op":"mcm","clk":"1001517798","pt":1580637406539,"mc":[{"id":"1.168215937","rc":[{"batl":[[1,1.27,561.47],[2,1.28,60.59]],"ltp":1.24,"tv":16934.39,"id":2258415}]}]}
{"op":"mcm","clk":"1001517942","pt":1580637408745,"mc":[{"id":"1.168215937","rc":[{"batb":[[1,3,456.56],[2,2.6,75.72]],"ltp":5.2,"tv":2116.7,"id":4423910},{"trd":[[1.22,6.04]],"batb":[[0,1.22,332.38]],"batl":[[0,1.26,44.75],[1,1.49,756.18],[2,1.5,4.2]],"ltp":1.22,"tv":16940.43,"id":2258415}],"tv":19057.14}]}
{"op":"mcm","clk":"1001518110","pt":1580637411673,"mc":[{"id":"1.168215937","rc":[{"batb":[[0,5.2,40.74],[1,5,365.91],[2,4.8,3.88]],"batl":[[0,5.5,8.06]],"ltp":5.2,"tv":2116.7,"id":4423910},{"batb":[[2,1.2,377.4]],"batl":[[0,1.24,1769.82],[1,1.25,1955.81],[2,1.26,44.75]],"ltp":1.22,"tv":16940.43,"id":2258415}]}]}
{"op":"mcm","clk":"1001518152","pt":1580637412241,"mc":[{"id":"1.168215937","rc":[{"batb":[[1,5,375.99]],"ltp":5.2,"tv":2116.7,"id":4423910},{"batb":[[2,1.2,545.44]],"batl":[[1,1.25,1997.82]],"ltp":1.22,"tv":16940.43,"id":2258415}]}]}
{"op":"mcm","clk":"1001518362","pt":1580637414963,"mc":[{"id":"1.168215937","rc":[{"trd":[[1.24,482.9]],"batb":[[0,1.22,332.41]],"batl":[[0,1.24,1769.8],[2,1.26,3044.5]],"ltp":1.24,"tv":16940.47,"id":2258415}],"tv":19057.18}]}
{"op":"mcm","clk":"1001518377","pt":1580637415171,"mc":[{"id":"1.168215937","rc":[{"batl":[[2,1.26,44.75]],"ltp":1.24,"tv":16940.47,"id":2258415}]}]}
{"op":"mcm","clk":"1001518563","pt":1580637417440,"mc":[{"id":"1.168215937","rc":[{"batb":[[0,1.22,403.23]],"ltp":1.24,"tv":16940.47,"id":2258415}]}]}
{"op":"mcm","clk":"1001519205","pt":1580637423758,"mc":[{"id":"1.168215937","rc":[{"trd":[[1.22,31.76],[1.23,0.03]],"batb":[[0,1.22,390.35]],"ltp":1.22,"tv":16966.22,"id":2258415}],"tv":19082.93}]}
{"op":"mcm","clk":"1001519627","pt":1580637429323,"mc":[{"id":"1.168215937","rc":[{"batb":[[0,1.22,390.33]],"ltp":1.22,"tv":16966.22,"id":2258415}]}]}
{"op":"mcm","clk":"1001519815","pt":1580637432365,"mc":[{"id":"1.168215937","rc":[{"trd":[[1.24,482.94]],"batl":[[0,1.24,1769.78]],"ltp":1.24,"tv":16966.26,"id":2258415}],"tv":19082.97}]}
{"op":"mcm","clk":"1001520280","pt":1580637439865,"mc":[{"id":"1.168215937","rc":[{"batb":[[0,5,10.08],[1,3,456.56],[2,2.6,75.72]],"batl":[[0,5.5,1.76],[1,5.8,2],[2,6,10.16]],"ltp":5.2,"tv":2116.7,"id":4423910},{"batb":[[0,1.22,70.81],[1,1.21,86.69],[2,1.2,168.14]],"batl":[[0,1.25,696.76],[1,1.49,756.18],[2,1.5,4.2]],"ltp":1.24,"tv":16966.26,"id":2258415}]}]}
{"op":"mcm","clk":"1001520365","pt":1580637441269,"mc":[{"id":"1.168215937","rc":[{"batb":[[0,3,456.56],[1,2.6,75.72],[2,2.2,75.72]],"batl":[[2,6,1.76]],"ltp":5.2,"tv":2116.7,"id":4423910},{"batb":[[2,1.18,29.51]],"batl":[[0,1.25,654.75]],"ltp":1.24,"tv":16966.26,"id":2258415}]}]}
{"op":"mcm","clk":"1001520439","pt":1580637442499,"mc":[{"id":"1.168215937","rc":[{"batb":[[0,5,3.72],[1,3,456.56],[2,2.6,75.72]],"ltp":5.2,"tv":2116.7,"id":4423910},{"batb":[[2,1.2,1039.98]],"batl":[[0,1.25,789.26],[1,1.26,578.99],[2,1.49,756.18]],"ltp":1.24,"tv":16966.26,"id":2258415}]}]}
{"op":"mcm","clk":"1001520515","pt":1580637443479,"mc":[{"id":"1.168215937","rc":[{"batb":[[2,1.18,29.51]],"ltp":1.24,"tv":16966.26,"id":2258415}]}]}
{"op":"mcm","clk":"1001520693","pt":1580637446487,"mc":[{"id":"1.168215937","rc":[{"batl":[[0,5.3,5.24],[1,5.5,1.76],[2,5.7,38.44]],"ltp":5.2,"tv":2116.7,"id":4423910},{"batb":[[0,1.22,819.99],[1,1.21,881.36],[2,1.2,766.9]],"batl":[[0,1.24,1181.39],[1,1.25,1968.76],[2,1.26,578.99]],"ltp":1.24,"tv":16966.26,"id":2258415}]}]}
{"op":"mcm","clk":"1001520830","pt":1580637448299,"mc":[{"id":"1.168215937","rc":[{"batb":[[1,4.9,10.08],[2,3,456.56]],"ltp":5.2,"tv":2116.7,"id":4423910},{"batb":[[2,1.2,934.94]],"batl":[[2,1.26,621]],"ltp":1.24,"tv":16966.26,"id":2258415}]}]}
{"op":"mcm","clk":"1001521299","pt":1580637453809,"mc":[{"id":"1.168215937","rc":[{"batl":[[1,5.4,2],[2,5.5,1.76]],"ltp":5.2,"tv":2116.7,"id":4423910},{"batb":[[0,1.23,75.63],[1,1.22,903.83],[2,1.21,881.36]],"ltp":1.24,"tv":16966.26,"id":2258415}]}]}
{"op":"mcm","clk":"1001521611","pt":1580637458532,"mc":[{"id":"1.168215937","rc":[{"batb":[[0,4.9,10.08],[1,3,456.56],[2,2.6,75.72]],"batl":[[0,5.5,1.76],[1,5.6,2],[2,5.8,2]],"ltp":5.2,"tv":2116.7,"id":4423910},{"batb":[[0,1.22,154.65],[1,1.21,881.36],[2,1.2,168.14]],"batl":[[0,1.25,368.04],[1,1.26,621],[2,1.49,756.18]],"ltp":1.24,"tv":16966.26,"id":2258415}]}]}
{"op":"mcm","clk":"1001521666","pt":1580637459311,"mc":[{"id":"1.168215937","rc":[{"batb":[[0,3,456.56],[1,2.6,75.72],[2,2.2,75.72]],"ltp":5.2,"tv":2116.7,"id":4423910},{"batb":[[2,1.18,29.51]],"batl":[[1,1.26,578.99]],"ltp":1.24,"tv":16966.26,"id":2258415}]}]}
{"op":"mcm","clk":"1001521870","pt":1580637461836,"mc":[{"id":"1.168215937","rc":[{"batb":[[0,5,3.79],[1,3,456.56],[2,2.6,75.72]],"batl":[[2,6,1.76]],"ltp":5.2,"tv":2116.7,"id":4423910},{"batb":[[1,1.18,29.51],[2,1.15,29.41]],"ltp":1.24,"tv":16966.26,"id":2258415}]}]}
{"op":"mcm","clk":"1001522015","pt":1580637463902,"mc":[{"id":"1.168215937","rc":[{"trd":[[5.1,400.94]],"batl":[[0,5.1,3.5],[1,5.5,1.76],[2,5.6,2]],"ltp":5.1,"tv":2517.64,"id":4423910},{"batb":[[0,1.23,467.87],[1,1.22,898.79],[2,1.21,168.13]],"batl":[[1,1.26,1773.29]],"ltp":1.24,"tv":16966.26,"id":2258415}],"tv":19483.91}]}
{"op":"mcm","clk":"1001522078","pt":1580637464829,"mc":[{"id":"1.168215937","rc":[{"batb":[[1,4.8,10.92],[2,3,380.84]],"ltp":5.1,"tv":2517.64,"id":4423910},{"batl":[[1,1.26,1815.3]],"ltp":1.24,"tv":16966.26,"id":2258415}]}]}
{"op":"mcm","clk":"1001522423","pt":1580637470614,"mc":[{"id":"1.168215937","rc":[{"batb":[[1,4.8,14.9]],"batl":[[1,5.4,2],[2,5.5,1.76]],"ltp":5.1,"tv":2517.64,"id":4423910},{"batb":[[0,1.23,540.5]],"batl":[[1,1.26,1890.55]],"ltp":1.24,"tv":16966.26,"id":2258415}]}]}
{"op":"mcm","clk":"1001522611","pt":1580637473949,"mc":[{"id":"1.168215937","rc":[{"batl":[[0,5.4,2],[1,5.5,1.76],[2,5.6,2]],"ltp":5.1,"tv":2517.64,"id":4423910},{"batl":[[1,1.26,696.25]],"ltp":1.24,"tv":16966.26,"id":2258415}]}]}
{"op":"mcm","clk":"1001522658","pt":1580637474418,"mc":[{"id":"1.168215937","rc":[{"batb":[[0,4.8,14.9],[1,3,380.84],[2,2.6,75.72]],"batl":[[0,5.5,1.76],[1,5.6,2],[2,5.8,8.4]],"ltp":5.1,"tv":2517.64,"id":4423910},{"batb":[[0,1.22,664.45],[1,1.18,29.51],[2,1.15,29.41]],"batl":[[0,1.26,646.9],[1,1.49,756.18],[2,1.5,4.2]],"ltp":1.24,"tv":16966.26,"id":2258415}]}]}
{"op":"mcm","clk":"1001522742","pt":1580637475755,"mc":[{"id":"1.168215937","rc":[{"batb":[[0,4.8,3.98]],"batl":[[2,6,1.76]],"ltp":5.1,"tv":2517.64,"id":4423910},{"batl":[[0,1.24,14.46],[1,1.26,604.89],[2,1.49,756.18]],"ltp":1.24,"tv":16966.26,"id":2258415}]}]}
{"op":"mcm","clk":"1001522882","pt":1580637477925,"mc":[{"id":"1.168215937","rc":[{"batb":[[1,3,456.56]],"ltp":5.1,"tv":2517.64,"id":4423910},{"batb":[[1,1.21,787.66],[2,1.18,29.51]],"batl":[[2,1.27,558.17]],"ltp":1.24,"tv":16966.26,"id":2258415}]}]}
{"op":"mcm","clk":"1001522888","pt":1580637478026,"mc":[{"id":"1.168215937","rc":[{"batb":[[1,1.18,29.51],[2,1.15,29.41]],"batl":[[2,1.49,756.18]],"ltp":1.24,"tv":16966.26,"id":2258415}]}]}
{"op":"mcm","clk":"1001523055","pt":1580637480933,"mc":[{"id":"1.168215937","rc":[{"trd":[[5.1,401.84]],"batb":[[0,5,3.94],[1,4.8,3.98],[2,3,380.84]],"ltp":5.1,"tv":2518.54,"id":4423910},{"trd":[[1.24,508.17]],"batl":[[0,1.26,604.89],[1,1.49,756.18],[2,1.5,4.2]],"ltp":1.24,"tv":16991.49,"id":2258415}],"tv":19510.04}]}
{"op":"mcm","clk":"1001523074","pt":1580637481345,"mc":[{"id":"1.168215937","rc":[{"batb":[[0,4.8,3.98],[1,3,380.84],[2,2.6,75.72]],"ltp":5.1,"tv":2518.54,"id":4423910}]}]}
{"op":"mcm","clk":"1001523235","pt":1580637483835,"mc":[{"id":"1.168215937","rc":[{"batl":[[0,1.25,81.86],[1,1.26,604.89],[2,1.49,756.18]],"ltp":1.24,"tv":16991.49,"id":2258415}]}]}
{"op":"mcm","clk":"1001523295","pt":1580637484754,"mc":[{"id":"1.168215937","rc":[{"batl":[[0,1.26,604.89],[1,1.49,756.18],[2,1.5,4.2]],"ltp":1.24,"tv":16991.49,"id":2258415}]}]}
{"op":"mcm","clk":"1001523385","pt":1580637486552,"mc":[{"id":"1.168215937","rc":[{"batb":[[1,1.21,787.66],[2,1.18,29.51]],"batl":[[0,1.26,75.25]],"ltp":1.24,"tv":16991.49,"id":2258415}]}]}
{"op":"mcm","clk":"1001523465","pt":1580637487845,"mc":[{"id":"1.168215937","rc":[{"batb":[[0,5,3.94],[1,4.8,3.98],[2,3,456.56]],"batl":[[0,5.4,2],[1,5.5,1.76],[2,5.6,2]],"ltp":5.1,"tv":2518.54,"id":4423910},{"batb":[[0,1.23,70.63],[1,1.22,664.45],[2,1.21,787.66]],"batl":[[0,1.25,58.66],[1,1.26,75.25],[2,1.49,756.18]],"ltp":1.24,"tv":16991.49,"id":2258415}]}]}
{"op":"mcm","clk":"1001523519","pt":1580637488870,"mc":[{"id":"1.168215937","rc":[{"batb":[[0,1.23,84.36],[2,1.21,1586.52]],"batl":[[0,1.24,798.04],[1,1.25,1628.66],[2,1.26,247.51]],"ltp":1.24,"tv":16991.49,"id":2258415}]}]}
{"op":"mcm","clk":"1001523538","pt":1580637489233,"mc":[{"id":"1.168215937","rc":[{"batl":[[0,5.5,1.76],[1,5.6,2],[2,6,230.76]],"ltp":5.1,"tv":2518.54,"id":4423910},{"batb":[[0,1.23,13.73]],"batl":[[0,1.24,1145.12],[1,1.25,2245.25]],"ltp":1.24,"tv":16991.49,"id":2258415}]}]}
{"op":"mcm","clk":"1001523599","pt":1580637490376,"mc":[{"id":"1.168215937","rc":[{"batb":[[0,5,14.02]],"batl":[[2,6,239.16]],"ltp":5.1,"tv":2518.54,"id":4423910},{"batl":[[1,1.25,2287.26]],"ltp":1.24,"tv":16991.49,"id":2258415}]}]}
{"op":"mcm","clk":"1001523881","pt":1580637495561,"mc":[{"id":"1.168215937","rc":[{"batl":[[0,5.4,2],[1,5.5,1.76],[2,5.6,2]],"ltp":5.1,"tv":2518.54,"id":4423910},{"batb":[[0,1.23,83.36]],"ltp":1.24,"tv":16991.49,"id":2258415}]}]}
{"op":"mcm","clk":"1001524387","pt":1580637505853,"mc":[{"id":"1.168215937","rc":[{"batl":[[0,5.5,1.76],[1,5.6,2],[2,6,10.16]],"ltp":5.1,"tv":2518.54,"id":4423910},{"batb":[[0,1.22,664.45],[1,1.21,787.66],[2,1.2,168.14]],"batl":[[0,1.24,347.08],[1,1.25,717.26]],"ltp":1.24,"tv":16991.49,"id":2258415}]}]}
{"op":"mcm","clk":"1001524400","pt":1580637506062,"mc":[{"id":"1.168215937","rc":[{"batb":[[0,1.22,154.65],[1,1.21,495.16]],"batl":[[0,1.25,631.5],[1,1.26,75.25],[2,1.49,756.18]],"ltp":1.24,"tv":16991.49,"id":2258415}]}]}
{"op":"mcm","clk":"1001524473","pt":1580637507289,"mc":[{"id":"1.168215937","rc":[{"batb":[[0,5,3.94]],"batl":[[2,6,1.76]],"ltp":5.1,"tv":2518.54,"id":4423910},{"batb":[[2,1.18,29.51]],"batl":[[0,1.25,589.49]],"ltp":1.24,"tv":16991.49,"id":2258415}]}]}
{"op":"mcm","clk":"1001524585","pt":1580637509300,"mc":[{"id":"1.168215937","rc":[{"batb":[[2,1.2,834.17]],"batl":[[1,1.26,659.54]],"ltp":1.24,"tv":16991.49,"id":2258415}]}]}
{"op":"mcm","clk":"1001524909","pt":1580637514774,"mc":[{"id":"1.168215937","rc":[{"batb":[[1,1.18,29.51],[2,1.15,29.41]],"ltp":1.24,"tv":16991.49,"id":2258415}]}]}
{"op":"mcm","clk":"1001524979","pt":1580637515903,"mc":[{"id":"1.168215937","rc":[{"batl":[[0,5.4,2],[1,5.5,1.76],[2,5.6,2]],"ltp":5.1,"tv":2518.54,"id":4423910},{"batb":[[0,1.23,78.63],[1,1.22,154.65],[2,1.18,29.51]],"ltp":1.24,"tv":16991.49,"id":2258415}]}]}
{"op":"mcm","clk":"1001525034","pt":1580637516777,"mc":[{"id":"1.168215937","rc":[{"batl":[[0,5.5,1.76],[1,5.6,2],[2,6,1.76]],"ltp":5.1,"tv":2518.54,"id":4423910},{"batb":[[0,1.22,154.65],[1,1.18,29.51],[2,1.15,29.41]],"ltp":1.24,"tv":16991.49,"id":2258415}]}]}
{"op":"mcm","clk":"1001525107","pt":1580637517762,"mc":[{"id":"1.168215937","rc":[{"batb":[[0,5,117.68]],"batl":[[0,5.3,6.94],[1,5.5,1.76],[2,5.6,2]],"ltp":5.1,"tv":2518.54,"id":4423910},{"batb":[[0,1.23,247.1],[1,1.22,1051.89],[2,1.21,167.4]],"batl":[[0,1.25,1052.48],[1,1.26,2218.54]],"ltp":1.24,"tv":16991.49,"id":2258415}]}]}
{"op":"mcm","clk":"1001525138","pt":1580637518277,"mc":[{"id":"1.168215937","rc":[{"batb":[[1,4.9,10.08],[2,4.8,3.98]],"ltp":5.1,"tv":2518.54,"id":4423910},{"batl":[[1,1.26,2260.55]],"ltp":1.24,"tv":16991.49,"id":2258415}]}]}
{"op":"mcm","clk":"1001525424","pt":1580637523478,"mc":[{"id":"1.168215937","rc":[{"batb":[[1,1.22,981.08]],"ltp":1.24,"tv":16991.49,"id":2258415}]}]}
{"op":"mcm","clk":"1001525485","pt":1580637524508,"mc":[{"id":"1.168215937","rc":[{"trd":[[5.3,13.88],[5.4,26.67]],"batl":[[0,5.4,2]],"ltp":5.4,"tv":2559.09,"id":4423910},{"trd":[[1.23,117.11]],"batb":[[0,1.23,75.63]],"ltp":1.23,"tv":17108.57,"id":2258415}],"tv":19667.67}]}
{"op":"mcm","clk":"1001525640","pt":1580637526620,"mc":[{"id":"1.168215937","rc":[{"trd":[[5.3,32.36]],"batb":[[0,5.3,50.41],[1,5,117.68],[2,4.9,10.08]],"ltp":5.3,"tv":2577.58,"id":4423910},{"trd":[[1.24,587.19]],"ltp":1.24,"tv":17187.59,"id":2258415}],"tv":19765.18}]}
{"op":"mcm","clk":"1001525682","pt":1580637527394,"mc":[{"id":"1.168215937","rc":[{"batb":[[1,1.22,1165.12],[2,1.21,832.53]],"batl":[[0,1.25,1116.16]],"ltp":1.24,"tv":17187.59,"id":2258415}]}]}
{"op":"mcm","clk":"1001525744","pt":1580637528322,"mc":[{"id":"1.168215937","rc":[{"batb":[[1,5.2,34.87],[2,5,117.68]],"ltp":5.3,"tv":2577.58,"id":4423910}]}]}
{"op":"mcm","clk":"1001525825","pt":1580637530117,"mc":[{"id":"1.168215937","rc":[{"batb":[[2,5.1,3.74]],"ltp":5.3,"tv":2577.58,"id":4423910},{"batb":[[2,1.21,915.22]],"batl":[[0,1.24,66.98],[1,1.25,1116.16],[2,1.26,2260.55]],"ltp":1.24,"tv":17187.59,"id":2258415}]}]}
{"op":"mcm","clk":"1001525957","pt":1580637532813,"mc":[{"id":"1.168215937","rc":[{"batl":[[0,5.5,1.76],[1,5.8,2],[2,5.9,8.4]],"ltp":5.3,"tv":2577.58,"id":4423910},{"batb":[[0,1.21,747.82],[1,1.2,168.14],[2,1.18,29.41]],"batl":[[1,1.25,58.66],[2,1.26,701.55]],"ltp":1.24,"tv":17187.59,"id":2258415}]}]}
{"op":"mcm","clk":"1001525996","pt":1580637533429,"mc":[{"id":"1.168215937","rc":[{"batb":[[1,5.1,3.74],[2,5,3.94]],"batl":[[2,6,1.76]],"ltp":5.3,"tv":2577.58,"id":4423910},{"batb":[[1,1.18,29.51],[2,1.15,29.41]],"batl":[[2,1.26,659.54]],"ltp":1.24,"tv":17187.59,"id":2258415}]}]}
{"op":"mcm","clk":"1001526042","pt":1580637534301,"mc":[{"id":"1.168215937","rc":[{"trd":[[5.3,32.97]],"batb":[[0,5.3,50.11]],"ltp":5.3,"tv":2578.18,"id":4423910}],"tv":19765.78}]}
{"op":"mcm","clk":"1001526122","pt":1580637535484,"mc":[{"id":"1.168215937","rc":[{"batb":[[0,5,3.94],[1,4.8,3.98],[2,3,456.56]],"ltp":5.3,"tv":2578.18,"id":4423910},{"batb":[[0,1.21,1102.52],[1,1.2,580.21],[2,1.18,29.41]],"batl":[[0,1.25,58.66],[1,1.26,874.67],[2,1.27,553.93]],"ltp":1.24,"tv":17187.59,"id":2258415}]}]}
{"op":"mcm","clk":"1001526183","pt":1580637536407,"mc":[{"id":"1.168215937","rc":[{"batb":[[0,5.4,34.87],[1,5,3.94],[2,4.8,3.98]],"ltp":5.3,"tv":2578.18,"id":4423910},{"batb":[[0,1.21,880.64],[1,1.18,29.51],[2,1.15,29.41]],"batl":[[1,1.26,659.54],[2,1.49,756.18]],"ltp":1.24,"tv":17187.59,"id":2258415}]}]}
{"op":"mcm","clk":"1001526317","pt":1580637538932,"mc":[{"id":"1.168215937","rc":[{"trd":[[5.5,3.51],[5.6,23.76]],"batb":[[0,5.6,35.19],[1,5.4,34.87],[2,5.1,3.74]],"batl":[[0,5.8,2],[1,6,1.76],[2,9.8,75.27]],"ltp":5.6,"tv":2605.45,"id":4423910},{"trd":[[1.22,43.6]],"batl":[[0,1.24,76.98],[1,1.25,58.66],[2,1.26,659.54]],"ltp":1.22,"tv":17199.43,"id":2258415}],"tv":19804.89}]}
{"op":"mcm","clk":"1001526365","pt":1580637539609,"mc":[{"id":"1.168215937","rc":[{"trd":[[5.6,47.43]],"batb":[[0,5.6,13.51]],"ltp":5.6,"tv":2629.13,"id":4423910},{"trd":[[1.22,133.94]],"ltp":1.22,"tv":17289.77,"id":2258415}],"tv":19918.91}]}
{"op":"mcm","clk":"1001526431","pt":1580637540645,"mc":[{"id":"1.168215937","rc":[{"trd":[[5.6,60.94]],"batb":[[0,5.4,34.87],[1,5.1,3.74],[2,5,3.94]],"ltp":5.6,"tv":2642.64,"id":4423910},{"trd":[[1.22,195.95]],"batl":[[1,1.25,299.82]],"ltp":1.22,"tv":17351.78,"id":2258415}],"tv":19994.43}]}
{"op":"mcm","clk":"1001526516","pt":1580637541625,"mc":[{"id":"1.168215937","rc":[{"batl":[[0,1.23,2.34],[1,1.24,76.98],[2,1.25,299.82]],"ltp":1.22,"tv":17351.78,"id":2258415}]}]}
{"op":"mcm","clk":"1001526710","pt":1580637544312,"mc":[{"id":"1.168215937","rc":[{"batb":[[0,1.21,1067.94],[1,1.2,615.07],[2,1.18,29.41]],"ltp":1.22,"tv":17351.78,"id":2258415}]}]}
{"op":"mcm","clk":"1001526865","pt":1580637547039,"mc":[{"id":"1.168215937","rc":[{"batl":[[0,1.24,76.98],[1,1.25,299.82],[2,1.26,659.54]],"ltp":1.22,"tv":17351.78,"id":2258415}]}]}
{"op":"mcm","clk":"1001526935","pt":1580637548636,"mc":[{"id":"1.168215937","rc":[{"batl":[[2,1.26,75.25]],"ltp":1.22,"tv":17351.78,"id":2258415}]}]}
{"op":"mcm","clk":"1001526995","pt":1580637549521,"mc":[{"id":"1.168215937","rc":[{"batb":[[0,5,3.94],[1,4.8,3.98],[2,3,456.56]],"ltp":5.6,"tv":2642.64,"id":4423910},{"batl":[[0,1.25,299.82],[1,1.26,75.25],[2,1.49,756.18]],"ltp":1.22,"tv":17351.78,"id":2258415}]}]}
{"op":"mcm","clk":"1001527032","pt":1580637550140,"mc":[{"id":"1.168215937","rc":[{"trd":[[1.21,4.68]],"batb":[[0,1.21,1065.6]],"ltp":1.21,"tv":17356.46,"id":2258415}],"tv":19999.11}]}
{"op":"mcm","clk":"1001527111","pt":1580637551531,"mc":[{"id":"1.168215937","rc":[{"batb":[[0,5,47.78],[1,4.9,38.7],[2,4.8,3.98]],"batl":[[0,5.7,4.18],[1,5.8,2],[2,6,133.65]],"ltp":5.6,"tv":2642.64,"id":4423910},{"batb":[[1,1.2,1274.54]],"batl":[[0,1.23,31.3],[1,1.24,3071.71],[2,1.25,670.73]],"ltp":1.21,"tv":17356.46,"id":2258415}]}]}
{"op":"mcm","clk":"1001527171","pt":1580637552508,"mc":[{"id":"1.168215937","rc":[{"batb":[[0,5.2,34.87],[1,5,57.86],[2,4.9,38.7]],"ltp":5.6,"tv":2642.64,"id":4423910},{"batb":[[2,1.19,168.04]],"batl":[[2,1.25,712.74]],"ltp":1.21,"tv":17356.46,"id":2258415}]}]}
{"op":"mcm","clk":"1001527424","pt":1580637556940,"mc":[{"id":"1.168215937","rc":[{"trd":[[5.7,8.36],[5.8,4.82]],"batl":[[0,6,133.65],[1,6.2,301.56],[2,11.5,70.11]],"ltp":5.8,"tv":2655.82,"id":4423910},{"trd":[[1.21,8.61],[1.22,195.96],[1.23,117.19]],"batb":[[0,1.21,1061.67]],"batl":[[0,1.23,31.26]],"ltp":1.21,"tv":17360.48,"id":2258415}],"tv":20016.31}]}
{"op":"mcm","clk":"1001527505","pt":1580637558341,"mc":[{"id":"1.168215937","rc":[{"batb":[[1,5.1,8.04],[2,5,57.86]],"batl":[[0,6,135.65]],"ltp":5.8,"tv":2655.82,"id":4423910},{"batb":[[1,1.2,1362.56]],"batl":[[1,1.24,3172.19]],"ltp":1.21,"tv":17360.48,"id":2258415}]}]}
{"op":"mcm","clk":"1001527596","pt":1580637560045,"mc":[{"id":"1.168215937","rc":[{"batl":[[0,5.8,2],[1,6,135.65],[2,6.2,301.56]],"ltp":5.8,"tv":2655.82,"id":4423910}]}]}
{"op":"mcm","clk":"1001527892","pt":1580637564852,"mc":[{"id":"1.168215937","rc":[{"batl":[[1,6,3.76],[2,6.2,7.56]],"ltp":5.8,"tv":2655.82,"id":4423910},{"batb":[[0,1.21,82.69],[1,1.2,703.09]],"batl":[[0,1.24,100.48],[1,1.25,712.74],[2,1.26,75.25]],"ltp":1.21,"tv":17360.48,"id":2258415}]}]}
{"op":"mcm","clk":"1001527926","pt":1580637565474,"mc":[{"id":"1.168215937","rc":[{"batb":[[1,5,3.94],[2,4.8,3.98]],"batl":[[0,6,3.76],[1,11.5,70.11],[2,1000,0.02]],"ltp":5.8,"tv":2655.82,"id":4423910},{"batb":[[0,1.2,703.09],[1,1.18,29.41],[2,1.15,29.41]],"batl":[[0,1.25,670.73],[1,1.26,75.25],[2,1.49,756.18]],"ltp":1.21,"tv":17360.48,"id":2258415}]}]}
{"op":"mcm","clk":"1001528120","pt":1580637567876,"mc":[{"id":"1.168215937","rc":[{"batb":[[0,1.2,1119.94],[1,1.19,581.46],[2,1.18,29.41]],"batl":[[0,1.25,877.64],[1,1.26,655.28]],"ltp":1.21,"tv":17360.48,"id":2258415}]}]}
{"op":"mcm","clk":"1001528180","pt":1580637568565,"mc":[{"id":"1.168215937","rc":[{"batb":[[0,1.2,863.8],[1,1.18,29.41],[2,1.15,29.41]],"batl":[[0,1.25,670.73],[1,1.26,75.25]],"ltp":1.21,"tv":17360.48,"id":2258415}]}]}
{"op":"mcm","clk":"1001528370","pt":1580637570873,"mc":[{"id":"1.168215937","rc":[{"batb":[[0,1.21,825.87],[1,1.2,863.8],[2,1.18,29.41]],"batl":[[0,1.24,783.13],[1,1.25,670.73],[2,1.26,75.25]],"ltp":1.21,"tv":17360.48,"id":2258415}]}]}
{"op":"mcm","clk":"1001528467","pt":1580637571754,"mc":[{"id":"1.168215937","rc":[{"batb":[[1,5.1,8.54],[2,5,3.94]],"batl":[[0,5.8,2],[1,6,3.76],[2,11.5,70.11]],"ltp":5.8,"tv":2655.82,"id":4423910},{"batb":[[0,1.21,909.56]],"batl":[[0,1.24,888.86]],"ltp":1.21,"tv":17360.48,"id":2258415}]}]}
{"op":"mcm","clk":"1001528570","pt":1580637573357,"mc":[{"id":"1.168215937","rc":[{"batb":[[1,5,3.94],[2,4.8,3.98]],"batl":[[0,6,3.76],[1,11.5,70.11],[2,1000,0.02]],"ltp":5.8,"tv":2655.82,"id":4423910},{"batb":[[0,1.2,863.8],[1,1.18,29.41],[2,1.15,29.41]],"batl":[[0,1.25,670.73],[1,1.26,75.25],[2,1.49,756.18]],"ltp":1.21,"tv":17360.48,"id":2258415}]}]}
{"op":"mcm","clk":"1001528768","pt":1580637575058,"mc":[{"id":"1.168215937","rc":[{"batl":[[0,1.25,58.66]],"ltp":1.21,"tv":17360.48,"id":2258415}]}]}
{"op":"mcm","clk":"1001528868","pt":1580637576761,"mc":[{"id":"1.168215937","rc":[{"batb":[[1,5.1,8.54],[2,5,3.94]],"batl":[[1,1000,0.02],[2,1000,0]],"ltp":5.8,"tv":2655.82,"id":4423910},{"batb":[[0,1.2,1119.94],[1,1.19,581.46],[2,1.18,29.41]],"batl":[[0,1.24,105.73],[1,1.25,58.66],[2,1.26,75.25]],"ltp":1.21,"tv":17360.48,"id":2258415}]}]}
{"op":"mcm","clk":"1001528945","pt":1580637577949,"mc":[{"id":"1.168215937","rc":[{"batb":[[0,5.4,37.02],[1,5.3,4.88],[2,5.2,34.87]],"batl":[[1,6.2,168.56],[2,6.6,304]],"ltp":5.8,"tv":2655.82,"id":4423910},{"batl":[[0,1.21,32.4],[1,1.22,750.64],[2,1.23,2326.23]],"ltp":1.21,"tv":17360.48,"id":2258415}]}]}
{"op":"mcm","clk":"1001529004","pt":1580637578775,"mc":[{"id":"1.168215937","rc":[{"batb":[[2,5.2,44.11]],"batl":[[1,6.2,176.12]],"ltp":5.8,"tv":2655.82,"id":4423910},{"batb":[[1,1.19,749.5]],"ltp":1.21,"tv":17360.48,"id":2258415}]}]}
{"op":"mcm","clk":"1001529024","pt":1580637579087,"mc":[{"id":"1.168215937","rc":[{"batb":[[1,5.2,44.11],[2,5.1,8.54]],"ltp":5.8,"tv":2655.82,"id":4423910}]}]}
{"op":"mcm","clk":"1001529421","pt":1580637584589,"mc":[{"id":"1.168215937","rc":[{"batl":[[2,6.4,2]],"ltp":5.8,"tv":2655.82,"id":4423910},{"batb":[[1,1.19,836.21]],"ltp":1.21,"tv":17360.48,"id":2258415}]}]}
{"op":"mcm","clk":"1001530456","pt":1580637599711,"mc":[{"id":"1.168215937","rc":[{"batl":[[2,1.23,707.23]],"ltp":1.21,"tv":17360.48,"id":2258415}]}]}
{"op":"mcm","clk":"1001530533","pt":1580637600812,"mc":[{"id":"1.168215937","rc":[{"batl":[[1,6.2,7.56]],"ltp":5.8,"tv":2655.82,"id":4423910},{"batb":[[0,1.2,88.12]],"batl":[[0,1.24,948.01],[1,1.25,58.66],[2,1.26,75.25]],"ltp":1.21,"tv":17360.48,"id":2258415}]}]}
{"op":"mcm","clk":"1001530619","pt":1580637601571,"mc":[{"id":"1.168215937","rc":[{"batb":[[0,5.2,34.87],[1,5.1,8.54],[2,5,3.94]],"batl":[[0,6,1.76],[1,6.4,2],[2,12.5,65.97]],"ltp":5.8,"tv":2655.82,"id":4423910},{"batb":[[0,1.19,668.27],[1,1.18,29.41],[2,1.15,29.41]],"batl":[[0,1.24,746.41]],"ltp":1.21,"tv":17360.48,"id":2258415}]}]}
{"op":"mcm","clk":"1001530871","pt":1580637603826,"mc":[{"id":"1.168215937","rc":[{"batb":[[0,1.19,1012.5],[1,1.18,731.56]],"batl":[[0,1.24,901.76],[1,1.25,666.95]],"ltp":1.21,"tv":17360.48,"id":2258415}]}]}
{"op":"mcm","clk":"1001530957","pt":1580637604623,"mc":[{"id":"1.168215937","rc":[{"batb":[[0,1.19,866.14],[1,1.18,29.41]],"batl":[[0,1.24,746.41],[1,1.25,58.66]],"ltp":1.21,"tv":17360.48,"id":2258415}]}]}
{"op":"mcm","clk":"1001531239","pt":1580637607811,"mc":[{"id":"1.168215937","rc":[{"batb":[[0,1.2,835.7],[1,1.19,866.04],[2,1.18,29.41]],"batl":[[0,1.23,882.05],[1,1.24,746.41],[2,1.25,58.66]],"ltp":1.21,"tv":17360.48,"id":2258415}]}]}
{"op":"mcm","clk":"1001531399","pt":1580637609829,"mc":[{"id":"1.168215937","rc":[{"batb":[[0,1.19,866.14],[1,1.18,29.41],[2,1.15,29.41]],"batl":[[0,1.24,746.41],[1,1.25,58.66],[2,1.26,75.25]],"ltp":1.21,"tv":17360.48,"id":2258415}]}]}
{"op":"mcm","clk":"1001531614","pt":1580637612587,"mc":[{"id":"1.168215937","rc":[{"batb":[[0,1.19,1012.5],[1,1.18,731.56]],"batl":[[0,1.24,901.76],[1,1.25,666.95]],"ltp":1.21,"tv":17360.48,"id":2258415}]}]}
{"op":"mcm","clk":"1001531977","pt":1580637617910,"mc":[{"id":"1.168215937","rc":[{"batb":[[0,1.19,86.81],[1,1.18,29.41]],"ltp":1.21,"tv":17360.48,"id":2258415}]}]}
{"op":"mcm","clk":"1001532105","pt":1580637619811,"mc":[{"id":"1.168215937","rc":[{"batl":[[2,1000,0.02]],"ltp":5.8,"tv":2655.82,"id":4423910},{"trd":[[1.24,587.23]],"batl":[[0,1.24,901.74]],"ltp":1.24,"tv":17360.52,"id":2258415}],"tv":20016.34}]}
{"op":"mcm","clk":"1001532175","pt":1580637620944,"mc":[{"id":"1.168215937","rc":[{"batl":[[0,5.7,33.37],[1,6,94.79],[2,6.2,207]],"ltp":5.8,"tv":2655.82,"id":4423910},{"batb":[[0,1.21,811.6],[1,1.2,1228.41],[2,1.19,86.71]],"batl":[[0,1.23,896.43],[1,1.24,2490.74],[2,1.25,666.95]],"ltp":1.24,"tv":17360.52,"id":2258415}]}]}
{"op":"mcm","clk":"1001532289","pt":1580637622444,"mc":[{"id":"1.168215937","rc":[{"batb":[[1,5.1,18.62]],"batl":[[2,6.2,214.56]],"ltp":5.8,"tv":2655.82,"id":4423910},{"batb":[[2,1.19,254.75]],"batl":[[2,1.25,708.96]],"ltp":1.24,"tv":17360.52,"id":2258415}]}]}
{"op":"mcm","clk":"1001532485","pt":1580637624839,"mc":[{"id":"1.168215937","rc":[{"batl":[[0,1.23,913.23]],"ltp":1.24,"tv":17360.52,"id":2258415}]}]}
{"op":"mcm","clk":"1001532723","pt":1580637627646,"mc":[{"id":"1.168215937","rc":[{"batl":[[1,6,96.79]],"ltp":5.8,"tv":2655.82,"id":4423910},{"batb":[[1,1.2,1314.58]],"ltp":1.24,"tv":17360.52,"id":2258415}]}]}
{"op":"mcm","clk":"1001533106","pt":1580637632819,"mc":[{"id":"1.168215937","rc":[{"trd":[[1.23,117.26]],"batb":[[0,1.21,811.62]],"batl":[[0,1.23,913.19]],"ltp":1.23,"tv":17360.59,"id":2258415}],"tv":20016.42}]}
{"op":"mcm","clk":"1001533128","pt":1580637633130,"mc":[{"id":"1.168215937","rc":[{"trd":[[5.7,75.1]],"batb":[[0,5.7,1.5],[1,5.2,34.87],[2,5.1,18.62]],"batl":[[0,6,96.79],[1,6.2,214.56],[2,6.4,2]],"ltp":5.7,"tv":2722.56,"id":4423910},{"trd":[[1.22,195.98]],"batb":[[0,1.21,811.6]],"ltp":1.22,"tv":17360.61,"id":2258415}],"tv":20083.18}]}
{"op":"mcm","clk":"1001533372","pt":1580637635861,"mc":[{"id":"1.168215937","rc":[{"batl":[[0,6,3.76],[1,6.2,7.56]],"ltp":5.7,"tv":2722.56,"id":4423910},{"batb":[[0,1.2,876.34],[1,1.19,254.75],[2,1.18,29.41]],"batl":[[0,1.23,16.8],[1,1.24,456.27]],"ltp":1.22,"tv":17360.61,"id":2258415}]}]}
{"op":"mcm","clk":"1001533402","pt":1580637636231,"mc":[{"id":"1.168215937","rc":[{"trd":[[5.7,78.1]],"batb":[[0,5.2,34.87],[1,5.1,18.62],[2,5,3.94]],"ltp":5.7,"tv":2725.56,"id":4423910}],"tv":20086.17}]}
{"op":"mcm","clk":"1001533491","pt":1580637637420,"mc":[{"id":"1.168215937","rc":[{"batb":[[1,5.1,8.54]],"batl":[[1,6.4,2],[2,11.5,70.11]],"ltp":5.7,"tv":2725.56,"id":4423910},{"batb":[[1,1.19,86.71]],"batl":[[2,1.25,666.95]],"ltp":1.22,"tv":17360.61,"id":2258415}]}]}
{"op":"mcm","clk":"1001533573","pt":1580637638460,"mc":[{"id":"1.168215937","rc":[{"batb":[[0,1.2,946.87],[1,1.19,840.83]],"ltp":1.22,"tv":17360.61,"id":2258415}]}]}
