{"op":"mcm","clk":"997862772","pt":1580583479664,"mc":[{"id":"1.168224030","marketDefinition":{"bspMarket":false,"turnInPlayEnabled":true,"persistenceEnabled":true,"marketBaseRate":5.0,"eventId":"29681672","eventTypeId":"2","numberOfWinners":1,"bettingType":"ODDS","marketType":"SET_WINNER","marketTime":"2020-02-02T13:00:00.000Z","suspendTime":"2020-02-02T13:00:00.000Z","bspReconciled":false,"complete":true,"inPlay":false,"crossMatching":false,"runnersVoidable":false,"numberOfActiveRunners":2,"betDelay":0,"status":"OPEN","runners":[{"status":"ACTIVE","sortPriority":1,"id":8908205,"name":"Juan Pablo Ficovich"},{"status":"ACTIVE","sortPriority":2,"id":4596961,"name":"Filip Horansky"}],"regulators":["MR_INT"],"countryCode":"AR","discountAllowed":false,"timezone":"UTC","openDate":"2020-02-02T13:00:00.000Z","version":3146950742,"name":"Set 2 Winner","eventName":"Ficovich v Horansky"},"rc":[{"batb":[[0,1.01,20]],"ltp":0.0,"tv":0.0,"id":8908205},{"batb":[[0,1.01,20]],"ltp":0.0,"tv":0.0,"id":4596961}]}]}
{"op":"mcm","clk":"997863080","pt":1580583482122,"mc":[{"id":"1.168224030","marketDefinition":{"bspMarket":false,"turnInPlayEnabled":true,"persistenceEnabled":true,"marketBaseRate":5.0,"eventId":"29681672","eventTypeId":"2","numberOfWinners":1,"bettingType":"ODDS","marketType":"SET_WINNER","marketTime":"2020-02-02T13:00:00.000Z","suspendTime":"2020-02-02T13:00:00.000Z","bspReconciled":false,"complete":true,"inPlay":false,"crossMatching":false,"runnersVoidable":false,"numberOfActiveRunners":2,"betDelay":0,"status":"OPEN","runners":[{"status":"ACTIVE","sortPriority":1,"id":8908205,"name":"Juan Pablo Ficovich"},{"status":"ACTIVE","sortPriority":2,"id":4596961,"name":"Filip Horansky"}],"regulators":["MR_INT"],"countryCode":"AR","discountAllowed":true,"timezone":"UTC","openDate":"2020-02-02T13:00:00.000Z","version":3146950742,"name":"Set 2 Winner","eventName":"Ficovich v Horansky"}}]}
{"op":"mcm","clk":"997881409","pt":1580583623459,"mc":[{"id":"1.168224030","rc":[{"batb":[[0,1.01,10]],"ltp":0.0,"tv":0.0,"id":8908205},{"batb":[[0,1.01,10]],"ltp":0.0,"tv":0.0,"id":4596961}]}]}
{"op":"mcm","clk":"998890757","pt":1580590302846,"mc":[{"id":"1.168224030","marketDefinition":{"bspMarket":false,"turnInPlayEnabled":true,"persistenceEnabled":true,"marketBaseRate":5.0,"eventId":"29681672","eventTypeId":"2","numberOfWinners":1,"bettingType":"ODDS","marketType":"SET_WINNER","marketTime":"2020-02-02T14:00:00.000Z","suspendTime":"2020-02-02T14:00:00.000Z","bspReconciled":false,"complete":true,"inPlay":false,"crossMatching":false,"runnersVoidable":false,"numberOfActiveRunners":2,"betDelay":0,"status":"OPEN","runners":[{"status":"ACTIVE","sortPriority":1,"id":8908205,"name":"Juan Pablo Ficovich"},{"status":"ACTIVE","sortPriority":2,"id":4596961,"name":"Filip Horansky"}],"regulators":["MR_INT"],"countryCode":"AR","discountAllowed":true,"timezone":"UTC","openDate":"2020-02-02T13:00:00.000Z","version":3147422061,"name":"Set 2 Winner","eventName":"Ficovich v Horansky"}}]}
{"op":"mcm","clk":"998891049","pt":1580590304855,"mc":[{"id":"1.168224030","marketDefinition":{"bspMarket":false,"turnInPlayEnabled":true,"persistenceEnabled":true,"marketBaseRate":5.0,"eventId":"29681672","eventTypeId":"2","numberOfWinners":1,"bettingType":"ODDS","marketType":"SET_WINNER","marketTime":"2020-02-02T14:00:00.000Z","suspendTime":"2020-02-02T14:00:00.000Z","bspReconciled":false,"complete":true,"inPlay":false,"crossMatching":false,"runnersVoidable":false,"numberOfActiveRunners":2,"betDelay":0,"status":"OPEN","runners":[{"status":"ACTIVE","sortPriority":1,"id":8908205,"name":"Juan Pablo Ficovich"},{"status":"ACTIVE","sortPriority":2,"id":4596961,"name":"Filip Horansky"}],"regulators":["MR_INT"],"countryCode":"AR","discountAllowed":true,"timezone":"UTC","openDate":"2020-02-02T14:00:00.000Z","version":3147422061,"name":"Set 2 Winner","eventName":"Ficovich v Horansky"}}]}
{"op":"mcm","clk":"999926852","pt":1580602757086,"mc":[{"id":"1.168224030","rc":[{"batb":[[0,1.01,12.53]],"ltp":0.0,"tv":0.0,"id":8908205},{"batb":[[0,1.01,12.53]],"ltp":0.0,"tv":0.0,"id":4596961}]}]}
{"op":"mcm","clk":"999926919","pt":1580602758073,"mc":[{"id":"1.168224030","rc":[{"batb":[[0,1.01,10.51]],"ltp":0.0,"tv":0.0,"id":8908205},{"batb":[[0,1.01,10.51]],"ltp":0.0,"tv":0.0,"id":4596961}]}]}
{"op":"mcm","clk":"999971893","pt":1580603520943,"mc":[{"id":"1.168224030","rc":[{"batb":[[0,1.01,13.04]],"ltp":0.0,"tv":0.0,"id":8908205},{"batb":[[0,1.01,13.04]],"ltp":0.0,"tv":0.0,"id":4596961}]}]}
{"op":"mcm","clk":"999971968","pt":1580603522041,"mc":[{"id":"1.168224030","rc":[{"batb":[[0,1.01,11.01]],"ltp":0.0,"tv":0.0,"id":8908205},{"batb":[[0,1.01,11.01]],"ltp":0.0,"tv":0.0,"id":4596961}]}]}
{"op":"mcm","clk":"1003804455","pt":1580652097370,"mc":[{"id":"1.168224030","rc":[{"batb":[[0,1.87,17.39],[1,1.01,11.01]],"ltp":0.0,"tv":0.0,"id":8908205},{"batb":[[0,2,27.85],[1,1.01,11.01]],"ltp":0.0,"tv":0.0,"id":4596961}]}]}
{"op":"mcm","clk":"1003823937","pt":1580652185875,"mc":[{"id":"1.168224030","rc":[{"batb":[[1,1.82,50.41],[2,1.01,11.01]],"batl":[[0,2,42.01]],"ltp":0.0,"tv":0.0,"id":8908205},{"batb":[[0,2,69.86]],"batl":[[0,2.24,33.61]],"ltp":0.0,"tv":0.0,"id":4596961}]}]}
{"op":"mcm","clk":"1003824171","pt":1580652186854,"mc":[{"id":"1.168224030","rc":[{"batb":[[0,1.86,17.78]],"ltp":0.0,"tv":0.0,"id":8908205},{"batb":[[0,2.02,27.3],[1,2,69.86],[2,1.01,11.01]],"ltp":0.0,"tv":0.0,"id":4596961}]}]}
{"op":"mcm","clk":"1003826530","pt":1580652197301,"mc":[{"id":"1.168224030","marketDefinition":{"bspMarket":false,"turnInPlayEnabled":true,"persistenceEnabled":true,"marketBaseRate":5.0,"eventId":"29681672","eventTypeId":"2","numberOfWinners":1,"bettingType":"ODDS","marketType":"SET_WINNER","marketTime":"2020-02-02T14:00:00.000Z","suspendTime":"2020-02-02T14:00:00.000Z","bspReconciled":false,"complete":true,"inPlay":false,"crossMatching":true,"runnersVoidable":false,"numberOfActiveRunners":2,"betDelay":0,"status":"OPEN","runners":[{"status":"ACTIVE","sortPriority":1,"id":8908205,"name":"Juan Pablo Ficovich"},{"status":"ACTIVE","sortPriority":2,"id":4596961,"name":"Filip Horansky"}],"regulators":["MR_INT"],"countryCode":"AR","discountAllowed":true,"timezone":"UTC","openDate":"2020-02-02T14:00:00.000Z","version":3149079706,"name":"Set 2 Winner","eventName":"Ficovich v Horansky"}}]}
{"op":"mcm","clk":"1003827037","pt":1580652199402,"mc":[{"id":"1.168224030","rc":[{"batb":[[0,1.84,18.18]],"ltp":0.0,"tv":0.0,"id":8908205},{"batb":[[0,2.04,26.67],[1,2.02,27.3],[2,2,42.01]],"ltp":0.0,"tv":0.0,"id":4596961}]}]}
{"op":"mcm","clk":"1003858478","pt":1580652330433,"mc":[{"id":"1.168224030","rc":[{"batb":[[0,1.83,18.57]],"ltp":0.0,"tv":0.0,"id":8908205},{"batb":[[0,2.04,26.04],[1,2,42.01],[2,1.01,11.01]],"ltp":0.0,"tv":0.0,"id":4596961}]}]}
{"op":"mcm","clk":"1003859872","pt":1580652336103,"mc":[{"id":"1.168224030","rc":[{"batb":[[0,1.84,1.37],[1,1.83,18.57],[2,1.82,50.41]],"ltp":0.0,"tv":0.0,"id":8908205},{"batb":[[2,1.01,12.69]],"ltp":0.0,"tv":0.0,"id":4596961}]}]}
{"op":"mcm","clk":"1003860028","pt":1580652336672,"mc":[{"id":"1.168224030","rc":[{"batb":[[0,2.06,1.23],[1,2.04,26.04],[2,2,42.01]],"ltp":0.0,"tv":0.0,"id":4596961}]}]}
{"op":"mcm","clk":"1003864190","pt":1580652354115,"mc":[{"id":"1.168224030","rc":[{"batb":[[0,2.06,27.03]],"ltp":0.0,"tv":0.0,"id":4596961}]}]}
{"op":"mcm","clk":"1003864238","pt":1580652354298,"mc":[{"id":"1.168224030","rc":[{"batb":[[1,2,42.01],[2,1.01,11.01]],"ltp":0.0,"tv":0.0,"id":4596961}]}]}
{"op":"mcm","clk":"1003870772","pt":1580652381954,"mc":[{"id":"1.168224030","rc":[{"batb":[[1,1.82,69.3],[2,1.01,11.01]],"ltp":0.0,"tv":0.0,"id":8908205},{"batb":[[0,2.06,26.8]],"ltp":0.0,"tv":0.0,"id":4596961}]}]}
{"op":"mcm","clk":"1003875886","pt":1580652403091,"mc":[{"id":"1.168224030","rc":[{"batb":[[1,1.82,50.41]],"ltp":0.0,"tv":0.0,"id":8908205},{"batb":[[0,2.06,1.23]],"ltp":0.0,"tv":0.0,"id":4596961}]}]}
{"op":"mcm","clk":"1003876018","pt":1580652403595,"mc":[{"id":"1.168224030","marketDefinition":{"bspMarket":false,"turnInPlayEnabled":true,"persistenceEnabled":true,"marketBaseRate":5.0,"eventId":"29681672","eventTypeId":"2","numberOfWinners":1,"bettingType":"ODDS","marketType":"SET_WINNER","marketTime":"2020-02-02T14:00:00.000Z","suspendTime":"2020-02-02T14:00:00.000Z","bspReconciled":false,"complete":true,"inPlay":true,"crossMatching":true,"runnersVoidable":false,"numberOfActiveRunners":2,"betDelay":3,"status":"OPEN","runners":[{"status":"ACTIVE","sortPriority":1,"id":8908205,"name":"Juan Pablo Ficovich"},{"status":"ACTIVE","sortPriority":2,"id":4596961,"name":"Filip Horansky"}],"regulators":["MR_INT"],"countryCode":"AR","discountAllowed":true,"timezone":"UTC","openDate":"2020-02-02T14:00:00.000Z","version":3149116818,"name":"Set 2 Winner","eventName":"Ficovich v Horansky"},"rc":[{"batb":[[0,1.01,10.51],[1,1.82,0],[2,1.01,0]],"ltp":0.0,"tv":0.0,"id":8908205},{"batb":[[0,1.01,10.51],[1,2,0],[2,1.01,0]],"ltp":0.0,"tv":0.0,"id":4596961}]}]}
{"op":"mcm","clk":"1003876886","pt":1580652407004,"mc":[{"id":"1.168224030","rc":[{"batb":[[0,1.82,50.41],[1,1.01,10.51]],"batl":[[0,2,42.01]],"ltp":0.0,"tv":0.0,"id":8908205},{"batb":[[0,2,42.01],[1,1.01,10.51]],"batl":[[0,2.24,33.61]],"ltp":0.0,"tv":0.0,"id":4596961}]}]}
{"op":"mcm","clk":"1003876959","pt":1580652407313,"mc":[{"id":"1.168224030","rc":[{"batb":[[0,1.01,10.51],[1,1.01,0]],"ltp":0.0,"tv":0.0,"id":8908205},{"batb":[[0,1.01,10.51],[1,1.01,0]],"ltp":0.0,"tv":0.0,"id":4596961}]}]}
{"op":"mcm","clk":"1003881581","pt":1580652425091,"mc":[{"id":"1.168224030","rc":[{"batb":[[0,1.78,20.38],[1,1.74,21.79],[2,1.01,10.51]],"ltp":0.0,"tv":0.0,"id":8908205},{"batb":[[0,2.12,23.6],[1,2.06,25.41],[2,1.57,563.57]],"ltp":0.0,"tv":0.0,"id":4596961}]}]}
{"op":"mcm","clk":"1003881761","pt":1580652425755,"mc":[{"id":"1.168224030","rc":[{"batb":[[1,1.77,53.77],[2,1.74,21.79]],"batl":[[0,1.96,42.01]],"ltp":0.0,"tv":0.0,"id":8908205},{"batb":[[2,2.04,40.33]],"batl":[[0,2.3,31.93]],"ltp":0.0,"tv":0.0,"id":4596961}]}]}
{"op":"mcm","clk":"1003884355","pt":1580652435514,"mc":[{"id":"1.168224030","rc":[{"batb":[[0,1.77,53.77],[1,1.74,21.79],[2,1.01,10.51]],"ltp":0.0,"tv":0.0,"id":8908205},{"batb":[[0,2.06,25.41],[1,2.04,40.33],[2,1.01,10.51]],"ltp":0.0,"tv":0.0,"id":4596961}]}]}
{"op":"mcm","clk":"1003884643","pt":1580652436533,"mc":[{"id":"1.168224030","rc":[{"batb":[[0,1.74,21.79],[1,1.01,10.51],[2,1.01,0]],"ltp":0.0,"tv":0.0,"id":8908205},{"batb":[[1,1.01,10.51],[2,1.01,0]],"ltp":0.0,"tv":0.0,"id":4596961}]}]}
{"op":"mcm","clk":"1003887126","pt":1580652445099,"mc":[{"id":"1.168224030","rc":[{"batb":[[1,1.71,23.45],[2,1.01,10.51]],"ltp":0.0,"tv":0.0,"id":8908205},{"batb":[[0,2.18,21.95],[1,2.12,23.45],[2,2.06,440.58]],"ltp":0.0,"tv":0.0,"id":4596961}]}]}
{"op":"mcm","clk":"1003887261","pt":1580652445638,"mc":[{"id":"1.168224030","rc":[{"batb":[[1,1.73,57.13],[2,1.71,23.45]],"ltp":0.0,"tv":0.0,"id":8908205},{"batb":[[2,2.1,37.81]],"batl":[[0,2.36,30.25]],"ltp":0.0,"tv":0.0,"id":4596961}]}]}
{"op":"mcm","clk":"1003887580","pt":1580652446808,"mc":[{"id":"1.168224030","rc":[{"batl":[[0,1.91,42.01]],"ltp":0.0,"tv":0.0,"id":8908205}]}]}
{"op":"mcm","clk":"1003890531","pt":1580652458052,"mc":[{"id":"1.168224030","rc":[{"batb":[[0,1.73,57.13],[1,1.71,23.45],[2,1.01,10.51]],"ltp":0.0,"tv":0.0,"id":8908205},{"batb":[[0,2.12,23.45],[1,2.1,37.81],[2,1.01,10.51]],"ltp":0.0,"tv":0.0,"id":4596961}]}]}
{"op":"mcm","clk":"1003890601","pt":1580652458340,"mc":[{"id":"1.168224030","rc":[{"batb":[[0,1.71,23.45],[1,1.01,10.51],[2,1.01,0]],"ltp":0.0,"tv":0.0,"id":8908205},{"batb":[[1,1.01,10.51],[2,1.01,0]],"ltp":0.0,"tv":0.0,"id":4596961}]}]}
{"op":"mcm","clk":"1003892584","pt":1580652466042,"mc":[{"id":"1.168224030","rc":[{"batb":[[0,1.78,20.54],[1,1.75,55.45],[2,1.73,22.27]],"batl":[[0,1.94,42.01]],"ltp":0.0,"tv":0.0,"id":8908205},{"batb":[[1,2.08,25.02],[2,2.06,39.49]],"batl":[[0,2.32,31.09]],"ltp":0.0,"tv":0.0,"id":4596961}]}]}
{"op":"mcm","clk":"1003895102","pt":1580652475182,"mc":[{"id":"1.168224030","rc":[{"batb":[[0,1.75,55.45],[1,1.73,22.27],[2,1.01,10.51]],"ltp":0.0,"tv":0.0,"id":8908205},{"batb":[[0,2.08,25.02],[1,2.06,39.49],[2,1.01,10.51]],"ltp":0.0,"tv":0.0,"id":4596961}]}]}
{"op":"mcm","clk":"1003895471","pt":1580652476474,"mc":[{"id":"1.168224030","rc":[{"batb":[[0,1.73,22.27],[1,1.01,10.51],[2,1.01,0]],"ltp":0.0,"tv":0.0,"id":8908205},{"batb":[[1,1.01,10.51],[2,1.01,0]],"ltp":0.0,"tv":0.0,"id":4596961}]}]}
{"op":"mcm","clk":"1003899058","pt":1580652489695,"mc":[{"id":"1.168224030","rc":[{"batb":[[1,1.71,58.81],[2,1.7,23.76]],"batl":[[0,1.9,42.01]],"ltp":0.0,"tv":0.0,"id":8908205},{"batb":[[0,2.2,21.48],[1,2.14,59.34],[2,2.08,442.56]],"batl":[[0,2.4,29.41]],"ltp":0.0,"tv":0.0,"id":4596961}]}]}
{"op":"mcm","clk":"1003899225","pt":1580652490284,"mc":[{"id":"1.168224030","rc":[{"batb":[[2,1.01,10.51]],"ltp":0.0,"tv":0.0,"id":4596961}]}]}
{"op":"mcm","clk":"1003902908","pt":1580652503480,"mc":[{"id":"1.168224030","rc":[{"batb":[[0,1.71,58.81],[1,1.7,23.76],[2,1.01,10.51]],"ltp":0.0,"tv":0.0,"id":8908205},{"batb":[[0,2.14,59.34],[1,1.01,10.51],[2,1.01,0]],"ltp":0.0,"tv":0.0,"id":4596961}]}]}
{"op":"mcm","clk":"1003903179","pt":1580652504498,"mc":[{"id":"1.168224030","rc":[{"batb":[[0,1.7,23.76],[1,1.01,10.51],[2,1.01,0]],"ltp":0.0,"tv":0.0,"id":8908205},{"batb":[[0,2.14,23.21]],"ltp":0.0,"tv":0.0,"id":4596961}]}]}
{"op":"mcm","clk":"1003907037","pt":1580652518959,"mc":[{"id":"1.168224030","rc":[{"batb":[[1,1.67,25.49],[2,1.01,10.51]],"ltp":0.0,"tv":0.0,"id":8908205},{"batb":[[0,2.24,19.99],[1,2.2,21.48],[2,2.14,23.21]],"ltp":0.0,"tv":0.0,"id":4596961}]}]}
{"op":"mcm","clk":"1003907265","pt":1580652519754,"mc":[{"id":"1.168224030","rc":[{"batb":[[2,1.63,66.38]],"batl":[[0,1.78,42.01]],"ltp":0.0,"tv":0.0,"id":8908205},{"batb":[[0,2.28,32.77],[1,2.24,19.99],[2,2.2,21.48]],"batl":[[0,2.6,26.05]],"ltp":0.0,"tv":0.0,"id":4596961}]}]}
{"op":"mcm","clk":"1003909520","pt":1580652527953,"mc":[{"id":"1.168224030","rc":[{"batb":[[0,1.69,24.31],[1,1.65,26.12]],"ltp":0.0,"tv":0.0,"id":8908205},{"batb":[[1,2.26,19.43],[2,2.22,20.85]],"ltp":0.0,"tv":0.0,"id":4596961}]}]}
{"op":"mcm","clk":"1003911695","pt":1580652535518,"mc":[{"id":"1.168224030","rc":[{"batb":[[0,1.68,24.47]],"ltp":0.0,"tv":0.0,"id":8908205},{"batb":[[0,2.28,52.12],[1,2.22,20.69],[2,1.01,10.51]],"ltp":0.0,"tv":0.0,"id":4596961}]}]}
{"op":"mcm","clk":"1003918859","pt":1580652563382,"mc":[{"id":"1.168224030","rc":[{"batb":[[0,1.65,26.12],[1,1.63,66.38],[2,1.01,10.51]],"ltp":0.0,"tv":0.0,"id":8908205},{"batb":[[0,2.28,32.77],[1,2.22,20.54]],"ltp":0.0,"tv":0.0,"id":4596961}]}]}
{"op":"mcm","clk":"1003919109","pt":1580652564480,"mc":[{"id":"1.168224030","rc":[{"batb":[[1,1.01,10.51],[2,1.01,0]],"ltp":0.0,"tv":0.0,"id":8908205},{"batb":[[0,2.22,20.54],[1,1.01,10.51],[2,1.01,0]],"ltp":0.0,"tv":0.0,"id":4596961}]}]}
{"op":"mcm","clk":"1003923729","pt":1580652583041,"mc":[{"id":"1.168224030","rc":[{"batb":[[0,1.71,23.21],[1,1.68,24.71],[2,1.01,10.51]],"ltp":0.0,"tv":0.0,"id":8908205},{"batb":[[1,2.16,22.03],[2,1.01,10.51]],"ltp":0.0,"tv":0.0,"id":4596961}]}]}
{"op":"mcm","clk":"1003923905","pt":1580652583658,"mc":[{"id":"1.168224030","rc":[{"batb":[[2,1.67,62.17]],"batl":[[0,1.83,42.01]],"ltp":0.0,"tv":0.0,"id":8908205},{"batb":[[1,2.2,34.45],[2,2.16,22.03]],"batl":[[0,2.5,27.73]],"ltp":0.0,"tv":0.0,"id":4596961}]}]}
{"op":"mcm","clk":"1003927750","pt":1580652598838,"mc":[{"id":"1.168224030","rc":[{"batb":[[0,1.68,24.71],[1,1.01,10.51],[2,1.67,0]],"ltp":0.0,"tv":0.0,"id":8908205},{"batb":[[0,2.16,22.03],[1,1.01,10.51],[2,2.16,0]],"ltp":0.0,"tv":0.0,"id":4596961}]}]}
{"op":"mcm","clk":"1003928531","pt":1580652602109,"mc":[{"id":"1.168224030","rc":[{"batb":[[0,1.69,24.39]],"ltp":0.0,"tv":0.0,"id":8908205}]}]}
{"op":"mcm","clk":"1003930459","pt":1580652609926,"mc":[{"id":"1.168224030","rc":[{"batb":[[0,1.75,21.48],[1,1.72,22.82],[2,1.71,58.81]],"batl":[[0,1.87,42.01]],"ltp":0.0,"tv":0.0,"id":8908205},{"batb":[[1,2.14,36.13],[2,2.1,24.16]],"ltp":0.0,"tv":0.0,"id":4596961}]}]}
{"op":"mcm","clk":"1003931171","pt":1580652613038,"mc":[{"id":"1.168224030","rc":[{"batl":[[0,2.42,29.41]],"ltp":0.0,"tv":0.0,"id":4596961}]}]}
{"op":"mcm","clk":"1003935714","pt":1580652630542,"mc":[{"id":"1.168224030","rc":[{"batb":[[0,1.72,22.82],[1,1.01,10.51],[2,1.71,0]],"ltp":0.0,"tv":0.0,"id":8908205},{"batb":[[0,2.1,24.16],[1,1.01,10.51],[2,2.1,0]],"ltp":0.0,"tv":0.0,"id":4596961}]}]}
{"op":"mcm","clk":"1003937769","pt":1580652638721,"mc":[{"id":"1.168224030","rc":[{"batb":[[1,1.69,24.31],[2,1.01,10.51]],"ltp":0.0,"tv":0.0,"id":8908205},{"batb":[[0,2.22,20.93],[1,2.14,23.05],[2,1.01,10.51]],"ltp":0.0,"tv":0.0,"id":4596961}]}]}
{"op":"mcm","clk":"1003938128","pt":1580652639995,"mc":[{"id":"1.168224030","rc":[{"batb":[[1,1.69,84.81]],"batl":[[0,1.85,42.01]],"ltp":0.0,"tv":0.0,"id":8908205},{"batb":[[1,2.18,35.29],[2,2.14,23.05]],"batl":[[0,2.46,28.57]],"ltp":0.0,"tv":0.0,"id":4596961}]}]}
{"op":"mcm","clk":"1003941787","pt":1580652653761,"mc":[{"id":"1.168224030","rc":[{"batb":[[0,1.69,84.81],[1,1.01,10.51],[2,1.01,0]],"ltp":0.0,"tv":0.0,"id":8908205},{"batb":[[0,2.18,35.29],[1,2.14,23.05],[2,1.01,10.51]],"ltp":0.0,"tv":0.0,"id":4596961}]}]}
{"op":"mcm","clk":"1003941993","pt":1580652654549,"mc":[{"id":"1.168224030","rc":[{"batb":[[0,1.69,24.31]],"ltp":0.0,"tv":0.0,"id":8908205},{"batb":[[0,2.14,23.05],[1,1.01,10.51],[2,1.01,0]],"ltp":0.0,"tv":0.0,"id":4596961}]}]}
{"op":"mcm","clk":"1003945596","pt":1580652667464,"mc":[{"id":"1.168224030","rc":[{"batb":[[0,1.77,20.85],[1,1.73,22.42],[2,1.72,57.97]],"batl":[[0,1.89,42.01]],"ltp":0.0,"tv":0.0,"id":8908205},{"batb":[[1,2.12,36.97],[2,2.08,24.86]],"batl":[[0,2.4,29.41]],"ltp":0.0,"tv":0.0,"id":4596961}]}]}
{"op":"mcm","clk":"1003949482","pt":1580652681400,"mc":[{"id":"1.168224030","rc":[{"batb":[[0,1.73,22.42],[1,1.72,57.97],[2,1.01,10.51]],"ltp":0.0,"tv":0.0,"id":8908205},{"batb":[[0,2.12,36.97],[1,2.08,24.86],[2,1.01,10.51]],"ltp":0.0,"tv":0.0,"id":4596961}]}]}
{"op":"mcm","clk":"1003949824","pt":1580652682574,"mc":[{"id":"1.168224030","rc":[{"batb":[[1,1.01,10.51],[2,1.01,0]],"ltp":0.0,"tv":0.0,"id":8908205},{"batb":[[0,2.08,24.86],[1,1.01,10.51],[2,1.01,0]],"ltp":0.0,"tv":0.0,"id":4596961}]}]}
{"op":"mcm","clk":"1003950367","pt":1580652684666,"mc":[{"id":"1.168224030","rc":[{"batb":[[0,1.74,21.79]],"ltp":0.0,"tv":0.0,"id":8908205},{"batb":[[0,2.06,25.65]],"ltp":0.0,"tv":0.0,"id":4596961}]}]}
{"op":"mcm","clk":"1003952154","pt":1580652691524,"mc":[{"id":"1.168224030","rc":[{"batb":[[1,1.71,58.81],[2,1.7,23.53]],"batl":[[0,1.88,42.01]],"ltp":0.0,"tv":0.0,"id":8908205},{"batb":[[0,2.18,22.03],[1,2.14,36.13],[2,2.1,24.16]],"batl":[[0,2.44,28.57]],"ltp":0.0,"tv":0.0,"id":4596961}]}]}
{"op":"mcm","clk":"1003955099","pt":1580652703005,"mc":[{"id":"1.168224030","rc":[{"batb":[[0,1.71,58.81],[1,1.7,23.53],[2,1.01,10.51]],"ltp":0.0,"tv":0.0,"id":8908205},{"batb":[[0,2.14,36.13],[1,2.1,24.16],[2,1.01,10.51]],"ltp":0.0,"tv":0.0,"id":4596961}]}]}
{"op":"mcm","clk":"1003955514","pt":1580652704628,"mc":[{"id":"1.168224030","rc":[{"batb":[[0,1.7,23.53],[1,1.01,10.51],[2,1.01,0]],"ltp":0.0,"tv":0.0,"id":8908205},{"batb":[[0,2.1,24.16],[1,1.01,10.51],[2,1.01,0]],"ltp":0.0,"tv":0.0,"id":4596961}]}]}
{"op":"mcm","clk":"1003960678","pt":1580652724667,"mc":[{"id":"1.168224030","rc":[{"batl":[[0,2.84,228.62]],"ltp":0.0,"tv":0.0,"id":4596961}]}]}
{"op":"mcm","clk":"1003960896","pt":1580652725554,"mc":[{"id":"1.168224030","rc":[{"batb":[[1,1.69,60.49],[2,1.67,25.34]],"batl":[[0,1.85,42.01]],"ltp":0.0,"tv":0.0,"id":8908205},{"batb":[[0,2.24,20.22],[1,2.18,35.29],[2,2.16,22.11]],"batl":[[0,2.48,27.73],[1,2.84,228.62]],"ltp":0.0,"tv":0.0,"id":4596961}]}]}
{"op":"mcm","clk":"1003961619","pt":1580652728390,"mc":[{"id":"1.168224030","rc":[{"batl":[[1,2.3,309.75]],"ltp":0.0,"tv":0.0,"id":8908205}]}]}
{"op":"mcm","clk":"1003965410","pt":1580652744042,"mc":[{"id":"1.168224030","rc":[{"batb":[[0,1.69,60.49],[1,1.67,25.34],[2,1.01,10.51]],"ltp":0.0,"tv":0.0,"id":8908205},{"batb":[[0,2.18,35.29],[1,2.16,22.11],[2,1.01,10.51]],"ltp":0.0,"tv":0.0,"id":4596961}]}]}
{"op":"mcm","clk":"1003965531","pt":1580652744610,"mc":[{"id":"1.168224030","rc":[{"batb":[[0,1.67,25.34],[1,1.01,10.51],[2,1.01,0]],"batl":[[0,2.3,309.75],[1,2.3,0]],"ltp":0.0,"tv":0.0,"id":8908205},{"batb":[[0,2.16,22.11],[1,1.01,10.51],[2,1.01,0]],"batl":[[0,2.84,228.62],[1,2.84,0]],"ltp":0.0,"tv":0.0,"id":4596961}]}]}
{"op":"mcm","clk":"1003969305","pt":1580652760105,"mc":[{"id":"1.168224030","rc":[{"batb":[[0,1.67,87.51],[1,1.64,26.91],[2,1.01,10.51]],"batl":[[0,1.82,42.01],[1,2.3,309.75]],"ltp":0.0,"tv":0.0,"id":8908205},{"batb":[[0,2.3,18.65],[1,2.24,20.3],[2,2.22,33.61]],"batl":[[0,2.52,26.89],[1,2.84,228.62]],"ltp":0.0,"tv":0.0,"id":4596961}]}]}
{"op":"mcm","clk":"1003971081","pt":1580652767433,"mc":[{"id":"1.168224030","rc":[{"batb":[[0,1.67,62.17]],"ltp":0.0,"tv":0.0,"id":8908205},{"batb":[[0,2.24,20.3],[1,2.22,33.61],[2,1.01,10.51]],"ltp":0.0,"tv":0.0,"id":4596961}]}]}
{"op":"mcm","clk":"1003971365","pt":1580652768620,"mc":[{"id":"1.168224030","rc":[{"batb":[[0,1.64,26.91],[1,1.01,10.51],[2,1.01,0]],"batl":[[0,2.3,309.75],[1,2.3,0]],"ltp":0.0,"tv":0.0,"id":8908205},{"batb":[[1,1.01,10.51],[2,1.01,0]],"batl":[[0,2.84,228.62],[1,2.84,0]],"ltp":0.0,"tv":0.0,"id":4596961}]}]}
{"op":"mcm","clk":"1003976978","pt":1580652791930,"mc":[{"id":"1.168224030","rc":[{"batb":[[1,1.62,67.22],[2,1.61,28.72]],"batl":[[0,1.78,42.01],[1,2.3,309.75]],"ltp":0.0,"tv":0.0,"id":8908205},{"batb":[[0,2.36,17.39],[1,2.32,31.09],[2,2.3,18.73]],"batl":[[0,2.62,25.21]],"ltp":0.0,"tv":0.0,"id":4596961}]}]}
{"op":"mcm","clk":"1003977539","pt":1580652794252,"mc":[{"id":"1.168224030","rc":[{"batl":[[1,3.15,200.42]],"ltp":0.0,"tv":0.0,"id":4596961}]}]}
{"op":"mcm","clk":"1003982723","pt":1580652814969,"mc":[{"id":"1.168224030","rc":[{"batb":[[0,1.62,67.22],[1,1.61,28.56],[2,1.01,10.51]],"ltp":0.0,"tv":0.0,"id":8908205},{"batb":[[0,2.32,31.09],[1,2.3,18.73],[2,1.01,10.51]],"ltp":0.0,"tv":0.0,"id":4596961}]}]}
{"op":"mcm","clk":"1003983253","pt":1580652817065,"mc":[{"id":"1.168224030","rc":[{"batb":[[0,1.61,28.56],[1,1.01,10.51],[2,1.01,0]],"batl":[[0,2.3,309.75],[1,2.3,0]],"ltp":0.0,"tv":0.0,"id":8908205},{"batb":[[0,2.3,18.73],[1,1.01,10.51],[2,1.01,0]],"batl":[[0,3.15,200.42],[1,3.15,0]],"ltp":0.0,"tv":0.0,"id":4596961}]}]}
{"op":"mcm","clk":"1003984468","pt":1580652822088,"mc":[{"id":"1.168224030","rc":[{"batb":[[0,1.67,25.1],[1,1.65,63.85],[2,1.64,26.91]],"batl":[[0,1.8,42.01],[1,2.3,309.75]],"ltp":0.0,"tv":0.0,"id":8908205},{"batb":[[1,2.28,32.77],[2,2.24,20.06]],"batl":[[0,2.58,26.05]],"ltp":0.0,"tv":0.0,"id":4596961}]}]}
{"op":"mcm","clk":"1003985114","pt":1580652824777,"mc":[{"id":"1.168224030","rc":[{"batl":[[1,3,213.45]],"ltp":0.0,"tv":0.0,"id":4596961}]}]}
{"op":"mcm","clk":"1003986896","pt":1580652832069,"mc":[{"id":"1.168224030","rc":[{"batb":[[0,1.65,63.85],[1,1.64,26.91],[2,1.01,10.51]],"ltp":0.0,"tv":0.0,"id":8908205},{"batb":[[0,2.28,32.77],[1,2.24,20.06],[2,1.01,10.51]],"ltp":0.0,"tv":0.0,"id":4596961}]}]}
{"op":"mcm","clk":"1003987053","pt":1580652832678,"mc":[{"id":"1.168224030","rc":[{"batb":[[0,1.64,26.91],[1,1.01,10.51],[2,1.01,0]],"batl":[[0,2.3,309.75],[1,2.3,0]],"ltp":0.0,"tv":0.0,"id":8908205},{"batb":[[0,2.24,20.06],[1,1.01,10.51],[2,1.01,0]],"batl":[[0,3,213.45],[1,3,0]],"ltp":0.0,"tv":0.0,"id":4596961}]}]}
{"op":"mcm","clk":"1003992017","pt":1580652853893,"mc":[{"id":"1.168224030","rc":[{"batb":[[1,1.62,67.22],[2,1.61,28.72]],"batl":[[0,1.76,42.01],[1,2.3,309.75]],"ltp":0.0,"tv":0.0,"id":8908205},{"batb":[[0,2.36,17.39],[1,2.32,31.09],[2,2.3,18.65]],"batl":[[0,2.64,25.21],[1,3,213.45]],"ltp":0.0,"tv":0.0,"id":4596961}]}]}
{"op":"mcm","clk":"1003995400","pt":1580652869319,"mc":[{"id":"1.168224030","rc":[{"batb":[[0,1.62,67.22],[1,1.61,28.72],[2,1.01,10.51]],"ltp":0.0,"tv":0.0,"id":8908205},{"batb":[[0,2.32,31.09],[1,2.3,18.65],[2,1.01,10.51]],"ltp":0.0,"tv":0.0,"id":4596961}]}]}
{"op":"mcm","clk":"1003995722","pt":1580652870746,"mc":[{"id":"1.168224030","rc":[{"batb":[[0,1.61,28.72],[1,1.01,10.51],[2,1.01,0]],"batl":[[0,2.3,309.75],[1,2.3,0]],"ltp":0.0,"tv":0.0,"id":8908205},{"batb":[[0,2.3,18.65],[1,1.01,10.51],[2,1.01,0]],"batl":[[0,3,213.45],[1,3,0]],"ltp":0.0,"tv":0.0,"id":4596961}]}]}
{"op":"mcm","clk":"1004000124","pt":1580652889913,"mc":[{"id":"1.168224030","rc":[{"batb":[[0,1.67,25.34],[1,1.64,27.07],[2,1.63,66.38]],"batl":[[0,1.78,42.01],[1,2.3,309.75]],"ltp":0.0,"tv":0.0,"id":8908205},{"batb":[[1,2.28,32.77],[2,2.24,20.3]],"batl":[[0,2.6,26.05],[1,3,213.45]],"ltp":0.0,"tv":0.0,"id":4596961}]}]}
{"op":"mcm","clk":"1004004063","pt":1580652907082,"mc":[{"id":"1.168224030","rc":[{"batb":[[0,1.64,27.07],[1,1.63,66.38],[2,1.01,10.51]],"ltp":0.0,"tv":0.0,"id":8908205},{"batb":[[0,2.28,32.77],[1,2.24,20.3],[2,1.01,10.51]],"ltp":0.0,"tv":0.0,"id":4596961}]}]}
{"op":"mcm","clk":"1004004459","pt":1580652908874,"mc":[{"id":"1.168224030","rc":[{"batb":[[1,1.01,10.51],[2,1.01,0]],"batl":[[0,2.3,309.75],[1,2.3,0]],"ltp":0.0,"tv":0.0,"id":8908205},{"batb":[[0,2.24,20.3],[1,1.01,10.51],[2,1.01,0]],"batl":[[0,3,213.45],[1,3,0]],"ltp":0.0,"tv":0.0,"id":4596961}]}]}
{"op":"mcm","clk":"1004008169","pt":1580652926094,"mc":[{"id":"1.168224030","rc":[{"batb":[[1,1.61,68.06],[2,1.01,10.51]],"ltp":0.0,"tv":0.0,"id":8908205},{"batl":[[0,2.66,25.21],[1,3,213.45]],"ltp":0.0,"tv":0.0,"id":4596961}]}]}
{"op":"mcm","clk":"1004008293","pt":1580652926689,"mc":[{"id":"1.168224030","rc":[{"batb":[[2,1.6,29.19]],"batl":[[0,1.75,42.01],[1,2.3,309.75]],"ltp":0.0,"tv":0.0,"id":8908205},{"batb":[[0,2.36,17.31],[1,2.34,31.09],[2,2.3,18.88]],"ltp":0.0,"tv":0.0,"id":4596961}]}]}
{"op":"mcm","clk":"1004011897","pt":1580652942850,"mc":[{"id":"1.168224030","rc":[{"batb":[[0,1.6,29.19],[1,1.01,10.51],[2,1.6,0]],"batl":[[0,2.3,309.75],[1,2.3,0]],"ltp":0.0,"tv":0.0,"id":8908205},{"batb":[[0,2.3,18.88],[1,1.01,10.51],[2,2.3,0]],"batl":[[0,3,213.45],[1,3,0]],"ltp":0.0,"tv":0.0,"id":4596961}]}]}
{"op":"mcm","clk":"1004017143","pt":1580652968033,"mc":[{"id":"1.168224030","rc":[{"batb":[[0,1.67,25.02],[1,1.64,26.83],[2,1.62,67.22]],"batl":[[0,1.77,42.01],[1,2.3,309.75]],"ltp":0.0,"tv":0.0,"id":8908205},{"batb":[[0,2.3,50.81],[1,2.24,20.3],[2,1.01,10.51]],"batl":[[0,2.62,25.21],[1,3,213.45]],"ltp":0.0,"tv":0.0,"id":4596961}]}]}
{"op":"mcm","clk":"1004020874","pt":1580652984840,"mc":[{"id":"1.168224030","rc":[{"batb":[[0,1.64,26.83],[1,1.01,10.51],[2,1.62,0]],"batl":[[0,2.3,309.75],[1,2.3,0]],"ltp":0.0,"tv":0.0,"id":8908205},{"batb":[[0,2.24,20.3],[1,1.01,10.51],[2,1.01,0]],"batl":[[0,3,213.45],[1,3,0]],"ltp":0.0,"tv":0.0,"id":4596961}]}]}
{"op":"mcm","clk":"1004024318","pt":1580653001121,"mc":[{"id":"1.168224030","rc":[{"batb":[[0,1.71,23.45],[1,1.68,24.86],[2,1.01,10.51]],"ltp":0.0,"tv":0.0,"id":8908205},{"batb":[[1,2.16,22.11],[2,1.01,10.51]],"ltp":0.0,"tv":0.0,"id":4596961}]}]}
{"op":"mcm","clk":"1004024529","pt":1580653002106,"mc":[{"id":"1.168224030","rc":[{"batb":[[2,1.66,63.01]],"batl":[[0,1.81,42.01],[1,2.3,309.75]],"ltp":0.0,"tv":0.0,"id":8908205},{"batb":[[0,2.24,53.91]],"batl":[[0,2.54,26.89],[1,3,213.45]],"ltp":0.0,"tv":0.0,"id":4596961}]}]}
{"op":"mcm","clk":"1004025988","pt":1580653008985,"mc":[{"id":"1.168224030","rc":[{"batb":[[0,1.7,23.6],[1,1.67,25.02]],"ltp":0.0,"tv":0.0,"id":8908205},{"batb":[[0,2.24,53.75],[1,2.18,21.87]],"ltp":0.0,"tv":0.0,"id":4596961}]}]}
{"op":"mcm","clk":"1004041317","pt":1580653086884,"mc":[{"id":"1.168224030","rc":[{"batb":[[0,1.67,25.02],[1,1.01,10.51],[2,1.66,0]],"batl":[[0,2.3,309.75],[1,2.3,0]],"ltp":0.0,"tv":0.0,"id":8908205},{"batb":[[0,2.18,21.87],[1,1.01,10.51],[2,1.01,0]],"batl":[[0,3,213.45],[1,3,0]],"ltp":0.0,"tv":0.0,"id":4596961}]}]}
{"op":"mcm","clk":"1004046724","pt":1580653115118,"mc":[{"id":"1.168224030","rc":[{"batb":[[1,1.65,26.52],[2,1.01,10.51]],"ltp":0.0,"tv":0.0,"id":8908205},{"batb":[[0,2.3,18.8],[1,2.22,20.46],[2,1.01,10.51]],"ltp":0.0,"tv":0.0,"id":4596961}]}]}
{"op":"mcm","clk":"1004046837","pt":1580653115812,"mc":[{"id":"1.168224030","rc":[{"batb":[[2,1.64,65.54]],"batl":[[0,1.79,42.01],[1,2.3,309.75]],"ltp":0.0,"tv":0.0,"id":8908205},{"batb":[[1,2.26,32.77],[2,2.22,20.46]],"batl":[[0,2.58,26.05],[1,3,213.45]],"ltp":0.0,"tv":0.0,"id":4596961}]}]}
{"op":"mcm","clk":"1004049265","pt":1580653128103,"mc":[{"id":"1.168224030","rc":[{"batb":[[0,1.65,26.52],[1,1.64,65.54],[2,1.01,10.51]],"ltp":0.0,"tv":0.0,"id":8908205},{"batb":[[0,2.26,32.77],[1,2.22,20.46],[2,1.01,10.51]],"ltp":0.0,"tv":0.0,"id":4596961}]}]}
{"op":"mcm","clk":"1004049403","pt":1580653128802,"mc":[{"id":"1.168224030","rc":[{"batb":[[1,1.01,10.51],[2,1.01,0]],"batl":[[0,2.3,309.75],[1,2.3,0]],"ltp":0.0,"tv":0.0,"id":8908205},{"batb":[[0,2.22,20.46],[1,1.01,10.51],[2,1.01,0]],"batl":[[0,3,213.45],[1,3,0]],"ltp":0.0,"tv":0.0,"id":4596961}]}]}
{"op":"mcm","clk":"1004052757","pt":1580653146107,"mc":[{"id":"1.168224030","rc":[{"batb":[[0,1.71,23.21],[1,1.68,24.94],[2,1.67,62.17]],"batl":[[0,1.83,42.01],[1,2.3,309.75]],"ltp":0.0,"tv":0.0,"id":8908205},{"batb":[[1,2.2,34.45],[2,2.16,22.42]],"batl":[[0,2.5,27.73],[1,3,213.45]],"ltp":0.0,"tv":0.0,"id":4596961}]}]}
{"op":"mcm","clk":"1004056120","pt":1580653163259,"mc":[{"id":"1.168224030","rc":[{"batb":[[0,1.68,24.94],[1,1.67,62.17],[2,1.01,10.51]],"ltp":0.0,"tv":0.0,"id":8908205},{"batb":[[0,2.2,34.45],[1,2.16,22.42],[2,1.01,10.51]],"ltp":0.0,"tv":0.0,"id":4596961}]}]}
{"op":"mcm","clk":"1004056442","pt":1580653164881,"mc":[{"id":"1.168224030","rc":[{"batb":[[1,1.01,10.51],[2,1.01,0]],"batl":[[0,2.3,309.75],[1,2.3,0]],"ltp":0.0,"tv":0.0,"id":8908205},{"batb":[[0,2.16,22.42],[1,1.01,10.51],[2,1.01,0]],"batl":[[0,3,213.45],[1,3,0]],"ltp":0.0,"tv":0.0,"id":4596961}]}]}
{"op":"mcm","clk":"1004057884","pt":1580653171976,"mc":[{"id":"1.168224030","rc":[{"batb":[[0,1.75,21.4],[1,1.72,23.05],[2,1.71,58.81]],"batl":[[0,1.88,42.01],[1,2.3,309.75]],"ltp":0.0,"tv":0.0,"id":8908205},{"batb":[[1,2.14,36.13],[2,2.1,24.47]],"batl":[[0,2.42,29.41]],"ltp":0.0,"tv":0.0,"id":4596961}]}]}
{"op":"mcm","clk":"1004058223","pt":1580653173679,"mc":[{"id":"1.168224030","rc":[{"batl":[[1,2.84,228.62]],"ltp":0.0,"tv":0.0,"id":4596961}]}]}
{"op":"mcm","clk":"1004060881","pt":1580653186958,"mc":[{"id":"1.168224030","rc":[{"batb":[[0,1.72,23.05],[1,1.01,10.51],[2,1.71,0]],"batl":[[0,2.3,309.75],[1,2.3,0]],"ltp":0.0,"tv":0.0,"id":8908205},{"batb":[[0,2.1,24.47],[1,1.01,10.51],[2,2.1,0]],"batl":[[0,2.84,228.62],[1,2.84,0]],"ltp":0.0,"tv":0.0,"id":4596961}]}]}
{"op":"mcm","clk":"1004066099","pt":1580653213013,"mc":[{"id":"1.168224030","rc":[{"batb":[[1,1.68,24.78],[2,1.01,10.51]],"ltp":0.0,"tv":0.0,"id":8908205},{"batb":[[0,2.22,20.69],[1,2.14,23.05],[2,2.1,24.47]],"ltp":0.0,"tv":0.0,"id":4596961}]}]}
{"op":"mcm","clk":"1004066277","pt":1580653213832,"mc":[{"id":"1.168224030","rc":[{"batb":[[1,1.69,60.49],[2,1.68,24.78]],"batl":[[0,1.85,42.01],[1,2.3,309.75]],"ltp":0.0,"tv":0.0,"id":8908205},{"batb":[[1,2.18,35.29],[2,2.14,23.05]],"batl":[[0,2.46,28.57],[1,2.84,228.62]],"ltp":0.0,"tv":0.0,"id":4596961}]}]}
{"op":"mcm","clk":"1004069450","pt":1580653229482,"mc":[{"id":"1.168224030","rc":[{"batb":[[0,1.69,60.49],[1,1.68,24.78],[2,1.01,10.51]],"ltp":0.0,"tv":0.0,"id":8908205},{"batb":[[0,2.18,35.29],[1,2.14,23.05],[2,1.01,10.51]],"ltp":0.0,"tv":0.0,"id":4596961}]}]}
{"op":"mcm","clk":"1004069753","pt":1580653230964,"mc":[{"id":"1.168224030","rc":[{"batb":[[0,1.68,24.78],[1,1.01,10.51],[2,1.01,0]],"batl":[[0,2.3,309.75],[1,2.3,0]],"ltp":0.0,"tv":0.0,"id":8908205},{"batb":[[0,2.14,23.05],[1,1.01,10.51],[2,1.01,0]],"batl":[[0,2.84,228.62],[1,2.84,0]],"ltp":0.0,"tv":0.0,"id":4596961}]}]}
{"op":"mcm","clk":"1004071212","pt":1580653238086,"mc":[{"id":"1.168224030","rc":[{"batb":[[0,1.77,20.85],[1,1.73,57.13],[2,1.72,22.74]],"batl":[[0,1.9,42.01],[1,2.3,309.75]],"ltp":0.0,"tv":0.0,"id":8908205},{"batb":[[1,2.12,36.97],[2,2.06,25.49]],"batl":[[0,2.4,29.41],[1,2.84,228.62]],"ltp":0.0,"tv":0.0,"id":4596961}]}]}
{"op":"mcm","clk":"1004074072","pt":1580653252012,"mc":[{"id":"1.168224030","rc":[{"batb":[[0,1.73,57.13],[1,1.72,22.74],[2,1.01,10.51]],"ltp":0.0,"tv":0.0,"id":8908205},{"batb":[[0,2.12,36.97],[1,2.06,25.49],[2,1.01,10.51]],"ltp":0.0,"tv":0.0,"id":4596961}]}]}
{"op":"mcm","clk":"1004074229","pt":1580653252804,"mc":[{"id":"1.168224030","rc":[{"batb":[[0,1.72,22.74],[1,1.01,10.51],[2,1.01,0]],"batl":[[0,2.3,309.75],[1,2.3,0]],"ltp":0.0,"tv":0.0,"id":8908205},{"batb":[[0,2.06,25.49],[1,1.01,10.51],[2,1.01,0]],"batl":[[0,2.84,228.62],[1,2.84,0]],"ltp":0.0,"tv":0.0,"id":4596961}]}]}
{"op":"mcm","clk":"1004078990","pt":1580653275066,"mc":[{"id":"1.168224030","rc":[{"batb":[[0,1.82,18.96],[1,1.77,20.54],[2,1.01,10.51]],"ltp":0.0,"tv":0.0,"id":8908205},{"batb":[[1,2.02,27.38],[2,1.01,10.51]],"ltp":0.0,"tv":0.0,"id":4596961}]}]}
{"op":"mcm","clk":"1004079221","pt":1580653276084,"mc":[{"id":"1.168224030","rc":[{"batb":[[0,1.83,50.41],[1,1.82,18.96],[2,1.77,20.54]],"batl":[[0,2.04,40.33],[1,2.3,309.75]],"ltp":0.0,"tv":0.0,"id":8908205},{"batb":[[2,1.98,42.85]],"batl":[[0,2.2,34.45]],"ltp":0.0,"tv":0.0,"id":4596961}]}]}
{"op":"mcm","clk":"1004079348","pt":1580653276677,"mc":[{"id":"1.168224030","rc":[{"batl":[[0,2.3,309.75],[1,2.3,0]],"ltp":0.0,"tv":0.0,"id":8908205},{"batl":[[1,2.7,245.56]],"ltp":0.0,"tv":0.0,"id":4596961}]}]}
{"op":"mcm","clk":"1004079574","pt":1580653277666,"mc":[{"id":"1.168224030","rc":[{"batl":[[0,2.02,41.17],[1,2.3,309.75]],"ltp":0.0,"tv":0.0,"id":8908205}]}]}
{"op":"mcm","clk":"1004086115","pt":1580653309023,"mc":[{"id":"1.168224030","rc":[{"batb":[[0,1.77,20.54],[1,1.01,10.51],[2,1.77,0]],"batl":[[0,2.3,309.75],[1,2.3,0]],"ltp":0.0,"tv":0.0,"id":8908205},{"batb":[[0,2.02,27.38],[1,1.01,10.51],[2,1.98,0]],"batl":[[0,2.7,245.56],[1,2.7,0]],"ltp":0.0,"tv":0.0,"id":4596961}]}]}
{"op":"mcm","clk":"1004086744","pt":1580653312104,"mc":[{"id":"1.168224030","rc":[{"batb":[[0,1.79,19.91],[1,1.77,20.54],[2,1.01,10.51]],"ltp":0.0,"tv":0.0,"id":8908205},{"batb":[[1,2,28.25],[2,1.01,10.51]],"ltp":0.0,"tv":0.0,"id":4596961}]}]}
{"op":"mcm","clk":"1004086864","pt":1580653312756,"mc":[{"id":"1.168224030","rc":[{"batb":[[1,1.01,10.51],[2,1.01,0]],"ltp":0.0,"tv":0.0,"id":8908205},{"batb":[[0,2,28.25],[1,1.01,10.51],[2,1.01,0]],"ltp":0.0,"tv":0.0,"id":4596961}]}]}
{"op":"mcm","clk":"1004090192","pt":1580653329076,"mc":[{"id":"1.168224030","rc":[{"batb":[[0,1.88,17.15],[1,1.84,49.57],[2,1.83,18.49]],"batl":[[0,2.04,40.33]],"ltp":0.0,"tv":0.0,"id":8908205},{"batb":[[1,1.97,42.85],[2,1.95,30.53]],"ltp":0.0,"tv":0.0,"id":4596961}]}]}
{"op":"mcm","clk":"1004090585","pt":1580653331075,"mc":[{"id":"1.168224030","rc":[{"batl":[[1,2.6,257.57]],"ltp":0.0,"tv":0.0,"id":8908205}]}]}
{"op":"mcm","clk":"1004090648","pt":1580653331404,"mc":[{"id":"1.168224030","rc":[{"batl":[[0,2.18,35.29],[1,2.7,245.56]],"ltp":0.0,"tv":0.0,"id":4596961}]}]}
{"op":"mcm","clk":"1004092580","pt":1580653341384,"mc":[{"id":"1.168224030","rc":[{"batb":[[0,1.83,18.49],[1,1.01,10.51],[2,1.83,0]],"batl":[[0,2.6,257.57],[1,2.6,0]],"ltp":0.0,"tv":0.0,"id":8908205},{"batb":[[0,1.95,30.53],[1,1.01,10.51],[2,1.95,0]],"batl":[[0,2.7,245.56],[1,2.7,0]],"ltp":0.0,"tv":0.0,"id":4596961}]}]}
{"op":"mcm","clk":"1004095472","pt":1580653356081,"mc":[{"id":"1.168224030","rc":[{"batb":[[1,1.8,52.09],[2,1.01,10.51]],"batl":[[0,2,42.01],[1,2.6,257.57]],"ltp":0.0,"tv":0.0,"id":8908205},{"batb":[[0,2,42.01],[1,1.95,30.53],[2,1.01,10.51]],"batl":[[0,2.24,33.61],[1,2.7,245.56]],"ltp":0.0,"tv":0.0,"id":4596961}]}]}
{"op":"mcm","clk":"1004095654","pt":1580653357094,"mc":[{"id":"1.168224030","rc":[{"batb":[[1,1.78,20.46]],"ltp":0.0,"tv":0.0,"id":8908205},{"batb":[[0,2.06,25.89],[1,2,70.34]],"ltp":0.0,"tv":0.0,"id":4596961}]}]}
{"op":"mcm","clk":"1004096030","pt":1580653359081,"mc":[{"id":"1.168224030","rc":[{"batb":[[1,1.81,51.25],[2,1.78,20.46]],"ltp":0.0,"tv":0.0,"id":8908205}]}]}
{"op":"mcm","clk":"1004099733","pt":1580653377944,"mc":[{"id":"1.168224030","rc":[{"batb":[[0,1.81,51.25],[1,1.78,20.46],[2,1.01,10.51]],"ltp":0.0,"tv":0.0,"id":8908205},{"batb":[[0,2,70.34],[1,1.01,10.51],[2,1.01,0]],"ltp":0.0,"tv":0.0,"id":4596961}]}]}
{"op":"mcm","clk":"1004099973","pt":1580653379277,"mc":[{"id":"1.168224030","rc":[{"batb":[[0,1.78,20.46],[1,1.01,10.51],[2,1.01,0]],"batl":[[0,2.6,257.57],[1,2.6,0]],"ltp":0.0,"tv":0.0,"id":8908205},{"batb":[[0,2,28.33]],"batl":[[0,2.7,245.56],[1,2.7,0]],"ltp":0.0,"tv":0.0,"id":4596961}]}]}
{"op":"mcm","clk":"1004100305","pt":1580653380859,"mc":[{"id":"1.168224030","rc":[{"batb":[[0,1.78,20.3]],"ltp":0.0,"tv":0.0,"id":8908205},{"batb":[[0,1.99,28.48]],"ltp":0.0,"tv":0.0,"id":4596961}]}]}
{"op":"mcm","clk":"1004101711","pt":1580653388100,"mc":[{"id":"1.168224030","rc":[{"batb":[[0,1.88,17],[1,1.83,18.65],[2,1.78,20.3]],"ltp":0.0,"tv":0.0,"id":8908205},{"batb":[[1,1.95,30.53],[2,1.01,10.51]],"ltp":0.0,"tv":0.0,"id":4596961}]}]}
{"op":"mcm","clk":"1004101730","pt":1580653388215,"mc":[{"id":"1.168224030","rc":[{"batb":[[1,1.84,49.57],[2,1.83,18.65]],"batl":[[0,2.02,41.17],[1,2.6,257.57]],"ltp":0.0,"tv":0.0,"id":8908205},{"batb":[[0,1.99,70.49]],"batl":[[0,2.22,33.61],[1,2.7,245.56]],"ltp":0.0,"tv":0.0,"id":4596961}]}]}
{"op":"mcm","clk":"1004104423","pt":1580653402828,"mc":[{"id":"1.168224030","rc":[{"batb":[[0,1.84,49.57],[1,1.83,18.65],[2,1.01,10.51]],"ltp":0.0,"tv":0.0,"id":8908205},{"batb":[[0,1.99,42.01]],"ltp":0.0,"tv":0.0,"id":4596961}]}]}
{"op":"mcm","clk":"1004104535","pt":1580653403476,"mc":[{"id":"1.168224030","rc":[{"batb":[[0,1.83,18.65],[1,1.01,10.51],[2,1.01,0]],"batl":[[0,2.6,257.57],[1,2.6,0]],"ltp":0.0,"tv":0.0,"id":8908205},{"batb":[[0,1.95,30.53],[1,1.01,10.51],[2,1.01,0]],"batl":[[0,2.7,245.56],[1,2.7,0]],"ltp":0.0,"tv":0.0,"id":4596961}]}]}
{"op":"mcm","clk":"1004109119","pt":1580653427022,"mc":[{"id":"1.168224030","rc":[{"batl":[[0,2.6,257.57]],"ltp":0.0,"tv":0.0,"id":8908205},{"batl":[[0,2.6,257.57]],"ltp":0.0,"tv":0.0,"id":4596961}]}]}
{"op":"mcm","clk":"1004111315","pt":1580653438032,"mc":[{"id":"1.168224030","rc":[{"batb":[[1,1.77,20.61],[2,1.01,10.51]],"ltp":0.0,"tv":0.0,"id":8908205},{"batb":[[0,2.06,25.89],[1,2,28.4],[2,1.96,445.88]],"ltp":0.0,"tv":0.0,"id":4596961}]}]}
{"op":"mcm","clk":"1004111506","pt":1580653439020,"mc":[{"id":"1.168224030","rc":[{"batb":[[1,1.8,52.09],[2,1.77,20.61]],"batl":[[0,1.99,42.01],[1,2.6,257.57]],"ltp":0.0,"tv":0.0,"id":8908205},{"batb":[[1,2.02,41.17],[2,2,28.4]],"batl":[[0,2.26,32.77],[1,2.6,257.57]],"ltp":0.0,"tv":0.0,"id":4596961}]}]}
{"op":"mcm","clk":"1004115422","pt":1580653457993,"mc":[{"id":"1.168224030","rc":[{"batb":[[0,1.8,52.09],[1,1.77,20.61],[2,1.01,10.51]],"ltp":0.0,"tv":0.0,"id":8908205},{"batb":[[0,2.02,41.17],[1,2,28.4],[2,1.01,10.51]],"ltp":0.0,"tv":0.0,"id":4596961}]}]}
{"op":"mcm","clk":"1004115681","pt":1580653459226,"mc":[{"id":"1.168224030","rc":[{"batb":[[0,1.77,20.61],[1,1.01,10.51],[2,1.01,0]],"batl":[[0,2.6,257.57],[1,2.6,0]],"ltp":0.0,"tv":0.0,"id":8908205},{"batb":[[0,2,28.4],[1,1.01,10.51],[2,1.01,0]],"batl":[[0,2.6,257.57],[1,2.6,0]],"ltp":0.0,"tv":0.0,"id":4596961}]}]}
{"op":"mcm","clk":"1004121820","pt":1580653488069,"mc":[{"id":"1.168224030","rc":[{"batb":[[0,1.88,17.07],[1,1.83,18.73],[2,1.01,10.51]],"ltp":0.0,"tv":0.0,"id":8908205},{"batb":[[1,1.94,15.5],[2,1.01,10.51]],"ltp":0.0,"tv":0.0,"id":4596961}]}]}
{"op":"mcm","clk":"1004121875","pt":1580653488269,"mc":[{"id":"1.168224030","rc":[{"batb":[[2,1.81,51.25]],"batl":[[0,2,42.01],[1,2.6,257.57]],"ltp":0.0,"tv":0.0,"id":8908205},{"batb":[[1,1.99,42.01],[2,1.94,15.5]],"batl":[[0,2.24,33.61],[1,2.6,257.57]],"ltp":0.0,"tv":0.0,"id":4596961}]}]}
{"op":"mcm","clk":"1004126583","pt":1580653510047,"mc":[{"id":"1.168224030","rc":[{"batb":[[0,1.83,18.73],[1,1.81,51.25],[2,1.01,10.51]],"ltp":0.0,"tv":0.0,"id":8908205},{"batb":[[0,1.99,42.01],[1,1.94,15.5],[2,1.01,10.51]],"ltp":0.0,"tv":0.0,"id":4596961}]}]}
{"op":"mcm","clk":"1004126960","pt":1580653511872,"mc":[{"id":"1.168224030","rc":[{"batb":[[1,1.01,10.51],[2,1.01,0]],"batl":[[0,2.6,257.57],[1,2.6,0]],"ltp":0.0,"tv":0.0,"id":8908205},{"batb":[[0,1.94,15.5],[1,1.01,10.51],[2,1.01,0]],"batl":[[0,2.6,257.57],[1,2.6,0]],"ltp":0.0,"tv":0.0,"id":4596961}]}]}
{"op":"mcm","clk":"1004127203","pt":1580653512964,"mc":[{"id":"1.168224030","rc":[{"batb":[[1,1.82,18.8],[2,1.01,10.51]],"ltp":0.0,"tv":0.0,"id":8908205}]}]}
{"op":"mcm","clk":"1004127393","pt":1580653513772,"mc":[{"id":"1.168224030","rc":[{"batb":[[0,1.82,18.8],[1,1.01,10.51],[2,1.01,0]],"ltp":0.0,"tv":0.0,"id":8908205}]}]}
{"op":"mcm","clk":"1004131308","pt":1580653531017,"mc":[{"id":"1.168224030","rc":[{"batb":[[1,1.79,52.93],[2,1.77,20.61]],"batl":[[0,1.97,42.01]],"ltp":0.0,"tv":0.0,"id":8908205},{"batb":[[0,2.06,25.73],[1,2.04,40.33],[2,2,28.01]],"batl":[[0,2.28,32.77],[1,2.6,257.57]],"ltp":0.0,"tv":0.0,"id":4596961}]}]}
{"op":"mcm","clk":"1004131805","pt":1580653533145,"mc":[{"id":"1.168224030","rc":[{"batl":[[1,2.4,289.78]],"ltp":0.0,"tv":0.0,"id":8908205}]}]}
{"op":"mcm","clk":"1004136201","pt":1580653552808,"mc":[{"id":"1.168224030","rc":[{"batb":[[0,1.79,52.93],[1,1.77,20.61],[2,1.01,10.51]],"ltp":0.0,"tv":0.0,"id":8908205},{"batb":[[0,2.04,40.33],[1,2,28.01],[2,1.01,10.51]],"ltp":0.0,"tv":0.0,"id":4596961}]}]}
{"op":"mcm","clk":"1004136306","pt":1580653553314,"mc":[{"id":"1.168224030","rc":[{"batb":[[0,1.77,20.61],[1,1.01,10.51],[2,1.01,0]],"batl":[[0,2.4,289.78],[1,2.4,0]],"ltp":0.0,"tv":0.0,"id":8908205},{"batb":[[0,2,28.01],[1,1.01,10.51],[2,1.01,0]],"batl":[[0,2.6,257.57],[1,2.6,0]],"ltp":0.0,"tv":0.0,"id":4596961}]}]}
{"op":"mcm","clk":"1004138855","pt":1580653565017,"mc":[{"id":"1.168224030","rc":[{"batb":[[1,1.76,54.61],[2,1.71,23.21]],"batl":[[0,1.94,42.01],[1,2.4,289.78]],"ltp":0.0,"tv":0.0,"id":8908205},{"batb":[[0,2.14,23.21],[1,2.08,38.65],[2,2.06,25.34]],"batl":[[0,2.32,31.09],[1,2.6,257.57]],"ltp":0.0,"tv":0.0,"id":4596961}]}]}
{"op":"mcm","clk":"1004142573","pt":1580653581820,"mc":[{"id":"1.168224030","rc":[{"batb":[[0,1.76,54.61],[1,1.71,23.21],[2,1.01,10.51]],"ltp":0.0,"tv":0.0,"id":8908205},{"batb":[[0,2.08,38.65],[1,2.06,25.34],[2,1.01,10.51]],"ltp":0.0,"tv":0.0,"id":4596961}]}]}
{"op":"mcm","clk":"1004142872","pt":1580653583237,"mc":[{"id":"1.168224030","rc":[{"batb":[[0,1.71,23.21],[1,1.01,10.51],[2,1.01,0]],"batl":[[0,2.4,289.78],[1,2.4,0]],"ltp":0.0,"tv":0.0,"id":8908205},{"batb":[[0,2.06,25.34],[1,1.01,10.51],[2,1.01,0]],"batl":[[0,2.6,257.57],[1,2.6,0]],"ltp":0.0,"tv":0.0,"id":4596961}]}]}
{"op":"mcm","clk":"1004143248","pt":1580653585032,"mc":[{"id":"1.168224030","rc":[{"batb":[[0,2.08,25.26]],"ltp":0.0,"tv":0.0,"id":4596961}]}]}
{"op":"mcm","clk":"1004145374","pt":1580653594517,"mc":[{"id":"1.168224030","rc":[{"batb":[[1,1.68,24.71],[2,1.67,62.17]],"batl":[[0,1.84,42.01]],"ltp":0.0,"tv":0.0,"id":8908205},{"batb":[[0,2.22,20.46],[1,2.2,34.45],[2,2.16,22.19]],"ltp":0.0,"tv":0.0,"id":4596961}]}]}
{"op":"mcm","clk":"1004145717","pt":1580653596036,"mc":[{"id":"1.168224030","rc":[{"batl":[[0,2.48,27.73]],"ltp":0.0,"tv":0.0,"id":4596961}]}]}
{"op":"mcm","clk":"1004145954","pt":1580653597119,"mc":[{"id":"1.168224030","rc":[{"batl":[[1,2.3,309.75]],"ltp":0.0,"tv":0.0,"id":8908205},{"batl":[[1,3,213.45]],"ltp":0.0,"tv":0.0,"id":4596961}]}]}
{"op":"mcm","clk":"1004146928","pt":1580653602048,"mc":[{"id":"1.168224030","rc":[{"batb":[[1,1.69,24.08],[2,1.68,24.71]],"ltp":0.0,"tv":0.0,"id":8908205},{"batb":[[0,2.26,19.67],[1,2.22,20.46],[2,2.2,55.77]],"ltp":0.0,"tv":0.0,"id":4596961}]}]}
{"op":"mcm","clk":"1004147089","pt":1580653602861,"mc":[{"id":"1.168224030","rc":[{"batb":[[0,1.69,24.08],[1,1.67,87.67],[2,1.01,10.51]],"ltp":0.0,"tv":0.0,"id":8908205},{"batb":[[1,2.2,55.77],[2,1.01,10.51]],"ltp":0.0,"tv":0.0,"id":4596961}]}]}
{"op":"mcm","clk":"1004148509","pt":1580653610405,"mc":[{"id":"1.168224030","rc":[{"batb":[[1,1.67,62.17],[2,1.66,25.65]],"ltp":0.0,"tv":0.0,"id":8908205},{"batb":[[0,2.26,19.51],[1,2.2,55.61]],"ltp":0.0,"tv":0.0,"id":4596961}]}]}
{"op":"mcm","clk":"1004162598","pt":1580653680529,"mc":[{"id":"1.168224030","rc":[{"batb":[[1,1.66,25.65],[2,1.01,10.51]],"ltp":0.0,"tv":0.0,"id":8908205}]}]}
{"op":"mcm","clk":"1004162844","pt":1580653681743,"mc":[{"id":"1.168224030","rc":[{"batl":[[0,3,213.45],[1,3,0]],"ltp":0.0,"tv":0.0,"id":4596961}]}]}
{"op":"mcm","clk":"1004163094","pt":1580653683020,"mc":[{"id":"1.168224030","rc":[{"batb":[[0,1.66,25.65],[1,1.01,10.51],[2,1.01,0]],"ltp":0.0,"tv":0.0,"id":8908205},{"batb":[[0,2.2,55.61],[1,1.01,10.51],[2,1.01,0]],"ltp":0.0,"tv":0.0,"id":4596961}]}]}
{"op":"mcm","clk":"1004163251","pt":1580653683741,"mc":[{"id":"1.168224030","rc":[{"batl":[[0,2.3,309.75],[1,2.3,0]],"ltp":0.0,"tv":0.0,"id":8908205},{"batb":[[0,2.2,21.17]],"ltp":0.0,"tv":0.0,"id":4596961}]}]}
{"op":"mcm","clk":"1004165081","pt":1580653692053,"mc":[{"id":"1.168224030","rc":[{"batb":[[0,1.73,22.58],[1,1.7,23.84],[2,1.67,242.41]],"ltp":0.0,"tv":0.0,"id":8908205},{"batb":[[1,2.12,23.45],[2,1.01,10.51]],"ltp":0.0,"tv":0.0,"id":4596961}]}]}
{"op":"mcm","clk":"1004165134","pt":1580653692262,"mc":[{"id":"1.168224030","rc":[{"batb":[[1,1.71,58.81],[2,1.7,23.84]],"batl":[[0,1.89,42.01],[1,2.3,309.75]],"ltp":0.0,"tv":0.0,"id":8908205},{"batb":[[1,2.14,36.13],[2,2.12,23.45]],"batl":[[0,2.4,29.41]],"ltp":0.0,"tv":0.0,"id":4596961}]}]}
{"op":"mcm","clk":"1004165684","pt":1580653694960,"mc":[{"id":"1.168224030","rc":[{"batl":[[1,2.84,228.62]],"ltp":0.0,"tv":0.0,"id":4596961}]}]}
{"op":"mcm","clk":"1004167907","pt":1580653706100,"mc":[{"id":"1.168224030","rc":[{"batb":[[0,1.71,58.81],[1,1.7,23.84],[2,1.01,10.51]],"ltp":0.0,"tv":0.0,"id":8908205},{"batb":[[0,2.14,36.13],[1,2.12,23.45],[2,1.01,10.51]],"ltp":0.0,"tv":0.0,"id":4596961}]}]}
{"op":"mcm","clk":"1004168160","pt":1580653707428,"mc":[{"id":"1.168224030","rc":[{"batb":[[0,1.7,23.84],[1,1.01,10.51],[2,1.01,0]],"batl":[[0,2.3,309.75],[1,2.3,0]],"ltp":0.0,"tv":0.0,"id":8908205},{"batb":[[0,2.12,23.45],[1,1.01,10.51],[2,1.01,0]],"batl":[[0,2.84,228.62],[1,2.84,0]],"ltp":0.0,"tv":0.0,"id":4596961}]}]}
{"op":"mcm","clk":"1004168605","pt":1580653709627,"mc":[{"id":"1.168224030","rc":[{"batb":[[0,1.69,24.23]],"ltp":0.0,"tv":0.0,"id":8908205},{"batb":[[0,2.14,23.21]],"ltp":0.0,"tv":0.0,"id":4596961}]}]}
{"op":"mcm","clk":"1004169749","pt":1580653715915,"mc":[{"id":"1.168224030","rc":[{"batb":[[1,1.65,26.12],[2,1.01,10.51]],"ltp":0.0,"tv":0.0,"id":8908205},{"batb":[[0,2.26,19.51],[1,2.2,21.4],[2,1.01,10.51]],"ltp":0.0,"tv":0.0,"id":4596961}]}]}
{"op":"mcm","clk":"1004169889","pt":1580653716610,"mc":[{"id":"1.168224030","rc":[{"batb":[[0,1.7,59.65],[1,1.69,24.23],[2,1.65,26.12]],"batl":[[0,1.87,42.01],[1,2.3,309.75]],"ltp":0.0,"tv":0.0,"id":8908205},{"batb":[[2,2.18,35.29]],"batl":[[0,2.44,28.57],[1,2.84,228.62]],"ltp":0.0,"tv":0.0,"id":4596961}]}]}
{"op":"mcm","clk":"1004172660","pt":1580653730934,"mc":[{"id":"1.168224030","rc":[{"batb":[[1,1.65,26.12],[2,1.01,10.51]],"ltp":0.0,"tv":0.0,"id":8908205},{"batb":[[0,2.2,21.4],[1,2.18,35.29],[2,1.01,10.51]],"ltp":0.0,"tv":0.0,"id":4596961}]}]}
{"op":"mcm","clk":"1004172771","pt":1580653731538,"mc":[{"id":"1.168224030","rc":[{"batb":[[0,1.65,26.12],[1,1.01,10.51],[2,1.01,0]],"batl":[[0,2.3,309.75],[1,2.3,0]],"ltp":0.0,"tv":0.0,"id":8908205},{"batb":[[1,1.01,10.51],[2,1.01,0]],"batl":[[0,2.84,228.62],[1,2.84,0]],"ltp":0.0,"tv":0.0,"id":4596961}]}]}
{"op":"mcm","clk":"1004173977","pt":1580653737799,"mc":[{"id":"1.168224030","rc":[{"batb":[[1,1.62,27.93],[2,1.01,10.51]],"ltp":0.0,"tv":0.0,"id":8908205},{"batb":[[0,2.34,18.02],[1,2.26,19.59],[2,1.01,10.51]],"ltp":0.0,"tv":0.0,"id":4596961}]}]}
{"op":"mcm","clk":"1004174238","pt":1580653739102,"mc":[{"id":"1.168224030","rc":[{"batb":[[0,1.67,62.17],[1,1.65,26.12],[2,1.62,27.93]],"ltp":0.0,"tv":0.0,"id":8908205},{"batb":[[2,2.2,34.45]],"batl":[[0,2.48,27.73],[1,2.84,228.62]],"ltp":0.0,"tv":0.0,"id":4596961}]}]}
{"op":"mcm","clk":"1004174522","pt":1580653740200,"mc":[{"id":"1.168224030","rc":[{"batl":[[0,1.84,42.01],[1,2.3,309.75]],"ltp":0.0,"tv":0.0,"id":8908205}]}]}
{"op":"mcm","clk":"1004176933","pt":1580653751116,"mc":[{"id":"1.168224030","rc":[{"batb":[[1,1.62,27.93],[2,1.01,10.51]],"ltp":0.0,"tv":0.0,"id":8908205},{"batb":[[0,2.26,19.59],[1,2.2,34.45],[2,1.01,10.51]],"ltp":0.0,"tv":0.0,"id":4596961}]}]}
{"op":"mcm","clk":"1004177034","pt":1580653751503,"mc":[{"id":"1.168224030","rc":[{"batb":[[0,1.62,27.93],[1,1.01,10.51],[2,1.01,0]],"batl":[[0,2.3,309.75],[1,2.3,0]],"ltp":0.0,"tv":0.0,"id":8908205},{"batb":[[1,1.01,10.51],[2,1.01,0]],"batl":[[0,2.84,228.62],[1,2.84,0]],"ltp":0.0,"tv":0.0,"id":4596961}]}]}
{"op":"mcm","clk":"1004183388","pt":1580653781608,"mc":[{"id":"1.168224030","rc":[{"batb":[[0,1.62,590.26]],"ltp":0.0,"tv":0.0,"id":8908205}]}]}
{"op":"mcm","clk":"1004183632","pt":1580653782830,"mc":[{"id":"1.168224030","rc":[{"batb":[[0,1.62,27.93]],"ltp":0.0,"tv":0.0,"id":8908205}]}]}
{"op":"mcm","clk":"1004185500","pt":1580653792929,"mc":[{"id":"1.168224030","rc":[{"batb":[[0,1.65,63.85],[1,1.62,27.93],[2,1.59,30.06]],"batl":[[0,1.82,42.01],[1,2.3,309.75]],"ltp":0.0,"tv":0.0,"id":8908205},{"batb":[[0,2.4,16.68],[1,2.32,18.25],[2,2.24,33.61]],"batl":[[0,2.52,26.89]],"ltp":0.0,"tv":0.0,"id":4596961}]}]}
{"op":"mcm","clk":"1004185752","pt":1580653794042,"mc":[{"id":"1.168224030","rc":[{"batl":[[1,3.15,200.42]],"ltp":0.0,"tv":0.0,"id":4596961}]}]}
{"op":"mcm","clk":"1004188819","pt":1580653808808,"mc":[{"id":"1.168224030","rc":[{"batb":[[1,1.59,29.82],[2,1.01,10.51]],"ltp":0.0,"tv":0.0,"id":8908205},{"batb":[[0,2.32,18.25],[1,2.24,33.61],[2,1.01,10.51]],"ltp":0.0,"tv":0.0,"id":4596961}]}]}
{"op":"mcm","clk":"1004189000","pt":1580653810047,"mc":[{"id":"1.168224030","rc":[{"batb":[[0,1.59,29.82],[1,1.01,10.51],[2,1.01,0]],"batl":[[0,2.3,309.75],[1,2.3,0]],"ltp":0.0,"tv":0.0,"id":8908205},{"batb":[[1,1.01,10.51],[2,1.01,0]],"batl":[[0,3.15,200.42],[1,3.15,0]],"ltp":0.0,"tv":0.0,"id":4596961}]}]}
{"op":"mcm","clk":"1004191708","pt":1580653825002,"mc":[{"id":"1.168224030","rc":[{"batb":[[0,1.68,61.33],[1,1.61,251.45],[2,1.59,29.82]],"batl":[[0,1.85,42.01],[1,2.3,309.75]],"ltp":0.0,"tv":0.0,"id":8908205},{"batb":[[1,2.18,35.29],[2,1.01,10.51]],"batl":[[0,2.46,28.57]],"ltp":0.0,"tv":0.0,"id":4596961}]}]}
{"op":"mcm","clk":"1004191897","pt":1580653825975,"mc":[{"id":"1.168224030","rc":[{"batb":[[1,1.66,25.65],[2,1.63,27.54]],"ltp":0.0,"tv":0.0,"id":8908205},{"batb":[[1,2.24,20.06],[2,2.18,35.29]],"ltp":0.0,"tv":0.0,"id":4596961}]}]}
{"op":"mcm","clk":"1004192116","pt":1580653827193,"mc":[{"id":"1.168224030","rc":[{"batl":[[1,3,213.45]],"ltp":0.0,"tv":0.0,"id":4596961}]}]}
{"op":"mcm","clk":"1004195401","pt":1580653845515,"mc":[{"id":"1.168224030","rc":[{"batb":[[0,1.63,27.54],[1,1.01,10.51],[2,1.63,0]],"batl":[[0,2.3,309.75],[1,2.3,0]],"ltp":0.0,"tv":0.0,"id":8908205},{"batb":[[0,2.24,20.06],[1,1.01,10.51],[2,2.18,0]],"batl":[[0,3,213.45],[1,3,0]],"ltp":0.0,"tv":0.0,"id":4596961}]}]}
{"op":"mcm","clk":"1004199420","pt":1580653866859,"mc":[{"id":"1.168224030","rc":[{"batb":[[0,1.65,63.85],[1,1.63,27.54],[2,1.59,29.82]],"batl":[[0,1.81,42.01],[1,2.3,309.75]],"ltp":0.0,"tv":0.0,"id":8908205},{"batb":[[0,2.38,16.92],[1,2.32,18.33],[2,2.24,53.67]],"batl":[[0,2.54,26.89],[1,3,213.45]],"ltp":0.0,"tv":0.0,"id":4596961}]}]}
{"op":"mcm","clk":"1004199595","pt":1580653867838,"mc":[{"id":"1.168224030","rc":[{"batb":[[2,2.24,33.61]],"ltp":0.0,"tv":0.0,"id":4596961}]}]}
{"op":"mcm","clk":"1004204732","pt":1580653892608,"mc":[{"id":"1.168224030","rc":[{"batb":[[1,1.59,29.82],[2,1.01,10.51]],"ltp":0.0,"tv":0.0,"id":8908205},{"batb":[[0,2.32,18.33],[1,2.24,33.61],[2,1.01,10.51]],"ltp":0.0,"tv":0.0,"id":4596961}]}]}
{"op":"mcm","clk":"1004204947","pt":1580653893617,"mc":[{"id":"1.168224030","rc":[{"batb":[[0,1.59,29.82],[1,1.01,10.51],[2,1.01,0]],"batl":[[0,2.3,309.75],[1,2.3,0]],"ltp":0.0,"tv":0.0,"id":8908205},{"batb":[[1,1.01,10.51],[2,1.01,0]],"batl":[[0,3,213.45],[1,3,0]],"ltp":0.0,"tv":0.0,"id":4596961}]}]}
{"op":"mcm","clk":"1004207134","pt":1580653904111,"mc":[{"id":"1.168224030","rc":[{"batb":[[1,1.56,32.26],[2,1.01,10.51]],"ltp":0.0,"tv":0.0,"id":8908205},{"batb":[[0,2.46,15.42],[1,2.38,17.07],[2,1.01,10.51]],"ltp":0.0,"tv":0.0,"id":4596961}]}]}
{"op":"mcm","clk":"1004207272","pt":1580653904807,"mc":[{"id":"1.168224030","rc":[{"batb":[[0,1.63,66.38],[1,1.59,29.82],[2,1.56,32.26]],"batl":[[0,1.79,42.01]],"ltp":0.0,"tv":0.0,"id":8908205},{"batb":[[2,2.28,32.77]],"batl":[[0,2.58,26.05],[1,3,213.45]],"ltp":0.0,"tv":0.0,"id":4596961}]}]}
{"op":"mcm","clk":"1004207722","pt":1580653907060,"mc":[{"id":"1.168224030","rc":[{"batl":[[1,2.16,342.82]],"ltp":0.0,"tv":0.0,"id":8908205}]}]}
{"op":"mcm","clk":"1004207821","pt":1580653907506,"mc":[{"id":"1.168224030","rc":[{"batl":[[0,2.16,342.82],[1,2.16,0]],"ltp":0.0,"tv":0.0,"id":8908205}]}]}
{"op":"mcm","clk":"1004208396","pt":1580653910514,"mc":[{"id":"1.168224030","rc":[{"batl":[[0,1.78,42.01],[1,2.16,342.82]],"ltp":0.0,"tv":0.0,"id":8908205}]}]}
{"op":"mcm","clk":"1004209426","pt":1580653915940,"mc":[{"id":"1.168224030","rc":[{"batb":[[0,1.56,32.26],[1,1.01,10.51],[2,1.56,0]],"batl":[[0,2.16,342.82],[1,2.16,0]],"ltp":0.0,"tv":0.0,"id":8908205},{"batb":[[0,2.38,17.07],[1,1.01,10.51],[2,2.28,0]],"batl":[[0,3,213.45],[1,3,0]],"ltp":0.0,"tv":0.0,"id":4596961}]}]}
{"op":"mcm","clk":"1004209913","pt":1580653918448,"mc":[{"id":"1.168224030","rc":[{"batb":[[0,1.57,31.79]],"ltp":0.0,"tv":0.0,"id":8908205},{"batb":[[0,2.36,17.39]],"ltp":0.0,"tv":0.0,"id":4596961}]}]}
{"op":"mcm","clk":"1004215237","pt":1580653946082,"mc":[{"id":"1.168224030","rc":[{"batb":[[1,1.53,34.62],[2,1.01,10.51]],"ltp":0.0,"tv":0.0,"id":8908205},{"batb":[[0,2.54,14.4],[1,2.44,15.97],[2,2.36,170.93]],"ltp":0.0,"tv":0.0,"id":4596961}]}]}
{"op":"mcm","clk":"1004215370","pt":1580653946788,"mc":[{"id":"1.168224030","rc":[{"batb":[[0,1.61,68.06],[1,1.57,31.79],[2,1.53,34.62]],"ltp":0.0,"tv":0.0,"id":8908205},{"batb":[[2,2.32,31.09]],"batl":[[0,2.64,25.21]],"ltp":0.0,"tv":0.0,"id":4596961}]}]}
{"op":"mcm","clk":"1004215683","pt":1580653948498,"mc":[{"id":"1.168224030","rc":[{"batl":[[1,3.45,180.4]],"ltp":0.0,"tv":0.0,"id":4596961}]}]}
{"op":"mcm","clk":"1004215851","pt":1580653949380,"mc":[{"id":"1.168224030","rc":[{"batl":[[0,1.76,42.01],[1,2.16,342.82]],"ltp":0.0,"tv":0.0,"id":8908205}]}]}
{"op":"mcm","clk":"1004219205","pt":1580653967826,"mc":[{"id":"1.168224030","rc":[{"batb":[[0,1.53,34.62],[1,1.01,10.51],[2,1.53,0]],"batl":[[0,2.16,342.82],[1,2.16,0]],"ltp":0.0,"tv":0.0,"id":8908205},{"batb":[[0,2.44,15.97],[1,1.01,10.51],[2,2.32,0]],"batl":[[0,3.45,180.4],[1,3.45,0]],"ltp":0.0,"tv":0.0,"id":4596961}]}]}
{"op":"mcm","clk":"1004219719","pt":1580653970627,"mc":[{"id":"1.168224030","rc":[{"batb":[[0,1.54,33.91]],"ltp":0.0,"tv":0.0,"id":8908205},{"batb":[[0,2.42,16.37]],"ltp":0.0,"tv":0.0,"id":4596961}]}]}
{"op":"mcm","clk":"1004223597","pt":1580653990850,"mc":[{"id":"1.168224030","rc":[{"batb":[[0,1.59,70.58],[1,1.54,33.91],[2,1.51,36.9]],"batl":[[0,1.74,42.01]],"ltp":0.0,"tv":0.0,"id":8908205},{"batb":[[0,2.6,13.3],[1,2.52,14.71],[2,2.44,165.17]],"batl":[[0,2.7,24.37],[1,3.45,180.4]],"ltp":0.0,"tv":0.0,"id":4596961}]}]}
{"op":"mcm","clk":"1004223839","pt":1580653992054,"mc":[{"id":"1.168224030","rc":[{"batb":[[2,2.38,30.25]],"ltp":0.0,"tv":0.0,"id":4596961}]}]}
{"op":"mcm","clk":"1004224044","pt":1580653993086,"mc":[{"id":"1.168224030","rc":[{"batl":[[1,2.04,383.01]],"ltp":0.0,"tv":0.0,"id":8908205}]}]}
{"op":"mcm","clk":"1004226590","pt":1580654005987,"mc":[{"id":"1.168224030","rc":[{"batb":[[1,1.51,36.9],[2,1.01,10.51]],"ltp":0.0,"tv":0.0,"id":8908205},{"batb":[[0,2.52,14.71],[1,2.38,30.25],[2,1.01,10.51]],"ltp":0.0,"tv":0.0,"id":4596961}]}]}
{"op":"mcm","clk":"1004226997","pt":1580654008039,"mc":[{"id":"1.168224030","rc":[{"batb":[[0,1.51,36.9],[1,1.01,10.51],[2,1.01,0]],"batl":[[0,2.04,383.01],[1,2.04,0]],"ltp":0.0,"tv":0.0,"id":8908205},{"batb":[[1,1.01,10.51],[2,1.01,0]],"batl":[[0,3.45,180.4],[1,3.45,0]],"ltp":0.0,"tv":0.0,"id":4596961}]}]}
{"op":"mcm","clk":"1004227248","pt":1580654009377,"mc":[{"id":"1.168224030","rc":[{"batb":[[0,1.52,35.96]],"ltp":0.0,"tv":0.0,"id":8908205},{"batb":[[0,2.5,15.03]],"ltp":0.0,"tv":0.0,"id":4596961}]}]}
{"op":"mcm","clk":"1004228399","pt":1580654014968,"mc":[{"id":"1.168224030","rc":[{"batb":[[1,1.49,38.95],[2,1.01,10.51]],"ltp":0.0,"tv":0.0,"id":8908205},{"batb":[[0,2.68,12.43],[1,2.58,13.77],[2,2.5,15.03]],"ltp":0.0,"tv":0.0,"id":4596961}]}]}
{"op":"mcm","clk":"1004228612","pt":1580654016043,"mc":[{"id":"1.168224030","rc":[{"batb":[[2,1.01,10.51]],"ltp":0.0,"tv":0.0,"id":4596961}]}]}
{"op":"mcm","clk":"1004228765","pt":1580654016788,"mc":[{"id":"1.168224030","rc":[{"batb":[[0,1.55,75.62],[1,1.52,35.96],[2,1.49,38.95]],"batl":[[0,1.69,42.01],[1,2.04,383.01]],"ltp":0.0,"tv":0.0,"id":8908205},{"batb":[[2,2.48,27.73]],"batl":[[0,2.82,22.69],[1,3.45,180.4]],"ltp":0.0,"tv":0.0,"id":4596961}]}]}
{"op":"mcm","clk":"1004245647","pt":1580654098099,"mc":[{"id":"1.168224030","rc":[{"batb":[[1,1.49,38.95],[2,1.01,10.51]],"ltp":0.0,"tv":0.0,"id":8908205},{"batb":[[0,2.58,13.77],[1,2.48,27.73],[2,1.01,10.51]],"ltp":0.0,"tv":0.0,"id":4596961}]}]}
{"op":"mcm","clk":"1004245973","pt":1580654099614,"mc":[{"id":"1.168224030","rc":[{"batb":[[0,1.49,38.95],[1,1.01,10.51],[2,1.01,0]],"batl":[[0,2.04,383.01],[1,2.04,0]],"ltp":0.0,"tv":0.0,"id":8908205},{"batb":[[1,1.01,10.51],[2,1.01,0]],"batl":[[0,3.45,180.4],[1,3.45,0]],"ltp":0.0,"tv":0.0,"id":4596961}]}]}
{"op":"mcm","clk":"1004248340","pt":1580654110800,"mc":[{"id":"1.168224030","rc":[{"batb":[[0,1.53,78.98],[1,1.49,38.95],[2,1.46,41.86]],"batl":[[0,1.67,42.01],[1,2.04,383.01]],"ltp":0.0,"tv":0.0,"id":8908205},{"batb":[[0,2.78,11.25],[1,2.66,12.67],[2,2.52,26.89]],"batl":[[0,2.88,21.85]],"ltp":0.0,"tv":0.0,"id":4596961}]}]}
{"op":"mcm","clk":"1004248824","pt":1580654112978,"mc":[{"id":"1.168224030","rc":[{"batl":[[1,3.9,158.24]],"ltp":0.0,"tv":0.0,"id":4596961}]}]}
{"op":"mcm","clk":"1004250741","pt":1580654121995,"mc":[{"id":"1.168224030","rc":[{"batb":[[1,1.46,41.86],[2,1.01,10.51]],"ltp":0.0,"tv":0.0,"id":8908205},{"batb":[[0,2.66,12.67],[1,2.52,26.89],[2,1.01,10.51]],"ltp":0.0,"tv":0.0,"id":4596961}]}]}
{"op":"mcm","clk":"1004251119","pt":1580654123911,"mc":[{"id":"1.168224030","rc":[{"batb":[[0,1.46,41.86],[1,1.01,10.51],[2,1.01,0]],"batl":[[0,2.04,383.01],[1,2.04,0]],"ltp":0.0,"tv":0.0,"id":8908205},{"batb":[[1,1.01,10.51],[2,1.01,0]],"batl":[[0,3.9,158.24],[1,3.9,0]],"ltp":0.0,"tv":0.0,"id":4596961}]}]}
{"op":"mcm","clk":"1004252546","pt":1580654130815,"mc":[{"id":"1.168224030","rc":[{"batb":[[0,1.52,80.66],[1,1.46,41.86],[2,1.44,44.69]],"batl":[[0,1.65,42.01],[1,2.04,383.01]],"ltp":0.0,"tv":0.0,"id":8908205},{"batb":[[0,2.86,10.39],[1,2.74,11.64],[2,2.56,26.89]],"batl":[[0,2.92,21.85],[1,3.9,158.24]],"ltp":0.0,"tv":0.0,"id":4596961}]}]}
{"op":"mcm","clk":"1004254918","pt":1580654141916,"mc":[{"id":"1.168224030","rc":[{"batb":[[0,1.44,44.69],[1,1.01,10.51],[2,1.44,0]],"batl":[[0,2.04,383.01],[1,2.04,0]],"ltp":0.0,"tv":0.0,"id":8908205},{"batb":[[0,2.74,11.64],[1,1.01,10.51],[2,2.56,0]],"batl":[[0,3.9,158.24],[1,3.9,0]],"ltp":0.0,"tv":0.0,"id":4596961}]}]}
{"op":"mcm","clk":"1004255552","pt":1580654144925,"mc":[{"id":"1.168224030","rc":[{"batb":[[0,1.44,43.83]],"ltp":0.0,"tv":0.0,"id":8908205},{"batb":[[0,2.72,11.88]],"ltp":0.0,"tv":0.0,"id":4596961}]}]}
{"op":"mcm","clk":"1004257567","pt":1580654155022,"mc":[{"id":"1.168224030","rc":[{"batb":[[0,1.5,84.02],[1,1.44,43.83],[2,1.42,46.74]],"batl":[[0,1.63,42.01]],"ltp":0.0,"tv":0.0,"id":8908205},{"batb":[[0,2.92,24.55],[1,2.82,10.78],[2,2.72,11.88]],"batl":[[0,3,21],[1,3.9,158.24]],"ltp":0.0,"tv":0.0,"id":4596961}]}]}
{"op":"mcm","clk":"1004257685","pt":1580654155678,"mc":[{"id":"1.168224030","rc":[{"batb":[[2,2.62,25.21]],"ltp":0.0,"tv":0.0,"id":4596961}]}]}
{"op":"mcm","clk":"1004258344","pt":1580654159027,"mc":[{"id":"1.168224030","rc":[{"batl":[[0,1.62,42.01],[1,1.89,435.28]],"ltp":0.0,"tv":0.0,"id":8908205}]}]}
{"op":"mcm","clk":"1004259227","pt":1580654162947,"mc":[{"id":"1.168224030","rc":[{"batb":[[1,1.42,46.74],[2,1.01,10.51]],"ltp":0.0,"tv":0.0,"id":8908205},{"batb":[[0,2.82,10.78],[1,2.62,25.21],[2,1.01,10.51]],"ltp":0.0,"tv":0.0,"id":4596961}]}]}
{"op":"mcm","clk":"1004259366","pt":1580654163544,"mc":[{"id":"1.168224030","rc":[{"batb":[[0,1.42,46.74],[1,1.01,10.51],[2,1.01,0]],"batl":[[0,1.89,435.28],[1,1.89,0]],"ltp":0.0,"tv":0.0,"id":8908205},{"batb":[[1,1.01,10.51],[2,1.01,0]],"batl":[[0,3.9,158.24],[1,3.9,0]],"ltp":0.0,"tv":0.0,"id":4596961}]}]}
{"op":"mcm","clk":"1004259874","pt":1580654165943,"mc":[{"id":"1.168224030","rc":[{"batb":[[0,1.43,45.48]],"ltp":0.0,"tv":0.0,"id":8908205},{"batb":[[0,2.78,11.17]],"ltp":0.0,"tv":0.0,"id":4596961}]}]}
{"op":"mcm","clk":"1004262540","pt":1580654178671,"mc":[{"id":"1.168224030","rc":[{"batb":[[0,1.47,171.12],[1,1.46,192.96],[2,1.43,45.48]],"batl":[[0,1.52,264.37],[1,1.53,156.58],[2,1.89,435.28]],"ltp":0.0,"tv":0.0,"id":8908205}]}]}
{"op":"mcm","clk":"1004262759","pt":1580654179744,"mc":[{"id":"1.168224030","rc":[{"batb":[[0,2.98,23.45],[1,2.66,12.59],[2,1.01,10.51]],"ltp":0.0,"tv":0.0,"id":4596961}]}]}
{"op":"mcm","clk":"1004262916","pt":1580654180557,"mc":[{"id":"1.168224030","rc":[{"batb":[[0,1.48,87.38],[1,1.47,171.12],[2,1.46,192.96]],"batl":[[2,1.61,42.01]],"ltp":0.0,"tv":0.0,"id":8908205},{"batb":[[1,2.68,24.37],[2,2.66,12.59]],"batl":[[0,3.05,20.16],[1,3.9,158.24]],"ltp":0.0,"tv":0.0,"id":4596961}]}]}
{"op":"mcm","clk":"1004268531","pt":1580654207997,"mc":[{"id":"1.168224030","rc":[{"batb":[[1,2.96,23.84],[2,2.68,24.37]],"ltp":0.0,"tv":0.0,"id":4596961}]}]}
{"op":"mcm","clk":"1004268628","pt":1580654208525,"mc":[{"id":"1.168224030","rc":[{"batb":[[0,2.96,23.84],[1,2.68,24.37],[2,2.66,12.59]],"ltp":0.0,"tv":0.0,"id":4596961}]}]}
{"op":"mcm","clk":"1004270344","pt":1580654216328,"mc":[{"id":"1.168224030","rc":[{"batb":[[2,2.64,12.83]],"ltp":0.0,"tv":0.0,"id":4596961}]}]}
{"op":"mcm","clk":"1004279012","pt":1580654257630,"mc":[{"id":"1.168224030","rc":[{"batl":[[2,1.89,435.28]],"ltp":0.0,"tv":0.0,"id":8908205},{"batl":[[0,3.9,158.24],[1,3.9,0]],"ltp":0.0,"tv":0.0,"id":4596961}]}]}
{"op":"mcm","clk":"1004279832","pt":1580654261562,"mc":[{"id":"1.168224030","rc":[{"batl":[[2,1.59,42.01]],"ltp":0.0,"tv":0.0,"id":8908205},{"batb":[[0,2.98,23.68],[2,2.66,12.67]],"batl":[[0,3.1,19.32],[1,3.9,158.24]],"ltp":0.0,"tv":0.0,"id":4596961}]}]}
{"op":"mcm","clk":"1004280452","pt":1580654264358,"mc":[{"id":"1.168224030","rc":[{"batb":[[0,1.47,171.12],[1,1.46,192.96],[2,1.43,45.16]],"ltp":0.0,"tv":0.0,"id":8908205},{"batb":[[1,2.66,12.67],[2,1.01,10.51]],"ltp":0.0,"tv":0.0,"id":4596961}]}]}
{"op":"mcm","clk":"1004280825","pt":1580654266263,"mc":[{"id":"1.168224030","rc":[{"batb":[[0,2.98,23.45],[1,2.66,12.51]],"ltp":0.0,"tv":0.0,"id":4596961}]}]}
{"op":"mcm","clk":"1004281011","pt":1580654267135,"mc":[{"id":"1.168224030","rc":[{"batb":[[0,1.47,260.18]],"ltp":0.0,"tv":0.0,"id":8908205},{"batb":[[1,2.74,23.53],[2,2.66,12.51]],"ltp":0.0,"tv":0.0,"id":4596961}]}]}
{"op":"mcm","clk":"1004293055","pt":1580654327083,"mc":[{"id":"1.168224030","rc":[{"batb":[[0,1.47,89.06],[1,1.35,58.22],[2,1.01,10.51]],"batl":[[0,1.59,42.01],[1,1.89,435.28],[2,1.59,0]],"ltp":0.0,"tv":0.0,"id":8908205},{"batb":[[0,2.74,23.53],[1,2.66,12.51],[2,1.01,10.51]],"ltp":0.0,"tv":0.0,"id":4596961}]}]}
{"op":"mcm","clk":"1004293154","pt":1580654327626,"mc":[{"id":"1.168224030","rc":[{"batb":[[0,1.35,58.22],[1,1.01,10.51],[2,1.01,0]],"batl":[[0,1.89,435.28],[1,1.89,0]],"ltp":0.0,"tv":0.0,"id":8908205},{"batb":[[0,2.66,12.51],[1,1.01,10.51],[2,1.01,0]],"batl":[[0,3.9,158.24],[1,3.9,0]],"ltp":0.0,"tv":0.0,"id":4596961}]}]}
{"op":"mcm","clk":"1004293569","pt":1580654329732,"mc":[{"id":"1.168224030","rc":[{"batb":[[0,1.36,58.15]],"ltp":0.0,"tv":0.0,"id":8908205}]}]}
{"op":"mcm","clk":"1004293906","pt":1580654331559,"mc":[{"id":"1.168224030","rc":[{"batb":[[0,1.45,202.97],[1,1.44,204.88],[2,1.36,58.15]],"batl":[[0,1.5,275.95],[1,1.51,164.63],[2,1.89,435.28]],"ltp":0.0,"tv":0.0,"id":8908205}]}]}
{"op":"mcm","clk":"1004294185","pt":1580654332853,"mc":[{"id":"1.168224030","rc":[{"batb":[[0,1.36,58.15],[1,1.01,10.51],[2,1.36,0]],"batl":[[0,1.89,435.28],[1,1.51,0],[2,1.89,0]],"ltp":0.0,"tv":0.0,"id":8908205}]}]}
{"op":"mcm","clk":"1004294728","pt":1580654335858,"mc":[{"id":"1.168224030","rc":[{"batb":[[0,1.38,169.75],[1,1.37,256.6],[2,1.36,58.15]],"batl":[[0,1.61,176.85],[1,1.62,127],[2,1.89,435.28]],"ltp":0.0,"tv":0.0,"id":8908205}]}]}
{"op":"mcm","clk":"1004295623","pt":1580654340044,"mc":[{"id":"1.168224030","rc":[{"batb":[[0,1.36,58.15],[1,1.01,10.51],[2,1.36,0]],"ltp":0.0,"tv":0.0,"id":8908205}]}]}
{"op":"mcm","clk":"1004296234","pt":1580654343061,"mc":[{"id":"1.168224030","rc":[{"batb":[[0,1.55,259.58],[1,1.54,155.65],[2,1.36,58.15]],"ltp":0.0,"tv":0.0,"id":8908205}]}]}
{"op":"mcm","clk":"1004296368","pt":1580654343750,"mc":[{"id":"1.168224030","rc":[{"batb":[[2,1.52,35.25]],"ltp":0.0,"tv":0.0,"id":8908205},{"batb":[[1,2.38,16.92],[2,1.01,10.51]],"ltp":0.0,"tv":0.0,"id":4596961}]}]}
{"op":"mcm","clk":"1004296546","pt":1580654344567,"mc":[{"id":"1.168224030","rc":[{"batb":[[2,1.52,115.91]],"batl":[[2,1.65,42.01]],"ltp":0.0,"tv":0.0,"id":8908205},{"batl":[[0,2.92,21.85]],"ltp":0.0,"tv":0.0,"id":4596961}]}]}
{"op":"mcm","clk":"1004296986","pt":1580654346871,"mc":[{"id":"1.168224030","rc":[{"batb":[[2,1.52,35.25]],"ltp":0.0,"tv":0.0,"id":8908205},{"batl":[[0,3.65,170.41]],"ltp":0.0,"tv":0.0,"id":4596961}]}]}
{"op":"mcm","clk":"1004297561","pt":1580654349784,"mc":[{"id":"1.168224030","rc":[{"batb":[[2,1.53,78.98]],"ltp":0.0,"tv":0.0,"id":8908205},{"batb":[[1,2.54,26.89],[2,2.38,16.92]],"batl":[[0,2.9,21.85],[1,3.65,170.41]],"ltp":0.0,"tv":0.0,"id":4596961}]}]}
{"op":"mcm","clk":"1004298626","pt":1580654355092,"mc":[{"id":"1.168224030","rc":[{"batb":[[0,1.53,78.98],[1,1.52,35.25],[2,1.43,45.16]],"batl":[[0,1.65,42.01],[1,1.89,435.28],[2,1.65,0]],"ltp":0.0,"tv":0.0,"id":8908205}]}]}
{"op":"mcm","clk":"1004298863","pt":1580654356077,"mc":[{"id":"1.168224030","rc":[{"batb":[[0,1.43,45.16],[1,1.01,10.51],[2,1.43,0]],"batl":[[0,1.89,435.28],[1,1.89,0]],"ltp":0.0,"tv":0.0,"id":8908205},{"batb":[[0,2.38,16.92],[1,1.01,10.51],[2,2.38,0]],"batl":[[0,3.65,170.41],[1,3.65,0]],"ltp":0.0,"tv":0.0,"id":4596961}]}]}
{"op":"mcm","clk":"1004299309","pt":1580654358114,"mc":[{"id":"1.168224030","rc":[{"batb":[[0,1.46,209.47],[1,1.45,198.9],[2,1.43,45.16]],"batl":[[0,1.7,116.69],[1,1.72,207.89],[2,1.89,435.28]],"ltp":0.0,"tv":0.0,"id":8908205}]}]}
{"op":"mcm","clk":"1004301922","pt":1580654370910,"mc":[{"id":"1.168224030","rc":[{"batb":[[0,1.43,45.16],[1,1.01,10.51],[2,1.43,0]],"ltp":0.0,"tv":0.0,"id":8908205}]}]}
{"op":"mcm","clk":"1004302435","pt":1580654373097,"mc":[{"id":"1.168224030","rc":[{"batl":[[2,1.89,0]],"ltp":0.0,"tv":0.0,"id":8908205}]}]}
{"op":"mcm","clk":"1004302645","pt":1580654374016,"mc":[{"id":"1.168224030","rc":[{"batb":[[0,1.64,187.94],[1,1.63,153],[2,1.54,34.23]],"ltp":0.0,"tv":0.0,"id":8908205},{"batb":[[1,2.2,21.01],[2,1.01,10.51]],"ltp":0.0,"tv":0.0,"id":4596961}]}]}
{"op":"mcm","clk":"1004302857","pt":1580654375058,"mc":[{"id":"1.168224030","rc":[{"batb":[[2,1.58,72.26]],"batl":[[1,1.72,249.9]],"ltp":0.0,"tv":0.0,"id":8908205},{"batb":[[0,2.38,47.16]],"batl":[[0,2.72,24.37]],"ltp":0.0,"tv":0.0,"id":4596961}]}]}
{"op":"mcm","clk":"1004303228","pt":1580654376927,"mc":[{"id":"1.168224030","rc":[{"batl":[[2,2.16,342.82]],"ltp":0.0,"tv":0.0,"id":8908205},{"batl":[[1,3.3,191.92]],"ltp":0.0,"tv":0.0,"id":4596961}]}]}
{"op":"mcm","clk":"1004303826","pt":1580654379928,"mc":[{"id":"1.168224030","rc":[{"batb":[[0,1.63,27.7],[1,1.58,72.26],[2,1.54,34.23]],"batl":[[0,1.72,42.01],[1,2.16,342.82],[2,2.16,0]],"ltp":0.0,"tv":0.0,"id":8908205}]}]}
{"op":"mcm","clk":"1004303945","pt":1580654380511,"mc":[{"id":"1.168224030","rc":[{"batb":[[0,1.58,72.26],[1,1.54,34.23],[2,1.01,10.51]],"ltp":0.0,"tv":0.0,"id":8908205},{"batb":[[0,2.38,30.25]],"ltp":0.0,"tv":0.0,"id":4596961}]}]}
{"op":"mcm","clk":"1004304178","pt":1580654381649,"mc":[{"id":"1.168224030","rc":[{"batb":[[0,1.54,34.23],[1,1.01,10.51],[2,1.01,0]],"batl":[[0,2.16,342.82],[1,2.16,0]],"ltp":0.0,"tv":0.0,"id":8908205},{"batb":[[0,2.2,21.01],[1,1.01,10.51],[2,1.01,0]],"batl":[[0,3.3,191.92],[1,3.3,0]],"ltp":0.0,"tv":0.0,"id":4596961}]}]}
{"op":"mcm","clk":"1004304986","pt":1580654385635,"mc":[{"id":"1.168224030","rc":[{"batb":[[0,1.62,229.16],[1,1.61,131.26],[2,1.54,34.23]],"batl":[[0,1.69,211.5],[1,1.71,211.52],[2,2.16,342.82]],"ltp":0.0,"tv":0.0,"id":8908205}]}]}
{"op":"mcm","clk":"1004305505","pt":1580654388059,"mc":[{"id":"1.168224030","rc":[{"batb":[[0,1.54,34.23],[1,1.01,10.51],[2,1.54,0]],"batl":[[0,2.16,342.82],[1,1.71,0],[2,2.16,0]],"ltp":0.0,"tv":0.0,"id":8908205}]}]}
{"op":"mcm","clk":"1004306122","pt":1580654391033,"mc":[{"id":"1.168224030","rc":[{"batb":[[0,1.56,176.98],[1,1.55,151.38],[2,1.54,34.23]],"batl":[[0,1.78,131.48],[1,1.8,178.88],[2,2.16,342.82]],"ltp":0.0,"tv":0.0,"id":8908205}]}]}
{"op":"mcm","clk":"1004306873","pt":1580654395034,"mc":[{"id":"1.168224030","rc":[{"batb":[[0,1.54,34.23],[1,1.01,10.51],[2,1.54,0]],"ltp":0.0,"tv":0.0,"id":8908205}]}]}
{"op":"mcm","clk":"1004307489","pt":1580654397953,"mc":[{"id":"1.168224030","rc":[{"batb":[[0,1.72,22.74],[1,1.71,191.86],[2,1.69,218.84]],"ltp":0.0,"tv":0.0,"id":8908205},{"batb":[[1,2.1,24.08],[2,1.01,10.51]],"ltp":0.0,"tv":0.0,"id":4596961}]}]}
{"op":"mcm","clk":"1004307710","pt":1580654398954,"mc":[{"id":"1.168224030","rc":[{"batl":[[0,1.78,173.49]],"ltp":0.0,"tv":0.0,"id":8908205},{"batb":[[0,2.28,32.77],[1,2.2,21.01],[2,2.1,24.08]],"batl":[[0,2.6,26.05]],"ltp":0.0,"tv":0.0,"id":4596961}]}]}
{"op":"mcm","clk":"1004308078","pt":1580654400786,"mc":[{"id":"1.168224030","rc":[{"batl":[[1,3,213.45]],"ltp":0.0,"tv":0.0,"id":4596961}]}]}
{"op":"mcm","clk":"1004308267","pt":1580654401776,"mc":[{"id":"1.168224030","rc":[{"batl":[[0,3,213.45],[1,3,0]],"ltp":0.0,"tv":0.0,"id":4596961}]}]}
{"op":"mcm","clk":"1004308923","pt":1580654404762,"mc":[{"id":"1.168224030","rc":[{"batl":[[0,2.58,26.05],[1,3,213.45]],"ltp":0.0,"tv":0.0,"id":4596961}]}]}
{"op":"mcm","clk":"1004310202","pt":1580654411076,"mc":[{"id":"1.168224030","rc":[{"batb":[[1,1.65,26.12],[2,1.63,66.38]],"batl":[[0,1.78,42.01],[1,2.16,342.82],[2,2.16,0]],"ltp":0.0,"tv":0.0,"id":8908205}]}]}
{"op":"mcm","clk":"1004310318","pt":1580654411663,"mc":[{"id":"1.168224030","rc":[{"batb":[[0,1.65,26.12],[1,1.01,10.51],[2,1.63,0]],"batl":[[0,2.16,342.82],[1,2.16,0]],"ltp":0.0,"tv":0.0,"id":8908205},{"batb":[[0,2.1,24.08],[1,1.01,10.51],[2,2.1,0]],"batl":[[0,3,213.45],[1,3,0]],"ltp":0.0,"tv":0.0,"id":4596961}]}]}
{"op":"mcm","clk":"1004310804","pt":1580654414074,"mc":[{"id":"1.168224030","rc":[{"batb":[[0,1.66,167.36],[1,1.65,145.94],[2,1.63,27.77]],"batl":[[0,1.83,148.55],[1,1.85,163.86],[2,2.16,342.82]],"ltp":0.0,"tv":0.0,"id":8908205},{"batb":[[0,2.16,22.42],[1,2.1,24.08],[2,1.01,10.51]],"ltp":0.0,"tv":0.0,"id":4596961}]}]}
{"op":"mcm","clk":"1004310946","pt":1580654414681,"mc":[{"id":"1.168224030","rc":[{"batb":[[0,1.63,27.77],[1,1.01,10.51],[2,1.63,0]],"batl":[[0,2.16,342.82],[1,1.85,0],[2,2.16,0]],"ltp":0.0,"tv":0.0,"id":8908205},{"batb":[[1,1.01,10.51],[2,1.01,0]],"ltp":0.0,"tv":0.0,"id":4596961}]}]}
{"op":"mcm","clk":"1004311669","pt":1580654418078,"mc":[{"id":"1.168224030","rc":[{"batb":[[0,1.7,184.44],[1,1.68,223.42],[2,1.63,27.77]],"batl":[[0,1.77,149.61],[1,1.79,182.08],[2,2.16,342.82]],"ltp":0.0,"tv":0.0,"id":8908205}]}]}
{"op":"mcm","clk":"1004311711","pt":1580654418285,"mc":[{"id":"1.168224030","rc":[{"batb":[[0,1.63,27.77],[1,1.01,10.51],[2,1.63,0]],"batl":[[0,2.16,342.82],[1,1.79,0],[2,2.16,0]],"ltp":0.0,"tv":0.0,"id":8908205}]}]}
{"op":"mcm","clk":"1004312381","pt":1580654421478,"mc":[{"id":"1.168224030","rc":[{"batb":[[0,1.66,167.36],[1,1.65,119.82],[2,1.63,27.77]],"batl":[[0,1.83,148.55],[1,1.85,163.86],[2,2.16,342.82]],"ltp":0.0,"tv":0.0,"id":8908205}]}]}
{"op":"mcm","clk":"1004312712","pt":1580654423066,"mc":[{"id":"1.168224030","rc":[{"batb":[[2,1.01,10.51]],"batl":[[0,2.16,342.82],[1,1.85,0],[2,2.16,0]],"ltp":0.0,"tv":0.0,"id":8908205}]}]}
{"op":"mcm","clk":"1004313304","pt":1580654426098,"mc":[{"id":"1.168224030","rc":[{"batl":[[0,1.72,113.28],[1,1.74,199.98],[2,2.16,342.82]],"ltp":0.0,"tv":0.0,"id":8908205}]}]}
{"op":"mcm","clk":"1004313429","pt":1580654426702,"mc":[{"id":"1.168224030","rc":[{"batb":[[2,1.62,27.85]],"batl":[[2,1.76,42.01]],"ltp":0.0,"tv":0.0,"id":8908205},{"batb":[[0,2.4,16.76],[1,2.32,31.09],[2,2.22,20.93]],"batl":[[0,2.66,25.21],[1,3,213.45]],"ltp":0.0,"tv":0.0,"id":4596961}]}]}
{"op":"mcm","clk":"1004316352","pt":1580654441093,"mc":[{"id":"1.168224030","rc":[{"batb":[[0,1.6,69.74],[1,1.54,33.99],[2,1.01,10.51]],"batl":[[0,1.76,42.01],[1,2.16,342.82],[2,1.76,0]],"ltp":0.0,"tv":0.0,"id":8908205},{"batb":[[0,2.32,31.09],[1,2.22,20.93],[2,1.01,10.51]],"ltp":0.0,"tv":0.0,"id":4596961}]}]}
{"op":"mcm","clk":"1004316486","pt":1580654441696,"mc":[{"id":"1.168224030","rc":[{"batb":[[0,1.54,33.99],[1,1.01,10.51],[2,1.01,0]],"batl":[[0,2.16,342.82],[1,2.16,0]],"ltp":0.0,"tv":0.0,"id":8908205},{"batb":[[0,2.22,20.93],[1,1.01,10.51],[2,1.01,0]],"batl":[[0,3,213.45],[1,3,0]],"ltp":0.0,"tv":0.0,"id":4596961}]}]}
{"op":"mcm","clk":"1004317480","pt":1580654446896,"mc":[{"id":"1.168224030","rc":[{"batb":[[0,1.64,209.75],[1,1.63,125.36],[2,1.54,33.99]],"batl":[[0,1.71,200.85],[1,1.73,203.46],[2,2.16,342.82]],"ltp":0.0,"tv":0.0,"id":8908205}]}]}
{"op":"mcm","clk":"1004317763","pt":1580654447837,"mc":[{"id":"1.168224030","rc":[{"batb":[[0,1.54,33.99],[1,1.01,10.51],[2,1.54,0]],"batl":[[0,2.16,342.82],[1,1.73,0],[2,2.16,0]],"ltp":0.0,"tv":0.0,"id":8908205}]}]}
{"op":"mcm","clk":"1004318467","pt":1580654451041,"mc":[{"id":"1.168224030","rc":[{"batb":[[0,1.58,172.52],[1,1.57,144.06],[2,1.54,33.99]],"ltp":0.0,"tv":0.0,"id":8908205}]}]}
{"op":"mcm","clk":"1004318898","pt":1580654453038,"mc":[{"id":"1.168224030","rc":[{"batl":[[0,1.64,211],[1,1.65,118.88]],"ltp":0.0,"tv":0.0,"id":8908205}]}]}
{"op":"mcm","clk":"1004319077","pt":1580654453806,"mc":[{"id":"1.168224030","rc":[{"batb":[[0,2.6,13.3],[1,2.28,19.36],[2,1.01,10.51]],"ltp":0.0,"tv":0.0,"id":4596961}]}]}
{"op":"mcm","clk":"1004319231","pt":1580654454606,"mc":[{"id":"1.168224030","rc":[{"batb":[[2,1.55,75.62]],"batl":[[2,1.69,42.01]],"ltp":0.0,"tv":0.0,"id":8908205},{"batb":[[1,2.44,28.57],[2,2.28,19.36]],"batl":[[0,2.8,22.69]],"ltp":0.0,"tv":0.0,"id":4596961}]}]}
{"op":"mcm","clk":"1004319391","pt":1580654455323,"mc":[{"id":"1.168224030","rc":[{"batl":[[1,3.65,170.41]],"ltp":0.0,"tv":0.0,"id":4596961}]}]}
{"op":"mcm","clk":"1004321873","pt":1580654467121,"mc":[{"id":"1.168224030","rc":[{"batb":[[0,1.55,75.62],[1,1.42,47.76],[2,1.01,10.51]],"batl":[[0,1.69,42.01],[1,2.04,383.01],[2,1.69,0]],"ltp":0.0,"tv":0.0,"id":8908205},{"batb":[[0,2.44,28.57],[1,2.28,19.36],[2,1.01,10.51]],"ltp":0.0,"tv":0.0,"id":4596961}]}]}
{"op":"mcm","clk":"1004321994","pt":1580654467624,"mc":[{"id":"1.168224030","rc":[{"batb":[[0,1.42,47.76],[1,1.01,10.51],[2,1.01,0]],"batl":[[0,2.04,383.01],[1,2.04,0]],"ltp":0.0,"tv":0.0,"id":8908205},{"batb":[[0,2.28,19.36],[1,1.01,10.51],[2,1.01,0]],"batl":[[0,3.65,170.41],[1,3.65,0]],"ltp":0.0,"tv":0.0,"id":4596961}]}]}
{"op":"mcm","clk":"1004322523","pt":1580654470050,"mc":[{"id":"1.168224030","rc":[{"batb":[[1,2.26,19.67],[2,1.01,10.51]],"ltp":0.0,"tv":0.0,"id":4596961}]}]}
{"op":"mcm","clk":"1004322563","pt":1580654470220,"mc":[{"id":"1.168224030","rc":[{"batb":[[0,1.42,47.29]],"ltp":0.0,"tv":0.0,"id":8908205},{"batb":[[0,2.26,19.67],[1,1.01,10.51],[2,1.01,0]],"ltp":0.0,"tv":0.0,"id":4596961}]}]}
{"op":"mcm","clk":"1004323189","pt":1580654473061,"mc":[{"id":"1.168224030","rc":[{"batb":[[0,1.55,206.93],[1,1.54,155.39],[2,1.42,47.29]],"batl":[[0,1.61,226.11],[1,1.62,126.79],[2,2.04,383.01]],"ltp":0.0,"tv":0.0,"id":8908205}]}]}
{"op":"mcm","clk":"1004323560","pt":1580654474871,"mc":[{"id":"1.168224030","rc":[{"batb":[[0,1.42,47.29],[1,1.01,10.51],[2,1.42,0]],"batl":[[0,2.04,383.01],[1,1.62,0],[2,2.04,0]],"ltp":0.0,"tv":0.0,"id":8908205}]}]}
{"op":"mcm","clk":"1004324469","pt":1580654479077,"mc":[{"id":"1.168224030","rc":[{"batb":[[0,1.45,184.91],[1,1.44,204.73],[2,1.42,47.29]],"batl":[[0,1.77,115.03],[1,1.79,182.16],[2,2.04,383.01]],"ltp":0.0,"tv":0.0,"id":8908205}]}]}
{"op":"mcm","clk":"1004325448","pt":1580654483750,"mc":[{"id":"1.168224030","rc":[{"batl":[[0,2.04,383.01],[1,1.79,0],[2,2.04,0]],"ltp":0.0,"tv":0.0,"id":8908205}]}]}
{"op":"mcm","clk":"1004326065","pt":1580654486892,"mc":[{"id":"1.168224030","rc":[{"batl":[[0,1.5,292.71],[1,1.51,164.51]],"ltp":0.0,"tv":0.0,"id":8908205}]}]}
{"op":"mcm","clk":"1004326244","pt":1580654487670,"mc":[{"id":"1.168224030","rc":[{"batb":[[0,3.05,22.35],[1,2.58,13.69],[2,1.01,10.51]],"ltp":0.0,"tv":0.0,"id":4596961}]}]}
{"op":"mcm","clk":"1004326460","pt":1580654488683,"mc":[{"id":"1.168224030","rc":[{"batb":[[0,1.46,90.74],[1,1.45,184.91],[2,1.44,204.73]],"batl":[[2,1.57,42.01]],"ltp":0.0,"tv":0.0,"id":8908205},{"batb":[[1,2.74,23.53],[2,2.58,13.69]],"batl":[[0,3.2,18.48]],"ltp":0.0,"tv":0.0,"id":4596961}]}]}
{"op":"mcm","clk":"1004326645","pt":1580654489553,"mc":[{"id":"1.168224030","rc":[{"batl":[[1,4.2,148.03]],"ltp":0.0,"tv":0.0,"id":4596961}]}]}
{"op":"mcm","clk":"1004328884","pt":1580654499979,"mc":[{"id":"1.168224030","rc":[{"batb":[[0,1.31,67.98],[1,1.01,10.51],[2,1.44,0]],"batl":[[0,1.89,435.28],[1,1.51,0],[2,1.57,0]],"ltp":0.0,"tv":0.0,"id":8908205},{"batb":[[0,2.58,13.69],[1,1.01,10.51],[2,2.58,0]],"batl":[[0,4.2,148.03],[1,4.2,0]],"ltp":0.0,"tv":0.0,"id":4596961}]}]}
{"op":"mcm","clk":"1004329523","pt":1580654503072,"mc":[{"id":"1.168224030","rc":[{"batb":[[0,1.32,247.81],[1,1.31,390.52],[2,1.01,10.51]],"batl":[[0,1.64,226.44],[1,1.65,118.83],[2,1.89,435.28]],"ltp":0.0,"tv":0.0,"id":8908205}]}]}
{"op":"mcm","clk":"1004334469","pt":1580654526928,"mc":[{"id":"1.168224030","rc":[{"batb":[[0,1.31,67.98],[1,1.01,10.51],[2,1.01,0]],"ltp":0.0,"tv":0.0,"id":8908205}]}]}
{"op":"mcm","clk":"1004335135","pt":1580654530012,"mc":[{"id":"1.168224030","rc":[{"batb":[[0,1.58,156.14],[1,1.57,143.99],[2,1.31,67.98]],"ltp":0.0,"tv":0.0,"id":8908205}]}]}
{"op":"mcm","clk":"1004335301","pt":1580654530727,"mc":[{"id":"1.168224030","rc":[{"batb":[[2,1.55,108.74]],"batl":[[2,1.68,42.01]],"ltp":0.0,"tv":0.0,"id":8908205},{"batb":[[1,2.48,27.73],[2,2.24,20.14]],"batl":[[0,2.82,22.69]],"ltp":0.0,"tv":0.0,"id":4596961}]}]}
{"op":"mcm","clk":"1004335772","pt":1580654532816,"mc":[{"id":"1.168224030","rc":[{"batl":[[1,3.65,170.41]],"ltp":0.0,"tv":0.0,"id":4596961}]}]}
{"op":"mcm","clk":"1004339672","pt":1580654549854,"mc":[{"id":"1.168224030","rc":[{"batl":[[2,3.9,309.12]],"ltp":0.0,"tv":0.0,"id":4596961}]}]}
{"op":"mcm","clk":"1004339840","pt":1580654550635,"mc":[{"id":"1.168224030","rc":[{"batb":[[0,1.55,75.62],[1,1.43,46.03],[2,1.01,10.51]],"batl":[[0,1.68,42.01],[1,1.89,435.28],[2,1.68,0]],"ltp":0.0,"tv":0.0,"id":8908205},{"batb":[[0,2.48,27.73],[1,2.24,20.14],[2,1.01,10.51]],"batl":[[2,3.9,0]],"ltp":0.0,"tv":0.0,"id":4596961}]}]}
{"op":"mcm","clk":"1004340034","pt":1580654551653,"mc":[{"id":"1.168224030","rc":[{"batb":[[0,1.43,46.03],[1,1.01,10.51],[2,1.01,0]],"batl":[[0,1.89,435.28],[1,1.89,0]],"ltp":0.0,"tv":0.0,"id":8908205},{"batb":[[0,2.24,20.14],[1,1.01,10.51],[2,1.01,0]],"batl":[[0,3.65,170.41],[1,3.65,0]],"ltp":0.0,"tv":0.0,"id":4596961}]}]}
{"op":"mcm","clk":"1004340537","pt":1580654553855,"mc":[{"id":"1.168224030","rc":[{"batb":[[0,1.45,165.04],[1,1.44,204.58],[2,1.43,46.03]],"batl":[[0,1.77,127.11],[1,1.79,182.12],[2,1.89,435.28]],"ltp":0.0,"tv":0.0,"id":8908205}]}]}
{"op":"mcm","clk":"1004341050","pt":1580654556166,"mc":[{"id":"1.168224030","rc":[{"batl":[[0,1.89,435.28],[1,1.79,0],[2,1.89,0]],"ltp":0.0,"tv":0.0,"id":8908205}]}]}
{"op":"mcm","clk":"1004341938","pt":1580654560078,"mc":[{"id":"1.168224030","rc":[{"batl":[[0,1.49,142.26],[1,1.5,169.93],[2,1.89,435.28]],"ltp":0.0,"tv":0.0,"id":8908205},{"batb":[[0,3,23.05],[1,2.56,14.08],[2,2.24,20.14]],"ltp":0.0,"tv":0.0,"id":4596961}]}]}
{"op":"mcm","clk":"1004342067","pt":1580654560669,"mc":[{"id":"1.168224030","rc":[{"batb":[[0,1.45,258.3]],"batl":[[2,1.57,42.01]],"ltp":0.0,"tv":0.0,"id":8908205},{"batb":[[1,2.74,23.53],[2,2.56,14.08]],"batl":[[0,3.2,18.48]],"ltp":0.0,"tv":0.0,"id":4596961}]}]}
{"op":"mcm","clk":"1004342371","pt":1580654562084,"mc":[{"id":"1.168224030","rc":[{"batl":[[1,4.2,148.03]],"ltp":0.0,"tv":0.0,"id":4596961}]}]}
{"op":"mcm","clk":"1004344684","pt":1580654572070,"mc":[{"id":"1.168224030","rc":[{"batb":[[0,1.32,66.88],[1,1.01,10.51],[2,1.43,0]],"batl":[[0,1.89,435.28],[1,1.5,0],[2,1.57,0]],"ltp":0.0,"tv":0.0,"id":8908205},{"batb":[[0,2.56,14.08],[1,1.01,10.51],[2,2.56,0]],"batl":[[0,4.2,148.03],[1,4.2,0]],"ltp":0.0,"tv":0.0,"id":4596961}]}]}
{"op":"mcm","clk":"1004345803","pt":1580654576868,"mc":[{"id":"1.168224030","rc":[{"batb":[[0,1.42,217.08],[1,1.41,225.01],[2,1.32,66.88]],"batl":[[0,1.46,150.22],[1,1.47,184.31],[2,1.89,435.28]],"ltp":0.0,"tv":0.0,"id":8908205}]}]}
{"op":"mcm","clk":"1004346294","pt":1580654578905,"mc":[{"id":"1.168224030","rc":[{"batb":[[0,1.32,66.88],[1,1.01,10.51],[2,1.32,0]],"batl":[[0,1.89,435.28],[1,1.47,0],[2,1.89,0]],"ltp":0.0,"tv":0.0,"id":8908205}]}]}
{"op":"mcm","clk":"1004347114","pt":1580654582070,"mc":[{"id":"1.168224030","rc":[{"batb":[[0,1.32,293.23],[1,1.31,322.2],[2,1.01,10.51]],"ltp":0.0,"tv":0.0,"id":8908205}]}]}
{"op":"mcm","clk":"1004347811","pt":1580654585103,"mc":[{"id":"1.168224030","rc":[{"batb":[[0,1.34,123.51],[1,1.32,293.23],[2,1.31,322.2]],"batl":[[0,1.35,158.06],[1,1.36,259.48]],"ltp":0.0,"tv":0.0,"id":8908205},{"batb":[[0,3.65,14.08],[1,2.98,23.6],[2,2.56,14.08]],"batl":[[0,3.9,14.28]],"ltp":0.0,"tv":0.0,"id":4596961}]}]}
{"op":"mcm","clk":"1004348000","pt":1580654585905,"mc":[{"id":"1.168224030","rc":[{"batb":[[2,1.01,10.51]],"ltp":0.0,"tv":0.0,"id":4596961}]}]}
{"op":"mcm","clk":"1004348497","pt":1580654588095,"mc":[{"id":"1.168224030","rc":[{"trd":[[1.35,110.9]],"batl":[[0,1.35,102.61],[2,1.41,42.01]],"ltp":1.35,"tv":110.9,"id":8908205},{"batb":[[1,3.45,16.8],[2,2.98,23.6]],"ltp":0.0,"tv":0.0,"id":4596961}],"tv":110.9}]}
{"op":"mcm","clk":"1004348613","pt":1580654588574,"mc":[{"id":"1.168224030","rc":[{"batl":[[0,1.36,259.48],[1,1.41,42.01],[2,1.71,542.06]],"ltp":1.35,"tv":110.9,"id":8908205},{"batl":[[1,5.5,115.06]],"ltp":0.0,"tv":0.0,"id":4596961}]}]}
{"op":"mcm","clk":"1004349294","pt":1580654591797,"mc":[{"id":"1.168224030","rc":[{"batl":[[0,1.36,396.25],[1,1.37,247.35],[2,1.41,42.01]],"ltp":1.35,"tv":110.9,"id":8908205}]}]}
{"op":"mcm","clk":"1004351599","pt":1580654602112,"mc":[{"id":"1.168224030","rc":[{"batb":[[1,1.32,66.88],[2,1.22,102.13]],"batl":[[0,1.41,42.01],[1,1.71,542.06],[2,1.41,0]],"ltp":1.35,"tv":110.9,"id":8908205}]}]}
{"op":"mcm","clk":"1004351658","pt":1580654602322,"mc":[{"id":"1.168224030","rc":[{"batb":[[1,1.22,102.13],[2,1.01,10.51]],"ltp":1.35,"tv":110.9,"id":8908205},{"batb":[[0,3.45,16.8],[1,2.98,23.6],[2,1.01,10.51]],"ltp":0.0,"tv":0.0,"id":4596961}]}]}
{"op":"mcm","clk":"1004351987","pt":1580654603724,"mc":[{"id":"1.168224030","rc":[{"batb":[[0,1.22,102.13],[1,1.01,10.51],[2,1.01,0]],"batl":[[0,1.71,542.06],[1,1.71,0]],"ltp":1.35,"tv":110.9,"id":8908205},{"batb":[[0,2.98,23.6],[1,1.01,10.51],[2,1.01,0]],"batl":[[0,5.5,115.06],[1,5.5,0]],"ltp":0.0,"tv":0.0,"id":4596961}]}]}
{"op":"mcm","clk":"1004352256","pt":1580654604939,"mc":[{"id":"1.168224030","rc":[{"batb":[[1,1.19,714.06],[2,1.18,369.52]],"batl":[[0,1.5,297.86],[1,1.51,164.34],[2,1.71,542.06]],"ltp":1.35,"tv":110.9,"id":8908205}]}]}
{"op":"mcm","clk":"1004352745","pt":1580654607052,"mc":[{"id":"1.168224030","rc":[{"batb":[[1,1.01,10.51],[2,1.18,0]],"batl":[[0,1.71,542.06],[1,1.51,0],[2,1.71,0]],"ltp":1.35,"tv":110.9,"id":8908205}]}]}
{"op":"mcm","clk":"1004354015","pt":1580654612667,"mc":[{"id":"1.168224030","rc":[{"batb":[[1,1.19,714.06],[2,1.18,369.52]],"batl":[[0,1.5,297.86],[1,1.51,164.34],[2,1.71,542.06]],"ltp":1.35,"tv":110.9,"id":8908205}]}]}
{"op":"mcm","clk":"1004356317","pt":1580654622760,"mc":[{"id":"1.168224030","rc":[{"batb":[[1,1.01,10.51],[2,1.18,0]],"ltp":1.35,"tv":110.9,"id":8908205}]}]}
{"op":"mcm","clk":"1004357004","pt":1580654625877,"mc":[{"id":"1.168224030","rc":[{"batb":[[0,1.45,185.74],[1,1.44,204.5],[2,1.22,102.13]],"ltp":1.35,"tv":110.9,"id":8908205}]}]}
{"op":"mcm","clk":"1004357248","pt":1580654626976,"mc":[{"id":"1.168224030","rc":[{"batb":[[0,1.45,279],[2,1.43,45.24]],"batl":[[2,1.53,42.01]],"ltp":1.35,"tv":110.9,"id":8908205},{"batb":[[1,2.88,21.85],[2,2.52,14.48]],"batl":[[0,3.2,18.48]],"ltp":0.0,"tv":0.0,"id":4596961}]}]}
{"op":"mcm","clk":"1004357696","pt":1580654629012,"mc":[{"id":"1.168224030","rc":[{"batl":[[1,4.6,136.05]],"ltp":0.0,"tv":0.0,"id":4596961}]}]}
{"op":"mcm","clk":"1004360112","pt":1580654639796,"mc":[{"id":"1.168224030","rc":[{"batb":[[0,1.32,65.38],[1,1.01,10.51],[2,1.43,0]],"batl":[[0,1.71,542.06],[1,1.51,0],[2,1.53,0]],"ltp":1.35,"tv":110.9,"id":8908205},{"batb":[[0,2.52,14.48],[1,1.01,10.51],[2,2.52,0]],"batl":[[0,4.6,136.05],[1,4.6,0]],"ltp":0.0,"tv":0.0,"id":4596961}]}]}
{"op":"mcm","clk":"1004361629","pt":1580654646005,"mc":[{"id":"1.168224030","rc":[{"batb":[[0,1.42,238.04],[1,1.41,224.94],[2,1.32,65.38]],"batl":[[0,1.47,312.94],[1,1.48,177.81],[2,1.71,542.06]],"ltp":1.35,"tv":110.9,"id":8908205}]}]}
{"op":"mcm","clk":"1004361692","pt":1580654646279,"mc":[{"id":"1.168224030","rc":[{"batb":[[0,1.32,65.38],[1,1.01,10.51],[2,1.32,0]],"batl":[[0,1.71,542.06],[1,1.48,0],[2,1.71,0]],"ltp":1.35,"tv":110.9,"id":8908205}]}]}
{"op":"mcm","clk":"1004362309","pt":1580654649279,"mc":[{"id":"1.168224030","rc":[{"batb":[[0,1.32,313.33],[1,1.31,322.1],[2,1.01,10.51]],"batl":[[0,1.64,221.33],[1,1.65,118.72],[2,1.71,542.06]],"ltp":1.35,"tv":110.9,"id":8908205}]}]}
{"op":"mcm","clk":"1004364072","pt":1580654657713,"mc":[{"id":"1.168224030","rc":[{"batl":[[0,1.71,542.06],[1,1.65,0],[2,1.71,0]],"ltp":1.35,"tv":110.9,"id":8908205}]}]}
{"op":"mcm","clk":"1004364798","pt":1580654661110,"mc":[{"id":"1.168224030","rc":[{"batb":[[2,1.22,100.87]],"batl":[[0,1.36,395.11],[1,1.37,247.26],[2,1.71,542.06]],"ltp":1.35,"tv":110.9,"id":8908205},{"batb":[[0,3.6,14.48],[1,2.94,24.39],[2,2.52,14.48]],"ltp":0.0,"tv":0.0,"id":4596961}]}]}
{"op":"mcm","clk":"1004364917","pt":1580654661606,"mc":[{"id":"1.168224030","rc":[{"batb":[[2,1.01,10.51]],"ltp":0.0,"tv":0.0,"id":4596961}]}]}
{"op":"mcm","clk":"1004365152","pt":1580654662737,"mc":[{"id":"1.168224030","rc":[{"batb":[[0,1.34,123.51],[1,1.32,313.33],[2,1.31,322.1]],"batl":[[2,1.41,42.01]],"ltp":1.35,"tv":110.9,"id":8908205},{"batb":[[1,3.45,16.8],[2,2.94,24.39]],"batl":[[0,3.95,13.44]],"ltp":0.0,"tv":0.0,"id":4596961}]}]}
{"op":"mcm","clk":"1004365472","pt":1580654664225,"mc":[{"id":"1.168224030","rc":[{"batl":[[1,6,106.18]],"ltp":0.0,"tv":0.0,"id":4596961}]}]}
{"op":"mcm","clk":"1004368304","pt":1580654677117,"mc":[{"id":"1.168224030","rc":[{"batb":[[1,1.22,100.87],[2,1.01,10.51]],"batl":[[0,1.41,42.01],[1,1.71,542.06],[2,1.41,0]],"ltp":1.35,"tv":110.9,"id":8908205},{"batb":[[0,3.45,16.8],[1,2.94,24.39],[2,1.01,10.51]],"ltp":0.0,"tv":0.0,"id":4596961}]}]}
{"op":"mcm","clk":"1004368413","pt":1580654677704,"mc":[{"id":"1.168224030","rc":[{"batb":[[0,1.22,100.87],[1,1.01,10.51],[2,1.01,0]],"batl":[[0,1.71,542.06],[1,1.71,0]],"ltp":1.35,"tv":110.9,"id":8908205},{"batb":[[0,2.94,24.39],[1,1.01,10.51],[2,1.01,0]],"batl":[[0,6,106.18],[1,6,0]],"ltp":0.0,"tv":0.0,"id":4596961}]}]}
{"op":"mcm","clk":"1004368807","pt":1580654679719,"mc":[{"id":"1.168224030","rc":[{"batb":[[1,1.19,712.05],[2,1.18,371.55]],"batl":[[0,1.5,295.96],[1,1.51,164.3],[2,1.71,542.06]],"ltp":1.35,"tv":110.9,"id":8908205}]}]}
{"op":"mcm","clk":"1004369781","pt":1580654684103,"mc":[{"id":"1.168224030","rc":[{"batl":[[0,1.71,542.06],[1,1.51,0],[2,1.71,0]],"ltp":1.35,"tv":110.9,"id":8908205}]}]}
{"op":"mcm","clk":"1004370423","pt":1580654687010,"mc":[{"id":"1.168224030","rc":[{"trd":[[1.22,201.73]],"batb":[[0,1.19,712.05],[1,1.18,371.55],[2,1.01,10.51]],"batl":[[0,1.22,241.73],[1,1.23,442.08]],"ltp":1.22,"tv":312.63,"id":8908205}],"tv":312.63}]}
{"op":"mcm","clk":"1004370600","pt":1580654687827,"mc":[{"id":"1.168224030","rc":[{"batb":[[0,1.19,578.89],[1,1.18,126.44]],"ltp":1.22,"tv":312.63,"id":8908205},{"batb":[[0,4.6,15.82],[1,3.9,24.23],[2,1.01,10.51]],"ltp":0.0,"tv":0.0,"id":4596961}]}]}
{"op":"mcm","clk":"1004370860","pt":1580654689011,"mc":[{"id":"1.168224030","rc":[{"batb":[[0,1.2,168.04],[1,1.19,578.89],[2,1.18,126.44]],"batl":[[2,1.25,42.01]],"ltp":1.22,"tv":312.63,"id":8908205},{"batb":[[0,5,10.08],[1,4.6,15.82],[2,3.9,24.23]],"batl":[[0,5.9,8.4]],"ltp":0.0,"tv":0.0,"id":4596961}]}]}
{"op":"mcm","clk":"1004371225","pt":1580654690750,"mc":[{"id":"1.168224030","rc":[{"batb":[[0,1.2,337.55]],"batl":[[0,1.22,305.65]],"ltp":1.22,"tv":312.63,"id":8908205},{"batl":[[1,8.6,81.89]],"ltp":0.0,"tv":0.0,"id":4596961}]}]}
{"op":"mcm","clk":"1004372281","pt":1580654695840,"mc":[{"id":"1.168224030","rc":[{"batb":[[0,1.21,105.98],[1,1.2,337.55],[2,1.19,578.89]],"ltp":1.22,"tv":312.63,"id":8908205},{"batb":[[1,4.9,14.63],[2,4.1,22.58]],"ltp":0.0,"tv":0.0,"id":4596961}]}]}
{"op":"mcm","clk":"1004374084","pt":1580654704055,"mc":[{"id":"1.168224030","rc":[{"batb":[[0,5,24.64],[1,4.1,22.42],[2,1.01,10.51]],"ltp":0.0,"tv":0.0,"id":4596961}]}]}
{"op":"mcm","clk":"1004375311","pt":1580654709041,"mc":[{"id":"1.168224030","rc":[{"batb":[[1,1.2,168.04]],"ltp":1.22,"tv":312.63,"id":8908205}]}]}
{"op":"mcm","clk":"1004375966","pt":1580654711920,"mc":[{"id":"1.168224030","rc":[{"batb":[[2,1.19,736.49]],"ltp":1.22,"tv":312.63,"id":8908205}]}]}
{"op":"mcm","clk":"1004378693","pt":1580654724427,"mc":[{"id":"1.168224030","rc":[{"batb":[[2,1.17,132.74]],"batl":[[0,1.25,42.01],[1,1.53,714.1],[2,1.25,0]],"ltp":1.22,"tv":312.63,"id":8908205}]}]}
{"op":"mcm","clk":"1004379263","pt":1580654727206,"mc":[{"id":"1.168224030","rc":[{"batl":[[1,1.29,438.24],[2,1.3,319.43]],"ltp":1.22,"tv":312.63,"id":8908205}]}]}
{"op":"mcm","clk":"1004381791","pt":1580654738905,"mc":[{"id":"1.168224030","rc":[{"batb":[[0,1.2,168.04],[1,1.17,132.74],[2,1.16,607.68]],"ltp":1.22,"tv":312.63,"id":8908205},{"batb":[[0,5,10.08],[1,4.1,22.27]],"ltp":0.0,"tv":0.0,"id":4596961}]}]}
{"op":"mcm","clk":"1004381977","pt":1580654739936,"mc":[{"id":"1.168224030","rc":[{"batb":[[0,1.17,132.74],[1,1.16,607.68],[2,1.15,505.03]],"batl":[[0,1.29,438.24],[1,1.3,319.43],[2,1.53,714.1]],"ltp":1.22,"tv":312.63,"id":8908205},{"batb":[[0,4.1,22.27],[1,1.01,10.51],[2,1.01,0]],"batl":[[0,8.6,81.89],[1,8.6,0]],"ltp":0.0,"tv":0.0,"id":4596961}]}]}
{"op":"mcm","clk":"1004382385","pt":1580654741924,"mc":[{"id":"1.168224030","rc":[{"batb":[[1,1.01,10.51],[2,1.15,0]],"batl":[[0,1.53,714.1],[1,1.3,0],[2,1.53,0]],"ltp":1.22,"tv":312.63,"id":8908205}]}]}
{"op":"mcm","clk":"1004382842","pt":1580654744048,"mc":[{"id":"1.168224030","rc":[{"batb":[[0,1.21,227.33],[1,1.2,547.55],[2,1.17,132.74]],"batl":[[0,1.23,205.44],[1,1.24,423.56],[2,1.53,714.1]],"ltp":1.22,"tv":312.63,"id":8908205}]}]}
{"op":"mcm","clk":"1004383619","pt":1580654747752,"mc":[{"id":"1.168224030","rc":[{"batb":[[0,1.17,132.74],[1,1.01,10.51],[2,1.17,0]],"batl":[[0,1.53,714.1],[1,1.24,0],[2,1.53,0]],"ltp":1.22,"tv":312.63,"id":8908205}]}]}
{"op":"mcm","clk":"1004384344","pt":1580654750947,"mc":[{"id":"1.168224030","rc":[{"batb":[[1,1.16,607.68],[2,1.15,505.03]],"batl":[[0,1.29,438.24],[1,1.3,319.43],[2,1.53,714.1]],"ltp":1.22,"tv":312.63,"id":8908205}]}]}
{"op":"mcm","clk":"1004384974","pt":1580654753718,"mc":[{"id":"1.168224030","rc":[{"batl":[[0,1.53,714.1],[1,1.3,0],[2,1.53,0]],"ltp":1.22,"tv":312.63,"id":8908205}]}]}
{"op":"mcm","clk":"1004385658","pt":1580654757029,"mc":[{"id":"1.168224030","rc":[{"batl":[[0,1.19,717.46],[1,1.2,359.92],[2,1.53,714.1]],"ltp":1.22,"tv":312.63,"id":8908205}]}]}
{"op":"mcm","clk":"1004385816","pt":1580654757731,"mc":[{"id":"1.168224030","rc":[{"batb":[[0,5.7,10.46],[1,4.8,15.66],[2,1.01,10.51]],"ltp":0.0,"tv":0.0,"id":4596961}]}]}
{"op":"mcm","clk":"1004386035","pt":1580654758764,"mc":[{"id":"1.168224030","rc":[{"batb":[[0,1.17,300.78]],"batl":[[2,1.21,42.01]],"ltp":1.22,"tv":312.63,"id":8908205},{"batb":[[1,5.6,8.4],[2,4.8,15.66]],"batl":[[0,6.8,6.72],[1,9.8,75.27]],"ltp":0.0,"tv":0.0,"id":4596961}]}]}
{"op":"mcm","clk":"1004389079","pt":1580654772906,"mc":[{"id":"1.168224030","rc":[{"batb":[[0,1.17,168.04],[1,1.14,168.54],[2,1.01,10.51]],"batl":[[0,1.21,42.01],[1,1.53,714.1],[2,1.21,0]],"ltp":1.22,"tv":312.63,"id":8908205},{"batb":[[0,5.6,8.4],[1,4.8,15.66],[2,1.01,10.51]],"ltp":0.0,"tv":0.0,"id":4596961}]}]}
{"op":"mcm","clk":"1004389298","pt":1580654773880,"mc":[{"id":"1.168224030","rc":[{"batb":[[0,1.14,168.54],[1,1.01,10.51],[2,1.01,0]],"batl":[[0,1.53,714.1],[1,1.53,0]],"ltp":1.22,"tv":312.63,"id":8908205},{"batb":[[0,4.8,15.66],[1,1.01,10.51],[2,1.01,0]],"batl":[[0,9.8,75.27],[1,9.8,0]],"ltp":0.0,"tv":0.0,"id":4596961}]}]}
{"op":"mcm","clk":"1004389808","pt":1580654776094,"mc":[{"id":"1.168224030","rc":[{"batb":[[0,1.14,417.26],[1,1.13,886.85],[2,1.01,10.51]],"batl":[[0,1.23,194.89],[1,1.24,423.86],[2,1.53,714.1]],"ltp":1.22,"tv":312.63,"id":8908205}]}]}
{"op":"mcm","clk":"1004391333","pt":1580654782986,"mc":[{"id":"1.168224030","rc":[{"batb":[[0,1.14,168.54],[1,1.01,10.51],[2,1.01,0]],"ltp":1.22,"tv":312.63,"id":8908205}]}]}
{"op":"mcm","clk":"1004392037","pt":1580654785983,"mc":[{"id":"1.168224030","rc":[{"batb":[[0,1.21,238.73],[1,1.2,547.93],[2,1.14,168.54]],"ltp":1.22,"tv":312.63,"id":8908205}]}]}
{"op":"mcm","clk":"1004392260","pt":1580654787111,"mc":[{"id":"1.168224030","rc":[{"batb":[[0,1.22,101.42],[1,1.21,406.77],[2,1.2,547.93]],"batl":[[2,1.26,42.01]],"ltp":1.22,"tv":312.63,"id":8908205},{"batb":[[0,4.8,26.58],[1,3.9,25.49],[2,1.01,10.51]],"batl":[[0,5.7,8.4]],"ltp":0.0,"tv":0.0,"id":4596961}]}]}
{"op":"mcm","clk":"1004392588","pt":1580654788705,"mc":[{"id":"1.168224030","rc":[{"batl":[[1,7.8,87.91]],"ltp":0.0,"tv":0.0,"id":4596961}]}]}
{"op":"mcm","clk":"1004395212","pt":1580654800912,"mc":[{"id":"1.168224030","rc":[{"batb":[[0,1.21,168.04],[1,1.17,133.29],[2,1.01,10.51]],"batl":[[0,1.26,42.01],[1,1.53,714.1],[2,1.26,0]],"ltp":1.22,"tv":312.63,"id":8908205},{"batb":[[0,4.8,10.92]],"ltp":0.0,"tv":0.0,"id":4596961}]}]}
{"op":"mcm","clk":"1004395384","pt":1580654801708,"mc":[{"id":"1.168224030","rc":[{"batb":[[0,1.17,133.29],[1,1.01,10.51],[2,1.01,0]],"batl":[[0,1.53,714.1],[1,1.53,0]],"ltp":1.22,"tv":312.63,"id":8908205},{"batb":[[0,3.9,25.49],[1,1.01,10.51],[2,1.01,0]],"batl":[[0,7.8,87.91],[1,7.8,0]],"ltp":0.0,"tv":0.0,"id":4596961}]}]}
{"op":"mcm","clk":"1004396368","pt":1580654806611,"mc":[{"id":"1.168224030","rc":[{"batb":[[0,1.22,439.18],[1,1.21,523.29],[2,1.17,133.29]],"batl":[[0,1.25,374.59],[1,1.26,381.2],[2,1.53,714.1]],"ltp":1.22,"tv":312.63,"id":8908205}]}]}
{"op":"mcm","clk":"1004397049","pt":1580654810040,"mc":[{"id":"1.168224030","rc":[{"batb":[[0,1.17,133.29],[1,1.01,10.51],[2,1.17,0]],"batl":[[0,1.53,714.1],[1,1.26,0],[2,1.53,0]],"ltp":1.22,"tv":312.63,"id":8908205}]}]}
{"op":"mcm","clk":"1004397627","pt":1580654812983,"mc":[{"id":"1.168224030","rc":[{"batb":[[1,1.16,834.63],[2,1.15,276.1]],"batl":[[0,1.32,425.19],[1,1.33,284.53],[2,1.53,714.1]],"ltp":1.22,"tv":312.63,"id":8908205}]}]}
{"op":"mcm","clk":"1004397734","pt":1580654813613,"mc":[{"id":"1.168224030","rc":[{"batb":[[1,1.01,10.51],[2,1.15,0]],"ltp":1.22,"tv":312.63,"id":8908205}]}]}
{"op":"mcm","clk":"1004398187","pt":1580654816015,"mc":[{"id":"1.168224030","rc":[{"batb":[[0,1.3,72.54],[1,1.28,398.7],[2,1.27,385.23]],"ltp":1.22,"tv":312.63,"id":8908205},{"batb":[[1,3.25,19.99],[2,1.01,10.51]],"ltp":0.0,"tv":0.0,"id":4596961}]}]}
{"op":"mcm","clk":"1004398366","pt":1580654817032,"mc":[{"id":"1.168224030","rc":[{"batb":[[1,1.28,548.25]],"batl":[[2,1.34,42.01]],"ltp":1.22,"tv":312.63,"id":8908205},{"batb":[[0,3.95,13.44],[1,3.9,25.49],[2,3.25,19.99]],"batl":[[0,4.5,11.76]],"ltp":0.0,"tv":0.0,"id":4596961}]}]}
{"op":"mcm","clk":"1004398582","pt":1580654818007,"mc":[{"id":"1.168224030","rc":[{"batl":[[1,6,106.18]],"ltp":0.0,"tv":0.0,"id":4596961}]}]}
{"op":"mcm","clk":"1004401319","pt":1580654832043,"mc":[{"id":"1.168224030","rc":[{"batb":[[1,1.28,149.55],[2,1.23,97.33]],"batl":[[0,1.34,42.01],[1,1.53,714.1],[2,1.34,0]],"ltp":1.22,"tv":312.63,"id":8908205}]}]}
{"op":"mcm","clk":"1004401388","pt":1580654832464,"mc":[{"id":"1.168224030","rc":[{"batb":[[0,1.28,149.55],[1,1.23,97.33],[2,1.01,10.51]],"ltp":1.22,"tv":312.63,"id":8908205},{"batb":[[1,3.25,19.99],[2,1.01,10.51]],"ltp":0.0,"tv":0.0,"id":4596961}]}]}
{"op":"mcm","clk":"1004401654","pt":1580654833745,"mc":[{"id":"1.168224030","rc":[{"batb":[[0,1.23,97.33],[1,1.01,10.51],[2,1.01,0]],"batl":[[0,1.53,714.1],[1,1.53,0]],"ltp":1.22,"tv":312.63,"id":8908205},{"batb":[[0,3.25,19.99],[1,1.01,10.51],[2,1.01,0]],"batl":[[0,6,106.18],[1,6,0]],"ltp":0.0,"tv":0.0,"id":4596961}]}]}
{"op":"mcm","clk":"1004401887","pt":1580654835028,"mc":[{"id":"1.168224030","rc":[{"batb":[[1,1.22,325.55],[2,1.21,519.95]],"batl":[[0,1.44,218.98],[1,1.45,194.2],[2,1.53,714.1]],"ltp":1.22,"tv":312.63,"id":8908205}]}]}
{"op":"mcm","clk":"1004402254","pt":1580654837046,"mc":[{"id":"1.168224030","rc":[{"batb":[[1,1.01,10.51],[2,1.21,0]],"batl":[[0,1.53,714.1],[1,1.45,0],[2,1.53,0]],"ltp":1.22,"tv":312.63,"id":8908205}]}]}
{"op":"mcm","clk":"1004402775","pt":1580654839870,"mc":[{"id":"1.168224030","rc":[{"batb":[[0,1.3,424.25],[1,1.29,353.07],[2,1.23,97.33]],"batl":[[0,1.34,312.08],[1,1.35,266.15],[2,1.53,714.1]],"ltp":1.22,"tv":312.63,"id":8908205}]}]}
{"op":"mcm","clk":"1004403122","pt":1580654841660,"mc":[{"id":"1.168224030","rc":[{"batb":[[0,1.23,97.33],[1,1.01,10.51],[2,1.23,0]],"batl":[[0,1.53,714.1],[1,1.35,0],[2,1.53,0]],"ltp":1.22,"tv":312.63,"id":8908205}]}]}
{"op":"mcm","clk":"1004403670","pt":1580654844669,"mc":[{"id":"1.168224030","rc":[{"batb":[[1,1.22,323.67],[2,1.21,519.95]],"batl":[[0,1.44,220.56],[1,1.45,194.19],[2,1.53,714.1]],"ltp":1.22,"tv":312.63,"id":8908205}]}]}
{"op":"mcm","clk":"1004406885","pt":1580654862546,"mc":[{"id":"1.168224030","rc":[{"batb":[[1,1.01,10.51],[2,1.21,0]],"ltp":1.22,"tv":312.63,"id":8908205}]}]}
{"op":"mcm","clk":"1004407311","pt":1580654864635,"mc":[{"id":"1.168224030","rc":[{"batl":[[2,1.53,0]],"ltp":1.22,"tv":312.63,"id":8908205}]}]}
{"op":"mcm","clk":"1004407492","pt":1580654865635,"mc":[{"id":"1.168224030","rc":[{"batb":[[0,1.4,189.99],[1,1.39,239.57],[2,1.23,97.33]],"ltp":1.22,"tv":312.63,"id":8908205}]}]}
{"op":"mcm","clk":"1004407707","pt":1580654866726,"mc":[{"id":"1.168224030","rc":[{"batb":[[1,1.39,398.26],[2,1.33,63.65]],"batl":[[2,1.47,42.01]],"ltp":1.22,"tv":312.63,"id":8908205},{"batb":[[1,3.15,19.32],[2,2.82,11.57]],"batl":[[0,3.55,15.96]],"ltp":0.0,"tv":0.0,"id":4596961}]}]}
{"op":"mcm","clk":"1004408060","pt":1580654868483,"mc":[{"id":"1.168224030","rc":[{"batl":[[1,4.9,126.27]],"ltp":0.0,"tv":0.0,"id":4596961}]}]}
{"op":"mcm","clk":"1004409272","pt":1580654874817,"mc":[{"id":"1.168224030","rc":[{"batl":[[0,1.44,156.56]],"ltp":1.22,"tv":312.63,"id":8908205}]}]}
{"op":"mcm","clk":"1004409770","pt":1580654877754,"mc":[{"id":"1.168224030","rc":[{"batb":[[0,1.4,252.95]],"ltp":1.22,"tv":312.63,"id":8908205}]}]}
{"op":"mcm","clk":"1004411411","pt":1580654886547,"mc":[{"id":"1.168224030","rc":[{"batb":[[0,1.39,107.54],[1,1.33,63.65],[2,1.01,10.51]],"batl":[[0,1.47,42.01],[1,1.77,500.61],[2,1.47,0]],"ltp":1.22,"tv":312.63,"id":8908205},{"batb":[[0,3.15,19.32],[1,2.82,11.57],[2,1.01,10.51]],"ltp":0.0,"tv":0.0,"id":4596961}]}]}
{"op":"mcm","clk":"1004411621","pt":1580654887804,"mc":[{"id":"1.168224030","rc":[{"batb":[[0,1.33,63.65],[1,1.01,10.51],[2,1.01,0]],"batl":[[0,1.77,500.61],[1,1.77,0]],"ltp":1.22,"tv":312.63,"id":8908205},{"batb":[[0,2.82,11.57],[1,1.01,10.51],[2,1.01,0]],"batl":[[0,4.9,126.27],[1,4.9,0]],"ltp":0.0,"tv":0.0,"id":4596961}]}]}
{"op":"mcm","clk":"1004411894","pt":1580654889267,"mc":[{"id":"1.168224030","rc":[{"batb":[[0,1.33,231.61],[1,1.32,307.22],[2,1.01,10.51]],"batl":[[0,1.59,228.15],[1,1.6,132.05],[2,1.77,500.61]],"ltp":1.22,"tv":312.63,"id":8908205}]}]}
{"op":"mcm","clk":"1004412293","pt":1580654891371,"mc":[{"id":"1.168224030","rc":[{"batl":[[0,1.77,500.61],[1,1.6,0],[2,1.77,0]],"ltp":1.22,"tv":312.63,"id":8908205}]}]}
{"op":"mcm","clk":"1004412944","pt":1580654894856,"mc":[{"id":"1.168224030","rc":[{"batb":[[1,1.32,438.29]],"batl":[[0,1.36,181.78],[1,1.37,249.08],[2,1.39,42.01]],"ltp":1.22,"tv":312.63,"id":8908205},{"batb":[[0,3.55,15.96],[1,2.82,11.57],[2,1.01,10.51]],"batl":[[0,4.1,13.44]],"ltp":0.0,"tv":0.0,"id":4596961}]}]}
{"op":"mcm","clk":"1004413137","pt":1580654895871,"mc":[{"id":"1.168224030","rc":[{"batb":[[2,1.24,94.02]],"ltp":1.22,"tv":312.63,"id":8908205},{"batb":[[0,3.65,15.03],[1,3.55,15.96],[2,2.9,10.78]],"ltp":0.0,"tv":0.0,"id":4596961}]}]}
{"op":"mcm","clk":"1004413484","pt":1580654897883,"mc":[{"id":"1.168224030","rc":[{"batl":[[1,5.5,115.06]],"ltp":0.0,"tv":0.0,"id":4596961}]}]}
{"op":"mcm","clk":"1004416573","pt":1580654914914,"mc":[{"id":"1.168224030","rc":[{"batb":[[0,1.32,131.07],[1,1.24,94.02],[2,1.01,10.51]],"batl":[[0,1.39,42.01],[1,1.77,500.61],[2,1.39,0]],"ltp":1.22,"tv":312.63,"id":8908205},{"batb":[[0,3.55,15.96],[1,2.9,10.78],[2,1.01,10.51]],"ltp":0.0,"tv":0.0,"id":4596961}]}]}
{"op":"mcm","clk":"1004416722","pt":1580654915708,"mc":[{"id":"1.168224030","rc":[{"batb":[[0,1.24,94.02],[1,1.01,10.51],[2,1.01,0]],"batl":[[0,1.77,500.61],[1,1.77,0]],"ltp":1.22,"tv":312.63,"id":8908205},{"batb":[[0,2.9,10.78],[1,1.01,10.51],[2,1.01,0]],"batl":[[0,5.5,115.06],[1,5.5,0]],"ltp":0.0,"tv":0.0,"id":4596961}]}]}
{"op":"mcm","clk":"1004417046","pt":1580654917604,"mc":[{"id":"1.168224030","rc":[{"batb":[[1,1.23,210.01],[2,1.22,486.98]],"batl":[[0,1.57,148.1],[1,1.58,138.64],[2,1.77,500.61]],"ltp":1.22,"tv":312.63,"id":8908205}]}]}
{"op":"mcm","clk":"1004417618","pt":1580654921232,"mc":[{"id":"1.168224030","rc":[{"batl":[[0,1.77,500.61],[1,1.58,0],[2,1.77,0]],"ltp":1.22,"tv":312.63,"id":8908205}]}]}
{"op":"mcm","clk":"1004418081","pt":1580654924123,"mc":[{"id":"1.168224030","rc":[{"batl":[[0,1.26,519.94],[1,1.27,359.7]],"ltp":1.22,"tv":312.63,"id":8908205}]}]}
{"op":"mcm","clk":"1004418232","pt":1580654925026,"mc":[{"id":"1.168224030","rc":[{"batb":[[1,1.23,378.05]],"batl":[[2,1.28,42.01]],"ltp":1.22,"tv":312.63,"id":8908205},{"batb":[[0,4.6,28.47],[1,3.6,15.42],[2,1.01,10.51]],"batl":[[0,5.4,9.24]],"ltp":0.0,"tv":0.0,"id":4596961}]}]}
{"op":"mcm","clk":"1004418681","pt":1580654927804,"mc":[{"id":"1.168224030","rc":[{"batl":[[1,7.8,87.91]],"ltp":0.0,"tv":0.0,"id":4596961}]}]}
{"op":"mcm","clk":"1004420629","pt":1580654940116,"mc":[{"id":"1.168224030","rc":[{"batb":[[1,1.23,168.04],[2,1.17,132.97]],"batl":[[0,1.28,42.01],[1,1.56,675.59],[2,1.28,0]],"ltp":1.22,"tv":312.63,"id":8908205}]}]}
{"op":"mcm","clk":"1004420680","pt":1580654940440,"mc":[{"id":"1.168224030","rc":[{"batb":[[0,1.23,168.04],[1,1.17,132.97],[2,1.01,10.51]],"ltp":1.22,"tv":312.63,"id":8908205},{"batb":[[0,4.6,10.92]],"ltp":0.0,"tv":0.0,"id":4596961}]}]}
{"op":"mcm","clk":"1004420915","pt":1580654941842,"mc":[{"id":"1.168224030","rc":[{"batb":[[0,1.17,132.97],[1,1.01,10.51],[2,1.01,0]],"batl":[[0,1.56,675.59],[1,1.56,0]],"ltp":1.22,"tv":312.63,"id":8908205},{"batb":[[0,3.6,15.42],[1,1.01,10.51],[2,1.01,0]],"batl":[[0,7.8,87.91],[1,7.8,0]],"ltp":0.0,"tv":0.0,"id":4596961}]}]}
{"op":"mcm","clk":"1004421116","pt":1580654943122,"mc":[{"id":"1.168224030","rc":[{"batb":[[0,1.17,410.96],[1,1.16,709.71],[2,1.01,10.51]],"batl":[[0,1.37,201.33],[1,1.38,240.67],[2,1.56,675.59]],"ltp":1.22,"tv":312.63,"id":8908205}]}]}
{"op":"mcm","clk":"1004421281","pt":1580654944039,"mc":[{"id":"1.168224030","rc":[{"batb":[[0,1.17,132.97],[1,1.01,10.51],[2,1.01,0]],"batl":[[0,1.56,675.59],[1,1.38,0],[2,1.56,0]],"ltp":1.22,"tv":312.63,"id":8908205}]}]}
{"op":"mcm","clk":"1004421760","pt":1580654946637,"mc":[{"id":"1.168224030","rc":[{"batb":[[0,1.25,204.99],[1,1.24,438.71],[2,1.17,132.97]],"batl":[[0,1.28,424.82],[1,1.29,332.05],[2,1.56,675.59]],"ltp":1.22,"tv":312.63,"id":8908205}]}]}
{"op":"mcm","clk":"1004421961","pt":1580654947753,"mc":[{"id":"1.168224030","rc":[{"batl":[[0,7.2,92.18]],"ltp":0.0,"tv":0.0,"id":4596961}]}]}
{"op":"mcm","clk":"1004422612","pt":1580654951756,"mc":[{"id":"1.168224030","rc":[{"batb":[[0,1.17,132.97],[1,1.01,10.51],[2,1.17,0]],"batl":[[0,1.56,675.59],[1,1.29,0],[2,1.56,0]],"ltp":1.22,"tv":312.63,"id":8908205}]}]}
{"op":"mcm","clk":"1004423054","pt":1580654954732,"mc":[{"id":"1.168224030","rc":[{"batb":[[0,1.17,410.96],[1,1.16,709.71],[2,1.01,10.51]],"batl":[[0,1.37,201.33],[1,1.38,240.67],[2,1.56,675.59]],"ltp":1.22,"tv":312.63,"id":8908205}]}]}
{"op":"mcm","clk":"1004423786","pt":1580654960057,"mc":[{"id":"1.168224030","rc":[{"batb":[[0,1.17,132.97],[1,1.01,10.51],[2,1.01,0]],"ltp":1.22,"tv":312.63,"id":8908205}]}]}
{"op":"mcm","clk":"1004424210","pt":1580654962948,"mc":[{"id":"1.168224030","rc":[{"batb":[[0,1.33,416.64],[1,1.32,311.04],[2,1.17,132.97]],"ltp":1.22,"tv":312.63,"id":8908205}]}]}
{"op":"mcm","clk":"1004424344","pt":1580654963750,"mc":[{"id":"1.168224030","rc":[{"batb":[[0,1.34,62.47],[1,1.33,416.64],[2,1.32,311.04]],"ltp":1.22,"tv":312.63,"id":8908205},{"batb":[[1,2.88,10.94],[2,1.01,10.51]],"ltp":0.0,"tv":0.0,"id":4596961}]}]}
{"op":"mcm","clk":"1004424515","pt":1580654964980,"mc":[{"id":"1.168224030","rc":[{"batb":[[1,1.33,543.51]],"batl":[[2,1.39,42.01]],"ltp":1.22,"tv":312.63,"id":8908205},{"batb":[[1,3.55,15.96],[2,2.88,10.94]],"batl":[[0,4,13.44],[1,5.5,115.06]],"ltp":0.0,"tv":0.0,"id":4596961}]}]}
{"op":"mcm","clk":"1004426359","pt":1580654977099,"mc":[{"id":"1.168224030","rc":[{"batb":[[0,1.33,126.87],[1,1.24,90.88],[2,1.01,10.51]],"batl":[[0,1.39,42.01],[1,1.56,675.59],[2,1.39,0]],"ltp":1.22,"tv":312.63,"id":8908205},{"batb":[[0,3.55,15.96],[1,2.88,10.94],[2,1.01,10.51]],"ltp":0.0,"tv":0.0,"id":4596961}]}]}
{"op":"mcm","clk":"1004426479","pt":1580654977799,"mc":[{"id":"1.168224030","rc":[{"batb":[[0,1.24,90.88],[1,1.01,10.51],[2,1.01,0]],"batl":[[0,1.56,675.59],[1,1.56,0]],"ltp":1.22,"tv":312.63,"id":8908205},{"batb":[[0,2.88,10.94],[1,1.01,10.51],[2,1.01,0]],"batl":[[0,5.5,115.06],[1,5.5,0]],"ltp":0.0,"tv":0.0,"id":4596961}]}]}
{"op":"mcm","clk":"1004426802","pt":1580654979676,"mc":[{"id":"1.168224030","rc":[{"batb":[[1,1.23,498.72],[2,1.22,495.09]],"batl":[[1,1.58,126],[2,1.59,135.59]],"ltp":1.22,"tv":312.63,"id":8908205}]}]}
{"op":"mcm","clk":"1004427058","pt":1580654981371,"mc":[{"id":"1.168224030","rc":[{"batl":[[1,1.58,0],[2,1.59,0]],"ltp":1.22,"tv":312.63,"id":8908205}]}]}
{"op":"mcm","clk":"1004427574","pt":1580654984913,"mc":[{"id":"1.168224030","rc":[{"batb":[[1,1.23,666.76]],"batl":[[0,1.26,258.61],[1,1.27,365.62],[2,1.29,42.01]],"ltp":1.22,"tv":312.63,"id":8908205},{"batb":[[0,4.5,30.17],[1,3.55,15.97],[2,2.88,10.94]],"batl":[[0,5.3,9.24]],"ltp":0.0,"tv":0.0,"id":4596961}]}]}
{"op":"mcm","clk":"1004427610","pt":1580654985210,"mc":[{"id":"1.168224030","rc":[{"batb":[[2,1.01,10.51]],"ltp":0.0,"tv":0.0,"id":4596961}]}]}
{"op":"mcm","clk":"1004428075","pt":1580654988123,"mc":[{"id":"1.168224030","rc":[{"batl":[[1,7.2,92.18]],"ltp":0.0,"tv":0.0,"id":4596961}]}]}
{"op":"mcm","clk":"1004430140","pt":1580655001123,"mc":[{"id":"1.168224030","rc":[{"batb":[[1,1.23,168.04],[2,1.18,130.61]],"batl":[[0,1.29,42.01],[1,1.56,675.59],[2,1.29,0]],"ltp":1.22,"tv":312.63,"id":8908205}]}]}
{"op":"mcm","clk":"1004430255","pt":1580655001826,"mc":[{"id":"1.168224030","rc":[{"batb":[[0,1.18,130.61],[1,1.01,10.51],[2,1.18,0]],"batl":[[0,1.56,675.59],[1,1.56,0]],"ltp":1.22,"tv":312.63,"id":8908205},{"batb":[[0,3.55,15.97],[1,1.01,10.51],[2,1.01,0]],"batl":[[0,7.2,92.18],[1,7.2,0]],"ltp":0.0,"tv":0.0,"id":4596961}]}]}
{"op":"mcm","clk":"1004430589","pt":1580655004030,"mc":[{"id":"1.168224030","rc":[{"batb":[[1,1.17,578.65],[2,1.16,524.71]],"batl":[[0,1.38,221.97],[1,1.39,232.69],[2,1.56,675.59]],"ltp":1.22,"tv":312.63,"id":8908205}]}]}
{"op":"mcm","clk":"1004430626","pt":1580655004198,"mc":[{"id":"1.168224030","rc":[{"batb":[[1,1.01,10.51],[2,1.16,0]],"batl":[[0,1.56,675.59],[1,1.39,0],[2,1.56,0]],"ltp":1.22,"tv":312.63,"id":8908205}]}]}
{"op":"mcm","clk":"1004431026","pt":1580655006902,"mc":[{"id":"1.168224030","rc":[{"batb":[[0,1.25,481.45],[1,1.24,445.5],[2,1.18,130.61]],"batl":[[0,1.28,172.28],[1,1.29,337.12],[2,1.56,675.59]],"ltp":1.22,"tv":312.63,"id":8908205}]}]}
{"op":"mcm","clk":"1004431666","pt":1580655011443,"mc":[{"id":"1.168224030","rc":[{"batb":[[0,1.18,130.61],[1,1.01,10.51],[2,1.18,0]],"batl":[[0,1.56,675.59],[1,1.29,0],[2,1.56,0]],"ltp":1.22,"tv":312.63,"id":8908205}]}]}
{"op":"mcm","clk":"1004432093","pt":1580655014408,"mc":[{"id":"1.168224030","rc":[{"batb":[[1,1.17,578.65],[2,1.16,524.71]],"batl":[[0,1.38,221.97],[1,1.39,232.69],[2,1.56,675.59]],"ltp":1.22,"tv":312.63,"id":8908205}]}]}
{"op":"mcm","clk":"1004432776","pt":1580655019440,"mc":[{"id":"1.168224030","rc":[{"batb":[[1,1.01,10.51],[2,1.16,0]],"ltp":1.22,"tv":312.63,"id":8908205}]}]}
{"op":"mcm","clk":"1004433263","pt":1580655023041,"mc":[{"id":"1.168224030","rc":[{"batb":[[0,1.34,419.09],[1,1.33,298.4],[2,1.25,89.07]],"batl":[[2,1.4,42.01]],"ltp":1.22,"tv":312.63,"id":8908205},{"batb":[[1,3.5,16.8],[2,2.84,11.33]],"ltp":0.0,"tv":0.0,"id":4596961}]}]}
{"op":"mcm","clk":"1004433324","pt":1580655023469,"mc":[{"id":"1.168224030","rc":[{"batb":[[0,1.34,542.6]],"ltp":1.22,"tv":312.63,"id":8908205},{"batl":[[0,4,13.44]],"ltp":0.0,"tv":0.0,"id":4596961}]}]}
{"op":"mcm","clk":"1004433643","pt":1580655025544,"mc":[{"id":"1.168224030","rc":[{"batl":[[1,5.5,115.06]],"ltp":0.0,"tv":0.0,"id":4596961}]}]}
{"op":"mcm","clk":"1004435734","pt":1580655040100,"mc":[{"id":"1.168224030","rc":[{"batb":[[0,1.34,184.41],[1,1.25,89.07],[2,1.01,10.51]],"batl":[[0,1.4,42.01],[1,1.56,675.59],[2,1.4,0]],"ltp":1.22,"tv":312.63,"id":8908205}]}]}
{"op":"mcm","clk":"1004435811","pt":1580655040638,"mc":[{"id":"1.168224030","rc":[{"batb":[[0,1.34,123.51]],"ltp":1.22,"tv":312.63,"id":8908205},{"batb":[[0,3.5,16.8],[1,2.84,11.33],[2,1.01,10.51]],"ltp":0.0,"tv":0.0,"id":4596961}]}]}
{"op":"mcm","clk":"1004436001","pt":1580655041806,"mc":[{"id":"1.168224030","rc":[{"batb":[[0,1.25,89.07],[1,1.01,10.51],[2,1.01,0]],"batl":[[0,1.56,675.59],[1,1.56,0]],"ltp":1.22,"tv":312.63,"id":8908205},{"batb":[[0,2.84,11.33],[1,1.01,10.51],[2,1.01,0]],"batl":[[0,5.5,115.06],[1,5.5,0]],"ltp":0.0,"tv":0.0,"id":4596961}]}]}
{"op":"mcm","clk":"1004436214","pt":1580655043122,"mc":[{"id":"1.168224030","rc":[{"batb":[[1,1.24,305.79],[2,1.23,464.72]],"batl":[[1,1.6,244.69],[2,1.61,129.13]],"ltp":1.22,"tv":312.63,"id":8908205}]}]}
{"op":"mcm","clk":"1004436385","pt":1580655044462,"mc":[{"id":"1.168224030","rc":[{"batb":[[1,1.01,10.51],[2,1.23,0]],"batl":[[1,1.6,0],[2,1.61,0]],"ltp":1.22,"tv":312.63,"id":8908205}]}]}
{"op":"mcm","clk":"1004436833","pt":1580655047028,"mc":[{"id":"1.168224030","rc":[{"batb":[[0,1.38,203.54],[1,1.37,256.06],[2,1.25,89.07]],"batl":[[0,1.42,251.1],[1,1.43,205.18]],"ltp":1.22,"tv":312.63,"id":8908205}]}]}
{"op":"mcm","clk":"1004437281","pt":1580655049809,"mc":[{"id":"1.168224030","rc":[{"batb":[[0,1.25,89.07],[1,1.01,10.51],[2,1.25,0]],"batl":[[0,1.73,527.57],[1,1.43,0]],"ltp":1.22,"tv":312.63,"id":8908205}]}]}
{"op":"mcm","clk":"1004437629","pt":1580655052107,"mc":[{"id":"1.168224030","rc":[{"batb":[[1,1.24,305.79],[2,1.23,464.72]],"batl":[[0,1.6,244.69],[1,1.61,129.13],[2,1.73,527.57]],"ltp":1.22,"tv":312.63,"id":8908205}]}]}
{"op":"mcm","clk":"1004437717","pt":1580655052736,"mc":[{"id":"1.168224030","rc":[{"batl":[[0,1.73,527.57],[1,1.61,0],[2,1.73,0]],"ltp":1.22,"tv":312.63,"id":8908205}]}]}
{"op":"mcm","clk":"1004438215","pt":1580655055840,"mc":[{"id":"1.168224030","rc":[{"batl":[[0,1.27,381.86],[1,1.28,347.62]],"ltp":1.22,"tv":312.63,"id":8908205}]}]}
{"op":"mcm","clk":"1004438364","pt":1580655056735,"mc":[{"id":"1.168224030","rc":[{"batb":[[1,1.24,473.83]],"batl":[[2,1.29,42.01]],"ltp":1.22,"tv":312.63,"id":8908205},{"batb":[[0,4.4,30.73],[1,3.5,16.6],[2,1.01,10.51]],"batl":[[0,5.2,9.24]],"ltp":0.0,"tv":0.0,"id":4596961}]}]}
{"op":"mcm","clk":"1004438717","pt":1580655058857,"mc":[{"id":"1.168224030","rc":[{"batl":[[1,7.2,92.18]],"ltp":0.0,"tv":0.0,"id":4596961}]}]}
{"op":"mcm","clk":"1004441010","pt":1580655073067,"mc":[{"id":"1.168224030","rc":[{"batb":[[1,1.24,168.04],[2,1.18,127.23]],"batl":[[0,1.29,42.01],[1,1.58,650.58],[2,1.29,0]],"ltp":1.22,"tv":312.63,"id":8908205}]}]}
{"op":"mcm","clk":"1004441139","pt":1580655073854,"mc":[{"id":"1.168224030","rc":[{"batb":[[0,1.18,127.23],[1,1.01,10.51],[2,1.18,0]],"batl":[[0,1.58,650.58],[1,1.58,0]],"ltp":1.22,"tv":312.63,"id":8908205},{"batb":[[0,3.5,16.6],[1,1.01,10.51],[2,1.01,0]],"batl":[[0,7.2,92.18],[1,7.2,0]],"ltp":0.0,"tv":0.0,"id":4596961}]}]}
{"op":"mcm","clk":"1004441455","pt":1580655075980,"mc":[{"id":"1.168224030","rc":[{"batb":[[0,1.18,320.44],[1,1.17,659.51],[2,1.01,10.51]],"batl":[[0,1.39,259.59],[1,1.4,225.16],[2,1.58,650.58]],"ltp":1.22,"tv":312.63,"id":8908205}]}]}
{"op":"mcm","clk":"1004443525","pt":1580655090111,"mc":[{"id":"1.168224030","rc":[{"batb":[[0,1.18,127.23],[1,1.01,10.51],[2,1.01,0]],"batl":[[0,1.58,650.58],[1,1.4,0],[2,1.58,0]],"ltp":1.22,"tv":312.63,"id":8908205}]}]}
{"op":"mcm","clk":"1004443864","pt":1580655092611,"mc":[{"id":"1.168224030","rc":[{"batb":[[0,1.26,310.94],[1,1.25,420.59],[2,1.18,127.23]],"batl":[[0,1.29,284.86],[1,1.3,321.79],[2,1.58,650.58]],"ltp":1.22,"tv":312.63,"id":8908205}]}]}
{"op":"mcm","clk":"1004444291","pt":1580655095319,"mc":[{"id":"1.168224030","rc":[{"batl":[[0,6.6,98.95]],"ltp":0.0,"tv":0.0,"id":4596961}]}]}
{"op":"mcm","clk":"1004444525","pt":1580655097137,"mc":[{"id":"1.168224030","rc":[{"batb":[[0,1.18,127.23],[1,1.01,10.51],[2,1.18,0]],"batl":[[0,1.58,650.58],[1,1.3,0],[2,1.58,0]],"ltp":1.22,"tv":312.63,"id":8908205}]}]}
{"op":"mcm","clk":"1004444962","pt":1580655100028,"mc":[{"id":"1.168224030","rc":[{"batb":[[0,1.18,320.54],[1,1.17,659.51],[2,1.01,10.51]],"batl":[[0,1.39,259.5],[1,1.4,225.16],[2,1.58,650.58]],"ltp":1.22,"tv":312.63,"id":8908205}]}]}
{"op":"mcm","clk":"1004446115","pt":1580655108235,"mc":[{"id":"1.168224030","rc":[{"batb":[[0,1.18,127.23],[1,1.01,10.51],[2,1.01,0]],"ltp":1.22,"tv":312.63,"id":8908205}]}]}
{"op":"mcm","clk":"1004446713","pt":1580655111918,"mc":[{"id":"1.168224030","rc":[{"batb":[[0,1.35,344.04],[1,1.34,286.6],[2,1.25,87.02]],"ltp":1.22,"tv":312.63,"id":8908205},{"batb":[[1,2.82,11.64],[2,1.01,10.51]],"ltp":0.0,"tv":0.0,"id":4596961}]}]}
{"op":"mcm","clk":"1004446863","pt":1580655112750,"mc":[{"id":"1.168224030","rc":[{"batb":[[1,1.34,410.11]],"batl":[[2,1.41,42.01]],"ltp":1.22,"tv":312.63,"id":8908205},{"batb":[[1,3.45,16.8],[2,2.82,11.64]],"batl":[[0,3.9,14.28]],"ltp":0.0,"tv":0.0,"id":4596961}]}]}
{"op":"mcm","clk":"1004447332","pt":1580655115738,"mc":[{"id":"1.168224030","rc":[{"batl":[[1,5.3,118.79]],"ltp":0.0,"tv":0.0,"id":4596961}]}]}
{"op":"mcm","clk":"1004449009","pt":1580655126314,"mc":[{"id":"1.168224030","rc":[{"batb":[[0,1.35,282.03]],"ltp":1.22,"tv":312.63,"id":8908205}]}]}
{"op":"mcm","clk":"1004449490","pt":1580655129231,"mc":[{"id":"1.168224030","rc":[{"batl":[[0,1.39,319.75]],"ltp":1.22,"tv":312.63,"id":8908205}]}]}
{"op":"mcm","clk":"1004449900","pt":1580655131858,"mc":[{"id":"1.168224030","rc":[{"batb":[[0,1.25,87.02],[1,1.01,10.51],[2,1.25,0]],"batl":[[0,1.58,650.58],[1,1.4,0],[2,1.41,0]],"ltp":1.22,"tv":312.63,"id":8908205},{"batb":[[0,2.82,11.64],[1,1.01,10.51],[2,2.82,0]],"batl":[[0,5.3,118.79],[1,5.3,0]],"ltp":0.0,"tv":0.0,"id":4596961}]}]}
{"op":"mcm","clk":"1004450241","pt":1580655134175,"mc":[{"id":"1.168224030","rc":[{"batb":[[1,1.24,494.84],[2,1.23,471.47]],"batl":[[1,1.6,154.94],[2,1.61,129.9]],"ltp":1.22,"tv":312.63,"id":8908205}]}]}
{"op":"mcm","clk":"1004452638","pt":1580655150092,"mc":[{"id":"1.168224030","rc":[{"batb":[[1,1.01,10.51],[2,1.23,0]],"ltp":1.22,"tv":312.63,"id":8908205}]}]}
{"op":"mcm","clk":"1004453031","pt":1580655152969,"mc":[{"id":"1.168224030","rc":[{"trd":[[1.55,21.18]],"batb":[[0,1.55,123.89],[1,1.54,155.09],[2,1.25,87.02]],"ltp":1.55,"tv":333.81,"id":8908205},{"trd":[[2.82,11.64]],"batb":[[0,1.01,10.51],[1,1.01,0]],"ltp":2.82,"tv":11.64,"id":4596961}],"tv":345.45}]}
{"op":"mcm","clk":"1004453171","pt":1580655153876,"mc":[{"id":"1.168224030","rc":[{"batb":[[2,1.5,37.92]],"batl":[[0,1.6,154.94],[1,1.61,129.9],[2,1.61,0]],"ltp":1.55,"tv":333.81,"id":8908205},{"batb":[[0,2.48,16.21],[1,1.01,10.51]],"ltp":2.82,"tv":11.64,"id":4596961}]}]}
{"op":"mcm","clk":"1004453625","pt":1580655156884,"mc":[{"id":"1.168224030","rc":[{"batb":[[0,1.59,70.58],[1,1.55,123.89],[2,1.54,155.09]],"batl":[[2,1.7,42.01]],"ltp":1.55,"tv":333.81,"id":8908205},{"batl":[[0,2.7,24.37]],"ltp":2.82,"tv":11.64,"id":4596961}]}]}
{"op":"mcm","clk":"1004453740","pt":1580655157678,"mc":[{"id":"1.168224030","rc":[{"batl":[[1,3.9,158.24]],"ltp":2.82,"tv":11.64,"id":4596961}]}]}
{"op":"mcm","clk":"1004454079","pt":1580655160087,"mc":[{"id":"1.168224030","rc":[{"trd":[[1.6,68.9]],"batl":[[0,1.6,120.49]],"ltp":1.6,"tv":402.71,"id":8908205}],"tv":414.35}]}
{"op":"mcm","clk":"1004454644","pt":1580655164103,"mc":[{"id":"1.168224030","rc":[{"batb":[[1,1.55,150.36]],"batl":[[0,1.6,149.89]],"ltp":1.6,"tv":402.71,"id":8908205}]}]}
{"op":"mcm","clk":"1004457952","pt":1580655187025,"mc":[{"id":"1.168224030","rc":[{"batb":[[1,1.5,37.92],[2,1.4,50.12]],"batl":[[0,1.7,42.01],[1,1.95,409.86],[2,1.7,0]],"ltp":1.6,"tv":402.71,"id":8908205}]}]}
{"op":"mcm","clk":"1004458104","pt":1580655188036,"mc":[{"id":"1.168224030","rc":[{"batb":[[0,1.4,50.12],[1,1.01,10.51],[2,1.4,0]],"batl":[[0,1.95,409.86],[1,1.95,0]],"ltp":1.6,"tv":402.71,"id":8908205},{"batl":[[0,3.9,158.24],[1,3.9,0]],"ltp":2.82,"tv":11.64,"id":4596961}]}]}
{"op":"mcm","clk":"1004458542","pt":1580655191009,"mc":[{"id":"1.168224030","rc":[{"batb":[[0,1.42,47.45]],"ltp":1.6,"tv":402.71,"id":8908205},{"batb":[[0,2.42,17.31]],"ltp":2.82,"tv":11.64,"id":4596961}]}]}
{"op":"mcm","clk":"1004458858","pt":1580655193026,"mc":[{"id":"1.168224030","rc":[{"batb":[[0,1.52,252.6],[1,1.51,168.25],[2,1.42,47.45]],"batl":[[0,1.58,236.82],[1,1.59,135.59],[2,1.95,409.86]],"ltp":1.6,"tv":402.71,"id":8908205}]}]}
{"op":"mcm","clk":"1004459233","pt":1580655195606,"mc":[{"id":"1.168224030","rc":[{"batb":[[0,1.42,47.45],[1,1.01,10.51],[2,1.42,0]],"batl":[[0,1.95,409.86],[1,1.59,0],[2,1.95,0]],"ltp":1.6,"tv":402.71,"id":8908205}]}]}
{"op":"mcm","clk":"1004459715","pt":1580655198919,"mc":[{"id":"1.168224030","rc":[{"batb":[[0,1.43,323.22],[1,1.42,266.23],[2,1.01,10.51]],"batl":[[0,1.72,142.36],[1,1.74,199.91],[2,1.95,409.86]],"ltp":1.6,"tv":402.71,"id":8908205}]}]}
{"op":"mcm","clk":"1004461142","pt":1580655209070,"mc":[{"id":"1.168224030","rc":[{"batl":[[0,1.95,409.86],[1,1.74,0],[2,1.95,0]],"ltp":1.6,"tv":402.71,"id":8908205}]}]}
{"op":"mcm","clk":"1004461521","pt":1580655211829,"mc":[{"id":"1.168224030","rc":[{"batl":[[0,1.48,209.52],[1,1.49,173.91]],"ltp":1.6,"tv":402.71,"id":8908205}]}]}
{"op":"mcm","clk":"1004461670","pt":1580655212834,"mc":[{"id":"1.168224030","rc":[{"trd":[[1.48,174.76]],"batb":[[2,1.33,62.47]],"batl":[[0,1.48,122.14],[2,1.58,42.01]],"ltp":1.48,"tv":577.47,"id":8908205},{"batb":[[0,3.1,22.19],[1,2.72,37.11],[2,1.01,10.51]],"ltp":2.82,"tv":11.64,"id":4596961}],"tv":589.11}]}
{"op":"mcm","clk":"1004461774","pt":1580655213669,"mc":[{"id":"1.168224030","rc":[{"batb":[[0,1.43,210.32],[1,1.42,47.45]],"ltp":1.48,"tv":577.47,"id":8908205}]}]}
{"op":"mcm","clk":"1004461960","pt":1580655214940,"mc":[{"id":"1.168224030","rc":[{"batl":[[0,4.6,136.05]],"ltp":2.82,"tv":11.64,"id":4596961}]}]}
{"op":"mcm","clk":"1004462123","pt":1580655216045,"mc":[{"id":"1.168224030","rc":[{"batb":[[0,1.47,89.06],[1,1.44,151.58],[2,1.43,210.32]],"batl":[[0,1.48,171.13]],"ltp":1.48,"tv":577.47,"id":8908205},{"trd":[[3.1,38.65]],"batb":[[0,3.1,2.86]],"batl":[[0,3.15,19.32],[1,4.6,136.05]],"ltp":3.1,"tv":50.29,"id":4596961}],"tv":627.76}]}
{"op":"mcm","clk":"1004462495","pt":1580655218650,"mc":[{"id":"1.168224030","rc":[{"trd":[[3.1,44.38]],"batb":[[0,2.72,37.11],[1,1.01,10.51],[2,1.01,0]],"batl":[[0,3.1,16.46],[1,3.15,19.32],[2,4.6,136.05]],"ltp":3.1,"tv":56.02,"id":4596961}],"tv":633.49}]}
{"op":"mcm","clk":"1004462546","pt":1580655219175,"mc":[{"id":"1.168224030","rc":[{"batl":[[0,3.15,19.32],[1,4.6,136.05],[2,4.6,0]],"ltp":3.1,"tv":56.02,"id":4596961}]}]}
{"op":"mcm","clk":"1004463277","pt":1580655224358,"mc":[{"id":"1.168224030","rc":[{"batb":[[1,1.43,210.32],[2,1.42,47.45]],"ltp":1.48,"tv":577.47,"id":8908205}]}]}
{"op":"mcm","clk":"1004463742","pt":1580655227769,"mc":[{"id":"1.168224030","rc":[{"batb":[[1,1.43,340.39],[2,1.42,266.25]],"ltp":1.48,"tv":577.47,"id":8908205}]}]}
{"op":"mcm","clk":"1004464482","pt":1580655233082,"mc":[{"id":"1.168224030","rc":[{"trd":[[1.47,178.12]],"batb":[[0,1.33,62.47],[1,1.01,10.51],[2,1.42,0]],"batl":[[0,1.47,78.98],[1,1.58,42.01],[2,1.82,469.11]],"ltp":1.47,"tv":755.59,"id":8908205}],"tv":811.61}]}
{"op":"mcm","clk":"1004464584","pt":1580655233879,"mc":[{"id":"1.168224030","rc":[{"batl":[[1,1.82,469.11],[2,1.82,0]],"ltp":1.47,"tv":755.59,"id":8908205},{"batb":[[0,2.72,12.75]],"batl":[[0,4.6,136.05],[1,4.6,0]],"ltp":3.1,"tv":56.02,"id":4596961}]}]}
{"op":"mcm","clk":"1004464908","pt":1580655236066,"mc":[{"id":"1.168224030","rc":[{"batb":[[0,1.36,59.01]],"ltp":1.47,"tv":755.59,"id":8908205},{"batb":[[0,2.6,13.77]],"ltp":3.1,"tv":56.02,"id":4596961}]}]}
{"op":"mcm","clk":"1004465164","pt":1580655237976,"mc":[{"id":"1.168224030","rc":[{"batb":[[0,1.41,307.72],[1,1.4,232.98],[2,1.36,59.01]],"batl":[[0,1.46,274.31],[1,1.47,262.03],[2,1.82,469.11]],"ltp":1.47,"tv":755.59,"id":8908205}]}]}
{"op":"mcm","clk":"1004465716","pt":1580655241938,"mc":[{"id":"1.168224030","rc":[{"batb":[[0,1.36,59.01],[1,1.01,10.51],[2,1.36,0]],"batl":[[0,1.47,78.98],[1,1.82,469.11],[2,1.82,0]],"ltp":1.47,"tv":755.59,"id":8908205}]}]}
{"op":"mcm","clk":"1004465994","pt":1580655243852,"mc":[{"id":"1.168224030","rc":[{"batl":[[2,1000,3.04]],"ltp":1.47,"tv":755.59,"id":8908205}]}]}
{"op":"mcm","clk":"1004466201","pt":1580655245087,"mc":[{"id":"1.168224030","rc":[{"batb":[[1,1.33,321.3],[2,1.32,310.4]],"batl":[[1,1.59,141.79],[2,1.6,132.89]],"ltp":1.47,"tv":755.59,"id":8908205}]}]}
{"op":"mcm","clk":"1004466585","pt":1580655247741,"mc":[{"id":"1.168224030","rc":[{"batl":[[0,1.47,78.99]],"ltp":1.47,"tv":755.59,"id":8908205}]}]}
{"op":"mcm","clk":"1004466924","pt":1580655250245,"mc":[{"id":"1.168224030","rc":[{"batb":[[1,1.01,10.51],[2,1.32,0]],"ltp":1.47,"tv":755.59,"id":8908205}]}]}
{"op":"mcm","clk":"1004467451","pt":1580655253921,"mc":[{"id":"1.168224030","rc":[{"trd":[[1.41,0.04],[1.47,336.08]],"batb":[[0,1.56,32.97],[1,1.54,94.62],[2,1.53,159.17]],"batl":[[0,1.59,141.79],[1,1.6,132.89],[2,1.82,469.11]],"ltp":1.47,"tv":913.58,"id":8908205},{"batb":[[1,2.28,19.91],[2,1.01,10.51]],"ltp":3.1,"tv":56.02,"id":4596961}],"tv":969.6}]}
{"op":"mcm","clk":"1004467723","pt":1580655255849,"mc":[{"id":"1.168224030","rc":[{"batl":[[0,3.05,37.86],[1,3.9,158.24]],"ltp":3.1,"tv":56.02,"id":4596961}]}]}
{"op":"mcm","clk":"1004467835","pt":1580655256505,"mc":[{"id":"1.168224030","rc":[{"batb":[[1,1.54,223.36]],"batl":[[0,1.59,168.57]],"ltp":1.47,"tv":913.58,"id":8908205},{"batl":[[0,2.86,21.85]],"ltp":3.1,"tv":56.02,"id":4596961}]}]}
{"op":"mcm","clk":"1004470551","pt":1580655273044,"mc":[{"id":"1.168224030","rc":[{"batb":[[1,1.54,77.3],[2,1.43,46.11]],"batl":[[0,1.82,469.11],[1,1.6,0],[2,1.82,0]],"ltp":1.47,"tv":913.58,"id":8908205}]}]}
{"op":"mcm","clk":"1004470684","pt":1580655273749,"mc":[{"id":"1.168224030","rc":[{"batb":[[0,1.43,46.11],[1,1.01,10.51],[2,1.43,0]],"ltp":1.47,"tv":913.58,"id":8908205},{"batb":[[0,2.28,19.91],[1,1.01,10.51],[2,1.01,0]],"batl":[[0,3.9,158.24],[1,3.9,0]],"ltp":3.1,"tv":56.02,"id":4596961}]}]}
{"op":"mcm","clk":"1004471004","pt":1580655275974,"mc":[{"id":"1.168224030","rc":[{"batb":[[1,1.41,200.38],[2,1.4,232.21]],"batl":[[0,1.73,153.11],[1,1.75,196.2],[2,1.82,469.11]],"ltp":1.47,"tv":913.58,"id":8908205}]}]}
{"op":"mcm","clk":"1004472531","pt":1580655285073,"mc":[{"id":"1.168224030","rc":[{"batl":[[0,1.82,469.11],[1,1.75,0],[2,1.82,0]],"ltp":1.47,"tv":913.58,"id":8908205}]}]}
{"op":"mcm","clk":"1004473073","pt":1580655288055,"mc":[{"id":"1.168224030","rc":[{"batl":[[0,1.45,186.69],[1,1.46,189.24],[2,1.82,469.11]],"ltp":1.47,"tv":913.58,"id":8908205}]}]}
{"op":"mcm","clk":"1004473216","pt":1580655288966,"mc":[{"id":"1.168224030","rc":[{"batb":[[0,1.43,143.57]],"ltp":1.47,"tv":913.58,"id":8908205},{"batb":[[0,3,23.05],[1,2.6,14.01],[2,1.01,10.51]],"batl":[[0,3.35,17.64]],"ltp":3.1,"tv":56.02,"id":4596961}]}]}
{"op":"mcm","clk":"1004473690","pt":1580655291762,"mc":[{"id":"1.168224030","rc":[{"batl":[[1,4.9,126.27]],"ltp":3.1,"tv":56.02,"id":4596961}]}]}
{"op":"mcm","clk":"1004476495","pt":1580655308892,"mc":[{"id":"1.168224030","rc":[{"batb":[[0,1.43,97.46],[1,1.33,63.81],[2,1.01,10.51]],"batl":[[0,1.82,469.11],[1,1.46,0],[2,1.82,0]],"ltp":1.47,"tv":913.58,"id":8908205},{"batb":[[0,2.6,14.01],[1,1.01,10.51],[2,1.01,0]],"ltp":3.1,"tv":56.02,"id":4596961}]}]}
{"op":"mcm","clk":"1004476647","pt":1580655309846,"mc":[{"id":"1.168224030","rc":[{"batb":[[0,1.33,63.81],[1,1.01,10.51],[2,1.01,0]],"ltp":1.47,"tv":913.58,"id":8908205},{"batl":[[0,4.9,126.27],[1,4.9,0]],"ltp":3.1,"tv":56.02,"id":4596961}]}]}
{"op":"mcm","clk":"1004476964","pt":1580655311705,"mc":[{"id":"1.168224030","rc":[{"batb":[[1,1.29,369.51],[2,1.28,368.08]],"batl":[[0,1.58,170.13],[1,1.59,135.97],[2,1.82,469.11]],"ltp":1.47,"tv":913.58,"id":8908205}]}]}
{"op":"mcm","clk":"1004479089","pt":1580655324742,"mc":[{"id":"1.168224030","rc":[{"batb":[[1,1.01,10.51],[2,1.28,0]],"ltp":1.47,"tv":913.58,"id":8908205}]}]}
{"op":"mcm","clk":"1004479644","pt":1580655328026,"mc":[{"id":"1.168224030","rc":[{"batb":[[0,1.53,160.1],[1,1.52,163.44],[2,1.33,63.81]],"ltp":1.47,"tv":913.58,"id":8908205}]}]}
{"op":"mcm","clk":"1004479777","pt":1580655328830,"mc":[{"id":"1.168224030","rc":[{"batb":[[0,1.56,32.5],[1,1.53,160.1],[2,1.52,244.1]],"ltp":1.47,"tv":913.58,"id":8908205},{"batb":[[1,2.18,22.19],[2,1.01,10.51]],"batl":[[0,2.9,21.85]],"ltp":3.1,"tv":56.02,"id":4596961}]}]}
{"op":"mcm","clk":"1004480074","pt":1580655330733,"mc":[{"id":"1.168224030","rc":[{"batl":[[1,3.9,158.24]],"ltp":3.1,"tv":56.02,"id":4596961}]}]}
{"op":"mcm","clk":"1004482296","pt":1580655345041,"mc":[{"id":"1.168224030","rc":[{"batb":[[1,1.52,80.66],[2,1.41,49.25]],"batl":[[0,1.82,469.11],[1,1.59,0],[2,1.82,0]],"ltp":1.47,"tv":913.58,"id":8908205}]}]}
{"op":"mcm","clk":"1004482428","pt":1580655345835,"mc":[{"id":"1.168224030","rc":[{"batb":[[0,1.41,49.25],[1,1.01,10.51],[2,1.41,0]],"ltp":1.47,"tv":913.58,"id":8908205},{"batb":[[0,2.18,22.19],[1,1.01,10.51],[2,1.01,0]],"batl":[[0,3.9,158.24],[1,3.9,0]],"ltp":3.1,"tv":56.02,"id":4596961}]}]}
{"op":"mcm","clk":"1004482521","pt":1580655346462,"mc":[{"id":"1.168224030","rc":[{"batb":[[0,1.41,49.27]],"ltp":1.47,"tv":913.58,"id":8908205}]}]}
{"op":"mcm","clk":"1004482748","pt":1580655348056,"mc":[{"id":"1.168224030","rc":[{"batb":[[1,1.37,198.17],[2,1.36,266.07]],"batl":[[0,1.76,120.72],[1,1.78,185.67],[2,1.82,469.11]],"ltp":1.47,"tv":913.58,"id":8908205}]}]}
{"op":"mcm","clk":"1004483986","pt":1580655356628,"mc":[{"id":"1.168224030","rc":[{"batl":[[0,1.82,469.11],[1,1.78,0],[2,1.82,0]],"ltp":1.47,"tv":913.58,"id":8908205}]}]}
{"op":"mcm","clk":"1004484552","pt":1580655360088,"mc":[{"id":"1.168224030","rc":[{"trd":[[1.41,98.58]],"batb":[[0,1.37,198.17],[1,1.36,266.07],[2,1.29,76.09]],"batl":[[0,1.41,235.85],[1,1.42,211.89]],"ltp":1.41,"tv":1012.12,"id":8908205},{"batb":[[0,3.1,21.17],[1,2.56,14.48],[2,1.01,10.51]],"ltp":3.1,"tv":56.02,"id":4596961}],"tv":1068.14}]}
{"op":"mcm","clk":"1004484708","pt":1580655360875,"mc":[{"id":"1.168224030","rc":[{"batb":[[0,1.39,107.54],[1,1.37,198.17],[2,1.36,266.07]],"ltp":1.41,"tv":1012.12,"id":8908205},{"batl":[[0,3.6,15.96]],"ltp":3.1,"tv":56.02,"id":4596961}]}]}
{"op":"mcm","clk":"1004484963","pt":1580655362464,"mc":[{"id":"1.168224030","rc":[{"batl":[[0,1.41,267.07]],"ltp":1.41,"tv":1012.12,"id":8908205}]}]}
{"op":"mcm","clk":"1004485079","pt":1580655363261,"mc":[{"id":"1.168224030","rc":[{"batl":[[2,1.73,527.57]],"ltp":1.41,"tv":1012.12,"id":8908205},{"batl":[[1,5.3,118.79]],"ltp":3.1,"tv":56.02,"id":4596961}]}]}
{"op":"mcm","clk":"1004487866","pt":1580655381981,"mc":[{"id":"1.168224030","rc":[{"batb":[[0,1.29,76.09],[1,1.01,10.51],[2,1.36,0]],"batl":[[0,1.73,527.57],[1,1.42,0],[2,1.73,0]],"ltp":1.41,"tv":1012.12,"id":8908205},{"batb":[[0,2.56,14.48],[1,1.01,10.51],[2,1.01,0]],"batl":[[0,5.3,118.79],[1,5.3,0]],"ltp":3.1,"tv":56.02,"id":4596961}]}]}
{"op":"mcm","clk":"1004488328","pt":1580655385065,"mc":[{"id":"1.168224030","rc":[{"batb":[[0,1.28,78.37],[1,1.22,506.26],[2,1.21,525.74]],"batl":[[0,1.58,173.63],[1,1.59,135.86],[2,1.73,527.57]],"ltp":1.41,"tv":1012.12,"id":8908205},{"batb":[[0,2.62,13.93]],"ltp":3.1,"tv":56.02,"id":4596961}]}]}
{"op":"mcm","clk":"1004489033","pt":1580655389790,"mc":[{"id":"1.168224030","rc":[{"batb":[[1,1.01,10.51],[2,1.21,0]],"ltp":1.41,"tv":1012.12,"id":8908205}]}]}
{"op":"mcm","clk":"1004489486","pt":1580655392916,"mc":[{"id":"1.168224030","rc":[{"batb":[[0,1.53,155.86],[1,1.52,163.31],[2,1.28,78.37]],"batl":[[2,1.73,0]],"ltp":1.41,"tv":1012.12,"id":8908205}]}]}
{"op":"mcm","clk":"1004489630","pt":1580655393928,"mc":[{"id":"1.168224030","rc":[{"batb":[[0,1.56,32.57],[1,1.53,155.86],[2,1.52,163.31]],"ltp":1.41,"tv":1012.12,"id":8908205},{"batb":[[1,2.2,22.03],[2,1.01,10.51]],"ltp":3.1,"tv":56.02,"id":4596961}]}]}
{"op":"mcm","clk":"1004489760","pt":1580655394836,"mc":[{"id":"1.168224030","rc":[{"batb":[[2,1.52,243.97]],"ltp":1.41,"tv":1012.12,"id":8908205},{"batl":[[0,2.92,21.85]],"ltp":3.1,"tv":56.02,"id":4596961}]}]}
{"op":"mcm","clk":"1004490000","pt":1580655396436,"mc":[{"id":"1.168224030","rc":[{"batl":[[2,1.95,409.86]],"ltp":1.41,"tv":1012.12,"id":8908205},{"batl":[[1,3.9,158.24]],"ltp":3.1,"tv":56.02,"id":4596961}]}]}
{"op":"mcm","clk":"1004492169","pt":1580655410950,"mc":[{"id":"1.168224030","rc":[{"batb":[[0,1.52,80.66],[1,1.41,49.25],[2,1.01,10.51]],"batl":[[0,1.95,409.86],[1,1.59,0],[2,1.95,0]],"ltp":1.41,"tv":1012.12,"id":8908205},{"batb":[[0,2.2,22.03],[1,1.01,10.51],[2,1.01,0]],"ltp":3.1,"tv":56.02,"id":4596961}]}]}
{"op":"mcm","clk":"1004492286","pt":1580655411848,"mc":[{"id":"1.168224030","rc":[{"batb":[[0,1.41,49.25],[1,1.01,10.51],[2,1.01,0]],"ltp":1.41,"tv":1012.12,"id":8908205},{"batl":[[0,3.9,158.24],[1,3.9,0]],"ltp":3.1,"tv":56.02,"id":4596961}]}]}
{"op":"mcm","clk":"1004492539","pt":1580655413441,"mc":[{"id":"1.168224030","rc":[{"batb":[[1,1.37,191.35],[2,1.36,265.76]],"batl":[[0,1.76,123.08],[1,1.78,185.55],[2,1.95,409.86]],"ltp":1.41,"tv":1012.12,"id":8908205}]}]}
{"op":"mcm","clk":"1004495310","pt":1580655432644,"mc":[{"id":"1.168224030","rc":[{"batb":[[1,1.01,10.51],[2,1.36,0]],"batl":[[0,1.95,409.86],[1,1.78,0],[2,1.95,0]],"ltp":1.41,"tv":1012.12,"id":8908205}]}]}
{"op":"mcm","clk":"1004495774","pt":1580655435813,"mc":[{"id":"1.168224030","rc":[{"trd":[[1.41,197.08]],"batb":[[0,1.37,191.35],[1,1.36,265.76],[2,1.01,10.51]],"batl":[[0,1.41,241.44],[1,1.42,211.65]],"ltp":1.41,"tv":1110.63,"id":8908205}],"tv":1166.65}]}
{"op":"mcm","clk":"1004495916","pt":1580655436815,"mc":[{"id":"1.168224030","rc":[{"batb":[[0,1.39,107.54],[1,1.37,191.35],[2,1.36,265.76]],"ltp":1.41,"tv":1110.63,"id":8908205},{"batb":[[0,3.15,21.17],[1,2.6,14.16],[2,1.01,10.51]],"batl":[[0,3.6,15.96]],"ltp":3.1,"tv":56.02,"id":4596961}]}]}
{"op":"mcm","clk":"1004496232","pt":1580655439041,"mc":[{"id":"1.168224030","rc":[{"batl":[[0,1.41,272.65],[2,1.73,527.57]],"ltp":1.41,"tv":1110.63,"id":8908205},{"batl":[[1,5.3,118.79]],"ltp":3.1,"tv":56.02,"id":4596961}]}]}
{"op":"mcm","clk":"1004499170","pt":1580655458771,"mc":[{"id":"1.168224030","rc":[{"batb":[[1,1.28,77.03],[2,1.01,10.51]],"batl":[[0,1.73,527.57],[1,1.42,0],[2,1.73,0]],"ltp":1.41,"tv":1110.63,"id":8908205},{"batb":[[0,2.6,14.16],[1,1.01,10.51],[2,1.01,0]],"ltp":3.1,"tv":56.02,"id":4596961}]}]}
{"op":"mcm","clk":"1004499345","pt":1580655459981,"mc":[{"id":"1.168224030","rc":[{"batb":[[0,1.28,77.03],[1,1.01,10.51],[2,1.01,0]],"ltp":1.41,"tv":1110.63,"id":8908205},{"batl":[[0,5.3,118.79],[1,5.3,0]],"ltp":3.1,"tv":56.02,"id":4596961}]}]}
{"op":"mcm","clk":"1004499502","pt":1580655461092,"mc":[{"id":"1.168224030","rc":[{"batb":[[1,1.22,492.44],[2,1.21,524.83]],"batl":[[0,1.58,176.94],[1,1.59,135.75],[2,1.73,527.57]],"ltp":1.41,"tv":1110.63,"id":8908205}]}]}
{"op":"mcm","clk":"1004499623","pt":1580655461984,"mc":[{"id":"1.168224030","rc":[{"batb":[[0,1.27,79.39],[1,1.01,10.51],[2,1.21,0]],"batl":[[0,1.73,527.57],[1,1.59,0],[2,1.73,0]],"ltp":1.41,"tv":1110.63,"id":8908205},{"batb":[[0,2.64,13.61]],"ltp":3.1,"tv":56.02,"id":4596961}]}]}
{"op":"mcm","clk":"1004499935","pt":1580655464074,"mc":[{"id":"1.168224030","rc":[{"batb":[[0,1.34,158.95],[1,1.33,296.15],[2,1.27,79.39]],"batl":[[0,1.37,167.06],[1,1.38,241.67],[2,1.73,527.57]],"ltp":1.41,"tv":1110.63,"id":8908205}]}]}
{"op":"mcm","clk":"1004500147","pt":1580655465378,"mc":[{"id":"1.168224030","rc":[{"batl":[[2,1.39,2]],"ltp":1.41,"tv":1110.63,"id":8908205}]}]}
{"op":"mcm","clk":"1004500573","pt":1580655468095,"mc":[{"id":"1.168224030","rc":[{"batb":[[0,1.27,79.39],[1,1.01,10.51],[2,1.27,0]],"batl":[[0,1.39,2],[1,1.73,527.57],[2,1.39,0]],"ltp":1.41,"tv":1110.63,"id":8908205}]}]}
{"op":"mcm","clk":"1004500969","pt":1580655470488,"mc":[{"id":"1.168224030","rc":[{"batb":[[1,1.22,497.18],[2,1.21,524.85]],"batl":[[1,1.58,173.37],[2,1.59,135.74]],"ltp":1.41,"tv":1110.63,"id":8908205}]}]}
{"op":"mcm","clk":"1004502990","pt":1580655483237,"mc":[{"id":"1.168224030","rc":[{"batb":[[1,1.01,10.51],[2,1.21,0]],"ltp":1.41,"tv":1110.63,"id":8908205}]}]}
{"op":"mcm","clk":"1004503628","pt":1580655487030,"mc":[{"id":"1.168224030","rc":[{"trd":[[1.39,4]],"batb":[[0,1.55,33.2],[1,1.53,157.91],[2,1.52,163.18]],"batl":[[0,1.58,173.37],[1,1.59,135.74],[2,1.59,0]],"ltp":1.39,"tv":1114.63,"id":8908205},{"batb":[[1,2.22,21.79],[2,1.01,10.51]],"ltp":3.1,"tv":56.02,"id":4596961}],"tv":1170.65}]}
{"op":"mcm","clk":"1004504049","pt":1580655489628,"mc":[{"id":"1.168224030","rc":[{"batb":[[2,1.52,243.84]],"batl":[[2,1.95,409.86]],"ltp":1.39,"tv":1114.63,"id":8908205},{"batl":[[0,2.92,21.85],[1,3.9,158.24]],"ltp":3.1,"tv":56.02,"id":4596961}]}]}
{"op":"mcm","clk":"1004507358","pt":1580655509069,"mc":[{"id":"1.168224030","rc":[{"batb":[[1,1.52,80.66],[2,1.4,49.73]],"batl":[[0,1.95,409.86],[1,1.59,0],[2,1.95,0]],"ltp":1.39,"tv":1114.63,"id":8908205}]}]}
{"op":"mcm","clk":"1004507504","pt":1580655509959,"mc":[{"id":"1.168224030","rc":[{"batb":[[0,1.4,49.73],[1,1.01,10.51],[2,1.4,0]],"ltp":1.39,"tv":1114.63,"id":8908205},{"batb":[[0,2.22,21.79],[1,1.01,10.51],[2,1.01,0]],"batl":[[0,3.9,158.24],[1,3.9,0]],"ltp":3.1,"tv":56.02,"id":4596961}]}]}
{"op":"mcm","clk":"1004507871","pt":1580655512052,"mc":[{"id":"1.168224030","rc":[{"batb":[[1,1.37,193.37],[2,1.36,265.47]],"batl":[[0,1.76,118.89],[1,1.78,185.43],[2,1.95,409.86]],"ltp":1.39,"tv":1114.63,"id":8908205}]}]}
{"op":"mcm","clk":"1004508210","pt":1580655514127,"mc":[{"id":"1.168224030","rc":[{"batb":[[1,1.01,10.51],[2,1.36,0]],"ltp":1.39,"tv":1114.63,"id":8908205}]}]}
{"op":"mcm","clk":"1004508488","pt":1580655515859,"mc":[{"id":"1.168224030","rc":[{"batl":[[2,1.95,0]],"ltp":1.39,"tv":1114.63,"id":8908205}]}]}
{"op":"mcm","clk":"1004508685","pt":1580655517078,"mc":[{"id":"1.168224030","rc":[{"batb":[[0,1.7,117.93],[1,1.68,223.02],[2,1.4,49.73]],"ltp":1.39,"tv":1114.63,"id":8908205}]}]}
{"op":"mcm","clk":"1004508843","pt":1580655517981,"mc":[{"id":"1.168224030","rc":[{"batb":[[0,1.74,21.95],[1,1.7,117.93],[2,1.68,223.02]],"ltp":1.39,"tv":1114.63,"id":8908205},{"batb":[[1,1.94,16.44],[2,1.01,10.51]],"ltp":3.1,"tv":56.02,"id":4596961}]}]}
{"op":"mcm","clk":"1004508989","pt":1580655518893,"mc":[{"id":"1.168224030","rc":[{"batl":[[0,2.54,26.89]],"ltp":3.1,"tv":56.02,"id":4596961}]}]}
{"op":"mcm","clk":"1004509094","pt":1580655519469,"mc":[{"id":"1.168224030","rc":[{"batl":[[2,2.16,342.82]],"ltp":1.39,"tv":1114.63,"id":8908205},{"batl":[[1,3.3,191.92]],"ltp":3.1,"tv":56.02,"id":4596961}]}]}
{"op":"mcm","clk":"1004509933","pt":1580655525055,"mc":[{"id":"1.168224030","rc":[{"batb":[[1,1.65,63.85],[2,1.56,32.5]],"ltp":1.39,"tv":1114.63,"id":8908205}]}]}
{"op":"mcm","clk":"1004510412","pt":1580655528008,"mc":[{"id":"1.168224030","rc":[{"batb":[[1,1.69,169.34],[2,1.67,228.28]],"batl":[[0,1.76,140.71]],"ltp":1.39,"tv":1114.63,"id":8908205}]}]}
{"op":"mcm","clk":"1004510684","pt":1580655529815,"mc":[{"id":"1.168224030","rc":[{"batl":[[0,1.76,175.74]],"ltp":1.39,"tv":1114.63,"id":8908205}]}]}
{"op":"mcm","clk":"1004511567","pt":1580655535105,"mc":[{"id":"1.168224030","rc":[{"batb":[[0,1.65,63.85],[1,1.56,32.5],[2,1.01,10.51]],"batl":[[0,2.16,342.82],[1,1.78,0],[2,2.16,0]],"ltp":1.39,"tv":1114.63,"id":8908205},{"batb":[[0,1.94,16.44],[1,1.01,10.51],[2,1.01,0]],"ltp":3.1,"tv":56.02,"id":4596961}]}]}
{"op":"mcm","clk":"1004511721","pt":1580655535897,"mc":[{"id":"1.168224030","rc":[{"batb":[[0,1.56,32.5],[1,1.01,10.51],[2,1.01,0]],"ltp":1.39,"tv":1114.63,"id":8908205},{"batl":[[0,3.3,191.92],[1,3.3,0]],"ltp":3.1,"tv":56.02,"id":4596961}]}]}
{"op":"mcm","clk":"1004512247","pt":1580655538933,"mc":[{"id":"1.168224030","rc":[{"batb":[[0,1.55,32.97]],"ltp":1.39,"tv":1114.63,"id":8908205},{"batb":[[0,1.95,16.13]],"ltp":3.1,"tv":56.02,"id":4596961}]}]}
{"op":"mcm","clk":"1004512458","pt":1580655540116,"mc":[{"id":"1.168224030","rc":[{"batb":[[0,1.65,214.31],[1,1.64,122.69],[2,1.55,32.97]],"batl":[[0,1.72,183.31],[1,1.74,199.81],[2,2.16,342.82]],"ltp":1.39,"tv":1114.63,"id":8908205}]}]}
{"op":"mcm","clk":"1004512969","pt":1580655543008,"mc":[{"id":"1.168224030","rc":[{"batb":[[0,1.55,32.97],[1,1.01,10.51],[2,1.55,0]],"batl":[[0,2.16,342.82],[1,1.74,0],[2,2.16,0]],"ltp":1.39,"tv":1114.63,"id":8908205}]}]}
{"op":"mcm","clk":"1004513503","pt":1580655546117,"mc":[{"id":"1.168224030","rc":[{"batb":[[1,1.52,223.62],[2,1.51,168.19]],"ltp":1.39,"tv":1114.63,"id":8908205}]}]}
{"op":"mcm","clk":"1004513977","pt":1580655548817,"mc":[{"id":"1.168224030","rc":[{"batb":[[1,1.53,78.98],[2,1.52,223.62]],"batl":[[0,1.57,125.83],[1,1.58,139.39]],"ltp":1.39,"tv":1114.63,"id":8908205},{"batl":[[0,2.92,21.85]],"ltp":3.1,"tv":56.02,"id":4596961}]}]}
{"op":"mcm","clk":"1004514107","pt":1580655549725,"mc":[{"id":"1.168224030","rc":[{"batb":[[0,2.64,13.77],[1,2.22,22.11],[2,1.01,10.51]],"ltp":3.1,"tv":56.02,"id":4596961}]}]}
{"op":"mcm","clk":"1004514273","pt":1580655550723,"mc":[{"id":"1.168224030","rc":[{"batl":[[2,1.95,409.86]],"ltp":1.39,"tv":1114.63,"id":8908205},{"batl":[[1,3.9,158.24]],"ltp":3.1,"tv":56.02,"id":4596961}]}]}
{"op":"mcm","clk":"1004517264","pt":1580655567929,"mc":[{"id":"1.168224030","rc":[{"batb":[[0,1.4,49.41],[1,1.01,10.51],[2,1.52,0]],"batl":[[0,1.95,409.86],[1,1.58,0],[2,1.95,0]],"ltp":1.39,"tv":1114.63,"id":8908205},{"batb":[[0,2.22,22.11],[1,1.01,10.51],[2,1.01,0]],"batl":[[0,3.9,158.24],[1,3.9,0]],"ltp":3.1,"tv":56.02,"id":4596961}]}]}
{"op":"mcm","clk":"1004517805","pt":1580655571016,"mc":[{"id":"1.168224030","rc":[{"batb":[[1,1.36,345.87],[2,1.35,277.79]],"batl":[[0,1.76,202.13],[1,1.78,185.36],[2,1.95,409.86]],"ltp":1.39,"tv":1114.63,"id":8908205}]}]}
{"op":"mcm","clk":"1004518982","pt":1580655578461,"mc":[{"id":"1.168224030","rc":[{"batl":[[0,1.95,409.86],[1,1.78,0],[2,1.95,0]],"ltp":1.39,"tv":1114.63,"id":8908205}]}]}
{"op":"mcm","clk":"1004519541","pt":1580655581926,"mc":[{"id":"1.168224030","rc":[{"trd":[[1.4,98.82]],"batb":[[0,1.36,345.87],[1,1.35,277.79],[2,1.28,78.37]],"batl":[[0,1.4,126.79],[1,1.41,219.76]],"ltp":1.4,"tv":1213.45,"id":8908205},{"batb":[[0,3.2,21.09],[1,2.62,14.16],[2,2.22,22.11]],"ltp":3.1,"tv":56.02,"id":4596961}],"tv":1269.47}]}
{"op":"mcm","clk":"1004519736","pt":1580655583030,"mc":[{"id":"1.168224030","rc":[{"batb":[[0,1.38,110.07],[1,1.36,345.87],[2,1.35,277.79]],"ltp":1.4,"tv":1213.45,"id":8908205},{"batb":[[2,1.01,10.51]],"batl":[[0,3.6,15.96]],"ltp":3.1,"tv":56.02,"id":4596961}]}]}
{"op":"mcm","clk":"1004520122","pt":1580655585044,"mc":[{"id":"1.168224030","rc":[{"batl":[[0,1.4,158.09],[2,1.73,527.57]],"ltp":1.4,"tv":1213.45,"id":8908205},{"batl":[[1,5.3,118.79]],"ltp":3.1,"tv":56.02,"id":4596961}]}]}
{"op":"mcm","clk":"1004522976","pt":1580655600794,"mc":[{"id":"1.168224030","rc":[{"batb":[[1,1.28,78.37],[2,1.01,10.51]],"batl":[[0,1.73,527.57],[1,1.41,0],[2,1.73,0]],"ltp":1.4,"tv":1213.45,"id":8908205},{"batb":[[0,2.62,14.16],[1,1.01,10.51],[2,1.01,0]],"ltp":3.1,"tv":56.02,"id":4596961}]}]}
{"op":"mcm","clk":"1004523234","pt":1580655601912,"mc":[{"id":"1.168224030","rc":[{"batb":[[0,1.28,78.37],[1,1.01,10.51],[2,1.01,0]],"ltp":1.4,"tv":1213.45,"id":8908205},{"batl":[[0,5.3,118.79],[1,5.3,0]],"ltp":3.1,"tv":56.02,"id":4596961}]}]}
{"op":"mcm","clk":"1004523694","pt":1580655604025,"mc":[{"id":"1.168224030","rc":[{"batb":[[0,1.27,80.81],[1,1.22,358.66],[2,1.21,521.68]],"batl":[[0,1.57,128.45],[1,1.58,139.29],[2,1.73,527.57]],"ltp":1.4,"tv":1213.45,"id":8908205},{"batb":[[0,2.66,13.61]],"ltp":3.1,"tv":56.02,"id":4596961}]}]}
{"op":"mcm","clk":"1004523910","pt":1580655605045,"mc":[{"id":"1.168224030","rc":[{"batb":[[1,1.01,10.51],[2,1.21,0]],"batl":[[0,1.73,527.57],[1,1.58,0],[2,1.73,0]],"ltp":1.4,"tv":1213.45,"id":8908205}]}]}
{"op":"mcm","clk":"1004524467","pt":1580655607889,"mc":[{"id":"1.168224030","rc":[{"batb":[[0,1.33,340.34],[1,1.32,310.96],[2,1.27,80.81]],"batl":[[0,1.37,275.03],[1,1.38,240.66],[2,1.73,527.57]],"ltp":1.4,"tv":1213.45,"id":8908205}]}]}
{"op":"mcm","clk":"1004525091","pt":1580655611018,"mc":[{"id":"1.168224030","rc":[{"batb":[[0,1.27,80.81],[1,1.01,10.51],[2,1.27,0]],"batl":[[0,1.73,527.57],[1,1.38,0],[2,1.73,0]],"ltp":1.4,"tv":1213.45,"id":8908205}]}]}
{"op":"mcm","clk":"1004525517","pt":1580655613670,"mc":[{"id":"1.168224030","rc":[{"batb":[[1,1.22,364.88],[2,1.21,521.7]],"batl":[[0,1.57,124.57],[1,1.58,139.29],[2,1.73,527.57]],"ltp":1.4,"tv":1213.45,"id":8908205}]}]}
{"op":"mcm","clk":"1004526495","pt":1580655619737,"mc":[{"id":"1.168224030","rc":[{"batb":[[1,1.01,10.51],[2,1.21,0]],"ltp":1.4,"tv":1213.45,"id":8908205}]}]}
{"op":"mcm","clk":"1004527064","pt":1580655623063,"mc":[{"id":"1.168224030","rc":[{"batb":[[0,1.52,224.32],[1,1.51,168.07],[2,1.27,80.81]],"batl":[[2,1.73,0]],"ltp":1.4,"tv":1213.45,"id":8908205}]}]}
{"op":"mcm","clk":"1004527216","pt":1580655623870,"mc":[{"id":"1.168224030","rc":[{"batb":[[0,1.55,33.2],[1,1.52,224.32],[2,1.51,168.07]],"ltp":1.4,"tv":1213.45,"id":8908205},{"batb":[[1,2.24,21.64],[2,1.01,10.51]],"ltp":3.1,"tv":56.02,"id":4596961}]}]}
{"op":"mcm","clk":"1004527380","pt":1580655624898,"mc":[{"id":"1.168224030","rc":[{"batb":[[1,1.52,304.98]],"ltp":1.4,"tv":1213.45,"id":8908205},{"batl":[[0,2.92,21.85]],"ltp":3.1,"tv":56.02,"id":4596961}]}]}
{"op":"mcm","clk":"1004527656","pt":1580655626607,"mc":[{"id":"1.168224030","rc":[{"batl":[[2,1.95,409.86]],"ltp":1.4,"tv":1213.45,"id":8908205},{"batl":[[1,3.9,158.24]],"ltp":3.1,"tv":56.02,"id":4596961}]}]}
{"op":"mcm","clk":"1004530518","pt":1580655644011,"mc":[{"id":"1.168224030","rc":[{"batb":[[0,1.4,50.36],[1,1.01,10.51],[2,1.51,0]],"batl":[[0,1.95,409.86],[1,1.58,0],[2,1.95,0]],"ltp":1.4,"tv":1213.45,"id":8908205},{"batb":[[0,2.24,21.64],[1,1.01,10.51],[2,1.01,0]],"batl":[[0,3.9,158.24],[1,3.9,0]],"ltp":3.1,"tv":56.02,"id":4596961}]}]}
{"op":"mcm","clk":"1004531011","pt":1580655646735,"mc":[{"id":"1.168224030","rc":[{"batb":[[1,1.36,344.72],[2,1.35,277.49]],"batl":[[0,1.76,200.33],[1,1.78,185.25],[2,1.95,409.86]],"ltp":1.4,"tv":1213.45,"id":8908205}]}]}
{"op":"mcm","clk":"1004531306","pt":1580655648245,"mc":[{"id":"1.168224030","rc":[{"batl":[[0,1.95,409.86],[1,1.78,0],[2,1.95,0]],"ltp":1.4,"tv":1213.45,"id":8908205}]}]}
{"op":"mcm","clk":"1004532003","pt":1580655651936,"mc":[{"id":"1.168224030","rc":[{"trd":[[1.4,199.53]],"batb":[[0,1.36,344.72],[1,1.35,277.49],[2,1.28,78.6]],"batl":[[0,1.4,125.92],[1,1.41,219.52]],"ltp":1.4,"tv":1314.15,"id":8908205},{"batb":[[0,3.2,20.54],[1,2.62,14.01],[2,2.24,21.64]],"ltp":3.1,"tv":56.02,"id":4596961}],"tv":1370.18}]}
{"op":"mcm","clk":"1004532160","pt":1580655652948,"mc":[{"id":"1.168224030","rc":[{"batb":[[0,1.38,110.07],[1,1.36,344.72],[2,1.35,277.49]],"ltp":1.4,"tv":1314.15,"id":8908205},{"batb":[[2,1.01,10.51]],"batl":[[0,3.6,15.96]],"ltp":3.1,"tv":56.02,"id":4596961}]}]}
{"op":"mcm","clk":"1004532225","pt":1580655653321,"mc":[{"id":"1.168224030","rc":[{"batl":[[2,1.73,527.57]],"ltp":1.4,"tv":1314.15,"id":8908205},{"batl":[[1,5.3,118.79]],"ltp":3.1,"tv":56.02,"id":4596961}]}]}
{"op":"mcm","clk":"1004532411","pt":1580655654438,"mc":[{"id":"1.168224030","rc":[{"batl":[[0,1.4,157.83]],"ltp":1.4,"tv":1314.15,"id":8908205}]}]}
{"op":"mcm","clk":"1004534930","pt":1580655668768,"mc":[{"id":"1.168224030","rc":[{"batb":[[1,1.28,78.6],[2,1.01,10.51]],"batl":[[0,1.73,527.57],[1,1.41,0],[2,1.73,0]],"ltp":1.4,"tv":1314.15,"id":8908205},{"batb":[[0,2.62,14.01],[1,1.01,10.51],[2,1.01,0]],"ltp":3.1,"tv":56.02,"id":4596961}]}]}
{"op":"mcm","clk":"1004535139","pt":1580655669971,"mc":[{"id":"1.168224030","rc":[{"batb":[[0,1.28,78.6],[1,1.01,10.51],[2,1.01,0]],"ltp":1.4,"tv":1314.15,"id":8908205},{"batl":[[0,5.3,118.79],[1,5.3,0]],"ltp":3.1,"tv":56.02,"id":4596961}]}]}
{"op":"mcm","clk":"1004535353","pt":1580655671036,"mc":[{"id":"1.168224030","rc":[{"batb":[[1,1.22,352.57],[2,1.21,520.81]],"batl":[[0,1.57,126.71],[1,1.58,139.17],[2,1.73,527.57]],"ltp":1.4,"tv":1314.15,"id":8908205}]}]}
{"op":"mcm","clk":"1004535510","pt":1580655671954,"mc":[{"id":"1.168224030","rc":[{"batb":[[0,1.27,80.96]],"ltp":1.4,"tv":1314.15,"id":8908205},{"batb":[[0,2.66,13.45]],"ltp":3.1,"tv":56.02,"id":4596961}]}]}
{"op":"mcm","clk":"1004536138","pt":1580655674809,"mc":[{"id":"1.168224030","rc":[{"batb":[[1,1.01,10.51],[2,1.21,0]],"ltp":1.4,"tv":1314.15,"id":8908205}]}]}
{"op":"mcm","clk":"1004536649","pt":1580655677111,"mc":[{"id":"1.168224030","rc":[{"batl":[[2,1.73,0]],"ltp":1.4,"tv":1314.15,"id":8908205}]}]}
{"op":"mcm","clk":"1004536801","pt":1580655677984,"mc":[{"id":"1.168224030","rc":[{"batb":[[0,1.52,221.5],[1,1.51,167.93],[2,1.27,80.96]],"ltp":1.4,"tv":1314.15,"id":8908205}]}]}
{"op":"mcm","clk":"1004536984","pt":1580655678886,"mc":[{"id":"1.168224030","rc":[{"batb":[[0,1.54,33.52],[1,1.52,302.16],[2,1.51,167.93]],"ltp":1.4,"tv":1314.15,"id":8908205},{"batb":[[1,2.26,21.24],[2,1.01,10.51]],"batl":[[0,2.92,21.85]],"ltp":3.1,"tv":56.02,"id":4596961}]}]}
{"op":"mcm","clk":"1004537314","pt":1580655680674,"mc":[{"id":"1.168224030","rc":[{"batl":[[2,1.95,409.86]],"ltp":1.4,"tv":1314.15,"id":8908205},{"batl":[[1,3.9,158.24]],"ltp":3.1,"tv":56.02,"id":4596961}]}]}
{"op":"mcm","clk":"1004539887","pt":1580655694103,"mc":[{"id":"1.168224030","rc":[{"batb":[[1,1.52,80.66],[2,1.4,50.75]],"batl":[[0,1.95,409.86],[1,1.58,0],[2,1.95,0]],"ltp":1.4,"tv":1314.15,"id":8908205}]}]}
{"op":"mcm","clk":"1004540015","pt":1580655694794,"mc":[{"id":"1.168224030","rc":[{"batb":[[0,1.52,80.66],[1,1.4,50.75],[2,1.01,10.51]],"ltp":1.4,"tv":1314.15,"id":8908205},{"batb":[[0,2.26,21.24],[1,1.01,10.51],[2,1.01,0]],"ltp":3.1,"tv":56.02,"id":4596961}]}]}
{"op":"mcm","clk":"1004540419","pt":1580655697033,"mc":[{"id":"1.168224030","rc":[{"batb":[[0,1.4,50.75],[1,1.36,339.41],[2,1.35,277.2]],"batl":[[0,1.76,201.58],[1,1.78,185.13],[2,1.95,409.86]],"ltp":1.4,"tv":1314.15,"id":8908205},{"batl":[[0,3.9,158.24],[1,3.9,0]],"ltp":3.1,"tv":56.02,"id":4596961}]}]}
{"op":"mcm","clk":"1004540618","pt":1580655698011,"mc":[{"id":"1.168224030","rc":[{"batb":[[1,1.01,10.51],[2,1.35,0]],"batl":[[0,1.95,409.86],[1,1.78,0],[2,1.95,0]],"ltp":1.4,"tv":1314.15,"id":8908205}]}]}
{"op":"mcm","clk":"1004540934","pt":1580655699723,"mc":[{"id":"1.168224030","rc":[{"batb":[[0,1.49,148.87],[1,1.48,181.81],[2,1.4,50.75]],"batl":[[0,1.54,245.78],[1,1.55,148.86],[2,1.95,409.86]],"ltp":1.4,"tv":1314.15,"id":8908205}]}]}
{"op":"mcm","clk":"1004541656","pt":1580655703800,"mc":[{"id":"1.168224030","rc":[{"batb":[[0,1.4,50.75],[1,1.01,10.51],[2,1.4,0]],"batl":[[0,1.95,409.86],[1,1.55,0],[2,1.95,0]],"ltp":1.4,"tv":1314.15,"id":8908205}]}]}
{"op":"mcm","clk":"1004542227","pt":1580655706969,"mc":[{"id":"1.168224030","rc":[{"batb":[[1,1.36,339.41],[2,1.35,277.2]],"batl":[[0,1.76,201.58],[1,1.78,185.13],[2,1.95,409.86]],"ltp":1.4,"tv":1314.15,"id":8908205}]}]}
{"op":"mcm","clk":"1004542525","pt":1580655708628,"mc":[{"id":"1.168224030","rc":[{"batb":[[1,1.01,10.51],[2,1.35,0]],"batl":[[0,1.95,409.86],[1,1.78,0],[2,1.95,0]],"ltp":1.4,"tv":1314.15,"id":8908205}]}]}
{"op":"mcm","clk":"1004543124","pt":1580655711897,"mc":[{"id":"1.168224030","rc":[{"batb":[[0,1.69,141.14],[1,1.67,227.88],[2,1.4,50.75]],"batl":[[0,1.76,201.58],[1,1.78,185.13]],"ltp":1.4,"tv":1314.15,"id":8908205}]}]}
{"op":"mcm","clk":"1004543336","pt":1580655713081,"mc":[{"id":"1.168224030","rc":[{"batb":[[0,1.73,22.5],[1,1.69,141.14],[2,1.67,227.88]],"ltp":1.4,"tv":1314.15,"id":8908205},{"batb":[[1,1.97,15.74],[2,1.01,10.51]],"batl":[[0,2.56,26.89]],"ltp":3.1,"tv":56.02,"id":4596961}]}]}
{"op":"mcm","clk":"1004543548","pt":1580655714262,"mc":[{"id":"1.168224030","rc":[{"batl":[[2,2.16,342.82]],"ltp":1.4,"tv":1314.15,"id":8908205},{"batl":[[1,3.3,191.92]],"ltp":3.1,"tv":56.02,"id":4596961}]}]}
{"op":"mcm","clk":"1004546576","pt":1580655730114,"mc":[{"id":"1.168224030","rc":[{"batb":[[1,1.64,65.54],[2,1.55,32.97]],"batl":[[0,2.16,342.82],[1,1.78,0],[2,2.16,0]],"ltp":1.4,"tv":1314.15,"id":8908205}]}]}
{"op":"mcm","clk":"1004546766","pt":1580655731080,"mc":[{"id":"1.168224030","rc":[{"batb":[[0,1.64,65.54],[1,1.55,32.97],[2,1.01,10.51]],"ltp":1.4,"tv":1314.15,"id":8908205},{"batb":[[0,1.97,15.74],[1,1.01,10.51],[2,1.01,0]],"ltp":3.1,"tv":56.02,"id":4596961}]}]}
{"op":"mcm","clk":"1004546955","pt":1580655732092,"mc":[{"id":"1.168224030","rc":[{"batb":[[0,1.55,32.97],[1,1.01,10.51],[2,1.01,0]],"ltp":1.4,"tv":1314.15,"id":8908205},{"batl":[[0,3.3,191.92],[1,3.3,0]],"ltp":3.1,"tv":56.02,"id":4596961}]}]}
{"op":"mcm","clk":"1004547098","pt":1580655732861,"mc":[{"id":"1.168224030","rc":[{"batb":[[1,1.52,190.05],[2,1.51,167.75]],"batl":[[0,1.94,113.32],[1,1.96,137.01],[2,2.16,342.82]],"ltp":1.4,"tv":1314.15,"id":8908205}]}]}
{"op":"mcm","clk":"1004552388","pt":1580655759681,"mc":[{"id":"1.168224030","rc":[{"batb":[[1,1.01,10.51],[2,1.51,0]],"ltp":1.4,"tv":1314.15,"id":8908205}]}]}
{"op":"mcm","clk":"1004553129","pt":1580655763076,"mc":[{"id":"1.168224030","rc":[{"trd":[[1.94,2.41]],"batb":[[0,1.86,147.4],[1,1.84,164.24],[2,1.75,55.45]],"batl":[[0,1.94,110.91]],"ltp":1.94,"tv":1316.56,"id":8908205},{"trd":[[2.06,2.27]],"ltp":2.06,"tv":58.29,"id":4596961}],"tv":1374.86}]}
{"op":"mcm","clk":"1004553256","pt":1580655763767,"mc":[{"id":"1.168224030","rc":[{"trd":[[1.94,33.25]],"batb":[[2,1.78,20.3]],"batl":[[0,1.94,95.49]],"ltp":1.94,"tv":1347.41,"id":8908205},{"batb":[[1,1.77,22.19],[2,1.01,10.51]],"batl":[[0,2.32,31.09]],"ltp":2.06,"tv":58.29,"id":4596961}],"tv":1405.7}]}
{"op":"mcm","clk":"1004553662","pt":1580655765737,"mc":[{"id":"1.168224030","rc":[{"batl":[[1,2.92,221.26]],"ltp":2.06,"tv":58.29,"id":4596961}]}]}
{"op":"mcm","clk":"1004554801","pt":1580655771580,"mc":[{"id":"1.168224030","rc":[{"batb":[[0,1.93,15.82],[1,1.86,147.4],[2,1.84,164.24]],"ltp":1.94,"tv":1347.41,"id":8908205},{"batb":[[0,1.98,30.76],[1,1.78,21.56]],"ltp":2.06,"tv":58.29,"id":4596961}]}]}
{"op":"mcm","clk":"1004556471","pt":1580655779666,"mc":[{"id":"1.168224030","rc":[{"batb":[[0,1.91,16.13]],"ltp":1.94,"tv":1347.41,"id":8908205},{"batb":[[0,2,30.06],[1,1.79,21.09]],"ltp":2.06,"tv":58.29,"id":4596961}]}]}
{"op":"mcm","clk":"1004577967","pt":1580655881434,"mc":[{"id":"1.168224030","rc":[{"batb":[[0,1.76,54.61],[1,1.75,21.32],[2,1.01,10.51]],"batl":[[0,2.16,342.82],[1,3,2.41],[2,2.16,0]],"ltp":1.94,"tv":1347.41,"id":8908205},{"batb":[[0,1.79,21.09],[1,1.01,10.51],[2,1.01,0]],"ltp":2.06,"tv":58.29,"id":4596961}]}]}
{"op":"mcm","clk":"1004578239","pt":1580655882746,"mc":[{"id":"1.168224030","rc":[{"batb":[[0,1.75,21.32],[1,1.01,10.51],[2,1.01,0]],"ltp":1.94,"tv":1347.41,"id":8908205},{"batl":[[0,2.92,221.26],[1,2.92,0]],"ltp":2.06,"tv":58.29,"id":4596961}]}]}
{"op":"mcm","clk":"1004578676","pt":1580655884963,"mc":[{"id":"1.168224030","rc":[{"batb":[[1,1.73,167.27],[2,1.71,210]],"batl":[[1,2.2,102.86],[2,2.22,95.49]],"ltp":1.94,"tv":1347.41,"id":8908205}]}]}
{"op":"mcm","clk":"1004578825","pt":1580655885623,"mc":[{"id":"1.168224030","rc":[{"batb":[[1,1.01,10.51],[2,1.71,0]],"batl":[[1,3,2.41],[2,2.22,0]],"ltp":1.94,"tv":1347.41,"id":8908205}]}]}
{"op":"mcm","clk":"1004579305","pt":1580655887843,"mc":[{"id":"1.168224030","rc":[{"batl":[[0,3,2.41],[1,3,0]],"ltp":1.94,"tv":1347.41,"id":8908205}]}]}
{"op":"mcm","clk":"1004579530","pt":1580655888955,"mc":[{"id":"1.168224030","rc":[{"batb":[[0,1.9,171.3],[1,1.88,153.27],[2,1.75,21.32]],"batl":[[0,1.99,125.48],[1,2.02,188.91],[2,3,2.41]],"ltp":1.94,"tv":1347.41,"id":8908205}]}]}
{"op":"mcm","clk":"1004580175","pt":1580655891851,"mc":[{"id":"1.168224030","rc":[{"batl":[[2,2.42,286.52]],"ltp":1.94,"tv":1347.41,"id":8908205}]}]}
{"op":"mcm","clk":"1004580787","pt":1580655894474,"mc":[{"id":"1.168224030","rc":[{"batb":[[0,1.75,21.32],[1,1.01,10.51],[2,1.75,0]],"batl":[[0,2.42,286.52],[1,3,2.41],[2,2.42,0]],"ltp":1.94,"tv":1347.41,"id":8908205}]}]}
{"op":"mcm","clk":"1004581442","pt":1580655897400,"mc":[{"id":"1.168224030","rc":[{"batb":[[1,1.73,167.17],[2,1.71,210]],"batl":[[0,2.2,102.94],[1,2.22,95.49],[2,2.42,286.52]],"ltp":1.94,"tv":1347.41,"id":8908205}]}]}
{"op":"mcm","clk":"1004582528","pt":1580655902530,"mc":[{"id":"1.168224030","rc":[{"batb":[[1,1.01,10.51],[2,1.71,0]],"batl":[[0,2.42,286.52],[1,3,2.41],[2,2.42,0]],"ltp":1.94,"tv":1347.41,"id":8908205}]}]}
{"op":"mcm","clk":"1004583056","pt":1580655904991,"mc":[{"id":"1.168224030","rc":[{"batl":[[0,3,2.41],[1,3,0]],"ltp":1.94,"tv":1347.41,"id":8908205}]}]}
{"op":"mcm","clk":"1004583229","pt":1580655905829,"mc":[{"id":"1.168224030","rc":[{"batb":[[0,1.83,151.82],[1,1.81,172.98],[2,1.79,21.09]],"batl":[[0,1.91,132.68],[1,1.93,143.39]],"ltp":2.06,"tv":58.29,"id":4596961}]}]}
{"op":"mcm","clk":"1004583517","pt":1580655907097,"mc":[{"id":"1.168224030","rc":[{"batb":[[0,2.14,22.74],[1,1.95,43.69],[2,1.94,15.58]],"ltp":1.94,"tv":1347.41,"id":8908205},{"batl":[[2,2.06,39.49]],"ltp":2.06,"tv":58.29,"id":4596961}]}]}
{"op":"mcm","clk":"1004583897","pt":1580655908990,"mc":[{"id":"1.168224030","rc":[{"batl":[[0,2.72,241.55],[1,3,2.41]],"ltp":1.94,"tv":1347.41,"id":8908205}]}]}
{"op":"mcm","clk":"1004584213","pt":1580655910596,"mc":[{"id":"1.168224030","rc":[{"batl":[[2,2.5,274.54]],"ltp":2.06,"tv":58.29,"id":4596961}]}]}
{"op":"mcm","clk":"1004584772","pt":1580655913535,"mc":[{"id":"1.168224030","rc":[{"batl":[[2,2.04,40.33]],"ltp":2.06,"tv":58.29,"id":4596961}]}]}
{"op":"mcm","clk":"1004585705","pt":1580655918075,"mc":[{"id":"1.168224030","rc":[{"batb":[[0,1.79,21.09],[1,1.61,30.69],[2,1.01,10.51]],"batl":[[0,2.04,40.33],[1,2.5,274.54],[2,2.04,0]],"ltp":2.06,"tv":58.29,"id":4596961}]}]}
{"op":"mcm","clk":"1004585730","pt":1580655918143,"mc":[{"id":"1.168224030","rc":[{"batb":[[0,1.94,15.58],[1,1.01,10.51],[2,1.94,0]],"ltp":1.94,"tv":1347.41,"id":8908205},{"batb":[[0,1.61,30.69],[1,1.01,10.51],[2,1.01,0]],"batl":[[0,2.5,274.54],[1,2.5,0]],"ltp":2.06,"tv":58.29,"id":4596961}]}]}
{"op":"mcm","clk":"1004587041","pt":1580655924464,"mc":[{"id":"1.168224030","rc":[{"batb":[[0,1.78,178.35],[1,1.76,189.79],[2,1.61,30.69]],"batl":[[0,1.86,153.27],[1,1.88,155.3],[2,2.5,274.54]],"ltp":2.06,"tv":58.29,"id":4596961}]}]}
{"op":"mcm","clk":"1004587512","pt":1580655926753,"mc":[{"id":"1.168224030","rc":[{"batb":[[0,1.61,30.69],[1,1.01,10.51],[2,1.61,0]],"batl":[[0,2.5,274.54],[1,1.88,0],[2,2.5,0]],"ltp":2.06,"tv":58.29,"id":4596961}]}]}
{"op":"mcm","clk":"1004588142","pt":1580655929757,"mc":[{"id":"1.168224030","rc":[{"batb":[[0,1.61,261.61],[1,1.6,133.54],[2,1.01,10.51]],"batl":[[0,2.12,152.06],[1,2.14,106.06],[2,2.5,274.54]],"ltp":2.06,"tv":58.29,"id":4596961}]}]}
{"op":"mcm","clk":"1004590465","pt":1580655940875,"mc":[{"id":"1.168224030","rc":[{"batl":[[0,2.5,274.54],[1,2.14,0],[2,2.5,0]],"ltp":2.06,"tv":58.29,"id":4596961}]}]}
{"op":"mcm","clk":"1004591115","pt":1580655944122,"mc":[{"id":"1.168224030","rc":[{"batl":[[0,3,2.41],[1,3,0]],"ltp":1.94,"tv":1347.41,"id":8908205},{"batl":[[0,1.68,219.27],[1,1.7,214.24]],"ltp":2.06,"tv":58.29,"id":4596961}]}]}
{"op":"mcm","clk":"1004591289","pt":1580655945094,"mc":[{"id":"1.168224030","rc":[{"batb":[[0,2.5,14.95],[1,2.28,32.77],[2,2.22,20.69]],"ltp":1.94,"tv":1347.41,"id":8908205},{"batb":[[2,1.47,43.35]],"batl":[[2,1.79,42.01]],"ltp":2.06,"tv":58.29,"id":4596961}]}]}
{"op":"mcm","clk":"1004591812","pt":1580655947626,"mc":[{"id":"1.168224030","rc":[{"batl":[[1,3.15,200.42]],"ltp":1.94,"tv":1347.41,"id":8908205}]}]}
{"op":"mcm","clk":"1004592058","pt":1580655948796,"mc":[{"id":"1.168224030","rc":[{"batl":[[2,2.22,329.01]],"ltp":2.06,"tv":58.29,"id":4596961}]}]}
{"op":"mcm","clk":"1004592636","pt":1580655951833,"mc":[{"id":"1.168224030","rc":[{"batl":[[2,1.78,42.01]],"ltp":2.06,"tv":58.29,"id":4596961}]}]}
{"op":"mcm","clk":"1004593763","pt":1580655957592,"mc":[{"id":"1.168224030","rc":[{"trd":[[1.61,3.46]],"batb":[[0,1.61,259.88]],"ltp":1.61,"tv":61.75,"id":4596961}],"tv":1409.16}]}
{"op":"mcm","clk":"1004595000","pt":1580655963615,"mc":[{"id":"1.168224030","rc":[{"batb":[[0,2.28,32.77],[1,2.22,20.69],[2,1.01,10.51]],"ltp":1.94,"tv":1347.41,"id":8908205},{"batb":[[0,1.47,43.35],[1,1.01,10.51],[2,1.47,0]],"batl":[[0,1.78,42.01],[1,2.22,329.01],[2,1.78,0]],"ltp":1.61,"tv":61.75,"id":4596961}]}]}
{"op":"mcm","clk":"1004595216","pt":1580655964524,"mc":[{"id":"1.168224030","rc":[{"batb":[[0,2.22,20.69],[1,1.01,10.51],[2,1.01,0]],"ltp":1.94,"tv":1347.41,"id":8908205},{"batl":[[0,2.22,329.01],[1,2.22,0]],"ltp":1.61,"tv":61.75,"id":4596961}]}]}
{"op":"mcm","clk":"1004595583","pt":1580655966338,"mc":[{"id":"1.168224030","rc":[{"batb":[[1,1.44,312.44],[2,1.43,209.93]],"batl":[[0,1.83,106.19],[1,1.85,163.37],[2,2.22,329.01]],"ltp":1.61,"tv":61.75,"id":4596961}]}]}
{"op":"mcm","clk":"1004596732","pt":1580655971877,"mc":[{"id":"1.168224030","rc":[{"batb":[[1,1.01,10.51],[2,1.43,0]],"ltp":1.61,"tv":61.75,"id":4596961}]}]}
{"op":"mcm","clk":"1004597123","pt":1580655973741,"mc":[{"id":"1.168224030","rc":[{"batl":[[1,3.15,0]],"ltp":1.94,"tv":1347.41,"id":8908205}]}]}
{"op":"mcm","clk":"1004597400","pt":1580655975086,"mc":[{"id":"1.168224030","rc":[{"batb":[[0,1.76,162.8],[1,1.74,197.15],[2,1.47,43.35]],"ltp":1.61,"tv":61.75,"id":4596961}]}]}
{"op":"mcm","clk":"1004597615","pt":1580655976057,"mc":[{"id":"1.168224030","rc":[{"batb":[[1,1.95,30.61],[2,1.01,10.51]],"ltp":1.94,"tv":1347.41,"id":8908205},{"batb":[[1,1.75,23.05],[2,1.74,197.15]],"ltp":1.61,"tv":61.75,"id":4596961}]}]}
{"op":"mcm","clk":"1004597984","pt":1580655977860,"mc":[{"id":"1.168224030","rc":[{"batb":[[1,2.08,38.65],[2,1.95,30.61]],"batl":[[0,2.82,231.28],[1,3,2.41]],"ltp":1.94,"tv":1347.41,"id":8908205},{"batl":[[2,1.93,42.01]],"ltp":1.61,"tv":61.75,"id":4596961}]}]}
{"op":"mcm","clk":"1004599555","pt":1580655986063,"mc":[{"id":"1.168224030","rc":[{"batb":[[0,2.08,38.65],[1,1.95,30.61],[2,1.01,10.51]],"ltp":1.94,"tv":1347.41,"id":8908205},{"batb":[[0,1.55,35.41],[1,1.01,10.51],[2,1.74,0]],"batl":[[0,1.93,42.01],[1,2.22,329.01],[2,1.93,0]],"ltp":1.61,"tv":61.75,"id":4596961}]}]}
{"op":"mcm","clk":"1004599731","pt":1580655986952,"mc":[{"id":"1.168224030","rc":[{"batb":[[0,1.95,30.61],[1,1.01,10.51],[2,1.01,0]],"ltp":1.94,"tv":1347.41,"id":8908205},{"batl":[[0,2.22,329.01],[1,2.22,0]],"ltp":1.61,"tv":61.75,"id":4596961}]}]}
{"op":"mcm","clk":"1004600140","pt":1580655988976,"mc":[{"id":"1.168224030","rc":[{"batb":[[1,1.52,215.43],[2,1.51,166.67]],"batl":[[0,2.08,175.45],[1,2.1,111.91],[2,2.22,329.01]],"ltp":1.61,"tv":61.75,"id":4596961}]}]}
{"op":"mcm","clk":"1004600308","pt":1580655989802,"mc":[{"id":"1.168224030","rc":[{"batb":[[1,1.01,10.51],[2,1.51,0]],"batl":[[0,2.22,329.01],[1,2.1,0],[2,2.22,0]],"ltp":1.61,"tv":61.75,"id":4596961}]}]}
{"op":"mcm","clk":"1004600903","pt":1580655992786,"mc":[{"id":"1.168224030","rc":[{"batb":[[0,1.71,129.75],[1,1.69,217.67],[2,1.55,35.41]],"batl":[[0,1.78,186.87],[1,1.8,177.85],[2,2.22,329.01]],"ltp":1.61,"tv":61.75,"id":4596961}]}]}
{"op":"mcm","clk":"1004601239","pt":1580655994489,"mc":[{"id":"1.168224030","rc":[{"batb":[[0,1.55,35.41],[1,1.01,10.51],[2,1.55,0]],"batl":[[0,2.22,329.01],[1,1.8,0],[2,2.22,0]],"ltp":1.61,"tv":61.75,"id":4596961}]}]}
{"op":"mcm","clk":"1004601871","pt":1580655997599,"mc":[{"id":"1.168224030","rc":[{"batb":[[1,1.52,215.43],[2,1.51,166.67]],"ltp":1.61,"tv":61.75,"id":4596961}]}]}
{"op":"mcm","clk":"1004602147","pt":1580655999006,"mc":[{"id":"1.168224030","rc":[{"batl":[[0,3,2.41],[1,3,0]],"ltp":1.94,"tv":1347.41,"id":8908205}]}]}
{"op":"mcm","clk":"1004602326","pt":1580655999784,"mc":[{"id":"1.168224030","rc":[{"batl":[[0,1.57,126.28],[1,1.58,138.07]],"ltp":1.61,"tv":61.75,"id":4596961}]}]}
{"op":"mcm","clk":"1004602617","pt":1580656001106,"mc":[{"id":"1.168224030","rc":[{"batb":[[0,2.66,12.67],[1,2.52,26.89],[2,2.34,17.86]],"ltp":1.94,"tv":1347.41,"id":8908205},{"batl":[[2,1.66,42.01]],"ltp":1.61,"tv":61.75,"id":4596961}]}]}
{"op":"mcm","clk":"1004603056","pt":1580656003218,"mc":[{"id":"1.168224030","rc":[{"batl":[[1,3.45,180.4]],"ltp":1.94,"tv":1347.41,"id":8908205}]}]}
{"op":"mcm","clk":"1004607007","pt":1580656021023,"mc":[{"id":"1.168224030","rc":[{"batb":[[0,2.52,26.89],[1,2.34,17.86],[2,1.01,10.51]],"ltp":1.94,"tv":1347.41,"id":8908205},{"batb":[[0,1.41,51.22],[1,1.01,10.51],[2,1.51,0]],"batl":[[0,1.66,42.01],[1,2.1,363.31],[2,1.66,0]],"ltp":1.61,"tv":61.75,"id":4596961}]}]}
{"op":"mcm","clk":"1004607247","pt":1580656022137,"mc":[{"id":"1.168224030","rc":[{"batb":[[0,2.34,17.86],[1,1.01,10.51],[2,1.01,0]],"ltp":1.94,"tv":1347.41,"id":8908205},{"batl":[[0,2.1,363.31],[1,2.1,0]],"ltp":1.61,"tv":61.75,"id":4596961}]}]}
{"op":"mcm","clk":"1004607687","pt":1580656023841,"mc":[{"id":"1.168224030","rc":[{"batb":[[1,1.36,227.63],[2,1.35,273.27]],"batl":[[0,1.73,168.34],[1,1.75,194.87],[2,2.1,363.31]],"ltp":1.61,"tv":61.75,"id":4596961}]}]}
{"op":"mcm","clk":"1004610463","pt":1580656037015,"mc":[{"id":"1.168224030","rc":[{"batl":[[0,2.1,363.31],[1,1.75,0],[2,2.1,0]],"ltp":1.61,"tv":61.75,"id":4596961}]}]}
{"op":"mcm","clk":"1004610742","pt":1580656038371,"mc":[{"id":"1.168224030","rc":[{"batl":[[1,3.45,0]],"ltp":1.94,"tv":1347.41,"id":8908205}]}]}
{"op":"mcm","clk":"1004611017","pt":1580656039892,"mc":[{"id":"1.168224030","rc":[{"trd":[[3,2.41]],"ltp":3.0,"tv":1349.81,"id":8908205},{"trd":[[1.41,102.44],[1.5,4.82]],"batb":[[0,1.36,227.63],[1,1.35,273.27],[2,1.01,10.51]],"batl":[[0,1.4,212.99],[1,1.41,215.52]],"ltp":1.41,"tv":169.01,"id":4596961}],"tv":1518.83}]}
{"op":"mcm","clk":"1004611272","pt":1580656041104,"mc":[{"id":"1.168224030","rc":[{"batb":[[0,3.45,15.12],[1,3.15,20.06],[2,2.74,11.72]],"ltp":3.0,"tv":1349.81,"id":8908205},{"batb":[[2,1.32,70.74]],"ltp":1.41,"tv":169.01,"id":4596961}]}]}
{"op":"mcm","clk":"1004611455","pt":1580656042091,"mc":[{"id":"1.168224030","rc":[{"batb":[[0,3.15,20.06],[1,2.74,11.72],[2,1.01,10.51]],"ltp":3.0,"tv":1349.81,"id":8908205}]}]}
{"op":"mcm","clk":"1004611629","pt":1580656043004,"mc":[{"id":"1.168224030","rc":[{"batb":[[0,3.4,16.8],[1,3.15,20.06],[2,2.74,11.72]],"batl":[[0,4.6,136.05]],"ltp":3.0,"tv":1349.81,"id":8908205},{"batb":[[0,1.36,283.95]],"batl":[[2,1.42,42.01]],"ltp":1.41,"tv":169.01,"id":4596961}]}]}
{"op":"mcm","clk":"1004612456","pt":1580656047330,"mc":[{"id":"1.168224030","rc":[{"batl":[[0,1.4,183.63]],"ltp":1.41,"tv":169.01,"id":4596961}]}]}
{"op":"mcm","clk":"1004613134","pt":1580656050835,"mc":[{"id":"1.168224030","rc":[{"batb":[[0,1.36,319.93]],"ltp":1.41,"tv":169.01,"id":4596961}]}]}
{"op":"mcm","clk":"1004617246","pt":1580656071961,"mc":[{"id":"1.168224030","rc":[{"batb":[[0,1.32,70.74],[1,1.01,10.51],[2,1.32,0]],"batl":[[0,1.82,469.11],[1,1.41,0],[2,1.42,0]],"ltp":1.41,"tv":169.01,"id":4596961}]}]}
{"op":"mcm","clk":"1004617371","pt":1580656072657,"mc":[{"id":"1.168224030","rc":[{"batb":[[0,2.74,11.72],[1,1.01,10.51],[2,2.74,0]],"ltp":3.0,"tv":1349.81,"id":8908205}]}]}
{"op":"mcm","clk":"1004617836","pt":1580656075072,"mc":[{"id":"1.168224030","rc":[{"batb":[[1,1.28,396.98],[2,1.27,379.4]],"batl":[[0,1.53,242.32],[1,1.54,150.64],[2,1.82,469.11]],"ltp":1.41,"tv":169.01,"id":4596961}]}]}
{"op":"mcm","clk":"1004618003","pt":1580656075858,"mc":[{"id":"1.168224030","rc":[{"batb":[[0,2.82,10.78]],"ltp":3.0,"tv":1349.81,"id":8908205},{"batb":[[0,1.3,75.46]],"ltp":1.41,"tv":169.01,"id":4596961}]}]}
{"op":"mcm","clk":"1004618582","pt":1580656078872,"mc":[{"id":"1.168224030","rc":[{"batb":[[1,1.01,10.51],[2,1.27,0]],"ltp":1.41,"tv":169.01,"id":4596961}]}]}
{"op":"mcm","clk":"1004618887","pt":1580656080571,"mc":[{"id":"1.168224030","rc":[{"batl":[[2,1.82,0]],"ltp":1.41,"tv":169.01,"id":4596961}]}]}
{"op":"mcm","clk":"1004619154","pt":1580656082007,"mc":[{"id":"1.168224030","rc":[{"batb":[[0,1.48,162.97],[1,1.47,185.04],[2,1.3,75.46]],"ltp":1.41,"tv":169.01,"id":4596961}]}]}
{"op":"mcm","clk":"1004619349","pt":1580656083097,"mc":[{"id":"1.168224030","rc":[{"batb":[[1,2.46,15.66],[2,1.01,10.51]],"ltp":3.0,"tv":1349.81,"id":8908205},{"batb":[[0,1.49,40.29],[1,1.48,162.97],[2,1.47,185.04]],"ltp":1.41,"tv":169.01,"id":4596961}]}]}
{"op":"mcm","clk":"1004619513","pt":1580656083984,"mc":[{"id":"1.168224030","rc":[{"batb":[[0,2.9,21.85],[1,2.82,10.78],[2,2.46,15.66]],"batl":[[0,3.65,170.41]],"ltp":3.0,"tv":1349.81,"id":8908205},{"batl":[[0,1.52,42.01],[1,1.53,242.32],[2,1.54,150.64]],"ltp":1.41,"tv":169.01,"id":4596961}]}]}
{"op":"mcm","clk":"1004621440","pt":1580656094104,"mc":[{"id":"1.168224030","rc":[{"batb":[[0,2.46,15.42],[1,1.01,10.51],[2,2.46,0]],"ltp":3.0,"tv":1349.81,"id":8908205},{"batb":[[0,1.38,54.92],[1,1.01,10.51],[2,1.47,0]],"batl":[[0,2.04,383.01],[1,1.53,0],[2,1.54,0]],"ltp":1.41,"tv":169.01,"id":4596961}]}]}
{"op":"mcm","clk":"1004621996","pt":1580656097008,"mc":[{"id":"1.168224030","rc":[{"batb":[[1,1.37,276.7],[2,1.36,263.28]],"batl":[[0,1.7,153.78],[1,1.72,205.77],[2,2.04,383.01]],"ltp":1.41,"tv":169.01,"id":4596961}]}]}
{"op":"mcm","clk":"1004622767","pt":1580656101030,"mc":[{"id":"1.168224030","rc":[{"batb":[[1,1.01,10.51],[2,1.36,0]],"ltp":1.41,"tv":169.01,"id":4596961}]}]}
{"op":"mcm","clk":"1004623298","pt":1580656103819,"mc":[{"id":"1.168224030","rc":[{"batb":[[0,1.64,142.99],[1,1.63,124.08],[2,1.38,54.92]],"ltp":1.41,"tv":169.01,"id":4596961}]}]}
{"op":"mcm","clk":"1004623562","pt":1580656105115,"mc":[{"id":"1.168224030","rc":[{"batb":[[0,2.46,43.99],[1,2.22,20.85],[2,1.01,10.51]],"ltp":3.0,"tv":1349.81,"id":8908205},{"batb":[[2,1.62,29.9]],"batl":[[0,1.68,42.01],[1,1.7,153.78],[2,1.72,205.77]],"ltp":1.41,"tv":169.01,"id":4596961}]}]}
{"op":"mcm","clk":"1004623761","pt":1580656106252,"mc":[{"id":"1.168224030","rc":[{"batl":[[0,3.3,191.92]],"ltp":3.0,"tv":1349.81,"id":8908205}]}]}
{"op":"mcm","clk":"1004625917","pt":1580656117950,"mc":[{"id":"1.168224030","rc":[{"batb":[[0,1.62,29.9],[1,1.5,38.95],[2,1.01,10.51]],"batl":[[1,2.04,383.01],[2,1.72,0]],"ltp":1.41,"tv":169.01,"id":4596961}]}]}
{"op":"mcm","clk":"1004625985","pt":1580656118272,"mc":[{"id":"1.168224030","rc":[{"batb":[[0,2.22,20.85],[1,1.01,10.51],[2,1.01,0]],"ltp":3.0,"tv":1349.81,"id":8908205},{"batb":[[0,1.5,38.95],[1,1.01,10.51],[2,1.01,0]],"batl":[[0,2.04,383.01],[1,2.04,0]],"ltp":1.41,"tv":169.01,"id":4596961}]}]}
{"op":"mcm","clk":"1004626436","pt":1580656120646,"mc":[{"id":"1.168224030","rc":[{"batb":[[0,1.51,255.18],[1,1.5,209.97],[2,1.01,10.51]],"batl":[[0,1.9,120.62],[1,1.92,145.14],[2,2.04,383.01]],"ltp":1.41,"tv":169.01,"id":4596961}]}]}
{"op":"mcm","clk":"1004626838","pt":1580656122764,"mc":[{"id":"1.168224030","rc":[{"batl":[[0,2.46,103.34],[1,3.3,191.92]],"ltp":3.0,"tv":1349.81,"id":8908205},{"batb":[[0,1.5,38.95],[1,1.01,10.51],[2,1.01,0]],"ltp":1.41,"tv":169.01,"id":4596961}]}]}
{"op":"mcm","clk":"1004627210","pt":1580656124967,"mc":[{"id":"1.168224030","rc":[{"batl":[[1,3.3,0]],"ltp":3.0,"tv":1349.81,"id":8908205},{"batl":[[2,2.04,0]],"ltp":1.41,"tv":169.01,"id":4596961}]}]}
{"op":"mcm","clk":"1004627389","pt":1580656125954,"mc":[{"id":"1.168224030","rc":[{"trd":[[2.22,20.85]],"batb":[[0,2.08,24.78]],"ltp":2.22,"tv":1370.67,"id":8908205},{"trd":[[1.82,25.43]],"batb":[[0,1.82,146.65],[1,1.8,175.54],[2,1.75,22.9]],"ltp":1.82,"tv":194.44,"id":4596961}],"tv":1565.11}]}
{"op":"mcm","clk":"1004627777","pt":1580656127876,"mc":[{"id":"1.168224030","rc":[{"batb":[[0,2.16,36.13],[1,2.08,24.78],[2,1.01,10.51]],"ltp":2.22,"tv":1370.67,"id":8908205},{"batl":[[0,1.87,42.01],[1,1.9,120.62],[2,1.92,145.14]],"ltp":1.82,"tv":194.44,"id":4596961}]}]}
{"op":"mcm","clk":"1004627926","pt":1580656128664,"mc":[{"id":"1.168224030","rc":[{"batl":[[0,2.82,231.28]],"ltp":2.22,"tv":1370.67,"id":8908205}]}]}
{"op":"mcm","clk":"1004629275","pt":1580656136088,"mc":[{"id":"1.168224030","rc":[{"trd":[[2.1,29.67],[2.14,36.71],[2.16,72.26]],"batb":[[0,2.08,24.78],[1,1.01,10.51],[2,1.01,0]],"ltp":2.1,"tv":1509.3,"id":8908205},{"trd":[[1.87,42.01],[1.9,32.79]],"batl":[[0,1.9,87.83],[1,1.92,145.14],[2,2.42,286.52]],"ltp":1.9,"tv":269.24,"id":4596961}],"tv":1778.54}]}
{"op":"mcm","clk":"1004629833","pt":1580656139103,"mc":[{"id":"1.168224030","rc":[{"batb":[[0,1.75,22.9],[1,1.65,27.62],[2,1.01,10.51]],"batl":[[0,2.42,286.52],[1,1.92,0],[2,2.42,0]],"ltp":1.9,"tv":269.24,"id":4596961}]}]}
{"op":"mcm","clk":"1004629956","pt":1580656139796,"mc":[{"id":"1.168224030","rc":[{"batb":[[0,2.14,36.13],[1,2.08,24.78],[2,1.01,10.51]],"ltp":2.1,"tv":1509.3,"id":8908205},{"batb":[[0,1.65,27.62],[1,1.01,10.51],[2,1.01,0]],"batl":[[0,1.9,42.01],[1,2.42,286.52]],"ltp":1.9,"tv":269.24,"id":4596961}]}]}
{"op":"mcm","clk":"1004630178","pt":1580656141025,"mc":[{"id":"1.168224030","rc":[{"batb":[[0,2.08,24.78],[1,1.01,10.51],[2,1.01,0]],"ltp":2.1,"tv":1509.3,"id":8908205},{"batl":[[0,2.42,286.52],[1,2.42,0]],"ltp":1.9,"tv":269.24,"id":4596961}]}]}
{"op":"mcm","clk":"1004630350","pt":1580656141787,"mc":[{"id":"1.168224030","rc":[{"batb":[[0,1.72,167.23],[1,1.7,212.75],[2,1.65,27.62]],"batl":[[0,2.06,154.26],[1,2.08,114.64],[2,2.42,286.52]],"ltp":1.9,"tv":269.24,"id":4596961}]}]}
{"op":"mcm","clk":"1004630561","pt":1580656143006,"mc":[{"id":"1.168224030","rc":[{"batb":[[0,2.06,25.41]],"ltp":2.1,"tv":1509.3,"id":8908205},{"batb":[[2,1.67,26.99]],"ltp":1.9,"tv":269.24,"id":4596961}]}]}
{"op":"mcm","clk":"1004630680","pt":1580656143604,"mc":[{"id":"1.168224030","rc":[{"batb":[[0,1.67,26.99],[1,1.01,10.51],[2,1.67,0]],"batl":[[0,2.42,286.52],[1,2.08,0],[2,2.42,0]],"ltp":1.9,"tv":269.24,"id":4596961}]}]}
{"op":"mcm","clk":"1004631895","pt":1580656150019,"mc":[{"id":"1.168224030","rc":[{"batb":[[0,1.72,167.23],[1,1.7,212.75],[2,1.67,26.99]],"batl":[[0,2.06,154.26],[1,2.08,114.64],[2,2.42,286.52]],"ltp":1.9,"tv":269.24,"id":4596961}]}]}
{"op":"mcm","clk":"1004631921","pt":1580656150128,"mc":[{"id":"1.168224030","rc":[{"batb":[[0,1.67,26.99],[1,1.01,10.51],[2,1.67,0]],"batl":[[0,2.42,286.52],[1,2.08,0],[2,2.42,0]],"ltp":1.9,"tv":269.24,"id":4596961}]}]}
{"op":"mcm","clk":"1004632492","pt":1580656153025,"mc":[{"id":"1.168224030","rc":[{"trd":[[2.06,50.82]],"batb":[[0,1.95,117.21],[1,1.93,140.47],[2,1.01,10.51]],"batl":[[0,2.04,112.93],[1,2.06,117.81],[2,2.82,231.28]],"ltp":2.06,"tv":1560.12,"id":8908205}],"tv":1829.37}]}
{"op":"mcm","clk":"1004632641","pt":1580656153810,"mc":[{"id":"1.168224030","rc":[{"batb":[[2,1.85,17.86]],"ltp":2.06,"tv":1560.12,"id":8908205},{"batb":[[0,1.85,18.96],[1,1.67,26.99],[2,1.66,27.62]],"ltp":1.9,"tv":269.24,"id":4596961}]}]}
{"op":"mcm","clk":"1004632714","pt":1580656154152,"mc":[{"id":"1.168224030","rc":[{"batb":[[1,1.66,27.62],[2,1.01,10.51]],"ltp":1.9,"tv":269.24,"id":4596961}]}]}
{"op":"mcm","clk":"1004632994","pt":1580656155511,"mc":[{"id":"1.168224030","rc":[{"batb":[[0,1.96,43.69],[1,1.95,117.21],[2,1.93,140.47]],"ltp":2.06,"tv":1560.12,"id":8908205},{"batl":[[0,2.06,39.49],[1,2.42,286.52]],"ltp":1.9,"tv":269.24,"id":4596961}]}]}
{"op":"mcm","clk":"1004634224","pt":1580656162066,"mc":[{"id":"1.168224030","rc":[{"trd":[[2.04,53.18]],"batl":[[0,2.04,86.34]],"ltp":2.04,"tv":1613.31,"id":8908205},{"batb":[[0,1.88,18.18],[1,1.67,26.52]],"ltp":1.9,"tv":269.24,"id":4596961}],"tv":1882.55}]}
{"op":"mcm","clk":"1004634793","pt":1580656165110,"mc":[{"id":"1.168224030","rc":[{"batb":[[1,1.95,143.57]],"batl":[[0,2.04,113.2]],"ltp":2.04,"tv":1613.31,"id":8908205}]}]}
{"op":"mcm","clk":"1004635690","pt":1580656169931,"mc":[{"id":"1.168224030","rc":[{"batb":[[0,2.02,27.3],[1,1.96,43.69],[2,1.95,143.57]],"ltp":2.04,"tv":1613.31,"id":8908205},{"batb":[[0,1.89,17.7],[1,1.88,18.18],[2,1.69,25.89]],"ltp":1.9,"tv":269.24,"id":4596961}]}]}
{"op":"mcm","clk":"1004635726","pt":1580656170161,"mc":[{"id":"1.168224030","rc":[{"batb":[[1,1.69,25.89],[2,1.01,10.51]],"ltp":1.9,"tv":269.24,"id":4596961}]}]}
{"op":"mcm","clk":"1004646962","pt":1580656228617,"mc":[{"id":"1.168224030","rc":[{"batb":[[2,1.95,117.21]],"ltp":2.04,"tv":1613.31,"id":8908205}]}]}
{"op":"mcm","clk":"1004647521","pt":1580656231544,"mc":[{"id":"1.168224030","rc":[{"batl":[[0,2.04,140.82]],"ltp":2.04,"tv":1613.31,"id":8908205}]}]}
{"op":"mcm","clk":"1004648906","pt":1580656238628,"mc":[{"id":"1.168224030","rc":[{"batb":[[0,1.96,43.69],[1,1.81,19.12],[2,1.01,10.51]],"batl":[[0,2.82,231.28],[1,2.06,0],[2,2.82,0]],"ltp":2.04,"tv":1613.31,"id":8908205},{"batb":[[0,1.69,25.89],[1,1.01,10.51],[2,1.01,0]],"ltp":1.9,"tv":269.24,"id":4596961}]}]}
{"op":"mcm","clk":"1004649253","pt":1580656240256,"mc":[{"id":"1.168224030","rc":[{"batb":[[0,1.81,19.12],[1,1.01,10.51],[2,1.01,0]],"ltp":2.04,"tv":1613.31,"id":8908205},{"batl":[[0,2.42,286.52],[1,2.42,0]],"ltp":1.9,"tv":269.24,"id":4596961}]}]}
{"op":"mcm","clk":"1004649580","pt":1580656241957,"mc":[{"id":"1.168224030","rc":[{"batb":[[0,1.8,19.51],[1,1.78,170.02],[2,1.76,189.47]],"batl":[[0,2.36,104.52],[1,2.4,154.87],[2,2.82,231.28]],"ltp":2.04,"tv":1613.31,"id":8908205},{"batb":[[0,1.7,25.34]],"ltp":1.9,"tv":269.24,"id":4596961}]}]}
{"op":"mcm","clk":"1004650523","pt":1580656247122,"mc":[{"id":"1.168224030","rc":[{"batl":[[0,2.82,231.28],[1,2.4,0],[2,2.82,0]],"ltp":2.04,"tv":1613.31,"id":8908205}]}]}
{"op":"mcm","clk":"1004651304","pt":1580656251105,"mc":[{"id":"1.168224030","rc":[{"batl":[[0,1.86,161.59],[1,1.88,155.13]],"ltp":2.04,"tv":1613.31,"id":8908205},{"batb":[[0,2.14,24.71],[1,1.89,17.86],[2,1.01,10.51]],"ltp":1.9,"tv":269.24,"id":4596961}]}]}
{"op":"mcm","clk":"1004651362","pt":1580656251415,"mc":[{"id":"1.168224030","rc":[{"batb":[[0,1.81,51.25],[1,1.8,19.51],[2,1.78,170.02]],"ltp":2.04,"tv":1613.31,"id":8908205},{"batl":[[0,2.24,33.61]],"ltp":1.9,"tv":269.24,"id":4596961}]}]}
{"op":"mcm","clk":"1004651890","pt":1580656253681,"mc":[{"id":"1.168224030","rc":[{"batl":[[2,2.42,286.52]],"ltp":2.04,"tv":1613.31,"id":8908205},{"batl":[[1,2.82,231.28]],"ltp":1.9,"tv":269.24,"id":4596961}]}]}
{"op":"mcm","clk":"1004654184","pt":1580656265107,"mc":[{"id":"1.168224030","rc":[{"batb":[[1,1.65,26.44],[2,1.01,10.51]],"batl":[[0,2.42,286.52],[1,1.88,0],[2,2.42,0]],"ltp":2.04,"tv":1613.31,"id":8908205},{"batb":[[0,1.89,17.86],[1,1.01,10.51],[2,1.01,0]],"ltp":1.9,"tv":269.24,"id":4596961}]}]}
{"op":"mcm","clk":"1004654464","pt":1580656266542,"mc":[{"id":"1.168224030","rc":[{"batb":[[0,1.65,26.44],[1,1.01,10.51],[2,1.01,0]],"ltp":2.04,"tv":1613.31,"id":8908205},{"batl":[[0,2.82,231.28],[1,2.82,0]],"ltp":1.9,"tv":269.24,"id":4596961}]}]}
{"op":"mcm","clk":"1004654642","pt":1580656267339,"mc":[{"id":"1.168224030","rc":[{"batb":[[0,1.66,216.99],[1,1.65,145.88],[2,1.01,10.51]],"batl":[[0,2.08,122.07],[1,2.1,111.42],[2,2.42,286.52]],"ltp":2.04,"tv":1613.31,"id":8908205}]}]}
{"op":"mcm","clk":"1004654879","pt":1580656268525,"mc":[{"id":"1.168224030","rc":[{"batl":[[0,2.42,286.52],[1,2.1,0],[2,2.42,0]],"ltp":2.04,"tv":1613.31,"id":8908205}]}]}
{"op":"mcm","clk":"1004655376","pt":1580656271123,"mc":[{"id":"1.168224030","rc":[{"batl":[[0,1.73,164.89],[1,1.75,195.16]],"ltp":2.04,"tv":1613.31,"id":8908205}]}]}
{"op":"mcm","clk":"1004655561","pt":1580656272042,"mc":[{"id":"1.168224030","rc":[{"batb":[[2,1.55,33.36]],"ltp":2.04,"tv":1613.31,"id":8908205},{"batb":[[0,2.4,17.7],[1,2.16,24.08],[2,1.01,10.51]],"ltp":1.9,"tv":269.24,"id":4596961}]}]}
{"op":"mcm","clk":"1004655981","pt":1580656274029,"mc":[{"id":"1.168224030","rc":[{"batb":[[0,1.7,59.65],[1,1.66,216.99],[2,1.65,145.88]],"batl":[[2,2.22,329.01]],"ltp":2.04,"tv":1613.31,"id":8908205},{"batl":[[0,2.42,29.41],[1,3.15,200.42]],"ltp":1.9,"tv":269.24,"id":4596961}]}]}
{"op":"mcm","clk":"1004657992","pt":1580656284653,"mc":[{"id":"1.168224030","rc":[{"batb":[[1,1.55,33.36],[2,1.01,10.51]],"batl":[[0,2.22,329.01],[1,1.75,0],[2,2.22,0]],"ltp":2.04,"tv":1613.31,"id":8908205},{"batb":[[0,2.16,24.08],[1,1.01,10.51],[2,1.01,0]],"ltp":1.9,"tv":269.24,"id":4596961}]}]}
{"op":"mcm","clk":"1004658404","pt":1580656286863,"mc":[{"id":"1.168224030","rc":[{"batb":[[0,1.55,33.36],[1,1.01,10.51],[2,1.01,0]],"ltp":2.04,"tv":1613.31,"id":8908205},{"batl":[[0,3.15,200.42],[1,3.15,0]],"ltp":1.9,"tv":269.24,"id":4596961}]}]}
{"op":"mcm","clk":"1004658597","pt":1580656287966,"mc":[{"id":"1.168224030","rc":[{"batb":[[0,1.59,200.92],[1,1.58,140.12],[2,1.55,32.97]],"batl":[[0,1.86,141.27],[1,1.88,155.18],[2,2.22,329.01]],"ltp":2.04,"tv":1613.31,"id":8908205},{"batb":[[0,2.14,24.39]],"ltp":1.9,"tv":269.24,"id":4596961}]}]}
{"op":"mcm","clk":"1004659730","pt":1580656293715,"mc":[{"id":"1.168224030","rc":[{"batl":[[0,2.22,329.01],[1,1.88,0],[2,2.22,0]],"ltp":2.04,"tv":1613.31,"id":8908205}]}]}
{"op":"mcm","clk":"1004660313","pt":1580656296831,"mc":[{"id":"1.168224030","rc":[{"batl":[[0,1.65,167.25],[1,1.66,116.02]],"ltp":2.04,"tv":1613.31,"id":8908205}]}]}
{"op":"mcm","clk":"1004660476","pt":1580656297539,"mc":[{"id":"1.168224030","rc":[{"trd":[[2.64,27.54]],"batb":[[0,2.46,16.68]],"ltp":2.64,"tv":296.78,"id":4596961}],"tv":1910.09}]}
{"op":"mcm","clk":"1004660917","pt":1580656299943,"mc":[{"id":"1.168224030","rc":[{"batl":[[2,2.1,363.31]],"ltp":2.04,"tv":1613.31,"id":8908205}]}]}
{"op":"mcm","clk":"1004661084","pt":1580656300714,"mc":[{"id":"1.168224030","rc":[{"batb":[[0,1.62,67.22],[1,1.59,200.92],[2,1.58,140.12]],"ltp":2.04,"tv":1613.31,"id":8908205},{"batl":[[0,2.6,26.05],[1,3.15,200.42]],"ltp":2.64,"tv":296.78,"id":4596961}]}]}
{"op":"mcm","clk":"1004663688","pt":1580656313975,"mc":[{"id":"1.168224030","rc":[{"batb":[[1,1.55,32.97],[2,1.5,37.69]],"batl":[[0,2.1,363.31],[1,1.66,0],[2,2.1,0]],"ltp":2.04,"tv":1613.31,"id":8908205}]}]}
{"op":"mcm","clk":"1004663790","pt":1580656314473,"mc":[{"id":"1.168224030","rc":[{"batb":[[1,1.5,37.69],[2,1.01,10.51]],"ltp":2.04,"tv":1613.31,"id":8908205}]}]}
{"op":"mcm","clk":"1004664263","pt":1580656316853,"mc":[{"id":"1.168224030","rc":[{"batb":[[0,1.55,255.42],[1,1.54,154.93],[2,1.5,37.69]],"batl":[[0,1.71,155.36],[1,1.73,202.87],[2,2.1,363.31]],"ltp":2.04,"tv":1613.31,"id":8908205},{"batl":[[0,3.15,200.42],[1,3.15,0]],"ltp":2.64,"tv":296.78,"id":4596961}]}]}
{"op":"mcm","clk":"1004664435","pt":1580656317686,"mc":[{"id":"1.168224030","rc":[{"batb":[[2,1.51,36.59]],"ltp":2.04,"tv":1613.31,"id":8908205},{"batb":[[0,2.42,17.31]],"ltp":2.64,"tv":296.78,"id":4596961}]}]}
{"op":"mcm","clk":"1004665413","pt":1580656322082,"mc":[{"id":"1.168224030","rc":[{"batb":[[0,1.51,36.59],[1,1.01,10.51],[2,1.51,0]],"batl":[[0,2.1,363.31],[1,1.73,0],[2,2.1,0]],"ltp":2.04,"tv":1613.31,"id":8908205}]}]}
{"op":"mcm","clk":"1004666079","pt":1580656325076,"mc":[{"id":"1.168224030","rc":[{"batb":[[0,1.6,204.96],[1,1.59,136.87],[2,1.51,36.59]],"batl":[[0,1.66,149.59],[1,1.68,224.09],[2,2.1,363.31]],"ltp":2.04,"tv":1613.31,"id":8908205}]}]}
{"op":"mcm","clk":"1004666289","pt":1580656326148,"mc":[{"id":"1.168224030","rc":[{"batb":[[0,1.51,36.59],[1,1.01,10.51],[2,1.51,0]],"batl":[[0,2.1,363.31],[1,1.68,0],[2,2.1,0]],"ltp":2.04,"tv":1613.31,"id":8908205}]}]}
{"op":"mcm","clk":"1004666904","pt":1580656329076,"mc":[{"id":"1.168224030","rc":[{"batb":[[0,1.55,255.42],[1,1.54,154.93],[2,1.51,36.59]],"batl":[[0,1.71,155.36],[1,1.73,202.87],[2,2.1,363.31]],"ltp":2.04,"tv":1613.31,"id":8908205}]}]}
{"op":"mcm","clk":"1004667439","pt":1580656331766,"mc":[{"id":"1.168224030","rc":[{"batb":[[0,1.51,36.59],[1,1.01,10.51],[2,1.51,0]],"ltp":2.04,"tv":1613.31,"id":8908205}]}]}
{"op":"mcm","clk":"1004667974","pt":1580656334490,"mc":[{"id":"1.168224030","rc":[{"batb":[[0,1.65,133.01],[1,1.64,121.9],[2,1.51,36.59]],"ltp":2.04,"tv":1613.31,"id":8908205}]}]}
{"op":"mcm","clk":"1004668181","pt":1580656335472,"mc":[{"id":"1.168224030","rc":[{"batb":[[0,1.66,63.01],[1,1.65,133.01],[2,1.64,148.97]],"ltp":2.04,"tv":1613.31,"id":8908205},{"batb":[[1,2.18,23.37],[2,1.01,10.51]],"ltp":2.64,"tv":296.78,"id":4596961}]}]}
{"op":"mcm","clk":"1004668620","pt":1580656337754,"mc":[{"id":"1.168224030","rc":[{"batl":[[0,2.5,27.73],[1,3.15,200.42]],"ltp":2.64,"tv":296.78,"id":4596961}]}]}
{"op":"mcm","clk":"1004672047","pt":1580656354937,"mc":[{"id":"1.168224030","rc":[{"batb":[[1,1.54,34.07],[2,1.01,10.51]],"batl":[[0,2.1,363.31],[1,1.73,0],[2,2.1,0]],"ltp":2.04,"tv":1613.31,"id":8908205},{"batb":[[0,2.18,23.37],[1,1.01,10.51],[2,1.01,0]],"ltp":2.64,"tv":296.78,"id":4596961}]}]}
{"op":"mcm","clk":"1004672328","pt":1580656356313,"mc":[{"id":"1.168224030","rc":[{"batb":[[0,1.54,34.07],[1,1.01,10.51],[2,1.01,0]],"ltp":2.04,"tv":1613.31,"id":8908205},{"batl":[[0,3.15,200.42],[1,3.15,0]],"ltp":2.64,"tv":296.78,"id":4596961}]}]}
{"op":"mcm","clk":"1004672563","pt":1580656357525,"mc":[{"id":"1.168224030","rc":[{"batb":[[0,1.58,131.38],[1,1.57,143.31],[2,1.54,34.07]],"batl":[[0,1.83,127.23],[1,1.85,163.28],[2,2.1,363.31]],"ltp":2.04,"tv":1613.31,"id":8908205}]}]}
{"op":"mcm","clk":"1004672857","pt":1580656358929,"mc":[{"id":"1.168224030","rc":[{"batl":[[0,2.1,363.31],[1,1.85,0],[2,2.1,0]],"ltp":2.04,"tv":1613.31,"id":8908205}]}]}
{"op":"mcm","clk":"1004673431","pt":1580656361901,"mc":[{"id":"1.168224030","rc":[{"batl":[[0,1.63,127.02],[1,1.64,121.25],[2,2.1,363.31]],"ltp":2.04,"tv":1613.31,"id":8908205}]}]}
{"op":"mcm","clk":"1004673589","pt":1580656362736,"mc":[{"id":"1.168224030","rc":[{"batb":[[0,2.68,13.22],[1,2.28,20.22],[2,1.01,10.51]],"ltp":2.64,"tv":296.78,"id":4596961}]}]}
{"op":"mcm","clk":"1004673828","pt":1580656363898,"mc":[{"id":"1.168224030","rc":[{"trd":[[2.68,26.43]],"batb":[[0,2.28,20.22],[1,1.01,10.51],[2,1.01,0]],"ltp":2.68,"tv":323.22,"id":4596961}],"tv":1936.53}]}
{"op":"mcm","clk":"1004674351","pt":1580656366737,"mc":[{"id":"1.168224030","rc":[{"batb":[[0,1.6,69.74],[1,1.58,131.38],[2,1.57,143.31]],"ltp":2.04,"tv":1613.31,"id":8908205},{"batl":[[0,2.66,25.21],[1,3.15,200.42]],"ltp":2.68,"tv":323.22,"id":4596961}]}]}
{"op":"mcm","clk":"1004674463","pt":1580656367319,"mc":[{"id":"1.168224030","rc":[{"batl":[[2,1.66,16]],"ltp":2.04,"tv":1613.31,"id":8908205}]}]}
{"op":"mcm","clk":"1004676599","pt":1580656378657,"mc":[{"id":"1.168224030","rc":[{"batl":[[2,2.1,363.31]],"ltp":2.04,"tv":1613.31,"id":8908205}]}]}
{"op":"mcm","clk":"1004677165","pt":1580656381753,"mc":[{"id":"1.168224030","rc":[{"trd":[[1.6,100.9]],"batb":[[0,1.6,53.74]],"ltp":1.6,"tv":1645.3,"id":8908205}],"tv":1968.52}]}
{"op":"mcm","clk":"1004677765","pt":1580656385060,"mc":[{"id":"1.168224030","rc":[{"batb":[[0,1.6,69.7]],"ltp":1.6,"tv":1645.3,"id":8908205}]}]}
{"op":"mcm","clk":"1004678339","pt":1580656388010,"mc":[{"id":"1.168224030","rc":[{"batb":[[1,1.54,34.07],[2,1.41,48.94]],"batl":[[0,2.1,363.31],[1,1.64,0],[2,2.1,0]],"ltp":1.6,"tv":1645.3,"id":8908205}]}]}
{"op":"mcm","clk":"1004678531","pt":1580656388917,"mc":[{"id":"1.168224030","rc":[{"batb":[[0,1.41,48.23],[1,1.01,10.51],[2,1.41,0]],"batl":[[0,1.6,16.8],[1,2.1,363.31]],"ltp":1.6,"tv":1645.3,"id":8908205},{"batl":[[0,3.15,200.42],[1,3.15,0]],"ltp":2.68,"tv":323.22,"id":4596961}]}]}
{"op":"mcm","clk":"1004679260","pt":1580656392963,"mc":[{"id":"1.168224030","rc":[{"batb":[[0,1.54,269.5],[1,1.53,159.09],[2,1.41,48.23]],"batl":[[0,1.6,198.97],[1,1.61,129.29],[2,2.1,363.31]],"ltp":1.6,"tv":1645.3,"id":8908205}]}]}
{"op":"mcm","clk":"1004679701","pt":1580656394918,"mc":[{"id":"1.168224030","rc":[{"batb":[[0,1.41,48.23],[1,1.01,10.51],[2,1.41,0]],"batl":[[0,1.6,16.8],[1,2.1,363.31],[2,2.1,0]],"ltp":1.6,"tv":1645.3,"id":8908205}]}]}
{"op":"mcm","clk":"1004679955","pt":1580656396219,"mc":[{"id":"1.168224030","rc":[{"batl":[[0,3.65,170.41]],"ltp":2.68,"tv":323.22,"id":4596961}]}]}
{"op":"mcm","clk":"1004680248","pt":1580656397732,"mc":[{"id":"1.168224030","rc":[{"batb":[[0,1.43,261.79],[1,1.42,217.43],[2,1.41,48.23]],"batl":[[1,1.8,181.88],[2,1.82,171.81]],"ltp":1.6,"tv":1645.3,"id":8908205}]}]}
{"op":"mcm","clk":"1004682433","pt":1580656408738,"mc":[{"id":"1.168224030","rc":[{"batl":[[1,2.1,363.31],[2,1.82,0]],"ltp":1.6,"tv":1645.3,"id":8908205}]}]}
{"op":"mcm","clk":"1004682912","pt":1580656411045,"mc":[{"id":"1.168224030","rc":[{"batb":[[0,1.43,233.77]],"batl":[[1,2.1,0]],"ltp":1.6,"tv":1645.3,"id":8908205}]}]}
{"op":"mcm","clk":"1004683097","pt":1580656411932,"mc":[{"id":"1.168224030","rc":[{"batl":[[0,1.48,264.09],[1,1.49,172.86],[2,1.6,16.8]],"ltp":1.6,"tv":1645.3,"id":8908205},{"batb":[[0,3.15,21.79],[1,2.64,13.85],[2,2.28,20.22]],"ltp":2.68,"tv":323.22,"id":4596961}]}]}
{"op":"mcm","clk":"1004683125","pt":1580656412149,"mc":[{"id":"1.168224030","rc":[{"batb":[[2,1.01,10.51]],"ltp":2.68,"tv":323.22,"id":4596961}]}]}
{"op":"mcm","clk":"1004683415","pt":1580656413633,"mc":[{"id":"1.168224030","rc":[{"batb":[[0,1.46,90.74],[1,1.43,233.77],[2,1.42,217.43]],"batl":[[0,1.48,291.21]],"ltp":1.6,"tv":1645.3,"id":8908205},{"trd":[[3.15,38.65]],"batb":[[0,3.15,2.47]],"ltp":3.15,"tv":361.87,"id":4596961}],"tv":2007.17}]}
{"op":"mcm","clk":"1004683532","pt":1580656414267,"mc":[{"id":"1.168224030","rc":[{"batl":[[0,4.2,148.03]],"ltp":3.15,"tv":361.87,"id":4596961}]}]}
{"op":"mcm","clk":"1004684065","pt":1580656417011,"mc":[{"id":"1.168224030","rc":[{"trd":[[3.15,43.59]],"batb":[[0,2.64,13.85],[1,1.01,10.51],[2,1.01,0]],"ltp":3.15,"tv":366.81,"id":4596961}],"tv":2012.11}]}
{"op":"mcm","clk":"1004684627","pt":1580656420032,"mc":[{"id":"1.168224030","rc":[{"batl":[[0,3.15,19.32],[1,4.2,148.03]],"ltp":3.15,"tv":366.81,"id":4596961}]}]}
{"op":"mcm","clk":"1004685408","pt":1580656423881,"mc":[{"id":"1.168224030","rc":[{"batb":[[1,1.31,69.55],[2,1.01,10.51]],"batl":[[0,1.6,16.8],[1,1.89,435.28],[2,1.6,0]],"ltp":1.6,"tv":1645.3,"id":8908205}]}]}
{"op":"mcm","clk":"1004685585","pt":1580656424648,"mc":[{"id":"1.168224030","rc":[{"batb":[[0,1.31,69.55],[1,1.01,10.51],[2,1.01,0]],"ltp":1.6,"tv":1645.3,"id":8908205},{"batl":[[0,4.2,148.03],[1,4.2,0]],"ltp":3.15,"tv":366.81,"id":4596961}]}]}
{"op":"mcm","clk":"1004686065","pt":1580656427041,"mc":[{"id":"1.168224030","rc":[{"batb":[[0,1.31,67.59]],"ltp":1.6,"tv":1645.3,"id":8908205},{"batb":[[0,2.6,14.4]],"ltp":3.15,"tv":366.81,"id":4596961}]}]}
{"op":"mcm","clk":"1004686415","pt":1580656429085,"mc":[{"id":"1.168224030","rc":[{"batb":[[0,1.4,307.08],[1,1.39,240.34],[2,1.31,67.59]],"batl":[[0,1.45,301.65],[1,1.46,187.68],[2,1.6,16.8]],"ltp":1.6,"tv":1645.3,"id":8908205}]}]}
{"op":"mcm","clk":"1004686738","pt":1580656430672,"mc":[{"id":"1.168224030","rc":[{"batb":[[0,1.31,67.59],[1,1.01,10.51],[2,1.31,0]],"batl":[[0,1.6,16.8],[1,1.89,435.28],[2,1.6,0]],"ltp":1.6,"tv":1645.3,"id":8908205}]}]}
{"op":"mcm","clk":"1004687266","pt":1580656433131,"mc":[{"id":"1.168224030","rc":[{"batb":[[1,1.3,414.9],[2,1.29,352.26]],"batl":[[1,1.62,172.91],[2,1.63,123.86]],"ltp":1.6,"tv":1645.3,"id":8908205}]}]}
{"op":"mcm","clk":"1004688936","pt":1580656440964,"mc":[{"id":"1.168224030","rc":[{"batl":[[1,1.62,0],[2,1.63,0]],"ltp":1.6,"tv":1645.3,"id":8908205}]}]}
{"op":"mcm","clk":"1004689556","pt":1580656443656,"mc":[{"id":"1.168224030","rc":[{"batl":[[0,1.34,319.51],[1,1.35,265.57],[2,1.6,16.8]],"ltp":1.6,"tv":1645.3,"id":8908205}]}]}
{"op":"mcm","clk":"1004689816","pt":1580656444960,"mc":[{"id":"1.168224030","rc":[{"batb":[[0,3.8,13.85],[1,3.15,21.4],[2,1.01,10.51]],"ltp":3.15,"tv":366.81,"id":4596961}]}]}
{"op":"mcm","clk":"1004689952","pt":1580656445561,"mc":[{"id":"1.168224030","rc":[{"batb":[[0,1.33,126.87],[1,1.31,67.59],[2,1.3,414.9]],"ltp":1.6,"tv":1645.3,"id":8908205},{"batl":[[0,4,13.44]],"ltp":3.15,"tv":366.81,"id":4596961}]}]}
{"op":"mcm","clk":"1004690241","pt":1580656446963,"mc":[{"id":"1.168224030","rc":[{"trd":[[1.34,20.16]],"batl":[[0,1.34,309.43]],"ltp":1.34,"tv":1665.47,"id":8908205},{"batl":[[1,5.5,115.06]],"ltp":3.15,"tv":366.81,"id":4596961}],"tv":2032.28}]}
{"op":"mcm","clk":"1004693119","pt":1580656461020,"mc":[{"id":"1.168224030","rc":[{"batb":[[1,1.24,92.84],[2,1.01,10.51]],"batl":[[0,1.6,16.8],[1,1.71,542.06],[2,1.6,0]],"ltp":1.34,"tv":1665.47,"id":8908205},{"batb":[[0,3.15,21.4],[1,1.01,10.51],[2,1.01,0]],"ltp":3.15,"tv":366.81,"id":4596961}]}]}
{"op":"mcm","clk":"1004693380","pt":1580656462314,"mc":[{"id":"1.168224030","rc":[{"batb":[[0,1.24,92.84],[1,1.01,10.51],[2,1.01,0]],"ltp":1.34,"tv":1665.47,"id":8908205},{"batl":[[0,5.5,115.06],[1,5.5,0]],"ltp":3.15,"tv":366.81,"id":4596961}]}]}
{"op":"mcm","clk":"1004693649","pt":1580656463614,"mc":[{"id":"1.168224030","rc":[{"batb":[[1,1.21,478.01],[2,1.2,553.81]],"batl":[[0,1.44,161.72],[1,1.45,194.11],[2,1.6,16.8]],"ltp":1.34,"tv":1665.47,"id":8908205}]}]}
{"op":"mcm","clk":"1004694116","pt":1580656466043,"mc":[{"id":"1.168224030","rc":[{"batb":[[1,1.01,10.51],[2,1.2,0]],"ltp":1.34,"tv":1665.47,"id":8908205}]}]}
{"op":"mcm","clk":"1004694728","pt":1580656469019,"mc":[{"id":"1.168224030","rc":[{"batb":[[0,1.4,252.35],[1,1.39,239.46],[2,1.24,92.84]],"ltp":1.34,"tv":1665.47,"id":8908205}]}]}
{"op":"mcm","clk":"1004694933","pt":1580656469933,"mc":[{"id":"1.168224030","rc":[{"batb":[[0,1.42,99.98],[1,1.41,48.78],[2,1.4,252.35]],"ltp":1.34,"tv":1665.47,"id":8908205},{"batb":[[1,2.58,14.63],[2,1.01,10.51]],"batl":[[0,3.4,16.8]],"ltp":3.15,"tv":366.81,"id":4596961}]}]}
{"op":"mcm","clk":"1004695043","pt":1580656470407,"mc":[{"id":"1.168224030","rc":[{"batl":[[2,1.71,542.06]],"ltp":1.34,"tv":1665.47,"id":8908205}]}]}
{"op":"mcm","clk":"1004695381","pt":1580656472101,"mc":[{"id":"1.168224030","rc":[{"batl":[[1,4.6,136.05]],"ltp":3.15,"tv":366.81,"id":4596961}]}]}
{"op":"mcm","clk":"1004698558","pt":1580656487095,"mc":[{"id":"1.168224030","rc":[{"batl":[[0,1.45,194.11],[1,1.71,542.06],[2,1.71,0]],"ltp":1.34,"tv":1665.47,"id":8908205}]}]}
{"op":"mcm","clk":"1004698756","pt":1580656488018,"mc":[{"id":"1.168224030","rc":[{"batb":[[1,1.29,75.53],[2,1.01,10.51]],"batl":[[0,1.71,542.06],[1,1.71,0]],"ltp":1.34,"tv":1665.47,"id":8908205},{"batb":[[0,2.58,14.63],[1,1.01,10.51],[2,1.01,0]],"ltp":3.15,"tv":366.81,"id":4596961}]}]}
{"op":"mcm","clk":"1004698817","pt":1580656488326,"mc":[{"id":"1.168224030","rc":[{"batb":[[0,1.29,75.53],[1,1.01,10.51],[2,1.01,0]],"ltp":1.34,"tv":1665.47,"id":8908205},{"batl":[[0,4.6,136.05],[1,4.6,0]],"ltp":3.15,"tv":366.81,"id":4596961}]}]}
{"op":"mcm","clk":"1004699218","pt":1580656490021,"mc":[{"id":"1.168224030","rc":[{"batb":[[0,1.4,87.88],[1,1.29,75.53],[2,1.01,10.51]],"batl":[[0,1.45,71.91],[1,1.46,187.01],[2,1.71,542.06]],"ltp":1.34,"tv":1665.47,"id":8908205}]}]}
{"op":"mcm","clk":"1004699413","pt":1580656490834,"mc":[{"id":"1.168224030","rc":[{"batb":[[0,1.29,75.53],[1,1.01,10.51],[2,1.01,0]],"batl":[[0,1.71,542.06],[1,1.46,0],[2,1.71,0]],"ltp":1.34,"tv":1665.47,"id":8908205}]}]}
{"op":"mcm","clk":"1004699868","pt":1580656492833,"mc":[{"id":"1.168224030","rc":[{"batb":[[0,1.37,326.31],[1,1.36,265.48],[2,1.29,75.53]],"batl":[[0,1.41,159.68],[1,1.42,211.38],[2,1.71,542.06]],"ltp":1.34,"tv":1665.47,"id":8908205}]}]}
{"op":"mcm","clk":"1004700159","pt":1580656494118,"mc":[{"id":"1.168224030","rc":[{"batb":[[0,1.29,75.53],[1,1.01,10.51],[2,1.29,0]],"batl":[[0,1.71,542.06],[1,1.42,0],[2,1.71,0]],"ltp":1.34,"tv":1665.47,"id":8908205}]}]}
{"op":"mcm","clk":"1004700810","pt":1580656496989,"mc":[{"id":"1.168224030","rc":[{"batb":[[1,1.26,338.19],[2,1.25,418.76]],"batl":[[0,1.62,208.15],[1,1.63,123.21],[2,1.71,542.06]],"ltp":1.34,"tv":1665.47,"id":8908205}]}]}
{"op":"mcm","clk":"1004702620","pt":1580656505041,"mc":[{"id":"1.168224030","rc":[{"batb":[[1,1.01,10.51],[2,1.25,0]],"ltp":1.34,"tv":1665.47,"id":8908205}]}]}
{"op":"mcm","clk":"1004703293","pt":1580656508036,"mc":[{"id":"1.168224030","rc":[{"batb":[[0,1.56,203.37],[1,1.55,150.43],[2,1.29,75.53]],"batl":[[2,1.71,0]],"ltp":1.34,"tv":1665.47,"id":8908205}]}]}
{"op":"mcm","clk":"1004703472","pt":1580656508847,"mc":[{"id":"1.168224030","rc":[{"batb":[[0,1.57,31.24],[1,1.56,203.37],[2,1.55,150.43]],"ltp":1.34,"tv":1665.47,"id":8908205},{"batb":[[1,2.08,26.83],[2,1.01,10.51]],"ltp":3.15,"tv":366.81,"id":4596961}]}]}
{"op":"mcm","clk":"1004703639","pt":1580656509568,"mc":[{"id":"1.168224030","rc":[{"batb":[[2,1.55,226.05]],"ltp":1.34,"tv":1665.47,"id":8908205},{"batl":[[0,2.82,22.69]],"ltp":3.15,"tv":366.81,"id":4596961}]}]}
{"op":"mcm","clk":"1004704060","pt":1580656511447,"mc":[{"id":"1.168224030","rc":[{"batl":[[2,2.04,383.01]],"ltp":1.34,"tv":1665.47,"id":8908205},{"batl":[[1,3.65,170.41]],"ltp":3.15,"tv":366.81,"id":4596961}]}]}
{"op":"mcm","clk":"1004707478","pt":1580656526986,"mc":[{"id":"1.168224030","rc":[{"batb":[[1,1.55,75.62],[2,1.37,54.61]],"batl":[[0,2.04,383.01],[1,1.63,0],[2,2.04,0]],"ltp":1.34,"tv":1665.47,"id":8908205}]}]}
{"op":"mcm","clk":"1004707652","pt":1580656527624,"mc":[{"id":"1.168224030","rc":[{"batb":[[0,1.55,75.62],[1,1.37,54.61],[2,1.01,10.51]],"ltp":1.34,"tv":1665.47,"id":8908205},{"batb":[[0,2.08,26.83],[1,1.01,10.51],[2,1.01,0]],"ltp":3.15,"tv":366.81,"id":4596961}]}]}
{"op":"mcm","clk":"1004707849","pt":1580656528358,"mc":[{"id":"1.168224030","rc":[{"batb":[[0,1.37,54.61],[1,1.01,10.51],[2,1.01,0]],"ltp":1.34,"tv":1665.47,"id":8908205},{"batl":[[0,3.65,170.41],[1,3.65,0]],"ltp":3.15,"tv":366.81,"id":4596961}]}]}
{"op":"mcm","clk":"1004708257","pt":1580656530122,"mc":[{"id":"1.168224030","rc":[{"batb":[[1,1.35,334.91],[2,1.34,285.66]],"batl":[[0,1.88,163.1],[1,1.9,149.81],[2,2.04,383.01]],"ltp":1.34,"tv":1665.47,"id":8908205}]}]}
{"op":"mcm","clk":"1004710540","pt":1580656539817,"mc":[{"id":"1.168224030","rc":[{"batb":[[1,1.01,10.51],[2,1.34,0]],"ltp":1.34,"tv":1665.47,"id":8908205}]}]}
{"op":"mcm","clk":"1004711278","pt":1580656543098,"mc":[{"id":"1.168224030","rc":[{"batb":[[0,1.85,18.02],[1,1.8,151.11],[2,1.78,182.02]],"batl":[[2,2.04,0]],"ltp":1.34,"tv":1665.47,"id":8908205},{"batb":[[1,1.75,22.98],[2,1.01,10.51]],"ltp":3.15,"tv":366.81,"id":4596961}]}]}
{"op":"mcm","clk":"1004712164","pt":1580656547117,"mc":[{"id":"1.168224030","rc":[{"batl":[[2,2.42,286.52]],"ltp":1.34,"tv":1665.47,"id":8908205},{"batl":[[0,2.82,231.28]],"ltp":3.15,"tv":366.81,"id":4596961}]}]}
{"op":"mcm","clk":"1004715843","pt":1580656564039,"mc":[{"id":"1.168224030","rc":[{"batb":[[1,1.58,30.84],[2,1.01,10.51]],"batl":[[0,2.42,286.52],[1,1.9,0],[2,2.42,0]],"ltp":1.34,"tv":1665.47,"id":8908205}]}]}
{"op":"mcm","clk":"1004716062","pt":1580656565067,"mc":[{"id":"1.168224030","rc":[{"batb":[[0,1.58,30.84],[1,1.01,10.51],[2,1.01,0]],"ltp":1.34,"tv":1665.47,"id":8908205},{"batb":[[0,1.75,22.98],[1,1.01,10.51],[2,1.01,0]],"ltp":3.15,"tv":366.81,"id":4596961}]}]}
{"op":"mcm","clk":"1004716469","pt":1580656566877,"mc":[{"id":"1.168224030","rc":[{"batb":[[1,1.56,190.17],[2,1.55,150.32]],"batl":[[0,2.18,157.24],[1,2.2,97.46],[2,2.42,286.52]],"ltp":1.34,"tv":1665.47,"id":8908205}]}]}
{"op":"mcm","clk":"1004717840","pt":1580656573055,"mc":[{"id":"1.168224030","rc":[{"batb":[[1,1.01,10.51],[2,1.55,0]],"batl":[[0,2.42,286.52],[1,2.2,0],[2,2.42,0]],"ltp":1.34,"tv":1665.47,"id":8908205}]}]}
{"op":"mcm","clk":"1004718542","pt":1580656576079,"mc":[{"id":"1.168224030","rc":[{"batb":[[0,1.85,164.78],[1,1.83,166.14],[2,1.75,22.98]],"batl":[[0,1.93,101.91],[1,1.95,138.37],[2,2.82,231.28]],"ltp":3.15,"tv":366.81,"id":4596961}]}]}
{"op":"mcm","clk":"1004718710","pt":1580656576891,"mc":[{"id":"1.168224030","rc":[{"trd":[[2.18,20.77]],"batb":[[0,1.94,15.5],[1,1.58,30.84],[2,1.01,10.51]],"ltp":2.18,"tv":1686.24,"id":8908205},{"trd":[[1.85,24.48]],"batb":[[0,1.85,140.3]],"ltp":1.85,"tv":391.29,"id":4596961}],"tv":2077.53}]}
{"op":"mcm","clk":"1004718957","pt":1580656578079,"mc":[{"id":"1.168224030","rc":[{"batb":[[1,1.01,10.51],[2,1.01,0]],"ltp":2.18,"tv":1686.24,"id":8908205}]}]}
{"op":"mcm","clk":"1004719263","pt":1580656579484,"mc":[{"id":"1.168224030","rc":[{"batb":[[1,1.92,45.37],[2,1.01,10.51]],"ltp":2.18,"tv":1686.24,"id":8908205},{"batl":[[0,2.08,38.65]],"ltp":1.85,"tv":391.29,"id":4596961}]}]}
{"op":"mcm","clk":"1004719461","pt":1580656580391,"mc":[{"id":"1.168224030","rc":[{"batl":[[0,2.82,231.28]],"ltp":2.18,"tv":1686.24,"id":8908205},{"batl":[[0,1.93,111.7],[1,1.95,138.39],[2,2.08,38.65]],"ltp":1.85,"tv":391.29,"id":4596961}]}]}
{"op":"mcm","clk":"1004720461","pt":1580656585093,"mc":[{"id":"1.168224030","rc":[{"trd":[[2.18,42.49]],"batb":[[0,1.92,61.34],[1,1.01,10.51],[2,1.01,0]],"ltp":2.18,"tv":1707.95,"id":8908205},{"trd":[[1.85,50.07]],"batb":[[0,1.85,114.71],[2,1.77,22.03]],"ltp":1.85,"tv":416.88,"id":4596961}],"tv":2124.83}]}
{"op":"mcm","clk":"1004721267","pt":1580656588797,"mc":[{"id":"1.168224030","rc":[{"batb":[[0,1.85,145.26]],"ltp":1.85,"tv":416.88,"id":4596961}]}]}
{"op":"mcm","clk":"1004721950","pt":1580656592098,"mc":[{"id":"1.168224030","rc":[{"batl":[[0,1.93,136.96]],"ltp":1.85,"tv":416.88,"id":4596961}]}]}
{"op":"mcm","clk":"1004722122","pt":1580656593081,"mc":[{"id":"1.168224030","rc":[{"batb":[[0,2.16,22.27],[1,1.92,45.37],[2,1.9,16.37]],"ltp":2.18,"tv":1707.95,"id":8908205},{"batb":[[2,1.78,21.56]],"ltp":1.85,"tv":416.88,"id":4596961}]}]}
{"op":"mcm","clk":"1004737310","pt":1580656662970,"mc":[{"id":"1.168224030","rc":[{"batb":[[0,1.9,16.37],[1,1.01,10.51],[2,1.9,0]],"ltp":2.18,"tv":1707.95,"id":8908205},{"batb":[[0,1.56,33.99],[1,1.01,10.51],[2,1.78,0]],"batl":[[0,2.42,286.52],[1,1.95,0],[2,2.08,0]],"ltp":1.85,"tv":416.88,"id":4596961}]}]}
{"op":"mcm","clk":"1004737882","pt":1580656665579,"mc":[{"id":"1.168224030","rc":[{"batb":[[0,1.61,218.31],[1,1.6,133.07],[2,1.56,33.99]],"batl":[[0,2.16,153.5],[1,2.18,100.19],[2,2.42,286.52]],"ltp":1.85,"tv":416.88,"id":4596961}]}]}
{"op":"mcm","clk":"1004738116","pt":1580656666623,"mc":[{"id":"1.168224030","rc":[{"batb":[[0,1.56,33.99],[1,1.01,10.51],[2,1.56,0]],"batl":[[0,2.42,286.52],[1,2.18,0],[2,2.42,0]],"ltp":1.85,"tv":416.88,"id":4596961}]}]}
{"op":"mcm","clk":"1004738857","pt":1580656670028,"mc":[{"id":"1.168224030","rc":[{"batb":[[1,1.87,114.78],[2,1.85,160.55]],"batl":[[0,1.95,134.85],[1,1.97,134.37]],"ltp":2.18,"tv":1707.95,"id":8908205}]}]}
{"op":"mcm","clk":"1004739110","pt":1580656670985,"mc":[{"id":"1.168224030","rc":[{"batb":[[0,2,29.58],[1,1.76,22.58],[2,1.01,10.51]],"ltp":1.85,"tv":416.88,"id":4596961}]}]}
{"op":"mcm","clk":"1004739274","pt":1580656671792,"mc":[{"id":"1.168224030","rc":[{"batl":[[0,2.32,31.09]],"ltp":1.85,"tv":416.88,"id":4596961}]}]}
{"op":"mcm","clk":"1004739551","pt":1580656672984,"mc":[{"id":"1.168224030","rc":[{"batl":[[2,2.5,274.54]],"ltp":2.18,"tv":1707.95,"id":8908205},{"batl":[[1,2.72,241.55]],"ltp":1.85,"tv":416.88,"id":4596961}]}]}
{"op":"mcm","clk":"1004741900","pt":1580656682822,"mc":[{"id":"1.168224030","rc":[{"batb":[[1,1.77,53.77],[2,1.72,22.9]],"batl":[[0,2.5,274.54],[1,1.97,0],[2,2.5,0]],"ltp":2.18,"tv":1707.95,"id":8908205}]}]}
{"op":"mcm","clk":"1004742175","pt":1580656684057,"mc":[{"id":"1.168224030","rc":[{"batb":[[0,1.77,53.77],[1,1.72,22.9],[2,1.01,10.51]],"ltp":2.18,"tv":1707.95,"id":8908205},{"batb":[[0,1.76,22.58],[1,1.01,10.51],[2,1.01,0]],"ltp":1.85,"tv":416.88,"id":4596961}]}]}
{"op":"mcm","clk":"1004742347","pt":1580656684834,"mc":[{"id":"1.168224030","rc":[{"batb":[[0,1.72,22.9],[1,1.01,10.51],[2,1.01,0]],"ltp":2.18,"tv":1707.95,"id":8908205},{"batl":[[0,2.72,241.55],[1,2.72,0]],"ltp":1.85,"tv":416.88,"id":4596961}]}]}
{"op":"mcm","clk":"1004742541","pt":1580656685745,"mc":[{"id":"1.168224030","rc":[{"batb":[[0,1.72,225.59],[1,1.7,213.29],[2,1.01,10.51]],"batl":[[0,2.24,121.04],[1,2.26,90.5],[2,2.5,274.54]],"ltp":2.18,"tv":1707.95,"id":8908205}]}]}
{"op":"mcm","clk":"1004745592","pt":1580656699113,"mc":[{"id":"1.168224030","rc":[{"batb":[[0,1.72,22.9],[1,1.01,10.51],[2,1.01,0]],"batl":[[0,2.5,274.54],[1,2.26,0],[2,2.5,0]],"ltp":2.18,"tv":1707.95,"id":8908205}]}]}
