{"op":"mcm","clk":"997862772","pt":1580583479664,"mc":[{"id":"1.168224028","marketDefinition":{"bspMarket":false,"turnInPlayEnabled":true,"persistenceEnabled":true,"marketBaseRate":5.0,"eventId":"29681672","eventTypeId":"2","numberOfWinners":1,"bettingType":"ODDS","marketType":"SET_BETTING","marketTime":"2020-02-02T13:00:00.000Z","suspendTime":"2020-02-02T13:00:00.000Z","bspReconciled":false,"complete":true,"inPlay":false,"crossMatching":false,"runnersVoidable":false,"numberOfActiveRunners":4,"betDelay":0,"status":"OPEN","runners":[{"status":"ACTIVE","sortPriority":1,"id":17467774,"name":"Ficovich 2-0"},{"status":"ACTIVE","sortPriority":2,"id":17467775,"name":"Ficovich 2-1"},{"status":"ACTIVE","sortPriority":3,"id":16775228,"name":"Horansky 2-0"},{"status":"ACTIVE","sortPriority":4,"id":16775230,"name":"Horansky 2-1"}],"regulators":["MR_INT"],"countryCode":"AR","discountAllowed":false,"timezone":"UTC","openDate":"2020-02-02T13:00:00.000Z","version":3146950740,"name":"Set Betting","eventName":"Ficovich v Horansky"}}]}
{"op":"mcm","clk":"997863080","pt":1580583482122,"mc":[{"id":"1.168224028","marketDefinition":{"bspMarket":false,"turnInPlayEnabled":true,"persistenceEnabled":true,"marketBaseRate":5.0,"eventId":"29681672","eventTypeId":"2","numberOfWinners":1,"bettingType":"ODDS","marketType":"SET_BETTING","marketTime":"2020-02-02T13:00:00.000Z","suspendTime":"2020-02-02T13:00:00.000Z","bspReconciled":false,"complete":true,"inPlay":false,"crossMatching":false,"runnersVoidable":false,"numberOfActiveRunners":4,"betDelay":0,"status":"OPEN","runners":[{"status":"ACTIVE","sortPriority":1,"id":17467774,"name":"Ficovich 2-0"},{"status":"ACTIVE","sortPriority":2,"id":17467775,"name":"Ficovich 2-1"},{"status":"ACTIVE","sortPriority":3,"id":16775228,"name":"Horansky 2-0"},{"status":"ACTIVE","sortPriority":4,"id":16775230,"name":"Horansky 2-1"}],"regulators":["MR_INT"],"countryCode":"AR","discountAllowed":false,"timezone":"UTC","openDate":"2020-02-02T13:00:00.000Z","version":3146950740,"name":"Set Betting","eventName":"Ficovich v Horansky"}}]}
{"op":"mcm","clk":"997863088","pt":1580583482128,"mc":[{"id":"1.168224028","marketDefinition":{"bspMarket":false,"turnInPlayEnabled":true,"persistenceEnabled":true,"marketBaseRate":5.0,"eventId":"29681672","eventTypeId":"2","numberOfWinners":1,"bettingType":"ODDS","marketType":"SET_BETTING","marketTime":"2020-02-02T13:00:00.000Z","suspendTime":"2020-02-02T13:00:00.000Z","bspReconciled":false,"complete":true,"inPlay":false,"crossMatching":false,"runnersVoidable":false,"numberOfActiveRunners":4,"betDelay":0,"status":"OPEN","runners":[{"status":"ACTIVE","sortPriority":1,"id":17467774,"name":"Ficovich 2-0"},{"status":"ACTIVE","sortPriority":2,"id":17467775,"name":"Ficovich 2-1"},{"status":"ACTIVE","sortPriority":3,"id":16775228,"name":"Horansky 2-0"},{"status":"ACTIVE","sortPriority":4,"id":16775230,"name":"Horansky 2-1"}],"regulators":["MR_INT"],"countryCode":"AR","discountAllowed":true,"timezone":"UTC","openDate":"2020-02-02T13:00:00.000Z","version":3146950740,"name":"Set Betting","eventName":"Ficovich v Horansky"}}]}
{"op":"mcm","clk":"997996338","pt":1580584351358,"mc":[{"id":"1.168224028","rc":[{"batb":[[0,1.02,2]],"ltp":0.0,"tv":0.0,"id":17467775},{"batb":[[0,1.02,2]],"ltp":0.0,"tv":0.0,"id":17467774},{"batb":[[0,1.02,2]],"ltp":0.0,"tv":0.0,"id":16775228},{"batb":[[0,1.02,2]],"ltp":0.0,"tv":0.0,"id":16775230}]}]}
{"op":"mcm","clk":"998890757","pt":1580590302846,"mc":[{"id":"1.168224028","marketDefinition":{"bspMarket":false,"turnInPlayEnabled":true,"persistenceEnabled":true,"marketBaseRate":5.0,"eventId":"29681672","eventTypeId":"2","numberOfWinners":1,"bettingType":"ODDS","marketType":"SET_BETTING","marketTime":"2020-02-02T14:00:00.000Z","suspendTime":"2020-02-02T14:00:00.000Z","bspReconciled":false,"complete":true,"inPlay":false,"crossMatching":false,"runnersVoidable":false,"numberOfActiveRunners":4,"betDelay":0,"status":"OPEN","runners":[{"status":"ACTIVE","sortPriority":1,"id":17467774,"name":"Ficovich 2-0"},{"status":"ACTIVE","sortPriority":2,"id":17467775,"name":"Ficovich 2-1"},{"status":"ACTIVE","sortPriority":3,"id":16775228,"name":"Horansky 2-0"},{"status":"ACTIVE","sortPriority":4,"id":16775230,"name":"Horansky 2-1"}],"regulators":["MR_INT"],"countryCode":"AR","discountAllowed":true,"timezone":"UTC","openDate":"2020-02-02T13:00:00.000Z","version":3147422057,"name":"Set Betting","eventName":"Ficovich v Horansky"}}]}
{"op":"mcm","clk":"998891049","pt":1580590304855,"mc":[{"id":"1.168224028","marketDefinition":{"bspMarket":false,"turnInPlayEnabled":true,"persistenceEnabled":true,"marketBaseRate":5.0,"eventId":"29681672","eventTypeId":"2","numberOfWinners":1,"bettingType":"ODDS","marketType":"SET_BETTING","marketTime":"2020-02-02T14:00:00.000Z","suspendTime":"2020-02-02T14:00:00.000Z","bspReconciled":false,"complete":true,"inPlay":false,"crossMatching":false,"runnersVoidable":false,"numberOfActiveRunners":4,"betDelay":0,"status":"OPEN","runners":[{"status":"ACTIVE","sortPriority":1,"id":17467774,"name":"Ficovich 2-0"},{"status":"ACTIVE","sortPriority":2,"id":17467775,"name":"Ficovich 2-1"},{"status":"ACTIVE","sortPriority":3,"id":16775228,"name":"Horansky 2-0"},{"status":"ACTIVE","sortPriority":4,"id":16775230,"name":"Horansky 2-1"}],"regulators":["MR_INT"],"countryCode":"AR","discountAllowed":true,"timezone":"UTC","openDate":"2020-02-02T14:00:00.000Z","version":3147422057,"name":"Set Betting","eventName":"Ficovich v Horansky"}}]}
{"op":"mcm","clk":"999672725","pt":1580598654192,"mc":[{"id":"1.168224028","rc":[{"batb":[[0,2.46,30.29],[1,1.02,2]],"ltp":0.0,"tv":0.0,"id":17467774}]}]}
{"op":"mcm","clk":"999926852","pt":1580602757086,"mc":[{"id":"1.168224028","rc":[{"batb":[[1,1.01,2.53]],"ltp":0.0,"tv":0.0,"id":17467775},{"batb":[[2,1.01,2.53]],"ltp":0.0,"tv":0.0,"id":17467774},{"batb":[[1,1.01,2.53]],"ltp":0.0,"tv":0.0,"id":16775228},{"batb":[[1,1.01,2.53]],"ltp":0.0,"tv":0.0,"id":16775230}]}]}
{"op":"mcm","clk":"999926919","pt":1580602758073,"mc":[{"id":"1.168224028","rc":[{"batb":[[1,1.01,0]],"ltp":0.0,"tv":0.0,"id":17467775},{"batb":[[2,1.01,0]],"ltp":0.0,"tv":0.0,"id":17467774},{"batb":[[1,1.01,0]],"ltp":0.0,"tv":0.0,"id":16775228},{"batb":[[1,1.01,0]],"ltp":0.0,"tv":0.0,"id":16775230}]}]}
{"op":"mcm","clk":"999926930","pt":1580602758182,"mc":[{"id":"1.168224028","rc":[{"batb":[[1,1.01,0.51]],"ltp":0.0,"tv":0.0,"id":17467775},{"batb":[[2,1.01,0.51]],"ltp":0.0,"tv":0.0,"id":17467774},{"batb":[[1,1.01,0.51]],"ltp":0.0,"tv":0.0,"id":16775228},{"batb":[[1,1.01,0.51]],"ltp":0.0,"tv":0.0,"id":16775230}]}]}
{"op":"mcm","clk":"999971968","pt":1580603522041,"mc":[{"id":"1.168224028","rc":[{"batb":[[1,1.01,1.01]],"ltp":0.0,"tv":0.0,"id":17467775},{"batb":[[2,1.01,1.01]],"ltp":0.0,"tv":0.0,"id":17467774},{"batb":[[1,1.01,1.01]],"ltp":0.0,"tv":0.0,"id":16775228},{"batb":[[1,1.01,1.01]],"ltp":0.0,"tv":0.0,"id":16775230}]}]}
{"op":"mcm","clk":"1003616459","pt":1580651112049,"mc":[{"id":"1.168224028","rc":[{"batb":[[0,1.02,2],[1,1.01,1.01],[2,1.01,0]],"ltp":0.0,"tv":0.0,"id":17467774}]}]}
{"op":"mcm","clk":"1003804455","pt":1580652097370,"mc":[{"id":"1.168224028","rc":[{"batb":[[0,4.5,17],[1,1.02,2],[2,1.01,1.01]],"batl":[[0,5.2,16.21]],"ltp":0.0,"tv":0.0,"id":17467775},{"batb":[[0,2.98,23.6],[1,1.02,2],[2,1.01,1.01]],"batl":[[0,3.3,22.74]],"ltp":0.0,"tv":0.0,"id":17467774},{"batb":[[0,3.35,17.15],[1,1.02,2],[2,1.01,1.01]],"batl":[[0,3.75,16.6]],"ltp":0.0,"tv":0.0,"id":16775228},{"batb":[[0,4.8,14.48],[1,1.02,2],[2,1.01,1.01]],"batl":[[0,5.6,13.85]],"ltp":0.0,"tv":0.0,"id":16775230}]}]}
{"op":"mcm","clk":"1003823937","pt":1580652185875,"mc":[{"id":"1.168224028","rc":[{"batb":[[0,4.6,10.92],[1,4.5,17],[2,1.02,2]],"batl":[[1,5.6,8.4]],"ltp":0.0,"tv":0.0,"id":17467775},{"batb":[[1,2.8,22.69],[2,1.02,2]],"batl":[[0,3.2,18.48],[1,3.3,22.74]],"ltp":0.0,"tv":0.0,"id":17467774},{"batb":[[1,3.25,18.48],[2,1.02,2]],"batl":[[0,3.75,31.73]],"ltp":0.0,"tv":0.0,"id":16775228},{"batb":[[0,4.9,10.08],[1,4.8,14.48],[2,1.02,2]],"batl":[[1,6,8.4]],"ltp":0.0,"tv":0.0,"id":16775230}]}]}
{"op":"mcm","clk":"1003824171","pt":1580652186854,"mc":[{"id":"1.168224028","rc":[{"batb":[[0,4.6,27.6],[1,1.02,2],[2,1.01,1.01]],"batl":[[0,5.2,15.97]],"ltp":0.0,"tv":0.0,"id":17467775},{"trd":[[2.98,47.21]],"batb":[[0,2.92,24.55]],"batl":[[0,2.98,125.01],[1,3.15,23.6],[2,3.2,18.48]],"ltp":2.98,"tv":47.2,"id":17467774},{"batb":[[0,3.45,16.92]],"batl":[[0,3.75,31.49]],"ltp":0.0,"tv":0.0,"id":16775228},{"batb":[[0,4.9,24.32],[1,1.02,2],[2,1.01,1.01]],"batl":[[0,5.6,13.69]],"ltp":0.0,"tv":0.0,"id":16775230}],"tv":47.2}]}
{"op":"mcm","clk":"1003826530","pt":1580652197301,"mc":[{"id":"1.168224028","marketDefinition":{"bspMarket":false,"turnInPlayEnabled":true,"persistenceEnabled":true,"marketBaseRate":5.0,"eventId":"29681672","eventTypeId":"2","numberOfWinners":1,"bettingType":"ODDS","marketType":"SET_BETTING","marketTime":"2020-02-02T14:00:00.000Z","suspendTime":"2020-02-02T14:00:00.000Z","bspReconciled":false,"complete":true,"inPlay":false,"crossMatching":true,"runnersVoidable":false,"numberOfActiveRunners":4,"betDelay":0,"status":"OPEN","runners":[{"status":"ACTIVE","sortPriority":1,"id":17467774,"name":"Ficovich 2-0"},{"status":"ACTIVE","sortPriority":2,"id":17467775,"name":"Ficovich 2-1"},{"status":"ACTIVE","sortPriority":3,"id":16775228,"name":"Horansky 2-0"},{"status":"ACTIVE","sortPriority":4,"id":16775230,"name":"Horansky 2-1"}],"regulators":["MR_INT"],"countryCode":"AR","discountAllowed":true,"timezone":"UTC","openDate":"2020-02-02T14:00:00.000Z","version":3149079702,"name":"Set Betting","eventName":"Ficovich v Horansky"}}]}
{"op":"mcm","clk":"1003826797","pt":1580652198379,"mc":[{"id":"1.168224028","rc":[{"trd":[[2.92,49.1]],"batb":[[0,2.8,22.69],[1,1.02,2],[2,1.01,1.01]],"batl":[[0,2.92,100.46]],"ltp":2.92,"tv":96.3,"id":17467774}],"tv":96.3}]}
{"op":"mcm","clk":"1003827037","pt":1580652199402,"mc":[{"id":"1.168224028","rc":[{"batb":[[0,4.6,27.29]],"batl":[[0,5.3,15.66]],"ltp":0.0,"tv":0.0,"id":17467775},{"batb":[[0,2.88,25.57],[1,2.8,22.69],[2,1.02,2]],"batl":[[1,3.1,24.55]],"ltp":2.92,"tv":96.3,"id":17467774},{"batb":[[0,3.5,16.6]],"batl":[[0,3.75,15.12],[1,3.8,16.05]],"ltp":0.0,"tv":0.0,"id":16775228},{"batb":[[0,5,14.01],[1,4.9,10.08],[2,1.02,2]],"batl":[[0,5.6,13.45]],"ltp":0.0,"tv":0.0,"id":16775230}]}]}
{"op":"mcm","clk":"1003838212","pt":1580652247053,"mc":[{"id":"1.168224028","rc":[{"batl":[[0,3.1,24.55],[1,3.2,18.48],[2,3.2,0]],"ltp":2.92,"tv":96.3,"id":17467774}]}]}
{"op":"mcm","clk":"1003838258","pt":1580652247229,"mc":[{"id":"1.168224028","rc":[{"batl":[[0,2.9,100.46],[1,3.1,24.55],[2,3.2,18.48]],"ltp":2.92,"tv":96.3,"id":17467774}]}]}
{"op":"mcm","clk":"1003858337","pt":1580652329819,"mc":[{"id":"1.168224028","rc":[{"trd":[[2.88,80.18]],"batb":[[0,2.8,22.69],[1,1.02,2],[2,1.01,1.01]],"batl":[[0,2.88,60.37]],"ltp":2.88,"tv":176.48,"id":17467774}],"tv":176.48}]}
{"op":"mcm","clk":"1003858478","pt":1580652330433,"mc":[{"id":"1.168224028","rc":[{"batb":[[0,4.7,16.13],[1,4.6,10.92],[2,1.02,2]],"batl":[[0,5.3,15.34]],"ltp":0.0,"tv":0.0,"id":17467775},{"batb":[[0,2.86,10.54],[1,2.8,22.69],[2,1.02,2]],"batl":[[1,3.05,10.31]],"ltp":2.88,"tv":176.48,"id":17467774},{"batb":[[0,3.5,16.29]],"batl":[[1,3.85,15.74]],"ltp":0.0,"tv":0.0,"id":16775228},{"batb":[[0,5,13.77]],"batl":[[0,5.7,13.22]],"ltp":0.0,"tv":0.0,"id":16775230}]}]}
{"op":"mcm","clk":"1003864190","pt":1580652354115,"mc":[{"id":"1.168224028","rc":[{"trd":[[2.86,25.09]],"batb":[[0,2.84,10.7]],"batl":[[0,2.86,47.83]],"ltp":2.86,"tv":201.57,"id":17467774},{"batb":[[0,3.55,16.13],[1,3.5,16.29],[2,3.25,18.48]],"ltp":0.0,"tv":0.0,"id":16775228}],"tv":201.57}]}
{"op":"mcm","clk":"1003864238","pt":1580652354298,"mc":[{"id":"1.168224028","rc":[{"batb":[[0,4.7,15.97]],"ltp":0.0,"tv":0.0,"id":17467775},{"batb":[[1,3.25,18.48],[2,1.02,2]],"batl":[[1,3.85,15.58]],"ltp":0.0,"tv":0.0,"id":16775228},{"batb":[[0,5,13.61]],"batl":[[0,5.7,13.06]],"ltp":0.0,"tv":0.0,"id":16775230}]}]}
{"op":"mcm","clk":"1003870564","pt":1580652381049,"mc":[{"id":"1.168224028","rc":[{"batl":[[0,3.05,10.31],[1,3.2,18.48],[2,3.2,0]],"ltp":2.86,"tv":201.57,"id":17467774}]}]}
{"op":"mcm","clk":"1003870772","pt":1580652381954,"mc":[{"id":"1.168224028","rc":[{"batb":[[0,4.7,15.82]],"batl":[[0,5.3,15.19]],"ltp":0.0,"tv":0.0,"id":17467775},{"trd":[[2.84,29]],"batb":[[0,2.82,10.86]],"batl":[[0,2.84,33.33],[1,3,10.7],[2,3.2,18.48]],"ltp":2.84,"tv":230.57,"id":17467774},{"batb":[[0,3.55,15.97]],"ltp":0.0,"tv":0.0,"id":16775228},{"batb":[[0,5.1,13.53]],"ltp":0.0,"tv":0.0,"id":16775230}],"tv":230.57}]}
{"op":"mcm","clk":"1003875886","pt":1580652403091,"mc":[{"id":"1.168224028","rc":[{"batb":[[0,4.6,10.92],[1,1.02,2],[2,1.01,1.01]],"batl":[[0,5.6,8.4],[1,5.6,0]],"ltp":0.0,"tv":0.0,"id":17467775},{"batb":[[0,2.8,22.69],[1,1.02,2],[2,1.01,1.01]],"batl":[[1,3.2,18.48],[2,3.2,0]],"ltp":2.84,"tv":230.57,"id":17467774},{"batb":[[0,3.25,18.48],[1,1.02,2],[2,1.01,1.01]],"batl":[[1,3.85,0]],"ltp":0.0,"tv":0.0,"id":16775228},{"batb":[[0,4.9,10.08],[1,1.02,2],[2,1.01,1.01]],"batl":[[0,6,8.4],[1,6,0]],"ltp":0.0,"tv":0.0,"id":16775230}]}]}
{"op":"mcm","clk":"1003876018","pt":1580652403595,"mc":[{"id":"1.168224028","marketDefinition":{"bspMarket":false,"turnInPlayEnabled":true,"persistenceEnabled":true,"marketBaseRate":5.0,"eventId":"29681672","eventTypeId":"2","numberOfWinners":1,"bettingType":"ODDS","marketType":"SET_BETTING","marketTime":"2020-02-02T14:00:00.000Z","suspendTime":"2020-02-02T14:00:00.000Z","bspReconciled":false,"complete":true,"inPlay":true,"crossMatching":true,"runnersVoidable":false,"numberOfActiveRunners":4,"betDelay":3,"status":"OPEN","runners":[{"status":"ACTIVE","sortPriority":1,"id":17467774,"name":"Ficovich 2-0"},{"status":"ACTIVE","sortPriority":2,"id":17467775,"name":"Ficovich 2-1"},{"status":"ACTIVE","sortPriority":3,"id":16775228,"name":"Horansky 2-0"},{"status":"ACTIVE","sortPriority":4,"id":16775230,"name":"Horansky 2-1"}],"regulators":["MR_INT"],"countryCode":"AR","discountAllowed":true,"timezone":"UTC","openDate":"2020-02-02T14:00:00.000Z","version":3149116736,"name":"Set Betting","eventName":"Ficovich v Horansky"},"rc":[{"batb":[[0,1.01,0.51],[1,1.02,0],[2,1.01,0]],"ltp":0.0,"tv":0.0,"id":17467775},{"batb":[[0,1.01,0.51],[1,1.02,0],[2,1.01,0]],"batl":[[1,3.2,0]],"ltp":2.84,"tv":230.57,"id":17467774},{"batb":[[0,1.01,0.51],[1,1.02,0],[2,1.01,0]],"ltp":0.0,"tv":0.0,"id":16775228},{"batb":[[0,1.01,0.51],[1,1.02,0],[2,1.01,0]],"ltp":0.0,"tv":0.0,"id":16775230}]}]}
{"op":"mcm","clk":"1003876886","pt":1580652407004,"mc":[{"id":"1.168224028","rc":[{"batb":[[0,4.6,10.92],[1,1.01,0.51]],"batl":[[0,5.6,8.4]],"ltp":0.0,"tv":0.0,"id":17467775},{"batb":[[0,2.76,23.53],[1,1.01,0.51]],"batl":[[1,3.2,18.48]],"ltp":2.84,"tv":230.57,"id":17467774},{"batb":[[0,3.25,18.48],[1,1.01,0.51]],"batl":[[0,3.8,14.28]],"ltp":0.0,"tv":0.0,"id":16775228},{"batb":[[0,4.9,10.08],[1,1.01,0.51]],"batl":[[0,6,8.4]],"ltp":0.0,"tv":0.0,"id":16775230}]}]}
{"op":"mcm","clk":"1003876959","pt":1580652407313,"mc":[{"id":"1.168224028","rc":[{"batb":[[0,1.01,0.51],[1,1.01,0]],"ltp":0.0,"tv":0.0,"id":17467775},{"batb":[[0,1.01,0.51],[1,1.01,0]],"batl":[[1,3.2,0]],"ltp":2.84,"tv":230.57,"id":17467774},{"batb":[[0,1.01,0.51],[1,1.01,0]],"ltp":0.0,"tv":0.0,"id":16775228},{"batb":[[0,1.01,0.51],[1,1.01,0]],"ltp":0.0,"tv":0.0,"id":16775230}]}]}
{"op":"mcm","clk":"1003877907","pt":1580652410794,"mc":[{"id":"1.168224028","rc":[{"batb":[[0,4.7,32.41],[1,4.6,38.79],[2,1.01,0.51]],"ltp":0.0,"tv":0.0,"id":17467775},{"trd":[[2.84,95.65]],"batb":[[0,2.96,7.92],[1,2.92,46.83],[2,1.01,0.51]],"ltp":2.84,"tv":297.22,"id":17467774},{"batb":[[0,3.5,43.95],[1,3.45,38.54],[2,1.01,0.51]],"ltp":0.0,"tv":0.0,"id":16775228},{"batb":[[0,5,41.8],[1,4.9,33.44],[2,1.01,0.51]],"ltp":0.0,"tv":0.0,"id":16775230}],"tv":297.22}]}
{"op":"mcm","clk":"1003878103","pt":1580652411692,"mc":[{"id":"1.168224028","rc":[{"batb":[[0,4.6,38.79],[1,1.01,0.51],[2,1.01,0]],"ltp":0.0,"tv":0.0,"id":17467775},{"batb":[[0,1.01,0.51],[1,2.92,0],[2,1.01,0]],"ltp":2.84,"tv":297.22,"id":17467774},{"batb":[[0,1.01,0.51],[1,3.45,0],[2,1.01,0]],"ltp":0.0,"tv":0.0,"id":16775228}]}]}
{"op":"mcm","clk":"1003879096","pt":1580652415469,"mc":[{"id":"1.168224028","rc":[{"batb":[[0,4.6,57.28],[1,4.5,40.42],[2,1.01,0.51]],"ltp":0.0,"tv":0.0,"id":17467775},{"batb":[[0,2.72,62.95],[1,2.68,58.23],[2,1.01,0.51]],"ltp":2.84,"tv":297.22,"id":17467774},{"batb":[[0,3.2,33.89],[1,3.15,48.32],[2,1.01,0.51]],"ltp":0.0,"tv":0.0,"id":16775228}]}]}
{"op":"mcm","clk":"1003880595","pt":1580652421252,"mc":[{"id":"1.168224028","rc":[{"batb":[[0,4.6,38.79],[1,1.01,0.51],[2,1.01,0]],"ltp":0.0,"tv":0.0,"id":17467775},{"batb":[[0,1.01,0.51],[1,3.15,0],[2,1.01,0]],"ltp":0.0,"tv":0.0,"id":16775228}]}]}
{"op":"mcm","clk":"1003881581","pt":1580652425091,"mc":[{"id":"1.168224028","rc":[{"batb":[[0,4.8,15.66],[1,4.7,48.66],[2,4.6,38.79]],"batl":[[0,5.5,14.16]],"ltp":0.0,"tv":0.0,"id":17467775},{"batb":[[2,2.58,13.77]],"batl":[[0,2.74,13.45],[1,2.98,10.94]],"ltp":2.84,"tv":297.22,"id":17467774},{"batb":[[0,3.95,24.78],[1,3.85,40.36],[2,3.8,30.59]],"batl":[[0,4.4,23.45],[1,5,17.55]],"ltp":0.0,"tv":0.0,"id":16775228},{"batb":[[0,5.1,13.53],[1,5,41.8],[2,4.9,33.44]],"batl":[[0,5.7,12.98]],"ltp":0.0,"tv":0.0,"id":16775230}]}]}
{"op":"mcm","clk":"1003881761","pt":1580652425755,"mc":[{"id":"1.168224028","rc":[{"batb":[[2,4.6,49.71]],"batl":[[1,5.6,8.4]],"ltp":0.0,"tv":0.0,"id":17467775},{"batl":[[1,2.94,21],[2,2.98,10.94]],"ltp":2.84,"tv":297.22,"id":17467774},{"batl":[[0,4.3,12.6],[1,4.4,23.45],[2,5,17.55]],"ltp":0.0,"tv":0.0,"id":16775228},{"batb":[[2,4.9,43.52]],"batl":[[1,6,8.4]],"ltp":0.0,"tv":0.0,"id":16775230}]}]}
{"op":"mcm","clk":"1003884355","pt":1580652435514,"mc":[{"id":"1.168224028","rc":[{"batb":[[1,4.7,30.26]],"ltp":0.0,"tv":0.0,"id":17467775},{"batb":[[0,2.56,26.89],[1,2.38,17.07],[2,1.01,0.51]],"batl":[[0,2.94,21],[1,2.98,10.94],[2,2.98,0]],"ltp":2.84,"tv":297.22,"id":17467774},{"batb":[[0,3.6,15.96],[1,3.55,15.74],[2,1.01,0.51]],"batl":[[1,5,17.55],[2,5,0]],"ltp":0.0,"tv":0.0,"id":16775228}]}]}
{"op":"mcm","clk":"1003884643","pt":1580652436533,"mc":[{"id":"1.168224028","rc":[{"batb":[[2,4.6,38.79]],"batl":[[1,5.6,0]],"ltp":0.0,"tv":0.0,"id":17467775},{"batb":[[0,2.38,17.07],[1,1.01,0.51],[2,1.01,0]],"batl":[[0,2.98,10.94],[1,2.98,0]],"ltp":2.84,"tv":297.22,"id":17467774},{"batb":[[0,3.55,15.74],[1,1.01,0.51],[2,1.01,0]],"batl":[[0,5,17.55],[1,5,0]],"ltp":0.0,"tv":0.0,"id":16775228},{"batb":[[2,4.9,33.44]],"batl":[[1,6,0]],"ltp":0.0,"tv":0.0,"id":16775230}]}]}
{"op":"mcm","clk":"1003885049","pt":1580652438116,"mc":[{"id":"1.168224028","rc":[{"batb":[[0,2.46,50.88],[1,2.42,76.59],[2,2.38,17.07]],"ltp":2.84,"tv":297.22,"id":17467774},{"batb":[[1,3.5,39.9],[2,3.45,38.6]],"ltp":0.0,"tv":0.0,"id":16775228}]}]}
{"op":"mcm","clk":"1003885215","pt":1580652438720,"mc":[{"id":"1.168224028","rc":[{"batb":[[0,4.7,46.31],[1,4.6,38.79],[2,1.01,0.51]],"ltp":0.0,"tv":0.0,"id":17467775},{"batl":[[0,2.98,10.78]],"ltp":2.84,"tv":297.22,"id":17467774},{"batb":[[0,3.55,15.58]],"batl":[[0,5,17.23]],"ltp":0.0,"tv":0.0,"id":16775228},{"batb":[[0,5,55.49],[1,4.9,33.44],[2,1.01,0.51]],"ltp":0.0,"tv":0.0,"id":16775230}]}]}
{"op":"mcm","clk":"1003885908","pt":1580652440928,"mc":[{"id":"1.168224028","rc":[{"batb":[[1,1.01,0.51],[2,1.01,0]],"ltp":0.0,"tv":0.0,"id":17467775},{"batb":[[1,1.01,0.51],[2,3.45,0]],"ltp":0.0,"tv":0.0,"id":16775228}]}]}
{"op":"mcm","clk":"1003886700","pt":1580652443536,"mc":[{"id":"1.168224028","rc":[{"batb":[[0,4.8,37.04],[1,4.7,46.31],[2,1.01,0.51]],"ltp":0.0,"tv":0.0,"id":17467775},{"batb":[[0,4.5,35.89],[1,4.4,42.93],[2,3.55,15.58]],"ltp":0.0,"tv":0.0,"id":16775228}]}]}
{"op":"mcm","clk":"1003887126","pt":1580652445099,"mc":[{"id":"1.168224028","rc":[{"batb":[[0,4.8,52.54],[1,4.7,30.26]],"batl":[[1,5.6,13.93]],"ltp":0.0,"tv":0.0,"id":17467775},{"batl":[[0,2.52,16.76],[1,2.7,13.93]],"ltp":2.84,"tv":297.22,"id":17467774},{"batb":[[0,4.5,53.99],[2,4,23.29]],"batl":[[1,5.8,12.75]],"ltp":0.0,"tv":0.0,"id":16775228},{"batb":[[0,5.1,13.53],[1,5,41.8],[2,4.9,33.44]],"batl":[[0,5.8,12.9]],"ltp":0.0,"tv":0.0,"id":16775230}]}]}
{"op":"mcm","clk":"1003887261","pt":1580652445638,"mc":[{"id":"1.168224028","rc":[{"batb":[[1,4.7,41.18]],"batl":[[2,5.7,8.4]],"ltp":0.0,"tv":0.0,"id":17467775},{"batl":[[1,2.66,25.21],[2,2.7,13.93]],"ltp":2.84,"tv":297.22,"id":17467774},{"batb":[[2,4.1,13.44]],"batl":[[0,5,27.31]],"ltp":0.0,"tv":0.0,"id":16775228},{"batb":[[2,4.9,43.52]],"batl":[[1,6,8.4]],"ltp":0.0,"tv":0.0,"id":16775230}]}]}
{"op":"mcm","clk":"1003890531","pt":1580652458052,"mc":[{"id":"1.168224028","rc":[{"batb":[[0,4.8,15.5]],"batl":[[0,5.6,13.93],[1,5.7,8.4],[2,5.7,0]],"ltp":0.0,"tv":0.0,"id":17467775},{"batb":[[0,2.34,31.09],[1,2.22,20.85],[2,1.01,0.51]],"batl":[[0,2.66,25.21],[1,2.7,13.93],[2,2.7,0]],"ltp":2.84,"tv":297.22,"id":17467774},{"batb":[[0,4.1,13.44],[1,4,23.29],[2,1.01,0.51]],"batl":[[0,5,10.08]],"ltp":0.0,"tv":0.0,"id":16775228}]}]}
{"op":"mcm","clk":"1003890601","pt":1580652458340,"mc":[{"id":"1.168224028","rc":[{"batb":[[1,4.7,30.26]],"batl":[[1,5.7,0]],"ltp":0.0,"tv":0.0,"id":17467775},{"batb":[[0,2.22,20.85],[1,1.01,0.51],[2,1.01,0]],"batl":[[0,2.7,13.93],[1,2.7,0]],"ltp":2.84,"tv":297.22,"id":17467774},{"batb":[[0,4,23.29],[1,1.01,0.51],[2,1.01,0]],"batl":[[0,5.8,12.75],[1,5.8,0]],"ltp":0.0,"tv":0.0,"id":16775228},{"batb":[[2,4.9,33.44]],"batl":[[1,6,0]],"ltp":0.0,"tv":0.0,"id":16775230}]}]}
{"op":"mcm","clk":"1003891240","pt":1580652460812,"mc":[{"id":"1.168224028","rc":[{"batb":[[1,4.7,53.86],[2,4.6,38.46]],"ltp":0.0,"tv":0.0,"id":17467775},{"batb":[[0,2.24,53.55],[1,2.22,69.98],[2,1.01,0.51]],"ltp":2.84,"tv":297.22,"id":17467774},{"batb":[[0,4,73.47],[1,3.95,27.83],[2,1.01,0.51]],"ltp":0.0,"tv":0.0,"id":16775228}]}]}
{"op":"mcm","clk":"1003891557","pt":1580652462010,"mc":[{"id":"1.168224028","rc":[{"batb":[[0,2.22,20.85],[1,1.01,0.51],[2,1.01,0]],"ltp":2.84,"tv":297.22,"id":17467774}]}]}
{"op":"mcm","clk":"1003892310","pt":1580652465038,"mc":[{"id":"1.168224028","rc":[{"batb":[[0,2.64,61.84],[1,2.6,63.08],[2,2.22,20.85]],"ltp":2.84,"tv":297.22,"id":17467774}]}]}
{"op":"mcm","clk":"1003892584","pt":1580652466042,"mc":[{"id":"1.168224028","rc":[{"batb":[[1,4.7,69.75],[2,4.6,49.38]],"batl":[[0,5.4,14.87],[1,5.5,14.16],[2,5.6,8.4]],"ltp":0.0,"tv":0.0,"id":17467775},{"batb":[[2,2.54,14.24]],"batl":[[1,2.8,22.69],[2,2.96,11.09]],"ltp":2.84,"tv":297.22,"id":17467774},{"batb":[[2,3.8,14.28]],"batl":[[0,4.5,33.79],[1,5.3,15.58]],"ltp":0.0,"tv":0.0,"id":16775228},{"batb":[[0,5,65.49],[1,4.9,33.44],[2,1.01,0.51]],"batl":[[1,6,8.4]],"ltp":0.0,"tv":0.0,"id":16775230}]}]}
{"op":"mcm","clk":"1003892874","pt":1580652467083,"mc":[{"id":"1.168224028","rc":[{"batl":[[1,2.8,41.45]],"ltp":2.84,"tv":297.22,"id":17467774}]}]}
{"op":"mcm","clk":"1003895068","pt":1580652475120,"mc":[{"id":"1.168224028","rc":[{"batb":[[1,4.7,46.15]],"ltp":0.0,"tv":0.0,"id":17467775},{"batb":[[0,2.54,14.24],[1,2.46,28.57],[2,2.32,18.41]],"ltp":2.84,"tv":297.22,"id":17467774},{"batb":[[0,4,23.29],[1,3.8,14.28],[2,3.6,15.19]],"ltp":0.0,"tv":0.0,"id":16775228}]}]}
{"op":"mcm","clk":"1003895102","pt":1580652475182,"mc":[{"id":"1.168224028","rc":[{"batb":[[0,4.7,46.15],[1,4.6,49.38],[2,1.01,0.51]],"batl":[[0,5.5,14.16],[1,5.6,8.4],[2,5.6,0]],"ltp":0.0,"tv":0.0,"id":17467775},{"batb":[[0,2.46,28.57],[1,2.32,18.41],[2,1.01,0.51]],"batl":[[0,2.8,41.45],[1,2.96,11.09],[2,2.96,0]],"ltp":2.84,"tv":297.22,"id":17467774},{"batb":[[0,3.8,14.28],[1,3.6,15.19],[2,1.01,0.51]],"batl":[[0,4.5,11.76]],"ltp":0.0,"tv":0.0,"id":16775228}]}]}
{"op":"mcm","clk":"1003895471","pt":1580652476474,"mc":[{"id":"1.168224028","rc":[{"batb":[[1,4.6,38.46]],"batl":[[1,5.6,0]],"ltp":0.0,"tv":0.0,"id":17467775},{"batb":[[0,2.32,18.41],[1,1.01,0.51],[2,1.01,0]],"batl":[[0,2.8,18.77]],"ltp":2.84,"tv":297.22,"id":17467774},{"batb":[[0,3.6,15.19],[1,1.01,0.51],[2,1.01,0]],"batl":[[0,5.3,15.58],[1,5.3,0]],"ltp":0.0,"tv":0.0,"id":16775228},{"batb":[[0,5,55.41]],"batl":[[1,6,0]],"ltp":0.0,"tv":0.0,"id":16775230}]}]}
{"op":"mcm","clk":"1003895910","pt":1580652478101,"mc":[{"id":"1.168224028","rc":[{"batb":[[1,1.01,0.51],[2,1.01,0]],"ltp":0.0,"tv":0.0,"id":17467775},{"batb":[[0,2.34,71.86],[1,2.32,18.41],[2,2.3,88.02]],"ltp":2.84,"tv":297.22,"id":17467774},{"batb":[[1,3.55,53.52],[2,3.5,37.16]],"ltp":0.0,"tv":0.0,"id":16775228}]}]}
{"op":"mcm","clk":"1003895963","pt":1580652478277,"mc":[{"id":"1.168224028","rc":[{"batb":[[0,2.32,18.41],[1,1.01,0.51],[2,2.3,0]],"ltp":2.84,"tv":297.22,"id":17467774},{"batb":[[1,1.01,0.51],[2,3.5,0]],"ltp":0.0,"tv":0.0,"id":16775228}]}]}
{"op":"mcm","clk":"1003896614","pt":1580652480711,"mc":[{"id":"1.168224028","rc":[{"batb":[[0,4.8,22.83],[1,4.7,46.15],[2,1.01,0.51]],"ltp":0.0,"tv":0.0,"id":17467775},{"batb":[[0,2.58,53.4],[1,2.54,67.18],[2,2.32,18.41]],"ltp":2.84,"tv":297.22,"id":17467774},{"batb":[[0,4.1,74.75],[1,4,52.91],[2,3.6,15.19]],"ltp":0.0,"tv":0.0,"id":16775228}]}]}
{"op":"mcm","clk":"1003896973","pt":1580652482082,"mc":[{"id":"1.168224028","rc":[{"batb":[[0,4.7,46.15],[1,1.01,0.51],[2,1.01,0]],"ltp":0.0,"tv":0.0,"id":17467775},{"batb":[[0,2.32,18.41],[1,1.01,0.51],[2,2.32,0]],"ltp":2.84,"tv":297.22,"id":17467774},{"batb":[[0,3.6,15.19],[1,1.01,0.51],[2,3.6,0]],"ltp":0.0,"tv":0.0,"id":16775228}]}]}
{"op":"mcm","clk":"1003897788","pt":1580652485102,"mc":[{"id":"1.168224028","rc":[{"batb":[[1,4.6,38.85],[2,1.01,0.51]],"ltp":0.0,"tv":0.0,"id":17467775},{"batb":[[0,2.34,71.86],[1,2.32,18.41],[2,2.3,88.02]],"ltp":2.84,"tv":297.22,"id":17467774},{"batb":[[1,3.55,53.52],[2,3.5,37.16]],"ltp":0.0,"tv":0.0,"id":16775228}]}]}
{"op":"mcm","clk":"1003898001","pt":1580652485929,"mc":[{"id":"1.168224028","rc":[{"batb":[[1,1.01,0.51],[2,1.01,0]],"ltp":0.0,"tv":0.0,"id":17467775},{"batb":[[0,2.32,18.41],[1,1.01,0.51],[2,2.3,0]],"ltp":2.84,"tv":297.22,"id":17467774},{"batb":[[1,1.01,0.51],[2,3.5,0]],"ltp":0.0,"tv":0.0,"id":16775228}]}]}
{"op":"mcm","clk":"1003898837","pt":1580652488907,"mc":[{"id":"1.168224028","rc":[{"batb":[[0,4.8,49.61],[1,4.7,46.15],[2,1.01,0.51]],"ltp":0.0,"tv":0.0,"id":17467775},{"batb":[[0,2.34,71.86],[1,2.32,18.41],[2,2.3,88.02]],"ltp":2.84,"tv":297.22,"id":17467774},{"batb":[[0,4.9,36.12],[1,4.8,35.17],[2,3.6,15.19]],"ltp":0.0,"tv":0.0,"id":16775228}]}]}
{"op":"mcm","clk":"1003899058","pt":1580652489695,"mc":[{"id":"1.168224028","rc":[{"batb":[[0,4.9,14.87],[1,4.8,64.8],[2,4.7,41.18]],"batl":[[0,5.6,13.61],[1,5.7,8.4]],"ltp":0.0,"tv":0.0,"id":17467775},{"batl":[[0,2.44,18.02],[1,2.52,26.89],[2,2.64,14.87]],"ltp":2.84,"tv":297.22,"id":17467774},{"batb":[[2,4.7,16.29]],"batl":[[1,5.5,9.24],[2,6.2,11.25]],"ltp":0.0,"tv":0.0,"id":16775228},{"batb":[[1,4.9,43.52]],"batl":[[1,5.9,8.4]],"ltp":0.0,"tv":0.0,"id":16775230}]}]}
{"op":"mcm","clk":"1003902908","pt":1580652503480,"mc":[{"id":"1.168224028","rc":[{"batb":[[0,4.8,42.05],[1,4.7,41.18],[2,1.01,0.51]],"ltp":0.0,"tv":0.0,"id":17467775},{"batb":[[0,2.24,33.61],[1,2.16,22.5],[2,1.01,0.51]],"batl":[[0,2.52,26.89],[1,2.64,14.87],[2,2.8,18.77]],"ltp":2.84,"tv":297.22,"id":17467774},{"batb":[[0,4.5,11.76],[1,4.2,21.32],[2,1.01,0.51]],"batl":[[0,5.5,9.24],[1,6.2,11.25],[2,6.2,0]],"ltp":0.0,"tv":0.0,"id":16775228}]}]}
{"op":"mcm","clk":"1003903179","pt":1580652504498,"mc":[{"id":"1.168224028","rc":[{"batb":[[1,4.7,30.26]],"batl":[[1,5.7,0]],"ltp":0.0,"tv":0.0,"id":17467775},{"batb":[[0,2.16,22.5],[1,1.01,0.51],[2,1.01,0]],"batl":[[0,2.64,14.87],[1,2.8,18.77],[2,2.8,0]],"ltp":2.84,"tv":297.22,"id":17467774},{"batb":[[0,4.2,21.32],[1,1.01,0.51],[2,1.01,0]],"batl":[[0,6.2,11.25],[1,6.2,0]],"ltp":0.0,"tv":0.0,"id":16775228},{"batb":[[1,4.9,33.44]],"batl":[[1,5.9,0]],"ltp":0.0,"tv":0.0,"id":16775230}]}]}
{"op":"mcm","clk":"1003903684","pt":1580652506390,"mc":[{"id":"1.168224028","rc":[{"batb":[[1,2.12,97.24],[2,2.1,57.64]],"ltp":2.84,"tv":297.22,"id":17467774},{"batb":[[0,4.3,37.14],[1,4.2,69.13],[2,1.01,0.51]],"ltp":0.0,"tv":0.0,"id":16775228}]}]}
{"op":"mcm","clk":"1003906051","pt":1580652515243,"mc":[{"id":"1.168224028","rc":[{"batb":[[1,1.01,0.51],[2,1.01,0]],"ltp":0.0,"tv":0.0,"id":17467775},{"batb":[[0,4.2,21.32],[1,1.01,0.51],[2,1.01,0]],"ltp":0.0,"tv":0.0,"id":16775228}]}]}
{"op":"mcm","clk":"1003907037","pt":1580652518959,"mc":[{"id":"1.168224028","rc":[{"batb":[[0,4.9,59.57],[1,4.8,50.2],[2,1.01,0.51]],"batl":[[1,5.7,13.3]],"ltp":0.0,"tv":0.0,"id":17467775},{"batl":[[0,2.28,21.95],[1,2.44,17.94],[2,2.64,14.87]],"ltp":2.84,"tv":297.22,"id":17467774},{"batb":[[0,6,48.01],[1,5.9,21.93],[2,5.4,11.64]],"batl":[[1,7.2,16.29]],"ltp":0.0,"tv":0.0,"id":16775228},{"batb":[[0,5.1,13.69],[1,5,63.09],[2,4.9,33.44]],"ltp":0.0,"tv":0.0,"id":16775230}]}]}
{"op":"mcm","clk":"1003907265","pt":1580652519754,"mc":[{"id":"1.168224028","rc":[{"batb":[[1,4.8,35.01],[2,4.7,10.92]],"batl":[[1,5.7,21.7]],"ltp":0.0,"tv":0.0,"id":17467775},{"batl":[[0,2.18,35.29],[1,2.28,21.95],[2,2.44,17.94]],"ltp":2.84,"tv":297.22,"id":17467774},{"batl":[[2,7.8,5.88]],"ltp":0.0,"tv":0.0,"id":16775228},{"batb":[[1,5,49.48]],"batl":[[0,5.8,12.59],[1,6.2,7.56]],"ltp":0.0,"tv":0.0,"id":16775230}]}]}
{"op":"mcm","clk":"1003907906","pt":1580652522145,"mc":[{"id":"1.168224028","rc":[{"batb":[[0,5.1,23.77]],"ltp":0.0,"tv":0.0,"id":16775230}]}]}
{"op":"mcm","clk":"1003908717","pt":1580652525073,"mc":[{"id":"1.168224028","rc":[{"batl":[[2,7.8,0]],"ltp":0.0,"tv":0.0,"id":16775228}]}]}
{"op":"mcm","clk":"1003909520","pt":1580652527953,"mc":[{"id":"1.168224028","rc":[{"batb":[[0,2.12,120.69],[1,2.1,57.64],[2,2,27.77]],"batl":[[1,2.24,22.82],[2,2.4,18.8]],"ltp":2.84,"tv":297.22,"id":17467774},{"batb":[[0,6.2,7.56],[1,6,48.01],[2,5.9,21.93]],"batl":[[0,6.4,10.46],[1,7.4,15.19],[2,7.6,5.88]],"ltp":0.0,"tv":0.0,"id":16775228},{"batb":[[0,5.1,23.3]],"batl":[[0,5.9,12.2]],"ltp":0.0,"tv":0.0,"id":16775230}]}]}
{"op":"mcm","clk":"1003909628","pt":1580652528374,"mc":[{"id":"1.168224028","rc":[{"batb":[[0,6,48.01],[1,5.9,21.93],[2,5.6,10.94]],"batl":[[2,7.6,0]],"ltp":0.0,"tv":0.0,"id":16775228}]}]}
{"op":"mcm","clk":"1003910335","pt":1580652530807,"mc":[{"id":"1.168224028","rc":[{"batb":[[0,6.2,7.56],[1,6,48.01],[2,5.9,21.93]],"batl":[[2,7.8,5.88]],"ltp":0.0,"tv":0.0,"id":16775228}]}]}
{"op":"mcm","clk":"1003911124","pt":1580652533596,"mc":[{"id":"1.168224028","rc":[{"batb":[[1,5,32.36],[2,1.01,0.51]],"ltp":0.0,"tv":0.0,"id":16775230}]}]}
{"op":"mcm","clk":"1003911695","pt":1580652535518,"mc":[{"id":"1.168224028","rc":[{"batl":[[1,2.22,23.29],[2,2.38,19.2]],"ltp":2.84,"tv":297.22,"id":17467774},{"batl":[[0,6.6,20.22],[1,7.6,14.63]],"ltp":0.0,"tv":0.0,"id":16775228}]}]}
{"op":"mcm","clk":"1003911996","pt":1580652536611,"mc":[{"id":"1.168224028","rc":[{"batb":[[0,5.1,43.28]],"ltp":0.0,"tv":0.0,"id":16775230}]}]}
{"op":"mcm","clk":"1003916942","pt":1580652555853,"mc":[{"id":"1.168224028","rc":[{"batb":[[0,4.9,14.71]],"ltp":0.0,"tv":0.0,"id":17467775},{"batb":[[0,2.12,23.45],[1,2,27.77],[2,1.96,43.69]],"ltp":2.84,"tv":297.22,"id":17467774},{"batb":[[1,5.7,10.46],[2,4.9,14.71]],"ltp":0.0,"tv":0.0,"id":16775228},{"batb":[[0,5.1,23.3]],"ltp":0.0,"tv":0.0,"id":16775230}]}]}
{"op":"mcm","clk":"1003917688","pt":1580652558672,"mc":[{"id":"1.168224028","rc":[{"batb":[[1,4.8,55.17],[2,4.7,47.47]],"ltp":0.0,"tv":0.0,"id":17467775},{"batb":[[1,2.04,49.73],[2,2.02,64.77]],"ltp":2.84,"tv":297.22,"id":17467774},{"batb":[[2,5.1,43.62]],"ltp":0.0,"tv":0.0,"id":16775228},{"batb":[[1,5,42.33],[2,4.9,33.52]],"ltp":0.0,"tv":0.0,"id":16775230}]}]}
{"op":"mcm","clk":"1003918859","pt":1580652563382,"mc":[{"id":"1.168224028","rc":[{"batl":[[0,5.7,21.7],[1,5.7,0]],"ltp":0.0,"tv":0.0,"id":17467775},{"batb":[[0,2.04,49.73],[1,2.02,64.77],[2,2,27.77]],"batl":[[1,2.38,19.2],[2,2.38,0]],"ltp":2.84,"tv":297.22,"id":17467774},{"batb":[[1,5.1,43.62],[2,5,31.96]],"batl":[[0,7.6,14.63],[1,7.8,5.88],[2,7.8,0]],"ltp":0.0,"tv":0.0,"id":16775228}]}]}
{"op":"mcm","clk":"1003919109","pt":1580652564480,"mc":[{"id":"1.168224028","rc":[{"batb":[[2,4.7,36.55]],"batl":[[0,5.7,13.3]],"ltp":0.0,"tv":0.0,"id":17467775},{"batl":[[0,2.38,19.2],[1,2.38,0]],"ltp":2.84,"tv":297.22,"id":17467774},{"batb":[[0,5.1,43.62],[1,5,31.96],[2,4.9,14.71]],"batl":[[1,7.8,0]],"ltp":0.0,"tv":0.0,"id":16775228},{"batb":[[0,5.1,13.22]],"batl":[[1,6.2,0]],"ltp":0.0,"tv":0.0,"id":16775230}]}]}
{"op":"mcm","clk":"1003919566","pt":1580652566460,"mc":[{"id":"1.168224028","rc":[{"batb":[[2,1.99,28.88]],"batl":[[0,2.36,19.67]],"ltp":2.84,"tv":297.22,"id":17467774},{"batb":[[1,5,46.12],[2,1.01,0.51]],"batl":[[0,7.8,14.08]],"ltp":0.0,"tv":0.0,"id":16775228}]}]}
{"op":"mcm","clk":"1003922769","pt":1580652579326,"mc":[{"id":"1.168224028","rc":[{"batb":[[0,1.99,28.88],[1,1.01,0.51],[2,1.99,0]],"ltp":2.84,"tv":297.22,"id":17467774}]}]}
{"op":"mcm","clk":"1003923729","pt":1580652583041,"mc":[{"id":"1.168224028","rc":[{"batb":[[1,4.8,70.75]],"batl":[[0,5.5,14.24],[1,5.6,13.93],[2,5.7,13.3]],"ltp":0.0,"tv":0.0,"id":17467775},{"batb":[[0,2.3,51.65],[1,2.28,45.55],[2,2.24,20.14]],"batl":[[1,2.56,15.89]],"ltp":2.84,"tv":297.22,"id":17467774},{"batb":[[2,4.3,19.51]],"batl":[[0,5.6,13.53],[1,6.6,19.43],[2,7.8,14.08]],"ltp":0.0,"tv":0.0,"id":16775228},{"batl":[[0,5.8,12.51],[1,5.9,12.2]],"ltp":0.0,"tv":0.0,"id":16775230}]}]}
{"op":"mcm","clk":"1003923905","pt":1580652583658,"mc":[{"id":"1.168224028","rc":[{"batb":[[0,4.8,70.75],[1,4.7,47.47],[2,1.01,0.51]],"batl":[[1,5.6,22.33],[2,5.7,0]],"ltp":0.0,"tv":0.0,"id":17467775},{"batl":[[0,2.36,49.92]],"ltp":2.84,"tv":297.22,"id":17467774},{"batb":[[0,5.2,9.24],[1,5.1,43.62],[2,5,46.12]],"batl":[[1,6.4,7.56],[2,6.6,19.43]],"ltp":0.0,"tv":0.0,"id":16775228},{"batb":[[1,5,52.41]],"batl":[[1,6,8.4]],"ltp":0.0,"tv":0.0,"id":16775230}]}]}
{"op":"mcm","clk":"1003927564","pt":1580652598107,"mc":[{"id":"1.168224028","rc":[{"batb":[[0,4.8,42.44]],"ltp":0.0,"tv":0.0,"id":17467775},{"batb":[[0,2.24,20.14],[1,2.1,61.96],[2,1.01,0.51]],"ltp":2.84,"tv":297.22,"id":17467774},{"batb":[[1,5,14.16],[2,4.3,19.51]],"ltp":0.0,"tv":0.0,"id":16775228}]}]}
{"op":"mcm","clk":"1003927750","pt":1580652598838,"mc":[{"id":"1.168224028","rc":[{"batb":[[1,4.7,36.55]],"batl":[[0,5.6,13.93],[1,5.6,0]],"ltp":0.0,"tv":0.0,"id":17467775},{"batb":[[0,2.1,24.16],[1,1.01,0.51],[2,1.01,0]],"batl":[[0,2.56,15.89],[1,2.56,0]],"ltp":2.84,"tv":297.22,"id":17467774},{"batb":[[0,4.3,19.51],[1,1.01,0.51],[2,4.3,0]],"batl":[[0,6.6,19.43],[1,6.4,0],[2,6.6,0]],"ltp":0.0,"tv":0.0,"id":16775228},{"batb":[[1,5,42.33]],"batl":[[1,6,0]],"ltp":0.0,"tv":0.0,"id":16775230}]}]}
{"op":"mcm","clk":"1003928531","pt":1580652602109,"mc":[{"id":"1.168224028","rc":[{"batb":[[0,2.16,61.41],[1,2.14,54.57],[2,2.12,23.84]],"batl":[[0,2.58,15.74]],"ltp":2.84,"tv":297.22,"id":17467774},{"batb":[[0,4.3,63.4],[1,4.2,47.8],[2,1.01,0.51]],"ltp":0.0,"tv":0.0,"id":16775228}]}]}
{"op":"mcm","clk":"1003929548","pt":1580652606107,"mc":[{"id":"1.168224028","rc":[{"batb":[[0,2.12,23.84],[1,1.01,0.51],[2,2.12,0]],"ltp":2.84,"tv":297.22,"id":17467774},{"batb":[[0,4.3,19.51],[1,1.01,0.51],[2,1.01,0]],"ltp":0.0,"tv":0.0,"id":16775228}]}]}
{"op":"mcm","clk":"1003930459","pt":1580652609926,"mc":[{"id":"1.168224028","rc":[{"batb":[[0,4.8,26.86],[1,4.7,52.6],[2,4.6,10.92]],"batl":[[0,5.4,15.03],[1,5.5,23.72]],"ltp":0.0,"tv":0.0,"id":17467775},{"batb":[[0,2.52,70.86],[1,2.48,71.5],[2,2.44,16.05]],"batl":[[0,2.58,41.78],[1,2.8,12.59]],"ltp":2.84,"tv":297.22,"id":17467774},{"batb":[[0,4.5,11.76],[1,4.3,63.4],[2,4.2,47.8]],"batl":[[0,4.9,18.65],[1,5.4,9.24],[2,5.5,14.4]],"ltp":0.0,"tv":0.0,"id":16775228},{"batb":[[2,4.9,43.6]],"batl":[[1,5.9,8.4]],"ltp":0.0,"tv":0.0,"id":16775230}]}]}
{"op":"mcm","clk":"1003935714","pt":1580652630542,"mc":[{"id":"1.168224028","rc":[{"batb":[[0,4.7,52.6],[1,1.01,0.51],[2,4.6,0]],"batl":[[0,5.5,14.48],[1,5.5,0]],"ltp":0.0,"tv":0.0,"id":17467775},{"batb":[[0,2.28,19.2],[1,1.01,0.51],[2,2.44,0]],"batl":[[0,2.8,12.59],[1,2.8,0]],"ltp":2.84,"tv":297.22,"id":17467774},{"batb":[[0,3.85,13.06],[1,1.01,0.51],[2,4.2,0]],"batl":[[0,5.5,14.4],[1,5.4,0],[2,5.5,0]],"ltp":0.0,"tv":0.0,"id":16775228},{"batb":[[2,4.9,33.52]],"batl":[[1,5.9,0]],"ltp":0.0,"tv":0.0,"id":16775230}]}]}
{"op":"mcm","clk":"1003936390","pt":1580652633193,"mc":[{"id":"1.168224028","rc":[{"batb":[[1,4.6,38.65],[2,1.01,0.51]],"ltp":0.0,"tv":0.0,"id":17467775},{"batb":[[0,2.36,58.25],[1,2.32,85.95],[2,2.28,19.2]],"ltp":2.84,"tv":297.22,"id":17467774},{"batb":[[1,3.7,42.93],[2,3.65,33.74]],"ltp":0.0,"tv":0.0,"id":16775228}]}]}
{"op":"mcm","clk":"1003936789","pt":1580652634877,"mc":[{"id":"1.168224028","rc":[{"batb":[[1,1.01,0.51],[2,1.01,0]],"ltp":0.0,"tv":0.0,"id":17467775},{"batb":[[1,1.01,0.51],[2,3.65,0]],"ltp":0.0,"tv":0.0,"id":16775228}]}]}
{"op":"mcm","clk":"1003937518","pt":1580652637791,"mc":[{"id":"1.168224028","rc":[{"batb":[[0,4.8,43.12],[1,4.7,52.6],[2,1.01,0.51]],"ltp":0.0,"tv":0.0,"id":17467775},{"batb":[[0,4.9,24.46],[1,4.8,35.44],[2,3.85,13.06]],"ltp":0.0,"tv":0.0,"id":16775228}]}]}
{"op":"mcm","clk":"1003937769","pt":1580652638721,"mc":[{"id":"1.168224028","rc":[{"batb":[[0,4.8,58.31]],"batl":[[0,5.5,14.16]],"ltp":0.0,"tv":0.0,"id":17467775},{"batl":[[0,2.42,18.73],[1,2.66,14.4]],"ltp":2.84,"tv":297.22,"id":17467774},{"batb":[[1,4.8,50.55],[2,4.1,21.95]],"batl":[[1,6.4,20.3]],"ltp":0.0,"tv":0.0,"id":16775228}]}]}
{"op":"mcm","clk":"1003938128","pt":1580652639995,"mc":[{"id":"1.168224028","rc":[{"batb":[[2,4.6,10.92]],"batl":[[1,5.6,8.4]],"ltp":0.0,"tv":0.0,"id":17467775},{"batl":[[1,2.44,28.57],[2,2.66,14.4]],"ltp":2.84,"tv":297.22,"id":17467774},{"batb":[[0,4.9,34.54]],"batl":[[1,6,8.4],[2,6.4,20.3]],"ltp":0.0,"tv":0.0,"id":16775228},{"batb":[[2,4.9,43.6]],"batl":[[1,6,8.4]],"ltp":0.0,"tv":0.0,"id":16775230}]}]}
{"op":"mcm","clk":"1003941787","pt":1580652653761,"mc":[{"id":"1.168224028","rc":[{"batb":[[0,4.7,52.6],[1,4.6,10.92],[2,1.01,0.51]],"ltp":0.0,"tv":0.0,"id":17467775},{"batb":[[0,2.18,35.29],[1,2.12,23.53],[2,1.01,0.51]],"batl":[[0,2.44,28.57],[1,2.66,14.4],[2,2.66,0]],"ltp":2.84,"tv":297.22,"id":17467774},{"batb":[[0,4.9,10.08],[1,4.1,21.95],[2,1.01,0.51]],"batl":[[0,6,8.4],[1,6.4,20.3],[2,6.4,0]],"ltp":0.0,"tv":0.0,"id":16775228}]}]}
{"op":"mcm","clk":"1003941993","pt":1580652654549,"mc":[{"id":"1.168224028","rc":[{"batb":[[1,1.01,0.51],[2,1.01,0]],"batl":[[1,5.6,0]],"ltp":0.0,"tv":0.0,"id":17467775},{"batb":[[0,2.12,23.53],[1,1.01,0.51],[2,1.01,0]],"batl":[[0,2.66,14.4],[1,2.66,0]],"ltp":2.84,"tv":297.22,"id":17467774},{"batb":[[0,4.1,21.95],[1,1.01,0.51],[2,1.01,0]],"batl":[[0,6.4,20.3],[1,6.4,0]],"ltp":0.0,"tv":0.0,"id":16775228},{"batb":[[2,4.9,33.52]],"batl":[[1,6,0]],"ltp":0.0,"tv":0.0,"id":16775230}]}]}
{"op":"mcm","clk":"1003942502","pt":1580652656430,"mc":[{"id":"1.168224028","rc":[{"batb":[[0,4.7,63.36],[1,4.6,38.5],[2,1.01,0.51]],"ltp":0.0,"tv":0.0,"id":17467775},{"batb":[[0,2.18,89.38],[1,2.16,53.06],[2,2.12,23.53]],"ltp":2.84,"tv":297.22,"id":17467774},{"batb":[[1,4,34.54],[2,3.95,28.03]],"ltp":0.0,"tv":0.0,"id":16775228}]}]}
{"op":"mcm","clk":"1003942814","pt":1580652657533,"mc":[{"id":"1.168224028","rc":[{"batb":[[0,4.7,52.87],[1,1.01,0.51],[2,1.01,0]],"ltp":0.0,"tv":0.0,"id":17467775},{"batb":[[0,2.12,23.53],[1,1.01,0.51],[2,2.12,0]],"ltp":2.84,"tv":297.22,"id":17467774},{"batb":[[1,1.01,0.51],[2,3.95,0]],"ltp":0.0,"tv":0.0,"id":16775228}]}]}
{"op":"mcm","clk":"1003943755","pt":1580652661070,"mc":[{"id":"1.168224028","rc":[{"batb":[[0,4.8,36.46],[1,4.7,52.87],[2,1.01,0.51]],"ltp":0.0,"tv":0.0,"id":17467775},{"batb":[[0,2.42,47.95],[1,2.38,80.14],[2,2.12,23.53]],"ltp":2.84,"tv":297.22,"id":17467774},{"batb":[[0,4.7,22.11],[1,4.6,39.08],[2,4.1,21.95]],"ltp":0.0,"tv":0.0,"id":16775228}]}]}
{"op":"mcm","clk":"1003943789","pt":1580652661135,"mc":[{"id":"1.168224028","rc":[{"batb":[[0,4.7,52.87],[1,1.01,0.51],[2,1.01,0]],"ltp":0.0,"tv":0.0,"id":17467775},{"batb":[[0,2.12,23.53],[1,1.01,0.51],[2,2.12,0]],"ltp":2.84,"tv":297.22,"id":17467774},{"batb":[[0,4.1,21.95],[1,1.01,0.51],[2,4.1,0]],"ltp":0.0,"tv":0.0,"id":16775228}]}]}
{"op":"mcm","clk":"1003944875","pt":1580652664973,"mc":[{"id":"1.168224028","rc":[{"batb":[[0,4.7,63.36],[1,4.6,38.5],[2,1.01,0.51]],"ltp":0.0,"tv":0.0,"id":17467775},{"batb":[[0,2.18,89.38],[1,2.16,53.06],[2,2.12,23.53]],"ltp":2.84,"tv":297.22,"id":17467774},{"batb":[[1,4,34.54],[2,3.95,28.03]],"ltp":0.0,"tv":0.0,"id":16775228}]}]}
{"op":"mcm","clk":"1003944922","pt":1580652665148,"mc":[{"id":"1.168224028","rc":[{"batb":[[0,2.12,23.53],[1,1.01,0.51],[2,2.12,0]],"ltp":2.84,"tv":297.22,"id":17467774}]}]}
{"op":"mcm","clk":"1003945438","pt":1580652666851,"mc":[{"id":"1.168224028","rc":[{"trd":[[2.66,28.8]],"batb":[[0,2.66,47.76],[1,2.62,61.78],[2,2.12,23.53]],"ltp":2.66,"tv":326.02,"id":17467774}],"tv":326.02}]}
{"op":"mcm","clk":"1003945596","pt":1580652667464,"mc":[{"id":"1.168224028","rc":[{"batb":[[1,4.6,55.02],[2,4.5,11.76]],"batl":[[0,5.3,15.26],[1,5.4,23.88]],"ltp":0.0,"tv":0.0,"id":17467775},{"batb":[[2,2.52,14.63]],"batl":[[0,2.72,24.37],[1,2.92,11.49]],"ltp":2.66,"tv":326.02,"id":17467774},{"batb":[[0,4.1,35.4]],"batl":[[0,4.6,20.85],[1,5,10.08],[2,5.2,15.97]],"ltp":0.0,"tv":0.0,"id":16775228},{"batb":[[0,5,55.94],[1,4.9,43.6],[2,1.01,0.51]],"batl":[[1,5.9,8.4]],"ltp":0.0,"tv":0.0,"id":16775230}]}]}
{"op":"mcm","clk":"1003949482","pt":1580652681400,"mc":[{"id":"1.168224028","rc":[{"batb":[[0,4.6,55.02],[1,4.5,11.76],[2,1.01,0.51]],"batl":[[0,5.4,23.88],[1,5.4,0]],"ltp":0.0,"tv":0.0,"id":17467775},{"batb":[[0,2.4,29.41],[1,2.34,17.94],[2,1.01,0.51]],"ltp":2.66,"tv":326.02,"id":17467774},{"batb":[[0,4.1,13.44],[1,3.7,14.16],[2,1.01,0.51]],"batl":[[0,5,10.08],[1,5.2,15.97],[2,5.2,0]],"ltp":0.0,"tv":0.0,"id":16775228}]}]}
{"op":"mcm","clk":"1003949824","pt":1580652682574,"mc":[{"id":"1.168224028","rc":[{"batb":[[1,1.01,0.51],[2,1.01,0]],"batl":[[0,5.4,14.63]],"ltp":0.0,"tv":0.0,"id":17467775},{"batb":[[0,2.34,17.94],[1,1.01,0.51],[2,1.01,0]],"batl":[[0,2.92,11.49],[1,2.92,0]],"ltp":2.66,"tv":326.02,"id":17467774},{"batb":[[0,3.7,14.16],[1,1.01,0.51],[2,1.01,0]],"batl":[[0,5.2,15.97],[1,5.2,0]],"ltp":0.0,"tv":0.0,"id":16775228},{"batb":[[1,4.9,33.52]],"batl":[[1,5.9,0]],"ltp":0.0,"tv":0.0,"id":16775230}]}]}
{"op":"mcm","clk":"1003950367","pt":1580652684666,"mc":[{"id":"1.168224028","rc":[{"batb":[[0,4.6,56.24],[1,4.5,40.3],[2,1.01,0.51]],"ltp":0.0,"tv":0.0,"id":17467775},{"batb":[[0,2.46,51.33],[1,2.42,76.47],[2,2.36,17.23]],"batl":[[0,2.96,11.02]],"ltp":2.66,"tv":326.02,"id":17467774},{"batb":[[0,3.65,14.63],[1,3.45,30.75],[2,3.4,40.23]],"batl":[[0,5.1,16.52]],"ltp":0.0,"tv":0.0,"id":16775228},{"batl":[[0,5.7,13.22]],"ltp":0.0,"tv":0.0,"id":16775230}]}]}
{"op":"mcm","clk":"1003951187","pt":1580652687801,"mc":[{"id":"1.168224028","rc":[{"batb":[[0,1.01,0.51],[1,4.5,0],[2,1.01,0]],"ltp":0.0,"tv":0.0,"id":17467775},{"batb":[[1,1.01,0.51],[2,3.4,0]],"ltp":0.0,"tv":0.0,"id":16775228}]}]}
{"op":"mcm","clk":"1003951957","pt":1580652690794,"mc":[{"id":"1.168224028","rc":[{"batb":[[0,4.8,26.41],[1,4.7,36.93],[2,1.01,0.51]],"ltp":0.0,"tv":0.0,"id":17467775},{"batb":[[0,4.5,48.78],[1,4.4,42.92],[2,3.65,14.63]],"ltp":0.0,"tv":0.0,"id":16775228}]}]}
{"op":"mcm","clk":"1003952154","pt":1580652691524,"mc":[{"id":"1.168224028","rc":[{"batb":[[0,4.8,41.67],[1,4.7,53.22],[2,4.5,11.76]],"batl":[[1,5.5,9.24],[2,5.6,13.93]],"ltp":0.0,"tv":0.0,"id":17467775},{"batl":[[0,2.5,16.84],[1,2.58,26.05],[2,2.86,11.96]],"ltp":2.66,"tv":326.02,"id":17467774},{"batb":[[0,4.6,28.23],[1,4.5,48.78],[2,4.4,42.92]],"batl":[[1,5.5,9.24],[2,6.4,10.62]],"ltp":0.0,"tv":0.0,"id":16775228},{"batb":[[1,4.9,43.6]],"batl":[[1,5.9,8.4]],"ltp":0.0,"tv":0.0,"id":16775230}]}]}
{"op":"mcm","clk":"1003955099","pt":1580652703005,"mc":[{"id":"1.168224028","rc":[{"batb":[[0,4.7,16.29],[1,4.5,11.76],[2,1.01,0.51]],"batl":[[0,5.5,9.24],[1,5.6,13.93],[2,5.6,0]],"ltp":0.0,"tv":0.0,"id":17467775},{"batb":[[0,2.28,32.77],[1,2.16,22.5],[2,1.01,0.51]],"batl":[[0,2.58,26.05],[1,2.86,11.96],[2,2.86,0]],"ltp":2.66,"tv":326.02,"id":17467774},{"batb":[[0,4.6,10.92],[1,3.8,13.38],[2,1.01,0.51]],"batl":[[0,5.5,9.24],[1,6.4,10.62],[2,6.4,0]],"ltp":0.0,"tv":0.0,"id":16775228}]}]}
{"op":"mcm","clk":"1003955514","pt":1580652704628,"mc":[{"id":"1.168224028","rc":[{"batb":[[1,1.01,0.51],[2,1.01,0]],"batl":[[0,5.6,13.93],[1,5.6,0]],"ltp":0.0,"tv":0.0,"id":17467775},{"batb":[[0,2.16,22.5],[1,1.01,0.51],[2,1.01,0]],"batl":[[0,2.86,11.96],[1,2.86,0]],"ltp":2.66,"tv":326.02,"id":17467774},{"batb":[[0,3.8,13.38],[1,1.01,0.51],[2,1.01,0]],"batl":[[0,6.4,10.62],[1,6.4,0]],"ltp":0.0,"tv":0.0,"id":16775228},{"batb":[[1,4.9,33.52]],"batl":[[1,5.9,0]],"ltp":0.0,"tv":0.0,"id":16775230}]}]}
{"op":"mcm","clk":"1003955775","pt":1580652705642,"mc":[{"id":"1.168224028","rc":[{"batb":[[1,4.6,50.99],[2,4.5,40.38]],"ltp":0.0,"tv":0.0,"id":17467775},{"batb":[[0,2.2,67.86],[1,2.18,51.66],[2,2.16,22.5]],"ltp":2.66,"tv":326.02,"id":17467774},{"batb":[[1,3.5,48.15],[2,3.45,38.68]],"ltp":0.0,"tv":0.0,"id":16775228}]}]}
{"op":"mcm","clk":"1003956288","pt":1580652707532,"mc":[{"id":"1.168224028","rc":[{"batb":[[1,4.6,38.35],[2,1.01,0.51]],"ltp":0.0,"tv":0.0,"id":17467775},{"batb":[[0,2.16,22.5],[1,1.01,0.51],[2,2.16,0]],"ltp":2.66,"tv":326.02,"id":17467774},{"batb":[[1,1.01,0.51],[2,3.45,0]],"ltp":0.0,"tv":0.0,"id":16775228}]}]}
{"op":"mcm","clk":"1003957140","pt":1580652710946,"mc":[{"id":"1.168224028","rc":[{"batb":[[0,4.7,69.73]],"ltp":0.0,"tv":0.0,"id":17467775},{"batb":[[0,2.54,60.76],[1,2.5,69.96],[2,2.16,22.5]],"ltp":2.66,"tv":326.02,"id":17467774},{"batb":[[0,4.3,27.58],[1,4.2,48.18],[2,3.8,13.38]],"ltp":0.0,"tv":0.0,"id":16775228}]}]}
{"op":"mcm","clk":"1003957541","pt":1580652712548,"mc":[{"id":"1.168224028","rc":[{"batb":[[0,4.7,16.29]],"ltp":0.0,"tv":0.0,"id":17467775},{"batb":[[0,2.16,22.5],[1,1.01,0.51],[2,2.16,0]],"ltp":2.66,"tv":326.02,"id":17467774},{"batb":[[0,3.8,13.38],[1,1.01,0.51],[2,3.8,0]],"ltp":0.0,"tv":0.0,"id":16775228}]}]}
{"op":"mcm","clk":"1003958591","pt":1580652716738,"mc":[{"id":"1.168224028","rc":[{"batb":[[1,4.6,50.99],[2,4.5,40.38]],"ltp":0.0,"tv":0.0,"id":17467775},{"batb":[[0,2.2,67.82],[1,2.18,51.66],[2,2.16,22.5]],"ltp":2.66,"tv":326.02,"id":17467774},{"batb":[[1,3.5,48.19],[2,3.45,38.68]],"ltp":0.0,"tv":0.0,"id":16775228}]}]}
{"op":"mcm","clk":"1003959963","pt":1580652721870,"mc":[{"id":"1.168224028","rc":[{"batb":[[1,1.01,0.51],[2,4.5,0]],"ltp":0.0,"tv":0.0,"id":17467775},{"batb":[[1,1.01,0.51],[2,3.45,0]],"ltp":0.0,"tv":0.0,"id":16775228}]}]}
{"op":"mcm","clk":"1003960678","pt":1580652724667,"mc":[{"id":"1.168224028","rc":[{"batb":[[0,4.9,26.42],[1,4.8,35.2],[2,4.7,16.29]],"ltp":0.0,"tv":0.0,"id":17467775},{"batb":[[0,5.7,22.44],[1,5.6,25.14],[2,3.8,13.38]],"ltp":0.0,"tv":0.0,"id":16775228}]}]}
{"op":"mcm","clk":"1003960896","pt":1580652725554,"mc":[{"id":"1.168224028","rc":[{"batb":[[0,4.9,40.98],[1,4.8,50.62],[2,4.7,10.92]],"batl":[[1,5.7,21.62]],"ltp":0.0,"tv":0.0,"id":17467775},{"batl":[[0,2.28,21.95],[1,2.34,31.09],[2,2.52,16.68]],"ltp":2.66,"tv":326.02,"id":17467774},{"batb":[[2,5.5,20.26]],"batl":[[1,6.8,6.72],[2,7.8,13.61]],"ltp":0.0,"tv":0.0,"id":16775228},{"batb":[[2,4.8,10.92]],"batl":[[1,5.8,8.4]],"ltp":0.0,"tv":0.0,"id":16775230}]}]}
{"op":"mcm","clk":"1003965410","pt":1580652744042,"mc":[{"id":"1.168224028","rc":[{"batb":[[0,4.8,41.76],[1,4.7,10.92],[2,1.01,0.51]],"batl":[[0,5.7,21.62],[1,5.7,0]],"ltp":0.0,"tv":0.0,"id":17467775},{"batb":[[0,2.08,38.65],[1,2,28.33],[2,1.01,0.51]],"batl":[[0,2.34,31.09],[1,2.52,16.68],[2,2.52,0]],"ltp":2.66,"tv":326.02,"id":17467774},{"batb":[[0,5.5,9.24],[1,4.5,17.39],[2,1.01,0.51]],"batl":[[0,6.8,6.72],[1,7.8,13.61],[2,7.8,0]],"ltp":0.0,"tv":0.0,"id":16775228}]}]}
{"op":"mcm","clk":"1003965531","pt":1580652744610,"mc":[{"id":"1.168224028","rc":[{"batb":[[1,1.01,0.51],[2,1.01,0]],"batl":[[0,5.7,13.22]],"ltp":0.0,"tv":0.0,"id":17467775},{"batb":[[0,2,28.33],[1,1.01,0.51],[2,1.01,0]],"batl":[[0,2.52,16.68],[1,2.52,0]],"ltp":2.66,"tv":326.02,"id":17467774},{"batb":[[0,4.5,17.39],[1,1.01,0.51],[2,1.01,0]],"batl":[[0,7.8,13.61],[1,7.8,0]],"ltp":0.0,"tv":0.0,"id":16775228},{"batb":[[2,1.01,0.51]],"batl":[[1,5.8,0]],"ltp":0.0,"tv":0.0,"id":16775230}]}]}
{"op":"mcm","clk":"1003966116","pt":1580652746930,"mc":[{"id":"1.168224028","rc":[{"batb":[[1,4.7,36.93],[2,1.01,0.51]],"ltp":0.0,"tv":0.0,"id":17467775},{"batb":[[0,2.04,95.17],[1,2.02,64.67],[2,2,28.33]],"ltp":2.66,"tv":326.02,"id":17467774},{"batb":[[1,4.4,66.15],[2,4.3,44.98]],"ltp":0.0,"tv":0.0,"id":16775228}]}]}
{"op":"mcm","clk":"1003968589","pt":1580652756977,"mc":[{"id":"1.168224028","rc":[{"batb":[[1,1.01,0.51],[2,1.01,0]],"ltp":0.0,"tv":0.0,"id":17467775},{"batb":[[0,2,28.33],[1,1.01,0.51],[2,2,0]],"ltp":2.66,"tv":326.02,"id":17467774},{"batb":[[1,1.01,0.51],[2,4.3,0]],"ltp":0.0,"tv":0.0,"id":16775228}]}]}
{"op":"mcm","clk":"1003969305","pt":1580652760105,"mc":[{"id":"1.168224028","rc":[{"batb":[[0,5,13.77],[1,4.9,64.94],[2,4.8,61.15]],"batl":[[1,5.8,20.99]],"ltp":0.0,"tv":0.0,"id":17467775},{"batb":[[0,2.04,95.17],[1,2.02,64.67],[2,2,28.33]],"batl":[[0,2.1,27.54],[1,2.18,35.29],[2,2.28,21.72]],"ltp":2.66,"tv":326.02,"id":17467774},{"batb":[[0,6.8,46.31],[1,6.6,48.32],[2,6.4,7.56]],"batl":[[1,8.2,5.04],[2,9.8,8.73]],"ltp":0.0,"tv":0.0,"id":16775228},{"batb":[[0,5.1,13.69],[1,5,55.94],[2,4.9,33.52]],"batl":[[1,5.8,8.4]],"ltp":0.0,"tv":0.0,"id":16775230}]}]}
{"op":"mcm","clk":"1003969399","pt":1580652760420,"mc":[{"id":"1.168224028","rc":[{"batb":[[2,4.8,45.73]],"ltp":0.0,"tv":0.0,"id":17467775}]}]}
{"op":"mcm","clk":"1003971000","pt":1580652767114,"mc":[{"id":"1.168224028","rc":[{"batb":[[1,4.9,39.45]],"ltp":0.0,"tv":0.0,"id":17467775},{"batb":[[0,2,28.33],[1,1.97,42.85],[2,1.89,16.84]],"ltp":2.66,"tv":326.02,"id":17467774},{"batb":[[0,6.6,14.48],[1,6.4,7.56],[2,5.5,11.33]],"ltp":0.0,"tv":0.0,"id":16775228},{"batb":[[1,5,47.59]],"ltp":0.0,"tv":0.0,"id":16775230}]}]}
{"op":"mcm","clk":"1003971081","pt":1580652767433,"mc":[{"id":"1.168224028","rc":[{"batb":[[0,4.9,39.45],[1,4.8,45.73],[2,1.01,0.51]],"batl":[[0,5.8,20.99],[1,5.8,0]],"ltp":0.0,"tv":0.0,"id":17467775},{"batb":[[0,1.97,42.85],[1,1.89,16.84],[2,1.01,0.51]],"batl":[[0,2.18,35.29],[1,2.28,21.72],[2,2.28,0]],"ltp":2.66,"tv":326.02,"id":17467774},{"batb":[[0,6.4,7.56],[1,5.5,11.33],[2,1.01,0.51]],"batl":[[0,8.2,5.04],[1,9.8,8.73],[2,9.8,0]],"ltp":0.0,"tv":0.0,"id":16775228},{"batb":[[0,5,47.59],[1,4.9,33.52],[2,4.8,10.92]],"ltp":0.0,"tv":0.0,"id":16775230}]}]}
{"op":"mcm","clk":"1003971365","pt":1580652768620,"mc":[{"id":"1.168224028","rc":[{"batb":[[1,4.8,34.81]],"batl":[[0,5.8,12.59]],"ltp":0.0,"tv":0.0,"id":17467775},{"batb":[[0,1.89,16.84],[1,1.01,0.51],[2,1.01,0]],"batl":[[0,2.28,21.72],[1,2.28,0]],"ltp":2.66,"tv":326.02,"id":17467774},{"batb":[[0,5.5,11.33],[1,1.01,0.51],[2,1.01,0]],"batl":[[0,9.8,8.73],[1,9.8,0]],"ltp":0.0,"tv":0.0,"id":16775228},{"batb":[[2,1.01,0.51]],"batl":[[1,5.8,0]],"ltp":0.0,"tv":0.0,"id":16775230}]}]}
{"op":"mcm","clk":"1003971688","pt":1580652769984,"mc":[{"id":"1.168224028","rc":[{"batb":[[0,1.95,66.37],[1,1.93,74.4],[2,1.89,16.84]],"ltp":2.66,"tv":326.02,"id":17467774},{"batb":[[0,5.6,23.58],[1,5.5,37.49],[2,1.01,0.51]],"ltp":0.0,"tv":0.0,"id":16775228}]}]}
{"op":"mcm","clk":"1003976048","pt":1580652788121,"mc":[{"id":"1.168224028","rc":[{"batb":[[1,1.01,0.51],[2,1.01,0]],"ltp":0.0,"tv":0.0,"id":17467775},{"batb":[[0,5.5,11.33],[1,1.01,0.51],[2,1.01,0]],"ltp":0.0,"tv":0.0,"id":16775228}]}]}
{"op":"mcm","clk":"1003976978","pt":1580652791930,"mc":[{"id":"1.168224028","rc":[{"batb":[[0,5.1,13.14],[1,5,46.88],[2,4.9,48.04]],"batl":[[1,5.9,20.76]],"ltp":0.0,"tv":0.0,"id":17467775},{"batl":[[0,1.97,16.6],[1,2.06,39.49],[2,2.08,28.56]],"ltp":2.66,"tv":326.02,"id":17467774},{"batb":[[0,8.2,36.87],[1,8,22.6],[2,7.6,5.88]],"batl":[[0,9.8,12.93],[1,12.5,14.24]],"ltp":0.0,"tv":0.0,"id":16775228},{"batb":[[0,5,70.78]],"batl":[[1,5.8,12.83],[2,6,8.4]],"ltp":0.0,"tv":0.0,"id":16775230}]}]}
{"op":"mcm","clk":"1003977215","pt":1580652792939,"mc":[{"id":"1.168224028","rc":[{"batb":[[2,4.9,33.48]],"ltp":0.0,"tv":0.0,"id":17467775}]}]}
{"op":"mcm","clk":"1003982723","pt":1580652814969,"mc":[{"id":"1.168224028","rc":[{"batb":[[0,5,13.77],[1,4.8,10.92],[2,1.01,0.51]],"batl":[[0,5.9,20.76],[1,5.9,0]],"ltp":0.0,"tv":0.0,"id":17467775},{"batb":[[0,1.87,47.89],[1,1.81,19.43],[2,1.01,0.51]],"batl":[[0,2.06,39.49],[1,2.08,28.56],[2,2.08,0]],"ltp":2.66,"tv":326.02,"id":17467774},{"batb":[[0,7.6,5.88],[1,7,12.51],[2,1.01,0.51]],"batl":[[0,9.8,4.2]],"ltp":0.0,"tv":0.0,"id":16775228},{"batb":[[0,5,23.69],[1,1.01,0.51],[2,1.01,0]],"batl":[[0,5.8,12.83],[1,6,8.4],[2,6,0]],"ltp":0.0,"tv":0.0,"id":16775230}]}]}
{"op":"mcm","clk":"1003983253","pt":1580652817065,"mc":[{"id":"1.168224028","rc":[{"batb":[[1,1.01,0.51],[2,1.01,0]],"batl":[[0,5.9,12.35]],"ltp":0.0,"tv":0.0,"id":17467775},{"batb":[[0,1.81,19.43],[1,1.01,0.51],[2,1.01,0]],"batl":[[0,2.08,28.56],[1,2.08,0]],"ltp":2.66,"tv":326.02,"id":17467774},{"batb":[[0,7,12.51],[1,1.01,0.51],[2,1.01,0]],"batl":[[0,12.5,14.24],[1,12.5,0]],"ltp":0.0,"tv":0.0,"id":16775228},{"batb":[[0,5,13.61]],"batl":[[1,6,0]],"ltp":0.0,"tv":0.0,"id":16775230}]}]}
{"op":"mcm","clk":"1003983600","pt":1580652818574,"mc":[{"id":"1.168224028","rc":[{"batb":[[1,4.9,50.56],[2,4.8,34.81]],"ltp":0.0,"tv":0.0,"id":17467775},{"batb":[[0,7.2,41.09],[1,7,42.37],[2,1.01,0.51]],"ltp":0.0,"tv":0.0,"id":16775228},{"batb":[[0,5,44.39],[1,4.9,33.82],[2,1.01,0.51]],"ltp":0.0,"tv":0.0,"id":16775230}]}]}
{"op":"mcm","clk":"1003984468","pt":1580652822088,"mc":[{"id":"1.168224028","rc":[{"batb":[[2,4.8,45.73]],"batl":[[0,5.7,13.14],[1,5.8,21.15],[2,5.9,12.35]],"ltp":0.0,"tv":0.0,"id":17467775},{"batb":[[0,2.02,79.03],[1,2,66.66],[2,1.98,29.27]],"batl":[[1,2.12,36.97],[2,2.18,24.86]],"ltp":2.66,"tv":326.02,"id":17467774},{"batb":[[1,7,49.09],[2,6.2,16.68]],"batl":[[0,8.4,11.88],[1,9,5.04],[2,10,8.42]],"ltp":0.0,"tv":0.0,"id":16775228},{"batb":[[1,4.9,58.46]],"batl":[[0,5.7,13.22],[1,5.8,12.83],[2,5.9,8.4]],"ltp":0.0,"tv":0.0,"id":16775230}]}]}
{"op":"mcm","clk":"1003984674","pt":1580652822888,"mc":[{"id":"1.168224028","rc":[{"batl":[[2,5.9,0]],"ltp":0.0,"tv":0.0,"id":17467775},{"batb":[[0,5,30.78]],"batl":[[1,5.9,8.4],[2,5.9,0]],"ltp":0.0,"tv":0.0,"id":16775230}]}]}
{"op":"mcm","clk":"1003986896","pt":1580652832069,"mc":[{"id":"1.168224028","rc":[{"batb":[[1,4.9,36.52]],"batl":[[0,5.8,21.15],[1,5.8,0]],"ltp":0.0,"tv":0.0,"id":17467775},{"batb":[[0,1.92,45.37],[1,1.89,16.92],[2,1.01,0.51]],"batl":[[0,2.12,36.97],[1,2.18,24.86],[2,2.18,0]],"ltp":2.66,"tv":326.02,"id":17467774},{"batb":[[0,7,6.72],[1,6.2,16.68],[2,1.01,0.51]],"batl":[[0,9,5.04],[1,10,8.42],[2,10,0]],"ltp":0.0,"tv":0.0,"id":16775228},{"batb":[[0,4.9,58.46],[1,1.01,0.51],[2,1.01,0]],"ltp":0.0,"tv":0.0,"id":16775230}]}]}
{"op":"mcm","clk":"1003987053","pt":1580652832678,"mc":[{"id":"1.168224028","rc":[{"batb":[[2,4.8,34.81]],"batl":[[0,5.8,12.75]],"ltp":0.0,"tv":0.0,"id":17467775},{"batb":[[0,1.89,16.92],[1,1.01,0.51],[2,1.01,0]],"batl":[[0,2.18,24.86],[1,2.18,0]],"ltp":2.66,"tv":326.02,"id":17467774},{"batb":[[0,6.2,16.68],[1,1.01,0.51],[2,1.01,0]],"batl":[[0,10,8.42],[1,10,0]],"ltp":0.0,"tv":0.0,"id":16775228},{"batb":[[0,4.9,48.38]],"batl":[[1,5.9,0]],"ltp":0.0,"tv":0.0,"id":16775230}]}]}
{"op":"mcm","clk":"1003987597","pt":1580652834892,"mc":[{"id":"1.168224028","rc":[{"batb":[[0,1.93,85.56],[1,1.91,76.86],[2,1.89,16.92]],"ltp":2.66,"tv":326.02,"id":17467774},{"batb":[[0,6.6,35.56],[1,6.4,36.5],[2,6.2,16.68]],"ltp":0.0,"tv":0.0,"id":16775228},{"batb":[[0,4.9,63.97],[1,4.8,35.15],[2,1.01,0.51]],"ltp":0.0,"tv":0.0,"id":16775230}]}]}
{"op":"mcm","clk":"1003987851","pt":1580652835990,"mc":[{"id":"1.168224028","rc":[{"batb":[[2,1.01,0.51]],"ltp":0.0,"tv":0.0,"id":17467775},{"batb":[[0,1.89,16.92],[1,1.01,0.51],[2,1.89,0]],"ltp":2.66,"tv":326.02,"id":17467774},{"batb":[[0,6.2,16.68],[1,1.01,0.51],[2,6.2,0]],"ltp":0.0,"tv":0.0,"id":16775228},{"batb":[[0,4.9,48.38],[1,1.01,0.51],[2,1.01,0]],"ltp":0.0,"tv":0.0,"id":16775230}]}]}
{"op":"mcm","clk":"1003988568","pt":1580652839078,"mc":[{"id":"1.168224028","rc":[{"batb":[[0,5,34.09]],"ltp":0.0,"tv":0.0,"id":17467775},{"batb":[[0,2,84.9],[1,1.98,68.74],[2,1.89,16.92]],"ltp":2.66,"tv":326.02,"id":17467774},{"batb":[[0,7.4,40.3],[1,7.2,28.09],[2,6.2,16.68]],"ltp":0.0,"tv":0.0,"id":16775228},{"batb":[[0,5,35.08],[1,4.9,48.38],[2,1.01,0.51]],"ltp":0.0,"tv":0.0,"id":16775230}]}]}
{"op":"mcm","clk":"1003988705","pt":1580652839575,"mc":[{"id":"1.168224028","rc":[{"batb":[[0,5,13.77]],"ltp":0.0,"tv":0.0,"id":17467775},{"batb":[[0,1.89,16.92],[1,1.01,0.51],[2,1.89,0]],"ltp":2.66,"tv":326.02,"id":17467774},{"batb":[[0,6.2,16.68],[1,1.01,0.51],[2,6.2,0]],"ltp":0.0,"tv":0.0,"id":16775228},{"batb":[[0,4.9,48.38],[1,1.01,0.51],[2,1.01,0]],"ltp":0.0,"tv":0.0,"id":16775230}]}]}
{"op":"mcm","clk":"1003989556","pt":1580652843051,"mc":[{"id":"1.168224028","rc":[{"batb":[[2,4.8,35.04]],"ltp":0.0,"tv":0.0,"id":17467775},{"batb":[[0,1.93,85.56],[1,1.91,76.86],[2,1.89,16.92]],"ltp":2.66,"tv":326.02,"id":17467774},{"batb":[[0,6.6,35.56],[1,6.4,36.5],[2,6.2,16.68]],"ltp":0.0,"tv":0.0,"id":16775228},{"batb":[[0,4.9,63.97],[1,4.8,35.15],[2,1.01,0.51]],"ltp":0.0,"tv":0.0,"id":16775230}]}]}
{"op":"mcm","clk":"1003991117","pt":1580652849862,"mc":[{"id":"1.168224028","rc":[{"batb":[[2,1.01,0.51]],"ltp":0.0,"tv":0.0,"id":17467775},{"batb":[[0,6.2,16.68],[1,1.01,0.51],[2,6.2,0]],"ltp":0.0,"tv":0.0,"id":16775228},{"batb":[[0,4.9,48.38],[1,1.01,0.51],[2,1.01,0]],"ltp":0.0,"tv":0.0,"id":16775230}]}]}
{"op":"mcm","clk":"1003991794","pt":1580652853006,"mc":[{"id":"1.168224028","rc":[{"batb":[[0,5,49.61]],"ltp":0.0,"tv":0.0,"id":17467775},{"batb":[[0,8.4,29.25],[1,8.2,21.4],[2,6.2,16.68]],"ltp":0.0,"tv":0.0,"id":16775228},{"batb":[[0,5,52.33],[1,4.9,48.38],[2,1.01,0.51]],"ltp":0.0,"tv":0.0,"id":16775230}]}]}
{"op":"mcm","clk":"1003992017","pt":1580652853893,"mc":[{"id":"1.168224028","rc":[{"batb":[[0,5.1,13.3],[1,5,49.61],[2,4.9,36.52]],"batl":[[0,5.8,21.15],[1,5.9,12.27]],"ltp":0.0,"tv":0.0,"id":17467775},{"batl":[[0,1.97,16.6],[1,2.04,40.33],[2,2.08,28.17]],"ltp":2.66,"tv":326.02,"id":17467774},{"batb":[[1,8.2,30.29],[2,7.8,5.88]],"batl":[[1,13,13.14]],"ltp":0.0,"tv":0.0,"id":16775228},{"batb":[[0,5,76.42],[1,4.9,33.82]],"batl":[[0,5.7,13.06],[1,6,8.4]],"ltp":0.0,"tv":0.0,"id":16775230}]}]}
{"op":"mcm","clk":"1003995400","pt":1580652869319,"mc":[{"id":"1.168224028","rc":[{"batb":[[0,5,13.77],[1,4.9,36.52],[2,4.8,10.92]],"batl":[[0,5.8,8.4]],"ltp":0.0,"tv":0.0,"id":17467775},{"batb":[[0,1.85,48.73],[1,1.8,19.75],[2,1.01,0.51]],"batl":[[0,2.04,40.33],[1,2.08,28.17],[2,2.08,0]],"ltp":2.66,"tv":326.02,"id":17467774},{"batb":[[0,7.8,5.88],[1,7,12.9],[2,1.01,0.51]],"batl":[[0,13,13.14],[1,13,0]],"ltp":0.0,"tv":0.0,"id":16775228},{"batb":[[0,5,60.85]],"ltp":0.0,"tv":0.0,"id":16775230}]}]}
{"op":"mcm","clk":"1003995722","pt":1580652870746,"mc":[{"id":"1.168224028","rc":[{"batb":[[2,1.01,0.51]],"batl":[[0,5.9,12.27],[1,5.9,0]],"ltp":0.0,"tv":0.0,"id":17467775},{"batb":[[0,1.8,19.75],[1,1.01,0.51],[2,1.01,0]],"batl":[[0,2.08,28.17],[1,2.08,0]],"ltp":2.66,"tv":326.02,"id":17467774},{"batb":[[0,7,12.9],[1,1.01,0.51],[2,1.01,0]],"ltp":0.0,"tv":0.0,"id":16775228},{"batb":[[0,5,50.77]],"batl":[[1,6,0]],"ltp":0.0,"tv":0.0,"id":16775230}]}]}
{"op":"mcm","clk":"1003996117","pt":1580652872454,"mc":[{"id":"1.168224028","rc":[{"batb":[[1,1.01,0.51],[2,1.01,0]],"ltp":0.0,"tv":0.0,"id":16775230}]}]}
{"op":"mcm","clk":"1003996879","pt":1580652875845,"mc":[{"id":"1.168224028","rc":[{"batb":[[0,5,55.01]],"ltp":0.0,"tv":0.0,"id":17467775},{"batb":[[0,1.91,81.7],[1,1.89,79.46],[2,1.8,19.75]],"ltp":2.66,"tv":326.02,"id":17467774},{"batb":[[0,8.8,24.59],[1,8.6,19.41],[2,7,12.9]],"ltp":0.0,"tv":0.0,"id":16775228},{"batb":[[0,5.1,22.91],[1,5,50.77],[2,1.01,0.51]],"ltp":0.0,"tv":0.0,"id":16775230}]}]}
{"op":"mcm","clk":"1003997603","pt":1580652879062,"mc":[{"id":"1.168224028","rc":[{"batb":[[0,5,13.77]],"ltp":0.0,"tv":0.0,"id":17467775},{"batb":[[0,1.8,19.75],[1,1.01,0.51],[2,1.8,0]],"ltp":2.66,"tv":326.02,"id":17467774},{"batb":[[0,7,12.9],[1,1.01,0.51],[2,7,0]],"ltp":0.0,"tv":0.0,"id":16775228},{"batb":[[0,5,50.77],[1,1.01,0.51],[2,1.01,0]],"ltp":0.0,"tv":0.0,"id":16775230}]}]}
{"op":"mcm","clk":"1003998245","pt":1580652881639,"mc":[{"id":"1.168224028","rc":[{"batb":[[1,4.9,51.25],[2,4.8,34.8]],"ltp":0.0,"tv":0.0,"id":17467775},{"batb":[[0,1.83,82.59],[1,1.81,91.34],[2,1.8,19.75]],"ltp":2.66,"tv":326.02,"id":17467774},{"batb":[[0,7.4,15.75],[1,7.2,28.68],[2,7,12.9]],"ltp":0.0,"tv":0.0,"id":16775228},{"batb":[[1,4.9,33.73],[2,1.01,0.51]],"ltp":0.0,"tv":0.0,"id":16775230}]}]}
{"op":"mcm","clk":"1003999447","pt":1580652887010,"mc":[{"id":"1.168224028","rc":[{"batb":[[0,1.8,19.75],[1,1.01,0.51],[2,1.8,0]],"ltp":2.66,"tv":326.02,"id":17467774}]}]}
{"op":"mcm","clk":"1004000124","pt":1580652889913,"mc":[{"id":"1.168224028","rc":[{"batb":[[1,4.9,65.73],[2,4.8,45.72]],"batl":[[0,5.7,13.38],[1,5.8,21.23],[2,5.9,12.27]],"ltp":0.0,"tv":0.0,"id":17467775},{"batb":[[0,2.02,63.18],[1,2,66.68],[2,1.98,29.03]],"batl":[[1,2.1,37.81],[2,2.2,24.08]],"ltp":2.66,"tv":326.02,"id":17467774},{"batb":[[1,7.2,35.4]],"batl":[[0,8.4,12.2],[1,9.2,5.04],[2,10,8.26]],"ltp":0.0,"tv":0.0,"id":16775228},{"batb":[[1,4.9,58.37]],"batl":[[1,6,8.4]],"ltp":0.0,"tv":0.0,"id":16775230}]}]}
{"op":"mcm","clk":"1004000182","pt":1580652890154,"mc":[{"id":"1.168224028","rc":[{"batl":[[2,5.9,0]],"ltp":0.0,"tv":0.0,"id":17467775}]}]}
{"op":"mcm","clk":"1004004063","pt":1580652907082,"mc":[{"id":"1.168224028","rc":[{"batb":[[0,4.9,51],[1,4.8,45.72],[2,1.01,0.51]],"batl":[[0,5.8,21.23],[1,5.8,0]],"ltp":0.0,"tv":0.0,"id":17467775},{"batb":[[0,1.9,46.21],[1,1.88,17],[2,1.01,0.51]],"batl":[[0,2.1,37.81],[1,2.2,24.08],[2,2.2,0]],"ltp":2.66,"tv":326.02,"id":17467774},{"batb":[[0,7.2,6.72],[1,6,17.62],[2,1.01,0.51]],"batl":[[0,9.2,5.04],[1,10,8.26],[2,10,0]],"ltp":0.0,"tv":0.0,"id":16775228},{"batb":[[0,5,20.97]],"ltp":0.0,"tv":0.0,"id":16775230}]}]}
{"op":"mcm","clk":"1004004459","pt":1580652908874,"mc":[{"id":"1.168224028","rc":[{"batb":[[1,4.8,34.8]],"batl":[[0,5.8,12.83]],"ltp":0.0,"tv":0.0,"id":17467775},{"batb":[[0,1.88,17],[1,1.01,0.51],[2,1.01,0]],"batl":[[0,2.2,24.08],[1,2.2,0]],"ltp":2.66,"tv":326.02,"id":17467774},{"batb":[[0,6,17.62],[1,1.01,0.51],[2,1.01,0]],"batl":[[0,10,8.26],[1,10,0]],"ltp":0.0,"tv":0.0,"id":16775228},{"batb":[[1,4.9,48.29]],"batl":[[1,6,0]],"ltp":0.0,"tv":0.0,"id":16775230}]}]}
{"op":"mcm","clk":"1004004754","pt":1580652910067,"mc":[{"id":"1.168224028","rc":[{"batb":[[1,1.01,0.51],[2,1.01,0]],"ltp":0.0,"tv":0.0,"id":17467775}]}]}
{"op":"mcm","clk":"1004005328","pt":1580652912648,"mc":[{"id":"1.168224028","rc":[{"batb":[[0,5,21.47],[1,4.9,51],[2,1.01,0.51]],"ltp":0.0,"tv":0.0,"id":17467775},{"batb":[[0,2,61.54],[1,1.98,68.75],[2,1.88,17]],"ltp":2.66,"tv":326.02,"id":17467774},{"batb":[[0,7.6,20.61],[1,7.4,26.93],[2,6,17.62]],"ltp":0.0,"tv":0.0,"id":16775228},{"batb":[[0,5,40.21]],"ltp":0.0,"tv":0.0,"id":16775230}]}]}
{"op":"mcm","clk":"1004005750","pt":1580652914868,"mc":[{"id":"1.168224028","rc":[{"batb":[[0,4.9,51],[1,1.01,0.51],[2,1.01,0]],"ltp":0.0,"tv":0.0,"id":17467775},{"batb":[[0,1.88,17],[1,1.01,0.51],[2,1.88,0]],"ltp":2.66,"tv":326.02,"id":17467774},{"batb":[[0,6,17.62],[1,1.01,0.51],[2,6,0]],"ltp":0.0,"tv":0.0,"id":16775228},{"batb":[[0,5,20.97]],"ltp":0.0,"tv":0.0,"id":16775230}]}]}
{"op":"mcm","clk":"1004006414","pt":1580652918072,"mc":[{"id":"1.168224028","rc":[{"batb":[[1,4.8,35.06],[2,1.01,0.51]],"ltp":0.0,"tv":0.0,"id":17467775},{"batb":[[0,1.92,69.18],[1,1.9,78.14],[2,1.88,17]],"ltp":2.66,"tv":326.02,"id":17467774},{"batb":[[0,6.6,23.74],[1,6.4,36.82],[2,6,17.62]],"ltp":0.0,"tv":0.0,"id":16775228}]}]}
{"op":"mcm","clk":"1004007530","pt":1580652923084,"mc":[{"id":"1.168224028","rc":[{"batb":[[1,1.01,0.51],[2,1.01,0]],"ltp":0.0,"tv":0.0,"id":17467775},{"batb":[[0,1.88,17],[1,1.01,0.51],[2,1.88,0]],"ltp":2.66,"tv":326.02,"id":17467774},{"batb":[[0,6,17.62],[1,1.01,0.51],[2,6,0]],"ltp":0.0,"tv":0.0,"id":16775228},{"batb":[[1,4.9,14.56]],"ltp":0.0,"tv":0.0,"id":16775230}]}]}
{"op":"mcm","clk":"1004008169","pt":1580652926094,"mc":[{"id":"1.168224028","rc":[{"batb":[[0,5,38.83],[1,4.9,51],[2,4.8,10.92]],"batl":[[0,5.8,21.23]],"ltp":0.0,"tv":0.0,"id":17467775},{"batb":[[0,1.92,69.18],[1,1.9,78.14],[2,1.88,17]],"batl":[[0,2.02,41.17],[1,2.2,24.08]],"ltp":2.66,"tv":326.02,"id":17467774},{"batb":[[0,8.8,11.71],[1,8.6,19.67],[2,6,17.62]],"batl":[[1,10.5,4.2]],"ltp":0.0,"tv":0.0,"id":16775228},{"batb":[[0,5.1,23.72],[1,5,42.49],[2,4.9,14.56]],"ltp":0.0,"tv":0.0,"id":16775230}]}]}
{"op":"mcm","clk":"1004008293","pt":1580652926689,"mc":[{"id":"1.168224028","rc":[{"batb":[[0,5.1,13.38],[1,5,52.84],[2,4.9,36.52]],"batl":[[1,5.9,12.12]],"ltp":0.0,"tv":0.0,"id":17467775},{"batl":[[0,1.96,16.76],[1,2.02,41.17],[2,2.1,27.38]],"ltp":2.66,"tv":326.02,"id":17467774},{"batb":[[2,8.4,8.66]],"batl":[[2,14,10.94]],"ltp":0.0,"tv":0.0,"id":16775228},{"batb":[[1,5,56.58],[2,1.01,0.51]],"batl":[[1,6.2,7.56]],"ltp":0.0,"tv":0.0,"id":16775230}]}]}
{"op":"mcm","clk":"1004011897","pt":1580652942850,"mc":[{"id":"1.168224028","rc":[{"batb":[[0,5,14.01],[1,4.9,36.52],[2,1.01,0.51]],"batl":[[0,5.9,12.12],[1,5.9,0]],"ltp":0.0,"tv":0.0,"id":17467775},{"batb":[[0,1.77,20.69],[1,1.01,0.51],[2,1.88,0]],"batl":[[0,2.1,27.38],[1,2.02,0],[2,2.1,0]],"ltp":2.66,"tv":326.02,"id":17467774},{"batb":[[0,6.8,13.85],[1,1.01,0.51],[2,8.4,0]],"batl":[[0,14,10.94],[1,10.5,0],[2,14,0]],"ltp":0.0,"tv":0.0,"id":16775228},{"batb":[[0,5,46.49],[1,1.01,0.51],[2,1.01,0]],"batl":[[1,6.2,0]],"ltp":0.0,"tv":0.0,"id":16775230}]}]}
{"op":"mcm","clk":"1004012548","pt":1580652946068,"mc":[{"id":"1.168224028","rc":[{"batb":[[1,4.9,47.32],[2,4.8,34.83]],"ltp":0.0,"tv":0.0,"id":17467775},{"batb":[[0,1.79,95.16],[1,1.77,119.08],[2,1.01,0.51]],"ltp":2.66,"tv":326.02,"id":17467774},{"batb":[[0,7.2,31.21],[1,7,30.19],[2,6.8,13.85]],"ltp":0.0,"tv":0.0,"id":16775228},{"batb":[[0,5,61.77],[1,4.9,33.63],[2,1.01,0.51]],"ltp":0.0,"tv":0.0,"id":16775230}]}]}
{"op":"mcm","clk":"1004016291","pt":1580652964114,"mc":[{"id":"1.168224028","rc":[{"batb":[[1,4.9,36.52],[2,1.01,0.51]],"ltp":0.0,"tv":0.0,"id":17467775},{"batb":[[0,1.77,20.69],[1,1.01,0.51],[2,1.01,0]],"ltp":2.66,"tv":326.02,"id":17467774},{"batb":[[0,6.8,13.85],[1,1.01,0.51],[2,6.8,0]],"ltp":0.0,"tv":0.0,"id":16775228},{"batb":[[0,5,46.49],[1,1.01,0.51],[2,1.01,0]],"ltp":0.0,"tv":0.0,"id":16775230}]}]}
{"op":"mcm","clk":"1004017143","pt":1580652968033,"mc":[{"id":"1.168224028","rc":[{"batb":[[1,4.9,61.95],[2,4.8,45.75]],"batl":[[0,5.7,13.06],[1,5.8,8.4]],"ltp":0.0,"tv":0.0,"id":17467775},{"batb":[[0,2.02,74.7],[1,2,94.84],[2,1.9,46.21]],"batl":[[0,2.1,65.19],[1,2.24,22.98]],"ltp":2.66,"tv":326.02,"id":17467774},{"batb":[[0,7.2,37.93],[1,7,30.19],[2,6.8,13.85]],"batl":[[0,8,13.06],[1,9.2,5.04],[2,10,8.34]],"ltp":0.0,"tv":0.0,"id":16775228},{"batb":[[0,5,71.86],[1,4.9,33.63],[2,1.01,0.51]],"batl":[[1,6,8.4]],"ltp":0.0,"tv":0.0,"id":16775230}]}]}
{"op":"mcm","clk":"1004020874","pt":1580652984840,"mc":[{"id":"1.168224028","rc":[{"batb":[[0,4.9,42.95],[1,4.8,34.83],[2,1.01,0.51]],"batl":[[1,5.8,0]],"ltp":0.0,"tv":0.0,"id":17467775},{"batb":[[0,1.89,16.76],[1,1.01,0.51],[2,1.9,0]],"batl":[[0,2.24,22.98],[1,2.24,0]],"ltp":2.66,"tv":326.02,"id":17467774},{"batb":[[0,5.8,19.75],[1,1.01,0.51],[2,6.8,0]],"batl":[[0,10,8.34],[1,9.2,0],[2,10,0]],"ltp":0.0,"tv":0.0,"id":16775228},{"batb":[[0,5,47.09]],"batl":[[1,6,0]],"ltp":0.0,"tv":0.0,"id":16775230}]}]}
{"op":"mcm","clk":"1004021318","pt":1580652987032,"mc":[{"id":"1.168224028","rc":[{"batb":[[0,1.91,71.38],[1,1.89,96.22],[2,1.01,0.51]],"ltp":2.66,"tv":326.02,"id":17467774},{"batb":[[0,6.4,28.08],[1,6.2,39.44],[2,5.8,19.75]],"ltp":0.0,"tv":0.0,"id":16775228}]}]}
{"op":"mcm","clk":"1004021495","pt":1580652987852,"mc":[{"id":"1.168224028","rc":[{"batb":[[0,1.89,16.76],[1,1.01,0.51],[2,1.01,0]],"ltp":2.66,"tv":326.02,"id":17467774},{"batb":[[0,5.8,19.75],[1,1.01,0.51],[2,5.8,0]],"ltp":0.0,"tv":0.0,"id":16775228}]}]}
{"op":"mcm","clk":"1004021845","pt":1580652989528,"mc":[{"id":"1.168224028","rc":[{"batb":[[0,4.9,67.11]],"ltp":0.0,"tv":0.0,"id":17467775},{"batb":[[0,2,63.81],[1,1.98,68.75],[2,1.89,16.76]],"ltp":2.66,"tv":326.02,"id":17467774},{"batb":[[0,7.4,39.35],[1,7.2,28.2],[2,5.8,19.75]],"ltp":0.0,"tv":0.0,"id":16775228},{"batb":[[0,5,65.72]],"ltp":0.0,"tv":0.0,"id":16775230}]}]}
{"op":"mcm","clk":"1004022319","pt":1580652991749,"mc":[{"id":"1.168224028","rc":[{"batb":[[0,4.9,42.95]],"ltp":0.0,"tv":0.0,"id":17467775},{"batb":[[0,1.89,16.76],[1,1.01,0.51],[2,1.89,0]],"ltp":2.66,"tv":326.02,"id":17467774},{"batb":[[0,5.8,19.75],[1,1.01,0.51],[2,5.8,0]],"ltp":0.0,"tv":0.0,"id":16775228},{"batb":[[0,5,47.09]],"ltp":0.0,"tv":0.0,"id":16775230}]}]}
{"op":"mcm","clk":"1004022951","pt":1580652994475,"mc":[{"id":"1.168224028","rc":[{"batb":[[0,1.91,71.38],[1,1.89,96.22],[2,1.01,0.51]],"ltp":2.66,"tv":326.02,"id":17467774},{"batb":[[0,6.4,28.08],[1,6.2,39.44],[2,5.8,19.75]],"ltp":0.0,"tv":0.0,"id":16775228}]}]}
{"op":"mcm","clk":"1004023492","pt":1580652997027,"mc":[{"id":"1.168224028","rc":[{"batb":[[0,1.89,16.76],[1,1.01,0.51],[2,1.01,0]],"ltp":2.66,"tv":326.02,"id":17467774}]}]}
{"op":"mcm","clk":"1004024082","pt":1580652999974,"mc":[{"id":"1.168224028","rc":[{"batb":[[0,2.12,47.97],[1,2.1,57.64],[2,1.89,16.76]],"ltp":2.66,"tv":326.02,"id":17467774}]}]}
{"op":"mcm","clk":"1004024318","pt":1580653001121,"mc":[{"id":"1.168224028","rc":[{"batb":[[1,4.8,50.09]],"batl":[[0,5.5,14.01],[1,5.7,13.06]],"ltp":0.0,"tv":0.0,"id":17467775},{"batb":[[0,2.12,71.57],[2,2,28.01]],"batl":[[1,2.42,18.41]],"ltp":2.66,"tv":326.02,"id":17467774},{"batl":[[0,6.8,18.33],[1,8,12.98]],"ltp":0.0,"tv":0.0,"id":16775228},{"batb":[[1,4.9,48.19]],"batl":[[0,5.6,13.53]],"ltp":0.0,"tv":0.0,"id":16775230}]}]}
{"op":"mcm","clk":"1004024529","pt":1580653002106,"mc":[{"id":"1.168224028","rc":[{"batb":[[1,4.8,61.02]],"batl":[[1,5.7,21.46]],"ltp":0.0,"tv":0.0,"id":17467775},{"batl":[[0,2.2,34.45],[1,2.24,22.98],[2,2.42,18.41]],"ltp":2.66,"tv":326.02,"id":17467774},{"batb":[[0,6.4,35.64]],"ltp":0.0,"tv":0.0,"id":16775228},{"batb":[[2,4.8,10.92]],"batl":[[1,5.8,8.4]],"ltp":0.0,"tv":0.0,"id":16775230}]}]}
{"op":"mcm","clk":"1004024950","pt":1580653004070,"mc":[{"id":"1.168224028","rc":[{"batl":[[1,8,18.86]],"ltp":0.0,"tv":0.0,"id":16775228}]}]}
{"op":"mcm","clk":"1004025988","pt":1580653008985,"mc":[{"id":"1.168224028","rc":[{"batl":[[0,5.6,13.93]],"ltp":0.0,"tv":0.0,"id":17467775},{"batb":[[0,2.12,47.97],[1,2.1,81.72],[2,1.99,28.56]],"batl":[[1,2.22,23.45],[2,2.4,18.88]],"ltp":2.66,"tv":326.02,"id":17467774},{"batb":[[2,5.9,18.88]],"batl":[[0,7,17.62],[1,8,5.88],[2,8.2,12.43]],"ltp":0.0,"tv":0.0,"id":16775228}]}]}
{"op":"mcm","clk":"1004029346","pt":1580653024986,"mc":[{"id":"1.168224028","rc":[{"batl":[[0,5.7,13.45]],"ltp":0.0,"tv":0.0,"id":16775230}]}]}
{"op":"mcm","clk":"1004033570","pt":1580653046915,"mc":[{"id":"1.168224028","rc":[{"batb":[[0,2.1,81.72],[1,1.99,28.56],[2,1.98,42.85]],"ltp":2.66,"tv":326.02,"id":17467774}]}]}
{"op":"mcm","clk":"1004034119","pt":1580653049784,"mc":[{"id":"1.168224028","rc":[{"batb":[[0,2.1,129.04],[1,2.08,59.21],[2,1.99,28.56]],"ltp":2.66,"tv":326.02,"id":17467774}]}]}
{"op":"mcm","clk":"1004041158","pt":1580653086090,"mc":[{"id":"1.168224028","rc":[{"batb":[[0,4.9,14.63]],"ltp":0.0,"tv":0.0,"id":17467775},{"batb":[[0,2.1,24.08],[1,1.99,28.56],[2,1.98,42.85]],"ltp":2.66,"tv":326.02,"id":17467774},{"batb":[[0,6.4,7.56],[1,5.9,18.88],[2,5.1,13.53]],"ltp":0.0,"tv":0.0,"id":16775228},{"batb":[[0,5,37.38]],"ltp":0.0,"tv":0.0,"id":16775230}]}]}
{"op":"mcm","clk":"1004041317","pt":1580653086884,"mc":[{"id":"1.168224028","rc":[{"batb":[[0,4.8,50.09],[1,1.01,0.51],[2,1.01,0]],"batl":[[0,5.7,13.06],[1,5.7,0]],"ltp":0.0,"tv":0.0,"id":17467775},{"batb":[[0,1.99,28.56],[1,1.01,0.51],[2,1.98,0]],"batl":[[0,2.4,18.88],[1,2.22,0],[2,2.4,0]],"ltp":2.66,"tv":326.02,"id":17467774},{"batb":[[0,5.1,13.53],[1,1.01,0.51],[2,5.1,0]],"batl":[[0,8.2,12.43],[1,8,0],[2,8.2,0]],"ltp":0.0,"tv":0.0,"id":16775228},{"batb":[[0,5,23.3],[2,1.01,0.51]],"batl":[[1,5.8,0]],"ltp":0.0,"tv":0.0,"id":16775230}]}]}
{"op":"mcm","clk":"1004041767","pt":1580653089050,"mc":[{"id":"1.168224028","rc":[{"batb":[[1,4.7,36.72],[2,1.01,0.51]],"ltp":0.0,"tv":0.0,"id":17467775},{"batb":[[0,2,111.53],[1,1.99,28.56],[2,1.98,68.69]],"ltp":2.66,"tv":326.02,"id":17467774},{"batb":[[0,5.3,25.57],[1,5.2,29.74],[2,5.1,13.53]],"ltp":0.0,"tv":0.0,"id":16775228}]}]}
{"op":"mcm","clk":"1004045938","pt":1580653110908,"mc":[{"id":"1.168224028","rc":[{"batb":[[1,1.01,0.51],[2,1.01,0]],"ltp":0.0,"tv":0.0,"id":17467775},{"batb":[[0,5.1,13.53],[1,1.01,0.51],[2,5.1,0]],"ltp":0.0,"tv":0.0,"id":16775228}]}]}
{"op":"mcm","clk":"1004046524","pt":1580653114092,"mc":[{"id":"1.168224028","rc":[{"batb":[[0,4.9,44.46],[1,4.8,50.09],[2,1.01,0.51]],"ltp":0.0,"tv":0.0,"id":17467775},{"batb":[[0,7.4,30.21],[1,7.2,28.41],[2,5.1,13.53]],"ltp":0.0,"tv":0.0,"id":16775228},{"batb":[[0,5,39.33]],"ltp":0.0,"tv":0.0,"id":16775230}]}]}
{"op":"mcm","clk":"1004046724","pt":1580653115118,"mc":[{"id":"1.168224028","rc":[{"batb":[[0,5,13.85],[1,4.9,59.17],[2,4.8,34.83]],"ltp":0.0,"tv":0.0,"id":17467775},{"batl":[[0,2.1,27.77],[1,2.24,22.74]],"ltp":2.66,"tv":326.02,"id":17467774},{"batb":[[2,7,13.14]],"batl":[[1,9.8,8.73]],"ltp":0.0,"tv":0.0,"id":16775228}]}]}
{"op":"mcm","clk":"1004046837","pt":1580653115812,"mc":[{"id":"1.168224028","rc":[{"batb":[[2,4.8,45.75]],"batl":[[1,5.8,8.4]],"ltp":0.0,"tv":0.0,"id":17467775},{"batl":[[1,2.12,36.97],[2,2.24,22.74]],"ltp":2.66,"tv":326.02,"id":17467774},{"batb":[[1,7.2,35.13]],"batl":[[1,9.2,5.04],[2,9.8,8.73]],"ltp":0.0,"tv":0.0,"id":16775228},{"batb":[[1,4.9,58.27]],"batl":[[1,5.9,8.4]],"ltp":0.0,"tv":0.0,"id":16775230}]}]}
{"op":"mcm","clk":"1004049265","pt":1580653128103,"mc":[{"id":"1.168224028","rc":[{"batb":[[0,4.9,36.78],[1,4.8,45.75],[2,1.01,0.51]],"ltp":0.0,"tv":0.0,"id":17467775},{"batb":[[0,1.91,61.74],[1,1.01,0.51],[2,1.98,0]],"batl":[[0,2.12,36.97],[1,2.24,22.74],[2,2.24,0]],"ltp":2.66,"tv":326.02,"id":17467774},{"batb":[[0,7.2,6.72],[1,5.8,19.67],[2,1.01,0.51]],"batl":[[0,9.2,5.04],[1,9.8,8.73],[2,9.8,0]],"ltp":0.0,"tv":0.0,"id":16775228},{"batb":[[0,5,24.05]],"ltp":0.0,"tv":0.0,"id":16775230}]}]}
{"op":"mcm","clk":"1004049403","pt":1580653128802,"mc":[{"id":"1.168224028","rc":[{"batb":[[1,4.8,34.83]],"batl":[[1,5.8,0]],"ltp":0.0,"tv":0.0,"id":17467775},{"batb":[[0,1.91,16.37]],"batl":[[0,2.24,22.74],[1,2.24,0]],"ltp":2.66,"tv":326.02,"id":17467774},{"batb":[[0,5.8,19.67],[1,1.01,0.51],[2,1.01,0]],"batl":[[0,9.8,8.73],[1,9.8,0]],"ltp":0.0,"tv":0.0,"id":16775228},{"batb":[[1,4.9,48.19]],"batl":[[1,5.9,0]],"ltp":0.0,"tv":0.0,"id":16775230}]}]}
{"op":"mcm","clk":"1004049762","pt":1580653130900,"mc":[{"id":"1.168224028","rc":[{"batb":[[0,1.94,53.85],[1,1.92,75.55],[2,1.91,16.37]],"ltp":2.66,"tv":326.02,"id":17467774},{"batb":[[0,6.2,21.77],[1,6,42.59],[2,5.8,19.67]],"ltp":0.0,"tv":0.0,"id":16775228}]}]}
{"op":"mcm","clk":"1004052118","pt":1580653142915,"mc":[{"id":"1.168224028","rc":[{"batb":[[0,1.91,16.37],[1,1.01,0.51],[2,1.91,0]],"ltp":2.66,"tv":326.02,"id":17467774}]}]}
{"op":"mcm","clk":"1004052533","pt":1580653145021,"mc":[{"id":"1.168224028","rc":[{"batb":[[0,2.14,87.43],[1,2.12,56],[2,1.91,16.37]],"ltp":2.66,"tv":326.02,"id":17467774}]}]}
{"op":"mcm","clk":"1004052757","pt":1580653146107,"mc":[{"id":"1.168224028","rc":[{"batb":[[1,4.8,50.25],[2,4.7,10.92]],"batl":[[0,5.5,14.08],[1,5.7,21.46]],"ltp":0.0,"tv":0.0,"id":17467775},{"batb":[[1,2.12,79.29],[2,2.02,41.17]],"batl":[[0,2.24,56.35],[1,2.46,17.7]],"ltp":2.66,"tv":326.02,"id":17467774},{"batb":[[0,6.2,29.33]],"batl":[[0,6.8,18.33],[1,7.6,5.88],[2,8.2,12.35]],"ltp":0.0,"tv":0.0,"id":16775228},{"batb":[[2,4.8,10.92]],"batl":[[0,5.6,13.77],[1,5.8,8.4]],"ltp":0.0,"tv":0.0,"id":16775230}]}]}
{"op":"mcm","clk":"1004056070","pt":1580653163048,"mc":[{"id":"1.168224028","rc":[{"batb":[[0,4.9,14.71]],"ltp":0.0,"tv":0.0,"id":17467775},{"batb":[[0,2.12,23.29],[1,2.02,41.17],[2,2,28.4]],"ltp":2.66,"tv":326.02,"id":17467774},{"batb":[[0,6.2,7.56],[1,5.8,19.67],[2,4.9,14.79]],"ltp":0.0,"tv":0.0,"id":16775228},{"batb":[[0,4.9,48.19],[1,4.8,10.92],[2,1.01,0.51]],"ltp":0.0,"tv":0.0,"id":16775230}]}]}
{"op":"mcm","clk":"1004056120","pt":1580653163259,"mc":[{"id":"1.168224028","rc":[{"batb":[[0,4.8,50.25],[1,4.7,10.92],[2,1.01,0.51]],"batl":[[0,5.7,21.46],[1,5.7,0]],"ltp":0.0,"tv":0.0,"id":17467775},{"batb":[[0,2.02,41.17],[1,2,28.4],[2,1.01,0.51]],"batl":[[0,2.24,33.61]],"ltp":2.66,"tv":326.02,"id":17467774},{"batb":[[1,4.9,14.79],[2,1.01,0.51]],"batl":[[0,7.6,5.88],[1,8.2,12.35],[2,8.2,0]],"ltp":0.0,"tv":0.0,"id":16775228}]}]}
{"op":"mcm","clk":"1004056442","pt":1580653164881,"mc":[{"id":"1.168224028","rc":[{"batb":[[1,1.01,0.51],[2,1.01,0]],"batl":[[0,5.7,13.06]],"ltp":0.0,"tv":0.0,"id":17467775},{"batb":[[0,2,28.4],[1,1.01,0.51],[2,1.01,0]],"batl":[[0,2.46,17.7],[1,2.46,0]],"ltp":2.66,"tv":326.02,"id":17467774},{"batb":[[0,4.9,14.79],[1,1.01,0.51],[2,1.01,0]],"batl":[[0,8.2,12.35],[1,8.2,0]],"ltp":0.0,"tv":0.0,"id":16775228},{"batb":[[1,1.01,0.51],[2,1.01,0]],"batl":[[1,5.8,0]],"ltp":0.0,"tv":0.0,"id":16775230}]}]}
{"op":"mcm","clk":"1004056682","pt":1580653166077,"mc":[{"id":"1.168224028","rc":[{"batb":[[1,4.7,36.9],[2,1.01,0.51]],"ltp":0.0,"tv":0.0,"id":17467775},{"batb":[[0,2.02,87.25],[1,2,95.03],[2,1.01,0.51]],"ltp":2.66,"tv":326.02,"id":17467774},{"batb":[[0,4.9,66.07],[1,4.8,35.23],[2,1.01,0.51]],"ltp":0.0,"tv":0.0,"id":16775228},{"batb":[[0,4.9,67.75],[1,4.8,35.21],[2,1.01,0.51]],"ltp":0.0,"tv":0.0,"id":16775230}]}]}
{"op":"mcm","clk":"1004057041","pt":1580653167957,"mc":[{"id":"1.168224028","rc":[{"batb":[[0,2,28.4],[1,1.01,0.51],[2,1.01,0]],"ltp":2.66,"tv":326.02,"id":17467774}]}]}
{"op":"mcm","clk":"1004057662","pt":1580653170864,"mc":[{"id":"1.168224028","rc":[{"batb":[[0,2.36,74.35],[1,2.32,85.84],[2,2,28.4]],"ltp":2.66,"tv":326.02,"id":17467774}]}]}
{"op":"mcm","clk":"1004057884","pt":1580653171976,"mc":[{"id":"1.168224028","rc":[{"batb":[[1,4.7,53.03],[2,4.6,10.92]],"batl":[[0,5.4,14.71],[1,5.5,23.48],[2,5.7,13.06]],"ltp":0.0,"tv":0.0,"id":17467775},{"batb":[[1,2.32,104.02],[2,2.18,35.29]],"batl":[[0,2.46,46.27],[1,2.74,13.3]],"ltp":2.66,"tv":326.02,"id":17467774},{"batb":[[0,5,10.08],[1,4.9,66.07],[2,4.8,35.23]],"batl":[[0,5.5,14.16],[1,6.2,7.56],[2,6.6,19.04]],"ltp":0.0,"tv":0.0,"id":16775228},{"batb":[[2,4.7,10.92]],"batl":[[1,5.7,8.4]],"ltp":0.0,"tv":0.0,"id":16775230}]}]}
{"op":"mcm","clk":"1004057951","pt":1580653172289,"mc":[{"id":"1.168224028","rc":[{"batl":[[2,5.7,0]],"ltp":0.0,"tv":0.0,"id":17467775}]}]}
{"op":"mcm","clk":"1004060683","pt":1580653186036,"mc":[{"id":"1.168224028","rc":[{"batb":[[0,4.8,15.42]],"ltp":0.0,"tv":0.0,"id":17467775},{"batb":[[0,2.32,18.18],[1,2.18,35.29],[2,2.14,22.66]],"ltp":2.66,"tv":326.02,"id":17467774},{"batb":[[1,4.9,14.79],[2,4.1,22.74]],"ltp":0.0,"tv":0.0,"id":16775228}]}]}
{"op":"mcm","clk":"1004060881","pt":1580653186958,"mc":[{"id":"1.168224028","rc":[{"batb":[[0,4.7,53.03],[1,1.01,0.51],[2,4.6,0]],"batl":[[0,5.5,14.24],[1,5.5,0]],"ltp":0.0,"tv":0.0,"id":17467775},{"batb":[[0,2.14,22.66],[1,1.01,0.51],[2,2.14,0]],"batl":[[0,2.74,13.3],[1,2.74,0]],"ltp":2.66,"tv":326.02,"id":17467774},{"batb":[[0,4.1,22.74],[1,1.01,0.51],[2,4.1,0]],"batl":[[0,6.6,19.04],[1,6.2,0],[2,6.6,0]],"ltp":0.0,"tv":0.0,"id":16775228},{"batb":[[2,1.01,0.51]],"batl":[[1,5.7,0]],"ltp":0.0,"tv":0.0,"id":16775230}]}]}
{"op":"mcm","clk":"1004061267","pt":1580653188814,"mc":[{"id":"1.168224028","rc":[{"batb":[[1,4.6,38.77],[2,1.01,0.51]],"ltp":0.0,"tv":0.0,"id":17467775},{"batb":[[0,2.18,70.81],[1,2.16,53.06],[2,2.14,22.66]],"ltp":2.66,"tv":326.02,"id":17467774},{"batb":[[1,3.95,47.15],[2,3.9,28.97]],"ltp":0.0,"tv":0.0,"id":16775228}]}]}
{"op":"mcm","clk":"1004061363","pt":1580653189360,"mc":[{"id":"1.168224028","rc":[{"batb":[[1,1.01,0.51],[2,1.01,0]],"ltp":0.0,"tv":0.0,"id":17467775},{"batb":[[0,2.14,22.66],[1,1.01,0.51],[2,2.14,0]],"ltp":2.66,"tv":326.02,"id":17467774},{"batb":[[1,1.01,0.51],[2,3.9,0]],"ltp":0.0,"tv":0.0,"id":16775228}]}]}
{"op":"mcm","clk":"1004062060","pt":1580653193061,"mc":[{"id":"1.168224028","rc":[{"batb":[[0,4.8,21.8],[1,4.7,53.03],[2,1.01,0.51]],"ltp":0.0,"tv":0.0,"id":17467775},{"batb":[[0,2.42,74.06],[1,2.38,79.99],[2,2.14,22.66]],"ltp":2.66,"tv":326.02,"id":17467774},{"batb":[[0,4.7,40.85],[1,4.6,39.02],[2,4.1,22.74]],"ltp":0.0,"tv":0.0,"id":16775228}]}]}
{"op":"mcm","clk":"1004062567","pt":1580653195669,"mc":[{"id":"1.168224028","rc":[{"batb":[[0,4.7,53.03],[1,1.01,0.51],[2,1.01,0]],"ltp":0.0,"tv":0.0,"id":17467775},{"batb":[[0,2.14,22.66],[1,1.01,0.51],[2,2.14,0]],"ltp":2.66,"tv":326.02,"id":17467774},{"batb":[[0,4.1,22.74],[1,1.01,0.51],[2,4.1,0]],"ltp":0.0,"tv":0.0,"id":16775228}]}]}
{"op":"mcm","clk":"1004063124","pt":1580653198579,"mc":[{"id":"1.168224028","rc":[{"batb":[[1,4.6,38.77],[2,1.01,0.51]],"ltp":0.0,"tv":0.0,"id":17467775},{"batb":[[0,2.18,70.81],[1,2.16,53.06],[2,2.14,22.66]],"ltp":2.66,"tv":326.02,"id":17467774},{"batb":[[1,3.95,47.15],[2,3.9,28.97]],"ltp":0.0,"tv":0.0,"id":16775228}]}]}
{"op":"mcm","clk":"1004065353","pt":1580653209621,"mc":[{"id":"1.168224028","rc":[{"batb":[[1,1.01,0.51],[2,1.01,0]],"ltp":0.0,"tv":0.0,"id":17467775},{"batb":[[1,1.01,0.51],[2,3.9,0]],"ltp":0.0,"tv":0.0,"id":16775228}]}]}
{"op":"mcm","clk":"1004066099","pt":1580653213013,"mc":[{"id":"1.168224028","rc":[{"batb":[[0,4.9,14.95],[1,4.8,67.3],[2,4.7,53.03]],"batl":[[1,5.6,13.53]],"ltp":0.0,"tv":0.0,"id":17467775},{"batl":[[0,2.26,22.11],[1,2.54,16.13],[2,2.74,13.3]],"ltp":2.66,"tv":326.02,"id":17467774},{"batb":[[0,6,18.72],[1,5.9,22.52],[2,5.7,20.46]],"batl":[[1,8.6,11.49]],"ltp":0.0,"tv":0.0,"id":16775228}]}]}
{"op":"mcm","clk":"1004066277","pt":1580653213832,"mc":[{"id":"1.168224028","rc":[{"batb":[[2,4.7,47.82]],"batl":[[1,5.6,21.94]],"ltp":0.0,"tv":0.0,"id":17467775},{"batl":[[1,2.3,31.93],[2,2.54,16.13]],"ltp":2.66,"tv":326.02,"id":17467774},{"batb":[[2,5.8,8.4]],"batl":[[1,7.4,5.88],[2,8.6,11.49]],"ltp":0.0,"tv":0.0,"id":16775228},{"batb":[[2,4.7,10.92]],"batl":[[1,5.7,8.4]],"ltp":0.0,"tv":0.0,"id":16775230}]}]}
{"op":"mcm","clk":"1004069450","pt":1580653229482,"mc":[{"id":"1.168224028","rc":[{"batb":[[0,4.8,15.58],[1,4.7,47.82],[2,1.01,0.51]],"batl":[[0,5.6,21.94],[1,5.6,0]],"ltp":0.0,"tv":0.0,"id":17467775},{"batb":[[0,2.06,39.49],[1,1.99,28.8],[2,1.01,0.51]],"batl":[[0,2.3,31.93],[1,2.54,16.13],[2,2.54,0]],"ltp":2.66,"tv":326.02,"id":17467774},{"batb":[[0,5.8,8.4],[1,4.5,17.39],[2,1.01,0.51]],"batl":[[0,7.4,5.88],[1,8.6,11.49],[2,8.6,0]],"ltp":0.0,"tv":0.0,"id":16775228}]}]}
{"op":"mcm","clk":"1004069753","pt":1580653230964,"mc":[{"id":"1.168224028","rc":[{"batb":[[1,4.7,36.9]],"batl":[[0,5.6,13.53]],"ltp":0.0,"tv":0.0,"id":17467775},{"batb":[[0,1.99,28.8],[1,1.01,0.51],[2,1.01,0]],"batl":[[0,2.54,16.13],[1,2.54,0]],"ltp":2.66,"tv":326.02,"id":17467774},{"batb":[[0,4.5,17.39],[1,1.01,0.51],[2,1.01,0]],"batl":[[0,8.6,11.49],[1,8.6,0]],"ltp":0.0,"tv":0.0,"id":16775228},{"batb":[[2,1.01,0.51]],"batl":[[1,5.7,0]],"ltp":0.0,"tv":0.0,"id":16775230}]}]}
{"op":"mcm","clk":"1004070039","pt":1580653232270,"mc":[{"id":"1.168224028","rc":[{"batb":[[1,4.7,51.12],[2,4.6,38.42]],"ltp":0.0,"tv":0.0,"id":17467775},{"batb":[[0,2.02,73.05],[1,2,66.63],[2,1.99,28.8]],"ltp":2.66,"tv":326.02,"id":17467774},{"batb":[[0,4.5,69.95],[1,4.4,43.04],[2,1.01,0.51]],"ltp":0.0,"tv":0.0,"id":16775228}]}]}
{"op":"mcm","clk":"1004070438","pt":1580653234373,"mc":[{"id":"1.168224028","rc":[{"batb":[[0,1.99,28.8],[1,1.01,0.51],[2,1.99,0]],"ltp":2.66,"tv":326.02,"id":17467774}]}]}
{"op":"mcm","clk":"1004071212","pt":1580653238086,"mc":[{"id":"1.168224028","rc":[{"batb":[[2,4.6,66.18]],"batl":[[0,5.4,14.87],[1,5.5,23.4]],"ltp":0.0,"tv":0.0,"id":17467775},{"batb":[[0,2.48,63.28],[1,2.44,74.78],[2,2.4,16.52]],"batl":[[1,2.58,26.05],[2,2.96,10.94]],"ltp":2.66,"tv":326.02,"id":17467774},{"batb":[[0,4.6,10.92],[1,4.5,69.95],[2,4.4,43.04]],"batl":[[0,5.1,16.6],[1,5.6,8.4],[2,6.6,19.51]],"ltp":0.0,"tv":0.0,"id":16775228},{"batb":[[2,4.7,10.92]],"batl":[[1,5.7,8.4]],"ltp":0.0,"tv":0.0,"id":16775230}]}]}
{"op":"mcm","clk":"1004074072","pt":1580653252012,"mc":[{"id":"1.168224028","rc":[{"batb":[[0,4.6,66.18],[1,1.01,0.51],[2,4.6,0]],"batl":[[0,5.5,23.4],[1,5.5,0]],"ltp":0.0,"tv":0.0,"id":17467775},{"batb":[[0,2.3,31.93],[1,2.16,22.35],[2,1.01,0.51]],"batl":[[0,2.58,26.05],[1,2.96,10.94],[2,2.96,0]],"ltp":2.66,"tv":326.02,"id":17467774},{"batb":[[1,3.7,14.24],[2,1.01,0.51]],"batl":[[0,5.6,8.4],[1,6.6,19.51],[2,6.6,0]],"ltp":0.0,"tv":0.0,"id":16775228},{"batb":[[0,4.9,58.07]],"ltp":0.0,"tv":0.0,"id":16775230}]}]}
{"op":"mcm","clk":"1004074229","pt":1580653252804,"mc":[{"id":"1.168224028","rc":[{"batb":[[0,4.6,55.26]],"batl":[[0,5.5,14.16]],"ltp":0.0,"tv":0.0,"id":17467775},{"batb":[[0,2.16,22.35],[1,1.01,0.51],[2,1.01,0]],"batl":[[0,2.96,10.94],[1,2.96,0]],"ltp":2.66,"tv":326.02,"id":17467774},{"batb":[[0,3.7,14.24],[1,1.01,0.51],[2,1.01,0]],"batl":[[0,6.6,19.51],[1,6.6,0]],"ltp":0.0,"tv":0.0,"id":16775228},{"batb":[[2,1.01,0.51]],"batl":[[1,5.7,0]],"ltp":0.0,"tv":0.0,"id":16775230}]}]}
{"op":"mcm","clk":"1004074712","pt":1580653254953,"mc":[{"id":"1.168224028","rc":[{"batb":[[0,4.9,48.67],[1,1.01,0.51],[2,1.01,0]],"ltp":0.0,"tv":0.0,"id":16775230}]}]}
{"op":"mcm","clk":"1004075399","pt":1580653257936,"mc":[{"id":"1.168224028","rc":[{"batb":[[0,4.7,39.73],[1,4.6,55.26],[2,1.01,0.51]],"ltp":0.0,"tv":0.0,"id":17467775},{"batb":[[0,2.58,55.41],[1,2.54,67.15],[2,2.16,22.35]],"ltp":2.66,"tv":326.02,"id":17467774},{"batb":[[0,4.2,67.7],[1,4.1,50.5],[2,3.7,14.24]],"ltp":0.0,"tv":0.0,"id":16775228},{"batb":[[0,5,22.43],[1,4.9,48.67],[2,1.01,0.51]],"ltp":0.0,"tv":0.0,"id":16775230}]}]}
{"op":"mcm","clk":"1004076354","pt":1580653262273,"mc":[{"id":"1.168224028","rc":[{"batb":[[0,4.6,55.26],[1,1.01,0.51],[2,1.01,0]],"ltp":0.0,"tv":0.0,"id":17467775},{"batb":[[0,2.16,22.35],[1,1.01,0.51],[2,2.16,0]],"ltp":2.66,"tv":326.02,"id":17467774},{"batb":[[0,3.7,14.24],[1,1.01,0.51],[2,3.7,0]],"ltp":0.0,"tv":0.0,"id":16775228},{"batb":[[0,4.9,48.67],[1,1.01,0.51],[2,1.01,0]],"ltp":0.0,"tv":0.0,"id":16775230}]}]}
{"op":"mcm","clk":"1004077132","pt":1580653265952,"mc":[{"id":"1.168224028","rc":[{"batb":[[1,4.5,40.6],[2,1.01,0.51]],"ltp":0.0,"tv":0.0,"id":17467775},{"batb":[[0,2.2,64.51],[1,2.18,51.66],[2,2.16,22.35]],"ltp":2.66,"tv":326.02,"id":17467774},{"batb":[[1,3.4,56.84],[2,3.35,41.57]],"ltp":0.0,"tv":0.0,"id":16775228},{"batb":[[0,4.9,58.08],[1,4.8,35.34],[2,1.01,0.51]],"ltp":0.0,"tv":0.0,"id":16775230}]}]}
{"op":"mcm","clk":"1004078168","pt":1580653271152,"mc":[{"id":"1.168224028","rc":[{"batb":[[0,2.16,22.35],[1,1.01,0.51],[2,2.16,0]],"ltp":2.66,"tv":326.02,"id":17467774},{"batb":[[0,4.9,48.67],[1,1.01,0.51],[2,1.01,0]],"ltp":0.0,"tv":0.0,"id":16775230}]}]}
{"op":"mcm","clk":"1004078990","pt":1580653275066,"mc":[{"id":"1.168224028","rc":[{"batl":[[0,5.2,16.05],[1,5.3,15.42]],"ltp":0.0,"tv":0.0,"id":17467775},{"trd":[[2.96,21.88]],"batb":[[0,3.05,53.08],[1,3,54.26],[2,2.78,11.17]],"batl":[[0,3.3,21.09]],"ltp":2.96,"tv":347.89,"id":17467774},{"batb":[[2,3.35,60.06]],"batl":[[0,4.1,13.77],[1,4.7,19.83]],"ltp":0.0,"tv":0.0,"id":16775228},{"batb":[[0,5,34.51],[1,4.9,48.51],[2,1.01,0.51]],"batl":[[0,5.6,13.61]],"ltp":0.0,"tv":0.0,"id":16775230}],"tv":347.89}]}
{"op":"mcm","clk":"1004079221","pt":1580653276084,"mc":[{"id":"1.168224028","rc":[{"batl":[[0,3.85,14.28],[1,4.1,13.77],[2,4.7,19.83]],"ltp":0.0,"tv":0.0,"id":16775228},{"batb":[[2,4.6,10.92]],"ltp":0.0,"tv":0.0,"id":16775230}]}]}
{"op":"mcm","clk":"1004079574","pt":1580653277666,"mc":[{"id":"1.168224028","rc":[{"batb":[[2,4.3,12.6]],"batl":[[0,5.2,25.29]],"ltp":0.0,"tv":0.0,"id":17467775},{"batb":[[2,2.98,21]],"batl":[[1,3.45,16.8]],"ltp":2.96,"tv":347.89,"id":17467774},{"batl":[[0,5.5,9.24],[1,5.6,13.61]],"ltp":0.0,"tv":0.0,"id":16775230}]}]}
{"op":"mcm","clk":"1004086115","pt":1580653309023,"mc":[{"id":"1.168224028","rc":[{"batb":[[0,4.6,16.84],[2,1.01,0.51]],"batl":[[0,5.3,15.42],[1,5.3,0]],"ltp":0.0,"tv":0.0,"id":17467775},{"batb":[[0,2.52,14.56],[1,1.01,0.51],[2,2.98,0]],"batl":[[1,3.45,0]],"ltp":2.96,"tv":347.89,"id":17467774},{"batb":[[0,3.35,18.49],[1,1.01,0.51],[2,3.35,0]],"batl":[[0,4.7,19.83],[1,4.1,0],[2,4.7,0]],"ltp":0.0,"tv":0.0,"id":16775228},{"batb":[[2,1.01,0.51]],"batl":[[0,5.6,13.61],[1,5.6,0]],"ltp":0.0,"tv":0.0,"id":16775230}]}]}
{"op":"mcm","clk":"1004086744","pt":1580653312104,"mc":[{"id":"1.168224028","rc":[{"batb":[[1,4.5,40.67]],"ltp":0.0,"tv":0.0,"id":17467775},{"batb":[[0,2.58,13.85],[1,2.52,14.56],[2,1.01,0.51]],"batl":[[1,3.4,19.83]],"ltp":2.96,"tv":347.89,"id":17467774},{"batb":[[1,3.25,19.43],[2,1.01,0.51]],"batl":[[0,4.6,20.93],[1,4.7,19.83]],"ltp":0.0,"tv":0.0,"id":16775228},{"batl":[[0,5.5,14.08],[1,5.6,13.61]],"ltp":0.0,"tv":0.0,"id":16775230}]}]}
{"op":"mcm","clk":"1004086864","pt":1580653312756,"mc":[{"id":"1.168224028","rc":[{"batb":[[1,1.01,0.51],[2,1.01,0]],"batl":[[0,3.4,19.83],[1,3.4,0]],"ltp":2.96,"tv":347.89,"id":17467774},{"batb":[[0,3.25,19.43],[1,1.01,0.51],[2,1.01,0]],"batl":[[1,4.7,0]],"ltp":0.0,"tv":0.0,"id":16775228},{"batl":[[1,5.6,0]],"ltp":0.0,"tv":0.0,"id":16775230}]}]}
{"op":"mcm","clk":"1004087330","pt":1580653315104,"mc":[{"id":"1.168224028","rc":[{"batb":[[0,4.6,53.49]],"ltp":0.0,"tv":0.0,"id":17467775},{"batb":[[0,2.98,50.18],[1,2.94,45.88],[2,2.58,13.85]],"ltp":2.96,"tv":347.89,"id":17467774},{"batb":[[0,3.5,57.08],[1,3.45,38.91],[2,3.25,19.43]],"ltp":0.0,"tv":0.0,"id":16775228}]}]}
{"op":"mcm","clk":"1004088093","pt":1580653318921,"mc":[{"id":"1.168224028","rc":[{"batb":[[0,4.6,16.84]],"ltp":0.0,"tv":0.0,"id":17467775},{"batb":[[0,2.58,13.85],[1,1.01,0.51],[2,2.58,0]],"ltp":2.96,"tv":347.89,"id":17467774},{"batb":[[0,3.25,19.43],[1,1.01,0.51],[2,3.25,0]],"ltp":0.0,"tv":0.0,"id":16775228}]}]}
{"op":"mcm","clk":"1004088707","pt":1580653322108,"mc":[{"id":"1.168224028","rc":[{"batb":[[1,4.5,57.25],[2,4.4,42.49]],"ltp":0.0,"tv":0.0,"id":17467775},{"batb":[[0,2.72,51.45],[1,2.68,58.29],[2,2.58,13.85]],"ltp":2.96,"tv":347.89,"id":17467774},{"batb":[[1,3.15,35.74],[2,3.1,50.83]],"ltp":0.0,"tv":0.0,"id":16775228}]}]}
{"op":"mcm","clk":"1004089318","pt":1580653325040,"mc":[{"id":"1.168224028","rc":[{"batb":[[0,2.58,13.85],[1,1.01,0.51],[2,2.58,0]],"ltp":2.96,"tv":347.89,"id":17467774}]}]}
{"op":"mcm","clk":"1004089942","pt":1580653327931,"mc":[{"id":"1.168224028","rc":[{"batb":[[0,3.35,43.83],[1,3.3,42.85],[2,2.58,13.85]],"ltp":2.96,"tv":347.89,"id":17467774}]}]}
{"op":"mcm","clk":"1004090192","pt":1580653329076,"mc":[{"id":"1.168224028","rc":[{"batb":[[1,4.5,74.72]],"batl":[[0,5.2,25.21],[1,5.3,15.42]],"ltp":0.0,"tv":0.0,"id":17467775},{"batb":[[2,3.2,18.48]],"batl":[[1,3.7,15.12],[2,3.8,15.26]],"ltp":2.96,"tv":347.89,"id":17467774},{"batb":[[2,3.1,70.15]],"batl":[[0,3.55,18.73],[1,3.65,15.12],[2,4,14.24]],"ltp":0.0,"tv":0.0,"id":16775228},{"batb":[[2,4.6,10.92]],"batl":[[0,5.5,23.33]],"ltp":0.0,"tv":0.0,"id":16775230}]}]}
{"op":"mcm","clk":"1004090233","pt":1580653329301,"mc":[{"id":"1.168224028","rc":[{"batb":[[0,4.5,74.72],[1,4.4,42.49],[2,4.3,12.6]],"batl":[[1,5.3,0]],"ltp":0.0,"tv":0.0,"id":17467775}]}]}
{"op":"mcm","clk":"1004092499","pt":1580653340990,"mc":[{"id":"1.168224028","rc":[{"batb":[[0,4.5,17.47],[1,4.3,12.6],[2,1.01,0.51]],"ltp":0.0,"tv":0.0,"id":17467775},{"batb":[[0,3.2,18.48],[1,3.1,20.61],[2,2.84,10.62]],"ltp":2.96,"tv":347.89,"id":17467774},{"batb":[[1,3.1,19.32],[2,2.98,24.55]],"ltp":0.0,"tv":0.0,"id":16775228},{"batb":[[0,4.9,14.4],[1,4.6,10.92],[2,1.01,0.51]],"ltp":0.0,"tv":0.0,"id":16775230}]}]}
{"op":"mcm","clk":"1004092580","pt":1580653341384,"mc":[{"id":"1.168224028","rc":[{"batb":[[1,1.01,0.51],[2,1.01,0]],"batl":[[0,5.2,15.97]],"ltp":0.0,"tv":0.0,"id":17467775},{"batb":[[0,2.84,10.62],[1,1.01,0.51],[2,2.84,0]],"batl":[[0,3.8,15.26],[1,3.7,0],[2,3.8,0]],"ltp":2.96,"tv":347.89,"id":17467774},{"batb":[[0,2.98,24.55],[1,1.01,0.51],[2,2.98,0]],"batl":[[0,4,14.24],[1,3.65,0],[2,4,0]],"ltp":0.0,"tv":0.0,"id":16775228},{"batb":[[1,1.01,0.51],[2,1.01,0]],"batl":[[0,5.5,14.08]],"ltp":0.0,"tv":0.0,"id":16775230}]}]}
{"op":"mcm","clk":"1004093334","pt":1580653345091,"mc":[{"id":"1.168224028","rc":[{"batb":[[0,4.5,64.26],[1,4.4,42.67],[2,1.01,0.51]],"batl":[[0,5.2,15.82]],"ltp":0.0,"tv":0.0,"id":17467775},{"batb":[[0,3,43.99],[1,2.96,45.13],[2,2.84,10.62]],"ltp":2.96,"tv":347.89,"id":17467774},{"batb":[[1,2.94,36.13],[2,2.9,48.26]],"ltp":0.0,"tv":0.0,"id":16775228},{"batb":[[0,5,39.84],[1,4.9,33.97],[2,4.8,14.95]],"ltp":0.0,"tv":0.0,"id":16775230}]}]}
{"op":"mcm","clk":"1004094877","pt":1580653353109,"mc":[{"id":"1.168224028","rc":[{"batb":[[1,1.01,0.51],[2,1.01,0]],"ltp":0.0,"tv":0.0,"id":17467775},{"batb":[[1,1.01,0.51],[2,2.9,0]],"ltp":0.0,"tv":0.0,"id":16775228}]}]}
{"op":"mcm","clk":"1004095472","pt":1580653356081,"mc":[{"id":"1.168224028","rc":[{"batb":[[0,4.6,30.98],[1,4.5,64.26],[2,4.3,12.6]],"batl":[[0,5.2,25.06]],"ltp":0.0,"tv":0.0,"id":17467775},{"batb":[[2,2.94,21]],"batl":[[0,3.4,16.8],[1,3.8,15.26]],"ltp":2.96,"tv":347.89,"id":17467774},{"batb":[[0,3.5,47.44],[1,3.45,39],[2,3.4,16.8]],"batl":[[0,4,27.68]],"ltp":0.0,"tv":0.0,"id":16775228},{"batl":[[1,5.6,8.4]],"ltp":0.0,"tv":0.0,"id":16775230}]}]}
{"op":"mcm","clk":"1004095654","pt":1580653357094,"mc":[{"id":"1.168224028","rc":[{"batb":[[0,4.6,48.05],[1,4.5,46.79]],"batl":[[0,5.2,9.24],[1,5.3,15.19]],"ltp":0.0,"tv":0.0,"id":17467775},{"batb":[[2,2.84,10.62]],"batl":[[0,3.05,10.46],[1,3.4,16.8],[2,3.45,19.36]],"ltp":2.96,"tv":347.89,"id":17467774},{"batb":[[0,3.65,14.63],[1,3.5,47.44],[2,3.45,39]],"batl":[[1,4.8,19.04]],"ltp":0.0,"tv":0.0,"id":16775228}]}]}
{"op":"mcm","clk":"1004096195","pt":1580653359995,"mc":[{"id":"1.168224028","rc":[{"batb":[[2,2.92,21.85]],"ltp":2.96,"tv":347.89,"id":17467774}]}]}
{"op":"mcm","clk":"1004099733","pt":1580653377944,"mc":[{"id":"1.168224028","rc":[{"batb":[[0,4.6,17.07]],"ltp":0.0,"tv":0.0,"id":17467775},{"batb":[[0,2.92,21.85],[1,2.52,14.56],[2,1.01,0.51]],"batl":[[0,3.4,16.8],[1,3.45,19.36],[2,3.45,0]],"ltp":2.96,"tv":347.89,"id":17467774},{"batb":[[0,3.4,16.8],[1,3.25,19.91],[2,1.01,0.51]],"batl":[[0,4,13.44]],"ltp":0.0,"tv":0.0,"id":16775228}]}]}
{"op":"mcm","clk":"1004099973","pt":1580653379277,"mc":[{"id":"1.168224028","rc":[{"batb":[[2,1.01,0.51]],"batl":[[0,5.3,15.19],[1,5.3,0]],"ltp":0.0,"tv":0.0,"id":17467775},{"batb":[[0,2.52,14.56],[1,1.01,0.51],[2,1.01,0]],"batl":[[0,3.45,19.36],[1,3.45,0]],"ltp":2.96,"tv":347.89,"id":17467774},{"batb":[[0,3.25,19.91],[1,1.01,0.51],[2,1.01,0]],"batl":[[0,4.8,19.04],[1,4.8,0]],"ltp":0.0,"tv":0.0,"id":16775228},{"batl":[[1,5.6,0]],"ltp":0.0,"tv":0.0,"id":16775230}]}]}
{"op":"mcm","clk":"1004100305","pt":1580653380859,"mc":[{"id":"1.168224028","rc":[{"batb":[[2,4.4,42.6]],"ltp":0.0,"tv":0.0,"id":17467775},{"batb":[[0,2.62,58.53],[1,2.58,64.39],[2,2.54,14.32]],"batl":[[0,3.45,18.88]],"ltp":2.96,"tv":347.89,"id":17467774},{"batb":[[0,3.2,20.3],[1,3.15,52.14],[2,3.1,50.7]],"ltp":0.0,"tv":0.0,"id":16775228}]}]}
{"op":"mcm","clk":"1004101073","pt":1580653384920,"mc":[{"id":"1.168224028","rc":[{"batb":[[0,2.54,14.32],[1,1.01,0.51],[2,2.54,0]],"ltp":2.96,"tv":347.89,"id":17467774}]}]}
{"op":"mcm","clk":"1004101711","pt":1580653388100,"mc":[{"id":"1.168224028","rc":[{"batb":[[1,4.5,64.57]],"batl":[[0,5.1,10.08],[1,5.2,15.97],[2,5.3,15.19]],"ltp":0.0,"tv":0.0,"id":17467775},{"batb":[[0,3.35,33.2],[1,3.3,42.93],[2,3.2,19.59]],"batl":[[1,3.65,15.12],[2,3.95,14.08]],"ltp":2.96,"tv":347.89,"id":17467774},{"batb":[[1,3.15,71.46]],"batl":[[0,3.5,19.59],[1,3.7,15.12],[2,4,14.16]],"ltp":0.0,"tv":0.0,"id":16775228},{"batb":[[1,4.9,48.92]],"batl":[[1,5.6,8.4]],"ltp":0.0,"tv":0.0,"id":16775230}]}]}
{"op":"mcm","clk":"1004101730","pt":1580653388215,"mc":[{"id":"1.168224028","rc":[{"batb":[[0,4.5,64.57],[1,4.4,42.6],[2,4.2,12.6]],"batl":[[2,5.3,0]],"ltp":0.0,"tv":0.0,"id":17467775},{"batb":[[2,4.6,10.92]],"ltp":0.0,"tv":0.0,"id":16775230}]}]}
{"op":"mcm","clk":"1004104423","pt":1580653402828,"mc":[{"id":"1.168224028","rc":[{"batb":[[0,4.5,53.65]],"ltp":0.0,"tv":0.0,"id":17467775},{"batb":[[0,3.15,19.32],[1,2.84,10.62],[2,1.01,0.51]],"batl":[[0,3.65,15.12],[1,3.95,14.08],[2,3.95,0]],"ltp":2.96,"tv":347.89,"id":17467774},{"batb":[[0,3.15,19.32],[1,2.92,10.46],[2,1.01,0.51]],"batl":[[0,3.7,15.12],[1,4,14.16],[2,4,0]],"ltp":0.0,"tv":0.0,"id":16775228}]}]}
{"op":"mcm","clk":"1004104535","pt":1580653403476,"mc":[{"id":"1.168224028","rc":[{"batb":[[2,1.01,0.51]],"batl":[[0,5.2,15.97],[1,5.2,0]],"ltp":0.0,"tv":0.0,"id":17467775},{"batb":[[0,2.84,10.62],[1,1.01,0.51],[2,1.01,0]],"batl":[[0,3.95,14.08],[1,3.95,0]],"ltp":2.96,"tv":347.89,"id":17467774},{"batb":[[0,2.92,10.46],[1,1.01,0.51],[2,1.01,0]],"batl":[[0,4,14.16],[1,4,0]],"ltp":0.0,"tv":0.0,"id":16775228},{"batb":[[2,1.01,0.51]],"batl":[[1,5.6,0]],"ltp":0.0,"tv":0.0,"id":16775230}]}]}
{"op":"mcm","clk":"1004105060","pt":1580653406021,"mc":[{"id":"1.168224028","rc":[{"batb":[[0,2.94,49.81],[1,2.9,47.5],[2,2.84,10.62]],"ltp":2.96,"tv":347.89,"id":17467774},{"batb":[[0,2.92,49.54],[1,2.88,49.09],[2,1.01,0.51]],"ltp":0.0,"tv":0.0,"id":16775228}]}]}
{"op":"mcm","clk":"1004106543","pt":1580653413637,"mc":[{"id":"1.168224028","rc":[{"batb":[[0,4.5,17.78],[1,1.01,0.51],[2,1.01,0]],"ltp":0.0,"tv":0.0,"id":17467775},{"batb":[[0,2.84,10.62],[1,1.01,0.51],[2,2.84,0]],"ltp":2.96,"tv":347.89,"id":17467774},{"batb":[[0,2.92,10.46],[1,1.01,0.51],[2,1.01,0]],"ltp":0.0,"tv":0.0,"id":16775228},{"batb":[[0,4.9,14.95],[1,1.01,0.51],[2,1.01,0]],"ltp":0.0,"tv":0.0,"id":16775230}]}]}
{"op":"mcm","clk":"1004108699","pt":1580653424920,"mc":[{"id":"1.168224028","rc":[{"batb":[[0,4.5,53.65],[1,4.4,42.53],[2,1.01,0.51]],"ltp":0.0,"tv":0.0,"id":17467775},{"batb":[[0,5,40.57],[1,4.9,48.91],[2,1.01,0.51]],"ltp":0.0,"tv":0.0,"id":16775230}]}]}
{"op":"mcm","clk":"1004109119","pt":1580653427022,"mc":[{"id":"1.168224028","rc":[{"batb":[[0,2.94,49.81],[1,2.9,47.5],[2,2.84,10.62]],"ltp":2.96,"tv":347.89,"id":17467774},{"batb":[[0,2.92,49.54],[1,2.88,49.09],[2,1.01,0.51]],"ltp":0.0,"tv":0.0,"id":16775228}]}]}
{"op":"mcm","clk":"1004110517","pt":1580653434018,"mc":[{"id":"1.168224028","rc":[{"batb":[[1,1.01,0.51],[2,1.01,0]],"ltp":0.0,"tv":0.0,"id":17467775},{"batb":[[0,2.92,10.46],[1,1.01,0.51],[2,1.01,0]],"ltp":0.0,"tv":0.0,"id":16775228}]}]}
{"op":"mcm","clk":"1004111103","pt":1580653437013,"mc":[{"id":"1.168224028","rc":[{"batb":[[0,4.6,30.06],[1,4.5,53.65],[2,1.01,0.51]],"ltp":0.0,"tv":0.0,"id":17467775},{"batb":[[0,3.6,31.96],[1,3.55,36.53],[2,2.92,10.46]],"ltp":0.0,"tv":0.0,"id":16775228}]}]}
{"op":"mcm","clk":"1004111315","pt":1580653438032,"mc":[{"id":"1.168224028","rc":[{"batb":[[0,4.6,46.82],[1,4.5,53.34]],"batl":[[1,5.3,15.19]],"ltp":0.0,"tv":0.0,"id":17467775},{"batl":[[0,3.05,10.46],[1,3.55,17.86]],"ltp":2.96,"tv":347.89,"id":17467774},{"batb":[[0,3.65,14.63],[1,3.6,31.96],[2,3.55,36.53]],"batl":[[1,5,17.23]],"ltp":0.0,"tv":0.0,"id":16775228},{"batb":[[1,4.9,33.96],[2,4.8,15.26]],"ltp":0.0,"tv":0.0,"id":16775230}]}]}
{"op":"mcm","clk":"1004111506","pt":1580653439020,"mc":[{"id":"1.168224028","rc":[{"batb":[[2,4.3,12.6]],"batl":[[0,5.1,10.08],[1,5.2,15.97],[2,5.3,15.19]],"ltp":0.0,"tv":0.0,"id":17467775},{"batb":[[2,2.88,21.85]],"batl":[[1,3.3,17.64],[2,3.55,17.86]],"ltp":2.96,"tv":347.89,"id":17467774},{"batl":[[1,4.2,12.6],[2,5,17.23]],"ltp":0.0,"tv":0.0,"id":16775228},{"batl":[[1,5.6,8.4]],"ltp":0.0,"tv":0.0,"id":16775230}]}]}
{"op":"mcm","clk":"1004115422","pt":1580653457993,"mc":[{"id":"1.168224028","rc":[{"batb":[[0,4.5,53.34],[1,4.3,12.6],[2,1.01,0.51]],"batl":[[1,5.3,15.19],[2,5.3,0]],"ltp":0.0,"tv":0.0,"id":17467775},{"batb":[[0,2.88,21.85],[1,2.46,15.5],[2,1.01,0.51]],"batl":[[0,3.3,17.64],[1,3.55,17.86],[2,3.55,0]],"ltp":2.96,"tv":347.89,"id":17467774},{"batb":[[0,3.5,16.8],[1,3.15,21.24],[2,1.01,0.51]],"batl":[[0,4.2,12.6],[1,5,17.23],[2,5,0]],"ltp":0.0,"tv":0.0,"id":16775228}]}]}
{"op":"mcm","clk":"1004115681","pt":1580653459226,"mc":[{"id":"1.168224028","rc":[{"batb":[[1,1.01,0.51],[2,1.01,0]],"batl":[[0,5.3,15.19],[1,5.3,0]],"ltp":0.0,"tv":0.0,"id":17467775},{"batb":[[0,2.46,15.5],[1,1.01,0.51],[2,1.01,0]],"batl":[[0,3.55,17.86],[1,3.55,0]],"ltp":2.96,"tv":347.89,"id":17467774},{"batb":[[0,3.15,21.24],[1,1.01,0.51],[2,1.01,0]],"batl":[[0,5,17.23],[1,5,0]],"ltp":0.0,"tv":0.0,"id":16775228},{"batl":[[1,5.6,0]],"ltp":0.0,"tv":0.0,"id":16775230}]}]}
{"op":"mcm","clk":"1004116701","pt":1580653464090,"mc":[{"id":"1.168224028","rc":[{"batb":[[0,4.6,39.01],[1,4.5,53.34],[2,1.01,0.51]],"ltp":0.0,"tv":0.0,"id":17467775},{"batb":[[0,2.84,48],[1,2.8,52],[2,2.46,15.5]],"ltp":2.96,"tv":347.89,"id":17467774},{"batb":[[0,3.75,33.94],[1,3.7,33.07],[2,3.15,21.24]],"ltp":0.0,"tv":0.0,"id":16775228}]}]}
{"op":"mcm","clk":"1004117102","pt":1580653465804,"mc":[{"id":"1.168224028","rc":[{"batb":[[0,4.5,53.34],[1,1.01,0.51],[2,1.01,0]],"ltp":0.0,"tv":0.0,"id":17467775},{"batb":[[0,2.46,15.5],[1,1.01,0.51],[2,2.46,0]],"ltp":2.96,"tv":347.89,"id":17467774},{"batb":[[0,3.15,21.24],[1,1.01,0.51],[2,3.15,0]],"ltp":0.0,"tv":0.0,"id":16775228}]}]}
{"op":"mcm","clk":"1004117715","pt":1580653468702,"mc":[{"id":"1.168224028","rc":[{"batb":[[1,4.4,42.79],[2,1.01,0.51]],"ltp":0.0,"tv":0.0,"id":17467775},{"batb":[[0,2.5,41.23],[1,2.46,88.81],[2,1.01,0.51]],"ltp":2.96,"tv":347.89,"id":17467774},{"batb":[[1,3.1,72.71],[2,3.05,52.62]],"ltp":0.0,"tv":0.0,"id":16775228}]}]}
{"op":"mcm","clk":"1004120927","pt":1580653483842,"mc":[{"id":"1.168224028","rc":[{"batb":[[0,2.46,15.5],[1,1.01,0.51],[2,1.01,0]],"ltp":2.96,"tv":347.89,"id":17467774}]}]}
{"op":"mcm","clk":"1004121538","pt":1580653486760,"mc":[{"id":"1.168224028","rc":[{"batb":[[0,3.35,70.77],[1,3.3,42.58],[2,2.46,15.5]],"ltp":2.96,"tv":347.89,"id":17467774}]}]}
{"op":"mcm","clk":"1004121820","pt":1580653488069,"mc":[{"id":"1.168224028","rc":[{"batb":[[1,4.4,61.12]],"batl":[[0,5.1,16.68],[1,5.2,15.89]],"ltp":0.0,"tv":0.0,"id":17467775},{"batb":[[2,3.25,18.49]],"batl":[[1,4.2,24.08]],"ltp":2.96,"tv":347.89,"id":17467774},{"batl":[[0,3.45,20.46],[1,4.1,14.01]],"ltp":0.0,"tv":0.0,"id":16775228},{"batb":[[1,4.9,48.83],[2,1.01,0.51]],"ltp":0.0,"tv":0.0,"id":16775230}]}]}
{"op":"mcm","clk":"1004121875","pt":1580653488269,"mc":[{"id":"1.168224028","rc":[{"batb":[[2,4.2,12.6]],"batl":[[0,5,10.08],[1,5.1,16.68],[2,5.2,15.89]],"ltp":0.0,"tv":0.0,"id":17467775},{"batl":[[1,3.7,15.12],[2,4.2,24.08]],"ltp":2.96,"tv":347.89,"id":17467774},{"batb":[[0,3.15,40.57]],"batl":[[1,3.7,15.12],[2,4.1,14.01]],"ltp":0.0,"tv":0.0,"id":16775228},{"batb":[[2,4.7,10.92]],"batl":[[1,5.6,8.4]],"ltp":0.0,"tv":0.0,"id":16775230}]}]}
{"op":"mcm","clk":"1004126583","pt":1580653510047,"mc":[{"id":"1.168224028","rc":[{"batb":[[0,4.5,17.47]],"ltp":0.0,"tv":0.0,"id":17467775},{"batb":[[0,3.25,18.49],[1,3.15,19.32],[2,2.82,10.78]],"ltp":2.96,"tv":347.89,"id":17467774},{"batb":[[1,2.82,11.41],[2,1.01,0.51]],"ltp":0.0,"tv":0.0,"id":16775228}]}]}
{"op":"mcm","clk":"1004126659","pt":1580653510338,"mc":[{"id":"1.168224028","rc":[{"batb":[[0,4.4,61.12],[1,4.2,12.6],[2,1.01,0.51]],"batl":[[1,5.2,15.89],[2,5.2,0]],"ltp":0.0,"tv":0.0,"id":17467775},{"batb":[[0,3.15,19.32],[1,2.82,10.78],[2,1.01,0.51]],"batl":[[0,3.7,15.12],[1,4.2,24.08],[2,4.2,0]],"ltp":2.96,"tv":347.89,"id":17467774},{"batb":[[0,3.15,19.32]],"batl":[[0,3.7,15.12],[1,4.1,14.01],[2,4.1,0]],"ltp":0.0,"tv":0.0,"id":16775228}]}]}
{"op":"mcm","clk":"1004126960","pt":1580653511872,"mc":[{"id":"1.168224028","rc":[{"batb":[[1,1.01,0.51],[2,1.01,0]],"batl":[[0,5.2,15.89],[1,5.2,0]],"ltp":0.0,"tv":0.0,"id":17467775},{"batb":[[0,2.82,10.78],[1,1.01,0.51],[2,1.01,0]],"batl":[[0,4.2,24.08],[1,4.2,0]],"ltp":2.96,"tv":347.89,"id":17467774},{"batb":[[0,2.82,11.41],[1,1.01,0.51],[2,1.01,0]],"batl":[[0,4.1,14.01],[1,4.1,0]],"ltp":0.0,"tv":0.0,"id":16775228},{"batb":[[2,1.01,0.51]],"batl":[[1,5.6,0]],"ltp":0.0,"tv":0.0,"id":16775230}]}]}
{"op":"mcm","clk":"1004127203","pt":1580653512964,"mc":[{"id":"1.168224028","rc":[{"batb":[[0,4.4,79.26],[1,4.3,44.78],[2,1.01,0.51]],"ltp":0.0,"tv":0.0,"id":17467775},{"batb":[[0,2.92,43.42],[1,2.88,48.4],[2,2.82,10.78]],"ltp":2.96,"tv":347.89,"id":17467774},{"batb":[[0,2.86,36.16],[1,2.82,63.25],[2,1.01,0.51]],"ltp":0.0,"tv":0.0,"id":16775228}]}]}
{"op":"mcm","clk":"1004127858","pt":1580653515750,"mc":[{"id":"1.168224028","rc":[{"batb":[[0,4.4,61.12],[1,1.01,0.51],[2,1.01,0]],"ltp":0.0,"tv":0.0,"id":17467775},{"batb":[[0,2.82,10.78],[1,1.01,0.51],[2,2.82,0]],"ltp":2.96,"tv":347.89,"id":17467774},{"batb":[[0,2.82,11.41],[1,1.01,0.51],[2,1.01,0]],"ltp":0.0,"tv":0.0,"id":16775228}]}]}
{"op":"mcm","clk":"1004128600","pt":1580653519087,"mc":[{"id":"1.168224028","rc":[{"batb":[[0,4.5,45.27],[1,4.4,61.12],[2,1.01,0.51]],"ltp":0.0,"tv":0.0,"id":17467775},{"batb":[[0,3.25,69.45],[1,3.2,45.98],[2,2.82,10.78]],"ltp":2.96,"tv":347.89,"id":17467774},{"batb":[[0,3.2,58.14],[1,3.15,48.66],[2,2.82,11.41]],"ltp":0.0,"tv":0.0,"id":16775228}]}]}
{"op":"mcm","clk":"1004128844","pt":1580653520074,"mc":[{"id":"1.168224028","rc":[{"batb":[[0,4.4,61.12],[1,1.01,0.51],[2,1.01,0]],"ltp":0.0,"tv":0.0,"id":17467775},{"batb":[[0,2.82,10.78],[1,1.01,0.51],[2,2.82,0]],"ltp":2.96,"tv":347.89,"id":17467774},{"batb":[[0,2.82,11.41],[1,1.01,0.51],[2,2.82,0]],"ltp":0.0,"tv":0.0,"id":16775228}]}]}
{"op":"mcm","clk":"1004129526","pt":1580653523066,"mc":[{"id":"1.168224028","rc":[{"batb":[[0,4.4,79.26],[1,4.3,44.78],[2,1.01,0.51]],"ltp":0.0,"tv":0.0,"id":17467775},{"batb":[[0,2.92,43.42],[1,2.88,48.4],[2,2.82,10.78]],"ltp":2.96,"tv":347.89,"id":17467774},{"batb":[[0,2.86,36.16],[1,2.82,63.25],[2,1.01,0.51]],"ltp":0.0,"tv":0.0,"id":16775228}]}]}
{"op":"mcm","clk":"1004130426","pt":1580653527012,"mc":[{"id":"1.168224028","rc":[{"batb":[[0,4.4,18.33],[1,1.01,0.51],[2,1.01,0]],"ltp":0.0,"tv":0.0,"id":17467775},{"batb":[[0,2.82,11.41],[1,1.01,0.51],[2,1.01,0]],"ltp":0.0,"tv":0.0,"id":16775228}]}]}
{"op":"mcm","clk":"1004131066","pt":1580653530023,"mc":[{"id":"1.168224028","rc":[{"batb":[[0,4.6,28.43],[1,4.5,40.8],[2,4.4,18.33]],"ltp":0.0,"tv":0.0,"id":17467775},{"batb":[[0,3.6,57.25],[1,3.55,36.31],[2,2.82,11.41]],"ltp":0.0,"tv":0.0,"id":16775228}]}]}
{"op":"mcm","clk":"1004131308","pt":1580653531017,"mc":[{"id":"1.168224028","rc":[{"batb":[[0,4.6,45.11],[1,4.5,58.42],[2,4.2,12.6]],"batl":[[0,5.1,10.08],[1,5.2,15.89],[2,5.3,15.11]],"ltp":0.0,"tv":0.0,"id":17467775},{"batb":[[2,2.84,22.69]],"batl":[[0,3,10.62],[1,3.25,18.48],[2,3.55,18.18]],"ltp":2.96,"tv":347.89,"id":17467774},{"batb":[[0,3.7,14.48],[1,3.6,57.25],[2,3.55,52.27]],"batl":[[1,4.2,12.6],[2,5.1,17.07]],"ltp":0.0,"tv":0.0,"id":16775228},{"batb":[[1,4.9,33.96],[2,4.8,15.19]],"batl":[[1,5.6,8.4]],"ltp":0.0,"tv":0.0,"id":16775230}]}]}
{"op":"mcm","clk":"1004136201","pt":1580653552808,"mc":[{"id":"1.168224028","rc":[{"batb":[[0,4.5,58.42],[1,4.2,12.6],[2,1.01,0.51]],"batl":[[1,5.3,15.11],[2,5.3,0]],"ltp":0.0,"tv":0.0,"id":17467775},{"batb":[[0,2.84,22.69],[1,2.46,15.66],[2,1.01,0.51]],"batl":[[0,3.25,18.48],[1,3.55,18.18],[2,3.55,0]],"ltp":2.96,"tv":347.89,"id":17467774},{"batb":[[0,3.55,15.96],[1,3.2,20.77],[2,1.01,0.51]],"batl":[[0,4.2,12.6],[1,5.1,17.07],[2,5.1,0]],"ltp":0.0,"tv":0.0,"id":16775228}]}]}
{"op":"mcm","clk":"1004136306","pt":1580653553314,"mc":[{"id":"1.168224028","rc":[{"batb":[[1,1.01,0.51],[2,1.01,0]],"batl":[[0,5.3,15.11],[1,5.3,0]],"ltp":0.0,"tv":0.0,"id":17467775},{"batb":[[0,2.46,15.66],[1,1.01,0.51],[2,1.01,0]],"batl":[[0,3.55,18.18],[1,3.55,0]],"ltp":2.96,"tv":347.89,"id":17467774},{"batb":[[0,3.2,20.77],[1,1.01,0.51],[2,1.01,0]],"batl":[[0,5.1,17.07],[1,5.1,0]],"ltp":0.0,"tv":0.0,"id":16775228},{"batl":[[1,5.6,0]],"ltp":0.0,"tv":0.0,"id":16775230}]}]}
{"op":"mcm","clk":"1004136770","pt":1580653555606,"mc":[{"id":"1.168224028","rc":[{"batb":[[1,4.4,42.85],[2,1.01,0.51]],"ltp":0.0,"tv":0.0,"id":17467775},{"batb":[[0,2.48,43.98],[1,2.46,15.66],[2,2.44,74.94]],"batl":[[0,3.5,18.25]],"ltp":2.96,"tv":347.89,"id":17467774},{"batb":[[1,3.15,47.97],[2,3.1,50.73]],"ltp":0.0,"tv":0.0,"id":16775228}]}]}
{"op":"mcm","clk":"1004137912","pt":1580653560926,"mc":[{"id":"1.168224028","rc":[{"batb":[[0,4.5,17.62],[1,1.01,0.51],[2,1.01,0]],"ltp":0.0,"tv":0.0,"id":17467775},{"batb":[[1,1.01,0.51],[2,3.1,0]],"ltp":0.0,"tv":0.0,"id":16775228}]}]}
{"op":"mcm","clk":"1004138637","pt":1580653564101,"mc":[{"id":"1.168224028","rc":[{"batb":[[0,4.7,35.55],[1,4.6,38.68],[2,4.5,17.62]],"batl":[[0,5.3,24.35]],"ltp":0.0,"tv":0.0,"id":17467775},{"batb":[[0,2.48,71.71]],"batl":[[0,2.84,22.69],[1,3.5,18.25]],"ltp":2.96,"tv":347.89,"id":17467774},{"batb":[[0,4.5,61.55],[1,4.4,43.09],[2,4.3,12.6]],"batl":[[1,5.2,9.24]],"ltp":0.0,"tv":0.0,"id":16775228},{"batl":[[0,5.4,9.24],[1,5.5,14.08]],"ltp":0.0,"tv":0.0,"id":16775230}]}]}
{"op":"mcm","clk":"1004138855","pt":1580653565017,"mc":[{"id":"1.168224028","rc":[{"batb":[[0,4.7,51.44],[1,4.6,55.44],[2,4.3,12.6]],"batl":[[0,5.2,9.24],[1,5.3,15.11],[2,5.5,14.16]],"ltp":0.0,"tv":0.0,"id":17467775},{"batl":[[0,2.6,15.42],[1,2.82,22.69],[2,2.98,10.78]],"ltp":2.96,"tv":347.89,"id":17467774},{"batb":[[0,4.5,79.41],[1,4.4,54.85],[2,3.7,14.16]],"batl":[[1,5.3,9.24],[2,7,17.55]],"ltp":0.0,"tv":0.0,"id":16775228},{"batl":[[0,5.5,23.33],[1,5.5,0]],"ltp":0.0,"tv":0.0,"id":16775230}]}]}
{"op":"mcm","clk":"1004142573","pt":1580653581820,"mc":[{"id":"1.168224028","rc":[{"batb":[[0,4.6,43.84],[1,4.3,12.6],[2,1.01,0.51]],"batl":[[1,5.5,14.16],[2,5.5,0]],"ltp":0.0,"tv":0.0,"id":17467775},{"batb":[[0,2.48,27.73],[1,2.12,23.29],[2,1.01,0.51]],"batl":[[0,2.82,22.69],[1,2.98,10.78],[2,2.98,0]],"ltp":2.96,"tv":347.89,"id":17467774},{"batb":[[0,4.4,11.76],[1,3.7,14.16],[2,1.01,0.51]],"batl":[[0,5.3,9.24],[1,7,17.55],[2,7,0]],"ltp":0.0,"tv":0.0,"id":16775228},{"batb":[[0,5,30.03]],"ltp":0.0,"tv":0.0,"id":16775230}]}]}
{"op":"mcm","clk":"1004142872","pt":1580653583237,"mc":[{"id":"1.168224028","rc":[{"batb":[[1,1.01,0.51],[2,1.01,0]],"batl":[[0,5.5,14.16],[1,5.5,0]],"ltp":0.0,"tv":0.0,"id":17467775},{"batb":[[0,2.12,23.29],[1,1.01,0.51],[2,1.01,0]],"batl":[[0,2.98,10.78],[1,2.98,0]],"ltp":2.96,"tv":347.89,"id":17467774},{"batb":[[0,3.7,14.16],[1,1.01,0.51],[2,1.01,0]],"batl":[[0,7,17.55],[1,7,0]],"ltp":0.0,"tv":0.0,"id":16775228},{"batl":[[0,5.5,14.08]],"ltp":0.0,"tv":0.0,"id":16775230}]}]}
{"op":"mcm","clk":"1004143248","pt":1580653585032,"mc":[{"id":"1.168224028","rc":[{"batb":[[1,4.5,40.83],[2,1.01,0.51]],"ltp":0.0,"tv":0.0,"id":17467775},{"batb":[[1,2.06,103.2],[2,2.04,62.87]],"ltp":2.96,"tv":347.89,"id":17467774},{"batb":[[0,3.75,14.08],[1,3.65,43.34],[2,3.6,35.22]],"ltp":0.0,"tv":0.0,"id":16775228}]}]}
{"op":"mcm","clk":"1004144473","pt":1580653590411,"mc":[{"id":"1.168224028","rc":[{"batb":[[0,4.6,16.76],[1,1.01,0.51],[2,1.01,0]],"ltp":0.0,"tv":0.0,"id":17467775},{"batb":[[1,1.01,0.51],[2,3.6,0]],"ltp":0.0,"tv":0.0,"id":16775228}]}]}
{"op":"mcm","clk":"1004145204","pt":1580653593706,"mc":[{"id":"1.168224028","rc":[{"batb":[[0,4.9,26.21],[1,4.8,35.24],[2,4.6,16.76]],"ltp":0.0,"tv":0.0,"id":17467775},{"batb":[[0,6.8,37.68],[1,6.6,34.42],[2,3.75,14.08]],"ltp":0.0,"tv":0.0,"id":16775228}]}]}
{"op":"mcm","clk":"1004145374","pt":1580653594517,"mc":[{"id":"1.168224028","rc":[{"batb":[[0,4.9,41.08],[1,4.8,50.66],[2,4.4,11.76]],"batl":[[1,5.6,13.69]],"ltp":0.0,"tv":0.0,"id":17467775},{"batl":[[0,2.24,22.82],[1,2.44,18.02]],"ltp":2.96,"tv":347.89,"id":17467774},{"batb":[[2,5.9,18.73]],"batl":[[1,8.4,11.72],[2,9,5.04]],"ltp":0.0,"tv":0.0,"id":16775228},{"batl":[[0,5.5,23.33]],"ltp":0.0,"tv":0.0,"id":16775230}]}]}
{"op":"mcm","clk":"1004145717","pt":1580653596036,"mc":[{"id":"1.168224028","rc":[{"batl":[[0,5.3,9.24],[1,5.5,14.16],[2,5.6,13.69]],"ltp":0.0,"tv":0.0,"id":17467775},{"batl":[[0,2.24,56.43]],"ltp":2.96,"tv":347.89,"id":17467774},{"trd":[[7,13.44]],"batl":[[0,7,10.82]],"ltp":7.0,"tv":13.44,"id":16775228}],"tv":361.34}]}
{"op":"mcm","clk":"1004145954","pt":1580653597119,"mc":[{"id":"1.168224028","rc":[{"batl":[[2,9,0]],"ltp":7.0,"tv":13.44,"id":16775228}]}]}
{"op":"mcm","clk":"1004146388","pt":1580653599345,"mc":[{"id":"1.168224028","rc":[{"batl":[[2,8.6,5.04]],"ltp":7.0,"tv":13.44,"id":16775228}]}]}
{"op":"mcm","clk":"1004146928","pt":1580653602048,"mc":[{"id":"1.168224028","rc":[{"batb":[[1,2.08,24.63],[2,2.06,103.2]],"batl":[[0,2.2,24],[1,2.24,56.43],[2,2.4,19.04]],"ltp":2.96,"tv":347.89,"id":17467774},{"batb":[[2,6.2,16.84]],"batl":[[1,7.4,15.74],[2,8.4,11.72]],"ltp":7.0,"tv":13.44,"id":16775228},{"batb":[[1,4.9,48.75]],"batl":[[1,5.6,13.77]],"ltp":0.0,"tv":0.0,"id":16775230}]}]}
{"op":"mcm","clk":"1004147089","pt":1580653602861,"mc":[{"id":"1.168224028","rc":[{"batb":[[0,4.9,26.21]],"ltp":0.0,"tv":0.0,"id":17467775},{"batb":[[0,2.08,24.63],[1,2.06,103.2],[2,2.04,62.87]],"batl":[[1,2.24,33.61]],"ltp":2.96,"tv":347.89,"id":17467774},{"batb":[[0,7,6.72],[1,6.8,37.68],[2,6.6,34.42]],"batl":[[0,7.4,15.74],[1,8.6,5.04],[2,9,10.54]],"ltp":7.0,"tv":13.44,"id":16775228},{"batb":[[2,4.6,10.92]],"batl":[[0,5.5,9.24]],"ltp":0.0,"tv":0.0,"id":16775230}]}]}
{"op":"mcm","clk":"1004147142","pt":1580653603182,"mc":[{"id":"1.168224028","rc":[{"batb":[[0,6.8,37.68],[1,6.6,34.42],[2,6.2,16.84]],"ltp":7.0,"tv":13.44,"id":16775228}]}]}
{"op":"mcm","clk":"1004147618","pt":1580653605773,"mc":[{"id":"1.168224028","rc":[{"batb":[[0,7,6.72],[1,6.8,37.68],[2,6.6,34.42]],"ltp":7.0,"tv":13.44,"id":16775228}]}]}
{"op":"mcm","clk":"1004148509","pt":1580653610405,"mc":[{"id":"1.168224028","rc":[{"batl":[[0,2.18,24.47],[2,2.38,19.51]],"ltp":2.96,"tv":347.89,"id":17467774},{"batl":[[0,7.4,15.03],[2,9.2,10.07]],"ltp":7.0,"tv":13.44,"id":16775228}]}]}
{"op":"mcm","clk":"1004155270","pt":1580653644853,"mc":[{"id":"1.168224028","rc":[{"batb":[[0,4.8,50.66],[1,4.4,11.76],[2,1.01,0.51]],"ltp":0.0,"tv":0.0,"id":17467775},{"batb":[[1,2.06,83.34]],"ltp":2.96,"tv":347.89,"id":17467774}]}]}
{"op":"mcm","clk":"1004155920","pt":1580653647852,"mc":[{"id":"1.168224028","rc":[{"batb":[[0,4.8,71.47],[1,4.7,36.39],[2,4.4,11.76]],"ltp":0.0,"tv":0.0,"id":17467775},{"batb":[[1,6.8,45.05]],"ltp":7.0,"tv":13.44,"id":16775228},{"batb":[[0,5,41.72]],"ltp":0.0,"tv":0.0,"id":16775230}]}]}
{"op":"mcm","clk":"1004162844","pt":1580653681743,"mc":[{"id":"1.168224028","rc":[{"batb":[[2,1.01,0.51]],"ltp":0.0,"tv":0.0,"id":17467775},{"batl":[[1,2.38,19.51],[2,2.38,0]],"ltp":2.96,"tv":347.89,"id":17467774}]}]}
{"op":"mcm","clk":"1004163094","pt":1580653683020,"mc":[{"id":"1.168224028","rc":[{"batb":[[0,4.8,40.89]],"batl":[[1,5.6,13.69],[2,5.6,0]],"ltp":0.0,"tv":0.0,"id":17467775},{"batb":[[0,1.96,29.98],[1,1.01,0.51],[2,2.04,0]],"batl":[[0,2.38,19.51],[1,2.38,0]],"ltp":2.96,"tv":347.89,"id":17467774},{"batb":[[1,5.3,12.12],[2,1.01,0.51]],"batl":[[0,8.6,5.04],[1,9.2,10.07],[2,9.2,0]],"ltp":7.0,"tv":13.44,"id":16775228},{"batb":[[0,5,30.03]],"ltp":0.0,"tv":0.0,"id":16775230}]}]}
{"op":"mcm","clk":"1004163251","pt":1580653683741,"mc":[{"id":"1.168224028","rc":[{"batl":[[0,5.6,13.69],[1,5.6,0]],"ltp":0.0,"tv":0.0,"id":17467775},{"batb":[[0,5.3,12.12],[1,1.01,0.51],[2,1.01,0]],"batl":[[0,9.2,10.07],[1,9.2,0]],"ltp":7.0,"tv":13.44,"id":16775228},{"batb":[[2,1.01,0.51]],"batl":[[0,5.6,13.77],[1,5.6,0]],"ltp":0.0,"tv":0.0,"id":16775230}]}]}
{"op":"mcm","clk":"1004163668","pt":1580653685533,"mc":[{"id":"1.168224028","rc":[{"batb":[[0,1.96,84.27],[1,1.94,73.36],[2,1.01,0.51]],"ltp":2.96,"tv":347.89,"id":17467774},{"batb":[[0,5.5,40.61],[1,5.4,27.44],[2,5.3,12.12]],"ltp":7.0,"tv":13.44,"id":16775228}]}]}
{"op":"mcm","clk":"1004164203","pt":1580653688152,"mc":[{"id":"1.168224028","rc":[{"batb":[[0,1.96,29.98],[1,1.01,0.51],[2,1.01,0]],"ltp":2.96,"tv":347.89,"id":17467774}]}]}
{"op":"mcm","clk":"1004165081","pt":1580653692053,"mc":[{"id":"1.168224028","rc":[{"batb":[[0,4.8,25.47],[2,4.6,16.6]],"batl":[[0,5.4,15.03],[1,5.5,14.56]],"ltp":0.0,"tv":0.0,"id":17467775},{"batb":[[0,2.24,109.33],[1,2.22,49.1],[2,2.1,24.23]],"batl":[[1,2.64,14.79]],"ltp":2.96,"tv":347.89,"id":17467774},{"batl":[[0,6,11.64],[1,7.4,15.58]],"ltp":7.0,"tv":13.44,"id":16775228},{"batb":[[1,4.9,33.96],[2,4.8,15.03]],"batl":[[0,5.5,14.01]],"ltp":0.0,"tv":0.0,"id":16775230}]}]}
{"op":"mcm","clk":"1004165134","pt":1580653692262,"mc":[{"id":"1.168224028","rc":[{"batl":[[0,5.2,9.24],[1,5.4,15.03],[2,5.5,14.56]],"ltp":0.0,"tv":0.0,"id":17467775},{"batb":[[2,2.2,34.45]],"batl":[[1,2.44,28.57],[2,2.64,14.79]],"ltp":2.96,"tv":347.89,"id":17467774},{"batb":[[0,5.7,8.4],[1,5.5,40.61],[2,5.4,27.44]],"batl":[[1,6.8,6.72],[2,7.4,15.58]],"ltp":7.0,"tv":13.44,"id":16775228},{"batl":[[0,5.4,9.24],[1,5.5,14.01]],"ltp":0.0,"tv":0.0,"id":16775230}]}]}
{"op":"mcm","clk":"1004167907","pt":1580653706100,"mc":[{"id":"1.168224028","rc":[{"batb":[[0,4.7,36.39],[1,4.6,16.6],[2,4.4,11.76]],"batl":[[1,5.5,14.56],[2,5.5,0]],"ltp":0.0,"tv":0.0,"id":17467775},{"batb":[[0,2.2,34.45],[1,2.1,24.23],[2,1.01,0.51]],"batl":[[0,2.44,28.57],[1,2.64,14.79],[2,2.64,0]],"ltp":2.96,"tv":347.89,"id":17467774},{"batb":[[1,4.4,18.41],[2,1.01,0.51]],"batl":[[0,6.8,6.72],[1,7.4,15.58],[2,7.4,0]],"ltp":7.0,"tv":13.44,"id":16775228}]}]}
{"op":"mcm","clk":"1004168160","pt":1580653707428,"mc":[{"id":"1.168224028","rc":[{"batb":[[2,1.01,0.51]],"batl":[[0,5.5,14.56],[1,5.5,0]],"ltp":0.0,"tv":0.0,"id":17467775},{"batb":[[0,2.1,24.23],[1,1.01,0.51],[2,1.01,0]],"batl":[[0,2.64,14.79],[1,2.64,0]],"ltp":2.96,"tv":347.89,"id":17467774},{"batb":[[0,4.4,18.41],[1,1.01,0.51],[2,1.01,0]],"batl":[[0,7.4,15.58],[1,7.4,0]],"ltp":7.0,"tv":13.44,"id":16775228},{"batl":[[0,5.5,14.01],[1,5.5,0]],"ltp":0.0,"tv":0.0,"id":16775230}]}]}
{"op":"mcm","clk":"1004168414","pt":1580653708720,"mc":[{"id":"1.168224028","rc":[{"batb":[[1,4.6,55.37]],"ltp":0.0,"tv":0.0,"id":17467775},{"batb":[[0,2.1,78.02],[1,2.08,59.42],[2,1.01,0.51]],"ltp":2.96,"tv":347.89,"id":17467774},{"batb":[[0,4.4,79.49],[1,4.3,45.79],[2,1.01,0.51]],"ltp":7.0,"tv":13.44,"id":16775228}]}]}
{"op":"mcm","clk":"1004168605","pt":1580653709627,"mc":[{"id":"1.168224028","rc":[{"batl":[[0,5.5,14.4]],"ltp":0.0,"tv":0.0,"id":17467775},{"batb":[[0,2.1,53.79],[1,2.08,84.28]],"batl":[[0,2.62,14.95]],"ltp":2.96,"tv":347.89,"id":17467774},{"batb":[[0,4.5,18.18],[1,4.4,61.08],[2,4.3,45.79]],"ltp":7.0,"tv":13.44,"id":16775228},{"batb":[[1,4.9,48.75],[2,1.01,0.51]],"batl":[[0,5.6,13.85]],"ltp":0.0,"tv":0.0,"id":16775230}]}]}
{"op":"mcm","clk":"1004169226","pt":1580653713102,"mc":[{"id":"1.168224028","rc":[{"batb":[[1,4.6,16.6]],"ltp":0.0,"tv":0.0,"id":17467775},{"batb":[[1,1.01,0.51],[2,4.3,0]],"ltp":7.0,"tv":13.44,"id":16775228}]}]}
{"op":"mcm","clk":"1004169749","pt":1580653715915,"mc":[{"id":"1.168224028","rc":[{"batb":[[0,4.9,15.03],[1,4.8,48.97],[2,4.7,52.28]],"batl":[[1,5.6,13.69]],"ltp":0.0,"tv":0.0,"id":17467775},{"batb":[[2,1.94,15.42]],"batl":[[0,2.2,24.23],[1,2.42,18.49]],"ltp":2.96,"tv":347.89,"id":17467774},{"batb":[[0,6.6,39.03],[1,6.4,37],[2,6.2,16.52]],"batl":[[1,9.4,9.44]],"ltp":7.0,"tv":13.44,"id":16775228}]}]}
{"op":"mcm","clk":"1004169889","pt":1580653716610,"mc":[{"id":"1.168224028","rc":[{"batl":[[0,5.3,9.24],[1,5.5,14.4],[2,5.6,13.69]],"ltp":0.0,"tv":0.0,"id":17467775},{"batb":[[1,2.08,122.93]],"batl":[[1,2.32,31.09],[2,2.42,18.49]],"ltp":2.96,"tv":347.89,"id":17467774},{"batb":[[0,6.6,45.75]],"batl":[[1,8.2,5.04],[2,9.4,9.44]],"ltp":7.0,"tv":13.44,"id":16775228},{"batb":[[2,4.5,11.76]],"batl":[[0,5.4,9.24],[1,5.6,13.85]],"ltp":0.0,"tv":0.0,"id":16775230}]}]}
{"op":"mcm","clk":"1004172660","pt":1580653730934,"mc":[{"id":"1.168224028","rc":[{"batb":[[0,4.7,52.28],[1,4.5,11.76],[2,1.01,0.51]],"batl":[[1,5.6,13.69],[2,5.6,0]],"ltp":0.0,"tv":0.0,"id":17467775},{"batb":[[0,2.08,38.65],[1,1.94,15.42],[2,1.01,0.51]],"batl":[[0,2.32,31.09],[1,2.42,18.49],[2,2.42,0]],"ltp":2.96,"tv":347.89,"id":17467774},{"batb":[[0,6.6,6.72],[1,5.1,13.14],[2,1.01,0.51]],"batl":[[0,8.2,5.04],[1,9.4,9.44],[2,9.4,0]],"ltp":7.0,"tv":13.44,"id":16775228}]}]}
{"op":"mcm","clk":"1004172771","pt":1580653731538,"mc":[{"id":"1.168224028","rc":[{"batb":[[1,1.01,0.51],[2,1.01,0]],"batl":[[0,5.6,13.69],[1,5.6,0]],"ltp":0.0,"tv":0.0,"id":17467775},{"batb":[[0,1.94,15.42],[1,1.01,0.51],[2,1.01,0]],"batl":[[0,2.42,18.49],[1,2.42,0]],"ltp":2.96,"tv":347.89,"id":17467774},{"batb":[[0,5.1,13.14],[1,1.01,0.51],[2,1.01,0]],"batl":[[0,9.4,9.44],[1,9.4,0]],"ltp":7.0,"tv":13.44,"id":16775228},{"batb":[[2,1.01,0.51]],"batl":[[0,5.6,13.85],[1,5.6,0]],"ltp":0.0,"tv":0.0,"id":16775230}]}]}
{"op":"mcm","clk":"1004173242","pt":1580653734097,"mc":[{"id":"1.168224028","rc":[{"batb":[[0,4.7,15.89]],"ltp":0.0,"tv":0.0,"id":17467775},{"batb":[[0,1.96,83.98],[1,1.94,88.77],[2,1.01,0.51]],"ltp":2.96,"tv":347.89,"id":17467774}]}]}
{"op":"mcm","clk":"1004173977","pt":1580653737799,"mc":[{"id":"1.168224028","rc":[{"batb":[[0,5,14.32],[1,4.9,37.7],[2,4.8,50.05]],"batl":[[1,5.8,12.98]],"ltp":0.0,"tv":0.0,"id":17467775},{"batb":[[2,1.83,18.49]],"batl":[[0,2.04,29.98],[1,2.22,23.68]],"ltp":2.96,"tv":347.89,"id":17467774},{"batb":[[0,8.2,34.44],[1,8,22.82],[2,7.8,9.91]],"batl":[[1,12.5,13.45]],"ltp":7.0,"tv":13.44,"id":16775228},{"batb":[[0,5,37.36],[1,4.9,48.59]],"ltp":0.0,"tv":0.0,"id":16775230}]}]}
{"op":"mcm","clk":"1004174238","pt":1580653739102,"mc":[{"id":"1.168224028","rc":[{"batl":[[0,5.4,9.24],[1,5.6,13.69],[2,5.8,12.98]],"ltp":0.0,"tv":0.0,"id":17467775},{"batb":[[0,1.96,127.67]],"batl":[[1,2.18,35.29],[2,2.22,23.68]],"ltp":2.96,"tv":347.89,"id":17467774},{"batb":[[1,8,28.7]],"batl":[[1,10,4.2],[2,12.5,13.45]],"ltp":7.0,"tv":13.44,"id":16775228},{"batb":[[2,4.5,11.76]],"batl":[[0,5.4,9.24],[1,5.6,13.85]],"ltp":0.0,"tv":0.0,"id":16775230}]}]}
{"op":"mcm","clk":"1004176933","pt":1580653751116,"mc":[{"id":"1.168224028","rc":[{"batb":[[0,4.8,50.05],[1,4.5,11.76],[2,1.01,0.51]],"batl":[[1,5.8,12.98],[2,5.8,0]],"ltp":0.0,"tv":0.0,"id":17467775},{"batb":[[0,1.96,43.69],[1,1.83,18.49],[2,1.01,0.51]],"batl":[[0,2.18,35.29],[1,2.22,23.68],[2,2.22,0]],"ltp":2.96,"tv":347.89,"id":17467774},{"batb":[[0,8,5.88],[1,6.2,17.15],[2,1.01,0.51]],"batl":[[0,10,4.2],[1,12.5,13.45],[2,12.5,0]],"ltp":7.0,"tv":13.44,"id":16775228},{"batb":[[0,5,22.77]],"ltp":0.0,"tv":0.0,"id":16775230}]}]}
{"op":"mcm","clk":"1004177034","pt":1580653751503,"mc":[{"id":"1.168224028","rc":[{"batb":[[1,1.01,0.51],[2,1.01,0]],"batl":[[0,5.8,12.98],[1,5.8,0]],"ltp":0.0,"tv":0.0,"id":17467775},{"batb":[[0,1.83,18.49],[1,1.01,0.51],[2,1.01,0]],"batl":[[0,2.22,23.68],[1,2.22,0]],"ltp":2.96,"tv":347.89,"id":17467774},{"batb":[[0,6.2,17.15],[1,1.01,0.51],[2,1.01,0]],"batl":[[0,12.5,13.45],[1,12.5,0]],"ltp":7.0,"tv":13.44,"id":16775228},{"batb":[[2,1.01,0.51]],"batl":[[0,5.6,13.85],[1,5.6,0]],"ltp":0.0,"tv":0.0,"id":16775230}]}]}
{"op":"mcm","clk":"1004177570","pt":1580653754092,"mc":[{"id":"1.168224028","rc":[{"batb":[[1,4.7,36.63],[2,1.01,0.51]],"ltp":0.0,"tv":0.0,"id":17467775},{"batb":[[0,1.87,59.75],[1,1.85,85.2],[2,1.83,18.49]],"ltp":2.96,"tv":347.89,"id":17467774},{"batb":[[0,6.4,32.45],[1,6.2,57.01],[2,1.01,0.51]],"ltp":7.0,"tv":13.44,"id":16775228}]}]}
{"op":"mcm","clk":"1004177728","pt":1580653754906,"mc":[{"id":"1.168224028","rc":[{"batb":[[1,1.01,0.51],[2,1.01,0]],"ltp":0.0,"tv":0.0,"id":17467775},{"batb":[[0,1.83,18.49],[1,1.01,0.51],[2,1.83,0]],"ltp":2.96,"tv":347.89,"id":17467774},{"batb":[[0,6.2,17.15],[1,1.01,0.51],[2,1.01,0]],"ltp":7.0,"tv":13.44,"id":16775228}]}]}
{"op":"mcm","clk":"1004178548","pt":1580653758596,"mc":[{"id":"1.168224028","rc":[{"batb":[[0,4.9,31.4],[1,4.8,50.05],[2,1.01,0.51]],"ltp":0.0,"tv":0.0,"id":17467775},{"batb":[[0,2,50.95],[1,1.98,68.9],[2,1.83,18.49]],"ltp":2.96,"tv":347.89,"id":17467774},{"batb":[[0,7.8,29.44],[1,7.6,25.62],[2,6.2,17.15]],"ltp":7.0,"tv":13.44,"id":16775228},{"batb":[[0,5,34.47]],"ltp":0.0,"tv":0.0,"id":16775230}]}]}
{"op":"mcm","clk":"1004178965","pt":1580653760485,"mc":[{"id":"1.168224028","rc":[{"batb":[[0,4.8,50.05],[1,1.01,0.51],[2,1.01,0]],"ltp":0.0,"tv":0.0,"id":17467775},{"batb":[[0,1.83,18.49],[1,1.01,0.51],[2,1.83,0]],"ltp":2.96,"tv":347.89,"id":17467774},{"batb":[[0,6.2,17.15],[1,1.01,0.51],[2,6.2,0]],"ltp":7.0,"tv":13.44,"id":16775228},{"batb":[[0,5,22.77]],"ltp":0.0,"tv":0.0,"id":16775230}]}]}
{"op":"mcm","clk":"1004179595","pt":1580653763427,"mc":[{"id":"1.168224028","rc":[{"batb":[[1,4.7,36.63],[2,1.01,0.51]],"ltp":0.0,"tv":0.0,"id":17467775},{"batb":[[0,1.87,59.75],[1,1.85,85.2],[2,1.83,18.49]],"ltp":2.96,"tv":347.89,"id":17467774},{"batb":[[0,6.4,32.45],[1,6.2,57.01],[2,1.01,0.51]],"ltp":7.0,"tv":13.44,"id":16775228}]}]}
{"op":"mcm","clk":"1004181818","pt":1580653774048,"mc":[{"id":"1.168224028","rc":[{"batb":[[1,1.01,0.51],[2,1.01,0]],"ltp":0.0,"tv":0.0,"id":17467775},{"batb":[[0,1.83,18.49],[1,1.01,0.51],[2,1.83,0]],"ltp":2.96,"tv":347.89,"id":17467774},{"batb":[[0,6.2,17.15],[1,1.01,0.51],[2,1.01,0]],"ltp":7.0,"tv":13.44,"id":16775228}]}]}
{"op":"mcm","clk":"1004182410","pt":1580653776907,"mc":[{"id":"1.168224028","rc":[{"batb":[[0,4.9,37.7],[1,4.8,50.05],[2,1.01,0.51]],"ltp":0.0,"tv":0.0,"id":17467775},{"batb":[[0,1.96,83.98],[1,1.94,73.35],[2,1.83,18.49]],"ltp":2.96,"tv":347.89,"id":17467774},{"batb":[[0,8.2,34.44],[1,8,22.82],[2,6.2,17.15]],"ltp":7.0,"tv":13.44,"id":16775228},{"batb":[[0,5,37.36]],"ltp":0.0,"tv":0.0,"id":16775230}]}]}
{"op":"mcm","clk":"1004183388","pt":1580653781608,"mc":[{"id":"1.168224028","rc":[{"batl":[[0,2.2,230.38],[1,2.22,23.68]],"ltp":2.96,"tv":347.89,"id":17467774},{"batl":[[0,11.5,237.63],[1,12.5,13.45]],"ltp":7.0,"tv":13.44,"id":16775228}]}]}
{"op":"mcm","clk":"1004183632","pt":1580653782830,"mc":[{"id":"1.168224028","rc":[{"batb":[[0,4.8,50.05],[1,1.01,0.51],[2,1.01,0]],"ltp":0.0,"tv":0.0,"id":17467775},{"batb":[[0,1.83,18.49],[1,1.01,0.51],[2,1.83,0]],"batl":[[0,2.22,23.68],[1,2.22,0]],"ltp":2.96,"tv":347.89,"id":17467774},{"batb":[[0,6.2,17.15],[1,1.01,0.51],[2,6.2,0]],"batl":[[0,12.5,13.45],[1,12.5,0]],"ltp":7.0,"tv":13.44,"id":16775228},{"batb":[[0,5,22.77]],"ltp":0.0,"tv":0.0,"id":16775230}]}]}
{"op":"mcm","clk":"1004184248","pt":1580653786030,"mc":[{"id":"1.168224028","rc":[{"batb":[[1,4.7,36.63],[2,1.01,0.51]],"ltp":0.0,"tv":0.0,"id":17467775},{"batb":[[0,1.87,59.75],[1,1.85,85.2],[2,1.83,18.49]],"ltp":2.96,"tv":347.89,"id":17467774},{"batb":[[0,6.4,32.45],[1,6.2,57.01],[2,1.01,0.51]],"ltp":7.0,"tv":13.44,"id":16775228}]}]}
{"op":"mcm","clk":"1004184810","pt":1580653789034,"mc":[{"id":"1.168224028","rc":[{"batb":[[0,4.8,15.11],[1,1.01,0.51],[2,1.01,0]],"ltp":0.0,"tv":0.0,"id":17467775},{"batb":[[0,6.2,17.15],[1,1.01,0.51],[2,1.01,0]],"ltp":7.0,"tv":13.44,"id":16775228}]}]}
{"op":"mcm","clk":"1004185328","pt":1580653791944,"mc":[{"id":"1.168224028","rc":[{"batb":[[0,5,24.92],[1,4.9,33.52],[2,4.8,15.11]],"ltp":0.0,"tv":0.0,"id":17467775},{"batb":[[0,10,44.06],[1,9.8,14.54],[2,6.2,17.15]],"ltp":7.0,"tv":13.44,"id":16775228},{"batb":[[0,5,47.04]],"ltp":0.0,"tv":0.0,"id":16775230}]}]}
{"op":"mcm","clk":"1004185500","pt":1580653792929,"mc":[{"id":"1.168224028","rc":[{"batb":[[0,5.1,13.53],[1,5,39.24],[2,4.9,33.52]],"batl":[[0,5.5,9.24],[1,5.8,12.98],[2,5.9,12.35]],"ltp":0.0,"tv":0.0,"id":17467775},{"batb":[[0,1.87,107.64]],"batl":[[0,1.91,18.18],[1,2.02,30.69],[2,2.08,38.65]],"ltp":2.96,"tv":347.89,"id":17467774},{"batb":[[1,9.8,29.41],[2,9.6,4.2]],"batl":[[0,12.5,16.82],[1,16,8.89]],"ltp":7.0,"tv":13.44,"id":16775228},{"batb":[[2,4.6,10.92]],"batl":[[0,5.5,9.24],[1,5.6,13.85],[2,5.7,13.14]],"ltp":0.0,"tv":0.0,"id":16775230}]}]}
{"op":"mcm","clk":"1004185752","pt":1580653794042,"mc":[{"id":"1.168224028","rc":[{"batl":[[2,2.08,0]],"ltp":2.96,"tv":347.89,"id":17467774}]}]}
{"op":"mcm","clk":"1004186165","pt":1580653796236,"mc":[{"id":"1.168224028","rc":[{"trd":[[1.91,18.48]],"batl":[[0,1.91,8.93],[2,2.06,39.49]],"ltp":1.91,"tv":366.38,"id":17467774}],"tv":379.82}]}
{"op":"mcm","clk":"1004188819","pt":1580653808808,"mc":[{"id":"1.168224028","rc":[{"batb":[[0,5,14.32],[1,4.9,33.52],[2,4.6,10.92]],"batl":[[1,5.9,12.35],[2,5.9,0]],"ltp":0.0,"tv":0.0,"id":17467775},{"batb":[[0,1.87,47.89],[1,1.75,21.48],[2,1.01,0.51]],"batl":[[0,2.02,30.69],[1,2.06,39.49],[2,2.06,0]],"ltp":1.91,"tv":366.38,"id":17467774},{"batb":[[0,9.6,4.2],[1,8.2,9.05],[2,1.01,0.51]],"batl":[[0,12.5,3.36]],"ltp":7.0,"tv":13.44,"id":16775228},{"batb":[[0,5,22.77]],"batl":[[1,5.7,13.14],[2,5.7,0]],"ltp":0.0,"tv":0.0,"id":16775230}]}]}
{"op":"mcm","clk":"1004189000","pt":1580653810047,"mc":[{"id":"1.168224028","rc":[{"batb":[[2,1.01,0.51]],"batl":[[0,5.9,12.35],[1,5.9,0]],"ltp":0.0,"tv":0.0,"id":17467775},{"batb":[[0,1.75,21.48],[1,1.01,0.51],[2,1.01,0]],"batl":[[1,2.06,0]],"ltp":1.91,"tv":366.38,"id":17467774},{"batb":[[0,8.2,9.05],[1,1.01,0.51],[2,1.01,0]],"batl":[[0,16,8.89],[1,16,0]],"ltp":7.0,"tv":13.44,"id":16775228},{"batb":[[2,1.01,0.51]],"batl":[[0,5.7,13.14],[1,5.7,0]],"ltp":0.0,"tv":0.0,"id":16775230}]}]}
{"op":"mcm","clk":"1004189460","pt":1580653812093,"mc":[{"id":"1.168224028","rc":[{"batb":[[0,4.9,47.92],[1,4.8,34.94]],"ltp":0.0,"tv":0.0,"id":17467775},{"batb":[[0,1.81,80.48],[1,1.79,95],[2,1.76,21.32]],"batl":[[0,2.04,30.21]],"ltp":1.91,"tv":366.38,"id":17467774},{"batb":[[0,8.6,19.25],[1,8.4,20.85],[2,8.2,9.05]],"batl":[[0,15.5,8.97]],"ltp":7.0,"tv":13.44,"id":16775228}]}]}
{"op":"mcm","clk":"1004191171","pt":1580653821880,"mc":[{"id":"1.168224028","rc":[{"batb":[[0,1.76,21.32],[1,1.01,0.51],[2,1.76,0]],"ltp":1.91,"tv":366.38,"id":17467774}]}]}
{"op":"mcm","clk":"1004191708","pt":1580653825002,"mc":[{"id":"1.168224028","rc":[{"batb":[[2,4.5,11.76]],"batl":[[0,5.4,9.24],[1,5.9,12.35]],"ltp":0.0,"tv":0.0,"id":17467775},{"batb":[[0,1.96,60.48],[1,1.95,43.69],[2,1.94,73.35]],"batl":[[1,2.16,36.13]],"ltp":1.91,"tv":366.38,"id":17467774},{"batb":[[1,8.4,25.89]],"batl":[[0,10.5,4.2],[1,15.5,8.97]],"ltp":7.0,"tv":13.44,"id":16775228},{"batb":[[2,4.5,11.76]],"batl":[[0,5.4,9.24],[1,5.7,13.14]],"ltp":0.0,"tv":0.0,"id":16775230}]}]}
{"op":"mcm","clk":"1004191897","pt":1580653825975,"mc":[{"id":"1.168224028","rc":[{"batb":[[1,4.8,50.13]],"batl":[[1,5.6,13.77],[2,5.7,13.06]],"ltp":0.0,"tv":0.0,"id":17467775},{"batb":[[0,1.95,43.69],[1,1.94,15.58],[2,1.81,19.36]],"batl":[[2,2.24,23.05]],"ltp":1.91,"tv":366.38,"id":17467774},{"batl":[[0,9.8,8.66],[1,10.5,4.2],[2,14.5,10.46]],"ltp":7.0,"tv":13.44,"id":16775228},{"batb":[[1,4.9,33.96],[2,4.8,15.03]],"batl":[[1,5.5,14.24]],"ltp":0.0,"tv":0.0,"id":16775230}]}]}
{"op":"mcm","clk":"1004192410","pt":1580653828760,"mc":[{"id":"1.168224028","rc":[{"batb":[[0,1.95,104.6],[2,1.93,74.51]],"ltp":1.91,"tv":366.38,"id":17467774},{"batb":[[0,8.6,30.09]],"ltp":7.0,"tv":13.44,"id":16775228},{"batb":[[0,5,41.18]],"ltp":0.0,"tv":0.0,"id":16775230}]}]}
{"op":"mcm","clk":"1004195401","pt":1580653845515,"mc":[{"id":"1.168224028","rc":[{"batb":[[0,4.8,50.13],[1,1.01,0.51],[2,4.5,0]],"batl":[[0,5.7,13.06],[1,5.6,0],[2,5.7,0]],"ltp":0.0,"tv":0.0,"id":17467775},{"batb":[[0,1.81,19.36],[1,1.01,0.51],[2,1.93,0]],"batl":[[0,2.24,23.05],[1,2.16,0],[2,2.24,0]],"ltp":1.91,"tv":366.38,"id":17467774},{"batb":[[0,6,17.62],[1,1.01,0.51],[2,8.2,0]],"batl":[[0,14.5,10.46],[1,10.5,0],[2,14.5,0]],"ltp":7.0,"tv":13.44,"id":16775228},{"batb":[[0,5,31.98]],"batl":[[0,5.5,14.24],[1,5.5,0]],"ltp":0.0,"tv":0.0,"id":16775230}]}]}
{"op":"mcm","clk":"1004195864","pt":1580653848025,"mc":[{"id":"1.168224028","rc":[{"batb":[[1,4.7,36.69],[2,1.01,0.51]],"ltp":0.0,"tv":0.0,"id":17467775},{"batb":[[0,1.84,62.27],[1,1.82,89.9],[2,1.81,19.36]],"ltp":1.91,"tv":366.38,"id":17467774},{"batb":[[0,6.4,23.88],[1,6.2,40.49],[2,6,17.62]],"ltp":7.0,"tv":13.44,"id":16775228}]}]}
{"op":"mcm","clk":"1004195929","pt":1580653848290,"mc":[{"id":"1.168224028","rc":[{"batb":[[1,1.01,0.51],[2,1.01,0]],"ltp":0.0,"tv":0.0,"id":17467775},{"batb":[[0,1.81,19.36],[1,1.01,0.51],[2,1.81,0]],"ltp":1.91,"tv":366.38,"id":17467774},{"batb":[[0,6,17.62],[1,1.01,0.51],[2,6,0]],"ltp":7.0,"tv":13.44,"id":16775228}]}]}
{"op":"mcm","clk":"1004196379","pt":1580653850517,"mc":[{"id":"1.168224028","rc":[{"batb":[[0,4.9,21.82],[1,4.8,50.13],[2,1.01,0.51]],"ltp":0.0,"tv":0.0,"id":17467775},{"batb":[[0,1.98,77.37],[1,1.96,71.04],[2,1.81,19.36]],"ltp":1.91,"tv":366.38,"id":17467774},{"batb":[[0,8,34.75],[1,7.8,24.36],[2,6,17.62]],"ltp":7.0,"tv":13.44,"id":16775228},{"batb":[[0,5,39.37]],"ltp":0.0,"tv":0.0,"id":16775230}]}]}
{"op":"mcm","clk":"1004197038","pt":1580653854153,"mc":[{"id":"1.168224028","rc":[{"batb":[[0,4.8,50.13],[1,1.01,0.51],[2,1.01,0]],"ltp":0.0,"tv":0.0,"id":17467775},{"batb":[[0,1.81,19.36],[1,1.01,0.51],[2,1.81,0]],"ltp":1.91,"tv":366.38,"id":17467774},{"batb":[[0,6,17.62],[1,1.01,0.51],[2,6,0]],"ltp":7.0,"tv":13.44,"id":16775228},{"batb":[[0,5,32.28]],"ltp":0.0,"tv":0.0,"id":16775230}]}]}
{"op":"mcm","clk":"1004197574","pt":1580653857015,"mc":[{"id":"1.168224028","rc":[{"batb":[[1,4.7,36.69],[2,1.01,0.51]],"ltp":0.0,"tv":0.0,"id":17467775},{"batb":[[0,1.84,61.7],[1,1.82,89.9],[2,1.81,19.36]],"ltp":1.91,"tv":366.38,"id":17467774},{"batb":[[0,6.4,24.11],[1,6.2,40.49],[2,6,17.62]],"ltp":7.0,"tv":13.44,"id":16775228}]}]}
{"op":"mcm","clk":"1004198859","pt":1580653863850,"mc":[{"id":"1.168224028","rc":[{"batb":[[1,1.01,0.51],[2,1.01,0]],"ltp":0.0,"tv":0.0,"id":17467775},{"batb":[[0,6,17.62],[1,1.01,0.51],[2,6,0]],"ltp":7.0,"tv":13.44,"id":16775228}]}]}
{"op":"mcm","clk":"1004199420","pt":1580653866859,"mc":[{"id":"1.168224028","rc":[{"batb":[[0,5.1,13.61],[1,4.9,66.81],[2,4.8,50.13]],"batl":[[0,5.5,9.24],[1,5.7,13.06],[2,5.9,12.43]],"ltp":0.0,"tv":0.0,"id":17467775},{"batb":[[0,1.84,111.27]],"batl":[[0,1.88,19.04],[1,1.97,16.44],[2,2.04,40.33]],"ltp":1.91,"tv":366.38,"id":17467774},{"batb":[[0,11.5,18.49],[1,11,40.31],[2,10.5,4.2]],"batl":[[1,19.5,5.98]],"ltp":7.0,"tv":13.44,"id":16775228},{"batb":[[0,5,47.75],[1,4.9,48.83]],"batl":[[0,5.5,23.48],[1,5.6,13.53]],"ltp":0.0,"tv":0.0,"id":16775230}]}]}
{"op":"mcm","clk":"1004199595","pt":1580653867838,"mc":[{"id":"1.168224028","rc":[{"batb":[[2,4.8,34.94]],"ltp":0.0,"tv":0.0,"id":17467775}]}]}
{"op":"mcm","clk":"1004204732","pt":1580653892608,"mc":[{"id":"1.168224028","rc":[{"batb":[[0,4.9,46.6],[1,4.8,34.94],[2,4.6,10.92]],"batl":[[1,5.9,12.43],[2,5.9,0]],"ltp":0.0,"tv":0.0,"id":17467775},{"batb":[[0,1.84,49.57],[1,1.72,22.74],[2,1.01,0.51]],"batl":[[0,1.97,16.44],[1,2.04,40.33],[2,2.04,0]],"ltp":1.91,"tv":366.38,"id":17467774},{"batb":[[0,10.5,4.2],[1,9.2,7],[2,1.01,0.51]],"batl":[[0,19.5,5.98],[1,19.5,0]],"ltp":7.0,"tv":13.44,"id":16775228},{"batb":[[0,5,24.32],[1,4.9,33.96]],"batl":[[0,5.5,9.24]],"ltp":0.0,"tv":0.0,"id":16775230}]}]}
{"op":"mcm","clk":"1004204947","pt":1580653893617,"mc":[{"id":"1.168224028","rc":[{"batb":[[2,1.01,0.51]],"batl":[[0,5.9,12.43],[1,5.9,0]],"ltp":0.0,"tv":0.0,"id":17467775},{"batb":[[0,1.72,22.74],[1,1.01,0.51],[2,1.01,0]],"batl":[[1,2.04,0]],"ltp":1.91,"tv":366.38,"id":17467774},{"batb":[[0,9.2,7],[1,1.01,0.51],[2,1.01,0]],"ltp":7.0,"tv":13.44,"id":16775228},{"batl":[[0,5.6,13.53],[1,5.6,0]],"ltp":0.0,"tv":0.0,"id":16775230}]}]}
{"op":"mcm","clk":"1004205270","pt":1580653895107,"mc":[{"id":"1.168224028","rc":[{"batb":[[0,1.76,60.17],[1,1.74,104.27],[2,1.72,22.74]],"ltp":1.91,"tv":366.38,"id":17467774},{"batb":[[0,9.8,25.42],[1,9.6,15.73],[2,9.2,7]],"ltp":7.0,"tv":13.44,"id":16775228}]}]}
{"op":"mcm","clk":"1004206293","pt":1580653900118,"mc":[{"id":"1.168224028","rc":[{"batb":[[1,1.01,0.51],[2,1.01,0]],"ltp":0.0,"tv":0.0,"id":17467775},{"batb":[[0,9.2,7],[1,1.01,0.51],[2,9.2,0]],"ltp":7.0,"tv":13.44,"id":16775228},{"batb":[[1,4.8,15.03],[2,1.01,0.51]],"ltp":0.0,"tv":0.0,"id":16775230}]}]}
{"op":"mcm","clk":"1004206818","pt":1580653902739,"mc":[{"id":"1.168224028","rc":[{"batb":[[0,5,45.28],[1,4.9,46.6],[2,1.01,0.51]],"ltp":0.0,"tv":0.0,"id":17467775},{"batb":[[0,15,7.09],[1,14.5,16.62],[2,9.2,7]],"ltp":7.0,"tv":13.44,"id":16775228},{"batb":[[0,5.1,44.38],[1,5,32.81],[2,4.8,15.03]],"ltp":0.0,"tv":0.0,"id":16775230}]}]}
{"op":"mcm","clk":"1004207134","pt":1580653904111,"mc":[{"id":"1.168224028","rc":[{"batb":[[0,5.2,12.9],[1,5.1,13.69],[2,5,45.28]],"batl":[[1,6,11.8]],"ltp":0.0,"tv":0.0,"id":17467775},{"batl":[[0,1.79,22.35],[1,1.89,18.96]],"ltp":1.91,"tv":366.38,"id":17467774},{"batb":[[2,14,6.37]],"ltp":7.0,"tv":13.44,"id":16775228},{"batb":[[1,5,46.97],[2,4.9,15.03]],"batl":[[1,5.8,12.9]],"ltp":0.0,"tv":0.0,"id":16775230}]}]}
{"op":"mcm","clk":"1004207272","pt":1580653904807,"mc":[{"id":"1.168224028","rc":[{"batl":[[0,5.5,9.24],[1,5.9,12.43],[2,6,11.8]],"ltp":0.0,"tv":0.0,"id":17467775},{"batb":[[0,1.78,53.77],[1,1.76,60.17],[2,1.74,104.27]],"ltp":1.91,"tv":366.38,"id":17467774},{"batl":[[0,5.6,21.94]],"ltp":0.0,"tv":0.0,"id":16775230}]}]}
{"op":"mcm","clk":"1004207821","pt":1580653907506,"mc":[{"id":"1.168224028","rc":[{"trd":[[1.79,43.69]],"batl":[[0,1.89,19.46],[1,1.92,42.01]],"ltp":1.79,"tv":410.07,"id":17467774}],"tv":423.51}]}
{"op":"mcm","clk":"1004209249","pt":1580653915046,"mc":[{"id":"1.168224028","rc":[{"batb":[[2,5,21.42]],"ltp":0.0,"tv":0.0,"id":17467775},{"batb":[[1,1.72,22.74],[2,1.64,26.67]],"ltp":1.79,"tv":410.07,"id":17467774},{"batb":[[0,14,6.37],[1,13,3.36],[2,11,11.25]],"ltp":7.0,"tv":13.44,"id":16775228},{"batb":[[0,5.1,19.98]],"ltp":0.0,"tv":0.0,"id":16775230}]}]}
{"op":"mcm","clk":"1004209426","pt":1580653915940,"mc":[{"id":"1.168224028","rc":[{"batb":[[0,5.1,13.69],[1,5,21.42],[2,4.9,32.2]],"batl":[[0,6,11.8],[1,5.9,0],[2,6,0]],"ltp":0.0,"tv":0.0,"id":17467775},{"batb":[[0,1.64,26.67],[1,1.01,0.51],[2,1.64,0]],"batl":[[0,1.89,18.96],[1,1.92,0]],"ltp":1.79,"tv":410.07,"id":17467774},{"batb":[[0,11,11.25],[1,1.01,0.51],[2,11,0]],"ltp":7.0,"tv":13.44,"id":16775228},{"batb":[[1,5,32.81]],"batl":[[0,5.8,12.9],[1,5.8,0]],"ltp":0.0,"tv":0.0,"id":16775230}]}]}
{"op":"mcm","clk":"1004209836","pt":1580653918071,"mc":[{"id":"1.168224028","rc":[{"batb":[[0,1.67,115.47],[1,1.66,61.91],[2,1.64,26.67]],"ltp":1.79,"tv":410.07,"id":17467774},{"batb":[[0,12,10.21],[1,11.5,26.68],[2,11,11.25]],"ltp":7.0,"tv":13.44,"id":16775228}]}]}
{"op":"mcm","clk":"1004209913","pt":1580653918448,"mc":[{"id":"1.168224028","rc":[{"batb":[[0,5,35.27],[1,4.9,32.2],[2,1.01,0.51]],"ltp":0.0,"tv":0.0,"id":17467775},{"batb":[[0,1.65,26.2],[1,1.01,0.51],[2,1.64,0]],"batl":[[0,1.9,18.57]],"ltp":1.79,"tv":410.07,"id":17467774},{"batb":[[0,11,11.25],[1,1.01,0.51],[2,11,0]],"batl":[[0,30,5.67]],"ltp":7.0,"tv":13.44,"id":16775228},{"batb":[[2,4.8,15.26]],"batl":[[0,5.7,13.14]],"ltp":0.0,"tv":0.0,"id":16775230}]}]}
{"op":"mcm","clk":"1004210369","pt":1580653920751,"mc":[{"id":"1.168224028","rc":[{"batb":[[0,5,65.29]],"ltp":0.0,"tv":0.0,"id":17467775},{"batb":[[0,1.74,77.07],[1,1.72,108.53],[2,1.65,26.2]],"ltp":1.79,"tv":410.07,"id":17467774},{"batb":[[0,16,7.14],[1,15.5,14.49],[2,11,11.25]],"ltp":7.0,"tv":13.44,"id":16775228},{"batb":[[0,5.1,50.62]],"ltp":0.0,"tv":0.0,"id":16775230}]}]}
{"op":"mcm","clk":"1004210656","pt":1580653922244,"mc":[{"id":"1.168224028","rc":[{"batb":[[0,5,35.27]],"ltp":0.0,"tv":0.0,"id":17467775},{"batb":[[0,1.65,26.2],[1,1.01,0.51],[2,1.65,0]],"ltp":1.79,"tv":410.07,"id":17467774},{"batb":[[0,11,11.25],[1,1.01,0.51],[2,11,0]],"ltp":7.0,"tv":13.44,"id":16775228},{"batb":[[0,5.1,19.98]],"ltp":0.0,"tv":0.0,"id":16775230}]}]}
{"op":"mcm","clk":"1004211339","pt":1580653925224,"mc":[{"id":"1.168224028","rc":[{"batb":[[0,1.67,115.47],[1,1.66,61.91],[2,1.65,26.2]],"ltp":1.79,"tv":410.07,"id":17467774},{"batb":[[0,12,10.21],[1,11.5,26.68],[2,11,11.25]],"ltp":7.0,"tv":13.44,"id":16775228}]}]}
{"op":"mcm","clk":"1004214581","pt":1580653942461,"mc":[{"id":"1.168224028","rc":[{"batb":[[1,1.01,0.51],[2,1.01,0]],"ltp":0.0,"tv":0.0,"id":17467775},{"batb":[[0,11,11.25],[1,1.01,0.51],[2,11,0]],"ltp":7.0,"tv":13.44,"id":16775228},{"batb":[[1,4.8,15.26],[2,1.01,0.51]],"ltp":0.0,"tv":0.0,"id":16775230}]}]}
{"op":"mcm","clk":"1004215237","pt":1580653946082,"mc":[{"id":"1.168224028","rc":[{"batb":[[0,5.2,12.51],[1,5.1,56.98],[2,5,31.56]],"batl":[[1,6.2,11.25]],"ltp":0.0,"tv":0.0,"id":17467775},{"batl":[[0,1.72,25.65],[1,1.8,22.03]],"ltp":1.79,"tv":410.07,"id":17467774},{"batb":[[0,22,4.64],[1,21,15.29],[2,19,6.22]],"ltp":7.0,"tv":13.44,"id":16775228},{"batb":[[0,5.2,43.22],[1,5.1,31.38],[2,5,13.69]],"batl":[[1,5.9,12.35]],"ltp":0.0,"tv":0.0,"id":16775230}]}]}
{"op":"mcm","clk":"1004215370","pt":1580653946788,"mc":[{"id":"1.168224028","rc":[{"batl":[[0,5.6,8.4],[1,6,11.8],[2,6.2,11.25]],"ltp":0.0,"tv":0.0,"id":17467775},{"batb":[[0,1.71,58.81],[1,1.67,115.47],[2,1.66,61.91]],"batl":[[2,1.85,42.01]],"ltp":1.79,"tv":410.07,"id":17467774},{"batl":[[0,5.6,8.4],[1,5.7,13.14],[2,5.9,12.35]],"ltp":0.0,"tv":0.0,"id":16775230}]}]}
{"op":"mcm","clk":"1004215851","pt":1580653949380,"mc":[{"id":"1.168224028","rc":[{"trd":[[1.72,50.41]],"batl":[[0,1.8,22.47],[1,1.85,42.01],[2,1.85,0]],"ltp":1.72,"tv":460.48,"id":17467774}],"tv":473.93}]}
{"op":"mcm","clk":"1004217283","pt":1580653957387,"mc":[{"id":"1.168224028","rc":[{"batb":[[1,1.67,90.65]],"ltp":1.72,"tv":460.48,"id":17467774},{"batb":[[0,5.2,30.49],[1,5,13.69],[2,4.9,14.63]],"ltp":0.0,"tv":0.0,"id":16775230}]}]}
{"op":"mcm","clk":"1004217823","pt":1580653960421,"mc":[{"id":"1.168224028","rc":[{"batb":[[0,22,7.51]],"ltp":7.0,"tv":13.44,"id":16775228},{"batb":[[0,5.3,26.35],[1,5.2,30.49],[2,5,13.69]],"ltp":0.0,"tv":0.0,"id":16775230}]}]}
{"op":"mcm","clk":"1004219044","pt":1580653967123,"mc":[{"id":"1.168224028","rc":[{"batl":[[1,1.85,0]],"ltp":1.72,"tv":460.48,"id":17467774}]}]}
{"op":"mcm","clk":"1004219205","pt":1580653967826,"mc":[{"id":"1.168224028","rc":[{"batb":[[0,5.1,13.3],[1,5,31.56],[2,1.01,0.51]],"batl":[[0,6.2,11.25],[1,6,0],[2,6.2,0]],"ltp":0.0,"tv":0.0,"id":17467775},{"batb":[[0,1.58,30.53],[1,1.01,0.51],[2,1.66,0]],"batl":[[0,1.8,22.03]],"ltp":1.72,"tv":460.48,"id":17467774},{"batb":[[0,14.5,5.74],[1,1.01,0.51],[2,19,0]],"ltp":7.0,"tv":13.44,"id":16775228},{"batb":[[0,5.2,30.49],[1,4.9,14.63],[2,1.01,0.51]],"batl":[[0,5.9,12.35],[1,5.7,0],[2,5.9,0]],"ltp":0.0,"tv":0.0,"id":16775230}]}]}
{"op":"mcm","clk":"1004219719","pt":1580653970627,"mc":[{"id":"1.168224028","rc":[{"batb":[[0,5,45.17],[1,1.01,0.51],[2,1.01,0]],"ltp":0.0,"tv":0.0,"id":17467775},{"batb":[[0,1.59,29.9]],"batl":[[0,1.82,21.56]],"ltp":1.72,"tv":460.48,"id":17467774},{"batb":[[1,4.8,14.95]],"batl":[[0,5.8,12.59]],"ltp":0.0,"tv":0.0,"id":16775230}]}]}
{"op":"mcm","clk":"1004220136","pt":1580653973007,"mc":[{"id":"1.168224028","rc":[{"batb":[[0,5.1,46.1],[1,5,45.17],[2,1.01,0.51]],"ltp":0.0,"tv":0.0,"id":17467775},{"batb":[[0,1.66,63.45],[1,1.65,63.17],[2,1.59,29.9]],"ltp":1.72,"tv":460.48,"id":17467774},{"batb":[[0,24,7.32],[1,23,12.72],[2,14.5,5.74]],"ltp":7.0,"tv":13.44,"id":16775228},{"batb":[[0,5.3,33.3],[1,5.2,30.49],[2,4.8,14.95]],"ltp":0.0,"tv":0.0,"id":16775230}]}]}
{"op":"mcm","clk":"1004220664","pt":1580653975936,"mc":[{"id":"1.168224028","rc":[{"batb":[[0,5,45.17],[1,1.01,0.51],[2,1.01,0]],"ltp":0.0,"tv":0.0,"id":17467775},{"batb":[[0,1.59,29.9],[1,1.01,0.51],[2,1.59,0]],"ltp":1.72,"tv":460.48,"id":17467774},{"batb":[[0,14.5,5.74],[1,1.01,0.51],[2,14.5,0]],"ltp":7.0,"tv":13.44,"id":16775228},{"batb":[[0,5.2,30.49],[1,4.8,14.95],[2,1.01,0.51]],"ltp":0.0,"tv":0.0,"id":16775230}]}]}
{"op":"mcm","clk":"1004221209","pt":1580653978918,"mc":[{"id":"1.168224028","rc":[{"batb":[[0,5,59.65],[1,4.9,32.95],[2,1.01,0.51]],"ltp":0.0,"tv":0.0,"id":17467775},{"batb":[[0,1.6,96.28],[1,1.59,102.38],[2,1.01,0.51]],"ltp":1.72,"tv":460.48,"id":17467774},{"batb":[[0,16.5,7.97],[1,16,13.66],[2,14.5,5.74]],"ltp":7.0,"tv":13.44,"id":16775228},{"batb":[[1,5.1,31.81],[2,4.8,14.95]],"ltp":0.0,"tv":0.0,"id":16775230}]}]}
{"op":"mcm","clk":"1004222854","pt":1580653987109,"mc":[{"id":"1.168224028","rc":[{"batb":[[0,5,13.61],[1,1.01,0.51],[2,1.01,0]],"ltp":0.0,"tv":0.0,"id":17467775},{"batb":[[0,14.5,5.74],[1,1.01,0.51],[2,14.5,0]],"ltp":7.0,"tv":13.44,"id":16775228},{"batb":[[0,4.8,14.95],[1,1.01,0.51],[2,4.8,0]],"ltp":0.0,"tv":0.0,"id":16775230}]}]}
{"op":"mcm","clk":"1004223389","pt":1580653989873,"mc":[{"id":"1.168224028","rc":[{"batb":[[0,5.2,41.08],[1,5.1,30.14],[2,5,13.61]],"ltp":0.0,"tv":0.0,"id":17467775},{"batb":[[0,38,5.51],[1,36,10.04],[2,14.5,5.74]],"ltp":7.0,"tv":13.44,"id":16775228},{"batb":[[0,5.4,31.18],[1,5.3,29.14],[2,4.8,14.95]],"ltp":0.0,"tv":0.0,"id":16775230}]}]}
{"op":"mcm","clk":"1004223597","pt":1580653990850,"mc":[{"id":"1.168224028","rc":[{"batb":[[0,5.3,11.88],[1,5.2,53.75],[2,5.1,30.14]],"batl":[[0,5.6,8.4],[1,6.2,11.25],[2,6.4,10.7]],"ltp":0.0,"tv":0.0,"id":17467775},{"batb":[[0,1.64,65.54],[1,1.6,96.28],[2,1.59,102.38]],"batl":[[0,1.66,29.27],[1,1.72,25.97],[2,1.76,42.01]],"ltp":1.72,"tv":460.48,"id":17467774},{"batb":[[2,27,3.32]],"ltp":7.0,"tv":13.44,"id":16775228},{"batb":[[2,5.1,13.14]],"batl":[[0,5.7,8.4],[1,5.8,12.59],[2,6.2,11.64]],"ltp":0.0,"tv":0.0,"id":16775230}]}]}
{"op":"mcm","clk":"1004224260","pt":1580653994067,"mc":[{"id":"1.168224028","rc":[{"trd":[[1.66,57.14]],"batl":[[0,1.72,26.67],[1,1.76,42.01],[2,1.76,0]],"ltp":1.66,"tv":517.62,"id":17467774}],"tv":531.06}]}
{"op":"mcm","clk":"1004226590","pt":1580654005987,"mc":[{"id":"1.168224028","rc":[{"batb":[[0,5.2,12.67],[1,5.1,30.14],[2,4.8,10.92]],"batl":[[1,6.4,10.7],[2,6.4,0]],"ltp":0.0,"tv":0.0,"id":17467775},{"batb":[[1,1.54,33.75],[2,1.01,0.51]],"batl":[[0,1.72,25.97]],"ltp":1.66,"tv":517.62,"id":17467774},{"batb":[[0,22,4.04],[1,1.01,0.51],[2,27,0]],"ltp":7.0,"tv":13.44,"id":16775228},{"batb":[[0,5.3,29.14],[1,4.9,14.32],[2,4.8,10.92]],"batl":[[1,6.2,11.64],[2,6.2,0]],"ltp":0.0,"tv":0.0,"id":16775230}]}]}
{"op":"mcm","clk":"1004226997","pt":1580654008039,"mc":[{"id":"1.168224028","rc":[{"batb":[[2,1.01,0.51]],"batl":[[0,6.4,10.7],[1,6.4,0]],"ltp":0.0,"tv":0.0,"id":17467775},{"batb":[[0,1.54,33.75],[1,1.01,0.51],[2,1.01,0]],"batl":[[1,1.76,0]],"ltp":1.66,"tv":517.62,"id":17467774},{"batb":[[2,1.01,0.51]],"batl":[[0,6.2,11.64],[1,6.2,0]],"ltp":0.0,"tv":0.0,"id":16775230}]}]}
{"op":"mcm","clk":"1004227096","pt":1580654008638,"mc":[{"id":"1.168224028","rc":[{"batb":[[1,5.1,48.56],[2,5,31.42]],"ltp":0.0,"tv":0.0,"id":17467775},{"batb":[[0,1.55,123.22],[1,1.54,115.77],[2,1.01,0.51]],"ltp":1.66,"tv":517.62,"id":17467774},{"batb":[[0,28,6.81],[1,27,9.19],[2,22,4.04]],"ltp":7.0,"tv":13.44,"id":16775228},{"batb":[[1,5.2,30.48],[2,4.9,14.32]],"ltp":0.0,"tv":0.0,"id":16775230}]}]}
{"op":"mcm","clk":"1004227248","pt":1580654009377,"mc":[{"id":"1.168224028","rc":[{"batb":[[0,5.1,61.54],[1,5,31.42],[2,1.01,0.51]],"batl":[[0,6.2,11.02]],"ltp":0.0,"tv":0.0,"id":17467775},{"batb":[[0,1.56,32.81],[1,1.55,123.22],[2,1.54,82.02]],"batl":[[0,1.74,25.49]],"ltp":1.66,"tv":517.62,"id":17467774},{"batb":[[2,22,3.89]],"ltp":7.0,"tv":13.44,"id":16775228},{"batl":[[0,6,11.96]],"ltp":0.0,"tv":0.0,"id":16775230}]}]}
{"op":"mcm","clk":"1004227784","pt":1580654012070,"mc":[{"id":"1.168224028","rc":[{"batb":[[0,5.1,12.98],[1,1.01,0.51],[2,1.01,0]],"ltp":0.0,"tv":0.0,"id":17467775},{"batb":[[0,22,3.89],[1,1.01,0.51],[2,22,0]],"ltp":7.0,"tv":13.44,"id":16775228},{"batb":[[0,4.9,14.32],[1,1.01,0.51],[2,4.9,0]],"ltp":0.0,"tv":0.0,"id":16775230}]}]}
{"op":"mcm","clk":"1004228399","pt":1580654014968,"mc":[{"id":"1.168224028","rc":[{"batb":[[0,5.4,11.49],[1,5.3,41.36],[2,5.2,41.11]],"batl":[[1,6.4,10.46]],"ltp":0.0,"tv":0.0,"id":17467775},{"batl":[[0,1.63,32.1],[1,1.68,28.25],[2,1.74,25.49]],"ltp":1.66,"tv":517.62,"id":17467774},{"batb":[[0,65,7.38],[1,60,3.28],[2,26,3.8]],"ltp":7.0,"tv":13.44,"id":16775228},{"batb":[[0,5.5,41.9],[1,5.4,27.76],[2,5.2,12.51]],"batl":[[1,6.2,10.94]],"ltp":0.0,"tv":0.0,"id":16775230}]}]}
{"op":"mcm","clk":"1004228612","pt":1580654016043,"mc":[{"id":"1.168224028","rc":[{"batl":[[2,1.74,0]],"ltp":1.66,"tv":517.62,"id":17467774}]}]}
{"op":"mcm","clk":"1004228765","pt":1580654016788,"mc":[{"id":"1.168224028","rc":[{"batl":[[0,5.7,8.4],[1,6.2,11.02],[2,6.4,10.46]],"ltp":0.0,"tv":0.0,"id":17467775},{"batb":[[0,1.57,73.1],[1,1.56,32.81],[2,1.55,123.22]],"batl":[[1,1.68,70.26]],"ltp":1.66,"tv":517.62,"id":17467774},{"batl":[[0,6,20.36]],"ltp":0.0,"tv":0.0,"id":16775230}]}]}
{"op":"mcm","clk":"1004238712","pt":1580654064658,"mc":[{"id":"1.168224028","rc":[{"batb":[[2,30,3.15]],"ltp":7.0,"tv":13.44,"id":16775228}]}]}
{"op":"mcm","clk":"1004245647","pt":1580654098099,"mc":[{"id":"1.168224028","rc":[{"batb":[[0,5.2,12.27],[1,4.8,10.92],[2,1.01,0.51]],"batl":[[1,6.4,10.46],[2,6.4,0]],"ltp":0.0,"tv":0.0,"id":17467775},{"batb":[[1,1.51,36.74],[2,1.01,0.51]],"batl":[[0,1.68,70.26],[1,1.68,0]],"ltp":1.66,"tv":517.62,"id":17467774},{"batb":[[0,27,3.48],[1,1.01,0.51],[2,30,0]],"ltp":7.0,"tv":13.44,"id":16775228},{"batb":[[0,5.1,10.08],[1,5,13.61],[2,1.01,0.51]],"batl":[[0,6,8.4]],"ltp":0.0,"tv":0.0,"id":16775230}]}]}
{"op":"mcm","clk":"1004245973","pt":1580654099614,"mc":[{"id":"1.168224028","rc":[{"batb":[[1,1.01,0.51],[2,1.01,0]],"batl":[[0,6.4,10.46],[1,6.4,0]],"ltp":0.0,"tv":0.0,"id":17467775},{"batb":[[0,1.51,36.74],[1,1.01,0.51],[2,1.01,0]],"batl":[[0,1.68,28.25]],"ltp":1.66,"tv":517.62,"id":17467774},{"batb":[[0,5,13.61],[1,1.01,0.51],[2,1.01,0]],"batl":[[0,6.2,10.94],[1,6.2,0]],"ltp":0.0,"tv":0.0,"id":16775230}]}]}
{"op":"mcm","clk":"1004246470","pt":1580654102021,"mc":[{"id":"1.168224028","rc":[{"batb":[[0,5.2,53.36],[1,5.1,30.15],[2,1.01,0.51]],"ltp":0.0,"tv":0.0,"id":17467775},{"batb":[[0,1.52,147.51],[1,1.51,125.55],[2,1.01,0.51]],"ltp":1.66,"tv":517.62,"id":17467774},{"batb":[[0,40,10.12],[1,38,7.15],[2,27,3.48]],"ltp":7.0,"tv":13.44,"id":16775228},{"batb":[[0,5.4,20.69],[1,5.3,29.26],[2,5,13.61]],"ltp":0.0,"tv":0.0,"id":16775230}]}]}
{"op":"mcm","clk":"1004247431","pt":1580654106548,"mc":[{"id":"1.168224028","rc":[{"batb":[[0,5.2,12.27],[1,1.01,0.51],[2,1.01,0]],"ltp":0.0,"tv":0.0,"id":17467775},{"batb":[[0,27,3.48],[1,1.01,0.51],[2,27,0]],"ltp":7.0,"tv":13.44,"id":16775228},{"batb":[[0,5,13.61],[1,1.01,0.51],[2,5,0]],"ltp":0.0,"tv":0.0,"id":16775230}]}]}
{"op":"mcm","clk":"1004248096","pt":1580654109583,"mc":[{"id":"1.168224028","rc":[{"batb":[[0,5.4,32.29],[1,5.3,27.75],[2,5.2,12.27]],"ltp":0.0,"tv":0.0,"id":17467775},{"batb":[[0,110,4.87],[1,27,3.48],[2,1.01,0.51]],"ltp":7.0,"tv":13.44,"id":16775228},{"batb":[[0,5.7,19.62],[1,5.6,25.91],[2,5,13.61]],"ltp":0.0,"tv":0.0,"id":16775230}]}]}
{"op":"mcm","clk":"1004248340","pt":1580654110800,"mc":[{"id":"1.168224028","rc":[{"batb":[[0,5.5,10.86],[1,5.4,44.01],[2,5.3,27.75]],"batl":[[0,5.7,8.4],[1,6.4,10.46],[2,6.6,19.43]],"ltp":0.0,"tv":0.0,"id":17467775},{"batb":[[0,1.55,75.62],[1,1.52,147.51],[2,1.51,125.55]],"batl":[[0,1.58,35.88],[1,1.63,31.47],[2,1.65,42.01]],"ltp":1.66,"tv":517.62,"id":17467774},{"batb":[[1,1.01,0.51],[2,1.01,0]],"ltp":7.0,"tv":13.44,"id":16775228},{"batb":[[2,5.4,11.41]],"batl":[[0,6.2,18.5],[1,6.6,19.67]],"ltp":0.0,"tv":0.0,"id":16775230}]}]}
{"op":"mcm","clk":"1004250741","pt":1580654121995,"mc":[{"id":"1.168224028","rc":[{"batb":[[0,5.4,11.72],[1,5.3,27.75],[2,4.9,10.08]],"batl":[[1,6.6,19.43],[2,6.6,0]],"ltp":0.0,"tv":0.0,"id":17467775},{"batb":[[1,1.48,40.68],[2,1.01,0.51]],"batl":[[0,1.63,31.47],[1,1.65,42.01],[2,1.65,0]],"ltp":1.66,"tv":517.62,"id":17467774},{"batb":[[0,1.01,0.51],[1,1.01,0]],"ltp":7.0,"tv":13.44,"id":16775228},{"batb":[[0,5.2,21.91],[1,1.01,0.51],[2,5.4,0]],"batl":[[0,6.2,7.56]],"ltp":0.0,"tv":0.0,"id":16775230}]}]}
{"op":"mcm","clk":"1004251119","pt":1580654123911,"mc":[{"id":"1.168224028","rc":[{"batb":[[2,1.01,0.51]],"batl":[[0,6.6,19.43],[1,6.6,0]],"ltp":0.0,"tv":0.0,"id":17467775},{"batb":[[0,1.48,40.68],[1,1.01,0.51],[2,1.01,0]],"batl":[[1,1.65,0]],"ltp":1.66,"tv":517.62,"id":17467774},{"batb":[[0,5.2,12.67]],"batl":[[0,6.6,19.67],[1,6.6,0]],"ltp":0.0,"tv":0.0,"id":16775230}]}]}
{"op":"mcm","clk":"1004251345","pt":1580654124918,"mc":[{"id":"1.168224028","rc":[{"batb":[[2,5.2,29]],"ltp":0.0,"tv":0.0,"id":17467775},{"batb":[[0,1.5,116.77],[1,1.49,93.56],[2,1.48,40.68]],"ltp":1.66,"tv":517.62,"id":17467774},{"batb":[[0,60,7.05],[1,55,4.61],[2,1.01,0.51]],"ltp":7.0,"tv":13.44,"id":16775228},{"batb":[[0,5.5,20.87],[1,5.4,28.07],[2,5.2,12.67]],"ltp":0.0,"tv":0.0,"id":16775230}]}]}
{"op":"mcm","clk":"1004251775","pt":1580654127001,"mc":[{"id":"1.168224028","rc":[{"batb":[[1,1.01,0.51],[2,5.2,0]],"ltp":0.0,"tv":0.0,"id":17467775},{"batb":[[0,1.01,0.51],[1,55,0],[2,1.01,0]],"ltp":7.0,"tv":13.44,"id":16775228},{"batb":[[0,5.2,12.67],[1,1.01,0.51],[2,5.2,0]],"ltp":0.0,"tv":0.0,"id":16775230}]}]}
{"op":"mcm","clk":"1004252356","pt":1580654129912,"mc":[{"id":"1.168224028","rc":[{"batb":[[0,5.5,23.86],[1,5.4,38.45],[2,1.01,0.51]],"ltp":0.0,"tv":0.0,"id":17467775},{"batb":[[0,5.8,26.39],[1,5.7,24.82],[2,5.2,12.67]],"ltp":0.0,"tv":0.0,"id":16775230}]}]}
{"op":"mcm","clk":"1004252546","pt":1580654130815,"mc":[{"id":"1.168224028","rc":[{"batb":[[0,5.6,10.46],[1,5.5,34.8],[2,5.4,26.73]],"batl":[[0,5.8,8.4],[1,6.6,19.43],[2,6.8,18.25]],"ltp":0.0,"tv":0.0,"id":17467775},{"batb":[[0,1.53,78.98],[1,1.5,116.77],[2,1.49,93.56]],"batl":[[0,1.54,39.66],[1,1.59,35.09],[2,1.62,42.01]],"ltp":1.66,"tv":517.62,"id":17467774},{"batb":[[2,5.6,10.54]],"batl":[[0,6.2,7.56],[1,6.6,19.67],[2,6.8,18.33]],"ltp":0.0,"tv":0.0,"id":16775230}]}]}
{"op":"mcm","clk":"1004253290","pt":1580654134230,"mc":[{"id":"1.168224028","rc":[{"trd":[[1.54,58.82]],"batl":[[0,1.54,10.25]],"ltp":1.54,"tv":576.43,"id":17467774}],"tv":589.88}]}
{"op":"mcm","clk":"1004254918","pt":1580654141916,"mc":[{"id":"1.168224028","rc":[{"batb":[[0,5.5,10.94],[1,5.4,26.73],[2,1.01,0.51]],"batl":[[0,6.8,18.25],[1,6.6,0],[2,6.8,0]],"ltp":0.0,"tv":0.0,"id":17467775},{"batb":[[0,1.45,44.38],[1,1.01,0.51],[2,1.49,0]],"batl":[[0,1.59,35.09],[1,1.59,0],[2,1.62,0]],"ltp":1.54,"tv":576.43,"id":17467774},{"batb":[[0,5.3,11.88],[1,1.01,0.51],[2,5.6,0]],"batl":[[0,6.8,18.33],[1,6.6,0],[2,6.8,0]],"ltp":0.0,"tv":0.0,"id":16775230}]}]}
{"op":"mcm","clk":"1004255552","pt":1580654144925,"mc":[{"id":"1.168224028","rc":[{"batb":[[2,5.3,27.9]],"ltp":0.0,"tv":0.0,"id":17467775},{"batb":[[0,1.48,125.18],[1,1.47,99],[2,1.46,43.51]],"batl":[[0,1.6,34.38]],"ltp":1.54,"tv":576.43,"id":17467774},{"batb":[[0,110,5.45],[1,1.01,0.51]],"ltp":7.0,"tv":13.44,"id":16775228},{"batb":[[0,5.6,23.07],[1,5.5,26.91],[2,5.3,11.88]],"ltp":0.0,"tv":0.0,"id":16775230}]}]}
{"op":"mcm","clk":"1004256935","pt":1580654151953,"mc":[{"id":"1.168224028","rc":[{"batb":[[2,1.01,0.51]],"ltp":0.0,"tv":0.0,"id":17467775},{"batb":[[0,1.01,0.51],[1,1.01,0]],"ltp":7.0,"tv":13.44,"id":16775228},{"batb":[[0,5.3,11.88],[1,1.01,0.51],[2,5.3,0]],"ltp":0.0,"tv":0.0,"id":16775230}]}]}
{"op":"mcm","clk":"1004257567","pt":1580654155022,"mc":[{"id":"1.168224028","rc":[{"batb":[[0,5.7,19.99],[1,5.6,10.54],[2,5.5,52.79]],"batl":[[0,5.9,8.4],[1,6.8,18.25]],"ltp":0.0,"tv":0.0,"id":17467775},{"batb":[[0,1.5,84.02],[1,1.48,125.18],[2,1.47,99]],"batl":[[0,1.51,42.33],[1,1.55,38.55],[2,1.6,76.39]],"ltp":1.54,"tv":576.43,"id":17467774},{"batb":[[0,5.9,26.07],[1,5.8,23.76],[2,5.7,20.14]],"batl":[[0,6.4,7.56],[1,6.8,18.33],[2,7,17.07]],"ltp":0.0,"tv":0.0,"id":16775230}]}]}
{"op":"mcm","clk":"1004257685","pt":1580654155678,"mc":[{"id":"1.168224028","rc":[{"batb":[[2,5.5,41.85]],"batl":[[1,6.8,17.86]],"ltp":0.0,"tv":0.0,"id":17467775},{"batl":[[2,1.6,42.01]],"ltp":1.54,"tv":576.43,"id":17467774}]}]}
{"op":"mcm","clk":"1004258344","pt":1580654159027,"mc":[{"id":"1.168224028","rc":[{"trd":[[1.51,84.02]],"batl":[[0,1.55,38.87],[1,1.6,42.01],[2,1.6,0]],"ltp":1.51,"tv":660.46,"id":17467774}],"tv":673.9}]}
{"op":"mcm","clk":"1004259227","pt":1580654162947,"mc":[{"id":"1.168224028","rc":[{"batb":[[0,5.6,10.54],[1,5.4,26.73],[2,5,10.08]],"ltp":0.0,"tv":0.0,"id":17467775},{"batb":[[1,1.47,99],[2,1.43,46.74]],"batl":[[0,1.55,38.55]],"ltp":1.51,"tv":660.46,"id":17467774},{"batb":[[0,5.5,20.18],[1,1.01,0.51],[2,5.7,0]],"batl":[[1,7,17.07],[2,7,0]],"ltp":0.0,"tv":0.0,"id":16775230}]}]}
{"op":"mcm","clk":"1004259366","pt":1580654163544,"mc":[{"id":"1.168224028","rc":[{"batb":[[2,1.01,0.51]],"batl":[[0,6.8,17.86],[1,6.8,0]],"ltp":0.0,"tv":0.0,"id":17467775},{"batb":[[0,1.47,99],[1,1.43,46.74],[2,1.01,0.51]],"batl":[[1,1.6,0]],"ltp":1.51,"tv":660.46,"id":17467774},{"batb":[[0,5.5,10.94]],"batl":[[0,7,17.07],[1,7,0]],"ltp":0.0,"tv":0.0,"id":16775230}]}]}
{"op":"mcm","clk":"1004259874","pt":1580654165943,"mc":[{"id":"1.168224028","rc":[{"batb":[[0,5.5,10.86],[1,5.4,43.33],[2,5.3,27.62]],"ltp":0.0,"tv":0.0,"id":17467775},{"batb":[[1,1.46,101.55],[2,1.44,45.48]],"batl":[[0,1.56,37.53]],"ltp":1.51,"tv":660.46,"id":17467774},{"batb":[[0,5.7,18.64],[1,5.6,25.79],[2,5.4,11.33]],"ltp":0.0,"tv":0.0,"id":16775230}]}]}
{"op":"mcm","clk":"1004260077","pt":1580654166926,"mc":[{"id":"1.168224028","rc":[{"batb":[[1,5.4,26.73],[2,1.01,0.51]],"ltp":0.0,"tv":0.0,"id":17467775},{"batb":[[0,1.44,45.48],[1,1.01,0.51],[2,1.44,0]],"ltp":1.51,"tv":660.46,"id":17467774},{"batb":[[1,5.4,11.33],[2,1.01,0.51]],"ltp":0.0,"tv":0.0,"id":16775230}]}]}
{"op":"mcm","clk":"1004260606","pt":1580654169437,"mc":[{"id":"1.168224028","rc":[{"batb":[[0,5.5,49]],"ltp":0.0,"tv":0.0,"id":17467775},{"batb":[[0,1.49,94.28],[1,1.48,95.96],[2,1.44,45.48]],"ltp":1.51,"tv":660.46,"id":17467774},{"batb":[[0,5.8,39.07],[1,5.7,18.64],[2,5.4,11.33]],"ltp":0.0,"tv":0.0,"id":16775230}]}]}
{"op":"mcm","clk":"1004261025","pt":1580654171440,"mc":[{"id":"1.168224028","rc":[{"batb":[[0,5.5,10.86]],"ltp":0.0,"tv":0.0,"id":17467775},{"batb":[[0,1.44,45.48],[1,1.01,0.51],[2,1.44,0]],"ltp":1.51,"tv":660.46,"id":17467774},{"batb":[[0,5.7,18.64],[1,5.4,11.33],[2,1.01,0.51]],"ltp":0.0,"tv":0.0,"id":16775230}]}]}
{"op":"mcm","clk":"1004261614","pt":1580654174246,"mc":[{"id":"1.168224028","rc":[{"batb":[[1,5.4,43.33],[2,5.3,27.62]],"ltp":0.0,"tv":0.0,"id":17467775},{"batb":[[0,1.47,91.45],[1,1.46,101.55],[2,1.44,45.48]],"ltp":1.51,"tv":660.46,"id":17467774},{"batb":[[1,5.6,25.79],[2,5.4,11.33]],"ltp":0.0,"tv":0.0,"id":16775230}]}]}
{"op":"mcm","clk":"1004261954","pt":1580654175968,"mc":[{"id":"1.168224028","rc":[{"batb":[[1,1.01,0.51],[2,5.3,0]],"ltp":0.0,"tv":0.0,"id":17467775},{"batb":[[0,5.4,11.33],[1,1.01,0.51],[2,5.4,0]],"ltp":0.0,"tv":0.0,"id":16775230}]}]}
{"op":"mcm","clk":"1004262540","pt":1580654178671,"mc":[{"id":"1.168224028","rc":[{"batb":[[0,5.6,34.48],[1,5.5,36.39],[2,1.01,0.51]],"ltp":0.0,"tv":0.0,"id":17467775},{"batb":[[0,6,36.51],[1,5.9,22.74],[2,5.4,11.33]],"ltp":0.0,"tv":0.0,"id":16775230}]}]}
{"op":"mcm","clk":"1004262759","pt":1580654179744,"mc":[{"id":"1.168224028","rc":[{"batb":[[0,5.8,19.75],[1,5.6,34.48],[2,5.5,25.53]],"batl":[[1,7.8,13.69]],"ltp":0.0,"tv":0.0,"id":17467775},{"batl":[[0,1.5,44.22],[1,1.59,34.7]],"ltp":1.51,"tv":660.46,"id":17467774},{"batb":[[1,5.9,41.62],[2,5.3,12.12]],"batl":[[0,6.8,17.62],[1,8,13.22]],"ltp":0.0,"tv":0.0,"id":16775230}]}]}
{"op":"mcm","clk":"1004262916","pt":1580654180557,"mc":[{"id":"1.168224028","rc":[{"batl":[[0,6,8.4],[1,6.8,17.86],[2,7.8,13.69]],"ltp":0.0,"tv":0.0,"id":17467775},{"batb":[[0,1.48,87.38],[1,1.47,91.45],[2,1.46,101.55]],"batl":[[1,1.57,42.01],[2,1.59,34.7]],"ltp":1.51,"tv":660.46,"id":17467774},{"batb":[[2,5.6,8.4]],"batl":[[0,6.6,6.72],[1,6.8,17.62],[2,8,13.22]],"ltp":0.0,"tv":0.0,"id":16775230}]}]}
{"op":"mcm","clk":"1004265021","pt":1580654190984,"mc":[{"id":"1.168224028","rc":[{"batl":[[2,7.8,13.38]],"ltp":0.0,"tv":0.0,"id":16775230}]}]}
{"op":"mcm","clk":"1004265065","pt":1580654191159,"mc":[{"id":"1.168224028","rc":[{"batl":[[0,1.5,43.98],[2,1.59,34.54]],"ltp":1.51,"tv":660.46,"id":17467774}]}]}
{"op":"mcm","clk":"1004268531","pt":1580654207997,"mc":[{"id":"1.168224028","rc":[{"batb":[[2,5.8,19.51]],"ltp":0.0,"tv":0.0,"id":16775230}]}]}
{"op":"mcm","clk":"1004268628","pt":1580654208525,"mc":[{"id":"1.168224028","rc":[{"batl":[[0,1.5,43.67],[2,1.6,34.31]],"ltp":1.51,"tv":660.46,"id":17467774},{"batb":[[1,5.9,22.74]],"ltp":0.0,"tv":0.0,"id":16775230}]}]}
{"op":"mcm","clk":"1004269653","pt":1580654213121,"mc":[{"id":"1.168224028","rc":[{"batb":[[0,5.8,19.59]],"ltp":0.0,"tv":0.0,"id":17467775},{"batl":[[0,1.5,43.51],[2,1.6,34.15]],"ltp":1.51,"tv":660.46,"id":17467774}]}]}
{"op":"mcm","clk":"1004279012","pt":1580654257630,"mc":[{"id":"1.168224028","rc":[{"batl":[[0,6.8,17.62],[1,7.8,13.38],[2,7.8,0]],"ltp":0.0,"tv":0.0,"id":16775230}]}]}
{"op":"mcm","clk":"1004279832","pt":1580654261562,"mc":[{"id":"1.168224028","rc":[{"batl":[[2,1.59,34.46]],"ltp":1.51,"tv":660.46,"id":17467774},{"batb":[[2,5.8,27.68]],"batl":[[0,6.8,24.35]],"ltp":0.0,"tv":0.0,"id":16775230}]}]}
{"op":"mcm","clk":"1004280452","pt":1580654264358,"mc":[{"id":"1.168224028","rc":[{"batb":[[0,1.47,91.45],[1,1.46,101.55],[2,1.44,45.16]],"batl":[[1,1.59,34.46],[2,1.59,0]],"ltp":1.51,"tv":660.46,"id":17467774},{"batl":[[0,6.8,17.62]],"ltp":0.0,"tv":0.0,"id":16775230}]}]}
{"op":"mcm","clk":"1004281011","pt":1580654267135,"mc":[{"id":"1.168224028","rc":[{"batb":[[0,1.47,180.51]],"batl":[[1,1.56,42.01],[2,1.59,34.46]],"ltp":1.51,"tv":660.46,"id":17467774},{"batl":[[1,7,6.72],[2,7.8,13.38]],"ltp":0.0,"tv":0.0,"id":16775230}]}]}
{"op":"mcm","clk":"1004281477","pt":1580654269441,"mc":[{"id":"1.168224028","rc":[{"batb":[[1,5.9,41.47],[2,5.8,8.4]],"batl":[[0,7,24.27],[1,8,13.14],[2,7.8,0]],"ltp":0.0,"tv":0.0,"id":16775230}]}]}
{"op":"mcm","clk":"1004282454","pt":1580654274276,"mc":[{"id":"1.168224028","rc":[{"batb":[[0,16,14.28],[1,1.01,0.51]],"ltp":7.0,"tv":13.44,"id":16775228}]}]}
{"op":"mcm","clk":"1004288464","pt":1580654303507,"mc":[{"id":"1.168224028","rc":[{"batb":[[0,1.01,0.51],[1,1.01,0]],"ltp":7.0,"tv":13.44,"id":16775228}]}]}
{"op":"mcm","clk":"1004293055","pt":1580654327083,"mc":[{"id":"1.168224028","rc":[{"batb":[[0,5.2,12.51],[1,5.1,10.08],[2,1.01,0.51]],"batl":[[1,7.8,13.69],[2,7.8,0]],"ltp":0.0,"tv":0.0,"id":17467775},{"batb":[[0,1.47,89.06],[1,1.36,57.75],[2,1.01,0.51]],"batl":[[0,1.56,42.01],[1,1.59,34.46],[2,1.59,0]],"ltp":1.51,"tv":660.46,"id":17467774},{"batb":[[0,5.8,8.4],[1,5.3,12.04],[2,1.01,0.51]],"batl":[[0,7,6.72]],"ltp":0.0,"tv":0.0,"id":16775230}]}]}
{"op":"mcm","clk":"1004293154","pt":1580654327626,"mc":[{"id":"1.168224028","rc":[{"batb":[[1,1.01,0.51],[2,1.01,0]],"batl":[[0,7.8,13.69],[1,7.8,0]],"ltp":0.0,"tv":0.0,"id":17467775},{"batb":[[0,1.36,57.75],[1,1.01,0.51],[2,1.01,0]],"batl":[[0,1.59,34.46],[1,1.59,0]],"ltp":1.51,"tv":660.46,"id":17467774},{"batb":[[0,5.3,12.04],[1,1.01,0.51],[2,1.01,0]],"batl":[[0,8,13.14],[1,8,0]],"ltp":0.0,"tv":0.0,"id":16775230}]}]}
{"op":"mcm","clk":"1004293569","pt":1580654329732,"mc":[{"id":"1.168224028","rc":[{"batl":[[0,1.6,34.38]],"ltp":1.51,"tv":660.46,"id":17467774},{"batb":[[0,5.2,12.43]],"batl":[[0,7.8,13.53]],"ltp":0.0,"tv":0.0,"id":16775230}]}]}
{"op":"mcm","clk":"1004293906","pt":1580654331559,"mc":[{"id":"1.168224028","rc":[{"batb":[[0,5.8,24.13],[1,5.7,23.72],[2,5.2,12.51]],"ltp":0.0,"tv":0.0,"id":17467775},{"batb":[[0,1.45,108.06],[1,1.44,107.83],[2,1.36,57.75]],"ltp":1.51,"tv":660.46,"id":17467774},{"batb":[[0,6.2,25.77],[1,6,43.28],[2,5.2,12.43]],"ltp":0.0,"tv":0.0,"id":16775230}]}]}
{"op":"mcm","clk":"1004294185","pt":1580654332853,"mc":[{"id":"1.168224028","rc":[{"batb":[[0,5.2,12.51],[1,1.01,0.51],[2,5.2,0]],"ltp":0.0,"tv":0.0,"id":17467775},{"batb":[[0,1.36,57.75],[1,1.01,0.51],[2,1.36,0]],"ltp":1.51,"tv":660.46,"id":17467774},{"batb":[[0,5.2,12.43],[1,1.01,0.51],[2,5.2,0]],"ltp":0.0,"tv":0.0,"id":16775230}]}]}
{"op":"mcm","clk":"1004294728","pt":1580654335858,"mc":[{"id":"1.168224028","rc":[{"batb":[[1,5,49.36],[2,4.9,32.94]],"ltp":0.0,"tv":0.0,"id":17467775},{"batb":[[0,1.38,90.63],[1,1.37,135.05],[2,1.36,57.75]],"ltp":1.51,"tv":660.46,"id":17467774},{"batb":[[0,5.4,31.43],[1,5.3,28.89],[2,5.2,12.43]],"ltp":0.0,"tv":0.0,"id":16775230}]}]}
{"op":"mcm","clk":"1004295322","pt":1580654338672,"mc":[{"id":"1.168224028","rc":[{"batb":[[0,9,15.96],[1,1.01,0.51]],"ltp":7.0,"tv":13.44,"id":16775228}]}]}
{"op":"mcm","clk":"1004295623","pt":1580654340044,"mc":[{"id":"1.168224028","rc":[{"batb":[[0,1.36,57.75],[1,1.01,0.51],[2,1.36,0]],"ltp":1.51,"tv":660.46,"id":17467774}]}]}
{"op":"mcm","clk":"1004296234","pt":1580654343061,"mc":[{"id":"1.168224028","rc":[{"batb":[[0,1.55,137.77],[1,1.54,81.92],[2,1.36,57.75]],"ltp":1.51,"tv":660.46,"id":17467774}]}]}
{"op":"mcm","clk":"1004296368","pt":1580654343750,"mc":[{"id":"1.168224028","rc":[{"batl":[[0,5.9,12.12],[1,6.8,18.25]],"ltp":0.0,"tv":0.0,"id":17467775},{"batb":[[1,1.54,117.17],[2,1.44,45.16]],"batl":[[1,1.71,26.99]],"ltp":1.51,"tv":660.46,"id":17467774},{"batl":[[0,5.9,11.96],[1,6.8,18.1]],"ltp":0.0,"tv":0.0,"id":16775230}]}]}
{"op":"mcm","clk":"1004296546","pt":1580654344567,"mc":[{"id":"1.168224028","rc":[{"batl":[[0,5.5,9.24],[1,5.9,12.12],[2,6.8,18.25]],"ltp":0.0,"tv":0.0,"id":17467775},{"batb":[[2,1.52,80.66]],"ltp":1.51,"tv":660.46,"id":17467774},{"batl":[[1,6.6,6.72],[2,6.8,18.1]],"ltp":0.0,"tv":0.0,"id":16775230}]}]}
{"op":"mcm","clk":"1004296986","pt":1580654346871,"mc":[{"id":"1.168224028","rc":[{"batb":[[2,1.44,45.16]],"ltp":1.51,"tv":660.46,"id":17467774}]}]}
{"op":"mcm","clk":"1004297561","pt":1580654349784,"mc":[{"id":"1.168224028","rc":[{"batb":[[2,1.53,78.98]],"batl":[[1,1.62,42.01],[2,1.71,26.99]],"ltp":1.51,"tv":660.46,"id":17467774},{"batb":[[0,5.5,9.24],[1,5.4,31.43],[2,5.3,28.89]],"ltp":0.0,"tv":0.0,"id":16775230}]}]}
{"op":"mcm","clk":"1004298626","pt":1580654355092,"mc":[{"id":"1.168224028","rc":[{"batb":[[1,4.7,27.05],[2,1.01,0.51]],"ltp":0.0,"tv":0.0,"id":17467775},{"batb":[[0,1.54,35.25],[1,1.53,78.98],[2,1.44,45.16]],"ltp":1.51,"tv":660.46,"id":17467774},{"batb":[[1,5.2,12.43],[2,4.7,15.89]],"ltp":0.0,"tv":0.0,"id":16775230}]}]}
{"op":"mcm","clk":"1004298863","pt":1580654356077,"mc":[{"id":"1.168224028","rc":[{"batb":[[0,4.7,16.13],[1,1.01,0.51],[2,1.01,0]],"batl":[[0,6.8,18.25],[1,5.9,0],[2,6.8,0]],"ltp":0.0,"tv":0.0,"id":17467775},{"batb":[[0,1.44,45.16],[1,1.01,0.51],[2,1.44,0]],"batl":[[0,1.71,26.99],[1,1.62,0],[2,1.71,0]],"ltp":1.51,"tv":660.46,"id":17467774},{"batb":[[0,4.7,15.89],[1,1.01,0.51],[2,4.7,0]],"batl":[[0,6.8,18.1],[1,6.6,0],[2,6.8,0]],"ltp":0.0,"tv":0.0,"id":16775230}]}]}
{"op":"mcm","clk":"1004299309","pt":1580654358114,"mc":[{"id":"1.168224028","rc":[{"batb":[[1,4.6,48.77],[2,4.5,40.08]],"ltp":0.0,"tv":0.0,"id":17467775},{"batb":[[0,1.46,111.47],[1,1.45,104.68],[2,1.44,45.16]],"ltp":1.51,"tv":660.46,"id":17467774},{"batb":[[0,4.9,47.5],[1,4.8,35.87],[2,4.7,15.89]],"ltp":0.0,"tv":0.0,"id":16775230}]}]}
{"op":"mcm","clk":"1004299506","pt":1580654359090,"mc":[{"id":"1.168224028","rc":[{"batb":[[0,4.6,65.06],[1,4.5,40.08],[2,1.01,0.51]],"ltp":0.0,"tv":0.0,"id":17467775},{"batb":[[2,4.7,15.66]],"batl":[[0,6.8,17.94]],"ltp":0.0,"tv":0.0,"id":16775230}]}]}
{"op":"mcm","clk":"1004301922","pt":1580654370910,"mc":[{"id":"1.168224028","rc":[{"batb":[[0,1.44,45.16],[1,1.01,0.51],[2,1.44,0]],"ltp":1.51,"tv":660.46,"id":17467774}]}]}
{"op":"mcm","clk":"1004302435","pt":1580654373097,"mc":[{"id":"1.168224028","rc":[{"batl":[[0,5.5,153.54],[1,6.8,17.94]],"ltp":0.0,"tv":0.0,"id":16775230}]}]}
{"op":"mcm","clk":"1004302645","pt":1580654374016,"mc":[{"id":"1.168224028","rc":[{"batb":[[2,4.3,19.36]],"batl":[[0,5.2,15.5],[1,5.7,12.75]],"ltp":0.0,"tv":0.0,"id":17467775},{"batb":[[0,1.64,127.7],[1,1.63,65.95],[2,1.55,34.23]],"batl":[[1,1.81,22.27]],"ltp":1.51,"tv":660.46,"id":17467774},{"batl":[[0,5.3,14.95],[1,5.9,12.04]],"ltp":0.0,"tv":0.0,"id":16775230}]}]}
{"op":"mcm","clk":"1004302857","pt":1580654375058,"mc":[{"id":"1.168224028","rc":[{"batb":[[2,4.4,11.76]],"batl":[[0,5.1,10.08],[1,5.2,15.5],[2,5.7,12.75]],"ltp":0.0,"tv":0.0,"id":17467775},{"batb":[[2,1.58,72.26]],"batl":[[0,1.69,42.01],[1,1.71,26.99],[2,1.81,22.27]],"ltp":1.51,"tv":660.46,"id":17467774},{"batb":[[0,5.2,9.24],[1,4.9,47.5],[2,4.8,35.87]],"batl":[[2,6.2,7.56]],"ltp":0.0,"tv":0.0,"id":16775230}]}]}
{"op":"mcm","clk":"1004303826","pt":1580654379928,"mc":[{"id":"1.168224028","rc":[{"batb":[[0,4.6,16.29],[1,4.4,11.76],[2,4.3,19.36]],"ltp":0.0,"tv":0.0,"id":17467775},{"batb":[[0,1.64,27.7],[1,1.58,72.26],[2,1.55,34.23]],"ltp":1.51,"tv":660.46,"id":17467774},{"batb":[[1,4.7,15.66],[2,4.3,19.04]],"ltp":0.0,"tv":0.0,"id":16775230}]}]}
{"op":"mcm","clk":"1004303945","pt":1580654380511,"mc":[{"id":"1.168224028","rc":[{"batb":[[0,4.4,11.76],[1,4.3,19.36],[2,1.01,0.51]],"batl":[[1,5.7,12.75],[2,5.7,0]],"ltp":0.0,"tv":0.0,"id":17467775},{"batb":[[0,1.58,72.26],[1,1.55,34.23],[2,1.01,0.51]],"batl":[[1,1.81,22.27],[2,1.81,0]],"ltp":1.51,"tv":660.46,"id":17467774},{"batb":[[1,4.3,19.04],[2,1.01,0.51]],"batl":[[0,5.9,12.04],[1,6.2,7.56],[2,6.2,0]],"ltp":0.0,"tv":0.0,"id":16775230}]}]}
{"op":"mcm","clk":"1004304178","pt":1580654381649,"mc":[{"id":"1.168224028","rc":[{"batb":[[0,4.3,19.36],[1,1.01,0.51],[2,1.01,0]],"batl":[[0,5.7,12.75],[1,5.7,0]],"ltp":0.0,"tv":0.0,"id":17467775},{"batb":[[0,1.55,34.23],[1,1.01,0.51],[2,1.01,0]],"batl":[[0,1.81,22.27],[1,1.81,0]],"ltp":1.51,"tv":660.46,"id":17467774},{"batb":[[0,4.3,19.04],[1,1.01,0.51],[2,1.01,0]],"batl":[[1,6.2,0]],"ltp":0.0,"tv":0.0,"id":16775230}]}]}
{"op":"mcm","clk":"1004304986","pt":1580654385635,"mc":[{"id":"1.168224028","rc":[{"batb":[[0,4.7,36.56],[1,4.6,38.29],[2,4.3,19.36]],"ltp":0.0,"tv":0.0,"id":17467775},{"batb":[[0,1.62,121.72],[1,1.61,69.08],[2,1.55,34.23]],"ltp":1.51,"tv":660.46,"id":17467774},{"batb":[[0,5,41.01],[1,4.9,34.33],[2,4.3,19.04]],"ltp":0.0,"tv":0.0,"id":16775230}]}]}
{"op":"mcm","clk":"1004305505","pt":1580654388059,"mc":[{"id":"1.168224028","rc":[{"batb":[[0,4.3,19.36],[1,1.01,0.51],[2,4.3,0]],"ltp":0.0,"tv":0.0,"id":17467775},{"batb":[[0,1.55,34.23],[1,1.01,0.51],[2,1.55,0]],"ltp":1.51,"tv":660.46,"id":17467774},{"batb":[[0,4.3,19.04],[1,1.01,0.51],[2,4.3,0]],"ltp":0.0,"tv":0.0,"id":16775230}]}]}
{"op":"mcm","clk":"1004306122","pt":1580654391033,"mc":[{"id":"1.168224028","rc":[{"batb":[[0,4.4,25.59],[1,4.3,64.3],[2,1.01,0.51]],"ltp":0.0,"tv":0.0,"id":17467775},{"batb":[[0,1.56,94.29],[1,1.55,113.9],[2,1.01,0.51]],"ltp":1.51,"tv":660.46,"id":17467774},{"batb":[[0,4.6,48.56],[1,4.5,41.56],[2,4.3,19.04]],"ltp":0.0,"tv":0.0,"id":16775230}]}]}
{"op":"mcm","clk":"1004306873","pt":1580654395034,"mc":[{"id":"1.168224028","rc":[{"batb":[[0,1.55,34.23],[1,1.01,0.51],[2,1.01,0]],"ltp":1.51,"tv":660.46,"id":17467774}]}]}
{"op":"mcm","clk":"1004307295","pt":1580654397041,"mc":[{"id":"1.168224028","rc":[{"batl":[[0,5.3,158.64],[1,5.9,12.04]],"ltp":0.0,"tv":0.0,"id":16775230}]}]}
{"op":"mcm","clk":"1004307489","pt":1580654397953,"mc":[{"id":"1.168224028","rc":[{"batb":[[2,4.1,21.64]],"batl":[[0,4.8,18.41],[1,5.1,16.68]],"ltp":0.0,"tv":0.0,"id":17467775},{"batb":[[0,1.74,22.74],[1,1.71,102.03],[2,1.69,115.18]],"batl":[[1,1.88,19.67]],"ltp":1.51,"tv":660.46,"id":17467774},{"batl":[[0,4.9,18.1],[1,5.2,15.5]],"ltp":0.0,"tv":0.0,"id":16775230}]}]}
{"op":"mcm","clk":"1004307710","pt":1580654398954,"mc":[{"id":"1.168224028","rc":[{"batb":[[2,4.2,12.6]],"batl":[[1,4.9,10.08],[2,5.1,16.68]],"ltp":0.0,"tv":0.0,"id":17467775},{"batl":[[0,1.75,42.01],[1,1.81,22.27],[2,1.88,19.67]],"ltp":1.51,"tv":660.46,"id":17467774},{"trd":[[4.9,20.17]],"batl":[[0,4.9,8.01]],"ltp":4.9,"tv":20.16,"id":16775230}],"tv":694.06}]}
{"op":"mcm","clk":"1004307880","pt":1580654399768,"mc":[{"id":"1.168224028","rc":[{"batb":[[0,1.01,0.51],[1,1.01,0]],"ltp":7.0,"tv":13.44,"id":16775228}]}]}
{"op":"mcm","clk":"1004308267","pt":1580654401776,"mc":[{"id":"1.168224028","rc":[{"batl":[[2,5.8,8.4]],"ltp":4.9,"tv":20.16,"id":16775230}]}]}
{"op":"mcm","clk":"1004308923","pt":1580654404762,"mc":[{"id":"1.168224028","rc":[{"trd":[[1.74,23.53]],"batb":[[0,1.74,10.98]],"ltp":1.74,"tv":683.98,"id":17467774},{"trd":[[4.9,35.29]],"batl":[[0,5.2,15.95],[1,5.8,8.4],[2,5.8,0]],"ltp":4.9,"tv":35.28,"id":16775230}],"tv":732.71}]}
{"op":"mcm","clk":"1004309619","pt":1580654408076,"mc":[{"id":"1.168224028","rc":[{"batb":[[0,4.8,10.92],[1,4.6,48.56],[2,4.5,41.56]],"ltp":4.9,"tv":35.28,"id":16775230}]}]}
{"op":"mcm","clk":"1004310202","pt":1580654411076,"mc":[{"id":"1.168224028","rc":[{"batb":[[0,4.3,19.36],[1,4.2,12.6],[2,4.1,21.64]],"ltp":0.0,"tv":0.0,"id":17467775},{"batb":[[1,1.67,26.12],[2,1.63,66.38]],"ltp":1.74,"tv":683.98,"id":17467774},{"batb":[[1,4.3,19.04],[2,4.1,21.24]],"ltp":4.9,"tv":35.28,"id":16775230}]}]}
{"op":"mcm","clk":"1004310318","pt":1580654411663,"mc":[{"id":"1.168224028","rc":[{"batb":[[0,4.1,21.64],[1,1.01,0.51],[2,4.1,0]],"batl":[[0,5.1,16.68],[1,4.9,0],[2,5.1,0]],"ltp":0.0,"tv":0.0,"id":17467775},{"batb":[[0,1.67,26.12],[1,1.01,0.51],[2,1.63,0]],"batl":[[0,1.88,19.67],[1,1.81,0],[2,1.88,0]],"ltp":1.74,"tv":683.98,"id":17467774},{"batb":[[0,4.1,21.24],[1,1.01,0.51],[2,4.1,0]],"batl":[[0,5.2,15.5],[1,5.8,0]],"ltp":4.9,"tv":35.28,"id":16775230}]}]}
{"op":"mcm","clk":"1004310804","pt":1580654414074,"mc":[{"id":"1.168224028","rc":[{"batb":[[0,4.2,64.66],[1,4.1,71.15],[2,1.01,0.51]],"batl":[[0,5,17.07],[1,5.1,16.68]],"ltp":0.0,"tv":0.0,"id":17467775},{"batb":[[1,1.66,89.16],[2,1.65,63.06]],"batl":[[0,1.84,21.01],[1,1.88,19.67]],"ltp":1.74,"tv":683.98,"id":17467774},{"batb":[[0,4.4,80.6],[1,4.3,45.92],[2,4.1,21.24]],"batl":[[1,5.7,13.38]],"ltp":4.9,"tv":35.28,"id":16775230}]}]}
{"op":"mcm","clk":"1004310946","pt":1580654414681,"mc":[{"id":"1.168224028","rc":[{"batb":[[0,4.1,21.64],[1,1.01,0.51],[2,1.01,0]],"batl":[[1,5.1,0]],"ltp":0.0,"tv":0.0,"id":17467775},{"batb":[[0,1.64,27.77],[1,1.01,0.51],[2,1.65,0]],"batl":[[1,1.88,0]],"ltp":1.74,"tv":683.98,"id":17467774},{"batb":[[0,4.4,18.33],[1,1.01,0.51],[2,4.1,0]],"batl":[[0,5.7,13.38],[1,5.7,0]],"ltp":4.9,"tv":35.28,"id":16775230}]}]}
{"op":"mcm","clk":"1004311669","pt":1580654418078,"mc":[{"id":"1.168224028","rc":[{"batb":[[0,4.4,39.57],[1,4.3,44.7],[2,4.1,21.64]],"ltp":0.0,"tv":0.0,"id":17467775},{"batb":[[0,1.7,98.13],[1,1.68,117.59],[2,1.64,27.77]],"ltp":1.74,"tv":683.98,"id":17467774},{"batb":[[0,4.7,26.92],[1,4.6,39.86],[2,4.4,18.33]],"ltp":4.9,"tv":35.28,"id":16775230}]}]}
{"op":"mcm","clk":"1004311711","pt":1580654418285,"mc":[{"id":"1.168224028","rc":[{"batb":[[0,4.1,21.64],[1,1.01,0.51],[2,4.1,0]],"ltp":0.0,"tv":0.0,"id":17467775},{"batb":[[0,1.64,27.77],[1,1.01,0.51],[2,1.64,0]],"ltp":1.74,"tv":683.98,"id":17467774},{"batb":[[0,4.4,18.33],[1,1.01,0.51],[2,4.4,0]],"ltp":4.9,"tv":35.28,"id":16775230}]}]}
{"op":"mcm","clk":"1004312381","pt":1580654421478,"mc":[{"id":"1.168224028","rc":[{"batb":[[0,4.2,64.66],[1,4.1,71.15],[2,1.01,0.51]],"ltp":0.0,"tv":0.0,"id":17467775},{"batb":[[0,1.66,89.16],[1,1.65,63.06],[2,1.64,27.77]],"ltp":1.74,"tv":683.98,"id":17467774},{"batb":[[0,4.4,80.6],[1,4.3,45.92],[2,1.01,0.51]],"ltp":4.9,"tv":35.28,"id":16775230}]}]}
{"op":"mcm","clk":"1004312712","pt":1580654423066,"mc":[{"id":"1.168224028","rc":[{"batb":[[0,4.1,21.64],[1,1.01,0.51],[2,1.01,0]],"ltp":0.0,"tv":0.0,"id":17467775},{"batb":[[2,1.01,0.51]],"ltp":1.74,"tv":683.98,"id":17467774},{"batb":[[0,4.4,18.33],[1,1.01,0.51],[2,1.01,0]],"ltp":4.9,"tv":35.28,"id":16775230}]}]}
{"op":"mcm","clk":"1004313304","pt":1580654426098,"mc":[{"id":"1.168224028","rc":[{"batb":[[0,4.5,52.27],[1,4.4,42.16],[2,4.1,21.64]],"ltp":0.0,"tv":0.0,"id":17467775},{"batb":[[0,4.9,26.05],[1,4.8,36.2],[2,4.4,18.33]],"ltp":4.9,"tv":35.28,"id":16775230}]}]}
{"op":"mcm","clk":"1004313429","pt":1580654426702,"mc":[{"id":"1.168224028","rc":[{"batb":[[1,4.4,60.1],[2,4.3,12.6]],"batl":[[0,5,27.16],[1,5.5,14.08]],"ltp":0.0,"tv":0.0,"id":17467775},{"batb":[[2,1.63,27.85]],"batl":[[0,1.7,27.22],[1,1.72,42.01],[2,1.81,22.42]],"ltp":1.74,"tv":683.98,"id":17467774},{"batb":[[0,5,24.01],[1,4.9,26.05],[2,4.8,36.2]],"batl":[[1,5.9,8.4],[2,6.2,10.94]],"ltp":4.9,"tv":35.28,"id":16775230}]}]}
{"op":"mcm","clk":"1004316352","pt":1580654441093,"mc":[{"id":"1.168224028","rc":[{"batb":[[0,4.3,12.6],[1,4.1,21.24],[2,1.01,0.51]],"batl":[[0,5,10.08]],"ltp":0.0,"tv":0.0,"id":17467775},{"batb":[[0,1.61,68.06],[1,1.55,33.99],[2,1.01,0.51]],"batl":[[0,1.72,42.01],[1,1.81,22.42],[2,1.81,0]],"ltp":1.74,"tv":683.98,"id":17467774},{"batb":[[0,5,10.08],[1,4.6,17.07],[2,1.01,0.51]],"batl":[[0,5.9,8.4],[1,6.2,10.94],[2,6.2,0]],"ltp":4.9,"tv":35.28,"id":16775230}]}]}
{"op":"mcm","clk":"1004316486","pt":1580654441696,"mc":[{"id":"1.168224028","rc":[{"batb":[[0,4.1,21.24],[1,1.01,0.51],[2,1.01,0]],"batl":[[0,5.5,14.08],[1,5.5,0]],"ltp":0.0,"tv":0.0,"id":17467775},{"batb":[[0,1.55,33.99],[1,1.01,0.51],[2,1.01,0]],"batl":[[0,1.81,22.42],[1,1.81,0]],"ltp":1.74,"tv":683.98,"id":17467774},{"batb":[[0,4.6,16.84],[1,1.01,0.51],[2,1.01,0]],"batl":[[0,6.2,10.94],[1,6.2,0]],"ltp":4.9,"tv":35.28,"id":16775230}]}]}
{"op":"mcm","clk":"1004317480","pt":1580654446896,"mc":[{"id":"1.168224028","rc":[{"batb":[[0,4.6,37.12],[1,4.5,40.27],[2,4.1,21.24]],"ltp":0.0,"tv":0.0,"id":17467775},{"batb":[[0,1.64,111.48],[1,1.63,65.98],[2,1.55,33.99]],"ltp":1.74,"tv":683.98,"id":17467774},{"batb":[[0,4.9,53.59],[1,4.8,35.78],[2,4.6,16.84]],"ltp":4.9,"tv":35.28,"id":16775230}]}]}
{"op":"mcm","clk":"1004317763","pt":1580654447837,"mc":[{"id":"1.168224028","rc":[{"batb":[[0,4.1,21.24],[1,1.01,0.51],[2,4.1,0]],"ltp":0.0,"tv":0.0,"id":17467775},{"batb":[[0,1.55,33.99],[1,1.01,0.51],[2,1.55,0]],"ltp":1.74,"tv":683.98,"id":17467774},{"batb":[[0,4.6,16.84],[1,1.01,0.51],[2,4.6,0]],"ltp":4.9,"tv":35.28,"id":16775230}]}]}
{"op":"mcm","clk":"1004318467","pt":1580654451041,"mc":[{"id":"1.168224028","rc":[{"batb":[[0,1.58,91.93],[1,1.57,75.82],[2,1.55,33.99]],"ltp":1.74,"tv":683.98,"id":17467774}]}]}
{"op":"mcm","clk":"1004318898","pt":1580654453038,"mc":[{"id":"1.168224028","rc":[{"batb":[[0,4.9,27.97],[1,4.8,34.87],[2,4.1,21.24]],"ltp":0.0,"tv":0.0,"id":17467775},{"batb":[[0,5.3,31.09],[1,5.2,30.16],[2,4.6,16.84]],"ltp":4.9,"tv":35.28,"id":16775230}]}]}
{"op":"mcm","clk":"1004319077","pt":1580654453806,"mc":[{"id":"1.168224028","rc":[{"batb":[[1,4.8,49.66],[2,4.2,20.69]],"batl":[[1,6.6,18.96]],"ltp":0.0,"tv":0.0,"id":17467775},{"batl":[[0,1.61,33.13],[1,1.77,23.92]],"ltp":1.74,"tv":683.98,"id":17467774},{"batb":[[0,5.4,11.41],[1,5.3,31.09],[2,5.2,30.16]],"batl":[[1,7.4,15.19]],"ltp":4.9,"tv":35.28,"id":16775230}]}]}
{"op":"mcm","clk":"1004319231","pt":1580654454606,"mc":[{"id":"1.168224028","rc":[{"batb":[[2,4.5,11.76]],"batl":[[0,5.3,9.24],[1,5.5,14.08],[2,6.6,18.96]],"ltp":0.0,"tv":0.0,"id":17467775},{"batb":[[2,1.56,74.78]],"batl":[[1,1.66,42.01],[2,1.77,23.92]],"ltp":1.74,"tv":683.98,"id":17467774},{"batb":[[1,5.3,40.33]],"batl":[[0,6.2,18.5]],"ltp":4.9,"tv":35.28,"id":16775230}]}]}
{"op":"mcm","clk":"1004321873","pt":1580654467121,"mc":[{"id":"1.168224028","rc":[{"batb":[[0,4.5,11.76],[1,4.2,20.54],[2,1.01,0.51]],"batl":[[1,6.6,18.96],[2,6.6,0]],"ltp":0.0,"tv":0.0,"id":17467775},{"batb":[[0,1.56,74.78],[1,1.42,47.29],[2,1.01,0.51]],"batl":[[0,1.66,42.01],[1,1.77,23.68],[2,1.77,0]],"ltp":1.74,"tv":683.98,"id":17467774},{"batb":[[0,5.3,9.24],[1,4.7,15.5],[2,1.01,0.51]],"batl":[[0,6.2,7.56]],"ltp":4.9,"tv":35.28,"id":16775230}]}]}
{"op":"mcm","clk":"1004321994","pt":1580654467624,"mc":[{"id":"1.168224028","rc":[{"batb":[[0,4.2,20.54],[1,1.01,0.51],[2,1.01,0]],"batl":[[0,6.6,18.96],[1,6.6,0]],"ltp":0.0,"tv":0.0,"id":17467775},{"batb":[[0,1.42,47.29],[1,1.01,0.51],[2,1.01,0]],"batl":[[0,1.77,23.68],[1,1.77,0]],"ltp":1.74,"tv":683.98,"id":17467774},{"batb":[[0,4.7,15.5],[1,1.01,0.51],[2,1.01,0]],"batl":[[0,7.4,15.19],[1,7.4,0]],"ltp":4.9,"tv":35.28,"id":16775230}]}]}
{"op":"mcm","clk":"1004323189","pt":1580654473061,"mc":[{"id":"1.168224028","rc":[{"batb":[[0,5,44.99],[1,4.9,33],[2,4.2,20.54]],"ltp":0.0,"tv":0.0,"id":17467775},{"batb":[[0,1.55,110.06],[1,1.54,81.78],[2,1.42,47.29]],"ltp":1.74,"tv":683.98,"id":17467774},{"batb":[[0,5.5,20.01],[1,5.4,27.87],[2,4.7,15.5]],"ltp":4.9,"tv":35.28,"id":16775230}]}]}
{"op":"mcm","clk":"1004323560","pt":1580654474871,"mc":[{"id":"1.168224028","rc":[{"batb":[[0,4.2,20.54],[1,1.01,0.51],[2,4.2,0]],"ltp":0.0,"tv":0.0,"id":17467775},{"batb":[[0,1.42,47.29],[1,1.01,0.51],[2,1.42,0]],"ltp":1.74,"tv":683.98,"id":17467774},{"batb":[[0,4.7,15.5],[1,1.01,0.51],[2,4.7,0]],"ltp":4.9,"tv":35.28,"id":16775230}]}]}
{"op":"mcm","clk":"1004324469","pt":1580654479077,"mc":[{"id":"1.168224028","rc":[{"batb":[[0,4.3,57.74],[1,4.2,67.44],[2,1.01,0.51]],"ltp":0.0,"tv":0.0,"id":17467775},{"batb":[[0,1.45,98.55],[1,1.44,107.75],[2,1.42,47.29]],"ltp":1.74,"tv":683.98,"id":17467774},{"batb":[[0,4.7,59.86],[1,4.6,39.58],[2,1.01,0.51]],"ltp":4.9,"tv":35.28,"id":16775230}]}]}
{"op":"mcm","clk":"1004325448","pt":1580654483750,"mc":[{"id":"1.168224028","rc":[{"batb":[[0,4.2,20.54],[1,1.01,0.51],[2,1.01,0]],"ltp":0.0,"tv":0.0,"id":17467775},{"batb":[[0,4.7,15.5],[1,1.01,0.51],[2,1.01,0]],"ltp":4.9,"tv":35.28,"id":16775230}]}]}
{"op":"mcm","clk":"1004326065","pt":1580654486892,"mc":[{"id":"1.168224028","rc":[{"batb":[[0,5.8,20.3],[1,5.7,23.78],[2,4.2,20.54]],"ltp":0.0,"tv":0.0,"id":17467775},{"batb":[[0,6.2,33.3],[1,6,43.08],[2,4.7,15.5]],"ltp":4.9,"tv":35.28,"id":16775230}]}]}
{"op":"mcm","clk":"1004326244","pt":1580654487670,"mc":[{"id":"1.168224028","rc":[{"batb":[[1,5.7,44.08],[2,4.8,14.79]],"batl":[[1,8.2,12.04]],"ltp":0.0,"tv":0.0,"id":17467775},{"batl":[[0,1.48,45.95],[1,1.62,32.34]],"ltp":1.74,"tv":683.98,"id":17467774},{"batb":[[0,6.2,50.06],[2,5.3,12.04]],"batl":[[1,9,10.46]],"ltp":4.9,"tv":35.28,"id":16775230}]}]}
{"op":"mcm","clk":"1004326460","pt":1580654488683,"mc":[{"id":"1.168224028","rc":[{"batb":[[2,5.1,10.08]],"batl":[[0,6.2,7.56],[1,6.6,18.96],[2,8.2,12.04]],"ltp":0.0,"tv":0.0,"id":17467775},{"batb":[[0,1.46,90.74],[1,1.45,98.55],[2,1.44,107.75]],"batl":[[1,1.55,42.01],[2,1.62,32.34]],"ltp":1.74,"tv":683.98,"id":17467774},{"batb":[[2,5.8,8.4]],"batl":[[0,7,6.72],[1,7.4,15.19],[2,9,10.46]],"ltp":4.9,"tv":35.28,"id":16775230}]}]}
{"op":"mcm","clk":"1004328884","pt":1580654499979,"mc":[{"id":"1.168224028","rc":[{"batb":[[0,4.8,14.79],[1,1.01,0.51],[2,5.1,0]],"batl":[[0,8.2,12.04],[1,6.6,0],[2,8.2,0]],"ltp":0.0,"tv":0.0,"id":17467775},{"batb":[[0,1.32,67.98],[1,1.01,0.51],[2,1.44,0]],"batl":[[0,1.62,32.34],[1,1.55,0],[2,1.62,0]],"ltp":1.74,"tv":683.98,"id":17467774},{"batb":[[0,5.3,12.04],[1,1.01,0.51],[2,5.8,0]],"batl":[[0,9,10.46],[1,7.4,0],[2,9,0]],"ltp":4.9,"tv":35.28,"id":16775230}]}]}
{"op":"mcm","clk":"1004329523","pt":1580654503072,"mc":[{"id":"1.168224028","rc":[{"batb":[[0,4.9,29.4],[1,4.8,49.64],[2,1.01,0.51]],"ltp":0.0,"tv":0.0,"id":17467775},{"batb":[[0,1.32,199.76],[1,1.31,169.76],[2,1.01,0.51]],"ltp":1.74,"tv":683.98,"id":17467774},{"batb":[[0,5.3,45.69],[1,5.2,30.12],[2,1.01,0.51]],"ltp":4.9,"tv":35.28,"id":16775230}]}]}
{"op":"mcm","clk":"1004334469","pt":1580654526928,"mc":[{"id":"1.168224028","rc":[{"batb":[[0,1.32,67.98],[1,1.01,0.51],[2,1.01,0]],"ltp":1.74,"tv":683.98,"id":17467774}]}]}
{"op":"mcm","clk":"1004335135","pt":1580654530012,"mc":[{"id":"1.168224028","rc":[{"batb":[[0,1.58,83.31],[1,1.57,75.79],[2,1.32,67.98]],"ltp":1.74,"tv":683.98,"id":17467774}]}]}
{"op":"mcm","clk":"1004335301","pt":1580654530727,"mc":[{"id":"1.168224028","rc":[{"batb":[[2,4.6,10.92]],"batl":[[0,5.3,9.24],[1,5.5,14.16],[2,6.6,19.12]],"ltp":0.0,"tv":0.0,"id":17467775},{"batb":[[2,1.56,33.13]],"batl":[[1,1.65,42.01],[2,1.79,23.13]],"ltp":1.74,"tv":683.98,"id":17467774},{"batb":[[0,5.3,54.93],[2,4.6,16.37]],"batl":[[0,6.2,11.57],[1,6.4,7.56],[2,7.2,16.44]],"ltp":4.9,"tv":35.28,"id":16775230}]}]}
{"op":"mcm","clk":"1004336090","pt":1580654534207,"mc":[{"id":"1.168224028","rc":[{"batb":[[0,7,15.96],[1,1.01,0.51]],"ltp":7.0,"tv":13.44,"id":16775228}]}]}
{"op":"mcm","clk":"1004339840","pt":1580654550635,"mc":[{"id":"1.168224028","rc":[{"batb":[[0,4.6,10.92],[1,4.2,20.85],[2,1.01,0.51]],"batl":[[1,6.6,19.12],[2,6.6,0]],"ltp":0.0,"tv":0.0,"id":17467775},{"batb":[[0,1.55,75.62],[1,1.43,46.03],[2,1.01,0.51]],"batl":[[0,1.65,42.01],[1,1.79,23.13],[2,1.79,0]],"ltp":1.74,"tv":683.98,"id":17467774},{"batb":[[0,5.3,9.24],[1,4.6,16.37],[2,1.01,0.51]],"batl":[[0,6.4,7.56],[1,7.2,16.44],[2,7.2,0]],"ltp":4.9,"tv":35.28,"id":16775230}]}]}
{"op":"mcm","clk":"1004340034","pt":1580654551653,"mc":[{"id":"1.168224028","rc":[{"batb":[[0,4.2,20.85],[1,1.01,0.51],[2,1.01,0]],"batl":[[0,6.6,19.12],[1,6.6,0]],"ltp":0.0,"tv":0.0,"id":17467775},{"batb":[[0,1.43,46.03],[1,1.01,0.51],[2,1.01,0]],"batl":[[0,1.79,23.13],[1,1.79,0]],"ltp":1.74,"tv":683.98,"id":17467774},{"batb":[[0,4.6,16.37],[1,1.01,0.51],[2,1.01,0]],"batl":[[0,7.2,16.44],[1,7.2,0]],"ltp":4.9,"tv":35.28,"id":16775230}]}]}
{"op":"mcm","clk":"1004340537","pt":1580654553855,"mc":[{"id":"1.168224028","rc":[{"batb":[[0,4.3,58.85],[1,4.2,67.73],[2,1.01,0.51]],"ltp":0.0,"tv":0.0,"id":17467775},{"batb":[[0,1.45,88.09],[1,1.44,107.67],[2,1.43,46.03]],"ltp":1.74,"tv":683.98,"id":17467774},{"batb":[[0,4.7,46.84],[1,4.6,55.92],[2,1.01,0.51]],"ltp":4.9,"tv":35.28,"id":16775230}]}]}
{"op":"mcm","clk":"1004341050","pt":1580654556166,"mc":[{"id":"1.168224028","rc":[{"batb":[[0,4.2,20.85],[1,1.01,0.51],[2,1.01,0]],"ltp":0.0,"tv":0.0,"id":17467775},{"batb":[[0,4.6,16.37],[1,1.01,0.51],[2,1.01,0]],"ltp":4.9,"tv":35.28,"id":16775230}]}]}
{"op":"mcm","clk":"1004341938","pt":1580654560078,"mc":[{"id":"1.168224028","rc":[{"batb":[[0,5.8,21.83],[1,5.7,44.3],[2,4.8,15.03]],"batl":[[1,8.2,12.35]],"ltp":0.0,"tv":0.0,"id":17467775},{"batl":[[0,1.49,44.77],[1,1.63,31.63],[2,1.79,23.13]],"ltp":1.74,"tv":683.98,"id":17467774},{"batb":[[0,6.2,35.72],[1,6,60.57],[2,5.2,12.35]],"batl":[[1,9,10.62]],"ltp":4.9,"tv":35.28,"id":16775230}]}]}
{"op":"mcm","clk":"1004342067","pt":1580654560669,"mc":[{"id":"1.168224028","rc":[{"batb":[[2,5.1,10.08]],"batl":[[0,6.2,7.56],[1,6.6,19.12],[2,8.2,12.35]],"ltp":0.0,"tv":0.0,"id":17467775},{"batb":[[0,1.45,181.35]],"batl":[[1,1.55,42.01],[2,1.63,31.63]],"ltp":1.74,"tv":683.98,"id":17467774},{"batb":[[2,5.8,8.4]],"batl":[[0,7,6.72],[1,7.2,16.44],[2,9,10.62]],"ltp":4.9,"tv":35.28,"id":16775230}]}]}
{"op":"mcm","clk":"1004343057","pt":1580654565063,"mc":[{"id":"1.168224028","rc":[{"batb":[[0,1.01,0.51],[1,1.01,0]],"ltp":7.0,"tv":13.44,"id":16775228}]}]}
{"op":"mcm","clk":"1004344684","pt":1580654572070,"mc":[{"id":"1.168224028","rc":[{"batb":[[0,4.8,15.03],[1,1.01,0.51],[2,5.1,0]],"batl":[[0,8.2,12.35],[1,6.6,0],[2,8.2,0]],"ltp":0.0,"tv":0.0,"id":17467775},{"batb":[[0,1.32,66.88],[1,1.01,0.51],[2,1.43,0]],"batl":[[0,1.63,31.63],[1,1.55,0],[2,1.63,0]],"ltp":1.74,"tv":683.98,"id":17467774},{"batb":[[0,5.2,12.35],[1,1.01,0.51],[2,5.8,0]],"batl":[[0,9,10.62],[1,7.2,0],[2,9,0]],"ltp":4.9,"tv":35.28,"id":16775230}]}]}
{"op":"mcm","clk":"1004345803","pt":1580654576868,"mc":[{"id":"1.168224028","rc":[{"batb":[[0,6,34.35],[1,5.9,21.83],[2,4.8,15.03]],"ltp":0.0,"tv":0.0,"id":17467775},{"batb":[[0,1.42,115.51],[1,1.41,118.43],[2,1.32,66.88]],"ltp":1.74,"tv":683.98,"id":17467774},{"batb":[[0,6.4,48],[1,6.2,39.7],[2,5.2,12.35]],"ltp":4.9,"tv":35.28,"id":16775230}]}]}
{"op":"mcm","clk":"1004346294","pt":1580654578905,"mc":[{"id":"1.168224028","rc":[{"batb":[[0,4.8,15.03],[1,1.01,0.51],[2,4.8,0]],"ltp":0.0,"tv":0.0,"id":17467775},{"batb":[[0,1.32,66.88],[1,1.01,0.51],[2,1.32,0]],"ltp":1.74,"tv":683.98,"id":17467774},{"batb":[[0,5.2,12.35],[1,1.01,0.51],[2,5.2,0]],"ltp":4.9,"tv":35.28,"id":16775230}]}]}
{"op":"mcm","clk":"1004347114","pt":1580654582070,"mc":[{"id":"1.168224028","rc":[{"batb":[[0,1.32,187.36],[1,1.31,169.58],[2,1.01,0.51]],"ltp":1.74,"tv":683.98,"id":17467774}]}]}
{"op":"mcm","clk":"1004347811","pt":1580654585103,"mc":[{"id":"1.168224028","rc":[{"batb":[[0,7.4,16.96],[1,7.2,28.13],[2,6.8,13.06]],"batl":[[0,7.8,5.88],[1,8.2,12.35],[2,11,6.92]],"ltp":0.0,"tv":0.0,"id":17467775},{"batb":[[0,1.34,123.51],[1,1.32,187.36],[2,1.31,169.58]],"batl":[[0,1.37,64.52],[1,1.41,42.01],[2,1.5,43.98]],"ltp":1.74,"tv":683.98,"id":17467774},{"batb":[[0,7.8,32.81],[1,7.6,25.75],[2,7.4,11.25]],"batl":[[0,8.6,5.04],[1,9,10.62],[2,12,15.26]],"ltp":4.9,"tv":35.28,"id":16775230}]}]}
{"op":"mcm","clk":"1004351599","pt":1580654602112,"mc":[{"id":"1.168224028","rc":[{"batb":[[0,6.8,13.06],[1,6.4,7.56],[2,5.6,10.62]],"ltp":0.0,"tv":0.0,"id":17467775},{"batb":[[1,1.32,66.88],[2,1.22,102.13]],"ltp":1.74,"tv":683.98,"id":17467774},{"batb":[[0,7.4,11.25],[1,7,6.72],[2,6,17.78]],"ltp":4.9,"tv":35.28,"id":16775230}]}]}
{"op":"mcm","clk":"1004351658","pt":1580654602322,"mc":[{"id":"1.168224028","rc":[{"batb":[[0,6.4,7.56],[1,5.6,10.62],[2,1.01,0.51]],"batl":[[1,11,6.92],[2,11,0]],"ltp":0.0,"tv":0.0,"id":17467775},{"batb":[[1,1.22,102.13],[2,1.01,0.51]],"batl":[[0,1.41,42.01],[1,1.5,43.98],[2,1.5,0]],"ltp":1.74,"tv":683.98,"id":17467774},{"batb":[[0,7,6.72],[1,6,17.78],[2,1.01,0.51]],"batl":[[1,12,15.26],[2,12,0]],"ltp":4.9,"tv":35.28,"id":16775230}]}]}
{"op":"mcm","clk":"1004351987","pt":1580654603724,"mc":[{"id":"1.168224028","rc":[{"batb":[[0,5.6,10.62],[1,1.01,0.51],[2,1.01,0]],"batl":[[0,11,6.92],[1,11,0]],"ltp":0.0,"tv":0.0,"id":17467775},{"batb":[[0,1.22,102.13],[1,1.01,0.51],[2,1.01,0]],"batl":[[0,1.5,43.98],[1,1.5,0]],"ltp":1.74,"tv":683.98,"id":17467774},{"batb":[[0,6,17.78],[1,1.01,0.51],[2,1.01,0]],"batl":[[0,12,15.26],[1,12,0]],"ltp":4.9,"tv":35.28,"id":16775230}]}]}
{"op":"mcm","clk":"1004352256","pt":1580654604939,"mc":[{"id":"1.168224028","rc":[{"batb":[[0,5.8,20.2],[1,5.7,23.75],[2,5.6,10.62]],"ltp":0.0,"tv":0.0,"id":17467775},{"batb":[[1,1.19,377.34],[2,1.18,193.21]],"ltp":1.74,"tv":683.98,"id":17467774},{"batb":[[0,6.2,34.46],[1,6,60.77],[2,1.01,0.51]],"ltp":4.9,"tv":35.28,"id":16775230}]}]}
{"op":"mcm","clk":"1004352745","pt":1580654607052,"mc":[{"id":"1.168224028","rc":[{"batb":[[0,5.6,10.62],[1,1.01,0.51],[2,5.6,0]],"ltp":0.0,"tv":0.0,"id":17467775},{"batb":[[1,1.01,0.51],[2,1.18,0]],"ltp":1.74,"tv":683.98,"id":17467774},{"batb":[[0,6,17.78],[1,1.01,0.51],[2,1.01,0]],"ltp":4.9,"tv":35.28,"id":16775230}]}]}
{"op":"mcm","clk":"1004354015","pt":1580654612667,"mc":[{"id":"1.168224028","rc":[{"batb":[[0,5.8,20.2],[1,5.7,23.75],[2,5.6,10.62]],"ltp":0.0,"tv":0.0,"id":17467775},{"batb":[[1,1.19,377.34],[2,1.18,193.21]],"ltp":1.74,"tv":683.98,"id":17467774},{"batb":[[0,6.2,34.46],[1,6,60.77],[2,1.01,0.51]],"ltp":4.9,"tv":35.28,"id":16775230}]}]}
{"op":"mcm","clk":"1004356317","pt":1580654622760,"mc":[{"id":"1.168224028","rc":[{"batb":[[1,1.01,0.51],[2,1.18,0]],"ltp":1.74,"tv":683.98,"id":17467774}]}]}
{"op":"mcm","clk":"1004357004","pt":1580654625877,"mc":[{"id":"1.168224028","rc":[{"batb":[[0,1.45,98.91],[1,1.44,107.64],[2,1.22,102.13]],"ltp":1.74,"tv":683.98,"id":17467774}]}]}
{"op":"mcm","clk":"1004357248","pt":1580654626976,"mc":[{"id":"1.168224028","rc":[{"batl":[[0,6.2,7.56],[1,6.6,19.67],[2,8.2,12.59]],"ltp":0.0,"tv":0.0,"id":17467775},{"batb":[[0,1.45,192.17],[1,1.44,152.88],[2,1.33,65.38]],"batl":[[1,1.53,42.01],[2,1.64,30.84]],"ltp":1.74,"tv":683.98,"id":17467774},{"batb":[[1,6,69.17],[2,5.2,12.75]],"batl":[[0,7.2,23.32],[1,8.8,11.02]],"ltp":4.9,"tv":35.28,"id":16775230}]}]}
{"op":"mcm","clk":"1004360112","pt":1580654639796,"mc":[{"id":"1.168224028","rc":[{"batb":[[0,4.8,15.42],[1,1.01,0.51],[2,5.6,0]],"batl":[[0,8.2,12.59],[1,6.6,0],[2,8.2,0]],"ltp":0.0,"tv":0.0,"id":17467775},{"batb":[[0,1.33,65.38],[1,1.01,0.51],[2,1.33,0]],"batl":[[0,1.64,30.84],[1,1.53,0],[2,1.64,0]],"ltp":1.74,"tv":683.98,"id":17467774},{"batb":[[0,5.2,12.75],[1,1.01,0.51],[2,5.2,0]],"batl":[[0,8.8,11.02],[1,8.8,0]],"ltp":4.9,"tv":35.28,"id":16775230}]}]}
{"op":"mcm","clk":"1004361629","pt":1580654646005,"mc":[{"id":"1.168224028","rc":[{"batb":[[0,6,33.1],[1,5.9,21.82],[2,4.8,15.42]],"ltp":0.0,"tv":0.0,"id":17467775},{"batb":[[0,1.42,126.46],[1,1.41,118.39],[2,1.33,65.38]],"ltp":1.74,"tv":683.98,"id":17467774},{"batb":[[0,6.4,44.99],[1,6.2,39.68],[2,5.2,12.75]],"ltp":4.9,"tv":35.28,"id":16775230}]}]}
{"op":"mcm","clk":"1004361692","pt":1580654646279,"mc":[{"id":"1.168224028","rc":[{"batb":[[0,4.8,15.42],[1,1.01,0.51],[2,4.8,0]],"ltp":0.0,"tv":0.0,"id":17467775},{"batb":[[0,1.33,65.38],[1,1.01,0.51],[2,1.33,0]],"ltp":1.74,"tv":683.98,"id":17467774},{"batb":[[0,5.2,12.75],[1,1.01,0.51],[2,5.2,0]],"ltp":4.9,"tv":35.28,"id":16775230}]}]}
{"op":"mcm","clk":"1004362309","pt":1580654649279,"mc":[{"id":"1.168224028","rc":[{"batb":[[0,4.9,29.26],[1,4.8,50.23],[2,1.01,0.51]],"ltp":0.0,"tv":0.0,"id":17467775},{"batb":[[1,1.32,131.77],[2,1.31,169.53]],"ltp":1.74,"tv":683.98,"id":17467774},{"batb":[[0,5.3,32.39],[1,5.2,42.82],[2,1.01,0.51]],"ltp":4.9,"tv":35.28,"id":16775230}]}]}
{"op":"mcm","clk":"1004364072","pt":1580654657713,"mc":[{"id":"1.168224028","rc":[{"batb":[[0,4.8,15.42],[1,1.01,0.51],[2,1.01,0]],"ltp":0.0,"tv":0.0,"id":17467775},{"batb":[[0,5.2,12.75],[1,1.01,0.51],[2,1.01,0]],"ltp":4.9,"tv":35.28,"id":16775230}]}]}
{"op":"mcm","clk":"1004364798","pt":1580654661110,"mc":[{"id":"1.168224028","rc":[{"batb":[[0,7.4,15.94],[1,7.2,28.12],[2,6.8,13.3]],"batl":[[1,11,7]],"ltp":0.0,"tv":0.0,"id":17467775},{"batl":[[0,1.38,63.1],[1,1.51,42.96],[2,1.64,30.84]],"ltp":1.74,"tv":683.98,"id":17467774},{"batb":[[0,7.8,30.37],[1,7.6,25.73],[2,7.2,11.64]],"batl":[[1,12,15.5]],"ltp":4.9,"tv":35.28,"id":16775230}]}]}
{"op":"mcm","clk":"1004364917","pt":1580654661606,"mc":[{"id":"1.168224028","rc":[{"batl":[[2,1.64,0]],"ltp":1.74,"tv":683.98,"id":17467774}]}]}
{"op":"mcm","clk":"1004365152","pt":1580654662737,"mc":[{"id":"1.168224028","rc":[{"batl":[[0,7.8,5.88],[1,8.2,12.59],[2,11,7]],"ltp":0.0,"tv":0.0,"id":17467775},{"batb":[[0,1.34,123.51],[1,1.33,65.38],[2,1.32,131.77]],"batl":[[1,1.41,42.01],[2,1.51,42.96]],"ltp":1.74,"tv":683.98,"id":17467774},{"batl":[[0,8.6,5.04],[1,8.8,11.02],[2,12,15.5]],"ltp":4.9,"tv":35.28,"id":16775230}]}]}
{"op":"mcm","clk":"1004365711","pt":1580654665415,"mc":[{"id":"1.168224028","rc":[{"batb":[[0,7,14.28],[1,1.01,0.51]],"ltp":7.0,"tv":13.44,"id":16775228}]}]}
{"op":"mcm","clk":"1004368304","pt":1580654677117,"mc":[{"id":"1.168224028","rc":[{"batb":[[0,6.4,7.56],[1,5.6,10.54],[2,1.01,0.51]],"batl":[[1,11,7],[2,11,0]],"ltp":0.0,"tv":0.0,"id":17467775},{"batb":[[1,1.23,100.87],[2,1.01,0.51]],"batl":[[0,1.41,42.01],[1,1.51,42.96],[2,1.51,0]],"ltp":1.74,"tv":683.98,"id":17467774},{"batb":[[0,7,6.72],[1,5.9,18.57],[2,1.01,0.51]],"batl":[[1,12,15.5],[2,12,0]],"ltp":4.9,"tv":35.28,"id":16775230}]}]}
{"op":"mcm","clk":"1004368413","pt":1580654677704,"mc":[{"id":"1.168224028","rc":[{"batb":[[0,5.6,10.54],[1,1.01,0.51],[2,1.01,0]],"batl":[[0,11,7],[1,11,0]],"ltp":0.0,"tv":0.0,"id":17467775},{"batb":[[0,1.23,100.87],[1,1.01,0.51],[2,1.01,0]],"batl":[[0,1.51,42.96],[1,1.51,0]],"ltp":1.74,"tv":683.98,"id":17467774},{"batb":[[0,5.9,18.57],[1,1.01,0.51],[2,1.01,0]],"batl":[[0,12,15.5],[1,12,0]],"ltp":4.9,"tv":35.28,"id":16775230}]}]}
{"op":"mcm","clk":"1004368807","pt":1580654679719,"mc":[{"id":"1.168224028","rc":[{"batb":[[0,5.8,20.98],[1,5.7,23.74],[2,5.6,10.54]],"ltp":0.0,"tv":0.0,"id":17467775},{"batb":[[1,1.19,376.18],[2,1.18,194.37]],"ltp":1.74,"tv":683.98,"id":17467774},{"batb":[[0,6.2,33.26],[1,6,42.97],[2,5.9,18.57]],"ltp":4.9,"tv":35.28,"id":16775230}]}]}
{"op":"mcm","clk":"1004369781","pt":1580654684103,"mc":[{"id":"1.168224028","rc":[{"batb":[[0,5.6,10.54],[1,1.01,0.51],[2,5.6,0]],"ltp":0.0,"tv":0.0,"id":17467775},{"batb":[[0,5.9,18.57],[1,1.01,0.51],[2,5.9,0]],"ltp":4.9,"tv":35.28,"id":16775230}]}]}
{"op":"mcm","clk":"1004370423","pt":1580654687010,"mc":[{"id":"1.168224028","rc":[{"batb":[[0,10.5,37.76],[1,10,28.04],[2,5.6,10.54]],"ltp":0.0,"tv":0.0,"id":17467775},{"batb":[[0,11,37.64],[1,10.5,25.03],[2,5.9,18.57]],"ltp":4.9,"tv":35.28,"id":16775230}]}]}
{"op":"mcm","clk":"1004370600","pt":1580654687827,"mc":[{"id":"1.168224028","rc":[{"batb":[[2,8.8,7.32]],"batl":[[1,13,12.51]],"ltp":0.0,"tv":0.0,"id":17467775},{"batb":[[1,1.19,304.69],[2,1.18,126.44]],"batl":[[0,1.27,96.15],[1,1.34,72.23]],"ltp":1.74,"tv":683.98,"id":17467774},{"batb":[[2,9.2,6.92]],"batl":[[1,14,11.33]],"ltp":4.9,"tv":35.28,"id":16775230}]}]}
{"op":"mcm","clk":"1004370860","pt":1580654689011,"mc":[{"id":"1.168224028","rc":[{"batb":[[2,9.4,4.2]],"batl":[[1,12,3.36],[2,13,12.51]],"ltp":0.0,"tv":0.0,"id":17467775},{"batb":[[1,1.2,168.04],[2,1.19,304.69]],"batl":[[0,1.25,42.01],[1,1.27,96.15],[2,1.34,72.23]],"ltp":1.74,"tv":683.98,"id":17467774},{"batb":[[2,9.6,4.2]],"batl":[[1,12.5,3.36],[2,14,11.33]],"ltp":4.9,"tv":35.28,"id":16775230}]}]}
{"op":"mcm","clk":"1004371225","pt":1580654690750,"mc":[{"id":"1.168224028","rc":[{"batb":[[1,1.2,258.65]],"ltp":1.74,"tv":683.98,"id":17467774}]}]}
{"op":"mcm","clk":"1004371959","pt":1580654694353,"mc":[{"id":"1.168224028","rc":[{"batb":[[2,9.2,6.92]],"ltp":4.9,"tv":35.28,"id":16775230}]}]}
{"op":"mcm","clk":"1004372281","pt":1580654695840,"mc":[{"id":"1.168224028","rc":[{"batl":[[0,11.5,15.89],[2,13.5,11.64]],"ltp":0.0,"tv":0.0,"id":17467775},{"batb":[[0,1.22,105.98]],"batl":[[1,1.26,100.87],[2,1.33,75.93]],"ltp":1.74,"tv":683.98,"id":17467774},{"batb":[[0,1.01,0.51],[1,1.01,0]],"ltp":7.0,"tv":13.44,"id":16775228},{"batb":[[2,9.4,16.05]],"batl":[[0,12.5,17.92],[1,14.5,10.62],[2,14,0]],"ltp":4.9,"tv":35.28,"id":16775230}]}]}
{"op":"mcm","clk":"1004372568","pt":1580654697358,"mc":[{"id":"1.168224028","rc":[{"batb":[[2,9.8,4.2]],"ltp":4.9,"tv":35.28,"id":16775230}]}]}
{"op":"mcm","clk":"1004373321","pt":1580654700846,"mc":[{"id":"1.168224028","rc":[{"batl":[[0,12.5,17.68],[1,14.5,10.46]],"ltp":4.9,"tv":35.28,"id":16775230}]}]}
{"op":"mcm","clk":"1004375311","pt":1580654709041,"mc":[{"id":"1.168224028","rc":[{"batb":[[1,1.2,168.04]],"ltp":1.74,"tv":683.98,"id":17467774}]}]}
{"op":"mcm","clk":"1004375966","pt":1580654711920,"mc":[{"id":"1.168224028","rc":[{"batb":[[2,1.19,389.19]],"ltp":1.74,"tv":683.98,"id":17467774}]}]}
{"op":"mcm","clk":"1004378693","pt":1580654724427,"mc":[{"id":"1.168224028","rc":[{"batb":[[0,9.4,4.2],[1,9,7.08],[2,7.6,10.15]],"ltp":0.0,"tv":0.0,"id":17467775},{"batb":[[2,1.18,126.44]],"ltp":1.74,"tv":683.98,"id":17467774},{"batb":[[0,9.8,4.2],[1,9.4,15.82],[2,8,9.21]],"ltp":4.9,"tv":35.28,"id":16775230}]}]}
{"op":"mcm","clk":"1004379263","pt":1580654727206,"mc":[{"id":"1.168224028","rc":[{"batb":[[2,8.8,15.45]],"ltp":0.0,"tv":0.0,"id":17467775},{"batb":[[2,9.2,19.49]],"ltp":4.9,"tv":35.28,"id":16775230}]}]}
{"op":"mcm","clk":"1004381791","pt":1580654738905,"mc":[{"id":"1.168224028","rc":[{"batb":[[1,8.8,15.45],[2,8.6,19.15]],"batl":[[0,12,3.36],[1,13.5,11.64],[2,13.5,0]],"ltp":0.0,"tv":0.0,"id":17467775},{"batb":[[0,1.2,168.04],[1,1.18,126.44],[2,1.16,321.51]],"batl":[[1,1.33,75.93],[2,1.33,0]],"ltp":1.74,"tv":683.98,"id":17467774},{"batb":[[1,9.2,19.49],[2,9,18.11]],"batl":[[0,12.5,3.36]],"ltp":4.9,"tv":35.28,"id":16775230}]}]}
{"op":"mcm","clk":"1004381977","pt":1580654739936,"mc":[{"id":"1.168224028","rc":[{"batb":[[0,8.8,15.45],[1,8.6,19.15],[2,7.6,10.15]],"batl":[[0,13.5,11.64],[1,13.5,0]],"ltp":0.0,"tv":0.0,"id":17467775},{"batb":[[0,1.18,126.44],[1,1.16,321.51],[2,1.15,264.36]],"batl":[[0,1.33,75.93],[1,1.33,0]],"ltp":1.74,"tv":683.98,"id":17467774},{"batb":[[0,9.2,19.49],[1,9,18.11],[2,8,9.21]],"batl":[[0,14.5,10.46],[1,14.5,0]],"ltp":4.9,"tv":35.28,"id":16775230}]}]}
{"op":"mcm","clk":"1004382385","pt":1580654741924,"mc":[{"id":"1.168224028","rc":[{"batb":[[0,7.6,10.15],[1,1.01,0.51],[2,7.6,0]],"ltp":0.0,"tv":0.0,"id":17467775},{"batb":[[1,1.17,133.84],[2,1.01,0.51]],"ltp":1.74,"tv":683.98,"id":17467774},{"batb":[[0,8,9.21],[1,1.01,0.51],[2,8,0]],"ltp":4.9,"tv":35.28,"id":16775230}]}]}
{"op":"mcm","clk":"1004382587","pt":1580654742839,"mc":[{"id":"1.168224028","rc":[{"batb":[[0,1.17,133.84],[1,1.01,0.51],[2,1.01,0]],"ltp":1.74,"tv":683.98,"id":17467774},{"batl":[[0,14.5,10.31]],"ltp":4.9,"tv":35.28,"id":16775230}]}]}
{"op":"mcm","clk":"1004382842","pt":1580654744048,"mc":[{"id":"1.168224028","rc":[{"batb":[[0,10,39.41],[1,9.8,14.06],[2,7.6,10.15]],"ltp":0.0,"tv":0.0,"id":17467775},{"batb":[[0,1.21,121.26],[1,1.2,288.17],[2,1.17,133.84]],"ltp":1.74,"tv":683.98,"id":17467774},{"batb":[[0,10.5,40.26],[1,10,25.41],[2,8,9.21]],"ltp":4.9,"tv":35.28,"id":16775230}]}]}
{"op":"mcm","clk":"1004383619","pt":1580654747752,"mc":[{"id":"1.168224028","rc":[{"batb":[[0,7.6,10.15],[1,1.01,0.51],[2,7.6,0]],"ltp":0.0,"tv":0.0,"id":17467775},{"batb":[[0,1.17,133.84],[1,1.01,0.51],[2,1.17,0]],"ltp":1.74,"tv":683.98,"id":17467774},{"batb":[[0,8,9.21],[1,1.01,0.51],[2,8,0]],"ltp":4.9,"tv":35.28,"id":16775230}]}]}
{"op":"mcm","clk":"1004384344","pt":1580654750947,"mc":[{"id":"1.168224028","rc":[{"batb":[[0,8.8,15.45],[1,8.6,19.15],[2,7.6,10.15]],"ltp":0.0,"tv":0.0,"id":17467775},{"batb":[[1,1.16,321.51],[2,1.15,264.36]],"ltp":1.74,"tv":683.98,"id":17467774},{"batb":[[0,9.2,19.49],[1,9,18.11],[2,8,9.21]],"ltp":4.9,"tv":35.28,"id":16775230}]}]}
{"op":"mcm","clk":"1004384974","pt":1580654753718,"mc":[{"id":"1.168224028","rc":[{"batb":[[0,7.6,10.15],[1,1.01,0.51],[2,7.6,0]],"ltp":0.0,"tv":0.0,"id":17467775},{"batb":[[0,8,9.21],[1,1.01,0.51],[2,8,0]],"ltp":4.9,"tv":35.28,"id":16775230}]}]}
{"op":"mcm","clk":"1004385658","pt":1580654757029,"mc":[{"id":"1.168224028","rc":[{"batb":[[0,12.5,18.19],[1,12,22.92],[2,7.6,10.15]],"ltp":0.0,"tv":0.0,"id":17467775},{"batb":[[0,13,25.16],[1,12.5,21.82],[2,8,9.21]],"ltp":4.9,"tv":35.28,"id":16775230}]}]}
