{"op":"mcm","clk":"997862772","pt":1580583479664,"mc":[{"id":"1.168224029","marketDefinition":{"bspMarket":false,"turnInPlayEnabled":true,"persistenceEnabled":true,"marketBaseRate":5.0,"eventId":"29681672","eventTypeId":"2","numberOfWinners":1,"bettingType":"ODDS","marketType":"SET_WINNER","marketTime":"2020-02-02T13:00:00.000Z","suspendTime":"2020-02-02T13:00:00.000Z","bspReconciled":false,"complete":true,"inPlay":false,"crossMatching":false,"runnersVoidable":false,"numberOfActiveRunners":2,"betDelay":0,"status":"OPEN","runners":[{"status":"ACTIVE","sortPriority":1,"id":8908205,"name":"Juan Pablo Ficovich"},{"status":"ACTIVE","sortPriority":2,"id":4596961,"name":"Filip Horansky"}],"regulators":["MR_INT"],"countryCode":"AR","discountAllowed":false,"timezone":"UTC","openDate":"2020-02-02T13:00:00.000Z","version":3146950732,"name":"Set 1 Winner","eventName":"Ficovich v Horansky"},"rc":[{"batb":[[0,1.01,20]],"ltp":0.0,"tv":0.0,"id":8908205},{"batb":[[0,1.01,20]],"ltp":0.0,"tv":0.0,"id":4596961}]}]}
{"op":"mcm","clk":"997863080","pt":1580583482122,"mc":[{"id":"1.168224029","marketDefinition":{"bspMarket":false,"turnInPlayEnabled":true,"persistenceEnabled":true,"marketBaseRate":5.0,"eventId":"29681672","eventTypeId":"2","numberOfWinners":1,"bettingType":"ODDS","marketType":"SET_WINNER","marketTime":"2020-02-02T13:00:00.000Z","suspendTime":"2020-02-02T13:00:00.000Z","bspReconciled":false,"complete":true,"inPlay":false,"crossMatching":false,"runnersVoidable":false,"numberOfActiveRunners":2,"betDelay":0,"status":"OPEN","runners":[{"status":"ACTIVE","sortPriority":1,"id":8908205,"name":"Juan Pablo Ficovich"},{"status":"ACTIVE","sortPriority":2,"id":4596961,"name":"Filip Horansky"}],"regulators":["MR_INT"],"countryCode":"AR","discountAllowed":true,"timezone":"UTC","openDate":"2020-02-02T13:00:00.000Z","version":3146950732,"name":"Set 1 Winner","eventName":"Ficovich v Horansky"}}]}
{"op":"mcm","clk":"997881409","pt":1580583623459,"mc":[{"id":"1.168224029","rc":[{"batb":[[0,1.01,10]],"ltp":0.0,"tv":0.0,"id":8908205},{"batb":[[0,1.01,10]],"ltp":0.0,"tv":0.0,"id":4596961}]}]}
{"op":"mcm","clk":"998890757","pt":1580590302846,"mc":[{"id":"1.168224029","marketDefinition":{"bspMarket":false,"turnInPlayEnabled":true,"persistenceEnabled":true,"marketBaseRate":5.0,"eventId":"29681672","eventTypeId":"2","numberOfWinners":1,"bettingType":"ODDS","marketType":"SET_WINNER","marketTime":"2020-02-02T14:00:00.000Z","suspendTime":"2020-02-02T14:00:00.000Z","bspReconciled":false,"complete":true,"inPlay":false,"crossMatching":false,"runnersVoidable":false,"numberOfActiveRunners":2,"betDelay":0,"status":"OPEN","runners":[{"status":"ACTIVE","sortPriority":1,"id":8908205,"name":"Juan Pablo Ficovich"},{"status":"ACTIVE","sortPriority":2,"id":4596961,"name":"Filip Horansky"}],"regulators":["MR_INT"],"countryCode":"AR","discountAllowed":true,"timezone":"UTC","openDate":"2020-02-02T13:00:00.000Z","version":3147422059,"name":"Set 1 Winner","eventName":"Ficovich v Horansky"}}]}
{"op":"mcm","clk":"998891049","pt":1580590304855,"mc":[{"id":"1.168224029","marketDefinition":{"bspMarket":false,"turnInPlayEnabled":true,"persistenceEnabled":true,"marketBaseRate":5.0,"eventId":"29681672","eventTypeId":"2","numberOfWinners":1,"bettingType":"ODDS","marketType":"SET_WINNER","marketTime":"2020-02-02T14:00:00.000Z","suspendTime":"2020-02-02T14:00:00.000Z","bspReconciled":false,"complete":true,"inPlay":false,"crossMatching":false,"runnersVoidable":false,"numberOfActiveRunners":2,"betDelay":0,"status":"OPEN","runners":[{"status":"ACTIVE","sortPriority":1,"id":8908205,"name":"Juan Pablo Ficovich"},{"status":"ACTIVE","sortPriority":2,"id":4596961,"name":"Filip Horansky"}],"regulators":["MR_INT"],"countryCode":"AR","discountAllowed":true,"timezone":"UTC","openDate":"2020-02-02T14:00:00.000Z","version":3147422059,"name":"Set 1 Winner","eventName":"Ficovich v Horansky"}}]}
{"op":"mcm","clk":"999926919","pt":1580602758073,"mc":[{"id":"1.168224029","rc":[{"batb":[[0,1.01,10.51]],"ltp":0.0,"tv":0.0,"id":8908205},{"batb":[[0,1.01,10.51]],"ltp":0.0,"tv":0.0,"id":4596961}]}]}
{"op":"mcm","clk":"999971968","pt":1580603522041,"mc":[{"id":"1.168224029","rc":[{"batb":[[0,1.01,11.01]],"ltp":0.0,"tv":0.0,"id":8908205},{"batb":[[0,1.01,11.01]],"ltp":0.0,"tv":0.0,"id":4596961}]}]}
{"op":"mcm","clk":"1002689950","pt":1580645901658,"mc":[{"id":"1.168224029","rc":[{"batl":[[0,3.05,4.54]],"ltp":0.0,"tv":0.0,"id":8908205},{"batl":[[0,3.1,4.54]],"ltp":0.0,"tv":0.0,"id":4596961}]}]}
{"op":"mcm","clk":"1003143017","pt":1580648425770,"mc":[{"id":"1.168224029","rc":[{"batb":[[0,1.02,2],[1,1.01,11.01]],"ltp":0.0,"tv":0.0,"id":8908205},{"batb":[[0,1.02,2],[1,1.01,11.01]],"ltp":0.0,"tv":0.0,"id":4596961}]}]}
{"op":"mcm","clk":"1003146345","pt":1580648445808,"mc":[{"id":"1.168224029","marketDefinition":{"bspMarket":false,"turnInPlayEnabled":true,"persistenceEnabled":true,"marketBaseRate":5.0,"eventId":"29681672","eventTypeId":"2","numberOfWinners":1,"bettingType":"ODDS","marketType":"SET_WINNER","marketTime":"2020-02-02T14:00:00.000Z","suspendTime":"2020-02-02T14:00:00.000Z","bspReconciled":false,"complete":true,"inPlay":false,"crossMatching":true,"runnersVoidable":false,"numberOfActiveRunners":2,"betDelay":0,"status":"OPEN","runners":[{"status":"ACTIVE","sortPriority":1,"id":8908205,"name":"Juan Pablo Ficovich"},{"status":"ACTIVE","sortPriority":2,"id":4596961,"name":"Filip Horansky"}],"regulators":["MR_INT"],"countryCode":"AR","discountAllowed":true,"timezone":"UTC","openDate":"2020-02-02T14:00:00.000Z","version":3147422059,"name":"Set 1 Winner","eventName":"Ficovich v Horansky"}}]}
{"op":"mcm","clk":"1003252982","pt":1580649025057,"mc":[{"id":"1.168224029","rc":[{"batb":[[0,1.01,11.01],[1,1.01,0]],"ltp":0.0,"tv":0.0,"id":8908205}]}]}
{"op":"mcm","clk":"1003253018","pt":1580649025268,"mc":[{"id":"1.168224029","rc":[{"batb":[[0,1.01,11.01],[1,1.01,0]],"ltp":0.0,"tv":0.0,"id":4596961}]}]}
{"op":"mcm","clk":"1003257698","pt":1580649049375,"mc":[{"id":"1.168224029","rc":[{"batb":[[0,1.48,2],[1,1.01,11.01]],"ltp":0.0,"tv":0.0,"id":8908205},{"batb":[[0,1.49,2],[1,1.01,11.01]],"ltp":0.0,"tv":0.0,"id":4596961}]}]}
{"op":"mcm","clk":"1003364676","pt":1580649648925,"mc":[{"id":"1.168224029","rc":[{"batb":[[0,1.01,11.01],[1,1.01,0]],"ltp":0.0,"tv":0.0,"id":8908205},{"batb":[[0,1.01,11.01],[1,1.01,0]],"ltp":0.0,"tv":0.0,"id":4596961}]}]}
{"op":"mcm","clk":"1003365612","pt":1580649654950,"mc":[{"id":"1.168224029","rc":[{"batb":[[0,1.48,2],[1,1.01,11.01]],"ltp":0.0,"tv":0.0,"id":8908205},{"batb":[[0,1.49,2],[1,1.01,11.01]],"ltp":0.0,"tv":0.0,"id":4596961}]}]}
{"op":"mcm","clk":"1003460106","pt":1580650254551,"mc":[{"id":"1.168224029","rc":[{"batb":[[0,1.01,11.01],[1,1.01,0]],"ltp":0.0,"tv":0.0,"id":8908205},{"batb":[[0,1.01,11.01],[1,1.01,0]],"ltp":0.0,"tv":0.0,"id":4596961}]}]}
{"op":"mcm","clk":"1003460955","pt":1580650259965,"mc":[{"id":"1.168224029","rc":[{"batb":[[0,1.48,2],[1,1.01,11.01]],"ltp":0.0,"tv":0.0,"id":8908205},{"batb":[[0,1.49,2],[1,1.01,11.01]],"ltp":0.0,"tv":0.0,"id":4596961}]}]}
{"op":"mcm","clk":"1003567198","pt":1580650859468,"mc":[{"id":"1.168224029","rc":[{"batb":[[0,1.01,11.01],[1,1.01,0]],"ltp":0.0,"tv":0.0,"id":8908205},{"batb":[[0,1.01,11.01],[1,1.01,0]],"ltp":0.0,"tv":0.0,"id":4596961}]}]}
{"op":"mcm","clk":"1003569254","pt":1580650870682,"mc":[{"id":"1.168224029","rc":[{"batb":[[0,1.48,2],[1,1.01,11.01]],"ltp":0.0,"tv":0.0,"id":8908205},{"batb":[[0,1.49,2],[1,1.01,11.01]],"ltp":0.0,"tv":0.0,"id":4596961}]}]}
{"op":"mcm","clk":"1003685552","pt":1580651470037,"mc":[{"id":"1.168224029","rc":[{"batb":[[0,1.01,11.01],[1,1.01,0]],"ltp":0.0,"tv":0.0,"id":4596961}]}]}
{"op":"mcm","clk":"1003685582","pt":1580651470208,"mc":[{"id":"1.168224029","rc":[{"batb":[[0,1.01,11.01],[1,1.01,0]],"ltp":0.0,"tv":0.0,"id":8908205}]}]}
{"op":"mcm","clk":"1003689059","pt":1580651489464,"mc":[{"id":"1.168224029","rc":[{"batb":[[0,1.48,2],[1,1.01,11.01]],"ltp":0.0,"tv":0.0,"id":8908205},{"batb":[[0,1.49,2],[1,1.01,11.01]],"ltp":0.0,"tv":0.0,"id":4596961}]}]}
{"op":"mcm","clk":"1003721298","pt":1580651668923,"mc":[{"id":"1.168224029","rc":[{"batb":[[0,1.01,11.01],[1,1.01,0]],"ltp":0.0,"tv":0.0,"id":8908205},{"batb":[[0,1.01,11.01],[1,1.01,0]],"ltp":0.0,"tv":0.0,"id":4596961}]}]}
{"op":"mcm","clk":"1003724059","pt":1580651684057,"mc":[{"id":"1.168224029","rc":[{"batb":[[0,1.48,2],[1,1.01,11.01]],"ltp":0.0,"tv":0.0,"id":8908205},{"batb":[[0,1.49,2],[1,1.01,11.01]],"ltp":0.0,"tv":0.0,"id":4596961}]}]}
{"op":"mcm","clk":"1003757274","pt":1580651863509,"mc":[{"id":"1.168224029","rc":[{"batb":[[0,1.01,11.01],[1,1.01,0]],"ltp":0.0,"tv":0.0,"id":8908205},{"batb":[[0,1.01,11.01],[1,1.01,0]],"ltp":0.0,"tv":0.0,"id":4596961}]}]}
{"op":"mcm","clk":"1003760277","pt":1580651879809,"mc":[{"id":"1.168224029","rc":[{"batb":[[0,1.48,2],[1,1.01,11.01]],"ltp":0.0,"tv":0.0,"id":8908205},{"batb":[[0,1.49,2],[1,1.01,11.01]],"ltp":0.0,"tv":0.0,"id":4596961}]}]}
{"op":"mcm","clk":"1003772001","pt":1580651939025,"mc":[{"id":"1.168224029","rc":[{"batb":[[0,1.01,11.01],[1,1.01,0]],"ltp":0.0,"tv":0.0,"id":8908205}]}]}
{"op":"mcm","clk":"1003772041","pt":1580651939231,"mc":[{"id":"1.168224029","rc":[{"batb":[[0,1.01,11.01],[1,1.01,0]],"ltp":0.0,"tv":0.0,"id":4596961}]}]}
{"op":"mcm","clk":"1003776927","pt":1580651963117,"mc":[{"id":"1.168224029","rc":[{"batb":[[0,1.48,2],[1,1.01,11.01]],"ltp":0.0,"tv":0.0,"id":8908205},{"batb":[[0,1.49,2],[1,1.01,11.01]],"ltp":0.0,"tv":0.0,"id":4596961}]}]}
{"op":"mcm","clk":"1003789257","pt":1580652022494,"mc":[{"id":"1.168224029","rc":[{"batb":[[0,1.01,11.01],[1,1.01,0]],"ltp":0.0,"tv":0.0,"id":8908205},{"batb":[[0,1.01,11.01],[1,1.01,0]],"ltp":0.0,"tv":0.0,"id":4596961}]}]}
{"op":"mcm","clk":"1003790302","pt":1580652027709,"mc":[{"id":"1.168224029","rc":[{"batb":[[0,1.48,2],[1,1.01,11.01]],"ltp":0.0,"tv":0.0,"id":8908205},{"batb":[[0,1.49,2],[1,1.01,11.01]],"ltp":0.0,"tv":0.0,"id":4596961}]}]}
{"op":"mcm","clk":"1003802251","pt":1580652086944,"mc":[{"id":"1.168224029","rc":[{"batb":[[0,1.01,11.01],[1,1.01,0]],"ltp":0.0,"tv":0.0,"id":4596961}]}]}
{"op":"mcm","clk":"1003802292","pt":1580652087156,"mc":[{"id":"1.168224029","rc":[{"batb":[[0,1.01,11.01],[1,1.01,0]],"ltp":0.0,"tv":0.0,"id":8908205}]}]}
{"op":"mcm","clk":"1003804455","pt":1580652097370,"mc":[{"id":"1.168224029","rc":[{"batb":[[0,1.87,17.47],[1,1.01,11.01]],"ltp":0.0,"tv":0.0,"id":8908205},{"batb":[[0,2,27.7],[1,1.01,11.01]],"ltp":0.0,"tv":0.0,"id":4596961}]}]}
{"op":"mcm","clk":"1003823937","pt":1580652185875,"mc":[{"id":"1.168224029","rc":[{"batb":[[1,1.82,50.41],[2,1.01,11.01]],"batl":[[0,2,42.01],[1,3.05,4.54]],"ltp":0.0,"tv":0.0,"id":8908205},{"batb":[[0,2,69.71]],"batl":[[0,2.24,33.61],[1,3.1,4.54]],"ltp":0.0,"tv":0.0,"id":4596961}]}]}
{"op":"mcm","clk":"1003824171","pt":1580652186854,"mc":[{"id":"1.168224029","rc":[{"batb":[[1,1.85,17.86],[2,1.82,50.41]],"ltp":0.0,"tv":0.0,"id":8908205},{"batb":[[0,2.02,27.07],[1,2,42.01],[2,1.01,11.01]],"ltp":0.0,"tv":0.0,"id":4596961}]}]}
{"op":"mcm","clk":"1003827037","pt":1580652199402,"mc":[{"id":"1.168224029","rc":[{"batb":[[0,1.84,18.25],[1,1.82,50.41],[2,1.01,11.01]],"ltp":0.0,"tv":0.0,"id":8908205},{"batb":[[0,2.04,26.52]],"ltp":0.0,"tv":0.0,"id":4596961}]}]}
{"op":"mcm","clk":"1003858478","pt":1580652330433,"mc":[{"id":"1.168224029","rc":[{"batb":[[1,1.83,18.65],[2,1.82,50.41]],"ltp":0.0,"tv":0.0,"id":8908205},{"batb":[[0,2.06,25.89]],"ltp":0.0,"tv":0.0,"id":4596961}]}]}
{"op":"mcm","clk":"1003864190","pt":1580652354115,"mc":[{"id":"1.168224029","rc":[{"batb":[[2,1.82,69.3]],"ltp":0.0,"tv":0.0,"id":8908205}]}]}
{"op":"mcm","clk":"1003864238","pt":1580652354298,"mc":[{"id":"1.168224029","rc":[{"batb":[[0,1.82,69.3],[1,1.01,11.01],[2,1.82,0]],"ltp":0.0,"tv":0.0,"id":8908205},{"batb":[[0,2.06,25.65]],"ltp":0.0,"tv":0.0,"id":4596961}]}]}
{"op":"mcm","clk":"1003867109","pt":1580652365928,"mc":[{"id":"1.168224029","rc":[{"batb":[[1,1.01,12.69]],"ltp":0.0,"tv":0.0,"id":8908205},{"batb":[[2,1.01,12.69]],"ltp":0.0,"tv":0.0,"id":4596961}]}]}
{"op":"mcm","clk":"1003867579","pt":1580652368068,"mc":[{"id":"1.168224029","rc":[{"batb":[[0,1.83,1.38],[1,1.82,69.3],[2,1.01,11.01]],"ltp":0.0,"tv":0.0,"id":8908205},{"batb":[[0,2.08,1.21],[1,2.06,25.65],[2,2,42.01]],"ltp":0.0,"tv":0.0,"id":4596961}]}]}
{"op":"mcm","clk":"1003870772","pt":1580652381954,"mc":[{"id":"1.168224029","rc":[{"batb":[[1,2.06,25.41]],"ltp":0.0,"tv":0.0,"id":4596961}]}]}
{"op":"mcm","clk":"1003875886","pt":1580652403091,"mc":[{"id":"1.168224029","rc":[{"batb":[[1,1.82,50.41]],"ltp":0.0,"tv":0.0,"id":8908205},{"batb":[[1,2,42.01],[2,1.01,11.01]],"ltp":0.0,"tv":0.0,"id":4596961}]}]}
{"op":"mcm","clk":"1003876018","pt":1580652403595,"mc":[{"id":"1.168224029","marketDefinition":{"bspMarket":false,"turnInPlayEnabled":true,"persistenceEnabled":true,"marketBaseRate":5.0,"eventId":"29681672","eventTypeId":"2","numberOfWinners":1,"bettingType":"ODDS","marketType":"SET_WINNER","marketTime":"2020-02-02T14:00:00.000Z","suspendTime":"2020-02-02T14:00:00.000Z","bspReconciled":false,"complete":true,"inPlay":true,"crossMatching":true,"runnersVoidable":false,"numberOfActiveRunners":2,"betDelay":3,"status":"OPEN","runners":[{"status":"ACTIVE","sortPriority":1,"id":8908205,"name":"Juan Pablo Ficovich"},{"status":"ACTIVE","sortPriority":2,"id":4596961,"name":"Filip Horansky"}],"regulators":["MR_INT"],"countryCode":"AR","discountAllowed":true,"timezone":"UTC","openDate":"2020-02-02T14:00:00.000Z","version":3149116742,"name":"Set 1 Winner","eventName":"Ficovich v Horansky"},"rc":[{"batb":[[0,1.01,10.51],[1,1.82,0],[2,1.01,0]],"ltp":0.0,"tv":0.0,"id":8908205},{"batb":[[0,1.01,10.51],[1,2,0],[2,1.01,0]],"ltp":0.0,"tv":0.0,"id":4596961}]}]}
{"op":"mcm","clk":"1003876886","pt":1580652407004,"mc":[{"id":"1.168224029","rc":[{"batb":[[0,1.82,50.41],[1,1.01,10.51]],"batl":[[0,2,42.01]],"ltp":0.0,"tv":0.0,"id":8908205},{"batb":[[0,2,42.01],[1,1.01,10.51]],"batl":[[0,2.24,33.61]],"ltp":0.0,"tv":0.0,"id":4596961}]}]}
{"op":"mcm","clk":"1003876959","pt":1580652407313,"mc":[{"id":"1.168224029","rc":[{"batb":[[0,1.01,10.51],[1,1.01,0]],"ltp":0.0,"tv":0.0,"id":8908205},{"batb":[[0,1.01,10.51],[1,1.01,0]],"ltp":0.0,"tv":0.0,"id":4596961}]}]}
{"op":"mcm","clk":"1003877907","pt":1580652410794,"mc":[{"id":"1.168224029","rc":[{"batb":[[0,1.85,161.9],[1,1.83,167.57],[2,1.01,10.51]],"batl":[[0,1.93,110.41],[1,1.95,139.59]],"ltp":0.0,"tv":0.0,"id":8908205}]}]}
{"op":"mcm","clk":"1003878103","pt":1580652411692,"mc":[{"id":"1.168224029","rc":[{"batb":[[0,1.01,10.51],[1,1.83,0],[2,1.01,0]],"ltp":0.0,"tv":0.0,"id":8908205}]}]}
{"op":"mcm","clk":"1003879096","pt":1580652415469,"mc":[{"id":"1.168224029","rc":[{"batb":[[0,1.72,134.18],[1,1.7,214.44],[2,1.01,10.51]],"batl":[[0,2.12,107.63],[1,2.14,106.32]],"ltp":0.0,"tv":0.0,"id":8908205}]}]}
{"op":"mcm","clk":"1003881581","pt":1580652425091,"mc":[{"id":"1.168224029","rc":[{"batb":[[2,1.67,25.41]],"batl":[[0,1.79,177.44],[1,1.81,175.78]],"ltp":0.0,"tv":0.0,"id":8908205},{"batb":[[0,2.3,18.57],[1,2.08,24.78],[2,1.01,10.51]],"ltp":0.0,"tv":0.0,"id":4596961}]}]}
{"op":"mcm","clk":"1003881761","pt":1580652425755,"mc":[{"id":"1.168224029","rc":[{"batb":[[2,1.68,61.33]],"ltp":0.0,"tv":0.0,"id":8908205},{"batb":[[1,2.2,34.45],[2,2.08,24.78]],"batl":[[0,2.5,27.73]],"ltp":0.0,"tv":0.0,"id":4596961}]}]}
{"op":"mcm","clk":"1003882219","pt":1580652427485,"mc":[{"id":"1.168224029","rc":[{"batl":[[2,1.83,42.01]],"ltp":0.0,"tv":0.0,"id":8908205}]}]}
{"op":"mcm","clk":"1003884355","pt":1580652435514,"mc":[{"id":"1.168224029","rc":[{"batb":[[0,1.68,61.33],[1,1.54,34.07],[2,1.01,10.51]],"batl":[[0,1.83,42.01],[1,1.81,0],[2,1.83,0]],"ltp":0.0,"tv":0.0,"id":8908205},{"batb":[[0,2.2,34.45],[1,2.08,24.78],[2,1.01,10.51]],"ltp":0.0,"tv":0.0,"id":4596961}]}]}
{"op":"mcm","clk":"1003884643","pt":1580652436533,"mc":[{"id":"1.168224029","rc":[{"batb":[[0,1.54,34.07],[1,1.01,10.51],[2,1.01,0]],"ltp":0.0,"tv":0.0,"id":8908205},{"batb":[[0,2.08,24.78],[1,1.01,10.51],[2,1.01,0]],"ltp":0.0,"tv":0.0,"id":4596961}]}]}
{"op":"mcm","clk":"1003885049","pt":1580652438116,"mc":[{"id":"1.168224029","rc":[{"batb":[[0,1.55,217.32],[1,1.54,189.5],[2,1.01,10.51]],"batl":[[0,1.94,136.76],[1,1.96,137.45]],"ltp":0.0,"tv":0.0,"id":8908205}]}]}
{"op":"mcm","clk":"1003885215","pt":1580652438720,"mc":[{"id":"1.168224029","rc":[{"batb":[[1,1.54,155.43],[2,1.53,34.38]],"ltp":0.0,"tv":0.0,"id":8908205}]}]}
{"op":"mcm","clk":"1003886700","pt":1580652443536,"mc":[{"id":"1.168224029","rc":[{"batl":[[0,1.61,217.45],[1,1.62,126.79]],"ltp":0.0,"tv":0.0,"id":8908205}]}]}
{"op":"mcm","clk":"1003887126","pt":1580652445099,"mc":[{"id":"1.168224029","rc":[{"batb":[[0,2.62,13.06],[1,2.36,17.31],[2,1.01,10.51]],"ltp":0.0,"tv":0.0,"id":4596961}]}]}
{"op":"mcm","clk":"1003887261","pt":1580652445638,"mc":[{"id":"1.168224029","rc":[{"batl":[[2,1.65,42.01]],"ltp":0.0,"tv":0.0,"id":8908205},{"batl":[[0,2.92,21.85]],"ltp":0.0,"tv":0.0,"id":4596961}]}]}
{"op":"mcm","clk":"1003887580","pt":1580652446808,"mc":[{"id":"1.168224029","rc":[{"batb":[[1,2.54,26.89],[2,2.36,17.31]],"ltp":0.0,"tv":0.0,"id":4596961}]}]}
{"op":"mcm","clk":"1003890531","pt":1580652458052,"mc":[{"id":"1.168224029","rc":[{"batb":[[0,1.52,80.66],[1,1.43,45.08],[2,1.01,10.51]],"batl":[[0,1.65,42.01],[1,1.62,0],[2,1.65,0]],"ltp":0.0,"tv":0.0,"id":8908205},{"batb":[[0,2.54,26.89],[1,2.36,17.31],[2,1.01,10.51]],"ltp":0.0,"tv":0.0,"id":4596961}]}]}
{"op":"mcm","clk":"1003890601","pt":1580652458340,"mc":[{"id":"1.168224029","rc":[{"batb":[[0,1.43,45.08],[1,1.01,10.51],[2,1.01,0]],"ltp":0.0,"tv":0.0,"id":8908205},{"batb":[[0,2.36,17.31],[1,1.01,10.51],[2,1.01,0]],"ltp":0.0,"tv":0.0,"id":4596961}]}]}
{"op":"mcm","clk":"1003891240","pt":1580652460812,"mc":[{"id":"1.168224029","rc":[{"batb":[[1,1.42,176.93],[2,1.41,224.26]],"batl":[[0,1.73,145.07],[1,1.75,196.24]],"ltp":0.0,"tv":0.0,"id":8908205}]}]}
{"op":"mcm","clk":"1003891557","pt":1580652462010,"mc":[{"id":"1.168224029","rc":[{"batb":[[1,1.01,10.51],[2,1.41,0]],"ltp":0.0,"tv":0.0,"id":8908205}]}]}
{"op":"mcm","clk":"1003892310","pt":1580652465038,"mc":[{"id":"1.168224029","rc":[{"batb":[[0,1.67,124.41],[1,1.66,117.26],[2,1.43,45.08]],"ltp":0.0,"tv":0.0,"id":8908205}]}]}
{"op":"mcm","clk":"1003892584","pt":1580652466042,"mc":[{"id":"1.168224029","rc":[{"batb":[[2,1.64,26.99]],"batl":[[2,1.76,42.01]],"ltp":0.0,"tv":0.0,"id":8908205},{"batb":[[1,2.32,31.09],[2,2.1,24.16]],"batl":[[0,2.62,25.21]],"ltp":0.0,"tv":0.0,"id":4596961}]}]}
{"op":"mcm","clk":"1003895068","pt":1580652475120,"mc":[{"id":"1.168224029","rc":[{"batb":[[0,1.64,26.99],[1,1.61,68.06],[2,1.49,38.16]],"batl":[[0,1.76,42.01],[1,1.75,0],[2,1.76,0]],"ltp":0.0,"tv":0.0,"id":8908205}]}]}
{"op":"mcm","clk":"1003895102","pt":1580652475182,"mc":[{"id":"1.168224029","rc":[{"batb":[[0,1.61,68.06],[1,1.49,38.16],[2,1.01,10.51]],"ltp":0.0,"tv":0.0,"id":8908205},{"batb":[[0,2.32,31.09],[1,2.1,24.16],[2,1.01,10.51]],"ltp":0.0,"tv":0.0,"id":4596961}]}]}
{"op":"mcm","clk":"1003895471","pt":1580652476474,"mc":[{"id":"1.168224029","rc":[{"batb":[[0,1.49,38.16],[1,1.01,10.51],[2,1.01,0]],"ltp":0.0,"tv":0.0,"id":8908205},{"batb":[[0,2.1,24.16],[1,1.01,10.51],[2,1.01,0]],"ltp":0.0,"tv":0.0,"id":4596961}]}]}
{"op":"mcm","clk":"1003895910","pt":1580652478101,"mc":[{"id":"1.168224029","rc":[{"batb":[[1,1.48,218.24],[2,1.47,187.57]],"batl":[[0,1.91,142.95],[1,1.93,144.01]],"ltp":0.0,"tv":0.0,"id":8908205}]}]}
{"op":"mcm","clk":"1003895963","pt":1580652478277,"mc":[{"id":"1.168224029","rc":[{"batb":[[1,1.01,10.51],[2,1.47,0]],"ltp":0.0,"tv":0.0,"id":8908205}]}]}
{"op":"mcm","clk":"1003896614","pt":1580652480711,"mc":[{"id":"1.168224029","rc":[{"batb":[[0,1.62,244.57],[1,1.61,131.41],[2,1.49,38.16]],"batl":[[0,1.69,198.68],[1,1.71,211.68]],"ltp":0.0,"tv":0.0,"id":8908205}]}]}
{"op":"mcm","clk":"1003896973","pt":1580652482082,"mc":[{"id":"1.168224029","rc":[{"batb":[[0,1.49,38.16],[1,1.01,10.51],[2,1.49,0]],"ltp":0.0,"tv":0.0,"id":8908205}]}]}
{"op":"mcm","clk":"1003897788","pt":1580652485102,"mc":[{"id":"1.168224029","rc":[{"batb":[[1,1.48,218.24],[2,1.47,187.57]],"batl":[[0,1.91,142.95],[1,1.93,144.01]],"ltp":0.0,"tv":0.0,"id":8908205}]}]}
{"op":"mcm","clk":"1003898001","pt":1580652485929,"mc":[{"id":"1.168224029","rc":[{"batb":[[1,1.01,10.51],[2,1.47,0]],"ltp":0.0,"tv":0.0,"id":8908205}]}]}
{"op":"mcm","clk":"1003898837","pt":1580652488907,"mc":[{"id":"1.168224029","rc":[{"batb":[[1,1.48,218.24],[2,1.47,187.57]],"batl":[[0,1.53,200.94],[1,1.54,152.85]],"ltp":0.0,"tv":0.0,"id":8908205}]}]}
{"op":"mcm","clk":"1003899058","pt":1580652489695,"mc":[{"id":"1.168224029","rc":[{"batl":[[2,1.56,42.01]],"ltp":0.0,"tv":0.0,"id":8908205},{"batb":[[0,2.78,23.53],[1,2.76,11.49],[2,2.46,15.5]],"batl":[[0,3.25,18.48]],"ltp":0.0,"tv":0.0,"id":4596961}]}]}
{"op":"mcm","clk":"1003902908","pt":1580652503480,"mc":[{"id":"1.168224029","rc":[{"batb":[[0,1.45,93.26],[1,1.39,51.06],[2,1.01,10.51]],"batl":[[0,1.56,42.01],[1,1.54,0],[2,1.56,0]],"ltp":0.0,"tv":0.0,"id":8908205},{"batb":[[1,2.46,15.5],[2,1.01,10.51]],"ltp":0.0,"tv":0.0,"id":4596961}]}]}
{"op":"mcm","clk":"1003903179","pt":1580652504498,"mc":[{"id":"1.168224029","rc":[{"batb":[[0,1.39,51.06],[1,1.01,10.51],[2,1.01,0]],"ltp":0.0,"tv":0.0,"id":8908205},{"batb":[[0,2.46,15.5],[1,1.01,10.51],[2,1.01,0]],"ltp":0.0,"tv":0.0,"id":4596961}]}]}
{"op":"mcm","clk":"1003903684","pt":1580652506390,"mc":[{"id":"1.168224029","rc":[{"batb":[[1,1.35,246.94],[2,1.34,286.24]],"batl":[[0,1.65,138.56],[1,1.66,116.66]],"ltp":0.0,"tv":0.0,"id":8908205}]}]}
{"op":"mcm","clk":"1003907037","pt":1580652518959,"mc":[{"id":"1.168224029","rc":[{"trd":[[1.39,102.12]],"batb":[[0,1.35,246.94],[1,1.34,286.24],[2,1.32,65.31]],"batl":[[0,1.39,245.3],[1,1.4,224.83]],"ltp":1.39,"tv":102.12,"id":8908205},{"batb":[[0,3.15,20.22],[1,2.76,11.57],[2,2.46,15.5]],"ltp":0.0,"tv":0.0,"id":4596961}],"tv":102.12}]}
{"op":"mcm","clk":"1003907265","pt":1580652519754,"mc":[{"id":"1.168224029","rc":[{"batb":[[2,1.01,10.51]],"ltp":0.0,"tv":0.0,"id":4596961}]}]}
{"op":"mcm","clk":"1003907746","pt":1580652521661,"mc":[{"id":"1.168224029","rc":[{"batl":[[0,1.39,280.16]],"ltp":1.39,"tv":102.12,"id":8908205}]}]}
{"op":"mcm","clk":"1003907906","pt":1580652522145,"mc":[{"id":"1.168224029","rc":[{"batl":[[0,1.36,42.01],[1,1.39,280.16],[2,1.4,224.83]],"ltp":1.39,"tv":102.12,"id":8908205},{"batb":[[0,3.75,15.12],[1,3.15,20.22],[2,2.76,11.57]],"batl":[[0,4.5,11.76]],"ltp":0.0,"tv":0.0,"id":4596961}]}]}
{"op":"mcm","clk":"1003909520","pt":1580652527953,"mc":[{"id":"1.168224029","rc":[{"trd":[[1.36,84.02],[1.37,11.49]],"batb":[[2,1.31,68.37]],"batl":[[0,1.39,280.16],[1,1.4,224.83],[2,1.4,0]],"ltp":1.37,"tv":197.63,"id":8908205},{"trd":[[3.75,4.2]],"batb":[[0,3.75,10.92],[1,3.3,18.96],[2,2.9,10.86]],"ltp":3.75,"tv":4.2,"id":4596961}],"tv":201.83}]}
{"op":"mcm","clk":"1003910335","pt":1580652530807,"mc":[{"id":"1.168224029","rc":[{"batl":[[0,1.37,42.01],[1,1.39,280.16],[2,1.4,224.83]],"ltp":1.37,"tv":197.63,"id":8908205},{"batb":[[0,3.75,15.12]],"batl":[[0,4.3,12.6]],"ltp":3.75,"tv":4.2,"id":4596961}]}]}
{"op":"mcm","clk":"1003911695","pt":1580652535518,"mc":[{"id":"1.168224029","rc":[{"trd":[[1.37,108.74]],"batb":[[2,1.3,70.5]],"batl":[[0,1.39,280.16],[1,1.4,224.83],[2,1.4,0]],"ltp":1.37,"tv":294.88,"id":8908205},{"trd":[[3.75,9.03]],"batb":[[0,3.4,18.25],[1,2.94,10.46],[2,1.01,10.51]],"ltp":3.75,"tv":9.03,"id":4596961}],"tv":303.91}]}
{"op":"mcm","clk":"1003912488","pt":1580652538526,"mc":[{"id":"1.168224029","rc":[{"batb":[[2,1.3,209.97]],"batl":[[0,1.37,42.01],[1,1.39,280.16],[2,1.4,224.83]],"ltp":1.37,"tv":294.88,"id":8908205},{"batb":[[0,3.65,15.12],[1,3.4,18.25],[2,2.94,10.46]],"batl":[[0,4.2,12.6]],"ltp":3.75,"tv":9.03,"id":4596961}]}]}
{"op":"mcm","clk":"1003916942","pt":1580652555853,"mc":[{"id":"1.168224029","rc":[{"batb":[[0,1.3,209.97],[1,1.01,10.51],[2,1.3,0]],"batl":[[1,1.39,0],[2,1.4,0]],"ltp":1.37,"tv":294.88,"id":8908205}]}]}
{"op":"mcm","clk":"1003917688","pt":1580652558672,"mc":[{"id":"1.168224029","rc":[{"batb":[[1,1.29,396.04],[2,1.28,367.64]],"batl":[[1,1.49,149.91],[2,1.5,169.64]],"ltp":1.37,"tv":294.88,"id":8908205}]}]}
{"op":"mcm","clk":"1003918859","pt":1580652563382,"mc":[{"id":"1.168224029","rc":[{"batb":[[1,2.94,10.46],[2,1.01,10.51]],"ltp":3.75,"tv":9.03,"id":4596961}]}]}
{"op":"mcm","clk":"1003919109","pt":1580652564480,"mc":[{"id":"1.168224029","rc":[{"batb":[[0,1.3,70.5]],"batl":[[0,1.49,149.91],[1,1.5,169.64],[2,1.5,0]],"ltp":1.37,"tv":294.88,"id":8908205},{"batb":[[0,2.94,10.46],[1,1.01,10.51],[2,1.01,0]],"ltp":3.75,"tv":9.03,"id":4596961}]}]}
{"op":"mcm","clk":"1003919566","pt":1580652566460,"mc":[{"id":"1.168224029","rc":[{"batb":[[0,2.98,25.41]],"ltp":3.75,"tv":9.03,"id":4596961}]}]}
{"op":"mcm","clk":"1003922769","pt":1580652579326,"mc":[{"id":"1.168224029","rc":[{"batb":[[1,1.01,10.51],[2,1.28,0]],"ltp":1.37,"tv":294.88,"id":8908205}]}]}
{"op":"mcm","clk":"1003923729","pt":1580652583041,"mc":[{"id":"1.168224029","rc":[{"batb":[[0,1.45,200.11],[1,1.44,204.27],[2,1.37,55.86]],"ltp":1.37,"tv":294.88,"id":8908205},{"batb":[[1,2.6,14.4],[2,1.01,10.51]],"ltp":3.75,"tv":9.03,"id":4596961}]}]}
{"op":"mcm","clk":"1003923905","pt":1580652583658,"mc":[{"id":"1.168224029","rc":[{"batb":[[2,1.39,107.54]],"batl":[[0,1.47,42.01],[1,1.49,149.91],[2,1.5,169.64]],"ltp":1.37,"tv":294.88,"id":8908205},{"batb":[[0,3.15,19.32],[1,2.98,25.41],[2,2.6,14.4]],"batl":[[0,3.6,15.96]],"ltp":3.75,"tv":9.03,"id":4596961}]}]}
{"op":"mcm","clk":"1003927564","pt":1580652598107,"mc":[{"id":"1.168224029","rc":[{"batb":[[0,1.45,42.72],[1,1.39,107.54],[2,1.37,55.86]],"batl":[[1,1.49,0],[2,1.5,0]],"ltp":1.37,"tv":294.88,"id":8908205}]}]}
{"op":"mcm","clk":"1003927750","pt":1580652598838,"mc":[{"id":"1.168224029","rc":[{"batb":[[0,1.37,55.86],[1,1.01,10.51],[2,1.37,0]],"ltp":1.37,"tv":294.88,"id":8908205},{"batb":[[0,2.6,14.4],[1,1.01,10.51],[2,2.6,0]],"ltp":3.75,"tv":9.03,"id":4596961}]}]}
{"op":"mcm","clk":"1003928531","pt":1580652602109,"mc":[{"id":"1.168224029","rc":[{"batb":[[1,1.36,375.35],[2,1.35,277.78]],"batl":[[0,1.65,215.54],[1,1.66,116.49]],"ltp":1.37,"tv":294.88,"id":8908205},{"batb":[[0,2.58,14.48]],"ltp":3.75,"tv":9.03,"id":4596961}]}]}
{"op":"mcm","clk":"1003929548","pt":1580652606107,"mc":[{"id":"1.168224029","rc":[{"batb":[[1,1.01,10.51],[2,1.35,0]],"ltp":1.37,"tv":294.88,"id":8908205}]}]}
{"op":"mcm","clk":"1003930459","pt":1580652609926,"mc":[{"id":"1.168224029","rc":[{"batb":[[0,1.59,154.39],[1,1.58,140.72],[2,1.57,31.55]],"batl":[[0,1.61,42.01],[1,1.65,215.54],[2,1.66,116.49]],"ltp":1.37,"tv":294.88,"id":8908205},{"batb":[[0,2.62,25.21],[1,2.58,14.48],[2,2.3,19.99]],"batl":[[0,2.96,21]],"ltp":3.75,"tv":9.03,"id":4596961}]}]}
{"op":"mcm","clk":"1003935714","pt":1580652630542,"mc":[{"id":"1.168224029","rc":[{"batb":[[0,1.48,40.13],[1,1.01,10.51],[2,1.57,0]],"ltp":1.37,"tv":294.88,"id":8908205},{"batb":[[0,2.3,19.99],[1,1.01,10.51],[2,2.3,0]],"ltp":3.75,"tv":9.03,"id":4596961}]}]}
{"op":"mcm","clk":"1003936390","pt":1580652633193,"mc":[{"id":"1.168224029","rc":[{"batb":[[0,1.48,339.87],[1,1.47,188.3],[2,1.01,10.51]],"batl":[[0,1.84,149.06],[1,1.86,161.5]],"ltp":1.37,"tv":294.88,"id":8908205}]}]}
{"op":"mcm","clk":"1003937518","pt":1580652637791,"mc":[{"id":"1.168224029","rc":[{"batl":[[0,1.54,277.97],[1,1.55,148.84]],"ltp":1.37,"tv":294.88,"id":8908205}]}]}
{"op":"mcm","clk":"1003937769","pt":1580652638721,"mc":[{"id":"1.168224029","rc":[{"batb":[[2,1.37,54.61]],"ltp":1.37,"tv":294.88,"id":8908205},{"batb":[[0,2.9,10.86],[1,2.46,16.52],[2,1.01,10.51]],"ltp":3.75,"tv":9.03,"id":4596961}]}]}
{"op":"mcm","clk":"1003938128","pt":1580652639995,"mc":[{"id":"1.168224029","rc":[{"batb":[[2,1.43,97.46]],"batl":[[0,1.51,42.01],[1,1.54,277.97],[2,1.55,148.84]],"ltp":1.37,"tv":294.88,"id":8908205},{"batb":[[0,2.94,21],[1,2.9,10.86],[2,2.46,16.52]],"batl":[[0,3.3,17.64]],"ltp":3.75,"tv":9.03,"id":4596961}]}]}
{"op":"mcm","clk":"1003941787","pt":1580652653761,"mc":[{"id":"1.168224029","rc":[{"batb":[[0,1.43,97.46],[1,1.37,54.61],[2,1.01,10.51]],"batl":[[1,1.54,0],[2,1.55,0]],"ltp":1.37,"tv":294.88,"id":8908205},{"batb":[[1,2.46,16.52],[2,1.01,10.51]],"ltp":3.75,"tv":9.03,"id":4596961}]}]}
{"op":"mcm","clk":"1003941993","pt":1580652654549,"mc":[{"id":"1.168224029","rc":[{"batb":[[0,1.37,54.61],[1,1.01,10.51],[2,1.01,0]],"ltp":1.37,"tv":294.88,"id":8908205},{"batb":[[0,2.46,16.52],[1,1.01,10.51],[2,1.01,0]],"ltp":3.75,"tv":9.03,"id":4596961}]}]}
{"op":"mcm","clk":"1003942502","pt":1580652656430,"mc":[{"id":"1.168224029","rc":[{"batb":[[0,1.38,252.75],[1,1.37,311.85],[2,1.01,10.51]],"batl":[[0,1.74,168.27],[1,1.76,192.66]],"ltp":1.37,"tv":294.88,"id":8908205}]}]}
{"op":"mcm","clk":"1003942814","pt":1580652657533,"mc":[{"id":"1.168224029","rc":[{"batb":[[0,1.37,54.61],[1,1.01,10.51],[2,1.01,0]],"ltp":1.37,"tv":294.88,"id":8908205}]}]}
{"op":"mcm","clk":"1003943755","pt":1580652661070,"mc":[{"id":"1.168224029","rc":[{"batb":[[0,1.52,183.22],[1,1.51,167.97],[2,1.37,54.61]],"batl":[[0,1.57,165.25],[1,1.58,139.18]],"ltp":1.37,"tv":294.88,"id":8908205}]}]}
{"op":"mcm","clk":"1003943789","pt":1580652661135,"mc":[{"id":"1.168224029","rc":[{"batb":[[0,1.37,54.61],[1,1.01,10.51],[2,1.37,0]],"ltp":1.37,"tv":294.88,"id":8908205}]}]}
{"op":"mcm","clk":"1003944875","pt":1580652664973,"mc":[{"id":"1.168224029","rc":[{"batb":[[0,1.38,252.75],[1,1.37,311.85],[2,1.01,10.51]],"batl":[[0,1.74,168.27],[1,1.76,192.66]],"ltp":1.37,"tv":294.88,"id":8908205}]}]}
{"op":"mcm","clk":"1003944922","pt":1580652665148,"mc":[{"id":"1.168224029","rc":[{"batb":[[0,1.37,54.61],[1,1.01,10.51],[2,1.01,0]],"ltp":1.37,"tv":294.88,"id":8908205}]}]}
{"op":"mcm","clk":"1003945438","pt":1580652666851,"mc":[{"id":"1.168224029","rc":[{"batb":[[0,1.67,204.99],[1,1.66,117.57],[2,1.37,54.61]],"ltp":1.37,"tv":294.88,"id":8908205}]}]}
{"op":"mcm","clk":"1003945596","pt":1580652667464,"mc":[{"id":"1.168224029","rc":[{"batb":[[0,1.67,180.01],[2,1.62,28.17]],"batl":[[0,1.71,42.01],[1,1.74,168.27],[2,1.76,192.66]],"ltp":1.37,"tv":294.88,"id":8908205},{"batb":[[1,2.42,29.41],[2,2.2,22.58]],"batl":[[0,2.7,24.37]],"ltp":3.75,"tv":9.03,"id":4596961}]}]}
{"op":"mcm","clk":"1003946435","pt":1580652670457,"mc":[{"id":"1.168224029","rc":[{"batl":[[1,1.74,192.27]],"ltp":1.37,"tv":294.88,"id":8908205}]}]}
{"op":"mcm","clk":"1003949482","pt":1580652681400,"mc":[{"id":"1.168224029","rc":[{"batb":[[0,1.59,70.58],[1,1.51,36.43],[2,1.01,10.51]],"batl":[[1,1.74,0],[2,1.76,0]],"ltp":1.37,"tv":294.88,"id":8908205},{"batb":[[0,2.42,29.41],[1,2.2,22.58],[2,1.01,10.51]],"ltp":3.75,"tv":9.03,"id":4596961}]}]}
{"op":"mcm","clk":"1003949824","pt":1580652682574,"mc":[{"id":"1.168224029","rc":[{"batb":[[0,1.51,36.43],[1,1.01,10.51],[2,1.01,0]],"ltp":1.37,"tv":294.88,"id":8908205},{"batb":[[0,2.2,22.58],[1,1.01,10.51],[2,1.01,0]],"ltp":3.75,"tv":9.03,"id":4596961}]}]}
{"op":"mcm","clk":"1003950367","pt":1580652684666,"mc":[{"id":"1.168224029","rc":[{"batb":[[0,1.55,139.44],[1,1.54,155.29],[2,1.52,35.49]],"batl":[[0,1.97,106.34],[1,1.99,131.48]],"ltp":1.37,"tv":294.88,"id":8908205},{"batb":[[0,2.18,23.21]],"ltp":3.75,"tv":9.03,"id":4596961}]}]}
{"op":"mcm","clk":"1003951957","pt":1580652690794,"mc":[{"id":"1.168224029","rc":[{"batl":[[0,1.6,163.87],[1,1.61,130.09]],"ltp":1.37,"tv":294.88,"id":8908205}]}]}
{"op":"mcm","clk":"1003952154","pt":1580652691524,"mc":[{"id":"1.168224029","rc":[{"batl":[[0,1.59,42.01],[1,1.6,163.87],[2,1.61,130.09]],"ltp":1.37,"tv":294.88,"id":8908205},{"batb":[[0,2.74,12.59],[1,2.68,24.37],[2,2.24,21.56]],"batl":[[0,3.05,20.16]],"ltp":3.75,"tv":9.03,"id":4596961}]}]}
{"op":"mcm","clk":"1003955099","pt":1580652703005,"mc":[{"id":"1.168224029","rc":[{"batb":[[0,1.49,85.7],[1,1.38,53.03],[2,1.01,10.51]],"batl":[[1,1.6,0],[2,1.61,0]],"ltp":1.37,"tv":294.88,"id":8908205},{"batb":[[0,2.68,24.37],[1,2.24,21.56],[2,1.01,10.51]],"ltp":3.75,"tv":9.03,"id":4596961}]}]}
{"op":"mcm","clk":"1003955514","pt":1580652704628,"mc":[{"id":"1.168224029","rc":[{"batb":[[0,1.38,53.03],[1,1.01,10.51],[2,1.01,0]],"ltp":1.37,"tv":294.88,"id":8908205},{"batb":[[0,2.24,21.56],[1,1.01,10.51],[2,1.01,0]],"ltp":3.75,"tv":9.03,"id":4596961}]}]}
{"op":"mcm","clk":"1003955775","pt":1580652705642,"mc":[{"id":"1.168224029","rc":[{"batb":[[0,1.38,436.7],[1,1.37,259.02],[2,1.01,10.51]],"batl":[[0,1.95,151.04],[1,1.97,135.47]],"ltp":1.37,"tv":294.88,"id":8908205}]}]}
{"op":"mcm","clk":"1003956288","pt":1580652707532,"mc":[{"id":"1.168224029","rc":[{"batb":[[0,1.38,53.03],[1,1.01,10.51],[2,1.01,0]],"ltp":1.37,"tv":294.88,"id":8908205}]}]}
{"op":"mcm","clk":"1003957140","pt":1580652710946,"mc":[{"id":"1.168224029","rc":[{"batb":[[0,1.6,196.15],[1,1.59,137.68],[2,1.38,53.03]],"batl":[[0,1.66,162.7],[1,1.68,225.38]],"ltp":1.37,"tv":294.88,"id":8908205}]}]}
{"op":"mcm","clk":"1003957541","pt":1580652712548,"mc":[{"id":"1.168224029","rc":[{"batb":[[0,1.38,53.03],[1,1.01,10.51],[2,1.38,0]],"ltp":1.37,"tv":294.88,"id":8908205}]}]}
{"op":"mcm","clk":"1003958591","pt":1580652716738,"mc":[{"id":"1.168224029","rc":[{"batb":[[0,1.38,436.47],[1,1.37,259.02],[2,1.01,10.51]],"batl":[[0,1.95,151.22],[1,1.97,135.48]],"ltp":1.37,"tv":294.88,"id":8908205}]}]}
{"op":"mcm","clk":"1003960678","pt":1580652724667,"mc":[{"id":"1.168224029","rc":[{"batl":[[0,1.43,294.92],[1,1.44,199.48]],"ltp":1.37,"tv":294.88,"id":8908205}]}]}
{"op":"mcm","clk":"1003960896","pt":1580652725554,"mc":[{"id":"1.168224029","rc":[{"batb":[[2,1.35,119.31]],"ltp":1.37,"tv":294.88,"id":8908205},{"batb":[[0,3.3,19.2],[1,2.72,12.75],[2,1.01,10.51]],"batl":[[0,3.85,14.28]],"ltp":3.75,"tv":9.03,"id":4596961}]}]}
{"op":"mcm","clk":"1003961170","pt":1580652726540,"mc":[{"id":"1.168224029","rc":[{"batl":[[0,1.43,336.93]],"ltp":1.37,"tv":294.88,"id":8908205},{"batb":[[0,3.35,17.64],[1,3.3,19.2],[2,2.72,12.75]],"ltp":3.75,"tv":9.03,"id":4596961}]}]}
{"op":"mcm","clk":"1003965410","pt":1580652744042,"mc":[{"id":"1.168224029","rc":[{"batb":[[0,1.35,119.31],[1,1.28,76.16],[2,1.25,505.09]],"batl":[[0,1.43,42.01],[1,1.44,0]],"ltp":1.37,"tv":294.88,"id":8908205},{"batb":[[1,2.72,12.75],[2,2.3,385.09]],"ltp":3.75,"tv":9.03,"id":4596961}]}]}
{"op":"mcm","clk":"1003965531","pt":1580652744610,"mc":[{"id":"1.168224029","rc":[{"batb":[[0,1.28,76.16],[1,1.25,505.09],[2,1.01,10.51]],"ltp":1.37,"tv":294.88,"id":8908205},{"batb":[[0,2.72,12.75],[1,2.3,385.09],[2,1.01,10.51]],"ltp":3.75,"tv":9.03,"id":4596961}]}]}
{"op":"mcm","clk":"1003966116","pt":1580652746930,"mc":[{"id":"1.168224029","rc":[{"batb":[[0,1.29,337.54],[1,1.28,443.47],[2,1.25,505.09]],"batl":[[0,1.61,157.1],[1,1.62,127.26]],"ltp":1.37,"tv":294.88,"id":8908205}]}]}
{"op":"mcm","clk":"1003968589","pt":1580652756977,"mc":[{"id":"1.168224029","rc":[{"batb":[[0,1.28,76.16],[1,1.25,505.09],[2,1.01,10.51]],"ltp":1.37,"tv":294.88,"id":8908205}]}]}
{"op":"mcm","clk":"1003969064","pt":1580652759105,"mc":[{"id":"1.168224029","rc":[{"batb":[[1,1.01,10.51],[2,1.01,0]],"ltp":1.37,"tv":294.88,"id":8908205},{"batb":[[1,1.01,10.51],[2,1.01,0]],"ltp":3.75,"tv":9.03,"id":4596961}]}]}
{"op":"mcm","clk":"1003969305","pt":1580652760105,"mc":[{"id":"1.168224029","rc":[{"batb":[[0,1.29,337.54],[1,1.28,443.47],[2,1.27,155.44]],"batl":[[0,1.32,148.08],[1,1.33,289.01]],"ltp":1.37,"tv":294.88,"id":8908205},{"batb":[[0,4,23.76],[1,3.25,19.75],[2,2.72,12.75]],"batl":[[0,4.6,10.92]],"ltp":3.75,"tv":9.03,"id":4596961}]}]}
{"op":"mcm","clk":"1003969399","pt":1580652760420,"mc":[{"id":"1.168224029","rc":[{"batl":[[1,1.33,331.02]],"ltp":1.37,"tv":294.88,"id":8908205},{"batb":[[1,3.95,13.44],[2,3.25,19.75]],"ltp":3.75,"tv":9.03,"id":4596961}]}]}
{"op":"mcm","clk":"1003971000","pt":1580652767114,"mc":[{"id":"1.168224029","rc":[{"batb":[[0,1.28,76.16],[1,1.27,155.44],[2,1.21,106.77]],"batl":[[0,1.33,42.01],[1,1.33,0]],"ltp":1.37,"tv":294.88,"id":8908205}]}]}
{"op":"mcm","clk":"1003971081","pt":1580652767433,"mc":[{"id":"1.168224029","rc":[{"batb":[[0,1.27,155.44],[1,1.21,106.77],[2,1.2,530.86]],"ltp":1.37,"tv":294.88,"id":8908205},{"batb":[[0,3.95,13.44],[1,3.25,19.75],[2,2.52,381.46]],"ltp":3.75,"tv":9.03,"id":4596961}]}]}
{"op":"mcm","clk":"1003971365","pt":1580652768620,"mc":[{"id":"1.168224029","rc":[{"batb":[[0,1.21,106.77],[1,1.2,530.86],[2,1.01,10.51]],"ltp":1.37,"tv":294.88,"id":8908205},{"batb":[[0,3.25,19.75],[1,2.52,381.46],[2,1.01,10.51]],"ltp":3.75,"tv":9.03,"id":4596961}]}]}
{"op":"mcm","clk":"1003971688","pt":1580652769984,"mc":[{"id":"1.168224029","rc":[{"batb":[[0,1.23,429.04],[1,1.22,494.66],[2,1.21,106.77]],"batl":[[0,1.44,321.2],[1,1.45,193.55]],"ltp":1.37,"tv":294.88,"id":8908205}]}]}
{"op":"mcm","clk":"1003976528","pt":1580652790085,"mc":[{"id":"1.168224029","rc":[{"batb":[[1,1.01,10.51],[2,1.01,0]],"ltp":3.75,"tv":9.03,"id":4596961}]}]}
{"op":"mcm","clk":"1003976978","pt":1580652791930,"mc":[{"id":"1.168224029","rc":[{"batb":[[1,1.22,662.7]],"batl":[[0,1.26,327.01],[1,1.27,365.24]],"ltp":1.37,"tv":294.88,"id":8908205},{"batb":[[0,5,14.48],[1,4.3,20.22],[2,3.25,19.75]],"batl":[[0,5.6,8.4]],"ltp":3.75,"tv":9.03,"id":4596961}]}]}
{"op":"mcm","clk":"1003977215","pt":1580652792939,"mc":[{"id":"1.168224029","rc":[{"batb":[[2,1.01,10.51]],"ltp":3.75,"tv":9.03,"id":4596961}]}]}
{"op":"mcm","clk":"1003977539","pt":1580652794252,"mc":[{"id":"1.168224029","rc":[{"batb":[[2,2.72,378.25]],"ltp":3.75,"tv":9.03,"id":4596961}]}]}
{"op":"mcm","clk":"1003982723","pt":1580652814969,"mc":[{"id":"1.168224029","rc":[{"batb":[[0,1.22,168.04],[1,1.17,139.66],[2,1.16,576.13]],"ltp":1.37,"tv":294.88,"id":8908205},{"batb":[[0,4.3,20.22],[1,2.72,378.25],[2,1.01,10.51]],"ltp":3.75,"tv":9.03,"id":4596961}]}]}
{"op":"mcm","clk":"1003983253","pt":1580652817065,"mc":[{"id":"1.168224029","rc":[{"batb":[[0,1.17,139.66],[1,1.16,576.13],[2,1.01,10.51]],"ltp":1.37,"tv":294.88,"id":8908205}]}]}
{"op":"mcm","clk":"1003983600","pt":1580652818574,"mc":[{"id":"1.168224029","rc":[{"batl":[[0,1.3,226.73],[1,1.31,310.75]],"ltp":1.37,"tv":294.88,"id":8908205}]}]}
{"op":"mcm","clk":"1003984210","pt":1580652821078,"mc":[{"id":"1.168224029","rc":[{"batb":[[1,1.01,10.51],[2,1.01,0]],"ltp":1.37,"tv":294.88,"id":8908205}]}]}
{"op":"mcm","clk":"1003984468","pt":1580652822088,"mc":[{"id":"1.168224029","rc":[{"batb":[[0,1.27,332.77],[1,1.26,487.14],[2,1.24,168.04]],"batl":[[0,1.3,268.74]],"ltp":1.37,"tv":294.88,"id":8908205},{"batb":[[0,4.3,32.82],[1,3.85,13.53],[2,2.72,378.25]],"batl":[[0,5,10.08]],"ltp":3.75,"tv":9.03,"id":4596961}]}]}
{"op":"mcm","clk":"1003986896","pt":1580652832069,"mc":[{"id":"1.168224029","rc":[{"batb":[[0,1.24,168.04],[1,1.21,108.42],[2,1.18,549.72]],"batl":[[0,1.3,42.01],[1,1.31,0]],"ltp":1.37,"tv":294.88,"id":8908205},{"batb":[[0,4.3,12.6]],"ltp":3.75,"tv":9.03,"id":4596961}]}]}
{"op":"mcm","clk":"1003987053","pt":1580652832678,"mc":[{"id":"1.168224029","rc":[{"batb":[[0,1.21,108.42],[1,1.18,549.72],[2,1.01,10.51]],"ltp":1.37,"tv":294.88,"id":8908205},{"batb":[[0,3.85,13.53],[1,2.72,378.25],[2,1.01,10.51]],"ltp":3.75,"tv":9.03,"id":4596961}]}]}
{"op":"mcm","clk":"1003987597","pt":1580652834892,"mc":[{"id":"1.168224029","rc":[{"batb":[[0,1.22,590.84],[1,1.21,571.85],[2,1.18,549.72]],"batl":[[0,1.34,246.97],[1,1.35,267.19]],"ltp":1.37,"tv":294.88,"id":8908205}]}]}
{"op":"mcm","clk":"1003987851","pt":1580652835990,"mc":[{"id":"1.168224029","rc":[{"batb":[[0,1.21,108.42],[1,1.18,549.72],[2,1.01,10.51]],"ltp":1.37,"tv":294.88,"id":8908205}]}]}
{"op":"mcm","clk":"1003988568","pt":1580652839078,"mc":[{"id":"1.168224029","rc":[{"batb":[[0,1.26,364.69],[1,1.25,422.55],[2,1.21,108.42]],"batl":[[0,1.29,238.9],[1,1.3,323.23]],"ltp":1.37,"tv":294.88,"id":8908205}]}]}
{"op":"mcm","clk":"1003988705","pt":1580652839575,"mc":[{"id":"1.168224029","rc":[{"batb":[[0,1.21,108.42],[1,1.18,549.72],[2,1.01,10.51]],"ltp":1.37,"tv":294.88,"id":8908205}]}]}
{"op":"mcm","clk":"1003989556","pt":1580652843051,"mc":[{"id":"1.168224029","rc":[{"batb":[[0,1.22,590.84],[1,1.21,571.85],[2,1.18,549.72]],"batl":[[0,1.34,246.97],[1,1.35,267.19]],"ltp":1.37,"tv":294.88,"id":8908205}]}]}
{"op":"mcm","clk":"1003991562","pt":1580652851851,"mc":[{"id":"1.168224029","rc":[{"batb":[[2,1.01,10.51]],"ltp":1.37,"tv":294.88,"id":8908205}]}]}
{"op":"mcm","clk":"1003991794","pt":1580652853006,"mc":[{"id":"1.168224029","rc":[{"batl":[[0,1.25,238.81],[1,1.26,384.19]],"ltp":1.37,"tv":294.88,"id":8908205}]}]}
{"op":"mcm","clk":"1003992017","pt":1580652853893,"mc":[{"id":"1.168224029","rc":[{"batb":[[1,1.21,739.89],[2,1.16,148.08]],"batl":[[1,1.26,426.2]],"ltp":1.37,"tv":294.88,"id":8908205},{"batb":[[0,5,14.16],[1,4.8,10.92],[2,4.2,21.32]],"batl":[[0,5.7,8.4]],"ltp":3.75,"tv":9.03,"id":4596961}]}]}
{"op":"mcm","clk":"1003995400","pt":1580652869319,"mc":[{"id":"1.168224029","rc":[{"batb":[[0,1.21,168.04],[1,1.16,148.08],[2,1.14,627.92]],"batl":[[0,1.26,42.01],[1,1.26,0]],"ltp":1.37,"tv":294.88,"id":8908205},{"batb":[[0,4.8,10.92],[1,4.2,21.32],[2,2.72,378.25]],"ltp":3.75,"tv":9.03,"id":4596961}]}]}
{"op":"mcm","clk":"1003995722","pt":1580652870746,"mc":[{"id":"1.168224029","rc":[{"batb":[[0,1.16,148.08],[1,1.14,627.92],[2,1.01,10.51]],"ltp":1.37,"tv":294.88,"id":8908205},{"batb":[[0,4.2,21.32],[1,2.72,378.25],[2,1.01,10.51]],"ltp":3.75,"tv":9.03,"id":4596961}]}]}
{"op":"mcm","clk":"1003996879","pt":1580652875845,"mc":[{"id":"1.168224029","rc":[{"batb":[[0,1.21,528.01],[1,1.2,535.56],[2,1.16,148.08]],"batl":[[0,1.24,359.41],[1,1.25,399.7]],"ltp":1.37,"tv":294.88,"id":8908205}]}]}
{"op":"mcm","clk":"1003997603","pt":1580652879062,"mc":[{"id":"1.168224029","rc":[{"batb":[[0,1.16,148.08],[1,1.14,627.92],[2,1.01,10.51]],"ltp":1.37,"tv":294.88,"id":8908205}]}]}
{"op":"mcm","clk":"1003998245","pt":1580652881639,"mc":[{"id":"1.168224029","rc":[{"batb":[[0,1.17,348.17],[1,1.16,862.86],[2,1.14,627.92]],"batl":[[0,1.3,234.01],[1,1.31,310.7]],"ltp":1.37,"tv":294.88,"id":8908205}]}]}
{"op":"mcm","clk":"1003999447","pt":1580652887010,"mc":[{"id":"1.168224029","rc":[{"batb":[[0,1.16,148.08],[1,1.14,627.92],[2,1.01,10.51]],"ltp":1.37,"tv":294.88,"id":8908205}]}]}
{"op":"mcm","clk":"1003999580","pt":1580652887612,"mc":[{"id":"1.168224029","rc":[{"batb":[[1,1.01,10.51],[2,1.01,0]],"ltp":1.37,"tv":294.88,"id":8908205}]}]}
{"op":"mcm","clk":"1004000124","pt":1580652889913,"mc":[{"id":"1.168224029","rc":[{"batb":[[0,1.27,407.44],[1,1.26,402.09],[2,1.24,168.04]],"batl":[[0,1.3,276.02]],"ltp":1.37,"tv":294.88,"id":8908205},{"batb":[[0,4.3,12.6],[1,4.2,21.32],[2,3.7,14.48]],"batl":[[0,5.1,10.08]],"ltp":3.75,"tv":9.03,"id":4596961}]}]}
{"op":"mcm","clk":"1004004063","pt":1580652907082,"mc":[{"id":"1.168224029","rc":[{"batb":[[0,1.24,168.04],[1,1.21,109.37],[2,1.18,549.72]],"batl":[[0,1.3,42.01],[1,1.31,0]],"ltp":1.37,"tv":294.88,"id":8908205},{"batb":[[1,3.7,14.48],[2,2.72,378.25]],"ltp":3.75,"tv":9.03,"id":4596961}]}]}
{"op":"mcm","clk":"1004004459","pt":1580652908874,"mc":[{"id":"1.168224029","rc":[{"batb":[[0,1.21,109.37],[1,1.18,549.72],[2,1.01,10.51]],"ltp":1.37,"tv":294.88,"id":8908205},{"batb":[[0,3.7,14.48],[1,2.72,378.25],[2,1.01,10.51]],"ltp":3.75,"tv":9.03,"id":4596961}]}]}
{"op":"mcm","clk":"1004005328","pt":1580652912648,"mc":[{"id":"1.168224029","rc":[{"batb":[[0,1.26,299.16],[1,1.25,421.15],[2,1.21,109.37]],"batl":[[0,1.29,299.33],[1,1.3,322.18]],"ltp":1.37,"tv":294.88,"id":8908205}]}]}
{"op":"mcm","clk":"1004005750","pt":1580652914868,"mc":[{"id":"1.168224029","rc":[{"batb":[[0,1.21,109.37],[1,1.18,549.72],[2,1.01,10.51]],"ltp":1.37,"tv":294.88,"id":8908205}]}]}
{"op":"mcm","clk":"1004006414","pt":1580652918072,"mc":[{"id":"1.168224029","rc":[{"batb":[[0,1.22,252.71],[1,1.21,627.04],[2,1.18,549.72]],"batl":[[0,1.35,344.51],[1,1.36,256.67]],"ltp":1.37,"tv":294.88,"id":8908205}]}]}
{"op":"mcm","clk":"1004007530","pt":1580652923084,"mc":[{"id":"1.168224029","rc":[{"batb":[[0,1.21,109.37],[1,1.18,549.72],[2,1.01,10.51]],"ltp":1.37,"tv":294.88,"id":8908205}]}]}
{"op":"mcm","clk":"1004007928","pt":1580652924875,"mc":[{"id":"1.168224029","rc":[{"batb":[[1,1.01,10.51],[2,1.01,0]],"ltp":1.37,"tv":294.88,"id":8908205}]}]}
{"op":"mcm","clk":"1004008169","pt":1580652926094,"mc":[{"id":"1.168224029","rc":[{"batb":[[0,1.22,252.71],[1,1.21,627.04],[2,1.2,168.04]],"batl":[[0,1.25,544.09],[1,1.26,377.08]],"ltp":1.37,"tv":294.88,"id":8908205},{"batl":[[0,5.9,8.4]],"ltp":3.75,"tv":9.03,"id":4596961}]}]}
{"op":"mcm","clk":"1004008293","pt":1580652926689,"mc":[{"id":"1.168224029","rc":[{"batl":[[0,1.25,586.1]],"ltp":1.37,"tv":294.88,"id":8908205},{"batb":[[0,5,24.09],[1,4.1,22.82],[2,2.72,378.25]],"ltp":3.75,"tv":9.03,"id":4596961}]}]}
{"op":"mcm","clk":"1004008895","pt":1580652929402,"mc":[{"id":"1.168224029","rc":[{"batl":[[0,1.25,447.18],[1,1.26,0]],"ltp":1.37,"tv":294.88,"id":8908205}]}]}
{"op":"mcm","clk":"1004009693","pt":1580652932960,"mc":[{"id":"1.168224029","rc":[{"batl":[[0,1.24,166.01],[1,1.25,447.18]],"ltp":1.37,"tv":294.88,"id":8908205},{"batb":[[1,4.2,505.12],[2,4.1,22.82]],"ltp":3.75,"tv":9.03,"id":4596961}]}]}
{"op":"mcm","clk":"1004011897","pt":1580652942850,"mc":[{"id":"1.168224029","rc":[{"batb":[[0,1.14,794.88],[1,1.01,10.51],[2,1.2,0]],"ltp":1.37,"tv":294.88,"id":8908205},{"batb":[[0,4.1,22.82],[1,2.72,378.25],[2,1.01,10.51]],"ltp":3.75,"tv":9.03,"id":4596961}]}]}
{"op":"mcm","clk":"1004012548","pt":1580652946068,"mc":[{"id":"1.168224029","rc":[{"batb":[[0,1.15,209.94],[1,1.14,1621.31],[2,1.01,10.51]],"batl":[[0,1.31,323.18],[1,1.32,297.77]],"ltp":1.37,"tv":294.88,"id":8908205}]}]}
{"op":"mcm","clk":"1004016291","pt":1580652964114,"mc":[{"id":"1.168224029","rc":[{"batb":[[0,1.14,794.88],[1,1.01,10.51],[2,1.01,0]],"ltp":1.37,"tv":294.88,"id":8908205}]}]}
{"op":"mcm","clk":"1004016724","pt":1580652966057,"mc":[{"id":"1.168224029","rc":[{"batb":[[0,1.14,166.96]],"ltp":1.37,"tv":294.88,"id":8908205}]}]}
{"op":"mcm","clk":"1004017143","pt":1580652968033,"mc":[{"id":"1.168224029","rc":[{"batb":[[0,1.28,266.97],[1,1.27,381.71],[2,1.24,168.04]],"batl":[[0,1.3,42.01],[1,1.31,323.18],[2,1.32,297.77]],"ltp":1.37,"tv":294.88,"id":8908205},{"batb":[[0,4.3,12.6],[1,4.1,22.82],[2,3.5,16.52]],"batl":[[0,5.1,10.08]],"ltp":3.75,"tv":9.03,"id":4596961}]}]}
{"op":"mcm","clk":"1004020874","pt":1580652984840,"mc":[{"id":"1.168224029","rc":[{"batb":[[0,1.21,108.66],[1,1.18,549.72],[2,1.01,10.51]],"ltp":1.37,"tv":294.88,"id":8908205},{"batb":[[0,3.5,16.52],[1,2.72,378.25],[2,1.01,10.51]],"ltp":3.75,"tv":9.03,"id":4596961}]}]}
{"op":"mcm","clk":"1004021318","pt":1580652987032,"mc":[{"id":"1.168224029","rc":[{"batb":[[0,1.21,750.67],[1,1.2,420.61],[2,1.18,549.72]],"batl":[[0,1.36,182.45],[1,1.37,250.48]],"ltp":1.37,"tv":294.88,"id":8908205}]}]}
{"op":"mcm","clk":"1004021495","pt":1580652987852,"mc":[{"id":"1.168224029","rc":[{"batb":[[0,1.21,108.66],[1,1.18,549.72],[2,1.01,10.51]],"ltp":1.37,"tv":294.88,"id":8908205}]}]}
{"op":"mcm","clk":"1004021845","pt":1580652989528,"mc":[{"id":"1.168224029","rc":[{"batb":[[0,1.26,480.34],[1,1.25,425.86],[2,1.21,108.66]],"batl":[[0,1.3,459.32],[1,1.31,307.16]],"ltp":1.37,"tv":294.88,"id":8908205}]}]}
{"op":"mcm","clk":"1004022319","pt":1580652991749,"mc":[{"id":"1.168224029","rc":[{"batb":[[0,1.21,108.66],[1,1.18,549.72],[2,1.01,10.51]],"ltp":1.37,"tv":294.88,"id":8908205}]}]}
{"op":"mcm","clk":"1004022951","pt":1580652994475,"mc":[{"id":"1.168224029","rc":[{"batb":[[0,1.21,750.67],[1,1.2,420.61],[2,1.18,549.72]],"batl":[[0,1.36,182.45],[1,1.37,250.48]],"ltp":1.37,"tv":294.88,"id":8908205}]}]}
{"op":"mcm","clk":"1004023492","pt":1580652997027,"mc":[{"id":"1.168224029","rc":[{"batb":[[0,1.21,108.66],[1,1.18,549.72],[2,1.01,10.51]],"ltp":1.37,"tv":294.88,"id":8908205}]}]}
{"op":"mcm","clk":"1004023733","pt":1580652998263,"mc":[{"id":"1.168224029","rc":[{"batb":[[1,1.01,10.51],[2,1.01,0]],"ltp":1.37,"tv":294.88,"id":8908205}]}]}
{"op":"mcm","clk":"1004024082","pt":1580652999974,"mc":[{"id":"1.168224029","rc":[{"batb":[[0,1.33,173.53],[1,1.32,308.96],[2,1.21,108.66]],"ltp":1.37,"tv":294.88,"id":8908205}]}]}
{"op":"mcm","clk":"1004024318","pt":1580653001121,"mc":[{"id":"1.168224029","rc":[{"batb":[[0,1.35,59.4],[1,1.33,173.53],[2,1.32,308.96]],"ltp":1.37,"tv":294.88,"id":8908205},{"batb":[[1,2.98,25.1],[2,2.72,378.25]],"ltp":3.75,"tv":9.03,"id":4596961}]}]}
{"op":"mcm","clk":"1004024529","pt":1580653002106,"mc":[{"id":"1.168224029","rc":[{"trd":[[1.35,84.02]],"batb":[[0,1.35,17.39]],"ltp":1.35,"tv":378.9,"id":8908205},{"batb":[[0,3.85,14.28],[1,3.5,16.52],[2,2.98,25.1]],"ltp":3.75,"tv":9.03,"id":4596961}],"tv":387.93}]}
{"op":"mcm","clk":"1004025167","pt":1580653005106,"mc":[{"id":"1.168224029","rc":[{"trd":[[1.35,118.81]],"batb":[[0,1.33,173.53],[1,1.32,308.96],[2,1.29,144.51]],"batl":[[0,1.35,24.62],[1,1.36,224.46],[2,1.37,250.48]],"ltp":1.35,"tv":413.68,"id":8908205},{"batl":[[0,4.4,11.76]],"ltp":3.75,"tv":9.03,"id":4596961}],"tv":422.72}]}
{"op":"mcm","clk":"1004025337","pt":1580653005904,"mc":[{"id":"1.168224029","rc":[{"batl":[[0,1.36,182.45],[1,1.37,250.48],[2,1.37,0]],"ltp":1.35,"tv":413.68,"id":8908205}]}]}
{"op":"mcm","clk":"1004025679","pt":1580653007611,"mc":[{"id":"1.168224029","rc":[{"batl":[[0,4.4,413.95]],"ltp":3.75,"tv":9.03,"id":4596961}]}]}
{"op":"mcm","clk":"1004025988","pt":1580653008985,"mc":[{"id":"1.168224029","rc":[{"batb":[[0,1.34,61.45],[1,1.33,173.53],[2,1.32,308.96]],"batl":[[0,1.35,42.01],[1,1.36,182.45],[2,1.37,250.48]],"ltp":1.35,"tv":413.68,"id":8908205},{"batb":[[1,3.6,15.74],[2,3,24]],"ltp":3.75,"tv":9.03,"id":4596961}]}]}
{"op":"mcm","clk":"1004029346","pt":1580653024986,"mc":[{"id":"1.168224029","rc":[{"batb":[[2,3.05,24]],"ltp":3.75,"tv":9.03,"id":4596961}]}]}
{"op":"mcm","clk":"1004041158","pt":1580653086090,"mc":[{"id":"1.168224029","rc":[{"batb":[[1,1.29,144.51],[2,1.27,81.12]],"batl":[[1,1.36,0],[2,1.37,0]],"ltp":1.35,"tv":413.68,"id":8908205},{"batl":[[0,4.4,11.76]],"ltp":3.75,"tv":9.03,"id":4596961}]}]}
{"op":"mcm","clk":"1004041317","pt":1580653086884,"mc":[{"id":"1.168224029","rc":[{"batb":[[0,1.27,81.12],[1,1.22,523],[2,1.01,10.51]],"ltp":1.35,"tv":413.68,"id":8908205},{"batb":[[0,3.05,24],[1,2.72,378.25],[2,1.01,10.51]],"ltp":3.75,"tv":9.03,"id":4596961}]}]}
{"op":"mcm","clk":"1004041767","pt":1580653089050,"mc":[{"id":"1.168224029","rc":[{"batb":[[0,1.27,297.87],[1,1.26,400.23],[2,1.22,523]],"batl":[[0,1.47,137.29],[1,1.48,179.86]],"ltp":1.35,"tv":413.68,"id":8908205}]}]}
{"op":"mcm","clk":"1004046299","pt":1580653112909,"mc":[{"id":"1.168224029","rc":[{"batb":[[2,1.01,10.51]],"ltp":1.35,"tv":413.68,"id":8908205}]}]}
{"op":"mcm","clk":"1004046524","pt":1580653114092,"mc":[{"id":"1.168224029","rc":[{"batl":[[0,1.3,335.1],[1,1.31,309.3]],"ltp":1.35,"tv":413.68,"id":8908205}]}]}
{"op":"mcm","clk":"1004046724","pt":1580653115118,"mc":[{"id":"1.168224029","rc":[{"batb":[[2,1.22,105.04]],"ltp":1.35,"tv":413.68,"id":8908205},{"batb":[[0,4.2,21.64],[1,3.5,16.52],[2,2.72,378.25]],"ltp":3.75,"tv":9.03,"id":4596961}]}]}
{"op":"mcm","clk":"1004046837","pt":1580653115812,"mc":[{"id":"1.168224029","rc":[{"batb":[[2,1.24,168.04]],"batl":[[0,1.3,377.11]],"ltp":1.35,"tv":413.68,"id":8908205},{"batb":[[0,4.3,12.6],[1,4.2,21.64],[2,3.5,16.52]],"batl":[[0,5.1,10.08]],"ltp":3.75,"tv":9.03,"id":4596961}]}]}
{"op":"mcm","clk":"1004049265","pt":1580653128103,"mc":[{"id":"1.168224029","rc":[{"batb":[[0,1.24,168.04],[1,1.22,105.04],[2,1.18,549.72]],"batl":[[0,1.3,42.01],[1,1.31,0]],"ltp":1.35,"tv":413.68,"id":8908205},{"batb":[[1,3.5,16.52],[2,2.72,378.25]],"ltp":3.75,"tv":9.03,"id":4596961}]}]}
{"op":"mcm","clk":"1004049403","pt":1580653128802,"mc":[{"id":"1.168224029","rc":[{"batb":[[0,1.22,105.04],[1,1.18,549.72],[2,1.01,10.51]],"ltp":1.35,"tv":413.68,"id":8908205},{"batb":[[0,3.5,16.52],[1,2.72,378.25],[2,1.01,10.51]],"ltp":3.75,"tv":9.03,"id":4596961}]}]}
{"op":"mcm","clk":"1004049762","pt":1580653130900,"mc":[{"id":"1.168224029","rc":[{"batb":[[0,1.22,648.35],[1,1.21,511.38],[2,1.18,549.72]],"batl":[[0,1.38,225.59],[1,1.39,233.98]],"ltp":1.35,"tv":413.68,"id":8908205}]}]}
{"op":"mcm","clk":"1004052118","pt":1580653142915,"mc":[{"id":"1.168224029","rc":[{"batb":[[0,1.22,105.04],[1,1.18,549.72],[2,1.01,10.51]],"ltp":1.35,"tv":413.68,"id":8908205}]}]}
{"op":"mcm","clk":"1004052364","pt":1580653144116,"mc":[{"id":"1.168224029","rc":[{"batb":[[1,1.01,10.51],[2,1.01,0]],"ltp":1.35,"tv":413.68,"id":8908205}]}]}
{"op":"mcm","clk":"1004052533","pt":1580653145021,"mc":[{"id":"1.168224029","rc":[{"batb":[[0,1.34,361.91],[1,1.33,300.07],[2,1.22,105.04]],"ltp":1.35,"tv":413.68,"id":8908205}]}]}
{"op":"mcm","clk":"1004052757","pt":1580653146107,"mc":[{"id":"1.168224029","rc":[{"batb":[[0,1.35,59.33],[1,1.34,361.91],[2,1.33,300.07]],"batl":[[0,1.37,42.01],[1,1.38,225.59],[2,1.39,233.98]],"ltp":1.35,"tv":413.68,"id":8908205},{"batb":[[0,3.65,15.12],[1,3.5,16.52],[2,2.94,10.54]],"batl":[[0,4.2,12.6]],"ltp":3.75,"tv":9.03,"id":4596961}]}]}
{"op":"mcm","clk":"1004056070","pt":1580653163048,"mc":[{"id":"1.168224029","rc":[{"batb":[[1,1.3,139.47],[2,1.27,81.36]],"batl":[[1,1.38,0],[2,1.39,0]],"ltp":1.35,"tv":413.68,"id":8908205}]}]}
{"op":"mcm","clk":"1004056120","pt":1580653163259,"mc":[{"id":"1.168224029","rc":[{"batb":[[0,1.3,139.47],[1,1.27,81.36],[2,1.22,523]],"ltp":1.35,"tv":413.68,"id":8908205},{"batb":[[1,2.94,10.54],[2,2.72,378.25]],"ltp":3.75,"tv":9.03,"id":4596961}]}]}
{"op":"mcm","clk":"1004056442","pt":1580653164881,"mc":[{"id":"1.168224029","rc":[{"batb":[[0,1.27,81.36],[1,1.22,523],[2,1.01,10.51]],"ltp":1.35,"tv":413.68,"id":8908205},{"batb":[[0,2.94,10.54],[1,2.72,378.25],[2,1.01,10.51]],"ltp":3.75,"tv":9.03,"id":4596961}]}]}
{"op":"mcm","clk":"1004056682","pt":1580653166077,"mc":[{"id":"1.168224029","rc":[{"batb":[[0,1.27,406.9],[1,1.26,402.56],[2,1.22,523]],"batl":[[0,1.52,175.44],[1,1.53,157.56]],"ltp":1.35,"tv":413.68,"id":8908205}]}]}
{"op":"mcm","clk":"1004057041","pt":1580653167957,"mc":[{"id":"1.168224029","rc":[{"batb":[[0,1.27,81.36],[1,1.22,523],[2,1.01,10.51]],"ltp":1.35,"tv":413.68,"id":8908205}]}]}
{"op":"mcm","clk":"1004057311","pt":1580653169258,"mc":[{"id":"1.168224029","rc":[{"batb":[[1,1.01,10.51],[2,1.01,0]],"ltp":1.35,"tv":413.68,"id":8908205},{"batb":[[1,1.01,10.51],[2,1.01,0]],"ltp":3.75,"tv":9.03,"id":4596961}]}]}
{"op":"mcm","clk":"1004057662","pt":1580653170864,"mc":[{"id":"1.168224029","rc":[{"batb":[[0,1.47,270.17],[1,1.46,194.23],[2,1.27,81.36]],"ltp":1.35,"tv":413.68,"id":8908205}]}]}
{"op":"mcm","clk":"1004057884","pt":1580653171976,"mc":[{"id":"1.168224029","rc":[{"batb":[[0,1.47,311.32],[2,1.36,57.2]],"batl":[[0,1.51,42.01],[1,1.52,175.44],[2,1.53,157.56]],"ltp":1.35,"tv":413.68,"id":8908205},{"batb":[[0,2.96,21],[1,2.94,10.54],[2,2.44,17.07]],"ltp":3.75,"tv":9.03,"id":4596961}]}]}
{"op":"mcm","clk":"1004060683","pt":1580653186036,"mc":[{"id":"1.168224029","rc":[{"batb":[[0,1.47,41.15],[1,1.36,57.2],[2,1.31,477.51]],"batl":[[1,1.52,0],[2,1.53,0]],"ltp":1.35,"tv":413.68,"id":8908205}]}]}
{"op":"mcm","clk":"1004060881","pt":1580653186958,"mc":[{"id":"1.168224029","rc":[{"batb":[[0,1.36,57.2],[1,1.31,477.51],[2,1.01,10.51]],"ltp":1.35,"tv":413.68,"id":8908205},{"batb":[[0,2.44,17.07],[1,2.12,388.65],[2,1.01,10.51]],"ltp":3.75,"tv":9.03,"id":4596961}]}]}
{"op":"mcm","clk":"1004061267","pt":1580653188814,"mc":[{"id":"1.168224029","rc":[{"batb":[[0,1.36,321.63],[1,1.35,277.2],[2,1.31,477.51]],"batl":[[0,1.75,184.31],[1,1.77,189.78]],"ltp":1.35,"tv":413.68,"id":8908205}]}]}
{"op":"mcm","clk":"1004061363","pt":1580653189360,"mc":[{"id":"1.168224029","rc":[{"batb":[[0,1.36,57.2],[1,1.31,477.51],[2,1.01,10.51]],"ltp":1.35,"tv":413.68,"id":8908205}]}]}
{"op":"mcm","clk":"1004061597","pt":1580653190545,"mc":[{"id":"1.168224029","rc":[{"batb":[[1,1.01,10.51],[2,1.01,0]],"ltp":1.35,"tv":413.68,"id":8908205}]}]}
{"op":"mcm","clk":"1004062060","pt":1580653193061,"mc":[{"id":"1.168224029","rc":[{"batb":[[0,1.51,206.03],[1,1.5,173.26],[2,1.36,57.2]],"batl":[[0,1.56,162.67],[1,1.57,143.01]],"ltp":1.35,"tv":413.68,"id":8908205}]}]}
{"op":"mcm","clk":"1004062567","pt":1580653195669,"mc":[{"id":"1.168224029","rc":[{"batb":[[0,1.36,57.2],[1,1.34,465.43],[2,1.01,10.51]],"ltp":1.35,"tv":413.68,"id":8908205}]}]}
{"op":"mcm","clk":"1004063124","pt":1580653198579,"mc":[{"id":"1.168224029","rc":[{"batb":[[0,1.36,321.63],[1,1.35,277.2],[2,1.34,465.43]],"batl":[[0,1.75,184.31],[1,1.77,189.78]],"ltp":1.35,"tv":413.68,"id":8908205}]}]}
{"op":"mcm","clk":"1004065626","pt":1580653210828,"mc":[{"id":"1.168224029","rc":[{"batb":[[2,1.01,10.51]],"ltp":1.35,"tv":413.68,"id":8908205},{"batb":[[1,1.01,10.51],[2,1.01,0]],"ltp":3.75,"tv":9.03,"id":4596961}]}]}
{"op":"mcm","clk":"1004066099","pt":1580653213013,"mc":[{"id":"1.168224029","rc":[{"batb":[[2,1.26,86.16]],"batl":[[0,1.4,254.78],[1,1.41,219.26]],"ltp":1.35,"tv":413.68,"id":8908205},{"batb":[[0,3.45,17.39],[1,2.74,12.51],[2,2.48,472.26]],"ltp":3.75,"tv":9.03,"id":4596961}]}]}
{"op":"mcm","clk":"1004066277","pt":1580653213832,"mc":[{"id":"1.168224029","rc":[{"batb":[[2,1.32,131.07]],"batl":[[0,1.39,42.01],[1,1.4,254.78],[2,1.41,219.26]],"ltp":1.35,"tv":413.68,"id":8908205},{"batb":[[0,3.55,15.96],[1,3.45,17.39],[2,2.74,12.51]],"batl":[[0,4.1,13.44]],"ltp":3.75,"tv":9.03,"id":4596961}]}]}
{"op":"mcm","clk":"1004069450","pt":1580653229482,"mc":[{"id":"1.168224029","rc":[{"batb":[[0,1.32,131.07],[1,1.26,86.16],[2,1.23,516.48]],"batl":[[1,1.4,0],[2,1.41,0]],"ltp":1.35,"tv":413.68,"id":8908205},{"batb":[[1,2.74,12.51],[2,2.38,382.3]],"ltp":3.75,"tv":9.03,"id":4596961}]}]}
{"op":"mcm","clk":"1004069753","pt":1580653230964,"mc":[{"id":"1.168224029","rc":[{"batb":[[0,1.26,86.16],[1,1.23,516.48],[2,1.01,10.51]],"ltp":1.35,"tv":413.68,"id":8908205},{"batb":[[0,2.74,12.51],[1,2.38,382.3],[2,1.01,10.51]],"ltp":3.75,"tv":9.03,"id":4596961}]}]}
{"op":"mcm","clk":"1004070039","pt":1580653232270,"mc":[{"id":"1.168224029","rc":[{"batb":[[0,1.26,481.35],[1,1.25,423.76],[2,1.23,516.48]],"batl":[[0,1.6,209.96],[1,1.61,130.26]],"ltp":1.35,"tv":413.68,"id":8908205}]}]}
{"op":"mcm","clk":"1004070438","pt":1580653234373,"mc":[{"id":"1.168224029","rc":[{"batb":[[0,1.26,86.16],[1,1.23,516.48],[2,1.01,10.51]],"ltp":1.35,"tv":413.68,"id":8908205}]}]}
{"op":"mcm","clk":"1004070769","pt":1580653236084,"mc":[{"id":"1.168224029","rc":[{"batb":[[1,1.01,10.51],[2,1.01,0]],"ltp":1.35,"tv":413.68,"id":8908205},{"batb":[[1,1.01,10.51],[2,1.01,0]],"ltp":3.75,"tv":9.03,"id":4596961}]}]}
{"op":"mcm","clk":"1004071212","pt":1580653238086,"mc":[{"id":"1.168224029","rc":[{"batb":[[0,1.54,247.65],[1,1.53,160.31],[2,1.52,35.64]],"batl":[[0,1.58,42.01],[1,1.6,209.96],[2,1.61,130.26]],"ltp":1.35,"tv":413.68,"id":8908205},{"batb":[[0,2.74,36.04],[1,2.18,22.98],[2,1.01,10.51]],"ltp":3.75,"tv":9.03,"id":4596961}]}]}
{"op":"mcm","clk":"1004071284","pt":1580653238418,"mc":[{"id":"1.168224029","rc":[{"batl":[[0,3.05,20.16]],"ltp":3.75,"tv":9.03,"id":4596961}]}]}
{"op":"mcm","clk":"1004071711","pt":1580653240505,"mc":[{"id":"1.168224029","rc":[{"batb":[[2,1.97,394.86]],"ltp":3.75,"tv":9.03,"id":4596961}]}]}
{"op":"mcm","clk":"1004072419","pt":1580653243774,"mc":[{"id":"1.168224029","rc":[{"batl":[[0,3.05,428.95]],"ltp":3.75,"tv":9.03,"id":4596961}]}]}
{"op":"mcm","clk":"1004074072","pt":1580653252012,"mc":[{"id":"1.168224029","rc":[{"batb":[[0,1.48,87.38],[1,1.38,448.45],[2,1.36,56.49]],"batl":[[1,1.6,0],[2,1.61,0]],"ltp":1.35,"tv":413.68,"id":8908205},{"batb":[[0,2.74,23.53]],"batl":[[0,3.05,20.16]],"ltp":3.75,"tv":9.03,"id":4596961}]}]}
{"op":"mcm","clk":"1004074229","pt":1580653252804,"mc":[{"id":"1.168224029","rc":[{"batb":[[0,1.38,448.45],[1,1.36,56.49],[2,1.01,10.51]],"ltp":1.35,"tv":413.68,"id":8908205},{"batb":[[0,2.18,22.98],[1,1.97,394.86],[2,1.01,10.51]],"ltp":3.75,"tv":9.03,"id":4596961}]}]}
{"op":"mcm","clk":"1004074844","pt":1580653255433,"mc":[{"id":"1.168224029","rc":[{"batb":[[0,1.36,56.49],[1,1.01,10.51],[2,1.01,0]],"ltp":1.35,"tv":413.68,"id":8908205}]}]}
{"op":"mcm","clk":"1004075399","pt":1580653257936,"mc":[{"id":"1.168224029","rc":[{"batb":[[0,1.6,237.78],[1,1.59,138.26],[2,1.36,56.49]],"batl":[[0,1.66,125.74],[1,1.68,226.32]],"ltp":1.35,"tv":413.68,"id":8908205}]}]}
{"op":"mcm","clk":"1004075759","pt":1580653259533,"mc":[{"id":"1.168224029","rc":[{"batb":[[2,1.4,451]],"ltp":1.35,"tv":413.68,"id":8908205}]}]}
{"op":"mcm","clk":"1004076354","pt":1580653262273,"mc":[{"id":"1.168224029","rc":[{"batb":[[0,1.4,451],[1,1.36,56.49],[2,1.01,10.51]],"ltp":1.35,"tv":413.68,"id":8908205}]}]}
{"op":"mcm","clk":"1004077132","pt":1580653265952,"mc":[{"id":"1.168224029","rc":[{"batb":[[1,1.37,171.79],[2,1.36,322.82]],"batl":[[0,1.99,100.43],[1,2.02,189.72]],"ltp":1.35,"tv":413.68,"id":8908205}]}]}
{"op":"mcm","clk":"1004078168","pt":1580653271152,"mc":[{"id":"1.168224029","rc":[{"batb":[[1,1.36,56.49],[2,1.01,10.51]],"ltp":1.35,"tv":413.68,"id":8908205}]}]}
{"op":"mcm","clk":"1004078453","pt":1580653272580,"mc":[{"id":"1.168224029","rc":[{"batb":[[0,1.36,56.49],[1,1.01,10.51],[2,1.01,0]],"ltp":1.35,"tv":413.68,"id":8908205},{"batb":[[1,1.01,10.51],[2,1.01,0]],"ltp":3.75,"tv":9.03,"id":4596961}]}]}
{"op":"mcm","clk":"1004078990","pt":1580653275066,"mc":[{"id":"1.168224029","rc":[{"trd":[[1.85,27.07]],"batb":[[0,1.91,99.79],[1,1.89,151.88],[2,1.77,20.93]],"ltp":1.85,"tv":440.75,"id":8908205},{"trd":[[2.18,22.98]],"batb":[[0,1.97,15.66]],"ltp":2.18,"tv":32.0,"id":4596961}],"tv":472.76}]}
{"op":"mcm","clk":"1004079221","pt":1580653276084,"mc":[{"id":"1.168224029","rc":[{"batl":[[2,2.06,39.49]],"ltp":1.85,"tv":440.75,"id":8908205},{"batb":[[1,1.94,44.53],[2,1.01,10.51]],"batl":[[0,2.18,22.69]],"ltp":2.18,"tv":32.0,"id":4596961}]}]}
{"op":"mcm","clk":"1004079348","pt":1580653276677,"mc":[{"id":"1.168224029","rc":[{"batb":[[2,1.67,409.76]],"ltp":2.18,"tv":32.0,"id":4596961}]}]}
{"op":"mcm","clk":"1004079574","pt":1580653277666,"mc":[{"id":"1.168224029","rc":[{"batb":[[1,1.9,46.21],[2,1.89,151.88]],"ltp":1.85,"tv":440.75,"id":8908205},{"batl":[[0,2.12,36.97]],"ltp":2.18,"tv":32.0,"id":4596961}]}]}
{"op":"mcm","clk":"1004085142","pt":1580653304285,"mc":[{"id":"1.168224029","rc":[{"batb":[[0,1.9,46.21],[1,1.77,20.93],[2,1.6,29.27]],"ltp":1.85,"tv":440.75,"id":8908205}]}]}
{"op":"mcm","clk":"1004085778","pt":1580653307290,"mc":[{"id":"1.168224029","rc":[{"batb":[[0,1.9,219.35],[1,1.88,154.51],[2,1.77,20.93]],"batl":[[0,1.99,129.02]],"ltp":1.85,"tv":440.75,"id":8908205}]}]}
{"op":"mcm","clk":"1004086115","pt":1580653309023,"mc":[{"id":"1.168224029","rc":[{"batb":[[0,1.6,29.27],[1,1.58,416.47],[2,1.01,10.51]],"ltp":1.85,"tv":440.75,"id":8908205},{"batb":[[1,1.67,409.76],[2,1.01,10.51]],"ltp":2.18,"tv":32.0,"id":4596961}]}]}
{"op":"mcm","clk":"1004086744","pt":1580653312104,"mc":[{"id":"1.168224029","rc":[{"batb":[[0,1.62,28.01],[1,1.6,29.27],[2,1.58,416.47]],"ltp":1.85,"tv":440.75,"id":8908205},{"batb":[[1,1.94,16.44],[2,1.67,409.76]],"ltp":2.18,"tv":32.0,"id":4596961}]}]}
{"op":"mcm","clk":"1004086864","pt":1580653312756,"mc":[{"id":"1.168224029","rc":[{"batb":[[1,1.58,416.47],[2,1.01,10.51]],"ltp":1.85,"tv":440.75,"id":8908205},{"batb":[[0,1.94,16.44],[1,1.67,409.76],[2,1.01,10.51]],"ltp":2.18,"tv":32.0,"id":4596961}]}]}
{"op":"mcm","clk":"1004087330","pt":1580653315104,"mc":[{"id":"1.168224029","rc":[{"batb":[[0,1.86,146.07],[1,1.84,165.53],[2,1.62,28.01]],"batl":[[0,1.94,119.67],[1,1.96,138.23]],"ltp":1.85,"tv":440.75,"id":8908205}]}]}
{"op":"mcm","clk":"1004088093","pt":1580653318921,"mc":[{"id":"1.168224029","rc":[{"batb":[[0,1.62,28.01],[1,1.58,416.47],[2,1.01,10.51]],"ltp":1.85,"tv":440.75,"id":8908205}]}]}
{"op":"mcm","clk":"1004088707","pt":1580653322108,"mc":[{"id":"1.168224029","rc":[{"batb":[[0,1.7,193.91],[1,1.68,225.12],[2,1.62,28.01]],"batl":[[0,2.18,110.01],[1,2.2,98.79]],"ltp":1.85,"tv":440.75,"id":8908205}]}]}
{"op":"mcm","clk":"1004089318","pt":1580653325040,"mc":[{"id":"1.168224029","rc":[{"batb":[[0,1.62,28.01],[1,1.58,416.47],[2,1.01,10.51]],"ltp":1.85,"tv":440.75,"id":8908205}]}]}
{"op":"mcm","clk":"1004089942","pt":1580653327931,"mc":[{"id":"1.168224029","rc":[{"batb":[[1,1.01,10.51],[2,1.01,0]],"ltp":1.85,"tv":440.75,"id":8908205},{"trd":[[1.94,32.88]],"batb":[[0,1.85,108.71],[1,1.83,168.27],[2,1.67,409.76]],"batl":[[0,1.93,146.32],[1,1.95,140.17]],"ltp":1.94,"tv":64.89,"id":4596961}],"tv":505.65}]}
{"op":"mcm","clk":"1004090192","pt":1580653329076,"mc":[{"id":"1.168224029","rc":[{"batb":[[0,2.04,40.33],[1,1.97,29.51],[2,1.78,20.22]],"batl":[[0,2.22,33.61]],"ltp":1.85,"tv":440.75,"id":8908205},{"batb":[[2,1.82,50.41]],"batl":[[2,1.97,42.01]],"ltp":1.94,"tv":64.89,"id":4596961}]}]}
{"op":"mcm","clk":"1004092499","pt":1580653340990,"mc":[{"id":"1.168224029","rc":[{"batb":[[0,1.82,50.41],[1,1.77,21.87],[2,1.67,409.76]],"batl":[[0,1.97,42.01],[1,1.95,0],[2,1.97,0]],"ltp":1.94,"tv":64.89,"id":4596961}]}]}
{"op":"mcm","clk":"1004092580","pt":1580653341384,"mc":[{"id":"1.168224029","rc":[{"batb":[[0,1.78,20.22],[1,1.67,409.76],[2,1.01,10.51]],"ltp":1.85,"tv":440.75,"id":8908205},{"batb":[[0,1.77,21.87],[1,1.67,409.76],[2,1.01,10.51]],"ltp":1.94,"tv":64.89,"id":4596961}]}]}
{"op":"mcm","clk":"1004093334","pt":1580653345091,"mc":[{"id":"1.168224029","rc":[{"batb":[[0,1.79,20.14]],"ltp":1.85,"tv":440.75,"id":8908205},{"batb":[[1,1.73,140.94],[2,1.71,210.96]],"batl":[[0,2.16,184.22],[1,2.18,101.5]],"ltp":1.94,"tv":64.89,"id":4596961}]}]}
{"op":"mcm","clk":"1004094877","pt":1580653353109,"mc":[{"id":"1.168224029","rc":[{"batb":[[1,1.67,409.76],[2,1.01,10.51]],"ltp":1.94,"tv":64.89,"id":4596961}]}]}
{"op":"mcm","clk":"1004095472","pt":1580653356081,"mc":[{"id":"1.168224029","rc":[{"batb":[[0,1.87,149.44],[1,1.85,211.39],[2,1.79,20.14]],"batl":[[0,1.95,108.58],[1,1.97,136.13]],"ltp":1.85,"tv":440.75,"id":8908205},{"batb":[[0,1.97,42.85],[1,1.77,21.87],[2,1.67,409.76]],"batl":[[0,2.16,36.13]],"ltp":1.94,"tv":64.89,"id":4596961}]}]}
{"op":"mcm","clk":"1004095654","pt":1580653357094,"mc":[{"id":"1.168224029","rc":[{"batb":[[1,1.85,162.66]],"ltp":1.85,"tv":440.75,"id":8908205},{"trd":[[2.16,47.84]],"batb":[[1,1.92,17],[2,1.78,532.57]],"batl":[[0,2.16,12.21]],"ltp":2.16,"tv":112.73,"id":4596961}],"tv":553.49}]}
{"op":"mcm","clk":"1004095684","pt":1580653357310,"mc":[{"id":"1.168224029","rc":[{"batb":[[2,1.67,409.76]],"ltp":2.16,"tv":112.73,"id":4596961}]}]}
{"op":"mcm","clk":"1004096030","pt":1580653359081,"mc":[{"id":"1.168224029","rc":[{"batb":[[1,1.86,48.73],[2,1.85,162.66]],"batl":[[2,2.04,40.33]],"ltp":1.85,"tv":440.75,"id":8908205}]}]}
{"op":"mcm","clk":"1004096195","pt":1580653359995,"mc":[{"id":"1.168224029","rc":[{"batl":[[0,2.16,35.73]],"ltp":2.16,"tv":112.73,"id":4596961}]}]}
{"op":"mcm","clk":"1004099733","pt":1580653377944,"mc":[{"id":"1.168224029","rc":[{"batb":[[0,1.86,48.73],[1,1.67,409.76],[2,1.59,30.14]],"batl":[[0,2.04,40.33],[1,1.97,0],[2,2.04,0]],"ltp":1.85,"tv":440.75,"id":8908205}]}]}
{"op":"mcm","clk":"1004099973","pt":1580653379277,"mc":[{"id":"1.168224029","rc":[{"batb":[[0,1.67,409.76],[1,1.59,30.14],[2,1.01,10.51]],"ltp":1.85,"tv":440.75,"id":8908205},{"batb":[[0,1.92,17],[1,1.67,409.76],[2,1.01,10.51]],"ltp":2.16,"tv":112.73,"id":4596961}]}]}
{"op":"mcm","clk":"1004100305","pt":1580653380859,"mc":[{"id":"1.168224029","rc":[{"batb":[[1,1.64,213.41],[2,1.63,126.29]],"batl":[[0,2.18,122.4],[1,2.2,98.8]],"ltp":1.85,"tv":440.75,"id":8908205},{"batb":[[0,1.9,17.47]],"ltp":2.16,"tv":112.73,"id":4596961}]}]}
{"op":"mcm","clk":"1004101073","pt":1580653384920,"mc":[{"id":"1.168224029","rc":[{"batb":[[1,1.6,29.43],[2,1.01,10.51]],"ltp":1.85,"tv":440.75,"id":8908205}]}]}
{"op":"mcm","clk":"1004101711","pt":1580653388100,"mc":[{"id":"1.168224029","rc":[{"batb":[[0,2,27.77],[1,1.79,20.06],[2,1.67,409.76]],"ltp":1.85,"tv":440.75,"id":8908205},{"batb":[[1,1.85,123.31],[2,1.83,168.29]],"batl":[[0,1.93,148.78],[1,1.95,140.17]],"ltp":2.16,"tv":112.73,"id":4596961}]}]}
{"op":"mcm","clk":"1004101730","pt":1580653388215,"mc":[{"id":"1.168224029","rc":[{"batb":[[0,2.02,41.17],[1,2,27.77],[2,1.79,20.06]],"batl":[[0,2.22,33.61]],"ltp":1.85,"tv":440.75,"id":8908205},{"batb":[[2,1.84,49.57]],"batl":[[2,1.99,42.01]],"ltp":2.16,"tv":112.73,"id":4596961}]}]}
{"op":"mcm","clk":"1004104423","pt":1580653402828,"mc":[{"id":"1.168224029","rc":[{"batb":[[1,1.79,20.06],[2,1.67,409.76]],"ltp":1.85,"tv":440.75,"id":8908205},{"batb":[[0,1.84,49.57],[1,1.72,24.16],[2,1.67,409.76]],"batl":[[0,1.99,42.01],[1,1.95,0],[2,1.99,0]],"ltp":2.16,"tv":112.73,"id":4596961}]}]}
{"op":"mcm","clk":"1004104535","pt":1580653403476,"mc":[{"id":"1.168224029","rc":[{"batb":[[0,1.79,20.06],[1,1.67,409.76],[2,1.01,10.51]],"ltp":1.85,"tv":440.75,"id":8908205},{"batb":[[0,1.72,24.16],[1,1.67,409.76],[2,1.01,10.51]],"ltp":2.16,"tv":112.73,"id":4596961}]}]}
{"op":"mcm","clk":"1004105060","pt":1580653406021,"mc":[{"id":"1.168224029","rc":[{"batb":[[1,1.71,158.64],[2,1.69,219.77]],"batl":[[0,2.2,162.93],[1,2.22,96.47]],"ltp":2.16,"tv":112.73,"id":4596961}]}]}
{"op":"mcm","clk":"1004106543","pt":1580653413637,"mc":[{"id":"1.168224029","rc":[{"batb":[[1,1.67,409.76],[2,1.01,10.51]],"ltp":2.16,"tv":112.73,"id":4596961}]}]}
{"op":"mcm","clk":"1004106956","pt":1580653415805,"mc":[{"id":"1.168224029","rc":[{"batb":[[1,1.01,10.51],[2,1.01,0]],"ltp":1.85,"tv":440.75,"id":8908205},{"batb":[[1,1.01,10.51],[2,1.01,0]],"ltp":2.16,"tv":112.73,"id":4596961}]}]}
{"op":"mcm","clk":"1004109119","pt":1580653427022,"mc":[{"id":"1.168224029","rc":[{"batb":[[1,1.71,158.64],[2,1.69,219.77]],"batl":[[0,2.2,162.93],[1,2.22,96.47]],"ltp":2.16,"tv":112.73,"id":4596961}]}]}
{"op":"mcm","clk":"1004110517","pt":1580653434018,"mc":[{"id":"1.168224029","rc":[{"batb":[[1,1.01,10.51],[2,1.69,0]],"ltp":2.16,"tv":112.73,"id":4596961}]}]}
{"op":"mcm","clk":"1004111103","pt":1580653437013,"mc":[{"id":"1.168224029","rc":[{"batb":[[0,1.84,138.75],[1,1.82,171.5],[2,1.79,20.06]],"batl":[[0,1.92,143.02],[1,1.94,142.56]],"ltp":1.85,"tv":440.75,"id":8908205}]}]}
{"op":"mcm","clk":"1004111315","pt":1580653438032,"mc":[{"id":"1.168224029","rc":[{"batb":[[0,2.14,24],[1,1.86,18.88],[2,1.01,10.51]],"ltp":2.16,"tv":112.73,"id":4596961}]}]}
{"op":"mcm","clk":"1004111506","pt":1580653439020,"mc":[{"id":"1.168224029","rc":[{"batb":[[2,1.81,51.25]],"batl":[[2,1.98,42.01]],"ltp":1.85,"tv":440.75,"id":8908205},{"batb":[[1,2.02,41.17],[2,1.86,18.88]],"batl":[[0,2.22,33.61]],"ltp":2.16,"tv":112.73,"id":4596961}]}]}
{"op":"mcm","clk":"1004115422","pt":1580653457993,"mc":[{"id":"1.168224029","rc":[{"batb":[[0,1.81,51.25],[1,1.55,453.94],[2,1.01,10.51]],"batl":[[0,1.98,42.01],[1,1.94,0],[2,1.98,0]],"ltp":1.85,"tv":440.75,"id":8908205},{"batb":[[0,2.02,41.17],[1,1.86,18.88],[2,1.7,409.32]],"ltp":2.16,"tv":112.73,"id":4596961}]}]}
{"op":"mcm","clk":"1004115681","pt":1580653459226,"mc":[{"id":"1.168224029","rc":[{"batb":[[0,1.55,453.94],[1,1.01,10.51],[2,1.01,0]],"ltp":1.85,"tv":440.75,"id":8908205},{"batb":[[0,1.86,18.88],[1,1.7,409.32],[2,1.01,10.51]],"ltp":2.16,"tv":112.73,"id":4596961}]}]}
{"op":"mcm","clk":"1004116701","pt":1580653464090,"mc":[{"id":"1.168224029","rc":[{"batb":[[0,1.78,110.01],[1,1.76,191.57],[2,1.55,453.94]],"batl":[[0,1.85,145.58],[1,1.87,159.63]],"ltp":1.85,"tv":440.75,"id":8908205}]}]}
{"op":"mcm","clk":"1004117102","pt":1580653465804,"mc":[{"id":"1.168224029","rc":[{"batb":[[0,1.55,453.94],[1,1.01,10.51],[2,1.55,0]],"ltp":1.85,"tv":440.75,"id":8908205}]}]}
{"op":"mcm","clk":"1004117715","pt":1580653468702,"mc":[{"id":"1.168224029","rc":[{"batb":[[0,1.56,190.22],[1,1.55,606.45],[2,1.01,10.51]],"batl":[[0,2.22,124.97],[1,2.24,93.95]],"ltp":1.85,"tv":440.75,"id":8908205}]}]}
{"op":"mcm","clk":"1004120927","pt":1580653483842,"mc":[{"id":"1.168224029","rc":[{"batb":[[0,1.55,453.94],[1,1.01,10.51],[2,1.01,0]],"ltp":1.85,"tv":440.75,"id":8908205}]}]}
{"op":"mcm","clk":"1004121538","pt":1580653486760,"mc":[{"id":"1.168224029","rc":[{"batb":[[0,1.55,33.44]],"ltp":1.85,"tv":440.75,"id":8908205},{"batb":[[1,1.82,149.6],[2,1.8,177.63]],"batl":[[0,1.9,149.14],[1,1.92,146.89]],"ltp":2.16,"tv":112.73,"id":4596961}]}]}
{"op":"mcm","clk":"1004121820","pt":1580653488069,"mc":[{"id":"1.168224029","rc":[{"batb":[[0,2.06,25.65],[1,1.78,20.38],[2,1.01,10.51]],"ltp":1.85,"tv":440.75,"id":8908205}]}]}
{"op":"mcm","clk":"1004121875","pt":1580653488269,"mc":[{"id":"1.168224029","rc":[{"batb":[[1,2.04,40.33],[2,1.78,20.38]],"batl":[[0,2.24,33.61]],"ltp":1.85,"tv":440.75,"id":8908205},{"batb":[[1,1.82,200.01]],"batl":[[2,1.97,42.01]],"ltp":2.16,"tv":112.73,"id":4596961}]}]}
{"op":"mcm","clk":"1004126583","pt":1580653510047,"mc":[{"id":"1.168224029","rc":[{"batb":[[0,2.04,40.33],[1,1.78,20.38],[2,1.7,409.32]],"ltp":1.85,"tv":440.75,"id":8908205},{"batb":[[0,1.82,50.41],[1,1.64,28.25],[2,1.55,420.5]],"batl":[[0,1.97,42.01],[1,1.92,0],[2,1.97,0]],"ltp":2.16,"tv":112.73,"id":4596961}]}]}
{"op":"mcm","clk":"1004126960","pt":1580653511872,"mc":[{"id":"1.168224029","rc":[{"batb":[[0,1.78,20.38],[1,1.7,409.32],[2,1.01,10.51]],"ltp":1.85,"tv":440.75,"id":8908205},{"batb":[[0,1.64,28.25],[1,1.55,420.5],[2,1.01,10.51]],"ltp":2.16,"tv":112.73,"id":4596961}]}]}
{"op":"mcm","clk":"1004127203","pt":1580653512964,"mc":[{"id":"1.168224029","rc":[{"batb":[[0,1.66,201.67],[1,1.65,120.45],[2,1.64,28.25]],"batl":[[0,2.2,88.12],[1,2.22,96.39]],"ltp":2.16,"tv":112.73,"id":4596961}]}]}
{"op":"mcm","clk":"1004127858","pt":1580653515750,"mc":[{"id":"1.168224029","rc":[{"batb":[[0,1.64,28.25],[1,1.55,420.5],[2,1.01,10.51]],"ltp":2.16,"tv":112.73,"id":4596961}]}]}
{"op":"mcm","clk":"1004128600","pt":1580653519087,"mc":[{"id":"1.168224029","rc":[{"batb":[[0,1.87,144.36],[1,1.85,162.53],[2,1.64,28.25]],"batl":[[0,1.95,112.9],[1,1.97,135.99]],"ltp":2.16,"tv":112.73,"id":4596961}]}]}
{"op":"mcm","clk":"1004128844","pt":1580653520074,"mc":[{"id":"1.168224029","rc":[{"batb":[[0,1.64,28.25],[1,1.55,420.5],[2,1.01,10.51]],"ltp":2.16,"tv":112.73,"id":4596961}]}]}
{"op":"mcm","clk":"1004129526","pt":1580653523066,"mc":[{"id":"1.168224029","rc":[{"batb":[[0,1.66,201.67],[1,1.65,120.45],[2,1.64,28.25]],"batl":[[0,2.2,88.12],[1,2.22,96.39]],"ltp":2.16,"tv":112.73,"id":4596961}]}]}
{"op":"mcm","clk":"1004130426","pt":1580653527012,"mc":[{"id":"1.168224029","rc":[{"batb":[[0,1.64,28.25],[1,1.55,420.5],[2,1.01,10.51]],"ltp":2.16,"tv":112.73,"id":4596961}]}]}
{"op":"mcm","clk":"1004130845","pt":1580653529022,"mc":[{"id":"1.168224029","rc":[{"batb":[[1,1.01,10.51],[2,1.01,0]],"ltp":1.85,"tv":440.75,"id":8908205},{"batb":[[1,1.01,10.51],[2,1.01,0]],"ltp":2.16,"tv":112.73,"id":4596961}]}]}
{"op":"mcm","clk":"1004131066","pt":1580653530023,"mc":[{"id":"1.168224029","rc":[{"batb":[[0,1.83,134.28],[1,1.81,174.61],[2,1.78,20.38]],"batl":[[0,1.91,155.8],[1,1.93,144.8]],"ltp":1.85,"tv":440.75,"id":8908205}]}]}
{"op":"mcm","clk":"1004131308","pt":1580653531017,"mc":[{"id":"1.168224029","rc":[{"batb":[[2,1.8,52.09]],"batl":[[2,1.97,42.01]],"ltp":1.85,"tv":440.75,"id":8908205},{"batb":[[0,2.16,23.6],[1,2.04,40.33],[2,1.86,18.65]],"batl":[[0,2.22,33.61]],"ltp":2.16,"tv":112.73,"id":4596961}]}]}
{"op":"mcm","clk":"1004136201","pt":1580653552808,"mc":[{"id":"1.168224029","rc":[{"batb":[[0,1.8,52.09],[1,1.55,420.5],[2,1.54,33.83]],"batl":[[0,1.97,42.01],[1,1.93,0],[2,1.97,0]],"ltp":1.85,"tv":440.75,"id":8908205},{"batb":[[0,2.04,40.33],[1,1.86,18.65],[2,1.7,409.32]],"ltp":2.16,"tv":112.73,"id":4596961}]}]}
{"op":"mcm","clk":"1004136306","pt":1580653553314,"mc":[{"id":"1.168224029","rc":[{"batb":[[0,1.55,420.5],[1,1.54,33.83],[2,1.01,10.51]],"ltp":1.85,"tv":440.75,"id":8908205},{"batb":[[0,1.86,18.65],[1,1.7,409.32],[2,1.01,10.51]],"ltp":2.16,"tv":112.73,"id":4596961}]}]}
{"op":"mcm","clk":"1004136770","pt":1580653555606,"mc":[{"id":"1.168224029","rc":[{"batb":[[0,1.55,660.22],[1,1.54,190.47]],"batl":[[0,2.2,97],[1,2.22,96.28]],"ltp":1.85,"tv":440.75,"id":8908205},{"batb":[[0,1.87,18.57]],"ltp":2.16,"tv":112.73,"id":4596961}]}]}
{"op":"mcm","clk":"1004138637","pt":1580653564101,"mc":[{"id":"1.168224029","rc":[{"batb":[[0,1.55,239.72]],"batl":[[0,1.61,200.99],[1,1.62,127.79]],"ltp":1.85,"tv":440.75,"id":8908205},{"batb":[[1,1.01,10.51],[2,1.01,0]],"ltp":2.16,"tv":112.73,"id":4596961}]}]}
{"op":"mcm","clk":"1004138855","pt":1580653565017,"mc":[{"id":"1.168224029","rc":[{"batb":[[0,1.55,315.34],[2,1.34,60.59]],"batl":[[2,1.66,42.01]],"ltp":1.85,"tv":440.75,"id":8908205},{"batb":[[0,2.68,13.3],[1,2.52,26.89],[2,2.16,23.37]],"batl":[[0,2.82,22.69]],"ltp":2.16,"tv":112.73,"id":4596961}]}]}
{"op":"mcm","clk":"1004139443","pt":1580653567519,"mc":[{"id":"1.168224029","rc":[{"batb":[[2,1.38,448.45]],"ltp":1.85,"tv":440.75,"id":8908205}]}]}
{"op":"mcm","clk":"1004142573","pt":1580653581820,"mc":[{"id":"1.168224029","rc":[{"batb":[[0,1.55,75.62],[1,1.38,448.45],[2,1.34,60.59]],"batl":[[0,1.66,42.01],[1,1.62,0],[2,1.66,0]],"ltp":1.85,"tv":440.75,"id":8908205},{"batb":[[0,2.52,26.89],[1,2.16,23.37],[2,1.97,394.86]],"ltp":2.16,"tv":112.73,"id":4596961}]}]}
{"op":"mcm","clk":"1004142872","pt":1580653583237,"mc":[{"id":"1.168224029","rc":[{"batb":[[0,1.38,448.45],[1,1.34,60.59],[2,1.01,10.51]],"ltp":1.85,"tv":440.75,"id":8908205},{"batb":[[0,2.16,23.37],[1,1.97,394.86],[2,1.01,10.51]],"ltp":2.16,"tv":112.73,"id":4596961}]}]}
{"op":"mcm","clk":"1004143248","pt":1580653585032,"mc":[{"id":"1.168224029","rc":[{"batb":[[2,1.3,289.81]],"batl":[[0,1.9,156.8],[1,1.92,147.1]],"ltp":1.85,"tv":440.75,"id":8908205},{"batb":[[0,2.18,23.29]],"ltp":2.16,"tv":112.73,"id":4596961}]}]}
{"op":"mcm","clk":"1004145015","pt":1580653592826,"mc":[{"id":"1.168224029","rc":[{"batb":[[0,1.34,60.59],[1,1.3,289.81],[2,1.29,353.05]],"ltp":1.85,"tv":440.75,"id":8908205},{"batb":[[1,1.01,10.51],[2,1.01,0]],"ltp":2.16,"tv":112.73,"id":4596961}]}]}
{"op":"mcm","clk":"1004145204","pt":1580653593706,"mc":[{"id":"1.168224029","rc":[{"trd":[[1.34,121.17]],"batb":[[0,1.3,289.81],[1,1.29,353.05],[2,1.01,10.51]],"batl":[[0,1.34,280.35]],"ltp":1.34,"tv":561.92,"id":8908205}],"tv":674.65}]}
{"op":"mcm","clk":"1004145374","pt":1580653594517,"mc":[{"id":"1.168224029","rc":[{"batb":[[2,1.26,244.64]],"ltp":1.34,"tv":561.92,"id":8908205},{"batb":[[0,3.55,15.97],[1,2.96,25.57],[2,1.01,10.51]],"batl":[[0,4.8,10.92]],"ltp":2.16,"tv":112.73,"id":4596961}]}]}
{"op":"mcm","clk":"1004145954","pt":1580653597119,"mc":[{"id":"1.168224029","rc":[{"batl":[[0,1.32,42.01],[1,1.34,420.48],[2,1.35,266.38]],"ltp":1.34,"tv":561.92,"id":8908205},{"batb":[[0,4.1,13.44],[1,3.55,15.97],[2,2.96,25.57]],"ltp":2.16,"tv":112.73,"id":4596961}]}]}
{"op":"mcm","clk":"1004146928","pt":1580653602048,"mc":[{"id":"1.168224029","rc":[{"trd":[[1.32,84.02],[1.33,22.74]],"batl":[[0,1.34,420.48],[1,1.35,266.38],[2,1.35,0]],"ltp":1.33,"tv":668.68,"id":8908205},{"trd":[[4.1,7.38]],"batb":[[0,4.1,6.07],[1,3.7,14.71],[2,3.55,15.97]],"ltp":4.1,"tv":120.1,"id":4596961}],"tv":788.79}]}
{"op":"mcm","clk":"1004147089","pt":1580653602861,"mc":[{"id":"1.168224029","rc":[{"batb":[[2,1.25,88.52]],"ltp":1.33,"tv":668.68,"id":8908205},{"batb":[[0,3.7,14.71],[1,3.05,23.53],[2,2.52,381.46]],"ltp":4.1,"tv":120.1,"id":4596961}]}]}
{"op":"mcm","clk":"1004147618","pt":1580653605773,"mc":[{"id":"1.168224029","rc":[{"batb":[[2,1.27,155.44]],"batl":[[0,1.33,42.01],[1,1.34,420.48],[2,1.35,266.38]],"ltp":1.33,"tv":668.68,"id":8908205},{"batb":[[0,4,13.44],[1,3.7,14.71],[2,3.05,23.53]],"batl":[[0,4.7,10.92]],"ltp":4.1,"tv":120.1,"id":4596961}]}]}
{"op":"mcm","clk":"1004148509","pt":1580653610405,"mc":[{"id":"1.168224029","rc":[{"batb":[[0,1.32,67.12],[1,1.3,289.81],[2,1.29,353.05]],"ltp":1.33,"tv":668.68,"id":8908205},{"batb":[[1,3.75,14.01],[2,3.1,22.42]],"ltp":4.1,"tv":120.1,"id":4596961}]}]}
{"op":"mcm","clk":"1004149563","pt":1580653616084,"mc":[{"id":"1.168224029","rc":[{"trd":[[4,4.54]],"batb":[[0,4,11.17]],"ltp":4.0,"tv":124.64,"id":4596961}],"tv":793.33}]}
{"op":"mcm","clk":"1004154271","pt":1580653639838,"mc":[{"id":"1.168224029","rc":[{"batl":[[1,1.34,280.37],[2,3,6.82]],"ltp":1.33,"tv":668.68,"id":8908205}]}]}
{"op":"mcm","clk":"1004154840","pt":1580653642650,"mc":[{"id":"1.168224029","rc":[{"batl":[[0,1.33,197.68]],"ltp":1.33,"tv":668.68,"id":8908205}]}]}
{"op":"mcm","clk":"1004155270","pt":1580653644853,"mc":[{"id":"1.168224029","rc":[{"batb":[[1,1.3,236.59]],"ltp":1.33,"tv":668.68,"id":8908205}]}]}
{"op":"mcm","clk":"1004155920","pt":1580653647852,"mc":[{"id":"1.168224029","rc":[{"batl":[[0,1.33,257.87]],"ltp":1.33,"tv":668.68,"id":8908205}]}]}
{"op":"mcm","clk":"1004163094","pt":1580653683020,"mc":[{"id":"1.168224029","rc":[{"batb":[[0,1.27,155.44],[1,1.24,91.66],[2,1.2,530.86]],"batl":[[0,1.33,42.01],[1,3,6.82],[2,3,0]],"ltp":1.33,"tv":668.68,"id":8908205},{"batb":[[1,3.1,22.42],[2,2.52,381.46]],"ltp":4.0,"tv":124.64,"id":4596961}]}]}
{"op":"mcm","clk":"1004163251","pt":1580653683741,"mc":[{"id":"1.168224029","rc":[{"batb":[[0,1.24,91.66],[1,1.2,530.86],[2,1.01,10.51]],"batl":[[0,3,6.82],[1,3,0]],"ltp":1.33,"tv":668.68,"id":8908205},{"batb":[[0,3.1,22.42],[1,2.52,381.46],[2,1.01,10.51]],"ltp":4.0,"tv":124.64,"id":4596961}]}]}
{"op":"mcm","clk":"1004163668","pt":1580653685533,"mc":[{"id":"1.168224029","rc":[{"batb":[[1,1.23,545.2],[2,1.22,502.75]],"batl":[[0,1.45,242.2],[1,1.46,190.75],[2,3,6.82]],"ltp":1.33,"tv":668.68,"id":8908205}]}]}
{"op":"mcm","clk":"1004164203","pt":1580653688152,"mc":[{"id":"1.168224029","rc":[{"batb":[[1,1.2,530.86],[2,1.01,10.51]],"ltp":1.33,"tv":668.68,"id":8908205}]}]}
{"op":"mcm","clk":"1004164852","pt":1580653691034,"mc":[{"id":"1.168224029","rc":[{"batb":[[1,1.01,10.51],[2,1.01,0]],"ltp":1.33,"tv":668.68,"id":8908205},{"batb":[[1,1.01,10.51],[2,1.01,0]],"ltp":4.0,"tv":124.64,"id":4596961}]}]}
{"op":"mcm","clk":"1004165081","pt":1580653692053,"mc":[{"id":"1.168224029","rc":[{"batb":[[0,1.42,47.05],[1,1.41,149.68],[2,1.4,234.06]],"ltp":1.33,"tv":668.68,"id":8908205},{"batb":[[1,2.62,14.08],[2,1.01,10.51]],"ltp":4.0,"tv":124.64,"id":4596961}]}]}
{"op":"mcm","clk":"1004165134","pt":1580653692262,"mc":[{"id":"1.168224029","rc":[{"batl":[[0,1.45,284.21]],"ltp":1.33,"tv":668.68,"id":8908205},{"batb":[[0,3.25,18.48],[1,3.1,22.42],[2,2.62,14.08]],"batl":[[0,3.7,15.12]],"ltp":4.0,"tv":124.64,"id":4596961}]}]}
{"op":"mcm","clk":"1004167907","pt":1580653706100,"mc":[{"id":"1.168224029","rc":[{"batb":[[0,1.36,115.95],[1,1.33,64.76],[2,1.28,485.89]],"batl":[[0,1.45,42.01],[1,3,6.82],[2,3,0]],"ltp":1.33,"tv":668.68,"id":8908205},{"batb":[[1,2.62,14.08],[2,2.22,384.52]],"ltp":4.0,"tv":124.64,"id":4596961}]}]}
{"op":"mcm","clk":"1004168160","pt":1580653707428,"mc":[{"id":"1.168224029","rc":[{"batb":[[0,1.33,64.76],[1,1.28,485.89],[2,1.01,10.51]],"batl":[[0,3,6.82],[1,3,0]],"ltp":1.33,"tv":668.68,"id":8908205},{"batb":[[0,2.62,14.08],[1,2.22,384.52],[2,1.01,10.51]],"ltp":4.0,"tv":124.64,"id":4596961}]}]}
{"op":"mcm","clk":"1004168414","pt":1580653708720,"mc":[{"id":"1.168224029","rc":[{"batb":[[1,1.31,382.36],[2,1.3,341.33]],"batl":[[0,1.62,142.05],[1,1.63,125.79],[2,3,6.82]],"ltp":1.33,"tv":668.68,"id":8908205}]}]}
{"op":"mcm","clk":"1004168605","pt":1580653709627,"mc":[{"id":"1.168224029","rc":[{"batb":[[0,1.32,65.54]],"ltp":1.33,"tv":668.68,"id":8908205},{"batb":[[0,2.64,13.85]],"ltp":4.0,"tv":124.64,"id":4596961}]}]}
{"op":"mcm","clk":"1004169226","pt":1580653713102,"mc":[{"id":"1.168224029","rc":[{"batl":[[0,3,6.82],[1,1.63,0],[2,3,0]],"ltp":1.33,"tv":668.68,"id":8908205}]}]}
{"op":"mcm","clk":"1004169370","pt":1580653713919,"mc":[{"id":"1.168224029","rc":[{"batb":[[1,1.01,10.51],[2,1.01,0]],"ltp":4.0,"tv":124.64,"id":4596961}]}]}
{"op":"mcm","clk":"1004169749","pt":1580653715915,"mc":[{"id":"1.168224029","rc":[{"batl":[[0,1.35,321.34],[1,1.36,259.7],[2,3,6.82]],"ltp":1.33,"tv":668.68,"id":8908205},{"batb":[[0,3.7,14.48],[1,3,24.86],[2,1.01,10.51]],"ltp":4.0,"tv":124.64,"id":4596961}]}]}
{"op":"mcm","clk":"1004169889","pt":1580653716610,"mc":[{"id":"1.168224029","rc":[{"batl":[[0,1.35,363.35]],"ltp":1.33,"tv":668.68,"id":8908205},{"batb":[[0,3.85,14.28],[1,3.7,14.48],[2,3,24.86]],"batl":[[0,4.5,11.76]],"ltp":4.0,"tv":124.64,"id":4596961}]}]}
{"op":"mcm","clk":"1004172660","pt":1580653730934,"mc":[{"id":"1.168224029","rc":[{"batb":[[0,1.29,144.51],[1,1.23,95.28],[2,1.22,523]],"batl":[[0,1.35,42.01],[1,3,6.82],[2,3,0]],"ltp":1.33,"tv":668.68,"id":8908205},{"batb":[[1,3,24.86],[2,2.42,381.73]],"ltp":4.0,"tv":124.64,"id":4596961}]}]}
{"op":"mcm","clk":"1004172771","pt":1580653731538,"mc":[{"id":"1.168224029","rc":[{"batb":[[0,1.23,95.28],[1,1.22,523],[2,1.01,10.51]],"batl":[[0,3,6.82],[1,3,0]],"ltp":1.33,"tv":668.68,"id":8908205},{"batb":[[0,3,24.86],[1,2.42,381.73],[2,1.01,10.51]],"ltp":4.0,"tv":124.64,"id":4596961}]}]}
{"op":"mcm","clk":"1004173242","pt":1580653734097,"mc":[{"id":"1.168224029","rc":[{"batb":[[0,1.23,645.77],[1,1.22,1023.14]],"ltp":1.33,"tv":668.68,"id":8908205}]}]}
{"op":"mcm","clk":"1004173401","pt":1580653734965,"mc":[{"id":"1.168224029","rc":[{"batb":[[1,1.22,500.14]],"ltp":1.33,"tv":668.68,"id":8908205},{"batb":[[1,1.01,10.51],[2,1.01,0]],"ltp":4.0,"tv":124.64,"id":4596961}]}]}
{"op":"mcm","clk":"1004173977","pt":1580653737799,"mc":[{"id":"1.168224029","rc":[{"batb":[[2,1.17,138.87]],"batl":[[0,1.26,227.31],[1,1.27,371.39],[2,3,6.82]],"ltp":1.33,"tv":668.68,"id":8908205},{"batb":[[0,4.6,17.15],[1,3.65,15.19],[2,1.01,10.51]],"ltp":4.0,"tv":124.64,"id":4596961}]}]}
{"op":"mcm","clk":"1004174238","pt":1580653739102,"mc":[{"id":"1.168224029","rc":[{"batb":[[1,1.22,668.18]],"batl":[[1,1.27,413.4]],"ltp":1.33,"tv":668.68,"id":8908205},{"batb":[[0,4.7,10.92],[1,4.6,17.15],[2,3.65,15.19]],"batl":[[0,5.5,9.24]],"ltp":4.0,"tv":124.64,"id":4596961}]}]}
{"op":"mcm","clk":"1004176933","pt":1580653751116,"mc":[{"id":"1.168224029","rc":[{"batb":[[0,1.22,168.04],[1,1.17,138.87],[2,1.16,576.13]],"batl":[[0,1.27,42.01],[1,3,6.82],[2,3,0]],"ltp":1.33,"tv":668.68,"id":8908205},{"batb":[[1,3.65,15.19],[2,2.72,378.25]],"ltp":4.0,"tv":124.64,"id":4596961}]}]}
{"op":"mcm","clk":"1004177034","pt":1580653751503,"mc":[{"id":"1.168224029","rc":[{"batb":[[0,1.17,138.87],[1,1.16,576.13],[2,1.01,10.51]],"batl":[[0,3,6.82],[1,3,0]],"ltp":1.33,"tv":668.68,"id":8908205},{"batb":[[0,3.65,15.19],[1,2.72,378.25],[2,1.01,10.51]],"ltp":4.0,"tv":124.64,"id":4596961}]}]}
{"op":"mcm","clk":"1004177570","pt":1580653754092,"mc":[{"id":"1.168224029","rc":[{"batb":[[0,1.18,303.23],[1,1.17,809.94],[2,1.16,576.13]],"batl":[[0,1.37,379.36],[1,1.38,241.95],[2,3,6.82]],"ltp":1.33,"tv":668.68,"id":8908205}]}]}
{"op":"mcm","clk":"1004177728","pt":1580653754906,"mc":[{"id":"1.168224029","rc":[{"batb":[[0,1.17,138.87],[1,1.16,576.13],[2,1.01,10.51]],"batl":[[0,3,6.82],[1,1.38,0],[2,3,0]],"ltp":1.33,"tv":668.68,"id":8908205}]}]}
{"op":"mcm","clk":"1004178001","pt":1580653756101,"mc":[{"id":"1.168224029","rc":[{"batb":[[1,1.01,10.51],[2,1.01,0]],"ltp":1.33,"tv":668.68,"id":8908205}]}]}
{"op":"mcm","clk":"1004178548","pt":1580653758596,"mc":[{"id":"1.168224029","rc":[{"batb":[[0,1.25,416.46],[1,1.24,449.69],[2,1.17,138.87]],"batl":[[0,1.28,245.89],[1,1.29,340.32],[2,3,6.82]],"ltp":1.33,"tv":668.68,"id":8908205}]}]}
{"op":"mcm","clk":"1004178777","pt":1580653759710,"mc":[{"id":"1.168224029","rc":[{"batb":[[2,1.18,549.72]],"ltp":1.33,"tv":668.68,"id":8908205}]}]}
{"op":"mcm","clk":"1004178965","pt":1580653760485,"mc":[{"id":"1.168224029","rc":[{"batb":[[0,1.18,549.72],[1,1.17,138.87],[2,1.01,10.51]],"batl":[[0,3,6.82],[1,1.29,0],[2,3,0]],"ltp":1.33,"tv":668.68,"id":8908205}]}]}
{"op":"mcm","clk":"1004179595","pt":1580653763427,"mc":[{"id":"1.168224029","rc":[{"batb":[[0,1.18,852.95],[1,1.17,809.94]],"batl":[[0,1.37,379.36],[1,1.38,241.95],[2,3,6.82]],"ltp":1.33,"tv":668.68,"id":8908205}]}]}
{"op":"mcm","clk":"1004181818","pt":1580653774048,"mc":[{"id":"1.168224029","rc":[{"batb":[[0,1.18,549.72],[1,1.17,138.87]],"batl":[[0,3,6.82],[1,1.38,0],[2,3,0]],"ltp":1.33,"tv":668.68,"id":8908205}]}]}
{"op":"mcm","clk":"1004182410","pt":1580653776907,"mc":[{"id":"1.168224029","rc":[{"batb":[[0,1.23,550.49],[1,1.22,500.14],[2,1.18,549.72]],"batl":[[0,1.26,227.31],[1,1.27,371.39],[2,3,6.82]],"ltp":1.33,"tv":668.68,"id":8908205}]}]}
{"op":"mcm","clk":"1004183632","pt":1580653782830,"mc":[{"id":"1.168224029","rc":[{"batb":[[0,1.18,549.72],[1,1.17,138.87],[2,1.01,10.51]],"batl":[[0,3,6.82],[1,1.27,0],[2,3,0]],"ltp":1.33,"tv":668.68,"id":8908205}]}]}
{"op":"mcm","clk":"1004184248","pt":1580653786030,"mc":[{"id":"1.168224029","rc":[{"batb":[[0,1.18,852.95],[1,1.17,809.94]],"batl":[[0,1.37,379.36],[1,1.38,241.95],[2,3,6.82]],"ltp":1.33,"tv":668.68,"id":8908205}]}]}
{"op":"mcm","clk":"1004184810","pt":1580653789034,"mc":[{"id":"1.168224029","rc":[{"batl":[[0,3,6.82],[1,1.38,0],[2,3,0]],"ltp":1.33,"tv":668.68,"id":8908205}]}]}
{"op":"mcm","clk":"1004185072","pt":1580653790345,"mc":[{"id":"1.168224029","rc":[{"batb":[[0,1.18,303.23]],"ltp":1.33,"tv":668.68,"id":8908205},{"batb":[[1,1.01,10.51],[2,1.01,0]],"ltp":4.0,"tv":124.64,"id":4596961}]}]}
{"op":"mcm","clk":"1004185328","pt":1580653791944,"mc":[{"id":"1.168224029","rc":[{"batl":[[0,1.2,305.54],[1,1.21,497.3],[2,3,6.82]],"ltp":1.33,"tv":668.68,"id":8908205}]}]}
{"op":"mcm","clk":"1004185500","pt":1580653792929,"mc":[{"id":"1.168224029","rc":[{"batb":[[1,1.17,977.98],[2,1.13,183.8]],"ltp":1.33,"tv":668.68,"id":8908205},{"batb":[[0,5.9,19.75],[1,5.6,8.4],[2,4.8,15.42]],"batl":[[0,6.8,6.72]],"ltp":4.0,"tv":124.64,"id":4596961}]}]}
{"op":"mcm","clk":"1004188819","pt":1580653808808,"mc":[{"id":"1.168224029","rc":[{"batb":[[0,1.17,168.04],[1,1.13,183.01],[2,1.11,684.32]],"batl":[[0,3,6.82],[1,1.21,0],[2,3,0]],"ltp":1.33,"tv":668.68,"id":8908205},{"batb":[[0,5.6,8.4],[1,4.8,15.42],[2,3,380.84]],"ltp":4.0,"tv":124.64,"id":4596961}]}]}
{"op":"mcm","clk":"1004189000","pt":1580653810047,"mc":[{"id":"1.168224029","rc":[{"batb":[[0,1.13,183.01],[1,1.11,684.32],[2,1.01,10.51]],"ltp":1.33,"tv":668.68,"id":8908205},{"batb":[[0,4.8,15.42],[1,3,380.84],[2,1.01,10.51]],"ltp":4.0,"tv":124.64,"id":4596961}]}]}
{"op":"mcm","clk":"1004189460","pt":1580653812093,"mc":[{"id":"1.168224029","rc":[{"batb":[[0,1.15,465.57],[1,1.14,659.53],[2,1.13,183.01]],"batl":[[0,1.25,300.26],[1,1.26,386.86],[2,3,6.82]],"ltp":1.33,"tv":668.68,"id":8908205}]}]}
{"op":"mcm","clk":"1004191171","pt":1580653821880,"mc":[{"id":"1.168224029","rc":[{"batb":[[0,1.13,183.01],[1,1.11,684.32],[2,1.01,10.51]],"ltp":1.33,"tv":668.68,"id":8908205}]}]}
{"op":"mcm","clk":"1004191555","pt":1580653824087,"mc":[{"id":"1.168224029","rc":[{"batb":[[1,1.01,10.51],[2,1.01,0]],"ltp":1.33,"tv":668.68,"id":8908205}]}]}
{"op":"mcm","clk":"1004191708","pt":1580653825002,"mc":[{"id":"1.168224029","rc":[{"batb":[[0,1.22,534.89],[1,1.21,524.55],[2,1.13,183.01]],"batl":[[1,1.26,428.87]],"ltp":1.33,"tv":668.68,"id":8908205},{"batb":[[0,4.8,26.34]],"ltp":4.0,"tv":124.64,"id":4596961}]}]}
{"op":"mcm","clk":"1004191897","pt":1580653825975,"mc":[{"id":"1.168224029","rc":[{"batb":[[0,1.22,526.98],[1,1.21,692.59],[2,1.14,167.67]],"ltp":1.33,"tv":668.68,"id":8908205},{"batb":[[1,3.6,15.58],[2,3,380.84]],"batl":[[0,5.8,8.4]],"ltp":4.0,"tv":124.64,"id":4596961}]}]}
{"op":"mcm","clk":"1004192116","pt":1580653827193,"mc":[{"id":"1.168224029","rc":[{"batb":[[2,1.16,576.13]],"ltp":1.33,"tv":668.68,"id":8908205}]}]}
{"op":"mcm","clk":"1004192410","pt":1580653828760,"mc":[{"id":"1.168224029","rc":[{"batl":[[0,1.25,407.7]],"ltp":1.33,"tv":668.68,"id":8908205}]}]}
{"op":"mcm","clk":"1004195401","pt":1580653845515,"mc":[{"id":"1.168224029","rc":[{"batb":[[0,1.16,576.13],[1,1.14,167.67],[2,1.01,10.51]],"batl":[[0,3,6.82],[1,1.26,0],[2,3,0]],"ltp":1.33,"tv":668.68,"id":8908205},{"batb":[[0,3.6,15.58],[1,3,380.84],[2,1.01,10.51]],"ltp":4.0,"tv":124.64,"id":4596961}]}]}
{"op":"mcm","clk":"1004195864","pt":1580653848025,"mc":[{"id":"1.168224029","rc":[{"batb":[[0,1.16,750.85],[1,1.15,774.36],[2,1.14,167.67]],"batl":[[0,1.37,296.33],[1,1.38,244.42],[2,3,6.82]],"ltp":1.33,"tv":668.68,"id":8908205}]}]}
{"op":"mcm","clk":"1004195929","pt":1580653848290,"mc":[{"id":"1.168224029","rc":[{"batb":[[0,1.16,576.13],[1,1.14,167.67],[2,1.01,10.51]],"batl":[[0,3,6.82],[1,1.38,0],[2,3,0]],"ltp":1.33,"tv":668.68,"id":8908205}]}]}
{"op":"mcm","clk":"1004196379","pt":1580653850517,"mc":[{"id":"1.168224029","rc":[{"batb":[[0,1.24,421.75],[1,1.23,476.31],[2,1.16,576.13]],"batl":[[0,1.27,297.72],[1,1.28,356.32],[2,3,6.82]],"ltp":1.33,"tv":668.68,"id":8908205}]}]}
{"op":"mcm","clk":"1004197038","pt":1580653854153,"mc":[{"id":"1.168224029","rc":[{"batb":[[0,1.16,576.13],[1,1.14,167.67],[2,1.01,10.51]],"batl":[[0,3,6.82],[1,1.28,0],[2,3,0]],"ltp":1.33,"tv":668.68,"id":8908205}]}]}
{"op":"mcm","clk":"1004197574","pt":1580653857015,"mc":[{"id":"1.168224029","rc":[{"batb":[[0,1.16,749.03],[1,1.15,774.36],[2,1.14,167.67]],"batl":[[0,1.37,297.87],[1,1.38,244.42],[2,3,6.82]],"ltp":1.33,"tv":668.68,"id":8908205}]}]}
{"op":"mcm","clk":"1004198859","pt":1580653863850,"mc":[{"id":"1.168224029","rc":[{"batl":[[0,3,6.82],[1,1.38,0],[2,3,0]],"ltp":1.33,"tv":668.68,"id":8908205}]}]}
{"op":"mcm","clk":"1004199268","pt":1580653865958,"mc":[{"id":"1.168224029","rc":[{"batb":[[0,1.16,172.9]],"ltp":1.33,"tv":668.68,"id":8908205}]}]}
{"op":"mcm","clk":"1004199420","pt":1580653866859,"mc":[{"id":"1.168224029","rc":[{"batb":[[1,1.15,942.4]],"batl":[[0,1.18,573.7],[1,1.19,511.62],[2,3,6.82]],"ltp":1.33,"tv":668.68,"id":8908205},{"batb":[[0,6.6,14.63],[1,5.6,11.17],[2,3.6,15.58]],"batl":[[0,7.6,5.88]],"ltp":4.0,"tv":124.64,"id":4596961}]}]}
{"op":"mcm","clk":"1004199595","pt":1580653867838,"mc":[{"id":"1.168224029","rc":[{"batl":[[1,1.19,553.63]],"ltp":1.33,"tv":668.68,"id":8908205},{"batb":[[1,6.2,7.56],[2,5.6,11.17]],"ltp":4.0,"tv":124.64,"id":4596961}]}]}
{"op":"mcm","clk":"1004203738","pt":1580653887997,"mc":[{"id":"1.168224029","rc":[{"trd":[[1.16,36]],"batb":[[0,1.16,154.9]],"ltp":1.16,"tv":704.68,"id":8908205}],"tv":829.33}]}
{"op":"mcm","clk":"1004203810","pt":1580653888378,"mc":[{"id":"1.168224029","rc":[{"batb":[[0,1.15,942.4],[1,1.14,167.67],[2,1.1,238.88]],"ltp":1.16,"tv":704.68,"id":8908205}]}]}
{"op":"mcm","clk":"1004204565","pt":1580653891890,"mc":[{"id":"1.168224029","rc":[{"batb":[[0,1.15,1109.23],[1,1.14,346.11]],"ltp":1.16,"tv":704.68,"id":8908205}]}]}
{"op":"mcm","clk":"1004204732","pt":1580653892608,"mc":[{"id":"1.168224029","rc":[{"batb":[[0,1.15,168.04],[1,1.1,238.88],[2,1.09,779.05]],"batl":[[0,1.19,42.01],[1,3,6.82],[2,3,0]],"ltp":1.16,"tv":704.68,"id":8908205},{"batb":[[0,6.2,7.56],[1,5.6,11.17],[2,3,380.84]],"ltp":4.0,"tv":124.64,"id":4596961}]}]}
{"op":"mcm","clk":"1004204947","pt":1580653893617,"mc":[{"id":"1.168224029","rc":[{"batb":[[0,1.1,238.88],[1,1.09,779.05],[2,1.01,10.51]],"batl":[[0,3,6.82],[1,3,0]],"ltp":1.16,"tv":704.68,"id":8908205},{"batb":[[0,5.6,11.17],[1,3,380.84],[2,1.01,10.51]],"ltp":4.0,"tv":124.64,"id":4596961}]}]}
{"op":"mcm","clk":"1004205270","pt":1580653895107,"mc":[{"id":"1.168224029","rc":[{"batb":[[0,1.12,225.04],[1,1.11,931.3],[2,1.1,238.88]],"batl":[[0,1.21,272.55],[1,1.22,475.29],[2,3,6.82]],"ltp":1.16,"tv":704.68,"id":8908205}]}]}
{"op":"mcm","clk":"1004206293","pt":1580653900118,"mc":[{"id":"1.168224029","rc":[{"batl":[[0,3,6.82],[1,1.22,0],[2,3,0]],"ltp":1.16,"tv":704.68,"id":8908205}]}]}
{"op":"mcm","clk":"1004206818","pt":1580653902739,"mc":[{"id":"1.168224029","rc":[{"batl":[[0,1.14,941.81],[1,1.15,184.45],[2,3,6.82]],"ltp":1.16,"tv":704.68,"id":8908205},{"batb":[[1,1.01,10.51],[2,1.01,0]],"ltp":4.0,"tv":124.64,"id":4596961}]}]}
{"op":"mcm","clk":"1004207134","pt":1580653904111,"mc":[{"id":"1.168224029","rc":[{"batb":[[0,8.6,8.18],[1,6.6,14.48],[2,1.01,10.51]],"ltp":4.0,"tv":124.64,"id":4596961}]}]}
{"op":"mcm","clk":"1004207272","pt":1580653904807,"mc":[{"id":"1.168224029","rc":[{"batl":[[1,1.15,226.46]],"ltp":1.16,"tv":704.68,"id":8908205},{"batl":[[0,9.4,4.2]],"ltp":4.0,"tv":124.64,"id":4596961}]}]}
{"op":"mcm","clk":"1004207722","pt":1580653907060,"mc":[{"id":"1.168224029","rc":[{"batb":[[2,3.35,371.23]],"ltp":4.0,"tv":124.64,"id":4596961}]}]}
{"op":"mcm","clk":"1004207821","pt":1580653907506,"mc":[{"id":"1.168224029","rc":[{"batb":[[1,7.6,5.88],[2,6.6,14.48]],"ltp":4.0,"tv":124.64,"id":4596961}]}]}
{"op":"mcm","clk":"1004209249","pt":1580653915046,"mc":[{"id":"1.168224029","rc":[{"batb":[[0,1.1,238.88],[1,1.07,893.98],[2,1.06,375.47]],"batl":[[0,1.15,42.01],[1,3,6.82],[2,3,0]],"ltp":1.16,"tv":704.68,"id":8908205}]}]}
{"op":"mcm","clk":"1004209426","pt":1580653915940,"mc":[{"id":"1.168224029","rc":[{"batb":[[0,1.07,893.98],[1,1.06,371.93],[2,1.01,10.51]],"batl":[[0,3,6.82],[1,3,0]],"ltp":1.16,"tv":704.68,"id":8908205},{"batb":[[0,6.6,14.48],[1,3.35,371.23],[2,1.01,10.51]],"ltp":4.0,"tv":124.64,"id":4596961}]}]}
{"op":"mcm","clk":"1004209836","pt":1580653918071,"mc":[{"id":"1.168224029","rc":[{"batb":[[0,1.07,2095.65]],"batl":[[0,1.17,305.78],[1,1.18,598.56],[2,3,6.82]],"ltp":1.16,"tv":704.68,"id":8908205}]}]}
{"op":"mcm","clk":"1004209913","pt":1580653918448,"mc":[{"id":"1.168224029","rc":[{"batb":[[0,1.07,893.98]],"batl":[[0,3,6.82],[1,1.18,0],[2,3,0]],"ltp":1.16,"tv":704.68,"id":8908205}]}]}
{"op":"mcm","clk":"1004210055","pt":1580653919149,"mc":[{"id":"1.168224029","rc":[{"batb":[[0,1.06,371.93],[1,1.01,10.51],[2,1.01,0]],"ltp":1.16,"tv":704.68,"id":8908205}]}]}
{"op":"mcm","clk":"1004210369","pt":1580653920751,"mc":[{"id":"1.168224029","rc":[{"batb":[[0,1.11,393.67],[1,1.1,771.65],[2,1.06,371.93]],"batl":[[0,1.13,942.58],[1,1.14,193.57],[2,3,6.82]],"ltp":1.16,"tv":704.68,"id":8908205}]}]}
{"op":"mcm","clk":"1004210656","pt":1580653922244,"mc":[{"id":"1.168224029","rc":[{"batb":[[0,1.06,371.93],[1,1.01,10.51],[2,1.06,0]],"batl":[[0,3,6.82],[1,1.14,0],[2,3,0]],"ltp":1.16,"tv":704.68,"id":8908205}]}]}
{"op":"mcm","clk":"1004210880","pt":1580653923271,"mc":[{"id":"1.168224029","rc":[{"batb":[[0,1.06,1327.54]],"ltp":1.16,"tv":704.68,"id":8908205}]}]}
{"op":"mcm","clk":"1004211339","pt":1580653925224,"mc":[{"id":"1.168224029","rc":[{"batb":[[0,1.07,1201.67],[1,1.06,1327.54],[2,1.01,10.51]],"batl":[[0,1.17,305.78],[1,1.18,598.56],[2,3,6.82]],"ltp":1.16,"tv":704.68,"id":8908205}]}]}
{"op":"mcm","clk":"1004214581","pt":1580653942461,"mc":[{"id":"1.168224029","rc":[{"batl":[[0,3,6.82],[1,1.18,0],[2,3,0]],"ltp":1.16,"tv":704.68,"id":8908205}]}]}
{"op":"mcm","clk":"1004215034","pt":1580653945097,"mc":[{"id":"1.168224029","rc":[{"batb":[[1,1.06,371.93]],"ltp":1.16,"tv":704.68,"id":8908205},{"batb":[[1,1.01,10.51],[2,1.01,0]],"ltp":4.0,"tv":124.64,"id":4596961}]}]}
{"op":"mcm","clk":"1004215237","pt":1580653946082,"mc":[{"id":"1.168224029","rc":[{"batb":[[2,1.03,641.18]],"batl":[[0,1.09,744.21],[1,1.1,431.46],[2,3,6.82]],"ltp":1.16,"tv":704.68,"id":8908205},{"batb":[[0,11.5,9.91],[1,9,7.32],[2,1.01,10.51]],"ltp":4.0,"tv":124.64,"id":4596961}]}]}
{"op":"mcm","clk":"1004215370","pt":1580653946788,"mc":[{"id":"1.168224029","rc":[{"batb":[[0,1.08,168.04],[1,1.07,1201.67],[2,1.06,371.93]],"ltp":1.16,"tv":704.68,"id":8908205},{"batb":[[1,10.5,4.2],[2,9,7.32]],"batl":[[0,13.5,3.36]],"ltp":4.0,"tv":124.64,"id":4596961}]}]}
{"op":"mcm","clk":"1004217283","pt":1580653957387,"mc":[{"id":"1.168224029","rc":[{"batl":[[1,1.1,350.5]],"ltp":1.16,"tv":704.68,"id":8908205}]}]}
{"op":"mcm","clk":"1004217823","pt":1580653960421,"mc":[{"id":"1.168224029","rc":[{"batl":[[0,1.09,825.9]],"ltp":1.16,"tv":704.68,"id":8908205}]}]}
{"op":"mcm","clk":"1004218048","pt":1580653961614,"mc":[{"id":"1.168224029","rc":[{"trd":[[1.09,22]],"batl":[[0,1.09,814.9]],"ltp":1.09,"tv":726.68,"id":8908205}],"tv":851.33}]}
{"op":"mcm","clk":"1004219044","pt":1580653967123,"mc":[{"id":"1.168224029","rc":[{"batb":[[0,1.07,1201.67],[1,1.06,371.93],[2,1.04,1263]],"ltp":1.09,"tv":726.68,"id":8908205}]}]}
{"op":"mcm","clk":"1004219205","pt":1580653967826,"mc":[{"id":"1.168224029","rc":[{"batb":[[0,1.04,1263],[1,1.03,634.33],[2,1.01,10.51]],"batl":[[0,3,6.82],[1,1.1,0],[2,3,0]],"ltp":1.09,"tv":726.68,"id":8908205},{"batb":[[0,9,7.32],[1,3.7,374.33],[2,1.01,10.51]],"ltp":4.0,"tv":124.64,"id":4596961}]}]}
{"op":"mcm","clk":"1004219382","pt":1580653968695,"mc":[{"id":"1.168224029","rc":[{"batb":[[0,1.03,634.33],[1,1.01,10.51],[2,1.01,0]],"ltp":1.09,"tv":726.68,"id":8908205},{"batb":[[1,1.01,10.51],[2,1.01,0]],"ltp":4.0,"tv":124.64,"id":4596961}]}]}
{"op":"mcm","clk":"1004220136","pt":1580653973007,"mc":[{"id":"1.168224029","rc":[{"batb":[[0,1.07,448.51],[1,1.06,760.27],[2,1.03,634.33]],"batl":[[0,1.08,581.34],[1,1.09,603.62],[2,3,6.82]],"ltp":1.09,"tv":726.68,"id":8908205}]}]}
{"op":"mcm","clk":"1004220456","pt":1580653974820,"mc":[{"id":"1.168224029","rc":[{"batb":[[2,1.03,2206.21]],"ltp":1.09,"tv":726.68,"id":8908205},{"batb":[[1,3.85,370.95],[2,1.01,10.51]],"ltp":4.0,"tv":124.64,"id":4596961}]}]}
{"op":"mcm","clk":"1004220664","pt":1580653975936,"mc":[{"id":"1.168224029","rc":[{"batb":[[0,1.03,2206.21],[1,1.01,10.51],[2,1.03,0]],"batl":[[0,3,6.82],[1,1.09,0],[2,3,0]],"ltp":1.09,"tv":726.68,"id":8908205}]}]}
{"op":"mcm","clk":"1004221050","pt":1580653978105,"mc":[{"id":"1.168224029","rc":[{"batb":[[0,1.03,634.33]],"ltp":1.09,"tv":726.68,"id":8908205},{"batb":[[1,1.01,10.51],[2,1.01,0]],"ltp":4.0,"tv":124.64,"id":4596961}]}]}
{"op":"mcm","clk":"1004221209","pt":1580653978918,"mc":[{"id":"1.168224029","rc":[{"batb":[[0,1.04,1236.34],[1,1.03,634.33],[2,1.01,10.51]],"batl":[[0,1.12,432.55],[1,1.13,709.15],[2,3,6.82]],"ltp":1.09,"tv":726.68,"id":8908205}]}]}
{"op":"mcm","clk":"1004222854","pt":1580653987109,"mc":[{"id":"1.168224029","rc":[{"batl":[[0,3,6.82],[1,1.13,0],[2,3,0]],"ltp":1.09,"tv":726.68,"id":8908205}]}]}
{"op":"mcm","clk":"1004223389","pt":1580653989873,"mc":[{"id":"1.168224029","rc":[{"batl":[[0,1.05,859.8],[1,1.06,361.32],[2,3,6.82]],"ltp":1.09,"tv":726.68,"id":8908205}]}]}
{"op":"mcm","clk":"1004223597","pt":1580653990850,"mc":[{"id":"1.168224029","rc":[{"batb":[[2,1.02,972.43]],"ltp":1.09,"tv":726.68,"id":8908205},{"batb":[[0,17.5,4.09],[1,13.5,7.08],[2,1.01,10.51]],"ltp":4.0,"tv":124.64,"id":4596961}]}]}
{"op":"mcm","clk":"1004223839","pt":1580653992054,"mc":[{"id":"1.168224029","rc":[{"batl":[[1,1.06,403.33]],"ltp":1.09,"tv":726.68,"id":8908205},{"batb":[[2,4.1,374.13]],"ltp":4.0,"tv":124.64,"id":4596961}]}]}
{"op":"mcm","clk":"1004224260","pt":1580653994067,"mc":[{"id":"1.168224029","rc":[{"batb":[[0,1.04,1404.38]],"ltp":1.09,"tv":726.68,"id":8908205}]}]}
{"op":"mcm","clk":"1004226590","pt":1580654005987,"mc":[{"id":"1.168224029","rc":[{"batb":[[0,1.04,168.04],[1,1.02,972.43],[2,1.01,4076.97]],"batl":[[0,1.06,42.01],[1,3,6.82],[2,3,0]],"ltp":1.09,"tv":726.68,"id":8908205},{"batb":[[0,13.5,7.08],[1,4.1,374.13],[2,1.01,10.51]],"ltp":4.0,"tv":124.64,"id":4596961}]}]}
{"op":"mcm","clk":"1004226631","pt":1580654006198,"mc":[{"id":"1.168224029","rc":[{"batb":[[0,13.5,6.92]],"ltp":4.0,"tv":124.64,"id":4596961}]}]}
{"op":"mcm","clk":"1004226997","pt":1580654008039,"mc":[{"id":"1.168224029","rc":[{"batb":[[0,1.02,972.43],[1,1.01,10.51],[2,1.01,0]],"batl":[[0,3,6.82],[1,3,0]],"ltp":1.09,"tv":726.68,"id":8908205},{"batb":[[1,1.01,10.51],[2,1.01,0]],"ltp":4.0,"tv":124.64,"id":4596961}]}]}
{"op":"mcm","clk":"1004227096","pt":1580654008638,"mc":[{"id":"1.168224029","rc":[{"batb":[[0,1.02,2233.01]],"batl":[[0,1.07,989.93],[1,1.08,209.78],[2,3,6.82]],"ltp":1.09,"tv":726.68,"id":8908205}]}]}
{"op":"mcm","clk":"1004227784","pt":1580654012070,"mc":[{"id":"1.168224029","rc":[{"batl":[[0,3,6.82],[1,1.08,0],[2,3,0]],"ltp":1.09,"tv":726.68,"id":8908205}]}]}
{"op":"mcm","clk":"1004228399","pt":1580654014968,"mc":[{"id":"1.168224029","rc":[{"batl":[[0,1.03,1248.34],[1,3,6.82]],"ltp":1.09,"tv":726.68,"id":8908205},{"batb":[[0,23,3.34],[1,17,4.33],[2,13.5,6.92]],"ltp":4.0,"tv":124.64,"id":4596961}]}]}
{"op":"mcm","clk":"1004228612","pt":1580654016043,"mc":[{"id":"1.168224029","rc":[{"batb":[[2,1.01,10.51]],"ltp":4.0,"tv":124.64,"id":4596961}]}]}
{"op":"mcm","clk":"1004228765","pt":1580654016788,"mc":[{"id":"1.168224029","rc":[{"batl":[[0,1.03,1290.35]],"ltp":1.09,"tv":726.68,"id":8908205},{"batb":[[2,4.4,369.4]],"batl":[[0,520,35.52]],"ltp":4.0,"tv":124.64,"id":4596961}]}]}
{"op":"mcm","clk":"1004230931","pt":1580654027600,"mc":[{"id":"1.168224029","rc":[{"batb":[[0,1.02,2240.88]],"ltp":1.09,"tv":726.68,"id":8908205}]}]}
{"op":"mcm","clk":"1004232853","pt":1580654036528,"mc":[{"id":"1.168224029","rc":[{"batb":[[1,1.01,18.37]],"ltp":1.09,"tv":726.68,"id":8908205}]}]}
{"op":"mcm","clk":"1004237981","pt":1580654061070,"mc":[{"id":"1.168224029","rc":[{"trd":[[1.02,20.17]],"batb":[[0,1.02,2230.79]],"ltp":1.02,"tv":746.85,"id":8908205}],"tv":871.5}]}
{"op":"mcm","clk":"1004245647","pt":1580654098099,"mc":[{"id":"1.168224029","rc":[{"trd":[[1.02,23.53]],"batb":[[0,1.02,7.87]],"batl":[[0,1.03,42.01]],"ltp":1.02,"tv":750.21,"id":8908205},{"batb":[[0,17,4.33],[1,4.4,369.4],[2,1.01,10.51]],"ltp":4.0,"tv":124.64,"id":4596961}],"tv":874.86}]}
{"op":"mcm","clk":"1004245973","pt":1580654099614,"mc":[{"id":"1.168224029","rc":[{"batl":[[0,3,6.82],[1,3,0]],"ltp":1.02,"tv":750.21,"id":8908205}]}]}
{"op":"mcm","clk":"1004246275","pt":1580654101104,"mc":[{"id":"1.168224029","rc":[{"batb":[[1,1.01,1291.43]],"batl":[[0,1.05,1224.57],[1,3,6.82]],"ltp":1.02,"tv":750.21,"id":8908205}]}]}
{"op":"mcm","clk":"1004247431","pt":1580654106548,"mc":[{"id":"1.168224029","rc":[{"batl":[[0,3,6.82],[1,3,0]],"ltp":1.02,"tv":750.21,"id":8908205}]}]}
{"op":"mcm","clk":"1004248096","pt":1580654109583,"mc":[{"id":"1.168224029","rc":[{"trd":[[1.02,39.26]],"batb":[[0,1.01,1291.43],[1,1.01,0]],"batl":[[0,1.02,1252.71],[1,3,6.82]],"ltp":1.02,"tv":765.95,"id":8908205}],"tv":890.6}]}
{"op":"mcm","clk":"1004248340","pt":1580654110800,"mc":[{"id":"1.168224029","rc":[{"batb":[[0,1.01,1459.47]],"ltp":1.02,"tv":765.95,"id":8908205},{"batb":[[0,23,3.48]],"ltp":4.0,"tv":124.64,"id":4596961}]}]}
{"op":"mcm","clk":"1004248824","pt":1580654112978,"mc":[{"id":"1.168224029","rc":[{"batl":[[0,1.02,1294.72]],"ltp":1.02,"tv":765.95,"id":8908205}]}]}
{"op":"mcm","clk":"1004250741","pt":1580654121995,"mc":[{"id":"1.168224029","rc":[{"batb":[[0,1.01,186.41]],"batl":[[0,1.02,42.01]],"ltp":1.02,"tv":765.95,"id":8908205}]}]}
{"op":"mcm","clk":"1004251119","pt":1580654123911,"mc":[{"id":"1.168224029","rc":[{"batb":[[0,1.01,18.37]],"batl":[[0,3,6.82],[1,3,0]],"ltp":1.02,"tv":765.95,"id":8908205},{"batb":[[1,1.01,10.51],[2,1.01,0]],"ltp":4.0,"tv":124.64,"id":4596961}]}]}
{"op":"mcm","clk":"1004251345","pt":1580654124918,"mc":[{"id":"1.168224029","rc":[{"batl":[[0,1.03,779.59],[1,1.04,464.25],[2,3,6.82]],"ltp":1.02,"tv":765.95,"id":8908205}]}]}
{"op":"mcm","clk":"1004251775","pt":1580654127001,"mc":[{"id":"1.168224029","rc":[{"batl":[[0,3,6.82],[1,1.04,0],[2,3,0]],"ltp":1.02,"tv":765.95,"id":8908205}]}]}
{"op":"mcm","clk":"1004251908","pt":1580654127701,"mc":[{"id":"1.168224029","rc":[{"batb":[[0,1.01,10.51],[1,1.01,0]],"ltp":4.0,"tv":124.64,"id":4596961}]}]}
{"op":"mcm","clk":"1004252356","pt":1580654129912,"mc":[{"id":"1.168224029","rc":[{"trd":[[1.01,36.75]],"batl":[[0,1.01,1254.68],[1,3,6.82]],"ltp":1.01,"tv":802.7,"id":8908205}],"tv":927.35}]}
{"op":"mcm","clk":"1004252769","pt":1580654131936,"mc":[{"id":"1.168224029","rc":[{"batb":[[0,4.7,374.21],[1,1.01,10.51]],"ltp":4.0,"tv":124.64,"id":4596961}]}]}
{"op":"mcm","clk":"1004253184","pt":1580654133741,"mc":[{"id":"1.168224029","rc":[{"batl":[[0,1.01,1316.69]],"ltp":1.01,"tv":802.7,"id":8908205}]}]}
{"op":"mcm","clk":"1004254216","pt":1580654138436,"mc":[{"id":"1.168224029","rc":[{"batl":[[1,1.04,1680.39],[2,3,6.82]],"ltp":1.01,"tv":802.7,"id":8908205}]}]}
{"op":"mcm","clk":"1004254918","pt":1580654141916,"mc":[{"id":"1.168224029","rc":[{"batl":[[0,1.01,20]],"ltp":1.01,"tv":802.7,"id":8908205}]}]}
{"op":"mcm","clk":"1004255242","pt":1580654143542,"mc":[{"id":"1.168224029","rc":[{"batb":[[0,1.01,10.51],[1,1.01,0]],"ltp":4.0,"tv":124.64,"id":4596961}]}]}
{"op":"mcm","clk":"1004255552","pt":1580654144925,"mc":[{"id":"1.168224029","rc":[{"batl":[[1,1.02,1260.58],[2,1.04,1680.39]],"ltp":1.01,"tv":802.7,"id":8908205}]}]}
{"op":"mcm","clk":"1004256935","pt":1580654151953,"mc":[{"id":"1.168224029","rc":[{"batl":[[1,1.04,1680.39],[2,3,6.82]],"ltp":1.01,"tv":802.7,"id":8908205}]}]}
{"op":"mcm","clk":"1004257567","pt":1580654155022,"mc":[{"id":"1.168224029","rc":[{"batl":[[0,1.01,1293.06]],"ltp":1.01,"tv":802.7,"id":8908205}]}]}
{"op":"mcm","clk":"1004258127","pt":1580654157967,"mc":[{"id":"1.168224029","rc":[{"batb":[[0,4.8,370.06],[1,1.01,10.51]],"ltp":4.0,"tv":124.64,"id":4596961}]}]}
{"op":"mcm","clk":"1004258344","pt":1580654159027,"mc":[{"id":"1.168224029","rc":[{"batl":[[0,1.01,2079.88]],"ltp":1.01,"tv":802.7,"id":8908205}]}]}
{"op":"mcm","clk":"1004259551","pt":1580654164322,"mc":[{"id":"1.168224029","rc":[{"batb":[[0,1.01,10.51],[1,1.01,0]],"ltp":4.0,"tv":124.64,"id":4596961}]}]}
{"op":"mcm","clk":"1004261954","pt":1580654175968,"mc":[{"id":"1.168224029","rc":[{"batl":[[0,1.01,806.82]],"ltp":1.01,"tv":802.7,"id":8908205}]}]}
{"op":"mcm","clk":"1004262154","pt":1580654176879,"mc":[{"id":"1.168224029","marketDefinition":{"bspMarket":false,"turnInPlayEnabled":true,"persistenceEnabled":true,"marketBaseRate":5.0,"eventId":"29681672","eventTypeId":"2","numberOfWinners":1,"bettingType":"ODDS","marketType":"SET_WINNER","marketTime":"2020-02-02T14:00:00.000Z","suspendTime":"2020-02-02T14:00:00.000Z","bspReconciled":false,"complete":true,"inPlay":true,"crossMatching":true,"runnersVoidable":false,"numberOfActiveRunners":2,"betDelay":3,"status":"SUSPENDED","runners":[{"status":"ACTIVE","sortPriority":1,"id":8908205,"name":"Juan Pablo Ficovich"},{"status":"ACTIVE","sortPriority":2,"id":4596961,"name":"Filip Horansky"}],"regulators":["MR_INT"],"countryCode":"AR","discountAllowed":true,"timezone":"UTC","openDate":"2020-02-02T14:00:00.000Z","version":3149237241,"name":"Set 1 Winner","eventName":"Ficovich v Horansky"}}]}
{"op":"mcm","clk":"1004262916","pt":1580654180557,"mc":[{"id":"1.168224029","rc":[{"batl":[[1,3,6.82],[2,3,0]],"ltp":1.01,"tv":802.7,"id":8908205}]}]}
{"op":"mcm","clk":"1004264470","pt":1580654188066,"mc":[{"id":"1.168224029","rc":[{"batl":[[0,1.01,20]],"ltp":1.01,"tv":802.7,"id":8908205}]}]}
{"op":"mcm","clk":"1004269059","pt":1580654210427,"mc":[{"id":"1.168224029","tv":0.0}]}
{"op":"mcm","clk":"1004269416","pt":1580654212108,"mc":[{"id":"1.168224029","marketDefinition":{"bspMarket":false,"turnInPlayEnabled":true,"persistenceEnabled":true,"marketBaseRate":5.0,"eventId":"29681672","eventTypeId":"2","numberOfWinners":1,"bettingType":"ODDS","marketType":"SET_WINNER","marketTime":"2020-02-02T14:00:00.000Z","suspendTime":"2020-02-02T14:00:00.000Z","bspReconciled":false,"complete":true,"inPlay":true,"crossMatching":false,"runnersVoidable":false,"numberOfActiveRunners":0,"betDelay":3,"status":"CLOSED","settledTime":"2020-02-02T14:36:48.000Z","runners":[{"status":"WINNER","sortPriority":1,"id":8908205,"name":"Juan Pablo Ficovich"},{"status":"LOSER","sortPriority":2,"id":4596961,"name":"Filip Horansky"}],"regulators":["MR_INT"],"countryCode":"AR","discountAllowed":true,"timezone":"UTC","openDate":"2020-02-02T14:00:00.000Z","version":3149238326,"name":"Set 1 Winner","eventName":"Ficovich v Horansky"}}]}
