{"op":"mcm","clk":"997862772","pt":1580583479664,"mc":[{"id":"1.168224027","marketDefinition":{"bspMarket":false,"turnInPlayEnabled":true,"persistenceEnabled":true,"marketBaseRate":5.0,"eventId":"29681672","eventTypeId":"2","numberOfWinners":1,"bettingType":"ODDS","marketType":"MATCH_ODDS","marketTime":"2020-02-02T13:00:00.000Z","suspendTime":"2020-02-02T13:00:00.000Z","bspReconciled":false,"complete":true,"inPlay":false,"crossMatching":false,"runnersVoidable":false,"numberOfActiveRunners":2,"betDelay":0,"status":"OPEN","runners":[{"status":"ACTIVE","sortPriority":1,"id":8908205,"name":"Juan Pablo Ficovich"},{"status":"ACTIVE","sortPriority":2,"id":4596961,"name":"Filip Horansky"}],"regulators":["MR_INT"],"countryCode":"AR","discountAllowed":false,"timezone":"UTC","openDate":"2020-02-02T13:00:00.000Z","version":3146950730,"name":"Match Odds","eventName":"Ficovich v Horansky"},"rc":[{"batb":[[0,1.02,3786.16],[1,1.01,4132.68]],"ltp":0.0,"tv":0.0,"id":8908205},{"batb":[[0,1.05,152.2],[1,1.04,168.86],[2,1.03,237.77]],"ltp":0.0,"tv":0.0,"id":4596961}]}]}
{"op":"mcm","clk":"997863080","pt":1580583482122,"mc":[{"id":"1.168224027","marketDefinition":{"bspMarket":false,"turnInPlayEnabled":true,"persistenceEnabled":true,"marketBaseRate":5.0,"eventId":"29681672","eventTypeId":"2","numberOfWinners":1,"bettingType":"ODDS","marketType":"MATCH_ODDS","marketTime":"2020-02-02T13:00:00.000Z","suspendTime":"2020-02-02T13:00:00.000Z","bspReconciled":false,"complete":true,"inPlay":false,"crossMatching":false,"runnersVoidable":false,"numberOfActiveRunners":2,"betDelay":0,"status":"OPEN","runners":[{"status":"ACTIVE","sortPriority":1,"id":8908205,"name":"Juan Pablo Ficovich"},{"status":"ACTIVE","sortPriority":2,"id":4596961,"name":"Filip Horansky"}],"regulators":["MR_INT"],"countryCode":"AR","discountAllowed":true,"timezone":"UTC","openDate":"2020-02-02T13:00:00.000Z","version":3146950730,"name":"Match Odds","eventName":"Ficovich v Horansky"}}]}
{"op":"mcm","clk":"997865597","pt":1580583503820,"mc":[{"id":"1.168224027","rc":[{"batb":[[1,1.01,4432.68]],"ltp":0.0,"tv":0.0,"id":8908205}]}]}
{"op":"mcm","clk":"997866120","pt":1580583507510,"mc":[{"id":"1.168224027","rc":[{"batb":[[1,1.01,4132.68]],"ltp":0.0,"tv":0.0,"id":8908205}]}]}
{"op":"mcm","clk":"997866441","pt":1580583510234,"mc":[{"id":"1.168224027","marketDefinition":{"bspMarket":false,"turnInPlayEnabled":true,"persistenceEnabled":true,"marketBaseRate":5.0,"eventId":"29681672","eventTypeId":"2","numberOfWinners":1,"bettingType":"ODDS","marketType":"MATCH_ODDS","marketTime":"2020-02-02T13:00:00.000Z","suspendTime":"2020-02-02T13:00:00.000Z","bspReconciled":false,"complete":true,"inPlay":false,"crossMatching":true,"runnersVoidable":false,"numberOfActiveRunners":2,"betDelay":0,"status":"OPEN","runners":[{"status":"ACTIVE","sortPriority":1,"id":8908205,"name":"Juan Pablo Ficovich"},{"status":"ACTIVE","sortPriority":2,"id":4596961,"name":"Filip Horansky"}],"regulators":["MR_INT"],"countryCode":"AR","discountAllowed":true,"timezone":"UTC","openDate":"2020-02-02T13:00:00.000Z","version":3146950730,"name":"Match Odds","eventName":"Ficovich v Horansky"}}]}
{"op":"mcm","clk":"997881355","pt":1580583623088,"mc":[{"id":"1.168224027","rc":[{"batb":[[1,1.01,4112.68]],"ltp":0.0,"tv":0.0,"id":8908205}]}]}
{"op":"mcm","clk":"997885925","pt":1580583660463,"mc":[{"id":"1.168224027","rc":[{"batb":[[0,1.13,75.72],[1,1.02,3786.16],[2,1.01,4112.68]],"ltp":0.0,"tv":0.0,"id":8908205}]}]}
{"op":"mcm","clk":"997947647","pt":1580584057429,"mc":[{"id":"1.168224027","rc":[{"batb":[[0,1.06,50.48],[1,1.05,152.2],[2,1.04,168.86]],"ltp":0.0,"tv":0.0,"id":4596961}]}]}
{"op":"mcm","clk":"997996284","pt":1580584351066,"mc":[{"id":"1.168224027","rc":[{"batl":[[0,990,2.2]],"ltp":0.0,"tv":0.0,"id":8908205},{"batl":[[0,990,2.2]],"ltp":0.0,"tv":0.0,"id":4596961}]}]}
{"op":"mcm","clk":"998182961","pt":1580585441119,"mc":[{"id":"1.168224027","rc":[{"batb":[[1,1.02,3811.36]],"ltp":0.0,"tv":0.0,"id":8908205}]}]}
{"op":"mcm","clk":"998183063","pt":1580585441712,"mc":[{"id":"1.168224027","rc":[{"batb":[[1,1.03,8.4],[2,1.02,3811.36]],"ltp":0.0,"tv":0.0,"id":8908205}]}]}
{"op":"mcm","clk":"998232682","pt":1580585712167,"mc":[{"id":"1.168224027","rc":[{"batl":[[0,48,31.05],[1,990,2.2]],"ltp":0.0,"tv":0.0,"id":8908205},{"batl":[[0,48,31.05],[1,990,2.2]],"ltp":0.0,"tv":0.0,"id":4596961}]}]}
{"op":"mcm","clk":"998808371","pt":1580589668767,"mc":[{"id":"1.168224027","rc":[{"batb":[[2,1.02,25.21]],"ltp":0.0,"tv":0.0,"id":8908205}]}]}
{"op":"mcm","clk":"998890757","pt":1580590302846,"mc":[{"id":"1.168224027","marketDefinition":{"bspMarket":false,"turnInPlayEnabled":true,"persistenceEnabled":true,"marketBaseRate":5.0,"eventId":"29681672","eventTypeId":"2","numberOfWinners":1,"bettingType":"ODDS","marketType":"MATCH_ODDS","marketTime":"2020-02-02T14:00:00.000Z","suspendTime":"2020-02-02T14:00:00.000Z","bspReconciled":false,"complete":true,"inPlay":false,"crossMatching":true,"runnersVoidable":false,"numberOfActiveRunners":2,"betDelay":0,"status":"OPEN","runners":[{"status":"ACTIVE","sortPriority":1,"id":8908205,"name":"Juan Pablo Ficovich"},{"status":"ACTIVE","sortPriority":2,"id":4596961,"name":"Filip Horansky"}],"regulators":["MR_INT"],"countryCode":"AR","discountAllowed":true,"timezone":"UTC","openDate":"2020-02-02T13:00:00.000Z","version":3147422055,"name":"Match Odds","eventName":"Ficovich v Horansky"}}]}
{"op":"mcm","clk":"998891049","pt":1580590304855,"mc":[{"id":"1.168224027","marketDefinition":{"bspMarket":false,"turnInPlayEnabled":true,"persistenceEnabled":true,"marketBaseRate":5.0,"eventId":"29681672","eventTypeId":"2","numberOfWinners":1,"bettingType":"ODDS","marketType":"MATCH_ODDS","marketTime":"2020-02-02T14:00:00.000Z","suspendTime":"2020-02-02T14:00:00.000Z","bspReconciled":false,"complete":true,"inPlay":false,"crossMatching":true,"runnersVoidable":false,"numberOfActiveRunners":2,"betDelay":0,"status":"OPEN","runners":[{"status":"ACTIVE","sortPriority":1,"id":8908205,"name":"Juan Pablo Ficovich"},{"status":"ACTIVE","sortPriority":2,"id":4596961,"name":"Filip Horansky"}],"regulators":["MR_INT"],"countryCode":"AR","discountAllowed":true,"timezone":"UTC","openDate":"2020-02-02T14:00:00.000Z","version":3147422055,"name":"Match Odds","eventName":"Ficovich v Horansky"}}]}
{"op":"mcm","clk":"998960891","pt":1580590918103,"mc":[{"id":"1.168224027","rc":[{"batb":[[0,1.14,15.12],[1,1.13,75.72],[2,1.03,8.4]],"batl":[[0,12,3.36],[1,48,31.05],[2,990,2.2]],"ltp":0.0,"tv":0.0,"id":8908205},{"batb":[[0,1.07,15.12],[1,1.06,50.48],[2,1.05,152.2]],"batl":[[0,13,3.36],[1,48,31.05],[2,990,2.2]],"ltp":0.0,"tv":0.0,"id":4596961}]}]}
{"op":"mcm","clk":"999322768","pt":1580594041349,"mc":[{"id":"1.168224027","rc":[{"batb":[[0,1.56,43.83],[1,1.14,15.12],[2,1.13,75.72]],"batl":[[0,2.4,25.54],[1,12,3.36],[2,48,31.05]],"ltp":0.0,"tv":0.0,"id":8908205}]}]}
{"op":"mcm","clk":"999326740","pt":1580594080974,"mc":[{"id":"1.168224027","rc":[{"batl":[[1,48,31.05],[2,990,2.2]],"ltp":0.0,"tv":0.0,"id":8908205}]}]}
{"op":"mcm","clk":"999326758","pt":1580594081180,"mc":[{"id":"1.168224027","rc":[{"batb":[[1,1.13,75.72],[2,1.03,8.4]],"ltp":0.0,"tv":0.0,"id":8908205}]}]}
{"op":"mcm","clk":"999331072","pt":1580594126065,"mc":[{"id":"1.168224027","rc":[{"batb":[[0,1.57,11.76],[1,1.56,43.83],[2,1.13,75.72]],"ltp":0.0,"tv":0.0,"id":8908205}]}]}
{"op":"mcm","clk":"999331106","pt":1580594126374,"mc":[{"id":"1.168224027","rc":[{"batb":[[0,1.7,36.42],[1,1.57,11.76]],"ltp":0.0,"tv":0.0,"id":8908205}]}]}
{"op":"mcm","clk":"999335679","pt":1580594171635,"mc":[{"id":"1.168224027","rc":[{"batb":[[1,1.13,75.72],[2,1.03,8.4]],"ltp":0.0,"tv":0.0,"id":8908205}]}]}
{"op":"mcm","clk":"999361933","pt":1580594417020,"mc":[{"id":"1.168224027","rc":[{"batb":[[0,1.88,32.96],[1,1.86,48.46],[2,1.13,75.72]],"ltp":0.0,"tv":0.0,"id":8908205},{"batb":[[0,1.67,35.59],[1,1.07,15.12],[2,1.06,50.48]],"ltp":0.0,"tv":0.0,"id":4596961}]}]}
{"op":"mcm","clk":"999363975","pt":1580594439611,"mc":[{"id":"1.168224027","rc":[{"batb":[[1,1.06,50.48],[2,1.05,152.2]],"ltp":0.0,"tv":0.0,"id":4596961}]}]}
{"op":"mcm","clk":"999366634","pt":1580594469599,"mc":[{"id":"1.168224027","rc":[{"batb":[[0,1.95,31.71],[1,1.92,48.46]],"batl":[[0,48,31.05],[1,990,2.2],[2,990,0]],"ltp":0.0,"tv":0.0,"id":8908205},{"batb":[[0,1.74,39.79],[1,1.72,35.59],[2,1.06,50.48]],"ltp":0.0,"tv":0.0,"id":4596961}]}]}
{"op":"mcm","clk":"999367828","pt":1580594482448,"mc":[{"id":"1.168224027","rc":[{"batl":[[0,12,3.36],[1,48,31.05],[2,990,2.2]],"ltp":0.0,"tv":0.0,"id":8908205}]}]}
{"op":"mcm","clk":"999385170","pt":1580594704485,"mc":[{"id":"1.168224027","rc":[{"batb":[[0,2.04,73.35]],"ltp":0.0,"tv":0.0,"id":8908205},{"batb":[[0,1.8,86.69]],"ltp":0.0,"tv":0.0,"id":4596961}]}]}
{"op":"mcm","clk":"999405434","pt":1580594938121,"mc":[{"id":"1.168224027","rc":[{"batb":[[2,1.31,37.86]],"ltp":0.0,"tv":0.0,"id":8908205},{"batb":[[2,1.21,37.86]],"ltp":0.0,"tv":0.0,"id":4596961}]}]}
{"op":"mcm","clk":"999405504","pt":1580594939003,"mc":[{"id":"1.168224027","rc":[{"batb":[[2,1.71,37.86]],"ltp":0.0,"tv":0.0,"id":8908205},{"batb":[[2,1.51,37.86]],"ltp":0.0,"tv":0.0,"id":4596961}]}]}
{"op":"mcm","clk":"999405546","pt":1580594939418,"mc":[{"id":"1.168224027","rc":[{"batb":[[2,1.81,37.86]],"ltp":0.0,"tv":0.0,"id":8908205},{"batb":[[2,1.61,37.86]],"ltp":0.0,"tv":0.0,"id":4596961}]}]}
{"op":"mcm","clk":"999434044","pt":1580595260693,"mc":[{"id":"1.168224027","rc":[{"batb":[[0,1.8,124.07]],"ltp":0.0,"tv":0.0,"id":4596961}]}]}
{"op":"mcm","clk":"999434148","pt":1580595262112,"mc":[{"id":"1.168224027","rc":[{"batb":[[1,1.81,37.86],[2,1.71,37.86]],"ltp":0.0,"tv":0.0,"id":8908205}]}]}
{"op":"mcm","clk":"999434235","pt":1580595263111,"mc":[{"id":"1.168224027","rc":[{"batb":[[1,1.77,35.59]],"ltp":0.0,"tv":0.0,"id":4596961}]}]}
{"op":"mcm","clk":"999434838","pt":1580595270546,"mc":[{"id":"1.168224027","rc":[{"batb":[[1,1.88,48.46],[2,1.81,37.86]],"ltp":0.0,"tv":0.0,"id":8908205},{"batb":[[1,1.75,35.59]],"ltp":0.0,"tv":0.0,"id":4596961}]}]}
{"op":"mcm","clk":"999436333","pt":1580595288552,"mc":[{"id":"1.168224027","rc":[{"batb":[[1,1.87,48.46]],"ltp":0.0,"tv":0.0,"id":8908205}]}]}
{"op":"mcm","clk":"999449740","pt":1580595464425,"mc":[{"id":"1.168224027","rc":[{"batb":[[1,1.75,51.49]],"ltp":0.0,"tv":0.0,"id":4596961}]}]}
{"op":"mcm","clk":"999602796","pt":1580597646298,"mc":[{"id":"1.168224027","rc":[{"batb":[[0,1.8,142.37]],"ltp":0.0,"tv":0.0,"id":4596961}]}]}
{"op":"mcm","clk":"999611318","pt":1580597791569,"mc":[{"id":"1.168224027","rc":[{"batb":[[1,1.81,37.86],[2,1.71,37.86]],"ltp":0.0,"tv":0.0,"id":8908205},{"batb":[[1,1.61,37.86],[2,1.51,37.86]],"ltp":0.0,"tv":0.0,"id":4596961}]}]}
{"op":"mcm","clk":"999612631","pt":1580597808782,"mc":[{"id":"1.168224027","rc":[{"batb":[[1,1.87,48.46],[2,1.81,37.86]],"ltp":0.0,"tv":0.0,"id":8908205},{"batb":[[1,1.75,51.49],[2,1.61,37.86]],"ltp":0.0,"tv":0.0,"id":4596961}]}]}
{"op":"mcm","clk":"999616310","pt":1580597867464,"mc":[{"id":"1.168224027","rc":[{"batb":[[2,1.7,41.11]],"ltp":0.0,"tv":0.0,"id":4596961}]}]}
{"op":"mcm","clk":"999635135","pt":1580598170108,"mc":[{"id":"1.168224027","rc":[{"trd":[[2.04,146.7]],"batb":[[0,1.87,48.46],[1,1.81,37.86],[2,1.8,35.97]],"batl":[[0,2.04,19.85],[1,12,3.36],[2,48,31.05]],"ltp":2.04,"tv":146.69,"id":8908205},{"batb":[[0,1.8,86.69]],"ltp":0.0,"tv":0.0,"id":4596961}],"tv":146.69}]}
{"op":"mcm","clk":"999635210","pt":1580598171094,"mc":[{"id":"1.168224027","rc":[{"batb":[[0,1.95,78.01],[1,1.87,48.46],[2,1.81,37.86]],"batl":[[0,12,3.36],[1,48,31.05],[2,990,2.2]],"ltp":2.04,"tv":146.69,"id":8908205},{"batb":[[0,1.87,87.94],[2,1.71,37.86]],"ltp":0.0,"tv":0.0,"id":4596961}]}]}
{"op":"mcm","clk":"999635262","pt":1580598171617,"mc":[{"id":"1.168224027","rc":[{"batb":[[1,1.83,34.67],[2,1.75,51.49]],"ltp":0.0,"tv":0.0,"id":4596961}]}]}
{"op":"mcm","clk":"999635409","pt":1580598173997,"mc":[{"id":"1.168224027","rc":[{"batb":[[1,1.81,37.86],[2,1.71,37.86]],"ltp":2.04,"tv":146.69,"id":8908205},{"batb":[[1,1.85,51.49],[2,1.83,34.67]],"ltp":0.0,"tv":0.0,"id":4596961}]}]}
{"op":"mcm","clk":"999635949","pt":1580598179389,"mc":[{"id":"1.168224027","rc":[{"batb":[[2,1.74,52.25]],"ltp":2.04,"tv":146.69,"id":8908205},{"batb":[[1,1.83,86.16],[2,1.71,37.86]],"ltp":0.0,"tv":0.0,"id":4596961}]}]}
{"op":"mcm","clk":"999636885","pt":1580598190846,"mc":[{"id":"1.168224027","rc":[{"batb":[[0,1.93,47.79],[1,1.87,87.94],[2,1.83,86.16]],"ltp":0.0,"tv":0.0,"id":4596961}]}]}
{"op":"mcm","clk":"999644964","pt":1580598297402,"mc":[{"id":"1.168224027","rc":[{"batb":[[0,1.91,82.21]],"ltp":2.04,"tv":146.69,"id":8908205},{"batb":[[0,1.94,53.02],[1,1.83,86.16],[2,1.81,37.86]],"ltp":0.0,"tv":0.0,"id":4596961}]}]}
{"op":"mcm","clk":"999645071","pt":1580598298707,"mc":[{"id":"1.168224027","rc":[{"batb":[[1,1.83,34.67]],"ltp":0.0,"tv":0.0,"id":4596961}]}]}
{"op":"mcm","clk":"999645155","pt":1580598299912,"mc":[{"id":"1.168224027","rc":[{"batb":[[2,1.78,52.25]],"ltp":2.04,"tv":146.69,"id":8908205},{"batb":[[1,1.81,37.86],[2,1.8,35.97]],"ltp":0.0,"tv":0.0,"id":4596961}]}]}
{"op":"mcm","clk":"999645696","pt":1580598306588,"mc":[{"id":"1.168224027","rc":[{"batb":[[2,1.76,52.25]],"ltp":2.04,"tv":146.69,"id":8908205},{"batb":[[1,1.83,49.98],[2,1.81,37.86]],"ltp":0.0,"tv":0.0,"id":4596961}]}]}
{"op":"mcm","clk":"999646372","pt":1580598316019,"mc":[{"id":"1.168224027","rc":[{"batb":[[1,1.81,37.86],[2,1.8,35.97]],"ltp":0.0,"tv":0.0,"id":4596961}]}]}
{"op":"mcm","clk":"999646388","pt":1580598316127,"mc":[{"id":"1.168224027","rc":[{"batb":[[1,1.87,49.98],[2,1.81,37.86]],"ltp":0.0,"tv":0.0,"id":4596961}]}]}
{"op":"mcm","clk":"999647084","pt":1580598326340,"mc":[{"id":"1.168224027","rc":[{"batb":[[0,1.91,81.87]],"ltp":0.0,"tv":0.0,"id":4596961}]}]}
{"op":"mcm","clk":"999844573","pt":1580601308181,"mc":[{"id":"1.168224027","rc":[{"batb":[[0,1.92,48.94],[1,1.91,81.87],[2,1.87,49.98]],"ltp":0.0,"tv":0.0,"id":4596961}]}]}
{"op":"mcm","clk":"999849746","pt":1580601410657,"mc":[{"id":"1.168224027","rc":[{"batb":[[0,1.93,62.46],[1,1.87,49.98],[2,1.81,37.86]],"ltp":0.0,"tv":0.0,"id":4596961}]}]}
{"op":"mcm","clk":"999856113","pt":1580601536998,"mc":[{"id":"1.168224027","rc":[{"batb":[[0,1.91,81.87],[1,1.88,66.71],[2,1.87,49.98]],"ltp":0.0,"tv":0.0,"id":4596961}]}]}
{"op":"mcm","clk":"999856127","pt":1580601537301,"mc":[{"id":"1.168224027","rc":[{"batb":[[0,1.92,65.19],[1,1.91,81.87]],"ltp":0.0,"tv":0.0,"id":4596961}]}]}
{"op":"mcm","clk":"999862021","pt":1580601668119,"mc":[{"id":"1.168224027","rc":[{"batb":[[0,1.93,62.46],[1,1.87,49.98],[2,1.81,37.86]],"ltp":0.0,"tv":0.0,"id":4596961}]}]}
{"op":"mcm","clk":"999864501","pt":1580601729001,"mc":[{"id":"1.168224027","rc":[{"batb":[[1,1.81,90.11],[2,1.74,51.17]],"ltp":2.04,"tv":146.69,"id":8908205},{"batb":[[1,1.81,37.86],[2,1.76,49.82]],"ltp":0.0,"tv":0.0,"id":4596961}]}]}
{"op":"mcm","clk":"999864875","pt":1580601737022,"mc":[{"id":"1.168224027","rc":[{"batb":[[1,1.81,37.86],[2,1.79,52.25]],"ltp":2.04,"tv":146.69,"id":8908205},{"batb":[[1,1.83,49.98],[2,1.81,37.86]],"ltp":0.0,"tv":0.0,"id":4596961}]}]}
{"op":"mcm","clk":"999867350","pt":1580601797702,"mc":[{"id":"1.168224027","rc":[{"batb":[[0,1.91,81.87]],"ltp":0.0,"tv":0.0,"id":4596961}]}]}
{"op":"mcm","clk":"1000122081","pt":1580607501728,"mc":[{"id":"1.168224027","rc":[{"batb":[[0,1.92,6.47],[1,1.91,82.21],[2,1.81,37.86]],"ltp":2.04,"tv":146.69,"id":8908205}]}]}
{"op":"mcm","clk":"1000122104","pt":1580607502347,"mc":[{"id":"1.168224027","rc":[{"batb":[[0,1.92,6.78],[1,1.91,81.87],[2,1.83,49.98]],"ltp":0.0,"tv":0.0,"id":4596961}]}]}
{"op":"mcm","clk":"1000122725","pt":1580607519361,"mc":[{"id":"1.168224027","rc":[{"batb":[[0,1.93,62.8],[1,1.92,6.47]],"ltp":2.04,"tv":146.69,"id":8908205},{"batb":[[0,1.93,62.46],[1,1.92,6.78]],"ltp":0.0,"tv":0.0,"id":4596961}]}]}
{"op":"mcm","clk":"1000190863","pt":1580609276765,"mc":[{"id":"1.168224027","rc":[{"batb":[[0,1.92,6.47],[1,1.86,84.95]],"ltp":2.04,"tv":146.69,"id":8908205},{"batb":[[0,1.96,81.81]],"ltp":0.0,"tv":0.0,"id":4596961}]}]}
{"op":"mcm","clk":"1000224596","pt":1580610074530,"mc":[{"id":"1.168224027","rc":[{"batb":[[0,1.87,6.47]],"ltp":2.04,"tv":146.69,"id":8908205}]}]}
{"op":"mcm","clk":"1000224643","pt":1580610075252,"mc":[{"id":"1.168224027","rc":[{"batb":[[0,1.97,6.78],[1,1.96,81.81]],"ltp":0.0,"tv":0.0,"id":4596961}]}]}
{"op":"mcm","clk":"1000224934","pt":1580610080766,"mc":[{"id":"1.168224027","rc":[{"batb":[[0,1.88,63.89],[1,1.87,6.47]],"ltp":2.04,"tv":146.69,"id":8908205},{"batb":[[0,1.98,63.85],[1,1.97,6.78]],"ltp":0.0,"tv":0.0,"id":4596961}]}]}
{"op":"mcm","clk":"1000336488","pt":1580612635726,"mc":[{"id":"1.168224027","rc":[{"batb":[[1,1.81,37.86],[2,1.79,201.78]],"ltp":2.04,"tv":146.69,"id":8908205}]}]}
{"op":"mcm","clk":"1000336520","pt":1580612636238,"mc":[{"id":"1.168224027","rc":[{"batb":[[1,1.83,49.98],[2,1.82,144.06]],"ltp":0.0,"tv":0.0,"id":4596961}]}]}
{"op":"mcm","clk":"1000337923","pt":1580612664064,"mc":[{"id":"1.168224027","rc":[{"batb":[[0,1.86,84.95]],"ltp":2.04,"tv":146.69,"id":8908205},{"batb":[[0,1.96,81.81]],"ltp":0.0,"tv":0.0,"id":4596961}]}]}
{"op":"mcm","clk":"1000424367","pt":1580614281988,"mc":[{"id":"1.168224027","rc":[{"trd":[[1.91,4]],"batl":[[0,12,3.88]],"ltp":1.91,"tv":150.69,"id":8908205}],"tv":150.69}]}
{"op":"mcm","clk":"1000473012","pt":1580615092984,"mc":[{"id":"1.168224027","rc":[{"batl":[[1,990,2.2],[2,1000,0.02]],"ltp":1.91,"tv":150.69,"id":8908205},{"batl":[[1,990,2.2],[2,1000,0.02]],"ltp":0.0,"tv":0.0,"id":4596961}]}]}
{"op":"mcm","clk":"1000477598","pt":1580615153047,"mc":[{"id":"1.168224027","rc":[{"batb":[[0,1.87,5.96],[1,1.86,84.95],[2,1.81,37.86]],"ltp":1.91,"tv":150.69,"id":8908205},{"batb":[[0,1.97,6.82],[1,1.96,81.81],[2,1.83,49.98]],"ltp":0.0,"tv":0.0,"id":4596961}]}]}
{"op":"mcm","clk":"1000485409","pt":1580615266095,"mc":[{"id":"1.168224027","rc":[{"batb":[[0,1.88,63.89],[1,1.87,5.96]],"ltp":1.91,"tv":150.69,"id":8908205},{"batb":[[0,1.98,63.85],[1,1.97,6.82]],"ltp":0.0,"tv":0.0,"id":4596961}]}]}
{"op":"mcm","clk":"1000555995","pt":1580616767794,"mc":[{"id":"1.168224027","rc":[{"batl":[[1,95,15.9],[2,990,2.2]],"ltp":1.91,"tv":150.69,"id":8908205},{"batl":[[1,95,15.9],[2,990,2.2]],"ltp":0.0,"tv":0.0,"id":4596961}]}]}
{"op":"mcm","clk":"1000621896","pt":1580617660273,"mc":[{"id":"1.168224027","rc":[{"batb":[[1,1.81,37.86],[2,1.79,280.38]],"ltp":1.91,"tv":150.69,"id":8908205}]}]}
{"op":"mcm","clk":"1000621960","pt":1580617661303,"mc":[{"id":"1.168224027","rc":[{"batb":[[1,1.83,49.98],[2,1.82,219.78]],"ltp":0.0,"tv":0.0,"id":4596961}]}]}
{"op":"mcm","clk":"1000623552","pt":1580617688025,"mc":[{"id":"1.168224027","rc":[{"batb":[[0,1.81,37.86],[1,1.79,280.38],[2,1.71,37.86]],"ltp":1.91,"tv":150.69,"id":8908205},{"batb":[[0,1.83,49.98],[1,1.82,219.78],[2,1.81,37.86]],"ltp":0.0,"tv":0.0,"id":4596961}]}]}
{"op":"mcm","clk":"1000623593","pt":1580617688539,"mc":[{"id":"1.168224027","rc":[{"batb":[[0,1.86,84.95],[1,1.81,37.86],[2,1.79,280.38]],"ltp":1.91,"tv":150.69,"id":8908205},{"batb":[[0,1.96,81.81],[1,1.83,49.98],[2,1.82,219.78]],"ltp":0.0,"tv":0.0,"id":4596961}]}]}
{"op":"mcm","clk":"1000756287","pt":1580620156586,"mc":[{"id":"1.168224027","rc":[{"batb":[[0,1.87,7],[1,1.86,84.95],[2,1.81,37.86]],"ltp":1.91,"tv":150.69,"id":8908205},{"batb":[[0,1.97,7.3],[1,1.96,81.81],[2,1.83,49.98]],"ltp":0.0,"tv":0.0,"id":4596961}]}]}
{"op":"mcm","clk":"1000757570","pt":1580620182618,"mc":[{"id":"1.168224027","rc":[{"batb":[[0,1.88,63.89],[1,1.87,7]],"ltp":1.91,"tv":150.69,"id":8908205},{"batb":[[0,1.98,63.85],[1,1.97,7.3]],"ltp":0.0,"tv":0.0,"id":4596961}]}]}
{"op":"mcm","clk":"1000766555","pt":1580620361061,"mc":[{"id":"1.168224027","rc":[{"trd":[[1.88,0.39]],"batb":[[0,1.88,63.7]],"ltp":1.88,"tv":151.08,"id":8908205}],"tv":151.08}]}
{"op":"mcm","clk":"1000766940","pt":1580620369298,"mc":[{"id":"1.168224027","rc":[{"trd":[[1.88,0.78]],"batb":[[0,1.88,63.5]],"ltp":1.88,"tv":151.47,"id":8908205}],"tv":151.47}]}
{"op":"mcm","clk":"1000868312","pt":1580622628894,"mc":[{"id":"1.168224027","rc":[{"batb":[[1,1.81,37.86],[2,1.79,280.38]],"ltp":1.88,"tv":151.47,"id":8908205}]}]}
{"op":"mcm","clk":"1000868333","pt":1580622629512,"mc":[{"id":"1.168224027","rc":[{"batb":[[1,1.83,49.98],[2,1.82,219.78]],"ltp":0.0,"tv":0.0,"id":4596961}]}]}
{"op":"mcm","clk":"1000871926","pt":1580622742412,"mc":[{"id":"1.168224027","rc":[{"batb":[[0,1.86,84.57]],"ltp":1.88,"tv":151.47,"id":8908205},{"batb":[[0,1.96,82.17]],"ltp":0.0,"tv":0.0,"id":4596961}]}]}
{"op":"mcm","clk":"1000891434","pt":1580623330033,"mc":[{"id":"1.168224027","rc":[{"batb":[[0,1.86,417.68],[2,1.79,52.25]],"ltp":1.88,"tv":151.47,"id":8908205},{"batb":[[2,1.81,37.86]],"ltp":0.0,"tv":0.0,"id":4596961}]}]}
{"op":"mcm","clk":"1000891438","pt":1580623330135,"mc":[{"id":"1.168224027","rc":[{"batb":[[2,1.8,225.28]],"ltp":1.88,"tv":151.47,"id":8908205},{"batb":[[2,1.81,260.36]],"ltp":0.0,"tv":0.0,"id":4596961}]}]}
{"op":"mcm","clk":"1000892071","pt":1580623343828,"mc":[{"id":"1.168224027","rc":[{"batb":[[2,1.8,277.53]],"ltp":1.88,"tv":151.47,"id":8908205},{"batb":[[1,1.82,49.98]],"ltp":0.0,"tv":0.0,"id":4596961}]}]}
{"op":"mcm","clk":"1000895786","pt":1580623443623,"mc":[{"id":"1.168224027","rc":[{"batb":[[2,1.8,52.25]],"ltp":1.88,"tv":151.47,"id":8908205},{"batb":[[2,1.81,37.86]],"ltp":0.0,"tv":0.0,"id":4596961}]}]}
{"op":"mcm","clk":"1000895814","pt":1580623444296,"mc":[{"id":"1.168224027","rc":[{"batb":[[1,1.81,260.36]],"ltp":1.88,"tv":151.47,"id":8908205},{"batb":[[2,1.81,260.36]],"ltp":0.0,"tv":0.0,"id":4596961}]}]}
{"op":"mcm","clk":"1000895969","pt":1580623448417,"mc":[{"id":"1.168224027","rc":[{"batb":[[1,1.81,312.61],[2,1.71,37.86]],"ltp":1.88,"tv":151.47,"id":8908205},{"batb":[[1,1.81,310.34],[2,1.71,37.86]],"ltp":0.0,"tv":0.0,"id":4596961}]}]}
{"op":"mcm","clk":"1000971385","pt":1580625197092,"mc":[{"id":"1.168224027","rc":[{"batb":[[1,1.81,90.11]],"ltp":1.88,"tv":151.47,"id":8908205},{"batb":[[1,1.81,87.84]],"ltp":0.0,"tv":0.0,"id":4596961}]}]}
{"op":"mcm","clk":"1000971408","pt":1580625197809,"mc":[{"id":"1.168224027","rc":[{"batb":[[1,1.81,312.61]],"ltp":1.88,"tv":151.47,"id":8908205},{"batb":[[1,1.81,310.34]],"ltp":0.0,"tv":0.0,"id":4596961}]}]}
{"op":"mcm","clk":"1000971806","pt":1580625207014,"mc":[{"id":"1.168224027","rc":[{"batb":[[1,1.82,52.25],[2,1.81,260.36]],"ltp":1.88,"tv":151.47,"id":8908205},{"batb":[[1,1.82,49.98],[2,1.81,260.36]],"ltp":0.0,"tv":0.0,"id":4596961}]}]}
{"op":"mcm","clk":"1000972685","pt":1580625230712,"mc":[{"id":"1.168224027","rc":[{"batb":[[0,1.87,333.55],[1,1.86,84.57],[2,1.82,52.25]],"ltp":1.88,"tv":151.47,"id":8908205},{"batb":[[0,1.97,7.42],[1,1.96,82.17],[2,1.82,49.98]],"ltp":0.0,"tv":0.0,"id":4596961}]}]}
{"op":"mcm","clk":"1000976181","pt":1580625318105,"mc":[{"id":"1.168224027","rc":[{"batb":[[0,1.88,63.51],[1,1.87,333.55]],"ltp":1.88,"tv":151.47,"id":8908205},{"batb":[[0,1.98,64.21],[1,1.97,7.42]],"ltp":0.0,"tv":0.0,"id":4596961}]}]}
{"op":"mcm","clk":"1000976189","pt":1580625318309,"mc":[{"id":"1.168224027","rc":[{"batb":[[1,1.87,6.97]],"ltp":1.88,"tv":151.47,"id":8908205}]}]}
{"op":"mcm","clk":"1001072375","pt":1580627846834,"mc":[{"id":"1.168224027","rc":[{"batb":[[1,1.82,52.25],[2,1.81,260.36]],"ltp":1.88,"tv":151.47,"id":8908205},{"batb":[[1,1.82,49.98],[2,1.81,260.36]],"ltp":0.0,"tv":0.0,"id":4596961}]}]}
{"op":"mcm","clk":"1001076553","pt":1580627949989,"mc":[{"id":"1.168224027","rc":[{"batb":[[0,1.86,84.57]],"ltp":1.88,"tv":151.47,"id":8908205},{"batb":[[0,1.96,82.17]],"ltp":0.0,"tv":0.0,"id":4596961}]}]}
{"op":"mcm","clk":"1001076570","pt":1580627950194,"mc":[{"id":"1.168224027","rc":[{"batb":[[0,1.87,328.04],[1,1.86,84.57],[2,1.82,52.25]],"ltp":1.88,"tv":151.47,"id":8908205}]}]}
{"op":"mcm","clk":"1001081749","pt":1580628071905,"mc":[{"id":"1.168224027","rc":[{"batb":[[0,1.88,63.51],[1,1.82,52.25],[2,1.81,260.36]],"ltp":1.88,"tv":151.47,"id":8908205}]}]}
{"op":"mcm","clk":"1001086553","pt":1580628190075,"mc":[{"id":"1.168224027","rc":[{"batb":[[0,1.86,84.57]],"ltp":1.88,"tv":151.47,"id":8908205}]}]}
{"op":"mcm","clk":"1001086580","pt":1580628190438,"mc":[{"id":"1.168224027","rc":[{"batb":[[0,1.87,328.04],[1,1.86,84.57],[2,1.82,52.25]],"ltp":1.88,"tv":151.47,"id":8908205}]}]}
{"op":"mcm","clk":"1001091629","pt":1580628308903,"mc":[{"id":"1.168224027","rc":[{"batb":[[0,1.88,63.51],[1,1.87,328.04]],"ltp":1.88,"tv":151.47,"id":8908205}]}]}
{"op":"mcm","clk":"1001091641","pt":1580628309209,"mc":[{"id":"1.168224027","rc":[{"batb":[[1,1.82,52.25],[2,1.81,260.36]],"ltp":1.88,"tv":151.47,"id":8908205}]}]}
{"op":"mcm","clk":"1001097802","pt":1580628431856,"mc":[{"id":"1.168224027","rc":[{"batb":[[0,1.87,328.04],[1,1.86,84.57],[2,1.82,52.25]],"ltp":1.88,"tv":151.47,"id":8908205}]}]}
{"op":"mcm","clk":"1001103851","pt":1580628553031,"mc":[{"id":"1.168224027","rc":[{"batb":[[0,1.88,63.51],[1,1.87,328.04]],"ltp":1.88,"tv":151.47,"id":8908205}]}]}
{"op":"mcm","clk":"1001103856","pt":1580628553236,"mc":[{"id":"1.168224027","rc":[{"batb":[[1,1.82,52.25],[2,1.81,260.36]],"ltp":1.88,"tv":151.47,"id":8908205}]}]}
{"op":"mcm","clk":"1001109926","pt":1580628682029,"mc":[{"id":"1.168224027","rc":[{"batb":[[0,1.86,84.57]],"ltp":1.88,"tv":151.47,"id":8908205}]}]}
{"op":"mcm","clk":"1001109948","pt":1580628682445,"mc":[{"id":"1.168224027","rc":[{"batb":[[0,1.87,328.04],[1,1.86,84.57],[2,1.82,52.25]],"ltp":1.88,"tv":151.47,"id":8908205}]}]}
{"op":"mcm","clk":"1001115793","pt":1580628809922,"mc":[{"id":"1.168224027","rc":[{"batb":[[0,1.88,63.51],[1,1.82,52.25],[2,1.81,260.36]],"ltp":1.88,"tv":151.47,"id":8908205}]}]}
{"op":"mcm","clk":"1001121133","pt":1580628938977,"mc":[{"id":"1.168224027","rc":[{"batb":[[0,1.87,328.04],[1,1.86,84.57],[2,1.82,52.25]],"ltp":1.88,"tv":151.47,"id":8908205}]}]}
{"op":"mcm","clk":"1001126631","pt":1580629066642,"mc":[{"id":"1.168224027","rc":[{"batb":[[0,1.88,63.51],[1,1.82,52.25],[2,1.81,260.36]],"ltp":1.88,"tv":151.47,"id":8908205}]}]}
{"op":"mcm","clk":"1001132444","pt":1580629196831,"mc":[{"id":"1.168224027","rc":[{"batb":[[0,1.87,328.04],[1,1.86,84.57],[2,1.82,52.25]],"ltp":1.88,"tv":151.47,"id":8908205}]}]}
{"op":"mcm","clk":"1001140134","pt":1580629330392,"mc":[{"id":"1.168224027","rc":[{"batb":[[0,1.86,84.57],[1,1.82,52.25],[2,1.81,260.36]],"ltp":1.88,"tv":151.47,"id":8908205}]}]}
{"op":"mcm","clk":"1001142652","pt":1580629377346,"mc":[{"id":"1.168224027","rc":[{"batb":[[0,1.87,328.04],[1,1.86,84.57],[2,1.82,52.25]],"ltp":1.88,"tv":151.47,"id":8908205}]}]}
{"op":"mcm","clk":"1001147570","pt":1580629485027,"mc":[{"id":"1.168224027","rc":[{"batb":[[0,1.88,63.51],[1,1.82,52.25],[2,1.81,260.36]],"ltp":1.88,"tv":151.47,"id":8908205}]}]}
{"op":"mcm","clk":"1001152702","pt":1580629609815,"mc":[{"id":"1.168224027","rc":[{"batb":[[0,1.86,414.54]],"ltp":1.88,"tv":151.47,"id":8908205}]}]}
{"op":"mcm","clk":"1001188147","pt":1580630467087,"mc":[{"id":"1.168224027","rc":[{"batb":[[0,1.87,6.66],[1,1.86,84.57],[2,1.82,52.25]],"ltp":1.88,"tv":151.47,"id":8908205}]}]}
{"op":"mcm","clk":"1001188163","pt":1580630467394,"mc":[{"id":"1.168224027","rc":[{"batb":[[0,1.87,334.7]],"ltp":1.88,"tv":151.47,"id":8908205},{"batb":[[0,1.97,7.21],[1,1.96,82.17],[2,1.82,49.98]],"ltp":0.0,"tv":0.0,"id":4596961}]}]}
{"op":"mcm","clk":"1001189333","pt":1580630492886,"mc":[{"id":"1.168224027","rc":[{"batb":[[0,1.87,436.47]],"ltp":1.88,"tv":151.47,"id":8908205}]}]}
{"op":"mcm","clk":"1001189446","pt":1580630494991,"mc":[{"id":"1.168224027","rc":[{"batb":[[2,1.83,285.56]],"ltp":1.88,"tv":151.47,"id":8908205},{"batb":[[2,1.83,285.56]],"ltp":0.0,"tv":0.0,"id":4596961}]}]}
{"op":"mcm","clk":"1001189510","pt":1580630496073,"mc":[{"id":"1.168224027","rc":[{"batb":[[0,1.88,63.51],[1,1.87,436.47]],"ltp":1.88,"tv":151.47,"id":8908205},{"batb":[[0,1.98,64.21],[1,1.97,7.21]],"ltp":0.0,"tv":0.0,"id":4596961}]}]}
{"op":"mcm","clk":"1001189521","pt":1580630496278,"mc":[{"id":"1.168224027","rc":[{"batb":[[1,1.87,6.66]],"ltp":1.88,"tv":151.47,"id":8908205}]}]}
{"op":"mcm","clk":"1001262208","pt":1580632043502,"mc":[{"id":"1.168224027","rc":[{"batl":[[0,2.12,37],[1,13,3.36],[2,95,15.9]],"ltp":0.0,"tv":0.0,"id":4596961}]}]}
{"op":"mcm","clk":"1001263423","pt":1580632068314,"mc":[{"id":"1.168224027","rc":[{"batl":[[1,95,15.9],[2,990,2.2]],"ltp":0.0,"tv":0.0,"id":4596961}]}]}
{"op":"mcm","clk":"1001267557","pt":1580632158764,"mc":[{"id":"1.168224027","rc":[{"batb":[[0,1.9,43.24]],"ltp":1.88,"tv":151.47,"id":8908205}]}]}
{"op":"mcm","clk":"1001308930","pt":1580633136723,"mc":[{"id":"1.168224027","rc":[{"batb":[[1,1.83,285.56],[2,1.82,52.25]],"ltp":1.88,"tv":151.47,"id":8908205},{"batb":[[1,1.83,285.56],[2,1.82,49.98]],"ltp":0.0,"tv":0.0,"id":4596961}]}]}
{"op":"mcm","clk":"1001311356","pt":1580633181831,"mc":[{"id":"1.168224027","rc":[{"batb":[[0,1.96,82.17]],"ltp":0.0,"tv":0.0,"id":4596961}]}]}
{"op":"mcm","clk":"1001332282","pt":1580633654952,"mc":[{"id":"1.168224027","rc":[{"batb":[[1,1.82,52.25],[2,1.81,37.86]],"ltp":1.88,"tv":151.47,"id":8908205},{"batb":[[1,1.82,49.98],[2,1.81,37.86]],"ltp":0.0,"tv":0.0,"id":4596961}]}]}
{"op":"mcm","clk":"1001332318","pt":1580633655685,"mc":[{"id":"1.168224027","rc":[{"batb":[[1,1.82,341.29]],"ltp":1.88,"tv":151.47,"id":8908205},{"batb":[[1,1.83,285.56],[2,1.82,49.98]],"ltp":0.0,"tv":0.0,"id":4596961}]}]}
{"op":"mcm","clk":"1001333397","pt":1580633682106,"mc":[{"id":"1.168224027","rc":[{"batb":[[1,1.82,52.25]],"ltp":1.88,"tv":151.47,"id":8908205},{"batb":[[1,1.82,49.98],[2,1.81,37.86]],"ltp":0.0,"tv":0.0,"id":4596961}]}]}
{"op":"mcm","clk":"1001333412","pt":1580633682672,"mc":[{"id":"1.168224027","rc":[{"batb":[[2,1.81,330.47]],"ltp":1.88,"tv":151.47,"id":8908205},{"batb":[[1,1.84,282.16],[2,1.82,49.98]],"ltp":0.0,"tv":0.0,"id":4596961}]}]}
{"op":"mcm","clk":"1001335515","pt":1580633738499,"mc":[{"id":"1.168224027","rc":[{"trd":[[1.9,12]],"batb":[[0,1.9,37.25]],"ltp":1.9,"tv":163.47,"id":8908205}],"tv":163.47}]}
{"op":"mcm","clk":"1001335789","pt":1580633744502,"mc":[{"id":"1.168224027","rc":[{"batb":[[0,1.97,78.77]],"ltp":0.0,"tv":0.0,"id":4596961}]}]}
{"op":"mcm","clk":"1001340466","pt":1580633864864,"mc":[{"id":"1.168224027","rc":[{"trd":[[1.9,64.98]],"batb":[[0,1.9,10.75],[2,1.81,37.86]],"ltp":1.9,"tv":216.45,"id":8908205},{"batb":[[1,1.86,275.59]],"ltp":0.0,"tv":0.0,"id":4596961}],"tv":216.45}]}
{"op":"mcm","clk":"1001340518","pt":1580633865962,"mc":[{"id":"1.168224027","rc":[{"batb":[[0,1.83,84.87]],"ltp":1.9,"tv":216.45,"id":8908205},{"batb":[[0,2,77.16]],"ltp":0.0,"tv":0.0,"id":4596961}]}]}
{"op":"mcm","clk":"1001340549","pt":1580633866471,"mc":[{"id":"1.168224027","rc":[{"batb":[[1,1.81,37.86],[2,1.79,300.02]],"ltp":1.9,"tv":216.45,"id":8908205}]}]}
{"op":"mcm","clk":"1001348537","pt":1580634068745,"mc":[{"id":"1.168224027","rc":[{"trd":[[2.12,34]],"batb":[[1,1.86,325.57],[2,1.81,37.86]],"batl":[[0,2.12,20]],"ltp":2.12,"tv":34.0,"id":4596961}],"tv":250.45}]}
{"op":"mcm","clk":"1001357083","pt":1580634257069,"mc":[{"id":"1.168224027","rc":[{"batl":[[0,2,8.92],[1,12,3.36],[2,95,15.9]],"ltp":1.9,"tv":216.45,"id":8908205},{"batb":[[0,2,85.56]],"ltp":2.12,"tv":34.0,"id":4596961}]}]}
{"op":"mcm","clk":"1001357130","pt":1580634257847,"mc":[{"id":"1.168224027","rc":[{"batb":[[0,1.89,9.44],[1,1.83,84.87],[2,1.81,37.86]],"ltp":1.9,"tv":216.45,"id":8908205},{"trd":[[2.12,52]],"batl":[[0,2.12,19.4]],"ltp":2.12,"tv":52.0,"id":4596961}],"tv":268.45}]}
{"op":"mcm","clk":"1001358397","pt":1580634286012,"mc":[{"id":"1.168224027","rc":[{"batl":[[1,95,15.9],[2,990,2.2]],"ltp":1.9,"tv":216.45,"id":8908205}]}]}
{"op":"mcm","clk":"1001370180","pt":1580634522058,"mc":[{"id":"1.168224027","rc":[{"batb":[[0,1.9,3.8],[1,1.89,9.44],[2,1.83,84.87]],"ltp":1.9,"tv":216.45,"id":8908205}]}]}
{"op":"mcm","clk":"1001370222","pt":1580634523092,"mc":[{"id":"1.168224027","rc":[{"trd":[[2.12,74]],"batl":[[0,2.12,8.4]],"ltp":2.12,"tv":74.0,"id":4596961}],"tv":290.45}]}
{"op":"mcm","clk":"1001370921","pt":1580634538700,"mc":[{"id":"1.168224027","rc":[{"batb":[[0,1.9,13.13],[1,1.83,84.87],[2,1.81,37.86]],"ltp":1.9,"tv":216.45,"id":8908205}]}]}
{"op":"mcm","clk":"1001389546","pt":1580634898375,"mc":[{"id":"1.168224027","rc":[{"trd":[[1.9,84.38]],"batb":[[0,1.9,3.44]],"ltp":1.9,"tv":235.85,"id":8908205}],"tv":309.85}]}
{"op":"mcm","clk":"1001397974","pt":1580635061840,"mc":[{"id":"1.168224027","rc":[{"batl":[[1,2.28,18.48],[2,95,15.9]],"ltp":1.9,"tv":235.85,"id":8908205}]}]}
{"op":"mcm","clk":"1001398006","pt":1580635062460,"mc":[{"id":"1.168224027","rc":[{"trd":[[2.12,86]],"batl":[[0,2.12,2.4]],"ltp":2.12,"tv":85.99,"id":4596961}],"tv":321.85}]}
{"op":"mcm","clk":"1001398334","pt":1580635068842,"mc":[{"id":"1.168224027","rc":[{"batl":[[0,95,15.9],[1,990,2.2],[2,1000,0.13]],"ltp":2.12,"tv":85.99,"id":4596961}]}]}
{"op":"mcm","clk":"1001398372","pt":1580635069358,"mc":[{"id":"1.168224027","rc":[{"batb":[[0,1.84,19.22]],"ltp":1.9,"tv":235.85,"id":8908205}]}]}
{"op":"mcm","clk":"1001398775","pt":1580635078660,"mc":[{"id":"1.168224027","rc":[{"batl":[[0,2.28,18.48],[1,95,15.9],[2,990,2.2]],"ltp":2.12,"tv":85.99,"id":4596961}]}]}
{"op":"mcm","clk":"1001402380","pt":1580635147819,"mc":[{"id":"1.168224027","rc":[{"batb":[[0,1.85,62.72],[1,1.81,37.86],[2,1.79,300.02]],"ltp":1.9,"tv":235.85,"id":8908205}]}]}
{"op":"mcm","clk":"1001408517","pt":1580635281101,"mc":[{"id":"1.168224027","rc":[{"batb":[[0,1.83,84.87]],"ltp":1.9,"tv":235.85,"id":8908205}]}]}
{"op":"mcm","clk":"1001408524","pt":1580635281203,"mc":[{"id":"1.168224027","rc":[{"batb":[[0,1.83,534.49]],"ltp":1.9,"tv":235.85,"id":8908205}]}]}
{"op":"mcm","clk":"1001437764","pt":1580635809752,"mc":[{"id":"1.168224027","rc":[{"batb":[[2,1.78,51.49]],"ltp":1.9,"tv":235.85,"id":8908205},{"batb":[[1,1.86,49.98]],"ltp":2.12,"tv":85.99,"id":4596961}]}]}
{"op":"mcm","clk":"1001437799","pt":1580635810366,"mc":[{"id":"1.168224027","rc":[{"batb":[[2,1.8,296.27]],"ltp":1.9,"tv":235.85,"id":8908205},{"batb":[[2,1.85,278.84]],"ltp":2.12,"tv":85.99,"id":4596961}]}]}
{"op":"mcm","clk":"1001438517","pt":1580635824066,"mc":[{"id":"1.168224027","rc":[{"batb":[[0,1.84,7.21],[1,1.83,534.49],[2,1.81,37.86]],"ltp":1.9,"tv":235.85,"id":8908205}]}]}
{"op":"mcm","clk":"1001438539","pt":1580635824488,"mc":[{"id":"1.168224027","rc":[{"batb":[[0,1.84,452.43],[1,1.83,84.87]],"ltp":1.9,"tv":235.85,"id":8908205},{"batb":[[0,2.02,6.22],[1,2,85.56],[2,1.86,49.98]],"ltp":2.12,"tv":85.99,"id":4596961}]}]}
{"op":"mcm","clk":"1001439334","pt":1580635840721,"mc":[{"id":"1.168224027","rc":[{"batl":[[0,2.28,19.01],[1,95,15.9],[2,990,2.2]],"ltp":1.9,"tv":235.85,"id":8908205}]}]}
{"op":"mcm","clk":"1001439383","pt":1580635841595,"mc":[{"id":"1.168224027","rc":[{"batl":[[0,1.99,13.12],[1,2.28,18.48],[2,95,15.9]],"ltp":1.9,"tv":235.85,"id":8908205},{"batb":[[0,2.02,18.58],[1,2,77.16]],"ltp":2.12,"tv":85.99,"id":4596961}]}]}
{"op":"mcm","clk":"1001444937","pt":1580635945661,"mc":[{"id":"1.168224027","rc":[{"batb":[[0,1.85,62.72],[1,1.84,7.21]],"ltp":1.9,"tv":235.85,"id":8908205},{"batb":[[0,2.04,43.93],[1,2.02,18.58]],"ltp":2.12,"tv":85.99,"id":4596961}]}]}
{"op":"mcm","clk":"1001445947","pt":1580635965953,"mc":[{"id":"1.168224027","rc":[{"batl":[[0,2.28,19.01],[1,95,15.9],[2,990,2.2]],"ltp":1.9,"tv":235.85,"id":8908205},{"batb":[[1,2.02,6.22]],"ltp":2.12,"tv":85.99,"id":4596961}]}]}
{"op":"mcm","clk":"1001445962","pt":1580635966570,"mc":[{"id":"1.168224027","rc":[{"batl":[[0,1.97,13.12],[1,2.28,18.48],[2,95,15.9]],"ltp":1.9,"tv":235.85,"id":8908205},{"batb":[[0,2.04,56.04]],"ltp":2.12,"tv":85.99,"id":4596961}]}]}
{"op":"mcm","clk":"1001446985","pt":1580635996116,"mc":[{"id":"1.168224027","rc":[{"batl":[[1,2,2],[2,2.28,18.48]],"ltp":1.9,"tv":235.85,"id":8908205}]}]}
{"op":"mcm","clk":"1001461007","pt":1580636350118,"mc":[{"id":"1.168224027","rc":[{"trd":[[1.91,4.52],[1.97,12.6],[2,1.52]],"batb":[[0,1.86,430.11],[1,1.85,62.72],[2,1.84,7.21]],"batl":[[0,2.28,18.96],[1,95,15.9],[2,990,2.2]],"ltp":2.0,"tv":250.49,"id":8908205},{"trd":[[2,1.52],[2.02,24.74],[2.04,112.08],[2.08,0.48]],"batb":[[0,1.86,49.98],[1,1.85,278.84],[2,1.81,37.86]],"ltp":2.0,"tv":224.82,"id":4596961}],"tv":475.31}]}
{"op":"mcm","clk":"1001461112","pt":1580636352031,"mc":[{"id":"1.168224027","rc":[{"batb":[[1,1.81,37.86],[2,1.71,37.86]],"ltp":2.0,"tv":224.82,"id":4596961}]}]}
{"op":"mcm","clk":"1001461149","pt":1580636352706,"mc":[{"id":"1.168224027","rc":[{"batb":[[0,1.91,81.11],[1,1.84,7.21],[2,1.83,285.56]],"ltp":2.0,"tv":250.49,"id":8908205},{"batb":[[0,1.91,82.97],[1,1.86,49.98],[2,1.82,289.04]],"ltp":2.0,"tv":224.82,"id":4596961}]}]}
{"op":"mcm","clk":"1001461251","pt":1580636354915,"mc":[{"id":"1.168224027","rc":[{"batb":[[1,1.82,289.04],[2,1.81,37.86]],"ltp":2.0,"tv":224.82,"id":4596961}]}]}
{"op":"mcm","clk":"1001461848","pt":1580636368639,"mc":[{"id":"1.168224027","rc":[{"batb":[[0,1.91,94.96]],"ltp":2.0,"tv":250.49,"id":8908205},{"batl":[[0,2.1,12.6],[1,2.28,18.48],[2,95,15.9]],"ltp":2.0,"tv":224.82,"id":4596961}]}]}
{"op":"mcm","clk":"1001464177","pt":1580636425029,"mc":[{"id":"1.168224027","rc":[{"trd":[[1.91,48.52]],"batb":[[0,1.91,72.96]],"batl":[[0,2,8.05],[1,2.28,18.48],[2,95,15.9]],"ltp":1.91,"tv":294.49,"id":8908205},{"batb":[[0,1.82,289.04],[1,1.81,37.86],[2,1.71,37.86]],"ltp":2.0,"tv":224.82,"id":4596961}],"tv":519.31}]}
{"op":"mcm","clk":"1001464183","pt":1580636425130,"mc":[{"id":"1.168224027","rc":[{"batb":[[0,1.93,84.87],[1,1.82,289.04],[2,1.81,37.86]],"ltp":2.0,"tv":224.82,"id":4596961}]}]}
{"op":"mcm","clk":"1001465023","pt":1580636443747,"mc":[{"id":"1.168224027","rc":[{"batb":[[0,1.92,7.57],[1,1.91,72.96],[2,1.84,7.21]],"ltp":1.91,"tv":294.49,"id":8908205}]}]}
{"op":"mcm","clk":"1001465212","pt":1580636447452,"mc":[{"id":"1.168224027","rc":[{"batb":[[0,1.91,72.96],[1,1.84,7.21],[2,1.83,285.56]],"ltp":1.91,"tv":294.49,"id":8908205}]}]}
{"op":"mcm","clk":"1001465293","pt":1580636449154,"mc":[{"id":"1.168224027","rc":[{"batl":[[0,2.28,18.96],[1,95,15.9],[2,990,2.2]],"ltp":1.91,"tv":294.49,"id":8908205}]}]}
{"op":"mcm","clk":"1001466825","pt":1580636484894,"mc":[{"id":"1.168224027","rc":[{"batl":[[1,2.36,74.21],[2,95,15.9]],"ltp":1.91,"tv":294.49,"id":8908205}]}]}
{"op":"mcm","clk":"1001466905","pt":1580636486078,"mc":[{"id":"1.168224027","rc":[{"trd":[[1.91,92.51]],"batb":[[0,1.91,50.97]],"ltp":1.91,"tv":338.48,"id":8908205},{"batb":[[0,1.82,289.04],[1,1.81,37.86],[2,1.71,37.86]],"ltp":2.0,"tv":224.82,"id":4596961}],"tv":563.31}]}
{"op":"mcm","clk":"1001466910","pt":1580636486184,"mc":[{"id":"1.168224027","rc":[{"batb":[[0,1.96,77.9],[1,1.82,289.04],[2,1.81,37.86]],"ltp":2.0,"tv":224.82,"id":4596961}]}]}
{"op":"mcm","clk":"1001470819","pt":1580636544661,"mc":[{"id":"1.168224027","rc":[{"trd":[[1.91,142.52]],"batb":[[0,1.91,25.96]],"ltp":1.91,"tv":388.49,"id":8908205}],"tv":613.31}]}
{"op":"mcm","clk":"1001470847","pt":1580636545381,"mc":[{"id":"1.168224027","rc":[{"batb":[[0,1.91,13.85],[1,1.85,74.68],[2,1.84,7.21]],"ltp":1.91,"tv":388.49,"id":8908205},{"batb":[[0,1.98,83.57]],"ltp":2.0,"tv":224.82,"id":4596961}]}]}
{"op":"mcm","clk":"1001475464","pt":1580636641710,"mc":[{"id":"1.168224027","rc":[{"batl":[[0,2,8.05],[1,2.28,18.48],[2,2.36,74.21]],"ltp":1.91,"tv":388.49,"id":8908205}]}]}
{"op":"mcm","clk":"1001475513","pt":1580636642689,"mc":[{"id":"1.168224027","rc":[{"trd":[[1.91,163.02]],"batb":[[0,1.91,3.6]],"ltp":1.91,"tv":408.99,"id":8908205}],"tv":633.81}]}
{"op":"mcm","clk":"1001475652","pt":1580636645111,"mc":[{"id":"1.168224027","rc":[{"batb":[[0,1.91,11.17]],"ltp":1.91,"tv":408.99,"id":8908205}]}]}
{"op":"mcm","clk":"1001475760","pt":1580636647989,"mc":[{"id":"1.168224027","rc":[{"batl":[[0,2,16.45]],"ltp":1.91,"tv":408.99,"id":8908205},{"batb":[[0,2,8.4],[1,1.98,83.57],[2,1.82,289.04]],"ltp":2.0,"tv":224.82,"id":4596961}]}]}
{"op":"mcm","clk":"1001475775","pt":1580636648397,"mc":[{"id":"1.168224027","rc":[{"batb":[[0,1.91,16.81]],"ltp":1.91,"tv":408.99,"id":8908205}]}]}
{"op":"mcm","clk":"1001475822","pt":1580636649632,"mc":[{"id":"1.168224027","rc":[{"batl":[[0,2,8.88]],"ltp":1.91,"tv":408.99,"id":8908205}]}]}
{"op":"mcm","clk":"1001476086","pt":1580636654226,"mc":[{"id":"1.168224027","rc":[{"batl":[[0,1.99,7.57],[1,2,8.88],[2,2.28,18.48]],"ltp":1.91,"tv":408.99,"id":8908205}]}]}
{"op":"mcm","clk":"1001476232","pt":1580636656604,"mc":[{"id":"1.168224027","rc":[{"batl":[[0,2,8.88],[1,2.28,18.48],[2,2.36,74.21]],"ltp":1.91,"tv":408.99,"id":8908205}]}]}
{"op":"mcm","clk":"1001476739","pt":1580636664763,"mc":[{"id":"1.168224027","rc":[{"batl":[[0,2,24.03]],"ltp":1.91,"tv":408.99,"id":8908205}]}]}
{"op":"mcm","clk":"1001476815","pt":1580636665739,"mc":[{"id":"1.168224027","rc":[{"trd":[[1.91,188.26]],"batb":[[0,1.91,4.18]],"ltp":1.91,"tv":434.23,"id":8908205}],"tv":659.05}]}
{"op":"mcm","clk":"1001476849","pt":1580636666457,"mc":[{"id":"1.168224027","rc":[{"trd":[[1.92,15.06]],"ltp":1.92,"tv":449.3,"id":8908205}],"tv":674.12}]}
{"op":"mcm","clk":"1001476995","pt":1580636668934,"mc":[{"id":"1.168224027","rc":[{"batl":[[0,2,8.88]],"ltp":1.92,"tv":449.3,"id":8908205}]}]}
{"op":"mcm","clk":"1001477053","pt":1580636669861,"mc":[{"id":"1.168224027","rc":[{"batb":[[0,1.91,11.76]],"ltp":1.92,"tv":449.3,"id":8908205}]}]}
{"op":"mcm","clk":"1001477068","pt":1580636670167,"mc":[{"id":"1.168224027","rc":[{"batb":[[0,1.91,19.33]],"ltp":1.92,"tv":449.3,"id":8908205}]}]}
{"op":"mcm","clk":"1001477320","pt":1580636675164,"mc":[{"id":"1.168224027","rc":[{"batl":[[0,2,16.45]],"ltp":1.92,"tv":449.3,"id":8908205}]}]}
{"op":"mcm","clk":"1001477421","pt":1580636677477,"mc":[{"id":"1.168224027","rc":[{"batl":[[0,2,8.88]],"ltp":1.92,"tv":449.3,"id":8908205}]}]}
{"op":"mcm","clk":"1001477683","pt":1580636680476,"mc":[{"id":"1.168224027","rc":[{"batb":[[0,1.91,24.38]],"ltp":1.92,"tv":449.3,"id":8908205}]}]}
{"op":"mcm","clk":"1001477880","pt":1580636684751,"mc":[{"id":"1.168224027","rc":[{"trd":[[1.91,226.14]],"batb":[[0,1.91,5.44]],"ltp":1.91,"tv":487.18,"id":8908205}],"tv":712.0}]}
{"op":"mcm","clk":"1001478028","pt":1580636688253,"mc":[{"id":"1.168224027","rc":[{"batl":[[0,1.94,14.91],[1,2,8.88],[2,2.28,18.48]],"ltp":1.91,"tv":487.18,"id":8908205}]}]}
{"op":"mcm","clk":"1001478110","pt":1580636689742,"mc":[{"id":"1.168224027","rc":[{"trd":[[2.1,18.94]],"batl":[[0,2.1,3.13]],"ltp":2.1,"tv":243.76,"id":4596961}],"tv":730.94}]}
{"op":"mcm","clk":"1001478179","pt":1580636691076,"mc":[{"id":"1.168224027","rc":[{"trd":[[1.93,25.8]],"batl":[[0,1.93,2.01]],"ltp":1.93,"tv":512.98,"id":8908205}],"tv":756.74}]}
{"op":"mcm","clk":"1001478481","pt":1580636696965,"mc":[{"id":"1.168224027","rc":[{"batb":[[0,1.91,13.01]],"ltp":1.93,"tv":512.98,"id":8908205}]}]}
{"op":"mcm","clk":"1001479023","pt":1580636704411,"mc":[{"id":"1.168224027","rc":[{"batb":[[0,1.91,20.58]],"ltp":1.93,"tv":512.98,"id":8908205}]}]}
{"op":"mcm","clk":"1001479201","pt":1580636707722,"mc":[{"id":"1.168224027","rc":[{"batl":[[0,2,8.88],[1,2.28,18.48],[2,2.36,74.21]],"ltp":1.93,"tv":512.98,"id":8908205}]}]}
{"op":"mcm","clk":"1001479318","pt":1580636709897,"mc":[{"id":"1.168224027","rc":[{"batl":[[0,2,16.45]],"ltp":1.93,"tv":512.98,"id":8908205}]}]}
{"op":"mcm","clk":"1001479437","pt":1580636712102,"mc":[{"id":"1.168224027","rc":[{"batl":[[0,1.97,7.57],[1,2,16.45],[2,2.28,18.48]],"ltp":1.93,"tv":512.98,"id":8908205}]}]}
{"op":"mcm","clk":"1001479462","pt":1580636712516,"mc":[{"id":"1.168224027","rc":[{"batb":[[0,1.91,15.14]],"ltp":1.93,"tv":512.98,"id":8908205},{"batl":[[0,2.28,18.48],[1,95,15.9],[2,990,2.2]],"ltp":2.1,"tv":243.76,"id":4596961}]}]}
{"op":"mcm","clk":"1001479646","pt":1580636715512,"mc":[{"id":"1.168224027","rc":[{"batb":[[0,1.85,74.68],[1,1.84,7.21],[2,1.83,285.56]],"ltp":1.93,"tv":512.98,"id":8908205}]}]}
{"op":"mcm","clk":"1001479744","pt":1580636716913,"mc":[{"id":"1.168224027","rc":[{"batb":[[0,1.88,7.57],[1,1.85,74.68],[2,1.84,7.21]],"ltp":1.93,"tv":512.98,"id":8908205}]}]}
{"op":"mcm","clk":"1001479919","pt":1580636719710,"mc":[{"id":"1.168224027","rc":[{"batb":[[0,1.88,22.72]],"ltp":1.93,"tv":512.98,"id":8908205}]}]}
{"op":"mcm","clk":"1001480056","pt":1580636722803,"mc":[{"id":"1.168224027","rc":[{"trd":[[1.88,35.54]],"batb":[[0,1.88,5.33]],"batl":[[0,2,16.45],[1,2.28,18.48],[2,2.36,74.21]],"ltp":1.88,"tv":547.75,"id":8908205}],"tv":791.51}]}
{"op":"mcm","clk":"1001480262","pt":1580636726832,"mc":[{"id":"1.168224027","rc":[{"batb":[[0,1.85,74.68],[1,1.84,7.21],[2,1.83,285.56]],"batl":[[0,2,8.88]],"ltp":1.88,"tv":547.75,"id":8908205}]}]}
{"op":"mcm","clk":"1001480306","pt":1580636727913,"mc":[{"id":"1.168224027","rc":[{"batl":[[0,1.93,19.02],[1,2,8.88],[2,2.28,18.48]],"ltp":1.88,"tv":547.75,"id":8908205}]}]}
{"op":"mcm","clk":"1001480456","pt":1580636730941,"mc":[{"id":"1.168224027","rc":[{"batl":[[0,1.92,19.02]],"ltp":1.88,"tv":547.75,"id":8908205}]}]}
{"op":"mcm","clk":"1001480631","pt":1580636734046,"mc":[{"id":"1.168224027","rc":[{"batb":[[2,1.83,315.17]],"batl":[[0,1.91,19.02]],"ltp":1.88,"tv":547.75,"id":8908205}]}]}
{"op":"mcm","clk":"1001480650","pt":1580636734315,"mc":[{"id":"1.168224027","rc":[{"trd":[[1.91,264.19]],"batb":[[0,1.91,20.18],[1,1.85,74.68],[2,1.84,7.21]],"batl":[[0,2,8.88],[1,2.28,18.48],[2,2.36,74.21]],"ltp":1.91,"tv":585.79,"id":8908205}],"tv":829.55}]}
{"op":"mcm","clk":"1001480708","pt":1580636735647,"mc":[{"id":"1.168224027","rc":[{"batb":[[0,2.02,49.29],[1,2,8.4]],"ltp":2.1,"tv":243.76,"id":4596961}]}]}
{"op":"mcm","clk":"1001480819","pt":1580636737721,"mc":[{"id":"1.168224027","rc":[{"batb":[[1,1.88,15.14],[2,1.85,74.68]],"ltp":1.91,"tv":585.79,"id":8908205}]}]}
{"op":"mcm","clk":"1001480871","pt":1580636738749,"mc":[{"id":"1.168224027","rc":[{"batb":[[0,1.88,15.14],[1,1.85,74.68],[2,1.84,7.21]],"ltp":1.91,"tv":585.79,"id":8908205}]}]}
{"op":"mcm","clk":"1001480941","pt":1580636740033,"mc":[{"id":"1.168224027","rc":[{"batb":[[0,1.88,30.29]],"ltp":1.91,"tv":585.79,"id":8908205}]}]}
{"op":"mcm","clk":"1001481135","pt":1580636743957,"mc":[{"id":"1.168224027","rc":[{"batl":[[0,2.28,18.96],[1,2.36,74.21],[2,95,15.9]],"ltp":1.91,"tv":585.79,"id":8908205},{"batb":[[1,1.82,289.04],[2,1.81,37.86]],"ltp":2.1,"tv":243.76,"id":4596961}]}]}
{"op":"mcm","clk":"1001481181","pt":1580636744364,"mc":[{"id":"1.168224027","rc":[{"batl":[[0,1.99,12.6],[1,2.28,18.96],[2,2.36,74.21]],"ltp":1.91,"tv":585.79,"id":8908205},{"batb":[[0,2.02,61.65]],"ltp":2.1,"tv":243.76,"id":4596961}]}]}
{"op":"mcm","clk":"1001481282","pt":1580636745959,"mc":[{"id":"1.168224027","rc":[{"batl":[[0,1.98,22.72],[1,1.99,12.6],[2,2.28,18.96]],"ltp":1.91,"tv":585.79,"id":8908205}]}]}
{"op":"mcm","clk":"1001481392","pt":1580636748071,"mc":[{"id":"1.168224027","rc":[{"batl":[[0,1.99,12.6],[1,2.28,18.96],[2,2.36,74.21]],"ltp":1.91,"tv":585.79,"id":8908205}]}]}
{"op":"mcm","clk":"1001481578","pt":1580636750855,"mc":[{"id":"1.168224027","rc":[{"batb":[[1,1.87,7.57],[2,1.86,7.57]],"ltp":1.91,"tv":585.79,"id":8908205}]}]}
{"op":"mcm","clk":"1001482164","pt":1580636761856,"mc":[{"id":"1.168224027","rc":[{"trd":[[1.88,83.01]],"batb":[[0,1.88,6.55],[1,1.86,7.57],[2,1.85,74.68]],"ltp":1.88,"tv":633.26,"id":8908205}],"tv":877.02}]}
{"op":"mcm","clk":"1001482357","pt":1580636765361,"mc":[{"id":"1.168224027","rc":[{"batb":[[0,1.85,74.68],[1,1.84,7.21],[2,1.83,315.17]],"ltp":1.88,"tv":633.26,"id":8908205}]}]}
{"op":"mcm","clk":"1001482417","pt":1580636766487,"mc":[{"id":"1.168224027","rc":[{"batl":[[0,1.92,23.44],[1,1.99,12.6],[2,2.28,18.96]],"ltp":1.88,"tv":633.26,"id":8908205}]}]}
{"op":"mcm","clk":"1001482479","pt":1580636768287,"mc":[{"id":"1.168224027","rc":[{"batb":[[0,1.87,7.57],[1,1.85,74.68],[2,1.84,7.21]],"ltp":1.88,"tv":633.26,"id":8908205}]}]}
{"op":"mcm","clk":"1001482545","pt":1580636769571,"mc":[{"id":"1.168224027","rc":[{"batb":[[1,1.86,7.57],[2,1.85,74.68]],"ltp":1.88,"tv":633.26,"id":8908205}]}]}
{"op":"mcm","clk":"1001482601","pt":1580636770495,"mc":[{"id":"1.168224027","rc":[{"batb":[[0,1.88,440.6],[1,1.87,7.57],[2,1.86,7.57]],"ltp":1.88,"tv":633.26,"id":8908205}]}]}
{"op":"mcm","clk":"1001482724","pt":1580636772666,"mc":[{"id":"1.168224027","rc":[{"batb":[[0,1.88,444.01]],"ltp":1.88,"tv":633.26,"id":8908205}]}]}
{"op":"mcm","clk":"1001482831","pt":1580636774782,"mc":[{"id":"1.168224027","rc":[{"trd":[[1.91,268.19]],"batl":[[0,1.91,21.44]],"ltp":1.91,"tv":637.26,"id":8908205}],"tv":881.02}]}
{"op":"mcm","clk":"1001482892","pt":1580636775873,"mc":[{"id":"1.168224027","rc":[{"trd":[[1.91,311.06]],"batb":[[0,1.91,17.77],[1,1.88,444.01],[2,1.87,7.57]],"batl":[[0,2.28,18.96],[1,2.36,74.21],[2,95,15.9]],"ltp":1.91,"tv":680.13,"id":8908205},{"batb":[[0,2.02,49.29]],"ltp":2.1,"tv":243.76,"id":4596961}],"tv":923.89}]}
{"op":"mcm","clk":"1001482924","pt":1580636776487,"mc":[{"id":"1.168224027","rc":[{"trd":[[1.91,336.26]],"batb":[[0,1.91,5.17]],"ltp":1.91,"tv":705.34,"id":8908205},{"batb":[[0,2.08,11.67],[1,2.02,49.29],[2,1.82,289.04]],"ltp":2.1,"tv":243.76,"id":4596961}],"tv":949.1}]}
{"op":"mcm","clk":"1001483012","pt":1580636778501,"mc":[{"id":"1.168224027","rc":[{"batb":[[1,1.88,18.55]],"ltp":1.91,"tv":705.34,"id":8908205}]}]}
{"op":"mcm","clk":"1001483073","pt":1580636780207,"mc":[{"id":"1.168224027","rc":[{"batb":[[0,1.88,18.55],[1,1.87,7.57],[2,1.86,7.57]],"ltp":1.91,"tv":705.34,"id":8908205}]}]}
{"op":"mcm","clk":"1001483204","pt":1580636783100,"mc":[{"id":"1.168224027","rc":[{"batb":[[0,1.88,33.7]],"ltp":1.91,"tv":705.34,"id":8908205}]}]}
{"op":"mcm","clk":"1001483212","pt":1580636783306,"mc":[{"id":"1.168224027","rc":[{"batb":[[0,1.88,466.73]],"ltp":1.91,"tv":705.34,"id":8908205}]}]}
{"op":"mcm","clk":"1001483582","pt":1580636791402,"mc":[{"id":"1.168224027","rc":[{"batb":[[1,1.86,7.57],[2,1.85,74.68]],"ltp":1.91,"tv":705.34,"id":8908205}]}]}
{"op":"mcm","clk":"1001483878","pt":1580636797912,"mc":[{"id":"1.168224027","rc":[{"trd":[[1.88,163.02]],"batb":[[0,1.88,426.72],[1,1.85,74.68],[2,1.84,7.21]],"ltp":1.88,"tv":785.35,"id":8908205}],"tv":1029.11}]}
{"op":"mcm","clk":"1001484052","pt":1580636801526,"mc":[{"id":"1.168224027","rc":[{"batb":[[0,1.88,425.46]],"ltp":1.88,"tv":785.35,"id":8908205}]}]}
{"op":"mcm","clk":"1001484116","pt":1580636802608,"mc":[{"id":"1.168224027","rc":[{"batl":[[0,1.92,35.96],[1,2.28,18.96],[2,2.36,74.21]],"ltp":1.88,"tv":785.35,"id":8908205}]}]}
{"op":"mcm","clk":"1001484194","pt":1580636803898,"mc":[{"id":"1.168224027","rc":[{"trd":[[1.9,90.7]],"batl":[[0,1.92,36.17]],"ltp":1.9,"tv":791.67,"id":8908205}],"tv":1035.43}]}
{"op":"mcm","clk":"1001484328","pt":1580636806831,"mc":[{"id":"1.168224027","rc":[{"batl":[[0,1.91,36.17]],"ltp":1.9,"tv":791.67,"id":8908205}]}]}
{"op":"mcm","clk":"1001484378","pt":1580636807810,"mc":[{"id":"1.168224027","rc":[{"trd":[[1.9,91.12],[1.91,408.19]],"batb":[[0,1.91,3.03]],"batl":[[0,2.28,18.96],[1,2.36,74.21],[2,95,15.9]],"ltp":1.91,"tv":864.01,"id":8908205},{"batl":[[0,2.12,8.4],[1,2.28,18.48],[2,95,15.9]],"ltp":2.1,"tv":243.76,"id":4596961}],"tv":1107.77}]}
{"op":"mcm","clk":"1001484557","pt":1580636811119,"mc":[{"id":"1.168224027","rc":[{"batb":[[1,1.88,30.29],[2,1.85,74.68]],"ltp":1.91,"tv":864.01,"id":8908205}]}]}
{"op":"mcm","clk":"1001484589","pt":1580636811741,"mc":[{"id":"1.168224027","rc":[{"batb":[[1,1.88,53.01]],"ltp":1.91,"tv":864.01,"id":8908205}]}]}
{"op":"mcm","clk":"1001484613","pt":1580636812150,"mc":[{"id":"1.168224027","rc":[{"batb":[[0,1.88,53.01],[1,1.85,74.68],[2,1.84,7.21]],"ltp":1.91,"tv":864.01,"id":8908205}]}]}
{"op":"mcm","clk":"1001484734","pt":1580636814106,"mc":[{"id":"1.168224027","rc":[{"batb":[[0,1.89,7.57],[1,1.88,53.01],[2,1.85,74.68]],"ltp":1.91,"tv":864.01,"id":8908205}]}]}
{"op":"mcm","clk":"1001484791","pt":1580636814830,"mc":[{"id":"1.168224027","rc":[{"batb":[[0,1.89,30.29]],"ltp":1.91,"tv":864.01,"id":8908205}]}]}
{"op":"mcm","clk":"1001485114","pt":1580636820007,"mc":[{"id":"1.168224027","rc":[{"batb":[[0,1.85,74.68],[1,1.84,7.21],[2,1.83,315.17]],"ltp":1.91,"tv":864.01,"id":8908205}]}]}
{"op":"mcm","clk":"1001485202","pt":1580636821936,"mc":[{"id":"1.168224027","rc":[{"batb":[[0,1.89,7.57],[1,1.88,15.14],[2,1.85,74.68]],"ltp":1.91,"tv":864.01,"id":8908205}]}]}
{"op":"mcm","clk":"1001485221","pt":1580636822352,"mc":[{"id":"1.168224027","rc":[{"batb":[[0,1.89,15.14]],"ltp":1.91,"tv":864.01,"id":8908205}]}]}
{"op":"mcm","clk":"1001485435","pt":1580636826019,"mc":[{"id":"1.168224027","rc":[{"batb":[[1,1.88,30.29]],"ltp":1.91,"tv":864.01,"id":8908205}]}]}
{"op":"mcm","clk":"1001485999","pt":1580636836954,"mc":[{"id":"1.168224027","rc":[{"batb":[[0,1.89,22.72]],"ltp":1.91,"tv":864.01,"id":8908205},{"trd":[[2.12,98.68]],"batl":[[0,2.12,2.06]],"ltp":2.12,"tv":256.44,"id":4596961}],"tv":1120.45}]}
{"op":"mcm","clk":"1001486117","pt":1580636839482,"mc":[{"id":"1.168224027","rc":[{"batb":[[0,1.88,30.29],[1,1.85,74.68],[2,1.84,7.21]],"batl":[[0,1.93,12.6],[1,2.28,18.96],[2,2.36,74.21]],"ltp":1.91,"tv":864.01,"id":8908205},{"batl":[[0,2.28,18.48],[1,95,15.9],[2,990,2.2]],"ltp":2.12,"tv":256.44,"id":4596961}]}]}
{"op":"mcm","clk":"1001486361","pt":1580636843872,"mc":[{"id":"1.168224027","rc":[{"batb":[[0,1.88,470.89]],"ltp":1.91,"tv":864.01,"id":8908205}]}]}
{"op":"mcm","clk":"1001486609","pt":1580636848170,"mc":[{"id":"1.168224027","rc":[{"batb":[[0,1.89,7.57],[1,1.88,470.89],[2,1.85,74.68]],"ltp":1.91,"tv":864.01,"id":8908205}]}]}
{"op":"mcm","clk":"1001486861","pt":1580636853595,"mc":[{"id":"1.168224027","rc":[{"batb":[[0,1.89,22.72]],"ltp":1.91,"tv":864.01,"id":8908205}]}]}
{"op":"mcm","clk":"1001486994","pt":1580636856489,"mc":[{"id":"1.168224027","rc":[{"batb":[[0,1.88,45.43],[1,1.85,74.68],[2,1.84,7.21]],"ltp":1.91,"tv":864.01,"id":8908205}]}]}
{"op":"mcm","clk":"1001487436","pt":1580636863510,"mc":[{"id":"1.168224027","rc":[{"batb":[[0,1.89,32.78],[1,1.88,470.89]],"ltp":1.91,"tv":864.01,"id":8908205},{"batb":[[1,1.98,83.57]],"ltp":2.12,"tv":256.44,"id":4596961}]}]}
{"op":"mcm","clk":"1001487623","pt":1580636866082,"mc":[{"id":"1.168224027","rc":[{"batb":[[0,1.89,55.5],[1,1.88,45.43]],"ltp":1.91,"tv":864.01,"id":8908205}]}]}
{"op":"mcm","clk":"1001487803","pt":1580636869012,"mc":[{"id":"1.168224027","rc":[{"trd":[[1.89,86.01]],"batb":[[0,1.89,12.49],[1,1.84,7.21],[2,1.83,315.17]],"ltp":1.89,"tv":950.02,"id":8908205}],"tv":1206.46}]}
{"op":"mcm","clk":"1001487839","pt":1580636869883,"mc":[{"id":"1.168224027","rc":[{"batb":[[0,1.89,38.88]],"batl":[[0,1.92,7.45],[1,1.93,12.6],[2,2.28,18.96]],"ltp":1.89,"tv":950.02,"id":8908205},{"batb":[[1,1.99,80.76]],"ltp":2.12,"tv":256.44,"id":4596961}]}]}
{"op":"mcm","clk":"1001487880","pt":1580636870912,"mc":[{"id":"1.168224027","rc":[{"batl":[[0,1.92,20.05],[1,2.28,18.96],[2,2.36,74.21]],"ltp":1.89,"tv":950.02,"id":8908205}]}]}
{"op":"mcm","clk":"1001487910","pt":1580636871479,"mc":[{"id":"1.168224027","rc":[{"batl":[[0,1.92,22.67]],"ltp":1.89,"tv":950.02,"id":8908205}]}]}
{"op":"mcm","clk":"1001488025","pt":1580636873384,"mc":[{"id":"1.168224027","rc":[{"batl":[[0,1.91,10.06],[1,1.92,12.6],[2,2.28,18.96]],"ltp":1.89,"tv":950.02,"id":8908205}]}]}
{"op":"mcm","clk":"1001488069","pt":1580636874306,"mc":[{"id":"1.168224027","rc":[{"trd":[[1.91,428.32]],"batb":[[0,1.91,29.14],[1,1.89,38.88],[2,1.84,7.21]],"batl":[[0,1.92,12.6],[1,2.28,18.96],[2,2.36,74.21]],"ltp":1.91,"tv":970.14,"id":8908205}],"tv":1226.59}]}
{"op":"mcm","clk":"1001488324","pt":1580636878938,"mc":[{"id":"1.168224027","rc":[{"batb":[[0,1.89,38.88],[1,1.84,7.21],[2,1.83,315.17]],"ltp":1.91,"tv":970.14,"id":8908205}]}]}
{"op":"mcm","clk":"1001488466","pt":1580636881815,"mc":[{"id":"1.168224027","rc":[{"batb":[[0,1.89,54.02]],"ltp":1.91,"tv":970.14,"id":8908205}]}]}
{"op":"mcm","clk":"1001488553","pt":1580636883619,"mc":[{"id":"1.168224027","rc":[{"batb":[[0,1.89,26.38]],"ltp":1.91,"tv":970.14,"id":8908205}]}]}
{"op":"mcm","clk":"1001488567","pt":1580636884131,"mc":[{"id":"1.168224027","rc":[{"batb":[[0,1.89,33.95]],"ltp":1.91,"tv":970.14,"id":8908205}]}]}
{"op":"mcm","clk":"1001488631","pt":1580636885312,"mc":[{"id":"1.168224027","rc":[{"batb":[[0,1.89,41.53]],"ltp":1.91,"tv":970.14,"id":8908205}]}]}
{"op":"mcm","clk":"1001488819","pt":1580636888954,"mc":[{"id":"1.168224027","rc":[{"batb":[[0,1.89,26.38]],"ltp":1.91,"tv":970.14,"id":8908205}]}]}
{"op":"mcm","clk":"1001488865","pt":1580636889832,"mc":[{"id":"1.168224027","rc":[{"batb":[[0,1.89,41.53]],"ltp":1.91,"tv":970.14,"id":8908205}]}]}
{"op":"mcm","clk":"1001488953","pt":1580636891939,"mc":[{"id":"1.168224027","rc":[{"batb":[[0,1.89,49.1]],"batl":[[0,1.92,12.85]],"ltp":1.91,"tv":970.14,"id":8908205}]}]}
{"op":"mcm","clk":"1001489725","pt":1580636906957,"mc":[{"id":"1.168224027","rc":[{"trd":[[1.89,174.96]],"batb":[[0,1.89,12.19]],"ltp":1.89,"tv":1059.09,"id":8908205}],"tv":1315.54}]}
{"op":"mcm","clk":"1001489779","pt":1580636907981,"mc":[{"id":"1.168224027","rc":[{"batb":[[1,1.85,68.21],[2,1.84,7.21]],"batl":[[0,1.91,15.24],[1,1.92,12.6],[2,2.28,18.96]],"ltp":1.89,"tv":1059.09,"id":8908205}]}]}
{"op":"mcm","clk":"1001489847","pt":1580636909061,"mc":[{"id":"1.168224027","rc":[{"trd":[[1.91,464.63]],"batb":[[0,1.91,21.05],[1,1.89,12.19],[2,1.85,68.21]],"batl":[[0,1.92,12.6],[1,2.28,18.96],[2,2.36,74.21]],"ltp":1.91,"tv":1095.41,"id":8908205}],"tv":1351.86}]}
{"op":"mcm","clk":"1001489909","pt":1580636910593,"mc":[{"id":"1.168224027","rc":[{"batb":[[1,1.89,19.76]],"ltp":1.91,"tv":1095.41,"id":8908205}]}]}
{"op":"mcm","clk":"1001489957","pt":1580636911369,"mc":[{"id":"1.168224027","rc":[{"batb":[[1,1.89,27.34]],"ltp":1.91,"tv":1095.41,"id":8908205}]}]}
{"op":"mcm","clk":"1001490034","pt":1580636913066,"mc":[{"id":"1.168224027","rc":[{"batb":[[0,1.89,27.34],[1,1.85,68.21],[2,1.84,7.21]],"ltp":1.91,"tv":1095.41,"id":8908205}]}]}
{"op":"mcm","clk":"1001490136","pt":1580636915077,"mc":[{"id":"1.168224027","rc":[{"batb":[[0,1.88,27.34]],"ltp":1.91,"tv":1095.41,"id":8908205}]}]}
{"op":"mcm","clk":"1001490161","pt":1580636915486,"mc":[{"id":"1.168224027","rc":[{"batb":[[0,1.88,452.8]],"ltp":1.91,"tv":1095.41,"id":8908205}]}]}
{"op":"mcm","clk":"1001490315","pt":1580636917968,"mc":[{"id":"1.168224027","rc":[{"batb":[[0,1.89,15.14],[1,1.88,452.8],[2,1.85,68.21]],"ltp":1.91,"tv":1095.41,"id":8908205}]}]}
{"op":"mcm","clk":"1001490422","pt":1580636919501,"mc":[{"id":"1.168224027","rc":[{"batb":[[0,1.89,22.72]],"ltp":1.91,"tv":1095.41,"id":8908205}]}]}
{"op":"mcm","clk":"1001490629","pt":1580636923769,"mc":[{"id":"1.168224027","rc":[{"batb":[[1,1.88,460.37]],"ltp":1.91,"tv":1095.41,"id":8908205}]}]}
{"op":"mcm","clk":"1001490816","pt":1580636927012,"mc":[{"id":"1.168224027","rc":[{"batb":[[0,1.88,34.91],[1,1.85,68.21],[2,1.84,7.21]],"ltp":1.91,"tv":1095.41,"id":8908205}]}]}
{"op":"mcm","clk":"1001490948","pt":1580636929692,"mc":[{"id":"1.168224027","rc":[{"batb":[[0,1.88,460.37]],"ltp":1.91,"tv":1095.41,"id":8908205}]}]}
{"op":"mcm","clk":"1001490997","pt":1580636930577,"mc":[{"id":"1.168224027","rc":[{"batb":[[0,1.88,467.94]],"ltp":1.91,"tv":1095.41,"id":8908205}]}]}
{"op":"mcm","clk":"1001491108","pt":1580636932793,"mc":[{"id":"1.168224027","rc":[{"batb":[[0,1.89,15.14],[1,1.88,42.48],[2,1.85,68.21]],"ltp":1.91,"tv":1095.41,"id":8908205}]}]}
{"op":"mcm","clk":"1001491191","pt":1580636934291,"mc":[{"id":"1.168224027","rc":[{"batb":[[0,1.88,42.48],[1,1.85,68.21],[2,1.84,7.21]],"ltp":1.91,"tv":1095.41,"id":8908205}]}]}
{"op":"mcm","clk":"1001492662","pt":1580636957013,"mc":[{"id":"1.168224027","rc":[{"trd":[[1.88,267.03]],"batb":[[0,1.88,415.93]],"ltp":1.88,"tv":1199.42,"id":8908205}],"tv":1455.87}]}
{"op":"mcm","clk":"1001492716","pt":1580636957741,"mc":[{"id":"1.168224027","rc":[{"batb":[[0,1.88,425.46]],"ltp":1.88,"tv":1199.42,"id":8908205}]}]}
{"op":"mcm","clk":"1001492962","pt":1580636960837,"mc":[{"id":"1.168224027","rc":[{"batl":[[0,1.91,41.8],[1,1.92,12.6],[2,2.28,18.96]],"ltp":1.88,"tv":1199.42,"id":8908205}]}]}
{"op":"mcm","clk":"1001493028","pt":1580636961712,"mc":[{"id":"1.168224027","rc":[{"trd":[[1.91,543.05]],"batl":[[0,1.91,2.59]],"ltp":1.91,"tv":1277.84,"id":8908205}],"tv":1534.28}]}
{"op":"mcm","clk":"1001493148","pt":1580636963064,"mc":[{"id":"1.168224027","rc":[{"batb":[[0,1.86,436.18]],"ltp":1.91,"tv":1277.84,"id":8908205}]}]}
{"op":"mcm","clk":"1001493219","pt":1580636964063,"mc":[{"id":"1.168224027","rc":[{"batl":[[0,1.91,15.19],[1,2.28,18.96],[2,2.36,74.21]],"ltp":1.91,"tv":1277.84,"id":8908205},{"batb":[[2,1.84,282.16]],"ltp":2.12,"tv":256.44,"id":4596961}]}]}
{"op":"mcm","clk":"1001493306","pt":1580636965445,"mc":[{"id":"1.168224027","rc":[{"batb":[[0,1.88,22.72],[1,1.86,436.18],[2,1.85,68.21]],"ltp":1.91,"tv":1277.84,"id":8908205}]}]}
{"op":"mcm","clk":"1001493428","pt":1580636967464,"mc":[{"id":"1.168224027","rc":[{"batb":[[1,1.85,68.21],[2,1.84,7.21]],"ltp":1.91,"tv":1277.84,"id":8908205}]}]}
{"op":"mcm","clk":"1001493693","pt":1580636971441,"mc":[{"id":"1.168224027","rc":[{"trd":[[1.91,557.95]],"batl":[[0,2.28,19.26],[1,2.36,74.21],[2,95,15.9]],"ltp":1.91,"tv":1292.74,"id":8908205},{"trd":[[2.08,37.47]],"batb":[[0,1.99,80.76],[1,1.84,282.16],[2,1.81,37.86]],"ltp":2.08,"tv":293.44,"id":4596961}],"tv":1586.18}]}
{"op":"mcm","clk":"1001493951","pt":1580636975949,"mc":[{"id":"1.168224027","rc":[{"batb":[[0,1.88,30.29]],"ltp":1.91,"tv":1292.74,"id":8908205}]}]}
{"op":"mcm","clk":"1001493961","pt":1580636976155,"mc":[{"id":"1.168224027","rc":[{"batb":[[0,1.88,37.86]],"ltp":1.91,"tv":1292.74,"id":8908205}]}]}
{"op":"mcm","clk":"1001494320","pt":1580636982389,"mc":[{"id":"1.168224027","rc":[{"batb":[[0,1.88,45.43]],"ltp":1.91,"tv":1292.74,"id":8908205}]}]}
{"op":"mcm","clk":"1001494426","pt":1580636983993,"mc":[{"id":"1.168224027","rc":[{"batb":[[0,1.85,68.21],[1,1.84,7.21],[2,1.83,29.61]],"ltp":1.91,"tv":1292.74,"id":8908205}]}]}
{"op":"mcm","clk":"1001494460","pt":1580636984364,"mc":[{"id":"1.168224027","rc":[{"batb":[[0,1.88,7.57],[1,1.85,68.21],[2,1.84,7.21]],"ltp":1.91,"tv":1292.74,"id":8908205}]}]}
{"op":"mcm","clk":"1001494559","pt":1580636985976,"mc":[{"id":"1.168224027","rc":[{"batb":[[0,1.88,15.14]],"ltp":1.91,"tv":1292.74,"id":8908205}]}]}
{"op":"mcm","clk":"1001494576","pt":1580636986187,"mc":[{"id":"1.168224027","rc":[{"batb":[[0,1.88,22.72]],"ltp":1.91,"tv":1292.74,"id":8908205}]}]}
{"op":"mcm","clk":"1001494799","pt":1580636990061,"mc":[{"id":"1.168224027","rc":[{"trd":[[1.88,314.8]],"batb":[[0,1.88,6.4]],"ltp":1.88,"tv":1340.51,"id":8908205}],"tv":1633.95}]}
{"op":"mcm","clk":"1001494833","pt":1580636990690,"mc":[{"id":"1.168224027","rc":[{"batl":[[0,1.91,22.65],[1,2.28,18.96],[2,2.36,74.21]],"ltp":1.88,"tv":1340.51,"id":8908205}]}]}
{"op":"mcm","clk":"1001494897","pt":1580636992189,"mc":[{"id":"1.168224027","rc":[{"batl":[[0,1.91,23.81]],"ltp":1.88,"tv":1340.51,"id":8908205}]}]}
{"op":"mcm","clk":"1001495087","pt":1580636994787,"mc":[{"id":"1.168224027","rc":[{"batb":[[0,1.85,68.21],[1,1.84,7.21],[2,1.83,29.61]],"batl":[[0,2.28,19.26],[1,2.36,74.21],[2,95,15.9]],"ltp":1.88,"tv":1340.51,"id":8908205}]}]}
{"op":"mcm","clk":"1001495184","pt":1580636996103,"mc":[{"id":"1.168224027","rc":[{"batb":[[0,1.88,14.33],[1,1.85,68.21],[2,1.84,7.21]],"batl":[[0,1.9,23.64],[1,2.28,18.96],[2,2.36,74.21]],"ltp":1.88,"tv":1340.51,"id":8908205},{"batl":[[0,2.14,12.6],[1,2.28,18.48],[2,95,15.9]],"ltp":2.08,"tv":293.44,"id":4596961}]}]}
{"op":"mcm","clk":"1001495605","pt":1580637001701,"mc":[{"id":"1.168224027","rc":[{"batl":[[2,4.2,153.72]],"ltp":2.08,"tv":293.44,"id":4596961}]}]}
{"op":"mcm","clk":"1001495747","pt":1580637003721,"mc":[{"id":"1.168224027","rc":[{"batl":[[0,1.92,23.64]],"ltp":1.88,"tv":1340.51,"id":8908205}]}]}
{"op":"mcm","clk":"1001495927","pt":1580637006536,"mc":[{"id":"1.168224027","rc":[{"batl":[[0,1.91,23.64]],"ltp":1.88,"tv":1340.51,"id":8908205}]}]}
{"op":"mcm","clk":"1001496779","pt":1580637020253,"mc":[{"id":"1.168224027","rc":[{"batb":[[0,1.88,17.74]],"ltp":1.88,"tv":1340.51,"id":8908205}]}]}
{"op":"mcm","clk":"1001496893","pt":1580637021851,"mc":[{"id":"1.168224027","rc":[{"batb":[[0,1.88,32.88]],"ltp":1.88,"tv":1340.51,"id":8908205}]}]}
{"op":"mcm","clk":"1001496947","pt":1580637022727,"mc":[{"id":"1.168224027","rc":[{"trd":[[1.88,354.62]],"batb":[[0,1.88,12.97]],"ltp":1.88,"tv":1380.32,"id":8908205}],"tv":1673.77}]}
{"op":"mcm","clk":"1001497030","pt":1580637024161,"mc":[{"id":"1.168224027","rc":[{"batl":[[0,1.89,2.16],[1,1.91,23.64],[2,2.28,18.96]],"ltp":1.88,"tv":1380.32,"id":8908205}]}]}
{"op":"mcm","clk":"1001497136","pt":1580637025923,"mc":[{"id":"1.168224027","rc":[{"batb":[[0,1.88,20.54]],"ltp":1.88,"tv":1380.32,"id":8908205}]}]}
{"op":"mcm","clk":"1001497238","pt":1580637028037,"mc":[{"id":"1.168224027","rc":[{"batb":[[0,1.85,68.21],[1,1.84,7.21],[2,1.83,29.61]],"ltp":1.88,"tv":1380.32,"id":8908205}]}]}
{"op":"mcm","clk":"1001497297","pt":1580637029066,"mc":[{"id":"1.168224027","rc":[{"trd":[[1.88,369.76]],"batb":[[0,1.87,7.57],[1,1.85,68.21],[2,1.84,7.21]],"batl":[[0,1.89,9.69]],"ltp":1.88,"tv":1395.47,"id":8908205}],"tv":1688.91}]}
{"op":"mcm","clk":"1001497549","pt":1580637033372,"mc":[{"id":"1.168224027","rc":[{"batb":[[0,1.86,7.57]],"ltp":1.88,"tv":1395.47,"id":8908205}]}]}
{"op":"mcm","clk":"1001497583","pt":1580637034144,"mc":[{"id":"1.168224027","rc":[{"trd":[[2.14,19.12]],"batl":[[0,2.14,3.04]],"ltp":2.14,"tv":312.56,"id":4596961}],"tv":1708.03}]}
{"op":"mcm","clk":"1001497772","pt":1580637037967,"mc":[{"id":"1.168224027","rc":[{"batb":[[0,1.87,7.57],[1,1.86,7.57],[2,1.85,68.21]],"ltp":1.88,"tv":1395.47,"id":8908205}]}]}
{"op":"mcm","clk":"1001497953","pt":1580637041072,"mc":[{"id":"1.168224027","rc":[{"batb":[[0,1.87,15.14],[1,1.85,68.21],[2,1.84,7.21]],"ltp":1.88,"tv":1395.47,"id":8908205}]}]}
{"op":"mcm","clk":"1001498372","pt":1580637047689,"mc":[{"id":"1.168224027","rc":[{"batl":[[1,1.93,23.64]],"ltp":1.88,"tv":1395.47,"id":8908205}]}]}
{"op":"mcm","clk":"1001498608","pt":1580637051096,"mc":[{"id":"1.168224027","rc":[{"batb":[[0,1.87,22.72]],"batl":[[1,1.9,3.37],[2,1.93,23.64]],"ltp":1.88,"tv":1395.47,"id":8908205}]}]}
{"op":"mcm","clk":"1001499032","pt":1580637058588,"mc":[{"id":"1.168224027","rc":[{"batl":[[0,1.89,20.13]],"ltp":1.88,"tv":1395.47,"id":8908205},{"batl":[[0,2.28,18.48],[1,4.2,153.72],[2,95,15.9]],"ltp":2.14,"tv":312.56,"id":4596961}]}]}
{"op":"mcm","clk":"1001499086","pt":1580637059671,"mc":[{"id":"1.168224027","rc":[{"batb":[[0,1.87,7.57]],"ltp":1.88,"tv":1395.47,"id":8908205}]}]}
{"op":"mcm","clk":"1001499198","pt":1580637061980,"mc":[{"id":"1.168224027","rc":[{"batb":[[0,1.86,7.57]],"ltp":1.88,"tv":1395.47,"id":8908205}]}]}
{"op":"mcm","clk":"1001499383","pt":1580637065114,"mc":[{"id":"1.168224027","rc":[{"batl":[[0,1.89,10.44]],"ltp":1.88,"tv":1395.47,"id":8908205}]}]}
{"op":"mcm","clk":"1001499450","pt":1580637066095,"mc":[{"id":"1.168224027","rc":[{"trd":[[1.88,389.15]],"batb":[[0,1.88,29.71],[1,1.86,7.57],[2,1.85,68.21]],"ltp":1.88,"tv":1414.85,"id":8908205}],"tv":1727.42}]}
{"op":"mcm","clk":"1001499515","pt":1580637067996,"mc":[{"id":"1.168224027","rc":[{"batb":[[1,1.87,15.14],[2,1.86,7.57]],"ltp":1.88,"tv":1414.85,"id":8908205}]}]}
{"op":"mcm","clk":"1001499632","pt":1580637070720,"mc":[{"id":"1.168224027","rc":[{"batb":[[0,1.87,15.14],[1,1.86,7.57],[2,1.85,68.21]],"ltp":1.88,"tv":1414.85,"id":8908205}]}]}
{"op":"mcm","clk":"1001499744","pt":1580637072621,"mc":[{"id":"1.168224027","rc":[{"batb":[[0,1.87,22.72]],"ltp":1.88,"tv":1414.85,"id":8908205}]}]}
{"op":"mcm","clk":"1001499899","pt":1580637075709,"mc":[{"id":"1.168224027","rc":[{"batb":[[1,1.85,68.21],[2,1.84,7.21]],"ltp":1.88,"tv":1414.85,"id":8908205}]}]}
{"op":"mcm","clk":"1001500038","pt":1580637078533,"mc":[{"id":"1.168224027","rc":[{"batb":[[0,1.86,22.72]],"ltp":1.88,"tv":1414.85,"id":8908205}]}]}
{"op":"mcm","clk":"1001500542","pt":1580637089423,"mc":[{"id":"1.168224027","rc":[{"batb":[[0,2.12,11.25],[1,1.99,80.76],[2,1.84,282.16]],"ltp":2.14,"tv":312.56,"id":4596961}]}]}
{"op":"mcm","clk":"1001501648","pt":1580637112189,"mc":[{"id":"1.168224027","rc":[{"batl":[[0,2.16,10],[1,2.28,18.48],[2,4.2,153.72]],"ltp":2.14,"tv":312.56,"id":4596961}]}]}
{"op":"mcm","clk":"1001502177","pt":1580637122009,"mc":[{"id":"1.168224027","rc":[{"trd":[[1.89,195.83]],"batl":[[0,1.9,3.37],[1,1.93,23.64],[2,2.28,18.96]],"ltp":1.89,"tv":1435.72,"id":8908205},{"trd":[[2.12,121.18]],"batb":[[0,1.99,80.76],[1,1.84,282.16],[2,1.81,37.86]],"ltp":2.12,"tv":335.06,"id":4596961}],"tv":1770.79}]}
{"op":"mcm","clk":"1001502203","pt":1580637122422,"mc":[{"id":"1.168224027","rc":[{"batb":[[0,1.87,23.8],[1,1.86,22.72]],"ltp":1.89,"tv":1435.72,"id":8908205},{"batb":[[0,2.08,28.73]],"ltp":2.12,"tv":335.06,"id":4596961}]}]}
{"op":"mcm","clk":"1001502470","pt":1580637127623,"mc":[{"id":"1.168224027","rc":[{"batb":[[1,1.84,7.21],[2,1.83,29.61]],"batl":[[1,2.28,18.96],[2,2.36,74.21]],"ltp":1.89,"tv":1435.72,"id":8908205}]}]}
{"op":"mcm","clk":"1001502545","pt":1580637128908,"mc":[{"id":"1.168224027","rc":[{"batl":[[0,1.9,27.06]],"ltp":1.89,"tv":1435.72,"id":8908205}]}]}
{"op":"mcm","clk":"1001503909","pt":1580637151924,"mc":[{"id":"1.168224027","rc":[{"batb":[[0,1.87,38.29]],"ltp":1.89,"tv":1435.72,"id":8908205},{"batl":[[0,2.16,22.6]],"ltp":2.12,"tv":335.06,"id":4596961}]}]}
{"op":"mcm","clk":"1001504961","pt":1580637170655,"mc":[{"id":"1.168224027","rc":[{"batb":[[0,1.88,7.57],[1,1.87,38.29],[2,1.84,7.21]],"ltp":1.89,"tv":1435.72,"id":8908205}]}]}
{"op":"mcm","clk":"1001505115","pt":1580637173650,"mc":[{"id":"1.168224027","rc":[{"batb":[[0,1.87,38.29],[1,1.84,7.21],[2,1.83,29.61]],"ltp":1.89,"tv":1435.72,"id":8908205}]}]}
{"op":"mcm","clk":"1001505370","pt":1580637177063,"mc":[{"id":"1.168224027","rc":[{"batl":[[0,1.9,3.37]],"ltp":1.89,"tv":1435.72,"id":8908205}]}]}
{"op":"mcm","clk":"1001505705","pt":1580637182878,"mc":[{"id":"1.168224027","rc":[{"batb":[[0,1.88,7.57],[1,1.87,38.29],[2,1.84,7.21]],"ltp":1.89,"tv":1435.72,"id":8908205}]}]}
{"op":"mcm","clk":"1001505775","pt":1580637183865,"mc":[{"id":"1.168224027","rc":[{"trd":[[1.88,400.35]],"batb":[[0,1.88,1.97]],"batl":[[0,1.89,5.57],[1,1.9,3.37],[2,2.28,18.96]],"ltp":1.88,"tv":1446.93,"id":8908205}],"tv":1781.99}]}
{"op":"mcm","clk":"1001505925","pt":1580637186590,"mc":[{"id":"1.168224027","rc":[{"batb":[[0,1.87,38.29],[1,1.84,7.21],[2,1.83,29.61]],"ltp":1.88,"tv":1446.93,"id":8908205}]}]}
{"op":"mcm","clk":"1001505982","pt":1580637187678,"mc":[{"id":"1.168224027","rc":[{"batl":[[1,1.9,10.94]],"ltp":1.88,"tv":1446.93,"id":8908205}]}]}
{"op":"mcm","clk":"1001506015","pt":1580637188294,"mc":[{"id":"1.168224027","rc":[{"batl":[[2,1.92,7.57]],"ltp":1.88,"tv":1446.93,"id":8908205}]}]}
{"op":"mcm","clk":"1001506211","pt":1580637191785,"mc":[{"id":"1.168224027","rc":[{"batb":[[0,1.87,45.86]],"ltp":1.88,"tv":1446.93,"id":8908205}]}]}
{"op":"mcm","clk":"1001507823","pt":1580637222881,"mc":[{"id":"1.168224027","rc":[{"batl":[[1,1.9,3.37],[2,1.92,15.14]],"ltp":1.88,"tv":1446.93,"id":8908205}]}]}
{"op":"mcm","clk":"1001509354","pt":1580637251917,"mc":[{"id":"1.168224027","rc":[{"batb":[[0,2.02,76.37]],"ltp":2.12,"tv":335.06,"id":4596961}]}]}
{"op":"mcm","clk":"1001510957","pt":1580637283944,"mc":[{"id":"1.168224027","rc":[{"batl":[[0,1.9,8.94],[1,1.92,15.14],[2,2.28,18.96]],"ltp":1.88,"tv":1446.93,"id":8908205}]}]}
{"op":"mcm","clk":"1001511143","pt":1580637287042,"mc":[{"id":"1.168224027","rc":[{"batl":[[0,1.9,3.37]],"ltp":1.88,"tv":1446.93,"id":8908205}]}]}
{"op":"mcm","clk":"1001511150","pt":1580637287144,"mc":[{"id":"1.168224027","rc":[{"batl":[[0,1.89,5.57],[1,1.9,3.37],[2,1.92,15.14]],"ltp":1.88,"tv":1446.93,"id":8908205}]}]}
{"op":"mcm","clk":"1001512038","pt":1580637304486,"mc":[{"id":"1.168224027","rc":[{"batl":[[0,1.9,8.94],[1,1.92,15.14],[2,2.28,18.96]],"ltp":1.88,"tv":1446.93,"id":8908205}]}]}
{"op":"mcm","clk":"1001512209","pt":1580637307888,"mc":[{"id":"1.168224027","rc":[{"batl":[[1,1.97,15.14]],"ltp":1.88,"tv":1446.93,"id":8908205}]}]}
{"op":"mcm","clk":"1001512504","pt":1580637312327,"mc":[{"id":"1.168224027","rc":[{"batl":[[0,1.89,5.57],[1,1.9,3.37],[2,1.97,15.14]],"ltp":1.88,"tv":1446.93,"id":8908205}]}]}
{"op":"mcm","clk":"1001513292","pt":1580637328540,"mc":[{"id":"1.168224027","rc":[{"batb":[[0,1.87,38.29]],"ltp":1.88,"tv":1446.93,"id":8908205}]}]}
{"op":"mcm","clk":"1001513455","pt":1580637332110,"mc":[{"id":"1.168224027","rc":[{"batl":[[1,1.9,10.94]],"ltp":1.88,"tv":1446.93,"id":8908205}]}]}
{"op":"mcm","clk":"1001543883","pt":1580637761971,"mc":[{"id":"1.168224027","rc":[{"batb":[[2,1.83,49.98]],"ltp":2.12,"tv":335.06,"id":4596961}]}]}
{"op":"mcm","clk":"1001544628","pt":1580637770880,"mc":[{"id":"1.168224027","rc":[{"batl":[[1,1.9,3.37]],"ltp":1.88,"tv":1446.93,"id":8908205}]}]}
{"op":"mcm","clk":"1001544705","pt":1580637771666,"mc":[{"id":"1.168224027","rc":[{"batb":[[0,1.87,38.51]],"ltp":1.88,"tv":1446.93,"id":8908205}]}]}
{"op":"mcm","clk":"1001544827","pt":1580637773266,"mc":[{"id":"1.168224027","rc":[{"batl":[[0,1.9,8.94],[1,1.97,15.14],[2,2.28,18.96]],"ltp":1.88,"tv":1446.93,"id":8908205}]}]}
{"op":"mcm","clk":"1001570686","pt":1580638071064,"mc":[{"id":"1.168224027","rc":[{"trd":[[2.12,121.53]],"ltp":2.12,"tv":335.4,"id":4596961}],"tv":1782.33}]}
{"op":"mcm","clk":"1001590693","pt":1580638293914,"mc":[{"id":"1.168224027","rc":[{"batl":[[0,1.9,3.37],[1,2.28,18.96],[2,2.36,74.21]],"ltp":1.88,"tv":1446.93,"id":8908205}]}]}
{"op":"mcm","clk":"1001590821","pt":1580638295107,"mc":[{"id":"1.168224027","rc":[{"batl":[[0,1.89,29.4],[1,1.9,3.37],[2,2.28,18.96]],"ltp":1.88,"tv":1446.93,"id":8908205}]}]}
{"op":"mcm","clk":"1001590943","pt":1580638296514,"mc":[{"id":"1.168224027","rc":[{"batl":[[0,1.9,3.37],[1,2.28,18.96],[2,2.36,74.21]],"ltp":1.88,"tv":1446.93,"id":8908205}]}]}
{"op":"mcm","clk":"1001591091","pt":1580638298117,"mc":[{"id":"1.168224027","rc":[{"batl":[[0,1.89,7.57],[1,1.9,3.37],[2,2.28,18.96]],"ltp":1.88,"tv":1446.93,"id":8908205}]}]}
{"op":"mcm","clk":"1001592158","pt":1580638306843,"mc":[{"id":"1.168224027","rc":[{"batl":[[0,1.9,3.37],[1,2.28,18.96],[2,2.36,74.21]],"ltp":1.88,"tv":1446.93,"id":8908205}]}]}
{"op":"mcm","clk":"1001592577","pt":1580638310311,"mc":[{"id":"1.168224027","rc":[{"trd":[[1.88,400.8]],"batb":[[0,1.87,38.29]],"batl":[[0,1.88,7.35],[1,1.9,3.37],[2,2.28,18.96]],"ltp":1.88,"tv":1447.38,"id":8908205}],"tv":1782.79}]}
{"op":"mcm","clk":"1001592775","pt":1580638311830,"mc":[{"id":"1.168224027","rc":[{"trd":[[1.88,415.5]],"batb":[[0,1.88,32.06],[1,1.87,45.67],[2,1.84,7.21]],"batl":[[0,1.9,3.37],[1,2.28,18.96],[2,2.36,74.21]],"ltp":1.88,"tv":1462.07,"id":8908205}],"tv":1797.48}]}
{"op":"mcm","clk":"1001592869","pt":1580638312709,"mc":[{"id":"1.168224027","rc":[{"batb":[[1,1.87,45.9]],"ltp":1.88,"tv":1462.07,"id":8908205}]}]}
{"op":"mcm","clk":"1001593008","pt":1580638314110,"mc":[{"id":"1.168224027","rc":[{"trd":[[1.88,430.64]],"batb":[[0,1.88,24.48]],"ltp":1.88,"tv":1477.22,"id":8908205}],"tv":1812.62}]}
{"op":"mcm","clk":"1001593067","pt":1580638314734,"mc":[{"id":"1.168224027","rc":[{"batb":[[1,1.87,53.51]],"ltp":1.88,"tv":1477.22,"id":8908205}]}]}
{"op":"mcm","clk":"1001593203","pt":1580638315878,"mc":[{"id":"1.168224027","rc":[{"batb":[[0,1.87,38.29],[1,1.84,7.21],[2,1.83,29.61]],"ltp":1.88,"tv":1477.22,"id":8908205}]}]}
{"op":"mcm","clk":"1001593615","pt":1580638318948,"mc":[{"id":"1.168224027","rc":[{"batl":[[0,1.89,7.57],[1,1.9,3.37],[2,2.28,18.96]],"ltp":1.88,"tv":1477.22,"id":8908205}]}]}
{"op":"mcm","clk":"1001594366","pt":1580638324763,"mc":[{"id":"1.168224027","rc":[{"batl":[[0,1.9,10.94],[1,2.28,18.96],[2,2.36,74.21]],"ltp":1.88,"tv":1477.22,"id":8908205}]}]}
{"op":"mcm","clk":"1001601844","pt":1580638393096,"mc":[{"id":"1.168224027","rc":[{"trd":[[1.9,102.06]],"batl":[[0,2.28,18.96],[1,2.36,74.21],[2,4.2,153.72]],"ltp":1.9,"tv":1488.16,"id":8908205},{"trd":[[2.02,177.49],[2.1,28.84]],"batb":[[0,1.84,282.16],[1,1.83,49.98],[2,1.81,37.86]],"ltp":2.02,"tv":498.05,"id":4596961}],"tv":1986.21}]}
{"op":"mcm","clk":"1001601925","pt":1580638393978,"mc":[{"id":"1.168224027","rc":[{"batb":[[0,1.89,93.83],[1,1.87,14.48],[2,1.84,7.21]],"ltp":1.9,"tv":1488.16,"id":8908205},{"batb":[[0,1.93,78.36],[1,1.84,282.16],[2,1.83,49.98]],"ltp":2.02,"tv":498.05,"id":4596961}]}]}
{"op":"mcm","clk":"1001602224","pt":1580638396998,"mc":[{"id":"1.168224027","rc":[{"batb":[[0,1.9,8.17],[1,1.89,93.83],[2,1.87,14.48]],"ltp":1.9,"tv":1488.16,"id":8908205},{"batl":[[0,2.1,2.93],[1,2.16,22.6],[2,2.28,18.48]],"ltp":2.02,"tv":498.05,"id":4596961}]}]}
{"op":"mcm","clk":"1001602699","pt":1580638402008,"mc":[{"id":"1.168224027","rc":[{"batb":[[0,1.94,48.33],[1,1.93,78.36],[2,1.84,282.16]],"ltp":2.02,"tv":498.05,"id":4596961}]}]}
{"op":"mcm","clk":"1001602950","pt":1580638404806,"mc":[{"id":"1.168224027","rc":[{"batb":[[2,1.85,106.89]],"ltp":2.02,"tv":498.05,"id":4596961}]}]}
{"op":"mcm","clk":"1001604324","pt":1580638418030,"mc":[{"id":"1.168224027","rc":[{"batb":[[0,1.93,78.36],[1,1.85,106.89],[2,1.84,282.16]],"ltp":2.02,"tv":498.05,"id":4596961}]}]}
{"op":"mcm","clk":"1001604448","pt":1580638419120,"mc":[{"id":"1.168224027","rc":[{"batb":[[0,1.9,11.5],[2,1.84,7.21]],"ltp":1.9,"tv":1488.16,"id":8908205},{"batl":[[1,2.16,10]],"ltp":2.02,"tv":498.05,"id":4596961}]}]}
{"op":"mcm","clk":"1001604503","pt":1580638419642,"mc":[{"id":"1.168224027","rc":[{"batb":[[0,1.9,25.51]],"ltp":1.9,"tv":1488.16,"id":8908205},{"batl":[[0,2.1,15.53]],"ltp":2.02,"tv":498.05,"id":4596961}]}]}
{"op":"mcm","clk":"1001617200","pt":1580638534608,"mc":[{"id":"1.168224027","rc":[{"batb":[[0,1.92,7.21],[1,1.9,25.51],[2,1.89,93.83]],"ltp":1.9,"tv":1488.16,"id":8908205},{"trd":[[2.1,53.62]],"batl":[[0,2.1,3.14]],"ltp":2.1,"tv":522.83,"id":4596961}],"tv":2010.99}]}
{"op":"mcm","clk":"1001618089","pt":1580638542606,"mc":[{"id":"1.168224027","rc":[{"batb":[[1,1.9,22.18]],"ltp":1.9,"tv":1488.16,"id":8908205}]}]}
{"op":"mcm","clk":"1001618214","pt":1580638543909,"mc":[{"id":"1.168224027","rc":[{"batb":[[1,1.9,8.17]],"ltp":1.9,"tv":1488.16,"id":8908205}]}]}
{"op":"mcm","clk":"1001619350","pt":1580638554956,"mc":[{"id":"1.168224027","rc":[{"batb":[[2,1.89,7.61]],"ltp":1.9,"tv":1488.16,"id":8908205}]}]}
{"op":"mcm","clk":"1001619375","pt":1580638555165,"mc":[{"id":"1.168224027","rc":[{"batb":[[0,1.93,46.83],[1,1.92,7.21],[2,1.9,8.17]],"ltp":1.9,"tv":1488.16,"id":8908205}]}]}
{"op":"mcm","clk":"1001621465","pt":1580638575073,"mc":[{"id":"1.168224027","rc":[{"batl":[[0,2.16,10],[1,2.28,18.48],[2,4.2,153.72]],"ltp":2.1,"tv":522.83,"id":4596961}]}]}
{"op":"mcm","clk":"1001621517","pt":1580638575591,"mc":[{"id":"1.168224027","rc":[{"trd":[[1.93,101.89]],"batb":[[0,1.93,8.79]],"ltp":1.93,"tv":1564.24,"id":8908205}],"tv":2087.08}]}
{"op":"mcm","clk":"1001621661","pt":1580638577057,"mc":[{"id":"1.168224027","rc":[{"batb":[[0,1.92,7.21],[1,1.9,8.17],[2,1.89,7.61]],"ltp":1.93,"tv":1564.24,"id":8908205},{"batb":[[0,1.85,106.89],[1,1.84,282.16],[2,1.83,49.98]],"ltp":2.1,"tv":522.83,"id":4596961}]}]}
{"op":"mcm","clk":"1001621671","pt":1580638577214,"mc":[{"id":"1.168224027","rc":[{"batb":[[1,1.9,46.21]],"ltp":1.93,"tv":1564.24,"id":8908205},{"batb":[[0,1.97,78.07],[1,1.85,106.89],[2,1.84,282.16]],"ltp":2.1,"tv":522.83,"id":4596961}]}]}
{"op":"mcm","clk":"1001622115","pt":1580638581579,"mc":[{"id":"1.168224027","rc":[{"trd":[[1.92,26.65]],"batb":[[0,1.92,1.42]],"ltp":1.92,"tv":1575.83,"id":8908205}],"tv":2098.66}]}
{"op":"mcm","clk":"1001624453","pt":1580638604485,"mc":[{"id":"1.168224027","rc":[{"batb":[[0,1.92,4.68]],"ltp":1.92,"tv":1575.83,"id":8908205}]}]}
{"op":"mcm","clk":"1001659879","pt":1580639004783,"mc":[{"id":"1.168224027","rc":[{"batb":[[0,1.97,86.73]],"batl":[[0,2.1,8.4],[1,2.16,10],[2,2.28,18.48]],"ltp":2.1,"tv":522.83,"id":4596961}]}]}
{"op":"mcm","clk":"1001667246","pt":1580639066984,"mc":[{"id":"1.168224027","rc":[{"batl":[[0,2.02,8.88],[1,2.28,18.48],[2,2.36,74.21]],"ltp":1.92,"tv":1575.83,"id":8908205}]}]}
{"op":"mcm","clk":"1001667384","pt":1580639068030,"mc":[{"id":"1.168224027","rc":[{"batb":[[0,1.92,13.81]],"ltp":1.92,"tv":1575.83,"id":8908205},{"trd":[[2.1,66.98]],"batl":[[0,2.1,1.72]],"ltp":2.1,"tv":536.19,"id":4596961}],"tv":2112.02}]}
{"op":"mcm","clk":"1001668666","pt":1580639080398,"mc":[{"id":"1.168224027","rc":[{"batb":[[0,1.99,60.39],[1,1.97,8.66],[2,1.85,106.89]],"ltp":2.1,"tv":536.19,"id":4596961}]}]}
{"op":"mcm","clk":"1001670517","pt":1580639099083,"mc":[{"id":"1.168224027","rc":[{"trd":[[1.92,48.39]],"batb":[[0,1.92,2.94]],"ltp":1.92,"tv":1597.56,"id":8908205},{"batb":[[0,1.99,68.88],[1,1.85,106.89],[2,1.84,282.16]],"ltp":2.1,"tv":536.19,"id":4596961}],"tv":2133.76}]}
{"op":"mcm","clk":"1001670632","pt":1580639100067,"mc":[{"id":"1.168224027","rc":[{"batl":[[0,1.94,3.23],[1,2.02,8.88],[2,2.28,18.48]],"ltp":1.92,"tv":1597.56,"id":8908205}]}]}
{"op":"mcm","clk":"1001670642","pt":1580639100171,"mc":[{"id":"1.168224027","rc":[{"trd":[[1.94,6.46]],"batl":[[0,2.02,8.88],[1,2.28,18.48],[2,2.36,74.21]],"ltp":1.94,"tv":1604.02,"id":8908205}],"tv":2140.22}]}
{"op":"mcm","clk":"1001673766","pt":1580639130767,"mc":[{"id":"1.168224027","rc":[{"batb":[[0,1.9,46.21],[1,1.89,7.61],[2,1.83,29.61]],"ltp":1.94,"tv":1604.02,"id":8908205},{"batl":[[0,2.16,10],[1,2.28,18.48],[2,4.2,153.72]],"ltp":2.1,"tv":536.19,"id":4596961}]}]}
{"op":"mcm","clk":"1001678212","pt":1580639169949,"mc":[{"id":"1.168224027","rc":[{"trd":[[1.9,179.12]],"batb":[[0,1.89,7.61],[1,1.87,38.29]],"ltp":1.9,"tv":1681.08,"id":8908205},{"batb":[[0,2,80.05],[1,1.99,8.49],[2,1.85,106.89]],"ltp":2.1,"tv":536.19,"id":4596961}],"tv":2217.27}]}
{"op":"mcm","clk":"1001681146","pt":1580639193004,"mc":[{"id":"1.168224027","rc":[{"batl":[[0,2.28,18.96],[1,2.36,74.21],[2,4.2,153.72]],"ltp":1.9,"tv":1681.08,"id":8908205},{"batb":[[1,1.85,106.89],[2,1.84,282.16]],"ltp":2.1,"tv":536.19,"id":4596961}]}]}
{"op":"mcm","clk":"1001681248","pt":1580639193582,"mc":[{"id":"1.168224027","rc":[{"batl":[[0,2,13.08],[1,2.28,18.48],[2,2.36,74.21]],"ltp":1.9,"tv":1681.08,"id":8908205},{"batb":[[0,2,92.66]],"ltp":2.1,"tv":536.19,"id":4596961}]}]}
{"op":"mcm","clk":"1001695821","pt":1580639317576,"mc":[{"id":"1.168224027","rc":[{"batb":[[0,1.87,38.29],[1,1.83,29.61],[2,1.81,292.61]],"ltp":1.9,"tv":1681.08,"id":8908205}]}]}
{"op":"mcm","clk":"1001695944","pt":1580639318754,"mc":[{"id":"1.168224027","rc":[{"batl":[[0,1.99,6.38],[1,2,13.08],[2,2.28,18.48]],"ltp":1.9,"tv":1681.08,"id":8908205}]}]}
{"op":"mcm","clk":"1001696272","pt":1580639321874,"mc":[{"id":"1.168224027","rc":[{"batb":[[0,1.88,7.57],[1,1.87,38.29],[2,1.83,29.61]],"ltp":1.9,"tv":1681.08,"id":8908205}]}]}
{"op":"mcm","clk":"1001699272","pt":1580639346506,"mc":[{"id":"1.168224027","rc":[{"batb":[[1,1.84,282.16],[2,1.83,49.98]],"ltp":2.1,"tv":536.19,"id":4596961}]}]}
{"op":"mcm","clk":"1001699536","pt":1580639348810,"mc":[{"id":"1.168224027","rc":[{"batl":[[0,1.99,18.99],[1,2.28,18.96],[2,2.36,74.21]],"ltp":1.9,"tv":1681.08,"id":8908205}]}]}
{"op":"mcm","clk":"1001699700","pt":1580639350086,"mc":[{"id":"1.168224027","rc":[{"trd":[[1.88,442.4]],"batb":[[0,1.88,1.69]],"batl":[[0,1.89,5.85],[1,1.99,18.99],[2,2.28,18.96]],"ltp":1.88,"tv":1692.84,"id":8908205}],"tv":2229.04}]}
{"op":"mcm","clk":"1001699714","pt":1580639350194,"mc":[{"id":"1.168224027","rc":[{"trd":[[1.89,200.27]],"batl":[[0,1.89,3.63]],"ltp":1.89,"tv":1697.28,"id":8908205}],"tv":2233.48}]}
{"op":"mcm","clk":"1001700441","pt":1580639356493,"mc":[{"id":"1.168224027","rc":[{"batl":[[0,1.93,3.63]],"ltp":1.89,"tv":1697.28,"id":8908205}]}]}
{"op":"mcm","clk":"1001701530","pt":1580639365645,"mc":[{"id":"1.168224027","rc":[{"batb":[[0,1.88,9.26]],"ltp":1.89,"tv":1697.28,"id":8908205}]}]}
{"op":"mcm","clk":"1001701789","pt":1580639367955,"mc":[{"id":"1.168224027","rc":[{"batb":[[0,1.87,38.29],[1,1.83,29.61],[2,1.81,292.61]],"ltp":1.89,"tv":1697.28,"id":8908205}]}]}
{"op":"mcm","clk":"1001701961","pt":1580639369120,"mc":[{"id":"1.168224027","rc":[{"batb":[[0,1.88,7.57],[1,1.87,38.29],[2,1.83,29.61]],"ltp":1.89,"tv":1697.28,"id":8908205}]}]}
{"op":"mcm","clk":"1001702249","pt":1580639371769,"mc":[{"id":"1.168224027","rc":[{"batb":[[0,1.87,38.29],[1,1.83,29.61],[2,1.81,292.61]],"batl":[[0,1.99,12.6],[1,2.28,18.96],[2,2.36,74.21]],"ltp":1.89,"tv":1697.28,"id":8908205}]}]}
{"op":"mcm","clk":"1001702372","pt":1580639372813,"mc":[{"id":"1.168224027","rc":[{"batb":[[0,1.88,7.57],[1,1.87,38.29],[2,1.83,29.61]],"batl":[[0,1.93,10.14],[1,1.99,12.6],[2,2.28,18.96]],"ltp":1.89,"tv":1697.28,"id":8908205}]}]}
{"op":"mcm","clk":"1001702822","pt":1580639376857,"mc":[{"id":"1.168224027","rc":[{"batl":[[0,1.98,10.14]],"ltp":1.89,"tv":1697.28,"id":8908205}]}]}
{"op":"mcm","clk":"1001703194","pt":1580639379956,"mc":[{"id":"1.168224027","rc":[{"batl":[[1,2.28,18.96],[2,2.36,74.21]],"ltp":1.89,"tv":1697.28,"id":8908205}]}]}
{"op":"mcm","clk":"1001703325","pt":1580639381059,"mc":[{"id":"1.168224027","rc":[{"trd":[[1.88,454.17]],"batb":[[0,1.88,1.69]],"batl":[[0,1.89,5.85],[1,1.98,22.74],[2,2.28,18.96]],"ltp":1.88,"tv":1709.05,"id":8908205},{"batb":[[0,2.02,12.36],[1,2,80.05],[2,1.84,282.16]],"ltp":2.1,"tv":536.19,"id":4596961}],"tv":2245.24}]}
{"op":"mcm","clk":"1001703886","pt":1580639385548,"mc":[{"id":"1.168224027","rc":[{"batl":[[0,1.92,5.85]],"ltp":1.88,"tv":1709.05,"id":8908205}]}]}
{"op":"mcm","clk":"1001704111","pt":1580639387226,"mc":[{"id":"1.168224027","rc":[{"batb":[[0,1.87,39.98],[1,1.83,29.61],[2,1.81,292.61]],"ltp":1.88,"tv":1709.05,"id":8908205}]}]}
{"op":"mcm","clk":"1001704587","pt":1580639391851,"mc":[{"id":"1.168224027","rc":[{"batl":[[1,1.95,10.14],[2,1.98,12.6]],"ltp":1.88,"tv":1709.05,"id":8908205}]}]}
{"op":"mcm","clk":"1001707089","pt":1580639412893,"mc":[{"id":"1.168224027","rc":[{"batl":[[0,1.92,18.46],[2,2.28,18.96]],"ltp":1.88,"tv":1709.05,"id":8908205},{"batb":[[0,2,80.05],[1,1.84,282.16],[2,1.83,49.98]],"ltp":2.1,"tv":536.19,"id":4596961}]}]}
{"op":"mcm","clk":"1001707138","pt":1580639413165,"mc":[{"id":"1.168224027","rc":[{"batb":[[0,2.08,11.67],[1,2,80.05],[2,1.84,282.16]],"ltp":2.1,"tv":536.19,"id":4596961}]}]}
{"op":"mcm","clk":"1001717788","pt":1580639509799,"mc":[{"id":"1.168224027","rc":[{"batl":[[0,1.91,5.85],[1,1.92,12.6],[2,1.95,10.14]],"ltp":1.88,"tv":1709.05,"id":8908205}]}]}
{"op":"mcm","clk":"1001718426","pt":1580639516314,"mc":[{"id":"1.168224027","rc":[{"batl":[[0,1.91,15.99],[2,2.28,18.96]],"ltp":1.88,"tv":1709.05,"id":8908205}]}]}
{"op":"mcm","clk":"1001718671","pt":1580639517727,"mc":[{"id":"1.168224027","rc":[{"batb":[[0,1.87,38.29]],"batl":[[0,1.91,10.14]],"ltp":1.88,"tv":1709.05,"id":8908205}]}]}
{"op":"mcm","clk":"1001718863","pt":1580639518818,"mc":[{"id":"1.168224027","rc":[{"batl":[[0,1.91,26.17]],"ltp":1.88,"tv":1709.05,"id":8908205}]}]}
{"op":"mcm","clk":"1001719061","pt":1580639520221,"mc":[{"id":"1.168224027","rc":[{"batl":[[0,1.92,12.6],[1,2.28,18.96],[2,2.36,74.21]],"ltp":1.88,"tv":1709.05,"id":8908205}]}]}
{"op":"mcm","clk":"1001719270","pt":1580639521908,"mc":[{"id":"1.168224027","rc":[{"batl":[[0,1.91,16.03],[1,1.92,12.6],[2,2.28,18.96]],"ltp":1.88,"tv":1709.05,"id":8908205}]}]}
{"op":"mcm","clk":"1001720734","pt":1580639536847,"mc":[{"id":"1.168224027","rc":[{"batl":[[0,1.91,28.63],[1,2.28,18.96],[2,2.36,74.21]],"ltp":1.88,"tv":1709.05,"id":8908205}]}]}
{"op":"mcm","clk":"1001727198","pt":1580639595195,"mc":[{"id":"1.168224027","rc":[{"batl":[[0,1.91,12.6]],"ltp":1.88,"tv":1709.05,"id":8908205}]}]}
{"op":"mcm","clk":"1001727302","pt":1580639596301,"mc":[{"id":"1.168224027","rc":[{"batl":[[0,1.9,16.12],[1,1.91,12.6],[2,2.28,18.96]],"ltp":1.88,"tv":1709.05,"id":8908205}]}]}
{"op":"mcm","clk":"1001727564","pt":1580639599021,"mc":[{"id":"1.168224027","rc":[{"batl":[[0,1.9,28.72],[1,2.28,18.96],[2,2.36,74.21]],"ltp":1.88,"tv":1709.05,"id":8908205},{"batb":[[0,2,80.05],[1,1.84,282.16],[2,1.83,49.98]],"ltp":2.1,"tv":536.19,"id":4596961}]}]}
{"op":"mcm","clk":"1001727587","pt":1580639599227,"mc":[{"id":"1.168224027","rc":[{"batb":[[0,2.1,11.46],[1,2,80.05],[2,1.84,282.16]],"ltp":2.1,"tv":536.19,"id":4596961}]}]}
{"op":"mcm","clk":"1001727979","pt":1580639603296,"mc":[{"id":"1.168224027","rc":[{"batl":[[0,1.9,12.6],[1,1.95,16.12],[2,2.28,18.96]],"ltp":1.88,"tv":1709.05,"id":8908205}]}]}
{"op":"mcm","clk":"1001734371","pt":1580639671987,"mc":[{"id":"1.168224027","rc":[{"batl":[[1,2.28,18.96],[2,2.36,74.21]],"ltp":1.88,"tv":1709.05,"id":8908205}]}]}
{"op":"mcm","clk":"1001734474","pt":1580639673196,"mc":[{"id":"1.168224027","rc":[{"batl":[[0,1.89,16.2],[1,1.9,12.6],[2,2.28,18.96]],"ltp":1.88,"tv":1709.05,"id":8908205}]}]}
{"op":"mcm","clk":"1001736553","pt":1580639692865,"mc":[{"id":"1.168224027","rc":[{"batl":[[0,1.89,28.81],[1,2.28,18.96],[2,2.36,74.21]],"ltp":1.88,"tv":1709.05,"id":8908205},{"batb":[[0,2,80.05],[1,1.84,282.16],[2,1.83,49.98]],"ltp":2.1,"tv":536.19,"id":4596961}]}]}
{"op":"mcm","clk":"1001736581","pt":1580639693174,"mc":[{"id":"1.168224027","rc":[{"batb":[[0,2.12,11.25],[1,2,80.05],[2,1.84,282.16]],"ltp":2.1,"tv":536.19,"id":4596961}]}]}
{"op":"mcm","clk":"1001736841","pt":1580639695583,"mc":[{"id":"1.168224027","rc":[{"batl":[[0,1.89,12.6]],"ltp":1.88,"tv":1709.05,"id":8908205}]}]}
{"op":"mcm","clk":"1001736986","pt":1580639696948,"mc":[{"id":"1.168224027","rc":[{"batl":[[1,1.95,15.7],[2,2.28,18.96]],"ltp":1.88,"tv":1709.05,"id":8908205}]}]}
{"op":"mcm","clk":"1001738618","pt":1580639710983,"mc":[{"id":"1.168224027","rc":[{"trd":[[1.89,225.47]],"batb":[[0,1.84,55.36]],"batl":[[0,1.95,15.7],[1,2.28,18.96],[2,2.36,74.21]],"ltp":1.89,"tv":1734.25,"id":8908205},{"trd":[[2.12,125.8]],"batb":[[0,2.12,9.12],[1,2.06,44.58]],"ltp":2.12,"tv":540.46,"id":4596961}],"tv":2274.71}]}
{"op":"mcm","clk":"1001739241","pt":1580639716918,"mc":[{"id":"1.168224027","rc":[{"batl":[[0,1.9,7.57],[1,1.95,15.7],[2,2.28,18.96]],"ltp":1.89,"tv":1734.25,"id":8908205}]}]}
{"op":"mcm","clk":"1001743286","pt":1580639755691,"mc":[{"id":"1.168224027","rc":[{"batb":[[0,2.06,44.58],[1,1.84,282.16],[2,1.83,49.98]],"ltp":2.12,"tv":540.46,"id":4596961}]}]}
{"op":"mcm","clk":"1001743333","pt":1580639756202,"mc":[{"id":"1.168224027","rc":[{"batl":[[0,2.16,385.72]],"ltp":2.12,"tv":540.46,"id":4596961}]}]}
{"op":"mcm","clk":"1001745559","pt":1580639778270,"mc":[{"id":"1.168224027","rc":[{"batl":[[0,1.95,15.7],[1,2.28,18.96],[2,2.36,74.21]],"ltp":1.89,"tv":1734.25,"id":8908205}]}]}
{"op":"mcm","clk":"1001745975","pt":1580639782452,"mc":[{"id":"1.168224027","rc":[{"batl":[[0,2.28,18.96],[1,2.36,74.21],[2,4.2,153.72]],"ltp":1.89,"tv":1734.25,"id":8908205}]}]}
{"op":"mcm","clk":"1001746071","pt":1580639783599,"mc":[{"id":"1.168224027","rc":[{"batl":[[0,1.95,15.7],[1,2.28,18.96],[2,2.36,74.21]],"ltp":1.89,"tv":1734.25,"id":8908205}]}]}
{"op":"mcm","clk":"1001746280","pt":1580639785990,"mc":[{"id":"1.168224027","rc":[{"batl":[[0,1.94,15.7]],"ltp":1.89,"tv":1734.25,"id":8908205}]}]}
{"op":"mcm","clk":"1001747130","pt":1580639794514,"mc":[{"id":"1.168224027","rc":[{"batb":[[0,1.87,9.58],[1,1.84,55.36],[2,1.83,29.61]],"ltp":1.89,"tv":1734.25,"id":8908205},{"batl":[[0,2.14,8.4],[1,2.16,385.72],[2,2.28,18.48]],"ltp":2.12,"tv":540.46,"id":4596961}]}]}
{"op":"mcm","clk":"1001749362","pt":1580639817900,"mc":[{"id":"1.168224027","rc":[{"batl":[[0,1.94,24.11]],"ltp":1.89,"tv":1734.25,"id":8908205},{"trd":[[2.14,32.68]],"batb":[[0,2.06,52.5]],"batl":[[0,2.14,10.02]],"ltp":2.14,"tv":554.02,"id":4596961}],"tv":2288.27}]}
{"op":"mcm","clk":"1001749395","pt":1580639818137,"mc":[{"id":"1.168224027","rc":[{"batb":[[0,1.87,19.23]],"ltp":1.89,"tv":1734.25,"id":8908205}]}]}
{"op":"mcm","clk":"1001750948","pt":1580639833067,"mc":[{"id":"1.168224027","rc":[{"batb":[[1,1.83,29.61],[2,1.81,292.61]],"ltp":1.89,"tv":1734.25,"id":8908205}]}]}
{"op":"mcm","clk":"1001750984","pt":1580639833481,"mc":[{"id":"1.168224027","rc":[{"batb":[[0,1.87,42.48]],"ltp":1.89,"tv":1734.25,"id":8908205},{"batl":[[1,2.16,10]],"ltp":2.14,"tv":554.02,"id":4596961}]}]}
{"op":"mcm","clk":"1001751043","pt":1580639834173,"mc":[{"id":"1.168224027","rc":[{"batb":[[0,1.87,32.9]],"ltp":1.89,"tv":1734.25,"id":8908205},{"batl":[[0,2.14,8.4]],"ltp":2.14,"tv":554.02,"id":4596961}]}]}
{"op":"mcm","clk":"1001751573","pt":1580639839396,"mc":[{"id":"1.168224027","rc":[{"batl":[[0,1.93,15.7],[1,1.94,8.4],[2,2.28,18.96]],"ltp":1.89,"tv":1734.25,"id":8908205}]}]}
{"op":"mcm","clk":"1001752617","pt":1580639849894,"mc":[{"id":"1.168224027","rc":[{"batl":[[0,1.93,24.11],[1,2.28,18.96],[2,2.36,74.21]],"ltp":1.89,"tv":1734.25,"id":8908205},{"trd":[[2.14,46.26]],"batl":[[0,2.14,1.61]],"ltp":2.14,"tv":567.59,"id":4596961}],"tv":2301.85}]}
{"op":"mcm","clk":"1001756048","pt":1580639881028,"mc":[{"id":"1.168224027","rc":[{"batl":[[0,1.93,15.7]],"ltp":1.89,"tv":1734.25,"id":8908205}]}]}
{"op":"mcm","clk":"1001756132","pt":1580639881815,"mc":[{"id":"1.168224027","rc":[{"batb":[[0,1.87,23.25]],"ltp":1.89,"tv":1734.25,"id":8908205}]}]}
{"op":"mcm","clk":"1001756216","pt":1580639882550,"mc":[{"id":"1.168224027","rc":[{"batl":[[0,2.16,18.4],[1,2.28,18.48],[2,4.2,153.72]],"ltp":2.14,"tv":567.59,"id":4596961}]}]}
{"op":"mcm","clk":"1001763548","pt":1580639962054,"mc":[{"id":"1.168224027","rc":[{"batb":[[0,1.84,55.36]],"ltp":1.89,"tv":1734.25,"id":8908205},{"batl":[[0,2.16,394.12]],"ltp":2.14,"tv":567.59,"id":4596961}]}]}
{"op":"mcm","clk":"1001763741","pt":1580639964212,"mc":[{"id":"1.168224027","rc":[{"batb":[[0,1.87,10.86],[1,1.84,55.36],[2,1.83,29.61]],"ltp":1.89,"tv":1734.25,"id":8908205}]}]}
{"op":"mcm","clk":"1001764490","pt":1580639971926,"mc":[{"id":"1.168224027","rc":[{"batb":[[0,1.84,55.36],[1,1.83,29.61],[2,1.81,292.61]],"ltp":1.89,"tv":1734.25,"id":8908205},{"batl":[[0,2.16,18.4]],"ltp":2.14,"tv":567.59,"id":4596961}]}]}
{"op":"mcm","clk":"1001767235","pt":1580640001748,"mc":[{"id":"1.168224027","rc":[{"batl":[[0,2.16,394.12]],"ltp":2.14,"tv":567.59,"id":4596961}]}]}
{"op":"mcm","clk":"1001775231","pt":1580640087682,"mc":[{"id":"1.168224027","rc":[{"batb":[[0,1.87,23.25]],"ltp":1.89,"tv":1734.25,"id":8908205}]}]}
{"op":"mcm","clk":"1001777046","pt":1580640105984,"mc":[{"id":"1.168224027","rc":[{"batb":[[0,1.87,32.57]],"ltp":1.89,"tv":1734.25,"id":8908205}]}]}
{"op":"mcm","clk":"1001780176","pt":1580640131623,"mc":[{"id":"1.168224027","rc":[{"batl":[[0,2.16,18.4]],"ltp":2.14,"tv":567.59,"id":4596961}]}]}
{"op":"mcm","clk":"1001780274","pt":1580640132455,"mc":[{"id":"1.168224027","rc":[{"batb":[[0,1.87,23.25]],"ltp":1.89,"tv":1734.25,"id":8908205}]}]}
{"op":"mcm","clk":"1001783977","pt":1580640159789,"mc":[{"id":"1.168224027","rc":[{"batb":[[0,1.88,7.57],[1,1.87,23.25],[2,1.83,29.61]],"ltp":1.89,"tv":1734.25,"id":8908205}]}]}
{"op":"mcm","clk":"1001784133","pt":1580640160900,"mc":[{"id":"1.168224027","rc":[{"batl":[[0,2.14,8.4],[1,2.16,10],[2,2.28,18.48]],"ltp":2.14,"tv":567.59,"id":4596961}]}]}
{"op":"mcm","clk":"1001784338","pt":1580640162099,"mc":[{"id":"1.168224027","rc":[{"trd":[[1.88,466.13]],"batb":[[0,1.87,23.25],[1,1.83,29.61],[2,1.81,292.61]],"batl":[[0,1.89,5.95],[1,1.93,15.7],[2,2.28,18.96]],"ltp":1.88,"tv":1746.21,"id":8908205}],"tv":2313.81}]}
{"op":"mcm","clk":"1001785180","pt":1580640167491,"mc":[{"id":"1.168224027","rc":[{"batl":[[0,1.91,5.95]],"ltp":1.88,"tv":1746.21,"id":8908205}]}]}
{"op":"mcm","clk":"1001789037","pt":1580640192042,"mc":[{"id":"1.168224027","rc":[{"batb":[[0,2.06,44.58]],"ltp":2.14,"tv":567.59,"id":4596961}]}]}
{"op":"mcm","clk":"1001789083","pt":1580640192352,"mc":[{"id":"1.168224027","rc":[{"trd":[[2.14,59.92]],"batb":[[0,2.08,7.78],[1,2.06,44.58],[2,1.84,282.16]],"batl":[[0,2.14,1.57]],"ltp":2.14,"tv":581.26,"id":4596961}],"tv":2327.48}]}
{"op":"mcm","clk":"1001792336","pt":1580640214347,"mc":[{"id":"1.168224027","rc":[{"batl":[[0,1.92,5.95]],"ltp":1.88,"tv":1746.21,"id":8908205}]}]}
{"op":"mcm","clk":"1001792726","pt":1580640217446,"mc":[{"id":"1.168224027","rc":[{"batb":[[0,1.84,55.36]],"ltp":1.88,"tv":1746.21,"id":8908205},{"batb":[[1,2.02,76.87]],"ltp":2.14,"tv":581.26,"id":4596961}]}]}
{"op":"mcm","clk":"1001792988","pt":1580640219615,"mc":[{"id":"1.168224027","rc":[{"batb":[[1,2.04,7.12],[2,2.02,76.87]],"ltp":2.14,"tv":581.26,"id":4596961}]}]}
{"op":"mcm","clk":"1001793492","pt":1580640223759,"mc":[{"id":"1.168224027","rc":[{"batl":[[0,1.92,18.55]],"ltp":1.88,"tv":1746.21,"id":8908205},{"batl":[[0,2.16,10],[1,2.28,18.48],[2,4.2,153.72]],"ltp":2.14,"tv":581.26,"id":4596961}]}]}
{"op":"mcm","clk":"1001795826","pt":1580640243942,"mc":[{"id":"1.168224027","rc":[{"batl":[[0,2.16,385.72]],"ltp":2.14,"tv":581.26,"id":4596961}]}]}
{"op":"mcm","clk":"1001796430","pt":1580640249258,"mc":[{"id":"1.168224027","rc":[{"batb":[[0,1.87,10.49],[1,1.84,55.36],[2,1.83,29.61]],"ltp":1.88,"tv":1746.21,"id":8908205}]}]}
{"op":"mcm","clk":"1001804804","pt":1580640318903,"mc":[{"id":"1.168224027","rc":[{"batl":[[0,2.16,10]],"ltp":2.14,"tv":581.26,"id":4596961}]}]}
{"op":"mcm","clk":"1001804963","pt":1580640320109,"mc":[{"id":"1.168224027","rc":[{"batb":[[0,1.84,55.36],[1,1.83,29.61],[2,1.81,292.61]],"ltp":1.88,"tv":1746.21,"id":8908205}]}]}
{"op":"mcm","clk":"1001809222","pt":1580640354820,"mc":[{"id":"1.168224027","rc":[{"batb":[[1,2.06,44.58],[2,2.04,7.12]],"batl":[[0,2.16,385.72]],"ltp":2.14,"tv":581.26,"id":4596961}]}]}
{"op":"mcm","clk":"1001809411","pt":1580640356338,"mc":[{"id":"1.168224027","rc":[{"batb":[[0,2.08,14.75],[2,1.84,282.16]],"ltp":2.14,"tv":581.26,"id":4596961}]}]}
{"op":"mcm","clk":"1001813856","pt":1580640393470,"mc":[{"id":"1.168224027","rc":[{"batb":[[0,1.87,10.82],[1,1.84,55.36],[2,1.83,29.61]],"ltp":1.88,"tv":1746.21,"id":8908205}]}]}
{"op":"mcm","clk":"1001825923","pt":1580640492047,"mc":[{"id":"1.168224027","rc":[{"batb":[[0,1.87,34.07],[1,1.83,29.61],[2,1.81,292.61]],"ltp":1.88,"tv":1746.21,"id":8908205},{"batb":[[1,2.02,76.87]],"batl":[[0,2.16,10]],"ltp":2.14,"tv":581.26,"id":4596961}]}]}
{"op":"mcm","clk":"1001826046","pt":1580640493046,"mc":[{"id":"1.168224027","rc":[{"batb":[[0,1.87,23.25]],"ltp":1.88,"tv":1746.21,"id":8908205},{"batb":[[0,2.08,7.78],[1,2.04,7.12],[2,2.02,76.87]],"ltp":2.14,"tv":581.26,"id":4596961}]}]}
{"op":"mcm","clk":"1001842827","pt":1580640633043,"mc":[{"id":"1.168224027","rc":[{"batb":[[0,1.83,29.61],[1,1.81,292.61],[2,1.8,50.73]],"ltp":1.88,"tv":1746.21,"id":8908205},{"batb":[[2,1.84,282.16]],"ltp":2.14,"tv":581.26,"id":4596961}]}]}
{"op":"mcm","clk":"1001842952","pt":1580640633966,"mc":[{"id":"1.168224027","rc":[{"batb":[[0,1.84,55.36],[1,1.83,29.61],[2,1.81,292.61]],"ltp":1.88,"tv":1746.21,"id":8908205},{"batb":[[0,2.08,14.75],[1,2.06,44.58]],"batl":[[0,2.16,385.72]],"ltp":2.14,"tv":581.26,"id":4596961}]}]}
{"op":"mcm","clk":"1001843148","pt":1580640635513,"mc":[{"id":"1.168224027","rc":[{"batb":[[0,1.87,9.55],[1,1.84,55.36],[2,1.83,29.61]],"ltp":1.88,"tv":1746.21,"id":8908205}]}]}
{"op":"mcm","clk":"1001851835","pt":1580640705072,"mc":[{"id":"1.168224027","rc":[{"batb":[[0,1.84,55.36],[1,1.83,29.61],[2,1.81,292.61]],"ltp":1.88,"tv":1746.21,"id":8908205},{"batl":[[0,2.16,10]],"ltp":2.14,"tv":581.26,"id":4596961}]}]}
{"op":"mcm","clk":"1001852053","pt":1580640707107,"mc":[{"id":"1.168224027","rc":[{"batb":[[2,1.8,50.73]],"ltp":1.88,"tv":1746.21,"id":8908205},{"batb":[[2,1.9,263.35]],"ltp":2.14,"tv":581.26,"id":4596961}]}]}
{"op":"mcm","clk":"1001852130","pt":1580640707684,"mc":[{"id":"1.168224027","rc":[{"batb":[[2,1.76,311.86]],"ltp":1.88,"tv":1746.21,"id":8908205}]}]}
{"op":"mcm","clk":"1001859438","pt":1580640770246,"mc":[{"id":"1.168224027","rc":[{"batb":[[1,2.02,76.87]],"ltp":2.14,"tv":581.26,"id":4596961}]}]}
{"op":"mcm","clk":"1001859669","pt":1580640772063,"mc":[{"id":"1.168224027","rc":[{"batb":[[0,2.08,7.78]],"ltp":2.14,"tv":581.26,"id":4596961}]}]}
{"op":"mcm","clk":"1001859695","pt":1580640772225,"mc":[{"id":"1.168224027","rc":[{"batb":[[1,2.04,7.12],[2,2.02,76.87]],"ltp":2.14,"tv":581.26,"id":4596961}]}]}
{"op":"mcm","clk":"1001862711","pt":1580640801200,"mc":[{"id":"1.168224027","rc":[{"batl":[[0,1.91,10.56],[1,1.92,18.55],[2,1.93,15.7]],"ltp":1.88,"tv":1746.21,"id":8908205}]}]}
{"op":"mcm","clk":"1001863756","pt":1580640811054,"mc":[{"id":"1.168224027","rc":[{"batl":[[0,1.91,23.16],[1,1.92,5.95]],"ltp":1.88,"tv":1746.21,"id":8908205}]}]}
{"op":"mcm","clk":"1001864185","pt":1580640814858,"mc":[{"id":"1.168224027","rc":[{"batb":[[2,1.71,37.86]],"ltp":1.88,"tv":1746.21,"id":8908205}]}]}
{"op":"mcm","clk":"1001864249","pt":1580640815542,"mc":[{"id":"1.168224027","rc":[{"batb":[[2,1.75,316.02]],"ltp":1.88,"tv":1746.21,"id":8908205}]}]}
{"op":"mcm","clk":"1001865728","pt":1580640828066,"mc":[{"id":"1.168224027","rc":[{"batl":[[0,1.91,12.6]],"ltp":1.88,"tv":1746.21,"id":8908205}]}]}
{"op":"mcm","clk":"1001865749","pt":1580640828271,"mc":[{"id":"1.168224027","rc":[{"batl":[[0,1.91,23.16]],"ltp":1.88,"tv":1746.21,"id":8908205}]}]}
{"op":"mcm","clk":"1001869369","pt":1580640863099,"mc":[{"id":"1.168224027","rc":[{"trd":[[1.91,598.13],[1.92,54.34]],"batl":[[0,1.93,15.7],[1,2.28,18.96],[2,2.36,74.21]],"ltp":1.92,"tv":1792.35,"id":8908205},{"trd":[[2.08,64.15]],"batb":[[0,2.04,7.12],[1,2.02,45.53],[2,1.92,257.63]],"batl":[[0,2.08,1.33],[1,2.16,10],[2,2.28,18.48]],"ltp":2.08,"tv":607.94,"id":4596961}],"tv":2400.29}]}
{"op":"mcm","clk":"1001869464","pt":1580640863882,"mc":[{"id":"1.168224027","rc":[{"batb":[[0,1.87,40.22]],"ltp":1.92,"tv":1792.35,"id":8908205},{"batb":[[0,2.02,7.18],[1,2,78.27]],"ltp":2.08,"tv":607.94,"id":4596961}]}]}
{"op":"mcm","clk":"1001870386","pt":1580640872895,"mc":[{"id":"1.168224027","rc":[{"trd":[[1.92,55.78]],"batl":[[0,1.92,14.27]],"ltp":1.92,"tv":1793.79,"id":8908205},{"trd":[[2.08,65.48]],"batl":[[0,2.16,10],[1,2.28,18.48],[2,4.2,153.72]],"ltp":2.08,"tv":609.27,"id":4596961}],"tv":2403.06}]}
{"op":"mcm","clk":"1001870483","pt":1580640873985,"mc":[{"id":"1.168224027","rc":[{"batb":[[0,1.87,54.71]],"ltp":1.92,"tv":1793.79,"id":8908205},{"batl":[[0,2.16,22.6]],"ltp":2.08,"tv":609.27,"id":4596961}]}]}
{"op":"mcm","clk":"1001870540","pt":1580640874710,"mc":[{"id":"1.168224027","rc":[{"batl":[[0,2.28,18.96],[1,2.36,74.21],[2,4.2,153.72]],"ltp":1.92,"tv":1793.79,"id":8908205}]}]}
{"op":"mcm","clk":"1001870670","pt":1580640876116,"mc":[{"id":"1.168224027","rc":[{"batl":[[0,1.97,14.05],[1,2.28,18.96],[2,2.36,74.21]],"ltp":1.92,"tv":1793.79,"id":8908205}]}]}
{"op":"mcm","clk":"1001870692","pt":1580640876280,"mc":[{"id":"1.168224027","rc":[{"batl":[[0,1.97,21.97]],"ltp":1.92,"tv":1793.79,"id":8908205}]}]}
{"op":"mcm","clk":"1001870939","pt":1580640878893,"mc":[{"id":"1.168224027","rc":[{"batl":[[0,2.28,18.96],[1,2.36,74.21],[2,4.2,153.72]],"ltp":1.92,"tv":1793.79,"id":8908205}]}]}
{"op":"mcm","clk":"1001871049","pt":1580640880082,"mc":[{"id":"1.168224027","rc":[{"batl":[[0,1.95,14.2],[1,2.28,18.96],[2,2.36,74.21]],"ltp":1.92,"tv":1793.79,"id":8908205}]}]}
{"op":"mcm","clk":"1001881547","pt":1580640975023,"mc":[{"id":"1.168224027","rc":[{"batl":[[0,2.28,18.96],[1,2.36,74.21],[2,4.2,153.72]],"ltp":1.92,"tv":1793.79,"id":8908205}]}]}
{"op":"mcm","clk":"1001881679","pt":1580640976123,"mc":[{"id":"1.168224027","rc":[{"batl":[[0,1.95,14.2],[1,2.28,18.96],[2,2.36,74.21]],"ltp":1.92,"tv":1793.79,"id":8908205}]}]}
{"op":"mcm","clk":"1001886434","pt":1580641015916,"mc":[{"id":"1.168224027","rc":[{"batl":[[0,1.92,7.57]],"ltp":1.92,"tv":1793.79,"id":8908205}]}]}
{"op":"mcm","clk":"1001887221","pt":1580641020324,"mc":[{"id":"1.168224027","rc":[{"batl":[[0,2.28,18.96],[1,2.36,74.21],[2,4.2,153.72]],"ltp":1.92,"tv":1793.79,"id":8908205}]}]}
{"op":"mcm","clk":"1001887415","pt":1580641021521,"mc":[{"id":"1.168224027","rc":[{"batl":[[0,1.92,14.42],[1,2.28,18.96],[2,2.36,74.21]],"ltp":1.92,"tv":1793.79,"id":8908205}]}]}
{"op":"mcm","clk":"1001888716","pt":1580641031614,"mc":[{"id":"1.168224027","rc":[{"batb":[[0,2.04,45.03],[1,2.02,7.18]],"ltp":2.08,"tv":609.27,"id":4596961}]}]}
{"op":"mcm","clk":"1001888964","pt":1580641033324,"mc":[{"id":"1.168224027","rc":[{"batb":[[1,1.92,257.63],[2,1.83,49.98]],"ltp":2.08,"tv":609.27,"id":4596961}]}]}
{"op":"mcm","clk":"1001903717","pt":1580641154563,"mc":[{"id":"1.168224027","rc":[{"batl":[[0,2.28,18.96],[1,2.36,74.21],[2,4.2,153.72]],"ltp":1.92,"tv":1793.79,"id":8908205}]}]}
{"op":"mcm","clk":"1001903861","pt":1580641155768,"mc":[{"id":"1.168224027","rc":[{"batl":[[0,1.96,14.12],[1,2.28,18.96],[2,2.36,74.21]],"ltp":1.92,"tv":1793.79,"id":8908205}]}]}
{"op":"mcm","clk":"1001905561","pt":1580641165766,"mc":[{"id":"1.168224027","rc":[{"batb":[[0,2,78.27]],"ltp":2.08,"tv":609.27,"id":4596961}]}]}
{"op":"mcm","clk":"1001905838","pt":1580641167657,"mc":[{"id":"1.168224027","rc":[{"batb":[[0,2.02,7.18],[1,2,78.27],[2,1.92,257.63]],"ltp":2.08,"tv":609.27,"id":4596961}]}]}
{"op":"mcm","clk":"1001908959","pt":1580641192010,"mc":[{"id":"1.168224027","rc":[{"batl":[[0,1.93,21.11],[1,1.96,14.12],[2,2.28,18.96]],"ltp":1.92,"tv":1793.79,"id":8908205}]}]}
{"op":"mcm","clk":"1001916744","pt":1580641242834,"mc":[{"id":"1.168224027","rc":[{"batl":[[1,2.28,18.96],[2,2.36,74.21]],"ltp":1.92,"tv":1793.79,"id":8908205}]}]}
{"op":"mcm","clk":"1001916915","pt":1580641244052,"mc":[{"id":"1.168224027","rc":[{"batl":[[0,1.92,14.42],[1,1.93,21.11],[2,2.28,18.96]],"ltp":1.92,"tv":1793.79,"id":8908205}]}]}
{"op":"mcm","clk":"1001922515","pt":1580641279502,"mc":[{"id":"1.168224027","rc":[{"batb":[[1,1.85,2.04],[2,1.84,2.1]],"batl":[[2,1.94,2.08]],"ltp":1.92,"tv":1793.79,"id":8908205},{"batb":[[0,2.04,2.12],[1,2.02,9.18],[2,2,78.27]],"batl":[[1,2.2,2.03],[2,2.22,2.16]],"ltp":2.08,"tv":609.27,"id":4596961}]}]}
{"op":"mcm","clk":"1001926689","pt":1580641306742,"mc":[{"id":"1.168224027","rc":[{"batb":[[2,1.84,2.04]],"ltp":1.92,"tv":1793.79,"id":8908205},{"batb":[[0,2.04,47.15],[1,2.02,9.2],[2,1.92,257.63]],"batl":[[2,2.22,2.07]],"ltp":2.08,"tv":609.27,"id":4596961}]}]}
{"op":"mcm","clk":"1001926846","pt":1580641307739,"mc":[{"id":"1.168224027","rc":[{"batb":[[0,2.06,7.04],[1,2.04,47.15],[2,2.02,2.02]],"ltp":2.08,"tv":609.27,"id":4596961}]}]}
{"op":"mcm","clk":"1001928210","pt":1580641316051,"mc":[{"id":"1.168224027","rc":[{"batb":[[2,1.84,2.1]],"batl":[[0,1.9,14.42],[1,1.92,2.06],[2,1.93,23.18]],"ltp":1.92,"tv":1793.79,"id":8908205},{"batb":[[0,2.06,9.12],[1,2.04,47.1],[2,2.02,2.24]],"batl":[[2,2.22,2.16]],"ltp":2.08,"tv":609.27,"id":4596961}]}]}
{"op":"mcm","clk":"1001929415","pt":1580641323056,"mc":[{"id":"1.168224027","rc":[{"batl":[[0,1.89,14.42]],"ltp":1.92,"tv":1793.79,"id":8908205}]}]}
{"op":"mcm","clk":"1001929593","pt":1580641323957,"mc":[{"id":"1.168224027","rc":[{"batb":[[2,1.84,2.22]],"batl":[[1,1.91,2.05],[2,1.92,2.06]],"ltp":1.92,"tv":1793.79,"id":8908205},{"batb":[[0,2.08,2.06],[1,2.06,9.12],[2,2.04,45.03]],"ltp":2.08,"tv":609.27,"id":4596961}]}]}
{"op":"mcm","clk":"1001929929","pt":1580641325882,"mc":[{"id":"1.168224027","rc":[{"trd":[[1.88,470.13]],"batl":[[0,1.88,12.42],[1,1.9,2.05],[2,1.91,2.05]],"ltp":1.88,"tv":1797.79,"id":8908205}],"tv":2407.06}]}
{"op":"mcm","clk":"1001930656","pt":1580641330060,"mc":[{"id":"1.168224027","rc":[{"batb":[[2,1.84,2.16]],"batl":[[0,1.89,12.42],[1,1.91,2.05],[2,1.92,2.06]],"ltp":1.88,"tv":1797.79,"id":8908205},{"batl":[[2,2.22,2]],"ltp":2.08,"tv":609.27,"id":4596961}]}]}
{"op":"mcm","clk":"1001930998","pt":1580641332059,"mc":[{"id":"1.168224027","rc":[{"batl":[[0,1.88,12.42],[1,1.9,2.05],[2,1.91,2.05]],"ltp":1.88,"tv":1797.79,"id":8908205}]}]}
{"op":"mcm","clk":"1001931759","pt":1580641337078,"mc":[{"id":"1.168224027","rc":[{"batb":[[2,1.84,2]],"batl":[[0,1.92,14.48],[1,1.93,23.18],[2,1.94,2]],"ltp":1.88,"tv":1797.79,"id":8908205},{"batb":[[0,2.06,7.04],[1,2.04,47.15],[2,2.02,2.12]],"batl":[[2,2.22,2.03]],"ltp":2.08,"tv":609.27,"id":4596961}]}]}
{"op":"mcm","clk":"1001931793","pt":1580641337286,"mc":[{"id":"1.168224027","rc":[{"batl":[[0,1.92,12.42],[1,1.93,21.11]],"ltp":1.88,"tv":1797.79,"id":8908205}]}]}
{"op":"mcm","clk":"1001932090","pt":1580641338889,"mc":[{"id":"1.168224027","rc":[{"batb":[[0,2.04,47.15],[1,2.02,2.12],[2,1.92,257.63]],"ltp":2.08,"tv":609.27,"id":4596961}]}]}
{"op":"mcm","clk":"1001932610","pt":1580641341899,"mc":[{"id":"1.168224027","rc":[{"batl":[[0,1.9,12.42],[1,1.92,2.06],[2,1.93,23.18]],"ltp":1.88,"tv":1797.79,"id":8908205},{"batb":[[0,2.06,2],[1,2.04,45.03],[2,2.02,2.12]],"ltp":2.08,"tv":609.27,"id":4596961}]}]}
{"op":"mcm","clk":"1001932664","pt":1580641342178,"mc":[{"id":"1.168224027","rc":[{"batb":[[1,2.04,47.15]],"ltp":2.08,"tv":609.27,"id":4596961}]}]}
{"op":"mcm","clk":"1001932990","pt":1580641344111,"mc":[{"id":"1.168224027","rc":[{"batb":[[2,1.84,2.22]],"batl":[[0,1.93,21.11],[1,1.95,2.1],[2,1.96,2.12]],"ltp":1.88,"tv":1797.79,"id":8908205},{"batb":[[0,2.04,45.03],[1,2.02,2.03],[2,2,2]],"batl":[[2,2.22,2.16]],"ltp":2.08,"tv":609.27,"id":4596961}]}]}
{"op":"mcm","clk":"1001933075","pt":1580641344587,"mc":[{"id":"1.168224027","rc":[{"batl":[[0,1.9,12.59],[1,1.92,2.01],[2,1.93,23.18]],"ltp":1.88,"tv":1797.79,"id":8908205},{"batb":[[0,2.06,2.08],[1,2.04,47.15],[2,2.02,2.14]],"ltp":2.08,"tv":609.27,"id":4596961}]}]}
{"op":"mcm","clk":"1001941951","pt":1580641399010,"mc":[{"id":"1.168224027","rc":[{"batb":[[2,1.83,29.61]],"batl":[[0,1.93,21.11],[1,1.94,2.06],[2,1.95,2.1]],"ltp":1.88,"tv":1797.79,"id":8908205},{"batb":[[1,2.04,45.03],[2,1.92,257.63]],"batl":[[2,2.28,18.48]],"ltp":2.08,"tv":609.27,"id":4596961}]}]}
{"op":"mcm","clk":"1001942130","pt":1580641399983,"mc":[{"id":"1.168224027","rc":[{"batb":[[2,1.84,2.22]],"batl":[[0,1.89,12.66],[1,1.91,2.05],[2,1.92,2.06]],"ltp":1.88,"tv":1797.79,"id":8908205},{"batb":[[0,2.08,2.06],[1,2.06,2.08],[2,2.04,45.03]],"batl":[[2,2.22,2.16]],"ltp":2.08,"tv":609.27,"id":4596961}]}]}
{"op":"mcm","clk":"1001942789","pt":1580641403999,"mc":[{"id":"1.168224027","rc":[{"batl":[[0,1.93,23.18],[1,1.94,2.08],[2,1.96,2.12]],"ltp":1.88,"tv":1797.79,"id":8908205},{"batb":[[0,2.04,47.12],[1,2.02,2.24],[2,2,2]],"ltp":2.08,"tv":609.27,"id":4596961}]}]}
{"op":"mcm","clk":"1001942915","pt":1580641404797,"mc":[{"id":"1.168224027","rc":[{"batl":[[0,1.88,12.72],[1,1.9,2],[2,1.91,2.05]],"ltp":1.88,"tv":1797.79,"id":8908205},{"batb":[[0,2.08,2.06],[1,2.06,2.08],[2,2.04,45.03]],"ltp":2.08,"tv":609.27,"id":4596961}]}]}
{"op":"mcm","clk":"1001943477","pt":1580641407114,"mc":[{"id":"1.168224027","rc":[{"batl":[[0,1.9,2],[1,1.92,2.06],[2,1.93,23.18]],"ltp":1.88,"tv":1797.79,"id":8908205}]}]}
{"op":"mcm","clk":"1001943678","pt":1580641408008,"mc":[{"id":"1.168224027","rc":[{"batl":[[0,1.92,12.46],[1,1.93,21.11],[2,1.94,2.08]],"ltp":1.88,"tv":1797.79,"id":8908205},{"batb":[[0,2.04,47.08],[1,2.02,2],[2,2,2]],"batl":[[2,2.22,2.07]],"ltp":2.08,"tv":609.27,"id":4596961}]}]}
{"op":"mcm","clk":"1001949653","pt":1580641438827,"mc":[{"id":"1.168224027","rc":[{"batb":[[0,2.04,2.05],[1,2.02,2.24],[2,2,78.27]],"batl":[[2,2.22,2.16]],"ltp":2.08,"tv":609.27,"id":4596961}]}]}
{"op":"mcm","clk":"1001972371","pt":1580641558076,"mc":[{"id":"1.168224027","rc":[{"batb":[[0,1.89,37.86],[1,1.87,54.71],[2,1.85,2.04]],"ltp":1.88,"tv":1797.79,"id":8908205}]}]}
{"op":"mcm","clk":"1001972561","pt":1580641558967,"mc":[{"id":"1.168224027","rc":[{"trd":[[1.89,290.29]],"batb":[[0,1.89,5.45],[1,1.87,56.71],[2,1.86,2.18]],"ltp":1.89,"tv":1862.6,"id":8908205},{"batb":[[1,2.02,2.13]],"batl":[[1,2.18,2.03],[2,2.2,2.03]],"ltp":2.08,"tv":609.27,"id":4596961}],"tv":2471.88}]}
{"op":"mcm","clk":"1001973208","pt":1580641561889,"mc":[{"id":"1.168224027","rc":[{"batb":[[0,1.89,8.82]],"ltp":1.89,"tv":1862.6,"id":8908205}]}]}
{"op":"mcm","clk":"1001974349","pt":1580641567070,"mc":[{"id":"1.168224027","rc":[{"batl":[[0,1.93,21.11],[1,1.94,2.08],[2,1.95,2.1]],"ltp":1.89,"tv":1862.6,"id":8908205}]}]}
{"op":"mcm","clk":"1001974482","pt":1580641567663,"mc":[{"id":"1.168224027","rc":[{"batl":[[1,1.95,2.1],[2,1.96,2.12]],"ltp":1.89,"tv":1862.6,"id":8908205},{"batb":[[0,2.02,2.24],[1,2,80.27],[2,1.92,257.63]],"ltp":2.08,"tv":609.27,"id":4596961}]}]}
{"op":"mcm","clk":"1001974755","pt":1580641568989,"mc":[{"id":"1.168224027","rc":[{"trd":[[1.89,307.94]],"batb":[[0,1.87,54.71],[1,1.85,2.17],[2,1.84,2.22]],"batl":[[0,1.89,3.84],[1,1.91,2.05],[2,1.92,2.06]],"ltp":1.89,"tv":1880.25,"id":8908205},{"batb":[[0,2.08,2.06],[1,2.06,2.08],[2,2.02,2.24]],"batl":[[1,2.2,2.03],[2,2.22,2]],"ltp":2.08,"tv":609.27,"id":4596961}],"tv":2489.52}]}
{"op":"mcm","clk":"1001975179","pt":1580641571104,"mc":[{"id":"1.168224027","rc":[{"batl":[[0,1.93,21.11],[1,1.95,2.02],[2,1.96,2.12]],"ltp":1.89,"tv":1880.25,"id":8908205},{"batb":[[0,2.04,2.12],[1,2.02,2.24],[2,2,80.27]],"ltp":2.08,"tv":609.27,"id":4596961}]}]}
{"op":"mcm","clk":"1001975297","pt":1580641571701,"mc":[{"id":"1.168224027","rc":[{"batb":[[0,2.02,9.42],[1,2,80.27],[2,1.92,257.63]],"ltp":2.08,"tv":609.27,"id":4596961}]}]}
{"op":"mcm","clk":"1001975489","pt":1580641572616,"mc":[{"id":"1.168224027","rc":[{"batl":[[0,1.92,3.78],[1,1.93,21.11],[2,1.94,2.08]],"ltp":1.89,"tv":1880.25,"id":8908205},{"batb":[[0,2.04,2.12],[1,2.02,9.42],[2,2,80.27]],"ltp":2.08,"tv":609.27,"id":4596961}]}]}
{"op":"mcm","clk":"1001977425","pt":1580641583033,"mc":[{"id":"1.168224027","rc":[{"batb":[[2,1.83,29.61]],"ltp":1.89,"tv":1880.25,"id":8908205},{"batb":[[1,2.02,7.18],[2,2,78.27]],"batl":[[2,2.28,18.48]],"ltp":2.08,"tv":609.27,"id":4596961}]}]}
{"op":"mcm","clk":"1001977463","pt":1580641583211,"mc":[{"id":"1.168224027","rc":[{"batb":[[2,1.84,2.22]],"ltp":1.89,"tv":1880.25,"id":8908205},{"batb":[[1,2.02,9.31]],"batl":[[2,2.22,2.16]],"ltp":2.08,"tv":609.27,"id":4596961}]}]}
{"op":"mcm","clk":"1001979277","pt":1580641592101,"mc":[{"id":"1.168224027","rc":[{"batl":[[0,1.91,3.33],[1,1.92,3.78],[2,1.93,23.18]],"ltp":1.89,"tv":1880.25,"id":8908205}]}]}
{"op":"mcm","clk":"1001979379","pt":1580641592733,"mc":[{"id":"1.168224027","rc":[{"batb":[[1,2.02,9.2]],"ltp":2.08,"tv":609.27,"id":4596961}]}]}
{"op":"mcm","clk":"1001979966","pt":1580641596006,"mc":[{"id":"1.168224027","rc":[{"batl":[[1,1.93,23.18],[2,1.94,2.08]],"ltp":1.89,"tv":1880.25,"id":8908205}]}]}
{"op":"mcm","clk":"1001980164","pt":1580641597117,"mc":[{"id":"1.168224027","rc":[{"batl":[[0,1.9,3.82],[1,1.91,3.33],[2,1.93,23.18]],"ltp":1.89,"tv":1880.25,"id":8908205}]}]}
{"op":"mcm","clk":"1001980290","pt":1580641597852,"mc":[{"id":"1.168224027","rc":[{"batl":[[2,1.92,2.06]],"ltp":1.89,"tv":1880.25,"id":8908205},{"batb":[[0,2.06,2.06],[1,2.04,2.12],[2,2.02,9.2]],"ltp":2.08,"tv":609.27,"id":4596961}]}]}
{"op":"mcm","clk":"1001999234","pt":1580641708115,"mc":[{"id":"1.168224027","rc":[{"trd":[[1.9,186.75]],"batb":[[0,1.87,50.87],[2,1.83,29.61]],"batl":[[0,1.91,3.33],[1,1.93,23.18],[2,2,38.34]],"ltp":1.9,"tv":1887.88,"id":8908205},{"batb":[[1,2.02,7.18],[2,1.92,257.63]],"batl":[[2,2.28,18.48]],"ltp":2.08,"tv":609.27,"id":4596961}],"tv":2497.15}]}
{"op":"mcm","clk":"1001999278","pt":1580641708325,"mc":[{"id":"1.168224027","rc":[{"batb":[[2,1.84,2]],"batl":[[2,1.94,2.06]],"ltp":1.9,"tv":1887.88,"id":8908205},{"batb":[[0,2.08,17.42],[1,2.04,2.11],[2,2.02,9.33]],"batl":[[2,2.22,2.03]],"ltp":2.08,"tv":609.27,"id":4596961}]}]}
{"op":"mcm","clk":"1002016386","pt":1580641804041,"mc":[{"id":"1.168224027","rc":[{"batb":[[2,1.83,29.61]],"batl":[[2,2,38.34]],"ltp":1.9,"tv":1887.88,"id":8908205},{"batb":[[2,2.02,7.18]],"ltp":2.08,"tv":609.27,"id":4596961}]}]}
{"op":"mcm","clk":"1002016449","pt":1580641804354,"mc":[{"id":"1.168224027","rc":[{"batb":[[2,1.84,2]],"batl":[[2,1.94,2.08]],"ltp":1.9,"tv":1887.88,"id":8908205},{"batb":[[2,2.02,9.39]],"batl":[[2,2.22,2]],"ltp":2.08,"tv":609.27,"id":4596961}]}]}
{"op":"mcm","clk":"1002031602","pt":1580641890364,"mc":[{"id":"1.168224027","rc":[{"batb":[[2,1.84,2.1]],"ltp":1.9,"tv":1887.88,"id":8908205},{"batb":[[2,2.02,9.23]],"batl":[[2,2.22,2.07]],"ltp":2.08,"tv":609.27,"id":4596961}]}]}
{"op":"mcm","clk":"1002080099","pt":1580642165076,"mc":[{"id":"1.168224027","rc":[{"batb":[[2,1.84,2.04]],"ltp":1.9,"tv":1887.88,"id":8908205},{"batb":[[2,2.02,9.21]],"batl":[[2,2.22,2.16]],"ltp":2.08,"tv":609.27,"id":4596961}]}]}
{"op":"mcm","clk":"1002080242","pt":1580642165779,"mc":[{"id":"1.168224027","rc":[{"batb":[[2,2.02,2.03]],"ltp":2.08,"tv":609.27,"id":4596961}]}]}
{"op":"mcm","clk":"1002082743","pt":1580642181118,"mc":[{"id":"1.168224027","rc":[{"batb":[[2,1.83,29.61]],"batl":[[2,2,38.34]],"ltp":1.9,"tv":1887.88,"id":8908205},{"batb":[[2,1.9,263.35]],"batl":[[2,2.28,18.48]],"ltp":2.08,"tv":609.27,"id":4596961}]}]}
{"op":"mcm","clk":"1002082775","pt":1580642181325,"mc":[{"id":"1.168224027","rc":[{"batb":[[2,1.84,2]],"batl":[[2,1.94,2.08]],"ltp":1.9,"tv":1887.88,"id":8908205},{"batb":[[2,2.02,2.24]],"batl":[[2,2.22,2.07]],"ltp":2.08,"tv":609.27,"id":4596961}]}]}
{"op":"mcm","clk":"1002090568","pt":1580642230984,"mc":[{"id":"1.168224027","rc":[{"batb":[[0,1.88,420.1],[1,1.87,50.87],[2,1.85,2.17]],"ltp":1.9,"tv":1887.88,"id":8908205}]}]}
{"op":"mcm","clk":"1002090732","pt":1580642231897,"mc":[{"id":"1.168224027","rc":[{"batb":[[2,1.86,2]],"ltp":1.9,"tv":1887.88,"id":8908205},{"batl":[[1,2.18,2],[2,2.2,2.03]],"ltp":2.08,"tv":609.27,"id":4596961}]}]}
{"op":"mcm","clk":"1002090939","pt":1580642233103,"mc":[{"id":"1.168224027","rc":[{"batb":[[1,1.87,456.48]],"ltp":1.9,"tv":1887.88,"id":8908205},{"batl":[[0,2.12,12.6],[1,2.16,10],[2,2.18,2]],"ltp":2.08,"tv":609.27,"id":4596961}]}]}
{"op":"mcm","clk":"1002090992","pt":1580642233391,"mc":[{"id":"1.168224027","rc":[{"batb":[[0,1.89,14.16],[1,1.88,420.1],[2,1.87,458.52]],"ltp":1.9,"tv":1887.88,"id":8908205},{"batl":[[1,2.16,12.22]],"ltp":2.08,"tv":609.27,"id":4596961}]}]}
{"op":"mcm","clk":"1002092207","pt":1580642240909,"mc":[{"id":"1.168224027","rc":[{"batl":[[2,2.18,2.03]],"ltp":2.08,"tv":609.27,"id":4596961}]}]}
{"op":"mcm","clk":"1002092308","pt":1580642241500,"mc":[{"id":"1.168224027","rc":[{"trd":[[2.12,147.05]],"batl":[[0,2.12,1.97],[1,2.16,10]],"ltp":2.12,"tv":630.52,"id":4596961}],"tv":2518.41}]}
{"op":"mcm","clk":"1002093633","pt":1580642247725,"mc":[{"id":"1.168224027","rc":[{"batl":[[2,1.94,34.85]],"ltp":1.9,"tv":1887.88,"id":8908205}]}]}
{"op":"mcm","clk":"1002093777","pt":1580642248311,"mc":[{"id":"1.168224027","rc":[{"batl":[[2,1.94,34.77]],"ltp":1.9,"tv":1887.88,"id":8908205}]}]}
{"op":"mcm","clk":"1002094967","pt":1580642254084,"mc":[{"id":"1.168224027","rc":[{"batb":[[0,1.89,35.61]],"batl":[[2,1.94,343.12]],"ltp":1.9,"tv":1887.88,"id":8908205}]}]}
{"op":"mcm","clk":"1002095178","pt":1580642255065,"mc":[{"id":"1.168224027","rc":[{"trd":[[1.89,341.54]],"batb":[[0,1.89,18.8]],"batl":[[2,1.94,343.18]],"ltp":1.89,"tv":1921.49,"id":8908205}],"tv":2552.02}]}
{"op":"mcm","clk":"1002095472","pt":1580642256551,"mc":[{"id":"1.168224027","rc":[{"batb":[[0,2.08,24.39]],"ltp":2.12,"tv":630.52,"id":4596961}]}]}
{"op":"mcm","clk":"1002095611","pt":1580642257361,"mc":[{"id":"1.168224027","rc":[{"batl":[[2,1.94,34.83]],"ltp":1.89,"tv":1921.49,"id":8908205}]}]}
{"op":"mcm","clk":"1002095958","pt":1580642259328,"mc":[{"id":"1.168224027","rc":[{"batb":[[0,2.08,17.42],[1,2.06,7.04],[2,2.04,2.11]],"ltp":2.12,"tv":630.52,"id":4596961}]}]}
{"op":"mcm","clk":"1002096853","pt":1580642264864,"mc":[{"id":"1.168224027","rc":[{"batl":[[0,2.16,10],[1,2.18,2.03],[2,2.2,2.03]],"ltp":2.12,"tv":630.52,"id":4596961}]}]}
{"op":"mcm","clk":"1002096959","pt":1580642265466,"mc":[{"id":"1.168224027","rc":[{"batl":[[0,1.91,15.93],[2,1.94,34.85]],"ltp":1.89,"tv":1921.49,"id":8908205},{"batb":[[0,2.08,29.09]],"ltp":2.12,"tv":630.52,"id":4596961}]}]}
{"op":"mcm","clk":"1002109755","pt":1580642331930,"mc":[{"id":"1.168224027","rc":[{"trd":[[1.89,373.49]],"batb":[[0,1.89,2.83]],"ltp":1.89,"tv":1953.43,"id":8908205}],"tv":2583.96}]}
{"op":"mcm","clk":"1002177862","pt":1580642714025,"mc":[{"id":"1.168224027","rc":[{"batl":[[2,1.94,34.77]],"ltp":1.89,"tv":1953.43,"id":8908205}]}]}
{"op":"mcm","clk":"1002179005","pt":1580642720553,"mc":[{"id":"1.168224027","rc":[{"batl":[[2,1.94,34.85]],"ltp":1.89,"tv":1953.43,"id":8908205}]}]}
{"op":"mcm","clk":"1002183521","pt":1580642745965,"mc":[{"id":"1.168224027","rc":[{"batl":[[2,1.94,32.77]],"ltp":1.89,"tv":1953.43,"id":8908205},{"batl":[[2,2.28,18.48]],"ltp":2.12,"tv":630.52,"id":4596961}]}]}
{"op":"mcm","clk":"1002183555","pt":1580642746173,"mc":[{"id":"1.168224027","rc":[{"batl":[[2,1.94,34.78]],"ltp":1.89,"tv":1953.43,"id":8908205},{"batl":[[2,2.2,2.03]],"ltp":2.12,"tv":630.52,"id":4596961}]}]}
{"op":"mcm","clk":"1002202769","pt":1580642845981,"mc":[{"id":"1.168224027","rc":[{"trd":[[1.88,632.51],[1.89,379.15]],"batb":[[0,1.88,338.91],[1,1.87,458.52],[2,1.86,422.21]],"ltp":1.88,"tv":2121.47,"id":8908205}],"tv":2752.0}]}
{"op":"mcm","clk":"1002203024","pt":1580642847067,"mc":[{"id":"1.168224027","rc":[{"trd":[[1.88,822.51]],"batb":[[0,1.88,243.91],[1,1.87,456.48]],"batl":[[1,1.93,44.18],[2,1.94,34.85]],"ltp":1.88,"tv":2311.47,"id":8908205}],"tv":2942.0}]}
{"op":"mcm","clk":"1002207522","pt":1580642869955,"mc":[{"id":"1.168224027","rc":[{"trd":[[1.88,1028.51]],"batb":[[0,1.88,140.91]],"batl":[[2,1.94,34.84]],"ltp":1.88,"tv":2517.47,"id":8908205}],"tv":3148.0}]}
{"op":"mcm","clk":"1002212473","pt":1580642895107,"mc":[{"id":"1.168224027","rc":[{"batb":[[0,1.89,4.5],[1,1.88,140.91],[2,1.87,456.48]],"ltp":1.88,"tv":2517.47,"id":8908205}]}]}
{"op":"mcm","clk":"1002212614","pt":1580642895853,"mc":[{"id":"1.168224027","rc":[{"batb":[[2,1.87,458.52]],"batl":[[0,1.91,18.93],[2,1.94,34.85]],"ltp":1.88,"tv":2517.47,"id":8908205}]}]}
{"op":"mcm","clk":"1002216471","pt":1580642916001,"mc":[{"id":"1.168224027","rc":[{"batl":[[2,1.94,337.32]],"ltp":1.88,"tv":2517.47,"id":8908205}]}]}
{"op":"mcm","clk":"1002216602","pt":1580642916699,"mc":[{"id":"1.168224027","rc":[{"batl":[[1,1.93,54.12]],"ltp":1.88,"tv":2517.47,"id":8908205}]}]}
{"op":"mcm","clk":"1002217333","pt":1580642920323,"mc":[{"id":"1.168224027","rc":[{"batl":[[2,1.94,304.55]],"ltp":1.88,"tv":2517.47,"id":8908205}]}]}
{"op":"mcm","clk":"1002243178","pt":1580643064577,"mc":[{"id":"1.168224027","rc":[{"batl":[[2,1.94,304.54]],"ltp":1.88,"tv":2517.47,"id":8908205}]}]}
{"op":"mcm","clk":"1002245070","pt":1580643074952,"mc":[{"id":"1.168224027","rc":[{"batl":[[2,1.94,302.47]],"ltp":1.88,"tv":2517.47,"id":8908205},{"batl":[[2,2.28,18.48]],"ltp":2.12,"tv":630.52,"id":4596961}]}]}
{"op":"mcm","clk":"1002245104","pt":1580643075167,"mc":[{"id":"1.168224027","rc":[{"batl":[[2,1.94,304.55]],"ltp":1.88,"tv":2517.47,"id":8908205},{"batl":[[2,2.2,2.03]],"ltp":2.12,"tv":630.52,"id":4596961}]}]}
{"op":"mcm","clk":"1002355944","pt":1580643673820,"mc":[{"id":"1.168224027","rc":[{"batl":[[2,2.2,2]],"ltp":2.12,"tv":630.52,"id":4596961}]}]}
{"op":"mcm","clk":"1002415282","pt":1580644006069,"mc":[{"id":"1.168224027","rc":[{"batl":[[1,1.93,33.01]],"ltp":1.88,"tv":2517.47,"id":8908205}]}]}
{"op":"mcm","clk":"1002415349","pt":1580644006599,"mc":[{"id":"1.168224027","rc":[{"batl":[[2,1.94,304.51]],"ltp":1.88,"tv":2517.47,"id":8908205},{"batl":[[2,2.2,2.03]],"ltp":2.12,"tv":630.52,"id":4596961}]}]}
{"op":"mcm","clk":"1002417754","pt":1580644022009,"mc":[{"id":"1.168224027","rc":[{"trd":[[1.89,419.69]],"batb":[[0,1.88,140.91],[1,1.87,456.48],[2,1.86,422.21]],"batl":[[0,1.91,19.77],[2,1.94,304.55]],"ltp":1.89,"tv":2558.01,"id":8908205}],"tv":3188.54}]}
{"op":"mcm","clk":"1002443795","pt":1580644194776,"mc":[{"id":"1.168224027","rc":[{"trd":[[1.88,1240.51]],"batb":[[0,1.88,34.91]],"ltp":1.88,"tv":2770.01,"id":8908205}],"tv":3400.54}]}
{"op":"mcm","clk":"1002503727","pt":1580644682092,"mc":[{"id":"1.168224027","rc":[{"trd":[[1.88,1270.8]],"batb":[[0,1.88,19.76]],"batl":[[2,1.94,302.47]],"ltp":1.88,"tv":2800.3,"id":8908205},{"batl":[[2,2.28,18.48]],"ltp":2.12,"tv":630.52,"id":4596961}],"tv":3430.83}]}
{"op":"mcm","clk":"1002503774","pt":1580644682507,"mc":[{"id":"1.168224027","rc":[{"trd":[[1.88,1305.72]],"batb":[[0,1.88,2.3]],"batl":[[2,1.94,304.5]],"ltp":1.88,"tv":2835.22,"id":8908205},{"batl":[[2,2.2,2.03]],"ltp":2.12,"tv":630.52,"id":4596961}],"tv":3465.75}]}
{"op":"mcm","clk":"1002514749","pt":1580644775116,"mc":[{"id":"1.168224027","rc":[{"batl":[[1,1.93,12.01],[2,1.94,304.47]],"ltp":1.88,"tv":2835.22,"id":8908205}]}]}
{"op":"mcm","clk":"1002529134","pt":1580644885837,"mc":[{"id":"1.168224027","rc":[{"batb":[[0,1.88,38.69]],"ltp":1.88,"tv":2835.22,"id":8908205},{"batb":[[0,2.08,46.5]],"ltp":2.12,"tv":630.52,"id":4596961}]}]}
{"op":"mcm","clk":"1002529259","pt":1580644886730,"mc":[{"id":"1.168224027","rc":[{"trd":[[1.88,1375.76]],"batb":[[0,1.88,3.67]],"batl":[[2,1.94,304.55]],"ltp":1.88,"tv":2905.26,"id":8908205}],"tv":3535.79}]}
{"op":"mcm","clk":"1002529406","pt":1580644887866,"mc":[{"id":"1.168224027","rc":[{"batb":[[0,1.87,460.21],[1,1.86,420.1],[2,1.85,2.17]],"ltp":1.88,"tv":2905.26,"id":8908205},{"batb":[[0,2.1,29.34],[1,2.08,46.5],[2,2.06,9.12]],"batl":[[1,2.2,2.03],[2,2.22,2.07]],"ltp":2.12,"tv":630.52,"id":4596961}]}]}
{"op":"mcm","clk":"1002529649","pt":1580644889648,"mc":[{"id":"1.168224027","rc":[{"batb":[[0,2.1,36.25],[2,2.06,2.08]],"ltp":2.12,"tv":630.52,"id":4596961}]}]}
{"op":"mcm","clk":"1002529921","pt":1580644892025,"mc":[{"id":"1.168224027","rc":[{"batl":[[2,1.94,302.47]],"ltp":1.88,"tv":2905.26,"id":8908205},{"batb":[[0,2.1,47.71],[1,2.08,34.83]],"ltp":2.12,"tv":630.52,"id":4596961}]}]}
{"op":"mcm","clk":"1002529948","pt":1580644892248,"mc":[{"id":"1.168224027","rc":[{"batl":[[2,1.94,304.55]],"ltp":1.88,"tv":2905.26,"id":8908205}]}]}
{"op":"mcm","clk":"1002549025","pt":1580645018069,"mc":[{"id":"1.168224027","rc":[{"batb":[[0,2.1,18.37]],"ltp":2.12,"tv":630.52,"id":4596961}]}]}
{"op":"mcm","clk":"1002549133","pt":1580645018555,"mc":[{"id":"1.168224027","rc":[{"batb":[[1,2.08,64.17]],"batl":[[2,2.22,2.03]],"ltp":2.12,"tv":630.52,"id":4596961}]}]}
{"op":"mcm","clk":"1002554297","pt":1580645046917,"mc":[{"id":"1.168224027","rc":[{"batl":[[2,1.94,302.47]],"ltp":1.88,"tv":2905.26,"id":8908205},{"batb":[[0,2.1,371.01]],"batl":[[2,2.28,18.48]],"ltp":2.12,"tv":630.52,"id":4596961}]}]}
{"op":"mcm","clk":"1002554453","pt":1580645048041,"mc":[{"id":"1.168224027","rc":[{"batl":[[1,1.93,2.07],[2,1.94,304.55]],"ltp":1.88,"tv":2905.26,"id":8908205},{"batl":[[2,2.22,2.16]],"ltp":2.12,"tv":630.52,"id":4596961}]}]}
{"op":"mcm","clk":"1002554584","pt":1580645048945,"mc":[{"id":"1.168224027","rc":[{"batl":[[0,1.9,22.18],[1,1.91,18.93],[2,1.92,2.06]],"ltp":1.88,"tv":2905.26,"id":8908205}]}]}
{"op":"mcm","clk":"1002558985","pt":1580645077954,"mc":[{"id":"1.168224027","rc":[{"batl":[[0,1.9,34.78],[1,1.91,6.33]],"ltp":1.88,"tv":2905.26,"id":8908205},{"batl":[[2,2.22,4.32]],"ltp":2.12,"tv":630.52,"id":4596961}]}]}
{"op":"mcm","clk":"1002570123","pt":1580645151018,"mc":[{"id":"1.168224027","rc":[{"batb":[[0,1.87,428.4]],"ltp":1.88,"tv":2905.26,"id":8908205},{"batb":[[0,2.1,18.37]],"ltp":2.12,"tv":630.52,"id":4596961}]}]}
{"op":"mcm","clk":"1002570316","pt":1580645152026,"mc":[{"id":"1.168224027","rc":[{"batb":[[0,1.87,420.1]],"ltp":1.88,"tv":2905.26,"id":8908205},{"batb":[[0,2.12,56.77],[1,2.1,242.71],[2,2.08,2.06]],"batl":[[2,2.22,2.16]],"ltp":2.12,"tv":630.52,"id":4596961}]}]}
{"op":"mcm","clk":"1002573270","pt":1580645170975,"mc":[{"id":"1.168224027","rc":[{"batb":[[1,2.1,231.25]],"ltp":2.12,"tv":630.52,"id":4596961}]}]}
{"op":"mcm","clk":"1002573385","pt":1580645171575,"mc":[{"id":"1.168224027","rc":[{"batl":[[2,2.22,2]],"ltp":2.12,"tv":630.52,"id":4596961}]}]}
{"op":"mcm","clk":"1002591663","pt":1580645285083,"mc":[{"id":"1.168224027","rc":[{"batl":[[2,2.22,2.16]],"ltp":2.12,"tv":630.52,"id":4596961}]}]}
{"op":"mcm","clk":"1002593212","pt":1580645294996,"mc":[{"id":"1.168224027","rc":[{"batb":[[1,2.1,215.35]],"batl":[[2,2.22,4.32]],"ltp":2.12,"tv":630.52,"id":4596961}]}]}
{"op":"mcm","clk":"1002620178","pt":1580645466023,"mc":[{"id":"1.168224027","rc":[{"batl":[[2,2.28,18.48]],"ltp":2.12,"tv":630.52,"id":4596961}]}]}
{"op":"mcm","clk":"1002620231","pt":1580645466338,"mc":[{"id":"1.168224027","rc":[{"batl":[[2,2.22,2.07]],"ltp":2.12,"tv":630.52,"id":4596961}]}]}
{"op":"mcm","clk":"1002627337","pt":1580645512999,"mc":[{"id":"1.168224027","rc":[{"batb":[[1,2.1,6.91]],"batl":[[2,2.22,2.16]],"ltp":2.12,"tv":630.52,"id":4596961}]}]}
{"op":"mcm","clk":"1002637098","pt":1580645572899,"mc":[{"id":"1.168224027","rc":[{"trd":[[1.87,123.88]],"batb":[[0,1.87,358.16]],"ltp":1.87,"tv":3029.14,"id":8908205}],"tv":3659.67}]}
{"op":"mcm","clk":"1002637162","pt":1580645573335,"mc":[{"id":"1.168224027","rc":[{"trd":[[1.87,247.99]],"batb":[[0,1.87,296.1]],"ltp":1.87,"tv":3153.25,"id":8908205}],"tv":3783.78}]}
{"op":"mcm","clk":"1002637415","pt":1580645575051,"mc":[{"id":"1.168224027","rc":[{"batl":[[0,1.9,13.44]],"ltp":1.87,"tv":3153.25,"id":8908205},{"batb":[[0,2.12,46.8]],"ltp":2.12,"tv":630.52,"id":4596961}]}]}
{"op":"mcm","clk":"1002637704","pt":1580645576747,"mc":[{"id":"1.168224027","rc":[{"batb":[[1,2.08,9.03],[2,2.06,2.08]],"ltp":2.12,"tv":630.52,"id":4596961}]}]}
{"op":"mcm","clk":"1002638183","pt":1580645579867,"mc":[{"id":"1.168224027","rc":[{"batl":[[2,1.92,23.17]],"ltp":1.87,"tv":3153.25,"id":8908205}]}]}
{"op":"mcm","clk":"1002660375","pt":1580645711776,"mc":[{"id":"1.168224027","rc":[{"batb":[[0,2.1,75.79],[1,2.08,6.97]],"batl":[[2,2.22,2.07]],"ltp":2.12,"tv":630.52,"id":4596961}]}]}
{"op":"mcm","clk":"1002660499","pt":1580645712592,"mc":[{"id":"1.168224027","rc":[{"batl":[[0,1.9,34.78],[2,1.92,2.06]],"ltp":1.87,"tv":3153.25,"id":8908205},{"batb":[[0,2.12,6.85],[1,2.1,75.79]],"ltp":2.12,"tv":630.52,"id":4596961}]}]}
{"op":"mcm","clk":"1002660665","pt":1580645713703,"mc":[{"id":"1.168224027","rc":[{"batb":[[2,2.08,2.06]],"ltp":2.12,"tv":630.52,"id":4596961}]}]}
{"op":"mcm","clk":"1002686000","pt":1580645875965,"mc":[{"id":"1.168224027","rc":[{"batl":[[2,2.28,18.48]],"ltp":2.12,"tv":630.52,"id":4596961}]}]}
{"op":"mcm","clk":"1002686068","pt":1580645876345,"mc":[{"id":"1.168224027","rc":[{"batl":[[2,2.22,2.16]],"ltp":2.12,"tv":630.52,"id":4596961}]}]}
{"op":"mcm","clk":"1002706028","pt":1580646011070,"mc":[{"id":"1.168224027","rc":[{"batl":[[0,1.89,38.7],[1,1.9,33.94],[2,1.91,6.33]],"ltp":1.87,"tv":3153.25,"id":8908205}]}]}
{"op":"mcm","clk":"1002706159","pt":1580646011861,"mc":[{"id":"1.168224027","rc":[{"batl":[[2,1.91,8.38]],"ltp":1.87,"tv":3153.25,"id":8908205}]}]}
{"op":"mcm","clk":"1002707236","pt":1580646019006,"mc":[{"id":"1.168224027","rc":[{"batl":[[0,1.9,34.78],[1,1.91,6.33],[2,1.92,2.06]],"ltp":1.87,"tv":3153.25,"id":8908205},{"batl":[[2,2.28,18.48]],"ltp":2.12,"tv":630.52,"id":4596961}]}]}
{"op":"mcm","clk":"1002707265","pt":1580646019213,"mc":[{"id":"1.168224027","rc":[{"batl":[[2,2.22,2.16]],"ltp":2.12,"tv":630.52,"id":4596961}]}]}
{"op":"mcm","clk":"1002709243","pt":1580646032018,"mc":[{"id":"1.168224027","rc":[{"batl":[[0,1.89,38.7],[1,1.9,33.94],[2,1.91,8.38]],"ltp":1.87,"tv":3153.25,"id":8908205},{"batl":[[2,2.28,18.48]],"ltp":2.12,"tv":630.52,"id":4596961}]}]}
{"op":"mcm","clk":"1002709280","pt":1580646032224,"mc":[{"id":"1.168224027","rc":[{"batl":[[2,2.22,2.16]],"ltp":2.12,"tv":630.52,"id":4596961}]}]}
{"op":"mcm","clk":"1002714537","pt":1580646063084,"mc":[{"id":"1.168224027","rc":[{"batl":[[0,1.89,55.51],[1,1.9,21.34]],"ltp":1.87,"tv":3153.25,"id":8908205},{"batl":[[2,2.28,18.48]],"ltp":2.12,"tv":630.52,"id":4596961}]}]}
{"op":"mcm","clk":"1002714568","pt":1580646063294,"mc":[{"id":"1.168224027","rc":[{"batl":[[2,2.22,2.16]],"ltp":2.12,"tv":630.52,"id":4596961}]}]}
{"op":"mcm","clk":"1002719944","pt":1580646098025,"mc":[{"id":"1.168224027","rc":[{"batl":[[2,2.28,18.48]],"ltp":2.12,"tv":630.52,"id":4596961}]}]}
{"op":"mcm","clk":"1002719961","pt":1580646098165,"mc":[{"id":"1.168224027","rc":[{"batl":[[2,2.22,2.16]],"ltp":2.12,"tv":630.52,"id":4596961}]}]}
{"op":"mcm","clk":"1002725782","pt":1580646134101,"mc":[{"id":"1.168224027","rc":[{"trd":[[1.88,1510.12]],"batl":[[0,1.88,26.05],[1,1.89,55.51],[2,1.9,23.39]],"ltp":1.88,"tv":3287.62,"id":8908205},{"batl":[[2,2.22,2.07]],"ltp":2.12,"tv":630.52,"id":4596961}],"tv":3918.15}]}
{"op":"mcm","clk":"1002729079","pt":1580646156064,"mc":[{"id":"1.168224027","rc":[{"batl":[[0,1.88,42.95],[1,1.89,38.7]],"ltp":1.88,"tv":3287.62,"id":8908205},{"batl":[[2,2.22,2.16]],"ltp":2.12,"tv":630.52,"id":4596961}]}]}
{"op":"mcm","clk":"1002730087","pt":1580646163088,"mc":[{"id":"1.168224027","rc":[{"batl":[[2,2.22,2.07]],"ltp":2.12,"tv":630.52,"id":4596961}]}]}
{"op":"mcm","clk":"1002773295","pt":1580646439048,"mc":[{"id":"1.168224027","rc":[{"batl":[[0,2.14,2.53],[1,2.16,10],[2,2.18,2.03]],"ltp":2.12,"tv":630.52,"id":4596961}]}]}
{"op":"mcm","clk":"1002785998","pt":1580646518673,"mc":[{"id":"1.168224027","rc":[{"trd":[[2.14,64.99]],"batl":[[0,2.16,10],[1,2.2,2.03],[2,2.22,2.07]],"ltp":2.14,"tv":635.59,"id":4596961}],"tv":3923.22}]}
{"op":"mcm","clk":"1002786127","pt":1580646519299,"mc":[{"id":"1.168224027","rc":[{"batb":[[1,2.1,73.23]],"ltp":2.14,"tv":635.59,"id":4596961}]}]}
{"op":"mcm","clk":"1002800456","pt":1580646605549,"mc":[{"id":"1.168224027","rc":[{"batl":[[2,2.22,2.16]],"ltp":2.14,"tv":635.59,"id":4596961}]}]}
{"op":"mcm","clk":"1002807095","pt":1580646643122,"mc":[{"id":"1.168224027","rc":[{"batl":[[2,2.28,18.48]],"ltp":2.14,"tv":635.59,"id":4596961}]}]}
{"op":"mcm","clk":"1002807130","pt":1580646643324,"mc":[{"id":"1.168224027","rc":[{"batl":[[2,2.22,2.16]],"ltp":2.14,"tv":635.59,"id":4596961}]}]}
{"op":"mcm","clk":"1002827422","pt":1580646755040,"mc":[{"id":"1.168224027","rc":[{"trd":[[1.88,1596.06],[1.89,421.43]],"batl":[[0,1.89,37.83],[1,1.9,21.34],[2,1.91,8.38]],"ltp":1.89,"tv":3375.29,"id":8908205}],"tv":4010.89}]}
{"op":"mcm","clk":"1002832590","pt":1580646781010,"mc":[{"id":"1.168224027","rc":[{"batl":[[2,2.22,2]],"ltp":2.14,"tv":635.59,"id":4596961}]}]}
{"op":"mcm","clk":"1002840539","pt":1580646822062,"mc":[{"id":"1.168224027","rc":[{"trd":[[1.89,432.68]],"batl":[[0,1.89,32.21]],"ltp":1.89,"tv":3386.54,"id":8908205}],"tv":4022.14}]}
{"op":"mcm","clk":"1002840644","pt":1580646822547,"mc":[{"id":"1.168224027","rc":[{"batl":[[2,2.22,2.16]],"ltp":2.14,"tv":635.59,"id":4596961}]}]}
{"op":"mcm","clk":"1003063326","pt":1580647949595,"mc":[{"id":"1.168224027","rc":[{"batl":[[2,2.22,2.07]],"ltp":2.14,"tv":635.59,"id":4596961}]}]}
{"op":"mcm","clk":"1003088573","pt":1580648106112,"mc":[{"id":"1.168224027","rc":[{"trd":[[2.12,157.93]],"batb":[[0,2.12,1.41],[2,2.06,2.08]],"batl":[[2,2.28,18.48]],"ltp":2.12,"tv":646.47,"id":4596961}],"tv":4033.02}]}
{"op":"mcm","clk":"1003088660","pt":1580648106493,"mc":[{"id":"1.168224027","rc":[{"batb":[[2,2.08,2.06]],"batl":[[2,2.22,2]],"ltp":2.12,"tv":646.47,"id":4596961}]}]}
{"op":"mcm","clk":"1003134559","pt":1580648379009,"mc":[{"id":"1.168224027","rc":[{"trd":[[1.89,452.77]],"batl":[[0,1.89,12.12]],"ltp":1.89,"tv":3406.63,"id":8908205},{"trd":[[2.12,178.67]],"batb":[[0,2.1,73.23],[1,2.08,2.04],[2,2.06,2.08]],"batl":[[2,2.22,2.16]],"ltp":2.12,"tv":667.21,"id":4596961}],"tv":4073.84}]}
{"op":"mcm","clk":"1003138679","pt":1580648402944,"mc":[{"id":"1.168224027","rc":[{"batb":[[0,1.87,301.85]],"ltp":1.89,"tv":3406.63,"id":8908205}]}]}
{"op":"mcm","clk":"1003140083","pt":1580648410019,"mc":[{"id":"1.168224027","rc":[{"trd":[[1.87,290]],"batb":[[0,1.87,280.85]],"ltp":1.87,"tv":3448.64,"id":8908205},{"batb":[[2,2.04,24.24]],"batl":[[2,2.28,18.48]],"ltp":2.12,"tv":667.21,"id":4596961}],"tv":4115.85}]}
{"op":"mcm","clk":"1003140123","pt":1580648410218,"mc":[{"id":"1.168224027","rc":[{"batb":[[2,2.06,2.08]],"batl":[[2,2.22,2.16]],"ltp":2.12,"tv":667.21,"id":4596961}]}]}
{"op":"mcm","clk":"1003141595","pt":1580648417666,"mc":[{"id":"1.168224027","rc":[{"batb":[[2,2.04,24.24]],"batl":[[2,2.28,18.48]],"ltp":2.12,"tv":667.21,"id":4596961}]}]}
{"op":"mcm","clk":"1003141678","pt":1580648418146,"mc":[{"id":"1.168224027","rc":[{"batb":[[2,2.06,2.08]],"batl":[[2,2.22,2.07]],"ltp":2.12,"tv":667.21,"id":4596961}]}]}
{"op":"mcm","clk":"1003142721","pt":1580648424089,"mc":[{"id":"1.168224027","rc":[{"batl":[[0,2.14,3.79],[1,2.16,10],[2,2.18,2.03]],"ltp":2.12,"tv":667.21,"id":4596961}]}]}
{"op":"mcm","clk":"1003149864","pt":1580648466088,"mc":[{"id":"1.168224027","rc":[{"batb":[[2,2.04,24.24]],"ltp":2.12,"tv":667.21,"id":4596961}]}]}
{"op":"mcm","clk":"1003149885","pt":1580648466311,"mc":[{"id":"1.168224027","rc":[{"batb":[[2,2.06,2.01]],"ltp":2.12,"tv":667.21,"id":4596961}]}]}
{"op":"mcm","clk":"1003162156","pt":1580648536034,"mc":[{"id":"1.168224027","rc":[{"trd":[[2.14,72.57]],"batl":[[0,2.16,10],[1,2.18,2.03],[2,2.2,2.03]],"ltp":2.14,"tv":674.78,"id":4596961}],"tv":4123.43}]}
{"op":"mcm","clk":"1003162306","pt":1580648536868,"mc":[{"id":"1.168224027","rc":[{"batb":[[0,2.1,69.42]],"batl":[[1,2.2,2.03],[2,2.22,2.07]],"ltp":2.14,"tv":674.78,"id":4596961}]}]}
{"op":"mcm","clk":"1003166107","pt":1580648557759,"mc":[{"id":"1.168224027","rc":[{"batb":[[2,2.06,2.08]],"batl":[[2,2.22,2.16]],"ltp":2.14,"tv":674.78,"id":4596961}]}]}
{"op":"mcm","clk":"1003177853","pt":1580648618908,"mc":[{"id":"1.168224027","rc":[{"trd":[[1.89,475.48]],"batl":[[0,1.9,22.1],[1,1.91,8.38],[2,1.92,244.04]],"ltp":1.89,"tv":3471.36,"id":8908205}],"tv":4146.15}]}
{"op":"mcm","clk":"1003177965","pt":1580648619505,"mc":[{"id":"1.168224027","rc":[{"batl":[[1,1.91,6.33]],"ltp":1.89,"tv":3471.36,"id":8908205},{"batb":[[1,2.06,2.08],[2,2.04,26.33]],"batl":[[2,2.22,2.07]],"ltp":2.14,"tv":674.78,"id":4596961}]}]}
{"op":"mcm","clk":"1003178254","pt":1580648621072,"mc":[{"id":"1.168224027","rc":[{"batl":[[0,1.91,28.31],[1,1.92,241.98],[2,1.93,2.07]],"ltp":1.89,"tv":3471.36,"id":8908205}]}]}
{"op":"mcm","clk":"1003183522","pt":1580648648081,"mc":[{"id":"1.168224027","rc":[{"trd":[[1.89,477],[1.9,229.16]],"batb":[[0,1.88,2],[1,1.87,282.89],[2,1.86,422.28]],"batl":[[0,1.91,27.55],[1,1.92,244.03]],"ltp":1.9,"tv":3515.28,"id":8908205},{"batb":[[2,2.04,2.12]],"batl":[[0,2.16,12],[1,2.18,2.03],[2,2.2,2.03]],"ltp":2.14,"tv":674.78,"id":4596961}],"tv":4190.07}]}
{"op":"mcm","clk":"1003183626","pt":1580648648591,"mc":[{"id":"1.168224027","rc":[{"batb":[[0,1.87,280.85],[1,1.86,420.1],[2,1.85,2.04]],"batl":[[1,1.92,241.98]],"ltp":1.9,"tv":3515.28,"id":8908205},{"batb":[[2,2.04,26.36]],"batl":[[0,2.16,10],[1,2.2,2.03],[2,2.22,2.16]],"ltp":2.14,"tv":674.78,"id":4596961}]}]}
{"op":"mcm","clk":"1003184955","pt":1580648656014,"mc":[{"id":"1.168224027","rc":[{"batl":[[0,1.89,50],[1,1.91,27.55],[2,1.92,241.98]],"ltp":1.9,"tv":3515.28,"id":8908205}]}]}
{"op":"mcm","clk":"1003185139","pt":1580648657086,"mc":[{"id":"1.168224027","rc":[{"batl":[[1,1.91,29.6],[2,1.92,244.04]],"ltp":1.9,"tv":3515.28,"id":8908205},{"batb":[[1,2.08,2.06],[2,2.06,2.02]],"batl":[[2,2.22,2]],"ltp":2.14,"tv":674.78,"id":4596961}]}]}
{"op":"mcm","clk":"1003189586","pt":1580648681993,"mc":[{"id":"1.168224027","rc":[{"batl":[[2,1.92,241.98]],"ltp":1.9,"tv":3515.28,"id":8908205},{"batb":[[2,2.04,24.24]],"batl":[[2,2.28,18.48]],"ltp":2.14,"tv":674.78,"id":4596961}]}]}
{"op":"mcm","clk":"1003189626","pt":1580648682327,"mc":[{"id":"1.168224027","rc":[{"batl":[[2,1.92,244.03]],"ltp":1.9,"tv":3515.28,"id":8908205},{"batb":[[2,2.06,2.08]],"batl":[[2,2.22,2.16]],"ltp":2.14,"tv":674.78,"id":4596961}]}]}
{"op":"mcm","clk":"1003213829","pt":1580648813748,"mc":[{"id":"1.168224027","rc":[{"trd":[[1.89,526.98]],"batl":[[0,1.89,25.01],[2,1.92,244.04]],"ltp":1.89,"tv":3565.26,"id":8908205}],"tv":4240.05}]}
{"op":"mcm","clk":"1003246298","pt":1580648989994,"mc":[{"id":"1.168224027","rc":[{"trd":[[1.87,407.63]],"batb":[[0,1.87,222.03]],"ltp":1.87,"tv":3682.89,"id":8908205}],"tv":4357.68}]}
{"op":"mcm","clk":"1003265819","pt":1580649091045,"mc":[{"id":"1.168224027","rc":[{"batb":[[0,1.88,58.81],[1,1.87,222.03],[2,1.86,422.14]],"batl":[[2,1.92,241.98]],"ltp":1.87,"tv":3682.89,"id":8908205},{"batb":[[2,2.04,24.24]],"batl":[[2,2.28,18.48]],"ltp":2.14,"tv":674.78,"id":4596961}]}]}
{"op":"mcm","clk":"1003265955","pt":1580649091643,"mc":[{"id":"1.168224027","rc":[{"trd":[[1.88,1708.62]],"batb":[[0,1.88,2.54]],"batl":[[2,1.92,244.04]],"ltp":1.88,"tv":3795.45,"id":8908205},{"batb":[[2,2.06,2.08]],"batl":[[1,2.18,2.03],[2,2.2,2.03]],"ltp":2.14,"tv":674.78,"id":4596961}],"tv":4470.23}]}
{"op":"mcm","clk":"1003267080","pt":1580649097118,"mc":[{"id":"1.168224027","rc":[{"trd":[[1.88,1713.69]],"batb":[[0,1.87,222.03],[1,1.86,420.1],[2,1.85,2.17]],"ltp":1.88,"tv":3800.52,"id":8908205},{"batb":[[0,2.1,67.17]],"batl":[[1,2.2,2.03],[2,2.22,2.16]],"ltp":2.14,"tv":674.78,"id":4596961}],"tv":4475.31}]}
{"op":"mcm","clk":"1003280150","pt":1580649163990,"mc":[{"id":"1.168224027","rc":[{"trd":[[2.16,0.54]],"batl":[[0,2.16,9.73]],"ltp":2.16,"tv":675.32,"id":4596961}],"tv":4475.85}]}
{"op":"mcm","clk":"1003366867","pt":1580649663038,"mc":[{"id":"1.168224027","rc":[{"trd":[[1.87,475.68]],"batb":[[0,1.87,188.01]],"ltp":1.87,"tv":3868.58,"id":8908205},{"batb":[[2,2.06,2.04]],"batl":[[2,2.22,2]],"ltp":2.16,"tv":675.32,"id":4596961}],"tv":4543.9}]}
{"op":"mcm","clk":"1003383237","pt":1580649769109,"mc":[{"id":"1.168224027","rc":[{"trd":[[1.87,479.48]],"batb":[[0,1.87,186.11]],"ltp":1.87,"tv":3872.38,"id":8908205}],"tv":4547.7}]}
{"op":"mcm","clk":"1003383323","pt":1580649769703,"mc":[{"id":"1.168224027","rc":[{"batb":[[2,2.06,2]],"batl":[[2,2.22,2.16]],"ltp":2.16,"tv":675.32,"id":4596961}]}]}
{"op":"mcm","clk":"1003435891","pt":1580650098865,"mc":[{"id":"1.168224027","rc":[{"trd":[[1.87,514.85]],"batb":[[0,1.87,168.42]],"ltp":1.87,"tv":3907.74,"id":8908205},{"batb":[[2,2.06,2.08]],"ltp":2.16,"tv":675.32,"id":4596961}],"tv":4583.07}]}
{"op":"mcm","clk":"1003451584","pt":1580650200881,"mc":[{"id":"1.168224027","rc":[{"batl":[[2,1.92,241.98]],"ltp":1.87,"tv":3907.74,"id":8908205},{"batb":[[2,2.04,24.24]],"batl":[[2,2.28,18.48]],"ltp":2.16,"tv":675.32,"id":4596961}]}]}
{"op":"mcm","clk":"1003451629","pt":1580650201495,"mc":[{"id":"1.168224027","rc":[{"batl":[[2,1.92,244.04]],"ltp":1.87,"tv":3907.74,"id":8908205},{"batb":[[2,2.06,2.08]],"batl":[[2,2.22,2.16]],"ltp":2.16,"tv":675.32,"id":4596961}]}]}
{"op":"mcm","clk":"1003454065","pt":1580650214018,"mc":[{"id":"1.168224027","rc":[{"batl":[[2,1.92,241.98]],"ltp":1.87,"tv":3907.74,"id":8908205},{"batb":[[2,2.04,24.24]],"batl":[[2,2.28,18.48]],"ltp":2.16,"tv":675.32,"id":4596961}]}]}
{"op":"mcm","clk":"1003454111","pt":1580650214321,"mc":[{"id":"1.168224027","rc":[{"batl":[[2,1.92,244.04]],"ltp":1.87,"tv":3907.74,"id":8908205},{"batb":[[2,2.06,2.08]],"batl":[[2,2.22,2.16]],"ltp":2.16,"tv":675.32,"id":4596961}]}]}
{"op":"mcm","clk":"1003454678","pt":1580650217954,"mc":[{"id":"1.168224027","rc":[{"trd":[[1.89,551.99]],"batl":[[0,1.91,29.6],[1,1.92,244.04],[2,1.94,302.47]],"ltp":1.89,"tv":3932.75,"id":8908205},{"trd":[[2.12,200.97]],"batl":[[0,2.12,24.87],[1,2.16,9.73],[2,2.2,2.03]],"ltp":2.12,"tv":697.62,"id":4596961}],"tv":4630.38}]}
{"op":"mcm","clk":"1003454848","pt":1580650219123,"mc":[{"id":"1.168224027","rc":[{"batb":[[0,1.87,170.46],[1,1.86,422.28],[2,1.84,2.1]],"batl":[[0,1.91,27.55],[1,1.92,241.98],[2,1.93,2.07]],"ltp":1.89,"tv":3932.75,"id":8908205},{"batb":[[1,2.06,2.08],[2,2.04,2.08]],"batl":[[1,2.16,11.83],[2,2.18,2]],"ltp":2.12,"tv":697.62,"id":4596961}]}]}
{"op":"mcm","clk":"1003455984","pt":1580650226955,"mc":[{"id":"1.168224027","rc":[{"batb":[[1,1.86,420.1],[2,1.83,30.36]],"ltp":1.89,"tv":3932.75,"id":8908205},{"batb":[[2,2.02,24.71]],"batl":[[2,2.28,18.48]],"ltp":2.12,"tv":697.62,"id":4596961}]}]}
{"op":"mcm","clk":"1003456016","pt":1580650227165,"mc":[{"id":"1.168224027","rc":[{"batb":[[1,1.86,422.1]],"ltp":1.89,"tv":3932.75,"id":8908205},{"batb":[[2,2.04,2.12]],"batl":[[2,2.18,2.03]],"ltp":2.12,"tv":697.62,"id":4596961}]}]}
{"op":"mcm","clk":"1003461074","pt":1580650260980,"mc":[{"id":"1.168224027","rc":[{"trd":[[2.12,248.13]],"batl":[[0,2.12,1.29]],"ltp":2.12,"tv":744.78,"id":4596961}],"tv":4677.54}]}
{"op":"mcm","clk":"1003461251","pt":1580650262118,"mc":[{"id":"1.168224027","rc":[{"batb":[[0,1.87,168.42],[1,1.86,420.1],[2,1.85,2.17]],"ltp":1.89,"tv":3932.75,"id":8908205},{"batb":[[2,2.04,2.09]],"batl":[[1,2.16,9.73],[2,2.2,2.03]],"ltp":2.12,"tv":744.78,"id":4596961}]}]}
{"op":"mcm","clk":"1003501659","pt":1580650502119,"mc":[{"id":"1.168224027","rc":[{"batl":[[0,1.9,41.21],[1,1.91,27.55],[2,1.92,241.98]],"ltp":1.89,"tv":3932.75,"id":8908205}]}]}
{"op":"mcm","clk":"1003501852","pt":1580650503035,"mc":[{"id":"1.168224027","rc":[{"batl":[[2,1.92,244.04]],"ltp":1.89,"tv":3932.75,"id":8908205},{"batb":[[2,2.04,2.12]],"ltp":2.12,"tv":744.78,"id":4596961}]}]}
{"op":"mcm","clk":"1003509250","pt":1580650539934,"mc":[{"id":"1.168224027","rc":[{"trd":[[1.9,236.56]],"batl":[[0,1.9,37.51]],"ltp":1.9,"tv":3940.15,"id":8908205}],"tv":4684.94}]}
{"op":"mcm","clk":"1003513166","pt":1580650560033,"mc":[{"id":"1.168224027","rc":[{"batb":[[2,2.02,24.71]],"ltp":2.12,"tv":744.78,"id":4596961}]}]}
{"op":"mcm","clk":"1003513205","pt":1580650560209,"mc":[{"id":"1.168224027","rc":[{"batb":[[2,2.04,2.12]],"ltp":2.12,"tv":744.78,"id":4596961}]}]}
{"op":"mcm","clk":"1003545629","pt":1580650738114,"mc":[{"id":"1.168224027","rc":[{"trd":[[1.89,553.43]],"batl":[[0,1.89,36.06],[1,1.91,29.6]],"ltp":1.89,"tv":3941.6,"id":8908205},{"trd":[[2.12,249.42]],"batb":[[1,2.08,2.06],[2,2.04,24.24]],"batl":[[0,2.16,9.73],[1,2.2,2.03],[2,2.22,2]],"ltp":2.12,"tv":746.07,"id":4596961}],"tv":4687.67}]}
{"op":"mcm","clk":"1003545675","pt":1580650738326,"mc":[{"id":"1.168224027","rc":[{"batb":[[2,2.06,2.08]],"ltp":2.12,"tv":746.07,"id":4596961}]}]}
{"op":"mcm","clk":"1003552211","pt":1580650774042,"mc":[{"id":"1.168224027","rc":[{"batl":[[1,1.91,8.38]],"ltp":1.89,"tv":3941.6,"id":8908205}]}]}
{"op":"mcm","clk":"1003552303","pt":1580650774529,"mc":[{"id":"1.168224027","rc":[{"trd":[[1.87,558.2]],"batb":[[0,1.87,146.74]],"ltp":1.87,"tv":3984.95,"id":8908205},{"batl":[[2,2.22,2.07]],"ltp":2.12,"tv":746.07,"id":4596961}],"tv":4731.03}]}
{"op":"mcm","clk":"1003553837","pt":1580650783846,"mc":[{"id":"1.168224027","rc":[{"trd":[[1.87,561.56]],"batb":[[0,1.87,145.06]],"batl":[[2,1.92,243.98]],"ltp":1.87,"tv":3988.31,"id":8908205},{"batl":[[2,2.22,2.16]],"ltp":2.12,"tv":746.07,"id":4596961}],"tv":4734.39}]}
{"op":"mcm","clk":"1003570738","pt":1580650878533,"mc":[{"id":"1.168224027","rc":[{"batl":[[2,1.92,243.99]],"ltp":1.87,"tv":3988.31,"id":8908205}]}]}
{"op":"mcm","clk":"1003575545","pt":1580650905000,"mc":[{"id":"1.168224027","rc":[{"batb":[[2,2.04,24.24]],"ltp":2.12,"tv":746.07,"id":4596961}]}]}
{"op":"mcm","clk":"1003575637","pt":1580650905483,"mc":[{"id":"1.168224027","rc":[{"batl":[[2,1.92,244.04]],"ltp":1.87,"tv":3988.31,"id":8908205},{"batb":[[2,2.06,2.08]],"ltp":2.12,"tv":746.07,"id":4596961}]}]}
{"op":"mcm","clk":"1003596611","pt":1580651012730,"mc":[{"id":"1.168224027","rc":[{"trd":[[1.87,566.92]],"batb":[[0,1.87,142.38]],"ltp":1.87,"tv":3993.67,"id":8908205},{"batb":[[2,2.06,2.06]],"ltp":2.12,"tv":746.07,"id":4596961}],"tv":4739.75}]}
{"op":"mcm","clk":"1003606014","pt":1580651060105,"mc":[{"id":"1.168224027","rc":[{"batl":[[0,1.9,36.06],[1,1.91,6.33]],"ltp":1.87,"tv":3993.67,"id":8908205},{"batb":[[1,2.06,2.08],[2,2.04,26.33]],"ltp":2.12,"tv":746.07,"id":4596961}]}]}
{"op":"mcm","clk":"1003621419","pt":1580651138810,"mc":[{"id":"1.168224027","rc":[{"batb":[[2,2.04,26.25]],"batl":[[2,2.22,2.07]],"ltp":2.12,"tv":746.07,"id":4596961}]}]}
{"op":"mcm","clk":"1003641291","pt":1580651239052,"mc":[{"id":"1.168224027","rc":[{"batb":[[2,1.96,1.04]],"batl":[[2,2.28,18.48]],"ltp":2.12,"tv":746.07,"id":4596961}]}]}
{"op":"mcm","clk":"1003641333","pt":1580651239266,"mc":[{"id":"1.168224027","rc":[{"batb":[[2,2.04,2.12]],"batl":[[2,2.22,2.07]],"ltp":2.12,"tv":746.07,"id":4596961}]}]}
{"op":"mcm","clk":"1003654256","pt":1580651311114,"mc":[{"id":"1.168224027","rc":[{"batb":[[2,1.96,1.04]],"batl":[[2,2.28,18.48]],"ltp":2.12,"tv":746.07,"id":4596961}]}]}
{"op":"mcm","clk":"1003654296","pt":1580651311267,"mc":[{"id":"1.168224027","rc":[{"batb":[[2,2.04,2.12]],"batl":[[2,2.22,2.07]],"ltp":2.12,"tv":746.07,"id":4596961}]}]}
{"op":"mcm","clk":"1003656391","pt":1580651322022,"mc":[{"id":"1.168224027","rc":[{"batb":[[2,1.96,1.04]],"batl":[[2,2.28,18.48]],"ltp":2.12,"tv":746.07,"id":4596961}]}]}
{"op":"mcm","clk":"1003656435","pt":1580651322227,"mc":[{"id":"1.168224027","rc":[{"batb":[[2,2.04,2.12]],"batl":[[2,2.22,2.16]],"ltp":2.12,"tv":746.07,"id":4596961}]}]}
{"op":"mcm","clk":"1003661410","pt":1580651347045,"mc":[{"id":"1.168224027","rc":[{"batb":[[2,2.04,24.24]],"batl":[[2,2.28,18.48]],"ltp":2.12,"tv":746.07,"id":4596961}]}]}
{"op":"mcm","clk":"1003661450","pt":1580651347253,"mc":[{"id":"1.168224027","rc":[{"batb":[[2,2.04,26.36]],"batl":[[2,2.22,2.07]],"ltp":2.12,"tv":746.07,"id":4596961}]}]}
{"op":"mcm","clk":"1003663837","pt":1580651359033,"mc":[{"id":"1.168224027","rc":[{"batl":[[0,1.89,36.06],[1,1.91,8.38]],"ltp":1.87,"tv":3993.67,"id":8908205},{"batb":[[1,2.08,2.06],[2,2.06,2.08]],"ltp":2.12,"tv":746.07,"id":4596961}]}]}
{"op":"mcm","clk":"1003672355","pt":1580651403519,"mc":[{"id":"1.168224027","rc":[{"batl":[[2,2.22,2.16]],"ltp":2.12,"tv":746.07,"id":4596961}]}]}
{"op":"mcm","clk":"1003689524","pt":1580651492057,"mc":[{"id":"1.168224027","rc":[{"trd":[[1.87,566.95]],"batb":[[0,1.87,142.37]],"ltp":1.87,"tv":3993.7,"id":8908205},{"batb":[[2,2.06,2.05]],"batl":[[2,2.22,2.07]],"ltp":2.12,"tv":746.07,"id":4596961}],"tv":4739.78}]}
{"op":"mcm","clk":"1003704292","pt":1580651574923,"mc":[{"id":"1.168224027","rc":[{"trd":[[1.88,1782.17]],"batl":[[0,1.88,1.82],[1,1.9,2.05],[2,1.91,8.34]],"ltp":1.88,"tv":4062.18,"id":8908205},{"batb":[[2,2.06,2.07]],"batl":[[2,2.22,2.16]],"ltp":2.12,"tv":746.07,"id":4596961}],"tv":4808.26}]}
{"op":"mcm","clk":"1003704428","pt":1580651575759,"mc":[{"id":"1.168224027","rc":[{"batl":[[1,1.91,6.33],[2,1.92,241.98]],"ltp":1.88,"tv":4062.18,"id":8908205},{"batb":[[1,2.06,2.07],[2,2.04,26.3]],"ltp":2.12,"tv":746.07,"id":4596961}]}]}
{"op":"mcm","clk":"1003707224","pt":1580651590576,"mc":[{"id":"1.168224027","rc":[{"batb":[[0,1.87,142.38]],"ltp":1.88,"tv":4062.18,"id":8908205},{"batb":[[2,2.04,26.36]],"batl":[[2,2.22,2.07]],"ltp":2.12,"tv":746.07,"id":4596961}]}]}
{"op":"mcm","clk":"1003726925","pt":1580651700050,"mc":[{"id":"1.168224027","rc":[{"batb":[[2,2.04,26.25]],"batl":[[2,2.22,2.16]],"ltp":2.12,"tv":746.07,"id":4596961}]}]}
{"op":"mcm","clk":"1003727106","pt":1580651700964,"mc":[{"id":"1.168224027","rc":[{"trd":[[1.87,568.95]],"batb":[[0,1.87,141.38]],"ltp":1.87,"tv":4064.18,"id":8908205}],"tv":4810.25}]}
{"op":"mcm","clk":"1003730758","pt":1580651719566,"mc":[{"id":"1.168224027","rc":[{"batb":[[2,2.04,26.36]],"ltp":2.12,"tv":746.07,"id":4596961}]}]}
{"op":"mcm","clk":"1003735025","pt":1580651742910,"mc":[{"id":"1.168224027","rc":[{"trd":[[1.87,573.15]],"batb":[[0,1.87,139.28]],"ltp":1.87,"tv":4068.38,"id":8908205}],"tv":4814.45}]}
{"op":"mcm","clk":"1003751281","pt":1580651830964,"mc":[{"id":"1.168224027","rc":[{"batb":[[2,2.04,24.24]],"batl":[[2,2.28,18.48]],"ltp":2.12,"tv":746.07,"id":4596961}]}]}
{"op":"mcm","clk":"1003751311","pt":1580651831165,"mc":[{"id":"1.168224027","rc":[{"batb":[[2,2.04,26.36]],"batl":[[2,2.22,2.16]],"ltp":2.12,"tv":746.07,"id":4596961}]}]}
{"op":"mcm","clk":"1003774118","pt":1580651949121,"mc":[{"id":"1.168224027","rc":[{"trd":[[1.87,574.45]],"batb":[[0,1.87,138.63]],"ltp":1.87,"tv":4069.68,"id":8908205},{"batb":[[2,2.04,24.24]],"batl":[[2,2.28,18.48]],"ltp":2.12,"tv":746.07,"id":4596961}],"tv":4815.75}]}
{"op":"mcm","clk":"1003774158","pt":1580651949349,"mc":[{"id":"1.168224027","rc":[{"batb":[[2,2.04,26.36]],"batl":[[2,2.22,2.16]],"ltp":2.12,"tv":746.07,"id":4596961}]}]}
{"op":"mcm","clk":"1003776302","pt":1580651959893,"mc":[{"id":"1.168224027","rc":[{"batl":[[0,1.91,6.33],[1,1.92,241.98],[2,1.93,2.07]],"ltp":1.87,"tv":4069.68,"id":8908205},{"batl":[[2,2.22,2]],"ltp":2.12,"tv":746.07,"id":4596961}]}]}
{"op":"mcm","clk":"1003783255","pt":1580651995872,"mc":[{"id":"1.168224027","rc":[{"batl":[[2,2.22,2.07]],"ltp":2.12,"tv":746.07,"id":4596961}]}]}
{"op":"mcm","clk":"1003792781","pt":1580652039634,"mc":[{"id":"1.168224027","rc":[{"batl":[[0,1.9,71.42],[1,1.91,6.33],[2,1.92,241.98]],"ltp":1.87,"tv":4069.68,"id":8908205}]}]}
{"op":"mcm","clk":"1003797919","pt":1580652065738,"mc":[{"id":"1.168224027","rc":[{"batb":[[2,1.82,142.49]],"ltp":1.87,"tv":4069.68,"id":8908205},{"batb":[[1,2.04,24.24],[2,1.96,1.04]],"batl":[[1,2.28,18.48],[2,4.2,153.72]],"ltp":2.12,"tv":746.07,"id":4596961}]}]}
{"op":"mcm","clk":"1003804455","pt":1580652097370,"mc":[{"id":"1.168224027","rc":[{"batb":[[2,1.85,72.7]],"ltp":1.87,"tv":4069.68,"id":8908205},{"batb":[[1,2.04,130.77]],"ltp":2.12,"tv":746.07,"id":4596961}]}]}
{"op":"mcm","clk":"1003821641","pt":1580652175937,"mc":[{"id":"1.168224027","rc":[{"trd":[[1.88,2064.27]],"batb":[[0,1.88,473.05],[1,1.87,138.63],[2,1.86,420.1]],"ltp":1.88,"tv":4351.78,"id":8908205},{"batb":[[1,2.04,106.54],[2,2.02,24.71]],"ltp":2.12,"tv":746.07,"id":4596961}],"tv":5097.86}]}
{"op":"mcm","clk":"1003821902","pt":1580652177014,"mc":[{"id":"1.168224027","rc":[{"trd":[[1.88,2070.27]],"batb":[[0,1.88,470.05]],"ltp":1.88,"tv":4357.78,"id":8908205}],"tv":5103.86}]}
{"op":"mcm","clk":"1003823937","pt":1580652185875,"mc":[{"id":"1.168224027","rc":[{"batb":[[2,2.02,65.88]],"batl":[[1,2.24,33.61],[2,2.28,18.48]],"ltp":2.12,"tv":746.07,"id":4596961}]}]}
{"op":"mcm","clk":"1003824171","pt":1580652186854,"mc":[{"id":"1.168224027","rc":[{"batb":[[1,2.06,104.25]],"ltp":2.12,"tv":746.07,"id":4596961}]}]}
{"op":"mcm","clk":"1003826000","pt":1580652194867,"mc":[{"id":"1.168224027","rc":[{"trd":[[1.88,2418.28]],"batb":[[0,1.88,296.04]],"ltp":1.88,"tv":4705.79,"id":8908205}],"tv":5451.86}]}
{"op":"mcm","clk":"1003827037","pt":1580652199402,"mc":[{"id":"1.168224027","rc":[{"batb":[[1,2.08,101.89]],"ltp":2.12,"tv":746.07,"id":4596961}]}]}
{"op":"mcm","clk":"1003829447","pt":1580652209534,"mc":[{"id":"1.168224027","rc":[{"batb":[[0,1.88,296.05]],"ltp":1.88,"tv":4705.79,"id":8908205}]}]}
{"op":"mcm","clk":"1003834965","pt":1580652232975,"mc":[{"id":"1.168224027","rc":[{"trd":[[1.88,3010.06]],"batb":[[0,1.87,138.63],[1,1.86,420.1],[2,1.85,45.29]],"batl":[[0,1.88,210.77],[1,1.9,71.42],[2,1.91,6.33]],"ltp":1.88,"tv":5297.57,"id":8908205}],"tv":6043.64}]}
{"op":"mcm","clk":"1003835183","pt":1580652233889,"mc":[{"id":"1.168224027","rc":[{"batb":[[2,2.04,24.24]],"ltp":2.12,"tv":746.07,"id":4596961}]}]}
{"op":"mcm","clk":"1003836274","pt":1580652238583,"mc":[{"id":"1.168224027","rc":[{"batb":[[2,1.85,63.4]],"ltp":1.88,"tv":5297.57,"id":8908205},{"batb":[[0,2.1,51.26]],"ltp":2.12,"tv":746.07,"id":4596961}]}]}
{"op":"mcm","clk":"1003844627","pt":1580652274098,"mc":[{"id":"1.168224027","rc":[{"batl":[[2,4.2,153.72]],"ltp":2.12,"tv":746.07,"id":4596961}]}]}
{"op":"mcm","clk":"1003848268","pt":1580652289708,"mc":[{"id":"1.168224027","rc":[{"batb":[[2,1.84,85.67]],"ltp":1.88,"tv":5297.57,"id":8908205},{"batb":[[0,2.1,50.81]],"ltp":2.12,"tv":746.07,"id":4596961}]}]}
{"op":"mcm","clk":"1003858478","pt":1580652330433,"mc":[{"id":"1.168224027","rc":[{"batb":[[0,2.1,150.35],[1,2.04,24.24],[2,2.02,65.88]],"ltp":2.12,"tv":746.07,"id":4596961}]}]}
{"op":"mcm","clk":"1003864190","pt":1580652354115,"mc":[{"id":"1.168224027","rc":[{"batb":[[0,2.1,149.4]],"ltp":2.12,"tv":746.07,"id":4596961}]}]}
{"op":"mcm","clk":"1003870564","pt":1580652381049,"mc":[{"id":"1.168224027","rc":[{"trd":[[1.88,3145.09]],"batl":[[0,1.88,143.29]],"ltp":1.88,"tv":5432.6,"id":8908205}],"tv":6178.68}]}
{"op":"mcm","clk":"1003870772","pt":1580652381954,"mc":[{"id":"1.168224027","rc":[{"batb":[[0,2.1,148.46]],"ltp":2.12,"tv":746.07,"id":4596961}]}]}
{"op":"mcm","clk":"1003875886","pt":1580652403091,"mc":[{"id":"1.168224027","rc":[{"batb":[[0,2.1,50.81]],"ltp":2.12,"tv":746.07,"id":4596961}]}]}
{"op":"mcm","clk":"1003876018","pt":1580652403595,"mc":[{"id":"1.168224027","marketDefinition":{"bspMarket":false,"turnInPlayEnabled":true,"persistenceEnabled":true,"marketBaseRate":5.0,"eventId":"29681672","eventTypeId":"2","numberOfWinners":1,"bettingType":"ODDS","marketType":"MATCH_ODDS","marketTime":"2020-02-02T14:00:00.000Z","suspendTime":"2020-02-02T14:00:00.000Z","bspReconciled":false,"complete":true,"inPlay":true,"crossMatching":true,"runnersVoidable":false,"numberOfActiveRunners":2,"betDelay":3,"status":"OPEN","runners":[{"status":"ACTIVE","sortPriority":1,"id":8908205,"name":"Juan Pablo Ficovich"},{"status":"ACTIVE","sortPriority":2,"id":4596961,"name":"Filip Horansky"}],"regulators":["MR_INT"],"countryCode":"AR","discountAllowed":true,"timezone":"UTC","openDate":"2020-02-02T14:00:00.000Z","version":3149116740,"name":"Match Odds","eventName":"Ficovich v Horansky"},"rc":[{"batb":[[0,1.78,39.4],[1,1.27,101.31],[2,1.11,37.96]],"batl":[[1,1.91,3.33],[2,1.96,3.6]],"ltp":1.88,"tv":5432.6,"id":8908205},{"batb":[[0,1.11,37.97],[1,1.05,152.3],[2,1.04,169.36]],"batl":[[1,1000,0.02],[2,4.2,0]],"ltp":2.12,"tv":746.07,"id":4596961}]}]}
{"op":"mcm","clk":"1003876886","pt":1580652407004,"mc":[{"id":"1.168224027","rc":[{"batb":[[0,1.8,52.11],[1,1.78,39.39],[2,1.27,101.31]],"batl":[[1,1.96,3.6],[2,1.97,42.01]],"ltp":1.88,"tv":5432.6,"id":8908205},{"batb":[[0,2.02,41.17],[1,1.11,37.97],[2,1.05,152.3]],"batl":[[1,2.24,33.61],[2,1000,0.02]],"ltp":2.12,"tv":746.07,"id":4596961}]}]}
{"op":"mcm","clk":"1003876959","pt":1580652407313,"mc":[{"id":"1.168224027","rc":[{"batb":[[0,1.78,39.4],[1,1.27,101.31],[2,1.11,37.96]],"batl":[[2,1000,0.4]],"ltp":1.88,"tv":5432.6,"id":8908205},{"batb":[[0,1.11,37.97],[1,1.05,152.3],[2,1.04,169.36]],"batl":[[1,1000,0.02],[2,1000,0]],"ltp":2.12,"tv":746.07,"id":4596961}]}]}
{"op":"mcm","clk":"1003877668","pt":1580652409874,"mc":[{"id":"1.168224027","rc":[{"batl":[[0,1.88,146.68]],"ltp":1.88,"tv":5432.6,"id":8908205}]}]}
{"op":"mcm","clk":"1003877907","pt":1580652410794,"mc":[{"id":"1.168224027","rc":[{"batl":[[1,1.91,184.47],[2,1.93,217.39]],"ltp":1.88,"tv":5432.6,"id":8908205}]}]}
{"op":"mcm","clk":"1003878103","pt":1580652411692,"mc":[{"id":"1.168224027","rc":[{"batl":[[1,1.96,3.6],[2,1000,0.4]],"ltp":1.88,"tv":5432.6,"id":8908205}]}]}
{"op":"mcm","clk":"1003879096","pt":1580652415469,"mc":[{"id":"1.168224027","rc":[{"batb":[[1,1.76,283.47],[2,1.74,298.75]],"batl":[[2,2.02,222.44]],"ltp":1.88,"tv":5432.6,"id":8908205}]}]}
{"op":"mcm","clk":"1003879969","pt":1580652418774,"mc":[{"id":"1.168224027","rc":[{"trd":[[1.88,3146.39]],"batl":[[0,1.88,146.03]],"ltp":1.88,"tv":5433.9,"id":8908205}],"tv":6179.98}]}
{"op":"mcm","clk":"1003880595","pt":1580652421252,"mc":[{"id":"1.168224027","rc":[{"batl":[[2,1000,0.4]],"ltp":1.88,"tv":5433.9,"id":8908205}]}]}
{"op":"mcm","clk":"1003881323","pt":1580652424053,"mc":[{"id":"1.168224027","rc":[{"trd":[[1.86,11.3],[1.87,574.48]],"batb":[[0,1.78,39.39]],"batl":[[0,1.8,3358.28],[1,1.88,146.03],[2,1.89,7.67]],"ltp":1.86,"tv":5445.24,"id":8908205},{"trd":[[2.16,10.27]],"batl":[[0,1000,0.02],[1,1000,0]],"ltp":2.16,"tv":755.8,"id":4596961}],"tv":6201.04}]}
{"op":"mcm","clk":"1003881581","pt":1580652425091,"mc":[{"id":"1.168224027","rc":[{"batl":[[0,1.82,172.84],[1,1.84,252.23],[2,1.88,146.03]],"ltp":1.86,"tv":5445.24,"id":8908205},{"batb":[[0,2.24,81.04],[1,2.12,96.62],[2,1.11,37.97]],"ltp":2.16,"tv":755.8,"id":4596961}]}]}
{"op":"mcm","clk":"1003881761","pt":1580652425755,"mc":[{"id":"1.168224027","rc":[{"batb":[[1,2.14,36.13],[2,2.12,96.62]],"ltp":2.16,"tv":755.8,"id":4596961}]}]}
{"op":"mcm","clk":"1003882219","pt":1580652427485,"mc":[{"id":"1.168224027","rc":[{"batl":[[2,1.87,42.01]],"ltp":1.86,"tv":5445.24,"id":8908205},{"batl":[[0,2.44,28.57],[1,1000,0.02]],"ltp":2.16,"tv":755.8,"id":4596961}]}]}
{"op":"mcm","clk":"1003883118","pt":1580652430874,"mc":[{"id":"1.168224027","rc":[{"batb":[[2,1.74,792.78]],"batl":[[2,1.85,480.59]],"ltp":1.86,"tv":5445.24,"id":8908205}]}]}
{"op":"mcm","clk":"1003884144","pt":1580652434742,"mc":[{"id":"1.168224027","rc":[{"trd":[[1.81,0.34]],"ltp":1.81,"tv":5445.57,"id":8908205},{"trd":[[2.24,0.27]],"batb":[[0,2.24,80.77]],"ltp":2.24,"tv":756.07,"id":4596961}],"tv":6201.65}]}
{"op":"mcm","clk":"1003884355","pt":1580652435514,"mc":[{"id":"1.168224027","rc":[{"batb":[[1,1.74,494.03],[2,1.72,510.84]],"batl":[[0,1.85,480.59],[1,1.87,539.41],[2,1.88,146.03]],"ltp":1.81,"tv":5445.57,"id":8908205},{"batb":[[0,2.14,36.13],[1,2.12,96.46],[2,1.11,37.97]],"ltp":2.24,"tv":756.07,"id":4596961}]}]}
{"op":"mcm","clk":"1003884643","pt":1580652436533,"mc":[{"id":"1.168224027","rc":[{"batl":[[1,1.87,497.4],[2,1.88,142.64]],"ltp":1.81,"tv":5445.57,"id":8908205},{"batb":[[0,2.12,96.46],[1,1.11,37.97],[2,1.05,152.3]],"batl":[[0,1000,0.02],[1,1000,0]],"ltp":2.24,"tv":756.07,"id":4596961}]}]}
{"op":"mcm","clk":"1003885642","pt":1580652440012,"mc":[{"id":"1.168224027","rc":[{"batl":[[0,1.81,3.52],[1,1.85,480.59],[2,1.87,497.4]],"ltp":1.81,"tv":5445.57,"id":8908205}]}]}
{"op":"mcm","clk":"1003885908","pt":1580652440928,"mc":[{"id":"1.168224027","rc":[{"batb":[[1,1.66,212.05],[2,1.65,180.56]],"ltp":1.81,"tv":5445.57,"id":8908205}]}]}
{"op":"mcm","clk":"1003886700","pt":1580652443536,"mc":[{"id":"1.168224027","rc":[{"trd":[[1.66,20.36],[1.78,78.78]],"batb":[[0,1.66,201.87],[1,1.65,180.56],[2,1.63,111.33]],"batl":[[0,1.7,721.07],[1,1.71,235.68],[2,1.73,307.94]],"ltp":1.66,"tv":5544.71,"id":8908205},{"batl":[[0,2.6,11],[1,2.66,387.11],[2,1000,0.02]],"ltp":2.24,"tv":756.07,"id":4596961}],"tv":6300.79}]}
{"op":"mcm","clk":"1003887126","pt":1580652445099,"mc":[{"id":"1.168224027","rc":[{"batb":[[0,2.42,66.09],[1,2.28,77.82],[2,1.11,37.97]],"ltp":2.24,"tv":756.07,"id":4596961}]}]}
{"op":"mcm","clk":"1003887580","pt":1580652446808,"mc":[{"id":"1.168224027","rc":[{"batb":[[1,2.32,31.09],[2,2.28,77.82]],"batl":[[1,2.66,412.32]],"ltp":2.24,"tv":756.07,"id":4596961}]}]}
{"op":"mcm","clk":"1003889413","pt":1580652453517,"mc":[{"id":"1.168224027","rc":[{"batl":[[0,2.66,412.32],[1,1000,0.02],[2,1000,0]],"ltp":2.24,"tv":756.07,"id":4596961}]}]}
{"op":"mcm","clk":"1003890161","pt":1580652456514,"mc":[{"id":"1.168224027","rc":[{"batl":[[0,1.68,14.7],[1,1.7,721.07],[2,1.71,235.68]],"ltp":1.66,"tv":5544.71,"id":8908205},{"batl":[[0,2.56,9.49],[1,2.66,412.32],[2,1000,0.02]],"ltp":2.24,"tv":756.07,"id":4596961}]}]}
{"op":"mcm","clk":"1003890531","pt":1580652458052,"mc":[{"id":"1.168224027","rc":[{"batb":[[0,1.62,494.03],[1,1.61,68.06],[2,1.6,510.84]],"batl":[[0,1.74,480.59],[1,1.76,539.41],[2,1.81,3.52]],"ltp":1.66,"tv":5544.71,"id":8908205},{"batb":[[0,2.32,31.09],[1,2.28,77.82],[2,1.11,37.97]],"batl":[[0,2.66,25.21],[1,1000,0.02],[2,1000,0]],"ltp":2.24,"tv":756.07,"id":4596961}]}]}
{"op":"mcm","clk":"1003890601","pt":1580652458340,"mc":[{"id":"1.168224027","rc":[{"batb":[[1,1.6,510.84],[2,1.56,131.95]],"batl":[[1,1.76,497.4]],"ltp":1.66,"tv":5544.71,"id":8908205},{"batb":[[0,2.28,77.82],[1,1.11,37.97],[2,1.05,152.3]],"batl":[[0,1000,0.02],[1,1000,0]],"ltp":2.24,"tv":756.07,"id":4596961}]}]}
{"op":"mcm","clk":"1003891240","pt":1580652460812,"mc":[{"id":"1.168224027","rc":[{"batb":[[2,1.56,523.05]],"batl":[[2,1.79,232.15]],"ltp":1.66,"tv":5544.71,"id":8908205}]}]}
{"op":"mcm","clk":"1003891557","pt":1580652462010,"mc":[{"id":"1.168224027","rc":[{"batb":[[2,1.56,131.95]],"ltp":1.66,"tv":5544.71,"id":8908205}]}]}
{"op":"mcm","clk":"1003891651","pt":1580652462458,"mc":[{"id":"1.168224027","rc":[{"batl":[[0,1.79,232.15],[1,1.81,269.15],[2,1.88,142.64]],"ltp":1.66,"tv":5544.71,"id":8908205}]}]}
{"op":"mcm","clk":"1003892310","pt":1580652465038,"mc":[{"id":"1.168224027","rc":[{"batb":[[0,1.73,263.33],[1,1.72,13.89],[2,1.71,316.96]],"batl":[[0,1.78,647.91],[1,1.79,232.15],[2,1.81,269.15]],"ltp":1.66,"tv":5544.71,"id":8908205},{"batb":[[0,2.32,7.92],[1,2.28,77.82],[2,1.11,37.97]],"batl":[[0,2.56,977.86],[1,1000,0.02]],"ltp":2.24,"tv":756.07,"id":4596961}]}]}
{"op":"mcm","clk":"1003892584","pt":1580652466042,"mc":[{"id":"1.168224027","rc":[{"batb":[[2,2.22,33.61]],"batl":[[0,2.5,27.73],[1,2.56,977.86],[2,1000,0.02]],"ltp":2.24,"tv":756.07,"id":4596961}]}]}
{"op":"mcm","clk":"1003893024","pt":1580652467657,"mc":[{"id":"1.168224027","rc":[{"batl":[[2,1.81,265.63]],"ltp":1.66,"tv":5544.71,"id":8908205}]}]}
{"op":"mcm","clk":"1003894025","pt":1580652471417,"mc":[{"id":"1.168224027","rc":[{"trd":[[1.73,7.68]],"batb":[[0,1.73,259.49]],"batl":[[2,1.8,480.59]],"ltp":1.73,"tv":5552.39,"id":8908205}],"tv":6308.47}]}
{"op":"mcm","clk":"1003895068","pt":1580652475120,"mc":[{"id":"1.168224027","rc":[{"batb":[[0,1.69,591.44],[1,1.67,573.01],[2,1.6,119.28]],"batl":[[0,1.8,480.59],[1,1.82,539.41],[2,1.88,142.64]],"ltp":1.73,"tv":5552.39,"id":8908205},{"batb":[[0,2.28,77.82],[1,2.22,33.61],[2,2.12,94.5]],"batl":[[1,1000,0.02],[2,1000,0]],"ltp":2.24,"tv":756.07,"id":4596961}]}]}
{"op":"mcm","clk":"1003895102","pt":1580652475182,"mc":[{"id":"1.168224027","rc":[{"batb":[[0,1.69,494.03]],"ltp":1.73,"tv":5552.39,"id":8908205},{"batb":[[0,2.22,33.61],[1,2.12,94.5],[2,1.11,37.97]],"ltp":2.24,"tv":756.07,"id":4596961}]}]}
{"op":"mcm","clk":"1003895471","pt":1580652476474,"mc":[{"id":"1.168224027","rc":[{"batb":[[1,1.67,510.84]],"batl":[[1,1.82,497.4]],"ltp":1.73,"tv":5552.39,"id":8908205},{"batb":[[0,2.12,94.5],[1,1.11,37.97],[2,1.05,152.3]],"batl":[[0,1000,0.02],[1,1000,0]],"ltp":2.24,"tv":756.07,"id":4596961}]}]}
{"op":"mcm","clk":"1003895910","pt":1580652478101,"mc":[{"id":"1.168224027","rc":[{"batb":[[2,1.61,297.34]],"ltp":1.73,"tv":5552.39,"id":8908205}]}]}
{"op":"mcm","clk":"1003895963","pt":1580652478277,"mc":[{"id":"1.168224027","rc":[{"batb":[[2,1.6,119.28]],"ltp":1.73,"tv":5552.39,"id":8908205}]}]}
{"op":"mcm","clk":"1003896614","pt":1580652480711,"mc":[{"id":"1.168224027","rc":[{"batb":[[0,1.71,179.8],[1,1.69,823.79],[2,1.67,510.84]],"batl":[[0,1.76,199.76],[1,1.78,280.5],[2,1.8,480.59]],"ltp":1.73,"tv":5552.39,"id":8908205}]}]}
{"op":"mcm","clk":"1003896973","pt":1580652482082,"mc":[{"id":"1.168224027","rc":[{"batb":[[0,1.69,494.03],[1,1.67,510.84],[2,1.6,119.28]],"batl":[[0,1.8,480.59],[1,1.82,497.4],[2,1.88,142.64]],"ltp":1.73,"tv":5552.39,"id":8908205}]}]}
{"op":"mcm","clk":"1003897788","pt":1580652485102,"mc":[{"id":"1.168224027","rc":[{"batb":[[2,1.61,297.34]],"ltp":1.73,"tv":5552.39,"id":8908205}]}]}
{"op":"mcm","clk":"1003898001","pt":1580652485929,"mc":[{"id":"1.168224027","rc":[{"batb":[[0,1.6,119.28],[1,1.27,101.31],[2,1.11,37.96]],"ltp":1.73,"tv":5552.39,"id":8908205}]}]}
{"op":"mcm","clk":"1003898837","pt":1580652488907,"mc":[{"id":"1.168224027","rc":[{"batb":[[0,1.61,297.34],[1,1.6,321.56],[2,1.27,101.31]],"batl":[[0,1.62,10.19],[1,1.66,234.38],[2,1.68,340.2]],"ltp":1.73,"tv":5552.39,"id":8908205},{"batb":[[0,2.56,399.73],[1,2.48,118.18],[2,2.12,94.5]],"batl":[[0,2.72,13.6],[1,2.84,522.17],[2,1000,0.02]],"ltp":2.24,"tv":756.07,"id":4596961}]}]}
{"op":"mcm","clk":"1003899058","pt":1580652489695,"mc":[{"id":"1.168224027","rc":[{"batb":[[2,1.57,73.1]],"ltp":1.73,"tv":5552.39,"id":8908205},{"batb":[[1,2.48,180.02],[2,2.42,29.41]],"batl":[[1,2.78,23.53],[2,2.84,522.17]],"ltp":2.24,"tv":756.07,"id":4596961}]}]}
{"op":"mcm","clk":"1003900647","pt":1580652495067,"mc":[{"id":"1.168224027","rc":[{"batl":[[1,1.64,480.59],[2,1.66,731.78]],"ltp":1.73,"tv":5552.39,"id":8908205}]}]}
{"op":"mcm","clk":"1003902780","pt":1580652503086,"mc":[{"id":"1.168224027","rc":[{"batl":[[0,1.64,480.59],[1,1.66,731.78],[2,1.68,340.2]],"ltp":1.73,"tv":5552.39,"id":8908205},{"batb":[[0,2.48,61.84],[1,2.42,29.41],[2,2.32,74.35]],"batl":[[0,2.78,23.53],[1,1000,0.02],[2,2.84,0]],"ltp":2.24,"tv":756.07,"id":4596961}]}]}
{"op":"mcm","clk":"1003902908","pt":1580652503480,"mc":[{"id":"1.168224027","rc":[{"batb":[[0,1.57,73.1],[1,1.53,140.05],[2,1.27,101.31]],"batl":[[1,1.66,497.4],[2,1.7,42.01]],"ltp":1.73,"tv":5552.39,"id":8908205},{"batb":[[0,2.42,29.41],[1,2.32,74.35],[2,1.11,37.97]],"ltp":2.24,"tv":756.07,"id":4596961}]}]}
{"op":"mcm","clk":"1003903179","pt":1580652504498,"mc":[{"id":"1.168224027","rc":[{"batb":[[0,1.53,140.05],[1,1.27,101.31],[2,1.11,37.96]],"batl":[[2,1.88,142.64]],"ltp":1.73,"tv":5552.39,"id":8908205},{"batb":[[0,2.32,74.35],[1,1.11,37.97],[2,1.05,152.3]],"batl":[[0,1000,0.02],[1,1000,0]],"ltp":2.24,"tv":756.07,"id":4596961}]}]}
{"op":"mcm","clk":"1003903684","pt":1580652506390,"mc":[{"id":"1.168224027","rc":[{"batb":[[1,1.52,247.97],[2,1.51,252.45]],"batl":[[2,1.74,203.1]],"ltp":1.73,"tv":5552.39,"id":8908205}]}]}
{"op":"mcm","clk":"1003904306","pt":1580652508780,"mc":[{"id":"1.168224027","rc":[{"batl":[[0,1.64,480.98]],"ltp":1.73,"tv":5552.39,"id":8908205}]}]}
{"op":"mcm","clk":"1003906051","pt":1580652515243,"mc":[{"id":"1.168224027","rc":[{"batl":[[2,1.88,142.64]],"ltp":1.73,"tv":5552.39,"id":8908205}]}]}
{"op":"mcm","clk":"1003906797","pt":1580652518064,"mc":[{"id":"1.168224027","rc":[{"trd":[[1.53,280.1]],"batb":[[0,1.52,247.97],[1,1.51,252.45],[2,1.27,101.31]],"batl":[[0,1.53,1251.29],[1,1.56,3862.89],[2,1.6,1357.08]],"ltp":1.53,"tv":5832.5,"id":8908205}],"tv":6588.57}]}
{"op":"mcm","clk":"1003907037","pt":1580652518959,"mc":[{"id":"1.168224027","rc":[{"trd":[[1.52,10.3]],"batb":[[0,1.52,237.67],[2,1.47,163.04]],"batl":[[0,1.53,139.13],[1,1.56,256.05],[2,1.57,215.27]],"ltp":1.52,"tv":5842.8,"id":8908205},{"trd":[[2.94,5.33]],"batb":[[0,2.88,415.68],[1,2.66,51.22],[2,2.48,62.32]],"batl":[[0,3.05,7.09],[1,3.2,341.75],[2,1000,0.02]],"ltp":2.94,"tv":761.4,"id":4596961}],"tv":6604.2}]}
{"op":"mcm","clk":"1003907906","pt":1580652522145,"mc":[{"id":"1.168224027","rc":[{"batl":[[2,3.35,17.64]],"ltp":2.94,"tv":761.4,"id":4596961}]}]}
{"op":"mcm","clk":"1003909131","pt":1580652526559,"mc":[{"id":"1.168224027","rc":[{"trd":[[1.53,283.47]],"batl":[[0,1.53,137.45]],"ltp":1.53,"tv":5846.16,"id":8908205}],"tv":6607.56}]}
{"op":"mcm","clk":"1003909520","pt":1580652527953,"mc":[{"id":"1.168224027","rc":[{"batb":[[1,1.51,399.19],[2,1.46,170.67]],"batl":[[0,1.53,179.46]],"ltp":1.53,"tv":5846.16,"id":8908205},{"batb":[[0,2.9,21.85],[1,2.88,415.68],[2,2.8,48.39]],"ltp":2.94,"tv":761.4,"id":4596961}]}]}
{"op":"mcm","clk":"1003909628","pt":1580652528374,"mc":[{"id":"1.168224027","rc":[{"batl":[[0,3.2,341.75],[1,3.35,17.64],[2,1000,0.02]],"ltp":2.94,"tv":761.4,"id":4596961}]}]}
{"op":"mcm","clk":"1003910470","pt":1580652531305,"mc":[{"id":"1.168224027","rc":[{"trd":[[1.52,30.82]],"batb":[[0,1.52,227.41]],"ltp":1.52,"tv":5866.68,"id":8908205},{"batl":[[0,3,5.57],[1,3.2,341.75],[2,3.35,17.64]],"ltp":2.94,"tv":761.4,"id":4596961}],"tv":6628.08}]}
{"op":"mcm","clk":"1003911124","pt":1580652533596,"mc":[{"id":"1.168224027","rc":[{"trd":[[1.52,130.82]],"batb":[[0,1.52,177.41]],"ltp":1.52,"tv":5966.68,"id":8908205}],"tv":6728.08}]}
{"op":"mcm","clk":"1003911695","pt":1580652535518,"mc":[{"id":"1.168224027","rc":[{"batb":[[2,1.45,173.35]],"ltp":1.52,"tv":5966.68,"id":8908205},{"batb":[[2,2.82,47.37]],"ltp":2.94,"tv":761.4,"id":4596961}]}]}
{"op":"mcm","clk":"1003911996","pt":1580652536611,"mc":[{"id":"1.168224027","rc":[{"batb":[[0,1.52,222.55]],"batl":[[1,1.56,280.86]],"ltp":1.52,"tv":5966.68,"id":8908205}]}]}
{"op":"mcm","clk":"1003912158","pt":1580652537213,"mc":[{"id":"1.168224027","rc":[{"trd":[[1.53,284.77]],"batl":[[0,1.53,178.81]],"ltp":1.53,"tv":5967.98,"id":8908205}],"tv":6729.39}]}
{"op":"mcm","clk":"1003913259","pt":1580652541428,"mc":[{"id":"1.168224027","rc":[{"batl":[[0,3.2,341.75],[1,3.35,17.64],[2,1000,0.02]],"ltp":2.94,"tv":761.4,"id":4596961}]}]}
{"op":"mcm","clk":"1003914068","pt":1580652544427,"mc":[{"id":"1.168224027","rc":[{"batb":[[1,2.88,422.09]],"batl":[[0,2.96,5.28],[1,3.2,341.75],[2,3.35,17.64]],"ltp":2.94,"tv":761.4,"id":4596961}]}]}
{"op":"mcm","clk":"1003914907","pt":1580652547820,"mc":[{"id":"1.168224027","rc":[{"trd":[[1.52,132.8]],"batb":[[0,1.52,221.56]],"ltp":1.52,"tv":5969.96,"id":8908205}],"tv":6731.37}]}
{"op":"mcm","clk":"1003916942","pt":1580652555853,"mc":[{"id":"1.168224027","rc":[{"batb":[[0,1.51,146.74],[1,1.45,173.35],[2,1.43,97.46]],"batl":[[1,1.6,135.71],[2,1.96,3.99]],"ltp":1.52,"tv":5969.96,"id":8908205}]}]}
{"op":"mcm","clk":"1003917688","pt":1580652558672,"mc":[{"id":"1.168224027","rc":[{"batb":[[1,1.47,396.31],[2,1.46,291.16]],"batl":[[2,1.64,295.02]],"ltp":1.52,"tv":5969.96,"id":8908205}]}]}
{"op":"mcm","clk":"1003918738","pt":1580652562937,"mc":[{"id":"1.168224027","rc":[{"batl":[[0,1.53,42.01],[1,1.64,295.02],[2,1.65,179.91]],"ltp":1.52,"tv":5969.96,"id":8908205},{"batb":[[1,2.82,47.37],[2,2.6,57.67]],"batl":[[0,3.35,17.64],[1,1000,0.02],[2,3.35,0]],"ltp":2.94,"tv":761.4,"id":4596961}]}]}
{"op":"mcm","clk":"1003918859","pt":1580652563382,"mc":[{"id":"1.168224027","rc":[{"batb":[[0,1.47,396.31],[1,1.46,291.16],[2,1.45,173.34]],"ltp":1.52,"tv":5969.96,"id":8908205},{"batb":[[1,2.6,57.67],[2,1.8,75.72]],"ltp":2.94,"tv":761.4,"id":4596961}]}]}
{"op":"mcm","clk":"1003919109","pt":1580652564480,"mc":[{"id":"1.168224027","rc":[{"batl":[[0,1.64,295.02],[1,1.65,179.91],[2,1.96,3.6]],"ltp":1.52,"tv":5969.96,"id":8908205},{"batb":[[0,2.6,57.67],[1,1.8,75.72],[2,1.6,75.72]],"batl":[[0,1000,0.02],[1,1000,0]],"ltp":2.94,"tv":761.4,"id":4596961}]}]}
{"op":"mcm","clk":"1003919352","pt":1580652565567,"mc":[{"id":"1.168224027","rc":[{"batb":[[0,1.48,87.53],[1,1.47,396.3],[2,1.46,291.16]],"ltp":1.52,"tv":5969.96,"id":8908205}]}]}
{"op":"mcm","clk":"1003919566","pt":1580652566460,"mc":[{"id":"1.168224027","rc":[{"batb":[[0,2.64,56.41]],"ltp":2.94,"tv":761.4,"id":4596961}]}]}
{"op":"mcm","clk":"1003919891","pt":1580652567798,"mc":[{"id":"1.168224027","rc":[{"batb":[[2,1.7,75.72]],"ltp":2.94,"tv":761.4,"id":4596961}]}]}
{"op":"mcm","clk":"1003922156","pt":1580652576815,"mc":[{"id":"1.168224027","rc":[{"trd":[[1.48,0.25]],"batb":[[0,1.48,87.29]],"ltp":1.48,"tv":5970.21,"id":8908205},{"trd":[[3.1,0.12]],"ltp":3.1,"tv":761.52,"id":4596961}],"tv":6731.73}]}
{"op":"mcm","clk":"1003922769","pt":1580652579326,"mc":[{"id":"1.168224027","rc":[{"batb":[[1,1.45,173.34],[2,1.27,101.3]],"ltp":1.48,"tv":5970.21,"id":8908205}]}]}
{"op":"mcm","clk":"1003923478","pt":1580652582036,"mc":[{"id":"1.168224027","rc":[{"batb":[[0,1.51,1274.3],[1,1.48,87.29],[2,1.45,173.34]],"batl":[[0,1.62,834.67],[1,1.63,242],[2,1.64,294.63]],"ltp":1.48,"tv":5970.21,"id":8908205},{"batl":[[0,2.7,2292.4],[1,2.72,12.23],[2,2.82,136]],"ltp":3.1,"tv":761.52,"id":4596961}]}]}
{"op":"mcm","clk":"1003923729","pt":1580652583041,"mc":[{"id":"1.168224027","rc":[{"batb":[[0,1.59,272.92],[1,1.58,212.03],[2,1.57,129.12]],"ltp":1.48,"tv":5970.21,"id":8908205},{"batb":[[1,2.44,68.3],[2,1.8,75.72]],"batl":[[0,2.72,12.23],[1,2.82,136],[2,2.88,442.62]],"ltp":3.1,"tv":761.52,"id":4596961}]}]}
{"op":"mcm","clk":"1003923905","pt":1580652583658,"mc":[{"id":"1.168224027","rc":[{"batl":[[0,1.61,42.4],[1,1.62,834.28],[2,1.63,242]],"ltp":1.48,"tv":5970.21,"id":8908205},{"batb":[[0,2.64,81.62]],"ltp":3.1,"tv":761.52,"id":4596961}]}]}
{"op":"mcm","clk":"1003926316","pt":1580652593110,"mc":[{"id":"1.168224027","rc":[{"trd":[[1.59,148.61]],"batb":[[0,1.59,198.62]],"ltp":1.59,"tv":6118.81,"id":8908205},{"batb":[[1,2.46,4.38],[2,2.44,68.3]],"ltp":3.1,"tv":761.52,"id":4596961}],"tv":6880.34}]}
{"op":"mcm","clk":"1003926361","pt":1580652593331,"mc":[{"id":"1.168224027","rc":[{"batb":[[1,2.44,68.3],[2,1.8,75.72]],"ltp":3.1,"tv":761.52,"id":4596961}]}]}
{"op":"mcm","clk":"1003927200","pt":1580652596722,"mc":[{"id":"1.168224027","rc":[{"batb":[[0,1.59,231.86]],"ltp":1.59,"tv":6118.81,"id":8908205}]}]}
{"op":"mcm","clk":"1003927564","pt":1580652598107,"mc":[{"id":"1.168224027","rc":[{"batb":[[0,1.57,129.12],[1,1.55,76.38],[2,1.5,151.7]],"batl":[[1,1.68,27.14],[2,1.71,25.81]],"ltp":1.59,"tv":6118.81,"id":8908205},{"batl":[[0,3.05,23.26],[1,1000,0.02],[2,2.88,0]],"ltp":3.1,"tv":761.52,"id":4596961}]}]}
{"op":"mcm","clk":"1003927750","pt":1580652598838,"mc":[{"id":"1.168224027","rc":[{"batb":[[0,1.55,76.38],[1,1.5,151.7],[2,1.48,87.29]],"batl":[[0,1.71,26.2],[1,1.96,3.6],[2,2,68.78]],"ltp":1.59,"tv":6118.81,"id":8908205},{"batb":[[0,2.44,68.3],[1,1.8,75.72],[2,1.7,75.72]],"batl":[[0,3.05,3.1]],"ltp":3.1,"tv":761.52,"id":4596961}]}]}
{"op":"mcm","clk":"1003928053","pt":1580652600088,"mc":[{"id":"1.168224027","rc":[{"batb":[[2,1.49,35.01]],"ltp":1.59,"tv":6118.81,"id":8908205},{"batb":[[1,2.4,4.36],[2,1.8,75.72]],"ltp":3.1,"tv":761.52,"id":4596961}]}]}
{"op":"mcm","clk":"1003928531","pt":1580652602109,"mc":[{"id":"1.168224027","rc":[{"batb":[[1,1.53,270.36],[2,1.52,246.42]],"batl":[[1,1.74,237.52],[2,1.76,291.28]],"ltp":1.59,"tv":6118.81,"id":8908205}]}]}
{"op":"mcm","clk":"1003929548","pt":1580652606107,"mc":[{"id":"1.168224027","rc":[{"batb":[[1,1.51,150.05],[2,1.49,35.01]],"batl":[[1,1.96,3.6],[2,2,68.78]],"ltp":1.59,"tv":6118.81,"id":8908205}]}]}
{"op":"mcm","clk":"1003930241","pt":1580652609014,"mc":[{"id":"1.168224027","rc":[{"trd":[[1.61,0.78]],"batb":[[0,1.69,174.18],[1,1.64,153.48],[2,1.55,76.38]],"batl":[[0,1.71,25.81],[1,1.75,249],[2,1.96,3.6]],"ltp":1.61,"tv":6119.6,"id":8908205},{"trd":[[2.44,14.14]],"batb":[[0,2.44,61.23],[2,2.36,543.53]],"batl":[[0,2.54,170],[1,2.6,501.54],[2,3.05,3.1]],"ltp":2.44,"tv":775.66,"id":4596961}],"tv":6895.26}]}
{"op":"mcm","clk":"1003930459","pt":1580652609926,"mc":[{"id":"1.168224027","rc":[{"batb":[[1,1.68,338.47],[2,1.66,352.4]],"batl":[[0,1.7,42.01],[1,1.71,25.81],[2,1.74,237.52]],"ltp":1.61,"tv":6119.6,"id":8908205}]}]}
{"op":"mcm","clk":"1003931171","pt":1580652613038,"mc":[{"id":"1.168224027","rc":[{"trd":[[1.69,21.84]],"batb":[[0,1.69,163.26]],"ltp":1.69,"tv":6141.44,"id":8908205},{"batb":[[1,2.42,29.41],[2,2.4,4.36]],"batl":[[2,2.74,23.53]],"ltp":2.44,"tv":775.66,"id":4596961}],"tv":6917.1}]}
{"op":"mcm","clk":"1003931959","pt":1580652616026,"mc":[{"id":"1.168224027","rc":[{"batl":[[2,1.74,718.11]],"ltp":1.69,"tv":6141.44,"id":8908205},{"batl":[[2,2.68,3.39]],"ltp":2.44,"tv":775.66,"id":4596961}]}]}
{"op":"mcm","clk":"1003933434","pt":1580652621942,"mc":[{"id":"1.168224027","rc":[{"batl":[[2,1.72,10.69]],"ltp":1.69,"tv":6141.44,"id":8908205},{"batl":[[0,2.46,9.28],[1,2.54,170],[2,2.6,501.54]],"ltp":2.44,"tv":775.66,"id":4596961}]}]}
{"op":"mcm","clk":"1003933667","pt":1580652622838,"mc":[{"id":"1.168224027","rc":[{"trd":[[1.69,50.84]],"batb":[[0,1.69,148.76]],"ltp":1.69,"tv":6170.44,"id":8908205}],"tv":6946.1}]}
{"op":"mcm","clk":"1003935569","pt":1580652630056,"mc":[{"id":"1.168224027","rc":[{"batb":[[0,1.68,338.47],[1,1.66,352.4],[2,1.65,494.03]],"batl":[[1,1.74,718.11],[2,1.76,788.68]],"ltp":1.69,"tv":6170.44,"id":8908205},{"batb":[[2,2.26,83.87]],"batl":[[0,2.68,3.39],[1,2.74,23.53],[2,2.76,3.02]],"ltp":2.44,"tv":775.66,"id":4596961}]}]}
{"op":"mcm","clk":"1003935714","pt":1580652630542,"mc":[{"id":"1.168224027","rc":[{"batb":[[0,1.65,494.03],[1,1.63,510.84],[2,1.61,68.87]],"batl":[[0,1.74,480.59],[1,1.76,497.4],[2,1.96,3.6]],"ltp":1.69,"tv":6170.44,"id":8908205},{"batb":[[0,2.26,83.87],[1,1.76,23.23],[2,1.7,75.72]],"batl":[[1,2.76,3.02],[2,3.05,3.1]],"ltp":2.44,"tv":775.66,"id":4596961}]}]}
{"op":"mcm","clk":"1003936390","pt":1580652633193,"mc":[{"id":"1.168224027","rc":[{"batb":[[2,1.62,181.68]],"batl":[[2,1.86,215.89]],"ltp":1.69,"tv":6170.44,"id":8908205}]}]}
{"op":"mcm","clk":"1003936789","pt":1580652634877,"mc":[{"id":"1.168224027","rc":[{"batb":[[0,1.62,181.68],[1,1.61,266.39],[2,1.6,30.74]],"batl":[[2,1.96,3.6]],"ltp":1.69,"tv":6170.44,"id":8908205}]}]}
{"op":"mcm","clk":"1003937290","pt":1580652636910,"mc":[{"id":"1.168224027","rc":[{"batb":[[1,1.61,197.52]],"ltp":1.69,"tv":6170.44,"id":8908205}]}]}
{"op":"mcm","clk":"1003937518","pt":1580652637791,"mc":[{"id":"1.168224027","rc":[{"batl":[[0,1.64,11.14],[1,1.66,123.87],[2,1.67,611.7]],"ltp":1.69,"tv":6170.44,"id":8908205},{"batb":[[0,2.56,342.41],[1,2.26,83.87],[2,1.76,23.23]],"batl":[[0,2.66,11.93],[1,2.68,3.39],[2,2.72,133]],"ltp":2.44,"tv":775.66,"id":4596961}]}]}
{"op":"mcm","clk":"1003937769","pt":1580652638721,"mc":[{"id":"1.168224027","rc":[{"batb":[[0,2.6,58.78],[1,2.56,342.41],[2,2.36,74.51]],"ltp":2.44,"tv":775.66,"id":4596961}]}]}
{"op":"mcm","clk":"1003938128","pt":1580652639995,"mc":[{"id":"1.168224027","rc":[{"batl":[[0,1.64,53.15]],"ltp":1.69,"tv":6170.44,"id":8908205},{"batb":[[2,2.54,26.89]],"ltp":2.44,"tv":775.66,"id":4596961}]}]}
{"op":"mcm","clk":"1003939165","pt":1580652643889,"mc":[{"id":"1.168224027","rc":[{"trd":[[1.63,0.67]],"batl":[[2,1.67,1092.29]],"ltp":1.63,"tv":6171.11,"id":8908205},{"trd":[[2.6,0.42]],"batb":[[0,2.6,58.35]],"ltp":2.6,"tv":776.08,"id":4596961}],"tv":6947.2}]}
{"op":"mcm","clk":"1003941625","pt":1580652653085,"mc":[{"id":"1.168224027","rc":[{"batl":[[2,1.67,809.29]],"ltp":1.63,"tv":6171.11,"id":8908205},{"batl":[[2,2.76,3.02]],"ltp":2.6,"tv":776.08,"id":4596961}]}]}
{"op":"mcm","clk":"1003941787","pt":1580652653761,"mc":[{"id":"1.168224027","rc":[{"batb":[[0,1.59,71.21],[1,1.58,494.03],[2,1.57,73.7]],"batl":[[0,1.64,42.01],[1,1.67,480.59],[2,1.69,497.4]],"ltp":1.63,"tv":6171.11,"id":8908205},{"batb":[[0,2.54,26.89],[1,2.36,74.51],[2,1.81,21.29]],"batl":[[0,2.82,3.25],[1,2.88,21.85],[2,2.94,3.08]],"ltp":2.6,"tv":776.08,"id":4596961}]}]}
{"op":"mcm","clk":"1003941993","pt":1580652654549,"mc":[{"id":"1.168224027","rc":[{"batl":[[0,1.67,480.59],[1,1.69,497.4],[2,1.96,3.6]],"ltp":1.63,"tv":6171.11,"id":8908205},{"batb":[[0,2.36,74.51],[1,1.81,21.29],[2,1.8,75.72]],"batl":[[1,2.94,3.08],[2,3.05,3.1]],"ltp":2.6,"tv":776.08,"id":4596961}]}]}
{"op":"mcm","clk":"1003942502","pt":1580652656430,"mc":[{"id":"1.168224027","rc":[{"batl":[[2,1.8,277.41]],"ltp":1.63,"tv":6171.11,"id":8908205}]}]}
{"op":"mcm","clk":"1003942814","pt":1580652657533,"mc":[{"id":"1.168224027","rc":[{"batl":[[2,1.96,3.6]],"ltp":1.63,"tv":6171.11,"id":8908205}]}]}
{"op":"mcm","clk":"1003943173","pt":1580652658848,"mc":[{"id":"1.168224027","rc":[{"batb":[[2,1.56,510.84]],"ltp":1.63,"tv":6171.11,"id":8908205}]}]}
{"op":"mcm","clk":"1003943755","pt":1580652661070,"mc":[{"id":"1.168224027","rc":[{"batb":[[0,1.64,235.26],[1,1.63,189],[2,1.59,71.21]],"batl":[[1,1.69,742.37],[2,1.71,320.63]],"ltp":1.63,"tv":6171.11,"id":8908205}]}]}
{"op":"mcm","clk":"1003943789","pt":1580652661135,"mc":[{"id":"1.168224027","rc":[{"batb":[[0,1.59,71.21],[1,1.58,494.03],[2,1.56,510.84]],"batl":[[1,1.69,497.4],[2,1.96,3.6]],"ltp":1.63,"tv":6171.11,"id":8908205}]}]}
{"op":"mcm","clk":"1003944593","pt":1580652663936,"mc":[{"id":"1.168224027","rc":[{"batl":[[0,1.96,3.6],[1,2,68.78],[2,2.24,5.11]],"ltp":1.63,"tv":6171.11,"id":8908205}]}]}
{"op":"mcm","clk":"1003944875","pt":1580652664973,"mc":[{"id":"1.168224027","rc":[{"batl":[[0,1.8,277.41],[1,1.82,261.17],[2,1.96,3.6]],"ltp":1.63,"tv":6171.11,"id":8908205}]}]}
{"op":"mcm","clk":"1003945438","pt":1580652666851,"mc":[{"id":"1.168224027","rc":[{"trd":[[1.74,101.06]],"batb":[[0,1.74,116.69],[1,1.72,310.81],[2,1.68,700.61]],"batl":[[0,1.78,9.72],[1,1.8,993.34],[2,1.81,222]],"ltp":1.74,"tv":6272.17,"id":8908205},{"trd":[[2.36,74.51]],"batb":[[0,1.81,21.29],[1,1.76,23.23],[2,1.7,103.44]],"batl":[[0,2.42,178],[1,2.46,152.44],[2,2.48,169.7]],"ltp":2.36,"tv":850.59,"id":4596961}],"tv":7122.77}]}
{"op":"mcm","clk":"1003945596","pt":1580652667464,"mc":[{"id":"1.168224027","rc":[{"batb":[[0,1.68,700.61],[1,1.67,101.26],[2,1.62,67.22]],"batl":[[0,1.77,42.01],[1,1.78,9.72],[2,1.8,715.93]],"ltp":1.74,"tv":6272.17,"id":8908205},{"batb":[[0,2.32,31.09],[1,2.2,89.93],[2,1.81,21.29]],"ltp":2.36,"tv":850.59,"id":4596961}]}]}
{"op":"mcm","clk":"1003946435","pt":1580652670457,"mc":[{"id":"1.168224027","rc":[{"batb":[[0,1.73,301.51],[1,1.71,317.68],[2,1.68,700.61]],"batl":[[2,1.79,197.23]],"ltp":1.74,"tv":6272.17,"id":8908205}]}]}
{"op":"mcm","clk":"1003947238","pt":1580652673378,"mc":[{"id":"1.168224027","rc":[{"batb":[[2,1.68,1194.64]],"ltp":1.74,"tv":6272.17,"id":8908205}]}]}
{"op":"mcm","clk":"1003948152","pt":1580652676674,"mc":[{"id":"1.168224027","rc":[{"batl":[[1,1.79,197.23],[2,1.8,715.93]],"ltp":1.74,"tv":6272.17,"id":8908205}]}]}
{"op":"mcm","clk":"1003948999","pt":1580652679685,"mc":[{"id":"1.168224027","rc":[{"batb":[[1,1.72,13.25],[2,1.71,317.68]],"ltp":1.74,"tv":6272.17,"id":8908205},{"batb":[[0,2.32,39.47]],"ltp":2.36,"tv":850.59,"id":4596961}]}]}
{"op":"mcm","clk":"1003949404","pt":1580652681114,"mc":[{"id":"1.168224027","rc":[{"trd":[[1.73,17.9]],"batb":[[0,1.73,296.4],[1,1.71,317.68],[2,1.68,494.03]],"batl":[[2,1.81,266.25]],"ltp":1.73,"tv":6282.39,"id":8908205},{"batb":[[0,2.32,31.09]],"batl":[[0,2.46,152.44],[1,2.48,169.7],[2,2.54,4.25]],"ltp":2.36,"tv":850.59,"id":4596961}],"tv":7132.99}]}
{"op":"mcm","clk":"1003949482","pt":1580652681400,"mc":[{"id":"1.168224027","rc":[{"batb":[[0,1.68,494.03],[1,1.66,510.84],[2,1.65,29.13]],"batl":[[1,1.96,3.6],[2,2,68.78]],"ltp":1.73,"tv":6282.39,"id":8908205},{"batb":[[2,1.71,27.19]],"batl":[[0,2.54,4.25],[1,2.62,28.67],[2,2.82,3.25]],"ltp":2.36,"tv":850.59,"id":4596961}]}]}
{"op":"mcm","clk":"1003949824","pt":1580652682574,"mc":[{"id":"1.168224027","rc":[{"batl":[[0,1.96,3.6],[1,2,68.78],[2,2.42,4.94]],"ltp":1.73,"tv":6282.39,"id":8908205},{"trd":[[2.32,62.18]],"batb":[[0,2.2,89.93],[1,1.71,27.19],[2,1.7,103.44]],"batl":[[0,2.32,28.91],[1,2.54,4.25],[2,2.62,3.46]],"ltp":2.32,"tv":912.77,"id":4596961}],"tv":7195.17}]}
{"op":"mcm","clk":"1003950367","pt":1580652684666,"mc":[{"id":"1.168224027","rc":[{"batb":[[2,1.65,363.29]],"batl":[[0,1.93,204.26],[1,1.95,210.97],[2,1.96,3.6]],"ltp":1.73,"tv":6282.39,"id":8908205},{"batb":[[1,2.14,93.63],[2,1.71,27.19]],"ltp":2.32,"tv":912.77,"id":4596961}]}]}
{"op":"mcm","clk":"1003950616","pt":1580652685599,"mc":[{"id":"1.168224027","rc":[{"trd":[[2.32,120]],"batl":[[0,2.54,4.25],[1,2.62,3.46],[2,2.82,3.25]],"ltp":2.32,"tv":970.59,"id":4596961}],"tv":7252.99}]}
{"op":"mcm","clk":"1003951187","pt":1580652687801,"mc":[{"id":"1.168224027","rc":[{"batb":[[0,1.65,363.29],[1,1.64,185.31],[2,1.62,144.55]],"batl":[[0,1.96,3.6],[1,2,68.78],[2,2.42,4.94]],"ltp":1.73,"tv":6282.39,"id":8908205}]}]}
{"op":"mcm","clk":"1003951957","pt":1580652690794,"mc":[{"id":"1.168224027","rc":[{"batb":[[0,1.66,2.56],[1,1.65,363.29],[2,1.64,185.31]],"batl":[[0,1.71,603.01],[1,1.73,431.04],[2,1.76,1856.78]],"ltp":1.73,"tv":6282.39,"id":8908205},{"batb":[[0,2.5,7.25],[1,2.34,2.68],[2,2.2,89.93]],"batl":[[1,2.56,5.63],[2,2.6,140]],"ltp":2.32,"tv":970.59,"id":4596961}]}]}
{"op":"mcm","clk":"1003952154","pt":1580652691524,"mc":[{"id":"1.168224027","rc":[{"batl":[[0,1.7,42.01],[1,1.71,603.01],[2,1.73,431.04]],"ltp":1.73,"tv":6282.39,"id":8908205},{"batb":[[1,2.44,65.23],[2,2.42,29.41]],"ltp":2.32,"tv":970.59,"id":4596961}]}]}
{"op":"mcm","clk":"1003953586","pt":1580652697042,"mc":[{"id":"1.168224027","rc":[{"batb":[[2,1.64,679.34]],"ltp":1.73,"tv":6282.39,"id":8908205}]}]}
{"op":"mcm","clk":"1003955099","pt":1580652703005,"mc":[{"id":"1.168224027","rc":[{"batb":[[1,1.64,494.03],[2,1.62,510.84]],"batl":[[1,1.96,3.6],[2,2,68.78]],"ltp":1.73,"tv":6282.39,"id":8908205},{"batb":[[0,2.42,29.41],[1,2.34,2.68],[2,2.2,87.34]],"batl":[[0,2.68,24.37],[1,2.8,3.37],[2,2.82,3.25]],"ltp":2.32,"tv":970.59,"id":4596961}]}]}
{"op":"mcm","clk":"1003955514","pt":1580652704628,"mc":[{"id":"1.168224027","rc":[{"batl":[[0,1.96,3.6],[1,2,68.78],[2,2.38,4.42]],"ltp":1.73,"tv":6282.39,"id":8908205},{"batb":[[0,2.34,2.68],[1,2.2,87.34],[2,1.73,23.13]],"batl":[[0,2.8,3.37],[1,2.82,3.25],[2,2.94,3.08]],"ltp":2.32,"tv":970.59,"id":4596961}]}]}
{"op":"mcm","clk":"1003955775","pt":1580652705642,"mc":[{"id":"1.168224027","rc":[{"batl":[[0,1.91,256.59],[1,1.93,217.63],[2,1.96,3.6]],"ltp":1.73,"tv":6282.39,"id":8908205}]}]}
{"op":"mcm","clk":"1003956288","pt":1580652707532,"mc":[{"id":"1.168224027","rc":[{"batl":[[0,1.96,3.6],[1,2,68.78],[2,2.38,4.42]],"ltp":1.73,"tv":6282.39,"id":8908205}]}]}
{"op":"mcm","clk":"1003957140","pt":1580652710946,"mc":[{"id":"1.168224027","rc":[{"batb":[[0,1.69,218.39],[1,1.67,344.65],[2,1.66,2.56]],"batl":[[0,1.74,189.69],[1,1.76,291.72],[2,1.96,3.6]],"ltp":1.73,"tv":6282.39,"id":8908205}]}]}
{"op":"mcm","clk":"1003957541","pt":1580652712548,"mc":[{"id":"1.168224027","rc":[{"batb":[[0,1.66,2.56],[1,1.64,494.03],[2,1.62,510.84]],"batl":[[0,1.96,3.6],[1,2,68.78],[2,2.38,4.42]],"ltp":1.73,"tv":6282.39,"id":8908205}]}]}
{"op":"mcm","clk":"1003958591","pt":1580652716738,"mc":[{"id":"1.168224027","rc":[{"batl":[[0,1.91,256.75],[1,1.93,217.63],[2,1.96,3.6]],"ltp":1.73,"tv":6282.39,"id":8908205},{"batb":[[2,1.73,23.47]],"ltp":2.32,"tv":970.59,"id":4596961}]}]}
{"op":"mcm","clk":"1003959280","pt":1580652719040,"mc":[{"id":"1.168224027","rc":[{"batb":[[0,1.64,494.03],[1,1.62,510.84],[2,1.57,73.7]],"ltp":1.73,"tv":6282.39,"id":8908205},{"batb":[[0,2.2,87.34],[1,1.73,23.47],[2,1.71,27.19]],"ltp":2.32,"tv":970.59,"id":4596961}]}]}
{"op":"mcm","clk":"1003959963","pt":1580652721870,"mc":[{"id":"1.168224027","rc":[{"batb":[[0,1.57,73.7],[1,1.55,260.92],[2,1.54,234.1]],"batl":[[0,1.96,3.6],[1,2,68.78],[2,2.38,4.42]],"ltp":1.73,"tv":6282.39,"id":8908205},{"batl":[[0,2.82,3.25],[1,2.94,3.08],[2,3.05,3.1]],"ltp":2.32,"tv":970.59,"id":4596961}]}]}
{"op":"mcm","clk":"1003960248","pt":1580652722928,"mc":[{"id":"1.168224027","rc":[{"batb":[[0,1.55,260.92],[1,1.54,234.1],[2,1.53,141.94]],"ltp":1.73,"tv":6282.39,"id":8908205}]}]}
{"op":"mcm","clk":"1003960678","pt":1580652724667,"mc":[{"id":"1.168224027","rc":[{"batl":[[0,1.56,17.04],[1,1.58,650.04],[2,1.59,468.48]],"ltp":1.73,"tv":6282.39,"id":8908205},{"batb":[[0,2.68,139.92],[1,2.2,87.34],[2,1.73,23.47]],"batl":[[1,2.88,5.56],[2,2.94,154.08]],"ltp":2.32,"tv":970.59,"id":4596961}]}]}
{"op":"mcm","clk":"1003960896","pt":1580652725554,"mc":[{"id":"1.168224027","rc":[{"batb":[[0,2.68,190.28],[1,2.44,65.62]],"ltp":2.32,"tv":970.59,"id":4596961}]}]}
{"op":"mcm","clk":"1003961170","pt":1580652726540,"mc":[{"id":"1.168224027","rc":[{"trd":[[2.82,5.34]],"batb":[[1,2.64,25.21],[2,2.44,65.62]],"batl":[[0,2.88,6.14],[1,2.94,154.08],[2,2.96,21]],"ltp":2.82,"tv":975.93,"id":4596961}],"tv":7258.33}]}
{"op":"mcm","clk":"1003962263","pt":1580652731074,"mc":[{"id":"1.168224027","rc":[{"batl":[[2,1.59,949.07]],"ltp":1.73,"tv":6282.39,"id":8908205}]}]}
{"op":"mcm","clk":"1003962899","pt":1580652733576,"mc":[{"id":"1.168224027","rc":[{"trd":[[1.56,0.34]],"batl":[[0,1.56,16.87]],"ltp":1.56,"tv":6282.73,"id":8908205}],"tv":7258.67}]}
{"op":"mcm","clk":"1003965410","pt":1580652744042,"mc":[{"id":"1.168224027","rc":[{"batb":[[0,1.52,574.82],[1,1.5,678.88],[2,1.49,37.61]],"batl":[[0,1.59,480.59],[1,1.61,539.41],[2,1.96,3.6]],"ltp":1.56,"tv":6282.73,"id":8908205},{"batb":[[0,2.64,25.21],[1,2.44,65.62],[2,1.87,19.61]],"batl":[[0,2.96,21],[1,3.05,3.1],[2,3.15,2.7]],"ltp":2.82,"tv":975.93,"id":4596961}]}]}
{"op":"mcm","clk":"1003965531","pt":1580652744610,"mc":[{"id":"1.168224027","rc":[{"batb":[[1,1.5,594.86]],"batl":[[1,1.61,497.4]],"ltp":1.56,"tv":6282.73,"id":8908205},{"batb":[[0,2.44,65.62],[1,1.87,19.61],[2,1.8,75.72]],"batl":[[0,3.05,3.1],[1,3.15,2.7],[2,1000,0.02]],"ltp":2.82,"tv":975.93,"id":4596961}]}]}
{"op":"mcm","clk":"1003966116","pt":1580652746930,"mc":[{"id":"1.168224027","rc":[{"batl":[[2,1.72,284.79]],"ltp":1.56,"tv":6282.73,"id":8908205}]}]}
{"op":"mcm","clk":"1003967996","pt":1580652754515,"mc":[{"id":"1.168224027","rc":[{"batb":[[2,1.49,35.01]],"ltp":1.56,"tv":6282.73,"id":8908205}]}]}
{"op":"mcm","clk":"1003968589","pt":1580652756977,"mc":[{"id":"1.168224027","rc":[{"batb":[[0,1.5,84.02],[1,1.47,35.67],[2,1.46,172.08]],"batl":[[2,1.96,3.6]],"ltp":1.56,"tv":6282.73,"id":8908205},{"batl":[[0,3.15,2.7],[1,1000,0.02],[2,1000,0]],"ltp":2.82,"tv":975.93,"id":4596961}]}]}
{"op":"mcm","clk":"1003968722","pt":1580652757620,"mc":[{"id":"1.168224027","rc":[{"batb":[[0,1.47,35.67],[1,1.46,172.08],[2,1.38,448.45]],"ltp":1.56,"tv":6282.73,"id":8908205}]}]}
{"op":"mcm","clk":"1003969064","pt":1580652759105,"mc":[{"id":"1.168224027","rc":[{"trd":[[1.48,20.91]],"batb":[[0,1.48,1509.94],[1,1.47,35.67],[2,1.46,185.81]],"batl":[[0,1.51,4238.2],[1,1.52,1773.26],[2,1.56,2352.04]],"ltp":1.48,"tv":6303.39,"id":8908205},{"batl":[[1,3.25,157],[2,3.3,350.24]],"ltp":2.82,"tv":975.93,"id":4596961}],"tv":7279.33}]}
{"op":"mcm","clk":"1003969305","pt":1580652760105,"mc":[{"id":"1.168224027","rc":[{"batb":[[0,1.48,1773.4],[1,1.47,318.23]],"batl":[[0,1.51,3.5],[1,1.52,2107.74],[2,1.53,237.59]],"ltp":1.48,"tv":6303.39,"id":8908205},{"batb":[[0,2.96,2],[1,2.92,100.63],[2,2.84,22.69]],"batl":[[1,3.2,18.48],[2,3.25,157]],"ltp":2.82,"tv":975.93,"id":4596961}]}]}
{"op":"mcm","clk":"1003970351","pt":1580652764407,"mc":[{"id":"1.168224027","rc":[{"batb":[[2,1.46,277.14]],"ltp":1.48,"tv":6303.39,"id":8908205}]}]}
{"op":"mcm","clk":"1003971000","pt":1580652767114,"mc":[{"id":"1.168224027","rc":[{"batb":[[0,1.48,2.61],[1,1.46,302.79],[2,1.45,93.26]],"batl":[[1,1.54,42.01],[2,1.57,27.5]],"ltp":1.48,"tv":6303.39,"id":8908205},{"batl":[[0,3.2,21.26],[1,3.3,2.45],[2,1000,0.02]],"ltp":2.82,"tv":975.93,"id":4596961}]}]}
{"op":"mcm","clk":"1003971081","pt":1580652767433,"mc":[{"id":"1.168224027","rc":[{"batb":[[1,1.46,91.33]],"batl":[[2,1.6,29.96]],"ltp":1.48,"tv":6303.39,"id":8908205},{"batb":[[1,2.84,22.69],[2,2.68,51.14]],"batl":[[0,3.2,18.48]],"ltp":2.82,"tv":975.93,"id":4596961}]}]}
{"op":"mcm","clk":"1003971365","pt":1580652768620,"mc":[{"id":"1.168224027","rc":[{"batb":[[2,1.44,131.65]],"batl":[[1,1.6,29.96],[2,1.89,435.28]],"ltp":1.48,"tv":6303.39,"id":8908205},{"batb":[[1,2.68,51.14],[2,2.66,3.78]],"batl":[[0,3.3,2.45],[1,1000,0.02],[2,1000,0]],"ltp":2.82,"tv":975.93,"id":4596961}]}]}
{"op":"mcm","clk":"1003971688","pt":1580652769984,"mc":[{"id":"1.168224027","rc":[{"batl":[[1,1.6,258.24],[2,1.61,196.97]],"ltp":1.48,"tv":6303.39,"id":8908205}]}]}
{"op":"mcm","clk":"1003971911","pt":1580652770879,"mc":[{"id":"1.168224027","rc":[{"batl":[[1,1.57,28.5],[2,1.6,258.24]],"ltp":1.48,"tv":6303.39,"id":8908205},{"batb":[[1,2.74,3.56],[2,2.68,51.14]],"ltp":2.82,"tv":975.93,"id":4596961}]}]}
{"op":"mcm","clk":"1003972664","pt":1580652773995,"mc":[{"id":"1.168224027","rc":[{"batb":[[1,1.46,129.21]],"ltp":1.48,"tv":6303.39,"id":8908205},{"batl":[[0,3.2,2.73],[1,3.3,2.45],[2,1000,0.02]],"ltp":2.82,"tv":975.93,"id":4596961}]}]}
{"op":"mcm","clk":"1003974610","pt":1580652781986,"mc":[{"id":"1.168224027","rc":[{"batb":[[1,1.46,91.33],[2,1.44,95.48]],"batl":[[0,1.57,28.5],[1,1.6,258.24],[2,1.61,196.97]],"ltp":1.48,"tv":6303.39,"id":8908205},{"batb":[[0,2.74,3.56],[1,2.68,51.14],[2,2.66,3.78]],"batl":[[0,3.3,2.45],[1,1000,0.02],[2,1000,0]],"ltp":2.82,"tv":975.93,"id":4596961}]}]}
{"op":"mcm","clk":"1003974671","pt":1580652782298,"mc":[{"id":"1.168224027","rc":[{"batl":[[0,1.6,258.24],[1,1.61,196.97],[2,1.89,435.28]],"ltp":1.48,"tv":6303.39,"id":8908205},{"batb":[[0,2.68,51.14],[1,2.66,3.78],[2,1.87,19.61]],"ltp":2.82,"tv":975.93,"id":4596961}]}]}
{"op":"mcm","clk":"1003975431","pt":1580652785503,"mc":[{"id":"1.168224027","rc":[{"batb":[[1,1.46,127.21],[2,1.44,131.9]],"batl":[[0,1.57,27.5],[1,1.6,258.24],[2,1.61,196.97]],"ltp":1.48,"tv":6303.39,"id":8908205},{"batb":[[0,2.74,3.52],[1,2.68,51.14],[2,2.66,3.78]],"batl":[[0,3.2,2.63],[1,3.3,2.45],[2,1000,0.02]],"ltp":2.82,"tv":975.93,"id":4596961}]}]}
{"op":"mcm","clk":"1003975585","pt":1580652786211,"mc":[{"id":"1.168224027","rc":[{"batb":[[1,1.46,91.33]],"batl":[[0,1.6,258.24],[1,1.61,196.97],[2,1.89,435.28]],"ltp":1.48,"tv":6303.39,"id":8908205},{"batb":[[0,2.68,51.14],[1,2.66,3.78],[2,1.87,19.61]],"batl":[[0,3.3,2.45],[1,1000,0.02],[2,1000,0]],"ltp":2.82,"tv":975.93,"id":4596961}]}]}
{"op":"mcm","clk":"1003976048","pt":1580652788121,"mc":[{"id":"1.168224027","rc":[{"batb":[[0,1.46,91.33],[1,1.44,131.9],[2,1.43,344.93]],"batl":[[0,1.6,29.96],[1,1.89,435.28],[2,1.96,3.6]],"ltp":1.48,"tv":6303.39,"id":8908205}]}]}
{"op":"mcm","clk":"1003976249","pt":1580652788881,"mc":[{"id":"1.168224027","rc":[{"batb":[[0,1.44,131.9],[1,1.43,344.93],[2,1.42,328.65]],"ltp":1.48,"tv":6303.39,"id":8908205}]}]}
{"op":"mcm","clk":"1003976528","pt":1580652790085,"mc":[{"id":"1.168224027","rc":[{"batb":[[0,1.44,36.42]],"ltp":1.48,"tv":6303.39,"id":8908205}]}]}
{"op":"mcm","clk":"1003976760","pt":1580652791027,"mc":[{"id":"1.168224027","rc":[{"trd":[[1.44,24.78]],"batb":[[0,1.44,24.03],[2,1.42,343.09]],"batl":[[0,1.47,346],[1,1.5,2660.59],[2,1.6,29.96]],"ltp":1.44,"tv":6328.17,"id":8908205},{"batb":[[0,3.1,1773.4],[1,3,600.06],[2,2.68,51.14]],"batl":[[1,3.5,134],[2,3.55,301.92]],"ltp":2.82,"tv":975.93,"id":4596961}],"tv":7304.11}]}
{"op":"mcm","clk":"1003976978","pt":1580652791930,"mc":[{"id":"1.168224027","rc":[{"batl":[[0,1.47,740.47],[1,1.48,312.49],[2,1.5,1346.18]],"ltp":1.44,"tv":6328.17,"id":8908205},{"batb":[[0,3.15,81.83],[1,3.1,198.66],[2,3,600.06]],"batl":[[1,3.5,150.8]],"ltp":2.82,"tv":975.93,"id":4596961}]}]}
{"op":"mcm","clk":"1003977215","pt":1580652792939,"mc":[{"id":"1.168224027","rc":[{"batb":[[0,1.46,2.63],[1,1.44,24.03],[2,1.43,344.93]],"ltp":1.44,"tv":6328.17,"id":8908205}]}]}
{"op":"mcm","clk":"1003977345","pt":1580652793420,"mc":[{"id":"1.168224027","rc":[{"trd":[[3.15,29.29]],"batb":[[0,3.15,67.18]],"ltp":3.15,"tv":1005.22,"id":4596961}],"tv":7333.4}]}
{"op":"mcm","clk":"1003978190","pt":1580652796944,"mc":[{"id":"1.168224027","rc":[{"trd":[[1.46,4.98]],"batb":[[0,1.44,24.18],[1,1.43,344.93],[2,1.42,343.09]],"ltp":1.46,"tv":6333.15,"id":8908205}],"tv":7338.37}]}
{"op":"mcm","clk":"1003979182","pt":1580652800950,"mc":[{"id":"1.168224027","rc":[{"batb":[[2,1.42,373.09]],"batl":[[2,1.49,36.5]],"ltp":1.46,"tv":6333.15,"id":8908205},{"batb":[[2,3,603.07]],"batl":[[1,3.4,2.44],[2,3.5,153.25]],"ltp":3.15,"tv":1005.22,"id":4596961}]}]}
{"op":"mcm","clk":"1003979948","pt":1580652803960,"mc":[{"id":"1.168224027","rc":[{"trd":[[1.46,5.27]],"batb":[[0,1.44,24.03],[1,1.43,358.12]],"batl":[[0,1.45,12.44],[1,1.47,740.47],[2,1.48,312.49]],"ltp":1.46,"tv":6333.45,"id":8908205},{"batl":[[2,3.45,2.1]],"ltp":3.15,"tv":1005.22,"id":4596961}],"tv":7338.67}]}
{"op":"mcm","clk":"1003981341","pt":1580652809443,"mc":[{"id":"1.168224027","rc":[{"trd":[[1.45,16.82]],"batl":[[0,1.45,4.03]],"ltp":1.45,"tv":6350.26,"id":8908205}],"tv":7355.49}]}
{"op":"mcm","clk":"1003981821","pt":1580652811358,"mc":[{"id":"1.168224027","rc":[{"trd":[[1.45,17.8]],"batl":[[0,1.45,3.54]],"ltp":1.45,"tv":6351.24,"id":8908205}],"tv":7356.47}]}
{"op":"mcm","clk":"1003982723","pt":1580652814969,"mc":[{"id":"1.168224027","rc":[{"batb":[[0,1.41,102.46],[1,1.4,41.51],[2,1.39,149.45]],"batl":[[0,1.48,42.01],[1,1.51,30.5],[2,1.6,29.96]],"ltp":1.45,"tv":6351.24,"id":8908205},{"batb":[[0,3.1,19.32],[1,2.98,95.99],[2,2.96,2.63]],"batl":[[0,3.5,19.25],[1,3.6,2.16],[2,3.65,2.5]],"ltp":3.15,"tv":1005.22,"id":4596961}]}]}
{"op":"mcm","clk":"1003983253","pt":1580652817065,"mc":[{"id":"1.168224027","rc":[{"batb":[[2,1.39,41.91]],"batl":[[0,1.46,15.65]],"ltp":1.45,"tv":6351.24,"id":8908205},{"batb":[[0,2.98,95.99],[1,2.96,2.63],[2,2.66,3.78]],"batl":[[0,3.3,6.94],[1,3.5,2.45],[2,3.6,2.16]],"ltp":3.15,"tv":1005.22,"id":4596961}]}]}
{"op":"mcm","clk":"1003983483","pt":1580652818070,"mc":[{"id":"1.168224027","rc":[{"batl":[[0,1.49,34.5]],"ltp":1.45,"tv":6351.24,"id":8908205},{"batb":[[0,3,2.91],[1,2.98,95.99],[2,2.96,99.25]],"batl":[[0,3.5,2.45],[1,3.6,2.16],[2,3.65,2.5]],"ltp":3.15,"tv":1005.22,"id":4596961}]}]}
{"op":"mcm","clk":"1003983600","pt":1580652818574,"mc":[{"id":"1.168224027","rc":[{"batl":[[0,1.5,194.84],[1,1.51,281.49]],"ltp":1.45,"tv":6351.24,"id":8908205},{"batb":[[0,2.96,99.25],[1,2.66,3.78],[2,2,75.72]],"ltp":3.15,"tv":1005.22,"id":4596961}]}]}
{"op":"mcm","clk":"1003984210","pt":1580652821078,"mc":[{"id":"1.168224027","rc":[{"batb":[[0,1.44,1361.75],[1,1.43,691.36],[2,1.41,102.46]],"batl":[[1,1.51,594.49]],"ltp":1.45,"tv":6351.24,"id":8908205},{"batb":[[0,3.05,314.9],[1,2.96,99.25],[2,2.66,3.78]],"batl":[[0,3.15,307.2],[1,3.3,758.1],[2,3.5,2.45]],"ltp":3.15,"tv":1005.22,"id":4596961}]}]}
{"op":"mcm","clk":"1003984468","pt":1580652822088,"mc":[{"id":"1.168224027","rc":[{"batb":[[0,1.46,461.92],[1,1.45,478.68],[2,1.44,136.17]],"batl":[[0,1.5,236.85]],"ltp":1.45,"tv":6351.24,"id":8908205},{"batb":[[1,2.96,120.26],[2,2.82,44.3]],"batl":[[0,3.3,212.61],[1,3.35,17.64]],"ltp":3.15,"tv":1005.22,"id":4596961}]}]}
{"op":"mcm","clk":"1003984674","pt":1580652822888,"mc":[{"id":"1.168224027","rc":[{"batb":[[2,1.44,231.65]],"ltp":1.45,"tv":6351.24,"id":8908205}]}]}
{"op":"mcm","clk":"1003984948","pt":1580652824085,"mc":[{"id":"1.168224027","rc":[{"batl":[[0,1.5,243.6]],"ltp":1.45,"tv":6351.24,"id":8908205},{"batb":[[1,3,3.37],[2,2.96,120.26]],"batl":[[0,3.1,6.25],[1,3.3,212.61],[2,3.35,17.64]],"ltp":3.15,"tv":1005.22,"id":4596961}]}]}
{"op":"mcm","clk":"1003985114","pt":1580652824777,"mc":[{"id":"1.168224027","rc":[{"batl":[[0,1.5,236.85]],"ltp":1.45,"tv":6351.24,"id":8908205},{"batb":[[1,2.96,120.26],[2,2.82,44.3]],"batl":[[0,3.3,212.61],[1,3.35,17.64],[2,3.5,2.45]],"ltp":3.15,"tv":1005.22,"id":4596961}]}]}
{"op":"mcm","clk":"1003985912","pt":1580652827981,"mc":[{"id":"1.168224027","rc":[{"batb":[[1,1.45,516.29],[2,1.44,766.85]],"batl":[[0,1.5,243.6],[2,1.52,518.6]],"ltp":1.45,"tv":6351.24,"id":8908205},{"batb":[[1,3,3.37],[2,2.96,120.26]],"batl":[[0,3.1,6.25],[1,3.25,2.5],[2,3.3,215.16]],"ltp":3.15,"tv":1005.22,"id":4596961}]}]}
{"op":"mcm","clk":"1003986896","pt":1580652832069,"mc":[{"id":"1.168224027","rc":[{"batb":[[0,1.45,130.96],[1,1.44,630.68],[2,1.42,610.82]],"batl":[[0,1.5,42.01],[1,1.51,30.5]],"ltp":1.45,"tv":6351.24,"id":8908205},{"batb":[[0,2.96,23.63],[1,2.92,2.69],[2,2.88,2.96]],"batl":[[0,3.25,2.5],[1,3.3,2.55],[2,3.35,17.64]],"ltp":3.15,"tv":1005.22,"id":4596961}]}]}
{"op":"mcm","clk":"1003987053","pt":1580652832678,"mc":[{"id":"1.168224027","rc":[{"batb":[[0,1.45,93.35],[2,1.42,510.84]],"batl":[[0,1.52,518.6],[1,1.53,33.5],[2,1.54,497.4]],"ltp":1.45,"tv":6351.24,"id":8908205},{"batb":[[0,2.92,2.69],[1,2.88,2.96],[2,2.82,44.3]],"batl":[[0,3.3,2.55],[1,3.5,2.45],[2,3.6,2.16]],"ltp":3.15,"tv":1005.22,"id":4596961}]}]}
