{"op":"mcm","clk":"1004746238","pt":1580656702115,"mc":[{"id":"1.168224030","rc":[{"batb":[[0,1.81,118.83],[1,1.79,178.55],[2,1.76,22.58]],"batl":[[0,1.88,104.66],[1,1.9,149.83],[2,2.72,241.55]],"ltp":1.85,"tv":416.88,"id":4596961}]}]}
{"op":"mcm","clk":"1004746442","pt":1580656703006,"mc":[{"id":"1.168224030","rc":[{"batb":[[0,2.2,21.09],[1,1.89,16.68],[2,1.01,10.51]],"ltp":2.18,"tv":1707.95,"id":8908205},{"batl":[[2,2.72,0]],"ltp":1.85,"tv":416.88,"id":4596961}]}]}
{"op":"mcm","clk":"1004746596","pt":1580656703715,"mc":[{"id":"1.168224030","rc":[{"batb":[[1,1.96,43.69],[2,1.89,16.68]],"ltp":2.18,"tv":1707.95,"id":8908205},{"batl":[[2,2.04,40.33]],"ltp":1.85,"tv":416.88,"id":4596961}]}]}
{"op":"mcm","clk":"1004747169","pt":1580656706513,"mc":[{"id":"1.168224030","rc":[{"batl":[[0,2.82,231.28]],"ltp":2.18,"tv":1707.95,"id":8908205}]}]}
{"op":"mcm","clk":"1004750936","pt":1580656724116,"mc":[{"id":"1.168224030","rc":[{"batb":[[0,1.76,22.58],[1,1.51,38.71],[2,1.01,10.51]],"batl":[[0,2.04,40.33],[1,2.42,286.52],[2,2.04,0]],"ltp":1.85,"tv":416.88,"id":4596961}]}]}
{"op":"mcm","clk":"1004751055","pt":1580656724712,"mc":[{"id":"1.168224030","rc":[{"batb":[[0,1.89,16.68],[1,1.01,10.51],[2,1.89,0]],"ltp":2.18,"tv":1707.95,"id":8908205},{"batb":[[0,1.51,38.71],[1,1.01,10.51],[2,1.01,0]],"batl":[[0,2.42,286.52],[1,2.42,0]],"ltp":1.85,"tv":416.88,"id":4596961}]}]}
{"op":"mcm","clk":"1004751480","pt":1580656726840,"mc":[{"id":"1.168224030","rc":[{"batb":[[0,1.54,226.64],[1,1.53,157.88],[2,1.51,38.71]],"batl":[[0,2.16,171.72],[1,2.18,100.21],[2,2.42,286.52]],"ltp":1.85,"tv":416.88,"id":4596961}]}]}
{"op":"mcm","clk":"1004751744","pt":1580656727939,"mc":[{"id":"1.168224030","rc":[{"batb":[[0,1.51,38.71],[1,1.01,10.51],[2,1.51,0]],"batl":[[0,2.42,286.52],[1,2.18,0],[2,2.42,0]],"ltp":1.85,"tv":416.88,"id":4596961}]}]}
{"op":"mcm","clk":"1004752363","pt":1580656730836,"mc":[{"id":"1.168224030","rc":[{"batb":[[0,1.75,122.56],[1,1.73,200.11],[2,1.51,38.71]],"batl":[[0,1.82,152.34],[1,1.84,165.41]],"ltp":1.85,"tv":416.88,"id":4596961}]}]}
{"op":"mcm","clk":"1004753049","pt":1580656734036,"mc":[{"id":"1.168224030","rc":[{"batb":[[0,1.51,38.71],[1,1.01,10.51],[2,1.51,0]],"batl":[[0,2.3,309.75],[1,1.84,0]],"ltp":1.85,"tv":416.88,"id":4596961}]}]}
{"op":"mcm","clk":"1004753683","pt":1580656736947,"mc":[{"id":"1.168224030","rc":[{"batb":[[0,1.54,226.64],[1,1.53,157.88],[2,1.51,38.71]],"batl":[[0,2.16,171.72],[1,2.18,100.21],[2,2.3,309.75]],"ltp":1.85,"tv":416.88,"id":4596961}]}]}
{"op":"mcm","clk":"1004756697","pt":1580656751116,"mc":[{"id":"1.168224030","rc":[{"batb":[[0,1.51,38.71],[1,1.01,10.51],[2,1.51,0]],"batl":[[0,2.3,309.75],[1,2.18,0],[2,2.3,0]],"ltp":1.85,"tv":416.88,"id":4596961}]}]}
{"op":"mcm","clk":"1004757316","pt":1580656754018,"mc":[{"id":"1.168224030","rc":[{"batb":[[1,1.87,135.82],[2,1.85,160.59]],"batl":[[0,1.95,114.81],[1,1.97,134.4]],"ltp":2.18,"tv":1707.95,"id":8908205}]}]}
{"op":"mcm","clk":"1004757535","pt":1580656755043,"mc":[{"id":"1.168224030","rc":[{"batb":[[0,2.02,29.03],[1,1.73,23.53],[2,1.01,10.51]],"ltp":1.85,"tv":416.88,"id":4596961}]}]}
{"op":"mcm","clk":"1004757749","pt":1580656756019,"mc":[{"id":"1.168224030","rc":[{"batl":[[0,2.3,31.93]],"ltp":1.85,"tv":416.88,"id":4596961}]}]}
{"op":"mcm","clk":"1004758128","pt":1580656757855,"mc":[{"id":"1.168224030","rc":[{"batl":[[2,2.5,274.54]],"ltp":2.18,"tv":1707.95,"id":8908205},{"batl":[[1,2.72,241.55]],"ltp":1.85,"tv":416.88,"id":4596961}]}]}
{"op":"mcm","clk":"1004761389","pt":1580656773081,"mc":[{"id":"1.168224030","rc":[{"batb":[[1,1.77,53.77],[2,1.68,24.78]],"batl":[[0,2.5,274.54],[1,1.97,0],[2,2.5,0]],"ltp":2.18,"tv":1707.95,"id":8908205}]}]}
{"op":"mcm","clk":"1004761575","pt":1580656773940,"mc":[{"id":"1.168224030","rc":[{"batb":[[0,1.77,53.77],[1,1.68,24.78],[2,1.01,10.51]],"ltp":2.18,"tv":1707.95,"id":8908205},{"batb":[[0,1.73,23.53],[1,1.01,10.51],[2,1.01,0]],"ltp":1.85,"tv":416.88,"id":4596961}]}]}
{"op":"mcm","clk":"1004761753","pt":1580656774755,"mc":[{"id":"1.168224030","rc":[{"batb":[[0,1.68,24.78],[1,1.01,10.51],[2,1.01,0]],"ltp":2.18,"tv":1707.95,"id":8908205},{"batl":[[0,2.72,241.55],[1,2.72,0]],"ltp":1.85,"tv":416.88,"id":4596961}]}]}
{"op":"mcm","clk":"1004762047","pt":1580656775974,"mc":[{"id":"1.168224030","rc":[{"batb":[[0,1.7,188.12],[1,1.68,247.07],[2,1.01,10.51]],"batl":[[0,2.3,93.26],[1,2.32,84.17],[2,2.5,274.54]],"ltp":2.18,"tv":1707.95,"id":8908205}]}]}
{"op":"mcm","clk":"1004762725","pt":1580656779061,"mc":[{"id":"1.168224030","rc":[{"batl":[[0,2.5,274.54],[1,2.32,0],[2,2.5,0]],"ltp":2.18,"tv":1707.95,"id":8908205}]}]}
{"op":"mcm","clk":"1004763290","pt":1580656781609,"mc":[{"id":"1.168224030","rc":[{"batl":[[0,1.77,143.05],[1,1.79,181.12]],"ltp":2.18,"tv":1707.95,"id":8908205}]}]}
{"op":"mcm","clk":"1004763516","pt":1580656782577,"mc":[{"id":"1.168224030","rc":[{"batb":[[2,1.57,31.55]],"ltp":2.18,"tv":1707.95,"id":8908205},{"batb":[[0,2.34,19.12],[1,2.08,26.67],[2,1.01,10.51]],"ltp":1.85,"tv":416.88,"id":4596961}]}]}
{"op":"mcm","clk":"1004763779","pt":1580656783793,"mc":[{"id":"1.168224030","rc":[{"batb":[[2,1.64,65.54]],"ltp":2.18,"tv":1707.95,"id":8908205},{"batl":[[0,2.58,26.05]],"ltp":1.85,"tv":416.88,"id":4596961}]}]}
{"op":"mcm","clk":"1004764084","pt":1580656785198,"mc":[{"id":"1.168224030","rc":[{"batl":[[2,2.22,329.01]],"ltp":2.18,"tv":1707.95,"id":8908205},{"batl":[[1,3.15,200.42]],"ltp":1.85,"tv":416.88,"id":4596961}]}]}
{"op":"mcm","clk":"1004767033","pt":1580656799000,"mc":[{"id":"1.168224030","rc":[{"batb":[[0,1.57,31.55],[1,1.01,10.51],[2,1.64,0]],"batl":[[0,2.22,329.01],[1,1.79,0],[2,2.22,0]],"ltp":2.18,"tv":1707.95,"id":8908205},{"batb":[[0,2.08,26.67],[1,1.01,10.51],[2,1.01,0]],"batl":[[0,3.15,200.42],[1,3.15,0]],"ltp":1.85,"tv":416.88,"id":4596961}]}]}
{"op":"mcm","clk":"1004767649","pt":1580656801807,"mc":[{"id":"1.168224030","rc":[{"batb":[[0,1.62,213.89],[1,1.61,130.33],[2,1.57,31.55]],"batl":[[0,1.92,156.02],[1,1.94,140.76],[2,2.22,329.01]],"ltp":2.18,"tv":1707.95,"id":8908205}]}]}
{"op":"mcm","clk":"1004769710","pt":1580656810731,"mc":[{"id":"1.168224030","rc":[{"batb":[[0,1.57,31.55],[1,1.01,10.51],[2,1.57,0]],"ltp":2.18,"tv":1707.95,"id":8908205}]}]}
{"op":"mcm","clk":"1004770461","pt":1580656814121,"mc":[{"id":"1.168224030","rc":[{"batb":[[0,1.84,117.74],[1,1.82,169.34],[2,1.73,57.13]],"ltp":2.18,"tv":1707.95,"id":8908205},{"batl":[[0,2.36,30.25]],"ltp":1.85,"tv":416.88,"id":4596961}]}]}
{"op":"mcm","clk":"1004770607","pt":1580656814714,"mc":[{"id":"1.168224030","rc":[{"batb":[[0,1.84,135.92]],"ltp":2.18,"tv":1707.95,"id":8908205},{"batb":[[1,1.72,24.08],[2,1.01,10.51]],"ltp":1.85,"tv":416.88,"id":4596961}]}]}
{"op":"mcm","clk":"1004771248","pt":1580656817411,"mc":[{"id":"1.168224030","rc":[{"batl":[[1,2.82,231.28]],"ltp":1.85,"tv":416.88,"id":4596961}]}]}
{"op":"mcm","clk":"1004775084","pt":1580656834938,"mc":[{"id":"1.168224030","rc":[{"batb":[[0,1.61,28.95],[1,1.01,10.51],[2,1.73,0]],"batl":[[0,2.22,329.01],[1,1.94,0],[2,2.22,0]],"ltp":2.18,"tv":1707.95,"id":8908205},{"batb":[[0,1.72,24.08],[1,1.01,10.51],[2,1.01,0]],"batl":[[0,2.82,231.28],[1,2.82,0]],"ltp":1.85,"tv":416.88,"id":4596961}]}]}
{"op":"mcm","clk":"1004775601","pt":1580656837338,"mc":[{"id":"1.168224030","rc":[{"batb":[[0,1.65,123.53],[1,1.64,121.58],[2,1.61,28.95]],"batl":[[1,2.34,157.55],[2,2.38,158.64]],"ltp":2.18,"tv":1707.95,"id":8908205}]}]}
{"op":"mcm","clk":"1004777811","pt":1580656847075,"mc":[{"id":"1.168224030","rc":[{"batb":[[0,1.61,28.95],[1,1.01,10.51],[2,1.61,0]],"batl":[[1,2.34,0],[2,2.38,0]],"ltp":2.18,"tv":1707.95,"id":8908205}]}]}
{"op":"mcm","clk":"1004778507","pt":1580656850071,"mc":[{"id":"1.168224030","rc":[{"batb":[[0,1.75,174.18],[1,1.73,200.34],[2,1.72,24.08]],"batl":[[0,1.83,186.65],[1,1.85,162.57]],"ltp":1.85,"tv":416.88,"id":4596961}]}]}
{"op":"mcm","clk":"1004778873","pt":1580656851800,"mc":[{"id":"1.168224030","rc":[{"batb":[[0,2.26,19.67],[1,2.02,41.17],[2,1.85,17.94]],"ltp":2.18,"tv":1707.95,"id":8908205},{"batl":[[2,1.99,42.01]],"ltp":1.85,"tv":416.88,"id":4596961}]}]}
{"op":"mcm","clk":"1004779296","pt":1580656853776,"mc":[{"id":"1.168224030","rc":[{"batl":[[0,2.92,221.26]],"ltp":2.18,"tv":1707.95,"id":8908205}]}]}
{"op":"mcm","clk":"1004784152","pt":1580656873920,"mc":[{"id":"1.168224030","rc":[{"batb":[[0,2.02,41.17],[1,1.85,17.94],[2,1.01,10.51]],"ltp":2.18,"tv":1707.95,"id":8908205},{"batb":[[0,1.43,48.63],[1,1.01,10.51],[2,1.72,0]],"batl":[[0,1.99,42.01],[1,2.36,299.17],[2,1.99,0]],"ltp":1.85,"tv":416.88,"id":4596961}]}]}
{"op":"mcm","clk":"1004784358","pt":1580656874818,"mc":[{"id":"1.168224030","rc":[{"batb":[[0,1.85,17.94],[1,1.01,10.51],[2,1.01,0]],"ltp":2.18,"tv":1707.95,"id":8908205},{"batl":[[0,2.36,299.17],[1,2.36,0]],"ltp":1.85,"tv":416.88,"id":4596961}]}]}
{"op":"mcm","clk":"1004784751","pt":1580656876549,"mc":[{"id":"1.168224030","rc":[{"batb":[[0,1.44,140.88],[1,1.43,256.73],[2,1.01,10.51]],"batl":[[0,2.18,136.97],[1,2.2,97.68],[2,2.36,299.17]],"ltp":1.85,"tv":416.88,"id":4596961}]}]}
{"op":"mcm","clk":"1004785927","pt":1580656881841,"mc":[{"id":"1.168224030","rc":[{"batb":[[0,1.43,48.63],[1,1.01,10.51],[2,1.01,0]],"batl":[[0,2.36,299.17],[1,2.2,0],[2,2.36,0]],"ltp":1.85,"tv":416.88,"id":4596961}]}]}
{"op":"mcm","clk":"1004786698","pt":1580656885111,"mc":[{"id":"1.168224030","rc":[{"batb":[[0,1.85,158.65],[1,1.83,166.4],[2,1.01,10.51]],"batl":[[0,1.93,126],[1,1.95,138.63]],"ltp":2.18,"tv":1707.95,"id":8908205}]}]}
{"op":"mcm","clk":"1004786885","pt":1580656885928,"mc":[{"id":"1.168224030","rc":[{"batb":[[2,1.75,55.45]],"ltp":2.18,"tv":1707.95,"id":8908205},{"batb":[[0,2.06,26.99],[1,1.72,24.31],[2,1.01,10.51]],"batl":[[0,2.34,31.09]],"ltp":1.85,"tv":416.88,"id":4596961}]}]}
{"op":"mcm","clk":"1004787302","pt":1580656887843,"mc":[{"id":"1.168224030","rc":[{"batl":[[2,2.42,286.52]],"ltp":2.18,"tv":1707.95,"id":8908205},{"batl":[[1,2.82,231.28]],"ltp":1.85,"tv":416.88,"id":4596961}]}]}
{"op":"mcm","clk":"1004789141","pt":1580656895743,"mc":[{"id":"1.168224030","rc":[{"trd":[[1.93,58.72]],"batl":[[0,1.93,96.64]],"ltp":1.93,"tv":1766.67,"id":8908205}],"tv":2183.55}]}
{"op":"mcm","clk":"1004789806","pt":1580656898712,"mc":[{"id":"1.168224030","rc":[{"batl":[[0,1.93,115.24]],"ltp":1.93,"tv":1766.67,"id":8908205}]}]}
{"op":"mcm","clk":"1004791998","pt":1580656908117,"mc":[{"id":"1.168224030","rc":[{"batb":[[0,1.75,55.45],[1,1.61,28.56],[2,1.01,10.51]],"batl":[[0,2.42,286.52],[1,1.95,0],[2,2.42,0]],"ltp":1.93,"tv":1766.67,"id":8908205},{"batb":[[0,1.72,24.31],[1,1.01,10.51],[2,1.01,0]],"ltp":1.85,"tv":416.88,"id":4596961}]}]}
{"op":"mcm","clk":"1004792165","pt":1580656908843,"mc":[{"id":"1.168224030","rc":[{"batb":[[0,1.61,28.56],[1,1.01,10.51],[2,1.01,0]],"ltp":1.93,"tv":1766.67,"id":8908205},{"batl":[[0,2.82,231.28],[1,2.82,0]],"ltp":1.85,"tv":416.88,"id":4596961}]}]}
{"op":"mcm","clk":"1004792469","pt":1580656910144,"mc":[{"id":"1.168224030","rc":[{"batb":[[0,1.66,116.61],[1,1.65,118.92],[2,1.61,28.56]],"batl":[[0,2.36,140.45],[1,2.4,155.06],[2,2.42,286.52]],"ltp":1.93,"tv":1766.67,"id":8908205}]}]}
{"op":"mcm","clk":"1004792859","pt":1580656911825,"mc":[{"id":"1.168224030","rc":[{"batl":[[0,2.42,286.52],[1,2.4,0],[2,2.42,0]],"ltp":1.93,"tv":1766.67,"id":8908205}]}]}
{"op":"mcm","clk":"1004793537","pt":1580656914914,"mc":[{"id":"1.168224030","rc":[{"batl":[[0,1.72,158.12],[1,1.74,198.74],[2,2.42,286.52]],"ltp":1.93,"tv":1766.67,"id":8908205}]}]}
{"op":"mcm","clk":"1004793727","pt":1580656915828,"mc":[{"id":"1.168224030","rc":[{"batl":[[2,2.42,0]],"ltp":1.93,"tv":1766.67,"id":8908205},{"batb":[[0,2.48,16.21],[1,2.08,26.59],[2,1.01,10.51]],"batl":[[0,2.7,24.37]],"ltp":1.85,"tv":416.88,"id":4596961}]}]}
{"op":"mcm","clk":"1004793972","pt":1580656917025,"mc":[{"id":"1.168224030","rc":[{"batb":[[0,1.65,118.92],[1,1.61,28.56],[2,1.6,69.74]],"ltp":1.93,"tv":1766.67,"id":8908205}]}]}
{"op":"mcm","clk":"1004794286","pt":1580656918639,"mc":[{"id":"1.168224030","rc":[{"batl":[[1,3.3,191.92]],"ltp":1.85,"tv":416.88,"id":4596961}]}]}
{"op":"mcm","clk":"1004794527","pt":1580656919956,"mc":[{"id":"1.168224030","rc":[{"batb":[[0,1.65,234.08],[1,1.64,122.07],[2,1.61,28.56]],"batl":[[2,2.16,342.82]],"ltp":1.93,"tv":1766.67,"id":8908205}]}]}
{"op":"mcm","clk":"1004796633","pt":1580656929257,"mc":[{"id":"1.168224030","rc":[{"batb":[[0,1.65,204]],"ltp":1.93,"tv":1766.67,"id":8908205}]}]}
{"op":"mcm","clk":"1004797258","pt":1580656932111,"mc":[{"id":"1.168224030","rc":[{"batl":[[0,1.72,189.4]],"ltp":1.93,"tv":1766.67,"id":8908205}]}]}
{"op":"mcm","clk":"1004800268","pt":1580656947102,"mc":[{"id":"1.168224030","rc":[{"batb":[[0,1.65,173.68]],"batl":[[0,2.16,342.82],[1,1.74,0],[2,2.16,0]],"ltp":1.93,"tv":1766.67,"id":8908205}]}]}
{"op":"mcm","clk":"1004800887","pt":1580656950125,"mc":[{"id":"1.168224030","rc":[{"batl":[[0,1.71,116.21],[1,1.73,203.12],[2,2.16,342.82]],"ltp":1.93,"tv":1766.67,"id":8908205}]}]}
{"op":"mcm","clk":"1004801214","pt":1580656951825,"mc":[{"id":"1.168224030","rc":[{"batb":[[0,1.61,28.56],[1,1.6,69.74],[2,1.43,46.34]],"batl":[[0,2.16,342.82],[1,1.73,0],[2,2.16,0]],"ltp":1.93,"tv":1766.67,"id":8908205}]}]}
{"op":"mcm","clk":"1004801795","pt":1580656954725,"mc":[{"id":"1.168224030","rc":[{"batb":[[2,1.46,164.41]],"batl":[[0,1.93,106.9],[1,1.95,138.89],[2,2.16,342.82]],"ltp":1.93,"tv":1766.67,"id":8908205}]}]}
{"op":"mcm","clk":"1004803040","pt":1580656960871,"mc":[{"id":"1.168224030","rc":[{"batb":[[0,1.46,164.41],[1,1.45,197.66],[2,1.43,46.34]],"ltp":1.93,"tv":1766.67,"id":8908205},{"batb":[[0,2.08,26.59],[1,1.01,10.51],[2,1.01,0]],"batl":[[0,3.3,191.92],[1,3.3,0]],"ltp":1.85,"tv":416.88,"id":4596961}]}]}
{"op":"mcm","clk":"1004804408","pt":1580656967664,"mc":[{"id":"1.168224030","rc":[{"batb":[[0,1.43,46.34],[1,1.01,10.51],[2,1.43,0]],"ltp":1.93,"tv":1766.67,"id":8908205}]}]}
{"op":"mcm","clk":"1004805076","pt":1580656970865,"mc":[{"id":"1.168224030","rc":[{"batb":[[0,1.85,161.33],[1,1.83,166.71],[2,1.43,46.34]],"batl":[[2,2.16,0]],"ltp":1.93,"tv":1766.67,"id":8908205}]}]}
{"op":"mcm","clk":"1004805316","pt":1580656971887,"mc":[{"id":"1.168224030","rc":[{"batb":[[1,1.84,18.18],[2,1.83,166.71]],"ltp":1.93,"tv":1766.67,"id":8908205},{"batb":[[1,1.81,20.46],[2,1.01,10.51]],"batl":[[0,2.36,30.25]],"ltp":1.85,"tv":416.88,"id":4596961}]}]}
{"op":"mcm","clk":"1004805908","pt":1580656974888,"mc":[{"id":"1.168224030","rc":[{"batl":[[2,2.5,274.54]],"ltp":1.93,"tv":1766.67,"id":8908205},{"batl":[[1,2.72,241.55]],"ltp":1.85,"tv":416.88,"id":4596961}]}]}
{"op":"mcm","clk":"1004807639","pt":1580656983010,"mc":[{"id":"1.168224030","rc":[{"batb":[[0,1.61,29.03],[1,1.01,10.51],[2,1.83,0]],"batl":[[0,2.5,274.54],[1,1.95,0],[2,2.5,0]],"ltp":1.93,"tv":1766.67,"id":8908205},{"batb":[[0,1.81,20.46],[1,1.01,10.51],[2,1.01,0]],"batl":[[0,2.72,241.55],[1,2.72,0]],"ltp":1.85,"tv":416.88,"id":4596961}]}]}
{"op":"mcm","clk":"1004808165","pt":1580656985443,"mc":[{"id":"1.168224030","rc":[{"batb":[[0,1.63,198.76],[1,1.62,127.72],[2,1.61,29.03]],"batl":[[0,2.18,115.88],[1,2.2,97.76],[2,2.5,274.54]],"ltp":1.93,"tv":1766.67,"id":8908205}]}]}
{"op":"mcm","clk":"1004808287","pt":1580656986179,"mc":[{"id":"1.168224030","rc":[{"batl":[[0,1.85,12],[1,2.18,115.88],[2,2.2,97.76]],"ltp":1.93,"tv":1766.67,"id":8908205}]}]}
{"op":"mcm","clk":"1004809721","pt":1580656993123,"mc":[{"id":"1.168224030","rc":[{"batb":[[0,1.61,29.03],[1,1.01,10.51],[2,1.61,0]],"batl":[[1,2.5,274.54],[2,2.2,0]],"ltp":1.93,"tv":1766.67,"id":8908205}]}]}
{"op":"mcm","clk":"1004810318","pt":1580656996118,"mc":[{"id":"1.168224030","rc":[{"trd":[[1.85,12]],"ltp":1.85,"tv":1778.67,"id":8908205},{"trd":[[2.16,10.28]],"batb":[[0,1.85,115.85],[1,1.83,166.52],[2,1.81,20.46]],"batl":[[0,1.93,139.48],[1,1.95,138.7]],"ltp":2.16,"tv":427.16,"id":4596961}],"tv":2205.83}]}
{"op":"mcm","clk":"1004810501","pt":1580656996924,"mc":[{"id":"1.168224030","rc":[{"batb":[[0,2.12,23.53],[1,1.87,17.31],[2,1.61,29.03]],"ltp":1.85,"tv":1778.67,"id":8908205}]}]}
{"op":"mcm","clk":"1004810696","pt":1580656997840,"mc":[{"id":"1.168224030","rc":[{"batb":[[2,1.85,11.76]],"ltp":1.85,"tv":1778.67,"id":8908205},{"batl":[[2,2.04,10.6]],"ltp":2.16,"tv":427.16,"id":4596961}]}]}
{"op":"mcm","clk":"1004810783","pt":1580656998221,"mc":[{"id":"1.168224030","rc":[{"batb":[[2,1.01,10.51]],"ltp":1.85,"tv":1778.67,"id":8908205},{"batl":[[2,2.04,0]],"ltp":2.16,"tv":427.16,"id":4596961}]}]}
{"op":"mcm","clk":"1004811209","pt":1580657000020,"mc":[{"id":"1.168224030","rc":[{"batb":[[1,1.88,47.05],[2,1.87,17.31]],"batl":[[0,2.82,231.28]],"ltp":1.85,"tv":1778.67,"id":8908205},{"batb":[[0,1.85,140.83]],"batl":[[2,2.12,36.97]],"ltp":2.16,"tv":427.16,"id":4596961}]}]}
{"op":"mcm","clk":"1004813400","pt":1580657010982,"mc":[{"id":"1.168224030","rc":[{"batb":[[0,1.81,20.46],[1,1.64,28.64],[2,1.01,10.51]],"batl":[[0,2.12,36.97],[1,2.42,286.52],[2,2.12,0]],"ltp":2.16,"tv":427.16,"id":4596961}]}]}
{"op":"mcm","clk":"1004813443","pt":1580657011131,"mc":[{"id":"1.168224030","rc":[{"batb":[[0,1.88,47.05],[1,1.87,17.31],[2,1.01,10.51]],"ltp":1.85,"tv":1778.67,"id":8908205},{"batb":[[0,1.64,28.64],[1,1.01,10.51],[2,1.01,0]],"ltp":2.16,"tv":427.16,"id":4596961}]}]}
{"op":"mcm","clk":"1004813820","pt":1580657012935,"mc":[{"id":"1.168224030","rc":[{"batb":[[0,1.87,17.31],[1,1.01,10.51],[2,1.01,0]],"ltp":1.85,"tv":1778.67,"id":8908205},{"batl":[[0,2.42,286.52],[1,2.42,0]],"ltp":2.16,"tv":427.16,"id":4596961}]}]}
{"op":"mcm","clk":"1004814468","pt":1580657016029,"mc":[{"id":"1.168224030","rc":[{"batb":[[0,1.89,109.48],[1,1.87,155.36],[2,1.64,28.64]],"batl":[[0,1.97,125.5],[1,1.99,130.55],[2,2.42,286.52]],"ltp":2.16,"tv":427.16,"id":4596961}]}]}
{"op":"mcm","clk":"1004815045","pt":1580657018853,"mc":[{"id":"1.168224030","rc":[{"trd":[[1.89,0.04]],"batb":[[0,1.64,28.64],[1,1.01,10.51],[2,1.64,0]],"batl":[[0,2.42,286.52],[1,1.99,0],[2,2.42,0]],"ltp":1.89,"tv":427.19,"id":4596961}],"tv":2205.87}]}
{"op":"mcm","clk":"1004816387","pt":1580657025072,"mc":[{"id":"1.168224030","rc":[{"batb":[[0,1.87,151.88],[1,1.85,160.89],[2,1.01,10.51]],"batl":[[0,1.95,116.65],[1,1.97,134.66]],"ltp":1.85,"tv":1778.67,"id":8908205}]}]}
{"op":"mcm","clk":"1004816553","pt":1580657025866,"mc":[{"id":"1.168224030","rc":[{"batb":[[2,1.76,54.61]],"ltp":1.85,"tv":1778.67,"id":8908205},{"batb":[[0,2.04,28.01],[1,1.74,23.45],[2,1.01,10.51]],"batl":[[0,2.34,31.09]],"ltp":1.89,"tv":427.19,"id":4596961}]}]}
{"op":"mcm","clk":"1004816771","pt":1580657027006,"mc":[{"id":"1.168224030","rc":[{"batl":[[2,2.5,274.54]],"ltp":1.85,"tv":1778.67,"id":8908205},{"batl":[[1,2.72,241.55]],"ltp":1.89,"tv":427.19,"id":4596961}]}]}
{"op":"mcm","clk":"1004818442","pt":1580657034992,"mc":[{"id":"1.168224030","rc":[{"trd":[[2.04,16.47]],"batb":[[0,2.04,19.78]],"ltp":2.04,"tv":443.66,"id":4596961}],"tv":2222.34}]}
{"op":"mcm","clk":"1004820334","pt":1580657043839,"mc":[{"id":"1.168224030","rc":[{"batb":[[0,1.87,17.31],[1,1.76,54.61],[2,1.6,29.43]],"batl":[[0,2.5,274.54],[1,1.97,0],[2,2.5,0]],"ltp":1.85,"tv":1778.67,"id":8908205}]}]}
{"op":"mcm","clk":"1004820588","pt":1580657044941,"mc":[{"id":"1.168224030","rc":[{"batb":[[0,1.6,29.43],[1,1.01,10.51],[2,1.6,0]],"ltp":1.85,"tv":1778.67,"id":8908205},{"batb":[[0,1.74,23.45],[1,1.01,10.51],[2,1.01,0]],"batl":[[0,2.72,241.55],[1,2.72,0]],"ltp":2.04,"tv":443.66,"id":4596961}]}]}
{"op":"mcm","clk":"1004821034","pt":1580657047003,"mc":[{"id":"1.168224030","rc":[{"batb":[[0,1.61,199.18],[1,1.6,163.17],[2,1.01,10.51]],"batl":[[0,2.26,133.55],[1,2.28,88.53],[2,2.5,274.54]],"ltp":1.85,"tv":1778.67,"id":8908205}]}]}
{"op":"mcm","clk":"1004821166","pt":1580657047658,"mc":[{"id":"1.168224030","rc":[{"batb":[[1,1.6,162.93]],"ltp":1.85,"tv":1778.67,"id":8908205},{"batb":[[0,1.73,23.6]],"ltp":2.04,"tv":443.66,"id":4596961}]}]}
{"op":"mcm","clk":"1004821420","pt":1580657048834,"mc":[{"id":"1.168224030","rc":[{"batb":[[0,1.6,29.19],[1,1.01,10.51],[2,1.01,0]],"batl":[[0,2.5,274.54],[1,2.28,0],[2,2.5,0]],"ltp":1.85,"tv":1778.67,"id":8908205}]}]}
{"op":"mcm","clk":"1004822104","pt":1580657052069,"mc":[{"id":"1.168224030","rc":[{"batb":[[0,1.93,44.53],[1,1.6,29.19],[2,1.01,10.51]],"ltp":1.85,"tv":1778.67,"id":8908205},{"batb":[[0,1.8,111.02],[1,1.78,182.24],[2,1.73,23.6]],"batl":[[0,1.87,120.7],[1,1.89,152.55],[2,2.06,39.49]],"ltp":2.04,"tv":443.66,"id":4596961}]}]}
{"op":"mcm","clk":"1004822308","pt":1580657053062,"mc":[{"id":"1.168224030","rc":[{"batb":[[0,2.24,20.14],[1,1.97,29.58],[2,1.93,44.53]],"ltp":1.85,"tv":1778.67,"id":8908205}]}]}
{"op":"mcm","clk":"1004822800","pt":1580657055557,"mc":[{"id":"1.168224030","rc":[{"batl":[[0,2.92,221.26]],"ltp":1.85,"tv":1778.67,"id":8908205}]}]}
{"op":"mcm","clk":"1004824364","pt":1580657062988,"mc":[{"id":"1.168224030","rc":[{"batb":[[0,1.97,29.58],[1,1.01,10.51],[2,1.93,0]],"ltp":1.85,"tv":1778.67,"id":8908205},{"batb":[[0,1.58,32.81],[1,1.4,2.53],[2,1.01,10.51]],"batl":[[0,2.36,299.17],[1,1.89,0],[2,2.06,0]],"ltp":2.04,"tv":443.66,"id":4596961}]}]}
{"op":"mcm","clk":"1004824873","pt":1580657065491,"mc":[{"id":"1.168224030","rc":[{"batb":[[0,1.67,227.44],[1,1.66,116.66],[2,1.58,32.81]],"batl":[[0,2.08,188.27],[1,2.1,111.58],[2,2.36,299.17]],"ltp":2.04,"tv":443.66,"id":4596961}]}]}
{"op":"mcm","clk":"1004825634","pt":1580657069052,"mc":[{"id":"1.168224030","rc":[{"batl":[[0,2.36,299.17],[1,2.1,0],[2,2.36,0]],"ltp":2.04,"tv":443.66,"id":4596961}]}]}
{"op":"mcm","clk":"1004826308","pt":1580657072076,"mc":[{"id":"1.168224030","rc":[{"batl":[[0,1.74,139.85],[1,1.76,191.18]],"ltp":2.04,"tv":443.66,"id":4596961}]}]}
{"op":"mcm","clk":"1004826419","pt":1580657072634,"mc":[{"id":"1.168224030","rc":[{"trd":[[2.5,13.85]],"batb":[[0,2.12,23.53]],"ltp":2.5,"tv":1792.52,"id":8908205},{"trd":[[1.67,20.73]],"batb":[[0,1.67,206.71]],"ltp":1.67,"tv":464.39,"id":4596961}],"tv":2256.92}]}
{"op":"mcm","clk":"1004826684","pt":1580657073902,"mc":[{"id":"1.168224030","rc":[{"batb":[[1,2.06,39.49],[2,1.01,10.51]],"ltp":2.5,"tv":1792.52,"id":8908205},{"batl":[[2,1.94,42.01]],"ltp":1.67,"tv":464.39,"id":4596961}]}]}
{"op":"mcm","clk":"1004826841","pt":1580657074698,"mc":[{"id":"1.168224030","rc":[{"batl":[[0,3.3,191.92]],"ltp":2.5,"tv":1792.52,"id":8908205}]}]}
{"op":"mcm","clk":"1004827348","pt":1580657077131,"mc":[{"id":"1.168224030","rc":[{"batb":[[1,1.01,10.51],[2,1.01,0]],"ltp":2.5,"tv":1792.52,"id":8908205},{"batl":[[2,2.16,342.82]],"ltp":1.67,"tv":464.39,"id":4596961}]}]}
{"op":"mcm","clk":"1004827964","pt":1580657079995,"mc":[{"id":"1.168224030","rc":[{"batb":[[1,2.08,38.65],[2,1.01,10.51]],"ltp":2.5,"tv":1792.52,"id":8908205},{"batl":[[2,1.93,42.01]],"ltp":1.67,"tv":464.39,"id":4596961}]}]}
{"op":"mcm","clk":"1004828151","pt":1580657080925,"mc":[{"id":"1.168224030","rc":[{"trd":[[2.5,28.25]],"batb":[[0,2.1,24.39]],"ltp":2.5,"tv":1806.92,"id":8908205},{"trd":[[1.67,42.28]],"batb":[[0,1.67,185.16],[2,1.59,31.71]],"ltp":1.67,"tv":485.94,"id":4596961}],"tv":2292.86}]}
{"op":"mcm","clk":"1004828827","pt":1580657084123,"mc":[{"id":"1.168224030","rc":[{"batl":[[0,1.74,163.6]],"ltp":1.67,"tv":485.94,"id":4596961}]}]}
{"op":"mcm","clk":"1004829015","pt":1580657085026,"mc":[{"id":"1.168224030","rc":[{"batl":[[2,2.16,342.82]],"ltp":1.67,"tv":485.94,"id":4596961}]}]}
{"op":"mcm","clk":"1004829671","pt":1580657088050,"mc":[{"id":"1.168224030","rc":[{"batl":[[2,1.92,42.01]],"ltp":1.67,"tv":485.94,"id":4596961}]}]}
{"op":"mcm","clk":"1004829812","pt":1580657088747,"mc":[{"id":"1.168224030","rc":[{"batb":[[0,2.46,15.58],[2,2.04,26.28]],"ltp":2.5,"tv":1806.92,"id":8908205},{"batb":[[2,1.62,29.66]],"ltp":1.67,"tv":485.94,"id":4596961}]}]}
{"op":"mcm","clk":"1004830040","pt":1580657089938,"mc":[{"id":"1.168224030","rc":[{"batb":[[1,2.04,26.28],[2,1.01,10.51]],"ltp":2.5,"tv":1806.92,"id":8908205},{"batl":[[2,2.16,342.82]],"ltp":1.67,"tv":485.94,"id":4596961}]}]}
{"op":"mcm","clk":"1004830610","pt":1580657092746,"mc":[{"id":"1.168224030","rc":[{"batb":[[1,2.1,37.81],[2,2.04,26.28]],"ltp":2.5,"tv":1806.92,"id":8908205},{"batl":[[2,1.91,42.01]],"ltp":1.67,"tv":485.94,"id":4596961}]}]}
{"op":"mcm","clk":"1004830926","pt":1580657094241,"mc":[{"id":"1.168224030","rc":[{"trd":[[2.46,25.21]],"batb":[[0,2.46,2.97]],"ltp":2.46,"tv":1832.13,"id":8908205}],"tv":2318.07}]}
{"op":"mcm","clk":"1004831410","pt":1580657096744,"mc":[{"id":"1.168224030","rc":[{"batb":[[0,2.44,15.97],[1,2.02,26.99],[2,1.01,10.51]],"ltp":2.46,"tv":1832.13,"id":8908205},{"batb":[[2,1.63,28.95]],"batl":[[2,2.16,342.82]],"ltp":1.67,"tv":485.94,"id":4596961}]}]}
{"op":"mcm","clk":"1004831918","pt":1580657099303,"mc":[{"id":"1.168224030","rc":[{"batb":[[1,2.12,36.97],[2,2.02,26.99]],"ltp":2.46,"tv":1832.13,"id":8908205},{"batl":[[2,1.89,42.01]],"ltp":1.67,"tv":485.94,"id":4596961}]}]}
{"op":"mcm","clk":"1004832897","pt":1580657103847,"mc":[{"id":"1.168224030","rc":[{"trd":[[2.44,26.89]],"batb":[[0,2.44,2.53]],"ltp":2.44,"tv":1859.01,"id":8908205}],"tv":2344.96}]}
{"op":"mcm","clk":"1004833155","pt":1580657105055,"mc":[{"id":"1.168224030","rc":[{"batb":[[0,2.42,16.29]],"ltp":2.44,"tv":1859.01,"id":8908205},{"batb":[[2,1.64,28.56]],"ltp":1.67,"tv":485.94,"id":4596961}]}]}
{"op":"mcm","clk":"1004833875","pt":1580657108532,"mc":[{"id":"1.168224030","rc":[{"trd":[[2.42,0.01]],"batb":[[0,2.42,16.28]],"ltp":2.42,"tv":1859.03,"id":8908205},{"trd":[[1.71,0.02]],"batl":[[0,1.74,198.24]],"ltp":1.71,"tv":485.95,"id":4596961}],"tv":2344.98}]}
{"op":"mcm","clk":"1004834800","pt":1580657112829,"mc":[{"id":"1.168224030","rc":[{"batb":[[0,2.4,16.52],[2,2,27.85]],"ltp":2.42,"tv":1859.03,"id":8908205},{"batb":[[2,1.65,28.09]],"ltp":1.71,"tv":485.95,"id":4596961}]}]}
{"op":"mcm","clk":"1004835703","pt":1580657116912,"mc":[{"id":"1.168224030","rc":[{"batb":[[1,2,27.85],[2,1.01,10.51]],"ltp":2.42,"tv":1859.03,"id":8908205}]}]}
{"op":"mcm","clk":"1004836334","pt":1580657119935,"mc":[{"id":"1.168224030","rc":[{"batb":[[1,2.14,36.13],[2,2,27.85]],"ltp":2.42,"tv":1859.03,"id":8908205}]}]}
{"op":"mcm","clk":"1004844781","pt":1580657160820,"mc":[{"id":"1.168224030","rc":[{"batb":[[0,1.65,28.09],[1,1.4,55.64],[2,1.01,10.51]],"batl":[[0,1.89,42.01],[1,2.16,342.82],[2,1.89,0]],"ltp":1.71,"tv":485.95,"id":4596961}]}]}
{"op":"mcm","clk":"1004844932","pt":1580657161535,"mc":[{"id":"1.168224030","rc":[{"batb":[[0,2.14,36.13],[1,2,27.85],[2,1.01,10.51]],"ltp":2.42,"tv":1859.03,"id":8908205},{"batb":[[0,1.4,55.64],[1,1.01,10.51],[2,1.01,0]],"batl":[[0,2.16,342.82],[1,2.16,0]],"ltp":1.71,"tv":485.95,"id":4596961}]}]}
{"op":"mcm","clk":"1004845192","pt":1580657162912,"mc":[{"id":"1.168224030","rc":[{"batb":[[0,2,27.85],[1,1.01,10.51],[2,1.01,0]],"ltp":2.42,"tv":1859.03,"id":8908205}]}]}
{"op":"mcm","clk":"1004845383","pt":1580657163832,"mc":[{"id":"1.168224030","rc":[{"batb":[[0,1.43,338.39],[1,1.42,217.26],[2,1.4,55.64]],"batl":[[0,1.96,108.6],[1,1.98,132.72],[2,2.16,342.82]],"ltp":1.71,"tv":485.95,"id":4596961}]}]}
{"op":"mcm","clk":"1004845599","pt":1580657165018,"mc":[{"id":"1.168224030","rc":[{"batl":[[0,1.87,42.01],[1,1.96,108.6],[2,1.98,132.72]],"ltp":1.71,"tv":485.95,"id":4596961}]}]}
{"op":"mcm","clk":"1004845653","pt":1580657165303,"mc":[{"id":"1.168224030","rc":[{"batl":[[0,1.96,108.6],[1,1.98,132.72],[2,2.16,342.82]],"ltp":1.71,"tv":485.95,"id":4596961}]}]}
{"op":"mcm","clk":"1004846332","pt":1580657168483,"mc":[{"id":"1.168224030","rc":[{"batb":[[0,1.4,55.64],[1,1.01,10.51],[2,1.4,0]],"batl":[[0,2.16,342.82],[1,1.98,0],[2,2.16,0]],"ltp":1.71,"tv":485.95,"id":4596961}]}]}
{"op":"mcm","clk":"1004847127","pt":1580657172077,"mc":[{"id":"1.168224030","rc":[{"batb":[[0,3.2,19.2],[1,2.66,25.21],[2,2.48,15.26]],"ltp":2.42,"tv":1859.03,"id":8908205},{"batb":[[0,1.43,338.39],[1,1.42,217.26],[2,1.4,55.64]],"batl":[[0,1.48,187.92],[1,1.49,172.61],[2,1.6,42.01]],"ltp":1.71,"tv":485.95,"id":4596961}]}]}
{"op":"mcm","clk":"1004847255","pt":1580657172677,"mc":[{"id":"1.168224030","rc":[{"batb":[[1,2.48,15.26],[2,1.01,10.51]],"ltp":2.42,"tv":1859.03,"id":8908205},{"batb":[[0,1.43,208.8],[1,1.4,55.64],[2,1.19,125.58]],"batl":[[2,1.6,0]],"ltp":1.71,"tv":485.95,"id":4596961}]}]}
{"op":"mcm","clk":"1004847466","pt":1580657173577,"mc":[{"id":"1.168224030","rc":[{"batl":[[0,4.6,136.05]],"ltp":2.42,"tv":1859.03,"id":8908205},{"batl":[[2,1.82,469.11]],"ltp":1.71,"tv":485.95,"id":4596961}]}]}
{"op":"mcm","clk":"1004848024","pt":1580657175791,"mc":[{"id":"1.168224030","rc":[{"batb":[[0,1.44,136.04],[1,1.43,208.8],[2,1.4,55.64]],"batl":[[2,1.59,42.01]],"ltp":1.71,"tv":485.95,"id":4596961}]}]}
{"op":"mcm","clk":"1004848706","pt":1580657179080,"mc":[{"id":"1.168224030","rc":[{"batl":[[2,1.82,469.11]],"ltp":1.71,"tv":485.95,"id":4596961}]}]}
{"op":"mcm","clk":"1004849303","pt":1580657181989,"mc":[{"id":"1.168224030","rc":[{"trd":[[3.2,36.97]],"batb":[[0,2.72,25.08]],"ltp":3.2,"tv":1896.0,"id":8908205},{"batl":[[2,1.58,42.01]],"ltp":1.71,"tv":485.95,"id":4596961}],"tv":2381.95}]}
{"op":"mcm","clk":"1004850613","pt":1580657187980,"mc":[{"id":"1.168224030","rc":[{"batb":[[0,1.4,55.64],[1,1.19,125.58],[2,1.01,10.51]],"batl":[[0,1.58,42.01],[1,1.82,469.11],[2,1.58,0]],"ltp":1.71,"tv":485.95,"id":4596961}]}]}
{"op":"mcm","clk":"1004850799","pt":1580657188913,"mc":[{"id":"1.168224030","rc":[{"batb":[[0,2.48,15.26],[1,1.01,10.51],[2,1.01,0]],"ltp":3.2,"tv":1896.0,"id":8908205},{"batb":[[0,1.4,2.53]],"batl":[[0,1.82,469.11],[1,1.82,0]],"ltp":1.71,"tv":485.95,"id":4596961}]}]}
{"op":"mcm","clk":"1004851248","pt":1580657190988,"mc":[{"id":"1.168224030","rc":[{"batb":[[1,1.23,197.46],[2,1.22,482.65]],"batl":[[0,1.69,128.78],[1,1.71,210.72]],"ltp":1.71,"tv":485.95,"id":4596961}]}]}
{"op":"mcm","clk":"1004851494","pt":1580657192110,"mc":[{"id":"1.168224030","rc":[{"batb":[[0,2.4,16.6]],"ltp":3.2,"tv":1896.0,"id":8908205},{"batb":[[1,1.2,117.94],[2,1.01,10.51]],"ltp":1.71,"tv":485.95,"id":4596961}]}]}
{"op":"mcm","clk":"1004852111","pt":1580657195106,"mc":[{"id":"1.168224030","rc":[{"batb":[[0,1.63,183.76],[1,1.62,127.46],[2,1.4,2.53]],"ltp":1.71,"tv":485.95,"id":4596961}]}]}
{"op":"mcm","clk":"1004852327","pt":1580657196105,"mc":[{"id":"1.168224030","rc":[{"batb":[[1,2.26,32.77],[2,1.94,15.42]],"ltp":3.2,"tv":1896.0,"id":8908205},{"batb":[[0,1.65,28.09],[1,1.63,183.76],[2,1.62,127.46]],"batl":[[2,1.79,42.01]],"ltp":1.71,"tv":485.95,"id":4596961}]}]}
{"op":"mcm","clk":"1004852593","pt":1580657197415,"mc":[{"id":"1.168224030","rc":[{"batl":[[0,3.45,180.4]],"ltp":3.2,"tv":1896.0,"id":8908205}]}]}
{"op":"mcm","clk":"1004855793","pt":1580657213110,"mc":[{"id":"1.168224030","rc":[{"batb":[[0,2.26,32.77],[1,1.94,15.42],[2,1.01,10.51]],"ltp":3.2,"tv":1896.0,"id":8908205},{"batb":[[0,1.36,61.14],[1,1.01,10.51],[2,1.62,0]],"batl":[[0,1.79,42.01],[1,2.1,363.31],[2,1.79,0]],"ltp":1.71,"tv":485.95,"id":4596961}]}]}
{"op":"mcm","clk":"1004855855","pt":1580657213431,"mc":[{"id":"1.168224030","rc":[{"batb":[[0,1.7,2.53],[1,1.36,61.14],[2,1.01,10.51]],"ltp":1.71,"tv":485.95,"id":4596961}]}]}
{"op":"mcm","clk":"1004856144","pt":1580657214940,"mc":[{"id":"1.168224030","rc":[{"batb":[[0,1.94,15.42],[1,1.01,10.51],[2,1.01,0]],"ltp":3.2,"tv":1896.0,"id":8908205},{"batl":[[0,2.1,363.31],[1,2.1,0]],"ltp":1.71,"tv":485.95,"id":4596961}]}]}
{"op":"mcm","clk":"1004856322","pt":1580657215727,"mc":[{"id":"1.168224030","rc":[{"batb":[[1,1.37,163.14],[2,1.36,324.14]],"batl":[[0,1.97,161.71],[1,1.99,130.68],[2,2.1,363.31]],"ltp":1.71,"tv":485.95,"id":4596961}]}]}
{"op":"mcm","clk":"1004856579","pt":1580657216849,"mc":[{"id":"1.168224030","rc":[{"batb":[[1,1.36,61.14],[2,1.01,10.51]],"batl":[[0,2.1,363.31],[1,1.99,0],[2,2.1,0]],"ltp":1.71,"tv":485.95,"id":4596961}]}]}
{"op":"mcm","clk":"1004857288","pt":1580657219988,"mc":[{"id":"1.168224030","rc":[{"trd":[[1.7,5.07]],"batb":[[0,1.57,185.79],[1,1.56,146.77],[2,1.36,61.14]],"batl":[[0,1.63,205.96],[1,1.64,120.62],[2,2.1,363.31]],"ltp":1.7,"tv":491.03,"id":4596961}],"tv":2387.03}]}
{"op":"mcm","clk":"1004858168","pt":1580657223868,"mc":[{"id":"1.168224030","rc":[{"batb":[[0,1.36,61.14],[1,1.01,10.51],[2,1.36,0]],"batl":[[0,2.1,363.31],[1,1.64,0],[2,2.1,0]],"ltp":1.7,"tv":491.03,"id":4596961}]}]}
{"op":"mcm","clk":"1004858877","pt":1580657227092,"mc":[{"id":"1.168224030","rc":[{"batb":[[0,1.37,164.3],[1,1.36,324.15],[2,1.01,10.51]],"batl":[[0,1.97,160.9],[1,1.99,130.68],[2,2.1,363.31]],"ltp":1.7,"tv":491.03,"id":4596961}]}]}
{"op":"mcm","clk":"1004860119","pt":1580657232777,"mc":[{"id":"1.168224030","rc":[{"batb":[[0,1.36,61.14],[1,1.01,10.51],[2,1.01,0]],"ltp":1.7,"tv":491.03,"id":4596961}]}]}
{"op":"mcm","clk":"1004860774","pt":1580657235921,"mc":[{"id":"1.168224030","rc":[{"batb":[[0,1.88,150.29],[1,1.86,158.27],[2,1.36,61.14]],"batl":[[2,2.1,0]],"ltp":1.7,"tv":491.03,"id":4596961}]}]}
{"op":"mcm","clk":"1004860996","pt":1580657236787,"mc":[{"id":"1.168224030","rc":[{"batb":[[1,1.68,24.71],[2,1.01,10.51]],"ltp":3.2,"tv":1896.0,"id":8908205},{"trd":[[1.97,31.16]],"batb":[[2,1.61,30.14]],"batl":[[0,1.97,145.32]],"ltp":1.97,"tv":522.19,"id":4596961}],"tv":2418.19}]}
{"op":"mcm","clk":"1004861239","pt":1580657237882,"mc":[{"id":"1.168224030","rc":[{"batb":[[0,1.94,59.95]],"ltp":3.2,"tv":1896.0,"id":8908205},{"batl":[[2,2.06,39.49]],"ltp":1.97,"tv":522.19,"id":4596961}]}]}
{"op":"mcm","clk":"1004861406","pt":1580657238695,"mc":[{"id":"1.168224030","rc":[{"batl":[[0,2.72,241.55]],"ltp":3.2,"tv":1896.0,"id":8908205}]}]}
{"op":"mcm","clk":"1004864470","pt":1580657254565,"mc":[{"id":"1.168224030","rc":[{"trd":[[1.88,4.06]],"batb":[[0,1.88,148.26]],"ltp":1.88,"tv":526.25,"id":4596961}],"tv":2422.25}]}
{"op":"mcm","clk":"1004864961","pt":1580657257080,"mc":[{"id":"1.168224030","rc":[{"batb":[[0,1.68,24.71],[1,1.01,10.51],[2,1.01,0]],"ltp":3.2,"tv":1896.0,"id":8908205},{"batb":[[0,1.61,30.14],[1,1.01,10.51],[2,1.61,0]],"batl":[[0,2.5,274.54],[1,1.99,0],[2,2.06,0]],"ltp":1.88,"tv":526.25,"id":4596961}]}]}
{"op":"mcm","clk":"1004865701","pt":1580657260664,"mc":[{"id":"1.168224030","rc":[{"batb":[[0,1.69,24.31]],"ltp":3.2,"tv":1896.0,"id":8908205},{"batb":[[0,1.6,31.24]],"ltp":1.88,"tv":526.25,"id":4596961}]}]}
{"op":"mcm","clk":"1004866060","pt":1580657262586,"mc":[{"id":"1.168224030","rc":[{"batb":[[0,1.82,110.44],[1,1.8,175.89],[2,1.6,31.24]],"batl":[[0,1.89,106.28],[1,1.91,147.93],[2,2.5,274.54]],"ltp":1.88,"tv":526.25,"id":4596961}]}]}
{"op":"mcm","clk":"1004866873","pt":1580657266881,"mc":[{"id":"1.168224030","rc":[{"batb":[[0,1.6,31.24],[1,1.01,10.51],[2,1.6,0]],"batl":[[0,2.5,274.54],[1,1.91,0],[2,2.5,0]],"ltp":1.88,"tv":526.25,"id":4596961}]}]}
{"op":"mcm","clk":"1004867514","pt":1580657270093,"mc":[{"id":"1.168224030","rc":[{"batb":[[1,1.59,208.48],[2,1.58,139.93]],"batl":[[0,2.26,140.8],[1,2.28,88.76],[2,2.5,274.54]],"ltp":1.88,"tv":526.25,"id":4596961}]}]}
{"op":"mcm","clk":"1004871820","pt":1580657292167,"mc":[{"id":"1.168224030","rc":[{"batb":[[1,1.01,10.51],[2,1.58,0]],"batl":[[0,2.5,274.54],[1,2.28,0],[2,2.5,0]],"ltp":1.88,"tv":526.25,"id":4596961}]}]}
{"op":"mcm","clk":"1004872593","pt":1580657296058,"mc":[{"id":"1.168224030","rc":[{"trd":[[1.8,24.5]],"batb":[[0,1.8,95.46],[1,1.78,182.74],[2,1.74,56.29]],"batl":[[0,1.87,113.61],[1,1.89,153.01]],"ltp":1.8,"tv":1920.5,"id":8908205},{"trd":[[2.26,19.51]],"batb":[[0,2.02,29.27],[1,1.6,31.24],[2,1.01,10.51]],"batl":[[0,2.36,30.25]],"ltp":2.26,"tv":545.76,"id":4596961}],"tv":2466.26}]}
{"op":"mcm","clk":"1004872707","pt":1580657296542,"mc":[{"id":"1.168224030","rc":[{"batb":[[0,1.74,56.29],[1,1.69,24.31],[2,1.56,32.18]],"ltp":1.8,"tv":1920.5,"id":8908205},{"batb":[[1,1.01,10.51],[2,1.01,0]],"ltp":2.26,"tv":545.76,"id":4596961}]}]}
{"op":"mcm","clk":"1004872876","pt":1580657297488,"mc":[{"id":"1.168224030","rc":[{"batl":[[2,2.36,299.17]],"ltp":1.8,"tv":1920.5,"id":8908205},{"batl":[[1,2.92,221.26]],"ltp":2.26,"tv":545.76,"id":4596961}]}]}
{"op":"mcm","clk":"1004873250","pt":1580657299467,"mc":[{"id":"1.168224030","rc":[{"batb":[[0,1.79,193.05],[1,1.77,186.42],[2,1.74,56.29]],"ltp":1.8,"tv":1920.5,"id":8908205}]}]}
{"op":"mcm","clk":"1004876184","pt":1580657314993,"mc":[{"id":"1.168224030","rc":[{"batb":[[0,1.56,32.18],[1,1.01,10.51],[2,1.74,0]],"batl":[[0,2.36,299.17],[1,1.89,0],[2,2.36,0]],"ltp":1.8,"tv":1920.5,"id":8908205},{"batl":[[0,2.92,221.26],[1,2.92,0]],"ltp":2.26,"tv":545.76,"id":4596961}]}]}
{"op":"mcm","clk":"1004876743","pt":1580657318121,"mc":[{"id":"1.168224030","rc":[{"batb":[[0,1.69,181.51],[1,1.67,227.61],[2,1.59,30.37]],"batl":[[0,2.08,174.05],[1,2.1,111.77],[2,2.36,299.17]],"ltp":1.8,"tv":1920.5,"id":8908205},{"batb":[[0,1.98,15.58]],"ltp":2.26,"tv":545.76,"id":4596961}]}]}
{"op":"mcm","clk":"1004877068","pt":1580657319500,"mc":[{"id":"1.168224030","rc":[{"batb":[[0,1.59,30.37],[1,1.01,10.51],[2,1.59,0]],"batl":[[0,2.36,299.17],[1,2.1,0],[2,2.36,0]],"ltp":1.8,"tv":1920.5,"id":8908205}]}]}
{"op":"mcm","clk":"1004877707","pt":1580657323038,"mc":[{"id":"1.168224030","rc":[{"batb":[[0,1.94,15.58],[1,1.62,28.01],[2,1.59,30.37]],"ltp":1.8,"tv":1920.5,"id":8908205},{"batb":[[1,1.93,158.49],[2,1.91,145.59]],"batl":[[0,2.02,114.08],[1,2.04,121.54]],"ltp":2.26,"tv":545.76,"id":4596961}]}]}
{"op":"mcm","clk":"1004877865","pt":1580657323906,"mc":[{"id":"1.168224030","rc":[{"batb":[[1,1.88,47.05],[2,1.62,28.01]],"ltp":1.8,"tv":1920.5,"id":8908205},{"batl":[[2,2.14,36.13]],"ltp":2.26,"tv":545.76,"id":4596961}]}]}
{"op":"mcm","clk":"1004878013","pt":1580657324728,"mc":[{"id":"1.168224030","rc":[{"batl":[[0,2.6,257.57]],"ltp":1.8,"tv":1920.5,"id":8908205}]}]}
{"op":"mcm","clk":"1004879663","pt":1580657334320,"mc":[{"id":"1.168224030","rc":[{"trd":[[1.98,16.66]],"ltp":1.98,"tv":1937.15,"id":8908205},{"trd":[[2.02,16.33]],"batl":[[0,2.02,97.75]],"ltp":2.02,"tv":562.09,"id":4596961}],"tv":2499.25}]}
{"op":"mcm","clk":"1004881226","pt":1580657343041,"mc":[{"id":"1.168224030","rc":[{"batb":[[0,1.62,28.01],[1,1.01,10.51],[2,1.62,0]],"ltp":1.98,"tv":1937.15,"id":8908205},{"batb":[[0,1.56,33.75],[1,1.01,10.51],[2,1.91,0]],"batl":[[0,2.6,257.57],[1,2.04,0],[2,2.14,0]],"ltp":2.02,"tv":562.09,"id":4596961}]}]}
{"op":"mcm","clk":"1004881773","pt":1580657346022,"mc":[{"id":"1.168224030","rc":[{"batb":[[0,1.58,233.93],[1,1.57,177.17],[2,1.56,33.75]],"batl":[[0,2.4,114.1],[1,2.44,149],[2,2.6,257.57]],"ltp":2.02,"tv":562.09,"id":4596961}]}]}
{"op":"mcm","clk":"1004881944","pt":1580657346948,"mc":[{"id":"1.168224030","rc":[{"batb":[[2,1.01,10.51]],"ltp":2.02,"tv":562.09,"id":4596961}]}]}
{"op":"mcm","clk":"1004882628","pt":1580657351027,"mc":[{"id":"1.168224030","rc":[{"batl":[[0,2.6,257.57],[1,2.44,0],[2,2.6,0]],"ltp":2.02,"tv":562.09,"id":4596961}]}]}
{"op":"mcm","clk":"1004883140","pt":1580657354051,"mc":[{"id":"1.168224030","rc":[{"batl":[[0,1.64,148.07],[1,1.65,118.27]],"ltp":2.02,"tv":562.09,"id":4596961}]}]}
{"op":"mcm","clk":"1004883323","pt":1580657355084,"mc":[{"id":"1.168224030","rc":[{"batb":[[0,2.6,13.38],[1,1.94,15.42],[2,1.62,28.01]],"ltp":1.98,"tv":1937.15,"id":8908205},{"batb":[[2,1.24,99.45]],"ltp":2.02,"tv":562.09,"id":4596961}]}]}
{"op":"mcm","clk":"1004883467","pt":1580657355950,"mc":[{"id":"1.168224030","rc":[{"batb":[[1,2.32,31.09],[2,1.94,15.42]],"ltp":1.98,"tv":1937.15,"id":8908205},{"batl":[[2,1.76,42.01]],"ltp":2.02,"tv":562.09,"id":4596961}]}]}
{"op":"mcm","clk":"1004883654","pt":1580657356959,"mc":[{"id":"1.168224030","rc":[{"batb":[[1,1.94,15.42],[2,1.01,10.51]],"batl":[[0,3.65,170.41]],"ltp":1.98,"tv":1937.15,"id":8908205},{"batl":[[2,2.04,383.01]],"ltp":2.02,"tv":562.09,"id":4596961}]}]}
{"op":"mcm","clk":"1004884207","pt":1580657359987,"mc":[{"id":"1.168224030","rc":[{"batl":[[0,2.62,25.21],[1,3.65,170.41]],"ltp":1.98,"tv":1937.15,"id":8908205},{"batl":[[2,1.74,42.01]],"ltp":2.02,"tv":562.09,"id":4596961}]}]}
{"op":"mcm","clk":"1004884413","pt":1580657361087,"mc":[{"id":"1.168224030","rc":[{"batb":[[1,2.36,30.25],[2,1.94,15.42]],"ltp":1.98,"tv":1937.15,"id":8908205}]}]}
{"op":"mcm","clk":"1004887117","pt":1580657376072,"mc":[{"id":"1.168224030","rc":[{"batb":[[0,2.36,30.25],[1,1.94,15.42],[2,1.01,10.51]],"ltp":1.98,"tv":1937.15,"id":8908205},{"batb":[[0,1.24,99.45],[1,1.01,10.51],[2,1.24,0]],"batl":[[0,1.74,42.01],[1,2.04,383.01],[2,1.74,0]],"ltp":2.02,"tv":562.09,"id":4596961}]}]}
{"op":"mcm","clk":"1004887279","pt":1580657376999,"mc":[{"id":"1.168224030","rc":[{"batb":[[0,1.94,15.42],[1,1.01,10.51],[2,1.01,0]],"batl":[[0,3.65,170.41],[1,3.65,0]],"ltp":1.98,"tv":1937.15,"id":8908205},{"batl":[[0,2.04,383.01],[1,2.04,0]],"ltp":2.02,"tv":562.09,"id":4596961}]}]}
{"op":"mcm","clk":"1004887721","pt":1580657379075,"mc":[{"id":"1.168224030","rc":[{"batb":[[0,1.93,15.74]],"ltp":1.98,"tv":1937.15,"id":8908205},{"batb":[[0,1.27,174.35],[1,1.26,393.99],[2,1.24,97.09]],"batl":[[0,2.02,195.59],[1,2.04,121.52]],"ltp":2.02,"tv":562.09,"id":4596961}]}]}
{"op":"mcm","clk":"1004887861","pt":1580657379780,"mc":[{"id":"1.168224030","rc":[{"batb":[[0,1.24,97.09],[1,1.01,10.51],[2,1.24,0]],"ltp":2.02,"tv":562.09,"id":4596961}]}]}
{"op":"mcm","clk":"1004888449","pt":1580657382973,"mc":[{"id":"1.168224030","rc":[{"batb":[[0,1.51,164.8],[1,1.5,171.01],[2,1.24,97.09]],"batl":[[0,1.56,191.01],[1,1.57,141.12]],"ltp":2.02,"tv":562.09,"id":4596961}]}]}
{"op":"mcm","clk":"1004888906","pt":1580657384983,"mc":[{"id":"1.168224030","rc":[{"batl":[[0,3.9,158.24]],"ltp":1.98,"tv":1937.15,"id":8908205},{"batb":[[0,1.24,97.09],[1,1.01,10.51],[2,1.24,0]],"batl":[[0,1.95,409.86],[1,1.57,0]],"ltp":2.02,"tv":562.09,"id":4596961}]}]}
{"op":"mcm","clk":"1004889522","pt":1580657387985,"mc":[{"id":"1.168224030","rc":[{"batb":[[0,1.27,175.41],[1,1.26,394],[2,1.24,97.09]],"batl":[[0,2.02,194.92],[1,2.04,121.51]],"ltp":2.02,"tv":562.09,"id":4596961}]}]}
{"op":"mcm","clk":"1004890531","pt":1580657393096,"mc":[{"id":"1.168224030","rc":[{"batl":[[0,1.3,357.5],[1,1.31,304.41]],"ltp":2.02,"tv":562.09,"id":4596961}]}]}
{"op":"mcm","clk":"1004890696","pt":1580657393995,"mc":[{"id":"1.168224030","rc":[{"trd":[[4.5,16.76]],"batb":[[0,3.75,15.12],[1,2.58,13.61],[2,1.01,10.51]],"ltp":4.5,"tv":1953.91,"id":8908205},{"trd":[[1.29,58.46],[1.3,162.02]],"batl":[[0,1.3,276.49],[2,1.36,42.01]],"ltp":1.3,"tv":782.57,"id":4596961}],"tv":2736.49}]}
{"op":"mcm","clk":"1004890760","pt":1580657394324,"mc":[{"id":"1.168224030","rc":[{"batb":[[0,2.58,13.61],[1,1.01,10.51],[2,1.01,0]],"batl":[[0,6.6,98.95]],"ltp":4.5,"tv":1953.91,"id":8908205},{"batl":[[2,1.62,614.4]],"ltp":1.3,"tv":782.57,"id":4596961}]}]}
{"op":"mcm","clk":"1004891108","pt":1580657396101,"mc":[{"id":"1.168224030","rc":[{"batb":[[0,3.85,14.28],[1,2.58,13.61],[2,1.01,10.51]],"batl":[[0,4.5,11.76],[1,6.6,98.95]],"ltp":4.5,"tv":1953.91,"id":8908205},{"batb":[[0,1.29,144.51],[1,1.27,175.41],[2,1.26,394]],"batl":[[2,1.35,42.01]],"ltp":1.3,"tv":782.57,"id":4596961}]}]}
{"op":"mcm","clk":"1004891167","pt":1580657396381,"mc":[{"id":"1.168224030","rc":[{"batl":[[0,6.6,98.95],[1,6.6,0]],"ltp":4.5,"tv":1953.91,"id":8908205},{"batb":[[0,1.27,175.41],[1,1.26,394],[2,1.24,97.09]],"batl":[[2,1.62,614.4]],"ltp":1.3,"tv":782.57,"id":4596961}]}]}
{"op":"mcm","clk":"1004891418","pt":1580657397703,"mc":[{"id":"1.168224030","rc":[{"batl":[[0,4.5,11.76],[1,6.6,98.95]],"ltp":4.5,"tv":1953.91,"id":8908205},{"batb":[[0,1.28,149.55],[1,1.27,205.8],[2,1.26,394]],"batl":[[0,1.3,327.82],[2,1.35,42.01]],"ltp":1.3,"tv":782.57,"id":4596961}]}]}
{"op":"mcm","clk":"1004894374","pt":1580657412025,"mc":[{"id":"1.168224030","rc":[{"batb":[[1,1.01,10.51],[2,1.26,0]],"batl":[[0,1.35,42.01],[1,1.62,614.4],[2,1.35,0]],"ltp":1.3,"tv":782.57,"id":4596961}]}]}
{"op":"mcm","clk":"1004894586","pt":1580657413116,"mc":[{"id":"1.168224030","rc":[{"batb":[[0,2.58,13.61],[1,1.01,10.51],[2,1.01,0]],"batl":[[0,6.6,98.95],[1,6.6,0]],"ltp":4.5,"tv":1953.91,"id":8908205},{"batb":[[0,1.01,10.51],[1,1.01,0]],"batl":[[0,1.62,614.4],[1,1.62,0]],"ltp":1.3,"tv":782.57,"id":4596961}]}]}
{"op":"mcm","clk":"1004894975","pt":1580657415000,"mc":[{"id":"1.168224030","rc":[{"batb":[[1,2.5,14.79],[2,1.01,10.51]],"ltp":4.5,"tv":1953.91,"id":8908205}]}]}
{"op":"mcm","clk":"1004895006","pt":1580657415219,"mc":[{"id":"1.168224030","rc":[{"batb":[[0,2.5,14.79],[1,1.01,10.51],[2,1.01,0]],"ltp":4.5,"tv":1953.91,"id":8908205}]}]}
{"op":"mcm","clk":"1004895363","pt":1580657417118,"mc":[{"id":"1.168224030","rc":[{"batb":[[0,1.2,483.52],[1,1.19,581.26],[2,1.01,10.51]],"batl":[[0,1.23,444.13],[1,1.24,410.04]],"ltp":1.3,"tv":782.57,"id":4596961}]}]}
{"op":"mcm","clk":"1004895750","pt":1580657419221,"mc":[{"id":"1.168224030","rc":[{"batl":[[0,8.6,81.89]],"ltp":4.5,"tv":1953.91,"id":8908205},{"batl":[[2,1.53,714.1]],"ltp":1.3,"tv":782.57,"id":4596961}]}]}
{"op":"mcm","clk":"1004896089","pt":1580657421047,"mc":[{"id":"1.168224030","rc":[{"batb":[[0,1.01,10.51],[1,1.19,0],[2,1.01,0]],"batl":[[0,1.53,714.1],[1,1.24,0],[2,1.53,0]],"ltp":1.3,"tv":782.57,"id":4596961}]}]}
{"op":"mcm","clk":"1004896614","pt":1580657423977,"mc":[{"id":"1.168224030","rc":[{"batl":[[0,1.64,214.72],[1,1.65,117.79]],"ltp":1.3,"tv":782.57,"id":4596961}]}]}
{"op":"mcm","clk":"1004900188","pt":1580657442112,"mc":[{"id":"1.168224030","marketDefinition":{"bspMarket":false,"turnInPlayEnabled":true,"persistenceEnabled":true,"marketBaseRate":5.0,"eventId":"29681672","eventTypeId":"2","numberOfWinners":1,"bettingType":"ODDS","marketType":"SET_WINNER","marketTime":"2020-02-02T14:00:00.000Z","suspendTime":"2020-02-02T14:00:00.000Z","bspReconciled":false,"complete":true,"inPlay":true,"crossMatching":true,"runnersVoidable":false,"numberOfActiveRunners":2,"betDelay":3,"status":"SUSPENDED","runners":[{"status":"ACTIVE","sortPriority":1,"id":8908205,"name":"Juan Pablo Ficovich"},{"status":"ACTIVE","sortPriority":2,"id":4596961,"name":"Filip Horansky"}],"regulators":["MR_INT"],"countryCode":"AR","discountAllowed":true,"timezone":"UTC","openDate":"2020-02-02T14:00:00.000Z","version":3149504594,"name":"Set 2 Winner","eventName":"Ficovich v Horansky"},"rc":[{"batb":[[0,1.01,10.51],[1,1.01,0]],"ltp":4.5,"tv":1953.91,"id":8908205}]}]}
{"op":"mcm","clk":"1004906579","pt":1580657475007,"mc":[{"id":"1.168224030","tv":0.0}]}
{"op":"mcm","clk":"1004906994","pt":1580657477106,"mc":[{"id":"1.168224030","marketDefinition":{"bspMarket":false,"turnInPlayEnabled":true,"persistenceEnabled":true,"marketBaseRate":5.0,"eventId":"29681672","eventTypeId":"2","numberOfWinners":1,"bettingType":"ODDS","marketType":"SET_WINNER","marketTime":"2020-02-02T14:00:00.000Z","suspendTime":"2020-02-02T14:00:00.000Z","bspReconciled":false,"complete":true,"inPlay":true,"crossMatching":false,"runnersVoidable":false,"numberOfActiveRunners":0,"betDelay":3,"status":"CLOSED","settledTime":"2020-02-02T15:31:13.000Z","runners":[{"status":"LOSER","sortPriority":1,"id":8908205,"name":"Juan Pablo Ficovich"},{"status":"WINNER","sortPriority":2,"id":4596961,"name":"Filip Horansky"}],"regulators":["MR_INT"],"countryCode":"AR","discountAllowed":true,"timezone":"UTC","openDate":"2020-02-02T14:00:00.000Z","version":3149507582,"name":"Set 2 Winner","eventName":"Ficovich v Horansky"}}]}
