{"op":"mcm","clk":"1004097111","pt":1580580427532,"mc":[{"id":"1.168222851","marketDefinition":{"bspMarket":false,"turnInPlayEnabled":true,"persistenceEnabled":true,"marketBaseRate":5.0,"eventId":"29681551","eventTypeId":"2","numberOfWinners":1,"bettingType":"ODDS","marketType":"SET_WINNER","marketTime":"2020-02-02T13:00:00.000Z","suspendTime":"2020-02-02T13:00:00.000Z","bspReconciled":false,"complete":true,"inPlay":false,"crossMatching":false,"runnersVoidable":false,"numberOfActiveRunners":2,"betDelay":0,"status":"OPEN","runners":[{"status":"ACTIVE","sortPriority":1,"id":11772759,"name":"Juan Pablo Varillas"},{"status":"ACTIVE","sortPriority":2,"id":9631075,"name":"Carlos Taberner"}],"regulators":["MR_INT"],"countryCode":"AR","discountAllowed":false,"timezone":"UTC","openDate":"2020-02-02T13:00:00.000Z","version":3146764517,"name":"Set 2 Winner","eventName":"Jua Varillas v Taberner"},"rc":[{"batb":[[0,1.01,20]],"ltp":0.0,"tv":0.0,"id":9631075},{"batb":[[0,1.01,20]],"ltp":0.0,"tv":0.0,"id":11772759}]}]}
{"op":"mcm","clk":"1004097346","pt":1580580428747,"mc":[{"id":"1.168222851","marketDefinition":{"bspMarket":false,"turnInPlayEnabled":true,"persistenceEnabled":true,"marketBaseRate":5.0,"eventId":"29681551","eventTypeId":"2","numberOfWinners":1,"bettingType":"ODDS","marketType":"SET_WINNER","marketTime":"2020-02-02T13:00:00.000Z","suspendTime":"2020-02-02T13:00:00.000Z","bspReconciled":false,"complete":true,"inPlay":false,"crossMatching":false,"runnersVoidable":false,"numberOfActiveRunners":2,"betDelay":0,"status":"OPEN","runners":[{"status":"ACTIVE","sortPriority":1,"id":11772759,"name":"Juan Pablo Varillas"},{"status":"ACTIVE","sortPriority":2,"id":9631075,"name":"Carlos Taberner"}],"regulators":["MR_INT"],"countryCode":"AR","discountAllowed":false,"timezone":"UTC","openDate":"2020-02-02T13:00:00.000Z","version":3146764517,"name":"Set 2 Winner","eventName":"Jua Varillas v Taberner"}}]}
{"op":"mcm","clk":"1004097530","pt":1580580429751,"mc":[{"id":"1.168222851","marketDefinition":{"bspMarket":false,"turnInPlayEnabled":true,"persistenceEnabled":true,"marketBaseRate":5.0,"eventId":"29681551","eventTypeId":"2","numberOfWinners":1,"bettingType":"ODDS","marketType":"SET_WINNER","marketTime":"2020-02-02T13:00:00.000Z","suspendTime":"2020-02-02T13:00:00.000Z","bspReconciled":false,"complete":true,"inPlay":false,"crossMatching":false,"runnersVoidable":false,"numberOfActiveRunners":2,"betDelay":0,"status":"OPEN","runners":[{"status":"ACTIVE","sortPriority":1,"id":11772759,"name":"Juan Pablo Varillas"},{"status":"ACTIVE","sortPriority":2,"id":9631075,"name":"Carlos Taberner"}],"regulators":["MR_INT"],"countryCode":"AR","discountAllowed":true,"timezone":"UTC","openDate":"2020-02-02T13:00:00.000Z","version":3146764517,"name":"Set 2 Winner","eventName":"Jua Varillas v Taberner"}}]}
{"op":"mcm","clk":"1004187401","pt":1580580913086,"mc":[{"id":"1.168222851","rc":[{"batb":[[0,1.01,10]],"ltp":0.0,"tv":0.0,"id":9631075},{"batb":[[0,1.01,10]],"ltp":0.0,"tv":0.0,"id":11772759}]}]}
{"op":"mcm","clk":"1005739150","pt":1580590302889,"mc":[{"id":"1.168222851","marketDefinition":{"bspMarket":false,"turnInPlayEnabled":true,"persistenceEnabled":true,"marketBaseRate":5.0,"eventId":"29681551","eventTypeId":"2","numberOfWinners":1,"bettingType":"ODDS","marketType":"SET_WINNER","marketTime":"2020-02-02T14:00:00.000Z","suspendTime":"2020-02-02T14:00:00.000Z","bspReconciled":false,"complete":true,"inPlay":false,"crossMatching":false,"runnersVoidable":false,"numberOfActiveRunners":2,"betDelay":0,"status":"OPEN","runners":[{"status":"ACTIVE","sortPriority":1,"id":11772759,"name":"Juan Pablo Varillas"},{"status":"ACTIVE","sortPriority":2,"id":9631075,"name":"Carlos Taberner"}],"regulators":["MR_INT"],"countryCode":"AR","discountAllowed":true,"timezone":"UTC","openDate":"2020-02-02T13:00:00.000Z","version":3147422165,"name":"Set 2 Winner","eventName":"Jua Varillas v Taberner"}}]}
{"op":"mcm","clk":"1005739706","pt":1580590307869,"mc":[{"id":"1.168222851","marketDefinition":{"bspMarket":false,"turnInPlayEnabled":true,"persistenceEnabled":true,"marketBaseRate":5.0,"eventId":"29681551","eventTypeId":"2","numberOfWinners":1,"bettingType":"ODDS","marketType":"SET_WINNER","marketTime":"2020-02-02T14:00:00.000Z","suspendTime":"2020-02-02T14:00:00.000Z","bspReconciled":false,"complete":true,"inPlay":false,"crossMatching":false,"runnersVoidable":false,"numberOfActiveRunners":2,"betDelay":0,"status":"OPEN","runners":[{"status":"ACTIVE","sortPriority":1,"id":11772759,"name":"Juan Pablo Varillas"},{"status":"ACTIVE","sortPriority":2,"id":9631075,"name":"Carlos Taberner"}],"regulators":["MR_INT"],"countryCode":"AR","discountAllowed":true,"timezone":"UTC","openDate":"2020-02-02T14:00:00.000Z","version":3147422165,"name":"Set 2 Winner","eventName":"Jua Varillas v Taberner"}}]}
{"op":"mcm","clk":"1006972855","pt":1580602758598,"mc":[{"id":"1.168222851","rc":[{"batb":[[0,1.01,12.53]],"ltp":0.0,"tv":0.0,"id":9631075},{"batb":[[0,1.01,12.53]],"ltp":0.0,"tv":0.0,"id":11772759}]}]}
{"op":"mcm","clk":"1006972947","pt":1580602759693,"mc":[{"id":"1.168222851","rc":[{"batb":[[0,1.01,10.51]],"ltp":0.0,"tv":0.0,"id":9631075},{"batb":[[0,1.01,10.51]],"ltp":0.0,"tv":0.0,"id":11772759}]}]}
{"op":"mcm","clk":"1007029663","pt":1580603522651,"mc":[{"id":"1.168222851","rc":[{"batb":[[0,1.01,13.04]],"ltp":0.0,"tv":0.0,"id":9631075},{"batb":[[0,1.01,13.04]],"ltp":0.0,"tv":0.0,"id":11772759}]}]}
{"op":"mcm","clk":"1007029730","pt":1580603523579,"mc":[{"id":"1.168222851","rc":[{"batb":[[0,1.01,11.01]],"ltp":0.0,"tv":0.0,"id":9631075},{"batb":[[0,1.01,11.01]],"ltp":0.0,"tv":0.0,"id":11772759}]}]}
{"op":"mcm","clk":"1010494854","pt":1580651596686,"mc":[{"id":"1.168222851","rc":[{"batb":[[0,1.87,17.23],[1,1.01,11.01]],"ltp":0.0,"tv":0.0,"id":9631075},{"batb":[[0,2,28.09],[1,1.01,11.01]],"ltp":0.0,"tv":0.0,"id":11772759}]}]}
{"op":"mcm","clk":"1010524387","pt":1580651803462,"mc":[{"id":"1.168222851","marketDefinition":{"bspMarket":false,"turnInPlayEnabled":true,"persistenceEnabled":true,"marketBaseRate":5.0,"eventId":"29681551","eventTypeId":"2","numberOfWinners":1,"bettingType":"ODDS","marketType":"SET_WINNER","marketTime":"2020-02-02T13:52:00.000Z","suspendTime":"2020-02-02T13:52:00.000Z","bspReconciled":false,"complete":true,"inPlay":false,"crossMatching":false,"runnersVoidable":false,"numberOfActiveRunners":2,"betDelay":0,"status":"OPEN","runners":[{"status":"ACTIVE","sortPriority":1,"id":11772759,"name":"Juan Pablo Varillas"},{"status":"ACTIVE","sortPriority":2,"id":9631075,"name":"Carlos Taberner"}],"regulators":["MR_INT"],"countryCode":"AR","discountAllowed":true,"timezone":"UTC","openDate":"2020-02-02T14:00:00.000Z","version":3149006719,"name":"Set 2 Winner","eventName":"Jua Varillas v Taberner"}}]}
{"op":"mcm","clk":"1010524886","pt":1580651806463,"mc":[{"id":"1.168222851","marketDefinition":{"bspMarket":false,"turnInPlayEnabled":true,"persistenceEnabled":true,"marketBaseRate":5.0,"eventId":"29681551","eventTypeId":"2","numberOfWinners":1,"bettingType":"ODDS","marketType":"SET_WINNER","marketTime":"2020-02-02T13:52:00.000Z","suspendTime":"2020-02-02T13:52:00.000Z","bspReconciled":false,"complete":true,"inPlay":false,"crossMatching":false,"runnersVoidable":false,"numberOfActiveRunners":2,"betDelay":0,"status":"OPEN","runners":[{"status":"ACTIVE","sortPriority":1,"id":11772759,"name":"Juan Pablo Varillas"},{"status":"ACTIVE","sortPriority":2,"id":9631075,"name":"Carlos Taberner"}],"regulators":["MR_INT"],"countryCode":"AR","discountAllowed":true,"timezone":"UTC","openDate":"2020-02-02T13:52:00.000Z","version":3149006719,"name":"Set 2 Winner","eventName":"Jua Varillas v Taberner"}}]}
{"op":"mcm","clk":"1010566847","pt":1580652062316,"mc":[{"id":"1.168222851","rc":[{"batb":[[0,1.86,17.62]],"ltp":0.0,"tv":0.0,"id":9631075},{"batb":[[0,2.02,27.46]],"ltp":0.0,"tv":0.0,"id":11772759}]}]}
{"op":"mcm","clk":"1010570994","pt":1580652085756,"mc":[{"id":"1.168222851","rc":[{"batb":[[1,1.85,48.73],[2,1.01,11.01]],"batl":[[0,2.04,40.33]],"ltp":0.0,"tv":0.0,"id":9631075},{"batb":[[1,1.97,42.85],[2,1.01,11.01]],"batl":[[0,2.18,35.29]],"ltp":0.0,"tv":0.0,"id":11772759}]}]}
{"op":"mcm","clk":"1010574665","pt":1580652105712,"mc":[{"id":"1.168222851","marketDefinition":{"bspMarket":false,"turnInPlayEnabled":true,"persistenceEnabled":true,"marketBaseRate":5.0,"eventId":"29681551","eventTypeId":"2","numberOfWinners":1,"bettingType":"ODDS","marketType":"SET_WINNER","marketTime":"2020-02-02T13:52:00.000Z","suspendTime":"2020-02-02T13:52:00.000Z","bspReconciled":false,"complete":true,"inPlay":false,"crossMatching":true,"runnersVoidable":false,"numberOfActiveRunners":2,"betDelay":0,"status":"OPEN","runners":[{"status":"ACTIVE","sortPriority":1,"id":11772759,"name":"Juan Pablo Varillas"},{"status":"ACTIVE","sortPriority":2,"id":9631075,"name":"Carlos Taberner"}],"regulators":["MR_INT"],"countryCode":"AR","discountAllowed":true,"timezone":"UTC","openDate":"2020-02-02T13:52:00.000Z","version":3149006719,"name":"Set 2 Winner","eventName":"Jua Varillas v Taberner"}}]}
{"op":"mcm","clk":"1010581506","pt":1580652141652,"mc":[{"id":"1.168222851","rc":[{"batb":[[0,1.87,17.47],[1,1.86,17.62],[2,1.85,48.73]],"ltp":0.0,"tv":0.0,"id":9631075},{"batb":[[0,2,27.7]],"ltp":0.0,"tv":0.0,"id":11772759}]}]}
{"op":"mcm","clk":"1010584027","pt":1580652154623,"mc":[{"id":"1.168222851","rc":[{"batb":[[0,2.02,1.25],[1,2,27.7],[2,1.97,42.85]],"ltp":0.0,"tv":0.0,"id":11772759}]}]}
{"op":"mcm","clk":"1010584051","pt":1580652154767,"mc":[{"id":"1.168222851","rc":[{"batb":[[0,1.88,1.34],[1,1.87,17.47],[2,1.86,17.62]],"ltp":0.0,"tv":0.0,"id":9631075}]}]}
{"op":"mcm","clk":"1010593176","pt":1580652196412,"mc":[{"id":"1.168222851","rc":[{"batb":[[2,1.85,66.59]],"ltp":0.0,"tv":0.0,"id":9631075},{"batb":[[0,2.02,28.4]],"ltp":0.0,"tv":0.0,"id":11772759}]}]}
{"op":"mcm","clk":"1010595461","pt":1580652206524,"mc":[{"id":"1.168222851","rc":[{"batb":[[1,1.86,17.7]],"ltp":0.0,"tv":0.0,"id":9631075},{"batb":[[1,1.97,42.85],[2,1.01,11.01]],"ltp":0.0,"tv":0.0,"id":11772759}]}]}
{"op":"mcm","clk":"1010597680","pt":1580652216682,"mc":[{"id":"1.168222851","rc":[{"batb":[[2,1.85,48.73]],"ltp":0.0,"tv":0.0,"id":9631075}]}]}
{"op":"mcm","clk":"1010616517","pt":1580652300397,"mc":[{"id":"1.168222851","rc":[{"batb":[[2,1.84,49.57]],"batl":[[0,2.02,41.17]],"ltp":0.0,"tv":0.0,"id":9631075},{"batl":[[0,2.2,34.45]],"ltp":0.0,"tv":0.0,"id":11772759}]}]}
{"op":"mcm","clk":"1010631641","pt":1580652368523,"mc":[{"id":"1.168222851","marketDefinition":{"bspMarket":false,"turnInPlayEnabled":true,"persistenceEnabled":true,"marketBaseRate":5.0,"eventId":"29681551","eventTypeId":"2","numberOfWinners":1,"bettingType":"ODDS","marketType":"SET_WINNER","marketTime":"2020-02-02T13:52:00.000Z","suspendTime":"2020-02-02T13:52:00.000Z","bspReconciled":false,"complete":true,"inPlay":true,"crossMatching":true,"runnersVoidable":false,"numberOfActiveRunners":2,"betDelay":3,"status":"OPEN","runners":[{"status":"ACTIVE","sortPriority":1,"id":11772759,"name":"Juan Pablo Varillas"},{"status":"ACTIVE","sortPriority":2,"id":9631075,"name":"Carlos Taberner"}],"regulators":["MR_INT"],"countryCode":"AR","discountAllowed":true,"timezone":"UTC","openDate":"2020-02-02T13:52:00.000Z","version":3149113290,"name":"Set 2 Winner","eventName":"Jua Varillas v Taberner"},"rc":[{"batb":[[0,1.01,10.51],[1,1.86,0],[2,1.84,0]],"ltp":0.0,"tv":0.0,"id":9631075},{"batb":[[0,1.01,10.51],[1,1.97,0],[2,1.01,0]],"ltp":0.0,"tv":0.0,"id":11772759}]}]}
{"op":"mcm","clk":"1010635523","pt":1580652386668,"mc":[{"id":"1.168222851","rc":[{"batb":[[0,1.82,18.96],[1,1.79,19.91],[2,1.01,10.51]],"ltp":0.0,"tv":0.0,"id":9631075},{"batb":[[0,2.06,25.49],[1,2.02,27.46],[2,1.63,164.69]],"ltp":0.0,"tv":0.0,"id":11772759}]}]}
{"op":"mcm","clk":"1010635747","pt":1580652387751,"mc":[{"id":"1.168222851","rc":[{"batb":[[1,1.8,52.09],[2,1.79,19.91]],"batl":[[0,2,42.01]],"ltp":0.0,"tv":0.0,"id":9631075},{"batb":[[2,1.99,42.01]],"batl":[[0,2.24,33.61]],"ltp":0.0,"tv":0.0,"id":11772759}]}]}
{"op":"mcm","clk":"1010639649","pt":1580652404544,"mc":[{"id":"1.168222851","rc":[{"batb":[[0,1.79,19.91],[1,1.01,10.51],[2,1.79,0]],"ltp":0.0,"tv":0.0,"id":9631075},{"batb":[[0,2.02,27.46],[1,1.01,10.51],[2,1.99,0]],"ltp":0.0,"tv":0.0,"id":11772759}]}]}
{"op":"mcm","clk":"1010640487","pt":1580652407747,"mc":[{"id":"1.168222851","rc":[{"batb":[[0,1.8,19.43],[1,1.79,19.91],[2,1.01,10.51]],"ltp":0.0,"tv":0.0,"id":9631075},{"batb":[[1,2,28.17],[2,1.01,10.51]],"ltp":0.0,"tv":0.0,"id":11772759}]}]}
{"op":"mcm","clk":"1010640578","pt":1580652408072,"mc":[{"id":"1.168222851","rc":[{"batb":[[1,1.01,10.51],[2,1.01,0]],"ltp":0.0,"tv":0.0,"id":9631075},{"batb":[[0,2,28.17],[1,1.01,10.51],[2,1.01,0]],"ltp":0.0,"tv":0.0,"id":11772759}]}]}
{"op":"mcm","clk":"1010646657","pt":1580652434508,"mc":[{"id":"1.168222851","rc":[{"batb":[[1,1.78,20.22],[2,1.01,10.51]],"ltp":0.0,"tv":0.0,"id":9631075},{"batb":[[0,2.08,24.78],[1,2.04,26.67],[2,1.01,10.51]],"ltp":0.0,"tv":0.0,"id":11772759}]}]}
{"op":"mcm","clk":"1010646953","pt":1580652435741,"mc":[{"id":"1.168222851","rc":[{"batb":[[1,1.79,52.93],[2,1.78,20.22]],"ltp":0.0,"tv":0.0,"id":9631075},{"batb":[[2,2.02,41.17]],"batl":[[0,2.26,32.77]],"ltp":0.0,"tv":0.0,"id":11772759}]}]}
{"op":"mcm","clk":"1010647216","pt":1580652436615,"mc":[{"id":"1.168222851","rc":[{"batl":[[0,1.98,42.01]],"ltp":0.0,"tv":0.0,"id":9631075}]}]}
{"op":"mcm","clk":"1010651262","pt":1580652453422,"mc":[{"id":"1.168222851","rc":[{"batb":[[0,1.79,52.93],[1,1.78,20.22],[2,1.01,10.51]],"ltp":0.0,"tv":0.0,"id":9631075},{"batb":[[0,2.04,26.67],[1,2.02,41.17],[2,1.01,10.51]],"ltp":0.0,"tv":0.0,"id":11772759}]}]}
{"op":"mcm","clk":"1010651587","pt":1580652454414,"mc":[{"id":"1.168222851","rc":[{"batb":[[0,1.78,20.22],[1,1.01,10.51],[2,1.01,0]],"ltp":0.0,"tv":0.0,"id":9631075},{"batb":[[1,1.01,10.51],[2,1.01,0]],"ltp":0.0,"tv":0.0,"id":11772759}]}]}
{"op":"mcm","clk":"1010652095","pt":1580652456555,"mc":[{"id":"1.168222851","rc":[{"batb":[[0,1.79,19.99]],"ltp":0.0,"tv":0.0,"id":9631075},{"batb":[[0,2.02,26.99]],"ltp":0.0,"tv":0.0,"id":11772759}]}]}
{"op":"mcm","clk":"1010655843","pt":1580652473477,"mc":[{"id":"1.168222851","rc":[{"batb":[[0,1.83,50.41],[1,1.79,19.99],[2,1.01,10.51]],"batl":[[0,2.02,41.17]],"ltp":0.0,"tv":0.0,"id":9631075},{"batb":[[1,1.99,42.01],[2,1.01,10.51]],"batl":[[0,2.22,33.61]],"ltp":0.0,"tv":0.0,"id":11772759}]}]}
{"op":"mcm","clk":"1010656099","pt":1580652474572,"mc":[{"id":"1.168222851","rc":[{"batb":[[0,1.85,17.94],[1,1.83,50.41],[2,1.82,19.04]],"ltp":0.0,"tv":0.0,"id":9631075},{"batb":[[2,1.98,29.19]],"ltp":0.0,"tv":0.0,"id":11772759}]}]}
{"op":"mcm","clk":"1010660227","pt":1580652490511,"mc":[{"id":"1.168222851","rc":[{"batb":[[0,1.82,19.04],[1,1.01,10.51],[2,1.82,0]],"ltp":0.0,"tv":0.0,"id":9631075},{"batb":[[0,1.98,29.19],[1,1.01,10.51],[2,1.98,0]],"ltp":0.0,"tv":0.0,"id":11772759}]}]}
{"op":"mcm","clk":"1010665286","pt":1580652511482,"mc":[{"id":"1.168222851","rc":[{"batb":[[1,1.81,51.25],[2,1.79,19.99]],"batl":[[0,2,42.01]],"ltp":0.0,"tv":0.0,"id":9631075},{"batb":[[0,2.06,25.34],[1,2.02,68.47],[2,1.01,10.51]],"batl":[[0,2.24,33.61]],"ltp":0.0,"tv":0.0,"id":11772759}]}]}
{"op":"mcm","clk":"1010670622","pt":1580652532745,"mc":[{"id":"1.168222851","rc":[{"batb":[[0,1.79,19.99],[1,1.01,10.51],[2,1.79,0]],"ltp":0.0,"tv":0.0,"id":9631075},{"batb":[[0,2.02,27.3],[1,1.01,10.51],[2,1.01,0]],"ltp":0.0,"tv":0.0,"id":11772759}]}]}
{"op":"mcm","clk":"1010672959","pt":1580652542690,"mc":[{"id":"1.168222851","rc":[{"batb":[[1,1.76,21.24],[2,1.01,10.51]],"ltp":0.0,"tv":0.0,"id":9631075},{"batb":[[0,2.1,24.23],[1,2.06,25.97],[2,2.02,27.3]],"ltp":0.0,"tv":0.0,"id":11772759}]}]}
{"op":"mcm","clk":"1010673128","pt":1580652543456,"mc":[{"id":"1.168222851","rc":[{"batb":[[1,1.77,53.77],[2,1.76,21.24]],"batl":[[0,1.96,42.01]],"ltp":0.0,"tv":0.0,"id":9631075},{"batb":[[1,2.06,65.45],[2,1.01,10.51]],"batl":[[0,2.3,31.93]],"ltp":0.0,"tv":0.0,"id":11772759}]}]}
{"op":"mcm","clk":"1010674888","pt":1580652551051,"mc":[{"id":"1.168222851","rc":[{"batb":[[0,1.8,19.67],[2,1.76,21.01]],"ltp":0.0,"tv":0.0,"id":9631075},{"batb":[[1,2.06,39.49],[2,2.04,26.36]],"ltp":0.0,"tv":0.0,"id":11772759}]}]}
{"op":"mcm","clk":"1010685737","pt":1580652599228,"mc":[{"id":"1.168222851","rc":[{"batb":[[0,1.77,53.77],[1,1.76,21.01],[2,1.01,10.51]],"ltp":0.0,"tv":0.0,"id":9631075},{"batb":[[0,2.06,39.49],[1,2.04,26.36],[2,1.01,10.51]],"ltp":0.0,"tv":0.0,"id":11772759}]}]}
{"op":"mcm","clk":"1010686043","pt":1580652600644,"mc":[{"id":"1.168222851","rc":[{"batb":[[0,1.76,21.01],[1,1.01,10.51],[2,1.01,0]],"ltp":0.0,"tv":0.0,"id":9631075},{"batb":[[0,2.04,26.36],[1,1.01,10.51],[2,1.01,0]],"ltp":0.0,"tv":0.0,"id":11772759}]}]}
{"op":"mcm","clk":"1010686533","pt":1580652602621,"mc":[{"id":"1.168222851","rc":[{"batb":[[0,1.77,20.54]],"ltp":0.0,"tv":0.0,"id":9631075},{"batb":[[0,2.02,26.91]],"ltp":0.0,"tv":0.0,"id":11772759}]}]}
{"op":"mcm","clk":"1010687179","pt":1580652605573,"mc":[{"id":"1.168222851","rc":[{"batb":[[0,1.8,52.09],[1,1.77,20.54],[2,1.01,10.51]],"batl":[[0,1.99,42.01],[1,2.52,270.1]],"ltp":0.0,"tv":0.0,"id":9631075},{"batb":[[0,2.02,68.08]],"batl":[[0,2.26,32.77],[1,2.7,245.56]],"ltp":0.0,"tv":0.0,"id":11772759}]}]}
{"op":"mcm","clk":"1010687369","pt":1580652606342,"mc":[{"id":"1.168222851","rc":[{"batb":[[0,1.85,18.02],[1,1.81,344.02],[2,1.8,52.09]],"ltp":0.0,"tv":0.0,"id":9631075},{"batb":[[1,2,28.4],[2,1.01,10.51]],"ltp":0.0,"tv":0.0,"id":11772759}]}]}
{"op":"mcm","clk":"1010690472","pt":1580652619752,"mc":[{"id":"1.168222851","rc":[{"batb":[[0,1.81,19.36],[1,1.8,52.09],[2,1.01,10.51]],"ltp":0.0,"tv":0.0,"id":9631075},{"batb":[[0,2.02,41.17]],"ltp":0.0,"tv":0.0,"id":11772759}]}]}
{"op":"mcm","clk":"1010690639","pt":1580652620574,"mc":[{"id":"1.168222851","rc":[{"batb":[[1,1.01,10.51],[2,1.01,0]],"batl":[[0,2.52,270.1],[1,2.52,0]],"ltp":0.0,"tv":0.0,"id":9631075},{"batb":[[0,2,28.4],[1,1.01,10.51],[2,1.01,0]],"batl":[[0,2.7,245.56],[1,2.7,0]],"ltp":0.0,"tv":0.0,"id":11772759}]}]}
{"op":"mcm","clk":"1010692179","pt":1580652627466,"mc":[{"id":"1.168222851","rc":[{"batb":[[0,1.88,17.07],[1,1.84,18.33],[2,1.82,50.41]],"batl":[[0,2,42.01],[1,2.52,270.1]],"ltp":0.0,"tv":0.0,"id":9631075},{"batb":[[0,2,70.41],[1,1.96,29.9],[2,1.01,10.51]],"batl":[[0,2.24,33.61],[1,2.7,245.56]],"ltp":0.0,"tv":0.0,"id":11772759}]}]}
{"op":"mcm","clk":"1010694317","pt":1580652636697,"mc":[{"id":"1.168222851","rc":[{"batb":[[0,1.84,18.33],[1,1.01,10.51],[2,1.82,0]],"batl":[[0,2.52,270.1],[1,2.52,0]],"ltp":0.0,"tv":0.0,"id":9631075},{"batb":[[0,1.96,29.9],[1,1.01,10.51],[2,1.01,0]],"batl":[[0,2.7,245.56],[1,2.7,0]],"ltp":0.0,"tv":0.0,"id":11772759}]}]}
{"op":"mcm","clk":"1010698508","pt":1580652655604,"mc":[{"id":"1.168222851","rc":[{"batb":[[1,1.8,19.75],[2,1.78,53.77]],"batl":[[0,1.97,42.01],[1,2.52,270.1]],"ltp":0.0,"tv":0.0,"id":9631075},{"batb":[[0,2.04,66.69],[1,2,27.85],[2,1.96,29.9]],"batl":[[0,2.3,31.93],[1,2.7,245.56]],"ltp":0.0,"tv":0.0,"id":11772759}]}]}
{"op":"mcm","clk":"1010698552","pt":1580652655813,"mc":[{"id":"1.168222851","rc":[{"batb":[[2,1.01,10.51]],"ltp":0.0,"tv":0.0,"id":11772759}]}]}
{"op":"mcm","clk":"1010701593","pt":1580652669749,"mc":[{"id":"1.168222851","rc":[{"batb":[[0,1.8,19.75],[1,1.78,53.77],[2,1.01,10.51]],"ltp":0.0,"tv":0.0,"id":9631075},{"batb":[[0,2.04,40.33]],"ltp":0.0,"tv":0.0,"id":11772759}]}]}
{"op":"mcm","clk":"1010701800","pt":1580652670754,"mc":[{"id":"1.168222851","rc":[{"batb":[[1,1.01,10.51],[2,1.01,0]],"batl":[[0,2.52,270.1],[1,2.52,0]],"ltp":0.0,"tv":0.0,"id":9631075},{"batb":[[0,2,27.85],[1,1.01,10.51],[2,1.01,0]],"batl":[[0,2.7,245.56],[1,2.7,0]],"ltp":0.0,"tv":0.0,"id":11772759}]}]}
{"op":"mcm","clk":"1010703386","pt":1580652677563,"mc":[{"id":"1.168222851","rc":[{"batb":[[1,1.75,76.93],[2,1.01,10.51]],"batl":[[0,1.92,42.01]],"ltp":0.0,"tv":0.0,"id":9631075},{"batb":[[0,2.1,24.47],[1,2.08,38.65],[2,2.04,26.28]],"batl":[[0,2.36,30.25],[1,2.7,245.56]],"ltp":0.0,"tv":0.0,"id":11772759}]}]}
{"op":"mcm","clk":"1010703996","pt":1580652680365,"mc":[{"id":"1.168222851","rc":[{"batl":[[1,2.4,289.78]],"ltp":0.0,"tv":0.0,"id":9631075}]}]}
{"op":"mcm","clk":"1010707644","pt":1580652697262,"mc":[{"id":"1.168222851","rc":[{"batb":[[0,1.75,76.93],[1,1.01,10.51],[2,1.01,0]],"ltp":0.0,"tv":0.0,"id":9631075},{"batb":[[0,2.08,38.65],[1,2.04,26.28],[2,1.01,10.51]],"ltp":0.0,"tv":0.0,"id":11772759}]}]}
{"op":"mcm","clk":"1010707937","pt":1580652698650,"mc":[{"id":"1.168222851","rc":[{"batb":[[0,1.75,21.48]],"batl":[[0,2.4,289.78],[1,2.4,0]],"ltp":0.0,"tv":0.0,"id":9631075},{"batb":[[0,2.04,26.28],[1,1.01,10.51],[2,1.01,0]],"batl":[[0,2.7,245.56],[1,2.7,0]],"ltp":0.0,"tv":0.0,"id":11772759}]}]}
{"op":"mcm","clk":"1010709051","pt":1580652703703,"mc":[{"id":"1.168222851","rc":[{"batb":[[0,1.77,53.77],[1,1.75,21.48],[2,1.01,10.51]],"batl":[[0,1.95,42.01],[1,2.4,289.78]],"ltp":0.0,"tv":0.0,"id":9631075},{"batb":[[0,2.06,39.49],[1,2.04,26.28],[2,1.01,10.51]],"batl":[[0,2.32,31.09],[1,2.7,245.56]],"ltp":0.0,"tv":0.0,"id":11772759}]}]}
{"op":"mcm","clk":"1010709259","pt":1580652704572,"mc":[{"id":"1.168222851","rc":[{"batb":[[0,1.84,18.41],[1,1.8,19.75],[2,1.77,53.77]],"ltp":0.0,"tv":0.0,"id":9631075},{"batb":[[2,2,27.85]],"ltp":0.0,"tv":0.0,"id":11772759}]}]}
{"op":"mcm","clk":"1010711918","pt":1580652716304,"mc":[{"id":"1.168222851","rc":[{"batl":[[0,2.7,245.56],[1,2.7,0]],"ltp":0.0,"tv":0.0,"id":11772759}]}]}
{"op":"mcm","clk":"1010712536","pt":1580652719207,"mc":[{"id":"1.168222851","rc":[{"batl":[[0,2.3,31.93],[1,2.7,245.56]],"ltp":0.0,"tv":0.0,"id":11772759}]}]}
{"op":"mcm","clk":"1010712814","pt":1580652720612,"mc":[{"id":"1.168222851","rc":[{"batb":[[0,1.8,19.75],[1,1.01,10.51],[2,1.77,0]],"batl":[[0,2.4,289.78],[1,2.4,0]],"ltp":0.0,"tv":0.0,"id":9631075},{"batb":[[0,2,27.85],[1,1.01,10.51],[2,2,0]],"batl":[[0,2.7,245.56],[1,2.7,0]],"ltp":0.0,"tv":0.0,"id":11772759}]}]}
{"op":"mcm","clk":"1010714983","pt":1580652730565,"mc":[{"id":"1.168222851","rc":[{"batb":[[0,1.87,17.39],[1,1.83,18.49],[2,1.01,10.51]],"ltp":0.0,"tv":0.0,"id":9631075},{"batb":[[1,1.96,30.14],[2,1.01,10.51]],"ltp":0.0,"tv":0.0,"id":11772759}]}]}
{"op":"mcm","clk":"1010715200","pt":1580652731531,"mc":[{"id":"1.168222851","rc":[{"batb":[[2,1.81,51.25]],"batl":[[0,2,42.01],[1,2.4,289.78]],"ltp":0.0,"tv":0.0,"id":9631075},{"batb":[[0,2,69.86]],"batl":[[0,2.24,33.61],[1,2.7,245.56]],"ltp":0.0,"tv":0.0,"id":11772759}]}]}
{"op":"mcm","clk":"1010721902","pt":1580652761541,"mc":[{"id":"1.168222851","rc":[{"batb":[[0,1.83,18.49],[1,1.81,51.25],[2,1.01,10.51]],"ltp":0.0,"tv":0.0,"id":9631075},{"batb":[[0,2,42.01],[1,1.96,29.82]],"ltp":0.0,"tv":0.0,"id":11772759}]}]}
{"op":"mcm","clk":"1010722166","pt":1580652762627,"mc":[{"id":"1.168222851","rc":[{"batb":[[1,1.01,10.51],[2,1.01,0]],"batl":[[0,2.4,289.78],[1,2.4,0]],"ltp":0.0,"tv":0.0,"id":9631075},{"batb":[[0,1.96,29.82],[1,1.01,10.51],[2,1.01,0]],"batl":[[0,2.7,245.56],[1,2.7,0]],"ltp":0.0,"tv":0.0,"id":11772759}]}]}
{"op":"mcm","clk":"1010723316","pt":1580652767741,"mc":[{"id":"1.168222851","rc":[{"batb":[[1,1.8,19.59],[2,1.79,52.93]],"batl":[[0,1.98,42.01],[1,2.4,289.78]],"ltp":0.0,"tv":0.0,"id":9631075},{"batb":[[0,2.06,25.89],[1,2.02,41.17],[2,2,28.4]],"batl":[[0,2.28,32.77],[1,2.7,245.56]],"ltp":0.0,"tv":0.0,"id":11772759}]}]}
{"op":"mcm","clk":"1010726871","pt":1580652783293,"mc":[{"id":"1.168222851","rc":[{"batb":[[0,1.8,19.59],[1,1.79,52.93],[2,1.01,10.51]],"ltp":0.0,"tv":0.0,"id":9631075},{"batb":[[0,2.02,41.17],[1,2,28.4],[2,1.01,10.51]],"ltp":0.0,"tv":0.0,"id":11772759}]}]}
{"op":"mcm","clk":"1010727157","pt":1580652784620,"mc":[{"id":"1.168222851","rc":[{"batb":[[1,1.01,10.51],[2,1.01,0]],"batl":[[0,2.4,289.78],[1,2.4,0]],"ltp":0.0,"tv":0.0,"id":9631075},{"batb":[[0,2,28.4],[1,1.01,10.51],[2,1.01,0]],"batl":[[0,2.7,245.56],[1,2.7,0]],"ltp":0.0,"tv":0.0,"id":11772759}]}]}
{"op":"mcm","clk":"1010731705","pt":1580652803626,"mc":[{"id":"1.168222851","rc":[{"batb":[[0,1.88,17.07],[1,1.84,332.9],[2,1.83,50.41]],"batl":[[0,2.02,41.17],[1,2.4,289.78]],"ltp":0.0,"tv":0.0,"id":9631075},{"batb":[[1,1.98,42.85],[2,1.95,30.76]],"batl":[[0,2.22,33.61],[1,2.7,245.56]],"ltp":0.0,"tv":0.0,"id":11772759}]}]}
{"op":"mcm","clk":"1010736945","pt":1580652825650,"mc":[{"id":"1.168222851","rc":[{"batb":[[0,1.84,18.18],[1,1.83,50.41],[2,1.01,10.51]],"ltp":0.0,"tv":0.0,"id":9631075},{"batb":[[0,1.98,42.85],[1,1.95,30.37],[2,1.01,10.51]],"ltp":0.0,"tv":0.0,"id":11772759}]}]}
{"op":"mcm","clk":"1010737191","pt":1580652826757,"mc":[{"id":"1.168222851","rc":[{"batb":[[1,1.01,10.51],[2,1.01,0]],"batl":[[0,2.4,289.78],[1,2.4,0]],"ltp":0.0,"tv":0.0,"id":9631075},{"batb":[[0,1.95,30.37],[1,1.01,10.51],[2,1.01,0]],"batl":[[0,2.7,245.56],[1,2.7,0]],"ltp":0.0,"tv":0.0,"id":11772759}]}]}
{"op":"mcm","clk":"1010739391","pt":1580652835607,"mc":[{"id":"1.168222851","rc":[{"batb":[[0,1.87,47.89],[1,1.84,18.18],[2,1.01,10.51]],"batl":[[0,2.06,39.49],[1,2.4,289.78]],"ltp":0.0,"tv":0.0,"id":9631075},{"batb":[[1,1.94,44.53],[2,1.01,10.51]],"batl":[[0,2.18,35.29],[1,2.7,245.56]],"ltp":0.0,"tv":0.0,"id":11772759}]}]}
{"op":"mcm","clk":"1010739658","pt":1580652836617,"mc":[{"id":"1.168222851","rc":[{"batb":[[0,1.92,15.97],[1,1.88,17.07],[2,1.87,47.89]],"ltp":0.0,"tv":0.0,"id":9631075},{"batb":[[2,1.9,16.52]],"batl":[[0,2.16,36.13]],"ltp":0.0,"tv":0.0,"id":11772759}]}]}
{"op":"mcm","clk":"1010744557","pt":1580652857456,"mc":[{"id":"1.168222851","rc":[{"batb":[[0,1.88,17.07],[1,1.87,47.89],[2,1.01,10.51]],"ltp":0.0,"tv":0.0,"id":9631075},{"batb":[[0,1.94,44.53],[1,1.9,16.52],[2,1.01,10.51]],"ltp":0.0,"tv":0.0,"id":11772759}]}]}
{"op":"mcm","clk":"1010744858","pt":1580652858732,"mc":[{"id":"1.168222851","rc":[{"batb":[[1,1.01,10.51],[2,1.01,0]],"batl":[[0,2.4,289.78],[1,2.4,0]],"ltp":0.0,"tv":0.0,"id":9631075},{"batb":[[0,1.9,16.52],[1,1.01,10.51],[2,1.01,0]],"batl":[[0,2.7,245.56],[1,2.7,0]],"ltp":0.0,"tv":0.0,"id":11772759}]}]}
{"op":"mcm","clk":"1010746673","pt":1580652865661,"mc":[{"id":"1.168222851","rc":[{"batb":[[1,1.84,18.25],[2,1.01,10.51]],"ltp":0.0,"tv":0.0,"id":9631075},{"batb":[[0,2,28.4],[1,1.94,15.5],[2,1.01,10.51]],"ltp":0.0,"tv":0.0,"id":11772759}]}]}
{"op":"mcm","clk":"1010746783","pt":1580652866151,"mc":[{"id":"1.168222851","rc":[{"batb":[[1,1.85,48.73],[2,1.84,18.25]],"batl":[[0,2.04,40.33],[1,2.4,289.78]],"ltp":0.0,"tv":0.0,"id":9631075},{"batb":[[1,1.96,43.69],[2,1.94,15.5]],"batl":[[0,2.2,34.45],[1,2.7,245.56]],"ltp":0.0,"tv":0.0,"id":11772759}]}]}
{"op":"mcm","clk":"1010750427","pt":1580652881685,"mc":[{"id":"1.168222851","rc":[{"batb":[[0,1.85,48.73],[1,1.84,18.25],[2,1.01,10.51]],"ltp":0.0,"tv":0.0,"id":9631075},{"batb":[[0,1.96,43.69],[1,1.94,15.5],[2,1.01,10.51]],"ltp":0.0,"tv":0.0,"id":11772759}]}]}
{"op":"mcm","clk":"1010750863","pt":1580652883597,"mc":[{"id":"1.168222851","rc":[{"batb":[[0,1.84,18.25],[1,1.01,10.51],[2,1.01,0]],"batl":[[0,2.4,289.78],[1,2.4,0]],"ltp":0.0,"tv":0.0,"id":9631075},{"batb":[[0,1.94,15.5],[1,1.01,10.51],[2,1.01,0]],"batl":[[0,2.7,245.56],[1,2.7,0]],"ltp":0.0,"tv":0.0,"id":11772759}]}]}
{"op":"mcm","clk":"1010754304","pt":1580652898701,"mc":[{"id":"1.168222851","rc":[{"batb":[[1,1.8,19.43],[2,1.01,10.51]],"ltp":0.0,"tv":0.0,"id":9631075},{"batb":[[0,2.04,26.52],[1,1.98,29.19],[2,1.94,15.5]],"ltp":0.0,"tv":0.0,"id":11772759}]}]}
{"op":"mcm","clk":"1010754528","pt":1580652899688,"mc":[{"id":"1.168222851","rc":[{"batb":[[1,1.83,50.41],[2,1.8,19.43]],"batl":[[0,2.02,41.17],[1,2.4,289.78]],"ltp":0.0,"tv":0.0,"id":9631075},{"batb":[[1,1.99,42.01],[2,1.98,29.19]],"batl":[[0,2.22,33.61],[1,2.7,245.56]],"ltp":0.0,"tv":0.0,"id":11772759}]}]}
{"op":"mcm","clk":"1010759395","pt":1580652920722,"mc":[{"id":"1.168222851","rc":[{"batb":[[0,1.8,19.43],[1,1.01,10.51],[2,1.8,0]],"batl":[[0,2.4,289.78],[1,2.4,0]],"ltp":0.0,"tv":0.0,"id":9631075},{"batb":[[0,1.98,29.19],[1,1.01,10.51],[2,1.98,0]],"batl":[[0,2.7,245.56],[1,2.7,0]],"ltp":0.0,"tv":0.0,"id":11772759}]}]}
{"op":"mcm","clk":"1010761258","pt":1580652928565,"mc":[{"id":"1.168222851","rc":[{"batb":[[1,1.79,52.93],[2,1.76,21.09]],"batl":[[0,1.98,42.01],[1,2.4,289.78]],"ltp":0.0,"tv":0.0,"id":9631075},{"batb":[[0,2.08,24.78],[1,2.04,66.77],[2,1.01,10.51]],"batl":[[0,2.28,32.77],[1,2.7,245.56]],"ltp":0.0,"tv":0.0,"id":11772759}]}]}
{"op":"mcm","clk":"1010763898","pt":1580652939971,"mc":[{"id":"1.168222851","rc":[{"batb":[[0,1.81,19.2],[2,1.77,20.77]],"ltp":0.0,"tv":0.0,"id":9631075},{"batb":[[1,2.04,40.33],[2,2.02,26.83]],"ltp":0.0,"tv":0.0,"id":11772759}]}]}
{"op":"mcm","clk":"1010769544","pt":1580652964271,"mc":[{"id":"1.168222851","rc":[{"batb":[[0,1.82,18.88],[2,1.78,20.46]],"ltp":0.0,"tv":0.0,"id":9631075},{"batb":[[0,2.06,25.57]],"ltp":0.0,"tv":0.0,"id":11772759}]}]}
{"op":"mcm","clk":"1010771717","pt":1580652973670,"mc":[{"id":"1.168222851","rc":[{"batb":[[0,1.83,18.65],[2,1.78,20.22]],"ltp":0.0,"tv":0.0,"id":9631075},{"batb":[[2,2,27.62]],"ltp":0.0,"tv":0.0,"id":11772759}]}]}
{"op":"mcm","clk":"1010774998","pt":1580652988506,"mc":[{"id":"1.168222851","rc":[{"batb":[[0,1.84,18.33],[1,1.79,72.84],[2,1.01,10.51]],"ltp":0.0,"tv":0.0,"id":9631075},{"batb":[[0,2.04,66.69],[1,2,27.62],[2,1.01,10.51]],"ltp":0.0,"tv":0.0,"id":11772759}]}]}
{"op":"mcm","clk":"1010779469","pt":1580653008264,"mc":[{"id":"1.168222851","rc":[{"batb":[[0,1.79,72.84],[1,1.01,10.51],[2,1.01,0]],"ltp":0.0,"tv":0.0,"id":9631075},{"batb":[[0,2.04,40.33]],"ltp":0.0,"tv":0.0,"id":11772759}]}]}
{"op":"mcm","clk":"1010779644","pt":1580653008933,"mc":[{"id":"1.168222851","rc":[{"batb":[[0,1.79,19.91]],"batl":[[0,2.4,289.78],[1,2.4,0]],"ltp":0.0,"tv":0.0,"id":9631075},{"batb":[[0,2,27.62],[1,1.01,10.51],[2,1.01,0]],"batl":[[0,2.7,245.56],[1,2.7,0]],"ltp":0.0,"tv":0.0,"id":11772759}]}]}
{"op":"mcm","clk":"1010781311","pt":1580653016640,"mc":[{"id":"1.168222851","rc":[{"batb":[[1,1.76,54.61],[2,1.75,21.64]],"ltp":0.0,"tv":0.0,"id":9631075},{"batb":[[0,2.1,24.23],[1,2.08,38.65],[2,2.06,25.73]],"batl":[[0,2.34,31.09],[1,2.7,245.56]],"ltp":0.0,"tv":0.0,"id":11772759}]}]}
{"op":"mcm","clk":"1010782001","pt":1580653019725,"mc":[{"id":"1.168222851","rc":[{"batl":[[0,1.93,42.01],[1,2.4,289.78]],"ltp":0.0,"tv":0.0,"id":9631075}]}]}
{"op":"mcm","clk":"1010783601","pt":1580653027148,"mc":[{"id":"1.168222851","rc":[{"batb":[[0,1.76,54.61],[1,1.75,21.64],[2,1.01,10.51]],"ltp":0.0,"tv":0.0,"id":9631075},{"batb":[[0,2.08,38.65],[1,2.06,25.73],[2,1.01,10.51]],"ltp":0.0,"tv":0.0,"id":11772759}]}]}
{"op":"mcm","clk":"1010784139","pt":1580653029448,"mc":[{"id":"1.168222851","rc":[{"batb":[[0,1.75,21.64],[1,1.01,10.51],[2,1.01,0]],"batl":[[0,2.4,289.78],[1,2.4,0]],"ltp":0.0,"tv":0.0,"id":9631075},{"batb":[[0,2.06,25.73],[1,1.01,10.51],[2,1.01,0]],"batl":[[0,2.7,245.56],[1,2.7,0]],"ltp":0.0,"tv":0.0,"id":11772759}]}]}
{"op":"mcm","clk":"1010790553","pt":1580653058759,"mc":[{"id":"1.168222851","rc":[{"batb":[[0,1.83,18.73],[1,1.78,20.3],[2,1.01,10.51]],"ltp":0.0,"tv":0.0,"id":9631075},{"batb":[[1,2,27.77],[2,1.01,10.51]],"ltp":0.0,"tv":0.0,"id":11772759}]}]}
{"op":"mcm","clk":"1010790797","pt":1580653059735,"mc":[{"id":"1.168222851","rc":[{"batb":[[1,1.78,74.07]],"batl":[[0,1.96,42.01],[1,2.4,289.78]],"ltp":0.0,"tv":0.0,"id":9631075},{"batb":[[0,2.06,65.22]],"batl":[[0,2.3,31.93],[1,2.7,245.56]],"ltp":0.0,"tv":0.0,"id":11772759}]}]}
{"op":"mcm","clk":"1010793890","pt":1580653074189,"mc":[{"id":"1.168222851","rc":[{"batb":[[0,1.78,74.07],[1,1.01,10.51],[2,1.01,0]],"ltp":0.0,"tv":0.0,"id":9631075},{"batb":[[0,2.06,39.49]],"ltp":0.0,"tv":0.0,"id":11772759}]}]}
{"op":"mcm","clk":"1010794029","pt":1580653074881,"mc":[{"id":"1.168222851","rc":[{"batb":[[0,1.78,20.3]],"batl":[[0,2.4,289.78],[1,2.4,0]],"ltp":0.0,"tv":0.0,"id":9631075},{"batb":[[0,2,27.77],[1,1.01,10.51],[2,1.01,0]],"batl":[[0,2.7,245.56],[1,2.7,0]],"ltp":0.0,"tv":0.0,"id":11772759}]}]}
{"op":"mcm","clk":"1010795538","pt":1580653081685,"mc":[{"id":"1.168222851","rc":[{"batb":[[0,1.87,17.47],[1,1.82,19.04],[2,1.01,10.51]],"ltp":0.0,"tv":0.0,"id":9631075},{"batb":[[1,1.97,29.43],[2,1.01,10.51]],"ltp":0.0,"tv":0.0,"id":11772759}]}]}
{"op":"mcm","clk":"1010795563","pt":1580653081796,"mc":[{"id":"1.168222851","rc":[{"batb":[[2,1.8,52.09]],"batl":[[0,1.98,42.01],[1,2.4,289.78]],"ltp":0.0,"tv":0.0,"id":9631075},{"batb":[[0,2.02,41.17],[1,2,27.77],[2,1.97,29.43]],"batl":[[0,2.28,32.77],[1,2.7,245.56]],"ltp":0.0,"tv":0.0,"id":11772759}]}]}
{"op":"mcm","clk":"1010798620","pt":1580653096156,"mc":[{"id":"1.168222851","rc":[{"batb":[[0,1.82,19.04],[1,1.8,52.09],[2,1.01,10.51]],"ltp":0.0,"tv":0.0,"id":9631075},{"batb":[[1,1.97,29.43],[2,1.01,10.51]],"ltp":0.0,"tv":0.0,"id":11772759}]}]}
{"op":"mcm","clk":"1010798860","pt":1580653097096,"mc":[{"id":"1.168222851","rc":[{"batb":[[1,1.01,10.51],[2,1.01,0]],"batl":[[0,2.4,289.78],[1,2.4,0]],"ltp":0.0,"tv":0.0,"id":9631075},{"batb":[[0,1.97,29.43],[1,1.01,10.51],[2,1.01,0]],"batl":[[0,2.7,245.56],[1,2.7,0]],"ltp":0.0,"tv":0.0,"id":11772759}]}]}
{"op":"mcm","clk":"1010801108","pt":1580653107747,"mc":[{"id":"1.168222851","rc":[{"batb":[[1,1.76,21.09],[2,1.01,10.51]],"ltp":0.0,"tv":0.0,"id":9631075},{"batb":[[0,2.06,25.41],[1,2.02,27.22],[2,1.01,10.51]],"ltp":0.0,"tv":0.0,"id":11772759}]}]}
{"op":"mcm","clk":"1010801264","pt":1580653108443,"mc":[{"id":"1.168222851","rc":[{"batb":[[1,1.76,75.7]],"batl":[[0,1.94,42.01],[1,2.4,289.78]],"ltp":0.0,"tv":0.0,"id":9631075},{"batb":[[0,2.08,38.65],[1,2.06,25.41],[2,2.02,27.22]],"batl":[[0,2.34,31.09],[1,2.7,245.56]],"ltp":0.0,"tv":0.0,"id":11772759}]}]}
{"op":"mcm","clk":"1010804331","pt":1580653124654,"mc":[{"id":"1.168222851","rc":[{"batb":[[0,1.76,75.7],[1,1.01,10.51],[2,1.01,0]],"ltp":0.0,"tv":0.0,"id":9631075},{"batb":[[1,2.02,27.22],[2,1.01,10.51]],"ltp":0.0,"tv":0.0,"id":11772759}]}]}
{"op":"mcm","clk":"1010804388","pt":1580653124878,"mc":[{"id":"1.168222851","rc":[{"batb":[[0,1.76,21.09]],"batl":[[0,2.4,289.78],[1,2.4,0]],"ltp":0.0,"tv":0.0,"id":9631075},{"batb":[[0,2.02,27.22],[1,1.01,10.51],[2,1.01,0]],"batl":[[0,2.7,245.56],[1,2.7,0]],"ltp":0.0,"tv":0.0,"id":11772759}]}]}
{"op":"mcm","clk":"1010809224","pt":1580653150579,"mc":[{"id":"1.168222851","rc":[{"batb":[[0,1.86,17.78],[1,1.8,19.51],[2,1.78,53.77]],"batl":[[0,1.96,42.01],[1,2.4,289.78]],"ltp":0.0,"tv":0.0,"id":9631075},{"batb":[[0,2.06,39.49],[1,2.02,27.22],[2,1.98,29.19]],"batl":[[0,2.3,31.93],[1,2.7,245.56]],"ltp":0.0,"tv":0.0,"id":11772759}]}]}
{"op":"mcm","clk":"1010813192","pt":1580653171657,"mc":[{"id":"1.168222851","rc":[{"batb":[[0,1.8,19.51],[1,1.78,53.77],[2,1.01,10.51]],"ltp":0.0,"tv":0.0,"id":9631075},{"batb":[[1,1.98,29.19],[2,1.01,10.51]],"ltp":0.0,"tv":0.0,"id":11772759}]}]}
{"op":"mcm","clk":"1010813457","pt":1580653173131,"mc":[{"id":"1.168222851","rc":[{"batb":[[1,1.01,10.51],[2,1.01,0]],"batl":[[0,2.4,289.78],[1,2.4,0]],"ltp":0.0,"tv":0.0,"id":9631075},{"batb":[[0,1.98,29.19],[1,1.01,10.51],[2,1.01,0]],"batl":[[0,2.7,245.56],[1,2.7,0]],"ltp":0.0,"tv":0.0,"id":11772759}]}]}
{"op":"mcm","clk":"1010813758","pt":1580653174640,"mc":[{"id":"1.168222851","rc":[{"batb":[[0,1.99,28.8],[1,1.98,29.19],[2,1.01,10.51]],"ltp":0.0,"tv":0.0,"id":11772759}]}]}
{"op":"mcm","clk":"1010820024","pt":1580653207256,"mc":[{"id":"1.168222851","rc":[{"batb":[[1,1.75,21.64],[2,1.01,10.51]],"ltp":0.0,"tv":0.0,"id":9631075},{"batb":[[0,2.1,24.39],[1,2.04,26.59]],"ltp":0.0,"tv":0.0,"id":11772759}]}]}
{"op":"mcm","clk":"1010820159","pt":1580653207846,"mc":[{"id":"1.168222851","rc":[{"batb":[[2,1.74,56.29]],"batl":[[0,1.92,42.01],[1,2.4,289.78]],"ltp":0.0,"tv":0.0,"id":9631075},{"batb":[[0,2.1,62.2]],"batl":[[0,2.36,30.25],[1,2.7,245.56]],"ltp":0.0,"tv":0.0,"id":11772759}]}]}
{"op":"mcm","clk":"1010824986","pt":1580653230019,"mc":[{"id":"1.168222851","rc":[{"batb":[[0,1.75,21.64],[1,1.74,56.29],[2,1.01,10.51]],"ltp":0.0,"tv":0.0,"id":9631075},{"batb":[[0,2.1,37.81]],"ltp":0.0,"tv":0.0,"id":11772759}]}]}
{"op":"mcm","clk":"1010825178","pt":1580653230912,"mc":[{"id":"1.168222851","rc":[{"batb":[[1,1.01,10.51],[2,1.01,0]],"batl":[[0,2.4,289.78],[1,2.4,0]],"ltp":0.0,"tv":0.0,"id":9631075},{"batb":[[0,2.04,26.59],[1,1.01,10.51],[2,1.01,0]],"batl":[[0,2.7,245.56],[1,2.7,0]],"ltp":0.0,"tv":0.0,"id":11772759}]}]}
{"op":"mcm","clk":"1010826577","pt":1580653237747,"mc":[{"id":"1.168222851","rc":[{"batb":[[0,1.84,18.25],[1,1.79,19.83],[2,1.75,21.64]],"ltp":0.0,"tv":0.0,"id":9631075},{"batb":[[1,2,28.17],[2,1.01,10.51]],"ltp":0.0,"tv":0.0,"id":11772759}]}]}
{"op":"mcm","clk":"1010826618","pt":1580653237931,"mc":[{"id":"1.168222851","rc":[{"batb":[[2,1.76,54.61]],"batl":[[0,1.94,42.01],[1,2.4,289.78]],"ltp":0.0,"tv":0.0,"id":9631075},{"batb":[[0,2.06,39.49],[1,2.04,26.59],[2,2,28.17]],"batl":[[0,2.32,31.09],[1,2.7,245.56]],"ltp":0.0,"tv":0.0,"id":11772759}]}]}
{"op":"mcm","clk":"1010829271","pt":1580653251139,"mc":[{"id":"1.168222851","rc":[{"batb":[[0,1.79,19.83],[1,1.76,54.61],[2,1.01,10.51]],"ltp":0.0,"tv":0.0,"id":9631075},{"batb":[[1,2,28.17],[2,1.01,10.51]],"ltp":0.0,"tv":0.0,"id":11772759}]}]}
{"op":"mcm","clk":"1010829694","pt":1580653252992,"mc":[{"id":"1.168222851","rc":[{"batb":[[1,1.01,10.51],[2,1.01,0]],"batl":[[0,2.4,289.78],[1,2.4,0]],"ltp":0.0,"tv":0.0,"id":9631075},{"batb":[[0,2,28.17],[1,1.01,10.51],[2,1.01,0]],"batl":[[0,2.7,245.56],[1,2.7,0]],"ltp":0.0,"tv":0.0,"id":11772759}]}]}
{"op":"mcm","clk":"1010831340","pt":1580653259583,"mc":[{"id":"1.168222851","rc":[{"batb":[[0,1.87,17.23],[1,1.84,18.25],[2,1.01,10.51]],"ltp":0.0,"tv":0.0,"id":9631075},{"batb":[[1,1.94,15.42],[2,1.01,10.51]],"ltp":0.0,"tv":0.0,"id":11772759}]}]}
{"op":"mcm","clk":"1010831526","pt":1580653260514,"mc":[{"id":"1.168222851","rc":[{"batb":[[2,1.8,52.09]],"batl":[[0,1.98,42.01],[1,2.4,289.78]],"ltp":0.0,"tv":0.0,"id":9631075},{"batb":[[0,2.02,41.17],[1,2,28.17],[2,1.94,15.42]],"batl":[[0,2.28,32.77],[1,2.7,245.56]],"ltp":0.0,"tv":0.0,"id":11772759}]}]}
{"op":"mcm","clk":"1010833678","pt":1580653270608,"mc":[{"id":"1.168222851","rc":[{"batl":[[0,2.7,245.56],[1,2.7,0]],"ltp":0.0,"tv":0.0,"id":11772759}]}]}
{"op":"mcm","clk":"1010834294","pt":1580653273611,"mc":[{"id":"1.168222851","rc":[{"batl":[[0,2.26,32.77],[1,2.7,245.56]],"ltp":0.0,"tv":0.0,"id":11772759}]}]}
{"op":"mcm","clk":"1010838820","pt":1580653294594,"mc":[{"id":"1.168222851","rc":[{"batb":[[0,1.84,18.25],[1,1.8,52.09],[2,1.01,10.51]],"ltp":0.0,"tv":0.0,"id":9631075},{"batb":[[1,1.94,15.42],[2,1.01,10.51]],"ltp":0.0,"tv":0.0,"id":11772759}]}]}
{"op":"mcm","clk":"1010839032","pt":1580653295652,"mc":[{"id":"1.168222851","rc":[{"batb":[[1,1.01,10.51],[2,1.01,0]],"batl":[[0,2.4,289.78],[1,2.4,0]],"ltp":0.0,"tv":0.0,"id":9631075},{"batb":[[0,1.94,15.42],[1,1.01,10.51],[2,1.01,0]],"batl":[[0,2.7,245.56],[1,2.7,0]],"ltp":0.0,"tv":0.0,"id":11772759}]}]}
{"op":"mcm","clk":"1010839460","pt":1580653297484,"mc":[{"id":"1.168222851","rc":[{"batb":[[0,1.95,30.53]],"ltp":0.0,"tv":0.0,"id":11772759}]}]}
{"op":"mcm","clk":"1010840477","pt":1580653302195,"mc":[{"id":"1.168222851","rc":[{"batb":[[1,1.8,19.59],[2,1.79,52.93]],"batl":[[0,1.97,42.01],[1,2.4,289.78]],"ltp":0.0,"tv":0.0,"id":9631075},{"batb":[[0,2.04,66.53],[1,1.99,28.8],[2,1.01,10.51]],"batl":[[0,2.3,31.93],[1,2.7,245.56]],"ltp":0.0,"tv":0.0,"id":11772759}]}]}
{"op":"mcm","clk":"1010843515","pt":1580653315670,"mc":[{"id":"1.168222851","rc":[{"batb":[[0,1.8,19.59],[1,1.79,52.93],[2,1.01,10.51]],"ltp":0.0,"tv":0.0,"id":9631075},{"batb":[[0,2.04,40.33],[1,1.99,28.48]],"ltp":0.0,"tv":0.0,"id":11772759}]}]}
{"op":"mcm","clk":"1010843825","pt":1580653317176,"mc":[{"id":"1.168222851","rc":[{"batb":[[1,1.01,10.51],[2,1.01,0]],"batl":[[0,2.4,289.78],[1,2.4,0]],"ltp":0.0,"tv":0.0,"id":9631075},{"batb":[[0,1.99,28.48],[1,1.01,10.51],[2,1.01,0]],"batl":[[0,2.7,245.56],[1,2.7,0]],"ltp":0.0,"tv":0.0,"id":11772759}]}]}
{"op":"mcm","clk":"1010847894","pt":1580653336608,"mc":[{"id":"1.168222851","rc":[{"batb":[[1,1.77,53.77],[2,1.76,21.01]],"batl":[[0,1.94,42.01],[1,2.4,289.78]],"ltp":0.0,"tv":0.0,"id":9631075},{"batb":[[0,2.1,24.31],[1,2.06,39.49],[2,2.04,26.44]],"batl":[[0,2.32,31.09],[1,2.7,245.56]],"ltp":0.0,"tv":0.0,"id":11772759}]}]}
{"op":"mcm","clk":"1010851253","pt":1580653353334,"mc":[{"id":"1.168222851","rc":[{"batb":[[0,1.76,21.01],[1,1.01,10.51],[2,1.76,0]],"batl":[[0,2.4,289.78],[1,2.4,0]],"ltp":0.0,"tv":0.0,"id":9631075},{"batb":[[0,2.04,26.44],[1,1.01,10.51],[2,2.04,0]],"batl":[[0,2.7,245.56],[1,2.7,0]],"ltp":0.0,"tv":0.0,"id":11772759}]}]}
{"op":"mcm","clk":"1010852985","pt":1580653362755,"mc":[{"id":"1.168222851","rc":[{"batb":[[1,1.75,55.45],[2,1.74,22.03]],"batl":[[0,1.92,42.01],[1,2.4,289.78]],"ltp":0.0,"tv":0.0,"id":9631075},{"batb":[[0,2.14,22.82],[1,2.08,63.67],[2,1.01,10.51]],"batl":[[0,2.36,30.25],[1,2.7,245.56]],"ltp":0.0,"tv":0.0,"id":11772759}]}]}
{"op":"mcm","clk":"1010855322","pt":1580653375293,"mc":[{"id":"1.168222851","rc":[{"batb":[[0,1.74,22.03],[1,1.01,10.51],[2,1.74,0]],"batl":[[0,2.4,289.78],[1,2.4,0]],"ltp":0.0,"tv":0.0,"id":9631075},{"batb":[[0,2.08,25.02],[1,1.01,10.51],[2,1.01,0]],"batl":[[0,2.7,245.56],[1,2.7,0]],"ltp":0.0,"tv":0.0,"id":11772759}]}]}
{"op":"mcm","clk":"1010857641","pt":1580653387396,"mc":[{"id":"1.168222851","rc":[{"batb":[[1,1.69,24.08],[2,1.01,10.51]],"ltp":0.0,"tv":0.0,"id":9631075},{"batb":[[0,2.18,21.79],[1,2.14,23.29],[2,1.01,10.51]],"ltp":0.0,"tv":0.0,"id":11772759}]}]}
{"op":"mcm","clk":"1010857899","pt":1580653388590,"mc":[{"id":"1.168222851","rc":[{"batb":[[1,1.72,57.97],[2,1.69,24.08]],"ltp":0.0,"tv":0.0,"id":9631075},{"batb":[[1,2.14,59.42]],"batl":[[0,2.42,29.41]],"ltp":0.0,"tv":0.0,"id":11772759}]}]}
{"op":"mcm","clk":"1010857959","pt":1580653388910,"mc":[{"id":"1.168222851","rc":[{"batl":[[0,2.3,309.75]],"ltp":0.0,"tv":0.0,"id":9631075},{"batl":[[1,3,213.45]],"ltp":0.0,"tv":0.0,"id":11772759}]}]}
{"op":"mcm","clk":"1010858296","pt":1580653390589,"mc":[{"id":"1.168222851","rc":[{"batl":[[0,1.88,42.01],[1,2.3,309.75]],"ltp":0.0,"tv":0.0,"id":9631075}]}]}
{"op":"mcm","clk":"1010859282","pt":1580653395440,"mc":[{"id":"1.168222851","rc":[{"batb":[[0,1.75,21.64],[2,1.7,23.76]],"ltp":0.0,"tv":0.0,"id":9631075},{"batb":[[0,2.16,22.19],[1,2.14,36.13],[2,2.12,23.6]],"ltp":0.0,"tv":0.0,"id":11772759}]}]}
{"op":"mcm","clk":"1010863531","pt":1580653416464,"mc":[{"id":"1.168222851","rc":[{"batb":[[0,1.75,21.4],[2,1.7,23.6]],"ltp":0.0,"tv":0.0,"id":9631075}]}]}
{"op":"mcm","clk":"1010876360","pt":1580653479364,"mc":[{"id":"1.168222851","rc":[{"batb":[[0,1.7,23.6],[1,1.01,10.51],[2,1.7,0]],"batl":[[0,2.3,309.75],[1,2.3,0]],"ltp":0.0,"tv":0.0,"id":9631075},{"batb":[[0,2.12,23.6],[1,1.01,10.51],[2,2.12,0]],"batl":[[0,3,213.45],[1,3,0]],"ltp":0.0,"tv":0.0,"id":11772759}]}]}
{"op":"mcm","clk":"1010883249","pt":1580653511598,"mc":[{"id":"1.168222851","rc":[{"batb":[[1,1.66,25.81],[2,1.01,10.51]],"ltp":0.0,"tv":0.0,"id":9631075},{"batb":[[0,2.24,20.14],[1,2.18,21.79],[2,2.12,281.79]],"ltp":0.0,"tv":0.0,"id":11772759}]}]}
{"op":"mcm","clk":"1010883467","pt":1580653512594,"mc":[{"id":"1.168222851","rc":[{"batb":[[1,1.68,61.33],[2,1.66,25.81]],"ltp":0.0,"tv":0.0,"id":9631075},{"batb":[[1,2.18,57.08],[2,1.01,10.51]],"batl":[[0,2.48,27.73],[1,3,213.45]],"ltp":0.0,"tv":0.0,"id":11772759}]}]}
{"op":"mcm","clk":"1010883937","pt":1580653514708,"mc":[{"id":"1.168222851","rc":[{"batl":[[0,1.84,42.01],[1,2.3,309.75]],"ltp":0.0,"tv":0.0,"id":9631075}]}]}
{"op":"mcm","clk":"1010887157","pt":1580653530684,"mc":[{"id":"1.168222851","rc":[{"batb":[[0,1.68,61.33],[1,1.66,25.81],[2,1.01,10.51]],"ltp":0.0,"tv":0.0,"id":9631075},{"batb":[[0,2.18,57.08],[1,1.01,10.51],[2,1.01,0]],"ltp":0.0,"tv":0.0,"id":11772759}]}]}
{"op":"mcm","clk":"1010887391","pt":1580653531739,"mc":[{"id":"1.168222851","rc":[{"batb":[[0,1.66,25.81],[1,1.01,10.51],[2,1.01,0]],"batl":[[0,2.3,309.75],[1,2.3,0]],"ltp":0.0,"tv":0.0,"id":9631075},{"batb":[[0,2.18,21.79]],"batl":[[0,3,213.45],[1,3,0]],"ltp":0.0,"tv":0.0,"id":11772759}]}]}
{"op":"mcm","clk":"1010887814","pt":1580653533652,"mc":[{"id":"1.168222851","rc":[{"batb":[[0,1.67,25.41],[1,1.66,25.81],[2,1.01,10.51]],"ltp":0.0,"tv":0.0,"id":9631075},{"batb":[[1,2.16,22.27],[2,1.01,10.51]],"ltp":0.0,"tv":0.0,"id":11772759}]}]}
{"op":"mcm","clk":"1010887945","pt":1580653534261,"mc":[{"id":"1.168222851","rc":[{"batb":[[1,1.01,10.51],[2,1.01,0]],"ltp":0.0,"tv":0.0,"id":9631075},{"batb":[[0,2.16,22.27],[1,1.01,10.51],[2,1.01,0]],"ltp":0.0,"tv":0.0,"id":11772759}]}]}
{"op":"mcm","clk":"1010890717","pt":1580653547739,"mc":[{"id":"1.168222851","rc":[{"batb":[[1,1.62,28.09],[2,1.01,10.51]],"ltp":0.0,"tv":0.0,"id":9631075},{"batb":[[0,2.3,18.57],[1,2.24,20.14],[2,1.01,10.51]],"ltp":0.0,"tv":0.0,"id":11772759}]}]}
{"op":"mcm","clk":"1010890829","pt":1580653548185,"mc":[{"id":"1.168222851","rc":[{"batb":[[1,1.66,63.01],[2,1.62,28.09]],"batl":[[0,1.81,42.01]],"ltp":0.0,"tv":0.0,"id":9631075},{"batb":[[1,2.24,53.75]],"batl":[[0,2.54,26.89],[1,3,213.45]],"ltp":0.0,"tv":0.0,"id":11772759}]}]}
{"op":"mcm","clk":"1010891070","pt":1580653549393,"mc":[{"id":"1.168222851","rc":[{"batl":[[1,2.16,342.82]],"ltp":0.0,"tv":0.0,"id":9631075}]}]}
{"op":"mcm","clk":"1010893275","pt":1580653560613,"mc":[{"id":"1.168222851","rc":[{"batb":[[0,1.66,63.01],[1,1.62,28.09],[2,1.01,10.51]],"ltp":0.0,"tv":0.0,"id":9631075},{"batb":[[0,2.24,53.75],[1,1.01,10.51],[2,1.01,0]],"ltp":0.0,"tv":0.0,"id":11772759}]}]}
{"op":"mcm","clk":"1010893467","pt":1580653561591,"mc":[{"id":"1.168222851","rc":[{"batb":[[0,1.62,28.09],[1,1.01,10.51],[2,1.01,0]],"batl":[[0,2.16,342.82],[1,2.16,0]],"ltp":0.0,"tv":0.0,"id":9631075},{"batb":[[0,2.24,20.14]],"batl":[[0,3,213.45],[1,3,0]],"ltp":0.0,"tv":0.0,"id":11772759}]}]}
{"op":"mcm","clk":"1010893902","pt":1580653563634,"mc":[{"id":"1.168222851","rc":[{"batb":[[0,1.63,27.77],[1,1.62,28.09],[2,1.01,10.51]],"ltp":0.0,"tv":0.0,"id":9631075}]}]}
{"op":"mcm","clk":"1010894154","pt":1580653564704,"mc":[{"id":"1.168222851","rc":[{"batb":[[1,1.01,10.51],[2,1.01,0]],"ltp":0.0,"tv":0.0,"id":9631075}]}]}
{"op":"mcm","clk":"1010899619","pt":1580653591563,"mc":[{"id":"1.168222851","rc":[{"batb":[[1,1.59,30.21],[2,1.01,10.51]],"ltp":0.0,"tv":0.0,"id":9631075},{"batb":[[0,2.4,16.76],[1,2.32,18.33],[2,1.01,10.51]],"ltp":0.0,"tv":0.0,"id":11772759}]}]}
{"op":"mcm","clk":"1010899795","pt":1580653592551,"mc":[{"id":"1.168222851","rc":[{"batb":[[0,1.63,94.15]],"batl":[[0,1.78,42.01],[1,2.16,342.82]],"ltp":0.0,"tv":0.0,"id":9631075},{"batb":[[2,2.3,31.93]],"batl":[[0,2.6,26.05]],"ltp":0.0,"tv":0.0,"id":11772759}]}]}
{"op":"mcm","clk":"1010900033","pt":1580653593758,"mc":[{"id":"1.168222851","rc":[{"batl":[[1,3.45,180.4]],"ltp":0.0,"tv":0.0,"id":11772759}]}]}
{"op":"mcm","clk":"1010904061","pt":1580653613706,"mc":[{"id":"1.168222851","rc":[{"batb":[[0,1.59,30.21],[1,1.01,10.51],[2,1.01,0]],"batl":[[0,2.16,342.82],[1,2.16,0]],"ltp":0.0,"tv":0.0,"id":9631075},{"batb":[[0,2.32,18.33],[1,1.01,10.51],[2,2.3,0]],"batl":[[0,3.45,180.4],[1,3.45,0]],"ltp":0.0,"tv":0.0,"id":11772759}]}]}
{"op":"mcm","clk":"1010904624","pt":1580653616570,"mc":[{"id":"1.168222851","rc":[{"batb":[[0,1.58,31.08]],"ltp":0.0,"tv":0.0,"id":9631075},{"batb":[[0,2.34,17.7]],"ltp":0.0,"tv":0.0,"id":11772759}]}]}
{"op":"mcm","clk":"1010906770","pt":1580653627346,"mc":[{"id":"1.168222851","rc":[{"batb":[[0,1.65,26.52],[1,1.6,29.19],[2,1.01,10.51]],"ltp":0.0,"tv":0.0,"id":9631075},{"batb":[[1,2.28,19.2],[2,1.01,10.51]],"ltp":0.0,"tv":0.0,"id":11772759}]}]}
{"op":"mcm","clk":"1010907034","pt":1580653628592,"mc":[{"id":"1.168222851","rc":[{"batl":[[0,1.78,42.01],[1,2.16,342.82]],"ltp":0.0,"tv":0.0,"id":9631075}]}]}
{"op":"mcm","clk":"1010907233","pt":1580653629578,"mc":[{"id":"1.168222851","rc":[{"batb":[[1,1.63,66.38],[2,1.6,29.19]],"ltp":0.0,"tv":0.0,"id":9631075},{"batb":[[1,2.28,51.97]],"batl":[[0,2.58,26.05],[1,3.3,191.92]],"ltp":0.0,"tv":0.0,"id":11772759}]}]}
{"op":"mcm","clk":"1010910832","pt":1580653647525,"mc":[{"id":"1.168222851","rc":[{"batb":[[0,1.6,29.19],[1,1.01,10.51],[2,1.6,0]],"batl":[[0,2.16,342.82],[1,2.16,0]],"ltp":0.0,"tv":0.0,"id":9631075},{"batb":[[0,2.28,19.2],[1,1.01,10.51],[2,1.01,0]],"batl":[[0,3.3,191.92],[1,3.3,0]],"ltp":0.0,"tv":0.0,"id":11772759}]}]}
{"op":"mcm","clk":"1010911458","pt":1580653650724,"mc":[{"id":"1.168222851","rc":[{"batb":[[0,1.59,29.9]],"ltp":0.0,"tv":0.0,"id":9631075},{"batb":[[0,2.3,18.65]],"ltp":0.0,"tv":0.0,"id":11772759}]}]}
{"op":"mcm","clk":"1010915549","pt":1580653671660,"mc":[{"id":"1.168222851","rc":[{"batb":[[0,1.67,25.26],[1,1.61,28.48],[2,1.6,420.79]],"ltp":0.0,"tv":0.0,"id":9631075},{"batb":[[1,2.22,20.54],[2,1.01,10.51]],"ltp":0.0,"tv":0.0,"id":11772759}]}]}
{"op":"mcm","clk":"1010915664","pt":1580653672244,"mc":[{"id":"1.168222851","rc":[{"batb":[[1,1.64,65.54],[2,1.61,28.48]],"batl":[[0,1.81,42.01],[1,2.16,342.82]],"ltp":0.0,"tv":0.0,"id":9631075},{"batb":[[1,2.26,32.77],[2,2.22,20.54]],"batl":[[0,2.56,26.89],[1,3.3,191.92]],"ltp":0.0,"tv":0.0,"id":11772759}]}]}
{"op":"mcm","clk":"1010916515","pt":1580653676684,"mc":[{"id":"1.168222851","rc":[{"batl":[[0,2.16,342.82],[1,2.16,0]],"ltp":0.0,"tv":0.0,"id":9631075}]}]}
{"op":"mcm","clk":"1010917041","pt":1580653679449,"mc":[{"id":"1.168222851","rc":[{"batl":[[0,1.8,42.01],[1,2.16,342.82]],"ltp":0.0,"tv":0.0,"id":9631075}]}]}
{"op":"mcm","clk":"1010919487","pt":1580653691382,"mc":[{"id":"1.168222851","rc":[{"batb":[[0,1.61,28.48],[1,1.01,10.51],[2,1.61,0]],"batl":[[0,2.16,342.82],[1,2.16,0]],"ltp":0.0,"tv":0.0,"id":9631075},{"batb":[[0,2.22,20.54],[1,1.01,10.51],[2,2.22,0]],"batl":[[0,3.3,191.92],[1,3.3,0]],"ltp":0.0,"tv":0.0,"id":11772759}]}]}
{"op":"mcm","clk":"1010920186","pt":1580653694576,"mc":[{"id":"1.168222851","rc":[{"batb":[[0,2.24,20.22],[1,2.22,20.54],[2,1.01,10.51]],"ltp":0.0,"tv":0.0,"id":11772759}]}]}
{"op":"mcm","clk":"1010920286","pt":1580653695065,"mc":[{"id":"1.168222851","rc":[{"batb":[[1,1.01,10.51],[2,1.01,0]],"ltp":0.0,"tv":0.0,"id":11772759}]}]}
{"op":"mcm","clk":"1010925288","pt":1580653718733,"mc":[{"id":"1.168222851","rc":[{"batb":[[1,1.58,31],[2,1.56,74.78]],"batl":[[0,1.7,42.01],[1,2.16,342.82]],"ltp":0.0,"tv":0.0,"id":9631075},{"batb":[[0,2.44,15.97],[1,2.42,29.41],[2,2.34,17.94]],"ltp":0.0,"tv":0.0,"id":11772759}]}]}
{"op":"mcm","clk":"1010925798","pt":1580653721335,"mc":[{"id":"1.168222851","rc":[{"batl":[[0,2.78,23.53],[1,3.3,191.92]],"ltp":0.0,"tv":0.0,"id":11772759}]}]}
{"op":"mcm","clk":"1010928604","pt":1580653734251,"mc":[{"id":"1.168222851","rc":[{"batl":[[0,3.3,191.92],[1,3.3,0]],"ltp":0.0,"tv":0.0,"id":11772759}]}]}
{"op":"mcm","clk":"1010929376","pt":1580653737473,"mc":[{"id":"1.168222851","rc":[{"batl":[[0,2.76,23.53],[1,3.3,191.92]],"ltp":0.0,"tv":0.0,"id":11772759}]}]}
{"op":"mcm","clk":"1010932620","pt":1580653750251,"mc":[{"id":"1.168222851","rc":[{"batb":[[0,1.58,31],[1,1.56,74.78],[2,1.01,10.51]],"ltp":0.0,"tv":0.0,"id":9631075},{"batb":[[0,2.42,29.41],[1,2.34,17.94],[2,1.01,10.51]],"ltp":0.0,"tv":0.0,"id":11772759}]}]}
{"op":"mcm","clk":"1010932960","pt":1580653751575,"mc":[{"id":"1.168222851","rc":[{"batb":[[1,1.01,10.51],[2,1.01,0]],"batl":[[0,2.16,342.82],[1,2.16,0]],"ltp":0.0,"tv":0.0,"id":9631075},{"batb":[[0,2.34,17.94],[1,1.01,10.51],[2,1.01,0]],"batl":[[0,3.3,191.92],[1,3.3,0]],"ltp":0.0,"tv":0.0,"id":11772759}]}]}
{"op":"mcm","clk":"1010933426","pt":1580653753456,"mc":[{"id":"1.168222851","rc":[{"batb":[[0,1.56,32.5]],"ltp":0.0,"tv":0.0,"id":9631075},{"batb":[[0,2.4,16.76]],"ltp":0.0,"tv":0.0,"id":11772759}]}]}
{"op":"mcm","clk":"1010934654","pt":1580653758471,"mc":[{"id":"1.168222851","rc":[{"batb":[[0,1.56,107.27]],"batl":[[0,1.69,42.01],[1,2.16,342.82]],"ltp":0.0,"tv":0.0,"id":9631075},{"batb":[[0,2.44,28.57],[1,2.4,16.76],[2,1.01,10.51]],"batl":[[0,2.82,22.69],[1,3.3,191.92]],"ltp":0.0,"tv":0.0,"id":11772759}]}]}
{"op":"mcm","clk":"1010934905","pt":1580653759657,"mc":[{"id":"1.168222851","rc":[{"batb":[[1,1.53,34.46],[2,1.01,10.51]],"ltp":0.0,"tv":0.0,"id":9631075},{"batb":[[0,2.56,14.01],[1,2.44,44.38]],"ltp":0.0,"tv":0.0,"id":11772759}]}]}
{"op":"mcm","clk":"1010938587","pt":1580653775715,"mc":[{"id":"1.168222851","rc":[{"batb":[[0,1.53,34.46],[1,1.01,10.51],[2,1.01,0]],"batl":[[0,2.16,342.82],[1,2.16,0]],"ltp":0.0,"tv":0.0,"id":9631075},{"batb":[[0,2.44,15.82],[1,1.01,10.51],[2,1.01,0]],"batl":[[0,3.3,191.92],[1,3.3,0]],"ltp":0.0,"tv":0.0,"id":11772759}]}]}
{"op":"mcm","clk":"1010939292","pt":1580653779013,"mc":[{"id":"1.168222851","rc":[{"batb":[[0,2.46,15.58]],"ltp":0.0,"tv":0.0,"id":11772759}]}]}
{"op":"mcm","clk":"1010940996","pt":1580653786514,"mc":[{"id":"1.168222851","rc":[{"batb":[[0,1.6,29.58],[1,1.57,104.33],[2,1.01,10.51]],"batl":[[0,1.71,42.01],[1,2.16,342.82]],"ltp":0.0,"tv":0.0,"id":9631075},{"batb":[[1,2.42,29.41],[2,2.36,17.47]],"batl":[[0,2.78,23.53],[1,3.3,191.92]],"ltp":0.0,"tv":0.0,"id":11772759}]}]}
{"op":"mcm","clk":"1010941181","pt":1580653787380,"mc":[{"id":"1.168222851","rc":[{"batl":[[0,2.74,23.53]],"ltp":0.0,"tv":0.0,"id":11772759}]}]}
{"op":"mcm","clk":"1010945877","pt":1580653808527,"mc":[{"id":"1.168222851","rc":[{"batb":[[0,1.57,104.33],[1,1.01,10.51],[2,1.01,0]],"ltp":0.0,"tv":0.0,"id":9631075},{"batb":[[0,2.42,29.41],[1,2.36,17.47],[2,1.01,10.51]],"ltp":0.0,"tv":0.0,"id":11772759}]}]}
{"op":"mcm","clk":"1010946076","pt":1580653809747,"mc":[{"id":"1.168222851","rc":[{"batb":[[0,1.57,31.24]],"batl":[[0,2.16,342.82],[1,2.16,0]],"ltp":0.0,"tv":0.0,"id":9631075},{"batb":[[0,2.36,17.47],[1,1.01,10.51],[2,1.01,0]],"batl":[[0,3.3,191.92],[1,3.3,0]],"ltp":0.0,"tv":0.0,"id":11772759}]}]}
{"op":"mcm","clk":"1010948669","pt":1580653822628,"mc":[{"id":"1.168222851","rc":[{"batb":[[0,1.57,104.33],[1,1.55,33.52],[2,1.01,10.51]],"batl":[[0,1.7,42.01],[1,1.71,42.01],[2,2.16,342.82]],"ltp":0.0,"tv":0.0,"id":9631075},{"batb":[[0,2.52,14.63],[1,2.44,28.57],[2,2.42,16.29]],"batl":[[0,2.78,23.53],[1,3.3,191.92]],"ltp":0.0,"tv":0.0,"id":11772759}]}]}
{"op":"mcm","clk":"1010948701","pt":1580653822848,"mc":[{"id":"1.168222851","rc":[{"batl":[[1,2.16,342.82],[2,2.16,0]],"ltp":0.0,"tv":0.0,"id":9631075}]}]}
{"op":"mcm","clk":"1010953066","pt":1580653845566,"mc":[{"id":"1.168222851","rc":[{"batb":[[0,1.55,33.52],[1,1.01,10.51],[2,1.01,0]],"batl":[[0,2.16,342.82],[1,2.16,0]],"ltp":0.0,"tv":0.0,"id":9631075},{"batb":[[0,2.42,16.29],[1,1.01,10.51],[2,2.42,0]],"batl":[[0,3.3,191.92],[1,3.3,0]],"ltp":0.0,"tv":0.0,"id":11772759}]}]}
{"op":"mcm","clk":"1010953551","pt":1580653848136,"mc":[{"id":"1.168222851","rc":[{"batb":[[0,1.54,33.52]],"ltp":0.0,"tv":0.0,"id":9631075}]}]}
{"op":"mcm","clk":"1010954775","pt":1580653854749,"mc":[{"id":"1.168222851","rc":[{"batb":[[0,1.61,28.48],[1,1.59,100.95],[2,1.54,33.52]],"batl":[[0,1.73,42.01],[1,2.16,342.82]],"ltp":0.0,"tv":0.0,"id":9631075},{"batb":[[1,2.38,30.25],[2,2.32,18.41]],"batl":[[0,2.7,24.37],[1,3.3,191.92]],"ltp":0.0,"tv":0.0,"id":11772759}]}]}
{"op":"mcm","clk":"1010954814","pt":1580653854930,"mc":[{"id":"1.168222851","rc":[{"batb":[[2,1.01,10.51]],"ltp":0.0,"tv":0.0,"id":9631075}]}]}
{"op":"mcm","clk":"1010959367","pt":1580653875958,"mc":[{"id":"1.168222851","rc":[{"batb":[[0,1.59,100.95],[1,1.01,10.51],[2,1.01,0]],"ltp":0.0,"tv":0.0,"id":9631075},{"batb":[[0,2.38,30.25],[1,2.32,18.41],[2,1.01,10.51]],"ltp":0.0,"tv":0.0,"id":11772759}]}]}
{"op":"mcm","clk":"1010959793","pt":1580653877579,"mc":[{"id":"1.168222851","rc":[{"batb":[[0,1.59,30.37]],"batl":[[0,2.16,342.82],[1,2.16,0]],"ltp":0.0,"tv":0.0,"id":9631075},{"batb":[[0,2.32,18.41],[1,1.01,10.51],[2,1.01,0]],"batl":[[0,3.3,191.92],[1,3.3,0]],"ltp":0.0,"tv":0.0,"id":11772759}]}]}
{"op":"mcm","clk":"1010961896","pt":1580653886696,"mc":[{"id":"1.168222851","rc":[{"batb":[[0,1.66,25.57],[1,1.63,27.22],[2,1.62,67.22]],"batl":[[0,1.77,42.01],[1,2.16,342.82]],"ltp":0.0,"tv":0.0,"id":9631075},{"batb":[[0,2.32,49.5],[1,2.22,20.61],[2,1.01,10.51]],"batl":[[0,2.62,25.21],[1,3.3,191.92]],"ltp":0.0,"tv":0.0,"id":11772759}]}]}
{"op":"mcm","clk":"1010967167","pt":1580653909527,"mc":[{"id":"1.168222851","rc":[{"batb":[[0,1.63,27.22],[1,1.01,10.51],[2,1.62,0]],"batl":[[0,2.16,342.82],[1,2.16,0]],"ltp":0.0,"tv":0.0,"id":9631075},{"batb":[[0,2.22,20.61],[1,1.01,10.51],[2,1.01,0]],"batl":[[0,3.3,191.92],[1,3.3,0]],"ltp":0.0,"tv":0.0,"id":11772759}]}]}
{"op":"mcm","clk":"1010969223","pt":1580653918532,"mc":[{"id":"1.168222851","rc":[{"batb":[[1,1.61,68.06],[2,1.6,29.43]],"batl":[[0,1.76,42.01],[1,2.16,342.82]],"ltp":0.0,"tv":0.0,"id":9631075},{"batb":[[0,2.38,17.15],[1,2.32,31.09],[2,2.28,19.2]],"batl":[[0,2.66,25.21],[1,3.3,191.92]],"ltp":0.0,"tv":0.0,"id":11772759}]}]}
{"op":"mcm","clk":"1010973369","pt":1580653937527,"mc":[{"id":"1.168222851","rc":[{"batb":[[0,1.6,29.43],[1,1.01,10.51],[2,1.6,0]],"batl":[[0,2.16,342.82],[1,2.16,0]],"ltp":0.0,"tv":0.0,"id":9631075},{"batb":[[0,2.28,19.2],[1,1.01,10.51],[2,2.28,0]],"batl":[[0,3.3,191.92],[1,3.3,0]],"ltp":0.0,"tv":0.0,"id":11772759}]}]}
{"op":"mcm","clk":"1010978159","pt":1580653958686,"mc":[{"id":"1.168222851","rc":[{"batb":[[0,1.6,99.16],[1,1.57,31.39],[2,1.01,10.51]],"batl":[[0,1.74,42.01],[1,2.16,342.82]],"ltp":0.0,"tv":0.0,"id":9631075},{"batb":[[0,2.46,15.66],[1,2.36,30.25],[2,2.34,48.79]],"batl":[[0,2.7,24.37],[1,3.3,191.92]],"ltp":0.0,"tv":0.0,"id":11772759}]}]}
{"op":"mcm","clk":"1010978302","pt":1580653959286,"mc":[{"id":"1.168222851","rc":[{"batb":[[2,2.34,17.7]],"ltp":0.0,"tv":0.0,"id":11772759}]}]}
{"op":"mcm","clk":"1010983114","pt":1580653981728,"mc":[{"id":"1.168222851","rc":[{"batb":[[0,1.57,31.39],[1,1.01,10.51],[2,1.01,0]],"batl":[[0,2.16,342.82],[1,2.16,0]],"ltp":0.0,"tv":0.0,"id":9631075},{"batb":[[0,2.34,17.7],[1,1.01,10.51],[2,2.34,0]],"batl":[[0,3.3,191.92],[1,3.3,0]],"ltp":0.0,"tv":0.0,"id":11772759}]}]}
{"op":"mcm","clk":"1010985947","pt":1580653994607,"mc":[{"id":"1.168222851","rc":[{"batb":[[0,1.57,104.49],[1,1.53,34.38],[2,1.01,10.51]],"batl":[[0,1.71,42.01],[1,2.16,342.82]],"ltp":0.0,"tv":0.0,"id":9631075},{"batb":[[0,2.52,14.56],[1,2.44,44.3],[2,2.34,17.7]],"batl":[[0,2.76,23.53],[1,3.3,191.92]],"ltp":0.0,"tv":0.0,"id":11772759}]}]}
{"op":"mcm","clk":"1010986133","pt":1580653995484,"mc":[{"id":"1.168222851","rc":[{"batb":[[2,1.01,10.51]],"ltp":0.0,"tv":0.0,"id":11772759}]}]}
{"op":"mcm","clk":"1011007729","pt":1580654091718,"mc":[{"id":"1.168222851","rc":[{"batb":[[0,1.53,34.38],[1,1.01,10.51],[2,1.01,0]],"batl":[[0,2.16,342.82],[1,2.16,0]],"ltp":0.0,"tv":0.0,"id":9631075},{"batb":[[0,2.44,15.74],[1,1.01,10.51],[2,1.01,0]],"batl":[[0,3.3,191.92],[1,3.3,0]],"ltp":0.0,"tv":0.0,"id":11772759}]}]}
{"op":"mcm","clk":"1011009805","pt":1580654100505,"mc":[{"id":"1.168222851","rc":[{"batb":[[0,1.58,72.26],[1,1.53,34.38],[2,1.01,10.51]],"batl":[[0,1.72,42.01],[1,2.16,342.82]],"ltp":0.0,"tv":0.0,"id":9631075},{"batb":[[1,2.4,29.41],[2,1.01,10.51]],"batl":[[0,2.74,23.53],[1,3.3,191.92]],"ltp":0.0,"tv":0.0,"id":11772759}]}]}
{"op":"mcm","clk":"1011010093","pt":1580654101599,"mc":[{"id":"1.168222851","rc":[{"batb":[[0,1.6,29.35],[1,1.58,72.26],[2,1.56,32.18]],"ltp":0.0,"tv":0.0,"id":9631075},{"batb":[[2,2.38,17.07]],"ltp":0.0,"tv":0.0,"id":11772759}]}]}
{"op":"mcm","clk":"1011013774","pt":1580654116722,"mc":[{"id":"1.168222851","rc":[{"batb":[[0,1.58,72.26],[1,1.56,32.18],[2,1.01,10.51]],"ltp":0.0,"tv":0.0,"id":9631075},{"batb":[[0,2.4,29.41],[1,2.38,17.07],[2,1.01,10.51]],"ltp":0.0,"tv":0.0,"id":11772759}]}]}
{"op":"mcm","clk":"1011014039","pt":1580654117661,"mc":[{"id":"1.168222851","rc":[{"batb":[[0,1.56,32.18],[1,1.01,10.51],[2,1.01,0]],"batl":[[0,2.16,342.82],[1,2.16,0]],"ltp":0.0,"tv":0.0,"id":9631075},{"batb":[[0,2.38,17.07],[1,1.01,10.51],[2,1.01,0]],"batl":[[0,3.3,191.92],[1,3.3,0]],"ltp":0.0,"tv":0.0,"id":11772759}]}]}
{"op":"mcm","clk":"1011017553","pt":1580654132552,"mc":[{"id":"1.168222851","rc":[{"batb":[[0,1.56,106.96],[1,1.53,35.17],[2,1.01,10.51]],"batl":[[0,1.7,42.01],[1,2.16,342.82]],"ltp":0.0,"tv":0.0,"id":9631075},{"batb":[[0,2.54,14.16],[1,2.46,44.07],[2,1.01,10.51]],"batl":[[0,2.8,22.69],[1,3.3,191.92]],"ltp":0.0,"tv":0.0,"id":11772759}]}]}
{"op":"mcm","clk":"1011019508","pt":1580654140664,"mc":[{"id":"1.168222851","rc":[{"batb":[[0,1.56,74.78]],"ltp":0.0,"tv":0.0,"id":9631075},{"batb":[[0,2.46,44.07],[1,1.01,10.51],[2,1.01,0]],"ltp":0.0,"tv":0.0,"id":11772759}]}]}
{"op":"mcm","clk":"1011019732","pt":1580654141567,"mc":[{"id":"1.168222851","rc":[{"batb":[[0,1.53,35.17],[1,1.01,10.51],[2,1.01,0]],"batl":[[0,2.16,342.82],[1,2.16,0]],"ltp":0.0,"tv":0.0,"id":9631075},{"batb":[[0,2.46,15.5]],"batl":[[0,3.3,191.92],[1,3.3,0]],"ltp":0.0,"tv":0.0,"id":11772759}]}]}
{"op":"mcm","clk":"1011021189","pt":1580654147679,"mc":[{"id":"1.168222851","rc":[{"batb":[[0,1.59,29.82],[1,1.56,32.65],[2,1.53,35.17]],"ltp":0.0,"tv":0.0,"id":9631075},{"batb":[[1,2.38,16.92],[2,1.01,10.51]],"ltp":0.0,"tv":0.0,"id":11772759}]}]}
{"op":"mcm","clk":"1011021411","pt":1580654148562,"mc":[{"id":"1.168222851","rc":[{"batb":[[1,1.57,73.1],[2,1.56,32.65]],"batl":[[0,1.71,42.01],[1,2.16,342.82]],"ltp":0.0,"tv":0.0,"id":9631075},{"batb":[[1,2.42,29.41],[2,2.38,16.92]],"batl":[[0,2.76,23.53],[1,3.3,191.92]],"ltp":0.0,"tv":0.0,"id":11772759}]}]}
{"op":"mcm","clk":"1011028354","pt":1580654178017,"mc":[{"id":"1.168222851","rc":[{"batb":[[0,1.57,73.1],[1,1.56,32.65],[2,1.01,10.51]],"ltp":0.0,"tv":0.0,"id":9631075},{"batb":[[0,2.42,29.41],[1,2.38,16.92],[2,1.01,10.51]],"ltp":0.0,"tv":0.0,"id":11772759}]}]}
{"op":"mcm","clk":"1011028709","pt":1580654179609,"mc":[{"id":"1.168222851","rc":[{"batb":[[0,1.56,32.65],[1,1.01,10.51],[2,1.01,0]],"batl":[[0,2.16,342.82],[1,2.16,0]],"ltp":0.0,"tv":0.0,"id":9631075},{"batb":[[0,2.38,16.92],[1,1.01,10.51],[2,1.01,0]],"batl":[[0,3.3,191.92],[1,3.3,0]],"ltp":0.0,"tv":0.0,"id":11772759}]}]}
{"op":"mcm","clk":"1011030934","pt":1580654189598,"mc":[{"id":"1.168222851","rc":[{"batb":[[1,1.52,36.04],[2,1.01,10.51]],"ltp":0.0,"tv":0.0,"id":9631075},{"batb":[[0,2.56,13.93],[1,2.48,15.26],[2,1.01,10.51]],"ltp":0.0,"tv":0.0,"id":11772759}]}]}
{"op":"mcm","clk":"1011031214","pt":1580654190671,"mc":[{"id":"1.168222851","rc":[{"batb":[[0,1.56,107.43]],"batl":[[0,1.69,42.01],[1,2.16,342.82]],"ltp":0.0,"tv":0.0,"id":9631075},{"batb":[[1,2.48,42.99]],"batl":[[0,2.82,22.69],[1,3.3,191.92]],"ltp":0.0,"tv":0.0,"id":11772759}]}]}
{"op":"mcm","clk":"1011033162","pt":1580654199588,"mc":[{"id":"1.168222851","rc":[{"batb":[[0,1.52,36.04],[1,1.01,10.51],[2,1.01,0]],"batl":[[0,2.16,342.82],[1,2.16,0]],"ltp":0.0,"tv":0.0,"id":9631075},{"batb":[[0,2.48,15.26],[1,1.01,10.51],[2,1.01,0]],"batl":[[0,3.3,191.92],[1,3.3,0]],"ltp":0.0,"tv":0.0,"id":11772759}]}]}
{"op":"mcm","clk":"1011033620","pt":1580654201654,"mc":[{"id":"1.168222851","rc":[{"batl":[[0,2.56,13.92],[1,3.3,191.92]],"ltp":0.0,"tv":0.0,"id":11772759}]}]}
{"op":"mcm","clk":"1011033757","pt":1580654202363,"mc":[{"id":"1.168222851","rc":[{"batl":[[0,3.3,191.92],[1,3.3,0]],"ltp":0.0,"tv":0.0,"id":11772759}]}]}
{"op":"mcm","clk":"1011037899","pt":1580654220737,"mc":[{"id":"1.168222851","rc":[{"batb":[[0,1.59,30.14],[1,1.57,460.34],[2,1.56,74.78]],"batl":[[0,1.7,42.01],[1,2.16,342.82]],"ltp":0.0,"tv":0.0,"id":9631075},{"batb":[[1,2.44,28.57],[2,2.4,16.68]],"batl":[[0,2.78,23.53],[1,3.3,191.92]],"ltp":0.0,"tv":0.0,"id":11772759}]}]}
{"op":"mcm","clk":"1011039448","pt":1580654227327,"mc":[{"id":"1.168222851","rc":[{"batb":[[1,1.56,74.78],[2,1.55,32.97]],"ltp":0.0,"tv":0.0,"id":9631075},{"trd":[[2.48,30.48]],"batb":[[0,2.44,28.59],[1,2.4,16.68],[2,1.01,10.51]],"ltp":2.48,"tv":30.48,"id":11772759}],"tv":30.48}]}
{"op":"mcm","clk":"1011043299","pt":1580654243673,"mc":[{"id":"1.168222851","rc":[{"batb":[[0,1.55,32.97],[1,1.01,10.51],[2,1.55,0]],"batl":[[0,2.16,342.82],[1,2.16,0]],"ltp":0.0,"tv":0.0,"id":9631075},{"batb":[[0,2.4,16.68],[1,1.01,10.51],[2,1.01,0]],"batl":[[0,3.3,191.92],[1,3.3,0]],"ltp":2.48,"tv":30.48,"id":11772759}]}]}
{"op":"mcm","clk":"1011043985","pt":1580654246658,"mc":[{"id":"1.168222851","rc":[{"batb":[[0,1.58,32.34]],"ltp":0.0,"tv":0.0,"id":9631075},{"batb":[[0,2.38,17.07]],"ltp":2.48,"tv":30.48,"id":11772759}]}]}
{"op":"mcm","clk":"1011044855","pt":1580654250575,"mc":[{"id":"1.168222851","rc":[{"batb":[[0,1.65,27.38],[1,1.62,29.35],[2,1.59,70.58]],"batl":[[0,1.73,42.01],[1,2.16,342.82]],"ltp":0.0,"tv":0.0,"id":9631075},{"batb":[[0,2.4,29.41],[1,2.38,17.07],[2,2.28,19.04]],"batl":[[0,2.72,24.37],[1,3.3,191.92]],"ltp":2.48,"tv":30.48,"id":11772759}]}]}
{"op":"mcm","clk":"1011052326","pt":1580654282622,"mc":[{"id":"1.168222851","rc":[{"batb":[[0,1.62,29.35],[1,1.59,70.58],[2,1.01,10.51]],"ltp":0.0,"tv":0.0,"id":9631075},{"batb":[[1,2.28,19.04],[2,1.01,10.51]],"ltp":2.48,"tv":30.48,"id":11772759}]}]}
{"op":"mcm","clk":"1011052543","pt":1580654283613,"mc":[{"id":"1.168222851","rc":[{"batb":[[1,1.01,10.51],[2,1.01,0]],"batl":[[0,2.16,342.82],[1,2.16,0]],"ltp":0.0,"tv":0.0,"id":9631075},{"batb":[[0,2.28,19.04],[1,1.01,10.51],[2,1.01,0]],"batl":[[0,3.3,191.92],[1,3.3,0]],"ltp":2.48,"tv":30.48,"id":11772759}]}]}
{"op":"mcm","clk":"1011053247","pt":1580654286609,"mc":[{"id":"1.168222851","rc":[{"batb":[[0,1.61,30.37]],"ltp":0.0,"tv":0.0,"id":9631075},{"batb":[[0,2.32,18.25]],"ltp":2.48,"tv":30.48,"id":11772759}]}]}
{"op":"mcm","clk":"1011057112","pt":1580654303729,"mc":[{"id":"1.168222851","rc":[{"batb":[[1,1.57,32.57],[2,1.01,10.51]],"ltp":0.0,"tv":0.0,"id":9631075},{"batb":[[0,2.48,15.11],[1,2.38,17],[2,2.32,18.25]],"ltp":2.48,"tv":30.48,"id":11772759}]}]}
{"op":"mcm","clk":"1011057328","pt":1580654304707,"mc":[{"id":"1.168222851","rc":[{"batb":[[1,1.58,72.26],[2,1.57,32.57]],"batl":[[0,1.72,42.01],[1,2.16,342.82]],"ltp":0.0,"tv":0.0,"id":9631075},{"batb":[[1,2.4,29.41],[2,2.38,17]],"batl":[[0,2.76,23.53],[1,3.3,191.92]],"ltp":2.48,"tv":30.48,"id":11772759}]}]}
{"op":"mcm","clk":"1011057484","pt":1580654305405,"mc":[{"id":"1.168222851","rc":[{"batl":[[0,1.71,42.01]],"ltp":0.0,"tv":0.0,"id":9631075}]}]}
{"op":"mcm","clk":"1011061324","pt":1580654323668,"mc":[{"id":"1.168222851","rc":[{"batb":[[0,1.57,32.57],[1,1.01,10.51],[2,1.57,0]],"batl":[[0,2.16,342.82],[1,2.16,0]],"ltp":0.0,"tv":0.0,"id":9631075},{"batb":[[0,2.38,17],[1,1.01,10.51],[2,2.38,0]],"batl":[[0,3.3,191.92],[1,3.3,0]],"ltp":2.48,"tv":30.48,"id":11772759}]}]}
{"op":"mcm","clk":"1011062215","pt":1580654327743,"mc":[{"id":"1.168222851","rc":[{"batl":[[0,2.48,14.99],[1,3.3,191.92]],"ltp":2.48,"tv":30.48,"id":11772759}]}]}
{"op":"mcm","clk":"1011062258","pt":1580654327955,"mc":[{"id":"1.168222851","rc":[{"batl":[[0,3.3,191.92],[1,3.3,0]],"ltp":2.48,"tv":30.48,"id":11772759}]}]}
{"op":"mcm","clk":"1011064803","pt":1580654340596,"mc":[{"id":"1.168222851","rc":[{"batb":[[1,1.56,74.78],[2,1.01,10.51]],"batl":[[0,1.7,42.01],[1,2.16,342.82]],"ltp":0.0,"tv":0.0,"id":9631075},{"batb":[[0,2.44,28.57],[1,2.38,17],[2,1.01,10.51]],"batl":[[0,2.8,22.69],[1,3.3,191.92]],"ltp":2.48,"tv":30.48,"id":11772759}]}]}
{"op":"mcm","clk":"1011064928","pt":1580654341158,"mc":[{"id":"1.168222851","rc":[{"batb":[[2,1.55,34.46]],"ltp":0.0,"tv":0.0,"id":9631075},{"batb":[[0,2.56,13.93],[1,2.44,44.54]],"ltp":2.48,"tv":30.48,"id":11772759}]}]}
{"op":"mcm","clk":"1011066299","pt":1580654347572,"mc":[{"id":"1.168222851","rc":[{"trd":[[2.56,27.84]],"batb":[[0,2.44,44.54],[1,1.01,10.51],[2,1.01,0]],"ltp":2.56,"tv":58.32,"id":11772759}],"tv":58.32}]}
{"op":"mcm","clk":"1011069396","pt":1580654362649,"mc":[{"id":"1.168222851","rc":[{"batb":[[0,1.56,74.78],[1,1.55,34.46],[2,1.01,10.51]],"ltp":0.0,"tv":0.0,"id":9631075},{"batb":[[0,2.44,44.54]],"ltp":2.56,"tv":58.32,"id":11772759}]}]}
{"op":"mcm","clk":"1011069610","pt":1580654363693,"mc":[{"id":"1.168222851","rc":[{"batb":[[0,1.55,34.46],[1,1.01,10.51],[2,1.01,0]],"batl":[[0,2.16,342.82],[1,2.16,0]],"ltp":0.0,"tv":0.0,"id":9631075},{"batb":[[0,2.44,15.97]],"batl":[[0,3.3,191.92],[1,3.3,0]],"ltp":2.56,"tv":58.32,"id":11772759}]}]}
{"op":"mcm","clk":"1011069935","pt":1580654365104,"mc":[{"id":"1.168222851","rc":[{"batb":[[0,1.56,33.91]],"ltp":0.0,"tv":0.0,"id":9631075},{"batb":[[0,2.42,16.29]],"ltp":2.56,"tv":58.32,"id":11772759}]}]}
{"op":"mcm","clk":"1011074696","pt":1580654386604,"mc":[{"id":"1.168222851","rc":[{"batb":[[1,1.55,75.62],[2,1.54,36.19]],"batl":[[0,1.69,42.01]],"ltp":0.0,"tv":0.0,"id":9631075},{"batb":[[0,2.6,13.3],[1,2.48,42.83],[2,1.01,10.51]],"batl":[[0,2.84,22.69]],"ltp":2.56,"tv":58.32,"id":11772759}]}]}
{"op":"mcm","clk":"1011075125","pt":1580654388485,"mc":[{"id":"1.168222851","rc":[{"batl":[[1,2.04,383.01]],"ltp":0.0,"tv":0.0,"id":9631075},{"batl":[[1,3.65,170.41]],"ltp":2.56,"tv":58.32,"id":11772759}]}]}
{"op":"mcm","clk":"1011079708","pt":1580654409642,"mc":[{"id":"1.168222851","rc":[{"batb":[[0,1.54,36.19],[1,1.01,10.51],[2,1.54,0]],"batl":[[0,2.04,383.01],[1,2.04,0]],"ltp":0.0,"tv":0.0,"id":9631075},{"batb":[[0,2.48,15.11],[1,1.01,10.51],[2,1.01,0]],"batl":[[0,3.65,170.41],[1,3.65,0]],"ltp":2.56,"tv":58.32,"id":11772759}]}]}
{"op":"mcm","clk":"1011079951","pt":1580654410727,"mc":[{"id":"1.168222851","rc":[{"batl":[[0,2.6,13.06],[1,3.65,170.41]],"ltp":2.56,"tv":58.32,"id":11772759}]}]}
{"op":"mcm","clk":"1011080128","pt":1580654411652,"mc":[{"id":"1.168222851","rc":[{"batl":[[0,3.65,170.41],[1,3.65,0]],"ltp":2.56,"tv":58.32,"id":11772759}]}]}
{"op":"mcm","clk":"1011081674","pt":1580654418676,"mc":[{"id":"1.168222851","rc":[{"batb":[[0,1.55,158.17],[1,1.54,267.81],[2,1.01,10.51]],"batl":[[0,1.6,142.08],[1,1.61,129.32],[2,1.67,42.01]],"ltp":0.0,"tv":0.0,"id":9631075},{"batb":[[0,2.52,26.89],[1,2.48,15.11],[2,1.01,10.51]],"batl":[[0,2.86,21.85],[1,3.65,170.41]],"ltp":2.56,"tv":58.32,"id":11772759}]}]}
{"op":"mcm","clk":"1011081909","pt":1580654419655,"mc":[{"id":"1.168222851","rc":[{"batb":[[2,1.43,48.15]],"ltp":0.0,"tv":0.0,"id":9631075},{"batb":[[0,2.68,12.27],[1,2.52,26.89],[2,2.44,15.97]],"ltp":2.56,"tv":58.32,"id":11772759}]}]}
{"op":"mcm","clk":"1011083875","pt":1580654428745,"mc":[{"id":"1.168222851","rc":[{"trd":[[1.6,20.56]],"batb":[[0,1.6,35.18],[1,1.54,113.49]],"batl":[[0,1.67,42.01],[1,2.04,383.01],[2,1.67,0]],"ltp":1.6,"tv":20.56,"id":9631075},{"trd":[[2.68,12.27]],"batb":[[0,2.52,26.89],[1,2.44,15.97],[2,1.01,10.51]],"ltp":2.68,"tv":70.59,"id":11772759}],"tv":91.15}]}
{"op":"mcm","clk":"1011084049","pt":1580654429656,"mc":[{"id":"1.168222851","rc":[{"batb":[[0,1.01,10.51],[1,1.54,0],[2,1.43,0]],"batl":[[0,2.04,383.01],[1,2.04,0]],"ltp":1.6,"tv":20.56,"id":9631075},{"batb":[[0,1.01,10.51],[1,2.44,0],[2,1.01,0]],"batl":[[0,3.65,170.41],[1,3.65,0]],"ltp":2.68,"tv":70.59,"id":11772759}]}]}
{"op":"mcm","clk":"1011165955","pt":1580654804692,"mc":[{"id":"1.168222851","rc":[{"batb":[[0,1.59,70.58],[1,1.01,10.51]],"batl":[[0,1.75,42.01]],"ltp":1.6,"tv":20.56,"id":9631075},{"batb":[[0,2.34,31.09],[1,1.01,10.51]],"batl":[[0,2.68,24.37]],"ltp":2.68,"tv":70.59,"id":11772759}]}]}
{"op":"mcm","clk":"1011166133","pt":1580654805711,"mc":[{"id":"1.168222851","rc":[{"batb":[[0,1.01,10.51],[1,1.01,0]],"batl":[[1,2.16,342.82]],"ltp":1.6,"tv":20.56,"id":9631075},{"batl":[[1,3.3,191.92]],"ltp":2.68,"tv":70.59,"id":11772759}]}]}
{"op":"mcm","clk":"1011166527","pt":1580654807548,"mc":[{"id":"1.168222851","rc":[{"batb":[[0,1.6,69.74],[1,1.01,10.51]],"ltp":1.6,"tv":20.56,"id":9631075}]}]}
{"op":"mcm","clk":"1011166918","pt":1580654809400,"mc":[{"id":"1.168222851","rc":[{"batl":[[0,3.3,191.92],[1,3.3,0]],"ltp":2.68,"tv":70.59,"id":11772759}]}]}
{"op":"mcm","clk":"1011167572","pt":1580654812721,"mc":[{"id":"1.168222851","rc":[{"batl":[[0,2.66,25.21],[1,3.3,191.92]],"ltp":2.68,"tv":70.59,"id":11772759}]}]}
{"op":"mcm","clk":"1011168432","pt":1580654817066,"mc":[{"id":"1.168222851","rc":[{"batb":[[0,1.01,10.51],[1,1.01,0]],"ltp":1.6,"tv":20.56,"id":9631075},{"batl":[[0,3.3,191.92],[1,3.3,0]],"ltp":2.68,"tv":70.59,"id":11772759}]}]}
{"op":"mcm","clk":"1011169159","pt":1580654820721,"mc":[{"id":"1.168222851","rc":[{"batb":[[0,1.61,68.06],[1,1.01,10.51]],"ltp":1.6,"tv":20.56,"id":9631075},{"batl":[[0,2.64,25.21],[1,3.3,191.92]],"ltp":2.68,"tv":70.59,"id":11772759}]}]}
{"op":"mcm","clk":"1011169388","pt":1580654821852,"mc":[{"id":"1.168222851","rc":[{"batb":[[0,1.01,10.51],[1,1.01,0]],"batl":[[0,2.16,342.82],[1,2.16,0]],"ltp":1.6,"tv":20.56,"id":9631075},{"batb":[[0,1.01,10.51],[1,1.01,0]],"batl":[[0,3.3,191.92],[1,3.3,0]],"ltp":2.68,"tv":70.59,"id":11772759}]}]}
{"op":"mcm","clk":"1011171635","pt":1580654832729,"mc":[{"id":"1.168222851","rc":[{"batb":[[0,1.66,63.01],[1,1.01,10.51]],"batl":[[0,1.83,42.01],[1,2.16,342.82]],"ltp":1.6,"tv":20.56,"id":9631075},{"batb":[[0,2.22,33.61],[1,1.01,10.51]],"batl":[[0,2.52,26.89]],"ltp":2.68,"tv":70.59,"id":11772759}]}]}
{"op":"mcm","clk":"1011172220","pt":1580654835551,"mc":[{"id":"1.168222851","rc":[{"batl":[[1,3,213.45]],"ltp":2.68,"tv":70.59,"id":11772759}]}]}
{"op":"mcm","clk":"1011174831","pt":1580654848642,"mc":[{"id":"1.168222851","rc":[{"batb":[[0,1.01,10.51],[1,1.01,0]],"batl":[[0,2.16,342.82],[1,2.16,0]],"ltp":1.6,"tv":20.56,"id":9631075},{"batb":[[0,1.01,10.51],[1,1.01,0]],"batl":[[0,3,213.45],[1,3,0]],"ltp":2.68,"tv":70.59,"id":11772759}]}]}
{"op":"mcm","clk":"1011178362","pt":1580654866690,"mc":[{"id":"1.168222851","rc":[{"batb":[[0,1.7,59.65],[1,1.01,10.51]],"batl":[[0,1.88,42.01]],"ltp":1.6,"tv":20.56,"id":9631075},{"batb":[[0,2.14,36.13],[1,1.01,10.51]],"batl":[[0,2.42,29.41]],"ltp":2.68,"tv":70.59,"id":11772759}]}]}
{"op":"mcm","clk":"1011178719","pt":1580654868496,"mc":[{"id":"1.168222851","rc":[{"batl":[[1,2.42,286.52]],"ltp":1.6,"tv":20.56,"id":9631075},{"batl":[[1,2.82,231.28]],"ltp":2.68,"tv":70.59,"id":11772759}]}]}
{"op":"mcm","clk":"1011182121","pt":1580654886623,"mc":[{"id":"1.168222851","rc":[{"batb":[[0,1.01,10.51],[1,1.01,0]],"batl":[[0,2.42,286.52],[1,2.42,0]],"ltp":1.6,"tv":20.56,"id":9631075},{"batb":[[0,1.01,10.51],[1,1.01,0]],"batl":[[0,2.82,231.28],[1,2.82,0]],"ltp":2.68,"tv":70.59,"id":11772759}]}]}
{"op":"mcm","clk":"1011185311","pt":1580654902739,"mc":[{"id":"1.168222851","rc":[{"batb":[[0,1.66,63.01],[1,1.01,10.51]],"batl":[[0,1.83,42.01]],"ltp":1.6,"tv":20.56,"id":9631075},{"batb":[[0,2.2,34.45],[1,1.01,10.51]],"batl":[[0,2.5,27.73],[1,2.82,231.28]],"ltp":2.68,"tv":70.59,"id":11772759}]}]}
{"op":"mcm","clk":"1011185466","pt":1580654903538,"mc":[{"id":"1.168222851","rc":[{"batl":[[1,2.3,309.75]],"ltp":1.6,"tv":20.56,"id":9631075}]}]}
{"op":"mcm","clk":"1011186903","pt":1580654911740,"mc":[{"id":"1.168222851","rc":[{"batb":[[0,1.01,10.51],[1,1.01,0]],"batl":[[0,2.3,309.75],[1,2.3,0]],"ltp":1.6,"tv":20.56,"id":9631075},{"batb":[[0,1.01,10.51],[1,1.01,0]],"batl":[[0,2.82,231.28],[1,2.82,0]],"ltp":2.68,"tv":70.59,"id":11772759}]}]}
{"op":"mcm","clk":"1011191438","pt":1580654937161,"mc":[{"id":"1.168222851","rc":[{"batb":[[0,1.61,68.06],[1,1.01,10.51]],"batl":[[0,1.76,42.01]],"ltp":1.6,"tv":20.56,"id":9631075},{"batb":[[0,2.32,31.09],[1,1.01,10.51]],"batl":[[0,2.62,25.21]],"ltp":2.68,"tv":70.59,"id":11772759}]}]}
{"op":"mcm","clk":"1011191878","pt":1580654939858,"mc":[{"id":"1.168222851","rc":[{"batl":[[1,2.16,342.82]],"ltp":1.6,"tv":20.56,"id":9631075},{"batl":[[1,3.3,191.92]],"ltp":2.68,"tv":70.59,"id":11772759}]}]}
{"op":"mcm","clk":"1011195577","pt":1580654960578,"mc":[{"id":"1.168222851","rc":[{"batb":[[0,1.01,10.51],[1,1.01,0]],"batl":[[0,2.16,342.82],[1,2.16,0]],"ltp":1.6,"tv":20.56,"id":9631075},{"batb":[[0,1.01,10.51],[1,1.01,0]],"batl":[[0,3.3,191.92],[1,3.3,0]],"ltp":2.68,"tv":70.59,"id":11772759}]}]}
{"op":"mcm","clk":"1011200299","pt":1580654990778,"mc":[{"id":"1.168222851","rc":[{"batb":[[0,1.5,84.02],[1,1.01,10.51]],"batl":[[0,1.63,42.01]],"ltp":1.6,"tv":20.56,"id":9631075},{"batb":[[0,2.58,26.05],[1,1.01,10.51]],"batl":[[0,2.98,21]],"ltp":2.68,"tv":70.59,"id":11772759}]}]}
{"op":"mcm","clk":"1011200578","pt":1580654992474,"mc":[{"id":"1.168222851","rc":[{"batl":[[1,1.95,409.86]],"ltp":1.6,"tv":20.56,"id":9631075},{"batl":[[1,3.9,158.24]],"ltp":2.68,"tv":70.59,"id":11772759}]}]}
{"op":"mcm","clk":"1011204381","pt":1580655015889,"mc":[{"id":"1.168222851","rc":[{"batb":[[0,1.01,10.51],[1,1.01,0]],"batl":[[0,1.95,409.86],[1,1.95,0]],"ltp":1.6,"tv":20.56,"id":9631075},{"batb":[[0,1.01,10.51],[1,1.01,0]],"batl":[[0,3.9,158.24],[1,3.9,0]],"ltp":2.68,"tv":70.59,"id":11772759}]}]}
{"op":"mcm","clk":"1011209644","pt":1580655048731,"mc":[{"id":"1.168222851","rc":[{"batb":[[0,1.36,115.95],[1,1.01,10.51]],"batl":[[0,1.46,42.01]],"ltp":1.6,"tv":20.56,"id":9631075},{"batb":[[0,3.2,18.48],[1,1.01,10.51]],"batl":[[0,3.75,15.12]],"ltp":2.68,"tv":70.59,"id":11772759}]}]}
{"op":"mcm","clk":"1011210050","pt":1580655051213,"mc":[{"id":"1.168222851","rc":[{"batl":[[1,1.73,527.57]],"ltp":1.6,"tv":20.56,"id":9631075},{"batl":[[1,5.3,118.79]],"ltp":2.68,"tv":70.59,"id":11772759}]}]}
{"op":"mcm","clk":"1011212996","pt":1580655069848,"mc":[{"id":"1.168222851","rc":[{"batb":[[0,1.01,10.51],[1,1.01,0]],"batl":[[0,1.73,527.57],[1,1.73,0]],"ltp":1.6,"tv":20.56,"id":9631075},{"batb":[[0,1.01,10.51],[1,1.01,0]],"batl":[[0,5.3,118.79],[1,5.3,0]],"ltp":2.68,"tv":70.59,"id":11772759}]}]}
{"op":"mcm","clk":"1011218436","pt":1580655104897,"mc":[{"id":"1.168222851","rc":[{"batb":[[0,1.5,84.02],[1,1.01,10.51]],"batl":[[0,1.63,42.01]],"ltp":1.6,"tv":20.56,"id":9631075},{"batb":[[0,2.6,26.05],[1,1.01,10.51]],"batl":[[0,3,21]],"ltp":2.68,"tv":70.59,"id":11772759}]}]}
{"op":"mcm","clk":"1011218937","pt":1580655108075,"mc":[{"id":"1.168222851","rc":[{"batl":[[1,1.95,409.86]],"ltp":1.6,"tv":20.56,"id":9631075},{"batl":[[1,3.9,158.24]],"ltp":2.68,"tv":70.59,"id":11772759}]}]}
{"op":"mcm","clk":"1011222437","pt":1580655130462,"mc":[{"id":"1.168222851","rc":[{"batb":[[0,1.01,10.51],[1,1.01,0]],"batl":[[0,1.95,409.86],[1,1.95,0]],"ltp":1.6,"tv":20.56,"id":9631075},{"batb":[[0,1.01,10.51],[1,1.01,0]],"batl":[[0,3.9,158.24],[1,3.9,0]],"ltp":2.68,"tv":70.59,"id":11772759}]}]}
{"op":"mcm","clk":"1011223848","pt":1580655139409,"mc":[{"id":"1.168222851","rc":[{"batl":[[1,1000,3.04]],"ltp":1.6,"tv":20.56,"id":9631075}]}]}
{"op":"mcm","clk":"1011223978","pt":1580655140248,"mc":[{"id":"1.168222851","rc":[{"batl":[[1,1000,0]],"ltp":1.6,"tv":20.56,"id":9631075}]}]}
{"op":"mcm","clk":"1011224430","pt":1580655143317,"mc":[{"id":"1.168222851","rc":[{"trd":[[1.34,0.02]],"ltp":1.34,"tv":20.57,"id":9631075},{"trd":[[3.9,0.01]],"batl":[[0,3.9,158.23]],"ltp":3.9,"tv":70.6,"id":11772759}],"tv":91.17}]}
{"op":"mcm","clk":"1011225357","pt":1580655148758,"mc":[{"id":"1.168222851","rc":[{"batb":[[0,1.59,70.58],[1,1.01,10.51]],"batl":[[0,1.75,42.01]],"ltp":1.34,"tv":20.57,"id":9631075},{"batb":[[0,2.34,31.09],[1,1.01,10.51]],"batl":[[0,2.68,24.37]],"ltp":3.9,"tv":70.6,"id":11772759}]}]}
{"op":"mcm","clk":"1011225656","pt":1580655150546,"mc":[{"id":"1.168222851","rc":[{"batl":[[1,2.16,342.82]],"ltp":1.34,"tv":20.57,"id":9631075},{"batl":[[1,3.3,191.91]],"ltp":3.9,"tv":70.6,"id":11772759}]}]}
{"op":"mcm","clk":"1011228666","pt":1580655167882,"mc":[{"id":"1.168222851","rc":[{"batb":[[0,1.01,10.51],[1,1.01,0]],"batl":[[0,2.16,342.82],[1,2.16,0]],"ltp":1.34,"tv":20.57,"id":9631075},{"batb":[[0,1.01,10.51],[1,1.01,0]],"batl":[[0,3.3,191.91],[1,3.3,0]],"ltp":3.9,"tv":70.6,"id":11772759}]}]}
{"op":"mcm","clk":"1011230074","pt":1580655176800,"mc":[{"id":"1.168222851","rc":[{"batb":[[0,1.67,62.17],[1,1.01,10.51]],"batl":[[0,1.84,42.01],[1,2.16,342.82]],"ltp":1.34,"tv":20.57,"id":9631075},{"batb":[[0,2.18,35.29],[1,1.01,10.51]],"batl":[[0,2.48,27.73]],"ltp":3.9,"tv":70.6,"id":11772759}]}]}
{"op":"mcm","clk":"1011230340","pt":1580655178597,"mc":[{"id":"1.168222851","rc":[{"batl":[[1,3,213.44]],"ltp":3.9,"tv":70.6,"id":11772759}]}]}
{"op":"mcm","clk":"1011240042","pt":1580655239867,"mc":[{"id":"1.168222851","rc":[{"batb":[[1,1.01,10.52]],"ltp":1.34,"tv":20.57,"id":9631075}]}]}
{"op":"mcm","clk":"1011240326","pt":1580655241790,"mc":[{"id":"1.168222851","rc":[{"batb":[[0,1.01,10.52],[1,1.01,0]],"batl":[[0,2.16,342.82],[1,2.16,0]],"ltp":1.34,"tv":20.57,"id":9631075},{"batb":[[0,1.01,10.51],[1,1.01,0]],"batl":[[0,3,213.44],[1,3,0]],"ltp":3.9,"tv":70.6,"id":11772759}]}]}
{"op":"mcm","clk":"1011243658","pt":1580655262797,"mc":[{"id":"1.168222851","rc":[{"batb":[[0,1.81,51.25],[1,1.01,10.52]],"batl":[[0,2.02,41.17]],"ltp":1.34,"tv":20.57,"id":9631075},{"batb":[[0,1.98,42.85],[1,1.01,10.51]],"batl":[[0,2.22,33.61]],"ltp":3.9,"tv":70.6,"id":11772759}]}]}
{"op":"mcm","clk":"1011244042","pt":1580655264405,"mc":[{"id":"1.168222851","rc":[{"batl":[[1,2.5,274.55]],"ltp":1.34,"tv":20.57,"id":9631075},{"batl":[[1,2.72,241.54]],"ltp":3.9,"tv":70.6,"id":11772759}]}]}
{"op":"mcm","clk":"1011246278","pt":1580655278314,"mc":[{"id":"1.168222851","rc":[{"batb":[[0,1.01,10.52],[1,1.01,0]],"batl":[[0,2.5,274.55],[1,2.5,0]],"ltp":1.34,"tv":20.57,"id":9631075},{"batb":[[0,1.01,10.51],[1,1.01,0]],"batl":[[0,2.72,241.54],[1,2.72,0]],"ltp":3.9,"tv":70.6,"id":11772759}]}]}
{"op":"mcm","clk":"1011248398","pt":1580655290745,"mc":[{"id":"1.168222851","rc":[{"batl":[[0,2.6,257.55]],"ltp":3.9,"tv":70.6,"id":11772759}]}]}
{"op":"mcm","clk":"1011249760","pt":1580655298759,"mc":[{"id":"1.168222851","rc":[{"batb":[[0,1.71,58.81],[1,1.01,10.52]],"batl":[[0,1.89,42.01]],"ltp":1.34,"tv":20.57,"id":9631075},{"batb":[[0,2.14,36.13],[1,1.01,10.51]],"batl":[[0,2.42,29.41]],"ltp":3.9,"tv":70.6,"id":11772759}]}]}
{"op":"mcm","clk":"1011250054","pt":1580655300552,"mc":[{"id":"1.168222851","rc":[{"batl":[[1,2.36,299.19]],"ltp":1.34,"tv":20.57,"id":9631075}]}]}
{"op":"mcm","clk":"1011250092","pt":1580655300767,"mc":[{"id":"1.168222851","rc":[{"batl":[[1,2.92,221.25]],"ltp":3.9,"tv":70.6,"id":11772759}]}]}
{"op":"mcm","clk":"1011253456","pt":1580655319774,"mc":[{"id":"1.168222851","rc":[{"batb":[[0,1.01,10.52],[1,1.01,0]],"batl":[[0,2.36,299.19],[1,2.36,0]],"ltp":1.34,"tv":20.57,"id":9631075},{"batb":[[0,1.01,10.51],[1,1.01,0]],"batl":[[0,2.92,221.25],[1,2.92,0]],"ltp":3.9,"tv":70.6,"id":11772759}]}]}
{"op":"mcm","clk":"1011254801","pt":1580655327069,"mc":[{"id":"1.168222851","rc":[{"batb":[[0,1.62,67.22],[1,1.01,10.52]],"batl":[[0,1.78,42.01]],"ltp":1.34,"tv":20.57,"id":9631075},{"batb":[[0,2.28,32.77],[1,1.01,10.51]],"batl":[[0,2.6,26.05],[1,2.92,221.25]],"ltp":3.9,"tv":70.6,"id":11772759}]}]}
{"op":"mcm","clk":"1011255493","pt":1580655330670,"mc":[{"id":"1.168222851","rc":[{"batl":[[1,2.22,329.03]],"ltp":1.34,"tv":20.57,"id":9631075}]}]}
{"op":"mcm","clk":"1011257754","pt":1580655343922,"mc":[{"id":"1.168222851","rc":[{"batb":[[0,1.01,10.52],[1,1.01,0]],"batl":[[0,2.22,329.03],[1,2.22,0]],"ltp":1.34,"tv":20.57,"id":9631075},{"batb":[[0,1.01,10.51],[1,1.01,0]],"batl":[[0,2.92,221.25],[1,2.92,0]],"ltp":3.9,"tv":70.6,"id":11772759}]}]}
{"op":"mcm","clk":"1011259028","pt":1580655351519,"mc":[{"id":"1.168222851","rc":[{"batb":[[0,1.57,73.1],[1,1.01,10.52]],"batl":[[0,1.72,42.01]],"ltp":1.34,"tv":20.57,"id":9631075},{"batb":[[0,2.4,29.41],[1,1.01,10.51]],"batl":[[0,2.74,23.53]],"ltp":3.9,"tv":70.6,"id":11772759}]}]}
{"op":"mcm","clk":"1011259280","pt":1580655353114,"mc":[{"id":"1.168222851","rc":[{"batl":[[1,2.1,363.33]],"ltp":1.34,"tv":20.57,"id":9631075},{"batl":[[1,3.45,180.39]],"ltp":3.9,"tv":70.6,"id":11772759}]}]}
{"op":"mcm","clk":"1011260232","pt":1580655359007,"mc":[{"id":"1.168222851","rc":[{"batb":[[1,1.54,35.49],[2,1.01,10.52]],"ltp":1.34,"tv":20.57,"id":9631075},{"batb":[[1,2.32,18.41],[2,1.01,10.51]],"ltp":3.9,"tv":70.6,"id":11772759}]}]}
{"op":"mcm","clk":"1011261962","pt":1580655369833,"mc":[{"id":"1.168222851","rc":[{"batb":[[0,1.54,35.49],[1,1.01,10.52],[2,1.01,0]],"batl":[[0,2.1,363.33],[1,2.1,0]],"ltp":1.34,"tv":20.57,"id":9631075},{"batb":[[0,2.32,18.41],[1,1.01,10.51],[2,1.01,0]],"batl":[[0,3.45,180.39],[1,3.45,0]],"ltp":3.9,"tv":70.6,"id":11772759}]}]}
{"op":"mcm","clk":"1011267536","pt":1580655407085,"mc":[{"id":"1.168222851","rc":[{"batb":[[0,1.54,112.78],[1,1.43,48.63],[2,1.01,10.52]],"batl":[[0,1.68,42.01],[1,2.1,363.33]],"ltp":1.34,"tv":20.57,"id":9631075},{"batb":[[0,2.66,12.59],[1,2.48,27.73],[2,2.4,16.68]],"batl":[[0,2.86,21.85],[1,3.45,180.39]],"ltp":3.9,"tv":70.6,"id":11772759}]}]}
{"op":"mcm","clk":"1011272622","pt":1580655441214,"mc":[{"id":"1.168222851","rc":[{"batb":[[0,1.54,77.3]],"ltp":1.34,"tv":20.57,"id":9631075},{"batb":[[0,2.48,27.73],[1,2.4,16.68],[2,1.01,10.51]],"ltp":3.9,"tv":70.6,"id":11772759}]}]}
{"op":"mcm","clk":"1011272709","pt":1580655441906,"mc":[{"id":"1.168222851","rc":[{"batb":[[0,1.43,48.63],[1,1.01,10.52],[2,1.01,0]],"batl":[[0,2.1,363.33],[1,2.1,0]],"ltp":1.34,"tv":20.57,"id":9631075},{"batb":[[0,2.4,16.68],[1,1.01,10.51],[2,1.01,0]],"batl":[[0,3.45,180.39],[1,3.45,0]],"ltp":3.9,"tv":70.6,"id":11772759}]}]}
{"op":"mcm","clk":"1011273079","pt":1580655444645,"mc":[{"id":"1.168222851","rc":[{"batb":[[0,1.43,47.92]],"ltp":1.34,"tv":20.57,"id":9631075},{"batb":[[0,2.38,17]],"ltp":3.9,"tv":70.6,"id":11772759}]}]}
{"op":"mcm","clk":"1011273843","pt":1580655449632,"mc":[{"id":"1.168222851","rc":[{"batb":[[0,1.66,27.46],[1,1.53,36.98],[2,1.01,10.52]],"ltp":1.34,"tv":20.57,"id":9631075},{"batb":[[1,2.2,21.32],[2,1.01,10.51]],"ltp":3.9,"tv":70.6,"id":11772759}]}]}
{"op":"mcm","clk":"1011274123","pt":1580655451646,"mc":[{"id":"1.168222851","rc":[{"batb":[[1,1.6,69.74],[2,1.53,36.98]],"batl":[[0,1.76,42.01],[1,2.1,363.33]],"ltp":1.34,"tv":20.57,"id":9631075},{"batb":[[1,2.34,31.09],[2,2.2,21.32]],"batl":[[0,2.66,25.21]],"ltp":3.9,"tv":70.6,"id":11772759}]}]}
{"op":"mcm","clk":"1011274183","pt":1580655452077,"mc":[{"id":"1.168222851","rc":[{"batl":[[1,3.3,191.91]],"ltp":3.9,"tv":70.6,"id":11772759}]}]}
{"op":"mcm","clk":"1011275719","pt":1580655462674,"mc":[{"id":"1.168222851","rc":[{"batb":[[0,1.6,69.74],[1,1.53,36.98],[2,1.01,10.52]],"ltp":1.34,"tv":20.57,"id":9631075},{"batb":[[0,2.34,31.09],[1,2.2,21.32],[2,1.01,10.51]],"ltp":3.9,"tv":70.6,"id":11772759}]}]}
{"op":"mcm","clk":"1011275928","pt":1580655463949,"mc":[{"id":"1.168222851","rc":[{"batb":[[0,1.53,36.98],[1,1.01,10.52],[2,1.01,0]],"batl":[[0,2.1,363.33],[1,2.1,0]],"ltp":1.34,"tv":20.57,"id":9631075},{"batb":[[0,2.2,21.32],[1,1.01,10.51],[2,1.01,0]],"batl":[[0,3.3,191.91],[1,3.3,0]],"ltp":3.9,"tv":70.6,"id":11772759}]}]}
{"op":"mcm","clk":"1011277435","pt":1580655474466,"mc":[{"id":"1.168222851","rc":[{"batb":[[1,1.4,53.11],[2,1.01,10.52]],"ltp":1.34,"tv":20.57,"id":9631075},{"batb":[[0,2.72,11.96],[1,2.4,16.68],[2,2.2,21.32]],"ltp":3.9,"tv":70.6,"id":11772759}]}]}
{"op":"mcm","clk":"1011277515","pt":1580655475040,"mc":[{"id":"1.168222851","rc":[{"batb":[[0,1.53,115.96]],"batl":[[0,1.65,42.01]],"ltp":1.34,"tv":20.57,"id":9631075},{"batb":[[1,2.54,26.89],[2,2.4,16.68]],"batl":[[0,2.92,21.85]],"ltp":3.9,"tv":70.6,"id":11772759}]}]}
{"op":"mcm","clk":"1011277645","pt":1580655475946,"mc":[{"id":"1.168222851","rc":[{"batl":[[1,1.95,409.88]],"ltp":1.34,"tv":20.57,"id":9631075},{"batl":[[1,3.9,158.23]],"ltp":3.9,"tv":70.6,"id":11772759}]}]}
{"op":"mcm","clk":"1011279805","pt":1580655490917,"mc":[{"id":"1.168222851","rc":[{"batb":[[0,1.53,78.98],[1,1.4,52.95]],"ltp":1.34,"tv":20.57,"id":9631075},{"batb":[[0,2.54,26.89],[1,2.4,16.68],[2,1.01,10.51]],"ltp":3.9,"tv":70.6,"id":11772759}]}]}
{"op":"mcm","clk":"1011280001","pt":1580655492293,"mc":[{"id":"1.168222851","rc":[{"batb":[[0,1.4,52.95],[1,1.01,10.52],[2,1.01,0]],"batl":[[0,1.95,409.88],[1,1.95,0]],"ltp":1.34,"tv":20.57,"id":9631075},{"batb":[[0,2.4,16.68],[1,1.01,10.51],[2,1.01,0]],"batl":[[0,3.9,158.23],[1,3.9,0]],"ltp":3.9,"tv":70.6,"id":11772759}]}]}
{"op":"mcm","clk":"1011280976","pt":1580655498690,"mc":[{"id":"1.168222851","rc":[{"batb":[[0,1.65,27.85],[1,1.51,38.32],[2,1.4,52.95]],"ltp":1.34,"tv":20.57,"id":9631075},{"batb":[[1,2.18,21.95],[2,1.01,10.51]],"ltp":3.9,"tv":70.6,"id":11772759}]}]}
{"op":"mcm","clk":"1011281113","pt":1580655499588,"mc":[{"id":"1.168222851","rc":[{"batb":[[1,1.6,69.74],[2,1.51,38.32]],"batl":[[0,1.75,42.01]],"ltp":1.34,"tv":20.57,"id":9631075},{"batb":[[1,2.36,30.25],[2,2.18,21.95]],"batl":[[0,2.68,24.37]],"ltp":3.9,"tv":70.6,"id":11772759}]}]}
{"op":"mcm","clk":"1011281216","pt":1580655500288,"mc":[{"id":"1.168222851","rc":[{"batl":[[1,2.16,342.82]],"ltp":1.34,"tv":20.57,"id":9631075},{"batl":[[1,3.3,191.91]],"ltp":3.9,"tv":70.6,"id":11772759}]}]}
{"op":"mcm","clk":"1011283100","pt":1580655512693,"mc":[{"id":"1.168222851","rc":[{"batb":[[0,1.6,69.74],[1,1.51,38.32],[2,1.01,10.52]],"ltp":1.34,"tv":20.57,"id":9631075},{"batb":[[0,2.36,30.25],[1,2.18,21.95],[2,1.01,10.51]],"ltp":3.9,"tv":70.6,"id":11772759}]}]}
{"op":"mcm","clk":"1011283271","pt":1580655513911,"mc":[{"id":"1.168222851","rc":[{"batb":[[0,1.51,38.32],[1,1.01,10.52],[2,1.01,0]],"batl":[[0,2.16,342.82],[1,2.16,0]],"ltp":1.34,"tv":20.57,"id":9631075},{"batb":[[0,2.18,21.95],[1,1.01,10.51],[2,1.01,0]],"batl":[[0,3.3,191.91],[1,3.3,0]],"ltp":3.9,"tv":70.6,"id":11772759}]}]}
{"op":"mcm","clk":"1011285919","pt":1580655532129,"mc":[{"id":"1.168222851","rc":[{"batb":[[0,1.78,21.79],[1,1.66,27.07],[2,1.01,10.52]],"ltp":1.34,"tv":20.57,"id":9631075},{"batb":[[1,2.06,25.89],[2,1.01,10.51]],"ltp":3.9,"tv":70.6,"id":11772759}]}]}
{"op":"mcm","clk":"1011286120","pt":1580655533651,"mc":[{"id":"1.168222851","rc":[{"batb":[[1,1.66,90.08]],"batl":[[0,1.83,42.01],[1,2.16,342.82]],"ltp":1.34,"tv":20.57,"id":9631075},{"batb":[[0,2.2,34.45],[1,2.18,21.95],[2,2.06,25.89]],"batl":[[0,2.5,27.73],[1,3,213.44]],"ltp":3.9,"tv":70.6,"id":11772759}]}]}
{"op":"mcm","clk":"1011287884","pt":1580655544754,"mc":[{"id":"1.168222851","rc":[{"batb":[[0,1.66,90.08],[1,1.01,10.52],[2,1.01,0]],"ltp":1.34,"tv":20.57,"id":9631075},{"batb":[[1,2.06,25.89],[2,1.01,10.51]],"ltp":3.9,"tv":70.6,"id":11772759}]}]}
{"op":"mcm","clk":"1011288202","pt":1580655546752,"mc":[{"id":"1.168222851","rc":[{"batb":[[0,1.66,27.07]],"batl":[[0,2.16,342.82],[1,2.16,0]],"ltp":1.34,"tv":20.57,"id":9631075},{"batb":[[0,2.06,25.89],[1,1.01,10.51],[2,1.01,0]],"batl":[[0,3,213.44],[1,3,0]],"ltp":3.9,"tv":70.6,"id":11772759}]}]}
{"op":"mcm","clk":"1011289846","pt":1580655556587,"mc":[{"id":"1.168222851","rc":[{"batb":[[1,1.5,39.5],[2,1.01,10.52]],"ltp":1.34,"tv":20.57,"id":9631075},{"batb":[[0,2.36,17.31],[1,2.12,23.53],[2,2.06,25.89]],"ltp":3.9,"tv":70.6,"id":11772759}]}]}
{"op":"mcm","clk":"1011289977","pt":1580655557408,"mc":[{"id":"1.168222851","rc":[{"batb":[[1,1.61,68.06],[2,1.5,39.5]],"batl":[[0,1.76,42.01],[1,2.16,342.82]],"ltp":1.34,"tv":20.57,"id":9631075},{"batb":[[1,2.32,31.09],[2,2.12,23.53]],"batl":[[0,2.66,25.21],[1,3,213.44]],"ltp":3.9,"tv":70.6,"id":11772759}]}]}
{"op":"mcm","clk":"1011292523","pt":1580655572667,"mc":[{"id":"1.168222851","rc":[{"batb":[[0,1.61,68.06],[1,1.5,39.5],[2,1.01,10.52]],"ltp":1.34,"tv":20.57,"id":9631075},{"batb":[[0,2.32,31.09],[1,2.12,23.53],[2,1.01,10.51]],"ltp":3.9,"tv":70.6,"id":11772759}]}]}
{"op":"mcm","clk":"1011292722","pt":1580655573998,"mc":[{"id":"1.168222851","rc":[{"batb":[[0,1.5,39.5],[1,1.01,10.52],[2,1.01,0]],"batl":[[0,2.16,342.82],[1,2.16,0]],"ltp":1.34,"tv":20.57,"id":9631075},{"batb":[[0,2.12,23.53],[1,1.01,10.51],[2,1.01,0]],"batl":[[0,3,213.44],[1,3,0]],"ltp":3.9,"tv":70.6,"id":11772759}]}]}
{"op":"mcm","clk":"1011293441","pt":1580655578721,"mc":[{"id":"1.168222851","rc":[{"batb":[[0,1.81,20.38],[1,1.7,24.94],[2,1.5,39.5]],"ltp":1.34,"tv":20.57,"id":9631075},{"batb":[[1,1.88,17.07],[2,1.01,10.51]],"ltp":3.9,"tv":70.6,"id":11772759}]}]}
{"op":"mcm","clk":"1011293471","pt":1580655578885,"mc":[{"id":"1.168222851","rc":[{"batb":[[2,1.69,60.49]],"batl":[[0,1.87,42.01],[1,2.16,342.82]],"ltp":1.34,"tv":20.57,"id":9631075},{"batb":[[0,2.16,36.13],[1,2.12,23.53],[2,1.88,17.07]],"batl":[[0,2.44,28.57],[1,3,213.44]],"ltp":3.9,"tv":70.6,"id":11772759}]}]}
{"op":"mcm","clk":"1011295377","pt":1580655590536,"mc":[{"id":"1.168222851","rc":[{"batb":[[1,1.77,170.06],[2,1.75,192.43]],"batl":[[0,1.85,171.08],[1,1.87,199.17],[2,2.16,342.82]],"ltp":1.34,"tv":20.57,"id":9631075}]}]}
{"op":"mcm","clk":"1011297115","pt":1580655600732,"mc":[{"id":"1.168222851","rc":[{"trd":[[1.81,40.76]],"batb":[[0,1.77,170.06],[1,1.75,192.43],[2,1.7,24.94]],"batl":[[0,1.81,358.24],[1,1.85,171.08],[2,1.87,199.17]],"ltp":1.81,"tv":61.33,"id":9631075}],"tv":131.93}]}
{"op":"mcm","clk":"1011298890","pt":1580655609478,"mc":[{"id":"1.168222851","rc":[{"batb":[[0,1.8,20.85],[1,1.77,170.06],[2,1.75,192.43]],"ltp":1.81,"tv":61.33,"id":9631075},{"batb":[[1,2.14,23.05],[2,1.89,16.68]],"ltp":3.9,"tv":70.6,"id":11772759}]}]}
{"op":"mcm","clk":"1011302411","pt":1580655630502,"mc":[{"id":"1.168222851","rc":[{"batl":[[0,1.85,171.08],[1,1.87,199.17],[2,2.16,342.82]],"ltp":1.81,"tv":61.33,"id":9631075}]}]}
{"op":"mcm","clk":"1011304560","pt":1580655643627,"mc":[{"id":"1.168222851","rc":[{"trd":[[1.8,41.7]],"batb":[[0,1.77,170.06],[1,1.75,192.43],[2,1.69,85.91]],"batl":[[0,1.8,282.05],[1,1.85,171.08],[2,1.87,199.17]],"ltp":1.8,"tv":103.02,"id":9631075}],"tv":173.63}]}
{"op":"mcm","clk":"1011305997","pt":1580655651507,"mc":[{"id":"1.168222851","rc":[{"batl":[[0,1.85,171.08],[1,1.87,199.17],[2,2.16,342.82]],"ltp":1.8,"tv":103.02,"id":9631075}]}]}
{"op":"mcm","clk":"1011311536","pt":1580655682564,"mc":[{"id":"1.168222851","rc":[{"batb":[[0,1.69,85.91],[1,1.01,10.52],[2,1.69,0]],"batl":[[0,1.87,42.01],[1,2.16,342.82],[2,2.16,0]],"ltp":1.8,"tv":103.02,"id":9631075}]}]}
{"op":"mcm","clk":"1011311689","pt":1580655683385,"mc":[{"id":"1.168222851","rc":[{"batb":[[1,1.89,16.68],[2,1.01,10.51]],"ltp":3.9,"tv":70.6,"id":11772759}]}]}
{"op":"mcm","clk":"1011311818","pt":1580655683983,"mc":[{"id":"1.168222851","rc":[{"batb":[[0,1.69,25.41]],"batl":[[0,2.16,342.82],[1,2.16,0]],"ltp":1.8,"tv":103.02,"id":9631075},{"batb":[[0,1.89,16.68],[1,1.01,10.51],[2,1.01,0]],"batl":[[0,3,213.44],[1,3,0]],"ltp":3.9,"tv":70.6,"id":11772759}]}]}
{"op":"mcm","clk":"1011312110","pt":1580655685481,"mc":[{"id":"1.168222851","rc":[{"batb":[[1,1.68,116.72],[2,1.66,231.1]],"batl":[[0,2.08,138.73],[1,2.1,110.9],[2,2.16,342.82]],"ltp":1.8,"tv":103.02,"id":9631075}]}]}
{"op":"mcm","clk":"1011312335","pt":1580655686558,"mc":[{"id":"1.168222851","rc":[{"batb":[[0,1.68,25.89],[1,1.01,10.52],[2,1.66,0]],"batl":[[0,2.16,342.82],[1,2.1,0],[2,2.16,0]],"ltp":1.8,"tv":103.02,"id":9631075},{"batb":[[0,1.91,16.37]],"ltp":3.9,"tv":70.6,"id":11772759}]}]}
{"op":"mcm","clk":"1011312886","pt":1580655689629,"mc":[{"id":"1.168222851","rc":[{"batb":[[0,1.81,150.7],[1,1.79,178.3],[2,1.68,25.89]],"batl":[[0,1.89,150.74],[1,1.91,147.18],[2,2.16,342.82]],"ltp":1.8,"tv":103.02,"id":9631075}]}]}
{"op":"mcm","clk":"1011313892","pt":1580655694515,"mc":[{"id":"1.168222851","rc":[{"batb":[[0,1.68,25.89],[1,1.01,10.52],[2,1.68,0]],"batl":[[0,2.16,342.82],[1,1.91,0],[2,2.16,0]],"ltp":1.8,"tv":103.02,"id":9631075}]}]}
{"op":"mcm","clk":"1011314473","pt":1580655697704,"mc":[{"id":"1.168222851","rc":[{"batb":[[0,1.68,142.61],[1,1.66,231.1],[2,1.01,10.52]],"batl":[[0,2.08,138.73],[1,2.1,110.9],[2,2.16,342.82]],"ltp":1.8,"tv":103.02,"id":9631075}]}]}
{"op":"mcm","clk":"1011316318","pt":1580655707514,"mc":[{"id":"1.168222851","rc":[{"batl":[[0,2.16,342.82],[1,2.1,0],[2,2.16,0]],"ltp":1.8,"tv":103.02,"id":9631075}]}]}
{"op":"mcm","clk":"1011316849","pt":1580655710609,"mc":[{"id":"1.168222851","rc":[{"batb":[[2,1.59,30.92]],"batl":[[0,1.74,138.57],[1,1.76,191.08],[2,2.16,342.82]],"ltp":1.8,"tv":103.02,"id":9631075},{"batb":[[0,2.32,18.18],[1,2.08,25.26],[2,1.91,16.37]],"ltp":3.9,"tv":70.6,"id":11772759}]}]}
{"op":"mcm","clk":"1011317056","pt":1580655711731,"mc":[{"id":"1.168222851","rc":[{"batb":[[2,1.63,66.38]],"batl":[[2,1.79,42.01]],"ltp":1.8,"tv":103.02,"id":9631075},{"batb":[[1,2.28,32.77],[2,2.08,25.26]],"batl":[[0,2.6,26.05],[1,3,213.44]],"ltp":3.9,"tv":70.6,"id":11772759}]}]}
{"op":"mcm","clk":"1011321098","pt":1580655733353,"mc":[{"id":"1.168222851","rc":[{"batb":[[0,1.63,66.38],[1,1.59,30.92],[2,1.01,10.52]],"batl":[[0,1.79,42.01],[1,2.16,342.82],[2,1.79,0]],"ltp":1.8,"tv":103.02,"id":9631075},{"batb":[[0,2.28,32.77],[1,2.08,25.26],[2,1.01,10.51]],"ltp":3.9,"tv":70.6,"id":11772759}]}]}
{"op":"mcm","clk":"1011321235","pt":1580655734054,"mc":[{"id":"1.168222851","rc":[{"batb":[[0,1.59,30.92],[1,1.01,10.52],[2,1.01,0]],"batl":[[0,2.16,342.82],[1,2.16,0]],"ltp":1.8,"tv":103.02,"id":9631075},{"batb":[[0,2.08,25.26],[1,1.01,10.51],[2,1.01,0]],"batl":[[0,3,213.44],[1,3,0]],"ltp":3.9,"tv":70.6,"id":11772759}]}]}
{"op":"mcm","clk":"1011321732","pt":1580655736571,"mc":[{"id":"1.168222851","rc":[{"batb":[[0,1.61,162.6],[1,1.6,133.18],[2,1.59,30.92]],"batl":[[0,1.9,157.88],[1,1.92,144.84],[2,2.16,342.82]],"ltp":1.8,"tv":103.02,"id":9631075}]}]}
{"op":"mcm","clk":"1011324433","pt":1580655751668,"mc":[{"id":"1.168222851","rc":[{"batb":[[0,1.59,30.92],[1,1.01,10.52],[2,1.59,0]],"ltp":1.8,"tv":103.02,"id":9631075}]}]}
{"op":"mcm","clk":"1011324978","pt":1580655754569,"mc":[{"id":"1.168222851","rc":[{"batb":[[0,1.82,133.82],[1,1.8,175.03],[2,1.59,30.92]],"ltp":1.8,"tv":103.02,"id":9631075}]}]}
{"op":"mcm","clk":"1011325190","pt":1580655755684,"mc":[{"id":"1.168222851","rc":[{"batb":[[0,1.84,19.12],[1,1.82,133.82],[2,1.8,175.03]],"batl":[[0,1.9,199.89]],"ltp":1.8,"tv":103.02,"id":9631075},{"batb":[[0,2.1,37.81],[1,2.08,25.26],[2,1.8,19.43]],"batl":[[0,2.38,30.25],[1,3,213.44]],"ltp":3.9,"tv":70.6,"id":11772759}]}]}
{"op":"mcm","clk":"1011327903","pt":1580655768507,"mc":[{"id":"1.168222851","rc":[{"trd":[[1.84,38.24]],"batb":[[0,1.82,133.82],[1,1.8,175.03],[2,1.72,57.97]],"batl":[[0,1.84,283.77],[1,1.9,199.89],[2,1.92,144.84]],"ltp":1.84,"tv":141.26,"id":9631075}],"tv":211.87}]}
{"op":"mcm","clk":"1011329373","pt":1580655775530,"mc":[{"id":"1.168222851","rc":[{"batl":[[0,1.9,199.89],[1,1.92,144.84],[2,2.16,342.82]],"ltp":1.84,"tv":141.26,"id":9631075}]}]}
{"op":"mcm","clk":"1011330794","pt":1580655782619,"mc":[{"id":"1.168222851","rc":[{"batb":[[0,1.7,24.71],[1,1.01,10.52],[2,1.72,0]],"batl":[[0,2.16,342.82],[1,1.92,0],[2,2.16,0]],"ltp":1.84,"tv":141.26,"id":9631075},{"batb":[[0,1.8,19.43],[1,1.01,10.51],[2,1.8,0]],"batl":[[0,3,213.44],[1,3,0]],"ltp":3.9,"tv":70.6,"id":11772759}]}]}
{"op":"mcm","clk":"1011331388","pt":1580655785425,"mc":[{"id":"1.168222851","rc":[{"batb":[[0,1.69,176.82],[1,1.68,25.1],[2,1.67,226.53]],"batl":[[1,2.22,162.06],[2,2.24,92.36]],"ltp":1.84,"tv":141.26,"id":9631075},{"batb":[[0,1.82,19.12]],"ltp":3.9,"tv":70.6,"id":11772759}]}]}
{"op":"mcm","clk":"1011332090","pt":1580655788644,"mc":[{"id":"1.168222851","rc":[{"batl":[[1,2.22,0],[2,2.24,0]],"ltp":1.84,"tv":141.26,"id":9631075}]}]}
{"op":"mcm","clk":"1011332765","pt":1580655791644,"mc":[{"id":"1.168222851","rc":[{"batl":[[0,1.76,166.14],[1,1.78,184.07],[2,2.16,342.82]],"ltp":1.84,"tv":141.26,"id":9631075}]}]}
{"op":"mcm","clk":"1011332958","pt":1580655792541,"mc":[{"id":"1.168222851","rc":[{"batb":[[0,2.3,18.8],[1,2.02,27.3],[2,1.01,10.51]],"ltp":3.9,"tv":70.6,"id":11772759}]}]}
{"op":"mcm","clk":"1011333063","pt":1580655793058,"mc":[{"id":"1.168222851","rc":[{"batl":[[2,1.8,42.01]],"ltp":1.84,"tv":141.26,"id":9631075},{"batb":[[1,2.26,32.77],[2,2.02,27.3]],"batl":[[0,2.56,26.89],[1,3,213.44]],"ltp":3.9,"tv":70.6,"id":11772759}]}]}
{"op":"mcm","clk":"1011337254","pt":1580655813691,"mc":[{"id":"1.168222851","rc":[{"batb":[[0,1.68,25.1],[1,1.65,63.85],[2,1.58,30.92]],"batl":[[0,1.8,42.01],[1,2.16,342.82],[2,1.8,0]],"ltp":1.84,"tv":141.26,"id":9631075}]}]}
{"op":"mcm","clk":"1011337435","pt":1580655814560,"mc":[{"id":"1.168222851","rc":[{"batb":[[0,1.58,30.92],[1,1.01,10.52],[2,1.58,0]],"batl":[[0,2.16,342.82],[1,2.16,0]],"ltp":1.84,"tv":141.26,"id":9631075},{"batb":[[0,2.02,27.3],[1,1.01,10.51],[2,2.02,0]],"batl":[[0,3,213.44],[1,3,0]],"ltp":3.9,"tv":70.6,"id":11772759}]}]}
{"op":"mcm","clk":"1011337809","pt":1580655816393,"mc":[{"id":"1.168222851","rc":[{"batb":[[0,1.61,163.69],[1,1.6,133.23],[2,1.58,30.92]],"batl":[[0,1.95,119.09],[1,1.97,133.97],[2,2.16,342.82]],"ltp":1.84,"tv":141.26,"id":9631075}]}]}
{"op":"mcm","clk":"1011337930","pt":1580655817000,"mc":[{"id":"1.168222851","rc":[{"batb":[[0,1.58,30.92],[1,1.01,10.52],[2,1.58,0]],"batl":[[0,2.16,342.82],[1,1.97,0],[2,2.16,0]],"ltp":1.84,"tv":141.26,"id":9631075}]}]}
{"op":"mcm","clk":"1011338657","pt":1580655820614,"mc":[{"id":"1.168222851","rc":[{"batb":[[0,1.72,198.18],[1,1.7,212.8],[2,1.58,30.92]],"batl":[[0,1.79,112.66],[1,1.81,174.51],[2,2.16,342.82]],"ltp":1.84,"tv":141.26,"id":9631075}]}]}
{"op":"mcm","clk":"1011339293","pt":1580655823693,"mc":[{"id":"1.168222851","rc":[{"batb":[[0,1.58,30.92],[1,1.01,10.52],[2,1.58,0]],"batl":[[0,2.16,342.82],[1,1.81,0],[2,2.16,0]],"ltp":1.84,"tv":141.26,"id":9631075}]}]}
{"op":"mcm","clk":"1011339931","pt":1580655826699,"mc":[{"id":"1.168222851","rc":[{"batb":[[0,1.61,163.69],[1,1.6,133.23],[2,1.58,30.92]],"batl":[[0,1.95,119.09],[1,1.97,133.97],[2,2.16,342.82]],"ltp":1.84,"tv":141.26,"id":9631075}]}]}
{"op":"mcm","clk":"1011341563","pt":1580655834534,"mc":[{"id":"1.168222851","rc":[{"batb":[[0,1.58,30.92],[1,1.01,10.52],[2,1.58,0]],"ltp":1.84,"tv":141.26,"id":9631075}]}]}
{"op":"mcm","clk":"1011341960","pt":1580655836434,"mc":[{"id":"1.168222851","rc":[{"batl":[[2,2.16,0]],"ltp":1.84,"tv":141.26,"id":9631075}]}]}
{"op":"mcm","clk":"1011342263","pt":1580655837689,"mc":[{"id":"1.168222851","rc":[{"batb":[[0,1.87,131.48],[1,1.85,160.03],[2,1.58,30.92]],"ltp":1.84,"tv":141.26,"id":9631075}]}]}
{"op":"mcm","clk":"1011342456","pt":1580655838615,"mc":[{"id":"1.168222851","rc":[{"batb":[[1,1.86,17.7],[2,1.85,160.03]],"ltp":1.84,"tv":141.26,"id":9631075},{"batb":[[1,1.7,24.08],[2,1.01,10.51]],"ltp":3.9,"tv":70.6,"id":11772759}]}]}
{"op":"mcm","clk":"1011342556","pt":1580655839101,"mc":[{"id":"1.168222851","rc":[{"batl":[[0,1.95,161.1]],"ltp":1.84,"tv":141.26,"id":9631075},{"batb":[[0,2.04,40.33],[1,2.02,27.3],[2,1.7,24.08]],"batl":[[0,2.3,31.93]],"ltp":3.9,"tv":70.6,"id":11772759}]}]}
{"op":"mcm","clk":"1011342842","pt":1580655840510,"mc":[{"id":"1.168222851","rc":[{"batl":[[2,2.42,286.54]],"ltp":1.84,"tv":141.26,"id":9631075},{"batl":[[1,2.82,231.26]],"ltp":3.9,"tv":70.6,"id":11772759}]}]}
{"op":"mcm","clk":"1011347146","pt":1580655860662,"mc":[{"id":"1.168222851","rc":[{"batb":[[0,1.86,17.7],[1,1.77,53.77],[2,1.68,25.02]],"batl":[[0,1.95,42.01],[1,2.42,286.54],[2,2.42,0]],"ltp":1.84,"tv":141.26,"id":9631075}]}]}
{"op":"mcm","clk":"1011347263","pt":1580655861145,"mc":[{"id":"1.168222851","rc":[{"batb":[[0,1.77,53.77],[1,1.68,25.02],[2,1.01,10.52]],"ltp":1.84,"tv":141.26,"id":9631075},{"batb":[[1,1.7,24.08],[2,1.01,10.51]],"ltp":3.9,"tv":70.6,"id":11772759}]}]}
{"op":"mcm","clk":"1011347482","pt":1580655862165,"mc":[{"id":"1.168222851","rc":[{"batb":[[0,1.68,25.02],[1,1.01,10.52],[2,1.01,0]],"batl":[[0,2.42,286.54],[1,2.42,0]],"ltp":1.84,"tv":141.26,"id":9631075},{"batb":[[0,1.7,24.08],[1,1.01,10.51],[2,1.01,0]],"batl":[[0,2.82,231.26],[1,2.82,0]],"ltp":3.9,"tv":70.6,"id":11772759}]}]}
{"op":"mcm","clk":"1011347780","pt":1580655863456,"mc":[{"id":"1.168222851","rc":[{"batb":[[0,1.69,139.81],[1,1.68,25.02],[2,1.67,226.41]],"batl":[[1,2.44,95.62],[2,2.48,140.9]],"ltp":1.84,"tv":141.26,"id":9631075}]}]}
{"op":"mcm","clk":"1011350091","pt":1580655874066,"mc":[{"id":"1.168222851","rc":[{"batb":[[0,1.68,25.02],[1,1.01,10.52],[2,1.67,0]],"batl":[[1,2.44,0],[2,2.48,0]],"ltp":1.84,"tv":141.26,"id":9631075}]}]}
{"op":"mcm","clk":"1011354376","pt":1580655892706,"mc":[{"id":"1.168222851","rc":[{"batb":[[0,1.69,139.81],[1,1.68,25.02],[2,1.67,226.41]],"batl":[[0,1.76,201.31],[1,1.78,183.99]],"ltp":1.84,"tv":141.26,"id":9631075}]}]}
{"op":"mcm","clk":"1011354588","pt":1580655893645,"mc":[{"id":"1.168222851","rc":[{"batl":[[2,1.79,42.01]],"ltp":1.84,"tv":141.26,"id":9631075},{"batb":[[0,2.3,18.88],[1,2.26,32.77],[2,1.98,29.35]],"batl":[[0,2.58,26.05]],"ltp":3.9,"tv":70.6,"id":11772759}]}]}
{"op":"mcm","clk":"1011355110","pt":1580655895943,"mc":[{"id":"1.168222851","rc":[{"batl":[[1,3.15,200.41]],"ltp":3.9,"tv":70.6,"id":11772759}]}]}
{"op":"mcm","clk":"1011356648","pt":1580655902753,"mc":[{"id":"1.168222851","rc":[{"batb":[[0,1.68,25.02],[1,1.64,65.54],[2,1.57,31.63]],"batl":[[0,1.79,42.01],[1,2.22,329.03],[2,1.79,0]],"ltp":1.84,"tv":141.26,"id":9631075}]}]}
{"op":"mcm","clk":"1011356664","pt":1580655902860,"mc":[{"id":"1.168222851","rc":[{"batb":[[0,1.64,65.54],[1,1.57,31.63],[2,1.01,10.52]],"ltp":1.84,"tv":141.26,"id":9631075},{"batb":[[0,2.26,32.77],[1,1.98,29.19],[2,1.01,10.51]],"ltp":3.9,"tv":70.6,"id":11772759}]}]}
{"op":"mcm","clk":"1011357008","pt":1580655904221,"mc":[{"id":"1.168222851","rc":[{"batb":[[0,1.57,31.63],[1,1.01,10.52],[2,1.01,0]],"batl":[[0,2.22,329.03],[1,2.22,0]],"ltp":1.84,"tv":141.26,"id":9631075},{"batb":[[0,1.98,29.19],[1,1.01,10.51],[2,1.01,0]],"batl":[[0,3.15,200.41],[1,3.15,0]],"ltp":3.9,"tv":70.6,"id":11772759}]}]}
{"op":"mcm","clk":"1011357290","pt":1580655905423,"mc":[{"id":"1.168222851","rc":[{"batb":[[0,1.59,252.85],[1,1.58,140.07],[2,1.57,31.63]],"batl":[[0,1.98,152.81],[1,2,128.05],[2,2.22,329.03]],"ltp":1.84,"tv":141.26,"id":9631075}]}]}
{"op":"mcm","clk":"1011359253","pt":1580655914340,"mc":[{"id":"1.168222851","rc":[{"batl":[[0,2.22,329.03],[1,2,0],[2,2.22,0]],"ltp":1.84,"tv":141.26,"id":9631075}]}]}
{"op":"mcm","clk":"1011359999","pt":1580655917691,"mc":[{"id":"1.168222851","rc":[{"batl":[[0,1.65,119.13],[1,1.66,116]],"ltp":1.84,"tv":141.26,"id":9631075},{"batb":[[0,2.56,14.4],[1,2.3,18.96],[2,1.98,29.19]],"ltp":3.9,"tv":70.6,"id":11772759}]}]}
{"op":"mcm","clk":"1011360058","pt":1580655917971,"mc":[{"id":"1.168222851","rc":[{"batb":[[2,1.01,10.51]],"ltp":3.9,"tv":70.6,"id":11772759}]}]}
{"op":"mcm","clk":"1011360423","pt":1580655919199,"mc":[{"id":"1.168222851","rc":[{"batl":[[2,1.71,42.01]],"ltp":1.84,"tv":141.26,"id":9631075},{"batb":[[1,2.42,29.41],[2,2.3,18.96]],"batl":[[0,2.78,23.53],[1,3.15,200.41]],"ltp":3.9,"tv":70.6,"id":11772759}]}]}
{"op":"mcm","clk":"1011362512","pt":1580655928598,"mc":[{"id":"1.168222851","rc":[{"trd":[[2.56,44.65]],"batb":[[0,2.56,6]],"ltp":2.56,"tv":87.4,"id":11772759}],"tv":228.67}]}
{"op":"mcm","clk":"1011363439","pt":1580655932696,"mc":[{"id":"1.168222851","rc":[{"trd":[[1.65,132.04]],"batl":[[0,1.65,53.11]],"ltp":1.65,"tv":273.3,"id":9631075}],"tv":360.71}]}
{"op":"mcm","clk":"1011363668","pt":1580655933593,"mc":[{"id":"1.168222851","rc":[{"batb":[[0,1.59,136.27],[1,1.57,31.63],[2,1.56,74.78]],"batl":[[0,1.66,116],[1,1.71,42.01],[2,2.1,363.33]],"ltp":1.65,"tv":273.3,"id":9631075}]}]}
{"op":"mcm","clk":"1011364231","pt":1580655935990,"mc":[{"id":"1.168222851","rc":[{"batb":[[0,1.6,140.79],[1,1.59,136.27],[2,1.57,31.63]],"batl":[[0,1.66,210.37],[1,1.68,223.18],[2,1.71,42.01]],"ltp":1.65,"tv":273.3,"id":9631075}]}]}
{"op":"mcm","clk":"1011365715","pt":1580655942727,"mc":[{"id":"1.168222851","rc":[{"batb":[[0,1.43,45.16],[1,1.01,10.52],[2,1.57,0]],"batl":[[0,2.1,363.33],[1,1.68,0],[2,1.71,0]],"ltp":1.65,"tv":273.3,"id":9631075},{"batb":[[0,2.3,18.96],[1,1.01,10.51],[2,2.3,0]],"batl":[[0,3.15,200.41],[1,3.15,0]],"ltp":2.56,"tv":87.4,"id":11772759}]}]}
{"op":"mcm","clk":"1011366300","pt":1580655945305,"mc":[{"id":"1.168222851","rc":[{"batb":[[0,1.46,242.99],[1,1.45,197.95],[2,1.44,44.61]],"batl":[[0,1.77,122.53],[1,1.79,180.79],[2,2.1,363.33]],"ltp":1.65,"tv":273.3,"id":9631075},{"batb":[[0,2.28,19.28]],"ltp":2.56,"tv":87.4,"id":11772759}]}]}
{"op":"mcm","clk":"1011367188","pt":1580655949720,"mc":[{"id":"1.168222851","rc":[{"batl":[[0,2.1,363.33],[1,1.79,0],[2,2.1,0]],"ltp":1.65,"tv":273.3,"id":9631075}]}]}
{"op":"mcm","clk":"1011367899","pt":1580655952587,"mc":[{"id":"1.168222851","rc":[{"batl":[[0,1.51,215.24],[1,1.52,159.88]],"ltp":1.65,"tv":273.3,"id":9631075}]}]}
{"op":"mcm","clk":"1011368131","pt":1580655953603,"mc":[{"id":"1.168222851","rc":[{"batb":[[0,1.46,333.73]],"ltp":1.65,"tv":273.3,"id":9631075},{"batb":[[0,2.96,24],[1,2.58,13.69],[2,1.01,10.51]],"batl":[[0,3.15,19.32]],"ltp":2.56,"tv":87.4,"id":11772759}]}]}
{"op":"mcm","clk":"1011368646","pt":1580655956147,"mc":[{"id":"1.168222851","rc":[{"batl":[[2,1.89,435.3]],"ltp":1.65,"tv":273.3,"id":9631075},{"batl":[[1,4.2,148.02]],"ltp":2.56,"tv":87.4,"id":11772759}]}]}
{"op":"mcm","clk":"1011370486","pt":1580655963989,"mc":[{"id":"1.168222851","rc":[{"trd":[[1.51,0.86]],"batl":[[0,1.51,214.81]],"ltp":1.51,"tv":274.16,"id":9631075}],"tv":361.57}]}
{"op":"mcm","clk":"1011371495","pt":1580655968569,"mc":[{"id":"1.168222851","rc":[{"batb":[[0,1.46,90.74],[1,1.44,44.61],[2,1.32,67.84]],"batl":[[0,1.89,435.3],[1,1.52,0],[2,1.89,0]],"ltp":1.51,"tv":274.16,"id":9631075}]}]}
{"op":"mcm","clk":"1011371721","pt":1580655969685,"mc":[{"id":"1.168222851","rc":[{"batb":[[1,1.32,67.52],[2,1.01,10.51]],"ltp":1.51,"tv":274.16,"id":9631075},{"batb":[[0,2.58,13.69],[1,1.01,10.51],[2,1.01,0]],"ltp":2.56,"tv":87.4,"id":11772759}]}]}
{"op":"mcm","clk":"1011371906","pt":1580655970474,"mc":[{"id":"1.168222851","rc":[{"batb":[[0,1.32,67.52],[1,1.01,10.51],[2,1.01,0]],"ltp":1.51,"tv":274.16,"id":9631075},{"batl":[[0,4.2,148.02],[1,4.2,0]],"ltp":2.56,"tv":87.4,"id":11772759}]}]}
{"op":"mcm","clk":"1011372697","pt":1580655973682,"mc":[{"id":"1.168222851","rc":[{"batb":[[0,1.43,263.52],[1,1.42,217.14],[2,1.32,67.52]],"batl":[[0,1.48,221.87],[1,1.49,172.66],[2,1.89,435.3]],"ltp":1.51,"tv":274.16,"id":9631075}]}]}
{"op":"mcm","clk":"1011373338","pt":1580655976487,"mc":[{"id":"1.168222851","rc":[{"batb":[[0,1.43,306.83]],"ltp":1.51,"tv":274.16,"id":9631075}]}]}
{"op":"mcm","clk":"1011373864","pt":1580655978701,"mc":[{"id":"1.168222851","rc":[{"batb":[[0,1.32,67.52],[1,1.01,10.51],[2,1.32,0]],"batl":[[0,1.89,435.3],[1,1.49,0],[2,1.89,0]],"ltp":1.51,"tv":274.16,"id":9631075}]}]}
{"op":"mcm","clk":"1011374558","pt":1580655981666,"mc":[{"id":"1.168222851","rc":[{"batb":[[0,1.33,182.81],[1,1.32,374.15],[2,1.01,10.51]],"batl":[[0,1.64,226.64],[1,1.65,117.8],[2,1.89,435.3]],"ltp":1.51,"tv":274.16,"id":9631075}]}]}
{"op":"mcm","clk":"1011379100","pt":1580656001747,"mc":[{"id":"1.168222851","rc":[{"batb":[[0,1.32,67.52],[1,1.01,10.51],[2,1.01,0]],"batl":[[0,1.89,435.3],[1,1.65,0],[2,1.89,0]],"ltp":1.51,"tv":274.16,"id":9631075}]}]}
{"op":"mcm","clk":"1011380949","pt":1580656009638,"mc":[{"id":"1.168222851","rc":[{"trd":[[1.58,124.82]],"batb":[[0,1.57,142.74],[1,1.56,32.89],[2,1.4,50.12]],"batl":[[0,1.64,120.79]],"ltp":1.58,"tv":398.98,"id":9631075},{"trd":[[2.74,23.53]],"batb":[[1,2.26,19.51],[2,1.01,10.51]],"ltp":2.74,"tv":110.93,"id":11772759}],"tv":509.91}]}
{"op":"mcm","clk":"1011381417","pt":1580656011452,"mc":[{"id":"1.168222851","rc":[{"batb":[[0,1.4,50.12],[1,1.01,10.52],[2,1.4,0]],"ltp":1.58,"tv":398.98,"id":9631075},{"batb":[[0,2.26,19.51],[1,1.01,10.51],[2,1.01,0]],"ltp":2.74,"tv":110.93,"id":11772759}]}]}
{"op":"mcm","clk":"1011381717","pt":1580656012747,"mc":[{"id":"1.168222851","rc":[{"batl":[[0,1.7,42.01],[1,2.04,383.03]],"ltp":1.58,"tv":398.98,"id":9631075},{"batl":[[0,3.65,170.4]],"ltp":2.74,"tv":110.93,"id":11772759}]}]}
{"op":"mcm","clk":"1011381833","pt":1580656013246,"mc":[{"id":"1.168222851","rc":[{"batl":[[0,2.04,383.03],[1,2.04,0]],"ltp":1.58,"tv":398.98,"id":9631075}]}]}
{"op":"mcm","clk":"1011382844","pt":1580656017465,"mc":[{"id":"1.168222851","rc":[{"batb":[[0,1.54,198.96],[1,1.53,158.26],[2,1.4,50.12]],"batl":[[0,1.6,247.89],[1,1.61,128.65],[2,2.04,383.03]],"ltp":1.58,"tv":398.98,"id":9631075}]}]}
{"op":"mcm","clk":"1011383843","pt":1580656021508,"mc":[{"id":"1.168222851","rc":[{"batb":[[0,1.4,50.12],[1,1.01,10.52],[2,1.4,0]],"batl":[[0,2.04,383.03],[1,1.61,0],[2,2.04,0]],"ltp":1.58,"tv":398.98,"id":9631075}]}]}
{"op":"mcm","clk":"1011384596","pt":1580656024465,"mc":[{"id":"1.168222851","rc":[{"batb":[[0,1.42,191.34],[1,1.41,223.37],[2,1.4,50.12]],"batl":[[0,1.77,147.63],[1,1.79,180.61],[2,2.04,383.03]],"ltp":1.58,"tv":398.98,"id":9631075}]}]}
{"op":"mcm","clk":"1011389784","pt":1580656045611,"mc":[{"id":"1.168222851","rc":[{"batb":[[0,1.4,50.12],[1,1.01,10.52],[2,1.4,0]],"ltp":1.58,"tv":398.98,"id":9631075}]}]}
{"op":"mcm","clk":"1011390507","pt":1580656048622,"mc":[{"id":"1.168222851","rc":[{"batb":[[0,1.7,183.55],[1,1.68,221.58],[2,1.4,50.12]],"ltp":1.58,"tv":398.98,"id":9631075}]}]}
{"op":"mcm","clk":"1011390646","pt":1580656049219,"mc":[{"id":"1.168222851","rc":[{"batb":[[0,1.7,207.86],[1,1.68,282.91],[2,1.53,35.09]],"batl":[[2,1.81,42.01]],"ltp":1.58,"tv":398.98,"id":9631075},{"batb":[[1,2.24,33.61],[2,2.06,25.73]],"batl":[[0,2.46,28.57]],"ltp":2.74,"tv":110.93,"id":11772759}]}]}
{"op":"mcm","clk":"1011391028","pt":1580656050741,"mc":[{"id":"1.168222851","rc":[{"batl":[[1,3.15,200.41]],"ltp":2.74,"tv":110.93,"id":11772759}]}]}
{"op":"mcm","clk":"1011395192","pt":1580656067738,"mc":[{"id":"1.168222851","rc":[{"batb":[[0,1.68,61.33],[1,1.53,35.09],[2,1.01,10.52]],"batl":[[0,1.81,42.01],[1,2.04,383.03],[2,1.81,0]],"ltp":1.58,"tv":398.98,"id":9631075},{"batb":[[0,2.24,33.61],[1,2.06,25.73],[2,1.01,10.51]],"ltp":2.74,"tv":110.93,"id":11772759}]}]}
{"op":"mcm","clk":"1011395292","pt":1580656068121,"mc":[{"id":"1.168222851","rc":[{"batb":[[0,1.53,35.09],[1,1.01,10.52],[2,1.01,0]],"batl":[[0,2.04,383.03],[1,2.04,0]],"ltp":1.58,"tv":398.98,"id":9631075},{"batb":[[0,2.06,25.73],[1,1.01,10.51],[2,1.01,0]],"batl":[[0,3.15,200.41],[1,3.15,0]],"ltp":2.74,"tv":110.93,"id":11772759}]}]}
{"op":"mcm","clk":"1011396665","pt":1580656073511,"mc":[{"id":"1.168222851","rc":[{"batb":[[0,1.67,157.05],[1,1.66,116.29],[2,1.53,35.09]],"batl":[[0,1.74,208.15],[1,1.76,190.67],[2,2.04,383.03]],"ltp":1.58,"tv":398.98,"id":9631075}]}]}
{"op":"mcm","clk":"1011397424","pt":1580656076649,"mc":[{"id":"1.168222851","rc":[{"batb":[[0,1.53,35.09],[1,1.01,10.52],[2,1.53,0]],"batl":[[0,2.04,383.03],[1,1.76,0],[2,2.04,0]],"ltp":1.58,"tv":398.98,"id":9631075}]}]}
{"op":"mcm","clk":"1011397921","pt":1580656078640,"mc":[{"id":"1.168222851","rc":[{"batb":[[0,1.55,198.5],[1,1.54,154.23],[2,1.53,35.09]],"batl":[[0,1.9,146.17],[1,1.92,144.75],[2,2.04,383.03]],"ltp":1.58,"tv":398.98,"id":9631075}]}]}
{"op":"mcm","clk":"1011398921","pt":1580656082724,"mc":[{"id":"1.168222851","rc":[{"batb":[[0,1.53,35.09],[1,1.01,10.52],[2,1.53,0]],"ltp":1.58,"tv":398.98,"id":9631075}]}]}
{"op":"mcm","clk":"1011399367","pt":1580656084525,"mc":[{"id":"1.168222851","rc":[{"batl":[[2,2.04,0]],"ltp":1.58,"tv":398.98,"id":9631075}]}]}
{"op":"mcm","clk":"1011399654","pt":1580656085740,"mc":[{"id":"1.168222851","rc":[{"batb":[[0,1.82,145.67],[1,1.8,174.92],[2,1.53,35.09]],"ltp":1.58,"tv":398.98,"id":9631075}]}]}
{"op":"mcm","clk":"1011399856","pt":1580656086555,"mc":[{"id":"1.168222851","rc":[{"batb":[[0,1.84,18.8],[1,1.82,145.67],[2,1.8,174.92]],"ltp":1.58,"tv":398.98,"id":9631075},{"batb":[[1,1.95,30.45],[2,1.01,10.51]],"ltp":2.74,"tv":110.93,"id":11772759}]}]}
{"op":"mcm","clk":"1011400109","pt":1580656087595,"mc":[{"id":"1.168222851","rc":[{"batl":[[1,1.92,186.76]],"ltp":1.58,"tv":398.98,"id":9631075},{"batb":[[0,2.08,38.65],[1,2.06,25.73],[2,1.95,30.45]],"batl":[[0,2.3,31.93]],"ltp":2.74,"tv":110.93,"id":11772759}]}]}
{"op":"mcm","clk":"1011400229","pt":1580656088075,"mc":[{"id":"1.168222851","rc":[{"batl":[[2,2.36,299.19]],"ltp":1.58,"tv":398.98,"id":9631075},{"batl":[[1,2.92,221.25]],"ltp":2.74,"tv":110.93,"id":11772759}]}]}
{"op":"mcm","clk":"1011403246","pt":1580656100690,"mc":[{"id":"1.168222851","rc":[{"batb":[[0,1.77,53.77],[1,1.72,23.6],[2,1.01,10.52]],"batl":[[0,1.92,42.01],[1,2.36,299.19],[2,2.36,0]],"ltp":1.58,"tv":398.98,"id":9631075},{"batb":[[1,1.95,30.45],[2,1.01,10.51]],"ltp":2.74,"tv":110.93,"id":11772759}]}]}
{"op":"mcm","clk":"1011403629","pt":1580656102305,"mc":[{"id":"1.168222851","rc":[{"batb":[[0,1.72,23.6],[1,1.01,10.52],[2,1.01,0]],"batl":[[0,2.36,299.19],[1,2.36,0]],"ltp":1.58,"tv":398.98,"id":9631075},{"batb":[[0,1.95,30.45],[1,1.01,10.51],[2,1.01,0]],"batl":[[0,2.92,221.25],[1,2.92,0]],"ltp":2.74,"tv":110.93,"id":11772759}]}]}
{"op":"mcm","clk":"1011403969","pt":1580656103707,"mc":[{"id":"1.168222851","rc":[{"batb":[[0,1.72,178.38],[1,1.7,212.42],[2,1.01,10.52]],"batl":[[0,1.97,99.34],[1,1.99,129.87],[2,2.36,299.19]],"ltp":1.58,"tv":398.98,"id":9631075}]}]}
{"op":"mcm","clk":"1011404348","pt":1580656105433,"mc":[{"id":"1.168222851","rc":[{"batb":[[0,1.72,23.6],[1,1.01,10.52],[2,1.01,0]],"batl":[[0,2.36,299.19],[1,1.99,0],[2,2.36,0]],"ltp":1.58,"tv":398.98,"id":9631075}]}]}
{"op":"mcm","clk":"1011405175","pt":1580656108606,"mc":[{"id":"1.168222851","rc":[{"batb":[[0,1.8,138.86],[1,1.78,181.53],[2,1.72,23.6]],"batl":[[0,1.88,170.8],[1,1.9,149.46],[2,2.36,299.19]],"ltp":1.58,"tv":398.98,"id":9631075}]}]}
{"op":"mcm","clk":"1011405838","pt":1580656111524,"mc":[{"id":"1.168222851","rc":[{"batb":[[0,1.72,23.6],[1,1.01,10.52],[2,1.72,0]],"batl":[[0,2.36,299.19],[1,1.9,0],[2,2.36,0]],"ltp":1.58,"tv":398.98,"id":9631075}]}]}
{"op":"mcm","clk":"1011406599","pt":1580656114696,"mc":[{"id":"1.168222851","rc":[{"batb":[[0,1.72,178.38],[1,1.7,212.42],[2,1.01,10.52]],"batl":[[0,1.97,99.34],[1,1.99,129.87],[2,2.36,299.19]],"ltp":1.58,"tv":398.98,"id":9631075}]}]}
{"op":"mcm","clk":"1011406997","pt":1580656116336,"mc":[{"id":"1.168222851","rc":[{"batl":[[0,2.36,299.19],[1,1.99,0],[2,2.36,0]],"ltp":1.58,"tv":398.98,"id":9631075}]}]}
{"op":"mcm","clk":"1011407794","pt":1580656119749,"mc":[{"id":"1.168222851","rc":[{"batl":[[0,1.79,153.14],[1,1.81,174.2]],"ltp":1.58,"tv":398.98,"id":9631075}]}]}
{"op":"mcm","clk":"1011407864","pt":1580656120019,"mc":[{"id":"1.168222851","rc":[{"batb":[[2,1.52,36.12]],"ltp":1.58,"tv":398.98,"id":9631075},{"batb":[[0,2.24,20.14],[1,2,27.85],[2,1.01,10.51]],"ltp":2.74,"tv":110.93,"id":11772759}]}]}
{"op":"mcm","clk":"1011408246","pt":1580656121515,"mc":[{"id":"1.168222851","rc":[{"batb":[[1,1.7,272.07]],"batl":[[2,2.22,329.03]],"ltp":1.58,"tv":398.98,"id":9631075},{"batl":[[0,2.42,29.41],[1,2.92,221.25]],"ltp":2.74,"tv":110.93,"id":11772759}]}]}
{"op":"mcm","clk":"1011408524","pt":1580656122665,"mc":[{"id":"1.168222851","rc":[{"batl":[[2,1.84,42.01]],"ltp":1.58,"tv":398.98,"id":9631075},{"batb":[[1,2.2,34.45],[2,2,27.85]],"ltp":2.74,"tv":110.93,"id":11772759}]}]}
{"op":"mcm","clk":"1011412080","pt":1580656136734,"mc":[{"id":"1.168222851","rc":[{"batb":[[0,1.72,23.6],[1,1.7,59.65]],"batl":[[0,1.84,42.01],[1,2.22,329.03],[2,1.84,0]],"ltp":1.58,"tv":398.98,"id":9631075}]}]}
{"op":"mcm","clk":"1011412238","pt":1580656137341,"mc":[{"id":"1.168222851","rc":[{"batb":[[0,1.7,59.65],[1,1.52,36.12],[2,1.01,10.52]],"ltp":1.58,"tv":398.98,"id":9631075},{"batb":[[0,2.2,34.45],[1,2,27.85],[2,1.01,10.51]],"ltp":2.74,"tv":110.93,"id":11772759}]}]}
{"op":"mcm","clk":"1011412438","pt":1580656138165,"mc":[{"id":"1.168222851","rc":[{"batb":[[0,1.52,36.12],[1,1.01,10.52],[2,1.01,0]],"batl":[[0,2.22,329.03],[1,2.22,0]],"ltp":1.58,"tv":398.98,"id":9631075},{"batb":[[0,2,27.85],[1,1.01,10.51],[2,1.01,0]],"batl":[[0,2.92,221.25],[1,2.92,0]],"ltp":2.74,"tv":110.93,"id":11772759}]}]}
{"op":"mcm","clk":"1011412841","pt":1580656139641,"mc":[{"id":"1.168222851","rc":[{"batb":[[0,1.54,249.67],[1,1.53,158.49],[2,1.52,36.12]],"batl":[[0,1.94,115.5],[1,1.96,135.92],[2,2.22,329.03]],"ltp":1.58,"tv":398.98,"id":9631075},{"batl":[[0,2.26,35.39],[1,2.92,221.25]],"ltp":2.74,"tv":110.93,"id":11772759}]}]}
{"op":"mcm","clk":"1011413760","pt":1580656143382,"mc":[{"id":"1.168222851","rc":[{"batl":[[0,2.92,221.25],[1,2.92,0]],"ltp":2.74,"tv":110.93,"id":11772759}]}]}
{"op":"mcm","clk":"1011414374","pt":1580656145685,"mc":[{"id":"1.168222851","rc":[{"batl":[[0,2.22,329.03],[1,1.96,0],[2,2.22,0]],"ltp":1.58,"tv":398.98,"id":9631075}]}]}
{"op":"mcm","clk":"1011415121","pt":1580656148734,"mc":[{"id":"1.168222851","rc":[{"batl":[[0,1.6,200.34],[1,1.61,128.83]],"ltp":1.58,"tv":398.98,"id":9631075}]}]}
{"op":"mcm","clk":"1011415356","pt":1580656149679,"mc":[{"id":"1.168222851","rc":[{"batb":[[0,1.56,74.78],[1,1.54,249.67],[2,1.53,158.49]],"ltp":1.58,"tv":398.98,"id":9631075},{"batb":[[0,2.68,12.35],[1,2.26,19.43],[2,1.01,10.51]],"batl":[[0,2.78,23.53]],"ltp":2.74,"tv":110.93,"id":11772759}]}]}
{"op":"mcm","clk":"1011415632","pt":1580656150751,"mc":[{"id":"1.168222851","rc":[{"batl":[[2,1.67,42.01]],"ltp":1.58,"tv":398.98,"id":9631075},{"batb":[[1,2.48,27.73],[2,2.26,19.43]],"ltp":2.74,"tv":110.93,"id":11772759}]}]}
{"op":"mcm","clk":"1011415836","pt":1580656151477,"mc":[{"id":"1.168222851","rc":[{"batl":[[1,3.65,170.4]],"ltp":2.74,"tv":110.93,"id":11772759}]}]}
{"op":"mcm","clk":"1011419670","pt":1580656167142,"mc":[{"id":"1.168222851","rc":[{"batb":[[1,1.34,62.25],[2,1.01,10.51]],"batl":[[0,1.67,42.01],[1,2.04,383.03],[2,1.67,0]],"ltp":1.58,"tv":398.98,"id":9631075},{"batb":[[0,2.48,27.73],[1,2.26,19.43],[2,1.01,10.51]],"ltp":2.74,"tv":110.93,"id":11772759}]}]}
{"op":"mcm","clk":"1011419938","pt":1580656168197,"mc":[{"id":"1.168222851","rc":[{"batb":[[0,1.34,62.25],[1,1.01,10.51],[2,1.01,0]],"batl":[[0,2.04,383.03],[1,2.04,0]],"ltp":1.58,"tv":398.98,"id":9631075},{"batb":[[0,2.26,19.43],[1,1.01,10.51],[2,1.01,0]],"batl":[[0,3.65,170.4],[1,3.65,0]],"ltp":2.74,"tv":110.93,"id":11772759}]}]}
{"op":"mcm","clk":"1011420270","pt":1580656169710,"mc":[{"id":"1.168222851","rc":[{"batb":[[0,1.35,300.85],[1,1.34,348.31],[2,1.01,10.51]],"batl":[[0,1.78,131.87],[1,1.8,177.39],[2,2.04,383.03]],"ltp":1.58,"tv":398.98,"id":9631075}]}]}
{"op":"mcm","clk":"1011421386","pt":1580656174250,"mc":[{"id":"1.168222851","rc":[{"batl":[[0,2.04,383.03],[1,1.8,0],[2,2.04,0]],"ltp":1.58,"tv":398.98,"id":9631075}]}]}
{"op":"mcm","clk":"1011422191","pt":1580656177745,"mc":[{"id":"1.168222851","rc":[{"batb":[[0,1.37,113.43],[1,1.35,300.85],[2,1.34,348.31]],"batl":[[0,1.39,245.67],[1,1.4,224.79],[2,1.45,42.01]],"ltp":1.58,"tv":398.98,"id":9631075},{"batb":[[0,3.5,15.5],[1,3.2,18.48],[2,2.7,12.12]],"batl":[[0,3.65,15.12]],"ltp":2.74,"tv":110.93,"id":11772759}]}]}
{"op":"mcm","clk":"1011422742","pt":1580656179754,"mc":[{"id":"1.168222851","rc":[{"batl":[[1,4.9,126.26]],"ltp":2.74,"tv":110.93,"id":11772759}]}]}
{"op":"mcm","clk":"1011425339","pt":1580656189942,"mc":[{"id":"1.168222851","rc":[{"batb":[[1,2.7,12.12],[2,1.01,10.51]],"ltp":2.74,"tv":110.93,"id":11772759}]}]}
{"op":"mcm","clk":"1011426060","pt":1580656192670,"mc":[{"id":"1.168222851","rc":[{"batb":[[1,3.25,18.48],[2,2.7,12.12]],"ltp":2.74,"tv":110.93,"id":11772759}]}]}
{"op":"mcm","clk":"1011427074","pt":1580656196571,"mc":[{"id":"1.168222851","rc":[{"batb":[[1,1.34,62.25],[2,1.17,134.7]],"batl":[[0,1.45,42.01],[1,1.77,500.63],[2,1.45,0]],"ltp":1.58,"tv":398.98,"id":9631075}]}]}
{"op":"mcm","clk":"1011427141","pt":1580656196900,"mc":[{"id":"1.168222851","rc":[{"batb":[[1,1.17,134.72],[2,1.01,10.51]],"ltp":1.58,"tv":398.98,"id":9631075},{"batb":[[0,3.25,18.48],[1,2.7,12.12],[2,1.01,10.51]],"ltp":2.74,"tv":110.93,"id":11772759}]}]}
{"op":"mcm","clk":"1011427543","pt":1580656198584,"mc":[{"id":"1.168222851","rc":[{"batb":[[0,1.17,134.72],[1,1.01,10.51],[2,1.01,0]],"ltp":1.58,"tv":398.98,"id":9631075},{"batb":[[0,2.7,12.12],[1,1.01,10.51],[2,1.01,0]],"ltp":2.74,"tv":110.93,"id":11772759}]}]}
{"op":"mcm","clk":"1011427925","pt":1580656200114,"mc":[{"id":"1.168222851","rc":[{"batb":[[0,1.18,132.28]],"ltp":1.58,"tv":398.98,"id":9631075},{"batb":[[0,2.68,12.43]],"ltp":2.74,"tv":110.93,"id":11772759}]}]}
{"op":"mcm","clk":"1011428320","pt":1580656201621,"mc":[{"id":"1.168222851","rc":[{"trd":[[1.34,0.05]],"batb":[[0,1.31,177.95],[1,1.3,333.12],[2,1.18,132.26]],"batl":[[0,1.34,231.19],[1,1.35,266.41]],"ltp":1.34,"tv":399.01,"id":9631075}],"tv":509.95}]}
{"op":"mcm","clk":"1011429017","pt":1580656204200,"mc":[{"id":"1.168222851","rc":[{"batl":[[2,1.71,542.08]],"ltp":1.34,"tv":399.01,"id":9631075},{"batl":[[0,5.5,115.06]],"ltp":2.74,"tv":110.93,"id":11772759}]}]}
{"op":"mcm","clk":"1011429500","pt":1580656206114,"mc":[{"id":"1.168222851","rc":[{"batb":[[0,1.18,132.26],[1,1.01,10.51],[2,1.18,0]],"batl":[[0,1.71,542.08],[1,1.35,0],[2,1.71,0]],"ltp":1.34,"tv":399.01,"id":9631075}]}]}
{"op":"mcm","clk":"1011430181","pt":1580656208934,"mc":[{"id":"1.168222851","rc":[{"batb":[[1,1.15,841.13],[2,1.14,270.77]],"batl":[[0,1.59,142.44],[1,1.6,132.02]],"ltp":1.34,"tv":399.01,"id":9631075}]}]}
{"op":"mcm","clk":"1011432138","pt":1580656216668,"mc":[{"id":"1.168222851","rc":[{"trd":[[1.18,264.52]],"batb":[[0,1.15,841.13],[1,1.14,270.77],[2,1.01,10.51]],"batl":[[0,1.18,506.06],[1,1.19,439.29]],"ltp":1.18,"tv":663.54,"id":9631075}],"tv":774.47}]}
{"op":"mcm","clk":"1011432394","pt":1580656217663,"mc":[{"id":"1.168222851","rc":[{"batb":[[1,1.14,195.65],[2,1.13,175.85]],"ltp":1.18,"tv":663.54,"id":9631075},{"batb":[[0,5.5,10.62],[1,4.2,19.59],[2,2.68,12.43]],"ltp":2.74,"tv":110.93,"id":11772759}]}]}
{"op":"mcm","clk":"1011432442","pt":1580656217869,"mc":[{"id":"1.168222851","rc":[{"batb":[[2,1.01,10.51]],"ltp":2.74,"tv":110.93,"id":11772759}]}]}
{"op":"mcm","clk":"1011432872","pt":1580656219676,"mc":[{"id":"1.168222851","rc":[{"batb":[[2,1.13,343.89]],"batl":[[2,1.49,761.7]],"ltp":1.18,"tv":663.54,"id":9631075},{"batl":[[0,8.6,5.04],[1,9.8,75.27]],"ltp":2.74,"tv":110.93,"id":11772759}]}]}
{"op":"mcm","clk":"1011433009","pt":1580656220185,"mc":[{"id":"1.168222851","rc":[{"batb":[[0,1.15,915.59]],"batl":[[0,1.17,42.01],[1,1.18,565.98],[2,1.19,511.02]],"ltp":1.18,"tv":663.54,"id":9631075},{"batb":[[0,7,6.72],[1,5.5,10.62],[2,4.2,19.59]],"ltp":2.74,"tv":110.93,"id":11772759}]}]}
{"op":"mcm","clk":"1011434456","pt":1580656226000,"mc":[{"id":"1.168222851","rc":[{"batb":[[0,1.16,146.9],[1,1.15,915.59],[2,1.14,195.65]],"ltp":1.18,"tv":663.54,"id":9631075},{"batb":[[1,6,18.1],[2,4.7,16.68]],"ltp":2.74,"tv":110.93,"id":11772759}]}]}
{"op":"mcm","clk":"1011435831","pt":1580656231560,"mc":[{"id":"1.168222851","rc":[{"batb":[[1,6,17.94],[2,4.7,16.52]],"ltp":2.74,"tv":110.93,"id":11772759}]}]}
{"op":"mcm","clk":"1011436673","pt":1580656234700,"mc":[{"id":"1.168222851","rc":[{"batb":[[0,6,17.94],[1,4.7,16.52],[2,1.01,10.51]],"batl":[[0,9.8,75.27],[1,9.8,0]],"ltp":2.74,"tv":110.93,"id":11772759}]}]}
{"op":"mcm","clk":"1011437338","pt":1580656237302,"mc":[{"id":"1.168222851","rc":[{"batb":[[0,6.8,6.72],[1,6,17.94],[2,4.7,16.52]],"batl":[[0,8.4,5.04],[1,9.8,75.27]],"ltp":2.74,"tv":110.93,"id":11772759}]}]}
{"op":"mcm","clk":"1011438715","pt":1580656242692,"mc":[{"id":"1.168222851","rc":[{"batb":[[0,1.15,1066.11],[1,1.14,195.65],[2,1.13,168.04]],"ltp":1.18,"tv":663.54,"id":9631075},{"batb":[[1,6.2,17.39],[2,4.7,16.05]],"ltp":2.74,"tv":110.93,"id":11772759}]}]}
{"op":"mcm","clk":"1011439934","pt":1580656247722,"mc":[{"id":"1.168222851","rc":[{"batb":[[0,1.15,796.5],[1,1.13,168.04],[2,1.12,194.82]],"batl":[[0,1.18,269.36],[1,1.19,511.02],[2,1.49,761.7]],"ltp":1.18,"tv":663.54,"id":9631075}]}]}
{"op":"mcm","clk":"1011440678","pt":1580656250603,"mc":[{"id":"1.168222851","rc":[{"batb":[[0,1.16,459.56],[1,1.15,796.5],[2,1.13,168.04]],"batl":[[1,1.19,540.9]],"ltp":1.18,"tv":663.54,"id":9631075}]}]}
{"op":"mcm","clk":"1011441596","pt":1580656254312,"mc":[{"id":"1.168222851","rc":[{"batl":[[0,1.17,42.01],[1,1.18,269.36],[2,1.19,540.9]],"ltp":1.18,"tv":663.54,"id":9631075}]}]}
{"op":"mcm","clk":"1011442468","pt":1580656257687,"mc":[{"id":"1.168222851","rc":[{"batb":[[0,1.16,609.84]],"ltp":1.18,"tv":663.54,"id":9631075}]}]}
{"op":"mcm","clk":"1011442705","pt":1580656258715,"mc":[{"id":"1.168222851","rc":[{"batb":[[1,1.15,609.15]],"batl":[[1,1.18,233.56]],"ltp":1.18,"tv":663.54,"id":9631075}]}]}
{"op":"mcm","clk":"1011443412","pt":1580656261751,"mc":[{"id":"1.168222851","rc":[{"batb":[[0,1.16,646.36]],"ltp":1.18,"tv":663.54,"id":9631075}]}]}
{"op":"mcm","clk":"1011445981","pt":1580656271437,"mc":[{"id":"1.168222851","rc":[{"batl":[[0,1.18,233.56],[1,1.19,540.9],[2,1.49,761.7]],"ltp":1.18,"tv":663.54,"id":9631075}]}]}
{"op":"mcm","clk":"1011448325","pt":1580656280869,"mc":[{"id":"1.168222851","rc":[{"batb":[[0,6.2,17.39],[1,4.7,16.05],[2,1.01,10.51]],"batl":[[0,9.8,75.27],[1,9.8,0]],"ltp":2.74,"tv":110.93,"id":11772759}]}]}
{"op":"mcm","clk":"1011449053","pt":1580656284056,"mc":[{"id":"1.168222851","rc":[{"batl":[[0,1.18,275.57]],"ltp":1.18,"tv":663.54,"id":9631075},{"batb":[[0,6.6,6.72],[1,6.2,17.39],[2,4.7,16.05]],"batl":[[0,8.2,5.04],[1,9.8,75.27]],"ltp":2.74,"tv":110.93,"id":11772759}]}]}
{"op":"mcm","clk":"1011451306","pt":1580656293287,"mc":[{"id":"1.168222851","rc":[{"batb":[[1,1.15,440.87]],"batl":[[0,1.18,42.01]],"ltp":1.18,"tv":663.54,"id":9631075}]}]}
{"op":"mcm","clk":"1011452044","pt":1580656296287,"mc":[{"id":"1.168222851","rc":[{"batb":[[0,1.16,813.18]],"batl":[[1,1.19,610.42],[2,1.2,457.98]],"ltp":1.18,"tv":663.54,"id":9631075}]}]}
{"op":"mcm","clk":"1011452435","pt":1580656297874,"mc":[{"id":"1.168222851","rc":[{"trd":[[1.16,50.42]],"batb":[[0,1.16,787.97]],"ltp":1.16,"tv":713.96,"id":9631075}],"tv":824.89}]}
{"op":"mcm","clk":"1011453335","pt":1580656301670,"mc":[{"id":"1.168222851","rc":[{"batb":[[0,1.16,821.64]],"ltp":1.16,"tv":713.96,"id":9631075}]}]}
{"op":"mcm","clk":"1011456150","pt":1580656313707,"mc":[{"id":"1.168222851","rc":[{"batb":[[0,1.16,150.28],[1,1.13,168.04],[2,1.12,194.82]],"batl":[[1,1.49,761.7],[2,1.2,0]],"ltp":1.16,"tv":713.96,"id":9631075}]}]}
{"op":"mcm","clk":"1011456294","pt":1580656314314,"mc":[{"id":"1.168222851","rc":[{"batb":[[0,1.12,194.82],[1,1.01,10.51],[2,1.12,0]],"batl":[[0,1.49,761.7],[1,1.49,0]],"ltp":1.16,"tv":713.96,"id":9631075},{"batb":[[0,4.7,16.05],[1,1.01,10.51],[2,4.7,0]],"batl":[[0,9.8,75.27],[1,9.8,0]],"ltp":2.74,"tv":110.93,"id":11772759}]}]}
{"op":"mcm","clk":"1011456835","pt":1580656316526,"mc":[{"id":"1.168222851","rc":[{"batb":[[0,1.13,381.67],[1,1.12,949],[2,1.01,10.51]],"batl":[[0,1.27,492.35],[1,1.28,333.32],[2,1.49,761.7]],"ltp":1.16,"tv":713.96,"id":9631075}]}]}
{"op":"mcm","clk":"1011458178","pt":1580656321752,"mc":[{"id":"1.168222851","rc":[{"batl":[[0,1.49,761.7],[1,1.28,0],[2,1.49,0]],"ltp":1.16,"tv":713.96,"id":9631075}]}]}
{"op":"mcm","clk":"1011458920","pt":1580656324601,"mc":[{"id":"1.168222851","rc":[{"batl":[[0,1.15,599.38],[1,1.16,505.76],[2,1.49,761.7]],"ltp":1.16,"tv":713.96,"id":9631075}]}]}
{"op":"mcm","clk":"1011459155","pt":1580656325586,"mc":[{"id":"1.168222851","rc":[{"batb":[[2,1.11,168.04]],"batl":[[0,1.15,641.39]],"ltp":1.16,"tv":713.96,"id":9631075},{"batb":[[0,7.8,5.88],[1,7.4,11.25],[2,5.7,10.62]],"batl":[[0,9.8,4.2]],"ltp":2.74,"tv":110.93,"id":11772759}]}]}
{"op":"mcm","clk":"1011459895","pt":1580656328301,"mc":[{"id":"1.168222851","rc":[{"batl":[[1,12.5,65.97]],"ltp":2.74,"tv":110.93,"id":11772759}]}]}
{"op":"mcm","clk":"1011464196","pt":1580656345474,"mc":[{"id":"1.168222851","rc":[{"batb":[[0,1.11,168.04],[1,1.09,257.84],[2,1.01,10.51]],"batl":[[0,1.15,42.01],[1,1.49,761.7],[2,1.49,0]],"ltp":1.16,"tv":713.96,"id":9631075},{"batb":[[1,5.7,10.62],[2,1.01,10.51]],"ltp":2.74,"tv":110.93,"id":11772759}]}]}
{"op":"mcm","clk":"1011464476","pt":1580656346665,"mc":[{"id":"1.168222851","rc":[{"batb":[[0,1.09,257.84],[1,1.01,10.51],[2,1.01,0]],"batl":[[0,1.49,761.7],[1,1.49,0]],"ltp":1.16,"tv":713.96,"id":9631075},{"batb":[[0,5.7,10.62],[1,1.01,10.51],[2,1.01,0]],"batl":[[0,12.5,65.97],[1,12.5,0]],"ltp":2.74,"tv":110.93,"id":11772759}]}]}
{"op":"mcm","clk":"1011464983","pt":1580656348661,"mc":[{"id":"1.168222851","rc":[{"batb":[[0,1.1,1067.99],[1,1.09,257.84],[2,1.01,10.51]],"batl":[[0,1.2,214.11],[1,1.21,476.77],[2,1.49,761.7]],"ltp":1.16,"tv":713.96,"id":9631075}]}]}
{"op":"mcm","clk":"1011465343","pt":1580656350101,"mc":[{"id":"1.168222851","rc":[{"batl":[[0,1.49,761.7],[1,1.21,0],[2,1.49,0]],"ltp":1.16,"tv":713.96,"id":9631075}]}]}
{"op":"mcm","clk":"1011466212","pt":1580656353709,"mc":[{"id":"1.168222851","rc":[{"batb":[[2,1.07,319.76]],"batl":[[0,1.12,440.58],[1,1.13,692.49]],"ltp":1.16,"tv":713.96,"id":9631075},{"batb":[[0,9.2,7.24],[1,7.2,12.27],[2,5.7,10.62]],"ltp":2.74,"tv":110.93,"id":11772759}]}]}
{"op":"mcm","clk":"1011466313","pt":1580656354152,"mc":[{"id":"1.168222851","rc":[{"batb":[[2,1.01,10.51]],"ltp":2.74,"tv":110.93,"id":11772759}]}]}
{"op":"mcm","clk":"1011466596","pt":1580656355198,"mc":[{"id":"1.168222851","rc":[{"batb":[[1,1.09,425.88]],"ltp":1.16,"tv":713.96,"id":9631075},{"batb":[[1,9,5.04],[2,7.2,12.27]],"batl":[[0,11.5,3.36]],"ltp":2.74,"tv":110.93,"id":11772759}]}]}
{"op":"mcm","clk":"1011467076","pt":1580656357122,"mc":[{"id":"1.168222851","rc":[{"batl":[[2,1.4,927.73]],"ltp":1.16,"tv":713.96,"id":9631075},{"batl":[[1,17,57.33]],"ltp":2.74,"tv":110.93,"id":11772759}]}]}
{"op":"mcm","clk":"1011469376","pt":1580656366363,"mc":[{"id":"1.168222851","rc":[{"batb":[[0,1.1,744.35]],"batl":[[1,1.13,377.27]],"ltp":1.16,"tv":713.96,"id":9631075}]}]}
{"op":"mcm","clk":"1011469950","pt":1580656368578,"mc":[{"id":"1.168222851","rc":[{"batb":[[0,1.09,168.04],[1,1.07,319.76],[2,1.01,10.51]],"batl":[[0,1.4,927.73],[1,1.13,0],[2,1.4,0]],"ltp":1.16,"tv":713.96,"id":9631075},{"batb":[[0,9,5.04],[1,7.2,12.27],[2,1.01,10.51]],"ltp":2.74,"tv":110.93,"id":11772759}]}]}
{"op":"mcm","clk":"1011470178","pt":1580656369590,"mc":[{"id":"1.168222851","rc":[{"batb":[[0,1.09,421.82]],"ltp":1.16,"tv":713.96,"id":9631075}]}]}
{"op":"mcm","clk":"1011470355","pt":1580656370301,"mc":[{"id":"1.168222851","rc":[{"batb":[[0,1.09,253.78]],"ltp":1.16,"tv":713.96,"id":9631075},{"batb":[[0,7.2,12.27],[1,1.01,10.51],[2,1.01,0]],"batl":[[0,17,57.33],[1,17,0]],"ltp":2.74,"tv":110.93,"id":11772759}]}]}
{"op":"mcm","clk":"1011470631","pt":1580656371431,"mc":[{"id":"1.168222851","rc":[{"batb":[[0,1.07,319.76],[1,1.01,10.51],[2,1.01,0]],"ltp":1.16,"tv":713.96,"id":9631075}]}]}
{"op":"mcm","clk":"1011471407","pt":1580656374395,"mc":[{"id":"1.168222851","rc":[{"batb":[[0,1.11,213.76],[1,1.1,878.66],[2,1.07,319.76]],"batl":[[0,1.13,841.76],[1,1.4,927.73]],"ltp":1.16,"tv":713.96,"id":9631075}]}]}
{"op":"mcm","clk":"1011472152","pt":1580656377366,"mc":[{"id":"1.168222851","rc":[{"batb":[[0,1.11,278.78]],"batl":[[0,1.13,980.2]],"ltp":1.16,"tv":713.96,"id":9631075}]}]}
{"op":"mcm","clk":"1011472371","pt":1580656378291,"mc":[{"id":"1.168222851","rc":[{"batb":[[0,1.07,319.76],[1,1.01,10.51],[2,1.07,0]],"batl":[[0,1.4,927.73],[1,1.4,0]],"ltp":1.16,"tv":713.96,"id":9631075}]}]}
{"op":"mcm","clk":"1011473058","pt":1580656380985,"mc":[{"id":"1.168222851","rc":[{"batb":[[0,1.09,314.3],[1,1.08,864.24],[2,1.07,319.76]],"batl":[[0,1.15,474.09],[1,1.16,629.98],[2,1.4,927.73]],"ltp":1.16,"tv":713.96,"id":9631075}]}]}
{"op":"mcm","clk":"1011475995","pt":1580656393414,"mc":[{"id":"1.168222851","rc":[{"batb":[[0,1.07,319.76],[1,1.01,10.51],[2,1.07,0]],"ltp":1.16,"tv":713.96,"id":9631075}]}]}
{"op":"mcm","clk":"1011476738","pt":1580656396552,"mc":[{"id":"1.168222851","rc":[{"batb":[[0,1.13,415.6],[1,1.12,579.8],[2,1.07,319.76]],"batl":[[1,1.16,494.51]],"ltp":1.16,"tv":713.96,"id":9631075}]}]}
{"op":"mcm","clk":"1011476916","pt":1580656397299,"mc":[{"id":"1.168222851","rc":[{"batb":[[0,1.13,602.55],[2,1.11,168.04]],"batl":[[0,1.15,516.1]],"ltp":1.16,"tv":713.96,"id":9631075},{"batb":[[0,7.6,5.88],[1,7.2,12.27],[2,5.3,12.2]],"batl":[[0,9.8,4.2]],"ltp":2.74,"tv":110.93,"id":11772759}]}]}
{"op":"mcm","clk":"1011477436","pt":1580656399532,"mc":[{"id":"1.168222851","rc":[{"batb":[[1,1.12,719.95]],"batl":[[0,1.15,652.74]],"ltp":1.16,"tv":713.96,"id":9631075},{"batl":[[1,14,62.58]],"ltp":2.74,"tv":110.93,"id":11772759}]}]}
{"op":"mcm","clk":"1011481992","pt":1580656418744,"mc":[{"id":"1.168222851","rc":[{"batb":[[0,1.11,168.04],[1,1.09,257.53],[2,1.01,10.51]],"batl":[[0,1.15,42.01],[1,1.4,927.73],[2,1.4,0]],"ltp":1.16,"tv":713.96,"id":9631075},{"batb":[[1,5.3,12.2],[2,1.01,10.51]],"ltp":2.74,"tv":110.93,"id":11772759}]}]}
{"op":"mcm","clk":"1011482367","pt":1580656420258,"mc":[{"id":"1.168222851","rc":[{"batb":[[0,1.09,257.53],[1,1.01,10.51],[2,1.01,0]],"batl":[[0,1.4,927.73],[1,1.4,0]],"ltp":1.16,"tv":713.96,"id":9631075},{"batb":[[0,5.3,12.2],[1,1.01,10.51],[2,1.01,0]],"batl":[[0,14,62.58],[1,14,0]],"ltp":2.74,"tv":110.93,"id":11772759}]}]}
{"op":"mcm","clk":"1011482627","pt":1580656421339,"mc":[{"id":"1.168222851","rc":[{"batb":[[0,1.1,510.74],[1,1.09,912.72],[2,1.01,10.51]],"batl":[[0,1.22,618.58],[1,1.23,423.82],[2,1.4,927.73]],"ltp":1.16,"tv":713.96,"id":9631075}]}]}
{"op":"mcm","clk":"1011484309","pt":1580656428755,"mc":[{"id":"1.168222851","rc":[{"batl":[[0,1.4,927.73],[1,1.23,0],[2,1.4,0]],"ltp":1.16,"tv":713.96,"id":9631075}]}]}
{"op":"mcm","clk":"1011484938","pt":1580656431468,"mc":[{"id":"1.168222851","rc":[{"batl":[[0,1.12,967.98],[1,1.13,169.76],[2,1.4,927.73]],"ltp":1.16,"tv":713.96,"id":9631075}]}]}
{"op":"mcm","clk":"1011485162","pt":1580656432381,"mc":[{"id":"1.168222851","rc":[{"batb":[[2,1.07,318.66]],"ltp":1.16,"tv":713.96,"id":9631075},{"batb":[[0,9.2,7.24],[1,7.2,12.04],[2,1.01,10.51]],"ltp":2.74,"tv":110.93,"id":11772759}]}]}
{"op":"mcm","clk":"1011485430","pt":1580656433666,"mc":[{"id":"1.168222851","rc":[{"batb":[[1,1.09,1080.75]],"ltp":1.16,"tv":713.96,"id":9631075}]}]}
{"op":"mcm","clk":"1011485683","pt":1580656434689,"mc":[{"id":"1.168222851","rc":[{"batl":[[0,1.12,1009.99]],"ltp":1.16,"tv":713.96,"id":9631075},{"batb":[[0,9.2,12.28]],"batl":[[0,12,3.36],[1,21,53.48]],"ltp":2.74,"tv":110.93,"id":11772759}]}]}
{"op":"mcm","clk":"1011487101","pt":1580656440284,"mc":[{"id":"1.168222851","rc":[{"batl":[[2,1.4,0]],"ltp":1.16,"tv":713.96,"id":9631075}]}]}
{"op":"mcm","clk":"1011487745","pt":1580656442581,"mc":[{"id":"1.168222851","rc":[{"batl":[[1,21,0]],"ltp":2.74,"tv":110.93,"id":11772759}]}]}
{"op":"mcm","clk":"1011488755","pt":1580656446717,"mc":[{"id":"1.168222851","rc":[{"batb":[[0,1.1,328.85]],"batl":[[0,1.12,971.01],[1,1.13,0]],"ltp":1.16,"tv":713.96,"id":9631075}]}]}
{"op":"mcm","clk":"1011489297","pt":1580656449080,"mc":[{"id":"1.168222851","rc":[{"batb":[[0,1.1,248.33],[1,1.09,1264.31]],"batl":[[0,1.11,212.15],[1,1.12,891.99]],"ltp":1.16,"tv":713.96,"id":9631075}]}]}
{"op":"mcm","clk":"1011490256","pt":1580656452578,"mc":[{"id":"1.168222851","rc":[{"batb":[[0,1.09,168.04],[1,1.07,318.66],[2,1.01,10.51]],"batl":[[0,1.12,42.01],[1,1.12,0]],"ltp":1.16,"tv":713.96,"id":9631075},{"batb":[[0,9.2,5.04]],"ltp":2.74,"tv":110.93,"id":11772759}]}]}
{"op":"mcm","clk":"1011490731","pt":1580656454397,"mc":[{"id":"1.168222851","rc":[{"batb":[[0,1.07,318.66],[1,1.01,10.51],[2,1.01,0]],"ltp":1.16,"tv":713.96,"id":9631075},{"batb":[[0,7.2,12.04],[1,1.01,10.51],[2,1.01,0]],"ltp":2.74,"tv":110.93,"id":11772759}]}]}
{"op":"mcm","clk":"1011490944","pt":1580656455267,"mc":[{"id":"1.168222851","rc":[{"batb":[[0,1.08,1181.46],[1,1.07,318.66],[2,1.01,10.51]],"batl":[[0,1.14,350.67],[1,1.15,727.19]],"ltp":1.16,"tv":713.96,"id":9631075}]}]}
{"op":"mcm","clk":"1011493227","pt":1580656464376,"mc":[{"id":"1.168222851","rc":[{"batl":[[0,1.1,806.71],[1,1.11,350.08]],"ltp":1.16,"tv":713.96,"id":9631075}]}]}
{"op":"mcm","clk":"1011493446","pt":1580656465289,"mc":[{"id":"1.168222851","rc":[{"batb":[[0,1.08,1349.5],[2,1.05,447.7]],"batl":[[1,1.11,392.09]],"ltp":1.16,"tv":713.96,"id":9631075},{"batb":[[0,10.5,12.98],[1,10,4.2],[2,9,7.47]],"batl":[[0,13.5,3.36]],"ltp":2.74,"tv":110.93,"id":11772759}]}]}
{"op":"mcm","clk":"1011494207","pt":1580656468023,"mc":[{"id":"1.168222851","rc":[{"batl":[[1,24,50.52]],"ltp":2.74,"tv":110.93,"id":11772759}]}]}
{"op":"mcm","clk":"1011499077","pt":1580656487710,"mc":[{"id":"1.168222851","rc":[{"batl":[[0,1.1,698.18]],"ltp":1.16,"tv":713.96,"id":9631075}]}]}
{"op":"mcm","clk":"1011499753","pt":1580656490617,"mc":[{"id":"1.168222851","rc":[{"batl":[[1,1.11,499.65]],"ltp":1.16,"tv":713.96,"id":9631075}]}]}
{"op":"mcm","clk":"1011499982","pt":1580656491507,"mc":[{"id":"1.168222851","rc":[{"batl":[[1,1.11,392.09]],"ltp":1.16,"tv":713.96,"id":9631075}]}]}
{"op":"mcm","clk":"1011500259","pt":1580656492622,"mc":[{"id":"1.168222851","rc":[{"batl":[[0,1.1,685.29]],"ltp":1.16,"tv":713.96,"id":9631075}]}]}
{"op":"mcm","clk":"1011500491","pt":1580656493571,"mc":[{"id":"1.168222851","rc":[{"batl":[[0,1.1,648.16]],"ltp":1.16,"tv":713.96,"id":9631075}]}]}
{"op":"mcm","clk":"1011500691","pt":1580656494412,"mc":[{"id":"1.168222851","marketDefinition":{"bspMarket":false,"turnInPlayEnabled":true,"persistenceEnabled":true,"marketBaseRate":5.0,"eventId":"29681551","eventTypeId":"2","numberOfWinners":1,"bettingType":"ODDS","marketType":"SET_WINNER","marketTime":"2020-02-02T13:52:00.000Z","suspendTime":"2020-02-02T13:52:00.000Z","bspReconciled":false,"complete":true,"inPlay":true,"crossMatching":true,"runnersVoidable":false,"numberOfActiveRunners":2,"betDelay":3,"status":"SUSPENDED","runners":[{"status":"ACTIVE","sortPriority":1,"id":11772759,"name":"Juan Pablo Varillas"},{"status":"ACTIVE","sortPriority":2,"id":9631075,"name":"Carlos Taberner"}],"regulators":["MR_INT"],"countryCode":"AR","discountAllowed":true,"timezone":"UTC","openDate":"2020-02-02T13:52:00.000Z","version":3149432491,"name":"Set 2 Winner","eventName":"Jua Varillas v Taberner"},"rc":[{"batb":[[0,1.01,10.51],[1,1.07,0],[2,1.05,0]],"ltp":1.16,"tv":713.96,"id":9631075},{"batb":[[0,1.01,10.51],[1,10,0],[2,9,0]],"batl":[[0,24,50.52],[1,24,0]],"ltp":2.74,"tv":110.93,"id":11772759}]}]}
{"op":"mcm","clk":"1011509134","pt":1580656528303,"mc":[{"id":"1.168222851","marketDefinition":{"bspMarket":false,"turnInPlayEnabled":true,"persistenceEnabled":true,"marketBaseRate":5.0,"eventId":"29681551","eventTypeId":"2","numberOfWinners":1,"bettingType":"ODDS","marketType":"SET_WINNER","marketTime":"2020-02-02T13:52:00.000Z","suspendTime":"2020-02-02T13:52:00.000Z","bspReconciled":false,"complete":true,"inPlay":true,"crossMatching":false,"runnersVoidable":false,"numberOfActiveRunners":2,"betDelay":3,"status":"SUSPENDED","runners":[{"status":"ACTIVE","sortPriority":1,"id":11772759,"name":"Juan Pablo Varillas"},{"status":"ACTIVE","sortPriority":2,"id":9631075,"name":"Carlos Taberner"}],"regulators":["MR_INT"],"countryCode":"AR","discountAllowed":true,"timezone":"UTC","openDate":"2020-02-02T13:52:00.000Z","version":3149437298,"name":"Set 2 Winner","eventName":"Jua Varillas v Taberner"},"tv":0.0}]}
{"op":"mcm","clk":"1011509452","pt":1580656529594,"mc":[{"id":"1.168222851","marketDefinition":{"bspMarket":false,"turnInPlayEnabled":true,"persistenceEnabled":true,"marketBaseRate":5.0,"eventId":"29681551","eventTypeId":"2","numberOfWinners":1,"bettingType":"ODDS","marketType":"SET_WINNER","marketTime":"2020-02-02T13:52:00.000Z","suspendTime":"2020-02-02T13:52:00.000Z","bspReconciled":false,"complete":true,"inPlay":true,"crossMatching":false,"runnersVoidable":false,"numberOfActiveRunners":0,"betDelay":3,"status":"CLOSED","settledTime":"2020-02-02T15:15:27.000Z","runners":[{"status":"REMOVED","sortPriority":1,"removalDate":"2020-02-02T15:15:27.000Z","id":11772759,"name":"Juan Pablo Varillas"},{"status":"REMOVED","sortPriority":2,"removalDate":"2020-02-02T15:15:27.000Z","id":9631075,"name":"Carlos Taberner"}],"regulators":["MR_INT"],"countryCode":"AR","discountAllowed":true,"timezone":"UTC","openDate":"2020-02-02T13:52:00.000Z","version":3149437332,"name":"Set 2 Winner","eventName":"Jua Varillas v Taberner"}}]}
