{"op":"mcm","clk":"1004097111","pt":1580580427532,"mc":[{"id":"1.168222850","marketDefinition":{"bspMarket":false,"turnInPlayEnabled":true,"persistenceEnabled":true,"marketBaseRate":5.0,"eventId":"29681551","eventTypeId":"2","numberOfWinners":1,"bettingType":"ODDS","marketType":"SET_WINNER","marketTime":"2020-02-02T13:00:00.000Z","suspendTime":"2020-02-02T13:00:00.000Z","bspReconciled":false,"complete":true,"inPlay":false,"crossMatching":false,"runnersVoidable":false,"numberOfActiveRunners":2,"betDelay":0,"status":"OPEN","runners":[{"status":"ACTIVE","sortPriority":1,"id":11772759,"name":"Juan Pablo Varillas"},{"status":"ACTIVE","sortPriority":2,"id":9631075,"name":"Carlos Taberner"}],"regulators":["MR_INT"],"countryCode":"AR","discountAllowed":false,"timezone":"UTC","openDate":"2020-02-02T13:00:00.000Z","version":3146764523,"name":"Set 1 Winner","eventName":"Jua Varillas v Taberner"},"rc":[{"batb":[[0,1.01,20]],"ltp":0.0,"tv":0.0,"id":9631075},{"batb":[[0,1.01,20]],"ltp":0.0,"tv":0.0,"id":11772759}]}]}
{"op":"mcm","clk":"1004097346","pt":1580580428747,"mc":[{"id":"1.168222850","marketDefinition":{"bspMarket":false,"turnInPlayEnabled":true,"persistenceEnabled":true,"marketBaseRate":5.0,"eventId":"29681551","eventTypeId":"2","numberOfWinners":1,"bettingType":"ODDS","marketType":"SET_WINNER","marketTime":"2020-02-02T13:00:00.000Z","suspendTime":"2020-02-02T13:00:00.000Z","bspReconciled":false,"complete":true,"inPlay":false,"crossMatching":false,"runnersVoidable":false,"numberOfActiveRunners":2,"betDelay":0,"status":"OPEN","runners":[{"status":"ACTIVE","sortPriority":1,"id":11772759,"name":"Juan Pablo Varillas"},{"status":"ACTIVE","sortPriority":2,"id":9631075,"name":"Carlos Taberner"}],"regulators":["MR_INT"],"countryCode":"AR","discountAllowed":false,"timezone":"UTC","openDate":"2020-02-02T13:00:00.000Z","version":3146764523,"name":"Set 1 Winner","eventName":"Jua Varillas v Taberner"}}]}
{"op":"mcm","clk":"1004097530","pt":1580580429751,"mc":[{"id":"1.168222850","marketDefinition":{"bspMarket":false,"turnInPlayEnabled":true,"persistenceEnabled":true,"marketBaseRate":5.0,"eventId":"29681551","eventTypeId":"2","numberOfWinners":1,"bettingType":"ODDS","marketType":"SET_WINNER","marketTime":"2020-02-02T13:00:00.000Z","suspendTime":"2020-02-02T13:00:00.000Z","bspReconciled":false,"complete":true,"inPlay":false,"crossMatching":false,"runnersVoidable":false,"numberOfActiveRunners":2,"betDelay":0,"status":"OPEN","runners":[{"status":"ACTIVE","sortPriority":1,"id":11772759,"name":"Juan Pablo Varillas"},{"status":"ACTIVE","sortPriority":2,"id":9631075,"name":"Carlos Taberner"}],"regulators":["MR_INT"],"countryCode":"AR","discountAllowed":true,"timezone":"UTC","openDate":"2020-02-02T13:00:00.000Z","version":3146764523,"name":"Set 1 Winner","eventName":"Jua Varillas v Taberner"}}]}
{"op":"mcm","clk":"1004187401","pt":1580580913086,"mc":[{"id":"1.168222850","rc":[{"batb":[[0,1.01,10]],"ltp":0.0,"tv":0.0,"id":9631075},{"batb":[[0,1.01,10]],"ltp":0.0,"tv":0.0,"id":11772759}]}]}
{"op":"mcm","clk":"1005739150","pt":1580590302889,"mc":[{"id":"1.168222850","marketDefinition":{"bspMarket":false,"turnInPlayEnabled":true,"persistenceEnabled":true,"marketBaseRate":5.0,"eventId":"29681551","eventTypeId":"2","numberOfWinners":1,"bettingType":"ODDS","marketType":"SET_WINNER","marketTime":"2020-02-02T14:00:00.000Z","suspendTime":"2020-02-02T14:00:00.000Z","bspReconciled":false,"complete":true,"inPlay":false,"crossMatching":false,"runnersVoidable":false,"numberOfActiveRunners":2,"betDelay":0,"status":"OPEN","runners":[{"status":"ACTIVE","sortPriority":1,"id":11772759,"name":"Juan Pablo Varillas"},{"status":"ACTIVE","sortPriority":2,"id":9631075,"name":"Carlos Taberner"}],"regulators":["MR_INT"],"countryCode":"AR","discountAllowed":true,"timezone":"UTC","openDate":"2020-02-02T13:00:00.000Z","version":3147422163,"name":"Set 1 Winner","eventName":"Jua Varillas v Taberner"}}]}
{"op":"mcm","clk":"1005739706","pt":1580590307869,"mc":[{"id":"1.168222850","marketDefinition":{"bspMarket":false,"turnInPlayEnabled":true,"persistenceEnabled":true,"marketBaseRate":5.0,"eventId":"29681551","eventTypeId":"2","numberOfWinners":1,"bettingType":"ODDS","marketType":"SET_WINNER","marketTime":"2020-02-02T14:00:00.000Z","suspendTime":"2020-02-02T14:00:00.000Z","bspReconciled":false,"complete":true,"inPlay":false,"crossMatching":false,"runnersVoidable":false,"numberOfActiveRunners":2,"betDelay":0,"status":"OPEN","runners":[{"status":"ACTIVE","sortPriority":1,"id":11772759,"name":"Juan Pablo Varillas"},{"status":"ACTIVE","sortPriority":2,"id":9631075,"name":"Carlos Taberner"}],"regulators":["MR_INT"],"countryCode":"AR","discountAllowed":true,"timezone":"UTC","openDate":"2020-02-02T14:00:00.000Z","version":3147422163,"name":"Set 1 Winner","eventName":"Jua Varillas v Taberner"}}]}
{"op":"mcm","clk":"1006972855","pt":1580602758598,"mc":[{"id":"1.168222850","rc":[{"batb":[[0,1.01,12.53]],"ltp":0.0,"tv":0.0,"id":9631075},{"batb":[[0,1.01,12.53]],"ltp":0.0,"tv":0.0,"id":11772759}]}]}
{"op":"mcm","clk":"1006972947","pt":1580602759693,"mc":[{"id":"1.168222850","rc":[{"batb":[[0,1.01,10.51]],"ltp":0.0,"tv":0.0,"id":9631075},{"batb":[[0,1.01,10.51]],"ltp":0.0,"tv":0.0,"id":11772759}]}]}
{"op":"mcm","clk":"1007029730","pt":1580603523579,"mc":[{"id":"1.168222850","rc":[{"batb":[[0,1.01,11.01]],"ltp":0.0,"tv":0.0,"id":9631075},{"batb":[[0,1.01,11.01]],"ltp":0.0,"tv":0.0,"id":11772759}]}]}
{"op":"mcm","clk":"1009578731","pt":1580645436129,"mc":[{"id":"1.168222850","rc":[{"batb":[[0,1.01,12.69]],"ltp":0.0,"tv":0.0,"id":11772759}]}]}
{"op":"mcm","clk":"1009579483","pt":1580645441825,"mc":[{"id":"1.168222850","rc":[{"batb":[[0,1.01,11.01]],"ltp":0.0,"tv":0.0,"id":11772759}]}]}
{"op":"mcm","clk":"1009660993","pt":1580646018239,"mc":[{"id":"1.168222850","rc":[{"batl":[[0,2.94,4.54]],"ltp":0.0,"tv":0.0,"id":9631075},{"batl":[[0,2.96,4.54]],"ltp":0.0,"tv":0.0,"id":11772759}]}]}
{"op":"mcm","clk":"1009977642","pt":1580648401886,"mc":[{"id":"1.168222850","rc":[{"batb":[[0,1.02,2],[1,1.01,11.01]],"ltp":0.0,"tv":0.0,"id":9631075},{"batb":[[0,1.02,2],[1,1.01,11.01]],"ltp":0.0,"tv":0.0,"id":11772759}]}]}
{"op":"mcm","clk":"1009979837","pt":1580648413638,"mc":[{"id":"1.168222850","marketDefinition":{"bspMarket":false,"turnInPlayEnabled":true,"persistenceEnabled":true,"marketBaseRate":5.0,"eventId":"29681551","eventTypeId":"2","numberOfWinners":1,"bettingType":"ODDS","marketType":"SET_WINNER","marketTime":"2020-02-02T14:00:00.000Z","suspendTime":"2020-02-02T14:00:00.000Z","bspReconciled":false,"complete":true,"inPlay":false,"crossMatching":true,"runnersVoidable":false,"numberOfActiveRunners":2,"betDelay":0,"status":"OPEN","runners":[{"status":"ACTIVE","sortPriority":1,"id":11772759,"name":"Juan Pablo Varillas"},{"status":"ACTIVE","sortPriority":2,"id":9631075,"name":"Carlos Taberner"}],"regulators":["MR_INT"],"countryCode":"AR","discountAllowed":true,"timezone":"UTC","openDate":"2020-02-02T14:00:00.000Z","version":3147422163,"name":"Set 1 Winner","eventName":"Jua Varillas v Taberner"}}]}
{"op":"mcm","clk":"1010072841","pt":1580649001243,"mc":[{"id":"1.168222850","rc":[{"batb":[[0,1.01,11.01],[1,1.01,0]],"ltp":0.0,"tv":0.0,"id":9631075},{"batb":[[0,1.01,11.01],[1,1.01,0]],"ltp":0.0,"tv":0.0,"id":11772759}]}]}
{"op":"mcm","clk":"1010072999","pt":1580649002345,"mc":[{"id":"1.168222850","rc":[{"batb":[[0,1.52,2],[1,1.01,11.01]],"ltp":0.0,"tv":0.0,"id":9631075},{"batb":[[0,1.52,2],[1,1.01,11.01]],"ltp":0.0,"tv":0.0,"id":11772759}]}]}
{"op":"mcm","clk":"1010172422","pt":1580649601567,"mc":[{"id":"1.168222850","rc":[{"batb":[[0,1.01,11.01],[1,1.01,0]],"ltp":0.0,"tv":0.0,"id":9631075}]}]}
{"op":"mcm","clk":"1010172473","pt":1580649601933,"mc":[{"id":"1.168222850","rc":[{"batb":[[0,1.01,11.01],[1,1.01,0]],"ltp":0.0,"tv":0.0,"id":11772759}]}]}
{"op":"mcm","clk":"1010266232","pt":1580650225089,"mc":[{"id":"1.168222850","rc":[{"batb":[[0,1.52,2],[1,1.01,11.01]],"ltp":0.0,"tv":0.0,"id":9631075},{"batb":[[0,1.52,2],[1,1.01,11.01]],"ltp":0.0,"tv":0.0,"id":11772759}]}]}
{"op":"mcm","clk":"1010366285","pt":1580650824703,"mc":[{"id":"1.168222850","rc":[{"batb":[[0,1.01,11.01],[1,1.01,0]],"ltp":0.0,"tv":0.0,"id":9631075}]}]}
{"op":"mcm","clk":"1010366438","pt":1580650825712,"mc":[{"id":"1.168222850","rc":[{"batb":[[0,1.01,11.01],[1,1.01,0]],"ltp":0.0,"tv":0.0,"id":11772759}]}]}
{"op":"mcm","clk":"1010494854","pt":1580651596686,"mc":[{"id":"1.168222850","rc":[{"batb":[[0,1.88,17.15],[1,1.01,11.01]],"ltp":0.0,"tv":0.0,"id":9631075},{"batb":[[0,2,28.25],[1,1.01,11.01]],"ltp":0.0,"tv":0.0,"id":11772759}]}]}
{"op":"mcm","clk":"1010495773","pt":1580651603196,"mc":[{"id":"1.168222850","rc":[{"batb":[[0,1.89,2],[1,1.88,17.15],[2,1.01,11.01]],"ltp":0.0,"tv":0.0,"id":9631075},{"batb":[[0,2.02,2],[1,2,28.25],[2,1.01,11.01]],"ltp":0.0,"tv":0.0,"id":11772759}]}]}
{"op":"mcm","clk":"1010521460","pt":1580651782576,"mc":[{"id":"1.168222850","rc":[{"batb":[[0,1.88,17.15],[1,1.01,11.01],[2,1.01,0]],"ltp":0.0,"tv":0.0,"id":9631075},{"batb":[[0,2,28.25],[1,1.01,11.01],[2,1.01,0]],"ltp":0.0,"tv":0.0,"id":11772759}]}]}
{"op":"mcm","clk":"1010524387","pt":1580651803462,"mc":[{"id":"1.168222850","marketDefinition":{"bspMarket":false,"turnInPlayEnabled":true,"persistenceEnabled":true,"marketBaseRate":5.0,"eventId":"29681551","eventTypeId":"2","numberOfWinners":1,"bettingType":"ODDS","marketType":"SET_WINNER","marketTime":"2020-02-02T13:52:00.000Z","suspendTime":"2020-02-02T13:52:00.000Z","bspReconciled":false,"complete":true,"inPlay":false,"crossMatching":true,"runnersVoidable":false,"numberOfActiveRunners":2,"betDelay":0,"status":"OPEN","runners":[{"status":"ACTIVE","sortPriority":1,"id":11772759,"name":"Juan Pablo Varillas"},{"status":"ACTIVE","sortPriority":2,"id":9631075,"name":"Carlos Taberner"}],"regulators":["MR_INT"],"countryCode":"AR","discountAllowed":true,"timezone":"UTC","openDate":"2020-02-02T14:00:00.000Z","version":3149006717,"name":"Set 1 Winner","eventName":"Jua Varillas v Taberner"}}]}
{"op":"mcm","clk":"1010524886","pt":1580651806463,"mc":[{"id":"1.168222850","marketDefinition":{"bspMarket":false,"turnInPlayEnabled":true,"persistenceEnabled":true,"marketBaseRate":5.0,"eventId":"29681551","eventTypeId":"2","numberOfWinners":1,"bettingType":"ODDS","marketType":"SET_WINNER","marketTime":"2020-02-02T13:52:00.000Z","suspendTime":"2020-02-02T13:52:00.000Z","bspReconciled":false,"complete":true,"inPlay":false,"crossMatching":true,"runnersVoidable":false,"numberOfActiveRunners":2,"betDelay":0,"status":"OPEN","runners":[{"status":"ACTIVE","sortPriority":1,"id":11772759,"name":"Juan Pablo Varillas"},{"status":"ACTIVE","sortPriority":2,"id":9631075,"name":"Carlos Taberner"}],"regulators":["MR_INT"],"countryCode":"AR","discountAllowed":true,"timezone":"UTC","openDate":"2020-02-02T13:52:00.000Z","version":3149006717,"name":"Set 1 Winner","eventName":"Jua Varillas v Taberner"}}]}
{"op":"mcm","clk":"1010541032","pt":1580651909531,"mc":[{"id":"1.168222850","rc":[{"batb":[[0,1.89,2],[1,1.88,17.15],[2,1.01,11.01]],"ltp":0.0,"tv":0.0,"id":9631075},{"batb":[[0,2.02,2],[1,2,28.25],[2,1.01,11.01]],"ltp":0.0,"tv":0.0,"id":11772759}]}]}
{"op":"mcm","clk":"1010550516","pt":1580651968685,"mc":[{"id":"1.168222850","rc":[{"batb":[[0,2,28.25],[1,1.01,11.01],[2,1.01,0]],"ltp":0.0,"tv":0.0,"id":11772759}]}]}
{"op":"mcm","clk":"1010550555","pt":1580651968895,"mc":[{"id":"1.168222850","rc":[{"batb":[[0,1.88,17.15],[1,1.01,11.01],[2,1.01,0]],"ltp":0.0,"tv":0.0,"id":9631075}]}]}
{"op":"mcm","clk":"1010551482","pt":1580651975088,"mc":[{"id":"1.168222850","rc":[{"batb":[[1,1.01,12.69]],"ltp":0.0,"tv":0.0,"id":9631075},{"batb":[[1,1.01,12.69]],"ltp":0.0,"tv":0.0,"id":11772759}]}]}
{"op":"mcm","clk":"1010551646","pt":1580651976165,"mc":[{"id":"1.168222850","rc":[{"batb":[[1,1.01,12.35]],"ltp":0.0,"tv":0.0,"id":9631075}]}]}
{"op":"mcm","clk":"1010551836","pt":1580651977648,"mc":[{"id":"1.168222850","rc":[{"batb":[[0,1.89,1.34],[1,1.88,17.15],[2,1.01,11.01]],"ltp":0.0,"tv":0.0,"id":9631075},{"batb":[[1,1.01,12.26]],"ltp":0.0,"tv":0.0,"id":11772759}]}]}
{"op":"mcm","clk":"1010551872","pt":1580651977872,"mc":[{"id":"1.168222850","rc":[{"batb":[[0,2.02,1.25],[1,2,28.25],[2,1.01,11.01]],"ltp":0.0,"tv":0.0,"id":11772759}]}]}
{"op":"mcm","clk":"1010554174","pt":1580651993016,"mc":[{"id":"1.168222850","rc":[{"batb":[[0,1.89,3.34]],"ltp":0.0,"tv":0.0,"id":9631075},{"batb":[[0,2.02,3.25]],"ltp":0.0,"tv":0.0,"id":11772759}]}]}
{"op":"mcm","clk":"1010565114","pt":1580652052232,"mc":[{"id":"1.168222850","rc":[{"batb":[[0,1.89,1.34]],"ltp":0.0,"tv":0.0,"id":9631075},{"batb":[[0,2.02,1.25]],"ltp":0.0,"tv":0.0,"id":11772759}]}]}
{"op":"mcm","clk":"1010566847","pt":1580652062316,"mc":[{"id":"1.168222850","rc":[{"batb":[[1,1.86,17.55]],"ltp":0.0,"tv":0.0,"id":9631075},{"batb":[[1,2,27.62]],"ltp":0.0,"tv":0.0,"id":11772759}]}]}
{"op":"mcm","clk":"1010570994","pt":1580652085756,"mc":[{"id":"1.168222850","rc":[{"batb":[[2,1.85,48.73]],"batl":[[0,2.04,40.33],[1,2.94,4.54]],"ltp":0.0,"tv":0.0,"id":9631075},{"batb":[[2,1.97,42.85]],"batl":[[0,2.18,35.29],[1,2.96,4.54]],"ltp":0.0,"tv":0.0,"id":11772759}]}]}
{"op":"mcm","clk":"1010581506","pt":1580652141652,"mc":[{"id":"1.168222850","rc":[{"batb":[[1,1.87,17.47]],"ltp":0.0,"tv":0.0,"id":9631075}]}]}
{"op":"mcm","clk":"1010593176","pt":1580652196412,"mc":[{"id":"1.168222850","rc":[{"batb":[[1,1.85,66.59],[2,1.01,11.01]],"ltp":0.0,"tv":0.0,"id":9631075},{"batb":[[0,2.02,28.4],[1,1.97,42.85],[2,1.01,11.01]],"ltp":0.0,"tv":0.0,"id":11772759}]}]}
{"op":"mcm","clk":"1010595461","pt":1580652206524,"mc":[{"id":"1.168222850","rc":[{"batb":[[1,1.86,17.7],[2,1.85,48.73]],"ltp":0.0,"tv":0.0,"id":9631075}]}]}
{"op":"mcm","clk":"1010616517","pt":1580652300397,"mc":[{"id":"1.168222850","rc":[{"batb":[[2,1.84,49.57]],"batl":[[0,2.02,41.17]],"ltp":0.0,"tv":0.0,"id":9631075},{"batl":[[0,2.2,34.45]],"ltp":0.0,"tv":0.0,"id":11772759}]}]}
{"op":"mcm","clk":"1010631641","pt":1580652368523,"mc":[{"id":"1.168222850","marketDefinition":{"bspMarket":false,"turnInPlayEnabled":true,"persistenceEnabled":true,"marketBaseRate":5.0,"eventId":"29681551","eventTypeId":"2","numberOfWinners":1,"bettingType":"ODDS","marketType":"SET_WINNER","marketTime":"2020-02-02T13:52:00.000Z","suspendTime":"2020-02-02T13:52:00.000Z","bspReconciled":false,"complete":true,"inPlay":true,"crossMatching":true,"runnersVoidable":false,"numberOfActiveRunners":2,"betDelay":3,"status":"OPEN","runners":[{"status":"ACTIVE","sortPriority":1,"id":11772759,"name":"Juan Pablo Varillas"},{"status":"ACTIVE","sortPriority":2,"id":9631075,"name":"Carlos Taberner"}],"regulators":["MR_INT"],"countryCode":"AR","discountAllowed":true,"timezone":"UTC","openDate":"2020-02-02T13:52:00.000Z","version":3149113297,"name":"Set 1 Winner","eventName":"Jua Varillas v Taberner"},"rc":[{"batb":[[0,1.01,10.51],[1,1.86,0],[2,1.84,0]],"ltp":0.0,"tv":0.0,"id":9631075},{"batb":[[0,1.01,10.51],[1,1.97,0],[2,1.01,0]],"ltp":0.0,"tv":0.0,"id":11772759}]}]}
{"op":"mcm","clk":"1010635523","pt":1580652386668,"mc":[{"id":"1.168222850","rc":[{"batb":[[0,1.73,22.19],[1,1.63,27.22],[2,1.01,10.51]],"ltp":0.0,"tv":0.0,"id":9631075},{"batb":[[0,2.18,21.56],[1,1.99,28.48],[2,1.64,130.32]],"ltp":0.0,"tv":0.0,"id":11772759}]}]}
{"op":"mcm","clk":"1010635747","pt":1580652387751,"mc":[{"id":"1.168222850","rc":[{"batb":[[0,1.74,56.29],[1,1.73,22.19],[2,1.63,27.22]],"batl":[[0,1.93,42.01]],"ltp":0.0,"tv":0.0,"id":9631075},{"batb":[[1,2.08,38.65],[2,1.99,28.48]],"batl":[[0,2.34,31.09]],"ltp":0.0,"tv":0.0,"id":11772759}]}]}
{"op":"mcm","clk":"1010637391","pt":1580652395378,"mc":[{"id":"1.168222850","rc":[{"batb":[[0,1.8,122.93],[1,1.78,183.43],[2,1.74,56.29]],"batl":[[0,1.87,114.06],[1,1.89,153.57],[2,1.93,42.01]],"ltp":0.0,"tv":0.0,"id":9631075}]}]}
{"op":"mcm","clk":"1010639649","pt":1580652404544,"mc":[{"id":"1.168222850","rc":[{"batb":[[0,1.63,27.22],[1,1.01,10.51],[2,1.74,0]],"ltp":0.0,"tv":0.0,"id":9631075},{"batb":[[0,1.99,28.48],[1,1.01,10.51],[2,1.99,0]],"ltp":0.0,"tv":0.0,"id":11772759}]}]}
{"op":"mcm","clk":"1010640487","pt":1580652407747,"mc":[{"id":"1.168222850","rc":[{"batb":[[0,1.64,26.67]],"ltp":0.0,"tv":0.0,"id":9631075},{"batb":[[0,1.98,29.19]],"ltp":0.0,"tv":0.0,"id":11772759}]}]}
{"op":"mcm","clk":"1010640961","pt":1580652409450,"mc":[{"id":"1.168222850","rc":[{"batb":[[0,1.83,107.78],[1,1.81,173.59],[2,1.64,26.67]],"batl":[[0,1.9,105.26],[1,1.92,146.34]],"ltp":0.0,"tv":0.0,"id":9631075}]}]}
{"op":"mcm","clk":"1010641068","pt":1580652410002,"mc":[{"id":"1.168222850","rc":[{"batb":[[0,1.64,26.67],[1,1.01,10.51],[2,1.64,0]],"ltp":0.0,"tv":0.0,"id":9631075}]}]}
{"op":"mcm","clk":"1010641981","pt":1580652413679,"mc":[{"id":"1.168222850","rc":[{"batb":[[0,1.82,189.46],[1,1.8,176.95],[2,1.64,26.67]],"ltp":0.0,"tv":0.0,"id":9631075}]}]}
{"op":"mcm","clk":"1010642025","pt":1580652413889,"mc":[{"id":"1.168222850","rc":[{"batb":[[0,1.64,26.67],[1,1.01,10.51],[2,1.64,0]],"ltp":0.0,"tv":0.0,"id":9631075}]}]}
{"op":"mcm","clk":"1010642568","pt":1580652416396,"mc":[{"id":"1.168222850","rc":[{"batb":[[0,1.71,187.16],[1,1.69,219.1],[2,1.64,26.67]],"batl":[[0,2.04,119.92],[1,2.06,118.64]],"ltp":0.0,"tv":0.0,"id":9631075}]}]}
{"op":"mcm","clk":"1010646421","pt":1580652433498,"mc":[{"id":"1.168222850","rc":[{"batl":[[0,1.78,137.85],[1,1.8,179.05]],"ltp":0.0,"tv":0.0,"id":9631075}]}]}
{"op":"mcm","clk":"1010646657","pt":1580652434508,"mc":[{"id":"1.168222850","rc":[{"batb":[[0,2.36,17.55],[1,2.16,22.27],[2,1.01,10.51]],"ltp":0.0,"tv":0.0,"id":11772759}]}]}
{"op":"mcm","clk":"1010646953","pt":1580652435741,"mc":[{"id":"1.168222850","rc":[{"batb":[[1,1.69,279.59]],"ltp":0.0,"tv":0.0,"id":9631075},{"batb":[[1,2.16,58.4]],"batl":[[0,2.44,28.57]],"ltp":0.0,"tv":0.0,"id":11772759}]}]}
{"op":"mcm","clk":"1010647216","pt":1580652436615,"mc":[{"id":"1.168222850","rc":[{"batl":[[2,1.86,42.01]],"ltp":0.0,"tv":0.0,"id":9631075}]}]}
{"op":"mcm","clk":"1010651262","pt":1580652453422,"mc":[{"id":"1.168222850","rc":[{"batb":[[0,1.69,60.49],[1,1.58,30.53],[2,1.01,10.51]],"batl":[[0,1.86,42.01],[1,1.8,0],[2,1.86,0]],"ltp":0.0,"tv":0.0,"id":9631075},{"batb":[[0,2.16,58.4],[1,1.01,10.51],[2,1.01,0]],"ltp":0.0,"tv":0.0,"id":11772759}]}]}
{"op":"mcm","clk":"1010651587","pt":1580652454414,"mc":[{"id":"1.168222850","rc":[{"batb":[[0,1.58,30.53],[1,1.01,10.51],[2,1.01,0]],"ltp":0.0,"tv":0.0,"id":9631075},{"batb":[[0,2.16,22.27]],"ltp":0.0,"tv":0.0,"id":11772759}]}]}
{"op":"mcm","clk":"1010652696","pt":1580652459323,"mc":[{"id":"1.168222850","rc":[{"batb":[[0,1.73,160.16],[1,1.71,210.25],[2,1.58,30.53]],"batl":[[0,1.8,142.49],[1,1.82,172.83]],"ltp":0.0,"tv":0.0,"id":9631075}]}]}
{"op":"mcm","clk":"1010653845","pt":1580652464716,"mc":[{"id":"1.168222850","rc":[{"batb":[[0,1.58,30.53],[1,1.01,10.51],[2,1.58,0]],"ltp":0.0,"tv":0.0,"id":9631075}]}]}
{"op":"mcm","clk":"1010654386","pt":1580652467333,"mc":[{"id":"1.168222850","rc":[{"batb":[[0,1.66,159.3],[1,1.65,119.91],[2,1.58,30.53]],"batl":[[0,1.88,106.6],[1,1.9,151.14]],"ltp":0.0,"tv":0.0,"id":9631075}]}]}
{"op":"mcm","clk":"1010655208","pt":1580652470757,"mc":[{"id":"1.168222850","rc":[{"batb":[[0,1.58,30.53],[1,1.01,10.51],[2,1.58,0]],"ltp":0.0,"tv":0.0,"id":9631075}]}]}
{"op":"mcm","clk":"1010655843","pt":1580652473477,"mc":[{"id":"1.168222850","rc":[{"batb":[[0,1.81,122.49],[1,1.79,180.1],[2,1.76,54.61]],"batl":[[2,1.95,42.01]],"ltp":0.0,"tv":0.0,"id":9631075},{"batb":[[1,2.06,39.49],[2,1.01,10.51]],"batl":[[0,2.32,31.09]],"ltp":0.0,"tv":0.0,"id":11772759}]}]}
{"op":"mcm","clk":"1010656099","pt":1580652474572,"mc":[{"id":"1.168222850","rc":[{"batb":[[2,1.76,75.86]],"ltp":0.0,"tv":0.0,"id":9631075},{"batb":[[2,1.93,15.74]],"ltp":0.0,"tv":0.0,"id":11772759}]}]}
{"op":"mcm","clk":"1010660227","pt":1580652490511,"mc":[{"id":"1.168222850","rc":[{"batb":[[0,1.64,26.67],[1,1.01,10.51],[2,1.76,0]],"ltp":0.0,"tv":0.0,"id":9631075},{"batb":[[0,1.93,15.74],[1,1.01,10.51],[2,1.93,0]],"ltp":0.0,"tv":0.0,"id":11772759}]}]}
{"op":"mcm","clk":"1010660899","pt":1580652493070,"mc":[{"id":"1.168222850","rc":[{"batb":[[0,1.71,137.33],[1,1.69,218.91],[2,1.64,26.67]],"batl":[[0,2.1,194.28],[1,2.12,109.26]],"ltp":0.0,"tv":0.0,"id":9631075}]}]}
{"op":"mcm","clk":"1010665059","pt":1580652510539,"mc":[{"id":"1.168222850","rc":[{"batl":[[0,1.78,185.15],[1,1.8,178.91]],"ltp":0.0,"tv":0.0,"id":9631075}]}]}
{"op":"mcm","clk":"1010665286","pt":1580652511482,"mc":[{"id":"1.168222850","rc":[{"batb":[[1,1.69,279.4]],"batl":[[2,1.86,42.01]],"ltp":0.0,"tv":0.0,"id":9631075},{"batb":[[0,2.36,17.55],[1,2.16,58.24],[2,1.01,10.51]],"batl":[[0,2.44,28.57]],"ltp":0.0,"tv":0.0,"id":11772759}]}]}
{"op":"mcm","clk":"1010668828","pt":1580652525542,"mc":[{"id":"1.168222850","rc":[{"trd":[[2.36,34.64]],"batb":[[0,2.16,58.46],[1,1.01,10.51],[2,1.01,0]],"ltp":2.36,"tv":34.64,"id":11772759}],"tv":34.64}]}
{"op":"mcm","clk":"1010670622","pt":1580652532745,"mc":[{"id":"1.168222850","rc":[{"batb":[[0,1.58,30.92],[1,1.01,10.51],[2,1.64,0]],"ltp":0.0,"tv":0.0,"id":9631075},{"batb":[[0,2.16,22.11]],"ltp":2.36,"tv":34.64,"id":11772759}]}]}
{"op":"mcm","clk":"1010671352","pt":1580652535663,"mc":[{"id":"1.168222850","rc":[{"batb":[[0,1.66,135.23],[1,1.65,119.84],[2,1.61,30.29]],"batl":[[0,1.87,110.93],[1,1.89,153.61]],"ltp":0.0,"tv":0.0,"id":9631075}]}]}
{"op":"mcm","clk":"1010672959","pt":1580652542690,"mc":[{"id":"1.168222850","rc":[{"batl":[[0,1.72,145.54],[1,1.74,199.99]],"ltp":0.0,"tv":0.0,"id":9631075},{"batb":[[0,2.48,15.19],[1,2.26,19.59],[2,2.16,22.11]],"ltp":2.36,"tv":34.64,"id":11772759}]}]}
{"op":"mcm","clk":"1010673128","pt":1580652543456,"mc":[{"id":"1.168222850","rc":[{"batb":[[2,1.64,65.54]],"batl":[[2,1.79,42.01]],"ltp":0.0,"tv":0.0,"id":9631075},{"batb":[[1,2.26,52.36],[2,1.01,10.51]],"batl":[[0,2.56,26.89]],"ltp":2.36,"tv":34.64,"id":11772759}]}]}
{"op":"mcm","clk":"1010679368","pt":1580652571187,"mc":[{"id":"1.168222850","rc":[{"trd":[[2.48,29.98]],"batb":[[0,2.26,52.55],[1,1.01,10.51],[2,1.01,0]],"ltp":2.48,"tv":64.62,"id":11772759}],"tv":64.62}]}
{"op":"mcm","clk":"1010681174","pt":1580652579201,"mc":[{"id":"1.168222850","rc":[{"batb":[[0,1.64,65.54],[1,1.61,29.98],[2,1.49,40.21]],"batl":[[0,1.79,42.01],[1,1.74,0],[2,1.79,0]],"ltp":0.0,"tv":0.0,"id":9631075}]}]}
{"op":"mcm","clk":"1010682083","pt":1580652583110,"mc":[{"id":"1.168222850","rc":[{"batb":[[2,1.52,271.54]],"batl":[[1,1.83,164.3],[2,1.85,164.09]],"ltp":0.0,"tv":0.0,"id":9631075}]}]}
{"op":"mcm","clk":"1010685737","pt":1580652599228,"mc":[{"id":"1.168222850","rc":[{"batb":[[1,1.52,271.54],[2,1.51,168.36]],"ltp":0.0,"tv":0.0,"id":9631075},{"batb":[[0,2.26,52.36]],"ltp":2.48,"tv":64.62,"id":11772759}]}]}
{"op":"mcm","clk":"1010686043","pt":1580652600644,"mc":[{"id":"1.168222850","rc":[{"batb":[[0,1.52,271.54],[1,1.51,168.36],[2,1.49,40.21]],"batl":[[0,1.83,164.3],[1,1.85,164.09],[2,1.85,0]],"ltp":0.0,"tv":0.0,"id":9631075},{"batb":[[0,2.26,19.59]],"ltp":2.48,"tv":64.62,"id":11772759}]}]}
{"op":"mcm","clk":"1010686533","pt":1580652602621,"mc":[{"id":"1.168222850","rc":[{"batb":[[0,1.51,39.03],[1,1.01,10.51],[2,1.49,0]],"ltp":0.0,"tv":0.0,"id":9631075},{"batb":[[0,2.22,20.54]],"ltp":2.48,"tv":64.62,"id":11772759}]}]}
{"op":"mcm","clk":"1010687179","pt":1580652605573,"mc":[{"id":"1.168222850","rc":[{"batb":[[0,1.75,205.05],[1,1.73,202.2],[2,1.71,58.81]],"batl":[[2,1.88,42.01]],"ltp":0.0,"tv":0.0,"id":9631075},{"batb":[[1,2.14,36.13],[2,1.01,10.51]],"batl":[[0,2.4,29.41]],"ltp":2.48,"tv":64.62,"id":11772759}]}]}
{"op":"mcm","clk":"1010687369","pt":1580652606342,"mc":[{"id":"1.168222850","rc":[{"batb":[[1,1.74,23.21],[2,1.73,202.2]],"ltp":0.0,"tv":0.0,"id":9631075},{"batb":[[2,2.06,25.57]],"batl":[[1,2.5,196.61]],"ltp":2.48,"tv":64.62,"id":11772759}]}]}
{"op":"mcm","clk":"1010690472","pt":1580652619752,"mc":[{"id":"1.168222850","rc":[{"batb":[[0,1.71,58.81],[1,1.61,30.37],[2,1.52,425.49]],"batl":[[0,1.88,42.01],[1,1.85,0],[2,1.88,0]],"ltp":0.0,"tv":0.0,"id":9631075},{"batb":[[0,2.14,36.13],[1,2.06,25.57],[2,1.74,404.28]],"batl":[[1,2.5,0]],"ltp":2.48,"tv":64.62,"id":11772759}]}]}
{"op":"mcm","clk":"1010690639","pt":1580652620574,"mc":[{"id":"1.168222850","rc":[{"batb":[[0,1.61,30.37],[1,1.52,425.49],[2,1.01,10.51]],"ltp":0.0,"tv":0.0,"id":9631075},{"batb":[[0,2.06,25.57],[1,1.74,404.28],[2,1.01,10.51]],"ltp":2.48,"tv":64.62,"id":11772759}]}]}
{"op":"mcm","clk":"1010691134","pt":1580652622679,"mc":[{"id":"1.168222850","rc":[{"batb":[[0,1.63,169.68],[1,1.62,128.2],[2,1.61,30.37]],"batl":[[0,1.93,167.87],[1,1.95,139.57]],"ltp":0.0,"tv":0.0,"id":9631075}]}]}
{"op":"mcm","clk":"1010691284","pt":1580652623447,"mc":[{"id":"1.168222850","rc":[{"batb":[[0,1.61,30.37],[1,1.52,425.49],[2,1.01,10.51]],"ltp":0.0,"tv":0.0,"id":9631075},{"batb":[[0,2.08,25.26]],"ltp":2.48,"tv":64.62,"id":11772759}]}]}
{"op":"mcm","clk":"1010691443","pt":1580652624209,"mc":[{"id":"1.168222850","rc":[{"batb":[[1,1.01,10.51],[2,1.01,0]],"ltp":0.0,"tv":0.0,"id":9631075}]}]}
{"op":"mcm","clk":"1010691912","pt":1580652626273,"mc":[{"id":"1.168222850","rc":[{"batb":[[0,1.84,185.15],[1,1.82,170.67],[2,1.61,30.37]],"batl":[[0,1.93,167.87],[1,1.95,139.57]],"ltp":0.0,"tv":0.0,"id":9631075}]}]}
{"op":"mcm","clk":"1010692179","pt":1580652627466,"mc":[{"id":"1.168222850","rc":[{"batb":[[0,1.85,19.12],[1,1.84,185.15],[2,1.82,170.67]],"batl":[[1,1.95,181.58]],"ltp":0.0,"tv":0.0,"id":9631075},{"batb":[[1,2.04,40.33],[2,1.97,29.74]],"batl":[[0,2.28,32.77]],"ltp":2.48,"tv":64.62,"id":11772759}]}]}
{"op":"mcm","clk":"1010694317","pt":1580652636697,"mc":[{"id":"1.168222850","rc":[{"batb":[[0,1.74,23.53],[1,1.58,416.47],[2,1.01,10.51]],"ltp":0.0,"tv":0.0,"id":9631075},{"batb":[[0,1.97,29.74],[1,1.74,404.28],[2,1.01,10.51]],"ltp":2.48,"tv":64.62,"id":11772759}]}]}
{"op":"mcm","clk":"1010694944","pt":1580652639717,"mc":[{"id":"1.168222850","rc":[{"batb":[[0,1.73,23.53]],"ltp":0.0,"tv":0.0,"id":9631075}]}]}
{"op":"mcm","clk":"1010695381","pt":1580652641584,"mc":[{"id":"1.168222850","rc":[{"batb":[[0,1.82,181.32],[1,1.8,176.96],[2,1.73,23.53]],"batl":[[0,1.9,117.59],[1,1.92,146.36]],"ltp":0.0,"tv":0.0,"id":9631075}]}]}
{"op":"mcm","clk":"1010696663","pt":1580652647448,"mc":[{"id":"1.168222850","rc":[{"batb":[[0,1.73,23.53],[1,1.58,416.47],[2,1.01,10.51]],"ltp":0.0,"tv":0.0,"id":9631075}]}]}
{"op":"mcm","clk":"1010697279","pt":1580652650295,"mc":[{"id":"1.168222850","rc":[{"batb":[[0,1.74,207.29],[1,1.73,23.53],[2,1.72,206.27]],"batl":[[0,2,132.24],[1,2.02,125.67]],"ltp":0.0,"tv":0.0,"id":9631075}]}]}
{"op":"mcm","clk":"1010698508","pt":1580652655604,"mc":[{"id":"1.168222850","rc":[{"batl":[[0,1.82,173.34],[1,1.84,166.88],[2,1.86,42.01]],"ltp":0.0,"tv":0.0,"id":9631075},{"batb":[[0,2.24,20.22],[1,2.14,36.13],[2,2.06,25.73]],"batl":[[0,2.44,28.57]],"ltp":2.48,"tv":64.62,"id":11772759}]}]}
{"op":"mcm","clk":"1010701593","pt":1580652669749,"mc":[{"id":"1.168222850","rc":[{"batb":[[0,1.7,59.65],[1,1.58,448.73],[2,1.01,10.51]],"batl":[[0,1.86,42.01],[1,1.84,0],[2,1.86,0]],"ltp":0.0,"tv":0.0,"id":9631075},{"batb":[[0,2.14,36.13],[1,2.06,25.73],[2,1.74,404.28]],"ltp":2.48,"tv":64.62,"id":11772759}]}]}
{"op":"mcm","clk":"1010701800","pt":1580652670754,"mc":[{"id":"1.168222850","rc":[{"batb":[[0,1.58,448.73],[1,1.01,10.51],[2,1.01,0]],"ltp":0.0,"tv":0.0,"id":9631075},{"batb":[[0,2.06,25.73],[1,1.74,404.28],[2,1.01,10.51]],"batl":[[0,2.42,29.41]],"ltp":2.48,"tv":64.62,"id":11772759}]}]}
{"op":"mcm","clk":"1010702174","pt":1580652672362,"mc":[{"id":"1.168222850","rc":[{"batb":[[0,1.6,212.7],[1,1.59,137.55],[2,1.58,448.73]],"batl":[[0,1.93,123.73],[1,1.95,139.61]],"ltp":0.0,"tv":0.0,"id":9631075}]}]}
{"op":"mcm","clk":"1010702884","pt":1580652675564,"mc":[{"id":"1.168222850","rc":[{"batb":[[2,1.58,32.26]],"ltp":0.0,"tv":0.0,"id":9631075},{"batb":[[1,1.01,10.51],[2,1.01,0]],"ltp":2.48,"tv":64.62,"id":11772759}]}]}
{"op":"mcm","clk":"1010703184","pt":1580652676659,"mc":[{"id":"1.168222850","rc":[{"batl":[[0,1.66,146.05],[1,1.68,225.16]],"ltp":0.0,"tv":0.0,"id":9631075}]}]}
{"op":"mcm","clk":"1010703386","pt":1580652677563,"mc":[{"id":"1.168222850","rc":[{"batb":[[1,1.59,208.13]],"batl":[[2,1.73,42.01]],"ltp":0.0,"tv":0.0,"id":9631075},{"batb":[[0,2.56,14.08],[1,2.38,30.25],[2,2.22,20.77]],"batl":[[0,2.72,24.37]],"ltp":2.48,"tv":64.62,"id":11772759}]}]}
{"op":"mcm","clk":"1010707644","pt":1580652697262,"mc":[{"id":"1.168222850","rc":[{"batb":[[0,1.59,70.58],[1,1.41,50.44],[2,1.4,451]],"batl":[[0,1.73,42.01],[1,1.68,0],[2,1.73,0]],"ltp":0.0,"tv":0.0,"id":9631075},{"batb":[[0,2.38,30.25],[1,2.22,20.77],[2,1.92,394.91]],"ltp":2.48,"tv":64.62,"id":11772759}]}]}
{"op":"mcm","clk":"1010707937","pt":1580652698650,"mc":[{"id":"1.168222850","rc":[{"batb":[[0,1.41,50.44],[1,1.4,451],[2,1.01,10.51]],"ltp":0.0,"tv":0.0,"id":9631075},{"batb":[[0,2.22,20.77],[1,1.92,394.91],[2,1.01,10.51]],"ltp":2.48,"tv":64.62,"id":11772759}]}]}
{"op":"mcm","clk":"1010708341","pt":1580652700420,"mc":[{"id":"1.168222850","rc":[{"batl":[[0,1.83,156.31],[1,1.85,164.11]],"ltp":0.0,"tv":0.0,"id":9631075}]}]}
{"op":"mcm","clk":"1010708590","pt":1580652701566,"mc":[{"id":"1.168222850","rc":[{"batb":[[1,1.01,10.51],[2,1.01,0]],"ltp":0.0,"tv":0.0,"id":9631075},{"batb":[[1,1.01,10.51],[2,1.01,0]],"ltp":2.48,"tv":64.62,"id":11772759}]}]}
{"op":"mcm","clk":"1010709051","pt":1580652703703,"mc":[{"id":"1.168222850","rc":[{"batb":[[0,1.76,115.16],[1,1.74,197.98],[2,1.41,50.44]],"batl":[[2,1.86,42.01]],"ltp":0.0,"tv":0.0,"id":9631075},{"batb":[[1,2.16,36.13],[2,1.01,10.51]],"ltp":2.48,"tv":64.62,"id":11772759}]}]}
{"op":"mcm","clk":"1010709259","pt":1580652704572,"mc":[{"id":"1.168222850","rc":[{"batb":[[1,1.75,22.98],[2,1.74,197.98]],"ltp":0.0,"tv":0.0,"id":9631075},{"batb":[[2,2.02,27.46]],"batl":[[0,2.42,29.41]],"ltp":2.48,"tv":64.62,"id":11772759}]}]}
{"op":"mcm","clk":"1010711918","pt":1580652716304,"mc":[{"id":"1.168222850","rc":[{"batl":[[2,1.86,0]],"ltp":0.0,"tv":0.0,"id":9631075}]}]}
{"op":"mcm","clk":"1010712536","pt":1580652719207,"mc":[{"id":"1.168222850","rc":[{"batl":[[2,1.87,42.01]],"ltp":0.0,"tv":0.0,"id":9631075}]}]}
{"op":"mcm","clk":"1010712814","pt":1580652720612,"mc":[{"id":"1.168222850","rc":[{"batb":[[0,1.58,32.89],[1,1.52,425.49],[2,1.01,10.51]],"ltp":0.0,"tv":0.0,"id":9631075},{"batb":[[0,2.02,27.46],[1,1.74,404.28],[2,1.01,10.51]],"ltp":2.48,"tv":64.62,"id":11772759}]}]}
{"op":"mcm","clk":"1010713354","pt":1580652723141,"mc":[{"id":"1.168222850","rc":[{"batb":[[0,1.59,221.85],[1,1.58,173.79],[2,1.52,425.49]],"batl":[[0,1.96,108.55],[1,1.98,133.37]],"ltp":0.0,"tv":0.0,"id":9631075}]}]}
{"op":"mcm","clk":"1010714149","pt":1580652726650,"mc":[{"id":"1.168222850","rc":[{"batb":[[0,1.58,32.89],[1,1.52,425.49],[2,1.01,10.51]],"ltp":0.0,"tv":0.0,"id":9631075}]}]}
{"op":"mcm","clk":"1010714578","pt":1580652728672,"mc":[{"id":"1.168222850","rc":[{"batb":[[1,1.01,10.51],[2,1.01,0]],"ltp":0.0,"tv":0.0,"id":9631075}]}]}
{"op":"mcm","clk":"1010714787","pt":1580652729671,"mc":[{"id":"1.168222850","rc":[{"batb":[[0,1.88,139.53],[1,1.86,159.03],[2,1.58,32.89]],"ltp":0.0,"tv":0.0,"id":9631075}]}]}
{"op":"mcm","clk":"1010714983","pt":1580652730565,"mc":[{"id":"1.168222850","rc":[{"batb":[[0,1.9,17.62],[1,1.88,139.53],[2,1.86,159.03]],"ltp":0.0,"tv":0.0,"id":9631075},{"batb":[[1,1.81,19.36],[2,1.74,404.28]],"ltp":2.48,"tv":64.62,"id":11772759}]}]}
{"op":"mcm","clk":"1010715200","pt":1580652731531,"mc":[{"id":"1.168222850","rc":[{"batl":[[2,1.99,42.01]],"ltp":0.0,"tv":0.0,"id":9631075},{"batb":[[1,2,42.01],[2,1.81,19.36]],"batl":[[0,2.24,33.61]],"ltp":2.48,"tv":64.62,"id":11772759}]}]}
{"op":"mcm","clk":"1010717430","pt":1580652741275,"mc":[{"id":"1.168222850","rc":[{"batb":[[1,1.88,107.34]],"ltp":0.0,"tv":0.0,"id":9631075}]}]}
{"op":"mcm","clk":"1010718132","pt":1580652744272,"mc":[{"id":"1.168222850","rc":[{"batl":[[0,1.96,139.47]],"ltp":0.0,"tv":0.0,"id":9631075}]}]}
{"op":"mcm","clk":"1010721902","pt":1580652761541,"mc":[{"id":"1.168222850","rc":[{"batb":[[0,1.8,52.09],[1,1.77,22.19],[2,1.58,416.47]],"batl":[[0,1.99,42.01],[1,1.98,0],[2,1.99,0]],"ltp":0.0,"tv":0.0,"id":9631075},{"batb":[[0,2,42.01],[1,1.81,19.36],[2,1.74,404.28]],"ltp":2.48,"tv":64.62,"id":11772759}]}]}
{"op":"mcm","clk":"1010722166","pt":1580652762627,"mc":[{"id":"1.168222850","rc":[{"batb":[[0,1.77,22.19],[1,1.58,416.47],[2,1.01,10.51]],"ltp":0.0,"tv":0.0,"id":9631075},{"batb":[[0,1.81,19.36],[1,1.74,404.28],[2,1.01,10.51]],"ltp":2.48,"tv":64.62,"id":11772759}]}]}
{"op":"mcm","clk":"1010722629","pt":1580652764681,"mc":[{"id":"1.168222850","rc":[{"batb":[[0,1.76,168.79],[1,1.74,198.16],[2,1.58,416.47]],"ltp":0.0,"tv":0.0,"id":9631075},{"batb":[[0,1.81,19.2]],"ltp":2.48,"tv":64.62,"id":11772759}]}]}
{"op":"mcm","clk":"1010723316","pt":1580652767741,"mc":[{"id":"1.168222850","rc":[{"batb":[[2,1.73,57.13]],"batl":[[0,1.83,126.78],[1,1.85,164.26],[2,1.88,42.01]],"ltp":0.0,"tv":0.0,"id":9631075},{"batb":[[0,2.2,21.32],[1,2.12,36.97],[2,1.98,29.19]],"batl":[[0,2.38,30.25]],"ltp":2.48,"tv":64.62,"id":11772759}]}]}
{"op":"mcm","clk":"1010726871","pt":1580652783293,"mc":[{"id":"1.168222850","rc":[{"batb":[[0,1.73,57.13],[1,1.66,27.38],[2,1.58,416.47]],"batl":[[0,1.88,42.01],[1,1.85,0],[2,1.88,0]],"ltp":0.0,"tv":0.0,"id":9631075},{"batb":[[0,2.12,36.97],[1,1.98,29.19],[2,1.74,404.28]],"ltp":2.48,"tv":64.62,"id":11772759}]}]}
{"op":"mcm","clk":"1010727157","pt":1580652784620,"mc":[{"id":"1.168222850","rc":[{"batb":[[0,1.66,27.38],[1,1.58,416.47],[2,1.01,10.51]],"ltp":0.0,"tv":0.0,"id":9631075},{"batb":[[0,1.98,29.19],[1,1.74,404.28],[2,1.01,10.51]],"ltp":2.48,"tv":64.62,"id":11772759}]}]}
{"op":"mcm","clk":"1010727417","pt":1580652785717,"mc":[{"id":"1.168222850","rc":[{"batb":[[0,1.68,124.46],[1,1.66,260.6],[2,1.58,416.47]],"batl":[[0,2,99.78],[1,2.02,125.71]],"ltp":0.0,"tv":0.0,"id":9631075}]}]}
{"op":"mcm","clk":"1010730738","pt":1580652799632,"mc":[{"id":"1.168222850","rc":[{"batb":[[0,1.66,27.38],[1,1.58,416.47],[2,1.01,10.51]],"ltp":0.0,"tv":0.0,"id":9631075}]}]}
{"op":"mcm","clk":"1010731443","pt":1580652802648,"mc":[{"id":"1.168222850","rc":[{"batb":[[1,1.01,10.51],[2,1.01,0]],"ltp":0.0,"tv":0.0,"id":9631075},{"batb":[[1,1.01,10.51],[2,1.01,0]],"ltp":2.48,"tv":64.62,"id":11772759}]}]}
{"op":"mcm","clk":"1010731705","pt":1580652803626,"mc":[{"id":"1.168222850","rc":[{"batb":[[0,1.93,16.6],[1,1.92,119.32],[2,1.9,148.66]],"batl":[[0,2,99.78],[1,2.02,125.71],[2,2.06,39.49]],"ltp":0.0,"tv":0.0,"id":9631075},{"batb":[[1,1.96,43.69],[2,1.75,21.64]],"batl":[[0,2.18,35.29]],"ltp":2.48,"tv":64.62,"id":11772759}]}]}
{"op":"mcm","clk":"1010736945","pt":1580652825650,"mc":[{"id":"1.168222850","rc":[{"batb":[[0,1.84,49.57],[1,1.77,22.03],[2,1.62,415.43]],"batl":[[0,2.06,39.49],[1,2.02,0],[2,2.06,0]],"ltp":0.0,"tv":0.0,"id":9631075},{"batb":[[0,1.96,43.69],[1,1.75,21.64],[2,1.62,415.43]],"ltp":2.48,"tv":64.62,"id":11772759}]}]}
{"op":"mcm","clk":"1010737191","pt":1580652826757,"mc":[{"id":"1.168222850","rc":[{"batb":[[0,1.77,22.03],[1,1.62,415.43],[2,1.01,10.51]],"ltp":0.0,"tv":0.0,"id":9631075},{"batb":[[0,1.75,21.64],[1,1.62,415.43],[2,1.01,10.51]],"ltp":2.48,"tv":64.62,"id":11772759}]}]}
{"op":"mcm","clk":"1010737683","pt":1580652828642,"mc":[{"id":"1.168222850","rc":[{"batb":[[0,1.77,177],[1,1.76,22.27],[2,1.75,194.39]],"batl":[[0,2.34,146.88],[1,2.38,159.93]],"ltp":0.0,"tv":0.0,"id":9631075}]}]}
{"op":"mcm","clk":"1010737747","pt":1580652828873,"mc":[{"id":"1.168222850","rc":[{"batb":[[0,1.77,154.97]],"ltp":0.0,"tv":0.0,"id":9631075},{"batb":[[0,1.75,21.4]],"ltp":2.48,"tv":64.62,"id":11772759}]}]}
{"op":"mcm","clk":"1010738691","pt":1580652832598,"mc":[{"id":"1.168222850","rc":[{"batb":[[0,1.76,22.27],[1,1.62,415.43],[2,1.01,10.51]],"ltp":0.0,"tv":0.0,"id":9631075}]}]}
{"op":"mcm","clk":"1010738890","pt":1580652833490,"mc":[{"id":"1.168222850","rc":[{"batb":[[1,1.01,10.51],[2,1.01,0]],"ltp":0.0,"tv":0.0,"id":9631075},{"batb":[[1,1.01,10.51],[2,1.01,0]],"ltp":2.48,"tv":64.62,"id":11772759}]}]}
{"op":"mcm","clk":"1010739391","pt":1580652835607,"mc":[{"id":"1.168222850","rc":[{"batl":[[0,2.34,31.09]],"ltp":0.0,"tv":0.0,"id":9631075},{"batb":[[0,1.75,236.47],[1,1.73,201.98],[2,1.01,10.51]],"batl":[[0,1.82,123.11],[1,1.84,166.94]],"ltp":2.48,"tv":64.62,"id":11772759}]}]}
{"op":"mcm","clk":"1010739658","pt":1580652836617,"mc":[{"id":"1.168222850","rc":[{"batb":[[0,2.2,22.42],[1,2.1,37.81],[2,1.97,15.82]],"ltp":0.0,"tv":0.0,"id":9631075},{"batb":[[0,1.75,181.02],[1,1.74,56.29],[2,1.73,201.98]],"ltp":2.48,"tv":64.62,"id":11772759}]}]}
{"op":"mcm","clk":"1010740048","pt":1580652838310,"mc":[{"id":"1.168222850","rc":[{"batl":[[0,2.36,30.25]],"ltp":0.0,"tv":0.0,"id":9631075},{"batl":[[2,1.91,42.01]],"ltp":2.48,"tv":64.62,"id":11772759}]}]}
{"op":"mcm","clk":"1010744557","pt":1580652857456,"mc":[{"id":"1.168222850","rc":[{"batb":[[0,2.1,37.81],[1,1.97,15.82],[2,1.77,402.27]],"ltp":0.0,"tv":0.0,"id":9631075},{"batb":[[0,1.74,56.29],[1,1.54,33.75],[2,1.5,426.9]],"batl":[[0,1.91,42.01],[1,1.84,0],[2,1.91,0]],"ltp":2.48,"tv":64.62,"id":11772759}]}]}
{"op":"mcm","clk":"1010744858","pt":1580652858732,"mc":[{"id":"1.168222850","rc":[{"batb":[[0,1.97,15.82],[1,1.77,402.27],[2,1.01,10.51]],"ltp":0.0,"tv":0.0,"id":9631075},{"batb":[[0,1.54,33.75],[1,1.5,426.9],[2,1.01,10.51]],"ltp":2.48,"tv":64.62,"id":11772759}]}]}
{"op":"mcm","clk":"1010745169","pt":1580652860038,"mc":[{"id":"1.168222850","rc":[{"batb":[[1,1.51,178.82],[2,1.5,599.06]],"batl":[[0,2.04,124.32],[1,2.06,118.67]],"ltp":2.48,"tv":64.62,"id":11772759}]}]}
{"op":"mcm","clk":"1010745546","pt":1580652861757,"mc":[{"id":"1.168222850","rc":[{"batb":[[1,1.5,426.9],[2,1.01,10.51]],"ltp":2.48,"tv":64.62,"id":11772759}]}]}
{"op":"mcm","clk":"1010746147","pt":1580652863658,"mc":[{"id":"1.168222850","rc":[{"batb":[[1,1.01,10.51],[2,1.01,0]],"ltp":2.48,"tv":64.62,"id":11772759}]}]}
{"op":"mcm","clk":"1010746673","pt":1580652865661,"mc":[{"id":"1.168222850","rc":[{"batb":[[2,1.75,22.98]],"ltp":0.0,"tv":0.0,"id":9631075},{"batb":[[0,1.95,167.34],[1,1.93,141.56],[2,1.67,25.1]],"ltp":2.48,"tv":64.62,"id":11772759}]}]}
{"op":"mcm","clk":"1010746783","pt":1580652866151,"mc":[{"id":"1.168222850","rc":[{"batb":[[1,1.91,45.37],[2,1.77,402.27]],"batl":[[0,2.12,36.97]],"ltp":0.0,"tv":0.0,"id":9631075},{"batb":[[2,1.89,47.05]],"batl":[[2,2.1,37.81]],"ltp":2.48,"tv":64.62,"id":11772759}]}]}
{"op":"mcm","clk":"1010750427","pt":1580652881685,"mc":[{"id":"1.168222850","rc":[{"batb":[[0,1.91,45.37],[1,1.77,402.27],[2,1.75,22.98]],"ltp":0.0,"tv":0.0,"id":9631075},{"batb":[[0,1.89,47.05],[1,1.67,25.1],[2,1.58,416.47]],"batl":[[0,2.1,37.81],[1,2.06,0],[2,2.1,0]],"ltp":2.48,"tv":64.62,"id":11772759}]}]}
{"op":"mcm","clk":"1010750863","pt":1580652883597,"mc":[{"id":"1.168222850","rc":[{"batb":[[0,1.77,402.27],[1,1.75,22.98],[2,1.01,10.51]],"ltp":0.0,"tv":0.0,"id":9631075},{"batb":[[0,1.67,25.1],[1,1.58,416.47],[2,1.01,10.51]],"ltp":2.48,"tv":64.62,"id":11772759}]}]}
{"op":"mcm","clk":"1010751081","pt":1580652884581,"mc":[{"id":"1.168222850","rc":[{"batb":[[1,1.65,156.42],[2,1.64,122.48]],"batl":[[0,2.32,122.57],[1,2.34,83.04]],"ltp":2.48,"tv":64.62,"id":11772759}]}]}
{"op":"mcm","clk":"1010753549","pt":1580652895598,"mc":[{"id":"1.168222850","rc":[{"batb":[[1,1.58,416.47],[2,1.01,10.51]],"ltp":2.48,"tv":64.62,"id":11772759}]}]}
{"op":"mcm","clk":"1010754017","pt":1580652897604,"mc":[{"id":"1.168222850","rc":[{"batb":[[0,1.75,22.98],[1,1.01,10.51],[2,1.01,0]],"ltp":0.0,"tv":0.0,"id":9631075},{"batb":[[1,1.01,10.51],[2,1.01,0]],"ltp":2.48,"tv":64.62,"id":11772759}]}]}
{"op":"mcm","clk":"1010754304","pt":1580652898701,"mc":[{"id":"1.168222850","rc":[{"batb":[[0,1.76,138.14],[1,1.75,22.98],[2,1.74,198.15]],"batl":[[0,1.83,134.71],[1,1.85,164.25]],"ltp":0.0,"tv":0.0,"id":9631075},{"batb":[[0,2.22,20.69],[1,1.93,15.74],[2,1.67,25.1]],"ltp":2.48,"tv":64.62,"id":11772759}]}]}
{"op":"mcm","clk":"1010754528","pt":1580652899688,"mc":[{"id":"1.168222850","rc":[{"batb":[[1,1.75,78.43]],"batl":[[2,1.92,42.01]],"ltp":0.0,"tv":0.0,"id":9631075},{"batb":[[1,2.1,37.81],[2,1.93,15.74]],"batl":[[0,2.36,30.25]],"ltp":2.48,"tv":64.62,"id":11772759}]}]}
{"op":"mcm","clk":"1010759395","pt":1580652920722,"mc":[{"id":"1.168222850","rc":[{"batb":[[0,1.61,30.45],[1,1.52,425.49],[2,1.01,10.51]],"ltp":0.0,"tv":0.0,"id":9631075},{"batb":[[0,1.93,15.74],[1,1.74,404.28],[2,1.01,10.51]],"ltp":2.48,"tv":64.62,"id":11772759}]}]}
{"op":"mcm","clk":"1010760046","pt":1580652923572,"mc":[{"id":"1.168222850","rc":[{"batb":[[0,1.65,133.84],[1,1.64,122.58],[2,1.61,30.45]],"batl":[[0,2.08,174.08],[1,2.1,112.28]],"ltp":0.0,"tv":0.0,"id":9631075}]}]}
{"op":"mcm","clk":"1010760632","pt":1580652925888,"mc":[{"id":"1.168222850","rc":[{"batb":[[1,1.01,10.51],[2,1.01,0]],"ltp":2.48,"tv":64.62,"id":11772759}]}]}
{"op":"mcm","clk":"1010761062","pt":1580652927709,"mc":[{"id":"1.168222850","rc":[{"batl":[[0,1.71,158.52],[1,1.73,203.96]],"ltp":0.0,"tv":0.0,"id":9631075}]}]}
{"op":"mcm","clk":"1010761258","pt":1580652928565,"mc":[{"id":"1.168222850","rc":[{"batb":[[0,1.65,197.69]],"batl":[[2,1.8,42.01]],"ltp":0.0,"tv":0.0,"id":9631075},{"batb":[[0,2.48,15.11],[1,2.26,19.83],[2,2.24,33.61]],"batl":[[0,2.56,26.89]],"ltp":2.48,"tv":64.62,"id":11772759}]}]}
{"op":"mcm","clk":"1010763082","pt":1580652936623,"mc":[{"id":"1.168222850","rc":[{"batl":[[0,1.71,115.89]],"ltp":0.0,"tv":0.0,"id":9631075}]}]}
{"op":"mcm","clk":"1010763770","pt":1580652939525,"mc":[{"id":"1.168222850","rc":[{"batb":[[0,1.65,241.93]],"ltp":0.0,"tv":0.0,"id":9631075}]}]}
{"op":"mcm","clk":"1010763898","pt":1580652939971,"mc":[{"id":"1.168222850","rc":[{"batb":[[2,1.61,30.14]],"ltp":0.0,"tv":0.0,"id":9631075},{"batb":[[1,2.24,53.67],[2,1.86,398.62]],"ltp":2.48,"tv":64.62,"id":11772759}]}]}
{"op":"mcm","clk":"1010765781","pt":1580652948033,"mc":[{"id":"1.168222850","rc":[{"batb":[[2,1.62,30.06]],"ltp":0.0,"tv":0.0,"id":9631075}]}]}
{"op":"mcm","clk":"1010769544","pt":1580652964271,"mc":[{"id":"1.168222850","rc":[{"batb":[[2,1.62,29.74]],"ltp":0.0,"tv":0.0,"id":9631075},{"batb":[[0,2.46,15.5]],"ltp":2.48,"tv":64.62,"id":11772759}]}]}
{"op":"mcm","clk":"1010771717","pt":1580652973670,"mc":[{"id":"1.168222850","rc":[{"batb":[[2,1.63,29.35]],"ltp":0.0,"tv":0.0,"id":9631075},{"batb":[[0,2.44,15.74],[1,2.24,33.61],[2,2.22,20.69]],"ltp":2.48,"tv":64.62,"id":11772759}]}]}
{"op":"mcm","clk":"1010774998","pt":1580652988506,"mc":[{"id":"1.168222850","rc":[{"batb":[[2,1.63,29.03]],"ltp":0.0,"tv":0.0,"id":9631075},{"batb":[[2,2.2,20.93]],"ltp":2.48,"tv":64.62,"id":11772759}]}]}
{"op":"mcm","clk":"1010779469","pt":1580653008264,"mc":[{"id":"1.168222850","rc":[{"batb":[[0,1.65,63.85],[1,1.49,40.44],[2,1.44,436.18]],"batl":[[0,1.8,42.01],[1,1.73,0],[2,1.8,0]],"ltp":0.0,"tv":0.0,"id":9631075},{"batb":[[0,2.24,33.61],[1,2.2,20.93],[2,1.86,398.62]],"ltp":2.48,"tv":64.62,"id":11772759}]}]}
{"op":"mcm","clk":"1010779644","pt":1580653008933,"mc":[{"id":"1.168222850","rc":[{"batb":[[0,1.49,40.44],[1,1.44,436.18],[2,1.01,10.51]],"ltp":0.0,"tv":0.0,"id":9631075},{"batb":[[0,2.2,20.93],[1,1.86,398.62],[2,1.01,10.51]],"ltp":2.48,"tv":64.62,"id":11772759}]}]}
{"op":"mcm","clk":"1010780115","pt":1580653011158,"mc":[{"id":"1.168222850","rc":[{"batb":[[0,1.51,195.11],[1,1.5,172.42],[2,1.49,40.44]],"batl":[[0,1.83,163.12],[1,1.85,164.04]],"ltp":0.0,"tv":0.0,"id":9631075}]}]}
{"op":"mcm","clk":"1010780892","pt":1580653014626,"mc":[{"id":"1.168222850","rc":[{"batb":[[1,1.01,10.51],[2,1.01,0]],"ltp":2.48,"tv":64.62,"id":11772759}]}]}
{"op":"mcm","clk":"1010781099","pt":1580653015652,"mc":[{"id":"1.168222850","rc":[{"batl":[[0,1.56,169.41],[1,1.57,142.3]],"ltp":0.0,"tv":0.0,"id":9631075}]}]}
{"op":"mcm","clk":"1010781311","pt":1580653016640,"mc":[{"id":"1.168222850","rc":[{"batb":[[0,1.52,80.66],[1,1.51,195.11],[2,1.5,172.42]],"ltp":0.0,"tv":0.0,"id":9631075},{"batb":[[0,2.82,10.78],[1,2.48,15.19],[2,1.01,10.51]],"batl":[[0,2.92,21.85]],"ltp":2.48,"tv":64.62,"id":11772759}]}]}
{"op":"mcm","clk":"1010781648","pt":1580653018254,"mc":[{"id":"1.168222850","rc":[{"batb":[[2,2.04,394.09]],"ltp":2.48,"tv":64.62,"id":11772759}]}]}
{"op":"mcm","clk":"1010782001","pt":1580653019725,"mc":[{"id":"1.168222850","rc":[{"batl":[[2,1.65,42.01]],"ltp":0.0,"tv":0.0,"id":9631075},{"batb":[[1,2.54,26.89],[2,2.48,15.19]],"ltp":2.48,"tv":64.62,"id":11772759}]}]}
{"op":"mcm","clk":"1010783601","pt":1580653027148,"mc":[{"id":"1.168222850","rc":[{"batb":[[1,1.36,59.25],[2,1.34,465.43]],"batl":[[0,1.65,42.01],[1,1.57,0],[2,1.65,0]],"ltp":0.0,"tv":0.0,"id":9631075},{"batb":[[0,2.54,26.89],[1,2.48,15.19],[2,2.04,394.09]],"ltp":2.48,"tv":64.62,"id":11772759}]}]}
{"op":"mcm","clk":"1010784139","pt":1580653029448,"mc":[{"id":"1.168222850","rc":[{"batb":[[0,1.36,59.25],[1,1.34,465.43],[2,1.01,10.51]],"ltp":0.0,"tv":0.0,"id":9631075},{"batb":[[0,2.48,15.19],[1,2.04,394.09],[2,1.01,10.51]],"ltp":2.48,"tv":64.62,"id":11772759}]}]}
{"op":"mcm","clk":"1010784392","pt":1580653030668,"mc":[{"id":"1.168222850","rc":[{"batb":[[0,1.36,454.08],[1,1.35,277.72],[2,1.34,465.43]],"batl":[[0,1.68,123.22],[1,1.7,216.3]],"ltp":0.0,"tv":0.0,"id":9631075}]}]}
{"op":"mcm","clk":"1010784467","pt":1580653031009,"mc":[{"id":"1.168222850","rc":[{"batb":[[0,1.36,59.25],[1,1.34,465.43],[2,1.01,10.51]],"ltp":0.0,"tv":0.0,"id":9631075}]}]}
{"op":"mcm","clk":"1010784987","pt":1580653033383,"mc":[{"id":"1.168222850","rc":[{"batb":[[0,1.48,180.01],[1,1.47,187.25],[2,1.36,59.25]],"batl":[[0,1.53,236.51],[1,1.54,152.6]],"ltp":0.0,"tv":0.0,"id":9631075}]}]}
{"op":"mcm","clk":"1010785975","pt":1580653038029,"mc":[{"id":"1.168222850","rc":[{"batb":[[0,1.36,59.25],[1,1.34,465.43],[2,1.01,10.51]],"ltp":0.0,"tv":0.0,"id":9631075}]}]}
{"op":"mcm","clk":"1010786581","pt":1580653040961,"mc":[{"id":"1.168222850","rc":[{"batb":[[0,1.36,462.09],[1,1.35,277.74],[2,1.34,465.43]],"batl":[[0,1.68,116.79],[1,1.7,216.29]],"ltp":0.0,"tv":0.0,"id":9631075}]}]}
{"op":"mcm","clk":"1010789797","pt":1580653055718,"mc":[{"id":"1.168222850","rc":[{"batb":[[0,1.36,59.25],[1,1.34,465.43],[2,1.01,10.51]],"ltp":0.0,"tv":0.0,"id":9631075}]}]}
{"op":"mcm","clk":"1010790008","pt":1580653056655,"mc":[{"id":"1.168222850","rc":[{"batb":[[1,1.01,10.51],[2,1.01,0]],"ltp":0.0,"tv":0.0,"id":9631075},{"batb":[[1,1.01,10.51],[2,1.01,0]],"ltp":2.48,"tv":64.62,"id":11772759}]}]}
{"op":"mcm","clk":"1010790553","pt":1580653058759,"mc":[{"id":"1.168222850","rc":[{"batb":[[0,1.62,215.22],[1,1.61,161.62],[2,1.45,45.08]],"ltp":0.0,"tv":0.0,"id":9631075},{"batb":[[1,2.2,21.17],[2,1.01,10.51]],"ltp":2.48,"tv":64.62,"id":11772759}]}]}
{"op":"mcm","clk":"1010790797","pt":1580653059735,"mc":[{"id":"1.168222850","rc":[{"batb":[[1,1.61,229.68]],"batl":[[2,1.75,42.01]],"ltp":0.0,"tv":0.0,"id":9631075},{"batb":[[1,2.34,31.09],[2,2.2,21.17]],"batl":[[0,2.64,25.21]],"ltp":2.48,"tv":64.62,"id":11772759}]}]}
{"op":"mcm","clk":"1010793781","pt":1580653073691,"mc":[{"id":"1.168222850","rc":[{"batb":[[0,1.61,98.43],[1,1.45,45.08],[2,1.44,436.18]],"batl":[[0,1.75,42.01],[1,1.7,0],[2,1.75,0]],"ltp":0.0,"tv":0.0,"id":9631075}]}]}
{"op":"mcm","clk":"1010793890","pt":1580653074189,"mc":[{"id":"1.168222850","rc":[{"batb":[[0,1.61,68.06]],"ltp":0.0,"tv":0.0,"id":9631075},{"batb":[[0,2.34,31.09],[1,2.2,21.17],[2,1.86,398.62]],"ltp":2.48,"tv":64.62,"id":11772759}]}]}
{"op":"mcm","clk":"1010794029","pt":1580653074881,"mc":[{"id":"1.168222850","rc":[{"batb":[[0,1.45,45.08],[1,1.44,436.18],[2,1.01,10.51]],"ltp":0.0,"tv":0.0,"id":9631075},{"batb":[[0,2.2,21.17],[1,1.86,398.62],[2,1.01,10.51]],"ltp":2.48,"tv":64.62,"id":11772759}]}]}
{"op":"mcm","clk":"1010794390","pt":1580653076600,"mc":[{"id":"1.168222850","rc":[{"batb":[[0,1.46,247.61],[1,1.45,243.95],[2,1.44,436.18]],"batl":[[0,1.82,147.9],[1,1.84,166.88]],"ltp":0.0,"tv":0.0,"id":9631075}]}]}
{"op":"mcm","clk":"1010794652","pt":1580653077697,"mc":[{"id":"1.168222850","rc":[{"batb":[[0,1.45,45.08],[1,1.44,436.18],[2,1.01,10.51]],"ltp":0.0,"tv":0.0,"id":9631075}]}]}
{"op":"mcm","clk":"1010795078","pt":1580653079667,"mc":[{"id":"1.168222850","rc":[{"batb":[[1,1.01,10.51],[2,1.01,0]],"ltp":0.0,"tv":0.0,"id":9631075}]}]}
{"op":"mcm","clk":"1010795277","pt":1580653080591,"mc":[{"id":"1.168222850","rc":[{"batb":[[0,1.75,133.54],[1,1.73,201.87],[2,1.45,45.08]],"ltp":0.0,"tv":0.0,"id":9631075}]}]}
{"op":"mcm","clk":"1010795538","pt":1580653081685,"mc":[{"id":"1.168222850","rc":[{"batb":[[0,1.76,22.58],[1,1.75,133.54],[2,1.73,201.87]],"ltp":0.0,"tv":0.0,"id":9631075},{"batb":[[1,2.02,27.3],[2,1.86,398.62]],"ltp":2.48,"tv":64.62,"id":11772759}]}]}
{"op":"mcm","clk":"1010795563","pt":1580653081796,"mc":[{"id":"1.168222850","rc":[{"batl":[[2,1.87,42.01]],"ltp":0.0,"tv":0.0,"id":9631075},{"batb":[[1,2.16,36.13],[2,2.02,27.3]],"batl":[[0,2.42,29.41]],"ltp":2.48,"tv":64.62,"id":11772759}]}]}
{"op":"mcm","clk":"1010798620","pt":1580653096156,"mc":[{"id":"1.168222850","rc":[{"batb":[[0,1.7,59.65],[1,1.59,31.94],[2,1.52,425.49]],"batl":[[0,1.87,42.01],[1,1.84,0],[2,1.87,0]],"ltp":0.0,"tv":0.0,"id":9631075},{"batb":[[0,2.16,36.13],[1,2.02,27.3],[2,1.86,398.62]],"ltp":2.48,"tv":64.62,"id":11772759}]}]}
{"op":"mcm","clk":"1010798860","pt":1580653097096,"mc":[{"id":"1.168222850","rc":[{"batb":[[0,1.59,31.94],[1,1.52,425.49],[2,1.01,10.51]],"ltp":0.0,"tv":0.0,"id":9631075},{"batb":[[0,2.02,27.3],[1,1.86,398.62],[2,1.01,10.51]],"ltp":2.48,"tv":64.62,"id":11772759}]}]}
{"op":"mcm","clk":"1010799191","pt":1580653098632,"mc":[{"id":"1.168222850","rc":[{"batb":[[0,1.59,279.64],[1,1.58,140.93],[2,1.52,425.49]],"batl":[[0,1.94,115.33],[1,1.96,137.43]],"ltp":0.0,"tv":0.0,"id":9631075}]}]}
{"op":"mcm","clk":"1010800578","pt":1580653104921,"mc":[{"id":"1.168222850","rc":[{"batb":[[2,1.01,10.51]],"ltp":0.0,"tv":0.0,"id":9631075}]}]}
{"op":"mcm","clk":"1010800898","pt":1580653106633,"mc":[{"id":"1.168222850","rc":[{"batl":[[0,1.65,126.7],[1,1.66,116.65]],"ltp":0.0,"tv":0.0,"id":9631075}]}]}
{"op":"mcm","clk":"1010801108","pt":1580653107747,"mc":[{"id":"1.168222850","rc":[{"batb":[[2,1.4,53.43]],"ltp":0.0,"tv":0.0,"id":9631075},{"batb":[[0,2.54,14.24],[1,2.18,21.64],[2,1.86,398.62]],"ltp":2.48,"tv":64.62,"id":11772759}]}]}
{"op":"mcm","clk":"1010801264","pt":1580653108443,"mc":[{"id":"1.168222850","rc":[{"batb":[[0,1.59,350.22],[2,1.4,504.42]],"batl":[[2,1.72,42.01]],"ltp":0.0,"tv":0.0,"id":9631075},{"batb":[[1,2.38,30.25],[2,2.18,21.64]],"batl":[[0,2.72,24.37]],"ltp":2.48,"tv":64.62,"id":11772759}]}]}
{"op":"mcm","clk":"1010804331","pt":1580653124654,"mc":[{"id":"1.168222850","rc":[{"batb":[[0,1.59,70.58],[1,1.4,504.42],[2,1.01,10.51]],"batl":[[0,1.72,42.01],[1,1.66,0],[2,1.72,0]],"ltp":0.0,"tv":0.0,"id":9631075},{"batb":[[0,2.38,30.25],[1,2.18,21.64],[2,1.86,398.62]],"ltp":2.48,"tv":64.62,"id":11772759}]}]}
{"op":"mcm","clk":"1010804388","pt":1580653124878,"mc":[{"id":"1.168222850","rc":[{"batb":[[0,1.4,504.42],[1,1.01,10.51],[2,1.01,0]],"ltp":0.0,"tv":0.0,"id":9631075},{"batb":[[0,2.18,21.64],[1,1.86,398.62],[2,1.01,10.51]],"ltp":2.48,"tv":64.62,"id":11772759}]}]}
{"op":"mcm","clk":"1010804887","pt":1580653127470,"mc":[{"id":"1.168222850","rc":[{"batb":[[1,1.39,339.37],[2,1.38,249.16]],"batl":[[0,1.83,115.06],[1,1.85,164.14]],"ltp":0.0,"tv":0.0,"id":9631075}]}]}
{"op":"mcm","clk":"1010805034","pt":1580653128273,"mc":[{"id":"1.168222850","rc":[{"batb":[[1,1.01,10.51],[2,1.38,0]],"ltp":0.0,"tv":0.0,"id":9631075}]}]}
{"op":"mcm","clk":"1010805379","pt":1580653130039,"mc":[{"id":"1.168222850","rc":[{"batb":[[1,1.01,10.51],[2,1.01,0]],"ltp":2.48,"tv":64.62,"id":11772759}]}]}
{"op":"mcm","clk":"1010805616","pt":1580653131272,"mc":[{"id":"1.168222850","rc":[{"batb":[[0,1.55,191.67],[1,1.54,155.24],[2,1.4,504.42]],"batl":[[0,1.61,241.17],[1,1.62,126.64]],"ltp":0.0,"tv":0.0,"id":9631075}]}]}
{"op":"mcm","clk":"1010806074","pt":1580653133665,"mc":[{"id":"1.168222850","rc":[{"batb":[[0,1.4,504.42],[1,1.01,10.51],[2,1.4,0]],"ltp":0.0,"tv":0.0,"id":9631075},{"batb":[[1,1.97,394.86],[2,1.01,10.51]],"ltp":2.48,"tv":64.62,"id":11772759}]}]}
{"op":"mcm","clk":"1010806568","pt":1580653136345,"mc":[{"id":"1.168222850","rc":[{"batb":[[1,1.39,339.37],[2,1.38,249.16]],"batl":[[0,1.83,115.06],[1,1.85,164.14]],"ltp":0.0,"tv":0.0,"id":9631075}]}]}
{"op":"mcm","clk":"1010808472","pt":1580653146686,"mc":[{"id":"1.168222850","rc":[{"batb":[[1,1.01,10.51],[2,1.38,0]],"ltp":0.0,"tv":0.0,"id":9631075}]}]}
{"op":"mcm","clk":"1010809034","pt":1580653149597,"mc":[{"id":"1.168222850","rc":[{"batb":[[0,1.76,158.19],[1,1.74,198.04],[2,1.4,53.43]],"ltp":0.0,"tv":0.0,"id":9631075},{"batb":[[1,1.01,10.51],[2,1.01,0]],"ltp":2.48,"tv":64.62,"id":11772759}]}]}
{"op":"mcm","clk":"1010809224","pt":1580653150579,"mc":[{"id":"1.168222850","rc":[{"batb":[[0,1.77,22.11],[1,1.76,158.19],[2,1.74,198.04]],"batl":[[2,1.87,42.01]],"ltp":0.0,"tv":0.0,"id":9631075},{"batb":[[1,2.14,36.13],[2,1.98,29.11]],"batl":[[0,2.42,29.41]],"ltp":2.48,"tv":64.62,"id":11772759}]}]}
{"op":"mcm","clk":"1010813192","pt":1580653171657,"mc":[{"id":"1.168222850","rc":[{"batb":[[0,1.71,58.81],[1,1.58,32.65],[2,1.52,425.49]],"batl":[[0,1.87,42.01],[1,1.85,0],[2,1.87,0]],"ltp":0.0,"tv":0.0,"id":9631075},{"batb":[[0,2.14,36.13],[1,1.98,29.11],[2,1.74,404.28]],"ltp":2.48,"tv":64.62,"id":11772759}]}]}
{"op":"mcm","clk":"1010813457","pt":1580653173131,"mc":[{"id":"1.168222850","rc":[{"batb":[[0,1.58,32.65],[1,1.52,425.49],[2,1.01,10.51]],"ltp":0.0,"tv":0.0,"id":9631075},{"batb":[[0,1.98,29.11],[1,1.74,404.28],[2,1.01,10.51]],"ltp":2.48,"tv":64.62,"id":11772759}]}]}
{"op":"mcm","clk":"1010813758","pt":1580653174640,"mc":[{"id":"1.168222850","rc":[{"batb":[[0,1.58,288.54],[1,1.57,144.4],[2,1.52,425.49]],"batl":[[0,1.98,147.1],[1,2,129.36]],"ltp":0.0,"tv":0.0,"id":9631075},{"batb":[[0,1.99,28.88]],"ltp":2.48,"tv":64.62,"id":11772759}]}]}
{"op":"mcm","clk":"1010813895","pt":1580653175449,"mc":[{"id":"1.168222850","rc":[{"batb":[[0,1.58,32.65],[1,1.52,425.49],[2,1.01,10.51]],"ltp":0.0,"tv":0.0,"id":9631075}]}]}
{"op":"mcm","clk":"1010814497","pt":1580653178759,"mc":[{"id":"1.168222850","rc":[{"batb":[[0,1.72,183.39],[1,1.7,214.58],[2,1.58,32.65]],"batl":[[0,1.79,130.56],[1,1.81,175.88]],"ltp":0.0,"tv":0.0,"id":9631075}]}]}
{"op":"mcm","clk":"1010815114","pt":1580653182143,"mc":[{"id":"1.168222850","rc":[{"batb":[[0,1.58,32.65],[1,1.52,425.49],[2,1.01,10.51]],"ltp":0.0,"tv":0.0,"id":9631075}]}]}
{"op":"mcm","clk":"1010815638","pt":1580653185035,"mc":[{"id":"1.168222850","rc":[{"batb":[[0,1.58,288.54],[1,1.57,144.4],[2,1.52,425.49]],"batl":[[0,1.98,147.1],[1,2,129.36]],"ltp":0.0,"tv":0.0,"id":9631075}]}]}
{"op":"mcm","clk":"1010819849","pt":1580653206450,"mc":[{"id":"1.168222850","rc":[{"batb":[[2,1.01,10.51]],"batl":[[0,1.64,133.6],[1,1.65,119.11]],"ltp":0.0,"tv":0.0,"id":9631075},{"batb":[[1,1.01,10.51],[2,1.01,0]],"ltp":2.48,"tv":64.62,"id":11772759}]}]}
{"op":"mcm","clk":"1010820024","pt":1580653207256,"mc":[{"id":"1.168222850","rc":[{"batb":[[2,1.39,55.08]],"ltp":0.0,"tv":0.0,"id":9631075},{"batb":[[0,2.58,13.77],[1,2.22,20.77],[2,1.99,28.88]],"ltp":2.48,"tv":64.62,"id":11772759}]}]}
{"op":"mcm","clk":"1010820159","pt":1580653207846,"mc":[{"id":"1.168222850","rc":[{"batb":[[1,1.57,217.5]],"batl":[[2,1.71,42.01]],"ltp":0.0,"tv":0.0,"id":9631075},{"batb":[[1,2.4,29.41],[2,2.22,20.77]],"batl":[[0,2.76,23.53]],"ltp":2.48,"tv":64.62,"id":11772759}]}]}
{"op":"mcm","clk":"1010820547","pt":1580653209794,"mc":[{"id":"1.168222850","rc":[{"batb":[[2,1.4,451]],"ltp":0.0,"tv":0.0,"id":9631075}]}]}
{"op":"mcm","clk":"1010824919","pt":1580653229718,"mc":[{"id":"1.168222850","rc":[{"batb":[[0,1.58,32.65],[1,1.57,73.1]],"batl":[[0,1.71,42.01],[1,1.65,0],[2,1.71,0]],"ltp":0.0,"tv":0.0,"id":9631075}]}]}
{"op":"mcm","clk":"1010824986","pt":1580653230019,"mc":[{"id":"1.168222850","rc":[{"batb":[[0,1.57,73.1],[1,1.4,451],[2,1.39,55.08]],"ltp":0.0,"tv":0.0,"id":9631075},{"batb":[[0,2.4,29.41],[1,2.22,20.77],[2,1.92,394.91]],"ltp":2.48,"tv":64.62,"id":11772759}]}]}
{"op":"mcm","clk":"1010825178","pt":1580653230912,"mc":[{"id":"1.168222850","rc":[{"batb":[[0,1.4,451],[1,1.39,55.08],[2,1.01,10.51]],"ltp":0.0,"tv":0.0,"id":9631075},{"batb":[[0,2.22,20.77],[1,1.92,394.91],[2,1.01,10.51]],"ltp":2.48,"tv":64.62,"id":11772759}]}]}
{"op":"mcm","clk":"1010825544","pt":1580653232752,"mc":[{"id":"1.168222850","rc":[{"batb":[[1,1.39,242.51],[2,1.38,247.47]],"batl":[[0,1.82,133.39],[1,1.84,166.92]],"ltp":0.0,"tv":0.0,"id":9631075}]}]}
{"op":"mcm","clk":"1010825756","pt":1580653233732,"mc":[{"id":"1.168222850","rc":[{"batb":[[1,1.39,55.08],[2,1.01,10.51]],"ltp":0.0,"tv":0.0,"id":9631075}]}]}
{"op":"mcm","clk":"1010826383","pt":1580653236734,"mc":[{"id":"1.168222850","rc":[{"batb":[[0,1.75,148.79],[1,1.73,201.92],[2,1.39,55.08]],"ltp":0.0,"tv":0.0,"id":9631075},{"batb":[[1,1.01,10.51],[2,1.01,0]],"ltp":2.48,"tv":64.62,"id":11772759}]}]}
{"op":"mcm","clk":"1010826577","pt":1580653237747,"mc":[{"id":"1.168222850","rc":[{"batb":[[0,1.75,171.69],[2,1.56,33.83]],"ltp":0.0,"tv":0.0,"id":9631075},{"batb":[[1,2,28.25],[2,1.01,10.51]],"ltp":2.48,"tv":64.62,"id":11772759}]}]}
{"op":"mcm","clk":"1010826618","pt":1580653237931,"mc":[{"id":"1.168222850","rc":[{"batb":[[2,1.69,60.49]],"batl":[[2,1.85,42.01]],"ltp":0.0,"tv":0.0,"id":9631075},{"batb":[[1,2.18,35.29],[2,2,28.25]],"batl":[[0,2.44,28.57]],"ltp":2.48,"tv":64.62,"id":11772759}]}]}
{"op":"mcm","clk":"1010829271","pt":1580653251139,"mc":[{"id":"1.168222850","rc":[{"batb":[[0,1.69,60.49],[1,1.56,33.83],[2,1.5,426.9]],"batl":[[0,1.85,42.01],[1,1.84,0],[2,1.85,0]],"ltp":0.0,"tv":0.0,"id":9631075},{"batb":[[0,2.18,35.29],[1,2,28.25],[2,1.77,402.27]],"ltp":2.48,"tv":64.62,"id":11772759}]}]}
{"op":"mcm","clk":"1010829694","pt":1580653252992,"mc":[{"id":"1.168222850","rc":[{"batb":[[0,1.56,33.83],[1,1.5,426.9],[2,1.01,10.51]],"ltp":0.0,"tv":0.0,"id":9631075},{"batb":[[0,2,28.25],[1,1.77,402.27],[2,1.01,10.51]],"ltp":2.48,"tv":64.62,"id":11772759}]}]}
{"op":"mcm","clk":"1010830052","pt":1580653254351,"mc":[{"id":"1.168222850","rc":[{"batb":[[0,1.58,126.86],[1,1.57,143.83],[2,1.56,33.83]],"batl":[[0,1.97,163.95],[1,1.99,131.29]],"ltp":0.0,"tv":0.0,"id":9631075}]}]}
{"op":"mcm","clk":"1010830450","pt":1580653255757,"mc":[{"id":"1.168222850","rc":[{"batb":[[0,1.56,33.83],[1,1.5,426.9],[2,1.01,10.51]],"ltp":0.0,"tv":0.0,"id":9631075}]}]}
{"op":"mcm","clk":"1010830833","pt":1580653257381,"mc":[{"id":"1.168222850","rc":[{"batb":[[1,1.01,10.51],[2,1.01,0]],"ltp":0.0,"tv":0.0,"id":9631075}]}]}
{"op":"mcm","clk":"1010831128","pt":1580653258726,"mc":[{"id":"1.168222850","rc":[{"batb":[[0,1.88,151.29],[1,1.86,158.98],[2,1.56,33.83]],"ltp":0.0,"tv":0.0,"id":9631075}]}]}
{"op":"mcm","clk":"1010831340","pt":1580653259583,"mc":[{"id":"1.168222850","rc":[{"batb":[[0,1.91,17.23],[1,1.88,151.29],[2,1.86,158.98]],"ltp":0.0,"tv":0.0,"id":9631075},{"batb":[[1,1.78,20.46],[2,1.77,402.27]],"ltp":2.48,"tv":64.62,"id":11772759}]}]}
{"op":"mcm","clk":"1010831526","pt":1580653260514,"mc":[{"id":"1.168222850","rc":[{"batl":[[1,1.98,42.01],[2,1.99,131.29]],"ltp":0.0,"tv":0.0,"id":9631075},{"batb":[[0,2,70.26]],"batl":[[0,2.26,32.77]],"ltp":2.48,"tv":64.62,"id":11772759}]}]}
{"op":"mcm","clk":"1010833678","pt":1580653270608,"mc":[{"id":"1.168222850","rc":[{"batb":[[1,1.77,22.11],[2,1.58,416.47]],"batl":[[0,1.98,42.01],[1,1.98,0],[2,1.99,0]],"ltp":0.0,"tv":0.0,"id":9631075}]}]}
{"op":"mcm","clk":"1010834294","pt":1580653273611,"mc":[{"id":"1.168222850","rc":[{"batb":[[1,1.87,181.12],[2,1.85,161.85]],"batl":[[0,1.96,144.43],[1,1.98,175.36]],"ltp":0.0,"tv":0.0,"id":9631075},{"batl":[[0,2.24,33.61]],"ltp":2.48,"tv":64.62,"id":11772759}]}]}
{"op":"mcm","clk":"1010838820","pt":1580653294594,"mc":[{"id":"1.168222850","rc":[{"batb":[[0,1.8,52.09],[1,1.77,22.11],[2,1.58,416.47]],"batl":[[0,1.98,42.01],[1,1.98,0]],"ltp":0.0,"tv":0.0,"id":9631075},{"batb":[[0,2,42.01]],"ltp":2.48,"tv":64.62,"id":11772759}]}]}
{"op":"mcm","clk":"1010839032","pt":1580653295652,"mc":[{"id":"1.168222850","rc":[{"batb":[[0,1.77,22.11],[1,1.58,416.47],[2,1.01,10.51]],"ltp":0.0,"tv":0.0,"id":9631075},{"batb":[[0,1.78,20.46],[1,1.77,402.27],[2,1.01,10.51]],"ltp":2.48,"tv":64.62,"id":11772759}]}]}
{"op":"mcm","clk":"1010839460","pt":1580653297484,"mc":[{"id":"1.168222850","rc":[{"batb":[[0,1.76,22.27],[1,1.75,142.76],[2,1.73,202.03]],"batl":[[0,2.24,138.86],[1,2.26,91.26]],"ltp":0.0,"tv":0.0,"id":9631075},{"batb":[[0,1.78,20.3]],"ltp":2.48,"tv":64.62,"id":11772759}]}]}
{"op":"mcm","clk":"1010840272","pt":1580653301262,"mc":[{"id":"1.168222850","rc":[{"batl":[[0,1.82,139.53],[1,1.84,167.02]],"ltp":0.0,"tv":0.0,"id":9631075}]}]}
{"op":"mcm","clk":"1010840477","pt":1580653302195,"mc":[{"id":"1.168222850","rc":[{"batl":[[2,1.89,42.01]],"ltp":0.0,"tv":0.0,"id":9631075},{"batb":[[0,2.2,21.48],[1,2.12,36.97],[2,1.96,29.9]],"batl":[[0,2.4,29.41]],"ltp":2.48,"tv":64.62,"id":11772759}]}]}
{"op":"mcm","clk":"1010843515","pt":1580653315670,"mc":[{"id":"1.168222850","rc":[{"batb":[[0,1.72,57.97],[1,1.65,27.93],[2,1.58,416.47]],"batl":[[0,1.89,42.01],[1,1.84,0],[2,1.89,0]],"ltp":0.0,"tv":0.0,"id":9631075},{"batb":[[0,2.12,36.97],[1,1.96,29.9],[2,1.77,402.27]],"ltp":2.48,"tv":64.62,"id":11772759}]}]}
{"op":"mcm","clk":"1010843825","pt":1580653317176,"mc":[{"id":"1.168222850","rc":[{"batb":[[0,1.65,27.93],[1,1.58,416.47],[2,1.01,10.51]],"ltp":0.0,"tv":0.0,"id":9631075},{"batb":[[0,1.96,29.9],[1,1.77,402.27],[2,1.01,10.51]],"ltp":2.48,"tv":64.62,"id":11772759}]}]}
{"op":"mcm","clk":"1010844154","pt":1580653318593,"mc":[{"id":"1.168222850","rc":[{"batb":[[0,1.66,174.82],[1,1.65,147.94],[2,1.58,416.47]],"batl":[[0,2.02,207.08],[1,2.04,122.07]],"ltp":0.0,"tv":0.0,"id":9631075},{"batb":[[0,1.97,29.58],[1,1.96,29.9],[2,1.77,402.27]],"ltp":2.48,"tv":64.62,"id":11772759}]}]}
{"op":"mcm","clk":"1010844418","pt":1580653319684,"mc":[{"id":"1.168222850","rc":[{"batb":[[0,1.65,27.93],[1,1.58,416.47],[2,1.01,10.51]],"ltp":0.0,"tv":0.0,"id":9631075},{"batb":[[1,1.77,402.27],[2,1.01,10.51]],"ltp":2.48,"tv":64.62,"id":11772759}]}]}
{"op":"mcm","clk":"1010845028","pt":1580653322598,"mc":[{"id":"1.168222850","rc":[{"batb":[[0,1.78,155.18],[1,1.76,190.65],[2,1.65,27.93]],"batl":[[0,1.86,180.19],[1,1.88,156.06]],"ltp":0.0,"tv":0.0,"id":9631075}]}]}
{"op":"mcm","clk":"1010845212","pt":1580653323515,"mc":[{"id":"1.168222850","rc":[{"batl":[[0,2.2,2.27]],"ltp":2.48,"tv":64.62,"id":11772759}]}]}
{"op":"mcm","clk":"1010845859","pt":1580653326571,"mc":[{"id":"1.168222850","rc":[{"batb":[[0,1.65,27.93],[1,1.58,416.47],[2,1.01,10.51]],"ltp":0.0,"tv":0.0,"id":9631075}]}]}
{"op":"mcm","clk":"1010846333","pt":1580653329084,"mc":[{"id":"1.168222850","rc":[{"batb":[[0,1.66,174.82],[1,1.65,147.94],[2,1.58,416.47]],"batl":[[0,2.02,207.08],[1,2.04,122.07]],"ltp":0.0,"tv":0.0,"id":9631075}]}]}
{"op":"mcm","clk":"1010847411","pt":1580653334222,"mc":[{"id":"1.168222850","rc":[{"batb":[[2,1.01,10.51]],"ltp":0.0,"tv":0.0,"id":9631075},{"batb":[[1,1.01,10.51],[2,1.01,0]],"ltp":2.48,"tv":64.62,"id":11772759}]}]}
{"op":"mcm","clk":"1010847719","pt":1580653335717,"mc":[{"id":"1.168222850","rc":[{"trd":[[1.83,2.73]],"batl":[[0,1.73,206.42],[1,1.75,196.05]],"ltp":1.83,"tv":2.73,"id":9631075},{"trd":[[2.2,2.27]],"ltp":2.2,"tv":66.89,"id":11772759}],"tv":69.62}]}
{"op":"mcm","clk":"1010847894","pt":1580653336608,"mc":[{"id":"1.168222850","rc":[{"batb":[[1,1.65,211.8],[2,1.57,33.2]],"ltp":1.83,"tv":2.73,"id":9631075},{"batb":[[0,2.4,16.52],[1,2.2,21.48],[2,1.01,10.51]],"batl":[[0,2.52,26.89]],"ltp":2.2,"tv":66.89,"id":11772759}]}]}
{"op":"mcm","clk":"1010848194","pt":1580653338110,"mc":[{"id":"1.168222850","rc":[{"batb":[[2,1.86,398.62]],"ltp":2.2,"tv":66.89,"id":11772759}]}]}
{"op":"mcm","clk":"1010848396","pt":1580653339153,"mc":[{"id":"1.168222850","rc":[{"batl":[[2,1.8,42.01]],"ltp":1.83,"tv":2.73,"id":9631075},{"batb":[[1,2.24,33.61],[2,2.2,21.48]],"ltp":2.2,"tv":66.89,"id":11772759}]}]}
{"op":"mcm","clk":"1010851253","pt":1580653353334,"mc":[{"id":"1.168222850","rc":[{"batb":[[0,1.57,33.2],[1,1.44,436.18],[2,1.01,10.51]],"ltp":1.83,"tv":2.73,"id":9631075},{"batb":[[0,2.2,21.48],[1,1.86,398.62],[2,1.01,10.51]],"ltp":2.2,"tv":66.89,"id":11772759}]}]}
{"op":"mcm","clk":"1010851754","pt":1580653356042,"mc":[{"id":"1.168222850","rc":[{"batb":[[0,1.61,142.32],[1,1.6,134.17],[2,1.57,33.2]],"batl":[[0,1.83,118.01],[1,1.85,164.24]],"ltp":1.83,"tv":2.73,"id":9631075}]}]}
{"op":"mcm","clk":"1010852361","pt":1580653359356,"mc":[{"id":"1.168222850","rc":[{"batb":[[0,1.57,33.2],[1,1.44,436.18],[2,1.01,10.51]],"ltp":1.83,"tv":2.73,"id":9631075}]}]}
{"op":"mcm","clk":"1010852985","pt":1580653362755,"mc":[{"id":"1.168222850","rc":[{"batb":[[0,1.61,210.38],[1,1.6,134.17],[2,1.57,33.2]],"batl":[[0,1.67,199.33],[1,1.69,220.4],[2,1.75,42.01]],"ltp":1.83,"tv":2.73,"id":9631075},{"batb":[[0,2.58,13.61],[1,2.42,16.13],[2,2.32,31.09]],"batl":[[0,2.6,26.05]],"ltp":2.2,"tv":66.89,"id":11772759}]}]}
{"op":"mcm","clk":"1010855225","pt":1580653374661,"mc":[{"id":"1.168222850","rc":[{"batb":[[0,1.61,68.06],[1,1.57,33.2],[2,1.53,36.82]],"batl":[[0,1.75,42.01],[1,1.69,0],[2,1.75,0]],"ltp":1.83,"tv":2.73,"id":9631075}]}]}
{"op":"mcm","clk":"1010855322","pt":1580653375293,"mc":[{"id":"1.168222850","rc":[{"batb":[[0,1.53,36.67],[1,1.44,436.18],[2,1.01,10.51]],"ltp":1.83,"tv":2.73,"id":9631075},{"batb":[[0,2.42,16.13],[1,1.86,398.62],[2,1.01,10.51]],"ltp":2.2,"tv":66.89,"id":11772759}]}]}
{"op":"mcm","clk":"1010855775","pt":1580653377706,"mc":[{"id":"1.168222850","rc":[{"batb":[[0,1.58,228.12],[1,1.57,144.4],[2,1.53,36.67]],"batl":[[0,1.72,169.48],[1,1.74,199.96]],"ltp":1.83,"tv":2.73,"id":9631075}]}]}
{"op":"mcm","clk":"1010857115","pt":1580653384622,"mc":[{"id":"1.168222850","rc":[{"batb":[[1,1.01,10.51],[2,1.01,0]],"ltp":2.2,"tv":66.89,"id":11772759}]}]}
{"op":"mcm","clk":"1010857416","pt":1580653386295,"mc":[{"id":"1.168222850","rc":[{"batl":[[0,1.64,160.38],[1,1.65,119.12]],"ltp":1.83,"tv":2.73,"id":9631075}]}]}
{"op":"mcm","clk":"1010857641","pt":1580653387396,"mc":[{"id":"1.168222850","rc":[{"batb":[[0,2.7,12.12],[1,2.42,282.63],[2,2.4,16.6]],"ltp":2.2,"tv":66.89,"id":11772759}]}]}
{"op":"mcm","clk":"1010857899","pt":1580653388590,"mc":[{"id":"1.168222850","rc":[{"batb":[[0,1.58,300.38]],"ltp":1.83,"tv":2.73,"id":9631075},{"trd":[[2.7,24.23]],"batb":[[0,2.42,282.63],[1,2.4,16.6],[2,1.01,10.51]],"ltp":2.7,"tv":91.12,"id":11772759}],"tv":93.85}]}
{"op":"mcm","clk":"1010857959","pt":1580653388910,"mc":[{"id":"1.168222850","rc":[{"batb":[[0,2.4,16.6],[1,1.97,394.86]],"ltp":2.7,"tv":91.12,"id":11772759}]}]}
{"op":"mcm","clk":"1010858296","pt":1580653390589,"mc":[{"id":"1.168222850","rc":[{"batl":[[2,1.7,42.01]],"ltp":1.83,"tv":2.73,"id":9631075},{"batl":[[0,2.72,24.37]],"ltp":2.7,"tv":91.12,"id":11772759}]}]}
{"op":"mcm","clk":"1010858495","pt":1580653391481,"mc":[{"id":"1.168222850","rc":[{"batb":[[0,2.46,28.57],[1,2.4,16.6],[2,1.97,394.86]],"ltp":2.7,"tv":91.12,"id":11772759}]}]}
{"op":"mcm","clk":"1010858785","pt":1580653392721,"mc":[{"id":"1.168222850","rc":[{"batb":[[0,2.42,29.41]],"ltp":2.7,"tv":91.12,"id":11772759}]}]}
{"op":"mcm","clk":"1010859282","pt":1580653395440,"mc":[{"id":"1.168222850","rc":[{"batb":[[2,1.54,35.8]],"ltp":1.83,"tv":2.73,"id":9631075},{"batb":[[0,2.68,12.51],[1,2.42,29.41],[2,2.38,17.07]],"ltp":2.7,"tv":91.12,"id":11772759}]}]}
{"op":"mcm","clk":"1010859471","pt":1580653396296,"mc":[{"id":"1.168222850","rc":[{"batb":[[1,2.38,17.07],[2,1.97,394.86]],"ltp":2.7,"tv":91.12,"id":11772759}]}]}
{"op":"mcm","clk":"1010859948","pt":1580653398712,"mc":[{"id":"1.168222850","rc":[{"trd":[[2.68,21.85]],"batb":[[0,2.68,1.59],[1,2.46,28.57],[2,2.38,17.07]],"ltp":2.68,"tv":112.97,"id":11772759}],"tv":115.7}]}
{"op":"mcm","clk":"1010860896","pt":1580653403487,"mc":[{"id":"1.168222850","rc":[{"batb":[[2,1.55,35.33]],"ltp":1.83,"tv":2.73,"id":9631075},{"batb":[[0,2.66,12.67],[2,2.36,17.39]],"ltp":2.68,"tv":112.97,"id":11772759}]}]}
{"op":"mcm","clk":"1010864123","pt":1580653419687,"mc":[{"id":"1.168222850","rc":[{"batb":[[2,1.55,35.09]],"ltp":1.83,"tv":2.73,"id":9631075},{"batb":[[0,2.64,12.75]],"ltp":2.68,"tv":112.97,"id":11772759}]}]}
{"op":"mcm","clk":"1010865787","pt":1580653428577,"mc":[{"id":"1.168222850","rc":[{"batl":[[0,2.66,12.66],[1,2.72,24.37]],"ltp":2.68,"tv":112.97,"id":11772759}]}]}
{"op":"mcm","clk":"1010865998","pt":1580653429717,"mc":[{"id":"1.168222850","rc":[{"batl":[[0,2.72,24.37],[1,2.72,0]],"ltp":2.68,"tv":112.97,"id":11772759}]}]}
{"op":"mcm","clk":"1010876226","pt":1580653478753,"mc":[{"id":"1.168222850","rc":[{"batb":[[0,1.58,72.26],[1,1.55,35.09],[2,1.41,50.44]],"batl":[[0,1.7,42.01],[1,1.65,0],[2,1.7,0]],"ltp":1.83,"tv":2.73,"id":9631075}]}]}
{"op":"mcm","clk":"1010876360","pt":1580653479364,"mc":[{"id":"1.168222850","rc":[{"batb":[[0,1.41,50.44],[1,1.38,448.45],[2,1.01,10.51]],"ltp":1.83,"tv":2.73,"id":9631075},{"batb":[[0,2.36,17.39],[1,1.97,394.86],[2,1.01,10.51]],"ltp":2.68,"tv":112.97,"id":11772759}]}]}
{"op":"mcm","clk":"1010876866","pt":1580653481667,"mc":[{"id":"1.168222850","rc":[{"batb":[[0,1.44,324.09],[1,1.43,212.12],[2,1.41,50.44]],"batl":[[0,1.75,122.58],[1,1.77,189.17]],"ltp":1.83,"tv":2.73,"id":9631075}]}]}
{"op":"mcm","clk":"1010877092","pt":1580653482654,"mc":[{"id":"1.168222850","rc":[{"batb":[[0,1.41,50.44],[1,1.38,448.45],[2,1.01,10.51]],"ltp":1.83,"tv":2.73,"id":9631075}]}]}
{"op":"mcm","clk":"1010877856","pt":1580653486158,"mc":[{"id":"1.168222850","rc":[{"batb":[[0,1.55,244.66],[1,1.54,155.64],[2,1.41,50.44]],"batl":[[0,1.61,192.27],[1,1.62,126.96]],"ltp":1.83,"tv":2.73,"id":9631075}]}]}
{"op":"mcm","clk":"1010878102","pt":1580653487362,"mc":[{"id":"1.168222850","rc":[{"batb":[[0,1.41,50.44],[1,1.38,448.45],[2,1.01,10.51]],"ltp":1.83,"tv":2.73,"id":9631075}]}]}
{"op":"mcm","clk":"1010878746","pt":1580653490376,"mc":[{"id":"1.168222850","rc":[{"batb":[[0,1.44,324.09],[1,1.43,212.12],[2,1.41,50.44]],"batl":[[0,1.75,122.58],[1,1.77,189.17]],"ltp":1.83,"tv":2.73,"id":9631075}]}]}
{"op":"mcm","clk":"1010883080","pt":1580653510703,"mc":[{"id":"1.168222850","rc":[{"batl":[[0,1.49,186.49],[1,1.5,169.5]],"ltp":1.83,"tv":2.73,"id":9631075},{"batb":[[1,1.01,10.51],[2,1.01,0]],"ltp":2.68,"tv":112.97,"id":11772759}]}]}
{"op":"mcm","clk":"1010883249","pt":1580653511598,"mc":[{"id":"1.168222850","rc":[{"batb":[[0,3.15,20.54],[1,2.72,11.96],[2,1.01,10.51]],"ltp":2.68,"tv":112.97,"id":11772759}]}]}
{"op":"mcm","clk":"1010883467","pt":1580653512594,"mc":[{"id":"1.168222850","rc":[{"batb":[[0,1.46,90.74],[1,1.44,324.09],[2,1.43,212.12]],"ltp":1.83,"tv":2.73,"id":9631075},{"batl":[[0,3.2,18.48]],"ltp":2.68,"tv":112.97,"id":11772759}]}]}
{"op":"mcm","clk":"1010883937","pt":1580653514708,"mc":[{"id":"1.168222850","rc":[{"batl":[[2,1.54,42.01]],"ltp":1.83,"tv":2.73,"id":9631075},{"trd":[[3.15,38.65]],"batb":[[0,3.15,1.21],[1,2.84,22.69],[2,2.72,11.96]],"ltp":3.15,"tv":151.62,"id":11772759}],"tv":154.35}]}
{"op":"mcm","clk":"1010887157","pt":1580653530684,"mc":[{"id":"1.168222850","rc":[{"batb":[[1,1.28,566.07],[2,1.01,10.51]],"batl":[[0,1.54,42.01],[1,1.5,0],[2,1.54,0]],"ltp":1.83,"tv":2.73,"id":9631075},{"batb":[[0,2.84,22.69],[1,2.72,11.96],[2,2.22,384.52]],"ltp":3.15,"tv":151.62,"id":11772759}]}]}
{"op":"mcm","clk":"1010887391","pt":1580653531739,"mc":[{"id":"1.168222850","rc":[{"batb":[[0,1.28,566.07],[1,1.01,10.51],[2,1.01,0]],"ltp":1.83,"tv":2.73,"id":9631075},{"batb":[[0,2.72,11.96],[1,2.22,384.52],[2,1.01,10.51]],"ltp":3.15,"tv":151.62,"id":11772759}]}]}
{"op":"mcm","clk":"1010887814","pt":1580653533652,"mc":[{"id":"1.168222850","rc":[{"batb":[[0,1.29,77.34],[1,1.28,566.07],[2,1.01,10.51]],"ltp":1.83,"tv":2.73,"id":9631075},{"batb":[[1,2.66,12.51],[2,2.22,384.52]],"ltp":3.15,"tv":151.62,"id":11772759}]}]}
{"op":"mcm","clk":"1010887945","pt":1580653534261,"mc":[{"id":"1.168222850","rc":[{"batb":[[1,1.28,485.89]],"ltp":1.83,"tv":2.73,"id":9631075},{"batb":[[0,2.66,12.51],[1,2.22,384.52],[2,1.01,10.51]],"ltp":3.15,"tv":151.62,"id":11772759}]}]}
{"op":"mcm","clk":"1010888145","pt":1580653535270,"mc":[{"id":"1.168222850","rc":[{"batb":[[0,1.41,325.45],[1,1.4,233.28],[2,1.29,77.34]],"batl":[[0,1.46,259.91],[1,1.47,183.24]],"ltp":1.83,"tv":2.73,"id":9631075}]}]}
{"op":"mcm","clk":"1010889416","pt":1580653541583,"mc":[{"id":"1.168222850","rc":[{"batb":[[0,1.29,77.34],[1,1.28,485.89],[2,1.01,10.51]],"ltp":1.83,"tv":2.73,"id":9631075}]}]}
{"op":"mcm","clk":"1010890071","pt":1580653544690,"mc":[{"id":"1.168222850","rc":[{"batb":[[0,1.3,395.85],[1,1.29,429.72],[2,1.28,485.89]],"ltp":1.83,"tv":2.73,"id":9631075}]}]}
{"op":"mcm","clk":"1010890177","pt":1580653545169,"mc":[{"id":"1.168222850","rc":[{"batb":[[2,1.01,10.51]],"ltp":1.83,"tv":2.73,"id":9631075},{"batb":[[1,1.01,10.51],[2,1.01,0]],"ltp":3.15,"tv":151.62,"id":11772759}]}]}
{"op":"mcm","clk":"1010890467","pt":1580653546637,"mc":[{"id":"1.168222850","rc":[{"batl":[[0,1.34,338.61],[1,1.35,265.57]],"ltp":1.83,"tv":2.73,"id":9631075}]}]}
{"op":"mcm","clk":"1010890717","pt":1580653547739,"mc":[{"id":"1.168222850","rc":[{"batb":[[2,1.19,127.7]],"ltp":1.83,"tv":2.73,"id":9631075},{"batb":[[0,3.95,23.29],[1,3.3,18.25],[2,1.01,10.51]],"ltp":3.15,"tv":151.62,"id":11772759}]}]}
{"op":"mcm","clk":"1010890829","pt":1580653548185,"mc":[{"id":"1.168222850","rc":[{"batb":[[0,1.31,135.27],[1,1.3,395.85],[2,1.29,429.72]],"batl":[[2,1.38,42.01]],"ltp":1.83,"tv":2.73,"id":9631075},{"batb":[[1,3.6,15.96],[2,3.3,18.25]],"batl":[[0,4.2,12.6]],"ltp":3.15,"tv":151.62,"id":11772759}]}]}
{"op":"mcm","clk":"1010893275","pt":1580653560613,"mc":[{"id":"1.168222850","rc":[{"batb":[[1,1.2,530.86],[2,1.19,127.7]],"batl":[[0,1.38,42.01],[1,1.35,0],[2,1.38,0]],"ltp":1.83,"tv":2.73,"id":9631075},{"batb":[[0,3.6,15.96],[1,3.3,18.25],[2,2.52,381.46]],"ltp":3.15,"tv":151.62,"id":11772759}]}]}
{"op":"mcm","clk":"1010893467","pt":1580653561591,"mc":[{"id":"1.168222850","rc":[{"batb":[[0,1.2,530.86],[1,1.19,127.7],[2,1.01,10.51]],"ltp":1.83,"tv":2.73,"id":9631075},{"batb":[[0,3.3,18.25],[1,2.52,381.46],[2,1.01,10.51]],"ltp":3.15,"tv":151.62,"id":11772759}]}]}
{"op":"mcm","clk":"1010894170","pt":1580653564802,"mc":[{"id":"1.168222850","rc":[{"batb":[[0,1.28,210.79],[1,1.27,381.17],[2,1.2,530.86]],"batl":[[0,1.31,300.01],[1,1.32,297.33]],"ltp":1.83,"tv":2.73,"id":9631075}]}]}
{"op":"mcm","clk":"1010895051","pt":1580653569090,"mc":[{"id":"1.168222850","rc":[{"batb":[[0,1.2,530.86],[1,1.19,127.7],[2,1.01,10.51]],"ltp":1.83,"tv":2.73,"id":9631075}]}]}
{"op":"mcm","clk":"1010895715","pt":1580653572110,"mc":[{"id":"1.168222850","rc":[{"batb":[[2,1.18,675.43]],"batl":[[0,1.44,211.23],[1,1.45,194.28]],"ltp":1.83,"tv":2.73,"id":9631075}]}]}
{"op":"mcm","clk":"1010899203","pt":1580653589667,"mc":[{"id":"1.168222850","rc":[{"batb":[[0,1.19,127.7],[1,1.18,675.43],[2,1.17,414.27]],"ltp":1.83,"tv":2.73,"id":9631075},{"batb":[[1,1.01,10.51],[2,1.01,0]],"ltp":3.15,"tv":151.62,"id":11772759}]}]}
{"op":"mcm","clk":"1010899433","pt":1580653590748,"mc":[{"id":"1.168222850","rc":[{"batl":[[0,1.21,458.63],[1,1.22,461.18]],"ltp":1.83,"tv":2.73,"id":9631075}]}]}
{"op":"mcm","clk":"1010899619","pt":1580653591563,"mc":[{"id":"1.168222850","rc":[{"batb":[[0,5.4,10.94],[1,4.6,16.37],[2,1.01,10.51]],"ltp":3.15,"tv":151.62,"id":11772759}]}]}
{"op":"mcm","clk":"1010899795","pt":1580653592551,"mc":[{"id":"1.168222850","rc":[{"batl":[[2,1.23,42.01]],"ltp":1.83,"tv":2.73,"id":9631075},{"batb":[[1,5.3,9.24],[2,4.6,16.37]],"batl":[[0,6.4,7.56]],"ltp":3.15,"tv":151.62,"id":11772759}]}]}
{"op":"mcm","clk":"1010900033","pt":1580653593758,"mc":[{"id":"1.168222850","rc":[{"batb":[[1,1.18,843.47]],"ltp":1.83,"tv":2.73,"id":9631075}]}]}
{"op":"mcm","clk":"1010904061","pt":1580653613706,"mc":[{"id":"1.168222850","rc":[{"batb":[[0,1.13,190.88],[1,1.11,684.32],[2,1.01,10.51]],"ltp":1.83,"tv":2.73,"id":9631075},{"batb":[[0,4.6,16.37],[1,3,380.84],[2,1.01,10.51]],"ltp":3.15,"tv":151.62,"id":11772759}]}]}
{"op":"mcm","clk":"1010904624","pt":1580653616570,"mc":[{"id":"1.168222850","rc":[{"batb":[[0,1.12,195.45],[1,1.11,1839.02]],"batl":[[0,1.27,480.83],[1,1.28,346.08]],"ltp":1.83,"tv":2.73,"id":9631075},{"batb":[[0,4.6,15.82]],"ltp":3.15,"tv":151.62,"id":11772759}]}]}
{"op":"mcm","clk":"1010906051","pt":1580653623677,"mc":[{"id":"1.168222850","rc":[{"batb":[[1,1.11,684.32]],"ltp":1.83,"tv":2.73,"id":9631075}]}]}
{"op":"mcm","clk":"1010906357","pt":1580653625247,"mc":[{"id":"1.168222850","rc":[{"batb":[[1,1.01,10.51],[2,1.01,0]],"ltp":1.83,"tv":2.73,"id":9631075}]}]}
{"op":"mcm","clk":"1010906625","pt":1580653626685,"mc":[{"id":"1.168222850","rc":[{"batb":[[0,1.24,200.71],[1,1.23,462.68],[2,1.12,195.45]],"ltp":1.83,"tv":2.73,"id":9631075}]}]}
{"op":"mcm","clk":"1010906770","pt":1580653627346,"mc":[{"id":"1.168222850","rc":[{"batb":[[1,1.23,563.55],[2,1.13,184.51]],"ltp":1.83,"tv":2.73,"id":9631075},{"batb":[[1,3.7,13.61],[2,3,380.84]],"ltp":3.15,"tv":151.62,"id":11772759}]}]}
{"op":"mcm","clk":"1010907034","pt":1580653628592,"mc":[{"id":"1.168222850","rc":[{"batl":[[2,1.29,42.01]],"ltp":1.83,"tv":2.73,"id":9631075},{"batb":[[1,4.5,11.76],[2,3.7,13.61]],"ltp":3.15,"tv":151.62,"id":11772759}]}]}
{"op":"mcm","clk":"1010907233","pt":1580653629578,"mc":[{"id":"1.168222850","rc":[{"batb":[[0,1.24,368.75],[2,1.16,576.13]],"ltp":1.83,"tv":2.73,"id":9631075},{"batl":[[0,5.2,9.24]],"ltp":3.15,"tv":151.62,"id":11772759}]}]}
{"op":"mcm","clk":"1010908062","pt":1580653633602,"mc":[{"id":"1.168222850","rc":[{"batb":[[0,1.23,563.55],[1,1.16,576.13],[2,1.13,184.51]],"batl":[[0,1.27,369.77],[1,1.29,42.01],[2,1.29,0]],"ltp":1.83,"tv":2.73,"id":9631075}]}]}
{"op":"mcm","clk":"1010908620","pt":1580653636436,"mc":[{"id":"1.168222850","rc":[{"batb":[[0,1.23,617.17],[1,1.22,500.7],[2,1.16,576.13]],"batl":[[0,1.26,257.29],[1,1.27,369.77],[2,1.29,42.01]],"ltp":1.83,"tv":2.73,"id":9631075}]}]}
{"op":"mcm","clk":"1010908949","pt":1580653638084,"mc":[{"id":"1.168222850","rc":[{"batb":[[0,1.24,168.04],[1,1.23,617.17],[2,1.22,500.7]],"ltp":1.83,"tv":2.73,"id":9631075}]}]}
{"op":"mcm","clk":"1010909214","pt":1580653639511,"mc":[{"id":"1.168222850","rc":[{"batb":[[0,1.23,617.17],[1,1.22,500.7],[2,1.16,576.13]],"ltp":1.83,"tv":2.73,"id":9631075}]}]}
{"op":"mcm","clk":"1010910832","pt":1580653647525,"mc":[{"id":"1.168222850","rc":[{"batb":[[0,1.16,576.13],[1,1.13,184.51],[2,1.01,10.51]],"ltp":1.83,"tv":2.73,"id":9631075},{"batb":[[0,3.7,13.61],[1,3,380.84],[2,1.01,10.51]],"ltp":3.15,"tv":151.62,"id":11772759}]}]}
{"op":"mcm","clk":"1010911150","pt":1580653649247,"mc":[{"id":"1.168222850","rc":[{"batb":[[0,1.13,184.51],[1,1.01,10.51],[2,1.01,0]],"ltp":1.83,"tv":2.73,"id":9631075},{"batb":[[1,1.01,10.51],[2,1.01,0]],"ltp":3.15,"tv":151.62,"id":11772759}]}]}
{"op":"mcm","clk":"1010911458","pt":1580653650724,"mc":[{"id":"1.168222850","rc":[{"batb":[[1,1.12,207.79],[2,1.11,945.03]],"batl":[[0,1.36,161.32],[1,1.37,252.36]],"ltp":1.83,"tv":2.73,"id":9631075},{"batb":[[0,3.75,13.22]],"ltp":3.15,"tv":151.62,"id":11772759}]}]}
{"op":"mcm","clk":"1010912480","pt":1580653655735,"mc":[{"id":"1.168222850","rc":[{"batb":[[1,1.01,10.51],[2,1.11,0]],"ltp":1.83,"tv":2.73,"id":9631075}]}]}
{"op":"mcm","clk":"1010913103","pt":1580653658654,"mc":[{"id":"1.168222850","rc":[{"batb":[[0,1.21,262.47],[1,1.2,553.51],[2,1.13,184.51]],"batl":[[0,1.23,182.86],[1,1.24,428.17]],"ltp":1.83,"tv":2.73,"id":9631075}]}]}
{"op":"mcm","clk":"1010913472","pt":1580653660562,"mc":[{"id":"1.168222850","rc":[{"batb":[[0,1.13,814.48],[1,1.01,10.51],[2,1.13,0]],"ltp":1.83,"tv":2.73,"id":9631075},{"batb":[[1,2.9,375.84],[2,1.01,10.51]],"ltp":3.15,"tv":151.62,"id":11772759}]}]}
{"op":"mcm","clk":"1010913899","pt":1580653662871,"mc":[{"id":"1.168222850","rc":[{"batb":[[1,1.12,207.79],[2,1.11,945.03]],"batl":[[0,1.36,161.32],[1,1.37,252.36]],"ltp":1.83,"tv":2.73,"id":9631075}]}]}
{"op":"mcm","clk":"1010914922","pt":1580653668365,"mc":[{"id":"1.168222850","rc":[{"batb":[[1,1.01,10.51],[2,1.11,0]],"ltp":1.83,"tv":2.73,"id":9631075}]}]}
{"op":"mcm","clk":"1010915164","pt":1580653669576,"mc":[{"id":"1.168222850","rc":[{"batb":[[0,1.13,184.51]],"ltp":1.83,"tv":2.73,"id":9631075},{"batb":[[1,1.01,10.51],[2,1.01,0]],"ltp":3.15,"tv":151.62,"id":11772759}]}]}
{"op":"mcm","clk":"1010915549","pt":1580653671660,"mc":[{"id":"1.168222850","rc":[{"batb":[[0,1.33,201.39],[1,1.32,381.04],[2,1.14,178.45]],"ltp":1.83,"tv":2.73,"id":9631075},{"batb":[[1,2.8,10.94],[2,1.01,10.51]],"ltp":3.15,"tv":151.62,"id":11772759}]}]}
{"op":"mcm","clk":"1010915664","pt":1580653672244,"mc":[{"id":"1.168222850","rc":[{"batb":[[0,1.33,328.26]],"batl":[[2,1.39,42.01]],"ltp":1.83,"tv":2.73,"id":9631075},{"batb":[[1,3.55,15.96],[2,2.8,10.94]],"batl":[[0,4,13.44]],"ltp":3.15,"tv":151.62,"id":11772759}]}]}
{"op":"mcm","clk":"1010915957","pt":1580653673764,"mc":[{"id":"1.168222850","rc":[{"batb":[[2,1.22,523]],"ltp":1.83,"tv":2.73,"id":9631075}]}]}
{"op":"mcm","clk":"1010916515","pt":1580653676684,"mc":[{"id":"1.168222850","rc":[{"batb":[[0,1.32,381.04],[1,1.22,523],[2,1.14,178.45]],"ltp":1.83,"tv":2.73,"id":9631075}]}]}
{"op":"mcm","clk":"1010917041","pt":1580653679449,"mc":[{"id":"1.168222850","rc":[{"batb":[[0,1.32,590.42],[1,1.31,328.82],[2,1.22,523]],"batl":[[0,1.36,282.36]],"ltp":1.83,"tv":2.73,"id":9631075},{"batl":[[0,4.1,13.44]],"ltp":3.15,"tv":151.62,"id":11772759}]}]}
{"op":"mcm","clk":"1010917265","pt":1580653680539,"mc":[{"id":"1.168222850","rc":[{"batb":[[0,1.32,465.7]],"ltp":1.83,"tv":2.73,"id":9631075}]}]}
{"op":"mcm","clk":"1010917738","pt":1580653682758,"mc":[{"id":"1.168222850","rc":[{"batl":[[0,1.36,403.49]],"ltp":1.83,"tv":2.73,"id":9631075}]}]}
{"op":"mcm","clk":"1010919487","pt":1580653691382,"mc":[{"id":"1.168222850","rc":[{"batb":[[0,1.22,523],[1,1.14,178.45],[2,1.01,10.51]],"ltp":1.83,"tv":2.73,"id":9631075},{"batb":[[0,2.8,10.94],[1,2.42,381.73],[2,1.01,10.51]],"ltp":3.15,"tv":151.62,"id":11772759}]}]}
{"op":"mcm","clk":"1010920018","pt":1580653693739,"mc":[{"id":"1.168222850","rc":[{"batb":[[0,1.14,178.45],[1,1.01,10.51],[2,1.01,0]],"ltp":1.83,"tv":2.73,"id":9631075},{"batb":[[1,1.01,10.51],[2,1.01,0]],"ltp":3.15,"tv":151.62,"id":11772759}]}]}
{"op":"mcm","clk":"1010920186","pt":1580653694576,"mc":[{"id":"1.168222850","rc":[{"batb":[[0,2.82,10.78],[1,2.8,10.94],[2,1.01,10.51]],"ltp":3.15,"tv":151.62,"id":11772759}]}]}
{"op":"mcm","clk":"1010920286","pt":1580653695065,"mc":[{"id":"1.168222850","rc":[{"batb":[[1,1.01,10.51],[2,1.01,0]],"ltp":3.15,"tv":151.62,"id":11772759}]}]}
{"op":"mcm","clk":"1010921273","pt":1580653699713,"mc":[{"id":"1.168222850","rc":[{"batb":[[0,1.2,530.86],[1,1.14,178.45],[2,1.01,10.51]],"ltp":1.83,"tv":2.73,"id":9631075},{"batb":[[1,2.52,381.46],[2,1.01,10.51]],"ltp":3.15,"tv":151.62,"id":11772759}]}]}
{"op":"mcm","clk":"1010921550","pt":1580653700917,"mc":[{"id":"1.168222850","rc":[{"batb":[[0,1.14,178.45],[1,1.01,10.51],[2,1.01,0]],"ltp":1.83,"tv":2.73,"id":9631075},{"batb":[[1,1.01,10.51],[2,1.01,0]],"ltp":3.15,"tv":151.62,"id":11772759}]}]}
{"op":"mcm","clk":"1010921723","pt":1580653701803,"mc":[{"id":"1.168222850","rc":[{"batb":[[1,1.12,200.43],[2,1.11,952.46]],"batl":[[0,1.56,267.37],[1,1.57,144.42]],"ltp":1.83,"tv":2.73,"id":9631075}]}]}
{"op":"mcm","clk":"1010925064","pt":1580653717654,"mc":[{"id":"1.168222850","rc":[{"trd":[[1.14,356.89]],"batb":[[0,1.12,200.43],[1,1.11,952.46],[2,1.01,10.51]],"batl":[[0,1.14,804.14]],"ltp":1.14,"tv":359.62,"id":9631075}],"tv":511.24}]}
{"op":"mcm","clk":"1010925288","pt":1580653718733,"mc":[{"id":"1.168222850","rc":[{"batb":[[1,1.11,886.25],[2,1.09,431.07]],"ltp":1.14,"tv":359.62,"id":9631075},{"batb":[[0,6.8,13.14],[1,5,13.14],[2,1.01,10.51]],"batl":[[0,12,3.36]],"ltp":3.15,"tv":151.62,"id":11772759}]}]}
{"op":"mcm","clk":"1010925371","pt":1580653719167,"mc":[{"id":"1.168222850","rc":[{"batb":[[2,3.35,371.23]],"ltp":3.15,"tv":151.62,"id":11772759}]}]}
{"op":"mcm","clk":"1010925798","pt":1580653721335,"mc":[{"id":"1.168222850","rc":[{"batb":[[0,1.12,267.29]],"batl":[[0,1.14,915.78],[1,1.15,207.92]],"ltp":1.14,"tv":359.62,"id":9631075},{"batb":[[0,9.2,5.04],[1,6.8,13.14],[2,5,13.14]],"ltp":3.15,"tv":151.62,"id":11772759}]}]}
{"op":"mcm","clk":"1010926471","pt":1580653724649,"mc":[{"id":"1.168222850","rc":[{"trd":[[1.12,80.66]],"batb":[[0,1.12,226.96]],"ltp":1.12,"tv":440.27,"id":9631075}],"tv":591.9}]}
{"op":"mcm","clk":"1010927124","pt":1580653727647,"mc":[{"id":"1.168222850","rc":[{"batl":[[1,1.15,174.5]],"ltp":1.12,"tv":440.27,"id":9631075},{"batl":[[0,11.5,3.36]],"ltp":3.15,"tv":151.62,"id":11772759}]}]}
{"op":"mcm","clk":"1010927755","pt":1580653730363,"mc":[{"id":"1.168222850","rc":[{"batb":[[1,1.11,920.84]],"batl":[[0,1.14,949.49]],"ltp":1.12,"tv":440.27,"id":9631075}]}]}
{"op":"mcm","clk":"1010928495","pt":1580653733755,"mc":[{"id":"1.168222850","rc":[{"trd":[[1.12,164.68]],"batb":[[0,1.12,184.95]],"ltp":1.12,"tv":524.29,"id":9631075}],"tv":675.92}]}
{"op":"mcm","clk":"1010928604","pt":1580653734251,"mc":[{"id":"1.168222850","rc":[{"batl":[[1,1.15,0]],"ltp":1.12,"tv":524.29,"id":9631075},{"batb":[[0,6.8,13.14],[1,5,13.14],[2,3.35,371.23]],"ltp":3.15,"tv":151.62,"id":11772759}]}]}
{"op":"mcm","clk":"1010929376","pt":1580653737473,"mc":[{"id":"1.168222850","rc":[{"batb":[[0,1.12,217.62]],"ltp":1.12,"tv":524.29,"id":9631075}]}]}
{"op":"mcm","clk":"1010929653","pt":1580653738452,"mc":[{"id":"1.168222850","rc":[{"trd":[[1.11,364.76],[1.12,599.92]],"batb":[[0,1.11,738.46],[1,1.09,431.07],[2,1.07,893.98]],"batl":[[0,1.14,811.61]],"ltp":1.11,"tv":1324.29,"id":9631075},{"batb":[[0,9,5.04],[1,6.8,13.14],[2,5,13.14]],"ltp":3.15,"tv":151.62,"id":11772759}],"tv":1475.92}]}
{"op":"mcm","clk":"1010930076","pt":1580653739868,"mc":[{"id":"1.168222850","rc":[{"batl":[[0,1.14,764.49]],"ltp":1.11,"tv":1324.29,"id":9631075}]}]}
{"op":"mcm","clk":"1010930497","pt":1580653741597,"mc":[{"id":"1.168222850","rc":[{"batb":[[0,1.11,1114.88]],"batl":[[0,1.13,300.01],[1,1.14,764.49]],"ltp":1.11,"tv":1324.29,"id":9631075}]}]}
{"op":"mcm","clk":"1010930802","pt":1580653742671,"mc":[{"id":"1.168222850","rc":[{"batl":[[0,1.13,364.23]],"ltp":1.11,"tv":1324.29,"id":9631075}]}]}
{"op":"mcm","clk":"1010932620","pt":1580653750251,"mc":[{"id":"1.168222850","rc":[{"batb":[[0,1.09,431.07],[1,1.07,893.98],[2,1.01,10.51]],"ltp":1.11,"tv":1324.29,"id":9631075},{"batb":[[1,5,13.14],[2,3.35,371.23]],"ltp":3.15,"tv":151.62,"id":11772759}]}]}
{"op":"mcm","clk":"1010932960","pt":1580653751575,"mc":[{"id":"1.168222850","rc":[{"batb":[[0,1.09,263.03]],"ltp":1.11,"tv":1324.29,"id":9631075},{"batb":[[0,5,13.14],[1,3.35,371.23],[2,1.01,10.51]],"ltp":3.15,"tv":151.62,"id":11772759}]}]}
{"op":"mcm","clk":"1010933246","pt":1580653752729,"mc":[{"id":"1.168222850","rc":[{"batb":[[1,1.08,1188.06],[2,1.07,893.98]],"batl":[[0,1.2,363.62],[1,1.21,509.25]],"ltp":1.11,"tv":1324.29,"id":9631075}]}]}
{"op":"mcm","clk":"1010933426","pt":1580653753456,"mc":[{"id":"1.168222850","rc":[{"batb":[[0,1.08,1488.55],[1,1.07,893.98],[2,1.01,10.51]],"batl":[[2,1.23,6.83]],"ltp":1.11,"tv":1324.29,"id":9631075},{"batb":[[0,5.6,10.62]],"ltp":3.15,"tv":151.62,"id":11772759}]}]}
{"op":"mcm","clk":"1010933751","pt":1580653754756,"mc":[{"id":"1.168222850","rc":[{"batl":[[2,1.23,0]],"ltp":1.11,"tv":1324.29,"id":9631075}]}]}
{"op":"mcm","clk":"1010934097","pt":1580653756178,"mc":[{"id":"1.168222850","rc":[{"batb":[[1,1.01,10.51],[2,1.01,0]],"ltp":1.11,"tv":1324.29,"id":9631075}]}]}
{"op":"mcm","clk":"1010934654","pt":1580653758471,"mc":[{"id":"1.168222850","rc":[{"batb":[[1,1.07,168.04],[2,1.01,10.51]],"batl":[[0,1.1,972.64],[1,1.11,192.07]],"ltp":1.11,"tv":1324.29,"id":9631075}]}]}
{"op":"mcm","clk":"1010934905","pt":1580653759657,"mc":[{"id":"1.168222850","rc":[{"batb":[[2,1.05,1505.22]],"ltp":1.11,"tv":1324.29,"id":9631075},{"batb":[[0,11.5,3.36],[1,9.8,14.32],[2,7,11.96]],"ltp":3.15,"tv":151.62,"id":11772759}]}]}
{"op":"mcm","clk":"1010936476","pt":1580653766688,"mc":[{"id":"1.168222850","rc":[{"batb":[[0,1.08,1431.77]],"batl":[[1,1.11,0]],"ltp":1.11,"tv":1324.29,"id":9631075}]}]}
{"op":"mcm","clk":"1010937079","pt":1580653769405,"mc":[{"id":"1.168222850","rc":[{"batl":[[0,1.1,1037.48]],"ltp":1.11,"tv":1324.29,"id":9631075}]}]}
{"op":"mcm","clk":"1010937546","pt":1580653771498,"mc":[{"id":"1.168222850","rc":[{"batb":[[0,1.08,1309.58]],"ltp":1.11,"tv":1324.29,"id":9631075}]}]}
{"op":"mcm","clk":"1010938328","pt":1580653774680,"mc":[{"id":"1.168222850","rc":[{"batb":[[1,1.07,348.68]],"batl":[[0,1.1,1157.52]],"ltp":1.11,"tv":1324.29,"id":9631075}]}]}
{"op":"mcm","clk":"1010938587","pt":1580653775715,"mc":[{"id":"1.168222850","rc":[{"batb":[[0,1.05,1505.22],[1,1.01,10.51],[2,1.05,0]],"ltp":1.11,"tv":1324.29,"id":9631075},{"batb":[[0,7,11.96],[1,3.35,371.23],[2,1.01,10.51]],"ltp":3.15,"tv":151.62,"id":11772759}]}]}
{"op":"mcm","clk":"1010939165","pt":1580653778374,"mc":[{"id":"1.168222850","rc":[{"batb":[[0,1.06,779.38],[1,1.05,1940.42],[2,1.01,10.51]],"batl":[[0,1.14,255.02],[1,1.15,764.64]],"ltp":1.11,"tv":1324.29,"id":9631075}]}]}
{"op":"mcm","clk":"1010940080","pt":1580653782396,"mc":[{"id":"1.168222850","rc":[{"batb":[[0,1.05,1505.22],[1,1.01,10.51],[2,1.01,0]],"ltp":1.11,"tv":1324.29,"id":9631075}]}]}
{"op":"mcm","clk":"1010940520","pt":1580653784260,"mc":[{"id":"1.168222850","rc":[{"batb":[[0,1.05,435.66]],"ltp":1.11,"tv":1324.29,"id":9631075}]}]}
{"op":"mcm","clk":"1010940834","pt":1580653785754,"mc":[{"id":"1.168222850","rc":[{"batb":[[0,1.12,1077.3],[1,1.05,435.66],[2,1.01,10.51]],"ltp":1.11,"tv":1324.29,"id":9631075}]}]}
{"op":"mcm","clk":"1010940996","pt":1580653786514,"mc":[{"id":"1.168222850","rc":[{"batb":[[0,1.13,189.47],[1,1.12,1077.3],[2,1.1,168.04]],"ltp":1.11,"tv":1324.29,"id":9631075},{"batb":[[0,8.4,5.04],[1,7,11.96],[2,5,13.38]],"ltp":3.15,"tv":151.62,"id":11772759}]}]}
{"op":"mcm","clk":"1010941181","pt":1580653787380,"mc":[{"id":"1.168222850","rc":[{"batl":[[0,1.14,297.03]],"ltp":1.11,"tv":1324.29,"id":9631075},{"batl":[[0,10.5,4.2]],"ltp":3.15,"tv":151.62,"id":11772759}]}]}
{"op":"mcm","clk":"1010945877","pt":1580653808527,"mc":[{"id":"1.168222850","rc":[{"batb":[[0,1.1,168.04],[1,1.08,1116.11],[2,1.01,10.51]],"batl":[[0,1.14,42.01],[1,1.15,0]],"ltp":1.11,"tv":1324.29,"id":9631075},{"batb":[[1,5,13.38],[2,3.35,371.23]],"ltp":3.15,"tv":151.62,"id":11772759}]}]}
{"op":"mcm","clk":"1010946076","pt":1580653809747,"mc":[{"id":"1.168222850","rc":[{"batb":[[0,1.08,1116.11],[1,1.01,10.51],[2,1.01,0]],"ltp":1.11,"tv":1324.29,"id":9631075},{"batb":[[0,5,13.38],[1,3.35,371.23],[2,1.01,10.51]],"ltp":3.15,"tv":151.62,"id":11772759}]}]}
{"op":"mcm","clk":"1010946387","pt":1580653811120,"mc":[{"id":"1.168222850","rc":[{"batb":[[0,1.08,2304.17]],"batl":[[0,1.23,290.37],[1,1.24,441.88]],"ltp":1.11,"tv":1324.29,"id":9631075}]}]}
{"op":"mcm","clk":"1010947859","pt":1580653818622,"mc":[{"id":"1.168222850","rc":[{"batb":[[0,1.08,1116.11]],"ltp":1.11,"tv":1324.29,"id":9631075}]}]}
{"op":"mcm","clk":"1010948278","pt":1580653820639,"mc":[{"id":"1.168222850","rc":[{"batb":[[0,1.08,291.44]],"ltp":1.11,"tv":1324.29,"id":9631075}]}]}
{"op":"mcm","clk":"1010948440","pt":1580653821438,"mc":[{"id":"1.168222850","rc":[{"batb":[[0,1.08,1479.5]],"batl":[[0,1.1,854.36],[1,1.11,309.28]],"ltp":1.11,"tv":1324.29,"id":9631075}]}]}
{"op":"mcm","clk":"1010948669","pt":1580653822628,"mc":[{"id":"1.168222850","rc":[{"batb":[[1,1.07,168.04],[2,1.05,475.71]],"ltp":1.11,"tv":1324.29,"id":9631075},{"batb":[[0,11.5,3.36],[1,9.6,15.11],[2,6.6,13.85]],"ltp":3.15,"tv":151.62,"id":11772759}]}]}
{"op":"mcm","clk":"1010949008","pt":1580653824439,"mc":[{"id":"1.168222850","rc":[{"batb":[[2,1.05,1545.27]],"ltp":1.11,"tv":1324.29,"id":9631075}]}]}
{"op":"mcm","clk":"1010952895","pt":1580653844759,"mc":[{"id":"1.168222850","rc":[{"batb":[[0,1.08,291.44]],"ltp":1.11,"tv":1324.29,"id":9631075}]}]}
{"op":"mcm","clk":"1010953066","pt":1580653845566,"mc":[{"id":"1.168222850","rc":[{"batb":[[0,1.05,1545.27],[1,1.01,10.51],[2,1.05,0]],"ltp":1.11,"tv":1324.29,"id":9631075},{"batb":[[0,6.6,13.85],[1,3.35,371.23],[2,1.01,10.51]],"ltp":3.15,"tv":151.62,"id":11772759}]}]}
{"op":"mcm","clk":"1010953469","pt":1580653847715,"mc":[{"id":"1.168222850","rc":[{"batb":[[0,1.05,2767.28]],"batl":[[0,1.16,679.68],[1,1.17,422.79]],"ltp":1.11,"tv":1324.29,"id":9631075}]}]}
{"op":"mcm","clk":"1010954108","pt":1580653851268,"mc":[{"id":"1.168222850","rc":[{"batb":[[0,1.05,1545.27]],"ltp":1.11,"tv":1324.29,"id":9631075}]}]}
{"op":"mcm","clk":"1010954571","pt":1580653853755,"mc":[{"id":"1.168222850","rc":[{"batb":[[0,1.05,475.71]],"ltp":1.11,"tv":1324.29,"id":9631075}]}]}
{"op":"mcm","clk":"1010954775","pt":1580653854749,"mc":[{"id":"1.168222850","rc":[{"batb":[[0,1.14,483.68],[1,1.13,822.64],[2,1.07,316.93]],"batl":[[0,1.15,42.01],[1,1.16,679.68],[2,1.17,422.79]],"ltp":1.11,"tv":1324.29,"id":9631075},{"batb":[[0,7.6,5.88],[1,6.6,13.85],[2,4.4,18.49]],"ltp":3.15,"tv":151.62,"id":11772759}]}]}
{"op":"mcm","clk":"1010954814","pt":1580653854930,"mc":[{"id":"1.168222850","rc":[{"batl":[[0,9.8,4.2]],"ltp":3.15,"tv":151.62,"id":11772759}]}]}
{"op":"mcm","clk":"1010955195","pt":1580653856540,"mc":[{"id":"1.168222850","rc":[{"batb":[[2,1.09,779.05]],"ltp":1.11,"tv":1324.29,"id":9631075}]}]}
{"op":"mcm","clk":"1010957468","pt":1580653867363,"mc":[{"id":"1.168222850","rc":[{"batb":[[1,1.13,754.98]],"batl":[[1,1.16,613.95]],"ltp":1.11,"tv":1324.29,"id":9631075}]}]}
{"op":"mcm","clk":"1010958069","pt":1580653870390,"mc":[{"id":"1.168222850","rc":[{"batb":[[0,1.14,550.74]],"batl":[[2,1.17,487.96]],"ltp":1.11,"tv":1324.29,"id":9631075}]}]}
{"op":"mcm","clk":"1010959367","pt":1580653875958,"mc":[{"id":"1.168222850","rc":[{"batb":[[0,1.09,779.05],[1,1.07,316.93],[2,1.01,10.51]],"batl":[[1,1.16,0],[2,1.17,0]],"ltp":1.11,"tv":1324.29,"id":9631075},{"batb":[[1,4.4,18.49],[2,3.35,371.23]],"ltp":3.15,"tv":151.62,"id":11772759}]}]}
{"op":"mcm","clk":"1010959793","pt":1580653877579,"mc":[{"id":"1.168222850","rc":[{"batb":[[0,4.4,18.49],[1,3.35,371.23],[2,1.01,10.51]],"ltp":3.15,"tv":151.62,"id":11772759}]}]}
{"op":"mcm","clk":"1010960098","pt":1580653878992,"mc":[{"id":"1.168222850","rc":[{"batb":[[1,1.08,699.51],[2,1.07,810.04]],"batl":[[0,1.29,345.17],[1,1.3,334.91]],"ltp":1.11,"tv":1324.29,"id":9631075}]}]}
{"op":"mcm","clk":"1010960971","pt":1580653882567,"mc":[{"id":"1.168222850","rc":[{"batb":[[1,1.07,316.93],[2,1.01,10.51]],"ltp":1.11,"tv":1324.29,"id":9631075}]}]}
{"op":"mcm","clk":"1010961635","pt":1580653885564,"mc":[{"id":"1.168222850","rc":[{"batb":[[0,1.26,295.2],[1,1.25,437.48],[2,1.07,316.93]],"ltp":1.11,"tv":1324.29,"id":9631075},{"batb":[[1,1.01,10.51],[2,1.01,0]],"ltp":3.15,"tv":151.62,"id":11772759}]}]}
{"op":"mcm","clk":"1010961896","pt":1580653886696,"mc":[{"id":"1.168222850","rc":[{"batb":[[1,1.25,528.2],[2,1.14,166.18]],"batl":[[0,1.28,42.01],[1,1.29,345.17],[2,1.3,334.91]],"ltp":1.11,"tv":1324.29,"id":9631075},{"batb":[[0,4.5,11.76],[1,4.4,18.49],[2,3,24]],"batl":[[0,5.4,9.24]],"ltp":3.15,"tv":151.62,"id":11772759}]}]}
{"op":"mcm","clk":"1010962565","pt":1580653889319,"mc":[{"id":"1.168222850","rc":[{"batb":[[2,1.18,549.72]],"ltp":1.11,"tv":1324.29,"id":9631075}]}]}
{"op":"mcm","clk":"1010967167","pt":1580653909527,"mc":[{"id":"1.168222850","rc":[{"batb":[[0,1.23,168.04],[1,1.18,549.72],[2,1.14,166.18]],"ltp":1.11,"tv":1324.29,"id":9631075},{"batb":[[0,3,24],[1,2.62,379.26],[2,1.01,10.51]],"ltp":3.15,"tv":151.62,"id":11772759}]}]}
{"op":"mcm","clk":"1010967390","pt":1580653910529,"mc":[{"id":"1.168222850","rc":[{"batb":[[0,1.18,549.72],[1,1.14,166.18],[2,1.01,10.51]],"ltp":1.11,"tv":1324.29,"id":9631075}]}]}
{"op":"mcm","clk":"1010967771","pt":1580653912221,"mc":[{"id":"1.168222850","rc":[{"batb":[[1,1.14,908.66],[2,1.13,386.44]],"batl":[[0,1.58,195.48],[1,1.59,140.2]],"ltp":1.11,"tv":1324.29,"id":9631075}]}]}
{"op":"mcm","clk":"1010968451","pt":1580653915105,"mc":[{"id":"1.168222850","rc":[{"batb":[[0,1.14,908.66],[1,1.13,386.44],[2,1.01,10.51]],"ltp":1.11,"tv":1324.29,"id":9631075},{"batb":[[1,1.01,10.51],[2,1.01,0]],"ltp":3.15,"tv":151.62,"id":11772759}]}]}
{"op":"mcm","clk":"1010968925","pt":1580653917205,"mc":[{"id":"1.168222850","rc":[{"batl":[[0,1.16,288.62],[1,1.17,659.05]],"ltp":1.11,"tv":1324.29,"id":9631075}]}]}
{"op":"mcm","clk":"1010969223","pt":1580653918532,"mc":[{"id":"1.168222850","rc":[{"batb":[[2,1.12,168.04]],"ltp":1.11,"tv":1324.29,"id":9631075},{"batb":[[0,6.4,14.87],[1,4.3,19.59],[2,1.01,10.51]],"batl":[[0,9.4,4.2]],"ltp":3.15,"tv":151.62,"id":11772759}]}]}
{"op":"mcm","clk":"1010969423","pt":1580653919436,"mc":[{"id":"1.168222850","rc":[{"batb":[[0,7.4,5.88],[1,6.4,14.87],[2,4.3,19.59]],"ltp":3.15,"tv":151.62,"id":11772759}]}]}
{"op":"mcm","clk":"1010973159","pt":1580653936663,"mc":[{"id":"1.168222850","rc":[{"batb":[[0,1.14,166.18],[1,1.12,168.04],[2,1.09,779.05]],"ltp":1.11,"tv":1324.29,"id":9631075}]}]}
{"op":"mcm","clk":"1010973369","pt":1580653937527,"mc":[{"id":"1.168222850","rc":[{"batb":[[0,1.09,779.05],[1,1.08,302.22],[2,1.01,10.51]],"ltp":1.11,"tv":1324.29,"id":9631075},{"batb":[[0,4.3,19.59],[1,3.15,373.59],[2,1.01,10.51]],"ltp":3.15,"tv":151.62,"id":11772759}]}]}
{"op":"mcm","clk":"1010973808","pt":1580653939474,"mc":[{"id":"1.168222850","rc":[{"batb":[[1,1.08,1410.11]],"batl":[[0,1.3,442.42],[1,1.31,320.05]],"ltp":1.11,"tv":1324.29,"id":9631075}]}]}
{"op":"mcm","clk":"1010977947","pt":1580653957721,"mc":[{"id":"1.168222850","rc":[{"batb":[[0,1.08,1410.11],[1,1.01,10.51],[2,1.01,0]],"ltp":1.11,"tv":1324.29,"id":9631075},{"batb":[[1,1.01,10.51],[2,1.01,0]],"ltp":3.15,"tv":151.62,"id":11772759}]}]}
{"op":"mcm","clk":"1010978159","pt":1580653958686,"mc":[{"id":"1.168222850","rc":[{"batb":[[1,1.04,573.28],[2,1.01,10.51]],"batl":[[0,1.1,1041.85]],"ltp":1.11,"tv":1324.29,"id":9631075},{"batb":[[0,9.8,14.16],[1,6.2,15.82],[2,4.3,19.59]],"ltp":3.15,"tv":151.62,"id":11772759}]}]}
{"op":"mcm","clk":"1010978302","pt":1580653959286,"mc":[{"id":"1.168222850","rc":[{"batb":[[2,1.01,10.51]],"ltp":3.15,"tv":151.62,"id":11772759}]}]}
{"op":"mcm","clk":"1010978596","pt":1580653960583,"mc":[{"id":"1.168222850","rc":[{"batb":[[0,11.5,3.36],[1,9.8,14.16],[2,6.2,15.82]],"ltp":3.15,"tv":151.62,"id":11772759}]}]}
{"op":"mcm","clk":"1010978853","pt":1580653961771,"mc":[{"id":"1.168222850","rc":[{"batb":[[1,1.05,1069.56],[2,1.04,573.28]],"ltp":1.11,"tv":1324.29,"id":9631075}]}]}
{"op":"mcm","clk":"1010979427","pt":1580653964481,"mc":[{"id":"1.168222850","rc":[{"trd":[[1.08,16.8]],"batb":[[0,1.08,1401.7]],"ltp":1.08,"tv":1341.1,"id":9631075}],"tv":1492.72}]}
{"op":"mcm","clk":"1010983114","pt":1580653981728,"mc":[{"id":"1.168222850","rc":[{"batb":[[0,1.05,1069.56],[1,1.04,573.28],[2,1.01,10.51]],"ltp":1.08,"tv":1341.1,"id":9631075},{"batb":[[0,6.2,15.82],[1,3.6,374.22],[2,1.01,10.51]],"ltp":3.15,"tv":151.62,"id":11772759}]}]}
{"op":"mcm","clk":"1010983736","pt":1580653984552,"mc":[{"id":"1.168222850","rc":[{"batb":[[0,1.05,1773.14],[1,1.04,1096.69]],"batl":[[0,1.17,599.59],[1,1.18,492.86]],"ltp":1.08,"tv":1341.1,"id":9631075}]}]}
{"op":"mcm","clk":"1010985684","pt":1580653993585,"mc":[{"id":"1.168222850","rc":[{"batb":[[0,1.05,703.58]],"ltp":1.08,"tv":1341.1,"id":9631075}]}]}
{"op":"mcm","clk":"1010985947","pt":1580653994607,"mc":[{"id":"1.168222850","rc":[{"batb":[[1,1.04,1264.73],[2,1.02,866.45]],"batl":[[0,1.06,996.01],[1,1.07,212.46]],"ltp":1.08,"tv":1341.1,"id":9631075},{"batb":[[0,16,4.72],[1,13,7.32],[2,6.2,15.82]],"ltp":3.15,"tv":151.62,"id":11772759}]}]}
{"op":"mcm","clk":"1010986133","pt":1580653995484,"mc":[{"id":"1.168222850","rc":[{"batl":[[0,1.06,1038.02]],"ltp":1.08,"tv":1341.1,"id":9631075},{"batb":[[2,3.6,374.22]],"ltp":3.15,"tv":151.62,"id":11772759}]}]}
{"op":"mcm","clk":"1010986463","pt":1580653997006,"mc":[{"id":"1.168222850","rc":[{"batb":[[2,1.02,3050.52]],"ltp":1.08,"tv":1341.1,"id":9631075}]}]}
{"op":"mcm","clk":"1010994575","pt":1580654034414,"mc":[{"id":"1.168222850","rc":[{"trd":[[1.05,100]],"batb":[[0,1.05,653.58]],"ltp":1.05,"tv":1441.1,"id":9631075}],"tv":1592.72}]}
{"op":"mcm","clk":"1010995318","pt":1580654037702,"mc":[{"id":"1.168222850","rc":[{"batb":[[0,1.05,707.35]],"ltp":1.05,"tv":1441.1,"id":9631075}]}]}
{"op":"mcm","clk":"1011001976","pt":1580654066069,"mc":[{"id":"1.168222850","rc":[{"batb":[[2,1.02,3058.39]],"ltp":1.05,"tv":1441.1,"id":9631075}]}]}
{"op":"mcm","clk":"1011007729","pt":1580654091718,"mc":[{"id":"1.168222850","rc":[{"batb":[[0,1.02,3058.39],[1,1.01,18.37],[2,1.02,0]],"batl":[[0,1.07,212.46],[1,1.07,0]],"ltp":1.05,"tv":1441.1,"id":9631075},{"batb":[[0,13,7.32],[1,3.6,374.22],[2,1.01,10.51]],"ltp":3.15,"tv":151.62,"id":11772759}]}]}
{"op":"mcm","clk":"1011008284","pt":1580654094207,"mc":[{"id":"1.168222850","rc":[{"batb":[[0,1.03,1245.73],[1,1.02,3058.39],[2,1.01,18.37]],"batl":[[0,1.07,882.73],[1,1.08,313.5]],"ltp":1.05,"tv":1441.1,"id":9631075}]}]}
{"op":"mcm","clk":"1011009035","pt":1580654097320,"mc":[{"id":"1.168222850","rc":[{"batb":[[0,1.02,3058.39],[1,1.01,18.37],[2,1.01,0]],"batl":[[0,1.07,215.4],[1,1.08,0]],"ltp":1.05,"tv":1441.1,"id":9631075}]}]}
{"op":"mcm","clk":"1011009367","pt":1580654098710,"mc":[{"id":"1.168222850","rc":[{"batb":[[0,1.02,874.31]],"ltp":1.05,"tv":1441.1,"id":9631075}]}]}
{"op":"mcm","clk":"1011009805","pt":1580654100505,"mc":[{"id":"1.168222850","rc":[{"batb":[[0,1.06,436.57],[1,1.05,781.27],[2,1.02,874.31]],"batl":[[0,1.07,882.73],[1,1.08,313.5]],"ltp":1.05,"tv":1441.1,"id":9631075}]}]}
{"op":"mcm","clk":"1011010093","pt":1580654101599,"mc":[{"id":"1.168222850","rc":[{"batb":[[1,1.05,1226.53],[2,1.04,598.61]],"ltp":1.05,"tv":1441.1,"id":9631075},{"batb":[[1,11.5,9.91],[2,3.6,374.22]],"ltp":3.15,"tv":151.62,"id":11772759}]}]}
{"op":"mcm","clk":"1011013513","pt":1580654115736,"mc":[{"id":"1.168222850","rc":[{"batb":[[0,1.05,445.26],[1,1.04,598.61],[2,1.03,1571.88]],"batl":[[0,1.08,313.5],[1,1.08,0]],"ltp":1.05,"tv":1441.1,"id":9631075}]}]}
{"op":"mcm","clk":"1011013774","pt":1580654116722,"mc":[{"id":"1.168222850","rc":[{"batb":[[0,1.04,598.61],[1,1.03,1571.88],[2,1.02,7.87]],"ltp":1.05,"tv":1441.1,"id":9631075},{"batb":[[0,11.5,9.91],[1,3.6,374.22],[2,1.01,10.51]],"ltp":3.15,"tv":151.62,"id":11772759}]}]}
{"op":"mcm","clk":"1011014283","pt":1580654118739,"mc":[{"id":"1.168222850","rc":[{"batb":[[0,1.04,1832.37]],"batl":[[0,1.08,719.35]],"ltp":1.05,"tv":1441.1,"id":9631075}]}]}
{"op":"mcm","clk":"1011014425","pt":1580654119439,"mc":[{"id":"1.168222850","rc":[{"batb":[[0,1.04,598.61]],"ltp":1.05,"tv":1441.1,"id":9631075}]}]}
{"op":"mcm","clk":"1011014740","pt":1580654120738,"mc":[{"id":"1.168222850","rc":[{"batb":[[0,1.05,1222.01],[1,1.04,598.61],[2,1.03,1571.88]],"batl":[[0,1.07,1199.17]],"ltp":1.05,"tv":1441.1,"id":9631075}]}]}
{"op":"mcm","clk":"1011015573","pt":1580654124143,"mc":[{"id":"1.168222850","rc":[{"batb":[[0,1.04,598.61],[1,1.03,1571.88],[2,1.02,7.87]],"ltp":1.05,"tv":1441.1,"id":9631075}]}]}
{"op":"mcm","clk":"1011016177","pt":1580654126728,"mc":[{"id":"1.168222850","rc":[{"batb":[[0,1.04,1832.37]],"batl":[[0,1.08,1032.85]],"ltp":1.05,"tv":1441.1,"id":9631075}]}]}
{"op":"mcm","clk":"1011016956","pt":1580654130075,"mc":[{"id":"1.168222850","rc":[{"batb":[[1,1.02,7.87],[2,1.01,18.37]],"ltp":1.05,"tv":1441.1,"id":9631075}]}]}
{"op":"mcm","clk":"1011017351","pt":1580654131735,"mc":[{"id":"1.168222850","rc":[{"batb":[[0,1.04,1617.07]],"batl":[[0,1.06,1210.48]],"ltp":1.05,"tv":1441.1,"id":9631075}]}]}
{"op":"mcm","clk":"1011017553","pt":1580654132552,"mc":[{"id":"1.168222850","rc":[{"batb":[[0,1.04,1785.11],[1,1.02,1006.11]],"batl":[[0,1.06,1252.49]],"ltp":1.05,"tv":1441.1,"id":9631075},{"batb":[[0,16.5,4.41],[1,13,7.16],[2,3.6,374.22]],"ltp":3.15,"tv":151.62,"id":11772759}]}]}
{"op":"mcm","clk":"1011018040","pt":1580654134652,"mc":[{"id":"1.168222850","rc":[{"batb":[[0,1.05,213.24],[1,1.04,1785.11],[2,1.02,3190.18]],"ltp":1.05,"tv":1441.1,"id":9631075}]}]}
{"op":"mcm","clk":"1011019508","pt":1580654140664,"mc":[{"id":"1.168222850","rc":[{"batb":[[0,1.04,168.04],[1,1.02,3190.18],[2,1.01,18.37]],"batl":[[0,1.06,42.01]],"ltp":1.05,"tv":1441.1,"id":9631075},{"batb":[[0,13,7.16],[1,3.6,374.22],[2,1.01,10.51]],"ltp":3.15,"tv":151.62,"id":11772759}]}]}
{"op":"mcm","clk":"1011019732","pt":1580654141567,"mc":[{"id":"1.168222850","rc":[{"batb":[[0,1.02,3190.18],[1,1.01,18.37],[2,1.01,0]],"ltp":1.05,"tv":1441.1,"id":9631075}]}]}
{"op":"mcm","clk":"1011020091","pt":1580654143109,"mc":[{"id":"1.168222850","rc":[{"batb":[[0,1.03,1245.73],[1,1.02,3190.18],[2,1.01,18.37]],"batl":[[0,1.07,857.06],[1,1.08,338.93]],"ltp":1.05,"tv":1441.1,"id":9631075}]}]}
{"op":"mcm","clk":"1011020400","pt":1580654144357,"mc":[{"id":"1.168222850","rc":[{"batb":[[0,1.02,3190.18],[1,1.01,18.37],[2,1.01,0]],"ltp":1.05,"tv":1441.1,"id":9631075}]}]}
{"op":"mcm","clk":"1011020816","pt":1580654146162,"mc":[{"id":"1.168222850","rc":[{"batb":[[0,1.02,1006.11]],"ltp":1.05,"tv":1441.1,"id":9631075}]}]}
{"op":"mcm","clk":"1011021189","pt":1580654147679,"mc":[{"id":"1.168222850","rc":[{"batb":[[0,1.06,454.62],[1,1.05,1212.09],[2,1.03,635.51]],"ltp":1.05,"tv":1441.1,"id":9631075},{"batb":[[1,11,10.39],[2,3.6,374.22]],"ltp":3.15,"tv":151.62,"id":11772759}]}]}
{"op":"mcm","clk":"1011021773","pt":1580654150113,"mc":[{"id":"1.168222850","rc":[{"batb":[[2,1.03,2207.39]],"ltp":1.05,"tv":1441.1,"id":9631075}]}]}
{"op":"mcm","clk":"1011028354","pt":1580654178017,"mc":[{"id":"1.168222850","rc":[{"batb":[[0,1.03,2207.39],[1,1.02,7.87],[2,1.01,18.37]],"batl":[[0,1.08,338.93],[1,1.08,0]],"ltp":1.05,"tv":1441.1,"id":9631075},{"batb":[[0,11,10.39],[1,3.6,374.22],[2,1.01,10.51]],"ltp":3.15,"tv":151.62,"id":11772759}]}]}
{"op":"mcm","clk":"1011029028","pt":1580654180997,"mc":[{"id":"1.168222850","rc":[{"batb":[[0,1.04,1233.76],[1,1.03,2207.39],[2,1.02,7.87]],"batl":[[0,1.08,779.11],[1,1.09,405.19]],"ltp":1.05,"tv":1441.1,"id":9631075}]}]}
{"op":"mcm","clk":"1011030525","pt":1580654187599,"mc":[{"id":"1.168222850","rc":[{"batb":[[1,1.03,635.51]],"ltp":1.05,"tv":1441.1,"id":9631075}]}]}
{"op":"mcm","clk":"1011030934","pt":1580654189598,"mc":[{"id":"1.168222850","rc":[{"batl":[[0,1.06,1210.48]],"ltp":1.05,"tv":1441.1,"id":9631075},{"batb":[[0,17,4.09],[1,12.5,7.79],[2,3.6,374.22]],"ltp":3.15,"tv":151.62,"id":11772759}]}]}
{"op":"mcm","clk":"1011031442","pt":1580654191752,"mc":[{"id":"1.168222850","rc":[{"batb":[[2,1.02,2191.95]],"ltp":1.05,"tv":1441.1,"id":9631075}]}]}
{"op":"mcm","clk":"1011033162","pt":1580654199588,"mc":[{"id":"1.168222850","rc":[{"batb":[[0,1.02,2191.95],[1,1.01,18.37],[2,1.02,0]],"ltp":1.05,"tv":1441.1,"id":9631075},{"batb":[[0,12.5,7.79],[1,3.6,374.22],[2,1.01,10.51]],"ltp":3.15,"tv":151.62,"id":11772759}]}]}
{"op":"mcm","clk":"1011033413","pt":1580654200674,"mc":[{"id":"1.168222850","rc":[{"batb":[[0,1.02,7.87]],"ltp":1.05,"tv":1441.1,"id":9631075},{"batb":[[1,1.01,10.51],[2,1.01,0]],"ltp":3.15,"tv":151.62,"id":11772759}]}]}
{"op":"mcm","clk":"1011033757","pt":1580654202363,"mc":[{"id":"1.168222850","rc":[{"batb":[[0,1.02,1265.82]],"batl":[[0,1.07,490.86],[1,1.08,701.74]],"ltp":1.05,"tv":1441.1,"id":9631075}]}]}
{"op":"mcm","clk":"1011036979","pt":1580654216725,"mc":[{"id":"1.168222850","rc":[{"batb":[[0,1.02,7.87]],"ltp":1.05,"tv":1441.1,"id":9631075}]}]}
{"op":"mcm","clk":"1011037665","pt":1580654219730,"mc":[{"id":"1.168222850","rc":[{"batb":[[0,1.06,866.96],[1,1.05,346.78],[2,1.02,7.87]],"ltp":1.05,"tv":1441.1,"id":9631075}]}]}
{"op":"mcm","clk":"1011037899","pt":1580654220737,"mc":[{"id":"1.168222850","rc":[{"batb":[[1,1.05,775.44],[2,1.03,634.49]],"ltp":1.05,"tv":1441.1,"id":9631075},{"batb":[[1,10.5,11.88],[2,1.01,10.51]],"ltp":3.15,"tv":151.62,"id":11772759}]}]}
{"op":"mcm","clk":"1011038383","pt":1580654222745,"mc":[{"id":"1.168222850","rc":[{"batb":[[2,1.03,2206.37]],"ltp":1.05,"tv":1441.1,"id":9631075},{"batb":[[2,3.85,370.95]],"ltp":3.15,"tv":151.62,"id":11772759}]}]}
{"op":"mcm","clk":"1011042743","pt":1580654241125,"mc":[{"id":"1.168222850","rc":[{"batb":[[0,1.06,815.59]],"batl":[[1,1.08,651.28]],"ltp":1.05,"tv":1441.1,"id":9631075}]}]}
{"op":"mcm","clk":"1011043100","pt":1580654242669,"mc":[{"id":"1.168222850","rc":[{"batb":[[0,1.05,428.66],[1,1.03,2206.37],[2,1.02,7.87]],"batl":[[0,1.08,288.85],[1,1.08,0]],"ltp":1.05,"tv":1441.1,"id":9631075}]}]}
{"op":"mcm","clk":"1011043299","pt":1580654243673,"mc":[{"id":"1.168222850","rc":[{"batb":[[0,1.03,2204.64],[1,1.02,7.87],[2,1.01,18.37]],"ltp":1.05,"tv":1441.1,"id":9631075},{"batb":[[0,10.5,11.88],[1,3.85,370.95],[2,1.01,10.51]],"ltp":3.15,"tv":151.62,"id":11772759}]}]}
{"op":"mcm","clk":"1011043713","pt":1580654245575,"mc":[{"id":"1.168222850","rc":[{"batb":[[0,1.04,1233.76],[1,1.03,2204.64],[2,1.02,7.87]],"batl":[[1,1.09,890.95]],"ltp":1.05,"tv":1441.1,"id":9631075}]}]}
{"op":"mcm","clk":"1011043985","pt":1580654246658,"mc":[{"id":"1.168222850","rc":[{"batb":[[0,1.03,2204.64],[1,1.02,7.87],[2,1.01,18.37]],"ltp":1.05,"tv":1441.1,"id":9631075}]}]}
{"op":"mcm","clk":"1011044664","pt":1580654249655,"mc":[{"id":"1.168222850","rc":[{"batb":[[0,1.07,814.81],[1,1.06,383.48],[2,1.03,632.76]],"ltp":1.05,"tv":1441.1,"id":9631075}]}]}
{"op":"mcm","clk":"1011044855","pt":1580654250575,"mc":[{"id":"1.168222850","rc":[{"batb":[[0,1.07,1149.37]],"ltp":1.05,"tv":1441.1,"id":9631075},{"batb":[[1,6.8,13.3],[2,3.85,370.95]],"ltp":3.15,"tv":151.62,"id":11772759}]}]}
{"op":"mcm","clk":"1011045494","pt":1580654253259,"mc":[{"id":"1.168222850","rc":[{"batb":[[2,1.04,1263]],"ltp":1.05,"tv":1441.1,"id":9631075}]}]}
{"op":"mcm","clk":"1011046599","pt":1580654258086,"mc":[{"id":"1.168222850","rc":[{"batl":[[0,1.08,291.38]],"ltp":1.05,"tv":1441.1,"id":9631075}]}]}
{"op":"mcm","clk":"1011049630","pt":1580654271204,"mc":[{"id":"1.168222850","rc":[{"batl":[[0,1.08,288.85]],"ltp":1.05,"tv":1441.1,"id":9631075}]}]}
{"op":"mcm","clk":"1011050403","pt":1580654274415,"mc":[{"id":"1.168222850","rc":[{"trd":[[1.07,5.06]],"batb":[[0,1.07,1146.84]],"ltp":1.07,"tv":1446.16,"id":9631075}],"tv":1597.78}]}
{"op":"mcm","clk":"1011052326","pt":1580654282622,"mc":[{"id":"1.168222850","rc":[{"batb":[[0,1.04,1263],[1,1.03,632.76],[2,1.02,7.87]],"ltp":1.07,"tv":1446.16,"id":9631075},{"batb":[[0,6.8,13.3],[1,3.85,370.95],[2,1.01,10.51]],"ltp":3.15,"tv":151.62,"id":11772759}]}]}
{"op":"mcm","clk":"1011052543","pt":1580654283613,"mc":[{"id":"1.168222850","rc":[{"batb":[[0,1.03,632.76],[1,1.02,7.87],[2,1.01,18.37]],"ltp":1.07,"tv":1446.16,"id":9631075},{"batb":[[1,1.01,10.51],[2,1.01,0]],"ltp":3.15,"tv":151.62,"id":11772759}]}]}
{"op":"mcm","clk":"1011053028","pt":1580654285731,"mc":[{"id":"1.168222850","rc":[{"batb":[[0,1.04,201.38],[1,1.03,1670.54],[2,1.02,7.87]],"batl":[[0,1.15,232.24],[1,1.16,703.04]],"ltp":1.07,"tv":1446.16,"id":9631075},{"batb":[[0,7,12.75],[1,6.8,13.3],[2,1.01,10.51]],"ltp":3.15,"tv":151.62,"id":11772759}]}]}
{"op":"mcm","clk":"1011053247","pt":1580654286609,"mc":[{"id":"1.168222850","rc":[{"batb":[[0,1.03,632.76],[1,1.02,7.87],[2,1.01,18.37]],"ltp":1.07,"tv":1446.16,"id":9631075},{"batb":[[1,1.01,10.51],[2,1.01,0]],"ltp":3.15,"tv":151.62,"id":11772759}]}]}
{"op":"mcm","clk":"1011053605","pt":1580654288134,"mc":[{"id":"1.168222850","rc":[{"batl":[[0,1.07,4.4]],"ltp":1.07,"tv":1446.16,"id":9631075}]}]}
{"op":"mcm","clk":"1011053971","pt":1580654289607,"mc":[{"id":"1.168222850","rc":[{"trd":[[1.07,13.86]],"batb":[[0,1.08,1084.98],[1,1.03,632.76],[2,1.02,7.87]],"batl":[[0,1.1,1063.21]],"ltp":1.07,"tv":1454.96,"id":9631075}],"tv":1606.58}]}
{"op":"mcm","clk":"1011054328","pt":1580654291131,"mc":[{"id":"1.168222850","rc":[{"batb":[[1,1.05,1069.56],[2,1.03,632.76]],"ltp":1.07,"tv":1454.96,"id":9631075},{"batb":[[1,3.6,374.22],[2,1.01,10.51]],"ltp":3.15,"tv":151.62,"id":11772759}]}]}
{"op":"mcm","clk":"1011055015","pt":1580654294141,"mc":[{"id":"1.168222850","rc":[{"batb":[[0,1.05,1069.56],[1,1.03,632.76],[2,1.02,7.87]],"ltp":1.07,"tv":1454.96,"id":9631075}]}]}
{"op":"mcm","clk":"1011055336","pt":1580654295605,"mc":[{"id":"1.168222850","rc":[{"batb":[[0,1.03,632.76],[1,1.02,7.87],[2,1.01,18.37]],"ltp":1.07,"tv":1454.96,"id":9631075},{"batb":[[1,1.01,10.51],[2,1.01,0]],"ltp":3.15,"tv":151.62,"id":11772759}]}]}
{"op":"mcm","clk":"1011055659","pt":1580654297055,"mc":[{"id":"1.168222850","rc":[{"batb":[[0,1.04,199.71],[1,1.03,1672.22],[2,1.02,7.87]],"batl":[[0,1.15,233.73],[1,1.16,703.05]],"ltp":1.07,"tv":1454.96,"id":9631075}]}]}
{"op":"mcm","clk":"1011057112","pt":1580654303729,"mc":[{"id":"1.168222850","rc":[{"batl":[[0,1.05,1217.48]],"ltp":1.07,"tv":1454.96,"id":9631075},{"batb":[[0,17.5,7.47],[1,10,13.69],[2,7,12.75]],"ltp":3.15,"tv":151.62,"id":11772759}]}]}
{"op":"mcm","clk":"1011057328","pt":1580654304707,"mc":[{"id":"1.168222850","rc":[{"batb":[[2,4.1,374.13]],"ltp":3.15,"tv":151.62,"id":11772759}]}]}
{"op":"mcm","clk":"1011061141","pt":1580654322744,"mc":[{"id":"1.168222850","rc":[{"batb":[[0,1.03,632.76],[1,1.02,7.87],[2,1.01,4084.84]],"ltp":1.07,"tv":1454.96,"id":9631075}]}]}
{"op":"mcm","clk":"1011061324","pt":1580654323668,"mc":[{"id":"1.168222850","rc":[{"batb":[[0,1.02,7.87],[1,1.01,4084.84],[2,1.01,0]],"ltp":1.07,"tv":1454.96,"id":9631075},{"batb":[[0,10,13.69],[1,4.1,374.13],[2,1.01,10.51]],"ltp":3.15,"tv":151.62,"id":11772759}]}]}
{"op":"mcm","clk":"1011061775","pt":1580654325629,"mc":[{"id":"1.168222850","rc":[{"batb":[[1,1.01,1284.06]],"batl":[[0,1.1,1162.14]],"ltp":1.07,"tv":1454.96,"id":9631075},{"batb":[[1,1.01,10.51],[2,1.01,0]],"ltp":3.15,"tv":151.62,"id":11772759}]}]}
{"op":"mcm","clk":"1011064803","pt":1580654340596,"mc":[{"id":"1.168222850","rc":[{"trd":[[1.02,15.74]],"batb":[[0,1.01,1452.1],[1,1.01,0]],"batl":[[0,1.02,1252.97]],"ltp":1.02,"tv":1470.7,"id":9631075}],"tv":1622.32}]}
{"op":"mcm","clk":"1011064928","pt":1580654341158,"mc":[{"id":"1.168222850","rc":[{"batl":[[0,1.02,1245.41]],"ltp":1.02,"tv":1470.7,"id":9631075},{"batb":[[0,17,7.63]],"ltp":3.15,"tv":151.62,"id":11772759}]}]}
{"op":"mcm","clk":"1011065253","pt":1580654342662,"mc":[{"id":"1.168222850","rc":[{"batb":[[1,4.5,371.06],[2,1.01,10.51]],"ltp":3.15,"tv":151.62,"id":11772759}]}]}
{"op":"mcm","clk":"1011065449","pt":1580654343543,"mc":[{"id":"1.168222850","rc":[{"batl":[[0,1.02,1287.42]],"ltp":1.02,"tv":1470.7,"id":9631075}]}]}
{"op":"mcm","clk":"1011067310","pt":1580654352653,"mc":[{"id":"1.168222850","rc":[{"trd":[[1.02,31.48]],"batl":[[0,1.02,1279.55]],"ltp":1.02,"tv":1486.44,"id":9631075}],"tv":1638.06}]}
{"op":"mcm","clk":"1011069187","pt":1580654361667,"mc":[{"id":"1.168222850","rc":[{"batb":[[0,1.01,186.41]],"batl":[[0,1.02,42.01]],"ltp":1.02,"tv":1486.44,"id":9631075}]}]}
{"op":"mcm","clk":"1011069610","pt":1580654363693,"mc":[{"id":"1.168222850","rc":[{"batb":[[0,1.01,18.37]],"ltp":1.02,"tv":1486.44,"id":9631075}]}]}
{"op":"mcm","clk":"1011069828","pt":1580654364672,"mc":[{"id":"1.168222850","rc":[{"batl":[[0,1.05,1217.48]],"ltp":1.02,"tv":1486.44,"id":9631075},{"batb":[[1,1.01,10.51],[2,1.01,0]],"ltp":3.15,"tv":151.62,"id":11772759}]}]}
{"op":"mcm","clk":"1011070869","pt":1580654369001,"mc":[{"id":"1.168222850","rc":[{"batb":[[0,1.02,1253.28],[1,1.01,18.37]],"batl":[[0,1.03,1241.11]],"ltp":1.02,"tv":1486.44,"id":9631075}]}]}
{"op":"mcm","clk":"1011071425","pt":1580654371391,"mc":[{"id":"1.168222850","rc":[{"batb":[[1,4.4,375.46],[2,1.01,10.51]],"ltp":3.15,"tv":151.62,"id":11772759}]}]}
{"op":"mcm","clk":"1011071712","pt":1580654372380,"mc":[{"id":"1.168222850","rc":[{"batb":[[0,1.01,18.37],[1,1.01,0]],"ltp":1.02,"tv":1486.44,"id":9631075}]}]}
{"op":"mcm","clk":"1011072101","pt":1580654374284,"mc":[{"id":"1.168222850","rc":[{"batb":[[1,1.01,10.51],[2,1.01,0]],"ltp":3.15,"tv":151.62,"id":11772759}]}]}
{"op":"mcm","clk":"1011072226","pt":1580654374884,"mc":[{"id":"1.168222850","rc":[{"batl":[[0,1.05,1217.48]],"ltp":1.02,"tv":1486.44,"id":9631075}]}]}
{"op":"mcm","clk":"1011073982","pt":1580654383201,"mc":[{"id":"1.168222850","rc":[{"batb":[[0,1.01,10.51],[1,1.01,0]],"ltp":3.15,"tv":151.62,"id":11772759}]}]}
{"op":"mcm","clk":"1011074505","pt":1580654385701,"mc":[{"id":"1.168222850","rc":[{"trd":[[1.01,36.75]],"batl":[[0,1.01,1247.31]],"ltp":1.01,"tv":1523.19,"id":9631075}],"tv":1674.82}]}
{"op":"mcm","clk":"1011074904","pt":1580654387477,"mc":[{"id":"1.168222850","rc":[{"batb":[[0,4.8,367.63],[1,1.01,10.51]],"ltp":3.15,"tv":151.62,"id":11772759}]}]}
{"op":"mcm","clk":"1011080128","pt":1580654411652,"mc":[{"id":"1.168222850","rc":[{"batb":[[0,1.01,10.51],[1,1.01,0]],"ltp":3.15,"tv":151.62,"id":11772759}]}]}
{"op":"mcm","clk":"1011080323","pt":1580654412522,"mc":[{"id":"1.168222850","rc":[{"batl":[[0,1.02,1253.28]],"ltp":1.01,"tv":1523.19,"id":9631075}]}]}
{"op":"mcm","clk":"1011081158","pt":1580654416477,"mc":[{"id":"1.168222850","marketDefinition":{"bspMarket":false,"turnInPlayEnabled":true,"persistenceEnabled":true,"marketBaseRate":5.0,"eventId":"29681551","eventTypeId":"2","numberOfWinners":1,"bettingType":"ODDS","marketType":"SET_WINNER","marketTime":"2020-02-02T13:52:00.000Z","suspendTime":"2020-02-02T13:52:00.000Z","bspReconciled":false,"complete":true,"inPlay":true,"crossMatching":true,"runnersVoidable":false,"numberOfActiveRunners":2,"betDelay":3,"status":"SUSPENDED","runners":[{"status":"ACTIVE","sortPriority":1,"id":11772759,"name":"Juan Pablo Varillas"},{"status":"ACTIVE","sortPriority":2,"id":9631075,"name":"Carlos Taberner"}],"regulators":["MR_INT"],"countryCode":"AR","discountAllowed":true,"timezone":"UTC","openDate":"2020-02-02T13:52:00.000Z","version":3149250970,"name":"Set 1 Winner","eventName":"Jua Varillas v Taberner"}}]}
{"op":"mcm","clk":"1011088497","pt":1580654450081,"mc":[{"id":"1.168222850","tv":0.0}]}
{"op":"mcm","clk":"1011088806","pt":1580654451473,"mc":[{"id":"1.168222850","marketDefinition":{"bspMarket":false,"turnInPlayEnabled":true,"persistenceEnabled":true,"marketBaseRate":5.0,"eventId":"29681551","eventTypeId":"2","numberOfWinners":1,"bettingType":"ODDS","marketType":"SET_WINNER","marketTime":"2020-02-02T13:52:00.000Z","suspendTime":"2020-02-02T13:52:00.000Z","bspReconciled":false,"complete":true,"inPlay":true,"crossMatching":false,"runnersVoidable":false,"numberOfActiveRunners":0,"betDelay":3,"status":"CLOSED","settledTime":"2020-02-02T14:40:48.000Z","runners":[{"status":"LOSER","sortPriority":1,"id":11772759,"name":"Juan Pablo Varillas"},{"status":"WINNER","sortPriority":2,"id":9631075,"name":"Carlos Taberner"}],"regulators":["MR_INT"],"countryCode":"AR","discountAllowed":true,"timezone":"UTC","openDate":"2020-02-02T13:52:00.000Z","version":3149252291,"name":"Set 1 Winner","eventName":"Jua Varillas v Taberner"}}]}
