{"op":"mcm","clk":"1004097111","pt":1580580427532,"mc":[{"id":"1.168222849","marketDefinition":{"bspMarket":false,"turnInPlayEnabled":true,"persistenceEnabled":true,"marketBaseRate":5.0,"eventId":"29681551","eventTypeId":"2","numberOfWinners":1,"bettingType":"ODDS","marketType":"SET_BETTING","marketTime":"2020-02-02T13:00:00.000Z","suspendTime":"2020-02-02T13:00:00.000Z","bspReconciled":false,"complete":true,"inPlay":false,"crossMatching":false,"runnersVoidable":false,"numberOfActiveRunners":4,"betDelay":0,"status":"OPEN","runners":[{"status":"ACTIVE","sortPriority":1,"id":19613367,"name":"Jua Varillas 2-0"},{"status":"ACTIVE","sortPriority":2,"id":19613369,"name":"Jua Varillas 2-1"},{"status":"ACTIVE","sortPriority":3,"id":16573039,"name":"Taberner 2-0"},{"status":"ACTIVE","sortPriority":4,"id":16573041,"name":"Taberner 2-1"}],"regulators":["MR_INT"],"countryCode":"AR","discountAllowed":false,"timezone":"UTC","openDate":"2020-02-02T13:00:00.000Z","version":3146764516,"name":"Set Betting","eventName":"Jua Varillas v Taberner"}}]}
{"op":"mcm","clk":"1004097346","pt":1580580428747,"mc":[{"id":"1.168222849","marketDefinition":{"bspMarket":false,"turnInPlayEnabled":true,"persistenceEnabled":true,"marketBaseRate":5.0,"eventId":"29681551","eventTypeId":"2","numberOfWinners":1,"bettingType":"ODDS","marketType":"SET_BETTING","marketTime":"2020-02-02T13:00:00.000Z","suspendTime":"2020-02-02T13:00:00.000Z","bspReconciled":false,"complete":true,"inPlay":false,"crossMatching":false,"runnersVoidable":false,"numberOfActiveRunners":4,"betDelay":0,"status":"OPEN","runners":[{"status":"ACTIVE","sortPriority":1,"id":19613367,"name":"Jua Varillas 2-0"},{"status":"ACTIVE","sortPriority":2,"id":19613369,"name":"Jua Varillas 2-1"},{"status":"ACTIVE","sortPriority":3,"id":16573039,"name":"Taberner 2-0"},{"status":"ACTIVE","sortPriority":4,"id":16573041,"name":"Taberner 2-1"}],"regulators":["MR_INT"],"countryCode":"AR","discountAllowed":false,"timezone":"UTC","openDate":"2020-02-02T13:00:00.000Z","version":3146764516,"name":"Set Betting","eventName":"Jua Varillas v Taberner"}}]}
{"op":"mcm","clk":"1004097530","pt":1580580429751,"mc":[{"id":"1.168222849","marketDefinition":{"bspMarket":false,"turnInPlayEnabled":true,"persistenceEnabled":true,"marketBaseRate":5.0,"eventId":"29681551","eventTypeId":"2","numberOfWinners":1,"bettingType":"ODDS","marketType":"SET_BETTING","marketTime":"2020-02-02T13:00:00.000Z","suspendTime":"2020-02-02T13:00:00.000Z","bspReconciled":false,"complete":true,"inPlay":false,"crossMatching":false,"runnersVoidable":false,"numberOfActiveRunners":4,"betDelay":0,"status":"OPEN","runners":[{"status":"ACTIVE","sortPriority":1,"id":19613367,"name":"Jua Varillas 2-0"},{"status":"ACTIVE","sortPriority":2,"id":19613369,"name":"Jua Varillas 2-1"},{"status":"ACTIVE","sortPriority":3,"id":16573039,"name":"Taberner 2-0"},{"status":"ACTIVE","sortPriority":4,"id":16573041,"name":"Taberner 2-1"}],"regulators":["MR_INT"],"countryCode":"AR","discountAllowed":true,"timezone":"UTC","openDate":"2020-02-02T13:00:00.000Z","version":3146764516,"name":"Set Betting","eventName":"Jua Varillas v Taberner"}}]}
{"op":"mcm","clk":"1004153174","pt":1580580736385,"mc":[{"id":"1.168222849","rc":[{"batb":[[0,1.02,2]],"ltp":0.0,"tv":0.0,"id":19613369},{"batb":[[0,1.02,2]],"ltp":0.0,"tv":0.0,"id":19613367},{"batb":[[0,1.02,2]],"ltp":0.0,"tv":0.0,"id":16573039},{"batb":[[0,1.02,2]],"ltp":0.0,"tv":0.0,"id":16573041}]}]}
{"op":"mcm","clk":"1005739150","pt":1580590302889,"mc":[{"id":"1.168222849","marketDefinition":{"bspMarket":false,"turnInPlayEnabled":true,"persistenceEnabled":true,"marketBaseRate":5.0,"eventId":"29681551","eventTypeId":"2","numberOfWinners":1,"bettingType":"ODDS","marketType":"SET_BETTING","marketTime":"2020-02-02T14:00:00.000Z","suspendTime":"2020-02-02T14:00:00.000Z","bspReconciled":false,"complete":true,"inPlay":false,"crossMatching":false,"runnersVoidable":false,"numberOfActiveRunners":4,"betDelay":0,"status":"OPEN","runners":[{"status":"ACTIVE","sortPriority":1,"id":19613367,"name":"Jua Varillas 2-0"},{"status":"ACTIVE","sortPriority":2,"id":19613369,"name":"Jua Varillas 2-1"},{"status":"ACTIVE","sortPriority":3,"id":16573039,"name":"Taberner 2-0"},{"status":"ACTIVE","sortPriority":4,"id":16573041,"name":"Taberner 2-1"}],"regulators":["MR_INT"],"countryCode":"AR","discountAllowed":true,"timezone":"UTC","openDate":"2020-02-02T13:00:00.000Z","version":3147422161,"name":"Set Betting","eventName":"Jua Varillas v Taberner"}}]}
{"op":"mcm","clk":"1005739706","pt":1580590307869,"mc":[{"id":"1.168222849","marketDefinition":{"bspMarket":false,"turnInPlayEnabled":true,"persistenceEnabled":true,"marketBaseRate":5.0,"eventId":"29681551","eventTypeId":"2","numberOfWinners":1,"bettingType":"ODDS","marketType":"SET_BETTING","marketTime":"2020-02-02T14:00:00.000Z","suspendTime":"2020-02-02T14:00:00.000Z","bspReconciled":false,"complete":true,"inPlay":false,"crossMatching":false,"runnersVoidable":false,"numberOfActiveRunners":4,"betDelay":0,"status":"OPEN","runners":[{"status":"ACTIVE","sortPriority":1,"id":19613367,"name":"Jua Varillas 2-0"},{"status":"ACTIVE","sortPriority":2,"id":19613369,"name":"Jua Varillas 2-1"},{"status":"ACTIVE","sortPriority":3,"id":16573039,"name":"Taberner 2-0"},{"status":"ACTIVE","sortPriority":4,"id":16573041,"name":"Taberner 2-1"}],"regulators":["MR_INT"],"countryCode":"AR","discountAllowed":true,"timezone":"UTC","openDate":"2020-02-02T14:00:00.000Z","version":3147422161,"name":"Set Betting","eventName":"Jua Varillas v Taberner"}}]}
{"op":"mcm","clk":"1006634369","pt":1580598654146,"mc":[{"id":"1.168222849","rc":[{"batb":[[0,2.34,30.29],[1,1.02,2]],"ltp":0.0,"tv":0.0,"id":16573039}]}]}
{"op":"mcm","clk":"1006972855","pt":1580602758598,"mc":[{"id":"1.168222849","rc":[{"batb":[[1,1.01,0.51]],"ltp":0.0,"tv":0.0,"id":19613369},{"batb":[[1,1.01,0.51]],"ltp":0.0,"tv":0.0,"id":19613367},{"batb":[[2,1.01,0.51]],"ltp":0.0,"tv":0.0,"id":16573039},{"batb":[[1,1.01,0.51]],"ltp":0.0,"tv":0.0,"id":16573041}]}]}
{"op":"mcm","clk":"1007029663","pt":1580603522651,"mc":[{"id":"1.168222849","rc":[{"batb":[[1,1.01,1.01]],"ltp":0.0,"tv":0.0,"id":19613369},{"batb":[[1,1.01,1.01]],"ltp":0.0,"tv":0.0,"id":19613367},{"batb":[[2,1.01,1.01]],"ltp":0.0,"tv":0.0,"id":16573039},{"batb":[[1,1.01,1.01]],"ltp":0.0,"tv":0.0,"id":16573041}]}]}
{"op":"mcm","clk":"1008390180","pt":1580634438271,"mc":[{"id":"1.168222849","rc":[{"batb":[[0,2.36,30.29],[1,1.02,2],[2,1.01,1.01]],"ltp":0.0,"tv":0.0,"id":19613367}]}]}
{"op":"mcm","clk":"1008405089","pt":1580634682065,"mc":[{"id":"1.168222849","rc":[{"batb":[[0,1.02,2],[1,1.01,1.01],[2,1.01,0]],"ltp":0.0,"tv":0.0,"id":16573039}]}]}
{"op":"mcm","clk":"1009224966","pt":1580642856094,"mc":[{"id":"1.168222849","rc":[{"batl":[[0,5.2,11.36]],"ltp":0.0,"tv":0.0,"id":16573041}]}]}
{"op":"mcm","clk":"1009225950","pt":1580642862085,"mc":[{"id":"1.168222849","marketDefinition":{"bspMarket":false,"turnInPlayEnabled":true,"persistenceEnabled":true,"marketBaseRate":5.0,"eventId":"29681551","eventTypeId":"2","numberOfWinners":1,"bettingType":"ODDS","marketType":"SET_BETTING","marketTime":"2020-02-02T14:00:00.000Z","suspendTime":"2020-02-02T14:00:00.000Z","bspReconciled":false,"complete":true,"inPlay":false,"crossMatching":true,"runnersVoidable":false,"numberOfActiveRunners":4,"betDelay":0,"status":"OPEN","runners":[{"status":"ACTIVE","sortPriority":1,"id":19613367,"name":"Jua Varillas 2-0"},{"status":"ACTIVE","sortPriority":2,"id":19613369,"name":"Jua Varillas 2-1"},{"status":"ACTIVE","sortPriority":3,"id":16573039,"name":"Taberner 2-0"},{"status":"ACTIVE","sortPriority":4,"id":16573041,"name":"Taberner 2-1"}],"regulators":["MR_INT"],"countryCode":"AR","discountAllowed":true,"timezone":"UTC","openDate":"2020-02-02T14:00:00.000Z","version":3147422161,"name":"Set Betting","eventName":"Jua Varillas v Taberner"}}]}
{"op":"mcm","clk":"1009977883","pt":1580648403061,"mc":[{"id":"1.168222849","rc":[{"batb":[[0,1.03,2],[1,1.02,2],[2,1.01,1.01]],"ltp":0.0,"tv":0.0,"id":16573041}]}]}
{"op":"mcm","clk":"1010072999","pt":1580649002345,"mc":[{"id":"1.168222849","rc":[{"batb":[[0,1.02,2],[1,1.01,1.01],[2,1.01,0]],"ltp":0.0,"tv":0.0,"id":16573041}]}]}
{"op":"mcm","clk":"1010073142","pt":1580649003238,"mc":[{"id":"1.168222849","rc":[{"batb":[[0,1.03,2],[1,1.02,2],[2,1.01,1.01]],"ltp":0.0,"tv":0.0,"id":16573041}]}]}
{"op":"mcm","clk":"1010172657","pt":1580649603163,"mc":[{"id":"1.168222849","rc":[{"batb":[[0,1.02,2],[1,1.01,1.01],[2,1.01,0]],"ltp":0.0,"tv":0.0,"id":16573041}]}]}
{"op":"mcm","clk":"1010173933","pt":1580649611581,"mc":[{"id":"1.168222849","rc":[{"batb":[[0,1.03,2],[1,1.02,2],[2,1.01,1.01]],"ltp":0.0,"tv":0.0,"id":16573041}]}]}
{"op":"mcm","clk":"1010218412","pt":1580649915299,"mc":[{"id":"1.168222849","rc":[{"batb":[[0,1.04,2.02],[1,1.03,2],[2,1.02,2]],"ltp":0.0,"tv":0.0,"id":16573041}]}]}
{"op":"mcm","clk":"1010263585","pt":1580650210774,"mc":[{"id":"1.168222849","rc":[{"batb":[[1,1.02,2],[2,1.01,1.01]],"ltp":0.0,"tv":0.0,"id":16573041}]}]}
{"op":"mcm","clk":"1010366285","pt":1580650824703,"mc":[{"id":"1.168222849","rc":[{"batb":[[0,1.03,137],[1,1.02,2],[2,1.01,1.01]],"ltp":0.0,"tv":0.0,"id":19613369},{"batb":[[0,2.38,6],[1,2.36,30.29],[2,1.02,2]],"ltp":0.0,"tv":0.0,"id":19613367},{"batb":[[0,1.03,137],[1,1.02,2],[2,1.01,1.01]],"ltp":0.0,"tv":0.0,"id":16573039},{"batb":[[0,1.05,84],[1,1.04,2.02],[2,1.02,2]],"ltp":0.0,"tv":0.0,"id":16573041}]}]}
{"op":"mcm","clk":"1010376114","pt":1580650884918,"mc":[{"id":"1.168222849","rc":[{"batl":[[0,5.4,4]],"ltp":0.0,"tv":0.0,"id":19613369},{"batl":[[0,3.55,5]],"ltp":0.0,"tv":0.0,"id":19613367},{"batl":[[0,3.3,5]],"ltp":0.0,"tv":0.0,"id":16573039},{"batl":[[1,5.3,4]],"ltp":0.0,"tv":0.0,"id":16573041}]}]}
{"op":"mcm","clk":"1010414502","pt":1580651112107,"mc":[{"id":"1.168222849","rc":[{"batb":[[1,1.02,2],[2,1.01,1.01]],"ltp":0.0,"tv":0.0,"id":19613367}]}]}
{"op":"mcm","clk":"1010439914","pt":1580651247651,"mc":[{"id":"1.168222849","rc":[{"batb":[[0,1.02,2],[1,1.01,1.01],[2,1.01,0]],"ltp":0.0,"tv":0.0,"id":19613369},{"batb":[[0,1.02,2],[1,1.01,1.01],[2,1.01,0]],"ltp":0.0,"tv":0.0,"id":19613367},{"batb":[[0,1.02,2],[1,1.01,1.01],[2,1.01,0]],"ltp":0.0,"tv":0.0,"id":16573039},{"batb":[[0,1.04,2.02],[1,1.02,2],[2,1.01,1.01]],"ltp":0.0,"tv":0.0,"id":16573041}]}]}
{"op":"mcm","clk":"1010440017","pt":1580651248055,"mc":[{"id":"1.168222849","rc":[{"batb":[[0,1.03,137],[1,1.02,2],[2,1.01,1.01]],"ltp":0.0,"tv":0.0,"id":19613369},{"batb":[[0,1.03,137],[1,1.02,2],[2,1.01,1.01]],"ltp":0.0,"tv":0.0,"id":19613367},{"batb":[[0,1.03,137],[1,1.02,2],[2,1.01,1.01]],"ltp":0.0,"tv":0.0,"id":16573039},{"batb":[[0,1.05,84],[1,1.04,2.02],[2,1.02,2]],"ltp":0.0,"tv":0.0,"id":16573041}]}]}
{"op":"mcm","clk":"1010494854","pt":1580651596686,"mc":[{"id":"1.168222849","rc":[{"batb":[[0,4.7,14.87],[1,1.03,137],[2,1.02,2]],"batl":[[1,5.5,14.24]],"ltp":0.0,"tv":0.0,"id":19613369},{"batb":[[0,3.35,17.31],[1,1.03,137],[2,1.02,2]],"batl":[[1,3.75,16.76]],"ltp":0.0,"tv":0.0,"id":19613367},{"batb":[[0,3,22.98],[1,1.03,137],[2,1.02,2]],"batl":[[1,3.35,22.11]],"ltp":0.0,"tv":0.0,"id":16573039},{"batb":[[0,4.5,17],[1,1.05,84],[2,1.04,2.02]],"batl":[[0,5.2,27.57]],"ltp":0.0,"tv":0.0,"id":16573041}]}]}
{"op":"mcm","clk":"1010495054","pt":1580651598091,"mc":[{"id":"1.168222849","rc":[{"batb":[[1,2.94,5.42],[2,1.03,137]],"ltp":0.0,"tv":0.0,"id":19613369},{"batb":[[1,2.48,5.51],[2,1.03,137]],"ltp":0.0,"tv":0.0,"id":19613367},{"batb":[[1,1.99,7.51],[2,1.03,137]],"ltp":0.0,"tv":0.0,"id":16573039},{"batb":[[1,3.1,5.14],[2,1.05,84]],"ltp":0.0,"tv":0.0,"id":16573041}]}]}
{"op":"mcm","clk":"1010524387","pt":1580651803462,"mc":[{"id":"1.168222849","marketDefinition":{"bspMarket":false,"turnInPlayEnabled":true,"persistenceEnabled":true,"marketBaseRate":5.0,"eventId":"29681551","eventTypeId":"2","numberOfWinners":1,"bettingType":"ODDS","marketType":"SET_BETTING","marketTime":"2020-02-02T13:52:00.000Z","suspendTime":"2020-02-02T13:52:00.000Z","bspReconciled":false,"complete":true,"inPlay":false,"crossMatching":true,"runnersVoidable":false,"numberOfActiveRunners":4,"betDelay":0,"status":"OPEN","runners":[{"status":"ACTIVE","sortPriority":1,"id":19613367,"name":"Jua Varillas 2-0"},{"status":"ACTIVE","sortPriority":2,"id":19613369,"name":"Jua Varillas 2-1"},{"status":"ACTIVE","sortPriority":3,"id":16573039,"name":"Taberner 2-0"},{"status":"ACTIVE","sortPriority":4,"id":16573041,"name":"Taberner 2-1"}],"regulators":["MR_INT"],"countryCode":"AR","discountAllowed":true,"timezone":"UTC","openDate":"2020-02-02T14:00:00.000Z","version":3149006715,"name":"Set Betting","eventName":"Jua Varillas v Taberner"}}]}
{"op":"mcm","clk":"1010524498","pt":1580651804119,"mc":[{"id":"1.168222849","rc":[{"batb":[[1,1.03,137],[2,1.02,2]],"ltp":0.0,"tv":0.0,"id":19613369},{"batb":[[1,1.03,137],[2,1.02,2]],"ltp":0.0,"tv":0.0,"id":19613367},{"batb":[[1,1.03,137],[2,1.02,2]],"ltp":0.0,"tv":0.0,"id":16573039},{"batb":[[1,1.05,84],[2,1.04,2.02]],"ltp":0.0,"tv":0.0,"id":16573041}]}]}
{"op":"mcm","clk":"1010524886","pt":1580651806463,"mc":[{"id":"1.168222849","marketDefinition":{"bspMarket":false,"turnInPlayEnabled":true,"persistenceEnabled":true,"marketBaseRate":5.0,"eventId":"29681551","eventTypeId":"2","numberOfWinners":1,"bettingType":"ODDS","marketType":"SET_BETTING","marketTime":"2020-02-02T13:52:00.000Z","suspendTime":"2020-02-02T13:52:00.000Z","bspReconciled":false,"complete":true,"inPlay":false,"crossMatching":true,"runnersVoidable":false,"numberOfActiveRunners":4,"betDelay":0,"status":"OPEN","runners":[{"status":"ACTIVE","sortPriority":1,"id":19613367,"name":"Jua Varillas 2-0"},{"status":"ACTIVE","sortPriority":2,"id":19613369,"name":"Jua Varillas 2-1"},{"status":"ACTIVE","sortPriority":3,"id":16573039,"name":"Taberner 2-0"},{"status":"ACTIVE","sortPriority":4,"id":16573041,"name":"Taberner 2-1"}],"regulators":["MR_INT"],"countryCode":"AR","discountAllowed":true,"timezone":"UTC","openDate":"2020-02-02T13:52:00.000Z","version":3149006715,"name":"Set Betting","eventName":"Jua Varillas v Taberner"}}]}
{"op":"mcm","clk":"1010529710","pt":1580651838348,"mc":[{"id":"1.168222849","rc":[{"batl":[[0,5.1,11.36],[1,5.2,16.21],[2,5.3,4]],"ltp":0.0,"tv":0.0,"id":16573041}]}]}
{"op":"mcm","clk":"1010533665","pt":1580651864552,"mc":[{"id":"1.168222849","rc":[{"batl":[[0,5,11.36]],"ltp":0.0,"tv":0.0,"id":16573041}]}]}
{"op":"mcm","clk":"1010566736","pt":1580652061558,"mc":[{"id":"1.168222849","rc":[{"trd":[[5.4,3.29]],"batl":[[0,5.5,14.95],[1,5.5,0]],"ltp":5.4,"tv":3.29,"id":19613369},{"trd":[[3.55,5]],"batl":[[0,3.75,16.76],[1,3.75,0]],"ltp":3.55,"tv":5.0,"id":19613367},{"trd":[[3,51.87]],"batb":[[0,1.03,137],[1,1.02,2],[2,1.01,1.01]],"batl":[[0,3,139.99],[1,3.3,5],[2,3.35,22.11]],"ltp":3.0,"tv":51.86,"id":16573039},{"trd":[[5,3.55]],"batl":[[0,5,7.81]],"ltp":5.0,"tv":3.55,"id":16573041}],"tv":63.7}]}
{"op":"mcm","clk":"1010566847","pt":1580652062316,"mc":[{"id":"1.168222849","rc":[{"batb":[[0,4.8,14.63]],"batl":[[0,5.6,14.72]],"ltp":5.4,"tv":3.29,"id":19613369},{"batb":[[0,3.4,17]],"batl":[[0,3.8,16.44]],"ltp":3.55,"tv":5.0,"id":19613367},{"batb":[[0,2.96,23.92],[1,1.03,137],[2,1.02,2]],"batl":[[1,3.3,27.98],[2,3.35,0]],"ltp":3.0,"tv":51.86,"id":16573039},{"batb":[[0,4.5,16.76]],"batl":[[1,5.3,19.97],[2,5.3,0]],"ltp":5.0,"tv":3.55,"id":16573041}]}]}
{"op":"mcm","clk":"1010570994","pt":1580652085756,"mc":[{"id":"1.168222849","rc":[{"batb":[[1,4.7,10.92],[2,1.03,137]],"batl":[[0,5.5,9.95],[1,5.6,14.01]],"ltp":5.4,"tv":3.29,"id":19613369},{"batb":[[1,3.35,17.64],[2,1.03,137]],"batl":[[0,3.8,30.73]],"ltp":3.55,"tv":5.0,"id":19613367},{"trd":[[3,135.89]],"batb":[[0,2.96,44.92]],"batl":[[0,3,97.98],[2,3.35,17.64]],"ltp":3.0,"tv":135.88,"id":16573039},{"batb":[[0,4.5,28.52]],"batl":[[1,5.3,29.21]],"ltp":5.0,"tv":3.55,"id":16573041}],"tv":147.72}]}
{"op":"mcm","clk":"1010579029","pt":1580652128719,"mc":[{"id":"1.168222849","rc":[{"trd":[[3,161.92]],"batl":[[0,3,84.96]],"ltp":3.0,"tv":161.92,"id":16573039},{"trd":[[5,15.74]],"batl":[[0,5,1.71]],"ltp":5.0,"tv":15.74,"id":16573041}],"tv":185.95}]}
{"op":"mcm","clk":"1010579209","pt":1580652129621,"mc":[{"id":"1.168222849","rc":[{"trd":[[3,167.62]],"batl":[[0,3,82.11]],"ltp":3.0,"tv":167.61,"id":16573039},{"trd":[[5,19.17]],"batl":[[0,5.3,29.21],[1,5.3,0]],"ltp":5.0,"tv":19.16,"id":16573041}],"tv":195.07}]}
{"op":"mcm","clk":"1010579257","pt":1580652129904,"mc":[{"id":"1.168222849","rc":[{"batb":[[0,5,1.71],[1,4.5,28.52],[2,1.05,84]],"ltp":5.0,"tv":19.16,"id":16573041}]}]}
{"op":"mcm","clk":"1010579491","pt":1580652131212,"mc":[{"id":"1.168222849","rc":[{"batl":[[0,5.5,24.04],[1,5.6,0]],"ltp":5.4,"tv":3.29,"id":19613369},{"batl":[[0,3.75,16.44],[1,3.8,14.28]],"ltp":3.55,"tv":5.0,"id":19613367},{"batl":[[1,3.2,22.98],[2,3.3,5]],"ltp":3.0,"tv":167.61,"id":16573039},{"batb":[[1,4.6,16.68],[2,4.5,11.76]],"batl":[[0,5.2,15.97],[1,5.3,13.24]],"ltp":5.0,"tv":19.16,"id":16573041}]}]}
{"op":"mcm","clk":"1010581153","pt":1580652139703,"mc":[{"id":"1.168222849","rc":[{"trd":[[2.98,20.43]],"batl":[[0,2.98,71.9]],"ltp":2.98,"tv":188.04,"id":16573039},{"trd":[[5.2,11.71]],"batl":[[0,5.2,10.12]],"ltp":5.2,"tv":30.87,"id":16573041}],"tv":227.2}]}
{"op":"mcm","clk":"1010581314","pt":1580652140619,"mc":[{"id":"1.168222849","rc":[{"trd":[[2.98,97.74]],"batl":[[0,2.98,33.24],[2,3.3,22.64]],"ltp":2.98,"tv":265.35,"id":16573039},{"trd":[[5.2,31.94]],"batl":[[0,5.3,13.24],[1,5.3,0]],"ltp":5.2,"tv":51.1,"id":16573041}],"tv":324.75}]}
{"op":"mcm","clk":"1010581506","pt":1580652141652,"mc":[{"id":"1.168222849","rc":[{"batb":[[0,3.35,35.03],[1,1.03,137],[2,1.02,2]],"ltp":3.55,"tv":5.0,"id":19613367},{"batb":[[1,4.7,15.74]],"batl":[[1,5.4,15.11]],"ltp":5.2,"tv":51.1,"id":16573041}]}]}
{"op":"mcm","clk":"1010592933","pt":1580652195421,"mc":[{"id":"1.168222849","rc":[{"trd":[[2.96,66.49]],"batb":[[0,2.96,11.68]],"batl":[[0,3.2,22.98],[1,3.3,22.64],[2,3.3,0]],"ltp":2.96,"tv":331.84,"id":16573039}],"tv":391.24}]}
{"op":"mcm","clk":"1010593176","pt":1580652196412,"mc":[{"id":"1.168222849","rc":[{"batb":[[0,3.45,17.07],[1,3.35,17.64],[2,1.03,137]],"ltp":3.55,"tv":5.0,"id":19613367},{"batb":[[0,2.96,20.92],[1,2.92,24.94],[2,1.03,137]],"batl":[[0,3.15,24]],"ltp":2.96,"tv":331.84,"id":16573039},{"batb":[[1,4.8,15.5],[2,4.6,10.92]],"batl":[[1,5.4,14.79]],"ltp":5.2,"tv":51.1,"id":16573041}]}]}
{"op":"mcm","clk":"1010595461","pt":1580652206524,"mc":[{"id":"1.168222849","rc":[{"batb":[[0,3.4,17.23]],"ltp":3.55,"tv":5.0,"id":19613367},{"batb":[[1,2.92,24.71]],"batl":[[0,3.15,23.76]],"ltp":2.96,"tv":331.84,"id":16573039}]}]}
{"op":"mcm","clk":"1010597680","pt":1580652216682,"mc":[{"id":"1.168222849","rc":[{"batb":[[1,4.8,15.34]],"batl":[[1,5.4,14.63]],"ltp":5.2,"tv":51.1,"id":16573041}]}]}
{"op":"mcm","clk":"1010616517","pt":1580652300397,"mc":[{"id":"1.168222849","rc":[{"trd":[[2.96,108.33]],"batb":[[0,2.92,46.55],[1,1.03,137],[2,1.02,2]],"batl":[[0,2.96,12.85],[1,3.15,23.76],[2,3.3,22.64]],"ltp":2.96,"tv":373.68,"id":16573039}],"tv":433.08}]}
{"op":"mcm","clk":"1010631641","pt":1580652368523,"mc":[{"id":"1.168222849","marketDefinition":{"bspMarket":false,"turnInPlayEnabled":true,"persistenceEnabled":true,"marketBaseRate":5.0,"eventId":"29681551","eventTypeId":"2","numberOfWinners":1,"bettingType":"ODDS","marketType":"SET_BETTING","marketTime":"2020-02-02T13:52:00.000Z","suspendTime":"2020-02-02T13:52:00.000Z","bspReconciled":false,"complete":true,"inPlay":true,"crossMatching":true,"runnersVoidable":false,"numberOfActiveRunners":4,"betDelay":3,"status":"OPEN","runners":[{"status":"ACTIVE","sortPriority":1,"id":19613367,"name":"Jua Varillas 2-0"},{"status":"ACTIVE","sortPriority":2,"id":19613369,"name":"Jua Varillas 2-1"},{"status":"ACTIVE","sortPriority":3,"id":16573039,"name":"Taberner 2-0"},{"status":"ACTIVE","sortPriority":4,"id":16573041,"name":"Taberner 2-1"}],"regulators":["MR_INT"],"countryCode":"AR","discountAllowed":true,"timezone":"UTC","openDate":"2020-02-02T13:52:00.000Z","version":3149113269,"name":"Set Betting","eventName":"Jua Varillas v Taberner"},"rc":[{"batb":[[0,1.01,0.51],[1,4.7,0],[2,1.03,0]],"ltp":5.4,"tv":3.29,"id":19613369},{"batb":[[0,1.01,0.51],[1,3.35,0],[2,1.03,0]],"ltp":3.55,"tv":5.0,"id":19613367},{"batb":[[0,1.01,0.51],[1,1.03,0],[2,1.02,0]],"batl":[[1,3.15,0],[2,3.3,0]],"ltp":2.96,"tv":373.68,"id":16573039},{"batb":[[0,1.01,0.51],[1,4.8,0],[2,4.6,0]],"ltp":5.2,"tv":51.1,"id":16573041}]}]}
{"op":"mcm","clk":"1010635523","pt":1580652386668,"mc":[{"id":"1.168222849","rc":[{"batb":[[0,4.8,14.95],[1,1.01,0.51]],"batl":[[0,5.5,14.16]],"ltp":5.4,"tv":3.29,"id":19613369},{"batb":[[0,3.75,13.93],[1,3.4,17.7],[2,1.01,0.51]],"batl":[[0,4.1,13.53],[1,4.5,21.95]],"ltp":3.55,"tv":5.0,"id":19613367},{"batb":[[0,2.74,11.8],[1,2.56,13.85],[2,1.01,0.51]],"batl":[[0,2.9,11.57],[1,2.96,12.86],[2,3.2,22.9]],"ltp":2.96,"tv":373.68,"id":16573039},{"batb":[[0,4.8,15.58],[1,1.01,0.51]],"batl":[[0,5.5,14.24]],"ltp":5.2,"tv":51.1,"id":16573041}]}]}
{"op":"mcm","clk":"1010635747","pt":1580652387751,"mc":[{"id":"1.168222849","rc":[{"batb":[[1,4.7,10.92],[2,1.01,0.51]],"batl":[[0,5.5,23.4]],"ltp":5.4,"tv":3.29,"id":19613369},{"batb":[[1,3.55,15.96],[2,3.4,17.7]],"batl":[[0,4.1,26.98]],"ltp":3.55,"tv":5.0,"id":19613367},{"batb":[[0,2.76,23.53],[1,2.74,11.8],[2,2.56,13.85]],"batl":[[2,3.1,19.32]],"ltp":2.96,"tv":373.68,"id":16573039},{"batb":[[1,4.6,10.92],[2,1.01,0.51]],"batl":[[0,5.3,9.24],[1,5.5,14.24]],"ltp":5.2,"tv":51.1,"id":16573041}]}]}
{"op":"mcm","clk":"1010637391","pt":1580652395378,"mc":[{"id":"1.168222849","rc":[{"batb":[[0,4.9,24.79],[1,4.8,50.27],[2,4.7,10.92]],"ltp":5.4,"tv":3.29,"id":19613369},{"batb":[[1,3.6,31.55],[2,3.55,52.03]],"ltp":3.55,"tv":5.0,"id":19613367},{"trd":[[2.9,23.14]],"batb":[[0,2.92,36.43],[1,2.88,48.46],[2,2.76,23.53]],"batl":[[0,2.96,12.86],[1,3.1,19.32],[2,3.2,22.9]],"ltp":2.9,"tv":396.82,"id":16573039},{"batb":[[0,4.8,39.87],[1,4.7,37.06],[2,4.6,10.92]],"ltp":5.2,"tv":51.1,"id":16573041}],"tv":456.22}]}
{"op":"mcm","clk":"1010639649","pt":1580652404544,"mc":[{"id":"1.168222849","rc":[{"batb":[[2,1.01,0.51]],"batl":[[0,5.5,14.16]],"ltp":5.4,"tv":3.29,"id":19613369},{"batb":[[0,3.4,17.7],[1,1.01,0.51],[2,3.55,0]],"batl":[[0,4.5,21.95],[1,4.5,0]],"ltp":3.55,"tv":5.0,"id":19613367},{"batb":[[0,2.56,13.85],[1,1.01,0.51],[2,2.76,0]],"batl":[[1,3.2,22.9],[2,3.2,0]],"ltp":2.9,"tv":396.82,"id":16573039},{"batb":[[0,4.8,15.58],[2,1.01,0.51]],"batl":[[0,5.5,14.24],[1,5.5,0]],"ltp":5.2,"tv":51.1,"id":16573041}]}]}
{"op":"mcm","clk":"1010640487","pt":1580652407747,"mc":[{"id":"1.168222849","rc":[{"batb":[[2,4.7,15.34]],"batl":[[0,5.4,14.56],[1,5.5,14.16]],"ltp":5.4,"tv":3.29,"id":19613369},{"batb":[[1,3.35,18.18],[2,1.01,0.51]],"ltp":3.55,"tv":5.0,"id":19613367},{"batb":[[0,2.6,13.38],[1,2.56,13.85],[2,1.01,0.51]],"batl":[[2,3.25,22.11]],"ltp":2.9,"tv":396.82,"id":16573039},{"batb":[[1,4.7,37.08]],"ltp":5.2,"tv":51.1,"id":16573041}]}]}
{"op":"mcm","clk":"1010640578","pt":1580652408072,"mc":[{"id":"1.168222849","rc":[{"batb":[[1,4.8,35.32]],"batl":[[1,5.5,0]],"ltp":5.4,"tv":3.29,"id":19613369},{"batb":[[0,3.35,18.18],[1,1.01,0.51],[2,1.01,0]],"ltp":3.55,"tv":5.0,"id":19613367},{"batb":[[1,1.01,0.51],[2,1.01,0]],"batl":[[1,3.25,22.11],[2,3.25,0]],"ltp":2.9,"tv":396.82,"id":16573039}]}]}
{"op":"mcm","clk":"1010640961","pt":1580652409450,"mc":[{"id":"1.168222849","rc":[{"batb":[[0,3.5,54.57],[1,3.45,38.45],[2,3.35,18.18]],"ltp":3.55,"tv":5.0,"id":19613367},{"trd":[[2.96,134.04]],"batb":[[0,2.96,43.62],[1,2.92,46.71],[2,2.6,13.38]],"batl":[[0,3.25,22.11],[1,3.25,0]],"ltp":2.96,"tv":422.53,"id":16573039},{"batb":[[0,4.8,39.16]],"ltp":5.2,"tv":51.1,"id":16573041}],"tv":481.92}]}
{"op":"mcm","clk":"1010641981","pt":1580652413679,"mc":[{"id":"1.168222849","rc":[{"batb":[[0,3.35,18.18],[1,1.01,0.51],[2,3.35,0]],"ltp":3.55,"tv":5.0,"id":19613367},{"batb":[[0,2.6,13.38],[1,1.01,0.51],[2,2.6,0]],"ltp":2.96,"tv":422.53,"id":16573039},{"batb":[[0,4.8,15.58]],"ltp":5.2,"tv":51.1,"id":16573041}]}]}
{"op":"mcm","clk":"1010642568","pt":1580652416396,"mc":[{"id":"1.168222849","rc":[{"batb":[[1,3.25,52.65],[2,3.2,46.29]],"ltp":3.55,"tv":5.0,"id":19613367},{"batb":[[0,2.78,40.37],[1,2.74,55.11],[2,2.6,13.38]],"ltp":2.96,"tv":422.53,"id":16573039},{"batb":[[1,4.7,56.77],[2,4.6,38.41]],"ltp":5.2,"tv":51.1,"id":16573041}]}]}
{"op":"mcm","clk":"1010645717","pt":1580652430588,"mc":[{"id":"1.168222849","rc":[{"batb":[[1,1.01,0.51],[2,3.2,0]],"ltp":3.55,"tv":5.0,"id":19613367},{"batb":[[1,4.7,37.06],[2,1.01,0.51]],"ltp":5.2,"tv":51.1,"id":16573041}]}]}
{"op":"mcm","clk":"1010646421","pt":1580652433498,"mc":[{"id":"1.168222849","rc":[{"batb":[[0,3.8,56.73],[1,3.75,31.42],[2,3.35,18.18]],"ltp":3.55,"tv":5.0,"id":19613367},{"batb":[[0,4.8,45.07]],"ltp":5.2,"tv":51.1,"id":16573041}]}]}
{"op":"mcm","clk":"1010646657","pt":1580652434508,"mc":[{"id":"1.168222849","rc":[{"batb":[[1,4.8,50.58]],"batl":[[0,5.5,14.48]],"ltp":5.4,"tv":3.29,"id":19613369},{"batb":[[0,3.95,23.84],[1,3.8,30.72],[2,3.65,14.56]],"batl":[[1,4.8,19.2]],"ltp":3.55,"tv":5.0,"id":19613367},{"trd":[[2.78,26.28]],"batb":[[0,2.78,27.23]],"batl":[[0,2.96,10.94]],"ltp":2.78,"tv":448.8,"id":16573039},{"batb":[[0,4.8,44.68]],"ltp":5.2,"tv":51.1,"id":16573041}],"tv":508.2}]}
{"op":"mcm","clk":"1010646953","pt":1580652435741,"mc":[{"id":"1.168222849","rc":[{"batb":[[2,4.7,26.27]],"ltp":5.4,"tv":3.29,"id":19613369},{"batb":[[2,3.7,15.12]],"batl":[[0,4.3,12.6],[1,4.5,21.95],[2,4.8,19.2]],"ltp":3.55,"tv":5.0,"id":19613367},{"batb":[[2,2.68,24.37]],"batl":[[1,3,21]],"ltp":2.78,"tv":448.8,"id":16573039},{"batb":[[2,4.6,10.92]],"batl":[[0,5.4,9.24],[1,5.5,14.24]],"ltp":5.2,"tv":51.1,"id":16573041}]}]}
{"op":"mcm","clk":"1010647216","pt":1580652436615,"mc":[{"id":"1.168222849","rc":[{"batl":[[1,5.6,8.4]],"ltp":5.4,"tv":3.29,"id":19613369}]}]}
{"op":"mcm","clk":"1010647482","pt":1580652437513,"mc":[{"id":"1.168222849","rc":[{"batb":[[1,3.85,26.53],[2,3.8,30.72]],"ltp":3.55,"tv":5.0,"id":19613367}]}]}
{"op":"mcm","clk":"1010651262","pt":1580652453422,"mc":[{"id":"1.168222849","rc":[{"batb":[[1,4.8,35.32]],"ltp":5.4,"tv":3.29,"id":19613369},{"batb":[[0,3.7,15.12],[1,3.65,14.56],[2,1.01,0.51]],"batl":[[1,4.8,19.2],[2,4.8,0]],"ltp":3.55,"tv":5.0,"id":19613367},{"batb":[[0,2.68,24.37],[1,2.5,14.95],[2,1.01,0.51]],"ltp":2.78,"tv":448.8,"id":16573039}]}]}
{"op":"mcm","clk":"1010651587","pt":1580652454414,"mc":[{"id":"1.168222849","rc":[{"batb":[[2,4.7,15.34]],"batl":[[1,5.6,0]],"ltp":5.4,"tv":3.29,"id":19613369},{"batb":[[0,3.65,14.56],[1,1.01,0.51],[2,1.01,0]],"batl":[[0,4.8,19.2],[1,4.8,0]],"ltp":3.55,"tv":5.0,"id":19613367},{"batb":[[0,2.5,14.95],[1,1.01,0.51],[2,1.01,0]],"batl":[[1,3,0]],"ltp":2.78,"tv":448.8,"id":16573039},{"batb":[[2,1.01,0.51]],"batl":[[0,5.5,14.24],[1,5.5,0]],"ltp":5.2,"tv":51.1,"id":16573041}]}]}
{"op":"mcm","clk":"1010652095","pt":1580652456555,"mc":[{"id":"1.168222849","rc":[{"batl":[[0,5.4,14.71]],"ltp":5.4,"tv":3.29,"id":19613369},{"batb":[[0,3.6,14.71]],"ltp":3.55,"tv":5.0,"id":19613367},{"batb":[[0,2.52,14.63]],"batl":[[0,3,10.7]],"ltp":2.78,"tv":448.8,"id":16573039}]}]}
{"op":"mcm","clk":"1010652696","pt":1580652459323,"mc":[{"id":"1.168222849","rc":[{"batb":[[0,3.75,52.84],[1,3.7,32.49],[2,3.6,14.71]],"ltp":3.55,"tv":5.0,"id":19613367},{"batb":[[0,2.8,54.92],[1,2.76,53.97],[2,2.52,14.63]],"ltp":2.78,"tv":448.8,"id":16573039}]}]}
{"op":"mcm","clk":"1010653845","pt":1580652464716,"mc":[{"id":"1.168222849","rc":[{"batb":[[0,3.6,14.71],[1,1.01,0.51],[2,3.6,0]],"ltp":3.55,"tv":5.0,"id":19613367},{"batb":[[0,2.52,14.63],[1,1.01,0.51],[2,2.52,0]],"ltp":2.78,"tv":448.8,"id":16573039}]}]}
{"op":"mcm","clk":"1010654386","pt":1580652467333,"mc":[{"id":"1.168222849","rc":[{"batb":[[1,3.55,42.29],[2,3.5,37.25]],"ltp":3.55,"tv":5.0,"id":19613367},{"batb":[[0,2.68,45.1],[1,2.64,60.69],[2,2.52,14.63]],"ltp":2.78,"tv":448.8,"id":16573039}]}]}
{"op":"mcm","clk":"1010655208","pt":1580652470757,"mc":[{"id":"1.168222849","rc":[{"batb":[[0,2.52,14.63],[1,1.01,0.51],[2,2.52,0]],"ltp":2.78,"tv":448.8,"id":16573039}]}]}
{"op":"mcm","clk":"1010655843","pt":1580652473477,"mc":[{"id":"1.168222849","rc":[{"batb":[[2,4.7,26.27]],"batl":[[1,5.5,9.24]],"ltp":5.4,"tv":3.29,"id":19613369},{"batb":[[2,3.5,54.05]],"batl":[[0,4,13.44],[1,4.8,19.2]],"ltp":3.55,"tv":5.0,"id":19613367},{"batb":[[0,2.94,52.45],[1,2.9,47.53],[2,2.8,22.69]],"batl":[[1,3.15,19.32]],"ltp":2.78,"tv":448.8,"id":16573039},{"batb":[[2,4.6,10.92]],"batl":[[0,5.4,9.24],[1,5.5,14.24]],"ltp":5.2,"tv":51.1,"id":16573041}]}]}
{"op":"mcm","clk":"1010656099","pt":1580652474572,"mc":[{"id":"1.168222849","rc":[{"batl":[[0,4,27.76],[1,4.5,22.58]],"ltp":3.55,"tv":5.0,"id":19613367},{"batb":[[2,2.82,10.94]],"batl":[[2,3.4,20.38]],"ltp":2.78,"tv":448.8,"id":16573039},{"batb":[[1,4.7,52.88]],"ltp":5.2,"tv":51.1,"id":16573041}]}]}
{"op":"mcm","clk":"1010660227","pt":1580652490511,"mc":[{"id":"1.168222849","rc":[{"batb":[[0,4.8,35.32],[1,4.7,15.34],[2,1.01,0.51]],"batl":[[1,5.5,0]],"ltp":5.4,"tv":3.29,"id":19613369},{"batb":[[0,3.2,19.59],[1,1.01,0.51],[2,3.5,0]],"batl":[[0,4.5,22.58],[1,4.5,0]],"ltp":3.55,"tv":5.0,"id":19613367},{"batb":[[0,2.62,13.06],[1,1.01,0.51],[2,2.82,0]],"batl":[[0,3.4,20.38],[1,3.15,0],[2,3.4,0]],"ltp":2.78,"tv":448.8,"id":16573039},{"batb":[[0,4.7,52.88],[1,1.01,0.51],[2,4.6,0]],"batl":[[0,5.5,14.24],[1,5.5,0]],"ltp":5.2,"tv":51.1,"id":16573041}]}]}
{"op":"mcm","clk":"1010660899","pt":1580652493070,"mc":[{"id":"1.168222849","rc":[{"batb":[[0,4.8,54.77],[1,4.7,51.94]],"ltp":5.4,"tv":3.29,"id":19613369},{"batb":[[1,3.15,78.15],[2,3.1,49.88]],"ltp":3.55,"tv":5.0,"id":19613367},{"batb":[[0,2.78,44.38],[1,2.74,55.07],[2,2.62,13.06]],"ltp":2.78,"tv":448.8,"id":16573039},{"batb":[[0,4.7,72.57],[1,4.6,38.43],[2,1.01,0.51]],"ltp":5.2,"tv":51.1,"id":16573041}]}]}
{"op":"mcm","clk":"1010664412","pt":1580652507621,"mc":[{"id":"1.168222849","rc":[{"batb":[[1,1.01,0.51],[2,3.1,0]],"ltp":3.55,"tv":5.0,"id":19613367},{"batb":[[0,4.7,52.88],[1,1.01,0.51],[2,1.01,0]],"ltp":5.2,"tv":51.1,"id":16573041}]}]}
{"op":"mcm","clk":"1010665059","pt":1580652510539,"mc":[{"id":"1.168222849","rc":[{"batb":[[0,3.8,56.29],[1,3.75,31.43],[2,3.2,19.59]],"ltp":3.55,"tv":5.0,"id":19613367},{"batb":[[0,4.8,33.38],[1,4.7,52.88],[2,1.01,0.51]],"ltp":5.2,"tv":51.1,"id":16573041}]}]}
{"op":"mcm","clk":"1010665286","pt":1580652511482,"mc":[{"id":"1.168222849","rc":[{"batb":[[1,4.7,47.52],[2,4.6,15.97]],"batl":[[1,5.5,9.24]],"ltp":5.4,"tv":3.29,"id":19613369},{"batb":[[0,3.95,23.92],[1,3.8,56.29],[2,3.75,31.43]],"batl":[[0,4.3,12.6],[1,4.5,22.58],[2,4.8,19.28]],"ltp":3.55,"tv":5.0,"id":19613367},{"batb":[[2,2.68,24.37]],"batl":[[0,2.8,12.83],[1,3,10.7],[2,3.05,20.16]],"ltp":2.78,"tv":448.8,"id":16573039},{"batb":[[0,4.8,48.72],[1,4.7,37.06],[2,4.6,10.92]],"batl":[[0,5.4,9.24],[1,5.5,14.24]],"ltp":5.2,"tv":51.1,"id":16573041}]}]}
{"op":"mcm","clk":"1010670622","pt":1580652532745,"mc":[{"id":"1.168222849","rc":[{"batb":[[1,4.7,36.6]],"batl":[[1,5.5,0]],"ltp":5.4,"tv":3.29,"id":19613369},{"batb":[[0,3.65,14.48],[1,1.01,0.51],[2,3.75,0]],"batl":[[0,4.8,19.28],[1,4.5,0],[2,4.8,0]],"ltp":3.55,"tv":5.0,"id":19613367},{"batb":[[0,2.5,14.79],[1,1.01,0.51],[2,2.68,0]],"batl":[[0,3,10.7],[1,3,0],[2,3.05,0]],"ltp":2.78,"tv":448.8,"id":16573039},{"batb":[[2,1.01,0.51]],"batl":[[0,5.5,14.24],[1,5.5,0]],"ltp":5.2,"tv":51.1,"id":16573041}]}]}
{"op":"mcm","clk":"1010671352","pt":1580652535663,"mc":[{"id":"1.168222849","rc":[{"batb":[[1,3.6,14.79],[2,3.55,48.23]],"ltp":3.55,"tv":5.0,"id":19613367},{"batb":[[0,2.68,56.34],[1,2.64,60.61],[2,2.52,14.56]],"batl":[[1,3.05,10.46]],"ltp":2.78,"tv":448.8,"id":16573039}]}]}
{"op":"mcm","clk":"1010671393","pt":1580652535887,"mc":[{"id":"1.168222849","rc":[{"batb":[[0,3.6,14.79],[1,3.55,48.23],[2,3.5,37.2]],"ltp":3.55,"tv":5.0,"id":19613367},{"batl":[[0,3.05,10.46],[1,3.05,0]],"ltp":2.78,"tv":448.8,"id":16573039}]}]}
{"op":"mcm","clk":"1010672091","pt":1580652539083,"mc":[{"id":"1.168222849","rc":[{"batb":[[0,4.8,35.39],[1,4.6,15.97],[2,1.01,0.51]],"ltp":5.4,"tv":3.29,"id":19613369},{"batb":[[1,1.01,0.51],[2,3.5,0]],"ltp":3.55,"tv":5.0,"id":19613367}]}]}
{"op":"mcm","clk":"1010672959","pt":1580652542690,"mc":[{"id":"1.168222849","rc":[{"batb":[[0,4.9,22.14],[1,4.8,35.39],[2,4.7,15.66]],"ltp":5.4,"tv":3.29,"id":19613369},{"batb":[[0,4.2,20.77],[1,4,44.8],[2,3.95,27.87]],"batl":[[1,5.5,14.63]],"ltp":3.55,"tv":5.0,"id":19613367},{"trd":[[2.68,28.48]],"batb":[[0,2.68,42.1]],"batl":[[0,2.88,11.88],[1,3.05,10.46]],"ltp":2.68,"tv":477.29,"id":16573039},{"batb":[[0,4.9,14.79],[1,4.8,48.72],[2,4.7,37.06]],"batl":[[1,5.6,13.61]],"ltp":5.2,"tv":51.1,"id":16573041}],"tv":536.68}]}
{"op":"mcm","clk":"1010673128","pt":1580652543456,"mc":[{"id":"1.168222849","rc":[{"batb":[[1,4.8,46.31]],"batl":[[1,5.6,8.4]],"ltp":5.4,"tv":3.29,"id":19613369},{"batl":[[0,4.5,11.76],[1,4.8,19.28],[2,5.5,14.63]],"ltp":3.55,"tv":5.0,"id":19613367},{"batb":[[2,2.58,26.05]],"batl":[[0,2.88,33.73],[1,3.05,0]],"ltp":2.68,"tv":477.29,"id":16573039},{"batb":[[1,4.8,48.57]],"batl":[[0,5.4,9.24]],"ltp":5.2,"tv":51.1,"id":16573041}]}]}
{"op":"mcm","clk":"1010674888","pt":1580652551051,"mc":[{"id":"1.168222849","rc":[{"batb":[[0,4.1,21.01]],"batl":[[1,4.7,19.91],[2,5.4,14.79]],"ltp":3.55,"tv":5.0,"id":19613367},{"batl":[[0,2.72,14.01],[1,2.88,21.85],[2,2.92,11.64]],"ltp":2.68,"tv":477.29,"id":16573039}]}]}
{"op":"mcm","clk":"1010681174","pt":1580652579201,"mc":[{"id":"1.168222849","rc":[{"batb":[[0,4.8,46.31],[1,4.7,15.66],[2,1.01,0.51]],"ltp":5.4,"tv":3.29,"id":19613369},{"batb":[[1,3.9,14.28],[2,3.8,13.14]],"ltp":3.55,"tv":5.0,"id":19613367},{"batb":[[0,2.58,26.05],[1,2.56,14.24],[2,2.36,17.7]],"ltp":2.68,"tv":477.29,"id":16573039},{"batb":[[1,4.8,38.79]],"ltp":5.2,"tv":51.1,"id":16573041}]}]}
{"op":"mcm","clk":"1010682083","pt":1580652583110,"mc":[{"id":"1.168222849","rc":[{"batb":[[0,4.8,66.52],[1,4.7,52.26]],"ltp":5.4,"tv":3.29,"id":19613369},{"batb":[[2,2.46,44.24]],"ltp":2.68,"tv":477.29,"id":16573039}]}]}
{"op":"mcm","clk":"1010685737","pt":1580652599228,"mc":[{"id":"1.168222849","rc":[{"batb":[[0,3.9,14.28],[1,3.8,13.14],[2,3.7,43.43]],"batl":[[1,5.4,14.79],[2,5.4,0]],"ltp":3.55,"tv":5.0,"id":19613367},{"batb":[[1,2.46,44.24],[2,2.42,76.6]],"batl":[[0,2.88,21.85],[1,2.92,11.64],[2,2.92,0]],"ltp":2.68,"tv":477.29,"id":16573039},{"batb":[[0,4.8,38.79],[1,4.7,37.06],[2,4.6,10.92]],"ltp":5.2,"tv":51.1,"id":16573041}]}]}
{"op":"mcm","clk":"1010686043","pt":1580652600644,"mc":[{"id":"1.168222849","rc":[{"batb":[[0,4.8,55.6]],"batl":[[1,5.6,0]],"ltp":5.4,"tv":3.29,"id":19613369},{"batb":[[0,3.8,13.14],[1,3.7,43.43],[2,3.65,33.67]],"batl":[[0,5.4,14.79],[1,5.4,0]],"ltp":3.55,"tv":5.0,"id":19613367},{"batb":[[0,2.46,44.24],[1,2.42,76.6],[2,2.36,17.7]],"batl":[[0,2.92,11.64],[1,2.92,0]],"ltp":2.68,"tv":477.29,"id":16573039},{"batb":[[2,1.01,0.51]],"batl":[[0,5.6,13.61],[1,5.6,0]],"ltp":5.2,"tv":51.1,"id":16573041}]}]}
{"op":"mcm","clk":"1010686533","pt":1580652602621,"mc":[{"id":"1.168222849","rc":[{"batb":[[1,4.7,36.6],[2,4.6,16.21]],"batl":[[0,5.3,15.34]],"ltp":5.4,"tv":3.29,"id":19613369},{"batb":[[0,3.75,13.61]],"batl":[[0,5.3,15.42]],"ltp":3.55,"tv":5.0,"id":19613367},{"batb":[[0,2.38,17.23],[1,1.01,0.51],[2,2.36,0]],"batl":[[0,2.96,11.25]],"ltp":2.68,"tv":477.29,"id":16573039},{"batb":[[0,4.8,23.6]],"batl":[[0,5.7,13.61]],"ltp":5.2,"tv":51.1,"id":16573041}]}]}
{"op":"mcm","clk":"1010687179","pt":1580652605573,"mc":[{"id":"1.168222849","rc":[{"batb":[[0,4.8,66.52]],"batl":[[1,5.5,9.24]],"ltp":5.4,"tv":3.29,"id":19613369},{"batb":[[1,3.7,58.55]],"batl":[[0,4.2,12.6],[1,5.3,15.42]],"ltp":3.55,"tv":5.0,"id":19613367},{"batb":[[0,2.86,38.95],[1,2.82,51.14],[2,2.7,24.37]],"batl":[[1,3.05,20.16]],"ltp":2.68,"tv":477.29,"id":16573039},{"batb":[[2,4.6,10.92]],"batl":[[0,5.3,9.24],[1,5.7,13.61]],"ltp":5.2,"tv":51.1,"id":16573041}]}]}
{"op":"mcm","clk":"1010687369","pt":1580652606342,"mc":[{"id":"1.168222849","rc":[{"batl":[[0,4.2,25.82],[1,4.7,19.99]],"ltp":3.55,"tv":5.0,"id":19613367},{"batb":[[2,2.78,11.49]],"batl":[[2,3.2,23.45]],"ltp":2.68,"tv":477.29,"id":16573039},{"batb":[[0,4.8,39.02]],"batl":[[1,5.5,14.4],[2,5.6,14.08]],"ltp":5.2,"tv":51.1,"id":16573041}]}]}
{"op":"mcm","clk":"1010690472","pt":1580652619752,"mc":[{"id":"1.168222849","rc":[{"batb":[[0,3.7,15.12],[1,3.45,16.37],[2,1.01,0.51]],"batl":[[0,4.2,12.6]],"ltp":3.55,"tv":5.0,"id":19613367},{"batb":[[0,2.7,24.37],[1,2.56,14.24],[2,1.01,0.51]],"batl":[[0,3.05,20.16],[1,3.2,23.45],[2,3.2,0]],"ltp":2.68,"tv":477.29,"id":16573039},{"batb":[[0,4.8,15.42]],"batl":[[1,5.6,14.08],[2,5.6,0]],"ltp":5.2,"tv":51.1,"id":16573041}]}]}
{"op":"mcm","clk":"1010690639","pt":1580652620574,"mc":[{"id":"1.168222849","rc":[{"batb":[[0,4.8,55.6]],"batl":[[1,5.5,0]],"ltp":5.4,"tv":3.29,"id":19613369},{"batb":[[0,3.45,16.37],[1,1.01,0.51],[2,1.01,0]],"batl":[[0,4.7,19.99],[1,4.7,0]],"ltp":3.55,"tv":5.0,"id":19613367},{"batb":[[0,2.56,14.24],[1,1.01,0.51],[2,1.01,0]],"batl":[[0,3.2,23.45],[1,3.2,0]],"ltp":2.68,"tv":477.29,"id":16573039},{"batb":[[2,1.01,0.51]],"batl":[[0,5.6,14.08],[1,5.6,0]],"ltp":5.2,"tv":51.1,"id":16573041}]}]}
{"op":"mcm","clk":"1010691134","pt":1580652622679,"mc":[{"id":"1.168222849","rc":[{"batb":[[0,3.45,82.92],[1,3.4,39.77],[2,1.01,0.51]],"ltp":3.55,"tv":5.0,"id":19613367},{"batb":[[0,2.64,38.45],[1,2.6,63.21],[2,2.56,14.24]],"ltp":2.68,"tv":477.29,"id":16573039},{"batb":[[1,4.7,53.59],[2,4.6,38.49]],"ltp":5.2,"tv":51.1,"id":16573041}]}]}
{"op":"mcm","clk":"1010691284","pt":1580652623447,"mc":[{"id":"1.168222849","rc":[{"batb":[[0,3.5,16.13],[1,1.01,0.51],[2,1.01,0]],"batl":[[0,4.7,19.75]],"ltp":3.55,"tv":5.0,"id":19613367},{"batb":[[0,2.56,14.24],[1,1.01,0.51],[2,2.56,0]],"ltp":2.68,"tv":477.29,"id":16573039},{"batb":[[1,4.7,37.11],[2,1.01,0.51]],"ltp":5.2,"tv":51.1,"id":16573041}]}]}
{"op":"mcm","clk":"1010691912","pt":1580652626273,"mc":[{"id":"1.168222849","rc":[{"batb":[[1,3.45,66.55],[2,3.4,39.77]],"ltp":3.55,"tv":5.0,"id":19613367},{"batb":[[0,3,60.1],[1,2.96,45.04],[2,2.56,14.24]],"ltp":2.68,"tv":477.29,"id":16573039},{"batb":[[1,4.7,53.59],[2,4.6,38.49]],"ltp":5.2,"tv":51.1,"id":16573041}]}]}
{"op":"mcm","clk":"1010692179","pt":1580652627466,"mc":[{"id":"1.168222849","rc":[{"batb":[[1,4.7,47.52]],"batl":[[1,5.5,9.24]],"ltp":5.4,"tv":3.29,"id":19613369},{"batb":[[0,3.55,15.96],[1,3.5,16.13],[2,3.45,66.55]],"batl":[[0,3.85,15.66],[1,4,13.44],[2,4.2,12.9]],"ltp":3.55,"tv":5.0,"id":19613367},{"batb":[[2,2.94,24.55]],"batl":[[0,3.15,19.32],[1,3.2,23.45],[2,3.4,20.61]],"ltp":2.68,"tv":477.29,"id":16573039},{"batb":[[2,4.6,49.41]],"batl":[[0,5.3,9.24],[1,5.5,14.56]],"ltp":5.2,"tv":51.1,"id":16573041}]}]}
{"op":"mcm","clk":"1010694317","pt":1580652636697,"mc":[{"id":"1.168222849","rc":[{"batb":[[0,4.8,47.12],[1,4.7,36.6]],"batl":[[1,5.5,0]],"ltp":5.4,"tv":3.29,"id":19613369},{"batb":[[0,3.25,18.73],[1,1.01,0.51],[2,3.45,0]],"batl":[[0,4.2,12.9],[1,4,0],[2,4.2,0]],"ltp":3.55,"tv":5.0,"id":19613367},{"batb":[[0,2.76,11.64],[1,1.01,0.51],[2,2.94,0]],"batl":[[0,3.4,20.61],[1,3.2,0],[2,3.4,0]],"ltp":2.68,"tv":477.29,"id":16573039},{"batb":[[2,4.6,38.49]],"batl":[[0,5.5,14.56],[1,5.5,0]],"ltp":5.2,"tv":51.1,"id":16573041}]}]}
{"op":"mcm","clk":"1010694944","pt":1580652639717,"mc":[{"id":"1.168222849","rc":[{"batb":[[0,3.3,18.65]],"ltp":3.55,"tv":5.0,"id":19613367}]}]}
{"op":"mcm","clk":"1010695381","pt":1580652641584,"mc":[{"id":"1.168222849","rc":[{"batb":[[0,3.5,65.3],[1,3.45,38.38],[2,3.3,18.65]],"ltp":3.55,"tv":5.0,"id":19613367},{"batb":[[0,2.98,39.13],[1,2.94,45.98],[2,2.76,11.64]],"ltp":2.68,"tv":477.29,"id":16573039}]}]}
{"op":"mcm","clk":"1010696663","pt":1580652647448,"mc":[{"id":"1.168222849","rc":[{"batb":[[0,3.3,18.65],[1,1.01,0.51],[2,3.3,0]],"ltp":3.55,"tv":5.0,"id":19613367},{"batb":[[0,2.76,11.64],[1,1.01,0.51],[2,2.76,0]],"ltp":2.68,"tv":477.29,"id":16573039}]}]}
{"op":"mcm","clk":"1010697279","pt":1580652650295,"mc":[{"id":"1.168222849","rc":[{"batb":[[0,3.3,92.16],[1,3.25,44.38],[2,1.01,0.51]],"ltp":3.55,"tv":5.0,"id":19613367},{"batb":[[0,2.82,57.46],[1,2.78,52.93],[2,2.76,11.64]],"ltp":2.68,"tv":477.29,"id":16573039}]}]}
{"op":"mcm","clk":"1010697688","pt":1580652651908,"mc":[{"id":"1.168222849","rc":[{"batb":[[0,4.8,35.39],[1,4.6,16.21],[2,1.01,0.51]],"ltp":5.4,"tv":3.29,"id":19613369},{"batb":[[0,3.3,18.65],[1,1.01,0.51],[2,1.01,0]],"ltp":3.55,"tv":5.0,"id":19613367}]}]}
{"op":"mcm","clk":"1010698508","pt":1580652655604,"mc":[{"id":"1.168222849","rc":[{"batb":[[0,4.9,24.29],[1,4.8,46.31],[2,4.6,16.21]],"batl":[[1,5.6,8.4]],"ltp":5.4,"tv":3.29,"id":19613369},{"batb":[[0,3.8,13.22],[1,3.75,52.71],[2,3.7,32.64]],"batl":[[1,4.3,12.6],[2,4.9,18.65]],"ltp":3.55,"tv":5.0,"id":19613367},{"batl":[[0,2.94,11.49],[1,3,21],[2,3.2,23.6]],"ltp":2.68,"tv":477.29,"id":16573039},{"batl":[[0,5.3,9.24],[1,5.5,14.56]],"ltp":5.2,"tv":51.1,"id":16573041}]}]}
{"op":"mcm","clk":"1010698552","pt":1580652655813,"mc":[{"id":"1.168222849","rc":[{"batb":[[2,4.6,16.05]],"ltp":5.4,"tv":3.29,"id":19613369},{"batl":[[1,5.5,14.24]],"ltp":5.2,"tv":51.1,"id":16573041}]}]}
{"op":"mcm","clk":"1010701593","pt":1580652669749,"mc":[{"id":"1.168222849","rc":[{"batb":[[0,3.75,15.12],[1,3.45,16.21],[2,1.01,0.51]],"batl":[[0,4.3,12.6],[1,4.9,18.65],[2,4.9,0]],"ltp":3.55,"tv":5.0,"id":19613367},{"batb":[[0,2.7,24.37],[1,2.52,14.95],[2,1.01,0.51]],"batl":[[0,3,21],[1,3.2,23.6],[2,3.2,0]],"ltp":2.68,"tv":477.29,"id":16573039}]}]}
{"op":"mcm","clk":"1010701800","pt":1580652670754,"mc":[{"id":"1.168222849","rc":[{"batb":[[1,4.8,35.39]],"batl":[[1,5.6,0]],"ltp":5.4,"tv":3.29,"id":19613369},{"batb":[[0,3.45,16.21],[1,1.01,0.51],[2,1.01,0]],"batl":[[0,4.9,18.65],[1,4.9,0]],"ltp":3.55,"tv":5.0,"id":19613367},{"batb":[[0,2.52,14.95],[1,1.01,0.51],[2,1.01,0]],"batl":[[0,3.2,23.6],[1,3.2,0]],"ltp":2.68,"tv":477.29,"id":16573039},{"batl":[[0,5.5,14.24],[1,5.5,0]],"ltp":5.2,"tv":51.1,"id":16573041}]}]}
{"op":"mcm","clk":"1010702174","pt":1580652672362,"mc":[{"id":"1.168222849","rc":[{"batb":[[0,3.5,29.67],[1,3.45,54.91],[2,1.01,0.51]],"ltp":3.55,"tv":5.0,"id":19613367},{"batb":[[0,2.58,54.19],[1,2.54,67.16],[2,2.52,14.95]],"ltp":2.68,"tv":477.29,"id":16573039}]}]}
{"op":"mcm","clk":"1010702475","pt":1580652673755,"mc":[{"id":"1.168222849","rc":[{"batb":[[1,4.8,35.32]],"ltp":5.4,"tv":3.29,"id":19613369},{"batb":[[0,3.45,16.21],[1,1.01,0.51],[2,1.01,0]],"ltp":3.55,"tv":5.0,"id":19613367},{"batb":[[1,4.7,37.06],[2,1.01,0.51]],"ltp":5.2,"tv":51.1,"id":16573041}]}]}
{"op":"mcm","clk":"1010703184","pt":1580652676659,"mc":[{"id":"1.168222849","rc":[{"batb":[[0,4.2,60.5],[1,4.1,50.17],[2,3.45,16.21]],"ltp":3.55,"tv":5.0,"id":19613367},{"batb":[[0,4.8,52.4]],"ltp":5.2,"tv":51.1,"id":16573041}]}]}
{"op":"mcm","clk":"1010703386","pt":1580652677563,"mc":[{"id":"1.168222849","rc":[{"batb":[[0,4.9,34.37],[2,4.7,15.97]],"batl":[[0,5.4,15.11],[1,5.7,8.4]],"ltp":5.4,"tv":3.29,"id":19613369},{"batb":[[0,4.3,19.59],[1,4.2,73.1],[2,4.1,50.17]],"batl":[[0,4.9,28.73],[1,6.2,11.57]],"ltp":3.55,"tv":5.0,"id":19613367},{"batl":[[0,2.66,14.63],[1,2.78,23.53],[2,2.96,11.25]],"ltp":2.68,"tv":477.29,"id":16573039},{"batb":[[0,4.9,14.87],[1,4.8,52.4],[2,4.7,37.06]],"batl":[[0,5.3,9.24],[1,5.7,13.53]],"ltp":5.2,"tv":51.1,"id":16573041}]}]}
{"op":"mcm","clk":"1010707644","pt":1580652697262,"mc":[{"id":"1.168222849","rc":[{"batb":[[2,4.6,16.05]],"ltp":5.4,"tv":3.29,"id":19613369},{"batb":[[0,4.2,12.6],[1,3.75,13.38],[2,1.01,0.51]],"batl":[[0,4.9,10.08]],"ltp":3.55,"tv":5.0,"id":19613367},{"batb":[[0,2.5,27.73],[1,2.24,20.22],[2,1.01,0.51]],"batl":[[0,2.78,23.53],[1,2.96,11.25],[2,2.96,0]],"ltp":2.68,"tv":477.29,"id":16573039},{"batb":[[0,4.8,15.42],[1,4.7,37.06],[2,4.5,11.76]],"ltp":5.2,"tv":51.1,"id":16573041}]}]}
{"op":"mcm","clk":"1010707937","pt":1580652698650,"mc":[{"id":"1.168222849","rc":[{"batb":[[0,4.9,24.29]],"batl":[[1,5.7,0]],"ltp":5.4,"tv":3.29,"id":19613369},{"batb":[[0,3.75,13.38],[1,1.01,0.51],[2,1.01,0]],"batl":[[0,6.2,11.57],[1,6.2,0]],"ltp":3.55,"tv":5.0,"id":19613367},{"batb":[[0,2.24,20.22],[1,1.01,0.51],[2,1.01,0]],"batl":[[0,2.96,11.25],[1,2.96,0]],"ltp":2.68,"tv":477.29,"id":16573039},{"batb":[[2,1.01,0.51]],"batl":[[0,5.7,13.53],[1,5.7,0]],"ltp":5.2,"tv":51.1,"id":16573041}]}]}
{"op":"mcm","clk":"1010708341","pt":1580652700420,"mc":[{"id":"1.168222849","rc":[{"batb":[[0,3.75,42.09],[1,3.7,32.72],[2,1.01,0.51]],"ltp":3.55,"tv":5.0,"id":19613367},{"batb":[[1,4.7,53.39],[2,4.6,38.49]],"ltp":5.2,"tv":51.1,"id":16573041}]}]}
{"op":"mcm","clk":"1010709051","pt":1580652703703,"mc":[{"id":"1.168222849","rc":[{"batb":[[0,4.9,34.37]],"batl":[[1,5.6,8.4]],"ltp":5.4,"tv":3.29,"id":19613369},{"batb":[[0,3.75,57.21]],"batl":[[0,4.4,11.76],[1,6.2,11.57]],"ltp":3.55,"tv":5.0,"id":19613367},{"batb":[[0,2.84,40.5],[1,2.8,52.08],[2,2.64,25.21]],"batl":[[0,2.96,32.26]],"ltp":2.68,"tv":477.29,"id":16573039},{"batl":[[0,5.2,9.24],[1,5.7,13.53]],"ltp":5.2,"tv":51.1,"id":16573041}]}]}
{"op":"mcm","clk":"1010709259","pt":1580652704572,"mc":[{"id":"1.168222849","rc":[{"batl":[[0,5.3,15.26]],"ltp":5.4,"tv":3.29,"id":19613369},{"batb":[[2,3.4,17]],"batl":[[0,4.2,12.98],[1,4.4,11.76],[2,4.9,18.33]],"ltp":3.55,"tv":5.0,"id":19613367},{"batb":[[2,2.78,11.49]],"batl":[[1,3.25,22.66]],"ltp":2.68,"tv":477.29,"id":16573039},{"batl":[[1,5.5,14.79],[2,5.6,14.16]],"ltp":5.2,"tv":51.1,"id":16573041}]}]}
{"op":"mcm","clk":"1010711918","pt":1580652716304,"mc":[{"id":"1.168222849","rc":[{"batb":[[0,4.9,24.29]],"ltp":5.4,"tv":3.29,"id":19613369},{"batl":[[1,4.9,18.33],[2,4.9,0]],"ltp":3.55,"tv":5.0,"id":19613367},{"batl":[[0,2.96,11.25]],"ltp":2.68,"tv":477.29,"id":16573039}]}]}
{"op":"mcm","clk":"1010712536","pt":1580652719207,"mc":[{"id":"1.168222849","rc":[{"batb":[[1,4.8,46.24]],"ltp":5.4,"tv":3.29,"id":19613369},{"batl":[[1,4.3,12.6],[2,4.9,18.33]],"ltp":3.55,"tv":5.0,"id":19613367},{"batl":[[1,2.98,21],[2,3.25,22.66]],"ltp":2.68,"tv":477.29,"id":16573039}]}]}
{"op":"mcm","clk":"1010712814","pt":1580652720612,"mc":[{"id":"1.168222849","rc":[{"batb":[[1,4.8,35.32]],"batl":[[1,5.6,0]],"ltp":5.4,"tv":3.29,"id":19613369},{"batb":[[0,3.4,17],[1,1.01,0.51],[2,3.4,0]],"batl":[[0,4.9,18.33],[1,4.3,0],[2,4.9,0]],"ltp":3.55,"tv":5.0,"id":19613367},{"batb":[[0,2.5,15.11],[1,1.01,0.51],[2,2.78,0]],"batl":[[0,3.25,22.66],[1,2.98,0],[2,3.25,0]],"ltp":2.68,"tv":477.29,"id":16573039},{"batb":[[1,4.7,39.52]],"batl":[[0,5.6,14.16],[1,5.5,0],[2,5.6,0]],"ltp":5.2,"tv":51.1,"id":16573041}]}]}
{"op":"mcm","clk":"1010713354","pt":1580652723141,"mc":[{"id":"1.168222849","rc":[{"batb":[[0,3.45,35.55],[1,3.4,57.05],[2,1.01,0.51]],"ltp":3.55,"tv":5.0,"id":19613367},{"batb":[[0,2.56,48.76],[1,2.52,68.63],[2,2.5,15.11]],"ltp":2.68,"tv":477.29,"id":16573039}]}]}
{"op":"mcm","clk":"1010714149","pt":1580652726650,"mc":[{"id":"1.168222849","rc":[{"batb":[[0,2.5,15.11],[1,1.01,0.51],[2,2.5,0]],"ltp":2.68,"tv":477.29,"id":16573039}]}]}
{"op":"mcm","clk":"1010714787","pt":1580652729671,"mc":[{"id":"1.168222849","rc":[{"batb":[[0,3.05,40.9],[1,3,54.41],[2,2.5,15.11]],"ltp":2.68,"tv":477.29,"id":16573039}]}]}
{"op":"mcm","clk":"1010714983","pt":1580652730565,"mc":[{"id":"1.168222849","rc":[{"batb":[[2,3.05,22.5]],"batl":[[0,3.75,16.44],[1,4.2,13.22]],"ltp":3.55,"tv":5.0,"id":19613367},{"batb":[[2,2.98,23.6]],"batl":[[1,3.7,16.92]],"ltp":2.68,"tv":477.29,"id":16573039},{"batb":[[0,4.7,55.81],[1,4.6,38.49],[2,1.01,0.51]],"batl":[[0,5.4,14.95]],"ltp":5.2,"tv":51.1,"id":16573041}]}]}
{"op":"mcm","clk":"1010715200","pt":1580652731531,"mc":[{"id":"1.168222849","rc":[{"batb":[[2,4.7,10.92]],"batl":[[1,5.5,9.24]],"ltp":5.4,"tv":3.29,"id":19613369},{"batb":[[0,3.45,52.35]],"batl":[[1,4,13.44],[2,4.2,13.22]],"ltp":3.55,"tv":5.0,"id":19613367},{"batl":[[0,3.25,41.14]],"ltp":2.68,"tv":477.29,"id":16573039},{"batb":[[2,4.5,11.76]],"batl":[[0,5.3,9.24],[1,5.4,14.95]],"ltp":5.2,"tv":51.1,"id":16573041}]}]}
{"op":"mcm","clk":"1010717430","pt":1580652741275,"mc":[{"id":"1.168222849","rc":[{"batb":[[0,3,54.41],[1,2.98,23.6],[2,2.84,22.69]],"ltp":2.68,"tv":477.29,"id":16573039},{"batb":[[0,4.7,53.35]],"ltp":5.2,"tv":51.1,"id":16573041}]}]}
{"op":"mcm","clk":"1010718132","pt":1580652744272,"mc":[{"id":"1.168222849","rc":[{"batb":[[0,4.9,34.71]],"ltp":5.4,"tv":3.29,"id":19613369},{"batb":[[0,3.45,63.61]],"ltp":3.55,"tv":5.0,"id":19613367},{"batb":[[0,3,83.59],[2,2.96,44.78]],"ltp":2.68,"tv":477.29,"id":16573039}]}]}
{"op":"mcm","clk":"1010721902","pt":1580652761541,"mc":[{"id":"1.168222849","rc":[{"batb":[[0,3.45,16.8],[1,3.05,22.5],[2,1.01,0.51]],"batl":[[0,4,13.44],[1,4.2,13.22],[2,4.2,0]],"ltp":3.55,"tv":5.0,"id":19613367},{"batb":[[0,2.84,22.69],[1,2.8,11.25],[2,1.01,0.51]],"batl":[[0,3.25,18.48]],"ltp":2.68,"tv":477.29,"id":16573039},{"batb":[[0,4.7,16.29]],"ltp":5.2,"tv":51.1,"id":16573041}]}]}
{"op":"mcm","clk":"1010722166","pt":1580652762627,"mc":[{"id":"1.168222849","rc":[{"batb":[[2,4.6,16.05]],"batl":[[1,5.5,0]],"ltp":5.4,"tv":3.29,"id":19613369},{"batb":[[0,3.05,22.5],[1,1.01,0.51],[2,1.01,0]],"batl":[[0,4.2,13.22],[1,4.2,0]],"ltp":3.55,"tv":5.0,"id":19613367},{"batb":[[0,2.8,11.25],[1,1.01,0.51],[2,1.01,0]],"batl":[[0,3.7,16.92],[1,3.7,0]],"ltp":2.68,"tv":477.29,"id":16573039},{"batb":[[2,1.01,0.51]],"batl":[[0,5.4,14.95],[1,5.4,0]],"ltp":5.2,"tv":51.1,"id":16573041}]}]}
{"op":"mcm","clk":"1010722629","pt":1580652764681,"mc":[{"id":"1.168222849","rc":[{"batl":[[0,5.4,15.03]],"ltp":5.4,"tv":3.29,"id":19613369},{"batb":[[0,3.05,22.27]],"batl":[[0,4.2,13.06]],"ltp":3.55,"tv":5.0,"id":19613367},{"batb":[[0,2.84,47.21],[1,2.8,51.93],[2,2.78,11.41]],"batl":[[0,3.65,17.07]],"ltp":2.68,"tv":477.29,"id":16573039},{"batb":[[1,4.6,38.58]],"ltp":5.2,"tv":51.1,"id":16573041}]}]}
{"op":"mcm","clk":"1010723316","pt":1580652767741,"mc":[{"id":"1.168222849","rc":[{"batb":[[2,4.7,26.82]],"batl":[[1,5.5,9.24]],"ltp":5.4,"tv":3.29,"id":19613369},{"batb":[[0,3.75,46.08],[1,3.7,47.89],[2,3.35,17.86]],"batl":[[1,4.3,12.6],[2,4.6,21.24]],"ltp":3.55,"tv":5.0,"id":19613367},{"batl":[[0,2.96,11.17],[1,3.05,20.16],[2,3.35,21.48]],"ltp":2.68,"tv":477.29,"id":16573039},{"batb":[[0,4.7,57.23],[2,4.5,11.76]],"batl":[[0,5.3,9.24],[1,5.4,14.95]],"ltp":5.2,"tv":51.1,"id":16573041}]}]}
{"op":"mcm","clk":"1010723629","pt":1580652768706,"mc":[{"id":"1.168222849","rc":[{"batb":[[0,4.7,56.99]],"ltp":5.2,"tv":51.1,"id":16573041}]}]}
{"op":"mcm","clk":"1010726871","pt":1580652783293,"mc":[{"id":"1.168222849","rc":[{"batb":[[0,3.7,15.12],[1,3.35,17.86],[2,1.01,0.51]],"batl":[[0,4.3,12.6],[1,4.6,21.24],[2,4.6,0]],"ltp":3.55,"tv":5.0,"id":19613367},{"batb":[[0,2.74,23.53],[1,2.62,13.3],[2,1.01,0.51]],"batl":[[0,3.05,20.16],[1,3.35,21.48],[2,3.35,0]],"ltp":2.68,"tv":477.29,"id":16573039},{"batb":[[0,4.7,47.17]],"ltp":5.2,"tv":51.1,"id":16573041}]}]}
{"op":"mcm","clk":"1010727157","pt":1580652784620,"mc":[{"id":"1.168222849","rc":[{"batb":[[2,4.7,15.89]],"batl":[[1,5.5,0]],"ltp":5.4,"tv":3.29,"id":19613369},{"batb":[[0,3.35,17.86],[1,1.01,0.51],[2,1.01,0]],"batl":[[0,4.6,21.24],[1,4.6,0]],"ltp":3.55,"tv":5.0,"id":19613367},{"batb":[[0,2.62,13.3],[1,1.01,0.51],[2,1.01,0]],"batl":[[0,3.35,21.48],[1,3.35,0]],"ltp":2.68,"tv":477.29,"id":16573039},{"batb":[[2,1.01,0.51]],"batl":[[0,5.4,14.95],[1,5.4,0]],"ltp":5.2,"tv":51.1,"id":16573041}]}]}
{"op":"mcm","clk":"1010727417","pt":1580652785717,"mc":[{"id":"1.168222849","rc":[{"batb":[[0,3.35,74.62],[1,3.3,43],[2,1.01,0.51]],"ltp":3.55,"tv":5.0,"id":19613367},{"batb":[[0,2.7,46.18],[1,2.66,59.36],[2,2.62,13.3]],"ltp":2.68,"tv":477.29,"id":16573039}]}]}
{"op":"mcm","clk":"1010729063","pt":1580652792497,"mc":[{"id":"1.168222849","rc":[{"batb":[[0,4.2,2],[1,3.35,74.62],[2,3.3,43]],"ltp":3.55,"tv":5.0,"id":19613367}]}]}
{"op":"mcm","clk":"1010730738","pt":1580652799632,"mc":[{"id":"1.168222849","rc":[{"batb":[[1,3.35,17.86],[2,1.01,0.51]],"ltp":3.55,"tv":5.0,"id":19613367},{"batb":[[0,2.62,13.3],[1,1.01,0.51],[2,2.62,0]],"ltp":2.68,"tv":477.29,"id":16573039}]}]}
{"op":"mcm","clk":"1010730929","pt":1580652800444,"mc":[{"id":"1.168222849","rc":[{"batb":[[0,3.35,17.86],[1,1.01,0.51],[2,1.01,0]],"ltp":3.55,"tv":5.0,"id":19613367}]}]}
{"op":"mcm","clk":"1010731705","pt":1580652803626,"mc":[{"id":"1.168222849","rc":[{"batb":[[2,4.7,26.82]],"batl":[[0,5.3,15.19],[1,5.4,24.11]],"ltp":5.4,"tv":3.29,"id":19613369},{"trd":[[3.7,4]],"batb":[[0,3.4,16.8],[1,3.35,74.62],[2,3.3,43]],"batl":[[0,3.7,15.23],[1,4.1,13.45]],"ltp":3.7,"tv":9.0,"id":19613367},{"batb":[[0,3.1,58.33],[1,3.05,74.2],[2,2.82,11.09]],"batl":[[0,3.35,39.12],[1,3.85,15.34]],"ltp":2.68,"tv":477.29,"id":16573039},{"batb":[[1,4.6,55.26],[2,4.5,11.76]],"batl":[[0,5.3,9.24],[1,5.4,14.95]],"ltp":5.2,"tv":51.1,"id":16573041}],"tv":540.68}]}
{"op":"mcm","clk":"1010731834","pt":1580652804135,"mc":[{"id":"1.168222849","rc":[{"batl":[[1,3.9,14.28],[2,4.1,13.45]],"ltp":3.7,"tv":9.0,"id":19613367},{"batb":[[2,2.94,21]],"ltp":2.68,"tv":477.29,"id":16573039}]}]}
{"op":"mcm","clk":"1010736945","pt":1580652825650,"mc":[{"id":"1.168222849","rc":[{"batb":[[0,4.9,26.96]],"batl":[[0,5.4,24.11],[1,5.4,0]],"ltp":5.4,"tv":3.29,"id":19613369},{"batb":[[1,2.96,24.47],[2,1.01,0.51]],"batl":[[0,3.9,14.28],[1,4.1,13.45],[2,4.1,0]],"ltp":3.7,"tv":9.0,"id":19613367},{"batb":[[0,2.94,21],[1,2.82,11.09],[2,1.01,0.51]],"batl":[[0,3.35,17.64]],"ltp":2.68,"tv":477.29,"id":16573039},{"batb":[[0,4.6,55.26],[1,4.5,11.76],[2,1.01,0.51]],"ltp":5.2,"tv":51.1,"id":16573041}]}]}
{"op":"mcm","clk":"1010737191","pt":1580652826757,"mc":[{"id":"1.168222849","rc":[{"batb":[[2,4.7,15.89]],"batl":[[0,5.4,14.87]],"ltp":5.4,"tv":3.29,"id":19613369},{"batb":[[0,2.96,24.47],[1,1.01,0.51],[2,1.01,0]],"batl":[[0,4.1,13.45],[1,4.1,0]],"ltp":3.7,"tv":9.0,"id":19613367},{"batb":[[0,2.82,11.09],[1,1.01,0.51],[2,1.01,0]],"batl":[[0,3.85,15.34],[1,3.85,0]],"ltp":2.68,"tv":477.29,"id":16573039},{"batb":[[1,1.01,0.51],[2,1.01,0]],"batl":[[0,5.4,14.95],[1,5.4,0]],"ltp":5.2,"tv":51.1,"id":16573041}]}]}
{"op":"mcm","clk":"1010737683","pt":1580652828642,"mc":[{"id":"1.168222849","rc":[{"batb":[[0,2.98,24.08],[1,2.96,24.47],[2,2.94,51.32]],"batl":[[1,4.2,13.22]],"ltp":3.7,"tv":9.0,"id":19613367},{"batb":[[0,2.86,59.35],[1,2.82,61.99],[2,2.8,11.25]],"batl":[[0,3.8,15.58],[1,3.85,15.34]],"ltp":2.68,"tv":477.29,"id":16573039},{"batb":[[0,4.6,68.83],[1,4.5,40.41],[2,1.01,0.51]],"ltp":5.2,"tv":51.1,"id":16573041}]}]}
{"op":"mcm","clk":"1010737747","pt":1580652828873,"mc":[{"id":"1.168222849","rc":[{"batb":[[1,2.94,51.32],[2,2.9,47.74]],"batl":[[0,4.2,13.22],[1,4.2,0]],"ltp":3.7,"tv":9.0,"id":19613367},{"batb":[[1,2.82,50.9]],"batl":[[1,3.85,0]],"ltp":2.68,"tv":477.29,"id":16573039}]}]}
{"op":"mcm","clk":"1010738691","pt":1580652832598,"mc":[{"id":"1.168222849","rc":[{"batb":[[0,2.8,11.25],[1,1.01,0.51],[2,2.8,0]],"ltp":2.68,"tv":477.29,"id":16573039}]}]}
{"op":"mcm","clk":"1010739391","pt":1580652835607,"mc":[{"id":"1.168222849","rc":[{"batb":[[0,4.9,36.86],[2,4.7,26.82]],"batl":[[0,5.4,24.11]],"ltp":5.4,"tv":3.29,"id":19613369},{"batb":[[0,3,21],[1,2.98,24.08],[2,2.94,51.32]],"batl":[[0,3.45,16.8],[1,4.2,13.22]],"ltp":3.7,"tv":9.0,"id":19613367},{"batb":[[0,3.6,47.2],[1,3.55,35.79],[2,3.3,17.64]],"batl":[[0,3.8,29.86]],"ltp":2.68,"tv":477.29,"id":16573039},{"batb":[[2,4.4,11.76]],"batl":[[0,5.2,9.24],[1,5.4,14.95]],"ltp":5.2,"tv":51.1,"id":16573041}]}]}
{"op":"mcm","clk":"1010739658","pt":1580652836617,"mc":[{"id":"1.168222849","rc":[{"batl":[[0,5.4,23.88]],"ltp":5.4,"tv":3.29,"id":19613369},{"batl":[[0,3.25,23.13],[1,3.4,16.8],[2,3.65,17.62]],"ltp":3.7,"tv":9.0,"id":19613367},{"batb":[[2,3.45,16.05]],"batl":[[1,4.7,19.67]],"ltp":2.68,"tv":477.29,"id":16573039},{"batb":[[0,4.6,52.15],[1,4.5,69.72],[2,1.01,0.51]],"batl":[[0,5.2,25.45],[1,5.3,15.82]],"ltp":5.2,"tv":51.1,"id":16573041}]}]}
{"op":"mcm","clk":"1010744557","pt":1580652857456,"mc":[{"id":"1.168222849","rc":[{"batb":[[0,4.9,27.35]],"ltp":5.4,"tv":3.29,"id":19613369},{"batb":[[1,2.62,13.3],[2,1.01,0.51]],"batl":[[0,3.4,16.8],[1,3.65,17.62],[2,3.65,0]],"ltp":3.7,"tv":9.0,"id":19613367},{"batb":[[0,3.35,17.64],[1,3.1,21.4],[2,1.01,0.51]],"batl":[[0,3.8,14.28]],"ltp":2.68,"tv":477.29,"id":16573039},{"batb":[[0,4.6,26.42]],"batl":[[0,5.2,9.24]],"ltp":5.2,"tv":51.1,"id":16573041}]}]}
{"op":"mcm","clk":"1010744858","pt":1580652858732,"mc":[{"id":"1.168222849","rc":[{"batb":[[2,4.7,15.89]],"batl":[[0,5.4,14.63]],"ltp":5.4,"tv":3.29,"id":19613369},{"batb":[[0,2.62,13.3],[1,1.01,0.51],[2,1.01,0]],"batl":[[0,3.65,17.62],[1,3.65,0]],"ltp":3.7,"tv":9.0,"id":19613367},{"batb":[[0,3.1,21.4],[1,1.01,0.51],[2,1.01,0]],"batl":[[0,4.7,19.67],[1,4.7,0]],"ltp":2.68,"tv":477.29,"id":16573039},{"batb":[[1,4.5,57.96]],"batl":[[0,5.3,15.82],[1,5.3,0]],"ltp":5.2,"tv":51.1,"id":16573041}]}]}
{"op":"mcm","clk":"1010745169","pt":1580652860038,"mc":[{"id":"1.168222849","rc":[{"batb":[[1,2.54,41.12],[2,2.5,70.46]],"ltp":3.7,"tv":9.0,"id":19613367},{"batb":[[0,3.2,38.42],[1,3.15,48.07],[2,3.1,21.4]],"ltp":2.68,"tv":477.29,"id":16573039}]}]}
{"op":"mcm","clk":"1010745546","pt":1580652861757,"mc":[{"id":"1.168222849","rc":[{"batb":[[1,1.01,0.51],[2,2.5,0]],"ltp":3.7,"tv":9.0,"id":19613367},{"batb":[[1,4.5,17.55]],"ltp":5.2,"tv":51.1,"id":16573041}]}]}
{"op":"mcm","clk":"1010746673","pt":1580652865661,"mc":[{"id":"1.168222849","rc":[{"batb":[[2,4.6,26.89]],"batl":[[0,5.4,23.88]],"ltp":5.4,"tv":3.29,"id":19613369},{"batb":[[0,3.3,35.9],[1,3.25,73.87],[2,3.2,46.24]],"batl":[[1,3.7,15.12],[2,4.2,12.98]],"ltp":3.7,"tv":9.0,"id":19613367},{"batl":[[0,3.4,20.61],[1,3.45,16.8],[2,4.1,13.45]],"ltp":2.68,"tv":477.29,"id":16573039},{"batb":[[0,4.7,45.81],[1,4.6,55.78],[2,4.5,11.76]],"batl":[[0,5.3,25.06],[1,5.4,15.03]],"ltp":5.2,"tv":51.1,"id":16573041}]}]}
{"op":"mcm","clk":"1010750427","pt":1580652881685,"mc":[{"id":"1.168222849","rc":[{"batb":[[0,4.8,35.32],[1,4.6,26.89],[2,1.01,0.51]],"ltp":5.4,"tv":3.29,"id":19613369},{"batb":[[0,3.3,17.64],[1,2.86,10.7],[2,1.01,0.51]],"batl":[[0,3.7,15.12],[1,4.2,12.98],[2,4.2,0]],"ltp":3.7,"tv":9.0,"id":19613367},{"batb":[[0,3.05,20.16],[1,2.78,11.41],[2,1.01,0.51]],"batl":[[0,3.45,16.8],[1,4.1,13.45],[2,4.1,0]],"ltp":2.68,"tv":477.29,"id":16573039},{"batb":[[0,4.6,55.78],[1,4.5,11.76],[2,1.01,0.51]],"batl":[[0,5.3,9.24]],"ltp":5.2,"tv":51.1,"id":16573041}]}]}
{"op":"mcm","clk":"1010750863","pt":1580652883597,"mc":[{"id":"1.168222849","rc":[{"batb":[[1,4.6,15.97]],"batl":[[0,5.4,14.63]],"ltp":5.4,"tv":3.29,"id":19613369},{"batb":[[0,2.86,10.7],[1,1.01,0.51],[2,1.01,0]],"batl":[[0,4.2,12.98],[1,4.2,0]],"ltp":3.7,"tv":9.0,"id":19613367},{"batb":[[0,2.78,11.41],[1,1.01,0.51],[2,1.01,0]],"batl":[[0,4.1,13.45],[1,4.1,0]],"ltp":2.68,"tv":477.29,"id":16573039},{"batb":[[1,1.01,0.51],[2,1.01,0]],"batl":[[0,5.4,15.03],[1,5.4,0]],"ltp":5.2,"tv":51.1,"id":16573041}]}]}
{"op":"mcm","clk":"1010751081","pt":1580652884581,"mc":[{"id":"1.168222849","rc":[{"batb":[[0,4.8,55.14],[1,4.7,36.72],[2,4.6,15.97]],"ltp":5.4,"tv":3.29,"id":19613369},{"batb":[[1,2.78,40.57],[2,2.74,55.33]],"ltp":3.7,"tv":9.0,"id":19613367},{"batb":[[0,2.86,51.66],[1,2.82,50.96],[2,2.78,11.41]],"ltp":2.68,"tv":477.29,"id":16573039},{"batb":[[1,4.5,40.62],[2,1.01,0.51]],"ltp":5.2,"tv":51.1,"id":16573041}]}]}
{"op":"mcm","clk":"1010753549","pt":1580652895598,"mc":[{"id":"1.168222849","rc":[{"batb":[[1,1.01,0.51],[2,2.74,0]],"ltp":3.7,"tv":9.0,"id":19613367},{"batb":[[1,1.01,0.51],[2,1.01,0]],"ltp":5.2,"tv":51.1,"id":16573041}]}]}
{"op":"mcm","clk":"1010754304","pt":1580652898701,"mc":[{"id":"1.168222849","rc":[{"batb":[[0,3.75,13.38],[1,3.7,47.7],[2,3.65,33.72]],"batl":[[1,4.8,19.36]],"ltp":3.7,"tv":9.0,"id":19613367},{"batl":[[0,2.96,11.17],[1,3.45,19.91],[2,4.1,13.45]],"ltp":2.68,"tv":477.29,"id":16573039},{"batb":[[0,4.7,63.61],[1,4.6,55.78],[2,1.01,0.51]],"ltp":5.2,"tv":51.1,"id":16573041}]}]}
{"op":"mcm","clk":"1010754528","pt":1580652899688,"mc":[{"id":"1.168222849","rc":[{"batb":[[2,4.6,26.89]],"batl":[[0,5.4,23.88]],"ltp":5.4,"tv":3.29,"id":19613369},{"batl":[[0,4.1,13.44],[1,4.2,12.98],[2,4.8,19.36]],"ltp":3.7,"tv":9.0,"id":19613367},{"batb":[[1,2.82,73.65]],"batl":[[1,3.15,19.32],[2,3.45,19.91]],"ltp":2.68,"tv":477.29,"id":16573039},{"batb":[[1,4.6,49.7]],"batl":[[0,5.4,24.03]],"ltp":5.2,"tv":51.1,"id":16573041}]}]}
{"op":"mcm","clk":"1010759395","pt":1580652920722,"mc":[{"id":"1.168222849","rc":[{"batb":[[2,4.6,15.97]],"batl":[[0,5.4,14.63]],"ltp":5.4,"tv":3.29,"id":19613369},{"batb":[[0,3.25,19.2],[1,1.01,0.51],[2,3.65,0]],"batl":[[0,4.8,19.36],[1,4.2,0],[2,4.8,0]],"ltp":3.7,"tv":9.0,"id":19613367},{"batb":[[0,2.56,14.08],[1,1.01,0.51],[2,2.78,0]],"batl":[[0,3.45,19.91],[1,3.15,0],[2,3.45,0]],"ltp":2.68,"tv":477.29,"id":16573039},{"batb":[[0,4.7,49.32],[1,4.6,38.78]],"batl":[[0,5.4,14.79]],"ltp":5.2,"tv":51.1,"id":16573041}]}]}
{"op":"mcm","clk":"1010760046","pt":1580652923572,"mc":[{"id":"1.168222849","rc":[{"batb":[[0,3.25,54.76],[1,3.2,46.59],[2,1.01,0.51]],"ltp":3.7,"tv":9.0,"id":19613367},{"batb":[[0,2.68,44.82],[1,2.64,60.56],[2,2.56,14.08]],"ltp":2.68,"tv":477.29,"id":16573039}]}]}
{"op":"mcm","clk":"1010760286","pt":1580652924665,"mc":[{"id":"1.168222849","rc":[{"batb":[[0,3.25,19.2],[1,1.01,0.51],[2,1.01,0]],"ltp":3.7,"tv":9.0,"id":19613367}]}]}
{"op":"mcm","clk":"1010761062","pt":1580652927709,"mc":[{"id":"1.168222849","rc":[{"batb":[[1,4.7,47.64]],"batl":[[1,5.5,9.24]],"ltp":5.4,"tv":3.29,"id":19613369},{"batb":[[0,4,77.44],[1,3.95,27.67],[2,3.9,14.28]],"batl":[[0,4.5,11.76],[1,4.8,19.36]],"ltp":3.7,"tv":9.0,"id":19613367},{"batb":[[1,2.64,85.77]],"batl":[[0,2.96,21],[1,3.45,19.91]],"ltp":2.68,"tv":477.29,"id":16573039},{"batb":[[0,4.7,72.34],[2,4.5,11.76]],"batl":[[0,5.3,9.24],[1,5.4,14.79]],"ltp":5.2,"tv":51.1,"id":16573041}]}]}
{"op":"mcm","clk":"1010761258","pt":1580652928565,"mc":[{"id":"1.168222849","rc":[{"batl":[[0,5.3,15.34]],"ltp":5.4,"tv":3.29,"id":19613369},{"batb":[[0,4.2,20.38],[1,4,77.44],[2,3.95,27.67]],"batl":[[2,5.6,13.61]],"ltp":3.7,"tv":9.0,"id":19613367},{"batl":[[0,2.72,13.85],[1,2.94,11.41],[2,2.96,21]],"ltp":2.68,"tv":477.29,"id":16573039},{"batb":[[0,4.8,15.5],[1,4.7,71.87],[2,4.6,38.78]],"batl":[[1,5.5,14.32]],"ltp":5.2,"tv":51.1,"id":16573041}]}]}
{"op":"mcm","clk":"1010763082","pt":1580652936623,"mc":[{"id":"1.168222849","rc":[{"batb":[[0,4.8,42.77]],"ltp":5.4,"tv":3.29,"id":19613369},{"batb":[[1,4,65.54]],"ltp":3.7,"tv":9.0,"id":19613367},{"batb":[[1,4.7,52.91],[2,4.5,11.76]],"ltp":5.2,"tv":51.1,"id":16573041}]}]}
{"op":"mcm","clk":"1010763770","pt":1580652939525,"mc":[{"id":"1.168222849","rc":[{"batb":[[0,2.68,61.22]],"ltp":2.68,"tv":477.29,"id":16573039},{"batb":[[0,4.8,41.36]],"ltp":5.2,"tv":51.1,"id":16573041}]}]}
{"op":"mcm","clk":"1010763898","pt":1580652939971,"mc":[{"id":"1.168222849","rc":[{"batb":[[2,2.58,13.85]],"batl":[[0,2.74,13.61],[1,2.96,32.26],[2,2.96,0]],"ltp":2.68,"tv":477.29,"id":16573039},{"batb":[[1,4.7,37.09]],"batl":[[2,5.6,14.08]],"ltp":5.2,"tv":51.1,"id":16573041}]}]}
{"op":"mcm","clk":"1010765781","pt":1580652948033,"mc":[{"id":"1.168222849","rc":[{"batl":[[1,4.7,19.83]],"ltp":3.7,"tv":9.0,"id":19613367}]}]}
{"op":"mcm","clk":"1010769544","pt":1580652964271,"mc":[{"id":"1.168222849","rc":[{"batb":[[2,4.5,16.84]],"batl":[[0,5.2,15.97]],"ltp":5.4,"tv":3.29,"id":19613369},{"batb":[[0,4.1,21.24]],"batl":[[2,5.5,14.24]],"ltp":3.7,"tv":9.0,"id":19613367},{"batb":[[2,2.6,13.61]],"batl":[[0,2.76,13.38],[1,2.96,21],[2,2.98,11.02]],"ltp":2.68,"tv":477.29,"id":16573039},{"batb":[[0,4.8,41.2]],"batl":[[1,5.6,13.93],[2,5.6,0]],"ltp":5.2,"tv":51.1,"id":16573041}]}]}
{"op":"mcm","clk":"1010771717","pt":1580652973670,"mc":[{"id":"1.168222849","rc":[{"batb":[[2,2.62,13.38]],"batl":[[0,2.78,13.14],[2,3,10.86]],"ltp":2.68,"tv":477.29,"id":16573039},{"batb":[[0,4.9,14.79],[1,4.8,40.97],[2,4.7,37.09]],"batl":[[1,5.6,13.69]],"ltp":5.2,"tv":51.1,"id":16573041}]}]}
{"op":"mcm","clk":"1010774998","pt":1580652988506,"mc":[{"id":"1.168222849","rc":[{"batl":[[0,5.1,16.6]],"ltp":5.4,"tv":3.29,"id":19613369},{"batb":[[0,4,87.65],[1,3.95,27.67],[2,3.9,14.28]],"batl":[[1,4.6,21.01],[2,5.4,14.79]],"ltp":3.7,"tv":9.0,"id":19613367},{"batb":[[1,2.64,98.91],[2,2.4,16.84]],"batl":[[0,2.8,12.9],[2,3.05,10.62]],"ltp":2.68,"tv":477.29,"id":16573039},{"batb":[[1,4.8,25.86]],"batl":[[2,5.7,13.53]],"ltp":5.2,"tv":51.1,"id":16573041}]}]}
{"op":"mcm","clk":"1010779469","pt":1580653008264,"mc":[{"id":"1.168222849","rc":[{"batb":[[0,3.9,14.28],[1,3.7,13.85],[2,1.01,0.51]],"batl":[[1,5.4,14.79],[2,5.4,0]],"ltp":3.7,"tv":9.0,"id":19613367},{"batb":[[0,2.64,25.21],[1,2.4,16.84],[2,1.01,0.51]],"batl":[[0,2.96,21],[1,3.05,10.62],[2,3.05,0]],"ltp":2.68,"tv":477.29,"id":16573039},{"batb":[[1,4.7,37.09],[2,4.5,11.76]],"batl":[[1,5.7,13.53],[2,5.7,0]],"ltp":5.2,"tv":51.1,"id":16573041}]}]}
{"op":"mcm","clk":"1010779644","pt":1580653008933,"mc":[{"id":"1.168222849","rc":[{"batb":[[1,4.7,36.72]],"batl":[[1,5.5,0]],"ltp":5.4,"tv":3.29,"id":19613369},{"batb":[[0,3.7,13.85],[1,1.01,0.51],[2,1.01,0]],"batl":[[0,5.4,14.79],[1,5.4,0]],"ltp":3.7,"tv":9.0,"id":19613367},{"batb":[[0,2.4,16.84],[1,1.01,0.51],[2,1.01,0]],"batl":[[0,3.05,10.62],[1,3.05,0]],"ltp":2.68,"tv":477.29,"id":16573039},{"batb":[[2,1.01,0.51]],"batl":[[0,5.7,13.53],[1,5.7,0]],"ltp":5.2,"tv":51.1,"id":16573041}]}]}
{"op":"mcm","clk":"1010780115","pt":1580653011158,"mc":[{"id":"1.168222849","rc":[{"batb":[[0,3.7,65.57],[1,3.65,33.57],[2,1.01,0.51]],"ltp":3.7,"tv":9.0,"id":19613367},{"batb":[[0,2.44,59.94],[1,2.4,95.11],[2,1.01,0.51]],"ltp":2.68,"tv":477.29,"id":16573039},{"batb":[[1,4.7,51.19],[2,4.6,38.54]],"ltp":5.2,"tv":51.1,"id":16573041}]}]}
{"op":"mcm","clk":"1010780455","pt":1580653012632,"mc":[{"id":"1.168222849","rc":[{"batb":[[0,3.7,13.85],[1,1.01,0.51],[2,1.01,0]],"ltp":3.7,"tv":9.0,"id":19613367},{"batb":[[1,4.7,37.09],[2,1.01,0.51]],"ltp":5.2,"tv":51.1,"id":16573041}]}]}
{"op":"mcm","clk":"1010781099","pt":1580653015652,"mc":[{"id":"1.168222849","rc":[{"batb":[[0,4.7,40.56],[1,4.6,38.67],[2,3.7,13.85]],"ltp":3.7,"tv":9.0,"id":19613367},{"batb":[[1,4.8,44.34],[2,4.7,37.09]],"ltp":5.2,"tv":51.1,"id":16573041}]}]}
{"op":"mcm","clk":"1010781311","pt":1580653016640,"mc":[{"id":"1.168222849","rc":[{"batb":[[1,4.7,47.64]],"ltp":5.4,"tv":3.29,"id":19613369},{"batb":[[0,4.7,56.06],[2,4.4,11.76]],"batl":[[0,5.2,9.24],[1,5.4,14.79],[2,6.8,18.8]],"ltp":3.7,"tv":9.0,"id":19613367},{"batb":[[0,2.44,88.51],[2,2.18,21.79]],"batl":[[0,2.56,16.44],[1,2.76,13.38]],"ltp":2.68,"tv":477.29,"id":16573039},{"batb":[[0,5,14.16],[1,4.9,14.56],[2,4.8,44.34]],"batl":[[0,5.4,9.24],[1,5.7,13.53],[2,5.8,13.06]],"ltp":5.2,"tv":51.1,"id":16573041}]}]}
{"op":"mcm","clk":"1010782001","pt":1580653019725,"mc":[{"id":"1.168222849","rc":[{"batl":[[1,5.5,9.24]],"ltp":5.4,"tv":3.29,"id":19613369},{"batl":[[1,2.7,24.37],[2,2.76,13.38]],"ltp":2.68,"tv":477.29,"id":16573039}]}]}
{"op":"mcm","clk":"1010783601","pt":1580653027148,"mc":[{"id":"1.168222849","rc":[{"batb":[[0,4.4,11.76],[1,4.1,20.93],[2,1.01,0.51]],"batl":[[1,6.8,18.8],[2,6.8,0]],"ltp":3.7,"tv":9.0,"id":19613367},{"batb":[[0,2.44,28.57],[1,2.18,21.79],[2,1.01,0.51]],"batl":[[0,2.7,24.37],[1,2.76,13.38],[2,2.76,0]],"ltp":2.68,"tv":477.29,"id":16573039},{"batb":[[0,4.9,14.56],[1,4.8,26.2],[2,4.7,37.09]],"batl":[[1,5.8,13.06],[2,5.8,0]],"ltp":5.2,"tv":51.1,"id":16573041}]}]}
{"op":"mcm","clk":"1010784139","pt":1580653029448,"mc":[{"id":"1.168222849","rc":[{"batb":[[1,4.7,36.72]],"batl":[[1,5.5,0]],"ltp":5.4,"tv":3.29,"id":19613369},{"batb":[[0,4.1,20.93],[1,1.01,0.51],[2,1.01,0]],"batl":[[0,6.8,18.8],[1,6.8,0]],"ltp":3.7,"tv":9.0,"id":19613367},{"batb":[[0,2.18,21.79],[1,1.01,0.51],[2,1.01,0]],"batl":[[0,2.76,13.38],[1,2.76,0]],"ltp":2.68,"tv":477.29,"id":16573039},{"batl":[[0,5.8,13.06],[1,5.8,0]],"ltp":5.2,"tv":51.1,"id":16573041}]}]}
{"op":"mcm","clk":"1010784392","pt":1580653030668,"mc":[{"id":"1.168222849","rc":[{"batb":[[0,4.1,94.28],[1,4,52.9],[2,1.01,0.51]],"ltp":3.7,"tv":9.0,"id":19613367},{"batb":[[0,2.2,56.77],[1,2.18,73.53],[2,1.01,0.51]],"ltp":2.68,"tv":477.29,"id":16573039}]}]}
{"op":"mcm","clk":"1010784467","pt":1580653031009,"mc":[{"id":"1.168222849","rc":[{"batb":[[0,4.1,20.93],[1,1.01,0.51],[2,1.01,0]],"ltp":3.7,"tv":9.0,"id":19613367},{"batb":[[0,2.18,21.79],[1,1.01,0.51],[2,1.01,0]],"ltp":2.68,"tv":477.29,"id":16573039}]}]}
{"op":"mcm","clk":"1010784987","pt":1580653033383,"mc":[{"id":"1.168222849","rc":[{"batb":[[0,4.9,37.83],[1,4.8,35.12],[2,4.1,20.93]],"ltp":3.7,"tv":9.0,"id":19613367},{"batb":[[0,2.38,75.85],[1,2.34,83.85],[2,2.18,21.79]],"ltp":2.68,"tv":477.29,"id":16573039},{"batb":[[1,4.8,49.98]],"ltp":5.2,"tv":51.1,"id":16573041}]}]}
{"op":"mcm","clk":"1010785975","pt":1580653038029,"mc":[{"id":"1.168222849","rc":[{"batb":[[0,4.1,20.93],[1,1.01,0.51],[2,4.1,0]],"ltp":3.7,"tv":9.0,"id":19613367},{"batb":[[0,2.18,21.79],[1,1.01,0.51],[2,2.18,0]],"ltp":2.68,"tv":477.29,"id":16573039},{"batb":[[1,4.8,27.38]],"ltp":5.2,"tv":51.1,"id":16573041}]}]}
{"op":"mcm","clk":"1010786581","pt":1580653040961,"mc":[{"id":"1.168222849","rc":[{"batb":[[0,4.1,92.56],[1,4,52.9],[2,1.01,0.51]],"ltp":3.7,"tv":9.0,"id":19613367},{"batb":[[0,2.2,59.58],[1,2.18,73.53],[2,1.01,0.51]],"ltp":2.68,"tv":477.29,"id":16573039}]}]}
{"op":"mcm","clk":"1010789797","pt":1580653055718,"mc":[{"id":"1.168222849","rc":[{"batb":[[0,2.18,21.79],[1,1.01,0.51],[2,1.01,0]],"ltp":2.68,"tv":477.29,"id":16573039}]}]}
{"op":"mcm","clk":"1010790553","pt":1580653058759,"mc":[{"id":"1.168222849","rc":[{"batb":[[2,3.7,13.85]],"batl":[[0,4.7,19.91],[1,5.7,13.06]],"ltp":3.7,"tv":9.0,"id":19613367},{"batb":[[0,2.64,45.64],[1,2.6,76.87],[2,2.34,18.1]],"batl":[[1,3.05,10.62]],"ltp":2.68,"tv":477.29,"id":16573039},{"batl":[[0,5.6,13.93],[1,5.7,13.45]],"ltp":5.2,"tv":51.1,"id":16573041}]}]}
{"op":"mcm","clk":"1010790797","pt":1580653059735,"mc":[{"id":"1.168222849","rc":[{"batb":[[1,4.7,47.64]],"batl":[[1,5.5,9.24]],"ltp":5.4,"tv":3.29,"id":19613369},{"batb":[[0,4.1,106]],"batl":[[0,4.7,30.83]],"ltp":3.7,"tv":9.0,"id":19613367},{"batb":[[2,2.56,26.89]],"batl":[[1,2.84,22.69],[2,3.05,10.62]],"ltp":2.68,"tv":477.29,"id":16573039},{"batl":[[0,5.3,9.24],[1,5.6,13.93],[2,5.7,13.45]],"ltp":5.2,"tv":51.1,"id":16573041}]}]}
{"op":"mcm","clk":"1010793781","pt":1580653073691,"mc":[{"id":"1.168222849","rc":[{"batb":[[0,4.1,34.37],[1,3.7,13.85],[2,1.01,0.51]],"ltp":3.7,"tv":9.0,"id":19613367},{"batb":[[0,2.6,13.69],[1,2.56,26.89],[2,2.34,18.1]],"ltp":2.68,"tv":477.29,"id":16573039},{"batb":[[1,4.7,37.09],[2,4.5,11.76]],"ltp":5.2,"tv":51.1,"id":16573041}]}]}
{"op":"mcm","clk":"1010793890","pt":1580653074189,"mc":[{"id":"1.168222849","rc":[{"batb":[[0,4.1,13.44]],"batl":[[0,4.7,10.92]],"ltp":3.7,"tv":9.0,"id":19613367},{"batb":[[0,2.56,26.89],[1,2.34,18.1],[2,1.01,0.51]],"batl":[[0,2.84,22.69],[1,3.05,10.62],[2,3.05,0]],"ltp":2.68,"tv":477.29,"id":16573039},{"batl":[[1,5.7,13.45],[2,5.7,0]],"ltp":5.2,"tv":51.1,"id":16573041}]}]}
{"op":"mcm","clk":"1010794029","pt":1580653074881,"mc":[{"id":"1.168222849","rc":[{"batb":[[1,4.7,36.72]],"batl":[[1,5.5,0]],"ltp":5.4,"tv":3.29,"id":19613369},{"batb":[[0,3.7,13.85],[1,1.01,0.51],[2,1.01,0]],"batl":[[0,5.7,13.06],[1,5.7,0]],"ltp":3.7,"tv":9.0,"id":19613367},{"batb":[[0,2.34,18.1],[1,1.01,0.51],[2,1.01,0]],"batl":[[0,3.05,10.62],[1,3.05,0]],"ltp":2.68,"tv":477.29,"id":16573039},{"batb":[[2,1.01,0.51]],"batl":[[0,5.7,13.45],[1,5.7,0]],"ltp":5.2,"tv":51.1,"id":16573041}]}]}
{"op":"mcm","clk":"1010794390","pt":1580653076600,"mc":[{"id":"1.168222849","rc":[{"batb":[[0,3.75,40.51],[1,3.7,46.42],[2,1.01,0.51]],"ltp":3.7,"tv":9.0,"id":19613367},{"batb":[[0,2.36,62.25],[1,2.34,18.1],[2,2.32,85.96]],"ltp":2.68,"tv":477.29,"id":16573039},{"batb":[[1,4.7,49.34],[2,4.6,38.59]],"ltp":5.2,"tv":51.1,"id":16573041}]}]}
{"op":"mcm","clk":"1010794652","pt":1580653077697,"mc":[{"id":"1.168222849","rc":[{"batb":[[0,2.34,18.1],[1,1.01,0.51],[2,2.32,0]],"ltp":2.68,"tv":477.29,"id":16573039}]}]}
{"op":"mcm","clk":"1010795277","pt":1580653080591,"mc":[{"id":"1.168222849","rc":[{"batb":[[0,2.84,60.23],[1,2.8,51.96],[2,2.34,18.1]],"ltp":2.68,"tv":477.29,"id":16573039}]}]}
{"op":"mcm","clk":"1010795538","pt":1580653081685,"mc":[{"id":"1.168222849","rc":[{"batb":[[1,4.7,47.64]],"batl":[[0,5.2,16.44],[1,5.4,9.24]],"ltp":5.4,"tv":3.29,"id":19613369},{"batb":[[0,3.75,55.63],[2,3.4,17.23]],"batl":[[0,4.1,13.38],[1,4.3,12.6],[2,4.9,18.73]],"ltp":3.7,"tv":9.0,"id":19613367},{"batb":[[0,2.84,71.09],[2,2.72,24.37]],"batl":[[0,3.05,30.79],[1,3.3,21.64]],"ltp":2.68,"tv":477.29,"id":16573039},{"batb":[[0,4.8,15.34]],"batl":[[0,5.3,9.24],[1,5.6,13.93]],"ltp":5.2,"tv":51.1,"id":16573041}]}]}
{"op":"mcm","clk":"1010798620","pt":1580653096156,"mc":[{"id":"1.168222849","rc":[{"batb":[[0,3.75,15.12],[1,3.4,17.23],[2,1.01,0.51]],"batl":[[0,4.3,12.6],[1,4.9,18.73],[2,4.9,0]],"ltp":3.7,"tv":9.0,"id":19613367},{"batb":[[0,2.72,24.37],[1,2.56,14.16],[2,1.01,0.51]],"batl":[[0,3.05,20.16]],"ltp":2.68,"tv":477.29,"id":16573039},{"batb":[[1,4.7,38.92]],"ltp":5.2,"tv":51.1,"id":16573041}]}]}
{"op":"mcm","clk":"1010798860","pt":1580653097096,"mc":[{"id":"1.168222849","rc":[{"batb":[[1,4.7,36.72]],"batl":[[1,5.4,0]],"ltp":5.4,"tv":3.29,"id":19613369},{"batb":[[0,3.4,17.23],[1,1.01,0.51],[2,1.01,0]],"batl":[[0,4.9,18.73],[1,4.9,0]],"ltp":3.7,"tv":9.0,"id":19613367},{"batb":[[0,2.56,14.16],[1,1.01,0.51],[2,1.01,0]],"batl":[[0,3.3,21.64],[1,3.3,0]],"ltp":2.68,"tv":477.29,"id":16573039},{"batl":[[0,5.6,13.93],[1,5.6,0]],"ltp":5.2,"tv":51.1,"id":16573041}]}]}
{"op":"mcm","clk":"1010799191","pt":1580653098632,"mc":[{"id":"1.168222849","rc":[{"batb":[[0,3.45,59.86],[1,3.4,57.01],[2,1.01,0.51]],"ltp":3.7,"tv":9.0,"id":19613367},{"batb":[[0,2.58,58.38],[1,2.56,14.16],[2,2.54,67.15]],"ltp":2.68,"tv":477.29,"id":16573039}]}]}
{"op":"mcm","clk":"1010800342","pt":1580653103634,"mc":[{"id":"1.168222849","rc":[{"batb":[[0,3.4,17.23],[1,1.01,0.51],[2,1.01,0]],"ltp":3.7,"tv":9.0,"id":19613367},{"batb":[[1,4.7,37.09],[2,1.01,0.51]],"ltp":5.2,"tv":51.1,"id":16573041}]}]}
{"op":"mcm","clk":"1010800898","pt":1580653106633,"mc":[{"id":"1.168222849","rc":[{"batb":[[0,4.3,35.53],[1,4.2,47.78],[2,3.4,17.23]],"ltp":3.7,"tv":9.0,"id":19613367},{"batb":[[0,4.8,43.67]],"ltp":5.2,"tv":51.1,"id":16573041}]}]}
{"op":"mcm","clk":"1010801108","pt":1580653107747,"mc":[{"id":"1.168222849","rc":[{"batb":[[1,4.7,47.64]],"batl":[[0,5.2,16.29],[1,5.5,9.24]],"ltp":5.4,"tv":3.29,"id":19613369},{"batb":[[0,4.3,55.2],[1,4.2,60.38],[2,3.7,13.93]],"batl":[[0,4.9,28.81],[1,6.4,10.78]],"ltp":3.7,"tv":9.0,"id":19613367},{"batl":[[0,2.72,13.93],[1,2.8,22.69],[2,3.05,10.7]],"ltp":2.68,"tv":477.29,"id":16573039},{"batb":[[0,4.9,15.11],[1,4.8,28.33],[2,4.7,37.09]],"batl":[[0,5.3,9.24],[1,5.6,13.93],[2,5.7,13.3]],"ltp":5.2,"tv":51.1,"id":16573041}]}]}
{"op":"mcm","clk":"1010804331","pt":1580653124654,"mc":[{"id":"1.168222849","rc":[{"batb":[[0,4.2,12.6],[1,3.7,13.93],[2,1.01,0.51]],"batl":[[0,4.9,10.08]],"ltp":3.7,"tv":9.0,"id":19613367},{"batb":[[0,2.52,26.89],[1,2.24,20.22],[2,1.01,0.51]],"batl":[[0,2.8,22.69],[1,3.05,10.7],[2,3.05,0]],"ltp":2.68,"tv":477.29,"id":16573039},{"batb":[[1,4.7,37.09],[2,4.5,11.76]],"batl":[[1,5.7,13.3],[2,5.7,0]],"ltp":5.2,"tv":51.1,"id":16573041}]}]}
{"op":"mcm","clk":"1010804388","pt":1580653124878,"mc":[{"id":"1.168222849","rc":[{"batb":[[1,4.7,36.72]],"batl":[[1,5.5,0]],"ltp":5.4,"tv":3.29,"id":19613369},{"batb":[[0,3.7,13.93],[1,1.01,0.51],[2,1.01,0]],"batl":[[0,6.4,10.78],[1,6.4,0]],"ltp":3.7,"tv":9.0,"id":19613367},{"batb":[[0,2.24,20.22],[1,1.01,0.51],[2,1.01,0]],"batl":[[0,3.05,10.7],[1,3.05,0]],"ltp":2.68,"tv":477.29,"id":16573039},{"batb":[[2,1.01,0.51]],"batl":[[0,5.7,13.3],[1,5.7,0]],"ltp":5.2,"tv":51.1,"id":16573041}]}]}
{"op":"mcm","clk":"1010804887","pt":1580653127470,"mc":[{"id":"1.168222849","rc":[{"batb":[[0,3.75,30.15],[1,3.7,46.59],[2,1.01,0.51]],"ltp":3.7,"tv":9.0,"id":19613367},{"batb":[[0,2.24,109.91],[1,2.22,49.05],[2,1.01,0.51]],"ltp":2.68,"tv":477.29,"id":16573039},{"batb":[[2,4.6,38.68]],"ltp":5.2,"tv":51.1,"id":16573041}]}]}
{"op":"mcm","clk":"1010805034","pt":1580653128273,"mc":[{"id":"1.168222849","rc":[{"batb":[[0,3.7,13.93],[1,1.01,0.51],[2,1.01,0]],"ltp":3.7,"tv":9.0,"id":19613367},{"batb":[[0,2.24,20.22],[1,1.01,0.51],[2,1.01,0]],"ltp":2.68,"tv":477.29,"id":16573039},{"batb":[[2,1.01,0.51]],"ltp":5.2,"tv":51.1,"id":16573041}]}]}
{"op":"mcm","clk":"1010805616","pt":1580653131272,"mc":[{"id":"1.168222849","rc":[{"batb":[[0,4.5,38.5],[1,4.4,42.85],[2,3.7,13.93]],"ltp":3.7,"tv":9.0,"id":19613367},{"batb":[[0,2.5,71.17],[1,2.46,73.12],[2,2.24,20.22]],"ltp":2.68,"tv":477.29,"id":16573039},{"batb":[[1,4.8,35.28],[2,4.7,37.09]],"ltp":5.2,"tv":51.1,"id":16573041}]}]}
{"op":"mcm","clk":"1010806074","pt":1580653133665,"mc":[{"id":"1.168222849","rc":[{"batb":[[0,3.7,13.93],[1,1.01,0.51],[2,3.7,0]],"ltp":3.7,"tv":9.0,"id":19613367},{"batb":[[0,2.24,20.22],[1,1.01,0.51],[2,2.24,0]],"ltp":2.68,"tv":477.29,"id":16573039},{"batb":[[1,4.7,37.09],[2,1.01,0.51]],"ltp":5.2,"tv":51.1,"id":16573041}]}]}
{"op":"mcm","clk":"1010806568","pt":1580653136345,"mc":[{"id":"1.168222849","rc":[{"batb":[[0,3.75,30.15],[1,3.7,46.59],[2,1.01,0.51]],"ltp":3.7,"tv":9.0,"id":19613367},{"batb":[[0,2.24,109.91],[1,2.22,49.05],[2,1.01,0.51]],"ltp":2.68,"tv":477.29,"id":16573039},{"batb":[[2,4.6,38.68]],"ltp":5.2,"tv":51.1,"id":16573041}]}]}
{"op":"mcm","clk":"1010808472","pt":1580653146686,"mc":[{"id":"1.168222849","rc":[{"batb":[[0,2.24,20.22],[1,1.01,0.51],[2,1.01,0]],"ltp":2.68,"tv":477.29,"id":16573039}]}]}
{"op":"mcm","clk":"1010809034","pt":1580653149597,"mc":[{"id":"1.168222849","rc":[{"batb":[[0,2.86,45.31],[1,2.82,51.12],[2,2.24,20.22]],"ltp":2.68,"tv":477.29,"id":16573039}]}]}
{"op":"mcm","clk":"1010809224","pt":1580653150579,"mc":[{"id":"1.168222849","rc":[{"batb":[[1,4.7,47.64]],"batl":[[1,5.5,9.24]],"ltp":5.4,"tv":3.29,"id":19613369},{"batb":[[0,3.8,14.28],[1,3.75,30.15],[2,3.7,46.59]],"batl":[[0,4.1,13.53],[1,4.4,11.76],[2,4.9,18.1]],"ltp":3.7,"tv":9.0,"id":19613367},{"batb":[[1,2.84,10.86],[2,2.82,51.12]],"batl":[[0,3.05,30.87],[1,3.4,20.69]],"ltp":2.68,"tv":477.29,"id":16573039},{"batb":[[0,4.8,15.82]],"batl":[[0,5.2,9.24],[1,5.5,14.4],[2,5.6,14.01]],"ltp":5.2,"tv":51.1,"id":16573041}]}]}
{"op":"mcm","clk":"1010813192","pt":1580653171657,"mc":[{"id":"1.168222849","rc":[{"batb":[[1,3.35,17.7],[2,1.01,0.51]],"batl":[[0,4.4,11.76],[1,4.9,18.1],[2,4.9,0]],"ltp":3.7,"tv":9.0,"id":19613367},{"batb":[[0,2.7,24.37],[1,2.52,14.63],[2,1.01,0.51]],"batl":[[0,3.05,20.16]],"ltp":2.68,"tv":477.29,"id":16573039},{"batb":[[1,4.7,33.03]],"batl":[[1,5.6,14.01],[2,5.6,0]],"ltp":5.2,"tv":51.1,"id":16573041}]}]}
{"op":"mcm","clk":"1010813457","pt":1580653173131,"mc":[{"id":"1.168222849","rc":[{"batb":[[1,4.7,36.72]],"batl":[[1,5.5,0]],"ltp":5.4,"tv":3.29,"id":19613369},{"batb":[[0,3.35,17.7],[1,1.01,0.51],[2,1.01,0]],"batl":[[0,4.9,18.1],[1,4.9,0]],"ltp":3.7,"tv":9.0,"id":19613367},{"batb":[[0,2.52,14.63],[1,1.01,0.51],[2,1.01,0]],"batl":[[0,3.4,20.69],[1,3.4,0]],"ltp":2.68,"tv":477.29,"id":16573039},{"batl":[[0,5.6,14.01],[1,5.6,0]],"ltp":5.2,"tv":51.1,"id":16573041}]}]}
{"op":"mcm","clk":"1010813758","pt":1580653174640,"mc":[{"id":"1.168222849","rc":[{"batl":[[0,5.2,16.05]],"ltp":5.4,"tv":3.29,"id":19613369},{"batb":[[0,3.4,65.51],[1,3.35,58.67],[2,1.01,0.51]],"batl":[[0,5,17.86]],"ltp":3.7,"tv":9.0,"id":19613367},{"batb":[[0,2.56,50.34],[1,2.52,83.27],[2,1.01,0.51]],"batl":[[0,3.35,21.01]],"ltp":2.68,"tv":477.29,"id":16573039},{"batb":[[0,4.7,49],[1,4.6,38.68],[2,1.01,0.51]],"ltp":5.2,"tv":51.1,"id":16573041}]}]}
{"op":"mcm","clk":"1010813895","pt":1580653175449,"mc":[{"id":"1.168222849","rc":[{"batb":[[0,3.35,17.47],[1,1.01,0.51],[2,1.01,0]],"ltp":3.7,"tv":9.0,"id":19613367},{"batb":[[0,2.52,14.63],[1,1.01,0.51],[2,1.01,0]],"ltp":2.68,"tv":477.29,"id":16573039}]}]}
{"op":"mcm","clk":"1010814497","pt":1580653178759,"mc":[{"id":"1.168222849","rc":[{"batb":[[0,4.8,50.53]],"ltp":5.4,"tv":3.29,"id":19613369},{"batb":[[0,3.85,35.64],[1,3.8,30.6],[2,3.35,17.47]],"ltp":3.7,"tv":9.0,"id":19613367},{"batb":[[0,2.8,38.92],[1,2.76,54.08],[2,2.52,14.63]],"ltp":2.68,"tv":477.29,"id":16573039},{"batb":[[0,4.7,63.84]],"ltp":5.2,"tv":51.1,"id":16573041}]}]}
{"op":"mcm","clk":"1010815114","pt":1580653182143,"mc":[{"id":"1.168222849","rc":[{"batb":[[0,3.35,17.47],[1,1.01,0.51],[2,3.35,0]],"ltp":3.7,"tv":9.0,"id":19613367},{"batb":[[0,2.52,14.63],[1,1.01,0.51],[2,2.52,0]],"ltp":2.68,"tv":477.29,"id":16573039},{"batb":[[0,4.7,49]],"ltp":5.2,"tv":51.1,"id":16573041}]}]}
{"op":"mcm","clk":"1010815638","pt":1580653185035,"mc":[{"id":"1.168222849","rc":[{"batb":[[0,3.4,65.51],[1,3.35,58.67],[2,1.01,0.51]],"ltp":3.7,"tv":9.0,"id":19613367},{"batb":[[0,2.56,50.34],[1,2.52,83.27],[2,1.01,0.51]],"ltp":2.68,"tv":477.29,"id":16573039}]}]}
{"op":"mcm","clk":"1010819276","pt":1580653203624,"mc":[{"id":"1.168222849","rc":[{"batb":[[0,3.35,17.47],[1,1.01,0.51],[2,1.01,0]],"ltp":3.7,"tv":9.0,"id":19613367},{"batb":[[1,1.01,0.51],[2,1.01,0]],"ltp":5.2,"tv":51.1,"id":16573041}]}]}
{"op":"mcm","clk":"1010819849","pt":1580653206450,"mc":[{"id":"1.168222849","rc":[{"batb":[[0,4.3,61.62],[1,4.2,47.33],[2,3.35,17.47]],"ltp":3.7,"tv":9.0,"id":19613367},{"batb":[[0,4.8,28.54],[1,4.7,49],[2,1.01,0.51]],"ltp":5.2,"tv":51.1,"id":16573041}]}]}
{"op":"mcm","clk":"1010820024","pt":1580653207256,"mc":[{"id":"1.168222849","rc":[{"batb":[[0,4.3,80.35],[2,3.8,13.22]],"batl":[[1,6.6,20.3]],"ltp":3.7,"tv":9.0,"id":19613367},{"batb":[[2,2.22,20.93]],"batl":[[0,2.68,14.56],[1,2.98,11.02]],"ltp":2.68,"tv":477.29,"id":16573039},{"batb":[[0,4.9,14.79],[1,4.8,43.96],[2,4.7,33.03]],"batl":[[1,5.7,13.45]],"ltp":5.2,"tv":51.1,"id":16573041}]}]}
{"op":"mcm","clk":"1010820159","pt":1580653207846,"mc":[{"id":"1.168222849","rc":[{"batb":[[0,4.8,61.45]],"batl":[[1,5.6,8.4]],"ltp":5.4,"tv":3.29,"id":19613369},{"batb":[[0,4.3,92.95]],"batl":[[0,5,27.94]],"ltp":3.7,"tv":9.0,"id":19613367},{"batb":[[2,2.5,27.73]],"batl":[[1,2.76,23.53],[2,2.98,11.02]],"ltp":2.68,"tv":477.29,"id":16573039},{"batl":[[0,5.2,9.24],[1,5.6,14.01],[2,5.7,13.45]],"ltp":5.2,"tv":51.1,"id":16573041}]}]}
{"op":"mcm","clk":"1010824919","pt":1580653229718,"mc":[{"id":"1.168222849","rc":[{"batb":[[0,4.3,31.33],[1,3.8,13.22],[2,1.01,0.51]],"ltp":3.7,"tv":9.0,"id":19613367},{"batb":[[0,2.52,14.63],[1,2.5,27.73],[2,2.22,20.93]],"ltp":2.68,"tv":477.29,"id":16573039},{"batb":[[1,4.8,15.42]],"ltp":5.2,"tv":51.1,"id":16573041}]}]}
{"op":"mcm","clk":"1010824986","pt":1580653230019,"mc":[{"id":"1.168222849","rc":[{"batb":[[0,4.3,12.6]],"batl":[[0,5,10.08]],"ltp":3.7,"tv":9.0,"id":19613367},{"batb":[[0,2.5,27.73],[1,2.22,20.93],[2,1.01,0.51]],"batl":[[0,2.76,23.53],[1,2.98,11.02],[2,2.98,0]],"ltp":2.68,"tv":477.29,"id":16573039},{"batb":[[0,4.8,15.42],[1,4.7,33.03],[2,4.5,11.76]],"batl":[[1,5.7,13.45],[2,5.7,0]],"ltp":5.2,"tv":51.1,"id":16573041}]}]}
{"op":"mcm","clk":"1010825178","pt":1580653230912,"mc":[{"id":"1.168222849","rc":[{"batb":[[0,4.8,50.53]],"batl":[[1,5.6,0]],"ltp":5.4,"tv":3.29,"id":19613369},{"batb":[[0,3.8,13.22],[1,1.01,0.51],[2,1.01,0]],"batl":[[0,6.6,20.3],[1,6.6,0]],"ltp":3.7,"tv":9.0,"id":19613367},{"batb":[[0,2.22,20.93],[1,1.01,0.51],[2,1.01,0]],"batl":[[0,2.98,11.02],[1,2.98,0]],"ltp":2.68,"tv":477.29,"id":16573039},{"batb":[[2,1.01,0.51]],"batl":[[0,5.7,13.45],[1,5.7,0]],"ltp":5.2,"tv":51.1,"id":16573041}]}]}
{"op":"mcm","clk":"1010825544","pt":1580653232752,"mc":[{"id":"1.168222849","rc":[{"batb":[[1,3.75,57.33],[2,3.7,32.42]],"ltp":3.7,"tv":9.0,"id":19613367},{"batb":[[0,2.22,115.02],[1,2.2,50.33],[2,1.01,0.51]],"ltp":2.68,"tv":477.29,"id":16573039},{"batb":[[1,4.7,42.15],[2,4.6,38.7]],"ltp":5.2,"tv":51.1,"id":16573041}]}]}
{"op":"mcm","clk":"1010825756","pt":1580653233732,"mc":[{"id":"1.168222849","rc":[{"batb":[[0,2.22,20.93],[1,1.01,0.51],[2,1.01,0]],"ltp":2.68,"tv":477.29,"id":16573039}]}]}
{"op":"mcm","clk":"1010826383","pt":1580653236734,"mc":[{"id":"1.168222849","rc":[{"batb":[[0,2.82,61.23],[1,2.78,52.93],[2,2.22,20.93]],"ltp":2.68,"tv":477.29,"id":16573039}]}]}
{"op":"mcm","clk":"1010826577","pt":1580653237747,"mc":[{"id":"1.168222849","rc":[{"batl":[[0,4.2,25.65],[1,5,17.55],[2,6.6,20.3]],"ltp":3.7,"tv":9.0,"id":19613367},{"batb":[[1,2.8,11.25],[2,2.78,52.93]],"batl":[[1,3.3,21.72]],"ltp":2.68,"tv":477.29,"id":16573039},{"batl":[[0,5.5,14.71],[1,5.6,14.08],[2,5.7,13.45]],"ltp":5.2,"tv":51.1,"id":16573041}]}]}
{"op":"mcm","clk":"1010826618","pt":1580653237931,"mc":[{"id":"1.168222849","rc":[{"batb":[[0,4.8,61.45]],"batl":[[1,5.6,8.4]],"ltp":5.4,"tv":3.29,"id":19613369},{"batb":[[0,3.85,14.28],[1,3.8,13.22],[2,3.75,57.33]],"batl":[[1,4.5,11.76],[2,5,17.55]],"ltp":3.7,"tv":9.0,"id":19613367},{"batl":[[0,2.98,32.02]],"ltp":2.68,"tv":477.29,"id":16573039},{"batl":[[0,5.2,9.24],[1,5.5,14.71],[2,5.6,14.08]],"ltp":5.2,"tv":51.1,"id":16573041}]}]}
{"op":"mcm","clk":"1010829271","pt":1580653251139,"mc":[{"id":"1.168222849","rc":[{"batb":[[1,3.4,17.07],[2,1.01,0.51]],"batl":[[0,4.5,11.76],[1,5,17.55],[2,5,0]],"ltp":3.7,"tv":9.0,"id":19613367},{"batb":[[0,2.66,25.21],[1,2.5,15.19],[2,1.01,0.51]],"batl":[[0,2.98,21]],"ltp":2.68,"tv":477.29,"id":16573039},{"batb":[[1,4.7,33.03]],"batl":[[1,5.6,14.08],[2,5.6,0]],"ltp":5.2,"tv":51.1,"id":16573041}]}]}
{"op":"mcm","clk":"1010829694","pt":1580653252992,"mc":[{"id":"1.168222849","rc":[{"batb":[[0,4.8,50.53]],"batl":[[1,5.6,0]],"ltp":5.4,"tv":3.29,"id":19613369},{"batb":[[0,3.4,17.07],[1,1.01,0.51],[2,1.01,0]],"batl":[[0,5,17.55],[1,5,0]],"ltp":3.7,"tv":9.0,"id":19613367},{"batb":[[0,2.5,15.19],[1,1.01,0.51],[2,1.01,0]],"batl":[[0,3.3,21.72],[1,3.3,0]],"ltp":2.68,"tv":477.29,"id":16573039},{"batl":[[0,5.6,14.08],[1,5.6,0]],"ltp":5.2,"tv":51.1,"id":16573041}]}]}
{"op":"mcm","clk":"1010830052","pt":1580653254351,"mc":[{"id":"1.168222849","rc":[{"batl":[[0,5.2,15.89]],"ltp":5.4,"tv":3.29,"id":19613369},{"batb":[[0,3.45,51.68],[1,3.4,56.92],[2,1.01,0.51]],"ltp":3.7,"tv":9.0,"id":19613367},{"batb":[[0,2.54,44.22],[1,2.5,70.16],[2,2.48,15.26]],"ltp":2.68,"tv":477.29,"id":16573039},{"batb":[[0,4.7,48.85],[1,4.6,38.7],[2,1.01,0.51]],"ltp":5.2,"tv":51.1,"id":16573041}]}]}
{"op":"mcm","clk":"1010830450","pt":1580653255757,"mc":[{"id":"1.168222849","rc":[{"batb":[[0,2.48,15.26],[1,1.01,0.51],[2,2.48,0]],"ltp":2.68,"tv":477.29,"id":16573039}]}]}
{"op":"mcm","clk":"1010831128","pt":1580653258726,"mc":[{"id":"1.168222849","rc":[{"batb":[[0,3.05,52.58],[1,3,54.33],[2,2.48,15.26]],"ltp":2.68,"tv":477.29,"id":16573039}]}]}
{"op":"mcm","clk":"1010831340","pt":1580653259583,"mc":[{"id":"1.168222849","rc":[{"batb":[[2,3,23.29]],"batl":[[0,3.75,16.44],[1,4.2,13.22]],"ltp":3.7,"tv":9.0,"id":19613367},{"batb":[[1,3,76.99],[2,2.82,10.94]],"batl":[[1,3.8,15.58]],"ltp":2.68,"tv":477.29,"id":16573039},{"batl":[[0,5.4,14.95]],"ltp":5.2,"tv":51.1,"id":16573041}]}]}
{"op":"mcm","clk":"1010831526","pt":1580653260514,"mc":[{"id":"1.168222849","rc":[{"batb":[[1,4.7,47.64]],"batl":[[1,5.5,9.24]],"ltp":5.4,"tv":3.29,"id":19613369},{"batb":[[0,3.55,15.96],[1,3.45,51.68],[2,3.4,56.92]],"batl":[[1,4.1,13.44],[2,4.2,13.22]],"ltp":3.7,"tv":9.0,"id":19613367},{"batb":[[2,2.84,22.69]],"batl":[[0,3.25,18.48],[1,3.3,21.72],[2,3.8,15.58]],"ltp":2.68,"tv":477.29,"id":16573039},{"batb":[[2,4.4,11.76]],"batl":[[0,5.1,10.08],[1,5.4,14.95]],"ltp":5.2,"tv":51.1,"id":16573041}]}]}
{"op":"mcm","clk":"1010833678","pt":1580653270608,"mc":[{"id":"1.168222849","rc":[{"batb":[[0,4.8,35.45],[1,4.7,10.92]],"ltp":5.4,"tv":3.29,"id":19613369},{"batb":[[1,3.45,38.81],[2,3.4,17.07]],"ltp":3.7,"tv":9.0,"id":19613367},{"batb":[[0,3.05,33.83],[2,2.82,10.94]],"ltp":2.68,"tv":477.29,"id":16573039},{"batb":[[0,4.7,15.82]],"ltp":5.2,"tv":51.1,"id":16573041}]}]}
{"op":"mcm","clk":"1010834294","pt":1580653273611,"mc":[{"id":"1.168222849","rc":[{"batb":[[0,4.9,26.93],[1,4.8,35.45],[2,4.7,10.92]],"ltp":5.4,"tv":3.29,"id":19613369},{"batb":[[1,3.5,29.74],[2,3.45,38.81]],"ltp":3.7,"tv":9.0,"id":19613367},{"batb":[[2,2.86,21.85]],"ltp":2.68,"tv":477.29,"id":16573039},{"batb":[[1,4.6,55.52],[2,4.5,40.31]],"ltp":5.2,"tv":51.1,"id":16573041}]}]}
{"op":"mcm","clk":"1010838820","pt":1580653294594,"mc":[{"id":"1.168222849","rc":[{"batb":[[1,3,23.29],[2,1.01,0.51]],"batl":[[0,4.1,13.44],[1,4.2,13.22],[2,4.2,0]],"ltp":3.7,"tv":9.0,"id":19613367},{"batb":[[0,2.86,21.85],[1,2.82,10.94],[2,1.01,0.51]],"batl":[[1,3.8,15.58],[2,3.8,0]],"ltp":2.68,"tv":477.29,"id":16573039},{"batb":[[1,4.6,38.82]],"ltp":5.2,"tv":51.1,"id":16573041}]}]}
{"op":"mcm","clk":"1010839032","pt":1580653295652,"mc":[{"id":"1.168222849","rc":[{"batb":[[2,4.5,16.84]],"batl":[[1,5.5,0]],"ltp":5.4,"tv":3.29,"id":19613369},{"batb":[[0,3,23.29],[1,1.01,0.51],[2,1.01,0]],"batl":[[0,4.2,13.22],[1,4.2,0]],"ltp":3.7,"tv":9.0,"id":19613367},{"batb":[[0,2.82,10.94],[1,1.01,0.51],[2,1.01,0]],"batl":[[0,3.8,15.58],[1,3.8,0]],"ltp":2.68,"tv":477.29,"id":16573039},{"batl":[[0,5.4,14.95],[1,5.4,0]],"ltp":5.2,"tv":51.1,"id":16573041}]}]}
{"op":"mcm","clk":"1010839460","pt":1580653297484,"mc":[{"id":"1.168222849","rc":[{"batb":[[2,4.6,16.6]],"batl":[[0,5.3,15.74]],"ltp":5.4,"tv":3.29,"id":19613369},{"batb":[[0,3.05,66.14],[1,3,77.43],[2,1.01,0.51]],"batl":[[0,4.2,12.98]],"ltp":3.7,"tv":9.0,"id":19613367},{"batb":[[0,2.82,57.33],[1,2.8,11.09],[2,2.78,52.8]],"ltp":2.68,"tv":477.29,"id":16573039},{"batb":[[0,4.6,55.42],[1,4.5,40.31],[2,1.01,0.51]],"ltp":5.2,"tv":51.1,"id":16573041}]}]}
{"op":"mcm","clk":"1010839699","pt":1580653298460,"mc":[{"id":"1.168222849","rc":[{"batb":[[0,3,22.98],[1,1.01,0.51],[2,1.01,0]],"ltp":3.7,"tv":9.0,"id":19613367},{"batb":[[1,1.01,0.51],[2,1.01,0]],"ltp":5.2,"tv":51.1,"id":16573041}]}]}
{"op":"mcm","clk":"1010840272","pt":1580653301262,"mc":[{"id":"1.168222849","rc":[{"batb":[[0,3.8,38.18],[1,3.75,31.7],[2,3,22.98]],"ltp":3.7,"tv":9.0,"id":19613367},{"batb":[[0,4.7,26.34],[1,4.6,55.42],[2,1.01,0.51]],"ltp":5.2,"tv":51.1,"id":16573041}]}]}
{"op":"mcm","clk":"1010840477","pt":1580653302195,"mc":[{"id":"1.168222849","rc":[{"batb":[[2,4.7,10.92]],"batl":[[1,5.4,9.24]],"ltp":5.4,"tv":3.29,"id":19613369},{"batb":[[1,3.75,60.2],[2,3.35,17.94]],"batl":[[1,4.3,12.6],[2,4.7,20.38]],"ltp":3.7,"tv":9.0,"id":19613367},{"batl":[[0,3,10.94],[1,3.05,20.16],[2,3.4,20.54]],"ltp":2.68,"tv":477.29,"id":16573039},{"batb":[[0,4.7,42.47],[1,4.6,38.82],[2,4.4,11.76]],"batl":[[0,5.2,9.24],[1,5.4,14.95]],"ltp":5.2,"tv":51.1,"id":16573041}]}]}
{"op":"mcm","clk":"1010843515","pt":1580653315670,"mc":[{"id":"1.168222849","rc":[{"batb":[[0,3.75,15.12],[1,3.35,17.94],[2,1.01,0.51]],"batl":[[0,4.3,12.6],[1,4.7,20.38],[2,4.7,0]],"ltp":3.7,"tv":9.0,"id":19613367},{"batb":[[0,2.76,23.53],[1,2.62,13.22],[2,1.01,0.51]],"batl":[[0,3.05,20.16],[1,3.4,20.54],[2,3.4,0]],"ltp":2.68,"tv":477.29,"id":16573039},{"batb":[[0,4.7,16.13]],"ltp":5.2,"tv":51.1,"id":16573041}]}]}
{"op":"mcm","clk":"1010843825","pt":1580653317176,"mc":[{"id":"1.168222849","rc":[{"batb":[[2,4.6,16.6]],"batl":[[1,5.4,0]],"ltp":5.4,"tv":3.29,"id":19613369},{"batb":[[0,3.35,17.94],[1,1.01,0.51],[2,1.01,0]],"batl":[[0,4.7,20.38],[1,4.7,0]],"ltp":3.7,"tv":9.0,"id":19613367},{"batb":[[0,2.62,13.22],[1,1.01,0.51],[2,1.01,0]],"batl":[[0,3.4,20.54],[1,3.4,0]],"ltp":2.68,"tv":477.29,"id":16573039},{"batb":[[2,1.01,0.51]],"batl":[[0,5.4,14.95],[1,5.4,0]],"ltp":5.2,"tv":51.1,"id":16573041}]}]}
{"op":"mcm","clk":"1010844154","pt":1580653318593,"mc":[{"id":"1.168222849","rc":[{"batb":[[0,3.4,31.99],[1,3.35,59.61],[2,1.01,0.51]],"ltp":3.7,"tv":9.0,"id":19613367},{"batb":[[0,2.68,43.06],[1,2.64,60.54],[2,2.62,13.22]],"batl":[[0,3.35,20.85],[1,3.4,20.54]],"ltp":2.68,"tv":477.29,"id":16573039},{"batb":[[1,4.6,53.34],[2,4.5,40.35]],"ltp":5.2,"tv":51.1,"id":16573041}]}]}
{"op":"mcm","clk":"1010844418","pt":1580653319684,"mc":[{"id":"1.168222849","rc":[{"batb":[[2,4.6,16.44]],"batl":[[0,5.3,15.42]],"ltp":5.4,"tv":3.29,"id":19613369},{"batb":[[0,3.35,17.7],[1,1.01,0.51],[2,1.01,0]],"batl":[[0,4.7,20.06]],"ltp":3.7,"tv":9.0,"id":19613367},{"batb":[[0,2.6,13.45],[1,1.01,0.51],[2,2.62,0]],"batl":[[1,3.4,0]],"ltp":2.68,"tv":477.29,"id":16573039},{"batb":[[1,4.6,38.83],[2,1.01,0.51]],"ltp":5.2,"tv":51.1,"id":16573041}]}]}
{"op":"mcm","clk":"1010845028","pt":1580653322598,"mc":[{"id":"1.168222849","rc":[{"batb":[[0,3.7,45.62],[1,3.65,33.75],[2,3.35,17.7]],"ltp":3.7,"tv":9.0,"id":19613367},{"batb":[[0,2.88,49.7],[1,2.84,50.02],[2,2.6,13.45]],"ltp":2.68,"tv":477.29,"id":16573039},{"batb":[[0,4.7,39.98]],"ltp":5.2,"tv":51.1,"id":16573041}]}]}
{"op":"mcm","clk":"1010845859","pt":1580653326571,"mc":[{"id":"1.168222849","rc":[{"batb":[[0,3.35,17.7],[1,1.01,0.51],[2,3.35,0]],"ltp":3.7,"tv":9.0,"id":19613367},{"batb":[[0,2.6,13.45],[1,1.01,0.51],[2,2.6,0]],"ltp":2.68,"tv":477.29,"id":16573039},{"batb":[[0,4.7,16.13]],"ltp":5.2,"tv":51.1,"id":16573041}]}]}
{"op":"mcm","clk":"1010846333","pt":1580653329084,"mc":[{"id":"1.168222849","rc":[{"batb":[[0,3.4,31.99],[1,3.35,59.37],[2,1.01,0.51]],"ltp":3.7,"tv":9.0,"id":19613367},{"batb":[[0,2.68,43.06],[1,2.64,60.54],[2,2.6,13.45]],"ltp":2.68,"tv":477.29,"id":16573039},{"batb":[[1,4.6,53.34],[2,4.5,40.35]],"ltp":5.2,"tv":51.1,"id":16573041}]}]}
{"op":"mcm","clk":"1010847086","pt":1580653332714,"mc":[{"id":"1.168222849","rc":[{"batb":[[0,3.35,17.7],[1,1.01,0.51],[2,1.01,0]],"ltp":3.7,"tv":9.0,"id":19613367},{"batb":[[1,4.6,38.7],[2,1.01,0.51]],"ltp":5.2,"tv":51.1,"id":16573041}]}]}
{"op":"mcm","clk":"1010847719","pt":1580653335717,"mc":[{"id":"1.168222849","rc":[{"batb":[[0,4.1,34.54],[1,4,53.79],[2,3.35,17.7]],"ltp":3.7,"tv":9.0,"id":19613367},{"batb":[[0,4.7,49.98]],"ltp":5.2,"tv":51.1,"id":16573041}]}]}
{"op":"mcm","clk":"1010847894","pt":1580653336608,"mc":[{"id":"1.168222849","rc":[{"batb":[[2,4.7,10.92]],"batl":[[1,5.5,9.24]],"ltp":5.4,"tv":3.29,"id":19613369},{"batb":[[0,4.1,55.71],[1,4,67.23],[2,3.75,13.45]],"batl":[[0,4.6,10.92],[1,4.7,20.06],[2,5.1,16.76]],"ltp":3.7,"tv":9.0,"id":19613367},{"batb":[[2,2.62,25.21]],"batl":[[0,2.78,13.22],[1,2.94,21],[2,3,10.78]],"ltp":2.68,"tv":477.29,"id":16573039},{"batb":[[0,4.7,49.74],[2,4.4,11.76]],"batl":[[0,5.2,9.24],[1,5.4,14.79]],"ltp":5.2,"tv":51.1,"id":16573041}]}]}
{"op":"mcm","clk":"1010851253","pt":1580653353334,"mc":[{"id":"1.168222849","rc":[{"batb":[[0,4.8,35.45],[1,4.6,16.44],[2,1.01,0.51]],"batl":[[1,5.5,0]],"ltp":5.4,"tv":3.29,"id":19613369},{"batb":[[0,3.75,13.45],[1,1.01,0.51],[2,3.75,0]],"batl":[[0,5.1,16.76],[1,4.7,0],[2,5.1,0]],"ltp":3.7,"tv":9.0,"id":19613367},{"batb":[[0,2.48,15.5],[1,1.01,0.51],[2,2.62,0]],"batl":[[0,3,10.78],[1,2.94,0],[2,3,0]],"ltp":2.68,"tv":477.29,"id":16573039},{"batb":[[2,1.01,0.51]],"batl":[[0,5.4,14.79],[1,5.4,0]],"ltp":5.2,"tv":51.1,"id":16573041}]}]}
{"op":"mcm","clk":"1010851754","pt":1580653356042,"mc":[{"id":"1.168222849","rc":[{"batb":[[0,4.8,53.98],[1,4.7,36.75],[2,4.6,16.44]],"ltp":5.4,"tv":3.29,"id":19613369},{"batb":[[0,3.75,53.21],[1,3.7,32.71],[2,1.01,0.51]],"ltp":3.7,"tv":9.0,"id":19613367},{"batb":[[0,2.58,47.7],[1,2.54,67.04],[2,2.48,15.5]],"ltp":2.68,"tv":477.29,"id":16573039}]}]}
{"op":"mcm","clk":"1010852361","pt":1580653359356,"mc":[{"id":"1.168222849","rc":[{"batb":[[0,4.8,35.32],[1,4.6,16.44],[2,1.01,0.51]],"ltp":5.4,"tv":3.29,"id":19613369},{"batb":[[0,3.75,13.45],[1,1.01,0.51],[2,1.01,0]],"ltp":3.7,"tv":9.0,"id":19613367},{"batb":[[0,2.48,15.5],[1,1.01,0.51],[2,2.48,0]],"ltp":2.68,"tv":477.29,"id":16573039}]}]}
{"op":"mcm","clk":"1010852985","pt":1580653362755,"mc":[{"id":"1.168222849","rc":[{"batb":[[0,4.9,34.94],[1,4.8,35.32],[2,4.7,10.92]],"batl":[[0,5.3,15.26],[1,5.5,9.24]],"ltp":5.4,"tv":3.29,"id":19613369},{"batb":[[0,4.5,17.55],[1,4.3,48.95],[2,4.2,60.36]],"batl":[[0,4.9,10.08],[1,5.1,16.76],[2,5.4,14.71]],"ltp":3.7,"tv":9.0,"id":19613367},{"batb":[[0,2.58,47.7],[1,2.56,26.89],[2,2.54,67.04]],"batl":[[0,2.64,15.19],[1,2.78,13.14],[2,2.86,21.85]],"ltp":2.68,"tv":477.29,"id":16573039},{"batb":[[0,4.8,15.58],[1,4.7,33.85],[2,4.6,38.7]],"batl":[[0,5.2,9.24],[1,5.5,14.79]],"ltp":5.2,"tv":51.1,"id":16573041}]}]}
{"op":"mcm","clk":"1010855225","pt":1580653374661,"mc":[{"id":"1.168222849","rc":[{"batb":[[0,4.8,35.32],[1,4.7,10.92],[2,4.6,16.44]],"ltp":5.4,"tv":3.29,"id":19613369},{"batb":[[1,4.2,12.6],[2,4.1,21.24]],"ltp":3.7,"tv":9.0,"id":19613367},{"batb":[[0,2.56,26.89],[1,2.48,15.5],[2,2.4,16.92]],"ltp":2.68,"tv":477.29,"id":16573039}]}]}
{"op":"mcm","clk":"1010855322","pt":1580653375293,"mc":[{"id":"1.168222849","rc":[{"batb":[[1,4.6,16.44],[2,1.01,0.51]],"batl":[[1,5.5,0]],"ltp":5.4,"tv":3.29,"id":19613369},{"batb":[[0,4.1,21.24],[1,1.01,0.51],[2,4.1,0]],"batl":[[0,5.4,14.71],[1,5.1,0],[2,5.4,0]],"ltp":3.7,"tv":9.0,"id":19613367},{"batb":[[0,2.4,16.92],[1,1.01,0.51],[2,2.4,0]],"batl":[[0,2.78,13.14],[1,2.78,0],[2,2.86,0]],"ltp":2.68,"tv":477.29,"id":16573039},{"batl":[[0,5.5,14.79],[1,5.5,0]],"ltp":5.2,"tv":51.1,"id":16573041}]}]}
{"op":"mcm","clk":"1010855775","pt":1580653377706,"mc":[{"id":"1.168222849","rc":[{"batb":[[0,4.8,52.78],[1,4.7,36.75],[2,4.6,16.44]],"ltp":5.4,"tv":3.29,"id":19613369},{"batb":[[0,4.1,53.62],[1,4,53.8],[2,1.01,0.51]],"ltp":3.7,"tv":9.0,"id":19613367},{"batb":[[0,2.52,61.13],[1,2.48,71.42],[2,2.4,16.92]],"ltp":2.68,"tv":477.29,"id":16573039}]}]}
{"op":"mcm","clk":"1010855865","pt":1580653378233,"mc":[{"id":"1.168222849","rc":[{"batb":[[2,4.5,16.76]],"ltp":5.4,"tv":3.29,"id":19613369}]}]}
{"op":"mcm","clk":"1010856936","pt":1580653383589,"mc":[{"id":"1.168222849","rc":[{"batb":[[0,4.8,35.32],[1,4.5,16.76],[2,1.01,0.51]],"ltp":5.4,"tv":3.29,"id":19613369},{"batb":[[0,4.1,21.24],[1,1.01,0.51],[2,1.01,0]],"ltp":3.7,"tv":9.0,"id":19613367}]}]}
{"op":"mcm","clk":"1010857416","pt":1580653386295,"mc":[{"id":"1.168222849","rc":[{"batb":[[0,4.9,43.81],[1,4.8,35.32],[2,4.5,16.76]],"ltp":5.4,"tv":3.29,"id":19613369},{"batb":[[0,4.4,63.7],[1,4.3,44.94],[2,4.1,21.24]],"ltp":3.7,"tv":9.0,"id":19613367}]}]}
{"op":"mcm","clk":"1010857641","pt":1580653387396,"mc":[{"id":"1.168222849","rc":[{"batb":[[2,4.6,16.21]],"batl":[[0,5.4,14.95]],"ltp":5.4,"tv":3.29,"id":19613369},{"batb":[[0,4.7,15.5],[1,4.4,63.7],[2,4.3,44.94]],"batl":[[1,6.6,19.2]],"ltp":3.7,"tv":9.0,"id":19613367},{"batl":[[0,2.54,16.52],[1,2.76,13.45]],"ltp":2.68,"tv":477.29,"id":16573039},{"batb":[[0,4.8,15.34],[1,4.7,49.82]],"batl":[[1,5.6,13.93]],"ltp":5.2,"tv":51.1,"id":16573041}]}]}
{"op":"mcm","clk":"1010857899","pt":1580653388590,"mc":[{"id":"1.168222849","rc":[{"batb":[[1,4.8,46.24]],"batl":[[1,5.6,8.4]],"ltp":5.4,"tv":3.29,"id":19613369},{"batl":[[0,5.1,10.08],[1,5.4,14.71],[2,6.6,19.2]],"ltp":3.7,"tv":9.0,"id":19613367},{"batb":[[2,2.46,28.57]],"batl":[[1,2.74,23.53],[2,2.76,13.45]],"ltp":2.68,"tv":477.29,"id":16573039},{"batl":[[0,5.1,10.08],[1,5.5,14.79],[2,5.6,13.93]],"ltp":5.2,"tv":51.1,"id":16573041}]}]}
{"op":"mcm","clk":"1010858296","pt":1580653390589,"mc":[{"id":"1.168222849","rc":[{"batb":[[1,4.4,75.46]],"ltp":3.7,"tv":9.0,"id":19613367}]}]}
{"op":"mcm","clk":"1010859282","pt":1580653395440,"mc":[{"id":"1.168222849","rc":[{"batl":[[0,5.3,15.26]],"ltp":5.4,"tv":3.29,"id":19613369},{"batl":[[1,5.3,15.34]],"ltp":3.7,"tv":9.0,"id":19613367},{"batl":[[0,2.58,16.13],[2,2.78,13.14]],"ltp":2.68,"tv":477.29,"id":16573039},{"batb":[[1,4.7,33.85]],"batl":[[1,5.5,14.56],[2,5.6,13.77]],"ltp":5.2,"tv":51.1,"id":16573041}]}]}
{"op":"mcm","clk":"1010860896","pt":1580653403487,"mc":[{"id":"1.168222849","rc":[{"batb":[[0,4.6,16.29]],"batl":[[2,6.4,10.31]],"ltp":3.7,"tv":9.0,"id":19613367},{"batl":[[0,2.58,15.97],[2,2.8,12.98]],"ltp":2.68,"tv":477.29,"id":16573039}]}]}
{"op":"mcm","clk":"1010864123","pt":1580653419687,"mc":[{"id":"1.168222849","rc":[{"batl":[[0,2.58,15.82]],"ltp":2.68,"tv":477.29,"id":16573039}]}]}
{"op":"mcm","clk":"1010876226","pt":1580653478753,"mc":[{"id":"1.168222849","rc":[{"batb":[[0,4.9,34.42]],"ltp":5.4,"tv":3.29,"id":19613369},{"batb":[[1,4.4,11.76],[2,4.1,21.17]],"ltp":3.7,"tv":9.0,"id":19613367},{"batb":[[0,2.46,28.57],[1,2.44,16.13],[2,2.2,21.24]],"ltp":2.68,"tv":477.29,"id":16573039},{"batb":[[1,4.6,38.7],[2,4.4,11.76]],"ltp":5.2,"tv":51.1,"id":16573041}]}]}
{"op":"mcm","clk":"1010876360","pt":1580653479364,"mc":[{"id":"1.168222849","rc":[{"batb":[[1,4.8,35.32]],"batl":[[1,5.6,0]],"ltp":5.4,"tv":3.29,"id":19613369},{"batb":[[0,4.1,21.17],[1,1.01,0.51],[2,4.1,0]],"batl":[[0,6.4,10.31],[1,5.3,0],[2,6.4,0]],"ltp":3.7,"tv":9.0,"id":19613367},{"batb":[[0,2.2,21.24],[1,1.01,0.51],[2,2.2,0]],"batl":[[0,2.8,12.98],[1,2.74,0],[2,2.8,0]],"ltp":2.68,"tv":477.29,"id":16573039},{"batb":[[2,1.01,0.51]],"batl":[[0,5.6,13.77],[1,5.5,0],[2,5.6,0]],"ltp":5.2,"tv":51.1,"id":16573041}]}]}
{"op":"mcm","clk":"1010876866","pt":1580653481667,"mc":[{"id":"1.168222849","rc":[{"batb":[[1,4,63.88],[2,3.95,27.78]],"ltp":3.7,"tv":9.0,"id":19613367},{"batb":[[0,2.28,76.57],[1,2.26,46.55],[2,2.2,21.24]],"ltp":2.68,"tv":477.29,"id":16573039},{"batb":[[1,4.6,57.5],[2,4.5,40.28]],"ltp":5.2,"tv":51.1,"id":16573041}]}]}
{"op":"mcm","clk":"1010877092","pt":1580653482654,"mc":[{"id":"1.168222849","rc":[{"batb":[[1,1.01,0.51],[2,3.95,0]],"ltp":3.7,"tv":9.0,"id":19613367},{"batb":[[0,2.2,21.24],[1,1.01,0.51],[2,2.2,0]],"ltp":2.68,"tv":477.29,"id":16573039},{"batb":[[1,4.6,38.7],[2,1.01,0.51]],"ltp":5.2,"tv":51.1,"id":16573041}]}]}
{"op":"mcm","clk":"1010877856","pt":1580653486158,"mc":[{"id":"1.168222849","rc":[{"batb":[[0,4.9,46.73]],"ltp":5.4,"tv":3.29,"id":19613369},{"batb":[[0,4.6,39.39],[1,4.5,40.83],[2,4.1,21.17]],"ltp":3.7,"tv":9.0,"id":19613367},{"batb":[[0,2.48,42.36],[1,2.44,74.77],[2,2.2,21.24]],"ltp":2.68,"tv":477.29,"id":16573039},{"batb":[[1,4.7,44.06],[2,4.6,38.7]],"ltp":5.2,"tv":51.1,"id":16573041}]}]}
{"op":"mcm","clk":"1010878102","pt":1580653487362,"mc":[{"id":"1.168222849","rc":[{"batb":[[0,4.9,34.42]],"ltp":5.4,"tv":3.29,"id":19613369},{"batb":[[0,4.1,21.17],[1,1.01,0.51],[2,4.1,0]],"ltp":3.7,"tv":9.0,"id":19613367},{"batb":[[0,2.2,21.24],[1,1.01,0.51],[2,2.2,0]],"ltp":2.68,"tv":477.29,"id":16573039},{"batb":[[1,4.6,38.7],[2,1.01,0.51]],"ltp":5.2,"tv":51.1,"id":16573041}]}]}
{"op":"mcm","clk":"1010878746","pt":1580653490376,"mc":[{"id":"1.168222849","rc":[{"batb":[[1,4,63.88],[2,3.95,27.78]],"ltp":3.7,"tv":9.0,"id":19613367},{"batb":[[0,2.28,76.57],[1,2.26,46.55],[2,2.2,21.24]],"ltp":2.68,"tv":477.29,"id":16573039},{"batb":[[1,4.6,57.5],[2,4.5,40.28]],"ltp":5.2,"tv":51.1,"id":16573041}]}]}
{"op":"mcm","clk":"1010882447","pt":1580653507693,"mc":[{"id":"1.168222849","rc":[{"batb":[[1,4.6,16.21],[2,1.01,0.51]],"ltp":5.4,"tv":3.29,"id":19613369},{"batb":[[1,1.01,0.51],[2,3.95,0]],"ltp":3.7,"tv":9.0,"id":19613367},{"batb":[[1,1.01,0.51],[2,4.5,0]],"ltp":5.2,"tv":51.1,"id":16573041}]}]}
{"op":"mcm","clk":"1010883080","pt":1580653510703,"mc":[{"id":"1.168222849","rc":[{"batb":[[0,5,24.09],[1,4.9,34.42],[2,4.6,16.21]],"ltp":5.4,"tv":3.29,"id":19613369},{"batb":[[0,5.3,38.31],[1,5.2,29.39],[2,4.1,21.17]],"ltp":3.7,"tv":9.0,"id":19613367},{"batb":[[0,4.8,46.73],[1,4.7,36.86],[2,1.01,0.51]],"ltp":5.2,"tv":51.1,"id":16573041}]}]}
{"op":"mcm","clk":"1010883249","pt":1580653511598,"mc":[{"id":"1.168222849","rc":[{"batl":[[0,5.4,14.95]],"ltp":5.4,"tv":3.29,"id":19613369},{"batb":[[0,5.5,10.78],[1,5.3,38.31],[2,5.2,29.39]],"batl":[[1,8.6,11.64]],"ltp":3.7,"tv":9.0,"id":19613367},{"batl":[[0,2.34,20.69],[1,2.54,16.6]],"ltp":2.68,"tv":477.29,"id":16573039},{"batb":[[0,5,14.32],[1,4.9,15.03],[2,4.8,31.39]],"batl":[[1,5.8,12.83]],"ltp":5.2,"tv":51.1,"id":16573041}]}]}
{"op":"mcm","clk":"1010883467","pt":1580653512594,"mc":[{"id":"1.168222849","rc":[{"batb":[[1,4.9,44.5]],"batl":[[1,5.7,8.4]],"ltp":5.4,"tv":3.29,"id":19613369},{"batl":[[0,6,8.4],[1,6.4,10.31],[2,8.6,11.64]],"ltp":3.7,"tv":9.0,"id":19613367},{"batb":[[0,2.28,109.34]],"ltp":2.68,"tv":477.29,"id":16573039},{"batl":[[0,5.2,9.24],[1,5.6,13.77],[2,5.8,12.83]],"ltp":5.2,"tv":51.1,"id":16573041}]}]}
{"op":"mcm","clk":"1010883937","pt":1580653514708,"mc":[{"id":"1.168222849","rc":[{"batl":[[1,2.5,27.73],[2,2.54,16.6]],"ltp":2.68,"tv":477.29,"id":16573039}]}]}
{"op":"mcm","clk":"1010887157","pt":1580653530684,"mc":[{"id":"1.168222849","rc":[{"batb":[[0,4.9,10.08],[1,4.6,16.21],[2,1.01,0.51]],"ltp":5.4,"tv":3.29,"id":19613369},{"batb":[[0,5.1,10.08],[1,4.7,15.34],[2,1.01,0.51]],"batl":[[1,8.6,11.64],[2,8.6,0]],"ltp":3.7,"tv":9.0,"id":19613367},{"batb":[[0,2.28,32.77],[1,2,28.48],[2,1.01,0.51]],"batl":[[0,2.5,27.73],[1,2.54,16.6],[2,2.54,0]],"ltp":2.68,"tv":477.29,"id":16573039},{"batb":[[0,4.9,15.03],[1,4.5,11.76],[2,1.01,0.51]],"batl":[[1,5.8,12.83],[2,5.8,0]],"ltp":5.2,"tv":51.1,"id":16573041}]}]}
{"op":"mcm","clk":"1010887391","pt":1580653531739,"mc":[{"id":"1.168222849","rc":[{"batb":[[0,4.6,16.21],[1,1.01,0.51],[2,1.01,0]],"batl":[[1,5.7,0]],"ltp":5.4,"tv":3.29,"id":19613369},{"batb":[[0,4.7,15.34],[1,1.01,0.51],[2,1.01,0]],"batl":[[0,8.6,11.64],[1,8.6,0]],"ltp":3.7,"tv":9.0,"id":19613367},{"batb":[[0,2,28.48],[1,1.01,0.51],[2,1.01,0]],"batl":[[0,2.54,16.6],[1,2.54,0]],"ltp":2.68,"tv":477.29,"id":16573039},{"batb":[[1,1.01,0.51],[2,1.01,0]],"batl":[[0,5.8,12.83],[1,5.8,0]],"ltp":5.2,"tv":51.1,"id":16573041}]}]}
{"op":"mcm","clk":"1010887814","pt":1580653533652,"mc":[{"id":"1.168222849","rc":[{"batl":[[0,5.3,15.26],[1,5.4,14.95]],"ltp":5.4,"tv":3.29,"id":19613369},{"batb":[[1,4.6,16.05],[2,1.01,0.51]],"batl":[[0,8.2,12.35],[1,8.6,11.64]],"ltp":3.7,"tv":9.0,"id":19613367},{"batb":[[0,2.02,27.7],[1,2,28.48],[2,1.01,0.51]],"batl":[[1,2.58,16.05]],"ltp":2.68,"tv":477.29,"id":16573039}]}]}
{"op":"mcm","clk":"1010887945","pt":1580653534261,"mc":[{"id":"1.168222849","rc":[{"batb":[[0,4.9,33.81],[1,4.6,16.21],[2,1.01,0.51]],"batl":[[1,5.4,0]],"ltp":5.4,"tv":3.29,"id":19613369},{"batb":[[0,4.6,16.05],[1,1.01,0.51],[2,1.01,0]],"batl":[[1,8.6,0]],"ltp":3.7,"tv":9.0,"id":19613367},{"batb":[[1,1.01,0.51],[2,1.01,0]],"batl":[[0,2.58,16.05],[1,2.58,0]],"ltp":2.68,"tv":477.29,"id":16573039},{"batb":[[0,4.9,14.87],[1,4.7,40.39],[2,1.01,0.51]],"ltp":5.2,"tv":51.1,"id":16573041}]}]}
{"op":"mcm","clk":"1010888145","pt":1580653535270,"mc":[{"id":"1.168222849","rc":[{"batb":[[0,5,27.23],[1,4.9,33.81],[2,4.6,16.21]],"ltp":5.4,"tv":3.29,"id":19613369},{"batb":[[0,5.6,27.32],[1,5.5,26.06],[2,4.6,16.05]],"ltp":3.7,"tv":9.0,"id":19613367},{"batb":[[0,2.24,50.27],[1,2.22,49.04],[2,2.02,27.7]],"ltp":2.68,"tv":477.29,"id":16573039},{"batb":[[1,4.8,40.07],[2,4.7,40.39]],"ltp":5.2,"tv":51.1,"id":16573041}]}]}
{"op":"mcm","clk":"1010889416","pt":1580653541583,"mc":[{"id":"1.168222849","rc":[{"batb":[[0,4.9,33.81],[1,4.6,16.21],[2,1.01,0.51]],"ltp":5.4,"tv":3.29,"id":19613369},{"batb":[[0,4.6,16.05],[1,1.01,0.51],[2,4.6,0]],"ltp":3.7,"tv":9.0,"id":19613367},{"batb":[[0,2.02,27.7],[1,1.01,0.51],[2,2.02,0]],"ltp":2.68,"tv":477.29,"id":16573039},{"batb":[[1,4.7,40.39],[2,1.01,0.51]],"ltp":5.2,"tv":51.1,"id":16573041}]}]}
{"op":"mcm","clk":"1010889856","pt":1580653543694,"mc":[{"id":"1.168222849","rc":[{"batb":[[1,1.01,0.51],[2,1.01,0]],"ltp":5.2,"tv":51.1,"id":16573041}]}]}
{"op":"mcm","clk":"1010890071","pt":1580653544690,"mc":[{"id":"1.168222849","rc":[{"batb":[[0,2.04,102.12],[1,2.02,92.36],[2,1.01,0.51]],"ltp":2.68,"tv":477.29,"id":16573039}]}]}
{"op":"mcm","clk":"1010890467","pt":1580653546637,"mc":[{"id":"1.168222849","rc":[{"batb":[[0,5,38.49],[1,4.9,33.81],[2,4.6,16.21]],"ltp":5.4,"tv":3.29,"id":19613369},{"batb":[[0,7,22.25],[1,6.8,32.22],[2,4.6,16.05]],"ltp":3.7,"tv":9.0,"id":19613367},{"batb":[[0,4.9,54.51],[1,4.8,35.02],[2,1.01,0.51]],"ltp":5.2,"tv":51.1,"id":16573041}]}]}
{"op":"mcm","clk":"1010890717","pt":1580653547739,"mc":[{"id":"1.168222849","rc":[{"batl":[[1,5.4,14.79]],"ltp":5.4,"tv":3.29,"id":19613369},{"batb":[[1,6.8,45.28],[2,5.7,19.75]],"batl":[[1,12,14.95]],"ltp":3.7,"tv":9.0,"id":19613367},{"batb":[[2,1.85,18.1]],"batl":[[0,2.14,26.91],[1,2.3,21.56]],"ltp":2.68,"tv":477.29,"id":16573039},{"batb":[[0,5.1,13.22],[1,5,14.08],[2,4.9,39.64]],"batl":[[1,6,11.88]],"ltp":5.2,"tv":51.1,"id":16573041}]}]}
{"op":"mcm","clk":"1010890829","pt":1580653548185,"mc":[{"id":"1.168222849","rc":[{"batb":[[1,4.9,43.89]],"batl":[[2,5.7,8.4]],"ltp":5.4,"tv":3.29,"id":19613369},{"batb":[[2,6.4,7.56]],"batl":[[0,7.8,5.88],[1,8.2,12.35],[2,12,14.95]],"ltp":3.7,"tv":9.0,"id":19613367},{"batb":[[0,2.04,142.45]],"batl":[[1,2.24,33.61],[2,2.3,21.56]],"ltp":2.68,"tv":477.29,"id":16573039},{"batl":[[0,5.4,9.24],[1,5.8,12.83],[2,6,11.88]],"ltp":5.2,"tv":51.1,"id":16573041}]}]}
{"op":"mcm","clk":"1010893275","pt":1580653560613,"mc":[{"id":"1.168222849","rc":[{"batb":[[0,5,25.04]],"batl":[[0,5.4,14.79],[1,5.7,8.4],[2,5.7,0]],"ltp":5.4,"tv":3.29,"id":19613369},{"batb":[[0,6.4,7.56],[1,5.7,19.75],[2,1.01,0.51]],"batl":[[1,12,14.95],[2,12,0]],"ltp":3.7,"tv":9.0,"id":19613367},{"batb":[[0,2.04,40.33],[1,1.85,18.1],[2,1.01,0.51]],"batl":[[0,2.24,33.61],[1,2.3,21.56],[2,2.3,0]],"ltp":2.68,"tv":477.29,"id":16573039},{"batb":[[0,5,13.85],[1,4.8,35.02],[2,4.6,10.92]],"batl":[[1,6,11.88],[2,6,0]],"ltp":5.2,"tv":51.1,"id":16573041}]}]}
{"op":"mcm","clk":"1010893467","pt":1580653561591,"mc":[{"id":"1.168222849","rc":[{"batb":[[1,4.9,33.81]],"batl":[[1,5.7,0]],"ltp":5.4,"tv":3.29,"id":19613369},{"batb":[[0,5.7,19.75],[1,1.01,0.51],[2,1.01,0]],"batl":[[0,12,14.95],[1,12,0]],"ltp":3.7,"tv":9.0,"id":19613367},{"batb":[[0,1.85,18.1],[1,1.01,0.51],[2,1.01,0]],"batl":[[0,2.3,21.56],[1,2.3,0]],"ltp":2.68,"tv":477.29,"id":16573039},{"batb":[[2,1.01,0.51]],"batl":[[0,6,11.88],[1,6,0]],"ltp":5.2,"tv":51.1,"id":16573041}]}]}
{"op":"mcm","clk":"1010894170","pt":1580653564802,"mc":[{"id":"1.168222849","rc":[{"batb":[[0,5,42.46]],"ltp":5.4,"tv":3.29,"id":19613369},{"batb":[[0,7.4,31.93],[1,7.2,28.24],[2,5.7,19.75]],"ltp":3.7,"tv":9.0,"id":19613367},{"batb":[[0,2,95.29],[1,1.98,68.73],[2,1.85,18.1]],"ltp":2.68,"tv":477.29,"id":16573039},{"batb":[[1,4.9,49.36],[2,4.8,35.02]],"ltp":5.2,"tv":51.1,"id":16573041}]}]}
{"op":"mcm","clk":"1010895051","pt":1580653569090,"mc":[{"id":"1.168222849","rc":[{"batb":[[0,5,25.04]],"ltp":5.4,"tv":3.29,"id":19613369},{"batb":[[0,5.7,19.75],[1,1.01,0.51],[2,5.7,0]],"ltp":3.7,"tv":9.0,"id":19613367},{"batb":[[0,1.85,18.1],[1,1.01,0.51],[2,1.85,0]],"ltp":2.68,"tv":477.29,"id":16573039},{"batb":[[1,4.8,35.02],[2,1.01,0.51]],"ltp":5.2,"tv":51.1,"id":16573041}]}]}
{"op":"mcm","clk":"1010895715","pt":1580653572110,"mc":[{"id":"1.168222849","rc":[{"batb":[[0,5.7,61.27],[1,5.6,24.81],[2,1.01,0.51]],"ltp":3.7,"tv":9.0,"id":19613367},{"batb":[[0,1.85,103.72],[1,1.83,88.13],[2,1.01,0.51]],"ltp":2.68,"tv":477.29,"id":16573039},{"batb":[[1,4.8,42.65],[2,4.7,36.7]],"ltp":5.2,"tv":51.1,"id":16573041}]}]}
{"op":"mcm","clk":"1010898760","pt":1580653587560,"mc":[{"id":"1.168222849","rc":[{"batb":[[1,4.6,16.21],[2,1.01,0.51]],"ltp":5.4,"tv":3.29,"id":19613369},{"batb":[[0,5.7,19.75],[1,1.01,0.51],[2,1.01,0]],"ltp":3.7,"tv":9.0,"id":19613367},{"batb":[[1,1.01,0.51],[2,4.7,0]],"ltp":5.2,"tv":51.1,"id":16573041}]}]}
{"op":"mcm","clk":"1010899433","pt":1580653590748,"mc":[{"id":"1.168222849","rc":[{"batb":[[0,5.1,25.45],[1,5,32.32],[2,4.6,16.21]],"ltp":5.4,"tv":3.29,"id":19613369},{"batb":[[0,10,37.48],[1,9.8,14.41],[2,5.7,19.75]],"ltp":3.7,"tv":9.0,"id":19613367},{"batb":[[0,5.1,21.27],[1,5,46.06],[2,1.01,0.51]],"ltp":5.2,"tv":51.1,"id":16573041}]}]}
{"op":"mcm","clk":"1010899619","pt":1580653591563,"mc":[{"id":"1.168222849","rc":[{"batb":[[2,4.7,15.58]],"batl":[[1,5.5,14.4]],"ltp":5.4,"tv":3.29,"id":19613369},{"batb":[[2,9.2,16.76]],"batl":[[1,16.5,8.42]],"ltp":3.7,"tv":9.0,"id":19613367},{"batb":[[2,1.75,21.87]],"batl":[[0,1.94,17.78],[1,2.06,30.06]],"ltp":2.68,"tv":477.29,"id":16573039},{"batb":[[0,5.3,12.27],[1,5.2,12.83],[2,5.1,21.27]],"batl":[[1,6.2,11.09]],"ltp":5.2,"tv":51.1,"id":16573041}]}]}
{"op":"mcm","clk":"1010899795","pt":1580653592551,"mc":[{"id":"1.168222849","rc":[{"batb":[[2,4.8,10.92]],"ltp":5.4,"tv":3.29,"id":19613369},{"batl":[[0,11.5,3.36],[1,12,14.95],[2,16.5,8.42]],"ltp":3.7,"tv":9.0,"id":19613367},{"batb":[[0,1.85,152.45]],"batl":[[1,2.02,41.17],[2,2.06,30.06]],"ltp":2.68,"tv":477.29,"id":16573039},{"batl":[[0,5.6,8.4],[1,6,11.88],[2,6.2,11.09]],"ltp":5.2,"tv":51.1,"id":16573041}]}]}
{"op":"mcm","clk":"1010900033","pt":1580653593758,"mc":[{"id":"1.168222849","rc":[{"batl":[[2,5.7,8.4]],"ltp":5.4,"tv":3.29,"id":19613369},{"batb":[[2,9.2,21.8]],"ltp":3.7,"tv":9.0,"id":19613367}]}]}
{"op":"mcm","clk":"1010904061","pt":1580653613706,"mc":[{"id":"1.168222849","rc":[{"batb":[[0,5,32.32],[1,4.6,16.21],[2,1.01,0.51]],"batl":[[0,5.5,14.4],[1,5.5,0],[2,5.7,0]],"ltp":5.4,"tv":3.29,"id":19613369},{"batb":[[0,7.8,9.76],[1,1.01,0.51],[2,9.2,0]],"batl":[[0,16.5,8.42],[1,12,0],[2,16.5,0]],"ltp":3.7,"tv":9.0,"id":19613367},{"batb":[[0,1.75,21.87],[1,1.01,0.51],[2,1.75,0]],"batl":[[0,2.06,30.06],[1,2.02,0],[2,2.06,0]],"ltp":2.68,"tv":477.29,"id":16573039},{"batb":[[0,5.2,12.83],[1,5,32.21],[2,1.01,0.51]],"batl":[[0,6.2,11.09],[1,6,0],[2,6.2,0]],"ltp":5.2,"tv":51.1,"id":16573041}]}]}
{"op":"mcm","clk":"1010904624","pt":1580653616570,"mc":[{"id":"1.168222849","rc":[{"batb":[[1,4.9,33.64],[2,4.7,15.26]],"batl":[[0,5.6,13.53]],"ltp":5.4,"tv":3.29,"id":19613369},{"batb":[[0,8.4,22.15],[1,8.2,21.51],[2,8,9.21]],"batl":[[0,17,7.95]],"ltp":3.7,"tv":9.0,"id":19613367},{"batb":[[0,1.73,101.01],[1,1.71,110.46],[2,1.01,0.51]],"batl":[[0,2.02,15.66]],"ltp":2.68,"tv":477.29,"id":16573039},{"batb":[[2,4.9,33.62]],"ltp":5.2,"tv":51.1,"id":16573041}]}]}
{"op":"mcm","clk":"1010906051","pt":1580653623677,"mc":[{"id":"1.168222849","rc":[{"batb":[[0,1.73,22.58],[1,1.01,0.51],[2,1.01,0]],"ltp":2.68,"tv":477.29,"id":16573039}]}]}
{"op":"mcm","clk":"1010906625","pt":1580653626685,"mc":[{"id":"1.168222849","rc":[{"batb":[[0,1.95,62.03],[1,1.93,74.39],[2,1.73,22.58]],"ltp":2.68,"tv":477.29,"id":16573039}]}]}
{"op":"mcm","clk":"1010906770","pt":1580653627346,"mc":[{"id":"1.168222849","rc":[{"batl":[[0,5.5,14.24]],"ltp":5.4,"tv":3.29,"id":19613369},{"batl":[[0,9.8,8.81],[1,16,8.97]],"ltp":3.7,"tv":9.0,"id":19613367},{"batb":[[1,1.93,90.28],[2,1.77,21.01]],"batl":[[1,2.2,24.86]],"ltp":2.68,"tv":477.29,"id":16573039},{"batb":[[1,5,46.45]],"batl":[[0,5.9,12.67],[1,6,11.8]],"ltp":5.2,"tv":51.1,"id":16573041}]}]}
{"op":"mcm","clk":"1010907034","pt":1580653628592,"mc":[{"id":"1.168222849","rc":[{"batl":[[1,2.1,37.81],[2,2.2,24.86]],"ltp":2.68,"tv":477.29,"id":16573039},{"batl":[[0,5.4,9.24],[1,5.9,12.67],[2,6,11.8]],"ltp":5.2,"tv":51.1,"id":16573041}]}]}
{"op":"mcm","clk":"1010907233","pt":1580653629578,"mc":[{"id":"1.168222849","rc":[{"batb":[[1,4.9,43.72]],"batl":[[1,5.7,8.4]],"ltp":5.4,"tv":3.29,"id":19613369},{"batl":[[0,9.8,13.01]],"ltp":3.7,"tv":9.0,"id":19613367},{"batb":[[1,1.93,134.81]],"ltp":2.68,"tv":477.29,"id":16573039}]}]}
{"op":"mcm","clk":"1010908062","pt":1580653633602,"mc":[{"id":"1.168222849","rc":[{"batb":[[1,4.9,10.08]],"ltp":5.4,"tv":3.29,"id":19613369},{"batb":[[1,8,9.21],[2,7.8,5.88]],"ltp":3.7,"tv":9.0,"id":19613367},{"batb":[[0,1.93,134.81],[1,1.77,21.01],[2,1.01,0.51]],"ltp":2.68,"tv":477.29,"id":16573039},{"batb":[[1,5,14.24]],"ltp":5.2,"tv":51.1,"id":16573041}]}]}
{"op":"mcm","clk":"1010908620","pt":1580653636436,"mc":[{"id":"1.168222849","rc":[{"batb":[[0,5.1,32.5],[1,5,32.32],[2,4.9,10.08]],"ltp":5.4,"tv":3.29,"id":19613369},{"batb":[[0,8.6,16.07],[1,8.4,22.15],[2,8,9.21]],"ltp":3.7,"tv":9.0,"id":19613367},{"batb":[[1,1.91,76.86],[2,1.77,21.01]],"ltp":2.68,"tv":477.29,"id":16573039},{"batb":[[2,4.9,48.68]],"ltp":5.2,"tv":51.1,"id":16573041}]}]}
{"op":"mcm","clk":"1010910832","pt":1580653647525,"mc":[{"id":"1.168222849","rc":[{"batb":[[0,5.1,21.15],[2,4.7,15.26]],"batl":[[1,5.7,0]],"ltp":5.4,"tv":3.29,"id":19613369},{"batb":[[0,6.4,15.34],[1,1.01,0.51],[2,8,0]],"batl":[[0,16,8.97],[1,16,0]],"ltp":3.7,"tv":9.0,"id":19613367},{"batb":[[0,1.77,21.01],[1,1.01,0.51],[2,1.77,0]],"batl":[[0,2.2,24.86],[1,2.1,0],[2,2.2,0]],"ltp":2.68,"tv":477.29,"id":16573039},{"batb":[[0,5,14.24],[1,4.8,34.68],[2,1.01,0.51]],"batl":[[0,6,11.8],[1,5.9,0],[2,6,0]],"ltp":5.2,"tv":51.1,"id":16573041}]}]}
{"op":"mcm","clk":"1010911458","pt":1580653650724,"mc":[{"id":"1.168222849","rc":[{"batb":[[2,4.8,14.79]],"batl":[[0,5.6,13.61]],"ltp":5.4,"tv":3.29,"id":19613369},{"batb":[[0,6.6,34.23],[1,6.4,51.78],[2,1.01,0.51]],"batl":[[0,16,8.58]],"ltp":3.7,"tv":9.0,"id":19613367},{"batb":[[0,1.75,21.56],[1,1.74,75.23],[2,1.72,108.28]],"batl":[[0,2.16,25.57]],"ltp":2.68,"tv":477.29,"id":16573039},{"batb":[[0,4.9,14.56],[1,4.8,44.11],[2,4.7,36.45]],"ltp":5.2,"tv":51.1,"id":16573041}]}]}
{"op":"mcm","clk":"1010912480","pt":1580653655735,"mc":[{"id":"1.168222849","rc":[{"batb":[[0,6.4,14.71],[1,1.01,0.51],[2,1.01,0]],"ltp":3.7,"tv":9.0,"id":19613367},{"batb":[[1,1.01,0.51],[2,1.72,0]],"ltp":2.68,"tv":477.29,"id":16573039},{"batb":[[1,1.01,0.51],[2,4.7,0]],"ltp":5.2,"tv":51.1,"id":16573041}]}]}
{"op":"mcm","clk":"1010913103","pt":1580653658654,"mc":[{"id":"1.168222849","rc":[{"batb":[[0,5.1,40.7]],"ltp":5.4,"tv":3.29,"id":19613369},{"batb":[[0,9.4,17.35],[1,9.2,17.2],[2,6.4,14.71]],"ltp":3.7,"tv":9.0,"id":19613367},{"batb":[[0,1.89,74.01],[1,1.87,82.19],[2,1.75,21.56]],"ltp":2.68,"tv":477.29,"id":16573039},{"batb":[[0,5,24.4],[1,4.9,48],[2,1.01,0.51]],"ltp":5.2,"tv":51.1,"id":16573041}]}]}
{"op":"mcm","clk":"1010913472","pt":1580653660562,"mc":[{"id":"1.168222849","rc":[{"batb":[[0,5.1,21.15]],"ltp":5.4,"tv":3.29,"id":19613369},{"batb":[[0,6.4,14.71],[1,1.01,0.51],[2,6.4,0]],"ltp":3.7,"tv":9.0,"id":19613367},{"batb":[[0,1.75,21.56],[1,1.01,0.51],[2,1.75,0]],"ltp":2.68,"tv":477.29,"id":16573039},{"batb":[[0,4.9,14.56],[1,1.01,0.51],[2,1.01,0]],"ltp":5.2,"tv":51.1,"id":16573041}]}]}
{"op":"mcm","clk":"1010913899","pt":1580653662871,"mc":[{"id":"1.168222849","rc":[{"batb":[[0,6.6,34.23],[1,6.4,51.78],[2,1.01,0.51]],"ltp":3.7,"tv":9.0,"id":19613367},{"batb":[[1,1.74,75.23],[2,1.72,108.28]],"ltp":2.68,"tv":477.29,"id":16573039},{"batb":[[1,4.8,44.11],[2,4.7,36.45]],"ltp":5.2,"tv":51.1,"id":16573041}]}]}
{"op":"mcm","clk":"1010914922","pt":1580653668365,"mc":[{"id":"1.168222849","rc":[{"batb":[[1,1.01,0.51],[2,1.72,0]],"ltp":2.68,"tv":477.29,"id":16573039}]}]}
{"op":"mcm","clk":"1010915549","pt":1580653671660,"mc":[{"id":"1.168222849","rc":[{"batl":[[0,5.5,14.01],[1,5.6,13.61]],"ltp":5.4,"tv":3.29,"id":19613369},{"batb":[[2,5,13.85]],"batl":[[0,7.8,13.85],[1,15.5,9.44],[2,16,8.58]],"ltp":3.7,"tv":9.0,"id":19613367},{"batb":[[0,2.08,95.37],[1,2.06,60.92],[2,2.04,26.28]],"batl":[[1,2.46,18.02]],"ltp":2.68,"tv":477.29,"id":16573039},{"batb":[[1,4.8,59.85]],"batl":[[0,5.6,13.93],[1,5.9,12.35],[2,6,11.8]],"ltp":5.2,"tv":51.1,"id":16573041}]}]}
{"op":"mcm","clk":"1010915664","pt":1580653672244,"mc":[{"id":"1.168222849","rc":[{"batb":[[2,4.9,10.08]],"batl":[[1,5.7,8.4]],"ltp":5.4,"tv":3.29,"id":19613369},{"batb":[[1,6.4,59.35]],"batl":[[0,7.6,5.88],[1,7.8,13.85],[2,15.5,9.44]],"ltp":3.7,"tv":9.0,"id":19613367},{"batb":[[1,2.06,100.41]],"batl":[[1,2.26,32.77],[2,2.46,18.02]],"ltp":2.68,"tv":477.29,"id":16573039},{"batl":[[0,5.3,9.24],[1,5.6,13.93],[2,5.9,12.35]],"ltp":5.2,"tv":51.1,"id":16573041}]}]}
{"op":"mcm","clk":"1010916515","pt":1580653676684,"mc":[{"id":"1.168222849","rc":[{"batl":[[1,5.7,0]],"ltp":5.4,"tv":3.29,"id":19613369},{"batb":[[1,6.4,22.28]],"ltp":3.7,"tv":9.0,"id":19613367},{"batb":[[0,2.08,52.29]],"ltp":2.68,"tv":477.29,"id":16573039},{"batb":[[1,4.8,47.6]],"ltp":5.2,"tv":51.1,"id":16573041}]}]}
{"op":"mcm","clk":"1010917041","pt":1580653679449,"mc":[{"id":"1.168222849","rc":[{"batb":[[0,5.1,44.89]],"batl":[[1,5.8,8.4]],"ltp":5.4,"tv":3.29,"id":19613369},{"batb":[[0,6.8,15.61],[1,6.6,34.23],[2,6.4,22.28]],"ltp":3.7,"tv":9.0,"id":19613367}]}]}
{"op":"mcm","clk":"1010917265","pt":1580653680539,"mc":[{"id":"1.168222849","rc":[{"batb":[[0,5.1,31.91],[1,4.9,10.08],[2,4.8,14.79]],"ltp":5.4,"tv":3.29,"id":19613369},{"batb":[[0,2.06,100.41],[1,2.04,26.28],[2,1.78,20.3]],"ltp":2.68,"tv":477.29,"id":16573039},{"batb":[[1,4.8,15.74]],"ltp":5.2,"tv":51.1,"id":16573041}]}]}
{"op":"mcm","clk":"1010917738","pt":1580653682758,"mc":[{"id":"1.168222849","rc":[{"batb":[[0,5.2,36.2],[1,5.1,31.91],[2,4.9,10.08]],"ltp":5.4,"tv":3.29,"id":19613369},{"batb":[[0,6.8,32.69]],"ltp":3.7,"tv":9.0,"id":19613367},{"batb":[[1,2.04,88.88]],"ltp":2.68,"tv":477.29,"id":16573039},{"batb":[[2,4.7,56.76]],"ltp":5.2,"tv":51.1,"id":16573041}]}]}
{"op":"mcm","clk":"1010919487","pt":1580653691382,"mc":[{"id":"1.168222849","rc":[{"batb":[[0,5.2,28.38],[2,4.8,14.79]],"batl":[[1,5.8,0]],"ltp":5.4,"tv":3.29,"id":19613369},{"batb":[[0,5,13.85],[1,1.01,0.51],[2,6.4,0]],"batl":[[0,15.5,9.44],[1,7.8,0],[2,15.5,0]],"ltp":3.7,"tv":9.0,"id":19613367},{"batb":[[0,1.78,20.3],[1,1.01,0.51],[2,1.78,0]],"batl":[[0,2.46,18.02],[1,2.26,0],[2,2.46,0]],"ltp":2.68,"tv":477.29,"id":16573039},{"batb":[[0,4.8,15.74],[1,4.6,37.65],[2,1.01,0.51]],"batl":[[0,5.9,12.35],[1,5.6,0],[2,5.9,0]],"ltp":5.2,"tv":51.1,"id":16573041}]}]}
{"op":"mcm","clk":"1010920286","pt":1580653695065,"mc":[{"id":"1.168222849","rc":[{"batb":[[2,4.9,14.4]],"batl":[[0,5.6,13.61]],"ltp":5.4,"tv":3.29,"id":19613369},{"batb":[[0,5,13.69]],"ltp":3.7,"tv":9.0,"id":19613367},{"batl":[[0,2.44,18.41]],"ltp":2.68,"tv":477.29,"id":16573039},{"batb":[[0,4.7,16.05],[1,1.01,0.51],[2,1.01,0]],"ltp":5.2,"tv":51.1,"id":16573041}]}]}
{"op":"mcm","clk":"1010921723","pt":1580653701803,"mc":[{"id":"1.168222849","rc":[{"batb":[[0,5,53.26],[1,4.9,34.89],[2,1.01,0.51]],"ltp":3.7,"tv":9.0,"id":19613367},{"batb":[[1,1.74,88.08],[2,1.72,108.16]],"ltp":2.68,"tv":477.29,"id":16573039},{"batb":[[1,4.6,35.19],[2,4.5,40.01]],"ltp":5.2,"tv":51.1,"id":16573041}]}]}
{"op":"mcm","clk":"1010924487","pt":1580653714727,"mc":[{"id":"1.168222849","rc":[{"batb":[[0,5,13.69],[1,1.01,0.51],[2,1.01,0]],"ltp":3.7,"tv":9.0,"id":19613367},{"batb":[[1,1.01,0.51],[2,4.5,0]],"ltp":5.2,"tv":51.1,"id":16573041}]}]}
{"op":"mcm","clk":"1010925064","pt":1580653717654,"mc":[{"id":"1.168222849","rc":[{"batb":[[0,5.2,49.43]],"ltp":5.4,"tv":3.29,"id":19613369},{"batb":[[0,15,16.73],[1,14.5,16.6],[2,5,13.69]],"ltp":3.7,"tv":9.0,"id":19613367},{"batb":[[0,5,39.65],[1,4.9,32.78],[2,4.7,16.05]],"ltp":5.2,"tv":51.1,"id":16573041}]}]}
{"op":"mcm","clk":"1010925288","pt":1580653718733,"mc":[{"id":"1.168222849","rc":[{"batb":[[0,5.2,58.67],[2,4.8,14.95]],"batl":[[1,5.7,13.38]],"ltp":5.4,"tv":3.29,"id":19613369},{"batb":[[0,15,14.24],[2,11.5,10.23]],"batl":[[1,22,5.11]],"ltp":3.7,"tv":9.0,"id":19613367},{"batl":[[0,1.81,42.01],[1,1.85,20.3],[2,2,16.13]],"ltp":2.68,"tv":477.29,"id":16573039},{"batb":[[0,5.2,12.9],[1,5,53.66],[2,4.9,32.78]],"batl":[[0,5.7,8.4],[1,5.9,12.35],[2,6,11.8]],"ltp":5.2,"tv":51.1,"id":16573041}]}]}
{"op":"mcm","clk":"1010927124","pt":1580653727647,"mc":[{"id":"1.168222849","rc":[{"batb":[[0,5.2,40.04],[1,4.8,14.95],[2,1.01,0.51]],"batl":[[2,6,8.4]],"ltp":5.4,"tv":3.29,"id":19613369}]}]}
{"op":"mcm","clk":"1010927755","pt":1580653730363,"mc":[{"id":"1.168222849","rc":[{"batb":[[0,5.3,21.47],[1,5.2,40.04],[2,4.8,14.95]],"ltp":5.4,"tv":3.29,"id":19613369}]}]}
{"op":"mcm","clk":"1010928604","pt":1580653734251,"mc":[{"id":"1.168222849","rc":[{"batb":[[1,5.2,30.8]],"ltp":5.4,"tv":3.29,"id":19613369}]}]}
{"op":"mcm","clk":"1010929376","pt":1580653737473,"mc":[{"id":"1.168222849","rc":[{"batb":[[2,5.1,10.08]],"ltp":5.4,"tv":3.29,"id":19613369}]}]}
{"op":"mcm","clk":"1010930028","pt":1580653739653,"mc":[{"id":"1.168222849","rc":[{"batb":[[1,11.5,10.23],[2,8.6,7.87]],"ltp":3.7,"tv":9.0,"id":19613367},{"batb":[[1,1.7,24.08],[2,1.68,61.33]],"ltp":2.68,"tv":477.29,"id":16573039}]}]}
{"op":"mcm","clk":"1010930497","pt":1580653741597,"mc":[{"id":"1.168222849","rc":[{"batb":[[0,15,15.96]],"ltp":3.7,"tv":9.0,"id":19613367}]}]}
{"op":"mcm","clk":"1010930848","pt":1580653742888,"mc":[{"id":"1.168222849","rc":[{"batb":[[0,5.3,33.29]],"ltp":5.4,"tv":3.29,"id":19613369},{"trd":[[15.5,18.22]],"batl":[[0,22,5.45],[1,22,0]],"ltp":15.5,"tv":27.22,"id":19613367},{"batb":[[1,1.73,106.64],[2,1.71,110.62]],"ltp":2.68,"tv":477.29,"id":16573039}],"tv":558.91}]}
{"op":"mcm","clk":"1010931544","pt":1580653746096,"mc":[{"id":"1.168222849","rc":[{"trd":[[15.5,18.88]],"batb":[[0,15.5,7.03],[1,15,15.96],[2,11.5,10.23]],"batl":[[0,22,5.11]],"ltp":15.5,"tv":27.88,"id":19613367}],"tv":559.57}]}
{"op":"mcm","clk":"1010932448","pt":1580653749541,"mc":[{"id":"1.168222849","rc":[{"batl":[[0,21,78.91],[1,22,5.11]],"ltp":15.5,"tv":27.88,"id":19613367}]}]}
{"op":"mcm","clk":"1010932620","pt":1580653750251,"mc":[{"id":"1.168222849","rc":[{"batb":[[0,5.2,30.8],[1,5.1,10.08],[2,4.8,14.95]],"batl":[[0,5.7,13.38],[1,6,8.4],[2,6,0]],"ltp":5.4,"tv":3.29,"id":19613369},{"batb":[[0,8.6,7.87],[1,1.01,0.51],[2,11.5,0]],"batl":[[0,22,5.11],[1,22,0]],"ltp":15.5,"tv":27.88,"id":19613367},{"batb":[[0,1.7,24.08],[1,1.68,61.33],[2,1.01,0.51]],"batl":[[1,2,16.13],[2,2,0]],"ltp":2.68,"tv":477.29,"id":16573039},{"batb":[[0,5,14.01],[1,4.9,32.78],[2,4.8,10.92]],"batl":[[1,6,11.8],[2,6,0]],"ltp":5.2,"tv":51.1,"id":16573041}]}]}
{"op":"mcm","clk":"1010932960","pt":1580653751575,"mc":[{"id":"1.168222849","rc":[{"batb":[[1,4.8,14.95],[2,1.01,0.51]],"batl":[[1,6,0]],"ltp":5.4,"tv":3.29,"id":19613369},{"batb":[[1,1.01,0.51],[2,1.01,0]],"batl":[[0,2,16.13],[1,2,0]],"ltp":2.68,"tv":477.29,"id":16573039},{"batb":[[2,1.01,0.51]],"batl":[[0,6,11.8],[1,6,0]],"ltp":5.2,"tv":51.1,"id":16573041}]}]}
{"op":"mcm","clk":"1010933246","pt":1580653752729,"mc":[{"id":"1.168222849","rc":[{"batb":[[1,5.1,32.22],[2,4.8,14.95]],"ltp":5.4,"tv":3.29,"id":19613369},{"batb":[[0,10.5,25.51],[1,10,36.02],[2,8.6,7.87]],"ltp":15.5,"tv":27.88,"id":19613367},{"batb":[[1,1.68,66.35],[2,1.66,122.57]],"ltp":2.68,"tv":477.29,"id":16573039},{"batb":[[2,4.8,34.46]],"ltp":5.2,"tv":51.1,"id":16573041}]}]}
{"op":"mcm","clk":"1010933426","pt":1580653753456,"mc":[{"id":"1.168222849","rc":[{"batb":[[2,4.9,14.24]],"batl":[[0,5.8,12.59]],"ltp":5.4,"tv":3.29,"id":19613369},{"batb":[[2,9.8,15.42]],"batl":[[0,26,7.63]],"ltp":15.5,"tv":27.88,"id":19613367},{"batb":[[0,1.68,66.35],[1,1.67,25.65]],"batl":[[0,1.94,17.62]],"ltp":2.68,"tv":477.29,"id":16573039}]}]}
{"op":"mcm","clk":"1010934009","pt":1580653755743,"mc":[{"id":"1.168222849","rc":[{"batb":[[0,4.9,14.24],[1,1.01,0.51],[2,4.9,0]],"ltp":5.4,"tv":3.29,"id":19613369},{"batb":[[0,9.8,15.42],[1,1.01,0.51],[2,9.8,0]],"ltp":15.5,"tv":27.88,"id":19613367},{"batb":[[1,1.01,0.51],[2,4.8,0]],"ltp":5.2,"tv":51.1,"id":16573041}]}]}
{"op":"mcm","clk":"1010934654","pt":1580653758471,"mc":[{"id":"1.168222849","rc":[{"batb":[[0,5.4,21.56],[1,5.3,29.67],[2,5.2,9.24]],"batl":[[1,6.2,7.56]],"ltp":5.4,"tv":3.29,"id":19613369},{"batb":[[0,20,17.09],[1,19.5,9.08],[2,9.8,15.42]],"ltp":15.5,"tv":27.88,"id":19613367},{"batl":[[0,1.76,42.01],[1,1.94,17.62]],"ltp":2.68,"tv":477.29,"id":16573039},{"batb":[[0,5.1,24.44],[1,5,45.47],[2,4.9,10.08]],"batl":[[0,5.7,8.4],[1,6,11.8]],"ltp":5.2,"tv":51.1,"id":16573041}]}]}
{"op":"mcm","clk":"1010934905","pt":1580653759657,"mc":[{"id":"1.168222849","rc":[{"batl":[[1,6,11.96],[2,6.2,7.56]],"ltp":5.4,"tv":3.29,"id":19613369},{"batb":[[2,17,4.25]],"ltp":15.5,"tv":27.88,"id":19613367},{"batl":[[0,1.74,25.18],[1,1.76,42.01],[2,1.84,20.61]],"ltp":2.68,"tv":477.29,"id":16573039},{"batb":[[0,5.1,38.13],[1,5,31.46]],"batl":[[2,6.2,11.8]],"ltp":5.2,"tv":51.1,"id":16573041}]}]}
{"op":"mcm","clk":"1010936476","pt":1580653766688,"mc":[{"id":"1.168222849","rc":[{"batb":[[0,1.67,25.65],[1,1.66,61.79],[2,1.64,65.54]],"ltp":2.68,"tv":477.29,"id":16573039}]}]}
{"op":"mcm","clk":"1010937079","pt":1580653769405,"mc":[{"id":"1.168222849","rc":[{"batb":[[0,5.4,32.48]],"ltp":5.4,"tv":3.29,"id":19613369},{"batb":[[0,20,19.66]],"ltp":15.5,"tv":27.88,"id":19613367},{"batb":[[0,1.67,133.34]],"ltp":2.68,"tv":477.29,"id":16573039}]}]}
{"op":"mcm","clk":"1010937546","pt":1580653771498,"mc":[{"id":"1.168222849","rc":[{"batb":[[1,5.2,9.24],[2,5.1,13.14]],"ltp":5.4,"tv":3.29,"id":19613369},{"batb":[[0,20,17.64],[1,17,4.25],[2,12.5,8.81]],"ltp":15.5,"tv":27.88,"id":19613367},{"batb":[[0,1.67,97.71]],"ltp":2.68,"tv":477.29,"id":16573039},{"batb":[[0,5.1,13.69]],"ltp":5.2,"tv":51.1,"id":16573041}]}]}
{"op":"mcm","clk":"1010938328","pt":1580653774680,"mc":[{"id":"1.168222849","rc":[{"batb":[[0,5.5,23.45],[1,5.4,32.48],[2,5.2,9.24]],"ltp":5.4,"tv":3.29,"id":19613369},{"batb":[[0,21,6.48],[1,20,17.64],[2,17,4.25]],"ltp":15.5,"tv":27.88,"id":19613367},{"batb":[[1,5,47.3],[2,4.9,42.49]],"ltp":5.2,"tv":51.1,"id":16573041}]}]}
{"op":"mcm","clk":"1010938587","pt":1580653775715,"mc":[{"id":"1.168222849","rc":[{"batb":[[0,4.9,14.01],[1,1.01,0.51],[2,5.2,0]],"batl":[[0,6,11.96],[1,6,0],[2,6.2,0]],"ltp":5.4,"tv":3.29,"id":19613369},{"batb":[[0,12.5,8.81],[1,1.01,0.51],[2,17,0]],"ltp":15.5,"tv":27.88,"id":19613367},{"batb":[[0,1.61,28.8],[1,1.01,0.51],[2,1.64,0]],"batl":[[0,1.84,20.61],[1,1.76,0],[2,1.84,0]],"ltp":2.68,"tv":477.29,"id":16573039},{"batb":[[1,4.9,32.41],[2,1.01,0.51]],"batl":[[0,6.2,11.8],[1,6,0],[2,6.2,0]],"ltp":5.2,"tv":51.1,"id":16573041}]}]}
{"op":"mcm","clk":"1010939165","pt":1580653778374,"mc":[{"id":"1.168222849","rc":[{"batb":[[0,5.3,43.81],[1,5.2,31.12],[2,4.9,14.01]],"ltp":5.4,"tv":3.29,"id":19613369},{"batb":[[0,14.5,7.44],[1,14,18.73],[2,12.5,8.81]],"ltp":15.5,"tv":27.88,"id":19613367},{"batb":[[0,1.62,119.35],[1,1.61,97.93],[2,1.01,0.51]],"ltp":2.68,"tv":477.29,"id":16573039},{"batb":[[1,4.9,45.95],[2,4.8,34.04]],"ltp":5.2,"tv":51.1,"id":16573041}]}]}
{"op":"mcm","clk":"1010939292","pt":1580653779013,"mc":[{"id":"1.168222849","rc":[{"batl":[[0,5.9,12.04]],"ltp":5.4,"tv":3.29,"id":19613369},{"batb":[[2,12.5,8.66]],"ltp":15.5,"tv":27.88,"id":19613367},{"batl":[[0,6.2,11.49]],"ltp":5.2,"tv":51.1,"id":16573041}]}]}
{"op":"mcm","clk":"1010940080","pt":1580653782396,"mc":[{"id":"1.168222849","rc":[{"batb":[[0,1.61,28.8],[1,1.01,0.51],[2,1.01,0]],"ltp":2.68,"tv":477.29,"id":16573039}]}]}
{"op":"mcm","clk":"1010940834","pt":1580653785754,"mc":[{"id":"1.168222849","rc":[{"batb":[[0,1.75,99.17],[1,1.73,106.37],[2,1.61,28.8]],"ltp":2.68,"tv":477.29,"id":16573039}]}]}
{"op":"mcm","clk":"1010940996","pt":1580653786514,"mc":[{"id":"1.168222849","rc":[{"batb":[[1,5.2,40.36]],"batl":[[0,5.6,13.38],[1,5.7,13.14],[2,6.2,7.56]],"ltp":5.4,"tv":3.29,"id":19613369},{"batl":[[0,17,8.03],[1,24,4.09]],"ltp":15.5,"tv":27.88,"id":19613367},{"batb":[[0,1.77,21.09],[1,1.75,99.17],[2,1.73,106.37]],"batl":[[0,1.83,42.01],[1,1.84,20.61],[2,1.99,16.13]],"ltp":2.68,"tv":477.29,"id":16573039},{"batb":[[1,4.9,60.66],[2,4.8,44.96]],"batl":[[0,5.6,8.4],[1,5.7,13.14],[2,5.9,12.43]],"ltp":5.2,"tv":51.1,"id":16573041}]}]}
{"op":"mcm","clk":"1010941181","pt":1580653787380,"mc":[{"id":"1.168222849","rc":[{"batb":[[1,5.2,31.12],[2,5.1,10.08]],"batl":[[2,5.9,8.4]],"ltp":5.4,"tv":3.29,"id":19613369}]}]}
{"op":"mcm","clk":"1010945877","pt":1580653808527,"mc":[{"id":"1.168222849","rc":[{"batb":[[0,5.2,31.12],[1,5.1,10.08],[2,4.8,14.71]],"batl":[[0,5.7,13.14],[1,5.9,8.4],[2,5.9,0]],"ltp":5.4,"tv":3.29,"id":19613369},{"batb":[[0,9,7.47],[1,1.01,0.51],[2,12.5,0]],"batl":[[0,24,4.09],[1,24,0]],"ltp":15.5,"tv":27.88,"id":19613367},{"batb":[[0,1.7,59.65],[1,1.69,24.55],[2,1.01,0.51]],"batl":[[1,1.99,16.13],[2,1.99,0]],"ltp":2.68,"tv":477.29,"id":16573039},{"batb":[[0,4.9,14.71],[1,4.8,44.96],[2,1.01,0.51]],"batl":[[1,5.9,12.43],[2,5.9,0]],"ltp":5.2,"tv":51.1,"id":16573041}]}]}
{"op":"mcm","clk":"1010946076","pt":1580653809747,"mc":[{"id":"1.168222849","rc":[{"batb":[[1,4.8,14.71],[2,1.01,0.51]],"batl":[[1,5.9,0]],"ltp":5.4,"tv":3.29,"id":19613369},{"batb":[[0,1.69,24.55],[1,1.01,0.51],[2,1.01,0]],"batl":[[0,1.99,16.13],[1,1.99,0]],"ltp":2.68,"tv":477.29,"id":16573039},{"batb":[[1,4.8,34.04]],"batl":[[0,5.9,12.43],[1,5.9,0]],"ltp":5.2,"tv":51.1,"id":16573041}]}]}
{"op":"mcm","clk":"1010946387","pt":1580653811120,"mc":[{"id":"1.168222849","rc":[{"batb":[[0,5.2,46.16],[1,5.1,32.52],[2,4.8,14.71]],"ltp":5.4,"tv":3.29,"id":19613369},{"batb":[[0,9.4,25.79],[1,9.2,18.04],[2,9,7.47]],"ltp":15.5,"tv":27.88,"id":19613367},{"batb":[[1,1.68,96.98],[2,1.66,122.85]],"ltp":2.68,"tv":477.29,"id":16573039},{"batb":[[2,4.7,35.94]],"ltp":5.2,"tv":51.1,"id":16573041}]}]}
{"op":"mcm","clk":"1010947859","pt":1580653818622,"mc":[{"id":"1.168222849","rc":[{"batb":[[0,4.8,14.71],[1,1.01,0.51],[2,4.8,0]],"ltp":5.4,"tv":3.29,"id":19613369},{"batb":[[0,9,7.47],[1,1.01,0.51],[2,9,0]],"ltp":15.5,"tv":27.88,"id":19613367},{"batb":[[1,1.01,0.51],[2,1.66,0]],"ltp":2.68,"tv":477.29,"id":16573039},{"batb":[[1,1.01,0.51],[2,4.7,0]],"ltp":5.2,"tv":51.1,"id":16573041}]}]}
{"op":"mcm","clk":"1010948440","pt":1580653821438,"mc":[{"id":"1.168222849","rc":[{"batb":[[0,5.4,29.76],[1,5.3,30],[2,4.8,14.71]],"ltp":5.4,"tv":3.29,"id":19613369},{"batb":[[0,20,14.34],[1,19.5,9.33],[2,9,7.47]],"ltp":15.5,"tv":27.88,"id":19613367},{"batb":[[1,1.68,96.98],[2,1.66,122.85]],"ltp":2.68,"tv":477.29,"id":16573039},{"batb":[[0,5,37.51],[1,4.9,47.28],[2,1.01,0.51]],"ltp":5.2,"tv":51.1,"id":16573041}]}]}
{"op":"mcm","clk":"1010948669","pt":1580653822628,"mc":[{"id":"1.168222849","rc":[{"batb":[[2,5.1,10.08]],"batl":[[1,5.8,12.51],[2,5.9,8.4]],"ltp":5.4,"tv":3.29,"id":19613369},{"batb":[[2,16.5,4.33]],"ltp":15.5,"tv":27.88,"id":19613367},{"batb":[[2,1.66,185.86]],"batl":[[0,1.76,24.08],[1,1.78,42.01],[2,1.87,19.51]],"ltp":2.68,"tv":477.29,"id":16573039},{"batb":[[0,5.2,12.98],[1,5.1,13.77],[2,5,37.51]],"batl":[[0,5.7,8.4],[1,5.9,12.43],[2,6.2,11.72]],"ltp":5.2,"tv":51.1,"id":16573041}]}]}
{"op":"mcm","clk":"1010952895","pt":1580653844759,"mc":[{"id":"1.168222849","rc":[{"batb":[[0,5.3,23.27],[1,5.1,10.08],[2,5,13.69]],"ltp":5.4,"tv":3.29,"id":19613369},{"batb":[[0,16.5,4.33],[1,11.5,9.99],[2,1.01,0.51]],"ltp":15.5,"tv":27.88,"id":19613367},{"batb":[[1,1.66,63.01],[2,1.62,28.48]],"ltp":2.68,"tv":477.29,"id":16573039},{"batb":[[2,4.9,32.57]],"ltp":5.2,"tv":51.1,"id":16573041}]}]}
{"op":"mcm","clk":"1010953066","pt":1580653845566,"mc":[{"id":"1.168222849","rc":[{"batb":[[1,4.8,14.71],[2,1.01,0.51]],"batl":[[0,5.8,12.51],[1,5.8,0],[2,5.9,0]],"ltp":5.4,"tv":3.29,"id":19613369},{"batb":[[0,11.5,9.99],[1,1.01,0.51],[2,1.01,0]],"ltp":15.5,"tv":27.88,"id":19613367},{"batb":[[0,1.62,28.48],[1,1.01,0.51],[2,1.62,0]],"batl":[[0,1.87,19.51],[1,1.78,0],[2,1.87,0]],"ltp":2.68,"tv":477.29,"id":16573039},{"batb":[[0,5.1,13.77],[1,4.9,32.57],[2,1.01,0.51]],"batl":[[0,6.2,11.72],[1,5.9,0],[2,6.2,0]],"ltp":5.2,"tv":51.1,"id":16573041}]}]}
{"op":"mcm","clk":"1010953469","pt":1580653847715,"mc":[{"id":"1.168222849","rc":[{"batb":[[1,5.2,31.43],[2,4.8,14.71]],"ltp":5.4,"tv":3.29,"id":19613369},{"batb":[[0,13,22.75],[1,12.5,23.09],[2,11.5,9.99]],"ltp":15.5,"tv":27.88,"id":19613367},{"batb":[[0,1.63,90.75],[1,1.62,95.95],[2,1.01,0.51]],"ltp":2.68,"tv":477.29,"id":16573039},{"batb":[[2,4.8,34.26]],"ltp":5.2,"tv":51.1,"id":16573041}]}]}
{"op":"mcm","clk":"1010954108","pt":1580653851268,"mc":[{"id":"1.168222849","rc":[{"batb":[[0,1.62,28.48],[1,1.01,0.51],[2,1.01,0]],"ltp":2.68,"tv":477.29,"id":16573039}]}]}
{"op":"mcm","clk":"1010954775","pt":1580653854749,"mc":[{"id":"1.168222849","rc":[{"batb":[[2,5,10.08]],"batl":[[0,5.6,13.53],[1,5.8,20.91]],"ltp":5.4,"tv":3.29,"id":19613369},{"batb":[[0,13.5,3.36],[1,13,22.75],[2,12.5,23.09]],"batl":[[0,15.5,9.21],[1,27,7.16]],"ltp":15.5,"tv":27.88,"id":19613367},{"batb":[[0,1.8,19.91],[1,1.78,98.73],[2,1.76,100.33]],"batl":[[0,1.87,61.52],[1,2.08,28.33]],"ltp":2.68,"tv":477.29,"id":16573039},{"batb":[[2,4.8,60.53]],"batl":[[0,5.6,8.4],[1,5.7,13.14],[2,5.8,12.75]],"ltp":5.2,"tv":51.1,"id":16573041}]}]}
{"op":"mcm","clk":"1010954814","pt":1580653854930,"mc":[{"id":"1.168222849","rc":[{"batl":[[1,5.8,8.4]],"ltp":5.4,"tv":3.29,"id":19613369},{"batb":[[0,4.9,32.57],[1,4.8,60.53],[2,1.01,0.51]],"ltp":5.2,"tv":51.1,"id":16573041}]}]}
{"op":"mcm","clk":"1010957468","pt":1580653867363,"mc":[{"id":"1.168222849","rc":[{"batb":[[0,5.2,31.43],[1,5,10.08],[2,4.8,14.71]],"ltp":5.4,"tv":3.29,"id":19613369},{"batb":[[1,13,18.52]],"ltp":15.5,"tv":27.88,"id":19613367},{"batb":[[1,1.73,57.13],[2,1.69,24.31]],"ltp":2.68,"tv":477.29,"id":16573039}]}]}
{"op":"mcm","clk":"1010958069","pt":1580653870390,"mc":[{"id":"1.168222849","rc":[{"batb":[[0,5.2,43.26],[1,5.1,32.36],[2,5,10.08]],"ltp":5.4,"tv":3.29,"id":19613369},{"batb":[[1,1.79,70.28],[2,1.77,98.38]],"ltp":2.68,"tv":477.29,"id":16573039}]}]}
{"op":"mcm","clk":"1010959367","pt":1580653875958,"mc":[{"id":"1.168222849","rc":[{"batb":[[0,5.2,22.03]],"ltp":5.4,"tv":3.29,"id":19613369},{"batb":[[1,7.8,9.99],[2,1.01,0.51]],"batl":[[0,27,7.16],[1,27,0]],"ltp":15.5,"tv":27.88,"id":19613367},{"batb":[[0,1.73,57.13],[1,1.69,24.31],[2,1.01,0.51]],"batl":[[0,1.87,42.01]],"ltp":2.68,"tv":477.29,"id":16573039},{"batb":[[0,4.8,26.27],[1,1.01,0.51],[2,1.01,0]],"batl":[[1,5.8,12.75],[2,5.8,0]],"ltp":5.2,"tv":51.1,"id":16573041}]}]}
{"op":"mcm","clk":"1010959793","pt":1580653877579,"mc":[{"id":"1.168222849","rc":[{"batb":[[2,4.8,14.71]],"batl":[[1,5.8,0]],"ltp":5.4,"tv":3.29,"id":19613369},{"batb":[[0,7.8,9.99],[1,1.01,0.51],[2,1.01,0]],"ltp":15.5,"tv":27.88,"id":19613367},{"batb":[[0,1.69,24.31],[1,1.01,0.51],[2,1.01,0]],"batl":[[0,2.08,28.33],[1,2.08,0]],"ltp":2.68,"tv":477.29,"id":16573039},{"batb":[[0,4.8,15.34]],"batl":[[0,5.8,12.75],[1,5.8,0]],"ltp":5.2,"tv":51.1,"id":16573041}]}]}
{"op":"mcm","clk":"1010960025","pt":1580653878658,"mc":[{"id":"1.168222849","rc":[{"batb":[[0,7.8,47.86],[1,7.6,26.71],[2,1.01,0.51]],"ltp":15.5,"tv":27.88,"id":19613367},{"batb":[[0,1.69,108.09],[1,1.67,120.19],[2,1.01,0.51]],"ltp":2.68,"tv":477.29,"id":16573039},{"batb":[[1,4.7,54.2],[2,4.6,37.59]],"ltp":5.2,"tv":51.1,"id":16573041}]}]}
{"op":"mcm","clk":"1010960971","pt":1580653882567,"mc":[{"id":"1.168222849","rc":[{"batb":[[0,1.69,24.31],[1,1.01,0.51],[2,1.01,0]],"ltp":2.68,"tv":477.29,"id":16573039}]}]}
{"op":"mcm","clk":"1010961635","pt":1580653885564,"mc":[{"id":"1.168222849","rc":[{"batb":[[0,1.99,73.67],[1,1.97,69.79],[2,1.69,24.31]],"ltp":2.68,"tv":477.29,"id":16573039}]}]}
{"op":"mcm","clk":"1010961896","pt":1580653886696,"mc":[{"id":"1.168222849","rc":[{"batb":[[2,5,10.08]],"batl":[[0,5.5,14.4],[1,5.8,8.4]],"ltp":5.4,"tv":3.29,"id":19613369},{"batb":[[0,8.2,5.04],[1,7.8,47.86],[2,7.6,26.71]],"batl":[[0,9.4,9.52],[1,10.5,4.2],[2,15,10.15]],"ltp":15.5,"tv":27.88,"id":19613367},{"batb":[[1,1.98,29.11],[2,1.97,69.79]],"batl":[[0,2.08,66.97],[1,2.42,18.73]],"ltp":2.68,"tv":477.29,"id":16573039},{"batb":[[2,4.6,65.51]],"batl":[[0,5.3,9.24],[1,5.5,14.63],[2,5.6,13.69]],"ltp":5.2,"tv":51.1,"id":16573041}]}]}
{"op":"mcm","clk":"1010966506","pt":1580653906528,"mc":[{"id":"1.168222849","rc":[{"batb":[[2,4.8,14.71]],"ltp":5.4,"tv":3.29,"id":19613369}]}]}
{"op":"mcm","clk":"1010967167","pt":1580653909527,"mc":[{"id":"1.168222849","rc":[{"batb":[[2,4.9,10.08]],"batl":[[1,5.8,0]],"ltp":5.4,"tv":3.29,"id":19613369},{"batb":[[0,5.4,11.8],[1,1.01,0.51],[2,7.6,0]],"batl":[[0,15,10.15],[1,10.5,0],[2,15,0]],"ltp":15.5,"tv":27.88,"id":19613367},{"batb":[[0,1.91,45.37],[1,1.83,18.88],[2,1.01,0.51]],"batl":[[0,2.42,18.73],[1,2.42,0]],"ltp":2.68,"tv":477.29,"id":16573039},{"batb":[[0,4.6,17],[1,1.01,0.51],[2,4.6,0]],"batl":[[0,5.6,13.69],[1,5.5,0],[2,5.6,0]],"ltp":5.2,"tv":51.1,"id":16573041}]}]}
{"op":"mcm","clk":"1010967390","pt":1580653910529,"mc":[{"id":"1.168222849","rc":[{"batb":[[2,4.8,14.71]],"ltp":5.4,"tv":3.29,"id":19613369},{"batb":[[0,1.83,18.88],[1,1.01,0.51],[2,1.01,0]],"ltp":2.68,"tv":477.29,"id":16573039}]}]}
{"op":"mcm","clk":"1010967771","pt":1580653912221,"mc":[{"id":"1.168222849","rc":[{"batb":[[1,4.8,47.85],[2,4.7,39.08]],"ltp":15.5,"tv":27.88,"id":19613367},{"batb":[[1,1.81,58.33],[2,1.79,94.74]],"ltp":2.68,"tv":477.29,"id":16573039},{"batb":[[1,4.5,52.07],[2,4.4,41.87]],"ltp":5.2,"tv":51.1,"id":16573041}]}]}
{"op":"mcm","clk":"1010968285","pt":1580653914408,"mc":[{"id":"1.168222849","rc":[{"batb":[[1,1.01,0.51],[2,4.7,0]],"ltp":15.5,"tv":27.88,"id":19613367},{"batb":[[1,1.01,0.51],[2,4.4,0]],"ltp":5.2,"tv":51.1,"id":16573041}]}]}
{"op":"mcm","clk":"1010968925","pt":1580653917205,"mc":[{"id":"1.168222849","rc":[{"batb":[[0,12.5,23.96],[1,12,24.93],[2,5.4,11.8]],"ltp":15.5,"tv":27.88,"id":19613367},{"batb":[[0,4.9,29.85],[1,4.8,34.39],[2,4.6,17]],"ltp":5.2,"tv":51.1,"id":16573041}]}]}
{"op":"mcm","clk":"1010969223","pt":1580653918532,"mc":[{"id":"1.168222849","rc":[{"batb":[[2,4.9,10.08]],"batl":[[0,5.5,14.01],[1,5.7,8.4]],"ltp":5.4,"tv":3.29,"id":19613369},{"batb":[[0,13,3.36],[1,12.5,23.96],[2,12,24.93]],"batl":[[1,25,8.03]],"ltp":15.5,"tv":27.88,"id":19613367},{"batl":[[0,1.9,18.57],[1,1.91,42.01],[2,2.12,27.07]],"ltp":2.68,"tv":477.29,"id":16573039},{"batb":[[0,5,14.32],[1,4.9,29.85],[2,4.8,49.73]],"batl":[[0,5.6,22.09],[1,5.8,12.9]],"ltp":5.2,"tv":51.1,"id":16573041}]}]}
{"op":"mcm","clk":"1010969423","pt":1580653919436,"mc":[{"id":"1.168222849","rc":[{"batl":[[0,1.9,60.58],[1,2.12,27.07],[2,2.12,0]],"ltp":2.68,"tv":477.29,"id":16573039}]}]}
{"op":"mcm","clk":"1010973159","pt":1580653936663,"mc":[{"id":"1.168222849","rc":[{"batb":[[0,5.1,32.36],[1,4.9,10.08],[2,4.7,15.58]],"ltp":5.4,"tv":3.29,"id":19613369},{"batb":[[1,11,11.02],[2,7.6,10.86]],"ltp":15.5,"tv":27.88,"id":19613367},{"batb":[[1,1.76,54.61],[2,1.71,23.45]],"ltp":2.68,"tv":477.29,"id":16573039},{"batb":[[1,4.8,15.34],[2,4.7,10.92]],"ltp":5.2,"tv":51.1,"id":16573041}]}]}
{"op":"mcm","clk":"1010973369","pt":1580653937527,"mc":[{"id":"1.168222849","rc":[{"batb":[[1,4.7,15.58],[2,1.01,0.51]],"batl":[[1,5.7,0]],"ltp":5.4,"tv":3.29,"id":19613369},{"batb":[[0,7.6,10.86],[1,1.01,0.51],[2,7.6,0]],"batl":[[0,25,8.03],[1,25,0]],"ltp":15.5,"tv":27.88,"id":19613367},{"batb":[[0,1.71,23.45],[1,1.01,0.51],[2,1.71,0]],"batl":[[0,2.12,27.07],[1,2.12,0]],"ltp":2.68,"tv":477.29,"id":16573039},{"batb":[[0,4.8,15.34],[1,1.01,0.51],[2,4.7,0]],"batl":[[0,5.8,12.9],[1,5.8,0]],"ltp":5.2,"tv":51.1,"id":16573041}]}]}
{"op":"mcm","clk":"1010973808","pt":1580653939474,"mc":[{"id":"1.168222849","rc":[{"batb":[[1,5,33.97],[2,4.7,15.58]],"ltp":5.4,"tv":3.29,"id":19613369},{"batb":[[0,7.6,51.1],[1,7.4,28.24],[2,1.01,0.51]],"ltp":15.5,"tv":27.88,"id":19613367},{"batb":[[1,1.7,108.38],[2,1.68,117.78]],"ltp":2.68,"tv":477.29,"id":16573039},{"batb":[[1,4.7,49.99],[2,4.6,37.66]],"ltp":5.2,"tv":51.1,"id":16573041}]}]}
{"op":"mcm","clk":"1010977423","pt":1580653955277,"mc":[{"id":"1.168222849","rc":[{"batb":[[1,4.7,15.58],[2,1.01,0.51]],"ltp":5.4,"tv":3.29,"id":19613369},{"batb":[[0,7.6,10.86],[1,1.01,0.51],[2,1.01,0]],"ltp":15.5,"tv":27.88,"id":19613367},{"batb":[[1,1.01,0.51],[2,4.6,0]],"ltp":5.2,"tv":51.1,"id":16573041}]}]}
{"op":"mcm","clk":"1010978159","pt":1580653958686,"mc":[{"id":"1.168222849","rc":[{"batb":[[0,5.2,33.02],[1,5.1,32.36],[2,4.8,25.56]],"batl":[[1,5.6,22.09]],"ltp":5.4,"tv":3.29,"id":19613369},{"batb":[[0,20,14.64],[1,19.5,9.24],[2,17,4.25]],"ltp":15.5,"tv":27.88,"id":19613367},{"batb":[[2,1.68,179.11]],"batl":[[0,1.78,22.98],[1,1.81,42.01],[2,1.93,17.94]],"ltp":2.68,"tv":477.29,"id":16573039},{"batb":[[0,5.1,13.45],[1,5,40.49],[2,4.9,32.83]],"batl":[[0,5.7,8.4],[1,5.8,12.9],[2,5.9,12.27]],"ltp":5.2,"tv":51.1,"id":16573041}]}]}
{"op":"mcm","clk":"1010983114","pt":1580653981728,"mc":[{"id":"1.168222849","rc":[{"batb":[[0,5.1,32.36],[1,4.7,15.58],[2,1.01,0.51]],"batl":[[0,5.6,13.69],[1,5.6,0]],"ltp":5.4,"tv":3.29,"id":19613369},{"batb":[[0,11,11.8],[1,1.01,0.51],[2,17,0]],"ltp":15.5,"tv":27.88,"id":19613367},{"batb":[[0,1.64,27.38],[1,1.01,0.51],[2,1.68,0]],"batl":[[0,1.93,17.94],[1,1.81,0],[2,1.93,0]],"ltp":2.68,"tv":477.29,"id":16573039},{"batb":[[0,5,14.4],[1,4.9,22.61],[2,1.01,0.51]],"batl":[[0,5.9,12.27],[1,5.8,0],[2,5.9,0]],"ltp":5.2,"tv":51.1,"id":16573041}]}]}
{"op":"mcm","clk":"1010983736","pt":1580653984552,"mc":[{"id":"1.168222849","rc":[{"batb":[[1,5,33.95],[2,4.7,15.58]],"ltp":5.4,"tv":3.29,"id":19613369},{"batb":[[0,12,29.39],[1,11.5,26.99],[2,11,11.8]],"ltp":15.5,"tv":27.88,"id":19613367},{"batb":[[0,1.64,136.35],[1,1.63,66.02],[2,1.01,0.51]],"ltp":2.68,"tv":477.29,"id":16573039},{"batb":[[2,4.8,34.52]],"ltp":5.2,"tv":51.1,"id":16573041}]}]}
{"op":"mcm","clk":"1010985262","pt":1580653991669,"mc":[{"id":"1.168222849","rc":[{"batb":[[1,4.7,15.58],[2,1.01,0.51]],"ltp":5.4,"tv":3.29,"id":19613369},{"batb":[[0,11,11.8],[1,1.01,0.51],[2,11,0]],"ltp":15.5,"tv":27.88,"id":19613367},{"batb":[[2,1.01,0.51]],"ltp":5.2,"tv":51.1,"id":16573041}]}]}
{"op":"mcm","clk":"1010985947","pt":1580653994607,"mc":[{"id":"1.168222849","rc":[{"batb":[[0,5.2,50.1],[1,5.1,32.36],[2,5,10.08]],"batl":[[1,5.8,8.4],[2,5.9,12.35]],"ltp":5.4,"tv":3.29,"id":19613369},{"batb":[[0,32,8.71],[1,30,13.22],[2,26,4.19]],"ltp":15.5,"tv":27.88,"id":19613367},{"batb":[[2,1.62,67.22]],"batl":[[0,1.7,26.83],[1,1.74,42.01],[2,1.75,24.31]],"ltp":2.68,"tv":477.29,"id":16573039},{"batb":[[0,5.2,12.75],[1,5.1,13.53],[2,5,61.46]],"batl":[[0,5.8,8.4],[1,5.9,12.27],[2,6.2,11.64]],"ltp":5.2,"tv":51.1,"id":16573041}]}]}
{"op":"mcm","clk":"1010986133","pt":1580653995484,"mc":[{"id":"1.168222849","rc":[{"batb":[[2,5,47.06]],"ltp":5.2,"tv":51.1,"id":16573041}]}]}
{"op":"mcm","clk":"1010991244","pt":1580654018697,"mc":[{"id":"1.168222849","rc":[{"batb":[[2,4.9,14.32]],"ltp":5.4,"tv":3.29,"id":19613369}]}]}
{"op":"mcm","clk":"1010991821","pt":1580654021604,"mc":[{"id":"1.168222849","rc":[{"batb":[[2,4.9,24.4]],"ltp":5.4,"tv":3.29,"id":19613369}]}]}
{"op":"mcm","clk":"1011007729","pt":1580654091718,"mc":[{"id":"1.168222849","rc":[{"batb":[[0,5.1,32.36],[1,4.8,15.19],[2,1.01,0.51]],"batl":[[0,5.9,12.35],[1,5.8,0],[2,5.9,0]],"ltp":5.4,"tv":3.29,"id":19613369},{"batb":[[0,22,4.11],[1,1.01,0.51],[2,26,0]],"ltp":15.5,"tv":27.88,"id":19613367},{"batb":[[0,1.58,31.16],[1,1.01,0.51],[2,1.62,0]],"batl":[[0,1.75,24.31],[1,1.74,0],[2,1.75,0]],"ltp":2.68,"tv":477.29,"id":16573039},{"batb":[[0,5.1,13.53],[1,5,23.69],[2,4.9,32.47]],"batl":[[0,6.2,11.64],[1,5.9,0],[2,6.2,0]],"ltp":5.2,"tv":51.1,"id":16573041}]}]}
{"op":"mcm","clk":"1011008284","pt":1580654094207,"mc":[{"id":"1.168222849","rc":[{"batb":[[0,5.1,45.33],[1,5,33.69],[2,4.8,15.19]],"ltp":5.4,"tv":3.29,"id":19613369},{"batb":[[0,28,4.16],[1,27,9.61],[2,22,4.11]],"ltp":15.5,"tv":27.88,"id":19613367},{"batb":[[0,1.6,74.91],[1,1.59,72.41],[2,1.58,31.16]],"ltp":2.68,"tv":477.29,"id":16573039}]}]}
{"op":"mcm","clk":"1011009035","pt":1580654097320,"mc":[{"id":"1.168222849","rc":[{"batb":[[0,5.1,32.36],[1,4.8,15.19],[2,1.01,0.51]],"ltp":5.4,"tv":3.29,"id":19613369},{"batb":[[0,22,4.11],[1,1.01,0.51],[2,22,0]],"ltp":15.5,"tv":27.88,"id":19613367},{"batb":[[0,1.58,31.16],[1,1.01,0.51],[2,1.58,0]],"ltp":2.68,"tv":477.29,"id":16573039}]}]}
{"op":"mcm","clk":"1011009805","pt":1580654100505,"mc":[{"id":"1.168222849","rc":[{"batb":[[0,5.1,45.33],[1,5,33.69],[2,4.9,10.08]],"batl":[[0,5.7,8.4],[1,5.9,12.35]],"ltp":5.4,"tv":3.29,"id":19613369},{"batb":[[0,28,4.16],[1,27,9.61],[2,22,4.11]],"ltp":15.5,"tv":27.88,"id":19613367},{"batb":[[0,1.68,62.82],[1,1.66,122.45],[2,1.65,63.85]],"batl":[[0,1.75,66.32]],"ltp":2.68,"tv":477.29,"id":16573039},{"batb":[[2,4.9,42.55]],"batl":[[0,5.7,8.4],[1,6.2,11.64]],"ltp":5.2,"tv":51.1,"id":16573041}]}]}
{"op":"mcm","clk":"1011010093","pt":1580654101599,"mc":[{"id":"1.168222849","rc":[{"batl":[[0,5.4,14.56],[1,5.6,13.38],[2,5.7,8.4]],"ltp":5.4,"tv":3.29,"id":19613369},{"batb":[[0,1.68,87.6]],"batl":[[1,1.8,22.19]],"ltp":2.68,"tv":477.29,"id":16573039},{"batb":[[1,5,37.85]],"batl":[[1,5.8,12.98],[2,6,12.12]],"ltp":5.2,"tv":51.1,"id":16573041}]}]}
{"op":"mcm","clk":"1011013513","pt":1580654115736,"mc":[{"id":"1.168222849","rc":[{"batb":[[0,5,33.69],[1,4.9,10.08],[2,4.8,15.19]],"ltp":5.4,"tv":3.29,"id":19613369},{"batb":[[0,22,4.11],[1,19.5,6.22],[2,1.01,0.51]],"ltp":15.5,"tv":27.88,"id":19613367},{"batb":[[0,1.68,24.78],[1,1.65,63.85],[2,1.62,28.17]],"ltp":2.68,"tv":477.29,"id":16573039},{"batb":[[1,5,14.16]],"ltp":5.2,"tv":51.1,"id":16573041}]}]}
{"op":"mcm","clk":"1011013774","pt":1580654116722,"mc":[{"id":"1.168222849","rc":[{"batb":[[2,4.6,16.37]],"batl":[[0,5.6,13.38],[1,5.7,8.4],[2,5.7,0]],"ltp":5.4,"tv":3.29,"id":19613369},{"batb":[[0,19.5,6.22],[1,1.01,0.51],[2,1.01,0]],"ltp":15.5,"tv":27.88,"id":19613367},{"batb":[[0,1.65,63.85],[1,1.62,28.17],[2,1.01,0.51]],"batl":[[0,1.75,42.01]],"ltp":2.68,"tv":477.29,"id":16573039},{"batb":[[0,5,14.16],[1,4.9,42.55],[2,1.01,0.51]],"batl":[[1,6,12.12],[2,6,0]],"ltp":5.2,"tv":51.1,"id":16573041}]}]}
{"op":"mcm","clk":"1011014039","pt":1580654117661,"mc":[{"id":"1.168222849","rc":[{"batb":[[0,4.6,16.37],[1,1.01,0.51],[2,4.6,0]],"batl":[[1,5.7,0]],"ltp":5.4,"tv":3.29,"id":19613369},{"batb":[[0,1.62,28.17],[1,1.01,0.51],[2,1.01,0]],"batl":[[0,1.8,22.19],[1,1.8,0]],"ltp":2.68,"tv":477.29,"id":16573039},{"batb":[[1,4.9,32.47]],"batl":[[0,6,12.12],[1,6,0]],"ltp":5.2,"tv":51.1,"id":16573041}]}]}
{"op":"mcm","clk":"1011014283","pt":1580654118739,"mc":[{"id":"1.168222849","rc":[{"batb":[[0,5,9.13],[1,4.9,35.26],[2,4.6,16.37]],"ltp":5.4,"tv":3.29,"id":19613369},{"batb":[[0,25,4.06],[1,24,12.18],[2,19.5,6.22]],"ltp":15.5,"tv":27.88,"id":19613367},{"batb":[[0,1.63,107.28],[1,1.62,95.71],[2,1.01,0.51]],"ltp":2.68,"tv":477.29,"id":16573039},{"batb":[[2,4.8,34.14]],"ltp":5.2,"tv":51.1,"id":16573041}]}]}
{"op":"mcm","clk":"1011014425","pt":1580654119439,"mc":[{"id":"1.168222849","rc":[{"batb":[[0,4.6,16.37],[1,1.01,0.51],[2,4.6,0]],"ltp":5.4,"tv":3.29,"id":19613369},{"batb":[[0,19.5,6.22],[1,1.01,0.51],[2,19.5,0]],"ltp":15.5,"tv":27.88,"id":19613367},{"batb":[[0,1.62,28.17],[1,1.01,0.51],[2,1.01,0]],"ltp":2.68,"tv":477.29,"id":16573039},{"batb":[[2,1.01,0.51]],"ltp":5.2,"tv":51.1,"id":16573041}]}]}
{"op":"mcm","clk":"1011014740","pt":1580654120738,"mc":[{"id":"1.168222849","rc":[{"batb":[[0,5.2,22.3],[1,5.1,32.56],[2,4.6,16.37]],"ltp":5.4,"tv":3.29,"id":19613369},{"batb":[[0,29,4.36],[1,28,8.92],[2,19.5,6.22]],"ltp":15.5,"tv":27.88,"id":19613367},{"batb":[[0,1.67,70.99],[1,1.66,61.64],[2,1.62,28.17]],"ltp":2.68,"tv":477.29,"id":16573039},{"batb":[[0,5,44.23]],"ltp":5.2,"tv":51.1,"id":16573041}]}]}
{"op":"mcm","clk":"1011015573","pt":1580654124143,"mc":[{"id":"1.168222849","rc":[{"batb":[[0,4.6,16.37],[1,1.01,0.51],[2,4.6,0]],"ltp":5.4,"tv":3.29,"id":19613369},{"batb":[[0,19.5,6.22],[1,1.01,0.51],[2,19.5,0]],"ltp":15.5,"tv":27.88,"id":19613367},{"batb":[[0,1.62,28.17],[1,1.01,0.51],[2,1.62,0]],"ltp":2.68,"tv":477.29,"id":16573039},{"batb":[[0,5,14.16]],"ltp":5.2,"tv":51.1,"id":16573041}]}]}
{"op":"mcm","clk":"1011016177","pt":1580654126728,"mc":[{"id":"1.168222849","rc":[{"batb":[[0,5,42.82],[1,4.9,35.26],[2,4.6,16.37]],"ltp":5.4,"tv":3.29,"id":19613369},{"batb":[[0,25,4.06],[1,24,12.18],[2,19.5,6.22]],"ltp":15.5,"tv":27.88,"id":19613367},{"batb":[[0,1.63,107.28],[1,1.62,95.71],[2,1.01,0.51]],"ltp":2.68,"tv":477.29,"id":16573039},{"batb":[[2,4.8,34.14]],"ltp":5.2,"tv":51.1,"id":16573041}]}]}
{"op":"mcm","clk":"1011016639","pt":1580654128647,"mc":[{"id":"1.168222849","rc":[{"batb":[[0,4.6,16.37],[1,1.01,0.51],[2,4.6,0]],"ltp":5.4,"tv":3.29,"id":19613369},{"batb":[[0,19.5,6.22],[1,1.01,0.51],[2,19.5,0]],"ltp":15.5,"tv":27.88,"id":19613367},{"batb":[[1,1.01,0.51],[2,4.8,0]],"ltp":5.2,"tv":51.1,"id":16573041}]}]}
{"op":"mcm","clk":"1011017351","pt":1580654131735,"mc":[{"id":"1.168222849","rc":[{"batb":[[0,5.3,21.01],[1,5.2,31.06],[2,4.6,16.37]],"ltp":5.4,"tv":3.29,"id":19613369},{"batb":[[0,34,2.99],[1,32,13.2],[2,19.5,6.22]],"ltp":15.5,"tv":27.88,"id":19613367},{"batb":[[0,1.63,65.87],[1,1.62,28.17]],"ltp":2.68,"tv":477.29,"id":16573039},{"batb":[[0,5.1,23.13],[1,5,45.55],[2,1.01,0.51]],"ltp":5.2,"tv":51.1,"id":16573041}]}]}
{"op":"mcm","clk":"1011017553","pt":1580654132552,"mc":[{"id":"1.168222849","rc":[{"batb":[[2,5,10.08]],"batl":[[1,5.8,8.4],[2,5.9,12.12]],"ltp":5.4,"tv":3.29,"id":19613369},{"batb":[[2,27,3.58]],"ltp":15.5,"tv":27.88,"id":19613367},{"batb":[[1,1.62,95.38],[2,1.56,32.18]],"batl":[[0,1.69,27.54],[1,1.73,42.01],[2,1.74,24.78]],"ltp":2.68,"tv":477.29,"id":16573039},{"batb":[[0,5.3,12.59],[1,5.2,13.22],[2,5.1,23.13]],"batl":[[0,5.8,8.4],[1,6,12.12],[2,6.2,11.41]],"ltp":5.2,"tv":51.1,"id":16573041}]}]}
{"op":"mcm","clk":"1011018040","pt":1580654134652,"mc":[{"id":"1.168222849","rc":[{"batb":[[0,1.64,62.1],[1,1.63,65.87],[2,1.62,95.38]],"ltp":2.68,"tv":477.29,"id":16573039}]}]}
{"op":"mcm","clk":"1011019508","pt":1580654140664,"mc":[{"id":"1.168222849","rc":[{"batb":[[0,5,10.08],[1,4.8,15.11],[2,1.01,0.51]],"batl":[[0,5.8,8.4],[1,5.9,12.12],[2,5.9,0]],"ltp":5.4,"tv":3.29,"id":19613369},{"batb":[[0,22,4.04],[1,1.01,0.51],[2,27,0]],"ltp":15.5,"tv":27.88,"id":19613367},{"batb":[[0,1.62,67.22],[1,1.56,32.18],[2,1.01,0.51]],"batl":[[0,1.73,42.01],[1,1.74,24.78],[2,1.74,0]],"ltp":2.68,"tv":477.29,"id":16573039},{"batb":[[0,5.2,13.22],[1,5,31.39],[2,4.9,10.08]],"batl":[[1,6.2,11.41],[2,6.2,0]],"ltp":5.2,"tv":51.1,"id":16573041}]}]}
{"op":"mcm","clk":"1011019732","pt":1580654141567,"mc":[{"id":"1.168222849","rc":[{"batb":[[0,4.8,15.11],[1,1.01,0.51],[2,1.01,0]],"batl":[[0,5.9,12.12],[1,5.9,0]],"ltp":5.4,"tv":3.29,"id":19613369},{"batb":[[0,1.56,32.18],[1,1.01,0.51],[2,1.01,0]],"batl":[[0,1.74,24.78],[1,1.74,0]],"ltp":2.68,"tv":477.29,"id":16573039},{"batb":[[2,1.01,0.51]],"batl":[[0,6.2,11.41],[1,6.2,0]],"ltp":5.2,"tv":51.1,"id":16573041}]}]}
{"op":"mcm","clk":"1011020091","pt":1580654143109,"mc":[{"id":"1.168222849","rc":[{"batb":[[0,5.1,46.6],[1,5,33.47],[2,4.8,15.11]],"ltp":5.4,"tv":3.29,"id":19613369},{"batb":[[0,28,4.35],[1,27,9.53],[2,22,4.04]],"ltp":15.5,"tv":27.88,"id":19613367},{"batb":[[0,1.58,136.75],[1,1.57,76.23],[2,1.56,32.18]],"ltp":2.68,"tv":477.29,"id":16573039},{"batb":[[2,4.9,32.72]],"ltp":5.2,"tv":51.1,"id":16573041}]}]}
{"op":"mcm","clk":"1011020400","pt":1580654144357,"mc":[{"id":"1.168222849","rc":[{"batb":[[0,1.56,32.18],[1,1.01,0.51],[2,1.56,0]],"ltp":2.68,"tv":477.29,"id":16573039}]}]}
{"op":"mcm","clk":"1011021189","pt":1580654147679,"mc":[{"id":"1.168222849","rc":[{"batl":[[0,5.5,14.4],[1,5.7,13.14],[2,5.9,12.12]],"ltp":5.4,"tv":3.29,"id":19613369},{"batb":[[0,1.68,25.26],[1,1.67,100.82],[2,1.66,61.67]],"batl":[[1,1.8,22.27]],"ltp":2.68,"tv":477.29,"id":16573039},{"batb":[[1,5,45.47]],"batl":[[0,5.8,12.67],[1,6,11.96],[2,6.2,11.41]],"ltp":5.2,"tv":51.1,"id":16573041}]}]}
{"op":"mcm","clk":"1011021411","pt":1580654148562,"mc":[{"id":"1.168222849","rc":[{"batb":[[2,4.9,10.08]],"batl":[[1,5.7,21.54],[2,5.9,0]],"ltp":5.4,"tv":3.29,"id":19613369},{"batl":[[1,1.75,42.01],[2,1.8,22.27]],"ltp":2.68,"tv":477.29,"id":16573039},{"batb":[[2,4.9,42.8]],"batl":[[0,5.7,8.4],[1,5.8,12.67],[2,6,11.96]],"ltp":5.2,"tv":51.1,"id":16573041}]}]}
{"op":"mcm","clk":"1011028354","pt":1580654178017,"mc":[{"id":"1.168222849","rc":[{"batb":[[0,5,33.47],[1,4.9,10.08],[2,4.6,16.13]],"batl":[[0,5.7,21.54],[1,5.7,0]],"ltp":5.4,"tv":3.29,"id":19613369},{"batb":[[0,19,6.45],[1,1.01,0.51],[2,22,0]],"ltp":15.5,"tv":27.88,"id":19613367},{"batb":[[0,1.64,65.54],[1,1.61,28.8],[2,1.01,0.51]],"batl":[[0,1.75,42.01],[1,1.8,22.27],[2,1.8,0]],"ltp":2.68,"tv":477.29,"id":16573039},{"batb":[[0,5,14.08],[1,4.9,42.8],[2,1.01,0.51]],"batl":[[1,6,11.96],[2,6,0]],"ltp":5.2,"tv":51.1,"id":16573041}]}]}
{"op":"mcm","clk":"1011028709","pt":1580654179609,"mc":[{"id":"1.168222849","rc":[{"batb":[[1,4.6,16.13],[2,1.01,0.51]],"batl":[[0,5.7,13.14]],"ltp":5.4,"tv":3.29,"id":19613369},{"batb":[[0,1.61,28.8],[1,1.01,0.51],[2,1.01,0]],"batl":[[0,1.8,22.27],[1,1.8,0]],"ltp":2.68,"tv":477.29,"id":16573039},{"batb":[[1,4.9,32.72]],"batl":[[0,6,11.96],[1,6,0]],"ltp":5.2,"tv":51.1,"id":16573041}]}]}
{"op":"mcm","clk":"1011029028","pt":1580654180997,"mc":[{"id":"1.168222849","rc":[{"batb":[[0,5,44.01],[1,4.9,35.03],[2,4.6,16.13]],"ltp":5.4,"tv":3.29,"id":19613369},{"batb":[[0,24,11.25],[1,23,12.88],[2,19,6.45]],"ltp":15.5,"tv":27.88,"id":19613367},{"batb":[[0,1.62,127.84],[1,1.61,97.95],[2,1.01,0.51]],"ltp":2.68,"tv":477.29,"id":16573039},{"batb":[[1,4.9,44.22],[2,4.8,34.07]],"ltp":5.2,"tv":51.1,"id":16573041}]}]}
{"op":"mcm","clk":"1011030103","pt":1580654185703,"mc":[{"id":"1.168222849","rc":[{"batb":[[0,4.6,16.13],[1,1.01,0.51],[2,4.6,0]],"ltp":5.4,"tv":3.29,"id":19613369},{"batb":[[0,19,6.45],[1,1.01,0.51],[2,19,0]],"ltp":15.5,"tv":27.88,"id":19613367},{"batb":[[1,1.01,0.51],[2,4.8,0]],"ltp":5.2,"tv":51.1,"id":16573041}]}]}
{"op":"mcm","clk":"1011030934","pt":1580654189598,"mc":[{"id":"1.168222849","rc":[{"batb":[[0,5.3,24.07],[1,5.2,30.85],[2,5,13.69]],"batl":[[1,6,11.96]],"ltp":5.4,"tv":3.29,"id":19613369},{"batb":[[0,34,10.88],[1,32,7.86],[2,28,2.97]],"ltp":15.5,"tv":27.88,"id":19613367},{"batb":[[0,1.62,67.41],[1,1.61,28.8],[2,1.55,33.6]],"batl":[[0,1.68,28.17],[1,1.74,24.78]],"ltp":2.68,"tv":477.29,"id":16573039},{"batb":[[0,5.3,12.51],[1,5.1,47.35],[2,5,31.29]],"batl":[[1,6.2,11.09]],"ltp":5.2,"tv":51.1,"id":16573041}]}]}
{"op":"mcm","clk":"1011031214","pt":1580654190671,"mc":[{"id":"1.168222849","rc":[{"batb":[[2,5.1,10.08]],"batl":[[1,5.9,8.4],[2,6,11.96]],"ltp":5.4,"tv":3.29,"id":19613369},{"batb":[[1,1.61,96.85]],"batl":[[1,1.72,42.01],[2,1.74,24.78]],"ltp":2.68,"tv":477.29,"id":16573039},{"batl":[[0,5.8,8.4],[1,6,11.96],[2,6.2,11.09]],"ltp":5.2,"tv":51.1,"id":16573041}]}]}
{"op":"mcm","clk":"1011031487","pt":1580654191967,"mc":[{"id":"1.168222849","rc":[{"batb":[[0,1.63,80.36],[1,1.62,67.41],[2,1.61,96.85]],"ltp":2.68,"tv":477.29,"id":16573039}]}]}
{"op":"mcm","clk":"1011033162","pt":1580654199588,"mc":[{"id":"1.168222849","rc":[{"batb":[[0,4.8,14.79],[1,1.01,0.51],[2,5.1,0]],"batl":[[0,6,11.96],[1,5.9,0],[2,6,0]],"ltp":5.4,"tv":3.29,"id":19613369},{"batb":[[0,21,4.41],[1,1.01,0.51],[2,28,0]],"ltp":15.5,"tv":27.88,"id":19613367},{"batb":[[0,1.55,33.6],[1,1.01,0.51],[2,1.61,0]],"batl":[[0,1.74,24.78],[1,1.72,0],[2,1.74,0]],"ltp":2.68,"tv":477.29,"id":16573039},{"batb":[[0,5.1,13.38],[1,5,31.29],[2,1.01,0.51]],"batl":[[0,6.2,11.09],[1,6,0],[2,6.2,0]],"ltp":5.2,"tv":51.1,"id":16573041}]}]}
{"op":"mcm","clk":"1011033757","pt":1580654202363,"mc":[{"id":"1.168222849","rc":[{"batb":[[0,5.1,47.65],[1,5,33.26],[2,4.8,14.79]],"ltp":5.4,"tv":3.29,"id":19613369},{"batb":[[0,27,7.25],[1,26,10.1],[2,21,4.41]],"ltp":15.5,"tv":27.88,"id":19613367},{"batb":[[0,1.57,93.83],[1,1.56,77.99],[2,1.55,33.6]],"ltp":2.68,"tv":477.29,"id":16573039},{"batb":[[1,5,39.96],[2,4.9,32.65]],"ltp":5.2,"tv":51.1,"id":16573041}]}]}
{"op":"mcm","clk":"1011036979","pt":1580654216725,"mc":[{"id":"1.168222849","rc":[{"batb":[[0,1.55,33.6],[1,1.01,0.51],[2,1.55,0]],"ltp":2.68,"tv":477.29,"id":16573039}]}]}
{"op":"mcm","clk":"1011037665","pt":1580654219730,"mc":[{"id":"1.168222849","rc":[{"batb":[[0,1.67,98.73],[1,1.66,61.61],[2,1.55,33.6]],"ltp":2.68,"tv":477.29,"id":16573039}]}]}
{"op":"mcm","clk":"1011037899","pt":1580654220737,"mc":[{"id":"1.168222849","rc":[{"batb":[[1,5,43.34]],"batl":[[0,5.5,14.16],[1,5.7,12.98],[2,5.8,8.4]],"ltp":5.4,"tv":3.29,"id":19613369},{"batb":[[0,1.67,123.99],[2,1.62,67.22]],"batl":[[0,1.74,66.79],[1,1.8,22.11]],"ltp":2.68,"tv":477.29,"id":16573039},{"batb":[[1,5,54.04],[2,4.9,42.73]],"batl":[[0,5.7,8.4],[1,5.8,12.83],[2,6,12.04]],"ltp":5.2,"tv":51.1,"id":16573041}]}]}
{"op":"mcm","clk":"1011043100","pt":1580654242669,"mc":[{"id":"1.168222849","rc":[{"batb":[[0,5,43.34],[1,4.8,14.79],[2,4.7,15.89]],"ltp":5.4,"tv":3.29,"id":19613369},{"batb":[[0,21,4.41],[1,18,7.16],[2,1.01,0.51]],"ltp":15.5,"tv":27.88,"id":19613367},{"batb":[[0,1.67,25.26],[1,1.62,67.22],[2,1.61,28.95]],"ltp":2.68,"tv":477.29,"id":16573039},{"batb":[[1,5,14.08]],"ltp":5.2,"tv":51.1,"id":16573041}]}]}
{"op":"mcm","clk":"1011043299","pt":1580654243673,"mc":[{"id":"1.168222849","rc":[{"batb":[[0,5,33.26],[1,4.7,15.89],[2,1.01,0.51]],"batl":[[0,5.7,12.98],[1,5.7,0],[2,5.8,0]],"ltp":5.4,"tv":3.29,"id":19613369},{"batb":[[0,18,7.16],[1,1.01,0.51],[2,1.01,0]],"ltp":15.5,"tv":27.88,"id":19613367},{"batb":[[0,1.61,28.95],[1,1.01,0.51],[2,1.61,0]],"batl":[[0,1.8,22.11],[1,1.8,0]],"ltp":2.68,"tv":477.29,"id":16573039},{"batb":[[0,5,14.08],[1,4.9,32.65],[2,1.01,0.51]],"batl":[[0,6,12.04],[1,5.8,0],[2,6,0]],"ltp":5.2,"tv":51.1,"id":16573041}]}]}
{"op":"mcm","clk":"1011043713","pt":1580654245575,"mc":[{"id":"1.168222849","rc":[{"batb":[[0,5,45.75],[1,4.9,34.92],[2,4.7,15.89]],"ltp":5.4,"tv":3.29,"id":19613369},{"batb":[[0,23,14.3],[1,22,13.98],[2,18,7.16]],"ltp":15.5,"tv":27.88,"id":19613367},{"batb":[[0,1.62,104.56],[1,1.61,98.01],[2,1.01,0.51]],"ltp":2.68,"tv":477.29,"id":16573039},{"batb":[[1,4.9,50.48],[2,4.8,34.14]],"ltp":5.2,"tv":51.1,"id":16573041}]}]}
{"op":"mcm","clk":"1011043985","pt":1580654246658,"mc":[{"id":"1.168222849","rc":[{"batb":[[2,4.6,16.13]],"ltp":5.4,"tv":3.29,"id":19613369},{"batb":[[0,1.62,28.48],[1,1.01,0.51],[2,1.01,0]],"batl":[[0,1.81,21.79]],"ltp":2.68,"tv":477.29,"id":16573039}]}]}
{"op":"mcm","clk":"1011044664","pt":1580654249655,"mc":[{"id":"1.168222849","rc":[{"batb":[[0,1.71,66.89],[1,1.69,114.63],[2,1.62,28.48]],"ltp":2.68,"tv":477.29,"id":16573039}]}]}
{"op":"mcm","clk":"1011044855","pt":1580654250575,"mc":[{"id":"1.168222849","rc":[{"batb":[[2,4.8,10.92]],"batl":[[0,5.3,15.42],[1,5.4,14.87],[2,5.6,8.4]],"ltp":5.4,"tv":3.29,"id":19613369},{"batl":[[0,28,6.61]],"ltp":15.5,"tv":27.88,"id":19613367},{"batb":[[0,1.74,22.19],[1,1.71,66.89],[2,1.69,114.63]],"batl":[[0,1.78,42.01],[1,1.81,21.79],[2,1.95,17.23]],"ltp":2.68,"tv":477.29,"id":16573039},{"batb":[[2,4.8,60.33]],"batl":[[0,5.6,13.69],[1,5.7,8.4],[2,5.8,13.06]],"ltp":5.2,"tv":51.1,"id":16573041}]}]}
{"op":"mcm","clk":"1011052326","pt":1580654282622,"mc":[{"id":"1.168222849","rc":[{"batb":[[0,4.9,34.92],[1,4.8,10.92],[2,4.5,17.07]],"batl":[[0,5.4,14.87],[1,5.6,8.4],[2,5.6,0]],"ltp":5.4,"tv":3.29,"id":19613369},{"batb":[[0,11.5,9.91],[1,1.01,0.51],[2,18,0]],"ltp":15.5,"tv":27.88,"id":19613367},{"batb":[[0,1.66,88.98],[1,1.01,0.51],[2,1.69,0]],"batl":[[1,1.95,17.23],[2,1.95,0]],"ltp":2.68,"tv":477.29,"id":16573039},{"batb":[[0,4.8,60.33],[1,1.01,0.51],[2,4.8,0]],"batl":[[0,5.7,8.4],[1,5.8,13.06],[2,5.8,0]],"ltp":5.2,"tv":51.1,"id":16573041}]}]}
{"op":"mcm","clk":"1011052543","pt":1580654283613,"mc":[{"id":"1.168222849","rc":[{"batb":[[1,4.5,17.07],[2,1.01,0.51]],"batl":[[1,5.6,0]],"ltp":5.4,"tv":3.29,"id":19613369},{"batb":[[0,1.66,25.97]],"batl":[[0,1.95,17.23],[1,1.95,0]],"ltp":2.68,"tv":477.29,"id":16573039},{"batb":[[0,4.8,49.4]],"batl":[[0,5.8,13.06],[1,5.8,0]],"ltp":5.2,"tv":51.1,"id":16573041}]}]}
{"op":"mcm","clk":"1011053028","pt":1580654285731,"mc":[{"id":"1.168222849","rc":[{"batb":[[0,4.9,51.47],[1,4.8,36.44],[2,4.5,17.07]],"ltp":5.4,"tv":3.29,"id":19613369},{"batb":[[0,13,26.04],[1,12.5,22.52],[2,11.5,9.91]],"ltp":15.5,"tv":27.88,"id":19613367},{"batb":[[1,1.64,124.43],[2,1.63,65.71]],"ltp":2.68,"tv":477.29,"id":16573039},{"batb":[[0,4.8,66.55],[1,4.7,35.77],[2,1.01,0.51]],"ltp":5.2,"tv":51.1,"id":16573041}]}]}
{"op":"mcm","clk":"1011053247","pt":1580654286609,"mc":[{"id":"1.168222849","rc":[{"batb":[[0,4.9,34.92],[1,4.7,15.82],[2,1.01,0.51]],"batl":[[0,5.6,13.69]],"ltp":5.4,"tv":3.29,"id":19613369},{"batb":[[0,12,9.21],[1,1.01,0.51],[2,11.5,0]],"ltp":15.5,"tv":27.88,"id":19613367},{"batb":[[0,1.65,26.91],[1,1.01,0.51],[2,1.63,0]],"batl":[[0,1.93,17.94]],"ltp":2.68,"tv":477.29,"id":16573039},{"batb":[[0,4.8,49.4],[1,1.01,0.51],[2,1.01,0]],"batl":[[0,5.7,13.38]],"ltp":5.2,"tv":51.1,"id":16573041}]}]}
{"op":"mcm","clk":"1011053971","pt":1580654289607,"mc":[{"id":"1.168222849","rc":[{"batb":[[0,5,39.7],[1,4.9,34.92],[2,4.7,15.82]],"ltp":5.4,"tv":3.29,"id":19613369},{"batb":[[0,20,15.46],[1,19.5,9.12],[2,12,9.21]],"ltp":15.5,"tv":27.88,"id":19613367},{"batb":[[0,1.73,80.85],[1,1.71,110.12],[2,1.65,26.91]],"ltp":2.68,"tv":477.29,"id":16573039},{"batb":[[0,4.9,43.51],[1,4.8,49.4],[2,1.01,0.51]],"ltp":5.2,"tv":51.1,"id":16573041}]}]}
{"op":"mcm","clk":"1011055015","pt":1580654294141,"mc":[{"id":"1.168222849","rc":[{"batb":[[0,4.9,34.92],[1,4.7,15.82],[2,1.01,0.51]],"ltp":5.4,"tv":3.29,"id":19613369},{"batb":[[0,12,9.21],[1,1.01,0.51],[2,12,0]],"ltp":15.5,"tv":27.88,"id":19613367},{"batb":[[0,1.65,26.91],[1,1.01,0.51],[2,1.65,0]],"ltp":2.68,"tv":477.29,"id":16573039},{"batb":[[0,4.8,49.4],[1,1.01,0.51],[2,1.01,0]],"ltp":5.2,"tv":51.1,"id":16573041}]}]}
{"op":"mcm","clk":"1011055659","pt":1580654297055,"mc":[{"id":"1.168222849","rc":[{"batb":[[0,4.9,51.48],[1,4.8,36.44],[2,4.7,15.82]],"ltp":5.4,"tv":3.29,"id":19613369},{"batb":[[0,13,26.11],[1,12.5,22.52],[2,12,9.21]],"ltp":15.5,"tv":27.88,"id":19613367},{"batb":[[1,1.64,124.38],[2,1.63,65.71]],"ltp":2.68,"tv":477.29,"id":16573039},{"batb":[[0,4.8,66.56],[1,4.7,35.77],[2,1.01,0.51]],"ltp":5.2,"tv":51.1,"id":16573041}]}]}
{"op":"mcm","clk":"1011056342","pt":1580654300143,"mc":[{"id":"1.168222849","rc":[{"batb":[[0,4.7,15.82],[1,1.01,0.51],[2,4.7,0]],"ltp":5.4,"tv":3.29,"id":19613369},{"batb":[[0,12,9.21],[1,1.01,0.51],[2,12,0]],"ltp":15.5,"tv":27.88,"id":19613367},{"batb":[[0,4.8,15.26],[1,1.01,0.51],[2,1.01,0]],"ltp":5.2,"tv":51.1,"id":16573041}]}]}
{"op":"mcm","clk":"1011057112","pt":1580654303729,"mc":[{"id":"1.168222849","rc":[{"batb":[[0,5.1,28.17],[1,5,33.46],[2,4.9,14.32]],"batl":[[1,5.7,13.06]],"ltp":5.4,"tv":3.29,"id":19613369},{"batb":[[0,42,2.89],[1,40,8.44],[2,29,2.51]],"ltp":15.5,"tv":27.88,"id":19613367},{"batl":[[0,1.71,26.36],[1,1.82,21.4],[2,1.93,17.94]],"ltp":2.68,"tv":477.29,"id":16573039},{"batb":[[0,5.1,13.93],[1,5,36.19],[2,4.9,47.74]],"batl":[[1,5.9,12.59]],"ltp":5.2,"tv":51.1,"id":16573041}]}]}
{"op":"mcm","clk":"1011057328","pt":1580654304707,"mc":[{"id":"1.168222849","rc":[{"batl":[[0,5.6,22.09]],"ltp":5.4,"tv":3.29,"id":19613369},{"batl":[[1,1.73,42.01],[2,1.82,21.4]],"ltp":2.68,"tv":477.29,"id":16573039},{"batb":[[2,4.9,57.82]],"batl":[[1,5.8,8.4],[2,5.9,12.59]],"ltp":5.2,"tv":51.1,"id":16573041}]}]}
{"op":"mcm","clk":"1011061141","pt":1580654322744,"mc":[{"id":"1.168222849","rc":[{"batb":[[0,5,24.24],[1,4.9,14.32],[2,4.8,10.92]],"ltp":5.4,"tv":3.29,"id":19613369},{"batb":[[0,29,2.51],[1,17.5,8.03],[2,1.01,0.51]],"ltp":15.5,"tv":27.88,"id":19613367},{"batb":[[1,1.61,68.06],[2,1.58,30.76]],"ltp":2.68,"tv":477.29,"id":16573039},{"batb":[[1,4.9,57.82],[2,1.01,0.51]],"ltp":5.2,"tv":51.1,"id":16573041}]}]}
{"op":"mcm","clk":"1011061324","pt":1580654323668,"mc":[{"id":"1.168222849","rc":[{"batb":[[1,4.7,15.42],[2,1.01,0.51]],"batl":[[0,5.7,13.06],[1,5.7,0]],"ltp":5.4,"tv":3.29,"id":19613369},{"batb":[[0,17.5,8.03],[1,1.01,0.51],[2,1.01,0]],"ltp":15.5,"tv":27.88,"id":19613367},{"batb":[[0,1.58,30.76],[1,1.01,0.51],[2,1.58,0]],"batl":[[0,1.82,21.4],[1,1.73,0],[2,1.82,0]],"ltp":2.68,"tv":477.29,"id":16573039},{"batb":[[0,4.9,47.74],[1,1.01,0.51],[2,1.01,0]],"batl":[[0,5.9,12.59],[1,5.8,0],[2,5.9,0]],"ltp":5.2,"tv":51.1,"id":16573041}]}]}
{"op":"mcm","clk":"1011061775","pt":1580654325629,"mc":[{"id":"1.168222849","rc":[{"batb":[[1,4.9,35.16],[2,4.7,15.42]],"ltp":5.4,"tv":3.29,"id":19613369},{"batb":[[0,20,20.9],[1,19.5,8.99],[2,17.5,8.03]],"ltp":15.5,"tv":27.88,"id":19613367},{"batb":[[0,1.6,85.12],[1,1.59,71.85],[2,1.58,30.76]],"ltp":2.68,"tv":477.29,"id":16573039},{"batb":[[1,4.8,34.24],[2,1.01,0.51]],"ltp":5.2,"tv":51.1,"id":16573041}]}]}
{"op":"mcm","clk":"1011064219","pt":1580654337646,"mc":[{"id":"1.168222849","rc":[{"batb":[[1,4.7,15.42],[2,1.01,0.51]],"ltp":5.4,"tv":3.29,"id":19613369},{"batb":[[0,17.5,8.03],[1,1.01,0.51],[2,17.5,0]],"ltp":15.5,"tv":27.88,"id":19613367},{"batb":[[0,4.9,15.11],[1,1.01,0.51],[2,1.01,0]],"ltp":5.2,"tv":51.1,"id":16573041}]}]}
{"op":"mcm","clk":"1011064803","pt":1580654340596,"mc":[{"id":"1.168222849","rc":[{"batb":[[0,5.1,51.72],[1,5,33.11],[2,4.9,10.08]],"batl":[[0,5.7,21.46]],"ltp":5.4,"tv":3.29,"id":19613369},{"batb":[[0,95,2.85],[1,90,4],[2,17.5,8.03]],"ltp":15.5,"tv":27.88,"id":19613367},{"batb":[[2,1.58,103.02]],"batl":[[0,1.69,42.01],[1,1.82,21.4]],"ltp":2.68,"tv":477.29,"id":16573039},{"batb":[[0,5.1,21.75],[1,5,31.35],[2,4.9,25.19]],"batl":[[0,5.8,8.4],[1,5.9,12.59]],"ltp":5.2,"tv":51.1,"id":16573041}]}]}
{"op":"mcm","clk":"1011064928","pt":1580654341158,"mc":[{"id":"1.168222849","rc":[{"batb":[[1,5,46.8]],"batl":[[1,5.9,12.35]],"ltp":5.4,"tv":3.29,"id":19613369},{"batb":[[2,28,2.79]],"ltp":15.5,"tv":27.88,"id":19613367},{"batl":[[0,1.65,30.14],[1,1.69,42.01],[2,1.74,25.18]],"ltp":2.68,"tv":477.29,"id":16573039},{"batb":[[0,5.2,13.14],[1,5.1,21.75],[2,5,45.75]],"batl":[[2,6,12.12]],"ltp":5.2,"tv":51.1,"id":16573041}]}]}
{"op":"mcm","clk":"1011069187","pt":1580654361667,"mc":[{"id":"1.168222849","rc":[{"batb":[[0,5,46.8],[1,4.9,10.08],[2,4.8,15.19]],"ltp":5.4,"tv":3.29,"id":19613369},{"batb":[[0,28,2.79],[1,1.01,0.51],[2,28,0]],"ltp":15.5,"tv":27.88,"id":19613367},{"batb":[[0,1.58,103.02],[1,1.54,33.99],[2,1.01,0.51]],"ltp":2.68,"tv":477.29,"id":16573039},{"batb":[[1,5,45.75],[2,4.9,10.08]],"ltp":5.2,"tv":51.1,"id":16573041}]}]}
{"op":"mcm","clk":"1011069396","pt":1580654362649,"mc":[{"id":"1.168222849","rc":[{"batb":[[0,5,33.11]],"batl":[[0,5.7,8.4]],"ltp":5.4,"tv":3.29,"id":19613369},{"batb":[[0,1.58,72.26]],"batl":[[0,1.69,42.01],[1,1.74,25.18],[2,1.74,0]],"ltp":2.68,"tv":477.29,"id":16573039},{"batb":[[0,5,45.75],[1,4.9,10.08],[2,1.01,0.51]],"batl":[[1,6,12.12],[2,6,0]],"ltp":5.2,"tv":51.1,"id":16573041}]}]}
{"op":"mcm","clk":"1011069610","pt":1580654363693,"mc":[{"id":"1.168222849","rc":[{"batb":[[1,4.8,15.19],[2,1.01,0.51]],"batl":[[0,5.9,12.35],[1,5.9,0]],"ltp":5.4,"tv":3.29,"id":19613369},{"batb":[[0,1.54,33.99],[1,1.01,0.51],[2,1.01,0]],"batl":[[0,1.74,25.18],[1,1.74,0]],"ltp":2.68,"tv":477.29,"id":16573039},{"batb":[[1,1.01,0.51],[2,1.01,0]],"batl":[[0,6,12.12],[1,6,0]],"ltp":5.2,"tv":51.1,"id":16573041}]}]}
{"op":"mcm","clk":"1011069828","pt":1580654364672,"mc":[{"id":"1.168222849","rc":[{"batb":[[1,4.9,34.94],[2,4.8,15.19]],"ltp":5.4,"tv":3.29,"id":19613369},{"batb":[[0,40,7.86],[1,38,9.1],[2,28,2.79]],"ltp":15.5,"tv":27.88,"id":19613367},{"batb":[[0,1.57,78.84],[1,1.56,77.16],[2,1.54,33.99]],"ltp":2.68,"tv":477.29,"id":16573039},{"batb":[[1,4.9,32.8],[2,1.01,0.51]],"ltp":5.2,"tv":51.1,"id":16573041}]}]}
{"op":"mcm","clk":"1011069935","pt":1580654365104,"mc":[{"id":"1.168222849","rc":[{"batb":[[2,4.7,15.42]],"batl":[[0,5.8,12.59]],"ltp":5.4,"tv":3.29,"id":19613369},{"batb":[[2,1.55,33.44]],"batl":[[0,1.74,24.78]],"ltp":2.68,"tv":477.29,"id":16573039},{"batb":[[0,5,31.35],[1,4.9,47.36]],"ltp":5.2,"tv":51.1,"id":16573041}]}]}
{"op":"mcm","clk":"1011070117","pt":1580654365902,"mc":[{"id":"1.168222849","rc":[{"batb":[[1,4.7,15.42],[2,1.01,0.51]],"ltp":5.4,"tv":3.29,"id":19613369},{"batb":[[0,28,2.79],[1,1.01,0.51],[2,28,0]],"ltp":15.5,"tv":27.88,"id":19613367},{"batb":[[0,1.55,33.44],[1,1.01,0.51],[2,1.55,0]],"ltp":2.68,"tv":477.29,"id":16573039}]}]}
{"op":"mcm","clk":"1011070869","pt":1580654369001,"mc":[{"id":"1.168222849","rc":[{"batb":[[0,5.1,41.69],[1,5,33.11],[2,4.7,15.42]],"ltp":5.4,"tv":3.29,"id":19613369},{"batb":[[0,75,3.22],[1,70,6.15],[2,28,2.79]],"ltp":15.5,"tv":27.88,"id":19613367},{"batb":[[0,1.61,95.71],[1,1.6,70.23],[2,1.55,33.44]],"ltp":2.68,"tv":477.29,"id":16573039},{"batb":[[0,5,47.74]],"ltp":5.2,"tv":51.1,"id":16573041}]}]}
{"op":"mcm","clk":"1011071712","pt":1580654372380,"mc":[{"id":"1.168222849","rc":[{"batb":[[0,5,33.11],[1,4.7,15.42],[2,1.01,0.51]],"ltp":5.4,"tv":3.29,"id":19613369},{"batb":[[0,28,2.79],[1,1.01,0.51],[2,28,0]],"ltp":15.5,"tv":27.88,"id":19613367},{"batb":[[0,1.55,33.44],[1,1.01,0.51],[2,1.55,0]],"ltp":2.68,"tv":477.29,"id":16573039},{"batb":[[0,5,31.35]],"ltp":5.2,"tv":51.1,"id":16573041}]}]}
{"op":"mcm","clk":"1011072226","pt":1580654374884,"mc":[{"id":"1.168222849","rc":[{"batb":[[1,4.9,34.94],[2,4.7,15.42]],"ltp":5.4,"tv":3.29,"id":19613369},{"batb":[[0,40,7.86],[1,38,9.1],[2,28,2.79]],"ltp":15.5,"tv":27.88,"id":19613367},{"batb":[[0,1.57,78.84],[1,1.56,77.16],[2,1.55,33.44]],"ltp":2.68,"tv":477.29,"id":16573039}]}]}
{"op":"mcm","clk":"1011073862","pt":1580654382610,"mc":[{"id":"1.168222849","rc":[{"batb":[[0,4.7,15.42],[1,1.01,0.51],[2,4.7,0]],"ltp":5.4,"tv":3.29,"id":19613369},{"batb":[[0,28,2.79],[1,1.01,0.51],[2,28,0]],"ltp":15.5,"tv":27.88,"id":19613367},{"batb":[[0,1.55,33.44],[1,1.01,0.51],[2,1.55,0]],"ltp":2.68,"tv":477.29,"id":16573039},{"batb":[[1,4.9,14.56]],"ltp":5.2,"tv":51.1,"id":16573041}]}]}
{"op":"mcm","clk":"1011074505","pt":1580654385701,"mc":[{"id":"1.168222849","rc":[{"batb":[[0,5.2,46.53],[1,5.1,31.72],[2,4.7,15.42]],"ltp":5.4,"tv":3.29,"id":19613369},{"batb":[[0,1.57,78.84],[1,1.56,77.16],[2,1.55,33.44]],"ltp":2.68,"tv":477.29,"id":16573039},{"batb":[[0,5.1,37.72],[1,5,31.35],[2,4.9,14.56]],"ltp":5.2,"tv":51.1,"id":16573041}]}]}
{"op":"mcm","clk":"1011074696","pt":1580654386604,"mc":[{"id":"1.168222849","rc":[{"batb":[[1,5.1,44.78],[2,4.9,10.08]],"batl":[[0,5.8,20.99],[1,6.2,11.49]],"ltp":5.4,"tv":3.29,"id":19613369},{"batb":[[0,1.01,0.51],[1,1.01,0]],"ltp":15.5,"tv":27.88,"id":19613367},{"batb":[[1,1.56,151.94]],"batl":[[0,1.61,32.65],[1,1.66,42.01],[2,1.67,28.64]],"ltp":2.68,"tv":477.29,"id":16573039},{"batb":[[0,5.2,12.83],[1,5.1,37.72],[2,5,55.36]],"batl":[[0,5.9,20.68],[1,6,11.88]],"ltp":5.2,"tv":51.1,"id":16573041}]}]}
{"op":"mcm","clk":"1011079708","pt":1580654409642,"mc":[{"id":"1.168222849","rc":[{"batb":[[0,4.8,14.79],[1,1.01,0.51],[2,4.9,0]],"batl":[[0,6.2,11.49],[1,6.2,0]],"ltp":5.4,"tv":3.29,"id":19613369},{"batb":[[0,1.52,36.19],[1,1.01,0.51],[2,1.55,0]],"batl":[[0,1.67,28.64],[1,1.66,0],[2,1.67,0]],"ltp":2.68,"tv":477.29,"id":16573039},{"batb":[[0,5,45.28],[1,1.01,0.51],[2,5,0]],"batl":[[0,6,11.88],[1,6,0]],"ltp":5.2,"tv":51.1,"id":16573041}]}]}
{"op":"mcm","clk":"1011080323","pt":1580654412522,"mc":[{"id":"1.168222849","rc":[{"batb":[[0,5,52.55],[1,4.9,34.64],[2,4.8,14.79]],"ltp":5.4,"tv":3.29,"id":19613369},{"batb":[[0,130,3.03],[1,120,2.31],[2,1.01,0.51]],"ltp":15.5,"tv":27.88,"id":19613367},{"batb":[[0,1.55,87.23],[1,1.54,81.29],[2,1.52,36.19]],"ltp":2.68,"tv":477.29,"id":16573039},{"batb":[[0,5,57.23],[1,4.9,32.47],[2,1.01,0.51]],"ltp":5.2,"tv":51.1,"id":16573041}]}]}
{"op":"mcm","clk":"1011080984","pt":1580654415558,"mc":[{"id":"1.168222849","rc":[{"batb":[[0,4.8,14.79],[1,1.01,0.51],[2,4.8,0]],"ltp":5.4,"tv":3.29,"id":19613369},{"batb":[[0,1.01,0.51],[1,120,0],[2,1.01,0]],"ltp":15.5,"tv":27.88,"id":19613367},{"batb":[[0,1.52,36.19],[1,1.01,0.51],[2,1.52,0]],"ltp":2.68,"tv":477.29,"id":16573039},{"batb":[[0,5,13.93],[1,1.01,0.51],[2,1.01,0]],"ltp":5.2,"tv":51.1,"id":16573041}]}]}
{"op":"mcm","clk":"1011081674","pt":1580654418676,"mc":[{"id":"1.168222849","rc":[{"batb":[[0,5.3,47.42],[1,5.2,30.35],[2,5,10.08]],"batl":[[0,5.9,8.4],[1,6.2,11.49]],"ltp":5.4,"tv":3.29,"id":19613369},{"batb":[[0,1.55,87.07],[1,1.54,158.44],[2,1.52,36.19]],"batl":[[0,1.64,42.01],[1,1.67,28.64]],"ltp":2.68,"tv":477.29,"id":16573039},{"batb":[[0,5.2,21.77],[1,5.1,29.95],[2,5,24.01]],"batl":[[0,5.9,8.4],[1,6,11.88]],"ltp":5.2,"tv":51.1,"id":16573041}]}]}
{"op":"mcm","clk":"1011081909","pt":1580654419655,"mc":[{"id":"1.168222849","rc":[{"batb":[[0,5.3,59.38]],"batl":[[2,7.2,16.76]],"ltp":5.4,"tv":3.29,"id":19613369},{"batl":[[0,1.58,35.33],[1,1.64,42.01],[2,1.68,28.4]],"ltp":2.68,"tv":477.29,"id":16573039},{"batb":[[0,5.3,12.35],[1,5.2,21.77],[2,5.1,29.95]],"batl":[[2,7.2,17]],"ltp":5.2,"tv":51.1,"id":16573041}]}]}
{"op":"mcm","clk":"1011083875","pt":1580654428745,"mc":[{"id":"1.168222849","rc":[{"batb":[[0,5.3,11.96],[1,5,10.08],[2,4.8,14.79]],"ltp":5.4,"tv":3.29,"id":19613369},{"batb":[[0,1.54,77.3],[1,1.52,36.19],[2,1.41,48.15]],"ltp":2.68,"tv":477.29,"id":16573039},{"batb":[[1,5,10.08],[2,4.8,15.34]],"ltp":5.2,"tv":51.1,"id":16573041}]}]}
{"op":"mcm","clk":"1011084049","pt":1580654429656,"mc":[{"id":"1.168222849","rc":[{"batb":[[0,1.01,0.51],[1,5,0],[2,4.8,0]],"ltp":5.4,"tv":3.29,"id":19613369},{"batb":[[0,1.01,0.51],[1,1.52,0],[2,1.41,0]],"ltp":2.68,"tv":477.29,"id":16573039},{"batb":[[0,1.01,0.51],[1,5,0],[2,4.8,0]],"ltp":5.2,"tv":51.1,"id":16573041}]}]}
{"op":"mcm","clk":"1011165955","pt":1580654804692,"mc":[{"id":"1.168222849","rc":[{"batb":[[0,4.7,10.92],[1,1.01,0.51]],"batl":[[0,5.6,8.4]],"ltp":5.4,"tv":3.29,"id":19613369},{"batb":[[0,1.59,70.58],[1,1.01,0.51]],"batl":[[0,1.72,42.01]],"ltp":2.68,"tv":477.29,"id":16573039},{"batb":[[0,4.6,10.92],[1,1.01,0.51]],"batl":[[0,5.5,9.24]],"ltp":5.2,"tv":51.1,"id":16573041}]}]}
{"op":"mcm","clk":"1011166133","pt":1580654805711,"mc":[{"id":"1.168222849","rc":[{"batb":[[0,1.01,0.51],[1,1.01,0]],"ltp":2.68,"tv":477.29,"id":16573039}]}]}
{"op":"mcm","clk":"1011166527","pt":1580654807548,"mc":[{"id":"1.168222849","rc":[{"batb":[[0,1.6,69.74],[1,1.01,0.51]],"ltp":2.68,"tv":477.29,"id":16573039}]}]}
{"op":"mcm","clk":"1011166918","pt":1580654809400,"mc":[{"id":"1.168222849","rc":[{"batb":[[0,1.01,0.51],[1,1.01,0]],"ltp":5.4,"tv":3.29,"id":19613369}]}]}
{"op":"mcm","clk":"1011167572","pt":1580654812721,"mc":[{"id":"1.168222849","rc":[{"batb":[[0,4.6,10.92],[1,1.01,0.51]],"batl":[[0,5.4,9.24]],"ltp":5.4,"tv":3.29,"id":19613369}]}]}
{"op":"mcm","clk":"1011168432","pt":1580654817066,"mc":[{"id":"1.168222849","rc":[{"batb":[[0,1.01,0.51],[1,1.01,0]],"ltp":2.68,"tv":477.29,"id":16573039},{"batb":[[0,1.01,0.51],[1,1.01,0]],"ltp":5.2,"tv":51.1,"id":16573041}]}]}
{"op":"mcm","clk":"1011169159","pt":1580654820721,"mc":[{"id":"1.168222849","rc":[{"batb":[[0,1.61,68.06],[1,1.01,0.51]],"ltp":2.68,"tv":477.29,"id":16573039},{"batb":[[0,4.7,10.92],[1,1.01,0.51]],"ltp":5.2,"tv":51.1,"id":16573041}]}]}
{"op":"mcm","clk":"1011169388","pt":1580654821852,"mc":[{"id":"1.168222849","rc":[{"batb":[[0,1.01,0.51],[1,1.01,0]],"ltp":5.4,"tv":3.29,"id":19613369},{"batb":[[0,1.01,0.51],[1,1.01,0]],"ltp":2.68,"tv":477.29,"id":16573039},{"batb":[[0,1.01,0.51],[1,1.01,0]],"ltp":5.2,"tv":51.1,"id":16573041}]}]}
{"op":"mcm","clk":"1011171635","pt":1580654832729,"mc":[{"id":"1.168222849","rc":[{"batb":[[0,4.4,11.76],[1,1.01,0.51]],"batl":[[0,5.1,10.08]],"ltp":5.4,"tv":3.29,"id":19613369},{"batb":[[0,1.66,63.01],[1,1.01,0.51]],"batl":[[0,1.79,42.01]],"ltp":2.68,"tv":477.29,"id":16573039},{"batb":[[0,4.4,11.76],[1,1.01,0.51]],"batl":[[0,5.2,9.24]],"ltp":5.2,"tv":51.1,"id":16573041}]}]}
{"op":"mcm","clk":"1011174831","pt":1580654848642,"mc":[{"id":"1.168222849","rc":[{"batb":[[0,1.01,0.51],[1,1.01,0]],"ltp":5.4,"tv":3.29,"id":19613369},{"batb":[[0,1.01,0.51],[1,1.01,0]],"ltp":2.68,"tv":477.29,"id":16573039},{"batb":[[0,1.01,0.51],[1,1.01,0]],"ltp":5.2,"tv":51.1,"id":16573041}]}]}
{"op":"mcm","clk":"1011178362","pt":1580654866690,"mc":[{"id":"1.168222849","rc":[{"batb":[[0,4.2,12.6],[1,1.01,0.51]],"batl":[[0,4.9,10.08]],"ltp":5.4,"tv":3.29,"id":19613369},{"batb":[[0,1.7,59.65],[1,1.01,0.51]],"batl":[[0,1.84,42.01]],"ltp":2.68,"tv":477.29,"id":16573039},{"batb":[[0,4.3,12.6],[1,1.01,0.51]],"batl":[[0,5.1,10.08]],"ltp":5.2,"tv":51.1,"id":16573041}]}]}
{"op":"mcm","clk":"1011182121","pt":1580654886623,"mc":[{"id":"1.168222849","rc":[{"batb":[[0,1.01,0.51],[1,1.01,0]],"ltp":5.4,"tv":3.29,"id":19613369},{"batb":[[0,1.01,0.51],[1,1.01,0]],"ltp":2.68,"tv":477.29,"id":16573039},{"batb":[[0,1.01,0.51],[1,1.01,0]],"ltp":5.2,"tv":51.1,"id":16573041}]}]}
{"op":"mcm","clk":"1011185311","pt":1580654902739,"mc":[{"id":"1.168222849","rc":[{"batb":[[0,4.3,12.6],[1,1.01,0.51]],"batl":[[0,5.1,10.08]],"ltp":5.4,"tv":3.29,"id":19613369},{"batb":[[0,1.66,63.01],[1,1.01,0.51]],"batl":[[0,1.8,42.01]],"ltp":2.68,"tv":477.29,"id":16573039},{"batb":[[0,4.4,11.76],[1,1.01,0.51]],"batl":[[0,5.2,9.24]],"ltp":5.2,"tv":51.1,"id":16573041}]}]}
{"op":"mcm","clk":"1011186903","pt":1580654911740,"mc":[{"id":"1.168222849","rc":[{"batb":[[0,1.01,0.51],[1,1.01,0]],"ltp":5.4,"tv":3.29,"id":19613369},{"batb":[[0,1.01,0.51],[1,1.01,0]],"ltp":2.68,"tv":477.29,"id":16573039},{"batb":[[0,1.01,0.51],[1,1.01,0]],"ltp":5.2,"tv":51.1,"id":16573041}]}]}
{"op":"mcm","clk":"1011191438","pt":1580654937161,"mc":[{"id":"1.168222849","rc":[{"batb":[[0,4.6,10.92],[1,1.01,0.51]],"batl":[[0,5.4,9.24]],"ltp":5.4,"tv":3.29,"id":19613369},{"batb":[[0,1.61,68.06],[1,1.01,0.51]],"batl":[[0,1.73,42.01]],"ltp":2.68,"tv":477.29,"id":16573039},{"batb":[[0,4.6,10.92],[1,1.01,0.51]],"batl":[[0,5.4,9.24]],"ltp":5.2,"tv":51.1,"id":16573041}]}]}
{"op":"mcm","clk":"1011194730","pt":1580654955694,"mc":[{"id":"1.168222849","rc":[{"batb":[[0,20,15.96],[1,1.01,0.51]],"ltp":15.5,"tv":27.88,"id":19613367}]}]}
{"op":"mcm","clk":"1011195577","pt":1580654960578,"mc":[{"id":"1.168222849","rc":[{"batb":[[0,1.01,0.51],[1,1.01,0]],"ltp":5.4,"tv":3.29,"id":19613369},{"batb":[[0,1.01,0.51],[1,1.01,0]],"ltp":2.68,"tv":477.29,"id":16573039},{"batb":[[0,1.01,0.51],[1,1.01,0]],"ltp":5.2,"tv":51.1,"id":16573041}]}]}
{"op":"mcm","clk":"1011200299","pt":1580654990778,"mc":[{"id":"1.168222849","rc":[{"batb":[[0,5.1,10.08],[1,1.01,0.51]],"batl":[[0,6,8.4]],"ltp":5.4,"tv":3.29,"id":19613369},{"batb":[[0,1.5,84.02],[1,1.01,0.51]],"batl":[[0,1.61,42.01]],"ltp":2.68,"tv":477.29,"id":16573039},{"batb":[[0,5.2,9.24],[1,1.01,0.51]],"batl":[[0,6.2,7.56]],"ltp":5.2,"tv":51.1,"id":16573041}]}]}
{"op":"mcm","clk":"1011204381","pt":1580655015889,"mc":[{"id":"1.168222849","rc":[{"batb":[[0,1.01,0.51],[1,1.01,0]],"ltp":5.4,"tv":3.29,"id":19613369},{"batb":[[0,1.01,0.51],[1,1.01,0]],"ltp":2.68,"tv":477.29,"id":16573039},{"batb":[[0,1.01,0.51],[1,1.01,0]],"ltp":5.2,"tv":51.1,"id":16573041}]}]}
{"op":"mcm","clk":"1011209644","pt":1580655048731,"mc":[{"id":"1.168222849","rc":[{"batb":[[0,6.2,7.56],[1,1.01,0.51]],"batl":[[0,7.6,5.88]],"ltp":5.4,"tv":3.29,"id":19613369},{"batb":[[0,1.36,115.95],[1,1.01,0.51]],"batl":[[0,1.44,42.01]],"ltp":2.68,"tv":477.29,"id":16573039},{"batb":[[0,6.6,6.72],[1,1.01,0.51]],"batl":[[0,8,5.88]],"ltp":5.2,"tv":51.1,"id":16573041}]}]}
{"op":"mcm","clk":"1011212996","pt":1580655069848,"mc":[{"id":"1.168222849","rc":[{"batb":[[0,1.01,0.51],[1,1.01,0]],"ltp":5.4,"tv":3.29,"id":19613369},{"batb":[[0,1.01,0.51],[1,1.01,0]],"ltp":2.68,"tv":477.29,"id":16573039},{"batb":[[0,1.01,0.51],[1,1.01,0]],"ltp":5.2,"tv":51.1,"id":16573041}]}]}
{"op":"mcm","clk":"1011218436","pt":1580655104897,"mc":[{"id":"1.168222849","rc":[{"batb":[[0,5.1,10.08],[1,1.01,0.51]],"batl":[[0,6.2,7.56]],"ltp":5.4,"tv":3.29,"id":19613369},{"batb":[[0,1.5,84.02],[1,1.01,0.51]],"batl":[[0,1.6,42.01]],"ltp":2.68,"tv":477.29,"id":16573039},{"batb":[[0,5.2,9.24],[1,1.01,0.51]],"batl":[[0,6.2,7.56]],"ltp":5.2,"tv":51.1,"id":16573041}]}]}
{"op":"mcm","clk":"1011222437","pt":1580655130462,"mc":[{"id":"1.168222849","rc":[{"batb":[[0,1.01,0.51],[1,1.01,0]],"ltp":5.4,"tv":3.29,"id":19613369},{"batb":[[0,1.01,0.51],[1,1.01,0]],"ltp":2.68,"tv":477.29,"id":16573039},{"batb":[[0,1.01,0.51],[1,1.01,0]],"ltp":5.2,"tv":51.1,"id":16573041}]}]}
{"op":"mcm","clk":"1011225357","pt":1580655148758,"mc":[{"id":"1.168222849","rc":[{"batb":[[0,4.7,10.92],[1,1.01,0.51]],"batl":[[0,5.6,8.4]],"ltp":5.4,"tv":3.29,"id":19613369},{"batb":[[0,1.59,70.58],[1,1.01,0.51]],"batl":[[0,1.72,42.01]],"ltp":2.68,"tv":477.29,"id":16573039},{"batb":[[0,4.6,10.92],[1,1.01,0.51]],"batl":[[0,5.5,9.24]],"ltp":5.2,"tv":51.1,"id":16573041}]}]}
{"op":"mcm","clk":"1011228666","pt":1580655167882,"mc":[{"id":"1.168222849","rc":[{"batb":[[0,1.01,0.51],[1,1.01,0]],"ltp":5.4,"tv":3.29,"id":19613369},{"batb":[[0,1.01,0.51],[1,1.01,0]],"ltp":2.68,"tv":477.29,"id":16573039},{"batb":[[0,1.01,0.51],[1,1.01,0]],"ltp":5.2,"tv":51.1,"id":16573041}]}]}
{"op":"mcm","clk":"1011230074","pt":1580655176800,"mc":[{"id":"1.168222849","rc":[{"batb":[[0,4.4,11.76],[1,1.01,0.51]],"batl":[[0,5.2,9.24]],"ltp":5.4,"tv":3.29,"id":19613369},{"batb":[[0,1.67,62.17],[1,1.01,0.51]],"batl":[[0,1.81,42.01]],"ltp":2.68,"tv":477.29,"id":16573039},{"batb":[[0,4.3,12.6],[1,1.01,0.51]],"batl":[[0,5.1,10.08]],"ltp":5.2,"tv":51.1,"id":16573041}]}]}
{"op":"mcm","clk":"1011240326","pt":1580655241790,"mc":[{"id":"1.168222849","rc":[{"batb":[[0,1.01,0.51],[1,1.01,0]],"ltp":5.4,"tv":3.29,"id":19613369},{"batb":[[0,1.01,0.51],[1,1.01,0]],"ltp":2.68,"tv":477.29,"id":16573039},{"batb":[[0,1.01,0.51],[1,1.01,0]],"ltp":5.2,"tv":51.1,"id":16573041}]}]}
{"op":"mcm","clk":"1011243658","pt":1580655262797,"mc":[{"id":"1.168222849","rc":[{"batb":[[0,3.95,13.44],[1,1.01,0.51]],"batl":[[0,4.6,10.92]],"ltp":5.4,"tv":3.29,"id":19613369},{"batb":[[0,1.81,51.25],[1,1.01,0.51]],"batl":[[0,1.98,42.01]],"ltp":2.68,"tv":477.29,"id":16573039},{"batb":[[0,3.9,14.28],[1,1.01,0.51]],"batl":[[0,4.5,11.76]],"ltp":5.2,"tv":51.1,"id":16573041}]}]}
{"op":"mcm","clk":"1011246278","pt":1580655278314,"mc":[{"id":"1.168222849","rc":[{"batb":[[0,1.01,0.51],[1,1.01,0]],"ltp":5.4,"tv":3.29,"id":19613369},{"batb":[[0,1.01,0.51],[1,1.01,0]],"ltp":2.68,"tv":477.29,"id":16573039},{"batb":[[0,1.01,0.51],[1,1.01,0]],"ltp":5.2,"tv":51.1,"id":16573041}]}]}
{"op":"mcm","clk":"1011249760","pt":1580655298759,"mc":[{"id":"1.168222849","rc":[{"batb":[[0,4.3,12.6],[1,1.01,0.51]],"batl":[[0,5,10.08]],"ltp":5.4,"tv":3.29,"id":19613369},{"batb":[[0,1.71,58.81],[1,1.01,0.51]],"batl":[[0,1.85,42.01]],"ltp":2.68,"tv":477.29,"id":16573039},{"batb":[[0,4.2,12.6],[1,1.01,0.51]],"batl":[[0,4.9,10.08]],"ltp":5.2,"tv":51.1,"id":16573041}]}]}
{"op":"mcm","clk":"1011253456","pt":1580655319774,"mc":[{"id":"1.168222849","rc":[{"batb":[[0,1.01,0.51],[1,1.01,0]],"ltp":5.4,"tv":3.29,"id":19613369},{"batb":[[0,1.01,0.51],[1,1.01,0]],"ltp":2.68,"tv":477.29,"id":16573039},{"batb":[[0,1.01,0.51],[1,1.01,0]],"ltp":5.2,"tv":51.1,"id":16573041}]}]}
{"op":"mcm","clk":"1011254801","pt":1580655327069,"mc":[{"id":"1.168222849","rc":[{"batb":[[0,4.5,11.76],[1,1.01,0.51]],"batl":[[0,5.4,9.24]],"ltp":5.4,"tv":3.29,"id":19613369},{"batb":[[0,1.62,67.22],[1,1.01,0.51]],"batl":[[0,1.75,42.01]],"ltp":2.68,"tv":477.29,"id":16573039},{"batb":[[0,4.5,11.76],[1,1.01,0.51]],"batl":[[0,5.3,9.24]],"ltp":5.2,"tv":51.1,"id":16573041}]}]}
{"op":"mcm","clk":"1011257754","pt":1580655343922,"mc":[{"id":"1.168222849","rc":[{"batb":[[0,1.01,0.51],[1,1.01,0]],"ltp":5.4,"tv":3.29,"id":19613369},{"batb":[[0,1.01,0.51],[1,1.01,0]],"ltp":2.68,"tv":477.29,"id":16573039},{"batb":[[0,1.01,0.51],[1,1.01,0]],"ltp":5.2,"tv":51.1,"id":16573041}]}]}
{"op":"mcm","clk":"1011259028","pt":1580655351519,"mc":[{"id":"1.168222849","rc":[{"batb":[[0,4.8,10.92],[1,1.01,0.51]],"batl":[[0,5.7,8.4]],"ltp":5.4,"tv":3.29,"id":19613369},{"batb":[[0,1.57,73.1],[1,1.01,0.51]],"batl":[[0,1.69,42.01]],"ltp":2.68,"tv":477.29,"id":16573039},{"batb":[[0,4.7,10.92],[1,1.01,0.51]],"batl":[[0,5.6,8.4]],"ltp":5.2,"tv":51.1,"id":16573041}]}]}
{"op":"mcm","clk":"1011260232","pt":1580655359007,"mc":[{"id":"1.168222849","rc":[{"batb":[[1,4.5,17.47],[2,1.01,0.51]],"batl":[[1,6.2,11.49]],"ltp":5.4,"tv":3.29,"id":19613369},{"batb":[[1,1.53,35.49],[2,1.01,0.51]],"batl":[[1,1.74,25.1]],"ltp":2.68,"tv":477.29,"id":16573039},{"batb":[[1,4.6,16.92],[2,1.01,0.51]],"batl":[[1,5.9,12.43]],"ltp":5.2,"tv":51.1,"id":16573041}]}]}
{"op":"mcm","clk":"1011261962","pt":1580655369833,"mc":[{"id":"1.168222849","rc":[{"batb":[[0,4.5,17.47],[1,1.01,0.51],[2,1.01,0]],"batl":[[0,6.2,11.49],[1,6.2,0]],"ltp":5.4,"tv":3.29,"id":19613369},{"batb":[[0,1.53,35.49],[1,1.01,0.51],[2,1.01,0]],"batl":[[0,1.74,25.1],[1,1.74,0]],"ltp":2.68,"tv":477.29,"id":16573039},{"batb":[[0,4.6,16.92],[1,1.01,0.51],[2,1.01,0]],"batl":[[0,5.9,12.43],[1,5.9,0]],"ltp":5.2,"tv":51.1,"id":16573041}]}]}
{"op":"mcm","clk":"1011267536","pt":1580655407085,"mc":[{"id":"1.168222849","rc":[{"batb":[[0,5.3,11.96],[1,5,10.08],[2,4.8,15.19]],"batl":[[0,6,8.4],[1,6.2,11.49],[2,7.4,15.89]],"ltp":5.4,"tv":3.29,"id":19613369},{"batb":[[0,1.54,77.3],[1,1.53,35.49],[2,1.41,48.63]],"batl":[[0,1.59,34.62],[1,1.65,42.01],[2,1.69,27.3]],"ltp":2.68,"tv":477.29,"id":16573039},{"batb":[[0,5.2,12.9],[1,4.8,10.92],[2,4.7,16.44]],"batl":[[0,5.8,8.4],[1,5.9,12.43],[2,7,17.62]],"ltp":5.2,"tv":51.1,"id":16573041}]}]}
{"op":"mcm","clk":"1011271405","pt":1580655432597,"mc":[{"id":"1.168222849","rc":[{"batb":[[0,1.01,0.51],[1,1.01,0]],"ltp":15.5,"tv":27.88,"id":19613367}]}]}
{"op":"mcm","clk":"1011272622","pt":1580655441214,"mc":[{"id":"1.168222849","rc":[{"batb":[[0,5,10.08],[1,4.8,15.19],[2,1.01,0.51]],"batl":[[1,7.4,15.89],[2,7.4,0]],"ltp":5.4,"tv":3.29,"id":19613369},{"batb":[[1,1.41,48.63],[2,1.01,0.51]],"batl":[[0,1.65,42.01],[1,1.69,27.3],[2,1.69,0]],"ltp":2.68,"tv":477.29,"id":16573039},{"batb":[[0,4.8,10.92],[1,4.7,16.44],[2,1.01,0.51]],"batl":[[1,7,17.62],[2,7,0]],"ltp":5.2,"tv":51.1,"id":16573041}]}]}
{"op":"mcm","clk":"1011272709","pt":1580655441906,"mc":[{"id":"1.168222849","rc":[{"batb":[[0,4.8,15.19],[1,1.01,0.51],[2,1.01,0]],"batl":[[0,7.4,15.89],[1,7.4,0]],"ltp":5.4,"tv":3.29,"id":19613369},{"batb":[[0,1.41,48.63],[1,1.01,0.51],[2,1.01,0]],"batl":[[0,1.69,27.3],[1,1.69,0]],"ltp":2.68,"tv":477.29,"id":16573039},{"batb":[[0,4.7,16.44],[1,1.01,0.51],[2,1.01,0]],"batl":[[0,7,17.62],[1,7,0]],"ltp":5.2,"tv":51.1,"id":16573041}]}]}
{"op":"mcm","clk":"1011273079","pt":1580655444645,"mc":[{"id":"1.168222849","rc":[{"batb":[[0,4.7,15.82]],"batl":[[0,7.2,16.52]],"ltp":5.4,"tv":3.29,"id":19613369},{"batb":[[0,1.42,47.92]],"batl":[[0,1.7,26.91]],"ltp":2.68,"tv":477.29,"id":16573039},{"batb":[[0,4.7,16.29]],"batl":[[0,7,17.47]],"ltp":5.2,"tv":51.1,"id":16573041}]}]}
{"op":"mcm","clk":"1011273843","pt":1580655449632,"mc":[{"id":"1.168222849","rc":[{"batb":[[1,4.3,19.43],[2,1.01,0.51]],"batl":[[0,5.3,15.11],[1,6.2,11.17]],"ltp":5.4,"tv":3.29,"id":19613369},{"batb":[[0,1.64,27.46],[1,1.51,36.98],[2,1.01,0.51]],"batl":[[1,1.81,21.95]],"ltp":2.68,"tv":477.29,"id":16573039},{"batb":[[1,4.4,19.43],[2,1.01,0.51]],"batl":[[0,5.3,15.58],[1,6.2,11.72]],"ltp":5.2,"tv":51.1,"id":16573041}]}]}
{"op":"mcm","clk":"1011274123","pt":1580655451646,"mc":[{"id":"1.168222849","rc":[{"batb":[[0,4.7,26.74]],"batl":[[1,5.6,8.4],[2,6.2,11.17]],"ltp":5.4,"tv":3.29,"id":19613369},{"batb":[[1,1.6,69.74],[2,1.51,36.98]],"batl":[[1,1.71,42.01],[2,1.81,21.95]],"ltp":2.68,"tv":477.29,"id":16573039},{"batb":[[1,4.6,10.92],[2,4.4,19.43]],"batl":[[0,5.3,24.82]],"ltp":5.2,"tv":51.1,"id":16573041}]}]}
{"op":"mcm","clk":"1011275719","pt":1580655462674,"mc":[{"id":"1.168222849","rc":[{"batb":[[0,4.7,10.92]],"batl":[[0,5.6,8.4],[1,6.2,11.17],[2,6.2,0]],"ltp":5.4,"tv":3.29,"id":19613369},{"batb":[[0,1.6,69.74],[1,1.51,36.98],[2,1.01,0.51]],"batl":[[0,1.71,42.01],[1,1.81,21.95],[2,1.81,0]],"ltp":2.68,"tv":477.29,"id":16573039},{"batb":[[0,4.6,10.92],[1,4.4,19.43],[2,1.01,0.51]],"batl":[[0,5.3,9.24]],"ltp":5.2,"tv":51.1,"id":16573041}]}]}
{"op":"mcm","clk":"1011275928","pt":1580655463949,"mc":[{"id":"1.168222849","rc":[{"batb":[[0,4.3,19.43],[1,1.01,0.51],[2,1.01,0]],"batl":[[0,6.2,11.17],[1,6.2,0]],"ltp":5.4,"tv":3.29,"id":19613369},{"batb":[[0,1.51,36.98],[1,1.01,0.51],[2,1.01,0]],"batl":[[0,1.81,21.95],[1,1.81,0]],"ltp":2.68,"tv":477.29,"id":16573039},{"batb":[[0,4.4,19.43],[1,1.01,0.51],[2,1.01,0]],"batl":[[0,6.2,11.72],[1,6.2,0]],"ltp":5.2,"tv":51.1,"id":16573041}]}]}
{"op":"mcm","clk":"1011277435","pt":1580655474466,"mc":[{"id":"1.168222849","rc":[{"batb":[[0,5.4,11.57],[1,4.7,15.42],[2,4.3,19.43]],"batl":[[1,7.6,14.79]],"ltp":5.4,"tv":3.29,"id":19613369},{"batb":[[1,1.38,53.11],[2,1.01,0.51]],"batl":[[0,1.57,36.12],[1,1.69,27.38],[2,1.81,21.95]],"ltp":2.68,"tv":477.29,"id":16573039},{"batb":[[0,5.4,12.2],[1,4.7,16.21],[2,4.4,19.43]],"batl":[[1,7.4,15.42]],"ltp":5.2,"tv":51.1,"id":16573041}]}]}
{"op":"mcm","clk":"1011277515","pt":1580655475040,"mc":[{"id":"1.168222849","rc":[{"batb":[[1,5.1,10.08],[2,4.7,15.42]],"batl":[[0,6.2,18.73]],"ltp":5.4,"tv":3.29,"id":19613369},{"batb":[[0,1.52,80.66],[1,1.51,36.98],[2,1.38,53.11]],"batl":[[1,1.63,42.01],[2,1.69,27.38]],"ltp":2.68,"tv":477.29,"id":16573039},{"batb":[[1,4.9,10.08],[2,4.7,16.21]],"batl":[[0,5.9,8.4],[1,6.2,11.72],[2,7.4,15.42]],"ltp":5.2,"tv":51.1,"id":16573041}]}]}
{"op":"mcm","clk":"1011279805","pt":1580655490917,"mc":[{"id":"1.168222849","rc":[{"batb":[[0,5.1,10.08],[1,4.7,15.42],[2,1.01,0.51]],"batl":[[0,6.2,7.56]],"ltp":5.4,"tv":3.29,"id":19613369},{"batb":[[1,1.38,53.11],[2,1.01,0.51]],"batl":[[0,1.63,42.01],[1,1.69,27.38],[2,1.69,0]],"ltp":2.68,"tv":477.29,"id":16573039},{"batb":[[0,4.9,10.08],[1,4.7,16.21],[2,1.01,0.51]],"batl":[[1,7.4,15.42],[2,7.4,0]],"ltp":5.2,"tv":51.1,"id":16573041}]}]}
{"op":"mcm","clk":"1011280001","pt":1580655492293,"mc":[{"id":"1.168222849","rc":[{"batb":[[0,4.7,15.42],[1,1.01,0.51],[2,1.01,0]],"batl":[[0,7.6,14.79],[1,7.6,0]],"ltp":5.4,"tv":3.29,"id":19613369},{"batb":[[0,1.38,53.11],[1,1.01,0.51],[2,1.01,0]],"batl":[[0,1.69,27.38],[1,1.69,0]],"ltp":2.68,"tv":477.29,"id":16573039},{"batb":[[0,4.7,16.21],[1,1.01,0.51],[2,1.01,0]],"batl":[[0,7.4,15.42],[1,7.4,0]],"ltp":5.2,"tv":51.1,"id":16573041}]}]}
{"op":"mcm","clk":"1011280315","pt":1580655494297,"mc":[{"id":"1.168222849","rc":[{"batb":[[0,1.38,52.95]],"batl":[[0,1.7,27.3]],"ltp":2.68,"tv":477.29,"id":16573039}]}]}
{"op":"mcm","clk":"1011280976","pt":1580655498690,"mc":[{"id":"1.168222849","rc":[{"batb":[[1,4.3,19.51],[2,1.01,0.51]],"batl":[[0,5.4,14.87],[1,6.4,10.7],[2,7.6,14.79]],"ltp":5.4,"tv":3.29,"id":19613369},{"batb":[[0,1.63,27.85],[1,1.5,38.32],[2,1.38,52.95]],"batl":[[1,1.82,21.4]],"ltp":2.68,"tv":477.29,"id":16573039},{"batb":[[1,4.3,20.3],[2,1.01,0.51]],"batl":[[0,5.3,15.42],[1,6.2,11.41],[2,7.4,15.42]],"ltp":5.2,"tv":51.1,"id":16573041}]}]}
{"op":"mcm","clk":"1011281113","pt":1580655499588,"mc":[{"id":"1.168222849","rc":[{"batb":[[0,4.8,10.92],[1,4.7,15.42],[2,4.3,19.51]],"batl":[[1,5.7,8.4],[2,6.4,10.7]],"ltp":5.4,"tv":3.29,"id":19613369},{"batb":[[1,1.6,69.74],[2,1.5,38.32]],"batl":[[1,1.71,42.01],[2,1.82,21.4]],"ltp":2.68,"tv":477.29,"id":16573039},{"batb":[[1,4.6,10.92],[2,4.3,20.3]],"batl":[[0,5.3,24.66],[2,7.4,0]],"ltp":5.2,"tv":51.1,"id":16573041}]}]}
{"op":"mcm","clk":"1011281216","pt":1580655500288,"mc":[{"id":"1.168222849","rc":[{"batb":[[0,7,13.44],[1,1.01,0.51]],"ltp":15.5,"tv":27.88,"id":19613367}]}]}
{"op":"mcm","clk":"1011283100","pt":1580655512693,"mc":[{"id":"1.168222849","rc":[{"batb":[[1,4.3,19.51],[2,1.01,0.51]],"batl":[[0,5.7,8.4],[1,6.4,10.7],[2,6.4,0]],"ltp":5.4,"tv":3.29,"id":19613369},{"batb":[[0,1.6,69.74],[1,1.5,38.32],[2,1.01,0.51]],"batl":[[0,1.71,42.01],[1,1.82,21.4],[2,1.82,0]],"ltp":2.68,"tv":477.29,"id":16573039},{"batb":[[0,4.6,10.92],[1,4.3,20.3],[2,1.01,0.51]],"batl":[[0,5.3,9.24]],"ltp":5.2,"tv":51.1,"id":16573041}]}]}
{"op":"mcm","clk":"1011283271","pt":1580655513911,"mc":[{"id":"1.168222849","rc":[{"batb":[[0,4.3,19.51],[1,1.01,0.51],[2,1.01,0]],"batl":[[0,6.4,10.7],[1,6.4,0]],"ltp":5.4,"tv":3.29,"id":19613369},{"batb":[[0,1.5,38.32],[1,1.01,0.51],[2,1.01,0]],"batl":[[0,1.82,21.4],[1,1.82,0]],"ltp":2.68,"tv":477.29,"id":16573039},{"batb":[[0,4.3,20.3],[1,1.01,0.51],[2,1.01,0]],"batl":[[0,6.2,11.41],[1,6.2,0]],"ltp":5.2,"tv":51.1,"id":16573041}]}]}
{"op":"mcm","clk":"1011285419","pt":1580655528751,"mc":[{"id":"1.168222849","rc":[{"batb":[[0,1.01,0.51],[1,1.01,0]],"ltp":15.5,"tv":27.88,"id":19613367}]}]}
{"op":"mcm","clk":"1011285919","pt":1580655532129,"mc":[{"id":"1.168222849","rc":[{"batb":[[1,4,22.9],[2,1.01,0.51]],"batl":[[0,4.9,18.57],[1,5.4,14.95]],"ltp":5.4,"tv":3.29,"id":19613369},{"batb":[[0,1.75,21.79],[1,1.64,27.07],[2,1.01,0.51]],"batl":[[1,1.91,18.41]],"ltp":2.68,"tv":477.29,"id":16573039},{"batb":[[1,4.1,22.58],[2,1.01,0.51]],"batl":[[0,4.8,19.28],[1,5.2,16.21]],"ltp":5.2,"tv":51.1,"id":16573041}]}]}
{"op":"mcm","clk":"1011286120","pt":1580655533651,"mc":[{"id":"1.168222849","rc":[{"batb":[[0,4.5,11.76],[1,4.3,19.51],[2,4,22.9]],"batl":[[1,5.4,24.19]],"ltp":5.4,"tv":3.29,"id":19613369},{"batb":[[1,1.66,63.01],[2,1.64,27.07]],"batl":[[0,1.8,42.01],[1,1.82,21.4],[2,1.91,18.41]],"ltp":2.68,"tv":477.29,"id":16573039},{"batb":[[0,4.3,32.9]],"batl":[[1,5,10.08],[2,5.2,16.21]],"ltp":5.2,"tv":51.1,"id":16573041}]}]}
{"op":"mcm","clk":"1011287884","pt":1580655544754,"mc":[{"id":"1.168222849","rc":[{"batb":[[1,4,22.9],[2,1.01,0.51]],"batl":[[0,5.4,24.19],[1,5.4,0]],"ltp":5.4,"tv":3.29,"id":19613369},{"batb":[[0,1.66,63.01],[1,1.64,27.07],[2,1.01,0.51]],"batl":[[1,1.91,18.41],[2,1.91,0]],"ltp":2.68,"tv":477.29,"id":16573039},{"batb":[[0,4.3,12.6]],"batl":[[0,5,10.08],[1,5.2,16.21],[2,5.2,0]],"ltp":5.2,"tv":51.1,"id":16573041}]}]}
{"op":"mcm","clk":"1011288202","pt":1580655546752,"mc":[{"id":"1.168222849","rc":[{"batb":[[0,4,22.9],[1,1.01,0.51],[2,1.01,0]],"batl":[[0,5.4,14.95]],"ltp":5.4,"tv":3.29,"id":19613369},{"batb":[[0,1.64,27.07],[1,1.01,0.51],[2,1.01,0]],"batl":[[0,1.91,18.41],[1,1.91,0]],"ltp":2.68,"tv":477.29,"id":16573039},{"batb":[[0,4.1,22.58],[1,1.01,0.51],[2,1.01,0]],"batl":[[0,5.2,16.21],[1,5.2,0]],"ltp":5.2,"tv":51.1,"id":16573041}]}]}
{"op":"mcm","clk":"1011289846","pt":1580655556587,"mc":[{"id":"1.168222849","rc":[{"batb":[[0,4.7,15.66],[1,4.2,20.22],[2,4,22.9]],"batl":[[1,6.4,20.46]],"ltp":5.4,"tv":3.29,"id":19613369},{"batb":[[1,1.48,39.5],[2,1.01,0.51]],"batl":[[0,1.71,26.52],[1,1.86,20.06],[2,1.91,18.41]],"ltp":2.68,"tv":477.29,"id":16573039},{"batb":[[0,4.6,17],[1,4.1,22.58],[2,1.01,0.51]],"batl":[[1,6.2,11.17]],"ltp":5.2,"tv":51.1,"id":16573041}]}]}
{"op":"mcm","clk":"1011289977","pt":1580655557408,"mc":[{"id":"1.168222849","rc":[{"batb":[[0,4.8,10.92],[1,4.7,15.66],[2,4.2,20.22]],"batl":[[1,5.6,8.4],[2,6.4,20.46]],"ltp":5.4,"tv":3.29,"id":19613369},{"batb":[[1,1.6,69.74],[2,1.48,39.5]],"batl":[[1,1.73,42.01],[2,1.86,20.06]],"ltp":2.68,"tv":477.29,"id":16573039},{"batb":[[1,4.5,11.76],[2,4.1,21.95]],"batl":[[0,5.2,25.45]],"ltp":5.2,"tv":51.1,"id":16573041}]}]}
{"op":"mcm","clk":"1011292523","pt":1580655572667,"mc":[{"id":"1.168222849","rc":[{"batb":[[1,4.2,20.22],[2,1.01,0.51]],"batl":[[0,5.6,8.4],[1,6.4,20.46],[2,6.4,0]],"ltp":5.4,"tv":3.29,"id":19613369},{"batb":[[0,1.6,69.74],[1,1.48,39.5],[2,1.01,0.51]],"batl":[[0,1.73,42.01],[1,1.86,20.06],[2,1.86,0]],"ltp":2.68,"tv":477.29,"id":16573039},{"batb":[[0,4.5,11.76],[1,4.1,21.95],[2,1.01,0.51]],"batl":[[0,5.2,9.24]],"ltp":5.2,"tv":51.1,"id":16573041}]}]}
{"op":"mcm","clk":"1011292722","pt":1580655573998,"mc":[{"id":"1.168222849","rc":[{"batb":[[0,4.2,20.22],[1,1.01,0.51],[2,1.01,0]],"batl":[[0,6.4,20.46],[1,6.4,0]],"ltp":5.4,"tv":3.29,"id":19613369},{"batb":[[0,1.48,39.5],[1,1.01,0.51],[2,1.01,0]],"batl":[[0,1.86,20.06],[1,1.86,0]],"ltp":2.68,"tv":477.29,"id":16573039},{"batb":[[0,4.1,21.95],[1,1.01,0.51],[2,1.01,0]],"batl":[[0,6.2,11.17],[1,6.2,0]],"ltp":5.2,"tv":51.1,"id":16573041}]}]}
{"op":"mcm","clk":"1011293441","pt":1580655578721,"mc":[{"id":"1.168222849","rc":[{"batb":[[1,3.75,13.61],[2,1.01,0.51]],"batl":[[0,4.8,19.2],[1,5.2,16.29],[2,6.4,20.46]],"ltp":5.4,"tv":3.29,"id":19613369},{"batb":[[0,1.79,20.38],[1,1.68,24.94],[2,1.48,39.5]],"batl":[[1,2.1,27.7]],"ltp":2.68,"tv":477.29,"id":16573039},{"batb":[[1,3.7,14.4],[2,1.01,0.51]],"batl":[[0,4.7,20.85],[1,5.1,17.31],[2,6.2,11.17]],"ltp":5.2,"tv":51.1,"id":16573041}]}]}
{"op":"mcm","clk":"1011293471","pt":1580655578885,"mc":[{"id":"1.168222849","rc":[{"batb":[[0,4.4,11.76],[1,4.2,20.22],[2,3.75,13.61]],"batl":[[1,5.2,25.53],[2,6.4,0]],"ltp":5.4,"tv":3.29,"id":19613369},{"batb":[[1,1.69,60.49],[2,1.68,24.94]],"batl":[[0,1.83,42.01],[1,1.86,20.06],[2,2.1,27.7]],"ltp":2.68,"tv":477.29,"id":16573039},{"batb":[[0,4.2,12.6],[1,4.1,21.95],[2,3.7,14.4]],"batl":[[1,4.8,10.92],[2,5.1,17.31]],"ltp":5.2,"tv":51.1,"id":16573041}]}]}
{"op":"mcm","clk":"1011295377","pt":1580655590536,"mc":[{"id":"1.168222849","rc":[{"batb":[[0,4.5,39.79],[1,4.4,56.22],[2,4.2,20.22]],"ltp":5.4,"tv":3.29,"id":19613369},{"batb":[[1,1.77,92.83],[2,1.75,101.18]],"ltp":2.68,"tv":477.29,"id":16573039},{"batb":[[1,4.1,70.4],[2,4,51.89]],"ltp":5.2,"tv":51.1,"id":16573041}]}]}
{"op":"mcm","clk":"1011298890","pt":1580655609478,"mc":[{"id":"1.168222849","rc":[{"batb":[[2,4.3,19.83]],"batl":[[0,4.8,18.8],[1,5.2,25.14]],"ltp":5.4,"tv":3.29,"id":19613369},{"batb":[[0,1.78,20.85]],"batl":[[1,1.85,20.46]],"ltp":2.68,"tv":477.29,"id":16573039},{"batb":[[0,4.2,34.24],[1,4.1,48.45]],"batl":[[0,4.7,20.54],[2,5.1,17.07]],"ltp":5.2,"tv":51.1,"id":16573041}]}]}
{"op":"mcm","clk":"1011311536","pt":1580655682564,"mc":[{"id":"1.168222849","rc":[{"batb":[[0,4.4,11.76],[1,4.3,19.83],[2,3.75,13.3]],"ltp":5.4,"tv":3.29,"id":19613369},{"batb":[[1,1.69,60.49],[2,1.67,25.41]],"ltp":2.68,"tv":477.29,"id":16573039},{"batb":[[1,3.75,14.24],[2,1.01,0.51]],"ltp":5.2,"tv":51.1,"id":16573041}]}]}
{"op":"mcm","clk":"1011311689","pt":1580655683385,"mc":[{"id":"1.168222849","rc":[{"batb":[[1,3.75,13.3],[2,1.01,0.51]],"batl":[[0,5.2,25.14],[1,5.2,0]],"ltp":5.4,"tv":3.29,"id":19613369},{"batb":[[0,1.69,60.49],[1,1.67,25.41],[2,1.01,0.51]],"batl":[[1,2.1,27.7],[2,2.1,0]],"ltp":2.68,"tv":477.29,"id":16573039},{"batb":[[0,4.2,12.6]],"batl":[[0,4.8,10.92],[1,5.1,17.07],[2,5.1,0]],"ltp":5.2,"tv":51.1,"id":16573041}]}]}
{"op":"mcm","clk":"1011311818","pt":1580655683983,"mc":[{"id":"1.168222849","rc":[{"batb":[[0,3.75,13.3],[1,1.01,0.51],[2,1.01,0]],"batl":[[0,5.2,15.89]],"ltp":5.4,"tv":3.29,"id":19613369},{"batb":[[0,1.67,25.41],[1,1.01,0.51],[2,1.01,0]],"batl":[[0,2.1,27.7],[1,2.1,0]],"ltp":2.68,"tv":477.29,"id":16573039},{"batb":[[0,3.75,14.24],[1,1.01,0.51],[2,1.01,0]],"batl":[[0,5.1,17.07],[1,5.1,0]],"ltp":5.2,"tv":51.1,"id":16573041}]}]}
{"op":"mcm","clk":"1011312110","pt":1580655685481,"mc":[{"id":"1.168222849","rc":[{"batb":[[0,3.95,44.97],[1,3.9,29.71],[2,3.75,13.3]],"ltp":5.4,"tv":3.29,"id":19613369},{"batb":[[0,1.68,64.96],[1,1.67,25.41],[2,1.66,121.51]],"ltp":2.68,"tv":477.29,"id":16573039},{"batb":[[1,3.65,47.22],[2,3.6,33.87]],"ltp":5.2,"tv":51.1,"id":16573041}]}]}
