{"op":"mcm","clk":"1004097111","pt":1580580427532,"mc":[{"id":"1.168222848","marketDefinition":{"bspMarket":false,"turnInPlayEnabled":true,"persistenceEnabled":true,"marketBaseRate":5.0,"eventId":"29681551","eventTypeId":"2","numberOfWinners":1,"bettingType":"ODDS","marketType":"MATCH_ODDS","marketTime":"2020-02-02T13:00:00.000Z","suspendTime":"2020-02-02T13:00:00.000Z","bspReconciled":false,"complete":true,"inPlay":false,"crossMatching":false,"runnersVoidable":false,"numberOfActiveRunners":2,"betDelay":0,"status":"OPEN","runners":[{"status":"ACTIVE","sortPriority":1,"id":11772759,"name":"Juan Pablo Varillas"},{"status":"ACTIVE","sortPriority":2,"id":9631075,"name":"Carlos Taberner"}],"regulators":["MR_INT"],"countryCode":"AR","discountAllowed":false,"timezone":"UTC","openDate":"2020-02-02T13:00:00.000Z","version":3146764511,"name":"Match Odds","eventName":"Jua Varillas v Taberner"},"rc":[{"batb":[[0,1.05,152.2],[1,1.04,168.86],[2,1.03,237.77]],"ltp":0.0,"tv":0.0,"id":9631075},{"batb":[[0,1.05,152.2],[1,1.04,168.86],[2,1.03,237.77]],"ltp":0.0,"tv":0.0,"id":11772759}]}]}
{"op":"mcm","clk":"1004097346","pt":1580580428747,"mc":[{"id":"1.168222848","marketDefinition":{"bspMarket":false,"turnInPlayEnabled":true,"persistenceEnabled":true,"marketBaseRate":5.0,"eventId":"29681551","eventTypeId":"2","numberOfWinners":1,"bettingType":"ODDS","marketType":"MATCH_ODDS","marketTime":"2020-02-02T13:00:00.000Z","suspendTime":"2020-02-02T13:00:00.000Z","bspReconciled":false,"complete":true,"inPlay":false,"crossMatching":false,"runnersVoidable":false,"numberOfActiveRunners":2,"betDelay":0,"status":"OPEN","runners":[{"status":"ACTIVE","sortPriority":1,"id":11772759,"name":"Juan Pablo Varillas"},{"status":"ACTIVE","sortPriority":2,"id":9631075,"name":"Carlos Taberner"}],"regulators":["MR_INT"],"countryCode":"AR","discountAllowed":false,"timezone":"UTC","openDate":"2020-02-02T13:00:00.000Z","version":3146764511,"name":"Match Odds","eventName":"Jua Varillas v Taberner"}}]}
{"op":"mcm","clk":"1004097530","pt":1580580429751,"mc":[{"id":"1.168222848","marketDefinition":{"bspMarket":false,"turnInPlayEnabled":true,"persistenceEnabled":true,"marketBaseRate":5.0,"eventId":"29681551","eventTypeId":"2","numberOfWinners":1,"bettingType":"ODDS","marketType":"MATCH_ODDS","marketTime":"2020-02-02T13:00:00.000Z","suspendTime":"2020-02-02T13:00:00.000Z","bspReconciled":false,"complete":true,"inPlay":false,"crossMatching":false,"runnersVoidable":false,"numberOfActiveRunners":2,"betDelay":0,"status":"OPEN","runners":[{"status":"ACTIVE","sortPriority":1,"id":11772759,"name":"Juan Pablo Varillas"},{"status":"ACTIVE","sortPriority":2,"id":9631075,"name":"Carlos Taberner"}],"regulators":["MR_INT"],"countryCode":"AR","discountAllowed":true,"timezone":"UTC","openDate":"2020-02-02T13:00:00.000Z","version":3146764511,"name":"Match Odds","eventName":"Jua Varillas v Taberner"}}]}
{"op":"mcm","clk":"1004152919","pt":1580580734976,"mc":[{"id":"1.168222848","rc":[{"batl":[[0,990,2.2]],"ltp":0.0,"tv":0.0,"id":9631075},{"batl":[[0,990,2.2]],"ltp":0.0,"tv":0.0,"id":11772759}]}]}
{"op":"mcm","clk":"1004155788","pt":1580580749884,"mc":[{"id":"1.168222848","marketDefinition":{"bspMarket":false,"turnInPlayEnabled":true,"persistenceEnabled":true,"marketBaseRate":5.0,"eventId":"29681551","eventTypeId":"2","numberOfWinners":1,"bettingType":"ODDS","marketType":"MATCH_ODDS","marketTime":"2020-02-02T13:00:00.000Z","suspendTime":"2020-02-02T13:00:00.000Z","bspReconciled":false,"complete":true,"inPlay":false,"crossMatching":true,"runnersVoidable":false,"numberOfActiveRunners":2,"betDelay":0,"status":"OPEN","runners":[{"status":"ACTIVE","sortPriority":1,"id":11772759,"name":"Juan Pablo Varillas"},{"status":"ACTIVE","sortPriority":2,"id":9631075,"name":"Carlos Taberner"}],"regulators":["MR_INT"],"countryCode":"AR","discountAllowed":true,"timezone":"UTC","openDate":"2020-02-02T13:00:00.000Z","version":3146764511,"name":"Match Odds","eventName":"Jua Varillas v Taberner"}}]}
{"op":"mcm","clk":"1004222421","pt":1580581097611,"mc":[{"id":"1.168222848","rc":[{"batb":[[0,1.06,50.48],[1,1.05,152.2],[2,1.04,168.86]],"ltp":0.0,"tv":0.0,"id":11772759}]}]}
{"op":"mcm","clk":"1004222472","pt":1580581097941,"mc":[{"id":"1.168222848","rc":[{"batb":[[0,1.06,50.48],[1,1.05,152.2],[2,1.04,168.86]],"ltp":0.0,"tv":0.0,"id":9631075}]}]}
{"op":"mcm","clk":"1004370302","pt":1580581961944,"mc":[{"id":"1.168222848","rc":[{"batb":[[0,1.13,75.72],[1,1.06,50.48],[2,1.05,152.2]],"ltp":0.0,"tv":0.0,"id":9631075},{"batb":[[0,1.09,75.72],[1,1.06,50.48],[2,1.05,152.2]],"ltp":0.0,"tv":0.0,"id":11772759}]}]}
{"op":"mcm","clk":"1005040543","pt":1580585738270,"mc":[{"id":"1.168222848","rc":[{"batl":[[0,48,31.05],[1,990,2.2]],"ltp":0.0,"tv":0.0,"id":9631075},{"batl":[[0,48,31.05],[1,990,2.2]],"ltp":0.0,"tv":0.0,"id":11772759}]}]}
{"op":"mcm","clk":"1005739150","pt":1580590302889,"mc":[{"id":"1.168222848","marketDefinition":{"bspMarket":false,"turnInPlayEnabled":true,"persistenceEnabled":true,"marketBaseRate":5.0,"eventId":"29681551","eventTypeId":"2","numberOfWinners":1,"bettingType":"ODDS","marketType":"MATCH_ODDS","marketTime":"2020-02-02T14:00:00.000Z","suspendTime":"2020-02-02T14:00:00.000Z","bspReconciled":false,"complete":true,"inPlay":false,"crossMatching":true,"runnersVoidable":false,"numberOfActiveRunners":2,"betDelay":0,"status":"OPEN","runners":[{"status":"ACTIVE","sortPriority":1,"id":11772759,"name":"Juan Pablo Varillas"},{"status":"ACTIVE","sortPriority":2,"id":9631075,"name":"Carlos Taberner"}],"regulators":["MR_INT"],"countryCode":"AR","discountAllowed":true,"timezone":"UTC","openDate":"2020-02-02T13:00:00.000Z","version":3147422159,"name":"Match Odds","eventName":"Jua Varillas v Taberner"}}]}
{"op":"mcm","clk":"1005739706","pt":1580590307869,"mc":[{"id":"1.168222848","marketDefinition":{"bspMarket":false,"turnInPlayEnabled":true,"persistenceEnabled":true,"marketBaseRate":5.0,"eventId":"29681551","eventTypeId":"2","numberOfWinners":1,"bettingType":"ODDS","marketType":"MATCH_ODDS","marketTime":"2020-02-02T14:00:00.000Z","suspendTime":"2020-02-02T14:00:00.000Z","bspReconciled":false,"complete":true,"inPlay":false,"crossMatching":true,"runnersVoidable":false,"numberOfActiveRunners":2,"betDelay":0,"status":"OPEN","runners":[{"status":"ACTIVE","sortPriority":1,"id":11772759,"name":"Juan Pablo Varillas"},{"status":"ACTIVE","sortPriority":2,"id":9631075,"name":"Carlos Taberner"}],"regulators":["MR_INT"],"countryCode":"AR","discountAllowed":true,"timezone":"UTC","openDate":"2020-02-02T14:00:00.000Z","version":3147422159,"name":"Match Odds","eventName":"Jua Varillas v Taberner"}}]}
{"op":"mcm","clk":"1006007744","pt":1580592415242,"mc":[{"id":"1.168222848","rc":[{"batb":[[0,1.88,378.62],[1,1.13,75.72],[2,1.06,50.48]],"ltp":0.0,"tv":0.0,"id":9631075}]}]}
{"op":"mcm","clk":"1006048503","pt":1580592748706,"mc":[{"id":"1.168222848","rc":[{"batl":[[0,12,3.36],[1,48,31.05],[2,990,2.2]],"ltp":0.0,"tv":0.0,"id":9631075},{"batb":[[0,1.1,15.12],[1,1.09,75.72],[2,1.06,50.48]],"batl":[[0,12,3.36],[1,48,31.05],[2,990,2.2]],"ltp":0.0,"tv":0.0,"id":11772759}]}]}
{"op":"mcm","clk":"1006198322","pt":1580594031049,"mc":[{"id":"1.168222848","rc":[{"batb":[[0,1.74,23.29],[1,1.1,15.12],[2,1.09,75.72]],"ltp":0.0,"tv":0.0,"id":11772759}]}]}
{"op":"mcm","clk":"1006198549","pt":1580594033656,"mc":[{"id":"1.168222848","rc":[{"batb":[[1,1.09,75.72],[2,1.06,50.48]],"ltp":0.0,"tv":0.0,"id":11772759}]}]}
{"op":"mcm","clk":"1006199280","pt":1580594041149,"mc":[{"id":"1.168222848","rc":[{"trd":[[1.88,87.08]],"batb":[[0,1.88,335.07]],"ltp":1.88,"tv":87.08,"id":9631075},{"batb":[[0,1.09,75.72],[1,1.06,50.48],[2,1.05,152.2]],"ltp":0.0,"tv":0.0,"id":11772759}],"tv":87.08}]}
{"op":"mcm","clk":"1006200599","pt":1580594056020,"mc":[{"id":"1.168222848","rc":[{"batl":[[0,2.08,19.44],[1,12,3.36],[2,48,31.05]],"ltp":1.88,"tv":87.08,"id":9631075}]}]}
{"op":"mcm","clk":"1006202717","pt":1580594080505,"mc":[{"id":"1.168222848","rc":[{"batl":[[1,48,31.05],[2,990,2.2]],"ltp":1.88,"tv":87.08,"id":9631075},{"batb":[[0,1.1,15.12],[1,1.09,75.72],[2,1.06,50.48]],"ltp":0.0,"tv":0.0,"id":11772759}]}]}
{"op":"mcm","clk":"1006231057","pt":1580594408530,"mc":[{"id":"1.168222848","rc":[{"batb":[[0,1.9,47.71],[1,1.1,15.12],[2,1.09,75.72]],"ltp":0.0,"tv":0.0,"id":11772759}]}]}
{"op":"mcm","clk":"1006231093","pt":1580594408796,"mc":[{"id":"1.168222848","rc":[{"batb":[[1,1.64,35.59],[2,1.13,75.72]],"ltp":1.88,"tv":87.08,"id":9631075}]}]}
{"op":"mcm","clk":"1006234294","pt":1580594439094,"mc":[{"id":"1.168222848","rc":[{"batb":[[1,1.09,75.72],[2,1.06,50.48]],"ltp":0.0,"tv":0.0,"id":11772759}]}]}
{"op":"mcm","clk":"1006237562","pt":1580594471427,"mc":[{"id":"1.168222848","rc":[{"batb":[[1,1.69,35.59]],"ltp":1.88,"tv":87.08,"id":9631075},{"batb":[[0,1.97,47.71]],"ltp":0.0,"tv":0.0,"id":11772759}]}]}
{"op":"mcm","clk":"1006258068","pt":1580594672484,"mc":[{"id":"1.168222848","rc":[{"trd":[[1.88,175.65]],"batb":[[0,1.88,290.79],[1,1.8,87.72],[2,1.69,35.59]],"batl":[[0,48,31.05],[1,990,2.2],[2,990,0]],"ltp":1.88,"tv":175.65,"id":9631075},{"batb":[[0,2.04,72.43],[1,2,20.29],[2,1.97,47.71]],"ltp":0.0,"tv":0.0,"id":11772759}],"tv":175.65}]}
{"op":"mcm","clk":"1006261829","pt":1580594709740,"mc":[{"id":"1.168222848","rc":[{"batb":[[1,1.97,47.71],[2,1.09,75.72]],"ltp":0.0,"tv":0.0,"id":11772759}]}]}
{"op":"mcm","clk":"1006262166","pt":1580594712717,"mc":[{"id":"1.168222848","rc":[{"batb":[[2,1.11,37.86]],"ltp":0.0,"tv":0.0,"id":11772759}]}]}
{"op":"mcm","clk":"1006262269","pt":1580594713655,"mc":[{"id":"1.168222848","rc":[{"batb":[[2,1.31,37.86]],"ltp":0.0,"tv":0.0,"id":11772759}]}]}
{"op":"mcm","clk":"1006262343","pt":1580594714329,"mc":[{"id":"1.168222848","rc":[{"batb":[[2,1.41,37.86]],"ltp":0.0,"tv":0.0,"id":11772759}]}]}
{"op":"mcm","clk":"1006262441","pt":1580594715157,"mc":[{"id":"1.168222848","rc":[{"batl":[[0,12,3.36],[1,48,31.05],[2,990,2.2]],"ltp":1.88,"tv":175.65,"id":9631075},{"batb":[[2,1.51,37.86]],"ltp":0.0,"tv":0.0,"id":11772759}]}]}
{"op":"mcm","clk":"1006262521","pt":1580594715935,"mc":[{"id":"1.168222848","rc":[{"batb":[[2,1.61,37.86]],"ltp":0.0,"tv":0.0,"id":11772759}]}]}
{"op":"mcm","clk":"1006262681","pt":1580594717444,"mc":[{"id":"1.168222848","rc":[{"batb":[[2,1.71,37.86]],"ltp":1.88,"tv":175.65,"id":9631075},{"batb":[[2,1.81,37.86]],"ltp":0.0,"tv":0.0,"id":11772759}]}]}
{"op":"mcm","clk":"1006299315","pt":1580595030391,"mc":[{"id":"1.168222848","rc":[{"batb":[[1,1.96,47.71]],"ltp":0.0,"tv":0.0,"id":11772759}]}]}
{"op":"mcm","clk":"1006339748","pt":1580595381463,"mc":[{"id":"1.168222848","rc":[{"batl":[[0,2.12,8.4],[1,12,3.36],[2,48,31.05]],"ltp":0.0,"tv":0.0,"id":11772759}]}]}
{"op":"mcm","clk":"1006339865","pt":1580595382400,"mc":[{"id":"1.168222848","rc":[{"trd":[[1.97,9.12]],"batb":[[0,1.89,9.44],[1,1.88,290.79],[2,1.8,87.72]],"batl":[[0,1.97,3.84],[1,12,3.36],[2,48,31.05]],"ltp":1.97,"tv":184.77,"id":9631075},{"batb":[[0,2.04,80.52]],"ltp":0.0,"tv":0.0,"id":11772759}],"tv":184.77}]}
{"op":"mcm","clk":"1006340838","pt":1580595390682,"mc":[{"id":"1.168222848","rc":[{"batl":[[1,48,31.05],[2,990,2.2]],"ltp":1.97,"tv":184.77,"id":9631075}]}]}
{"op":"mcm","clk":"1006340877","pt":1580595391002,"mc":[{"id":"1.168222848","rc":[{"batl":[[1,48,31.05],[2,990,2.2]],"ltp":0.0,"tv":0.0,"id":11772759}]}]}
{"op":"mcm","clk":"1006347242","pt":1580595437464,"mc":[{"id":"1.168222848","rc":[{"trd":[[2.12,16.8]],"batl":[[0,48,31.05],[1,990,2.2],[2,990,0]],"ltp":2.12,"tv":16.8,"id":11772759}],"tv":201.57}]}
{"op":"mcm","clk":"1006347324","pt":1580595438086,"mc":[{"id":"1.168222848","rc":[{"batb":[[2,1.81,85.58]],"ltp":1.97,"tv":184.77,"id":9631075},{"batb":[[0,2.04,71.97]],"ltp":2.12,"tv":16.8,"id":11772759}]}]}
{"op":"mcm","clk":"1006348216","pt":1580595445674,"mc":[{"id":"1.168222848","rc":[{"batl":[[0,48,31.05],[1,990,2.2],[2,990,0]],"ltp":1.97,"tv":184.77,"id":9631075},{"batl":[[0,2.12,8.4],[1,48,31.05],[2,990,2.2]],"ltp":2.12,"tv":16.8,"id":11772759}]}]}
{"op":"mcm","clk":"1006348248","pt":1580595445884,"mc":[{"id":"1.168222848","rc":[{"batl":[[0,1.97,8.4],[1,48,31.05],[2,990,2.2]],"ltp":1.97,"tv":184.77,"id":9631075}]}]}
{"op":"mcm","clk":"1006572517","pt":1580597792809,"mc":[{"id":"1.168222848","rc":[{"batb":[[1,1.81,37.86],[2,1.71,37.86]],"ltp":2.12,"tv":16.8,"id":11772759}]}]}
{"op":"mcm","clk":"1006573831","pt":1580597810740,"mc":[{"id":"1.168222848","rc":[{"batb":[[1,1.93,46.95],[2,1.81,37.86]],"ltp":2.12,"tv":16.8,"id":11772759}]}]}
{"op":"mcm","clk":"1006584899","pt":1580597991065,"mc":[{"id":"1.168222848","rc":[{"batb":[[1,1.92,46.95]],"ltp":2.12,"tv":16.8,"id":11772759}]}]}
{"op":"mcm","clk":"1006699026","pt":1580599387392,"mc":[{"id":"1.168222848","rc":[{"batb":[[1,1.81,37.86],[2,1.71,37.86]],"ltp":2.12,"tv":16.8,"id":11772759}]}]}
{"op":"mcm","clk":"1006699207","pt":1580599389380,"mc":[{"id":"1.168222848","rc":[{"batb":[[1,1.89,48.46],[2,1.81,37.86]],"ltp":2.12,"tv":16.8,"id":11772759}]}]}
{"op":"mcm","clk":"1006730137","pt":1580599740468,"mc":[{"id":"1.168222848","rc":[{"batb":[[1,1.81,37.86],[2,1.71,37.86]],"ltp":2.12,"tv":16.8,"id":11772759}]}]}
{"op":"mcm","clk":"1006730810","pt":1580599748176,"mc":[{"id":"1.168222848","rc":[{"batb":[[1,1.86,48.46],[2,1.81,37.86]],"ltp":2.12,"tv":16.8,"id":11772759}]}]}
{"op":"mcm","clk":"1006746054","pt":1580599913572,"mc":[{"id":"1.168222848","rc":[{"batb":[[2,1.76,52.25]],"ltp":1.97,"tv":184.77,"id":9631075},{"batb":[[0,2.04,60.97]],"ltp":2.12,"tv":16.8,"id":11772759}]}]}
{"op":"mcm","clk":"1006746074","pt":1580599913784,"mc":[{"id":"1.168222848","rc":[{"batb":[[2,1.82,86.3]],"ltp":1.97,"tv":184.77,"id":9631075}]}]}
{"op":"mcm","clk":"1007079031","pt":1580604376386,"mc":[{"id":"1.168222848","rc":[{"batb":[[1,1.81,37.86],[2,1.76,49.82]],"ltp":2.12,"tv":16.8,"id":11772759}]}]}
{"op":"mcm","clk":"1007079166","pt":1580604378752,"mc":[{"id":"1.168222848","rc":[{"batb":[[1,1.83,49.98],[2,1.81,37.86]],"ltp":2.12,"tv":16.8,"id":11772759}]}]}
{"op":"mcm","clk":"1007106806","pt":1580604945175,"mc":[{"id":"1.168222848","rc":[{"batb":[[0,1.89,32.57],[2,1.79,52.25]],"ltp":1.97,"tv":184.77,"id":9631075},{"batb":[[0,2.04,49.99]],"ltp":2.12,"tv":16.8,"id":11772759}]}]}
{"op":"mcm","clk":"1007164942","pt":1580606200054,"mc":[{"id":"1.168222848","rc":[{"batb":[[2,1.8,52.25]],"ltp":1.97,"tv":184.77,"id":9631075},{"batb":[[1,1.82,49.98]],"ltp":2.12,"tv":16.8,"id":11772759}]}]}
{"op":"mcm","clk":"1007259557","pt":1580608636930,"mc":[{"id":"1.168222848","rc":[{"batb":[[2,1.8,199.91]],"ltp":1.97,"tv":184.77,"id":9631075},{"batb":[[2,1.81,183.7]],"ltp":2.12,"tv":16.8,"id":11772759}]}]}
{"op":"mcm","clk":"1007265444","pt":1580608839487,"mc":[{"id":"1.168222848","rc":[{"batb":[[2,1.8,52.25]],"ltp":1.97,"tv":184.77,"id":9631075},{"batb":[[2,1.81,37.86]],"ltp":2.12,"tv":16.8,"id":11772759}]}]}
{"op":"mcm","clk":"1007265472","pt":1580608840209,"mc":[{"id":"1.168222848","rc":[{"batb":[[2,1.81,145.84]],"ltp":1.97,"tv":184.77,"id":9631075}]}]}
{"op":"mcm","clk":"1007265502","pt":1580608841193,"mc":[{"id":"1.168222848","rc":[{"batb":[[2,1.84,52.25]],"ltp":1.97,"tv":184.77,"id":9631075}]}]}
{"op":"mcm","clk":"1007265623","pt":1580608845492,"mc":[{"id":"1.168222848","rc":[{"batb":[[2,1.82,52.25]],"ltp":1.97,"tv":184.77,"id":9631075},{"batb":[[1,1.81,37.86],[2,1.8,197.64]],"ltp":2.12,"tv":16.8,"id":11772759}]}]}
{"op":"mcm","clk":"1007276635","pt":1580609211664,"mc":[{"id":"1.168222848","rc":[{"trd":[[1.97,69.32]],"batb":[[0,1.9,54.62],[1,1.89,32.57],[2,1.88,290.79]],"batl":[[0,48,31.05],[1,990,2.2],[2,1000,0.02]],"ltp":1.97,"tv":244.97,"id":9631075},{"trd":[[2.04,41.91]],"batb":[[0,1.94,77.14],[1,1.91,28.17],[2,1.81,37.86]],"ltp":2.04,"tv":58.71,"id":11772759}],"tv":303.68}]}
{"op":"mcm","clk":"1007276653","pt":1580609212028,"mc":[{"id":"1.168222848","rc":[{"batb":[[0,1.96,30.63],[1,1.94,77.14]],"ltp":2.04,"tv":58.71,"id":11772759}]}]}
{"op":"mcm","clk":"1007276776","pt":1580609215625,"mc":[{"id":"1.168222848","rc":[{"batb":[[0,1.94,77.14],[1,1.81,37.86],[2,1.8,197.64]],"batl":[[0,2.04,49.75],[1,2.12,8.4],[2,48,31.05]],"ltp":2.04,"tv":58.71,"id":11772759}]}]}
{"op":"mcm","clk":"1007277437","pt":1580609234277,"mc":[{"id":"1.168222848","rc":[{"batl":[[1,48,31.05],[2,990,2.2]],"ltp":2.04,"tv":58.71,"id":11772759}]}]}
{"op":"mcm","clk":"1007277494","pt":1580609235461,"mc":[{"id":"1.168222848","rc":[{"batb":[[1,1.89,23.13]],"ltp":1.97,"tv":244.97,"id":9631075}]}]}
{"op":"mcm","clk":"1007277515","pt":1580609236078,"mc":[{"id":"1.168222848","rc":[{"batb":[[0,1.96,13.13],[1,1.9,54.62],[2,1.89,23.13]],"ltp":1.97,"tv":244.97,"id":9631075},{"batl":[[0,2.04,62.35]],"ltp":2.04,"tv":58.71,"id":11772759}]}]}
{"op":"mcm","clk":"1007277663","pt":1580609239572,"mc":[{"id":"1.168222848","rc":[{"batb":[[1,1.88,290.79],[2,1.82,52.25]],"ltp":1.97,"tv":244.97,"id":9631075},{"batb":[[0,1.81,37.86],[1,1.8,197.64],[2,1.71,37.86]],"ltp":2.04,"tv":58.71,"id":11772759}]}]}
{"op":"mcm","clk":"1007277687","pt":1580609240189,"mc":[{"id":"1.168222848","rc":[{"batb":[[0,1.97,79.36],[1,1.96,13.13],[2,1.88,290.79]],"ltp":1.97,"tv":244.97,"id":9631075},{"batb":[[0,1.86,139.68],[1,1.85,88.77],[2,1.81,37.86]],"ltp":2.04,"tv":58.71,"id":11772759}]}]}
{"op":"mcm","clk":"1007278273","pt":1580609253521,"mc":[{"id":"1.168222848","rc":[{"batl":[[0,12,3.36],[1,48,31.05],[2,990,2.2]],"ltp":1.97,"tv":244.97,"id":9631075}]}]}
{"op":"mcm","clk":"1007278879","pt":1580609267642,"mc":[{"id":"1.168222848","rc":[{"batb":[[0,1.97,92.35],[1,1.88,290.79],[2,1.82,52.25]],"ltp":1.97,"tv":244.97,"id":9631075}]}]}
{"op":"mcm","clk":"1007279831","pt":1580609293457,"mc":[{"id":"1.168222848","rc":[{"batb":[[0,1.87,67.33],[1,1.81,37.86],[2,1.8,197.64]],"ltp":2.04,"tv":58.71,"id":11772759}]}]}
{"op":"mcm","clk":"1007283579","pt":1580609413571,"mc":[{"id":"1.168222848","rc":[{"batb":[[0,1.85,88.77],[1,1.84,141.22],[2,1.81,37.86]],"ltp":2.04,"tv":58.71,"id":11772759}]}]}
{"op":"mcm","clk":"1007283589","pt":1580609413879,"mc":[{"id":"1.168222848","rc":[{"batb":[[0,1.86,139.68],[1,1.85,88.77]],"ltp":2.04,"tv":58.71,"id":11772759}]}]}
{"op":"mcm","clk":"1007288621","pt":1580609538558,"mc":[{"id":"1.168222848","rc":[{"batb":[[0,1.87,67.33],[1,1.86,139.68]],"ltp":2.04,"tv":58.71,"id":11772759}]}]}
{"op":"mcm","clk":"1007288633","pt":1580609538767,"mc":[{"id":"1.168222848","rc":[{"batb":[[1,1.81,37.86],[2,1.8,197.64]],"ltp":2.04,"tv":58.71,"id":11772759}]}]}
{"op":"mcm","clk":"1007294051","pt":1580609662712,"mc":[{"id":"1.168222848","rc":[{"batb":[[0,1.86,139.68],[1,1.85,88.77],[2,1.81,37.86]],"ltp":2.04,"tv":58.71,"id":11772759}]}]}
{"op":"mcm","clk":"1007299288","pt":1580609783453,"mc":[{"id":"1.168222848","rc":[{"batb":[[0,1.87,67.33],[1,1.81,37.86],[2,1.8,197.64]],"ltp":2.04,"tv":58.71,"id":11772759}]}]}
{"op":"mcm","clk":"1007303266","pt":1580609903714,"mc":[{"id":"1.168222848","rc":[{"batb":[[0,1.85,88.77]],"ltp":2.04,"tv":58.71,"id":11772759}]}]}
{"op":"mcm","clk":"1007303283","pt":1580609904331,"mc":[{"id":"1.168222848","rc":[{"batb":[[0,1.86,139.68],[1,1.85,88.77],[2,1.81,37.86]],"ltp":2.04,"tv":58.71,"id":11772759}]}]}
{"op":"mcm","clk":"1007307268","pt":1580610023642,"mc":[{"id":"1.168222848","rc":[{"batb":[[0,1.87,67.33],[1,1.81,37.86],[2,1.8,197.64]],"ltp":2.04,"tv":58.71,"id":11772759}]}]}
{"op":"mcm","clk":"1007311758","pt":1580610146430,"mc":[{"id":"1.168222848","rc":[{"batb":[[0,1.86,139.68],[1,1.85,88.77],[2,1.81,37.86]],"ltp":2.04,"tv":58.71,"id":11772759}]}]}
{"op":"mcm","clk":"1007315694","pt":1580610271681,"mc":[{"id":"1.168222848","rc":[{"batb":[[1,1.81,37.86],[2,1.8,197.64]],"ltp":2.04,"tv":58.71,"id":11772759}]}]}
{"op":"mcm","clk":"1007315708","pt":1580610271990,"mc":[{"id":"1.168222848","rc":[{"batb":[[0,1.87,67.33]],"ltp":2.04,"tv":58.71,"id":11772759}]}]}
{"op":"mcm","clk":"1007319415","pt":1580610394337,"mc":[{"id":"1.168222848","rc":[{"batb":[[0,1.86,139.68],[1,1.85,88.77],[2,1.81,37.86]],"ltp":2.04,"tv":58.71,"id":11772759}]}]}
{"op":"mcm","clk":"1007323064","pt":1580610515714,"mc":[{"id":"1.168222848","rc":[{"batb":[[0,1.87,67.33],[1,1.81,37.86],[2,1.8,197.64]],"ltp":2.04,"tv":58.71,"id":11772759}]}]}
{"op":"mcm","clk":"1007327473","pt":1580610637721,"mc":[{"id":"1.168222848","rc":[{"batb":[[0,1.85,88.77]],"ltp":2.04,"tv":58.71,"id":11772759}]}]}
{"op":"mcm","clk":"1007327489","pt":1580610638088,"mc":[{"id":"1.168222848","rc":[{"batb":[[0,1.86,139.68],[1,1.85,88.77],[2,1.81,37.86]],"ltp":2.04,"tv":58.71,"id":11772759}]}]}
{"op":"mcm","clk":"1007331838","pt":1580610760469,"mc":[{"id":"1.168222848","rc":[{"batb":[[0,1.87,67.33],[1,1.81,37.86],[2,1.8,197.64]],"ltp":2.04,"tv":58.71,"id":11772759}]}]}
{"op":"mcm","clk":"1007336112","pt":1580610885098,"mc":[{"id":"1.168222848","rc":[{"batb":[[0,1.85,229.14]],"ltp":2.04,"tv":58.71,"id":11772759}]}]}
{"op":"mcm","clk":"1007347210","pt":1580611266529,"mc":[{"id":"1.168222848","rc":[{"batb":[[0,1.86,6.48],[1,1.85,88.77],[2,1.81,37.86]],"ltp":2.04,"tv":58.71,"id":11772759}]}]}
{"op":"mcm","clk":"1007347251","pt":1580611268021,"mc":[{"id":"1.168222848","rc":[{"batb":[[0,1.98,5.98],[1,1.97,92.35],[2,1.88,290.79]],"ltp":1.97,"tv":244.97,"id":9631075},{"batb":[[0,1.86,146.16]],"ltp":2.04,"tv":58.71,"id":11772759}]}]}
{"op":"mcm","clk":"1007347586","pt":1580611278061,"mc":[{"id":"1.168222848","rc":[{"batb":[[0,1.98,18.85],[1,1.97,79.36]],"ltp":1.97,"tv":244.97,"id":9631075}]}]}
{"op":"mcm","clk":"1007350864","pt":1580611375275,"mc":[{"id":"1.168222848","rc":[{"batb":[[0,1.99,61.68],[1,1.98,18.85]],"ltp":1.97,"tv":244.97,"id":9631075},{"batb":[[0,1.87,67.33],[1,1.86,6.48]],"ltp":2.04,"tv":58.71,"id":11772759}]}]}
{"op":"mcm","clk":"1007351895","pt":1580611402275,"mc":[{"id":"1.168222848","rc":[{"batl":[[0,2.04,49.75]],"ltp":2.04,"tv":58.71,"id":11772759}]}]}
{"op":"mcm","clk":"1007351945","pt":1580611403715,"mc":[{"id":"1.168222848","rc":[{"batb":[[1,1.98,5.98]],"ltp":1.97,"tv":244.97,"id":9631075}]}]}
{"op":"mcm","clk":"1007351968","pt":1580611404076,"mc":[{"id":"1.168222848","rc":[{"batb":[[0,1.99,74.41]],"ltp":1.97,"tv":244.97,"id":9631075},{"batl":[[0,2.02,12.6],[1,2.04,49.75],[2,48,31.05]],"ltp":2.04,"tv":58.71,"id":11772759}]}]}
{"op":"mcm","clk":"1007430022","pt":1580613831537,"mc":[{"id":"1.168222848","rc":[{"batb":[[1,1.88,290.79],[2,1.82,52.25]],"ltp":1.97,"tv":244.97,"id":9631075},{"batb":[[1,1.81,37.86],[2,1.8,197.64]],"ltp":2.04,"tv":58.71,"id":11772759}]}]}
{"op":"mcm","clk":"1007432765","pt":1580613913713,"mc":[{"id":"1.168222848","rc":[{"batb":[[0,1.85,88.77]],"ltp":2.04,"tv":58.71,"id":11772759}]}]}
{"op":"mcm","clk":"1007432790","pt":1580613914175,"mc":[{"id":"1.168222848","rc":[{"batb":[[0,1.86,139.68],[1,1.85,88.77],[2,1.81,37.86]],"ltp":2.04,"tv":58.71,"id":11772759}]}]}
{"op":"mcm","clk":"1007437649","pt":1580614045715,"mc":[{"id":"1.168222848","rc":[{"batb":[[1,1.81,37.86],[2,1.8,197.64]],"ltp":2.04,"tv":58.71,"id":11772759}]}]}
{"op":"mcm","clk":"1007437658","pt":1580614046027,"mc":[{"id":"1.168222848","rc":[{"batb":[[0,1.87,67.33]],"ltp":2.04,"tv":58.71,"id":11772759}]}]}
{"op":"mcm","clk":"1007441452","pt":1580614180728,"mc":[{"id":"1.168222848","rc":[{"batb":[[0,1.85,88.77]],"ltp":2.04,"tv":58.71,"id":11772759}]}]}
{"op":"mcm","clk":"1007441466","pt":1580614181088,"mc":[{"id":"1.168222848","rc":[{"batb":[[0,1.86,139.68],[1,1.85,88.77],[2,1.81,37.86]],"ltp":2.04,"tv":58.71,"id":11772759}]}]}
{"op":"mcm","clk":"1007445858","pt":1580614310566,"mc":[{"id":"1.168222848","rc":[{"batb":[[0,1.87,67.33],[1,1.81,37.86],[2,1.8,197.64]],"ltp":2.04,"tv":58.71,"id":11772759}]}]}
{"op":"mcm","clk":"1007449910","pt":1580614441727,"mc":[{"id":"1.168222848","rc":[{"batb":[[0,1.85,88.77]],"ltp":2.04,"tv":58.71,"id":11772759}]}]}
{"op":"mcm","clk":"1007449915","pt":1580614442139,"mc":[{"id":"1.168222848","rc":[{"batb":[[0,1.86,139.68],[1,1.85,88.77],[2,1.81,37.86]],"ltp":2.04,"tv":58.71,"id":11772759}]}]}
{"op":"mcm","clk":"1007453520","pt":1580614573313,"mc":[{"id":"1.168222848","rc":[{"batb":[[0,1.87,67.33],[1,1.81,37.86],[2,1.8,197.64]],"ltp":2.04,"tv":58.71,"id":11772759}]}]}
{"op":"mcm","clk":"1007456358","pt":1580614703477,"mc":[{"id":"1.168222848","rc":[{"batb":[[0,1.86,139.68],[1,1.85,88.77],[2,1.81,37.86]],"ltp":2.04,"tv":58.71,"id":11772759}]}]}
{"op":"mcm","clk":"1007458975","pt":1580614830224,"mc":[{"id":"1.168222848","rc":[{"batb":[[0,1.87,67.33],[1,1.81,37.86],[2,1.8,197.64]],"ltp":2.04,"tv":58.71,"id":11772759}]}]}
{"op":"mcm","clk":"1007462118","pt":1580614957679,"mc":[{"id":"1.168222848","rc":[{"batb":[[0,1.85,88.77]],"ltp":2.04,"tv":58.71,"id":11772759}]}]}
{"op":"mcm","clk":"1007462131","pt":1580614958092,"mc":[{"id":"1.168222848","rc":[{"batb":[[0,1.86,139.68],[1,1.85,88.77],[2,1.81,37.86]],"ltp":2.04,"tv":58.71,"id":11772759}]}]}
{"op":"mcm","clk":"1007465536","pt":1580615083676,"mc":[{"id":"1.168222848","rc":[{"batb":[[1,1.81,37.86],[2,1.8,197.64]],"ltp":2.04,"tv":58.71,"id":11772759}]}]}
{"op":"mcm","clk":"1007465549","pt":1580615083933,"mc":[{"id":"1.168222848","rc":[{"batb":[[0,1.87,67.33]],"ltp":2.04,"tv":58.71,"id":11772759}]}]}
{"op":"mcm","clk":"1007465914","pt":1580615093087,"mc":[{"id":"1.168222848","rc":[{"batl":[[1,990,2.2],[2,1000,0.02]],"ltp":1.97,"tv":244.97,"id":9631075},{"batl":[[2,990,2.2]],"ltp":2.04,"tv":58.71,"id":11772759}]}]}
{"op":"mcm","clk":"1007469046","pt":1580615210671,"mc":[{"id":"1.168222848","rc":[{"batb":[[0,1.81,37.86],[1,1.8,197.64],[2,1.71,37.86]],"ltp":2.04,"tv":58.71,"id":11772759}]}]}
{"op":"mcm","clk":"1007469067","pt":1580615211239,"mc":[{"id":"1.168222848","rc":[{"batb":[[0,1.86,139.68],[1,1.85,88.77],[2,1.81,37.86]],"ltp":2.04,"tv":58.71,"id":11772759}]}]}
{"op":"mcm","clk":"1007472611","pt":1580615335150,"mc":[{"id":"1.168222848","rc":[{"batb":[[0,1.87,67.33],[1,1.81,37.86],[2,1.8,197.64]],"ltp":2.04,"tv":58.71,"id":11772759}]}]}
{"op":"mcm","clk":"1007477400","pt":1580615461686,"mc":[{"id":"1.168222848","rc":[{"batb":[[0,1.85,88.77]],"ltp":2.04,"tv":58.71,"id":11772759}]}]}
{"op":"mcm","clk":"1007477407","pt":1580615461792,"mc":[{"id":"1.168222848","rc":[{"batb":[[0,1.86,139.68],[1,1.85,88.77],[2,1.81,37.86]],"ltp":2.04,"tv":58.71,"id":11772759}]}]}
{"op":"mcm","clk":"1007482799","pt":1580615591272,"mc":[{"id":"1.168222848","rc":[{"batb":[[0,1.87,67.33],[1,1.81,37.86],[2,1.8,197.64]],"ltp":2.04,"tv":58.71,"id":11772759}]}]}
{"op":"mcm","clk":"1007487336","pt":1580615716744,"mc":[{"id":"1.168222848","rc":[{"batb":[[0,1.85,88.77]],"ltp":2.04,"tv":58.71,"id":11772759}]}]}
{"op":"mcm","clk":"1007487365","pt":1580615717259,"mc":[{"id":"1.168222848","rc":[{"batb":[[0,1.86,139.68],[1,1.85,88.77],[2,1.81,37.86]],"ltp":2.04,"tv":58.71,"id":11772759}]}]}
{"op":"mcm","clk":"1007491750","pt":1580615844124,"mc":[{"id":"1.168222848","rc":[{"batb":[[0,1.87,67.33],[1,1.81,37.86],[2,1.8,197.64]],"ltp":2.04,"tv":58.71,"id":11772759}]}]}
{"op":"mcm","clk":"1007497033","pt":1580615970735,"mc":[{"id":"1.168222848","rc":[{"batb":[[0,1.86,139.68],[1,1.85,88.77],[2,1.81,37.86]],"ltp":2.04,"tv":58.71,"id":11772759}]}]}
{"op":"mcm","clk":"1007500710","pt":1580616041734,"mc":[{"id":"1.168222848","rc":[{"batb":[[0,1.85,88.77],[1,1.81,37.86],[2,1.8,197.64]],"ltp":2.04,"tv":58.71,"id":11772759}]}]}
{"op":"mcm","clk":"1007500716","pt":1580616041837,"mc":[{"id":"1.168222848","rc":[{"batb":[[0,1.86,211.18],[1,1.85,88.77],[2,1.81,37.86]],"ltp":2.04,"tv":58.71,"id":11772759}]}]}
{"op":"mcm","clk":"1007503229","pt":1580616097146,"mc":[{"id":"1.168222848","rc":[{"batb":[[0,1.87,67.33],[1,1.81,37.86],[2,1.8,275.25]],"ltp":2.04,"tv":58.71,"id":11772759}]}]}
{"op":"mcm","clk":"1007508590","pt":1580616225310,"mc":[{"id":"1.168222848","rc":[{"batb":[[0,1.86,212.18],[1,1.85,88.77],[2,1.81,37.86]],"ltp":2.04,"tv":58.71,"id":11772759}]}]}
{"op":"mcm","clk":"1007513297","pt":1580616346606,"mc":[{"id":"1.168222848","rc":[{"batb":[[1,1.89,6.1],[2,1.88,290.79]],"ltp":1.97,"tv":244.97,"id":9631075},{"batb":[[0,1.87,6.65]],"ltp":2.04,"tv":58.71,"id":11772759}]}]}
{"op":"mcm","clk":"1007513500","pt":1580616351447,"mc":[{"id":"1.168222848","rc":[{"batb":[[0,1.88,56.92],[1,1.87,6.65]],"ltp":2.04,"tv":58.71,"id":11772759}]}]}
{"op":"mcm","clk":"1007526594","pt":1580616782286,"mc":[{"id":"1.168222848","rc":[{"batl":[[1,95,15.9],[2,990,2.2]],"ltp":1.97,"tv":244.97,"id":9631075},{"batl":[[2,95,15.9]],"ltp":2.04,"tv":58.71,"id":11772759}]}]}
{"op":"mcm","clk":"1007603497","pt":1580618782282,"mc":[{"id":"1.168222848","rc":[{"batl":[[2,2.6,15.14]],"ltp":2.04,"tv":58.71,"id":11772759}]}]}
{"op":"mcm","clk":"1007606114","pt":1580618855312,"mc":[{"id":"1.168222848","rc":[{"batb":[[1,1.81,37.86],[2,1.8,275.25]],"ltp":2.04,"tv":58.71,"id":11772759}]}]}
{"op":"mcm","clk":"1007606135","pt":1580618855882,"mc":[{"id":"1.168222848","rc":[{"batb":[[1,1.88,290.79],[2,1.82,52.25]],"ltp":1.97,"tv":244.97,"id":9631075}]}]}
{"op":"mcm","clk":"1007607539","pt":1580618897668,"mc":[{"id":"1.168222848","rc":[{"batb":[[0,1.81,37.86],[1,1.8,275.25],[2,1.71,37.86]],"ltp":2.04,"tv":58.71,"id":11772759}]}]}
{"op":"mcm","clk":"1007607558","pt":1580618898132,"mc":[{"id":"1.168222848","rc":[{"batb":[[0,1.86,212.18],[1,1.85,88.77],[2,1.81,37.86]],"ltp":2.04,"tv":58.71,"id":11772759}]}]}
{"op":"mcm","clk":"1007611151","pt":1580619022741,"mc":[{"id":"1.168222848","rc":[{"batb":[[0,1.87,67.33],[1,1.81,37.86],[2,1.8,275.25]],"ltp":2.04,"tv":58.71,"id":11772759}]}]}
{"op":"mcm","clk":"1007615269","pt":1580619147646,"mc":[{"id":"1.168222848","rc":[{"batb":[[0,1.85,88.77],[1,1.84,214.47],[2,1.81,37.86]],"ltp":2.04,"tv":58.71,"id":11772759}]}]}
{"op":"mcm","clk":"1007615282","pt":1580619148013,"mc":[{"id":"1.168222848","rc":[{"batb":[[0,1.86,212.18],[1,1.85,88.77]],"ltp":2.04,"tv":58.71,"id":11772759}]}]}
{"op":"mcm","clk":"1007619338","pt":1580619271407,"mc":[{"id":"1.168222848","rc":[{"batb":[[0,1.87,67.33],[1,1.81,37.86],[2,1.8,275.25]],"ltp":2.04,"tv":58.71,"id":11772759}]}]}
{"op":"mcm","clk":"1007623972","pt":1580619395653,"mc":[{"id":"1.168222848","rc":[{"batb":[[0,1.86,212.18],[1,1.85,88.77],[2,1.81,37.86]],"ltp":2.04,"tv":58.71,"id":11772759}]}]}
{"op":"mcm","clk":"1007628051","pt":1580619520307,"mc":[{"id":"1.168222848","rc":[{"batb":[[0,1.87,67.33],[1,1.81,37.86],[2,1.8,275.25]],"ltp":2.04,"tv":58.71,"id":11772759}]}]}
{"op":"mcm","clk":"1007632975","pt":1580619640557,"mc":[{"id":"1.168222848","rc":[{"batb":[[0,1.85,88.77]],"ltp":2.04,"tv":58.71,"id":11772759}]}]}
{"op":"mcm","clk":"1007633000","pt":1580619640968,"mc":[{"id":"1.168222848","rc":[{"batb":[[0,1.86,212.18],[1,1.85,88.77],[2,1.81,37.86]],"ltp":2.04,"tv":58.71,"id":11772759}]}]}
{"op":"mcm","clk":"1007638562","pt":1580619761720,"mc":[{"id":"1.168222848","rc":[{"batb":[[0,1.87,67.33],[1,1.86,212.18]],"ltp":2.04,"tv":58.71,"id":11772759}]}]}
{"op":"mcm","clk":"1007638579","pt":1580619761927,"mc":[{"id":"1.168222848","rc":[{"batb":[[1,1.81,37.86],[2,1.8,275.25]],"ltp":2.04,"tv":58.71,"id":11772759}]}]}
{"op":"mcm","clk":"1007643972","pt":1580619883693,"mc":[{"id":"1.168222848","rc":[{"batb":[[0,1.86,212.18],[1,1.85,88.77],[2,1.81,37.86]],"ltp":2.04,"tv":58.71,"id":11772759}]}]}
{"op":"mcm","clk":"1007650241","pt":1580620006456,"mc":[{"id":"1.168222848","rc":[{"batb":[[0,1.87,67.33],[1,1.81,37.86],[2,1.8,275.25]],"ltp":2.04,"tv":58.71,"id":11772759}]}]}
{"op":"mcm","clk":"1007656766","pt":1580620128672,"mc":[{"id":"1.168222848","rc":[{"batb":[[0,1.85,88.77]],"ltp":2.04,"tv":58.71,"id":11772759}]}]}
{"op":"mcm","clk":"1007656795","pt":1580620129140,"mc":[{"id":"1.168222848","rc":[{"batb":[[0,1.86,212.18],[1,1.85,88.77],[2,1.81,37.86]],"ltp":2.04,"tv":58.71,"id":11772759}]}]}
{"op":"mcm","clk":"1007662807","pt":1580620249454,"mc":[{"id":"1.168222848","rc":[{"batb":[[0,1.87,67.33],[1,1.81,37.86],[2,1.8,275.25]],"ltp":2.04,"tv":58.71,"id":11772759}]}]}
{"op":"mcm","clk":"1007670005","pt":1580620371510,"mc":[{"id":"1.168222848","rc":[{"batb":[[0,1.86,212.18],[1,1.85,88.77],[2,1.81,37.86]],"ltp":2.04,"tv":58.71,"id":11772759}]}]}
{"op":"mcm","clk":"1007676120","pt":1580620493126,"mc":[{"id":"1.168222848","rc":[{"batb":[[0,1.87,67.33],[1,1.81,37.86],[2,1.8,275.25]],"ltp":2.04,"tv":58.71,"id":11772759}]}]}
{"op":"mcm","clk":"1007682095","pt":1580620613561,"mc":[{"id":"1.168222848","rc":[{"batb":[[0,1.85,88.77],[1,1.82,217.03],[2,1.81,37.86]],"ltp":2.04,"tv":58.71,"id":11772759}]}]}
{"op":"mcm","clk":"1007682107","pt":1580620613872,"mc":[{"id":"1.168222848","rc":[{"batb":[[0,1.86,212.18],[1,1.85,88.77]],"ltp":2.04,"tv":58.71,"id":11772759}]}]}
{"op":"mcm","clk":"1007687997","pt":1580620737482,"mc":[{"id":"1.168222848","rc":[{"batb":[[0,1.87,67.33],[1,1.86,212.18]],"ltp":2.04,"tv":58.71,"id":11772759}]}]}
{"op":"mcm","clk":"1007688008","pt":1580620737793,"mc":[{"id":"1.168222848","rc":[{"batb":[[1,1.81,37.86],[2,1.8,275.25]],"ltp":2.04,"tv":58.71,"id":11772759}]}]}
{"op":"mcm","clk":"1007693932","pt":1580620858717,"mc":[{"id":"1.168222848","rc":[{"batb":[[0,1.81,37.86],[1,1.8,275.25],[2,1.71,37.86]],"ltp":2.04,"tv":58.71,"id":11772759}]}]}
{"op":"mcm","clk":"1007693954","pt":1580620859128,"mc":[{"id":"1.168222848","rc":[{"batb":[[0,1.86,212.18],[1,1.85,88.77],[2,1.81,37.86]],"ltp":2.04,"tv":58.71,"id":11772759}]}]}
{"op":"mcm","clk":"1007696092","pt":1580620909948,"mc":[{"id":"1.168222848","rc":[{"batb":[[0,1.85,88.77],[1,1.81,37.86],[2,1.8,275.25]],"ltp":2.04,"tv":58.71,"id":11772759}]}]}
{"op":"mcm","clk":"1007696477","pt":1580620918658,"mc":[{"id":"1.168222848","rc":[{"batb":[[0,1.86,212.18],[1,1.85,88.77],[2,1.81,37.86]],"ltp":2.04,"tv":58.71,"id":11772759}]}]}
{"op":"mcm","clk":"1007699055","pt":1580620980655,"mc":[{"id":"1.168222848","rc":[{"batb":[[0,1.87,67.33],[1,1.81,37.86],[2,1.8,275.25]],"ltp":2.04,"tv":58.71,"id":11772759}]}]}
{"op":"mcm","clk":"1007703516","pt":1580621100577,"mc":[{"id":"1.168222848","rc":[{"batb":[[0,1.85,88.77]],"ltp":2.04,"tv":58.71,"id":11772759}]}]}
{"op":"mcm","clk":"1007703533","pt":1580621101091,"mc":[{"id":"1.168222848","rc":[{"batb":[[0,1.86,212.18],[1,1.85,88.77],[2,1.81,37.86]],"ltp":2.04,"tv":58.71,"id":11772759}]}]}
{"op":"mcm","clk":"1007707675","pt":1580621221744,"mc":[{"id":"1.168222848","rc":[{"batb":[[0,1.87,67.33],[1,1.86,212.18]],"ltp":2.04,"tv":58.71,"id":11772759}]}]}
{"op":"mcm","clk":"1007707679","pt":1580621221949,"mc":[{"id":"1.168222848","rc":[{"batb":[[1,1.81,37.86],[2,1.8,275.25]],"ltp":2.04,"tv":58.71,"id":11772759}]}]}
{"op":"mcm","clk":"1007711803","pt":1580621342234,"mc":[{"id":"1.168222848","rc":[{"batb":[[0,1.85,302.14]],"ltp":2.04,"tv":58.71,"id":11772759}]}]}
{"op":"mcm","clk":"1007713336","pt":1580621377536,"mc":[{"id":"1.168222848","rc":[{"batb":[[1,1.89,7.39],[2,1.88,290.79]],"ltp":1.97,"tv":244.97,"id":9631075},{"batb":[[0,1.86,218.25],[1,1.85,88.77],[2,1.81,37.86]],"ltp":2.04,"tv":58.71,"id":11772759}]}]}
{"op":"mcm","clk":"1007717308","pt":1580621467212,"mc":[{"id":"1.168222848","rc":[{"batb":[[0,1.87,67.33],[1,1.86,6.07]],"ltp":2.04,"tv":58.71,"id":11772759}]}]}
{"op":"mcm","clk":"1007833898","pt":1580624014358,"mc":[{"id":"1.168222848","rc":[{"batb":[[1,1.81,37.86],[2,1.77,285.54]],"ltp":2.04,"tv":58.71,"id":11772759}]}]}
{"op":"mcm","clk":"1007833912","pt":1580624014867,"mc":[{"id":"1.168222848","rc":[{"batb":[[1,1.88,290.79],[2,1.85,52.25]],"ltp":1.97,"tv":244.97,"id":9631075}]}]}
{"op":"mcm","clk":"1007834523","pt":1580624031722,"mc":[{"id":"1.168222848","rc":[{"batb":[[0,1.85,88.77]],"ltp":2.04,"tv":58.71,"id":11772759}]}]}
{"op":"mcm","clk":"1007885543","pt":1580625151581,"mc":[{"id":"1.168222848","rc":[{"batb":[[2,1.77,51.49]],"ltp":2.04,"tv":58.71,"id":11772759}]}]}
{"op":"mcm","clk":"1007885569","pt":1580625152170,"mc":[{"id":"1.168222848","rc":[{"batb":[[2,1.85,264.27]],"ltp":1.97,"tv":244.97,"id":9631075},{"batb":[[2,1.78,231.05]],"ltp":2.04,"tv":58.71,"id":11772759}]}]}
{"op":"mcm","clk":"1007885928","pt":1580625162118,"mc":[{"id":"1.168222848","rc":[{"batb":[[2,1.86,52.25]],"ltp":1.97,"tv":244.97,"id":9631075},{"batb":[[2,1.78,282.55]],"ltp":2.04,"tv":58.71,"id":11772759}]}]}
{"op":"mcm","clk":"1007952266","pt":1580626634476,"mc":[{"id":"1.168222848","rc":[{"batb":[[1,1.89,7.11],[2,1.88,290.79]],"ltp":1.97,"tv":244.97,"id":9631075},{"batb":[[0,1.86,6.11],[1,1.85,88.77],[2,1.81,37.86]],"ltp":2.04,"tv":58.71,"id":11772759}]}]}
{"op":"mcm","clk":"1007955547","pt":1580626716436,"mc":[{"id":"1.168222848","rc":[{"batb":[[0,1.87,67.33],[1,1.86,6.11]],"ltp":2.04,"tv":58.71,"id":11772759}]}]}
{"op":"mcm","clk":"1007969297","pt":1580626945151,"mc":[{"id":"1.168222848","rc":[{"batl":[[2,2.52,15.14]],"ltp":2.04,"tv":58.71,"id":11772759}]}]}
{"op":"mcm","clk":"1008017348","pt":1580627806631,"mc":[{"id":"1.168222848","rc":[{"trd":[[1.88,8.4]],"ltp":1.88,"tv":67.11,"id":11772759}],"tv":312.08}]}
{"op":"mcm","clk":"1008017386","pt":1580627807308,"mc":[{"id":"1.168222848","rc":[{"batb":[[2,1.78,282.55]],"ltp":1.88,"tv":67.11,"id":11772759}]}]}
{"op":"mcm","clk":"1008017795","pt":1580627814610,"mc":[{"id":"1.168222848","rc":[{"trd":[[1.99,7.93]],"batb":[[0,1.99,70.44]],"ltp":1.99,"tv":252.9,"id":9631075},{"batb":[[0,1.87,71.48]],"ltp":1.88,"tv":67.11,"id":11772759}],"tv":320.01}]}
{"op":"mcm","clk":"1008019625","pt":1580627846572,"mc":[{"id":"1.168222848","rc":[{"trd":[[1.88,18.48]],"ltp":1.88,"tv":77.19,"id":11772759}],"tv":330.09}]}
{"op":"mcm","clk":"1008020226","pt":1580627857187,"mc":[{"id":"1.168222848","rc":[{"trd":[[1.99,17.46]],"batb":[[0,1.99,65.68]],"ltp":1.99,"tv":262.43,"id":9631075},{"batb":[[0,1.87,76.45]],"ltp":1.88,"tv":77.19,"id":11772759}],"tv":339.62}]}
{"op":"mcm","clk":"1008021532","pt":1580627885190,"mc":[{"id":"1.168222848","rc":[{"trd":[[1.88,35.28]],"ltp":1.88,"tv":93.99,"id":11772759}],"tv":356.42}]}
{"op":"mcm","clk":"1008021967","pt":1580627894523,"mc":[{"id":"1.168222848","rc":[{"trd":[[1.99,33.32]],"batb":[[0,1.99,57.75]],"ltp":1.99,"tv":278.29,"id":9631075},{"batb":[[0,1.87,84.71]],"ltp":1.88,"tv":93.99,"id":11772759}],"tv":372.29}]}
{"op":"mcm","clk":"1008023017","pt":1580627914759,"mc":[{"id":"1.168222848","rc":[{"trd":[[1.99,33.34]],"batb":[[0,1.99,57.74]],"ltp":1.99,"tv":278.31,"id":9631075}],"tv":372.3}]}
{"op":"mcm","clk":"1008023714","pt":1580627930465,"mc":[{"id":"1.168222848","rc":[{"trd":[[1.89,10.08]],"ltp":1.89,"tv":104.07,"id":11772759}],"tv":382.38}]}
{"op":"mcm","clk":"1008024082","pt":1580627939586,"mc":[{"id":"1.168222848","rc":[{"trd":[[1.99,42.9]],"batb":[[0,1.99,52.96]],"ltp":1.99,"tv":287.87,"id":9631075}],"tv":391.95}]}
{"op":"mcm","clk":"1008024105","pt":1580627939997,"mc":[{"id":"1.168222848","rc":[{"batb":[[0,1.88,79.22]],"ltp":1.89,"tv":104.07,"id":11772759}]}]}
{"op":"mcm","clk":"1008025525","pt":1580627972710,"mc":[{"id":"1.168222848","rc":[{"trd":[[1.99,42.92]],"batb":[[0,1.99,52.95]],"ltp":1.99,"tv":287.88,"id":9631075}],"tv":391.96}]}
{"op":"mcm","clk":"1008030092","pt":1580628050348,"mc":[{"id":"1.168222848","rc":[{"trd":[[1.89,14.08]],"batl":[[0,1.89,12.28],[1,2.02,12.6],[2,2.04,49.75]],"ltp":1.89,"tv":108.07,"id":11772759}],"tv":395.96}]}
{"op":"mcm","clk":"1008030159","pt":1580628051324,"mc":[{"id":"1.168222848","rc":[{"trd":[[1.89,38.54]],"batl":[[0,2.02,12.65],[1,2.04,49.75],[2,2.52,15.14]],"ltp":1.89,"tv":132.54,"id":11772759}],"tv":420.43}]}
{"op":"mcm","clk":"1008032911","pt":1580628094994,"mc":[{"id":"1.168222848","rc":[{"batl":[[0,2.02,12.6]],"ltp":1.89,"tv":132.54,"id":11772759}]}]}
{"op":"mcm","clk":"1008033427","pt":1580628103720,"mc":[{"id":"1.168222848","rc":[{"trd":[[1.99,69.95]],"batb":[[0,1.99,12.73],[1,1.97,44.66],[2,1.89,7.11]],"ltp":1.99,"tv":314.92,"id":9631075},{"batb":[[0,1.89,82.9]],"ltp":1.89,"tv":132.54,"id":11772759}],"tv":447.46}]}
{"op":"mcm","clk":"1008092015","pt":1580629230507,"mc":[{"id":"1.168222848","rc":[{"batb":[[1,1.78,282.55],[2,1.71,37.86]],"ltp":1.89,"tv":132.54,"id":11772759}]}]}
{"op":"mcm","clk":"1008092042","pt":1580629231118,"mc":[{"id":"1.168222848","rc":[{"batb":[[2,1.88,290.79]],"ltp":1.99,"tv":314.92,"id":9631075}]}]}
{"op":"mcm","clk":"1008099073","pt":1580629359578,"mc":[{"id":"1.168222848","rc":[{"batb":[[0,2,54.71],[1,1.99,12.73]],"ltp":1.99,"tv":314.92,"id":9631075},{"batb":[[0,1.85,87.01]],"ltp":1.89,"tv":132.54,"id":11772759}]}]}
{"op":"mcm","clk":"1008100430","pt":1580629384400,"mc":[{"id":"1.168222848","rc":[{"batl":[[0,2.04,49.75],[1,2.52,15.14],[2,95,15.9]],"ltp":1.89,"tv":132.54,"id":11772759}]}]}
{"op":"mcm","clk":"1008100487","pt":1580629385430,"mc":[{"id":"1.168222848","rc":[{"batb":[[0,2,67.31],[1,1.88,290.79],[2,1.86,52.25]],"ltp":1.99,"tv":314.92,"id":9631075},{"batl":[[0,2,12.6],[1,2.04,49.75],[2,2.52,15.14]],"ltp":1.89,"tv":132.54,"id":11772759}]}]}
{"op":"mcm","clk":"1008166622","pt":1580630612569,"mc":[{"id":"1.168222848","rc":[{"batb":[[1,1.78,51.49]],"ltp":1.89,"tv":132.54,"id":11772759}]}]}
{"op":"mcm","clk":"1008166657","pt":1580630613187,"mc":[{"id":"1.168222848","rc":[{"batb":[[2,1.86,327.84]],"ltp":1.99,"tv":314.92,"id":9631075},{"batb":[[1,1.79,300.02],[2,1.78,51.49]],"ltp":1.89,"tv":132.54,"id":11772759}]}]}
{"op":"mcm","clk":"1008244597","pt":1580631849310,"mc":[{"id":"1.168222848","rc":[{"batb":[[0,1.86,6.97],[1,1.85,87.01],[2,1.79,300.02]],"ltp":1.89,"tv":132.54,"id":11772759}]}]}
{"op":"mcm","clk":"1008244635","pt":1580631850026,"mc":[{"id":"1.168222848","rc":[{"batb":[[1,1.89,5.88],[2,1.88,290.79]],"ltp":1.99,"tv":314.92,"id":9631075}]}]}
{"op":"mcm","clk":"1008251163","pt":1580631974383,"mc":[{"id":"1.168222848","rc":[{"batb":[[0,1.87,65.59],[1,1.86,6.97]],"ltp":1.89,"tv":132.54,"id":11772759}]}]}
{"op":"mcm","clk":"1008349800","pt":1580633738501,"mc":[{"id":"1.168222848","rc":[{"trd":[[2,17.08]],"batl":[[0,2,4.07]],"ltp":2.0,"tv":149.61,"id":11772759}],"tv":464.54}]}
{"op":"mcm","clk":"1008350178","pt":1580633745525,"mc":[{"id":"1.168222848","rc":[{"trd":[[2,95.44]],"batb":[[0,2,19.58]],"ltp":2.0,"tv":410.37,"id":9631075}],"tv":559.98}]}
{"op":"mcm","clk":"1008350369","pt":1580633748913,"mc":[{"id":"1.168222848","rc":[{"batb":[[0,2,12.6],[1,1.97,33.36],[2,1.89,5.88]],"ltp":2.0,"tv":410.37,"id":9631075},{"batb":[[0,1.9,84.38]],"ltp":2.0,"tv":149.61,"id":11772759}]}]}
{"op":"mcm","clk":"1008350466","pt":1580633750507,"mc":[{"id":"1.168222848","rc":[{"batl":[[0,2.04,49.75],[1,2.52,15.14],[2,95,15.9]],"ltp":2.0,"tv":149.61,"id":11772759}]}]}
{"op":"mcm","clk":"1008350515","pt":1580633751324,"mc":[{"id":"1.168222848","rc":[{"batl":[[0,2.12,8.4],[1,12,3.36],[2,95,15.9]],"ltp":2.0,"tv":410.37,"id":9631075},{"batb":[[0,1.91,9.23],[1,1.9,84.38],[2,1.86,6.97]],"batl":[[0,2,8.4],[1,2.04,49.75],[2,2.52,15.14]],"ltp":2.0,"tv":149.61,"id":11772759}]}]}
{"op":"mcm","clk":"1008351922","pt":1580633775954,"mc":[{"id":"1.168222848","rc":[{"batb":[[0,1.92,64.65],[1,1.91,9.23]],"ltp":2.0,"tv":149.61,"id":11772759}]}]}
{"op":"mcm","clk":"1008352354","pt":1580633782672,"mc":[{"id":"1.168222848","rc":[{"batl":[[0,95,15.9],[1,990,2.2],[2,1000,0.13]],"ltp":2.0,"tv":410.37,"id":9631075},{"trd":[[2,28.47]],"batl":[[0,2,2.71]],"ltp":2.0,"tv":161.01,"id":11772759}],"tv":571.38}]}
{"op":"mcm","clk":"1008352455","pt":1580633783560,"mc":[{"id":"1.168222848","rc":[{"batl":[[0,2.1,8.4],[1,95,15.9],[2,990,2.2]],"ltp":2.0,"tv":410.37,"id":9631075},{"batb":[[1,1.86,6.97],[2,1.79,300.02]],"ltp":2.0,"tv":161.01,"id":11772759}]}]}
{"op":"mcm","clk":"1008352480","pt":1580633783870,"mc":[{"id":"1.168222848","rc":[{"batb":[[0,1.92,73.79]],"ltp":2.0,"tv":161.01,"id":11772759}]}]}
{"op":"mcm","clk":"1008354875","pt":1580633815702,"mc":[{"id":"1.168222848","rc":[{"batl":[[0,2.04,49.75],[1,2.52,15.14],[2,95,15.9]],"ltp":2.0,"tv":161.01,"id":11772759}]}]}
{"op":"mcm","clk":"1008354927","pt":1580633816628,"mc":[{"id":"1.168222848","rc":[{"trd":[[2,112.58]],"batb":[[0,2,4.03]],"ltp":2.0,"tv":427.51,"id":9631075},{"batl":[[0,2,8.4],[1,2.04,49.75],[2,2.52,15.14]],"ltp":2.0,"tv":161.01,"id":11772759}],"tv":588.52}]}
{"op":"mcm","clk":"1008356756","pt":1580633848165,"mc":[{"id":"1.168222848","rc":[{"batb":[[0,1.97,33.36],[1,1.89,5.88],[2,1.88,290.79]],"ltp":2.0,"tv":427.51,"id":9631075},{"batl":[[0,2.04,49.75],[1,2.52,15.14],[2,95,15.9]],"ltp":2.0,"tv":161.01,"id":11772759}]}]}
{"op":"mcm","clk":"1008393212","pt":1580634488076,"mc":[{"id":"1.168222848","rc":[{"trd":[[1.97,115.32]],"batb":[[0,1.97,10.37]],"ltp":1.97,"tv":473.5,"id":9631075}],"tv":634.52}]}
{"op":"mcm","clk":"1008393287","pt":1580634489264,"mc":[{"id":"1.168222848","rc":[{"batb":[[1,1.9,2.53],[2,1.86,6.97]],"ltp":2.0,"tv":161.01,"id":11772759}]}]}
{"op":"mcm","clk":"1008393344","pt":1580634489982,"mc":[{"id":"1.168222848","rc":[{"batb":[[0,1.9,76.37]],"ltp":1.97,"tv":473.5,"id":9631075},{"batb":[[0,1.93,78.1],[1,1.92,9.13],[2,1.9,2.53]],"ltp":2.0,"tv":161.01,"id":11772759}]}]}
{"op":"mcm","clk":"1008393927","pt":1580634499493,"mc":[{"id":"1.168222848","rc":[{"batl":[[0,95,15.9],[1,990,2.2],[2,1000,0.13]],"ltp":1.97,"tv":473.5,"id":9631075},{"batb":[[1,1.9,2.53],[2,1.86,6.97]],"ltp":2.0,"tv":161.01,"id":11772759}]}]}
{"op":"mcm","clk":"1008393961","pt":1580634500065,"mc":[{"id":"1.168222848","rc":[{"batl":[[0,2.08,12.6],[1,95,15.9],[2,990,2.2]],"ltp":1.97,"tv":473.5,"id":9631075},{"batb":[[0,1.93,91.65]],"ltp":2.0,"tv":161.01,"id":11772759}]}]}
{"op":"mcm","clk":"1008395278","pt":1580634521596,"mc":[{"id":"1.168222848","rc":[{"batb":[[2,1.79,300.02]],"ltp":2.0,"tv":161.01,"id":11772759}]}]}
{"op":"mcm","clk":"1008395316","pt":1580634522112,"mc":[{"id":"1.168222848","rc":[{"batb":[[1,1.88,290.79],[2,1.86,327.84]],"ltp":1.97,"tv":473.5,"id":9631075},{"trd":[[2.04,91.91]],"batl":[[0,2.04,24.75]],"ltp":2.04,"tv":211.01,"id":11772759}],"tv":684.52}]}
{"op":"mcm","clk":"1008397660","pt":1580634559455,"mc":[{"id":"1.168222848","rc":[{"batb":[[0,1.89,86.49]],"ltp":1.97,"tv":473.5,"id":9631075}]}]}
{"op":"mcm","clk":"1008397699","pt":1580634560131,"mc":[{"id":"1.168222848","rc":[{"trd":[[2.04,127.29]],"batl":[[0,2.04,7.06]],"ltp":2.04,"tv":246.39,"id":11772759}],"tv":719.9}]}
{"op":"mcm","clk":"1008412066","pt":1580634785264,"mc":[{"id":"1.168222848","rc":[{"batb":[[1,1.86,327.84],[2,1.81,37.86]],"ltp":1.97,"tv":473.5,"id":9631075}]}]}
{"op":"mcm","clk":"1008412126","pt":1580634786293,"mc":[{"id":"1.168222848","rc":[{"trd":[[2.04,137.69]],"batl":[[0,2.04,1.86]],"ltp":2.04,"tv":256.79,"id":11772759}],"tv":730.3}]}
{"op":"mcm","clk":"1008412300","pt":1580634789376,"mc":[{"id":"1.168222848","rc":[{"batl":[[2,4,3.03]],"ltp":2.04,"tv":256.79,"id":11772759}]}]}
{"op":"mcm","clk":"1008412739","pt":1580634797508,"mc":[{"id":"1.168222848","rc":[{"batl":[[2,4,3.41]],"ltp":2.04,"tv":256.79,"id":11772759}]}]}
{"op":"mcm","clk":"1008413297","pt":1580634807518,"mc":[{"id":"1.168222848","rc":[{"batl":[[1,2.52,15.52],[2,95,15.9]],"ltp":2.04,"tv":256.79,"id":11772759}]}]}
{"op":"mcm","clk":"1008414191","pt":1580634823104,"mc":[{"id":"1.168222848","rc":[{"batl":[[0,2.06,72.92],[1,2.08,12.6],[2,95,15.9]],"ltp":1.97,"tv":473.5,"id":9631075}]}]}
{"op":"mcm","clk":"1008414343","pt":1580634825631,"mc":[{"id":"1.168222848","rc":[{"batb":[[0,1.95,59.31],[1,1.93,13.55],[2,1.9,2.53]],"ltp":2.04,"tv":256.79,"id":11772759}]}]}
{"op":"mcm","clk":"1008415226","pt":1580634840444,"mc":[{"id":"1.168222848","rc":[{"batl":[[1,95,15.9],[2,990,2.2]],"ltp":1.97,"tv":473.5,"id":9631075}]}]}
{"op":"mcm","clk":"1008415292","pt":1580634841428,"mc":[{"id":"1.168222848","rc":[{"batl":[[0,2.04,12.6],[1,2.06,72.92],[2,95,15.9]],"ltp":1.97,"tv":473.5,"id":9631075},{"batb":[[0,1.95,72.58],[1,1.9,2.53],[2,1.79,300.02]],"batl":[[1,2.1,238.56],[2,2.52,15.14]],"ltp":2.04,"tv":256.79,"id":11772759}]}]}
{"op":"mcm","clk":"1008417112","pt":1580634873103,"mc":[{"id":"1.168222848","rc":[{"batb":[[0,1.96,13.13],[1,1.95,59.31],[2,1.9,2.53]],"ltp":2.04,"tv":256.79,"id":11772759}]}]}
{"op":"mcm","clk":"1008422094","pt":1580634958193,"mc":[{"id":"1.168222848","rc":[{"batb":[[0,1.91,66.43]],"ltp":1.97,"tv":473.5,"id":9631075},{"batb":[[0,1.97,41.19],[1,1.96,13.13]],"ltp":2.04,"tv":256.79,"id":11772759}]}]}
{"op":"mcm","clk":"1008422524","pt":1580634966588,"mc":[{"id":"1.168222848","rc":[{"batb":[[0,1.92,260.44],[1,1.91,66.43],[2,1.86,327.84]],"ltp":1.97,"tv":473.5,"id":9631075},{"batb":[[0,1.97,54.18],[1,1.9,2.53],[2,1.79,300.02]],"batl":[[1,2.52,15.52],[2,95,15.9]],"ltp":2.04,"tv":256.79,"id":11772759}]}]}
{"op":"mcm","clk":"1008429661","pt":1580635090990,"mc":[{"id":"1.168222848","rc":[{"batb":[[0,1.93,47.1],[1,1.92,260.44]],"ltp":1.97,"tv":473.5,"id":9631075}]}]}
{"op":"mcm","clk":"1008429943","pt":1580635095989,"mc":[{"id":"1.168222848","rc":[{"batb":[[1,1.86,327.84],[2,1.81,37.86]],"ltp":1.97,"tv":473.5,"id":9631075},{"batl":[[1,2.28,18.86],[2,2.52,15.14]],"ltp":2.04,"tv":256.79,"id":11772759}]}]}
{"op":"mcm","clk":"1008430845","pt":1580635110736,"mc":[{"id":"1.168222848","rc":[{"batl":[[2,2.28,18.48]],"ltp":1.97,"tv":473.5,"id":9631075}]}]}
{"op":"mcm","clk":"1008437090","pt":1580635224485,"mc":[{"id":"1.168222848","rc":[{"batb":[[0,1.89,86.49]],"ltp":1.97,"tv":473.5,"id":9631075}]}]}
{"op":"mcm","clk":"1008437113","pt":1580635224853,"mc":[{"id":"1.168222848","rc":[{"batl":[[1,2.1,238.56],[2,2.28,18.48]],"ltp":2.04,"tv":256.79,"id":11772759}]}]}
{"op":"mcm","clk":"1008444760","pt":1580635360341,"mc":[{"id":"1.168222848","rc":[{"batb":[[0,1.91,66.43]],"ltp":1.97,"tv":473.5,"id":9631075}]}]}
{"op":"mcm","clk":"1008483384","pt":1580635996119,"mc":[{"id":"1.168222848","rc":[{"batl":[[0,2,2],[1,2.04,1.86],[2,2.28,18.86]],"ltp":2.04,"tv":256.79,"id":11772759}]}]}
{"op":"mcm","clk":"1008485417","pt":1580636026661,"mc":[{"id":"1.168222848","rc":[{"trd":[[2,114.58]],"ltp":2.0,"tv":475.5,"id":9631075},{"trd":[[2,30.47]],"batl":[[0,2.04,1.86],[1,2.28,18.86],[2,2.52,15.14]],"ltp":2.0,"tv":258.79,"id":11772759}],"tv":734.29}]}
{"op":"mcm","clk":"1008485471","pt":1580636027335,"mc":[{"id":"1.168222848","rc":[{"batb":[[0,1.9,78.42]],"ltp":2.0,"tv":475.5,"id":9631075},{"batb":[[0,1.97,52.17]],"ltp":2.0,"tv":258.79,"id":11772759}]}]}
{"op":"mcm","clk":"1008489609","pt":1580636081435,"mc":[{"id":"1.168222848","rc":[{"batb":[[1,1.86,52.25]],"ltp":2.0,"tv":475.5,"id":9631075},{"batb":[[2,1.78,51.49]],"ltp":2.0,"tv":258.79,"id":11772759}]}]}
{"op":"mcm","clk":"1008489654","pt":1580636082053,"mc":[{"id":"1.168222848","rc":[{"batb":[[2,1.85,278.84]],"ltp":2.0,"tv":475.5,"id":9631075},{"batb":[[2,1.8,296.27]],"ltp":2.0,"tv":258.79,"id":11772759}]}]}
{"op":"mcm","clk":"1008517288","pt":1580636474513,"mc":[{"id":"1.168222848","rc":[{"batl":[[0,2.02,7.57],[1,2.04,12.6],[2,2.06,72.92]],"ltp":2.0,"tv":475.5,"id":9631075}]}]}
{"op":"mcm","clk":"1008517630","pt":1580636478909,"mc":[{"id":"1.168222848","rc":[{"batl":[[0,2.02,80.49],[2,2.28,18.48]],"ltp":2.0,"tv":475.5,"id":9631075}]}]}
{"op":"mcm","clk":"1008517918","pt":1580636483600,"mc":[{"id":"1.168222848","rc":[{"batl":[[1,2.28,18.48],[2,95,15.9]],"ltp":2.0,"tv":475.5,"id":9631075},{"batb":[[0,1.97,39.18]],"ltp":2.0,"tv":258.79,"id":11772759}]}]}
{"op":"mcm","clk":"1008517956","pt":1580636484214,"mc":[{"id":"1.168222848","rc":[{"batl":[[0,2.02,93.1]],"ltp":2.0,"tv":475.5,"id":9631075},{"batb":[[0,1.98,12.86],[1,1.97,39.18],[2,1.9,2.53]],"ltp":2.0,"tv":258.79,"id":11772759}]}]}
{"op":"mcm","clk":"1008518271","pt":1580636489014,"mc":[{"id":"1.168222848","rc":[{"batl":[[1,2.1,239.53],[2,2.28,18.48]],"ltp":2.0,"tv":258.79,"id":11772759}]}]}
{"op":"mcm","clk":"1008518474","pt":1580636492714,"mc":[{"id":"1.168222848","rc":[{"batl":[[0,2.02,88.33]],"ltp":2.0,"tv":475.5,"id":9631075}]}]}
{"op":"mcm","clk":"1008520944","pt":1580636524591,"mc":[{"id":"1.168222848","rc":[{"batl":[[2,2.36,74.21]],"ltp":2.0,"tv":475.5,"id":9631075}]}]}
{"op":"mcm","clk":"1008522972","pt":1580636547602,"mc":[{"id":"1.168222848","rc":[{"batb":[[0,1.99,21.7],[1,1.98,12.86]],"ltp":2.0,"tv":258.79,"id":11772759}]}]}
{"op":"mcm","clk":"1008524996","pt":1580636577548,"mc":[{"id":"1.168222848","rc":[{"batb":[[1,1.9,2.53],[2,1.8,296.27]],"ltp":2.0,"tv":258.79,"id":11772759}]}]}
{"op":"mcm","clk":"1008525017","pt":1580636577858,"mc":[{"id":"1.168222848","rc":[{"batb":[[0,1.99,34.43]],"ltp":2.0,"tv":258.79,"id":11772759}]}]}
{"op":"mcm","clk":"1008525166","pt":1580636580180,"mc":[{"id":"1.168222848","rc":[{"batl":[[0,2.02,80.75]],"ltp":2.0,"tv":475.5,"id":9631075}]}]}
{"op":"mcm","clk":"1008577433","pt":1580637346683,"mc":[{"id":"1.168222848","rc":[{"batl":[[0,2,7.57],[1,2.02,80.75],[2,2.28,18.48]],"ltp":2.0,"tv":475.5,"id":9631075},{"batb":[[2,1.81,37.86]],"ltp":2.0,"tv":258.79,"id":11772759}]}]}
{"op":"mcm","clk":"1008577784","pt":1580637351639,"mc":[{"id":"1.168222848","rc":[{"batl":[[1,2.02,68.15]],"ltp":2.0,"tv":475.5,"id":9631075},{"batb":[[0,1.99,21.7]],"ltp":2.0,"tv":258.79,"id":11772759}]}]}
{"op":"mcm","clk":"1008577813","pt":1580637352002,"mc":[{"id":"1.168222848","rc":[{"batl":[[0,2,20.18]],"ltp":2.0,"tv":475.5,"id":9631075},{"batb":[[0,2,12.6],[1,1.99,21.7],[2,1.9,2.53]],"ltp":2.0,"tv":258.79,"id":11772759}]}]}
{"op":"mcm","clk":"1008599859","pt":1580637657347,"mc":[{"id":"1.168222848","rc":[{"batb":[[1,1.85,331.09],[2,1.81,37.86]],"ltp":2.0,"tv":475.5,"id":9631075}]}]}
{"op":"mcm","clk":"1008608089","pt":1580637771033,"mc":[{"id":"1.168222848","rc":[{"batb":[[0,2,12.78]],"ltp":2.0,"tv":258.79,"id":11772759}]}]}
{"op":"mcm","clk":"1008617254","pt":1580637888211,"mc":[{"id":"1.168222848","rc":[{"trd":[[2,47.79],[2.02,0.36]],"batb":[[0,2,3.94]],"ltp":2.0,"tv":276.47,"id":11772759}],"tv":751.98}]}
{"op":"mcm","clk":"1008618089","pt":1580637899729,"mc":[{"id":"1.168222848","rc":[{"trd":[[2,134.76]],"batl":[[0,2.02,68.15],[1,2.28,18.48],[2,2.36,74.21]],"ltp":2.0,"tv":495.68,"id":9631075},{"trd":[[2,75.85]],"batb":[[0,1.99,21.7],[1,1.9,2.53],[2,1.81,37.86]],"batl":[[0,2,281.88],[1,2.04,1.86],[2,2.1,239.53]],"ltp":2.0,"tv":304.53,"id":11772759}],"tv":800.21}]}
{"op":"mcm","clk":"1008618161","pt":1580637900564,"mc":[{"id":"1.168222848","rc":[{"trd":[[2,142.37]],"batb":[[0,1.99,7.61],[1,1.9,78.42],[2,1.85,331.09]],"ltp":2.0,"tv":503.29,"id":9631075},{"trd":[[2,83.46]],"batl":[[0,2,274.27],[2,2.28,18.86]],"ltp":2.0,"tv":312.14,"id":11772759}],"tv":815.43}]}
{"op":"mcm","clk":"1008619037","pt":1580637909352,"mc":[{"id":"1.168222848","rc":[{"trd":[[2.02,29.02]],"batl":[[0,2.02,53.64]],"ltp":2.02,"tv":532.31,"id":9631075}],"tv":844.45}]}
{"op":"mcm","clk":"1008619116","pt":1580637910289,"mc":[{"id":"1.168222848","rc":[{"batb":[[0,1.9,78.42],[1,1.85,331.09],[2,1.81,37.86]],"ltp":2.02,"tv":532.31,"id":9631075}]}]}
{"op":"mcm","clk":"1008625298","pt":1580637982582,"mc":[{"id":"1.168222848","rc":[{"trd":[[2,155.56]],"batb":[[0,1.91,82.01]],"ltp":2.0,"tv":545.5,"id":9631075},{"trd":[[2,96.65]],"batb":[[0,1.91,82.07]],"batl":[[0,2,261.08]],"ltp":2.0,"tv":325.33,"id":11772759}],"tv":870.83}]}
{"op":"mcm","clk":"1008625327","pt":1580637982999,"mc":[{"id":"1.168222848","rc":[{"trd":[[2,170.65]],"batl":[[0,2,224.08]],"ltp":2.0,"tv":399.33,"id":11772759}],"tv":944.83}]}
{"op":"mcm","clk":"1008625744","pt":1580637987900,"mc":[{"id":"1.168222848","rc":[{"batb":[[0,1.97,7.69],[1,1.91,82.01],[2,1.85,331.09]],"ltp":2.0,"tv":545.5,"id":9631075}]}]}
{"op":"mcm","clk":"1008625958","pt":1580637990603,"mc":[{"id":"1.168222848","rc":[{"batl":[[1,2.08,7.57],[2,2.28,18.48]],"ltp":2.0,"tv":545.5,"id":9631075}]}]}
{"op":"mcm","clk":"1008632553","pt":1580638070253,"mc":[{"id":"1.168222848","rc":[{"trd":[[2.02,29.31]],"batl":[[0,2.02,53.5]],"ltp":2.02,"tv":545.78,"id":9631075}],"tv":945.12}]}
{"op":"mcm","clk":"1008632637","pt":1580638071169,"mc":[{"id":"1.168222848","rc":[{"trd":[[2,252.65]],"batl":[[0,2,183.08]],"ltp":2.0,"tv":481.33,"id":11772759}],"tv":1027.12}]}
{"op":"mcm","clk":"1008635898","pt":1580638110509,"mc":[{"id":"1.168222848","rc":[{"batb":[[2,1.86,275.59]],"ltp":2.02,"tv":545.78,"id":9631075},{"trd":[[2,340.65]],"batl":[[0,2,139.08]],"ltp":2.0,"tv":569.33,"id":11772759}],"tv":1115.12}]}
{"op":"mcm","clk":"1008635988","pt":1580638111687,"mc":[{"id":"1.168222848","rc":[{"batb":[[0,1.9,2.53],[1,1.81,37.86],[2,1.78,303.86]],"ltp":2.0,"tv":569.33,"id":11772759}]}]}
{"op":"mcm","clk":"1008635995","pt":1580638111806,"mc":[{"id":"1.168222848","rc":[{"batb":[[2,1.88,52.25]],"ltp":2.02,"tv":545.78,"id":9631075},{"batb":[[0,1.93,62.66],[1,1.9,2.53],[2,1.81,37.86]],"ltp":2.0,"tv":569.33,"id":11772759}]}]}
{"op":"mcm","clk":"1008637043","pt":1580638124127,"mc":[{"id":"1.168222848","rc":[{"batb":[[2,1.86,327.84]],"ltp":2.02,"tv":545.78,"id":9631075}]}]}
{"op":"mcm","clk":"1008664360","pt":1580638426443,"mc":[{"id":"1.168222848","rc":[{"trd":[[2,430.65]],"batl":[[0,2,94.08]],"ltp":2.0,"tv":659.33,"id":11772759}],"tv":1205.12}]}
{"op":"mcm","clk":"1008678288","pt":1580638586620,"mc":[{"id":"1.168222848","rc":[{"trd":[[2,530.65]],"batl":[[0,2,44.08]],"ltp":2.0,"tv":759.33,"id":11772759}],"tv":1305.12}]}
{"op":"mcm","clk":"1008724246","pt":1580639059126,"mc":[{"id":"1.168222848","rc":[{"trd":[[2,604.19]],"batl":[[0,2,7.31]],"ltp":2.0,"tv":832.87,"id":11772759}],"tv":1378.66}]}
{"op":"mcm","clk":"1008725900","pt":1580639076062,"mc":[{"id":"1.168222848","rc":[{"trd":[[2,615.89]],"batl":[[0,2,1.46]],"ltp":2.0,"tv":844.57,"id":11772759}],"tv":1390.36}]}
{"op":"mcm","clk":"1008726035","pt":1580639077627,"mc":[{"id":"1.168222848","rc":[{"batb":[[0,1.97,16.35]],"batl":[[0,2.02,61.9]],"ltp":2.02,"tv":545.78,"id":9631075},{"batb":[[0,1.98,8.57],[1,1.93,62.66],[2,1.9,2.53]],"batl":[[1,2.04,10.26]],"ltp":2.0,"tv":844.57,"id":11772759}]}]}
{"op":"mcm","clk":"1008735272","pt":1580639169263,"mc":[{"id":"1.168222848","rc":[{"trd":[[1.97,139.2],[2,157.02]],"batb":[[0,1.97,4.41]],"ltp":1.97,"tv":571.12,"id":9631075},{"trd":[[2,617.35]],"batl":[[0,2.04,10.26],[1,2.28,18.86],[2,2.52,15.14]],"ltp":2.0,"tv":846.03,"id":11772759}],"tv":1417.16}]}
{"op":"mcm","clk":"1008735862","pt":1580639174272,"mc":[{"id":"1.168222848","rc":[{"trd":[[2.04,154.43]],"batl":[[0,2.04,1.89]],"ltp":2.04,"tv":862.78,"id":11772759}],"tv":1433.9}]}
{"op":"mcm","clk":"1008738085","pt":1580639193372,"mc":[{"id":"1.168222848","rc":[{"batb":[[0,1.97,7.5]],"ltp":1.97,"tv":571.12,"id":9631075}]}]}
{"op":"mcm","clk":"1008739148","pt":1580639203684,"mc":[{"id":"1.168222848","rc":[{"batb":[[0,1.97,3.09]],"ltp":1.97,"tv":571.12,"id":9631075},{"batl":[[0,2.28,18.86],[1,2.52,15.14],[2,4.2,153.72]],"ltp":2.04,"tv":862.78,"id":11772759}]}]}
{"op":"mcm","clk":"1008739201","pt":1580639204306,"mc":[{"id":"1.168222848","rc":[{"trd":[[1.97,145.38]],"batb":[[0,1.91,82.01],[1,1.86,327.84],[2,1.81,37.86]],"ltp":1.97,"tv":577.3,"id":9631075}],"tv":1440.08}]}
{"op":"mcm","clk":"1008741706","pt":1580639224404,"mc":[{"id":"1.168222848","rc":[{"batb":[[0,1.92,16.19],[1,1.91,82.01],[2,1.86,327.84]],"batl":[[0,1.99,3.06],[1,2.02,61.9],[2,2.08,7.57]],"ltp":1.97,"tv":577.3,"id":9631075}]}]}
{"op":"mcm","clk":"1008742954","pt":1580639235670,"mc":[{"id":"1.168222848","rc":[{"batl":[[0,1.99,15.66],[1,2.02,53.5]],"ltp":1.97,"tv":577.3,"id":9631075},{"batb":[[0,2,12.6]],"ltp":2.04,"tv":862.78,"id":11772759}]}]}
{"op":"mcm","clk":"1008748833","pt":1580639292423,"mc":[{"id":"1.168222848","rc":[{"trd":[[1.99,86.84]],"batl":[[0,1.99,7.22]],"ltp":1.99,"tv":594.19,"id":9631075}],"tv":1456.97}]}
{"op":"mcm","clk":"1008748917","pt":1580639293315,"mc":[{"id":"1.168222848","rc":[{"batb":[[0,1.93,54.03],[1,1.92,260.44]],"ltp":1.99,"tv":594.19,"id":9631075},{"batb":[[1,1.99,16.92]],"ltp":2.04,"tv":862.78,"id":11772759}]}]}
{"op":"mcm","clk":"1008752113","pt":1580639328351,"mc":[{"id":"1.168222848","rc":[{"batl":[[2,2.28,18.48]],"ltp":1.99,"tv":594.19,"id":9631075}]}]}
{"op":"mcm","clk":"1008752166","pt":1580639328937,"mc":[{"id":"1.168222848","rc":[{"batl":[[0,2.02,53.5],[1,2.28,18.48],[2,2.36,74.21]],"ltp":1.99,"tv":594.19,"id":9631075}]}]}
{"op":"mcm","clk":"1008754533","pt":1580639352286,"mc":[{"id":"1.168222848","rc":[{"batb":[[1,1.86,327.84],[2,1.81,37.86]],"ltp":1.99,"tv":594.19,"id":9631075}]}]}
{"op":"mcm","clk":"1008761611","pt":1580639418492,"mc":[{"id":"1.168222848","rc":[{"batb":[[0,1.9,83.36]],"ltp":1.99,"tv":594.19,"id":9631075}]}]}
{"op":"mcm","clk":"1008765327","pt":1580639452748,"mc":[{"id":"1.168222848","rc":[{"batl":[[0,2,8.4],[1,2.02,53.5],[2,2.28,18.48]],"ltp":1.99,"tv":594.19,"id":9631075}]}]}
{"op":"mcm","clk":"1008770424","pt":1580639497935,"mc":[{"id":"1.168222848","rc":[{"batl":[[0,1.99,7.57],[1,2,8.4],[2,2.02,53.5]],"ltp":1.99,"tv":594.19,"id":9631075}]}]}
{"op":"mcm","clk":"1008771115","pt":1580639504926,"mc":[{"id":"1.168222848","rc":[{"batl":[[0,2,8.4],[1,2.02,53.5],[2,2.28,18.48]],"ltp":1.99,"tv":594.19,"id":9631075}]}]}
{"op":"mcm","clk":"1008785617","pt":1580639640511,"mc":[{"id":"1.168222848","rc":[{"batb":[[1,1.87,8.81],[2,1.86,327.84]],"ltp":1.99,"tv":594.19,"id":9631075}]}]}
{"op":"mcm","clk":"1008833321","pt":1580640067516,"mc":[{"id":"1.168222848","rc":[{"batb":[[0,1.91,269.41],[1,1.9,83.36]],"ltp":1.99,"tv":594.19,"id":9631075}]}]}
{"op":"mcm","clk":"1008833461","pt":1580640068879,"mc":[{"id":"1.168222848","rc":[{"batb":[[0,1.92,9.23],[1,1.91,269.41],[2,1.9,83.36]],"ltp":1.99,"tv":594.19,"id":9631075},{"batl":[[0,2.08,8.63],[1,2.28,18.86],[2,2.52,15.14]],"ltp":2.04,"tv":862.78,"id":11772759}]}]}
{"op":"mcm","clk":"1008835081","pt":1580640084608,"mc":[{"id":"1.168222848","rc":[{"batb":[[0,1.94,7.57],[1,1.92,9.23],[2,1.91,269.41]],"ltp":1.99,"tv":594.19,"id":9631075}]}]}
{"op":"mcm","clk":"1008835378","pt":1580640087314,"mc":[{"id":"1.168222848","rc":[{"batb":[[2,1.91,261.84]],"ltp":1.99,"tv":594.19,"id":9631075}]}]}
{"op":"mcm","clk":"1008835461","pt":1580640088151,"mc":[{"id":"1.168222848","rc":[{"batl":[[0,1.99,7.57],[1,2,8.4],[2,2.02,53.5]],"ltp":1.99,"tv":594.19,"id":9631075}]}]}
{"op":"mcm","clk":"1008835635","pt":1580640089925,"mc":[{"id":"1.168222848","rc":[{"batl":[[0,2,8.4],[1,2.02,53.5],[2,2.28,18.48]],"ltp":1.99,"tv":594.19,"id":9631075}]}]}
{"op":"mcm","clk":"1008844738","pt":1580640160527,"mc":[{"id":"1.168222848","rc":[{"batb":[[0,1.95,35.37],[1,1.94,7.57],[2,1.92,9.23]],"ltp":1.99,"tv":594.19,"id":9631075}]}]}
{"op":"mcm","clk":"1008844830","pt":1580640161209,"mc":[{"id":"1.168222848","rc":[{"trd":[[1.95,59.8]],"batb":[[0,1.95,5.47]],"ltp":1.95,"tv":653.99,"id":9631075}],"tv":1516.77}]}
{"op":"mcm","clk":"1008845034","pt":1580640162522,"mc":[{"id":"1.168222848","rc":[{"batb":[[0,1.94,7.57],[1,1.92,42.9],[2,1.91,261.84]],"ltp":1.95,"tv":653.99,"id":9631075},{"batb":[[1,1.99,45.95]],"ltp":2.04,"tv":862.78,"id":11772759}]}]}
{"op":"mcm","clk":"1008870379","pt":1580640346351,"mc":[{"id":"1.168222848","rc":[{"trd":[[1.94,12]],"batb":[[0,1.94,1.58]],"ltp":1.94,"tv":665.99,"id":9631075}],"tv":1528.77}]}
{"op":"mcm","clk":"1008870469","pt":1580640347083,"mc":[{"id":"1.168222848","rc":[{"trd":[[1.95,71.74]],"ltp":1.95,"tv":677.93,"id":9631075}],"tv":1540.71}]}
{"op":"mcm","clk":"1008871020","pt":1580640351769,"mc":[{"id":"1.168222848","rc":[{"batb":[[0,1.94,9.15]],"ltp":1.95,"tv":677.93,"id":9631075}]}]}
{"op":"mcm","clk":"1008984307","pt":1580641272742,"mc":[{"id":"1.168222848","rc":[{"batb":[[0,1.92,42.9],[1,1.91,261.84],[2,1.86,327.84]],"ltp":1.95,"tv":677.93,"id":9631075}]}]}
{"op":"mcm","clk":"1008984440","pt":1580641273687,"mc":[{"id":"1.168222848","rc":[{"batb":[[0,1.93,9.15],[1,1.92,33.67]],"ltp":1.95,"tv":677.93,"id":9631075},{"batl":[[0,2.28,18.86],[1,2.52,15.14],[2,4.2,153.72]],"ltp":2.04,"tv":862.78,"id":11772759}]}]}
{"op":"mcm","clk":"1008985200","pt":1580641279505,"mc":[{"id":"1.168222848","rc":[{"batb":[[2,1.91,2.06]],"batl":[[2,2.04,2.13]],"ltp":1.95,"tv":677.93,"id":9631075},{"batb":[[2,1.98,2.26]],"batl":[[0,2.12,2.59],[1,2.14,2.25],[2,2.28,18.48]],"ltp":2.04,"tv":862.78,"id":11772759}]}]}
{"op":"mcm","clk":"1008993363","pt":1580641338344,"mc":[{"id":"1.168222848","rc":[{"batl":[[1,2.14,2.04]],"ltp":2.04,"tv":862.78,"id":11772759}]}]}
{"op":"mcm","clk":"1008998561","pt":1580641376723,"mc":[{"id":"1.168222848","rc":[{"batb":[[1,1.91,2.06],[2,1.9,2.06]],"ltp":1.95,"tv":677.93,"id":9631075}]}]}
{"op":"mcm","clk":"1008998621","pt":1580641377207,"mc":[{"id":"1.168222848","rc":[{"batl":[[1,2.14,2.18]],"ltp":2.04,"tv":862.78,"id":11772759}]}]}
{"op":"mcm","clk":"1008998958","pt":1580641379719,"mc":[{"id":"1.168222848","rc":[{"batb":[[0,1.91,2.06],[1,1.9,2.06],[2,1.88,73.55]],"ltp":1.95,"tv":677.93,"id":9631075}]}]}
{"op":"mcm","clk":"1008999044","pt":1580641380237,"mc":[{"id":"1.168222848","rc":[{"batb":[[0,1.92,269.59],[2,1.89,2.05]],"ltp":1.95,"tv":677.93,"id":9631075},{"batl":[[0,2.14,2.56],[1,2.16,2.16]],"ltp":2.04,"tv":862.78,"id":11772759}]}]}
{"op":"mcm","clk":"1008999192","pt":1580641381417,"mc":[{"id":"1.168222848","rc":[{"batb":[[0,1.93,9.13],[1,1.92,9.15],[2,1.91,2.06]],"ltp":1.95,"tv":677.93,"id":9631075},{"batl":[[0,2.08,8.63],[1,2.12,2.38],[2,2.14,2.18]],"ltp":2.04,"tv":862.78,"id":11772759}]}]}
{"op":"mcm","clk":"1008999372","pt":1580641382629,"mc":[{"id":"1.168222848","rc":[{"batb":[[0,1.93,18.28],[1,1.91,2.06],[2,1.9,2.06]],"ltp":1.95,"tv":677.93,"id":9631075}]}]}
{"op":"mcm","clk":"1008999518","pt":1580641383749,"mc":[{"id":"1.168222848","rc":[{"batb":[[0,1.93,9.15]],"ltp":1.95,"tv":677.93,"id":9631075},{"batl":[[0,2.12,2.51],[1,2.14,2.18],[2,2.16,2.16]],"ltp":2.04,"tv":862.78,"id":11772759}]}]}
{"op":"mcm","clk":"1008999576","pt":1580641384224,"mc":[{"id":"1.168222848","rc":[{"batl":[[1,2.14,2]],"ltp":2.04,"tv":862.78,"id":11772759}]}]}
{"op":"mcm","clk":"1009001164","pt":1580641395700,"mc":[{"id":"1.168222848","rc":[{"batb":[[0,1.91,2.06],[1,1.9,2.06],[2,1.89,2.05]],"ltp":1.95,"tv":677.93,"id":9631075}]}]}
{"op":"mcm","clk":"1009001273","pt":1580641396403,"mc":[{"id":"1.168222848","rc":[{"batb":[[0,1.92,260.44],[2,1.89,2]],"ltp":1.95,"tv":677.93,"id":9631075},{"batl":[[0,2.14,2.49],[1,2.16,2.16],[2,2.28,18.48]],"ltp":2.04,"tv":862.78,"id":11772759}]}]}
{"op":"mcm","clk":"1009008425","pt":1580641445733,"mc":[{"id":"1.168222848","rc":[{"batb":[[2,1.88,73.55]],"batl":[[0,1.99,7.57],[1,2,8.4],[2,2.02,55.5]],"ltp":1.95,"tv":677.93,"id":9631075},{"batl":[[1,2.28,18.48],[2,2.52,15.14]],"ltp":2.04,"tv":862.78,"id":11772759}]}]}
{"op":"mcm","clk":"1009008453","pt":1580641445950,"mc":[{"id":"1.168222848","rc":[{"batb":[[2,1.89,2.05]],"ltp":1.95,"tv":677.93,"id":9631075},{"batl":[[1,2.16,2.22],[2,2.28,18.48]],"ltp":2.04,"tv":862.78,"id":11772759}]}]}
{"op":"mcm","clk":"1009008747","pt":1580641448054,"mc":[{"id":"1.168222848","rc":[{"batl":[[0,2,8.4],[1,2.02,53.5],[2,2.04,2.13]],"ltp":1.95,"tv":677.93,"id":9631075}]}]}
{"op":"mcm","clk":"1009016460","pt":1580641500702,"mc":[{"id":"1.168222848","rc":[{"batb":[[0,1.93,9.13],[1,1.91,2],[2,1.88,73.55]],"ltp":1.95,"tv":677.93,"id":9631075},{"batl":[[0,2.08,8.63],[1,2.12,2.59]],"ltp":2.04,"tv":862.78,"id":11772759}]}]}
{"op":"mcm","clk":"1009016509","pt":1580641501006,"mc":[{"id":"1.168222848","rc":[{"batb":[[2,1.9,2.06]],"ltp":1.95,"tv":677.93,"id":9631075},{"batl":[[2,2.14,2.25]],"ltp":2.04,"tv":862.78,"id":11772759}]}]}
{"op":"mcm","clk":"1009016756","pt":1580641502601,"mc":[{"id":"1.168222848","rc":[{"batb":[[0,1.92,260.44],[1,1.9,2.06],[2,1.89,2.05]],"ltp":1.95,"tv":677.93,"id":9631075},{"batl":[[0,2.14,2.63],[1,2.16,2],[2,2.28,18.48]],"ltp":2.04,"tv":862.78,"id":11772759}]}]}
{"op":"mcm","clk":"1009017915","pt":1580641509627,"mc":[{"id":"1.168222848","rc":[{"batb":[[0,1.93,24.16],[1,1.91,2.06],[2,1.86,327.84]],"ltp":1.95,"tv":677.93,"id":9631075},{"batl":[[0,2.12,2.38],[1,2.28,18.48],[2,2.52,15.14]],"ltp":2.04,"tv":862.78,"id":11772759}]}]}
{"op":"mcm","clk":"1009018087","pt":1580641510739,"mc":[{"id":"1.168222848","rc":[{"batb":[[0,1.94,7.57],[1,1.93,24.16],[2,1.92,2.19]],"ltp":1.95,"tv":677.93,"id":9631075},{"batl":[[1,2.14,2.11],[2,2.28,18.48]],"ltp":2.04,"tv":862.78,"id":11772759}]}]}
{"op":"mcm","clk":"1009040570","pt":1580641646688,"mc":[{"id":"1.168222848","rc":[{"batb":[[1,1.92,2.19],[2,1.91,2.06]],"ltp":1.95,"tv":677.93,"id":9631075}]}]}
{"op":"mcm","clk":"1009040720","pt":1580641647660,"mc":[{"id":"1.168222848","rc":[{"trd":[[1.94,24.28]],"batb":[[0,1.94,1.43],[2,1.9,2.06]],"ltp":1.94,"tv":690.21,"id":9631075},{"batl":[[1,2.14,2.25]],"ltp":2.04,"tv":862.78,"id":11772759}],"tv":1552.99}]}
{"op":"mcm","clk":"1009040843","pt":1580641648576,"mc":[{"id":"1.168222848","rc":[{"batb":[[1,1.88,73.55],[2,1.86,329.88]],"batl":[[0,1.95,6.11],[1,1.97,2.11],[2,1.98,2.25]],"ltp":1.94,"tv":690.21,"id":9631075},{"batl":[[0,2.14,2.63],[1,2.16,2.22]],"ltp":2.04,"tv":862.78,"id":11772759}]}]}
{"op":"mcm","clk":"1009040938","pt":1580641649186,"mc":[{"id":"1.168222848","rc":[{"batb":[[0,2,14.6],[1,1.99,47.95],[2,1.97,2]],"ltp":2.04,"tv":862.78,"id":11772759}]}]}
{"op":"mcm","clk":"1009041477","pt":1580641652684,"mc":[{"id":"1.168222848","rc":[{"batb":[[0,2,2]],"ltp":2.04,"tv":862.78,"id":11772759}]}]}
{"op":"mcm","clk":"1009041617","pt":1580641653601,"mc":[{"id":"1.168222848","rc":[{"batl":[[0,1.95,14.51]],"ltp":1.94,"tv":690.21,"id":9631075},{"batb":[[0,2.04,8.08],[1,2,2],[2,1.99,47.95]],"batl":[[1,2.28,18.48],[2,2.52,15.14]],"ltp":2.04,"tv":862.78,"id":11772759}]}]}
{"op":"mcm","clk":"1009041796","pt":1580641654655,"mc":[{"id":"1.168222848","rc":[{"batb":[[0,1.94,4.62],[1,1.92,2.19],[2,1.91,2.06]],"batl":[[2,2.02,53.5]],"ltp":1.94,"tv":690.21,"id":9631075},{"batb":[[2,1.99,45.95]],"batl":[[0,2.12,2.43],[1,2.14,2.25],[2,2.16,2]],"ltp":2.04,"tv":862.78,"id":11772759}]}]}
{"op":"mcm","clk":"1009041830","pt":1580641654866,"mc":[{"id":"1.168222848","rc":[{"batl":[[2,1.98,2.17]],"ltp":1.94,"tv":690.21,"id":9631075},{"batb":[[2,1.99,47.95]],"ltp":2.04,"tv":862.78,"id":11772759}]}]}
{"op":"mcm","clk":"1009046433","pt":1580641684645,"mc":[{"id":"1.168222848","rc":[{"batb":[[2,1.88,73.55]],"batl":[[0,1.95,6.11],[2,2.02,53.5]],"ltp":1.94,"tv":690.21,"id":9631075},{"batb":[[2,1.99,45.95]],"batl":[[1,2.28,18.48],[2,2.52,15.14]],"ltp":2.04,"tv":862.78,"id":11772759}]}]}
{"op":"mcm","clk":"1009046468","pt":1580641684823,"mc":[{"id":"1.168222848","rc":[{"batb":[[2,1.91,2.06]],"batl":[[2,1.98,2.18]],"ltp":1.94,"tv":690.21,"id":9631075},{"batb":[[2,1.99,47.95]],"batl":[[1,2.14,2],[2,2.28,18.48]],"ltp":2.04,"tv":862.78,"id":11772759}]}]}
{"op":"mcm","clk":"1009049048","pt":1580641702559,"mc":[{"id":"1.168222848","rc":[{"batb":[[0,1.94,27.34]],"batl":[[2,1.98,2.14]],"ltp":1.94,"tv":690.21,"id":9631075}]}]}
{"op":"mcm","clk":"1009058036","pt":1580641760636,"mc":[{"id":"1.168222848","rc":[{"trd":[[1.94,71.74]],"batb":[[0,1.94,3.6]],"ltp":1.94,"tv":737.67,"id":9631075}],"tv":1600.45}]}
{"op":"mcm","clk":"1009058154","pt":1580641761319,"mc":[{"id":"1.168222848","rc":[{"batl":[[2,1.98,2.25]],"ltp":1.94,"tv":737.67,"id":9631075},{"batl":[[1,2.14,2.18]],"ltp":2.04,"tv":862.78,"id":11772759}]}]}
{"op":"mcm","clk":"1009058384","pt":1580641762742,"mc":[{"id":"1.168222848","rc":[{"batl":[[0,1.95,7.53]],"ltp":1.94,"tv":737.67,"id":9631075}]}]}
{"op":"mcm","clk":"1009060836","pt":1580641778351,"mc":[{"id":"1.168222848","rc":[{"batl":[[1,1.96,3.16],[2,1.97,2.11]],"ltp":1.94,"tv":737.67,"id":9631075},{"batl":[[1,2.14,2.25]],"ltp":2.04,"tv":862.78,"id":11772759}]}]}
{"op":"mcm","clk":"1009064515","pt":1580641804091,"mc":[{"id":"1.168222848","rc":[{"batl":[[1,2.14,2.11]],"ltp":2.04,"tv":862.78,"id":11772759}]}]}
{"op":"mcm","clk":"1009069076","pt":1580641836602,"mc":[{"id":"1.168222848","rc":[{"trd":[[1.95,86.8],[1.96,6.32]],"batb":[[0,1.94,4.39]],"batl":[[0,1.97,2.11],[1,1.98,2.25],[2,2.02,53.5]],"ltp":1.96,"tv":759.06,"id":9631075}],"tv":1621.84}]}
{"op":"mcm","clk":"1009069179","pt":1580641837398,"mc":[{"id":"1.168222848","rc":[{"batb":[[2,1.91,2]],"batl":[[0,1.99,2.08],[1,2,2],[2,2.02,55.5]],"ltp":1.96,"tv":759.06,"id":9631075},{"batl":[[1,2.14,2]],"ltp":2.04,"tv":862.78,"id":11772759}]}]}
{"op":"mcm","clk":"1009069792","pt":1580641841696,"mc":[{"id":"1.168222848","rc":[{"batb":[[0,1.96,3.91],[1,1.94,5.69],[2,1.93,2.08]],"ltp":1.96,"tv":759.06,"id":9631075},{"batl":[[0,2.1,2.43],[1,2.12,2.21],[2,2.14,2]],"ltp":2.04,"tv":862.78,"id":11772759}]}]}
{"op":"mcm","clk":"1009070197","pt":1580641844726,"mc":[{"id":"1.168222848","rc":[{"batb":[[0,1.96,3.12]],"ltp":1.96,"tv":759.06,"id":9631075}]}]}
{"op":"mcm","clk":"1009070280","pt":1580641845206,"mc":[{"id":"1.168222848","rc":[{"trd":[[1.97,146.17]],"batl":[[2,2.02,53.5]],"ltp":1.97,"tv":759.85,"id":9631075},{"trd":[[2.04,155.2]],"batb":[[0,2.04,7.32]],"batl":[[2,2.28,18.48]],"ltp":2.04,"tv":863.54,"id":11772759}],"tv":1623.39}]}
{"op":"mcm","clk":"1009073888","pt":1580641870687,"mc":[{"id":"1.168222848","rc":[{"batl":[[0,2.02,53.5],[1,2.06,2.25],[2,2.08,2.19]],"ltp":1.97,"tv":759.85,"id":9631075},{"batb":[[0,1.99,45.95],[1,1.97,2.17],[2,1.96,2]],"ltp":2.04,"tv":863.54,"id":11772759}]}]}
{"op":"mcm","clk":"1009076634","pt":1580641888747,"mc":[{"id":"1.168222848","rc":[{"batb":[[2,1.88,73.55]],"batl":[[2,2.28,18.48]],"ltp":1.97,"tv":759.85,"id":9631075},{"batb":[[2,1.9,2.53]],"batl":[[1,2.28,18.48],[2,2.52,15.14]],"ltp":2.04,"tv":863.54,"id":11772759}]}]}
{"op":"mcm","clk":"1009076678","pt":1580641888994,"mc":[{"id":"1.168222848","rc":[{"batb":[[2,1.93,2.08]],"batl":[[2,2.08,2.19]],"ltp":1.97,"tv":759.85,"id":9631075},{"batb":[[2,1.96,2.13]],"batl":[[1,2.12,2.13],[2,2.28,18.48]],"ltp":2.04,"tv":863.54,"id":11772759}]}]}
{"op":"mcm","clk":"1009078501","pt":1580641900597,"mc":[{"id":"1.168222848","rc":[{"batl":[[2,2.08,2.07]],"ltp":1.97,"tv":759.85,"id":9631075},{"batb":[[2,1.96,2]],"ltp":2.04,"tv":863.54,"id":11772759}]}]}
{"op":"mcm","clk":"1009078636","pt":1580641901554,"mc":[{"id":"1.168222848","rc":[{"batl":[[0,2,8.4],[1,2.02,53.5],[2,2.04,2.13]],"ltp":1.97,"tv":759.85,"id":9631075},{"batb":[[0,1.99,54.44],[1,1.98,2.26],[2,1.97,2.17]],"ltp":2.04,"tv":863.54,"id":11772759}]}]}
{"op":"mcm","clk":"1009081254","pt":1580641916040,"mc":[{"id":"1.168222848","rc":[{"batb":[[0,1.99,34]],"batl":[[1,2.12,2.21]],"ltp":2.04,"tv":863.54,"id":11772759}]}]}
{"op":"mcm","clk":"1009083782","pt":1580641932667,"mc":[{"id":"1.168222848","rc":[{"batb":[[2,1.93,2]],"ltp":1.97,"tv":759.85,"id":9631075},{"batb":[[0,2,8.4],[1,1.99,25.52],[2,1.98,2.26]],"ltp":2.04,"tv":863.54,"id":11772759}]}]}
{"op":"mcm","clk":"1009103876","pt":1580642060509,"mc":[{"id":"1.168222848","rc":[{"batl":[[2,2.04,21.06]],"ltp":1.97,"tv":759.85,"id":9631075}]}]}
{"op":"mcm","clk":"1009103975","pt":1580642061106,"mc":[{"id":"1.168222848","rc":[{"batb":[[2,1.93,2.08]],"ltp":1.97,"tv":759.85,"id":9631075}]}]}
{"op":"mcm","clk":"1009121519","pt":1580642164752,"mc":[{"id":"1.168222848","rc":[{"batl":[[1,2.12,2]],"ltp":2.04,"tv":863.54,"id":11772759}]}]}
{"op":"mcm","clk":"1009124046","pt":1580642180748,"mc":[{"id":"1.168222848","rc":[{"batl":[[1,2.28,18.48],[2,2.52,15.14]],"ltp":2.04,"tv":863.54,"id":11772759}]}]}
{"op":"mcm","clk":"1009124153","pt":1580642181374,"mc":[{"id":"1.168222848","rc":[{"batl":[[1,2.12,2],[2,2.28,18.48]],"ltp":2.04,"tv":863.54,"id":11772759}]}]}
{"op":"mcm","clk":"1009128701","pt":1580642210609,"mc":[{"id":"1.168222848","rc":[{"batb":[[2,1.9,74.48]],"ltp":1.97,"tv":759.85,"id":9631075},{"batl":[[0,2.1,4.11],[1,2.28,18.48],[2,2.52,15.14]],"ltp":2.04,"tv":863.54,"id":11772759}]}]}
{"op":"mcm","clk":"1009128729","pt":1580642210818,"mc":[{"id":"1.168222848","rc":[{"batb":[[2,1.93,2.08]],"ltp":1.97,"tv":759.85,"id":9631075},{"batl":[[1,2.12,2.13],[2,2.28,18.48]],"ltp":2.04,"tv":863.54,"id":11772759}]}]}
{"op":"mcm","clk":"1009137677","pt":1580642268667,"mc":[{"id":"1.168222848","rc":[{"batl":[[0,1.99,420.1],[1,2,8.4],[2,2.02,55.5]],"ltp":1.97,"tv":759.85,"id":9631075},{"batl":[[1,2.12,2.05]],"ltp":2.04,"tv":863.54,"id":11772759}]}]}
{"op":"mcm","clk":"1009137936","pt":1580642270481,"mc":[{"id":"1.168222848","rc":[{"batl":[[1,2,428.5]],"ltp":1.97,"tv":759.85,"id":9631075}]}]}
{"op":"mcm","clk":"1009138230","pt":1580642272748,"mc":[{"id":"1.168222848","rc":[{"batl":[[0,1.98,8.4],[1,1.99,420.1],[2,2,420.1]],"ltp":1.97,"tv":759.85,"id":9631075}]}]}
{"op":"mcm","clk":"1009138328","pt":1580642273484,"mc":[{"id":"1.168222848","rc":[{"batl":[[2,2,422.1]],"ltp":1.97,"tv":759.85,"id":9631075},{"batb":[[1,1.99,27.52],[2,1.98,2]],"ltp":2.04,"tv":863.54,"id":11772759}]}]}
{"op":"mcm","clk":"1009138804","pt":1580642276689,"mc":[{"id":"1.168222848","rc":[{"batb":[[2,1.9,74.48]],"batl":[[0,1.98,428.5]],"ltp":1.97,"tv":759.85,"id":9631075},{"batl":[[1,2.28,18.48],[2,2.52,15.14]],"ltp":2.04,"tv":863.54,"id":11772759}]}]}
{"op":"mcm","clk":"1009138891","pt":1580642277178,"mc":[{"id":"1.168222848","rc":[{"batb":[[2,1.93,2.08]],"ltp":1.97,"tv":759.85,"id":9631075},{"batl":[[1,2.12,2.21],[2,2.28,18.48]],"ltp":2.04,"tv":863.54,"id":11772759}]}]}
{"op":"mcm","clk":"1009139419","pt":1580642280557,"mc":[{"id":"1.168222848","rc":[{"batl":[[0,1.97,8.4],[1,1.98,428.5],[2,1.99,422.21]],"ltp":1.97,"tv":759.85,"id":9631075},{"trd":[[2.04,171.95]],"batb":[[0,2,10.49],[2,1.9,2.53]],"ltp":2.04,"tv":880.3,"id":11772759}],"tv":1640.15}]}
{"op":"mcm","clk":"1009139581","pt":1580642281678,"mc":[{"id":"1.168222848","rc":[{"trd":[[1.97,162.5]],"batl":[[0,1.98,428.73],[1,1.99,422.21],[2,2,422.1]],"ltp":1.97,"tv":776.18,"id":9631075},{"batb":[[0,2,8.49],[2,1.98,2]],"ltp":2.04,"tv":880.3,"id":11772759}],"tv":1656.48}]}
{"op":"mcm","clk":"1009139738","pt":1580642282687,"mc":[{"id":"1.168222848","rc":[{"batl":[[0,1.98,428.5],[1,1.99,420.1]],"ltp":1.97,"tv":776.18,"id":9631075},{"batb":[[0,2,8.4]],"batl":[[1,2.28,18.48],[2,2.52,15.14]],"ltp":2.04,"tv":880.3,"id":11772759}]}]}
{"op":"mcm","clk":"1009139903","pt":1580642283704,"mc":[{"id":"1.168222848","rc":[{"batl":[[1,2.12,10.27],[2,2.28,18.48]],"ltp":2.04,"tv":880.3,"id":11772759}]}]}
{"op":"mcm","clk":"1009143167","pt":1580642304528,"mc":[{"id":"1.168222848","rc":[{"batb":[[2,1.93,2]],"ltp":1.97,"tv":776.18,"id":9631075},{"batb":[[0,1.99,27.52],[1,1.98,2],[2,1.9,2.53]],"batl":[[1,2.12,10.11]],"ltp":2.04,"tv":880.3,"id":11772759}]}]}
{"op":"mcm","clk":"1009153408","pt":1580642370481,"mc":[{"id":"1.168222848","rc":[{"batb":[[2,1.93,2.08]],"ltp":1.97,"tv":776.18,"id":9631075},{"batl":[[1,2.12,10.27]],"ltp":2.04,"tv":880.3,"id":11772759}]}]}
{"op":"mcm","clk":"1009154007","pt":1580642374657,"mc":[{"id":"1.168222848","rc":[{"batl":[[0,1.97,37.86],[1,1.98,428.5],[2,1.99,422.3]],"ltp":1.97,"tv":776.18,"id":9631075}]}]}
{"op":"mcm","clk":"1009156990","pt":1580642396479,"mc":[{"id":"1.168222848","rc":[{"batl":[[1,1.98,420.1]],"ltp":1.97,"tv":776.18,"id":9631075}]}]}
{"op":"mcm","clk":"1009157062","pt":1580642397065,"mc":[{"id":"1.168222848","rc":[{"batl":[[1,2.12,10.19]],"ltp":2.04,"tv":880.3,"id":11772759}]}]}
{"op":"mcm","clk":"1009164568","pt":1580642445731,"mc":[{"id":"1.168222848","rc":[{"trd":[[1.97,179.84]],"batb":[[2,1.9,74.48]],"batl":[[0,1.97,29.19]],"ltp":1.97,"tv":793.52,"id":9631075},{"batb":[[1,1.9,2.53],[2,1.81,37.86]],"batl":[[1,2.12,8.06]],"ltp":2.04,"tv":880.3,"id":11772759}],"tv":1673.83}]}
{"op":"mcm","clk":"1009164643","pt":1580642446155,"mc":[{"id":"1.168222848","rc":[{"trd":[[1.97,197.29]],"batb":[[2,1.93,2]],"batl":[[0,1.97,20.47]],"ltp":1.97,"tv":810.97,"id":9631075},{"batb":[[1,1.98,2],[2,1.9,2.53]],"batl":[[1,2.12,10.27]],"ltp":2.04,"tv":880.3,"id":11772759}],"tv":1691.27}]}
{"op":"mcm","clk":"1009164744","pt":1580642446851,"mc":[{"id":"1.168222848","rc":[{"trd":[[1.97,214.75]],"batl":[[0,1.97,11.74]],"ltp":1.97,"tv":828.43,"id":9631075}],"tv":1708.73}]}
{"op":"mcm","clk":"1009165109","pt":1580642449450,"mc":[{"id":"1.168222848","rc":[{"trd":[[1.97,232.21]],"batl":[[0,1.97,3.01]],"ltp":1.97,"tv":845.89,"id":9631075}],"tv":1726.19}]}
{"op":"mcm","clk":"1009165325","pt":1580642450757,"mc":[{"id":"1.168222848","rc":[{"trd":[[1.97,238.22]],"batl":[[0,1.98,420.1],[1,1.99,420.1],[2,2,422.1]],"ltp":1.97,"tv":851.9,"id":9631075},{"batb":[[0,1.99,2]],"ltp":2.04,"tv":880.3,"id":11772759}],"tv":1732.21}]}
{"op":"mcm","clk":"1009165359","pt":1580642451074,"mc":[{"id":"1.168222848","rc":[{"batb":[[2,1.97,45.93]],"ltp":2.04,"tv":880.3,"id":11772759}]}]}
{"op":"mcm","clk":"1009206451","pt":1580642734715,"mc":[{"id":"1.168222848","rc":[{"batl":[[0,1.97,26.4],[1,1.98,420.1],[2,1.99,420.1]],"ltp":1.97,"tv":851.9,"id":9631075}]}]}
{"op":"mcm","clk":"1009206549","pt":1580642735399,"mc":[{"id":"1.168222848","rc":[{"batb":[[2,1.93,2.08]],"batl":[[2,1.99,422.47]],"ltp":1.97,"tv":851.9,"id":9631075},{"batb":[[1,1.98,2.26]],"batl":[[1,2.12,10.11]],"ltp":2.04,"tv":880.3,"id":11772759}]}]}
{"op":"mcm","clk":"1009207289","pt":1580642740708,"mc":[{"id":"1.168222848","rc":[{"trd":[[1.97,290.56]],"batl":[[0,1.98,420.33],[1,1.99,420.1],[2,2,422.1]],"ltp":1.97,"tv":904.24,"id":9631075}],"tv":1784.55}]}
{"op":"mcm","clk":"1009252384","pt":1580643034652,"mc":[{"id":"1.168222848","rc":[{"trd":[[1.97,291.03],[1.98,19.94]],"batl":[[0,1.98,410.12]],"ltp":1.98,"tv":924.65,"id":9631075},{"batb":[[1,1.98,2]],"batl":[[1,2.12,10.27]],"ltp":2.04,"tv":880.3,"id":11772759}],"tv":1804.95}]}
{"op":"mcm","clk":"1009257295","pt":1580643064691,"mc":[{"id":"1.168222848","rc":[{"batb":[[2,1.93,2]],"ltp":1.98,"tv":924.65,"id":9631075},{"batl":[[1,2.12,10.19]],"ltp":2.04,"tv":880.3,"id":11772759}]}]}
{"op":"mcm","clk":"1009258850","pt":1580643074721,"mc":[{"id":"1.168222848","rc":[{"batb":[[2,1.9,71.48]],"ltp":1.98,"tv":924.65,"id":9631075},{"batb":[[1,1.97,45.93],[2,1.9,2.53]],"batl":[[1,2.12,8.06]],"ltp":2.04,"tv":880.3,"id":11772759}]}]}
{"op":"mcm","clk":"1009258890","pt":1580643074999,"mc":[{"id":"1.168222848","rc":[{"batb":[[2,1.93,2.08]],"ltp":1.98,"tv":924.65,"id":9631075},{"batb":[[1,1.98,2.26],[2,1.97,45.93]],"batl":[[1,2.12,10.06]],"ltp":2.04,"tv":880.3,"id":11772759}]}]}
{"op":"mcm","clk":"1009306164","pt":1580643388307,"mc":[{"id":"1.168222848","rc":[{"trd":[[1.98,524.06]],"batb":[[2,1.93,2]],"batl":[[0,1.98,158.07]],"ltp":1.98,"tv":1428.77,"id":9631075},{"batl":[[1,2.12,10.11]],"ltp":2.04,"tv":880.3,"id":11772759}],"tv":2309.07}]}
{"op":"mcm","clk":"1009308101","pt":1580643401708,"mc":[{"id":"1.168222848","rc":[{"trd":[[1.98,839.97]],"batb":[[2,1.9,71.48]],"batl":[[0,1.99,420.21],[1,2,420.1],[2,2.02,2.25]],"ltp":1.98,"tv":1744.68,"id":9631075},{"batb":[[1,1.97,45.93],[2,1.9,2.53]],"batl":[[1,2.12,8.06]],"ltp":2.04,"tv":880.3,"id":11772759}],"tv":2624.98}]}
{"op":"mcm","clk":"1009308154","pt":1580643402044,"mc":[{"id":"1.168222848","rc":[{"batb":[[2,1.93,2]],"ltp":1.98,"tv":1744.68,"id":9631075},{"batb":[[0,1.98,2.26],[1,1.97,48.1]],"batl":[[1,2.12,10.27]],"ltp":2.04,"tv":880.3,"id":11772759}]}]}
{"op":"mcm","clk":"1009309387","pt":1580643410736,"mc":[{"id":"1.168222848","rc":[{"batl":[[0,1.98,8.51],[1,1.99,420.1],[2,2,422.1]],"ltp":1.98,"tv":1744.68,"id":9631075},{"batb":[[0,2.02,8.23],[1,1.98,2.26],[2,1.97,48.1]],"ltp":2.04,"tv":880.3,"id":11772759}]}]}
{"op":"mcm","clk":"1009309501","pt":1580643411540,"mc":[{"id":"1.168222848","rc":[{"batb":[[2,1.93,2.08]],"ltp":1.98,"tv":1744.68,"id":9631075},{"batb":[[1,1.99,2],[2,1.98,2]],"batl":[[1,2.12,10.11]],"ltp":2.04,"tv":880.3,"id":11772759}]}]}
{"op":"mcm","clk":"1009347864","pt":1580643673723,"mc":[{"id":"1.168222848","rc":[{"batb":[[2,1.97,45.93]],"batl":[[1,2.12,10.27]],"ltp":2.04,"tv":880.3,"id":11772759}]}]}
{"op":"mcm","clk":"1009347873","pt":1580643673812,"mc":[{"id":"1.168222848","rc":[{"batb":[[2,1.98,2]],"ltp":2.04,"tv":880.3,"id":11772759}]}]}
{"op":"mcm","clk":"1009395634","pt":1580643988753,"mc":[{"id":"1.168222848","rc":[{"trd":[[1.98,848.12]],"batl":[[0,1.99,420.46],[1,2,420.1],[2,2.02,2]],"ltp":1.98,"tv":1752.83,"id":9631075},{"trd":[[2.02,24.81]],"batb":[[0,1.98,2],[1,1.97,48.1],[2,1.9,2.53]],"ltp":2.02,"tv":904.74,"id":11772759}],"tv":2657.58}]}
{"op":"mcm","clk":"1009397132","pt":1580643998495,"mc":[{"id":"1.168222848","rc":[{"batl":[[2,2.02,422.1]],"ltp":1.98,"tv":1752.83,"id":9631075},{"batl":[[1,2.12,10.19]],"ltp":2.02,"tv":904.74,"id":11772759}]}]}
{"op":"mcm","clk":"1009397305","pt":1580643999681,"mc":[{"id":"1.168222848","rc":[{"batl":[[0,1.99,420.1]],"ltp":1.98,"tv":1752.83,"id":9631075}]}]}
{"op":"mcm","clk":"1009397386","pt":1580644000056,"mc":[{"id":"1.168222848","rc":[{"batb":[[0,1.96,16.25]],"ltp":1.98,"tv":1752.83,"id":9631075},{"batl":[[0,2.06,12.6],[1,2.1,4.11],[2,2.12,10.19]],"ltp":2.02,"tv":904.74,"id":11772759}]}]}
{"op":"mcm","clk":"1009401873","pt":1580644031632,"mc":[{"id":"1.168222848","rc":[{"batb":[[0,1.99,28.42],[1,1.98,2],[2,1.97,2.17]],"ltp":2.02,"tv":904.74,"id":11772759}]}]}
{"op":"mcm","clk":"1009402082","pt":1580644032750,"mc":[{"id":"1.168222848","rc":[{"trd":[[1.96,35.46]],"batb":[[0,1.96,1.68],[1,1.94,3.6],[2,1.92,2.19]],"ltp":1.96,"tv":1781.97,"id":9631075},{"batb":[[2,1.97,2]],"batl":[[2,2.12,10.11]],"ltp":2.02,"tv":904.74,"id":11772759}],"tv":2686.72}]}
{"op":"mcm","clk":"1009404975","pt":1580644052748,"mc":[{"id":"1.168222848","rc":[{"batl":[[0,1.98,3.09],[1,1.99,420.1],[2,2,422.1]],"ltp":1.96,"tv":1781.97,"id":9631075}]}]}
{"op":"mcm","clk":"1009405117","pt":1580644053549,"mc":[{"id":"1.168222848","rc":[{"batb":[[0,1.99,30.42],[1,1.98,2.26],[2,1.9,2.53]],"batl":[[2,2.12,10.19]],"ltp":2.02,"tv":904.74,"id":11772759}]}]}
{"op":"mcm","clk":"1009406375","pt":1580644062756,"mc":[{"id":"1.168222848","rc":[{"batb":[[0,1.96,8.75],[1,1.94,5.69],[2,1.93,2.08]],"batl":[[0,1.98,11.49]],"ltp":1.96,"tv":1781.97,"id":9631075},{"trd":[[2.06,21.86]],"batb":[[1,1.98,2]],"batl":[[0,2.06,240.76],[2,2.12,10.11]],"ltp":2.06,"tv":926.6,"id":11772759}],"tv":2708.58}]}
{"op":"mcm","clk":"1009406412","pt":1580644062962,"mc":[{"id":"1.168222848","rc":[{"batb":[[0,2.02,8.23],[1,1.99,30.42],[2,1.98,2]],"batl":[[0,2.06,1.67]],"ltp":2.06,"tv":926.6,"id":11772759}]}]}
{"op":"mcm","clk":"1009410600","pt":1580644094685,"mc":[{"id":"1.168222848","rc":[{"batl":[[0,2.1,4.11],[1,2.12,10.11],[2,2.14,2.11]],"ltp":2.06,"tv":926.6,"id":11772759}]}]}
{"op":"mcm","clk":"1009410679","pt":1580644095316,"mc":[{"id":"1.168222848","rc":[{"batb":[[0,1.94,257.52],[1,1.92,2.19],[2,1.91,2.06]],"ltp":1.96,"tv":1781.97,"id":9631075},{"batl":[[0,2.1,2.06]],"ltp":2.06,"tv":926.6,"id":11772759}]}]}
{"op":"mcm","clk":"1009410858","pt":1580644096592,"mc":[{"id":"1.168222848","rc":[{"batb":[[0,1.95,8.25],[1,1.94,3.6],[2,1.93,2.08]],"ltp":1.96,"tv":1781.97,"id":9631075},{"batl":[[0,2.06,8.29],[1,2.1,4.11]],"ltp":2.06,"tv":926.6,"id":11772759}]}]}
{"op":"mcm","clk":"1009410882","pt":1580644096802,"mc":[{"id":"1.168222848","rc":[{"batl":[[2,2.12,2.21]],"ltp":2.06,"tv":926.6,"id":11772759}]}]}
{"op":"mcm","clk":"1009411371","pt":1580644100490,"mc":[{"id":"1.168222848","rc":[{"batb":[[0,1.94,257.52],[1,1.92,2.19],[2,1.91,2.06]],"ltp":1.96,"tv":1781.97,"id":9631075},{"batl":[[0,2.1,2.06],[1,2.12,2.21],[2,2.14,2.11]],"ltp":2.06,"tv":926.6,"id":11772759}]}]}
{"op":"mcm","clk":"1009411412","pt":1580644101000,"mc":[{"id":"1.168222848","rc":[{"batl":[[2,2.14,2.18]],"ltp":2.06,"tv":926.6,"id":11772759}]}]}
{"op":"mcm","clk":"1009415674","pt":1580644140672,"mc":[{"id":"1.168222848","rc":[{"trd":[[1.95,103.2]],"batb":[[0,1.95,1.13],[1,1.94,3.6],[2,1.93,2.08]],"ltp":1.95,"tv":1798.37,"id":9631075},{"batb":[[2,1.9,2.53]],"batl":[[0,2.06,9.27],[1,2.1,4.11],[2,2.12,2.21]],"ltp":2.06,"tv":926.6,"id":11772759}],"tv":2724.98}]}
{"op":"mcm","clk":"1009415739","pt":1580644141244,"mc":[{"id":"1.168222848","rc":[{"batb":[[2,1.92,2.19]],"ltp":1.95,"tv":1798.37,"id":9631075},{"batb":[[2,1.98,2.26]],"batl":[[2,2.12,2.05]],"ltp":2.06,"tv":926.6,"id":11772759}]}]}
{"op":"mcm","clk":"1009415894","pt":1580644142553,"mc":[{"id":"1.168222848","rc":[{"batb":[[0,1.94,257.52],[1,1.92,2.19],[2,1.91,2]],"ltp":1.95,"tv":1798.37,"id":9631075},{"batl":[[0,2.1,2.06],[1,2.12,10.11],[2,2.14,2.11]],"ltp":2.06,"tv":926.6,"id":11772759}]}]}
{"op":"mcm","clk":"1009416000","pt":1580644143568,"mc":[{"id":"1.168222848","rc":[{"batl":[[1,2.12,2.05]],"ltp":2.06,"tv":926.6,"id":11772759}]}]}
{"op":"mcm","clk":"1009417111","pt":1580644152676,"mc":[{"id":"1.168222848","rc":[{"batb":[[0,1.95,7.57],[1,1.94,257.52],[2,1.93,2.08]],"ltp":1.95,"tv":1798.37,"id":9631075},{"batb":[[2,1.9,2.53]],"batl":[[2,2.28,18.48]],"ltp":2.06,"tv":926.6,"id":11772759}]}]}
{"op":"mcm","clk":"1009417188","pt":1580644153361,"mc":[{"id":"1.168222848","rc":[{"batb":[[1,1.94,3.6]],"ltp":1.95,"tv":1798.37,"id":9631075},{"batb":[[2,1.98,2.26]],"batl":[[0,2.1,4.11],[1,2.12,2]],"ltp":2.06,"tv":926.6,"id":11772759}]}]}
{"op":"mcm","clk":"1009419249","pt":1580644172687,"mc":[{"id":"1.168222848","rc":[{"trd":[[1.95,130.57]],"batb":[[0,1.95,1.46]],"ltp":1.95,"tv":1825.74,"id":9631075},{"batl":[[1,2.12,2.21]],"ltp":2.06,"tv":926.6,"id":11772759}],"tv":2752.34}]}
{"op":"mcm","clk":"1009419362","pt":1580644173684,"mc":[{"id":"1.168222848","rc":[{"trd":[[1.95,132.03],[1.96,62.23]],"batb":[[0,1.94,3.6],[1,1.92,2.19],[2,1.91,2.06]],"batl":[[0,1.98,13.88],[1,1.99,422.16],[2,2,420.1]],"ltp":1.95,"tv":1853.97,"id":9631075},{"trd":[[2.06,23.25]],"batb":[[1,2,2],[2,1.99,28.42]],"batl":[[0,2.1,2.06],[2,2.14,2]],"ltp":2.06,"tv":927.99,"id":11772759}],"tv":2781.96}]}
{"op":"mcm","clk":"1009419399","pt":1580644174100,"mc":[{"id":"1.168222848","rc":[{"batl":[[0,1.98,11.72],[1,1.99,420.1],[2,2,422.1]],"ltp":1.95,"tv":1853.97,"id":9631075},{"batb":[[1,1.99,30.42],[2,1.98,2.26]],"ltp":2.06,"tv":927.99,"id":11772759}]}]}
{"op":"mcm","clk":"1009419565","pt":1580644175675,"mc":[{"id":"1.168222848","rc":[{"batb":[[0,1.95,7.57],[1,1.94,3.6],[2,1.93,2.08]],"batl":[[0,1.96,1.68],[1,1.98,11.49],[2,1.99,420.1]],"ltp":1.95,"tv":1853.97,"id":9631075},{"batl":[[0,2.1,4.11]],"ltp":2.06,"tv":927.99,"id":11772759}]}]}
{"op":"mcm","clk":"1009419691","pt":1580644176984,"mc":[{"id":"1.168222848","rc":[{"batb":[[0,1.95,15.14]],"ltp":1.95,"tv":1853.97,"id":9631075},{"batl":[[0,2.1,12.25]],"ltp":2.06,"tv":927.99,"id":11772759}]}]}
{"op":"mcm","clk":"1009419958","pt":1580644179600,"mc":[{"id":"1.168222848","rc":[{"batl":[[0,1.97,1.68]],"ltp":1.95,"tv":1853.97,"id":9631075},{"batb":[[2,1.9,2.53]],"batl":[[1,2.28,18.48],[2,2.52,15.14]],"ltp":2.06,"tv":927.99,"id":11772759}]}]}
{"op":"mcm","clk":"1009419980","pt":1580644179805,"mc":[{"id":"1.168222848","rc":[{"batb":[[2,1.98,2]],"batl":[[1,2.12,2.05],[2,2.28,18.48]],"ltp":2.06,"tv":927.99,"id":11772759}]}]}
{"op":"mcm","clk":"1009420109","pt":1580644181218,"mc":[{"id":"1.168222848","rc":[{"batl":[[0,1.96,1.68]],"ltp":1.95,"tv":1853.97,"id":9631075}]}]}
{"op":"mcm","clk":"1009420250","pt":1580644182427,"mc":[{"id":"1.168222848","rc":[{"batb":[[0,1.95,22.72]],"ltp":1.95,"tv":1853.97,"id":9631075}]}]}
{"op":"mcm","clk":"1009420351","pt":1580644183512,"mc":[{"id":"1.168222848","rc":[{"batb":[[0,1.95,15.14]],"ltp":1.95,"tv":1853.97,"id":9631075}]}]}
{"op":"mcm","clk":"1009420473","pt":1580644184886,"mc":[{"id":"1.168222848","rc":[{"batb":[[0,1.95,22.72]],"ltp":1.95,"tv":1853.97,"id":9631075}]}]}
{"op":"mcm","clk":"1009420854","pt":1580644188392,"mc":[{"id":"1.168222848","rc":[{"batb":[[0,1.95,30.29]],"batl":[[1,1.98,3.09]],"ltp":1.95,"tv":1853.97,"id":9631075},{"batb":[[2,1.98,2.26]],"batl":[[1,2.12,2.21]],"ltp":2.06,"tv":927.99,"id":11772759}]}]}
{"op":"mcm","clk":"1009420990","pt":1580644189711,"mc":[{"id":"1.168222848","rc":[{"batb":[[0,1.94,257.52],[1,1.92,2.19],[2,1.91,2.06]],"ltp":1.95,"tv":1853.97,"id":9631075},{"batl":[[2,2.14,2.25]],"ltp":2.06,"tv":927.99,"id":11772759}]}]}
{"op":"mcm","clk":"1009421057","pt":1580644190294,"mc":[{"id":"1.168222848","rc":[{"batl":[[0,2.1,2.06]],"ltp":2.06,"tv":927.99,"id":11772759}]}]}
{"op":"mcm","clk":"1009421788","pt":1580644197639,"mc":[{"id":"1.168222848","rc":[{"batl":[[0,1.98,3.09],[1,1.99,420.1],[2,2,422.1]],"ltp":1.95,"tv":1853.97,"id":9631075}]}]}
{"op":"mcm","clk":"1009421902","pt":1580644198744,"mc":[{"id":"1.168222848","rc":[{"trd":[[1.94,251.75]],"batb":[[0,1.94,167.52]],"ltp":1.94,"tv":2033.97,"id":9631075},{"batb":[[2,1.98,2]],"batl":[[2,2.14,2.18]],"ltp":2.06,"tv":927.99,"id":11772759}],"tv":2961.96}]}
{"op":"mcm","clk":"1009421999","pt":1580644199741,"mc":[{"id":"1.168222848","rc":[{"batb":[[0,1.9,71.48],[1,1.89,266.31],[2,1.88,54.38]],"ltp":1.94,"tv":2033.97,"id":9631075},{"batl":[[1,2.14,2.18],[2,2.16,2.04]],"ltp":2.06,"tv":927.99,"id":11772759}]}]}
{"op":"mcm","clk":"1009422120","pt":1580644200741,"mc":[{"id":"1.168222848","rc":[{"batb":[[0,1.9,73.54],[1,1.89,2.05]],"batl":[[0,1.96,1.67],[1,1.98,3.09],[2,1.99,420.1]],"ltp":1.94,"tv":2033.97,"id":9631075},{"batl":[[0,2.08,239.19],[1,2.1,2.06],[2,2.12,2]],"ltp":2.06,"tv":927.99,"id":11772759}]}]}
{"op":"mcm","clk":"1009422207","pt":1580644201532,"mc":[{"id":"1.168222848","rc":[{"batb":[[2,1.88,323.71]],"ltp":1.94,"tv":2033.97,"id":9631075}]}]}
{"op":"mcm","clk":"1009422311","pt":1580644202430,"mc":[{"id":"1.168222848","rc":[{"batb":[[0,1.93,10.33],[1,1.91,2.06],[2,1.9,73.54]],"batl":[[1,1.98,23.43]],"ltp":1.94,"tv":2033.97,"id":9631075}]}]}
{"op":"mcm","clk":"1009422558","pt":1580644204516,"mc":[{"id":"1.168222848","rc":[{"batl":[[0,2.1,2.06],[1,2.12,2],[2,2.14,2.18]],"ltp":2.06,"tv":927.99,"id":11772759}]}]}
{"op":"mcm","clk":"1009422691","pt":1580644205718,"mc":[{"id":"1.168222848","rc":[{"batb":[[0,1.9,73.54],[1,1.89,2.05],[2,1.88,321.58]],"ltp":1.94,"tv":2033.97,"id":9631075},{"batl":[[1,2.12,2.21],[2,2.14,2.25]],"ltp":2.06,"tv":927.99,"id":11772759}]}]}
{"op":"mcm","clk":"1009422773","pt":1580644206448,"mc":[{"id":"1.168222848","rc":[{"batb":[[0,1.92,259.19],[1,1.9,73.54],[2,1.89,2.05]],"ltp":1.94,"tv":2033.97,"id":9631075},{"batl":[[1,2.14,2.25],[2,2.16,2.04]],"ltp":2.06,"tv":927.99,"id":11772759}]}]}
{"op":"mcm","clk":"1009422973","pt":1580644208360,"mc":[{"id":"1.168222848","rc":[{"batb":[[0,1.94,15.14],[1,1.92,261.26],[2,1.91,2.06]],"ltp":1.94,"tv":2033.97,"id":9631075},{"batl":[[0,2.08,8.22],[1,2.1,2.06],[2,2.12,2]],"ltp":2.06,"tv":927.99,"id":11772759}]}]}
{"op":"mcm","clk":"1009423163","pt":1580644210237,"mc":[{"id":"1.168222848","rc":[{"batb":[[1,1.93,7.57],[2,1.92,261.26]],"ltp":1.94,"tv":2033.97,"id":9631075}]}]}
{"op":"mcm","clk":"1009423464","pt":1580644212722,"mc":[{"id":"1.168222848","rc":[{"batb":[[0,1.93,7.57],[1,1.92,261.26],[2,1.91,2.06]],"ltp":1.94,"tv":2033.97,"id":9631075}]}]}
{"op":"mcm","clk":"1009423554","pt":1580644213658,"mc":[{"id":"1.168222848","rc":[{"batb":[[1,1.91,2.06],[2,1.9,73.54]],"ltp":1.94,"tv":2033.97,"id":9631075},{"batl":[[0,2.1,2.06],[1,2.12,2],[2,2.14,2]],"ltp":2.06,"tv":927.99,"id":11772759}]}]}
{"op":"mcm","clk":"1009423621","pt":1580644214142,"mc":[{"id":"1.168222848","rc":[{"batl":[[1,2.12,2.05]],"ltp":2.06,"tv":927.99,"id":11772759}]}]}
{"op":"mcm","clk":"1009423736","pt":1580644215152,"mc":[{"id":"1.168222848","rc":[{"batb":[[0,1.93,22.72]],"ltp":1.94,"tv":2033.97,"id":9631075}]}]}
{"op":"mcm","clk":"1009423979","pt":1580644217729,"mc":[{"id":"1.168222848","rc":[{"batb":[[0,1.94,7.57],[1,1.93,22.72],[2,1.91,2.06]],"ltp":1.94,"tv":2033.97,"id":9631075}]}]}
{"op":"mcm","clk":"1009424059","pt":1580644218452,"mc":[{"id":"1.168222848","rc":[{"batb":[[2,1.92,2]],"ltp":1.94,"tv":2033.97,"id":9631075}]}]}
{"op":"mcm","clk":"1009424156","pt":1580644219453,"mc":[{"id":"1.168222848","rc":[{"batl":[[1,1.98,36.03]],"ltp":1.94,"tv":2033.97,"id":9631075}]}]}
{"op":"mcm","clk":"1009424219","pt":1580644219935,"mc":[{"id":"1.168222848","rc":[{"batl":[[2,2.14,2.25]],"ltp":2.06,"tv":927.99,"id":11772759}]}]}
{"op":"mcm","clk":"1009426608","pt":1580644243510,"mc":[{"id":"1.168222848","rc":[{"batb":[[0,1.94,15.14]],"ltp":1.94,"tv":2033.97,"id":9631075}]}]}
{"op":"mcm","clk":"1009426786","pt":1580644244718,"mc":[{"id":"1.168222848","rc":[{"trd":[[1.94,279.15],[1.95,159.06]],"batb":[[0,1.94,1.44],[2,1.91,2.06]],"batl":[[0,1.96,1.79],[1,1.97,2.16],[2,1.98,38.05]],"ltp":1.95,"tv":2088.4,"id":9631075},{"batb":[[2,1.98,2.26]],"ltp":2.06,"tv":927.99,"id":11772759}],"tv":3016.39}]}
{"op":"mcm","clk":"1009426858","pt":1580644245294,"mc":[{"id":"1.168222848","rc":[{"batl":[[1,1.98,36.03],[2,1.99,420.1]],"ltp":1.95,"tv":2088.4,"id":9631075}]}]}
{"op":"mcm","clk":"1009427269","pt":1580644248694,"mc":[{"id":"1.168222848","rc":[{"batb":[[0,1.9,71.48],[1,1.89,2.05],[2,1.88,323.79]],"batl":[[0,1.98,36.03],[1,1.99,420.1],[2,2,422.1]],"ltp":1.95,"tv":2088.4,"id":9631075},{"batl":[[1,2.14,2.25],[2,2.16,2.22]],"ltp":2.06,"tv":927.99,"id":11772759}]}]}
{"op":"mcm","clk":"1009427365","pt":1580644249586,"mc":[{"id":"1.168222848","rc":[{"batb":[[0,1.9,73.48]],"ltp":1.95,"tv":2088.4,"id":9631075},{"batb":[[2,1.9,2.53]],"batl":[[0,2.08,239.19],[1,2.1,2.06],[2,2.12,2.05]],"ltp":2.06,"tv":927.99,"id":11772759}]}]}
{"op":"mcm","clk":"1009427466","pt":1580644250524,"mc":[{"id":"1.168222848","rc":[{"batb":[[0,1.92,2.19],[1,1.91,2.06],[2,1.9,73.48]],"ltp":1.95,"tv":2088.4,"id":9631075},{"batb":[[2,1.98,2]],"batl":[[0,2.06,8.29],[1,2.08,239.19],[2,2.1,4.11]],"ltp":2.06,"tv":927.99,"id":11772759}]}]}
{"op":"mcm","clk":"1009427574","pt":1580644251315,"mc":[{"id":"1.168222848","rc":[{"batl":[[0,1.96,1.79],[1,1.98,36.03],[2,1.99,420.1]],"ltp":1.95,"tv":2088.4,"id":9631075},{"batl":[[1,2.1,4.11],[2,2.12,2.05]],"ltp":2.06,"tv":927.99,"id":11772759}]}]}
{"op":"mcm","clk":"1009427726","pt":1580644252578,"mc":[{"id":"1.168222848","rc":[{"batl":[[0,2.1,2.06],[1,2.14,2.04],[2,2.16,2.22]],"ltp":2.06,"tv":927.99,"id":11772759}]}]}
{"op":"mcm","clk":"1009427764","pt":1580644252890,"mc":[{"id":"1.168222848","rc":[{"batb":[[0,1.92,259.19],[1,1.9,73.48],[2,1.89,2.05]],"ltp":1.95,"tv":2088.4,"id":9631075}]}]}
{"op":"mcm","clk":"1009428487","pt":1580644258683,"mc":[{"id":"1.168222848","rc":[{"batb":[[0,1.94,15.14],[1,1.92,2],[2,1.91,2.06]],"ltp":1.95,"tv":2088.4,"id":9631075},{"batb":[[2,1.9,2.53]],"batl":[[1,2.12,2.21],[2,2.14,2.04]],"ltp":2.06,"tv":927.99,"id":11772759}]}]}
{"op":"mcm","clk":"1009428528","pt":1580644259104,"mc":[{"id":"1.168222848","rc":[{"batb":[[2,1.98,2]],"batl":[[2,2.14,2.25]],"ltp":2.06,"tv":927.99,"id":11772759}]}]}
{"op":"mcm","clk":"1009431018","pt":1580644280737,"mc":[{"id":"1.168222848","rc":[{"batb":[[0,1.94,22.72]],"ltp":1.95,"tv":2088.4,"id":9631075},{"batb":[[2,1.98,2.26]],"batl":[[2,2.14,2.18]],"ltp":2.06,"tv":927.99,"id":11772759}]}]}
{"op":"mcm","clk":"1009431138","pt":1580644281734,"mc":[{"id":"1.168222848","rc":[{"trd":[[1.94,319.36]],"batb":[[0,1.94,10.18]],"batl":[[1,1.98,23.43]],"ltp":1.94,"tv":2128.61,"id":9631075}],"tv":3056.6}]}
{"op":"mcm","clk":"1009431250","pt":1580644282733,"mc":[{"id":"1.168222848","rc":[{"batl":[[0,1.96,14.4],[1,1.98,25.62],[2,1.99,422.33]],"ltp":1.94,"tv":2128.61,"id":9631075},{"batb":[[0,2,2]],"ltp":2.06,"tv":927.99,"id":11772759}]}]}
{"op":"mcm","clk":"1009431275","pt":1580644282943,"mc":[{"id":"1.168222848","rc":[{"batb":[[0,2.04,12.12],[1,2,2],[2,1.99,30.42]],"ltp":2.06,"tv":927.99,"id":11772759}]}]}
{"op":"mcm","clk":"1009431465","pt":1580644284626,"mc":[{"id":"1.168222848","rc":[{"batl":[[0,1.96,21.97]],"ltp":1.94,"tv":2128.61,"id":9631075}]}]}
{"op":"mcm","clk":"1009431682","pt":1580644286734,"mc":[{"id":"1.168222848","rc":[{"trd":[[1.95,174.08]],"batb":[[2,1.9,71.48]],"batl":[[0,1.96,22.03],[1,1.97,2.16],[2,1.98,25.62]],"ltp":1.95,"tv":2143.63,"id":9631075},{"batl":[[2,2.28,18.48]],"ltp":2.06,"tv":927.99,"id":11772759}],"tv":3071.62}]}
{"op":"mcm","clk":"1009431707","pt":1580644286939,"mc":[{"id":"1.168222848","rc":[{"batb":[[2,1.91,2.06]],"batl":[[1,1.98,25.62],[2,1.99,422.33]],"ltp":1.95,"tv":2143.63,"id":9631075},{"batl":[[2,2.14,2.25]],"ltp":2.06,"tv":927.99,"id":11772759}]}]}
{"op":"mcm","clk":"1009432014","pt":1580644289731,"mc":[{"id":"1.168222848","rc":[{"trd":[[1.95,189.1]],"batl":[[0,1.96,22.09],[1,1.97,2],[2,1.98,23.43]],"ltp":1.95,"tv":2158.65,"id":9631075}],"tv":3086.64}]}
{"op":"mcm","clk":"1009432045","pt":1580644290043,"mc":[{"id":"1.168222848","rc":[{"batl":[[1,1.98,25.68],[2,1.99,422.21]],"ltp":1.95,"tv":2158.65,"id":9631075}]}]}
{"op":"mcm","clk":"1009432199","pt":1580644291530,"mc":[{"id":"1.168222848","rc":[{"batl":[[0,1.96,12.72]],"ltp":1.95,"tv":2158.65,"id":9631075}]}]}
{"op":"mcm","clk":"1009432260","pt":1580644291938,"mc":[{"id":"1.168222848","rc":[{"batl":[[1,2.12,10.27]],"ltp":2.06,"tv":927.99,"id":11772759}]}]}
{"op":"mcm","clk":"1009432596","pt":1580644294656,"mc":[{"id":"1.168222848","rc":[{"trd":[[1.95,189.34],[1.96,87.44]],"batb":[[2,1.91,2]],"batl":[[0,1.98,23.43],[1,1.99,422.21],[2,2,422.1]],"ltp":1.96,"tv":2184.1,"id":9631075},{"batb":[[2,1.99,2]],"ltp":2.06,"tv":927.99,"id":11772759}],"tv":3112.09}]}
{"op":"mcm","clk":"1009432626","pt":1580644294823,"mc":[{"id":"1.168222848","rc":[{"batb":[[1,2.02,15.59],[2,2,2]],"ltp":2.06,"tv":927.99,"id":11772759}]}]}
{"op":"mcm","clk":"1009432812","pt":1580644296558,"mc":[{"id":"1.168222848","rc":[{"batl":[[0,1.96,7.57],[1,1.98,23.43],[2,1.99,422.21]],"ltp":1.96,"tv":2184.1,"id":9631075}]}]}
{"op":"mcm","clk":"1009432904","pt":1580644297187,"mc":[{"id":"1.168222848","rc":[{"batl":[[1,1.98,25.54],[2,1.99,422.36]],"ltp":1.96,"tv":2184.1,"id":9631075}]}]}
{"op":"mcm","clk":"1009433175","pt":1580644299652,"mc":[{"id":"1.168222848","rc":[{"batb":[[0,1.94,17.76]],"ltp":1.96,"tv":2184.1,"id":9631075}]}]}
{"op":"mcm","clk":"1009434645","pt":1580644312573,"mc":[{"id":"1.168222848","rc":[{"batb":[[0,1.92,259.19],[1,1.9,60.66],[2,1.89,2.05]],"batl":[[0,1.98,23.43],[1,1.99,422.36],[2,2,422.1]],"ltp":1.96,"tv":2184.1,"id":9631075},{"batl":[[1,2.12,8.06],[2,2.14,2.18]],"ltp":2.06,"tv":927.99,"id":11772759}]}]}
{"op":"mcm","clk":"1009434792","pt":1580644313678,"mc":[{"id":"1.168222848","rc":[{"batb":[[0,1.93,7.57],[1,1.92,259.19],[2,1.91,2.06]],"batl":[[0,1.95,6.66],[1,1.97,2.16],[2,1.98,25.59]],"ltp":1.96,"tv":2184.1,"id":9631075},{"batl":[[1,2.12,2.21]],"ltp":2.06,"tv":927.99,"id":11772759}]}]}
{"op":"mcm","clk":"1009434890","pt":1580644314360,"mc":[{"id":"1.168222848","rc":[{"batl":[[0,2.08,8.4],[1,2.1,2.06],[2,2.12,2.21]],"ltp":2.06,"tv":927.99,"id":11772759}]}]}
{"op":"mcm","clk":"1009435470","pt":1580644319701,"mc":[{"id":"1.168222848","rc":[{"batb":[[0,1.92,259.19],[1,1.91,2.06],[2,1.9,60.66]],"ltp":1.96,"tv":2184.1,"id":9631075}]}]}
{"op":"mcm","clk":"1009435557","pt":1580644320592,"mc":[{"id":"1.168222848","rc":[{"trd":[[1.95,202.36]],"batb":[[0,1.9,60.66],[1,1.89,2.05],[2,1.88,321.58]],"batl":[[0,1.98,23.58],[1,1.99,420.1],[2,2,422.1]],"ltp":1.95,"tv":2197.12,"id":9631075}],"tv":3125.11}]}
{"op":"mcm","clk":"1009435610","pt":1580644321074,"mc":[{"id":"1.168222848","rc":[{"batb":[[1,1.89,11.49]],"batl":[[1,1.99,422.1]],"ltp":1.95,"tv":2197.12,"id":9631075}]}]}
{"op":"mcm","clk":"1009435737","pt":1580644322484,"mc":[{"id":"1.168222848","rc":[{"batb":[[0,1.94,7.57],[1,1.92,2],[2,1.91,2]],"ltp":1.95,"tv":2197.12,"id":9631075}]}]}
{"op":"mcm","clk":"1009441751","pt":1580644376650,"mc":[{"id":"1.168222848","rc":[{"batb":[[0,1.94,16.51]],"ltp":1.95,"tv":2197.12,"id":9631075}]}]}
{"op":"mcm","clk":"1009441842","pt":1580644377544,"mc":[{"id":"1.168222848","rc":[{"trd":[[1.94,348.64]],"batb":[[0,1.94,1.87],[1,1.9,60.66],[2,1.89,11.44]],"batl":[[0,1.97,8.55],[1,1.98,23.43],[2,1.99,422.1]],"ltp":1.94,"tv":2226.4,"id":9631075}],"tv":3154.39}]}
{"op":"mcm","clk":"1009442215","pt":1580644381057,"mc":[{"id":"1.168222848","rc":[{"batl":[[0,2.08,247.59]],"ltp":2.06,"tv":927.99,"id":11772759}]}]}
{"op":"mcm","clk":"1009442324","pt":1580644382259,"mc":[{"id":"1.168222848","rc":[{"batb":[[2,1.89,2]],"ltp":1.94,"tv":2226.4,"id":9631075}]}]}
{"op":"mcm","clk":"1009444348","pt":1580644400696,"mc":[{"id":"1.168222848","rc":[{"batb":[[1,1.92,2.19],[2,1.91,2.06]],"ltp":1.94,"tv":2226.4,"id":9631075},{"batl":[[0,2.06,8.29],[1,2.08,8.4],[2,2.1,4.11]],"ltp":2.06,"tv":927.99,"id":11772759}]}]}
{"op":"mcm","clk":"1009444456","pt":1580644401703,"mc":[{"id":"1.168222848","rc":[{"batl":[[0,2.08,8.4],[1,2.1,4.11],[2,2.12,2.21]],"ltp":2.06,"tv":927.99,"id":11772759}]}]}
{"op":"mcm","clk":"1009444588","pt":1580644402716,"mc":[{"id":"1.168222848","rc":[{"batb":[[1,1.9,60.66],[2,1.89,2.05]],"ltp":1.94,"tv":2226.4,"id":9631075},{"batl":[[0,2.08,247.59],[1,2.1,2.06]],"ltp":2.06,"tv":927.99,"id":11772759}]}]}
{"op":"mcm","clk":"1009447084","pt":1580644426702,"mc":[{"id":"1.168222848","rc":[{"batb":[[1,1.93,29.47],[2,1.91,2.06]],"ltp":1.94,"tv":2226.4,"id":9631075},{"batl":[[0,2.08,8.4]],"ltp":2.06,"tv":927.99,"id":11772759}]}]}
{"op":"mcm","clk":"1009448639","pt":1580644442718,"mc":[{"id":"1.168222848","rc":[{"batl":[[2,2.12,10.27]],"ltp":2.06,"tv":927.99,"id":11772759}]}]}
{"op":"mcm","clk":"1009453428","pt":1580644490605,"mc":[{"id":"1.168222848","rc":[{"batl":[[0,1.97,8.4]],"ltp":1.94,"tv":2226.4,"id":9631075}]}]}
{"op":"mcm","clk":"1009453526","pt":1580644491675,"mc":[{"id":"1.168222848","rc":[{"batl":[[0,1.95,7.68],[1,1.97,10.56],[2,1.98,25.68]],"ltp":1.94,"tv":2226.4,"id":9631075}]}]}
{"op":"mcm","clk":"1009454713","pt":1580644502702,"mc":[{"id":"1.168222848","rc":[{"batl":[[1,1.97,2.16],[2,1.98,23.43]],"ltp":1.94,"tv":2226.4,"id":9631075}]}]}
{"op":"mcm","clk":"1009454740","pt":1580644503018,"mc":[{"id":"1.168222848","rc":[{"batl":[[2,1.98,25.61]],"ltp":1.94,"tv":2226.4,"id":9631075}]}]}
{"op":"mcm","clk":"1009458170","pt":1580644533673,"mc":[{"id":"1.168222848","rc":[{"batb":[[0,1.93,29.47],[1,1.91,2.06],[2,1.9,2.06]],"ltp":1.94,"tv":2226.4,"id":9631075}]}]}
{"op":"mcm","clk":"1009458270","pt":1580644534660,"mc":[{"id":"1.168222848","rc":[{"trd":[[1.95,217.38]],"batl":[[0,1.98,23.6],[1,1.99,422.1],[2,2,422.1]],"ltp":1.95,"tv":2241.42,"id":9631075}],"tv":3169.41}]}
{"op":"mcm","clk":"1009458781","pt":1580644539751,"mc":[{"id":"1.168222848","rc":[{"batb":[[0,1.94,7.57],[1,1.93,29.47],[2,1.92,2]],"ltp":1.95,"tv":2241.42,"id":9631075}]}]}
{"op":"mcm","clk":"1009458926","pt":1580644541281,"mc":[{"id":"1.168222848","rc":[{"batb":[[0,1.94,15.14]],"ltp":1.95,"tv":2241.42,"id":9631075}]}]}
{"op":"mcm","clk":"1009459454","pt":1580644546660,"mc":[{"id":"1.168222848","rc":[{"batb":[[0,1.93,29.47],[1,1.92,2],[2,1.91,2.06]],"ltp":1.95,"tv":2241.42,"id":9631075}]}]}
{"op":"mcm","clk":"1009459530","pt":1580644547405,"mc":[{"id":"1.168222848","rc":[{"batb":[[0,1.94,15.14],[1,1.93,29.47],[2,1.92,2.19]],"ltp":1.95,"tv":2241.42,"id":9631075}]}]}
{"op":"mcm","clk":"1009460656","pt":1580644557702,"mc":[{"id":"1.168222848","rc":[{"batb":[[1,1.92,2.19],[2,1.91,2.06]],"ltp":1.95,"tv":2241.42,"id":9631075}]}]}
{"op":"mcm","clk":"1009461092","pt":1580644561497,"mc":[{"id":"1.168222848","rc":[{"batb":[[1,1.93,15.14],[2,1.92,2.19]],"ltp":1.95,"tv":2241.42,"id":9631075}]}]}
{"op":"mcm","clk":"1009461194","pt":1580644562515,"mc":[{"id":"1.168222848","rc":[{"trd":[[1.94,376.15]],"batb":[[0,1.94,1.39],[2,1.91,2.06]],"ltp":1.94,"tv":2268.94,"id":9631075}],"tv":3196.93}]}
{"op":"mcm","clk":"1009461291","pt":1580644563307,"mc":[{"id":"1.168222848","rc":[{"batl":[[0,1.95,13.86],[1,1.97,2.15],[2,1.98,25.43]],"ltp":1.94,"tv":2268.94,"id":9631075}]}]}
{"op":"mcm","clk":"1009461555","pt":1580644565632,"mc":[{"id":"1.168222848","rc":[{"batb":[[0,1.93,15.14],[1,1.91,2.06],[2,1.9,60.66]],"ltp":1.94,"tv":2268.94,"id":9631075}]}]}
{"op":"mcm","clk":"1009463182","pt":1580644578728,"mc":[{"id":"1.168222848","rc":[{"trd":[[1.95,244.81]],"batb":[[2,1.9,58.6]],"batl":[[0,1.98,23.57],[1,1.99,422.27],[2,2,422.1]],"ltp":1.95,"tv":2296.36,"id":9631075}],"tv":3224.35}]}
{"op":"mcm","clk":"1009463240","pt":1580644579142,"mc":[{"id":"1.168222848","rc":[{"batb":[[2,1.9,60.66]],"batl":[[1,1.99,422.39]],"ltp":1.95,"tv":2296.36,"id":9631075}]}]}
{"op":"mcm","clk":"1009465581","pt":1580644599758,"mc":[{"id":"1.168222848","rc":[{"trd":[[1.95,244.95]],"batl":[[0,1.98,23.43]],"ltp":1.95,"tv":2296.5,"id":9631075},{"trd":[[2.04,196.32]],"batb":[[0,2.02,15.59],[1,2,2],[2,1.99,2]],"batl":[[0,2.04,2.89],[1,2.08,8.4],[2,2.1,2.06]],"ltp":2.04,"tv":952.35,"id":11772759}],"tv":3248.86}]}
{"op":"mcm","clk":"1009465647","pt":1580644600390,"mc":[{"id":"1.168222848","rc":[{"batl":[[1,1.99,420.1]],"ltp":1.95,"tv":2296.5,"id":9631075},{"trd":[[2.04,201.82]],"batb":[[1,1.99,2],[2,1.98,2]],"batl":[[0,2.08,8.55],[1,2.1,2.06],[2,2.12,10.27]],"ltp":2.04,"tv":957.85,"id":11772759}],"tv":3254.36}]}
{"op":"mcm","clk":"1009468592","pt":1580644627603,"mc":[{"id":"1.168222848","rc":[{"batb":[[0,1.93,24.18],[2,1.9,60.6]],"ltp":1.95,"tv":2296.5,"id":9631075}]}]}
{"op":"mcm","clk":"1009475882","pt":1580644693510,"mc":[{"id":"1.168222848","rc":[{"batb":[[0,1.94,20.11],[1,1.93,24.18],[2,1.92,2.07]],"ltp":1.95,"tv":2296.5,"id":9631075},{"batb":[[2,1.98,2.26]],"ltp":2.04,"tv":957.85,"id":11772759}]}]}
{"op":"mcm","clk":"1009476318","pt":1580644697607,"mc":[{"id":"1.168222848","rc":[{"batb":[[1,1.93,9.03]],"ltp":1.95,"tv":2296.5,"id":9631075}]}]}
{"op":"mcm","clk":"1009476422","pt":1580644698700,"mc":[{"id":"1.168222848","rc":[{"batb":[[0,1.94,27.69]],"ltp":1.95,"tv":2296.5,"id":9631075}]}]}
{"op":"mcm","clk":"1009478800","pt":1580644720721,"mc":[{"id":"1.168222848","rc":[{"batb":[[1,1.92,2.07],[2,1.91,2]],"ltp":1.95,"tv":2296.5,"id":9631075}]}]}
{"op":"mcm","clk":"1009478888","pt":1580644721548,"mc":[{"id":"1.168222848","rc":[{"trd":[[1.94,425.5],[1.96,87.59]],"batb":[[0,1.94,11.95]],"ltp":1.94,"tv":2346.0,"id":9631075},{"trd":[[2.04,201.96]],"batl":[[0,2.08,8.4]],"ltp":2.04,"tv":957.99,"id":11772759}],"tv":3304.0}]}
{"op":"mcm","clk":"1009479005","pt":1580644722642,"mc":[{"id":"1.168222848","rc":[{"batl":[[0,1.95,4.54],[1,1.97,2.16],[2,1.98,25.68]],"ltp":1.94,"tv":2346.0,"id":9631075},{"batb":[[1,2,2]],"ltp":2.04,"tv":957.99,"id":11772759}]}]}
{"op":"mcm","clk":"1009479110","pt":1580644723527,"mc":[{"id":"1.168222848","rc":[{"trd":[[1.95,253.57]],"batl":[[0,1.98,23.66],[1,1.99,422.27],[2,2,422.1]],"ltp":1.95,"tv":2354.62,"id":9631075},{"batb":[[1,1.99,2]],"ltp":2.04,"tv":957.99,"id":11772759}],"tv":3312.61}]}
{"op":"mcm","clk":"1009479203","pt":1580644724629,"mc":[{"id":"1.168222848","rc":[{"batb":[[0,1.94,38.56]],"batl":[[1,1.99,420.1]],"ltp":1.95,"tv":2354.62,"id":9631075}]}]}
{"op":"mcm","clk":"1009479223","pt":1580644724839,"mc":[{"id":"1.168222848","rc":[{"batb":[[0,1.94,46.13]],"ltp":1.95,"tv":2354.62,"id":9631075}]}]}
{"op":"mcm","clk":"1009483294","pt":1580644761687,"mc":[{"id":"1.168222848","rc":[{"trd":[[1.94,523.03]],"batb":[[0,1.94,4.93],[2,1.88,321.58]],"ltp":1.94,"tv":2452.15,"id":9631075},{"batb":[[2,1.9,2.53]],"ltp":2.04,"tv":957.99,"id":11772759}],"tv":3410.15}]}
{"op":"mcm","clk":"1009483427","pt":1580644762689,"mc":[{"id":"1.168222848","rc":[{"trd":[[1.95,283.79]],"batb":[[2,1.91,2.06]],"batl":[[0,1.97,2.34],[1,1.98,25.55],[2,1.99,420.1]],"ltp":1.95,"tv":2482.37,"id":9631075},{"batb":[[0,2.02,33.18],[1,2,2],[2,1.98,2]],"ltp":2.04,"tv":957.99,"id":11772759}],"tv":3440.37}]}
{"op":"mcm","clk":"1009483575","pt":1580644763759,"mc":[{"id":"1.168222848","rc":[{"batl":[[0,1.98,23.61],[1,1.99,420.1],[2,2,422.1]],"ltp":1.95,"tv":2482.37,"id":9631075},{"batb":[[1,1.99,2]],"ltp":2.04,"tv":957.99,"id":11772759}]}]}
{"op":"mcm","clk":"1009483688","pt":1580644764756,"mc":[{"id":"1.168222848","rc":[{"trd":[[1.95,290.01]],"batb":[[0,1.94,12.5]],"batl":[[0,1.97,2.23],[1,1.98,25.68],[2,1.99,422.48]],"ltp":1.95,"tv":2488.59,"id":9631075},{"batb":[[1,2,2],[2,1.99,2]],"batl":[[1,2.1,10.6]],"ltp":2.04,"tv":957.99,"id":11772759}],"tv":3446.59}]}
{"op":"mcm","clk":"1009483802","pt":1580644765685,"mc":[{"id":"1.168222848","rc":[{"batl":[[0,1.98,23.5],[1,1.99,420.1],[2,2,422.1]],"ltp":1.95,"tv":2488.59,"id":9631075},{"batb":[[1,1.99,2],[2,1.98,2]],"ltp":2.04,"tv":957.99,"id":11772759}]}]}
{"op":"mcm","clk":"1009483903","pt":1580644766682,"mc":[{"id":"1.168222848","rc":[{"batb":[[0,1.94,20.07]],"batl":[[0,1.95,2.7],[1,1.97,2.11],[2,1.98,25.43]],"ltp":1.95,"tv":2488.59,"id":9631075},{"batb":[[1,2,2],[2,1.99,2]],"ltp":2.04,"tv":957.99,"id":11772759}]}]}
{"op":"mcm","clk":"1009483994","pt":1580644767574,"mc":[{"id":"1.168222848","rc":[{"trd":[[1.95,295.03]],"batl":[[0,1.97,2.3],[1,1.98,25.43],[2,1.99,420.1]],"ltp":1.95,"tv":2493.61,"id":9631075}],"tv":3451.61}]}
{"op":"mcm","clk":"1009484087","pt":1580644768298,"mc":[{"id":"1.168222848","rc":[{"batb":[[0,1.93,20.07],[1,1.91,2.06],[2,1.9,117.07]],"batl":[[0,1.98,23.62],[1,1.99,420.1],[2,2,422.1]],"ltp":1.95,"tv":2493.61,"id":9631075},{"batb":[[1,1.99,2],[2,1.98,2.26]],"ltp":2.04,"tv":957.99,"id":11772759}]}]}
{"op":"mcm","clk":"1009484342","pt":1580644770569,"mc":[{"id":"1.168222848","rc":[{"batb":[[0,1.94,15.14],[1,1.93,20.07],[2,1.92,2.07]],"ltp":1.95,"tv":2493.61,"id":9631075}]}]}
{"op":"mcm","clk":"1009484842","pt":1580644774298,"mc":[{"id":"1.168222848","rc":[{"batb":[[0,1.93,20.07],[1,1.91,2.06],[2,1.9,117.07]],"ltp":1.95,"tv":2493.61,"id":9631075}]}]}
{"op":"mcm","clk":"1009485116","pt":1580644776599,"mc":[{"id":"1.168222848","rc":[{"batb":[[0,1.94,15.14],[1,1.93,20.07],[2,1.92,2.19]],"ltp":1.95,"tv":2493.61,"id":9631075},{"batb":[[2,1.9,2.53]],"ltp":2.04,"tv":957.99,"id":11772759}]}]}
{"op":"mcm","clk":"1009485166","pt":1580644777007,"mc":[{"id":"1.168222848","rc":[{"batb":[[2,1.98,2.26]],"ltp":2.04,"tv":957.99,"id":11772759}]}]}
{"op":"mcm","clk":"1009485319","pt":1580644778265,"mc":[{"id":"1.168222848","rc":[{"batb":[[0,1.94,22.72]],"ltp":1.95,"tv":2493.61,"id":9631075}]}]}
{"op":"mcm","clk":"1009485581","pt":1580644780607,"mc":[{"id":"1.168222848","rc":[{"batb":[[1,1.92,2.19],[2,1.91,2.06]],"ltp":1.95,"tv":2493.61,"id":9631075}]}]}
{"op":"mcm","clk":"1009485944","pt":1580644783600,"mc":[{"id":"1.168222848","rc":[{"batb":[[0,1.94,39.23]],"ltp":1.95,"tv":2493.61,"id":9631075},{"batb":[[2,1.98,2]],"ltp":2.04,"tv":957.99,"id":11772759}]}]}
{"op":"mcm","clk":"1009486020","pt":1580644784228,"mc":[{"id":"1.168222848","rc":[{"batl":[[0,1.98,32.02]],"ltp":1.95,"tv":2493.61,"id":9631075},{"batb":[[0,2.02,41.41]],"ltp":2.04,"tv":957.99,"id":11772759}]}]}
{"op":"mcm","clk":"1009486144","pt":1580644785290,"mc":[{"id":"1.168222848","rc":[{"batb":[[0,1.94,8.94]],"ltp":1.95,"tv":2493.61,"id":9631075}]}]}
{"op":"mcm","clk":"1009486303","pt":1580644786706,"mc":[{"id":"1.168222848","rc":[{"batb":[[0,1.94,24.08]],"ltp":1.95,"tv":2493.61,"id":9631075}]}]}
{"op":"mcm","clk":"1009486413","pt":1580644787601,"mc":[{"id":"1.168222848","rc":[{"trd":[[1.94,552.47]],"batb":[[0,1.94,9.37]],"ltp":1.94,"tv":2523.05,"id":9631075}],"tv":3481.05}]}
{"op":"mcm","clk":"1009486538","pt":1580644788609,"mc":[{"id":"1.168222848","rc":[{"batb":[[1,1.93,15.14],[2,1.92,2.19]],"batl":[[0,1.95,5.94],[1,1.97,2],[2,1.98,34.08]],"ltp":1.94,"tv":2523.05,"id":9631075},{"batb":[[1,2,2]],"ltp":2.04,"tv":957.99,"id":11772759}]}]}
{"op":"mcm","clk":"1009486680","pt":1580644789704,"mc":[{"id":"1.168222848","rc":[{"trd":[[1.95,306.45]],"batl":[[0,1.98,32.06],[1,1.99,420.1],[2,2,422.1]],"ltp":1.95,"tv":2534.47,"id":9631075},{"batb":[[1,1.99,2],[2,1.9,2.53]],"ltp":2.04,"tv":957.99,"id":11772759}],"tv":3492.47}]}
{"op":"mcm","clk":"1009486786","pt":1580644790607,"mc":[{"id":"1.168222848","rc":[{"batb":[[0,1.94,16.94]],"ltp":1.95,"tv":2534.47,"id":9631075},{"batb":[[2,1.98,2]],"ltp":2.04,"tv":957.99,"id":11772759}]}]}
{"op":"mcm","clk":"1009486830","pt":1580644791026,"mc":[{"id":"1.168222848","rc":[{"batb":[[0,1.94,24.51]],"ltp":1.95,"tv":2534.47,"id":9631075}]}]}
{"op":"mcm","clk":"1009486960","pt":1580644792228,"mc":[{"id":"1.168222848","rc":[{"batb":[[0,1.94,32.08]],"ltp":1.95,"tv":2534.47,"id":9631075}]}]}
{"op":"mcm","clk":"1009487366","pt":1580644795739,"mc":[{"id":"1.168222848","rc":[{"batb":[[0,1.94,47.23]],"ltp":1.95,"tv":2534.47,"id":9631075},{"batb":[[2,1.9,2.53]],"ltp":2.04,"tv":957.99,"id":11772759}]}]}
{"op":"mcm","clk":"1009487389","pt":1580644795909,"mc":[{"id":"1.168222848","rc":[{"batb":[[2,1.98,2.26]],"ltp":2.04,"tv":957.99,"id":11772759}]}]}
{"op":"mcm","clk":"1009487601","pt":1580644797636,"mc":[{"id":"1.168222848","rc":[{"batb":[[0,1.93,15.14],[1,1.92,2.19],[2,1.91,2.06]],"ltp":1.95,"tv":2534.47,"id":9631075}]}]}
{"op":"mcm","clk":"1009487729","pt":1580644798635,"mc":[{"id":"1.168222848","rc":[{"batb":[[0,1.94,7.57],[1,1.93,15.14]],"ltp":1.95,"tv":2534.47,"id":9631075}]}]}
{"op":"mcm","clk":"1009487764","pt":1580644798904,"mc":[{"id":"1.168222848","rc":[{"batb":[[2,1.92,2.19]],"ltp":1.95,"tv":2534.47,"id":9631075}]}]}
{"op":"mcm","clk":"1009487904","pt":1580644800118,"mc":[{"id":"1.168222848","rc":[{"batb":[[0,1.94,22.72]],"ltp":1.95,"tv":2534.47,"id":9631075}]}]}
{"op":"mcm","clk":"1009488175","pt":1580644801638,"mc":[{"id":"1.168222848","rc":[{"batl":[[0,1.98,11.72]],"ltp":1.95,"tv":2534.47,"id":9631075},{"batl":[[2,2.12,2.21]],"ltp":2.04,"tv":957.99,"id":11772759}]}]}
{"op":"mcm","clk":"1009488256","pt":1580644802238,"mc":[{"id":"1.168222848","rc":[{"batb":[[2,1.98,2]],"ltp":2.04,"tv":957.99,"id":11772759}]}]}
{"op":"mcm","clk":"1009488733","pt":1580644804654,"mc":[{"id":"1.168222848","rc":[{"batb":[[1,1.92,2.19],[2,1.91,2.06]],"ltp":1.95,"tv":2534.47,"id":9631075}]}]}
{"op":"mcm","clk":"1009489003","pt":1580644806552,"mc":[{"id":"1.168222848","rc":[{"batb":[[0,1.94,37.86]],"ltp":1.95,"tv":2534.47,"id":9631075}]}]}
{"op":"mcm","clk":"1009489623","pt":1580644810438,"mc":[{"id":"1.168222848","rc":[{"batb":[[0,1.94,53.01]],"ltp":1.95,"tv":2534.47,"id":9631075},{"batb":[[2,1.98,2.26]],"ltp":2.04,"tv":957.99,"id":11772759}]}]}
{"op":"mcm","clk":"1009489773","pt":1580644811640,"mc":[{"id":"1.168222848","rc":[{"batb":[[0,1.92,2.19],[1,1.91,2.06],[2,1.9,115.07]],"ltp":1.95,"tv":2534.47,"id":9631075}]}]}
{"op":"mcm","clk":"1009489892","pt":1580644812481,"mc":[{"id":"1.168222848","rc":[{"batb":[[0,1.94,15.14],[1,1.92,2.19],[2,1.91,2.06]],"ltp":1.95,"tv":2534.47,"id":9631075}]}]}
{"op":"mcm","clk":"1009490055","pt":1580644813800,"mc":[{"id":"1.168222848","rc":[{"batb":[[0,1.94,22.72]],"ltp":1.95,"tv":2534.47,"id":9631075}]}]}
{"op":"mcm","clk":"1009490455","pt":1580644816632,"mc":[{"id":"1.168222848","rc":[{"batb":[[2,1.9,2.53]],"batl":[[0,2.1,10.6],[1,2.12,2.21],[2,2.16,2.1]],"ltp":2.04,"tv":957.99,"id":11772759}]}]}
{"op":"mcm","clk":"1009490610","pt":1580644817739,"mc":[{"id":"1.168222848","rc":[{"batb":[[0,1.94,37.86]],"ltp":1.95,"tv":2534.47,"id":9631075},{"batb":[[2,1.98,2]],"batl":[[2,2.14,2.11]],"ltp":2.04,"tv":957.99,"id":11772759}]}]}
{"op":"mcm","clk":"1009490846","pt":1580644819683,"mc":[{"id":"1.168222848","rc":[{"batb":[[0,1.92,2.19],[1,1.91,2.06],[2,1.9,115.07]],"ltp":1.95,"tv":2534.47,"id":9631075}]}]}
{"op":"mcm","clk":"1009490942","pt":1580644820469,"mc":[{"id":"1.168222848","rc":[{"batb":[[0,1.94,15.14],[1,1.92,2.19],[2,1.91,2]],"ltp":1.95,"tv":2534.47,"id":9631075}]}]}
{"op":"mcm","clk":"1009491137","pt":1580644822162,"mc":[{"id":"1.168222848","rc":[{"batb":[[0,1.94,30.29]],"ltp":1.95,"tv":2534.47,"id":9631075}]}]}
{"op":"mcm","clk":"1009491662","pt":1580644826676,"mc":[{"id":"1.168222848","rc":[{"batb":[[0,1.94,37.86]],"ltp":1.95,"tv":2534.47,"id":9631075}]}]}
{"op":"mcm","clk":"1009491733","pt":1580644827262,"mc":[{"id":"1.168222848","rc":[{"batb":[[0,1.94,53.01]],"ltp":1.95,"tv":2534.47,"id":9631075},{"batb":[[2,1.98,2.26]],"batl":[[2,2.14,2.25]],"ltp":2.04,"tv":957.99,"id":11772759}]}]}
{"op":"mcm","clk":"1009491911","pt":1580644828672,"mc":[{"id":"1.168222848","rc":[{"batb":[[0,1.9,117.13],[1,1.89,2],[2,1.88,323.79]],"ltp":1.95,"tv":2534.47,"id":9631075},{"batl":[[1,2.14,2.25],[2,2.16,2.22]],"ltp":2.04,"tv":957.99,"id":11772759}]}]}
{"op":"mcm","clk":"1009492015","pt":1580644829577,"mc":[{"id":"1.168222848","rc":[{"trd":[[1.94,567.61]],"batb":[[0,1.93,7.57],[1,1.9,117.13],[2,1.89,2.05]],"batl":[[0,1.95,7.76],[1,1.98,11.49],[2,1.99,420.1]],"ltp":1.94,"tv":2549.61,"id":9631075}],"tv":3507.61}]}
{"op":"mcm","clk":"1009492084","pt":1580644830171,"mc":[{"id":"1.168222848","rc":[{"batb":[[1,1.91,2.06],[2,1.9,117.13]],"batl":[[1,1.97,2.03],[2,1.98,13.55]],"ltp":1.94,"tv":2549.61,"id":9631075},{"batb":[[1,2,2],[2,1.99,2]],"batl":[[1,2.12,2.13],[2,2.14,2.25]],"ltp":2.04,"tv":957.99,"id":11772759}]}]}
{"op":"mcm","clk":"1009492381","pt":1580644832688,"mc":[{"id":"1.168222848","rc":[{"batb":[[0,1.92,7.57],[1,1.9,117.13],[2,1.89,2.05]],"ltp":1.94,"tv":2549.61,"id":9631075},{"batl":[[1,2.14,2.25],[2,2.16,2.22]],"ltp":2.04,"tv":957.99,"id":11772759}]}]}
{"op":"mcm","clk":"1009493204","pt":1580644839696,"mc":[{"id":"1.168222848","rc":[{"trd":[[1.95,321.46]],"batl":[[0,1.97,2.29],[1,1.98,13.55],[2,1.99,422.37]],"ltp":1.95,"tv":2564.62,"id":9631075}],"tv":3522.62}]}
{"op":"mcm","clk":"1009493264","pt":1580644840174,"mc":[{"id":"1.168222848","rc":[{"batl":[[0,1.98,11.75],[1,1.99,420.1],[2,2,422.1]],"ltp":1.95,"tv":2564.62,"id":9631075},{"batb":[[1,1.99,2],[2,1.98,2.26]],"batl":[[2,2.16,2.16]],"ltp":2.04,"tv":957.99,"id":11772759}]}]}
{"op":"mcm","clk":"1009493694","pt":1580644843488,"mc":[{"id":"1.168222848","rc":[{"batb":[[0,1.94,15.14],[1,1.92,9.57],[2,1.91,2.06]],"ltp":1.95,"tv":2564.62,"id":9631075},{"batl":[[1,2.12,2.21],[2,2.14,2.25]],"ltp":2.04,"tv":957.99,"id":11772759}]}]}
{"op":"mcm","clk":"1009493966","pt":1580644845279,"mc":[{"id":"1.168222848","rc":[{"batb":[[0,1.94,22.72]],"ltp":1.95,"tv":2564.62,"id":9631075}]}]}
{"op":"mcm","clk":"1009494575","pt":1580644849683,"mc":[{"id":"1.168222848","rc":[{"batb":[[1,1.92,2]],"ltp":1.95,"tv":2564.62,"id":9631075}]}]}
{"op":"mcm","clk":"1009494665","pt":1580644850316,"mc":[{"id":"1.168222848","rc":[{"batb":[[2,1.91,2]],"ltp":1.95,"tv":2564.62,"id":9631075},{"batb":[[2,1.98,2]],"batl":[[2,2.14,2.11]],"ltp":2.04,"tv":957.99,"id":11772759}]}]}
{"op":"mcm","clk":"1009495349","pt":1580644854824,"mc":[{"id":"1.168222848","rc":[{"batb":[[0,1.94,30.29]],"ltp":1.95,"tv":2564.62,"id":9631075}]}]}
{"op":"mcm","clk":"1009495767","pt":1580644857701,"mc":[{"id":"1.168222848","rc":[{"batb":[[0,1.94,37.86]],"ltp":1.95,"tv":2564.62,"id":9631075},{"batl":[[2,2.28,18.48]],"ltp":2.04,"tv":957.99,"id":11772759}]}]}
{"op":"mcm","clk":"1009495883","pt":1580644858431,"mc":[{"id":"1.168222848","rc":[{"batb":[[2,1.91,2.06]],"ltp":1.95,"tv":2564.62,"id":9631075},{"batb":[[2,1.98,2.26]],"batl":[[2,2.14,2.25]],"ltp":2.04,"tv":957.99,"id":11772759}]}]}
{"op":"mcm","clk":"1009496068","pt":1580644859721,"mc":[{"id":"1.168222848","rc":[{"batb":[[0,1.94,7.57]],"ltp":1.95,"tv":2564.62,"id":9631075},{"batl":[[1,2.12,2]],"ltp":2.04,"tv":957.99,"id":11772759}]}]}
{"op":"mcm","clk":"1009496290","pt":1580644861423,"mc":[{"id":"1.168222848","rc":[{"batb":[[0,1.94,22.72]],"ltp":1.95,"tv":2564.62,"id":9631075}]}]}
{"op":"mcm","clk":"1009496722","pt":1580644864722,"mc":[{"id":"1.168222848","rc":[{"trd":[[1.94,608.15]],"batb":[[0,1.94,2.45],[2,1.9,115.07]],"ltp":1.94,"tv":2605.17,"id":9631075},{"batb":[[2,1.98,2]],"batl":[[2,2.14,2.18]],"ltp":2.04,"tv":957.99,"id":11772759}],"tv":3563.16}]}
{"op":"mcm","clk":"1009496860","pt":1580644865728,"mc":[{"id":"1.168222848","rc":[{"batb":[[2,1.91,2.06]],"batl":[[0,1.95,20.17],[1,1.97,2.42],[2,1.98,13.74]],"ltp":1.94,"tv":2605.17,"id":9631075},{"batb":[[1,2,2],[2,1.99,2]],"ltp":2.04,"tv":957.99,"id":11772759}]}]}
{"op":"mcm","clk":"1009496984","pt":1580644866728,"mc":[{"id":"1.168222848","rc":[{"batb":[[2,1.98,2]],"ltp":2.04,"tv":957.99,"id":11772759}]}]}
{"op":"mcm","clk":"1009497109","pt":1580644867712,"mc":[{"id":"1.168222848","rc":[{"batb":[[2,1.99,2]],"ltp":2.04,"tv":957.99,"id":11772759}]}]}
{"op":"mcm","clk":"1009497198","pt":1580644868442,"mc":[{"id":"1.168222848","rc":[{"batb":[[0,1.93,2.45],[1,1.91,2.06],[2,1.9,117.07]],"ltp":1.94,"tv":2605.17,"id":9631075},{"batl":[[1,2.12,2.13]],"ltp":2.04,"tv":957.99,"id":11772759}]}]}
{"op":"mcm","clk":"1009497452","pt":1580644870642,"mc":[{"id":"1.168222848","rc":[{"batb":[[0,1.93,10.02]],"ltp":1.94,"tv":2605.17,"id":9631075},{"batl":[[2,2.16,2.22]],"ltp":2.04,"tv":957.99,"id":11772759}]}]}
{"op":"mcm","clk":"1009497513","pt":1580644871124,"mc":[{"id":"1.168222848","rc":[{"batb":[[1,1.92,7.57],[2,1.91,2.06]],"batl":[[2,1.98,13.66]],"ltp":1.94,"tv":2605.17,"id":9631075},{"batl":[[2,2.14,4.29]],"ltp":2.04,"tv":957.99,"id":11772759}]}]}
{"op":"mcm","clk":"1009498473","pt":1580644878729,"mc":[{"id":"1.168222848","rc":[{"batl":[[0,1.95,32.78],[2,1.98,5.34]],"ltp":1.94,"tv":2605.17,"id":9631075},{"batb":[[0,2.02,33.18]],"batl":[[2,2.14,2]],"ltp":2.04,"tv":957.99,"id":11772759}]}]}
{"op":"mcm","clk":"1009498489","pt":1580644878836,"mc":[{"id":"1.168222848","rc":[{"batb":[[0,2.04,12.12],[1,2.02,33.18],[2,2,2]],"ltp":2.04,"tv":957.99,"id":11772759}]}]}
{"op":"mcm","clk":"1009501017","pt":1580644897689,"mc":[{"id":"1.168222848","rc":[{"batl":[[0,1.95,12.6]],"ltp":1.94,"tv":2605.17,"id":9631075}]}]}
{"op":"mcm","clk":"1009501097","pt":1580644898172,"mc":[{"id":"1.168222848","rc":[{"batl":[[2,1.98,5.32]],"ltp":1.94,"tv":2605.17,"id":9631075},{"batl":[[2,2.14,2.25]],"ltp":2.04,"tv":957.99,"id":11772759}]}]}
{"op":"mcm","clk":"1009501718","pt":1580644902659,"mc":[{"id":"1.168222848","rc":[{"batb":[[0,1.9,115.07],[1,1.89,2],[2,1.88,271.54]],"batl":[[1,1.97,2.16]],"ltp":1.94,"tv":2605.17,"id":9631075}]}]}
{"op":"mcm","clk":"1009501880","pt":1580644903668,"mc":[{"id":"1.168222848","rc":[{"batb":[[1,1.88,271.54],[2,1.87,54.29]],"batl":[[0,1.95,33.03],[2,1.98,5.12]],"ltp":1.94,"tv":2605.17,"id":9631075},{"batl":[[1,2.14,2.25],[2,2.16,2.04]],"ltp":2.04,"tv":957.99,"id":11772759}]}]}
{"op":"mcm","clk":"1009501996","pt":1580644904564,"mc":[{"id":"1.168222848","rc":[{"batb":[[0,1.91,7.57],[1,1.9,115.07],[2,1.88,271.54]],"ltp":1.94,"tv":2605.17,"id":9631075}]}]}
{"op":"mcm","clk":"1009502082","pt":1580644905086,"mc":[{"id":"1.168222848","rc":[{"batb":[[2,1.89,2]],"ltp":1.94,"tv":2605.17,"id":9631075}]}]}
{"op":"mcm","clk":"1009503861","pt":1580644916570,"mc":[{"id":"1.168222848","rc":[{"batb":[[0,1.91,10.57]],"batl":[[2,1.98,3.09]],"ltp":1.94,"tv":2605.17,"id":9631075},{"batl":[[2,2.28,18.48]],"ltp":2.04,"tv":957.99,"id":11772759}]}]}
{"op":"mcm","clk":"1009504014","pt":1580644917687,"mc":[{"id":"1.168222848","rc":[{"trd":[[1.95,387.29]],"batl":[[0,1.98,3.2],[1,1.99,422.22],[2,2,422.1]],"ltp":1.95,"tv":2670.99,"id":9631075},{"batl":[[2,2.16,2.04]],"ltp":2.04,"tv":957.99,"id":11772759}],"tv":3628.99}]}
{"op":"mcm","clk":"1009504080","pt":1580644918085,"mc":[{"id":"1.168222848","rc":[{"batb":[[0,1.91,3]],"batl":[[0,1.98,3.09]],"ltp":1.95,"tv":2670.99,"id":9631075}]}]}
{"op":"mcm","clk":"1009504336","pt":1580644919681,"mc":[{"id":"1.168222848","rc":[{"trd":[[1.94,648.99]],"batl":[[0,1.96,2.23],[1,1.97,2.06],[2,1.98,3.09]],"ltp":1.94,"tv":2711.83,"id":9631075},{"batb":[[1,2.02,35.42],[2,1.99,2]],"ltp":2.04,"tv":957.99,"id":11772759}],"tv":3669.83}]}
{"op":"mcm","clk":"1009504475","pt":1580644920469,"mc":[{"id":"1.168222848","rc":[{"batl":[[0,1.98,3.2],[1,1.99,422.25],[2,2,422.1]],"ltp":1.94,"tv":2711.83,"id":9631075},{"batb":[[1,2.02,33.18],[2,2,2]],"ltp":2.04,"tv":957.99,"id":11772759}]}]}
{"op":"mcm","clk":"1009504691","pt":1580644921705,"mc":[{"id":"1.168222848","rc":[{"batb":[[0,1.93,15.14],[1,1.91,5.06],[2,1.9,117.13]],"ltp":1.94,"tv":2711.83,"id":9631075}]}]}
{"op":"mcm","clk":"1009504836","pt":1580644922679,"mc":[{"id":"1.168222848","rc":[{"batb":[[0,1.93,22.72]],"batl":[[2,2,420.1]],"ltp":1.94,"tv":2711.83,"id":9631075},{"batl":[[1,2.12,2.21],[2,2.28,18.48]],"ltp":2.04,"tv":957.99,"id":11772759}]}]}
{"op":"mcm","clk":"1009504989","pt":1580644923684,"mc":[{"id":"1.168222848","rc":[{"batb":[[0,1.94,15.04],[1,1.93,22.72],[2,1.92,2.19]],"batl":[[0,1.98,3.09],[2,2,422.1]],"ltp":1.94,"tv":2711.83,"id":9631075},{"batl":[[2,2.14,2]],"ltp":2.04,"tv":957.99,"id":11772759}]}]}
{"op":"mcm","clk":"1009505277","pt":1580644925590,"mc":[{"id":"1.168222848","rc":[{"trd":[[1.94,676.65]],"batb":[[0,1.94,1.21],[1,1.91,3],[2,1.9,115.07]],"batl":[[0,1.95,13.86],[1,1.97,2.16],[2,1.98,5.15]],"ltp":1.94,"tv":2739.49,"id":9631075},{"batl":[[1,2.14,2],[2,2.16,2.22]],"ltp":2.04,"tv":957.99,"id":11772759}],"tv":3697.49}]}
{"op":"mcm","clk":"1009505430","pt":1580644926596,"mc":[{"id":"1.168222848","rc":[{"trd":[[1.95,414.7]],"batl":[[0,1.98,3.25],[1,1.99,422.37],[2,2,422.1]],"ltp":1.95,"tv":2766.9,"id":9631075}],"tv":3724.9}]}
{"op":"mcm","clk":"1009505749","pt":1580644928682,"mc":[{"id":"1.168222848","rc":[{"batb":[[0,1.94,8.78],[1,1.92,261.38],[2,1.91,5]],"batl":[[2,2,420.1]],"ltp":1.95,"tv":2766.9,"id":9631075}]}]}
{"op":"mcm","clk":"1009505892","pt":1580644929579,"mc":[{"id":"1.168222848","rc":[{"batb":[[1,1.92,2.19]],"batl":[[0,1.98,3.09],[2,2,422.1]],"ltp":1.95,"tv":2766.9,"id":9631075},{"batl":[[1,2.12,2.13],[2,2.14,2.25]],"ltp":2.04,"tv":957.99,"id":11772759}]}]}
{"op":"mcm","clk":"1009506364","pt":1580644932671,"mc":[{"id":"1.168222848","rc":[{"batb":[[0,1.92,2.19],[1,1.91,5],[2,1.9,117.13]],"ltp":1.95,"tv":2766.9,"id":9631075}]}]}
{"op":"mcm","clk":"1009506519","pt":1580644933640,"mc":[{"id":"1.168222848","rc":[{"batb":[[0,1.94,20.26],[1,1.92,259.19],[2,1.91,3]],"batl":[[2,2,420.1]],"ltp":1.95,"tv":2766.9,"id":9631075},{"batl":[[1,2.14,2.25],[2,2.16,2.22]],"ltp":2.04,"tv":957.99,"id":11772759}]}]}
{"op":"mcm","clk":"1009506666","pt":1580644934682,"mc":[{"id":"1.168222848","rc":[{"batb":[[1,1.92,2.19],[2,1.91,5]],"batl":[[2,2,422.1]],"ltp":1.95,"tv":2766.9,"id":9631075},{"batl":[[1,2.12,2.13]],"ltp":2.04,"tv":957.99,"id":11772759}]}]}
{"op":"mcm","clk":"1009506768","pt":1580644935391,"mc":[{"id":"1.168222848","rc":[{"batb":[[0,1.94,35.4]],"ltp":1.95,"tv":2766.9,"id":9631075},{"batl":[[2,2.14,2.18]],"ltp":2.04,"tv":957.99,"id":11772759}]}]}
{"op":"mcm","clk":"1009507699","pt":1580644941491,"mc":[{"id":"1.168222848","rc":[{"batb":[[2,1.91,5.06]],"ltp":1.95,"tv":2766.9,"id":9631075},{"batl":[[0,2.08,8.4],[1,2.1,10.6],[2,2.12,2.13]],"ltp":2.04,"tv":957.99,"id":11772759}]}]}
{"op":"mcm","clk":"1009508019","pt":1580644943718,"mc":[{"id":"1.168222848","rc":[{"batb":[[0,1.94,7.57],[1,1.91,3],[2,1.9,117.13]],"ltp":1.95,"tv":2766.9,"id":9631075},{"batl":[[0,2.08,247.59]],"ltp":2.04,"tv":957.99,"id":11772759}]}]}
{"op":"mcm","clk":"1009508136","pt":1580644944615,"mc":[{"id":"1.168222848","rc":[{"batb":[[0,1.94,15.14],[1,1.92,2.07],[2,1.91,5.06]],"ltp":1.95,"tv":2766.9,"id":9631075},{"trd":[[2.06,38.99]],"batl":[[0,2.08,8.82],[1,2.1,4.11],[2,2.14,2.04]],"ltp":2.06,"tv":973.74,"id":11772759}],"tv":3740.65}]}
{"op":"mcm","clk":"1009508165","pt":1580644944832,"mc":[{"id":"1.168222848","rc":[{"batl":[[1,2.1,2.06],[2,2.12,2.21]],"ltp":2.06,"tv":973.74,"id":11772759}]}]}
{"op":"mcm","clk":"1009508411","pt":1580644946732,"mc":[{"id":"1.168222848","rc":[{"batb":[[0,1.94,22.72]],"ltp":1.95,"tv":2766.9,"id":9631075},{"batl":[[0,2.08,8.4]],"ltp":2.06,"tv":973.74,"id":11772759}]}]}
{"op":"mcm","clk":"1009509100","pt":1580644951437,"mc":[{"id":"1.168222848","rc":[{"batb":[[0,1.94,30.29]],"ltp":1.95,"tv":2766.9,"id":9631075}]}]}
{"op":"mcm","clk":"1009509157","pt":1580644951816,"mc":[{"id":"1.168222848","rc":[{"trd":[[1.94,732]],"batb":[[0,1.94,2.61]],"ltp":1.94,"tv":2822.25,"id":9631075}],"tv":3795.99}]}
{"op":"mcm","clk":"1009509850","pt":1580644956654,"mc":[{"id":"1.168222848","rc":[{"batb":[[1,1.92,77.96],[2,1.91,3]],"ltp":1.94,"tv":2822.25,"id":9631075}]}]}
{"op":"mcm","clk":"1009509997","pt":1580644957724,"mc":[{"id":"1.168222848","rc":[{"batb":[[2,1.91,5.06]],"batl":[[0,1.96,7.57],[1,1.98,5.09],[2,1.99,420.1]],"ltp":1.94,"tv":2822.25,"id":9631075}]}]}
{"op":"mcm","clk":"1009510028","pt":1580644957941,"mc":[{"id":"1.168222848","rc":[{"batl":[[2,1.99,422.21]],"ltp":1.94,"tv":2822.25,"id":9631075}]}]}
{"op":"mcm","clk":"1009510162","pt":1580644958846,"mc":[{"id":"1.168222848","rc":[{"batb":[[0,1.94,10.18]],"ltp":1.94,"tv":2822.25,"id":9631075}]}]}
{"op":"mcm","clk":"1009510561","pt":1580644961546,"mc":[{"id":"1.168222848","rc":[{"batb":[[0,1.94,17.76]],"ltp":1.94,"tv":2822.25,"id":9631075}]}]}
{"op":"mcm","clk":"1009510804","pt":1580644963350,"mc":[{"id":"1.168222848","rc":[{"batb":[[1,1.93,15.14],[2,1.92,77.96]],"batl":[[2,1.99,422.14]],"ltp":1.94,"tv":2822.25,"id":9631075}]}]}
{"op":"mcm","clk":"1009512206","pt":1580644972634,"mc":[{"id":"1.168222848","rc":[{"batb":[[0,1.94,26.7]],"batl":[[0,1.96,15.97],[2,1.99,422.39]],"ltp":1.94,"tv":2822.25,"id":9631075}]}]}
{"op":"mcm","clk":"1009514129","pt":1580644986655,"mc":[{"id":"1.168222848","rc":[{"batb":[[0,1.94,34.27]],"batl":[[2,1.99,422.34]],"ltp":1.94,"tv":2822.25,"id":9631075}]}]}
{"op":"mcm","clk":"1009514155","pt":1580644986873,"mc":[{"id":"1.168222848","rc":[{"trd":[[1.94,794.76]],"batb":[[0,1.94,2.89]],"ltp":1.94,"tv":2885.01,"id":9631075}],"tv":3858.76}]}
{"op":"mcm","clk":"1009514556","pt":1580644989756,"mc":[{"id":"1.168222848","rc":[{"trd":[[1.95,444.52]],"batl":[[0,1.96,16.21],[1,1.98,5.34]],"ltp":1.95,"tv":2914.83,"id":9631075}],"tv":3888.58}]}
{"op":"mcm","clk":"1009515125","pt":1580644993554,"mc":[{"id":"1.168222848","rc":[{"batl":[[0,1.95,7.81],[1,1.96,15.97],[2,1.97,2.16]],"ltp":1.95,"tv":2914.83,"id":9631075}]}]}
{"op":"mcm","clk":"1009515269","pt":1580644994626,"mc":[{"id":"1.168222848","rc":[{"trd":[[1.95,459.95]],"batl":[[0,1.96,16.07],[1,1.98,5.34],[2,1.99,422.11]],"ltp":1.95,"tv":2930.26,"id":9631075}],"tv":3904.0}]}
{"op":"mcm","clk":"1009515340","pt":1580644995050,"mc":[{"id":"1.168222848","rc":[{"batl":[[0,1.96,8.49]],"ltp":1.95,"tv":2930.26,"id":9631075}]}]}
{"op":"mcm","clk":"1009515587","pt":1580644996495,"mc":[{"id":"1.168222848","rc":[{"batb":[[0,1.94,18.03]],"ltp":1.95,"tv":2930.26,"id":9631075}]}]}
{"op":"mcm","clk":"1009516631","pt":1580645003564,"mc":[{"id":"1.168222848","rc":[{"batl":[[0,1.98,5.43],[1,1.99,422.11],[2,2,420.1]],"ltp":1.95,"tv":2930.26,"id":9631075}]}]}
{"op":"mcm","clk":"1009516745","pt":1580645004269,"mc":[{"id":"1.168222848","rc":[{"batb":[[0,1.94,25.6]],"batl":[[0,1.98,3.18],[2,2,422.1]],"ltp":1.95,"tv":2930.26,"id":9631075}]}]}
{"op":"mcm","clk":"1009517068","pt":1580645006266,"mc":[{"id":"1.168222848","rc":[{"batb":[[1,1.92,77.96],[2,1.91,5.06]],"ltp":1.95,"tv":2930.26,"id":9631075}]}]}
{"op":"mcm","clk":"1009517706","pt":1580645010597,"mc":[{"id":"1.168222848","rc":[{"batb":[[0,1.94,33.17],[2,1.91,3]],"batl":[[2,2,420.1]],"ltp":1.95,"tv":2930.26,"id":9631075}]}]}
{"op":"mcm","clk":"1009517756","pt":1580645010785,"mc":[{"id":"1.168222848","rc":[{"batb":[[2,1.91,5.06]],"batl":[[2,2,422.1]],"ltp":1.95,"tv":2930.26,"id":9631075}]}]}
{"op":"mcm","clk":"1009517969","pt":1580645011959,"mc":[{"id":"1.168222848","rc":[{"trd":[[1.94,855.68]],"batb":[[0,1.94,2.71]],"ltp":1.94,"tv":2991.18,"id":9631075}],"tv":3964.93}]}
{"op":"mcm","clk":"1009518132","pt":1580645013074,"mc":[{"id":"1.168222848","rc":[{"batb":[[0,1.92,75.89],[1,1.91,3],[2,1.9,2.06]],"ltp":1.94,"tv":2991.18,"id":9631075}]}]}
{"op":"mcm","clk":"1009518322","pt":1580645014470,"mc":[{"id":"1.168222848","rc":[{"batl":[[0,1.95,7.66],[1,1.97,2.16],[2,1.98,5.34]],"ltp":1.94,"tv":2991.18,"id":9631075}]}]}
{"op":"mcm","clk":"1009519018","pt":1580645018703,"mc":[{"id":"1.168222848","rc":[{"batb":[[0,1.93,7.57],[1,1.92,75.89],[2,1.91,5.06]],"ltp":1.94,"tv":2991.18,"id":9631075}]}]}
{"op":"mcm","clk":"1009519116","pt":1580645019188,"mc":[{"id":"1.168222848","rc":[{"batl":[[0,1.95,15.24]],"ltp":1.94,"tv":2991.18,"id":9631075}]}]}
{"op":"mcm","clk":"1009519658","pt":1580645022681,"mc":[{"id":"1.168222848","rc":[{"trd":[[1.95,490.17]],"batl":[[0,1.97,2.28],[1,1.98,5.34],[2,1.99,422.33]],"ltp":1.95,"tv":3021.41,"id":9631075}],"tv":3995.15}]}
{"op":"mcm","clk":"1009519771","pt":1580645023300,"mc":[{"id":"1.168222848","rc":[{"batl":[[0,1.98,3.21],[1,1.99,422.16],[2,2,422.1]],"ltp":1.95,"tv":3021.41,"id":9631075}]}]}
{"op":"mcm","clk":"1009520060","pt":1580645025496,"mc":[{"id":"1.168222848","rc":[{"trd":[[1.95,520.4]],"batl":[[0,1.97,2.31],[1,1.98,5.15],[2,1.99,422.16]],"ltp":1.95,"tv":3051.63,"id":9631075}],"tv":4025.38}]}
{"op":"mcm","clk":"1009520165","pt":1580645026185,"mc":[{"id":"1.168222848","rc":[{"batl":[[0,1.98,3.24],[1,1.99,422.17],[2,2,422.1]],"ltp":1.95,"tv":3051.63,"id":9631075}]}]}
{"op":"mcm","clk":"1009520902","pt":1580645030692,"mc":[{"id":"1.168222848","rc":[{"batb":[[0,1.94,15.14],[1,1.93,7.57],[2,1.92,77.96]],"ltp":1.95,"tv":3051.63,"id":9631075}]}]}
{"op":"mcm","clk":"1009521106","pt":1580645032034,"mc":[{"id":"1.168222848","rc":[{"batb":[[1,1.92,77.96],[2,1.91,5]],"ltp":1.95,"tv":3051.63,"id":9631075}]}]}
{"op":"mcm","clk":"1009521744","pt":1580645035733,"mc":[{"id":"1.168222848","rc":[{"batb":[[0,1.94,22.72]],"batl":[[0,1.97,8.55],[1,1.98,3.09],[2,1.99,422.17]],"ltp":1.95,"tv":3051.63,"id":9631075}]}]}
{"op":"mcm","clk":"1009521820","pt":1580645036344,"mc":[{"id":"1.168222848","rc":[{"batb":[[2,1.91,5.06]],"ltp":1.95,"tv":3051.63,"id":9631075}]}]}
{"op":"mcm","clk":"1009521909","pt":1580645036911,"mc":[{"id":"1.168222848","rc":[{"trd":[[1.94,896.31]],"batb":[[0,1.94,2.4]],"ltp":1.94,"tv":3092.26,"id":9631075}],"tv":4066.0}]}
{"op":"mcm","clk":"1009522282","pt":1580645039604,"mc":[{"id":"1.168222848","rc":[{"trd":[[1.95,550.62]],"batl":[[0,1.97,10.68],[1,1.98,5.24]],"ltp":1.95,"tv":3122.48,"id":9631075}],"tv":4096.23}]}
{"op":"mcm","clk":"1009522392","pt":1580645040387,"mc":[{"id":"1.168222848","rc":[{"batl":[[0,1.97,8.58],[1,1.98,3.09],[2,1.99,422.44]],"ltp":1.95,"tv":3122.48,"id":9631075}]}]}
{"op":"mcm","clk":"1009522630","pt":1580645041721,"mc":[{"id":"1.168222848","rc":[{"batb":[[0,1.94,17.55],[2,1.91,3]],"ltp":1.95,"tv":3122.48,"id":9631075}]}]}
{"op":"mcm","clk":"1009522760","pt":1580645042635,"mc":[{"id":"1.168222848","rc":[{"batb":[[2,1.91,5.06]],"ltp":1.95,"tv":3122.48,"id":9631075}]}]}
{"op":"mcm","clk":"1009522846","pt":1580645043225,"mc":[{"id":"1.168222848","rc":[{"batl":[[0,1.95,7.75],[1,1.97,10.56],[2,1.98,5.29]],"ltp":1.95,"tv":3122.48,"id":9631075}]}]}
{"op":"mcm","clk":"1009523290","pt":1580645046640,"mc":[{"id":"1.168222848","rc":[{"batb":[[0,1.94,7.57],[1,1.92,75.89],[2,1.91,3]],"ltp":1.95,"tv":3122.48,"id":9631075}]}]}
{"op":"mcm","clk":"1009523331","pt":1580645046819,"mc":[{"id":"1.168222848","rc":[{"batb":[[0,1.94,15.14],[1,1.92,78.08],[2,1.91,5.06]],"ltp":1.95,"tv":3122.48,"id":9631075}]}]}
{"op":"mcm","clk":"1009523653","pt":1580645049313,"mc":[{"id":"1.168222848","rc":[{"batb":[[0,1.94,22.72]],"batl":[[2,1.98,5.11]],"ltp":1.95,"tv":3122.48,"id":9631075}]}]}
{"op":"mcm","clk":"1009524073","pt":1580645052703,"mc":[{"id":"1.168222848","rc":[{"batb":[[2,1.91,3]],"ltp":1.95,"tv":3122.48,"id":9631075}]}]}
{"op":"mcm","clk":"1009524122","pt":1580645053234,"mc":[{"id":"1.168222848","rc":[{"batb":[[0,1.92,75.89],[1,1.91,3],[2,1.9,2]],"batl":[[0,1.97,8.4],[1,1.98,3.09],[2,1.99,422.33]],"ltp":1.95,"tv":3122.48,"id":9631075}]}]}
{"op":"mcm","clk":"1009524253","pt":1580645054314,"mc":[{"id":"1.168222848","rc":[{"batl":[[0,1.95,12.26],[1,1.97,10.44],[2,1.98,5.34]],"ltp":1.95,"tv":3122.48,"id":9631075}]}]}
{"op":"mcm","clk":"1009525839","pt":1580645066649,"mc":[{"id":"1.168222848","rc":[{"batl":[[1,1.97,2.04]],"ltp":1.95,"tv":3122.48,"id":9631075}]}]}
{"op":"mcm","clk":"1009525916","pt":1580645067231,"mc":[{"id":"1.168222848","rc":[{"batl":[[0,1.95,20.66],[2,1.98,5.16]],"ltp":1.95,"tv":3122.48,"id":9631075}]}]}
{"op":"mcm","clk":"1009526305","pt":1580645070161,"mc":[{"id":"1.168222848","rc":[{"batl":[[0,1.95,8.4]],"ltp":1.95,"tv":3122.48,"id":9631075}]}]}
{"op":"mcm","clk":"1009526455","pt":1580645071342,"mc":[{"id":"1.168222848","rc":[{"batl":[[0,1.95,20.66]],"ltp":1.95,"tv":3122.48,"id":9631075}]}]}
{"op":"mcm","clk":"1009527273","pt":1580645077637,"mc":[{"id":"1.168222848","rc":[{"batb":[[0,1.93,7.57],[1,1.92,75.89],[2,1.91,5.06]],"batl":[[2,1.98,3.09]],"ltp":1.95,"tv":3122.48,"id":9631075}]}]}
{"op":"mcm","clk":"1009527320","pt":1580645078057,"mc":[{"id":"1.168222848","rc":[{"batl":[[2,1.98,5.11]],"ltp":1.95,"tv":3122.48,"id":9631075}]}]}
{"op":"mcm","clk":"1009528936","pt":1580645089757,"mc":[{"id":"1.168222848","rc":[{"trd":[[1.95,590.19]],"batb":[[1,1.91,5.06],[2,1.9,2.06]],"batl":[[0,1.98,3.97],[1,1.99,422.27],[2,2,422.1]],"ltp":1.95,"tv":3162.05,"id":9631075},{"batb":[[1,2.02,52.16]],"ltp":2.06,"tv":973.74,"id":11772759}],"tv":4135.8}]}
{"op":"mcm","clk":"1009529150","pt":1580645091365,"mc":[{"id":"1.168222848","rc":[{"batb":[[0,1.94,15.14],[1,1.93,7.57],[2,1.92,2.19]],"ltp":1.95,"tv":3162.05,"id":9631075}]}]}
{"op":"mcm","clk":"1009529265","pt":1580645092059,"mc":[{"id":"1.168222848","rc":[{"trd":[[1.94,909.25]],"batb":[[0,1.94,8.68]],"ltp":1.94,"tv":3174.99,"id":9631075}],"tv":4148.73}]}
{"op":"mcm","clk":"1009529545","pt":1580645094187,"mc":[{"id":"1.168222848","rc":[{"batl":[[0,1.95,8.45],[1,1.97,2.07],[2,1.98,5.11]],"ltp":1.94,"tv":3174.99,"id":9631075}]}]}
{"op":"mcm","clk":"1009529824","pt":1580645096360,"mc":[{"id":"1.168222848","rc":[{"batb":[[0,1.94,16.25]],"ltp":1.94,"tv":3174.99,"id":9631075}]}]}
{"op":"mcm","clk":"1009531087","pt":1580645105517,"mc":[{"id":"1.168222848","rc":[{"batb":[[0,1.94,23.82]],"ltp":1.94,"tv":3174.99,"id":9631075}]}]}
{"op":"mcm","clk":"1009531180","pt":1580645106003,"mc":[{"id":"1.168222848","rc":[{"batl":[[2,1.98,5.26]],"ltp":1.94,"tv":3174.99,"id":9631075}]}]}
{"op":"mcm","clk":"1009531436","pt":1580645107626,"mc":[{"id":"1.168222848","rc":[{"batb":[[0,1.93,7.57],[1,1.91,5.06],[2,1.9,2.06]],"ltp":1.94,"tv":3174.99,"id":9631075}]}]}
{"op":"mcm","clk":"1009531924","pt":1580645110699,"mc":[{"id":"1.168222848","rc":[{"batb":[[0,1.91,3],[1,1.9,2.06],[2,1.89,2.05]],"batl":[[0,1.98,3.09],[1,1.99,420.1],[2,2,422.1]],"ltp":1.94,"tv":3174.99,"id":9631075}]}]}
{"op":"mcm","clk":"1009531995","pt":1580645111120,"mc":[{"id":"1.168222848","rc":[{"batl":[[0,1.95,7.31],[1,1.97,2.16],[2,1.98,5.34]],"ltp":1.94,"tv":3174.99,"id":9631075}]}]}
{"op":"mcm","clk":"1009532494","pt":1580645114619,"mc":[{"id":"1.168222848","rc":[{"batb":[[0,1.93,7.57],[1,1.91,5.06],[2,1.86,177.79]],"ltp":1.94,"tv":3174.99,"id":9631075}]}]}
{"op":"mcm","clk":"1009532521","pt":1580645114827,"mc":[{"id":"1.168222848","rc":[{"batb":[[2,1.9,2.06]],"ltp":1.94,"tv":3174.99,"id":9631075}]}]}
{"op":"mcm","clk":"1009532788","pt":1580645116600,"mc":[{"id":"1.168222848","rc":[{"batb":[[0,1.93,15.14]],"batl":[[2,1.98,3.09]],"ltp":1.94,"tv":3174.99,"id":9631075}]}]}
{"op":"mcm","clk":"1009532818","pt":1580645116816,"mc":[{"id":"1.168222848","rc":[{"batl":[[2,1.98,5.34]],"ltp":1.94,"tv":3174.99,"id":9631075}]}]}
{"op":"mcm","clk":"1009533792","pt":1580645123742,"mc":[{"id":"1.168222848","rc":[{"batb":[[0,1.94,15.14],[1,1.93,15.14],[2,1.92,2]],"batl":[[2,1.98,3.09]],"ltp":1.94,"tv":3174.99,"id":9631075}]}]}
{"op":"mcm","clk":"1009533826","pt":1580645123950,"mc":[{"id":"1.168222848","rc":[{"batl":[[2,1.98,5.34]],"ltp":1.94,"tv":3174.99,"id":9631075}]}]}
{"op":"mcm","clk":"1009534646","pt":1580645129616,"mc":[{"id":"1.168222848","rc":[{"batb":[[0,1.94,7.57],[2,1.91,5.06]],"batl":[[2,1.98,3.09]],"ltp":1.94,"tv":3174.99,"id":9631075}]}]}
{"op":"mcm","clk":"1009534688","pt":1580645129934,"mc":[{"id":"1.168222848","rc":[{"batb":[[2,1.92,2]],"batl":[[2,1.98,5.32]],"ltp":1.94,"tv":3174.99,"id":9631075}]}]}
{"op":"mcm","clk":"1009535060","pt":1580645132749,"mc":[{"id":"1.168222848","rc":[{"trd":[[1.94,924.39]],"batb":[[0,1.93,15.14],[1,1.91,5],[2,1.9,2.06]],"batl":[[0,1.94,11.36],[1,1.95,7.53],[2,1.96,9.35]],"ltp":1.94,"tv":3190.13,"id":9631075},{"batb":[[1,2.02,54.4]],"ltp":2.06,"tv":973.74,"id":11772759}],"tv":4163.88}]}
{"op":"mcm","clk":"1009535174","pt":1580645133660,"mc":[{"id":"1.168222848","rc":[{"trd":[[1.94,946.91]],"batl":[[0,1.95,7.63],[1,1.96,7.31],[2,1.97,2.12]],"ltp":1.94,"tv":3212.65,"id":9631075}],"tv":4186.4}]}
{"op":"mcm","clk":"1009535207","pt":1580645133982,"mc":[{"id":"1.168222848","rc":[{"batb":[[1,2.02,52.16]],"ltp":2.06,"tv":973.74,"id":11772759}]}]}
{"op":"mcm","clk":"1009535752","pt":1580645137646,"mc":[{"id":"1.168222848","rc":[{"batb":[[0,1.91,5],[1,1.9,2.06],[2,1.86,177.79]],"batl":[[0,1.97,2.22],[1,1.98,5.32],[2,1.99,420.1]],"ltp":1.94,"tv":3212.65,"id":9631075}]}]}
{"op":"mcm","clk":"1009535905","pt":1580645138750,"mc":[{"id":"1.168222848","rc":[{"batb":[[0,1.91,3],[2,1.89,2.05]],"batl":[[0,1.95,14.95],[1,1.98,3.09],[2,1.99,422.1]],"ltp":1.94,"tv":3212.65,"id":9631075}]}]}
{"op":"mcm","clk":"1009535934","pt":1580645138919,"mc":[{"id":"1.168222848","rc":[{"batl":[[1,1.97,2.16],[2,1.98,5.27]],"ltp":1.94,"tv":3212.65,"id":9631075}]}]}
{"op":"mcm","clk":"1009536704","pt":1580645144554,"mc":[{"id":"1.168222848","rc":[{"batb":[[0,1.93,7.57],[1,1.91,5.06],[2,1.9,2.06]],"ltp":1.94,"tv":3212.65,"id":9631075}]}]}
{"op":"mcm","clk":"1009536789","pt":1580645145189,"mc":[{"id":"1.168222848","rc":[{"batl":[[2,1.98,5.23]],"ltp":1.94,"tv":3212.65,"id":9631075}]}]}
{"op":"mcm","clk":"1009538171","pt":1580645154742,"mc":[{"id":"1.168222848","rc":[{"batb":[[0,1.92,7.57]],"ltp":1.94,"tv":3212.65,"id":9631075}]}]}
{"op":"mcm","clk":"1009538228","pt":1580645155170,"mc":[{"id":"1.168222848","rc":[{"batb":[[1,1.91,3]],"batl":[[2,1.98,5.14]],"ltp":1.94,"tv":3212.65,"id":9631075}]}]}
{"op":"mcm","clk":"1009538420","pt":1580645156556,"mc":[{"id":"1.168222848","rc":[{"batb":[[0,1.91,3],[1,1.9,2.06],[2,1.89,2.05]],"batl":[[0,1.98,3.19],[1,1.99,420.1],[2,2,422.1]],"ltp":1.94,"tv":3212.65,"id":9631075}]}]}
{"op":"mcm","clk":"1009538574","pt":1580645157677,"mc":[{"id":"1.168222848","rc":[{"batl":[[0,1.94,15.02],[1,1.96,2.12],[2,1.97,2.16]],"ltp":1.94,"tv":3212.65,"id":9631075},{"batb":[[1,2.02,54.19],[2,1.99,2]],"ltp":2.06,"tv":973.74,"id":11772759}]}]}
{"op":"mcm","clk":"1009538602","pt":1580645157876,"mc":[{"id":"1.168222848","rc":[{"batb":[[2,2,2]],"ltp":2.06,"tv":973.74,"id":11772759}]}]}
{"op":"mcm","clk":"1009539077","pt":1580645161606,"mc":[{"id":"1.168222848","rc":[{"batb":[[0,2.02,54.19],[1,2,2],[2,1.99,2]],"ltp":2.06,"tv":973.74,"id":11772759}]}]}
{"op":"mcm","clk":"1009539193","pt":1580645162570,"mc":[{"id":"1.168222848","rc":[{"batb":[[2,1.89,2]],"batl":[[2,1.98,3.09]],"ltp":1.94,"tv":3212.65,"id":9631075},{"batb":[[1,1.9,2.53],[2,1.81,37.86]],"ltp":2.06,"tv":973.74,"id":11772759}]}]}
{"op":"mcm","clk":"1009539216","pt":1580645162807,"mc":[{"id":"1.168222848","rc":[{"batl":[[2,1.97,2.16]],"ltp":1.94,"tv":3212.65,"id":9631075},{"batb":[[1,2,2],[2,1.9,2.53]],"ltp":2.06,"tv":973.74,"id":11772759}]}]}
{"op":"mcm","clk":"1009539750","pt":1580645166907,"mc":[{"id":"1.168222848","rc":[{"batb":[[0,1.92,7.57],[1,1.91,3],[2,1.9,2.06]],"ltp":1.94,"tv":3212.65,"id":9631075}]}]}
{"op":"mcm","clk":"1009540267","pt":1580645170706,"mc":[{"id":"1.168222848","rc":[{"batb":[[0,1.91,3],[1,1.89,2],[2,1.88,2.21]],"batl":[[2,1.98,3.09]],"ltp":1.94,"tv":3212.65,"id":9631075},{"batb":[[1,1.9,2.53],[2,1.81,37.86]],"ltp":2.06,"tv":973.74,"id":11772759}]}]}
{"op":"mcm","clk":"1009540370","pt":1580645171294,"mc":[{"id":"1.168222848","rc":[{"batb":[[1,1.9,2.06],[2,1.89,2.05]],"batl":[[2,1.97,2.02]],"ltp":1.94,"tv":3212.65,"id":9631075},{"batb":[[1,2,2],[2,1.9,2.53]],"ltp":2.06,"tv":973.74,"id":11772759}]}]}
{"op":"mcm","clk":"1009540702","pt":1580645173699,"mc":[{"id":"1.168222848","rc":[{"batl":[[0,1.98,5.44],[1,1.99,422.29],[2,2,422.1]],"ltp":1.94,"tv":3212.65,"id":9631075},{"batb":[[0,2.02,52.16],[2,1.99,2]],"ltp":2.06,"tv":973.74,"id":11772759}]}]}
{"op":"mcm","clk":"1009540816","pt":1580645174602,"mc":[{"id":"1.168222848","rc":[{"batl":[[0,1.93,15],[1,1.95,2.2],[2,1.96,2.08]],"ltp":1.94,"tv":3212.65,"id":9631075},{"batb":[[0,2.02,54.21]],"ltp":2.06,"tv":973.74,"id":11772759}]}]}
{"op":"mcm","clk":"1009540992","pt":1580645175691,"mc":[{"id":"1.168222848","rc":[{"trd":[[1.93,29.86]],"batl":[[0,1.97,2.33],[1,1.98,5.34],[2,1.99,420.1]],"ltp":1.93,"tv":3242.52,"id":9631075},{"batb":[[0,2.02,52.16]],"ltp":2.06,"tv":973.74,"id":11772759}],"tv":4216.26}]}
{"op":"mcm","clk":"1009541125","pt":1580645176650,"mc":[{"id":"1.168222848","rc":[{"batb":[[2,1.86,177.79]],"batl":[[0,1.98,3.26],[1,1.99,420.1],[2,2,422.1]],"ltp":1.93,"tv":3242.52,"id":9631075},{"batb":[[1,1.99,2],[2,1.98,2]],"ltp":2.06,"tv":973.74,"id":11772759}]}]}
{"op":"mcm","clk":"1009541155","pt":1580645176878,"mc":[{"id":"1.168222848","rc":[{"batb":[[2,1.89,2.05]],"ltp":1.93,"tv":3242.52,"id":9631075}]}]}
{"op":"mcm","clk":"1009541436","pt":1580645178744,"mc":[{"id":"1.168222848","rc":[{"batl":[[0,1.98,3.19]],"ltp":1.93,"tv":3242.52,"id":9631075},{"batb":[[2,1.9,2.53]],"ltp":2.06,"tv":973.74,"id":11772759}]}]}
{"op":"mcm","clk":"1009541478","pt":1580645179057,"mc":[{"id":"1.168222848","rc":[{"batb":[[2,1.98,2]],"ltp":2.06,"tv":973.74,"id":11772759}]}]}
{"op":"mcm","clk":"1009541822","pt":1580645181465,"mc":[{"id":"1.168222848","rc":[{"batl":[[0,1.98,3.26]],"ltp":1.93,"tv":3242.52,"id":9631075}]}]}
{"op":"mcm","clk":"1009542936","pt":1580645188689,"mc":[{"id":"1.168222848","rc":[{"batl":[[1,2.12,2.59],[2,2.14,2.18]],"ltp":2.06,"tv":973.74,"id":11772759}]}]}
{"op":"mcm","clk":"1009543012","pt":1580645189165,"mc":[{"id":"1.168222848","rc":[{"batl":[[2,2.14,2]],"ltp":2.06,"tv":973.74,"id":11772759}]}]}
{"op":"mcm","clk":"1009543504","pt":1580645192650,"mc":[{"id":"1.168222848","rc":[{"batl":[[0,2.12,2.59],[1,2.14,2],[2,2.28,18.48]],"ltp":2.06,"tv":973.74,"id":11772759}]}]}
{"op":"mcm","clk":"1009543576","pt":1580645193138,"mc":[{"id":"1.168222848","rc":[{"batb":[[1,1.89,2.05],[2,1.88,2.05]],"ltp":1.93,"tv":3242.52,"id":9631075},{"batl":[[0,2.14,2.38],[1,2.16,2.16]],"ltp":2.06,"tv":973.74,"id":11772759}]}]}
{"op":"mcm","clk":"1009548039","pt":1580645223689,"mc":[{"id":"1.168222848","rc":[{"batl":[[0,2.1,8.78],[1,2.14,2],[2,2.16,2.16]],"ltp":2.06,"tv":973.74,"id":11772759}]}]}
{"op":"mcm","clk":"1009548176","pt":1580645224490,"mc":[{"id":"1.168222848","rc":[{"batb":[[0,1.91,12.23],[2,1.88,2.21]],"batl":[[0,1.98,11.66]],"ltp":1.93,"tv":3242.52,"id":9631075},{"batb":[[0,2.02,60.39]],"batl":[[2,2.16,2.04]],"ltp":2.06,"tv":973.74,"id":11772759}]}]}
{"op":"mcm","clk":"1009563811","pt":1580645331755,"mc":[{"id":"1.168222848","rc":[{"batb":[[0,1.92,7.57],[1,1.91,12.23],[2,1.9,2.06]],"ltp":1.93,"tv":3242.52,"id":9631075},{"batb":[[2,1.9,2.53]],"batl":[[2,2.28,18.48]],"ltp":2.06,"tv":973.74,"id":11772759}]}]}
{"op":"mcm","clk":"1009563832","pt":1580645331969,"mc":[{"id":"1.168222848","rc":[{"batb":[[2,1.98,2.26]],"batl":[[2,2.16,2.16]],"ltp":2.06,"tv":973.74,"id":11772759}]}]}
{"op":"mcm","clk":"1009564076","pt":1580645333685,"mc":[{"id":"1.168222848","rc":[{"batb":[[0,1.93,7.57],[1,1.92,7.57],[2,1.91,14.29]],"ltp":1.93,"tv":3242.52,"id":9631075},{"batl":[[1,2.12,2.13]],"ltp":2.06,"tv":973.74,"id":11772759}]}]}
{"op":"mcm","clk":"1009564109","pt":1580645333854,"mc":[{"id":"1.168222848","rc":[{"batl":[[2,2.14,2.25]],"ltp":2.06,"tv":973.74,"id":11772759}]}]}
{"op":"mcm","clk":"1009564363","pt":1580645335466,"mc":[{"id":"1.168222848","rc":[{"batb":[[0,1.92,7.57],[1,1.91,14.29],[2,1.9,2.06]],"ltp":1.93,"tv":3242.52,"id":9631075}]}]}
{"op":"mcm","clk":"1009564471","pt":1580645336109,"mc":[{"id":"1.168222848","rc":[{"batb":[[1,1.91,12.23]],"ltp":1.93,"tv":3242.52,"id":9631075},{"batl":[[1,2.14,2.25],[2,2.16,2.16]],"ltp":2.06,"tv":973.74,"id":11772759}]}]}
{"op":"mcm","clk":"1009564741","pt":1580645337752,"mc":[{"id":"1.168222848","rc":[{"batb":[[0,1.91,12.23],[1,1.89,2.05],[2,1.88,2]],"ltp":1.93,"tv":3242.52,"id":9631075},{"batb":[[2,1.9,2.53]],"batl":[[2,2.28,18.48]],"ltp":2.06,"tv":973.74,"id":11772759}]}]}
{"op":"mcm","clk":"1009564769","pt":1580645337965,"mc":[{"id":"1.168222848","rc":[{"batb":[[2,1.98,2.26]],"batl":[[2,2.16,2.22]],"ltp":2.06,"tv":973.74,"id":11772759}]}]}
{"op":"mcm","clk":"1009568120","pt":1580645360599,"mc":[{"id":"1.168222848","rc":[{"batb":[[0,1.91,87.57],[2,1.85,331.09]],"ltp":1.93,"tv":3242.52,"id":9631075},{"batb":[[2,1.9,2.53]],"batl":[[2,2.28,18.48]],"ltp":2.06,"tv":973.74,"id":11772759}]}]}
{"op":"mcm","clk":"1009568143","pt":1580645360807,"mc":[{"id":"1.168222848","rc":[{"batb":[[2,1.88,2.05]],"ltp":1.93,"tv":3242.52,"id":9631075},{"batb":[[2,1.98,2]],"batl":[[2,2.16,2.22]],"ltp":2.06,"tv":973.74,"id":11772759}]}]}
{"op":"mcm","clk":"1009572342","pt":1580645388742,"mc":[{"id":"1.168222848","rc":[{"batb":[[1,1.9,1.68],[2,1.89,2.05]],"ltp":1.93,"tv":3242.52,"id":9631075}]}]}
{"op":"mcm","clk":"1009572416","pt":1580645389217,"mc":[{"id":"1.168222848","rc":[{"batl":[[2,2.16,2.1]],"ltp":2.06,"tv":973.74,"id":11772759}]}]}
{"op":"mcm","clk":"1009575410","pt":1580645411649,"mc":[{"id":"1.168222848","rc":[{"batb":[[1,1.89,2.05],[2,1.88,2]],"ltp":1.93,"tv":3242.52,"id":9631075}]}]}
{"op":"mcm","clk":"1009575480","pt":1580645412272,"mc":[{"id":"1.168222848","rc":[{"batb":[[2,1.88,2.13]],"ltp":1.93,"tv":3242.52,"id":9631075},{"batl":[[2,2.16,2.16]],"ltp":2.06,"tv":973.74,"id":11772759}]}]}
{"op":"mcm","clk":"1009582023","pt":1580645460343,"mc":[{"id":"1.168222848","rc":[{"batb":[[2,1.88,2]],"batl":[[0,1.98,11.56]],"ltp":1.93,"tv":3242.52,"id":9631075},{"trd":[[2.1,7.16]],"batb":[[2,1.98,2.26]],"batl":[[0,2.1,5.2],[2,2.16,2.22]],"ltp":2.1,"tv":980.9,"id":11772759}],"tv":4223.42}]}
{"op":"mcm","clk":"1009582641","pt":1580645464752,"mc":[{"id":"1.168222848","rc":[{"batb":[[0,1.92,7.57],[1,1.91,87.57],[2,1.9,2]],"ltp":1.93,"tv":3242.52,"id":9631075}]}]}
{"op":"mcm","clk":"1009582910","pt":1580645466658,"mc":[{"id":"1.168222848","rc":[{"batb":[[0,1.91,87.57],[1,1.89,2],[2,1.88,2]],"ltp":1.93,"tv":3242.52,"id":9631075},{"batl":[[2,2.16,2.04]],"ltp":2.1,"tv":980.9,"id":11772759}]}]}
{"op":"mcm","clk":"1009635779","pt":1580645822701,"mc":[{"id":"1.168222848","rc":[{"batb":[[1,1.9,2],[2,1.89,2]],"ltp":1.93,"tv":3242.52,"id":9631075},{"batb":[[2,1.98,2]],"batl":[[0,2.08,10],[1,2.1,5.2],[2,2.12,2.21]],"ltp":2.1,"tv":980.9,"id":11772759}]}]}
{"op":"mcm","clk":"1009635823","pt":1580645823020,"mc":[{"id":"1.168222848","rc":[{"batb":[[2,1.89,2.05]],"ltp":1.93,"tv":3242.52,"id":9631075}]}]}
{"op":"mcm","clk":"1009638889","pt":1580645846630,"mc":[{"id":"1.168222848","rc":[{"batb":[[2,1.89,2]],"ltp":1.93,"tv":3242.52,"id":9631075}]}]}
{"op":"mcm","clk":"1009639219","pt":1580645849082,"mc":[{"id":"1.168222848","rc":[{"batl":[[1,2.12,2.21],[2,2.14,2.18]],"ltp":2.1,"tv":980.9,"id":11772759}]}]}
{"op":"mcm","clk":"1009639392","pt":1580645850354,"mc":[{"id":"1.168222848","rc":[{"batb":[[0,1.92,9.13],[1,1.91,78.33],[2,1.9,2]],"ltp":1.93,"tv":3242.52,"id":9631075},{"batl":[[0,2.08,18.4]],"ltp":2.1,"tv":980.9,"id":11772759}]}]}
{"op":"mcm","clk":"1009642874","pt":1580645875691,"mc":[{"id":"1.168222848","rc":[{"batl":[[2,2.28,18.48]],"ltp":2.1,"tv":980.9,"id":11772759}]}]}
{"op":"mcm","clk":"1009642975","pt":1580645876381,"mc":[{"id":"1.168222848","rc":[{"batl":[[2,2.14,2.18]],"ltp":2.1,"tv":980.9,"id":11772759}]}]}
{"op":"mcm","clk":"1009648753","pt":1580645921640,"mc":[{"id":"1.168222848","rc":[{"batb":[[0,1.93,36.99],[1,1.92,9.13],[2,1.91,5.06]],"ltp":1.93,"tv":3242.52,"id":9631075},{"batb":[[2,1.98,2.26]],"batl":[[2,2.14,2]],"ltp":2.1,"tv":980.9,"id":11772759}]}]}
{"op":"mcm","clk":"1009650842","pt":1580645937663,"mc":[{"id":"1.168222848","rc":[{"batb":[[0,1.93,48.7]],"ltp":1.93,"tv":3242.52,"id":9631075},{"batb":[[0,2.02,49.22]],"batl":[[2,2.28,18.48]],"ltp":2.1,"tv":980.9,"id":11772759}]}]}
{"op":"mcm","clk":"1009650875","pt":1580645937930,"mc":[{"id":"1.168222848","rc":[{"batb":[[2,1.98,2]],"batl":[[2,2.14,2.25]],"ltp":2.1,"tv":980.9,"id":11772759}]}]}
{"op":"mcm","clk":"1009651700","pt":1580645944671,"mc":[{"id":"1.168222848","rc":[{"batb":[[0,1.93,57.73],[1,1.91,5.06],[2,1.85,331.09]],"ltp":1.93,"tv":3242.52,"id":9631075},{"batb":[[2,1.9,2.53]],"batl":[[2,2.28,18.48]],"ltp":2.1,"tv":980.9,"id":11772759}]}]}
{"op":"mcm","clk":"1009651732","pt":1580645944844,"mc":[{"id":"1.168222848","rc":[{"batb":[[2,1.9,2.06]],"ltp":1.93,"tv":3242.52,"id":9631075},{"batb":[[2,1.98,2.26]],"batl":[[2,2.14,2.25]],"ltp":2.1,"tv":980.9,"id":11772759}]}]}
{"op":"mcm","clk":"1009665743","pt":1580646055695,"mc":[{"id":"1.168222848","rc":[{"batb":[[0,1.93,9.03]],"ltp":1.93,"tv":3242.52,"id":9631075}]}]}
{"op":"mcm","clk":"1009665802","pt":1580646056098,"mc":[{"id":"1.168222848","rc":[{"batb":[[2,1.98,2]],"batl":[[2,2.14,2]],"ltp":2.1,"tv":980.9,"id":11772759}]}]}
{"op":"mcm","clk":"1009671454","pt":1580646097702,"mc":[{"id":"1.168222848","rc":[{"batb":[[2,1.88,147.5]],"ltp":1.93,"tv":3242.52,"id":9631075},{"batb":[[2,1.9,2.53]],"batl":[[2,2.28,18.48]],"ltp":2.1,"tv":980.9,"id":11772759}]}]}
{"op":"mcm","clk":"1009671504","pt":1580646098129,"mc":[{"id":"1.168222848","rc":[{"batb":[[2,1.9,2.06]],"ltp":1.93,"tv":3242.52,"id":9631075},{"batb":[[2,1.98,2.26]],"batl":[[2,2.14,2.25]],"ltp":2.1,"tv":980.9,"id":11772759}]}]}
{"op":"mcm","clk":"1009674099","pt":1580646116678,"mc":[{"id":"1.168222848","rc":[{"trd":[[1.94,946.98],[1.98,848.85]],"batl":[[0,1.98,10.76]],"ltp":1.98,"tv":3243.31,"id":9631075},{"trd":[[2.02,123.96],[2.06,39.05]],"batb":[[0,1.99,2],[1,1.98,2.26],[2,1.9,2.53]],"ltp":2.02,"tv":1080.12,"id":11772759}],"tv":4323.44}]}
{"op":"mcm","clk":"1009674257","pt":1580646117738,"mc":[{"id":"1.168222848","rc":[{"batb":[[0,1.94,72.38],[1,1.93,9.03],[2,1.91,5.06]],"ltp":1.98,"tv":3243.31,"id":9631075},{"batb":[[0,1.99,52.35],[1,1.98,2],[2,1.97,2]],"batl":[[2,2.14,2]],"ltp":2.02,"tv":1080.12,"id":11772759}]}]}
{"op":"mcm","clk":"1009674363","pt":1580646118438,"mc":[{"id":"1.168222848","rc":[{"batb":[[2,1.92,2.07]],"ltp":1.98,"tv":3243.31,"id":9631075}]}]}
{"op":"mcm","clk":"1009676379","pt":1580646132663,"mc":[{"id":"1.168222848","rc":[{"batb":[[0,1.94,81.32],[1,1.92,2.07],[2,1.91,3]],"ltp":1.98,"tv":3243.31,"id":9631075},{"batb":[[1,1.9,2.53],[2,1.81,37.86]],"batl":[[2,2.28,18.48]],"ltp":2.02,"tv":1080.12,"id":11772759}]}]}
{"op":"mcm","clk":"1009676494","pt":1580646133501,"mc":[{"id":"1.168222848","rc":[{"trd":[[1.94,1081.9]],"batb":[[0,1.94,8.94],[2,1.91,5.06]],"ltp":1.94,"tv":3378.23,"id":9631075},{"batb":[[0,1.99,2],[1,1.98,2],[2,1.9,2.53]],"batl":[[2,2.14,2.11]],"ltp":2.02,"tv":1080.12,"id":11772759}],"tv":4458.36}]}
{"op":"mcm","clk":"1009676534","pt":1580646133774,"mc":[{"id":"1.168222848","rc":[{"batb":[[0,2.02,64.59],[1,1.99,2],[2,1.98,2]],"ltp":2.02,"tv":1080.12,"id":11772759}]}]}
{"op":"mcm","clk":"1009740045","pt":1580646605509,"mc":[{"id":"1.168222848","rc":[{"batb":[[2,1.91,5]],"ltp":1.94,"tv":3378.23,"id":9631075},{"batl":[[2,2.14,2.04]],"ltp":2.02,"tv":1080.12,"id":11772759}]}]}
{"op":"mcm","clk":"1009740252","pt":1580646606712,"mc":[{"id":"1.168222848","rc":[{"trd":[[1.94,1096.97]],"batb":[[0,1.94,1.4],[1,1.91,3],[2,1.9,2.06]],"ltp":1.94,"tv":3393.31,"id":9631075}],"tv":4473.43}]}
{"op":"mcm","clk":"1009742995","pt":1580646625648,"mc":[{"id":"1.168222848","rc":[{"batb":[[2,1.9,2.53]],"batl":[[2,2.28,18.48]],"ltp":2.02,"tv":1080.12,"id":11772759}]}]}
{"op":"mcm","clk":"1009743030","pt":1580646625858,"mc":[{"id":"1.168222848","rc":[{"batb":[[2,1.98,2]],"batl":[[2,2.14,2]],"ltp":2.02,"tv":1080.12,"id":11772759}]}]}
{"op":"mcm","clk":"1009743926","pt":1580646631651,"mc":[{"id":"1.168222848","rc":[{"batb":[[0,1.92,9.13]],"ltp":1.94,"tv":3393.31,"id":9631075},{"batb":[[0,2.02,72.83],[2,1.98,2.26]],"batl":[[2,2.14,2.25]],"ltp":2.02,"tv":1080.12,"id":11772759}]}]}
{"op":"mcm","clk":"1009744856","pt":1580646637666,"mc":[{"id":"1.168222848","rc":[{"trd":[[1.98,859.62],[1.99,103.56]],"batl":[[0,1.99,403.39],[1,2,420.1],[2,2.02,422.1]],"ltp":1.99,"tv":3420.78,"id":9631075},{"trd":[[2,633.98],[2.02,280.16]],"batb":[[0,1.98,2.26],[1,1.97,2.17],[2,1.9,2.53]],"batl":[[2,2.28,18.48]],"ltp":2.0,"tv":1252.95,"id":11772759}],"tv":4673.74}]}
{"op":"mcm","clk":"1009745038","pt":1580646638672,"mc":[{"id":"1.168222848","rc":[{"batb":[[0,1.93,90.98],[1,1.92,9.13],[2,1.91,3]],"ltp":1.99,"tv":3420.78,"id":9631075},{"batb":[[0,1.99,50.55],[1,1.98,2.26],[2,1.97,2.17]],"batl":[[2,2.14,2.25]],"ltp":2.0,"tv":1252.95,"id":11772759}]}]}
{"op":"mcm","clk":"1009745131","pt":1580646639260,"mc":[{"id":"1.168222848","rc":[{"batb":[[2,1.91,5.06]],"ltp":1.99,"tv":3420.78,"id":9631075}]}]}
{"op":"mcm","clk":"1009745762","pt":1580646643267,"mc":[{"id":"1.168222848","rc":[{"batl":[[2,2.14,2.11]],"ltp":2.0,"tv":1252.95,"id":11772759}]}]}
{"op":"mcm","clk":"1009748990","pt":1580646663496,"mc":[{"id":"1.168222848","rc":[{"batb":[[1,1.91,5.06],[2,1.9,2.06]],"ltp":1.99,"tv":3420.78,"id":9631075}]}]}
{"op":"mcm","clk":"1009749161","pt":1580646664497,"mc":[{"id":"1.168222848","rc":[{"batb":[[0,1.94,13.41],[1,1.93,90.98],[2,1.92,2.19]],"ltp":1.99,"tv":3420.78,"id":9631075},{"batl":[[2,2.14,2.25]],"ltp":2.0,"tv":1252.95,"id":11772759}]}]}
{"op":"mcm","clk":"1009749722","pt":1580646668636,"mc":[{"id":"1.168222848","rc":[{"trd":[[1.99,224.17]],"batl":[[0,1.99,343.08]],"ltp":1.99,"tv":3541.4,"id":9631075},{"batb":[[2,1.9,2.53]],"batl":[[2,2.28,18.48]],"ltp":2.0,"tv":1252.95,"id":11772759}],"tv":4794.35}]}
{"op":"mcm","clk":"1009749750","pt":1580646668815,"mc":[{"id":"1.168222848","rc":[{"batb":[[2,1.97,2.17]],"batl":[[2,2.14,2.25]],"ltp":2.0,"tv":1252.95,"id":11772759}]}]}
{"op":"mcm","clk":"1009765357","pt":1580646780576,"mc":[{"id":"1.168222848","rc":[{"batb":[[2,1.9,2.53]],"batl":[[2,2.28,18.48]],"ltp":2.0,"tv":1252.95,"id":11772759}]}]}
{"op":"mcm","clk":"1009765498","pt":1580646781589,"mc":[{"id":"1.168222848","rc":[{"trd":[[1.94,1121.54]],"batb":[[0,1.94,1.13],[2,1.91,5]],"ltp":1.94,"tv":3565.97,"id":9631075},{"batb":[[2,1.97,2]],"batl":[[2,2.14,2.25]],"ltp":2.0,"tv":1252.95,"id":11772759}],"tv":4818.92}]}
{"op":"mcm","clk":"1009765941","pt":1580646784570,"mc":[{"id":"1.168222848","rc":[{"batl":[[0,1.98,7.57],[1,1.99,343.08],[2,2,422.1]],"ltp":1.94,"tv":3565.97,"id":9631075},{"batb":[[0,1.99,52.55]],"ltp":2.0,"tv":1252.95,"id":11772759}]}]}
{"op":"mcm","clk":"1009765996","pt":1580646784992,"mc":[{"id":"1.168222848","rc":[{"batb":[[1,1.98,2]],"ltp":2.0,"tv":1252.95,"id":11772759}]}]}
{"op":"mcm","clk":"1009766535","pt":1580646788686,"mc":[{"id":"1.168222848","rc":[{"batb":[[0,1.94,8.94],[2,1.92,2.19]],"batl":[[0,1.98,15.97]],"ltp":1.94,"tv":3565.97,"id":9631075},{"batb":[[2,1.9,2.53]],"ltp":2.0,"tv":1252.95,"id":11772759}]}]}
{"op":"mcm","clk":"1009766565","pt":1580646788903,"mc":[{"id":"1.168222848","rc":[{"batb":[[0,2.02,8.23],[1,1.99,52.55],[2,1.98,2]],"ltp":2.0,"tv":1252.95,"id":11772759}]}]}
{"op":"mcm","clk":"1009766798","pt":1580646790603,"mc":[{"id":"1.168222848","rc":[{"batb":[[0,1.94,12.13]],"ltp":1.94,"tv":3565.97,"id":9631075},{"batb":[[2,1.9,2.53]],"ltp":2.0,"tv":1252.95,"id":11772759}]}]}
{"op":"mcm","clk":"1009766834","pt":1580646790811,"mc":[{"id":"1.168222848","rc":[{"batb":[[2,1.98,2.26]],"ltp":2.0,"tv":1252.95,"id":11772759}]}]}
{"op":"mcm","clk":"1009786689","pt":1580646939610,"mc":[{"id":"1.168222848","rc":[{"trd":[[1.94,1144.24]],"batb":[[0,1.93,91.76],[1,1.92,2.19],[2,1.91,5.06]],"ltp":1.94,"tv":3588.67,"id":9631075}],"tv":4841.62}]}
{"op":"mcm","clk":"1009786763","pt":1580646940090,"mc":[{"id":"1.168222848","rc":[{"batb":[[1,1.91,5.06],[2,1.9,2.06]],"ltp":1.94,"tv":3588.67,"id":9631075}]}]}
{"op":"mcm","clk":"1009808887","pt":1580647101679,"mc":[{"id":"1.168222848","rc":[{"trd":[[1.98,875.59]],"batb":[[0,1.97,7.61],[1,1.96,2.13],[2,1.95,2.11]],"batl":[[0,1.99,343.08],[1,2,420.1],[2,2.02,422.1]],"ltp":1.98,"tv":3604.64,"id":9631075},{"trd":[[2.02,323.88]],"batb":[[0,1.99,50.55],[1,1.98,2.26],[2,1.97,2.17]],"batl":[[0,2.08,18.71],[1,2.1,2.05],[2,2.28,18.48]],"ltp":2.02,"tv":1296.67,"id":11772759}],"tv":4901.31}]}
{"op":"mcm","clk":"1009808934","pt":1580647101950,"mc":[{"id":"1.168222848","rc":[{"batb":[[1,1.95,2],[2,1.94,2.78]],"ltp":1.98,"tv":3604.64,"id":9631075},{"trd":[[2.02,324.5]],"batl":[[0,2.08,20.4],[2,2.12,2.21]],"ltp":2.02,"tv":1297.29,"id":11772759}],"tv":4901.93}]}
{"op":"mcm","clk":"1009813095","pt":1580647131597,"mc":[{"id":"1.168222848","rc":[{"batb":[[2,1.93,91.76]],"ltp":1.98,"tv":3604.64,"id":9631075},{"batb":[[2,1.9,2.53]],"batl":[[0,2.08,12],[1,2.28,18.48],[2,2.52,15.14]],"ltp":2.02,"tv":1297.29,"id":11772759}]}]}
{"op":"mcm","clk":"1009813173","pt":1580647132136,"mc":[{"id":"1.168222848","rc":[{"trd":[[1.97,304.31]],"batb":[[0,1.97,12.69],[2,1.94,2.87]],"ltp":1.97,"tv":3617.92,"id":9631075},{"batb":[[2,1.97,2]],"batl":[[1,2.1,2.05],[2,2.28,18.48]],"ltp":2.02,"tv":1297.29,"id":11772759}],"tv":4915.21}]}
{"op":"mcm","clk":"1009833044","pt":1580647270669,"mc":[{"id":"1.168222848","rc":[{"trd":[[1.99,361.75]],"batb":[[2,1.93,91.76]],"batl":[[0,1.99,274.29]],"ltp":1.99,"tv":3755.49,"id":9631075},{"batb":[[2,1.9,2.53]],"batl":[[1,2.28,18.48],[2,2.52,15.14]],"ltp":2.02,"tv":1297.29,"id":11772759}],"tv":5052.79}]}
{"op":"mcm","clk":"1009833214","pt":1580647271733,"mc":[{"id":"1.168222848","rc":[{"trd":[[1.97,327.1]],"batb":[[0,1.97,1.29],[1,1.93,93.84],[2,1.92,2.07]],"ltp":1.97,"tv":3778.29,"id":9631075},{"batb":[[2,1.97,2]],"batl":[[1,2.1,2.05],[2,2.28,18.48]],"ltp":2.02,"tv":1297.29,"id":11772759}],"tv":5075.58}]}
{"op":"mcm","clk":"1009833321","pt":1580647272388,"mc":[{"id":"1.168222848","rc":[{"batb":[[1,1.93,91.76],[2,1.91,5.06]],"ltp":1.97,"tv":3778.29,"id":9631075},{"batl":[[0,2.08,10],[1,2.12,2],[2,2.14,2.04]],"ltp":2.02,"tv":1297.29,"id":11772759}]}]}
{"op":"mcm","clk":"1009834445","pt":1580647279565,"mc":[{"id":"1.168222848","rc":[{"trd":[[1.99,429.3]],"batl":[[0,1.99,240.51]],"ltp":1.99,"tv":3845.84,"id":9631075},{"batl":[[2,2.14,2]],"ltp":2.02,"tv":1297.29,"id":11772759}],"tv":5143.14}]}
{"op":"mcm","clk":"1009838096","pt":1580647305606,"mc":[{"id":"1.168222848","rc":[{"trd":[[1.99,454.42]],"batl":[[0,1.99,215.39]],"ltp":1.99,"tv":3870.96,"id":9631075},{"trd":[[2,658.98]],"batb":[[2,1.9,2.53]],"batl":[[2,2.28,18.48]],"ltp":2.0,"tv":1322.29,"id":11772759}],"tv":5193.26}]}
{"op":"mcm","clk":"1009838124","pt":1580647305768,"mc":[{"id":"1.168222848","rc":[{"batb":[[2,1.97,2.17]],"batl":[[2,2.14,2.25]],"ltp":2.0,"tv":1322.29,"id":11772759}]}]}
{"op":"mcm","clk":"1009839853","pt":1580647317685,"mc":[{"id":"1.168222848","rc":[{"batb":[[0,1.93,91.76],[1,1.91,5.06],[2,1.85,331.09]],"ltp":1.99,"tv":3870.96,"id":9631075},{"batb":[[2,1.9,2.53]],"batl":[[0,2.06,8.4],[1,2.08,10],[2,2.12,2]],"ltp":2.0,"tv":1322.29,"id":11772759}]}]}
{"op":"mcm","clk":"1009839991","pt":1580647318589,"mc":[{"id":"1.168222848","rc":[{"batb":[[0,1.94,9.72],[1,1.93,90.98],[2,1.92,2.07]],"batl":[[0,1.98,8.4],[1,1.99,215.39],[2,2,422.1]],"ltp":1.99,"tv":3870.96,"id":9631075},{"batb":[[0,2.02,8.23],[1,1.99,52.55],[2,1.98,2.26]],"batl":[[2,2.1,2.05]],"ltp":2.0,"tv":1322.29,"id":11772759}]}]}
{"op":"mcm","clk":"1009842943","pt":1580647339509,"mc":[{"id":"1.168222848","rc":[{"trd":[[1.98,892.39],[1.99,491.66]],"batl":[[0,1.99,196.77],[1,2,420.1],[2,2.02,422.1]],"ltp":1.99,"tv":3925.01,"id":9631075},{"batb":[[2,1.98,2]],"ltp":2.0,"tv":1322.29,"id":11772759}],"tv":5247.3}]}
{"op":"mcm","clk":"1009843073","pt":1580647340351,"mc":[{"id":"1.168222848","rc":[{"trd":[[2.06,54.26]],"batl":[[0,2.08,10.8],[1,2.12,2.13],[2,2.14,2.25]],"ltp":2.06,"tv":1337.49,"id":11772759}],"tv":5262.5}]}
{"op":"mcm","clk":"1009843389","pt":1580647342662,"mc":[{"id":"1.168222848","rc":[{"batl":[[0,1.98,7.57],[1,1.99,196.77],[2,2,420.1]],"ltp":1.99,"tv":3925.01,"id":9631075}]}]}
{"op":"mcm","clk":"1009843465","pt":1580647343244,"mc":[{"id":"1.168222848","rc":[{"batl":[[2,2,422.1]],"ltp":1.99,"tv":3925.01,"id":9631075}]}]}
{"op":"mcm","clk":"1009844437","pt":1580647350651,"mc":[{"id":"1.168222848","rc":[{"batl":[[0,2.08,10]],"ltp":2.06,"tv":1337.49,"id":11772759}]}]}
{"op":"mcm","clk":"1009844539","pt":1580647351552,"mc":[{"id":"1.168222848","rc":[{"batl":[[0,1.98,15.97]],"ltp":1.99,"tv":3925.01,"id":9631075},{"batb":[[2,1.98,2.26]],"batl":[[0,2.06,8.4],[1,2.08,10],[2,2.1,2.05]],"ltp":2.06,"tv":1337.49,"id":11772759}]}]}
{"op":"mcm","clk":"1009847263","pt":1580647370692,"mc":[{"id":"1.168222848","rc":[{"batl":[[0,2.06,38.4]],"ltp":2.06,"tv":1337.49,"id":11772759}]}]}
{"op":"mcm","clk":"1009847403","pt":1580647371700,"mc":[{"id":"1.168222848","rc":[{"trd":[[2.06,126.56]],"batb":[[2,1.98,2]],"batl":[[0,2.06,2.25]],"ltp":2.06,"tv":1409.79,"id":11772759}],"tv":5334.8}]}
{"op":"mcm","clk":"1009848278","pt":1580647377600,"mc":[{"id":"1.168222848","rc":[{"trd":[[1.98,899.48]],"batl":[[0,1.98,12.43]],"ltp":1.98,"tv":3932.09,"id":9631075},{"batb":[[2,1.9,2.53]],"ltp":2.06,"tv":1409.79,"id":11772759}],"tv":5341.89}]}
{"op":"mcm","clk":"1009848454","pt":1580647378678,"mc":[{"id":"1.168222848","rc":[{"trd":[[1.97,334.22]],"ltp":1.97,"tv":3939.21,"id":9631075},{"batb":[[2,1.98,2]],"ltp":2.06,"tv":1409.79,"id":11772759}],"tv":5349.01}]}
{"op":"mcm","clk":"1009854555","pt":1580647419744,"mc":[{"id":"1.168222848","rc":[{"trd":[[1.98,960.5]],"batb":[[0,1.98,1.42],[1,1.97,4.05],[2,1.96,2.13]],"batl":[[0,1.99,196.77],[1,2,420.1],[2,2.02,422.35]],"ltp":1.98,"tv":4000.23,"id":9631075},{"batb":[[2,1.98,2.26]],"batl":[[1,2.08,12],[2,2.28,18.48]],"ltp":2.06,"tv":1409.79,"id":11772759}],"tv":5410.03}]}
{"op":"mcm","clk":"1009854607","pt":1580647420062,"mc":[{"id":"1.168222848","rc":[{"batb":[[2,1.95,2.11]],"ltp":1.98,"tv":4000.23,"id":9631075},{"batl":[[2,2.1,2.05]],"ltp":2.06,"tv":1409.79,"id":11772759}]}]}
{"op":"mcm","clk":"1009858416","pt":1580647445585,"mc":[{"id":"1.168222848","rc":[{"batb":[[2,1.9,2.53]],"batl":[[2,2.28,18.48]],"ltp":2.06,"tv":1409.79,"id":11772759}]}]}
{"op":"mcm","clk":"1009858445","pt":1580647445834,"mc":[{"id":"1.168222848","rc":[{"batb":[[2,1.98,2]],"batl":[[2,2.1,2.05]],"ltp":2.06,"tv":1409.79,"id":11772759}]}]}
{"op":"mcm","clk":"1009863027","pt":1580647476614,"mc":[{"id":"1.168222848","rc":[{"batb":[[0,1.99,50.55],[1,1.98,2],[2,1.97,2.17]],"batl":[[2,2.28,18.48]],"ltp":2.06,"tv":1409.79,"id":11772759}]}]}
{"op":"mcm","clk":"1009863061","pt":1580647476808,"mc":[{"id":"1.168222848","rc":[{"batl":[[2,2.1,2]],"ltp":2.06,"tv":1409.79,"id":11772759}]}]}
{"op":"mcm","clk":"1009863560","pt":1580647480033,"mc":[{"id":"1.168222848","rc":[{"trd":[[1.99,555.2]],"batl":[[0,1.99,165.01]],"ltp":1.99,"tv":4063.77,"id":9631075}],"tv":5473.57}]}
{"op":"mcm","clk":"1009866059","pt":1580647496720,"mc":[{"id":"1.168222848","rc":[{"trd":[[1.99,558.05]],"batb":[[0,1.97,4.05],[1,1.95,2.11],[2,1.94,2.87]],"batl":[[0,1.99,163.58]],"ltp":1.99,"tv":4066.63,"id":9631075}],"tv":5476.43}]}
{"op":"mcm","clk":"1009871702","pt":1580647533702,"mc":[{"id":"1.168222848","rc":[{"trd":[[1.99,621.59]],"batl":[[0,1.99,131.81]],"ltp":1.99,"tv":4130.17,"id":9631075}],"tv":5539.97}]}
{"op":"mcm","clk":"1009881603","pt":1580647602581,"mc":[{"id":"1.168222848","rc":[{"trd":[[1.99,685.13]],"batl":[[0,1.99,100.04]],"ltp":1.99,"tv":4193.71,"id":9631075},{"batl":[[2,2.1,2.05]],"ltp":2.06,"tv":1409.79,"id":11772759}],"tv":5603.51}]}
{"op":"mcm","clk":"1009884790","pt":1580647625699,"mc":[{"id":"1.168222848","rc":[{"batb":[[0,1.95,2.11],[1,1.94,2.87],[2,1.93,92.98]],"ltp":1.99,"tv":4193.71,"id":9631075}]}]}
{"op":"mcm","clk":"1009884916","pt":1580647626707,"mc":[{"id":"1.168222848","rc":[{"batb":[[0,1.96,4.07],[1,1.93,91.76],[2,1.92,2.19]],"ltp":1.99,"tv":4193.71,"id":9631075},{"batl":[[1,2.08,10]],"ltp":2.06,"tv":1409.79,"id":11772759}]}]}
{"op":"mcm","clk":"1009884956","pt":1580647627022,"mc":[{"id":"1.168222848","rc":[{"batb":[[1,1.94,2.78],[2,1.93,93.06]],"ltp":1.99,"tv":4193.71,"id":9631075}]}]}
{"op":"mcm","clk":"1009885296","pt":1580647629606,"mc":[{"id":"1.168222848","rc":[{"batb":[[0,1.95,4.07],[1,1.93,93.84],[2,1.92,2.19]],"ltp":1.99,"tv":4193.71,"id":9631075}]}]}
{"op":"mcm","clk":"1009889744","pt":1580647660676,"mc":[{"id":"1.168222848","rc":[{"batl":[[0,2.06,10.65]],"ltp":2.06,"tv":1409.79,"id":11772759}]}]}
{"op":"mcm","clk":"1009889924","pt":1580647661752,"mc":[{"id":"1.168222848","rc":[{"batb":[[0,1.95,12.92],[2,1.92,2.07]],"batl":[[0,1.98,8.4],[1,1.99,100.04],[2,2,422.1]],"ltp":1.99,"tv":4193.71,"id":9631075},{"batb":[[0,2.02,8.23],[1,1.99,50.55],[2,1.98,2]],"ltp":2.06,"tv":1409.79,"id":11772759}]}]}
{"op":"mcm","clk":"1009890029","pt":1580647662341,"mc":[{"id":"1.168222848","rc":[{"batb":[[1,1.99,52.55],[2,1.98,2.26]],"ltp":2.06,"tv":1409.79,"id":11772759}]}]}
{"op":"mcm","clk":"1009908462","pt":1580647821750,"mc":[{"id":"1.168222848","rc":[{"trd":[[1.98,962.31]],"batl":[[0,1.98,6.6]],"ltp":1.98,"tv":4195.51,"id":9631075},{"trd":[[2.02,342.74]],"batb":[[0,1.99,52.55],[1,1.98,2.26],[2,1.97,2]],"ltp":2.02,"tv":1428.03,"id":11772759}],"tv":5623.55}]}
{"op":"mcm","clk":"1009908597","pt":1580647822751,"mc":[{"id":"1.168222848","rc":[{"trd":[[1.95,613.14]],"batb":[[0,1.95,1.45],[2,1.92,2]],"ltp":1.95,"tv":4218.46,"id":9631075},{"batb":[[1,1.98,2],[2,1.9,2.53]],"ltp":2.02,"tv":1428.03,"id":11772759}],"tv":5646.49}]}
{"op":"mcm","clk":"1009908632","pt":1580647823067,"mc":[{"id":"1.168222848","rc":[{"batb":[[1,1.93,91.76]],"ltp":1.95,"tv":4218.46,"id":9631075}]}]}
{"op":"mcm","clk":"1009910126","pt":1580647834582,"mc":[{"id":"1.168222848","rc":[{"batb":[[0,1.95,5.54],[1,1.93,93.84],[2,1.91,3]],"ltp":1.95,"tv":4218.46,"id":9631075}]}]}
{"op":"mcm","clk":"1009910154","pt":1580647834773,"mc":[{"id":"1.168222848","rc":[{"batb":[[2,1.92,2.19]],"ltp":1.95,"tv":4218.46,"id":9631075}]}]}
{"op":"mcm","clk":"1009910486","pt":1580647837390,"mc":[{"id":"1.168222848","rc":[{"batl":[[0,1.98,14.17]],"ltp":1.95,"tv":4218.46,"id":9631075}]}]}
{"op":"mcm","clk":"1009912053","pt":1580647850607,"mc":[{"id":"1.168222848","rc":[{"batb":[[0,1.95,12.94]],"ltp":1.95,"tv":4218.46,"id":9631075}]}]}
{"op":"mcm","clk":"1009912122","pt":1580647851214,"mc":[{"id":"1.168222848","rc":[{"batb":[[2,1.92,4.26]],"ltp":1.95,"tv":4218.46,"id":9631075},{"trd":[[2.06,145.68]],"batb":[[1,1.98,4.26]],"batl":[[0,2.06,1.09]],"ltp":2.06,"tv":1447.15,"id":11772759}],"tv":5665.61}]}
{"op":"mcm","clk":"1009913528","pt":1580647863512,"mc":[{"id":"1.168222848","rc":[{"batb":[[0,1.95,8.85],[2,1.92,2.19]],"batl":[[0,1.98,6.6]],"ltp":1.95,"tv":4218.46,"id":9631075},{"batb":[[1,1.98,2]],"ltp":2.06,"tv":1447.15,"id":11772759}]}]}
{"op":"mcm","clk":"1009913765","pt":1580647865431,"mc":[{"id":"1.168222848","rc":[{"batb":[[0,1.95,8.87]],"ltp":1.95,"tv":4218.46,"id":9631075}]}]}
{"op":"mcm","clk":"1009914388","pt":1580647870736,"mc":[{"id":"1.168222848","rc":[{"batb":[[2,1.91,3]],"batl":[[0,1.98,14.17]],"ltp":1.95,"tv":4218.46,"id":9631075},{"batb":[[1,1.9,2.53],[2,1.81,37.86]],"ltp":2.06,"tv":1447.15,"id":11772759}]}]}
{"op":"mcm","clk":"1009914438","pt":1580647871214,"mc":[{"id":"1.168222848","rc":[{"trd":[[1.95,628.4],[1.96,87.63]],"batb":[[0,1.95,1.22],[1,1.93,91.76],[2,1.91,5.06]],"ltp":1.95,"tv":4233.76,"id":9631075},{"batb":[[1,1.98,2.26],[2,1.9,2.53]],"ltp":2.06,"tv":1447.15,"id":11772759}],"tv":5680.91}]}
{"op":"mcm","clk":"1009914776","pt":1580647874141,"mc":[{"id":"1.168222848","rc":[{"batl":[[0,1.98,21.74]],"ltp":1.95,"tv":4233.76,"id":9631075}]}]}
{"op":"mcm","clk":"1009915684","pt":1580647882758,"mc":[{"id":"1.168222848","rc":[{"batb":[[0,1.93,91.76],[1,1.91,5.06],[2,1.9,2.06]],"ltp":1.95,"tv":4233.76,"id":9631075},{"batb":[[1,1.98,2]],"batl":[[0,2.08,10],[1,2.12,2],[2,2.14,2.25]],"ltp":2.06,"tv":1447.15,"id":11772759}]}]}
{"op":"mcm","clk":"1009915701","pt":1580647882867,"mc":[{"id":"1.168222848","rc":[{"batb":[[0,2.02,12.36],[1,1.99,52.55],[2,1.98,2]],"ltp":2.06,"tv":1447.15,"id":11772759}]}]}
{"op":"mcm","clk":"1009921706","pt":1580647936725,"mc":[{"id":"1.168222848","rc":[{"batl":[[0,1.98,29.31]],"ltp":1.95,"tv":4233.76,"id":9631075},{"batl":[[2,2.14,2.11]],"ltp":2.06,"tv":1447.15,"id":11772759}]}]}
{"op":"mcm","clk":"1009921894","pt":1580647938435,"mc":[{"id":"1.168222848","rc":[{"batl":[[0,1.98,36.88]],"ltp":1.95,"tv":4233.76,"id":9631075}]}]}
{"op":"mcm","clk":"1009922163","pt":1580647941051,"mc":[{"id":"1.168222848","rc":[{"batl":[[0,1.98,6.6]],"ltp":1.95,"tv":4233.76,"id":9631075}]}]}
{"op":"mcm","clk":"1009922332","pt":1580647942740,"mc":[{"id":"1.168222848","rc":[{"batl":[[0,1.97,7.57],[1,1.98,6.6],[2,1.99,100.04]],"ltp":1.95,"tv":4233.76,"id":9631075}]}]}
{"op":"mcm","clk":"1009922418","pt":1580647943541,"mc":[{"id":"1.168222848","rc":[{"batb":[[2,1.9,2]],"batl":[[2,1.99,102.3]],"ltp":1.95,"tv":4233.76,"id":9631075},{"batb":[[2,1.98,2.26]],"ltp":2.06,"tv":1447.15,"id":11772759}]}]}
{"op":"mcm","clk":"1009922532","pt":1580647944653,"mc":[{"id":"1.168222848","rc":[{"batl":[[0,1.98,6.6],[1,1.99,102.3],[2,2,422.1]],"ltp":1.95,"tv":4233.76,"id":9631075}]}]}
{"op":"mcm","clk":"1009922638","pt":1580647945547,"mc":[{"id":"1.168222848","rc":[{"batl":[[0,1.97,12.6],[1,1.98,7.57],[2,1.99,102.16]],"ltp":1.95,"tv":4233.76,"id":9631075}]}]}
{"op":"mcm","clk":"1009924978","pt":1580647966599,"mc":[{"id":"1.168222848","rc":[{"batl":[[0,1.97,432.7]],"ltp":1.95,"tv":4233.76,"id":9631075}]}]}
{"op":"mcm","clk":"1009925038","pt":1580647967094,"mc":[{"id":"1.168222848","rc":[{"batb":[[2,1.9,2.06]],"ltp":1.95,"tv":4233.76,"id":9631075},{"batl":[[2,2.14,2.25]],"ltp":2.06,"tv":1447.15,"id":11772759}]}]}
{"op":"mcm","clk":"1009925262","pt":1580647968880,"mc":[{"id":"1.168222848","rc":[{"batl":[[1,1.98,427.67]],"ltp":1.95,"tv":4233.76,"id":9631075}]}]}
{"op":"mcm","clk":"1009925509","pt":1580647971293,"mc":[{"id":"1.168222848","rc":[{"batl":[[2,1.99,522.26]],"ltp":1.95,"tv":4233.76,"id":9631075}]}]}
{"op":"mcm","clk":"1009927022","pt":1580647984703,"mc":[{"id":"1.168222848","rc":[{"trd":[[1.97,350.22]],"batl":[[0,1.97,424.7]],"ltp":1.97,"tv":4249.76,"id":9631075}],"tv":5696.91}]}
{"op":"mcm","clk":"1009927086","pt":1580647985225,"mc":[{"id":"1.168222848","rc":[{"batb":[[2,1.98,2]],"ltp":2.06,"tv":1447.15,"id":11772759}]}]}
{"op":"mcm","clk":"1009928112","pt":1580647994643,"mc":[{"id":"1.168222848","rc":[{"trd":[[1.97,414.42]],"batl":[[0,1.97,392.61]],"ltp":1.97,"tv":4313.96,"id":9631075}],"tv":5761.11}]}
{"op":"mcm","clk":"1009929694","pt":1580648008640,"mc":[{"id":"1.168222848","rc":[{"batb":[[0,1.94,9.72],[1,1.93,90.98],[2,1.92,2.19]],"ltp":1.97,"tv":4313.96,"id":9631075},{"batb":[[2,1.98,2.26]],"ltp":2.06,"tv":1447.15,"id":11772759}]}]}
{"op":"mcm","clk":"1009935883","pt":1580648064511,"mc":[{"id":"1.168222848","rc":[{"trd":[[1.97,450.08]],"batl":[[0,1.97,374.78]],"ltp":1.97,"tv":4349.61,"id":9631075}],"tv":5796.77}]}
{"op":"mcm","clk":"1009936029","pt":1580648065683,"mc":[{"id":"1.168222848","rc":[{"trd":[[1.94,1161.5]],"batb":[[0,1.94,1.09],[1,1.93,72.99],[2,1.91,5.06]],"ltp":1.94,"tv":4366.87,"id":9631075},{"batb":[[1,1.99,70.05],[2,1.98,2]],"ltp":2.06,"tv":1447.15,"id":11772759}],"tv":5814.02}]}
{"op":"mcm","clk":"1009936549","pt":1580648070719,"mc":[{"id":"1.168222848","rc":[{"batl":[[0,1.96,8.4],[1,1.97,374.78],[2,1.98,429.92]],"ltp":1.94,"tv":4366.87,"id":9631075},{"batb":[[1,2,2],[2,1.99,70.05]],"batl":[[2,2.28,18.48]],"ltp":2.06,"tv":1447.15,"id":11772759}]}]}
{"op":"mcm","clk":"1009936597","pt":1580648071092,"mc":[{"id":"1.168222848","rc":[{"batl":[[2,2.14,2.25]],"ltp":2.06,"tv":1447.15,"id":11772759}]}]}
{"op":"mcm","clk":"1009937223","pt":1580648077511,"mc":[{"id":"1.168222848","rc":[{"batb":[[0,1.94,8.66],[2,1.92,2.07]],"ltp":1.94,"tv":4366.87,"id":9631075},{"batl":[[2,2.14,2.04]],"ltp":2.06,"tv":1447.15,"id":11772759}]}]}
{"op":"mcm","clk":"1009938870","pt":1580648093759,"mc":[{"id":"1.168222848","rc":[{"trd":[[1.94,1176.84]],"batb":[[0,1.93,73.98],[1,1.91,3],[2,1.9,2.06]],"batl":[[0,1.96,11.56]],"ltp":1.94,"tv":4382.21,"id":9631075},{"batb":[[2,1.99,68.05]],"batl":[[2,2.28,18.48]],"ltp":2.06,"tv":1447.15,"id":11772759}],"tv":5829.37}]}
{"op":"mcm","clk":"1009938990","pt":1580648094721,"mc":[{"id":"1.168222848","rc":[{"batb":[[1,1.91,5.06]],"batl":[[0,1.95,6.55],[1,1.96,11.56],[2,1.97,376.85]],"ltp":1.94,"tv":4382.21,"id":9631075},{"batb":[[2,1.99,70.05]],"batl":[[2,2.14,2]],"ltp":2.06,"tv":1447.15,"id":11772759}]}]}
{"op":"mcm","clk":"1009939260","pt":1580648097026,"mc":[{"id":"1.168222848","rc":[{"batb":[[0,1.93,81.55]],"ltp":1.94,"tv":4382.21,"id":9631075}]}]}
{"op":"mcm","clk":"1009939415","pt":1580648098537,"mc":[{"id":"1.168222848","rc":[{"batb":[[0,1.93,80.56]],"ltp":1.94,"tv":4382.21,"id":9631075}]}]}
{"op":"mcm","clk":"1009939457","pt":1580648099018,"mc":[{"id":"1.168222848","rc":[{"batl":[[2,2.14,2.25]],"ltp":2.06,"tv":1447.15,"id":11772759}]}]}
{"op":"mcm","clk":"1009939778","pt":1580648101624,"mc":[{"id":"1.168222848","rc":[{"batl":[[1,1.96,3.16]],"ltp":1.94,"tv":4382.21,"id":9631075}]}]}
{"op":"mcm","clk":"1009939809","pt":1580648101833,"mc":[{"id":"1.168222848","rc":[{"batb":[[0,2,2],[1,1.99,70.05],[2,1.9,2.53]],"ltp":2.06,"tv":1447.15,"id":11772759}]}]}
{"op":"mcm","clk":"1009948978","pt":1580648176720,"mc":[{"id":"1.168222848","rc":[{"trd":[[1.95,666.07]],"batb":[[0,1.95,1.3],[1,1.93,82.64],[2,1.92,2]],"batl":[[0,1.96,3.16],[1,1.97,374.78],[2,1.98,422.35]],"ltp":1.95,"tv":4419.89,"id":9631075},{"trd":[[2.06,168.94]],"batb":[[1,1.99,68.05]],"batl":[[2,2.28,18.48]],"ltp":2.06,"tv":1470.41,"id":11772759}],"tv":5890.31}]}
{"op":"mcm","clk":"1009949043","pt":1580648177315,"mc":[{"id":"1.168222848","rc":[{"trd":[[1.95,668.68]],"batb":[[0,1.93,80.56],[1,1.91,5.06],[2,1.9,2.06]],"ltp":1.95,"tv":4422.5,"id":9631075},{"batb":[[1,1.99,70.05]],"batl":[[2,2.14,2.18]],"ltp":2.06,"tv":1470.41,"id":11772759}],"tv":5892.91}]}
{"op":"mcm","clk":"1009949400","pt":1580648180410,"mc":[{"id":"1.168222848","rc":[{"batb":[[0,1.94,7.57],[1,1.93,80.56],[2,1.92,2.19]],"ltp":1.95,"tv":4422.5,"id":9631075}]}]}
{"op":"mcm","clk":"1009951397","pt":1580648198728,"mc":[{"id":"1.168222848","rc":[{"trd":[[1.96,93.95]],"batl":[[0,1.97,374.78],[1,1.98,420.1],[2,1.99,522.41]],"ltp":1.96,"tv":4428.82,"id":9631075},{"batb":[[1,1.99,68.05]],"batl":[[2,2.28,18.48]],"ltp":2.06,"tv":1470.41,"id":11772759}],"tv":5899.23}]}
{"op":"mcm","clk":"1009951505","pt":1580648199618,"mc":[{"id":"1.168222848","rc":[{"trd":[[1.94,1190.27]],"batb":[[0,1.93,78.23],[1,1.91,5.06],[2,1.9,2.06]],"batl":[[0,1.95,6.68],[1,1.97,376.84],[2,1.98,422.18]],"ltp":1.94,"tv":4442.25,"id":9631075},{"batb":[[0,2.02,20.74],[1,2,2],[2,1.99,2]],"batl":[[2,2.14,2.25]],"ltp":2.06,"tv":1470.41,"id":11772759}],"tv":5912.67}]}
{"op":"mcm","clk":"1009951915","pt":1580648203633,"mc":[{"id":"1.168222848","rc":[{"batb":[[0,1.93,77.38]],"ltp":1.94,"tv":4442.25,"id":9631075}]}]}
{"op":"mcm","clk":"1009954475","pt":1580648224684,"mc":[{"id":"1.168222848","rc":[{"trd":[[1.95,682.04]],"batb":[[0,1.95,25.75],[1,1.93,79.46],[2,1.92,2]],"batl":[[0,1.97,374.78],[1,1.98,420.1],[2,1.99,522.21]],"ltp":1.95,"tv":4455.61,"id":9631075},{"batb":[[1,1.99,2],[2,1.98,2.26]],"batl":[[1,2.1,2.05],[2,2.12,2]],"ltp":2.06,"tv":1470.41,"id":11772759}],"tv":5926.03}]}
{"op":"mcm","clk":"1009954552","pt":1580648225264,"mc":[{"id":"1.168222848","rc":[{"trd":[[1.95,730.08]],"batb":[[0,1.95,1.73],[1,1.93,77.38],[2,1.91,5.06]],"ltp":1.95,"tv":4503.65,"id":9631075},{"batl":[[1,2.12,2.21],[2,2.14,2.25]],"ltp":2.06,"tv":1470.41,"id":11772759}],"tv":5974.07}]}
{"op":"mcm","clk":"1009954968","pt":1580648228071,"mc":[{"id":"1.168222848","rc":[{"batb":[[1,1.94,7.57],[2,1.93,77.38]],"ltp":1.95,"tv":4503.65,"id":9631075}]}]}
{"op":"mcm","clk":"1009955335","pt":1580648230362,"mc":[{"id":"1.168222848","rc":[{"batb":[[2,1.93,69.8]],"ltp":1.95,"tv":4503.65,"id":9631075}]}]}
{"op":"mcm","clk":"1009955499","pt":1580648231574,"mc":[{"id":"1.168222848","rc":[{"batb":[[2,1.98,2]],"ltp":2.06,"tv":1470.41,"id":11772759}]}]}
{"op":"mcm","clk":"1009957763","pt":1580648248758,"mc":[{"id":"1.168222848","rc":[{"batb":[[0,1.95,4.89],[2,1.93,71.88]],"ltp":1.95,"tv":4503.65,"id":9631075},{"batb":[[2,1.9,2.53]],"batl":[[1,2.1,2.05],[2,2.12,2.21]],"ltp":2.06,"tv":1470.41,"id":11772759}]}]}
{"op":"mcm","clk":"1009957805","pt":1580648249180,"mc":[{"id":"1.168222848","rc":[{"batb":[[2,1.98,2]],"ltp":2.06,"tv":1470.41,"id":11772759}]}]}
{"op":"mcm","clk":"1009963751","pt":1580648298731,"mc":[{"id":"1.168222848","rc":[{"batb":[[0,1.96,32.1],[1,1.95,4.89],[2,1.94,9.66]],"ltp":1.95,"tv":4503.65,"id":9631075},{"batb":[[2,1.9,2.53]],"batl":[[2,2.28,18.48]],"ltp":2.06,"tv":1470.41,"id":11772759}]}]}
{"op":"mcm","clk":"1009963804","pt":1580648299147,"mc":[{"id":"1.168222848","rc":[{"trd":[[1.96,155.49]],"batb":[[0,1.96,1.33]],"ltp":1.96,"tv":4565.19,"id":9631075},{"batb":[[2,1.98,2]],"batl":[[2,2.12,2.13]],"ltp":2.06,"tv":1470.41,"id":11772759}],"tv":6035.61}]}
{"op":"mcm","clk":"1009963977","pt":1580648300417,"mc":[{"id":"1.168222848","rc":[{"batb":[[2,1.94,7.57]],"ltp":1.96,"tv":4565.19,"id":9631075}]}]}
{"op":"mcm","clk":"1009964838","pt":1580648306759,"mc":[{"id":"1.168222848","rc":[{"trd":[[1.95,738.96],[1.96,158.15]],"batb":[[0,1.94,8.02],[1,1.93,69.8],[2,1.92,2.19]],"ltp":1.95,"tv":4576.74,"id":9631075},{"batl":[[1,2.12,2.05],[2,2.14,2.25]],"ltp":2.06,"tv":1470.41,"id":11772759}],"tv":6047.16}]}
{"op":"mcm","clk":"1009966241","pt":1580648317756,"mc":[{"id":"1.168222848","rc":[{"batl":[[0,1.96,8.4],[1,1.97,374.78],[2,1.98,422.35]],"ltp":1.95,"tv":4576.74,"id":9631075},{"batb":[[0,2.04,8.08],[1,2.02,20.74],[2,2,2]],"batl":[[2,2.14,2.11]],"ltp":2.06,"tv":1470.41,"id":11772759}]}]}
{"op":"mcm","clk":"1009969955","pt":1580648348587,"mc":[{"id":"1.168222848","rc":[{"batl":[[0,1.97,374.78],[1,1.98,422.35],[2,1.99,522.34]],"ltp":1.95,"tv":4576.74,"id":9631075}]}]}
{"op":"mcm","clk":"1009970100","pt":1580648349698,"mc":[{"id":"1.168222848","rc":[{"trd":[[1.94,1204.75],[1.95,739.86]],"batb":[[0,1.93,70.14],[1,1.91,5.06],[2,1.9,2.06]],"batl":[[0,1.95,7.2],[1,1.97,374.78],[2,1.98,420.1]],"ltp":1.94,"tv":4592.12,"id":9631075},{"batl":[[2,2.14,2.04]],"ltp":2.06,"tv":1470.41,"id":11772759}],"tv":6062.54}]}
{"op":"mcm","clk":"1009970153","pt":1580648350084,"mc":[{"id":"1.168222848","rc":[{"batl":[[1,1.97,376.94],[2,1.98,422.35]],"ltp":1.94,"tv":4592.12,"id":9631075}]}]}
{"op":"mcm","clk":"1009973116","pt":1580648372628,"mc":[{"id":"1.168222848","rc":[{"batb":[[2,1.85,331.09]],"batl":[[1,1.97,380.07],[2,1.98,420.1]],"ltp":1.94,"tv":4592.12,"id":9631075},{"batl":[[2,2.28,18.48]],"ltp":2.06,"tv":1470.41,"id":11772759}]}]}
{"op":"mcm","clk":"1009973150","pt":1580648372848,"mc":[{"id":"1.168222848","rc":[{"batb":[[2,1.9,2.06]],"batl":[[2,1.98,422.35]],"ltp":1.94,"tv":4592.12,"id":9631075},{"batl":[[2,2.14,2.04]],"ltp":2.06,"tv":1470.41,"id":11772759}]}]}
{"op":"mcm","clk":"1009974280","pt":1580648380450,"mc":[{"id":"1.168222848","rc":[{"batl":[[0,1.95,15.6]],"ltp":1.94,"tv":4592.12,"id":9631075},{"batl":[[2,2.14,2.25]],"ltp":2.06,"tv":1470.41,"id":11772759}]}]}
{"op":"mcm","clk":"1009976907","pt":1580648397567,"mc":[{"id":"1.168222848","rc":[{"batb":[[2,1.85,52.25]],"batl":[[2,1.98,420.1]],"ltp":1.94,"tv":4592.12,"id":9631075},{"batl":[[2,2.28,18.48]],"ltp":2.06,"tv":1470.41,"id":11772759}]}]}
{"op":"mcm","clk":"1009976964","pt":1580648397776,"mc":[{"id":"1.168222848","rc":[{"batb":[[2,1.9,2.06]],"batl":[[2,1.98,422.26]],"ltp":1.94,"tv":4592.12,"id":9631075},{"batl":[[2,2.14,2.11]],"ltp":2.06,"tv":1470.41,"id":11772759}]}]}
{"op":"mcm","clk":"1009978207","pt":1580648404573,"mc":[{"id":"1.168222848","rc":[{"batb":[[0,1.94,5.65],[1,1.93,69.8],[2,1.92,2.07]],"batl":[[2,1.98,422.19]],"ltp":1.94,"tv":4592.12,"id":9631075},{"batl":[[2,2.14,2.25]],"ltp":2.06,"tv":1470.41,"id":11772759}]}]}
{"op":"mcm","clk":"1009980556","pt":1580648418190,"mc":[{"id":"1.168222848","rc":[{"batl":[[2,1.98,422.21]],"ltp":1.94,"tv":4592.12,"id":9631075},{"batl":[[2,2.14,2.18]],"ltp":2.06,"tv":1470.41,"id":11772759}]}]}
{"op":"mcm","clk":"1009986340","pt":1580648452547,"mc":[{"id":"1.168222848","rc":[{"batl":[[2,1.98,420.1]],"ltp":1.94,"tv":4592.12,"id":9631075},{"batl":[[0,2.06,30],[1,2.08,10],[2,2.1,2.05]],"ltp":2.06,"tv":1470.41,"id":11772759}]}]}
{"op":"mcm","clk":"1009986511","pt":1580648453647,"mc":[{"id":"1.168222848","rc":[{"batl":[[2,1.98,422.35]],"ltp":1.94,"tv":4592.12,"id":9631075},{"trd":[[2.06,226.74]],"batl":[[0,2.06,1.1],[2,2.12,2.21]],"ltp":2.06,"tv":1528.21,"id":11772759}],"tv":6120.34}]}
{"op":"mcm","clk":"1009989807","pt":1580648473642,"mc":[{"id":"1.168222848","rc":[{"trd":[[1.95,771.07]],"batl":[[0,1.97,377.91],[1,1.98,420.1],[2,1.99,522.35]],"ltp":1.95,"tv":4623.32,"id":9631075}],"tv":6151.54}]}
{"op":"mcm","clk":"1009990347","pt":1580648476658,"mc":[{"id":"1.168222848","rc":[{"batb":[[1,1.92,75.29],[2,1.91,5.06]],"ltp":1.95,"tv":4623.32,"id":9631075},{"batb":[[1,2.02,35.73]],"ltp":2.06,"tv":1528.21,"id":11772759}]}]}
{"op":"mcm","clk":"1009991177","pt":1580648481737,"mc":[{"id":"1.168222848","rc":[{"batl":[[0,2.06,31.1],[2,2.1,2.05]],"ltp":2.06,"tv":1528.21,"id":11772759}]}]}
{"op":"mcm","clk":"1009991311","pt":1580648482542,"mc":[{"id":"1.168222848","rc":[{"batb":[[2,1.91,5]],"ltp":1.95,"tv":4623.32,"id":9631075}]}]}
{"op":"mcm","clk":"1009999270","pt":1580648535710,"mc":[{"id":"1.168222848","rc":[{"batb":[[0,2.02,35.73],[1,2,2],[2,1.99,2]],"ltp":2.06,"tv":1528.21,"id":11772759}]}]}
{"op":"mcm","clk":"1009999414","pt":1580648536759,"mc":[{"id":"1.168222848","rc":[{"batb":[[2,1.91,5.06]],"ltp":1.95,"tv":4623.32,"id":9631075},{"trd":[[2.06,286.52]],"batb":[[1,1.99,2],[2,1.98,2]],"batl":[[0,2.06,1.21],[2,2.12,2.13]],"ltp":2.06,"tv":1587.99,"id":11772759}],"tv":6211.32}]}
{"op":"mcm","clk":"1010002617","pt":1580648557747,"mc":[{"id":"1.168222848","rc":[{"batb":[[2,1.91,5]],"ltp":1.95,"tv":4623.32,"id":9631075}]}]}
{"op":"mcm","clk":"1010069143","pt":1580648977487,"mc":[{"id":"1.168222848","rc":[{"trd":[[2.02,346.74]],"batb":[[0,2.02,33.73]],"ltp":2.02,"tv":1591.99,"id":11772759}],"tv":6215.32}]}
{"op":"mcm","clk":"1010069231","pt":1580648978117,"mc":[{"id":"1.168222848","rc":[{"batb":[[1,1.92,77.37],[2,1.91,5.06]],"ltp":1.95,"tv":4623.32,"id":9631075}]}]}
{"op":"mcm","clk":"1010177488","pt":1580649634684,"mc":[{"id":"1.168222848","rc":[{"trd":[[1.94,1230.11]],"batb":[[0,1.92,77.91],[1,1.91,3],[2,1.87,28.97]],"ltp":1.94,"tv":4648.68,"id":9631075},{"batb":[[2,1.97,25.99]],"ltp":2.02,"tv":1591.99,"id":11772759}],"tv":6240.68}]}
{"op":"mcm","clk":"1010177665","pt":1580649635708,"mc":[{"id":"1.168222848","rc":[{"batb":[[0,1.92,75.84],[2,1.9,2]],"batl":[[0,1.95,6.99],[1,1.97,380.07],[2,1.98,422.35]],"ltp":1.94,"tv":4648.68,"id":9631075},{"trd":[[2.06,288.94]],"batb":[[1,2,2],[2,1.98,2]],"batl":[[0,2.08,10],[1,2.12,2.13],[2,2.14,2.25]],"ltp":2.06,"tv":1594.41,"id":11772759}],"tv":6243.1}]}
{"op":"mcm","clk":"1010177826","pt":1580649636661,"mc":[{"id":"1.168222848","rc":[{"batb":[[0,1.92,75.3]],"ltp":1.94,"tv":4648.68,"id":9631075},{"batb":[[2,1.99,2]],"ltp":2.06,"tv":1594.41,"id":11772759}]}]}
{"op":"mcm","clk":"1010177839","pt":1580649636779,"mc":[{"id":"1.168222848","rc":[{"batl":[[0,1.95,7.32]],"ltp":1.94,"tv":4648.68,"id":9631075}]}]}
{"op":"mcm","clk":"1010178233","pt":1580649639383,"mc":[{"id":"1.168222848","rc":[{"batl":[[0,1.97,377.91],[1,1.98,420.1],[2,1.99,522.26]],"ltp":1.94,"tv":4648.68,"id":9631075},{"batb":[[1,1.99,2],[2,1.98,2]],"ltp":2.06,"tv":1594.41,"id":11772759}]}]}
{"op":"mcm","clk":"1010178593","pt":1580649641674,"mc":[{"id":"1.168222848","rc":[{"batl":[[0,1.96,14.86],[1,1.97,377.91],[2,1.98,422.35]],"ltp":1.94,"tv":4648.68,"id":9631075},{"batb":[[1,2,2],[2,1.97,25.99]],"ltp":2.06,"tv":1594.41,"id":11772759}]}]}
{"op":"mcm","clk":"1010178624","pt":1580649641888,"mc":[{"id":"1.168222848","rc":[{"batb":[[2,1.99,2]],"ltp":2.06,"tv":1594.41,"id":11772759}]}]}
{"op":"mcm","clk":"1010179841","pt":1580649649619,"mc":[{"id":"1.168222848","rc":[{"batb":[[0,1.93,7.57],[1,1.92,75.3],[2,1.91,5.06]],"ltp":1.94,"tv":4648.68,"id":9631075},{"batb":[[2,1.97,25.99]],"batl":[[2,2.28,18.48]],"ltp":2.06,"tv":1594.41,"id":11772759}]}]}
{"op":"mcm","clk":"1010179965","pt":1580649650327,"mc":[{"id":"1.168222848","rc":[{"batb":[[2,1.99,2]],"batl":[[2,2.14,2.25]],"ltp":2.06,"tv":1594.41,"id":11772759}]}]}
{"op":"mcm","clk":"1010183639","pt":1580649674748,"mc":[{"id":"1.168222848","rc":[{"trd":[[1.96,187.88],[1.97,619.33]],"batl":[[0,1.97,293.28],[1,1.98,420.1],[2,1.99,522.55]],"ltp":1.97,"tv":4847.67,"id":9631075},{"batb":[[1,1.98,2],[2,1.97,25.99]],"batl":[[2,2.28,18.48]],"ltp":2.06,"tv":1594.41,"id":11772759}],"tv":6442.08}]}
{"op":"mcm","clk":"1010183743","pt":1580649675465,"mc":[{"id":"1.168222848","rc":[{"batb":[[0,1.95,7.61],[1,1.93,9.65],[2,1.92,77.49]],"ltp":1.97,"tv":4847.67,"id":9631075},{"batb":[[1,1.99,2],[2,1.98,2]],"batl":[[1,2.1,2.05],[2,2.12,2.05]],"ltp":2.06,"tv":1594.41,"id":11772759}]}]}
{"op":"mcm","clk":"1010184217","pt":1580649678653,"mc":[{"id":"1.168222848","rc":[{"batb":[[0,1.93,9.65],[1,1.92,77.49],[2,1.91,3]],"ltp":1.97,"tv":4847.67,"id":9631075}]}]}
{"op":"mcm","clk":"1010184276","pt":1580649679075,"mc":[{"id":"1.168222848","rc":[{"batb":[[0,1.93,7.57],[1,1.92,75.3],[2,1.91,5.06]],"ltp":1.97,"tv":4847.67,"id":9631075},{"batl":[[1,2.12,2.05],[2,2.14,2.11]],"ltp":2.06,"tv":1594.41,"id":11772759}]}]}
{"op":"mcm","clk":"1010184478","pt":1580649680365,"mc":[{"id":"1.168222848","rc":[{"batb":[[0,1.92,75.3],[1,1.91,3],[2,1.9,2.06]],"ltp":1.97,"tv":4847.67,"id":9631075}]}]}
{"op":"mcm","clk":"1010184653","pt":1580649681656,"mc":[{"id":"1.168222848","rc":[{"trd":[[1.95,786.29]],"batb":[[0,1.93,2.08],[1,1.92,77.49],[2,1.91,3]],"ltp":1.95,"tv":4862.89,"id":9631075},{"batb":[[2,1.97,25.99]],"batl":[[2,2.28,18.48]],"ltp":2.06,"tv":1594.41,"id":11772759}],"tv":6457.3}]}
{"op":"mcm","clk":"1010184787","pt":1580649682348,"mc":[{"id":"1.168222848","rc":[{"batb":[[0,1.92,75.3],[1,1.91,3],[2,1.9,2.06]],"ltp":1.95,"tv":4862.89,"id":9631075},{"batb":[[2,1.98,2.26]],"batl":[[2,2.14,2.25]],"ltp":2.06,"tv":1594.41,"id":11772759}]}]}
{"op":"mcm","clk":"1010185167","pt":1580649684577,"mc":[{"id":"1.168222848","rc":[{"batl":[[0,1.96,15.14],[1,1.97,293.28],[2,1.98,422.35]],"ltp":1.95,"tv":4862.89,"id":9631075},{"batb":[[1,2,2],[2,1.99,2]],"ltp":2.06,"tv":1594.41,"id":11772759}]}]}
{"op":"mcm","clk":"1010185627","pt":1580649687298,"mc":[{"id":"1.168222848","rc":[{"batb":[[0,1.93,7.57],[1,1.92,75.3],[2,1.91,5.06]],"ltp":1.95,"tv":4862.89,"id":9631075}]}]}
{"op":"mcm","clk":"1010190081","pt":1580649717681,"mc":[{"id":"1.168222848","rc":[{"batb":[[2,1.97,25.99]],"batl":[[2,2.28,18.48]],"ltp":2.06,"tv":1594.41,"id":11772759}]}]}
{"op":"mcm","clk":"1010190217","pt":1580649718483,"mc":[{"id":"1.168222848","rc":[{"trd":[[1.96,189.43]],"batl":[[0,1.96,14.11]],"ltp":1.96,"tv":4864.43,"id":9631075},{"trd":[[2.04,202.47]],"batb":[[2,1.99,2]],"batl":[[2,2.14,2.25]],"ltp":2.04,"tv":1594.92,"id":11772759}],"tv":6459.36}]}
{"op":"mcm","clk":"1010190525","pt":1580649720681,"mc":[{"id":"1.168222848","rc":[{"trd":[[1.95,787.3]],"ltp":1.95,"tv":4865.45,"id":9631075}],"tv":6460.38}]}
{"op":"mcm","clk":"1010190557","pt":1580649720895,"mc":[{"id":"1.168222848","rc":[{"trd":[[1.95,788.36]],"ltp":1.95,"tv":4866.51,"id":9631075}],"tv":6461.44}]}
{"op":"mcm","clk":"1010190880","pt":1580649723126,"mc":[{"id":"1.168222848","rc":[{"batl":[[0,1.96,21.68]],"ltp":1.95,"tv":4866.51,"id":9631075}]}]}
{"op":"mcm","clk":"1010191112","pt":1580649724627,"mc":[{"id":"1.168222848","rc":[{"batb":[[2,1.98,25.72]],"batl":[[2,2.28,18.48]],"ltp":2.04,"tv":1594.92,"id":11772759}]}]}
{"op":"mcm","clk":"1010191138","pt":1580649724862,"mc":[{"id":"1.168222848","rc":[{"batb":[[2,1.99,2]],"batl":[[2,2.14,2.25]],"ltp":2.04,"tv":1594.92,"id":11772759}]}]}
{"op":"mcm","clk":"1010192011","pt":1580649730728,"mc":[{"id":"1.168222848","rc":[{"batb":[[0,1.94,7.57],[1,1.93,7.57],[2,1.92,77.37]],"ltp":1.95,"tv":4866.51,"id":9631075}]}]}
{"op":"mcm","clk":"1010192420","pt":1580649733532,"mc":[{"id":"1.168222848","rc":[{"batb":[[0,1.93,7.57],[1,1.92,75.3],[2,1.91,5.06]],"ltp":1.95,"tv":4866.51,"id":9631075}]}]}
{"op":"mcm","clk":"1010193066","pt":1580649737654,"mc":[{"id":"1.168222848","rc":[{"batl":[[0,1.97,293.28],[1,1.98,420.1],[2,1.99,522.25]],"ltp":1.95,"tv":4866.51,"id":9631075},{"batb":[[2,1.98,25.72]],"batl":[[2,2.28,18.48]],"ltp":2.04,"tv":1594.92,"id":11772759}]}]}
{"op":"mcm","clk":"1010193197","pt":1580649738433,"mc":[{"id":"1.168222848","rc":[{"batl":[[0,1.96,7.57],[1,1.97,293.28],[2,1.98,422.3]],"ltp":1.95,"tv":4866.51,"id":9631075},{"batb":[[2,1.99,2]],"batl":[[2,2.14,2.04]],"ltp":2.04,"tv":1594.92,"id":11772759}]}]}
{"op":"mcm","clk":"1010193374","pt":1580649739720,"mc":[{"id":"1.168222848","rc":[{"batl":[[0,1.96,22.72]],"ltp":1.95,"tv":4866.51,"id":9631075}]}]}
{"op":"mcm","clk":"1010193626","pt":1580649741531,"mc":[{"id":"1.168222848","rc":[{"batl":[[0,1.97,293.28],[1,1.98,422.3],[2,1.99,522.47]],"ltp":1.95,"tv":4866.51,"id":9631075}]}]}
{"op":"mcm","clk":"1010193750","pt":1580649742333,"mc":[{"id":"1.168222848","rc":[{"batl":[[0,1.96,7.57],[1,1.97,293.28],[2,1.98,422.35]],"ltp":1.95,"tv":4866.51,"id":9631075}]}]}
{"op":"mcm","clk":"1010194064","pt":1580649744647,"mc":[{"id":"1.168222848","rc":[{"batb":[[0,1.92,75.3],[1,1.91,3],[2,1.9,2.06]],"ltp":1.95,"tv":4866.51,"id":9631075},{"batb":[[2,1.97,25.99]],"batl":[[2,2.28,18.48]],"ltp":2.04,"tv":1594.92,"id":11772759}]}]}
{"op":"mcm","clk":"1010194128","pt":1580649745125,"mc":[{"id":"1.168222848","rc":[{"batb":[[2,1.99,2]],"batl":[[2,2.14,2.25]],"ltp":2.04,"tv":1594.92,"id":11772759}]}]}
{"op":"mcm","clk":"1010198933","pt":1580649779694,"mc":[{"id":"1.168222848","rc":[{"batl":[[2,2.14,2.04]],"ltp":2.04,"tv":1594.92,"id":11772759}]}]}
{"op":"mcm","clk":"1010210592","pt":1580649862719,"mc":[{"id":"1.168222848","rc":[{"batb":[[0,1.91,3],[1,1.9,2.06],[2,1.89,2.05]],"ltp":1.95,"tv":4866.51,"id":9631075}]}]}
{"op":"mcm","clk":"1010210739","pt":1580649863680,"mc":[{"id":"1.168222848","rc":[{"batl":[[2,2.14,2.11]],"ltp":2.04,"tv":1594.92,"id":11772759}]}]}
{"op":"mcm","clk":"1010210863","pt":1580649864698,"mc":[{"id":"1.168222848","rc":[{"trd":[[1.92,10.83]],"batb":[[1,1.89,2.05],[2,1.88,157.37]],"batl":[[0,1.92,2.17],[1,1.94,2.08],[2,1.95,2.1]],"ltp":1.92,"tv":4877.34,"id":9631075},{"trd":[[2.08,10]],"batl":[[0,2.14,2.11],[1,2.16,2],[2,2.28,18.48]],"ltp":2.08,"tv":1604.92,"id":11772759}],"tv":6482.27}]}
{"op":"mcm","clk":"1010211005","pt":1580649865712,"mc":[{"id":"1.168222848","rc":[{"batb":[[0,2.04,2.1],[1,2.02,35.73],[2,1.99,27.46]],"ltp":2.08,"tv":1604.92,"id":11772759}]}]}
{"op":"mcm","clk":"1010231250","pt":1580650004620,"mc":[{"id":"1.168222848","rc":[{"trd":[[1.92,15.17],[1.94,1234.28],[1.95,792.56]],"batb":[[2,1.88,151.71]],"batl":[[0,1.96,7.57],[1,1.97,293.28],[2,1.98,420.1]],"ltp":1.95,"tv":4890.04,"id":9631075},{"batb":[[0,2.02,39.8],[1,1.99,27.46],[2,1.98,27.98]],"batl":[[1,2.16,2.22]],"ltp":2.08,"tv":1604.92,"id":11772759}],"tv":6494.97}]}
{"op":"mcm","clk":"1010231309","pt":1580650004992,"mc":[{"id":"1.168222848","rc":[{"batb":[[1,2,2],[2,1.99,27.46]],"ltp":2.08,"tv":1604.92,"id":11772759}]}]}
{"op":"mcm","clk":"1010233605","pt":1580650020758,"mc":[{"id":"1.168222848","rc":[{"batb":[[0,1.92,7.57],[1,1.91,3],[2,1.9,3.06]],"ltp":1.95,"tv":4890.04,"id":9631075}]}]}
{"op":"mcm","clk":"1010233910","pt":1580650022639,"mc":[{"id":"1.168222848","rc":[{"batb":[[0,1.92,15.14]],"ltp":1.95,"tv":4890.04,"id":9631075}]}]}
{"op":"mcm","clk":"1010233960","pt":1580650023017,"mc":[{"id":"1.168222848","rc":[{"batb":[[2,1.99,2]],"ltp":2.08,"tv":1604.92,"id":11772759}]}]}
{"op":"mcm","clk":"1010241529","pt":1580650076579,"mc":[{"id":"1.168222848","rc":[{"batb":[[0,1.92,22.72]],"ltp":1.95,"tv":4890.04,"id":9631075},{"batb":[[2,1.98,25.72]],"batl":[[1,2.28,18.48],[2,2.52,15.14]],"ltp":2.08,"tv":1604.92,"id":11772759}]}]}
{"op":"mcm","clk":"1010241599","pt":1580650077008,"mc":[{"id":"1.168222848","rc":[{"batb":[[2,1.99,2]],"batl":[[1,2.16,2],[2,2.28,18.48]],"ltp":2.08,"tv":1604.92,"id":11772759}]}]}
{"op":"mcm","clk":"1010242014","pt":1580650079632,"mc":[{"id":"1.168222848","rc":[{"batb":[[0,1.91,3],[1,1.89,2.6],[2,1.88,151.71]],"ltp":1.95,"tv":4890.04,"id":9631075}]}]}
{"op":"mcm","clk":"1010242078","pt":1580650080004,"mc":[{"id":"1.168222848","rc":[{"batb":[[2,1.99,27.46]],"ltp":2.08,"tv":1604.92,"id":11772759}]}]}
{"op":"mcm","clk":"1010242319","pt":1580650081293,"mc":[{"id":"1.168222848","rc":[{"batb":[[0,1.92,7.57],[1,1.91,3],[2,1.9,2.66]],"ltp":1.95,"tv":4890.04,"id":9631075}]}]}
{"op":"mcm","clk":"1010242510","pt":1580650082534,"mc":[{"id":"1.168222848","rc":[{"batb":[[0,1.92,15.14]],"ltp":1.95,"tv":4890.04,"id":9631075}]}]}
{"op":"mcm","clk":"1010242607","pt":1580650083110,"mc":[{"id":"1.168222848","rc":[{"batb":[[0,1.92,22.72]],"ltp":1.95,"tv":4890.04,"id":9631075},{"batb":[[2,1.99,2]],"batl":[[1,2.16,2.22]],"ltp":2.08,"tv":1604.92,"id":11772759}]}]}
{"op":"mcm","clk":"1010242891","pt":1580650084638,"mc":[{"id":"1.168222848","rc":[{"batb":[[0,1.91,3],[1,1.9,2.66],[2,1.89,3.05]],"ltp":1.95,"tv":4890.04,"id":9631075}]}]}
{"op":"mcm","clk":"1010242992","pt":1580650085117,"mc":[{"id":"1.168222848","rc":[{"batb":[[1,1.89,3.05],[2,1.88,151.71]],"ltp":1.95,"tv":4890.04,"id":9631075},{"batb":[[2,1.99,27.46]],"ltp":2.08,"tv":1604.92,"id":11772759}]}]}
{"op":"mcm","clk":"1010243215","pt":1580650086509,"mc":[{"id":"1.168222848","rc":[{"batb":[[2,1.88,151.46]],"batl":[[0,1.96,15.14]],"ltp":1.95,"tv":4890.04,"id":9631075}]}]}
{"op":"mcm","clk":"1010243764","pt":1580650089700,"mc":[{"id":"1.168222848","rc":[{"batl":[[0,1.97,293.28],[1,1.98,420.1],[2,1.99,520.14]],"ltp":1.95,"tv":4890.04,"id":9631075},{"batb":[[2,1.99,25.46]],"batl":[[1,2.28,18.48],[2,2.52,15.14]],"ltp":2.08,"tv":1604.92,"id":11772759}]}]}
{"op":"mcm","clk":"1010243829","pt":1580650090117,"mc":[{"id":"1.168222848","rc":[{"batl":[[0,1.96,7.57],[1,1.97,293.28],[2,1.98,420.1]],"ltp":1.95,"tv":4890.04,"id":9631075},{"batb":[[2,1.99,27.46]],"batl":[[1,2.16,2.22],[2,2.28,18.48]],"ltp":2.08,"tv":1604.92,"id":11772759}]}]}
{"op":"mcm","clk":"1010244040","pt":1580650091316,"mc":[{"id":"1.168222848","rc":[{"batl":[[0,1.96,15.14]],"ltp":1.95,"tv":4890.04,"id":9631075}]}]}
{"op":"mcm","clk":"1010249956","pt":1580650130638,"mc":[{"id":"1.168222848","rc":[{"batb":[[2,1.88,148.75]],"batl":[[0,1.96,22.72]],"ltp":1.95,"tv":4890.04,"id":9631075},{"batb":[[2,1.99,25.46]],"batl":[[1,2.28,18.48],[2,2.52,15.14]],"ltp":2.08,"tv":1604.92,"id":11772759}]}]}
{"op":"mcm","clk":"1010250025","pt":1580650131058,"mc":[{"id":"1.168222848","rc":[{"batb":[[2,1.88,151.71]],"ltp":1.95,"tv":4890.04,"id":9631075},{"batb":[[1,2,27.21],[2,1.99,27.46]],"batl":[[1,2.16,2.22],[2,2.28,18.48]],"ltp":2.08,"tv":1604.92,"id":11772759}]}]}
{"op":"mcm","clk":"1010250236","pt":1580650132550,"mc":[{"id":"1.168222848","rc":[{"batl":[[0,1.97,293.28],[1,1.98,420.1],[2,1.99,520.14]],"ltp":1.95,"tv":4890.04,"id":9631075}]}]}
