{"op":"mcm","clk":"1001177857","pt":1580585273658,"mc":[{"id":"1.168224450","marketDefinition":{"bspMarket":false,"turnInPlayEnabled":true,"persistenceEnabled":true,"marketBaseRate":5.0,"eventId":"29681727","eventTypeId":"2","numberOfWinners":1,"bettingType":"ODDS","marketType":"SET_WINNER","marketTime":"2020-02-02T15:00:00.000Z","suspendTime":"2020-02-02T15:00:00.000Z","bspReconciled":false,"complete":true,"inPlay":false,"crossMatching":false,"runnersVoidable":false,"numberOfActiveRunners":2,"betDelay":0,"status":"OPEN","runners":[{"status":"ACTIVE","sortPriority":1,"id":10894176,"name":"Elliot Benchetrit"},{"status":"ACTIVE","sortPriority":2,"id":2263634,"name":"Lukas Lacko"}],"regulators":["MR_INT"],"countryCode":"FR","discountAllowed":false,"timezone":"UTC","openDate":"2020-02-02T15:00:00.000Z","version":3147098558,"name":"Set 1 Winner","eventName":"Benchetrit v Lacko"},"rc":[{"batb":[[0,1.01,20]],"ltp":0.0,"tv":0.0,"id":10894176},{"batb":[[0,1.01,20]],"ltp":0.0,"tv":0.0,"id":2263634}]}]}
{"op":"mcm","clk":"1001178215","pt":1580585275453,"mc":[{"id":"1.168224450","marketDefinition":{"bspMarket":false,"turnInPlayEnabled":true,"persistenceEnabled":true,"marketBaseRate":5.0,"eventId":"29681727","eventTypeId":"2","numberOfWinners":1,"bettingType":"ODDS","marketType":"SET_WINNER","marketTime":"2020-02-02T15:00:00.000Z","suspendTime":"2020-02-02T15:00:00.000Z","bspReconciled":false,"complete":true,"inPlay":false,"crossMatching":false,"runnersVoidable":false,"numberOfActiveRunners":2,"betDelay":0,"status":"OPEN","runners":[{"status":"ACTIVE","sortPriority":1,"id":10894176,"name":"Elliot Benchetrit"},{"status":"ACTIVE","sortPriority":2,"id":2263634,"name":"Lukas Lacko"}],"regulators":["MR_INT"],"countryCode":"FR","discountAllowed":true,"timezone":"UTC","openDate":"2020-02-02T15:00:00.000Z","version":3147098558,"name":"Set 1 Winner","eventName":"Benchetrit v Lacko"}}]}
{"op":"mcm","clk":"1001204807","pt":1580585418184,"mc":[{"id":"1.168224450","rc":[{"batb":[[0,1.01,15]],"ltp":0.0,"tv":0.0,"id":10894176},{"batb":[[0,1.01,15]],"ltp":0.0,"tv":0.0,"id":2263634}]}]}
{"op":"mcm","clk":"1003033094","pt":1580602191259,"mc":[{"id":"1.168224450","rc":[{"batb":[[0,1.01,15.51]],"ltp":0.0,"tv":0.0,"id":10894176},{"batb":[[0,1.01,15.51]],"ltp":0.0,"tv":0.0,"id":2263634}]}]}
{"op":"mcm","clk":"1003160717","pt":1580603730430,"mc":[{"id":"1.168224450","rc":[{"batb":[[0,1.01,18.04]],"ltp":0.0,"tv":0.0,"id":10894176},{"batb":[[0,1.01,18.04]],"ltp":0.0,"tv":0.0,"id":2263634}]}]}
{"op":"mcm","clk":"1003160793","pt":1580603731415,"mc":[{"id":"1.168224450","rc":[{"batb":[[0,1.01,16.01]],"ltp":0.0,"tv":0.0,"id":10894176},{"batb":[[0,1.01,16.01]],"ltp":0.0,"tv":0.0,"id":2263634}]}]}
{"op":"mcm","clk":"1006028481","pt":1580646073661,"mc":[{"id":"1.168224450","rc":[{"batl":[[0,3.6,3.79]],"ltp":0.0,"tv":0.0,"id":10894176},{"batl":[[0,2.94,7.57]],"ltp":0.0,"tv":0.0,"id":2263634}]}]}
{"op":"mcm","clk":"1006943682","pt":1580652024934,"mc":[{"id":"1.168224450","rc":[{"batb":[[0,1.02,2],[1,1.01,16.01]],"ltp":0.0,"tv":0.0,"id":10894176},{"batb":[[0,1.02,2],[1,1.01,16.01]],"ltp":0.0,"tv":0.0,"id":2263634}]}]}
{"op":"mcm","clk":"1006946736","pt":1580652046426,"mc":[{"id":"1.168224450","marketDefinition":{"bspMarket":false,"turnInPlayEnabled":true,"persistenceEnabled":true,"marketBaseRate":5.0,"eventId":"29681727","eventTypeId":"2","numberOfWinners":1,"bettingType":"ODDS","marketType":"SET_WINNER","marketTime":"2020-02-02T15:00:00.000Z","suspendTime":"2020-02-02T15:00:00.000Z","bspReconciled":false,"complete":true,"inPlay":false,"crossMatching":true,"runnersVoidable":false,"numberOfActiveRunners":2,"betDelay":0,"status":"OPEN","runners":[{"status":"ACTIVE","sortPriority":1,"id":10894176,"name":"Elliot Benchetrit"},{"status":"ACTIVE","sortPriority":2,"id":2263634,"name":"Lukas Lacko"}],"regulators":["MR_INT"],"countryCode":"FR","discountAllowed":true,"timezone":"UTC","openDate":"2020-02-02T15:00:00.000Z","version":3147124903,"name":"Set 1 Winner","eventName":"Benchetrit v Lacko"}}]}
{"op":"mcm","clk":"1007045245","pt":1580652624212,"mc":[{"id":"1.168224450","rc":[{"batb":[[0,1.01,16.01],[1,1.01,0]],"ltp":0.0,"tv":0.0,"id":2263634}]}]}
{"op":"mcm","clk":"1007045303","pt":1580652624588,"mc":[{"id":"1.168224450","rc":[{"batb":[[0,1.01,16.01],[1,1.01,0]],"ltp":0.0,"tv":0.0,"id":10894176}]}]}
{"op":"mcm","clk":"1007045710","pt":1580652626771,"mc":[{"id":"1.168224450","rc":[{"batb":[[0,1.52,2],[1,1.01,16.01]],"ltp":0.0,"tv":0.0,"id":10894176},{"batb":[[0,1.39,2],[1,1.01,16.01]],"ltp":0.0,"tv":0.0,"id":2263634}]}]}
{"op":"mcm","clk":"1007149081","pt":1580653226337,"mc":[{"id":"1.168224450","rc":[{"batb":[[0,1.01,16.01],[1,1.01,0]],"ltp":0.0,"tv":0.0,"id":10894176},{"batb":[[0,1.01,16.01],[1,1.01,0]],"ltp":0.0,"tv":0.0,"id":2263634}]}]}
{"op":"mcm","clk":"1007247629","pt":1580653841956,"mc":[{"id":"1.168224450","rc":[{"batb":[[0,1.52,2],[1,1.01,16.01]],"ltp":0.0,"tv":0.0,"id":10894176},{"batb":[[0,1.39,2],[1,1.01,16.01]],"ltp":0.0,"tv":0.0,"id":2263634}]}]}
{"op":"mcm","clk":"1007347048","pt":1580654441181,"mc":[{"id":"1.168224450","rc":[{"batb":[[0,1.01,16.01],[1,1.01,0]],"ltp":0.0,"tv":0.0,"id":10894176}]}]}
{"op":"mcm","clk":"1007347223","pt":1580654442283,"mc":[{"id":"1.168224450","rc":[{"batb":[[0,1.01,16.01],[1,1.01,0]],"ltp":0.0,"tv":0.0,"id":2263634}]}]}
{"op":"mcm","clk":"1007348852","pt":1580654452812,"mc":[{"id":"1.168224450","rc":[{"batb":[[0,1.52,2],[1,1.01,16.01]],"ltp":0.0,"tv":0.0,"id":10894176},{"batb":[[0,1.39,2],[1,1.01,16.01]],"ltp":0.0,"tv":0.0,"id":2263634}]}]}
{"op":"mcm","clk":"1007364733","pt":1580654552085,"mc":[{"id":"1.168224450","rc":[{"batb":[[0,1.53,2.02],[1,1.52,2],[2,1.01,16.01]],"ltp":0.0,"tv":0.0,"id":10894176},{"batb":[[0,1.4,2.02],[1,1.39,2],[2,1.01,16.01]],"ltp":0.0,"tv":0.0,"id":2263634}]}]}
{"op":"mcm","clk":"1007435854","pt":1580655052310,"mc":[{"id":"1.168224450","rc":[{"batb":[[1,1.01,16.01],[2,1.01,0]],"ltp":0.0,"tv":0.0,"id":10894176},{"batb":[[1,1.01,16.01],[2,1.01,0]],"ltp":0.0,"tv":0.0,"id":2263634}]}]}
{"op":"mcm","clk":"1007443321","pt":1580655113558,"mc":[{"id":"1.168224450","marketDefinition":{"bspMarket":false,"turnInPlayEnabled":true,"persistenceEnabled":true,"marketBaseRate":5.0,"eventId":"29681727","eventTypeId":"2","numberOfWinners":1,"bettingType":"ODDS","marketType":"SET_WINNER","marketTime":"2020-02-02T14:51:00.000Z","suspendTime":"2020-02-02T14:51:00.000Z","bspReconciled":false,"complete":true,"inPlay":false,"crossMatching":true,"runnersVoidable":false,"numberOfActiveRunners":2,"betDelay":0,"status":"OPEN","runners":[{"status":"ACTIVE","sortPriority":1,"id":10894176,"name":"Elliot Benchetrit"},{"status":"ACTIVE","sortPriority":2,"id":2263634,"name":"Lukas Lacko"}],"regulators":["MR_INT"],"countryCode":"FR","discountAllowed":true,"timezone":"UTC","openDate":"2020-02-02T15:00:00.000Z","version":3149300454,"name":"Set 1 Winner","eventName":"Benchetrit v Lacko"}}]}
{"op":"mcm","clk":"1007443834","pt":1580655117578,"mc":[{"id":"1.168224450","marketDefinition":{"bspMarket":false,"turnInPlayEnabled":true,"persistenceEnabled":true,"marketBaseRate":5.0,"eventId":"29681727","eventTypeId":"2","numberOfWinners":1,"bettingType":"ODDS","marketType":"SET_WINNER","marketTime":"2020-02-02T14:51:00.000Z","suspendTime":"2020-02-02T14:51:00.000Z","bspReconciled":false,"complete":true,"inPlay":false,"crossMatching":true,"runnersVoidable":false,"numberOfActiveRunners":2,"betDelay":0,"status":"OPEN","runners":[{"status":"ACTIVE","sortPriority":1,"id":10894176,"name":"Elliot Benchetrit"},{"status":"ACTIVE","sortPriority":2,"id":2263634,"name":"Lukas Lacko"}],"regulators":["MR_INT"],"countryCode":"FR","discountAllowed":true,"timezone":"UTC","openDate":"2020-02-02T14:51:00.000Z","version":3149300454,"name":"Set 1 Winner","eventName":"Benchetrit v Lacko"}}]}
{"op":"mcm","clk":"1007447209","pt":1580655147016,"mc":[{"id":"1.168224450","rc":[{"batb":[[0,2.08,24.71],[1,1.53,2.02],[2,1.01,16.01]],"ltp":0.0,"tv":0.0,"id":10894176},{"batb":[[0,1.8,19.51],[1,1.4,2.02],[2,1.01,16.01]],"ltp":0.0,"tv":0.0,"id":2263634}]}]}
{"op":"mcm","clk":"1007552140","pt":1580655876896,"mc":[{"id":"1.168224450","rc":[{"batb":[[1,2.06,39.49],[2,1.53,2.02]],"batl":[[0,2.32,31.09],[1,3.6,3.79]],"ltp":0.0,"tv":0.0,"id":10894176},{"batb":[[1,1.77,53.77],[2,1.4,2.02]],"batl":[[0,1.95,42.01],[1,2.94,7.57]],"ltp":0.0,"tv":0.0,"id":2263634}]}]}
{"op":"mcm","clk":"1007580343","pt":1580656014494,"mc":[{"id":"1.168224450","rc":[{"batl":[[0,2.2,1.68],[1,2.32,31.09],[2,3.6,3.79]],"ltp":0.0,"tv":0.0,"id":10894176}]}]}
{"op":"mcm","clk":"1007608076","pt":1580656137407,"mc":[{"id":"1.168224450","marketDefinition":{"bspMarket":false,"turnInPlayEnabled":true,"persistenceEnabled":true,"marketBaseRate":5.0,"eventId":"29681727","eventTypeId":"2","numberOfWinners":1,"bettingType":"ODDS","marketType":"SET_WINNER","marketTime":"2020-02-02T14:51:00.000Z","suspendTime":"2020-02-02T14:51:00.000Z","bspReconciled":false,"complete":true,"inPlay":true,"crossMatching":true,"runnersVoidable":false,"numberOfActiveRunners":2,"betDelay":3,"status":"OPEN","runners":[{"status":"ACTIVE","sortPriority":1,"id":10894176,"name":"Elliot Benchetrit"},{"status":"ACTIVE","sortPriority":2,"id":2263634,"name":"Lukas Lacko"}],"regulators":["MR_INT"],"countryCode":"FR","discountAllowed":true,"timezone":"UTC","openDate":"2020-02-02T14:51:00.000Z","version":3149404456,"name":"Set 1 Winner","eventName":"Benchetrit v Lacko"},"rc":[{"batb":[[0,1.01,15.51],[1,2.06,0],[2,1.53,0]],"batl":[[1,2.32,0],[2,3.6,0]],"ltp":0.0,"tv":0.0,"id":10894176},{"batb":[[0,1.01,15.51],[1,1.77,0],[2,1.4,0]],"ltp":0.0,"tv":0.0,"id":2263634}]}]}
{"op":"mcm","clk":"1007609996","pt":1580656145324,"mc":[{"id":"1.168224450","rc":[{"batb":[[0,1.98,29.19],[1,1.93,44.53],[2,1.89,16.68]],"batl":[[0,2.16,36.13],[1,2.2,1.68]],"ltp":0.0,"tv":0.0,"id":10894176},{"batb":[[0,1.9,16.6],[1,1.85,48.73],[2,1.75,21.4]],"batl":[[0,2.06,39.49]],"ltp":0.0,"tv":0.0,"id":2263634}]}]}
{"op":"mcm","clk":"1007611711","pt":1580656152308,"mc":[{"id":"1.168224450","rc":[{"batl":[[0,1.96,119.5],[1,1.98,133.3],[2,2.06,39.49]],"ltp":0.0,"tv":0.0,"id":2263634}]}]}
{"op":"mcm","clk":"1007612160","pt":1580656154204,"mc":[{"id":"1.168224450","rc":[{"batb":[[0,1.89,16.68],[1,1.01,15.51],[2,1.89,0]],"batl":[[0,2.2,1.68],[1,2.2,0]],"ltp":0.0,"tv":0.0,"id":10894176},{"batb":[[0,1.75,21.4],[1,1.01,15.51],[2,1.75,0]],"ltp":0.0,"tv":0.0,"id":2263634}]}]}
{"op":"mcm","clk":"1007612873","pt":1580656157127,"mc":[{"id":"1.168224450","rc":[{"batb":[[1,1.74,166.78],[2,1.72,205.99]],"batl":[[0,2.06,148.18],[1,2.08,115.35]],"ltp":0.0,"tv":0.0,"id":2263634}]}]}
{"op":"mcm","clk":"1007613090","pt":1580656158009,"mc":[{"id":"1.168224450","rc":[{"batb":[[1,1.01,15.51],[2,1.72,0]],"ltp":0.0,"tv":0.0,"id":2263634}]}]}
{"op":"mcm","clk":"1007614150","pt":1580656162210,"mc":[{"id":"1.168224450","rc":[{"batb":[[0,1.85,137.18],[1,1.83,167.5],[2,1.75,21.4]],"batl":[[0,1.93,133.87],[1,1.95,139.53]],"ltp":0.0,"tv":0.0,"id":2263634}]}]}
{"op":"mcm","clk":"1007614473","pt":1580656163735,"mc":[{"id":"1.168224450","rc":[{"batb":[[0,1.75,21.4],[1,1.01,15.51],[2,1.75,0]],"ltp":0.0,"tv":0.0,"id":2263634}]}]}
{"op":"mcm","clk":"1007615112","pt":1580656166542,"mc":[{"id":"1.168224450","rc":[{"batb":[[1,1.74,166.78],[2,1.72,205.99]],"batl":[[0,2.06,148.18],[1,2.08,115.35]],"ltp":0.0,"tv":0.0,"id":2263634}]}]}
{"op":"mcm","clk":"1007615833","pt":1580656169818,"mc":[{"id":"1.168224450","rc":[{"batb":[[1,1.01,15.51],[2,1.72,0]],"ltp":0.0,"tv":0.0,"id":2263634}]}]}
{"op":"mcm","clk":"1007616592","pt":1580656173182,"mc":[{"id":"1.168224450","rc":[{"batb":[[1,1.85,48.73],[2,1.01,15.51]],"batl":[[0,2.04,148.94],[1,2.06,158.12],[2,2.2,1.68]],"ltp":0.0,"tv":0.0,"id":10894176},{"batb":[[0,1.94,44.53],[1,1.75,21.4],[2,1.01,15.51]],"batl":[[0,2.16,36.13]],"ltp":0.0,"tv":0.0,"id":2263634}]}]}
{"op":"mcm","clk":"1007616772","pt":1580656173848,"mc":[{"id":"1.168224450","rc":[{"batb":[[2,1.84,18.41]],"ltp":0.0,"tv":0.0,"id":10894176},{"batb":[[0,1.98,29.03],[1,1.94,44.53],[2,1.87,17.39]],"ltp":0.0,"tv":0.0,"id":2263634}]}]}
{"op":"mcm","clk":"1007617350","pt":1580656176206,"mc":[{"id":"1.168224450","rc":[{"batb":[[0,1.94,141.19],[1,1.92,143.81],[2,1.89,16.68]],"batl":[[0,2.04,187.05]],"ltp":0.0,"tv":0.0,"id":10894176}]}]}
{"op":"mcm","clk":"1007619400","pt":1580656184560,"mc":[{"id":"1.168224450","rc":[{"batb":[[0,1.85,48.73],[1,1.84,18.41],[2,1.01,15.51]],"batl":[[0,2.06,39.49],[1,2.2,1.68],[2,2.2,0]],"ltp":0.0,"tv":0.0,"id":10894176},{"batb":[[0,1.94,44.53],[1,1.87,17.39],[2,1.01,15.51]],"ltp":0.0,"tv":0.0,"id":2263634}]}]}
{"op":"mcm","clk":"1007619841","pt":1580656186270,"mc":[{"id":"1.168224450","rc":[{"batb":[[0,1.84,18.41],[1,1.01,15.51],[2,1.01,0]],"batl":[[0,2.2,1.68],[1,2.2,0]],"ltp":0.0,"tv":0.0,"id":10894176},{"batb":[[0,1.87,17.39],[1,1.01,15.51],[2,1.01,0]],"ltp":0.0,"tv":0.0,"id":2263634}]}]}
{"op":"mcm","clk":"1007620232","pt":1580656187803,"mc":[{"id":"1.168224450","rc":[{"batb":[[0,1.88,167.56],[1,1.86,159.05],[2,1.84,18.41]],"ltp":0.0,"tv":0.0,"id":10894176}]}]}
{"op":"mcm","clk":"1007620639","pt":1580656189349,"mc":[{"id":"1.168224450","rc":[{"batl":[[0,1.97,148.72],[1,1.99,131.35],[2,2.2,1.68]],"ltp":0.0,"tv":0.0,"id":10894176}]}]}
{"op":"mcm","clk":"1007620845","pt":1580656190271,"mc":[{"id":"1.168224450","rc":[{"batb":[[0,1.88,119.12]],"batl":[[0,2.2,1.68],[1,1.99,0],[2,2.2,0]],"ltp":0.0,"tv":0.0,"id":10894176},{"batb":[[0,2.04,26.28],[1,1.96,29.98],[2,1.01,15.51]],"ltp":0.0,"tv":0.0,"id":2263634}]}]}
{"op":"mcm","clk":"1007621042","pt":1580656191172,"mc":[{"id":"1.168224450","rc":[{"batl":[[0,1.99,42.01],[1,2.2,1.68]],"ltp":0.0,"tv":0.0,"id":10894176},{"batb":[[1,2.02,41.17],[2,1.96,29.98]],"batl":[[0,2.24,33.61]],"ltp":0.0,"tv":0.0,"id":2263634}]}]}
{"op":"mcm","clk":"1007621606","pt":1580656193444,"mc":[{"id":"1.168224450","rc":[{"batl":[[0,1.96,128.24],[1,1.98,133.41],[2,1.99,42.01]],"ltp":0.0,"tv":0.0,"id":10894176}]}]}
{"op":"mcm","clk":"1007623570","pt":1580656201395,"mc":[{"id":"1.168224450","rc":[{"batb":[[0,1.8,19.59],[1,1.79,52.93],[2,1.01,15.51]],"batl":[[0,1.99,42.01],[1,2.2,1.68],[2,1.99,0]],"ltp":0.0,"tv":0.0,"id":10894176},{"batb":[[0,2.02,41.17],[1,1.96,29.98],[2,1.01,15.51]],"ltp":0.0,"tv":0.0,"id":2263634}]}]}
{"op":"mcm","clk":"1007623784","pt":1580656202271,"mc":[{"id":"1.168224450","rc":[{"batb":[[1,1.01,15.51],[2,1.01,0]],"batl":[[0,2.2,1.68],[1,2.2,0]],"ltp":0.0,"tv":0.0,"id":10894176},{"batb":[[0,1.96,29.98],[1,1.01,15.51],[2,1.01,0]],"ltp":0.0,"tv":0.0,"id":2263634}]}]}
{"op":"mcm","clk":"1007624267","pt":1580656204413,"mc":[{"id":"1.168224450","rc":[{"batb":[[0,1.85,114.05],[1,1.83,167.6],[2,1.8,19.59]],"batl":[[0,2.04,210.1],[1,2.06,118.7],[2,2.2,1.68]],"ltp":0.0,"tv":0.0,"id":10894176}]}]}
{"op":"mcm","clk":"1007624998","pt":1580656207386,"mc":[{"id":"1.168224450","rc":[{"batb":[[0,1.8,19.59],[1,1.01,15.51],[2,1.8,0]],"ltp":0.0,"tv":0.0,"id":10894176}]}]}
{"op":"mcm","clk":"1007625578","pt":1580656209921,"mc":[{"id":"1.168224450","rc":[{"batb":[[0,1.94,117.16],[1,1.92,143.85],[2,1.8,19.59]],"ltp":0.0,"tv":0.0,"id":10894176}]}]}
{"op":"mcm","clk":"1007625909","pt":1580656211247,"mc":[{"id":"1.168224450","rc":[{"batb":[[2,1.91,16.21]],"batl":[[1,2.06,158.19]],"ltp":0.0,"tv":0.0,"id":10894176},{"batb":[[1,1.94,44.53],[2,1.85,18.02]],"batl":[[0,2.16,36.13]],"ltp":0.0,"tv":0.0,"id":2263634}]}]}
{"op":"mcm","clk":"1007630157","pt":1580656228229,"mc":[{"id":"1.168224450","rc":[{"batb":[[0,1.86,17.78],[1,1.01,15.51],[2,1.91,0]],"batl":[[0,2.2,1.68],[1,2.06,0],[2,2.2,0]],"ltp":0.0,"tv":0.0,"id":10894176},{"batb":[[0,1.85,18.02],[1,1.01,15.51],[2,1.85,0]],"ltp":0.0,"tv":0.0,"id":2263634}]}]}
{"op":"mcm","clk":"1007630859","pt":1580656231038,"mc":[{"id":"1.168224450","rc":[{"batb":[[0,1.88,156.53],[1,1.86,176.87],[2,1.01,15.51]],"batl":[[0,2.14,101.09],[1,2.16,103.54],[2,2.2,1.68]],"ltp":0.0,"tv":0.0,"id":10894176}]}]}
{"op":"mcm","clk":"1007634704","pt":1580656246149,"mc":[{"id":"1.168224450","rc":[{"batb":[[0,1.86,17.78],[1,1.01,15.51],[2,1.01,0]],"batl":[[0,2.2,1.68],[1,2.16,0],[2,2.2,0]],"ltp":0.0,"tv":0.0,"id":10894176}]}]}
{"op":"mcm","clk":"1007635540","pt":1580656249352,"mc":[{"id":"1.168224450","rc":[{"batb":[[0,1.94,44.53],[1,1.86,17.78],[2,1.01,15.51]],"batl":[[0,2.16,36.13],[1,2.2,1.68]],"ltp":0.0,"tv":0.0,"id":10894176},{"batb":[[0,1.87,172.29],[1,1.85,228.57],[2,1.01,15.51]],"batl":[[0,1.96,152.65],[1,1.98,133.28],[2,2.06,39.49]],"ltp":0.0,"tv":0.0,"id":2263634}]}]}
{"op":"mcm","clk":"1007635767","pt":1580656250251,"mc":[{"id":"1.168224450","rc":[{"batb":[[0,2.02,26.83],[1,1.94,44.53],[2,1.91,16.21]],"ltp":0.0,"tv":0.0,"id":10894176},{"batb":[[2,1.68,24.71]],"ltp":0.0,"tv":0.0,"id":2263634}]}]}
{"op":"mcm","clk":"1007639022","pt":1580656263084,"mc":[{"id":"1.168224450","rc":[{"trd":[[2.04,1.68]],"ltp":2.04,"tv":1.68,"id":10894176},{"trd":[[1.96,1.75]],"batl":[[0,1.96,150.9]],"ltp":1.96,"tv":1.75,"id":2263634}],"tv":3.43}]}
{"op":"mcm","clk":"1007640379","pt":1580656268228,"mc":[{"id":"1.168224450","rc":[{"batl":[[1,2.2,0]],"ltp":2.04,"tv":1.68,"id":10894176}]}]}
{"op":"mcm","clk":"1007640536","pt":1580656268787,"mc":[{"id":"1.168224450","rc":[{"batb":[[0,1.94,44.53],[1,1.91,16.21],[2,1.01,15.51]],"ltp":2.04,"tv":1.68,"id":10894176},{"batb":[[0,1.85,48.73],[1,1.68,24.71],[2,1.01,15.51]],"batl":[[0,2.06,39.49],[1,1.98,0],[2,2.06,0]],"ltp":1.96,"tv":1.75,"id":2263634}]}]}
{"op":"mcm","clk":"1007640902","pt":1580656270285,"mc":[{"id":"1.168224450","rc":[{"batb":[[0,1.91,16.21],[1,1.01,15.51],[2,1.01,0]],"ltp":2.04,"tv":1.68,"id":10894176},{"batb":[[0,1.68,24.71],[1,1.01,15.51],[2,1.01,0]],"ltp":1.96,"tv":1.75,"id":2263634}]}]}
{"op":"mcm","clk":"1007641148","pt":1580656271392,"mc":[{"id":"1.168224450","rc":[{"batb":[[0,1.7,124.98],[1,1.68,247.87],[2,1.01,15.51]],"batl":[[0,2.1,191.12],[1,2.12,109.29]],"ltp":1.96,"tv":1.75,"id":2263634}]}]}
{"op":"mcm","clk":"1007641368","pt":1580656272300,"mc":[{"id":"1.168224450","rc":[{"batb":[[0,1.68,24.71],[1,1.01,15.51],[2,1.01,0]],"ltp":1.96,"tv":1.75,"id":2263634}]}]}
{"op":"mcm","clk":"1007642073","pt":1580656275233,"mc":[{"id":"1.168224450","rc":[{"batb":[[0,1.84,108.12],[1,1.82,170.47],[2,1.68,24.71]],"batl":[[0,1.92,169.76],[1,1.94,141.66]],"ltp":1.96,"tv":1.75,"id":2263634}]}]}
{"op":"mcm","clk":"1007642958","pt":1580656278700,"mc":[{"id":"1.168224450","rc":[{"batb":[[0,1.68,24.71],[1,1.01,15.51],[2,1.68,0]],"ltp":1.96,"tv":1.75,"id":2263634}]}]}
{"op":"mcm","clk":"1007643696","pt":1580656281727,"mc":[{"id":"1.168224450","rc":[{"batb":[[0,1.7,124.98],[1,1.68,247.87],[2,1.01,15.51]],"batl":[[0,2.1,191.12],[1,2.12,109.29]],"ltp":1.96,"tv":1.75,"id":2263634}]}]}
{"op":"mcm","clk":"1007645258","pt":1580656288437,"mc":[{"id":"1.168224450","rc":[{"batb":[[0,2.28,19.12],[1,2.06,25.81],[2,1.01,15.51]],"ltp":2.04,"tv":1.68,"id":10894176},{"batb":[[2,1.46,41.86]],"batl":[[0,1.76,113.62],[1,1.78,185.49]],"ltp":1.96,"tv":1.75,"id":2263634}]}]}
{"op":"mcm","clk":"1007645449","pt":1580656289198,"mc":[{"id":"1.168224450","rc":[{"batb":[[1,2.16,36.13],[2,2.06,25.81]],"batl":[[0,2.46,28.57]],"ltp":2.04,"tv":1.68,"id":10894176},{"batb":[[0,1.7,184.63]],"batl":[[2,1.86,42.01]],"ltp":1.96,"tv":1.75,"id":2263634}]}]}
{"op":"mcm","clk":"1007649944","pt":1580656308230,"mc":[{"id":"1.168224450","rc":[{"batb":[[0,2.06,25.81],[1,1.01,15.51],[2,2.06,0]],"ltp":2.04,"tv":1.68,"id":10894176},{"batb":[[0,1.46,41.86],[1,1.01,15.51],[2,1.46,0]],"ltp":1.96,"tv":1.75,"id":2263634}]}]}
{"op":"mcm","clk":"1007651103","pt":1580656313269,"mc":[{"id":"1.168224450","rc":[{"batb":[[0,1.65,149.32],[1,1.64,122.34],[2,1.46,41.86]],"batl":[[0,1.71,142.22],[1,1.73,203.51]],"ltp":1.96,"tv":1.75,"id":2263634}]}]}
{"op":"mcm","clk":"1007652376","pt":1580656318671,"mc":[{"id":"1.168224450","rc":[{"batb":[[0,1.46,41.86],[1,1.01,15.51],[2,1.46,0]],"ltp":1.96,"tv":1.75,"id":2263634}]}]}
{"op":"mcm","clk":"1007653064","pt":1580656321644,"mc":[{"id":"1.168224450","rc":[{"batb":[[0,1.48,203.5],[1,1.47,186.89],[2,1.46,41.86]],"batl":[[0,1.94,134.29],[1,1.96,137.41]],"ltp":1.96,"tv":1.75,"id":2263634}]}]}
{"op":"mcm","clk":"1007653732","pt":1580656324371,"mc":[{"id":"1.168224450","rc":[{"batb":[[0,1.46,41.86],[1,1.01,15.51],[2,1.46,0]],"ltp":1.96,"tv":1.75,"id":2263634}]}]}
{"op":"mcm","clk":"1007654420","pt":1580656327357,"mc":[{"id":"1.168224450","rc":[{"batb":[[0,1.86,128.44],[1,1.84,164.6],[2,1.46,41.86]],"ltp":1.96,"tv":1.75,"id":2263634}]}]}
{"op":"mcm","clk":"1007654634","pt":1580656328287,"mc":[{"id":"1.168224450","rc":[{"batb":[[1,1.94,15.5],[2,1.01,15.51]],"ltp":2.04,"tv":1.68,"id":10894176},{"batb":[[2,1.83,18.73]],"ltp":1.96,"tv":1.75,"id":2263634}]}]}
{"op":"mcm","clk":"1007654886","pt":1580656329349,"mc":[{"id":"1.168224450","rc":[{"batb":[[1,1.98,42.85],[2,1.94,15.5]],"batl":[[0,2.2,34.45]],"ltp":2.04,"tv":1.68,"id":10894176},{"batb":[[2,1.83,69.14]],"batl":[[2,2.02,41.17]],"ltp":1.96,"tv":1.75,"id":2263634}]}]}
{"op":"mcm","clk":"1007657886","pt":1580656341635,"mc":[{"id":"1.168224450","rc":[{"batl":[[0,2.02,41.17],[1,1.96,0],[2,2.02,0]],"ltp":1.96,"tv":1.75,"id":2263634}]}]}
{"op":"mcm","clk":"1007658742","pt":1580656345158,"mc":[{"id":"1.168224450","rc":[{"batb":[[0,1.98,42.85],[1,1.94,15.5],[2,1.01,15.51]],"ltp":2.04,"tv":1.68,"id":10894176},{"batb":[[0,1.83,50.41],[1,1.66,25.73],[2,1.01,15.51]],"ltp":1.96,"tv":1.75,"id":2263634}]}]}
{"op":"mcm","clk":"1007659007","pt":1580656346244,"mc":[{"id":"1.168224450","rc":[{"batb":[[0,1.94,15.5],[1,1.01,15.51],[2,1.01,0]],"ltp":2.04,"tv":1.68,"id":10894176},{"batb":[[0,1.66,25.73],[1,1.01,15.51],[2,1.01,0]],"ltp":1.96,"tv":1.75,"id":2263634}]}]}
{"op":"mcm","clk":"1007659570","pt":1580656348743,"mc":[{"id":"1.168224450","rc":[{"batb":[[0,1.69,132.14],[1,1.67,227.8],[2,1.66,25.73]],"batl":[[0,2.08,143.11],[1,2.1,112.26]],"ltp":1.96,"tv":1.75,"id":2263634}]}]}
{"op":"mcm","clk":"1007664530","pt":1580656370306,"mc":[{"id":"1.168224450","rc":[{"batb":[[0,2.32,18.25],[1,2.08,24.86],[2,1.01,15.51]],"ltp":2.04,"tv":1.68,"id":10894176},{"batl":[[0,1.75,116.11],[1,1.77,188.79]],"ltp":1.96,"tv":1.75,"id":2263634}]}]}
{"op":"mcm","clk":"1007664746","pt":1580656371266,"mc":[{"id":"1.168224450","rc":[{"batb":[[1,2.18,35.29],[2,2.08,24.86]],"batl":[[0,2.48,27.73]],"ltp":2.04,"tv":1.68,"id":10894176},{"batb":[[1,1.68,61.33],[2,1.67,227.8]],"batl":[[2,1.84,42.01]],"ltp":1.96,"tv":1.75,"id":2263634}]}]}
{"op":"mcm","clk":"1007668453","pt":1580656387013,"mc":[{"id":"1.168224450","rc":[{"batb":[[0,2.18,35.29],[1,2.08,24.86],[2,1.9,4.2]],"ltp":2.04,"tv":1.68,"id":10894176},{"batb":[[0,1.68,61.33],[1,1.45,43.35],[2,1.01,15.51]],"batl":[[0,1.84,42.01],[1,1.77,0],[2,1.84,0]],"ltp":1.96,"tv":1.75,"id":2263634}]}]}
{"op":"mcm","clk":"1007668750","pt":1580656388266,"mc":[{"id":"1.168224450","rc":[{"batb":[[0,2.08,24.86],[1,1.9,4.2],[2,1.01,15.51]],"ltp":2.04,"tv":1.68,"id":10894176},{"batb":[[0,1.45,43.35],[1,1.01,15.51],[2,1.01,0]],"ltp":1.96,"tv":1.75,"id":2263634}]}]}
{"op":"mcm","clk":"1007669932","pt":1580656393286,"mc":[{"id":"1.168224450","rc":[{"batb":[[0,1.64,165.66],[1,1.63,125.05],[2,1.45,43.35]],"batl":[[0,1.7,137.82],[1,1.72,207.37]],"ltp":1.96,"tv":1.75,"id":2263634}]}]}
{"op":"mcm","clk":"1007670676","pt":1580656396320,"mc":[{"id":"1.168224450","rc":[{"batb":[[0,1.45,43.35],[1,1.01,15.51],[2,1.45,0]],"ltp":1.96,"tv":1.75,"id":2263634}]}]}
{"op":"mcm","clk":"1007671285","pt":1580656399204,"mc":[{"id":"1.168224450","rc":[{"batb":[[0,1.47,272.44],[1,1.46,192.63],[2,1.45,43.35]],"batl":[[0,1.93,141.62],[1,1.95,139.49]],"ltp":1.96,"tv":1.75,"id":2263634}]}]}
{"op":"mcm","clk":"1007673261","pt":1580656408020,"mc":[{"id":"1.168224450","rc":[{"batb":[[0,1.45,43.35],[1,1.01,15.51],[2,1.45,0]],"ltp":1.96,"tv":1.75,"id":2263634}]}]}
{"op":"mcm","clk":"1007674096","pt":1580656411438,"mc":[{"id":"1.168224450","rc":[{"batb":[[1,2,42.01],[2,1.96,30.21]],"batl":[[0,2.22,33.61]],"ltp":2.04,"tv":1.68,"id":10894176},{"batb":[[0,1.85,128.95],[1,1.83,167.48],[2,1.81,70.69]],"batl":[[2,2,42.01]],"ltp":1.96,"tv":1.75,"id":2263634}]}]}
{"op":"mcm","clk":"1007678640","pt":1580656430891,"mc":[{"id":"1.168224450","rc":[{"batb":[[0,2,42.01],[1,1.96,30.21],[2,1.9,4.2]],"ltp":2.04,"tv":1.68,"id":10894176},{"batb":[[0,1.81,51.25],[1,1.64,26.83],[2,1.01,15.51]],"batl":[[0,2,42.01],[1,1.95,0],[2,2,0]],"ltp":1.96,"tv":1.75,"id":2263634}]}]}
{"op":"mcm","clk":"1007679018","pt":1580656432367,"mc":[{"id":"1.168224450","rc":[{"batb":[[0,1.96,30.21],[1,1.9,4.2],[2,1.01,15.51]],"ltp":2.04,"tv":1.68,"id":10894176},{"batb":[[0,1.64,26.83],[1,1.01,15.51],[2,1.01,0]],"ltp":1.96,"tv":1.75,"id":2263634}]}]}
{"op":"mcm","clk":"1007680141","pt":1580656437279,"mc":[{"id":"1.168224450","rc":[{"batb":[[1,1.94,156.73],[2,1.92,143.86]],"batl":[[0,2.04,212.85],[1,2.06,118.7]],"ltp":2.04,"tv":1.68,"id":10894176},{"batb":[[0,1.95,43.69],[1,1.64,26.83],[2,1.01,15.51]],"batl":[[0,2.18,35.29]],"ltp":1.96,"tv":1.75,"id":2263634}]}]}
{"op":"mcm","clk":"1007680297","pt":1580656437889,"mc":[{"id":"1.168224450","rc":[{"batb":[[1,1.92,16.05],[2,1.82,19.04]],"ltp":1.96,"tv":1.75,"id":2263634}]}]}
{"op":"mcm","clk":"1007684554","pt":1580656454887,"mc":[{"id":"1.168224450","rc":[{"trd":[[2.04,10.08]],"batl":[[0,2.04,208.65]],"ltp":2.04,"tv":10.08,"id":10894176}],"tv":11.83}]}
{"op":"mcm","clk":"1007689163","pt":1580656474336,"mc":[{"id":"1.168224450","rc":[{"batb":[[1,1.85,48.73],[2,1.77,20.85]],"batl":[[0,2.04,40.33],[1,2.06,0]],"ltp":2.04,"tv":10.08,"id":10894176}]}]}
{"op":"mcm","clk":"1007690063","pt":1580656478148,"mc":[{"id":"1.168224450","rc":[{"batl":[[1,2.16,108.72],[2,2.18,100.87]],"ltp":2.04,"tv":10.08,"id":10894176}]}]}
{"op":"mcm","clk":"1007691096","pt":1580656482367,"mc":[{"id":"1.168224450","rc":[{"batb":[[0,1.77,20.85],[1,1.75,195.93],[2,1.73,202.43]],"batl":[[0,2.16,108.72],[1,2.18,100.87],[2,2.18,0]],"ltp":2.04,"tv":10.08,"id":10894176},{"batb":[[0,1.82,19.04],[1,1.01,15.51],[2,1.82,0]],"ltp":1.96,"tv":1.75,"id":2263634}]}]}
{"op":"mcm","clk":"1007692249","pt":1580656487058,"mc":[{"id":"1.168224450","rc":[{"batl":[[0,1.96,50],[1,2.16,108.72],[2,2.18,100.87]],"ltp":2.04,"tv":10.08,"id":10894176}]}]}
{"op":"mcm","clk":"1007694541","pt":1580656496355,"mc":[{"id":"1.168224450","rc":[{"batb":[[1,1.01,15.51],[2,1.73,0]],"batl":[[1,2.16,0],[2,2.18,0]],"ltp":2.04,"tv":10.08,"id":10894176}]}]}
{"op":"mcm","clk":"1007695258","pt":1580656499288,"mc":[{"id":"1.168224450","rc":[{"trd":[[1.96,50]],"ltp":1.96,"tv":60.08,"id":10894176},{"trd":[[2.04,48.04]],"batb":[[0,1.86,142.86],[1,1.84,164.6],[2,1.82,19.04]],"batl":[[0,1.94,72.38],[1,1.96,137.39]],"ltp":2.04,"tv":49.79,"id":2263634}],"tv":109.87}]}
{"op":"mcm","clk":"1007695464","pt":1580656500308,"mc":[{"id":"1.168224450","rc":[{"batb":[[0,2.06,25.41],[1,1.9,16.52],[2,1.01,15.51]],"ltp":1.96,"tv":60.08,"id":10894176}]}]}
{"op":"mcm","clk":"1007695722","pt":1580656501318,"mc":[{"id":"1.168224450","rc":[{"batb":[[1,1.96,43.69],[2,1.94,44.53]],"batl":[[0,2.12,36.97]],"ltp":1.96,"tv":60.08,"id":10894176},{"batb":[[0,1.88,47.05],[1,1.86,142.86],[2,1.84,164.6]],"batl":[[2,2.06,39.49]],"ltp":2.04,"tv":49.79,"id":2263634}]}]}
{"op":"mcm","clk":"1007696016","pt":1580656502370,"mc":[{"id":"1.168224450","rc":[{"batb":[[1,1.9,16.52],[2,1.7,409.32]],"ltp":1.96,"tv":60.08,"id":10894176},{"batb":[[0,1.86,142.86],[1,1.84,164.6],[2,1.82,19.04]],"batl":[[2,2.06,0]],"ltp":2.04,"tv":49.79,"id":2263634}]}]}
{"op":"mcm","clk":"1007696248","pt":1580656503205,"mc":[{"id":"1.168224450","rc":[{"batb":[[1,1.95,43.69],[2,1.9,16.52]],"batl":[[0,2.18,35.29]],"ltp":1.96,"tv":60.08,"id":10894176},{"batb":[[0,1.86,162.18],[1,1.84,214.17]],"batl":[[0,1.94,101.95],[2,2.04,40.33]],"ltp":2.04,"tv":49.79,"id":2263634}]}]}
{"op":"mcm","clk":"1007698638","pt":1580656513310,"mc":[{"id":"1.168224450","rc":[{"batb":[[0,1.95,43.69],[1,1.9,16.52],[2,1.7,409.32]],"ltp":1.96,"tv":60.08,"id":10894176},{"batb":[[0,1.84,49.57],[1,1.75,21.56],[2,1.55,420.5]],"batl":[[0,2.04,40.33],[1,1.96,0],[2,2.04,0]],"ltp":2.04,"tv":49.79,"id":2263634}]}]}
{"op":"mcm","clk":"1007698855","pt":1580656514400,"mc":[{"id":"1.168224450","rc":[{"batb":[[0,1.9,16.52],[1,1.7,409.32],[2,1.01,15.51]],"ltp":1.96,"tv":60.08,"id":10894176},{"batb":[[0,1.75,21.56],[1,1.55,420.5],[2,1.01,15.51]],"ltp":2.04,"tv":49.79,"id":2263634}]}]}
{"op":"mcm","clk":"1007699142","pt":1580656515777,"mc":[{"id":"1.168224450","rc":[{"batb":[[0,1.79,125.76],[1,1.77,186.76],[2,1.75,21.56]],"batl":[[0,2.12,102.35],[1,2.14,106.38]],"ltp":2.04,"tv":49.79,"id":2263634}]}]}
{"op":"mcm","clk":"1007701211","pt":1580656524413,"mc":[{"id":"1.168224450","rc":[{"batb":[[1,1.01,15.51],[2,1.01,0]],"ltp":1.96,"tv":60.08,"id":10894176},{"batl":[[0,1.86,119.12],[1,1.88,155.95]],"ltp":2.04,"tv":49.79,"id":2263634}]}]}
{"op":"mcm","clk":"1007701420","pt":1580656525444,"mc":[{"id":"1.168224450","rc":[{"batb":[[0,2.16,22.19],[1,2.06,39.49],[2,2.02,26.91]],"batl":[[0,2.32,31.09]],"ltp":1.96,"tv":60.08,"id":10894176},{"batb":[[2,1.76,54.61]],"batl":[[2,1.93,42.01]],"ltp":2.04,"tv":49.79,"id":2263634}]}]}
{"op":"mcm","clk":"1007703925","pt":1580656536424,"mc":[{"id":"1.168224450","rc":[{"batb":[[0,2.02,26.91],[1,1.77,402.27],[2,1.01,15.51]],"ltp":1.96,"tv":60.08,"id":10894176},{"batb":[[0,1.7,23.68],[1,1.55,420.5],[2,1.01,15.51]],"ltp":2.04,"tv":49.79,"id":2263634}]}]}
{"op":"mcm","clk":"1007704526","pt":1580656539142,"mc":[{"id":"1.168224450","rc":[{"batb":[[0,1.74,167.66],[1,1.72,205.84],[2,1.7,23.68]],"batl":[[0,1.97,137],[1,1.99,131.28]],"ltp":2.04,"tv":49.79,"id":2263634}]}]}
{"op":"mcm","clk":"1007706605","pt":1580656548442,"mc":[{"id":"1.168224450","rc":[{"batb":[[0,2.24,20.06],[1,2.14,22.98],[2,1.77,402.27]],"ltp":1.96,"tv":60.08,"id":10894176},{"batl":[[0,1.81,124.43],[1,1.83,169.64]],"ltp":2.04,"tv":49.79,"id":2263634}]}]}
{"op":"mcm","clk":"1007706867","pt":1580656549784,"mc":[{"id":"1.168224450","rc":[{"batb":[[2,2.12,36.97]],"batl":[[0,2.4,29.41]],"ltp":1.96,"tv":60.08,"id":10894176},{"batb":[[2,1.71,58.81]],"batl":[[2,1.87,42.01]],"ltp":2.04,"tv":49.79,"id":2263634}]}]}
{"op":"mcm","clk":"1007709045","pt":1580656560419,"mc":[{"id":"1.168224450","rc":[{"batb":[[0,2.14,22.98],[1,1.77,402.27],[2,1.01,15.51]],"ltp":1.96,"tv":60.08,"id":10894176},{"batb":[[0,1.72,119.72],[1,1.67,25.34],[2,1.46,435.7]],"ltp":2.04,"tv":49.79,"id":2263634}]}]}
{"op":"mcm","clk":"1007709673","pt":1580656563388,"mc":[{"id":"1.168224450","rc":[{"batb":[[0,1.67,25.34],[1,1.46,435.7],[2,1.01,15.51]],"ltp":2.04,"tv":49.79,"id":2263634}]}]}
{"op":"mcm","clk":"1007710208","pt":1580656565880,"mc":[{"id":"1.168224450","rc":[{"batb":[[0,1.75,164.03],[1,1.73,201.81],[2,1.67,25.34]],"batl":[[0,1.82,118.28],[1,1.84,166.78]],"ltp":2.04,"tv":49.79,"id":2263634}]}]}
{"op":"mcm","clk":"1007710791","pt":1580656568693,"mc":[{"id":"1.168224450","rc":[{"batb":[[0,1.67,25.34],[1,1.46,435.7],[2,1.01,15.51]],"ltp":2.04,"tv":49.79,"id":2263634}]}]}
{"op":"mcm","clk":"1007711455","pt":1580656571578,"mc":[{"id":"1.168224450","rc":[{"batb":[[0,1.72,119.72],[1,1.7,214.08],[2,1.67,25.34]],"batl":[[0,1.87,149.54],[1,1.89,153.35]],"ltp":2.04,"tv":49.79,"id":2263634}]}]}
{"op":"mcm","clk":"1007713034","pt":1580656579103,"mc":[{"id":"1.168224450","rc":[{"batb":[[1,1.7,216.6]],"ltp":2.04,"tv":49.79,"id":2263634}]}]}
{"op":"mcm","clk":"1007714390","pt":1580656585418,"mc":[{"id":"1.168224450","rc":[{"batb":[[0,2.22,33.61],[1,2.14,22.98],[2,1.77,402.27]],"batl":[[0,2.5,27.73]],"ltp":1.96,"tv":60.08,"id":10894176},{"batb":[[2,1.67,87.51]],"batl":[[0,1.79,190.18],[1,1.81,175.44],[2,1.82,42.01]],"ltp":2.04,"tv":49.79,"id":2263634}]}]}
{"op":"mcm","clk":"1007714483","pt":1580656585807,"mc":[{"id":"1.168224450","rc":[{"batb":[[0,2.3,18.65],[1,2.22,33.61],[2,2.14,22.98]],"ltp":1.96,"tv":60.08,"id":10894176}]}]}
{"op":"mcm","clk":"1007716813","pt":1580656596333,"mc":[{"id":"1.168224450","rc":[{"batb":[[1,1.7,214.08]],"ltp":2.04,"tv":49.79,"id":2263634}]}]}
{"op":"mcm","clk":"1007717556","pt":1580656599436,"mc":[{"id":"1.168224450","rc":[{"trd":[[2.3,1.94]],"batb":[[0,2.3,16.71]],"ltp":2.3,"tv":62.02,"id":10894176},{"trd":[[1.77,2.52]],"ltp":1.77,"tv":52.31,"id":2263634}],"tv":114.33}]}
{"op":"mcm","clk":"1007721154","pt":1580656614153,"mc":[{"id":"1.168224450","rc":[{"batb":[[0,2.22,33.61],[1,2.14,22.98],[2,1.77,402.27]],"ltp":2.3,"tv":62.02,"id":10894176},{"batb":[[0,1.67,62.17],[1,1.53,35.09],[2,1.46,435.7]],"batl":[[0,1.82,42.01],[1,1.81,0],[2,1.82,0]],"ltp":1.77,"tv":52.31,"id":2263634}]}]}
{"op":"mcm","clk":"1007721345","pt":1580656615059,"mc":[{"id":"1.168224450","rc":[{"batb":[[0,2.14,22.98],[1,1.77,402.27],[2,1.01,15.51]],"ltp":2.3,"tv":62.02,"id":10894176},{"batb":[[0,1.53,35.09],[1,1.46,435.7],[2,1.01,15.51]],"ltp":1.77,"tv":52.31,"id":2263634}]}]}
{"op":"mcm","clk":"1007721774","pt":1580656616863,"mc":[{"id":"1.168224450","rc":[{"batb":[[0,1.57,145.71],[1,1.56,147.1],[2,1.53,35.09]],"batl":[[0,1.89,108.55],[1,1.91,148.61]],"ltp":1.77,"tv":52.31,"id":2263634}]}]}
{"op":"mcm","clk":"1007721944","pt":1580656617635,"mc":[{"id":"1.168224450","rc":[{"batb":[[0,1.53,35.09],[1,1.46,435.7],[2,1.01,15.51]],"ltp":1.77,"tv":52.31,"id":2263634}]}]}
{"op":"mcm","clk":"1007722566","pt":1580656620365,"mc":[{"id":"1.168224450","rc":[{"batb":[[1,1.01,15.51],[2,1.01,0]],"ltp":1.77,"tv":52.31,"id":2263634}]}]}
{"op":"mcm","clk":"1007722815","pt":1580656621366,"mc":[{"id":"1.168224450","rc":[{"batb":[[1,2.04,26.52],[2,1.77,402.27]],"ltp":2.3,"tv":62.02,"id":10894176},{"batb":[[0,1.82,111.96],[1,1.8,176.71],[2,1.77,20.85]],"batl":[[0,1.89,108.55],[1,1.91,148.61]],"ltp":1.77,"tv":52.31,"id":2263634}]}]}
{"op":"mcm","clk":"1007722874","pt":1580656621542,"mc":[{"id":"1.168224450","rc":[{"batb":[[1,2.08,38.65],[2,2.04,26.52]],"batl":[[0,2.32,31.09]],"ltp":2.3,"tv":62.02,"id":10894176},{"batl":[[2,1.95,42.01]],"ltp":1.77,"tv":52.31,"id":2263634}]}]}
{"op":"mcm","clk":"1007725322","pt":1580656631269,"mc":[{"id":"1.168224450","rc":[{"batb":[[0,1.77,20.85],[1,1.76,54.61],[2,1.63,27.46]],"ltp":1.77,"tv":52.31,"id":2263634}]}]}
{"op":"mcm","clk":"1007725445","pt":1580656631883,"mc":[{"id":"1.168224450","rc":[{"batb":[[0,2.08,38.65],[1,2.04,26.52],[2,1.77,402.27]],"ltp":2.3,"tv":62.02,"id":10894176},{"batb":[[0,1.76,54.61],[1,1.63,27.46],[2,1.52,425.49]],"batl":[[0,1.95,42.01],[1,1.91,0],[2,1.95,0]],"ltp":1.77,"tv":52.31,"id":2263634}]}]}
{"op":"mcm","clk":"1007725567","pt":1580656632470,"mc":[{"id":"1.168224450","rc":[{"batb":[[0,2.04,26.52],[1,1.77,402.27],[2,1.01,15.51]],"ltp":2.3,"tv":62.02,"id":10894176},{"batb":[[0,1.63,27.46],[1,1.52,425.49],[2,1.01,15.51]],"ltp":1.77,"tv":52.31,"id":2263634}]}]}
{"op":"mcm","clk":"1007726046","pt":1580656634385,"mc":[{"id":"1.168224450","rc":[{"batb":[[0,1.79,117.85],[1,1.63,27.46],[2,1.52,425.49]],"ltp":1.77,"tv":52.31,"id":2263634}]}]}
{"op":"mcm","clk":"1007726597","pt":1580656636577,"mc":[{"id":"1.168224450","rc":[{"batb":[[1,1.77,186.81],[2,1.63,27.46]],"batl":[[0,1.86,126.89],[1,1.88,155.99]],"ltp":1.77,"tv":52.31,"id":2263634}]}]}
{"op":"mcm","clk":"1007727315","pt":1580656639693,"mc":[{"id":"1.168224450","rc":[{"batb":[[0,1.63,27.46],[1,1.52,425.49],[2,1.01,15.51]],"ltp":1.77,"tv":52.31,"id":2263634}]}]}
{"op":"mcm","clk":"1007728144","pt":1580656643289,"mc":[{"id":"1.168224450","rc":[{"batl":[[0,1.99,148.85],[1,2.02,189.4]],"ltp":1.77,"tv":52.31,"id":2263634}]}]}
{"op":"mcm","clk":"1007728841","pt":1580656646305,"mc":[{"id":"1.168224450","rc":[{"batb":[[0,1.9,150.18],[1,1.88,153.74],[2,1.63,27.46]],"ltp":1.77,"tv":52.31,"id":2263634}]}]}
{"op":"mcm","clk":"1007729116","pt":1580656647408,"mc":[{"id":"1.168224450","rc":[{"batb":[[1,1.97,29.74],[2,1.77,402.27]],"ltp":2.3,"tv":62.02,"id":10894176},{"batb":[[2,1.85,18.25]],"ltp":1.77,"tv":52.31,"id":2263634}]}]}
{"op":"mcm","clk":"1007729253","pt":1580656647991,"mc":[{"id":"1.168224450","rc":[{"batb":[[1,1.97,72.59]],"batl":[[0,2.18,35.29]],"ltp":2.3,"tv":62.02,"id":10894176},{"batl":[[2,2.04,40.33]],"ltp":1.77,"tv":52.31,"id":2263634}]}]}
{"op":"mcm","clk":"1007732020","pt":1580656659417,"mc":[{"id":"1.168224450","rc":[{"batb":[[0,1.85,18.25],[1,1.84,49.57],[2,1.74,22.03]],"batl":[[0,2.04,40.33],[1,2.02,0],[2,2.04,0]],"ltp":1.77,"tv":52.31,"id":2263634}]}]}
{"op":"mcm","clk":"1007732121","pt":1580656659809,"mc":[{"id":"1.168224450","rc":[{"batb":[[0,1.97,72.59],[1,1.77,402.27],[2,1.01,15.51]],"ltp":2.3,"tv":62.02,"id":10894176},{"batb":[[0,1.84,49.57],[1,1.74,22.03],[2,1.52,425.49]],"ltp":1.77,"tv":52.31,"id":2263634}]}]}
{"op":"mcm","clk":"1007732375","pt":1580656660839,"mc":[{"id":"1.168224450","rc":[{"batb":[[0,1.97,29.74]],"ltp":2.3,"tv":62.02,"id":10894176},{"batb":[[0,1.74,22.03],[1,1.52,425.49],[2,1.01,15.51]],"ltp":1.77,"tv":52.31,"id":2263634}]}]}
{"op":"mcm","clk":"1007732707","pt":1580656662207,"mc":[{"id":"1.168224450","rc":[{"batb":[[0,1.8,141.91],[1,1.78,183.45],[2,1.74,22.03]],"batl":[[0,2.06,160.3],[1,2.08,115.43]],"ltp":1.77,"tv":52.31,"id":2263634}]}]}
{"op":"mcm","clk":"1007733008","pt":1580656663419,"mc":[{"id":"1.168224450","rc":[{"batb":[[0,1.74,22.03],[1,1.52,425.49],[2,1.01,15.51]],"ltp":1.77,"tv":52.31,"id":2263634}]}]}
{"op":"mcm","clk":"1007733363","pt":1580656664923,"mc":[{"id":"1.168224450","rc":[{"batb":[[1,1.01,15.51],[2,1.01,0]],"ltp":1.77,"tv":52.31,"id":2263634}]}]}
{"op":"mcm","clk":"1007733685","pt":1580656666292,"mc":[{"id":"1.168224450","rc":[{"batb":[[1,1.95,123.4],[2,1.93,141.58]],"batl":[[0,2.04,137.16],[1,2.06,118.73]],"ltp":2.3,"tv":62.02,"id":10894176}]}]}
{"op":"mcm","clk":"1007733957","pt":1580656667434,"mc":[{"id":"1.168224450","rc":[{"batb":[[2,1.93,157.4]],"batl":[[2,2.18,185.25]],"ltp":2.3,"tv":62.02,"id":10894176},{"batb":[[0,1.91,16.29],[1,1.84,18.49],[2,1.01,15.51]],"ltp":1.77,"tv":52.31,"id":2263634}]}]}
{"op":"mcm","clk":"1007734049","pt":1580656667816,"mc":[{"id":"1.168224450","rc":[{"batl":[[2,2.1,37.81]],"ltp":2.3,"tv":62.02,"id":10894176},{"batb":[[1,1.9,46.21],[2,1.84,18.49]],"batl":[[0,2.12,36.97]],"ltp":1.77,"tv":52.31,"id":2263634}]}]}
{"op":"mcm","clk":"1007737188","pt":1580656680384,"mc":[{"id":"1.168224450","rc":[{"batb":[[1,1.93,15.82],[2,1.9,46.21]],"batl":[[0,2.1,37.81],[1,2.06,0],[2,2.1,0]],"ltp":2.3,"tv":62.02,"id":10894176}]}]}
{"op":"mcm","clk":"1007737289","pt":1580656680774,"mc":[{"id":"1.168224450","rc":[{"batb":[[0,1.93,15.82],[1,1.77,402.27],[2,1.01,15.51]],"ltp":2.3,"tv":62.02,"id":10894176},{"batb":[[0,1.84,18.49],[1,1.58,416.47],[2,1.01,15.51]],"ltp":1.77,"tv":52.31,"id":2263634}]}]}
{"op":"mcm","clk":"1007737903","pt":1580656683242,"mc":[{"id":"1.168224450","rc":[{"batb":[[1,1.92,110.37],[2,1.9,148.7]],"batl":[[0,2.12,176.25],[1,2.14,106.43]],"ltp":2.3,"tv":62.02,"id":10894176}]}]}
{"op":"mcm","clk":"1007737964","pt":1580656683466,"mc":[{"id":"1.168224450","rc":[{"batb":[[1,1.77,402.27],[2,1.01,15.51]],"ltp":2.3,"tv":62.02,"id":10894176}]}]}
{"op":"mcm","clk":"1007738337","pt":1580656685160,"mc":[{"id":"1.168224450","rc":[{"batb":[[0,1.95,131.72],[1,1.93,141.61],[2,1.84,18.49]],"batl":[[0,2.04,129.19],[1,2.06,118.7]],"ltp":1.77,"tv":52.31,"id":2263634}]}]}
{"op":"mcm","clk":"1007738623","pt":1580656686250,"mc":[{"id":"1.168224450","rc":[{"batl":[[0,2.04,131.71]],"ltp":1.77,"tv":52.31,"id":2263634}]}]}
{"op":"mcm","clk":"1007739063","pt":1580656688069,"mc":[{"id":"1.168224450","rc":[{"batb":[[0,1.84,18.49],[1,1.58,416.47],[2,1.01,15.51]],"batl":[[0,2.04,2.52],[1,2.06,0]],"ltp":1.77,"tv":52.31,"id":2263634}]}]}
{"op":"mcm","clk":"1007739814","pt":1580656691170,"mc":[{"id":"1.168224450","rc":[{"batb":[[0,1.9,142.73],[1,1.88,153.76],[2,1.84,18.49]],"ltp":1.77,"tv":52.31,"id":2263634}]}]}
{"op":"mcm","clk":"1007740606","pt":1580656694381,"mc":[{"id":"1.168224450","rc":[{"batb":[[0,2.04,26.2],[1,1.99,28.64],[2,1.96,43.69]],"batl":[[0,2.16,36.13]],"ltp":2.3,"tv":62.02,"id":10894176},{"batb":[[2,1.84,68.06]],"batl":[[0,1.99,156.02],[1,2.02,189.42],[2,2.04,42.85]],"ltp":1.77,"tv":52.31,"id":2263634}]}]}
{"op":"mcm","clk":"1007743540","pt":1580656707660,"mc":[{"id":"1.168224450","rc":[{"trd":[[2.04,62.48]],"batb":[[0,1.99,28.64],[1,1.96,43.69],[2,1.77,402.27]],"batl":[[0,2.04,23.8],[1,2.16,36.13]],"ltp":2.04,"tv":114.42,"id":10894176}],"tv":166.73}]}
{"op":"mcm","clk":"1007744422","pt":1580656711763,"mc":[{"id":"1.168224450","rc":[{"batb":[[0,1.84,49.57],[1,1.73,22.58],[2,1.58,416.47]],"batl":[[0,2.04,42.85],[1,2.02,0],[2,2.04,0]],"ltp":1.77,"tv":52.31,"id":2263634}]}]}
{"op":"mcm","clk":"1007744639","pt":1580656712794,"mc":[{"id":"1.168224450","rc":[{"batb":[[1,1.77,402.27],[2,1.01,15.51]],"batl":[[1,2.16,0]],"ltp":2.04,"tv":114.42,"id":10894176},{"batb":[[0,1.73,22.58],[1,1.58,416.47],[2,1.01,15.51]],"batl":[[0,2.04,2.52]],"ltp":1.77,"tv":52.31,"id":2263634}]}]}
{"op":"mcm","clk":"1007745049","pt":1580656714681,"mc":[{"id":"1.168224450","rc":[{"batb":[[0,1.97,29.43]],"ltp":2.04,"tv":114.42,"id":10894176},{"batb":[[0,1.77,22.03]],"ltp":1.77,"tv":52.31,"id":2263634}]}]}
{"op":"mcm","clk":"1007745568","pt":1580656717172,"mc":[{"id":"1.168224450","rc":[{"trd":[[2.04,86.28]],"ltp":2.04,"tv":138.22,"id":10894176},{"trd":[[1.96,26.52]],"batb":[[0,1.88,144.35],[1,1.86,159.07],[2,1.77,22.03]],"ltp":1.96,"tv":77.08,"id":2263634}],"tv":215.3}]}
{"op":"mcm","clk":"1007746396","pt":1580656720898,"mc":[{"id":"1.168224450","rc":[{"batl":[[0,1.97,161.83],[1,1.99,131.33],[2,2.04,2.52]],"ltp":1.96,"tv":77.08,"id":2263634}]}]}
{"op":"mcm","clk":"1007746645","pt":1580656722008,"mc":[{"id":"1.168224450","rc":[{"batb":[[0,1.77,22.03],[1,1.58,416.47],[2,1.01,15.51]],"batl":[[0,2.04,2.52],[1,1.99,0],[2,2.04,0]],"ltp":1.96,"tv":77.08,"id":2263634}]}]}
{"op":"mcm","clk":"1007747234","pt":1580656725020,"mc":[{"id":"1.168224450","rc":[{"batb":[[0,1.81,107.73],[1,1.79,180.01],[2,1.77,22.03]],"batl":[[1,2.06,179.92],[2,2.08,115.42]],"ltp":1.96,"tv":77.08,"id":2263634}]}]}
{"op":"mcm","clk":"1007747737","pt":1580656727100,"mc":[{"id":"1.168224450","rc":[{"batb":[[0,1.77,22.03],[1,1.58,416.47],[2,1.01,15.51]],"batl":[[1,2.06,0],[2,2.08,0]],"ltp":1.96,"tv":77.08,"id":2263634}]}]}
{"op":"mcm","clk":"1007748455","pt":1580656730181,"mc":[{"id":"1.168224450","rc":[{"batb":[[1,1.95,144.13],[2,1.93,141.59]],"batl":[[0,2.04,117.38],[1,2.06,158.22]],"ltp":2.04,"tv":138.22,"id":10894176},{"batb":[[0,1.94,60.97],[1,1.84,19.36],[2,1.77,22.03]],"batl":[[1,2.14,36.13]],"ltp":1.96,"tv":77.08,"id":2263634}]}]}
{"op":"mcm","clk":"1007748581","pt":1580656730688,"mc":[{"id":"1.168224450","rc":[{"batb":[[2,1.58,416.47]],"ltp":1.96,"tv":77.08,"id":2263634}]}]}
{"op":"mcm","clk":"1007750436","pt":1580656739333,"mc":[{"id":"1.168224450","rc":[{"batl":[[0,2.14,36.13],[1,2.14,0]],"ltp":1.96,"tv":77.08,"id":2263634}]}]}
{"op":"mcm","clk":"1007751128","pt":1580656742416,"mc":[{"id":"1.168224450","rc":[{"trd":[[2.04,88.7]],"batl":[[0,2.04,114.96]],"ltp":2.04,"tv":140.64,"id":10894176},{"trd":[[1.96,29.04]],"ltp":1.96,"tv":79.6,"id":2263634}],"tv":220.24}]}
{"op":"mcm","clk":"1007751836","pt":1580656745320,"mc":[{"id":"1.168224450","rc":[{"trd":[[2.04,92.34]],"batl":[[0,2.04,111.32]],"ltp":2.04,"tv":144.28,"id":10894176},{"trd":[[1.96,32.83]],"ltp":1.96,"tv":83.38,"id":2263634}],"tv":227.66}]}
{"op":"mcm","clk":"1007754509","pt":1580656757356,"mc":[{"id":"1.168224450","rc":[{"trd":[[2.04,286.5]],"batb":[[1,1.88,47.05],[2,1.77,423.2]],"batl":[[0,2.04,14.24]],"ltp":2.04,"tv":338.44,"id":10894176}],"tv":421.82}]}
{"op":"mcm","clk":"1007754591","pt":1580656757665,"mc":[{"id":"1.168224450","rc":[{"batl":[[0,2.06,39.49],[1,2.06,0]],"ltp":2.04,"tv":338.44,"id":10894176}]}]}
{"op":"mcm","clk":"1007755248","pt":1580656760370,"mc":[{"id":"1.168224450","rc":[{"batb":[[1,1.96,98.32],[2,1.94,139.35]],"ltp":2.04,"tv":338.44,"id":10894176}]}]}
{"op":"mcm","clk":"1007755364","pt":1580656760844,"mc":[{"id":"1.168224450","rc":[{"batb":[[1,1.88,47.05],[2,1.77,423.2]],"ltp":2.04,"tv":338.44,"id":10894176},{"batb":[[0,1.95,121.77],[1,1.94,60.97],[2,1.93,141.65]],"batl":[[0,2.04,119.98],[1,2.06,118.74],[2,2.14,36.13]],"ltp":1.96,"tv":83.38,"id":2263634}]}]}
{"op":"mcm","clk":"1007755731","pt":1580656762433,"mc":[{"id":"1.168224450","rc":[{"batl":[[0,2.04,138.89]],"ltp":1.96,"tv":83.38,"id":2263634}]}]}
{"op":"mcm","clk":"1007757859","pt":1580656772176,"mc":[{"id":"1.168224450","rc":[{"trd":[[1.95,2.02]],"batb":[[0,1.95,120.76]],"ltp":1.95,"tv":85.4,"id":2263634}],"tv":423.84}]}
{"op":"mcm","clk":"1007765965","pt":1580656808006,"mc":[{"id":"1.168224450","rc":[{"batb":[[0,1.88,47.05],[1,1.77,423.2],[2,1.01,15.51]],"ltp":2.04,"tv":338.44,"id":10894176},{"batb":[[0,1.94,44.53],[1,1.84,19.36],[2,1.58,416.47]],"batl":[[0,2.14,36.13],[1,2.06,0],[2,2.14,0]],"ltp":1.95,"tv":85.4,"id":2263634}]}]}
{"op":"mcm","clk":"1007766186","pt":1580656809026,"mc":[{"id":"1.168224450","rc":[{"batb":[[0,1.77,423.2],[1,1.01,15.51],[2,1.01,0]],"ltp":2.04,"tv":338.44,"id":10894176},{"batb":[[0,1.84,19.36],[1,1.58,416.47],[2,1.01,15.51]],"ltp":1.95,"tv":85.4,"id":2263634}]}]}
{"op":"mcm","clk":"1007767106","pt":1580656813341,"mc":[{"id":"1.168224450","rc":[{"batb":[[0,1.92,127.28],[1,1.9,148.8],[2,1.77,423.2]],"batl":[[0,2.02,217.59],[1,2.04,122.23]],"ltp":2.04,"tv":338.44,"id":10894176}]}]}
{"op":"mcm","clk":"1007767647","pt":1580656815917,"mc":[{"id":"1.168224450","rc":[{"batb":[[0,1.77,423.2],[1,1.01,15.51],[2,1.77,0]],"ltp":2.04,"tv":338.44,"id":10894176}]}]}
{"op":"mcm","clk":"1007768408","pt":1580656819335,"mc":[{"id":"1.168224450","rc":[{"batb":[[1,1.76,147.69],[2,1.74,198.58]],"ltp":2.04,"tv":338.44,"id":10894176}]}]}
{"op":"mcm","clk":"1007768605","pt":1580656820216,"mc":[{"id":"1.168224450","rc":[{"batb":[[0,1.77,20.93]],"ltp":2.04,"tv":338.44,"id":10894176},{"batb":[[1,1.01,15.51],[2,1.01,0]],"ltp":1.95,"tv":85.4,"id":2263634}]}]}
{"op":"mcm","clk":"1007768790","pt":1580656821118,"mc":[{"id":"1.168224450","rc":[{"batl":[[0,1.83,126.9],[1,1.85,164.61]],"ltp":2.04,"tv":338.44,"id":10894176}]}]}
{"op":"mcm","clk":"1007769085","pt":1580656822435,"mc":[{"id":"1.168224450","rc":[{"batl":[[2,1.87,42.01]],"ltp":2.04,"tv":338.44,"id":10894176},{"batb":[[0,2.18,22.98],[1,2.16,36.13],[2,2,29.98]],"batl":[[0,2.44,28.57]],"ltp":1.95,"tv":85.4,"id":2263634}]}]}
{"op":"mcm","clk":"1007771486","pt":1580656832377,"mc":[{"id":"1.168224450","rc":[{"batb":[[0,1.7,59.65],[1,1.55,420.5],[2,1.53,34.93]],"batl":[[0,1.87,42.01],[1,1.85,0],[2,1.87,0]],"ltp":2.04,"tv":338.44,"id":10894176},{"batb":[[0,2.16,36.13],[1,2,29.98],[2,1.7,409.32]],"ltp":1.95,"tv":85.4,"id":2263634}]}]}
{"op":"mcm","clk":"1007771614","pt":1580656832871,"mc":[{"id":"1.168224450","rc":[{"batb":[[0,1.55,420.5],[1,1.53,34.93],[2,1.01,15.51]],"ltp":2.04,"tv":338.44,"id":10894176},{"batb":[[0,2,29.98],[1,1.7,409.32],[2,1.01,15.51]],"ltp":1.95,"tv":85.4,"id":2263634}]}]}
{"op":"mcm","clk":"1007771911","pt":1580656834064,"mc":[{"id":"1.168224450","rc":[{"batl":[[0,2.2,1.68]],"ltp":1.95,"tv":85.4,"id":2263634}]}]}
{"op":"mcm","clk":"1007772455","pt":1580656836364,"mc":[{"id":"1.168224450","rc":[{"trd":[[1.83,2.02]],"batb":[[0,1.71,147.35],[1,1.69,219.63],[2,1.55,420.5]],"batl":[[0,1.78,175.75],[1,1.8,179.51]],"ltp":1.83,"tv":340.46,"id":10894176},{"trd":[[2.2,1.68]],"ltp":2.2,"tv":87.08,"id":2263634}],"tv":427.54}]}
{"op":"mcm","clk":"1007773394","pt":1580656840349,"mc":[{"id":"1.168224450","rc":[{"batb":[[0,1.55,420.5],[1,1.53,34.93],[2,1.01,15.51]],"ltp":1.83,"tv":340.46,"id":10894176}]}]}
{"op":"mcm","clk":"1007773978","pt":1580656842881,"mc":[{"id":"1.168224450","rc":[{"batb":[[1,1.53,273.66],[2,1.52,164.58]],"batl":[[0,1.99,102.92],[1,2.02,189.67]],"ltp":1.83,"tv":340.46,"id":10894176}]}]}
{"op":"mcm","clk":"1007776297","pt":1580656853391,"mc":[{"id":"1.168224450","rc":[{"batb":[[1,1.53,34.93],[2,1.01,15.51]],"ltp":1.83,"tv":340.46,"id":10894176}]}]}
{"op":"mcm","clk":"1007776730","pt":1580656855279,"mc":[{"id":"1.168224450","rc":[{"batb":[[0,1.53,34.93],[1,1.01,15.51],[2,1.01,0]],"ltp":1.83,"tv":340.46,"id":10894176}]}]}
{"op":"mcm","clk":"1007776943","pt":1580656856274,"mc":[{"id":"1.168224450","rc":[{"batb":[[0,1.91,123.62],[1,1.89,151.3],[2,1.53,34.93]],"ltp":1.83,"tv":340.46,"id":10894176}]}]}
{"op":"mcm","clk":"1007777159","pt":1580656857295,"mc":[{"id":"1.168224450","rc":[{"batb":[[0,1.91,139.83],[2,1.66,25.73]],"ltp":1.83,"tv":340.46,"id":10894176},{"batb":[[1,1.88,18.25],[2,1.7,409.32]],"ltp":2.2,"tv":87.08,"id":2263634}]}]}
{"op":"mcm","clk":"1007777257","pt":1580656857783,"mc":[{"id":"1.168224450","rc":[{"batb":[[2,1.82,50.41]],"batl":[[1,2.02,230.84]],"ltp":1.83,"tv":340.46,"id":10894176},{"batb":[[1,1.99,42.01],[2,1.88,18.25]],"batl":[[0,2.22,33.61]],"ltp":2.2,"tv":87.08,"id":2263634}]}]}
{"op":"mcm","clk":"1007781483","pt":1580656876008,"mc":[{"id":"1.168224450","rc":[{"batb":[[0,1.82,50.41],[1,1.66,25.73],[2,1.62,415.43]],"batl":[[0,2.02,41.17],[1,2.02,0]],"ltp":1.83,"tv":340.46,"id":10894176},{"batb":[[0,1.99,42.01],[1,1.88,18.25],[2,1.7,409.32]],"ltp":2.2,"tv":87.08,"id":2263634}]}]}
{"op":"mcm","clk":"1007781692","pt":1580656876912,"mc":[{"id":"1.168224450","rc":[{"batb":[[0,1.66,25.73],[1,1.62,415.43],[2,1.01,15.51]],"ltp":1.83,"tv":340.46,"id":10894176},{"batb":[[0,1.88,18.25],[1,1.7,409.32],[2,1.01,15.51]],"ltp":2.2,"tv":87.08,"id":2263634}]}]}
{"op":"mcm","clk":"1007782515","pt":1580656880725,"mc":[{"id":"1.168224450","rc":[{"batb":[[1,1.01,15.51],[2,1.01,0]],"ltp":1.83,"tv":340.46,"id":10894176},{"batb":[[1,1.01,15.51],[2,1.01,0]],"ltp":2.2,"tv":87.08,"id":2263634}]}]}
{"op":"mcm","clk":"1007782883","pt":1580656882384,"mc":[{"id":"1.168224450","rc":[{"batb":[[1,1.86,156.21],[2,1.84,164.64]],"batl":[[0,1.94,107.81],[1,1.96,137.45]],"ltp":2.2,"tv":87.08,"id":2263634}]}]}
{"op":"mcm","clk":"1007783055","pt":1580656883077,"mc":[{"id":"1.168224450","rc":[{"batb":[[0,2.04,26.44],[1,1.83,18.57],[2,1.01,15.51]],"ltp":1.83,"tv":340.46,"id":10894176}]}]}
{"op":"mcm","clk":"1007783284","pt":1580656884226,"mc":[{"id":"1.168224450","rc":[{"batb":[[1,1.95,43.69],[2,1.83,18.57]],"batl":[[0,2.18,35.29]],"ltp":1.83,"tv":340.46,"id":10894176},{"batb":[[2,1.85,48.73]],"batl":[[2,2.04,40.33]],"ltp":2.2,"tv":87.08,"id":2263634}]}]}
{"op":"mcm","clk":"1007784965","pt":1580656891934,"mc":[{"id":"1.168224450","rc":[{"batb":[[0,1.95,43.69],[1,1.83,18.57],[2,1.7,409.32]],"ltp":1.83,"tv":340.46,"id":10894176},{"trd":[[1.94,3.36]],"batb":[[0,1.85,48.73],[1,1.79,21.09],[2,1.55,420.5]],"batl":[[0,2.04,40.33],[1,1.96,0],[2,2.04,0]],"ltp":1.94,"tv":90.44,"id":2263634}],"tv":430.91}]}
{"op":"mcm","clk":"1007785226","pt":1580656893227,"mc":[{"id":"1.168224450","rc":[{"batb":[[0,1.83,18.57],[1,1.7,409.32],[2,1.01,15.51]],"ltp":1.83,"tv":340.46,"id":10894176},{"batb":[[0,1.79,21.09],[1,1.55,420.5],[2,1.01,15.51]],"ltp":1.94,"tv":90.44,"id":2263634}]}]}
{"op":"mcm","clk":"1007786264","pt":1580656898011,"mc":[{"id":"1.168224450","rc":[{"batb":[[0,1.9,141.72],[1,1.88,153.74],[2,1.79,21.09]],"batl":[[0,1.99,156.94],[1,2.02,189.42]],"ltp":1.94,"tv":90.44,"id":2263634}]}]}
{"op":"mcm","clk":"1007786731","pt":1580656900135,"mc":[{"id":"1.168224450","rc":[{"batb":[[0,1.79,21.09],[1,1.55,420.5],[2,1.01,15.51]],"ltp":1.94,"tv":90.44,"id":2263634}]}]}
{"op":"mcm","clk":"1007787688","pt":1580656904257,"mc":[{"id":"1.168224450","rc":[{"batb":[[1,1.76,197.38],[2,1.74,198.11]],"batl":[[0,2.16,94.39],[1,2.18,101.05]],"ltp":1.94,"tv":90.44,"id":2263634}]}]}
{"op":"mcm","clk":"1007787911","pt":1580656905238,"mc":[{"id":"1.168224450","rc":[{"batb":[[1,1.01,15.51],[2,1.01,0]],"ltp":1.83,"tv":340.46,"id":10894176},{"batb":[[1,1.74,198.11],[2,1.55,420.5]],"ltp":1.94,"tv":90.44,"id":2263634}]}]}
{"op":"mcm","clk":"1007788446","pt":1580656907260,"mc":[{"id":"1.168224450","rc":[{"batb":[[0,2.14,22.74],[1,2.02,27.46],[2,1.01,15.51]],"ltp":1.83,"tv":340.46,"id":10894176},{"batb":[[1,1.74,221.32]],"batl":[[0,1.84,164.86],[1,1.86,161.22]],"ltp":1.94,"tv":90.44,"id":2263634}]}]}
{"op":"mcm","clk":"1007788696","pt":1580656908233,"mc":[{"id":"1.168224450","rc":[{"batb":[[1,2.08,38.65],[2,2.02,27.46]],"batl":[[0,2.34,31.09]],"ltp":1.83,"tv":340.46,"id":10894176},{"batb":[[1,1.76,247.13],[2,1.74,221.32]],"batl":[[2,1.94,42.01]],"ltp":1.94,"tv":90.44,"id":2263634}]}]}
{"op":"mcm","clk":"1007791581","pt":1580656921333,"mc":[{"id":"1.168224450","rc":[{"batb":[[2,1.75,3.36]],"ltp":1.94,"tv":90.44,"id":2263634}]}]}
{"op":"mcm","clk":"1007791944","pt":1580656923014,"mc":[{"id":"1.168224450","rc":[{"batb":[[0,2.02,27.46],[1,1.77,402.27],[2,1.01,15.51]],"ltp":1.83,"tv":340.46,"id":10894176},{"batb":[[0,1.75,3.36],[1,1.74,23.21],[2,1.55,420.5]],"ltp":1.94,"tv":90.44,"id":2263634}]}]}
{"op":"mcm","clk":"1007792553","pt":1580656925694,"mc":[{"id":"1.168224450","rc":[{"batb":[[2,1.72,192.33]],"batl":[[0,1.94,156.69],[1,1.96,137.45]],"ltp":1.94,"tv":90.44,"id":2263634}]}]}
{"op":"mcm","clk":"1007794246","pt":1580656933304,"mc":[{"id":"1.168224450","rc":[{"batl":[[0,1.79,122.49],[1,1.81,175.8]],"ltp":1.94,"tv":90.44,"id":2263634}]}]}
{"op":"mcm","clk":"1007794466","pt":1580656934322,"mc":[{"id":"1.168224450","rc":[{"batb":[[0,2.22,20.54],[1,2.08,25.18],[2,1.77,402.27]],"batl":[[0,2.46,28.57]],"ltp":1.83,"tv":340.46,"id":10894176}]}]}
{"op":"mcm","clk":"1007794490","pt":1580656934472,"mc":[{"id":"1.168224450","rc":[{"batb":[[1,2.16,36.13],[2,2.08,25.18]],"ltp":1.83,"tv":340.46,"id":10894176},{"batl":[[2,1.86,42.01]],"ltp":1.94,"tv":90.44,"id":2263634}]}]}
{"op":"mcm","clk":"1007795018","pt":1580656936725,"mc":[{"id":"1.168224450","rc":[{"batb":[[0,1.74,23.21],[1,1.72,192.33],[2,1.7,214.82]],"ltp":1.94,"tv":90.44,"id":2263634}]}]}
{"op":"mcm","clk":"1007795745","pt":1580656939804,"mc":[{"id":"1.168224450","rc":[{"trd":[[1.79,6.72]],"batl":[[0,1.79,119.13]],"ltp":1.79,"tv":97.16,"id":2263634}],"tv":437.63}]}
{"op":"mcm","clk":"1007800043","pt":1580656959230,"mc":[{"id":"1.168224450","rc":[{"batb":[[0,2.08,25.18],[1,1.77,402.27],[2,1.01,15.51]],"ltp":1.83,"tv":340.46,"id":10894176},{"batb":[[0,1.57,33.05],[1,1.46,435.7],[2,1.01,15.51]],"ltp":1.79,"tv":97.16,"id":2263634}]}]}
{"op":"mcm","clk":"1007800731","pt":1580656962444,"mc":[{"id":"1.168224450","rc":[{"batb":[[1,1.56,228.06],[2,1.55,151.42]],"batl":[[0,1.91,145.3],[1,1.93,143.9]],"ltp":1.79,"tv":97.16,"id":2263634}]}]}
{"op":"mcm","clk":"1007801564","pt":1580656966340,"mc":[{"id":"1.168224450","rc":[{"batb":[[1,1.46,435.7],[2,1.01,15.51]],"ltp":1.79,"tv":97.16,"id":2263634}]}]}
{"op":"mcm","clk":"1007802007","pt":1580656968442,"mc":[{"id":"1.168224450","rc":[{"batb":[[1,1.01,15.51],[2,1.01,0]],"ltp":1.79,"tv":97.16,"id":2263634}]}]}
{"op":"mcm","clk":"1007802222","pt":1580656969366,"mc":[{"id":"1.168224450","rc":[{"batb":[[0,1.83,143.01],[1,1.81,173.57],[2,1.57,33.05]],"ltp":1.79,"tv":97.16,"id":2263634}]}]}
{"op":"mcm","clk":"1007802442","pt":1580656970363,"mc":[{"id":"1.168224450","rc":[{"batb":[[1,2.04,40.33],[2,1.97,29.43]],"batl":[[0,2.26,32.77]],"ltp":1.83,"tv":340.46,"id":10894176},{"batb":[[0,1.85,19.2],[1,1.83,143.01],[2,1.81,173.57]],"batl":[[2,1.97,42.01]],"ltp":1.79,"tv":97.16,"id":2263634}]}]}
{"op":"mcm","clk":"1007805230","pt":1580656982374,"mc":[{"id":"1.168224450","rc":[{"batb":[[0,2.04,40.33],[1,1.97,29.43],[2,1.77,402.27]],"ltp":1.83,"tv":340.46,"id":10894176},{"batb":[[0,1.79,52.93],[1,1.69,25.49],[2,1.52,425.49]],"batl":[[0,1.97,42.01],[1,1.93,0],[2,1.97,0]],"ltp":1.79,"tv":97.16,"id":2263634}]}]}
{"op":"mcm","clk":"1007805435","pt":1580656983300,"mc":[{"id":"1.168224450","rc":[{"batb":[[0,1.97,29.43],[1,1.77,402.27],[2,1.01,15.51]],"ltp":1.83,"tv":340.46,"id":10894176},{"batb":[[0,1.69,25.49],[1,1.52,425.49],[2,1.01,15.51]],"ltp":1.79,"tv":97.16,"id":2263634}]}]}
{"op":"mcm","clk":"1007805864","pt":1580656985073,"mc":[{"id":"1.168224450","rc":[{"batb":[[1,1.68,221.54],[2,1.66,233.35]],"batl":[[0,2.02,198.89],[1,2.04,122]],"ltp":1.79,"tv":97.16,"id":2263634}]}]}
{"op":"mcm","clk":"1007809542","pt":1580657001157,"mc":[{"id":"1.168224450","rc":[{"batb":[[1,1.52,425.49],[2,1.01,15.51]],"ltp":1.79,"tv":97.16,"id":2263634}]}]}
{"op":"mcm","clk":"1007809948","pt":1580657002828,"mc":[{"id":"1.168224450","rc":[{"batb":[[1,1.01,15.51],[2,1.01,0]],"ltp":1.79,"tv":97.16,"id":2263634}]}]}
{"op":"mcm","clk":"1007810244","pt":1580657004163,"mc":[{"id":"1.168224450","rc":[{"batb":[[0,1.92,146.26],[1,1.9,148.56],[2,1.69,25.49]],"ltp":1.79,"tv":97.16,"id":2263634}]}]}
{"op":"mcm","clk":"1007810534","pt":1580657005441,"mc":[{"id":"1.168224450","rc":[{"batb":[[1,1.91,16.21],[2,1.77,402.27]],"ltp":1.83,"tv":340.46,"id":10894176},{"batb":[[0,1.94,16.44],[1,1.92,146.26],[2,1.9,148.56]],"ltp":1.79,"tv":97.16,"id":2263634}]}]}
{"op":"mcm","clk":"1007810635","pt":1580657005833,"mc":[{"id":"1.168224450","rc":[{"batb":[[1,1.92,45.37],[2,1.91,16.21]],"batl":[[0,2.14,36.13]],"ltp":1.83,"tv":340.46,"id":10894176},{"batl":[[2,2.08,38.65]],"ltp":1.79,"tv":97.16,"id":2263634}]}]}
{"op":"mcm","clk":"1007814143","pt":1580657020375,"mc":[{"id":"1.168224450","rc":[{"batb":[[0,1.92,45.37],[1,1.91,16.21],[2,1.77,402.27]],"ltp":1.83,"tv":340.46,"id":10894176},{"batb":[[0,1.88,47.05],[1,1.82,20.14],[2,1.58,416.47]],"batl":[[0,2.08,38.65],[1,2.04,0],[2,2.08,0]],"ltp":1.79,"tv":97.16,"id":2263634}]}]}
{"op":"mcm","clk":"1007814288","pt":1580657020948,"mc":[{"id":"1.168224450","rc":[{"batb":[[0,1.91,16.21],[1,1.77,402.27],[2,1.01,15.51]],"ltp":1.83,"tv":340.46,"id":10894176},{"batb":[[0,1.82,20.14],[1,1.58,416.47],[2,1.01,15.51]],"ltp":1.79,"tv":97.16,"id":2263634}]}]}
{"op":"mcm","clk":"1007814829","pt":1580657023378,"mc":[{"id":"1.168224450","rc":[{"batb":[[0,1.92,16.13],[1,1.91,16.21],[2,1.77,402.27]],"ltp":1.83,"tv":340.46,"id":10894176}]}]}
{"op":"mcm","clk":"1007814895","pt":1580657023676,"mc":[{"id":"1.168224450","rc":[{"batb":[[1,1.77,402.27],[2,1.01,15.51]],"ltp":1.83,"tv":340.46,"id":10894176}]}]}
{"op":"mcm","clk":"1007815155","pt":1580657024851,"mc":[{"id":"1.168224450","rc":[{"batb":[[1,1.01,15.51],[2,1.01,0]],"ltp":1.83,"tv":340.46,"id":10894176},{"batb":[[1,1.01,15.51],[2,1.01,0]],"ltp":1.79,"tv":97.16,"id":2263634}]}]}
{"op":"mcm","clk":"1007815711","pt":1580657027374,"mc":[{"id":"1.168224450","rc":[{"batb":[[0,1.93,110.74],[1,1.92,16.13],[2,1.91,146.12]],"batl":[[0,2.02,163.5],[1,2.04,122.02]],"ltp":1.83,"tv":340.46,"id":10894176},{"batb":[[0,2,30.14],[1,1.92,17.15],[2,1.01,15.51]],"ltp":1.79,"tv":97.16,"id":2263634}]}]}
{"op":"mcm","clk":"1007815967","pt":1580657028379,"mc":[{"id":"1.168224450","rc":[{"batl":[[1,2.04,162.35]],"ltp":1.83,"tv":340.46,"id":10894176},{"batb":[[1,1.95,43.69],[2,1.92,17.15]],"batl":[[0,2.06,2.52],[1,2.18,35.29]],"ltp":1.79,"tv":97.16,"id":2263634}]}]}
{"op":"mcm","clk":"1007817578","pt":1580657035188,"mc":[{"id":"1.168224450","rc":[{"batb":[[0,1.88,17.07],[1,1.62,415.43],[2,1.01,15.51]],"ltp":1.83,"tv":340.46,"id":10894176},{"batb":[[0,1.92,17.15],[1,1.62,415.43],[2,1.01,15.51]],"batl":[[1,2.18,0]],"ltp":1.79,"tv":97.16,"id":2263634}]}]}
{"op":"mcm","clk":"1007818067","pt":1580657037363,"mc":[{"id":"1.168224450","rc":[{"batb":[[0,1.9,110.58],[1,1.88,170.67],[2,1.62,415.43]],"batl":[[0,2.08,105.16],[1,2.1,112.17]],"ltp":1.83,"tv":340.46,"id":10894176}]}]}
{"op":"mcm","clk":"1007820696","pt":1580657049231,"mc":[{"id":"1.168224450","rc":[{"batb":[[0,1.88,17.07],[1,1.62,415.43],[2,1.01,15.51]],"ltp":1.83,"tv":340.46,"id":10894176}]}]}
{"op":"mcm","clk":"1007821070","pt":1580657051094,"mc":[{"id":"1.168224450","rc":[{"batb":[[1,1.01,15.51],[2,1.01,0]],"ltp":1.83,"tv":340.46,"id":10894176}]}]}
{"op":"mcm","clk":"1007821280","pt":1580657052112,"mc":[{"id":"1.168224450","rc":[{"batb":[[0,1.92,173.99],[1,1.9,148.58],[2,1.62,415.43]],"batl":[[0,2.02,188.87],[1,2.04,122],[2,2.06,2.52]],"ltp":1.79,"tv":97.16,"id":2263634}]}]}
{"op":"mcm","clk":"1007821524","pt":1580657053207,"mc":[{"id":"1.168224450","rc":[{"batb":[[0,2,28.33],[1,1.94,15.58],[2,1.01,15.51]],"ltp":1.83,"tv":340.46,"id":10894176},{"batb":[[2,1.8,20.61]],"ltp":1.79,"tv":97.16,"id":2263634}]}]}
{"op":"mcm","clk":"1007821655","pt":1580657053798,"mc":[{"id":"1.168224450","rc":[{"batb":[[2,1.92,45.37]],"batl":[[0,2.12,36.97]],"ltp":1.83,"tv":340.46,"id":10894176},{"batb":[[2,1.89,47.05]],"ltp":1.79,"tv":97.16,"id":2263634}]}]}
{"op":"mcm","clk":"1007823531","pt":1580657062224,"mc":[{"id":"1.168224450","rc":[{"batl":[[2,2.1,37.81]],"ltp":1.79,"tv":97.16,"id":2263634}]}]}
{"op":"mcm","clk":"1007824170","pt":1580657065306,"mc":[{"id":"1.168224450","rc":[{"batl":[[0,2,2.52],[1,2.02,188.87],[2,2.04,122]],"ltp":1.79,"tv":97.16,"id":2263634}]}]}
{"op":"mcm","clk":"1007825960","pt":1580657073335,"mc":[{"id":"1.168224450","rc":[{"batb":[[0,1.94,15.58],[1,1.67,409.76],[2,1.01,15.51]],"ltp":1.83,"tv":340.46,"id":10894176},{"batb":[[0,1.8,20.61],[1,1.62,415.43],[2,1.01,15.51]],"batl":[[1,2.02,0],[2,2.04,0]],"ltp":1.79,"tv":97.16,"id":2263634}]}]}
{"op":"mcm","clk":"1007827058","pt":1580657077863,"mc":[{"id":"1.168224450","rc":[{"batb":[[0,1.9,149.81],[1,1.88,153.62],[2,1.8,20.61]],"batl":[[0,1.99,149.25],[1,2,2.52],[2,2.02,189.29]],"ltp":1.79,"tv":97.16,"id":2263634}]}]}
{"op":"mcm","clk":"1007828444","pt":1580657083967,"mc":[{"id":"1.168224450","rc":[{"batb":[[0,1.8,20.61],[1,1.62,415.43],[2,1.01,15.51]],"batl":[[0,2,2.52],[1,2,0],[2,2.02,0]],"ltp":1.79,"tv":97.16,"id":2263634}]}]}
{"op":"mcm","clk":"1007829234","pt":1580657087373,"mc":[{"id":"1.168224450","rc":[{"batb":[[0,1.82,154.66],[1,1.8,197.39],[2,1.62,415.43]],"batl":[[1,2.08,152.55],[2,2.1,112.19]],"ltp":1.79,"tv":97.16,"id":2263634}]}]}
{"op":"mcm","clk":"1007830978","pt":1580657095353,"mc":[{"id":"1.168224450","rc":[{"batb":[[0,1.8,20.61],[1,1.62,415.43],[2,1.01,15.51]],"batl":[[1,2.08,0],[2,2.1,0]],"ltp":1.79,"tv":97.16,"id":2263634}]}]}
{"op":"mcm","clk":"1007831604","pt":1580657098389,"mc":[{"id":"1.168224450","rc":[{"batb":[[1,1.93,135.21],[2,1.91,146.13]],"batl":[[0,2.02,140.18],[1,2.04,122.03]],"ltp":1.83,"tv":340.46,"id":10894176}]}]}
{"op":"mcm","clk":"1007831771","pt":1580657099181,"mc":[{"id":"1.168224450","rc":[{"batb":[[0,1.97,15.66],[1,1.88,18.25],[2,1.62,415.43]],"ltp":1.79,"tv":97.16,"id":2263634}]}]}
{"op":"mcm","clk":"1007831904","pt":1580657099877,"mc":[{"id":"1.168224450","rc":[{"batl":[[0,2.02,181.35]],"ltp":1.83,"tv":340.46,"id":10894176},{"batb":[[0,1.97,58.51]],"batl":[[1,2.2,34.45]],"ltp":1.79,"tv":97.16,"id":2263634}]}]}
{"op":"mcm","clk":"1007832543","pt":1580657102814,"mc":[{"id":"1.168224450","rc":[{"batl":[[0,2.2,34.45],[1,2.2,0]],"ltp":1.79,"tv":97.16,"id":2263634}]}]}
{"op":"mcm","clk":"1007833202","pt":1580657105939,"mc":[{"id":"1.168224450","rc":[{"trd":[[2.02,2.47]],"batl":[[0,2.02,178.88]],"ltp":2.02,"tv":342.93,"id":10894176},{"trd":[[1.98,2.52]],"ltp":1.98,"tv":99.68,"id":2263634}],"tv":442.62}]}
{"op":"mcm","clk":"1007839855","pt":1580657136717,"mc":[{"id":"1.168224450","rc":[{"batb":[[2,1.75,2.52]],"ltp":1.98,"tv":99.68,"id":2263634}]}]}
{"op":"mcm","clk":"1007843025","pt":1580657151719,"mc":[{"id":"1.168224450","rc":[{"trd":[[2.02,4.7]],"batl":[[0,2.02,176.65]],"ltp":2.02,"tv":345.16,"id":10894176},{"trd":[[1.98,4.79]],"ltp":1.98,"tv":101.96,"id":2263634}],"tv":447.12}]}
{"op":"mcm","clk":"1007843795","pt":1580657155337,"mc":[{"id":"1.168224450","rc":[{"batb":[[1,1.93,153.36]],"ltp":2.02,"tv":345.16,"id":10894176}]}]}
{"op":"mcm","clk":"1007850021","pt":1580657183000,"mc":[{"id":"1.168224450","rc":[{"batb":[[0,1.72,22.74],[1,1.67,409.76],[2,1.01,15.51]],"ltp":2.02,"tv":345.16,"id":10894176},{"batb":[[0,1.88,18.25],[1,1.75,2.52],[2,1.67,409.76]],"ltp":1.98,"tv":101.96,"id":2263634}]}]}
{"op":"mcm","clk":"1007850813","pt":1580657186386,"mc":[{"id":"1.168224450","rc":[{"batb":[[0,1.72,178.7],[1,1.7,214.71],[2,1.67,409.76]],"batl":[[0,2.16,119.38],[1,2.18,100.8]],"ltp":2.02,"tv":345.16,"id":10894176}]}]}
{"op":"mcm","clk":"1007852796","pt":1580657195177,"mc":[{"id":"1.168224450","rc":[{"batb":[[2,1.01,15.51]],"ltp":2.02,"tv":345.16,"id":10894176},{"batb":[[2,1.01,15.51]],"ltp":1.98,"tv":101.96,"id":2263634}]}]}
{"op":"mcm","clk":"1007853245","pt":1580657197180,"mc":[{"id":"1.168224450","rc":[{"batb":[[2,1.48,39.73]],"batl":[[0,1.79,157.87],[1,1.81,175.99]],"ltp":2.02,"tv":345.16,"id":10894176},{"batb":[[0,2.26,21.01],[1,2.06,27.62],[2,1.88,18.25]],"ltp":1.98,"tv":101.96,"id":2263634}]}]}
{"op":"mcm","clk":"1007853539","pt":1580657198398,"mc":[{"id":"1.168224450","rc":[{"batb":[[2,1.75,2.52]],"batl":[[0,2.54,26.89]],"ltp":1.98,"tv":101.96,"id":2263634}]}]}
{"op":"mcm","clk":"1007853751","pt":1580657199405,"mc":[{"id":"1.168224450","rc":[{"batb":[[2,1.82,401.24]],"ltp":1.98,"tv":101.96,"id":2263634}]}]}
{"op":"mcm","clk":"1007853924","pt":1580657200128,"mc":[{"id":"1.168224450","rc":[{"batb":[[2,1.65,63.85]],"ltp":2.02,"tv":345.16,"id":10894176}]}]}
{"op":"mcm","clk":"1007855823","pt":1580657208199,"mc":[{"id":"1.168224450","rc":[{"batb":[[0,1.65,63.85],[1,1.48,39.73],[2,1.46,435.7]],"ltp":2.02,"tv":345.16,"id":10894176},{"batb":[[0,2.06,27.62],[1,1.82,401.24],[2,1.75,2.52]],"ltp":1.98,"tv":101.96,"id":2263634}]}]}
{"op":"mcm","clk":"1007856010","pt":1580657209019,"mc":[{"id":"1.168224450","rc":[{"batb":[[0,1.48,39.73],[1,1.46,435.7],[2,1.01,15.51]],"ltp":2.02,"tv":345.16,"id":10894176}]}]}
{"op":"mcm","clk":"1007856428","pt":1580657210720,"mc":[{"id":"1.168224450","rc":[{"batb":[[0,1.48,294.53],[1,1.47,188.25],[2,1.46,435.7]],"batl":[[0,1.96,153.53],[1,1.98,133.32]],"ltp":2.02,"tv":345.16,"id":10894176},{"batb":[[0,2.04,27.77]],"ltp":1.98,"tv":101.96,"id":2263634}]}]}
{"op":"mcm","clk":"1007856630","pt":1580657211630,"mc":[{"id":"1.168224450","rc":[{"batb":[[0,1.79,1.68],[1,1.48,294.53],[2,1.47,188.25]],"ltp":2.02,"tv":345.16,"id":10894176}]}]}
{"op":"mcm","clk":"1007857986","pt":1580657216934,"mc":[{"id":"1.168224450","rc":[{"batb":[[0,1.48,39.5],[1,1.46,435.7],[2,1.01,15.51]],"ltp":2.02,"tv":345.16,"id":10894176}]}]}
{"op":"mcm","clk":"1007858352","pt":1580657218433,"mc":[{"id":"1.168224450","rc":[{"batb":[[1,1.01,15.51],[2,1.01,0]],"ltp":2.02,"tv":345.16,"id":10894176}]}]}
{"op":"mcm","clk":"1007858842","pt":1580657220350,"mc":[{"id":"1.168224450","rc":[{"batb":[[0,1.87,189.41],[1,1.85,161.81],[2,1.79,52.93]],"batl":[[0,1.96,195.54]],"ltp":2.02,"tv":345.16,"id":10894176},{"batb":[[0,2.04,68.1],[1,1.91,17.39],[2,1.82,401.24]],"batl":[[0,2.28,32.77]],"ltp":1.98,"tv":101.96,"id":2263634}]}]}
{"op":"mcm","clk":"1007862996","pt":1580657237334,"mc":[{"id":"1.168224450","rc":[{"batb":[[0,1.62,28.17],[1,1.55,420.5],[2,1.01,15.51]],"ltp":2.02,"tv":345.16,"id":10894176},{"batb":[[0,1.91,17.39],[1,1.82,401.24],[2,1.75,2.52]],"ltp":1.98,"tv":101.96,"id":2263634}]}]}
{"op":"mcm","clk":"1007863922","pt":1580657241238,"mc":[{"id":"1.168224450","rc":[{"batb":[[0,1.82,131.33],[1,1.8,176.89],[2,1.62,28.17]],"batl":[[0,1.9,165.72],[1,1.92,146.31]],"ltp":2.02,"tv":345.16,"id":10894176}]}]}
{"op":"mcm","clk":"1007864909","pt":1580657245358,"mc":[{"id":"1.168224450","rc":[{"batb":[[0,1.62,28.17],[1,1.55,420.5],[2,1.01,15.51]],"ltp":2.02,"tv":345.16,"id":10894176}]}]}
{"op":"mcm","clk":"1007865501","pt":1580657248068,"mc":[{"id":"1.168224450","rc":[{"batb":[[0,1.62,271.05],[1,1.61,131.57],[2,1.55,420.5]],"batl":[[0,2.14,177.08],[1,2.16,103.51]],"ltp":2.02,"tv":345.16,"id":10894176}]}]}
{"op":"mcm","clk":"1007865700","pt":1580657248995,"mc":[{"id":"1.168224450","rc":[{"batb":[[0,1.62,28.17],[1,1.55,420.5],[2,1.01,15.51]],"ltp":2.02,"tv":345.16,"id":10894176}]}]}
{"op":"mcm","clk":"1007866486","pt":1580657252155,"mc":[{"id":"1.168224450","rc":[{"batb":[[0,1.62,271.05],[1,1.61,131.57]],"batl":[[0,1.69,201.87],[1,1.71,211.94]],"ltp":2.02,"tv":345.16,"id":10894176},{"batb":[[1,1.75,2.52],[2,1.01,15.51]],"ltp":1.98,"tv":101.96,"id":2263634}]}]}
{"op":"mcm","clk":"1007866671","pt":1580657252996,"mc":[{"id":"1.168224450","rc":[{"batb":[[2,1.34,61.69]],"ltp":2.02,"tv":345.16,"id":10894176},{"batb":[[0,2.46,16.52],[1,2.14,24.39],[2,1.75,2.52]],"ltp":1.98,"tv":101.96,"id":2263634}]}]}
{"op":"mcm","clk":"1007866865","pt":1580657253869,"mc":[{"id":"1.168224450","rc":[{"batb":[[2,1.58,72.26]],"batl":[[2,1.72,42.01]],"ltp":2.02,"tv":345.16,"id":10894176},{"batb":[[1,2.4,29.41],[2,2.14,24.39]],"batl":[[0,2.74,23.53]],"ltp":1.98,"tv":101.96,"id":2263634}]}]}
{"op":"mcm","clk":"1007867550","pt":1580657256649,"mc":[{"id":"1.168224450","rc":[{"batb":[[0,1.62,156.34],[1,1.58,72.26],[2,1.38,448.45]],"ltp":2.02,"tv":345.16,"id":10894176}]}]}
{"op":"mcm","clk":"1007868393","pt":1580657260271,"mc":[{"id":"1.168224450","rc":[{"batb":[[0,1.63,119.77],[1,1.62,156.34],[2,1.58,72.26]],"ltp":2.02,"tv":345.16,"id":10894176}]}]}
{"op":"mcm","clk":"1007868535","pt":1580657260902,"mc":[{"id":"1.168224450","rc":[{"trd":[[1.69,3.36]],"batl":[[0,1.69,200.19]],"ltp":1.69,"tv":348.52,"id":10894176}],"tv":450.48}]}
{"op":"mcm","clk":"1007869992","pt":1580657267403,"mc":[{"id":"1.168224450","rc":[{"batb":[[0,1.38,448.45],[1,1.34,61.69],[2,1.01,15.51]],"ltp":1.69,"tv":348.52,"id":10894176},{"batb":[[0,2.14,24.39],[1,1.97,394.86],[2,1.75,2.52]],"ltp":1.98,"tv":101.96,"id":2263634}]}]}
{"op":"mcm","clk":"1007871010","pt":1580657271689,"mc":[{"id":"1.168224450","rc":[{"batb":[[0,1.56,235.75],[1,1.55,151.9],[2,1.38,448.45]],"batl":[[0,1.62,185.67],[1,1.63,124.38]],"ltp":1.69,"tv":348.52,"id":10894176}]}]}
{"op":"mcm","clk":"1007871405","pt":1580657273368,"mc":[{"id":"1.168224450","rc":[{"batb":[[0,1.38,448.45],[1,1.34,61.69],[2,1.01,15.51]],"ltp":1.69,"tv":348.52,"id":10894176}]}]}
{"op":"mcm","clk":"1007872057","pt":1580657276267,"mc":[{"id":"1.168224450","rc":[{"batb":[[1,1.35,397.46],[2,1.34,350.89]],"batl":[[0,1.89,107.24],[1,1.91,148.73]],"ltp":1.69,"tv":348.52,"id":10894176}]}]}
{"op":"mcm","clk":"1007872931","pt":1580657280108,"mc":[{"id":"1.168224450","rc":[{"batb":[[1,1.34,61.69],[2,1.01,15.51]],"ltp":1.69,"tv":348.52,"id":10894176}]}]}
{"op":"mcm","clk":"1007873467","pt":1580657282387,"mc":[{"id":"1.168224450","rc":[{"batb":[[0,1.34,61.69],[1,1.01,15.51],[2,1.01,0]],"ltp":1.69,"tv":348.52,"id":10894176},{"batb":[[1,1.75,2.52],[2,1.01,15.51]],"ltp":1.98,"tv":101.96,"id":2263634}]}]}
{"op":"mcm","clk":"1007873703","pt":1580657283380,"mc":[{"id":"1.168224450","rc":[{"batb":[[0,1.82,114.24],[1,1.8,196.57],[2,1.48,39.42]],"ltp":1.69,"tv":348.52,"id":10894176},{"batb":[[1,1.93,16.84],[2,1.75,2.52]],"ltp":1.98,"tv":101.96,"id":2263634}]}]}
{"op":"mcm","clk":"1007873808","pt":1580657283904,"mc":[{"id":"1.168224450","rc":[{"batb":[[2,1.73,57.13]],"batl":[[1,1.9,42.01],[2,1.91,148.73]],"ltp":1.69,"tv":348.52,"id":10894176},{"batb":[[1,2.1,37.81],[2,1.93,16.84]],"batl":[[0,2.36,30.25]],"ltp":1.98,"tv":101.96,"id":2263634}]}]}
{"op":"mcm","clk":"1007875898","pt":1580657293103,"mc":[{"id":"1.168224450","rc":[{"trd":[[2.14,10]],"batb":[[0,2.14,19.39]],"ltp":2.14,"tv":111.96,"id":2263634}],"tv":460.48}]}
{"op":"mcm","clk":"1007877425","pt":1580657299420,"mc":[{"id":"1.168224450","rc":[{"batb":[[0,1.8,19.75],[1,1.73,57.13],[2,1.5,426.9]],"batl":[[0,1.9,42.01],[1,1.9,0],[2,1.91,0]],"ltp":1.69,"tv":348.52,"id":10894176}]}]}
{"op":"mcm","clk":"1007877624","pt":1580657300316,"mc":[{"id":"1.168224450","rc":[{"batb":[[0,1.73,57.13],[1,1.5,426.9],[2,1.48,39.42]],"ltp":1.69,"tv":348.52,"id":10894176},{"batb":[[0,2.1,37.81],[1,1.93,16.84],[2,1.77,402.27]],"ltp":2.14,"tv":111.96,"id":2263634}]}]}
{"op":"mcm","clk":"1007877864","pt":1580657301360,"mc":[{"id":"1.168224450","rc":[{"batb":[[0,1.5,426.9],[1,1.48,39.42],[2,1.01,15.51]],"ltp":1.69,"tv":348.52,"id":10894176},{"batb":[[0,1.93,16.84],[1,1.77,402.27],[2,1.75,2.52]],"ltp":2.14,"tv":111.96,"id":2263634}]}]}
{"op":"mcm","clk":"1007878049","pt":1580657302121,"mc":[{"id":"1.168224450","rc":[{"batb":[[0,1.5,670.13],[1,1.49,177.86],[2,1.48,39.42]],"batl":[[0,2.14,153.5],[1,2.16,103.46]],"ltp":1.69,"tv":348.52,"id":10894176}]}]}
{"op":"mcm","clk":"1007878327","pt":1580657303219,"mc":[{"id":"1.168224450","rc":[{"batb":[[1,1.49,216.96],[2,1.01,15.51]],"ltp":1.69,"tv":348.52,"id":10894176},{"batb":[[0,1.92,17]],"ltp":2.14,"tv":111.96,"id":2263634}]}]}
{"op":"mcm","clk":"1007878835","pt":1580657305417,"mc":[{"id":"1.168224450","rc":[{"batb":[[0,1.5,426.9],[1,1.49,39.1]],"ltp":1.69,"tv":348.52,"id":10894176}]}]}
{"op":"mcm","clk":"1007880352","pt":1580657312160,"mc":[{"id":"1.168224450","rc":[{"batb":[[0,1.5,670.13],[1,1.49,216.96]],"batl":[[0,2.14,153.5],[1,2.16,103.46]],"ltp":1.69,"tv":348.52,"id":10894176}]}]}
{"op":"mcm","clk":"1007881307","pt":1580657316355,"mc":[{"id":"1.168224450","rc":[{"batb":[[0,1.5,426.9],[1,1.49,39.1]],"ltp":1.69,"tv":348.52,"id":10894176}]}]}
{"op":"mcm","clk":"1007881487","pt":1580657317145,"mc":[{"id":"1.168224450","rc":[{"batb":[[0,1.49,39.1],[1,1.01,15.51],[2,1.01,0]],"ltp":1.69,"tv":348.52,"id":10894176},{"batb":[[1,1.75,2.52],[2,1.01,15.51]],"ltp":2.14,"tv":111.96,"id":2263634}]}]}
{"op":"mcm","clk":"1007881995","pt":1580657319178,"mc":[{"id":"1.168224450","rc":[{"batb":[[1,1.88,152.9],[2,1.86,158.82]],"batl":[[0,1.97,162.24],[1,1.99,131.15]],"ltp":2.14,"tv":111.96,"id":2263634}]}]}
{"op":"mcm","clk":"1007882216","pt":1580657319983,"mc":[{"id":"1.168224450","rc":[{"batb":[[0,1.99,28.48],[1,1.76,21.09],[2,1.01,15.51]],"batl":[[0,2.16,36.13]],"ltp":1.69,"tv":348.52,"id":10894176},{"batb":[[1,1.88,199.95]],"ltp":2.14,"tv":111.96,"id":2263634}]}]}
{"op":"mcm","clk":"1007882385","pt":1580657320657,"mc":[{"id":"1.168224450","rc":[{"batb":[[2,1.62,415.43]],"ltp":1.69,"tv":348.52,"id":10894176}]}]}
{"op":"mcm","clk":"1007883984","pt":1580657327474,"mc":[{"id":"1.168224450","rc":[{"trd":[[2.02,6.38]],"ltp":2.02,"tv":350.2,"id":10894176},{"trd":[[1.97,1.72]],"batl":[[0,1.97,160.52]],"ltp":1.97,"tv":113.68,"id":2263634}],"tv":463.88}]}
{"op":"mcm","clk":"1007886213","pt":1580657337122,"mc":[{"id":"1.168224450","rc":[{"batb":[[0,1.76,21.09],[1,1.62,415.43],[2,1.01,15.51]],"ltp":2.02,"tv":350.2,"id":10894176},{"batb":[[0,1.81,20.46],[1,1.62,415.43],[2,1.01,15.51]],"ltp":1.97,"tv":113.68,"id":2263634}]}]}
{"op":"mcm","clk":"1007886927","pt":1580657340302,"mc":[{"id":"1.168224450","rc":[{"batb":[[1,1.77,180.12],[2,1.75,194.22]],"batl":[[0,2.26,137.23],[1,2.28,89.11]],"ltp":1.97,"tv":113.68,"id":2263634}]}]}
{"op":"mcm","clk":"1007888355","pt":1580657346414,"mc":[{"id":"1.168224450","rc":[{"batb":[[1,1.01,15.51],[2,1.01,0]],"ltp":2.02,"tv":350.2,"id":10894176}]}]}
{"op":"mcm","clk":"1007888575","pt":1580657347284,"mc":[{"id":"1.168224450","rc":[{"batl":[[0,1.85,166.24],[1,1.87,158.28]],"ltp":1.97,"tv":113.68,"id":2263634}]}]}
{"op":"mcm","clk":"1007888766","pt":1580657348156,"mc":[{"id":"1.168224450","rc":[{"batb":[[0,2.12,23.53],[1,2.1,37.81],[2,1.98,29.03]],"batl":[[0,2.36,30.25]],"ltp":2.02,"tv":350.2,"id":10894176},{"batl":[[2,1.92,42.01]],"ltp":1.97,"tv":113.68,"id":2263634}]}]}
{"op":"mcm","clk":"1007891151","pt":1580657359300,"mc":[{"id":"1.168224450","rc":[{"trd":[[1.85,4.8]],"batl":[[0,1.85,163.84]],"ltp":1.85,"tv":118.48,"id":2263634}],"tv":468.68}]}
{"op":"mcm","clk":"1007891609","pt":1580657361410,"mc":[{"id":"1.168224450","rc":[{"trd":[[1.85,9]],"batl":[[0,1.85,161.74]],"ltp":1.85,"tv":122.68,"id":2263634}],"tv":472.88}]}
{"op":"mcm","clk":"1007892896","pt":1580657367939,"mc":[{"id":"1.168224450","rc":[{"trd":[[1.85,9.06]],"batl":[[0,1.85,161.71]],"ltp":1.85,"tv":122.74,"id":2263634}],"tv":472.94}]}
{"op":"mcm","clk":"1007893738","pt":1580657372327,"mc":[{"id":"1.168224450","rc":[{"batb":[[1,1.74,56.29],[2,1.62,415.43]],"batl":[[0,1.92,42.01],[1,1.87,0],[2,1.92,0]],"ltp":1.85,"tv":122.74,"id":2263634}]}]}
{"op":"mcm","clk":"1007893875","pt":1580657373026,"mc":[{"id":"1.168224450","rc":[{"batb":[[0,1.98,28.88],[1,1.7,409.32],[2,1.01,15.51]],"ltp":2.02,"tv":350.2,"id":10894176},{"batb":[[0,1.62,415.43],[1,1.61,30.14],[2,1.01,15.51]],"ltp":1.85,"tv":122.74,"id":2263634}]}]}
{"op":"mcm","clk":"1007894540","pt":1580657376423,"mc":[{"id":"1.168224450","rc":[{"batb":[[2,1.59,157.5]],"batl":[[0,1.98,103.28],[1,2,129.17]],"ltp":1.85,"tv":122.74,"id":2263634}]}]}
{"op":"mcm","clk":"1007895620","pt":1580657381289,"mc":[{"id":"1.168224450","rc":[{"batb":[[2,1.01,15.51]],"ltp":1.85,"tv":122.74,"id":2263634}]}]}
{"op":"mcm","clk":"1007896300","pt":1580657384434,"mc":[{"id":"1.168224450","rc":[{"batb":[[0,1.98,71.73],[1,1.89,16.76],[2,1.7,409.32]],"ltp":2.02,"tv":350.2,"id":10894176},{"batb":[[0,1.93,16.76],[1,1.9,129.68],[2,1.88,153.38]],"batl":[[2,2.02,41.17]],"ltp":1.85,"tv":122.74,"id":2263634}]}]}
{"op":"mcm","clk":"1007896394","pt":1580657384822,"mc":[{"id":"1.168224450","rc":[{"batb":[[0,1.98,28.88]],"batl":[[0,2.16,36.13]],"ltp":2.02,"tv":350.2,"id":10894176},{"batl":[[2,2.02,0]],"ltp":1.85,"tv":122.74,"id":2263634}]}]}
{"op":"mcm","clk":"1007897105","pt":1580657387947,"mc":[{"id":"1.168224450","rc":[{"batb":[[1,1.95,43.69],[2,1.89,16.76]],"ltp":2.02,"tv":350.2,"id":10894176},{"batl":[[2,2.06,39.49]],"ltp":1.85,"tv":122.74,"id":2263634}]}]}
{"op":"mcm","clk":"1007899565","pt":1580657399391,"mc":[{"id":"1.168224450","rc":[{"batb":[[0,1.95,43.69],[1,1.89,16.76],[2,1.7,409.32]],"ltp":2.02,"tv":350.2,"id":10894176},{"batb":[[0,1.85,48.73],[1,1.75,22.82],[2,1.62,415.43]],"batl":[[0,2.06,39.49],[1,2,0],[2,2.06,0]],"ltp":1.85,"tv":122.74,"id":2263634}]}]}
{"op":"mcm","clk":"1007899964","pt":1580657400962,"mc":[{"id":"1.168224450","rc":[{"batb":[[0,1.89,16.76],[1,1.7,409.32],[2,1.01,15.51]],"ltp":2.02,"tv":350.2,"id":10894176},{"batb":[[0,1.75,22.82],[1,1.62,415.43],[2,1.01,15.51]],"ltp":1.85,"tv":122.74,"id":2263634}]}]}
{"op":"mcm","clk":"1007900341","pt":1580657402380,"mc":[{"id":"1.168224450","rc":[{"batb":[[1,1.73,157.91],[2,1.71,209.69]],"batl":[[0,2.1,122.16],[1,2.12,109.04]],"ltp":1.85,"tv":122.74,"id":2263634}]}]}
{"op":"mcm","clk":"1007901412","pt":1580657406253,"mc":[{"id":"1.168224450","rc":[{"batb":[[1,1.62,415.43],[2,1.01,15.51]],"ltp":1.85,"tv":122.74,"id":2263634}]}]}
{"op":"mcm","clk":"1007902051","pt":1580657409151,"mc":[{"id":"1.168224450","rc":[{"batb":[[0,1.91,127.6],[1,1.89,167.63]],"batl":[[0,1.99,98.52],[1,2.02,189.13]],"ltp":2.02,"tv":350.2,"id":10894176},{"batb":[[1,1.01,15.51],[2,1.01,0]],"ltp":1.85,"tv":122.74,"id":2263634}]}]}
{"op":"mcm","clk":"1007902333","pt":1580657410365,"mc":[{"id":"1.168224450","rc":[{"batb":[[2,1.84,67.9]],"batl":[[2,2.04,40.33]],"ltp":2.02,"tv":350.2,"id":10894176},{"batb":[[0,2.02,28.88],[1,1.97,42.85],[2,1.89,17.7]],"batl":[[0,2.2,34.45]],"ltp":1.85,"tv":122.74,"id":2263634}]}]}
{"op":"mcm","clk":"1007905766","pt":1580657426315,"mc":[{"id":"1.168224450","rc":[{"batb":[[0,1.84,67.9],[1,1.55,420.5],[2,1.01,15.51]],"batl":[[0,2.04,40.33],[1,2.02,0],[2,2.04,0]],"ltp":2.02,"tv":350.2,"id":10894176},{"batb":[[0,1.97,42.85],[1,1.89,17.7],[2,1.7,409.32]],"ltp":1.85,"tv":122.74,"id":2263634}]}]}
{"op":"mcm","clk":"1007905914","pt":1580657427003,"mc":[{"id":"1.168224450","rc":[{"batb":[[0,1.84,18.33]],"ltp":2.02,"tv":350.2,"id":10894176},{"batb":[[0,1.89,17.7],[1,1.7,409.32],[2,1.01,15.51]],"ltp":1.85,"tv":122.74,"id":2263634}]}]}
{"op":"mcm","clk":"1007906890","pt":1580657431419,"mc":[{"id":"1.168224450","rc":[{"batb":[[0,1.93,156.61],[1,1.91,145.96],[2,1.84,18.33]],"batl":[[0,2.02,119.47],[1,2.04,121.88]],"ltp":2.02,"tv":350.2,"id":10894176}]}]}
{"op":"mcm","clk":"1007907678","pt":1580657435143,"mc":[{"id":"1.168224450","rc":[{"batb":[[0,1.84,18.33],[1,1.55,420.5],[2,1.01,15.51]],"ltp":2.02,"tv":350.2,"id":10894176}]}]}
{"op":"mcm","clk":"1007907765","pt":1580657435525,"mc":[{"id":"1.168224450","rc":[{"batl":[[0,2.1,2.52]],"ltp":1.85,"tv":122.74,"id":2263634}]}]}
{"op":"mcm","clk":"1007908805","pt":1580657440133,"mc":[{"id":"1.168224450","rc":[{"batb":[[1,1.01,15.51],[2,1.01,0]],"ltp":2.02,"tv":350.2,"id":10894176}]}]}
{"op":"mcm","clk":"1007909126","pt":1580657441327,"mc":[{"id":"1.168224450","rc":[{"batb":[[1,1.88,146.85],[2,1.86,158.72]],"batl":[[0,1.96,101.33],[1,1.98,133.1],[2,2.1,2.52]],"ltp":1.85,"tv":122.74,"id":2263634}]}]}
{"op":"mcm","clk":"1007909329","pt":1580657442029,"mc":[{"id":"1.168224450","rc":[{"batb":[[0,2.02,27.3],[1,1.94,44.53],[2,1.9,16.37]],"batl":[[0,2.18,35.29]],"ltp":2.02,"tv":350.2,"id":10894176},{"batb":[[2,1.86,207.45]],"batl":[[2,2.06,39.49]],"ltp":1.85,"tv":122.74,"id":2263634}]}]}
{"op":"mcm","clk":"1007913586","pt":1580657460987,"mc":[{"id":"1.168224450","rc":[{"batb":[[0,1.9,16.37],[1,1.62,415.43],[2,1.01,15.51]],"ltp":2.02,"tv":350.2,"id":10894176},{"batb":[[0,1.7,409.32],[1,1.69,25.65],[2,1.01,15.51]],"batl":[[0,2.1,2.52],[1,1.98,0],[2,2.06,0]],"ltp":1.85,"tv":122.74,"id":2263634}]}]}
{"op":"mcm","clk":"1007914622","pt":1580657465477,"mc":[{"id":"1.168224450","rc":[{"batb":[[1,1.01,15.51],[2,1.01,0]],"ltp":2.02,"tv":350.2,"id":10894176},{"batb":[[0,1.69,25.65],[1,1.01,15.51],[2,1.01,0]],"ltp":1.85,"tv":122.74,"id":2263634}]}]}
{"op":"mcm","clk":"1007914942","pt":1580657466956,"mc":[{"id":"1.168224450","rc":[{"batb":[[0,1.84,128.05],[1,1.82,170.2],[2,1.69,25.65]],"batl":[[0,1.92,150.69],[1,1.94,141.45],[2,2.1,2.52]],"ltp":1.85,"tv":122.74,"id":2263634}]}]}
{"op":"mcm","clk":"1007915390","pt":1580657468875,"mc":[{"id":"1.168224450","rc":[{"batb":[[1,1.67,409.76],[2,1.01,15.51]],"ltp":2.02,"tv":350.2,"id":10894176}]}]}
{"op":"mcm","clk":"1007915653","pt":1580657470080,"mc":[{"id":"1.168224450","rc":[{"batb":[[0,1.69,25.65],[1,1.58,416.47],[2,1.01,15.51]],"batl":[[0,2.1,2.52],[1,1.94,0],[2,2.1,0]],"ltp":1.85,"tv":122.74,"id":2263634}]}]}
{"op":"mcm","clk":"1007916351","pt":1580657473003,"mc":[{"id":"1.168224450","rc":[{"batb":[[1,1.68,217.93],[2,1.66,232.92]],"batl":[[0,2.1,94.21],[1,2.12,109.04]],"ltp":1.85,"tv":122.74,"id":2263634}]}]}
{"op":"mcm","clk":"1007917409","pt":1580657477990,"mc":[{"id":"1.168224450","rc":[{"batb":[[1,1.01,15.51],[2,1.01,0]],"ltp":2.02,"tv":350.2,"id":10894176}]}]}
{"op":"mcm","clk":"1007917656","pt":1580657479030,"mc":[{"id":"1.168224450","rc":[{"batb":[[1,1.01,15.51],[2,1.66,0]],"batl":[[0,2.1,2.52],[1,2.12,0]],"ltp":1.85,"tv":122.74,"id":2263634}]}]}
{"op":"mcm","clk":"1007918179","pt":1580657481426,"mc":[{"id":"1.168224450","rc":[{"batb":[[0,1.9,185.57],[1,1.88,153.47],[2,1.01,15.51]],"batl":[[0,1.99,130.66],[1,2.02,189.13]],"ltp":2.02,"tv":350.2,"id":10894176}]}]}
{"op":"mcm","clk":"1007918403","pt":1580657482429,"mc":[{"id":"1.168224450","rc":[{"batb":[[2,1.84,18.18]],"batl":[[1,2.02,230.3]],"ltp":2.02,"tv":350.2,"id":10894176},{"batb":[[0,2,29.58],[1,1.98,42.85],[2,1.88,18.1]],"batl":[[1,2.2,34.45]],"ltp":1.85,"tv":122.74,"id":2263634}]}]}
{"op":"mcm","clk":"1007919437","pt":1580657487135,"mc":[{"id":"1.168224450","rc":[{"batl":[[0,2.2,34.45],[1,2.2,0]],"ltp":1.85,"tv":122.74,"id":2263634}]}]}
{"op":"mcm","clk":"1007920153","pt":1580657490228,"mc":[{"id":"1.168224450","rc":[{"trd":[[2,5.04]],"batb":[[0,2,27.06]],"ltp":2.0,"tv":127.78,"id":2263634}],"tv":477.98}]}
{"op":"mcm","clk":"1007922304","pt":1580657500149,"mc":[{"id":"1.168224450","rc":[{"batb":[[0,1.9,16.37],[1,1.84,18.18],[2,1.83,50.41]],"batl":[[0,2.02,41.17],[1,2.02,0]],"ltp":2.02,"tv":350.2,"id":10894176}]}]}
{"op":"mcm","clk":"1007922515","pt":1580657501066,"mc":[{"id":"1.168224450","rc":[{"batb":[[0,1.84,18.18],[1,1.01,15.51],[2,1.83,0]],"ltp":2.02,"tv":350.2,"id":10894176},{"batb":[[0,1.88,18.1],[1,1.01,15.51],[2,1.88,0]],"ltp":2.0,"tv":127.78,"id":2263634}]}]}
{"op":"mcm","clk":"1007922999","pt":1580657503444,"mc":[{"id":"1.168224450","rc":[{"batb":[[0,1.85,142.78],[1,1.84,18.18],[2,1.83,167.22]],"batl":[[0,2.12,122.47],[1,2.14,106.15]],"ltp":2.02,"tv":350.2,"id":10894176}]}]}
{"op":"mcm","clk":"1007923097","pt":1580657503890,"mc":[{"id":"1.168224450","rc":[{"batb":[[1,1.83,167.22],[2,1.01,15.51]],"ltp":2.02,"tv":350.2,"id":10894176}]}]}
{"op":"mcm","clk":"1007924666","pt":1580657510444,"mc":[{"id":"1.168224450","rc":[{"batb":[[0,1.85,18.1],[1,1.01,15.51],[2,1.01,0]],"ltp":2.02,"tv":350.2,"id":10894176}]}]}
{"op":"mcm","clk":"1007925342","pt":1580657513344,"mc":[{"id":"1.168224450","rc":[{"batb":[[0,2.04,26.67],[1,1.9,16.44],[2,1.85,18.1]],"ltp":2.02,"tv":350.2,"id":10894176},{"batb":[[0,1.89,159.13],[1,1.88,18.1],[2,1.87,156.05]],"batl":[[0,1.98,148.14],[1,2,129.16]],"ltp":2.0,"tv":127.78,"id":2263634}]}]}
{"op":"mcm","clk":"1007925579","pt":1580657514391,"mc":[{"id":"1.168224450","rc":[{"batb":[[1,1.92,45.37],[2,1.9,16.44]],"batl":[[0,2.16,36.13]],"ltp":2.02,"tv":350.2,"id":10894176},{"batb":[[1,1.88,65.15]],"batl":[[2,2.08,38.65]],"ltp":2.0,"tv":127.78,"id":2263634}]}]}
{"op":"mcm","clk":"1007929649","pt":1580657531366,"mc":[{"id":"1.168224450","rc":[{"batb":[[0,1.92,45.37],[1,1.9,16.44],[2,1.62,415.43]],"ltp":2.02,"tv":350.2,"id":10894176},{"batb":[[0,1.88,47.05],[1,1.8,1.68],[2,1.66,27.22]],"batl":[[0,2.08,38.65],[1,2,0],[2,2.08,0]],"ltp":2.0,"tv":127.78,"id":2263634}]}]}
{"op":"mcm","clk":"1007930112","pt":1580657533275,"mc":[{"id":"1.168224450","rc":[{"batb":[[0,1.9,16.44],[1,1.62,415.43],[2,1.01,15.51]],"ltp":2.02,"tv":350.2,"id":10894176},{"batb":[[0,1.8,1.68],[1,1.66,27.22],[2,1.01,15.51]],"ltp":2.0,"tv":127.78,"id":2263634}]}]}
{"op":"mcm","clk":"1007930363","pt":1580657535320,"mc":[{"id":"1.168224450","rc":[{"batb":[[0,1.89,16.68]],"ltp":2.02,"tv":350.2,"id":10894176},{"batb":[[1,1.67,205.74],[2,1.66,117.07]],"batl":[[0,2.14,119.91],[1,2.16,103.37]],"ltp":2.0,"tv":127.78,"id":2263634}]}]}
{"op":"mcm","clk":"1007933353","pt":1580657548780,"mc":[{"id":"1.168224450","rc":[{"batb":[[1,1.67,26.91],[2,1.01,15.51]],"ltp":2.0,"tv":127.78,"id":2263634}]}]}
{"op":"mcm","clk":"1007933622","pt":1580657550194,"mc":[{"id":"1.168224450","rc":[{"batb":[[1,1.01,15.51],[2,1.01,0]],"ltp":2.02,"tv":350.2,"id":10894176}]}]}
{"op":"mcm","clk":"1007934155","pt":1580657552494,"mc":[{"id":"1.168224450","rc":[{"batb":[[0,1.84,174.77],[1,1.82,170.3],[2,1.8,1.68]],"batl":[[0,1.92,106.23],[1,1.94,141.52]],"ltp":2.0,"tv":127.78,"id":2263634}]}]}
{"op":"mcm","clk":"1007934556","pt":1580657554291,"mc":[{"id":"1.168224450","rc":[{"batb":[[1,1.67,409.76],[2,1.01,15.51]],"ltp":2.02,"tv":350.2,"id":10894176}]}]}
{"op":"mcm","clk":"1007935205","pt":1580657557221,"mc":[{"id":"1.168224450","rc":[{"batb":[[0,1.8,1.68],[1,1.67,26.91],[2,1.58,416.47]],"ltp":2.0,"tv":127.78,"id":2263634}]}]}
{"op":"mcm","clk":"1007935859","pt":1580657560440,"mc":[{"id":"1.168224450","rc":[{"batb":[[1,1.01,15.51],[2,1.01,0]],"ltp":2.02,"tv":350.2,"id":10894176},{"batb":[[2,1.01,15.51]],"ltp":2.0,"tv":127.78,"id":2263634}]}]}
{"op":"mcm","clk":"1007936277","pt":1580657562315,"mc":[{"id":"1.168224450","rc":[{"batb":[[1,1.88,114.76],[2,1.86,158.78]],"batl":[[0,1.96,132.2],[1,1.98,133.17]],"ltp":2.02,"tv":350.2,"id":10894176}]}]}
{"op":"mcm","clk":"1007936402","pt":1580657562911,"mc":[{"id":"1.168224450","rc":[{"batb":[[0,2,29.03],[1,1.9,17.47],[2,1.8,1.68]],"ltp":2.0,"tv":127.78,"id":2263634}]}]}
{"op":"mcm","clk":"1007936731","pt":1580657564390,"mc":[{"id":"1.168224450","rc":[{"batl":[[0,1.96,174.21]],"ltp":2.02,"tv":350.2,"id":10894176},{"batb":[[0,2.04,40.33],[1,2,29.03],[2,1.9,17.47]],"batl":[[0,2.3,31.93]],"ltp":2.0,"tv":127.78,"id":2263634}]}]}
{"op":"mcm","clk":"1007956186","pt":1580657649247,"mc":[{"id":"1.168224450","rc":[{"batb":[[0,1.67,25.41],[1,1.55,420.5],[2,1.01,15.51]],"ltp":2.02,"tv":350.2,"id":10894176},{"batb":[[0,1.9,17.47],[1,1.8,1.68],[2,1.7,409.32]],"ltp":2.0,"tv":127.78,"id":2263634}]}]}
{"op":"mcm","clk":"1007956837","pt":1580657651925,"mc":[{"id":"1.168224450","rc":[{"batb":[[1,1.66,126.62],[2,1.65,119.77]],"batl":[[0,2.12,175.89],[1,2.14,106.17]],"ltp":2.02,"tv":350.2,"id":10894176}]}]}
{"op":"mcm","clk":"1007958014","pt":1580657657430,"mc":[{"id":"1.168224450","rc":[{"batl":[[0,1.72,154.33],[1,1.74,199.88]],"ltp":2.02,"tv":350.2,"id":10894176},{"batb":[[2,1.01,15.51]],"ltp":2.0,"tv":127.78,"id":2263634}]}]}
{"op":"mcm","clk":"1007958210","pt":1580657658349,"mc":[{"id":"1.168224450","rc":[{"batb":[[0,2.36,18.57],[1,2.1,25.34],[2,1.9,17.47]],"batl":[[0,2.72,24.37]],"ltp":2.0,"tv":127.78,"id":2263634}]}]}
{"op":"mcm","clk":"1007958298","pt":1580657658737,"mc":[{"id":"1.168224450","rc":[{"batl":[[1,1.73,42.01],[2,1.74,199.88]],"ltp":2.02,"tv":350.2,"id":10894176},{"batb":[[0,2.38,30.25],[1,2.36,18.57],[2,2.1,25.34]],"ltp":2.0,"tv":127.78,"id":2263634}]}]}
{"op":"mcm","clk":"1007960233","pt":1580657667381,"mc":[{"id":"1.168224450","rc":[{"batb":[[0,1.44,436.18],[1,1.42,47.45],[2,1.01,15.51]],"ltp":2.02,"tv":350.2,"id":10894176},{"batb":[[0,2.1,25.34],[1,1.86,398.62],[2,1.8,1.68]],"ltp":2.0,"tv":127.78,"id":2263634}]}]}
{"op":"mcm","clk":"1007960858","pt":1580657670296,"mc":[{"id":"1.168224450","rc":[{"batb":[[2,1.41,309.34]],"batl":[[0,1.9,159.72],[1,1.92,146.12]],"ltp":2.02,"tv":350.2,"id":10894176}]}]}
{"op":"mcm","clk":"1007961076","pt":1580657671307,"mc":[{"id":"1.168224450","rc":[{"batb":[[0,1.42,47.45],[1,1.01,15.51],[2,1.41,0]],"ltp":2.02,"tv":350.2,"id":10894176},{"batb":[[1,1.8,1.68],[2,1.01,15.51]],"ltp":2.0,"tv":127.78,"id":2263634}]}]}
{"op":"mcm","clk":"1007962014","pt":1580657675450,"mc":[{"id":"1.168224450","rc":[{"batb":[[1,1.38,448.45],[2,1.01,15.51]],"ltp":2.02,"tv":350.2,"id":10894176},{"batb":[[1,1.97,394.86],[2,1.8,1.68]],"ltp":2.0,"tv":127.78,"id":2263634}]}]}
{"op":"mcm","clk":"1007962692","pt":1580657678602,"mc":[{"id":"1.168224450","rc":[{"batb":[[1,1.41,313.32],[2,1.4,233.09]],"batl":[[0,1.9,156.79],[1,1.92,146.11]],"ltp":2.02,"tv":350.2,"id":10894176}]}]}
{"op":"mcm","clk":"1007966861","pt":1580657697393,"mc":[{"id":"1.168224450","rc":[{"batl":[[0,1.46,271.73],[1,1.47,183.09]],"ltp":2.02,"tv":350.2,"id":10894176},{"batb":[[1,1.8,1.68],[2,1.01,15.51]],"ltp":2.0,"tv":127.78,"id":2263634}]}]}
{"op":"mcm","clk":"1007967061","pt":1580657698322,"mc":[{"id":"1.168224450","rc":[{"batb":[[0,3.1,22.19],[1,2.62,14.08],[2,1.8,1.68]],"batl":[[0,3.65,15.12]],"ltp":2.0,"tv":127.78,"id":2263634}]}]}
{"op":"mcm","clk":"1007967384","pt":1580657699767,"mc":[{"id":"1.168224450","rc":[{"batl":[[2,1.48,42.01]],"ltp":2.02,"tv":350.2,"id":10894176},{"batb":[[0,3.1,41.51]],"ltp":2.0,"tv":127.78,"id":2263634}]}]}
{"op":"mcm","clk":"1007967580","pt":1580657700817,"mc":[{"id":"1.168224450","rc":[{"batb":[[2,2.3,385.09]],"ltp":2.0,"tv":127.78,"id":2263634}]}]}
{"op":"mcm","clk":"1007970377","pt":1580657713132,"mc":[{"id":"1.168224450","rc":[{"batb":[[1,1.38,110.07],[2,1.25,505.09]],"batl":[[0,1.48,42.01],[1,1.47,0],[2,1.48,0]],"ltp":2.02,"tv":350.2,"id":10894176}]}]}
{"op":"mcm","clk":"1007970500","pt":1580657713464,"mc":[{"id":"1.168224450","rc":[{"batb":[[0,1.38,110.07],[1,1.25,505.09],[2,1.19,118.89]],"ltp":2.02,"tv":350.2,"id":10894176},{"batb":[[0,3.1,19.32]],"ltp":2.0,"tv":127.78,"id":2263634}]}]}
{"op":"mcm","clk":"1007970872","pt":1580657715134,"mc":[{"id":"1.168224450","rc":[{"batb":[[0,1.19,118.89],[1,1.01,15.51],[2,1.19,0]],"ltp":2.02,"tv":350.2,"id":10894176},{"batb":[[0,2.62,14.08],[1,1.8,1.68],[2,1.01,15.51]],"ltp":2.0,"tv":127.78,"id":2263634}]}]}
{"op":"mcm","clk":"1007971732","pt":1580657718954,"mc":[{"id":"1.168224450","rc":[{"batb":[[0,1.36,402.42],[1,1.35,278.1],[2,1.19,118.89]],"batl":[[0,1.41,343.93],[1,1.42,210.99]],"ltp":2.02,"tv":350.2,"id":10894176}]}]}
{"op":"mcm","clk":"1007971936","pt":1580657719936,"mc":[{"id":"1.168224450","rc":[{"batb":[[2,1.23,516.48]],"ltp":2.02,"tv":350.2,"id":10894176},{"batb":[[1,2.38,382.3],[2,1.8,1.68]],"ltp":2.0,"tv":127.78,"id":2263634}]}]}
{"op":"mcm","clk":"1007972264","pt":1580657721350,"mc":[{"id":"1.168224450","rc":[{"batb":[[0,1.23,516.48],[1,1.19,118.89],[2,1.01,15.51]],"ltp":2.02,"tv":350.2,"id":10894176}]}]}
{"op":"mcm","clk":"1007972601","pt":1580657722843,"mc":[{"id":"1.168224450","rc":[{"batb":[[0,1.19,118.89],[1,1.01,15.51],[2,1.01,0]],"ltp":2.02,"tv":350.2,"id":10894176},{"batb":[[1,1.8,1.68],[2,1.01,15.51]],"ltp":2.0,"tv":127.78,"id":2263634}]}]}
{"op":"mcm","clk":"1007972875","pt":1580657724243,"mc":[{"id":"1.168224450","rc":[{"batb":[[0,1.2,537.95],[1,1.19,650.98],[2,1.01,15.51]],"batl":[[0,1.62,215.08],[1,1.63,124.05]],"ltp":2.02,"tv":350.2,"id":10894176}]}]}
{"op":"mcm","clk":"1007975233","pt":1580657735069,"mc":[{"id":"1.168224450","rc":[{"batl":[[0,1.23,420.59],[1,1.24,417.67]],"ltp":2.02,"tv":350.2,"id":10894176}]}]}
{"op":"mcm","clk":"1007975468","pt":1580657736260,"mc":[{"id":"1.168224450","rc":[{"batb":[[0,1.2,705.99],[2,1.06,391.99]],"ltp":2.02,"tv":350.2,"id":10894176},{"batb":[[0,5.3,12.35],[1,4,23.05],[2,1.8,1.68]],"batl":[[0,6,8.4]],"ltp":2.0,"tv":127.78,"id":2263634}]}]}
{"op":"mcm","clk":"1007975656","pt":1580657737164,"mc":[{"id":"1.168224450","rc":[{"batb":[[2,1.13,629.97]],"ltp":2.02,"tv":350.2,"id":10894176},{"batb":[[2,2.9,375.84]],"ltp":2.0,"tv":127.78,"id":2263634}]}]}
{"op":"mcm","clk":"1007977061","pt":1580657743553,"mc":[{"id":"1.168224450","rc":[{"trd":[[1.2,9.46]],"batb":[[0,1.2,701.26]],"ltp":1.2,"tv":359.66,"id":10894176}],"tv":487.44}]}
{"op":"mcm","clk":"1007977999","pt":1580657748354,"mc":[{"id":"1.168224450","rc":[{"batb":[[0,1.2,168.04],[1,1.19,118.89]],"ltp":1.2,"tv":359.66,"id":10894176}]}]}
{"op":"mcm","clk":"1007978152","pt":1580657749052,"mc":[{"id":"1.168224450","rc":[{"batb":[[0,1.13,629.97],[1,1.06,390.89],[2,1.01,15.51]],"ltp":1.2,"tv":359.66,"id":10894176},{"batb":[[0,4,23.05],[1,2.9,375.84],[2,1.01,15.51]],"ltp":2.0,"tv":127.78,"id":2263634}]}]}
{"op":"mcm","clk":"1007978375","pt":1580657750174,"mc":[{"id":"1.168224450","rc":[{"batb":[[0,1.06,390.89],[1,1.01,15.51],[2,1.01,0]],"ltp":1.2,"tv":359.66,"id":10894176},{"batb":[[1,1.01,15.51],[2,1.01,0]],"ltp":2.0,"tv":127.78,"id":2263634}]}]}
{"op":"mcm","clk":"1007978615","pt":1580657751360,"mc":[{"id":"1.168224450","rc":[{"batb":[[0,1.08,379.02],[1,1.07,812.52],[2,1.06,390.89]],"batl":[[0,1.32,331.74],[1,1.33,285.87]],"ltp":1.2,"tv":359.66,"id":10894176}]}]}
{"op":"mcm","clk":"1007979610","pt":1580657756363,"mc":[{"id":"1.168224450","rc":[{"batl":[[0,1.09,424.73],[1,1.1,748.28],[2,1.12,42.01]],"ltp":1.2,"tv":359.66,"id":10894176},{"batb":[[0,12,9.13],[1,9.4,4.2],[2,6.8,13.85]],"batl":[[0,12.5,3.36]],"ltp":2.0,"tv":127.78,"id":2263634}]}]}
{"op":"mcm","clk":"1007982108","pt":1580657768000,"mc":[{"id":"1.168224450","rc":[{"batb":[[0,1.08,331.22]],"batl":[[1,1.1,699.14]],"ltp":1.2,"tv":359.66,"id":10894176}]}]}
{"op":"mcm","clk":"1007982546","pt":1580657770034,"mc":[{"id":"1.168224450","rc":[{"batb":[[1,1.07,847.36]],"ltp":1.2,"tv":359.66,"id":10894176}]}]}
{"op":"mcm","clk":"1007982735","pt":1580657770931,"mc":[{"id":"1.168224450","rc":[{"batl":[[0,1.09,474.32]],"ltp":1.2,"tv":359.66,"id":10894176}]}]}
{"op":"mcm","clk":"1007987694","pt":1580657793252,"mc":[{"id":"1.168224450","rc":[{"batb":[[0,1.06,390.89],[1,1.03,1571.88],[2,1.02,818.92]],"batl":[[0,1.12,42.01],[1,1.1,0],[2,1.12,0]],"ltp":1.2,"tv":359.66,"id":10894176}]}]}
{"op":"mcm","clk":"1007988370","pt":1580657796367,"mc":[{"id":"1.168224450","rc":[{"batb":[[0,1.04,1163.31],[2,1.02,817.66]],"batl":[[1,1.18,501.9],[2,1.19,549.44]],"ltp":1.2,"tv":359.66,"id":10894176},{"batb":[[0,9.4,4.2],[1,6.8,13.85],[2,3.85,370.95]],"ltp":2.0,"tv":127.78,"id":2263634}]}]}
{"op":"mcm","clk":"1007988584","pt":1580657797382,"mc":[{"id":"1.168224450","rc":[{"batb":[[1,1.02,817.66],[2,1.01,15.51]],"batl":[[0,1.18,501.9],[1,1.19,549.44],[2,1.19,0]],"ltp":1.2,"tv":359.66,"id":10894176},{"batb":[[0,6.8,13.85],[1,1.01,15.51],[2,3.85,0]],"ltp":2.0,"tv":127.78,"id":2263634}]}]}
{"op":"mcm","clk":"1007990405","pt":1580657806369,"mc":[{"id":"1.168224450","rc":[{"batl":[[0,1.05,1006.22],[1,1.06,216.53]],"ltp":1.2,"tv":359.66,"id":10894176},{"batb":[[0,20,5.27],[1,10,13.06],[2,1.01,15.51]],"ltp":2.0,"tv":127.78,"id":2263634}]}]}
{"op":"mcm","clk":"1007990746","pt":1580657807979,"mc":[{"id":"1.168224450","rc":[{"batb":[[2,1.01,3892.94]],"ltp":1.2,"tv":359.66,"id":10894176},{"batb":[[2,4.2,372.95]],"ltp":2.0,"tv":127.78,"id":2263634}]}]}
{"op":"mcm","clk":"1007992955","pt":1580657817910,"mc":[{"id":"1.168224450","rc":[{"batl":[[2,1.07,42.01]],"ltp":1.2,"tv":359.66,"id":10894176}]}]}
{"op":"mcm","clk":"1007993722","pt":1580657821414,"mc":[{"id":"1.168224450","rc":[{"batb":[[0,1.01,3892.94],[1,1.02,0],[2,1.01,0]],"batl":[[0,1.07,42.01],[1,1.06,0],[2,1.07,0]],"ltp":1.2,"tv":359.66,"id":10894176},{"batb":[[0,10,13.06],[1,4.2,372.95],[2,1.01,15.51]],"ltp":2.0,"tv":127.78,"id":2263634}]}]}
{"op":"mcm","clk":"1007994140","pt":1580657823176,"mc":[{"id":"1.168224450","rc":[{"batb":[[0,1.01,15.51]],"ltp":1.2,"tv":359.66,"id":10894176},{"batb":[[1,1.01,15.51],[2,1.01,0]],"ltp":2.0,"tv":127.78,"id":2263634}]}]}
{"op":"mcm","clk":"1007994502","pt":1580657824969,"mc":[{"id":"1.168224450","rc":[{"batb":[[0,1.01,1288.84]],"batl":[[0,1.11,864.04],[1,1.12,291.94]],"ltp":1.2,"tv":359.66,"id":10894176}]}]}
{"op":"mcm","clk":"1007998030","pt":1580657840432,"mc":[{"id":"1.168224450","rc":[{"batb":[[0,1.01,15.51]],"ltp":1.2,"tv":359.66,"id":10894176}]}]}
{"op":"mcm","clk":"1007998618","pt":1580657843029,"mc":[{"id":"1.168224450","rc":[{"batb":[[0,1.09,922.41],[1,1.08,259.84],[2,1.01,15.51]],"ltp":1.2,"tv":359.66,"id":10894176}]}]}
{"op":"mcm","clk":"1007998858","pt":1580657844015,"mc":[{"id":"1.168224450","rc":[{"batb":[[2,1.07,317.64]],"batl":[[2,1.13,42.01]],"ltp":1.2,"tv":359.66,"id":10894176},{"batb":[[1,8.8,5.04],[2,5.5,11.09]],"batl":[[0,11.5,3.36]],"ltp":2.0,"tv":127.78,"id":2263634}]}]}
{"op":"mcm","clk":"1008003640","pt":1580657865372,"mc":[{"id":"1.168224450","rc":[{"batb":[[0,1.05,1069.56],[1,1.02,761.25],[2,1.01,15.51]],"batl":[[0,1.13,42.01],[1,1.12,0],[2,1.13,0]],"ltp":1.2,"tv":359.66,"id":10894176},{"batb":[[0,8.8,5.04],[1,5.5,11.09],[2,3.6,374.22]],"ltp":2.0,"tv":127.78,"id":2263634}]}]}
{"op":"mcm","clk":"1008004076","pt":1580657867156,"mc":[{"id":"1.168224450","rc":[{"batb":[[0,1.02,761.25],[1,1.01,15.51],[2,1.01,0]],"ltp":1.2,"tv":359.66,"id":10894176},{"batb":[[0,5.5,11.09],[1,1.01,15.51],[2,3.6,0]],"ltp":2.0,"tv":127.78,"id":2263634}]}]}
{"op":"mcm","clk":"1008004292","pt":1580657868071,"mc":[{"id":"1.168224450","rc":[{"batb":[[0,1.04,1236.6],[1,1.02,761.25],[2,1.01,15.51]],"batl":[[0,1.23,533.89],[1,1.24,418.79]],"ltp":1.2,"tv":359.66,"id":10894176}]}]}
{"op":"mcm","clk":"1008005211","pt":1580657872177,"mc":[{"id":"1.168224450","rc":[{"batl":[[0,1.05,552.45],[1,1.06,666.03]],"ltp":1.2,"tv":359.66,"id":10894176},{"batb":[[0,19.5,5.98],[1,9.2,7],[2,5.5,11.09]],"ltp":2.0,"tv":127.78,"id":2263634}]}]}
{"op":"mcm","clk":"1008005445","pt":1580657873259,"mc":[{"id":"1.168224450","rc":[{"batb":[[2,1.01,4081.97]],"ltp":1.2,"tv":359.66,"id":10894176},{"batb":[[2,4.1,374.13]],"ltp":2.0,"tv":127.78,"id":2263634}]}]}
{"op":"mcm","clk":"1008008152","pt":1580657885373,"mc":[{"id":"1.168224450","rc":[{"batb":[[0,1.02,761.25],[1,1.01,4081.97],[2,1.01,0]],"ltp":1.2,"tv":359.66,"id":10894176}]}]}
{"op":"mcm","clk":"1008008216","pt":1580657885709,"mc":[{"id":"1.168224450","rc":[{"batb":[[0,1.01,4081.97],[1,1.01,0]],"ltp":1.2,"tv":359.66,"id":10894176},{"batb":[[0,9.2,7],[1,4.1,374.13],[2,1.01,15.51]],"ltp":2.0,"tv":127.78,"id":2263634}]}]}
{"op":"mcm","clk":"1008008759","pt":1580657888308,"mc":[{"id":"1.168224450","rc":[{"batb":[[0,1.01,1288.84]],"batl":[[0,1.13,937.95],[1,1.14,198.39]],"ltp":1.2,"tv":359.66,"id":10894176},{"batb":[[1,1.01,15.51],[2,1.01,0]],"ltp":2.0,"tv":127.78,"id":2263634}]}]}
{"op":"mcm","clk":"1008008806","pt":1580657888487,"mc":[{"id":"1.168224450","rc":[{"batb":[[0,1.01,15.51]],"ltp":1.2,"tv":359.66,"id":10894176}]}]}
{"op":"mcm","clk":"1008009389","pt":1580657891102,"mc":[{"id":"1.168224450","rc":[{"batb":[[0,1.05,1224.82],[1,1.01,15.51]],"batl":[[0,1.07,1201.93]],"ltp":1.2,"tv":359.66,"id":10894176}]}]}
{"op":"mcm","clk":"1008009900","pt":1580657893386,"mc":[{"id":"1.168224450","rc":[{"batb":[[1,1.02,2184.08],[2,1.01,15.51]],"ltp":1.2,"tv":359.66,"id":10894176},{"batb":[[1,4,369.93],[2,1.01,15.51]],"ltp":2.0,"tv":127.78,"id":2263634}]}]}
{"op":"mcm","clk":"1008010315","pt":1580657895377,"mc":[{"id":"1.168224450","rc":[{"batb":[[0,1.02,2184.08],[1,1.01,15.51],[2,1.01,0]],"ltp":1.2,"tv":359.66,"id":10894176}]}]}
{"op":"mcm","clk":"1008010613","pt":1580657896482,"mc":[{"id":"1.168224450","rc":[{"batb":[[0,1.01,15.51],[1,1.01,0]],"ltp":1.2,"tv":359.66,"id":10894176},{"batb":[[1,1.01,15.51],[2,1.01,0]],"ltp":2.0,"tv":127.78,"id":2263634}]}]}
{"op":"mcm","clk":"1008010928","pt":1580657897894,"mc":[{"id":"1.168224450","rc":[{"batb":[[0,1.01,1288.84]],"batl":[[0,1.13,939.52],[1,1.14,196.85]],"ltp":1.2,"tv":359.66,"id":10894176}]}]}
{"op":"mcm","clk":"1008013590","pt":1580657909163,"mc":[{"id":"1.168224450","rc":[{"batl":[[0,1.02,1260.85]],"ltp":1.2,"tv":359.66,"id":10894176},{"batb":[[0,22,3.89]],"ltp":2.0,"tv":127.78,"id":2263634}]}]}
{"op":"mcm","clk":"1008013926","pt":1580657910587,"mc":[{"id":"1.168224450","rc":[{"batb":[[1,4.6,373.8],[2,1.01,15.51]],"ltp":2.0,"tv":127.78,"id":2263634}]}]}
{"op":"mcm","clk":"1008017911","pt":1580657928364,"mc":[{"id":"1.168224450","rc":[{"batb":[[0,1.01,15.51]],"ltp":1.2,"tv":359.66,"id":10894176}]}]}
{"op":"mcm","clk":"1008018183","pt":1580657929770,"mc":[{"id":"1.168224450","rc":[{"batb":[[1,1.01,15.51],[2,1.01,0]],"ltp":2.0,"tv":127.78,"id":2263634}]}]}
{"op":"mcm","clk":"1008018535","pt":1580657931408,"mc":[{"id":"1.168224450","rc":[{"batl":[[0,1.05,1224.82]],"ltp":1.2,"tv":359.66,"id":10894176}]}]}
{"op":"mcm","clk":"1008019034","pt":1580657933375,"mc":[{"id":"1.168224450","rc":[{"batb":[[0,1.01,1288.84]],"batl":[[0,1.02,863.03],[1,1.03,393.95]],"ltp":1.2,"tv":359.66,"id":10894176}]}]}
{"op":"mcm","clk":"1008019387","pt":1580657935005,"mc":[{"id":"1.168224450","rc":[{"batb":[[1,4.6,368.39],[2,1.01,15.51]],"ltp":2.0,"tv":127.78,"id":2263634}]}]}
{"op":"mcm","clk":"1008019661","pt":1580657936301,"mc":[{"id":"1.168224450","rc":[{"batb":[[0,1.01,15.51]],"ltp":1.2,"tv":359.66,"id":10894176}]}]}
{"op":"mcm","clk":"1008020082","pt":1580657938187,"mc":[{"id":"1.168224450","rc":[{"batb":[[1,1.01,15.51],[2,1.01,0]],"ltp":2.0,"tv":127.78,"id":2263634}]}]}
{"op":"mcm","clk":"1008020456","pt":1580657940012,"mc":[{"id":"1.168224450","rc":[{"batl":[[0,1.05,1224.82]],"ltp":1.2,"tv":359.66,"id":10894176}]}]}
{"op":"mcm","clk":"1008021743","pt":1580657945437,"mc":[{"id":"1.168224450","rc":[{"batb":[[0,1.03,1248.61],[1,1.02,915.94],[2,1.01,15.51]],"ltp":1.2,"tv":359.66,"id":10894176},{"batb":[[1,8.6,7.79],[2,1.01,15.51]],"ltp":2.0,"tv":127.78,"id":2263634}]}]}
{"op":"mcm","clk":"1008022153","pt":1580657947127,"mc":[{"id":"1.168224450","rc":[{"batb":[[2,4.3,371.17]],"batl":[[0,160,37.1]],"ltp":2.0,"tv":127.78,"id":2263634}]}]}
{"op":"mcm","clk":"1008025839","pt":1580657963127,"mc":[{"id":"1.168224450","rc":[{"batb":[[0,1.01,15.51],[1,1.02,0],[2,1.01,0]],"ltp":1.2,"tv":359.66,"id":10894176},{"batb":[[0,8.6,7.79],[1,4.3,371.17],[2,1.01,15.51]],"ltp":2.0,"tv":127.78,"id":2263634}]}]}
{"op":"mcm","clk":"1008026055","pt":1580657964040,"mc":[{"id":"1.168224450","rc":[{"batb":[[1,1.01,15.51],[2,1.01,0]],"ltp":2.0,"tv":127.78,"id":2263634}]}]}
{"op":"mcm","clk":"1008027055","pt":1580657968352,"mc":[{"id":"1.168224450","rc":[{"batb":[[0,1.05,781.98],[1,1.04,447.1],[2,1.01,15.51]],"batl":[[0,1.06,844.7],[1,1.07,365.12]],"ltp":1.2,"tv":359.66,"id":10894176}]}]}
{"op":"mcm","clk":"1008027506","pt":1580657970339,"mc":[{"id":"1.168224450","rc":[{"batb":[[2,1.01,4081.97]],"ltp":1.2,"tv":359.66,"id":10894176},{"batb":[[1,4.1,374.13],[2,1.01,15.51]],"ltp":2.0,"tv":127.78,"id":2263634}]}]}
{"op":"mcm","clk":"1008027789","pt":1580657971544,"mc":[{"id":"1.168224450","rc":[{"batb":[[0,1.01,4081.97],[1,1.04,0],[2,1.01,0]],"ltp":1.2,"tv":359.66,"id":10894176}]}]}
{"op":"mcm","clk":"1008028260","pt":1580657973427,"mc":[{"id":"1.168224450","rc":[{"batb":[[0,1.01,15.51]],"ltp":1.2,"tv":359.66,"id":10894176},{"batb":[[1,1.01,15.51],[2,1.01,0]],"ltp":2.0,"tv":127.78,"id":2263634}]}]}
{"op":"mcm","clk":"1008028537","pt":1580657974512,"mc":[{"id":"1.168224450","rc":[{"batl":[[0,1.13,556.6],[1,1.14,576.41]],"ltp":1.2,"tv":359.66,"id":10894176}]}]}
{"op":"mcm","clk":"1008029434","pt":1580657978341,"mc":[{"id":"1.168224450","marketDefinition":{"bspMarket":false,"turnInPlayEnabled":true,"persistenceEnabled":true,"marketBaseRate":5.0,"eventId":"29681727","eventTypeId":"2","numberOfWinners":1,"bettingType":"ODDS","marketType":"SET_WINNER","marketTime":"2020-02-02T14:51:00.000Z","suspendTime":"2020-02-02T14:51:00.000Z","bspReconciled":false,"complete":true,"inPlay":true,"crossMatching":true,"runnersVoidable":false,"numberOfActiveRunners":2,"betDelay":3,"status":"SUSPENDED","runners":[{"status":"ACTIVE","sortPriority":1,"id":10894176,"name":"Elliot Benchetrit"},{"status":"ACTIVE","sortPriority":2,"id":2263634,"name":"Lukas Lacko"}],"regulators":["MR_INT"],"countryCode":"FR","discountAllowed":true,"timezone":"UTC","openDate":"2020-02-02T14:51:00.000Z","version":3149541021,"name":"Set 1 Winner","eventName":"Benchetrit v Lacko"},"rc":[{"batb":[[0,1.01,15.51],[1,1.01,0]],"ltp":2.0,"tv":127.78,"id":2263634}]}]}
{"op":"mcm","clk":"1008037644","pt":1580658012512,"mc":[{"id":"1.168224450","tv":0.0}]}
{"op":"mcm","clk":"1008037883","pt":1580658013485,"mc":[{"id":"1.168224450","marketDefinition":{"bspMarket":false,"turnInPlayEnabled":true,"persistenceEnabled":true,"marketBaseRate":5.0,"eventId":"29681727","eventTypeId":"2","numberOfWinners":1,"bettingType":"ODDS","marketType":"SET_WINNER","marketTime":"2020-02-02T14:51:00.000Z","suspendTime":"2020-02-02T14:51:00.000Z","bspReconciled":false,"complete":true,"inPlay":true,"crossMatching":false,"runnersVoidable":false,"numberOfActiveRunners":0,"betDelay":3,"status":"CLOSED","settledTime":"2020-02-02T15:40:11.000Z","runners":[{"status":"WINNER","sortPriority":1,"id":10894176,"name":"Elliot Benchetrit"},{"status":"LOSER","sortPriority":2,"id":2263634,"name":"Lukas Lacko"}],"regulators":["MR_INT"],"countryCode":"FR","discountAllowed":true,"timezone":"UTC","openDate":"2020-02-02T14:51:00.000Z","version":3149543478,"name":"Set 1 Winner","eventName":"Benchetrit v Lacko"}}]}
