{"op":"mcm","clk":"1001177857","pt":1580585273658,"mc":[{"id":"1.168224454","marketDefinition":{"bspMarket":false,"turnInPlayEnabled":true,"persistenceEnabled":true,"marketBaseRate":5.0,"eventId":"29681727","eventTypeId":"2","numberOfWinners":1,"bettingType":"ODDS","marketType":"SET_WINNER","marketTime":"2020-02-02T15:00:00.000Z","suspendTime":"2020-02-02T15:00:00.000Z","bspReconciled":false,"complete":true,"inPlay":false,"crossMatching":false,"runnersVoidable":false,"numberOfActiveRunners":2,"betDelay":0,"status":"OPEN","runners":[{"status":"ACTIVE","sortPriority":1,"id":10894176,"name":"Elliot Benchetrit"},{"status":"ACTIVE","sortPriority":2,"id":2263634,"name":"Lukas Lacko"}],"regulators":["MR_INT"],"countryCode":"FR","discountAllowed":false,"timezone":"UTC","openDate":"2020-02-02T15:00:00.000Z","version":3147098557,"name":"Set 2 Winner","eventName":"Benchetrit v Lacko"},"rc":[{"batb":[[0,1.01,20]],"ltp":0.0,"tv":0.0,"id":10894176},{"batb":[[0,1.01,20]],"ltp":0.0,"tv":0.0,"id":2263634}]}]}
{"op":"mcm","clk":"1001178215","pt":1580585275453,"mc":[{"id":"1.168224454","marketDefinition":{"bspMarket":false,"turnInPlayEnabled":true,"persistenceEnabled":true,"marketBaseRate":5.0,"eventId":"29681727","eventTypeId":"2","numberOfWinners":1,"bettingType":"ODDS","marketType":"SET_WINNER","marketTime":"2020-02-02T15:00:00.000Z","suspendTime":"2020-02-02T15:00:00.000Z","bspReconciled":false,"complete":true,"inPlay":false,"crossMatching":false,"runnersVoidable":false,"numberOfActiveRunners":2,"betDelay":0,"status":"OPEN","runners":[{"status":"ACTIVE","sortPriority":1,"id":10894176,"name":"Elliot Benchetrit"},{"status":"ACTIVE","sortPriority":2,"id":2263634,"name":"Lukas Lacko"}],"regulators":["MR_INT"],"countryCode":"FR","discountAllowed":true,"timezone":"UTC","openDate":"2020-02-02T15:00:00.000Z","version":3147098557,"name":"Set 2 Winner","eventName":"Benchetrit v Lacko"}}]}
{"op":"mcm","clk":"1001204807","pt":1580585418184,"mc":[{"id":"1.168224454","rc":[{"batb":[[0,1.01,15]],"ltp":0.0,"tv":0.0,"id":10894176},{"batb":[[0,1.01,15]],"ltp":0.0,"tv":0.0,"id":2263634}]}]}
{"op":"mcm","clk":"1003033094","pt":1580602191259,"mc":[{"id":"1.168224454","rc":[{"batb":[[0,1.01,15.51]],"ltp":0.0,"tv":0.0,"id":10894176},{"batb":[[0,1.01,15.51]],"ltp":0.0,"tv":0.0,"id":2263634}]}]}
{"op":"mcm","clk":"1003160717","pt":1580603730430,"mc":[{"id":"1.168224454","rc":[{"batb":[[0,1.01,18.04]],"ltp":0.0,"tv":0.0,"id":10894176},{"batb":[[0,1.01,18.04]],"ltp":0.0,"tv":0.0,"id":2263634}]}]}
{"op":"mcm","clk":"1003160793","pt":1580603731415,"mc":[{"id":"1.168224454","rc":[{"batb":[[0,1.01,16.01]],"ltp":0.0,"tv":0.0,"id":10894176},{"batb":[[0,1.01,16.01]],"ltp":0.0,"tv":0.0,"id":2263634}]}]}
{"op":"mcm","clk":"1007443321","pt":1580655113558,"mc":[{"id":"1.168224454","marketDefinition":{"bspMarket":false,"turnInPlayEnabled":true,"persistenceEnabled":true,"marketBaseRate":5.0,"eventId":"29681727","eventTypeId":"2","numberOfWinners":1,"bettingType":"ODDS","marketType":"SET_WINNER","marketTime":"2020-02-02T14:51:00.000Z","suspendTime":"2020-02-02T14:51:00.000Z","bspReconciled":false,"complete":true,"inPlay":false,"crossMatching":false,"runnersVoidable":false,"numberOfActiveRunners":2,"betDelay":0,"status":"OPEN","runners":[{"status":"ACTIVE","sortPriority":1,"id":10894176,"name":"Elliot Benchetrit"},{"status":"ACTIVE","sortPriority":2,"id":2263634,"name":"Lukas Lacko"}],"regulators":["MR_INT"],"countryCode":"FR","discountAllowed":true,"timezone":"UTC","openDate":"2020-02-02T15:00:00.000Z","version":3149300460,"name":"Set 2 Winner","eventName":"Benchetrit v Lacko"}}]}
{"op":"mcm","clk":"1007443834","pt":1580655117578,"mc":[{"id":"1.168224454","marketDefinition":{"bspMarket":false,"turnInPlayEnabled":true,"persistenceEnabled":true,"marketBaseRate":5.0,"eventId":"29681727","eventTypeId":"2","numberOfWinners":1,"bettingType":"ODDS","marketType":"SET_WINNER","marketTime":"2020-02-02T14:51:00.000Z","suspendTime":"2020-02-02T14:51:00.000Z","bspReconciled":false,"complete":true,"inPlay":false,"crossMatching":false,"runnersVoidable":false,"numberOfActiveRunners":2,"betDelay":0,"status":"OPEN","runners":[{"status":"ACTIVE","sortPriority":1,"id":10894176,"name":"Elliot Benchetrit"},{"status":"ACTIVE","sortPriority":2,"id":2263634,"name":"Lukas Lacko"}],"regulators":["MR_INT"],"countryCode":"FR","discountAllowed":true,"timezone":"UTC","openDate":"2020-02-02T14:51:00.000Z","version":3149300460,"name":"Set 2 Winner","eventName":"Benchetrit v Lacko"}}]}
{"op":"mcm","clk":"1007447209","pt":1580655147016,"mc":[{"id":"1.168224454","rc":[{"batb":[[0,2.08,25.1],[1,1.01,16.01]],"ltp":0.0,"tv":0.0,"id":10894176},{"batb":[[0,1.81,19.28],[1,1.01,16.01]],"ltp":0.0,"tv":0.0,"id":2263634}]}]}
{"op":"mcm","clk":"1007552140","pt":1580655876896,"mc":[{"id":"1.168224454","rc":[{"batb":[[1,2.06,39.49],[2,1.01,16.01]],"batl":[[0,2.32,31.09]],"ltp":0.0,"tv":0.0,"id":10894176},{"batb":[[1,1.77,53.77],[2,1.01,16.01]],"batl":[[0,1.95,42.01]],"ltp":0.0,"tv":0.0,"id":2263634}]}]}
{"op":"mcm","clk":"1007554172","pt":1580655887340,"mc":[{"id":"1.168224454","marketDefinition":{"bspMarket":false,"turnInPlayEnabled":true,"persistenceEnabled":true,"marketBaseRate":5.0,"eventId":"29681727","eventTypeId":"2","numberOfWinners":1,"bettingType":"ODDS","marketType":"SET_WINNER","marketTime":"2020-02-02T14:51:00.000Z","suspendTime":"2020-02-02T14:51:00.000Z","bspReconciled":false,"complete":true,"inPlay":false,"crossMatching":true,"runnersVoidable":false,"numberOfActiveRunners":2,"betDelay":0,"status":"OPEN","runners":[{"status":"ACTIVE","sortPriority":1,"id":10894176,"name":"Elliot Benchetrit"},{"status":"ACTIVE","sortPriority":2,"id":2263634,"name":"Lukas Lacko"}],"regulators":["MR_INT"],"countryCode":"FR","discountAllowed":true,"timezone":"UTC","openDate":"2020-02-02T14:51:00.000Z","version":3149300460,"name":"Set 2 Winner","eventName":"Benchetrit v Lacko"}}]}
{"op":"mcm","clk":"1007608076","pt":1580656137407,"mc":[{"id":"1.168224454","marketDefinition":{"bspMarket":false,"turnInPlayEnabled":true,"persistenceEnabled":true,"marketBaseRate":5.0,"eventId":"29681727","eventTypeId":"2","numberOfWinners":1,"bettingType":"ODDS","marketType":"SET_WINNER","marketTime":"2020-02-02T14:51:00.000Z","suspendTime":"2020-02-02T14:51:00.000Z","bspReconciled":false,"complete":true,"inPlay":true,"crossMatching":true,"runnersVoidable":false,"numberOfActiveRunners":2,"betDelay":3,"status":"OPEN","runners":[{"status":"ACTIVE","sortPriority":1,"id":10894176,"name":"Elliot Benchetrit"},{"status":"ACTIVE","sortPriority":2,"id":2263634,"name":"Lukas Lacko"}],"regulators":["MR_INT"],"countryCode":"FR","discountAllowed":true,"timezone":"UTC","openDate":"2020-02-02T14:51:00.000Z","version":3149404452,"name":"Set 2 Winner","eventName":"Benchetrit v Lacko"},"rc":[{"batb":[[0,1.01,15.51],[1,2.06,0],[2,1.01,0]],"ltp":0.0,"tv":0.0,"id":10894176},{"batb":[[0,1.01,15.51],[1,1.77,0],[2,1.01,0]],"ltp":0.0,"tv":0.0,"id":2263634}]}]}
{"op":"mcm","clk":"1007609996","pt":1580656145324,"mc":[{"id":"1.168224454","rc":[{"batb":[[0,2.04,26.12],[1,2.02,68.39],[2,1.01,15.51]],"batl":[[0,2.28,32.77]],"ltp":0.0,"tv":0.0,"id":10894176},{"batb":[[0,1.83,18.57],[1,1.8,19.75],[2,1.78,53.77]],"batl":[[0,1.98,42.01]],"ltp":0.0,"tv":0.0,"id":2263634}]}]}
{"op":"mcm","clk":"1007612160","pt":1580656154204,"mc":[{"id":"1.168224454","rc":[{"batb":[[0,2.02,27.22],[1,1.01,15.51],[2,1.01,0]],"ltp":0.0,"tv":0.0,"id":10894176},{"batb":[[0,1.8,19.75],[1,1.01,15.51],[2,1.78,0]],"ltp":0.0,"tv":0.0,"id":2263634}]}]}
{"op":"mcm","clk":"1007616592","pt":1580656173182,"mc":[{"id":"1.168224454","rc":[{"batb":[[1,1.99,42.01],[2,1.01,15.51]],"batl":[[0,2.24,33.61]],"ltp":0.0,"tv":0.0,"id":10894176},{"batb":[[0,1.81,51.25],[1,1.8,19.75],[2,1.01,15.51]],"batl":[[0,2,42.01]],"ltp":0.0,"tv":0.0,"id":2263634}]}]}
{"op":"mcm","clk":"1007616772","pt":1580656173848,"mc":[{"id":"1.168224454","rc":[{"batb":[[1,1.99,70.49]],"ltp":0.0,"tv":0.0,"id":10894176},{"batb":[[0,1.86,17.78],[1,1.82,19.04],[2,1.81,51.25]],"ltp":0.0,"tv":0.0,"id":2263634}]}]}
{"op":"mcm","clk":"1007619400","pt":1580656184560,"mc":[{"id":"1.168224454","rc":[{"batb":[[0,1.99,70.49],[1,1.01,15.51],[2,1.01,0]],"ltp":0.0,"tv":0.0,"id":10894176},{"batb":[[0,1.82,19.04],[1,1.81,51.25],[2,1.01,15.51]],"ltp":0.0,"tv":0.0,"id":2263634}]}]}
{"op":"mcm","clk":"1007619841","pt":1580656186270,"mc":[{"id":"1.168224454","rc":[{"batb":[[0,1.99,28.48]],"ltp":0.0,"tv":0.0,"id":10894176},{"batb":[[1,1.01,15.51],[2,1.01,0]],"ltp":0.0,"tv":0.0,"id":2263634}]}]}
{"op":"mcm","clk":"1007620845","pt":1580656190271,"mc":[{"id":"1.168224454","rc":[{"batb":[[1,1.98,29.27],[2,1.01,15.51]],"ltp":0.0,"tv":0.0,"id":10894176},{"batb":[[0,1.88,17],[1,1.84,18.18],[2,1.01,15.51]],"ltp":0.0,"tv":0.0,"id":2263634}]}]}
{"op":"mcm","clk":"1007621042","pt":1580656191172,"mc":[{"id":"1.168224454","rc":[{"batb":[[2,1.96,43.69]],"batl":[[0,2.2,34.45]],"ltp":0.0,"tv":0.0,"id":10894176},{"batb":[[1,1.84,67.75]],"batl":[[0,2.04,40.33]],"ltp":0.0,"tv":0.0,"id":2263634}]}]}
{"op":"mcm","clk":"1007623570","pt":1580656201395,"mc":[{"id":"1.168224454","rc":[{"batb":[[0,1.98,29.27],[1,1.96,43.69],[2,1.01,15.51]],"ltp":0.0,"tv":0.0,"id":10894176},{"batb":[[0,1.84,67.75],[1,1.01,15.51],[2,1.01,0]],"ltp":0.0,"tv":0.0,"id":2263634}]}]}
{"op":"mcm","clk":"1007623784","pt":1580656202271,"mc":[{"id":"1.168224454","rc":[{"batb":[[1,1.01,15.51],[2,1.01,0]],"ltp":0.0,"tv":0.0,"id":10894176},{"batb":[[0,1.84,18.18]],"ltp":0.0,"tv":0.0,"id":2263634}]}]}
{"op":"mcm","clk":"1007625909","pt":1580656211247,"mc":[{"id":"1.168224454","rc":[{"batb":[[0,2.04,26.59],[1,2.02,68.71],[2,1.01,15.51]],"batl":[[0,2.26,32.77]],"ltp":0.0,"tv":0.0,"id":10894176},{"batb":[[1,1.8,71.68],[2,1.01,15.51]],"batl":[[0,1.99,42.01]],"ltp":0.0,"tv":0.0,"id":2263634}]}]}
{"op":"mcm","clk":"1007630157","pt":1580656228229,"mc":[{"id":"1.168224454","rc":[{"batb":[[0,2.02,27.54],[1,1.01,15.51],[2,1.01,0]],"ltp":0.0,"tv":0.0,"id":10894176},{"batb":[[0,1.8,19.59],[1,1.01,15.51],[2,1.01,0]],"ltp":0.0,"tv":0.0,"id":2263634}]}]}
{"op":"mcm","clk":"1007635540","pt":1580656249352,"mc":[{"id":"1.168224454","rc":[{"batb":[[0,2.08,38.65],[1,2.02,27.54],[2,1.01,15.51]],"batl":[[0,2.32,31.09]],"ltp":0.0,"tv":0.0,"id":10894176},{"batb":[[1,1.76,54.61],[2,1.01,15.51]],"batl":[[0,1.94,42.01]],"ltp":0.0,"tv":0.0,"id":2263634}]}]}
{"op":"mcm","clk":"1007635767","pt":1580656250251,"mc":[{"id":"1.168224454","rc":[{"batb":[[0,2.08,63.28],[1,2.06,25.89],[2,2.04,153.12]],"ltp":0.0,"tv":0.0,"id":10894176},{"batb":[[1,1.76,75.7]],"ltp":0.0,"tv":0.0,"id":2263634}]}]}
{"op":"mcm","clk":"1007635808","pt":1580656250468,"mc":[{"id":"1.168224454","rc":[{"batb":[[2,1.01,15.51]],"ltp":0.0,"tv":0.0,"id":10894176}]}]}
{"op":"mcm","clk":"1007640536","pt":1580656268787,"mc":[{"id":"1.168224454","rc":[{"batb":[[0,2.08,38.65]],"ltp":0.0,"tv":0.0,"id":10894176},{"batb":[[0,1.76,75.7],[1,1.01,15.51],[2,1.01,0]],"ltp":0.0,"tv":0.0,"id":2263634}]}]}
{"op":"mcm","clk":"1007640902","pt":1580656270285,"mc":[{"id":"1.168224454","rc":[{"batb":[[0,2.06,25.89],[1,1.01,15.51],[2,1.01,0]],"ltp":0.0,"tv":0.0,"id":10894176},{"batb":[[0,1.76,21.09]],"ltp":0.0,"tv":0.0,"id":2263634}]}]}
{"op":"mcm","clk":"1007645258","pt":1580656288437,"mc":[{"id":"1.168224454","rc":[{"batb":[[0,2.14,22.74],[1,2.12,23.92],[2,1.01,15.51]],"ltp":0.0,"tv":0.0,"id":10894176},{"batb":[[1,1.71,23.21],[2,1.01,15.51]],"ltp":0.0,"tv":0.0,"id":2263634}]}]}
{"op":"mcm","clk":"1007645449","pt":1580656289198,"mc":[{"id":"1.168224454","rc":[{"batb":[[1,2.12,60.89]],"batl":[[0,2.4,29.41]],"ltp":0.0,"tv":0.0,"id":10894176},{"batb":[[1,1.73,57.13],[2,1.71,23.21]],"batl":[[0,1.9,42.01]],"ltp":0.0,"tv":0.0,"id":2263634}]}]}
{"op":"mcm","clk":"1007649944","pt":1580656308230,"mc":[{"id":"1.168224454","rc":[{"batb":[[0,2.12,23.92],[1,1.01,15.51],[2,1.01,0]],"ltp":0.0,"tv":0.0,"id":10894176},{"batb":[[0,1.71,23.21],[1,1.01,15.51],[2,1.71,0]],"ltp":0.0,"tv":0.0,"id":2263634}]}]}
{"op":"mcm","clk":"1007654634","pt":1580656328287,"mc":[{"id":"1.168224454","rc":[{"batb":[[1,2.08,25.1],[2,1.01,15.51]],"ltp":0.0,"tv":0.0,"id":10894176},{"batb":[[0,1.79,20.14],[1,1.75,21.64],[2,1.01,15.51]],"ltp":0.0,"tv":0.0,"id":2263634}]}]}
{"op":"mcm","clk":"1007654886","pt":1580656329349,"mc":[{"id":"1.168224454","rc":[{"batb":[[1,2.08,63.75]],"batl":[[0,2.36,30.25]],"ltp":0.0,"tv":0.0,"id":10894176},{"batb":[[1,1.75,77.09]],"batl":[[0,1.92,42.01]],"ltp":0.0,"tv":0.0,"id":2263634}]}]}
{"op":"mcm","clk":"1007658742","pt":1580656345158,"mc":[{"id":"1.168224454","rc":[{"batb":[[0,2.08,63.75],[1,1.01,15.51],[2,1.01,0]],"ltp":0.0,"tv":0.0,"id":10894176},{"batb":[[0,1.75,77.09],[1,1.01,15.51],[2,1.01,0]],"ltp":0.0,"tv":0.0,"id":2263634}]}]}
{"op":"mcm","clk":"1007659007","pt":1580656346244,"mc":[{"id":"1.168224454","rc":[{"batb":[[0,2.08,25.1]],"ltp":0.0,"tv":0.0,"id":10894176},{"batb":[[0,1.75,21.64]],"ltp":0.0,"tv":0.0,"id":2263634}]}]}
{"op":"mcm","clk":"1007664530","pt":1580656370306,"mc":[{"id":"1.168224454","rc":[{"batb":[[0,2.16,22.19],[1,2.12,23.29],[2,1.01,15.51]],"ltp":0.0,"tv":0.0,"id":10894176},{"batb":[[1,1.7,23.92],[2,1.01,15.51]],"ltp":0.0,"tv":0.0,"id":2263634}]}]}
{"op":"mcm","clk":"1007664746","pt":1580656371266,"mc":[{"id":"1.168224454","rc":[{"batb":[[1,2.14,36.13],[2,2.12,23.29]],"batl":[[0,2.42,29.41]],"ltp":0.0,"tv":0.0,"id":10894176},{"batb":[[1,1.71,58.81],[2,1.7,23.92]],"batl":[[0,1.88,42.01]],"ltp":0.0,"tv":0.0,"id":2263634}]}]}
{"op":"mcm","clk":"1007668453","pt":1580656387013,"mc":[{"id":"1.168224454","rc":[{"batb":[[0,2.14,36.13],[1,2.12,23.29],[2,1.01,15.51]],"ltp":0.0,"tv":0.0,"id":10894176},{"batb":[[0,1.71,58.81],[1,1.7,23.92],[2,1.01,15.51]],"ltp":0.0,"tv":0.0,"id":2263634}]}]}
{"op":"mcm","clk":"1007668750","pt":1580656388266,"mc":[{"id":"1.168224454","rc":[{"batb":[[0,2.12,23.29],[1,1.01,15.51],[2,1.01,0]],"ltp":0.0,"tv":0.0,"id":10894176},{"batb":[[0,1.7,23.92],[1,1.01,15.51],[2,1.01,0]],"ltp":0.0,"tv":0.0,"id":2263634}]}]}
{"op":"mcm","clk":"1007674096","pt":1580656411438,"mc":[{"id":"1.168224454","rc":[{"batb":[[1,2.1,37.81],[2,2.08,24.71]],"batl":[[0,2.38,30.25]],"ltp":0.0,"tv":0.0,"id":10894176},{"batb":[[0,1.77,20.61],[1,1.74,22.11],[2,1.73,57.13]],"batl":[[0,1.91,42.01]],"ltp":0.0,"tv":0.0,"id":2263634}]}]}
{"op":"mcm","clk":"1007678640","pt":1580656430891,"mc":[{"id":"1.168224454","rc":[{"batb":[[0,2.1,37.81],[1,2.08,24.71],[2,1.01,15.51]],"ltp":0.0,"tv":0.0,"id":10894176},{"batb":[[0,1.74,22.11],[1,1.73,57.13],[2,1.01,15.51]],"ltp":0.0,"tv":0.0,"id":2263634}]}]}
{"op":"mcm","clk":"1007679018","pt":1580656432367,"mc":[{"id":"1.168224454","rc":[{"batb":[[0,2.08,24.71],[1,1.01,15.51],[2,1.01,0]],"ltp":0.0,"tv":0.0,"id":10894176},{"batb":[[1,1.01,15.51],[2,1.01,0]],"ltp":0.0,"tv":0.0,"id":2263634}]}]}
{"op":"mcm","clk":"1007680141","pt":1580656437279,"mc":[{"id":"1.168224454","rc":[{"batb":[[1,2.04,40.33],[2,1.01,15.51]],"batl":[[0,2.3,31.93]],"ltp":0.0,"tv":0.0,"id":10894176},{"batb":[[0,1.78,53.77],[1,1.74,22.11],[2,1.01,15.51]],"batl":[[0,1.96,42.01]],"ltp":0.0,"tv":0.0,"id":2263634}]}]}
{"op":"mcm","clk":"1007680297","pt":1580656437889,"mc":[{"id":"1.168224454","rc":[{"batb":[[1,2.04,66.92]],"ltp":0.0,"tv":0.0,"id":10894176},{"batb":[[0,1.8,19.51],[1,1.78,74.23]],"ltp":0.0,"tv":0.0,"id":2263634}]}]}
{"op":"mcm","clk":"1007682122","pt":1580656444862,"mc":[{"id":"1.168224454","rc":[{"batl":[[1,3,213.45]],"ltp":0.0,"tv":0.0,"id":10894176},{"batl":[[1,2.3,309.75]],"ltp":0.0,"tv":0.0,"id":2263634}]}]}
{"op":"mcm","clk":"1007690759","pt":1580656481135,"mc":[{"id":"1.168224454","rc":[{"batb":[[1,2.04,26.59]],"ltp":0.0,"tv":0.0,"id":10894176},{"batb":[[1,1.78,20.46]],"batl":[[0,2.3,309.75],[1,2.3,0]],"ltp":0.0,"tv":0.0,"id":2263634}]}]}
{"op":"mcm","clk":"1007691096","pt":1580656482367,"mc":[{"id":"1.168224454","rc":[{"batb":[[0,2.04,26.59],[1,1.01,15.51],[2,1.01,0]],"batl":[[0,3,213.45],[1,3,0]],"ltp":0.0,"tv":0.0,"id":10894176},{"batb":[[0,1.78,20.46],[1,1.01,15.51],[2,1.01,0]],"ltp":0.0,"tv":0.0,"id":2263634}]}]}
{"op":"mcm","clk":"1007695464","pt":1580656500308,"mc":[{"id":"1.168224454","rc":[{"batb":[[0,2.12,23.53],[1,2.06,25.34],[2,1.01,15.51]],"ltp":0.0,"tv":0.0,"id":10894176},{"batb":[[1,1.76,21.24],[2,1.01,15.51]],"ltp":0.0,"tv":0.0,"id":2263634}]}]}
{"op":"mcm","clk":"1007695722","pt":1580656501318,"mc":[{"id":"1.168224454","rc":[{"batb":[[1,2.1,37.81],[2,2.06,25.34]],"batl":[[0,2.36,30.25],[1,3,213.45]],"ltp":0.0,"tv":0.0,"id":10894176},{"batb":[[2,1.75,55.45]],"batl":[[0,1.92,42.01],[1,2.3,309.75]],"ltp":0.0,"tv":0.0,"id":2263634}]}]}
{"op":"mcm","clk":"1007698638","pt":1580656513310,"mc":[{"id":"1.168224454","rc":[{"batb":[[0,2.1,37.81],[1,2.06,25.34],[2,1.01,15.51]],"ltp":0.0,"tv":0.0,"id":10894176},{"batb":[[0,1.76,21.24],[1,1.75,55.45],[2,1.01,15.51]],"ltp":0.0,"tv":0.0,"id":2263634}]}]}
{"op":"mcm","clk":"1007698855","pt":1580656514400,"mc":[{"id":"1.168224454","rc":[{"batb":[[0,2.06,25.34],[1,1.01,15.51],[2,1.01,0]],"batl":[[0,3,213.45],[1,3,0]],"ltp":0.0,"tv":0.0,"id":10894176},{"batb":[[1,1.01,15.51],[2,1.01,0]],"batl":[[0,2.3,309.75],[1,2.3,0]],"ltp":0.0,"tv":0.0,"id":2263634}]}]}
{"op":"mcm","clk":"1007701420","pt":1580656525444,"mc":[{"id":"1.168224454","rc":[{"batb":[[0,2.16,22.58],[1,2.12,36.97],[2,2.1,24.39]],"batl":[[0,2.4,29.41],[1,3,213.45]],"ltp":0.0,"tv":0.0,"id":10894176},{"batb":[[1,1.74,21.87],[2,1.72,57.97]],"batl":[[0,1.89,42.01],[1,2.3,309.75]],"ltp":0.0,"tv":0.0,"id":2263634}]}]}
{"op":"mcm","clk":"1007703925","pt":1580656536424,"mc":[{"id":"1.168224454","rc":[{"batb":[[0,2.1,24.39],[1,1.01,15.51],[2,2.1,0]],"batl":[[0,3,213.45],[1,3,0]],"ltp":0.0,"tv":0.0,"id":10894176},{"batb":[[0,1.74,21.87],[1,1.01,15.51],[2,1.72,0]],"batl":[[0,2.3,309.75],[1,2.3,0]],"ltp":0.0,"tv":0.0,"id":2263634}]}]}
{"op":"mcm","clk":"1007706605","pt":1580656548442,"mc":[{"id":"1.168224454","rc":[{"batb":[[0,2.18,21.87],[1,2.14,23.21],[2,1.01,15.51]],"ltp":0.0,"tv":0.0,"id":10894176},{"batb":[[1,1.72,22.74],[2,1.01,15.51]],"ltp":0.0,"tv":0.0,"id":2263634}]}]}
{"op":"mcm","clk":"1007706867","pt":1580656549784,"mc":[{"id":"1.168224454","rc":[{"batb":[[1,2.16,36.13],[2,2.14,23.21]],"batl":[[0,2.44,28.57],[1,3,213.45]],"ltp":0.0,"tv":0.0,"id":10894176},{"batb":[[2,1.7,59.65]],"batl":[[0,1.87,42.01],[1,2.3,309.75]],"ltp":0.0,"tv":0.0,"id":2263634}]}]}
{"op":"mcm","clk":"1007709045","pt":1580656560419,"mc":[{"id":"1.168224454","rc":[{"batb":[[0,2.14,23.21],[1,1.01,15.51],[2,2.14,0]],"batl":[[0,3,213.45],[1,3,0]],"ltp":0.0,"tv":0.0,"id":10894176},{"batb":[[0,1.72,22.74],[1,1.01,15.51],[2,1.7,0]],"batl":[[0,2.3,309.75],[1,2.3,0]],"ltp":0.0,"tv":0.0,"id":2263634}]}]}
{"op":"mcm","clk":"1007714390","pt":1580656585418,"mc":[{"id":"1.168224454","rc":[{"batb":[[0,2.22,33.61],[1,2.14,23.21],[2,1.01,15.51]],"batl":[[0,2.52,26.89],[1,3,213.45]],"ltp":0.0,"tv":0.0,"id":10894176},{"batb":[[1,1.67,62.17],[2,1.01,15.51]],"batl":[[0,1.82,42.01],[1,2.3,309.75]],"ltp":0.0,"tv":0.0,"id":2263634}]}]}
{"op":"mcm","clk":"1007714483","pt":1580656585807,"mc":[{"id":"1.168224454","rc":[{"batb":[[1,2.2,21.01],[2,2.16,22.03]],"ltp":0.0,"tv":0.0,"id":10894176},{"batb":[[1,1.68,24.71],[2,1.67,62.17]],"ltp":0.0,"tv":0.0,"id":2263634}]}]}
{"op":"mcm","clk":"1007721154","pt":1580656614153,"mc":[{"id":"1.168224454","rc":[{"batb":[[1,2.16,22.03],[2,1.01,15.51]],"ltp":0.0,"tv":0.0,"id":10894176},{"batb":[[0,1.68,24.71],[1,1.67,62.17],[2,1.01,15.51]],"ltp":0.0,"tv":0.0,"id":2263634}]}]}
{"op":"mcm","clk":"1007721345","pt":1580656615059,"mc":[{"id":"1.168224454","rc":[{"batb":[[0,2.16,22.03],[1,1.01,15.51],[2,1.01,0]],"batl":[[0,3,213.45],[1,3,0]],"ltp":0.0,"tv":0.0,"id":10894176},{"batb":[[1,1.01,15.51],[2,1.01,0]],"batl":[[0,2.3,309.75],[1,2.3,0]],"ltp":0.0,"tv":0.0,"id":2263634}]}]}
{"op":"mcm","clk":"1007722815","pt":1580656621366,"mc":[{"id":"1.168224454","rc":[{"batb":[[1,2.14,23.29],[2,1.01,15.51]],"ltp":0.0,"tv":0.0,"id":10894176},{"batb":[[0,1.75,21.72],[1,1.71,23.37],[2,1.69,601.92]],"ltp":0.0,"tv":0.0,"id":2263634}]}]}
{"op":"mcm","clk":"1007722874","pt":1580656621542,"mc":[{"id":"1.168224454","rc":[{"batb":[[0,2.18,35.29],[1,2.16,22.03],[2,2.14,23.29]],"batl":[[0,2.48,27.73],[1,3,213.45]],"ltp":0.0,"tv":0.0,"id":10894176},{"batb":[[2,1.69,60.49]],"batl":[[0,1.85,42.01],[1,2.3,309.75]],"ltp":0.0,"tv":0.0,"id":2263634}]}]}
{"op":"mcm","clk":"1007725445","pt":1580656631883,"mc":[{"id":"1.168224454","rc":[{"batb":[[1,2.14,23.29],[2,1.01,15.51]],"ltp":0.0,"tv":0.0,"id":10894176},{"batb":[[0,1.71,23.37],[1,1.69,60.49],[2,1.01,15.51]],"ltp":0.0,"tv":0.0,"id":2263634}]}]}
{"op":"mcm","clk":"1007725567","pt":1580656632470,"mc":[{"id":"1.168224454","rc":[{"batb":[[0,2.14,23.29],[1,1.01,15.51],[2,1.01,0]],"batl":[[0,3,213.45],[1,3,0]],"ltp":0.0,"tv":0.0,"id":10894176},{"batb":[[1,1.01,15.51],[2,1.01,0]],"batl":[[0,2.3,309.75],[1,2.3,0]],"ltp":0.0,"tv":0.0,"id":2263634}]}]}
{"op":"mcm","clk":"1007729116","pt":1580656647408,"mc":[{"id":"1.168224454","rc":[{"batb":[[1,2.1,24.16],[2,1.01,15.51]],"ltp":0.0,"tv":0.0,"id":10894176},{"batb":[[0,1.77,20.69],[1,1.73,22.35],[2,1.01,15.51]],"ltp":0.0,"tv":0.0,"id":2263634}]}]}
{"op":"mcm","clk":"1007729253","pt":1580656647991,"mc":[{"id":"1.168224454","rc":[{"batb":[[0,2.16,36.13],[1,2.14,23.29],[2,2.1,24.16]],"batl":[[0,2.44,28.57],[1,3,213.45]],"ltp":0.0,"tv":0.0,"id":10894176},{"batb":[[2,1.71,58.81]],"batl":[[0,1.87,42.01],[1,2.3,309.75]],"ltp":0.0,"tv":0.0,"id":2263634}]}]}
{"op":"mcm","clk":"1007732121","pt":1580656659809,"mc":[{"id":"1.168224454","rc":[{"batb":[[1,2.1,24.16],[2,1.01,15.51]],"ltp":0.0,"tv":0.0,"id":10894176},{"batb":[[0,1.73,22.35],[1,1.71,58.81],[2,1.01,15.51]],"ltp":0.0,"tv":0.0,"id":2263634}]}]}
{"op":"mcm","clk":"1007732375","pt":1580656660839,"mc":[{"id":"1.168224454","rc":[{"batb":[[0,2.1,24.16],[1,1.01,15.51],[2,1.01,0]],"batl":[[0,3,213.45],[1,3,0]],"ltp":0.0,"tv":0.0,"id":10894176},{"batb":[[1,1.01,15.51],[2,1.01,0]],"batl":[[0,2.3,309.75],[1,2.3,0]],"ltp":0.0,"tv":0.0,"id":2263634}]}]}
{"op":"mcm","clk":"1007733957","pt":1580656667434,"mc":[{"id":"1.168224454","rc":[{"batb":[[1,2.08,25.18],[2,1.01,15.51]],"ltp":0.0,"tv":0.0,"id":10894176},{"batb":[[0,1.79,19.99],[1,1.75,21.4],[2,1.01,15.51]],"ltp":0.0,"tv":0.0,"id":2263634}]}]}
{"op":"mcm","clk":"1007734049","pt":1580656667816,"mc":[{"id":"1.168224454","rc":[{"batb":[[0,2.12,36.97],[1,2.1,24.16],[2,2.08,25.18]],"batl":[[0,2.4,29.41],[1,3,213.45]],"ltp":0.0,"tv":0.0,"id":10894176},{"batb":[[2,1.73,57.13]],"batl":[[0,1.9,42.01],[1,2.3,309.75]],"ltp":0.0,"tv":0.0,"id":2263634}]}]}
{"op":"mcm","clk":"1007737289","pt":1580656680774,"mc":[{"id":"1.168224454","rc":[{"batb":[[0,2.08,25.18],[1,1.01,15.51],[2,2.08,0]],"batl":[[0,3,213.45],[1,3,0]],"ltp":0.0,"tv":0.0,"id":10894176},{"batb":[[0,1.75,21.4],[1,1.01,15.51],[2,1.73,0]],"batl":[[0,2.3,309.75],[1,2.3,0]],"ltp":0.0,"tv":0.0,"id":2263634}]}]}
{"op":"mcm","clk":"1007740606","pt":1580656694381,"mc":[{"id":"1.168224454","rc":[{"batb":[[0,2.18,35.29],[1,2.16,22.42],[2,2.12,23.37]],"batl":[[0,2.46,28.57],[1,3,213.45]],"ltp":0.0,"tv":0.0,"id":10894176},{"batb":[[1,1.71,23.13],[2,1.69,60.49]],"batl":[[0,1.85,42.01],[1,2.3,309.75]],"ltp":0.0,"tv":0.0,"id":2263634}]}]}
{"op":"mcm","clk":"1007744422","pt":1580656711763,"mc":[{"id":"1.168224454","rc":[{"batb":[[1,2.12,23.37],[2,1.01,15.51]],"ltp":0.0,"tv":0.0,"id":10894176},{"batb":[[0,1.71,23.13],[1,1.69,60.49],[2,1.01,15.51]],"ltp":0.0,"tv":0.0,"id":2263634}]}]}
{"op":"mcm","clk":"1007744639","pt":1580656712794,"mc":[{"id":"1.168224454","rc":[{"batb":[[0,2.12,23.37],[1,1.01,15.51],[2,1.01,0]],"batl":[[0,3,213.45],[1,3,0]],"ltp":0.0,"tv":0.0,"id":10894176},{"batb":[[1,1.01,15.51],[2,1.01,0]],"batl":[[0,2.3,309.75],[1,2.3,0]],"ltp":0.0,"tv":0.0,"id":2263634}]}]}
{"op":"mcm","clk":"1007745049","pt":1580656714681,"mc":[{"id":"1.168224454","rc":[{"batb":[[0,1.72,22.98]],"ltp":0.0,"tv":0.0,"id":2263634}]}]}
{"op":"mcm","clk":"1007748455","pt":1580656730181,"mc":[{"id":"1.168224454","rc":[{"batb":[[1,2.1,37.81],[2,2.06,25.81]],"batl":[[0,2.38,30.25],[1,3,213.45]],"ltp":0.0,"tv":0.0,"id":10894176},{"batb":[[0,1.78,20.54],[1,1.75,21.48],[2,1.74,56.29]],"batl":[[0,1.91,42.01],[1,2.3,309.75]],"ltp":0.0,"tv":0.0,"id":2263634}]}]}
{"op":"mcm","clk":"1007765965","pt":1580656808006,"mc":[{"id":"1.168224454","rc":[{"batb":[[0,2.1,37.81],[1,2.06,25.81],[2,1.01,15.51]],"ltp":0.0,"tv":0.0,"id":10894176},{"batb":[[0,1.75,21.48],[1,1.74,56.29],[2,1.01,15.51]],"ltp":0.0,"tv":0.0,"id":2263634}]}]}
{"op":"mcm","clk":"1007766186","pt":1580656809026,"mc":[{"id":"1.168224454","rc":[{"batb":[[0,2.06,25.81],[1,1.01,15.51],[2,1.01,0]],"batl":[[0,3,213.45],[1,3,0]],"ltp":0.0,"tv":0.0,"id":10894176},{"batb":[[1,1.01,15.51],[2,1.01,0]],"batl":[[0,2.3,309.75],[1,2.3,0]],"ltp":0.0,"tv":0.0,"id":2263634}]}]}
{"op":"mcm","clk":"1007769085","pt":1580656822435,"mc":[{"id":"1.168224454","rc":[{"batb":[[0,2.06,65.3],[1,1.99,28.56],[2,1.01,15.51]],"ltp":0.0,"tv":0.0,"id":10894176},{"batb":[[0,1.83,18.73],[1,1.79,19.83],[2,1.77,53.77]],"batl":[[0,1.95,42.01],[1,2.3,309.75]],"ltp":0.0,"tv":0.0,"id":2263634}]}]}
{"op":"mcm","clk":"1007769623","pt":1580656824630,"mc":[{"id":"1.168224454","rc":[{"batl":[[0,2.3,31.93],[1,3,213.45]],"ltp":0.0,"tv":0.0,"id":10894176}]}]}
{"op":"mcm","clk":"1007771486","pt":1580656832377,"mc":[{"id":"1.168224454","rc":[{"batb":[[0,2.06,39.49]],"ltp":0.0,"tv":0.0,"id":10894176},{"batb":[[0,1.79,19.83],[1,1.77,53.77],[2,1.01,15.51]],"ltp":0.0,"tv":0.0,"id":2263634}]}]}
{"op":"mcm","clk":"1007771614","pt":1580656832871,"mc":[{"id":"1.168224454","rc":[{"batb":[[0,1.99,28.56],[1,1.01,15.51],[2,1.01,0]],"batl":[[0,3,213.45],[1,3,0]],"ltp":0.0,"tv":0.0,"id":10894176},{"batb":[[1,1.01,15.51],[2,1.01,0]],"batl":[[0,2.3,309.75],[1,2.3,0]],"ltp":0.0,"tv":0.0,"id":2263634}]}]}
{"op":"mcm","clk":"1007777159","pt":1580656857295,"mc":[{"id":"1.168224454","rc":[{"batb":[[0,2.1,24.31],[1,2.02,27.15],[2,1.01,15.51]],"ltp":0.0,"tv":0.0,"id":10894176},{"batb":[[1,1.78,20.46],[2,1.01,15.51]],"ltp":0.0,"tv":0.0,"id":2263634}]}]}
{"op":"mcm","clk":"1007777257","pt":1580656857783,"mc":[{"id":"1.168224454","rc":[{"batb":[[1,2.08,38.65],[2,2.02,27.15]],"batl":[[0,2.34,31.09],[1,3,213.45]],"ltp":0.0,"tv":0.0,"id":10894176},{"batb":[[2,1.75,55.45]],"batl":[[0,1.93,42.01],[1,2.3,309.75]],"ltp":0.0,"tv":0.0,"id":2263634}]}]}
{"op":"mcm","clk":"1007781483","pt":1580656876008,"mc":[{"id":"1.168224454","rc":[{"batb":[[0,2.08,38.65],[1,2.02,27.15],[2,1.01,15.51]],"ltp":0.0,"tv":0.0,"id":10894176},{"batb":[[0,1.78,20.46],[1,1.75,55.45],[2,1.01,15.51]],"ltp":0.0,"tv":0.0,"id":2263634}]}]}
{"op":"mcm","clk":"1007781692","pt":1580656876912,"mc":[{"id":"1.168224454","rc":[{"batb":[[0,2.02,27.15],[1,1.01,15.51],[2,1.01,0]],"batl":[[0,3,213.45],[1,3,0]],"ltp":0.0,"tv":0.0,"id":10894176},{"batb":[[1,1.01,15.51],[2,1.01,0]],"batl":[[0,2.3,309.75],[1,2.3,0]],"ltp":0.0,"tv":0.0,"id":2263634}]}]}
{"op":"mcm","clk":"1007783055","pt":1580656883077,"mc":[{"id":"1.168224454","rc":[{"batb":[[0,2.12,23.53],[1,2.06,25.81],[2,1.01,15.51]],"ltp":0.0,"tv":0.0,"id":10894176},{"batb":[[1,1.75,21.56],[2,1.01,15.51]],"ltp":0.0,"tv":0.0,"id":2263634}]}]}
{"op":"mcm","clk":"1007783284","pt":1580656884226,"mc":[{"id":"1.168224454","rc":[{"batb":[[0,2.12,60.49]],"batl":[[0,2.38,30.25],[1,3,213.45]],"ltp":0.0,"tv":0.0,"id":10894176},{"batb":[[2,1.73,57.13]],"batl":[[0,1.9,42.01],[1,2.3,309.75]],"ltp":0.0,"tv":0.0,"id":2263634}]}]}
{"op":"mcm","clk":"1007784965","pt":1580656891934,"mc":[{"id":"1.168224454","rc":[{"batb":[[0,2.12,36.97]],"ltp":0.0,"tv":0.0,"id":10894176},{"batb":[[0,1.75,21.56],[1,1.73,57.13],[2,1.01,15.51]],"ltp":0.0,"tv":0.0,"id":2263634}]}]}
{"op":"mcm","clk":"1007785226","pt":1580656893227,"mc":[{"id":"1.168224454","rc":[{"batb":[[0,2.06,25.81],[1,1.01,15.51],[2,1.01,0]],"batl":[[0,3,213.45],[1,3,0]],"ltp":0.0,"tv":0.0,"id":10894176},{"batb":[[1,1.01,15.51],[2,1.01,0]],"batl":[[0,2.3,309.75],[1,2.3,0]],"ltp":0.0,"tv":0.0,"id":2263634}]}]}
{"op":"mcm","clk":"1007788446","pt":1580656907260,"mc":[{"id":"1.168224454","rc":[{"batb":[[0,2.16,22.27],[1,2.1,24.08],[2,1.01,15.51]],"ltp":0.0,"tv":0.0,"id":10894176},{"batb":[[1,1.73,22.35],[2,1.01,15.51]],"ltp":0.0,"tv":0.0,"id":2263634}]}]}
{"op":"mcm","clk":"1007788696","pt":1580656908233,"mc":[{"id":"1.168224454","rc":[{"batb":[[1,2.14,36.13],[2,2.1,24.08]],"batl":[[0,2.42,29.41],[1,3,213.45]],"ltp":0.0,"tv":0.0,"id":10894176},{"batb":[[2,1.71,58.81]],"batl":[[0,1.88,42.01],[1,2.3,309.75]],"ltp":0.0,"tv":0.0,"id":2263634}]}]}
{"op":"mcm","clk":"1007791944","pt":1580656923014,"mc":[{"id":"1.168224454","rc":[{"batb":[[0,2.1,24.08],[1,1.01,15.51],[2,2.1,0]],"batl":[[0,3,213.45],[1,3,0]],"ltp":0.0,"tv":0.0,"id":10894176},{"batb":[[0,1.73,22.35],[1,1.01,15.51],[2,1.71,0]],"batl":[[0,2.3,309.75],[1,2.3,0]],"ltp":0.0,"tv":0.0,"id":2263634}]}]}
{"op":"mcm","clk":"1007794466","pt":1580656934322,"mc":[{"id":"1.168224454","rc":[{"batb":[[0,2.2,55.77],[1,2.16,22.66],[2,1.01,15.51]],"batl":[[0,2.5,27.73],[1,3,213.45]],"ltp":0.0,"tv":0.0,"id":10894176},{"batb":[[1,1.69,24.47],[2,1.67,62.17]],"batl":[[0,1.83,42.01],[1,2.3,309.75]],"ltp":0.0,"tv":0.0,"id":2263634}]}]}
{"op":"mcm","clk":"1007800043","pt":1580656959230,"mc":[{"id":"1.168224454","rc":[{"batb":[[0,2.16,22.66],[1,1.01,15.51],[2,1.01,0]],"batl":[[0,3,213.45],[1,3,0]],"ltp":0.0,"tv":0.0,"id":10894176},{"batb":[[0,1.69,24.47],[1,1.01,15.51],[2,1.67,0]],"batl":[[0,2.3,309.75],[1,2.3,0]],"ltp":0.0,"tv":0.0,"id":2263634}]}]}
{"op":"mcm","clk":"1007802442","pt":1580656970363,"mc":[{"id":"1.168224454","rc":[{"batb":[[0,2.18,35.29],[1,2.16,22.66],[2,2.12,23.68]],"batl":[[0,2.46,28.57],[1,3,213.45]],"ltp":0.0,"tv":0.0,"id":10894176},{"batb":[[0,1.76,21.24],[1,1.71,23.29],[2,1.69,662.41]],"batl":[[0,1.85,42.01],[1,2.3,309.75]],"ltp":0.0,"tv":0.0,"id":2263634}]}]}
{"op":"mcm","clk":"1007802495","pt":1580656970518,"mc":[{"id":"1.168224454","rc":[{"batb":[[2,1.69,60.49]],"ltp":0.0,"tv":0.0,"id":2263634}]}]}
{"op":"mcm","clk":"1007805230","pt":1580656982374,"mc":[{"id":"1.168224454","rc":[{"batb":[[1,2.12,23.68],[2,1.01,15.51]],"ltp":0.0,"tv":0.0,"id":10894176},{"batb":[[0,1.71,23.29],[1,1.69,60.49],[2,1.01,15.51]],"ltp":0.0,"tv":0.0,"id":2263634}]}]}
{"op":"mcm","clk":"1007805435","pt":1580656983300,"mc":[{"id":"1.168224454","rc":[{"batb":[[0,2.12,23.68],[1,1.01,15.51],[2,1.01,0]],"batl":[[0,3,213.45],[1,3,0]],"ltp":0.0,"tv":0.0,"id":10894176},{"batb":[[1,1.01,15.51],[2,1.01,0]],"batl":[[0,2.3,309.75],[1,2.3,0]],"ltp":0.0,"tv":0.0,"id":2263634}]}]}
{"op":"mcm","clk":"1007810534","pt":1580657005441,"mc":[{"id":"1.168224454","rc":[{"batb":[[1,2.08,24.94],[2,1.01,15.51]],"ltp":0.0,"tv":0.0,"id":10894176},{"batb":[[0,1.78,20.3],[1,1.74,22.11],[2,1.01,15.51]],"ltp":0.0,"tv":0.0,"id":2263634}]}]}
{"op":"mcm","clk":"1007810635","pt":1580657005833,"mc":[{"id":"1.168224454","rc":[{"batb":[[0,2.14,36.13],[1,2.12,23.68],[2,2.08,24.94]],"batl":[[0,2.42,29.41],[1,3,213.45]],"ltp":0.0,"tv":0.0,"id":10894176},{"batb":[[2,1.71,58.81]],"batl":[[0,1.88,42.01],[1,2.3,309.75]],"ltp":0.0,"tv":0.0,"id":2263634}]}]}
{"op":"mcm","clk":"1007814143","pt":1580657020375,"mc":[{"id":"1.168224454","rc":[{"batb":[[1,2.08,24.94],[2,1.01,15.51]],"ltp":0.0,"tv":0.0,"id":10894176},{"batb":[[0,1.74,22.11],[1,1.71,58.81],[2,1.01,15.51]],"ltp":0.0,"tv":0.0,"id":2263634}]}]}
{"op":"mcm","clk":"1007814288","pt":1580657020948,"mc":[{"id":"1.168224454","rc":[{"batb":[[0,2.08,24.94],[1,1.01,15.51],[2,1.01,0]],"batl":[[0,3,213.45],[1,3,0]],"ltp":0.0,"tv":0.0,"id":10894176},{"batb":[[1,1.01,15.51],[2,1.01,0]],"batl":[[0,2.3,309.75],[1,2.3,0]],"ltp":0.0,"tv":0.0,"id":2263634}]}]}
{"op":"mcm","clk":"1007814829","pt":1580657023378,"mc":[{"id":"1.168224454","rc":[{"batb":[[1,1.73,22.19],[2,1.01,15.51]],"ltp":0.0,"tv":0.0,"id":2263634}]}]}
{"op":"mcm","clk":"1007814895","pt":1580657023676,"mc":[{"id":"1.168224454","rc":[{"batb":[[0,2.08,24.78]],"ltp":0.0,"tv":0.0,"id":10894176},{"batb":[[0,1.73,22.19],[1,1.01,15.51],[2,1.01,0]],"ltp":0.0,"tv":0.0,"id":2263634}]}]}
{"op":"mcm","clk":"1007815711","pt":1580657027374,"mc":[{"id":"1.168224454","rc":[{"batb":[[1,2.06,25.73],[2,1.01,15.51]],"ltp":0.0,"tv":0.0,"id":10894176},{"batb":[[0,1.81,19.43],[1,1.76,21.17],[2,1.01,15.51]],"ltp":0.0,"tv":0.0,"id":2263634}]}]}
{"op":"mcm","clk":"1007815967","pt":1580657028379,"mc":[{"id":"1.168224454","rc":[{"batb":[[0,2.1,37.81],[1,2.08,24.78],[2,2.06,25.73]],"batl":[[0,2.38,30.25],[1,3,213.45]],"ltp":0.0,"tv":0.0,"id":10894176},{"batb":[[2,1.74,56.29]],"batl":[[0,1.91,42.01],[1,2.3,309.75]],"ltp":0.0,"tv":0.0,"id":2263634}]}]}
{"op":"mcm","clk":"1007817578","pt":1580657035188,"mc":[{"id":"1.168224454","rc":[{"batb":[[0,2.06,25.73],[1,1.01,15.51],[2,2.06,0]],"batl":[[0,3,213.45],[1,3,0]],"ltp":0.0,"tv":0.0,"id":10894176},{"batb":[[0,1.76,21.17],[1,1.01,15.51],[2,1.74,0]],"batl":[[0,2.3,309.75],[1,2.3,0]],"ltp":0.0,"tv":0.0,"id":2263634}]}]}
{"op":"mcm","clk":"1007821524","pt":1580657053207,"mc":[{"id":"1.168224454","rc":[{"batb":[[0,2.14,22.74],[1,2.12,23.45],[2,1.01,15.51]],"ltp":0.0,"tv":0.0,"id":10894176},{"batb":[[1,1.72,22.98],[2,1.01,15.51]],"ltp":0.0,"tv":0.0,"id":2263634}]}]}
{"op":"mcm","clk":"1007821655","pt":1580657053798,"mc":[{"id":"1.168224454","rc":[{"batb":[[0,2.16,36.13],[1,2.14,22.74],[2,2.12,23.45]],"batl":[[0,2.44,28.57],[1,3,213.45]],"ltp":0.0,"tv":0.0,"id":10894176},{"batb":[[2,1.7,59.65]],"batl":[[0,1.86,42.01],[1,2.3,309.75]],"ltp":0.0,"tv":0.0,"id":2263634}]}]}
{"op":"mcm","clk":"1007825960","pt":1580657073335,"mc":[{"id":"1.168224454","rc":[{"batb":[[0,2.12,23.45],[1,1.01,15.51],[2,2.12,0]],"batl":[[0,3,213.45],[1,3,0]],"ltp":0.0,"tv":0.0,"id":10894176},{"batb":[[0,1.72,22.98],[1,1.01,15.51],[2,1.7,0]],"batl":[[0,2.3,309.75],[1,2.3,0]],"ltp":0.0,"tv":0.0,"id":2263634}]}]}
{"op":"mcm","clk":"1007831771","pt":1580657099181,"mc":[{"id":"1.168224454","rc":[{"batb":[[1,2.04,26.36],[2,1.01,15.51]],"ltp":0.0,"tv":0.0,"id":10894176},{"batb":[[0,1.78,20.46],[1,1.76,21.24],[2,1.01,15.51]],"ltp":0.0,"tv":0.0,"id":2263634}]}]}
{"op":"mcm","clk":"1007831904","pt":1580657099877,"mc":[{"id":"1.168224454","rc":[{"batb":[[1,2.1,37.81],[2,2.04,26.36]],"batl":[[0,2.36,30.25],[1,3,213.45]],"ltp":0.0,"tv":0.0,"id":10894176},{"batb":[[2,1.74,56.29]],"batl":[[0,1.92,42.01],[1,2.3,309.75]],"ltp":0.0,"tv":0.0,"id":2263634}]}]}
{"op":"mcm","clk":"1007841572","pt":1580657144825,"mc":[{"id":"1.168224454","rc":[{"batl":[[1,3,0]],"ltp":0.0,"tv":0.0,"id":10894176}]}]}
{"op":"mcm","clk":"1007842287","pt":1580657148217,"mc":[{"id":"1.168224454","rc":[{"batl":[[1,2.84,228.62]],"ltp":0.0,"tv":0.0,"id":10894176}]}]}
{"op":"mcm","clk":"1007850021","pt":1580657183000,"mc":[{"id":"1.168224454","rc":[{"batb":[[0,2.04,26.36],[1,1.01,15.51],[2,2.04,0]],"batl":[[0,2.84,228.62],[1,2.84,0]],"ltp":0.0,"tv":0.0,"id":10894176},{"batb":[[0,1.76,21.24],[1,1.01,15.51],[2,1.74,0]],"batl":[[0,2.3,309.75],[1,2.3,0]],"ltp":0.0,"tv":0.0,"id":2263634}]}]}
{"op":"mcm","clk":"1007853245","pt":1580657197180,"mc":[{"id":"1.168224454","rc":[{"batb":[[1,1.97,29.51],[2,1.01,15.51]],"ltp":0.0,"tv":0.0,"id":10894176},{"batb":[[0,1.84,18.33],[1,1.8,19.43],[2,1.76,21.24]],"ltp":0.0,"tv":0.0,"id":2263634}]}]}
{"op":"mcm","clk":"1007853539","pt":1580657198398,"mc":[{"id":"1.168224454","rc":[{"batb":[[0,2.06,39.49],[1,2.04,26.36],[2,1.97,29.51]],"ltp":0.0,"tv":0.0,"id":10894176},{"batb":[[2,1.77,53.77]],"batl":[[0,1.95,42.01],[1,2.3,309.75]],"ltp":0.0,"tv":0.0,"id":2263634}]}]}
{"op":"mcm","clk":"1007853751","pt":1580657199405,"mc":[{"id":"1.168224454","rc":[{"batl":[[0,2.7,245.56]],"ltp":0.0,"tv":0.0,"id":10894176}]}]}
{"op":"mcm","clk":"1007853924","pt":1580657200128,"mc":[{"id":"1.168224454","rc":[{"batl":[[0,2.3,31.93],[1,2.7,245.56]],"ltp":0.0,"tv":0.0,"id":10894176}]}]}
{"op":"mcm","clk":"1007855823","pt":1580657208199,"mc":[{"id":"1.168224454","rc":[{"batb":[[1,1.97,29.35],[2,1.01,15.51]],"ltp":0.0,"tv":0.0,"id":10894176},{"batb":[[0,1.8,19.43],[1,1.77,53.77],[2,1.01,15.51]],"ltp":0.0,"tv":0.0,"id":2263634}]}]}
{"op":"mcm","clk":"1007856010","pt":1580657209019,"mc":[{"id":"1.168224454","rc":[{"batb":[[0,1.97,29.35],[1,1.01,15.51],[2,1.01,0]],"batl":[[0,2.7,245.56],[1,2.7,0]],"ltp":0.0,"tv":0.0,"id":10894176},{"batb":[[1,1.01,15.51],[2,1.01,0]],"batl":[[0,2.3,309.75],[1,2.3,0]],"ltp":0.0,"tv":0.0,"id":2263634}]}]}
{"op":"mcm","clk":"1007858842","pt":1580657220350,"mc":[{"id":"1.168224454","rc":[{"batb":[[0,2.08,63.28],[1,2,27.7],[2,1.97,29.35]],"batl":[[0,2.34,31.09],[1,2.7,245.56]],"ltp":0.0,"tv":0.0,"id":10894176},{"batb":[[1,1.77,20.61],[2,1.76,54.61]],"batl":[[0,1.93,42.01],[1,2.3,309.75]],"ltp":0.0,"tv":0.0,"id":2263634}]}]}
{"op":"mcm","clk":"1007858923","pt":1580657220622,"mc":[{"id":"1.168224454","rc":[{"batb":[[2,1.01,15.51]],"ltp":0.0,"tv":0.0,"id":10894176}]}]}
{"op":"mcm","clk":"1007859843","pt":1580657224313,"mc":[{"id":"1.168224454","rc":[{"batb":[[2,1.98,161.4]],"ltp":0.0,"tv":0.0,"id":10894176}]}]}
{"op":"mcm","clk":"1007862996","pt":1580657237334,"mc":[{"id":"1.168224454","rc":[{"batb":[[0,2,27.7],[1,1.01,15.51],[2,1.98,0]],"batl":[[0,2.7,245.56],[1,2.7,0]],"ltp":0.0,"tv":0.0,"id":10894176},{"batb":[[0,1.77,20.61],[1,1.01,15.51],[2,1.76,0]],"batl":[[0,2.3,309.75],[1,2.3,0]],"ltp":0.0,"tv":0.0,"id":2263634}]}]}
{"op":"mcm","clk":"1007866671","pt":1580657252996,"mc":[{"id":"1.168224454","rc":[{"batb":[[1,1.93,15.66],[2,1.01,15.51]],"ltp":0.0,"tv":0.0,"id":10894176},{"batb":[[0,1.87,17.47],[1,1.82,18.8],[2,1.01,15.51]],"ltp":0.0,"tv":0.0,"id":2263634}]}]}
{"op":"mcm","clk":"1007866865","pt":1580657253869,"mc":[{"id":"1.168224454","rc":[{"batb":[[0,2.02,41.17],[1,2,27.7],[2,1.93,15.66]],"batl":[[0,2.28,32.77],[1,2.7,245.56]],"ltp":0.0,"tv":0.0,"id":10894176},{"batb":[[2,1.8,52.09]],"batl":[[0,1.98,42.01]],"ltp":0.0,"tv":0.0,"id":2263634}]}]}
{"op":"mcm","clk":"1007867101","pt":1580657254889,"mc":[{"id":"1.168224454","rc":[{"batl":[[1,2.6,257.57]],"ltp":0.0,"tv":0.0,"id":2263634}]}]}
{"op":"mcm","clk":"1007869992","pt":1580657267403,"mc":[{"id":"1.168224454","rc":[{"batb":[[0,1.93,15.66],[1,1.01,15.51],[2,1.93,0]],"batl":[[0,2.7,245.56],[1,2.7,0]],"ltp":0.0,"tv":0.0,"id":10894176},{"batb":[[0,1.82,18.8],[1,1.01,15.51],[2,1.8,0]],"batl":[[0,2.6,257.57],[1,2.6,0]],"ltp":0.0,"tv":0.0,"id":2263634}]}]}
{"op":"mcm","clk":"1007873703","pt":1580657283380,"mc":[{"id":"1.168224454","rc":[{"batb":[[0,2.06,25.65],[1,1.97,29.43],[2,1.93,15.66]],"ltp":0.0,"tv":0.0,"id":10894176},{"batb":[[1,1.8,19.67],[2,1.01,15.51]],"ltp":0.0,"tv":0.0,"id":2263634}]}]}
{"op":"mcm","clk":"1007873808","pt":1580657283904,"mc":[{"id":"1.168224454","rc":[{"batb":[[0,2.06,65.14],[2,1.01,15.51]],"batl":[[0,2.3,31.93],[1,2.7,245.56]],"ltp":0.0,"tv":0.0,"id":10894176},{"batb":[[2,1.78,53.77]],"batl":[[0,1.96,42.01],[1,2.6,257.57]],"ltp":0.0,"tv":0.0,"id":2263634}]}]}
{"op":"mcm","clk":"1007873965","pt":1580657284623,"mc":[{"id":"1.168224454","rc":[{"trd":[[1.82,37.5]],"batb":[[0,1.8,19.72],[1,1.78,53.77],[2,1.01,15.51]],"ltp":1.82,"tv":37.5,"id":2263634}],"tv":37.5}]}
{"op":"mcm","clk":"1007877624","pt":1580657300316,"mc":[{"id":"1.168224454","rc":[{"batb":[[0,2.06,39.49]],"ltp":0.0,"tv":0.0,"id":10894176},{"batb":[[0,1.8,19.67]],"ltp":1.82,"tv":37.5,"id":2263634}]}]}
{"op":"mcm","clk":"1007877864","pt":1580657301360,"mc":[{"id":"1.168224454","rc":[{"batb":[[0,1.97,29.43],[1,1.01,15.51],[2,1.01,0]],"batl":[[0,2.7,245.56],[1,2.7,0]],"ltp":0.0,"tv":0.0,"id":10894176},{"batb":[[1,1.01,15.51],[2,1.01,0]],"batl":[[0,2.6,257.57],[1,2.6,0]],"ltp":1.82,"tv":37.5,"id":2263634}]}]}
{"op":"mcm","clk":"1007878327","pt":1580657303219,"mc":[{"id":"1.168224454","rc":[{"batb":[[0,2,28.88]],"ltp":0.0,"tv":0.0,"id":10894176},{"batb":[[0,1.79,20.06]],"ltp":1.82,"tv":37.5,"id":2263634}]}]}
{"op":"mcm","clk":"1007882216","pt":1580657319983,"mc":[{"id":"1.168224454","rc":[{"batb":[[0,2.14,24],[1,2.08,38.65],[2,2.06,26.36]],"batl":[[0,2.34,31.09],[1,2.7,245.56]],"ltp":0.0,"tv":0.0,"id":10894176},{"batb":[[1,1.76,21.01],[2,1.75,55.45]],"batl":[[0,1.93,42.01],[1,2.6,257.57]],"ltp":1.82,"tv":37.5,"id":2263634}]}]}
{"op":"mcm","clk":"1007882975","pt":1580657323149,"mc":[{"id":"1.168224454","rc":[{"batb":[[2,2.06,469.1]],"ltp":0.0,"tv":0.0,"id":10894176}]}]}
{"op":"mcm","clk":"1007886213","pt":1580657337122,"mc":[{"id":"1.168224454","rc":[{"batb":[[0,2.06,26.36],[1,1.01,15.51],[2,2.06,0]],"batl":[[0,2.7,245.56],[1,2.7,0]],"ltp":0.0,"tv":0.0,"id":10894176},{"batb":[[0,1.76,21.01],[1,1.01,15.51],[2,1.75,0]],"batl":[[0,2.6,257.57],[1,2.6,0]],"ltp":1.82,"tv":37.5,"id":2263634}]}]}
{"op":"mcm","clk":"1007888766","pt":1580657348156,"mc":[{"id":"1.168224454","rc":[{"batb":[[0,2.18,22.9],[1,2.16,36.13],[2,2.14,24]],"batl":[[0,2.42,29.41],[1,2.7,245.56]],"ltp":0.0,"tv":0.0,"id":10894176},{"batb":[[1,1.71,82.34],[2,1.01,15.51]],"batl":[[0,1.88,42.01]],"ltp":1.82,"tv":37.5,"id":2263634}]}]}
{"op":"mcm","clk":"1007889111","pt":1580657349850,"mc":[{"id":"1.168224454","rc":[{"batl":[[1,2.4,289.78]],"ltp":1.82,"tv":37.5,"id":2263634}]}]}
{"op":"mcm","clk":"1007893136","pt":1580657369228,"mc":[{"id":"1.168224454","rc":[{"trd":[[1.76,41.54]],"batb":[[0,1.71,82.58],[1,1.01,15.51],[2,1.01,0]],"ltp":1.76,"tv":79.04,"id":2263634}],"tv":79.04}]}
{"op":"mcm","clk":"1007893875","pt":1580657373026,"mc":[{"id":"1.168224454","rc":[{"batb":[[0,2.14,24],[1,1.01,15.51],[2,2.14,0]],"batl":[[0,2.7,245.56],[1,2.7,0]],"ltp":0.0,"tv":0.0,"id":10894176},{"batb":[[0,1.71,23.53]],"batl":[[0,2.4,289.78],[1,2.4,0]],"ltp":1.76,"tv":79.04,"id":2263634}]}]}
{"op":"mcm","clk":"1007894323","pt":1580657375360,"mc":[{"id":"1.168224454","rc":[{"batb":[[0,2.16,23.53],[1,2.14,24],[2,1.01,15.51]],"ltp":0.0,"tv":0.0,"id":10894176},{"batb":[[1,1.7,23.92],[2,1.01,15.51]],"ltp":1.76,"tv":79.04,"id":2263634}]}]}
{"op":"mcm","clk":"1007894540","pt":1580657376423,"mc":[{"id":"1.168224454","rc":[{"batb":[[1,1.01,15.51],[2,1.01,0]],"ltp":0.0,"tv":0.0,"id":10894176},{"batb":[[0,1.7,23.92],[1,1.01,15.51],[2,1.01,0]],"ltp":1.76,"tv":79.04,"id":2263634}]}]}
{"op":"mcm","clk":"1007896300","pt":1580657384434,"mc":[{"id":"1.168224454","rc":[{"batb":[[1,2.12,61.83],[2,1.01,15.51]],"batl":[[0,2.38,30.25],[1,2.7,245.56]],"ltp":0.0,"tv":0.0,"id":10894176},{"batb":[[0,1.78,20.46],[1,1.73,79.64],[2,1.72,576.34]],"batl":[[0,1.91,42.01],[1,2.4,289.78]],"ltp":1.76,"tv":79.04,"id":2263634}]}]}
{"op":"mcm","clk":"1007899565","pt":1580657399391,"mc":[{"id":"1.168224454","rc":[{"batb":[[0,2.12,61.83],[1,1.01,15.51],[2,1.01,0]],"ltp":0.0,"tv":0.0,"id":10894176},{"batb":[[0,1.73,79.64],[1,1.01,15.51],[2,1.72,0]],"ltp":1.76,"tv":79.04,"id":2263634}]}]}
{"op":"mcm","clk":"1007899964","pt":1580657400962,"mc":[{"id":"1.168224454","rc":[{"batb":[[0,2.12,24.86]],"batl":[[0,2.7,245.56],[1,2.7,0]],"ltp":0.0,"tv":0.0,"id":10894176},{"batb":[[0,1.73,22.5]],"batl":[[0,2.4,289.78],[1,2.4,0]],"ltp":1.76,"tv":79.04,"id":2263634}]}]}
{"op":"mcm","clk":"1007902333","pt":1580657410365,"mc":[{"id":"1.168224454","rc":[{"batb":[[1,2.1,25.89],[2,2.08,38.65]],"batl":[[0,2.34,31.09],[1,2.7,245.56]],"ltp":0.0,"tv":0.0,"id":10894176},{"batb":[[0,1.81,19.43],[1,1.76,75.86],[2,1.01,15.51]],"batl":[[0,1.93,42.01],[1,2.4,289.78]],"ltp":1.76,"tv":79.04,"id":2263634}]}]}
{"op":"mcm","clk":"1007903142","pt":1580657413830,"mc":[{"id":"1.168224454","rc":[{"batb":[[2,1.73,565.39]],"ltp":1.76,"tv":79.04,"id":2263634}]}]}
{"op":"mcm","clk":"1007905766","pt":1580657426315,"mc":[{"id":"1.168224454","rc":[{"batb":[[0,2.1,25.89],[1,2.08,38.65],[2,1.01,15.51]],"ltp":0.0,"tv":0.0,"id":10894176},{"batb":[[0,1.76,75.86],[1,1.01,15.51],[2,1.73,0]],"ltp":1.76,"tv":79.04,"id":2263634}]}]}
{"op":"mcm","clk":"1007905914","pt":1580657427003,"mc":[{"id":"1.168224454","rc":[{"batb":[[1,1.01,15.51],[2,1.01,0]],"batl":[[0,2.7,245.56],[1,2.7,0]],"ltp":0.0,"tv":0.0,"id":10894176},{"batb":[[0,1.76,21.24]],"batl":[[0,2.4,289.78],[1,2.4,0]],"ltp":1.76,"tv":79.04,"id":2263634}]}]}
{"op":"mcm","clk":"1007909329","pt":1580657442029,"mc":[{"id":"1.168224454","rc":[{"batb":[[0,2.2,22.58],[1,2.16,23.84],[2,2.14,36.13]],"batl":[[0,2.4,29.41],[1,2.7,245.56]],"ltp":0.0,"tv":0.0,"id":10894176},{"batb":[[1,1.72,57.97],[2,1.7,23.6]],"batl":[[0,1.89,42.01],[1,2.4,289.78]],"ltp":1.76,"tv":79.04,"id":2263634}]}]}
{"op":"mcm","clk":"1007913586","pt":1580657460987,"mc":[{"id":"1.168224454","rc":[{"batb":[[0,2.16,23.84],[1,1.01,15.51],[2,2.14,0]],"batl":[[0,2.7,245.56],[1,2.7,0]],"ltp":0.0,"tv":0.0,"id":10894176},{"batb":[[0,1.7,23.6],[1,1.01,15.51],[2,1.7,0]],"batl":[[0,2.4,289.78],[1,2.4,0]],"ltp":1.76,"tv":79.04,"id":2263634}]}]}
{"op":"mcm","clk":"1007918403","pt":1580657482429,"mc":[{"id":"1.168224454","rc":[{"batb":[[1,2.12,24.94],[2,2.1,37.81]],"batl":[[0,2.36,30.25]],"ltp":0.0,"tv":0.0,"id":10894176},{"batb":[[0,1.78,20.22],[1,1.74,78.4],[2,1.7,23.6]],"batl":[[0,1.92,42.01]],"ltp":1.76,"tv":79.04,"id":2263634}]}]}
{"op":"mcm","clk":"1007918449","pt":1580657482628,"mc":[{"id":"1.168224454","rc":[{"batb":[[2,1.01,15.51]],"ltp":1.76,"tv":79.04,"id":2263634}]}]}
{"op":"mcm","clk":"1007918657","pt":1580657483616,"mc":[{"id":"1.168224454","rc":[{"batb":[[2,1.72,573.84]],"ltp":1.76,"tv":79.04,"id":2263634}]}]}
{"op":"mcm","clk":"1007922304","pt":1580657500149,"mc":[{"id":"1.168224454","rc":[{"batb":[[2,1.01,15.51]],"ltp":1.76,"tv":79.04,"id":2263634}]}]}
{"op":"mcm","clk":"1007922515","pt":1580657501066,"mc":[{"id":"1.168224454","rc":[{"batb":[[0,2.12,24.94],[1,1.01,15.51],[2,2.1,0]],"ltp":0.0,"tv":0.0,"id":10894176},{"batb":[[0,1.74,22.11],[1,1.01,15.51],[2,1.01,0]],"ltp":1.76,"tv":79.04,"id":2263634}]}]}
{"op":"mcm","clk":"1007925342","pt":1580657513344,"mc":[{"id":"1.168224454","rc":[{"batb":[[0,2.24,21.64],[1,2.2,22.82],[2,2.12,24.94]],"ltp":0.0,"tv":0.0,"id":10894176},{"batb":[[1,1.68,24.71],[2,1.01,15.51]],"ltp":1.76,"tv":79.04,"id":2263634}]}]}
{"op":"mcm","clk":"1007925579","pt":1580657514391,"mc":[{"id":"1.168224454","rc":[{"batb":[[2,2.16,36.13]],"batl":[[0,2.44,28.57]],"ltp":0.0,"tv":0.0,"id":10894176},{"batb":[[1,1.71,58.81],[2,1.68,24.71]],"batl":[[0,1.87,42.01]],"ltp":1.76,"tv":79.04,"id":2263634}]}]}
{"op":"mcm","clk":"1007929649","pt":1580657531366,"mc":[{"id":"1.168224454","rc":[{"batb":[[0,2.2,22.82],[1,2.16,36.13],[2,1.01,15.51]],"ltp":0.0,"tv":0.0,"id":10894176},{"batb":[[0,1.71,58.81],[1,1.68,24.71],[2,1.01,15.51]],"ltp":1.76,"tv":79.04,"id":2263634}]}]}
{"op":"mcm","clk":"1007930112","pt":1580657533275,"mc":[{"id":"1.168224454","rc":[{"batb":[[1,1.01,15.51],[2,1.01,0]],"ltp":0.0,"tv":0.0,"id":10894176},{"batb":[[0,1.68,24.71],[1,1.01,15.51],[2,1.01,0]],"ltp":1.76,"tv":79.04,"id":2263634}]}]}
{"op":"mcm","clk":"1007930363","pt":1580657535320,"mc":[{"id":"1.168224454","rc":[{"batb":[[0,2.18,23.21]],"ltp":0.0,"tv":0.0,"id":10894176},{"batb":[[0,1.69,24.31]],"ltp":1.76,"tv":79.04,"id":2263634}]}]}
{"op":"mcm","clk":"1007936402","pt":1580657562911,"mc":[{"id":"1.168224454","rc":[{"batb":[[1,2.1,26.04],[2,1.01,15.51]],"ltp":0.0,"tv":0.0,"id":10894176},{"batb":[[0,1.77,20.69],[1,1.74,21.72],[2,1.72,573.84]],"ltp":1.76,"tv":79.04,"id":2263634}]}]}
{"op":"mcm","clk":"1007936731","pt":1580657564390,"mc":[{"id":"1.168224454","rc":[{"batb":[[1,2.1,63.85]],"batl":[[0,2.36,30.25]],"ltp":0.0,"tv":0.0,"id":10894176},{"batb":[[1,1.75,55.45],[2,1.74,21.72]],"batl":[[0,1.92,42.01]],"ltp":1.76,"tv":79.04,"id":2263634}]}]}
{"op":"mcm","clk":"1007956186","pt":1580657649247,"mc":[{"id":"1.168224454","rc":[{"batb":[[0,2.1,26.04],[1,1.01,15.51],[2,1.01,0]],"ltp":0.0,"tv":0.0,"id":10894176},{"batb":[[0,1.74,21.72],[1,1.01,15.51],[2,1.74,0]],"ltp":1.76,"tv":79.04,"id":2263634}]}]}
{"op":"mcm","clk":"1007958210","pt":1580657658349,"mc":[{"id":"1.168224454","rc":[{"batb":[[1,2.04,40.33],[2,2,29.74]],"batl":[[0,2.3,31.93]],"ltp":0.0,"tv":0.0,"id":10894176},{"batb":[[0,1.83,18.57],[1,1.8,19.59],[2,1.79,52.93]],"batl":[[0,1.97,42.01]],"ltp":1.76,"tv":79.04,"id":2263634}]}]}
{"op":"mcm","clk":"1007960233","pt":1580657667381,"mc":[{"id":"1.168224454","rc":[{"batb":[[0,2,29.74],[1,1.01,15.51],[2,2,0]],"ltp":0.0,"tv":0.0,"id":10894176},{"batb":[[0,1.8,19.59],[1,1.01,15.51],[2,1.79,0]],"ltp":1.76,"tv":79.04,"id":2263634}]}]}
{"op":"mcm","clk":"1007967061","pt":1580657698322,"mc":[{"id":"1.168224454","rc":[{"batb":[[1,1.98,42.85],[2,1.93,16.84]],"batl":[[0,2.22,33.61]],"ltp":0.0,"tv":0.0,"id":10894176},{"batb":[[0,1.91,16.29],[1,1.86,17.62],[2,1.83,50.41]],"batl":[[0,2.02,41.17]],"ltp":1.76,"tv":79.04,"id":2263634}]}]}
{"op":"mcm","clk":"1007970500","pt":1580657713464,"mc":[{"id":"1.168224454","rc":[{"batb":[[0,1.98,42.85],[1,1.93,16.84],[2,1.01,15.51]],"ltp":0.0,"tv":0.0,"id":10894176},{"batb":[[0,1.86,17.62],[1,1.83,50.41],[2,1.01,15.51]],"ltp":1.76,"tv":79.04,"id":2263634}]}]}
{"op":"mcm","clk":"1007970872","pt":1580657715134,"mc":[{"id":"1.168224454","rc":[{"batb":[[0,1.93,16.84],[1,1.01,15.51],[2,1.01,0]],"ltp":0.0,"tv":0.0,"id":10894176},{"batb":[[1,1.01,15.51],[2,1.01,0]],"ltp":1.76,"tv":79.04,"id":2263634}]}]}
{"op":"mcm","clk":"1007975468","pt":1580657736260,"mc":[{"id":"1.168224454","rc":[{"batb":[[0,1.94,44.53],[1,1.93,16.84],[2,1.84,19.36]],"batl":[[0,2.18,35.29]],"ltp":0.0,"tv":0.0,"id":10894176},{"batb":[[0,1.99,28.8],[1,1.94,15.5],[2,1.87,47.89]],"batl":[[0,2.06,39.49]],"ltp":1.76,"tv":79.04,"id":2263634}]}]}
{"op":"mcm","clk":"1007975656","pt":1580657737164,"mc":[{"id":"1.168224454","rc":[{"batl":[[0,2.16,36.13]],"ltp":0.0,"tv":0.0,"id":10894176}]}]}
{"op":"mcm","clk":"1007976091","pt":1580657739133,"mc":[{"id":"1.168224454","rc":[{"batl":[[1,2.52,270.1]],"ltp":0.0,"tv":0.0,"id":10894176},{"batl":[[1,2.7,245.56]],"ltp":1.76,"tv":79.04,"id":2263634}]}]}
{"op":"mcm","clk":"1007978152","pt":1580657749052,"mc":[{"id":"1.168224454","rc":[{"batb":[[0,1.84,19.36],[1,1.01,15.51],[2,1.84,0]],"batl":[[0,2.52,270.1],[1,2.52,0]],"ltp":0.0,"tv":0.0,"id":10894176},{"batb":[[0,1.94,15.5],[1,1.01,15.51],[2,1.87,0]],"batl":[[0,2.7,245.56],[1,2.7,0]],"ltp":1.76,"tv":79.04,"id":2263634}]}]}
{"op":"mcm","clk":"1007978615","pt":1580657751360,"mc":[{"id":"1.168224454","rc":[{"batb":[[0,1.85,19.28],[1,1.84,19.36],[2,1.01,15.51]],"ltp":0.0,"tv":0.0,"id":10894176}]}]}
{"op":"mcm","clk":"1007978651","pt":1580657751582,"mc":[{"id":"1.168224454","rc":[{"batb":[[1,1.01,15.51],[2,1.01,0]],"ltp":0.0,"tv":0.0,"id":10894176}]}]}
{"op":"mcm","clk":"1007979610","pt":1580657756363,"mc":[{"id":"1.168224454","rc":[{"batb":[[1,1.81,71.71],[2,1.01,15.51]],"batl":[[0,2,42.01]],"ltp":0.0,"tv":0.0,"id":10894176},{"batb":[[0,2.08,25.1],[1,2,70.41],[2,1.94,15.5]],"batl":[[0,2.24,33.61],[1,2.7,245.56]],"ltp":1.76,"tv":79.04,"id":2263634}]}]}
{"op":"mcm","clk":"1007979707","pt":1580657756907,"mc":[{"id":"1.168224454","rc":[{"batb":[[2,1.01,15.51]],"ltp":1.76,"tv":79.04,"id":2263634}]}]}
{"op":"mcm","clk":"1007980232","pt":1580657759389,"mc":[{"id":"1.168224454","rc":[{"batl":[[1,2.4,289.78]],"ltp":0.0,"tv":0.0,"id":10894176}]}]}
{"op":"mcm","clk":"1007988370","pt":1580657796367,"mc":[{"id":"1.168224454","rc":[{"batb":[[0,1.81,71.71],[1,1.01,15.51],[2,1.01,0]],"ltp":0.0,"tv":0.0,"id":10894176},{"batb":[[0,2,70.41],[1,1.01,15.51],[2,1.01,0]],"ltp":1.76,"tv":79.04,"id":2263634}]}]}
{"op":"mcm","clk":"1007988584","pt":1580657797382,"mc":[{"id":"1.168224454","rc":[{"batb":[[0,1.81,20.46]],"batl":[[0,2.4,289.78],[1,2.4,0]],"ltp":0.0,"tv":0.0,"id":10894176},{"batb":[[0,2,28.4]],"batl":[[0,2.7,245.56],[1,2.7,0]],"ltp":1.76,"tv":79.04,"id":2263634}]}]}
{"op":"mcm","clk":"1007988893","pt":1580657798674,"mc":[{"id":"1.168224454","rc":[{"batb":[[0,1.99,28.56]],"ltp":1.76,"tv":79.04,"id":2263634}]}]}
{"op":"mcm","clk":"1007990405","pt":1580657806369,"mc":[{"id":"1.168224454","rc":[{"batb":[[1,1.79,52.93],[2,1.78,21.72]],"batl":[[0,1.97,42.01],[1,2.4,289.78]],"ltp":0.0,"tv":0.0,"id":10894176},{"batb":[[0,2.12,23.6],[1,2.04,66.85],[2,1.01,15.51]],"batl":[[0,2.28,32.77],[1,2.7,245.56]],"ltp":1.76,"tv":79.04,"id":2263634}]}]}
{"op":"mcm","clk":"1007993722","pt":1580657821414,"mc":[{"id":"1.168224454","rc":[{"batb":[[0,1.79,52.93],[1,1.78,21.72],[2,1.01,15.51]],"ltp":0.0,"tv":0.0,"id":10894176},{"batb":[[0,2.04,66.85],[1,1.01,15.51],[2,1.01,0]],"ltp":1.76,"tv":79.04,"id":2263634}]}]}
{"op":"mcm","clk":"1007994140","pt":1580657823176,"mc":[{"id":"1.168224454","rc":[{"batb":[[0,1.78,21.72],[1,1.01,15.51],[2,1.01,0]],"batl":[[0,2.4,289.78],[1,2.4,0]],"ltp":0.0,"tv":0.0,"id":10894176},{"batb":[[0,2.04,26.52]],"batl":[[0,2.7,245.56],[1,2.7,0]],"ltp":1.76,"tv":79.04,"id":2263634}]}]}
{"op":"mcm","clk":"1007998858","pt":1580657844015,"mc":[{"id":"1.168224454","rc":[{"batb":[[0,1.88,18.25],[1,1.84,19.43],[2,1.83,50.41]],"batl":[[0,2.02,41.17],[1,2.4,289.78]],"ltp":0.0,"tv":0.0,"id":10894176},{"batb":[[1,2,42.01],[2,1.95,30.45]],"batl":[[0,2.22,33.61],[1,2.7,245.56]],"ltp":1.76,"tv":79.04,"id":2263634}]}]}
{"op":"mcm","clk":"1008003640","pt":1580657865372,"mc":[{"id":"1.168224454","rc":[{"batb":[[0,1.84,19.43],[1,1.83,50.41],[2,1.01,15.51]],"ltp":0.0,"tv":0.0,"id":10894176},{"batb":[[0,2,42.01],[1,1.95,30.45],[2,1.01,15.51]],"ltp":1.76,"tv":79.04,"id":2263634}]}]}
{"op":"mcm","clk":"1008004076","pt":1580657867156,"mc":[{"id":"1.168224454","rc":[{"batb":[[1,1.01,15.51],[2,1.01,0]],"batl":[[0,2.4,289.78],[1,2.4,0]],"ltp":0.0,"tv":0.0,"id":10894176},{"batb":[[0,1.95,30.45],[1,1.01,15.51],[2,1.01,0]],"batl":[[0,2.7,245.56],[1,2.7,0]],"ltp":1.76,"tv":79.04,"id":2263634}]}]}
{"op":"mcm","clk":"1008005211","pt":1580657872177,"mc":[{"id":"1.168224454","rc":[{"batb":[[1,1.81,71.79],[2,1.01,15.51]],"batl":[[0,1.99,42.01],[1,2.4,289.78]],"ltp":0.0,"tv":0.0,"id":10894176},{"batb":[[0,2.08,24.78],[1,2.02,41.17],[2,2,28.09]],"batl":[[0,2.26,32.77],[1,2.7,245.56]],"ltp":1.76,"tv":79.04,"id":2263634}]}]}
{"op":"mcm","clk":"1008008216","pt":1580657885709,"mc":[{"id":"1.168224454","rc":[{"batb":[[0,1.81,71.79],[1,1.01,15.51],[2,1.01,0]],"ltp":0.0,"tv":0.0,"id":10894176},{"batb":[[0,2.02,41.17],[1,2,28.09],[2,1.01,15.51]],"ltp":1.76,"tv":79.04,"id":2263634}]}]}
{"op":"mcm","clk":"1008008522","pt":1580657887180,"mc":[{"id":"1.168224454","rc":[{"batb":[[0,1.81,20.54]],"batl":[[0,2.4,289.78],[1,2.4,0]],"ltp":0.0,"tv":0.0,"id":10894176},{"batb":[[0,2,28.09],[1,1.01,15.51],[2,1.01,0]],"batl":[[0,2.7,245.56],[1,2.7,0]],"ltp":1.76,"tv":79.04,"id":2263634}]}]}
{"op":"mcm","clk":"1008013590","pt":1580657909163,"mc":[{"id":"1.168224454","rc":[{"batb":[[1,1.77,21.87],[2,1.01,15.51]],"ltp":0.0,"tv":0.0,"id":10894176},{"batb":[[0,2.12,23.45],[1,2.04,26.2],[2,1.01,15.51]],"ltp":1.76,"tv":79.04,"id":2263634}]}]}
{"op":"mcm","clk":"1008013800","pt":1580657910090,"mc":[{"id":"1.168224454","rc":[{"batb":[[1,1.78,53.77],[2,1.77,21.87]],"batl":[[0,1.97,42.01],[1,2.4,289.78]],"ltp":0.0,"tv":0.0,"id":10894176},{"batb":[[1,2.06,39.49],[2,2.04,26.2]],"batl":[[0,2.3,31.93],[1,2.7,245.56]],"ltp":1.76,"tv":79.04,"id":2263634}]}]}
{"op":"mcm","clk":"1008018051","pt":1580657929075,"mc":[{"id":"1.168224454","rc":[{"batb":[[0,1.77,21.87],[1,1.01,15.51],[2,1.77,0]],"batl":[[0,2.4,289.78],[1,2.4,0]],"ltp":0.0,"tv":0.0,"id":10894176},{"batb":[[0,2.04,26.2],[1,1.01,15.51],[2,2.04,0]],"batl":[[0,2.7,245.56],[1,2.7,0]],"ltp":1.76,"tv":79.04,"id":2263634}]}]}
{"op":"mcm","clk":"1008021743","pt":1580657945437,"mc":[{"id":"1.168224454","rc":[{"batb":[[0,1.87,18.49],[1,1.83,19.67],[2,1.77,21.87]],"ltp":0.0,"tv":0.0,"id":10894176},{"batb":[[1,1.97,29.66],[2,1.01,15.51]],"ltp":1.76,"tv":79.04,"id":2263634}]}]}
{"op":"mcm","clk":"1008021914","pt":1580657946112,"mc":[{"id":"1.168224454","rc":[{"batb":[[2,1.82,50.41]],"batl":[[0,2,42.01],[1,2.4,289.78]],"ltp":0.0,"tv":0.0,"id":10894176},{"batb":[[1,2,42.01],[2,1.97,29.66]],"batl":[[0,2.24,33.61],[1,2.7,245.56]],"ltp":1.76,"tv":79.04,"id":2263634}]}]}
{"op":"mcm","clk":"1008025839","pt":1580657963127,"mc":[{"id":"1.168224454","rc":[{"batb":[[0,1.83,19.67],[1,1.01,15.51],[2,1.82,0]],"batl":[[0,2.4,289.78],[1,2.4,0]],"ltp":0.0,"tv":0.0,"id":10894176},{"batb":[[0,1.97,29.66],[1,1.01,15.51],[2,1.97,0]],"batl":[[0,2.7,245.56],[1,2.7,0]],"ltp":1.76,"tv":79.04,"id":2263634}]}]}
{"op":"mcm","clk":"1008030135","pt":1580657981325,"mc":[{"id":"1.168224454","rc":[{"batb":[[0,1.83,208.73],[1,1.81,173.99],[2,1.67,27.07]],"batl":[[0,1.92,173.2],[1,1.94,141.94],[2,2.4,289.78]],"ltp":0.0,"tv":0.0,"id":10894176},{"batb":[[0,2.1,24.47],[1,1.98,29.19],[2,1.01,15.51]],"ltp":1.76,"tv":79.04,"id":2263634}]}]}
{"op":"mcm","clk":"1008030366","pt":1580657982370,"mc":[{"id":"1.168224454","rc":[{"batb":[[2,1.8,52.09]],"ltp":0.0,"tv":0.0,"id":10894176},{"batb":[[1,2.02,41.17],[2,1.98,29.19]],"batl":[[0,2.26,32.77],[1,2.7,245.56]],"ltp":1.76,"tv":79.04,"id":2263634}]}]}
{"op":"mcm","clk":"1008030415","pt":1580657982538,"mc":[{"id":"1.168224454","rc":[{"batl":[[2,1.98,42.01]],"ltp":0.0,"tv":0.0,"id":10894176}]}]}
{"op":"mcm","clk":"1008032912","pt":1580657992974,"mc":[{"id":"1.168224454","rc":[{"batb":[[0,1.84,19.43],[1,1.83,189.06],[2,1.81,173.99]],"ltp":0.0,"tv":0.0,"id":10894176},{"batb":[[0,2.08,24.86],[2,1.97,29.66]],"ltp":1.76,"tv":79.04,"id":2263634}]}]}
{"op":"mcm","clk":"1008037034","pt":1580658010186,"mc":[{"id":"1.168224454","rc":[{"batb":[[0,1.85,19.12]],"ltp":0.0,"tv":0.0,"id":10894176},{"batb":[[2,1.96,30.06]],"ltp":1.76,"tv":79.04,"id":2263634}]}]}
{"op":"mcm","clk":"1008051957","pt":1580658071981,"mc":[{"id":"1.168224454","rc":[{"batb":[[0,1.8,52.09],[1,1.68,26.36],[2,1.01,15.51]],"batl":[[0,1.98,42.01],[1,2.4,289.78],[2,1.98,0]],"ltp":0.0,"tv":0.0,"id":10894176},{"batb":[[0,2.02,41.17],[1,1.96,30.06],[2,1.01,15.51]],"ltp":1.76,"tv":79.04,"id":2263634}]}]}
{"op":"mcm","clk":"1008052245","pt":1580658073155,"mc":[{"id":"1.168224454","rc":[{"batb":[[0,1.68,26.36],[1,1.01,15.51],[2,1.01,0]],"batl":[[0,2.4,289.78],[1,2.4,0]],"ltp":0.0,"tv":0.0,"id":10894176},{"batb":[[0,1.96,30.06],[1,1.01,15.51],[2,1.01,0]],"batl":[[0,2.7,245.56],[1,2.7,0]],"ltp":1.76,"tv":79.04,"id":2263634}]}]}
{"op":"mcm","clk":"1008052974","pt":1580658076461,"mc":[{"id":"1.168224454","rc":[{"batb":[[0,1.8,144.64],[1,1.78,183.79],[2,1.68,26.36]],"batl":[[0,1.88,170.17],[1,1.9,151.26],[2,2.4,289.78]],"ltp":0.0,"tv":0.0,"id":10894176}]}]}
{"op":"mcm","clk":"1008053900","pt":1580658080790,"mc":[{"id":"1.168224454","rc":[{"batb":[[0,1.68,26.36],[1,1.01,15.51],[2,1.68,0]],"batl":[[0,2.4,289.78],[1,1.9,0],[2,2.4,0]],"ltp":0.0,"tv":0.0,"id":10894176}]}]}
{"op":"mcm","clk":"1008054593","pt":1580658083759,"mc":[{"id":"1.168224454","rc":[{"batb":[[1,1.67,167.84],[2,1.66,117.62]],"batl":[[0,2.04,158.17],[1,2.06,118.77],[2,2.4,289.78]],"ltp":0.0,"tv":0.0,"id":10894176}]}]}
{"op":"mcm","clk":"1008057594","pt":1580658097412,"mc":[{"id":"1.168224454","rc":[{"batl":[[0,2.4,289.78],[1,2.06,0],[2,2.4,0]],"ltp":0.0,"tv":0.0,"id":10894176}]}]}
{"op":"mcm","clk":"1008058335","pt":1580658100435,"mc":[{"id":"1.168224454","rc":[{"batl":[[0,1.74,202.66],[1,1.76,192.77]],"ltp":0.0,"tv":0.0,"id":10894176}]}]}
{"op":"mcm","clk":"1008058525","pt":1580658101228,"mc":[{"id":"1.168224454","rc":[{"batb":[[0,2.34,17.86],[1,2.12,23.29],[2,1.01,15.51]],"ltp":1.76,"tv":79.04,"id":2263634}]}]}
{"op":"mcm","clk":"1008058771","pt":1580658102305,"mc":[{"id":"1.168224454","rc":[{"batb":[[2,1.66,180.63]],"batl":[[2,1.81,42.01]],"ltp":0.0,"tv":0.0,"id":10894176},{"batb":[[1,2.24,33.61],[2,2.12,23.29]],"batl":[[0,2.54,26.89]],"ltp":1.76,"tv":79.04,"id":2263634}]}]}
{"op":"mcm","clk":"1008059157","pt":1580658103935,"mc":[{"id":"1.168224454","rc":[{"batl":[[1,3.15,200.42]],"ltp":1.76,"tv":79.04,"id":2263634}]}]}
{"op":"mcm","clk":"1008061155","pt":1580658112397,"mc":[{"id":"1.168224454","rc":[{"batb":[[0,1.66,63.01],[1,1.49,40.52],[2,1.01,15.51]],"batl":[[0,1.81,42.01],[1,2.22,329.01],[2,1.81,0]],"ltp":0.0,"tv":0.0,"id":10894176},{"batb":[[0,2.24,33.61],[1,2.12,23.29],[2,1.01,15.51]],"ltp":1.76,"tv":79.04,"id":2263634}]}]}
{"op":"mcm","clk":"1008061403","pt":1580658113434,"mc":[{"id":"1.168224454","rc":[{"batb":[[0,1.49,40.52],[1,1.01,15.51],[2,1.01,0]],"batl":[[0,2.22,329.01],[1,2.22,0]],"ltp":0.0,"tv":0.0,"id":10894176},{"batb":[[0,2.12,23.29],[1,1.01,15.51],[2,1.01,0]],"batl":[[0,3.15,200.42],[1,3.15,0]],"ltp":1.76,"tv":79.04,"id":2263634}]}]}
{"op":"mcm","clk":"1008061983","pt":1580658115870,"mc":[{"id":"1.168224454","rc":[{"batb":[[0,1.49,40.13]],"ltp":0.0,"tv":0.0,"id":10894176},{"batb":[[0,2.14,23.21]],"ltp":1.76,"tv":79.04,"id":2263634}]}]}
{"op":"mcm","clk":"1008062312","pt":1580658117272,"mc":[{"id":"1.168224454","rc":[{"batb":[[0,1.63,188.81],[1,1.62,128.53],[2,1.49,40.13]],"batl":[[0,1.69,129.49],[1,1.71,212.56],[2,2.22,329.01]],"ltp":0.0,"tv":0.0,"id":10894176}]}]}
{"op":"mcm","clk":"1008063182","pt":1580658120980,"mc":[{"id":"1.168224454","rc":[{"batb":[[0,1.49,40.13],[1,1.01,15.51],[2,1.49,0]],"batl":[[0,2.22,329.01],[1,1.71,0],[2,2.22,0]],"ltp":0.0,"tv":0.0,"id":10894176}]}]}
{"op":"mcm","clk":"1008063848","pt":1580658123975,"mc":[{"id":"1.168224454","rc":[{"batb":[[0,1.49,289.9],[1,1.48,183.11],[2,1.01,15.51]],"batl":[[0,1.87,123.76],[1,1.89,153.83],[2,2.22,329.01]],"ltp":0.0,"tv":0.0,"id":10894176}]}]}
{"op":"mcm","clk":"1008065723","pt":1580658131900,"mc":[{"id":"1.168224454","rc":[{"batl":[[0,2.22,329.01],[1,1.89,0],[2,2.22,0]],"ltp":0.0,"tv":0.0,"id":10894176}]}]}
{"op":"mcm","clk":"1008066506","pt":1580658135194,"mc":[{"id":"1.168224454","rc":[{"batb":[[2,1.33,66.8]],"batl":[[0,1.54,153.52],[1,1.55,149.89]],"ltp":0.0,"tv":0.0,"id":10894176},{"batb":[[0,2.82,10.86],[1,2.48,15.26],[2,1.01,15.51]],"ltp":1.76,"tv":79.04,"id":2263634}]}]}
{"op":"mcm","clk":"1008066727","pt":1580658136121,"mc":[{"id":"1.168224454","rc":[{"batb":[[0,1.5,84.02],[1,1.49,289.9],[2,1.48,183.11]],"batl":[[2,1.63,42.01]],"ltp":0.0,"tv":0.0,"id":10894176},{"batb":[[1,2.58,26.05],[2,2.48,15.26]],"batl":[[0,2.98,21]],"ltp":1.76,"tv":79.04,"id":2263634}]}]}
{"op":"mcm","clk":"1008066870","pt":1580658136791,"mc":[{"id":"1.168224454","rc":[{"batl":[[1,3.9,158.24]],"ltp":1.76,"tv":79.04,"id":2263634}]}]}
{"op":"mcm","clk":"1008068289","pt":1580658142809,"mc":[{"id":"1.168224454","rc":[{"batl":[[2,1.95,409.86]],"ltp":0.0,"tv":0.0,"id":10894176},{"batb":[[1,2.48,15.26],[2,1.01,15.51]],"ltp":1.76,"tv":79.04,"id":2263634}]}]}
{"op":"mcm","clk":"1008069060","pt":1580658146105,"mc":[{"id":"1.168224454","rc":[{"batl":[[2,1.62,42.01]],"ltp":0.0,"tv":0.0,"id":10894176},{"batb":[[1,2.6,26.05],[2,2.48,15.26]],"ltp":1.76,"tv":79.04,"id":2263634}]}]}
{"op":"mcm","clk":"1008069577","pt":1580658148312,"mc":[{"id":"1.168224454","rc":[{"batb":[[1,1.33,66.8],[2,1.01,15.51]],"batl":[[0,1.62,42.01],[1,1.95,409.86],[2,1.62,0]],"ltp":0.0,"tv":0.0,"id":10894176},{"batb":[[0,2.6,26.05],[1,2.48,15.26],[2,1.01,15.51]],"ltp":1.76,"tv":79.04,"id":2263634}]}]}
{"op":"mcm","clk":"1008069832","pt":1580658149391,"mc":[{"id":"1.168224454","rc":[{"batb":[[0,1.33,66.8],[1,1.01,15.51],[2,1.01,0]],"batl":[[0,1.95,409.86],[1,1.95,0]],"ltp":0.0,"tv":0.0,"id":10894176},{"batb":[[0,2.48,15.26],[1,1.01,15.51],[2,1.01,0]],"batl":[[0,3.9,158.24],[1,3.9,0]],"ltp":1.76,"tv":79.04,"id":2263634}]}]}
{"op":"mcm","clk":"1008070221","pt":1580658151022,"mc":[{"id":"1.168224454","rc":[{"batb":[[0,1.34,168.93],[1,1.33,364.14],[2,1.01,15.51]],"batl":[[0,1.67,210.34],[1,1.69,220.75],[2,1.95,409.86]],"ltp":0.0,"tv":0.0,"id":10894176}]}]}
{"op":"mcm","clk":"1008071181","pt":1580658155028,"mc":[{"id":"1.168224454","rc":[{"batl":[[0,1.95,409.86],[1,1.69,0],[2,1.95,0]],"ltp":0.0,"tv":0.0,"id":10894176}]}]}
{"op":"mcm","clk":"1008071991","pt":1580658158345,"mc":[{"id":"1.168224454","rc":[{"trd":[[1.37,267.7]],"batb":[[2,1.22,104.57]],"batl":[[0,1.37,5.78],[1,1.38,242.62]],"ltp":1.37,"tv":267.69,"id":10894176},{"trd":[[3.7,15.12]],"batb":[[0,3.65,14.08],[1,3.2,19.59],[2,2.48,15.26]],"ltp":3.7,"tv":94.16,"id":2263634}],"tv":361.86}]}
{"op":"mcm","clk":"1008072172","pt":1580658159021,"mc":[{"id":"1.168224454","rc":[{"batl":[[0,1.38,242.62],[1,1.38,0]],"ltp":1.37,"tv":267.69,"id":10894176},{"batb":[[2,1.01,15.51]],"ltp":3.7,"tv":94.16,"id":2263634}]}]}
{"op":"mcm","clk":"1008072500","pt":1580658160442,"mc":[{"id":"1.168224454","rc":[{"batl":[[1,1.71,542.06]],"ltp":1.37,"tv":267.69,"id":10894176},{"batl":[[0,5.5,115.06]],"ltp":3.7,"tv":94.16,"id":2263634}]}]}
{"op":"mcm","clk":"1008072768","pt":1580658161438,"mc":[{"id":"1.168224454","rc":[{"batb":[[0,1.36,115.95],[1,1.34,234.35],[2,1.33,364.14]],"batl":[[0,1.38,338.09],[1,1.39,231.91],[2,1.43,42.01]],"ltp":1.37,"tv":267.69,"id":10894176},{"batl":[[0,3.8,14.28],[1,5.5,115.06]],"ltp":3.7,"tv":94.16,"id":2263634}]}]}
{"op":"mcm","clk":"1008072991","pt":1580658162403,"mc":[{"id":"1.168224454","rc":[{"batb":[[1,3.35,17.64],[2,3.2,19.59]],"ltp":3.7,"tv":94.16,"id":2263634}]}]}
{"op":"mcm","clk":"1008073967","pt":1580658166459,"mc":[{"id":"1.168224454","rc":[{"batb":[[1,1.34,201.59]],"ltp":1.37,"tv":267.69,"id":10894176}]}]}
{"op":"mcm","clk":"1008074689","pt":1580658169399,"mc":[{"id":"1.168224454","rc":[{"batb":[[0,1.33,364.14],[1,1.22,104.57],[2,1.01,15.51]],"batl":[[0,1.38,274.53],[1,1.43,42.01],[2,1.71,542.06]],"ltp":1.37,"tv":267.69,"id":10894176}]}]}
{"op":"mcm","clk":"1008074954","pt":1580658170443,"mc":[{"id":"1.168224454","rc":[{"batb":[[0,1.22,104.57],[1,1.01,15.51],[2,1.01,0]],"batl":[[0,1.43,42.01],[1,1.71,542.06],[2,1.71,0]],"ltp":1.37,"tv":267.69,"id":10894176},{"batb":[[0,3.35,17.64],[1,3.2,19.59],[2,1.01,15.51]],"ltp":3.7,"tv":94.16,"id":2263634}]}]}
{"op":"mcm","clk":"1008075147","pt":1580658171355,"mc":[{"id":"1.168224454","rc":[{"batl":[[0,1.71,542.06],[1,1.71,0]],"ltp":1.37,"tv":267.69,"id":10894176},{"batb":[[0,3.2,19.59],[1,1.01,15.51],[2,1.01,0]],"batl":[[0,5.5,115.06],[1,5.5,0]],"ltp":3.7,"tv":94.16,"id":2263634}]}]}
{"op":"mcm","clk":"1008075426","pt":1580658172431,"mc":[{"id":"1.168224454","rc":[{"batb":[[0,1.24,343.61],[1,1.23,469.49],[2,1.22,104.57]],"batl":[[0,1.44,146.72],[1,1.45,196],[2,1.71,542.06]],"ltp":1.37,"tv":267.69,"id":10894176}]}]}
{"op":"mcm","clk":"1008075537","pt":1580658172832,"mc":[{"id":"1.168224454","rc":[{"batb":[[1,1.23,572.25],[2,1.01,15.51]],"ltp":1.37,"tv":267.69,"id":10894176},{"batb":[[0,3.15,20.06]],"ltp":3.7,"tv":94.16,"id":2263634}]}]}
{"op":"mcm","clk":"1008075934","pt":1580658174437,"mc":[{"id":"1.168224454","rc":[{"batb":[[0,1.23,102.76],[1,1.01,15.51],[2,1.01,0]],"ltp":1.37,"tv":267.69,"id":10894176}]}]}
{"op":"mcm","clk":"1008076710","pt":1580658177342,"mc":[{"id":"1.168224454","rc":[{"batb":[[0,1.4,270.56],[1,1.39,241.82],[2,1.23,102.76]],"ltp":1.37,"tv":267.69,"id":10894176}]}]}
{"op":"mcm","clk":"1008076970","pt":1580658178425,"mc":[{"id":"1.168224454","rc":[{"batb":[[0,1.41,152.96],[1,1.4,270.56],[2,1.39,241.82]],"batl":[[2,1.49,42.01]],"ltp":1.37,"tv":267.69,"id":10894176},{"batb":[[1,3.05,20.16],[2,2.7,12.2]],"batl":[[0,3.45,16.8]],"ltp":3.7,"tv":94.16,"id":2263634}]}]}
{"op":"mcm","clk":"1008077356","pt":1580658179960,"mc":[{"id":"1.168224454","rc":[{"batl":[[1,4.6,136.05]],"ltp":3.7,"tv":94.16,"id":2263634}]}]}
{"op":"mcm","clk":"1008079099","pt":1580658187438,"mc":[{"id":"1.168224454","rc":[{"batb":[[1,1.4,232.28]],"ltp":1.37,"tv":267.69,"id":10894176}]}]}
{"op":"mcm","clk":"1008079549","pt":1580658189373,"mc":[{"id":"1.168224454","rc":[{"batb":[[0,1.24,97.33],[1,1.01,15.51],[2,1.39,0]],"batl":[[0,1.71,542.06],[1,1.45,0],[2,1.49,0]],"ltp":1.37,"tv":267.69,"id":10894176},{"batb":[[0,2.7,12.2],[1,1.01,15.51],[2,2.7,0]],"batl":[[0,4.6,136.05],[1,4.6,0]],"ltp":3.7,"tv":94.16,"id":2263634}]}]}
{"op":"mcm","clk":"1008079763","pt":1580658190369,"mc":[{"id":"1.168224454","rc":[{"batl":[[0,1.44,37.19],[1,1.71,542.06]],"ltp":1.37,"tv":267.69,"id":10894176}]}]}
{"op":"mcm","clk":"1008079971","pt":1580658191158,"mc":[{"id":"1.168224454","rc":[{"batl":[[0,1.71,542.06],[1,1.71,0]],"ltp":1.37,"tv":267.69,"id":10894176}]}]}
{"op":"mcm","clk":"1008080247","pt":1580658192342,"mc":[{"id":"1.168224454","rc":[{"batl":[[0,1.57,217.88],[1,1.58,139.76],[2,1.71,542.06]],"ltp":1.37,"tv":267.69,"id":10894176}]}]}
{"op":"mcm","clk":"1008080944","pt":1580658195378,"mc":[{"id":"1.168224454","rc":[{"batb":[[0,1.52,130.15],[1,1.51,168.63],[2,1.24,97.33]],"batl":[[2,1.71,0]],"ltp":1.37,"tv":267.69,"id":10894176}]}]}
{"op":"mcm","clk":"1008081201","pt":1580658196399,"mc":[{"id":"1.168224454","rc":[{"batb":[[0,1.53,36.35],[1,1.52,130.15],[2,1.51,168.63]],"batl":[[2,1.59,42.01]],"ltp":1.37,"tv":267.69,"id":10894176},{"batb":[[0,2.7,36.56],[1,2.2,21.4],[2,1.01,15.51]],"batl":[[0,3,21]],"ltp":3.7,"tv":94.16,"id":2263634}]}]}
{"op":"mcm","clk":"1008081688","pt":1580658198437,"mc":[{"id":"1.168224454","rc":[{"batl":[[1,3.9,158.24]],"ltp":3.7,"tv":94.16,"id":2263634}]}]}
{"op":"mcm","clk":"1008083720","pt":1580658207202,"mc":[{"id":"1.168224454","rc":[{"batb":[[0,1.25,93.4],[1,1.01,15.51],[2,1.51,0]],"batl":[[0,1.95,409.86],[1,1.58,0],[2,1.59,0]],"ltp":1.37,"tv":267.69,"id":10894176},{"batb":[[0,2.2,21.4],[1,1.01,15.51],[2,1.01,0]],"batl":[[0,3.9,158.24],[1,3.9,0]],"ltp":3.7,"tv":94.16,"id":2263634}]}]}
{"op":"mcm","clk":"1008085209","pt":1580658213257,"mc":[{"id":"1.168224454","rc":[{"batb":[[0,1.45,294.47],[1,1.44,206.85],[2,1.25,93.4]],"batl":[[0,1.5,195.65],[1,1.51,166.2]],"ltp":1.37,"tv":267.69,"id":10894176}]}]}
{"op":"mcm","clk":"1008085539","pt":1580658214576,"mc":[{"id":"1.168224454","rc":[{"batb":[[0,1.25,93.4],[1,1.01,15.51],[2,1.25,0]],"batl":[[0,1.89,435.28],[1,1.51,0]],"ltp":1.37,"tv":267.69,"id":10894176},{"batl":[[0,4.2,148.03]],"ltp":3.7,"tv":94.16,"id":2263634}]}]}
{"op":"mcm","clk":"1008086204","pt":1580658217382,"mc":[{"id":"1.168224454","rc":[{"batb":[[0,1.25,447.05],[1,1.24,447.22],[2,1.01,15.51]],"batl":[[0,1.81,141.36],[1,1.83,170.66],[2,1.89,435.28]],"ltp":1.37,"tv":267.69,"id":10894176}]}]}
{"op":"mcm","clk":"1008086681","pt":1580658219390,"mc":[{"id":"1.168224454","rc":[{"batb":[[2,1.2,114.4]],"batl":[[0,1.28,300.9],[1,1.29,338.49]],"ltp":1.37,"tv":267.69,"id":10894176},{"batb":[[0,4.4,17.62],[1,3.55,14.79],[2,2.2,21.4]],"ltp":3.7,"tv":94.16,"id":2263634}]}]}
{"op":"mcm","clk":"1008086877","pt":1580658220215,"mc":[{"id":"1.168224454","rc":[{"batb":[[0,1.26,161.32],[1,1.25,447.05],[2,1.24,447.22]],"batl":[[2,1.32,42.01]],"ltp":1.37,"tv":267.69,"id":10894176},{"batb":[[1,4.1,13.44],[2,3.55,14.79]],"batl":[[0,4.7,10.92]],"ltp":3.7,"tv":94.16,"id":2263634}]}]}
{"op":"mcm","clk":"1008087153","pt":1580658221265,"mc":[{"id":"1.168224454","rc":[{"batl":[[2,1.3,37.86]],"ltp":1.37,"tv":267.69,"id":10894176}]}]}
{"op":"mcm","clk":"1008087343","pt":1580658222106,"mc":[{"id":"1.168224454","rc":[{"batl":[[2,1.32,42.01]],"ltp":1.37,"tv":267.69,"id":10894176},{"batl":[[1,6.6,98.95]],"ltp":3.7,"tv":94.16,"id":2263634}]}]}
{"op":"mcm","clk":"1008095300","pt":1580658255109,"mc":[{"id":"1.168224454","rc":[{"batl":[[0,6.6,98.95],[1,6.6,0]],"ltp":3.7,"tv":94.16,"id":2263634}]}]}
{"op":"mcm","clk":"1008095549","pt":1580658256231,"mc":[{"id":"1.168224454","rc":[{"batb":[[1,1.25,93.4],[2,1.2,114.4]],"batl":[[0,1.32,42.01],[1,1.62,614.4],[2,1.32,0]],"ltp":1.37,"tv":267.69,"id":10894176}]}]}
{"op":"mcm","clk":"1008096002","pt":1580658258040,"mc":[{"id":"1.168224454","rc":[{"batl":[[0,4.8,10.92],[1,6.6,98.95]],"ltp":3.7,"tv":94.16,"id":2263634}]}]}
{"op":"mcm","clk":"1008096216","pt":1580658258837,"mc":[{"id":"1.168224454","rc":[{"batb":[[2,1.21,501.43]],"batl":[[1,1.37,280.15],[2,1.38,242.43]],"ltp":1.37,"tv":267.69,"id":10894176}]}]}
{"op":"mcm","clk":"1008099341","pt":1580658273263,"mc":[{"id":"1.168224454","rc":[{"batb":[[0,1.21,501.43],[1,1.2,675.17],[2,1.01,15.51]],"batl":[[0,1.37,280.15],[1,1.38,242.43],[2,1.62,614.4]],"ltp":1.37,"tv":267.69,"id":10894176},{"batb":[[0,3.55,14.79],[1,1.01,15.51],[2,3.55,0]],"batl":[[0,6.6,98.95],[1,6.6,0]],"ltp":3.7,"tv":94.16,"id":2263634}]}]}
{"op":"mcm","clk":"1008099994","pt":1580658276148,"mc":[{"id":"1.168224454","rc":[{"batb":[[0,3.6,14.48]],"ltp":3.7,"tv":94.16,"id":2263634}]}]}
{"op":"mcm","clk":"1008101402","pt":1580658282345,"mc":[{"id":"1.168224454","rc":[{"batl":[[0,1.62,614.4],[1,1.38,0],[2,1.62,0]],"ltp":1.37,"tv":267.69,"id":10894176}]}]}
{"op":"mcm","clk":"1008102077","pt":1580658285370,"mc":[{"id":"1.168224454","rc":[{"batl":[[0,1.24,392.3],[1,1.25,402.41],[2,1.62,614.4]],"ltp":1.37,"tv":267.69,"id":10894176}]}]}
{"op":"mcm","clk":"1008102315","pt":1580658286342,"mc":[{"id":"1.168224454","rc":[{"batb":[[0,1.23,168.04],[1,1.21,501.43],[2,1.2,675.17]],"batl":[[2,1.28,42.01]],"ltp":1.37,"tv":267.69,"id":10894176},{"batb":[[0,5.1,12.83],[1,4.6,10.92],[2,4.1,20.46]],"batl":[[0,5.4,9.24]],"ltp":3.7,"tv":94.16,"id":2263634}]}]}
{"op":"mcm","clk":"1008102666","pt":1580658287961,"mc":[{"id":"1.168224454","rc":[{"batl":[[1,7.8,87.91]],"ltp":3.7,"tv":94.16,"id":2263634}]}]}
{"op":"mcm","clk":"1008104320","pt":1580658295371,"mc":[{"id":"1.168224454","rc":[{"batb":[[0,1.17,136.67],[1,1.01,15.51],[2,1.2,0]],"batl":[[0,1.62,614.4],[1,1.25,0],[2,1.28,0]],"ltp":1.37,"tv":267.69,"id":10894176},{"batb":[[0,4.1,20.46],[1,1.01,15.51],[2,4.1,0]],"batl":[[0,7.8,87.91],[1,7.8,0]],"ltp":3.7,"tv":94.16,"id":2263634}]}]}
{"op":"mcm","clk":"1008104928","pt":1580658298277,"mc":[{"id":"1.168224454","rc":[{"batb":[[0,1.18,755.9],[1,1.17,474.55],[2,1.01,15.51]],"batl":[[0,1.3,246.8],[1,1.31,312.98],[2,1.62,614.4]],"ltp":1.37,"tv":267.69,"id":10894176}]}]}
{"op":"mcm","clk":"1008105126","pt":1580658299095,"mc":[{"id":"1.168224454","rc":[{"batl":[[0,1.62,614.4],[1,1.31,0],[2,1.62,0]],"ltp":1.37,"tv":267.69,"id":10894176}]}]}
{"op":"mcm","clk":"1008105908","pt":1580658302411,"mc":[{"id":"1.168224454","rc":[{"batl":[[0,1.21,400.94],[1,1.22,467.67]],"ltp":1.37,"tv":267.69,"id":10894176}]}]}
{"op":"mcm","clk":"1008106042","pt":1580658302956,"mc":[{"id":"1.168224454","rc":[{"batb":[[2,1.16,153.51]],"ltp":1.37,"tv":267.69,"id":10894176},{"batb":[[0,5.6,20.22],[1,4.8,14.4],[2,1.01,15.51]],"ltp":3.7,"tv":94.16,"id":2263634}]}]}
{"op":"mcm","clk":"1008106386","pt":1580658304432,"mc":[{"id":"1.168224454","rc":[{"batb":[[0,1.2,168.04],[1,1.18,755.9],[2,1.17,474.55]],"batl":[[2,1.25,42.01]],"ltp":1.37,"tv":267.69,"id":10894176},{"batb":[[1,5,10.08],[2,4.8,14.4]],"batl":[[0,6,8.4]],"ltp":3.7,"tv":94.16,"id":2263634}]}]}
{"op":"mcm","clk":"1008106634","pt":1580658305307,"mc":[{"id":"1.168224454","rc":[{"batl":[[1,9.8,75.27]],"ltp":3.7,"tv":94.16,"id":2263634}]}]}
{"op":"mcm","clk":"1008108902","pt":1580658315340,"mc":[{"id":"1.168224454","rc":[{"batb":[[0,1.17,337.88],[1,1.16,153.51],[2,1.01,15.51]],"batl":[[0,1.49,761.67],[1,1.22,0],[2,1.25,0]],"ltp":1.37,"tv":267.69,"id":10894176},{"batb":[[0,4.8,14.4],[1,1.01,15.51],[2,4.8,0]],"batl":[[0,9.8,75.27],[1,9.8,0]],"ltp":3.7,"tv":94.16,"id":2263634}]}]}
{"op":"mcm","clk":"1008109471","pt":1580658318106,"mc":[{"id":"1.168224454","rc":[{"batb":[[1,1.16,874.88]],"batl":[[0,1.25,436.38],[1,1.26,383.02],[2,1.49,761.67]],"ltp":1.37,"tv":267.69,"id":10894176}]}]}
{"op":"mcm","clk":"1008109649","pt":1580658318875,"mc":[{"id":"1.168224454","rc":[{"batl":[[0,1.49,761.67],[1,1.26,0],[2,1.49,0]],"ltp":1.37,"tv":267.69,"id":10894176}]}]}
{"op":"mcm","clk":"1008110355","pt":1580658322167,"mc":[{"id":"1.168224454","rc":[{"batb":[[0,1.18,168.04],[1,1.17,337.88],[2,1.16,874.88]],"batl":[[0,1.19,319.65],[1,1.2,525.3],[2,1.49,761.67]],"ltp":1.37,"tv":267.69,"id":10894176},{"batb":[[0,5.4,9.24],[1,4.8,14.4],[2,1.01,15.51]],"batl":[[0,6.4,7.56],[1,9.8,75.27]],"ltp":3.7,"tv":94.16,"id":2263634}]}]}
{"op":"mcm","clk":"1008110575","pt":1580658323059,"mc":[{"id":"1.168224454","rc":[{"batb":[[0,6,16.84],[1,5.5,10.54],[2,5.4,9.24]],"ltp":3.7,"tv":94.16,"id":2263634}]}]}
{"op":"mcm","clk":"1008111694","pt":1580658328269,"mc":[{"id":"1.168224454","rc":[{"batl":[[2,1.22,42.01]],"ltp":1.37,"tv":267.69,"id":10894176}]}]}
{"op":"mcm","clk":"1008113507","pt":1580658336394,"mc":[{"id":"1.168224454","rc":[{"batb":[[1,1.16,614.82],[2,1.14,167.99]],"batl":[[0,1.22,42.01],[1,1.49,761.67],[2,1.22,0]],"ltp":1.37,"tv":267.69,"id":10894176}]}]}
{"op":"mcm","clk":"1008113660","pt":1580658337264,"mc":[{"id":"1.168224454","rc":[{"batb":[[0,1.16,461.31],[1,1.14,167.99],[2,1.01,15.51]],"batl":[[0,1.49,761.67],[1,1.49,0]],"ltp":1.37,"tv":267.69,"id":10894176},{"batb":[[0,5.5,10.54],[1,1.01,15.51],[2,5.4,0]],"batl":[[0,9.8,75.27],[1,9.8,0]],"ltp":3.7,"tv":94.16,"id":2263634}]}]}
{"op":"mcm","clk":"1008114057","pt":1580658339380,"mc":[{"id":"1.168224454","rc":[{"batb":[[1,1.15,654.06],[2,1.14,167.99]],"batl":[[0,1.21,316.48],[1,1.22,470.27],[2,1.49,761.67]],"ltp":1.37,"tv":267.69,"id":10894176}]}]}
{"op":"mcm","clk":"1008115392","pt":1580658345969,"mc":[{"id":"1.168224454","rc":[{"batl":[[0,1.49,761.67],[1,1.22,0],[2,1.49,0]],"ltp":1.37,"tv":267.69,"id":10894176}]}]}
{"op":"mcm","clk":"1008116059","pt":1580658349391,"mc":[{"id":"1.168224454","rc":[{"batl":[[0,1.18,302.68],[1,1.19,557.95],[2,1.49,761.67]],"ltp":1.37,"tv":267.69,"id":10894176},{"batb":[[0,6.4,14.56],[1,5.9,17.94],[2,5.5,10.54]],"ltp":3.7,"tv":94.16,"id":2263634}]}]}
{"op":"mcm","clk":"1008116215","pt":1580658350194,"mc":[{"id":"1.168224454","rc":[{"batb":[[0,1.17,168.04],[1,1.16,461.31],[2,1.15,654.06]],"batl":[[2,1.21,42.01]],"ltp":1.37,"tv":267.69,"id":10894176},{"batb":[[2,5.7,8.4]],"batl":[[0,7,6.72]],"ltp":3.7,"tv":94.16,"id":2263634}]}]}
{"op":"mcm","clk":"1008116477","pt":1580658351487,"mc":[{"id":"1.168224454","rc":[{"batl":[[1,11.5,70.11]],"ltp":3.7,"tv":94.16,"id":2263634}]}]}
{"op":"mcm","clk":"1008119940","pt":1580658367910,"mc":[{"id":"1.168224454","rc":[{"batb":[[1,1.11,213.94],[2,1.01,15.51]],"batl":[[0,1.21,42.01],[1,1.49,761.67],[2,1.21,0]],"ltp":1.37,"tv":267.69,"id":10894176},{"batb":[[0,5.9,17.94],[1,5.7,8.4],[2,1.01,15.51]],"ltp":3.7,"tv":94.16,"id":2263634}]}]}
{"op":"mcm","clk":"1008120252","pt":1580658369414,"mc":[{"id":"1.168224454","rc":[{"batb":[[0,1.11,213.94],[1,1.01,15.51],[2,1.01,0]],"batl":[[0,1.49,761.67],[1,1.49,0]],"ltp":1.37,"tv":267.69,"id":10894176},{"batb":[[1,1.01,15.51],[2,1.01,0]],"batl":[[0,11.5,70.11],[1,11.5,0]],"ltp":3.7,"tv":94.16,"id":2263634}]}]}
{"op":"mcm","clk":"1008120460","pt":1580658370394,"mc":[{"id":"1.168224454","rc":[{"batb":[[0,1.13,299.87],[1,1.12,846.82],[2,1.11,213.94]],"batl":[[0,1.21,613.83],[1,1.22,446.35],[2,1.49,761.67]],"ltp":1.37,"tv":267.69,"id":10894176}]}]}
{"op":"mcm","clk":"1008120653","pt":1580658371305,"mc":[{"id":"1.168224454","rc":[{"batb":[[0,1.11,213.94],[1,1.01,15.51],[2,1.11,0]],"batl":[[0,1.49,761.67],[1,1.22,0],[2,1.49,0]],"ltp":1.37,"tv":267.69,"id":10894176}]}]}
{"op":"mcm","clk":"1008121172","pt":1580658373429,"mc":[{"id":"1.168224454","rc":[{"batb":[[0,1.15,733.34],[1,1.14,389.42],[2,1.11,213.94]],"batl":[[0,1.18,743.05],[1,1.19,344.95],[2,1.49,761.67]],"ltp":1.37,"tv":267.69,"id":10894176}]}]}
{"op":"mcm","clk":"1008121495","pt":1580658375107,"mc":[{"id":"1.168224454","rc":[{"batb":[[0,1.11,213.94],[1,1.01,15.51],[2,1.11,0]],"batl":[[0,1.49,761.67],[1,1.19,0],[2,1.49,0]],"ltp":1.37,"tv":267.69,"id":10894176}]}]}
{"op":"mcm","clk":"1008122762","pt":1580658381112,"mc":[{"id":"1.168224454","rc":[{"batb":[[0,1.18,514.16],[1,1.17,581.69],[2,1.11,213.94]],"batl":[[0,1.21,613.83],[1,1.22,446.35],[2,1.49,761.67]],"ltp":1.37,"tv":267.69,"id":10894176}]}]}
{"op":"mcm","clk":"1008122957","pt":1580658382132,"mc":[{"id":"1.168224454","rc":[{"batb":[[0,1.19,168.04],[1,1.18,514.16],[2,1.17,581.69]],"batl":[[2,1.23,42.01]],"ltp":1.37,"tv":267.69,"id":10894176},{"batb":[[1,5.5,10.46],[2,5.4,9.24]],"batl":[[0,6.4,7.56]],"ltp":3.7,"tv":94.16,"id":2263634}]}]}
{"op":"mcm","clk":"1008123312","pt":1580658383825,"mc":[{"id":"1.168224454","rc":[{"batl":[[1,9.8,75.27]],"ltp":3.7,"tv":94.16,"id":2263634}]}]}
{"op":"mcm","clk":"1008126128","pt":1580658397934,"mc":[{"id":"1.168224454","rc":[{"batb":[[1,1.14,176.09],[2,1.01,15.51]],"batl":[[0,1.23,42.01],[1,1.49,761.67],[2,1.23,0]],"ltp":1.37,"tv":267.69,"id":10894176},{"batb":[[0,5.5,10.46],[1,5.4,9.24],[2,1.01,15.51]],"ltp":3.7,"tv":94.16,"id":2263634}]}]}
{"op":"mcm","clk":"1008126390","pt":1580658399156,"mc":[{"id":"1.168224454","rc":[{"batb":[[0,1.14,176.09],[1,1.01,15.51],[2,1.01,0]],"batl":[[0,1.49,761.67],[1,1.49,0]],"ltp":1.37,"tv":267.69,"id":10894176},{"batb":[[1,1.01,15.51],[2,1.01,0]],"batl":[[0,9.8,75.27],[1,9.8,0]],"ltp":3.7,"tv":94.16,"id":2263634}]}]}
{"op":"mcm","clk":"1008126777","pt":1580658401145,"mc":[{"id":"1.168224454","rc":[{"batb":[[0,1.15,744.4],[1,1.14,554.35],[2,1.01,15.51]],"batl":[[0,1.23,584.93],[1,1.24,417.36],[2,1.49,761.67]],"ltp":1.37,"tv":267.69,"id":10894176}]}]}
{"op":"mcm","clk":"1008126830","pt":1580658401948,"mc":[{"id":"1.168224454","rc":[{"batb":[[0,1.14,176.09],[1,1.01,15.51],[2,1.01,0]],"batl":[[0,1.49,761.67],[1,1.24,0],[2,1.49,0]],"ltp":1.37,"tv":267.69,"id":10894176}]}]}
{"op":"mcm","clk":"1008127475","pt":1580658404348,"mc":[{"id":"1.168224454","rc":[{"batb":[[0,1.2,364.46],[1,1.19,591.21],[2,1.14,176.09]],"batl":[[0,1.23,584.93],[1,1.24,417.36],[2,1.49,761.67]],"ltp":1.37,"tv":267.69,"id":10894176}]}]}
{"op":"mcm","clk":"1008127724","pt":1580658405428,"mc":[{"id":"1.168224454","rc":[{"batb":[[2,1.18,132.26]],"ltp":1.37,"tv":267.69,"id":10894176},{"batb":[[1,5.3,11.64],[2,1.01,15.51]],"ltp":3.7,"tv":94.16,"id":2263634}]}]}
{"op":"mcm","clk":"1008127852","pt":1580658406165,"mc":[{"id":"1.168224454","rc":[{"batb":[[0,1.2,532.5]],"batl":[[2,1.25,42.01]],"ltp":1.37,"tv":267.69,"id":10894176},{"batb":[[2,5,10.08]],"batl":[[0,5.9,8.4]],"ltp":3.7,"tv":94.16,"id":2263634}]}]}
{"op":"mcm","clk":"1008128105","pt":1580658407358,"mc":[{"id":"1.168224454","rc":[{"batl":[[1,8.6,81.89]],"ltp":3.7,"tv":94.16,"id":2263634}]}]}
{"op":"mcm","clk":"1008130146","pt":1580658418091,"mc":[{"id":"1.168224454","rc":[{"batb":[[0,1.2,168.04],[1,1.16,150.28],[2,1.01,15.51]],"batl":[[0,1.24,388.14],[1,1.25,42.01],[2,1.49,761.67]],"ltp":1.37,"tv":267.69,"id":10894176},{"batb":[[0,5.3,11.64],[1,5,10.08],[2,1.01,15.51]],"ltp":3.7,"tv":94.16,"id":2263634}]}]}
{"op":"mcm","clk":"1008130371","pt":1580658419170,"mc":[{"id":"1.168224454","rc":[{"batb":[[0,1.16,150.28],[1,1.01,15.51],[2,1.01,0]],"batl":[[0,1.49,761.67],[1,1.25,0],[2,1.49,0]],"ltp":1.37,"tv":267.69,"id":10894176},{"batb":[[1,1.01,15.51],[2,1.01,0]],"batl":[[0,8.6,81.89],[1,8.6,0]],"ltp":3.7,"tv":94.16,"id":2263634}]}]}
{"op":"mcm","clk":"1008130732","pt":1580658420993,"mc":[{"id":"1.168224454","rc":[{"batb":[[0,1.18,348.67],[1,1.16,150.28],[2,1.01,15.51]],"ltp":1.37,"tv":267.69,"id":10894176}]}]}
{"op":"mcm","clk":"1008131052","pt":1580658422374,"mc":[{"id":"1.168224454","rc":[{"batb":[[0,1.19,736.01],[1,1.18,348.67],[2,1.16,150.28]],"batl":[[0,1.22,330.85],[1,1.23,445.55],[2,1.49,761.67]],"ltp":1.37,"tv":267.69,"id":10894176}]}]}
{"op":"mcm","clk":"1008131826","pt":1580658425898,"mc":[{"id":"1.168224454","rc":[{"batb":[[0,1.18,348.67],[1,1.16,150.28],[2,1.01,15.51]],"batl":[[0,1.49,761.67],[1,1.23,0],[2,1.49,0]],"ltp":1.37,"tv":267.69,"id":10894176}]}]}
{"op":"mcm","clk":"1008132556","pt":1580658429394,"mc":[{"id":"1.168224454","rc":[{"batb":[[0,1.18,391.81],[1,1.17,673.4],[2,1.16,150.28]],"batl":[[0,1.24,386.25],[1,1.25,402.27],[2,1.49,761.67]],"ltp":1.37,"tv":267.69,"id":10894176}]}]}
{"op":"mcm","clk":"1008132641","pt":1580658429780,"mc":[{"id":"1.168224454","rc":[{"batl":[[0,1.49,761.67],[1,1.25,0],[2,1.49,0]],"ltp":1.37,"tv":267.69,"id":10894176}]}]}
{"op":"mcm","clk":"1008133357","pt":1580658433377,"mc":[{"id":"1.168224454","rc":[{"batl":[[0,1.2,222.42],[1,1.21,499.02],[2,1.49,761.67]],"ltp":1.37,"tv":267.69,"id":10894176},{"batb":[[0,6,17.39],[1,5.5,10.39],[2,1.01,15.51]],"ltp":3.7,"tv":94.16,"id":2263634}]}]}
{"op":"mcm","clk":"1008133504","pt":1580658434172,"mc":[{"id":"1.168224454","rc":[{"batl":[[2,1.23,42.01]],"ltp":1.37,"tv":267.69,"id":10894176},{"batb":[[2,5.3,9.24]],"batl":[[0,6.4,7.56]],"ltp":3.7,"tv":94.16,"id":2263634}]}]}
{"op":"mcm","clk":"1008133953","pt":1580658436402,"mc":[{"id":"1.168224454","rc":[{"batl":[[1,9.8,75.27]],"ltp":3.7,"tv":94.16,"id":2263634}]}]}
{"op":"mcm","clk":"1008135384","pt":1580658443433,"mc":[{"id":"1.168224454","rc":[{"batb":[[0,1.16,150.28],[1,1.13,188.52],[2,1.01,15.51]],"batl":[[0,1.23,42.01],[1,1.49,761.67],[2,1.23,0]],"ltp":1.37,"tv":267.69,"id":10894176}]}]}
{"op":"mcm","clk":"1008135428","pt":1580658443645,"mc":[{"id":"1.168224454","rc":[{"batb":[[0,1.13,187.97],[1,1.01,15.51],[2,1.01,0]],"ltp":1.37,"tv":267.69,"id":10894176},{"batb":[[0,5.5,10.39],[1,5.3,9.24],[2,1.01,15.51]],"ltp":3.7,"tv":94.16,"id":2263634}]}]}
{"op":"mcm","clk":"1008135730","pt":1580658445248,"mc":[{"id":"1.168224454","rc":[{"batl":[[0,1.49,761.67],[1,1.49,0]],"ltp":1.37,"tv":267.69,"id":10894176},{"batb":[[1,1.01,15.51],[2,1.01,0]],"batl":[[0,9.8,75.27],[1,9.8,0]],"ltp":3.7,"tv":94.16,"id":2263634}]}]}
{"op":"mcm","clk":"1008136341","pt":1580658448131,"mc":[{"id":"1.168224454","rc":[{"batb":[[0,1.17,640.54],[1,1.16,463.67],[2,1.13,187.97]],"batl":[[0,1.2,595.07],[1,1.21,473.72],[2,1.49,761.67]],"ltp":1.37,"tv":267.69,"id":10894176}]}]}
{"op":"mcm","clk":"1008136893","pt":1580658450530,"mc":[{"id":"1.168224454","rc":[{"batb":[[0,1.13,187.97],[1,1.01,15.51],[2,1.13,0]],"batl":[[0,1.49,761.67],[1,1.21,0],[2,1.49,0]],"ltp":1.37,"tv":267.69,"id":10894176}]}]}
{"op":"mcm","clk":"1008137520","pt":1580658453509,"mc":[{"id":"1.168224454","rc":[{"batb":[[0,1.15,259.46],[1,1.14,833.69],[2,1.13,187.97]],"batl":[[0,1.23,509.67],[1,1.24,418.6],[2,1.49,761.67]],"ltp":1.37,"tv":267.69,"id":10894176}]}]}
{"op":"mcm","clk":"1008137814","pt":1580658454947,"mc":[{"id":"1.168224454","rc":[{"batb":[[0,1.13,187.97],[1,1.01,15.51],[2,1.13,0]],"ltp":1.37,"tv":267.69,"id":10894176}]}]}
{"op":"mcm","clk":"1008138529","pt":1580658458369,"mc":[{"id":"1.168224454","rc":[{"batb":[[0,1.2,446.17],[1,1.19,593.01],[2,1.13,187.97]],"ltp":1.37,"tv":267.69,"id":10894176}]}]}
{"op":"mcm","clk":"1008138638","pt":1580658458751,"mc":[{"id":"1.168224454","rc":[{"batb":[[2,1.18,134.15]],"ltp":1.37,"tv":267.69,"id":10894176},{"batb":[[1,5.3,11.41],[2,1.01,15.51]],"ltp":3.7,"tv":94.16,"id":2263634}]}]}
{"op":"mcm","clk":"1008138905","pt":1580658460134,"mc":[{"id":"1.168224454","rc":[{"batl":[[2,1.25,42.01]],"ltp":1.37,"tv":267.69,"id":10894176},{"batb":[[2,5,10.08]],"ltp":3.7,"tv":94.16,"id":2263634}]}]}
{"op":"mcm","clk":"1008139288","pt":1580658461850,"mc":[{"id":"1.168224454","rc":[{"batl":[[0,8.6,81.89]],"ltp":3.7,"tv":94.16,"id":2263634}]}]}
{"op":"mcm","clk":"1008140724","pt":1580658469230,"mc":[{"id":"1.168224454","rc":[{"batb":[[0,1.16,150.05],[1,1.01,15.51],[2,1.18,0]],"batl":[[0,1.49,761.67],[1,1.24,0],[2,1.25,0]],"ltp":1.37,"tv":267.69,"id":10894176},{"batb":[[0,5.3,11.41],[1,1.01,15.51],[2,5,0]],"ltp":3.7,"tv":94.16,"id":2263634}]}]}
{"op":"mcm","clk":"1008141197","pt":1580658471537,"mc":[{"id":"1.168224454","rc":[{"batb":[[0,1.18,537.02],[1,1.17,558.63],[2,1.16,150.05]],"batl":[[0,1.24,354.1],[1,1.25,402.76],[2,1.49,761.67]],"ltp":1.37,"tv":267.69,"id":10894176}]}]}
{"op":"mcm","clk":"1008141849","pt":1580658474789,"mc":[{"id":"1.168224454","rc":[{"batb":[[0,1.16,150.05],[1,1.01,15.51],[2,1.16,0]],"ltp":1.37,"tv":267.69,"id":10894176}]}]}
{"op":"mcm","clk":"1008142370","pt":1580658477351,"mc":[{"id":"1.168224454","rc":[{"batb":[[0,1.21,541.9],[1,1.2,526.32],[2,1.16,150.05]],"ltp":1.37,"tv":267.69,"id":10894176}]}]}
{"op":"mcm","clk":"1008142525","pt":1580658478148,"mc":[{"id":"1.168224454","rc":[{"batb":[[0,1.22,168.04],[1,1.21,541.9],[2,1.2,526.32]],"batl":[[2,1.27,42.01]],"ltp":1.37,"tv":267.69,"id":10894176},{"batb":[[1,4.7,10.92],[2,4.1,21.4]],"batl":[[0,5.6,8.4],[1,8.6,81.89]],"ltp":3.7,"tv":94.16,"id":2263634}]}]}
{"op":"mcm","clk":"1008158344","pt":1580658560366,"mc":[{"id":"1.168224454","rc":[{"batb":[[1,1.15,156.1],[2,1.01,15.51]],"batl":[[0,1.27,42.01],[1,1.49,761.67],[2,1.27,0]],"ltp":1.37,"tv":267.69,"id":10894176},{"batb":[[0,4.7,10.92],[1,4.1,21.4],[2,1.01,15.51]],"ltp":3.7,"tv":94.16,"id":2263634}]}]}
{"op":"mcm","clk":"1008158507","pt":1580658561270,"mc":[{"id":"1.168224454","rc":[{"batb":[[0,1.15,156.1],[1,1.01,15.51],[2,1.01,0]],"batl":[[0,1.49,761.67],[1,1.49,0]],"ltp":1.37,"tv":267.69,"id":10894176},{"batb":[[0,4.1,21.4],[1,1.01,15.51],[2,1.01,0]],"batl":[[0,8.6,81.89],[1,8.6,0]],"ltp":3.7,"tv":94.16,"id":2263634}]}]}
{"op":"mcm","clk":"1008158872","pt":1580658563266,"mc":[{"id":"1.168224454","rc":[{"batb":[[0,1.18,209.77],[1,1.17,666.06],[2,1.15,156.1]],"batl":[[0,1.33,325.61],[1,1.34,277.45],[2,1.49,761.67]],"ltp":1.37,"tv":267.69,"id":10894176}]}]}
{"op":"mcm","clk":"1008160741","pt":1580658573406,"mc":[{"id":"1.168224454","rc":[{"batl":[[0,1.49,761.67],[1,1.34,0],[2,1.49,0]],"ltp":1.37,"tv":267.69,"id":10894176}]}]}
{"op":"mcm","clk":"1008161285","pt":1580658576390,"mc":[{"id":"1.168224454","rc":[{"batb":[[0,1.18,377.81]],"batl":[[0,1.2,388.96],[1,1.21,493.62],[2,1.23,42.01]],"ltp":1.37,"tv":267.69,"id":10894176},{"batb":[[0,5.4,9.24],[1,4.5,485.68],[2,4.1,21.4]],"batl":[[0,6.4,7.56]],"ltp":3.7,"tv":94.16,"id":2263634}]}]}
{"op":"mcm","clk":"1008161371","pt":1580658576909,"mc":[{"id":"1.168224454","rc":[{"batb":[[0,6.2,16.37],[1,5.4,9.24],[2,4.9,13.93]],"ltp":3.7,"tv":94.16,"id":2263634}]}]}
{"op":"mcm","clk":"1008161763","pt":1580658578994,"mc":[{"id":"1.168224454","rc":[{"batl":[[1,9.8,75.27]],"ltp":3.7,"tv":94.16,"id":2263634}]}]}
{"op":"mcm","clk":"1008164449","pt":1580658594315,"mc":[{"id":"1.168224454","rc":[{"batb":[[0,1.18,168.04],[1,1.13,187.42],[2,1.01,15.51]],"batl":[[0,1.23,42.01],[1,1.49,761.67],[2,1.23,0]],"ltp":1.37,"tv":267.69,"id":10894176},{"batb":[[0,5.4,9.24],[1,4.9,13.93],[2,1.01,15.51]],"ltp":3.7,"tv":94.16,"id":2263634}]}]}
{"op":"mcm","clk":"1008164609","pt":1580658595334,"mc":[{"id":"1.168224454","rc":[{"batb":[[0,1.13,187.42],[1,1.01,15.51],[2,1.01,0]],"batl":[[0,1.49,761.67],[1,1.49,0]],"ltp":1.37,"tv":267.69,"id":10894176},{"batb":[[0,4.9,13.93],[1,1.01,15.51],[2,1.01,0]],"batl":[[0,9.8,75.27],[1,9.8,0]],"ltp":3.7,"tv":94.16,"id":2263634}]}]}
{"op":"mcm","clk":"1008164861","pt":1580658596790,"mc":[{"id":"1.168224454","rc":[{"batb":[[0,1.15,570.58],[1,1.14,553.61],[2,1.13,187.42]],"batl":[[0,1.26,279.9],[1,1.27,368.92],[2,1.49,761.67]],"ltp":1.37,"tv":267.69,"id":10894176}]}]}
{"op":"mcm","clk":"1008165417","pt":1580658600124,"mc":[{"id":"1.168224454","rc":[{"batb":[[0,1.13,187.42],[1,1.01,15.51],[2,1.13,0]],"ltp":1.37,"tv":267.69,"id":10894176}]}]}
{"op":"mcm","clk":"1008166014","pt":1580658603223,"mc":[{"id":"1.168224454","rc":[{"batb":[[0,1.23,487.83],[1,1.22,499.51],[2,1.13,187.42]],"ltp":1.37,"tv":267.69,"id":10894176}]}]}
{"op":"mcm","clk":"1008166181","pt":1580658604211,"mc":[{"id":"1.168224454","rc":[{"batb":[[0,1.23,655.87],[2,1.21,109.68]],"batl":[[2,1.28,42.01]],"ltp":1.37,"tv":267.69,"id":10894176},{"batb":[[1,4.6,10.92],[2,3.65,14.24]],"batl":[[0,5.4,9.24]],"ltp":3.7,"tv":94.16,"id":2263634}]}]}
{"op":"mcm","clk":"1008166545","pt":1580658606221,"mc":[{"id":"1.168224454","rc":[{"batl":[[1,7.8,87.91]],"ltp":3.7,"tv":94.16,"id":2263634}]}]}
{"op":"mcm","clk":"1008169677","pt":1580658624338,"mc":[{"id":"1.168224454","rc":[{"batb":[[0,1.23,168.04],[1,1.21,109.68],[2,1.17,143.91]],"batl":[[0,1.28,42.01],[1,1.49,761.67],[2,1.28,0]],"ltp":1.37,"tv":267.69,"id":10894176}]}]}
{"op":"mcm","clk":"1008169837","pt":1580658625245,"mc":[{"id":"1.168224454","rc":[{"batb":[[0,1.17,143.91],[1,1.01,15.51],[2,1.17,0]],"batl":[[0,1.49,761.67],[1,1.49,0]],"ltp":1.37,"tv":267.69,"id":10894176},{"batb":[[0,3.65,14.24],[1,1.01,15.51],[2,3.65,0]],"batl":[[0,7.8,87.91],[1,7.8,0]],"ltp":3.7,"tv":94.16,"id":2263634}]}]}
{"op":"mcm","clk":"1008170145","pt":1580658627140,"mc":[{"id":"1.168224454","rc":[{"batb":[[0,1.18,665.88],[1,1.17,572.58],[2,1.01,15.51]],"batl":[[0,1.38,227.78],[1,1.39,234.67],[2,1.49,761.67]],"ltp":1.37,"tv":267.69,"id":10894176}]}]}
{"op":"mcm","clk":"1008170297","pt":1580658627964,"mc":[{"id":"1.168224454","rc":[{"batb":[[1,1.17,428.67],[2,1.16,145.25]],"batl":[[0,1.49,761.67],[1,1.39,0],[2,1.49,0]],"ltp":1.37,"tv":267.69,"id":10894176},{"batb":[[0,3.65,14.08]],"ltp":3.7,"tv":94.16,"id":2263634}]}]}
{"op":"mcm","clk":"1008170648","pt":1580658630246,"mc":[{"id":"1.168224454","rc":[{"batb":[[0,1.18,618.23]],"ltp":1.37,"tv":267.69,"id":10894176}]}]}
{"op":"mcm","clk":"1008170772","pt":1580658631030,"mc":[{"id":"1.168224454","rc":[{"batl":[[0,1.21,478.64],[1,1.22,464.87],[2,1.49,761.67]],"ltp":1.37,"tv":267.69,"id":10894176}]}]}
{"op":"mcm","clk":"1008171016","pt":1580658632255,"mc":[{"id":"1.168224454","rc":[{"batl":[[2,1.23,42.01]],"ltp":1.37,"tv":267.69,"id":10894176},{"batb":[[0,5.8,18.41],[1,5.3,9.24],[2,4.5,16.84]],"batl":[[0,6.4,7.56]],"ltp":3.7,"tv":94.16,"id":2263634}]}]}
{"op":"mcm","clk":"1008171104","pt":1580658632750,"mc":[{"id":"1.168224454","rc":[{"batb":[[1,1.17,476.73]],"batl":[[0,1.21,525.1]],"ltp":1.37,"tv":267.69,"id":10894176}]}]}
{"op":"mcm","clk":"1008171415","pt":1580658634368,"mc":[{"id":"1.168224454","rc":[{"batl":[[1,9.8,75.27]],"ltp":3.7,"tv":94.16,"id":2263634}]}]}
{"op":"mcm","clk":"1008173116","pt":1580658643366,"mc":[{"id":"1.168224454","rc":[{"batb":[[0,1.16,145.25],[1,1.13,181.99],[2,1.01,15.51]],"batl":[[0,1.23,42.01],[1,1.49,761.67],[2,1.23,0]],"ltp":1.37,"tv":267.69,"id":10894176}]}]}
{"op":"mcm","clk":"1008173321","pt":1580658644379,"mc":[{"id":"1.168224454","rc":[{"batb":[[0,1.13,181.99],[1,1.01,15.51],[2,1.01,0]],"ltp":1.37,"tv":267.69,"id":10894176},{"batb":[[0,5.3,9.24],[1,4.5,16.84],[2,1.01,15.51]],"ltp":3.7,"tv":94.16,"id":2263634}]}]}
{"op":"mcm","clk":"1008173469","pt":1580658645260,"mc":[{"id":"1.168224454","rc":[{"batl":[[0,1.49,761.67],[1,1.49,0]],"ltp":1.37,"tv":267.69,"id":10894176},{"batb":[[0,4.5,16.84],[1,1.01,15.51],[2,1.01,0]],"batl":[[0,9.8,75.27],[1,9.8,0]],"ltp":3.7,"tv":94.16,"id":2263634}]}]}
{"op":"mcm","clk":"1008173654","pt":1580658646288,"mc":[{"id":"1.168224454","rc":[{"batb":[[0,1.15,567.81],[1,1.14,556.41],[2,1.13,181.99]],"batl":[[0,1.28,179.63],[1,1.29,341.25],[2,1.49,761.67]],"ltp":1.37,"tv":267.69,"id":10894176}]}]}
{"op":"mcm","clk":"1008174006","pt":1580658648080,"mc":[{"id":"1.168224454","rc":[{"batb":[[0,1.13,181.99],[1,1.01,15.51],[2,1.13,0]],"ltp":1.37,"tv":267.69,"id":10894176}]}]}
{"op":"mcm","clk":"1008174546","pt":1580658651176,"mc":[{"id":"1.168224454","rc":[{"batb":[[0,1.25,487.57],[1,1.24,450.9],[2,1.13,181.99]],"ltp":1.37,"tv":267.69,"id":10894176}]}]}
{"op":"mcm","clk":"1008174743","pt":1580658652278,"mc":[{"id":"1.168224454","rc":[{"batb":[[1,1.24,715.48],[2,1.17,142.26]],"batl":[[1,1.29,383.26]],"ltp":1.37,"tv":267.69,"id":10894176},{"batb":[[1,4.4,11.76],[2,3.1,20.93]],"batl":[[0,5.2,9.24]],"ltp":3.7,"tv":94.16,"id":2263634}]}]}
{"op":"mcm","clk":"1008175035","pt":1580658654172,"mc":[{"id":"1.168224454","rc":[{"batl":[[0,5.1,10.08],[1,7.2,92.18]],"ltp":3.7,"tv":94.16,"id":2263634}]}]}
{"op":"mcm","clk":"1008177854","pt":1580658671386,"mc":[{"id":"1.168224454","rc":[{"batb":[[0,1.24,264.58],[1,1.17,142.26],[2,1.01,15.51]],"batl":[[0,1.29,42.01],[1,1.49,761.67],[2,1.49,0]],"ltp":1.37,"tv":267.69,"id":10894176}]}]}
{"op":"mcm","clk":"1008177885","pt":1580658671591,"mc":[{"id":"1.168224454","rc":[{"batb":[[0,1.24,168.04]],"ltp":1.37,"tv":267.69,"id":10894176},{"batb":[[0,4.4,11.76],[1,3.1,20.77],[2,1.01,15.51]],"ltp":3.7,"tv":94.16,"id":2263634}]}]}
{"op":"mcm","clk":"1008178158","pt":1580658673287,"mc":[{"id":"1.168224454","rc":[{"batb":[[0,1.17,142.26],[1,1.01,15.51],[2,1.01,0]],"batl":[[0,1.49,761.67],[1,1.49,0]],"ltp":1.37,"tv":267.69,"id":10894176},{"batb":[[0,3.1,20.77],[1,1.01,15.51],[2,1.01,0]],"batl":[[0,7.2,92.18],[1,7.2,0]],"ltp":3.7,"tv":94.16,"id":2263634}]}]}
{"op":"mcm","clk":"1008178351","pt":1580658674335,"mc":[{"id":"1.168224454","rc":[{"batb":[[0,1.18,560.82],[1,1.17,676.89],[2,1.01,15.51]],"batl":[[0,1.47,303.26],[1,1.48,179.3],[2,1.49,761.67]],"ltp":1.37,"tv":267.69,"id":10894176}]}]}
{"op":"mcm","clk":"1008178607","pt":1580658675732,"mc":[{"id":"1.168224454","rc":[{"batl":[[0,1.49,761.67],[1,1.48,0],[2,1.49,0]],"ltp":1.37,"tv":267.69,"id":10894176}]}]}
{"op":"mcm","clk":"1008179246","pt":1580658679320,"mc":[{"id":"1.168224454","rc":[{"batb":[[2,1.13,184.67]],"batl":[[0,1.21,576.4],[1,1.22,463.61],[2,1.49,761.67]],"ltp":1.37,"tv":267.69,"id":10894176},{"batb":[[0,5.8,18.8],[1,4.3,18.65],[2,3.1,20.77]],"ltp":3.7,"tv":94.16,"id":2263634}]}]}
{"op":"mcm","clk":"1008179391","pt":1580658680334,"mc":[{"id":"1.168224454","rc":[{"batb":[[0,1.18,728.86]],"batl":[[1,1.22,505.62]],"ltp":1.37,"tv":267.69,"id":10894176},{"batb":[[1,5.4,9.24],[2,4.3,18.65]],"batl":[[0,6.6,6.72]],"ltp":3.7,"tv":94.16,"id":2263634}]}]}
{"op":"mcm","clk":"1008179637","pt":1580658681832,"mc":[{"id":"1.168224454","rc":[{"batl":[[1,9.8,75.27]],"ltp":3.7,"tv":94.16,"id":2263634}]}]}
{"op":"mcm","clk":"1008181038","pt":1580658690438,"mc":[{"id":"1.168224454","rc":[{"batb":[[0,1.18,168.04],[1,1.17,142.26]],"batl":[[0,1.22,42.01],[1,1.49,761.67],[2,1.49,0]],"ltp":1.37,"tv":267.69,"id":10894176}]}]}
{"op":"mcm","clk":"1008181155","pt":1580658691342,"mc":[{"id":"1.168224454","rc":[{"batb":[[0,1.13,184.67],[1,1.01,15.51],[2,1.13,0]],"batl":[[0,1.49,761.67],[1,1.49,0]],"ltp":1.37,"tv":267.69,"id":10894176},{"batb":[[0,4.3,18.65],[1,1.01,15.51],[2,4.3,0]],"batl":[[0,9.8,75.27],[1,9.8,0]],"ltp":3.7,"tv":94.16,"id":2263634}]}]}
{"op":"mcm","clk":"1008181458","pt":1580658693325,"mc":[{"id":"1.168224454","rc":[{"batb":[[0,1.14,945.32],[1,1.13,370.17],[2,1.01,15.51]],"batl":[[0,1.29,168.31],[1,1.3,327.73],[2,1.49,761.67]],"ltp":1.37,"tv":267.69,"id":10894176}]}]}
{"op":"mcm","clk":"1008181498","pt":1580658693630,"mc":[{"id":"1.168224454","rc":[{"batb":[[0,1.13,184.67],[1,1.01,15.51],[2,1.01,0]],"batl":[[0,1.49,761.67],[1,1.3,0],[2,1.49,0]],"ltp":1.37,"tv":267.69,"id":10894176}]}]}
{"op":"mcm","clk":"1008181868","pt":1580658696119,"mc":[{"id":"1.168224454","rc":[{"batb":[[0,1.2,252.4],[1,1.19,588.52],[2,1.13,184.67]],"batl":[[0,1.22,240.12],[1,1.23,449.44],[2,1.49,761.67]],"ltp":1.37,"tv":267.69,"id":10894176}]}]}
{"op":"mcm","clk":"1008182342","pt":1580658699339,"mc":[{"id":"1.168224454","rc":[{"batb":[[0,1.13,184.67],[1,1.01,15.51],[2,1.13,0]],"batl":[[0,1.49,761.67],[1,1.23,0],[2,1.49,0]],"ltp":1.37,"tv":267.69,"id":10894176},{"batl":[[0,8.6,81.89]],"ltp":3.7,"tv":94.16,"id":2263634}]}]}
{"op":"mcm","clk":"1008182752","pt":1580658702162,"mc":[{"id":"1.168224454","rc":[{"batb":[[0,1.14,945.32],[1,1.13,370.17],[2,1.01,15.51]],"batl":[[0,1.29,168.31],[1,1.3,327.73],[2,1.49,761.67]],"ltp":1.37,"tv":267.69,"id":10894176}]}]}
{"op":"mcm","clk":"1008183510","pt":1580658707068,"mc":[{"id":"1.168224454","rc":[{"batl":[[0,1.49,761.67],[1,1.3,0],[2,1.49,0]],"ltp":1.37,"tv":267.69,"id":10894176}]}]}
{"op":"mcm","clk":"1008184049","pt":1580658710422,"mc":[{"id":"1.168224454","rc":[{"batb":[[0,1.14,1113.36]],"batl":[[0,1.17,703.47],[1,1.18,436.03],[2,1.49,761.67]],"ltp":1.37,"tv":267.69,"id":10894176},{"batb":[[0,6.6,6.72],[1,4.3,18.65],[2,1.01,15.51]],"batl":[[0,8,5.88]],"ltp":3.7,"tv":94.16,"id":2263634}]}]}
{"op":"mcm","clk":"1008184113","pt":1580658710894,"mc":[{"id":"1.168224454","rc":[{"batb":[[2,1.1,236.44]],"ltp":1.37,"tv":267.69,"id":10894176},{"batb":[[0,6.8,12.51],[1,6.6,6.72],[2,6.4,15.19]],"ltp":3.7,"tv":94.16,"id":2263634}]}]}
{"op":"mcm","clk":"1008184495","pt":1580658713271,"mc":[{"id":"1.168224454","rc":[{"batl":[[1,12.5,65.97]],"ltp":3.7,"tv":94.16,"id":2263634}]}]}
{"op":"mcm","clk":"1008186964","pt":1580658729261,"mc":[{"id":"1.168224454","rc":[{"batb":[[0,1.1,236.44],[1,1.01,15.51],[2,1.1,0]],"batl":[[0,1.49,761.67],[1,1.18,0],[2,1.49,0]],"ltp":1.37,"tv":267.69,"id":10894176},{"batb":[[0,6.4,15.19],[1,1.01,15.51],[2,6.4,0]],"batl":[[0,12.5,65.97],[1,12.5,0]],"ltp":3.7,"tv":94.16,"id":2263634}]}]}
{"op":"mcm","clk":"1008187457","pt":1580658732436,"mc":[{"id":"1.168224454","rc":[{"batb":[[0,1.11,1146.1],[1,1.1,236.44],[2,1.01,15.51]],"batl":[[0,1.19,579.81],[1,1.2,498.36],[2,1.49,761.67]],"ltp":1.37,"tv":267.69,"id":10894176}]}]}
{"op":"mcm","clk":"1008187798","pt":1580658734571,"mc":[{"id":"1.168224454","rc":[{"batb":[[0,1.1,236.44],[1,1.01,15.51],[2,1.01,0]],"ltp":1.37,"tv":267.69,"id":10894176}]}]}
{"op":"mcm","clk":"1008188353","pt":1580658738381,"mc":[{"id":"1.168224454","rc":[{"batb":[[0,1.16,958.12],[1,1.15,486.55],[2,1.12,197.33]],"batl":[[1,1.2,540.37]],"ltp":1.37,"tv":267.69,"id":10894176},{"batb":[[1,6,8.4],[2,5.9,17.86]],"batl":[[0,7.4,5.88]],"ltp":3.7,"tv":94.16,"id":2263634}]}]}
{"op":"mcm","clk":"1008188588","pt":1580658739994,"mc":[{"id":"1.168224454","rc":[{"batl":[[0,7.2,6.72]],"ltp":3.7,"tv":94.16,"id":2263634}]}]}
{"op":"mcm","clk":"1008188788","pt":1580658741415,"mc":[{"id":"1.168224454","rc":[{"batb":[[0,1.12,197.33],[1,1.01,15.51],[2,1.12,0]],"batl":[[0,1.2,171.07],[1,1.49,761.67],[2,1.49,0]],"ltp":1.37,"tv":267.69,"id":10894176},{"batb":[[0,5.9,17.86],[1,1.01,15.51],[2,5.9,0]],"ltp":3.7,"tv":94.16,"id":2263634}]}]}
{"op":"mcm","clk":"1008188815","pt":1580658741490,"mc":[{"id":"1.168224454","rc":[{"batl":[[0,11.5,70.11]],"ltp":3.7,"tv":94.16,"id":2263634}]}]}
{"op":"mcm","clk":"1008189208","pt":1580658744197,"mc":[{"id":"1.168224454","rc":[{"batb":[[0,1.14,422.98],[1,1.13,713.1],[2,1.12,197.33]],"batl":[[1,1.21,502.8],[2,1.49,761.67]],"ltp":1.37,"tv":267.69,"id":10894176}]}]}
{"op":"mcm","clk":"1008189384","pt":1580658745314,"mc":[{"id":"1.168224454","rc":[{"batb":[[0,1.12,197.33],[1,1.01,15.51],[2,1.12,0]],"ltp":1.37,"tv":267.69,"id":10894176}]}]}
{"op":"mcm","clk":"1008189874","pt":1580658748281,"mc":[{"id":"1.168224454","rc":[{"batb":[[0,1.18,452.58],[1,1.17,644.41],[2,1.12,197.33]],"ltp":1.37,"tv":267.69,"id":10894176}]}]}
{"op":"mcm","clk":"1008190057","pt":1580658749258,"mc":[{"id":"1.168224454","rc":[{"batb":[[2,1.16,148.16]],"ltp":1.37,"tv":267.69,"id":10894176},{"batb":[[1,5.7,19.43],[2,1.01,15.51]],"ltp":3.7,"tv":94.16,"id":2263634}]}]}
{"op":"mcm","clk":"1008190229","pt":1580658750283,"mc":[{"id":"1.168224454","rc":[{"batl":[[2,1.22,42.01]],"ltp":1.37,"tv":267.69,"id":10894176},{"batb":[[1,5.7,27.84]],"batl":[[0,6.8,6.72]],"ltp":3.7,"tv":94.16,"id":2263634}]}]}
{"op":"mcm","clk":"1008190417","pt":1580658751460,"mc":[{"id":"1.168224454","rc":[{"batl":[[1,9.8,75.27]],"ltp":3.7,"tv":94.16,"id":2263634}]}]}
{"op":"mcm","clk":"1008190713","pt":1580658753379,"mc":[{"id":"1.168224454","rc":[{"batl":[[0,9.8,75.27],[1,9.8,0]],"ltp":3.7,"tv":94.16,"id":2263634}]}]}
{"op":"mcm","clk":"1008191141","pt":1580658756180,"mc":[{"id":"1.168224454","rc":[{"batl":[[0,6.6,6.72],[1,9.8,75.27]],"ltp":3.7,"tv":94.16,"id":2263634}]}]}
{"op":"mcm","clk":"1008191771","pt":1580658760386,"mc":[{"id":"1.168224454","rc":[{"batb":[[0,1.16,148.16],[1,1.14,169.01],[2,1.01,15.51]],"batl":[[0,1.22,42.01],[1,1.49,761.67],[2,1.22,0]],"ltp":1.37,"tv":267.69,"id":10894176}]}]}
{"op":"mcm","clk":"1008191926","pt":1580658761387,"mc":[{"id":"1.168224454","rc":[{"batb":[[0,1.14,169.01],[1,1.01,15.51],[2,1.01,0]],"batl":[[0,1.49,761.67],[1,1.49,0]],"ltp":1.37,"tv":267.69,"id":10894176},{"batb":[[0,5.7,19.43],[1,1.01,15.51],[2,1.01,0]],"batl":[[0,9.8,75.27],[1,9.8,0]],"ltp":3.7,"tv":94.16,"id":2263634}]}]}
{"op":"mcm","clk":"1008192242","pt":1580658763403,"mc":[{"id":"1.168224454","rc":[{"batb":[[0,1.16,638],[1,1.15,476.45],[2,1.14,169.01]],"batl":[[0,1.22,560.15],[1,1.23,440.95],[2,1.49,761.67]],"ltp":1.37,"tv":267.69,"id":10894176}]}]}
{"op":"mcm","clk":"1008194883","pt":1580658780309,"mc":[{"id":"1.168224454","rc":[{"batb":[[0,1.14,169.01],[1,1.01,15.51],[2,1.14,0]],"ltp":1.37,"tv":267.69,"id":10894176}]}]}
{"op":"mcm","clk":"1008195356","pt":1580658783213,"mc":[{"id":"1.168224454","rc":[{"batb":[[0,1.19,483.55],[1,1.18,603.88],[2,1.14,169.01]],"ltp":1.37,"tv":267.69,"id":10894176}]}]}
{"op":"mcm","clk":"1008195567","pt":1580658784427,"mc":[{"id":"1.168224454","rc":[{"batb":[[2,1.17,140.21]],"batl":[[1,1.23,482.96]],"ltp":1.37,"tv":267.69,"id":10894176},{"batb":[[1,5.5,10.46],[2,5.4,9.24]],"batl":[[0,6.4,7.56],[1,9.8,75.27]],"ltp":3.7,"tv":94.16,"id":2263634}]}]}
{"op":"mcm","clk":"1008198254","pt":1580658799971,"mc":[{"id":"1.168224454","rc":[{"batb":[[0,1.18,499.91],[1,1.16,151.15],[2,1.01,15.51]],"batl":[[0,1.22,264.87]],"ltp":1.37,"tv":267.69,"id":10894176},{"batb":[[0,5.5,10.46],[1,5.4,9.24],[2,1.01,15.51]],"ltp":3.7,"tv":94.16,"id":2263634}]}]}
{"op":"mcm","clk":"1008198664","pt":1580658802445,"mc":[{"id":"1.168224454","rc":[{"batb":[[1,1.17,596.68],[2,1.16,151.15]],"batl":[[1,1.23,440.95]],"ltp":1.37,"tv":267.69,"id":10894176},{"batb":[[1,1.01,15.51],[2,1.01,0]],"batl":[[0,9.8,75.27],[1,9.8,0]],"ltp":3.7,"tv":94.16,"id":2263634}]}]}
{"op":"mcm","clk":"1008198903","pt":1580658803828,"mc":[{"id":"1.168224454","rc":[{"batb":[[0,1.16,151.15],[1,1.01,15.51],[2,1.16,0]],"ltp":1.37,"tv":267.69,"id":10894176}]}]}
{"op":"mcm","clk":"1008199470","pt":1580658807243,"mc":[{"id":"1.168224454","rc":[{"batb":[[0,1.2,226.67],[1,1.19,588.36],[2,1.17,347.79]],"ltp":1.37,"tv":267.69,"id":10894176}]}]}
{"op":"mcm","clk":"1008199655","pt":1580658808357,"mc":[{"id":"1.168224454","rc":[{"batb":[[2,1.18,134.07]],"batl":[[2,1.24,42.01]],"ltp":1.37,"tv":267.69,"id":10894176},{"batb":[[1,5.2,9.24],[2,4.1,21.17]],"batl":[[0,6,8.4],[1,9.8,75.27]],"ltp":3.7,"tv":94.16,"id":2263634}]}]}
{"op":"mcm","clk":"1008200251","pt":1580658811868,"mc":[{"id":"1.168224454","rc":[{"batl":[[0,9.8,75.27],[1,9.8,0]],"ltp":3.7,"tv":94.16,"id":2263634}]}]}
{"op":"mcm","clk":"1008200752","pt":1580658814843,"mc":[{"id":"1.168224454","rc":[{"batb":[[1,1.19,756.4]],"ltp":1.37,"tv":267.69,"id":10894176},{"batl":[[0,6.2,7.56],[1,9.8,75.27]],"ltp":3.7,"tv":94.16,"id":2263634}]}]}
{"op":"mcm","clk":"1008205840","pt":1580658846072,"mc":[{"id":"1.168224454","rc":[{"trd":[[5.5,10.08]],"batb":[[0,5.5,5.42]],"ltp":5.5,"tv":104.24,"id":2263634}],"tv":371.94}]}
{"op":"mcm","clk":"1008205979","pt":1580658847024,"mc":[{"id":"1.168224454","rc":[{"batb":[[2,1.18,132.58]],"ltp":1.37,"tv":267.69,"id":10894176}]}]}
{"op":"mcm","clk":"1008206908","pt":1580658852926,"mc":[{"id":"1.168224454","rc":[{"batb":[[0,1.2,194.17]],"ltp":1.37,"tv":267.69,"id":10894176}]}]}
{"op":"mcm","clk":"1008207471","pt":1580658856410,"mc":[{"id":"1.168224454","rc":[{"batl":[[0,1.22,296.83]],"ltp":1.37,"tv":267.69,"id":10894176}]}]}
{"op":"mcm","clk":"1008208003","pt":1580658859831,"mc":[{"id":"1.168224454","rc":[{"batb":[[0,1.19,756.4],[1,1.18,132.58],[2,1.14,174.28]],"ltp":1.37,"tv":267.69,"id":10894176}]}]}
{"op":"mcm","clk":"1008208444","pt":1580658862730,"mc":[{"id":"1.168224454","rc":[{"batb":[[0,1.19,898.37],[1,1.18,487.59]],"batl":[[0,1.22,349.44]],"ltp":1.37,"tv":267.69,"id":10894176}]}]}
{"op":"mcm","clk":"1008211425","pt":1580658882094,"mc":[{"id":"1.168224454","rc":[{"batb":[[0,6,1.72],[1,5.5,5.42],[2,5.2,9.24]],"ltp":5.5,"tv":104.24,"id":2263634}]}]}
{"op":"mcm","clk":"1008214597","pt":1580658902055,"mc":[{"id":"1.168224454","rc":[{"batb":[[0,5.5,5.42],[1,5.2,9.24],[2,4.1,21.17]],"ltp":5.5,"tv":104.24,"id":2263634}]}]}
{"op":"mcm","clk":"1008215129","pt":1580658905347,"mc":[{"id":"1.168224454","rc":[{"batb":[[0,1.14,174.28],[1,1.01,15.51],[2,1.14,0]],"batl":[[0,1.49,761.67],[1,1.23,0],[2,1.24,0]],"ltp":1.37,"tv":267.69,"id":10894176},{"batb":[[0,4.1,21.17],[1,1.01,15.51],[2,4.1,0]],"batl":[[0,9.8,75.27],[1,9.8,0]],"ltp":5.5,"tv":104.24,"id":2263634}]}]}
{"op":"mcm","clk":"1008215149","pt":1580658905465,"mc":[{"id":"1.168224454","rc":[{"batb":[[0,6.2,1.66],[1,4.1,21.17],[2,1.01,15.51]],"ltp":5.5,"tv":104.24,"id":2263634}]}]}
{"op":"mcm","clk":"1008215598","pt":1580658908129,"mc":[{"id":"1.168224454","rc":[{"trd":[[6.2,3.33]],"batb":[[0,4.1,21.17],[1,1.01,15.51],[2,1.01,0]],"batl":[[0,9.8,75.29]],"ltp":6.2,"tv":107.57,"id":2263634}],"tv":375.27}]}
{"op":"mcm","clk":"1008215703","pt":1580658908739,"mc":[{"id":"1.168224454","rc":[{"batl":[[0,6,0.02]],"ltp":6.2,"tv":107.57,"id":2263634}]}]}
{"op":"mcm","clk":"1008215925","pt":1580658910039,"mc":[{"id":"1.168224454","rc":[{"batb":[[0,1.21,500.28],[1,1.2,565.24],[2,1.14,174.28]],"batl":[[0,1.24,404.42],[1,1.25,405.69],[2,1.49,761.67]],"ltp":1.37,"tv":267.69,"id":10894176}]}]}
{"op":"mcm","clk":"1008216303","pt":1580658912146,"mc":[{"id":"1.168224454","rc":[{"batb":[[0,1.14,174.28],[1,1.01,15.51],[2,1.14,0]],"batl":[[0,1.49,761.67],[1,1.25,0],[2,1.49,0]],"ltp":1.37,"tv":267.69,"id":10894176},{"batl":[[0,8.6,81.89]],"ltp":6.2,"tv":107.57,"id":2263634}]}]}
{"op":"mcm","clk":"1008216785","pt":1580658914886,"mc":[{"id":"1.168224454","rc":[{"batb":[[0,1.15,890.91],[1,1.14,405.38],[2,1.01,15.51]],"batl":[[0,1.32,358.02],[1,1.33,290.36],[2,1.49,761.67]],"ltp":1.37,"tv":267.69,"id":10894176}]}]}
{"op":"mcm","clk":"1008218019","pt":1580658922262,"mc":[{"id":"1.168224454","rc":[{"batl":[[0,1.49,761.67],[1,1.33,0],[2,1.49,0]],"ltp":1.37,"tv":267.69,"id":10894176}]}]}
{"op":"mcm","clk":"1008218553","pt":1580658925341,"mc":[{"id":"1.168224454","rc":[{"batl":[[0,1.18,624.54],[1,1.19,463.07],[2,1.49,761.67]],"ltp":1.37,"tv":267.69,"id":10894176}]}]}
{"op":"mcm","clk":"1008218701","pt":1580658926337,"mc":[{"id":"1.168224454","rc":[{"batb":[[2,1.11,223.06]],"ltp":1.37,"tv":267.69,"id":10894176},{"batb":[[0,6.6,13.77],[1,6.2,7.56],[2,5,12.9]],"batl":[[0,7.4,5.88]],"ltp":6.2,"tv":107.57,"id":2263634}]}]}
{"op":"mcm","clk":"1008218977","pt":1580658928170,"mc":[{"id":"1.168224454","rc":[{"batl":[[1,11.5,70.11]],"ltp":6.2,"tv":107.57,"id":2263634}]}]}
{"op":"mcm","clk":"1008219202","pt":1580658929348,"mc":[{"id":"1.168224454","rc":[{"trd":[[1.15,0.04]],"batb":[[0,1.15,890.89]],"ltp":1.15,"tv":267.73,"id":10894176}],"tv":375.3}]}
{"op":"mcm","clk":"1008220286","pt":1580658936948,"mc":[{"id":"1.168224454","rc":[{"batb":[[0,1.11,223.06],[1,1.01,15.51],[2,1.11,0]],"batl":[[0,1.49,761.67],[1,1.19,0],[2,1.49,0]],"ltp":1.15,"tv":267.73,"id":10894176},{"batb":[[0,6.2,7.56],[1,5,12.9],[2,1.01,15.51]],"ltp":6.2,"tv":107.57,"id":2263634}]}]}
{"op":"mcm","clk":"1008220379","pt":1580658937461,"mc":[{"id":"1.168224454","rc":[{"batb":[[0,5,12.9],[1,1.01,15.51],[2,1.01,0]],"batl":[[0,11.5,70.11],[1,11.5,0]],"ltp":6.2,"tv":107.57,"id":2263634}]}]}
{"op":"mcm","clk":"1008220687","pt":1580658939365,"mc":[{"id":"1.168224454","rc":[{"batb":[[0,1.13,328.74],[1,1.12,818.33],[2,1.11,223.06]],"batl":[[0,1.24,244.45],[1,1.25,409.65],[2,1.49,761.67]],"ltp":1.15,"tv":267.73,"id":10894176}]}]}
{"op":"mcm","clk":"1008220850","pt":1580658940362,"mc":[{"id":"1.168224454","rc":[{"batb":[[0,1.11,223.06],[1,1.01,15.51],[2,1.11,0]],"batl":[[0,1.49,761.67],[1,1.25,0],[2,1.49,0]],"ltp":1.15,"tv":267.73,"id":10894176}]}]}
{"op":"mcm","clk":"1008221174","pt":1580658942274,"mc":[{"id":"1.168224454","rc":[{"batb":[[0,1.17,225.6],[1,1.16,721.8],[2,1.11,223.06]],"batl":[[0,1.19,451.94],[1,1.2,525.7],[2,1.49,761.67]],"ltp":1.15,"tv":267.73,"id":10894176}]}]}
{"op":"mcm","clk":"1008222075","pt":1580658947685,"mc":[{"id":"1.168224454","rc":[{"batb":[[0,1.11,223.06],[1,1.01,15.51],[2,1.11,0]],"batl":[[0,1.49,761.67],[1,1.2,0],[2,1.49,0]],"ltp":1.15,"tv":267.73,"id":10894176}]}]}
{"op":"mcm","clk":"1008222570","pt":1580658950698,"mc":[{"id":"1.168224454","rc":[{"batb":[[0,1.13,328.74],[1,1.12,818.33],[2,1.11,223.06]],"batl":[[0,1.24,244.45],[1,1.25,409.65],[2,1.49,761.67]],"ltp":1.15,"tv":267.73,"id":10894176}]}]}
{"op":"mcm","clk":"1008223913","pt":1580658959008,"mc":[{"id":"1.168224454","rc":[{"trd":[[1.13,16.8]],"batb":[[0,1.13,320.34]],"batl":[[0,1.49,761.67],[1,1.25,0],[2,1.49,0]],"ltp":1.13,"tv":284.53,"id":10894176}],"tv":392.1}]}
{"op":"mcm","clk":"1008224484","pt":1580658962415,"mc":[{"id":"1.168224454","rc":[{"batb":[[0,1.13,488.38]],"batl":[[0,1.15,725.58],[1,1.16,391.02]],"ltp":1.13,"tv":284.53,"id":10894176},{"batb":[[0,7,6.72],[1,5,12.9],[2,1.01,15.51]],"batl":[[0,8.8,5.04]],"ltp":6.2,"tv":107.57,"id":2263634}]}]}
{"op":"mcm","clk":"1008224643","pt":1580658963328,"mc":[{"id":"1.168224454","rc":[{"batl":[[1,1.16,433.03]],"ltp":1.13,"tv":284.53,"id":10894176},{"batb":[[0,7.8,9.21],[1,7,6.72],[2,6.2,15.5]],"ltp":6.2,"tv":107.57,"id":2263634}]}]}
{"op":"mcm","clk":"1008225001","pt":1580658965397,"mc":[{"id":"1.168224454","rc":[{"batl":[[2,1.43,872.38]],"ltp":1.13,"tv":284.53,"id":10894176},{"batl":[[1,14,62.58]],"ltp":6.2,"tv":107.57,"id":2263634}]}]}
{"op":"mcm","clk":"1008227727","pt":1580658982233,"mc":[{"id":"1.168224454","rc":[{"batb":[[0,1.13,168.04],[1,1.09,262.09],[2,1.01,15.51]],"batl":[[0,1.16,42.01],[1,1.43,872.38],[2,1.43,0]],"ltp":1.13,"tv":284.53,"id":10894176},{"batb":[[0,7,6.72],[1,6.2,15.5],[2,1.01,15.51]],"ltp":6.2,"tv":107.57,"id":2263634}]}]}
{"op":"mcm","clk":"1008227920","pt":1580658983433,"mc":[{"id":"1.168224454","rc":[{"batb":[[0,1.09,262.09],[1,1.01,15.51],[2,1.01,0]],"batl":[[0,1.43,872.38],[1,1.43,0]],"ltp":1.13,"tv":284.53,"id":10894176},{"batb":[[0,6.2,15.5],[1,1.01,15.51],[2,1.01,0]],"batl":[[0,14,62.58],[1,14,0]],"ltp":6.2,"tv":107.57,"id":2263634}]}]}
{"op":"mcm","clk":"1008228139","pt":1580658984720,"mc":[{"id":"1.168224454","rc":[{"batb":[[0,1.11,817.54],[1,1.1,345.94],[2,1.09,262.09]],"batl":[[0,1.18,171.84],[1,1.19,567.82],[2,1.43,872.38]],"ltp":1.13,"tv":284.53,"id":10894176}]}]}
{"op":"mcm","clk":"1008228297","pt":1580658985645,"mc":[{"id":"1.168224454","rc":[{"batl":[[0,1.43,872.38],[1,1.19,0],[2,1.43,0]],"ltp":1.13,"tv":284.53,"id":10894176}]}]}
{"op":"mcm","clk":"1008228888","pt":1580658989426,"mc":[{"id":"1.168224454","rc":[{"batl":[[0,1.13,577.44],[1,1.14,557.45],[2,1.43,872.38]],"ltp":1.13,"tv":284.53,"id":10894176},{"batb":[[0,8.8,7],[1,7.6,9.91],[2,1.01,15.51]],"ltp":6.2,"tv":107.57,"id":2263634}]}]}
{"op":"mcm","clk":"1008229045","pt":1580658990357,"mc":[{"id":"1.168224454","rc":[{"batb":[[1,7.8,5.88],[2,7.6,9.91]],"batl":[[0,10,4.2]],"ltp":6.2,"tv":107.57,"id":2263634}]}]}
{"op":"mcm","clk":"1008229450","pt":1580658992846,"mc":[{"id":"1.168224454","rc":[{"batl":[[1,17,57.33]],"ltp":6.2,"tv":107.57,"id":2263634}]}]}
{"op":"mcm","clk":"1008230013","pt":1580658996062,"mc":[{"id":"1.168224454","rc":[{"trd":[[8.8,2.34]],"batb":[[0,8.8,5.83]],"ltp":8.8,"tv":109.91,"id":2263634}],"tv":394.45}]}
{"op":"mcm","clk":"1008231263","pt":1580659003371,"mc":[{"id":"1.168224454","rc":[{"batb":[[0,1.1,345.94],[1,1.08,288.29],[2,1.01,15.51]],"batl":[[0,1.43,872.38],[1,1.14,0],[2,1.43,0]],"ltp":1.13,"tv":284.53,"id":10894176},{"batb":[[0,7.8,5.88],[1,7.6,9.91],[2,1.01,15.51]],"ltp":8.8,"tv":109.91,"id":2263634}]}]}
{"op":"mcm","clk":"1008231282","pt":1580659003471,"mc":[{"id":"1.168224454","rc":[{"batb":[[1,1.08,287.11]],"ltp":1.13,"tv":284.53,"id":10894176},{"batb":[[0,7.6,9.91],[1,1.01,15.51],[2,1.01,0]],"batl":[[0,17,57.33],[1,17,0]],"ltp":8.8,"tv":109.91,"id":2263634}]}]}
{"op":"mcm","clk":"1008231747","pt":1580659006273,"mc":[{"id":"1.168224454","rc":[{"batb":[[0,1.1,1170.92]],"batl":[[0,1.15,747.76],[1,1.16,369.04],[2,1.43,872.38]],"ltp":1.13,"tv":284.53,"id":10894176}]}]}
{"op":"mcm","clk":"1008232334","pt":1580659009982,"mc":[{"id":"1.168224454","rc":[{"batb":[[0,1.08,287.11],[1,1.01,15.51],[2,1.01,0]],"ltp":1.13,"tv":284.53,"id":10894176}]}]}
{"op":"mcm","clk":"1008232872","pt":1580659013361,"mc":[{"id":"1.168224454","rc":[{"batb":[[0,1.13,302.88],[1,1.12,844.41],[2,1.11,2476.86]],"ltp":1.13,"tv":284.53,"id":10894176}]}]}
{"op":"mcm","clk":"1008233052","pt":1580659014364,"mc":[{"id":"1.168224454","rc":[{"batb":[[2,1.11,212.44]],"batl":[[1,1.16,411.05]],"ltp":1.13,"tv":284.53,"id":10894176},{"batb":[[1,7.4,5.88],[2,6,16.44]],"batl":[[0,9,5.04]],"ltp":8.8,"tv":109.91,"id":2263634}]}]}
{"op":"mcm","clk":"1008233337","pt":1580659016090,"mc":[{"id":"1.168224454","rc":[{"batl":[[1,14,62.58]],"ltp":8.8,"tv":109.91,"id":2263634}]}]}
{"op":"mcm","clk":"1008235080","pt":1580659026430,"mc":[{"id":"1.168224454","rc":[{"trd":[[1.15,0.07]],"batl":[[0,1.15,747.74]],"ltp":1.15,"tv":284.56,"id":10894176}],"tv":394.48}]}
{"op":"mcm","clk":"1008236286","pt":1580659033433,"mc":[{"id":"1.168224454","rc":[{"batb":[[0,1.1,250.76],[1,1.01,15.51],[2,1.11,0]],"batl":[[0,1.43,872.38],[1,1.16,0],[2,1.43,0]],"ltp":1.15,"tv":284.56,"id":10894176},{"batb":[[0,6,16.44],[1,1.01,15.51],[2,6,0]],"batl":[[0,14,62.58],[1,14,0]],"ltp":8.8,"tv":109.91,"id":2263634}]}]}
{"op":"mcm","clk":"1008237328","pt":1580659039420,"mc":[{"id":"1.168224454","rc":[{"batb":[[0,1.13,881.63],[1,1.12,260.5],[2,1.1,250.76]],"batl":[[0,1.15,237.22],[1,1.16,688.39],[2,1.43,872.38]],"ltp":1.15,"tv":284.56,"id":10894176}]}]}
{"op":"mcm","clk":"1008237920","pt":1580659043124,"mc":[{"id":"1.168224454","rc":[{"batb":[[0,1.1,250.76],[1,1.01,15.51],[2,1.1,0]],"batl":[[0,1.43,872.38],[1,1.16,0],[2,1.43,0]],"ltp":1.15,"tv":284.56,"id":10894176}]}]}
{"op":"mcm","clk":"1008238345","pt":1580659046094,"mc":[{"id":"1.168224454","rc":[{"batb":[[0,1.11,846.33],[1,1.1,567.65],[2,1.01,15.51]],"batl":[[0,1.18,311.61],[1,1.19,562.85],[2,1.43,872.38]],"ltp":1.15,"tv":284.56,"id":10894176}]}]}
{"op":"mcm","clk":"1008238867","pt":1580659049508,"mc":[{"id":"1.168224454","rc":[{"batl":[[0,1.43,872.38],[1,1.19,0],[2,1.43,0]],"ltp":1.15,"tv":284.56,"id":10894176}]}]}
{"op":"mcm","clk":"1008239524","pt":1580659053387,"mc":[{"id":"1.168224454","rc":[{"batb":[[2,1.07,318.82]],"batl":[[0,1.13,553.02],[1,1.14,581.64],[2,1.43,872.38]],"ltp":1.15,"tv":284.56,"id":10894176},{"batb":[[0,8.6,7.55],[1,8,9.05],[2,1.01,15.51]],"ltp":8.8,"tv":109.91,"id":2263634}]}]}
{"op":"mcm","clk":"1008239676","pt":1580659054420,"mc":[{"id":"1.168224454","rc":[{"batb":[[0,1.11,1014.37]],"batl":[[1,1.14,623.65]],"ltp":1.15,"tv":284.56,"id":10894176},{"batb":[[1,8.2,5.04],[2,8,9.05]],"batl":[[0,10,4.2]],"ltp":8.8,"tv":109.91,"id":2263634}]}]}
{"op":"mcm","clk":"1008239935","pt":1580659056178,"mc":[{"id":"1.168224454","rc":[{"batl":[[1,17,57.33]],"ltp":8.8,"tv":109.91,"id":2263634}]}]}
{"op":"mcm","clk":"1008242980","pt":1580659076968,"mc":[{"id":"1.168224454","rc":[{"batb":[[0,1.11,168.04],[1,1.07,318.82],[2,1.01,15.51]],"batl":[[0,1.14,42.01],[1,1.43,872.38],[2,1.43,0]],"ltp":1.15,"tv":284.56,"id":10894176},{"batb":[[0,8.2,5.04],[1,8,9.05],[2,1.01,15.51]],"ltp":8.8,"tv":109.91,"id":2263634}]}]}
{"op":"mcm","clk":"1008243041","pt":1580659077449,"mc":[{"id":"1.168224454","rc":[{"batb":[[0,1.07,318.82],[1,1.01,15.51],[2,1.01,0]],"batl":[[0,1.43,872.38],[1,1.43,0]],"ltp":1.15,"tv":284.56,"id":10894176},{"batb":[[0,8,9.05],[1,1.01,15.51],[2,1.01,0]],"batl":[[0,17,57.33],[1,17,0]],"ltp":8.8,"tv":109.91,"id":2263634}]}]}
{"op":"mcm","clk":"1008243780","pt":1580659082324,"mc":[{"id":"1.168224454","rc":[{"batb":[[0,1.11,308.37],[1,1.1,859.71],[2,1.07,318.82]],"batl":[[0,1.13,1016.61],[1,1.43,872.38]],"ltp":1.15,"tv":284.56,"id":10894176}]}]}
{"op":"mcm","clk":"1008244121","pt":1580659084427,"mc":[{"id":"1.168224454","rc":[{"batb":[[0,1.07,318.82],[1,1.01,15.51],[2,1.07,0]],"batl":[[0,1.43,872.38],[1,1.43,0]],"ltp":1.15,"tv":284.56,"id":10894176}]}]}
{"op":"mcm","clk":"1008244572","pt":1580659087314,"mc":[{"id":"1.168224454","rc":[{"batb":[[0,1.09,466.96],[1,1.08,721.29],[2,1.07,318.82]],"batl":[[0,1.15,815.89],[1,1.16,301.47],[2,1.43,872.38]],"ltp":1.15,"tv":284.56,"id":10894176}]}]}
{"op":"mcm","clk":"1008244896","pt":1580659089560,"mc":[{"id":"1.168224454","rc":[{"batl":[[0,1.43,872.38],[1,1.16,0],[2,1.43,0]],"ltp":1.15,"tv":284.56,"id":10894176}]}]}
{"op":"mcm","clk":"1008245433","pt":1580659093136,"mc":[{"id":"1.168224454","rc":[{"batl":[[0,1.1,218.08],[1,1.11,944.22],[2,1.43,872.38]],"ltp":1.15,"tv":284.56,"id":10894176},{"batb":[[0,10,12.98],[1,8.8,7],[2,8,9.05]],"ltp":8.8,"tv":109.91,"id":2263634}]}]}
{"op":"mcm","clk":"1008245619","pt":1580659094359,"mc":[{"id":"1.168224454","rc":[{"batl":[[1,1.11,986.23]],"ltp":1.15,"tv":284.56,"id":10894176},{"batb":[[1,9.8,4.2],[2,8.8,7]],"batl":[[0,12.5,3.36]],"ltp":8.8,"tv":109.91,"id":2263634}]}]}
{"op":"mcm","clk":"1008245881","pt":1580659095971,"mc":[{"id":"1.168224454","rc":[{"batl":[[1,21,53.48]],"ltp":8.8,"tv":109.91,"id":2263634}]}]}
{"op":"mcm","clk":"1008246916","pt":1580659103437,"mc":[{"id":"1.168224454","rc":[{"batb":[[0,1.04,493.49],[1,1.01,15.51],[2,1.07,0]],"batl":[[0,1.43,872.38],[1,1.11,0],[2,1.43,0]],"ltp":1.15,"tv":284.56,"id":10894176},{"batb":[[0,8.8,7],[1,1.01,15.51],[2,8.8,0]],"batl":[[0,21,53.48],[1,21,0]],"ltp":8.8,"tv":109.91,"id":2263634}]}]}
{"op":"mcm","clk":"1008247478","pt":1580659107040,"mc":[{"id":"1.168224454","rc":[{"batb":[[0,1.08,1100.59],[1,1.04,493.49],[2,1.01,15.51]],"batl":[[0,1.1,996.8]],"ltp":1.15,"tv":284.56,"id":10894176}]}]}
{"op":"mcm","clk":"1008247622","pt":1580659108041,"mc":[{"id":"1.168224454","rc":[{"batb":[[0,1.04,493.49],[1,1.01,15.51],[2,1.01,0]],"ltp":1.15,"tv":284.56,"id":10894176}]}]}
{"op":"mcm","clk":"1008247997","pt":1580659110366,"mc":[{"id":"1.168224454","rc":[{"batb":[[0,1.08,91.99],[1,1.04,493.49],[2,1.01,15.51]],"batl":[[0,1.11,370.03],[1,1.37,1010.69]],"ltp":1.15,"tv":284.56,"id":10894176},{"batl":[[0,24,50.52]],"ltp":8.8,"tv":109.91,"id":2263634}]}]}
{"op":"mcm","clk":"1008248169","pt":1580659111372,"mc":[{"id":"1.168224454","rc":[{"batb":[[0,1.06,982.12],[1,1.05,235.18],[2,1.04,493.49]],"batl":[[0,1.13,644.78],[1,1.14,490.68],[2,1.37,1010.69]],"ltp":1.15,"tv":284.56,"id":10894176}]}]}
{"op":"mcm","clk":"1008249143","pt":1580659117962,"mc":[{"id":"1.168224454","rc":[{"batl":[[0,1.37,1010.69],[1,1.14,0],[2,1.37,0]],"ltp":1.15,"tv":284.56,"id":10894176}]}]}
{"op":"mcm","clk":"1008249619","pt":1580659121219,"mc":[{"id":"1.168224454","rc":[{"batl":[[0,1.07,306.85],[1,1.08,888.57],[2,1.37,1010.69]],"ltp":1.15,"tv":284.56,"id":10894176}]}]}
{"op":"mcm","clk":"1008249790","pt":1580659122376,"mc":[{"id":"1.168224454","rc":[{"batb":[[0,1.06,1150.16]],"batl":[[1,1.08,930.58]],"ltp":1.15,"tv":284.56,"id":10894176},{"batb":[[0,14,6.14],[1,13.5,3.36],[2,11,10.15]],"ltp":8.8,"tv":109.91,"id":2263634}]}]}
{"op":"mcm","clk":"1008250047","pt":1580659124386,"mc":[{"id":"1.168224454","rc":[{"batl":[[0,42,43.68]],"ltp":8.8,"tv":109.91,"id":2263634}]}]}
{"op":"mcm","clk":"1008251119","pt":1580659132384,"mc":[{"id":"1.168224454","rc":[{"batb":[[0,1.06,168.04],[1,1.04,493.49],[2,1.01,15.51]],"batl":[[0,1.08,42.01],[1,1.37,1010.69],[2,1.37,0]],"ltp":1.15,"tv":284.56,"id":10894176}]}]}
{"op":"mcm","clk":"1008251158","pt":1580659132700,"mc":[{"id":"1.168224454","rc":[{"batb":[[1,1.01,15.51],[2,1.01,0]],"ltp":1.15,"tv":284.56,"id":10894176},{"batb":[[0,13.5,3.36],[1,11,10.15],[2,1.01,15.51]],"ltp":8.8,"tv":109.91,"id":2263634}]}]}
{"op":"mcm","clk":"1008251387","pt":1580659134167,"mc":[{"id":"1.168224454","rc":[{"batb":[[0,1.01,15.51],[1,1.01,0]],"ltp":1.15,"tv":284.56,"id":10894176},{"batb":[[0,11,10.15],[1,1.01,15.51],[2,1.01,0]],"ltp":8.8,"tv":109.91,"id":2263634}]}]}
{"op":"mcm","clk":"1008251567","pt":1580659135412,"mc":[{"id":"1.168224454","rc":[{"batb":[[0,1.03,993.14],[1,1.02,259.85],[2,1.01,15.51]],"batl":[[0,1.1,1108.12]],"ltp":1.15,"tv":284.56,"id":10894176}]}]}
{"op":"mcm","clk":"1008252060","pt":1580659138639,"mc":[{"id":"1.168224454","rc":[{"batb":[[0,1.01,15.51],[1,1.02,0],[2,1.01,0]],"ltp":1.15,"tv":284.56,"id":10894176}]}]}
{"op":"mcm","clk":"1008252461","pt":1580659141433,"mc":[{"id":"1.168224454","rc":[{"batb":[[0,1.08,883.73],[1,1.07,311.73],[2,1.01,15.51]],"ltp":1.15,"tv":284.56,"id":10894176}]}]}
{"op":"mcm","clk":"1008252558","pt":1580659141929,"mc":[{"id":"1.168224454","rc":[{"batb":[[2,1.06,366.11]],"ltp":1.15,"tv":284.56,"id":10894176},{"batb":[[1,9.2,16.05],[2,1.01,15.51]],"ltp":8.8,"tv":109.91,"id":2263634}]}]}
{"op":"mcm","clk":"1008252758","pt":1580659143425,"mc":[{"id":"1.168224454","rc":[{"batl":[[0,1.1,1150.13],[1,1.37,1010.69]],"ltp":1.15,"tv":284.56,"id":10894176},{"batb":[[0,11,14.35]],"batl":[[0,24,50.52]],"ltp":8.8,"tv":109.91,"id":2263634}]}]}
{"op":"mcm","clk":"1008254377","pt":1580659153405,"mc":[{"id":"1.168224454","rc":[{"batb":[[0,1.03,712.7],[1,1.01,15.51],[2,1.06,0]],"batl":[[0,1.37,1010.69],[1,1.37,0]],"ltp":1.15,"tv":284.56,"id":10894176},{"batb":[[0,9.2,16.05],[1,1.01,15.51],[2,1.01,0]],"ltp":8.8,"tv":109.91,"id":2263634}]}]}
{"op":"mcm","clk":"1008254634","pt":1580659155322,"mc":[{"id":"1.168224454","rc":[{"batb":[[0,1.04,1238.45],[1,1.03,712.7],[2,1.01,15.51]],"batl":[[0,1.12,288.17],[1,1.13,841.99]],"ltp":1.15,"tv":284.56,"id":10894176}]}]}
{"op":"mcm","clk":"1008254763","pt":1580659156333,"mc":[{"id":"1.168224454","rc":[{"batb":[[0,1.03,712.7],[1,1.01,15.51],[2,1.01,0]],"ltp":1.15,"tv":284.56,"id":10894176}]}]}
{"op":"mcm","clk":"1008255175","pt":1580659159319,"mc":[{"id":"1.168224454","rc":[{"batb":[[0,1.1,1170.89],[1,1.03,712.7],[2,1.01,15.51]],"ltp":1.15,"tv":284.56,"id":10894176}]}]}
{"op":"mcm","clk":"1008255324","pt":1580659160425,"mc":[{"id":"1.168224454","rc":[{"batb":[[0,1.1,1285.82],[1,1.09,281.29],[2,1.05,453.52]],"batl":[[1,1.13,710.89]],"ltp":1.15,"tv":284.56,"id":10894176},{"batb":[[1,9,5.04],[2,8,8.89]],"batl":[[0,11,4.2]],"ltp":8.8,"tv":109.91,"id":2263634}]}]}
{"op":"mcm","clk":"1008255473","pt":1580659161541,"mc":[{"id":"1.168224454","rc":[{"batl":[[2,1.38,972.97]],"ltp":1.15,"tv":284.56,"id":10894176},{"batl":[[1,21,53.48]],"ltp":8.8,"tv":109.91,"id":2263634}]}]}
{"op":"mcm","clk":"1008255684","pt":1580659162824,"mc":[{"id":"1.168224454","rc":[{"batl":[[0,1.12,475.13]],"ltp":1.15,"tv":284.56,"id":10894176}]}]}
{"op":"mcm","clk":"1008256765","pt":1580659169426,"mc":[{"id":"1.168224454","rc":[{"batb":[[0,1.05,446.52],[1,1.01,15.51],[2,1.05,0]],"batl":[[0,1.38,972.97],[1,1.13,0],[2,1.38,0]],"ltp":1.15,"tv":284.56,"id":10894176},{"batb":[[0,8,8.89],[1,1.01,15.51],[2,8,0]],"batl":[[0,21,53.48],[1,21,0]],"ltp":8.8,"tv":109.91,"id":2263634}]}]}
{"op":"mcm","clk":"1008257774","pt":1580659175311,"mc":[{"id":"1.168224454","rc":[{"batb":[[0,1.09,1181.64],[1,1.05,446.52],[2,1.01,15.51]],"batl":[[0,1.11,375.5],[1,1.12,777.83],[2,1.38,972.97]],"ltp":1.15,"tv":284.56,"id":10894176}]}]}
{"op":"mcm","clk":"1008258103","pt":1580659177427,"mc":[{"id":"1.168224454","rc":[{"batb":[[0,1.05,446.52],[1,1.01,15.51],[2,1.01,0]],"batl":[[0,1.38,972.97],[1,1.12,0],[2,1.38,0]],"ltp":1.15,"tv":284.56,"id":10894176}]}]}
{"op":"mcm","clk":"1008258518","pt":1580659180246,"mc":[{"id":"1.168224454","rc":[{"batb":[[0,1.06,1215.08],[1,1.05,446.52],[2,1.01,15.51]],"batl":[[0,1.15,585.78],[1,1.16,529.6]],"ltp":1.15,"tv":284.56,"id":10894176}]}]}
{"op":"mcm","clk":"1008258622","pt":1580659180952,"mc":[{"id":"1.168224454","rc":[{"batb":[[0,1.05,446.52],[1,1.01,15.51],[2,1.01,0]],"ltp":1.15,"tv":284.56,"id":10894176}]}]}
{"op":"mcm","clk":"1008259175","pt":1580659184439,"mc":[{"id":"1.168224454","rc":[{"batb":[[0,1.13,460.76],[1,1.12,853.14],[2,1.11,223.93]],"ltp":1.15,"tv":284.56,"id":10894176},{"batb":[[1,7.6,5.88],[2,7.4,10.86]],"batl":[[0,9.2,5.04]],"ltp":8.8,"tv":109.91,"id":2263634}]}]}
{"op":"mcm","clk":"1008259620","pt":1580659187150,"mc":[{"id":"1.168224454","rc":[{"batl":[[2,1.43,872.38]],"ltp":1.15,"tv":284.56,"id":10894176},{"batl":[[1,14,62.58]],"ltp":8.8,"tv":109.91,"id":2263634}]}]}
{"op":"mcm","clk":"1008260851","pt":1580659194803,"mc":[{"id":"1.168224454","rc":[{"batb":[[1,1.12,819.78]],"batl":[[0,1.15,553.32]],"ltp":1.15,"tv":284.56,"id":10894176}]}]}
{"op":"mcm","clk":"1008261248","pt":1580659197325,"mc":[{"id":"1.168224454","rc":[{"batb":[[0,1.12,168.04],[1,1.11,223.93],[2,1.08,285.06]],"batl":[[0,1.43,872.38],[1,1.16,0],[2,1.43,0]],"ltp":1.15,"tv":284.56,"id":10894176}]}]}
{"op":"mcm","clk":"1008261401","pt":1580659198306,"mc":[{"id":"1.168224454","rc":[{"batb":[[0,1.08,285.06],[1,1.01,15.51],[2,1.08,0]],"ltp":1.15,"tv":284.56,"id":10894176},{"batb":[[0,7.4,10.54],[1,1.01,15.51],[2,7.4,0]],"batl":[[0,14,62.58],[1,14,0]],"ltp":8.8,"tv":109.91,"id":2263634}]}]}
{"op":"mcm","clk":"1008262281","pt":1580659202751,"mc":[{"id":"1.168224454","rc":[{"batb":[[0,1.12,970.43],[1,1.11,181.16],[2,1.08,285.06]],"batl":[[0,1.14,263.47],[1,1.15,726.09],[2,1.43,872.38]],"ltp":1.15,"tv":284.56,"id":10894176}]}]}
{"op":"mcm","clk":"1008262727","pt":1580659204837,"mc":[{"id":"1.168224454","rc":[{"batl":[[0,17,57.33]],"ltp":8.8,"tv":109.91,"id":2263634}]}]}
{"op":"mcm","clk":"1008263222","pt":1580659207134,"mc":[{"id":"1.168224454","rc":[{"batb":[[0,1.08,285.06],[1,1.01,15.51],[2,1.08,0]],"batl":[[0,1.43,872.38],[1,1.15,0],[2,1.43,0]],"ltp":1.15,"tv":284.56,"id":10894176}]}]}
{"op":"mcm","clk":"1008263803","pt":1580659210047,"mc":[{"id":"1.168224454","rc":[{"batb":[[0,1.1,996.46],[1,1.08,285.06],[2,1.01,15.51]],"batl":[[0,1.17,676.32],[1,1.18,420.92],[2,1.43,872.38]],"ltp":1.15,"tv":284.56,"id":10894176}]}]}
{"op":"mcm","clk":"1008264286","pt":1580659212638,"mc":[{"id":"1.168224454","rc":[{"batl":[[0,1.43,872.38],[1,1.18,0],[2,1.43,0]],"ltp":1.15,"tv":284.56,"id":10894176}]}]}
{"op":"mcm","clk":"1008264976","pt":1580659216223,"mc":[{"id":"1.168224454","rc":[{"batb":[[2,1.05,476.97]],"batl":[[0,1.12,571.3],[1,1.13,573.56],[2,1.43,872.38]],"ltp":1.15,"tv":284.56,"id":10894176},{"batb":[[0,9.4,15.26],[1,8,8.66],[2,7.4,10.54]],"ltp":8.8,"tv":109.91,"id":2263634}]}]}
{"op":"mcm","clk":"1008265022","pt":1580659216588,"mc":[{"id":"1.168224454","rc":[{"batb":[[1,8.8,5.04],[2,8,8.66]],"batl":[[0,11.5,3.36]],"ltp":8.8,"tv":109.91,"id":2263634}]}]}
{"op":"mcm","clk":"1008265325","pt":1580659218013,"mc":[{"id":"1.168224454","rc":[{"batl":[[1,21,53.48]],"ltp":8.8,"tv":109.91,"id":2263634}]}]}
{"op":"mcm","clk":"1008267137","pt":1580659227352,"mc":[{"id":"1.168224454","rc":[{"batb":[[0,1.05,476.97],[1,1.01,15.51],[2,1.05,0]],"batl":[[0,1.43,872.38],[1,1.13,0],[2,1.43,0]],"ltp":1.15,"tv":284.56,"id":10894176},{"batb":[[0,8.8,5.04],[1,8,8.66],[2,1.01,15.51]],"ltp":8.8,"tv":109.91,"id":2263634}]}]}
{"op":"mcm","clk":"1008267155","pt":1580659227523,"mc":[{"id":"1.168224454","rc":[{"batb":[[0,8,8.66],[1,1.01,15.51],[2,1.01,0]],"batl":[[0,21,53.48],[1,21,0]],"ltp":8.8,"tv":109.91,"id":2263634}]}]}
{"op":"mcm","clk":"1008267894","pt":1580659231391,"mc":[{"id":"1.168224454","rc":[{"batb":[[0,1.09,1181.64],[1,1.05,476.97],[2,1.01,15.51]],"batl":[[0,1.11,495.94],[1,1.12,658.47],[2,1.43,872.38]],"ltp":1.15,"tv":284.56,"id":10894176}]}]}
{"op":"mcm","clk":"1008268158","pt":1580659232679,"mc":[{"id":"1.168224454","rc":[{"batb":[[0,1.05,476.97],[1,1.01,15.51],[2,1.01,0]],"batl":[[0,1.43,872.38],[1,1.12,0],[2,1.43,0]],"ltp":1.15,"tv":284.56,"id":10894176}]}]}
{"op":"mcm","clk":"1008268634","pt":1580659235576,"mc":[{"id":"1.168224454","rc":[{"batb":[[0,1.06,1215.08],[1,1.05,476.97],[2,1.01,15.51]],"batl":[[0,1.15,665.71],[1,1.16,450.35]],"ltp":1.15,"tv":284.56,"id":10894176}]}]}
{"op":"mcm","clk":"1008270489","pt":1580659246418,"mc":[{"id":"1.168224454","rc":[{"batb":[[0,1.06,1383.12]],"batl":[[0,1.08,1192.58]],"ltp":1.15,"tv":284.56,"id":10894176}]}]}
{"op":"mcm","clk":"1008270569","pt":1580659246905,"mc":[{"id":"1.168224454","rc":[{"batb":[[0,13.5,6.45],[1,13,3.36],[2,9.6,14.95]],"ltp":8.8,"tv":109.91,"id":2263634}]}]}
{"op":"mcm","clk":"1008270759","pt":1580659248194,"mc":[{"id":"1.168224454","rc":[{"batl":[[1,1.35,1057.18]],"ltp":1.15,"tv":284.56,"id":10894176},{"batl":[[0,30,47.16]],"ltp":8.8,"tv":109.91,"id":2263634}]}]}
{"op":"mcm","clk":"1008273164","pt":1580659261425,"mc":[{"id":"1.168224454","rc":[{"batb":[[0,1.06,168.04],[1,1.01,15.51],[2,1.01,0]],"batl":[[0,1.35,1057.18],[1,1.35,0]],"ltp":1.15,"tv":284.56,"id":10894176},{"batb":[[0,13,3.36],[1,9.6,14.95],[2,1.01,15.51]],"ltp":8.8,"tv":109.91,"id":2263634}]}]}
{"op":"mcm","clk":"1008273254","pt":1580659262033,"mc":[{"id":"1.168224454","rc":[{"batb":[[0,1.01,15.51],[1,1.01,0]],"ltp":1.15,"tv":284.56,"id":10894176},{"batb":[[0,9.6,14.95],[1,1.01,15.51],[2,1.01,0]],"ltp":8.8,"tv":109.91,"id":2263634}]}]}
{"op":"mcm","clk":"1008273607","pt":1580659264239,"mc":[{"id":"1.168224454","rc":[{"batl":[[0,1.12,710.49],[1,1.13,435.6]],"ltp":1.15,"tv":284.56,"id":10894176}]}]}
{"op":"mcm","clk":"1008274088","pt":1580659267148,"mc":[{"id":"1.168224454","rc":[{"batb":[[0,1.1,833.41],[1,1.09,340.58],[2,1.01,15.51]],"ltp":1.15,"tv":284.56,"id":10894176}]}]}
{"op":"mcm","clk":"1008274290","pt":1580659268403,"mc":[{"id":"1.168224454","rc":[{"batb":[[2,1.08,293.33]],"ltp":1.15,"tv":284.56,"id":10894176},{"batb":[[1,9.2,5.04],[2,8.2,8.26]],"batl":[[0,11.5,3.36]],"ltp":8.8,"tv":109.91,"id":2263634}]}]}
{"op":"mcm","clk":"1008274470","pt":1580659269422,"mc":[{"id":"1.168224454","rc":[{"batl":[[2,1.38,972.97]],"ltp":1.15,"tv":284.56,"id":10894176},{"batl":[[1,21,53.48]],"ltp":8.8,"tv":109.91,"id":2263634}]}]}
{"op":"mcm","clk":"1008275706","pt":1580659276363,"mc":[{"id":"1.168224454","rc":[{"batb":[[0,1.05,484.29],[1,1.01,15.51],[2,1.08,0]],"batl":[[0,1.38,972.97],[1,1.13,0],[2,1.38,0]],"ltp":1.15,"tv":284.56,"id":10894176},{"batb":[[0,9.2,5.04],[1,8.2,8.26],[2,1.01,15.51]],"ltp":8.8,"tv":109.91,"id":2263634}]}]}
{"op":"mcm","clk":"1008275933","pt":1580659277668,"mc":[{"id":"1.168224454","rc":[{"batb":[[0,8.2,8.26],[1,1.01,15.51],[2,1.01,0]],"batl":[[0,21,53.48],[1,21,0]],"ltp":8.8,"tv":109.91,"id":2263634}]}]}
{"op":"mcm","clk":"1008276122","pt":1580659278627,"mc":[{"id":"1.168224454","rc":[{"batb":[[0,1.06,1215.08],[1,1.05,484.29],[2,1.01,15.51]],"batl":[[0,1.15,755.93],[1,1.16,360.91],[2,1.38,972.97]],"ltp":1.15,"tv":284.56,"id":10894176}]}]}
{"op":"mcm","clk":"1008276410","pt":1580659280133,"mc":[{"id":"1.168224454","rc":[{"batb":[[0,1.05,484.29],[1,1.01,15.51],[2,1.01,0]],"ltp":1.15,"tv":284.56,"id":10894176}]}]}
{"op":"mcm","clk":"1008276909","pt":1580659283145,"mc":[{"id":"1.168224454","rc":[{"batb":[[0,1.13,262.76],[1,1.12,884.88],[2,1.05,484.29]],"ltp":1.15,"tv":284.56,"id":10894176}]}]}
{"op":"mcm","clk":"1008277136","pt":1580659284392,"mc":[{"id":"1.168224454","rc":[{"batb":[[1,1.12,1052.92],[2,1.1,237.38]],"batl":[[0,1.15,797.94]],"ltp":1.15,"tv":284.56,"id":10894176},{"batb":[[1,7.6,15.72],[2,1.01,15.51]],"batl":[[0,9.4,4.2]],"ltp":8.8,"tv":109.91,"id":2263634}]}]}
{"op":"mcm","clk":"1008277560","pt":1580659286799,"mc":[{"id":"1.168224454","rc":[{"batl":[[1,14,62.58]],"ltp":8.8,"tv":109.91,"id":2263634}]}]}
{"op":"mcm","clk":"1008278890","pt":1580659294408,"mc":[{"id":"1.168224454","rc":[{"batb":[[0,1.12,168.04],[1,1.08,306.7],[2,1.01,15.51]],"batl":[[0,1.15,42.01],[1,1.16,196.32]],"ltp":1.15,"tv":284.56,"id":10894176},{"batb":[[0,7.6,15.72],[1,1.01,15.51],[2,1.01,0]],"ltp":8.8,"tv":109.91,"id":2263634}]}]}
{"op":"mcm","clk":"1008279261","pt":1580659296121,"mc":[{"id":"1.168224454","rc":[{"batb":[[0,1.08,306.7],[1,1.01,15.51],[2,1.01,0]],"batl":[[0,1.16,196.32],[1,1.38,972.97],[2,1.38,0]],"ltp":1.15,"tv":284.56,"id":10894176},{"batb":[[0,7.6,9.84]],"batl":[[0,14,62.58],[1,14,0]],"ltp":8.8,"tv":109.91,"id":2263634}]}]}
{"op":"mcm","clk":"1008279476","pt":1580659297246,"mc":[{"id":"1.168224454","rc":[{"batb":[[0,1.1,690.06],[1,1.09,485.24],[2,1.08,306.7]],"batl":[[1,1.17,632.65],[2,1.38,972.97]],"ltp":1.15,"tv":284.56,"id":10894176}]}]}
{"op":"mcm","clk":"1008281287","pt":1580659306377,"mc":[{"id":"1.168224454","rc":[{"batb":[[0,1.08,306.7],[1,1.01,15.51],[2,1.08,0]],"batl":[[0,1.38,972.97],[1,1.17,0],[2,1.38,0]],"ltp":1.15,"tv":284.56,"id":10894176}]}]}
{"op":"mcm","clk":"1008281742","pt":1580659308836,"mc":[{"id":"1.168224454","rc":[{"batb":[[0,1.12,736.5],[1,1.11,417.2],[2,1.08,306.7]],"batl":[[0,1.14,464.45],[1,1.15,659.57],[2,1.38,972.97]],"ltp":1.15,"tv":284.56,"id":10894176}]}]}
{"op":"mcm","clk":"1008282200","pt":1580659311393,"mc":[{"id":"1.168224454","rc":[{"batb":[[0,1.08,306.7],[1,1.01,15.51],[2,1.08,0]],"batl":[[0,1.38,972.97],[1,1.15,0],[2,1.38,0]],"ltp":1.15,"tv":284.56,"id":10894176}]}]}
{"op":"mcm","clk":"1008282329","pt":1580659312041,"mc":[{"id":"1.168224454","rc":[{"batl":[[0,17,57.33]],"ltp":8.8,"tv":109.91,"id":2263634}]}]}
{"op":"mcm","clk":"1008282713","pt":1580659314362,"mc":[{"id":"1.168224454","rc":[{"batb":[[0,1.1,707.38],[1,1.09,467.76],[2,1.08,306.7]],"batl":[[0,1.16,179.79],[1,1.17,632.67],[2,1.38,972.97]],"ltp":1.15,"tv":284.56,"id":10894176}]}]}
{"op":"mcm","clk":"1008282895","pt":1580659315237,"mc":[{"id":"1.168224454","rc":[{"batl":[[0,1.38,972.97],[1,1.17,0],[2,1.38,0]],"ltp":1.15,"tv":284.56,"id":10894176}]}]}
{"op":"mcm","clk":"1008283515","pt":1580659318394,"mc":[{"id":"1.168224454","rc":[{"batl":[[0,1.12,812.54],[1,1.13,334.45],[2,1.38,972.97]],"ltp":1.15,"tv":284.56,"id":10894176}]}]}
{"op":"mcm","clk":"1008283711","pt":1580659319211,"mc":[{"id":"1.168224454","rc":[{"batb":[[2,1.08,306.23]],"batl":[[0,1.12,854.55]],"ltp":1.15,"tv":284.56,"id":10894176},{"batb":[[0,9.8,13.93],[1,9,5.04],[2,8.4,8.03]],"batl":[[0,11.5,3.36]],"ltp":8.8,"tv":109.91,"id":2263634}]}]}
{"op":"mcm","clk":"1008284065","pt":1580659321095,"mc":[{"id":"1.168224454","rc":[{"batl":[[1,21,53.48]],"ltp":8.8,"tv":109.91,"id":2263634}]}]}
{"op":"mcm","clk":"1008285913","pt":1580659330420,"mc":[{"id":"1.168224454","rc":[{"batb":[[0,1.08,306.23],[1,1.04,498.14],[2,1.01,15.51]],"batl":[[0,1.12,42.01],[1,1.38,972.97],[2,1.38,0]],"ltp":1.15,"tv":284.56,"id":10894176}]}]}
{"op":"mcm","clk":"1008285973","pt":1580659330731,"mc":[{"id":"1.168224454","rc":[{"batb":[[0,1.04,498.14],[1,1.01,15.51],[2,1.01,0]],"ltp":1.15,"tv":284.56,"id":10894176},{"batb":[[0,9,5.04],[1,8.4,8.03],[2,1.01,15.51]],"ltp":8.8,"tv":109.91,"id":2263634}]}]}
{"op":"mcm","clk":"1008286128","pt":1580659331485,"mc":[{"id":"1.168224454","rc":[{"batl":[[0,1.38,972.97],[1,1.38,0]],"ltp":1.15,"tv":284.56,"id":10894176},{"batb":[[0,8.4,8.03],[1,1.01,15.51],[2,1.01,0]],"batl":[[0,21,53.48],[1,21,0]],"ltp":8.8,"tv":109.91,"id":2263634}]}]}
{"op":"mcm","clk":"1008287047","pt":1580659336348,"mc":[{"id":"1.168224454","rc":[{"batb":[[0,1.09,1034.35],[1,1.04,498.14],[2,1.01,15.51]],"batl":[[0,1.11,747.34],[1,1.12,409.32],[2,1.38,972.97]],"ltp":1.15,"tv":284.56,"id":10894176}]}]}
{"op":"mcm","clk":"1008287231","pt":1580659337338,"mc":[{"id":"1.168224454","rc":[{"batl":[[0,1.11,628.56]],"ltp":1.15,"tv":284.56,"id":10894176}]}]}
{"op":"mcm","clk":"1008287318","pt":1580659337734,"mc":[{"id":"1.168224454","rc":[{"batb":[[0,1.04,498.14],[1,1.01,15.51],[2,1.01,0]],"batl":[[0,1.38,972.97],[1,1.12,0],[2,1.38,0]],"ltp":1.15,"tv":284.56,"id":10894176}]}]}
{"op":"mcm","clk":"1008287828","pt":1580659340367,"mc":[{"id":"1.168224454","rc":[{"batb":[[0,1.06,1215.08],[1,1.04,498.14],[2,1.01,15.51]],"batl":[[0,1.15,729.71],[1,1.16,386.91]],"ltp":1.15,"tv":284.56,"id":10894176}]}]}
{"op":"mcm","clk":"1008288867","pt":1580659346421,"mc":[{"id":"1.168224454","rc":[{"batb":[[0,1.04,498.14],[1,1.01,15.51],[2,1.01,0]],"ltp":1.15,"tv":284.56,"id":10894176}]}]}
{"op":"mcm","clk":"1008289316","pt":1580659349338,"mc":[{"id":"1.168224454","rc":[{"batb":[[0,1.13,278.71],[1,1.12,868.78],[2,1.04,498.14]],"ltp":1.15,"tv":284.56,"id":10894176}]}]}
{"op":"mcm","clk":"1008289684","pt":1580659351386,"mc":[{"id":"1.168224454","rc":[{"batb":[[2,1.1,241.32]],"batl":[[0,1.15,771.72],[2,1.4,927.7]],"ltp":1.15,"tv":284.56,"id":10894176},{"batb":[[1,7.8,15.56],[2,1.01,15.51]],"batl":[[0,9.6,4.2],[1,17,57.33]],"ltp":8.8,"tv":109.91,"id":2263634}]}]}
{"op":"mcm","clk":"1008291297","pt":1580659360357,"mc":[{"id":"1.168224454","rc":[{"batb":[[0,1.08,308.98],[1,1.01,15.51],[2,1.1,0]],"batl":[[0,1.15,42.01],[1,1.4,927.7],[2,1.4,0]],"ltp":1.15,"tv":284.56,"id":10894176},{"batb":[[0,7.8,15.56],[1,1.01,15.51],[2,1.01,0]],"ltp":8.8,"tv":109.91,"id":2263634}]}]}
{"op":"mcm","clk":"1008291488","pt":1580659361529,"mc":[{"id":"1.168224454","rc":[{"batl":[[0,1.4,927.7],[1,1.4,0]],"ltp":1.15,"tv":284.56,"id":10894176},{"batb":[[0,7.8,9.68]],"batl":[[0,17,57.33],[1,17,0]],"ltp":8.8,"tv":109.91,"id":2263634}]}]}
{"op":"mcm","clk":"1008291814","pt":1580659363243,"mc":[{"id":"1.168224454","rc":[{"batb":[[0,1.1,671.91],[1,1.09,503.56],[2,1.08,308.98]],"batl":[[0,1.17,776.29],[1,1.18,321.8],[2,1.4,927.7]],"ltp":1.15,"tv":284.56,"id":10894176}]}]}
{"op":"mcm","clk":"1008292894","pt":1580659369063,"mc":[{"id":"1.168224454","rc":[{"batl":[[0,1.4,927.7],[1,1.18,0],[2,1.4,0]],"ltp":1.15,"tv":284.56,"id":10894176}]}]}
{"op":"mcm","clk":"1008293497","pt":1580659372305,"mc":[{"id":"1.168224454","rc":[{"batl":[[0,1.12,826.31],[1,1.13,320.81],[2,1.4,927.7]],"ltp":1.15,"tv":284.56,"id":10894176}]}]}
{"op":"mcm","clk":"1008293670","pt":1580659373151,"mc":[{"id":"1.168224454","rc":[{"batl":[[0,1.12,868.32]],"ltp":1.15,"tv":284.56,"id":10894176},{"batb":[[0,10,13.69],[1,9.2,5.04],[2,8.6,7.63]],"batl":[[0,11.5,3.36]],"ltp":8.8,"tv":109.91,"id":2263634}]}]}
{"op":"mcm","clk":"1008294133","pt":1580659375556,"mc":[{"id":"1.168224454","rc":[{"batl":[[1,21,53.48]],"ltp":8.8,"tv":109.91,"id":2263634}]}]}
{"op":"mcm","clk":"1008296074","pt":1580659385394,"mc":[{"id":"1.168224454","rc":[{"batb":[[0,1.04,509.78],[1,1.01,15.51],[2,1.08,0]],"batl":[[0,1.12,42.01],[1,1.4,927.7],[2,1.4,0]],"ltp":1.15,"tv":284.56,"id":10894176},{"batb":[[0,9.2,5.04],[1,8.6,7.63],[2,1.01,15.51]],"ltp":8.8,"tv":109.91,"id":2263634}]}]}
{"op":"mcm","clk":"1008296118","pt":1580659385593,"mc":[{"id":"1.168224454","rc":[{"batl":[[0,1.4,927.7],[1,1.4,0]],"ltp":1.15,"tv":284.56,"id":10894176},{"batb":[[0,8.6,7.63],[1,1.01,15.51],[2,1.01,0]],"batl":[[0,21,53.48],[1,21,0]],"ltp":8.8,"tv":109.91,"id":2263634}]}]}
{"op":"mcm","clk":"1008296627","pt":1580659388075,"mc":[{"id":"1.168224454","rc":[{"batb":[[0,1.06,1215.08],[1,1.04,509.78],[2,1.01,15.51]],"batl":[[0,1.15,830.92],[1,1.16,286.57],[2,1.4,927.7]],"ltp":1.15,"tv":284.56,"id":10894176}]}]}
{"op":"mcm","clk":"1008299955","pt":1580659405612,"mc":[{"id":"1.168224454","rc":[{"batl":[[0,1.4,927.7],[1,1.16,0],[2,1.4,0]],"ltp":1.15,"tv":284.56,"id":10894176}]}]}
{"op":"mcm","clk":"1008300749","pt":1580659409231,"mc":[{"id":"1.168224454","rc":[{"batl":[[0,1.08,1192.58]],"ltp":1.15,"tv":284.56,"id":10894176},{"batb":[[0,14.5,5.74],[1,10,13.3],[2,8.6,7.63]],"ltp":8.8,"tv":109.91,"id":2263634}]}]}
{"op":"mcm","clk":"1008300801","pt":1580659409513,"mc":[{"id":"1.168224454","rc":[{"batb":[[2,1.01,15.51]],"ltp":8.8,"tv":109.91,"id":2263634}]}]}
{"op":"mcm","clk":"1008301008","pt":1580659410514,"mc":[{"id":"1.168224454","rc":[{"batb":[[0,1.06,1383.12]],"batl":[[0,1.08,1234.59]],"ltp":1.15,"tv":284.56,"id":10894176},{"batb":[[1,13,3.36],[2,10,13.3]],"ltp":8.8,"tv":109.91,"id":2263634}]}]}
{"op":"mcm","clk":"1008301328","pt":1580659412221,"mc":[{"id":"1.168224454","rc":[{"batl":[[1,1.34,1109.8]],"ltp":1.15,"tv":284.56,"id":10894176},{"batl":[[0,42,43.68]],"ltp":8.8,"tv":109.91,"id":2263634}]}]}
{"op":"mcm","clk":"1008303815","pt":1580659425364,"mc":[{"id":"1.168224454","rc":[{"batb":[[0,1.06,168.04],[1,1.01,15.51],[2,1.01,0]],"batl":[[0,1.08,42.01]],"ltp":1.15,"tv":284.56,"id":10894176},{"batb":[[0,13,3.36],[1,10,13.3],[2,1.01,15.51]],"ltp":8.8,"tv":109.91,"id":2263634}]}]}
{"op":"mcm","clk":"1008303877","pt":1580659425644,"mc":[{"id":"1.168224454","rc":[{"batb":[[0,1.01,15.51],[1,1.01,0]],"batl":[[0,1.34,1109.8],[1,1.34,0]],"ltp":1.15,"tv":284.56,"id":10894176},{"batb":[[0,10,13.3],[1,1.01,15.51],[2,1.01,0]],"ltp":8.8,"tv":109.91,"id":2263634}]}]}
{"op":"mcm","clk":"1008304399","pt":1580659428354,"mc":[{"id":"1.168224454","rc":[{"batl":[[0,1.12,946.03],[1,1.13,202.15]],"ltp":1.15,"tv":284.56,"id":10894176}]}]}
{"op":"mcm","clk":"1008304965","pt":1580659431385,"mc":[{"id":"1.168224454","rc":[{"batb":[[0,1.1,530.68],[1,1.09,646.08],[2,1.01,15.51]],"ltp":1.15,"tv":284.56,"id":10894176}]}]}
{"op":"mcm","clk":"1008305177","pt":1580659432291,"mc":[{"id":"1.168224454","rc":[{"batb":[[2,1.08,309.22]],"ltp":1.15,"tv":284.56,"id":10894176},{"batb":[[1,8.4,7.79],[2,1.01,15.51]],"ltp":8.8,"tv":109.91,"id":2263634}]}]}
{"op":"mcm","clk":"1008305314","pt":1580659432966,"mc":[{"id":"1.168224454","rc":[{"batl":[[0,1.12,988.04]],"ltp":1.15,"tv":284.56,"id":10894176},{"batb":[[1,9.4,4.2],[2,8.4,7.79]],"ltp":8.8,"tv":109.91,"id":2263634}]}]}
{"op":"mcm","clk":"1008305627","pt":1580659434770,"mc":[{"id":"1.168224454","rc":[{"batl":[[2,1.38,972.97]],"ltp":1.15,"tv":284.56,"id":10894176},{"batl":[[0,21,53.48]],"ltp":8.8,"tv":109.91,"id":2263634}]}]}
{"op":"mcm","clk":"1008306101","pt":1580659437482,"mc":[{"id":"1.168224454","rc":[{"batb":[[1,1.09,814.12]],"ltp":1.15,"tv":284.56,"id":10894176},{"batl":[[0,12,3.36],[1,21,53.48]],"ltp":8.8,"tv":109.91,"id":2263634}]}]}
{"op":"mcm","clk":"1008308433","pt":1580659450355,"mc":[{"id":"1.168224454","rc":[{"batb":[[0,1.09,168.04],[1,1.04,512.22],[2,1.01,15.51]],"batl":[[0,1.12,42.01],[1,1.38,972.97],[2,1.38,0]],"ltp":1.15,"tv":284.56,"id":10894176},{"batb":[[0,9.4,4.2],[1,8.4,7.79],[2,1.01,15.51]],"ltp":8.8,"tv":109.91,"id":2263634}]}]}
{"op":"mcm","clk":"1008308680","pt":1580659451538,"mc":[{"id":"1.168224454","rc":[{"batb":[[0,1.04,512.22],[1,1.01,15.51],[2,1.01,0]],"batl":[[0,1.38,972.97],[1,1.38,0]],"ltp":1.15,"tv":284.56,"id":10894176},{"batb":[[0,8.4,7.79],[1,1.01,15.51],[2,1.01,0]],"batl":[[0,21,53.48],[1,21,0]],"ltp":8.8,"tv":109.91,"id":2263634}]}]}
{"op":"mcm","clk":"1008308881","pt":1580659452548,"mc":[{"id":"1.168224454","rc":[{"batb":[[0,1.06,1040.57],[1,1.04,512.22],[2,1.01,15.51]],"batl":[[0,1.14,205.1],[1,1.15,721.36],[2,1.38,972.97]],"ltp":1.15,"tv":284.56,"id":10894176}]}]}
{"op":"mcm","clk":"1008309735","pt":1580659457256,"mc":[{"id":"1.168224454","rc":[{"batb":[[0,1.04,512.22],[1,1.01,15.51],[2,1.01,0]],"ltp":1.15,"tv":284.56,"id":10894176}]}]}
{"op":"mcm","clk":"1008310300","pt":1580659460435,"mc":[{"id":"1.168224454","rc":[{"batb":[[0,1.12,1018.15],[1,1.1,245.96],[2,1.08,314.65]],"batl":[[1,1.15,763.37]],"ltp":1.15,"tv":284.56,"id":10894176},{"batb":[[1,7.8,15.32],[2,1.01,15.51]],"batl":[[0,9.8,4.2]],"ltp":8.8,"tv":109.91,"id":2263634}]}]}
{"op":"mcm","clk":"1008310673","pt":1580659462638,"mc":[{"id":"1.168224454","rc":[{"batl":[[1,17,57.33]],"ltp":8.8,"tv":109.91,"id":2263634}]}]}
{"op":"mcm","clk":"1008313708","pt":1580659479346,"mc":[{"id":"1.168224454","rc":[{"batb":[[0,1.08,314.65],[1,1.01,15.51],[2,1.08,0]],"batl":[[0,1.15,42.01],[1,1.38,972.97],[2,1.38,0]],"ltp":1.15,"tv":284.56,"id":10894176},{"batb":[[0,7.8,15.32],[1,1.01,15.51],[2,1.01,0]],"ltp":8.8,"tv":109.91,"id":2263634}]}]}
{"op":"mcm","clk":"1008313760","pt":1580659479667,"mc":[{"id":"1.168224454","rc":[{"batl":[[0,1.38,972.97],[1,1.38,0]],"ltp":1.15,"tv":284.56,"id":10894176},{"batb":[[0,7.8,9.44]],"batl":[[0,17,57.33],[1,17,0]],"ltp":8.8,"tv":109.91,"id":2263634}]}]}
{"op":"mcm","clk":"1008314614","pt":1580659483859,"mc":[{"id":"1.168224454","rc":[{"batb":[[0,1.12,485.41],[1,1.11,670.55],[2,1.08,314.65]],"batl":[[0,1.14,669.86],[1,1.15,455.94],[2,1.38,972.97]],"ltp":1.15,"tv":284.56,"id":10894176}]}]}
{"op":"mcm","clk":"1008315103","pt":1580659486365,"mc":[{"id":"1.168224454","rc":[{"batb":[[0,1.08,314.65],[1,1.01,15.51],[2,1.08,0]],"batl":[[0,1.38,972.97],[1,1.15,0],[2,1.38,0]],"ltp":1.15,"tv":284.56,"id":10894176}]}]}
{"op":"mcm","clk":"1008315564","pt":1580659488823,"mc":[{"id":"1.168224454","rc":[{"batb":[[0,1.1,382.78],[1,1.09,795.34],[2,1.08,314.65]],"batl":[[0,1.16,310.12],[1,1.17,621.72],[2,1.38,972.97]],"ltp":1.15,"tv":284.56,"id":10894176}]}]}
{"op":"mcm","clk":"1008316273","pt":1580659492028,"mc":[{"id":"1.168224454","rc":[{"batl":[[0,1.38,972.97],[1,1.17,0],[2,1.38,0]],"ltp":1.15,"tv":284.56,"id":10894176}]}]}
{"op":"mcm","clk":"1008316880","pt":1580659495246,"mc":[{"id":"1.168224454","rc":[{"batl":[[0,1.12,1071.39],[1,1.38,972.97]],"ltp":1.15,"tv":284.56,"id":10894176}]}]}
{"op":"mcm","clk":"1008317065","pt":1580659496257,"mc":[{"id":"1.168224454","rc":[{"batb":[[0,10,13.3],[1,8.6,7.55],[2,1.01,15.51]],"ltp":8.8,"tv":109.91,"id":2263634}]}]}
{"op":"mcm","clk":"1008317147","pt":1580659496645,"mc":[{"id":"1.168224454","rc":[{"batb":[[1,1.09,963.38]],"batl":[[0,1.12,1113.4]],"ltp":1.15,"tv":284.56,"id":10894176},{"batb":[[1,9.2,5.04],[2,8.6,7.55]],"batl":[[0,12,3.36]],"ltp":8.8,"tv":109.91,"id":2263634}]}]}
{"op":"mcm","clk":"1008317425","pt":1580659498148,"mc":[{"id":"1.168224454","rc":[{"batl":[[1,21,53.48]],"ltp":8.8,"tv":109.91,"id":2263634}]}]}
{"op":"mcm","clk":"1008318838","pt":1580659505362,"mc":[{"id":"1.168224454","rc":[{"batb":[[0,1.09,168.04],[1,1.08,314.65],[2,1.04,523.86]],"batl":[[0,1.12,42.01]],"ltp":1.15,"tv":284.56,"id":10894176}]}]}
{"op":"mcm","clk":"1008318968","pt":1580659506057,"mc":[{"id":"1.168224454","rc":[{"batb":[[0,1.04,523.86],[1,1.01,15.51],[2,1.04,0]],"batl":[[0,1.38,972.97],[1,1.38,0]],"ltp":1.15,"tv":284.56,"id":10894176},{"batb":[[0,8.6,7.55],[1,1.01,15.51],[2,8.6,0]],"batl":[[0,21,53.48],[1,21,0]],"ltp":8.8,"tv":109.91,"id":2263634}]}]}
{"op":"mcm","clk":"1008319375","pt":1580659508142,"mc":[{"id":"1.168224454","rc":[{"batb":[[0,1.06,853.49],[1,1.05,365.03],[2,1.04,523.86]],"batl":[[0,1.14,309.16],[1,1.15,716.03],[2,1.38,972.97]],"ltp":1.15,"tv":284.56,"id":10894176}]}]}
{"op":"mcm","clk":"1008323241","pt":1580659527401,"mc":[{"id":"1.168224454","rc":[{"batb":[[0,1.04,523.86],[1,1.01,15.51],[2,1.04,0]],"ltp":1.15,"tv":284.56,"id":10894176}]}]}
{"op":"mcm","clk":"1008323865","pt":1580659530431,"mc":[{"id":"1.168224454","rc":[{"batb":[[0,1.12,898.77],[1,1.11,253.47],[2,1.04,523.86]],"ltp":1.15,"tv":284.56,"id":10894176}]}]}
{"op":"mcm","clk":"1008324065","pt":1580659531313,"mc":[{"id":"1.168224454","rc":[{"batb":[[1,1.11,421.51],[2,1.1,250.84]],"ltp":1.15,"tv":284.56,"id":10894176},{"batb":[[1,8,5.88],[2,7.8,9.28]],"ltp":8.8,"tv":109.91,"id":2263634}]}]}
{"op":"mcm","clk":"1008324395","pt":1580659533091,"mc":[{"id":"1.168224454","rc":[{"batl":[[0,9.8,4.2]],"ltp":8.8,"tv":109.91,"id":2263634}]}]}
{"op":"mcm","clk":"1008324490","pt":1580659533652,"mc":[{"id":"1.168224454","rc":[{"batl":[[1,17,57.33]],"ltp":8.8,"tv":109.91,"id":2263634}]}]}
{"op":"mcm","clk":"1008328015","pt":1580659551356,"mc":[{"id":"1.168224454","rc":[{"batb":[[0,1.11,168.04],[1,1.1,250.84],[2,1.07,318.98]],"batl":[[0,1.38,972.97],[1,1.15,0],[2,1.38,0]],"ltp":1.15,"tv":284.56,"id":10894176}]}]}
{"op":"mcm","clk":"1008328076","pt":1580659551684,"mc":[{"id":"1.168224454","rc":[{"batb":[[0,1.07,318.98],[1,1.01,15.51],[2,1.07,0]],"ltp":1.15,"tv":284.56,"id":10894176},{"batb":[[0,7.8,9.28],[1,1.01,15.51],[2,7.8,0]],"batl":[[0,17,57.33],[1,17,0]],"ltp":8.8,"tv":109.91,"id":2263634}]}]}
{"op":"mcm","clk":"1008328601","pt":1580659554369,"mc":[{"id":"1.168224454","rc":[{"batb":[[0,1.1,236.38],[1,1.09,943.09],[2,1.07,318.98]],"batl":[[0,1.16,393.57],[1,1.17,618.22],[2,1.38,972.97]],"ltp":1.15,"tv":284.56,"id":10894176}]}]}
{"op":"mcm","clk":"1008330698","pt":1580659564902,"mc":[{"id":"1.168224454","rc":[{"batb":[[0,1.07,318.98],[1,1.01,15.51],[2,1.07,0]],"ltp":1.15,"tv":284.56,"id":10894176}]}]}
{"op":"mcm","clk":"1008331444","pt":1580659568287,"mc":[{"id":"1.168224454","rc":[{"batb":[[0,1.14,486.79],[1,1.13,600.44],[2,1.11,2491.31]],"ltp":1.15,"tv":284.56,"id":10894176}]}]}
{"op":"mcm","clk":"1008331526","pt":1580659568667,"mc":[{"id":"1.168224454","rc":[{"batb":[[1,1.13,768.48],[2,1.11,220.39]],"ltp":1.15,"tv":284.56,"id":10894176},{"batb":[[1,7,6.72],[2,5.2,12.12]],"batl":[[0,8.6,5.04]],"ltp":8.8,"tv":109.91,"id":2263634}]}]}
{"op":"mcm","clk":"1008332068","pt":1580659571284,"mc":[{"id":"1.168224454","rc":[{"batb":[[1,1.13,816.75]],"batl":[[0,1.16,440.59]],"ltp":1.15,"tv":284.56,"id":10894176}]}]}
{"op":"mcm","clk":"1008332223","pt":1580659571992,"mc":[{"id":"1.168224454","rc":[{"batl":[[1,14,62.58]],"ltp":8.8,"tv":109.91,"id":2263634}]}]}
{"op":"mcm","clk":"1008350525","pt":1580659658822,"mc":[{"id":"1.168224454","rc":[{"batb":[[0,1.13,168.04],[1,1.07,318.74],[2,1.01,15.51]],"batl":[[0,1.38,972.97],[1,1.17,0],[2,1.38,0]],"ltp":1.15,"tv":284.56,"id":10894176},{"batb":[[0,7,6.72],[1,5.2,12.12],[2,1.01,15.51]],"ltp":8.8,"tv":109.91,"id":2263634}]}]}
{"op":"mcm","clk":"1008350799","pt":1580659659907,"mc":[{"id":"1.168224454","rc":[{"batb":[[0,1.07,318.74],[1,1.01,15.51],[2,1.01,0]],"ltp":1.15,"tv":284.56,"id":10894176},{"batb":[[0,5.2,12.12],[1,1.01,15.51],[2,1.01,0]],"batl":[[0,14,62.58],[1,14,0]],"ltp":8.8,"tv":109.91,"id":2263634}]}]}
{"op":"mcm","clk":"1008351131","pt":1580659661428,"mc":[{"id":"1.168224454","rc":[{"batb":[[0,1.1,740.68],[1,1.09,434.16],[2,1.07,318.74]],"batl":[[0,1.26,515.16],[1,1.27,358.31],[2,1.38,972.97]],"ltp":1.15,"tv":284.56,"id":10894176}]}]}
{"op":"mcm","clk":"1008351343","pt":1580659662362,"mc":[{"id":"1.168224454","rc":[{"batb":[[0,1.1,515.66],[1,1.09,661.24]],"batl":[[0,1.15,2.53],[1,1.25,331.19],[2,1.26,384.45]],"ltp":1.15,"tv":284.56,"id":10894176}]}]}
{"op":"mcm","clk":"1008351511","pt":1580659663112,"mc":[{"id":"1.168224454","rc":[{"batl":[[1,1.38,972.97],[2,1.26,0]],"ltp":1.15,"tv":284.56,"id":10894176}]}]}
{"op":"mcm","clk":"1008352284","pt":1580659666437,"mc":[{"id":"1.168224454","rc":[{"batl":[[0,1.12,1001],[1,1.15,2.53],[2,1.38,972.97]],"ltp":1.15,"tv":284.56,"id":10894176},{"batb":[[0,10,12.98],[1,7,12.43],[2,5.2,12.12]],"ltp":8.8,"tv":109.91,"id":2263634}]}]}
{"op":"mcm","clk":"1008352355","pt":1580659666763,"mc":[{"id":"1.168224454","rc":[{"batb":[[1,8.8,5.04],[2,7,12.43]],"batl":[[0,11.5,3.36]],"ltp":8.8,"tv":109.91,"id":2263634}]}]}
{"op":"mcm","clk":"1008352763","pt":1580659668692,"mc":[{"id":"1.168224454","rc":[{"batl":[[1,21,53.48]],"ltp":8.8,"tv":109.91,"id":2263634}]}]}
{"op":"mcm","clk":"1008354300","pt":1580659675418,"mc":[{"id":"1.168224454","rc":[{"batb":[[0,1.05,450.22],[1,1.01,15.51],[2,1.07,0]],"batl":[[0,1.15,2.53],[1,1.38,972.97],[2,1.38,0]],"ltp":1.15,"tv":284.56,"id":10894176},{"batb":[[0,8.8,5.04],[1,7,12.43],[2,1.01,15.51]],"ltp":8.8,"tv":109.91,"id":2263634}]}]}
{"op":"mcm","clk":"1008354350","pt":1580659675664,"mc":[{"id":"1.168224454","rc":[{"batb":[[0,7,12.43],[1,1.01,15.51],[2,1.01,0]],"batl":[[0,21,53.48],[1,21,0]],"ltp":8.8,"tv":109.91,"id":2263634}]}]}
{"op":"mcm","clk":"1008355588","pt":1580659681364,"mc":[{"id":"1.168224454","rc":[{"batb":[[0,1.11,576.91],[1,1.1,588.73],[2,1.05,450.22]],"batl":[[0,1.13,772.44],[1,1.14,364.14],[2,1.15,2.53]],"ltp":1.15,"tv":284.56,"id":10894176}]}]}
{"op":"mcm","clk":"1008356359","pt":1580659685173,"mc":[{"id":"1.168224454","rc":[{"batb":[[0,1.05,450.22],[1,1.01,15.51],[2,1.05,0]],"batl":[[0,1.15,2.53],[1,1.38,972.97],[2,1.15,0]],"ltp":1.15,"tv":284.56,"id":10894176}]}]}
{"op":"mcm","clk":"1008357012","pt":1580659688112,"mc":[{"id":"1.168224454","rc":[{"batb":[[0,1.07,1203.73],[1,1.05,450.22],[2,1.01,15.51]],"batl":[[1,1.18,588.75],[2,1.19,498.53]],"ltp":1.15,"tv":284.56,"id":10894176}]}]}
{"op":"mcm","clk":"1008359522","pt":1580659699290,"mc":[{"id":"1.168224454","rc":[{"batb":[[0,1.05,450.22],[1,1.01,15.51],[2,1.01,0]],"ltp":1.15,"tv":284.56,"id":10894176}]}]}
{"op":"mcm","clk":"1008360160","pt":1580659702327,"mc":[{"id":"1.168224454","rc":[{"batb":[[0,1.15,911.82],[1,1.14,209.98],[2,1.05,450.22]],"batl":[[0,1.18,588.75],[1,1.19,498.53],[2,1.38,972.97]],"ltp":1.15,"tv":284.56,"id":10894176}]}]}
{"op":"mcm","clk":"1008360436","pt":1580659703388,"mc":[{"id":"1.168224454","rc":[{"batb":[[1,1.14,378.02],[2,1.13,185.69]],"batl":[[0,1.18,630.76]],"ltp":1.15,"tv":284.56,"id":10894176},{"batb":[[1,6.6,6.72],[2,4.3,18.73]],"batl":[[0,8,5.88]],"ltp":8.8,"tv":109.91,"id":2263634}]}]}
{"op":"mcm","clk":"1008360884","pt":1580659705384,"mc":[{"id":"1.168224454","rc":[{"batl":[[2,1.2,2.53]],"ltp":1.15,"tv":284.56,"id":10894176}]}]}
{"op":"mcm","clk":"1008361054","pt":1580659706191,"mc":[{"id":"1.168224454","rc":[{"batb":[[0,1.15,831.41]],"batl":[[1,1.19,420.76]],"ltp":1.15,"tv":284.56,"id":10894176},{"batl":[[1,12.5,65.97]],"ltp":8.8,"tv":109.91,"id":2263634}]}]}
{"op":"mcm","clk":"1008361696","pt":1580659708989,"mc":[{"id":"1.168224454","rc":[{"batb":[[1,1.14,459.14]],"batl":[[0,1.18,709.19]],"ltp":1.15,"tv":284.56,"id":10894176}]}]}
{"op":"mcm","clk":"1008364145","pt":1580659720330,"mc":[{"id":"1.168224454","rc":[{"batb":[[0,1.14,168.04],[1,1.08,294.19],[2,1.01,15.51]],"batl":[[0,1.18,42.01],[1,1.2,2.53],[2,1.38,972.97]],"ltp":1.15,"tv":284.56,"id":10894176},{"batb":[[0,6.6,6.72],[1,4.3,18.73],[2,1.01,15.51]],"ltp":8.8,"tv":109.91,"id":2263634}]}]}
{"op":"mcm","clk":"1008364432","pt":1580659721613,"mc":[{"id":"1.168224454","rc":[{"batb":[[0,1.08,294.19],[1,1.01,15.51],[2,1.01,0]],"batl":[[0,1.2,2.53],[1,1.38,972.97],[2,1.38,0]],"ltp":1.15,"tv":284.56,"id":10894176},{"batb":[[0,4.3,18.73],[1,1.01,15.51],[2,1.01,0]],"batl":[[0,12.5,65.97],[1,12.5,0]],"ltp":8.8,"tv":109.91,"id":2263634}]}]}
{"op":"mcm","clk":"1008364738","pt":1580659722931,"mc":[{"id":"1.168224454","rc":[{"batb":[[0,1.1,1023.99],[1,1.08,294.19],[2,1.01,15.51]],"batl":[[1,1.3,182.28],[2,1.31,314.48]],"ltp":1.15,"tv":284.56,"id":10894176}]}]}
{"op":"mcm","clk":"1008365955","pt":1580659728413,"mc":[{"id":"1.168224454","rc":[{"batl":[[1,1.38,972.97],[2,1.31,0]],"ltp":1.15,"tv":284.56,"id":10894176}]}]}
{"op":"mcm","clk":"1008366542","pt":1580659731068,"mc":[{"id":"1.168224454","rc":[{"batl":[[0,1.12,580.25],[1,1.13,564.69],[2,1.2,2.53]],"ltp":1.15,"tv":284.56,"id":10894176}]}]}
{"op":"mcm","clk":"1008366683","pt":1580659731639,"mc":[{"id":"1.168224454","rc":[{"batb":[[2,1.05,456.43]],"ltp":1.15,"tv":284.56,"id":10894176},{"batb":[[0,9.6,14.87],[1,6,16.68],[2,1.01,15.51]],"ltp":8.8,"tv":109.91,"id":2263634}]}]}
{"op":"mcm","clk":"1008366941","pt":1580659732746,"mc":[{"id":"1.168224454","rc":[{"batb":[[1,8.8,5.04],[2,6,16.68]],"batl":[[0,11,4.2]],"ltp":8.8,"tv":109.91,"id":2263634}]}]}
{"op":"mcm","clk":"1008367284","pt":1580659734436,"mc":[{"id":"1.168224454","rc":[{"batl":[[1,21,53.48]],"ltp":8.8,"tv":109.91,"id":2263634}]}]}
{"op":"mcm","clk":"1008370187","pt":1580659747744,"mc":[{"id":"1.168224454","rc":[{"batb":[[0,1.05,456.43],[1,1.01,15.51],[2,1.05,0]],"batl":[[0,1.2,2.53],[1,1.38,972.97],[2,1.2,0]],"ltp":1.15,"tv":284.56,"id":10894176},{"batb":[[0,8.8,5.04],[1,6,16.68],[2,1.01,15.51]],"ltp":8.8,"tv":109.91,"id":2263634}]}]}
{"op":"mcm","clk":"1008370642","pt":1580659749668,"mc":[{"id":"1.168224454","rc":[{"batb":[[0,6,16.68],[1,1.01,15.51],[2,1.01,0]],"batl":[[0,21,53.48],[1,21,0]],"ltp":8.8,"tv":109.91,"id":2263634}]}]}
{"op":"mcm","clk":"1008370823","pt":1580659750465,"mc":[{"id":"1.168224454","rc":[{"batb":[[0,1.07,921.29],[1,1.06,285.1],[2,1.05,456.43]],"batl":[[0,1.2,477.46],[1,1.21,493.46],[2,1.38,972.97]],"ltp":1.15,"tv":284.56,"id":10894176}]}]}
{"op":"mcm","clk":"1008371411","pt":1580659752671,"mc":[{"id":"1.168224454","rc":[{"batl":[[0,1.2,2.53],[1,1.38,972.97],[2,1.38,0]],"ltp":1.15,"tv":284.56,"id":10894176}]}]}
{"op":"mcm","clk":"1008372104","pt":1580659755915,"mc":[{"id":"1.168224454","rc":[{"batl":[[0,1.09,1181.64],[1,1.2,2.53],[2,1.38,972.97]],"ltp":1.15,"tv":284.56,"id":10894176}]}]}
{"op":"mcm","clk":"1008372332","pt":1580659756953,"mc":[{"id":"1.168224454","rc":[{"batl":[[0,1.09,1223.65]],"ltp":1.15,"tv":284.56,"id":10894176},{"batb":[[0,13,7],[1,12,3.36],[2,9.6,15.03]],"ltp":8.8,"tv":109.91,"id":2263634}]}]}
{"op":"mcm","clk":"1008373070","pt":1580659760258,"mc":[{"id":"1.168224454","rc":[{"batl":[[0,30,47.16]],"ltp":8.8,"tv":109.91,"id":2263634}]}]}
{"op":"mcm","clk":"1008373499","pt":1580659762221,"mc":[{"id":"1.168224454","rc":[{"batl":[[1,1.38,972.97],[2,1.38,0]],"ltp":1.15,"tv":284.56,"id":10894176}]}]}
{"op":"mcm","clk":"1008374280","pt":1580659765522,"mc":[{"id":"1.168224454","rc":[{"batl":[[1,1.15,2.53],[2,1.38,972.97]],"ltp":1.15,"tv":284.56,"id":10894176}]}]}
{"op":"mcm","clk":"1008374936","pt":1580659768303,"mc":[{"id":"1.168224454","rc":[{"batb":[[0,1.05,456.43],[1,1.04,582.88],[2,1.01,15.51]],"batl":[[0,1.09,42.01]],"ltp":1.15,"tv":284.56,"id":10894176}]}]}
{"op":"mcm","clk":"1008375109","pt":1580659769059,"mc":[{"id":"1.168224454","rc":[{"batb":[[0,1.04,582.88],[1,1.01,15.51],[2,1.01,0]],"ltp":1.15,"tv":284.56,"id":10894176},{"batb":[[0,12,3.36],[1,9.6,15.03],[2,1.01,15.51]],"ltp":8.8,"tv":109.91,"id":2263634}]}]}
{"op":"mcm","clk":"1008375288","pt":1580659769726,"mc":[{"id":"1.168224454","rc":[{"batl":[[0,1.15,2.53],[1,1.38,972.97],[2,1.38,0]],"ltp":1.15,"tv":284.56,"id":10894176},{"batb":[[0,9.6,15.03],[1,1.01,15.51],[2,1.01,0]],"ltp":8.8,"tv":109.91,"id":2263634}]}]}
{"op":"mcm","clk":"1008375624","pt":1580659771267,"mc":[{"id":"1.168224454","rc":[{"batb":[[0,1.06,318.22],[1,1.05,905.4],[2,1.04,582.88]],"batl":[[0,1.12,998.18],[1,1.15,2.53],[2,1.38,972.97]],"ltp":1.15,"tv":284.56,"id":10894176}]}]}
{"op":"mcm","clk":"1008375847","pt":1580659772246,"mc":[{"id":"1.168224454","rc":[{"batb":[[0,1.04,582.88],[1,1.01,15.51],[2,1.04,0]],"batl":[[0,1.15,2.53],[1,1.38,972.97],[2,1.38,0]],"ltp":1.15,"tv":284.56,"id":10894176}]}]}
{"op":"mcm","clk":"1008376316","pt":1580659774428,"mc":[{"id":"1.168224454","rc":[{"batb":[[0,1.07,1203.73],[1,1.04,582.88],[2,1.01,15.51]],"batl":[[0,1.09,669.42],[1,1.1,507.56],[2,1.15,2.53]],"ltp":1.15,"tv":284.56,"id":10894176}]}]}
{"op":"mcm","clk":"1008377396","pt":1580659779387,"mc":[{"id":"1.168224454","rc":[{"batb":[[0,1.04,582.88],[1,1.01,15.51],[2,1.01,0]],"batl":[[0,1.15,2.53],[1,1.38,972.97],[2,1.15,0]],"ltp":1.15,"tv":284.56,"id":10894176}]}]}
{"op":"mcm","clk":"1008378080","pt":1580659782384,"mc":[{"id":"1.168224454","rc":[{"batb":[[0,1.06,318.22],[1,1.05,905.4],[2,1.04,582.88]],"batl":[[0,1.12,998.18],[1,1.15,2.53],[2,1.38,972.97]],"ltp":1.15,"tv":284.56,"id":10894176}]}]}
{"op":"mcm","clk":"1008379248","pt":1580659787256,"mc":[{"id":"1.168224454","rc":[{"batl":[[0,1.15,2.53],[1,1.38,972.97],[2,1.38,0]],"ltp":1.15,"tv":284.56,"id":10894176}]}]}
{"op":"mcm","clk":"1008379913","pt":1580659790295,"mc":[{"id":"1.168224454","rc":[{"batl":[[0,1.07,937.6],[1,1.08,266.74],[2,1.15,2.53]],"ltp":1.15,"tv":284.56,"id":10894176}]}]}
{"op":"mcm","clk":"1008380158","pt":1580659791410,"mc":[{"id":"1.168224454","rc":[{"batb":[[2,1.02,769.27]],"ltp":1.15,"tv":284.56,"id":10894176},{"batb":[[0,15.5,4.56],[1,14.5,5.67],[2,9.6,15.03]],"ltp":8.8,"tv":109.91,"id":2263634}]}]}
{"op":"mcm","clk":"1008380516","pt":1580659793041,"mc":[{"id":"1.168224454","rc":[{"batl":[[0,42,43.68]],"ltp":8.8,"tv":109.91,"id":2263634}]}]}
{"op":"mcm","clk":"1008383551","pt":1580659806300,"mc":[{"id":"1.168224454","rc":[{"batb":[[1,1.05,833.26]],"batl":[[0,1.07,864.61]],"ltp":1.15,"tv":284.56,"id":10894176}]}]}
{"op":"mcm","clk":"1008384062","pt":1580659808593,"mc":[{"id":"1.168224454","rc":[{"batb":[[0,1.06,392.82]],"batl":[[1,1.08,339.05]],"ltp":1.15,"tv":284.56,"id":10894176}]}]}
{"op":"mcm","clk":"1008384920","pt":1580659812390,"mc":[{"id":"1.168224454","rc":[{"batb":[[0,1.02,769.27],[1,1.01,15.51],[2,1.02,0]],"batl":[[0,1.08,339.05],[1,1.15,2.53],[2,1.38,972.97]],"ltp":1.15,"tv":284.56,"id":10894176}]}]}
{"op":"mcm","clk":"1008385065","pt":1580659813191,"mc":[{"id":"1.168224454","rc":[{"batb":[[0,14.5,5.67],[1,1.01,15.51],[2,9.6,0]],"ltp":8.8,"tv":109.91,"id":2263634}]}]}
{"op":"mcm","clk":"1008385507","pt":1580659815189,"mc":[{"id":"1.168224454","rc":[{"batb":[[0,1.04,1241.64],[1,1.02,769.27],[2,1.01,15.51]],"batl":[[0,1.08,874.8],[1,1.09,317.91],[2,1.15,2.53]],"ltp":1.15,"tv":284.56,"id":10894176}]}]}
{"op":"mcm","clk":"1008387771","pt":1580659825460,"mc":[{"id":"1.168224454","rc":[{"batl":[[0,1.15,2.53],[1,1.38,972.97],[2,1.15,0]],"ltp":1.15,"tv":284.56,"id":10894176}]}]}
{"op":"mcm","clk":"1008388157","pt":1580659827056,"mc":[{"id":"1.168224454","rc":[{"batl":[[1,1.38,0]],"ltp":1.15,"tv":284.56,"id":10894176}]}]}
{"op":"mcm","clk":"1008388469","pt":1580659828363,"mc":[{"id":"1.168224454","rc":[{"batl":[[0,1.06,1218.22],[1,1.15,2.53]],"ltp":1.15,"tv":284.56,"id":10894176}]}]}
{"op":"mcm","clk":"1008388651","pt":1580659829171,"mc":[{"id":"1.168224454","rc":[{"batl":[[0,1.06,1260.23]],"ltp":1.15,"tv":284.56,"id":10894176},{"batb":[[0,19,5.82],[1,16.5,4.17],[2,1.01,15.51]],"ltp":8.8,"tv":109.91,"id":2263634}]}]}
{"op":"mcm","clk":"1008388977","pt":1580659830574,"mc":[{"id":"1.168224454","rc":[{"batl":[[2,1.32,1159.8]],"ltp":1.15,"tv":284.56,"id":10894176},{"batl":[[0,65,40.67]],"ltp":8.8,"tv":109.91,"id":2263634}]}]}
{"op":"mcm","clk":"1008392139","pt":1580659845136,"mc":[{"id":"1.168224454","rc":[{"batb":[[0,1.01,15.51],[1,1.02,0],[2,1.01,0]],"batl":[[0,1.06,42.01]],"ltp":1.15,"tv":284.56,"id":10894176},{"batb":[[0,16.5,4.17],[1,1.01,15.51],[2,1.01,0]],"ltp":8.8,"tv":109.91,"id":2263634}]}]}
{"op":"mcm","clk":"1008392421","pt":1580659846323,"mc":[{"id":"1.168224454","rc":[{"batl":[[0,1.15,2.53],[1,1.32,1159.8],[2,1.32,0]],"ltp":1.15,"tv":284.56,"id":10894176}]}]}
{"op":"mcm","clk":"1008392686","pt":1580659847417,"mc":[{"id":"1.168224454","rc":[{"batb":[[0,1.02,1265.99],[1,1.01,15.51]],"batl":[[0,1.07,1206.83],[1,1.15,2.53],[2,1.32,1159.8]],"ltp":1.15,"tv":284.56,"id":10894176}]}]}
{"op":"mcm","clk":"1008393459","pt":1580659851217,"mc":[{"id":"1.168224454","rc":[{"batb":[[0,1.01,15.51],[1,1.01,0]],"ltp":1.15,"tv":284.56,"id":10894176}]}]}
{"op":"mcm","clk":"1008393973","pt":1580659853343,"mc":[{"id":"1.168224454","rc":[{"batb":[[0,1.05,1229.82],[1,1.01,15.51]],"ltp":1.15,"tv":284.56,"id":10894176}]}]}
{"op":"mcm","clk":"1008394138","pt":1580659854075,"mc":[{"id":"1.168224454","rc":[{"batb":[[1,1.03,614.74],[2,1.02,888.95]],"ltp":1.15,"tv":284.56,"id":10894176},{"batb":[[1,14.5,5.51],[2,1.01,15.51]],"ltp":8.8,"tv":109.91,"id":2263634}]}]}
{"op":"mcm","clk":"1008394263","pt":1580659854625,"mc":[{"id":"1.168224454","rc":[{"batb":[[0,1.05,1397.86]],"batl":[[0,1.07,1248.84]],"ltp":1.15,"tv":284.56,"id":10894176}]}]}
{"op":"mcm","clk":"1008394558","pt":1580659855826,"mc":[{"id":"1.168224454","rc":[{"batl":[[0,42,43.68]],"ltp":8.8,"tv":109.91,"id":2263634}]}]}
{"op":"mcm","clk":"1008396449","pt":1580659864320,"mc":[{"id":"1.168224454","rc":[{"batb":[[0,1.05,168.04]],"batl":[[0,1.07,42.01]],"ltp":1.15,"tv":284.56,"id":10894176}]}]}
{"op":"mcm","clk":"1008396548","pt":1580659864762,"mc":[{"id":"1.168224454","rc":[{"batb":[[1,1.02,888.95],[2,1.01,15.51]],"ltp":1.15,"tv":284.56,"id":10894176},{"batb":[[0,14.5,5.51],[1,1.01,15.51],[2,1.01,0]],"ltp":8.8,"tv":109.91,"id":2263634}]}]}
{"op":"mcm","clk":"1008396808","pt":1580659865950,"mc":[{"id":"1.168224454","rc":[{"batb":[[0,1.02,888.95],[1,1.01,15.51],[2,1.01,0]],"batl":[[0,1.15,2.53],[1,1.32,1159.8],[2,1.32,0]],"ltp":1.15,"tv":284.56,"id":10894176}]}]}
{"op":"mcm","clk":"1008397100","pt":1580659867241,"mc":[{"id":"1.168224454","rc":[{"batb":[[0,1.04,791.26],[1,1.03,454.75],[2,1.02,888.95]],"batl":[[0,1.08,851.13],[1,1.09,341.36],[2,1.15,2.53]],"ltp":1.15,"tv":284.56,"id":10894176}]}]}
{"op":"mcm","clk":"1008397576","pt":1580659869195,"mc":[{"id":"1.168224454","rc":[{"batb":[[0,1.02,888.95],[1,1.01,15.51],[2,1.02,0]],"batl":[[0,1.15,2.53],[1,1.32,1159.8],[2,1.15,0]],"ltp":1.15,"tv":284.56,"id":10894176}]}]}
{"op":"mcm","clk":"1008398203","pt":1580659871379,"mc":[{"id":"1.168224454","rc":[{"batb":[[0,1.05,1229.82],[1,1.02,888.95],[2,1.01,15.51]],"batl":[[0,1.07,1206.83],[1,1.15,2.53],[2,1.32,1159.8]],"ltp":1.15,"tv":284.56,"id":10894176}]}]}
{"op":"mcm","clk":"1008398805","pt":1580659873976,"mc":[{"id":"1.168224454","rc":[{"batl":[[0,65,40.67]],"ltp":8.8,"tv":109.91,"id":2263634}]}]}
{"op":"mcm","clk":"1008399046","pt":1580659875087,"mc":[{"id":"1.168224454","rc":[{"batb":[[0,1.02,888.95],[1,1.01,15.51],[2,1.01,0]],"batl":[[0,1.15,2.53],[1,1.32,1159.8],[2,1.32,0]],"ltp":1.15,"tv":284.56,"id":10894176}]}]}
{"op":"mcm","clk":"1008399584","pt":1580659877387,"mc":[{"id":"1.168224454","rc":[{"batb":[[0,1.04,791.26],[1,1.03,454.75],[2,1.02,888.95]],"batl":[[0,1.08,851.13],[1,1.09,341.36],[2,1.15,2.53]],"ltp":1.15,"tv":284.56,"id":10894176}]}]}
{"op":"mcm","clk":"1008399897","pt":1580659878888,"mc":[{"id":"1.168224454","rc":[{"batb":[[0,1.02,888.95],[1,1.01,15.51],[2,1.02,0]],"ltp":1.15,"tv":284.56,"id":10894176}]}]}
{"op":"mcm","clk":"1008400435","pt":1580659881395,"mc":[{"id":"1.168224454","rc":[{"batb":[[0,1.06,1218.22],[1,1.02,888.95],[2,1.01,15.51]],"ltp":1.15,"tv":284.56,"id":10894176}]}]}
{"op":"mcm","clk":"1008400652","pt":1580659882363,"mc":[{"id":"1.168224454","rc":[{"batb":[[1,1.04,522.84],[2,1.03,660.22]],"ltp":1.15,"tv":284.56,"id":10894176},{"batb":[[1,13.5,6.61],[2,1.01,15.51]],"ltp":8.8,"tv":109.91,"id":2263634}]}]}
{"op":"mcm","clk":"1008400702","pt":1580659882598,"mc":[{"id":"1.168224454","rc":[{"batb":[[0,1.06,1386.26]],"ltp":1.15,"tv":284.56,"id":10894176},{"batb":[[2,13,3.36]],"ltp":8.8,"tv":109.91,"id":2263634}]}]}
{"op":"mcm","clk":"1008401184","pt":1580659884908,"mc":[{"id":"1.168224454","rc":[{"batl":[[0,42,43.68]],"ltp":8.8,"tv":109.91,"id":2263634}]}]}
{"op":"mcm","clk":"1008403083","pt":1580659893388,"mc":[{"id":"1.168224454","rc":[{"batb":[[0,1.06,168.04]],"batl":[[0,1.09,341.36],[1,1.15,2.53],[2,1.32,1159.8]],"ltp":1.15,"tv":284.56,"id":10894176}]}]}
{"op":"mcm","clk":"1008403216","pt":1580659894022,"mc":[{"id":"1.168224454","rc":[{"batb":[[1,1.03,660.22],[2,1.01,15.51]],"ltp":1.15,"tv":284.56,"id":10894176},{"batb":[[0,13.5,6.61],[1,13,3.36],[2,1.01,15.51]],"ltp":8.8,"tv":109.91,"id":2263634}]}]}
{"op":"mcm","clk":"1008403747","pt":1580659896302,"mc":[{"id":"1.168224454","rc":[{"batb":[[0,1.05,1229.82]],"batl":[[0,1.09,904.85],[1,1.1,277.29],[2,1.15,2.53]],"ltp":1.15,"tv":284.56,"id":10894176},{"batb":[[1,1.01,15.51],[2,1.01,0]],"ltp":8.8,"tv":109.91,"id":2263634}]}]}
{"op":"mcm","clk":"1008404117","pt":1580659897912,"mc":[{"id":"1.168224454","rc":[{"batl":[[0,1.15,2.53],[1,1.32,1159.8],[2,1.15,0]],"ltp":1.15,"tv":284.56,"id":10894176}]}]}
{"op":"mcm","clk":"1008404664","pt":1580659900344,"mc":[{"id":"1.168224454","rc":[{"batl":[[0,1.07,1206.83],[1,1.15,2.53],[2,1.32,1159.8]],"ltp":1.15,"tv":284.56,"id":10894176}]}]}
{"op":"mcm","clk":"1008404882","pt":1580659901289,"mc":[{"id":"1.168224454","rc":[{"batb":[[0,1.05,1397.86]],"batl":[[0,1.07,1248.84]],"ltp":1.15,"tv":284.56,"id":10894176},{"batb":[[0,17,7.63],[1,14.5,5.67],[2,1.01,15.51]],"ltp":8.8,"tv":109.91,"id":2263634}]}]}
{"op":"mcm","clk":"1008405526","pt":1580659904166,"mc":[{"id":"1.168224454","rc":[{"batl":[[0,65,40.67]],"ltp":8.8,"tv":109.91,"id":2263634}]}]}
{"op":"mcm","clk":"1008407545","pt":1580659913255,"mc":[{"id":"1.168224454","rc":[{"batb":[[0,1.05,168.04]],"batl":[[0,1.07,42.01]],"ltp":1.15,"tv":284.56,"id":10894176}]}]}
{"op":"mcm","clk":"1008407683","pt":1580659913845,"mc":[{"id":"1.168224454","rc":[{"batb":[[0,1.01,15.51],[1,1.03,0],[2,1.01,0]],"batl":[[0,1.15,2.53],[1,1.32,1159.8],[2,1.32,0]],"ltp":1.15,"tv":284.56,"id":10894176},{"batb":[[0,14.5,5.67],[1,1.01,15.51],[2,1.01,0]],"ltp":8.8,"tv":109.91,"id":2263634}]}]}
{"op":"mcm","clk":"1008408248","pt":1580659916108,"mc":[{"id":"1.168224454","rc":[{"batb":[[0,1.03,1253.7],[1,1.01,15.51]],"batl":[[0,1.08,600.58],[1,1.09,589.61],[2,1.15,2.53]],"ltp":1.15,"tv":284.56,"id":10894176}]}]}
{"op":"mcm","clk":"1008410174","pt":1580659924434,"mc":[{"id":"1.168224454","rc":[{"batb":[[0,1.01,15.51],[1,1.01,0]],"ltp":1.15,"tv":284.56,"id":10894176}]}]}
{"op":"mcm","clk":"1008410812","pt":1580659927401,"mc":[{"id":"1.168224454","rc":[{"batb":[[0,1.07,398.43],[1,1.06,816.02],[2,1.01,15.51]],"ltp":1.15,"tv":284.56,"id":10894176}]}]}
{"op":"mcm","clk":"1008410987","pt":1580659928113,"mc":[{"id":"1.168224454","rc":[{"batb":[[2,1.04,517.41]],"ltp":1.15,"tv":284.56,"id":10894176},{"batb":[[1,13,6.92],[2,1.01,15.51]],"ltp":8.8,"tv":109.91,"id":2263634}]}]}
{"op":"mcm","clk":"1008411101","pt":1580659928605,"mc":[{"id":"1.168224454","rc":[{"batb":[[1,13,10.28]],"ltp":8.8,"tv":109.91,"id":2263634}]}]}
{"op":"mcm","clk":"1008411807","pt":1580659931567,"mc":[{"id":"1.168224454","rc":[{"batl":[[0,42,43.68]],"ltp":8.8,"tv":109.91,"id":2263634}]}]}
{"op":"mcm","clk":"1008413948","pt":1580659941176,"mc":[{"id":"1.168224454","rc":[{"batb":[[0,1.04,517.41],[1,1.03,665.96],[2,1.01,15.51]],"batl":[[0,1.09,525.93],[1,1.15,2.53],[2,1.32,1159.8]],"ltp":1.15,"tv":284.56,"id":10894176}]}]}
{"op":"mcm","clk":"1008414043","pt":1580659941668,"mc":[{"id":"1.168224454","rc":[{"batb":[[0,1.03,665.96],[1,1.01,15.51],[2,1.01,0]],"ltp":1.15,"tv":284.56,"id":10894176},{"batb":[[0,13,6.92],[1,1.01,15.51],[2,1.01,0]],"ltp":8.8,"tv":109.91,"id":2263634}]}]}
{"op":"mcm","clk":"1008414572","pt":1580659944087,"mc":[{"id":"1.168224454","rc":[{"batb":[[0,1.05,1229.82],[1,1.03,665.96],[2,1.01,15.51]],"batl":[[1,1.1,652.76],[2,1.15,2.53]],"ltp":1.15,"tv":284.56,"id":10894176}]}]}
{"op":"mcm","clk":"1008414831","pt":1580659945268,"mc":[{"id":"1.168224454","rc":[{"batl":[[0,1.15,2.53],[1,1.32,1159.8],[2,1.15,0]],"ltp":1.15,"tv":284.56,"id":10894176}]}]}
{"op":"mcm","clk":"1008415544","pt":1580659948405,"mc":[{"id":"1.168224454","rc":[{"batl":[[0,1.07,1206.83],[1,1.15,2.53],[2,1.32,1159.8]],"ltp":1.15,"tv":284.56,"id":10894176}]}]}
{"op":"mcm","clk":"1008415714","pt":1580659949106,"mc":[{"id":"1.168224454","rc":[{"batb":[[0,1.05,1397.86]],"batl":[[0,1.07,1248.84]],"ltp":1.15,"tv":284.56,"id":10894176},{"batb":[[0,17,7.47],[1,14.5,5.43],[2,1.01,15.51]],"ltp":8.8,"tv":109.91,"id":2263634}]}]}
{"op":"mcm","clk":"1008416164","pt":1580659951193,"mc":[{"id":"1.168224454","rc":[{"batl":[[1,1.32,1159.8],[2,1.32,0]],"ltp":1.15,"tv":284.56,"id":10894176},{"batl":[[0,65,40.67]],"ltp":8.8,"tv":109.91,"id":2263634}]}]}
{"op":"mcm","clk":"1008416914","pt":1580659954485,"mc":[{"id":"1.168224454","rc":[{"batl":[[1,1.15,3.21],[2,1.32,1159.8]],"ltp":1.15,"tv":284.56,"id":10894176}]}]}
{"op":"mcm","clk":"1008417585","pt":1580659957405,"mc":[{"id":"1.168224454","rc":[{"batb":[[0,1.05,168.04]],"batl":[[0,1.07,42.01]],"ltp":1.15,"tv":284.56,"id":10894176}]}]}
{"op":"mcm","clk":"1008417819","pt":1580659958386,"mc":[{"id":"1.168224454","rc":[{"batb":[[0,1.01,15.51],[1,1.03,0],[2,1.01,0]],"batl":[[0,1.15,3.21],[1,1.32,1159.8],[2,1.32,0]],"ltp":1.15,"tv":284.56,"id":10894176},{"batb":[[0,14.5,5.43],[1,1.01,15.51],[2,1.01,0]],"ltp":8.8,"tv":109.91,"id":2263634}]}]}
{"op":"mcm","clk":"1008418979","pt":1580659963310,"mc":[{"id":"1.168224454","rc":[{"batb":[[0,1.05,468.08],[1,1.04,769.05],[2,1.01,15.51]],"batl":[[0,1.06,1105.91],[1,1.15,3.21],[2,1.32,1159.8]],"ltp":1.15,"tv":284.56,"id":10894176}]}]}
{"op":"mcm","clk":"1008419597","pt":1580659966223,"mc":[{"id":"1.168224454","rc":[{"batb":[[0,1.01,15.51],[1,1.04,0],[2,1.01,0]],"batl":[[0,1.15,3.21],[1,1.32,1159.8],[2,1.32,0]],"ltp":1.15,"tv":284.56,"id":10894176}]}]}
{"op":"mcm","clk":"1008419937","pt":1580659967900,"mc":[{"id":"1.168224454","rc":[{"batl":[[1,1.32,0]],"ltp":1.15,"tv":284.56,"id":10894176}]}]}
{"op":"mcm","clk":"1008420186","pt":1580659969064,"mc":[{"id":"1.168224454","rc":[{"batb":[[0,1.03,1253.7],[1,1.01,15.51]],"batl":[[0,1.08,683.98],[1,1.09,506.98],[2,1.15,3.21]],"ltp":1.15,"tv":284.56,"id":10894176}]}]}
{"op":"mcm","clk":"1008423361","pt":1580659982867,"mc":[{"id":"1.168224454","rc":[{"batl":[[0,1.15,3.21],[1,1.09,0],[2,1.15,0]],"ltp":1.15,"tv":284.56,"id":10894176}]}]}
{"op":"mcm","clk":"1008424179","pt":1580659986432,"mc":[{"id":"1.168224454","rc":[{"batl":[[0,1.04,1241.64],[1,1.15,3.21]],"ltp":1.15,"tv":284.56,"id":10894176},{"batb":[[0,25,4.19],[1,17.5,7.24],[2,14.5,5.43]],"ltp":8.8,"tv":109.91,"id":2263634}]}]}
{"op":"mcm","clk":"1008424205","pt":1580659986545,"mc":[{"id":"1.168224454","rc":[{"batb":[[2,1.01,15.51]],"ltp":8.8,"tv":109.91,"id":2263634}]}]}
{"op":"mcm","clk":"1008424574","pt":1580659988049,"mc":[{"id":"1.168224454","rc":[{"batl":[[2,1.3,1224.86]],"ltp":1.15,"tv":284.56,"id":10894176},{"batl":[[0,160,37.1]],"ltp":8.8,"tv":109.91,"id":2263634}]}]}
{"op":"mcm","clk":"1008426670","pt":1580659997307,"mc":[{"id":"1.168224454","rc":[{"batb":[[0,1.01,15.51],[1,1.01,0]],"batl":[[0,1.15,3.21],[1,1.3,1224.86],[2,1.3,0]],"ltp":1.15,"tv":284.56,"id":10894176}]}]}
{"op":"mcm","clk":"1008426862","pt":1580659998110,"mc":[{"id":"1.168224454","rc":[{"batb":[[0,17.5,7.24],[1,1.01,15.51],[2,1.01,0]],"ltp":8.8,"tv":109.91,"id":2263634}]}]}
{"op":"mcm","clk":"1008427141","pt":1580659999205,"mc":[{"id":"1.168224454","rc":[{"batl":[[1,1.3,0]],"ltp":1.15,"tv":284.56,"id":10894176}]}]}
{"op":"mcm","clk":"1008427304","pt":1580660000081,"mc":[{"id":"1.168224454","rc":[{"batl":[[0,1.07,1206.83],[1,1.15,3.21]],"ltp":1.15,"tv":284.56,"id":10894176}]}]}
{"op":"mcm","clk":"1008428522","pt":1580660005316,"mc":[{"id":"1.168224454","rc":[{"batb":[[0,1.05,1229.82],[1,1.01,15.51]],"ltp":1.15,"tv":284.56,"id":10894176}]}]}
{"op":"mcm","clk":"1008428643","pt":1580660005806,"mc":[{"id":"1.168224454","rc":[{"batb":[[1,1.03,680.76],[2,1.01,15.51]],"ltp":1.15,"tv":284.56,"id":10894176},{"batb":[[1,15,5.27],[2,1.01,15.51]],"ltp":8.8,"tv":109.91,"id":2263634}]}]}
{"op":"mcm","clk":"1008428841","pt":1580660006632,"mc":[{"id":"1.168224454","rc":[{"batb":[[0,1.05,1397.86]],"batl":[[0,1.07,1248.84]],"ltp":1.15,"tv":284.56,"id":10894176}]}]}
{"op":"mcm","clk":"1008429071","pt":1580660007515,"mc":[{"id":"1.168224454","rc":[{"batl":[[2,1.32,1159.8]],"ltp":1.15,"tv":284.56,"id":10894176},{"batl":[[0,65,40.67]],"ltp":8.8,"tv":109.91,"id":2263634}]}]}
{"op":"mcm","clk":"1008432007","pt":1580660020180,"mc":[{"id":"1.168224454","rc":[{"batb":[[0,1.05,168.04],[1,1.01,15.51],[2,1.01,0]],"batl":[[0,1.07,42.01]],"ltp":1.15,"tv":284.56,"id":10894176},{"batb":[[0,15,5.27],[1,1.01,15.51],[2,1.01,0]],"ltp":8.8,"tv":109.91,"id":2263634}]}]}
{"op":"mcm","clk":"1008432369","pt":1580660021772,"mc":[{"id":"1.168224454","rc":[{"batb":[[0,1.01,15.51],[1,1.01,0]],"batl":[[0,1.15,3.21],[1,1.32,1159.8],[2,1.32,0]],"ltp":1.15,"tv":284.56,"id":10894176}]}]}
{"op":"mcm","clk":"1008433128","pt":1580660024871,"mc":[{"id":"1.168224454","rc":[{"batb":[[0,1.05,385.64],[1,1.04,852.3],[2,1.01,15.51]],"batl":[[0,1.06,1168.23],[1,1.15,3.21],[2,1.32,1159.8]],"ltp":1.15,"tv":284.56,"id":10894176}]}]}
{"op":"mcm","clk":"1008434349","pt":1580660030274,"mc":[{"id":"1.168224454","rc":[{"batb":[[0,1.01,15.51],[1,1.04,0],[2,1.01,0]],"batl":[[0,1.15,3.21],[1,1.32,1159.8],[2,1.32,0]],"ltp":1.15,"tv":284.56,"id":10894176}]}]}
{"op":"mcm","clk":"1008435039","pt":1580660033184,"mc":[{"id":"1.168224454","rc":[{"batb":[[0,1.03,1253.7],[1,1.01,15.51]],"batl":[[0,1.08,716.61],[1,1.09,474.65],[2,1.15,3.21]],"ltp":1.15,"tv":284.56,"id":10894176}]}]}
{"op":"mcm","clk":"1008436978","pt":1580660041528,"mc":[{"id":"1.168224454","rc":[{"batl":[[0,1.15,3.21],[1,1.09,0],[2,1.15,0]],"ltp":1.15,"tv":284.56,"id":10894176}]}]}
{"op":"mcm","clk":"1008437862","pt":1580660045199,"mc":[{"id":"1.168224454","rc":[{"batl":[[0,1.04,1241.64],[1,1.15,3.21]],"ltp":1.15,"tv":284.56,"id":10894176},{"batb":[[0,26,3.86],[1,17.5,7.16],[2,1.01,15.51]],"ltp":8.8,"tv":109.91,"id":2263634}]}]}
{"op":"mcm","clk":"1008438460","pt":1580660047597,"mc":[{"id":"1.168224454","rc":[{"batl":[[2,1.3,1224.86]],"ltp":1.15,"tv":284.56,"id":10894176},{"batl":[[0,160,37.1]],"ltp":8.8,"tv":109.91,"id":2263634}]}]}
{"op":"mcm","clk":"1008440440","pt":1580660056094,"mc":[{"id":"1.168224454","rc":[{"batb":[[0,1.01,15.51],[1,1.01,0]],"batl":[[0,1.15,3.21],[1,1.3,1224.86],[2,1.3,0]],"ltp":1.15,"tv":284.56,"id":10894176},{"batb":[[0,17.5,7.16],[1,1.01,15.51],[2,1.01,0]],"ltp":8.8,"tv":109.91,"id":2263634}]}]}
{"op":"mcm","clk":"1008440614","pt":1580660056801,"mc":[{"id":"1.168224454","rc":[{"batl":[[1,1.3,0]],"ltp":1.15,"tv":284.56,"id":10894176}]}]}
{"op":"mcm","clk":"1008441009","pt":1580660058404,"mc":[{"id":"1.168224454","rc":[{"batl":[[0,1.06,280.72],[1,1.07,928.73],[2,1.15,3.21]],"ltp":1.15,"tv":284.56,"id":10894176}]}]}
{"op":"mcm","clk":"1008441048","pt":1580660058618,"mc":[{"id":"1.168224454","rc":[{"batl":[[0,1.15,3.21],[1,1.07,0],[2,1.15,0]],"ltp":1.15,"tv":284.56,"id":10894176}]}]}
{"op":"mcm","clk":"1008441368","pt":1580660060023,"mc":[{"id":"1.168224454","rc":[{"batb":[[0,1.02,1265.99],[1,1.01,15.51]],"batl":[[0,1.03,816.82],[1,1.04,266.49],[2,1.15,3.21]],"ltp":1.15,"tv":284.56,"id":10894176}]}]}
{"op":"mcm","clk":"1008441862","pt":1580660062107,"mc":[{"id":"1.168224454","rc":[{"batb":[[0,1.01,15.51],[1,1.01,0]],"batl":[[0,1.15,3.21],[1,1.29,1276.55],[2,1.15,0]],"ltp":1.15,"tv":284.56,"id":10894176}]}]}
{"op":"mcm","clk":"1008442424","pt":1580660064421,"mc":[{"id":"1.168224454","rc":[{"batl":[[1,1.29,0]],"ltp":1.15,"tv":284.56,"id":10894176}]}]}
{"op":"mcm","clk":"1008442558","pt":1580660065011,"mc":[{"id":"1.168224454","rc":[{"batl":[[0,1.07,1206.83],[1,1.15,3.21]],"ltp":1.15,"tv":284.56,"id":10894176}]}]}
{"op":"mcm","clk":"1008444449","pt":1580660073030,"mc":[{"id":"1.168224454","rc":[{"batl":[[0,1.15,3.21],[1,1.15,0]],"ltp":1.15,"tv":284.56,"id":10894176}]}]}
{"op":"mcm","clk":"1008444746","pt":1580660074233,"mc":[{"id":"1.168224454","marketDefinition":{"bspMarket":false,"turnInPlayEnabled":true,"persistenceEnabled":true,"marketBaseRate":5.0,"eventId":"29681727","eventTypeId":"2","numberOfWinners":1,"bettingType":"ODDS","marketType":"SET_WINNER","marketTime":"2020-02-02T14:51:00.000Z","suspendTime":"2020-02-02T14:51:00.000Z","bspReconciled":false,"complete":true,"inPlay":true,"crossMatching":true,"runnersVoidable":false,"numberOfActiveRunners":2,"betDelay":3,"status":"SUSPENDED","runners":[{"status":"ACTIVE","sortPriority":1,"id":10894176,"name":"Elliot Benchetrit"},{"status":"ACTIVE","sortPriority":2,"id":2263634,"name":"Lukas Lacko"}],"regulators":["MR_INT"],"countryCode":"FR","discountAllowed":true,"timezone":"UTC","openDate":"2020-02-02T14:51:00.000Z","version":3149730862,"name":"Set 2 Winner","eventName":"Benchetrit v Lacko"},"rc":[{"batb":[[0,1.01,15.51],[1,1.01,0]],"ltp":8.8,"tv":109.91,"id":2263634}]}]}
{"op":"mcm","clk":"1008452799","pt":1580660108339,"mc":[{"id":"1.168224454","marketDefinition":{"bspMarket":false,"turnInPlayEnabled":true,"persistenceEnabled":true,"marketBaseRate":5.0,"eventId":"29681727","eventTypeId":"2","numberOfWinners":1,"bettingType":"ODDS","marketType":"SET_WINNER","marketTime":"2020-02-02T14:51:00.000Z","suspendTime":"2020-02-02T14:51:00.000Z","bspReconciled":false,"complete":true,"inPlay":true,"crossMatching":false,"runnersVoidable":false,"numberOfActiveRunners":0,"betDelay":3,"status":"CLOSED","settledTime":"2020-02-02T16:15:06.000Z","runners":[{"status":"WINNER","sortPriority":1,"id":10894176,"name":"Elliot Benchetrit"},{"status":"LOSER","sortPriority":2,"id":2263634,"name":"Lukas Lacko"}],"regulators":["MR_INT"],"countryCode":"FR","discountAllowed":true,"timezone":"UTC","openDate":"2020-02-02T14:51:00.000Z","version":3149732521,"name":"Set 2 Winner","eventName":"Benchetrit v Lacko"},"tv":0.0}]}
