{"op":"mcm","clk":"1001177857","pt":1580585273658,"mc":[{"id":"1.168224441","marketDefinition":{"bspMarket":false,"turnInPlayEnabled":true,"persistenceEnabled":true,"marketBaseRate":5.0,"eventId":"29681727","eventTypeId":"2","numberOfWinners":1,"bettingType":"ODDS","marketType":"MATCH_ODDS","marketTime":"2020-02-02T15:00:00.000Z","suspendTime":"2020-02-02T15:00:00.000Z","bspReconciled":false,"complete":true,"inPlay":false,"crossMatching":false,"runnersVoidable":false,"numberOfActiveRunners":2,"betDelay":0,"status":"OPEN","runners":[{"status":"ACTIVE","sortPriority":1,"id":10894176,"name":"Elliot Benchetrit"},{"status":"ACTIVE","sortPriority":2,"id":2263634,"name":"Lukas Lacko"}],"regulators":["MR_INT"],"countryCode":"FR","discountAllowed":false,"timezone":"UTC","openDate":"2020-02-02T15:00:00.000Z","version":3147098561,"name":"Match Odds","eventName":"Benchetrit v Lacko"},"rc":[{"batb":[[0,1.05,152.2],[1,1.04,168.86],[2,1.03,190.07]],"ltp":0.0,"tv":0.0,"id":10894176},{"batb":[[0,1.05,152.2],[1,1.04,168.86],[2,1.03,190.07]],"ltp":0.0,"tv":0.0,"id":2263634}]}]}
{"op":"mcm","clk":"1001178215","pt":1580585275453,"mc":[{"id":"1.168224441","marketDefinition":{"bspMarket":false,"turnInPlayEnabled":true,"persistenceEnabled":true,"marketBaseRate":5.0,"eventId":"29681727","eventTypeId":"2","numberOfWinners":1,"bettingType":"ODDS","marketType":"MATCH_ODDS","marketTime":"2020-02-02T15:00:00.000Z","suspendTime":"2020-02-02T15:00:00.000Z","bspReconciled":false,"complete":true,"inPlay":false,"crossMatching":false,"runnersVoidable":false,"numberOfActiveRunners":2,"betDelay":0,"status":"OPEN","runners":[{"status":"ACTIVE","sortPriority":1,"id":10894176,"name":"Elliot Benchetrit"},{"status":"ACTIVE","sortPriority":2,"id":2263634,"name":"Lukas Lacko"}],"regulators":["MR_INT"],"countryCode":"FR","discountAllowed":true,"timezone":"UTC","openDate":"2020-02-02T15:00:00.000Z","version":3147098561,"name":"Match Odds","eventName":"Benchetrit v Lacko"}}]}
{"op":"mcm","clk":"1001227702","pt":1580585542382,"mc":[{"id":"1.168224441","rc":[{"batb":[[0,1.06,50.48],[1,1.05,152.2],[2,1.04,168.86]],"ltp":0.0,"tv":0.0,"id":10894176},{"batb":[[0,1.06,50.48],[1,1.05,152.2],[2,1.04,168.86]],"ltp":0.0,"tv":0.0,"id":2263634}]}]}
{"op":"mcm","clk":"1001229256","pt":1580585550620,"mc":[{"id":"1.168224441","marketDefinition":{"bspMarket":false,"turnInPlayEnabled":true,"persistenceEnabled":true,"marketBaseRate":5.0,"eventId":"29681727","eventTypeId":"2","numberOfWinners":1,"bettingType":"ODDS","marketType":"MATCH_ODDS","marketTime":"2020-02-02T15:00:00.000Z","suspendTime":"2020-02-02T15:00:00.000Z","bspReconciled":false,"complete":true,"inPlay":false,"crossMatching":true,"runnersVoidable":false,"numberOfActiveRunners":2,"betDelay":0,"status":"OPEN","runners":[{"status":"ACTIVE","sortPriority":1,"id":10894176,"name":"Elliot Benchetrit"},{"status":"ACTIVE","sortPriority":2,"id":2263634,"name":"Lukas Lacko"}],"regulators":["MR_INT"],"countryCode":"FR","discountAllowed":true,"timezone":"UTC","openDate":"2020-02-02T15:00:00.000Z","version":3147124899,"name":"Match Odds","eventName":"Benchetrit v Lacko"}}]}
{"op":"mcm","clk":"1001281343","pt":1580585812858,"mc":[{"id":"1.168224441","rc":[{"batl":[[0,48,31.05]],"ltp":0.0,"tv":0.0,"id":10894176},{"batl":[[0,48,31.05]],"ltp":0.0,"tv":0.0,"id":2263634}]}]}
{"op":"mcm","clk":"1001666038","pt":1580587949371,"mc":[{"id":"1.168224441","rc":[{"batl":[[1,990,2.2]],"ltp":0.0,"tv":0.0,"id":10894176},{"batl":[[1,990,2.2]],"ltp":0.0,"tv":0.0,"id":2263634}]}]}
{"op":"mcm","clk":"1001963812","pt":1580589601137,"mc":[{"id":"1.168224441","rc":[{"batb":[[0,1.4,530.06],[1,1.06,50.48],[2,1.05,152.2]],"ltp":0.0,"tv":0.0,"id":2263634}]}]}
{"op":"mcm","clk":"1002033273","pt":1580590016318,"mc":[{"id":"1.168224441","rc":[{"batb":[[0,1.41,6.22],[1,1.4,530.06],[2,1.06,50.48]],"ltp":0.0,"tv":0.0,"id":2263634}]}]}
{"op":"mcm","clk":"1002984729","pt":1580601553440,"mc":[{"id":"1.168224441","rc":[{"batl":[[2,1000,2]],"ltp":0.0,"tv":0.0,"id":10894176},{"batl":[[2,1000,2]],"ltp":0.0,"tv":0.0,"id":2263634}]}]}
{"op":"mcm","clk":"1002984735","pt":1580601553495,"mc":[{"id":"1.168224441","rc":[{"batb":[[0,1.06,50.58],[2,1.04,169.36]],"batl":[[2,1000,0.02]],"ltp":0.0,"tv":0.0,"id":10894176},{"batb":[[2,1.06,50.58]],"batl":[[2,1000,0.02]],"ltp":0.0,"tv":0.0,"id":2263634}]}]}
{"op":"mcm","clk":"1002990231","pt":1580601628437,"mc":[{"id":"1.168224441","rc":[{"batb":[[0,1.06,50.68]],"ltp":0.0,"tv":0.0,"id":10894176},{"batb":[[2,1.06,50.68]],"ltp":0.0,"tv":0.0,"id":2263634}]}]}
{"op":"mcm","clk":"1003881052","pt":1580615093035,"mc":[{"id":"1.168224441","rc":[{"batl":[[0,990,2.2],[1,1000,0.02],[2,1000,0]],"ltp":0.0,"tv":0.0,"id":10894176},{"batl":[[0,990,2.2],[1,1000,0.02],[2,1000,0]],"ltp":0.0,"tv":0.0,"id":2263634}]}]}
{"op":"mcm","clk":"1003930067","pt":1580616445544,"mc":[{"id":"1.168224441","rc":[{"batl":[[0,95,15.9],[1,990,2.2],[2,1000,0.02]],"ltp":0.0,"tv":0.0,"id":10894176},{"batl":[[0,95,15.9],[1,990,2.2],[2,1000,0.02]],"ltp":0.0,"tv":0.0,"id":2263634}]}]}
{"op":"mcm","clk":"1003936342","pt":1580616592024,"mc":[{"id":"1.168224441","rc":[{"batb":[[0,1.13,75.82],[1,1.06,50.58],[2,1.05,152.2]],"ltp":0.0,"tv":0.0,"id":10894176},{"batb":[[2,1.13,75.82]],"ltp":0.0,"tv":0.0,"id":2263634}]}]}
{"op":"mcm","clk":"1004080589","pt":1580619818203,"mc":[{"id":"1.168224441","rc":[{"batl":[[0,1.65,25.33],[1,95,15.9],[2,990,2.2]],"ltp":0.0,"tv":0.0,"id":2263634}]}]}
{"op":"mcm","clk":"1004296466","pt":1580626126190,"mc":[{"id":"1.168224441","rc":[{"batb":[[0,1.07,75.92],[1,1.06,50.48]],"ltp":0.0,"tv":0.0,"id":10894176},{"batb":[[2,1.07,75.92]],"ltp":0.0,"tv":0.0,"id":2263634}]}]}
{"op":"mcm","clk":"1004296859","pt":1580626140909,"mc":[{"id":"1.168224441","rc":[{"batb":[[2,1.21,15.14]],"batl":[[1,2.2,3.03],[2,95,15.9]],"ltp":0.0,"tv":0.0,"id":2263634}]}]}
{"op":"mcm","clk":"1004372183","pt":1580628221517,"mc":[{"id":"1.168224441","rc":[{"batb":[[0,1.48,55.51],[1,1.41,6.22],[2,1.4,530.06]],"ltp":0.0,"tv":0.0,"id":2263634}]}]}
{"op":"mcm","clk":"1004372617","pt":1580628231980,"mc":[{"id":"1.168224441","rc":[{"batb":[[0,1.49,60.01]],"ltp":0.0,"tv":0.0,"id":2263634}]}]}
{"op":"mcm","clk":"1004376963","pt":1580628360048,"mc":[{"id":"1.168224441","rc":[{"batb":[[0,2.1,43.16],[1,1.07,75.92],[2,1.06,50.48]],"ltp":0.0,"tv":0.0,"id":10894176}]}]}
{"op":"mcm","clk":"1004379595","pt":1580628412115,"mc":[{"id":"1.168224441","rc":[{"batb":[[0,2.18,43.16]],"ltp":0.0,"tv":0.0,"id":10894176},{"batb":[[2,1.4,565.65]],"ltp":0.0,"tv":0.0,"id":2263634}]}]}
{"op":"mcm","clk":"1004380322","pt":1580628432359,"mc":[{"id":"1.168224441","rc":[{"batb":[[0,2.36,43.16]],"ltp":0.0,"tv":0.0,"id":10894176},{"batb":[[1,1.47,35.59],[2,1.41,6.22]],"ltp":0.0,"tv":0.0,"id":2263634}]}]}
{"op":"mcm","clk":"1004419386","pt":1580629418731,"mc":[{"id":"1.168224441","rc":[{"batl":[[0,16,3.36],[1,95,15.9],[2,990,2.2]],"ltp":0.0,"tv":0.0,"id":10894176}]}]}
{"op":"mcm","clk":"1004474347","pt":1580630632199,"mc":[{"id":"1.168224441","rc":[{"batb":[[0,1.07,75.92],[1,1.06,50.48],[2,1.05,152.2]],"ltp":0.0,"tv":0.0,"id":10894176},{"batb":[[0,1.5,35.59],[1,1.49,60.01]],"ltp":0.0,"tv":0.0,"id":2263634}]}]}
{"op":"mcm","clk":"1004474768","pt":1580630642398,"mc":[{"id":"1.168224441","rc":[{"batb":[[0,1.51,56.48],[1,1.5,35.59]],"ltp":0.0,"tv":0.0,"id":2263634}]}]}
{"op":"mcm","clk":"1004474930","pt":1580630645395,"mc":[{"id":"1.168224441","rc":[{"batb":[[1,1.41,6.22],[2,1.4,530.06]],"ltp":0.0,"tv":0.0,"id":2263634}]}]}
{"op":"mcm","clk":"1004474932","pt":1580630645497,"mc":[{"id":"1.168224441","rc":[{"batb":[[0,1.52,35.59],[1,1.51,56.48],[2,1.41,6.22]],"ltp":0.0,"tv":0.0,"id":2263634}]}]}
{"op":"mcm","clk":"1004475388","pt":1580630652316,"mc":[{"id":"1.168224441","rc":[{"batb":[[0,2.28,40.13],[1,1.07,75.92],[2,1.06,50.48]],"ltp":0.0,"tv":0.0,"id":10894176},{"batb":[[0,1.51,92.07],[1,1.41,6.22],[2,1.4,530.06]],"ltp":0.0,"tv":0.0,"id":2263634}]}]}
{"op":"mcm","clk":"1004480305","pt":1580630763227,"mc":[{"id":"1.168224441","rc":[{"trd":[[2.52,5.88]],"ltp":2.52,"tv":5.88,"id":10894176},{"trd":[[1.65,8.98]],"batl":[[0,1.65,16.35]],"ltp":1.65,"tv":8.97,"id":2263634}],"tv":14.85}]}
{"op":"mcm","clk":"1004482787","pt":1580630822208,"mc":[{"id":"1.168224441","rc":[{"trd":[[1.55,5.04]],"batb":[[0,1.51,35.59]],"ltp":1.55,"tv":14.01,"id":2263634}],"tv":19.89}]}
{"op":"mcm","clk":"1004482887","pt":1580630825301,"mc":[{"id":"1.168224441","rc":[{"batb":[[0,1.41,6.22],[1,1.4,530.06],[2,1.21,15.14]],"ltp":1.55,"tv":14.01,"id":2263634}]}]}
{"op":"mcm","clk":"1004482896","pt":1580630825506,"mc":[{"id":"1.168224441","rc":[{"batb":[[0,1.51,60.58],[1,1.41,6.22],[2,1.4,530.06]],"ltp":1.55,"tv":14.01,"id":2263634}]}]}
{"op":"mcm","clk":"1004492697","pt":1580631048529,"mc":[{"id":"1.168224441","rc":[{"batb":[[0,1.52,56.24],[1,1.51,60.58],[2,1.41,6.22]],"ltp":1.55,"tv":14.01,"id":2263634}]}]}
{"op":"mcm","clk":"1004509742","pt":1580631443253,"mc":[{"id":"1.168224441","rc":[{"trd":[[2.52,16.6]],"batl":[[0,2.52,146.65],[1,16,3.36],[2,95,15.9]],"ltp":2.52,"tv":16.59,"id":10894176},{"trd":[[1.65,25.33]],"batl":[[0,2.2,3.03],[1,95,15.9],[2,990,2.2]],"ltp":1.65,"tv":30.36,"id":2263634}],"tv":46.96}]}
{"op":"mcm","clk":"1004511664","pt":1580631489981,"mc":[{"id":"1.168224441","rc":[{"batl":[[1,95,15.9],[2,990,2.2]],"ltp":2.52,"tv":16.59,"id":10894176}]}]}
{"op":"mcm","clk":"1004513292","pt":1580631530640,"mc":[{"id":"1.168224441","rc":[{"batb":[[0,2.3,32.08],[1,2.28,40.13],[2,1.07,75.92]],"ltp":2.52,"tv":16.59,"id":10894176},{"batb":[[0,1.51,60.58],[1,1.41,6.22],[2,1.4,530.06]],"ltp":1.65,"tv":30.36,"id":2263634}]}]}
{"op":"mcm","clk":"1004514429","pt":1580631555664,"mc":[{"id":"1.168224441","rc":[{"batl":[[0,95,15.9],[1,990,2.2],[2,1000,0.02]],"ltp":2.52,"tv":16.59,"id":10894176}]}]}
{"op":"mcm","clk":"1004516700","pt":1580631604947,"mc":[{"id":"1.168224441","rc":[{"batl":[[0,15.5,3.36],[1,95,15.9],[2,990,2.2]],"ltp":2.52,"tv":16.59,"id":10894176}]}]}
{"op":"mcm","clk":"1004524143","pt":1580631770228,"mc":[{"id":"1.168224441","rc":[{"batb":[[0,1.52,55.99],[1,1.51,60.58],[2,1.41,6.22]],"ltp":1.65,"tv":30.36,"id":2263634}]}]}
{"op":"mcm","clk":"1004524375","pt":1580631776597,"mc":[{"id":"1.168224441","rc":[{"batb":[[1,1.07,75.92],[2,1.06,50.48]],"ltp":2.52,"tv":16.59,"id":10894176}]}]}
{"op":"mcm","clk":"1004526291","pt":1580631828054,"mc":[{"id":"1.168224441","rc":[{"batb":[[0,2.3,47.68]],"ltp":2.52,"tv":16.59,"id":10894176},{"batb":[[0,1.52,82.99]],"ltp":1.65,"tv":30.36,"id":2263634}]}]}
{"op":"mcm","clk":"1004533484","pt":1580631970509,"mc":[{"id":"1.168224441","rc":[{"batb":[[1,1.11,37.96],[2,1.07,75.82]],"ltp":2.52,"tv":16.59,"id":10894176}]}]}
{"op":"mcm","clk":"1004533554","pt":1580631972012,"mc":[{"id":"1.168224441","rc":[{"batb":[[1,1.21,37.86],[2,1.11,37.96]],"ltp":2.52,"tv":16.59,"id":10894176}]}]}
{"op":"mcm","clk":"1004533623","pt":1580631973353,"mc":[{"id":"1.168224441","rc":[{"batb":[[1,1.41,37.86],[2,1.31,37.86]],"ltp":2.52,"tv":16.59,"id":10894176}]}]}
{"op":"mcm","clk":"1004533655","pt":1580631973816,"mc":[{"id":"1.168224441","rc":[{"batb":[[1,1.61,37.86],[2,1.51,37.86]],"ltp":2.52,"tv":16.59,"id":10894176},{"batb":[[2,1.41,44.08]],"ltp":1.65,"tv":30.36,"id":2263634}]}]}
{"op":"mcm","clk":"1004533822","pt":1580631976441,"mc":[{"id":"1.168224441","rc":[{"batb":[[1,1.81,37.86],[2,1.71,37.86]],"ltp":2.52,"tv":16.59,"id":10894176}]}]}
{"op":"mcm","clk":"1004533864","pt":1580631977211,"mc":[{"id":"1.168224441","rc":[{"batb":[[1,2,37.86],[2,1.81,37.86]],"ltp":2.52,"tv":16.59,"id":10894176}]}]}
{"op":"mcm","clk":"1004559584","pt":1580632575381,"mc":[{"id":"1.168224441","rc":[{"batb":[[0,2,37.86],[1,1.81,37.86],[2,1.71,37.86]],"ltp":2.52,"tv":16.59,"id":10894176}]}]}
{"op":"mcm","clk":"1004559596","pt":1580632575792,"mc":[{"id":"1.168224441","rc":[{"batb":[[0,2.08,51.31],[1,2,37.86],[2,1.81,37.86]],"ltp":2.52,"tv":16.59,"id":10894176}]}]}
{"op":"mcm","clk":"1004561820","pt":1580632631387,"mc":[{"id":"1.168224441","rc":[{"batb":[[0,2.1,10.92],[1,2.08,51.31],[2,2,37.86]],"ltp":2.52,"tv":16.59,"id":10894176}]}]}
{"op":"mcm","clk":"1004561835","pt":1580632631644,"mc":[{"id":"1.168224441","rc":[{"batb":[[0,2.18,48.86],[1,2.1,10.92]],"ltp":2.52,"tv":16.59,"id":10894176}]}]}
{"op":"mcm","clk":"1004564042","pt":1580632688781,"mc":[{"id":"1.168224441","rc":[{"batb":[[1,2,37.86],[2,1.81,37.86]],"ltp":2.52,"tv":16.59,"id":10894176}]}]}
{"op":"mcm","clk":"1004567167","pt":1580632761353,"mc":[{"id":"1.168224441","rc":[{"batl":[[0,1.58,310.46],[1,2.2,3.03],[2,95,15.9]],"ltp":1.65,"tv":30.36,"id":2263634}]}]}
{"op":"mcm","clk":"1004567196","pt":1580632761865,"mc":[{"id":"1.168224441","rc":[{"batb":[[0,2,37.86],[1,1.81,37.86],[2,1.71,37.86]],"ltp":2.52,"tv":16.59,"id":10894176},{"trd":[[1.58,591.48]],"batb":[[0,1.53,53.65]],"batl":[[0,1.58,205.52]],"ltp":1.58,"tv":621.85,"id":2263634}],"tv":638.44}]}
{"op":"mcm","clk":"1004567296","pt":1580632764850,"mc":[{"id":"1.168224441","rc":[{"batb":[[1,1.41,44.08],[2,1.4,530.06]],"ltp":1.58,"tv":621.85,"id":2263634}]}]}
{"op":"mcm","clk":"1004567531","pt":1580632770633,"mc":[{"id":"1.168224441","rc":[{"batb":[[0,1.41,44.08],[1,1.4,530.06],[2,1.31,37.86]],"ltp":1.58,"tv":621.85,"id":2263634}]}]}
{"op":"mcm","clk":"1004568851","pt":1580632804319,"mc":[{"id":"1.168224441","rc":[{"batb":[[0,2.02,11.76],[1,2,37.86],[2,1.81,37.86]],"ltp":2.52,"tv":16.59,"id":10894176},{"batb":[[0,1.42,10.08],[1,1.41,44.08],[2,1.4,530.06]],"ltp":1.58,"tv":621.85,"id":2263634}]}]}
{"op":"mcm","clk":"1004568860","pt":1580632804525,"mc":[{"id":"1.168224441","rc":[{"batb":[[0,1.43,91.22],[1,1.42,10.08],[2,1.41,44.08]],"ltp":1.58,"tv":621.85,"id":2263634}]}]}
{"op":"mcm","clk":"1004571717","pt":1580632862387,"mc":[{"id":"1.168224441","rc":[{"batb":[[1,1.41,44.08],[2,1.4,530.06]],"ltp":1.58,"tv":621.85,"id":2263634}]}]}
{"op":"mcm","clk":"1004579325","pt":1580633003552,"mc":[{"id":"1.168224441","rc":[{"batl":[[0,1.58,190.8]],"ltp":1.58,"tv":621.85,"id":2263634}]}]}
{"op":"mcm","clk":"1004583044","pt":1580633081356,"mc":[{"id":"1.168224441","rc":[{"batb":[[0,1.55,392.05]],"ltp":1.58,"tv":621.85,"id":2263634}]}]}
{"op":"mcm","clk":"1004583567","pt":1580633092139,"mc":[{"id":"1.168224441","rc":[{"batb":[[0,1.55,310.46]],"ltp":1.58,"tv":621.85,"id":2263634}]}]}
{"op":"mcm","clk":"1004584348","pt":1580633108267,"mc":[{"id":"1.168224441","rc":[{"batb":[[0,1.55,461.91]],"ltp":1.58,"tv":621.85,"id":2263634}]}]}
{"op":"mcm","clk":"1004585573","pt":1580633135586,"mc":[{"id":"1.168224441","rc":[{"batb":[[0,1.55,477.81]],"ltp":1.58,"tv":621.85,"id":2263634}]}]}
{"op":"mcm","clk":"1004585879","pt":1580633141990,"mc":[{"id":"1.168224441","rc":[{"batb":[[1,1.41,37.86]],"ltp":1.58,"tv":621.85,"id":2263634}]}]}
{"op":"mcm","clk":"1004585923","pt":1580633143021,"mc":[{"id":"1.168224441","rc":[{"trd":[[1.58,781.6]],"batl":[[0,1.58,95.74]],"ltp":1.58,"tv":811.96,"id":2263634}],"tv":828.56}]}
{"op":"mcm","clk":"1004586577","pt":1580633155745,"mc":[{"id":"1.168224441","rc":[{"trd":[[2.72,55.61]],"batl":[[0,2.72,11.6],[1,15.5,3.36],[2,95,15.9]],"ltp":2.72,"tv":72.21,"id":10894176},{"trd":[[1.58,877.34]],"batl":[[0,2.2,3.03],[1,95,15.9],[2,990,2.2]],"ltp":1.58,"tv":907.71,"id":2263634}],"tv":979.92}]}
{"op":"mcm","clk":"1004587561","pt":1580633176062,"mc":[{"id":"1.168224441","rc":[{"batl":[[1,95,15.9],[2,990,2.2]],"ltp":2.72,"tv":72.21,"id":10894176}]}]}
{"op":"mcm","clk":"1004588660","pt":1580633197878,"mc":[{"id":"1.168224441","rc":[{"trd":[[2.72,58.56]],"batl":[[0,2.72,8.65]],"ltp":2.72,"tv":75.16,"id":10894176},{"trd":[[1.58,882.41]],"ltp":1.58,"tv":912.77,"id":2263634}],"tv":987.93}]}
{"op":"mcm","clk":"1004589802","pt":1580633228013,"mc":[{"id":"1.168224441","rc":[{"batb":[[0,1.58,151.45],[1,1.55,326.37],[2,1.41,37.86]],"ltp":1.58,"tv":912.77,"id":2263634}]}]}
{"op":"mcm","clk":"1004590225","pt":1580633236415,"mc":[{"id":"1.168224441","rc":[{"batb":[[0,2.08,53.81],[1,2.02,11.76],[2,2,37.86]],"ltp":2.72,"tv":75.16,"id":10894176},{"batb":[[0,1.58,461.91],[1,1.55,15.9]],"ltp":1.58,"tv":912.77,"id":2263634}]}]}
{"op":"mcm","clk":"1004590573","pt":1580633244419,"mc":[{"id":"1.168224441","rc":[{"batb":[[1,1.41,37.86],[2,1.4,530.06]],"ltp":1.58,"tv":912.77,"id":2263634}]}]}
{"op":"mcm","clk":"1004590576","pt":1580633244519,"mc":[{"id":"1.168224441","rc":[{"batb":[[0,1.58,477.81]],"ltp":1.58,"tv":912.77,"id":2263634}]}]}
{"op":"mcm","clk":"1004592503","pt":1580633290995,"mc":[{"id":"1.168224441","rc":[{"batb":[[1,2,37.86],[2,1.81,37.86]],"ltp":2.72,"tv":75.16,"id":10894176}]}]}
{"op":"mcm","clk":"1004595126","pt":1580633349954,"mc":[{"id":"1.168224441","rc":[{"batb":[[2,1.31,37.86]],"ltp":1.58,"tv":912.77,"id":2263634}]}]}
{"op":"mcm","clk":"1004604954","pt":1580633572468,"mc":[{"id":"1.168224441","rc":[{"batb":[[0,1.6,8],[1,1.58,477.81],[2,1.41,37.86]],"ltp":1.58,"tv":912.77,"id":2263634}]}]}
{"op":"mcm","clk":"1004605990","pt":1580633599887,"mc":[{"id":"1.168224441","rc":[{"batb":[[0,1.58,477.81],[1,1.41,37.86],[2,1.31,37.86]],"ltp":1.58,"tv":912.77,"id":2263634}]}]}
{"op":"mcm","clk":"1004621406","pt":1580633913393,"mc":[{"id":"1.168224441","rc":[{"batb":[[0,2,37.86],[1,1.81,37.86],[2,1.71,37.86]],"ltp":2.72,"tv":75.16,"id":10894176}]}]}
{"op":"mcm","clk":"1004621415","pt":1580633913496,"mc":[{"id":"1.168224441","rc":[{"batb":[[0,2.08,48.81],[1,2,37.86],[2,1.81,37.86]],"batl":[[0,2.64,43.68],[1,2.72,8.65],[2,95,15.9]],"ltp":2.72,"tv":75.16,"id":10894176}]}]}
{"op":"mcm","clk":"1004625322","pt":1580633982114,"mc":[{"id":"1.168224441","rc":[{"batb":[[0,1.41,37.86],[1,1.31,37.86],[2,1.21,53.01]],"ltp":1.58,"tv":912.77,"id":2263634}]}]}
{"op":"mcm","clk":"1004626103","pt":1580633996422,"mc":[{"id":"1.168224441","rc":[{"batb":[[2,1.98,29.37]],"ltp":2.72,"tv":75.16,"id":10894176},{"batb":[[0,1.55,52.32],[1,1.41,37.86],[2,1.31,37.86]],"ltp":1.58,"tv":912.77,"id":2263634}]}]}
{"op":"mcm","clk":"1004626875","pt":1580634006946,"mc":[{"id":"1.168224441","rc":[{"batb":[[0,1.61,477.81],[1,1.55,52.32],[2,1.41,37.86]],"ltp":1.58,"tv":912.77,"id":2263634}]}]}
{"op":"mcm","clk":"1004630175","pt":1580634058425,"mc":[{"id":"1.168224441","rc":[{"batb":[[0,2.1,43.16],[1,2.08,48.81],[2,2,37.86]],"ltp":2.72,"tv":75.16,"id":10894176},{"batb":[[1,1.56,58.31],[2,1.55,52.32]],"ltp":1.58,"tv":912.77,"id":2263634}]}]}
{"op":"mcm","clk":"1004632203","pt":1580634090879,"mc":[{"id":"1.168224441","rc":[{"batb":[[1,1.57,43.16]],"ltp":1.58,"tv":912.77,"id":2263634}]}]}
{"op":"mcm","clk":"1004633397","pt":1580634115378,"mc":[{"id":"1.168224441","rc":[{"batb":[[0,2.24,51.52],[1,2.1,43.16],[2,2.08,48.81]],"ltp":2.72,"tv":75.16,"id":10894176},{"batb":[[0,1.67,69.23],[1,1.61,477.81],[2,1.57,43.16]],"ltp":1.58,"tv":912.77,"id":2263634}]}]}
{"op":"mcm","clk":"1004637739","pt":1580634208407,"mc":[{"id":"1.168224441","rc":[{"batb":[[2,1.55,52.32]],"ltp":1.58,"tv":912.77,"id":2263634}]}]}
{"op":"mcm","clk":"1004637745","pt":1580634208503,"mc":[{"id":"1.168224441","rc":[{"batb":[[2,1.58,43.16]],"ltp":1.58,"tv":912.77,"id":2263634}]}]}
{"op":"mcm","clk":"1004639851","pt":1580634255779,"mc":[{"id":"1.168224441","rc":[{"batb":[[2,1.58,57.55]],"ltp":1.58,"tv":912.77,"id":2263634}]}]}
{"op":"mcm","clk":"1004639927","pt":1580634257380,"mc":[{"id":"1.168224441","rc":[{"batl":[[0,2.5,8.4],[1,2.64,43.68],[2,2.72,8.65]],"ltp":2.72,"tv":75.16,"id":10894176},{"batb":[[0,1.67,81.78]],"batl":[[0,1.81,8.4],[1,2.2,3.03],[2,95,15.9]],"ltp":1.58,"tv":912.77,"id":2263634}]}]}
{"op":"mcm","clk":"1004639937","pt":1580634257585,"mc":[{"id":"1.168224441","rc":[{"batb":[[0,2.24,58.29]],"ltp":2.72,"tv":75.16,"id":10894176}]}]}
{"op":"mcm","clk":"1004659859","pt":1580634690893,"mc":[{"id":"1.168224441","rc":[{"batb":[[2,2,37.86]],"batl":[[1,2.72,8.65],[2,95,15.9]],"ltp":2.72,"tv":75.16,"id":10894176}]}]}
{"op":"mcm","clk":"1004676369","pt":1580635005482,"mc":[{"id":"1.168224441","rc":[{"batb":[[0,2.26,46.98],[1,2.24,58.29],[2,2.1,43.16]],"ltp":2.72,"tv":75.16,"id":10894176}]}]}
{"op":"mcm","clk":"1004676628","pt":1580635010109,"mc":[{"id":"1.168224441","rc":[{"batb":[[2,2.22,43.16]],"ltp":2.72,"tv":75.16,"id":10894176},{"batb":[[2,1.51,94.28]],"ltp":1.58,"tv":912.77,"id":2263634}]}]}
{"op":"mcm","clk":"1004677325","pt":1580635021787,"mc":[{"id":"1.168224441","rc":[{"batb":[[2,2.2,43.16]],"ltp":2.72,"tv":75.16,"id":10894176},{"batb":[[2,1.55,59.06]],"ltp":1.58,"tv":912.77,"id":2263634}]}]}
{"op":"mcm","clk":"1004677429","pt":1580635023892,"mc":[{"id":"1.168224441","rc":[{"batb":[[0,2.24,58.29],[1,2.2,43.16],[2,2.06,27.15]],"ltp":2.72,"tv":75.16,"id":10894176}]}]}
{"op":"mcm","clk":"1004677615","pt":1580635027229,"mc":[{"id":"1.168224441","rc":[{"batb":[[1,2.02,28.21],[2,2,37.86]],"ltp":2.72,"tv":75.16,"id":10894176},{"batb":[[2,1.59,59.06]],"ltp":1.58,"tv":912.77,"id":2263634}]}]}
{"op":"mcm","clk":"1004678287","pt":1580635040395,"mc":[{"id":"1.168224441","rc":[{"batb":[[1,2.16,42.4],[2,2.02,28.21]],"ltp":2.72,"tv":75.16,"id":10894176},{"batb":[[2,1.58,42.4]],"ltp":1.58,"tv":912.77,"id":2263634}]}]}
{"op":"mcm","clk":"1004684005","pt":1580635148547,"mc":[{"id":"1.168224441","rc":[{"batl":[[0,1.8,7.57],[1,1.81,8.4],[2,2.2,3.03]],"ltp":1.58,"tv":912.77,"id":2263634}]}]}
{"op":"mcm","clk":"1004684489","pt":1580635158161,"mc":[{"id":"1.168224441","rc":[{"batb":[[2,1.58,57.55]],"ltp":1.58,"tv":912.77,"id":2263634}]}]}
{"op":"mcm","clk":"1004684544","pt":1580635159243,"mc":[{"id":"1.168224441","rc":[{"batl":[[1,2.2,3.03],[2,95,15.9]],"ltp":1.58,"tv":912.77,"id":2263634}]}]}
{"op":"mcm","clk":"1004684573","pt":1580635159765,"mc":[{"id":"1.168224441","rc":[{"batl":[[0,1.8,15.97]],"ltp":1.58,"tv":912.77,"id":2263634}]}]}
{"op":"mcm","clk":"1004697998","pt":1580635474241,"mc":[{"id":"1.168224441","rc":[{"batb":[[2,2,37.86]],"ltp":2.72,"tv":75.16,"id":10894176}]}]}
{"op":"mcm","clk":"1004698027","pt":1580635474868,"mc":[{"id":"1.168224441","rc":[{"batb":[[2,2.02,37.12]],"ltp":2.72,"tv":75.16,"id":10894176}]}]}
{"op":"mcm","clk":"1004708855","pt":1580635722443,"mc":[{"id":"1.168224441","rc":[{"batb":[[0,1.7,82.42],[1,1.67,81.78],[2,1.61,477.81]],"ltp":1.58,"tv":912.77,"id":2263634}]}]}
{"op":"mcm","clk":"1004708887","pt":1580635723163,"mc":[{"id":"1.168224441","rc":[{"batb":[[2,2,37.86]],"ltp":2.72,"tv":75.16,"id":10894176},{"batb":[[0,1.67,81.78],[1,1.61,477.81],[2,1.58,57.55]],"ltp":1.58,"tv":912.77,"id":2263634}]}]}
{"op":"mcm","clk":"1004708912","pt":1580635723777,"mc":[{"id":"1.168224441","rc":[{"batb":[[1,1.63,60.1],[2,1.61,477.81]],"ltp":1.58,"tv":912.77,"id":2263634}]}]}
{"op":"mcm","clk":"1004708967","pt":1580635724960,"mc":[{"id":"1.168224441","rc":[{"batb":[[1,2,37.86],[2,1.88,43.03]],"ltp":2.72,"tv":75.16,"id":10894176}]}]}
{"op":"mcm","clk":"1004709028","pt":1580635726039,"mc":[{"id":"1.168224441","rc":[{"batb":[[2,1.94,40.28]],"ltp":2.72,"tv":75.16,"id":10894176},{"batb":[[1,1.61,477.81],[2,1.58,57.55]],"ltp":1.58,"tv":912.77,"id":2263634}]}]}
{"op":"mcm","clk":"1004710545","pt":1580635761979,"mc":[{"id":"1.168224441","rc":[{"batb":[[0,2.42,42.01],[1,2.24,58.29],[2,2,37.86]],"ltp":2.72,"tv":75.16,"id":10894176},{"batl":[[0,1.8,8.4]],"ltp":1.58,"tv":912.77,"id":2263634}]}]}
{"op":"mcm","clk":"1004711352","pt":1580635782425,"mc":[{"id":"1.168224441","rc":[{"batl":[[0,2.2,3.03],[1,95,15.9],[2,990,2.2]],"ltp":1.58,"tv":912.77,"id":2263634}]}]}
{"op":"mcm","clk":"1004711385","pt":1580635783197,"mc":[{"id":"1.168224441","rc":[{"batb":[[1,2.24,51.52]],"ltp":2.72,"tv":75.16,"id":10894176},{"batl":[[0,1.71,8.4],[1,2.2,3.03],[2,95,15.9]],"ltp":1.58,"tv":912.77,"id":2263634}]}]}
{"op":"mcm","clk":"1004711392","pt":1580635783522,"mc":[{"id":"1.168224441","rc":[{"batb":[[0,2.42,47.92]],"ltp":2.72,"tv":75.16,"id":10894176}]}]}
{"op":"mcm","clk":"1004714181","pt":1580635853426,"mc":[{"id":"1.168224441","rc":[{"trd":[[2.42,77.06]],"batb":[[0,2.42,9.39],[1,2.3,47.68]],"ltp":2.42,"tv":152.22,"id":10894176},{"batb":[[0,1.67,50.09]],"ltp":1.58,"tv":912.77,"id":2263634}],"tv":1064.99}]}
{"op":"mcm","clk":"1004715352","pt":1580635885153,"mc":[{"id":"1.168224441","rc":[{"trd":[[2.42,88.84]],"batb":[[0,2.42,3.5]],"ltp":2.42,"tv":164.0,"id":10894176}],"tv":1076.77}]}
{"op":"mcm","clk":"1004717267","pt":1580635929068,"mc":[{"id":"1.168224441","rc":[{"batb":[[0,2.42,45.51]],"ltp":2.42,"tv":164.0,"id":10894176}]}]}
{"op":"mcm","clk":"1004717319","pt":1580635930202,"mc":[{"id":"1.168224441","rc":[{"trd":[[2.42,148.02]],"batb":[[0,2.42,15.92]],"ltp":2.42,"tv":223.18,"id":10894176}],"tv":1135.95}]}
{"op":"mcm","clk":"1004717974","pt":1580635944522,"mc":[{"id":"1.168224441","rc":[{"batl":[[2,4,3.03]],"ltp":1.58,"tv":912.77,"id":2263634}]}]}
{"op":"mcm","clk":"1004718124","pt":1580635947629,"mc":[{"id":"1.168224441","rc":[{"trd":[[2.42,179.87]],"batb":[[0,2.3,47.68],[1,2,37.86],[2,1.94,40.28]],"ltp":2.42,"tv":255.02,"id":10894176}],"tv":1167.8}]}
{"op":"mcm","clk":"1004718470","pt":1580635955120,"mc":[{"id":"1.168224441","rc":[{"batl":[[2,4,3.79]],"ltp":1.58,"tv":912.77,"id":2263634}]}]}
{"op":"mcm","clk":"1004719179","pt":1580635970267,"mc":[{"id":"1.168224441","rc":[{"batl":[[1,2.2,3.79],[2,95,15.9]],"ltp":1.58,"tv":912.77,"id":2263634}]}]}
{"op":"mcm","clk":"1004719219","pt":1580635971157,"mc":[{"id":"1.168224441","rc":[{"trd":[[1.71,10.54]],"batl":[[0,1.71,3.13]],"ltp":1.71,"tv":923.31,"id":2263634}],"tv":1178.34}]}
{"op":"mcm","clk":"1004720019","pt":1580635988766,"mc":[{"id":"1.168224441","rc":[{"batb":[[0,2.4,84.02],[1,2.3,47.68],[2,2,37.86]],"ltp":2.42,"tv":255.02,"id":10894176}]}]}
{"op":"mcm","clk":"1004720055","pt":1580635989487,"mc":[{"id":"1.168224441","rc":[{"batl":[[0,1.71,12.37]],"ltp":1.71,"tv":923.31,"id":2263634}]}]}
{"op":"mcm","clk":"1004720594","pt":1580636002125,"mc":[{"id":"1.168224441","rc":[{"batl":[[0,1.71,9.23]],"ltp":1.71,"tv":923.31,"id":2263634}]}]}
{"op":"mcm","clk":"1004722640","pt":1580636047250,"mc":[{"id":"1.168224441","rc":[{"batb":[[0,2.42,84.02]],"ltp":2.42,"tv":255.02,"id":10894176},{"trd":[[1.71,22.46]],"batl":[[0,1.71,3.28]],"ltp":1.71,"tv":935.23,"id":2263634}],"tv":1190.25}]}
{"op":"mcm","clk":"1004732456","pt":1580636287956,"mc":[{"id":"1.168224441","rc":[{"batl":[[1,1.86,22.6],[2,2.2,3.03]],"ltp":1.71,"tv":935.23,"id":2263634}]}]}
{"op":"mcm","clk":"1004732482","pt":1580636288467,"mc":[{"id":"1.168224441","rc":[{"trd":[[2.42,255.87]],"batb":[[0,2.42,46.02]],"ltp":2.42,"tv":331.02,"id":10894176}],"tv":1266.25}]}
{"op":"mcm","clk":"1004732523","pt":1580636289459,"mc":[{"id":"1.168224441","rc":[{"batl":[[0,1.86,22.6],[1,2.2,3.03],[2,95,15.9]],"ltp":1.71,"tv":935.23,"id":2263634}]}]}
{"op":"mcm","clk":"1004733504","pt":1580636312008,"mc":[{"id":"1.168224441","rc":[{"batb":[[2,2.02,37.12]],"ltp":2.42,"tv":331.02,"id":10894176},{"batb":[[2,1.52,72.81]],"ltp":1.71,"tv":935.23,"id":2263634}]}]}
{"op":"mcm","clk":"1004747640","pt":1580636582355,"mc":[{"id":"1.168224441","rc":[{"batl":[[1,2.2,77.24]],"ltp":1.71,"tv":935.23,"id":2263634}]}]}
{"op":"mcm","clk":"1004747660","pt":1580636582662,"mc":[{"id":"1.168224441","rc":[{"trd":[[2.42,318.91]],"batb":[[0,2.42,14.49]],"ltp":2.42,"tv":394.07,"id":10894176}],"tv":1329.3}]}
{"op":"mcm","clk":"1004759458","pt":1580636845938,"mc":[{"id":"1.168224441","rc":[{"trd":[[2.3,65.34],[2.42,347.9]],"batb":[[0,2.3,15.01],[1,2.02,37.12],[2,2,37.86]],"ltp":2.3,"tv":488.39,"id":10894176}],"tv":1423.62}]}
{"op":"mcm","clk":"1004759535","pt":1580636847128,"mc":[{"id":"1.168224441","rc":[{"batb":[[0,2.24,62.27],[1,2.22,51.57],[2,2.02,37.12]],"ltp":2.3,"tv":488.39,"id":10894176},{"batb":[[0,1.68,70.44],[1,1.67,12.54],[2,1.61,477.81]],"ltp":1.71,"tv":935.23,"id":2263634}]}]}
{"op":"mcm","clk":"1004759628","pt":1580636848636,"mc":[{"id":"1.168224441","rc":[{"batb":[[1,1.67,18.64]],"ltp":1.71,"tv":935.23,"id":2263634}]}]}
{"op":"mcm","clk":"1004760668","pt":1580636867163,"mc":[{"id":"1.168224441","rc":[{"batl":[[0,2.72,8.65],[1,95,15.9],[2,990,2.2]],"ltp":2.3,"tv":488.39,"id":10894176},{"batb":[[1,1.67,6.1]],"ltp":1.71,"tv":935.23,"id":2263634}]}]}
{"op":"mcm","clk":"1004760690","pt":1580636867674,"mc":[{"id":"1.168224441","rc":[{"batl":[[0,2.48,12.6],[1,2.72,8.65],[2,95,15.9]],"ltp":2.3,"tv":488.39,"id":10894176},{"batb":[[0,1.68,88.98],[1,1.61,477.81],[2,1.52,72.81]],"ltp":1.71,"tv":935.23,"id":2263634}]}]}
{"op":"mcm","clk":"1004760783","pt":1580636869370,"mc":[{"id":"1.168224441","rc":[{"batb":[[0,1.69,6.02],[1,1.68,88.98],[2,1.61,477.81]],"ltp":1.71,"tv":935.23,"id":2263634}]}]}
{"op":"mcm","clk":"1004762236","pt":1580636899251,"mc":[{"id":"1.168224441","rc":[{"batl":[[0,2.46,12.6]],"ltp":2.3,"tv":488.39,"id":10894176},{"batb":[[1,1.68,70.44]],"ltp":1.71,"tv":935.23,"id":2263634}]}]}
{"op":"mcm","clk":"1004762250","pt":1580636899456,"mc":[{"id":"1.168224441","rc":[{"batb":[[0,1.69,24.29]],"ltp":1.71,"tv":935.23,"id":2263634}]}]}
{"op":"mcm","clk":"1004762372","pt":1580636901717,"mc":[{"id":"1.168224441","rc":[{"batb":[[0,2.26,33.04],[1,2.24,62.27]],"ltp":2.3,"tv":488.39,"id":10894176},{"batb":[[0,1.7,48.46],[1,1.69,24.29]],"ltp":1.71,"tv":935.23,"id":2263634}]}]}
{"op":"mcm","clk":"1004763908","pt":1580636931298,"mc":[{"id":"1.168224441","rc":[{"batb":[[1,2.02,37.12],[2,2,37.86]],"batl":[[0,2.44,12.6]],"ltp":2.3,"tv":488.39,"id":10894176},{"batb":[[0,1.7,66.47],[1,1.61,477.81],[2,1.52,72.81]],"ltp":1.71,"tv":935.23,"id":2263634}]}]}
{"op":"mcm","clk":"1004763974","pt":1580636932482,"mc":[{"id":"1.168224441","rc":[{"batb":[[0,1.7,72.46]],"ltp":1.71,"tv":935.23,"id":2263634}]}]}
{"op":"mcm","clk":"1004767528","pt":1580636995087,"mc":[{"id":"1.168224441","rc":[{"trd":[[2.4,130.46]],"batb":[[0,2.4,18.79],[1,2.26,33.04],[2,2.02,37.12]],"ltp":2.4,"tv":618.85,"id":10894176}],"tv":1554.09}]}
{"op":"mcm","clk":"1004767639","pt":1580636996876,"mc":[{"id":"1.168224441","rc":[{"trd":[[2.4,168.04]],"batb":[[0,2.26,33.04],[1,2.02,37.12],[2,2,37.86]],"ltp":2.4,"tv":656.43,"id":10894176}],"tv":1591.66}]}
{"op":"mcm","clk":"1004769724","pt":1580637032333,"mc":[{"id":"1.168224441","rc":[{"batb":[[0,2.22,51.57]],"ltp":2.4,"tv":656.43,"id":10894176}]}]}
{"op":"mcm","clk":"1004769745","pt":1580637032748,"mc":[{"id":"1.168224441","rc":[{"batl":[[0,1.84,76.87],[1,1.86,21.85],[2,2.2,77.24]],"ltp":1.71,"tv":935.23,"id":2263634}]}]}
{"op":"mcm","clk":"1004775133","pt":1580637135018,"mc":[{"id":"1.168224441","rc":[{"batb":[[0,2.24,62.27],[1,2.22,51.57],[2,2.02,37.12]],"ltp":2.4,"tv":656.43,"id":10894176},{"batl":[[0,1.81,3.03]],"ltp":1.71,"tv":935.23,"id":2263634}]}]}
{"op":"mcm","clk":"1004776411","pt":1580637155168,"mc":[{"id":"1.168224441","rc":[{"batl":[[0,1.78,8.33],[1,1.81,2.27],[2,1.86,21.85]],"ltp":1.71,"tv":935.23,"id":2263634}]}]}
{"op":"mcm","clk":"1004776683","pt":1580637160366,"mc":[{"id":"1.168224441","rc":[{"batb":[[0,2.26,33.04],[1,2.24,62.27]],"ltp":2.4,"tv":656.43,"id":10894176}]}]}
{"op":"mcm","clk":"1004776691","pt":1580637160470,"mc":[{"id":"1.168224441","rc":[{"batb":[[1,2.02,37.12],[2,2,37.86]],"ltp":2.4,"tv":656.43,"id":10894176}]}]}
{"op":"mcm","clk":"1004778799","pt":1580637200963,"mc":[{"id":"1.168224441","rc":[{"batb":[[0,2.38,42.01],[1,2.26,33.04],[2,2.02,37.12]],"ltp":2.4,"tv":656.43,"id":10894176}]}]}
{"op":"mcm","clk":"1004781049","pt":1580637247836,"mc":[{"id":"1.168224441","rc":[{"trd":[[2.38,84.02]],"batb":[[0,2.26,33.04],[1,2.02,37.12],[2,2,37.86]],"ltp":2.38,"tv":740.45,"id":10894176}],"tv":1675.68}]}
{"op":"mcm","clk":"1004781231","pt":1580637251302,"mc":[{"id":"1.168224441","rc":[{"batb":[[1,2,37.86],[2,1.98,38.63]],"ltp":2.38,"tv":740.45,"id":10894176},{"batb":[[2,1.55,68.84]],"ltp":1.71,"tv":935.23,"id":2263634}]}]}
{"op":"mcm","clk":"1004783175","pt":1580637290281,"mc":[{"id":"1.168224441","rc":[{"batb":[[0,2.22,51.57]],"ltp":2.38,"tv":740.45,"id":10894176}]}]}
{"op":"mcm","clk":"1004785964","pt":1580637350399,"mc":[{"id":"1.168224441","rc":[{"trd":[[2.44,62.2]],"batb":[[0,2,37.86],[1,1.98,38.63],[2,1.81,37.86]],"batl":[[0,2.72,8.65],[1,95,15.9],[2,990,2.2]],"ltp":2.44,"tv":802.65,"id":10894176},{"trd":[[1.7,53.11]],"batb":[[0,1.7,19.35]],"ltp":1.7,"tv":988.33,"id":2263634}],"tv":1790.99}]}
{"op":"mcm","clk":"1004785987","pt":1580637350811,"mc":[{"id":"1.168224441","rc":[{"batb":[[0,2.3,50.75],[1,2,37.86],[2,1.98,38.63]],"ltp":2.44,"tv":802.65,"id":10894176},{"batb":[[0,1.7,13.36],[1,1.64,68.6],[2,1.61,477.81]],"ltp":1.7,"tv":988.33,"id":2263634}]}]}
{"op":"mcm","clk":"1004786093","pt":1580637353036,"mc":[{"id":"1.168224441","rc":[{"batl":[[0,1.76,7.57],[1,1.78,8.33],[2,1.81,2.27]],"ltp":1.7,"tv":988.33,"id":2263634}]}]}
{"op":"mcm","clk":"1004786191","pt":1580637354895,"mc":[{"id":"1.168224441","rc":[{"batl":[[1,1.81,3.03],[2,1.86,21.85]],"ltp":1.7,"tv":988.33,"id":2263634}]}]}
{"op":"mcm","clk":"1004786648","pt":1580637364143,"mc":[{"id":"1.168224441","rc":[{"batb":[[0,2.3,57.21]],"ltp":2.44,"tv":802.65,"id":10894176},{"batl":[[0,1.76,15.97]],"ltp":1.7,"tv":988.33,"id":2263634}]}]}
{"op":"mcm","clk":"1004789109","pt":1580637400400,"mc":[{"id":"1.168224441","rc":[{"trd":[[2.44,71.51]],"batb":[[0,2.44,21.79],[1,2.3,57.21],[2,2.22,37.86]],"ltp":2.44,"tv":811.96,"id":10894176},{"trd":[[1.7,66.47]],"batb":[[0,1.64,68.6],[1,1.61,477.81],[2,1.55,68.84]],"ltp":1.7,"tv":1001.69,"id":2263634}],"tv":1813.66}]}
{"op":"mcm","clk":"1004789117","pt":1580637400504,"mc":[{"id":"1.168224441","rc":[{"trd":[[2.44,101.49]],"batb":[[0,2.44,6.8]],"ltp":2.44,"tv":841.94,"id":10894176}],"tv":1843.64}]}
{"op":"mcm","clk":"1004789230","pt":1580637401901,"mc":[{"id":"1.168224441","rc":[{"batl":[[0,2.62,8.42],[1,2.72,8.65],[2,95,15.9]],"ltp":2.44,"tv":841.94,"id":10894176},{"batb":[[1,1.62,16.43],[2,1.61,477.81]],"ltp":1.7,"tv":1001.69,"id":2263634}]}]}
{"op":"mcm","clk":"1004790905","pt":1580637426436,"mc":[{"id":"1.168224441","rc":[{"batb":[[1,2.3,50.75]],"ltp":2.44,"tv":841.94,"id":10894176},{"batl":[[0,1.76,7.57]],"ltp":1.7,"tv":1001.69,"id":2263634}]}]}
{"op":"mcm","clk":"1004790955","pt":1580637427207,"mc":[{"id":"1.168224441","rc":[{"batb":[[0,2.44,15.55]],"ltp":2.44,"tv":841.94,"id":10894176},{"batl":[[0,1.7,12.6],[1,1.76,7.57],[2,1.81,3.03]],"ltp":1.7,"tv":1001.69,"id":2263634}]}]}
{"op":"mcm","clk":"1004809763","pt":1580637720714,"mc":[{"id":"1.168224441","rc":[{"trd":[[2.44,123.21]],"batb":[[0,2.44,4.7],[1,2.38,84.02],[2,2.3,50.75]],"ltp":2.44,"tv":863.66,"id":10894176}],"tv":1865.36}]}
{"op":"mcm","clk":"1004834690","pt":1580638092146,"mc":[{"id":"1.168224441","rc":[{"trd":[[2.44,132.6]],"batb":[[0,2.38,84.02],[1,2.3,50.75],[2,2.22,37.86]],"ltp":2.44,"tv":873.05,"id":10894176}],"tv":1874.74}]}
{"op":"mcm","clk":"1004834763","pt":1580638093174,"mc":[{"id":"1.168224441","rc":[{"trd":[[1.7,84.11]],"batl":[[0,1.7,3.78]],"ltp":1.7,"tv":1019.34,"id":2263634}],"tv":1892.39}]}
{"op":"mcm","clk":"1004835777","pt":1580638108265,"mc":[{"id":"1.168224441","rc":[{"batb":[[0,2.42,5.91],[1,2.38,84.02],[2,2.3,50.75]],"batl":[[0,2.58,8.4],[1,2.62,8.42],[2,2.72,8.65]],"ltp":2.44,"tv":873.05,"id":10894176},{"trd":[[1.7,90.97]],"batb":[[0,1.67,89.23],[1,1.64,81.73],[2,1.62,16.43]],"batl":[[0,1.7,4.97]],"ltp":1.7,"tv":1026.19,"id":2263634}],"tv":1899.24}]}
{"op":"mcm","clk":"1004835848","pt":1580638109404,"mc":[{"id":"1.168224441","rc":[{"batl":[[1,2.72,8.65],[2,95,15.9]],"ltp":2.44,"tv":873.05,"id":10894176},{"batb":[[0,1.68,6.07],[1,1.67,89.23],[2,1.64,81.73]],"ltp":1.7,"tv":1026.19,"id":2263634}]}]}
{"op":"mcm","clk":"1004835910","pt":1580638110197,"mc":[{"id":"1.168224441","rc":[{"batb":[[1,1.64,81.73],[2,1.61,477.81]],"ltp":1.7,"tv":1026.19,"id":2263634}]}]}
{"op":"mcm","clk":"1004835982","pt":1580638111282,"mc":[{"id":"1.168224441","rc":[{"batb":[[0,1.64,81.73],[1,1.61,477.81],[2,1.58,65.28]],"ltp":1.7,"tv":1026.19,"id":2263634}]}]}
{"op":"mcm","clk":"1004836165","pt":1580638114401,"mc":[{"id":"1.168224441","rc":[{"batl":[[1,2.62,8.73],[2,2.72,8.65]],"ltp":2.44,"tv":873.05,"id":10894176}]}]}
{"op":"mcm","clk":"1004836174","pt":1580638114608,"mc":[{"id":"1.168224441","rc":[{"batb":[[0,1.66,89.78],[1,1.64,81.73],[2,1.61,477.81]],"ltp":1.7,"tv":1026.19,"id":2263634}]}]}
{"op":"mcm","clk":"1004836283","pt":1580638116433,"mc":[{"id":"1.168224441","rc":[{"batl":[[1,2.72,8.65],[2,95,15.9]],"ltp":2.44,"tv":873.05,"id":10894176}]}]}
{"op":"mcm","clk":"1004836297","pt":1580638116639,"mc":[{"id":"1.168224441","rc":[{"batb":[[0,1.67,6.1],[1,1.66,89.78],[2,1.64,81.73]],"ltp":1.7,"tv":1026.19,"id":2263634}]}]}
{"op":"mcm","clk":"1004837798","pt":1580638139222,"mc":[{"id":"1.168224441","rc":[{"batl":[[0,2.72,8.65],[1,95,15.9],[2,990,2.2]],"ltp":2.44,"tv":873.05,"id":10894176}]}]}
{"op":"mcm","clk":"1004837859","pt":1580638140308,"mc":[{"id":"1.168224441","rc":[{"batl":[[0,2.5,8.4],[1,2.72,8.65],[2,95,15.9]],"ltp":2.44,"tv":873.05,"id":10894176},{"batb":[[0,1.67,95.33],[1,1.64,68.6],[2,1.61,477.81]],"ltp":1.7,"tv":1026.19,"id":2263634}]}]}
{"op":"mcm","clk":"1004837877","pt":1580638140517,"mc":[{"id":"1.168224441","rc":[{"batb":[[0,1.67,107.87]],"ltp":1.7,"tv":1026.19,"id":2263634}]}]}
{"op":"mcm","clk":"1004842525","pt":1580638204186,"mc":[{"id":"1.168224441","rc":[{"batb":[[0,1.68,22.02],[1,1.67,107.87]],"ltp":1.7,"tv":1026.19,"id":2263634}]}]}
{"op":"mcm","clk":"1004842730","pt":1580638207302,"mc":[{"id":"1.168224441","rc":[{"batb":[[1,1.67,18.64]],"ltp":1.7,"tv":1026.19,"id":2263634}]}]}
{"op":"mcm","clk":"1004842829","pt":1580638208812,"mc":[{"id":"1.168224441","rc":[{"batb":[[1,1.67,12.54]],"ltp":1.7,"tv":1026.19,"id":2263634}]}]}
{"op":"mcm","clk":"1004844630","pt":1580638233860,"mc":[{"id":"1.168224441","rc":[{"batl":[[0,2.72,8.65],[1,95,15.9],[2,990,2.2]],"ltp":2.44,"tv":873.05,"id":10894176}]}]}
{"op":"mcm","clk":"1004844706","pt":1580638235063,"mc":[{"id":"1.168224441","rc":[{"batl":[[0,2.48,8.4],[1,2.72,8.65],[2,95,15.9]],"ltp":2.44,"tv":873.05,"id":10894176},{"batb":[[0,1.68,34.38],[1,1.61,477.81],[2,1.58,65.28]],"ltp":1.7,"tv":1026.19,"id":2263634}]}]}
{"op":"mcm","clk":"1004852183","pt":1580638333918,"mc":[{"id":"1.168224441","rc":[{"batb":[[0,1.68,12.36],[1,1.64,68.6],[2,1.61,477.81]],"ltp":1.7,"tv":1026.19,"id":2263634}]}]}
{"op":"mcm","clk":"1004853315","pt":1580638347326,"mc":[{"id":"1.168224441","rc":[{"trd":[[2.42,359.73]],"batb":[[0,2.38,84.02],[1,2.3,50.75],[2,2.22,37.86]],"ltp":2.42,"tv":884.88,"id":10894176},{"trd":[[1.7,94.97]],"batl":[[0,1.7,2.97]],"ltp":1.7,"tv":1030.19,"id":2263634}],"tv":1915.07}]}
{"op":"mcm","clk":"1004853395","pt":1580638348206,"mc":[{"id":"1.168224441","rc":[{"trd":[[1.7,100.92]],"batl":[[0,1.76,7.57],[1,1.81,3.03],[2,1.86,21.85]],"ltp":1.7,"tv":1036.14,"id":2263634}],"tv":1921.02}]}
{"op":"mcm","clk":"1004856377","pt":1580638388345,"mc":[{"id":"1.168224441","rc":[{"trd":[[2.38,208.92]],"batb":[[0,2.38,21.57]],"ltp":2.38,"tv":1009.78,"id":10894176},{"batb":[[0,1.69,86.21],[1,1.68,12.36],[2,1.64,68.6]],"ltp":1.7,"tv":1036.14,"id":2263634}],"tv":2045.92}]}
{"op":"mcm","clk":"1004856394","pt":1580638388550,"mc":[{"id":"1.168224441","rc":[{"batb":[[0,1.7,5.99],[1,1.69,86.21],[2,1.68,12.36]],"ltp":1.7,"tv":1036.14,"id":2263634}]}]}
{"op":"mcm","clk":"1004856529","pt":1580638389966,"mc":[{"id":"1.168224441","rc":[{"batb":[[2,2,83.3]],"ltp":2.38,"tv":1009.78,"id":10894176},{"batb":[[1,1.68,12.36],[2,1.64,68.6]],"ltp":1.7,"tv":1036.14,"id":2263634}]}]}
{"op":"mcm","clk":"1004856637","pt":1580638391276,"mc":[{"id":"1.168224441","rc":[{"batl":[[0,2.72,8.65],[1,95,15.9],[2,990,2.2]],"ltp":2.38,"tv":1009.78,"id":10894176},{"batb":[[0,1.64,68.6],[1,1.61,477.81],[2,1.6,63.1]],"ltp":1.7,"tv":1036.14,"id":2263634}]}]}
{"op":"mcm","clk":"1004856680","pt":1580638391742,"mc":[{"id":"1.168224441","rc":[{"batl":[[0,2.44,12.6],[1,2.72,8.65],[2,95,15.9]],"ltp":2.38,"tv":1009.78,"id":10894176},{"batb":[[0,1.7,18.01],[1,1.65,88.33],[2,1.64,68.6]],"ltp":1.7,"tv":1036.14,"id":2263634}]}]}
{"op":"mcm","clk":"1004856844","pt":1580638394390,"mc":[{"id":"1.168224441","rc":[{"batb":[[0,1.7,22.3],[1,1.64,68.6],[2,1.61,477.81]],"ltp":1.7,"tv":1036.14,"id":2263634}]}]}
{"op":"mcm","clk":"1004862361","pt":1580638464271,"mc":[{"id":"1.168224441","rc":[{"batb":[[2,2.08,45.43]],"ltp":2.38,"tv":1009.78,"id":10894176}]}]}
{"op":"mcm","clk":"1004862390","pt":1580638464544,"mc":[{"id":"1.168224441","rc":[{"trd":[[2.38,240.22]],"batb":[[0,2.38,5.91]],"ltp":2.38,"tv":1041.08,"id":10894176}],"tv":2077.23}]}
{"op":"mcm","clk":"1004862568","pt":1580638466834,"mc":[{"id":"1.168224441","rc":[{"batb":[[2,2.06,45.43]],"ltp":2.38,"tv":1041.08,"id":10894176}]}]}
{"op":"mcm","clk":"1004866370","pt":1580638509197,"mc":[{"id":"1.168224441","rc":[{"batb":[[2,2.06,81.15]],"ltp":2.38,"tv":1041.08,"id":10894176}]}]}
{"op":"mcm","clk":"1004866412","pt":1580638509526,"mc":[{"id":"1.168224441","rc":[{"trd":[[2.38,244.02]],"batb":[[0,2.38,2.12]],"ltp":2.38,"tv":1044.88,"id":10894176},{"trd":[[1.73,5.22]],"ltp":1.73,"tv":1041.36,"id":2263634}],"tv":2086.24}]}
{"op":"mcm","clk":"1004866663","pt":1580638512728,"mc":[{"id":"1.168224441","rc":[{"batb":[[2,2.22,45.43]],"ltp":2.38,"tv":1044.88,"id":10894176}]}]}
{"op":"mcm","clk":"1004866846","pt":1580638515417,"mc":[{"id":"1.168224441","rc":[{"batb":[[2,2.2,45.43]],"ltp":2.38,"tv":1044.88,"id":10894176}]}]}
{"op":"mcm","clk":"1004886880","pt":1580638772007,"mc":[{"id":"1.168224441","rc":[{"batb":[[2,2,75.72]],"ltp":2.38,"tv":1044.88,"id":10894176}]}]}
{"op":"mcm","clk":"1004886992","pt":1580638773421,"mc":[{"id":"1.168224441","rc":[{"trd":[[2.38,246.14]],"batb":[[0,2.3,50.75],[1,2,75.72],[2,1.81,37.86]],"ltp":2.38,"tv":1047.0,"id":10894176},{"trd":[[1.73,8.13],[1.76,4.72]],"batl":[[0,1.76,5.21]],"ltp":1.76,"tv":1048.99,"id":2263634}],"tv":2095.99}]}
{"op":"mcm","clk":"1004887148","pt":1580638775143,"mc":[{"id":"1.168224441","rc":[{"trd":[[1.75,4.76]],"batb":[[2,1.61,515.67]],"ltp":1.75,"tv":1053.75,"id":2263634}],"tv":2100.75}]}
{"op":"mcm","clk":"1004888135","pt":1580638786725,"mc":[{"id":"1.168224441","rc":[{"batb":[[1,2.14,42.4],[2,2,75.72]],"ltp":2.38,"tv":1047.0,"id":10894176}]}]}
{"op":"mcm","clk":"1004893126","pt":1580638848437,"mc":[{"id":"1.168224441","rc":[{"batb":[[1,2,75.72],[2,1.81,37.86]],"ltp":2.38,"tv":1047.0,"id":10894176}]}]}
{"op":"mcm","clk":"1004893221","pt":1580638849133,"mc":[{"id":"1.168224441","rc":[{"trd":[[2.3,140.9]],"batb":[[0,2.3,12.96],[1,2,37.86],[2,1.96,39.44]],"ltp":2.3,"tv":1122.56,"id":10894176}],"tv":2176.32}]}
{"op":"mcm","clk":"1004893282","pt":1580638849857,"mc":[{"id":"1.168224441","rc":[{"batb":[[0,2.22,49.59]],"ltp":2.3,"tv":1122.56,"id":10894176},{"batb":[[0,1.71,40.46],[1,1.7,22.3]],"ltp":1.75,"tv":1053.75,"id":2263634}]}]}
{"op":"mcm","clk":"1004893408","pt":1580638851313,"mc":[{"id":"1.168224441","rc":[{"batb":[[1,2.08,43.92],[2,2,37.86]],"ltp":2.3,"tv":1122.56,"id":10894176}]}]}
{"op":"mcm","clk":"1004893825","pt":1580638856254,"mc":[{"id":"1.168224441","rc":[{"batl":[[0,2.72,8.65],[1,95,15.9],[2,990,2.2]],"ltp":2.3,"tv":1122.56,"id":10894176}]}]}
{"op":"mcm","clk":"1004893915","pt":1580638857347,"mc":[{"id":"1.168224441","rc":[{"batl":[[0,2.42,12.6],[1,2.72,8.65],[2,95,15.9]],"ltp":2.3,"tv":1122.56,"id":10894176},{"batb":[[0,1.71,58.22],[1,1.7,4.29]],"ltp":1.75,"tv":1053.75,"id":2263634}]}]}
{"op":"mcm","clk":"1004894124","pt":1580638859548,"mc":[{"id":"1.168224441","rc":[{"batb":[[1,1.61,515.67],[2,1.57,42.4]],"ltp":1.75,"tv":1053.75,"id":2263634}]}]}
{"op":"mcm","clk":"1004894244","pt":1580638860954,"mc":[{"id":"1.168224441","rc":[{"trd":[[2.42,372.33]],"batl":[[0,2.72,8.65],[1,95,15.9],[2,990,2.2]],"ltp":2.42,"tv":1135.16,"id":10894176},{"trd":[[1.7,118.85],[1.71,138.89]],"batb":[[0,1.61,515.67],[1,1.57,42.4],[2,1.56,67.61]],"ltp":1.7,"tv":1188.12,"id":2263634}],"tv":2323.29}]}
{"op":"mcm","clk":"1004894372","pt":1580638862263,"mc":[{"id":"1.168224441","rc":[{"batb":[[0,1.62,6.28],[1,1.61,515.67],[2,1.57,42.4]],"ltp":1.7,"tv":1188.12,"id":2263634}]}]}
{"op":"mcm","clk":"1004894463","pt":1580638863251,"mc":[{"id":"1.168224441","rc":[{"batb":[[0,2.34,54.65]],"ltp":2.42,"tv":1135.16,"id":10894176},{"batb":[[0,1.63,51.01],[1,1.62,101.61],[2,1.61,515.67]],"ltp":1.7,"tv":1188.12,"id":2263634}]}]}
{"op":"mcm","clk":"1004894558","pt":1580638864355,"mc":[{"id":"1.168224441","rc":[{"batb":[[1,2.14,43.92]],"ltp":2.42,"tv":1135.16,"id":10894176},{"batb":[[1,1.62,6.28]],"ltp":1.7,"tv":1188.12,"id":2263634}]}]}
{"op":"mcm","clk":"1004894786","pt":1580638867168,"mc":[{"id":"1.168224441","rc":[{"batb":[[2,2,75.72]],"ltp":2.42,"tv":1135.16,"id":10894176}]}]}
{"op":"mcm","clk":"1004894882","pt":1580638868262,"mc":[{"id":"1.168224441","rc":[{"batb":[[1,2.16,43.92]],"ltp":2.42,"tv":1135.16,"id":10894176}]}]}
{"op":"mcm","clk":"1004895113","pt":1580638871245,"mc":[{"id":"1.168224441","rc":[{"trd":[[2.38,319.64]],"batl":[[0,2.38,173.3],[1,2.72,8.65],[2,95,15.9]],"ltp":2.38,"tv":1208.66,"id":10894176}],"tv":2396.79}]}
{"op":"mcm","clk":"1004895205","pt":1580638872278,"mc":[{"id":"1.168224441","rc":[{"batb":[[1,1.61,515.67],[2,1.57,57.55]],"ltp":1.7,"tv":1188.12,"id":2263634}]}]}
{"op":"mcm","clk":"1004895473","pt":1580638875377,"mc":[{"id":"1.168224441","rc":[{"trd":[[2.38,492.94]],"batl":[[0,2.72,8.65],[1,95,15.9],[2,990,2.2]],"ltp":2.38,"tv":1381.96,"id":10894176},{"trd":[[1.72,239.8]],"ltp":1.72,"tv":1427.92,"id":2263634}],"tv":2809.89}]}
{"op":"mcm","clk":"1004896218","pt":1580638884089,"mc":[{"id":"1.168224441","rc":[{"batb":[[1,2.14,43.92]],"ltp":2.38,"tv":1381.96,"id":10894176},{"batb":[[2,1.58,42.4]],"ltp":1.72,"tv":1427.92,"id":2263634}]}]}
{"op":"mcm","clk":"1004896341","pt":1580638885403,"mc":[{"id":"1.168224441","rc":[{"trd":[[2.34,81.7]],"batb":[[0,2.32,22.76]],"ltp":2.34,"tv":1463.66,"id":10894176},{"batb":[[0,1.66,71.98]],"ltp":1.72,"tv":1427.92,"id":2263634}],"tv":2891.59}]}
{"op":"mcm","clk":"1004896666","pt":1580638889369,"mc":[{"id":"1.168224441","rc":[{"batb":[[0,2.32,32.31]],"ltp":2.34,"tv":1463.66,"id":10894176},{"batl":[[0,1.76,17.81]],"ltp":1.72,"tv":1427.92,"id":2263634}]}]}
{"op":"mcm","clk":"1004901682","pt":1580638949336,"mc":[{"id":"1.168224441","rc":[{"batb":[[2,1.58,57.55]],"ltp":1.72,"tv":1427.92,"id":2263634}]}]}
{"op":"mcm","clk":"1004901733","pt":1580638949958,"mc":[{"id":"1.168224441","rc":[{"trd":[[2.32,48.52]],"batb":[[0,2.32,8.04]],"ltp":2.32,"tv":1512.19,"id":10894176}],"tv":2940.11}]}
{"op":"mcm","clk":"1004901801","pt":1580638950633,"mc":[{"id":"1.168224441","rc":[{"batb":[[1,2.2,54.03],[2,2.14,43.92]],"ltp":2.32,"tv":1512.19,"id":10894176},{"batb":[[0,1.69,68.82]],"ltp":1.72,"tv":1427.92,"id":2263634}]}]}
{"op":"mcm","clk":"1004924157","pt":1580639169422,"mc":[{"id":"1.168224441","rc":[{"trd":[[2.32,60.72]],"batb":[[0,2.32,1.94]],"ltp":2.32,"tv":1524.39,"id":10894176}],"tv":2952.31}]}
{"op":"mcm","clk":"1004927345","pt":1580639198992,"mc":[{"id":"1.168224441","rc":[{"batb":[[0,2.32,6.37]],"ltp":2.32,"tv":1524.39,"id":10894176}]}]}
{"op":"mcm","clk":"1004955246","pt":1580639465433,"mc":[{"id":"1.168224441","rc":[{"trd":[[2.32,69.97]],"batb":[[0,2.32,1.75]],"ltp":2.32,"tv":1533.63,"id":10894176}],"tv":2961.56}]}
{"op":"mcm","clk":"1004956405","pt":1580639477409,"mc":[{"id":"1.168224441","rc":[{"batl":[[0,2.46,8.4],[1,2.72,8.65],[2,95,15.9]],"ltp":2.32,"tv":1533.63,"id":10894176},{"batb":[[0,1.69,80.99]],"ltp":1.72,"tv":1427.92,"id":2263634}]}]}
{"op":"mcm","clk":"1004956493","pt":1580639478196,"mc":[{"id":"1.168224441","rc":[{"batb":[[0,2.32,6.37]],"ltp":2.32,"tv":1533.63,"id":10894176},{"batb":[[0,1.69,87.02]],"ltp":1.72,"tv":1427.92,"id":2263634}]}]}
{"op":"mcm","clk":"1004964103","pt":1580639552579,"mc":[{"id":"1.168224441","rc":[{"trd":[[2.32,79.23]],"batb":[[0,2.32,1.74]],"ltp":2.32,"tv":1542.89,"id":10894176}],"tv":2970.82}]}
{"op":"mcm","clk":"1004966369","pt":1580639572014,"mc":[{"id":"1.168224441","rc":[{"batb":[[0,2.32,6.37]],"ltp":2.32,"tv":1542.89,"id":10894176}]}]}
{"op":"mcm","clk":"1004989510","pt":1580639821789,"mc":[{"id":"1.168224441","rc":[{"trd":[[2.32,88.57]],"batb":[[0,2.32,1.7]],"ltp":2.32,"tv":1552.23,"id":10894176}],"tv":2980.16}]}
{"op":"mcm","clk":"1004989669","pt":1580639823070,"mc":[{"id":"1.168224441","rc":[{"batb":[[0,2.2,54.03],[1,2.14,43.92],[2,2,85.57]],"ltp":2.32,"tv":1552.23,"id":10894176},{"batl":[[0,1.76,5.21]],"ltp":1.72,"tv":1427.92,"id":2263634}]}]}
{"op":"mcm","clk":"1005059516","pt":1580640428095,"mc":[{"id":"1.168224441","rc":[{"batb":[[1,2,85.57],[2,1.81,37.86]],"ltp":2.32,"tv":1552.23,"id":10894176}]}]}
{"op":"mcm","clk":"1005059657","pt":1580640429246,"mc":[{"id":"1.168224441","rc":[{"batb":[[1,2,37.86]],"ltp":2.32,"tv":1552.23,"id":10894176}]}]}
{"op":"mcm","clk":"1005059737","pt":1580640429831,"mc":[{"id":"1.168224441","rc":[{"batb":[[2,1.98,48.68]],"ltp":2.32,"tv":1552.23,"id":10894176}]}]}
{"op":"mcm","clk":"1005066737","pt":1580640488181,"mc":[{"id":"1.168224441","rc":[{"batb":[[2,1.96,49.7]],"ltp":2.32,"tv":1552.23,"id":10894176}]}]}
{"op":"mcm","clk":"1005087906","pt":1580640652233,"mc":[{"id":"1.168224441","rc":[{"batb":[[2,1.56,85.19]],"ltp":1.72,"tv":1427.92,"id":2263634}]}]}
{"op":"mcm","clk":"1005088029","pt":1580640653327,"mc":[{"id":"1.168224441","rc":[{"batb":[[1,2.02,46.77],[2,2,37.86]],"ltp":2.32,"tv":1552.23,"id":10894176},{"batb":[[2,1.52,91.74]],"ltp":1.72,"tv":1427.92,"id":2263634}]}]}
{"op":"mcm","clk":"1005096947","pt":1580640728807,"mc":[{"id":"1.168224441","rc":[{"batb":[[0,2.32,49.52]],"ltp":2.32,"tv":1552.23,"id":10894176},{"batb":[[0,1.69,18.2],[1,1.63,70.53],[2,1.61,515.67]],"ltp":1.72,"tv":1427.92,"id":2263634}]}]}
{"op":"mcm","clk":"1005097122","pt":1580640730416,"mc":[{"id":"1.168224441","rc":[{"batb":[[0,1.69,12.17]],"ltp":1.72,"tv":1427.92,"id":2263634}]}]}
{"op":"mcm","clk":"1005117373","pt":1580640902166,"mc":[{"id":"1.168224441","rc":[{"trd":[[2.32,167.21]],"batb":[[0,2.32,10.2],[1,2,85.57],[2,1.81,37.86]],"ltp":2.32,"tv":1630.87,"id":10894176}],"tv":3058.8}]}
{"op":"mcm","clk":"1005117465","pt":1580640902692,"mc":[{"id":"1.168224441","rc":[{"batb":[[0,2.24,45.89]],"ltp":2.32,"tv":1630.87,"id":10894176},{"batb":[[0,1.7,43.51],[1,1.69,12.17]],"ltp":1.72,"tv":1427.92,"id":2263634}]}]}
{"op":"mcm","clk":"1005117888","pt":1580640905360,"mc":[{"id":"1.168224441","rc":[{"batl":[[0,2.44,12.6]],"ltp":2.32,"tv":1630.87,"id":10894176},{"batb":[[1,1.61,515.67],[2,1.53,90.01]],"ltp":1.72,"tv":1427.92,"id":2263634}]}]}
{"op":"mcm","clk":"1005117929","pt":1580640905676,"mc":[{"id":"1.168224441","rc":[{"batb":[[0,1.7,61.52]],"ltp":1.72,"tv":1427.92,"id":2263634}]}]}
{"op":"mcm","clk":"1005122309","pt":1580640941304,"mc":[{"id":"1.168224441","rc":[{"trd":[[2.34,155.6]],"batb":[[0,2.34,9.26],[1,2.24,45.89],[2,2,85.57]],"ltp":2.34,"tv":1704.77,"id":10894176}],"tv":3132.7}]}
{"op":"mcm","clk":"1005122529","pt":1580640943314,"mc":[{"id":"1.168224441","rc":[{"batb":[[2,2,37.86]],"ltp":2.34,"tv":1704.77,"id":10894176},{"batb":[[2,1.51,37.86]],"ltp":1.72,"tv":1427.92,"id":2263634}]}]}
{"op":"mcm","clk":"1005122610","pt":1580640943896,"mc":[{"id":"1.168224441","rc":[{"batb":[[2,2.06,80.72]],"ltp":2.34,"tv":1704.77,"id":10894176},{"batb":[[2,1.55,155.57]],"ltp":1.72,"tv":1427.92,"id":2263634}]}]}
{"op":"mcm","clk":"1005159592","pt":1580641218686,"mc":[{"id":"1.168224441","rc":[{"trd":[[2.34,170.14]],"batb":[[0,2.34,1.99]],"ltp":2.34,"tv":1719.31,"id":10894176}],"tv":3147.24}]}
{"op":"mcm","clk":"1005167465","pt":1580641263167,"mc":[{"id":"1.168224441","rc":[{"batb":[[2,2.04,82.27]],"ltp":2.34,"tv":1719.31,"id":10894176},{"batb":[[2,1.56,152.8]],"ltp":1.72,"tv":1427.92,"id":2263634}]}]}
{"op":"mcm","clk":"1005169599","pt":1580641275285,"mc":[{"id":"1.168224441","rc":[{"batb":[[2,2.12,43.16]],"ltp":2.34,"tv":1719.31,"id":10894176}]}]}
{"op":"mcm","clk":"1005169643","pt":1580641275522,"mc":[{"id":"1.168224441","rc":[{"batb":[[2,1.59,57.55]],"ltp":1.72,"tv":1427.92,"id":2263634}]}]}
{"op":"mcm","clk":"1005184821","pt":1580641359054,"mc":[{"id":"1.168224441","rc":[{"batb":[[0,1.71,22.72],[1,1.7,61.52],[2,1.61,515.67]],"ltp":1.72,"tv":1427.92,"id":2263634}]}]}
{"op":"mcm","clk":"1005184980","pt":1580641359964,"mc":[{"id":"1.168224441","rc":[{"batb":[[0,1.71,28.67]],"ltp":1.72,"tv":1427.92,"id":2263634}]}]}
{"op":"mcm","clk":"1005186418","pt":1580641368042,"mc":[{"id":"1.168224441","rc":[{"batb":[[1,2.24,45.97]],"ltp":2.34,"tv":1719.31,"id":10894176}]}]}
{"op":"mcm","clk":"1005186663","pt":1580641369275,"mc":[{"id":"1.168224441","rc":[{"batl":[[0,2.72,8.65],[1,95,15.9],[2,990,2.2]],"ltp":2.34,"tv":1719.31,"id":10894176},{"batb":[[1,1.7,43.51]],"ltp":1.72,"tv":1427.92,"id":2263634}]}]}
{"op":"mcm","clk":"1005186773","pt":1580641369804,"mc":[{"id":"1.168224441","rc":[{"batl":[[0,2.42,12.6],[1,2.72,8.65],[2,95,15.9]],"ltp":2.34,"tv":1719.31,"id":10894176},{"batb":[[0,1.71,46.43]],"ltp":1.72,"tv":1427.92,"id":2263634}]}]}
{"op":"mcm","clk":"1005208117","pt":1580641474219,"mc":[{"id":"1.168224441","rc":[{"batb":[[0,1.72,22.56],[1,1.71,46.43]],"ltp":1.72,"tv":1427.92,"id":2263634}]}]}
{"op":"mcm","clk":"1005208446","pt":1580641475803,"mc":[{"id":"1.168224441","rc":[{"batb":[[1,1.71,40.47]],"ltp":1.72,"tv":1427.92,"id":2263634}]}]}
{"op":"mcm","clk":"1005211755","pt":1580641493261,"mc":[{"id":"1.168224441","rc":[{"batl":[[0,2.72,8.65],[1,95,15.9],[2,990,2.2]],"ltp":2.34,"tv":1719.31,"id":10894176}]}]}
{"op":"mcm","clk":"1005211907","pt":1580641494156,"mc":[{"id":"1.168224441","rc":[{"batl":[[0,2.4,12.6],[1,2.72,8.65],[2,95,15.9]],"ltp":2.34,"tv":1719.31,"id":10894176},{"batb":[[0,1.72,40.06],[1,1.71,22.72]],"ltp":1.72,"tv":1427.92,"id":2263634}]}]}
{"op":"mcm","clk":"1005223592","pt":1580641550350,"mc":[{"id":"1.168224441","rc":[{"batb":[[1,2.32,98.47],[2,2.24,45.89]],"ltp":2.34,"tv":1719.31,"id":10894176}]}]}
{"op":"mcm","clk":"1005226899","pt":1580641565688,"mc":[{"id":"1.168224441","rc":[{"batb":[[1,2.32,84.47]],"ltp":2.34,"tv":1719.31,"id":10894176}]}]}
{"op":"mcm","clk":"1005230153","pt":1580641580587,"mc":[{"id":"1.168224441","rc":[{"batb":[[1,2.32,70.22]],"ltp":2.34,"tv":1719.31,"id":10894176}]}]}
{"op":"mcm","clk":"1005233306","pt":1580641595780,"mc":[{"id":"1.168224441","rc":[{"batb":[[1,2.32,56.22]],"ltp":2.34,"tv":1719.31,"id":10894176}]}]}
{"op":"mcm","clk":"1005236262","pt":1580641610826,"mc":[{"id":"1.168224441","rc":[{"batb":[[1,2.32,42.22]],"ltp":2.34,"tv":1719.31,"id":10894176}]}]}
{"op":"mcm","clk":"1005239650","pt":1580641627031,"mc":[{"id":"1.168224441","rc":[{"batb":[[1,2.32,36.47]],"ltp":2.34,"tv":1719.31,"id":10894176}]}]}
{"op":"mcm","clk":"1005242719","pt":1580641642243,"mc":[{"id":"1.168224441","rc":[{"batb":[[1,2.32,30.72]],"ltp":2.34,"tv":1719.31,"id":10894176}]}]}
{"op":"mcm","clk":"1005245931","pt":1580641658279,"mc":[{"id":"1.168224441","rc":[{"batb":[[1,2.32,24.72]],"ltp":2.34,"tv":1719.31,"id":10894176}]}]}
{"op":"mcm","clk":"1005247777","pt":1580641667110,"mc":[{"id":"1.168224441","rc":[{"batb":[[0,1.72,40.14]],"ltp":1.72,"tv":1427.92,"id":2263634}]}]}
{"op":"mcm","clk":"1005249116","pt":1580641673807,"mc":[{"id":"1.168224441","rc":[{"batb":[[1,2.32,18.97]],"ltp":2.34,"tv":1719.31,"id":10894176}]}]}
{"op":"mcm","clk":"1005249427","pt":1580641675410,"mc":[{"id":"1.168224441","rc":[{"trd":[[2.38,493],[2.4,212.87]],"batb":[[2,2.12,43.16]],"batl":[[0,2.72,8.65],[1,95,15.9],[2,990,2.2]],"ltp":2.4,"tv":1764.2,"id":10894176},{"trd":[[1.72,267.19],[1.73,8.21]],"batb":[[0,1.72,12.67]],"ltp":1.72,"tv":1455.39,"id":2263634}],"tv":3219.6}]}
{"op":"mcm","clk":"1005249530","pt":1580641675887,"mc":[{"id":"1.168224441","rc":[{"batb":[[0,2.34,21.14],[1,2.12,43.24],[2,2.04,82.27]],"ltp":2.4,"tv":1764.2,"id":10894176},{"batb":[[2,1.65,77.41]],"ltp":1.72,"tv":1455.39,"id":2263634}]}]}
{"op":"mcm","clk":"1005250399","pt":1580641680414,"mc":[{"id":"1.168224441","rc":[{"batb":[[0,1.71,22.72],[1,1.65,77.41],[2,1.61,515.67]],"batl":[[0,1.75,12.6],[1,1.76,5.21],[2,1.81,3.03]],"ltp":1.72,"tv":1455.39,"id":2263634}]}]}
{"op":"mcm","clk":"1005250448","pt":1580641680731,"mc":[{"id":"1.168224441","rc":[{"batb":[[0,2.34,30.54]],"ltp":2.4,"tv":1764.2,"id":10894176}]}]}
{"op":"mcm","clk":"1005251575","pt":1580641686320,"mc":[{"id":"1.168224441","rc":[{"batb":[[2,1.61,477.81]],"batl":[[0,1.72,44],[1,1.75,12.6],[2,1.76,5.21]],"ltp":1.72,"tv":1455.39,"id":2263634}]}]}
{"op":"mcm","clk":"1005252473","pt":1580641691436,"mc":[{"id":"1.168224441","rc":[{"batl":[[0,1.75,12.6],[1,1.76,5.21],[2,1.81,3.03]],"ltp":1.72,"tv":1455.39,"id":2263634}]}]}
{"op":"mcm","clk":"1005252523","pt":1580641691604,"mc":[{"id":"1.168224441","rc":[{"trd":[[1.71,184.33]],"batb":[[0,1.65,77.41],[1,1.61,477.81],[2,1.59,57.55]],"batl":[[0,1.71,21.54],[1,1.75,12.6],[2,1.76,5.21]],"ltp":1.71,"tv":1500.83,"id":2263634}],"tv":3265.03}]}
{"op":"mcm","clk":"1005256672","pt":1580641712355,"mc":[{"id":"1.168224441","rc":[{"batb":[[0,2.34,21.14]],"ltp":2.4,"tv":1764.2,"id":10894176},{"batl":[[0,1.71,34.14],[1,1.76,5.21],[2,1.81,3.03]],"ltp":1.71,"tv":1500.83,"id":2263634}]}]}
{"op":"mcm","clk":"1005256737","pt":1580641712663,"mc":[{"id":"1.168224441","rc":[{"batb":[[0,2.4,9],[1,2.34,21.14],[2,2.12,43.24]],"ltp":2.4,"tv":1764.2,"id":10894176},{"trd":[[1.71,218.69]],"batl":[[0,1.71,16.96]],"ltp":1.71,"tv":1535.19,"id":2263634}],"tv":3299.39}]}
{"op":"mcm","clk":"1005259324","pt":1580641725569,"mc":[{"id":"1.168224441","rc":[{"batb":[[0,2.4,41.29]],"ltp":2.4,"tv":1764.2,"id":10894176}]}]}
{"op":"mcm","clk":"1005262891","pt":1580641744370,"mc":[{"id":"1.168224441","rc":[{"batb":[[1,2.34,1.99],[2,2.32,34.98]],"ltp":2.4,"tv":1764.2,"id":10894176},{"trd":[[1.71,239.42]],"batb":[[0,1.64,78.96]],"batl":[[0,1.71,6.6]],"ltp":1.71,"tv":1555.92,"id":2263634}],"tv":3320.13}]}
{"op":"mcm","clk":"1005262973","pt":1580641744828,"mc":[{"id":"1.168224441","rc":[{"trd":[[2.4,280.03]],"batb":[[0,2.4,7.71]],"batl":[[0,2.62,8.55],[1,2.72,8.65],[2,95,15.9]],"ltp":2.4,"tv":1831.36,"id":10894176},{"batb":[[1,1.62,14.84],[2,1.61,477.81]],"ltp":1.71,"tv":1555.92,"id":2263634}],"tv":3387.29}]}
{"op":"mcm","clk":"1005266039","pt":1580641760423,"mc":[{"id":"1.168224441","rc":[{"batb":[[0,2.34,1.99],[1,2.32,34.98],[2,2.12,43.16]],"ltp":2.4,"tv":1831.36,"id":10894176}]}]}
{"op":"mcm","clk":"1005267045","pt":1580641765614,"mc":[{"id":"1.168224441","rc":[{"trd":[[1.71,252.62]],"batb":[[0,1.71,26.4],[1,1.64,78.96],[2,1.62,14.84]],"batl":[[0,1.76,5.21],[1,1.81,3.03],[2,1.86,21.85]],"ltp":1.71,"tv":1569.12,"id":2263634}],"tv":3400.48}]}
{"op":"mcm","clk":"1005267867","pt":1580641769443,"mc":[{"id":"1.168224441","rc":[{"batl":[[0,2.72,8.65],[1,95,15.9],[2,990,2.2]],"ltp":2.4,"tv":1831.36,"id":10894176},{"batb":[[2,1.61,477.81]],"ltp":1.71,"tv":1569.12,"id":2263634}]}]}
{"op":"mcm","clk":"1005269033","pt":1580641775345,"mc":[{"id":"1.168224441","rc":[{"batl":[[0,2.42,12.6],[1,2.72,8.65],[2,95,15.9]],"ltp":2.4,"tv":1831.36,"id":10894176},{"batb":[[0,1.71,44.15]],"ltp":1.71,"tv":1569.12,"id":2263634}]}]}
{"op":"mcm","clk":"1005269102","pt":1580641775654,"mc":[{"id":"1.168224441","rc":[{"batb":[[1,2.32,57.62]],"ltp":2.4,"tv":1831.36,"id":10894176}]}]}
{"op":"mcm","clk":"1005270024","pt":1580641780253,"mc":[{"id":"1.168224441","rc":[{"trd":[[2.34,172.13]],"batb":[[0,2.32,57.62],[1,2.12,43.16],[2,2.04,82.27]],"ltp":2.34,"tv":1833.35,"id":10894176},{"trd":[[1.75,53.7]],"batb":[[0,1.71,17.75],[2,1.61,515.67]],"ltp":1.75,"tv":1618.06,"id":2263634}],"tv":3451.41}]}
{"op":"mcm","clk":"1005270084","pt":1580641780557,"mc":[{"id":"1.168224441","rc":[{"batb":[[0,2.32,43.87]],"ltp":2.34,"tv":1833.35,"id":10894176}]}]}
{"op":"mcm","clk":"1005271035","pt":1580641785555,"mc":[{"id":"1.168224441","rc":[{"batl":[[1,1.81,25.75]],"ltp":1.75,"tv":1618.06,"id":2263634}]}]}
{"op":"mcm","clk":"1005278919","pt":1580641828323,"mc":[{"id":"1.168224441","rc":[{"trd":[[2.42,402.26]],"batl":[[0,2.72,8.65],[1,95,15.9],[2,990,2.2]],"ltp":2.42,"tv":1863.27,"id":10894176},{"trd":[[1.71,259.3]],"batb":[[0,1.71,11.07]],"ltp":1.71,"tv":1624.74,"id":2263634}],"tv":3488.02}]}
{"op":"mcm","clk":"1005279080","pt":1580641829227,"mc":[{"id":"1.168224441","rc":[{"trd":[[2.32,237.77]],"batb":[[0,2.32,8.59],[1,2.24,35.2],[2,2.12,43.16]],"ltp":2.32,"tv":1933.83,"id":10894176},{"batb":[[0,1.72,36.65],[1,1.71,11.07]],"ltp":1.71,"tv":1624.74,"id":2263634}],"tv":3558.57}]}
{"op":"mcm","clk":"1005279242","pt":1580641830021,"mc":[{"id":"1.168224441","rc":[{"batb":[[0,2.32,3.39]],"ltp":2.32,"tv":1933.83,"id":10894176}]}]}
{"op":"mcm","clk":"1005280753","pt":1580641838133,"mc":[{"id":"1.168224441","rc":[{"batb":[[1,1.61,515.67],[2,1.59,57.55]],"batl":[[0,1.76,17.81]],"ltp":1.71,"tv":1624.74,"id":2263634}]}]}
{"op":"mcm","clk":"1005280815","pt":1580641838452,"mc":[{"id":"1.168224441","rc":[{"batb":[[0,2.32,12.93]],"ltp":2.32,"tv":1933.83,"id":10894176}]}]}
{"op":"mcm","clk":"1005283589","pt":1580641852755,"mc":[{"id":"1.168224441","rc":[{"trd":[[2.32,257.47]],"batb":[[0,2.32,3.08]],"ltp":2.32,"tv":1953.53,"id":10894176}],"tv":3578.27}]}
{"op":"mcm","clk":"1005286822","pt":1580641870298,"mc":[{"id":"1.168224441","rc":[{"batb":[[0,2.24,35.2],[1,2.12,43.16],[2,2.04,82.27]],"batl":[[0,2.4,8.4],[1,2.72,8.65],[2,95,15.9]],"ltp":2.32,"tv":1953.53,"id":10894176},{"batb":[[0,1.72,48.32]],"ltp":1.71,"tv":1624.74,"id":2263634}]}]}
{"op":"mcm","clk":"1005286856","pt":1580641870513,"mc":[{"id":"1.168224441","rc":[{"batb":[[0,2.32,6.37],[1,2.24,35.2],[2,2.12,43.16]],"ltp":2.32,"tv":1953.53,"id":10894176}]}]}
{"op":"mcm","clk":"1005304794","pt":1580641969129,"mc":[{"id":"1.168224441","rc":[{"batb":[[0,2.32,14.51]],"ltp":2.32,"tv":1953.53,"id":10894176},{"batb":[[0,1.72,63.46]],"ltp":1.71,"tv":1624.74,"id":2263634}]}]}
{"op":"mcm","clk":"1005304908","pt":1580641969817,"mc":[{"id":"1.168224441","rc":[{"trd":[[2.32,267.33]],"batb":[[0,2.32,9.58]],"ltp":2.32,"tv":1963.39,"id":10894176}],"tv":3588.14}]}
{"op":"mcm","clk":"1005309298","pt":1580641995044,"mc":[{"id":"1.168224441","rc":[{"batb":[[0,2.32,14.51]],"ltp":2.32,"tv":1963.39,"id":10894176}]}]}
{"op":"mcm","clk":"1005310482","pt":1580642002019,"mc":[{"id":"1.168224441","rc":[{"batb":[[0,2.32,6.37]],"ltp":2.32,"tv":1963.39,"id":10894176}]}]}
{"op":"mcm","clk":"1005310636","pt":1580642002823,"mc":[{"id":"1.168224441","rc":[{"trd":[[2.32,277.21]],"batb":[[0,2.32,1.43]],"ltp":2.32,"tv":1973.27,"id":10894176}],"tv":3598.02}]}
{"op":"mcm","clk":"1005314725","pt":1580642026859,"mc":[{"id":"1.168224441","rc":[{"batb":[[0,2.24,35.2],[1,2.12,43.16],[2,2.04,82.27]],"ltp":2.32,"tv":1973.27,"id":10894176},{"batl":[[0,1.76,5.21]],"ltp":1.71,"tv":1624.74,"id":2263634}]}]}
{"op":"mcm","clk":"1005337168","pt":1580642151124,"mc":[{"id":"1.168224441","rc":[{"batb":[[0,1.72,211.34]],"batl":[[0,1.76,149.72]],"ltp":1.71,"tv":1624.74,"id":2263634}]}]}
{"op":"mcm","clk":"1005337341","pt":1580642152043,"mc":[{"id":"1.168224441","rc":[{"trd":[[1.76,251.04]],"batl":[[0,1.76,26.57]],"ltp":1.76,"tv":1871.05,"id":2263634}],"tv":3844.33}]}
{"op":"mcm","clk":"1005337477","pt":1580642152845,"mc":[{"id":"1.168224441","rc":[{"batb":[[0,2.32,9.01],[1,2.24,35.2],[2,2.12,43.16]],"batl":[[0,2.38,9.81],[1,2.4,8.4],[2,2.72,8.65]],"ltp":2.32,"tv":1973.27,"id":10894176},{"trd":[[1.75,64.18]],"batb":[[0,1.73,16.62],[1,1.72,211.34],[2,1.61,515.67]],"ltp":1.75,"tv":1881.53,"id":2263634}],"tv":3854.81}]}
{"op":"mcm","clk":"1005337671","pt":1580642153953,"mc":[{"id":"1.168224441","rc":[{"batb":[[0,2.24,35.2],[1,2.12,43.16],[2,2.04,82.27]],"ltp":2.32,"tv":1973.27,"id":10894176}]}]}
{"op":"mcm","clk":"1005338261","pt":1580642157474,"mc":[{"id":"1.168224441","rc":[{"batl":[[0,1.76,34.14]],"ltp":1.75,"tv":1881.53,"id":2263634}]}]}
{"op":"mcm","clk":"1005342713","pt":1580642181381,"mc":[{"id":"1.168224441","rc":[{"batl":[[1,2.72,8.65],[2,95,15.9]],"ltp":2.32,"tv":1973.27,"id":10894176},{"batb":[[1,1.72,199.67]],"ltp":1.75,"tv":1881.53,"id":2263634}]}]}
{"op":"mcm","clk":"1005342862","pt":1580642182062,"mc":[{"id":"1.168224441","rc":[{"batl":[[0,2.38,22.41]],"ltp":2.32,"tv":1973.27,"id":10894176},{"trd":[[1.76,307.28]],"batb":[[0,1.73,33.89]],"batl":[[0,1.76,6.02]],"ltp":1.76,"tv":1937.77,"id":2263634}],"tv":3911.05}]}
{"op":"mcm","clk":"1005343299","pt":1580642184284,"mc":[{"id":"1.168224441","rc":[{"trd":[[1.75,67.3]],"ltp":1.75,"tv":1940.89,"id":2263634}],"tv":3914.17}]}
{"op":"mcm","clk":"1005343668","pt":1580642186187,"mc":[{"id":"1.168224441","rc":[{"batl":[[0,1.76,13.59]],"ltp":1.75,"tv":1940.89,"id":2263634}]}]}
{"op":"mcm","clk":"1005343749","pt":1580642186604,"mc":[{"id":"1.168224441","rc":[{"batl":[[0,1.76,21.16]],"ltp":1.75,"tv":1940.89,"id":2263634}]}]}
{"op":"mcm","clk":"1005344176","pt":1580642188998,"mc":[{"id":"1.168224441","rc":[{"batl":[[0,1.76,7.57]],"ltp":1.75,"tv":1940.89,"id":2263634}]}]}
{"op":"mcm","clk":"1005344545","pt":1580642191013,"mc":[{"id":"1.168224441","rc":[{"batl":[[0,1.76,15.14]],"ltp":1.75,"tv":1940.89,"id":2263634}]}]}
{"op":"mcm","clk":"1005351566","pt":1580642230241,"mc":[{"id":"1.168224441","rc":[{"trd":[[1.76,332.12]],"batl":[[0,1.76,2.73]],"ltp":1.76,"tv":1965.73,"id":2263634}],"tv":3939.01}]}
{"op":"mcm","clk":"1005351703","pt":1580642230982,"mc":[{"id":"1.168224441","rc":[{"trd":[[1.75,71.42]],"batb":[[0,1.75,10.43],[1,1.73,33.89],[2,1.72,199.67]],"ltp":1.75,"tv":1969.85,"id":2263634}],"tv":3943.13}]}
{"op":"mcm","clk":"1005354104","pt":1580642244161,"mc":[{"id":"1.168224441","rc":[{"batl":[[0,2.38,9.81]],"ltp":2.32,"tv":1973.27,"id":10894176},{"batb":[[1,1.73,16.62]],"ltp":1.75,"tv":1969.85,"id":2263634}]}]}
{"op":"mcm","clk":"1005354162","pt":1580642244464,"mc":[{"id":"1.168224441","rc":[{"batl":[[0,2.34,12.6],[1,2.38,9.81],[2,2.72,8.65]],"ltp":2.32,"tv":1973.27,"id":10894176}]}]}
{"op":"mcm","clk":"1005359210","pt":1580642270999,"mc":[{"id":"1.168224441","rc":[{"batb":[[2,2,37.86]],"ltp":2.32,"tv":1973.27,"id":10894176}]}]}
{"op":"mcm","clk":"1005359603","pt":1580642273073,"mc":[{"id":"1.168224441","rc":[{"batb":[[1,2,37.86],[2,1.93,92.01]],"ltp":2.32,"tv":1973.27,"id":10894176}]}]}
{"op":"mcm","clk":"1005360443","pt":1580642277391,"mc":[{"id":"1.168224441","rc":[{"batb":[[2,1.81,37.86]],"ltp":2.32,"tv":1973.27,"id":10894176},{"batl":[[0,1.77,2.73]],"ltp":1.75,"tv":1969.85,"id":2263634}]}]}
{"op":"mcm","clk":"1005360601","pt":1580642278225,"mc":[{"id":"1.168224441","rc":[{"batb":[[2,1.96,89.13]],"ltp":2.32,"tv":1973.27,"id":10894176}]}]}
{"op":"mcm","clk":"1005361845","pt":1580642284726,"mc":[{"id":"1.168224441","rc":[{"trd":[[1.75,91.77]],"batb":[[0,1.73,16.88],[1,1.72,199.67],[2,1.61,655.95]],"ltp":1.75,"tv":1990.21,"id":2263634}],"tv":3963.49}]}
{"op":"mcm","clk":"1005362151","pt":1580642286336,"mc":[{"id":"1.168224441","rc":[{"batb":[[1,2.04,44.68],[2,2,37.86]],"ltp":2.32,"tv":1973.27,"id":10894176},{"batb":[[2,1.63,56.04]],"ltp":1.75,"tv":1990.21,"id":2263634}]}]}
{"op":"mcm","clk":"1005362726","pt":1580642289339,"mc":[{"id":"1.168224441","rc":[{"batl":[[0,1.76,15.14],[1,1.77,2.73],[2,1.81,25.75]],"ltp":1.75,"tv":1990.21,"id":2263634}]}]}
{"op":"mcm","clk":"1005363027","pt":1580642290734,"mc":[{"id":"1.168224441","rc":[{"batl":[[1,1.81,25.75],[2,1.86,21.85]],"ltp":1.75,"tv":1990.21,"id":2263634}]}]}
{"op":"mcm","clk":"1005363298","pt":1580642291933,"mc":[{"id":"1.168224441","rc":[{"batl":[[0,1.76,7.57]],"ltp":1.75,"tv":1990.21,"id":2263634}]}]}
{"op":"mcm","clk":"1005363496","pt":1580642292910,"mc":[{"id":"1.168224441","rc":[{"batl":[[1,1.77,7.57],[2,1.81,25.75]],"ltp":1.75,"tv":1990.21,"id":2263634}]}]}
{"op":"mcm","clk":"1005366040","pt":1580642306163,"mc":[{"id":"1.168224441","rc":[{"batb":[[0,1.74,17.29],[1,1.73,16.62],[2,1.72,199.67]],"ltp":1.75,"tv":1990.21,"id":2263634}]}]}
{"op":"mcm","clk":"1005366267","pt":1580642307351,"mc":[{"id":"1.168224441","rc":[{"trd":[[1.76,343.72]],"batl":[[0,1.76,1.77]],"ltp":1.76,"tv":2001.81,"id":2263634}],"tv":3975.09}]}
{"op":"mcm","clk":"1005366429","pt":1580642308351,"mc":[{"id":"1.168224441","rc":[{"trd":[[1.75,103.5]],"batb":[[0,1.74,17.26]],"ltp":1.75,"tv":2013.53,"id":2263634}],"tv":3986.81}]}
{"op":"mcm","clk":"1005366900","pt":1580642311063,"mc":[{"id":"1.168224441","rc":[{"batl":[[0,1.76,16.92]],"ltp":1.75,"tv":2013.53,"id":2263634}]}]}
{"op":"mcm","clk":"1005367454","pt":1580642314092,"mc":[{"id":"1.168224441","rc":[{"batl":[[0,1.76,7.57]],"ltp":1.75,"tv":2013.53,"id":2263634}]}]}
{"op":"mcm","clk":"1005374691","pt":1580642350406,"mc":[{"id":"1.168224441","rc":[{"trd":[[2.34,197.5]],"batb":[[0,2.34,9.81],[1,2.24,35.2],[2,2.04,44.68]],"batl":[[0,2.38,9.81],[1,2.72,8.65],[2,95,15.9]],"ltp":2.34,"tv":1998.65,"id":10894176},{"trd":[[1.75,103.72]],"batb":[[0,1.74,17.03]],"ltp":1.75,"tv":2013.76,"id":2263634}],"tv":4012.41}]}
{"op":"mcm","clk":"1005374865","pt":1580642351420,"mc":[{"id":"1.168224441","rc":[{"trd":[[2.38,512.34]],"batb":[[0,2.24,35.2],[1,2.04,44.68],[2,2,37.86]],"batl":[[0,2.72,8.79],[1,95,15.9],[2,990,2.2]],"ltp":2.38,"tv":2017.99,"id":10894176},{"trd":[[1.73,41.11],[1.74,34.06],[1.76,355.34]],"batb":[[0,1.72,199.84],[1,1.63,56.04],[2,1.61,655.95]],"batl":[[0,1.76,1.76]],"ltp":1.76,"tv":2092.34,"id":2263634}],"tv":4110.33}]}
{"op":"mcm","clk":"1005374989","pt":1580642352220,"mc":[{"id":"1.168224441","rc":[{"trd":[[1.75,108.32]],"batb":[[0,1.75,3.54],[1,1.72,199.84],[2,1.63,56.04]],"ltp":1.75,"tv":2096.94,"id":2263634}],"tv":4114.93}]}
{"op":"mcm","clk":"1005375205","pt":1580642353413,"mc":[{"id":"1.168224441","rc":[{"batl":[[0,2.72,8.65]],"ltp":2.38,"tv":2017.99,"id":10894176},{"batb":[[1,1.72,199.67]],"ltp":1.75,"tv":2096.94,"id":2263634}]}]}
{"op":"mcm","clk":"1005375580","pt":1580642355418,"mc":[{"id":"1.168224441","rc":[{"trd":[[1.75,114.93]],"batb":[[0,1.72,199.9],[1,1.61,515.67],[2,1.6,142.61]],"ltp":1.75,"tv":2103.54,"id":2263634}],"tv":4121.53}]}
{"op":"mcm","clk":"1005375987","pt":1580642357599,"mc":[{"id":"1.168224441","rc":[{"batl":[[0,1.76,9.34]],"ltp":1.75,"tv":2103.54,"id":2263634}]}]}
{"op":"mcm","clk":"1005376482","pt":1580642360319,"mc":[{"id":"1.168224441","rc":[{"batl":[[0,1.76,7.57]],"ltp":1.75,"tv":2103.54,"id":2263634}]}]}
{"op":"mcm","clk":"1005376909","pt":1580642362401,"mc":[{"id":"1.168224441","rc":[{"batl":[[0,1.76,15.14]],"ltp":1.75,"tv":2103.54,"id":2263634}]}]}
{"op":"mcm","clk":"1005378176","pt":1580642369305,"mc":[{"id":"1.168224441","rc":[{"batb":[[0,2.3,9.7],[1,2.24,35.2],[2,2.04,44.68]],"ltp":2.38,"tv":2017.99,"id":10894176},{"batl":[[0,1.76,27.75]],"ltp":1.75,"tv":2103.54,"id":2263634}]}]}
{"op":"mcm","clk":"1005378336","pt":1580642370150,"mc":[{"id":"1.168224441","rc":[{"batl":[[0,1.76,353.52]],"ltp":1.75,"tv":2103.54,"id":2263634}]}]}
{"op":"mcm","clk":"1005378776","pt":1580642372332,"mc":[{"id":"1.168224441","rc":[{"batb":[[0,2.32,9.92],[1,2.3,9.7],[2,2.24,35.2]],"ltp":2.38,"tv":2017.99,"id":10894176},{"batl":[[0,1.75,10.44],[1,1.76,353.52],[2,1.77,7.57]],"ltp":1.75,"tv":2103.54,"id":2263634}]}]}
{"op":"mcm","clk":"1005378961","pt":1580642373339,"mc":[{"id":"1.168224441","rc":[{"batb":[[0,2.3,9.7],[1,2.24,35.2],[2,2.04,44.68]],"ltp":2.38,"tv":2017.99,"id":10894176},{"batl":[[0,1.76,27.75],[1,1.77,7.57],[2,1.81,25.75]],"ltp":1.75,"tv":2103.54,"id":2263634}]}]}
{"op":"mcm","clk":"1005379024","pt":1580642373705,"mc":[{"id":"1.168224441","rc":[{"batl":[[0,1.76,353.52]],"ltp":1.75,"tv":2103.54,"id":2263634}]}]}
{"op":"mcm","clk":"1005379694","pt":1580642377367,"mc":[{"id":"1.168224441","rc":[{"batb":[[0,2.32,9.73],[1,2.3,9.7],[2,2.24,35.2]],"ltp":2.38,"tv":2017.99,"id":10894176},{"batl":[[0,1.75,11.32],[1,1.76,27.75],[2,1.77,7.57]],"ltp":1.75,"tv":2103.54,"id":2263634}]}]}
{"op":"mcm","clk":"1005379874","pt":1580642378322,"mc":[{"id":"1.168224441","rc":[{"batb":[[0,2.3,9.7],[1,2.24,35.2],[2,2.04,44.68]],"ltp":2.38,"tv":2017.99,"id":10894176},{"batl":[[0,1.76,27.75],[1,1.77,7.57],[2,1.81,25.75]],"ltp":1.75,"tv":2103.54,"id":2263634}]}]}
{"op":"mcm","clk":"1005380366","pt":1580642381159,"mc":[{"id":"1.168224441","rc":[{"trd":[[1.72,516.08],[1.73,41.57]],"batb":[[0,1.72,75.22]],"ltp":1.72,"tv":2352.89,"id":2263634}],"tv":4370.88}]}
{"op":"mcm","clk":"1005380618","pt":1580642382378,"mc":[{"id":"1.168224441","rc":[{"batb":[[0,2.32,27.3],[1,2.3,9.7]],"ltp":2.38,"tv":2017.99,"id":10894176},{"trd":[[1.75,130.16],[1.76,400.2]],"batb":[[1,1.65,77.52],[2,1.61,515.67]],"batl":[[0,1.75,1.76],[1,1.76,5.31],[2,1.77,7.57]],"ltp":1.75,"tv":2413.0,"id":2263634}],"tv":4430.99}]}
{"op":"mcm","clk":"1005380651","pt":1580642382529,"mc":[{"id":"1.168224441","rc":[{"batl":[[0,1.76,5.31],[1,1.77,7.57],[2,1.81,25.75]],"ltp":1.75,"tv":2413.0,"id":2263634}]}]}
{"op":"mcm","clk":"1005381148","pt":1580642385184,"mc":[{"id":"1.168224441","rc":[{"batl":[[1,1.81,25.75],[2,1.86,21.85]],"ltp":1.75,"tv":2413.0,"id":2263634}]}]}
{"op":"mcm","clk":"1005381337","pt":1580642386249,"mc":[{"id":"1.168224441","rc":[{"batb":[[0,1.73,7.7],[1,1.72,75.22],[2,1.65,77.52]],"batl":[[0,1.76,12.88]],"ltp":1.75,"tv":2413.0,"id":2263634}]}]}
{"op":"mcm","clk":"1005383863","pt":1580642400174,"mc":[{"id":"1.168224441","rc":[{"batb":[[0,2.32,36.84],[1,2.04,44.68],[2,2,37.86]],"ltp":2.38,"tv":2017.99,"id":10894176}]}]}
{"op":"mcm","clk":"1005386181","pt":1580642412116,"mc":[{"id":"1.168224441","rc":[{"batb":[[0,2.32,31.17]],"ltp":2.38,"tv":2017.99,"id":10894176},{"trd":[[1.73,56.98]],"batb":[[0,1.72,75.22],[1,1.65,77.52],[2,1.61,515.67]],"ltp":1.73,"tv":2428.4,"id":2263634}],"tv":4446.39}]}
{"op":"mcm","clk":"1005386304","pt":1580642412591,"mc":[{"id":"1.168224441","rc":[{"batb":[[0,2.32,9.54],[1,2.26,47.69],[2,2.04,44.68]],"ltp":2.38,"tv":2017.99,"id":10894176},{"batb":[[1,1.66,73.56]],"ltp":1.73,"tv":2428.4,"id":2263634}]}]}
{"op":"mcm","clk":"1005386515","pt":1580642413597,"mc":[{"id":"1.168224441","rc":[{"trd":[[2.32,296.29]],"batb":[[0,2.26,47.69],[1,2.04,44.68],[2,2,37.86]],"ltp":2.32,"tv":2037.07,"id":10894176}],"tv":4465.48}]}
{"op":"mcm","clk":"1005387132","pt":1580642417108,"mc":[{"id":"1.168224441","rc":[{"batb":[[0,1.72,223.1]],"batl":[[0,1.76,164.97]],"ltp":1.73,"tv":2428.4,"id":2263634}]}]}
{"op":"mcm","clk":"1005389653","pt":1580642431337,"mc":[{"id":"1.168224441","rc":[{"batl":[[0,2.38,8.4],[1,2.72,8.65],[2,95,15.9]],"ltp":2.32,"tv":2037.07,"id":10894176}]}]}
{"op":"mcm","clk":"1005389738","pt":1580642431810,"mc":[{"id":"1.168224441","rc":[{"batb":[[0,2.32,6.37],[1,2.26,47.69],[2,2.04,44.68]],"ltp":2.32,"tv":2037.07,"id":10894176},{"batb":[[0,1.73,11.51],[1,1.72,223.1],[2,1.66,73.56]],"ltp":1.73,"tv":2428.4,"id":2263634}]}]}
{"op":"mcm","clk":"1005392049","pt":1580642444334,"mc":[{"id":"1.168224441","rc":[{"batb":[[0,2.34,10.13],[1,2.32,6.37],[2,2.26,47.69]],"ltp":2.32,"tv":2037.07,"id":10894176}]}]}
{"op":"mcm","clk":"1005392102","pt":1580642444655,"mc":[{"id":"1.168224441","rc":[{"trd":[[2.34,214.12]],"batb":[[0,2.34,1.82]],"ltp":2.34,"tv":2053.69,"id":10894176}],"tv":4482.1}]}
{"op":"mcm","clk":"1005395516","pt":1580642463294,"mc":[{"id":"1.168224441","rc":[{"batb":[[1,2.26,47.69],[2,2.04,44.68]],"ltp":2.34,"tv":2053.69,"id":10894176},{"batl":[[0,1.76,159.66]],"ltp":1.73,"tv":2428.4,"id":2263634}]}]}
{"op":"mcm","clk":"1005395641","pt":1580642463980,"mc":[{"id":"1.168224441","rc":[{"batb":[[0,2.34,8.09]],"ltp":2.34,"tv":2053.69,"id":10894176},{"batl":[[0,1.75,8.4],[1,1.76,159.66],[2,1.81,25.75]],"ltp":1.73,"tv":2428.4,"id":2263634}]}]}
{"op":"mcm","clk":"1005399620","pt":1580642486499,"mc":[{"id":"1.168224441","rc":[{"trd":[[2.38,533.35]],"batl":[[0,2.72,8.65],[1,95,15.9],[2,990,2.2]],"ltp":2.38,"tv":2074.7,"id":10894176},{"trd":[[1.73,62.77]],"batb":[[0,1.73,5.72]],"ltp":1.73,"tv":2434.19,"id":2263634}],"tv":4508.9}]}
{"op":"mcm","clk":"1005399843","pt":1580642487706,"mc":[{"id":"1.168224441","rc":[{"trd":[[2.34,227.44]],"batb":[[0,2.34,1.43]],"ltp":2.34,"tv":2088.02,"id":10894176}],"tv":4522.22}]}
{"op":"mcm","clk":"1005401276","pt":1580642496227,"mc":[{"id":"1.168224441","rc":[{"batb":[[0,2.32,9.54]],"ltp":2.34,"tv":2088.02,"id":10894176},{"batb":[[0,1.72,223.1],[1,1.66,73.56],[2,1.61,515.67]],"ltp":1.73,"tv":2434.19,"id":2263634}]}]}
{"op":"mcm","clk":"1005403432","pt":1580642508651,"mc":[{"id":"1.168224441","rc":[{"batb":[[0,2.32,19.47]],"ltp":2.34,"tv":2088.02,"id":10894176},{"batl":[[0,1.75,18.85]],"ltp":1.73,"tv":2434.19,"id":2263634}]}]}
{"op":"mcm","clk":"1005404558","pt":1580642514987,"mc":[{"id":"1.168224441","rc":[{"batb":[[0,2.32,28.08]],"ltp":2.34,"tv":2088.02,"id":10894176},{"batl":[[0,1.75,27.46]],"ltp":1.73,"tv":2434.19,"id":2263634}]}]}
{"op":"mcm","clk":"1005408587","pt":1580642536275,"mc":[{"id":"1.168224441","rc":[{"trd":[[1.72,644.39]],"batb":[[0,1.72,158.94]],"ltp":1.72,"tv":2562.51,"id":2263634}],"tv":4650.54}]}
{"op":"mcm","clk":"1005408684","pt":1580642536808,"mc":[{"id":"1.168224441","rc":[{"trd":[[1.75,175.17]],"batl":[[0,1.75,4.95]],"ltp":1.75,"tv":2607.52,"id":2263634}],"tv":4695.55}]}
{"op":"mcm","clk":"1005409004","pt":1580642538405,"mc":[{"id":"1.168224441","rc":[{"trd":[[2.38,540.84]],"batb":[[0,2.38,5.12],[1,2.32,28.08],[2,2.26,47.69]],"ltp":2.38,"tv":2095.51,"id":10894176},{"trd":[[1.73,73.08]],"ltp":1.73,"tv":2617.83,"id":2263634}],"tv":4713.34}]}
{"op":"mcm","clk":"1005409432","pt":1580642540869,"mc":[{"id":"1.168224441","rc":[{"batl":[[0,1.75,20.09]],"ltp":1.73,"tv":2617.83,"id":2263634}]}]}
{"op":"mcm","clk":"1005409965","pt":1580642543687,"mc":[{"id":"1.168224441","rc":[{"batb":[[1,2.34,13.42],[2,2.32,28.08]],"ltp":2.38,"tv":2095.51,"id":10894176},{"batl":[[1,1.76,144.51]],"ltp":1.73,"tv":2617.83,"id":2263634}]}]}
{"op":"mcm","clk":"1005411062","pt":1580642549157,"mc":[{"id":"1.168224441","rc":[{"batl":[[1,3.9,153.72],[2,95,15.9]],"ltp":2.38,"tv":2095.51,"id":10894176}]}]}
{"op":"mcm","clk":"1005412855","pt":1580642558371,"mc":[{"id":"1.168224441","rc":[{"batb":[[2,2.32,18.53]],"ltp":2.38,"tv":2095.51,"id":10894176}]}]}
{"op":"mcm","clk":"1005418852","pt":1580642589331,"mc":[{"id":"1.168224441","rc":[{"trd":[[2.4,337.92]],"ltp":2.4,"tv":2153.4,"id":10894176},{"trd":[[1.72,725.17]],"batb":[[0,1.72,78.16]],"ltp":1.72,"tv":2698.6,"id":2263634}],"tv":4852.01}]}
{"op":"mcm","clk":"1005418983","pt":1580642589919,"mc":[{"id":"1.168224441","rc":[{"trd":[[2.38,549.18]],"batb":[[0,2.34,14.37],[1,2.32,18.53],[2,2.04,44.68]],"ltp":2.38,"tv":2161.74,"id":10894176}],"tv":4860.35}]}
{"op":"mcm","clk":"1005424665","pt":1580642618328,"mc":[{"id":"1.168224441","rc":[{"trd":[[1.72,880.99]],"batb":[[0,1.66,73.81],[1,1.61,515.67],[2,1.6,142.61]],"ltp":1.72,"tv":2854.42,"id":2263634}],"tv":5016.17}]}
{"op":"mcm","clk":"1005424989","pt":1580642619939,"mc":[{"id":"1.168224441","rc":[{"trd":[[2.34,248.92],[2.38,551.08]],"batb":[[0,2.34,2.68]],"ltp":2.34,"tv":2185.12,"id":10894176},{"batb":[[0,1.66,277.59]],"ltp":1.72,"tv":2854.42,"id":2263634}],"tv":5039.55}]}
{"op":"mcm","clk":"1005425111","pt":1580642620639,"mc":[{"id":"1.168224441","rc":[{"batb":[[0,2.32,18.53],[1,2.24,45.95]],"ltp":2.34,"tv":2185.12,"id":10894176},{"batb":[[0,1.67,76.99],[1,1.66,203.78],[2,1.61,515.67]],"ltp":1.72,"tv":2854.42,"id":2263634}]}]}
{"op":"mcm","clk":"1005425271","pt":1580642621550,"mc":[{"id":"1.168224441","rc":[{"batb":[[1,1.61,515.67],[2,1.6,142.61]],"ltp":1.72,"tv":2854.42,"id":2263634}]}]}
{"op":"mcm","clk":"1005430889","pt":1580642650995,"mc":[{"id":"1.168224441","rc":[{"batb":[[0,2.32,24.9]],"ltp":2.34,"tv":2185.12,"id":10894176},{"trd":[[1.75,221.96]],"batl":[[0,1.75,5.1]],"ltp":1.75,"tv":2901.21,"id":2263634}],"tv":5086.34}]}
{"op":"mcm","clk":"1005431042","pt":1580642651746,"mc":[{"id":"1.168224441","rc":[{"trd":[[1.74,64.48]],"batb":[[0,1.67,77.02]],"ltp":1.74,"tv":2931.62,"id":2263634}],"tv":5116.75}]}
{"op":"mcm","clk":"1005431287","pt":1580642652876,"mc":[{"id":"1.168224441","rc":[{"trd":[[1.74,64.54]],"batb":[[0,1.67,76.99]],"batl":[[0,1.74,117.17],[1,1.75,5.1],[2,1.76,144.51]],"ltp":1.74,"tv":2931.68,"id":2263634}],"tv":5116.81}]}
{"op":"mcm","clk":"1005431557","pt":1580642654158,"mc":[{"id":"1.168224441","rc":[{"batb":[[0,2.36,9.75],[1,2.32,6.37],[2,2.24,45.95]],"ltp":2.34,"tv":2185.12,"id":10894176},{"batb":[[1,1.61,477.81]],"batl":[[0,1.73,9.41],[1,1.74,98.25],[2,1.75,5.1]],"ltp":1.74,"tv":2931.68,"id":2263634}]}]}
{"op":"mcm","clk":"1005431740","pt":1580642655074,"mc":[{"id":"1.168224441","rc":[{"batl":[[1,1.75,20.24],[2,1.76,144.51]],"ltp":1.74,"tv":2931.68,"id":2263634}]}]}
{"op":"mcm","clk":"1005431993","pt":1580642656291,"mc":[{"id":"1.168224441","rc":[{"batb":[[0,2.32,24.82],[1,2.24,45.95],[2,2.04,44.68]],"ltp":2.34,"tv":2185.12,"id":10894176},{"batl":[[0,1.75,28.77],[1,1.76,144.51],[2,1.81,25.75]],"ltp":1.74,"tv":2931.68,"id":2263634}]}]}
{"op":"mcm","clk":"1005432126","pt":1580642656885,"mc":[{"id":"1.168224441","rc":[{"batl":[[0,1.74,98.25],[1,1.75,28.77],[2,1.76,144.51]],"ltp":1.74,"tv":2931.68,"id":2263634}]}]}
{"op":"mcm","clk":"1005432394","pt":1580642658079,"mc":[{"id":"1.168224441","rc":[{"batl":[[0,1.74,116.98],[1,1.75,20.24]],"ltp":1.74,"tv":2931.68,"id":2263634}]}]}
{"op":"mcm","clk":"1005432632","pt":1580642659268,"mc":[{"id":"1.168224441","rc":[{"batl":[[0,1.74,98.25]],"ltp":1.74,"tv":2931.68,"id":2263634}]}]}
{"op":"mcm","clk":"1005432794","pt":1580642660073,"mc":[{"id":"1.168224441","rc":[{"batl":[[1,1.75,27.82]],"ltp":1.74,"tv":2931.68,"id":2263634}]}]}
{"op":"mcm","clk":"1005433026","pt":1580642661306,"mc":[{"id":"1.168224441","rc":[{"batl":[[0,1.75,27.82],[1,1.76,144.51],[2,1.81,25.75]],"ltp":1.74,"tv":2931.68,"id":2263634}]}]}
{"op":"mcm","clk":"1005433072","pt":1580642661471,"mc":[{"id":"1.168224441","rc":[{"batl":[[0,1.74,98.25],[1,1.75,27.82],[2,1.76,144.51]],"ltp":1.74,"tv":2931.68,"id":2263634}]}]}
{"op":"mcm","clk":"1005435192","pt":1580642672097,"mc":[{"id":"1.168224441","rc":[{"trd":[[1.67,41.71],[1.72,881.49]],"batb":[[0,1.67,55.88]],"ltp":1.67,"tv":2973.9,"id":2263634}],"tv":5159.03}]}
{"op":"mcm","clk":"1005435639","pt":1580642674393,"mc":[{"id":"1.168224441","rc":[{"batb":[[0,2.34,17.53],[1,2.32,24.82]],"ltp":2.34,"tv":2185.12,"id":10894176},{"batb":[[0,1.66,67.83]],"ltp":1.67,"tv":2973.9,"id":2263634}]}]}
{"op":"mcm","clk":"1005435733","pt":1580642674880,"mc":[{"id":"1.168224441","rc":[{"batb":[[0,1.66,271.61]],"ltp":1.67,"tv":2973.9,"id":2263634}]}]}
{"op":"mcm","clk":"1005435852","pt":1580642675618,"mc":[{"id":"1.168224441","rc":[{"batb":[[1,2.32,6.37]],"ltp":2.34,"tv":2185.12,"id":10894176}]}]}
{"op":"mcm","clk":"1005437160","pt":1580642682346,"mc":[{"id":"1.168224441","rc":[{"batb":[[1,2.04,44.68],[2,2,37.86]],"ltp":2.34,"tv":2185.12,"id":10894176},{"batl":[[1,1.75,22.72]],"ltp":1.67,"tv":2973.9,"id":2263634}]}]}
{"op":"mcm","clk":"1005437332","pt":1580642683246,"mc":[{"id":"1.168224441","rc":[{"batl":[[0,2.5,8.4],[1,2.72,8.65],[2,3.9,153.72]],"ltp":2.34,"tv":2185.12,"id":10894176},{"trd":[[1.74,228.42]],"batb":[[0,1.67,12.54],[1,1.66,67.83],[2,1.61,477.81]],"batl":[[0,1.73,8.4],[1,1.74,16.31],[2,1.75,22.72]],"ltp":1.74,"tv":3137.78,"id":2263634}],"tv":5322.91}]}
{"op":"mcm","clk":"1005437388","pt":1580642683521,"mc":[{"id":"1.168224441","rc":[{"batb":[[0,2.36,6.18],[1,2.34,17.53],[2,2.04,44.68]],"ltp":2.34,"tv":2185.12,"id":10894176},{"batl":[[1,1.75,22.72],[2,1.76,144.51]],"ltp":1.74,"tv":3137.78,"id":2263634}]}]}
{"op":"mcm","clk":"1005441867","pt":1580642707960,"mc":[{"id":"1.168224441","rc":[{"batb":[[2,1.65,1.29]],"ltp":1.74,"tv":3137.78,"id":2263634}]}]}
{"op":"mcm","clk":"1005443212","pt":1580642715191,"mc":[{"id":"1.168224441","rc":[{"trd":[[2.36,10.04]],"batb":[[0,2.36,1.16],[1,2.34,55.75]],"ltp":2.36,"tv":2195.16,"id":10894176},{"batl":[[0,1.75,22.72],[1,1.76,144.51],[2,1.81,25.75]],"ltp":1.74,"tv":3137.78,"id":2263634}],"tv":5332.94}]}
{"op":"mcm","clk":"1005443263","pt":1580642715503,"mc":[{"id":"1.168224441","rc":[{"batb":[[0,1.66,67.83],[1,1.65,1.29],[2,1.61,477.81]],"ltp":1.74,"tv":3137.78,"id":2263634}]}]}
{"op":"mcm","clk":"1005444431","pt":1580642722236,"mc":[{"id":"1.168224441","rc":[{"batl":[[0,1.74,7.57],[1,1.75,22.72],[2,1.76,144.51]],"ltp":1.74,"tv":3137.78,"id":2263634}]}]}
{"op":"mcm","clk":"1005444533","pt":1580642722867,"mc":[{"id":"1.168224441","rc":[{"batb":[[1,2.34,17.53]],"ltp":2.36,"tv":2195.16,"id":10894176},{"batl":[[0,1.74,58.82]],"ltp":1.74,"tv":3137.78,"id":2263634}]}]}
{"op":"mcm","clk":"1005449031","pt":1580642747405,"mc":[{"id":"1.168224441","rc":[{"batb":[[0,2.34,17.53],[1,2.04,44.68],[2,2,37.86]],"ltp":2.36,"tv":2195.16,"id":10894176},{"trd":[[1.74,325.54]],"batb":[[0,1.66,80.56]],"batl":[[0,1.74,8.4]],"ltp":1.74,"tv":3234.9,"id":2263634}],"tv":5430.06}]}
{"op":"mcm","clk":"1005449052","pt":1580642747513,"mc":[{"id":"1.168224441","rc":[{"batb":[[0,2.34,23.79]],"ltp":2.36,"tv":2195.16,"id":10894176}]}]}
{"op":"mcm","clk":"1005449243","pt":1580642748527,"mc":[{"id":"1.168224441","rc":[{"batl":[[0,1.74,23.88]],"ltp":1.74,"tv":3234.9,"id":2263634}]}]}
{"op":"mcm","clk":"1005450261","pt":1580642754103,"mc":[{"id":"1.168224441","rc":[{"batl":[[1,1.75,30.29]],"ltp":1.74,"tv":3234.9,"id":2263634}]}]}
{"op":"mcm","clk":"1005450878","pt":1580642757225,"mc":[{"id":"1.168224441","rc":[{"trd":[[1.74,364.06]],"batl":[[0,1.74,4.62],[1,1.76,144.51],[2,1.81,25.75]],"ltp":1.74,"tv":3273.42,"id":2263634}],"tv":5468.59}]}
{"op":"mcm","clk":"1005451065","pt":1580642758137,"mc":[{"id":"1.168224441","rc":[{"batb":[[0,1.7,7.75],[1,1.66,80.56],[2,1.65,1.29]],"batl":[[0,1.74,15.55]],"ltp":1.74,"tv":3273.42,"id":2263634}]}]}
{"op":"mcm","clk":"1005451274","pt":1580642759108,"mc":[{"id":"1.168224441","rc":[{"trd":[[1.66,11.88],[1.7,134.34]],"batb":[[0,1.66,74.62],[1,1.65,1.29],[2,1.61,477.81]],"batl":[[1,1.75,7.57],[2,1.76,144.51]],"ltp":1.66,"tv":3300.79,"id":2263634}],"tv":5495.95}]}
{"op":"mcm","clk":"1005451504","pt":1580642760336,"mc":[{"id":"1.168224441","rc":[{"batb":[[0,2.34,6.27],[1,2.32,29.94],[2,2.04,44.68]],"ltp":2.36,"tv":2195.16,"id":10894176},{"batl":[[1,1.75,15.14]],"ltp":1.66,"tv":3300.79,"id":2263634}]}]}
{"op":"mcm","clk":"1005452078","pt":1580642763238,"mc":[{"id":"1.168224441","rc":[{"batl":[[0,1.74,23.12]],"ltp":1.66,"tv":3300.79,"id":2263634}]}]}
{"op":"mcm","clk":"1005452137","pt":1580642763558,"mc":[{"id":"1.168224441","rc":[{"batl":[[0,1.74,30.7]],"ltp":1.66,"tv":3300.79,"id":2263634}]}]}
{"op":"mcm","clk":"1005452900","pt":1580642767924,"mc":[{"id":"1.168224441","rc":[{"batb":[[2,1.62,190.53]],"ltp":1.66,"tv":3300.79,"id":2263634}]}]}
{"op":"mcm","clk":"1005455031","pt":1580642779235,"mc":[{"id":"1.168224441","rc":[{"batb":[[0,2.32,29.94],[1,2.04,44.68],[2,2.02,115.81]],"ltp":2.36,"tv":2195.16,"id":10894176},{"batl":[[0,1.74,22.72]],"ltp":1.66,"tv":3300.79,"id":2263634}]}]}
{"op":"mcm","clk":"1005455419","pt":1580642781426,"mc":[{"id":"1.168224441","rc":[{"batl":[[0,1.74,30.29]],"ltp":1.66,"tv":3300.79,"id":2263634}]}]}
{"op":"mcm","clk":"1005455896","pt":1580642784027,"mc":[{"id":"1.168224441","rc":[{"batl":[[0,1.75,15.14],[1,1.76,144.51],[2,1.81,25.75]],"ltp":1.66,"tv":3300.79,"id":2263634}]}]}
{"op":"mcm","clk":"1005456167","pt":1580642785356,"mc":[{"id":"1.168224441","rc":[{"batb":[[0,2.34,9.84],[1,2.32,319.58],[2,2.04,44.68]],"ltp":2.36,"tv":2195.16,"id":10894176}]}]}
{"op":"mcm","clk":"1005456356","pt":1580642786227,"mc":[{"id":"1.168224441","rc":[{"trd":[[2.34,264]],"batb":[[0,2.34,2.3],[1,2.32,273.08]],"ltp":2.34,"tv":2210.23,"id":10894176}],"tv":5511.03}]}
{"op":"mcm","clk":"1005456519","pt":1580642787179,"mc":[{"id":"1.168224441","rc":[{"batb":[[0,2.32,273.08],[1,2.04,44.68],[2,2.02,115.81]],"ltp":2.34,"tv":2210.23,"id":10894176}]}]}
{"op":"mcm","clk":"1005456840","pt":1580642788725,"mc":[{"id":"1.168224441","rc":[{"batb":[[0,2.32,29.94]],"ltp":2.34,"tv":2210.23,"id":10894176},{"batl":[[0,1.74,15.14],[1,1.75,15.14],[2,1.76,144.51]],"ltp":1.66,"tv":3300.79,"id":2263634}]}]}
{"op":"mcm","clk":"1005458117","pt":1580642794737,"mc":[{"id":"1.168224441","rc":[{"batb":[[0,2.32,41]],"ltp":2.34,"tv":2210.23,"id":10894176},{"batl":[[1,1.75,25.13]],"ltp":1.66,"tv":3300.79,"id":2263634}]}]}
{"op":"mcm","clk":"1005459667","pt":1580642802988,"mc":[{"id":"1.168224441","rc":[{"batl":[[0,1.74,22.72]],"ltp":1.66,"tv":3300.79,"id":2263634}]}]}
{"op":"mcm","clk":"1005460252","pt":1580642805567,"mc":[{"id":"1.168224441","rc":[{"batl":[[1,1.75,9.99]],"ltp":1.66,"tv":3300.79,"id":2263634}]}]}
{"op":"mcm","clk":"1005460663","pt":1580642807169,"mc":[{"id":"1.168224441","rc":[{"batl":[[1,1.75,17.56]],"ltp":1.66,"tv":3300.79,"id":2263634}]}]}
{"op":"mcm","clk":"1005460760","pt":1580642807660,"mc":[{"id":"1.168224441","rc":[{"batl":[[1,1.75,25.13]],"ltp":1.66,"tv":3300.79,"id":2263634}]}]}
{"op":"mcm","clk":"1005461039","pt":1580642809291,"mc":[{"id":"1.168224441","rc":[{"batb":[[0,2.32,11.06]],"ltp":2.34,"tv":2210.23,"id":10894176},{"batl":[[0,1.74,30.29]],"ltp":1.66,"tv":3300.79,"id":2263634}]}]}
{"op":"mcm","clk":"1005461167","pt":1580642809871,"mc":[{"id":"1.168224441","rc":[{"batb":[[0,2.36,13.67],[1,2.32,11.06],[2,2.04,44.68]],"ltp":2.34,"tv":2210.23,"id":10894176},{"batl":[[0,1.74,15.14]],"ltp":1.66,"tv":3300.79,"id":2263634}]}]}
{"op":"mcm","clk":"1005465154","pt":1580642830345,"mc":[{"id":"1.168224441","rc":[{"batl":[[1,1.75,9.99]],"ltp":1.66,"tv":3300.79,"id":2263634}]}]}
{"op":"mcm","clk":"1005465328","pt":1580642831311,"mc":[{"id":"1.168224441","rc":[{"trd":[[2.36,31.83]],"batb":[[0,2.36,2.77]],"ltp":2.36,"tv":2232.03,"id":10894176}],"tv":5532.82}]}
{"op":"mcm","clk":"1005465563","pt":1580642832602,"mc":[{"id":"1.168224441","rc":[{"batb":[[0,2.32,30.05],[1,2.04,44.68],[2,2.02,115.81]],"ltp":2.36,"tv":2232.03,"id":10894176},{"batb":[[0,1.67,15.31],[1,1.66,74.62],[2,1.65,1.29]],"ltp":1.66,"tv":3300.79,"id":2263634}]}]}
{"op":"mcm","clk":"1005467215","pt":1580642841932,"mc":[{"id":"1.168224441","rc":[{"batb":[[0,1.67,34.12],[1,1.66,61.89]],"ltp":1.66,"tv":3300.79,"id":2263634}]}]}
{"op":"mcm","clk":"1005474157","pt":1580642878414,"mc":[{"id":"1.168224441","rc":[{"trd":[[1.74,401.01]],"batl":[[0,1.74,4.24]],"ltp":1.74,"tv":3337.73,"id":2263634}],"tv":5569.77}]}
{"op":"mcm","clk":"1005475046","pt":1580642883659,"mc":[{"id":"1.168224441","rc":[{"batb":[[0,1.7,7.57],[1,1.67,34.12],[2,1.66,61.89]],"ltp":1.74,"tv":3337.73,"id":2263634}]}]}
{"op":"mcm","clk":"1005477937","pt":1580642900521,"mc":[{"id":"1.168224441","rc":[{"batb":[[0,1.7,15.14]],"ltp":1.74,"tv":3337.73,"id":2263634}]}]}
{"op":"mcm","clk":"1005478299","pt":1580642902334,"mc":[{"id":"1.168224441","rc":[{"batb":[[0,1.67,34.12],[1,1.66,61.89],[2,1.65,1.29]],"batl":[[0,1.75,9.99],[1,1.76,144.51],[2,1.81,25.75]],"ltp":1.74,"tv":3337.73,"id":2263634}]}]}
{"op":"mcm","clk":"1005478652","pt":1580642904030,"mc":[{"id":"1.168224441","rc":[{"batb":[[0,2.32,273.19]],"ltp":2.36,"tv":2232.03,"id":10894176},{"batb":[[0,1.7,18.92],[1,1.67,34.12],[2,1.66,61.89]],"ltp":1.74,"tv":3337.73,"id":2263634}]}]}
{"op":"mcm","clk":"1005479033","pt":1580642906342,"mc":[{"id":"1.168224441","rc":[{"batb":[[0,2.32,30.05]],"ltp":2.36,"tv":2232.03,"id":10894176},{"batl":[[0,1.75,17.56]],"ltp":1.74,"tv":3337.73,"id":2263634}]}]}
{"op":"mcm","clk":"1005479225","pt":1580642907430,"mc":[{"id":"1.168224441","rc":[{"batb":[[0,2.32,273.19]],"ltp":2.36,"tv":2232.03,"id":10894176},{"trd":[[1.75,250.52]],"batl":[[0,1.75,3.28]],"ltp":1.75,"tv":3366.3,"id":2263634}],"tv":5598.33}]}
{"op":"mcm","clk":"1005479546","pt":1580642909422,"mc":[{"id":"1.168224441","rc":[{"batb":[[0,2.32,30.05]],"ltp":2.36,"tv":2232.03,"id":10894176}]}]}
{"op":"mcm","clk":"1005479633","pt":1580642909915,"mc":[{"id":"1.168224441","rc":[{"trd":[[1.74,415.97]],"batb":[[0,1.7,19.01]],"ltp":1.74,"tv":3381.26,"id":2263634}],"tv":5613.29}]}
{"op":"mcm","clk":"1005479897","pt":1580642911523,"mc":[{"id":"1.168224441","rc":[{"batl":[[0,1.75,10.85]],"ltp":1.74,"tv":3381.26,"id":2263634}]}]}
{"op":"mcm","clk":"1005480522","pt":1580642915305,"mc":[{"id":"1.168224441","rc":[{"batb":[[0,1.67,34.21],[1,1.66,61.89],[2,1.65,1.29]],"ltp":1.74,"tv":3381.26,"id":2263634}]}]}
{"op":"mcm","clk":"1005480856","pt":1580642917441,"mc":[{"id":"1.168224441","rc":[{"batb":[[0,1.67,42.93]],"batl":[[0,1.75,7.57]],"ltp":1.74,"tv":3381.26,"id":2263634}]}]}
{"op":"mcm","clk":"1005480949","pt":1580642918028,"mc":[{"id":"1.168224441","rc":[{"batb":[[0,1.7,15.67],[1,1.67,42.93],[2,1.66,61.89]],"batl":[[0,1.75,15.14]],"ltp":1.74,"tv":3381.26,"id":2263634}]}]}
{"op":"mcm","clk":"1005483765","pt":1580642934258,"mc":[{"id":"1.168224441","rc":[{"batl":[[0,1.75,392.88]],"ltp":1.74,"tv":3381.26,"id":2263634}]}]}
{"op":"mcm","clk":"1005483889","pt":1580642935057,"mc":[{"id":"1.168224441","rc":[{"batl":[[0,2.72,8.65],[1,3.9,153.72],[2,95,15.9]],"ltp":2.36,"tv":2232.03,"id":10894176}]}]}
{"op":"mcm","clk":"1005484124","pt":1580642936356,"mc":[{"id":"1.168224441","rc":[{"batl":[[0,2.44,12.6],[1,2.72,8.65],[2,3.9,153.72]],"ltp":2.36,"tv":2232.03,"id":10894176},{"batb":[[0,1.7,33.68],[1,1.67,24.12]],"batl":[[0,1.75,15.14]],"ltp":1.74,"tv":3381.26,"id":2263634}]}]}
{"op":"mcm","clk":"1005484292","pt":1580642937366,"mc":[{"id":"1.168224441","rc":[{"trd":[[1.75,275.72]],"batl":[[0,1.75,380.28]],"ltp":1.75,"tv":3406.46,"id":2263634}],"tv":5638.49}]}
{"op":"mcm","clk":"1005484491","pt":1580642938343,"mc":[{"id":"1.168224441","rc":[{"batl":[[0,1.75,320.1]],"ltp":1.75,"tv":3406.46,"id":2263634}]}]}
{"op":"mcm","clk":"1005484825","pt":1580642940166,"mc":[{"id":"1.168224441","rc":[{"trd":[[1.74,430.93]],"batb":[[0,1.7,33.77]],"batl":[[0,1.75,2.54]],"ltp":1.74,"tv":3421.42,"id":2263634}],"tv":5653.46}]}
{"op":"mcm","clk":"1005485239","pt":1580642942144,"mc":[{"id":"1.168224441","rc":[{"batb":[[0,1.71,21.92],[1,1.7,33.68],[2,1.67,8.81]],"ltp":1.74,"tv":3421.42,"id":2263634}]}]}
{"op":"mcm","clk":"1005485334","pt":1580642942677,"mc":[{"id":"1.168224441","rc":[{"batb":[[0,1.71,21.83]],"ltp":1.74,"tv":3421.42,"id":2263634}]}]}
{"op":"mcm","clk":"1005485575","pt":1580642943965,"mc":[{"id":"1.168224441","rc":[{"batb":[[2,1.65,1.29]],"batl":[[0,1.75,7.57]],"ltp":1.74,"tv":3421.42,"id":2263634}]}]}
{"op":"mcm","clk":"1005485902","pt":1580642945779,"mc":[{"id":"1.168224441","rc":[{"batb":[[0,1.72,7.57],[1,1.71,21.83],[2,1.7,33.68]],"ltp":1.74,"tv":3421.42,"id":2263634}]}]}
{"op":"mcm","clk":"1005486229","pt":1580642947581,"mc":[{"id":"1.168224441","rc":[{"batb":[[2,1.7,18.01]],"ltp":1.74,"tv":3421.42,"id":2263634}]}]}
{"op":"mcm","clk":"1005489699","pt":1580642967233,"mc":[{"id":"1.168224441","rc":[{"batl":[[0,2.72,8.65],[1,3.9,153.72],[2,95,15.9]],"ltp":2.36,"tv":2232.03,"id":10894176}]}]}
{"op":"mcm","clk":"1005489940","pt":1580642968444,"mc":[{"id":"1.168224441","rc":[{"batl":[[0,2.4,12.6],[1,2.72,8.65],[2,3.9,153.72]],"ltp":2.36,"tv":2232.03,"id":10894176},{"trd":[[1.75,287.49]],"batb":[[0,1.72,25.07],[2,1.65,1.29]],"batl":[[0,1.75,313.95]],"ltp":1.75,"tv":3433.18,"id":2263634}],"tv":5665.22}]}
{"op":"mcm","clk":"1005490116","pt":1580642969428,"mc":[{"id":"1.168224441","rc":[{"batl":[[0,1.75,1.69]],"ltp":1.75,"tv":3433.18,"id":2263634}]}]}
{"op":"mcm","clk":"1005490137","pt":1580642969536,"mc":[{"id":"1.168224441","rc":[{"batl":[[0,1.75,313.95]],"ltp":1.75,"tv":3433.18,"id":2263634}]}]}
{"op":"mcm","clk":"1005490744","pt":1580642972866,"mc":[{"id":"1.168224441","rc":[{"trd":[[1.74,445.89]],"batb":[[0,1.72,25.16]],"batl":[[0,1.75,1.69]],"ltp":1.74,"tv":3448.14,"id":2263634}],"tv":5680.18}]}
{"op":"mcm","clk":"1005491116","pt":1580642974819,"mc":[{"id":"1.168224441","rc":[{"batb":[[0,1.72,25.07]],"ltp":1.74,"tv":3448.14,"id":2263634}]}]}
{"op":"mcm","clk":"1005491226","pt":1580642975546,"mc":[{"id":"1.168224441","rc":[{"batl":[[0,1.75,9.26]],"ltp":1.74,"tv":3448.14,"id":2263634}]}]}
{"op":"mcm","clk":"1005499507","pt":1580643019201,"mc":[{"id":"1.168224441","rc":[{"batl":[[0,1.75,374.96]],"ltp":1.74,"tv":3448.14,"id":2263634}]}]}
{"op":"mcm","clk":"1005499707","pt":1580643020329,"mc":[{"id":"1.168224441","rc":[{"trd":[[1.75,751.49]],"batl":[[0,1.75,186.82]],"ltp":1.75,"tv":3912.15,"id":2263634}],"tv":6144.18}]}
{"op":"mcm","clk":"1005499855","pt":1580643021235,"mc":[{"id":"1.168224441","rc":[{"batl":[[0,1.75,156.98]],"ltp":1.75,"tv":3912.15,"id":2263634}]}]}
{"op":"mcm","clk":"1005500263","pt":1580643023232,"mc":[{"id":"1.168224441","rc":[{"batl":[[0,1.75,186.82]],"ltp":1.75,"tv":3912.15,"id":2263634}]}]}
{"op":"mcm","clk":"1005500455","pt":1580643024202,"mc":[{"id":"1.168224441","rc":[{"batl":[[0,1.75,156.98]],"ltp":1.75,"tv":3912.15,"id":2263634}]}]}
{"op":"mcm","clk":"1005500631","pt":1580643025212,"mc":[{"id":"1.168224441","rc":[{"batl":[[0,1.75,186.82]],"ltp":1.75,"tv":3912.15,"id":2263634}]}]}
{"op":"mcm","clk":"1005500824","pt":1580643026231,"mc":[{"id":"1.168224441","rc":[{"batl":[[0,1.75,156.98]],"ltp":1.75,"tv":3912.15,"id":2263634}]}]}
{"op":"mcm","clk":"1005501003","pt":1580643027147,"mc":[{"id":"1.168224441","rc":[{"batl":[[0,1.75,186.82]],"ltp":1.75,"tv":3912.15,"id":2263634}]}]}
{"op":"mcm","clk":"1005502223","pt":1580643033443,"mc":[{"id":"1.168224441","rc":[{"batb":[[0,1.74,7.57],[1,1.72,25.07],[2,1.71,21.83]],"ltp":1.75,"tv":3912.15,"id":2263634}]}]}
{"op":"mcm","clk":"1005502278","pt":1580643033790,"mc":[{"id":"1.168224441","rc":[{"trd":[[1.74,460.85]],"batb":[[0,1.72,25.16],[1,1.71,21.83],[2,1.65,1.29]],"batl":[[0,1.76,144.51],[1,1.81,25.75],[2,1.86,21.85]],"ltp":1.74,"tv":3927.11,"id":2263634}],"tv":6159.14}]}
{"op":"mcm","clk":"1005502560","pt":1580643035437,"mc":[{"id":"1.168224441","rc":[{"batl":[[0,1.75,7.57],[1,1.76,144.51],[2,1.81,25.75]],"ltp":1.74,"tv":3927.11,"id":2263634}]}]}
{"op":"mcm","clk":"1005502641","pt":1580643035929,"mc":[{"id":"1.168224441","rc":[{"batl":[[0,1.75,15.14]],"ltp":1.74,"tv":3927.11,"id":2263634}]}]}
{"op":"mcm","clk":"1005502923","pt":1580643037760,"mc":[{"id":"1.168224441","rc":[{"batb":[[0,1.72,17.59]],"ltp":1.74,"tv":3927.11,"id":2263634}]}]}
{"op":"mcm","clk":"1005505526","pt":1580643052539,"mc":[{"id":"1.168224441","rc":[{"trd":[[1.75,781.77]],"batl":[[0,1.76,144.51],[1,1.81,25.75],[2,1.86,21.85]],"ltp":1.75,"tv":3957.39,"id":2263634}],"tv":6189.43}]}
{"op":"mcm","clk":"1005506763","pt":1580643059017,"mc":[{"id":"1.168224441","rc":[{"batl":[[0,1.75,151.94],[1,1.76,144.51],[2,1.81,25.75]],"ltp":1.75,"tv":3957.39,"id":2263634}]}]}
{"op":"mcm","clk":"1005506947","pt":1580643060023,"mc":[{"id":"1.168224441","rc":[{"batl":[[0,1.75,181.05]],"ltp":1.75,"tv":3957.39,"id":2263634}]}]}
{"op":"mcm","clk":"1005507188","pt":1580643061217,"mc":[{"id":"1.168224441","rc":[{"batl":[[0,1.75,151.94]],"ltp":1.75,"tv":3957.39,"id":2263634}]}]}
{"op":"mcm","clk":"1005509466","pt":1580643073436,"mc":[{"id":"1.168224441","rc":[{"batb":[[1,1.66,77.2]],"ltp":1.75,"tv":3957.39,"id":2263634}]}]}
{"op":"mcm","clk":"1005529810","pt":1580643181360,"mc":[{"id":"1.168224441","rc":[{"trd":[[1.75,1050.39]],"batl":[[0,1.75,76.47]],"ltp":1.75,"tv":4226.01,"id":2263634}],"tv":6458.05}]}
{"op":"mcm","clk":"1005530329","pt":1580643183994,"mc":[{"id":"1.168224441","rc":[{"batl":[[0,1.75,15.14]],"ltp":1.75,"tv":4226.01,"id":2263634}]}]}
{"op":"mcm","clk":"1005530757","pt":1580643186099,"mc":[{"id":"1.168224441","rc":[{"batb":[[0,1.74,7.66],[1,1.72,17.5],[2,1.66,77.2]],"ltp":1.75,"tv":4226.01,"id":2263634}]}]}
{"op":"mcm","clk":"1005531323","pt":1580643189204,"mc":[{"id":"1.168224441","rc":[{"batl":[[0,1.76,144.51],[1,1.81,25.75],[2,1.86,21.85]],"ltp":1.75,"tv":4226.01,"id":2263634}]}]}
{"op":"mcm","clk":"1005531997","pt":1580643193000,"mc":[{"id":"1.168224441","rc":[{"batb":[[0,1.74,15.24]],"ltp":1.75,"tv":4226.01,"id":2263634}]}]}
{"op":"mcm","clk":"1005532386","pt":1580643194983,"mc":[{"id":"1.168224441","rc":[{"trd":[[2.32,300.29]],"batb":[[0,2.32,28.05]],"ltp":2.32,"tv":2236.03,"id":10894176}],"tv":6462.05}]}
{"op":"mcm","clk":"1005532788","pt":1580643197174,"mc":[{"id":"1.168224441","rc":[{"batb":[[0,2.32,27.73]],"ltp":2.32,"tv":2236.03,"id":10894176}]}]}
{"op":"mcm","clk":"1005534565","pt":1580643205420,"mc":[{"id":"1.168224441","rc":[{"batb":[[0,2.32,21.46]],"ltp":2.32,"tv":2236.03,"id":10894176},{"trd":[[1.74,477.74]],"batb":[[0,1.74,6.79],[2,1.67,74.23]],"ltp":1.74,"tv":4242.9,"id":2263634}],"tv":6478.94}]}
{"op":"mcm","clk":"1005535822","pt":1580643211217,"mc":[{"id":"1.168224441","rc":[{"batl":[[0,1.75,7.57],[1,1.76,144.51],[2,1.81,25.75]],"ltp":1.74,"tv":4242.9,"id":2263634}]}]}
{"op":"mcm","clk":"1005535952","pt":1580643211819,"mc":[{"id":"1.168224441","rc":[{"trd":[[1.75,1062.21]],"batl":[[0,1.75,1.67]],"ltp":1.75,"tv":4254.72,"id":2263634}],"tv":6490.75}]}
{"op":"mcm","clk":"1005536421","pt":1580643214135,"mc":[{"id":"1.168224441","rc":[{"batb":[[0,1.74,14.36]],"ltp":1.75,"tv":4254.72,"id":2263634}]}]}
{"op":"mcm","clk":"1005536882","pt":1580643216238,"mc":[{"id":"1.168224441","rc":[{"batl":[[0,2.72,8.65],[1,3.9,153.72],[2,95,15.9]],"ltp":2.32,"tv":2236.03,"id":10894176}]}]}
{"op":"mcm","clk":"1005537059","pt":1580643217024,"mc":[{"id":"1.168224441","rc":[{"batl":[[0,2.36,12.6],[1,2.72,8.65],[2,3.9,153.72]],"ltp":2.32,"tv":2236.03,"id":10894176},{"batb":[[1,1.67,74.23],[2,1.66,1.28]],"ltp":1.75,"tv":4254.72,"id":2263634}]}]}
{"op":"mcm","clk":"1005537193","pt":1580643217614,"mc":[{"id":"1.168224441","rc":[{"batb":[[1,1.72,7.57],[2,1.67,74.23]],"ltp":1.75,"tv":4254.72,"id":2263634}]}]}
{"op":"mcm","clk":"1005537735","pt":1580643220167,"mc":[{"id":"1.168224441","rc":[{"batb":[[1,1.71,7.57]],"ltp":1.75,"tv":4254.72,"id":2263634}]}]}
{"op":"mcm","clk":"1005538212","pt":1580643222643,"mc":[{"id":"1.168224441","rc":[{"batb":[[1,1.7,7.57]],"ltp":1.75,"tv":4254.72,"id":2263634}]}]}
{"op":"mcm","clk":"1005546430","pt":1580643265364,"mc":[{"id":"1.168224441","rc":[{"batb":[[2,1.66,1.28]],"ltp":1.75,"tv":4254.72,"id":2263634}]}]}
{"op":"mcm","clk":"1005546529","pt":1580643265888,"mc":[{"id":"1.168224441","rc":[{"trd":[[2.32,335.81]],"batb":[[0,2.32,3.7]],"ltp":2.32,"tv":2271.55,"id":10894176},{"batb":[[1,1.71,30.36],[2,1.7,7.57]],"ltp":1.75,"tv":4254.72,"id":2263634}],"tv":6526.27}]}
{"op":"mcm","clk":"1005546997","pt":1580643268398,"mc":[{"id":"1.168224441","rc":[{"batb":[[0,2.24,38.67]],"ltp":2.32,"tv":2271.55,"id":10894176},{"batb":[[1,1.71,42.47]],"ltp":1.75,"tv":4254.72,"id":2263634}]}]}
{"op":"mcm","clk":"1005548341","pt":1580643275292,"mc":[{"id":"1.168224441","rc":[{"batb":[[0,1.74,41.07],[1,1.72,8.56],[2,1.71,42.47]],"ltp":1.75,"tv":4254.72,"id":2263634}]}]}
{"op":"mcm","clk":"1005550247","pt":1580643285285,"mc":[{"id":"1.168224441","rc":[{"batb":[[0,1.74,14.36],[1,1.71,42.47],[2,1.7,7.57]],"ltp":1.75,"tv":4254.72,"id":2263634}]}]}
{"op":"mcm","clk":"1005550495","pt":1580643286526,"mc":[{"id":"1.168224441","rc":[{"trd":[[2.3,249.8],[2.32,337.07]],"ltp":2.3,"tv":2381.71,"id":10894176},{"trd":[[1.75,1063.87],[1.76,542.51]],"batl":[[0,1.76,2.21],[1,1.81,25.75],[2,1.86,21.85]],"ltp":1.76,"tv":4398.68,"id":2263634}],"tv":6780.4}]}
{"op":"mcm","clk":"1005552914","pt":1580643299298,"mc":[{"id":"1.168224441","rc":[{"batb":[[0,1.74,41.07]],"ltp":1.76,"tv":4398.68,"id":2263634}]}]}
{"op":"mcm","clk":"1005554975","pt":1580643309835,"mc":[{"id":"1.168224441","rc":[{"batb":[[0,1.74,58.11]],"ltp":1.76,"tv":4398.68,"id":2263634}]}]}
{"op":"mcm","clk":"1005555183","pt":1580643310958,"mc":[{"id":"1.168224441","rc":[{"batl":[[1,2.4,8.14],[2,2.72,8.65]],"ltp":2.3,"tv":2381.71,"id":10894176}]}]}
{"op":"mcm","clk":"1005555817","pt":1580643314260,"mc":[{"id":"1.168224441","rc":[{"batb":[[2,1.66,1.28]],"ltp":1.76,"tv":4398.68,"id":2263634}]}]}
{"op":"mcm","clk":"1005556152","pt":1580643315756,"mc":[{"id":"1.168224441","rc":[{"batb":[[0,1.75,7.57],[1,1.74,58.11],[2,1.71,42.47]],"ltp":1.76,"tv":4398.68,"id":2263634}]}]}
{"op":"mcm","clk":"1005556817","pt":1580643318935,"mc":[{"id":"1.168224441","rc":[{"batl":[[1,1.78,8.33],[2,1.81,24.99]],"ltp":1.76,"tv":4398.68,"id":2263634}]}]}
{"op":"mcm","clk":"1005556949","pt":1580643319668,"mc":[{"id":"1.168224441","rc":[{"batl":[[2,1.79,7.57]],"ltp":1.76,"tv":4398.68,"id":2263634}]}]}
{"op":"mcm","clk":"1005557213","pt":1580643321069,"mc":[{"id":"1.168224441","rc":[{"trd":[[1.75,1078.55]],"batb":[[0,1.74,58.34],[1,1.71,42.47],[2,1.66,1.28]],"ltp":1.75,"tv":4413.36,"id":2263634}],"tv":6795.08}]}
{"op":"mcm","clk":"1005557428","pt":1580643322081,"mc":[{"id":"1.168224441","rc":[{"trd":[[1.74,593.78],[1.75,1079.02]],"batb":[[0,1.71,42.56],[1,1.66,1.28],[2,1.62,190.53]],"ltp":1.74,"tv":4529.87,"id":2263634}],"tv":6911.58}]}
{"op":"mcm","clk":"1005557897","pt":1580643324264,"mc":[{"id":"1.168224441","rc":[{"batl":[[1,2.72,8.65],[2,3.9,153.72]],"ltp":2.3,"tv":2381.71,"id":10894176},{"batl":[[0,1.76,9.78]],"ltp":1.74,"tv":4529.87,"id":2263634}]}]}
{"op":"mcm","clk":"1005559176","pt":1580643330065,"mc":[{"id":"1.168224441","rc":[{"trd":[[1.74,608.74],[1.76,557.74]],"batb":[[0,1.71,42.65]],"batl":[[0,1.76,2.17]],"ltp":1.74,"tv":4560.07,"id":2263634}],"tv":6941.78}]}
{"op":"mcm","clk":"1005559636","pt":1580643332395,"mc":[{"id":"1.168224441","rc":[{"batl":[[0,1.76,440.26]],"ltp":1.74,"tv":4560.07,"id":2263634}]}]}
{"op":"mcm","clk":"1005560291","pt":1580643335388,"mc":[{"id":"1.168224441","rc":[{"batl":[[0,1.75,7.57],[1,1.76,9.74],[2,1.78,8.33]],"ltp":1.74,"tv":4560.07,"id":2263634}]}]}
{"op":"mcm","clk":"1005560875","pt":1580643338019,"mc":[{"id":"1.168224441","rc":[{"batb":[[0,1.74,7.75],[1,1.71,42.47],[2,1.66,1.28]],"ltp":1.74,"tv":4560.07,"id":2263634}]}]}
{"op":"mcm","clk":"1005561091","pt":1580643339188,"mc":[{"id":"1.168224441","rc":[{"trd":[[1.74,624.23]],"batb":[[0,1.71,42.47],[1,1.66,1.28],[2,1.62,190.53]],"ltp":1.74,"tv":4575.55,"id":2263634}],"tv":6957.27}]}
{"op":"mcm","clk":"1005561405","pt":1580643340804,"mc":[{"id":"1.168224441","rc":[{"batb":[[0,1.68,75.1]],"ltp":1.74,"tv":4575.55,"id":2263634}]}]}
{"op":"mcm","clk":"1005561931","pt":1580643343380,"mc":[{"id":"1.168224441","rc":[{"trd":[[2.26,10.12],[2.28,6.5],[2.3,257.25],[2.32,342.78]],"batb":[[0,2.28,273.65],[1,2.24,38.67],[2,2.04,44.68]],"ltp":2.26,"tv":2411.49,"id":10894176},{"trd":[[1.75,1086.59],[1.76,567.48],[1.78,8.33],[1.79,7.57]],"batl":[[0,1.81,24.99],[1,1.86,21.85],[2,2.2,89.35]],"ltp":1.79,"tv":4608.77,"id":2263634}],"tv":7020.26}]}
{"op":"mcm","clk":"1005562096","pt":1580643344177,"mc":[{"id":"1.168224441","rc":[{"batb":[[0,2.28,325.91]],"ltp":2.26,"tv":2411.49,"id":10894176}]}]}
{"op":"mcm","clk":"1005562341","pt":1580643345398,"mc":[{"id":"1.168224441","rc":[{"batb":[[0,2.3,322.98]],"ltp":2.26,"tv":2411.49,"id":10894176},{"trd":[[1.75,1101.27]],"batb":[[0,1.68,75.33],[1,1.62,190.53],[2,1.61,515.67]],"ltp":1.75,"tv":4623.44,"id":2263634}],"tv":7034.94}]}
{"op":"mcm","clk":"1005562567","pt":1580643346365,"mc":[{"id":"1.168224441","rc":[{"batb":[[0,2.24,38.67],[1,2.04,44.68],[2,2.02,115.81]],"ltp":2.26,"tv":2411.49,"id":10894176},{"trd":[[1.74,639.39],[1.75,1101.73]],"batb":[[0,1.74,7.56],[1,1.68,75.1],[2,1.62,190.53]],"ltp":1.74,"tv":4639.07,"id":2263634}],"tv":7050.57}]}
{"op":"mcm","clk":"1005562708","pt":1580643347103,"mc":[{"id":"1.168224441","rc":[{"trd":[[1.74,654.51]],"batb":[[0,1.68,75.1],[1,1.67,1.25]],"ltp":1.74,"tv":4654.19,"id":2263634}],"tv":7065.69}]}
{"op":"mcm","clk":"1005562937","pt":1580643348207,"mc":[{"id":"1.168224441","rc":[{"batl":[[0,1.79,7.57],[1,1.81,24.99],[2,1.86,21.85]],"ltp":1.74,"tv":4654.19,"id":2263634}]}]}
{"op":"mcm","clk":"1005563042","pt":1580643348752,"mc":[{"id":"1.168224441","rc":[{"batl":[[1,1.8,7.57],[2,1.81,24.99]],"ltp":1.74,"tv":4654.19,"id":2263634}]}]}
{"op":"mcm","clk":"1005563530","pt":1580643351205,"mc":[{"id":"1.168224441","rc":[{"trd":[[2.3,283.81]],"batl":[[0,2.36,12.76]],"ltp":2.3,"tv":2438.06,"id":10894176},{"batl":[[0,1.79,15.14]],"ltp":1.74,"tv":4654.19,"id":2263634}],"tv":7092.26}]}
{"op":"mcm","clk":"1005563925","pt":1580643353111,"mc":[{"id":"1.168224441","rc":[{"trd":[[2.3,283.97]],"batl":[[0,2.36,12.6]],"ltp":2.3,"tv":2438.22,"id":10894176},{"trd":[[1.74,669.05],[1.76,567.69]],"batb":[[0,1.68,75.4]],"ltp":1.74,"tv":4668.94,"id":2263634}],"tv":7107.16}]}
{"op":"mcm","clk":"1005564342","pt":1580643355306,"mc":[{"id":"1.168224441","rc":[{"batl":[[0,1.76,15.14],[1,1.79,15.14],[2,1.8,7.57]],"ltp":1.74,"tv":4668.94,"id":2263634}]}]}
{"op":"mcm","clk":"1005565492","pt":1580643361228,"mc":[{"id":"1.168224441","rc":[{"batb":[[0,1.74,7.88],[1,1.68,75.1],[2,1.67,1.25]],"ltp":1.74,"tv":4668.94,"id":2263634}]}]}
{"op":"mcm","clk":"1005565685","pt":1580643362101,"mc":[{"id":"1.168224441","rc":[{"trd":[[1.74,684.56],[1.76,593.11]],"batb":[[0,1.68,75.22],[1,1.67,1.25],[2,1.62,190.53]],"batl":[[0,1.76,2.43]],"ltp":1.74,"tv":4709.87,"id":2263634}],"tv":7148.09}]}
{"op":"mcm","clk":"1005567805","pt":1580643372214,"mc":[{"id":"1.168224441","rc":[{"batl":[[0,2.72,8.65],[1,3.9,153.72],[2,95,15.9]],"ltp":2.3,"tv":2438.22,"id":10894176}]}]}
{"op":"mcm","clk":"1005567995","pt":1580643373214,"mc":[{"id":"1.168224441","rc":[{"batb":[[0,1.73,11.63],[1,1.68,75.1],[2,1.67,1.25]],"batl":[[0,1.76,388.8]],"ltp":1.74,"tv":4709.87,"id":2263634}]}]}
{"op":"mcm","clk":"1005568172","pt":1580643374218,"mc":[{"id":"1.168224441","rc":[{"batl":[[0,1.76,328.1]],"ltp":1.74,"tv":4709.87,"id":2263634}]}]}
{"op":"mcm","clk":"1005568613","pt":1580643376241,"mc":[{"id":"1.168224441","rc":[{"batl":[[0,1.75,7.57],[1,1.76,328.1],[2,1.79,15.14]],"ltp":1.74,"tv":4709.87,"id":2263634}]}]}
{"op":"mcm","clk":"1005569798","pt":1580643382333,"mc":[{"id":"1.168224441","rc":[{"batb":[[0,1.74,7.69],[1,1.73,11.51],[2,1.68,75.1]],"batl":[[1,1.76,10.83]],"ltp":1.74,"tv":4709.87,"id":2263634}]}]}
{"op":"mcm","clk":"1005569859","pt":1580643382618,"mc":[{"id":"1.168224441","rc":[{"trd":[[1.74,699.52]],"batb":[[0,1.73,11.72],[1,1.68,75.1],[2,1.67,1.25]],"ltp":1.74,"tv":4724.83,"id":2263634}],"tv":7163.05}]}
{"op":"mcm","clk":"1005570514","pt":1580643386025,"mc":[{"id":"1.168224441","rc":[{"batl":[[1,1.76,18.4]],"ltp":1.74,"tv":4724.83,"id":2263634}]}]}
{"op":"mcm","clk":"1005571007","pt":1580643388517,"mc":[{"id":"1.168224441","rc":[{"batl":[[0,1.76,18.4],[1,1.79,15.14],[2,1.8,7.57]],"ltp":1.74,"tv":4724.83,"id":2263634}]}]}
{"op":"mcm","clk":"1005571304","pt":1580643390149,"mc":[{"id":"1.168224441","rc":[{"batl":[[0,1.76,390.42]],"ltp":1.74,"tv":4724.83,"id":2263634}]}]}
{"op":"mcm","clk":"1005571532","pt":1580643391434,"mc":[{"id":"1.168224441","rc":[{"trd":[[1.76,1167.12]],"batl":[[0,1.79,15.14],[1,1.8,7.57],[2,1.81,24.99]],"ltp":1.76,"tv":5298.84,"id":2263634}],"tv":7737.06}]}
{"op":"mcm","clk":"1005571666","pt":1580643392055,"mc":[{"id":"1.168224441","rc":[{"batl":[[0,1.76,131.27],[1,1.79,15.14],[2,1.8,7.57]],"ltp":1.76,"tv":5298.84,"id":2263634}]}]}
{"op":"mcm","clk":"1005571871","pt":1580643393025,"mc":[{"id":"1.168224441","rc":[{"batb":[[0,1.74,7.78],[1,1.73,11.51],[2,1.68,75.1]],"ltp":1.76,"tv":5298.84,"id":2263634}]}]}
{"op":"mcm","clk":"1005572612","pt":1580643396331,"mc":[{"id":"1.168224441","rc":[{"trd":[[1.74,715.02]],"batb":[[0,1.73,11.54],[1,1.68,75.1],[2,1.67,1.25]],"batl":[[0,1.79,15.14],[1,1.8,7.57],[2,1.81,24.99]],"ltp":1.74,"tv":5314.34,"id":2263634}],"tv":7752.56}]}
{"op":"mcm","clk":"1005573029","pt":1580643398350,"mc":[{"id":"1.168224441","rc":[{"batl":[[0,1.76,7.57],[1,1.79,15.14],[2,1.8,7.57]],"ltp":1.74,"tv":5314.34,"id":2263634}]}]}
{"op":"mcm","clk":"1005573078","pt":1580643398527,"mc":[{"id":"1.168224441","rc":[{"batl":[[0,1.76,15.14]],"ltp":1.74,"tv":5314.34,"id":2263634}]}]}
{"op":"mcm","clk":"1005574175","pt":1580643404153,"mc":[{"id":"1.168224441","rc":[{"batl":[[0,2.38,8.4],[1,2.72,8.65],[2,3.9,153.72]],"ltp":2.3,"tv":2438.22,"id":10894176},{"trd":[[1.75,1116.41]],"batb":[[0,1.73,11.78]],"ltp":1.75,"tv":5329.02,"id":2263634}],"tv":7767.24}]}
{"op":"mcm","clk":"1005574272","pt":1580643404631,"mc":[{"id":"1.168224441","rc":[{"batb":[[0,2.3,6.46],[1,2.24,38.67],[2,2.04,44.68]],"ltp":2.3,"tv":2438.22,"id":10894176},{"batl":[[0,1.76,23.55]],"ltp":1.75,"tv":5329.02,"id":2263634}]}]}
{"op":"mcm","clk":"1005574715","pt":1580643406848,"mc":[{"id":"1.168224441","rc":[{"batb":[[0,1.73,11.54]],"ltp":1.75,"tv":5329.02,"id":2263634}]}]}
{"op":"mcm","clk":"1005575022","pt":1580643408241,"mc":[{"id":"1.168224441","rc":[{"batl":[[0,1.76,144.82]],"ltp":1.75,"tv":5329.02,"id":2263634}]}]}
{"op":"mcm","clk":"1005575667","pt":1580643411165,"mc":[{"id":"1.168224441","rc":[{"batl":[[0,1.75,7.57],[1,1.76,144.82],[2,1.79,15.14]],"ltp":1.75,"tv":5329.02,"id":2263634}]}]}
{"op":"mcm","clk":"1005575716","pt":1580643411455,"mc":[{"id":"1.168224441","rc":[{"batl":[[1,1.76,23.55]],"ltp":1.75,"tv":5329.02,"id":2263634}]}]}
{"op":"mcm","clk":"1005578153","pt":1580643423877,"mc":[{"id":"1.168224441","rc":[{"batl":[[0,1.75,15.14]],"ltp":1.75,"tv":5329.02,"id":2263634}]}]}
{"op":"mcm","clk":"1005578438","pt":1580643425170,"mc":[{"id":"1.168224441","rc":[{"trd":[[1.75,1141.87]],"batl":[[0,1.75,2.42]],"ltp":1.75,"tv":5354.48,"id":2263634}],"tv":7792.7}]}
{"op":"mcm","clk":"1005578542","pt":1580643425704,"mc":[{"id":"1.168224441","rc":[{"batl":[[0,1.76,23.55],[1,1.79,15.14],[2,1.8,7.57]],"ltp":1.75,"tv":5354.48,"id":2263634}]}]}
{"op":"mcm","clk":"1005578884","pt":1580643427408,"mc":[{"id":"1.168224441","rc":[{"trd":[[1.74,730.23]],"batb":[[0,1.73,11.51]],"ltp":1.74,"tv":5369.68,"id":2263634}],"tv":7807.9}]}
{"op":"mcm","clk":"1005579642","pt":1580643431096,"mc":[{"id":"1.168224441","rc":[{"batl":[[0,1.75,7.57],[1,1.76,23.55],[2,1.79,15.14]],"ltp":1.74,"tv":5369.68,"id":2263634}]}]}
{"op":"mcm","clk":"1005580797","pt":1580643436209,"mc":[{"id":"1.168224441","rc":[{"batb":[[0,2.24,38.67],[1,2.04,44.68],[2,2.02,115.81]],"ltp":2.3,"tv":2438.22,"id":10894176},{"batl":[[1,1.76,15.14]],"ltp":1.74,"tv":5369.68,"id":2263634}]}]}
{"op":"mcm","clk":"1005580942","pt":1580643436885,"mc":[{"id":"1.168224441","rc":[{"batb":[[0,2.32,6.37],[1,2.24,38.67],[2,2.04,44.68]],"ltp":2.3,"tv":2438.22,"id":10894176},{"batl":[[0,1.75,15.97],[1,1.79,15.14],[2,1.8,7.57]],"ltp":1.74,"tv":5369.68,"id":2263634}]}]}
{"op":"mcm","clk":"1005584402","pt":1580643454254,"mc":[{"id":"1.168224441","rc":[{"trd":[[1.75,1180.93]],"batl":[[0,1.75,4.01]],"ltp":1.75,"tv":5408.74,"id":2263634}],"tv":7846.97}]}
{"op":"mcm","clk":"1005587303","pt":1580643468480,"mc":[{"id":"1.168224441","rc":[{"batb":[[0,2.24,38.67],[1,2.04,44.68],[2,2.02,115.81]],"ltp":2.3,"tv":2438.22,"id":10894176}]}]}
{"op":"mcm","clk":"1005589358","pt":1580643478691,"mc":[{"id":"1.168224441","rc":[{"trd":[[1.74,745.19]],"batb":[[0,1.73,11.6]],"ltp":1.74,"tv":5423.7,"id":2263634}],"tv":7861.93}]}
{"op":"mcm","clk":"1005590081","pt":1580643482320,"mc":[{"id":"1.168224441","rc":[{"batl":[[0,1.75,11.59]],"ltp":1.74,"tv":5423.7,"id":2263634}]}]}
{"op":"mcm","clk":"1005590279","pt":1580643483281,"mc":[{"id":"1.168224441","rc":[{"trd":[[1.75,1199.61]],"batb":[[0,1.74,7.66],[1,1.73,11.51],[2,1.68,75.1]],"batl":[[0,1.75,2.24]],"ltp":1.75,"tv":5442.39,"id":2263634}],"tv":7880.61}]}
{"op":"mcm","clk":"1005590367","pt":1580643483710,"mc":[{"id":"1.168224441","rc":[{"trd":[[1.74,760.15]],"batb":[[0,1.73,11.69],[1,1.68,75.1],[2,1.67,1.25]],"ltp":1.74,"tv":5457.35,"id":2263634}],"tv":7895.57}]}
{"op":"mcm","clk":"1005590875","pt":1580643486016,"mc":[{"id":"1.168224441","rc":[{"batb":[[0,1.74,7.75],[1,1.73,11.51],[2,1.68,75.1]],"ltp":1.74,"tv":5457.35,"id":2263634}]}]}
{"op":"mcm","clk":"1005591024","pt":1580643486719,"mc":[{"id":"1.168224441","rc":[{"trd":[[1.74,775.65]],"batb":[[0,1.73,11.51],[1,1.68,75.1],[2,1.67,1.25]],"ltp":1.74,"tv":5472.85,"id":2263634}],"tv":7911.08}]}
{"op":"mcm","clk":"1005591334","pt":1580643488227,"mc":[{"id":"1.168224441","rc":[{"batl":[[0,1.75,9.81]],"ltp":1.74,"tv":5472.85,"id":2263634}]}]}
{"op":"mcm","clk":"1005592114","pt":1580643491704,"mc":[{"id":"1.168224441","rc":[{"batl":[[0,1.79,15.14],[1,1.8,7.57],[2,1.81,24.99]],"ltp":1.74,"tv":5472.85,"id":2263634}]}]}
{"op":"mcm","clk":"1005592362","pt":1580643492785,"mc":[{"id":"1.168224441","rc":[{"batl":[[0,1.77,7.57],[1,1.79,15.14],[2,1.8,7.57]],"ltp":1.74,"tv":5472.85,"id":2263634}]}]}
{"op":"mcm","clk":"1005593113","pt":1580643496333,"mc":[{"id":"1.168224441","rc":[{"batl":[[0,1.76,7.57],[1,1.77,7.57],[2,1.79,15.14]],"ltp":1.74,"tv":5472.85,"id":2263634}]}]}
{"op":"mcm","clk":"1005593549","pt":1580643498328,"mc":[{"id":"1.168224441","rc":[{"batl":[[0,1.76,108.34]],"ltp":1.74,"tv":5472.85,"id":2263634}]}]}
{"op":"mcm","clk":"1005593797","pt":1580643499415,"mc":[{"id":"1.168224441","rc":[{"batl":[[0,1.76,7.57]],"ltp":1.74,"tv":5472.85,"id":2263634}]}]}
{"op":"mcm","clk":"1005593943","pt":1580643500116,"mc":[{"id":"1.168224441","rc":[{"batl":[[0,1.76,108.34]],"ltp":1.74,"tv":5472.85,"id":2263634}]}]}
{"op":"mcm","clk":"1005594253","pt":1580643501426,"mc":[{"id":"1.168224441","rc":[{"batl":[[0,1.76,7.57]],"ltp":1.74,"tv":5472.85,"id":2263634}]}]}
{"op":"mcm","clk":"1005594671","pt":1580643503248,"mc":[{"id":"1.168224441","rc":[{"batl":[[0,1.76,108.34]],"ltp":1.74,"tv":5472.85,"id":2263634}]}]}
{"op":"mcm","clk":"1005594955","pt":1580643504429,"mc":[{"id":"1.168224441","rc":[{"batl":[[0,1.76,7.57]],"ltp":1.74,"tv":5472.85,"id":2263634}]}]}
{"op":"mcm","clk":"1005594990","pt":1580643504639,"mc":[{"id":"1.168224441","rc":[{"batl":[[0,1.76,108.34]],"ltp":1.74,"tv":5472.85,"id":2263634}]}]}
{"op":"mcm","clk":"1005595398","pt":1580643506427,"mc":[{"id":"1.168224441","rc":[{"batl":[[0,1.76,7.57]],"ltp":1.74,"tv":5472.85,"id":2263634}]}]}
{"op":"mcm","clk":"1005595527","pt":1580643506902,"mc":[{"id":"1.168224441","rc":[{"batl":[[0,1.76,108.34]],"ltp":1.74,"tv":5472.85,"id":2263634}]}]}
{"op":"mcm","clk":"1005597763","pt":1580643517331,"mc":[{"id":"1.168224441","rc":[{"trd":[[1.76,1350.8]],"batl":[[0,1.76,16.5],[1,1.79,15.14],[2,1.8,7.57]],"ltp":1.76,"tv":5656.54,"id":2263634}],"tv":8094.76}]}
{"op":"mcm","clk":"1005597935","pt":1580643518029,"mc":[{"id":"1.168224441","rc":[{"batl":[[0,1.78,43.43]],"ltp":1.76,"tv":5656.54,"id":2263634}]}]}
{"op":"mcm","clk":"1005598193","pt":1580643519259,"mc":[{"id":"1.168224441","rc":[{"batb":[[0,1.74,7.57],[1,1.73,11.51],[2,1.68,75.1]],"ltp":1.76,"tv":5656.54,"id":2263634}]}]}
{"op":"mcm","clk":"1005598353","pt":1580643519966,"mc":[{"id":"1.168224441","rc":[{"trd":[[1.74,790.61]],"batb":[[0,1.73,11.6],[1,1.68,75.1],[2,1.67,1.25]],"batl":[[0,1.79,15.14],[1,1.8,7.57],[2,1.81,24.99]],"ltp":1.74,"tv":5671.5,"id":2263634}],"tv":8109.72}]}
{"op":"mcm","clk":"1005598572","pt":1580643521051,"mc":[{"id":"1.168224441","rc":[{"batl":[[0,1.76,7.57],[1,1.79,15.14],[2,1.8,7.57]],"ltp":1.74,"tv":5671.5,"id":2263634}]}]}
{"op":"mcm","clk":"1005599177","pt":1580643523773,"mc":[{"id":"1.168224441","rc":[{"batl":[[0,1.78,7.57]],"ltp":1.74,"tv":5671.5,"id":2263634}]}]}
{"op":"mcm","clk":"1005599560","pt":1580643525475,"mc":[{"id":"1.168224441","rc":[{"batl":[[0,1.78,15.14]],"ltp":1.74,"tv":5671.5,"id":2263634}]}]}
{"op":"mcm","clk":"1005600467","pt":1580643529353,"mc":[{"id":"1.168224441","rc":[{"batl":[[0,1.78,22.72]],"ltp":1.74,"tv":5671.5,"id":2263634}]}]}
{"op":"mcm","clk":"1005601101","pt":1580643532394,"mc":[{"id":"1.168224441","rc":[{"batl":[[0,1.76,7.57],[1,1.77,46.02],[2,1.78,22.72]],"ltp":1.74,"tv":5671.5,"id":2263634}]}]}
{"op":"mcm","clk":"1005601305","pt":1580643533246,"mc":[{"id":"1.168224441","rc":[{"batl":[[1,1.78,22.72],[2,1.79,15.14]],"ltp":1.74,"tv":5671.5,"id":2263634}]}]}
{"op":"mcm","clk":"1005601472","pt":1580643533969,"mc":[{"id":"1.168224441","rc":[{"batl":[[0,1.76,46.59]],"ltp":1.74,"tv":5671.5,"id":2263634}]}]}
{"op":"mcm","clk":"1005601759","pt":1580643535251,"mc":[{"id":"1.168224441","rc":[{"batl":[[0,1.76,7.57],[1,1.79,15.14],[2,1.8,7.57]],"ltp":1.74,"tv":5671.5,"id":2263634}]}]}
{"op":"mcm","clk":"1005601986","pt":1580643536267,"mc":[{"id":"1.168224441","rc":[{"batl":[[1,1.8,7.57],[2,1.81,24.99]],"ltp":1.74,"tv":5671.5,"id":2263634}]}]}
{"op":"mcm","clk":"1005602170","pt":1580643537286,"mc":[{"id":"1.168224441","rc":[{"batl":[[1,1.81,24.99],[2,1.86,21.85]],"ltp":1.74,"tv":5671.5,"id":2263634}]}]}
{"op":"mcm","clk":"1005602392","pt":1580643538353,"mc":[{"id":"1.168224441","rc":[{"batl":[[1,1.78,7.57],[2,1.81,24.99]],"ltp":1.74,"tv":5671.5,"id":2263634}]}]}
{"op":"mcm","clk":"1005602773","pt":1580643540168,"mc":[{"id":"1.168224441","rc":[{"batl":[[0,1.76,46.59]],"ltp":1.74,"tv":5671.5,"id":2263634}]}]}
{"op":"mcm","clk":"1005602970","pt":1580643541299,"mc":[{"id":"1.168224441","rc":[{"batl":[[0,1.76,7.57]],"ltp":1.74,"tv":5671.5,"id":2263634}]}]}
{"op":"mcm","clk":"1005603198","pt":1580643542267,"mc":[{"id":"1.168224441","rc":[{"batl":[[0,1.76,46.59]],"ltp":1.74,"tv":5671.5,"id":2263634}]}]}
{"op":"mcm","clk":"1005607418","pt":1580643562309,"mc":[{"id":"1.168224441","rc":[{"batl":[[0,1.76,15.84]],"ltp":1.74,"tv":5671.5,"id":2263634}]}]}
{"op":"mcm","clk":"1005607464","pt":1580643562520,"mc":[{"id":"1.168224441","rc":[{"trd":[[1.76,1362.7]],"batl":[[0,1.76,9.89]],"ltp":1.76,"tv":5683.4,"id":2263634}],"tv":8121.62}]}
{"op":"mcm","clk":"1005608181","pt":1580643566096,"mc":[{"id":"1.168224441","rc":[{"trd":[[1.74,805.58]],"batb":[[0,1.73,11.69]],"ltp":1.74,"tv":5698.36,"id":2263634}],"tv":8136.58}]}
{"op":"mcm","clk":"1005608554","pt":1580643568123,"mc":[{"id":"1.168224441","rc":[{"batl":[[0,1.76,17.46]],"ltp":1.74,"tv":5698.36,"id":2263634}]}]}
{"op":"mcm","clk":"1005608782","pt":1580643569022,"mc":[{"id":"1.168224441","rc":[{"batl":[[0,1.76,25.04]],"ltp":1.74,"tv":5698.36,"id":2263634}]}]}
{"op":"mcm","clk":"1005615013","pt":1580643599042,"mc":[{"id":"1.168224441","rc":[{"batl":[[0,1.75,7.57],[1,1.76,25.04],[2,1.78,7.57]],"ltp":1.74,"tv":5698.36,"id":2263634}]}]}
{"op":"mcm","clk":"1005615123","pt":1580643599565,"mc":[{"id":"1.168224441","rc":[{"trd":[[1.75,1211.53]],"batl":[[0,1.75,1.61]],"ltp":1.75,"tv":5710.28,"id":2263634}],"tv":8148.5}]}
{"op":"mcm","clk":"1005615659","pt":1580643602167,"mc":[{"id":"1.168224441","rc":[{"batb":[[0,1.74,7.75],[1,1.73,11.51],[2,1.68,75.1]],"ltp":1.75,"tv":5710.28,"id":2263634}]}]}
{"op":"mcm","clk":"1005616433","pt":1580643605789,"mc":[{"id":"1.168224441","rc":[{"batl":[[0,1.76,25.04],[1,1.78,7.57],[2,1.81,24.99]],"ltp":1.75,"tv":5710.28,"id":2263634}]}]}
{"op":"mcm","clk":"1005616675","pt":1580643607071,"mc":[{"id":"1.168224441","rc":[{"batl":[[0,1.76,8.27]],"ltp":1.75,"tv":5710.28,"id":2263634}]}]}
{"op":"mcm","clk":"1005617476","pt":1580643611094,"mc":[{"id":"1.168224441","rc":[{"batb":[[0,1.73,11.51],[1,1.68,75.1],[2,1.67,1.25]],"batl":[[1,1.81,24.99],[2,1.86,21.85]],"ltp":1.75,"tv":5710.28,"id":2263634}]}]}
{"op":"mcm","clk":"1005617707","pt":1580643612265,"mc":[{"id":"1.168224441","rc":[{"batb":[[0,1.74,6.89],[1,1.73,11.51],[2,1.68,75.1]],"ltp":1.75,"tv":5710.28,"id":2263634}]}]}
{"op":"mcm","clk":"1005617802","pt":1580643612784,"mc":[{"id":"1.168224441","rc":[{"trd":[[1.74,815.54]],"batb":[[0,1.74,1.91]],"batl":[[0,1.81,24.99],[1,1.86,21.85],[2,2.2,89.35]],"ltp":1.74,"tv":5720.24,"id":2263634}],"tv":8158.47}]}
{"op":"mcm","clk":"1005618254","pt":1580643615175,"mc":[{"id":"1.168224441","rc":[{"batl":[[0,1.79,15.14],[1,1.81,24.99],[2,1.86,21.85]],"ltp":1.74,"tv":5720.24,"id":2263634}]}]}
{"op":"mcm","clk":"1005618968","pt":1580643618866,"mc":[{"id":"1.168224441","rc":[{"batl":[[0,1.76,7.57],[1,1.79,15.14],[2,1.81,24.99]],"ltp":1.74,"tv":5720.24,"id":2263634}]}]}
{"op":"mcm","clk":"1005619382","pt":1580643620895,"mc":[{"id":"1.168224441","rc":[{"batb":[[2,2,37.86]],"ltp":2.3,"tv":2438.22,"id":10894176}]}]}
{"op":"mcm","clk":"1005619503","pt":1580643621484,"mc":[{"id":"1.168224441","rc":[{"batb":[[1,2.1,107.39],[2,2.04,44.68]],"ltp":2.3,"tv":2438.22,"id":10894176}]}]}
{"op":"mcm","clk":"1005619845","pt":1580643623180,"mc":[{"id":"1.168224441","rc":[{"batb":[[0,1.74,18.94],[1,1.68,75.1],[2,1.67,1.25]],"ltp":1.74,"tv":5720.24,"id":2263634}]}]}
{"op":"mcm","clk":"1005620581","pt":1580643626971,"mc":[{"id":"1.168224441","rc":[{"batl":[[0,1.76,418.34]],"ltp":1.74,"tv":5720.24,"id":2263634}]}]}
{"op":"mcm","clk":"1005625816","pt":1580643654238,"mc":[{"id":"1.168224441","rc":[{"batl":[[0,2.72,8.65],[1,3.9,153.72],[2,95,15.9]],"ltp":2.3,"tv":2438.22,"id":10894176}]}]}
{"op":"mcm","clk":"1005626003","pt":1580643655149,"mc":[{"id":"1.168224441","rc":[{"batl":[[0,2.36,12.6],[1,2.72,8.65],[2,3.9,153.72]],"ltp":2.3,"tv":2438.22,"id":10894176},{"trd":[[1.74,853.03],[1.76,1377.85]],"batb":[[0,1.68,75.29],[1,1.67,1.25],[2,1.61,515.67]],"batl":[[0,1.76,398.02]],"ltp":1.76,"tv":5772.88,"id":2263634}],"tv":8211.1}]}
{"op":"mcm","clk":"1005626907","pt":1580643659754,"mc":[{"id":"1.168224441","rc":[{"batl":[[1,1.81,24.99],[2,1.86,21.85]],"ltp":1.76,"tv":5772.88,"id":2263634}]}]}
{"op":"mcm","clk":"1005627389","pt":1580643662239,"mc":[{"id":"1.168224441","rc":[{"batb":[[1,2.12,105.47]],"ltp":2.3,"tv":2438.22,"id":10894176},{"batb":[[0,1.74,2.1],[1,1.68,75.1],[2,1.67,1.25]],"ltp":1.76,"tv":5772.88,"id":2263634}]}]}
{"op":"mcm","clk":"1005627460","pt":1580643662616,"mc":[{"id":"1.168224441","rc":[{"trd":[[1.74,857.22]],"batb":[[0,1.68,75.1],[1,1.67,1.25],[2,1.61,515.67]],"batl":[[0,1.81,24.99],[1,1.86,21.85],[2,2.2,89.35]],"ltp":1.74,"tv":5777.07,"id":2263634}],"tv":8215.29}]}
{"op":"mcm","clk":"1005627989","pt":1580643665038,"mc":[{"id":"1.168224441","rc":[{"batl":[[0,1.76,7.57],[1,1.81,24.99],[2,1.86,21.85]],"ltp":1.74,"tv":5777.07,"id":2263634}]}]}
{"op":"mcm","clk":"1005628378","pt":1580643666756,"mc":[{"id":"1.168224441","rc":[{"batl":[[0,1.76,15.14]],"ltp":1.74,"tv":5777.07,"id":2263634}]}]}
{"op":"mcm","clk":"1005628700","pt":1580643668360,"mc":[{"id":"1.168224441","rc":[{"batl":[[1,1.79,15.14],[2,1.81,24.99]],"ltp":1.74,"tv":5777.07,"id":2263634}]}]}
{"op":"mcm","clk":"1005630570","pt":1580643677984,"mc":[{"id":"1.168224441","rc":[{"batl":[[0,1.76,494.49]],"ltp":1.74,"tv":5777.07,"id":2263634}]}]}
{"op":"mcm","clk":"1005630810","pt":1580643679160,"mc":[{"id":"1.168224441","rc":[{"batl":[[0,1.76,419.24]],"ltp":1.74,"tv":5777.07,"id":2263634}]}]}
{"op":"mcm","clk":"1005631038","pt":1580643680393,"mc":[{"id":"1.168224441","rc":[{"batl":[[0,1.76,22.72]],"ltp":1.74,"tv":5777.07,"id":2263634}]}]}
{"op":"mcm","clk":"1005631176","pt":1580643681042,"mc":[{"id":"1.168224441","rc":[{"batl":[[0,1.76,494.49]],"ltp":1.74,"tv":5777.07,"id":2263634}]}]}
{"op":"mcm","clk":"1005631362","pt":1580643682054,"mc":[{"id":"1.168224441","rc":[{"batl":[[0,1.76,419.24]],"ltp":1.74,"tv":5777.07,"id":2263634}]}]}
{"op":"mcm","clk":"1005631800","pt":1580643684364,"mc":[{"id":"1.168224441","rc":[{"trd":[[1.76,2039.85]],"batl":[[0,1.76,282.52]],"ltp":1.76,"tv":6439.07,"id":2263634}],"tv":8877.29}]}
{"op":"mcm","clk":"1005632221","pt":1580643686361,"mc":[{"id":"1.168224441","rc":[{"batb":[[0,1.73,11.52],[1,1.68,75.1],[2,1.67,1.25]],"batl":[[0,1.75,8.4],[1,1.76,282.52],[2,1.79,15.14]],"ltp":1.76,"tv":6439.07,"id":2263634}]}]}
{"op":"mcm","clk":"1005632838","pt":1580643689276,"mc":[{"id":"1.168224441","rc":[{"batb":[[0,1.74,7.58],[1,1.73,11.51],[2,1.68,75.1]],"ltp":1.76,"tv":6439.07,"id":2263634}]}]}
{"op":"mcm","clk":"1005633611","pt":1580643693386,"mc":[{"id":"1.168224441","rc":[{"batb":[[0,1.74,15.15]],"ltp":1.76,"tv":6439.07,"id":2263634}]}]}
{"op":"mcm","clk":"1005634627","pt":1580643698522,"mc":[{"id":"1.168224441","rc":[{"batb":[[0,1.73,11.51],[1,1.68,75.1],[2,1.67,1.25]],"batl":[[2,1.81,24.99]],"ltp":1.76,"tv":6439.07,"id":2263634}]}]}
{"op":"mcm","clk":"1005634949","pt":1580643700236,"mc":[{"id":"1.168224441","rc":[{"batb":[[0,1.74,28.74],[1,1.73,11.51],[2,1.68,75.1]],"batl":[[2,1.79,7.57]],"ltp":1.76,"tv":6439.07,"id":2263634}]}]}
{"op":"mcm","clk":"1005638453","pt":1580643717119,"mc":[{"id":"1.168224441","rc":[{"batl":[[0,2.72,8.65],[1,3.9,153.72],[2,95,15.9]],"ltp":2.3,"tv":2438.22,"id":10894176}]}]}
{"op":"mcm","clk":"1005638605","pt":1580643717829,"mc":[{"id":"1.168224441","rc":[{"trd":[[1.75,1225.18]],"batb":[[1,1.68,75.1],[2,1.67,1.25]],"batl":[[0,1.75,1.58]],"ltp":1.75,"tv":6452.71,"id":2263634}],"tv":8890.94}]}
{"op":"mcm","clk":"1005639302","pt":1580643721039,"mc":[{"id":"1.168224441","rc":[{"batb":[[0,1.68,75.1],[1,1.67,1.25],[2,1.61,515.67]],"ltp":1.75,"tv":6452.71,"id":2263634}]}]}
{"op":"mcm","clk":"1005639684","pt":1580643722928,"mc":[{"id":"1.168224441","rc":[{"batb":[[0,1.68,82.67]],"ltp":1.75,"tv":6452.71,"id":2263634}]}]}
{"op":"mcm","clk":"1005639991","pt":1580643724436,"mc":[{"id":"1.168224441","rc":[{"batb":[[0,1.71,7.57],[1,1.7,7.57],[2,1.68,82.67]],"ltp":1.75,"tv":6452.71,"id":2263634}]}]}
{"op":"mcm","clk":"1005640011","pt":1580643724538,"mc":[{"id":"1.168224441","rc":[{"batb":[[2,1.69,8.71]],"ltp":1.75,"tv":6452.71,"id":2263634}]}]}
{"op":"mcm","clk":"1005641651","pt":1580643732759,"mc":[{"id":"1.168224441","rc":[{"batb":[[0,1.72,32.09],[1,1.71,7.57],[2,1.7,7.57]],"ltp":1.75,"tv":6452.71,"id":2263634}]}]}
{"op":"mcm","clk":"1005641944","pt":1580643734374,"mc":[{"id":"1.168224441","rc":[{"batb":[[0,1.73,7.57],[1,1.72,32.09],[2,1.71,7.57]],"ltp":1.75,"tv":6452.71,"id":2263634}]}]}
{"op":"mcm","clk":"1005642313","pt":1580643736334,"mc":[{"id":"1.168224441","rc":[{"trd":[[1.74,872.18]],"batb":[[0,1.73,7.66]],"batl":[[1,1.79,7.57],[2,1.81,24.99]],"ltp":1.74,"tv":6467.68,"id":2263634}],"tv":8905.9}]}
{"op":"mcm","clk":"1005642913","pt":1580643739335,"mc":[{"id":"1.168224441","rc":[{"trd":[[1.74,887.14]],"batb":[[0,1.73,7.75]],"ltp":1.74,"tv":6482.64,"id":2263634}],"tv":8920.86}]}
{"op":"mcm","clk":"1005643062","pt":1580643740076,"mc":[{"id":"1.168224441","rc":[{"batb":[[2,1.7,7.57]],"ltp":1.74,"tv":6482.64,"id":2263634}]}]}
{"op":"mcm","clk":"1005643354","pt":1580643741534,"mc":[{"id":"1.168224441","rc":[{"batb":[[2,1.68,7.57]],"ltp":1.74,"tv":6482.64,"id":2263634}]}]}
{"op":"mcm","clk":"1005643850","pt":1580643744377,"mc":[{"id":"1.168224441","rc":[{"trd":[[1.74,902.64]],"batb":[[0,1.73,7.57]],"ltp":1.74,"tv":6498.14,"id":2263634}],"tv":8936.36}]}
{"op":"mcm","clk":"1005644884","pt":1580643749436,"mc":[{"id":"1.168224441","rc":[{"batb":[[0,1.72,32.09],[1,1.67,1.25],[2,1.61,515.67]],"batl":[[0,1.75,7.57],[1,1.81,24.99],[2,1.86,21.85]],"ltp":1.74,"tv":6498.14,"id":2263634}]}]}
{"op":"mcm","clk":"1005645059","pt":1580643750371,"mc":[{"id":"1.168224441","rc":[{"trd":[[1.74,945.14]],"batb":[[0,1.72,32.09]],"ltp":1.74,"tv":6540.64,"id":2263634}],"tv":8978.86}]}
{"op":"mcm","clk":"1005645388","pt":1580643751963,"mc":[{"id":"1.168224441","rc":[{"batl":[[0,1.81,24.99],[1,1.86,21.85],[2,2.2,89.35]],"ltp":1.74,"tv":6540.64,"id":2263634}]}]}
{"op":"mcm","clk":"1005645589","pt":1580643752979,"mc":[{"id":"1.168224441","rc":[{"batb":[[0,2.3,145.18],[1,2.24,38.67],[2,2.12,105.47]],"ltp":2.3,"tv":2438.22,"id":10894176},{"batl":[[0,1.76,15.14],[1,1.81,24.99],[2,1.86,21.85]],"ltp":1.74,"tv":6540.64,"id":2263634}]}]}
{"op":"mcm","clk":"1005645882","pt":1580643754368,"mc":[{"id":"1.168224441","rc":[{"batb":[[0,2.24,38.67],[1,2.12,105.47],[2,2.04,44.68]],"ltp":2.3,"tv":2438.22,"id":10894176},{"batl":[[1,1.79,22.72],[2,1.81,24.99]],"ltp":1.74,"tv":6540.64,"id":2263634}]}]}
{"op":"mcm","clk":"1005646151","pt":1580643755551,"mc":[{"id":"1.168224441","rc":[{"batl":[[0,1.76,174.66]],"ltp":1.74,"tv":6540.64,"id":2263634}]}]}
{"op":"mcm","clk":"1005646491","pt":1580643757176,"mc":[{"id":"1.168224441","rc":[{"batl":[[0,1.76,182.24]],"ltp":1.74,"tv":6540.64,"id":2263634}]}]}
{"op":"mcm","clk":"1005646736","pt":1580643758430,"mc":[{"id":"1.168224441","rc":[{"batl":[[0,1.76,22.72]],"ltp":1.74,"tv":6540.64,"id":2263634}]}]}
{"op":"mcm","clk":"1005646973","pt":1580643759486,"mc":[{"id":"1.168224441","rc":[{"batl":[[0,1.76,182.24]],"ltp":1.74,"tv":6540.64,"id":2263634}]}]}
{"op":"mcm","clk":"1005648110","pt":1580643765275,"mc":[{"id":"1.168224441","rc":[{"batl":[[0,1.75,7.57],[1,1.76,182.24],[2,1.79,22.72]],"ltp":1.74,"tv":6540.64,"id":2263634}]}]}
{"op":"mcm","clk":"1005649555","pt":1580643773020,"mc":[{"id":"1.168224441","rc":[{"batl":[[1,1.79,22.72],[2,1.81,24.99]],"ltp":1.74,"tv":6540.64,"id":2263634}]}]}
{"op":"mcm","clk":"1005650670","pt":1580643778909,"mc":[{"id":"1.168224441","rc":[{"trd":[[1.75,1250.8]],"batl":[[0,1.75,2.33]],"ltp":1.75,"tv":6566.26,"id":2263634}],"tv":9004.48}]}
{"op":"mcm","clk":"1005650959","pt":1580643780298,"mc":[{"id":"1.168224441","rc":[{"batl":[[0,2.4,8.4],[1,2.72,8.65],[2,3.9,153.72]],"ltp":2.3,"tv":2438.22,"id":10894176},{"batb":[[0,1.72,43.76]],"batl":[[0,1.75,10.73]],"ltp":1.75,"tv":6566.26,"id":2263634}]}]}
{"op":"mcm","clk":"1005650993","pt":1580643780517,"mc":[{"id":"1.168224441","rc":[{"batb":[[0,2.32,6.37],[1,2.24,38.67],[2,2.12,105.47]],"ltp":2.3,"tv":2438.22,"id":10894176}]}]}
{"op":"mcm","clk":"1005651390","pt":1580643782480,"mc":[{"id":"1.168224441","rc":[{"batl":[[0,1.75,18.31]],"ltp":1.75,"tv":6566.26,"id":2263634}]}]}
{"op":"mcm","clk":"1005656890","pt":1580643810832,"mc":[{"id":"1.168224441","rc":[{"batl":[[0,1.75,25.88]],"ltp":1.75,"tv":6566.26,"id":2263634}]}]}
{"op":"mcm","clk":"1005657110","pt":1580643812052,"mc":[{"id":"1.168224441","rc":[{"trd":[[1.75,1293.57]],"batl":[[0,1.75,4.49]],"ltp":1.75,"tv":6609.03,"id":2263634}],"tv":9047.25}]}
{"op":"mcm","clk":"1005657658","pt":1580643815131,"mc":[{"id":"1.168224441","rc":[{"trd":[[1.74,960.1]],"batb":[[0,1.72,43.86]],"ltp":1.74,"tv":6623.98,"id":2263634}],"tv":9062.21}]}
{"op":"mcm","clk":"1005658065","pt":1580643817218,"mc":[{"id":"1.168224441","rc":[{"batl":[[0,1.75,12.06]],"ltp":1.74,"tv":6623.98,"id":2263634}]}]}
{"op":"mcm","clk":"1005659741","pt":1580643826257,"mc":[{"id":"1.168224441","rc":[{"batl":[[0,1.75,19.64]],"ltp":1.74,"tv":6623.98,"id":2263634}]}]}
{"op":"mcm","clk":"1005660826","pt":1580643832089,"mc":[{"id":"1.168224441","rc":[{"batl":[[0,1.75,34.78]],"ltp":1.74,"tv":6623.98,"id":2263634}]}]}
{"op":"mcm","clk":"1005661193","pt":1580643834121,"mc":[{"id":"1.168224441","rc":[{"batl":[[0,1.75,7.57]],"ltp":1.74,"tv":6623.98,"id":2263634}]}]}
{"op":"mcm","clk":"1005661387","pt":1580643835202,"mc":[{"id":"1.168224441","rc":[{"batl":[[1,1.76,7.57],[2,1.79,22.72]],"ltp":1.74,"tv":6623.98,"id":2263634}]}]}
{"op":"mcm","clk":"1005661700","pt":1580643836713,"mc":[{"id":"1.168224441","rc":[{"batl":[[0,1.76,7.57],[1,1.79,22.72],[2,1.81,24.99]],"ltp":1.74,"tv":6623.98,"id":2263634}]}]}
{"op":"mcm","clk":"1005662032","pt":1580643838548,"mc":[{"id":"1.168224441","rc":[{"batb":[[0,1.72,43.76]],"batl":[[0,1.81,24.99],[1,1.86,21.85],[2,2.2,89.35]],"ltp":1.74,"tv":6623.98,"id":2263634}]}]}
{"op":"mcm","clk":"1005662337","pt":1580643840107,"mc":[{"id":"1.168224441","rc":[{"trd":[[2.32,353.05]],"batb":[[0,2.32,1.24]],"ltp":2.32,"tv":2448.48,"id":10894176},{"trd":[[1.74,966.6]],"batl":[[0,1.76,7.57],[1,1.81,24.99],[2,1.86,21.85]],"ltp":1.74,"tv":6630.48,"id":2263634}],"tv":9078.97}]}
{"op":"mcm","clk":"1005662563","pt":1580643841314,"mc":[{"id":"1.168224441","rc":[{"batl":[[0,1.75,7.57],[1,1.76,193.34],[2,1.81,24.99]],"ltp":1.74,"tv":6630.48,"id":2263634}]}]}
{"op":"mcm","clk":"1005662752","pt":1580643842396,"mc":[{"id":"1.168224441","rc":[{"batl":[[0,1.75,15.14]],"ltp":1.74,"tv":6630.48,"id":2263634}]}]}
{"op":"mcm","clk":"1005662797","pt":1580643842614,"mc":[{"id":"1.168224441","rc":[{"batl":[[1,1.76,7.57]],"ltp":1.74,"tv":6630.48,"id":2263634}]}]}
{"op":"mcm","clk":"1005662929","pt":1580643843460,"mc":[{"id":"1.168224441","rc":[{"batb":[[0,2.24,38.67],[1,2.12,105.47],[2,2.04,44.68]],"ltp":2.32,"tv":2448.48,"id":10894176}]}]}
{"op":"mcm","clk":"1005664214","pt":1580643850667,"mc":[{"id":"1.168224441","rc":[{"batl":[[0,1.75,22.72]],"ltp":1.74,"tv":6630.48,"id":2263634}]}]}
{"op":"mcm","clk":"1005666151","pt":1580643861586,"mc":[{"id":"1.168224441","rc":[{"batl":[[0,1.74,42.01],[1,1.75,22.72],[2,1.76,7.57]],"ltp":1.74,"tv":6630.48,"id":2263634}]}]}
{"op":"mcm","clk":"1005666327","pt":1580643862696,"mc":[{"id":"1.168224441","rc":[{"trd":[[1.74,990.59]],"batb":[[0,1.72,31.71]],"batl":[[0,1.74,30.01]],"ltp":1.74,"tv":6654.48,"id":2263634}],"tv":9102.96}]}
{"op":"mcm","clk":"1005666699","pt":1580643864891,"mc":[{"id":"1.168224441","rc":[{"batb":[[0,2.24,47.79]],"ltp":2.32,"tv":2448.48,"id":10894176},{"batb":[[0,1.72,11.67],[1,1.68,62.91],[2,1.67,1.25]],"ltp":1.74,"tv":6654.48,"id":2263634}]}]}
{"op":"mcm","clk":"1005667141","pt":1580643867416,"mc":[{"id":"1.168224441","rc":[{"batl":[[1,1.81,24.99],[2,1.86,21.85]],"ltp":1.74,"tv":6654.48,"id":2263634}]}]}
{"op":"mcm","clk":"1005667786","pt":1580643871108,"mc":[{"id":"1.168224441","rc":[{"batb":[[1,2.04,44.68],[2,2,37.86]],"ltp":2.32,"tv":2448.48,"id":10894176},{"trd":[[1.74,1041.95]],"batl":[[0,1.74,4.34],[1,1.79,7.57],[2,1.81,24.99]],"ltp":1.74,"tv":6705.83,"id":2263634}],"tv":9154.32}]}
{"op":"mcm","clk":"1005667995","pt":1580643872166,"mc":[{"id":"1.168224441","rc":[{"batb":[[1,2.12,105.47],[2,2.04,44.68]],"ltp":2.32,"tv":2448.48,"id":10894176},{"batl":[[0,1.79,7.57],[1,1.81,24.99],[2,1.86,21.85]],"ltp":1.74,"tv":6705.83,"id":2263634}]}]}
{"op":"mcm","clk":"1005668423","pt":1580643874617,"mc":[{"id":"1.168224441","rc":[{"batl":[[0,1.75,7.57],[1,1.79,7.57],[2,1.81,24.99]],"ltp":1.74,"tv":6705.83,"id":2263634}]}]}
{"op":"mcm","clk":"1005670425","pt":1580643885812,"mc":[{"id":"1.168224441","rc":[{"batl":[[0,1.75,15.14]],"ltp":1.74,"tv":6705.83,"id":2263634}]}]}
{"op":"mcm","clk":"1005670806","pt":1580643888129,"mc":[{"id":"1.168224441","rc":[{"batb":[[0,1.73,42.01],[1,1.72,11.67],[2,1.68,62.91]],"ltp":1.74,"tv":6705.83,"id":2263634}]}]}
{"op":"mcm","clk":"1005671173","pt":1580643890020,"mc":[{"id":"1.168224441","rc":[{"batl":[[0,1.79,7.57],[1,1.81,24.99],[2,1.86,21.85]],"ltp":1.74,"tv":6705.83,"id":2263634}]}]}
{"op":"mcm","clk":"1005671453","pt":1580643891526,"mc":[{"id":"1.168224441","rc":[{"batl":[[0,1.79,15.14]],"ltp":1.74,"tv":6705.83,"id":2263634}]}]}
{"op":"mcm","clk":"1005674364","pt":1580643906264,"mc":[{"id":"1.168224441","rc":[{"batl":[[0,2.38,12.6]],"ltp":2.32,"tv":2448.48,"id":10894176},{"batb":[[1,1.68,62.91],[2,1.67,1.25]],"batl":[[0,1.78,183.75],[1,1.79,15.14],[2,1.81,24.99]],"ltp":1.74,"tv":6705.83,"id":2263634}]}]}
{"op":"mcm","clk":"1005674566","pt":1580643907335,"mc":[{"id":"1.168224441","rc":[{"batb":[[0,1.73,59.28]],"batl":[[0,1.79,15.14],[1,1.81,24.99],[2,1.86,21.85]],"ltp":1.74,"tv":6705.83,"id":2263634}]}]}
{"op":"mcm","clk":"1005674709","pt":1580643908180,"mc":[{"id":"1.168224441","rc":[{"batl":[[0,1.78,154.25],[1,1.79,15.14],[2,1.81,24.99]],"ltp":1.74,"tv":6705.83,"id":2263634}]}]}
{"op":"mcm","clk":"1005675321","pt":1580643911051,"mc":[{"id":"1.168224441","rc":[{"batl":[[0,1.78,183.75]],"ltp":1.74,"tv":6705.83,"id":2263634}]}]}
{"op":"mcm","clk":"1005675531","pt":1580643911949,"mc":[{"id":"1.168224441","rc":[{"batl":[[0,1.78,154.25]],"ltp":1.74,"tv":6705.83,"id":2263634}]}]}
{"op":"mcm","clk":"1005675694","pt":1580643912865,"mc":[{"id":"1.168224441","rc":[{"batl":[[0,1.79,15.14],[1,1.81,24.99],[2,1.86,21.85]],"ltp":1.74,"tv":6705.83,"id":2263634}]}]}
{"op":"mcm","clk":"1005676558","pt":1580643917361,"mc":[{"id":"1.168224441","rc":[{"batl":[[0,1.78,183.75],[1,1.79,15.14],[2,1.81,24.99]],"ltp":1.74,"tv":6705.83,"id":2263634}]}]}
{"op":"mcm","clk":"1005676705","pt":1580643918073,"mc":[{"id":"1.168224441","rc":[{"batl":[[0,1.78,154.25]],"ltp":1.74,"tv":6705.83,"id":2263634}]}]}
{"op":"mcm","clk":"1005677535","pt":1580643922374,"mc":[{"id":"1.168224441","rc":[{"batl":[[0,1.76,7.57]],"ltp":1.74,"tv":6705.83,"id":2263634}]}]}
{"op":"mcm","clk":"1005677685","pt":1580643923072,"mc":[{"id":"1.168224441","rc":[{"batl":[[1,1.78,154.25],[2,1.79,15.14]],"ltp":1.74,"tv":6705.83,"id":2263634}]}]}
{"op":"mcm","clk":"1005678027","pt":1580643925063,"mc":[{"id":"1.168224441","rc":[{"batl":[[1,1.78,183.75]],"ltp":1.74,"tv":6705.83,"id":2263634}]}]}
{"op":"mcm","clk":"1005678249","pt":1580643926281,"mc":[{"id":"1.168224441","rc":[{"batl":[[1,1.78,154.25]],"ltp":1.74,"tv":6705.83,"id":2263634}]}]}
{"op":"mcm","clk":"1005678762","pt":1580643928956,"mc":[{"id":"1.168224441","rc":[{"batl":[[1,1.78,183.75]],"ltp":1.74,"tv":6705.83,"id":2263634}]}]}
{"op":"mcm","clk":"1005678953","pt":1580643929971,"mc":[{"id":"1.168224441","rc":[{"batl":[[1,1.78,154.25]],"ltp":1.74,"tv":6705.83,"id":2263634}]}]}
{"op":"mcm","clk":"1005679148","pt":1580643930992,"mc":[{"id":"1.168224441","rc":[{"batl":[[1,1.78,183.75]],"ltp":1.74,"tv":6705.83,"id":2263634}]}]}
{"op":"mcm","clk":"1005679244","pt":1580643931582,"mc":[{"id":"1.168224441","rc":[{"batl":[[1,1.78,154.25]],"ltp":1.74,"tv":6705.83,"id":2263634}]}]}
{"op":"mcm","clk":"1005680360","pt":1580643937419,"mc":[{"id":"1.168224441","rc":[{"trd":[[1.76,2051.85]],"batl":[[0,1.76,1.58],[1,1.79,15.14],[2,1.81,24.99]],"ltp":1.76,"tv":6717.83,"id":2263634}],"tv":9166.32}]}
{"op":"mcm","clk":"1005680499","pt":1580643938076,"mc":[{"id":"1.168224441","rc":[{"batl":[[1,1.78,183.75],[2,1.79,15.14]],"ltp":1.76,"tv":6717.83,"id":2263634}]}]}
{"op":"mcm","clk":"1005680714","pt":1580643939298,"mc":[{"id":"1.168224441","rc":[{"batl":[[1,1.78,154.25]],"ltp":1.76,"tv":6717.83,"id":2263634}]}]}
{"op":"mcm","clk":"1005680875","pt":1580643940106,"mc":[{"id":"1.168224441","rc":[{"batl":[[1,1.78,183.75]],"ltp":1.76,"tv":6717.83,"id":2263634}]}]}
{"op":"mcm","clk":"1005681044","pt":1580643941083,"mc":[{"id":"1.168224441","rc":[{"batl":[[1,1.78,154.25]],"ltp":1.76,"tv":6717.83,"id":2263634}]}]}
{"op":"mcm","clk":"1005681244","pt":1580643942199,"mc":[{"id":"1.168224441","rc":[{"batl":[[1,1.78,183.75]],"ltp":1.76,"tv":6717.83,"id":2263634}]}]}
{"op":"mcm","clk":"1005681434","pt":1580643943211,"mc":[{"id":"1.168224441","rc":[{"batl":[[1,1.78,154.25]],"ltp":1.76,"tv":6717.83,"id":2263634}]}]}
{"op":"mcm","clk":"1005681579","pt":1580643944083,"mc":[{"id":"1.168224441","rc":[{"batl":[[1,1.78,183.75]],"ltp":1.76,"tv":6717.83,"id":2263634}]}]}
{"op":"mcm","clk":"1005681747","pt":1580643945087,"mc":[{"id":"1.168224441","rc":[{"batl":[[1,1.78,154.25]],"ltp":1.76,"tv":6717.83,"id":2263634}]}]}
{"op":"mcm","clk":"1005682001","pt":1580643946421,"mc":[{"id":"1.168224441","rc":[{"batl":[[1,1.79,15.14],[2,1.81,24.99]],"ltp":1.76,"tv":6717.83,"id":2263634}]}]}
{"op":"mcm","clk":"1005682021","pt":1580643946523,"mc":[{"id":"1.168224441","rc":[{"batl":[[1,1.78,154.25],[2,1.79,15.14]],"ltp":1.76,"tv":6717.83,"id":2263634}]}]}
{"op":"mcm","clk":"1005685667","pt":1580643966124,"mc":[{"id":"1.168224441","rc":[{"batl":[[1,1.78,150.67]],"ltp":1.76,"tv":6717.83,"id":2263634}]}]}
{"op":"mcm","clk":"1005685865","pt":1580643967195,"mc":[{"id":"1.168224441","rc":[{"batl":[[1,1.78,179.25]],"ltp":1.76,"tv":6717.83,"id":2263634}]}]}
{"op":"mcm","clk":"1005686054","pt":1580643968327,"mc":[{"id":"1.168224441","rc":[{"batl":[[1,1.79,15.14],[2,1.81,24.99]],"ltp":1.76,"tv":6717.83,"id":2263634}]}]}
{"op":"mcm","clk":"1005686221","pt":1580643969134,"mc":[{"id":"1.168224441","rc":[{"batl":[[1,1.78,150.67],[2,1.79,15.14]],"ltp":1.76,"tv":6717.83,"id":2263634}]}]}
{"op":"mcm","clk":"1005686432","pt":1580643970247,"mc":[{"id":"1.168224441","rc":[{"batl":[[1,1.78,179.25]],"ltp":1.76,"tv":6717.83,"id":2263634}]}]}
{"op":"mcm","clk":"1005686593","pt":1580643971212,"mc":[{"id":"1.168224441","rc":[{"batl":[[1,1.78,150.67]],"ltp":1.76,"tv":6717.83,"id":2263634}]}]}
{"op":"mcm","clk":"1005686985","pt":1580643973340,"mc":[{"id":"1.168224441","rc":[{"batl":[[1,1.79,15.14],[2,1.81,24.99]],"ltp":1.76,"tv":6717.83,"id":2263634}]}]}
{"op":"mcm","clk":"1005687272","pt":1580643975019,"mc":[{"id":"1.168224441","rc":[{"batl":[[1,1.78,150.67],[2,1.79,15.14]],"ltp":1.76,"tv":6717.83,"id":2263634}]}]}
{"op":"mcm","clk":"1005687988","pt":1580643979346,"mc":[{"id":"1.168224441","rc":[{"batl":[[0,2.36,16.75],[1,2.38,12.6],[2,2.72,8.65]],"ltp":2.32,"tv":2448.48,"id":10894176},{"batb":[[0,1.74,18.46],[1,1.73,207.99],[2,1.68,62.91]],"batl":[[0,1.76,182.85],[1,1.77,145.35]],"ltp":1.76,"tv":6717.83,"id":2263634}]}]}
{"op":"mcm","clk":"1005688109","pt":1580643980033,"mc":[{"id":"1.168224441","rc":[{"trd":[[1.74,1078.45]],"batb":[[0,1.73,208.2],[1,1.68,62.91],[2,1.67,1.25]],"batl":[[0,1.76,1.58]],"ltp":1.74,"tv":6754.33,"id":2263634}],"tv":9202.82}]}
{"op":"mcm","clk":"1005688395","pt":1580643981321,"mc":[{"id":"1.168224441","rc":[{"batb":[[0,1.73,207.99]],"batl":[[0,1.76,152.51]],"ltp":1.74,"tv":6754.33,"id":2263634}]}]}
{"op":"mcm","clk":"1005688538","pt":1580643982246,"mc":[{"id":"1.168224441","rc":[{"batl":[[0,1.76,179.01]],"ltp":1.74,"tv":6754.33,"id":2263634}]}]}
{"op":"mcm","clk":"1005688686","pt":1580643983126,"mc":[{"id":"1.168224441","rc":[{"batl":[[0,1.75,12.34],[1,1.76,12.49],[2,1.77,145.35]],"ltp":1.74,"tv":6754.33,"id":2263634}]}]}
{"op":"mcm","clk":"1005688865","pt":1580643984236,"mc":[{"id":"1.168224441","rc":[{"batl":[[0,1.76,12.49],[1,1.77,145.35],[2,1.79,15.14]],"ltp":1.74,"tv":6754.33,"id":2263634}]}]}
{"op":"mcm","clk":"1005690669","pt":1580643995241,"mc":[{"id":"1.168224441","rc":[{"batl":[[0,1.76,179.01]],"ltp":1.74,"tv":6754.33,"id":2263634}]}]}
{"op":"mcm","clk":"1005690850","pt":1580643996362,"mc":[{"id":"1.168224441","rc":[{"trd":[[1.76,2359.07]],"batl":[[0,1.76,25.4]],"ltp":1.76,"tv":7061.55,"id":2263634}],"tv":9510.04}]}
{"op":"mcm","clk":"1005690996","pt":1580643997247,"mc":[{"id":"1.168224441","rc":[{"batl":[[0,1.77,145.35],[1,1.79,15.14],[2,1.81,24.99]],"ltp":1.76,"tv":7061.55,"id":2263634}]}]}
{"op":"mcm","clk":"1005691184","pt":1580643998254,"mc":[{"id":"1.168224441","rc":[{"batb":[[0,2.32,12.7]],"ltp":2.32,"tv":2448.48,"id":10894176}]}]}
{"op":"mcm","clk":"1005691382","pt":1580643999361,"mc":[{"id":"1.168224441","rc":[{"trd":[[2.32,378.44]],"batb":[[0,2.12,105.47],[1,2.04,44.68],[2,2,37.86]],"ltp":2.32,"tv":2473.88,"id":10894176},{"batl":[[0,1.76,68.77],[1,1.77,145.35],[2,1.79,15.14]],"ltp":1.76,"tv":7061.55,"id":2263634}],"tv":9535.43}]}
{"op":"mcm","clk":"1005691561","pt":1580644000373,"mc":[{"id":"1.168224441","rc":[{"batl":[[0,2.36,29.36],[1,2.72,8.65],[2,3.9,153.72]],"ltp":2.32,"tv":2473.88,"id":10894176},{"batl":[[0,1.76,81.77]],"ltp":1.76,"tv":7061.55,"id":2263634}]}]}
{"op":"mcm","clk":"1005691663","pt":1580644001069,"mc":[{"id":"1.168224441","rc":[{"batb":[[0,2.24,34.91],[1,2.12,105.47],[2,2.04,44.68]],"ltp":2.32,"tv":2473.88,"id":10894176},{"trd":[[1.74,1111.95]],"batb":[[0,1.73,208.14],[1,1.67,1.25],[2,1.61,515.67]],"batl":[[0,1.77,145.35],[1,1.79,15.14],[2,1.81,24.99]],"ltp":1.74,"tv":7095.05,"id":2263634}],"tv":9568.94}]}
{"op":"mcm","clk":"1005691836","pt":1580644002061,"mc":[{"id":"1.168224441","rc":[{"batb":[[0,2.32,12.56]],"ltp":2.32,"tv":2473.88,"id":10894176},{"batb":[[0,1.73,207.99],[1,1.68,63.09],[2,1.67,1.25]],"ltp":1.74,"tv":7095.05,"id":2263634}]}]}
{"op":"mcm","clk":"1005709634","pt":1580644117410,"mc":[{"id":"1.168224441","rc":[{"batb":[[0,2.32,15.77],[1,2.3,3.24],[2,2.12,105.47]],"batl":[[0,2.36,32.52],[1,2.38,3.13],[2,2.72,8.65]],"ltp":2.32,"tv":2473.88,"id":10894176},{"batb":[[0,1.74,4.83],[1,1.73,212.85],[2,1.68,63.09]],"batl":[[0,1.76,4.77],[1,1.77,150.1],[2,1.79,15.14]],"ltp":1.74,"tv":7095.05,"id":2263634}]}]}
{"op":"mcm","clk":"1005709761","pt":1580644118198,"mc":[{"id":"1.168224441","rc":[{"trd":[[1.74,1121.45]],"batb":[[0,1.73,212.93],[1,1.68,63.09],[2,1.67,1.25]],"ltp":1.74,"tv":7104.55,"id":2263634}],"tv":9578.43}]}
{"op":"mcm","clk":"1005709913","pt":1580644119297,"mc":[{"id":"1.168224441","rc":[{"trd":[[2.32,404.24]],"batb":[[0,2.32,2.87],[2,2.24,34.92]],"ltp":2.32,"tv":2499.67,"id":10894176},{"batb":[[0,1.74,16.9],[1,1.73,212.85],[2,1.72,4.88]],"ltp":1.74,"tv":7104.55,"id":2263634}],"tv":9604.23}]}
{"op":"mcm","clk":"1005710036","pt":1580644120194,"mc":[{"id":"1.168224441","rc":[{"trd":[[1.74,1154.95]],"batb":[[0,1.73,213],[1,1.72,4.88],[2,1.67,1.25]],"ltp":1.74,"tv":7138.05,"id":2263634}],"tv":9637.73}]}
{"op":"mcm","clk":"1005710193","pt":1580644121284,"mc":[{"id":"1.168224441","rc":[{"batb":[[1,2.3,24.21],[2,2.12,105.47]],"ltp":2.32,"tv":2499.67,"id":10894176},{"batb":[[0,1.73,212.85],[2,1.68,63.08]],"batl":[[0,1.75,15.14],[1,1.76,4.77],[2,1.77,150.1]],"ltp":1.74,"tv":7138.05,"id":2263634}]}]}
{"op":"mcm","clk":"1005710297","pt":1580644122015,"mc":[{"id":"1.168224441","rc":[{"batl":[[0,1.75,19.4]],"ltp":1.74,"tv":7138.05,"id":2263634}]}]}
{"op":"mcm","clk":"1005710722","pt":1580644125214,"mc":[{"id":"1.168224441","rc":[{"trd":[[1.74,1176.91]],"batb":[[0,1.73,213.1]],"ltp":1.74,"tv":7160.02,"id":2263634}],"tv":9659.69}]}
{"op":"mcm","clk":"1005710966","pt":1580644127002,"mc":[{"id":"1.168224441","rc":[{"batb":[[0,1.73,212.85]],"batl":[[0,1.75,26.98],[1,1.76,15.01]],"ltp":1.74,"tv":7160.02,"id":2263634}]}]}
{"op":"mcm","clk":"1005711059","pt":1580644127698,"mc":[{"id":"1.168224441","rc":[{"batl":[[0,1.75,34.55]],"ltp":1.74,"tv":7160.02,"id":2263634}]}]}
{"op":"mcm","clk":"1005712048","pt":1580644135047,"mc":[{"id":"1.168224441","rc":[{"batl":[[0,1.75,4.26]],"ltp":1.74,"tv":7160.02,"id":2263634}]}]}
{"op":"mcm","clk":"1005712140","pt":1580644135614,"mc":[{"id":"1.168224441","rc":[{"batl":[[0,1.75,11.83]],"ltp":1.74,"tv":7160.02,"id":2263634}]}]}
{"op":"mcm","clk":"1005712309","pt":1580644137023,"mc":[{"id":"1.168224441","rc":[{"batl":[[0,1.75,19.4]],"ltp":1.74,"tv":7160.02,"id":2263634}]}]}
{"op":"mcm","clk":"1005715762","pt":1580644162761,"mc":[{"id":"1.168224441","rc":[{"batl":[[0,1.75,26.98]],"ltp":1.74,"tv":7160.02,"id":2263634}]}]}
{"op":"mcm","clk":"1005715998","pt":1580644164338,"mc":[{"id":"1.168224441","rc":[{"trd":[[1.75,1338.34]],"batb":[[0,1.74,15.24],[1,1.73,212.85],[2,1.72,4.88]],"batl":[[0,1.75,4.59]],"ltp":1.75,"tv":7204.78,"id":2263634}],"tv":9704.46}]}
{"op":"mcm","clk":"1005716085","pt":1580644164975,"mc":[{"id":"1.168224441","rc":[{"batb":[[0,1.74,19.52]],"ltp":1.75,"tv":7204.78,"id":2263634}]}]}
{"op":"mcm","clk":"1005716197","pt":1580644165860,"mc":[{"id":"1.168224441","rc":[{"batb":[[0,1.74,22.52]],"ltp":1.75,"tv":7204.78,"id":2263634}]}]}
{"op":"mcm","clk":"1005716326","pt":1580644166855,"mc":[{"id":"1.168224441","rc":[{"batl":[[0,1.76,15.01],[1,1.77,150.1],[2,1.79,15.14]],"ltp":1.75,"tv":7204.78,"id":2263634}]}]}
{"op":"mcm","clk":"1005716523","pt":1580644168271,"mc":[{"id":"1.168224441","rc":[{"batl":[[0,2.34,3.19],[1,2.36,32.52],[2,2.38,3.13]],"ltp":2.32,"tv":2499.67,"id":10894176}]}]}
{"op":"mcm","clk":"1005718701","pt":1580644185369,"mc":[{"id":"1.168224441","rc":[{"batl":[[1,2.36,19.91]],"ltp":2.32,"tv":2499.67,"id":10894176}]}]}
{"op":"mcm","clk":"1005718802","pt":1580644186194,"mc":[{"id":"1.168224441","rc":[{"batb":[[0,1.74,39.55],[1,1.73,195.58]],"ltp":1.75,"tv":7204.78,"id":2263634}]}]}
{"op":"mcm","clk":"1005731003","pt":1580644270781,"mc":[{"id":"1.168224441","rc":[{"batl":[[0,1.76,23.46]],"ltp":1.75,"tv":7204.78,"id":2263634}]}]}
{"op":"mcm","clk":"1005731126","pt":1580644271885,"mc":[{"id":"1.168224441","rc":[{"trd":[[1.76,2398.74]],"batl":[[0,1.76,3.62]],"ltp":1.76,"tv":7244.45,"id":2263634}],"tv":9744.13}]}
{"op":"mcm","clk":"1005731312","pt":1580644273288,"mc":[{"id":"1.168224441","rc":[{"batb":[[0,2.3,24.21],[1,2.28,3.28]],"ltp":2.32,"tv":2499.67,"id":10894176},{"trd":[[1.75,1346.37]],"batb":[[0,1.74,39.8]],"batl":[[2,1.78,4.2]],"ltp":1.75,"tv":7252.49,"id":2263634}],"tv":9752.17}]}
{"op":"mcm","clk":"1005731447","pt":1580644274286,"mc":[{"id":"1.168224441","rc":[{"trd":[[2.34,270.38]],"batb":[[0,2.32,3.22],[1,2.3,24.21],[2,2.28,3.28]],"batl":[[0,2.36,19.91],[1,2.38,3.13],[2,2.72,8.65]],"ltp":2.34,"tv":2506.06,"id":10894176},{"trd":[[1.74,1199.41]],"batb":[[0,1.74,39.81]],"batl":[[0,1.76,7.86]],"ltp":1.74,"tv":7274.98,"id":2263634}],"tv":9781.04}]}
{"op":"mcm","clk":"1005732110","pt":1580644279110,"mc":[{"id":"1.168224441","rc":[{"batl":[[0,2.36,32.52]],"ltp":2.34,"tv":2506.06,"id":10894176}]}]}
{"op":"mcm","clk":"1005738037","pt":1580644321020,"mc":[{"id":"1.168224441","rc":[{"batb":[[1,2.3,33.62]],"batl":[[0,2.36,40.97]],"ltp":2.34,"tv":2506.06,"id":10894176},{"batb":[[0,1.74,49.07]],"batl":[[0,1.76,16.32]],"ltp":1.74,"tv":7274.98,"id":2263634}]}]}
{"op":"mcm","clk":"1005738184","pt":1580644321921,"mc":[{"id":"1.168224441","rc":[{"trd":[[1.76,2426.36]],"batl":[[0,1.76,2.5]],"ltp":1.76,"tv":7302.6,"id":2263634}],"tv":9808.67}]}
{"op":"mcm","clk":"1005738334","pt":1580644323032,"mc":[{"id":"1.168224441","rc":[{"batb":[[0,2.3,33.62],[1,2.28,3.28],[2,2.12,105.47]],"batl":[[0,2.34,3.19],[1,2.36,40.97],[2,2.38,3.13]],"ltp":2.34,"tv":2506.06,"id":10894176},{"batb":[[0,1.75,4.28],[1,1.74,49.07],[2,1.73,195.58]],"ltp":1.76,"tv":7302.6,"id":2263634}]}]}
{"op":"mcm","clk":"1005738857","pt":1580644326930,"mc":[{"id":"1.168224441","rc":[{"batb":[[1,1.74,42.09]],"ltp":1.76,"tv":7302.6,"id":2263634}]}]}
{"op":"mcm","clk":"1005738999","pt":1580644328024,"mc":[{"id":"1.168224441","rc":[{"batb":[[0,1.75,18.84]],"ltp":1.76,"tv":7302.6,"id":2263634}]}]}
{"op":"mcm","clk":"1005740661","pt":1580644341171,"mc":[{"id":"1.168224441","rc":[{"batl":[[1,2.36,28.36]],"ltp":2.34,"tv":2506.06,"id":10894176}]}]}
{"op":"mcm","clk":"1005740786","pt":1580644341951,"mc":[{"id":"1.168224441","rc":[{"batl":[[0,2.34,15.8]],"ltp":2.34,"tv":2506.06,"id":10894176},{"batb":[[1,1.74,25.05]],"ltp":1.76,"tv":7302.6,"id":2263634}]}]}
{"op":"mcm","clk":"1005747209","pt":1580644392156,"mc":[{"id":"1.168224441","rc":[{"trd":[[2.28,6.72],[2.3,338.88]],"batb":[[0,2.28,3.17],[1,2.12,105.47],[2,2.04,44.68]],"ltp":2.28,"tv":2561.18,"id":10894176},{"trd":[[1.75,1365.3],[1.76,2428.86]],"batb":[[0,1.75,9.37]],"batl":[[0,1.77,150.1],[1,1.78,4.2],[2,1.81,24.99]],"ltp":1.76,"tv":7324.03,"id":2263634}],"tv":9885.21}]}
{"op":"mcm","clk":"1005747339","pt":1580644393259,"mc":[{"id":"1.168224441","rc":[{"trd":[[2.32,410.7]],"batb":[[0,2.3,3.25],[1,2.28,3.17],[2,2.24,26.46]],"ltp":2.32,"tv":2567.63,"id":10894176},{"batb":[[0,1.75,31.77]],"ltp":1.76,"tv":7324.03,"id":2263634}],"tv":9891.67}]}
{"op":"mcm","clk":"1005750422","pt":1580644417193,"mc":[{"id":"1.168224441","rc":[{"batb":[[1,1.74,35.93]],"ltp":1.76,"tv":7324.03,"id":2263634}]}]}
{"op":"mcm","clk":"1005751877","pt":1580644428394,"mc":[{"id":"1.168224441","rc":[{"batl":[[2,1.81,2.27]],"ltp":1.76,"tv":7324.03,"id":2263634}]}]}
{"op":"mcm","clk":"1005751982","pt":1580644429077,"mc":[{"id":"1.168224441","rc":[{"trd":[[1.77,178]],"batl":[[0,1.77,61.1]],"ltp":1.77,"tv":7502.03,"id":2263634}],"tv":10069.67}]}
{"op":"mcm","clk":"1005752702","pt":1580644434619,"mc":[{"id":"1.168224441","rc":[{"batb":[[0,1.75,48.58]],"ltp":1.77,"tv":7502.03,"id":2263634}]}]}
{"op":"mcm","clk":"1005754130","pt":1580644446813,"mc":[{"id":"1.168224441","rc":[{"batl":[[2,1.81,40.13]],"ltp":1.77,"tv":7502.03,"id":2263634}]}]}
{"op":"mcm","clk":"1005754350","pt":1580644448442,"mc":[{"id":"1.168224441","rc":[{"batl":[[0,2.32,3.23],[1,2.34,15.8],[2,2.36,28.36]],"ltp":2.32,"tv":2567.63,"id":10894176}]}]}
{"op":"mcm","clk":"1005755734","pt":1580644458425,"mc":[{"id":"1.168224441","rc":[{"batl":[[0,2.34,15.8],[1,2.36,28.36],[2,2.38,3.13]],"ltp":2.32,"tv":2567.63,"id":10894176}]}]}
{"op":"mcm","clk":"1005837941","pt":1580645034179,"mc":[{"id":"1.168224441","rc":[{"trd":[[2.3,357.14]],"batb":[[0,2.28,3.17],[1,2.24,26.46],[2,2.16,44.68]],"batl":[[0,2.3,6.01],[1,2.34,15.8],[2,2.36,28.36]],"ltp":2.3,"tv":2585.9,"id":10894176}],"tv":10087.94}]}
{"op":"mcm","clk":"1005838147","pt":1580645035092,"mc":[{"id":"1.168224441","rc":[{"batb":[[1,2.26,3.34],[2,2.24,26.46]],"batl":[[1,2.32,3.24],[2,2.34,15.8]],"ltp":2.3,"tv":2585.9,"id":10894176},{"batb":[[0,1.76,4.28],[1,1.75,48.58],[2,1.74,35.93]],"batl":[[0,1.77,56.35],[2,1.79,4.21]],"ltp":1.77,"tv":7502.03,"id":2263634}]}]}
{"op":"mcm","clk":"1005841566","pt":1580645053293,"mc":[{"id":"1.168224441","rc":[{"batl":[[2,2.34,3.19]],"ltp":2.3,"tv":2585.9,"id":10894176},{"batb":[[1,1.75,31.77]],"ltp":1.77,"tv":7502.03,"id":2263634}]}]}
{"op":"mcm","clk":"1005841616","pt":1580645053613,"mc":[{"id":"1.168224441","rc":[{"batl":[[0,2.3,18.82]],"ltp":2.3,"tv":2585.9,"id":10894176}]}]}
{"op":"mcm","clk":"1005842231","pt":1580645056703,"mc":[{"id":"1.168224441","rc":[{"trd":[[2.28,15.9]],"batb":[[0,2.26,3.34],[1,2.24,26.46],[2,2.16,44.68]],"batl":[[0,2.3,12.8]],"ltp":2.28,"tv":2595.08,"id":10894176},{"trd":[[1.77,181.67]],"batl":[[0,1.77,52.68]],"ltp":1.77,"tv":7505.71,"id":2263634}],"tv":10100.79}]}
{"op":"mcm","clk":"1005842448","pt":1580645057919,"mc":[{"id":"1.168224441","rc":[{"batb":[[1,2.24,29.82]],"ltp":2.28,"tv":2595.08,"id":10894176}]}]}
{"op":"mcm","clk":"1005908831","pt":1580645396678,"mc":[{"id":"1.168224441","rc":[{"trd":[[2.3,369.94]],"batl":[[0,2.32,3.24],[1,2.34,3.19],[2,2.36,28.36]],"ltp":2.3,"tv":2607.88,"id":10894176},{"trd":[[1.76,2454.15]],"batb":[[0,1.75,31.77],[1,1.74,35.93],[2,1.73,195.58]],"batl":[[0,1.76,3.78],[1,1.77,52.68],[2,1.78,4.2]],"ltp":1.76,"tv":7530.99,"id":2263634}],"tv":10138.88}]}
{"op":"mcm","clk":"1005909022","pt":1580645397789,"mc":[{"id":"1.168224441","rc":[{"batl":[[0,2.34,3.19],[1,2.36,28.36],[2,2.38,3.13]],"ltp":2.3,"tv":2607.88,"id":10894176},{"batl":[[1,1.77,56.95]],"ltp":1.76,"tv":7530.99,"id":2263634}]}]}
{"op":"mcm","clk":"1005909585","pt":1580645400896,"mc":[{"id":"1.168224441","rc":[{"batl":[[1,2.36,37.3]],"ltp":2.3,"tv":2607.88,"id":10894176},{"batb":[[1,1.74,44.86]],"ltp":1.76,"tv":7530.99,"id":2263634}]}]}
{"op":"mcm","clk":"1005919234","pt":1580645454074,"mc":[{"id":"1.168224441","rc":[{"batb":[[0,2.3,6.46],[1,2.26,3.34],[2,2.24,29.82]],"batl":[[0,2.34,11.59]],"ltp":2.3,"tv":2607.88,"id":10894176}]}]}
{"op":"mcm","clk":"1005919380","pt":1580645454875,"mc":[{"id":"1.168224441","rc":[{"batb":[[0,2.3,9.75],[1,2.28,3.32],[2,2.26,3.34]],"ltp":2.3,"tv":2607.88,"id":10894176}]}]}
{"op":"mcm","clk":"1005922046","pt":1580645468993,"mc":[{"id":"1.168224441","rc":[{"trd":[[1.76,2461.71]],"batb":[[0,1.75,13.65],[1,1.74,68.95]],"batl":[[0,1.77,56.95],[1,1.78,4.2],[2,1.79,4.21]],"ltp":1.76,"tv":7538.55,"id":2263634}],"tv":10146.44}]}
{"op":"mcm","clk":"1005925043","pt":1580645485321,"mc":[{"id":"1.168224441","rc":[{"batb":[[0,1.75,24.85]],"ltp":1.76,"tv":7538.55,"id":2263634}]}]}
{"op":"mcm","clk":"1005925104","pt":1580645485585,"mc":[{"id":"1.168224441","rc":[{"batl":[[0,1.77,65.35]],"ltp":1.76,"tv":7538.55,"id":2263634}]}]}
{"op":"mcm","clk":"1005986318","pt":1580645830354,"mc":[{"id":"1.168224441","rc":[{"trd":[[1.75,1393.49]],"batb":[[0,1.75,10.75]],"ltp":1.75,"tv":7566.75,"id":2263634}],"tv":10174.63}]}
{"op":"mcm","clk":"1005986415","pt":1580645830846,"mc":[{"id":"1.168224441","rc":[{"batb":[[0,2.3,23.6]],"ltp":2.3,"tv":2607.88,"id":10894176},{"batb":[[1,1.74,44.86]],"ltp":1.75,"tv":7566.75,"id":2263634}]}]}
{"op":"mcm","clk":"1005986532","pt":1580645831525,"mc":[{"id":"1.168224441","rc":[{"batb":[[0,2.32,3.27],[1,2.3,23.6],[2,2.28,3.32]],"ltp":2.3,"tv":2607.88,"id":10894176},{"batl":[[0,1.76,4.31],[1,1.77,65.35],[2,1.78,4.2]],"ltp":1.75,"tv":7566.75,"id":2263634}]}]}
{"op":"mcm","clk":"1005986963","pt":1580645834076,"mc":[{"id":"1.168224441","rc":[{"batb":[[0,2.3,23.6],[1,2.28,3.32],[2,2.26,3.34]],"ltp":2.3,"tv":2607.88,"id":10894176}]}]}
{"op":"mcm","clk":"1005987294","pt":1580645835926,"mc":[{"id":"1.168224441","rc":[{"batb":[[0,1.75,15.09]],"ltp":1.75,"tv":7566.75,"id":2263634}]}]}
{"op":"mcm","clk":"1005989562","pt":1580645849504,"mc":[{"id":"1.168224441","rc":[{"batl":[[0,1.77,65.35],[1,1.78,4.2],[2,1.79,4.21]],"ltp":1.75,"tv":7566.75,"id":2263634}]}]}
{"op":"mcm","clk":"1005994024","pt":1580645875641,"mc":[{"id":"1.168224441","rc":[{"batb":[[2,2.26,5.55]],"batl":[[2,2.38,5.17]],"ltp":2.3,"tv":2607.88,"id":10894176},{"batb":[[2,1.73,197.71]],"batl":[[2,1.79,6.23]],"ltp":1.75,"tv":7566.75,"id":2263634}]}]}
{"op":"mcm","clk":"1006025871","pt":1580646059348,"mc":[{"id":"1.168224441","rc":[{"trd":[[2.34,283.3]],"batl":[[0,2.34,5.13]],"ltp":2.34,"tv":2620.8,"id":10894176},{"trd":[[1.75,1423.21]],"batb":[[0,1.74,45.08],[1,1.73,197.71],[2,1.72,2.09]],"ltp":1.75,"tv":7596.47,"id":2263634}],"tv":10217.28}]}
{"op":"mcm","clk":"1006026034","pt":1580646060343,"mc":[{"id":"1.168224441","rc":[{"trd":[[2.34,293.57]],"batb":[[0,2.34,2.85],[1,2.3,23.6],[2,2.28,5.32]],"batl":[[0,2.36,37.3],[1,2.38,5.17],[2,2.72,8.65]],"ltp":2.34,"tv":2631.07,"id":10894176},{"trd":[[1.75,1423.67]],"batb":[[0,1.74,44.86],[2,1.71,2.19]],"batl":[[0,1.77,67.35],[1,1.78,6.22]],"ltp":1.75,"tv":7596.93,"id":2263634}],"tv":10228.0}]}
{"op":"mcm","clk":"1006026233","pt":1580646061359,"mc":[{"id":"1.168224441","rc":[{"batb":[[0,2.3,23.6],[1,2.28,5.32],[2,2.26,5.55]],"batl":[[2,2.4,2.04]],"ltp":2.34,"tv":2631.07,"id":10894176},{"batb":[[1,1.73,195.58],[2,1.72,2.02]],"ltp":1.75,"tv":7596.93,"id":2263634}]}]}
{"op":"mcm","clk":"1006026314","pt":1580646061732,"mc":[{"id":"1.168224441","rc":[{"batb":[[1,2.28,3.32]],"batl":[[1,2.38,3.13]],"ltp":2.34,"tv":2631.07,"id":10894176},{"batl":[[0,1.77,65.35],[1,1.78,4.2]],"ltp":1.75,"tv":7596.93,"id":2263634}]}]}
{"op":"mcm","clk":"1006026660","pt":1580646063440,"mc":[{"id":"1.168224441","rc":[{"batb":[[0,2.32,3.28],[1,2.3,23.6],[2,2.28,3.32]],"ltp":2.34,"tv":2631.07,"id":10894176},{"batl":[[0,1.76,4.32],[1,1.77,65.35],[2,1.78,4.2]],"ltp":1.75,"tv":7596.93,"id":2263634}]}]}
{"op":"mcm","clk":"1006026768","pt":1580646064030,"mc":[{"id":"1.168224441","rc":[{"batb":[[2,2.28,5.32]],"ltp":2.34,"tv":2631.07,"id":10894176},{"batl":[[2,1.78,6.21]],"ltp":1.75,"tv":7596.93,"id":2263634}]}]}
{"op":"mcm","clk":"1006029351","pt":1580646078349,"mc":[{"id":"1.168224441","rc":[{"batb":[[1,2.3,17.14]],"ltp":2.34,"tv":2631.07,"id":10894176},{"batl":[[0,1.76,16.92],[1,1.77,56.95]],"ltp":1.75,"tv":7596.93,"id":2263634}]}]}
{"op":"mcm","clk":"1006029399","pt":1580646078661,"mc":[{"id":"1.168224441","rc":[{"batb":[[0,2.32,12.82]],"ltp":2.34,"tv":2631.07,"id":10894176}]}]}
{"op":"mcm","clk":"1006040983","pt":1580646142279,"mc":[{"id":"1.168224441","rc":[{"trd":[[1.74,1288.91]],"batb":[[0,1.73,195.68],[1,1.71,2],[2,1.7,2.02]],"ltp":1.74,"tv":7686.43,"id":2263634}],"tv":10317.51}]}
{"op":"mcm","clk":"1006041128","pt":1580646143025,"mc":[{"id":"1.168224441","rc":[{"batb":[[0,1.73,195.58],[1,1.72,4.43],[2,1.71,2]],"ltp":1.74,"tv":7686.43,"id":2263634}]}]}
{"op":"mcm","clk":"1006041348","pt":1580646144235,"mc":[{"id":"1.168224441","rc":[{"batl":[[0,1.75,4.35],[1,1.76,29.98],[2,1.77,58.97]],"ltp":1.74,"tv":7686.43,"id":2263634}]}]}
{"op":"mcm","clk":"1006041423","pt":1580646144653,"mc":[{"id":"1.168224441","rc":[{"batl":[[1,1.76,39.42]],"ltp":1.74,"tv":7686.43,"id":2263634}]}]}
{"op":"mcm","clk":"1006043082","pt":1580646154371,"mc":[{"id":"1.168224441","rc":[{"trd":[[2.36,93.13]],"batl":[[0,2.36,6.65]],"ltp":2.36,"tv":2692.37,"id":10894176}],"tv":10378.81}]}
{"op":"mcm","clk":"1006043248","pt":1580646155269,"mc":[{"id":"1.168224441","rc":[{"trd":[[2.36,106.43]],"batb":[[1,2.3,25.84]],"batl":[[0,2.38,3.13],[1,2.4,2.04],[2,2.42,2.06]],"ltp":2.36,"tv":2705.67,"id":10894176},{"trd":[[1.73,86.62]],"batb":[[0,1.73,188.81]],"batl":[[0,1.76,39.42],[1,1.77,58.97],[2,1.78,6.22]],"ltp":1.73,"tv":7699.98,"id":2263634}],"tv":10405.65}]}
{"op":"mcm","clk":"1006043335","pt":1580646155747,"mc":[{"id":"1.168224441","rc":[{"batb":[[0,2.32,27.44]],"batl":[[1,2.4,3.18]],"ltp":2.36,"tv":2705.67,"id":10894176},{"batl":[[1,1.77,56.95]],"ltp":1.73,"tv":7699.98,"id":2263634}]}]}
{"op":"mcm","clk":"1006043480","pt":1580646156650,"mc":[{"id":"1.168224441","rc":[{"batb":[[1,2.3,34.26]],"ltp":2.36,"tv":2705.67,"id":10894176},{"batl":[[0,1.75,4.35],[1,1.76,39.42],[2,1.77,58.97]],"ltp":1.73,"tv":7699.98,"id":2263634}]}]}
{"op":"mcm","clk":"1006043784","pt":1580646158373,"mc":[{"id":"1.168224441","rc":[{"batl":[[1,1.76,47.94]],"ltp":1.73,"tv":7699.98,"id":2263634}]}]}
{"op":"mcm","clk":"1006044162","pt":1580646160437,"mc":[{"id":"1.168224441","rc":[{"batb":[[0,2.34,3.25],[1,2.32,27.44],[2,2.3,36.34]],"ltp":2.36,"tv":2705.67,"id":10894176}]}]}
{"op":"mcm","clk":"1006046201","pt":1580646171372,"mc":[{"id":"1.168224441","rc":[{"batl":[[1,1.76,35.34]],"ltp":1.73,"tv":7699.98,"id":2263634}]}]}
{"op":"mcm","clk":"1006046304","pt":1580646172073,"mc":[{"id":"1.168224441","rc":[{"batb":[[0,2.34,20.06],[1,2.32,17.9]],"ltp":2.36,"tv":2705.67,"id":10894176}]}]}
{"op":"mcm","clk":"1006047799","pt":1580646181187,"mc":[{"id":"1.168224441","rc":[{"batl":[[1,1.76,44.77]],"ltp":1.73,"tv":7699.98,"id":2263634}]}]}
{"op":"mcm","clk":"1006059267","pt":1580646246986,"mc":[{"id":"1.168224441","rc":[{"trd":[[1.73,397.09]],"batb":[[0,1.73,33.57]],"ltp":1.73,"tv":8010.45,"id":2263634}],"tv":10716.12}]}
{"op":"mcm","clk":"1006062282","pt":1580646265348,"mc":[{"id":"1.168224441","rc":[{"batl":[[0,1.75,16.96]],"ltp":1.73,"tv":8010.45,"id":2263634}]}]}
{"op":"mcm","clk":"1006080518","pt":1580646371370,"mc":[{"id":"1.168224441","rc":[{"trd":[[2.38,557.03]],"batb":[[1,2.32,20.04]],"batl":[[0,2.4,3.34],[1,2.42,2.06],[2,2.72,8.65]],"ltp":2.38,"tv":2711.61,"id":10894176},{"trd":[[1.73,464.21]],"batb":[[0,1.72,4.43],[1,1.7,2.02],[2,1.69,2.05]],"batl":[[0,1.73,472.97],[1,1.75,18.98],[2,1.76,46.79]],"ltp":1.73,"tv":8077.57,"id":2263634}],"tv":10789.19}]}
{"op":"mcm","clk":"1006080698","pt":1580646372413,"mc":[{"id":"1.168224441","rc":[{"batb":[[0,2.38,19.88],[1,2.34,22.22],[2,2.32,20.04]],"batl":[[0,2.42,3.16],[1,2.44,3.13],[2,2.46,2.12]],"ltp":2.38,"tv":2711.61,"id":10894176},{"batb":[[0,1.71,4.48],[1,1.7,4.5]],"batl":[[0,1.72,23.22],[1,1.73,472.97],[2,1.74,2.21]],"ltp":1.73,"tv":8077.57,"id":2263634}]}]}
{"op":"mcm","clk":"1006080906","pt":1580646373404,"mc":[{"id":"1.168224441","rc":[{"batb":[[0,2.38,28.02]],"batl":[[0,2.44,3.13],[1,2.46,5.23],[2,2.48,2.04]],"ltp":2.38,"tv":2711.61,"id":10894176},{"batb":[[0,1.7,4.5],[1,1.69,6.58],[2,1.68,2.11]],"batl":[[0,1.72,32.89]],"ltp":1.73,"tv":8077.57,"id":2263634}]}]}
{"op":"mcm","clk":"1006080991","pt":1580646373893,"mc":[{"id":"1.168224441","rc":[{"batl":[[1,2.46,3.11]],"ltp":2.38,"tv":2711.61,"id":10894176},{"batb":[[1,1.69,4.53]],"batl":[[2,1.74,6.61]],"ltp":1.73,"tv":8077.57,"id":2263634}]}]}
{"op":"mcm","clk":"1006081247","pt":1580646375210,"mc":[{"id":"1.168224441","rc":[{"batb":[[0,1.69,4.53],[1,1.68,4.55],[2,1.67,3.36]],"ltp":1.73,"tv":8077.57,"id":2263634}]}]}
{"op":"mcm","clk":"1006081655","pt":1580646377406,"mc":[{"id":"1.168224441","rc":[{"batb":[[2,2.32,17.9]],"ltp":2.38,"tv":2711.61,"id":10894176},{"batl":[[1,1.74,6.61],[2,1.75,16.96]],"ltp":1.73,"tv":8077.57,"id":2263634}]}]}
{"op":"mcm","clk":"1006081848","pt":1580646378406,"mc":[{"id":"1.168224441","rc":[{"batb":[[0,2.36,3.24],[1,2.34,30.77],[2,2.32,20.04]],"ltp":2.38,"tv":2711.61,"id":10894176},{"batl":[[0,1.74,6.61],[1,1.75,18.98],[2,1.76,4.32]],"ltp":1.73,"tv":8077.57,"id":2263634}]}]}
{"op":"mcm","clk":"1006081959","pt":1580646379044,"mc":[{"id":"1.168224441","rc":[{"batb":[[1,2.34,28.61]],"ltp":2.38,"tv":2711.61,"id":10894176},{"batl":[[0,1.74,4.4],[1,1.75,16.96],[2,1.76,6.34]],"ltp":1.73,"tv":8077.57,"id":2263634}]}]}
{"op":"mcm","clk":"1006082122","pt":1580646380032,"mc":[{"id":"1.168224441","rc":[{"batb":[[1,2.34,20.06]],"ltp":2.38,"tv":2711.61,"id":10894176},{"batl":[[1,1.75,30.09]],"ltp":1.73,"tv":8077.57,"id":2263634}]}]}
{"op":"mcm","clk":"1006083862","pt":1580646389323,"mc":[{"id":"1.168224441","rc":[{"batb":[[1,2.34,3.25]],"ltp":2.38,"tv":2711.61,"id":10894176},{"batl":[[1,1.75,17.48],[2,1.76,19.4]],"ltp":1.73,"tv":8077.57,"id":2263634}]}]}
{"op":"mcm","clk":"1006083973","pt":1580646389846,"mc":[{"id":"1.168224441","rc":[{"batb":[[0,2.36,12.51]],"ltp":2.38,"tv":2711.61,"id":10894176},{"batl":[[0,1.74,17.01],[2,1.76,28.84]],"ltp":1.73,"tv":8077.57,"id":2263634}]}]}
{"op":"mcm","clk":"1006084279","pt":1580646391305,"mc":[{"id":"1.168224441","rc":[{"batl":[[0,1.73,4.43],[1,1.74,17.01],[2,1.75,17.48]],"ltp":1.73,"tv":8077.57,"id":2263634}]}]}
{"op":"mcm","clk":"1006084401","pt":1580646391919,"mc":[{"id":"1.168224441","rc":[{"batl":[[2,1.75,19.5]],"ltp":1.73,"tv":8077.57,"id":2263634}]}]}
{"op":"mcm","clk":"1006088190","pt":1580646413356,"mc":[{"id":"1.168224441","rc":[{"batb":[[0,2.38,3.22],[1,2.36,12.51],[2,2.34,5.41]],"ltp":2.38,"tv":2711.61,"id":10894176}]}]}
{"op":"mcm","clk":"1006089368","pt":1580646420365,"mc":[{"id":"1.168224441","rc":[{"batb":[[2,2.34,10.83]],"ltp":2.38,"tv":2711.61,"id":10894176},{"batb":[[0,1.7,30.97],[1,1.69,4.53],[2,1.68,6.57]],"ltp":1.73,"tv":8077.57,"id":2263634}]}]}
{"op":"mcm","clk":"1006089574","pt":1580646421379,"mc":[{"id":"1.168224441","rc":[{"batb":[[1,2.36,3.24]],"ltp":2.38,"tv":2711.61,"id":10894176},{"batb":[[0,1.7,35.47]],"batl":[[1,1.74,4.4]],"ltp":1.73,"tv":8077.57,"id":2263634}]}]}
{"op":"mcm","clk":"1006089687","pt":1580646421986,"mc":[{"id":"1.168224441","rc":[{"batb":[[0,2.38,12.35]],"ltp":2.38,"tv":2711.61,"id":10894176},{"batl":[[0,1.73,17.03]],"ltp":1.73,"tv":8077.57,"id":2263634}]}]}
{"op":"mcm","clk":"1006095732","pt":1580646455379,"mc":[{"id":"1.168224441","rc":[{"batl":[[0,1.72,4.45],[1,1.73,17.03],[2,1.74,4.4]],"ltp":1.73,"tv":8077.57,"id":2263634}]}]}
{"op":"mcm","clk":"1006095878","pt":1580646456341,"mc":[{"id":"1.168224441","rc":[{"batb":[[0,2.4,3.19],[1,2.38,12.35],[2,2.36,5.28]],"ltp":2.38,"tv":2711.61,"id":10894176},{"batl":[[2,1.74,6.65]],"ltp":1.73,"tv":8077.57,"id":2263634}]}]}
{"op":"mcm","clk":"1006096033","pt":1580646457230,"mc":[{"id":"1.168224441","rc":[{"batb":[[0,2.38,12.35],[1,2.36,3.24],[2,2.34,10.89]],"ltp":2.38,"tv":2711.61,"id":10894176},{"batl":[[2,1.74,16.2]],"ltp":1.73,"tv":8077.57,"id":2263634}]}]}
{"op":"mcm","clk":"1006096185","pt":1580646458237,"mc":[{"id":"1.168224441","rc":[{"batb":[[1,2.36,5.28]],"ltp":2.38,"tv":2711.61,"id":10894176}]}]}
{"op":"mcm","clk":"1006096354","pt":1580646459377,"mc":[{"id":"1.168224441","rc":[{"batb":[[0,2.4,3.19],[1,2.38,12.35],[2,2.36,5.42]],"ltp":2.38,"tv":2711.61,"id":10894176}]}]}
{"op":"mcm","clk":"1006096522","pt":1580646460434,"mc":[{"id":"1.168224441","rc":[{"batb":[[2,2.36,3.24]],"ltp":2.38,"tv":2711.61,"id":10894176}]}]}
{"op":"mcm","clk":"1006096613","pt":1580646461070,"mc":[{"id":"1.168224441","rc":[{"batb":[[2,2.36,5.28]],"ltp":2.38,"tv":2711.61,"id":10894176}]}]}
{"op":"mcm","clk":"1006096832","pt":1580646462445,"mc":[{"id":"1.168224441","rc":[{"batb":[[2,2.36,5.42]],"ltp":2.38,"tv":2711.61,"id":10894176}]}]}
{"op":"mcm","clk":"1006098481","pt":1580646473267,"mc":[{"id":"1.168224441","rc":[{"trd":[[1.7,142.71]],"batb":[[0,1.7,31.29]],"ltp":1.7,"tv":8085.93,"id":2263634}],"tv":10797.55}]}
{"op":"mcm","clk":"1006098936","pt":1580646476270,"mc":[{"id":"1.168224441","rc":[{"trd":[[2.4,344.3]],"batb":[[0,2.38,12.35],[1,2.36,3.24],[2,2.34,13.73]],"ltp":2.4,"tv":2718.0,"id":10894176},{"batb":[[0,1.7,4.5]],"ltp":1.7,"tv":8085.93,"id":2263634}],"tv":10803.94}]}
{"op":"mcm","clk":"1006098981","pt":1580646476477,"mc":[{"id":"1.168224441","rc":[{"batb":[[1,1.69,37.65]],"ltp":1.7,"tv":8085.93,"id":2263634}]}]}
{"op":"mcm","clk":"1006099181","pt":1580646477587,"mc":[{"id":"1.168224441","rc":[{"batb":[[2,2.34,5.44]],"ltp":2.4,"tv":2718.0,"id":10894176}]}]}
{"op":"mcm","clk":"1006099456","pt":1580646479275,"mc":[{"id":"1.168224441","rc":[{"batl":[[2,1.74,6.65]],"ltp":1.7,"tv":8085.93,"id":2263634}]}]}
{"op":"mcm","clk":"1006100257","pt":1580646484389,"mc":[{"id":"1.168224441","rc":[{"batl":[[0,1.72,17.06],[1,1.73,4.43]],"ltp":1.7,"tv":8085.93,"id":2263634}]}]}
{"op":"mcm","clk":"1006101451","pt":1580646492299,"mc":[{"id":"1.168224441","rc":[{"batb":[[0,2.4,3.19],[1,2.38,12.35],[2,2.36,3.24]],"ltp":2.4,"tv":2718.0,"id":10894176}]}]}
{"op":"mcm","clk":"1006101564","pt":1580646493099,"mc":[{"id":"1.168224441","rc":[{"batb":[[2,2.36,5.28]],"ltp":2.4,"tv":2718.0,"id":10894176}]}]}
{"op":"mcm","clk":"1006101769","pt":1580646494414,"mc":[{"id":"1.168224441","rc":[{"batb":[[0,1.69,37.65],[1,1.68,6.57],[2,1.67,3.25]],"batl":[[0,1.71,4.48],[1,1.72,17.06],[2,1.73,4.43]],"ltp":1.7,"tv":8085.93,"id":2263634}]}]}
{"op":"mcm","clk":"1006101893","pt":1580646495308,"mc":[{"id":"1.168224441","rc":[{"batb":[[1,1.68,4.55]],"batl":[[0,1.72,17.06],[1,1.73,4.43],[2,1.74,6.65]],"ltp":1.7,"tv":8085.93,"id":2263634}]}]}
{"op":"mcm","clk":"1006105435","pt":1580646516325,"mc":[{"id":"1.168224441","rc":[{"batb":[[0,2.4,12.19],[1,2.38,3.22]],"ltp":2.4,"tv":2718.0,"id":10894176},{"batl":[[0,1.71,4.48],[1,1.72,17.06],[2,1.73,6.44]],"ltp":1.7,"tv":8085.93,"id":2263634}]}]}
{"op":"mcm","clk":"1006105613","pt":1580646517438,"mc":[{"id":"1.168224441","rc":[{"batl":[[0,1.72,17.06],[1,1.73,4.43],[2,1.74,6.57]],"ltp":1.7,"tv":8085.93,"id":2263634}]}]}
{"op":"mcm","clk":"1006119336","pt":1580646597336,"mc":[{"id":"1.168224441","rc":[{"batl":[[0,1.71,4.49],[1,1.72,17.06],[2,1.73,6.67]],"ltp":1.7,"tv":8085.93,"id":2263634}]}]}
{"op":"mcm","clk":"1006119478","pt":1580646598023,"mc":[{"id":"1.168224441","rc":[{"batl":[[0,1.72,17.06],[1,1.73,4.43],[2,1.74,6.53]],"ltp":1.7,"tv":8085.93,"id":2263634}]}]}
{"op":"mcm","clk":"1006119638","pt":1580646598873,"mc":[{"id":"1.168224441","rc":[{"batl":[[0,1.71,4.49],[1,1.72,17.06],[2,1.73,6.67]],"ltp":1.7,"tv":8085.93,"id":2263634}]}]}
{"op":"mcm","clk":"1006121605","pt":1580646608869,"mc":[{"id":"1.168224441","rc":[{"batl":[[0,1.71,17.09],[1,1.72,4.45]],"ltp":1.7,"tv":8085.93,"id":2263634}]}]}
{"op":"mcm","clk":"1006121893","pt":1580646610363,"mc":[{"id":"1.168224441","rc":[{"batb":[[0,2.42,3.17],[1,2.4,12.19],[2,2.38,5.39]],"ltp":2.4,"tv":2718.0,"id":10894176}]}]}
{"op":"mcm","clk":"1006122048","pt":1580646611229,"mc":[{"id":"1.168224441","rc":[{"batb":[[0,2.4,12.19],[1,2.38,3.22],[2,2.36,5.42]],"batl":[[0,2.46,3.11],[1,2.48,3.09],[2,2.5,2]],"ltp":2.4,"tv":2718.0,"id":10894176}]}]}
{"op":"mcm","clk":"1006122179","pt":1580646611861,"mc":[{"id":"1.168224441","rc":[{"batb":[[0,2.42,3.17],[1,2.4,12.19],[2,2.38,5.39]],"ltp":2.4,"tv":2718.0,"id":10894176}]}]}
{"op":"mcm","clk":"1006122410","pt":1580646613202,"mc":[{"id":"1.168224441","rc":[{"batb":[[2,2.38,3.22]],"ltp":2.4,"tv":2718.0,"id":10894176}]}]}
{"op":"mcm","clk":"1006122461","pt":1580646613456,"mc":[{"id":"1.168224441","rc":[{"batb":[[2,2.38,5.23]],"ltp":2.4,"tv":2718.0,"id":10894176}]}]}
{"op":"mcm","clk":"1006122712","pt":1580646615096,"mc":[{"id":"1.168224441","rc":[{"batb":[[2,2.38,3.22]],"ltp":2.4,"tv":2718.0,"id":10894176}]}]}
{"op":"mcm","clk":"1006122920","pt":1580646616268,"mc":[{"id":"1.168224441","rc":[{"batb":[[2,2.38,5.39]],"ltp":2.4,"tv":2718.0,"id":10894176}]}]}
{"op":"mcm","clk":"1006127106","pt":1580646640333,"mc":[{"id":"1.168224441","rc":[{"batb":[[0,2.42,12.04],[1,2.4,3.19]],"ltp":2.4,"tv":2718.0,"id":10894176}]}]}
{"op":"mcm","clk":"1006127458","pt":1580646642302,"mc":[{"id":"1.168224441","rc":[{"batl":[[0,1.7,4.51],[1,1.71,17.09],[2,1.72,8.66]],"ltp":1.7,"tv":8085.93,"id":2263634}]}]}
{"op":"mcm","clk":"1006132478","pt":1580646671358,"mc":[{"id":"1.168224441","rc":[{"batl":[[1,1.71,4.49]],"ltp":1.7,"tv":8085.93,"id":2263634}]}]}
{"op":"mcm","clk":"1006132596","pt":1580646671960,"mc":[{"id":"1.168224441","rc":[{"batl":[[2,1.72,6.61]],"ltp":1.7,"tv":8085.93,"id":2263634}]}]}
{"op":"mcm","clk":"1006135875","pt":1580646690353,"mc":[{"id":"1.168224441","rc":[{"trd":[[2.42,421.09]],"batb":[[0,2.42,2.62]],"ltp":2.42,"tv":2736.84,"id":10894176},{"trd":[[1.7,151.73]],"batl":[[0,1.71,4.49],[1,1.72,6.61],[2,1.73,6.43]],"ltp":1.7,"tv":8094.96,"id":2263634}],"tv":10831.8}]}
{"op":"mcm","clk":"1006135995","pt":1580646691035,"mc":[{"id":"1.168224441","rc":[{"batb":[[0,1.69,4.53]],"batl":[[1,1.72,4.45]],"ltp":1.7,"tv":8094.96,"id":2263634}]}]}
{"op":"mcm","clk":"1006138352","pt":1580646703371,"mc":[{"id":"1.168224441","rc":[{"batb":[[0,2.42,8.87],[2,2.38,3.22]],"ltp":2.42,"tv":2736.84,"id":10894176},{"batl":[[0,1.71,17.09]],"ltp":1.7,"tv":8094.96,"id":2263634}]}]}
{"op":"mcm","clk":"1006138388","pt":1580646703584,"mc":[{"id":"1.168224441","rc":[{"batb":[[2,2.38,5.39]],"ltp":2.42,"tv":2736.84,"id":10894176}]}]}
{"op":"mcm","clk":"1006144005","pt":1580646735216,"mc":[{"id":"1.168224441","rc":[{"batb":[[0,2.42,12.05]],"ltp":2.42,"tv":2736.84,"id":10894176}]}]}
{"op":"mcm","clk":"1006149213","pt":1580646765345,"mc":[{"id":"1.168224441","rc":[{"batl":[[0,1.7,4.52],[1,1.71,4.49],[2,1.72,6.61]],"ltp":1.7,"tv":8094.96,"id":2263634}]}]}
{"op":"mcm","clk":"1006149465","pt":1580646766850,"mc":[{"id":"1.168224441","rc":[{"batb":[[0,1.68,4.55],[1,1.67,5.86],[2,1.66,2.02]],"ltp":1.7,"tv":8094.96,"id":2263634}]}]}
{"op":"mcm","clk":"1006154629","pt":1580646796379,"mc":[{"id":"1.168224441","rc":[{"batl":[[0,1.7,17.12]],"ltp":1.7,"tv":8094.96,"id":2263634}]}]}
{"op":"mcm","clk":"1006155171","pt":1580646799269,"mc":[{"id":"1.168224441","rc":[{"batb":[[0,2.44,3.15],[1,2.42,12.05],[2,2.4,3.19]],"ltp":2.42,"tv":2736.84,"id":10894176}]}]}
{"op":"mcm","clk":"1006155318","pt":1580646799991,"mc":[{"id":"1.168224441","rc":[{"batb":[[2,2.4,5.2]],"ltp":2.42,"tv":2736.84,"id":10894176}]}]}
{"op":"mcm","clk":"1006155550","pt":1580646801375,"mc":[{"id":"1.168224441","rc":[{"batl":[[0,2.48,3.09],[1,2.5,3.08],[2,2.52,2.01]],"ltp":2.42,"tv":2736.84,"id":10894176}]}]}
{"op":"mcm","clk":"1006156102","pt":1580646804399,"mc":[{"id":"1.168224441","rc":[{"batb":[[0,2.42,12.05],[1,2.4,5.2],[2,2.38,5.31]],"ltp":2.42,"tv":2736.84,"id":10894176}]}]}
{"op":"mcm","clk":"1006156121","pt":1580646804508,"mc":[{"id":"1.168224441","rc":[{"batb":[[1,2.4,3.19]],"ltp":2.42,"tv":2736.84,"id":10894176}]}]}
{"op":"mcm","clk":"1006156473","pt":1580646806388,"mc":[{"id":"1.168224441","rc":[{"batb":[[0,2.44,3.15],[1,2.42,12.05],[2,2.4,5.2]],"ltp":2.42,"tv":2736.84,"id":10894176}]}]}
{"op":"mcm","clk":"1006156871","pt":1580646808291,"mc":[{"id":"1.168224441","rc":[{"batl":[[0,1.69,4.55],[1,1.7,17.12],[2,1.71,6.5]],"ltp":1.7,"tv":8094.96,"id":2263634}]}]}
{"op":"mcm","clk":"1006157324","pt":1580646810888,"mc":[{"id":"1.168224441","rc":[{"batb":[[0,1.67,5.86],[1,1.66,4.63],[2,1.65,2.13]],"batl":[[0,1.7,17.12],[1,1.71,4.49],[2,1.72,6.61]],"ltp":1.7,"tv":8094.96,"id":2263634}]}]}
{"op":"mcm","clk":"1006157534","pt":1580646812199,"mc":[{"id":"1.168224441","rc":[{"batl":[[0,1.69,4.55],[1,1.7,17.12],[2,1.71,6.61]],"ltp":1.7,"tv":8094.96,"id":2263634}]}]}
{"op":"mcm","clk":"1006157838","pt":1580646813902,"mc":[{"id":"1.168224441","rc":[{"batl":[[0,1.7,17.12],[1,1.71,4.49],[2,1.72,6.61]],"ltp":1.7,"tv":8094.96,"id":2263634}]}]}
{"op":"mcm","clk":"1006158068","pt":1580646815395,"mc":[{"id":"1.168224441","rc":[{"batl":[[0,1.69,4.55],[1,1.7,17.12],[2,1.71,6.49]],"ltp":1.7,"tv":8094.96,"id":2263634}]}]}
{"op":"mcm","clk":"1006158388","pt":1580646817305,"mc":[{"id":"1.168224441","rc":[{"batl":[[0,1.7,17.12],[1,1.71,4.49],[2,1.72,6.61]],"ltp":1.7,"tv":8094.96,"id":2263634}]}]}
{"op":"mcm","clk":"1006160313","pt":1580646828128,"mc":[{"id":"1.168224441","rc":[{"batb":[[0,2.44,11.91],[1,2.42,3.18]],"ltp":2.42,"tv":2736.84,"id":10894176}]}]}
{"op":"mcm","clk":"1006160733","pt":1580646830369,"mc":[{"id":"1.168224441","rc":[{"trd":[[2.44,147.07]],"batb":[[0,2.44,4.67]],"ltp":2.44,"tv":2751.31,"id":10894176}],"tv":10846.27}]}
{"op":"mcm","clk":"1006161159","pt":1580646832664,"mc":[{"id":"1.168224441","rc":[{"batb":[[1,1.66,43.07]],"ltp":1.7,"tv":8094.96,"id":2263634}]}]}
{"op":"mcm","clk":"1006169090","pt":1580646874389,"mc":[{"id":"1.168224441","rc":[{"batb":[[0,2.44,7.82]],"ltp":2.44,"tv":2751.31,"id":10894176},{"batl":[[0,1.69,4.55],[1,1.7,17.12],[2,1.71,4.49]],"ltp":1.7,"tv":8094.96,"id":2263634}]}]}
{"op":"mcm","clk":"1006169196","pt":1580646874979,"mc":[{"id":"1.168224441","rc":[{"batl":[[2,1.71,6.61]],"ltp":1.7,"tv":8094.96,"id":2263634}]}]}
{"op":"mcm","clk":"1006172332","pt":1580646890408,"mc":[{"id":"1.168224441","rc":[{"batb":[[0,2.44,3.15]],"ltp":2.44,"tv":2751.31,"id":10894176},{"batl":[[1,1.7,4.52]],"ltp":1.7,"tv":8094.96,"id":2263634}]}]}
{"op":"mcm","clk":"1006207985","pt":1580647073322,"mc":[{"id":"1.168224441","rc":[{"trd":[[2.48,3.09]],"batb":[[0,2.44,5.16],[1,2.42,5.31]],"batl":[[0,2.5,3.08],[1,2.54,2.01],[2,2.56,2.17]],"ltp":2.48,"tv":2754.4,"id":10894176},{"trd":[[1.67,58.01]],"batb":[[0,1.66,43.07],[1,1.64,2.02],[2,1.63,2.23]],"batl":[[0,1.67,496.07],[1,1.69,6.63],[2,1.7,6.57]],"ltp":1.67,"tv":8111.25,"id":2263634}],"tv":10865.66}]}
{"op":"mcm","clk":"1006208242","pt":1580647074444,"mc":[{"id":"1.168224441","rc":[{"trd":[[2.5,6.15]],"batb":[[0,2.5,21.46],[1,2.46,2.01],[2,2.44,5.16]],"batl":[[0,2.54,3.03],[1,2.56,5.18],[2,2.58,2.13]],"ltp":2.5,"tv":2760.55,"id":10894176},{"trd":[[1.66,29.42]],"batb":[[0,1.66,34.3],[1,1.65,4.67],[2,1.64,6.72]],"batl":[[0,1.67,519.77],[1,1.68,1.24],[2,1.69,6.63]],"ltp":1.66,"tv":8128.8,"id":2263634}],"tv":10889.35}]}
{"op":"mcm","clk":"1006208431","pt":1580647075445,"mc":[{"id":"1.168224441","rc":[{"trd":[[2.5,15.51]],"batb":[[0,2.5,16.78]],"batl":[[1,2.56,3.01]],"ltp":2.5,"tv":2769.91,"id":10894176},{"trd":[[1.67,89.8]],"batb":[[0,1.65,4.67],[1,1.64,39.77],[2,1.63,2.23]],"batl":[[0,1.67,503.88]],"ltp":1.67,"tv":8160.59,"id":2263634}],"tv":10930.5}]}
{"op":"mcm","clk":"1006208640","pt":1580647076440,"mc":[{"id":"1.168224441","rc":[{"batb":[[1,2.46,5.14]],"batl":[[0,2.56,3.01],[1,2.58,2.13],[2,2.6,2.01]],"ltp":2.5,"tv":2769.91,"id":10894176},{"batb":[[0,1.64,39.77],[1,1.63,2.23],[2,1.62,2.04]],"ltp":1.67,"tv":8160.59,"id":2263634}]}]}
{"op":"mcm","clk":"1006208711","pt":1580647076756,"mc":[{"id":"1.168224441","rc":[{"batl":[[1,2.58,2.99]],"ltp":2.5,"tv":2769.91,"id":10894176},{"batb":[[1,1.63,4.73]],"ltp":1.67,"tv":8160.59,"id":2263634}]}]}
{"op":"mcm","clk":"1006209038","pt":1580647078363,"mc":[{"id":"1.168224441","rc":[{"batl":[[1,1.68,5.83]],"ltp":1.67,"tv":8160.59,"id":2263634}]}]}
{"op":"mcm","clk":"1006209119","pt":1580647078832,"mc":[{"id":"1.168224441","rc":[{"batb":[[2,2.44,5.32]],"ltp":2.5,"tv":2769.91,"id":10894176}]}]}
{"op":"mcm","clk":"1006209333","pt":1580647079846,"mc":[{"id":"1.168224441","rc":[{"batb":[[1,2.48,3.11],[2,2.46,5.14]],"ltp":2.5,"tv":2769.91,"id":10894176}]}]}
{"op":"mcm","clk":"1006209802","pt":1580647082260,"mc":[{"id":"1.168224441","rc":[{"batb":[[0,2.5,28.08]],"ltp":2.5,"tv":2769.91,"id":10894176},{"batl":[[0,1.66,11.73],[1,1.67,503.88],[2,1.68,7.84]],"ltp":1.67,"tv":8160.59,"id":2263634}]}]}
{"op":"mcm","clk":"1006211496","pt":1580647091271,"mc":[{"id":"1.168224441","rc":[{"trd":[[1.66,52.27]],"batb":[[0,1.64,28.29]],"batl":[[0,1.67,504.18],[1,1.68,5.83],[2,1.69,6.63]],"ltp":1.66,"tv":8183.44,"id":2263634}],"tv":10953.36}]}
{"op":"mcm","clk":"1006211577","pt":1580647091700,"mc":[{"id":"1.168224441","rc":[{"batl":[[0,1.67,503.88]],"ltp":1.66,"tv":8183.44,"id":2263634}]}]}
{"op":"mcm","clk":"1006211766","pt":1580647092691,"mc":[{"id":"1.168224441","rc":[{"batl":[[0,1.67,508.5]],"ltp":1.66,"tv":8183.44,"id":2263634}]}]}
{"op":"mcm","clk":"1006212008","pt":1580647093890,"mc":[{"id":"1.168224441","rc":[{"batb":[[0,1.64,40.83]],"ltp":1.66,"tv":8183.44,"id":2263634}]}]}
{"op":"mcm","clk":"1006220497","pt":1580647136179,"mc":[{"id":"1.168224441","rc":[{"batb":[[0,2.5,31.16]],"ltp":2.5,"tv":2769.91,"id":10894176}]}]}
{"op":"mcm","clk":"1006221782","pt":1580647142348,"mc":[{"id":"1.168224441","rc":[{"batb":[[2,1.62,39.24]],"ltp":1.66,"tv":8183.44,"id":2263634}]}]}
{"op":"mcm","clk":"1006235645","pt":1580647211418,"mc":[{"id":"1.168224441","rc":[{"trd":[[2.56,6.02]],"batb":[[0,2.56,16.99],[1,2.5,31.16],[2,2.48,3.11]],"batl":[[0,2.58,2.99],[1,2.6,2.01],[2,2.62,10.58]],"ltp":2.56,"tv":2775.93,"id":10894176},{"batl":[[0,1.66,11.6],[1,1.67,508.5],[2,1.68,7.84]],"ltp":1.66,"tv":8183.44,"id":2263634}],"tv":10959.37}]}
{"op":"mcm","clk":"1006235843","pt":1580647212341,"mc":[{"id":"1.168224441","rc":[{"trd":[[2.56,39.86]],"batb":[[0,2.5,31.23],[1,2.48,5.12],[2,2.46,5.14]],"batl":[[1,2.62,12.83],[2,2.64,2.01]],"ltp":2.56,"tv":2809.77,"id":10894176}],"tv":10993.21}]}
{"op":"mcm","clk":"1006236086","pt":1580647213305,"mc":[{"id":"1.168224441","rc":[{"trd":[[2.56,39.93]],"batb":[[0,2.5,31.16],[1,2.48,3.11]],"batl":[[1,2.6,2.97],[2,2.62,12.83]],"ltp":2.56,"tv":2809.84,"id":10894176},{"trd":[[1.65,25.44],[1.66,74.79]],"batb":[[0,1.64,36.14],[2,1.62,44]],"batl":[[0,1.67,508.85],[1,1.68,5.83],[2,1.69,6.63]],"ltp":1.66,"tv":8206.07,"id":2263634}],"tv":11015.91}]}
{"op":"mcm","clk":"1006236282","pt":1580647214316,"mc":[{"id":"1.168224441","rc":[{"batl":[[0,1.66,5],[1,1.67,508.5],[2,1.68,5.83]],"ltp":1.66,"tv":8206.07,"id":2263634}]}]}
{"op":"mcm","clk":"1006236413","pt":1580647214895,"mc":[{"id":"1.168224441","rc":[{"trd":[[1.66,84.35]],"batl":[[0,1.67,508.72],[1,1.68,5.83],[2,1.69,6.63]],"ltp":1.66,"tv":8215.63,"id":2263634}],"tv":11025.47}]}
{"op":"mcm","clk":"1006236562","pt":1580647215610,"mc":[{"id":"1.168224441","rc":[{"batb":[[0,1.64,40.85]],"ltp":1.66,"tv":8215.63,"id":2263634}]}]}
{"op":"mcm","clk":"1006236896","pt":1580647217315,"mc":[{"id":"1.168224441","rc":[{"trd":[[2.52,22.74]],"batl":[[0,2.58,28.63]],"ltp":2.52,"tv":2815.97,"id":10894176},{"batb":[[0,1.65,25.54],[1,1.64,40.85],[2,1.63,4.73]],"ltp":1.66,"tv":8215.63,"id":2263634}],"tv":11031.61}]}
{"op":"mcm","clk":"1006237156","pt":1580647218425,"mc":[{"id":"1.168224441","rc":[{"batl":[[0,2.56,3.02],[1,2.58,30.76],[2,2.6,4.98]],"ltp":2.52,"tv":2815.97,"id":10894176},{"batb":[[0,1.65,30.22],[2,1.63,6.88]],"ltp":1.66,"tv":8215.63,"id":2263634}]}]}
{"op":"mcm","clk":"1006237573","pt":1580647220425,"mc":[{"id":"1.168224441","rc":[{"trd":[[1.66,84.79]],"batb":[[0,1.66,25.17],[1,1.65,4.68],[2,1.64,40.85]],"batl":[[0,1.67,508.5]],"ltp":1.66,"tv":8216.07,"id":2263634}],"tv":11032.05}]}
{"op":"mcm","clk":"1006237641","pt":1580647220739,"mc":[{"id":"1.168224441","rc":[{"batl":[[0,2.56,5.19]],"ltp":2.52,"tv":2815.97,"id":10894176},{"batb":[[2,1.64,42.92]],"ltp":1.66,"tv":8216.07,"id":2263634}]}]}
{"op":"mcm","clk":"1006238456","pt":1580647224415,"mc":[{"id":"1.168224441","rc":[{"trd":[[2.5,48.96]],"batb":[[0,2.5,14.43]],"batl":[[1,2.58,30.64]],"ltp":2.5,"tv":2849.42,"id":10894176},{"batb":[[0,1.65,4.68],[1,1.64,40.85],[2,1.63,6.88]],"ltp":1.66,"tv":8216.07,"id":2263634}],"tv":11065.5}]}
{"op":"mcm","clk":"1006238676","pt":1580647225439,"mc":[{"id":"1.168224441","rc":[{"batl":[[0,2.56,3.02]],"ltp":2.5,"tv":2849.42,"id":10894176},{"batb":[[0,1.64,40.85],[1,1.63,4.73],[2,1.62,6.8]],"batl":[[0,1.66,4.65],[1,1.67,508.5],[2,1.68,5.83]],"ltp":1.66,"tv":8216.07,"id":2263634}]}]}
{"op":"mcm","clk":"1006238838","pt":1580647226228,"mc":[{"id":"1.168224441","rc":[{"batb":[[0,2.5,14.38]],"batl":[[1,2.58,28.63]],"ltp":2.5,"tv":2849.42,"id":10894176},{"trd":[[1.66,93.59]],"batl":[[0,1.67,508.76],[1,1.68,5.83],[2,1.69,6.55]],"ltp":1.66,"tv":8224.87,"id":2263634}],"tv":11074.3}]}
{"op":"mcm","clk":"1006239070","pt":1580647227441,"mc":[{"id":"1.168224441","rc":[{"trd":[[2.52,28.87]],"batl":[[1,2.58,30.64]],"ltp":2.52,"tv":2855.56,"id":10894176},{"batb":[[0,1.65,4.68],[1,1.64,40.85],[2,1.63,6.8]],"batl":[[0,1.67,508.5]],"ltp":1.66,"tv":8224.87,"id":2263634}],"tv":11080.44}]}
{"op":"mcm","clk":"1006241765","pt":1580647240441,"mc":[{"id":"1.168224441","rc":[{"trd":[[2.5,77.73]],"batb":[[0,2.48,3.11],[1,2.46,5.14],[2,2.44,2.17]],"ltp":2.5,"tv":2884.33,"id":10894176}],"tv":11109.21}]}
{"op":"mcm","clk":"1006241929","pt":1580647241247,"mc":[{"id":"1.168224441","rc":[{"trd":[[2.5,83.91]],"batb":[[1,2.46,3.13],[2,2.44,2.01]],"ltp":2.5,"tv":2890.51,"id":10894176}],"tv":11115.39}]}
{"op":"mcm","clk":"1006258317","pt":1580647322430,"mc":[{"id":"1.168224441","rc":[{"batb":[[0,1.65,12.25]],"ltp":1.66,"tv":8224.87,"id":2263634}]}]}
{"op":"mcm","clk":"1006258641","pt":1580647324219,"mc":[{"id":"1.168224441","rc":[{"batb":[[0,1.65,19.82]],"ltp":1.66,"tv":8224.87,"id":2263634}]}]}
{"op":"mcm","clk":"1006259085","pt":1580647326393,"mc":[{"id":"1.168224441","rc":[{"batb":[[0,1.65,12.25]],"ltp":1.66,"tv":8224.87,"id":2263634}]}]}
{"op":"mcm","clk":"1006259240","pt":1580647327235,"mc":[{"id":"1.168224441","rc":[{"batb":[[1,2.46,5.14]],"ltp":2.5,"tv":2890.51,"id":10894176},{"batl":[[0,1.66,4.66],[1,1.67,508.5],[2,1.68,7.84]],"ltp":1.66,"tv":8224.87,"id":2263634}]}]}
{"op":"mcm","clk":"1006259464","pt":1580647328310,"mc":[{"id":"1.168224441","rc":[{"batb":[[1,2.46,3.13]],"ltp":2.5,"tv":2890.51,"id":10894176},{"trd":[[1.66,102.45]],"batb":[[0,1.65,7.57]],"batl":[[0,1.67,508.74],[1,1.68,5.83],[2,1.69,6.63]],"ltp":1.66,"tv":8233.73,"id":2263634}],"tv":11124.25}]}
{"op":"mcm","clk":"1006259580","pt":1580647328956,"mc":[{"id":"1.168224441","rc":[{"batb":[[0,1.65,19.83]],"batl":[[0,1.67,508.5]],"ltp":1.66,"tv":8233.73,"id":2263634}]}]}
{"op":"mcm","clk":"1006259855","pt":1580647330322,"mc":[{"id":"1.168224441","rc":[{"batb":[[0,1.65,27.41]],"ltp":1.66,"tv":8233.73,"id":2263634}]}]}
{"op":"mcm","clk":"1006260186","pt":1580647331921,"mc":[{"id":"1.168224441","rc":[{"batl":[[1,2.58,50.06]],"ltp":2.5,"tv":2890.51,"id":10894176}]}]}
{"op":"mcm","clk":"1006260473","pt":1580647333410,"mc":[{"id":"1.168224441","rc":[{"batb":[[0,1.65,12.26]],"ltp":1.66,"tv":8233.73,"id":2263634}]}]}
{"op":"mcm","clk":"1006260568","pt":1580647333834,"mc":[{"id":"1.168224441","rc":[{"batl":[[1,2.58,41.6]],"ltp":2.5,"tv":2890.51,"id":10894176}]}]}
{"op":"mcm","clk":"1006260825","pt":1580647335203,"mc":[{"id":"1.168224441","rc":[{"batl":[[1,2.58,30.64]],"ltp":2.5,"tv":2890.51,"id":10894176}]}]}
{"op":"mcm","clk":"1006261832","pt":1580647340360,"mc":[{"id":"1.168224441","rc":[{"batl":[[2,2.6,2.97]],"ltp":2.5,"tv":2890.51,"id":10894176},{"batl":[[0,1.67,28.32]],"ltp":1.66,"tv":8233.73,"id":2263634}]}]}
{"op":"mcm","clk":"1006261901","pt":1580647340629,"mc":[{"id":"1.168224441","rc":[{"batl":[[2,2.6,4.98]],"ltp":2.5,"tv":2890.51,"id":10894176}]}]}
{"op":"mcm","clk":"1006262120","pt":1580647341862,"mc":[{"id":"1.168224441","rc":[{"batl":[[0,1.67,4.62]],"ltp":1.66,"tv":8233.73,"id":2263634}]}]}
{"op":"mcm","clk":"1006262438","pt":1580647343515,"mc":[{"id":"1.168224441","rc":[{"batb":[[1,1.64,47.46]],"ltp":1.66,"tv":8233.73,"id":2263634}]}]}
{"op":"mcm","clk":"1006262964","pt":1580647346358,"mc":[{"id":"1.168224441","rc":[{"batb":[[0,1.65,27.41]],"ltp":1.66,"tv":8233.73,"id":2263634}]}]}
{"op":"mcm","clk":"1006263744","pt":1580647350235,"mc":[{"id":"1.168224441","rc":[{"batb":[[0,1.65,4.69]],"ltp":1.66,"tv":8233.73,"id":2263634}]}]}
{"op":"mcm","clk":"1006263831","pt":1580647350650,"mc":[{"id":"1.168224441","rc":[{"batb":[[0,1.65,12.26]],"ltp":1.66,"tv":8233.73,"id":2263634}]}]}
{"op":"mcm","clk":"1006298381","pt":1580647527331,"mc":[{"id":"1.168224441","rc":[{"trd":[[2.48,7.63]],"batb":[[0,2.46,3.97],[1,2.42,2.13],[2,2.4,2.01]],"batl":[[2,2.6,2.97]],"ltp":2.48,"tv":2895.05,"id":10894176}],"tv":11128.79}]}
{"op":"mcm","clk":"1006298456","pt":1580647527713,"mc":[{"id":"1.168224441","rc":[{"batb":[[1,2.44,2.17],[2,2.42,2.13]],"batl":[[2,2.6,4.98]],"ltp":2.48,"tv":2895.05,"id":10894176}]}]}
{"op":"mcm","clk":"1006298706","pt":1580647528915,"mc":[{"id":"1.168224441","rc":[{"batb":[[0,2.46,3.13],[1,2.44,3.18]],"ltp":2.48,"tv":2895.05,"id":10894176},{"batl":[[0,1.68,5.83],[1,1.69,4.55],[2,1.7,2.05]],"ltp":1.66,"tv":8233.73,"id":2263634}]}]}
{"op":"mcm","clk":"1006298978","pt":1580647530390,"mc":[{"id":"1.168224441","rc":[{"batl":[[0,1.68,1.24],[2,1.7,6.61]],"ltp":1.66,"tv":8233.73,"id":2263634}]}]}
{"op":"mcm","clk":"1006299000","pt":1580647530501,"mc":[{"id":"1.168224441","rc":[{"batl":[[2,1.7,4.56]],"ltp":1.66,"tv":8233.73,"id":2263634}]}]}
{"op":"mcm","clk":"1006321910","pt":1580647668376,"mc":[{"id":"1.168224441","rc":[{"batb":[[0,1.65,19.83]],"ltp":1.66,"tv":8233.73,"id":2263634}]}]}
{"op":"mcm","clk":"1006322067","pt":1580647669385,"mc":[{"id":"1.168224441","rc":[{"batl":[[0,2.56,5.03]],"ltp":2.48,"tv":2895.05,"id":10894176},{"batb":[[0,1.66,4.68],[1,1.65,27.41],[2,1.64,49.53]],"ltp":1.66,"tv":8233.73,"id":2263634}]}]}
{"op":"mcm","clk":"1006322191","pt":1580647670179,"mc":[{"id":"1.168224441","rc":[{"batl":[[0,2.56,24.59],[1,2.58,30.88]],"ltp":2.48,"tv":2895.05,"id":10894176}]}]}
{"op":"mcm","clk":"1006322358","pt":1580647671090,"mc":[{"id":"1.168224441","rc":[{"batl":[[0,2.54,3.06],[1,2.56,24.59],[2,2.58,30.88]],"ltp":2.48,"tv":2895.05,"id":10894176},{"batb":[[1,1.65,4.69]],"ltp":1.66,"tv":8233.73,"id":2263634}]}]}
{"op":"mcm","clk":"1006345348","pt":1580647819412,"mc":[{"id":"1.168224441","rc":[{"trd":[[1.66,106.45]],"batb":[[0,1.66,2.68]],"ltp":1.66,"tv":8237.73,"id":2263634}],"tv":11132.79}]}
{"op":"mcm","clk":"1006345441","pt":1580647819906,"mc":[{"id":"1.168224441","rc":[{"batl":[[1,2.56,11.54],[2,2.58,41.6]],"ltp":2.48,"tv":2895.05,"id":10894176}]}]}
{"op":"mcm","clk":"1006345615","pt":1580647820988,"mc":[{"id":"1.168224441","rc":[{"batl":[[1,2.56,3.02],[2,2.58,50.06]],"ltp":2.48,"tv":2895.05,"id":10894176},{"batb":[[0,1.65,4.69],[1,1.64,47.46],[2,1.63,6.88]],"ltp":1.66,"tv":8237.73,"id":2263634}]}]}
{"op":"mcm","clk":"1006345910","pt":1580647822788,"mc":[{"id":"1.168224441","rc":[{"batb":[[0,1.65,12.26]],"ltp":1.66,"tv":8237.73,"id":2263634}]}]}
{"op":"mcm","clk":"1006348656","pt":1580647842410,"mc":[{"id":"1.168224441","rc":[{"batb":[[0,1.65,19.83]],"ltp":1.66,"tv":8237.73,"id":2263634}]}]}
{"op":"mcm","clk":"1006350313","pt":1580647853439,"mc":[{"id":"1.168224441","rc":[{"batl":[[1,2.56,5.03]],"ltp":2.48,"tv":2895.05,"id":10894176},{"batb":[[0,1.66,4.69],[1,1.65,4.69],[2,1.64,49.53]],"ltp":1.66,"tv":8237.73,"id":2263634}]}]}
{"op":"mcm","clk":"1006350366","pt":1580647853843,"mc":[{"id":"1.168224441","rc":[{"batl":[[2,2.58,39.34]],"ltp":2.48,"tv":2895.05,"id":10894176}]}]}
{"op":"mcm","clk":"1006350585","pt":1580647855536,"mc":[{"id":"1.168224441","rc":[{"batl":[[1,2.56,16.07]],"ltp":2.48,"tv":2895.05,"id":10894176}]}]}
{"op":"mcm","clk":"1006352985","pt":1580647871062,"mc":[{"id":"1.168224441","rc":[{"batl":[[1,1.69,12.96]],"ltp":1.66,"tv":8237.73,"id":2263634}]}]}
{"op":"mcm","clk":"1006354661","pt":1580647882011,"mc":[{"id":"1.168224441","rc":[{"batb":[[0,1.66,12.26]],"ltp":1.66,"tv":8237.73,"id":2263634}]}]}
{"op":"mcm","clk":"1006354769","pt":1580647882695,"mc":[{"id":"1.168224441","rc":[{"batl":[[2,2.58,39.1]],"ltp":2.48,"tv":2895.05,"id":10894176}]}]}
{"op":"mcm","clk":"1006355433","pt":1580647887383,"mc":[{"id":"1.168224441","rc":[{"batb":[[0,1.66,4.69]],"ltp":1.66,"tv":8237.73,"id":2263634}]}]}
{"op":"mcm","clk":"1006355511","pt":1580647887907,"mc":[{"id":"1.168224441","rc":[{"batl":[[2,2.58,39.34]],"ltp":2.48,"tv":2895.05,"id":10894176}]}]}
{"op":"mcm","clk":"1006365704","pt":1580647963374,"mc":[{"id":"1.168224441","rc":[{"batb":[[0,2.46,8.89]],"ltp":2.48,"tv":2895.05,"id":10894176}]}]}
{"op":"mcm","clk":"1006365784","pt":1580647963851,"mc":[{"id":"1.168224441","rc":[{"batl":[[2,2.58,39.1]],"ltp":2.48,"tv":2895.05,"id":10894176}]}]}
{"op":"mcm","clk":"1006369449","pt":1580647990405,"mc":[{"id":"1.168224441","rc":[{"batb":[[1,2.44,5.35],[2,2.36,48.25]],"ltp":2.48,"tv":2895.05,"id":10894176},{"batl":[[0,1.67,303.91],[1,1.68,1.24],[2,1.69,15.04]],"ltp":1.66,"tv":8237.73,"id":2263634}]}]}
{"op":"mcm","clk":"1006369593","pt":1580647991374,"mc":[{"id":"1.168224441","rc":[{"batb":[[2,2.42,2.13]],"ltp":2.48,"tv":2895.05,"id":10894176},{"batb":[[0,1.65,4.69],[1,1.64,49.53],[2,1.63,6.8]],"batl":[[0,1.67,308.57],[1,1.68,5.88]],"ltp":1.66,"tv":8237.73,"id":2263634}]}]}
{"op":"mcm","clk":"1006369636","pt":1580647991704,"mc":[{"id":"1.168224441","rc":[{"batl":[[1,2.56,14.06]],"ltp":2.48,"tv":2895.05,"id":10894176},{"batb":[[1,1.64,47.46]],"ltp":1.66,"tv":8237.73,"id":2263634}]}]}
{"op":"mcm","clk":"1006369876","pt":1580647993204,"mc":[{"id":"1.168224441","rc":[{"batl":[[1,2.56,3.02],[2,2.58,41.6]],"ltp":2.48,"tv":2895.05,"id":10894176}]}]}
{"op":"mcm","clk":"1006370056","pt":1580647994382,"mc":[{"id":"1.168224441","rc":[{"batl":[[2,2.58,30.64]],"ltp":2.48,"tv":2895.05,"id":10894176}]}]}
{"op":"mcm","clk":"1006370214","pt":1580647995289,"mc":[{"id":"1.168224441","rc":[{"batb":[[0,2.5,5.6],[1,2.46,3.13],[2,2.44,5.35]],"batl":[[2,2.58,39.1]],"ltp":2.48,"tv":2895.05,"id":10894176},{"batl":[[2,1.69,6.63]],"ltp":1.66,"tv":8237.73,"id":2263634}]}]}
{"op":"mcm","clk":"1006370385","pt":1580647996444,"mc":[{"id":"1.168224441","rc":[{"batb":[[0,2.5,8.72],[1,2.48,3.14],[2,2.46,5.14]],"ltp":2.48,"tv":2895.05,"id":10894176}]}]}
{"op":"mcm","clk":"1006370499","pt":1580647997118,"mc":[{"id":"1.168224441","rc":[{"batl":[[2,2.58,30.64]],"ltp":2.48,"tv":2895.05,"id":10894176}]}]}
{"op":"mcm","clk":"1006372768","pt":1580648013132,"mc":[{"id":"1.168224441","rc":[{"batb":[[0,1.65,12.26]],"ltp":1.66,"tv":8237.73,"id":2263634}]}]}
{"op":"mcm","clk":"1006372903","pt":1580648014082,"mc":[{"id":"1.168224441","rc":[{"batb":[[0,1.65,4.69]],"ltp":1.66,"tv":8237.73,"id":2263634}]}]}
{"op":"mcm","clk":"1006374728","pt":1580648026328,"mc":[{"id":"1.168224441","rc":[{"batb":[[0,2.5,3.12]],"ltp":2.48,"tv":2895.05,"id":10894176}]}]}
{"op":"mcm","clk":"1006385864","pt":1580648103814,"mc":[{"id":"1.168224441","rc":[{"batb":[[0,1.65,12.26]],"ltp":1.66,"tv":8237.73,"id":2263634}]}]}
{"op":"mcm","clk":"1006386124","pt":1580648105330,"mc":[{"id":"1.168224441","rc":[{"batb":[[0,1.65,4.69]],"ltp":1.66,"tv":8237.73,"id":2263634}]}]}
{"op":"mcm","clk":"1006405328","pt":1580648244355,"mc":[{"id":"1.168224441","rc":[{"batb":[[0,1.66,200],[1,1.65,4.69],[2,1.64,47.46]],"ltp":1.66,"tv":8237.73,"id":2263634}]}]}
{"op":"mcm","clk":"1006405481","pt":1580648245430,"mc":[{"id":"1.168224441","rc":[{"trd":[[2.5,90.15]],"batb":[[0,2.48,3.14],[1,2.46,3.13],[2,2.44,5.35]],"batl":[[0,2.5,8.18],[1,2.54,5.07],[2,2.56,5.19]],"ltp":2.5,"tv":2901.29,"id":10894176},{"batb":[[2,1.64,49.53]],"ltp":1.66,"tv":8237.73,"id":2263634}],"tv":11139.02}]}
{"op":"mcm","clk":"1006405594","pt":1580648246369,"mc":[{"id":"1.168224441","rc":[{"batl":[[0,2.5,16.91],[1,2.52,3.1],[2,2.54,5.07]],"ltp":2.5,"tv":2901.29,"id":10894176},{"batb":[[0,1.66,211.24],[1,1.65,6.26],[2,1.64,42.92]],"batl":[[0,1.67,303.91]],"ltp":1.66,"tv":8237.73,"id":2263634}]}]}
{"op":"mcm","clk":"1006466681","pt":1580648707268,"mc":[{"id":"1.168224441","rc":[{"trd":[[2.5,123.98],[2.52,40.94]],"batl":[[0,2.54,3.06],[1,2.56,5.03],[2,2.58,5.24]],"ltp":2.52,"tv":2947.18,"id":10894176},{"trd":[[1.66,115.36]],"batb":[[0,1.66,202.33]],"ltp":1.66,"tv":8246.64,"id":2263634}],"tv":11193.83}]}
{"op":"mcm","clk":"1006466738","pt":1580648707642,"mc":[{"id":"1.168224441","rc":[{"batl":[[0,1.67,308.61]],"ltp":1.66,"tv":8246.64,"id":2263634}]}]}
{"op":"mcm","clk":"1006483752","pt":1580648825352,"mc":[{"id":"1.168224441","rc":[{"batl":[[2,2.58,2.99]],"ltp":2.52,"tv":2947.18,"id":10894176},{"trd":[[1.67,184.88]],"batb":[[2,1.64,42.14]],"batl":[[0,1.67,261.09]],"ltp":1.67,"tv":8341.72,"id":2263634}],"tv":11288.91}]}
{"op":"mcm","clk":"1006483878","pt":1580648826155,"mc":[{"id":"1.168224441","rc":[{"trd":[[2.48,12.61]],"batb":[[0,2.46,3.79],[1,2.44,5.19],[2,2.42,2.01]],"batl":[[2,2.58,5]],"ltp":2.48,"tv":2952.16,"id":10894176}],"tv":11293.88}]}
{"op":"mcm","clk":"1006483990","pt":1580648826852,"mc":[{"id":"1.168224441","rc":[{"batb":[[0,2.46,3.13],[1,2.44,5.35]],"ltp":2.48,"tv":2952.16,"id":10894176},{"batl":[[0,1.67,256.39]],"ltp":1.67,"tv":8341.72,"id":2263634}]}]}
{"op":"mcm","clk":"1006484359","pt":1580648829050,"mc":[{"id":"1.168224441","rc":[{"batb":[[1,2.44,3.18]],"ltp":2.48,"tv":2952.16,"id":10894176},{"trd":[[1.67,692.64]],"batl":[[0,1.67,2.64]],"ltp":1.67,"tv":8849.48,"id":2263634}],"tv":11801.64}]}
{"op":"mcm","clk":"1006492458","pt":1580648884808,"mc":[{"id":"1.168224441","rc":[{"batl":[[2,2.58,5.24]],"ltp":2.48,"tv":2952.16,"id":10894176}]}]}
{"op":"mcm","clk":"1006493621","pt":1580648892328,"mc":[{"id":"1.168224441","rc":[{"batb":[[2,1.64,44.55]],"ltp":1.67,"tv":8849.48,"id":2263634}]}]}
{"op":"mcm","clk":"1006493680","pt":1580648892730,"mc":[{"id":"1.168224441","rc":[{"batl":[[2,2.58,5]],"ltp":2.48,"tv":2952.16,"id":10894176}]}]}
{"op":"mcm","clk":"1006494306","pt":1580648897260,"mc":[{"id":"1.168224441","rc":[{"trd":[[1.67,697.92]],"batb":[[0,1.67,165.4],[1,1.66,202.33],[2,1.65,8.39]],"batl":[[0,1.68,5.88],[1,1.69,4.55],[2,1.7,6.61]],"ltp":1.67,"tv":8854.76,"id":2263634}],"tv":11806.92}]}
{"op":"mcm","clk":"1006494467","pt":1580648898236,"mc":[{"id":"1.168224441","rc":[{"batl":[[0,2.52,2.01],[1,2.54,5.07],[2,2.56,3.02]],"ltp":2.48,"tv":2952.16,"id":10894176},{"trd":[[1.68,2.49]],"batb":[[0,1.68,5.21],[1,1.67,165.4],[2,1.66,197.82]],"batl":[[0,1.69,4.55],[1,1.7,4.56],[2,1.71,2.12]],"ltp":1.68,"tv":8857.24,"id":2263634}],"tv":11809.41}]}
{"op":"mcm","clk":"1006494645","pt":1580648899331,"mc":[{"id":"1.168224441","rc":[{"batb":[[0,2.44,3.18],[1,2.42,3.27],[2,2.4,2.01]],"batl":[[0,2.52,5.14]],"ltp":2.48,"tv":2952.16,"id":10894176},{"batl":[[0,1.7,4.56],[1,1.71,4.92],[2,1.72,2.05]],"ltp":1.68,"tv":8857.24,"id":2263634}]}]}
{"op":"mcm","clk":"1006494680","pt":1580648899542,"mc":[{"id":"1.168224441","rc":[{"batb":[[1,1.67,166.65]],"ltp":1.68,"tv":8857.24,"id":2263634}]}]}
{"op":"mcm","clk":"1006494847","pt":1580648900847,"mc":[{"id":"1.168224441","rc":[{"batb":[[1,1.67,171.69]],"ltp":1.68,"tv":8857.24,"id":2263634}]}]}
{"op":"mcm","clk":"1006496370","pt":1580648912282,"mc":[{"id":"1.168224441","rc":[{"batb":[[1,1.67,6.28]],"ltp":1.68,"tv":8857.24,"id":2263634}]}]}
{"op":"mcm","clk":"1006496659","pt":1580648914274,"mc":[{"id":"1.168224441","rc":[{"batl":[[0,2.52,3.13],[2,2.56,5.03]],"ltp":2.48,"tv":2952.16,"id":10894176},{"batb":[[0,1.67,11.53],[1,1.66,195.8],[2,1.65,8.39]],"ltp":1.68,"tv":8857.24,"id":2263634}]}]}
{"op":"mcm","clk":"1006496757","pt":1580648914971,"mc":[{"id":"1.168224441","rc":[{"batb":[[0,2.44,9.01]],"ltp":2.48,"tv":2952.16,"id":10894176},{"batl":[[0,1.7,12.96]],"ltp":1.68,"tv":8857.24,"id":2263634}]}]}
{"op":"mcm","clk":"1006499287","pt":1580648933274,"mc":[{"id":"1.168224441","rc":[{"batl":[[0,1.69,2],[1,1.7,12.96],[2,1.71,4.92]],"ltp":1.68,"tv":8857.24,"id":2263634}]}]}
{"op":"mcm","clk":"1006499390","pt":1580648934190,"mc":[{"id":"1.168224441","rc":[{"batl":[[2,2.56,5.19]],"ltp":2.48,"tv":2952.16,"id":10894176},{"batl":[[0,1.69,6.68],[2,1.71,7.04]],"ltp":1.68,"tv":8857.24,"id":2263634}]}]}
{"op":"mcm","clk":"1006501143","pt":1580648946400,"mc":[{"id":"1.168224441","rc":[{"batb":[[0,2.44,3.18]],"batl":[[2,2.56,3.02]],"ltp":2.48,"tv":2952.16,"id":10894176},{"batl":[[1,1.7,4.56]],"ltp":1.68,"tv":8857.24,"id":2263634}]}]}
{"op":"mcm","clk":"1006501184","pt":1580648946721,"mc":[{"id":"1.168224441","rc":[{"batl":[[2,2.56,5.03]],"ltp":2.48,"tv":2952.16,"id":10894176}]}]}
