{"op":"mcm","clk":"1001177857","pt":1580585273658,"mc":[{"id":"1.168224445","marketDefinition":{"bspMarket":false,"turnInPlayEnabled":true,"persistenceEnabled":true,"marketBaseRate":5.0,"eventId":"29681727","eventTypeId":"2","numberOfWinners":1,"bettingType":"ODDS","marketType":"SET_BETTING","marketTime":"2020-02-02T15:00:00.000Z","suspendTime":"2020-02-02T15:00:00.000Z","bspReconciled":false,"complete":true,"inPlay":false,"crossMatching":false,"runnersVoidable":false,"numberOfActiveRunners":4,"betDelay":0,"status":"OPEN","runners":[{"status":"ACTIVE","sortPriority":1,"id":16569868,"name":"Benchetrit 2-0"},{"status":"ACTIVE","sortPriority":2,"id":16569870,"name":"Benchetrit 2-1"},{"status":"ACTIVE","sortPriority":3,"id":13117430,"name":"Lacko 2-0"},{"status":"ACTIVE","sortPriority":4,"id":13117431,"name":"Lacko 2-1"}],"regulators":["MR_INT"],"countryCode":"FR","discountAllowed":false,"timezone":"UTC","openDate":"2020-02-02T15:00:00.000Z","version":3147098565,"name":"Set Betting","eventName":"Benchetrit v Lacko"}}]}
{"op":"mcm","clk":"1001178215","pt":1580585275453,"mc":[{"id":"1.168224445","marketDefinition":{"bspMarket":false,"turnInPlayEnabled":true,"persistenceEnabled":true,"marketBaseRate":5.0,"eventId":"29681727","eventTypeId":"2","numberOfWinners":1,"bettingType":"ODDS","marketType":"SET_BETTING","marketTime":"2020-02-02T15:00:00.000Z","suspendTime":"2020-02-02T15:00:00.000Z","bspReconciled":false,"complete":true,"inPlay":false,"crossMatching":false,"runnersVoidable":false,"numberOfActiveRunners":4,"betDelay":0,"status":"OPEN","runners":[{"status":"ACTIVE","sortPriority":1,"id":16569868,"name":"Benchetrit 2-0"},{"status":"ACTIVE","sortPriority":2,"id":16569870,"name":"Benchetrit 2-1"},{"status":"ACTIVE","sortPriority":3,"id":13117430,"name":"Lacko 2-0"},{"status":"ACTIVE","sortPriority":4,"id":13117431,"name":"Lacko 2-1"}],"regulators":["MR_INT"],"countryCode":"FR","discountAllowed":true,"timezone":"UTC","openDate":"2020-02-02T15:00:00.000Z","version":3147098565,"name":"Set Betting","eventName":"Benchetrit v Lacko"}}]}
{"op":"mcm","clk":"1001666038","pt":1580587949371,"mc":[{"id":"1.168224445","rc":[{"batb":[[0,1.02,2]],"ltp":0.0,"tv":0.0,"id":13117431},{"batb":[[0,1.02,2]],"ltp":0.0,"tv":0.0,"id":13117430},{"batb":[[0,1.02,2]],"ltp":0.0,"tv":0.0,"id":16569868},{"batb":[[0,1.02,2]],"ltp":0.0,"tv":0.0,"id":16569870}]}]}
{"op":"mcm","clk":"1003033094","pt":1580602191259,"mc":[{"id":"1.168224445","rc":[{"batb":[[1,1.01,2.53]],"ltp":0.0,"tv":0.0,"id":13117431},{"batb":[[1,1.01,2.53]],"ltp":0.0,"tv":0.0,"id":13117430},{"batb":[[1,1.01,2.53]],"ltp":0.0,"tv":0.0,"id":16569868},{"batb":[[1,1.01,2.53]],"ltp":0.0,"tv":0.0,"id":16569870}]}]}
{"op":"mcm","clk":"1003033180","pt":1580602192292,"mc":[{"id":"1.168224445","rc":[{"batb":[[1,1.01,0.51]],"ltp":0.0,"tv":0.0,"id":13117431},{"batb":[[1,1.01,0.51]],"ltp":0.0,"tv":0.0,"id":13117430},{"batb":[[1,1.01,0.51]],"ltp":0.0,"tv":0.0,"id":16569868},{"batb":[[1,1.01,0.51]],"ltp":0.0,"tv":0.0,"id":16569870}]}]}
{"op":"mcm","clk":"1003160793","pt":1580603731415,"mc":[{"id":"1.168224445","rc":[{"batb":[[1,1.01,1.01]],"ltp":0.0,"tv":0.0,"id":13117431},{"batb":[[1,1.01,1.01]],"ltp":0.0,"tv":0.0,"id":13117430},{"batb":[[1,1.01,1.01]],"ltp":0.0,"tv":0.0,"id":16569868},{"batb":[[1,1.01,1.01]],"ltp":0.0,"tv":0.0,"id":16569870}]}]}
{"op":"mcm","clk":"1004449765","pt":1580630119139,"mc":[{"id":"1.168224445","rc":[{"batb":[[0,2.04,30.29],[1,1.02,2],[2,1.01,1.01]],"ltp":0.0,"tv":0.0,"id":13117430}]}]}
{"op":"mcm","clk":"1004494892","pt":1580631092661,"mc":[{"id":"1.168224445","rc":[{"batb":[[0,1.91,30.29]],"ltp":0.0,"tv":0.0,"id":13117430}]}]}
{"op":"mcm","clk":"1004823083","pt":1580637911163,"mc":[{"id":"1.168224445","rc":[{"batb":[[0,1.98,30.29]],"ltp":0.0,"tv":0.0,"id":13117430}]}]}
{"op":"mcm","clk":"1005834474","pt":1580645016455,"mc":[{"id":"1.168224445","rc":[{"batb":[[0,1.03,137],[1,1.02,2],[2,1.01,1.01]],"ltp":0.0,"tv":0.0,"id":13117431},{"batb":[[0,1.99,8],[1,1.98,30.29],[2,1.02,2]],"ltp":0.0,"tv":0.0,"id":13117430},{"batb":[[0,1.03,137],[1,1.02,2],[2,1.01,1.01]],"ltp":0.0,"tv":0.0,"id":16569868},{"batb":[[0,1.03,137],[1,1.02,2],[2,1.01,1.01]],"ltp":0.0,"tv":0.0,"id":16569870}]}]}
{"op":"mcm","clk":"1005835819","pt":1580645023640,"mc":[{"id":"1.168224445","marketDefinition":{"bspMarket":false,"turnInPlayEnabled":true,"persistenceEnabled":true,"marketBaseRate":5.0,"eventId":"29681727","eventTypeId":"2","numberOfWinners":1,"bettingType":"ODDS","marketType":"SET_BETTING","marketTime":"2020-02-02T15:00:00.000Z","suspendTime":"2020-02-02T15:00:00.000Z","bspReconciled":false,"complete":true,"inPlay":false,"crossMatching":true,"runnersVoidable":false,"numberOfActiveRunners":4,"betDelay":0,"status":"OPEN","runners":[{"status":"ACTIVE","sortPriority":1,"id":16569868,"name":"Benchetrit 2-0"},{"status":"ACTIVE","sortPriority":2,"id":16569870,"name":"Benchetrit 2-1"},{"status":"ACTIVE","sortPriority":3,"id":13117430,"name":"Lacko 2-0"},{"status":"ACTIVE","sortPriority":4,"id":13117431,"name":"Lacko 2-1"}],"regulators":["MR_INT"],"countryCode":"FR","discountAllowed":true,"timezone":"UTC","openDate":"2020-02-02T15:00:00.000Z","version":3147124901,"name":"Set Betting","eventName":"Benchetrit v Lacko"}}]}
{"op":"mcm","clk":"1005845995","pt":1580645077222,"mc":[{"id":"1.168224445","rc":[{"batl":[[0,5.1,4]],"ltp":0.0,"tv":0.0,"id":13117431},{"batl":[[0,2.84,6]],"ltp":0.0,"tv":0.0,"id":13117430},{"batl":[[0,4.2,5]],"ltp":0.0,"tv":0.0,"id":16569868},{"batl":[[0,5.9,4]],"ltp":0.0,"tv":0.0,"id":16569870}]}]}
{"op":"mcm","clk":"1005848403","pt":1580645091257,"mc":[{"id":"1.168224445","rc":[{"batb":[[0,2,30.29],[1,1.99,8]],"ltp":0.0,"tv":0.0,"id":13117430}]}]}
{"op":"mcm","clk":"1006044881","pt":1580646164164,"mc":[{"id":"1.168224445","rc":[{"batb":[[0,1.02,2],[1,1.01,1.01],[2,1.01,0]],"ltp":0.0,"tv":0.0,"id":13117431},{"batb":[[1,1.02,2],[2,1.01,1.01]],"ltp":0.0,"tv":0.0,"id":13117430},{"batb":[[0,1.02,2],[1,1.01,1.01],[2,1.01,0]],"ltp":0.0,"tv":0.0,"id":16569868},{"batb":[[0,1.02,2],[1,1.01,1.01],[2,1.01,0]],"ltp":0.0,"tv":0.0,"id":16569870}]}]}
{"op":"mcm","clk":"1006044959","pt":1580646164578,"mc":[{"id":"1.168224445","rc":[{"batb":[[0,1.03,137],[1,1.02,2],[2,1.01,1.01]],"ltp":0.0,"tv":0.0,"id":13117431},{"batb":[[0,2.02,7],[1,2,30.29],[2,1.02,2]],"ltp":0.0,"tv":0.0,"id":13117430},{"batb":[[0,1.03,137],[1,1.02,2],[2,1.01,1.01]],"ltp":0.0,"tv":0.0,"id":16569868},{"batb":[[0,1.03,137],[1,1.02,2],[2,1.01,1.01]],"ltp":0.0,"tv":0.0,"id":16569870}]}]}
{"op":"mcm","clk":"1006048781","pt":1580646187199,"mc":[{"id":"1.168224445","rc":[{"batb":[[1,1.98,30.29]],"ltp":0.0,"tv":0.0,"id":13117430}]}]}
{"op":"mcm","clk":"1006055629","pt":1580646226172,"mc":[{"id":"1.168224445","rc":[{"batl":[[0,2.78,6]],"ltp":0.0,"tv":0.0,"id":13117430},{"batl":[[0,4.3,5]],"ltp":0.0,"tv":0.0,"id":16569868},{"batl":[[0,6,4]],"ltp":0.0,"tv":0.0,"id":16569870}]}]}
{"op":"mcm","clk":"1006069843","pt":1580646308193,"mc":[{"id":"1.168224445","rc":[{"batb":[[0,2.04,30.29],[1,2.02,7]],"ltp":0.0,"tv":0.0,"id":13117430}]}]}
{"op":"mcm","clk":"1006117794","pt":1580646588438,"mc":[{"id":"1.168224445","rc":[{"batb":[[0,1.02,2],[1,1.01,1.01],[2,1.01,0]],"ltp":0.0,"tv":0.0,"id":16569868}]}]}
{"op":"mcm","clk":"1006117917","pt":1580646589135,"mc":[{"id":"1.168224445","rc":[{"batb":[[0,1.02,2],[1,1.01,1.01],[2,1.01,0]],"ltp":0.0,"tv":0.0,"id":13117431},{"batb":[[1,1.02,2],[2,1.01,1.01]],"ltp":0.0,"tv":0.0,"id":13117430},{"batb":[[0,1.02,2],[1,1.01,1.01],[2,1.01,0]],"ltp":0.0,"tv":0.0,"id":16569870}]}]}
{"op":"mcm","clk":"1006117987","pt":1580646589551,"mc":[{"id":"1.168224445","rc":[{"batb":[[0,1.04,104],[1,1.02,2],[2,1.01,1.01]],"ltp":0.0,"tv":0.0,"id":13117431},{"batb":[[0,2.06,7],[1,2.04,30.29],[2,1.02,2]],"ltp":0.0,"tv":0.0,"id":13117430},{"batb":[[0,1.03,137],[1,1.02,2],[2,1.01,1.01]],"ltp":0.0,"tv":0.0,"id":16569868},{"batb":[[0,1.03,137],[1,1.02,2],[2,1.01,1.01]],"ltp":0.0,"tv":0.0,"id":16569870}]}]}
{"op":"mcm","clk":"1006129084","pt":1580646651245,"mc":[{"id":"1.168224445","rc":[{"batl":[[0,2.72,6]],"ltp":0.0,"tv":0.0,"id":13117430},{"batl":[[0,4.5,5]],"ltp":0.0,"tv":0.0,"id":16569868},{"batl":[[0,6.2,4]],"ltp":0.0,"tv":0.0,"id":16569870}]}]}
{"op":"mcm","clk":"1006132828","pt":1580646673065,"mc":[{"id":"1.168224445","rc":[{"batb":[[0,2.08,30.29],[1,2.06,7]],"ltp":0.0,"tv":0.0,"id":13117430}]}]}
{"op":"mcm","clk":"1006196125","pt":1580647014395,"mc":[{"id":"1.168224445","rc":[{"batb":[[0,1.02,2],[1,1.01,1.01],[2,1.01,0]],"ltp":0.0,"tv":0.0,"id":13117431},{"batb":[[1,1.02,2],[2,1.01,1.01]],"ltp":0.0,"tv":0.0,"id":13117430},{"batb":[[0,1.02,2],[1,1.01,1.01],[2,1.01,0]],"ltp":0.0,"tv":0.0,"id":16569868},{"batb":[[0,1.02,2],[1,1.01,1.01],[2,1.01,0]],"ltp":0.0,"tv":0.0,"id":16569870}]}]}
{"op":"mcm","clk":"1006196557","pt":1580647016828,"mc":[{"id":"1.168224445","rc":[{"batb":[[0,1.03,137],[1,1.02,2],[2,1.01,1.01]],"ltp":0.0,"tv":0.0,"id":13117431},{"batb":[[0,2.1,7],[1,2.08,30.29],[2,1.02,2]],"ltp":0.0,"tv":0.0,"id":13117430},{"batb":[[0,1.03,137],[1,1.02,2],[2,1.01,1.01]],"ltp":0.0,"tv":0.0,"id":16569868},{"batb":[[0,1.03,137],[1,1.02,2],[2,1.01,1.01]],"ltp":0.0,"tv":0.0,"id":16569870}]}]}
{"op":"mcm","clk":"1006201125","pt":1580647039081,"mc":[{"id":"1.168224445","rc":[{"batb":[[1,1.98,30.29]],"ltp":0.0,"tv":0.0,"id":13117430}]}]}
{"op":"mcm","clk":"1006209038","pt":1580647078363,"mc":[{"id":"1.168224445","rc":[{"batl":[[0,5,5]],"ltp":0.0,"tv":0.0,"id":13117431},{"batl":[[0,2.66,6]],"ltp":0.0,"tv":0.0,"id":13117430},{"batl":[[0,4.5,5]],"ltp":0.0,"tv":0.0,"id":16569868},{"batl":[[0,6.2,4]],"ltp":0.0,"tv":0.0,"id":16569870}]}]}
{"op":"mcm","clk":"1006225685","pt":1580647160886,"mc":[{"id":"1.168224445","rc":[{"batb":[[0,2.12,30.29],[1,2.1,7]],"ltp":0.0,"tv":0.0,"id":13117430}]}]}
{"op":"mcm","clk":"1006281379","pt":1580647440293,"mc":[{"id":"1.168224445","rc":[{"batb":[[0,1.02,2],[1,1.01,1.01],[2,1.01,0]],"ltp":0.0,"tv":0.0,"id":13117431},{"batb":[[1,1.02,2],[2,1.01,1.01]],"ltp":0.0,"tv":0.0,"id":13117430},{"batb":[[0,1.02,2],[1,1.01,1.01],[2,1.01,0]],"ltp":0.0,"tv":0.0,"id":16569868},{"batb":[[0,1.02,2],[1,1.01,1.01],[2,1.01,0]],"ltp":0.0,"tv":0.0,"id":16569870}]}]}
{"op":"mcm","clk":"1006281468","pt":1580647440772,"mc":[{"id":"1.168224445","rc":[{"batb":[[0,1.04,104],[1,1.02,2],[2,1.01,1.01]],"ltp":0.0,"tv":0.0,"id":13117431},{"batb":[[0,2.14,7],[1,2.12,30.29],[2,1.02,2]],"ltp":0.0,"tv":0.0,"id":13117430},{"batb":[[0,1.03,137],[1,1.02,2],[2,1.01,1.01]],"ltp":0.0,"tv":0.0,"id":16569868},{"batb":[[0,1.03,137],[1,1.02,2],[2,1.01,1.01]],"ltp":0.0,"tv":0.0,"id":16569870}]}]}
{"op":"mcm","clk":"1006293513","pt":1580647502495,"mc":[{"id":"1.168224445","rc":[{"batl":[[0,2.62,6]],"ltp":0.0,"tv":0.0,"id":13117430},{"batl":[[0,4.7,5]],"ltp":0.0,"tv":0.0,"id":16569868},{"batl":[[0,6.6,4]],"ltp":0.0,"tv":0.0,"id":16569870}]}]}
{"op":"mcm","clk":"1006298115","pt":1580647525791,"mc":[{"id":"1.168224445","rc":[{"batb":[[1,1.02,2],[2,1.01,1.01]],"ltp":0.0,"tv":0.0,"id":13117430}]}]}
{"op":"mcm","clk":"1006501809","pt":1580648951328,"mc":[{"id":"1.168224445","rc":[{"batl":[[0,2.66,6]],"ltp":0.0,"tv":0.0,"id":13117430},{"batl":[[0,4.6,5]],"ltp":0.0,"tv":0.0,"id":16569868},{"batl":[[0,6.4,4]],"ltp":0.0,"tv":0.0,"id":16569870}]}]}
{"op":"mcm","clk":"1006766100","pt":1580650761419,"mc":[{"id":"1.168224445","rc":[{"batb":[[0,1.02,2],[1,1.01,1.01],[2,1.01,0]],"ltp":0.0,"tv":0.0,"id":13117431},{"batb":[[0,1.02,2],[1,1.01,1.01],[2,1.01,0]],"ltp":0.0,"tv":0.0,"id":13117430},{"batb":[[0,1.02,2],[1,1.01,1.01],[2,1.01,0]],"ltp":0.0,"tv":0.0,"id":16569868},{"batb":[[0,1.02,2],[1,1.01,1.01],[2,1.01,0]],"ltp":0.0,"tv":0.0,"id":16569870}]}]}
{"op":"mcm","clk":"1006766163","pt":1580650761825,"mc":[{"id":"1.168224445","rc":[{"batb":[[0,1.05,84],[1,1.02,2],[2,1.01,1.01]],"ltp":0.0,"tv":0.0,"id":13117431},{"batb":[[0,1.03,137],[1,1.02,2],[2,1.01,1.01]],"ltp":0.0,"tv":0.0,"id":13117430},{"batb":[[0,1.03,137],[1,1.02,2],[2,1.01,1.01]],"ltp":0.0,"tv":0.0,"id":16569868},{"batb":[[0,1.03,137],[1,1.02,2],[2,1.01,1.01]],"ltp":0.0,"tv":0.0,"id":16569870}]}]}
{"op":"mcm","clk":"1006775604","pt":1580650823675,"mc":[{"id":"1.168224445","rc":[{"batl":[[0,5.1,4]],"ltp":0.0,"tv":0.0,"id":13117431},{"batl":[[0,2.78,6]],"ltp":0.0,"tv":0.0,"id":13117430},{"batl":[[0,4.4,5]],"ltp":0.0,"tv":0.0,"id":16569868},{"batl":[[0,6,4]],"ltp":0.0,"tv":0.0,"id":16569870}]}]}
{"op":"mcm","clk":"1007003324","pt":1580652395167,"mc":[{"id":"1.168224445","rc":[{"batl":[[0,2.84,6]],"ltp":0.0,"tv":0.0,"id":13117430},{"batl":[[0,4.3,5]],"ltp":0.0,"tv":0.0,"id":16569868},{"batl":[[0,5.9,4]],"ltp":0.0,"tv":0.0,"id":16569870}]}]}
{"op":"mcm","clk":"1007045925","pt":1580652627912,"mc":[{"id":"1.168224445","rc":[{"batb":[[0,4.1,2],[1,1.05,84],[2,1.02,2]],"ltp":0.0,"tv":0.0,"id":13117431},{"batb":[[0,2.5,2],[1,1.03,137],[2,1.02,2]],"ltp":0.0,"tv":0.0,"id":13117430},{"batb":[[0,3.55,2],[1,1.03,137],[2,1.02,2]],"ltp":0.0,"tv":0.0,"id":16569868},{"batb":[[0,4.6,2],[1,1.03,137],[2,1.02,2]],"ltp":0.0,"tv":0.0,"id":16569870}]}]}
{"op":"mcm","clk":"1007069059","pt":1580652759297,"mc":[{"id":"1.168224445","rc":[{"batb":[[1,1.02,2],[2,1.01,1.01]],"ltp":0.0,"tv":0.0,"id":16569868}]}]}
{"op":"mcm","clk":"1007069252","pt":1580652760406,"mc":[{"id":"1.168224445","rc":[{"batb":[[1,1.02,2],[2,1.01,1.01]],"ltp":0.0,"tv":0.0,"id":13117431},{"batb":[[1,1.02,2],[2,1.01,1.01]],"ltp":0.0,"tv":0.0,"id":13117430},{"batb":[[1,1.02,2],[2,1.01,1.01]],"ltp":0.0,"tv":0.0,"id":16569870}]}]}
{"op":"mcm","clk":"1007069933","pt":1580652764600,"mc":[{"id":"1.168224445","rc":[{"batb":[[0,4.2,5],[1,4.1,2],[2,1.02,2]],"ltp":0.0,"tv":0.0,"id":13117431},{"batb":[[0,2.52,6],[1,2.5,2],[2,1.02,2]],"ltp":0.0,"tv":0.0,"id":13117430},{"batb":[[0,3.6,5],[1,3.55,2],[2,1.02,2]],"ltp":0.0,"tv":0.0,"id":16569868},{"batb":[[0,4.7,5],[1,4.6,2],[2,1.02,2]],"ltp":0.0,"tv":0.0,"id":16569870}]}]}
{"op":"mcm","clk":"1007081177","pt":1580652825372,"mc":[{"id":"1.168224445","rc":[{"batl":[[0,5.1,4]],"ltp":0.0,"tv":0.0,"id":13117431},{"batl":[[0,2.84,6]],"ltp":0.0,"tv":0.0,"id":13117430},{"batl":[[0,4.3,5]],"ltp":0.0,"tv":0.0,"id":16569868},{"batl":[[0,5.9,4]],"ltp":0.0,"tv":0.0,"id":16569870}]}]}
{"op":"mcm","clk":"1007149248","pt":1580653227424,"mc":[{"id":"1.168224445","rc":[{"batb":[[1,1.02,2],[2,1.01,1.01]],"ltp":0.0,"tv":0.0,"id":13117431},{"batb":[[1,1.02,2],[2,1.01,1.01]],"ltp":0.0,"tv":0.0,"id":13117430}]}]}
{"op":"mcm","clk":"1007149338","pt":1580653227964,"mc":[{"id":"1.168224445","rc":[{"batb":[[1,1.02,2],[2,1.01,1.01]],"ltp":0.0,"tv":0.0,"id":16569868},{"batb":[[1,1.02,2],[2,1.01,1.01]],"ltp":0.0,"tv":0.0,"id":16569870}]}]}
{"op":"mcm","clk":"1007151034","pt":1580653238373,"mc":[{"id":"1.168224445","rc":[{"batb":[[0,4.3,2],[1,4.2,5],[2,1.02,2]],"ltp":0.0,"tv":0.0,"id":13117431},{"batb":[[0,2.54,2],[1,2.52,6],[2,1.02,2]],"ltp":0.0,"tv":0.0,"id":13117430},{"batb":[[0,3.65,2],[1,3.6,5],[2,1.02,2]],"ltp":0.0,"tv":0.0,"id":16569868},{"batb":[[0,4.8,2],[1,4.7,5],[2,1.02,2]],"ltp":0.0,"tv":0.0,"id":16569870}]}]}
{"op":"mcm","clk":"1007247504","pt":1580653841156,"mc":[{"id":"1.168224445","rc":[{"batb":[[0,4.2,5],[1,1.02,2],[2,1.01,1.01]],"ltp":0.0,"tv":0.0,"id":13117431},{"batb":[[0,2.52,6],[1,1.02,2],[2,1.01,1.01]],"ltp":0.0,"tv":0.0,"id":13117430},{"batb":[[0,3.6,5],[1,1.02,2],[2,1.01,1.01]],"ltp":0.0,"tv":0.0,"id":16569868},{"batb":[[0,4.7,5],[1,1.02,2],[2,1.01,1.01]],"ltp":0.0,"tv":0.0,"id":16569870}]}]}
{"op":"mcm","clk":"1007247770","pt":1580653842990,"mc":[{"id":"1.168224445","rc":[{"batb":[[0,4.3,2],[1,4.2,5],[2,1.02,2]],"ltp":0.0,"tv":0.0,"id":13117431},{"batb":[[0,2.54,2],[1,2.52,6],[2,1.02,2]],"ltp":0.0,"tv":0.0,"id":13117430},{"batb":[[0,3.65,2],[1,3.6,5],[2,1.02,2]],"ltp":0.0,"tv":0.0,"id":16569868},{"batb":[[0,4.8,2],[1,4.7,5],[2,1.02,2]],"ltp":0.0,"tv":0.0,"id":16569870}]}]}
{"op":"mcm","clk":"1007268721","pt":1580653974352,"mc":[{"id":"1.168224445","rc":[{"batb":[[1,1.02,2],[2,1.01,1.01]],"ltp":0.0,"tv":0.0,"id":13117430},{"batb":[[1,1.02,2],[2,1.01,1.01]],"ltp":0.0,"tv":0.0,"id":16569868},{"batb":[[1,1.02,2],[2,1.01,1.01]],"ltp":0.0,"tv":0.0,"id":16569870}]}]}
{"op":"mcm","clk":"1007268812","pt":1580653974937,"mc":[{"id":"1.168224445","rc":[{"batb":[[0,4.4,5],[1,4.3,2]],"ltp":0.0,"tv":0.0,"id":13117431},{"batb":[[0,2.56,6],[1,2.54,2],[2,1.02,2]],"ltp":0.0,"tv":0.0,"id":13117430},{"batb":[[1,3.6,5],[2,1.02,2]],"ltp":0.0,"tv":0.0,"id":16569868},{"batb":[[0,4.9,5],[1,4.8,2],[2,1.02,2]],"ltp":0.0,"tv":0.0,"id":16569870}]}]}
{"op":"mcm","clk":"1007279158","pt":1580654036886,"mc":[{"id":"1.168224445","rc":[{"batl":[[0,5.2,4]],"ltp":0.0,"tv":0.0,"id":13117431},{"batl":[[0,2.94,6]],"ltp":0.0,"tv":0.0,"id":13117430},{"batl":[[0,4.1,5]],"ltp":0.0,"tv":0.0,"id":16569868}]}]}
{"op":"mcm","clk":"1007347223","pt":1580654442283,"mc":[{"id":"1.168224445","rc":[{"batb":[[1,1.02,2],[2,1.01,1.01]],"ltp":0.0,"tv":0.0,"id":13117430}]}]}
{"op":"mcm","clk":"1007347306","pt":1580654442795,"mc":[{"id":"1.168224445","rc":[{"batb":[[1,1.02,2],[2,1.01,1.01]],"ltp":0.0,"tv":0.0,"id":13117431},{"batb":[[0,3.6,5],[1,1.02,2],[2,1.01,1.01]],"ltp":0.0,"tv":0.0,"id":16569868},{"batb":[[1,1.02,2],[2,1.01,1.01]],"ltp":0.0,"tv":0.0,"id":16569870}]}]}
{"op":"mcm","clk":"1007349022","pt":1580654453787,"mc":[{"id":"1.168224445","rc":[{"batb":[[0,4.5,2],[1,4.4,5],[2,1.02,2]],"ltp":0.0,"tv":0.0,"id":13117431},{"batb":[[0,2.58,2],[1,2.56,6],[2,1.02,2]],"ltp":0.0,"tv":0.0,"id":13117430},{"batb":[[0,3.65,2],[1,3.6,5],[2,1.02,2]],"ltp":0.0,"tv":0.0,"id":16569868},{"batb":[[0,5,2],[1,4.9,5],[2,1.02,2]],"ltp":0.0,"tv":0.0,"id":16569870}]}]}
{"op":"mcm","clk":"1007396004","pt":1580654751275,"mc":[{"id":"1.168224445","rc":[{"trd":[[5,4]],"batb":[[0,4.9,5],[1,1.02,2],[2,1.01,1.01]],"batl":[[0,5,2.54],[1,5.9,4]],"ltp":5.0,"tv":3.99,"id":16569870}],"tv":3.99}]}
{"op":"mcm","clk":"1007396037","pt":1580654751448,"mc":[{"id":"1.168224445","rc":[{"trd":[[5,9.08]],"batl":[[0,5.9,4],[1,5.9,0]],"ltp":5.0,"tv":9.08,"id":16569870}],"tv":9.08}]}
{"op":"mcm","clk":"1007435967","pt":1580655053313,"mc":[{"id":"1.168224445","rc":[{"batb":[[0,4.4,5],[1,1.02,2],[2,1.01,1.01]],"ltp":0.0,"tv":0.0,"id":13117431},{"batb":[[0,2.56,6],[1,1.02,2],[2,1.01,1.01]],"ltp":0.0,"tv":0.0,"id":13117430},{"batb":[[0,3.6,5],[1,1.02,2],[2,1.01,1.01]],"ltp":0.0,"tv":0.0,"id":16569868}]}]}
{"op":"mcm","clk":"1007437735","pt":1580655068140,"mc":[{"id":"1.168224445","rc":[{"batb":[[0,4.5,2],[1,4.4,5],[2,1.02,2]],"ltp":0.0,"tv":0.0,"id":13117431},{"batb":[[0,2.58,2],[1,2.56,6],[2,1.02,2]],"ltp":0.0,"tv":0.0,"id":13117430},{"batb":[[0,3.65,2],[1,3.6,5],[2,1.02,2]],"ltp":0.0,"tv":0.0,"id":16569868}]}]}
{"op":"mcm","clk":"1007443321","pt":1580655113558,"mc":[{"id":"1.168224445","marketDefinition":{"bspMarket":false,"turnInPlayEnabled":true,"persistenceEnabled":true,"marketBaseRate":5.0,"eventId":"29681727","eventTypeId":"2","numberOfWinners":1,"bettingType":"ODDS","marketType":"SET_BETTING","marketTime":"2020-02-02T14:51:00.000Z","suspendTime":"2020-02-02T14:51:00.000Z","bspReconciled":false,"complete":true,"inPlay":false,"crossMatching":true,"runnersVoidable":false,"numberOfActiveRunners":4,"betDelay":0,"status":"OPEN","runners":[{"status":"ACTIVE","sortPriority":1,"id":16569868,"name":"Benchetrit 2-0"},{"status":"ACTIVE","sortPriority":2,"id":16569870,"name":"Benchetrit 2-1"},{"status":"ACTIVE","sortPriority":3,"id":13117430,"name":"Lacko 2-0"},{"status":"ACTIVE","sortPriority":4,"id":13117431,"name":"Lacko 2-1"}],"regulators":["MR_INT"],"countryCode":"FR","discountAllowed":true,"timezone":"UTC","openDate":"2020-02-02T15:00:00.000Z","version":3149300452,"name":"Set Betting","eventName":"Benchetrit v Lacko"}}]}
{"op":"mcm","clk":"1007443834","pt":1580655117578,"mc":[{"id":"1.168224445","marketDefinition":{"bspMarket":false,"turnInPlayEnabled":true,"persistenceEnabled":true,"marketBaseRate":5.0,"eventId":"29681727","eventTypeId":"2","numberOfWinners":1,"bettingType":"ODDS","marketType":"SET_BETTING","marketTime":"2020-02-02T14:51:00.000Z","suspendTime":"2020-02-02T14:51:00.000Z","bspReconciled":false,"complete":true,"inPlay":false,"crossMatching":true,"runnersVoidable":false,"numberOfActiveRunners":4,"betDelay":0,"status":"OPEN","runners":[{"status":"ACTIVE","sortPriority":1,"id":16569868,"name":"Benchetrit 2-0"},{"status":"ACTIVE","sortPriority":2,"id":16569870,"name":"Benchetrit 2-1"},{"status":"ACTIVE","sortPriority":3,"id":13117430,"name":"Lacko 2-0"},{"status":"ACTIVE","sortPriority":4,"id":13117431,"name":"Lacko 2-1"}],"regulators":["MR_INT"],"countryCode":"FR","discountAllowed":true,"timezone":"UTC","openDate":"2020-02-02T14:51:00.000Z","version":3149300452,"name":"Set Betting","eventName":"Benchetrit v Lacko"}}]}
{"op":"mcm","clk":"1007447209","pt":1580655147016,"mc":[{"id":"1.168224445","rc":[{"batb":[[1,4.4,23.25]],"batl":[[0,5.1,17.39],[1,5.2,4]],"ltp":0.0,"tv":0.0,"id":13117431},{"batb":[[0,2.84,10.62],[1,2.58,2],[2,2.56,6]],"batl":[[1,3.1,10.46]],"ltp":0.0,"tv":0.0,"id":13117430},{"batb":[[1,3.6,19.56]],"batl":[[0,4.1,19.08]],"ltp":0.0,"tv":0.0,"id":16569868},{"batb":[[0,4.9,18.77]],"batl":[[0,5.7,13.22],[1,5.9,4]],"ltp":5.0,"tv":9.08,"id":16569870}]}]}
{"op":"mcm","clk":"1007459644","pt":1580655247375,"mc":[{"id":"1.168224445","rc":[{"batb":[[0,4.4,23.25],[1,1.02,2],[2,1.01,1.01]],"ltp":0.0,"tv":0.0,"id":13117431}]}]}
{"op":"mcm","clk":"1007459702","pt":1580655247861,"mc":[{"id":"1.168224445","rc":[{"batb":[[1,2.56,6],[2,1.02,2]],"ltp":0.0,"tv":0.0,"id":13117430},{"batb":[[0,3.6,19.56],[1,1.02,2],[2,1.01,1.01]],"ltp":0.0,"tv":0.0,"id":16569868}]}]}
{"op":"mcm","clk":"1007460668","pt":1580655256288,"mc":[{"id":"1.168224445","rc":[{"batb":[[0,4.5,2],[1,4.4,23.25],[2,1.02,2]],"ltp":0.0,"tv":0.0,"id":13117431},{"batb":[[0,3.65,2],[1,3.6,19.56],[2,1.02,2]],"ltp":0.0,"tv":0.0,"id":16569868}]}]}
{"op":"mcm","clk":"1007477400","pt":1580655382238,"mc":[{"id":"1.168224445","rc":[{"batb":[[2,4.3,18.25]],"ltp":0.0,"tv":0.0,"id":13117431},{"batl":[[1,5.8,13.14],[2,5.9,4]],"ltp":5.0,"tv":9.08,"id":16569870}]}]}
{"op":"mcm","clk":"1007477432","pt":1580655382556,"mc":[{"id":"1.168224445","rc":[{"batb":[[1,4.4,5]],"ltp":0.0,"tv":0.0,"id":13117431},{"batl":[[0,5.8,13.14],[1,5.9,4],[2,5.9,0]],"ltp":5.0,"tv":9.08,"id":16569870}]}]}
{"op":"mcm","clk":"1007483503","pt":1580655435751,"mc":[{"id":"1.168224445","rc":[{"batb":[[0,4.4,5],[1,4.3,18.25],[2,1.02,2]],"ltp":0.0,"tv":0.0,"id":13117431},{"batb":[[0,3.6,19.56],[1,1.02,2],[2,1.01,1.01]],"ltp":0.0,"tv":0.0,"id":16569868}]}]}
{"op":"mcm","clk":"1007483712","pt":1580655437496,"mc":[{"id":"1.168224445","rc":[{"batb":[[0,4.5,2],[1,4.4,5],[2,4.3,18.25]],"ltp":0.0,"tv":0.0,"id":13117431},{"batb":[[0,3.65,2],[1,3.6,19.56],[2,1.02,2]],"ltp":0.0,"tv":0.0,"id":16569868}]}]}
{"op":"mcm","clk":"1007490910","pt":1580655497011,"mc":[{"id":"1.168224445","rc":[{"batb":[[0,4.4,5],[1,4.3,18.25],[2,1.02,2]],"ltp":0.0,"tv":0.0,"id":13117431},{"batb":[[0,3.6,19.56],[1,1.02,2],[2,1.01,1.01]],"ltp":0.0,"tv":0.0,"id":16569868}]}]}
{"op":"mcm","clk":"1007492979","pt":1580655514233,"mc":[{"id":"1.168224445","rc":[{"batb":[[0,4.5,2],[1,4.4,5],[2,4.3,18.25]],"ltp":0.0,"tv":0.0,"id":13117431},{"batb":[[0,3.65,2],[1,3.6,19.56],[2,1.02,2]],"ltp":0.0,"tv":0.0,"id":16569868}]}]}
{"op":"mcm","clk":"1007500123","pt":1580655573677,"mc":[{"id":"1.168224445","rc":[{"batb":[[0,4.4,5],[1,4.3,18.25],[2,1.02,2]],"ltp":0.0,"tv":0.0,"id":13117431},{"batb":[[0,3.6,19.56],[1,1.02,2],[2,1.01,1.01]],"ltp":0.0,"tv":0.0,"id":16569868}]}]}
{"op":"mcm","clk":"1007502030","pt":1580655591008,"mc":[{"id":"1.168224445","rc":[{"batb":[[0,4.5,2],[1,4.4,5],[2,4.3,18.25]],"ltp":0.0,"tv":0.0,"id":13117431},{"batb":[[0,3.65,2],[1,3.6,19.56],[2,1.02,2]],"ltp":0.0,"tv":0.0,"id":16569868}]}]}
{"op":"mcm","clk":"1007510856","pt":1580655650264,"mc":[{"id":"1.168224445","rc":[{"batb":[[0,3.6,19.56],[1,1.02,2],[2,1.01,1.01]],"ltp":0.0,"tv":0.0,"id":16569868}]}]}
{"op":"mcm","clk":"1007510882","pt":1580655650476,"mc":[{"id":"1.168224445","rc":[{"batb":[[0,4.4,5],[1,4.3,18.25],[2,1.02,2]],"ltp":0.0,"tv":0.0,"id":13117431}]}]}
{"op":"mcm","clk":"1007512689","pt":1580655662795,"mc":[{"id":"1.168224445","rc":[{"batb":[[0,4.5,2],[1,4.4,5],[2,4.3,18.25]],"ltp":0.0,"tv":0.0,"id":13117431},{"batb":[[0,3.65,2],[1,3.6,19.56],[2,1.02,2]],"ltp":0.0,"tv":0.0,"id":16569868}]}]}
{"op":"mcm","clk":"1007522607","pt":1580655722198,"mc":[{"id":"1.168224445","rc":[{"batb":[[0,4.4,5],[1,4.3,18.25],[2,1.02,2]],"ltp":0.0,"tv":0.0,"id":13117431},{"batb":[[0,3.6,19.56],[1,1.02,2],[2,1.01,1.01]],"ltp":0.0,"tv":0.0,"id":16569868}]}]}
{"op":"mcm","clk":"1007525054","pt":1580655735930,"mc":[{"id":"1.168224445","rc":[{"batb":[[0,4.5,2],[1,4.4,5],[2,4.3,18.25]],"ltp":0.0,"tv":0.0,"id":13117431},{"batb":[[0,3.65,2],[1,3.6,19.56],[2,1.02,2]],"ltp":0.0,"tv":0.0,"id":16569868}]}]}
{"op":"mcm","clk":"1007536166","pt":1580655795326,"mc":[{"id":"1.168224445","rc":[{"batb":[[0,4.4,5],[1,4.3,18.25],[2,1.02,2]],"ltp":0.0,"tv":0.0,"id":13117431},{"batb":[[0,3.6,19.56],[1,1.02,2],[2,1.01,1.01]],"ltp":0.0,"tv":0.0,"id":16569868}]}]}
{"op":"mcm","clk":"1007539154","pt":1580655810706,"mc":[{"id":"1.168224445","rc":[{"batb":[[0,4.5,2],[1,4.4,5],[2,4.3,18.25]],"ltp":0.0,"tv":0.0,"id":13117431},{"batb":[[0,3.65,2],[1,3.6,19.56],[2,1.02,2]],"ltp":0.0,"tv":0.0,"id":16569868}]}]}
{"op":"mcm","clk":"1007550752","pt":1580655870214,"mc":[{"id":"1.168224445","rc":[{"batb":[[0,4.4,5],[1,4.3,18.25],[2,1.02,2]],"ltp":0.0,"tv":0.0,"id":13117431},{"batb":[[0,3.6,19.56],[1,1.02,2],[2,1.01,1.01]],"ltp":0.0,"tv":0.0,"id":16569868}]}]}
{"op":"mcm","clk":"1007552140","pt":1580655876896,"mc":[{"id":"1.168224445","rc":[{"batb":[[0,4.5,11.76],[1,4.4,5],[2,4.3,18.25]],"batl":[[2,5.4,9.24]],"ltp":0.0,"tv":0.0,"id":13117431},{"batb":[[1,2.7,24.37],[2,2.56,6]],"batl":[[1,3.1,29.79]],"ltp":0.0,"tv":0.0,"id":13117430},{"batb":[[1,3.5,16.8],[2,1.02,2]],"batl":[[0,4.1,32.53]],"ltp":0.0,"tv":0.0,"id":16569868},{"batb":[[0,4.9,28.85]],"batl":[[2,6,8.4]],"ltp":5.0,"tv":9.08,"id":16569870}]}]}
{"op":"mcm","clk":"1007554172","pt":1580655887340,"mc":[{"id":"1.168224445","rc":[{"batb":[[0,4.6,2],[1,4.5,11.76],[2,4.4,5]],"ltp":0.0,"tv":0.0,"id":13117431},{"batb":[[0,3.65,2],[1,3.6,19.56],[2,3.5,16.8]],"ltp":0.0,"tv":0.0,"id":16569868}]}]}
{"op":"mcm","clk":"1007566466","pt":1580655946868,"mc":[{"id":"1.168224445","rc":[{"batb":[[0,4.5,11.76],[1,4.4,5],[2,4.3,18.25]],"ltp":0.0,"tv":0.0,"id":13117431},{"batb":[[0,3.6,19.56],[1,3.5,16.8],[2,1.02,2]],"ltp":0.0,"tv":0.0,"id":16569868}]}]}
{"op":"mcm","clk":"1007571043","pt":1580655969412,"mc":[{"id":"1.168224445","rc":[{"batl":[[1,4.3,1.68]],"ltp":0.0,"tv":0.0,"id":16569868}]}]}
{"op":"mcm","clk":"1007574379","pt":1580655985014,"mc":[{"id":"1.168224445","rc":[{"batl":[[1,4.5,1.68]],"ltp":0.0,"tv":0.0,"id":16569868}]}]}
{"op":"mcm","clk":"1007587556","pt":1580656047607,"mc":[{"id":"1.168224445","rc":[{"batl":[[1,4.2,1.68]],"ltp":0.0,"tv":0.0,"id":16569868}]}]}
{"op":"mcm","clk":"1007608076","pt":1580656137407,"mc":[{"id":"1.168224445","marketDefinition":{"bspMarket":false,"turnInPlayEnabled":true,"persistenceEnabled":true,"marketBaseRate":5.0,"eventId":"29681727","eventTypeId":"2","numberOfWinners":1,"bettingType":"ODDS","marketType":"SET_BETTING","marketTime":"2020-02-02T14:51:00.000Z","suspendTime":"2020-02-02T14:51:00.000Z","bspReconciled":false,"complete":true,"inPlay":false,"crossMatching":true,"runnersVoidable":false,"numberOfActiveRunners":4,"betDelay":0,"status":"OPEN","runners":[{"status":"ACTIVE","sortPriority":1,"id":16569868,"name":"Benchetrit 2-0"},{"status":"ACTIVE","sortPriority":2,"id":16569870,"name":"Benchetrit 2-1"},{"status":"ACTIVE","sortPriority":3,"id":13117430,"name":"Lacko 2-0"},{"status":"ACTIVE","sortPriority":4,"id":13117431,"name":"Lacko 2-1"}],"regulators":["MR_INT"],"countryCode":"FR","discountAllowed":true,"timezone":"UTC","openDate":"2020-02-02T14:51:00.000Z","version":3149300452,"name":"Set Betting","eventName":"Benchetrit v Lacko"},"rc":[{"batb":[[2,1.02,2]],"batl":[[0,5.2,4],[1,5.4,9.24],[2,5.4,0]],"ltp":0.0,"tv":0.0,"id":13117431},{"batb":[[0,2.7,24.37],[1,2.56,6],[2,1.02,2]],"batl":[[1,3.1,19.32]],"ltp":0.0,"tv":0.0,"id":13117430},{"batb":[[0,3.6,5]],"batl":[[0,4.1,18.44]],"ltp":0.0,"tv":0.0,"id":16569868},{"batb":[[0,4.9,15.08]],"batl":[[0,5.9,4],[1,6,8.4],[2,6,0]],"ltp":5.0,"tv":9.08,"id":16569870}]}]}
{"op":"mcm","clk":"1007608091","pt":1580656137501,"mc":[{"id":"1.168224445","marketDefinition":{"bspMarket":false,"turnInPlayEnabled":true,"persistenceEnabled":true,"marketBaseRate":5.0,"eventId":"29681727","eventTypeId":"2","numberOfWinners":1,"bettingType":"ODDS","marketType":"SET_BETTING","marketTime":"2020-02-02T14:51:00.000Z","suspendTime":"2020-02-02T14:51:00.000Z","bspReconciled":false,"complete":true,"inPlay":true,"crossMatching":true,"runnersVoidable":false,"numberOfActiveRunners":4,"betDelay":3,"status":"OPEN","runners":[{"status":"ACTIVE","sortPriority":1,"id":16569868,"name":"Benchetrit 2-0"},{"status":"ACTIVE","sortPriority":2,"id":16569870,"name":"Benchetrit 2-1"},{"status":"ACTIVE","sortPriority":3,"id":13117430,"name":"Lacko 2-0"},{"status":"ACTIVE","sortPriority":4,"id":13117431,"name":"Lacko 2-1"}],"regulators":["MR_INT"],"countryCode":"FR","discountAllowed":true,"timezone":"UTC","openDate":"2020-02-02T14:51:00.000Z","version":3149404530,"name":"Set Betting","eventName":"Benchetrit v Lacko"},"rc":[{"batb":[[0,1.01,0.51],[1,4.4,0],[2,1.02,0]],"ltp":0.0,"tv":0.0,"id":13117431},{"batb":[[0,1.01,0.51],[1,2.56,0],[2,1.02,0]],"ltp":0.0,"tv":0.0,"id":13117430},{"batb":[[0,1.01,0.51],[1,3.5,0],[2,1.02,0]],"ltp":0.0,"tv":0.0,"id":16569868},{"batb":[[0,1.01,0.51],[1,1.02,0],[2,1.01,0]],"ltp":5.0,"tv":9.08,"id":16569870}]}]}
{"op":"mcm","clk":"1007609996","pt":1580656145324,"mc":[{"id":"1.168224445","rc":[{"batb":[[0,4.4,11.76],[1,4.3,18.88],[2,1.01,0.51]],"batl":[[0,5,17.55],[1,5.4,9.24]],"ltp":0.0,"tv":0.0,"id":13117431},{"batb":[[0,2.98,23.45],[1,2.82,22.69],[2,2.76,11.41]],"batl":[[0,3.3,40.23],[1,3.5,19.99]],"ltp":0.0,"tv":0.0,"id":13117430},{"batb":[[0,3.4,16.76],[1,3.25,37.45],[2,1.01,0.51]],"batl":[[0,3.8,16.21],[1,3.85,14.28],[2,4.2,12.9]],"ltp":0.0,"tv":0.0,"id":16569868},{"batb":[[0,4.9,23.69],[1,1.01,0.51]],"batl":[[0,5.8,13.06],[1,5.9,8.4]],"ltp":5.0,"tv":9.08,"id":16569870}]}]}
{"op":"mcm","clk":"1007611711","pt":1580656152308,"mc":[{"id":"1.168224445","rc":[{"batb":[[1,4.3,78.87],[2,4.2,47.37]],"ltp":0.0,"tv":0.0,"id":13117431},{"batb":[[0,3.65,33.75],[1,3.4,16.76],[2,3.25,37.45]],"ltp":0.0,"tv":0.0,"id":16569868},{"batb":[[0,5.2,29.56],[1,4.9,23.69],[2,1.01,0.51]],"ltp":5.0,"tv":9.08,"id":16569870}]}]}
{"op":"mcm","clk":"1007612160","pt":1580656154204,"mc":[{"id":"1.168224445","rc":[{"batb":[[0,4.3,78.87],[1,4.2,47.37],[2,1.01,0.51]],"batl":[[1,5.4,0]],"ltp":0.0,"tv":0.0,"id":13117431},{"batb":[[0,2.76,11.41],[1,1.01,0.51],[2,2.76,0]],"batl":[[0,3.5,19.99],[1,3.5,0]],"ltp":0.0,"tv":0.0,"id":13117430},{"batb":[[0,3.25,18.96],[1,1.01,0.51],[2,3.25,0]],"batl":[[0,4.2,12.9],[1,3.85,0],[2,4.2,0]],"ltp":0.0,"tv":0.0,"id":16569868},{"batb":[[1,4.9,13.61]],"batl":[[1,5.9,0]],"ltp":5.0,"tv":9.08,"id":16569870}]}]}
{"op":"mcm","clk":"1007612473","pt":1580656155445,"mc":[{"id":"1.168224445","rc":[{"batb":[[0,5.2,33.43],[1,5.1,30.42],[2,4.9,13.61]],"ltp":5.0,"tv":9.08,"id":16569870}]}]}
{"op":"mcm","clk":"1007612873","pt":1580656157127,"mc":[{"id":"1.168224445","rc":[{"batb":[[1,2.68,58.39],[2,2.64,60.77]],"ltp":0.0,"tv":0.0,"id":13117430},{"batb":[[0,3.5,35.54],[1,3.45,38.5],[2,3.25,18.96]],"ltp":0.0,"tv":0.0,"id":16569868}]}]}
{"op":"mcm","clk":"1007613090","pt":1580656158009,"mc":[{"id":"1.168224445","rc":[{"batb":[[0,4.3,64.42],[1,1.01,0.51],[2,1.01,0]],"ltp":0.0,"tv":0.0,"id":13117431},{"batb":[[1,1.01,0.51],[2,2.64,0]],"ltp":0.0,"tv":0.0,"id":13117430},{"batb":[[0,3.25,18.96],[1,1.01,0.51],[2,3.25,0]],"ltp":0.0,"tv":0.0,"id":16569868}]}]}
{"op":"mcm","clk":"1007614150","pt":1580656162210,"mc":[{"id":"1.168224445","rc":[{"batb":[[0,4.4,25.8],[1,4.3,64.42],[2,1.01,0.51]],"ltp":0.0,"tv":0.0,"id":13117431},{"batb":[[0,2.86,54.48],[1,2.82,51.2],[2,2.76,11.41]],"ltp":0.0,"tv":0.0,"id":13117430},{"batb":[[0,3.75,31.75],[1,3.7,32.56],[2,3.25,18.96]],"ltp":0.0,"tv":0.0,"id":16569868},{"batb":[[0,5.2,44.93]],"ltp":5.0,"tv":9.08,"id":16569870}]}]}
{"op":"mcm","clk":"1007614473","pt":1580656163735,"mc":[{"id":"1.168224445","rc":[{"batb":[[0,4.3,64.42],[1,1.01,0.51],[2,1.01,0]],"ltp":0.0,"tv":0.0,"id":13117431},{"batb":[[0,2.76,11.41],[1,1.01,0.51],[2,2.76,0]],"ltp":0.0,"tv":0.0,"id":13117430},{"batb":[[0,3.25,18.96],[1,1.01,0.51],[2,3.25,0]],"ltp":0.0,"tv":0.0,"id":16569868},{"batb":[[0,5.2,33.43]],"ltp":5.0,"tv":9.08,"id":16569870}]}]}
{"op":"mcm","clk":"1007615112","pt":1580656166542,"mc":[{"id":"1.168224445","rc":[{"batb":[[0,4.3,73.87],[1,4.2,47.59],[2,1.01,0.51]],"ltp":0.0,"tv":0.0,"id":13117431},{"batb":[[1,2.68,58.39],[2,2.64,60.77]],"ltp":0.0,"tv":0.0,"id":13117430},{"batb":[[0,3.5,35.54],[1,3.45,38.5],[2,3.25,18.96]],"ltp":0.0,"tv":0.0,"id":16569868}]}]}
{"op":"mcm","clk":"1007615833","pt":1580656169818,"mc":[{"id":"1.168224445","rc":[{"batb":[[1,1.01,0.51],[2,2.64,0]],"ltp":0.0,"tv":0.0,"id":13117430}]}]}
{"op":"mcm","clk":"1007616592","pt":1580656173182,"mc":[{"id":"1.168224445","rc":[{"batb":[[0,4.4,11.76],[1,4.3,73.87],[2,4.2,47.59]],"batl":[[1,5.3,9.24]],"ltp":0.0,"tv":0.0,"id":13117431},{"batb":[[0,3.05,54.94],[1,3,54.47],[2,2.98,21]],"batl":[[0,3.5,36.79]],"ltp":0.0,"tv":0.0,"id":13117430},{"batb":[[0,3.45,38.5],[1,3.25,18.96],[2,3.1,19.32]],"batl":[[0,3.65,15.12],[1,4.2,12.9]],"ltp":0.0,"tv":0.0,"id":16569868},{"batb":[[0,5.2,29.56]],"batl":[[1,5.9,8.4]],"ltp":5.0,"tv":9.08,"id":16569870}]}]}
{"op":"mcm","clk":"1007616772","pt":1580656173848,"mc":[{"id":"1.168224445","rc":[{"batb":[[0,3.1,20.69],[1,3.05,54.94],[2,3,54.47]],"batl":[[1,3.65,18.02]],"ltp":0.0,"tv":0.0,"id":13117430},{"batb":[[2,3.1,40.1]],"batl":[[0,3.6,18.33],[1,3.65,15.12],[2,3.9,15.42]],"ltp":0.0,"tv":0.0,"id":16569868}]}]}
{"op":"mcm","clk":"1007617350","pt":1580656176206,"mc":[{"id":"1.168224445","rc":[{"batb":[[1,4.3,83.51]],"ltp":0.0,"tv":0.0,"id":13117431},{"batb":[[1,3.05,70.39]],"ltp":0.0,"tv":0.0,"id":13117430},{"batb":[[0,3.45,59.67],[1,3.4,39.53],[2,3.25,18.96]],"ltp":0.0,"tv":0.0,"id":16569868}]}]}
{"op":"mcm","clk":"1007619400","pt":1580656184560,"mc":[{"id":"1.168224445","rc":[{"batb":[[0,2.98,21],[1,2.92,24.63],[2,1.01,0.51]],"batl":[[0,3.5,16.8]],"ltp":0.0,"tv":0.0,"id":13117430},{"batb":[[0,3.1,40.1],[1,1.01,0.51],[2,3.25,0]],"batl":[[0,3.65,15.12],[1,3.9,15.42],[2,3.9,0]],"ltp":0.0,"tv":0.0,"id":16569868},{"batb":[[0,5.1,30.42],[1,4.9,13.61],[2,4.8,10.92]],"ltp":5.0,"tv":9.08,"id":16569870}]}]}
{"op":"mcm","clk":"1007619841","pt":1580656186270,"mc":[{"id":"1.168224445","rc":[{"batb":[[0,4.3,83.51],[1,4.2,47.59],[2,1.01,0.51]],"batl":[[1,5.3,0]],"ltp":0.0,"tv":0.0,"id":13117431},{"batb":[[0,2.92,24.63],[1,1.01,0.51],[2,1.01,0]],"batl":[[0,3.65,18.02],[1,3.65,0]],"ltp":0.0,"tv":0.0,"id":13117430},{"batb":[[0,3.1,20.77]],"batl":[[0,3.9,15.42],[1,3.9,0]],"ltp":0.0,"tv":0.0,"id":16569868},{"batb":[[2,1.01,0.51]],"batl":[[1,5.9,0]],"ltp":5.0,"tv":9.08,"id":16569870}]}]}
{"op":"mcm","clk":"1007620232","pt":1580656187803,"mc":[{"id":"1.168224445","rc":[{"batb":[[0,3.35,48.67],[1,3.3,42.65],[2,3.1,20.77]],"ltp":0.0,"tv":0.0,"id":16569868},{"batb":[[0,5.1,48.31],[1,5,31.57],[2,4.9,13.61]],"ltp":5.0,"tv":9.08,"id":16569870}]}]}
{"op":"mcm","clk":"1007620639","pt":1580656189349,"mc":[{"id":"1.168224445","rc":[{"batb":[[0,3.15,78.85],[1,3.1,50.08],[2,2.92,24.63]],"ltp":0.0,"tv":0.0,"id":13117430}]}]}
{"op":"mcm","clk":"1007620845","pt":1580656190271,"mc":[{"id":"1.168224445","rc":[{"batb":[[0,4.3,64.79],[1,1.01,0.51],[2,1.01,0]],"ltp":0.0,"tv":0.0,"id":13117431},{"batb":[[0,3.25,18.65],[1,3.15,48.56],[2,3.1,21.32]],"batl":[[1,3.75,16.84]],"ltp":0.0,"tv":0.0,"id":13117430},{"batb":[[0,3.35,30.91]],"batl":[[0,3.5,20.06],[1,3.7,17.55]],"ltp":0.0,"tv":0.0,"id":16569868},{"batb":[[0,5.1,38.13]],"ltp":5.0,"tv":9.08,"id":16569870}]}]}
{"op":"mcm","clk":"1007621042","pt":1580656191172,"mc":[{"id":"1.168224445","rc":[{"batb":[[0,4.5,11.76],[1,4.3,64.79],[2,1.01,0.51]],"batl":[[1,5.4,9.24]],"ltp":0.0,"tv":0.0,"id":13117431},{"batb":[[2,3.1,40.65]],"batl":[[0,3.65,33.14]],"ltp":0.0,"tv":0.0,"id":13117430},{"batl":[[0,3.5,36.87]],"ltp":0.0,"tv":0.0,"id":16569868},{"batl":[[0,5.8,21.46]],"ltp":5.0,"tv":9.08,"id":16569870}]}]}
{"op":"mcm","clk":"1007621606","pt":1580656193444,"mc":[{"id":"1.168224445","rc":[{"batb":[[1,4.4,24.52],[2,4.3,64.79]],"ltp":0.0,"tv":0.0,"id":13117431},{"batb":[[1,3.2,47.29],[2,3.15,48.56]],"ltp":0.0,"tv":0.0,"id":13117430}]}]}
{"op":"mcm","clk":"1007623570","pt":1580656201395,"mc":[{"id":"1.168224445","rc":[{"batb":[[0,3.1,40.65],[1,1.01,0.51],[2,3.15,0]],"batl":[[0,3.65,15.12]],"ltp":0.0,"tv":0.0,"id":13117430},{"batb":[[0,3.05,22.03],[1,3,21],[2,1.01,0.51]],"batl":[[0,3.5,16.8]],"ltp":0.0,"tv":0.0,"id":16569868}]}]}
{"op":"mcm","clk":"1007623784","pt":1580656202271,"mc":[{"id":"1.168224445","rc":[{"batb":[[0,4.4,24.52],[1,4.3,64.79],[2,1.01,0.51]],"batl":[[1,5.4,0]],"ltp":0.0,"tv":0.0,"id":13117431},{"batb":[[0,3.1,21.32]],"batl":[[0,3.75,16.84],[1,3.75,0]],"ltp":0.0,"tv":0.0,"id":13117430},{"batb":[[1,1.01,0.51],[2,1.01,0]],"batl":[[0,3.7,17.55],[1,3.7,0]],"ltp":0.0,"tv":0.0,"id":16569868},{"batl":[[0,5.8,13.06]],"ltp":5.0,"tv":9.08,"id":16569870}]}]}
{"op":"mcm","clk":"1007624267","pt":1580656204413,"mc":[{"id":"1.168224445","rc":[{"batb":[[1,3.05,69.15],[2,3,54.67]],"ltp":0.0,"tv":0.0,"id":13117430},{"batb":[[0,3.25,57.27],[1,3.2,45.76],[2,3.05,22.03]],"ltp":0.0,"tv":0.0,"id":16569868}]}]}
{"op":"mcm","clk":"1007624998","pt":1580656207386,"mc":[{"id":"1.168224445","rc":[{"batb":[[0,3.05,22.03],[1,1.01,0.51],[2,3.05,0]],"ltp":0.0,"tv":0.0,"id":16569868},{"batb":[[0,5.1,30.47],[1,4.9,13.61],[2,1.01,0.51]],"ltp":5.0,"tv":9.08,"id":16569870}]}]}
{"op":"mcm","clk":"1007625578","pt":1580656209921,"mc":[{"id":"1.168224445","rc":[{"batb":[[0,3.45,61.2],[1,3.4,39.36],[2,3.05,22.03]],"ltp":0.0,"tv":0.0,"id":16569868},{"batb":[[0,5.2,19.68],[1,5.1,30.47],[2,4.9,13.61]],"ltp":5.0,"tv":9.08,"id":16569870}]}]}
{"op":"mcm","clk":"1007625909","pt":1580656211247,"mc":[{"id":"1.168224445","rc":[{"batb":[[0,4.4,36.28],[1,4.3,45.91],[2,4.2,19.43]],"batl":[[0,4.9,18.33],[1,5,17.55],[2,5.3,9.24]],"ltp":0.0,"tv":0.0,"id":13117431},{"batl":[[0,3.45,37.34],[1,3.55,18.88]],"ltp":0.0,"tv":0.0,"id":13117430},{"batb":[[2,3.3,18.1]],"batl":[[0,3.7,32.67],[1,3.95,14.71]],"ltp":0.0,"tv":0.0,"id":16569868},{"batb":[[0,5.1,30.47],[1,4.9,23.69],[2,1.01,0.51]],"batl":[[1,5.9,8.4]],"ltp":5.0,"tv":9.08,"id":16569870}]}]}
{"op":"mcm","clk":"1007626560","pt":1580656213802,"mc":[{"id":"1.168224445","rc":[{"batb":[[0,5.1,50.05],[1,5,31.38],[2,4.9,23.69]],"ltp":5.0,"tv":9.08,"id":16569870}]}]}
{"op":"mcm","clk":"1007630157","pt":1580656228229,"mc":[{"id":"1.168224445","rc":[{"batb":[[0,4.3,45.91],[1,4.2,19.43],[2,1.01,0.51]],"batl":[[0,5,17.55],[1,5,0],[2,5.3,0]],"ltp":0.0,"tv":0.0,"id":13117431},{"batb":[[0,2.88,10.31],[1,1.01,0.51],[2,3,0]],"batl":[[0,3.55,18.88],[1,3.55,0]],"ltp":0.0,"tv":0.0,"id":13117430},{"batb":[[0,3.15,19.83],[1,1.01,0.51],[2,3.3,0]],"batl":[[0,3.95,14.71],[1,3.95,0]],"ltp":0.0,"tv":0.0,"id":16569868},{"batb":[[0,5.1,42.42],[2,4.9,13.61]],"batl":[[1,5.9,0]],"ltp":5.0,"tv":9.08,"id":16569870}]}]}
{"op":"mcm","clk":"1007630859","pt":1580656231038,"mc":[{"id":"1.168224445","rc":[{"batb":[[0,4.3,65.34],[1,4.2,67.22]],"ltp":0.0,"tv":0.0,"id":13117431},{"batb":[[0,2.9,41.19],[1,2.88,10.31],[2,2.86,49.76]],"ltp":0.0,"tv":0.0,"id":13117430},{"batb":[[0,3.35,52.3],[1,3.3,42.44],[2,3.15,19.83]],"ltp":0.0,"tv":0.0,"id":16569868}]}]}
{"op":"mcm","clk":"1007634704","pt":1580656246149,"mc":[{"id":"1.168224445","rc":[{"batb":[[0,4.3,45.91],[1,4.2,19.43]],"ltp":0.0,"tv":0.0,"id":13117431},{"batb":[[0,3.15,19.83],[1,1.01,0.51],[2,3.15,0]],"ltp":0.0,"tv":0.0,"id":16569868},{"batb":[[0,5.1,30.42],[1,4.9,13.61],[2,1.01,0.51]],"ltp":5.0,"tv":9.08,"id":16569870}]}]}
{"op":"mcm","clk":"1007635540","pt":1580656249352,"mc":[{"id":"1.168224445","rc":[{"batb":[[0,4.4,44.85],[1,4.3,45.91],[2,4.2,19.43]],"batl":[[1,5.2,9.24]],"ltp":0.0,"tv":0.0,"id":13117431},{"batl":[[0,3.25,18.48],[1,3.55,18.88]],"ltp":0.0,"tv":0.0,"id":13117430},{"batb":[[0,3.7,37.29],[1,3.65,33.32],[2,3.35,17.64]],"batl":[[0,3.95,28.16]],"ltp":0.0,"tv":0.0,"id":16569868},{"batb":[[0,5.2,33.15],[1,5.1,30.42],[2,5,10.08]],"batl":[[1,6,8.4]],"ltp":5.0,"tv":9.08,"id":16569870}]}]}
{"op":"mcm","clk":"1007635767","pt":1580656250251,"mc":[{"id":"1.168224445","rc":[{"batb":[[1,4.3,65.03],[2,1.01,0.51]],"batl":[[0,5.1,17.31]],"ltp":0.0,"tv":0.0,"id":13117431},{"batl":[[0,3.2,24.63],[1,3.25,18.48],[2,3.4,21.01]],"ltp":0.0,"tv":0.0,"id":13117430},{"batb":[[2,3.55,15.19]],"batl":[[1,4.6,21.72]],"ltp":0.0,"tv":0.0,"id":16569868},{"batl":[[0,5.8,12.83]],"ltp":5.0,"tv":9.08,"id":16569870}]}]}
{"op":"mcm","clk":"1007640536","pt":1580656268787,"mc":[{"id":"1.168224445","rc":[{"batb":[[0,4.4,11.76]],"ltp":0.0,"tv":0.0,"id":13117431},{"batb":[[0,2.82,22.69],[1,2.62,13.06],[2,1.01,0.51]],"batl":[[0,3.25,18.48],[1,3.4,21.01],[2,3.4,0]],"ltp":0.0,"tv":0.0,"id":13117430},{"batb":[[0,3.35,17.64],[1,3.3,17.94],[2,1.01,0.51]],"batl":[[0,3.95,13.44]],"ltp":0.0,"tv":0.0,"id":16569868},{"batb":[[0,5.2,23.41]],"ltp":5.0,"tv":9.08,"id":16569870}]}]}
{"op":"mcm","clk":"1007640902","pt":1580656270285,"mc":[{"id":"1.168224445","rc":[{"batb":[[0,4.3,65.03],[1,1.01,0.51],[2,1.01,0]],"batl":[[1,5.2,0]],"ltp":0.0,"tv":0.0,"id":13117431},{"batb":[[0,2.62,13.06],[1,1.01,0.51],[2,1.01,0]],"batl":[[0,3.4,21.01],[1,3.4,0]],"ltp":0.0,"tv":0.0,"id":13117430},{"batb":[[0,3.3,17.94],[1,1.01,0.51],[2,1.01,0]],"batl":[[0,4.6,21.72],[1,4.6,0]],"ltp":0.0,"tv":0.0,"id":16569868},{"batb":[[2,4.9,13.61]],"batl":[[1,6,0]],"ltp":5.0,"tv":9.08,"id":16569870}]}]}
{"op":"mcm","clk":"1007641148","pt":1580656271392,"mc":[{"id":"1.168224445","rc":[{"batb":[[0,4.3,78.37],[1,4.2,47.9],[2,1.01,0.51]],"ltp":0.0,"tv":0.0,"id":13117431},{"batb":[[1,2.6,66.38],[2,2.56,66.23]],"ltp":0.0,"tv":0.0,"id":13117430},{"batb":[[0,3.45,51.05],[1,3.4,39.45],[2,3.3,17.94]],"ltp":0.0,"tv":0.0,"id":16569868}]}]}
{"op":"mcm","clk":"1007641368","pt":1580656272300,"mc":[{"id":"1.168224445","rc":[{"batb":[[0,4.3,65.03],[1,1.01,0.51],[2,1.01,0]],"ltp":0.0,"tv":0.0,"id":13117431},{"batb":[[1,1.01,0.51],[2,2.56,0]],"ltp":0.0,"tv":0.0,"id":13117430},{"batb":[[0,3.3,17.94],[1,1.01,0.51],[2,3.3,0]],"ltp":0.0,"tv":0.0,"id":16569868}]}]}
{"op":"mcm","clk":"1007642073","pt":1580656275233,"mc":[{"id":"1.168224445","rc":[{"batb":[[0,4.4,40.15],[1,4.3,65.03],[2,1.01,0.51]],"ltp":0.0,"tv":0.0,"id":13117431},{"batb":[[0,2.84,39.15],[1,2.8,52.55],[2,2.62,13.06]],"ltp":0.0,"tv":0.0,"id":13117430},{"batb":[[0,3.8,29.94],[1,3.75,31.3],[2,3.3,17.94]],"ltp":0.0,"tv":0.0,"id":16569868},{"batb":[[0,5.2,36.53]],"ltp":5.0,"tv":9.08,"id":16569870}]}]}
{"op":"mcm","clk":"1007642958","pt":1580656278700,"mc":[{"id":"1.168224445","rc":[{"batb":[[0,4.3,65.03],[1,1.01,0.51],[2,1.01,0]],"ltp":0.0,"tv":0.0,"id":13117431},{"batb":[[0,2.62,13.06],[1,1.01,0.51],[2,2.62,0]],"ltp":0.0,"tv":0.0,"id":13117430},{"batb":[[0,3.3,17.94],[1,1.01,0.51],[2,3.3,0]],"ltp":0.0,"tv":0.0,"id":16569868},{"batb":[[0,5.2,23.41]],"ltp":5.0,"tv":9.08,"id":16569870}]}]}
{"op":"mcm","clk":"1007643696","pt":1580656281727,"mc":[{"id":"1.168224445","rc":[{"batb":[[0,4.3,78.37],[1,4.2,47.9],[2,1.01,0.51]],"ltp":0.0,"tv":0.0,"id":13117431},{"batb":[[1,2.6,66.38],[2,2.56,66.23]],"ltp":0.0,"tv":0.0,"id":13117430},{"batb":[[0,3.45,51.05],[1,3.4,39.45],[2,3.3,17.94]],"batl":[[0,3.8,1.68],[1,4.6,21.72]],"ltp":0.0,"tv":0.0,"id":16569868}]}]}
{"op":"mcm","clk":"1007644538","pt":1580656285321,"mc":[{"id":"1.168224445","rc":[{"batb":[[0,4.3,19.12],[1,1.01,0.51],[2,1.01,0]],"ltp":0.0,"tv":0.0,"id":13117431},{"batb":[[0,3.3,17.94],[1,1.01,0.51],[2,3.3,0]],"batl":[[0,4.6,21.72],[1,4.6,0]],"ltp":0.0,"tv":0.0,"id":16569868},{"batb":[[1,4.9,13.61],[2,1.01,0.51]],"ltp":5.0,"tv":9.08,"id":16569870}]}]}
{"op":"mcm","clk":"1007645258","pt":1580656288437,"mc":[{"id":"1.168224445","rc":[{"batb":[[0,4.5,24.39],[1,4.4,61.77],[2,4.3,18.8]],"batl":[[1,5.2,16.21]],"ltp":0.0,"tv":0.0,"id":13117431},{"batl":[[0,2.86,12.83],[1,3.1,10.46]],"ltp":0.0,"tv":0.0,"id":13117430},{"batb":[[0,4.2,32.37],[1,4.1,50.02],[2,3.95,22.98]],"batl":[[1,5.8,12.83]],"ltp":0.0,"tv":0.0,"id":16569868},{"batb":[[0,5.3,20.62],[1,5.2,23.41],[2,5,13.45]],"ltp":5.0,"tv":9.08,"id":16569870}]}]}
{"op":"mcm","clk":"1007645449","pt":1580656289198,"mc":[{"id":"1.168224445","rc":[{"batb":[[1,4.4,73.53]],"batl":[[2,5.3,9.24]],"ltp":0.0,"tv":0.0,"id":13117431},{"batb":[[2,2.56,93.12]],"batl":[[1,2.94,21],[2,3.1,10.46]],"ltp":0.0,"tv":0.0,"id":13117430},{"batl":[[0,4.4,11.76],[1,4.6,21.72],[2,5.8,12.83]],"ltp":0.0,"tv":0.0,"id":16569868},{"batb":[[2,5.1,10.08]],"batl":[[1,6.2,7.56]],"ltp":5.0,"tv":9.08,"id":16569870}]}]}
{"op":"mcm","clk":"1007646708","pt":1580656294622,"mc":[{"id":"1.168224445","rc":[{"trd":[[4.2,3.36]],"batb":[[0,4.2,30.69]],"ltp":4.2,"tv":3.36,"id":16569868}],"tv":12.44}]}
{"op":"mcm","clk":"1007649944","pt":1580656308230,"mc":[{"id":"1.168224445","rc":[{"batb":[[0,4.4,32.41],[1,4.3,18.8],[2,1.01,0.51]],"batl":[[0,5.2,16.21],[1,5.2,0],[2,5.3,0]],"ltp":0.0,"tv":0.0,"id":13117431},{"batb":[[0,2.28,19.2],[1,1.01,0.51],[2,2.56,0]],"batl":[[0,3.1,10.46],[1,2.94,0],[2,3.1,0]],"ltp":0.0,"tv":0.0,"id":13117430},{"batb":[[0,3.6,14.48],[1,1.01,0.51],[2,3.95,0]],"batl":[[0,5.8,12.83],[1,4.6,0],[2,5.8,0]],"ltp":4.2,"tv":3.36,"id":16569868},{"batb":[[0,5.2,23.41],[1,5,13.45],[2,1.01,0.51]],"batl":[[1,6.2,0]],"ltp":5.0,"tv":9.08,"id":16569870}]}]}
{"op":"mcm","clk":"1007650568","pt":1580656310841,"mc":[{"id":"1.168224445","rc":[{"batb":[[0,5.2,29.1]],"ltp":5.0,"tv":9.08,"id":16569870}]}]}
{"op":"mcm","clk":"1007651103","pt":1580656313269,"mc":[{"id":"1.168224445","rc":[{"batb":[[0,4.5,36.67],[1,4.4,43.39],[2,4.3,18.8]],"ltp":0.0,"tv":0.0,"id":13117431},{"batb":[[0,2.54,42.25],[1,2.5,70.72],[2,2.28,19.2]],"ltp":0.0,"tv":0.0,"id":13117430},{"batb":[[0,4.3,66.32],[1,4.2,46.69],[2,3.6,14.48]],"ltp":4.2,"tv":3.36,"id":16569868},{"batb":[[0,5.3,24.56],[1,5.2,29.1],[2,5,13.45]],"ltp":5.0,"tv":9.08,"id":16569870}]}]}
{"op":"mcm","clk":"1007652376","pt":1580656318671,"mc":[{"id":"1.168224445","rc":[{"batb":[[0,4.4,32.41],[1,4.3,18.8],[2,1.01,0.51]],"ltp":0.0,"tv":0.0,"id":13117431},{"batb":[[0,2.28,19.2],[1,1.01,0.51],[2,2.28,0]],"ltp":0.0,"tv":0.0,"id":13117430},{"batb":[[0,3.6,14.48],[1,1.01,0.51],[2,3.6,0]],"ltp":4.2,"tv":3.36,"id":16569868},{"batb":[[0,5.2,29.1],[1,5,13.45],[2,1.01,0.51]],"ltp":5.0,"tv":9.08,"id":16569870}]}]}
{"op":"mcm","clk":"1007653064","pt":1580656321644,"mc":[{"id":"1.168224445","rc":[{"batb":[[1,4.3,64.61]],"ltp":0.0,"tv":0.0,"id":13117431},{"batb":[[1,2.26,86.62],[2,2.24,48.15]],"ltp":0.0,"tv":0.0,"id":13117430},{"batb":[[0,3.75,36.16],[1,3.7,32.26],[2,3.6,14.48]],"ltp":4.2,"tv":3.36,"id":16569868},{"batb":[[0,5.2,38.79],[1,5.1,30.17],[2,5,13.45]],"ltp":5.0,"tv":9.08,"id":16569870}]}]}
{"op":"mcm","clk":"1007653732","pt":1580656324371,"mc":[{"id":"1.168224445","rc":[{"batb":[[1,1.01,0.51],[2,2.24,0]],"ltp":0.0,"tv":0.0,"id":13117430}]}]}
{"op":"mcm","clk":"1007654420","pt":1580656327357,"mc":[{"id":"1.168224445","rc":[{"batb":[[0,2.86,49.03],[1,2.82,51.53],[2,2.28,19.2]],"ltp":0.0,"tv":0.0,"id":13117430}]}]}
{"op":"mcm","clk":"1007654634","pt":1580656328287,"mc":[{"id":"1.168224445","rc":[{"batl":[[0,5,17.86],[1,5.1,17.15]],"ltp":0.0,"tv":0.0,"id":13117431},{"batb":[[1,2.84,10.62],[2,2.82,51.53]],"batl":[[1,3.35,22.03]],"ltp":0.0,"tv":0.0,"id":13117430},{"batl":[[0,4.1,14.08],[1,4.7,20.85]],"ltp":4.2,"tv":3.36,"id":16569868},{"batb":[[2,4.9,13.53]],"batl":[[0,5.9,12.59]],"ltp":5.0,"tv":9.08,"id":16569870}]}]}
{"op":"mcm","clk":"1007654886","pt":1580656329349,"mc":[{"id":"1.168224445","rc":[{"batb":[[1,4.3,77.22]],"batl":[[2,5.2,9.24]],"ltp":0.0,"tv":0.0,"id":13117431},{"batl":[[1,3.15,19.32],[2,3.35,22.03]],"ltp":0.0,"tv":0.0,"id":13117430},{"batl":[[0,4,13.44],[1,4.1,14.08],[2,4.7,20.85]],"ltp":4.2,"tv":3.36,"id":16569868},{"batb":[[2,5,10.08]],"batl":[[1,6.2,7.56]],"ltp":5.0,"tv":9.08,"id":16569870}]}]}
{"op":"mcm","clk":"1007657886","pt":1580656341635,"mc":[{"id":"1.168224445","rc":[{"batb":[[0,2.84,10.62],[1,2.74,23.53],[2,2.58,13.77]],"ltp":0.0,"tv":0.0,"id":13117430},{"batb":[[0,3.7,32.26],[1,3.6,14.48],[2,3.45,16.8]],"ltp":4.2,"tv":3.36,"id":16569868},{"batb":[[0,5.2,30.12]],"ltp":5.0,"tv":9.08,"id":16569870}]}]}
{"op":"mcm","clk":"1007658742","pt":1580656345158,"mc":[{"id":"1.168224445","rc":[{"batb":[[0,4.3,31.41],[1,1.01,0.51],[2,1.01,0]],"batl":[[0,5.1,17.15],[1,5.2,9.24],[2,5.2,0]],"ltp":0.0,"tv":0.0,"id":13117431},{"batb":[[0,2.74,23.53],[1,2.58,13.77],[2,1.01,0.51]],"batl":[[0,3.15,19.32],[1,3.35,22.03],[2,3.35,0]],"ltp":0.0,"tv":0.0,"id":13117430},{"batb":[[0,3.45,16.8],[1,3.4,16.84],[2,1.01,0.51]],"batl":[[1,4.7,20.85],[2,4.7,0]],"ltp":4.2,"tv":3.36,"id":16569868},{"batb":[[0,5,10.08],[1,4.9,13.53],[2,1.01,0.51]],"ltp":5.0,"tv":9.08,"id":16569870}]}]}
{"op":"mcm","clk":"1007659007","pt":1580656346244,"mc":[{"id":"1.168224445","rc":[{"batb":[[0,4.3,18.8]],"batl":[[1,5.2,0]],"ltp":0.0,"tv":0.0,"id":13117431},{"batb":[[0,2.58,13.77],[1,1.01,0.51],[2,1.01,0]],"batl":[[0,3.35,22.03],[1,3.35,0]],"ltp":0.0,"tv":0.0,"id":13117430},{"batb":[[0,3.4,16.84],[1,1.01,0.51],[2,1.01,0]],"batl":[[0,4.7,20.85],[1,4.7,0]],"ltp":4.2,"tv":3.36,"id":16569868},{"batb":[[0,4.9,13.53],[1,1.01,0.51],[2,1.01,0]],"batl":[[1,6.2,0]],"ltp":5.0,"tv":9.08,"id":16569870}]}]}
{"op":"mcm","clk":"1007659570","pt":1580656348743,"mc":[{"id":"1.168224445","rc":[{"batb":[[0,4.3,85.42],[1,4.2,47.93],[2,1.01,0.51]],"ltp":0.0,"tv":0.0,"id":13117431},{"batb":[[0,2.58,82.45],[1,2.54,67.76],[2,1.01,0.51]],"ltp":0.0,"tv":0.0,"id":13117430},{"batb":[[0,3.5,29.18],[1,3.45,38.12],[2,3.4,16.84]],"ltp":4.2,"tv":3.36,"id":16569868},{"batb":[[0,5.2,19.98],[1,5.1,30.32],[2,4.9,13.53]],"ltp":5.0,"tv":9.08,"id":16569870}]}]}
{"op":"mcm","clk":"1007663639","pt":1580656366584,"mc":[{"id":"1.168224445","rc":[{"batb":[[0,4.3,18.8],[1,1.01,0.51],[2,1.01,0]],"ltp":0.0,"tv":0.0,"id":13117431},{"batb":[[0,3.4,16.84],[1,1.01,0.51],[2,3.4,0]],"ltp":4.2,"tv":3.36,"id":16569868}]}]}
{"op":"mcm","clk":"1007664530","pt":1580656370306,"mc":[{"id":"1.168224445","rc":[{"batb":[[0,4.5,33.39],[1,4.4,61.61],[2,4.3,18.8]],"batl":[[1,5.3,15.89]],"ltp":0.0,"tv":0.0,"id":13117431},{"batb":[[2,2.24,20.14]],"batl":[[0,2.8,13.45],[1,3.05,10.86]],"ltp":0.0,"tv":0.0,"id":13117430},{"batb":[[0,4.2,50.16],[1,4.1,49.5],[2,4,21.95]],"batl":[[1,5.9,12.43]],"ltp":4.2,"tv":3.36,"id":16569868},{"batb":[[0,5.2,47.69],[2,5,13.3]],"batl":[[0,5.9,12.35]],"ltp":5.0,"tv":9.08,"id":16569870}]}]}
{"op":"mcm","clk":"1007664746","pt":1580656371266,"mc":[{"id":"1.168224445","rc":[{"batb":[[1,4.4,73.37]],"batl":[[1,5.3,25.14]],"ltp":0.0,"tv":0.0,"id":13117431},{"batb":[[1,2.54,94.65]],"batl":[[1,2.9,21.85],[2,3.05,10.86]],"ltp":0.0,"tv":0.0,"id":13117430},{"batl":[[0,4.5,11.76],[1,4.7,20.85],[2,5.9,12.43]],"ltp":4.2,"tv":3.36,"id":16569868},{"batb":[[1,5.1,40.4]],"batl":[[1,6.2,7.56]],"ltp":5.0,"tv":9.08,"id":16569870}]}]}
{"op":"mcm","clk":"1007668453","pt":1580656387013,"mc":[{"id":"1.168224445","rc":[{"batb":[[0,4.4,55.35],[1,4.3,18.8],[2,1.01,0.51]],"batl":[[0,5.3,25.14],[1,5.3,0]],"ltp":0.0,"tv":0.0,"id":13117431},{"batb":[[0,2.54,26.89],[1,2.24,20.14],[2,1.01,0.51]],"batl":[[0,2.9,21.85],[1,3.05,10.86],[2,3.05,0]],"ltp":0.0,"tv":0.0,"id":13117430},{"batb":[[0,3.8,14.28],[1,3.65,13.85],[2,1.01,0.51]],"batl":[[1,5.9,12.43],[2,5.9,0]],"ltp":4.2,"tv":3.36,"id":16569868},{"batb":[[0,5.2,35.57]],"ltp":5.0,"tv":9.08,"id":16569870}]}]}
{"op":"mcm","clk":"1007668750","pt":1580656388266,"mc":[{"id":"1.168224445","rc":[{"batb":[[0,4.4,43.59]],"batl":[[0,5.3,15.89]],"ltp":0.0,"tv":0.0,"id":13117431},{"batb":[[0,2.24,20.14],[1,1.01,0.51],[2,1.01,0]],"batl":[[0,3.05,10.86],[1,3.05,0]],"ltp":0.0,"tv":0.0,"id":13117430},{"batb":[[0,3.65,13.85],[1,1.01,0.51],[2,1.01,0]],"batl":[[0,5.9,12.43],[1,5.9,0]],"ltp":4.2,"tv":3.36,"id":16569868},{"batb":[[1,5.1,30.32]],"batl":[[1,6.2,0]],"ltp":5.0,"tv":9.08,"id":16569870}]}]}
{"op":"mcm","clk":"1007669140","pt":1580656390225,"mc":[{"id":"1.168224445","rc":[{"batb":[[1,5,13.3],[2,1.01,0.51]],"ltp":5.0,"tv":9.08,"id":16569870}]}]}
{"op":"mcm","clk":"1007669932","pt":1580656393286,"mc":[{"id":"1.168224445","rc":[{"batb":[[0,4.5,45.78],[1,4.4,43.59],[2,4.3,18.8]],"ltp":0.0,"tv":0.0,"id":13117431},{"batb":[[0,2.52,46.02],[1,2.48,72.37],[2,2.24,20.14]],"ltp":0.0,"tv":0.0,"id":13117430},{"batb":[[0,4.4,38.27],[1,4.3,44.48],[2,3.65,13.85]],"ltp":4.2,"tv":3.36,"id":16569868},{"batb":[[0,5.3,22.3],[1,5.2,35.57],[2,5,13.3]],"ltp":5.0,"tv":9.08,"id":16569870}]}]}
{"op":"mcm","clk":"1007670676","pt":1580656396320,"mc":[{"id":"1.168224445","rc":[{"batb":[[0,4.4,43.59],[1,4.3,18.8],[2,1.01,0.51]],"ltp":0.0,"tv":0.0,"id":13117431},{"batb":[[0,2.24,20.14],[1,1.01,0.51],[2,2.24,0]],"ltp":0.0,"tv":0.0,"id":13117430},{"batb":[[0,3.65,13.85],[1,1.01,0.51],[2,3.65,0]],"ltp":4.2,"tv":3.36,"id":16569868},{"batb":[[0,5.2,35.57],[1,5,13.3],[2,1.01,0.51]],"ltp":5.0,"tv":9.08,"id":16569870}]}]}
{"op":"mcm","clk":"1007671285","pt":1580656399204,"mc":[{"id":"1.168224445","rc":[{"batb":[[1,4.3,64.62]],"ltp":0.0,"tv":0.0,"id":13117431},{"batb":[[0,2.26,53.54],[1,2.24,68.43],[2,1.01,0.51]],"ltp":0.0,"tv":0.0,"id":13117430},{"batb":[[0,3.75,53.31],[1,3.7,31.98],[2,3.65,13.85]],"ltp":4.2,"tv":3.36,"id":16569868},{"batb":[[1,5.1,30.09],[2,5,13.3]],"ltp":5.0,"tv":9.08,"id":16569870}]}]}
{"op":"mcm","clk":"1007673261","pt":1580656408020,"mc":[{"id":"1.168224445","rc":[{"batb":[[0,2.24,20.14],[1,1.01,0.51],[2,1.01,0]],"ltp":0.0,"tv":0.0,"id":13117430}]}]}
{"op":"mcm","clk":"1007674096","pt":1580656411438,"mc":[{"id":"1.168224445","rc":[{"batb":[[1,4.3,77.23]],"batl":[[0,5,17.94],[1,5.1,17.07],[2,5.2,9.24]],"ltp":0.0,"tv":0.0,"id":13117431},{"batb":[[0,2.84,49.29],[1,2.8,63.62],[2,2.7,24.37]],"batl":[[1,3.1,19.32],[2,3.3,22.74]],"ltp":0.0,"tv":0.0,"id":13117430},{"batl":[[0,4.1,13.44],[1,4.2,13.45],[2,4.8,19.83]],"ltp":4.2,"tv":3.36,"id":16569868},{"batb":[[1,5.1,40.17]],"batl":[[1,6.2,7.56]],"ltp":5.0,"tv":9.08,"id":16569870}]}]}
{"op":"mcm","clk":"1007678640","pt":1580656430891,"mc":[{"id":"1.168224445","rc":[{"batb":[[0,4.3,77.23],[1,1.01,0.51],[2,1.01,0]],"batl":[[0,5.1,17.07],[1,5.2,9.24],[2,5.2,0]],"ltp":0.0,"tv":0.0,"id":13117431},{"batb":[[0,2.7,24.37],[1,2.54,14.32],[2,1.01,0.51]],"batl":[[0,3.1,19.32],[1,3.3,22.74],[2,3.3,0]],"ltp":0.0,"tv":0.0,"id":13117430},{"batb":[[0,3.5,16.8],[1,3.45,16.44],[2,1.01,0.51]],"batl":[[1,4.8,19.83],[2,4.8,0]],"ltp":4.2,"tv":3.36,"id":16569868},{"batb":[[0,5.2,24.53]],"ltp":5.0,"tv":9.08,"id":16569870}]}]}
{"op":"mcm","clk":"1007679018","pt":1580656432367,"mc":[{"id":"1.168224445","rc":[{"batb":[[0,4.3,64.62]],"batl":[[1,5.2,0]],"ltp":0.0,"tv":0.0,"id":13117431},{"batb":[[0,2.54,14.32],[1,1.01,0.51],[2,1.01,0]],"batl":[[0,3.3,22.74],[1,3.3,0]],"ltp":0.0,"tv":0.0,"id":13117430},{"batb":[[0,3.45,16.44],[1,1.01,0.51],[2,1.01,0]],"batl":[[0,4.8,19.83],[1,4.8,0]],"ltp":4.2,"tv":3.36,"id":16569868},{"batb":[[1,5.1,30.09]],"batl":[[1,6.2,0]],"ltp":5.0,"tv":9.08,"id":16569870}]}]}
{"op":"mcm","clk":"1007680141","pt":1580656437279,"mc":[{"id":"1.168224445","rc":[{"batb":[[0,4.3,96.34],[1,4.2,47.97],[2,1.01,0.51]],"batl":[[1,5.2,9.24]],"ltp":0.0,"tv":0.0,"id":13117431},{"batb":[[0,3,84.82],[1,2.96,45.41],[2,2.94,21]],"batl":[[1,3.4,16.8]],"ltp":0.0,"tv":0.0,"id":13117430},{"batb":[[0,3.5,58.87],[1,3.45,54.28],[2,3.2,18.48]],"batl":[[0,3.75,15.12],[1,4.8,19.83]],"ltp":4.2,"tv":3.36,"id":16569868},{"batb":[[2,5,23.38]],"batl":[[1,6,8.4]],"ltp":5.0,"tv":9.08,"id":16569870}]}]}
{"op":"mcm","clk":"1007680297","pt":1580656437889,"mc":[{"id":"1.168224445","rc":[{"batb":[[0,4.3,77.53],[1,4.2,68.11]],"batl":[[0,4.9,18.25],[1,5,18.02],[2,5.2,9.24]],"ltp":0.0,"tv":0.0,"id":13117431},{"batb":[[1,2.98,23.68],[2,2.96,45.41]],"batl":[[2,3.75,17.07]],"ltp":0.0,"tv":0.0,"id":13117430},{"batl":[[1,3.85,15.89],[2,4.1,13.77]],"ltp":4.2,"tv":3.36,"id":16569868}]}]}
{"op":"mcm","clk":"1007689163","pt":1580656474336,"mc":[{"id":"1.168224445","rc":[{"batb":[[0,4.3,12.6],[1,4.2,20.14]],"ltp":0.0,"tv":0.0,"id":13117431},{"batb":[[0,2.98,23.68],[1,2.94,21],[2,2.82,10.86]],"ltp":0.0,"tv":0.0,"id":13117430},{"batb":[[0,3.45,16.44],[1,3.2,18.48],[2,3.1,21.32]],"ltp":4.2,"tv":3.36,"id":16569868},{"batb":[[0,5,23.38],[1,1.01,0.51],[2,5,0]],"ltp":5.0,"tv":9.08,"id":16569870}]}]}
{"op":"mcm","clk":"1007690063","pt":1580656478148,"mc":[{"id":"1.168224445","rc":[{"batb":[[0,4.3,49.5],[1,4.2,68.56]],"ltp":0.0,"tv":0.0,"id":13117431},{"batb":[[2,2.86,50.92]],"ltp":0.0,"tv":0.0,"id":13117430},{"batb":[[2,3.15,55.13]],"ltp":4.2,"tv":3.36,"id":16569868},{"batb":[[0,5.1,42.29],[1,5,54.73],[2,1.01,0.51]],"ltp":5.0,"tv":9.08,"id":16569870}]}]}
{"op":"mcm","clk":"1007690759","pt":1580656481135,"mc":[{"id":"1.168224445","rc":[{"batl":[[1,6,0]],"ltp":5.0,"tv":9.08,"id":16569870}]}]}
{"op":"mcm","clk":"1007691096","pt":1580656482367,"mc":[{"id":"1.168224445","rc":[{"batb":[[0,4.3,36.9]],"batl":[[0,5,18.02],[1,5,0],[2,5.2,0]],"ltp":0.0,"tv":0.0,"id":13117431},{"batb":[[0,2.86,50.92],[1,2.82,62.49],[2,1.01,0.51]],"batl":[[0,3.75,17.07],[1,3.4,0],[2,3.75,0]],"ltp":0.0,"tv":0.0,"id":13117430},{"batb":[[0,3.15,55.13],[1,3.1,70.7],[2,1.01,0.51]],"batl":[[0,4.1,13.77],[1,3.85,0],[2,4.1,0]],"ltp":4.2,"tv":3.36,"id":16569868},{"batb":[[1,5,44.65]],"ltp":5.0,"tv":9.08,"id":16569870}]}]}
{"op":"mcm","clk":"1007694541","pt":1580656496355,"mc":[{"id":"1.168224445","rc":[{"batb":[[1,4.2,20.14]],"ltp":0.0,"tv":0.0,"id":13117431},{"batb":[[0,3.1,21.32],[1,1.01,0.51],[2,1.01,0]],"ltp":4.2,"tv":3.36,"id":16569868},{"batb":[[0,5.1,30.15],[1,5,13.3]],"ltp":5.0,"tv":9.08,"id":16569870}]}]}
{"op":"mcm","clk":"1007695258","pt":1580656499288,"mc":[{"id":"1.168224445","rc":[{"batb":[[0,4.4,33.2],[1,4.3,45.95],[2,4.2,20.14]],"ltp":0.0,"tv":0.0,"id":13117431},{"batb":[[0,3.75,41.55],[1,3.7,32.09],[2,3.1,21.32]],"ltp":4.2,"tv":3.36,"id":16569868},{"batb":[[0,5.2,31.5],[1,5.1,30.15],[2,5,13.3]],"ltp":5.0,"tv":9.08,"id":16569870}]}]}
{"op":"mcm","clk":"1007695464","pt":1580656500308,"mc":[{"id":"1.168224445","rc":[{"batb":[[2,4.2,19.43]],"batl":[[0,5,17.86]],"ltp":0.0,"tv":0.0,"id":13117431},{"batb":[[2,2.7,12.04]],"batl":[[0,3.1,10.62],[1,3.4,20.93]],"ltp":0.0,"tv":0.0,"id":13117430},{"batb":[[2,3.65,14.16]],"batl":[[1,4.4,24]],"ltp":4.2,"tv":3.36,"id":16569868}]}]}
{"op":"mcm","clk":"1007695722","pt":1580656501318,"mc":[{"id":"1.168224445","rc":[{"batb":[[1,4.3,58.55]],"batl":[[1,5.1,10.08]],"ltp":0.0,"tv":0.0,"id":13117431},{"batb":[[1,2.82,85.17]],"batl":[[1,3.25,18.48],[2,3.4,20.93]],"ltp":0.0,"tv":0.0,"id":13117430},{"batl":[[0,4,13.44],[1,4.1,13.77],[2,4.4,24]],"ltp":4.2,"tv":3.36,"id":16569868},{"batb":[[1,5.1,40.23]],"batl":[[1,6.2,7.56]],"ltp":5.0,"tv":9.08,"id":16569870}]}]}
{"op":"mcm","clk":"1007696016","pt":1580656502370,"mc":[{"id":"1.168224445","rc":[{"batb":[[1,2.82,62.49]],"batl":[[1,3.4,20.93],[2,3.4,0]],"ltp":0.0,"tv":0.0,"id":13117430}]}]}
{"op":"mcm","clk":"1007696248","pt":1580656503205,"mc":[{"id":"1.168224445","rc":[{"batb":[[2,2.8,22.69]],"batl":[[1,3.2,18.48],[2,3.4,20.93]],"ltp":0.0,"tv":0.0,"id":13117430}]}]}
{"op":"mcm","clk":"1007698638","pt":1580656513310,"mc":[{"id":"1.168224445","rc":[{"batb":[[0,4.3,58.55],[1,4.2,19.43],[2,1.01,0.51]],"ltp":0.0,"tv":0.0,"id":13117431},{"batb":[[0,2.8,22.69],[1,2.7,12.04],[2,1.01,0.51]],"batl":[[0,3.2,18.48],[1,3.4,20.93],[2,3.4,0]],"ltp":0.0,"tv":0.0,"id":13117430},{"batb":[[0,3.4,16.8],[1,3.3,17.86],[2,1.01,0.51]],"batl":[[1,4.4,24],[2,4.4,0]],"ltp":4.2,"tv":3.36,"id":16569868},{"batb":[[0,5.1,40.23],[1,5,13.3],[2,1.01,0.51]],"ltp":5.0,"tv":9.08,"id":16569870}]}]}
{"op":"mcm","clk":"1007698855","pt":1580656514400,"mc":[{"id":"1.168224445","rc":[{"batb":[[0,4.3,45.95]],"batl":[[1,5.1,0]],"ltp":0.0,"tv":0.0,"id":13117431},{"batb":[[0,2.7,12.04],[1,1.01,0.51],[2,1.01,0]],"batl":[[0,3.4,20.93],[1,3.4,0]],"ltp":0.0,"tv":0.0,"id":13117430},{"batb":[[0,3.3,17.86],[1,1.01,0.51],[2,1.01,0]],"batl":[[0,4.4,24],[1,4.4,0]],"ltp":4.2,"tv":3.36,"id":16569868},{"batb":[[0,5.1,30.15]],"batl":[[1,6.2,0]],"ltp":5.0,"tv":9.08,"id":16569870}]}]}
{"op":"mcm","clk":"1007699142","pt":1580656515777,"mc":[{"id":"1.168224445","rc":[{"batb":[[0,4.3,60.07],[1,4.2,67.47]],"ltp":0.0,"tv":0.0,"id":13117431},{"batb":[[0,2.74,54.51],[1,2.7,69.83],[2,1.01,0.51]],"ltp":0.0,"tv":0.0,"id":13117430},{"batb":[[0,3.4,52.07],[1,3.35,40.71],[2,3.3,17.86]],"ltp":4.2,"tv":3.36,"id":16569868},{"batb":[[0,5.1,48.29],[1,5,44.56]],"ltp":5.0,"tv":9.08,"id":16569870}]}]}
{"op":"mcm","clk":"1007700480","pt":1580656521430,"mc":[{"id":"1.168224445","rc":[{"batb":[[0,4.3,45.95],[1,4.2,19.43]],"ltp":0.0,"tv":0.0,"id":13117431},{"batb":[[0,3.3,17.86],[1,1.01,0.51],[2,3.3,0]],"ltp":4.2,"tv":3.36,"id":16569868},{"batb":[[0,5.1,30.15],[1,5,13.3]],"ltp":5.0,"tv":9.08,"id":16569870}]}]}
{"op":"mcm","clk":"1007701211","pt":1580656524413,"mc":[{"id":"1.168224445","rc":[{"batb":[[0,4.4,43.18],[1,4.3,45.95],[2,4.2,19.43]],"ltp":0.0,"tv":0.0,"id":13117431},{"batb":[[0,3.95,37.82],[1,3.9,28.3],[2,3.3,17.86]],"ltp":4.2,"tv":3.36,"id":16569868},{"batb":[[0,5.2,38.48],[1,5.1,30.15],[2,5,13.3]],"ltp":5.0,"tv":9.08,"id":16569870}]}]}
{"op":"mcm","clk":"1007701420","pt":1580656525444,"mc":[{"id":"1.168224445","rc":[{"batb":[[1,4.3,77.67],[2,1.01,0.51]],"batl":[[0,5,17.7],[1,5.1,10.08]],"ltp":0.0,"tv":0.0,"id":13117431},{"batb":[[2,2.66,25.21]],"batl":[[0,2.96,11.8],[1,3.05,20.16],[2,3.2,24.63]],"ltp":0.0,"tv":0.0,"id":13117430},{"batb":[[2,3.8,25.41]],"batl":[[0,4.2,12.6],[1,4.4,24],[2,4.6,21.87]],"ltp":4.2,"tv":3.36,"id":16569868},{"batb":[[1,5.1,40.23]],"batl":[[1,6.2,7.56]],"ltp":5.0,"tv":9.08,"id":16569870}]}]}
{"op":"mcm","clk":"1007703925","pt":1580656536424,"mc":[{"id":"1.168224445","rc":[{"batb":[[0,4.4,34.12],[1,4.3,65.07]],"batl":[[1,5.1,0]],"ltp":0.0,"tv":0.0,"id":13117431},{"batb":[[0,2.62,13.06],[1,1.01,0.51],[2,2.66,0]],"batl":[[0,3.2,24.63],[1,3.05,0],[2,3.2,0]],"ltp":0.0,"tv":0.0,"id":13117430},{"batb":[[0,3.55,15.03],[1,1.01,0.51],[2,3.8,0]],"batl":[[0,4.6,21.87],[1,4.4,0],[2,4.6,0]],"ltp":4.2,"tv":3.36,"id":16569868},{"batb":[[0,5.2,24.31],[1,5.1,30.15]],"batl":[[1,6.2,0]],"ltp":5.0,"tv":9.08,"id":16569870}]}]}
{"op":"mcm","clk":"1007704526","pt":1580656539142,"mc":[{"id":"1.168224445","rc":[{"batb":[[0,2.66,56.48],[1,2.62,75.58],[2,1.01,0.51]],"ltp":0.0,"tv":0.0,"id":13117430},{"batb":[[0,3.65,59.51],[1,3.6,34.08],[2,3.55,15.03]],"ltp":4.2,"tv":3.36,"id":16569868}]}]}
{"op":"mcm","clk":"1007705797","pt":1580656544873,"mc":[{"id":"1.168224445","rc":[{"batb":[[0,3.55,15.03],[1,1.01,0.51],[2,3.55,0]],"ltp":4.2,"tv":3.36,"id":16569868}]}]}
{"op":"mcm","clk":"1007706605","pt":1580656548442,"mc":[{"id":"1.168224445","rc":[{"batb":[[0,4.4,48.09],[1,4.3,64.75]],"ltp":0.0,"tv":0.0,"id":13117431},{"batb":[[2,2.56,13.93]],"batl":[[0,2.86,12.83],[1,3,11.33]],"ltp":0.0,"tv":0.0,"id":13117430},{"batb":[[0,4.1,39.15],[1,4,52.61],[2,3.95,23.13]],"batl":[[1,4.7,20.06]],"ltp":4.2,"tv":3.36,"id":16569868},{"batb":[[0,5.2,45.95]],"ltp":5.0,"tv":9.08,"id":16569870}]}]}
{"op":"mcm","clk":"1007706768","pt":1580656549366,"mc":[{"id":"1.168224445","rc":[{"batb":[[1,4.3,77.36]],"batl":[[1,5.1,10.08]],"ltp":0.0,"tv":0.0,"id":13117431},{"batb":[[2,2.58,26.05]],"batl":[[1,2.94,21],[2,3,11.33]],"ltp":0.0,"tv":0.0,"id":13117430},{"batl":[[0,4.5,11.76],[1,4.6,21.87],[2,4.7,20.06]],"ltp":4.2,"tv":3.36,"id":16569868},{"batb":[[0,5.2,55.19]],"batl":[[1,6.2,7.56]],"ltp":5.0,"tv":9.08,"id":16569870}]}]}
{"op":"mcm","clk":"1007709045","pt":1580656560419,"mc":[{"id":"1.168224445","rc":[{"batb":[[1,4.3,64.75]],"batl":[[1,5.1,0]],"ltp":0.0,"tv":0.0,"id":13117431},{"batb":[[0,2.62,43.08],[1,2.56,13.93],[2,1.01,0.51]],"batl":[[0,3,11.33],[1,2.94,0],[2,3,0]],"ltp":0.0,"tv":0.0,"id":13117430},{"batb":[[0,3.75,13.14],[1,1.01,0.51],[2,3.95,0]],"batl":[[0,4.7,20.06],[1,4.6,0],[2,4.7,0]],"ltp":4.2,"tv":3.36,"id":16569868},{"batb":[[0,5.2,31.87]],"batl":[[1,6.2,0]],"ltp":5.0,"tv":9.08,"id":16569870}]}]}
{"op":"mcm","clk":"1007709673","pt":1580656563388,"mc":[{"id":"1.168224445","rc":[{"batb":[[0,2.56,13.93],[1,1.01,0.51],[2,1.01,0]],"ltp":0.0,"tv":0.0,"id":13117430}]}]}
{"op":"mcm","clk":"1007710208","pt":1580656565880,"mc":[{"id":"1.168224445","rc":[{"batb":[[0,2.68,54.43],[1,2.64,61.29],[2,2.56,13.93]],"ltp":0.0,"tv":0.0,"id":13117430},{"batb":[[0,4,72.89],[1,3.95,27.15],[2,3.75,13.14]],"ltp":4.2,"tv":3.36,"id":16569868},{"batb":[[0,5.2,43.69]],"ltp":5.0,"tv":9.08,"id":16569870}]}]}
{"op":"mcm","clk":"1007710791","pt":1580656568693,"mc":[{"id":"1.168224445","rc":[{"batb":[[0,2.56,13.93],[1,1.01,0.51],[2,2.56,0]],"ltp":0.0,"tv":0.0,"id":13117430},{"batb":[[0,3.75,13.14],[1,1.01,0.51],[2,3.75,0]],"ltp":4.2,"tv":3.36,"id":16569868},{"batb":[[0,5.2,31.87]],"ltp":5.0,"tv":9.08,"id":16569870}]}]}
{"op":"mcm","clk":"1007711455","pt":1580656571578,"mc":[{"id":"1.168224445","rc":[{"batb":[[0,2.62,43.08],[1,2.58,65.19],[2,2.56,13.93]],"ltp":0.0,"tv":0.0,"id":13117430},{"batb":[[0,3.9,44.85],[1,3.85,29.13],[2,3.75,13.14]],"ltp":4.2,"tv":3.36,"id":16569868}]}]}
{"op":"mcm","clk":"1007713664","pt":1580656582100,"mc":[{"id":"1.168224445","rc":[{"batb":[[0,3.75,13.14],[1,1.01,0.51],[2,3.75,0]],"ltp":4.2,"tv":3.36,"id":16569868},{"batb":[[1,5,13.3],[2,1.01,0.51]],"ltp":5.0,"tv":9.08,"id":16569870}]}]}
{"op":"mcm","clk":"1007714390","pt":1580656585418,"mc":[{"id":"1.168224445","rc":[{"batb":[[2,4.2,12.6]],"batl":[[1,5.1,10.08]],"ltp":0.0,"tv":0.0,"id":13117431},{"batl":[[0,2.82,22.69],[1,3,11.33]],"ltp":0.0,"tv":0.0,"id":13117430},{"batb":[[0,4.2,40.88],[1,4.1,49.64],[2,3.95,13.44]],"batl":[[0,4.7,30.99]],"ltp":4.2,"tv":3.36,"id":16569868},{"batb":[[0,5.3,34.21],[1,5.2,31.87],[2,5,13.3]],"batl":[[1,6.4,7.56]],"ltp":5.0,"tv":9.08,"id":16569870}]}]}
{"op":"mcm","clk":"1007714483","pt":1580656585807,"mc":[{"id":"1.168224445","rc":[{"batb":[[1,4.3,64.52],[2,4.2,31.88]],"batl":[[1,5.1,27]],"ltp":0.0,"tv":0.0,"id":13117431},{"batl":[[0,2.78,13.69],[1,2.82,22.69],[2,2.98,11.64]],"ltp":0.0,"tv":0.0,"id":13117430},{"batb":[[1,4.1,70.81]],"batl":[[1,5.5,14.32]],"ltp":4.2,"tv":3.36,"id":16569868},{"batl":[[0,6,12.12]],"ltp":5.0,"tv":9.08,"id":16569870}]}]}
{"op":"mcm","clk":"1007721154","pt":1580656614153,"mc":[{"id":"1.168224445","rc":[{"batb":[[0,4.3,45.95],[1,4.2,31.88],[2,1.01,0.51]],"batl":[[0,5.1,27],[1,5.1,0]],"ltp":0.0,"tv":0.0,"id":13117431},{"batb":[[0,2.48,27.73],[1,2.34,18.02],[2,1.01,0.51]],"batl":[[0,2.82,22.69],[1,2.98,11.64],[2,2.98,0]],"ltp":0.0,"tv":0.0,"id":13117430},{"batb":[[0,3.95,13.44],[1,3.8,25.26],[2,1.01,0.51]],"batl":[[0,4.7,10.92]],"ltp":4.2,"tv":3.36,"id":16569868},{"batb":[[0,5.3,9.24]],"ltp":5.0,"tv":9.08,"id":16569870}]}]}
{"op":"mcm","clk":"1007721345","pt":1580656615059,"mc":[{"id":"1.168224445","rc":[{"batb":[[1,4.2,19.28]],"batl":[[0,5.1,16.92]],"ltp":0.0,"tv":0.0,"id":13117431},{"batb":[[0,2.34,18.02],[1,1.01,0.51],[2,1.01,0]],"batl":[[0,2.98,11.64],[1,2.98,0]],"ltp":0.0,"tv":0.0,"id":13117430},{"batb":[[0,3.8,25.26],[1,1.01,0.51],[2,1.01,0]],"batl":[[0,5.5,14.32],[1,5.5,0]],"ltp":4.2,"tv":3.36,"id":16569868},{"batb":[[0,5.2,31.87],[1,5,13.3],[2,1.01,0.51]],"batl":[[1,6.4,0]],"ltp":5.0,"tv":9.08,"id":16569870}]}]}
{"op":"mcm","clk":"1007721774","pt":1580656616863,"mc":[{"id":"1.168224445","rc":[{"batb":[[0,4.3,69.58],[1,4.2,67.17]],"ltp":0.0,"tv":0.0,"id":13117431},{"batb":[[0,2.38,45.31],[1,2.34,102.85],[2,1.01,0.51]],"ltp":0.0,"tv":0.0,"id":13117430},{"batb":[[0,3.9,46.1],[1,3.85,29.12],[2,3.8,25.26]],"ltp":4.2,"tv":3.36,"id":16569868},{"batb":[[0,5.2,40.73],[1,5.1,30.02],[2,5,13.3]],"ltp":5.0,"tv":9.08,"id":16569870}]}]}
{"op":"mcm","clk":"1007721944","pt":1580656617635,"mc":[{"id":"1.168224445","rc":[{"batb":[[0,4.3,45.95],[1,4.2,19.28]],"ltp":0.0,"tv":0.0,"id":13117431},{"batb":[[0,2.34,18.02],[1,1.01,0.51],[2,1.01,0]],"ltp":0.0,"tv":0.0,"id":13117430},{"batb":[[0,3.8,25.26],[1,1.01,0.51],[2,3.8,0]],"ltp":4.2,"tv":3.36,"id":16569868},{"batb":[[0,5.2,31.87],[1,5,13.3],[2,1.01,0.51]],"ltp":5.0,"tv":9.08,"id":16569870}]}]}
{"op":"mcm","clk":"1007722815","pt":1580656621366,"mc":[{"id":"1.168224445","rc":[{"batb":[[0,4.3,69.58],[1,4.2,79.77]],"batl":[[0,5,10.08],[1,5.1,16.92]],"ltp":0.0,"tv":0.0,"id":13117431},{"batb":[[0,2.78,44.49],[1,2.74,55.69],[2,2.72,11.8]],"batl":[[0,2.98,32.65],[1,3.15,10.31]],"ltp":0.0,"tv":0.0,"id":13117430},{"batb":[[0,3.9,46.1],[1,3.85,29.12],[2,3.8,25.26]],"batl":[[0,4.4,35.68],[1,4.9,18.49]],"ltp":4.2,"tv":3.36,"id":16569868},{"batb":[[0,5.2,49.97],[1,5.1,30.02],[2,5,13.3]],"batl":[[0,5.9,12.35],[1,6.4,7.56]],"ltp":5.0,"tv":9.08,"id":16569870}]}]}
{"op":"mcm","clk":"1007725445","pt":1580656631883,"mc":[{"id":"1.168224445","rc":[{"batb":[[0,4.3,50.48]],"ltp":0.0,"tv":0.0,"id":13117431},{"batb":[[0,2.58,26.05],[1,2.5,14.95],[2,1.01,0.51]],"batl":[[0,2.98,21]],"ltp":0.0,"tv":0.0,"id":13117430},{"batb":[[0,3.75,15.12],[1,3.65,14.24],[2,1.01,0.51]],"batl":[[0,4.4,11.76]],"ltp":4.2,"tv":3.36,"id":16569868},{"batb":[[0,5.2,41.11]],"ltp":5.0,"tv":9.08,"id":16569870}]}]}
{"op":"mcm","clk":"1007725567","pt":1580656632470,"mc":[{"id":"1.168224445","rc":[{"batb":[[1,4.2,67.17]],"batl":[[0,5.1,16.92],[1,5.1,0]],"ltp":0.0,"tv":0.0,"id":13117431},{"batb":[[0,2.5,14.95],[1,1.01,0.51],[2,1.01,0]],"batl":[[0,3.15,10.31],[1,3.15,0]],"ltp":0.0,"tv":0.0,"id":13117430},{"batb":[[0,3.65,14.24],[1,1.01,0.51],[2,1.01,0]],"batl":[[0,4.9,18.49],[1,4.9,0]],"ltp":4.2,"tv":3.36,"id":16569868},{"batb":[[0,5.2,31.87]],"batl":[[1,6.4,0]],"ltp":5.0,"tv":9.08,"id":16569870}]}]}
{"op":"mcm","clk":"1007726046","pt":1580656634385,"mc":[{"id":"1.168224445","rc":[{"batb":[[1,4.2,19.28]],"ltp":0.0,"tv":0.0,"id":13117431}]}]}
{"op":"mcm","clk":"1007726597","pt":1580656636577,"mc":[{"id":"1.168224445","rc":[{"batb":[[0,4.4,27.42],[1,4.3,50.48],[2,4.2,19.28]],"ltp":0.0,"tv":0.0,"id":13117431},{"batb":[[0,2.72,59.95],[1,2.68,58.87],[2,2.5,14.95]],"ltp":0.0,"tv":0.0,"id":13117430},{"batb":[[0,4,36.36],[1,3.95,27.51],[2,3.65,14.24]],"ltp":4.2,"tv":3.36,"id":16569868},{"batb":[[0,5.2,46.66]],"ltp":5.0,"tv":9.08,"id":16569870}]}]}
{"op":"mcm","clk":"1007727315","pt":1580656639693,"mc":[{"id":"1.168224445","rc":[{"batb":[[0,4.3,50.48],[1,4.2,19.28],[2,1.01,0.51]],"ltp":0.0,"tv":0.0,"id":13117431},{"batb":[[0,2.5,14.95],[1,1.01,0.51],[2,2.5,0]],"ltp":0.0,"tv":0.0,"id":13117430},{"batb":[[0,3.65,14.24],[1,1.01,0.51],[2,3.65,0]],"ltp":4.2,"tv":3.36,"id":16569868},{"batb":[[0,5.2,31.87]],"ltp":5.0,"tv":9.08,"id":16569870}]}]}
{"op":"mcm","clk":"1007728144","pt":1580656643289,"mc":[{"id":"1.168224445","rc":[{"batb":[[1,4.2,67.46]],"ltp":0.0,"tv":0.0,"id":13117431},{"batb":[[0,3.7,44.96],[1,3.65,47.37],[2,1.01,0.51]],"ltp":4.2,"tv":3.36,"id":16569868}]}]}
{"op":"mcm","clk":"1007728841","pt":1580656646305,"mc":[{"id":"1.168224445","rc":[{"batb":[[0,2.92,45.37],[1,2.88,48.98],[2,2.5,14.95]],"ltp":0.0,"tv":0.0,"id":13117430}]}]}
{"op":"mcm","clk":"1007729116","pt":1580656647408,"mc":[{"id":"1.168224445","rc":[{"batb":[[1,4.2,80.06]],"batl":[[0,5,28.26]],"ltp":0.0,"tv":0.0,"id":13117431},{"batb":[[2,2.86,10.46]],"batl":[[0,3.15,29.63],[1,3.3,22.98]],"ltp":0.0,"tv":0.0,"id":13117430},{"batb":[[2,3.55,15.96]],"batl":[[0,4.1,27.29],[1,4.5,22.42]],"ltp":4.2,"tv":3.36,"id":16569868},{"batb":[[1,5.1,40.1],[2,4.9,13.53]],"batl":[[1,6.2,7.56]],"ltp":5.0,"tv":9.08,"id":16569870}]}]}
{"op":"mcm","clk":"1007732020","pt":1580656659417,"mc":[{"id":"1.168224445","rc":[{"batb":[[0,4.3,45.95]],"ltp":0.0,"tv":0.0,"id":13117431},{"batb":[[0,2.86,10.46],[1,2.72,24.37],[2,2.66,12.51]],"ltp":0.0,"tv":0.0,"id":13117430},{"batb":[[0,3.65,14.24],[1,3.55,15.96],[2,3.5,15.74]],"ltp":4.2,"tv":3.36,"id":16569868},{"batb":[[0,5.2,24.31]],"ltp":5.0,"tv":9.08,"id":16569870}]}]}
{"op":"mcm","clk":"1007732121","pt":1580656659809,"mc":[{"id":"1.168224445","rc":[{"batb":[[0,2.72,24.37],[1,2.66,12.51],[2,1.01,0.51]],"batl":[[0,3.15,19.32]],"ltp":0.0,"tv":0.0,"id":13117430},{"batb":[[0,3.55,15.96],[1,3.5,15.74],[2,1.01,0.51]],"batl":[[0,4.1,13.44]],"ltp":4.2,"tv":3.36,"id":16569868}]}]}
{"op":"mcm","clk":"1007732375","pt":1580656660839,"mc":[{"id":"1.168224445","rc":[{"batb":[[1,4.2,67.46]],"batl":[[0,5,18.18]],"ltp":0.0,"tv":0.0,"id":13117431},{"batb":[[0,2.66,12.51],[1,1.01,0.51],[2,1.01,0]],"batl":[[0,3.3,22.98],[1,3.3,0]],"ltp":0.0,"tv":0.0,"id":13117430},{"batb":[[0,3.5,15.74],[1,1.01,0.51],[2,1.01,0]],"batl":[[0,4.5,22.42],[1,4.5,0]],"ltp":4.2,"tv":3.36,"id":16569868},{"batb":[[1,5.1,30.02]],"batl":[[1,6.2,0]],"ltp":5.0,"tv":9.08,"id":16569870}]}]}
{"op":"mcm","clk":"1007732707","pt":1580656662207,"mc":[{"id":"1.168224445","rc":[{"batb":[[0,2.74,48.86],[1,2.7,57.79],[2,2.66,12.51]],"ltp":0.0,"tv":0.0,"id":13117430},{"batb":[[0,3.55,58.67],[1,3.5,52.31],[2,1.01,0.51]],"ltp":4.2,"tv":3.36,"id":16569868}]}]}
{"op":"mcm","clk":"1007733008","pt":1580656663419,"mc":[{"id":"1.168224445","rc":[{"batb":[[0,2.66,12.51],[1,1.01,0.51],[2,2.66,0]],"ltp":0.0,"tv":0.0,"id":13117430}]}]}
{"op":"mcm","clk":"1007733685","pt":1580656666292,"mc":[{"id":"1.168224445","rc":[{"batb":[[0,3,75.55],[1,2.96,45.47],[2,2.66,12.51]],"ltp":0.0,"tv":0.0,"id":13117430}]}]}
{"op":"mcm","clk":"1007733957","pt":1580656667434,"mc":[{"id":"1.168224445","rc":[{"batl":[[0,4.9,18.73]],"ltp":0.0,"tv":0.0,"id":13117431},{"batb":[[1,2.96,69.39],[2,2.82,10.78]],"batl":[[1,3.4,21.4]],"ltp":0.0,"tv":0.0,"id":13117430},{"batb":[[2,3.4,17]],"batl":[[0,3.9,15.26],[1,4.2,13.38]],"ltp":4.2,"tv":3.36,"id":16569868},{"batl":[[0,5.8,12.75]],"ltp":5.0,"tv":9.08,"id":16569870}]}]}
{"op":"mcm","clk":"1007734049","pt":1580656667816,"mc":[{"id":"1.168224445","rc":[{"batb":[[2,4.1,13.44]],"batl":[[1,5,10.08]],"ltp":0.0,"tv":0.0,"id":13117431},{"batb":[[2,2.84,22.69]],"batl":[[0,3.3,40.62]],"ltp":0.0,"tv":0.0,"id":13117430},{"batb":[[2,3.4,33.8]],"batl":[[1,4,13.44],[2,4.2,13.38]],"ltp":4.2,"tv":3.36,"id":16569868},{"batb":[[1,5.1,40.1]],"batl":[[1,6.2,7.56]],"ltp":5.0,"tv":9.08,"id":16569870}]}]}
{"op":"mcm","clk":"1007737188","pt":1580656680384,"mc":[{"id":"1.168224445","rc":[{"batb":[[0,2.96,23.92],[1,2.84,22.69],[2,2.82,10.78]],"ltp":0.0,"tv":0.0,"id":13117430},{"batb":[[0,3.5,52.31],[1,3.4,33.8],[2,1.01,0.51]],"ltp":4.2,"tv":3.36,"id":16569868},{"batb":[[0,5.1,40.1],[1,4.9,13.53],[2,1.01,0.51]],"ltp":5.0,"tv":9.08,"id":16569870}]}]}
{"op":"mcm","clk":"1007737289","pt":1580656680774,"mc":[{"id":"1.168224445","rc":[{"batb":[[2,1.01,0.51]],"batl":[[1,5,0]],"ltp":0.0,"tv":0.0,"id":13117431},{"batb":[[0,2.82,10.78],[1,1.01,0.51],[2,2.82,0]],"batl":[[0,3.4,21.4],[1,3.4,0]],"ltp":0.0,"tv":0.0,"id":13117430},{"batb":[[0,3.5,36.57],[1,3.4,17]],"batl":[[0,4.2,13.38],[1,4,0],[2,4.2,0]],"ltp":4.2,"tv":3.36,"id":16569868},{"batb":[[0,5.1,30.02]],"batl":[[1,6.2,0]],"ltp":5.0,"tv":9.08,"id":16569870}]}]}
{"op":"mcm","clk":"1007737560","pt":1580656681836,"mc":[{"id":"1.168224445","rc":[{"batb":[[0,3.4,17],[1,1.01,0.51],[2,1.01,0]],"ltp":4.2,"tv":3.36,"id":16569868}]}]}
{"op":"mcm","clk":"1007737903","pt":1580656683242,"mc":[{"id":"1.168224445","rc":[{"batb":[[0,2.9,51.28],[1,2.86,49.79],[2,2.82,10.78]],"ltp":0.0,"tv":0.0,"id":13117430},{"batb":[[0,3.45,38.07],[1,3.4,17],[2,1.01,0.51]],"ltp":4.2,"tv":3.36,"id":16569868},{"batb":[[0,5.1,44.75],[1,5,31.39],[2,4.9,13.53]],"ltp":5.0,"tv":9.08,"id":16569870}]}]}
{"op":"mcm","clk":"1007737964","pt":1580656683466,"mc":[{"id":"1.168224445","rc":[{"batb":[[0,2.82,10.78],[1,1.01,0.51],[2,2.82,0]],"ltp":0.0,"tv":0.0,"id":13117430},{"batb":[[0,3.4,17],[1,1.01,0.51],[2,1.01,0]],"ltp":4.2,"tv":3.36,"id":16569868},{"batb":[[0,5.1,30.31],[1,4.9,13.53],[2,1.01,0.51]],"ltp":5.0,"tv":9.08,"id":16569870}]}]}
{"op":"mcm","clk":"1007738337","pt":1580656685160,"mc":[{"id":"1.168224445","rc":[{"batb":[[0,3,45.96],[1,2.96,45.66],[2,2.82,10.78]],"ltp":0.0,"tv":0.0,"id":13117430},{"batb":[[0,3.6,45.7],[1,3.55,35.46],[2,3.4,17]],"ltp":4.2,"tv":3.36,"id":16569868},{"batb":[[0,5.2,25.39],[1,5.1,30.31],[2,4.9,13.53]],"ltp":5.0,"tv":9.08,"id":16569870}]}]}
{"op":"mcm","clk":"1007739063","pt":1580656688069,"mc":[{"id":"1.168224445","rc":[{"batb":[[0,2.82,10.78],[1,1.01,0.51],[2,2.82,0]],"ltp":0.0,"tv":0.0,"id":13117430},{"batb":[[0,3.4,17],[1,1.01,0.51],[2,3.4,0]],"ltp":4.2,"tv":3.36,"id":16569868},{"batb":[[0,5.1,30.31],[1,4.9,13.53],[2,1.01,0.51]],"ltp":5.0,"tv":9.08,"id":16569870}]}]}
{"op":"mcm","clk":"1007739814","pt":1580656691170,"mc":[{"id":"1.168224445","rc":[{"batb":[[0,2.9,51.28],[1,2.86,49.79],[2,2.82,10.78]],"ltp":0.0,"tv":0.0,"id":13117430}]}]}
{"op":"mcm","clk":"1007740606","pt":1580656694381,"mc":[{"id":"1.168224445","rc":[{"batb":[[2,4.1,13.44]],"batl":[[0,4.9,28.42]],"ltp":0.0,"tv":0.0,"id":13117431},{"batl":[[0,3.1,10.62],[1,3.15,19.32],[2,3.25,23.92]],"ltp":0.0,"tv":0.0,"id":13117430},{"batb":[[0,3.75,29.59],[1,3.7,46.01],[2,3.55,14.95]],"batl":[[0,4.2,25.98],[1,4.6,21.48]],"ltp":4.2,"tv":3.36,"id":16569868},{"batb":[[0,5.2,47.31],[1,5.1,30.31],[2,5,13.3]],"batl":[[0,5.9,12.35],[1,6.4,7.56]],"ltp":5.0,"tv":9.08,"id":16569870}]}]}
{"op":"mcm","clk":"1007744422","pt":1580656711763,"mc":[{"id":"1.168224445","rc":[{"batb":[[0,4.3,36.9]],"ltp":0.0,"tv":0.0,"id":13117431},{"batb":[[0,2.76,23.53],[1,2.64,12.98],[2,1.01,0.51]],"batl":[[0,3.15,19.32],[1,3.25,23.92],[2,3.25,0]],"ltp":0.0,"tv":0.0,"id":13117430},{"batb":[[0,3.55,14.95],[1,3.5,16.8],[2,1.01,0.51]],"batl":[[0,4.2,12.6]],"ltp":4.2,"tv":3.36,"id":16569868},{"batb":[[0,5.2,36.99],[2,4.9,13.53]],"ltp":5.0,"tv":9.08,"id":16569870}]}]}
{"op":"mcm","clk":"1007744639","pt":1580656712794,"mc":[{"id":"1.168224445","rc":[{"batb":[[2,1.01,0.51]],"batl":[[0,4.9,18.33]],"ltp":0.0,"tv":0.0,"id":13117431},{"batb":[[0,2.64,12.98],[1,1.01,0.51],[2,1.01,0]],"batl":[[0,3.25,23.92],[1,3.25,0]],"ltp":0.0,"tv":0.0,"id":13117430},{"batb":[[1,1.01,0.51],[2,1.01,0]],"batl":[[0,4.6,21.48],[1,4.6,0]],"ltp":4.2,"tv":3.36,"id":16569868},{"batb":[[0,5.2,27.75]],"batl":[[1,6.4,0]],"ltp":5.0,"tv":9.08,"id":16569870}]}]}
{"op":"mcm","clk":"1007745049","pt":1580656714681,"mc":[{"id":"1.168224445","rc":[{"batb":[[0,2.66,12.75]],"batl":[[0,3.25,23.45]],"ltp":0.0,"tv":0.0,"id":13117430},{"batl":[[0,4.5,21.95]],"ltp":4.2,"tv":3.36,"id":16569868}]}]}
{"op":"mcm","clk":"1007745568","pt":1580656717172,"mc":[{"id":"1.168224445","rc":[{"batb":[[0,2.86,57.86],[1,2.82,51.58],[2,2.66,12.75]],"ltp":0.0,"tv":0.0,"id":13117430},{"batb":[[0,3.8,28.92],[1,3.75,31.22],[2,3.55,14.95]],"ltp":4.2,"tv":3.36,"id":16569868},{"batb":[[0,5.2,41.77]],"ltp":5.0,"tv":9.08,"id":16569870}]}]}
{"op":"mcm","clk":"1007746645","pt":1580656722008,"mc":[{"id":"1.168224445","rc":[{"batb":[[0,2.66,12.75],[1,1.01,0.51],[2,2.66,0]],"ltp":0.0,"tv":0.0,"id":13117430},{"batb":[[0,3.55,14.95],[1,1.01,0.51],[2,3.55,0]],"ltp":4.2,"tv":3.36,"id":16569868},{"batb":[[0,5.2,27.75]],"ltp":5.0,"tv":9.08,"id":16569870}]}]}
{"op":"mcm","clk":"1007747234","pt":1580656725020,"mc":[{"id":"1.168224445","rc":[{"batb":[[0,2.74,44.4],[1,2.7,57.83],[2,2.66,12.75]],"ltp":0.0,"tv":0.0,"id":13117430},{"batb":[[0,3.6,42.05],[1,3.55,50.43],[2,1.01,0.51]],"ltp":4.2,"tv":3.36,"id":16569868}]}]}
{"op":"mcm","clk":"1007747737","pt":1580656727100,"mc":[{"id":"1.168224445","rc":[{"batb":[[0,2.66,12.75],[1,1.01,0.51],[2,2.66,0]],"ltp":0.0,"tv":0.0,"id":13117430}]}]}
{"op":"mcm","clk":"1007748455","pt":1580656730181,"mc":[{"id":"1.168224445","rc":[{"batb":[[2,4.1,34.06]],"batl":[[1,5,10.08]],"ltp":0.0,"tv":0.0,"id":13117431},{"batb":[[0,3,55.29],[1,2.96,45.62],[2,2.94,24.39]],"batl":[[1,3.35,17.64],[2,3.7,17.15]],"ltp":0.0,"tv":0.0,"id":13117430},{"batb":[[2,3.35,17.64]],"batl":[[0,3.9,14.28],[1,3.95,14.79],[2,4.2,25.65]],"ltp":4.2,"tv":3.36,"id":16569868},{"batb":[[2,5,10.08]],"batl":[[0,5.8,12.83],[1,5.9,12.35],[2,6.2,7.56]],"ltp":5.0,"tv":9.08,"id":16569870}]}]}
{"op":"mcm","clk":"1007748581","pt":1580656730688,"mc":[{"id":"1.168224445","rc":[{"batb":[[1,4.2,48.18]],"ltp":0.0,"tv":0.0,"id":13117431},{"batl":[[1,6.2,7.56],[2,6.2,0]],"ltp":5.0,"tv":9.08,"id":16569870}]}]}
{"op":"mcm","clk":"1007754591","pt":1580656757665,"mc":[{"id":"1.168224445","rc":[{"batb":[[0,3,38.76]],"ltp":0.0,"tv":0.0,"id":13117430}]}]}
{"op":"mcm","clk":"1007755248","pt":1580656760370,"mc":[{"id":"1.168224445","rc":[{"batb":[[0,4.3,27.47]],"ltp":0.0,"tv":0.0,"id":13117431},{"batb":[[0,2.94,24.39],[1,2.88,21.85],[2,2.8,11.09]],"ltp":0.0,"tv":0.0,"id":13117430}]}]}
{"op":"mcm","clk":"1007755364","pt":1580656760844,"mc":[{"id":"1.168224445","rc":[{"batb":[[0,3.6,55.19]],"ltp":4.2,"tv":3.36,"id":16569868}]}]}
{"op":"mcm","clk":"1007755731","pt":1580656762433,"mc":[{"id":"1.168224445","rc":[{"batb":[[0,2.98,53.75],[1,2.94,70.64],[2,2.88,21.85]],"ltp":0.0,"tv":0.0,"id":13117430},{"batb":[[0,5.2,34.69]],"ltp":5.0,"tv":9.08,"id":16569870}]}]}
{"op":"mcm","clk":"1007765965","pt":1580656808006,"mc":[{"id":"1.168224445","rc":[{"batb":[[0,4.2,48.18],[1,4.1,34.06],[2,1.01,0.51]],"ltp":0.0,"tv":0.0,"id":13117431},{"batb":[[0,2.88,21.85],[1,2.8,11.09],[2,1.01,0.51]],"batl":[[0,3.35,17.64],[1,3.7,17.15],[2,3.7,0]],"ltp":0.0,"tv":0.0,"id":13117430},{"batb":[[0,3.35,17.64],[1,3.1,20.69],[2,1.01,0.51]],"batl":[[1,4.2,25.65],[2,4.2,0]],"ltp":4.2,"tv":3.36,"id":16569868},{"batb":[[0,5.1,30.31],[1,5,10.08],[2,4.9,13.53]],"ltp":5.0,"tv":9.08,"id":16569870}]}]}
{"op":"mcm","clk":"1007766186","pt":1580656809026,"mc":[{"id":"1.168224445","rc":[{"batb":[[1,4.1,20.61]],"batl":[[1,5,0]],"ltp":0.0,"tv":0.0,"id":13117431},{"batb":[[0,2.8,11.09],[1,1.01,0.51],[2,1.01,0]],"batl":[[0,3.7,17.15],[1,3.7,0]],"ltp":0.0,"tv":0.0,"id":13117430},{"batb":[[0,3.1,20.69],[1,1.01,0.51],[2,1.01,0]],"batl":[[0,4.2,25.65],[1,4.2,0]],"ltp":4.2,"tv":3.36,"id":16569868},{"batb":[[1,4.9,13.53],[2,1.01,0.51]],"batl":[[1,6.2,0]],"ltp":5.0,"tv":9.08,"id":16569870}]}]}
{"op":"mcm","clk":"1007766640","pt":1580656811255,"mc":[{"id":"1.168224445","rc":[{"batb":[[1,4.1,71.66]],"ltp":0.0,"tv":0.0,"id":13117431},{"batl":[[0,4.3,25.57]],"ltp":4.2,"tv":3.36,"id":16569868},{"batb":[[0,5.1,30.35]],"ltp":5.0,"tv":9.08,"id":16569870}]}]}
{"op":"mcm","clk":"1007767106","pt":1580656813341,"mc":[{"id":"1.168224445","rc":[{"batb":[[0,4.2,69.62]],"ltp":0.0,"tv":0.0,"id":13117431},{"batb":[[0,3.05,56.04],[1,3,54.74],[2,2.8,11.09]],"ltp":0.0,"tv":0.0,"id":13117430},{"batb":[[0,3.55,36.21],[1,3.5,36.99],[2,3.1,20.69]],"ltp":4.2,"tv":3.36,"id":16569868},{"batb":[[0,5.2,31.2],[1,5.1,30.35],[2,4.9,13.53]],"ltp":5.0,"tv":9.08,"id":16569870}]}]}
{"op":"mcm","clk":"1007767647","pt":1580656815917,"mc":[{"id":"1.168224445","rc":[{"batb":[[0,4.2,48.18]],"ltp":0.0,"tv":0.0,"id":13117431},{"batb":[[0,2.8,11.09],[1,1.01,0.51],[2,2.8,0]],"ltp":0.0,"tv":0.0,"id":13117430},{"batb":[[0,3.1,20.69],[1,1.01,0.51],[2,3.1,0]],"ltp":4.2,"tv":3.36,"id":16569868},{"batb":[[0,5.1,30.35],[1,4.9,13.53],[2,1.01,0.51]],"ltp":5.0,"tv":9.08,"id":16569870}]}]}
{"op":"mcm","clk":"1007768408","pt":1580656819335,"mc":[{"id":"1.168224445","rc":[{"batb":[[0,3.2,73.48],[1,3.15,47.64],[2,3.1,20.69]],"ltp":4.2,"tv":3.36,"id":16569868},{"batb":[[0,5.1,48.59],[1,5,31.51],[2,4.9,13.53]],"ltp":5.0,"tv":9.08,"id":16569870}]}]}
{"op":"mcm","clk":"1007768790","pt":1580656821118,"mc":[{"id":"1.168224445","rc":[{"batb":[[0,3.4,36.48],[1,3.35,41.82],[2,2.8,11.09]],"ltp":0.0,"tv":0.0,"id":13117430}]}]}
{"op":"mcm","clk":"1007769085","pt":1580656822435,"mc":[{"id":"1.168224445","rc":[{"batb":[[1,4.1,85.11],[2,4,21.95]],"batl":[[0,4.8,19.12],[1,4.9,10.08]],"ltp":0.0,"tv":0.0,"id":13117431},{"batb":[[2,3.3,17.78]],"batl":[[1,4.7,20.38]],"ltp":0.0,"tv":0.0,"id":13117430},{"batl":[[0,3.5,19.91],[1,3.8,16.21]],"ltp":4.2,"tv":3.36,"id":16569868},{"batb":[[1,5,41.59]],"batl":[[1,6,8.4]],"ltp":5.0,"tv":9.08,"id":16569870}]}]}
{"op":"mcm","clk":"1007769586","pt":1580656824430,"mc":[{"id":"1.168224445","rc":[{"batl":[[1,3.8,14.28],[2,4.7,20.38]],"ltp":0.0,"tv":0.0,"id":13117430},{"batl":[[0,3.5,36.71]],"ltp":4.2,"tv":3.36,"id":16569868}]}]}
{"op":"mcm","clk":"1007771486","pt":1580656832377,"mc":[{"id":"1.168224445","rc":[{"batb":[[0,4.1,52.08],[1,4,21.95],[2,1.01,0.51]],"ltp":0.0,"tv":0.0,"id":13117431},{"batb":[[0,3.25,18.48],[1,3.05,22.19],[2,1.01,0.51]],"batl":[[0,3.8,14.28],[1,4.7,20.38],[2,4.7,0]],"ltp":0.0,"tv":0.0,"id":13117430},{"batb":[[0,3,21],[1,2.72,11.8],[2,1.01,0.51]],"batl":[[0,3.5,16.8]],"ltp":4.2,"tv":3.36,"id":16569868},{"batb":[[0,5.1,31]],"ltp":5.0,"tv":9.08,"id":16569870}]}]}
{"op":"mcm","clk":"1007771614","pt":1580656832871,"mc":[{"id":"1.168224445","rc":[{"batb":[[0,4.1,38.64]],"batl":[[1,4.9,0]],"ltp":0.0,"tv":0.0,"id":13117431},{"batb":[[0,3.05,22.19],[1,1.01,0.51],[2,1.01,0]],"batl":[[0,4.7,20.38],[1,4.7,0]],"ltp":0.0,"tv":0.0,"id":13117430},{"batb":[[0,2.72,11.8],[1,1.01,0.51],[2,1.01,0]],"batl":[[0,3.8,16.21],[1,3.8,0]],"ltp":4.2,"tv":3.36,"id":16569868},{"batb":[[1,5,31.51]],"batl":[[1,6,0]],"ltp":5.0,"tv":9.08,"id":16569870}]}]}
{"op":"mcm","clk":"1007772455","pt":1580656836364,"mc":[{"id":"1.168224445","rc":[{"batb":[[0,4.2,30.48],[1,4.1,51.25],[2,4,21.95]],"ltp":0.0,"tv":0.0,"id":13117431},{"batb":[[0,3.5,61.4],[1,3.45,38.72],[2,3.05,22.19]],"ltp":0.0,"tv":0.0,"id":13117430},{"batb":[[0,3.1,81.18],[1,3.05,51.62],[2,2.72,11.8]],"ltp":4.2,"tv":3.36,"id":16569868},{"batb":[[0,5.1,45.1]],"ltp":5.0,"tv":9.08,"id":16569870}]}]}
{"op":"mcm","clk":"1007773394","pt":1580656840349,"mc":[{"id":"1.168224445","rc":[{"batb":[[0,4.1,38.64],[1,4,21.95],[2,1.01,0.51]],"ltp":0.0,"tv":0.0,"id":13117431},{"batb":[[0,3.05,22.19],[1,1.01,0.51],[2,3.05,0]],"ltp":0.0,"tv":0.0,"id":13117430},{"batb":[[0,2.72,11.8],[1,1.01,0.51],[2,2.72,0]],"ltp":4.2,"tv":3.36,"id":16569868},{"batb":[[0,5.1,31.65]],"ltp":5.0,"tv":9.08,"id":16569870}]}]}
{"op":"mcm","clk":"1007773978","pt":1580656842881,"mc":[{"id":"1.168224445","rc":[{"batb":[[1,4,76.18]],"ltp":0.0,"tv":0.0,"id":13117431},{"batb":[[0,3.05,106.68],[1,3,54.47],[2,1.01,0.51]],"ltp":0.0,"tv":0.0,"id":13117430},{"batb":[[0,2.8,54.49],[1,2.76,53.87],[2,2.72,11.8]],"ltp":4.2,"tv":3.36,"id":16569868}]}]}
{"op":"mcm","clk":"1007776297","pt":1580656853391,"mc":[{"id":"1.168224445","rc":[{"batb":[[1,4,21.95]],"ltp":0.0,"tv":0.0,"id":13117431},{"batb":[[0,2.72,11.8],[1,1.01,0.51],[2,2.72,0]],"ltp":4.2,"tv":3.36,"id":16569868},{"batb":[[0,5.1,31],[1,4.9,13.53],[2,1.01,0.51]],"ltp":5.0,"tv":9.08,"id":16569870}]}]}
{"op":"mcm","clk":"1007776943","pt":1580656856274,"mc":[{"id":"1.168224445","rc":[{"batb":[[0,4.2,69.16],[1,4.1,50.5],[2,4,21.95]],"ltp":0.0,"tv":0.0,"id":13117431},{"batb":[[0,3.5,52.1],[1,3.45,38.18],[2,2.72,11.8]],"ltp":4.2,"tv":3.36,"id":16569868},{"batb":[[0,5.2,27.44],[1,5.1,31],[2,4.9,13.53]],"ltp":5.0,"tv":9.08,"id":16569870}]}]}
{"op":"mcm","clk":"1007777159","pt":1580656857295,"mc":[{"id":"1.168224445","rc":[{"batb":[[1,4.1,71.9],[2,1.01,0.51]],"batl":[[1,4.9,18.73]],"ltp":0.0,"tv":0.0,"id":13117431},{"batb":[[2,2.86,10.46]],"batl":[[0,3.4,21.32],[1,4.1,13.93]],"ltp":0.0,"tv":0.0,"id":13117430},{"batb":[[2,3.4,16.76]],"batl":[[1,4.1,13.77]],"ltp":4.2,"tv":3.36,"id":16569868},{"batl":[[0,5.7,13.14],[1,5.8,12.83]],"ltp":5.0,"tv":9.08,"id":16569870}]}]}
{"op":"mcm","clk":"1007777257","pt":1580656857783,"mc":[{"id":"1.168224445","rc":[{"batb":[[1,4.1,85.34]],"batl":[[1,4.9,28.81]],"ltp":0.0,"tv":0.0,"id":13117431},{"batb":[[1,3,75.47]],"batl":[[1,3.5,16.8],[2,4.1,13.93]],"ltp":0.0,"tv":0.0,"id":13117430},{"batl":[[0,3.8,30.49]],"ltp":4.2,"tv":3.36,"id":16569868},{"batb":[[2,5,10.08]],"batl":[[2,6,8.4]],"ltp":5.0,"tv":9.08,"id":16569870}]}]}
{"op":"mcm","clk":"1007781483","pt":1580656876008,"mc":[{"id":"1.168224445","rc":[{"batb":[[0,4.1,85.34],[1,1.01,0.51],[2,1.01,0]],"batl":[[0,4.9,28.81],[1,4.9,0]],"ltp":0.0,"tv":0.0,"id":13117431},{"batb":[[0,3,21],[1,2.86,10.46],[2,1.01,0.51]],"batl":[[0,3.5,16.8],[1,4.1,13.93],[2,4.1,0]],"ltp":0.0,"tv":0.0,"id":13117430},{"batb":[[0,3.25,18.48],[1,2.94,24.16],[2,1.01,0.51]],"batl":[[0,3.8,14.28]],"ltp":4.2,"tv":3.36,"id":16569868},{"batb":[[0,5.1,31],[1,5,10.08],[2,4.9,13.53]],"batl":[[0,5.8,12.83],[1,6,8.4],[2,6,0]],"ltp":5.0,"tv":9.08,"id":16569870}]}]}
{"op":"mcm","clk":"1007781692","pt":1580656876912,"mc":[{"id":"1.168224445","rc":[{"batb":[[0,4.1,71.9]],"batl":[[0,4.9,18.73]],"ltp":0.0,"tv":0.0,"id":13117431},{"batb":[[0,2.86,10.46],[1,1.01,0.51],[2,1.01,0]],"batl":[[0,4.1,13.93],[1,4.1,0]],"ltp":0.0,"tv":0.0,"id":13117430},{"batb":[[0,2.94,24.16],[1,1.01,0.51],[2,1.01,0]],"batl":[[0,4.1,13.77],[1,4.1,0]],"ltp":4.2,"tv":3.36,"id":16569868},{"batb":[[1,4.9,13.53],[2,1.01,0.51]],"batl":[[1,6,0]],"ltp":5.0,"tv":9.08,"id":16569870}]}]}
{"op":"mcm","clk":"1007782205","pt":1580656879298,"mc":[{"id":"1.168224445","rc":[{"batb":[[0,4.1,21.4]],"ltp":0.0,"tv":0.0,"id":13117431},{"batb":[[0,5.1,30.31]],"ltp":5.0,"tv":9.08,"id":16569870}]}]}
{"op":"mcm","clk":"1007782883","pt":1580656882384,"mc":[{"id":"1.168224445","rc":[{"batb":[[0,4.3,44.7],[1,4.2,48.1],[2,4.1,21.4]],"ltp":0.0,"tv":0.0,"id":13117431},{"batb":[[0,2.86,58.62],[1,2.82,51.44],[2,1.01,0.51]],"ltp":0.0,"tv":0.0,"id":13117430},{"batb":[[0,3.8,42.38],[1,3.75,31.25],[2,2.94,24.16]],"ltp":4.2,"tv":3.36,"id":16569868},{"batb":[[0,5.2,36.87],[1,5.1,30.31],[2,4.9,13.53]],"ltp":5.0,"tv":9.08,"id":16569870}]}]}
{"op":"mcm","clk":"1007783055","pt":1580656883077,"mc":[{"id":"1.168224445","rc":[{"batb":[[1,4.2,68.24],[2,1.01,0.51]],"batl":[[0,4.9,18.33]],"ltp":0.0,"tv":0.0,"id":13117431},{"batb":[[2,2.72,11.8]],"batl":[[0,3.15,25.1],[1,3.6,18.73]],"ltp":0.0,"tv":0.0,"id":13117430},{"batb":[[2,3.65,14.24]],"batl":[[1,4.4,23.68]],"ltp":4.2,"tv":3.36,"id":16569868}]}]}
{"op":"mcm","clk":"1007783284","pt":1580656884226,"mc":[{"id":"1.168224445","rc":[{"batb":[[1,4.2,80.85]],"batl":[[1,5,10.08]],"ltp":0.0,"tv":0.0,"id":13117431},{"batb":[[2,2.8,22.69]],"batl":[[1,3.2,18.48],[2,3.6,18.73]],"ltp":0.0,"tv":0.0,"id":13117430},{"batl":[[0,4.1,27.21]],"ltp":4.2,"tv":3.36,"id":16569868},{"batb":[[2,5,10.08]],"batl":[[1,6.2,7.56]],"ltp":5.0,"tv":9.08,"id":16569870}]}]}
{"op":"mcm","clk":"1007784965","pt":1580656891934,"mc":[{"id":"1.168224445","rc":[{"batb":[[0,4.2,80.85],[1,1.01,0.51],[2,1.01,0]],"ltp":0.0,"tv":0.0,"id":13117431},{"batb":[[0,2.8,22.69],[1,2.72,11.8],[2,1.01,0.51]],"batl":[[0,3.2,18.48],[1,3.6,18.73],[2,3.6,0]],"ltp":0.0,"tv":0.0,"id":13117430},{"batb":[[0,3.45,16.8],[1,3.2,19.12],[2,1.01,0.51]],"batl":[[0,4.1,13.44]],"ltp":4.2,"tv":3.36,"id":16569868},{"batb":[[0,5.1,30.31],[1,5,10.08],[2,4.9,13.53]],"ltp":5.0,"tv":9.08,"id":16569870}]}]}
{"op":"mcm","clk":"1007785226","pt":1580656893227,"mc":[{"id":"1.168224445","rc":[{"batb":[[0,4.2,68.24]],"batl":[[1,5,0]],"ltp":0.0,"tv":0.0,"id":13117431},{"batb":[[0,2.72,11.8],[1,1.01,0.51],[2,1.01,0]],"batl":[[0,3.6,18.73],[1,3.6,0]],"ltp":0.0,"tv":0.0,"id":13117430},{"batb":[[0,3.2,19.12],[1,1.01,0.51],[2,1.01,0]],"batl":[[0,4.4,23.68],[1,4.4,0]],"ltp":4.2,"tv":3.36,"id":16569868},{"batb":[[1,4.9,13.53],[2,1.01,0.51]],"batl":[[1,6.2,0]],"ltp":5.0,"tv":9.08,"id":16569870}]}]}
{"op":"mcm","clk":"1007785636","pt":1580656895195,"mc":[{"id":"1.168224445","rc":[{"batb":[[0,4.2,68.36]],"ltp":0.0,"tv":0.0,"id":13117431}]}]}
{"op":"mcm","clk":"1007786264","pt":1580656898011,"mc":[{"id":"1.168224445","rc":[{"batb":[[0,4.3,38.45],[1,4.2,68.36],[2,1.01,0.51]],"ltp":0.0,"tv":0.0,"id":13117431},{"batb":[[0,2.92,50.58],[1,2.88,48.74],[2,2.72,11.8]],"ltp":0.0,"tv":0.0,"id":13117430},{"batb":[[0,3.7,49.77],[1,3.65,33.29],[2,3.2,19.12]],"ltp":4.2,"tv":3.36,"id":16569868},{"batb":[[0,5.2,33.29],[1,5.1,30.31],[2,4.9,13.53]],"ltp":5.0,"tv":9.08,"id":16569870}]}]}
{"op":"mcm","clk":"1007786731","pt":1580656900135,"mc":[{"id":"1.168224445","rc":[{"batb":[[0,4.2,68.36],[1,1.01,0.51],[2,1.01,0]],"ltp":0.0,"tv":0.0,"id":13117431},{"batb":[[0,2.72,11.8],[1,1.01,0.51],[2,2.72,0]],"ltp":0.0,"tv":0.0,"id":13117430},{"batb":[[0,3.2,19.12],[1,1.01,0.51],[2,3.2,0]],"ltp":4.2,"tv":3.36,"id":16569868}]}]}
{"op":"mcm","clk":"1007787688","pt":1580656904257,"mc":[{"id":"1.168224445","rc":[{"batb":[[0,4.2,68.24],[1,4.1,50.65],[2,1.01,0.51]],"ltp":0.0,"tv":0.0,"id":13117431},{"batb":[[1,2.7,46.89],[2,2.66,59.68]],"ltp":0.0,"tv":0.0,"id":13117430},{"batb":[[0,3.4,57.26],[1,3.35,41.21],[2,3.2,19.12]],"ltp":4.2,"tv":3.36,"id":16569868},{"batb":[[1,4.9,13.53],[2,1.01,0.51]],"ltp":5.0,"tv":9.08,"id":16569870}]}]}
{"op":"mcm","clk":"1007787911","pt":1580656905238,"mc":[{"id":"1.168224445","rc":[{"batb":[[1,1.01,0.51],[2,1.01,0]],"ltp":0.0,"tv":0.0,"id":13117431},{"batb":[[1,2.66,59.68],[2,1.01,0.51]],"ltp":0.0,"tv":0.0,"id":13117430},{"batb":[[0,3.2,19.12],[1,1.01,0.51],[2,3.2,0]],"ltp":4.2,"tv":3.36,"id":16569868}]}]}
{"op":"mcm","clk":"1007788446","pt":1580656907260,"mc":[{"id":"1.168224445","rc":[{"batb":[[0,4.3,47.85],[1,4.2,67.61],[2,1.01,0.51]],"ltp":0.0,"tv":0.0,"id":13117431},{"batb":[[2,2.64,12.9]],"batl":[[0,2.98,11.64],[1,3.2,24.23]],"ltp":0.0,"tv":0.0,"id":13117430},{"batb":[[0,4.1,31.69],[1,4,53.39],[2,3.85,25.1]],"batl":[[1,4.6,21.4]],"ltp":4.2,"tv":3.36,"id":16569868},{"batb":[[0,5.3,29.73],[1,5.2,33.29],[2,4.9,13.53]],"batl":[[0,5.9,12.59]],"ltp":5.0,"tv":9.08,"id":16569870}]}]}
{"op":"mcm","clk":"1007788696","pt":1580656908233,"mc":[{"id":"1.168224445","rc":[{"batb":[[1,4.2,80.22]],"batl":[[1,5,10.08]],"ltp":0.0,"tv":0.0,"id":13117431},{"batb":[[1,2.7,45.02],[2,2.66,84.89]],"batl":[[1,3.05,20.16],[2,3.2,24.23]],"ltp":0.0,"tv":0.0,"id":13117430},{"batl":[[0,4.4,35.45]],"ltp":4.2,"tv":3.36,"id":16569868},{"batb":[[2,5.1,10.08]],"batl":[[1,6.2,7.56]],"ltp":5.0,"tv":9.08,"id":16569870}]}]}
{"op":"mcm","clk":"1007791944","pt":1580656923014,"mc":[{"id":"1.168224445","rc":[{"batb":[[0,4.3,38.98],[1,4.2,67.61]],"batl":[[1,5,0]],"ltp":0.0,"tv":0.0,"id":13117431},{"batb":[[0,2.64,12.9],[1,1.01,0.51],[2,2.66,0]],"batl":[[0,3.2,24.23],[1,3.05,0],[2,3.2,0]],"ltp":0.0,"tv":0.0,"id":13117430},{"batb":[[0,3.55,14.87],[1,1.01,0.51],[2,3.85,0]],"batl":[[0,4.6,21.4],[1,4.6,0]],"ltp":4.2,"tv":3.36,"id":16569868},{"batb":[[0,5.2,33.29],[1,4.9,13.53],[2,1.01,0.51]],"batl":[[1,6.2,0]],"ltp":5.0,"tv":9.08,"id":16569870}]}]}
{"op":"mcm","clk":"1007792553","pt":1580656925694,"mc":[{"id":"1.168224445","rc":[{"batb":[[1,2.62,58.02],[2,2.58,64.69]],"ltp":0.0,"tv":0.0,"id":13117430},{"batb":[[0,3.8,43.46],[1,3.75,31.42],[2,3.55,14.87]],"ltp":4.2,"tv":3.36,"id":16569868},{"batb":[[0,5.2,42.57],[1,5.1,30.36],[2,4.9,13.53]],"ltp":5.0,"tv":9.08,"id":16569870}]}]}
{"op":"mcm","clk":"1007793635","pt":1580656930530,"mc":[{"id":"1.168224445","rc":[{"batb":[[0,3.55,14.87],[1,1.01,0.51],[2,3.55,0]],"ltp":4.2,"tv":3.36,"id":16569868},{"batb":[[0,5.2,33.29],[1,4.9,13.53],[2,1.01,0.51]],"ltp":5.0,"tv":9.08,"id":16569870}]}]}
{"op":"mcm","clk":"1007794246","pt":1580656933304,"mc":[{"id":"1.168224445","rc":[{"batb":[[0,4.3,52.3]],"ltp":0.0,"tv":0.0,"id":13117431},{"batb":[[0,4.2,56.85],[1,4.1,49.94],[2,3.55,14.87]],"ltp":4.2,"tv":3.36,"id":16569868},{"batb":[[0,5.3,38.29],[1,5.2,33.29],[2,4.9,13.53]],"ltp":5.0,"tv":9.08,"id":16569870}]}]}
{"op":"mcm","clk":"1007794466","pt":1580656934322,"mc":[{"id":"1.168224445","rc":[{"batb":[[1,4.2,80.22]],"batl":[[0,5,10.08],[1,5.1,17.39]],"ltp":0.0,"tv":0.0,"id":13117431},{"batl":[[0,2.88,12.67],[1,2.9,21.85],[2,3.1,10.62]],"ltp":0.0,"tv":0.0,"id":13117430},{"batb":[[2,4,22.58]],"batl":[[1,4.7,10.92],[2,5.4,15.03]],"ltp":4.2,"tv":3.36,"id":16569868},{"batb":[[1,5.2,42.53],[2,5,13.14]],"batl":[[0,5.9,12.35],[1,6.4,7.56]],"ltp":5.0,"tv":9.08,"id":16569870}]}]}
{"op":"mcm","clk":"1007800043","pt":1580656959230,"mc":[{"id":"1.168224445","rc":[{"batb":[[0,4.3,25.2],[1,4.2,67.61]],"batl":[[0,5.1,17.39],[1,5.1,0]],"ltp":0.0,"tv":0.0,"id":13117431},{"batb":[[0,2.38,17.07],[1,1.01,0.51],[2,2.58,0]],"batl":[[0,3.1,10.62],[1,2.9,0],[2,3.1,0]],"ltp":0.0,"tv":0.0,"id":13117430},{"batb":[[0,3.75,13.22],[1,1.01,0.51],[2,4,0]],"batl":[[0,5.4,15.03],[1,4.7,0],[2,5.4,0]],"ltp":4.2,"tv":3.36,"id":16569868},{"batb":[[0,5.3,23.28],[1,5.2,33.29],[2,4.9,13.53]],"batl":[[1,6.4,0]],"ltp":5.0,"tv":9.08,"id":16569870}]}]}
{"op":"mcm","clk":"1007800731","pt":1580656962444,"mc":[{"id":"1.168224445","rc":[{"batb":[[1,2.36,68.9],[2,2.32,86.14]],"ltp":0.0,"tv":0.0,"id":13117430},{"batb":[[0,3.95,25.87],[1,3.9,28.74],[2,3.75,13.22]],"ltp":4.2,"tv":3.36,"id":16569868}]}]}
{"op":"mcm","clk":"1007801564","pt":1580656966340,"mc":[{"id":"1.168224445","rc":[{"batb":[[1,1.01,0.51],[2,2.32,0]],"ltp":0.0,"tv":0.0,"id":13117430}]}]}
{"op":"mcm","clk":"1007802222","pt":1580656969366,"mc":[{"id":"1.168224445","rc":[{"batb":[[0,2.8,44.76],[1,2.76,54.2],[2,2.38,17.07]],"ltp":0.0,"tv":0.0,"id":13117430}]}]}
{"op":"mcm","clk":"1007802442","pt":1580656970363,"mc":[{"id":"1.168224445","rc":[{"batb":[[2,4.1,13.44]],"batl":[[0,4.9,29.12],[1,5,18.02]],"ltp":0.0,"tv":0.0,"id":13117431},{"batb":[[0,2.82,10.86],[1,2.8,44.76],[2,2.76,54.2]],"batl":[[0,3.1,29.95],[1,3.3,23.05]],"ltp":0.0,"tv":0.0,"id":13117430},{"batl":[[0,4.2,25.65],[1,4.4,11.76],[2,4.8,19.28]],"ltp":4.2,"tv":3.36,"id":16569868},{"batb":[[2,5.1,10.08]],"batl":[[1,6.2,7.56]],"ltp":5.0,"tv":9.08,"id":16569870}]}]}
{"op":"mcm","clk":"1007804196","pt":1580656978019,"mc":[{"id":"1.168224445","rc":[{"batb":[[0,3.9,28.74],[1,3.75,13.22],[2,3.7,15.12]],"ltp":4.2,"tv":3.36,"id":16569868}]}]}
{"op":"mcm","clk":"1007804876","pt":1580656980871,"mc":[{"id":"1.168224445","rc":[{"batb":[[0,3.9,54.66],[1,3.85,29.37],[2,3.75,13.22]],"ltp":4.2,"tv":3.36,"id":16569868}]}]}
{"op":"mcm","clk":"1007805230","pt":1580656982374,"mc":[{"id":"1.168224445","rc":[{"batb":[[0,4.2,67.61],[1,4.1,13.44],[2,1.01,0.51]],"batl":[[0,4.9,10.08]],"ltp":0.0,"tv":0.0,"id":13117431},{"batb":[[0,2.66,25.21],[1,2.56,14.08],[2,1.01,0.51]],"batl":[[0,3.1,19.32]],"ltp":0.0,"tv":0.0,"id":13117430},{"batb":[[0,3.7,15.12],[1,3.55,15.19],[2,1.01,0.51]],"batl":[[0,4.4,11.76],[1,4.8,19.28],[2,4.8,0]],"ltp":4.2,"tv":3.36,"id":16569868},{"batb":[[0,5.2,33.29],[1,5.1,10.08],[2,4.9,13.53]],"ltp":5.0,"tv":9.08,"id":16569870}]}]}
{"op":"mcm","clk":"1007805435","pt":1580656983300,"mc":[{"id":"1.168224445","rc":[{"batb":[[1,1.01,0.51],[2,1.01,0]],"batl":[[0,5,18.02],[1,5,0]],"ltp":0.0,"tv":0.0,"id":13117431},{"batb":[[0,2.56,14.08],[1,1.01,0.51],[2,1.01,0]],"batl":[[0,3.3,23.05],[1,3.3,0]],"ltp":0.0,"tv":0.0,"id":13117430},{"batb":[[0,3.55,15.19],[1,1.01,0.51],[2,1.01,0]],"batl":[[0,4.8,19.28],[1,4.8,0]],"ltp":4.2,"tv":3.36,"id":16569868},{"batb":[[1,4.9,13.53],[2,1.01,0.51]],"batl":[[1,6.2,0]],"ltp":5.0,"tv":9.08,"id":16569870}]}]}
{"op":"mcm","clk":"1007805864","pt":1580656985073,"mc":[{"id":"1.168224445","rc":[{"batb":[[1,4.1,50.41],[2,1.01,0.51]],"ltp":0.0,"tv":0.0,"id":13117431},{"batb":[[0,2.56,62.99],[1,2.52,68.84],[2,1.01,0.51]],"ltp":0.0,"tv":0.0,"id":13117430},{"batb":[[0,3.7,46.6],[1,3.65,33.45],[2,3.55,15.19]],"ltp":4.2,"tv":3.36,"id":16569868},{"batb":[[1,5.1,30.37],[2,4.9,13.53]],"ltp":5.0,"tv":9.08,"id":16569870}]}]}
{"op":"mcm","clk":"1007809542","pt":1580657001157,"mc":[{"id":"1.168224445","rc":[{"batb":[[0,2.56,14.08],[1,1.01,0.51],[2,1.01,0]],"ltp":0.0,"tv":0.0,"id":13117430}]}]}
{"op":"mcm","clk":"1007810244","pt":1580657004163,"mc":[{"id":"1.168224445","rc":[{"batb":[[0,2.96,35.17],[1,2.92,46.98],[2,2.56,14.08]],"ltp":0.0,"tv":0.0,"id":13117430}]}]}
{"op":"mcm","clk":"1007810534","pt":1580657005441,"mc":[{"id":"1.168224445","rc":[{"batb":[[0,4.2,48.1],[1,4.1,71.02]],"batl":[[0,4.9,18.8]],"ltp":0.0,"tv":0.0,"id":13117431},{"batb":[[0,2.96,59.17],[2,2.76,11.57]],"batl":[[1,3.45,20.77]],"ltp":0.0,"tv":0.0,"id":13117430},{"batl":[[0,3.95,14.71],[1,4.4,23.68]],"ltp":4.2,"tv":3.36,"id":16569868},{"batl":[[0,5.8,12.98]],"ltp":5.0,"tv":9.08,"id":16569870}]}]}
{"op":"mcm","clk":"1007810635","pt":1580657005833,"mc":[{"id":"1.168224445","rc":[{"batb":[[2,4,13.44]],"batl":[[0,4.8,10.92],[1,4.9,18.8]],"ltp":0.0,"tv":0.0,"id":13117431},{"batb":[[2,2.82,22.69]],"batl":[[0,3.3,40.7]],"ltp":0.0,"tv":0.0,"id":13117430},{"batl":[[1,4.1,13.44],[2,4.4,23.68]],"ltp":4.2,"tv":3.36,"id":16569868},{"batb":[[2,5,10.08]],"batl":[[1,6.2,7.56]],"ltp":5.0,"tv":9.08,"id":16569870}]}]}
{"op":"mcm","clk":"1007814143","pt":1580657020375,"mc":[{"id":"1.168224445","rc":[{"batb":[[0,2.82,22.69],[1,2.76,11.57],[2,1.01,0.51]],"batl":[[0,3.3,17.64]],"ltp":0.0,"tv":0.0,"id":13117430},{"batb":[[0,3.5,16.8],[1,3.4,16.76],[2,1.01,0.51]],"batl":[[0,4.1,13.44],[1,4.4,23.68],[2,4.4,0]],"ltp":4.2,"tv":3.36,"id":16569868}]}]}
{"op":"mcm","clk":"1007814288","pt":1580657020948,"mc":[{"id":"1.168224445","rc":[{"batb":[[2,1.01,0.51]],"batl":[[0,4.9,18.8],[1,4.9,0]],"ltp":0.0,"tv":0.0,"id":13117431},{"batb":[[0,2.76,11.57],[1,1.01,0.51],[2,1.01,0]],"batl":[[0,3.45,20.77],[1,3.45,0]],"ltp":0.0,"tv":0.0,"id":13117430},{"batb":[[0,3.4,16.76],[1,1.01,0.51],[2,1.01,0]],"batl":[[0,4.4,23.68],[1,4.4,0]],"ltp":4.2,"tv":3.36,"id":16569868},{"batb":[[2,4.9,13.53]],"batl":[[1,6.2,0]],"ltp":5.0,"tv":9.08,"id":16569870}]}]}
{"op":"mcm","clk":"1007814829","pt":1580657023378,"mc":[{"id":"1.168224445","rc":[{"batb":[[1,2.74,11.57],[2,1.01,0.51]],"batl":[[0,3.4,20.85],[1,3.45,20.77]],"ltp":0.0,"tv":0.0,"id":13117430}]}]}
{"op":"mcm","clk":"1007814895","pt":1580657023676,"mc":[{"id":"1.168224445","rc":[{"batb":[[0,2.74,11.57],[1,1.01,0.51],[2,1.01,0]],"batl":[[1,3.45,0]],"ltp":0.0,"tv":0.0,"id":13117430},{"batl":[[0,4.4,23.53]],"ltp":4.2,"tv":3.36,"id":16569868}]}]}
{"op":"mcm","clk":"1007815711","pt":1580657027374,"mc":[{"id":"1.168224445","rc":[{"batl":[[0,4.8,19.43]],"ltp":0.0,"tv":0.0,"id":13117431},{"batb":[[0,3.05,82.84],[1,3,54.43],[2,2.9,25.34]],"batl":[[1,3.5,19.59]],"ltp":0.0,"tv":0.0,"id":13117430},{"batb":[[0,3.55,56.78],[1,3.5,36.93],[2,3.4,16.76]],"batl":[[0,3.8,16.13],[1,4.1,13.93]],"ltp":4.2,"tv":3.36,"id":16569868}]}]}
{"op":"mcm","clk":"1007815967","pt":1580657028379,"mc":[{"id":"1.168224445","rc":[{"batb":[[2,4,13.44]],"batl":[[0,4.8,30.36]],"ltp":0.0,"tv":0.0,"id":13117431},{"batb":[[2,2.96,21]],"batl":[[1,3.45,16.8],[2,3.5,19.59]],"ltp":0.0,"tv":0.0,"id":13117430},{"batl":[[1,3.95,13.44],[2,4.1,13.93]],"ltp":4.2,"tv":3.36,"id":16569868},{"batb":[[2,5,10.08]],"batl":[[1,6,8.4]],"ltp":5.0,"tv":9.08,"id":16569870}]}]}
{"op":"mcm","clk":"1007817578","pt":1580657035188,"mc":[{"id":"1.168224445","rc":[{"batb":[[2,1.01,0.51]],"batl":[[0,4.8,19.43]],"ltp":0.0,"tv":0.0,"id":13117431},{"batb":[[0,2.9,25.34],[1,1.01,0.51],[2,2.96,0]],"batl":[[0,3.5,19.59],[1,3.45,0],[2,3.5,0]],"ltp":0.0,"tv":0.0,"id":13117430},{"batb":[[0,3.5,36.93],[1,3.3,17.78],[2,1.01,0.51]],"batl":[[0,4.1,13.93],[1,3.95,0],[2,4.1,0]],"ltp":4.2,"tv":3.36,"id":16569868},{"batb":[[0,5.2,20.43],[2,4.9,13.53]],"batl":[[1,6,0]],"ltp":5.0,"tv":9.08,"id":16569870}]}]}
{"op":"mcm","clk":"1007818067","pt":1580657037363,"mc":[{"id":"1.168224445","rc":[{"batb":[[0,2.94,44.38],[1,2.9,73.08],[2,1.01,0.51]],"ltp":0.0,"tv":0.0,"id":13117430},{"batb":[[1,3.45,38.43],[2,3.3,17.78]],"ltp":4.2,"tv":3.36,"id":16569868}]}]}
{"op":"mcm","clk":"1007820696","pt":1580657049231,"mc":[{"id":"1.168224445","rc":[{"batb":[[0,3.3,17.78],[1,1.01,0.51],[2,3.3,0]],"ltp":4.2,"tv":3.36,"id":16569868}]}]}
{"op":"mcm","clk":"1007821280","pt":1580657052112,"mc":[{"id":"1.168224445","rc":[{"batb":[[0,3.75,28.66],[1,3.7,32.53],[2,3.3,17.78]],"ltp":4.2,"tv":3.36,"id":16569868},{"batb":[[0,5.2,46.12]],"ltp":5.0,"tv":9.08,"id":16569870}]}]}
{"op":"mcm","clk":"1007821524","pt":1580657053207,"mc":[{"id":"1.168224445","rc":[{"batl":[[0,4.9,18.96]],"ltp":0.0,"tv":0.0,"id":13117431},{"batb":[[2,2.7,12.04]],"batl":[[0,3.2,24.31],[1,3.35,22.27]],"ltp":0.0,"tv":0.0,"id":13117430},{"batb":[[2,3.6,14.4]],"batl":[[1,4.5,22.66]],"ltp":4.2,"tv":3.36,"id":16569868},{"batl":[[0,5.9,12.67]],"ltp":5.0,"tv":9.08,"id":16569870}]}]}
{"op":"mcm","clk":"1007821655","pt":1580657053798,"mc":[{"id":"1.168224445","rc":[{"batb":[[2,4,13.44]],"batl":[[0,4.8,10.92],[1,4.9,18.96]],"ltp":0.0,"tv":0.0,"id":13117431},{"batb":[[2,2.82,22.69]],"batl":[[1,3.3,17.64],[2,3.35,22.27]],"ltp":0.0,"tv":0.0,"id":13117430},{"batl":[[0,4.1,27.37]],"ltp":4.2,"tv":3.36,"id":16569868},{"batb":[[1,5.1,40.45]],"batl":[[1,6.2,7.56]],"ltp":5.0,"tv":9.08,"id":16569870}]}]}
{"op":"mcm","clk":"1007825960","pt":1580657073335,"mc":[{"id":"1.168224445","rc":[{"batb":[[0,4.2,39.29],[2,1.01,0.51]],"batl":[[0,4.9,18.96],[1,4.9,0]],"ltp":0.0,"tv":0.0,"id":13117431},{"batb":[[0,2.7,12.04],[1,1.01,0.51],[2,2.82,0]],"batl":[[0,3.35,22.27],[1,3.3,0],[2,3.35,0]],"ltp":0.0,"tv":0.0,"id":13117430},{"batb":[[0,3.5,15.58],[1,1.01,0.51],[2,3.6,0]],"batl":[[0,4.5,22.66],[1,4.5,0]],"ltp":4.2,"tv":3.36,"id":16569868},{"batb":[[0,5.2,35.19],[1,5.1,30.37]],"batl":[[1,6.2,0]],"ltp":5.0,"tv":9.08,"id":16569870}]}]}
{"op":"mcm","clk":"1007826327","pt":1580657074979,"mc":[{"id":"1.168224445","rc":[{"batb":[[1,4.9,13.53],[2,1.01,0.51]],"ltp":5.0,"tv":9.08,"id":16569870}]}]}
{"op":"mcm","clk":"1007827058","pt":1580657077863,"mc":[{"id":"1.168224445","rc":[{"batb":[[0,4.2,50.02]],"ltp":0.0,"tv":0.0,"id":13117431},{"batb":[[0,2.9,47.55],[1,2.86,49.45],[2,2.7,12.04]],"ltp":0.0,"tv":0.0,"id":13117430},{"batb":[[0,3.8,29.33],[1,3.75,31.5],[2,3.5,15.58]],"ltp":4.2,"tv":3.36,"id":16569868},{"batb":[[0,5.3,20.38],[1,5.2,35.19],[2,4.9,13.53]],"ltp":5.0,"tv":9.08,"id":16569870}]}]}
{"op":"mcm","clk":"1007828444","pt":1580657083967,"mc":[{"id":"1.168224445","rc":[{"batb":[[0,4.2,39.29]],"ltp":0.0,"tv":0.0,"id":13117431},{"batb":[[0,2.7,12.04],[1,1.01,0.51],[2,2.7,0]],"ltp":0.0,"tv":0.0,"id":13117430},{"batb":[[0,3.5,15.58],[1,1.01,0.51],[2,3.5,0]],"ltp":4.2,"tv":3.36,"id":16569868},{"batb":[[0,5.2,35.19],[1,4.9,13.53],[2,1.01,0.51]],"ltp":5.0,"tv":9.08,"id":16569870}]}]}
{"op":"mcm","clk":"1007829234","pt":1580657087373,"mc":[{"id":"1.168224445","rc":[{"batb":[[0,2.76,46.92],[1,2.72,56.29],[2,2.7,12.04]],"ltp":0.0,"tv":0.0,"id":13117430},{"batb":[[0,3.6,42.39],[1,3.55,35.81],[2,3.5,15.58]],"ltp":4.2,"tv":3.36,"id":16569868},{"batb":[[1,5.1,30.45],[2,4.9,13.53]],"ltp":5.0,"tv":9.08,"id":16569870}]}]}
{"op":"mcm","clk":"1007830978","pt":1580657095353,"mc":[{"id":"1.168224445","rc":[{"batb":[[0,2.7,12.04],[1,1.01,0.51],[2,2.7,0]],"ltp":0.0,"tv":0.0,"id":13117430}]}]}
{"op":"mcm","clk":"1007831604","pt":1580657098389,"mc":[{"id":"1.168224445","rc":[{"batb":[[0,3.05,39.32],[1,3,54.63],[2,2.7,12.04]],"ltp":0.0,"tv":0.0,"id":13117430}]}]}
{"op":"mcm","clk":"1007831771","pt":1580657099181,"mc":[{"id":"1.168224445","rc":[{"batl":[[0,4.8,19.36]],"ltp":0.0,"tv":0.0,"id":13117431},{"batb":[[1,3,77.76],[2,2.86,10.46]],"batl":[[1,3.9,15.5]],"ltp":0.0,"tv":0.0,"id":13117430},{"batl":[[0,3.95,15.11],[1,4.2,13.14]],"ltp":4.2,"tv":3.36,"id":16569868},{"batl":[[0,5.8,13.06]],"ltp":5.0,"tv":9.08,"id":16569870}]}]}
{"op":"mcm","clk":"1007831904","pt":1580657099877,"mc":[{"id":"1.168224445","rc":[{"batb":[[2,4,13.44]],"batl":[[0,4.8,30.28]],"ltp":0.0,"tv":0.0,"id":13117431},{"batb":[[1,3,98.77]],"batl":[[1,3.5,16.8],[2,3.9,15.5]],"ltp":0.0,"tv":0.0,"id":13117430},{"batl":[[0,3.9,14.28],[1,3.95,15.11],[2,4.2,13.14]],"ltp":4.2,"tv":3.36,"id":16569868},{"batb":[[2,5,10.08]],"batl":[[1,6,8.4]],"ltp":5.0,"tv":9.08,"id":16569870}]}]}
{"op":"mcm","clk":"1007850021","pt":1580657183000,"mc":[{"id":"1.168224445","rc":[{"batb":[[0,4.1,71.02],[1,1.01,0.51],[2,4,0]],"batl":[[0,4.8,19.36]],"ltp":0.0,"tv":0.0,"id":13117431},{"batb":[[0,2.86,10.46],[1,1.01,0.51],[2,2.86,0]],"batl":[[0,3.9,15.5],[1,3.5,0],[2,3.9,0]],"ltp":0.0,"tv":0.0,"id":13117430},{"batb":[[0,3.05,21.64],[1,1.01,0.51],[2,3.5,0]],"batl":[[0,4.2,13.14],[1,3.95,0],[2,4.2,0]],"ltp":4.2,"tv":3.36,"id":16569868},{"batb":[[0,5.1,30.45],[1,4.9,13.53],[2,1.01,0.51]],"batl":[[1,6,0]],"ltp":5.0,"tv":9.08,"id":16569870}]}]}
{"op":"mcm","clk":"1007850813","pt":1580657186386,"mc":[{"id":"1.168224445","rc":[{"batb":[[1,4,53.57],[2,1.01,0.51]],"ltp":0.0,"tv":0.0,"id":13117431},{"batb":[[0,2.86,47.91],[1,2.82,51.28],[2,1.01,0.51]],"ltp":0.0,"tv":0.0,"id":13117430},{"batb":[[0,3.15,78.56],[1,3.1,49.76],[2,3.05,21.64]],"ltp":4.2,"tv":3.36,"id":16569868},{"batb":[[0,5.1,47.73],[1,5,31.71],[2,4.9,13.53]],"ltp":5.0,"tv":9.08,"id":16569870}]}]}
{"op":"mcm","clk":"1007852596","pt":1580657194297,"mc":[{"id":"1.168224445","rc":[{"batb":[[0,2.86,10.46],[1,1.01,0.51],[2,1.01,0]],"ltp":0.0,"tv":0.0,"id":13117430}]}]}
{"op":"mcm","clk":"1007853245","pt":1580657197180,"mc":[{"id":"1.168224445","rc":[{"batb":[[1,4,76.47]],"batl":[[0,4.7,20.38],[1,4.8,19.36]],"ltp":0.0,"tv":0.0,"id":13117431},{"batb":[[0,3.5,44.35],[1,3.45,54.69],[2,3.15,20.46]],"batl":[[1,5.1,17.31]],"ltp":0.0,"tv":0.0,"id":13117430},{"batl":[[0,3.4,20.85],[1,3.75,17.07],[2,4.2,13.14]],"ltp":4.2,"tv":3.36,"id":16569868},{"batl":[[0,5.7,13.22],[1,5.8,13.06]],"ltp":5.0,"tv":9.08,"id":16569870}]}]}
{"op":"mcm","clk":"1007853539","pt":1580657198398,"mc":[{"id":"1.168224445","rc":[{"batb":[[0,4.1,50.41],[2,3.95,13.44]],"batl":[[0,4.7,31.3]],"ltp":0.0,"tv":0.0,"id":13117431},{"batb":[[2,3.4,16.8]],"ltp":0.0,"tv":0.0,"id":13117430},{"batl":[[2,4.2,0]],"ltp":4.2,"tv":3.36,"id":16569868},{"batb":[[2,4.9,23.62]],"batl":[[1,5.9,8.4]],"ltp":5.0,"tv":9.08,"id":16569870}]}]}
{"op":"mcm","clk":"1007853924","pt":1580657200128,"mc":[{"id":"1.168224445","rc":[{"batl":[[1,4,13.44],[2,5.1,17.31]],"ltp":0.0,"tv":0.0,"id":13117430},{"batl":[[1,3.45,16.8],[2,3.75,17.07]],"ltp":4.2,"tv":3.36,"id":16569868}]}]}
{"op":"mcm","clk":"1007855823","pt":1580657208199,"mc":[{"id":"1.168224445","rc":[{"batb":[[0,4,67.23],[1,3.95,13.44],[2,1.01,0.51]],"batl":[[0,4.7,10.92]],"ltp":0.0,"tv":0.0,"id":13117431},{"batb":[[0,3.4,16.8],[1,3.15,20.46],[2,1.01,0.51]],"batl":[[0,4,13.44],[1,5.1,17.31],[2,5.1,0]],"ltp":0.0,"tv":0.0,"id":13117430},{"batb":[[0,3,21],[1,2.64,12.83],[2,1.01,0.51]],"batl":[[0,3.45,16.8],[1,3.75,17.07],[2,3.75,0]],"ltp":4.2,"tv":3.36,"id":16569868},{"batb":[[0,5.1,30.45]],"ltp":5.0,"tv":9.08,"id":16569870}]}]}
{"op":"mcm","clk":"1007856010","pt":1580657209019,"mc":[{"id":"1.168224445","rc":[{"batb":[[1,1.01,0.51],[2,1.01,0]],"batl":[[0,4.8,19.36],[1,4.8,0]],"ltp":0.0,"tv":0.0,"id":13117431},{"batb":[[0,3.15,20.46],[1,1.01,0.51],[2,1.01,0]],"batl":[[0,5.1,17.31],[1,5.1,0]],"ltp":0.0,"tv":0.0,"id":13117430},{"batb":[[0,2.64,12.83],[1,1.01,0.51],[2,1.01,0]],"batl":[[0,3.75,17.07],[1,3.75,0]],"ltp":4.2,"tv":3.36,"id":16569868},{"batb":[[2,4.9,13.53]],"batl":[[1,5.9,0]],"ltp":5.0,"tv":9.08,"id":16569870}]}]}
{"op":"mcm","clk":"1007856428","pt":1580657210720,"mc":[{"id":"1.168224445","rc":[{"batb":[[0,4,44.33],[1,3.95,51.13],[2,1.01,0.51]],"ltp":0.0,"tv":0.0,"id":13117431},{"batb":[[0,3.15,70.44],[1,3.1,50.21],[2,1.01,0.51]],"batl":[[0,5,17.47]],"ltp":0.0,"tv":0.0,"id":13117430},{"batb":[[0,2.74,39.27],[1,2.7,57.35],[2,2.66,12.75]],"ltp":4.2,"tv":3.36,"id":16569868},{"batl":[[0,5.8,13.14]],"ltp":5.0,"tv":9.08,"id":16569870}]}]}
{"op":"mcm","clk":"1007857986","pt":1580657216934,"mc":[{"id":"1.168224445","rc":[{"batb":[[0,3.95,23.05],[1,1.01,0.51],[2,1.01,0]],"ltp":0.0,"tv":0.0,"id":13117431},{"batb":[[0,2.66,12.75],[1,1.01,0.51],[2,2.66,0]],"ltp":4.2,"tv":3.36,"id":16569868},{"batb":[[1,4.9,13.53],[2,1.01,0.51]],"ltp":5.0,"tv":9.08,"id":16569870}]}]}
{"op":"mcm","clk":"1007858842","pt":1580657220350,"mc":[{"id":"1.168224445","rc":[{"batb":[[0,4.2,32.86],[1,4.1,71.84],[2,4,35.4]],"batl":[[0,4.8,30.28]],"ltp":0.0,"tv":0.0,"id":13117431},{"batb":[[1,3.1,69.53],[2,2.9,25.1]],"batl":[[0,3.5,19.83],[1,3.65,15.12],[2,4.3,24.86]],"ltp":0.0,"tv":0.0,"id":13117430},{"batb":[[0,3.45,65.04],[1,3.4,39.61],[2,3.35,17.55]],"batl":[[0,3.75,32.2],[1,4.1,14.01]],"ltp":4.2,"tv":3.36,"id":16569868},{"batb":[[0,5.2,26.22],[1,5.1,30.45],[2,4.9,23.62]],"batl":[[1,5.9,8.4]],"ltp":5.0,"tv":9.08,"id":16569870}]}]}
{"op":"mcm","clk":"1007862996","pt":1580657237334,"mc":[{"id":"1.168224445","rc":[{"batb":[[0,4.1,30.1],[1,4,21.95],[2,1.01,0.51]],"batl":[[0,4.8,19.36]],"ltp":0.0,"tv":0.0,"id":13117431},{"batb":[[0,2.9,25.1],[1,1.01,0.51],[2,2.9,0]],"batl":[[0,4.3,24.86],[1,3.65,0],[2,4.3,0]],"ltp":0.0,"tv":0.0,"id":13117430},{"batb":[[0,2.88,25.65],[1,1.01,0.51],[2,3.35,0]],"batl":[[0,4.1,14.01],[1,4.1,0]],"ltp":4.2,"tv":3.36,"id":16569868},{"batb":[[0,5.1,30.45],[1,4.9,13.53],[2,1.01,0.51]],"batl":[[1,5.9,0]],"ltp":5.0,"tv":9.08,"id":16569870}]}]}
{"op":"mcm","clk":"1007863704","pt":1580657240245,"mc":[{"id":"1.168224445","rc":[{"batb":[[1,4,75.95]],"ltp":0.0,"tv":0.0,"id":13117431}]}]}
{"op":"mcm","clk":"1007863922","pt":1580657241238,"mc":[{"id":"1.168224445","rc":[{"batb":[[0,4.1,73.64]],"ltp":0.0,"tv":0.0,"id":13117431},{"batb":[[0,3.25,59.73],[1,3.2,46.31],[2,2.9,25.1]],"ltp":0.0,"tv":0.0,"id":13117430},{"batb":[[0,3.35,61.36],[1,3.3,42.68],[2,2.88,25.65]],"ltp":4.2,"tv":3.36,"id":16569868},{"batb":[[0,5.2,22.15],[1,5.1,30.45],[2,4.9,13.53]],"ltp":5.0,"tv":9.08,"id":16569870}]}]}
{"op":"mcm","clk":"1007864909","pt":1580657245358,"mc":[{"id":"1.168224445","rc":[{"batb":[[0,4.1,30.1]],"ltp":0.0,"tv":0.0,"id":13117431},{"batb":[[0,2.9,25.1],[1,1.01,0.51],[2,2.9,0]],"ltp":0.0,"tv":0.0,"id":13117430},{"batb":[[0,2.88,25.65],[1,1.01,0.51],[2,2.88,0]],"ltp":4.2,"tv":3.36,"id":16569868},{"batb":[[0,5.1,30.45],[1,4.9,13.53],[2,1.01,0.51]],"ltp":5.0,"tv":9.08,"id":16569870}]}]}
{"op":"mcm","clk":"1007865501","pt":1580657248068,"mc":[{"id":"1.168224445","rc":[{"batb":[[0,2.9,76.15],[1,2.86,49.37],[2,1.01,0.51]],"ltp":0.0,"tv":0.0,"id":13117430},{"batb":[[0,3,47.58],[1,2.96,45.16],[2,2.88,25.65]],"ltp":4.2,"tv":3.36,"id":16569868},{"batb":[[1,5,31.9],[2,4.9,13.53]],"ltp":5.0,"tv":9.08,"id":16569870}]}]}
{"op":"mcm","clk":"1007865700","pt":1580657248995,"mc":[{"id":"1.168224445","rc":[{"batb":[[0,2.9,25.1],[1,1.01,0.51],[2,1.01,0]],"ltp":0.0,"tv":0.0,"id":13117430},{"batb":[[0,2.88,25.65],[1,1.01,0.51],[2,2.88,0]],"ltp":4.2,"tv":3.36,"id":16569868},{"batb":[[1,4.9,13.53],[2,1.01,0.51]],"ltp":5.0,"tv":9.08,"id":16569870}]}]}
{"op":"mcm","clk":"1007866486","pt":1580657252155,"mc":[{"id":"1.168224445","rc":[{"batb":[[0,3.8,46.81],[1,3.75,31.61],[2,2.9,25.1]],"ltp":0.0,"tv":0.0,"id":13117430},{"batb":[[0,3,47.58],[1,2.96,45.16],[2,2.88,25.65]],"ltp":4.2,"tv":3.36,"id":16569868},{"batb":[[1,5,31.9],[2,4.9,13.53]],"ltp":5.0,"tv":9.08,"id":16569870}]}]}
{"op":"mcm","clk":"1007866671","pt":1580657252996,"mc":[{"id":"1.168224445","rc":[{"batb":[[2,3.9,24.23]],"batl":[[0,4.7,20.22]],"ltp":0.0,"tv":0.0,"id":13117431},{"batb":[[1,3.75,44.75],[2,3.3,18.1]],"batl":[[1,6.4,10.39]],"ltp":0.0,"tv":0.0,"id":13117430},{"batl":[[0,3.2,24.63],[1,3.6,18.73]],"ltp":4.2,"tv":3.36,"id":16569868},{"batl":[[0,5.7,13.22]],"ltp":5.0,"tv":9.08,"id":16569870}]}]}
{"op":"mcm","clk":"1007866865","pt":1580657253869,"mc":[{"id":"1.168224445","rc":[{"batb":[[2,3.95,13.44]],"batl":[[0,4.7,31.14]],"ltp":0.0,"tv":0.0,"id":13117431},{"batb":[[2,3.65,15.12]],"batl":[[0,4.3,37.47]],"ltp":0.0,"tv":0.0,"id":13117430},{"batl":[[1,3.3,17.64],[2,3.6,18.73]],"ltp":4.2,"tv":3.36,"id":16569868},{"batb":[[2,4.9,23.62]],"batl":[[1,5.9,8.4]],"ltp":5.0,"tv":9.08,"id":16569870}]}]}
{"op":"mcm","clk":"1007868393","pt":1580657260271,"mc":[{"id":"1.168224445","rc":[{"batb":[[0,5.1,38.01]],"ltp":5.0,"tv":9.08,"id":16569870}]}]}
{"op":"mcm","clk":"1007869992","pt":1580657267403,"mc":[{"id":"1.168224445","rc":[{"batb":[[0,3.9,24.23],[1,1.01,0.51],[2,3.95,0]],"batl":[[0,4.7,20.22]],"ltp":0.0,"tv":0.0,"id":13117431},{"batb":[[0,3.3,18.1],[1,1.01,0.51],[2,3.65,0]],"batl":[[0,6.4,10.39],[1,6.4,0]],"ltp":0.0,"tv":0.0,"id":13117430},{"batb":[[0,2.4,16.68],[1,1.01,0.51],[2,2.88,0]],"batl":[[0,3.6,18.73],[1,3.3,0],[2,3.6,0]],"ltp":4.2,"tv":3.36,"id":16569868},{"batb":[[0,5,31.9],[1,4.9,13.53],[2,1.01,0.51]],"batl":[[1,5.9,0]],"ltp":5.0,"tv":9.08,"id":16569870}]}]}
{"op":"mcm","clk":"1007870651","pt":1580657270199,"mc":[{"id":"1.168224445","rc":[{"batb":[[0,5,31.99]],"ltp":5.0,"tv":9.08,"id":16569870}]}]}
{"op":"mcm","clk":"1007871010","pt":1580657271689,"mc":[{"id":"1.168224445","rc":[{"batb":[[0,4,65.34],[1,3.95,27.86],[2,3.9,24.23]],"ltp":0.0,"tv":0.0,"id":13117431},{"batb":[[0,4,69.9],[1,3.95,27.73],[2,3.3,18.1]],"ltp":0.0,"tv":0.0,"id":13117430},{"batb":[[0,2.88,55.95],[1,2.84,50.18],[2,2.4,16.68]],"ltp":4.2,"tv":3.36,"id":16569868},{"batb":[[0,5.1,33.62],[1,5,31.99],[2,4.9,13.53]],"ltp":5.0,"tv":9.08,"id":16569870}]}]}
{"op":"mcm","clk":"1007871405","pt":1580657273368,"mc":[{"id":"1.168224445","rc":[{"batb":[[0,3.9,24.23],[1,1.01,0.51],[2,3.9,0]],"ltp":0.0,"tv":0.0,"id":13117431},{"batb":[[0,3.3,18.1],[1,1.01,0.51],[2,3.3,0]],"ltp":0.0,"tv":0.0,"id":13117430},{"batb":[[0,2.4,16.68],[1,1.01,0.51],[2,2.4,0]],"ltp":4.2,"tv":3.36,"id":16569868},{"batb":[[0,5,31.99],[1,4.9,13.53],[2,1.01,0.51]],"ltp":5.0,"tv":9.08,"id":16569870}]}]}
{"op":"mcm","clk":"1007872057","pt":1580657276267,"mc":[{"id":"1.168224445","rc":[{"batb":[[0,3.9,74.76],[1,3.85,29.81],[2,1.01,0.51]],"ltp":0.0,"tv":0.0,"id":13117431},{"batb":[[1,3.25,74.19],[2,3.2,46.16]],"ltp":0.0,"tv":0.0,"id":13117430},{"batb":[[0,2.5,51.37],[1,2.46,73.49],[2,2.4,16.68]],"ltp":4.2,"tv":3.36,"id":16569868},{"batb":[[0,5,48.52],[1,4.9,46.87]],"ltp":5.0,"tv":9.08,"id":16569870}]}]}
{"op":"mcm","clk":"1007872931","pt":1580657280108,"mc":[{"id":"1.168224445","rc":[{"batb":[[0,3.9,24.23],[1,1.01,0.51],[2,1.01,0]],"ltp":0.0,"tv":0.0,"id":13117431},{"batb":[[0,2.4,16.68],[1,1.01,0.51],[2,2.4,0]],"ltp":4.2,"tv":3.36,"id":16569868},{"batb":[[0,5,31.9],[1,4.9,13.53]],"ltp":5.0,"tv":9.08,"id":16569870}]}]}
{"op":"mcm","clk":"1007873703","pt":1580657283380,"mc":[{"id":"1.168224445","rc":[{"batb":[[0,4.2,24.19],[1,4.1,72.29],[2,3.95,23.13]],"batl":[[1,4.8,19.2]],"ltp":0.0,"tv":0.0,"id":13117431},{"batl":[[0,3.7,17.47],[1,5.1,17.31],[2,6.4,10.39]],"ltp":0.0,"tv":0.0,"id":13117430},{"batb":[[0,3.35,49.27],[1,3.3,42.81],[2,3.2,19.36]],"batl":[[1,3.95,14.79]],"ltp":4.2,"tv":3.36,"id":16569868},{"batb":[[0,5.1,49.41],[1,5,31.9],[2,4.9,13.53]],"ltp":5.0,"tv":9.08,"id":16569870}]}]}
{"op":"mcm","clk":"1007873808","pt":1580657283904,"mc":[{"id":"1.168224445","rc":[{"batb":[[2,4,13.44]],"batl":[[1,4.8,30.12]],"ltp":0.0,"tv":0.0,"id":13117431},{"batb":[[1,3.25,92.67]],"batl":[[1,3.8,14.28],[2,5.1,17.31]],"ltp":0.0,"tv":0.0,"id":13117430},{"batl":[[0,3.6,34.69]],"ltp":4.2,"tv":3.36,"id":16569868},{"batb":[[2,4.9,23.62]],"batl":[[1,5.8,8.4]],"ltp":5.0,"tv":9.08,"id":16569870}]}]}
{"op":"mcm","clk":"1007877425","pt":1580657299420,"mc":[{"id":"1.168224445","rc":[{"batb":[[0,4.1,21.32],[1,4,13.44],[2,3.95,23.13]],"ltp":0.0,"tv":0.0,"id":13117431},{"batb":[[1,3.25,18.48],[2,2.96,23.84]],"ltp":0.0,"tv":0.0,"id":13117430},{"batb":[[0,3.2,19.36],[1,3.1,19.32],[2,2.66,12.59]],"ltp":4.2,"tv":3.36,"id":16569868},{"batb":[[0,5.1,26.14]],"ltp":5.0,"tv":9.08,"id":16569870}]}]}
{"op":"mcm","clk":"1007877624","pt":1580657300316,"mc":[{"id":"1.168224445","rc":[{"batb":[[0,4,13.44],[1,3.95,23.13],[2,1.01,0.51]],"batl":[[0,4.8,30.12],[1,4.8,0]],"ltp":0.0,"tv":0.0,"id":13117431},{"batb":[[0,3.25,18.48],[1,2.96,23.84],[2,1.01,0.51]],"batl":[[0,3.8,14.28],[1,5.1,17.31],[2,5.1,0]],"ltp":0.0,"tv":0.0,"id":13117430},{"batb":[[0,3.1,19.32],[1,2.66,12.59],[2,1.01,0.51]],"batl":[[0,3.6,15.96]],"ltp":4.2,"tv":3.36,"id":16569868}]}]}
{"op":"mcm","clk":"1007877864","pt":1580657301360,"mc":[{"id":"1.168224445","rc":[{"batb":[[0,3.95,23.13],[1,1.01,0.51],[2,1.01,0]],"batl":[[0,4.8,19.2]],"ltp":0.0,"tv":0.0,"id":13117431},{"batb":[[0,2.96,23.84],[1,1.01,0.51],[2,1.01,0]],"batl":[[0,5.1,17.31],[1,5.1,0]],"ltp":0.0,"tv":0.0,"id":13117430},{"batb":[[0,2.66,12.59],[1,1.01,0.51],[2,1.01,0]],"batl":[[0,3.95,14.79],[1,3.95,0]],"ltp":4.2,"tv":3.36,"id":16569868},{"batb":[[2,4.9,13.53]],"batl":[[1,5.8,0]],"ltp":5.0,"tv":9.08,"id":16569870}]}]}
{"op":"mcm","clk":"1007878049","pt":1580657302121,"mc":[{"id":"1.168224445","rc":[{"batb":[[0,4,44.78],[1,3.95,51.18],[2,1.01,0.51]],"ltp":0.0,"tv":0.0,"id":13117431},{"batb":[[1,2.92,39.51],[2,2.88,48.56]],"ltp":0.0,"tv":0.0,"id":13117430},{"batb":[[0,2.78,39.86],[1,2.74,55.2],[2,2.66,12.59]],"ltp":4.2,"tv":3.36,"id":16569868}]}]}
{"op":"mcm","clk":"1007878327","pt":1580657303219,"mc":[{"id":"1.168224445","rc":[{"batb":[[0,2.94,24.31]],"batl":[[0,5,17.7]],"ltp":0.0,"tv":0.0,"id":13117430},{"batb":[[2,2.68,12.35]],"batl":[[0,4,14.48]],"ltp":4.2,"tv":3.36,"id":16569868}]}]}
{"op":"mcm","clk":"1007878835","pt":1580657305417,"mc":[{"id":"1.168224445","rc":[{"batb":[[1,3.95,23.13]],"ltp":0.0,"tv":0.0,"id":13117431},{"batb":[[1,1.01,0.51],[2,2.88,0]],"ltp":0.0,"tv":0.0,"id":13117430},{"batb":[[0,2.68,12.35],[1,1.01,0.51],[2,2.68,0]],"ltp":4.2,"tv":3.36,"id":16569868}]}]}
{"op":"mcm","clk":"1007880352","pt":1580657312160,"mc":[{"id":"1.168224445","rc":[{"batb":[[1,3.95,51.18]],"ltp":0.0,"tv":0.0,"id":13117431},{"batb":[[1,2.92,39.51],[2,2.88,48.56]],"ltp":0.0,"tv":0.0,"id":13117430},{"batb":[[0,2.78,39.86],[1,2.74,55.2],[2,2.68,12.35]],"ltp":4.2,"tv":3.36,"id":16569868}]}]}
{"op":"mcm","clk":"1007881307","pt":1580657316355,"mc":[{"id":"1.168224445","rc":[{"batb":[[0,3.95,23.13],[1,1.01,0.51],[2,1.01,0]],"ltp":0.0,"tv":0.0,"id":13117431},{"batb":[[0,2.68,12.35],[1,1.01,0.51],[2,2.68,0]],"ltp":4.2,"tv":3.36,"id":16569868},{"batb":[[1,4.9,13.53],[2,1.01,0.51]],"ltp":5.0,"tv":9.08,"id":16569870}]}]}
{"op":"mcm","clk":"1007881995","pt":1580657319178,"mc":[{"id":"1.168224445","rc":[{"batb":[[0,4.2,67.7],[1,4.1,50.14],[2,3.95,23.13]],"ltp":0.0,"tv":0.0,"id":13117431},{"batb":[[0,3.75,50.41],[1,3.7,32.35],[2,2.68,12.35]],"ltp":4.2,"tv":3.36,"id":16569868},{"batb":[[0,5.2,30.13],[1,5.1,26.14],[2,4.9,13.53]],"ltp":5.0,"tv":9.08,"id":16569870}]}]}
{"op":"mcm","clk":"1007882216","pt":1580657319983,"mc":[{"id":"1.168224445","rc":[{"batb":[[1,4.1,84.75],[2,1.01,0.51]],"batl":[[1,4.9,28.89]],"ltp":0.0,"tv":0.0,"id":13117431},{"batb":[[1,2.92,61.36]],"batl":[[0,3.25,23.37],[1,3.35,17.64],[2,3.8,16.44]],"ltp":0.0,"tv":0.0,"id":13117430},{"batb":[[2,3.55,14.95]],"batl":[[1,4.1,13.44],[2,4.4,24.23]],"ltp":4.2,"tv":3.36,"id":16569868},{"batb":[[2,4.9,23.62]],"batl":[[1,5.8,8.4]],"ltp":5.0,"tv":9.08,"id":16569870}]}]}
{"op":"mcm","clk":"1007886213","pt":1580657337122,"mc":[{"id":"1.168224445","rc":[{"batb":[[0,4.2,31.5],[1,4.1,71.31]],"batl":[[0,4.9,18.8],[1,4.9,0]],"ltp":0.0,"tv":0.0,"id":13117431},{"batb":[[0,2.78,11.17],[1,1.01,0.51],[2,2.88,0]],"batl":[[0,3.8,16.44],[1,3.35,0],[2,3.8,0]],"ltp":0.0,"tv":0.0,"id":13117430},{"batb":[[0,3.1,20.69],[1,1.01,0.51],[2,3.55,0]],"batl":[[0,4.4,24.23],[1,4.1,0],[2,4.4,0]],"ltp":4.2,"tv":3.36,"id":16569868},{"batb":[[0,5.1,26.14],[1,4.9,13.53],[2,1.01,0.51]],"batl":[[1,5.8,0]],"ltp":5.0,"tv":9.08,"id":16569870}]}]}
{"op":"mcm","clk":"1007886927","pt":1580657340302,"mc":[{"id":"1.168224445","rc":[{"batb":[[1,2.74,47.64],[2,2.7,57.35]],"ltp":0.0,"tv":0.0,"id":13117430},{"batb":[[0,3.3,39.31],[1,3.25,44.55],[2,3.1,20.69]],"ltp":4.2,"tv":3.36,"id":16569868},{"batb":[[0,5.1,43.37],[1,5,31.76],[2,4.9,13.53]],"ltp":5.0,"tv":9.08,"id":16569870}]}]}
{"op":"mcm","clk":"1007887913","pt":1580657344270,"mc":[{"id":"1.168224445","rc":[{"batb":[[1,4.1,21.17]],"ltp":0.0,"tv":0.0,"id":13117431},{"batb":[[0,3.1,20.69],[1,1.01,0.51],[2,3.1,0]],"ltp":4.2,"tv":3.36,"id":16569868},{"batb":[[0,5.1,30.36],[1,4.9,13.53],[2,1.01,0.51]],"ltp":5.0,"tv":9.08,"id":16569870}]}]}
{"op":"mcm","clk":"1007888575","pt":1580657347284,"mc":[{"id":"1.168224445","rc":[{"batb":[[0,4.3,37.63],[1,4.2,47.87],[2,4.1,21.17]],"ltp":0.0,"tv":0.0,"id":13117431},{"batb":[[0,4,68.16],[1,3.95,27.49],[2,3.1,20.69]],"ltp":4.2,"tv":3.36,"id":16569868},{"batb":[[0,5.2,38.6],[1,5.1,30.36],[2,4.9,13.53]],"ltp":5.0,"tv":9.08,"id":16569870}]}]}
{"op":"mcm","clk":"1007888766","pt":1580657348156,"mc":[{"id":"1.168224445","rc":[{"batb":[[1,4.2,67.62],[2,4.1,34.06]],"batl":[[0,4.9,28.89],[1,5,18.18]],"ltp":0.0,"tv":0.0,"id":13117431},{"batl":[[0,3.05,31.18],[1,3.3,22.9]],"ltp":0.0,"tv":0.0,"id":13117430},{"batb":[[2,3.8,39.93]],"batl":[[1,4.5,11.76],[2,5.2,16.29]],"ltp":4.2,"tv":3.36,"id":16569868},{"batb":[[2,4.9,23.62]],"batl":[[0,5.8,12.75],[1,5.9,8.4]],"ltp":5.0,"tv":9.08,"id":16569870}]}]}
{"op":"mcm","clk":"1007893738","pt":1580657372327,"mc":[{"id":"1.168224445","rc":[{"batb":[[0,4.2,67.62],[1,4.1,34.06],[2,1.01,0.51]],"ltp":0.0,"tv":0.0,"id":13117431},{"batb":[[1,2.68,24.37],[2,2.46,15.5]],"ltp":0.0,"tv":0.0,"id":13117430},{"batb":[[0,3.8,39.93],[1,3.55,14.95],[2,1.01,0.51]],"ltp":4.2,"tv":3.36,"id":16569868},{"batb":[[0,5.2,21.68]],"ltp":5.0,"tv":9.08,"id":16569870}]}]}
{"op":"mcm","clk":"1007893875","pt":1580657373026,"mc":[{"id":"1.168224445","rc":[{"batb":[[0,4.2,47.87],[1,4.1,20.61]],"batl":[[0,5,18.18],[1,5,0]],"ltp":0.0,"tv":0.0,"id":13117431},{"batb":[[0,2.46,15.5],[1,1.01,0.51],[2,2.46,0]],"batl":[[0,3.3,22.9],[1,3.3,0]],"ltp":0.0,"tv":0.0,"id":13117430},{"batb":[[0,3.55,14.95],[1,1.01,0.51],[2,1.01,0]],"batl":[[0,5.2,16.29],[1,4.5,0],[2,5.2,0]],"ltp":4.2,"tv":3.36,"id":16569868},{"batb":[[2,4.9,13.53]],"batl":[[1,5.9,0]],"ltp":5.0,"tv":9.08,"id":16569870}]}]}
{"op":"mcm","clk":"1007894323","pt":1580657375360,"mc":[{"id":"1.168224445","rc":[{"batb":[[0,3.6,14.71],[1,3.55,14.95],[2,1.01,0.51]],"ltp":4.2,"tv":3.36,"id":16569868}]}]}
{"op":"mcm","clk":"1007894540","pt":1580657376423,"mc":[{"id":"1.168224445","rc":[{"batb":[[0,4.2,64.37],[1,4.1,70.86]],"ltp":0.0,"tv":0.0,"id":13117431},{"batb":[[1,2.44,55.26],[2,2.4,78.4]],"ltp":0.0,"tv":0.0,"id":13117430},{"batb":[[0,3.75,28.52],[1,3.7,32.45],[2,3.6,14.71]],"batl":[[0,5.2,16.05]],"ltp":4.2,"tv":3.36,"id":16569868}]}]}
{"op":"mcm","clk":"1007895620","pt":1580657381289,"mc":[{"id":"1.168224445","rc":[{"batb":[[1,1.01,0.51],[2,2.4,0]],"ltp":0.0,"tv":0.0,"id":13117430}]}]}
{"op":"mcm","clk":"1007896300","pt":1580657384434,"mc":[{"id":"1.168224445","rc":[{"batb":[[2,4,13.44]],"batl":[[0,4.8,10.92],[1,4.9,18.88]],"ltp":0.0,"tv":0.0,"id":13117431},{"batb":[[0,2.94,79.12],[1,2.9,47.64],[2,2.86,21.85]],"batl":[[0,3.3,40.54],[1,3.5,20.06]],"ltp":0.0,"tv":0.0,"id":13117430},{"batl":[[0,4.1,14.24],[1,4.2,12.6],[2,4.6,21.09]],"ltp":4.2,"tv":3.36,"id":16569868},{"batb":[[2,4.9,23.62]],"batl":[[1,5.9,8.4]],"ltp":5.0,"tv":9.08,"id":16569870}]}]}
{"op":"mcm","clk":"1007899565","pt":1580657399391,"mc":[{"id":"1.168224445","rc":[{"batb":[[0,4.2,47.88]],"ltp":0.0,"tv":0.0,"id":13117431},{"batb":[[0,2.86,21.85],[1,2.66,12.59],[2,1.01,0.51]],"batl":[[0,3.3,17.64]],"ltp":0.0,"tv":0.0,"id":13117430},{"batb":[[0,3.55,15.96],[1,3.4,17],[2,1.01,0.51]],"batl":[[0,4.2,12.6],[1,4.6,21.09],[2,4.6,0]],"ltp":4.2,"tv":3.36,"id":16569868},{"batb":[[0,5.1,30.36],[1,4.9,23.62],[2,1.01,0.51]],"ltp":5.0,"tv":9.08,"id":16569870}]}]}
{"op":"mcm","clk":"1007900341","pt":1580657402380,"mc":[{"id":"1.168224445","rc":[{"batb":[[2,1.01,0.51]],"batl":[[0,4.9,18.88],[1,4.9,0]],"ltp":0.0,"tv":0.0,"id":13117431},{"batb":[[0,2.66,70.32],[1,2.62,61.95]],"batl":[[0,3.5,20.06],[1,3.5,0]],"ltp":0.0,"tv":0.0,"id":13117430},{"batb":[[0,3.5,55.85],[1,3.45,38.16],[2,3.4,17]],"batl":[[0,4.6,21.09],[1,4.6,0]],"ltp":4.2,"tv":3.36,"id":16569868},{"batb":[[0,5.1,40.79],[1,5,31.67],[2,4.9,13.53]],"batl":[[1,5.9,0]],"ltp":5.0,"tv":9.08,"id":16569870}]}]}
{"op":"mcm","clk":"1007901412","pt":1580657406253,"mc":[{"id":"1.168224445","rc":[{"batb":[[0,2.66,12.59],[1,1.01,0.51],[2,1.01,0]],"ltp":0.0,"tv":0.0,"id":13117430}]}]}
{"op":"mcm","clk":"1007902051","pt":1580657409151,"mc":[{"id":"1.168224445","rc":[{"batb":[[0,3.1,71.92],[1,3.05,52.1],[2,2.66,12.59]],"ltp":0.0,"tv":0.0,"id":13117430}]}]}
{"op":"mcm","clk":"1007902333","pt":1580657410365,"mc":[{"id":"1.168224445","rc":[{"batb":[[2,4,13.44]],"batl":[[0,4.8,30.59]],"ltp":0.0,"tv":0.0,"id":13117431},{"batb":[[0,3.1,92.77],[1,3.05,72.26],[2,2.88,10.31]],"batl":[[1,3.55,15.96],[2,3.6,18.33]],"ltp":0.0,"tv":0.0,"id":13117430},{"batl":[[0,3.8,16.44],[1,3.95,13.44],[2,4.2,13.38]],"ltp":4.2,"tv":3.36,"id":16569868},{"batb":[[2,4.8,25.16]],"batl":[[0,5.8,21.15]],"ltp":5.0,"tv":9.08,"id":16569870}]}]}
{"op":"mcm","clk":"1007905766","pt":1580657426315,"mc":[{"id":"1.168224445","rc":[{"batb":[[0,4.2,47.87]],"ltp":0.0,"tv":0.0,"id":13117431},{"batb":[[0,3.05,20.16],[1,2.88,10.31],[2,1.01,0.51]],"batl":[[0,3.55,15.96],[1,3.6,18.33],[2,3.6,0]],"ltp":0.0,"tv":0.0,"id":13117430},{"batb":[[0,3.35,17.64],[1,3.25,18.57],[2,1.01,0.51]],"batl":[[0,3.95,13.44],[1,4.2,13.38],[2,4.2,0]],"ltp":4.2,"tv":3.36,"id":16569868},{"batb":[[0,5.1,30.95]],"ltp":5.0,"tv":9.08,"id":16569870}]}]}
{"op":"mcm","clk":"1007905914","pt":1580657427003,"mc":[{"id":"1.168224445","rc":[{"batb":[[2,1.01,0.51]],"batl":[[0,4.8,19.67]],"ltp":0.0,"tv":0.0,"id":13117431},{"batb":[[0,2.88,10.31],[1,1.01,0.51],[2,1.01,0]],"batl":[[0,3.6,18.33],[1,3.6,0]],"ltp":0.0,"tv":0.0,"id":13117430},{"batb":[[0,3.25,18.57],[1,1.01,0.51],[2,1.01,0]],"batl":[[0,4.2,13.38],[1,4.2,0]],"ltp":4.2,"tv":3.36,"id":16569868},{"batb":[[2,4.8,14.24]],"batl":[[0,5.8,12.75]],"ltp":5.0,"tv":9.08,"id":16569870}]}]}
{"op":"mcm","clk":"1007906890","pt":1580657431419,"mc":[{"id":"1.168224445","rc":[{"batb":[[0,3.05,76.81],[1,3,54.27],[2,2.88,10.31]],"ltp":0.0,"tv":0.0,"id":13117430},{"batb":[[0,3.55,56.74],[1,3.5,36.84],[2,3.25,18.57]],"ltp":4.2,"tv":3.36,"id":16569868},{"batb":[[0,5.1,44.5]],"ltp":5.0,"tv":9.08,"id":16569870}]}]}
{"op":"mcm","clk":"1007907678","pt":1580657435143,"mc":[{"id":"1.168224445","rc":[{"batb":[[0,2.88,10.31],[1,1.01,0.51],[2,2.88,0]],"ltp":0.0,"tv":0.0,"id":13117430},{"batb":[[0,3.25,18.57],[1,1.01,0.51],[2,3.25,0]],"ltp":4.2,"tv":3.36,"id":16569868},{"batb":[[0,5.1,30.95]],"ltp":5.0,"tv":9.08,"id":16569870}]}]}
{"op":"mcm","clk":"1007908370","pt":1580657438343,"mc":[{"id":"1.168224445","rc":[{"batb":[[0,2.9,53.36],[1,2.88,10.31],[2,2.86,49.37]],"ltp":0.0,"tv":0.0,"id":13117430},{"batb":[[1,4.8,14.24],[2,1.01,0.51]],"ltp":5.0,"tv":9.08,"id":16569870}]}]}
{"op":"mcm","clk":"1007909126","pt":1580657441327,"mc":[{"id":"1.168224445","rc":[{"batb":[[0,4.2,59.49]],"ltp":0.0,"tv":0.0,"id":13117431},{"batb":[[0,3.8,38.04],[1,3.75,31.35],[2,3.25,18.57]],"ltp":4.2,"tv":3.36,"id":16569868},{"batb":[[0,5.2,28.49],[1,5.1,30.95],[2,4.8,14.24]],"ltp":5.0,"tv":9.08,"id":16569870}]}]}
{"op":"mcm","clk":"1007909329","pt":1580657442029,"mc":[{"id":"1.168224445","rc":[{"batb":[[2,4,13.44]],"batl":[[0,4.8,30.59],[1,4.9,18.8]],"ltp":0.0,"tv":0.0,"id":13117431},{"batb":[[2,2.86,71.22]],"batl":[[0,3.2,24.71],[1,3.3,17.64],[2,3.4,20.93]],"ltp":0.0,"tv":0.0,"id":13117430},{"batb":[[2,3.7,13.77]],"batl":[[0,4.2,25.98],[1,4.9,18.49]],"ltp":4.2,"tv":3.36,"id":16569868},{"batb":[[2,4.9,24.09]],"batl":[[1,5.9,21.07]],"ltp":5.0,"tv":9.08,"id":16569870}]}]}
{"op":"mcm","clk":"1007913586","pt":1580657460987,"mc":[{"id":"1.168224445","rc":[{"batb":[[0,4.2,36.73],[2,1.01,0.51]],"batl":[[0,4.9,18.8],[1,4.9,0]],"ltp":0.0,"tv":0.0,"id":13117431},{"batb":[[0,2.56,14.01],[1,1.01,0.51],[2,2.86,0]],"batl":[[0,3.4,20.93],[1,3.3,0],[2,3.4,0]],"ltp":0.0,"tv":0.0,"id":13117430},{"batb":[[0,3.45,16.21],[1,1.01,0.51],[2,3.7,0]],"batl":[[0,4.9,18.49],[1,4.9,0]],"ltp":4.2,"tv":3.36,"id":16569868},{"batb":[[0,5.1,30.95],[1,4.9,14.01],[2,1.01,0.51]],"batl":[[0,5.9,12.67],[1,5.9,0]],"ltp":5.0,"tv":9.08,"id":16569870}]}]}
{"op":"mcm","clk":"1007914942","pt":1580657466956,"mc":[{"id":"1.168224445","rc":[{"batb":[[0,4.2,67.77]],"ltp":0.0,"tv":0.0,"id":13117431},{"batb":[[0,2.84,41.61],[1,2.8,52.21],[2,2.56,14.01]],"ltp":0.0,"tv":0.0,"id":13117430},{"batb":[[0,3.9,40.03],[1,3.85,29.42],[2,3.45,16.21]],"ltp":4.2,"tv":3.36,"id":16569868},{"batb":[[0,5.2,33.08],[1,5.1,30.95],[2,4.9,14.01]],"ltp":5.0,"tv":9.08,"id":16569870}]}]}
{"op":"mcm","clk":"1007915653","pt":1580657470080,"mc":[{"id":"1.168224445","rc":[{"batb":[[0,4.2,36.73]],"ltp":0.0,"tv":0.0,"id":13117431},{"batb":[[0,2.56,14.01],[1,1.01,0.51],[2,2.56,0]],"ltp":0.0,"tv":0.0,"id":13117430},{"batb":[[0,3.45,16.21],[1,1.01,0.51],[2,3.45,0]],"ltp":4.2,"tv":3.36,"id":16569868},{"batb":[[0,5.1,30.95],[1,4.9,14.01],[2,1.01,0.51]],"ltp":5.0,"tv":9.08,"id":16569870}]}]}
{"op":"mcm","clk":"1007916351","pt":1580657473003,"mc":[{"id":"1.168224445","rc":[{"batb":[[0,2.58,60.94],[1,2.56,14.01],[2,2.54,67.25]],"ltp":0.0,"tv":0.0,"id":13117430},{"batb":[[0,3.55,31.78],[1,3.5,37.07],[2,3.45,16.21]],"ltp":4.2,"tv":3.36,"id":16569868},{"batb":[[0,5.1,46.84],[1,5,31.58],[2,4.9,14.01]],"ltp":5.0,"tv":9.08,"id":16569870}]}]}
{"op":"mcm","clk":"1007917656","pt":1580657479030,"mc":[{"id":"1.168224445","rc":[{"batb":[[0,2.56,14.01],[1,1.01,0.51],[2,2.54,0]],"ltp":0.0,"tv":0.0,"id":13117430}]}]}
{"op":"mcm","clk":"1007918179","pt":1580657481426,"mc":[{"id":"1.168224445","rc":[{"batb":[[0,3.1,62.88],[1,3.05,52.18],[2,2.56,14.01]],"ltp":0.0,"tv":0.0,"id":13117430}]}]}
{"op":"mcm","clk":"1007918403","pt":1580657482429,"mc":[{"id":"1.168224445","rc":[{"batb":[[2,3.95,13.44]],"batl":[[0,4.7,10.92],[1,4.8,19.67],[2,4.9,18.8]],"ltp":0.0,"tv":0.0,"id":13117431},{"batb":[[1,3.05,94.06],[2,2.84,10.62]],"batl":[[1,3.55,15.96],[2,3.6,18.8]],"ltp":0.0,"tv":0.0,"id":13117430},{"batl":[[0,3.85,15.66],[1,3.95,13.44],[2,4.2,25.65]],"ltp":4.2,"tv":3.36,"id":16569868},{"batb":[[2,4.9,24.09]],"batl":[[0,5.7,13.38],[1,5.8,21.23],[2,5.9,12.67]],"ltp":5.0,"tv":9.08,"id":16569870}]}]}
{"op":"mcm","clk":"1007918449","pt":1580657482628,"mc":[{"id":"1.168224445","rc":[{"batl":[[2,4.9,0]],"ltp":0.0,"tv":0.0,"id":13117431},{"batl":[[2,5.9,0]],"ltp":5.0,"tv":9.08,"id":16569870}]}]}
{"op":"mcm","clk":"1007922304","pt":1580657500149,"mc":[{"id":"1.168224445","rc":[{"batb":[[0,3.05,41.88],[1,2.84,10.62],[2,1.01,0.51]],"ltp":0.0,"tv":0.0,"id":13117430},{"batb":[[0,3.45,16.21],[1,3.35,17.64],[2,3.3,17.78]],"ltp":4.2,"tv":3.36,"id":16569868},{"batb":[[0,5.1,36.53]],"ltp":5.0,"tv":9.08,"id":16569870}]}]}
{"op":"mcm","clk":"1007922515","pt":1580657501066,"mc":[{"id":"1.168224445","rc":[{"batb":[[2,1.01,0.51]],"batl":[[0,4.8,19.67],[1,4.8,0]],"ltp":0.0,"tv":0.0,"id":13117431},{"batb":[[0,2.84,10.62],[1,1.01,0.51],[2,1.01,0]],"batl":[[0,3.6,18.8],[1,3.55,0],[2,3.6,0]],"ltp":0.0,"tv":0.0,"id":13117430},{"batb":[[0,3.3,17.78],[1,1.01,0.51],[2,3.3,0]],"batl":[[0,4.2,25.65],[1,3.95,0],[2,4.2,0]],"ltp":4.2,"tv":3.36,"id":16569868},{"batb":[[2,4.8,14.24]],"batl":[[0,5.8,12.83],[1,5.8,0]],"ltp":5.0,"tv":9.08,"id":16569870}]}]}
{"op":"mcm","clk":"1007922999","pt":1580657503444,"mc":[{"id":"1.168224445","rc":[{"batb":[[0,2.9,55.93],[1,2.86,49.36],[2,2.84,10.62]],"ltp":0.0,"tv":0.0,"id":13117430},{"batb":[[0,3.4,52.57],[1,3.35,41.02],[2,3.3,17.78]],"batl":[[1,4.3,25.57]],"ltp":4.2,"tv":3.36,"id":16569868}]}]}
{"op":"mcm","clk":"1007923097","pt":1580657503890,"mc":[{"id":"1.168224445","rc":[{"batl":[[0,4.3,25.57],[1,4.3,0]],"ltp":4.2,"tv":3.36,"id":16569868}]}]}
{"op":"mcm","clk":"1007924666","pt":1580657510444,"mc":[{"id":"1.168224445","rc":[{"batb":[[0,3.3,17.78],[1,1.01,0.51],[2,3.3,0]],"ltp":4.2,"tv":3.36,"id":16569868},{"batb":[[0,5.1,30.36],[1,4.8,14.24],[2,1.01,0.51]],"ltp":5.0,"tv":9.08,"id":16569870}]}]}
{"op":"mcm","clk":"1007925342","pt":1580657513344,"mc":[{"id":"1.168224445","rc":[{"batb":[[0,4.2,47.86],[2,4,21.64]],"batl":[[1,4.9,18.65]],"ltp":0.0,"tv":0.0,"id":13117431},{"batl":[[0,3.1,10.46],[1,3.4,21.32],[2,3.6,18.8]],"ltp":0.0,"tv":0.0,"id":13117430},{"batb":[[0,3.8,40.55],[1,3.75,44.46],[2,3.5,15.74]],"batl":[[1,5.1,17.07]],"ltp":4.2,"tv":3.36,"id":16569868},{"batb":[[0,5.2,34.99],[1,5.1,30.36],[2,5,13.38]],"batl":[[1,5.9,12.35]],"ltp":5.0,"tv":9.08,"id":16569870}]}]}
{"op":"mcm","clk":"1007925579","pt":1580657514391,"mc":[{"id":"1.168224445","rc":[{"batl":[[0,4.7,10.92],[1,4.8,19.67],[2,4.9,18.65]],"ltp":0.0,"tv":0.0,"id":13117431},{"batb":[[1,2.86,71.21]],"batl":[[1,3.3,17.64],[2,3.4,21.32]],"ltp":0.0,"tv":0.0,"id":13117430},{"batb":[[2,3.55,15.96]],"batl":[[0,4.2,12.6],[1,4.3,25.57],[2,5.1,17.07]],"ltp":4.2,"tv":3.36,"id":16569868},{"batb":[[2,5,23.46]],"batl":[[2,6,8.4]],"ltp":5.0,"tv":9.08,"id":16569870}]}]}
{"op":"mcm","clk":"1007929649","pt":1580657531366,"mc":[{"id":"1.168224445","rc":[{"batb":[[0,4.1,50.25],[1,4,21.64],[2,3.95,13.44]],"batl":[[1,4.9,18.65],[2,4.9,0]],"ltp":0.0,"tv":0.0,"id":13117431},{"batb":[[0,2.86,21.85],[1,2.5,15.03],[2,1.01,0.51]],"batl":[[0,3.3,17.64],[1,3.4,21.32],[2,3.4,0]],"ltp":0.0,"tv":0.0,"id":13117430},{"batb":[[0,3.55,15.96],[1,3.5,15.74],[2,1.01,0.51]],"batl":[[1,5.1,17.07],[2,5.1,0]],"ltp":4.2,"tv":3.36,"id":16569868},{"batb":[[0,5.2,20.45],[2,5,10.08]],"batl":[[0,5.9,12.35],[1,6,8.4],[2,6,0]],"ltp":5.0,"tv":9.08,"id":16569870}]}]}
{"op":"mcm","clk":"1007930112","pt":1580657533275,"mc":[{"id":"1.168224445","rc":[{"batb":[[2,1.01,0.51]],"batl":[[0,4.9,18.65],[1,4.9,0]],"ltp":0.0,"tv":0.0,"id":13117431},{"batb":[[0,2.5,15.03],[1,1.01,0.51],[2,1.01,0]],"batl":[[0,3.4,21.32],[1,3.4,0]],"ltp":0.0,"tv":0.0,"id":13117430},{"batb":[[0,3.5,15.74],[1,1.01,0.51],[2,1.01,0]],"batl":[[0,5.1,17.07],[1,5.1,0]],"ltp":4.2,"tv":3.36,"id":16569868},{"batb":[[2,4.9,13.77]],"batl":[[1,6,0]],"ltp":5.0,"tv":9.08,"id":16569870}]}]}
{"op":"mcm","clk":"1007930363","pt":1580657535320,"mc":[{"id":"1.168224445","rc":[{"batb":[[0,4.1,69.96],[1,4,53.14]],"batl":[[0,4.9,18.33]],"ltp":0.0,"tv":0.0,"id":13117431},{"batb":[[0,2.54,72.44],[1,2.5,84.9],[2,1.01,0.51]],"batl":[[0,3.4,20.85]],"ltp":0.0,"tv":0.0,"id":13117430},{"batb":[[0,3.5,53.92],[1,3.45,54.21],[2,1.01,0.51]],"batl":[[0,5,17.47]],"ltp":4.2,"tv":3.36,"id":16569868}]}]}
{"op":"mcm","clk":"1007933353","pt":1580657548780,"mc":[{"id":"1.168224445","rc":[{"batb":[[0,4.1,50.35],[1,1.01,0.51],[2,1.01,0]],"ltp":0.0,"tv":0.0,"id":13117431},{"batb":[[0,2.5,14.79],[1,1.01,0.51],[2,1.01,0]],"ltp":0.0,"tv":0.0,"id":13117430},{"batb":[[0,3.45,16.05],[1,1.01,0.51],[2,1.01,0]],"ltp":4.2,"tv":3.36,"id":16569868}]}]}
{"op":"mcm","clk":"1007934155","pt":1580657552494,"mc":[{"id":"1.168224445","rc":[{"batb":[[0,4.2,58.55],[1,4.1,50.35],[2,1.01,0.51]],"ltp":0.0,"tv":0.0,"id":13117431},{"batb":[[0,2.82,59.13],[1,2.78,53.07],[2,2.5,14.79]],"ltp":0.0,"tv":0.0,"id":13117430},{"batb":[[0,3.9,49],[1,3.85,29.34],[2,3.45,16.05]],"ltp":4.2,"tv":3.36,"id":16569868},{"batb":[[0,5.2,40.24]],"ltp":5.0,"tv":9.08,"id":16569870}]}]}
{"op":"mcm","clk":"1007935205","pt":1580657557221,"mc":[{"id":"1.168224445","rc":[{"batb":[[0,4.1,50.35],[1,1.01,0.51],[2,1.01,0]],"ltp":0.0,"tv":0.0,"id":13117431},{"batb":[[0,2.5,14.79],[1,1.01,0.51],[2,2.5,0]],"ltp":0.0,"tv":0.0,"id":13117430},{"batb":[[0,3.45,16.05],[1,1.01,0.51],[2,3.45,0]],"ltp":4.2,"tv":3.36,"id":16569868},{"batb":[[0,5.2,20.45]],"ltp":5.0,"tv":9.08,"id":16569870}]}]}
{"op":"mcm","clk":"1007935859","pt":1580657560440,"mc":[{"id":"1.168224445","rc":[{"batb":[[0,4.1,69.96],[1,4,53.14],[2,1.01,0.51]],"ltp":0.0,"tv":0.0,"id":13117431},{"batb":[[0,3.5,53.92],[1,3.45,54.21],[2,1.01,0.51]],"ltp":4.2,"tv":3.36,"id":16569868}]}]}
{"op":"mcm","clk":"1007936277","pt":1580657562315,"mc":[{"id":"1.168224445","rc":[{"batb":[[0,3.15,43.1],[1,3.1,50.28],[2,2.5,14.79]],"ltp":0.0,"tv":0.0,"id":13117430}]}]}
{"op":"mcm","clk":"1007936402","pt":1580657562911,"mc":[{"id":"1.168224445","rc":[{"batb":[[1,4,75.41]],"batl":[[0,4.7,20.14],[1,4.8,19.67]],"ltp":0.0,"tv":0.0,"id":13117431},{"batb":[[2,3.05,21.72]],"batl":[[1,4.1,14.01]],"ltp":0.0,"tv":0.0,"id":13117430},{"batb":[[2,3,22.66]],"batl":[[0,3.9,15.58],[1,4.2,13.22]],"ltp":4.2,"tv":3.36,"id":16569868},{"batb":[[2,4.8,14.32]],"batl":[[0,5.7,13.38]],"ltp":5.0,"tv":9.08,"id":16569870}]}]}
{"op":"mcm","clk":"1007936731","pt":1580657564390,"mc":[{"id":"1.168224445","rc":[{"batb":[[2,3.9,14.28]],"batl":[[0,4.7,31.07]],"ltp":0.0,"tv":0.0,"id":13117431},{"batb":[[0,3.15,62.42]],"batl":[[1,3.65,15.12],[2,4.1,14.01]],"ltp":0.0,"tv":0.0,"id":13117430},{"batb":[[2,3.3,17.64]],"batl":[[0,3.85,14.28],[1,3.9,15.58],[2,4.2,13.22]],"ltp":4.2,"tv":3.36,"id":16569868},{"batb":[[2,4.8,25.24]],"batl":[[1,5.8,8.4]],"ltp":5.0,"tv":9.08,"id":16569870}]}]}
{"op":"mcm","clk":"1007956186","pt":1580657649247,"mc":[{"id":"1.168224445","rc":[{"batb":[[0,4,75.41],[1,1.01,0.51],[2,3.9,0]],"batl":[[0,4.8,19.67],[1,4.8,0]],"ltp":0.0,"tv":0.0,"id":13117431},{"batb":[[0,2.88,10.31],[1,1.01,0.51],[2,3.05,0]],"batl":[[0,4.1,14.01],[1,3.65,0],[2,4.1,0]],"ltp":0.0,"tv":0.0,"id":13117430},{"batb":[[0,3,22.66],[1,1.01,0.51],[2,3.3,0]],"batl":[[0,4.2,13.22],[1,3.9,0],[2,4.2,0]],"ltp":4.2,"tv":3.36,"id":16569868},{"batb":[[0,5.1,30.36],[1,4.8,14.32],[2,1.01,0.51]],"batl":[[1,5.8,0]],"ltp":5.0,"tv":9.08,"id":16569870}]}]}
{"op":"mcm","clk":"1007956837","pt":1580657651925,"mc":[{"id":"1.168224445","rc":[{"batb":[[0,4,101.21],[1,3.95,27.69],[2,1.01,0.51]],"ltp":0.0,"tv":0.0,"id":13117431},{"batb":[[0,2.92,50.27],[1,2.88,58.82],[2,1.01,0.51]],"ltp":0.0,"tv":0.0,"id":13117430},{"batb":[[0,3.05,77.89],[1,3,76.56],[2,1.01,0.51]],"ltp":4.2,"tv":3.36,"id":16569868},{"batb":[[1,5,31.88],[2,4.8,14.32]],"ltp":5.0,"tv":9.08,"id":16569870}]}]}
{"op":"mcm","clk":"1007957577","pt":1580657655328,"mc":[{"id":"1.168224445","rc":[{"batb":[[0,2.88,10.31],[1,1.01,0.51],[2,1.01,0]],"ltp":0.0,"tv":0.0,"id":13117430}]}]}
{"op":"mcm","clk":"1007958014","pt":1580657657430,"mc":[{"id":"1.168224445","rc":[{"batb":[[0,3.7,46.45],[1,3.65,33.7],[2,2.88,10.31]],"ltp":0.0,"tv":0.0,"id":13117430}]}]}
{"op":"mcm","clk":"1007958210","pt":1580657658349,"mc":[{"id":"1.168224445","rc":[{"batb":[[2,3.9,23.76]],"batl":[[0,4.5,11.76],[1,4.6,21.09],[2,4.7,20.3]],"ltp":0.0,"tv":0.0,"id":13117431},{"batb":[[1,3.65,48.82],[2,3.6,14.48]],"batl":[[1,4.4,11.76],[2,5.6,14.16]],"ltp":0.0,"tv":0.0,"id":13117430},{"batb":[[2,2.94,21]],"batl":[[0,3.35,21.79],[1,3.4,16.8],[2,3.7,17.55]],"ltp":4.2,"tv":3.36,"id":16569868},{"batb":[[2,4.8,25.24]],"batl":[[1,5.8,8.4]],"ltp":5.0,"tv":9.08,"id":16569870}]}]}
{"op":"mcm","clk":"1007960233","pt":1580657667381,"mc":[{"id":"1.168224445","rc":[{"batb":[[0,3.95,27.69],[1,3.9,23.76],[2,1.01,0.51]],"batl":[[0,4.7,20.3],[1,4.6,0],[2,4.7,0]],"ltp":0.0,"tv":0.0,"id":13117431},{"batb":[[0,3.25,18.88],[1,1.01,0.51],[2,3.6,0]],"batl":[[0,5.6,14.16],[1,4.4,0],[2,5.6,0]],"ltp":0.0,"tv":0.0,"id":13117430},{"batb":[[0,2.56,13.93],[1,1.01,0.51],[2,2.94,0]],"batl":[[0,3.7,17.55],[1,3.4,0],[2,3.7,0]],"ltp":4.2,"tv":3.36,"id":16569868},{"batb":[[0,5,31.88],[1,4.8,14.32],[2,1.01,0.51]],"batl":[[1,5.8,0]],"ltp":5.0,"tv":9.08,"id":16569870}]}]}
{"op":"mcm","clk":"1007960858","pt":1580657670296,"mc":[{"id":"1.168224445","rc":[{"batb":[[1,3.9,52.74]],"ltp":0.0,"tv":0.0,"id":13117431},{"batb":[[0,3.25,88.45],[1,3.2,46.21],[2,1.01,0.51]],"ltp":0.0,"tv":0.0,"id":13117430},{"batb":[[0,2.62,48.49],[1,2.58,64.35],[2,2.56,13.93]],"ltp":4.2,"tv":3.36,"id":16569868},{"batb":[[0,5,40.38],[1,4.9,33.27],[2,4.8,14.32]],"ltp":5.0,"tv":9.08,"id":16569870}]}]}
{"op":"mcm","clk":"1007961076","pt":1580657671307,"mc":[{"id":"1.168224445","rc":[{"batb":[[1,3.9,23.76]],"ltp":0.0,"tv":0.0,"id":13117431},{"batb":[[0,3.25,18.88],[1,1.01,0.51],[2,1.01,0]],"ltp":0.0,"tv":0.0,"id":13117430},{"batb":[[0,2.56,13.93],[1,1.01,0.51],[2,2.56,0]],"ltp":4.2,"tv":3.36,"id":16569868},{"batb":[[0,5,31.96],[1,4.8,14.32],[2,1.01,0.51]],"ltp":5.0,"tv":9.08,"id":16569870}]}]}
{"op":"mcm","clk":"1007962692","pt":1580657678602,"mc":[{"id":"1.168224445","rc":[{"batb":[[1,3.9,52.74]],"ltp":0.0,"tv":0.0,"id":13117431},{"batb":[[0,3.25,87.4],[1,3.2,46.21],[2,1.01,0.51]],"ltp":0.0,"tv":0.0,"id":13117430},{"batb":[[0,2.62,49.84],[1,2.58,64.36],[2,2.56,13.93]],"ltp":4.2,"tv":3.36,"id":16569868},{"batb":[[0,5,40.93],[1,4.9,33.27],[2,4.8,14.32]],"ltp":5.0,"tv":9.08,"id":16569870}]}]}
{"op":"mcm","clk":"1007966296","pt":1580657694796,"mc":[{"id":"1.168224445","rc":[{"batb":[[0,3.25,18.88],[1,1.01,0.51],[2,1.01,0]],"ltp":0.0,"tv":0.0,"id":13117430}]}]}
{"op":"mcm","clk":"1007966861","pt":1580657697393,"mc":[{"id":"1.168224445","rc":[{"batb":[[0,5,26.79],[1,4.9,33.8],[2,3.25,18.88]],"ltp":0.0,"tv":0.0,"id":13117430}]}]}
{"op":"mcm","clk":"1007967061","pt":1580657698322,"mc":[{"id":"1.168224445","rc":[{"batb":[[2,3.75,12.98]],"batl":[[0,4.3,12.6],[1,4.5,22.42],[2,4.6,21.56]],"ltp":0.0,"tv":0.0,"id":13117431},{"batb":[[2,4.8,14.79]],"batl":[[1,5.8,8.4],[2,10,8.5]],"ltp":0.0,"tv":0.0,"id":13117430},{"batb":[[2,2.56,40.81]],"batl":[[0,2.78,13.69],[1,2.94,21],[2,3.1,10.54]],"ltp":4.2,"tv":3.36,"id":16569868},{"batb":[[2,4.8,25.24]],"batl":[[0,5.6,13.69],[1,5.7,8.4]],"ltp":5.0,"tv":9.08,"id":16569870}]}]}
{"op":"mcm","clk":"1007970377","pt":1580657713132,"mc":[{"id":"1.168224445","rc":[{"batb":[[0,3.9,23.76],[1,3.75,12.98],[2,3.7,15.12]],"ltp":0.0,"tv":0.0,"id":13117431},{"batb":[[0,4.8,14.79],[1,4.7,10.92],[2,4,22.66]],"ltp":0.0,"tv":0.0,"id":13117430},{"batb":[[0,2.56,40.81],[1,2.16,22.42],[2,1.01,0.51]],"ltp":4.2,"tv":3.36,"id":16569868},{"batb":[[0,5,20.25]],"ltp":5.0,"tv":9.08,"id":16569870}]}]}
{"op":"mcm","clk":"1007970500","pt":1580657713464,"mc":[{"id":"1.168224445","rc":[{"batb":[[0,3.75,12.98],[1,3.7,15.12],[2,1.01,0.51]],"batl":[[1,4.6,21.56],[2,4.6,0]],"ltp":0.0,"tv":0.0,"id":13117431},{"batb":[[0,4.7,10.92],[1,4,22.66],[2,1.01,0.51]],"batl":[[0,5.8,8.4],[1,10,8.5],[2,10,0]],"ltp":0.0,"tv":0.0,"id":13117430},{"batb":[[0,2.56,26.89]],"batl":[[0,2.94,21],[1,3.1,10.54],[2,3.1,0]],"ltp":4.2,"tv":3.36,"id":16569868}]}]}
{"op":"mcm","clk":"1007970872","pt":1580657715134,"mc":[{"id":"1.168224445","rc":[{"batb":[[1,1.01,0.51],[2,1.01,0]],"batl":[[0,4.6,21.56],[1,4.6,0]],"ltp":0.0,"tv":0.0,"id":13117431},{"batb":[[0,4,22.66],[1,1.01,0.51],[2,1.01,0]],"batl":[[0,10,8.5],[1,10,0]],"ltp":0.0,"tv":0.0,"id":13117430},{"batb":[[0,2.16,22.42],[1,1.01,0.51],[2,1.01,0]],"batl":[[0,3.1,10.54],[1,3.1,0]],"ltp":4.2,"tv":3.36,"id":16569868},{"batb":[[2,4.8,14.32]],"batl":[[1,5.7,0]],"ltp":5.0,"tv":9.08,"id":16569870}]}]}
{"op":"mcm","clk":"1007971732","pt":1580657718954,"mc":[{"id":"1.168224445","rc":[{"batb":[[0,3.9,44.96],[1,3.85,29.79],[2,3.75,12.98]],"ltp":0.0,"tv":0.0,"id":13117431},{"batb":[[0,5.4,38.16],[1,5.3,28.15],[2,4,22.66]],"ltp":0.0,"tv":0.0,"id":13117430},{"batb":[[0,2.52,67.57],[1,2.48,71.46],[2,2.16,22.42]],"ltp":4.2,"tv":3.36,"id":16569868},{"batb":[[0,5,36.82]],"ltp":5.0,"tv":9.08,"id":16569870}]}]}
{"op":"mcm","clk":"1007972264","pt":1580657721350,"mc":[{"id":"1.168224445","rc":[{"batb":[[0,3.75,12.98],[1,1.01,0.51],[2,3.75,0]],"ltp":0.0,"tv":0.0,"id":13117431},{"batb":[[0,4,22.66],[1,1.01,0.51],[2,4,0]],"ltp":0.0,"tv":0.0,"id":13117430},{"batb":[[0,2.16,22.42],[1,1.01,0.51],[2,2.16,0]],"ltp":4.2,"tv":3.36,"id":16569868},{"batb":[[0,5,20.25]],"ltp":5.0,"tv":9.08,"id":16569870}]}]}
{"op":"mcm","clk":"1007972875","pt":1580657724243,"mc":[{"id":"1.168224445","rc":[{"batb":[[0,3.8,35.87],[1,3.75,44.81],[2,1.01,0.51]],"ltp":0.0,"tv":0.0,"id":13117431},{"batb":[[0,4.1,32.09],[1,4,76.43],[2,1.01,0.51]],"ltp":0.0,"tv":0.0,"id":13117430},{"batb":[[0,2.22,62.15],[1,2.2,50.4],[2,2.16,22.42]],"ltp":4.2,"tv":3.36,"id":16569868}]}]}
{"op":"mcm","clk":"1007974597","pt":1580657732171,"mc":[{"id":"1.168224445","rc":[{"batb":[[0,4,22.66],[1,1.01,0.51],[2,1.01,0]],"ltp":0.0,"tv":0.0,"id":13117430}]}]}
{"op":"mcm","clk":"1007975233","pt":1580657735069,"mc":[{"id":"1.168224445","rc":[{"batb":[[0,8.4,28.57],[1,8.2,21.4],[2,4,22.66]],"ltp":0.0,"tv":0.0,"id":13117430}]}]}
{"op":"mcm","clk":"1007975468","pt":1580657736260,"mc":[{"id":"1.168224445","rc":[{"batl":[[0,4.1,13.44],[1,4.3,24.55],[2,4.4,23.92]],"ltp":0.0,"tv":0.0,"id":13117431},{"batb":[[2,8,8.89]],"batl":[[0,9.4,4.2],[1,10,8.5],[2,28,6.53]],"ltp":0.0,"tv":0.0,"id":13117430},{"batb":[[0,2.24,33.61],[1,2.22,62.15],[2,2.2,50.4]],"batl":[[0,2.32,21.87],[1,2.52,17.7]],"ltp":4.2,"tv":3.36,"id":16569868},{"batb":[[2,4.7,14.87]],"batl":[[1,5.7,8.4]],"ltp":5.0,"tv":9.08,"id":16569870}]}]}
{"op":"mcm","clk":"1007975939","pt":1580657738438,"mc":[{"id":"1.168224445","rc":[{"batl":[[1,2.52,44.59]],"ltp":4.2,"tv":3.36,"id":16569868},{"batb":[[2,4.7,25.79]],"ltp":5.0,"tv":9.08,"id":16569870}]}]}
{"op":"mcm","clk":"1007976091","pt":1580657739133,"mc":[{"id":"1.168224445","rc":[{"batb":[[2,3.5,16.8]],"ltp":0.0,"tv":0.0,"id":13117431}]}]}
{"op":"mcm","clk":"1007976662","pt":1580657741666,"mc":[{"id":"1.168224445","rc":[{"batb":[[0,2.22,62.15],[1,2.2,50.4],[2,2.16,22.42]],"ltp":4.2,"tv":3.36,"id":16569868}]}]}
{"op":"mcm","clk":"1007977264","pt":1580657744671,"mc":[{"id":"1.168224445","rc":[{"batb":[[0,2.22,95.76]],"ltp":4.2,"tv":3.36,"id":16569868}]}]}
{"op":"mcm","clk":"1007977999","pt":1580657748354,"mc":[{"id":"1.168224445","rc":[{"batb":[[0,3.75,12.98],[1,3.5,16.8],[2,1.01,0.51]],"ltp":0.0,"tv":0.0,"id":13117431},{"batb":[[0,8,8.89],[1,7.4,5.88],[2,6.2,16.13]],"ltp":0.0,"tv":0.0,"id":13117430},{"batb":[[0,2.22,33.61],[1,2.16,22.42],[2,1.9,16.52]],"ltp":4.2,"tv":3.36,"id":16569868},{"batb":[[0,4.9,33.27],[1,4.7,25.79],[2,1.01,0.51]],"ltp":5.0,"tv":9.08,"id":16569870}]}]}
{"op":"mcm","clk":"1007978152","pt":1580657749052,"mc":[{"id":"1.168224445","rc":[{"batb":[[1,1.01,0.51],[2,1.01,0]],"batl":[[0,4.4,23.92],[1,4.3,0],[2,4.4,0]],"ltp":0.0,"tv":0.0,"id":13117431},{"batb":[[0,6.2,16.13],[1,1.01,0.51],[2,6.2,0]],"batl":[[0,28,6.53],[1,10,0],[2,28,0]],"ltp":0.0,"tv":0.0,"id":13117430},{"batb":[[0,1.9,16.52],[1,1.01,0.51],[2,1.9,0]],"batl":[[0,2.52,17.7],[1,2.52,0]],"ltp":4.2,"tv":3.36,"id":16569868},{"batb":[[1,4.7,14.87]],"batl":[[1,5.7,0]],"ltp":5.0,"tv":9.08,"id":16569870}]}]}
{"op":"mcm","clk":"1007978615","pt":1580657751360,"mc":[{"id":"1.168224445","rc":[{"batb":[[1,3.7,51.9],[2,3.65,33.65]],"ltp":0.0,"tv":0.0,"id":13117431},{"batb":[[0,6.4,45.86],[1,6.2,54.95],[2,1.01,0.51]],"ltp":0.0,"tv":0.0,"id":13117430},{"batb":[[0,1.97,79.18],[1,1.95,71.83],[2,1.9,16.52]],"ltp":4.2,"tv":3.36,"id":16569868},{"batb":[[0,4.9,43.83],[1,4.8,49.52],[2,4.7,14.87]],"ltp":5.0,"tv":9.08,"id":16569870}]}]}
{"op":"mcm","clk":"1007978651","pt":1580657751582,"mc":[{"id":"1.168224445","rc":[{"batb":[[2,1.01,0.51]],"ltp":5.0,"tv":9.08,"id":16569870}]}]}
{"op":"mcm","clk":"1007978953","pt":1580657753171,"mc":[{"id":"1.168224445","rc":[{"batb":[[0,6.2,16.13],[1,1.01,0.51],[2,1.01,0]],"ltp":0.0,"tv":0.0,"id":13117430}]}]}
{"op":"mcm","clk":"1007979610","pt":1580657756363,"mc":[{"id":"1.168224445","rc":[{"batb":[[1,3.7,65.43],[2,3.65,48.77]],"batl":[[0,4.2,25.65],[1,4.3,12.6],[2,4.4,23.92]],"ltp":0.0,"tv":0.0,"id":13117431},{"batb":[[0,19,10.75],[1,18.5,9.74],[2,17.5,7.16]],"ltp":0.0,"tv":0.0,"id":13117430},{"batb":[[2,1.93,44.53]],"batl":[[0,2.02,16.21],[1,2.14,36.13],[2,2.24,24.63]],"ltp":4.2,"tv":3.36,"id":16569868},{"batb":[[2,4.7,10.92]],"batl":[[0,5.6,22.09]],"ltp":5.0,"tv":9.08,"id":16569870}]}]}
{"op":"mcm","clk":"1007979707","pt":1580657756907,"mc":[{"id":"1.168224445","rc":[{"batb":[[0,3.7,65.43],[1,3.65,48.77],[2,1.01,0.51]],"batl":[[2,4.4,0]],"ltp":0.0,"tv":0.0,"id":13117431}]}]}
{"op":"mcm","clk":"1007980880","pt":1580657762387,"mc":[{"id":"1.168224445","rc":[{"batl":[[2,2.22,4.89]],"ltp":4.2,"tv":3.36,"id":16569868}]}]}
{"op":"mcm","clk":"1007981263","pt":1580657764209,"mc":[{"id":"1.168224445","rc":[{"batl":[[2,2.24,24.63]],"ltp":4.2,"tv":3.36,"id":16569868}]}]}
{"op":"mcm","clk":"1007981427","pt":1580657764889,"mc":[{"id":"1.168224445","rc":[{"trd":[[2.02,3.36]],"batl":[[0,2.02,14.53]],"ltp":2.02,"tv":6.72,"id":16569868}],"tv":15.8}]}
{"op":"mcm","clk":"1007982108","pt":1580657768000,"mc":[{"id":"1.168224445","rc":[{"batb":[[0,3.7,46.58],[1,3.65,15.12]],"ltp":0.0,"tv":0.0,"id":13117431}]}]}
{"op":"mcm","clk":"1007982735","pt":1580657770931,"mc":[{"id":"1.168224445","rc":[{"batb":[[0,3.75,31.02],[1,3.7,46.58],[2,3.65,15.12]],"ltp":0.0,"tv":0.0,"id":13117431},{"trd":[[2.02,6.81]],"batl":[[0,2.02,12.81]],"ltp":2.02,"tv":10.16,"id":16569868}],"tv":19.24}]}
{"op":"mcm","clk":"1007984417","pt":1580657778435,"mc":[{"id":"1.168224445","rc":[{"trd":[[2.02,6.97]],"batl":[[0,2.02,12.72]],"ltp":2.02,"tv":10.33,"id":16569868}],"tv":19.41}]}
{"op":"mcm","clk":"1007985245","pt":1580657782107,"mc":[{"id":"1.168224445","rc":[{"batb":[[0,19,12.8]],"ltp":0.0,"tv":0.0,"id":13117430}]}]}
{"op":"mcm","clk":"1007987694","pt":1580657793252,"mc":[{"id":"1.168224445","rc":[{"batb":[[0,17.5,7.16],[1,10,13.3],[2,1.01,0.51]],"ltp":0.0,"tv":0.0,"id":13117430},{"batb":[[0,1.93,44.53],[1,1.9,16.52],[2,1.83,18.8]],"ltp":2.02,"tv":10.33,"id":16569868}]}]}
{"op":"mcm","clk":"1007988370","pt":1580657796367,"mc":[{"id":"1.168224445","rc":[{"batl":[[0,4.2,12.9]],"ltp":0.0,"tv":0.0,"id":13117431},{"batb":[[0,10.5,10.84],[1,10,48.32]],"ltp":0.0,"tv":0.0,"id":13117430},{"batb":[[1,1.89,67.54],[2,1.87,82.39]],"batl":[[0,2.14,36.13],[1,2.24,24.63],[2,2.24,0]],"ltp":2.02,"tv":10.33,"id":16569868}]}]}
{"op":"mcm","clk":"1007988584","pt":1580657797382,"mc":[{"id":"1.168224445","rc":[{"batb":[[2,1.01,0.51]],"batl":[[1,4.3,0]],"ltp":0.0,"tv":0.0,"id":13117431},{"batb":[[0,1.89,67.54],[1,1.87,82.39],[2,1.83,18.8]],"batl":[[0,2.24,24.63],[1,2.24,0]],"ltp":2.02,"tv":10.33,"id":16569868},{"batb":[[2,1.01,0.51]],"batl":[[0,5.6,13.69]],"ltp":5.0,"tv":9.08,"id":16569870}]}]}
{"op":"mcm","clk":"1007989613","pt":1580657802594,"mc":[{"id":"1.168224445","rc":[{"batb":[[0,10,13.3],[1,1.01,0.51],[2,1.01,0]],"ltp":0.0,"tv":0.0,"id":13117430}]}]}
{"op":"mcm","clk":"1007990405","pt":1580657806369,"mc":[{"id":"1.168224445","rc":[{"batb":[[2,3.65,15.12]],"batl":[[0,4.3,37.15]],"ltp":0.0,"tv":0.0,"id":13117431},{"batb":[[0,34,9.53],[1,32,11.03],[2,15.5,5.04]],"ltp":0.0,"tv":0.0,"id":13117430},{"batb":[[2,1.86,48.73]],"batl":[[0,1.94,18.41],[1,2.04,40.33],[2,2.1,29.66]],"ltp":2.02,"tv":10.33,"id":16569868},{"batb":[[2,4.7,10.92]],"batl":[[0,5.6,22.09]],"ltp":5.0,"tv":9.08,"id":16569870}]}]}
{"op":"mcm","clk":"1007992216","pt":1580657814480,"mc":[{"id":"1.168224445","rc":[{"batb":[[0,4.9,35.65]],"ltp":5.0,"tv":9.08,"id":16569870}]}]}
{"op":"mcm","clk":"1007993722","pt":1580657821414,"mc":[{"id":"1.168224445","rc":[{"batb":[[0,3.7,46.58],[1,3.65,15.12],[2,1.01,0.51]],"ltp":0.0,"tv":0.0,"id":13117431},{"batb":[[0,15.5,5.04],[1,1.01,0.51],[2,15.5,0]],"ltp":0.0,"tv":0.0,"id":13117430},{"batb":[[0,1.86,48.73],[1,1.77,20.93],[2,1.01,0.51]],"batl":[[0,2.04,40.33],[1,2.1,29.66],[2,2.1,0]],"ltp":2.02,"tv":10.33,"id":16569868}]}]}
{"op":"mcm","clk":"1007994140","pt":1580657823176,"mc":[{"id":"1.168224445","rc":[{"batb":[[1,1.01,0.51],[2,1.01,0]],"batl":[[0,4.3,24.55]],"ltp":0.0,"tv":0.0,"id":13117431},{"batb":[[0,1.77,20.93],[1,1.01,0.51],[2,1.01,0]],"batl":[[0,2.1,29.66],[1,2.1,0]],"ltp":2.02,"tv":10.33,"id":16569868},{"batb":[[2,1.01,0.51]],"batl":[[0,5.6,13.69]],"ltp":5.0,"tv":9.08,"id":16569870}]}]}
{"op":"mcm","clk":"1007994502","pt":1580657824969,"mc":[{"id":"1.168224445","rc":[{"batb":[[0,3.7,64.81],[1,3.65,34.06],[2,1.01,0.51]],"ltp":0.0,"tv":0.0,"id":13117431},{"batb":[[0,16.5,11.33],[1,16,13.25],[2,15.5,5.04]],"ltp":0.0,"tv":0.0,"id":13117430},{"batb":[[0,1.83,67.25],[1,1.81,91.55],[2,1.77,20.93]],"ltp":2.02,"tv":10.33,"id":16569868}]}]}
{"op":"mcm","clk":"1007998030","pt":1580657840432,"mc":[{"id":"1.168224445","rc":[{"batb":[[0,1.77,20.93],[1,1.01,0.51],[2,1.77,0]],"ltp":2.02,"tv":10.33,"id":16569868}]}]}
{"op":"mcm","clk":"1007998618","pt":1580657843029,"mc":[{"id":"1.168224445","rc":[{"batb":[[0,2,99.07],[1,1.98,68.91],[2,1.77,20.93]],"ltp":2.02,"tv":10.33,"id":16569868}]}]}
{"op":"mcm","clk":"1007998858","pt":1580657844015,"mc":[{"id":"1.168224445","rc":[{"batb":[[0,3.7,51.28],[1,3.65,63.11]],"batl":[[0,4.2,13.3],[1,4.3,12.6]],"ltp":0.0,"tv":0.0,"id":13117431},{"batl":[[0,23,4.72]],"ltp":0.0,"tv":0.0,"id":13117430},{"batb":[[2,1.95,74.22]],"batl":[[1,2.16,36.13],[2,2.36,21.24]],"ltp":2.02,"tv":10.33,"id":16569868},{"batb":[[2,4.7,10.92]],"batl":[[0,5.6,22.09]],"ltp":5.0,"tv":9.08,"id":16569870}]}]}
{"op":"mcm","clk":"1008003640","pt":1580657865372,"mc":[{"id":"1.168224445","rc":[{"batb":[[0,3.7,33.05]],"ltp":0.0,"tv":0.0,"id":13117431},{"batb":[[0,13.5,3.36],[1,8.4,8.26],[2,1.01,0.51]],"ltp":0.0,"tv":0.0,"id":13117430},{"batb":[[0,1.95,43.69],[1,1.86,17.78],[2,1.01,0.51]],"batl":[[0,2.16,36.13],[1,2.36,21.24],[2,2.36,0]],"ltp":2.02,"tv":10.33,"id":16569868},{"batb":[[0,4.9,33.27]],"ltp":5.0,"tv":9.08,"id":16569870}]}]}
{"op":"mcm","clk":"1008004076","pt":1580657867156,"mc":[{"id":"1.168224445","rc":[{"batb":[[1,3.65,47.99]],"batl":[[1,4.3,0]],"ltp":0.0,"tv":0.0,"id":13117431},{"batb":[[0,8.4,8.26],[1,1.01,0.51],[2,1.01,0]],"ltp":0.0,"tv":0.0,"id":13117430},{"batb":[[0,1.86,17.78],[1,1.01,0.51],[2,1.01,0]],"batl":[[0,2.36,21.24],[1,2.36,0]],"ltp":2.02,"tv":10.33,"id":16569868},{"batb":[[2,1.01,0.51]],"batl":[[0,5.6,13.69]],"ltp":5.0,"tv":9.08,"id":16569870}]}]}
{"op":"mcm","clk":"1008004292","pt":1580657868071,"mc":[{"id":"1.168224445","rc":[{"batb":[[0,8.6,13.39],[1,8.4,29.15],[2,1.01,0.51]],"ltp":0.0,"tv":0.0,"id":13117430},{"batb":[[0,1.91,61.81],[1,1.89,79.65],[2,1.86,17.78]],"ltp":2.02,"tv":10.33,"id":16569868}]}]}
{"op":"mcm","clk":"1008004522","pt":1580657869057,"mc":[{"id":"1.168224445","rc":[{"batb":[[0,8.4,8.26],[1,1.01,0.51],[2,1.01,0]],"ltp":0.0,"tv":0.0,"id":13117430}]}]}
{"op":"mcm","clk":"1008005211","pt":1580657872177,"mc":[{"id":"1.168224445","rc":[{"batb":[[2,3.55,15.96]],"batl":[[0,4.1,13.38],[1,4.2,25.9]],"ltp":0.0,"tv":0.0,"id":13117431},{"batb":[[0,32,14.77],[1,30,6.81],[2,27,3.07]],"ltp":0.0,"tv":0.0,"id":13117430},{"batb":[[2,1.86,66.51]],"batl":[[0,1.97,17.47],[1,2.06,39.49],[2,2.16,27.07]],"ltp":2.02,"tv":10.33,"id":16569868},{"batb":[[2,4.7,26.03]],"batl":[[0,5.6,22.09]],"ltp":5.0,"tv":9.08,"id":16569870}]}]}
{"op":"mcm","clk":"1008005445","pt":1580657873259,"mc":[{"id":"1.168224445","rc":[{"batl":[[1,4.2,12.6]],"ltp":0.0,"tv":0.0,"id":13117431},{"batb":[[1,4.8,34.73]],"ltp":5.0,"tv":9.08,"id":16569870}]}]}
{"op":"mcm","clk":"1008008152","pt":1580657885373,"mc":[{"id":"1.168224445","rc":[{"batb":[[0,27,3.07],[1,13.5,6.77],[2,1.01,0.51]],"ltp":0.0,"tv":0.0,"id":13117430},{"batb":[[0,1.86,66.51],[1,1.8,19.99],[2,1.01,0.51]],"ltp":2.02,"tv":10.33,"id":16569868}]}]}
{"op":"mcm","clk":"1008008216","pt":1580657885709,"mc":[{"id":"1.168224445","rc":[{"batb":[[0,13.5,6.77],[1,1.01,0.51],[2,1.01,0]],"ltp":0.0,"tv":0.0,"id":13117430},{"batb":[[0,1.86,48.73]],"batl":[[0,2.06,39.49],[1,2.16,27.07],[2,2.16,0]],"ltp":2.02,"tv":10.33,"id":16569868}]}]}
{"op":"mcm","clk":"1008008522","pt":1580657887180,"mc":[{"id":"1.168224445","rc":[{"batb":[[2,1.01,0.51]],"batl":[[1,4.2,0]],"ltp":0.0,"tv":0.0,"id":13117431},{"batb":[[0,1.8,19.99],[1,1.01,0.51],[2,1.01,0]],"batl":[[0,2.16,27.07],[1,2.16,0]],"ltp":2.02,"tv":10.33,"id":16569868},{"batb":[[2,4.7,15.11]],"batl":[[0,5.6,13.69]],"ltp":5.0,"tv":9.08,"id":16569870}]}]}
{"op":"mcm","clk":"1008009389","pt":1580657891102,"mc":[{"id":"1.168224445","rc":[{"batb":[[0,26,10.84],[1,25,10.35],[2,13.5,6.77]],"ltp":0.0,"tv":0.0,"id":13117430},{"batb":[[0,1.94,53.62],[1,1.92,75.8],[2,1.8,19.99]],"ltp":2.02,"tv":10.33,"id":16569868}]}]}
{"op":"mcm","clk":"1008010315","pt":1580657895377,"mc":[{"id":"1.168224445","rc":[{"batb":[[0,13.5,6.77],[1,1.01,0.51],[2,13.5,0]],"ltp":0.0,"tv":0.0,"id":13117430},{"batb":[[0,1.8,19.99],[1,1.01,0.51],[2,1.8,0]],"ltp":2.02,"tv":10.33,"id":16569868}]}]}
{"op":"mcm","clk":"1008010928","pt":1580657897894,"mc":[{"id":"1.168224445","rc":[{"batb":[[0,14,24.2],[1,13.5,25.16],[2,1.01,0.51]],"ltp":0.0,"tv":0.0,"id":13117430},{"batb":[[0,1.84,62.03],[1,1.82,89.9],[2,1.8,19.99]],"ltp":2.02,"tv":10.33,"id":16569868}]}]}
{"op":"mcm","clk":"1008012859","pt":1580657906172,"mc":[{"id":"1.168224445","rc":[{"batb":[[0,13.5,6.77],[1,1.01,0.51],[2,1.01,0]],"ltp":0.0,"tv":0.0,"id":13117430}]}]}
{"op":"mcm","clk":"1008013590","pt":1580657909163,"mc":[{"id":"1.168224445","rc":[{"batb":[[0,3.7,46.9],[1,3.65,34.06],[2,3.55,14.95]],"batl":[[1,4.2,25.57]],"ltp":0.0,"tv":0.0,"id":13117431},{"batb":[[0,110,4.13],[1,100,2.22],[2,1.01,0.51]],"ltp":0.0,"tv":0.0,"id":13117430},{"batl":[[0,1.9,19.59],[1,2,16.84]],"ltp":2.02,"tv":10.33,"id":16569868}]}]}
{"op":"mcm","clk":"1008013800","pt":1580657910090,"mc":[{"id":"1.168224445","rc":[{"batb":[[2,3.55,30.91]],"batl":[[0,4.1,26.82]],"ltp":0.0,"tv":0.0,"id":13117431},{"batl":[[1,1.99,42.01],[2,2,16.84]],"ltp":2.02,"tv":10.33,"id":16569868},{"batb":[[2,4.7,26.03]],"batl":[[0,5.6,22.09]],"ltp":5.0,"tv":9.08,"id":16569870}]}]}
{"op":"mcm","clk":"1008017911","pt":1580657928364,"mc":[{"id":"1.168224445","rc":[{"batb":[[0,3.7,13.85],[1,3.55,30.91],[2,1.01,0.51]],"ltp":0.0,"tv":0.0,"id":13117431},{"batb":[[0,1.01,0.51],[1,100,0],[2,1.01,0]],"ltp":0.0,"tv":0.0,"id":13117430},{"batb":[[0,1.8,19.99],[1,1.79,52.93],[2,1.75,21.87]],"ltp":2.02,"tv":10.33,"id":16569868},{"batb":[[0,4.8,34.73],[1,4.7,26.03],[2,1.01,0.51]],"ltp":5.0,"tv":9.08,"id":16569870}]}]}
{"op":"mcm","clk":"1008018051","pt":1580657929075,"mc":[{"id":"1.168224445","rc":[{"batb":[[0,3.55,14.95],[1,1.01,0.51],[2,1.01,0]],"batl":[[0,4.2,25.57],[1,4.2,0]],"ltp":0.0,"tv":0.0,"id":13117431},{"batb":[[0,1.75,21.87],[1,1.01,0.51],[2,1.75,0]],"batl":[[0,2,16.84],[1,1.99,0],[2,2,0]],"ltp":2.02,"tv":10.33,"id":16569868},{"batb":[[1,4.7,15.11]],"batl":[[0,5.6,13.69]],"ltp":5.0,"tv":9.08,"id":16569870}]}]}
{"op":"mcm","clk":"1008018535","pt":1580657931408,"mc":[{"id":"1.168224445","rc":[{"batb":[[0,3.6,52.59],[1,3.55,51.34],[2,1.01,0.51]],"ltp":0.0,"tv":0.0,"id":13117431},{"batb":[[0,38,10.73],[1,36,7.47],[2,1.01,0.51]],"ltp":0.0,"tv":0.0,"id":13117430},{"batb":[[0,1.8,73.81],[1,1.78,96.65],[2,1.75,21.87]],"ltp":2.02,"tv":10.33,"id":16569868},{"batb":[[0,4.8,54.85],[1,4.7,51.48]],"ltp":5.0,"tv":9.08,"id":16569870}]}]}
{"op":"mcm","clk":"1008018637","pt":1580657931786,"mc":[{"id":"1.168224445","rc":[{"batb":[[0,3.6,35.14],[1,3.55,14.95]],"ltp":0.0,"tv":0.0,"id":13117431},{"batb":[[0,1.01,0.51],[1,36,0],[2,1.01,0]],"ltp":0.0,"tv":0.0,"id":13117430},{"batb":[[0,1.75,21.87],[1,1.01,0.51],[2,1.75,0]],"ltp":2.02,"tv":10.33,"id":16569868},{"batb":[[0,4.8,35.12],[1,4.7,15.11]],"ltp":5.0,"tv":9.08,"id":16569870}]}]}
{"op":"mcm","clk":"1008019034","pt":1580657933375,"mc":[{"id":"1.168224445","rc":[{"batb":[[0,3.65,57.06],[1,3.6,35.14],[2,3.55,14.95]],"ltp":0.0,"tv":0.0,"id":13117431},{"batb":[[0,80,5.17],[1,75,3.5],[2,1.01,0.51]],"ltp":0.0,"tv":0.0,"id":13117430},{"batb":[[0,1.85,84.49],[1,1.83,88.35],[2,1.75,21.87]],"ltp":2.02,"tv":10.33,"id":16569868},{"batb":[[0,4.9,25.36],[1,4.8,35.12],[2,4.7,15.11]],"ltp":5.0,"tv":9.08,"id":16569870}]}]}
{"op":"mcm","clk":"1008019661","pt":1580657936301,"mc":[{"id":"1.168224445","rc":[{"batb":[[0,3.6,35.14],[1,3.55,14.95],[2,1.01,0.51]],"ltp":0.0,"tv":0.0,"id":13117431},{"batb":[[0,1.01,0.51],[1,75,0],[2,1.01,0]],"ltp":0.0,"tv":0.0,"id":13117430},{"batb":[[0,1.75,21.87],[1,1.01,0.51],[2,1.75,0]],"ltp":2.02,"tv":10.33,"id":16569868},{"batb":[[0,4.8,35.12],[1,4.7,15.11],[2,1.01,0.51]],"ltp":5.0,"tv":9.08,"id":16569870}]}]}
{"op":"mcm","clk":"1008020456","pt":1580657940012,"mc":[{"id":"1.168224445","rc":[{"batb":[[0,3.6,52.59],[1,3.55,51.34]],"ltp":0.0,"tv":0.0,"id":13117431},{"batb":[[0,38,10.73],[1,36,7.47],[2,1.01,0.51]],"ltp":0.0,"tv":0.0,"id":13117430},{"batb":[[0,1.8,73.81],[1,1.78,96.65],[2,1.75,21.87]],"ltp":2.02,"tv":10.33,"id":16569868},{"batb":[[0,4.8,54.85],[1,4.7,51.48]],"ltp":5.0,"tv":9.08,"id":16569870}]}]}
{"op":"mcm","clk":"1008020977","pt":1580657942304,"mc":[{"id":"1.168224445","rc":[{"batb":[[0,1.75,21.87],[1,1.01,0.51],[2,1.75,0]],"ltp":2.02,"tv":10.33,"id":16569868}]}]}
{"op":"mcm","clk":"1008021743","pt":1580657945437,"mc":[{"id":"1.168224445","rc":[{"batl":[[0,4,14.32],[1,4.2,25.57]],"ltp":0.0,"tv":0.0,"id":13117431},{"batb":[[2,12.5,7.79]],"ltp":0.0,"tv":0.0,"id":13117430},{"batb":[[0,1.91,91.39],[1,1.89,96.74],[2,1.8,19.67]],"batl":[[1,2.2,25.49]],"ltp":2.02,"tv":10.33,"id":16569868},{"batl":[[0,5.5,14.48],[1,5.6,13.69]],"ltp":5.0,"tv":9.08,"id":16569870}]}]}
{"op":"mcm","clk":"1008021914","pt":1580657946112,"mc":[{"id":"1.168224445","rc":[{"batb":[[2,3.5,16.8]],"batl":[[1,4.1,13.44]],"ltp":0.0,"tv":0.0,"id":13117431},{"batb":[[2,1.88,47.05]],"batl":[[1,2.06,39.49],[2,2.2,25.49]],"ltp":2.02,"tv":10.33,"id":16569868},{"batb":[[1,4.7,62.4]],"batl":[[1,5.6,8.4]],"ltp":5.0,"tv":9.08,"id":16569870}]}]}
{"op":"mcm","clk":"1008024056","pt":1580657955246,"mc":[{"id":"1.168224445","rc":[{"batb":[[0,1.89,17.07],[1,1.88,47.05],[2,1.8,19.67]],"ltp":2.02,"tv":10.33,"id":16569868}]}]}
{"op":"mcm","clk":"1008024746","pt":1580657958227,"mc":[{"id":"1.168224445","rc":[{"batb":[[0,1.92,53.22],[1,1.9,78.33],[2,1.89,17.07]],"ltp":2.02,"tv":10.33,"id":16569868}]}]}
{"op":"mcm","clk":"1008025839","pt":1580657963127,"mc":[{"id":"1.168224445","rc":[{"batb":[[0,3.6,42.82],[2,1.01,0.51]],"batl":[[1,4.1,0]],"ltp":0.0,"tv":0.0,"id":13117431},{"batb":[[0,12.5,7.79],[1,1.01,0.51],[2,12.5,0]],"ltp":0.0,"tv":0.0,"id":13117430},{"batb":[[0,1.8,19.67],[1,1.01,0.51],[2,1.89,0]],"batl":[[0,2.2,25.49],[1,2.06,0],[2,2.2,0]],"ltp":2.02,"tv":10.33,"id":16569868},{"batb":[[1,4.7,51.48]],"batl":[[1,5.6,0]],"ltp":5.0,"tv":9.08,"id":16569870}]}]}
{"op":"mcm","clk":"1008026350","pt":1580657965355,"mc":[{"id":"1.168224445","rc":[{"batb":[[0,4.8,35.2],[1,4.7,15.11]],"ltp":5.0,"tv":9.08,"id":16569870}]}]}
{"op":"mcm","clk":"1008027055","pt":1580657968352,"mc":[{"id":"1.168224445","rc":[{"batb":[[0,3.6,55.14]],"ltp":0.0,"tv":0.0,"id":13117431},{"batb":[[0,29,3.66],[1,28,8.45],[2,12.5,7.79]],"ltp":0.0,"tv":0.0,"id":13117430},{"batb":[[0,1.95,58.17],[1,1.93,74.59],[2,1.8,19.67]],"ltp":2.02,"tv":10.33,"id":16569868},{"batb":[[0,4.9,21.02],[1,4.8,35.2],[2,4.7,15.11]],"ltp":5.0,"tv":9.08,"id":16569870}]}]}
{"op":"mcm","clk":"1008027789","pt":1580657971544,"mc":[{"id":"1.168224445","rc":[{"batb":[[0,3.6,42.82]],"ltp":0.0,"tv":0.0,"id":13117431},{"batb":[[0,12.5,7.79],[1,1.01,0.51],[2,12.5,0]],"ltp":0.0,"tv":0.0,"id":13117430},{"batb":[[0,1.8,19.67],[1,1.01,0.51],[2,1.8,0]],"ltp":2.02,"tv":10.33,"id":16569868},{"batb":[[0,4.8,35.2],[1,4.7,15.11],[2,1.01,0.51]],"ltp":5.0,"tv":9.08,"id":16569870}]}]}
{"op":"mcm","clk":"1008028537","pt":1580657974512,"mc":[{"id":"1.168224445","rc":[{"batb":[[0,13.5,24.26],[1,13,19.89],[2,12.5,7.79]],"ltp":0.0,"tv":0.0,"id":13117430},{"batb":[[0,1.83,99.76],[1,1.81,91.51],[2,1.8,19.67]],"ltp":2.02,"tv":10.33,"id":16569868},{"batb":[[0,4.8,50.69],[1,4.7,51.51]],"ltp":5.0,"tv":9.08,"id":16569870}]}]}
{"op":"mcm","clk":"1008029434","pt":1580657978341,"mc":[{"id":"1.168224445","rc":[{"batb":[[0,12.5,7.79],[1,1.01,0.51],[2,12.5,0]],"ltp":0.0,"tv":0.0,"id":13117430}]}]}
{"op":"mcm","clk":"1008030135","pt":1580657981325,"mc":[{"id":"1.168224445","rc":[{"batb":[[0,3.6,57.61],[1,3.55,36.39],[2,3.35,17.23]],"batl":[[1,4.6,21.09]],"ltp":0.0,"tv":0.0,"id":13117431},{"batb":[[0,1.01,0.51],[1,1.01,0]],"ltp":0.0,"tv":0.0,"id":13117430},{"batl":[[0,1.91,19.36],[1,2.02,16.37]],"ltp":2.02,"tv":10.33,"id":16569868},{"batb":[[2,4.5,17.15]],"batl":[[1,6.2,11.09]],"ltp":5.0,"tv":9.08,"id":16569870}]}]}
{"op":"mcm","clk":"1008030366","pt":1580657982370,"mc":[{"id":"1.168224445","rc":[{"batb":[[2,3.4,16.8]],"ltp":0.0,"tv":0.0,"id":13117431},{"batb":[[2,4.6,10.92]],"batl":[[1,5.6,8.4],[2,6.2,11.09]],"ltp":5.0,"tv":9.08,"id":16569870}]}]}
{"op":"mcm","clk":"1008030415","pt":1580657982538,"mc":[{"id":"1.168224445","rc":[{"batl":[[0,4,27.76]],"ltp":0.0,"tv":0.0,"id":13117431},{"batl":[[1,1.98,42.01],[2,2.02,16.37]],"ltp":2.02,"tv":10.33,"id":16569868}]}]}
{"op":"mcm","clk":"1008032912","pt":1580657992974,"mc":[{"id":"1.168224445","rc":[{"batb":[[0,3.6,42.82],[1,3.55,51.65]],"batl":[[0,3.95,14.79],[1,4,13.44],[2,4.6,21.09]],"ltp":0.0,"tv":0.0,"id":13117431},{"batb":[[1,1.81,110.94],[2,1.79,52.93]],"batl":[[0,1.92,19.04],[2,2.04,16.13]],"ltp":2.02,"tv":10.33,"id":16569868},{"batb":[[1,4.7,51.35]],"batl":[[0,5.5,14.32],[2,6.2,10.94]],"ltp":5.0,"tv":9.08,"id":16569870}]}]}
{"op":"mcm","clk":"1008037034","pt":1580658010186,"mc":[{"id":"1.168224445","rc":[{"batb":[[1,3.55,36.39],[2,3.5,15.66]],"batl":[[0,3.9,15.11],[2,4.5,22.27]],"ltp":0.0,"tv":0.0,"id":13117431},{"batb":[[1,1.82,19.12],[2,1.81,91.51]],"batl":[[0,1.93,18.8],[2,2.04,15.89]],"ltp":2.02,"tv":10.33,"id":16569868},{"batb":[[0,4.8,65.56],[1,4.7,36.4]],"batl":[[2,6.4,10.86]],"ltp":5.0,"tv":9.08,"id":16569870}]}]}
{"op":"mcm","clk":"1008038239","pt":1580658015072,"mc":[{"id":"1.168224445","rc":[{"batl":[[0,5.5,14.16]],"ltp":5.0,"tv":9.08,"id":16569870}]}]}
{"op":"mcm","clk":"1008047453","pt":1580658052356,"mc":[{"id":"1.168224445","rc":[{"batb":[[0,18,15.12],[1,1.01,0.51]],"ltp":0.0,"tv":0.0,"id":13117430}]}]}
{"op":"mcm","clk":"1008051957","pt":1580658071981,"mc":[{"id":"1.168224445","rc":[{"batb":[[0,3.4,16.8],[1,3.3,17.7],[2,1.01,0.51]],"batl":[[0,4,13.44],[1,4.5,22.27],[2,4.5,0]],"ltp":0.0,"tv":0.0,"id":13117431},{"batb":[[0,1.79,52.93],[1,1.65,26.36],[2,1.01,0.51]],"batl":[[0,1.98,42.01],[1,2.04,15.89],[2,2.04,0]],"ltp":2.02,"tv":10.33,"id":16569868},{"batb":[[0,4.6,10.92],[1,4.5,16.84],[2,1.01,0.51]],"batl":[[0,5.6,8.4],[1,6.4,10.86],[2,6.4,0]],"ltp":5.0,"tv":9.08,"id":16569870}]}]}
{"op":"mcm","clk":"1008052245","pt":1580658073155,"mc":[{"id":"1.168224445","rc":[{"batb":[[0,3.3,17.7],[1,1.01,0.51],[2,1.01,0]],"batl":[[0,4.5,22.27],[1,4.5,0]],"ltp":0.0,"tv":0.0,"id":13117431},{"batb":[[0,1.65,26.36],[1,1.01,0.51],[2,1.01,0]],"batl":[[0,2.04,15.89],[1,2.04,0]],"ltp":2.02,"tv":10.33,"id":16569868},{"batb":[[0,4.5,16.84],[1,1.01,0.51],[2,1.01,0]],"batl":[[0,6.4,10.86],[1,6.4,0]],"ltp":5.0,"tv":9.08,"id":16569870}]}]}
{"op":"mcm","clk":"1008052974","pt":1580658076461,"mc":[{"id":"1.168224445","rc":[{"batb":[[0,3.7,32.73],[1,3.65,34.19],[2,3.3,17.7]],"ltp":0.0,"tv":0.0,"id":13117431},{"batb":[[0,1.8,76.48],[1,1.78,96.76],[2,1.65,26.36]],"ltp":2.02,"tv":10.33,"id":16569868},{"batb":[[0,4.9,52.38],[1,4.8,34.69],[2,4.5,16.84]],"ltp":5.0,"tv":9.08,"id":16569870}]}]}
{"op":"mcm","clk":"1008053900","pt":1580658080790,"mc":[{"id":"1.168224445","rc":[{"batb":[[0,3.3,17.7],[1,1.01,0.51],[2,3.3,0]],"ltp":0.0,"tv":0.0,"id":13117431},{"batb":[[0,1.65,26.36],[1,1.01,0.51],[2,1.65,0]],"ltp":2.02,"tv":10.33,"id":16569868},{"batb":[[0,4.5,16.84],[1,1.01,0.51],[2,4.5,0]],"ltp":5.0,"tv":9.08,"id":16569870}]}]}
{"op":"mcm","clk":"1008054593","pt":1580658083759,"mc":[{"id":"1.168224445","rc":[{"batb":[[0,3.35,66.45],[1,3.3,61.02],[2,1.01,0.51]],"ltp":0.0,"tv":0.0,"id":13117431},{"batb":[[0,1.67,88.72],[1,1.66,61.92],[2,1.65,26.36]],"ltp":2.02,"tv":10.33,"id":16569868},{"batb":[[0,4.5,78],[1,4.4,42.26],[2,1.01,0.51]],"ltp":5.0,"tv":9.08,"id":16569870}]}]}
{"op":"mcm","clk":"1008057594","pt":1580658097412,"mc":[{"id":"1.168224445","rc":[{"batb":[[0,3.3,17.7],[1,1.01,0.51],[2,1.01,0]],"ltp":0.0,"tv":0.0,"id":13117431},{"batb":[[0,4.5,16.84],[1,1.01,0.51],[2,1.01,0]],"ltp":5.0,"tv":9.08,"id":16569870}]}]}
{"op":"mcm","clk":"1008058335","pt":1580658100435,"mc":[{"id":"1.168224445","rc":[{"batb":[[0,4.1,26.92],[1,4,54.48],[2,3.3,17.7]],"ltp":0.0,"tv":0.0,"id":13117431},{"batb":[[0,5.4,43.31],[1,5.3,27.8],[2,4.5,16.84]],"ltp":5.0,"tv":9.08,"id":16569870}]}]}
{"op":"mcm","clk":"1008058525","pt":1580658101228,"mc":[{"id":"1.168224445","rc":[{"batb":[[2,3.95,23.53]],"batl":[[1,5.5,14.48]],"ltp":0.0,"tv":0.0,"id":13117431},{"batl":[[0,1.74,25.81],[1,1.88,20.22]],"ltp":2.02,"tv":10.33,"id":16569868},{"batb":[[0,5.4,54.64],[2,4.9,14.16]],"batl":[[1,7.8,13.93]],"ltp":5.0,"tv":9.08,"id":16569870}]}]}
{"op":"mcm","clk":"1008058771","pt":1580658102305,"mc":[{"id":"1.168224445","rc":[{"batl":[[0,4.5,34.03]],"ltp":0.0,"tv":0.0,"id":13117431},{"batb":[[1,1.66,124.93]],"batl":[[1,1.81,42.01],[2,1.88,20.22]],"ltp":2.02,"tv":10.33,"id":16569868},{"batb":[[2,5.1,10.08]],"batl":[[0,6.2,7.56],[1,6.4,10.86],[2,7.8,13.93]],"ltp":5.0,"tv":9.08,"id":16569870}]}]}
{"op":"mcm","clk":"1008061155","pt":1580658112397,"mc":[{"id":"1.168224445","rc":[{"batb":[[0,3.75,15.12],[1,3.6,14.48],[2,1.01,0.51]],"batl":[[0,4.5,11.76]],"ltp":0.0,"tv":0.0,"id":13117431},{"batb":[[0,1.66,63.01],[1,1.47,40.52],[2,1.01,0.51]],"batl":[[0,1.81,42.01],[1,1.88,20.22],[2,1.88,0]],"ltp":2.02,"tv":10.33,"id":16569868},{"batb":[[0,5.1,10.08],[1,4.9,14.16],[2,1.01,0.51]],"batl":[[1,7.8,13.93],[2,7.8,0]],"ltp":5.0,"tv":9.08,"id":16569870}]}]}
{"op":"mcm","clk":"1008061403","pt":1580658113434,"mc":[{"id":"1.168224445","rc":[{"batb":[[0,3.6,14.48],[1,1.01,0.51],[2,1.01,0]],"batl":[[0,5.5,14.48],[1,5.5,0]],"ltp":0.0,"tv":0.0,"id":13117431},{"batb":[[0,1.47,40.52],[1,1.01,0.51],[2,1.01,0]],"batl":[[0,1.88,20.22],[1,1.88,0]],"ltp":2.02,"tv":10.33,"id":16569868},{"batb":[[0,4.9,14.16],[1,1.01,0.51],[2,1.01,0]],"batl":[[0,7.8,13.93],[1,7.8,0]],"ltp":5.0,"tv":9.08,"id":16569870}]}]}
{"op":"mcm","clk":"1008061443","pt":1580658113598,"mc":[{"id":"1.168224445","rc":[{"batb":[[0,1.01,0.51],[1,1.01,0]],"ltp":0.0,"tv":0.0,"id":13117430}]}]}
{"op":"mcm","clk":"1008061983","pt":1580658115870,"mc":[{"id":"1.168224445","rc":[{"batb":[[0,1.48,40.13]],"ltp":2.02,"tv":10.33,"id":16569868},{"batb":[[0,4.9,14.01]],"ltp":5.0,"tv":9.08,"id":16569870}]}]}
{"op":"mcm","clk":"1008062312","pt":1580658117272,"mc":[{"id":"1.168224445","rc":[{"batb":[[0,4.2,49.3],[1,4.1,51.06],[2,3.6,14.48]],"ltp":0.0,"tv":0.0,"id":13117431},{"batb":[[0,1.63,99.77],[1,1.62,67.67],[2,1.48,40.13]],"ltp":2.02,"tv":10.33,"id":16569868},{"batb":[[0,5.6,39.56],[1,5.5,25.62],[2,4.9,14.01]],"ltp":5.0,"tv":9.08,"id":16569870}]}]}
{"op":"mcm","clk":"1008063182","pt":1580658120980,"mc":[{"id":"1.168224445","rc":[{"batb":[[0,3.6,14.48],[1,1.01,0.51],[2,3.6,0]],"ltp":0.0,"tv":0.0,"id":13117431},{"batb":[[0,1.48,40.13],[1,1.01,0.51],[2,1.48,0]],"ltp":2.02,"tv":10.33,"id":16569868},{"batb":[[0,4.9,14.01],[1,1.01,0.51],[2,4.9,0]],"ltp":5.0,"tv":9.08,"id":16569870}]}]}
{"op":"mcm","clk":"1008063848","pt":1580658123975,"mc":[{"id":"1.168224445","rc":[{"batb":[[0,3.7,45.38],[1,3.65,34.08],[2,3.6,14.48]],"ltp":0.0,"tv":0.0,"id":13117431},{"batb":[[0,1.49,131.9],[1,1.48,136.53],[2,1.01,0.51]],"ltp":2.02,"tv":10.33,"id":16569868},{"batb":[[0,4.9,64.46],[1,4.8,34.72],[2,1.01,0.51]],"ltp":5.0,"tv":9.08,"id":16569870}]}]}
{"op":"mcm","clk":"1008065723","pt":1580658131900,"mc":[{"id":"1.168224445","rc":[{"batb":[[0,3.6,14.48],[1,1.01,0.51],[2,3.6,0]],"ltp":0.0,"tv":0.0,"id":13117431},{"batb":[[0,4.9,14.01],[1,1.01,0.51],[2,1.01,0]],"ltp":5.0,"tv":9.08,"id":16569870}]}]}
{"op":"mcm","clk":"1008066506","pt":1580658135194,"mc":[{"id":"1.168224445","rc":[{"batb":[[0,4.9,42.53],[1,4.8,35.59],[2,4.7,15.11]],"batl":[[1,7.4,15.82]],"ltp":0.0,"tv":0.0,"id":13117431},{"batb":[[2,1.32,66.8]],"batl":[[0,1.55,39.1],[1,1.68,29.51]],"ltp":2.02,"tv":10.33,"id":16569868},{"batb":[[0,6.6,20.58],[1,6.4,51.64],[2,5.6,20.38]],"batl":[[1,10.5,7.95]],"ltp":5.0,"tv":9.08,"id":16569870}]}]}
{"op":"mcm","clk":"1008066727","pt":1580658136121,"mc":[{"id":"1.168224445","rc":[{"batl":[[0,5.3,9.24],[1,5.5,14.48],[2,7.4,15.82]],"ltp":0.0,"tv":0.0,"id":13117431},{"batb":[[0,1.5,84.02],[1,1.49,131.9],[2,1.48,136.53]],"batl":[[1,1.63,42.01],[2,1.68,29.51]],"ltp":2.02,"tv":10.33,"id":16569868},{"batb":[[2,5.9,8.4]],"batl":[[0,7.4,5.88],[1,7.8,13.93],[2,10.5,7.95]],"ltp":5.0,"tv":9.08,"id":16569870}]}]}
{"op":"mcm","clk":"1008068289","pt":1580658142809,"mc":[{"id":"1.168224445","rc":[{"batl":[[1,1.68,29.51],[2,1.68,0]],"ltp":2.02,"tv":10.33,"id":16569868}]}]}
{"op":"mcm","clk":"1008069060","pt":1580658146105,"mc":[{"id":"1.168224445","rc":[{"batl":[[1,1.62,42.01],[2,1.68,29.51]],"ltp":2.02,"tv":10.33,"id":16569868}]}]}
{"op":"mcm","clk":"1008069577","pt":1580658148312,"mc":[{"id":"1.168224445","rc":[{"batb":[[0,4.4,11.76],[1,4.1,20.54],[2,1.01,0.51]],"batl":[[1,7.4,15.82],[2,7.4,0]],"ltp":0.0,"tv":0.0,"id":13117431},{"batb":[[1,1.32,66.8],[2,1.01,0.51]],"batl":[[0,1.62,42.01],[1,1.68,29.51],[2,1.68,0]],"ltp":2.02,"tv":10.33,"id":16569868},{"batb":[[0,5.9,8.4],[1,5.6,20.38],[2,1.01,0.51]],"batl":[[1,10.5,7.95],[2,10.5,0]],"ltp":5.0,"tv":9.08,"id":16569870}]}]}
{"op":"mcm","clk":"1008069832","pt":1580658149391,"mc":[{"id":"1.168224445","rc":[{"batb":[[0,4.1,20.54],[1,1.01,0.51],[2,1.01,0]],"batl":[[0,7.4,15.82],[1,7.4,0]],"ltp":0.0,"tv":0.0,"id":13117431},{"batb":[[0,1.32,66.8],[1,1.01,0.51],[2,1.01,0]],"batl":[[0,1.68,29.51],[1,1.68,0]],"ltp":2.02,"tv":10.33,"id":16569868},{"batb":[[0,5.6,20.38],[1,1.01,0.51],[2,1.01,0]],"batl":[[0,10.5,7.95],[1,10.5,0]],"ltp":5.0,"tv":9.08,"id":16569870}]}]}
{"op":"mcm","clk":"1008070221","pt":1580658151022,"mc":[{"id":"1.168224445","rc":[{"batb":[[0,4.3,51.98],[1,4.2,48.22],[2,4.1,20.54]],"ltp":0.0,"tv":0.0,"id":13117431},{"batb":[[0,1.34,89.38],[1,1.33,156.55],[2,1.32,66.8]],"ltp":2.02,"tv":10.33,"id":16569868},{"batb":[[0,5.8,20.16],[1,5.7,23.92],[2,5.6,20.38]],"ltp":5.0,"tv":9.08,"id":16569870}]}]}
{"op":"mcm","clk":"1008071181","pt":1580658155028,"mc":[{"id":"1.168224445","rc":[{"batb":[[0,4.1,20.54],[1,1.01,0.51],[2,4.1,0]],"ltp":0.0,"tv":0.0,"id":13117431},{"batb":[[0,5.6,20.38],[1,1.01,0.51],[2,5.6,0]],"ltp":5.0,"tv":9.08,"id":16569870}]}]}
{"op":"mcm","clk":"1008071991","pt":1580658158345,"mc":[{"id":"1.168224445","rc":[{"trd":[[6.4,15.12]],"batb":[[0,6.4,14.76],[1,6.2,39.94],[2,6,16.84]],"batl":[[1,9.6,8.97]],"ltp":6.4,"tv":15.12,"id":13117431},{"batb":[[0,1.37,113.43],[1,1.34,89.38],[2,1.33,156.55]],"batl":[[0,1.38,64.44],[1,1.46,92.68],[2,1.68,29.51]],"ltp":2.02,"tv":10.33,"id":16569868},{"batb":[[0,8.6,16.1],[1,8.4,20.33],[2,8.2,8.34]],"batl":[[0,9.4,4.2],[1,10.5,7.95],[2,14.5,10.46]],"ltp":5.0,"tv":9.08,"id":16569870}],"tv":34.53}]}
{"op":"mcm","clk":"1008072172","pt":1580658159021,"mc":[{"id":"1.168224445","rc":[{"batb":[[0,6.2,39.94],[1,6,16.84],[2,5.4,11.17]],"ltp":6.4,"tv":15.12,"id":13117431},{"batb":[[0,1.34,89.38],[1,1.33,156.55],[2,1.32,66.8]],"batl":[[1,1.46,50.67],[2,1.68,0]],"ltp":2.02,"tv":10.33,"id":16569868}]}]}
{"op":"mcm","clk":"1008072768","pt":1580658161438,"mc":[{"id":"1.168224445","rc":[{"batb":[[0,6.2,55.77],[1,6,58.64]],"batl":[[0,6.6,6.72],[1,7.4,15.82],[2,9.6,8.97]],"ltp":6.4,"tv":15.12,"id":13117431},{"batb":[[0,1.36,115.95],[1,1.34,123.78],[2,1.33,156.55]],"batl":[[1,1.44,42.01],[2,1.46,50.67]],"ltp":2.02,"tv":10.33,"id":16569868}]}]}
{"op":"mcm","clk":"1008072991","pt":1580658162403,"mc":[{"id":"1.168224445","rc":[{"batb":[[2,5.6,8.4]],"ltp":6.4,"tv":15.12,"id":13117431}]}]}
{"op":"mcm","clk":"1008073967","pt":1580658166459,"mc":[{"id":"1.168224445","rc":[{"batb":[[0,6.2,39.94],[1,6,16.84]],"ltp":6.4,"tv":15.12,"id":13117431},{"batb":[[0,8.4,20.33],[1,8.2,8.34],[2,7.6,5.88]],"ltp":5.0,"tv":9.08,"id":16569870}]}]}
{"op":"mcm","clk":"1008074689","pt":1580658169399,"mc":[{"id":"1.168224445","rc":[{"batb":[[0,6.4,21.63],[1,6.2,39.94],[2,6,16.84]],"batl":[[0,7.4,15.82],[1,9.6,8.97],[2,9.6,0]],"ltp":6.4,"tv":15.12,"id":13117431},{"batb":[[0,1.33,156.55],[1,1.32,66.8],[2,1.22,104.57]],"ltp":2.02,"tv":10.33,"id":16569868},{"batb":[[0,8.4,32.16],[1,8.2,29.3]],"ltp":5.0,"tv":9.08,"id":16569870}]}]}
{"op":"mcm","clk":"1008074954","pt":1580658170443,"mc":[{"id":"1.168224445","rc":[{"batb":[[0,5.6,8.4],[1,5.4,11.17],[2,1.01,0.51]],"batl":[[0,9.6,8.97],[1,9.6,0]],"ltp":6.4,"tv":15.12,"id":13117431},{"batb":[[0,1.22,104.57],[1,1.01,0.51],[2,1.22,0]],"batl":[[0,1.44,42.01],[1,1.46,50.67],[2,1.46,0]],"ltp":2.02,"tv":10.33,"id":16569868},{"batb":[[0,7.6,5.88],[1,7.2,11.25],[2,1.01,0.51]],"batl":[[1,14.5,10.46],[2,14.5,0]],"ltp":5.0,"tv":9.08,"id":16569870}]}]}
{"op":"mcm","clk":"1008075147","pt":1580658171355,"mc":[{"id":"1.168224445","rc":[{"batb":[[0,5.4,11.17],[1,1.01,0.51],[2,1.01,0]],"ltp":6.4,"tv":15.12,"id":13117431},{"batl":[[0,1.46,50.67],[1,1.46,0]],"ltp":2.02,"tv":10.33,"id":16569868},{"batb":[[0,7.2,11.25],[1,1.01,0.51],[2,1.01,0]],"batl":[[0,14.5,10.46],[1,14.5,0]],"ltp":5.0,"tv":9.08,"id":16569870}]}]}
{"op":"mcm","clk":"1008075537","pt":1580658172832,"mc":[{"id":"1.168224445","rc":[{"batb":[[0,5.7,26.34],[1,5.6,25.64],[2,5.3,11.72]],"batl":[[0,9.4,9.36]],"ltp":6.4,"tv":15.12,"id":13117431},{"batb":[[0,1.24,182.34],[1,1.23,247.1],[2,1.22,102.76]],"batl":[[0,1.46,49.73]],"ltp":2.02,"tv":10.33,"id":16569868},{"batb":[[0,7.4,31.42],[1,7.2,38.85],[2,1.01,0.51]],"ltp":5.0,"tv":9.08,"id":16569870}]}]}
{"op":"mcm","clk":"1008075934","pt":1580658174437,"mc":[{"id":"1.168224445","rc":[{"batb":[[0,1.22,102.76],[1,1.01,0.51],[2,1.22,0]],"ltp":2.02,"tv":10.33,"id":16569868}]}]}
{"op":"mcm","clk":"1008076710","pt":1580658177342,"mc":[{"id":"1.168224445","rc":[{"batb":[[0,1.4,143.72],[1,1.39,127.27],[2,1.22,102.76]],"ltp":2.02,"tv":10.33,"id":16569868}]}]}
{"op":"mcm","clk":"1008076970","pt":1580658178425,"mc":[{"id":"1.168224445","rc":[{"batl":[[0,6.2,18.81],[1,9.2,10.15]],"ltp":6.4,"tv":15.12,"id":13117431},{"batb":[[0,1.41,101.66],[1,1.4,143.72],[2,1.39,178.57]],"batl":[[1,1.5,42.01],[2,1.59,35.49]],"ltp":2.02,"tv":10.33,"id":16569868},{"batb":[[2,6.8,6.72]],"batl":[[0,8.6,5.04],[1,9,10.54],[2,14,11.17]],"ltp":5.0,"tv":9.08,"id":16569870}]}]}
{"op":"mcm","clk":"1008079549","pt":1580658189373,"mc":[{"id":"1.168224445","rc":[{"batb":[[0,4.5,17.23],[1,1.01,0.51],[2,5.3,0]],"batl":[[0,9.2,10.15],[1,9.2,0]],"ltp":6.4,"tv":15.12,"id":13117431},{"batb":[[0,1.23,97.33],[1,1.01,0.51],[2,1.39,0]],"batl":[[0,1.59,35.49],[1,1.5,0],[2,1.59,0]],"ltp":2.02,"tv":10.33,"id":16569868},{"batb":[[0,6.2,16.29],[1,1.01,0.51],[2,6.8,0]],"batl":[[0,14,11.17],[1,9,0],[2,14,0]],"ltp":5.0,"tv":9.08,"id":16569870}]}]}
{"op":"mcm","clk":"1008079763","pt":1580658190369,"mc":[{"id":"1.168224445","rc":[{"batb":[[0,5.7,8.71],[1,4.5,17.23],[2,1.01,0.51]],"ltp":6.4,"tv":15.12,"id":13117431}]}]}
{"op":"mcm","clk":"1008079971","pt":1580658191158,"mc":[{"id":"1.168224445","rc":[{"batb":[[0,4.5,17.23],[1,1.01,0.51],[2,1.01,0]],"ltp":6.4,"tv":15.12,"id":13117431}]}]}
{"op":"mcm","clk":"1008080247","pt":1580658192342,"mc":[{"id":"1.168224445","rc":[{"batb":[[0,4.8,50.38],[1,4.7,37.79],[2,4.5,17.23]],"ltp":6.4,"tv":15.12,"id":13117431},{"batb":[[0,6.2,57.37],[1,6,41.11],[2,1.01,0.51]],"ltp":5.0,"tv":9.08,"id":16569870}]}]}
{"op":"mcm","clk":"1008080944","pt":1580658195378,"mc":[{"id":"1.168224445","rc":[{"batb":[[0,1.52,70.1],[1,1.51,88.74],[2,1.23,97.33]],"ltp":2.02,"tv":10.33,"id":16569868}]}]}
{"op":"mcm","clk":"1008081201","pt":1580658196399,"mc":[{"id":"1.168224445","rc":[{"batb":[[2,4.6,10.92]],"batl":[[0,5.2,16.44],[1,5.4,9.24],[2,8.8,10.94]],"ltp":6.4,"tv":15.12,"id":13117431},{"batb":[[0,1.52,106.45],[2,1.5,84.02]],"batl":[[1,1.6,42.01],[2,1.84,21.87]],"ltp":2.02,"tv":10.33,"id":16569868},{"batb":[[1,6,49.51],[2,5,12.98]],"batl":[[0,7.2,6.72],[1,7.4,15.26],[2,14,11.17]],"ltp":5.0,"tv":9.08,"id":16569870}]}]}
{"op":"mcm","clk":"1008081315","pt":1580658196796,"mc":[{"id":"1.168224445","rc":[{"batl":[[1,1.84,21.87],[2,1.84,0]],"ltp":2.02,"tv":10.33,"id":16569868}]}]}
{"op":"mcm","clk":"1008081688","pt":1580658198437,"mc":[{"id":"1.168224445","rc":[{"batl":[[1,1.61,42.01],[2,1.84,21.87]],"ltp":2.02,"tv":10.33,"id":16569868}]}]}
{"op":"mcm","clk":"1008083720","pt":1580658207202,"mc":[{"id":"1.168224445","rc":[{"batb":[[0,3.7,13.69],[1,1.01,0.51],[2,4.6,0]],"batl":[[0,8.8,10.94],[1,5.4,0],[2,8.8,0]],"ltp":6.4,"tv":15.12,"id":13117431},{"batb":[[0,1.24,93.4],[1,1.01,0.51],[2,1.5,0]],"batl":[[0,1.84,21.87],[1,1.61,0],[2,1.84,0]],"ltp":2.02,"tv":10.33,"id":16569868},{"batb":[[0,5,12.98],[1,1.01,0.51],[2,5,0]],"batl":[[0,14,11.17],[1,7.4,0],[2,14,0]],"ltp":5.0,"tv":9.08,"id":16569870}]}]}
{"op":"mcm","clk":"1008084497","pt":1580658210292,"mc":[{"id":"1.168224445","rc":[{"batl":[[0,1.83,21.95]],"ltp":2.02,"tv":10.33,"id":16569868}]}]}
{"op":"mcm","clk":"1008085209","pt":1580658213257,"mc":[{"id":"1.168224445","rc":[{"batb":[[0,5.2,48.67],[1,5.1,31.41],[2,3.7,13.69]],"ltp":6.4,"tv":15.12,"id":13117431},{"batb":[[0,1.45,156.64],[1,1.44,108.85],[2,1.24,93.4]],"ltp":2.02,"tv":10.33,"id":16569868},{"batb":[[0,6.8,30.51],[1,6.6,33.57],[2,5,12.98]],"ltp":5.0,"tv":9.08,"id":16569870}]}]}
{"op":"mcm","clk":"1008085539","pt":1580658214576,"mc":[{"id":"1.168224445","rc":[{"batb":[[0,3.7,13.69],[1,1.01,0.51],[2,3.7,0]],"ltp":6.4,"tv":15.12,"id":13117431},{"batb":[[0,1.24,93.4],[1,1.01,0.51],[2,1.24,0]],"ltp":2.02,"tv":10.33,"id":16569868},{"batb":[[0,5,12.98],[1,1.01,0.51],[2,5,0]],"ltp":5.0,"tv":9.08,"id":16569870}]}]}
{"op":"mcm","clk":"1008085939","pt":1580658216267,"mc":[{"id":"1.168224445","rc":[{"batb":[[0,4,14.28],[1,1.01,0.51]],"ltp":0.0,"tv":0.0,"id":13117430}]}]}
{"op":"mcm","clk":"1008086204","pt":1580658217382,"mc":[{"id":"1.168224445","rc":[{"batb":[[0,3.95,25.9],[1,3.9,29.68],[2,3.7,13.69]],"ltp":6.4,"tv":15.12,"id":13117431},{"batb":[[0,1.25,188.04],[1,1.24,328.75],[2,1.01,0.51]],"ltp":2.02,"tv":10.33,"id":16569868},{"batb":[[0,5,56.1],[1,4.9,33.01],[2,1.01,0.51]],"ltp":5.0,"tv":9.08,"id":16569870}]}]}
{"op":"mcm","clk":"1008086230","pt":1580658217490,"mc":[{"id":"1.168224445","rc":[{"batb":[[0,3.7,13.69],[1,1.01,0.51],[2,3.7,0]],"ltp":6.4,"tv":15.12,"id":13117431},{"batb":[[0,5,12.98],[1,1.01,0.51],[2,1.01,0]],"ltp":5.0,"tv":9.08,"id":16569870}]}]}
{"op":"mcm","clk":"1008086681","pt":1580658219390,"mc":[{"id":"1.168224445","rc":[{"batb":[[0,8,16.63],[1,7.8,24.82],[2,7.2,11.57]],"batl":[[1,10.5,8.18]],"ltp":6.4,"tv":15.12,"id":13117431},{"batb":[[2,1.2,114.4]],"batl":[[0,1.3,89.38],[1,1.39,62.16],[2,1.83,21.95]],"ltp":2.02,"tv":10.33,"id":16569868},{"batb":[[0,10.5,28.01],[1,10,45.63],[2,8.4,7.95]],"batl":[[1,16,8.81]],"ltp":5.0,"tv":9.08,"id":16569870}]}]}
{"op":"mcm","clk":"1008086877","pt":1580658220215,"mc":[{"id":"1.168224445","rc":[{"batl":[[0,8.6,5.04],[1,8.8,10.94],[2,10.5,8.18]],"ltp":6.4,"tv":15.12,"id":13117431},{"batb":[[0,1.26,161.32],[1,1.25,188.04],[2,1.24,328.75]],"batl":[[1,1.33,42.01],[2,1.39,62.16]],"ltp":2.02,"tv":10.33,"id":16569868},{"batb":[[2,9,5.04]],"batl":[[0,12,3.36],[1,14,11.17],[2,16,8.81]],"ltp":5.0,"tv":9.08,"id":16569870}]}]}
{"op":"mcm","clk":"1008093629","pt":1580658248028,"mc":[{"id":"1.168224445","rc":[{"batb":[[0,1.01,0.51],[1,1.01,0]],"ltp":0.0,"tv":0.0,"id":13117430}]}]}
{"op":"mcm","clk":"1008095549","pt":1580658256231,"mc":[{"id":"1.168224445","rc":[{"batb":[[0,7.2,11.57],[1,7,6.72],[2,5.8,18.88]],"ltp":6.4,"tv":15.12,"id":13117431},{"batb":[[1,1.24,93.4],[2,1.2,114.4]],"ltp":2.02,"tv":10.33,"id":16569868},{"batb":[[0,10,12.43],[1,9,5.04],[2,8.4,7.95]],"ltp":5.0,"tv":9.08,"id":16569870}]}]}
{"op":"mcm","clk":"1008096216","pt":1580658258837,"mc":[{"id":"1.168224445","rc":[{"batb":[[2,6.4,31.69]],"ltp":6.4,"tv":15.12,"id":13117431},{"batb":[[2,1.21,265.87]],"ltp":2.02,"tv":10.33,"id":16569868},{"batb":[[2,8.6,26.12]],"ltp":5.0,"tv":9.08,"id":16569870}]}]}
{"op":"mcm","clk":"1008099341","pt":1580658273263,"mc":[{"id":"1.168224445","rc":[{"batb":[[0,6.4,31.69],[1,6.2,40.34],[2,5.8,18.88]],"batl":[[0,10.5,8.18],[1,8.8,0],[2,10.5,0]],"ltp":6.4,"tv":15.12,"id":13117431},{"batb":[[0,1.21,265.87],[1,1.2,409.5],[2,1.01,0.51]],"batl":[[0,1.39,62.16],[1,1.33,0],[2,1.39,0]],"ltp":2.02,"tv":10.33,"id":16569868},{"batb":[[0,8.6,26.12],[1,8.4,27.9],[2,1.01,0.51]],"batl":[[0,16,8.81],[1,14,0],[2,16,0]],"ltp":5.0,"tv":9.08,"id":16569870}]}]}
{"op":"mcm","clk":"1008099994","pt":1580658276148,"mc":[{"id":"1.168224445","rc":[{"batb":[[2,5.9,18.25]],"batl":[[0,10.5,7.87]],"ltp":6.4,"tv":15.12,"id":13117431}]}]}
{"op":"mcm","clk":"1008101402","pt":1580658282345,"mc":[{"id":"1.168224445","rc":[{"batb":[[0,5.9,18.25],[1,1.01,0.51],[2,5.9,0]],"ltp":6.4,"tv":15.12,"id":13117431},{"batb":[[0,8.4,7.95],[1,1.01,0.51],[2,1.01,0]],"ltp":5.0,"tv":9.08,"id":16569870}]}]}
{"op":"mcm","clk":"1008102077","pt":1580658285370,"mc":[{"id":"1.168224445","rc":[{"batb":[[0,9,25.98],[1,8.8,19],[2,5.9,18.25]],"ltp":6.4,"tv":15.12,"id":13117431},{"batb":[[0,12,21.16],[1,11.5,24.98],[2,8.4,7.95]],"ltp":5.0,"tv":9.08,"id":16569870}]}]}
{"op":"mcm","clk":"1008102315","pt":1580658286342,"mc":[{"id":"1.168224445","rc":[{"batb":[[2,8.2,8.26]],"batl":[[0,9.8,4.2],[1,10.5,7.87],[2,12,15.03]],"ltp":6.4,"tv":15.12,"id":13117431},{"batb":[[0,1.23,168.04],[1,1.21,265.87],[2,1.2,409.5]],"batl":[[0,1.25,110],[1,1.28,42.01],[2,1.32,81.12]],"ltp":2.02,"tv":10.33,"id":16569868},{"batb":[[1,11.5,34.5],[2,10,4.2]],"batl":[[0,13.5,3.36],[1,16,8.81],[2,18,7.08]],"ltp":5.0,"tv":9.08,"id":16569870}]}]}
{"op":"mcm","clk":"1008104320","pt":1580658295371,"mc":[{"id":"1.168224445","rc":[{"batb":[[0,6.8,12.98],[1,1.01,0.51],[2,8.2,0]],"batl":[[0,12,15.03],[1,10.5,0],[2,12,0]],"ltp":6.4,"tv":15.12,"id":13117431},{"batb":[[0,1.17,136.67],[1,1.01,0.51],[2,1.2,0]],"batl":[[0,1.32,81.12],[1,1.28,0],[2,1.32,0]],"ltp":2.02,"tv":10.33,"id":16569868},{"batb":[[0,9.6,14.71],[1,1.01,0.51],[2,10,0]],"batl":[[0,18,7.08],[1,16,0],[2,18,0]],"ltp":5.0,"tv":9.08,"id":16569870}]}]}
{"op":"mcm","clk":"1008104928","pt":1580658298277,"mc":[{"id":"1.168224445","rc":[{"batb":[[0,7.4,36.34],[1,7.2,29.01],[2,6.8,12.98]],"ltp":6.4,"tv":15.12,"id":13117431},{"batb":[[0,1.18,399.85],[1,1.17,312.73],[2,1.01,0.51]],"ltp":2.02,"tv":10.33,"id":16569868},{"batb":[[0,10,25.64],[1,9.8,14.34],[2,9.6,14.71]],"ltp":5.0,"tv":9.08,"id":16569870}]}]}
{"op":"mcm","clk":"1008105126","pt":1580658299095,"mc":[{"id":"1.168224445","rc":[{"batb":[[0,6.8,12.98],[1,1.01,0.51],[2,6.8,0]],"ltp":6.4,"tv":15.12,"id":13117431},{"batb":[[0,9.6,14.71],[1,1.01,0.51],[2,9.6,0]],"ltp":5.0,"tv":9.08,"id":16569870}]}]}
{"op":"mcm","clk":"1008105908","pt":1580658302411,"mc":[{"id":"1.168224445","rc":[{"batb":[[0,10,28.36],[1,9.8,15.05],[2,6.8,12.98]],"ltp":6.4,"tv":15.12,"id":13117431},{"batb":[[0,13.5,12.96],[1,13,19.61],[2,9.6,14.71]],"ltp":5.0,"tv":9.08,"id":16569870}]}]}
{"op":"mcm","clk":"1008106042","pt":1580658302956,"mc":[{"id":"1.168224445","rc":[{"batb":[[2,9,16.6]],"batl":[[1,13,12.59]],"ltp":6.4,"tv":15.12,"id":13117431},{"batb":[[2,1.15,153.51]],"batl":[[0,1.22,128.72],[1,1.27,102.13]],"ltp":2.02,"tv":10.33,"id":16569868},{"batb":[[2,12.5,7.55]],"batl":[[1,19.5,6.06]],"ltp":5.0,"tv":9.08,"id":16569870}]}]}
{"op":"mcm","clk":"1008106386","pt":1580658304432,"mc":[{"id":"1.168224445","rc":[{"batl":[[0,10.5,4.2],[1,12,15.03],[2,13,12.59]],"ltp":6.4,"tv":15.12,"id":13117431},{"batb":[[0,1.2,168.04],[1,1.18,399.85],[2,1.17,312.73]],"batl":[[1,1.25,42.01],[2,1.27,102.13]],"ltp":2.02,"tv":10.33,"id":16569868}]}]}
{"op":"mcm","clk":"1008108902","pt":1580658315340,"mc":[{"id":"1.168224445","rc":[{"batb":[[0,7.8,9.28],[1,1.01,0.51],[2,9,0]],"batl":[[0,13,12.59],[1,12,0],[2,13,0]],"ltp":6.4,"tv":15.12,"id":13117431},{"batb":[[0,1.17,176.06],[1,1.15,153.51],[2,1.01,0.51]],"batl":[[0,1.27,102.13],[1,1.25,0],[2,1.27,0]],"ltp":2.02,"tv":10.33,"id":16569868},{"batb":[[0,11,10.62],[1,1.01,0.51],[2,12.5,0]],"batl":[[0,19.5,6.06],[1,19.5,0]],"ltp":5.0,"tv":9.08,"id":16569870}]}]}
{"op":"mcm","clk":"1008109471","pt":1580658318106,"mc":[{"id":"1.168224445","rc":[{"batb":[[0,8.8,17.03],[1,8.6,20.14],[2,7.8,9.28]],"ltp":6.4,"tv":15.12,"id":13117431},{"batb":[[1,1.16,379.62],[2,1.15,153.51]],"ltp":2.02,"tv":10.33,"id":16569868},{"batb":[[0,11.5,33.54],[1,11,37.16],[2,1.01,0.51]],"ltp":5.0,"tv":9.08,"id":16569870}]}]}
{"op":"mcm","clk":"1008109649","pt":1580658318875,"mc":[{"id":"1.168224445","rc":[{"batb":[[0,7.8,9.28],[1,1.01,0.51],[2,7.8,0]],"ltp":6.4,"tv":15.12,"id":13117431},{"batb":[[0,11,10.62],[1,1.01,0.51],[2,1.01,0]],"ltp":5.0,"tv":9.08,"id":16569870}]}]}
{"op":"mcm","clk":"1008110355","pt":1580658322167,"mc":[{"id":"1.168224445","rc":[{"batb":[[0,11,16.08],[1,10.5,32.09],[2,9,5.04]],"batl":[[0,11.5,3.36],[1,13,12.59]],"ltp":6.4,"tv":15.12,"id":13117431},{"batb":[[0,1.18,168.04],[1,1.17,176.06],[2,1.16,379.62]],"batl":[[0,1.23,42.01],[1,1.27,102.13]],"ltp":2.02,"tv":10.33,"id":16569868},{"batb":[[0,14.5,12.06],[1,14,16.84],[2,12,3.36]],"ltp":5.0,"tv":9.08,"id":16569870}]}]}
{"op":"mcm","clk":"1008110575","pt":1580658323059,"mc":[{"id":"1.168224445","rc":[{"batb":[[2,9.8,13.77]],"batl":[[2,14,10.86]],"ltp":6.4,"tv":15.12,"id":13117431},{"batl":[[0,1.2,143.75],[1,1.23,165.93]],"ltp":2.02,"tv":10.33,"id":16569868},{"batb":[[2,13.5,6.45]],"batl":[[1,21,5.35]],"ltp":5.0,"tv":9.08,"id":16569870}]}]}
{"op":"mcm","clk":"1008113507","pt":1580658336394,"mc":[{"id":"1.168224445","rc":[{"batb":[[0,9.8,13.77],[1,9.2,5.04],[2,8.8,7.16]],"ltp":6.4,"tv":15.12,"id":13117431},{"batb":[[1,1.16,244.85],[2,1.15,153.51]],"ltp":2.02,"tv":10.33,"id":16569868},{"batb":[[0,13.5,6.45],[1,12.5,7.95],[2,12,3.36]],"ltp":5.0,"tv":9.08,"id":16569870}]}]}
{"op":"mcm","clk":"1008113660","pt":1580658337264,"mc":[{"id":"1.168224445","rc":[{"batb":[[0,8.8,7.16],[1,1.01,0.51],[2,8.8,0]],"batl":[[0,14,10.86],[1,13,0],[2,14,0]],"ltp":6.4,"tv":15.12,"id":13117431},{"batb":[[0,1.16,244.85],[1,1.14,167.99],[2,1.01,0.51]],"batl":[[0,1.23,123.92],[1,1.23,0]],"ltp":2.02,"tv":10.33,"id":16569868},{"batb":[[0,12.5,7.95],[1,1.01,0.51],[2,12,0]],"batl":[[0,21,5.35],[1,21,0]],"ltp":5.0,"tv":9.08,"id":16569870}]}]}
{"op":"mcm","clk":"1008114057","pt":1580658339380,"mc":[{"id":"1.168224445","rc":[{"batb":[[0,10,19.09],[1,9.8,15.22],[2,8.8,7.16]],"ltp":6.4,"tv":15.12,"id":13117431},{"batb":[[1,1.15,342.42],[2,1.14,167.99]],"ltp":2.02,"tv":10.33,"id":16569868},{"batb":[[0,13.5,13.41],[1,13,19.6],[2,12.5,7.95]],"ltp":5.0,"tv":9.08,"id":16569870}]}]}
{"op":"mcm","clk":"1008115392","pt":1580658345969,"mc":[{"id":"1.168224445","rc":[{"batb":[[0,8.8,7.16],[1,1.01,0.51],[2,8.8,0]],"ltp":6.4,"tv":15.12,"id":13117431},{"batb":[[0,12.5,7.95],[1,1.01,0.51],[2,12.5,0]],"ltp":5.0,"tv":9.08,"id":16569870}]}]}
{"op":"mcm","clk":"1008116059","pt":1580658349391,"mc":[{"id":"1.168224445","rc":[{"batb":[[0,11.5,18.54],[1,11,29.03],[2,10.5,11.8]],"batl":[[1,17.5,7.47]],"ltp":6.4,"tv":15.12,"id":13117431},{"batb":[[0,15,13.44],[1,1.01,0.51]],"ltp":0.0,"tv":0.0,"id":13117430},{"batl":[[0,1.19,147.69],[1,1.21,138.32],[2,1.23,123.92]],"ltp":2.02,"tv":10.33,"id":16569868},{"batb":[[0,15,13.28],[1,14.5,21.36],[2,13,7]],"batl":[[1,26,7.32]],"ltp":5.0,"tv":9.08,"id":16569870}]}]}
{"op":"mcm","clk":"1008116215","pt":1580658350194,"mc":[{"id":"1.168224445","rc":[{"batl":[[0,12.5,3.36],[1,14,10.86],[2,17.5,7.47]],"ltp":6.4,"tv":15.12,"id":13117431},{"batb":[[0,1.17,168.04],[1,1.16,244.85],[2,1.15,342.42]],"batl":[[1,1.21,180.33],[2,1.23,0]],"ltp":2.02,"tv":10.33,"id":16569868}]}]}
{"op":"mcm","clk":"1008119940","pt":1580658367910,"mc":[{"id":"1.168224445","rc":[{"batb":[[0,9.8,4.2],[1,9.6,14.48],[2,1.01,0.51]],"batl":[[1,17.5,7.47],[2,17.5,0]],"ltp":6.4,"tv":15.12,"id":13117431},{"batb":[[1,1.11,213.94],[2,1.01,0.51]],"batl":[[0,1.21,180.33],[1,1.21,0]],"ltp":2.02,"tv":10.33,"id":16569868},{"batb":[[0,13,7],[1,12.5,3.36],[2,1.01,0.51]],"batl":[[0,26,7.32],[1,26,0]],"ltp":5.0,"tv":9.08,"id":16569870}]}]}
{"op":"mcm","clk":"1008120252","pt":1580658369414,"mc":[{"id":"1.168224445","rc":[{"batb":[[0,9.6,14.48],[1,1.01,0.51],[2,1.01,0]],"batl":[[0,17.5,7.47],[1,17.5,0]],"ltp":6.4,"tv":15.12,"id":13117431},{"batb":[[0,1.11,213.94],[1,1.01,0.51],[2,1.01,0]],"batl":[[0,1.21,138.32]],"ltp":2.02,"tv":10.33,"id":16569868},{"batb":[[1,1.01,0.51],[2,1.01,0]],"ltp":5.0,"tv":9.08,"id":16569870}]}]}
{"op":"mcm","clk":"1008120460","pt":1580658370394,"mc":[{"id":"1.168224445","rc":[{"batb":[[0,10.5,10.52],[1,10,35.81],[2,9.6,14.48]],"ltp":6.4,"tv":15.12,"id":13117431},{"batb":[[0,1.13,160.03],[1,1.12,443.74],[2,1.11,213.94]],"ltp":2.02,"tv":10.33,"id":16569868},{"batb":[[0,13.5,16.32],[1,13,26.49],[2,1.01,0.51]],"ltp":5.0,"tv":9.08,"id":16569870}]}]}
{"op":"mcm","clk":"1008120653","pt":1580658371305,"mc":[{"id":"1.168224445","rc":[{"batb":[[0,9.6,14.48],[1,1.01,0.51],[2,9.6,0]],"ltp":6.4,"tv":15.12,"id":13117431},{"batb":[[0,1.11,213.94],[1,1.01,0.51],[2,1.11,0]],"ltp":2.02,"tv":10.33,"id":16569868},{"batb":[[0,13,7],[1,1.01,0.51],[2,1.01,0]],"ltp":5.0,"tv":9.08,"id":16569870}]}]}
{"op":"mcm","clk":"1008121172","pt":1580658373429,"mc":[{"id":"1.168224445","rc":[{"batb":[[0,12,14.35],[1,11.5,26.64],[2,9.6,14.48]],"ltp":6.4,"tv":15.12,"id":13117431},{"batb":[[0,1.15,388.1],[1,1.14,203.07],[2,1.11,213.94]],"ltp":2.02,"tv":10.33,"id":16569868},{"batb":[[0,15.5,13.67],[1,15,14.55],[2,13,7]],"ltp":5.0,"tv":9.08,"id":16569870}]}]}
{"op":"mcm","clk":"1008121495","pt":1580658375107,"mc":[{"id":"1.168224445","rc":[{"batb":[[0,9.6,14.48],[1,1.01,0.51],[2,9.6,0]],"ltp":6.4,"tv":15.12,"id":13117431},{"batb":[[0,1.11,213.94],[1,1.01,0.51],[2,1.11,0]],"ltp":2.02,"tv":10.33,"id":16569868},{"batb":[[0,13,7],[1,1.01,0.51],[2,13,0]],"ltp":5.0,"tv":9.08,"id":16569870}]}]}
{"op":"mcm","clk":"1008122762","pt":1580658381112,"mc":[{"id":"1.168224445","rc":[{"batb":[[0,10.5,10.52],[1,10,35.81],[2,9.6,14.48]],"ltp":6.4,"tv":15.12,"id":13117431},{"batb":[[0,1.18,272.7],[1,1.17,304.3],[2,1.11,213.94]],"ltp":2.02,"tv":10.33,"id":16569868},{"batb":[[0,13.5,16.32],[1,13,26.49],[2,1.01,0.51]],"ltp":5.0,"tv":9.08,"id":16569870}]}]}
{"op":"mcm","clk":"1008122957","pt":1580658382132,"mc":[{"id":"1.168224445","rc":[{"batl":[[0,11.5,3.36],[1,13,13.14],[2,15,10.07]],"ltp":6.4,"tv":15.12,"id":13117431},{"batb":[[0,1.19,168.04],[1,1.18,272.7],[2,1.17,304.3]],"batl":[[1,1.23,124.71]],"ltp":2.02,"tv":10.33,"id":16569868},{"batb":[[2,12.5,8.03]],"batl":[[0,18.5,6.53],[1,22,5.04]],"ltp":5.0,"tv":9.08,"id":16569870}]}]}
{"op":"mcm","clk":"1008126128","pt":1580658397934,"mc":[{"id":"1.168224445","rc":[{"batb":[[0,9.2,5.04],[1,9,6.92],[2,1.01,0.51]],"batl":[[1,15,10.07],[2,15,0]],"ltp":6.4,"tv":15.12,"id":13117431},{"batb":[[1,1.13,176.09],[2,1.01,0.51]],"batl":[[0,1.23,124.71],[1,1.23,0]],"ltp":2.02,"tv":10.33,"id":16569868},{"batb":[[0,12.5,8.03],[1,11.5,3.36],[2,1.01,0.51]],"batl":[[0,22,5.04],[1,22,0]],"ltp":5.0,"tv":9.08,"id":16569870}]}]}
{"op":"mcm","clk":"1008126390","pt":1580658399156,"mc":[{"id":"1.168224445","rc":[{"batb":[[0,9,6.92],[1,1.01,0.51],[2,1.01,0]],"batl":[[0,15,10.07],[1,15,0]],"ltp":6.4,"tv":15.12,"id":13117431},{"batb":[[0,1.13,176.09],[1,1.01,0.51],[2,1.01,0]],"ltp":2.02,"tv":10.33,"id":16569868},{"batb":[[1,1.01,0.51],[2,1.01,0]],"ltp":5.0,"tv":9.08,"id":16569870}]}]}
{"op":"mcm","clk":"1008126777","pt":1580658401145,"mc":[{"id":"1.168224445","rc":[{"batb":[[0,9.6,19.48],[1,9.4,16.64],[2,9,6.92]],"ltp":6.4,"tv":15.12,"id":13117431},{"batb":[[0,1.15,393.93],[1,1.14,197.2],[2,1.13,176.09]],"ltp":2.02,"tv":10.33,"id":16569868},{"batb":[[0,12.5,27.43],[1,12,22.91],[2,1.01,0.51]],"ltp":5.0,"tv":9.08,"id":16569870}]}]}
{"op":"mcm","clk":"1008126830","pt":1580658401948,"mc":[{"id":"1.168224445","rc":[{"batb":[[0,9,6.92],[1,1.01,0.51],[2,9,0]],"ltp":6.4,"tv":15.12,"id":13117431},{"batb":[[0,1.13,176.09],[1,1.01,0.51],[2,1.13,0]],"ltp":2.02,"tv":10.33,"id":16569868},{"batb":[[0,12.5,8.03],[1,1.01,0.51],[2,1.01,0]],"ltp":5.0,"tv":9.08,"id":16569870}]}]}
{"op":"mcm","clk":"1008127475","pt":1580658404348,"mc":[{"id":"1.168224445","rc":[{"batb":[[0,9.6,19.48],[1,9.4,16.64],[2,9,6.92]],"ltp":6.4,"tv":15.12,"id":13117431},{"batb":[[0,1.2,193.89],[1,1.19,311.11],[2,1.13,176.09]],"ltp":2.02,"tv":10.33,"id":16569868},{"batb":[[0,12.5,27.43],[1,12,22.91],[2,1.01,0.51]],"ltp":5.0,"tv":9.08,"id":16569870}]}]}
{"op":"mcm","clk":"1008127724","pt":1580658405428,"mc":[{"id":"1.168224445","rc":[{"batl":[[0,12,15.66],[1,13,12.98]],"ltp":6.4,"tv":15.12,"id":13117431},{"batb":[[2,1.18,132.26]],"batl":[[1,1.24,116.84]],"ltp":2.02,"tv":10.33,"id":16569868},{"batb":[[1,12,31.8]],"batl":[[0,17.5,7.47],[1,19,6.22]],"ltp":5.0,"tv":9.08,"id":16569870}]}]}
{"op":"mcm","clk":"1008127852","pt":1580658406165,"mc":[{"id":"1.168224445","rc":[{"batl":[[0,11,4.2],[1,12,15.66],[2,13,12.98]],"ltp":6.4,"tv":15.12,"id":13117431},{"batb":[[0,1.2,361.93]],"batl":[[2,1.25,42.01]],"ltp":2.02,"tv":10.33,"id":16569868},{"batb":[[2,10.5,4.2]],"ltp":5.0,"tv":9.08,"id":16569870}]}]}
{"op":"mcm","clk":"1008128623","pt":1580658410174,"mc":[{"id":"1.168224445","rc":[{"batb":[[0,1.01,0.51],[1,1.01,0]],"ltp":0.0,"tv":0.0,"id":13117430}]}]}
{"op":"mcm","clk":"1008130146","pt":1580658418091,"mc":[{"id":"1.168224445","rc":[{"batb":[[0,8.8,5.04],[1,8.6,7.47],[2,1.01,0.51]],"batl":[[1,13,12.98],[2,13,0]],"ltp":6.4,"tv":15.12,"id":13117431},{"batb":[[0,1.2,168.04],[1,1.16,150.28],[2,1.01,0.51]],"batl":[[0,1.24,116.84],[1,1.25,42.01],[2,1.25,0]],"ltp":2.02,"tv":10.33,"id":16569868},{"batb":[[0,12,27.03],[1,10.5,4.2],[2,1.01,0.51]],"batl":[[0,19,6.22],[1,19,0]],"ltp":5.0,"tv":9.08,"id":16569870}]}]}
{"op":"mcm","clk":"1008130371","pt":1580658419170,"mc":[{"id":"1.168224445","rc":[{"batb":[[0,8.6,7.47],[1,1.01,0.51],[2,1.01,0]],"batl":[[0,13,12.98],[1,13,0]],"ltp":6.4,"tv":15.12,"id":13117431},{"batb":[[0,1.16,150.28],[1,1.01,0.51],[2,1.01,0]],"batl":[[1,1.25,0]],"ltp":2.02,"tv":10.33,"id":16569868},{"batb":[[1,1.01,0.51],[2,1.01,0]],"ltp":5.0,"tv":9.08,"id":16569870}]}]}
{"op":"mcm","clk":"1008130732","pt":1580658420993,"mc":[{"id":"1.168224445","rc":[{"batb":[[0,1.18,207.11],[1,1.16,150.28],[2,1.01,0.51]],"ltp":2.02,"tv":10.33,"id":16569868}]}]}
{"op":"mcm","clk":"1008131052","pt":1580658422374,"mc":[{"id":"1.168224445","rc":[{"batb":[[0,9.8,15.46],[1,9.6,15.95],[2,8.6,7.47]],"ltp":6.4,"tv":15.12,"id":13117431},{"batb":[[0,1.19,389.28],[1,1.18,207.11],[2,1.16,150.28]],"ltp":2.02,"tv":10.33,"id":16569868},{"batb":[[0,12.5,27.78],[1,12,31.49],[2,1.01,0.51]],"ltp":5.0,"tv":9.08,"id":16569870}]}]}
{"op":"mcm","clk":"1008131826","pt":1580658425898,"mc":[{"id":"1.168224445","rc":[{"batb":[[0,8.6,7.47],[1,1.01,0.51],[2,8.6,0]],"ltp":6.4,"tv":15.12,"id":13117431},{"batb":[[0,1.18,207.11],[1,1.16,150.28],[2,1.01,0.51]],"ltp":2.02,"tv":10.33,"id":16569868},{"batb":[[0,12,27.13],[1,1.01,0.51],[2,1.01,0]],"ltp":5.0,"tv":9.08,"id":16569870}]}]}
