{"op":"mcm","clk":"1002113593","pt":1580590610212,"mc":[{"id":"1.168236371","marketDefinition":{"bspMarket":false,"turnInPlayEnabled":true,"persistenceEnabled":true,"marketBaseRate":5.0,"eventId":"29681838","eventTypeId":"2","numberOfWinners":1,"bettingType":"ODDS","marketType":"SET_WINNER","marketTime":"2020-02-02T16:00:00.000Z","suspendTime":"2020-02-02T16:00:00.000Z","bspReconciled":false,"complete":true,"inPlay":false,"crossMatching":false,"runnersVoidable":false,"numberOfActiveRunners":2,"betDelay":0,"status":"OPEN","runners":[{"status":"ACTIVE","sortPriority":1,"id":4520808,"name":"Facundo Bagnis"},{"status":"ACTIVE","sortPriority":2,"id":8284479,"name":"Federico Gaio"}],"regulators":["MR_INT"],"countryCode":"AR","discountAllowed":false,"timezone":"UTC","openDate":"2020-02-02T16:00:00.000Z","version":3147446739,"name":"Set 2 Winner","eventName":"Bagnis v Gaio"},"rc":[{"batb":[[0,1.01,20]],"ltp":0.0,"tv":0.0,"id":4520808},{"batb":[[0,1.01,20]],"ltp":0.0,"tv":0.0,"id":8284479}]}]}
{"op":"mcm","clk":"1002113713","pt":1580590611242,"mc":[{"id":"1.168236371","marketDefinition":{"bspMarket":false,"turnInPlayEnabled":true,"persistenceEnabled":true,"marketBaseRate":5.0,"eventId":"29681838","eventTypeId":"2","numberOfWinners":1,"bettingType":"ODDS","marketType":"SET_WINNER","marketTime":"2020-02-02T16:00:00.000Z","suspendTime":"2020-02-02T16:00:00.000Z","bspReconciled":false,"complete":true,"inPlay":false,"crossMatching":false,"runnersVoidable":false,"numberOfActiveRunners":2,"betDelay":0,"status":"OPEN","runners":[{"status":"ACTIVE","sortPriority":1,"id":4520808,"name":"Facundo Bagnis"},{"status":"ACTIVE","sortPriority":2,"id":8284479,"name":"Federico Gaio"}],"regulators":["MR_INT"],"countryCode":"AR","discountAllowed":false,"timezone":"UTC","openDate":"2020-02-02T16:00:00.000Z","version":3147446739,"name":"Set 2 Winner","eventName":"Bagnis v Gaio"}}]}
{"op":"mcm","clk":"1002113926","pt":1580590613250,"mc":[{"id":"1.168236371","marketDefinition":{"bspMarket":false,"turnInPlayEnabled":true,"persistenceEnabled":true,"marketBaseRate":5.0,"eventId":"29681838","eventTypeId":"2","numberOfWinners":1,"bettingType":"ODDS","marketType":"SET_WINNER","marketTime":"2020-02-02T16:00:00.000Z","suspendTime":"2020-02-02T16:00:00.000Z","bspReconciled":false,"complete":true,"inPlay":false,"crossMatching":false,"runnersVoidable":false,"numberOfActiveRunners":2,"betDelay":0,"status":"OPEN","runners":[{"status":"ACTIVE","sortPriority":1,"id":4520808,"name":"Facundo Bagnis"},{"status":"ACTIVE","sortPriority":2,"id":8284479,"name":"Federico Gaio"}],"regulators":["MR_INT"],"countryCode":"AR","discountAllowed":true,"timezone":"UTC","openDate":"2020-02-02T16:00:00.000Z","version":3147446739,"name":"Set 2 Winner","eventName":"Bagnis v Gaio"}}]}
{"op":"mcm","clk":"1002136314","pt":1580590825589,"mc":[{"id":"1.168236371","rc":[{"batb":[[0,1.01,10]],"ltp":0.0,"tv":0.0,"id":4520808},{"batb":[[0,1.01,10]],"ltp":0.0,"tv":0.0,"id":8284479}]}]}
{"op":"mcm","clk":"1003084143","pt":1580602759997,"mc":[{"id":"1.168236371","rc":[{"batb":[[0,1.01,10.51]],"ltp":0.0,"tv":0.0,"id":4520808},{"batb":[[0,1.01,10.51]],"ltp":0.0,"tv":0.0,"id":8284479}]}]}
{"op":"mcm","clk":"1003143057","pt":1580603524150,"mc":[{"id":"1.168236371","rc":[{"batb":[[0,1.01,11.01]],"ltp":0.0,"tv":0.0,"id":4520808},{"batb":[[0,1.01,11.01]],"ltp":0.0,"tv":0.0,"id":8284479}]}]}
{"op":"mcm","clk":"1008280601","pt":1580659302802,"mc":[{"id":"1.168236371","marketDefinition":{"bspMarket":false,"turnInPlayEnabled":true,"persistenceEnabled":true,"marketBaseRate":5.0,"eventId":"29681838","eventTypeId":"2","numberOfWinners":1,"bettingType":"ODDS","marketType":"SET_WINNER","marketTime":"2020-02-02T16:15:00.000Z","suspendTime":"2020-02-02T16:15:00.000Z","bspReconciled":false,"complete":true,"inPlay":false,"crossMatching":false,"runnersVoidable":false,"numberOfActiveRunners":2,"betDelay":0,"status":"OPEN","runners":[{"status":"ACTIVE","sortPriority":1,"id":4520808,"name":"Facundo Bagnis"},{"status":"ACTIVE","sortPriority":2,"id":8284479,"name":"Federico Gaio"}],"regulators":["MR_INT"],"countryCode":"AR","discountAllowed":true,"timezone":"UTC","openDate":"2020-02-02T16:00:00.000Z","version":3149673263,"name":"Set 2 Winner","eventName":"Bagnis v Gaio"}}]}
{"op":"mcm","clk":"1008281157","pt":1580659305787,"mc":[{"id":"1.168236371","marketDefinition":{"bspMarket":false,"turnInPlayEnabled":true,"persistenceEnabled":true,"marketBaseRate":5.0,"eventId":"29681838","eventTypeId":"2","numberOfWinners":1,"bettingType":"ODDS","marketType":"SET_WINNER","marketTime":"2020-02-02T16:15:00.000Z","suspendTime":"2020-02-02T16:15:00.000Z","bspReconciled":false,"complete":true,"inPlay":false,"crossMatching":false,"runnersVoidable":false,"numberOfActiveRunners":2,"betDelay":0,"status":"OPEN","runners":[{"status":"ACTIVE","sortPriority":1,"id":4520808,"name":"Facundo Bagnis"},{"status":"ACTIVE","sortPriority":2,"id":8284479,"name":"Federico Gaio"}],"regulators":["MR_INT"],"countryCode":"AR","discountAllowed":true,"timezone":"UTC","openDate":"2020-02-02T16:15:00.000Z","version":3149673263,"name":"Set 2 Winner","eventName":"Bagnis v Gaio"}}]}
{"op":"mcm","clk":"1008474745","pt":1580660203653,"mc":[{"id":"1.168236371","marketDefinition":{"bspMarket":false,"turnInPlayEnabled":true,"persistenceEnabled":true,"marketBaseRate":5.0,"eventId":"29681838","eventTypeId":"2","numberOfWinners":1,"bettingType":"ODDS","marketType":"SET_WINNER","marketTime":"2020-02-02T16:30:00.000Z","suspendTime":"2020-02-02T16:30:00.000Z","bspReconciled":false,"complete":true,"inPlay":false,"crossMatching":false,"runnersVoidable":false,"numberOfActiveRunners":2,"betDelay":0,"status":"OPEN","runners":[{"status":"ACTIVE","sortPriority":1,"id":4520808,"name":"Facundo Bagnis"},{"status":"ACTIVE","sortPriority":2,"id":8284479,"name":"Federico Gaio"}],"regulators":["MR_INT"],"countryCode":"AR","discountAllowed":true,"timezone":"UTC","openDate":"2020-02-02T16:15:00.000Z","version":3149737480,"name":"Set 2 Winner","eventName":"Bagnis v Gaio"}}]}
{"op":"mcm","clk":"1008475458","pt":1580660206679,"mc":[{"id":"1.168236371","marketDefinition":{"bspMarket":false,"turnInPlayEnabled":true,"persistenceEnabled":true,"marketBaseRate":5.0,"eventId":"29681838","eventTypeId":"2","numberOfWinners":1,"bettingType":"ODDS","marketType":"SET_WINNER","marketTime":"2020-02-02T16:30:00.000Z","suspendTime":"2020-02-02T16:30:00.000Z","bspReconciled":false,"complete":true,"inPlay":false,"crossMatching":false,"runnersVoidable":false,"numberOfActiveRunners":2,"betDelay":0,"status":"OPEN","runners":[{"status":"ACTIVE","sortPriority":1,"id":4520808,"name":"Facundo Bagnis"},{"status":"ACTIVE","sortPriority":2,"id":8284479,"name":"Federico Gaio"}],"regulators":["MR_INT"],"countryCode":"AR","discountAllowed":true,"timezone":"UTC","openDate":"2020-02-02T16:30:00.000Z","version":3149737480,"name":"Set 2 Winner","eventName":"Bagnis v Gaio"}}]}
{"op":"mcm","clk":"1008675211","pt":1580661104119,"mc":[{"id":"1.168236371","marketDefinition":{"bspMarket":false,"turnInPlayEnabled":true,"persistenceEnabled":true,"marketBaseRate":5.0,"eventId":"29681838","eventTypeId":"2","numberOfWinners":1,"bettingType":"ODDS","marketType":"SET_WINNER","marketTime":"2020-02-02T16:45:00.000Z","suspendTime":"2020-02-02T16:45:00.000Z","bspReconciled":false,"complete":true,"inPlay":false,"crossMatching":false,"runnersVoidable":false,"numberOfActiveRunners":2,"betDelay":0,"status":"OPEN","runners":[{"status":"ACTIVE","sortPriority":1,"id":4520808,"name":"Facundo Bagnis"},{"status":"ACTIVE","sortPriority":2,"id":8284479,"name":"Federico Gaio"}],"regulators":["MR_INT"],"countryCode":"AR","discountAllowed":true,"timezone":"UTC","openDate":"2020-02-02T16:30:00.000Z","version":3149796843,"name":"Set 2 Winner","eventName":"Bagnis v Gaio"}}]}
{"op":"mcm","clk":"1008675568","pt":1580661105685,"mc":[{"id":"1.168236371","marketDefinition":{"bspMarket":false,"turnInPlayEnabled":true,"persistenceEnabled":true,"marketBaseRate":5.0,"eventId":"29681838","eventTypeId":"2","numberOfWinners":1,"bettingType":"ODDS","marketType":"SET_WINNER","marketTime":"2020-02-02T16:45:00.000Z","suspendTime":"2020-02-02T16:45:00.000Z","bspReconciled":false,"complete":true,"inPlay":false,"crossMatching":false,"runnersVoidable":false,"numberOfActiveRunners":2,"betDelay":0,"status":"OPEN","runners":[{"status":"ACTIVE","sortPriority":1,"id":4520808,"name":"Facundo Bagnis"},{"status":"ACTIVE","sortPriority":2,"id":8284479,"name":"Federico Gaio"}],"regulators":["MR_INT"],"countryCode":"AR","discountAllowed":true,"timezone":"UTC","openDate":"2020-02-02T16:45:00.000Z","version":3149796843,"name":"Set 2 Winner","eventName":"Bagnis v Gaio"}}]}
{"op":"mcm","clk":"1008739976","pt":1580661402947,"mc":[{"id":"1.168236371","marketDefinition":{"bspMarket":false,"turnInPlayEnabled":true,"persistenceEnabled":true,"marketBaseRate":5.0,"eventId":"29681838","eventTypeId":"2","numberOfWinners":1,"bettingType":"ODDS","marketType":"SET_WINNER","marketTime":"2020-02-02T16:35:00.000Z","suspendTime":"2020-02-02T16:35:00.000Z","bspReconciled":false,"complete":true,"inPlay":false,"crossMatching":false,"runnersVoidable":false,"numberOfActiveRunners":2,"betDelay":0,"status":"OPEN","runners":[{"status":"ACTIVE","sortPriority":1,"id":4520808,"name":"Facundo Bagnis"},{"status":"ACTIVE","sortPriority":2,"id":8284479,"name":"Federico Gaio"}],"regulators":["MR_INT"],"countryCode":"AR","discountAllowed":true,"timezone":"UTC","openDate":"2020-02-02T16:45:00.000Z","version":3149819976,"name":"Set 2 Winner","eventName":"Bagnis v Gaio"}}]}
{"op":"mcm","clk":"1008740299","pt":1580661404236,"mc":[{"id":"1.168236371","rc":[{"batb":[[0,1.82,19.04],[1,1.01,11.01]],"ltp":0.0,"tv":0.0,"id":4520808},{"batb":[[0,2.06,25.34],[1,1.01,11.01]],"ltp":0.0,"tv":0.0,"id":8284479}]}]}
{"op":"mcm","clk":"1008740488","pt":1580661404960,"mc":[{"id":"1.168236371","marketDefinition":{"bspMarket":false,"turnInPlayEnabled":true,"persistenceEnabled":true,"marketBaseRate":5.0,"eventId":"29681838","eventTypeId":"2","numberOfWinners":1,"bettingType":"ODDS","marketType":"SET_WINNER","marketTime":"2020-02-02T16:35:00.000Z","suspendTime":"2020-02-02T16:35:00.000Z","bspReconciled":false,"complete":true,"inPlay":false,"crossMatching":false,"runnersVoidable":false,"numberOfActiveRunners":2,"betDelay":0,"status":"OPEN","runners":[{"status":"ACTIVE","sortPriority":1,"id":4520808,"name":"Facundo Bagnis"},{"status":"ACTIVE","sortPriority":2,"id":8284479,"name":"Federico Gaio"}],"regulators":["MR_INT"],"countryCode":"AR","discountAllowed":true,"timezone":"UTC","openDate":"2020-02-02T16:35:00.000Z","version":3149819976,"name":"Set 2 Winner","eventName":"Bagnis v Gaio"}}]}
{"op":"mcm","clk":"1008891322","pt":1580662142430,"mc":[{"id":"1.168236371","rc":[{"batb":[[1,1.78,53.77],[2,1.01,11.01]],"batl":[[0,1.97,42.01]],"ltp":0.0,"tv":0.0,"id":4520808},{"batb":[[0,2.06,64.82]],"batl":[[0,2.3,31.93]],"ltp":0.0,"tv":0.0,"id":8284479}]}]}
{"op":"mcm","clk":"1008893771","pt":1580662157668,"mc":[{"id":"1.168236371","marketDefinition":{"bspMarket":false,"turnInPlayEnabled":true,"persistenceEnabled":true,"marketBaseRate":5.0,"eventId":"29681838","eventTypeId":"2","numberOfWinners":1,"bettingType":"ODDS","marketType":"SET_WINNER","marketTime":"2020-02-02T16:35:00.000Z","suspendTime":"2020-02-02T16:35:00.000Z","bspReconciled":false,"complete":true,"inPlay":false,"crossMatching":true,"runnersVoidable":false,"numberOfActiveRunners":2,"betDelay":0,"status":"OPEN","runners":[{"status":"ACTIVE","sortPriority":1,"id":4520808,"name":"Facundo Bagnis"},{"status":"ACTIVE","sortPriority":2,"id":8284479,"name":"Federico Gaio"}],"regulators":["MR_INT"],"countryCode":"AR","discountAllowed":true,"timezone":"UTC","openDate":"2020-02-02T16:35:00.000Z","version":3149819976,"name":"Set 2 Winner","eventName":"Bagnis v Gaio"}}]}
{"op":"mcm","clk":"1008895958","pt":1580662172116,"mc":[{"id":"1.168236371","marketDefinition":{"bspMarket":false,"turnInPlayEnabled":true,"persistenceEnabled":true,"marketBaseRate":5.0,"eventId":"29681838","eventTypeId":"2","numberOfWinners":1,"bettingType":"ODDS","marketType":"SET_WINNER","marketTime":"2020-02-02T16:35:00.000Z","suspendTime":"2020-02-02T16:35:00.000Z","bspReconciled":false,"complete":true,"inPlay":true,"crossMatching":true,"runnersVoidable":false,"numberOfActiveRunners":2,"betDelay":3,"status":"OPEN","runners":[{"status":"ACTIVE","sortPriority":1,"id":4520808,"name":"Facundo Bagnis"},{"status":"ACTIVE","sortPriority":2,"id":8284479,"name":"Federico Gaio"}],"regulators":["MR_INT"],"countryCode":"AR","discountAllowed":true,"timezone":"UTC","openDate":"2020-02-02T16:35:00.000Z","version":3149870780,"name":"Set 2 Winner","eventName":"Bagnis v Gaio"},"rc":[{"batb":[[0,1.01,10.51],[1,1.78,0],[2,1.01,0]],"ltp":0.0,"tv":0.0,"id":4520808},{"batb":[[0,1.01,10.51],[1,1.01,0]],"ltp":0.0,"tv":0.0,"id":8284479}]}]}
{"op":"mcm","clk":"1008897442","pt":1580662182386,"mc":[{"id":"1.168236371","rc":[{"batb":[[0,1.85,17.86],[1,1.81,19.36],[2,1.01,10.51]],"ltp":0.0,"tv":0.0,"id":4520808},{"batb":[[0,2.02,27.07],[1,1.99,28.56],[2,1.01,10.51]],"ltp":0.0,"tv":0.0,"id":8284479}]}]}
{"op":"mcm","clk":"1008897607","pt":1580662183556,"mc":[{"id":"1.168236371","rc":[{"batb":[[2,1.79,52.93]],"batl":[[0,1.99,42.01]],"ltp":0.0,"tv":0.0,"id":4520808},{"batb":[[0,2.02,68.24]],"batl":[[0,2.26,32.77]],"ltp":0.0,"tv":0.0,"id":8284479}]}]}
{"op":"mcm","clk":"1008898149","pt":1580662187004,"mc":[{"id":"1.168236371","rc":[{"batb":[[0,1.86,311.54],[1,1.85,17.86],[2,1.81,19.36]],"ltp":0.0,"tv":0.0,"id":4520808}]}]}
{"op":"mcm","clk":"1008898916","pt":1580662192125,"mc":[{"id":"1.168236371","rc":[{"batb":[[0,1.81,19.36],[1,1.79,52.93],[2,1.01,10.51]],"ltp":0.0,"tv":0.0,"id":4520808},{"batb":[[0,2.02,41.17]],"ltp":0.0,"tv":0.0,"id":8284479}]}]}
{"op":"mcm","clk":"1008899078","pt":1580662193124,"mc":[{"id":"1.168236371","rc":[{"batb":[[1,1.01,10.51],[2,1.01,0]],"ltp":0.0,"tv":0.0,"id":4520808},{"batb":[[0,1.99,28.56],[1,1.01,10.51],[2,1.01,0]],"ltp":0.0,"tv":0.0,"id":8284479}]}]}
{"op":"mcm","clk":"1008901361","pt":1580662207593,"mc":[{"id":"1.168236371","rc":[{"batb":[[0,1.88,17],[1,1.84,18.33],[2,1.81,51.25]],"batl":[[0,2,42.01]],"ltp":0.0,"tv":0.0,"id":4520808},{"batb":[[0,1.99,70.57],[1,1.96,29.82],[2,1.01,10.51]],"batl":[[0,2.24,33.61]],"ltp":0.0,"tv":0.0,"id":8284479}]}]}
{"op":"mcm","clk":"1008903038","pt":1580662218556,"mc":[{"id":"1.168236371","rc":[{"batb":[[0,1.84,18.33],[1,1.01,10.51],[2,1.81,0]],"ltp":0.0,"tv":0.0,"id":4520808},{"batb":[[0,1.96,29.82],[1,1.01,10.51],[2,1.01,0]],"ltp":0.0,"tv":0.0,"id":8284479}]}]}
{"op":"mcm","clk":"1008904915","pt":1580662230674,"mc":[{"id":"1.168236371","rc":[{"batb":[[1,1.8,19.83],[2,1.01,10.51]],"ltp":0.0,"tv":0.0,"id":4520808},{"batb":[[0,2.04,26.36],[1,2,27.77],[2,1.01,10.51]],"ltp":0.0,"tv":0.0,"id":8284479}]}]}
{"op":"mcm","clk":"1008905059","pt":1580662231480,"mc":[{"id":"1.168236371","rc":[{"batb":[[2,1.78,53.77]],"batl":[[0,1.97,42.01]],"ltp":0.0,"tv":0.0,"id":4520808},{"batb":[[0,2.04,66.69]],"batl":[[0,2.28,32.77]],"ltp":0.0,"tv":0.0,"id":8284479}]}]}
{"op":"mcm","clk":"1008906803","pt":1580662242017,"mc":[{"id":"1.168236371","rc":[{"batb":[[0,1.8,19.43],[1,1.78,53.77],[2,1.01,10.51]],"ltp":0.0,"tv":0.0,"id":4520808},{"batb":[[0,2.04,40.33]],"ltp":0.0,"tv":0.0,"id":8284479}]}]}
{"op":"mcm","clk":"1008907000","pt":1580662243085,"mc":[{"id":"1.168236371","rc":[{"batb":[[1,1.01,10.51],[2,1.01,0]],"ltp":0.0,"tv":0.0,"id":4520808},{"batb":[[0,2,27.77],[1,1.01,10.51],[2,1.01,0]],"ltp":0.0,"tv":0.0,"id":8284479}]}]}
{"op":"mcm","clk":"1008907873","pt":1580662248906,"mc":[{"id":"1.168236371","rc":[{"batb":[[0,1.88,17.15],[1,1.84,18.33],[2,1.01,10.51]],"ltp":0.0,"tv":0.0,"id":4520808},{"batb":[[1,1.97,29.74],[2,1.01,10.51]],"ltp":0.0,"tv":0.0,"id":8284479}]}]}
{"op":"mcm","clk":"1008907960","pt":1580662249502,"mc":[{"id":"1.168236371","rc":[{"batb":[[2,1.81,51.25]],"batl":[[0,2,42.01]],"ltp":0.0,"tv":0.0,"id":4520808},{"batb":[[0,2,69.78]],"batl":[[0,2.26,32.77]],"ltp":0.0,"tv":0.0,"id":8284479}]}]}
{"op":"mcm","clk":"1008909188","pt":1580662258233,"mc":[{"id":"1.168236371","rc":[{"batb":[[0,2,27.77]],"ltp":0.0,"tv":0.0,"id":8284479}]}]}
{"op":"mcm","clk":"1008909274","pt":1580662258809,"mc":[{"id":"1.168236371","rc":[{"batb":[[0,1.84,18.33],[1,1.81,51.25],[2,1.01,10.51]],"ltp":0.0,"tv":0.0,"id":4520808},{"batb":[[0,1.97,29.74],[1,1.01,10.51],[2,1.01,0]],"ltp":0.0,"tv":0.0,"id":8284479}]}]}
{"op":"mcm","clk":"1008909650","pt":1580662261139,"mc":[{"id":"1.168236371","rc":[{"batb":[[1,1.01,10.51],[2,1.01,0]],"batl":[[0,1.99,42.01]],"ltp":0.0,"tv":0.0,"id":4520808},{"batb":[[0,2.02,41.17],[1,1.97,29.74],[2,1.01,10.51]],"ltp":0.0,"tv":0.0,"id":8284479}]}]}
{"op":"mcm","clk":"1008909784","pt":1580662262132,"mc":[{"id":"1.168236371","rc":[{"batb":[[0,1.97,29.74],[1,1.01,10.51],[2,1.01,0]],"ltp":0.0,"tv":0.0,"id":8284479}]}]}
{"op":"mcm","clk":"1008911659","pt":1580662275218,"mc":[{"id":"1.168236371","rc":[{"batb":[[0,1.91,16.37],[1,1.87,17.23],[2,1.01,10.51]],"ltp":0.0,"tv":0.0,"id":4520808},{"batb":[[1,1.92,16.05],[2,1.01,10.51]],"ltp":0.0,"tv":0.0,"id":8284479}]}]}
{"op":"mcm","clk":"1008911762","pt":1580662275951,"mc":[{"id":"1.168236371","rc":[{"batb":[[2,1.84,49.57]],"batl":[[0,2.04,40.33]],"ltp":0.0,"tv":0.0,"id":4520808},{"batb":[[1,1.96,43.69],[2,1.92,16.05]],"batl":[[0,2.2,34.45]],"ltp":0.0,"tv":0.0,"id":8284479}]}]}
{"op":"mcm","clk":"1008912757","pt":1580662283035,"mc":[{"id":"1.168236371","rc":[{"batb":[[1,1.9,16.6],[2,1.87,17.23]],"ltp":0.0,"tv":0.0,"id":4520808},{"batb":[[0,1.98,29.19],[1,1.97,29.74],[2,1.96,43.69]],"ltp":0.0,"tv":0.0,"id":8284479}]}]}
{"op":"mcm","clk":"1008912786","pt":1580662283248,"mc":[{"id":"1.168236371","rc":[{"batb":[[0,1.9,16.6],[1,1.86,17.55],[2,1.84,49.57]],"ltp":0.0,"tv":0.0,"id":4520808},{"batb":[[1,1.96,43.69],[2,1.93,15.74]],"ltp":0.0,"tv":0.0,"id":8284479}]}]}
{"op":"mcm","clk":"1008917784","pt":1580662321399,"mc":[{"id":"1.168236371","rc":[{"batb":[[0,1.86,17.55],[1,1.84,49.57],[2,1.01,10.51]],"ltp":0.0,"tv":0.0,"id":4520808},{"batb":[[0,1.96,43.69],[1,1.93,15.74],[2,1.01,10.51]],"ltp":0.0,"tv":0.0,"id":8284479}]}]}
{"op":"mcm","clk":"1008917925","pt":1580662322516,"mc":[{"id":"1.168236371","rc":[{"batb":[[1,1.01,10.51],[2,1.01,0]],"ltp":0.0,"tv":0.0,"id":4520808},{"batb":[[0,1.93,15.74],[1,1.01,10.51],[2,1.01,0]],"ltp":0.0,"tv":0.0,"id":8284479}]}]}
{"op":"mcm","clk":"1008918793","pt":1580662329089,"mc":[{"id":"1.168236371","rc":[{"batb":[[1,1.84,18.33],[2,1.01,10.51]],"ltp":0.0,"tv":0.0,"id":4520808},{"batb":[[0,2.02,27.54],[1,1.96,29.82],[2,1.93,303.1]],"ltp":0.0,"tv":0.0,"id":8284479}]}]}
{"op":"mcm","clk":"1008918847","pt":1580662329507,"mc":[{"id":"1.168236371","rc":[{"batb":[[2,1.82,50.41]],"batl":[[0,2,42.01]],"ltp":0.0,"tv":0.0,"id":4520808},{"batb":[[1,2,42.01],[2,1.96,29.82]],"batl":[[0,2.24,33.61]],"ltp":0.0,"tv":0.0,"id":8284479}]}]}
{"op":"mcm","clk":"1008920806","pt":1580662343231,"mc":[{"id":"1.168236371","rc":[{"batb":[[0,1.84,18.33],[1,1.82,50.41],[2,1.01,10.51]],"ltp":0.0,"tv":0.0,"id":4520808},{"batb":[[0,2,42.01],[1,1.96,29.82],[2,1.01,10.51]],"ltp":0.0,"tv":0.0,"id":8284479}]}]}
{"op":"mcm","clk":"1008921086","pt":1580662345243,"mc":[{"id":"1.168236371","rc":[{"batb":[[1,1.01,10.51],[2,1.01,0]],"ltp":0.0,"tv":0.0,"id":4520808},{"batb":[[0,1.96,29.82],[1,1.01,10.51],[2,1.01,0]],"ltp":0.0,"tv":0.0,"id":8284479}]}]}
{"op":"mcm","clk":"1008923262","pt":1580662361212,"mc":[{"id":"1.168236371","rc":[{"batb":[[0,1.91,16.29],[1,1.88,17.15],[2,1.85,139.17]],"ltp":0.0,"tv":0.0,"id":4520808},{"batb":[[1,1.91,16.21],[2,1.01,10.51]],"ltp":0.0,"tv":0.0,"id":8284479}]}]}
{"op":"mcm","clk":"1008923401","pt":1580662362053,"mc":[{"id":"1.168236371","rc":[{"batb":[[2,1.86,48.73]],"batl":[[0,2.06,39.49]],"ltp":0.0,"tv":0.0,"id":4520808},{"batb":[[1,1.94,44.53],[2,1.91,16.21]],"batl":[[0,2.18,35.29]],"ltp":0.0,"tv":0.0,"id":8284479}]}]}
{"op":"mcm","clk":"1008924838","pt":1580662373173,"mc":[{"id":"1.168236371","rc":[{"batb":[[0,1.88,17.15],[1,1.86,48.73],[2,1.01,10.51]],"ltp":0.0,"tv":0.0,"id":4520808},{"batb":[[0,1.94,44.53],[1,1.91,16.21],[2,1.01,10.51]],"ltp":0.0,"tv":0.0,"id":8284479}]}]}
{"op":"mcm","clk":"1008925042","pt":1580662374564,"mc":[{"id":"1.168236371","rc":[{"batb":[[1,1.01,10.51],[2,1.01,0]],"ltp":0.0,"tv":0.0,"id":4520808},{"batb":[[0,1.91,16.21],[1,1.01,10.51],[2,1.01,0]],"ltp":0.0,"tv":0.0,"id":8284479}]}]}
{"op":"mcm","clk":"1008925777","pt":1580662379938,"mc":[{"id":"1.168236371","rc":[{"batb":[[1,1.85,18.02],[2,1.84,49.57]],"batl":[[0,2.04,40.33]],"ltp":0.0,"tv":0.0,"id":4520808},{"batb":[[0,2,28.33],[1,1.97,42.85],[2,1.95,30.69]],"batl":[[0,2.2,34.45]],"ltp":0.0,"tv":0.0,"id":8284479}]}]}
{"op":"mcm","clk":"1008927788","pt":1580662394097,"mc":[{"id":"1.168236371","rc":[{"batb":[[0,1.85,18.02],[1,1.84,49.57],[2,1.01,10.51]],"ltp":0.0,"tv":0.0,"id":4520808},{"batb":[[0,1.97,42.85],[1,1.95,30.69],[2,1.01,10.51]],"ltp":0.0,"tv":0.0,"id":8284479}]}]}
{"op":"mcm","clk":"1008927854","pt":1580662394572,"mc":[{"id":"1.168236371","rc":[{"batb":[[1,1.01,10.51],[2,1.01,0]],"ltp":0.0,"tv":0.0,"id":4520808},{"batb":[[0,1.95,30.69],[1,1.01,10.51],[2,1.01,0]],"ltp":0.0,"tv":0.0,"id":8284479}]}]}
{"op":"mcm","clk":"1008929316","pt":1580662404648,"mc":[{"id":"1.168236371","rc":[{"batb":[[1,1.82,18.8],[2,1.01,10.51]],"ltp":0.0,"tv":0.0,"id":4520808},{"batb":[[0,2.02,26.83],[1,1.98,28.95],[2,1.01,10.51]],"ltp":0.0,"tv":0.0,"id":8284479}]}]}
{"op":"mcm","clk":"1008929413","pt":1580662405478,"mc":[{"id":"1.168236371","rc":[{"batb":[[1,1.82,69.22]],"batl":[[0,2,42.01]],"ltp":0.0,"tv":0.0,"id":4520808},{"batb":[[1,2,42.01],[2,1.98,28.95]],"batl":[[0,2.24,33.61]],"ltp":0.0,"tv":0.0,"id":8284479}]}]}
{"op":"mcm","clk":"1008930906","pt":1580662416831,"mc":[{"id":"1.168236371","rc":[{"batb":[[0,1.82,18.8],[1,1.01,10.51],[2,1.01,0]],"ltp":0.0,"tv":0.0,"id":4520808},{"batb":[[0,1.98,28.95],[1,1.01,10.51],[2,1.98,0]],"ltp":0.0,"tv":0.0,"id":8284479}]}]}
{"op":"mcm","clk":"1008932951","pt":1580662432923,"mc":[{"id":"1.168236371","rc":[{"batb":[[0,1.89,16.68],[1,1.86,17.62],[2,1.01,10.51]],"ltp":0.0,"tv":0.0,"id":4520808},{"batb":[[1,1.93,15.74],[2,1.01,10.51]],"ltp":0.0,"tv":0.0,"id":8284479}]}]}
{"op":"mcm","clk":"1008933026","pt":1580662433546,"mc":[{"id":"1.168236371","rc":[{"batb":[[1,1.86,66.36]],"batl":[[0,2.06,39.49]],"ltp":0.0,"tv":0.0,"id":4520808},{"batb":[[1,1.95,43.69],[2,1.93,15.74]],"batl":[[0,2.18,35.29]],"ltp":0.0,"tv":0.0,"id":8284479}]}]}
{"op":"mcm","clk":"1008934458","pt":1580662444954,"mc":[{"id":"1.168236371","rc":[{"batl":[[1,2.7,245.56]],"ltp":0.0,"tv":0.0,"id":4520808},{"batl":[[1,2.52,270.1]],"ltp":0.0,"tv":0.0,"id":8284479}]}]}
{"op":"mcm","clk":"1008934963","pt":1580662448860,"mc":[{"id":"1.168236371","rc":[{"batb":[[0,1.86,17.62],[1,1.01,10.51],[2,1.01,0]],"batl":[[0,2.7,245.56],[1,2.7,0]],"ltp":0.0,"tv":0.0,"id":4520808},{"batb":[[0,1.93,15.74],[1,1.01,10.51],[2,1.93,0]],"batl":[[0,2.52,270.1],[1,2.52,0]],"ltp":0.0,"tv":0.0,"id":8284479}]}]}
{"op":"mcm","clk":"1008938187","pt":1580662473217,"mc":[{"id":"1.168236371","rc":[{"batb":[[1,1.82,19.04],[2,1.01,10.51]],"ltp":0.0,"tv":0.0,"id":4520808},{"batb":[[0,2.02,27.46],[1,1.98,29.03],[2,1.01,10.51]],"ltp":0.0,"tv":0.0,"id":8284479}]}]}
{"op":"mcm","clk":"1008938334","pt":1580662474157,"mc":[{"id":"1.168236371","rc":[{"batb":[[1,1.83,50.41],[2,1.82,19.04]],"batl":[[0,2.02,41.17],[1,2.7,245.56]],"ltp":0.0,"tv":0.0,"id":4520808},{"batb":[[1,1.99,42.01],[2,1.98,29.03]],"batl":[[0,2.22,33.61],[1,2.52,270.1]],"ltp":0.0,"tv":0.0,"id":8284479}]}]}
{"op":"mcm","clk":"1008942763","pt":1580662507014,"mc":[{"id":"1.168236371","rc":[{"batb":[[0,1.83,50.41],[1,1.82,19.04],[2,1.01,10.51]],"ltp":0.0,"tv":0.0,"id":4520808},{"batb":[[0,1.99,42.01],[1,1.98,29.03],[2,1.01,10.51]],"ltp":0.0,"tv":0.0,"id":8284479}]}]}
{"op":"mcm","clk":"1008943066","pt":1580662509216,"mc":[{"id":"1.168236371","rc":[{"batb":[[0,1.82,19.04],[1,1.01,10.51],[2,1.01,0]],"batl":[[0,2.7,245.56],[1,2.7,0]],"ltp":0.0,"tv":0.0,"id":4520808},{"batb":[[0,1.98,29.03],[1,1.01,10.51],[2,1.01,0]],"batl":[[0,2.52,270.1],[1,2.52,0]],"ltp":0.0,"tv":0.0,"id":8284479}]}]}
{"op":"mcm","clk":"1008945694","pt":1580662530058,"mc":[{"id":"1.168236371","rc":[{"batb":[[0,1.89,16.68],[1,1.85,48.73],[2,1.84,18.1]],"batl":[[0,2.04,40.33],[1,2.7,245.56]],"ltp":0.0,"tv":0.0,"id":4520808},{"batb":[[1,1.97,42.85],[2,1.95,30.69]],"batl":[[0,2.2,34.45],[1,2.52,270.1]],"ltp":0.0,"tv":0.0,"id":8284479}]}]}
{"op":"mcm","clk":"1008946065","pt":1580662533072,"mc":[{"id":"1.168236371","rc":[{"batb":[[1,1.86,308.61],[2,1.85,48.73]],"ltp":0.0,"tv":0.0,"id":4520808}]}]}
{"op":"mcm","clk":"1008946095","pt":1580662533273,"mc":[{"id":"1.168236371","rc":[{"batb":[[1,1.85,48.73],[2,1.84,18.1]],"ltp":0.0,"tv":0.0,"id":4520808}]}]}
{"op":"mcm","clk":"1008947336","pt":1580662543856,"mc":[{"id":"1.168236371","rc":[{"batb":[[0,1.85,48.73],[1,1.84,18.1],[2,1.01,10.51]],"ltp":0.0,"tv":0.0,"id":4520808},{"batb":[[0,1.97,42.85],[1,1.95,30.69],[2,1.01,10.51]],"ltp":0.0,"tv":0.0,"id":8284479}]}]}
{"op":"mcm","clk":"1008947427","pt":1580662544591,"mc":[{"id":"1.168236371","rc":[{"batb":[[0,1.84,18.1],[1,1.01,10.51],[2,1.01,0]],"batl":[[0,2.7,245.56],[1,2.7,0]],"ltp":0.0,"tv":0.0,"id":4520808},{"batb":[[0,1.95,30.69],[1,1.01,10.51],[2,1.01,0]],"batl":[[0,2.52,270.1],[1,2.52,0]],"ltp":0.0,"tv":0.0,"id":8284479}]}]}
{"op":"mcm","clk":"1008948701","pt":1580662554204,"mc":[{"id":"1.168236371","rc":[{"batb":[[0,1.93,15.82],[1,1.87,65.12],[2,1.01,10.51]],"batl":[[0,2.06,39.49],[1,2.7,245.56]],"ltp":0.0,"tv":0.0,"id":4520808},{"batb":[[0,1.95,74.38],[1,1.92,15.89],[2,1.01,10.51]],"batl":[[0,2.16,36.13],[1,2.52,270.1]],"ltp":0.0,"tv":0.0,"id":8284479}]}]}
{"op":"mcm","clk":"1008950000","pt":1580662563778,"mc":[{"id":"1.168236371","rc":[{"batb":[[0,1.87,65.12],[1,1.01,10.51],[2,1.01,0]],"ltp":0.0,"tv":0.0,"id":4520808},{"batb":[[0,1.95,43.69]],"ltp":0.0,"tv":0.0,"id":8284479}]}]}
{"op":"mcm","clk":"1008950136","pt":1580662564677,"mc":[{"id":"1.168236371","rc":[{"batb":[[0,1.87,17.23]],"batl":[[0,2.7,245.56],[1,2.7,0]],"ltp":0.0,"tv":0.0,"id":4520808},{"batb":[[0,1.92,15.89],[1,1.01,10.51],[2,1.01,0]],"batl":[[0,2.52,270.1],[1,2.52,0]],"ltp":0.0,"tv":0.0,"id":8284479}]}]}
{"op":"mcm","clk":"1008951076","pt":1580662571226,"mc":[{"id":"1.168236371","rc":[{"batb":[[0,1.95,30.61],[1,1.91,16.29],[2,1.87,17.23]],"ltp":0.0,"tv":0.0,"id":4520808},{"batb":[[1,1.9,16.68],[2,1.01,10.51]],"ltp":0.0,"tv":0.0,"id":8284479}]}]}
{"op":"mcm","clk":"1008951217","pt":1580662572226,"mc":[{"id":"1.168236371","rc":[{"batb":[[2,1.89,47.05]],"batl":[[0,2.08,38.65],[1,2.7,245.56]],"ltp":0.0,"tv":0.0,"id":4520808},{"batb":[[0,1.92,61.26]],"batl":[[0,2.14,36.13],[1,2.4,289.78]],"ltp":0.0,"tv":0.0,"id":8284479}]}]}
{"op":"mcm","clk":"1008952458","pt":1580662581421,"mc":[{"id":"1.168236371","rc":[{"batb":[[0,1.91,16.29],[1,1.89,47.05],[2,1.01,10.51]],"ltp":0.0,"tv":0.0,"id":4520808},{"batb":[[0,1.92,45.37]],"ltp":0.0,"tv":0.0,"id":8284479}]}]}
{"op":"mcm","clk":"1008952621","pt":1580662582928,"mc":[{"id":"1.168236371","rc":[{"batb":[[1,1.01,10.51],[2,1.01,0]],"batl":[[0,2.7,245.56],[1,2.7,0]],"ltp":0.0,"tv":0.0,"id":4520808},{"batb":[[0,1.9,16.68],[1,1.01,10.51],[2,1.01,0]],"batl":[[0,2.4,289.78],[1,2.4,0]],"ltp":0.0,"tv":0.0,"id":8284479}]}]}
{"op":"mcm","clk":"1008954110","pt":1580662594043,"mc":[{"id":"1.168236371","rc":[{"batb":[[0,1.98,29.11],[1,1.95,30.45],[2,1.92,45.37]],"batl":[[0,2.12,36.97],[1,2.7,245.56]],"ltp":0.0,"tv":0.0,"id":4520808},{"batb":[[1,1.88,47.05],[2,1.84,18.18]],"batl":[[0,2.1,37.81],[1,2.4,289.78]],"ltp":0.0,"tv":0.0,"id":8284479}]}]}
{"op":"mcm","clk":"1008955126","pt":1580662602046,"mc":[{"id":"1.168236371","rc":[{"batb":[[0,1.97,29.58],[1,1.94,15.5]],"ltp":0.0,"tv":0.0,"id":4520808},{"batb":[[0,1.9,16.37],[2,1.85,17.94]],"ltp":0.0,"tv":0.0,"id":8284479}]}]}
{"op":"mcm","clk":"1008957178","pt":1580662618207,"mc":[{"id":"1.168236371","rc":[{"batb":[[0,1.91,16.29]],"ltp":0.0,"tv":0.0,"id":8284479}]}]}
{"op":"mcm","clk":"1008964964","pt":1580662682173,"mc":[{"id":"1.168236371","rc":[{"batb":[[0,1.94,15.5],[1,1.92,45.37],[2,1.01,10.51]],"ltp":0.0,"tv":0.0,"id":4520808},{"batb":[[0,1.88,47.05],[1,1.85,17.94],[2,1.01,10.51]],"ltp":0.0,"tv":0.0,"id":8284479}]}]}
{"op":"mcm","clk":"1008965026","pt":1580662682664,"mc":[{"id":"1.168236371","rc":[{"batb":[[1,1.01,10.51],[2,1.01,0]],"batl":[[0,2.7,245.56],[1,2.7,0]],"ltp":0.0,"tv":0.0,"id":4520808},{"batb":[[0,1.85,17.94],[1,1.01,10.51],[2,1.01,0]],"batl":[[0,2.4,289.78],[1,2.4,0]],"ltp":0.0,"tv":0.0,"id":8284479}]}]}
{"op":"mcm","clk":"1008965386","pt":1580662685861,"mc":[{"id":"1.168236371","rc":[{"batb":[[0,1.93,15.74]],"ltp":0.0,"tv":0.0,"id":4520808},{"batb":[[0,1.87,17.47]],"ltp":0.0,"tv":0.0,"id":8284479}]}]}
{"op":"mcm","clk":"1008967307","pt":1580662699983,"mc":[{"id":"1.168236371","rc":[{"batb":[[0,2,27.7],[1,1.97,29.66],[2,1.96,43.69]],"batl":[[0,2.18,35.29]],"ltp":0.0,"tv":0.0,"id":4520808},{"batb":[[1,1.85,48.73],[2,1.81,19.2]],"batl":[[0,2.06,39.49]],"ltp":0.0,"tv":0.0,"id":8284479}]}]}
{"op":"mcm","clk":"1008967648","pt":1580662702095,"mc":[{"id":"1.168236371","rc":[{"batl":[[1,3,213.45]],"ltp":0.0,"tv":0.0,"id":4520808},{"batl":[[1,2.3,309.75]],"ltp":0.0,"tv":0.0,"id":8284479}]}]}
{"op":"mcm","clk":"1008969832","pt":1580662718111,"mc":[{"id":"1.168236371","rc":[{"batb":[[0,1.97,29.66],[1,1.96,43.69],[2,1.01,10.51]],"ltp":0.0,"tv":0.0,"id":4520808},{"batb":[[0,1.85,48.73],[1,1.81,19.2],[2,1.01,10.51]],"ltp":0.0,"tv":0.0,"id":8284479}]}]}
{"op":"mcm","clk":"1008969938","pt":1580662718789,"mc":[{"id":"1.168236371","rc":[{"batb":[[1,1.01,10.51],[2,1.01,0]],"batl":[[0,3,213.45],[1,3,0]],"ltp":0.0,"tv":0.0,"id":4520808},{"batb":[[0,1.81,19.2],[1,1.01,10.51],[2,1.01,0]],"batl":[[0,2.3,309.75],[1,2.3,0]],"ltp":0.0,"tv":0.0,"id":8284479}]}]}
{"op":"mcm","clk":"1008971064","pt":1580662727993,"mc":[{"id":"1.168236371","rc":[{"batb":[[1,1.94,44.53],[2,1.93,15.58]],"batl":[[0,2.16,36.13]],"ltp":0.0,"tv":0.0,"id":4520808},{"batb":[[0,1.91,16.37],[1,1.87,47.89],[2,1.85,18.02]],"batl":[[0,2.08,38.65],[1,2.3,309.75]],"ltp":0.0,"tv":0.0,"id":8284479}]}]}
{"op":"mcm","clk":"1008971333","pt":1580662730084,"mc":[{"id":"1.168236371","rc":[{"batl":[[1,2.84,228.62]],"ltp":0.0,"tv":0.0,"id":4520808}]}]}
{"op":"mcm","clk":"1008973184","pt":1580662744620,"mc":[{"id":"1.168236371","rc":[{"batb":[[0,1.93,15.58],[1,1.01,10.51],[2,1.93,0]],"batl":[[0,2.84,228.62],[1,2.84,0]],"ltp":0.0,"tv":0.0,"id":4520808},{"batb":[[0,1.85,18.02],[1,1.01,10.51],[2,1.85,0]],"batl":[[0,2.3,309.75],[1,2.3,0]],"ltp":0.0,"tv":0.0,"id":8284479}]}]}
{"op":"mcm","clk":"1008973496","pt":1580662747228,"mc":[{"id":"1.168236371","rc":[{"batb":[[0,1.94,15.58],[1,1.93,15.58],[2,1.01,10.51]],"ltp":0.0,"tv":0.0,"id":4520808},{"batb":[[1,1.84,18.25],[2,1.01,10.51]],"ltp":0.0,"tv":0.0,"id":8284479}]}]}
{"op":"mcm","clk":"1008973566","pt":1580662747755,"mc":[{"id":"1.168236371","rc":[{"batb":[[1,1.01,10.51],[2,1.01,0]],"ltp":0.0,"tv":0.0,"id":4520808},{"batb":[[0,1.84,18.25],[1,1.01,10.51],[2,1.01,0]],"ltp":0.0,"tv":0.0,"id":8284479}]}]}
{"op":"mcm","clk":"1008974140","pt":1580662753200,"mc":[{"id":"1.168236371","rc":[{"batb":[[0,2.04,26.52],[1,2,28.25],[2,1.01,10.51]],"ltp":0.0,"tv":0.0,"id":4520808},{"batb":[[1,1.78,20.22],[2,1.01,10.51]],"ltp":0.0,"tv":0.0,"id":8284479}]}]}
{"op":"mcm","clk":"1008974222","pt":1580662753655,"mc":[{"id":"1.168236371","rc":[{"batb":[[2,1.98,42.85]],"batl":[[0,2.2,34.45],[1,2.84,228.62]],"ltp":0.0,"tv":0.0,"id":4520808},{"batb":[[0,1.84,67.83]],"batl":[[0,2.04,40.33],[1,2.3,309.75]],"ltp":0.0,"tv":0.0,"id":8284479}]}]}
{"op":"mcm","clk":"1008976306","pt":1580662771779,"mc":[{"id":"1.168236371","rc":[{"batb":[[0,2,28.25],[1,1.98,42.85],[2,1.01,10.51]],"ltp":0.0,"tv":0.0,"id":4520808},{"batb":[[0,1.84,49.57]],"ltp":0.0,"tv":0.0,"id":8284479}]}]}
{"op":"mcm","clk":"1008976427","pt":1580662772760,"mc":[{"id":"1.168236371","rc":[{"batb":[[1,1.01,10.51],[2,1.01,0]],"batl":[[0,2.84,228.62],[1,2.84,0]],"ltp":0.0,"tv":0.0,"id":4520808},{"batb":[[0,1.78,20.22],[1,1.01,10.51],[2,1.01,0]],"batl":[[0,2.3,309.75],[1,2.3,0]],"ltp":0.0,"tv":0.0,"id":8284479}]}]}
{"op":"mcm","clk":"1008976638","pt":1580662774666,"mc":[{"id":"1.168236371","rc":[{"batb":[[0,1.79,20.14]],"ltp":0.0,"tv":0.0,"id":8284479}]}]}
{"op":"mcm","clk":"1008977612","pt":1580662782610,"mc":[{"id":"1.168236371","rc":[{"batb":[[1,1.95,30.61],[2,1.01,10.51]],"ltp":0.0,"tv":0.0,"id":4520808},{"batb":[[0,1.88,17.07],[1,1.82,18.96],[2,1.01,10.51]],"ltp":0.0,"tv":0.0,"id":8284479}]}]}
{"op":"mcm","clk":"1008977739","pt":1580662783667,"mc":[{"id":"1.168236371","rc":[{"batb":[[1,1.96,43.69],[2,1.95,30.61]],"batl":[[0,2.18,35.29],[1,2.84,228.62]],"ltp":0.0,"tv":0.0,"id":4520808},{"batb":[[1,1.85,48.73],[2,1.82,18.96]],"batl":[[0,2.06,39.49],[1,2.3,309.75]],"ltp":0.0,"tv":0.0,"id":8284479}]}]}
{"op":"mcm","clk":"1008980429","pt":1580662805012,"mc":[{"id":"1.168236371","rc":[{"batb":[[0,1.95,30.61],[1,1.01,10.51],[2,1.95,0]],"batl":[[0,2.84,228.62],[1,2.84,0]],"ltp":0.0,"tv":0.0,"id":4520808},{"batb":[[0,1.82,18.96],[1,1.01,10.51],[2,1.82,0]],"batl":[[0,2.3,309.75],[1,2.3,0]],"ltp":0.0,"tv":0.0,"id":8284479}]}]}
{"op":"mcm","clk":"1008980885","pt":1580662808245,"mc":[{"id":"1.168236371","rc":[{"batb":[[0,1.95,30.29]],"ltp":0.0,"tv":0.0,"id":4520808},{"batb":[[0,1.81,19.2]],"ltp":0.0,"tv":0.0,"id":8284479}]}]}
{"op":"mcm","clk":"1008983644","pt":1580662830923,"mc":[{"id":"1.168236371","rc":[{"batb":[[1,1.92,15.89],[2,1.01,10.51]],"ltp":0.0,"tv":0.0,"id":4520808},{"batb":[[0,1.92,16.05],[1,1.86,17.62],[2,1.01,10.51]],"ltp":0.0,"tv":0.0,"id":8284479}]}]}
{"op":"mcm","clk":"1008983756","pt":1580662831733,"mc":[{"id":"1.168236371","rc":[{"batb":[[1,1.94,44.53],[2,1.92,15.89]],"batl":[[0,2.16,36.13],[1,2.84,228.62]],"ltp":0.0,"tv":0.0,"id":4520808},{"batb":[[1,1.86,66.36]],"batl":[[0,2.08,38.65],[1,2.3,309.75]],"ltp":0.0,"tv":0.0,"id":8284479}]}]}
{"op":"mcm","clk":"1008986869","pt":1580662855081,"mc":[{"id":"1.168236371","rc":[{"batb":[[0,1.94,44.53],[1,1.92,15.89],[2,1.01,10.51]],"ltp":0.0,"tv":0.0,"id":4520808},{"batb":[[0,1.86,66.36],[1,1.01,10.51],[2,1.01,0]],"ltp":0.0,"tv":0.0,"id":8284479}]}]}
{"op":"mcm","clk":"1008987137","pt":1580662857048,"mc":[{"id":"1.168236371","rc":[{"batb":[[0,1.92,15.89],[1,1.01,10.51],[2,1.01,0]],"batl":[[0,2.84,228.62],[1,2.84,0]],"ltp":0.0,"tv":0.0,"id":4520808},{"batb":[[0,1.86,17.62]],"batl":[[0,2.3,309.75],[1,2.3,0]],"ltp":0.0,"tv":0.0,"id":8284479}]}]}
{"op":"mcm","clk":"1008987295","pt":1580662858156,"mc":[{"id":"1.168236371","rc":[{"batb":[[0,1.93,15.74]],"ltp":0.0,"tv":0.0,"id":4520808},{"batb":[[0,1.85,17.86]],"ltp":0.0,"tv":0.0,"id":8284479}]}]}
{"op":"mcm","clk":"1008987946","pt":1580662863188,"mc":[{"id":"1.168236371","rc":[{"batb":[[1,1.87,17.31],[2,1.01,10.51]],"ltp":0.0,"tv":0.0,"id":4520808},{"batb":[[0,1.94,15.42],[1,1.91,16.21],[2,1.85,17.86]],"ltp":0.0,"tv":0.0,"id":8284479}]}]}
{"op":"mcm","clk":"1008988076","pt":1580662864085,"mc":[{"id":"1.168236371","rc":[{"batb":[[1,1.9,46.21],[2,1.87,17.31]],"batl":[[0,2.1,37.81],[1,2.84,228.62]],"ltp":0.0,"tv":0.0,"id":4520808},{"batb":[[1,1.92,45.37],[2,1.91,16.21]],"batl":[[0,2.12,36.97],[1,2.3,309.75]],"ltp":0.0,"tv":0.0,"id":8284479}]}]}
{"op":"mcm","clk":"1008991561","pt":1580662889116,"mc":[{"id":"1.168236371","rc":[{"batb":[[0,1.9,46.21],[1,1.87,17.31],[2,1.01,10.51]],"ltp":0.0,"tv":0.0,"id":4520808},{"batb":[[0,1.92,45.37],[1,1.91,16.21],[2,1.01,10.51]],"ltp":0.0,"tv":0.0,"id":8284479}]}]}
{"op":"mcm","clk":"1008991803","pt":1580662890701,"mc":[{"id":"1.168236371","rc":[{"batb":[[0,1.87,17.31],[1,1.01,10.51],[2,1.01,0]],"batl":[[0,2.84,228.62],[1,2.84,0]],"ltp":0.0,"tv":0.0,"id":4520808},{"batb":[[0,1.91,16.21],[1,1.01,10.51],[2,1.01,0]],"batl":[[0,2.3,309.75],[1,2.3,0]],"ltp":0.0,"tv":0.0,"id":8284479}]}]}
{"op":"mcm","clk":"1008994539","pt":1580662908076,"mc":[{"id":"1.168236371","rc":[{"batb":[[0,1.96,29.9],[1,1.92,45.37],[2,1.91,16.21]],"ltp":0.0,"tv":0.0,"id":4520808},{"batb":[[1,1.9,46.21],[2,1.88,17.07]],"batl":[[0,2.1,37.81],[1,2.3,309.75]],"ltp":0.0,"tv":0.0,"id":8284479}]}]}
{"op":"mcm","clk":"1008994721","pt":1580662909137,"mc":[{"id":"1.168236371","rc":[{"batl":[[0,2.12,36.97],[1,2.84,228.62]],"ltp":0.0,"tv":0.0,"id":4520808}]}]}
{"op":"mcm","clk":"1008996503","pt":1580662921204,"mc":[{"id":"1.168236371","rc":[{"batb":[[0,1.92,45.37],[1,1.91,16.21],[2,1.01,10.51]],"ltp":0.0,"tv":0.0,"id":4520808},{"batb":[[0,1.9,46.21],[1,1.88,17.07],[2,1.01,10.51]],"ltp":0.0,"tv":0.0,"id":8284479}]}]}
{"op":"mcm","clk":"1008996747","pt":1580662922894,"mc":[{"id":"1.168236371","rc":[{"batb":[[0,1.91,16.21],[1,1.01,10.51],[2,1.01,0]],"batl":[[0,2.84,228.62],[1,2.84,0]],"ltp":0.0,"tv":0.0,"id":4520808},{"batb":[[0,1.88,17.07],[1,1.01,10.51],[2,1.01,0]],"batl":[[0,2.3,309.75],[1,2.3,0]],"ltp":0.0,"tv":0.0,"id":8284479}]}]}
{"op":"mcm","clk":"1009005421","pt":1580662979171,"mc":[{"id":"1.168236371","rc":[{"batb":[[0,1.99,28.48],[1,1.94,15.5],[2,1.92,134.19]],"ltp":0.0,"tv":0.0,"id":4520808},{"batb":[[1,1.86,17.78],[2,1.01,10.51]],"ltp":0.0,"tv":0.0,"id":8284479}]}]}
{"op":"mcm","clk":"1009005557","pt":1580662979845,"mc":[{"id":"1.168236371","rc":[{"batb":[[1,1.94,60.03],[2,1.01,10.51]],"batl":[[0,2.16,36.13]],"ltp":0.0,"tv":0.0,"id":4520808},{"batb":[[1,1.87,47.89],[2,1.86,17.78]],"batl":[[0,2.08,38.65]],"ltp":0.0,"tv":0.0,"id":8284479}]}]}
{"op":"mcm","clk":"1009005963","pt":1580662982240,"mc":[{"id":"1.168236371","rc":[{"batl":[[1,3,213.45]],"ltp":0.0,"tv":0.0,"id":4520808},{"batl":[[1,2.3,309.75]],"ltp":0.0,"tv":0.0,"id":8284479}]}]}
{"op":"mcm","clk":"1009007329","pt":1580662991244,"mc":[{"id":"1.168236371","rc":[{"batb":[[0,1.94,60.03],[1,1.01,10.51],[2,1.01,0]],"ltp":0.0,"tv":0.0,"id":4520808},{"batb":[[0,1.87,47.89],[1,1.86,17.78],[2,1.01,10.51]],"ltp":0.0,"tv":0.0,"id":8284479}]}]}
{"op":"mcm","clk":"1009007665","pt":1580662993172,"mc":[{"id":"1.168236371","rc":[{"batb":[[0,1.94,15.5]],"batl":[[0,3,213.45],[1,3,0]],"ltp":0.0,"tv":0.0,"id":4520808},{"batb":[[0,1.86,17.78],[1,1.01,10.51],[2,1.01,0]],"batl":[[0,2.3,309.75],[1,2.3,0]],"ltp":0.0,"tv":0.0,"id":8284479}]}]}
{"op":"mcm","clk":"1009008775","pt":1580662999979,"mc":[{"id":"1.168236371","rc":[{"batb":[[0,2.02,27.22],[1,1.97,29.58],[2,1.96,43.69]],"batl":[[0,2.18,35.29],[1,3,213.45]],"ltp":0.0,"tv":0.0,"id":4520808},{"batb":[[0,1.86,66.51],[1,1.82,18.8],[2,1.01,10.51]],"batl":[[0,2.06,39.49],[1,2.3,309.75]],"ltp":0.0,"tv":0.0,"id":8284479}]}]}
{"op":"mcm","clk":"1009010403","pt":1580663009977,"mc":[{"id":"1.168236371","rc":[{"batb":[[0,1.97,29.58],[1,1.96,43.69],[2,1.01,10.51]],"ltp":0.0,"tv":0.0,"id":4520808},{"batb":[[0,1.86,48.73]],"ltp":0.0,"tv":0.0,"id":8284479}]}]}
{"op":"mcm","clk":"1009010533","pt":1580663010772,"mc":[{"id":"1.168236371","rc":[{"batb":[[1,1.01,10.51],[2,1.01,0]],"batl":[[0,3,213.45],[1,3,0]],"ltp":0.0,"tv":0.0,"id":4520808},{"batb":[[0,1.82,18.8],[1,1.01,10.51],[2,1.01,0]],"batl":[[0,2.3,309.75],[1,2.3,0]],"ltp":0.0,"tv":0.0,"id":8284479}]}]}
{"op":"mcm","clk":"1009011475","pt":1580663016064,"mc":[{"id":"1.168236371","rc":[{"batb":[[0,2,42.01],[1,1.97,29.58],[2,1.01,10.51]],"batl":[[0,2.22,33.61],[1,3,213.45]],"ltp":0.0,"tv":0.0,"id":4520808},{"batb":[[0,1.82,69.22]],"batl":[[0,2.02,41.17],[1,2.3,309.75]],"ltp":0.0,"tv":0.0,"id":8284479}]}]}
{"op":"mcm","clk":"1009011560","pt":1580663016585,"mc":[{"id":"1.168236371","rc":[{"batb":[[0,2.06,25.65],[1,2.02,27.38],[2,2,42.01]],"ltp":0.0,"tv":0.0,"id":4520808},{"batb":[[1,1.77,20.77],[2,1.01,10.51]],"ltp":0.0,"tv":0.0,"id":8284479}]}]}
{"op":"mcm","clk":"1009015798","pt":1580663041028,"mc":[{"id":"1.168236371","rc":[{"batb":[[0,2.04,26.04],[1,2,69.78],[2,1.01,10.51]],"ltp":0.0,"tv":0.0,"id":4520808},{"batb":[[0,1.83,18.57],[1,1.82,50.41],[2,1.78,20.54]],"ltp":0.0,"tv":0.0,"id":8284479}]}]}
{"op":"mcm","clk":"1009018168","pt":1580663054416,"mc":[{"id":"1.168236371","rc":[{"batb":[[0,2.06,26.04]],"ltp":0.0,"tv":0.0,"id":4520808}]}]}
{"op":"mcm","clk":"1009019523","pt":1580663062171,"mc":[{"id":"1.168236371","rc":[{"batb":[[1,2.02,27.54],[2,2,69.78]],"ltp":0.0,"tv":0.0,"id":4520808}]}]}
{"op":"mcm","clk":"1009019732","pt":1580663063169,"mc":[{"id":"1.168236371","rc":[{"batb":[[0,2.06,25.89],[2,2,42.01]],"ltp":0.0,"tv":0.0,"id":4520808},{"batb":[[2,1.77,20.69]],"ltp":0.0,"tv":0.0,"id":8284479}]}]}
{"op":"mcm","clk":"1009020183","pt":1580663065456,"mc":[{"id":"1.168236371","rc":[{"batl":[[1,3,0]],"ltp":0.0,"tv":0.0,"id":4520808}]}]}
{"op":"mcm","clk":"1009020839","pt":1580663068835,"mc":[{"id":"1.168236371","rc":[{"batl":[[1,2.84,228.62]],"ltp":0.0,"tv":0.0,"id":4520808}]}]}
{"op":"mcm","clk":"1009027700","pt":1580663107036,"mc":[{"id":"1.168236371","rc":[{"batb":[[0,2.02,27.54],[1,1.01,10.51],[2,2,0]],"batl":[[0,2.84,228.62],[1,2.84,0]],"ltp":0.0,"tv":0.0,"id":4520808},{"batb":[[0,1.77,20.69],[1,1.01,10.51],[2,1.77,0]],"batl":[[0,2.3,309.75],[1,2.3,0]],"ltp":0.0,"tv":0.0,"id":8284479}]}]}
{"op":"mcm","clk":"1009029654","pt":1580663118217,"mc":[{"id":"1.168236371","rc":[{"batb":[[0,2.14,23.29],[1,2.08,25.1],[2,2.04,40.33]],"batl":[[0,2.28,32.77],[1,2.84,228.62]],"ltp":0.0,"tv":0.0,"id":4520808},{"batb":[[0,1.78,53.77],[1,1.77,20.69],[2,1.72,22.9]],"batl":[[0,1.98,42.01],[1,2.3,309.75]],"ltp":0.0,"tv":0.0,"id":8284479}]}]}
{"op":"mcm","clk":"1009031568","pt":1580663129211,"mc":[{"id":"1.168236371","rc":[{"batb":[[0,2.08,25.1],[1,1.01,10.51],[2,2.04,0]],"batl":[[0,2.84,228.62],[1,2.84,0]],"ltp":0.0,"tv":0.0,"id":4520808},{"batb":[[0,1.72,22.74],[1,1.01,10.51],[2,1.72,0]],"batl":[[0,2.3,309.75],[1,2.3,0]],"ltp":0.0,"tv":0.0,"id":8284479}]}]}
{"op":"mcm","clk":"1009037481","pt":1580663162700,"mc":[{"id":"1.168236371","rc":[{"batb":[[0,1.01,10.51],[1,1.01,0]],"ltp":0.0,"tv":0.0,"id":4520808}]}]}
{"op":"mcm","clk":"1009038050","pt":1580663165768,"mc":[{"id":"1.168236371","rc":[{"batb":[[0,2.06,25.34],[1,2.02,68.31],[2,1.01,10.51]],"batl":[[0,2.26,32.77],[1,2.84,228.62]],"ltp":0.0,"tv":0.0,"id":4520808},{"batb":[[0,1.82,19.12],[1,1.8,52.09],[2,1.75,21.48]],"batl":[[0,2,42.01],[1,2.3,309.75]],"ltp":0.0,"tv":0.0,"id":8284479}]}]}
{"op":"mcm","clk":"1009042401","pt":1580663189500,"mc":[{"id":"1.168236371","rc":[{"batb":[[0,2.02,68.08],[1,1.01,10.51],[2,1.01,0]],"ltp":0.0,"tv":0.0,"id":4520808},{"batb":[[0,1.8,52.09],[1,1.75,21.48],[2,1.01,10.51]],"ltp":0.0,"tv":0.0,"id":8284479}]}]}
{"op":"mcm","clk":"1009042615","pt":1580663190908,"mc":[{"id":"1.168236371","rc":[{"batb":[[0,2.02,26.91]],"batl":[[0,2.84,228.62],[1,2.84,0]],"ltp":0.0,"tv":0.0,"id":4520808},{"batb":[[0,1.75,21.48],[1,1.01,10.51],[2,1.01,0]],"batl":[[0,2.3,309.75],[1,2.3,0]],"ltp":0.0,"tv":0.0,"id":8284479}]}]}
{"op":"mcm","clk":"1009043576","pt":1580663196187,"mc":[{"id":"1.168236371","rc":[{"batb":[[1,2,70.26],[2,1.01,10.51]],"batl":[[0,2.22,33.61]],"ltp":0.0,"tv":0.0,"id":4520808},{"batb":[[0,1.85,18.02],[1,1.81,51.25],[2,1.79,19.91]],"batl":[[0,2.02,41.17],[1,2.3,309.75]],"ltp":0.0,"tv":0.0,"id":8284479}]}]}
{"op":"mcm","clk":"1009043790","pt":1580663197435,"mc":[{"id":"1.168236371","rc":[{"batl":[[1,2.7,245.56]],"ltp":0.0,"tv":0.0,"id":4520808}]}]}
{"op":"mcm","clk":"1009046268","pt":1580663211218,"mc":[{"id":"1.168236371","rc":[{"batb":[[0,2,28.25],[1,1.01,10.51],[2,1.01,0]],"batl":[[0,2.7,245.56],[1,2.7,0]],"ltp":0.0,"tv":0.0,"id":4520808},{"batb":[[0,1.79,19.91],[1,1.01,10.51],[2,1.79,0]],"batl":[[0,2.3,309.75],[1,2.3,0]],"ltp":0.0,"tv":0.0,"id":8284479}]}]}
{"op":"mcm","clk":"1009056891","pt":1580663269412,"mc":[{"id":"1.168236371","rc":[{"batl":[[0,2.7,245.56]],"ltp":0.0,"tv":0.0,"id":4520808},{"batl":[[0,2.52,270.1]],"ltp":0.0,"tv":0.0,"id":8284479}]}]}
{"op":"mcm","clk":"1009060366","pt":1580663288161,"mc":[{"id":"1.168236371","rc":[{"batb":[[1,1.98,42.85],[2,1.96,29.9]],"batl":[[0,2.2,34.45],[1,2.7,245.56]],"ltp":0.0,"tv":0.0,"id":4520808},{"batb":[[0,1.88,17.15],[1,1.83,68.98],[2,1.79,19.91]],"batl":[[0,2.04,40.33],[1,2.52,270.1]],"ltp":0.0,"tv":0.0,"id":8284479}]}]}
{"op":"mcm","clk":"1009060419","pt":1580663288439,"mc":[{"id":"1.168236371","rc":[{"batb":[[2,1.01,10.51]],"ltp":0.0,"tv":0.0,"id":8284479}]}]}
{"op":"mcm","clk":"1009063226","pt":1580663304084,"mc":[{"id":"1.168236371","rc":[{"batb":[[0,1.98,42.85],[1,1.96,29.9],[2,1.01,10.51]],"ltp":0.0,"tv":0.0,"id":4520808},{"batb":[[0,1.83,68.98],[1,1.01,10.51],[2,1.01,0]],"ltp":0.0,"tv":0.0,"id":8284479}]}]}
{"op":"mcm","clk":"1009063355","pt":1580663304887,"mc":[{"id":"1.168236371","rc":[{"batb":[[0,1.96,29.9],[1,1.01,10.51],[2,1.01,0]],"batl":[[0,2.7,245.56],[1,2.7,0]],"ltp":0.0,"tv":0.0,"id":4520808},{"batb":[[0,1.83,18.57]],"batl":[[0,2.52,270.1],[1,2.52,0]],"ltp":0.0,"tv":0.0,"id":8284479}]}]}
{"op":"mcm","clk":"1009068174","pt":1580663334136,"mc":[{"id":"1.168236371","rc":[{"batb":[[1,1.93,44.53],[2,1.89,16.76]],"ltp":0.0,"tv":0.0,"id":4520808},{"batb":[[0,1.91,16.29],[1,1.88,47.05],[2,1.87,17.31]],"batl":[[0,2.08,38.65],[1,2.52,270.1]],"ltp":0.0,"tv":0.0,"id":8284479}]}]}
{"op":"mcm","clk":"1009068531","pt":1580663336228,"mc":[{"id":"1.168236371","rc":[{"batl":[[0,2.14,36.13],[1,2.7,245.56]],"ltp":0.0,"tv":0.0,"id":4520808}]}]}
{"op":"mcm","clk":"1009072789","pt":1580663362140,"mc":[{"id":"1.168236371","rc":[{"batb":[[0,1.93,44.53],[1,1.89,16.76],[2,1.01,10.51]],"ltp":0.0,"tv":0.0,"id":4520808},{"batb":[[0,1.88,47.05],[1,1.87,17.31],[2,1.01,10.51]],"ltp":0.0,"tv":0.0,"id":8284479}]}]}
{"op":"mcm","clk":"1009072965","pt":1580663363241,"mc":[{"id":"1.168236371","rc":[{"batb":[[0,1.89,16.76],[1,1.01,10.51],[2,1.01,0]],"batl":[[0,2.7,245.56],[1,2.7,0]],"ltp":0.0,"tv":0.0,"id":4520808},{"batb":[[0,1.87,17.31],[1,1.01,10.51],[2,1.01,0]],"batl":[[0,2.52,270.1],[1,2.52,0]],"ltp":0.0,"tv":0.0,"id":8284479}]}]}
{"op":"mcm","clk":"1009073266","pt":1580663365159,"mc":[{"id":"1.168236371","rc":[{"batb":[[0,1.9,16.6],[1,1.89,16.76],[2,1.01,10.51]],"ltp":0.0,"tv":0.0,"id":4520808}]}]}
{"op":"mcm","clk":"1009073437","pt":1580663366052,"mc":[{"id":"1.168236371","rc":[{"batb":[[1,1.01,10.51],[2,1.01,0]],"ltp":0.0,"tv":0.0,"id":4520808}]}]}
{"op":"mcm","clk":"1009076542","pt":1580663385199,"mc":[{"id":"1.168236371","rc":[{"batb":[[1,1.84,18.25],[2,1.01,10.51]],"ltp":0.0,"tv":0.0,"id":4520808},{"batb":[[0,1.98,29.27],[1,1.93,15.66],[2,1.01,10.51]],"ltp":0.0,"tv":0.0,"id":8284479}]}]}
{"op":"mcm","clk":"1009076730","pt":1580663386210,"mc":[{"id":"1.168236371","rc":[{"batb":[[1,1.89,47.05],[2,1.84,18.25]],"batl":[[0,2.1,37.81],[1,2.7,245.56]],"ltp":0.0,"tv":0.0,"id":4520808},{"batb":[[2,1.92,45.37]],"batl":[[0,2.12,36.97],[1,2.52,270.1]],"ltp":0.0,"tv":0.0,"id":8284479}]}]}
{"op":"mcm","clk":"1009079403","pt":1580663403133,"mc":[{"id":"1.168236371","rc":[{"batb":[[0,1.84,18.25],[1,1.01,10.51],[2,1.84,0]],"batl":[[0,2.7,245.56],[1,2.7,0]],"ltp":0.0,"tv":0.0,"id":4520808},{"batb":[[0,1.93,15.66],[1,1.01,10.51],[2,1.92,0]],"batl":[[0,2.52,270.1],[1,2.52,0]],"ltp":0.0,"tv":0.0,"id":8284479}]}]}
{"op":"mcm","clk":"1009079909","pt":1580663406241,"mc":[{"id":"1.168236371","rc":[{"batb":[[0,1.85,17.94]],"ltp":0.0,"tv":0.0,"id":4520808},{"batb":[[0,1.92,15.89]],"ltp":0.0,"tv":0.0,"id":8284479}]}]}
{"op":"mcm","clk":"1009083844","pt":1580663430245,"mc":[{"id":"1.168236371","rc":[{"batb":[[0,1.85,66.67],[1,1.79,20.06],[2,1.01,10.51]],"batl":[[0,2.06,39.49]],"ltp":0.0,"tv":0.0,"id":4520808},{"batb":[[0,2.02,26.91],[1,1.99,28.72],[2,1.95,43.69]],"batl":[[0,2.16,36.13],[1,2.52,270.1]],"ltp":0.0,"tv":0.0,"id":8284479}]}]}
{"op":"mcm","clk":"1009084119","pt":1580663431945,"mc":[{"id":"1.168236371","rc":[{"batl":[[1,2.52,270.1]],"ltp":0.0,"tv":0.0,"id":4520808}]}]}
{"op":"mcm","clk":"1009087393","pt":1580663452171,"mc":[{"id":"1.168236371","rc":[{"batb":[[0,1.85,48.73]],"ltp":0.0,"tv":0.0,"id":4520808},{"batb":[[0,1.99,28.72],[1,1.95,43.69],[2,1.01,10.51]],"ltp":0.0,"tv":0.0,"id":8284479}]}]}
{"op":"mcm","clk":"1009087520","pt":1580663452983,"mc":[{"id":"1.168236371","rc":[{"batb":[[0,1.79,20.06],[1,1.01,10.51],[2,1.01,0]],"batl":[[0,2.52,270.1],[1,2.52,0]],"ltp":0.0,"tv":0.0,"id":4520808},{"batb":[[1,1.01,10.51],[2,1.01,0]],"batl":[[0,2.52,270.1],[1,2.52,0]],"ltp":0.0,"tv":0.0,"id":8284479}]}]}
{"op":"mcm","clk":"1009087846","pt":1580663455127,"mc":[{"id":"1.168236371","rc":[{"batb":[[0,1.8,19.83]],"ltp":0.0,"tv":0.0,"id":4520808},{"batb":[[0,1.98,29.11]],"ltp":0.0,"tv":0.0,"id":8284479}]}]}
{"op":"mcm","clk":"1009089812","pt":1580663468179,"mc":[{"id":"1.168236371","rc":[{"batb":[[0,1.82,50.41],[1,1.8,19.83],[2,1.74,21.95]],"batl":[[0,2.02,41.17]],"ltp":0.0,"tv":0.0,"id":4520808},{"batb":[[0,2.1,24.31],[1,2.06,25.89],[2,1.99,42.01]],"batl":[[0,2.22,33.61]],"ltp":0.0,"tv":0.0,"id":8284479}]}]}
{"op":"mcm","clk":"1009090092","pt":1580663470291,"mc":[{"id":"1.168236371","rc":[{"batl":[[1,2.4,289.78]],"ltp":0.0,"tv":0.0,"id":4520808},{"batl":[[1,2.84,228.62]],"ltp":0.0,"tv":0.0,"id":8284479}]}]}
{"op":"mcm","clk":"1009091068","pt":1580663477199,"mc":[{"id":"1.168236371","rc":[{"trd":[[2.1,4]],"batb":[[0,2.1,22.31]],"ltp":2.1,"tv":4.0,"id":8284479}],"tv":4.0}]}
{"op":"mcm","clk":"1009091180","pt":1580663477988,"mc":[{"id":"1.168236371","rc":[{"trd":[[2.1,14]],"batb":[[0,2.1,17.31]],"ltp":2.1,"tv":14.0,"id":8284479}],"tv":14.0}]}
{"op":"mcm","clk":"1009091302","pt":1580663478725,"mc":[{"id":"1.168236371","rc":[{"trd":[[2.1,18]],"batb":[[0,2.1,15.31]],"ltp":2.1,"tv":18.0,"id":8284479}],"tv":18.0}]}
{"op":"mcm","clk":"1009091887","pt":1580663482699,"mc":[{"id":"1.168236371","rc":[{"batl":[[0,2.4,289.78],[1,2.4,0]],"ltp":0.0,"tv":0.0,"id":4520808}]}]}
{"op":"mcm","clk":"1009092375","pt":1580663486146,"mc":[{"id":"1.168236371","rc":[{"batl":[[0,2,42.01],[1,2.4,289.78]],"ltp":0.0,"tv":0.0,"id":4520808}]}]}
{"op":"mcm","clk":"1009092809","pt":1580663489055,"mc":[{"id":"1.168236371","rc":[{"batb":[[0,1.74,21.95],[1,1.01,10.51],[2,1.74,0]],"batl":[[0,2.4,289.78],[1,2.4,0]],"ltp":0.0,"tv":0.0,"id":4520808},{"batb":[[0,2.06,25.89],[1,1.01,10.51],[2,1.99,0]],"batl":[[0,2.84,228.62],[1,2.84,0]],"ltp":2.1,"tv":18.0,"id":8284479}]}]}
{"op":"mcm","clk":"1009093130","pt":1580663491038,"mc":[{"id":"1.168236371","rc":[{"batb":[[0,1.75,22.03],[1,1.74,21.95],[2,1.01,10.51]],"ltp":0.0,"tv":0.0,"id":4520808}]}]}
{"op":"mcm","clk":"1009093277","pt":1580663491456,"mc":[{"id":"1.168236371","rc":[{"batb":[[1,1.01,10.51],[2,1.01,0]],"ltp":0.0,"tv":0.0,"id":4520808},{"batb":[[0,2.06,25.73]],"ltp":2.1,"tv":18.0,"id":8284479}]}]}
{"op":"mcm","clk":"1009094033","pt":1580663496159,"mc":[{"id":"1.168236371","rc":[{"batb":[[0,1.83,50.41],[1,1.75,22.03],[2,1.01,10.51]],"batl":[[0,2.04,40.33],[1,2.4,289.78]],"ltp":0.0,"tv":0.0,"id":4520808},{"batb":[[1,1.98,42.85],[2,1.01,10.51]],"batl":[[0,2.2,34.45],[1,2.84,228.62]],"ltp":2.1,"tv":18.0,"id":8284479}]}]}
{"op":"mcm","clk":"1009094126","pt":1580663496740,"mc":[{"id":"1.168236371","rc":[{"batb":[[0,1.84,18.8],[1,1.83,50.41],[2,1.77,21.17]],"batl":[[0,2.4,289.78],[1,2.4,0]],"ltp":0.0,"tv":0.0,"id":4520808},{"batb":[[1,2.02,27.54],[2,1.98,42.85]],"ltp":2.1,"tv":18.0,"id":8284479}]}]}
{"op":"mcm","clk":"1009094307","pt":1580663497956,"mc":[{"id":"1.168236371","rc":[{"batl":[[0,2.02,41.17],[1,2.4,289.78]],"ltp":0.0,"tv":0.0,"id":4520808}]}]}
{"op":"mcm","clk":"1009096146","pt":1580663508754,"mc":[{"id":"1.168236371","rc":[{"batl":[[0,2.84,228.62],[1,2.84,0]],"ltp":2.1,"tv":18.0,"id":8284479}]}]}
{"op":"mcm","clk":"1009096509","pt":1580663511071,"mc":[{"id":"1.168236371","rc":[{"batb":[[0,1.77,21.17],[1,1.01,10.51],[2,1.77,0]],"batl":[[0,2.4,289.78],[1,2.4,0]],"ltp":0.0,"tv":0.0,"id":4520808},{"batb":[[0,2.02,27.07],[1,1.01,10.51],[2,1.98,0]],"ltp":2.1,"tv":18.0,"id":8284479}]}]}
{"op":"mcm","clk":"1009098884","pt":1580663525156,"mc":[{"id":"1.168236371","rc":[{"batb":[[0,1.87,17.94],[1,1.79,20.54],[2,1.01,10.51]],"ltp":0.0,"tv":0.0,"id":4520808},{"batb":[[1,1.98,29.35],[2,1.01,10.51]],"ltp":2.1,"tv":18.0,"id":8284479}]}]}
{"op":"mcm","clk":"1009099033","pt":1580663526182,"mc":[{"id":"1.168236371","rc":[{"batb":[[1,1.83,50.41],[2,1.79,20.54]],"batl":[[0,2.04,40.33],[1,2.4,289.78]],"ltp":0.0,"tv":0.0,"id":4520808},{"batb":[[1,1.98,72.2]],"batl":[[0,2.2,34.45]],"ltp":2.1,"tv":18.0,"id":8284479}]}]}
{"op":"mcm","clk":"1009099206","pt":1580663527216,"mc":[{"id":"1.168236371","rc":[{"batb":[[1,1.84,49.57]],"ltp":0.0,"tv":0.0,"id":4520808},{"batb":[[1,1.98,29.35],[2,1.97,42.85]],"batl":[[0,2.18,35.29]],"ltp":2.1,"tv":18.0,"id":8284479}]}]}
{"op":"mcm","clk":"1009099370","pt":1580663528081,"mc":[{"id":"1.168236371","rc":[{"batl":[[1,2.7,245.56]],"ltp":2.1,"tv":18.0,"id":8284479}]}]}
{"op":"mcm","clk":"1009101962","pt":1580663543890,"mc":[{"id":"1.168236371","rc":[{"batb":[[0,1.84,49.57],[1,1.79,20.54],[2,1.01,10.51]],"ltp":0.0,"tv":0.0,"id":4520808},{"batb":[[0,1.98,29.35],[1,1.97,42.85],[2,1.01,10.51]],"ltp":2.1,"tv":18.0,"id":8284479}]}]}
{"op":"mcm","clk":"1009102128","pt":1580663545017,"mc":[{"id":"1.168236371","rc":[{"batb":[[0,1.79,20.54],[1,1.01,10.51],[2,1.01,0]],"batl":[[0,2.4,289.78],[1,2.4,0]],"ltp":0.0,"tv":0.0,"id":4520808},{"batb":[[1,1.01,10.51],[2,1.01,0]],"batl":[[0,2.7,245.56],[1,2.7,0]],"ltp":2.1,"tv":18.0,"id":8284479}]}]}
{"op":"mcm","clk":"1009103651","pt":1580663554014,"mc":[{"id":"1.168236371","rc":[{"batb":[[0,1.92,16.52],[1,1.86,48.73],[2,1.84,18.73]],"batl":[[0,2.06,39.49],[1,2.4,289.78]],"ltp":0.0,"tv":0.0,"id":4520808},{"batb":[[1,1.95,43.69],[2,1.93,15.66]],"batl":[[0,2.16,36.13],[1,2.7,245.56]],"ltp":2.1,"tv":18.0,"id":8284479}]}]}
{"op":"mcm","clk":"1009106443","pt":1580663569357,"mc":[{"id":"1.168236371","rc":[{"batb":[[0,1.86,48.73],[1,1.84,18.73],[2,1.01,10.51]],"ltp":0.0,"tv":0.0,"id":4520808},{"batb":[[0,1.95,43.69],[1,1.93,15.66],[2,1.01,10.51]],"ltp":2.1,"tv":18.0,"id":8284479}]}]}
{"op":"mcm","clk":"1009106736","pt":1580663571020,"mc":[{"id":"1.168236371","rc":[{"batb":[[0,1.84,18.73],[1,1.01,10.51],[2,1.01,0]],"batl":[[0,2.4,289.78],[1,2.4,0]],"ltp":0.0,"tv":0.0,"id":4520808},{"batb":[[0,1.93,15.66],[1,1.01,10.51],[2,1.01,0]],"batl":[[0,2.7,245.56],[1,2.7,0]],"ltp":2.1,"tv":18.0,"id":8284479}]}]}
{"op":"mcm","clk":"1009106968","pt":1580663572219,"mc":[{"id":"1.168236371","rc":[{"batb":[[0,1.85,18.65],[1,1.84,18.73],[2,1.01,10.51]],"ltp":0.0,"tv":0.0,"id":4520808}]}]}
{"op":"mcm","clk":"1009107071","pt":1580663572843,"mc":[{"id":"1.168236371","rc":[{"batb":[[1,1.01,10.51],[2,1.01,0]],"ltp":0.0,"tv":0.0,"id":4520808}]}]}
{"op":"mcm","clk":"1009109012","pt":1580663584239,"mc":[{"id":"1.168236371","rc":[{"batb":[[0,1.97,15.5],[1,1.9,17.23],[2,1.89,47.05]],"batl":[[0,2.1,37.81],[1,2.4,289.78]],"ltp":0.0,"tv":0.0,"id":4520808},{"batb":[[0,1.93,60.19],[1,1.89,16.92],[2,1.01,10.51]],"batl":[[0,2.14,36.13],[1,2.7,245.56]],"ltp":2.1,"tv":18.0,"id":8284479}]}]}
{"op":"mcm","clk":"1009111886","pt":1580663600987,"mc":[{"id":"1.168236371","rc":[{"batb":[[0,1.9,17.23],[1,1.01,10.51],[2,1.89,0]],"batl":[[0,2.4,289.78],[1,2.4,0]],"ltp":0.0,"tv":0.0,"id":4520808},{"batb":[[0,1.89,16.92],[1,1.01,10.51],[2,1.01,0]],"batl":[[0,2.7,245.56],[1,2.7,0]],"ltp":2.1,"tv":18.0,"id":8284479}]}]}
{"op":"mcm","clk":"1009114174","pt":1580663615092,"mc":[{"id":"1.168236371","rc":[{"batb":[[1,1.82,19.59],[2,1.01,10.51]],"ltp":0.0,"tv":0.0,"id":4520808},{"batb":[[0,2,28.17],[1,1.95,30.29],[2,1.01,10.51]],"ltp":2.1,"tv":18.0,"id":8284479}]}]}
{"op":"mcm","clk":"1009114324","pt":1580663615992,"mc":[{"id":"1.168236371","rc":[{"batb":[[1,1.86,48.73],[2,1.82,19.59]],"batl":[[0,2.04,40.33],[1,2.4,289.78]],"ltp":0.0,"tv":0.0,"id":4520808},{"batb":[[1,1.96,43.69],[2,1.95,30.29]],"batl":[[0,2.18,35.29],[1,2.7,245.56]],"ltp":2.1,"tv":18.0,"id":8284479}]}]}
{"op":"mcm","clk":"1009118383","pt":1580663640117,"mc":[{"id":"1.168236371","rc":[{"batb":[[0,1.86,48.73],[1,1.82,19.59],[2,1.01,10.51]],"ltp":0.0,"tv":0.0,"id":4520808},{"batb":[[0,1.96,43.69],[1,1.95,30.29],[2,1.01,10.51]],"ltp":2.1,"tv":18.0,"id":8284479}]}]}
{"op":"mcm","clk":"1009118529","pt":1580663641033,"mc":[{"id":"1.168236371","rc":[{"batb":[[0,1.82,19.59],[1,1.01,10.51],[2,1.01,0]],"batl":[[0,2.4,289.78],[1,2.4,0]],"ltp":0.0,"tv":0.0,"id":4520808},{"batb":[[0,1.95,30.29],[1,1.01,10.51],[2,1.01,0]],"batl":[[0,2.7,245.56],[1,2.7,0]],"ltp":2.1,"tv":18.0,"id":8284479}]}]}
{"op":"mcm","clk":"1009118883","pt":1580663643108,"mc":[{"id":"1.168236371","rc":[{"batb":[[0,1.83,19.2]],"ltp":0.0,"tv":0.0,"id":4520808},{"batb":[[0,1.94,15.5]],"ltp":2.1,"tv":18.0,"id":8284479}]}]}
{"op":"mcm","clk":"1009120017","pt":1580663650112,"mc":[{"id":"1.168236371","rc":[{"batb":[[0,1.96,15.74],[1,1.88,17.7],[2,1.87,47.89]],"batl":[[0,2.08,38.65],[1,2.4,289.78]],"ltp":0.0,"tv":0.0,"id":4520808},{"batb":[[0,1.95,43.69],[1,1.94,15.5],[2,1.9,16.44]],"batl":[[0,2.16,36.13],[1,2.7,245.56]],"ltp":2.1,"tv":18.0,"id":8284479}]}]}
{"op":"mcm","clk":"1009122811","pt":1580663667035,"mc":[{"id":"1.168236371","rc":[{"batb":[[0,1.88,17.7],[1,1.01,10.51],[2,1.87,0]],"batl":[[0,2.4,289.78],[1,2.4,0]],"ltp":0.0,"tv":0.0,"id":4520808},{"batb":[[0,1.9,16.44],[1,1.01,10.51],[2,1.9,0]],"batl":[[0,2.7,245.56],[1,2.7,0]],"ltp":2.1,"tv":18.0,"id":8284479}]}]}
{"op":"mcm","clk":"1009125877","pt":1580663685957,"mc":[{"id":"1.168236371","rc":[{"batb":[[1,1.84,49.57],[2,1.01,10.51]],"batl":[[0,2.02,41.17],[1,2.4,289.78]],"ltp":0.0,"tv":0.0,"id":4520808},{"batb":[[0,1.97,42.85],[1,1.9,16.44],[2,1.01,10.51]],"batl":[[0,2.2,34.45],[1,2.7,245.56]],"ltp":2.1,"tv":18.0,"id":8284479}]}]}
{"op":"mcm","clk":"1009126056","pt":1580663686877,"mc":[{"id":"1.168236371","rc":[{"batb":[[2,1.8,20.14]],"ltp":0.0,"tv":0.0,"id":4520808},{"batb":[[0,2.02,27.3],[1,1.97,72.43]],"ltp":2.1,"tv":18.0,"id":8284479}]}]}
{"op":"mcm","clk":"1009129259","pt":1580663705144,"mc":[{"id":"1.168236371","rc":[{"batb":[[0,1.8,20.14],[1,1.01,10.51],[2,1.8,0]],"batl":[[0,2.4,289.78],[1,2.4,0]],"ltp":0.0,"tv":0.0,"id":4520808},{"batb":[[0,1.97,29.58],[1,1.01,10.51],[2,1.01,0]],"batl":[[0,2.7,245.56],[1,2.7,0]],"ltp":2.1,"tv":18.0,"id":8284479}]}]}
{"op":"mcm","clk":"1009129747","pt":1580663707968,"mc":[{"id":"1.168236371","rc":[{"batb":[[0,1.81,19.91]],"ltp":0.0,"tv":0.0,"id":4520808},{"batb":[[0,1.96,29.9]],"ltp":2.1,"tv":18.0,"id":8284479}]}]}
{"op":"mcm","clk":"1009134106","pt":1580663733186,"mc":[{"id":"1.168236371","rc":[{"batb":[[0,1.93,16.21],[1,1.86,18.25],[2,1.85,139.17]],"ltp":0.0,"tv":0.0,"id":4520808},{"batb":[[1,1.92,15.97],[2,1.01,10.51]],"ltp":2.1,"tv":18.0,"id":8284479}]}]}
{"op":"mcm","clk":"1009134230","pt":1580663733974,"mc":[{"id":"1.168236371","rc":[{"batb":[[2,1.85,48.73]],"batl":[[0,2.06,39.49],[1,2.4,289.78]],"ltp":0.0,"tv":0.0,"id":4520808},{"batb":[[1,1.95,43.69],[2,1.92,15.97]],"batl":[[0,2.18,35.29],[1,2.7,245.56]],"ltp":2.1,"tv":18.0,"id":8284479}]}]}
{"op":"mcm","clk":"1009137713","pt":1580663755144,"mc":[{"id":"1.168236371","rc":[{"batb":[[0,1.86,18.25],[1,1.01,10.51],[2,1.85,0]],"batl":[[0,2.4,289.78],[1,2.4,0]],"ltp":0.0,"tv":0.0,"id":4520808},{"batb":[[0,1.92,15.97],[1,1.01,10.51],[2,1.92,0]],"batl":[[0,2.7,245.56],[1,2.7,0]],"ltp":2.1,"tv":18.0,"id":8284479}]}]}
{"op":"mcm","clk":"1009139164","pt":1580663763211,"mc":[{"id":"1.168236371","rc":[{"batb":[[0,1.97,30.29],[1,1.94,16.05],[2,1.01,10.51]],"ltp":0.0,"tv":0.0,"id":4520808},{"batb":[[1,1.86,17.78],[2,1.01,10.51]],"ltp":2.1,"tv":18.0,"id":8284479}]}]}
{"op":"mcm","clk":"1009139305","pt":1580663764005,"mc":[{"id":"1.168236371","rc":[{"batb":[[2,1.89,47.05]],"batl":[[0,2.1,37.81],[1,2.4,289.78]],"ltp":0.0,"tv":0.0,"id":4520808},{"batb":[[1,1.91,45.37],[2,1.86,17.78]],"batl":[[0,2.14,36.13],[1,2.7,245.56]],"ltp":2.1,"tv":18.0,"id":8284479}]}]}
{"op":"mcm","clk":"1009142442","pt":1580663781968,"mc":[{"id":"1.168236371","rc":[{"batb":[[2,1.85,17.86]],"ltp":2.1,"tv":18.0,"id":8284479}]}]}
{"op":"mcm","clk":"1009143724","pt":1580663790107,"mc":[{"id":"1.168236371","rc":[{"batb":[[2,1.86,17.78]],"ltp":2.1,"tv":18.0,"id":8284479}]}]}
{"op":"mcm","clk":"1009144991","pt":1580663797694,"mc":[{"id":"1.168236371","rc":[{"batb":[[0,1.96,30.69],[1,1.93,16.37]],"ltp":0.0,"tv":0.0,"id":4520808},{"batb":[[0,1.93,15.82],[2,1.86,17.55]],"ltp":2.1,"tv":18.0,"id":8284479}]}]}
{"op":"mcm","clk":"1009149315","pt":1580663824122,"mc":[{"id":"1.168236371","rc":[{"batb":[[0,1.97,15.42]],"ltp":0.0,"tv":0.0,"id":4520808},{"batb":[[2,1.87,17.47]],"ltp":2.1,"tv":18.0,"id":8284479}]}]}
{"op":"mcm","clk":"1009149568","pt":1580663825922,"mc":[{"id":"1.168236371","rc":[{"batl":[[1,2.4,0]],"ltp":0.0,"tv":0.0,"id":4520808},{"batl":[[1,2.7,0]],"ltp":2.1,"tv":18.0,"id":8284479}]}]}
{"op":"mcm","clk":"1009150200","pt":1580663830045,"mc":[{"id":"1.168236371","rc":[{"batl":[[1,2.7,245.56]],"ltp":0.0,"tv":0.0,"id":4520808},{"batl":[[1,2.52,270.1]],"ltp":2.1,"tv":18.0,"id":8284479}]}]}
{"op":"mcm","clk":"1009154558","pt":1580663856164,"mc":[{"id":"1.168236371","rc":[{"batb":[[0,1.93,16.37],[1,1.89,47.05],[2,1.01,10.51]],"ltp":0.0,"tv":0.0,"id":4520808},{"batb":[[0,1.91,45.37],[1,1.87,17.47],[2,1.01,10.51]],"ltp":2.1,"tv":18.0,"id":8284479}]}]}
{"op":"mcm","clk":"1009154717","pt":1580663857171,"mc":[{"id":"1.168236371","rc":[{"batb":[[1,1.01,10.51],[2,1.01,0]],"batl":[[0,2.7,245.56],[1,2.7,0]],"ltp":0.0,"tv":0.0,"id":4520808},{"batb":[[0,1.87,17.47],[1,1.01,10.51],[2,1.01,0]],"batl":[[0,2.52,270.1],[1,2.52,0]],"ltp":2.1,"tv":18.0,"id":8284479}]}]}
{"op":"mcm","clk":"1009155039","pt":1580663858978,"mc":[{"id":"1.168236371","rc":[{"batb":[[0,1.92,16.6]],"ltp":0.0,"tv":0.0,"id":4520808},{"batb":[[0,1.87,17.31]],"ltp":2.1,"tv":18.0,"id":8284479}]}]}
{"op":"mcm","clk":"1009157865","pt":1580663876058,"mc":[{"id":"1.168236371","rc":[{"batb":[[1,1.88,64.6],[2,1.01,10.51]],"batl":[[0,2.08,38.65],[1,2.7,245.56]],"ltp":0.0,"tv":0.0,"id":4520808},{"batb":[[0,1.98,29.19],[1,1.93,44.53],[2,1.92,16.05]],"batl":[[0,2.16,36.13],[1,2.52,270.1]],"ltp":2.1,"tv":18.0,"id":8284479}]}]}
{"op":"mcm","clk":"1009160377","pt":1580663891204,"mc":[{"id":"1.168236371","rc":[{"batb":[[0,1.88,17.55],[1,1.01,10.51],[2,1.01,0]],"batl":[[0,2.7,245.56],[1,2.7,0]],"ltp":0.0,"tv":0.0,"id":4520808},{"batb":[[0,1.92,16.05],[1,1.01,10.51],[2,1.92,0]],"batl":[[0,2.52,270.1],[1,2.52,0]],"ltp":2.1,"tv":18.0,"id":8284479}]}]}
{"op":"mcm","clk":"1009160886","pt":1580663894194,"mc":[{"id":"1.168236371","rc":[{"batb":[[0,1.89,17.55]],"ltp":0.0,"tv":0.0,"id":4520808}]}]}
{"op":"mcm","clk":"1009162659","pt":1580663905240,"mc":[{"id":"1.168236371","rc":[{"batb":[[0,1.97,30.21],[1,1.95,15.89],[2,1.01,10.51]],"ltp":0.0,"tv":0.0,"id":4520808},{"batb":[[1,1.84,18.33],[2,1.01,10.51]],"ltp":2.1,"tv":18.0,"id":8284479}]}]}
{"op":"mcm","clk":"1009162771","pt":1580663906047,"mc":[{"id":"1.168236371","rc":[{"batb":[[2,1.91,45.37]],"batl":[[0,2.12,36.97],[1,2.7,245.56]],"ltp":0.0,"tv":0.0,"id":4520808},{"batb":[[1,1.9,46.21],[2,1.84,18.33]],"batl":[[0,2.12,36.97],[1,2.52,270.1]],"ltp":2.1,"tv":18.0,"id":8284479}]}]}
{"op":"mcm","clk":"1009165808","pt":1580663925150,"mc":[{"id":"1.168236371","rc":[{"batb":[[0,1.95,15.89],[1,1.01,10.51],[2,1.91,0]],"batl":[[0,2.7,245.56],[1,2.7,0]],"ltp":0.0,"tv":0.0,"id":4520808},{"batb":[[0,1.84,18.33],[1,1.01,10.51],[2,1.84,0]],"batl":[[0,2.52,270.1],[1,2.52,0]],"ltp":2.1,"tv":18.0,"id":8284479}]}]}
{"op":"mcm","clk":"1009166891","pt":1580663932170,"mc":[{"id":"1.168236371","rc":[{"batb":[[1,1.9,46.21],[2,1.01,10.51]],"batl":[[0,2.1,37.81],[1,2.7,245.56]],"ltp":0.0,"tv":0.0,"id":4520808},{"batb":[[0,1.92,45.37],[1,1.84,18.33],[2,1.01,10.51]],"batl":[[0,2.12,36.97],[1,2.52,270.1]],"ltp":2.1,"tv":18.0,"id":8284479}]}]}
{"op":"mcm","clk":"1009167010","pt":1580663932952,"mc":[{"id":"1.168236371","rc":[{"batb":[[1,1.91,16.84],[2,1.89,47.05]],"ltp":0.0,"tv":0.0,"id":4520808},{"batb":[[0,1.95,30.61],[1,1.92,45.37],[2,1.88,17]],"ltp":2.1,"tv":18.0,"id":8284479}]}]}
{"op":"mcm","clk":"1009169266","pt":1580663947593,"mc":[{"id":"1.168236371","rc":[{"batb":[[0,1.91,16.84],[1,1.89,47.05],[2,1.01,10.51]],"ltp":0.0,"tv":0.0,"id":4520808},{"batb":[[0,1.92,45.37],[1,1.88,17],[2,1.01,10.51]],"ltp":2.1,"tv":18.0,"id":8284479}]}]}
{"op":"mcm","clk":"1009169515","pt":1580663949100,"mc":[{"id":"1.168236371","rc":[{"batb":[[1,1.01,10.51],[2,1.01,0]],"batl":[[0,2.7,245.56],[1,2.7,0]],"ltp":0.0,"tv":0.0,"id":4520808},{"batb":[[0,1.88,17],[1,1.01,10.51],[2,1.01,0]],"batl":[[0,2.52,270.1],[1,2.52,0]],"ltp":2.1,"tv":18.0,"id":8284479}]}]}
{"op":"mcm","clk":"1009174826","pt":1580663981132,"mc":[{"id":"1.168236371","rc":[{"batb":[[1,1.87,17.94],[2,1.01,10.51]],"ltp":0.0,"tv":0.0,"id":4520808},{"batb":[[0,1.99,28.8],[1,1.93,15.82],[2,1.88,17]],"ltp":2.1,"tv":18.0,"id":8284479}]}]}
{"op":"mcm","clk":"1009174984","pt":1580663982135,"mc":[{"id":"1.168236371","rc":[{"batb":[[1,1.87,65.83]],"batl":[[0,2.08,38.65],[1,2.7,245.56]],"ltp":0.0,"tv":0.0,"id":4520808},{"batb":[[1,1.93,60.35],[2,1.01,10.51]],"batl":[[0,2.16,36.13],[1,2.52,270.1]],"ltp":2.1,"tv":18.0,"id":8284479}]}]}
{"op":"mcm","clk":"1009178379","pt":1580664003747,"mc":[{"id":"1.168236371","rc":[{"batb":[[0,1.87,65.83],[1,1.01,10.51],[2,1.01,0]],"ltp":0.0,"tv":0.0,"id":4520808},{"batb":[[0,1.93,60.35],[1,1.01,10.51],[2,1.01,0]],"ltp":2.1,"tv":18.0,"id":8284479}]}]}
{"op":"mcm","clk":"1009178595","pt":1580664005168,"mc":[{"id":"1.168236371","rc":[{"batb":[[0,1.87,17.94]],"batl":[[0,2.7,245.56],[1,2.7,0]],"ltp":0.0,"tv":0.0,"id":4520808},{"batb":[[0,1.93,15.82]],"batl":[[0,2.52,270.1],[1,2.52,0]],"ltp":2.1,"tv":18.0,"id":8284479}]}]}
{"op":"mcm","clk":"1009179951","pt":1580664014075,"mc":[{"id":"1.168236371","rc":[{"batb":[[0,1.91,45.37],[1,1.87,17.94],[2,1.01,10.51]],"batl":[[0,2.12,36.97],[1,2.7,245.56]],"ltp":0.0,"tv":0.0,"id":4520808},{"batb":[[1,1.91,45.37],[2,1.01,10.51]],"batl":[[0,2.12,36.97],[1,2.52,270.1]],"ltp":2.1,"tv":18.0,"id":8284479}]}]}
{"op":"mcm","clk":"1009180131","pt":1580664015069,"mc":[{"id":"1.168236371","rc":[{"batb":[[0,1.96,30.76],[1,1.92,16.6],[2,1.91,45.37]],"ltp":0.0,"tv":0.0,"id":4520808},{"batb":[[2,1.86,17.55]],"ltp":2.1,"tv":18.0,"id":8284479}]}]}
{"op":"mcm","clk":"1009183121","pt":1580664035910,"mc":[{"id":"1.168236371","rc":[{"batb":[[0,1.92,16.6],[1,1.91,45.37],[2,1.01,10.51]],"ltp":0.0,"tv":0.0,"id":4520808},{"batb":[[0,1.91,45.37],[1,1.86,17.55],[2,1.01,10.51]],"ltp":2.1,"tv":18.0,"id":8284479}]}]}
{"op":"mcm","clk":"1009183324","pt":1580664037191,"mc":[{"id":"1.168236371","rc":[{"batb":[[1,1.01,10.51],[2,1.01,0]],"batl":[[0,2.7,245.56],[1,2.7,0]],"ltp":0.0,"tv":0.0,"id":4520808},{"batb":[[0,1.86,17.55],[1,1.01,10.51],[2,1.01,0]],"batl":[[0,2.52,270.1],[1,2.52,0]],"ltp":2.1,"tv":18.0,"id":8284479}]}]}
{"op":"mcm","clk":"1009185009","pt":1580664050226,"mc":[{"id":"1.168236371","rc":[{"batb":[[1,1.88,47.05],[2,1.84,18.8]],"batl":[[0,2.08,38.65],[1,2.7,245.56]],"ltp":0.0,"tv":0.0,"id":4520808},{"batb":[[0,1.98,29.27],[1,1.94,44.53],[2,1.93,15.66]],"batl":[[0,2.16,36.13],[1,2.52,270.1]],"ltp":2.1,"tv":18.0,"id":8284479}]}]}
{"op":"mcm","clk":"1009189420","pt":1580664080126,"mc":[{"id":"1.168236371","rc":[{"batb":[[0,1.88,47.05],[1,1.84,18.8],[2,1.01,10.51]],"ltp":0.0,"tv":0.0,"id":4520808},{"batb":[[0,1.94,44.53],[1,1.93,15.66],[2,1.01,10.51]],"ltp":2.1,"tv":18.0,"id":8284479}]}]}
{"op":"mcm","clk":"1009189684","pt":1580664082057,"mc":[{"id":"1.168236371","rc":[{"batb":[[0,1.84,18.8],[1,1.01,10.51],[2,1.01,0]],"batl":[[0,2.7,245.56],[1,2.7,0]],"ltp":0.0,"tv":0.0,"id":4520808},{"batb":[[0,1.93,15.66],[1,1.01,10.51],[2,1.01,0]],"batl":[[0,2.52,270.1],[1,2.52,0]],"ltp":2.1,"tv":18.0,"id":8284479}]}]}
{"op":"mcm","clk":"1009189872","pt":1580664083228,"mc":[{"id":"1.168236371","rc":[{"batb":[[0,1.85,18.65]],"ltp":0.0,"tv":0.0,"id":4520808}]}]}
{"op":"mcm","clk":"1009193515","pt":1580664108161,"mc":[{"id":"1.168236371","rc":[{"batb":[[1,1.84,49.57],[2,1.78,20.85]],"batl":[[0,2.04,40.33],[1,2.7,245.56]],"ltp":0.0,"tv":0.0,"id":4520808},{"batb":[[0,2.06,25.97],[1,2,28.4],[2,1.98,42.85]],"batl":[[0,2.2,34.45],[1,2.52,270.1]],"ltp":2.1,"tv":18.0,"id":8284479}]}]}
{"op":"mcm","clk":"1009195779","pt":1580664123180,"mc":[{"id":"1.168236371","rc":[{"batb":[[1,1.78,20.85],[2,1.01,10.51]],"batl":[[0,2.7,245.56],[1,2.7,0]],"ltp":0.0,"tv":0.0,"id":4520808},{"batb":[[2,1.01,10.51]],"batl":[[0,2.52,270.1],[1,2.52,0]],"ltp":2.1,"tv":18.0,"id":8284479}]}]}
{"op":"mcm","clk":"1009195939","pt":1580664124187,"mc":[{"id":"1.168236371","rc":[{"batb":[[0,1.78,20.85],[1,1.01,10.51],[2,1.01,0]],"ltp":0.0,"tv":0.0,"id":4520808},{"batb":[[0,2,28.4],[1,1.01,10.51],[2,1.01,0]],"ltp":2.1,"tv":18.0,"id":8284479}]}]}
{"op":"mcm","clk":"1009196301","pt":1580664126475,"mc":[{"id":"1.168236371","rc":[{"batb":[[0,1.79,20.54]],"ltp":0.0,"tv":0.0,"id":4520808},{"batb":[[0,1.98,28.88]],"ltp":2.1,"tv":18.0,"id":8284479}]}]}
{"op":"mcm","clk":"1009200912","pt":1580664156165,"mc":[{"id":"1.168236371","rc":[{"batb":[[0,1.79,73.47]],"batl":[[0,2,42.01]],"ltp":0.0,"tv":0.0,"id":4520808},{"batb":[[0,2.02,41.17],[1,1.98,28.88],[2,1.01,10.51]],"batl":[[0,2.26,32.77],[1,2.52,270.1]],"ltp":2.1,"tv":18.0,"id":8284479}]}]}
{"op":"mcm","clk":"1009201061","pt":1580664157073,"mc":[{"id":"1.168236371","rc":[{"batb":[[1,1.73,23.21],[2,1.01,10.51]],"ltp":0.0,"tv":0.0,"id":4520808},{"batb":[[0,2.12,23.37],[1,2.06,25.41],[2,2.02,41.17]],"ltp":2.1,"tv":18.0,"id":8284479}]}]}
{"op":"mcm","clk":"1009201480","pt":1580664159824,"mc":[{"id":"1.168236371","rc":[{"batl":[[1,2.52,270.1]],"ltp":0.0,"tv":0.0,"id":4520808}]}]}
{"op":"mcm","clk":"1009203286","pt":1580664171057,"mc":[{"id":"1.168236371","rc":[{"batl":[[0,2.52,270.1],[1,2.52,0]],"ltp":0.0,"tv":0.0,"id":4520808}]}]}
{"op":"mcm","clk":"1009203752","pt":1580664174177,"mc":[{"id":"1.168236371","rc":[{"batl":[[0,1.99,42.01],[1,2.52,270.1]],"ltp":0.0,"tv":0.0,"id":4520808}]}]}
{"op":"mcm","clk":"1009204336","pt":1580664178147,"mc":[{"id":"1.168236371","rc":[{"batb":[[0,1.79,52.93]],"ltp":0.0,"tv":0.0,"id":4520808},{"batb":[[0,2.06,25.41],[1,2.02,41.17],[2,1.01,10.51]],"ltp":2.1,"tv":18.0,"id":8284479}]}]}
{"op":"mcm","clk":"1009204487","pt":1580664179173,"mc":[{"id":"1.168236371","rc":[{"batb":[[0,1.73,23.21],[1,1.01,10.51],[2,1.01,0]],"batl":[[0,2.52,270.1],[1,2.52,0]],"ltp":0.0,"tv":0.0,"id":4520808},{"batb":[[1,1.01,10.51],[2,1.01,0]],"batl":[[0,2.52,270.1],[1,2.52,0]],"ltp":2.1,"tv":18.0,"id":8284479}]}]}
{"op":"mcm","clk":"1009204819","pt":1580664181202,"mc":[{"id":"1.168236371","rc":[{"batb":[[0,1.72,23.29]],"ltp":0.0,"tv":0.0,"id":4520808},{"batb":[[0,2.08,25.26]],"ltp":2.1,"tv":18.0,"id":8284479}]}]}
{"op":"mcm","clk":"1009210780","pt":1580664220245,"mc":[{"id":"1.168236371","rc":[{"batb":[[0,1.76,54.61],[1,1.72,23.29],[2,1.67,26.04]],"batl":[[0,1.95,42.01]],"ltp":0.0,"tv":0.0,"id":4520808},{"batb":[[0,2.24,20.38],[1,2.18,21.95],[2,2.06,39.49]],"batl":[[0,2.32,31.09]],"ltp":2.1,"tv":18.0,"id":8284479}]}]}
{"op":"mcm","clk":"1009211071","pt":1580664222158,"mc":[{"id":"1.168236371","rc":[{"batl":[[1,2.4,289.78]],"ltp":0.0,"tv":0.0,"id":4520808},{"batl":[[1,2.84,228.62]],"ltp":2.1,"tv":18.0,"id":8284479}]}]}
{"op":"mcm","clk":"1009217705","pt":1580664263989,"mc":[{"id":"1.168236371","rc":[{"batl":[[0,2.4,289.78],[1,2.4,0]],"ltp":0.0,"tv":0.0,"id":4520808},{"batb":[[2,1.01,10.51]],"ltp":2.1,"tv":18.0,"id":8284479}]}]}
{"op":"mcm","clk":"1009217884","pt":1580664265195,"mc":[{"id":"1.168236371","rc":[{"batb":[[0,1.67,26.04],[1,1.01,10.51],[2,1.67,0]],"ltp":0.0,"tv":0.0,"id":4520808},{"batb":[[0,2.18,21.95],[1,1.01,10.51],[2,1.01,0]],"batl":[[0,2.84,228.62],[1,2.84,0]],"ltp":2.1,"tv":18.0,"id":8284479}]}]}
{"op":"mcm","clk":"1009218877","pt":1580664271196,"mc":[{"id":"1.168236371","rc":[{"batb":[[0,1.75,22.11],[1,1.68,25.34],[2,1.01,10.51]],"ltp":0.0,"tv":0.0,"id":4520808},{"batb":[[0,2.18,21.56],[1,2.12,23.76],[2,1.01,10.51]],"ltp":2.1,"tv":18.0,"id":8284479}]}]}
{"op":"mcm","clk":"1009219045","pt":1580664272212,"mc":[{"id":"1.168236371","rc":[{"batb":[[0,1.76,54.61],[1,1.75,22.11],[2,1.68,25.34]],"batl":[[0,1.95,42.01],[1,2.4,289.78]],"ltp":0.0,"tv":0.0,"id":4520808},{"batb":[[2,2.06,39.49]],"batl":[[0,2.32,31.09],[1,2.84,228.62]],"ltp":2.1,"tv":18.0,"id":8284479}]}]}
{"op":"mcm","clk":"1009219090","pt":1580664272541,"mc":[{"id":"1.168236371","rc":[{"batl":[[0,2.3,31.93]],"ltp":2.1,"tv":18.0,"id":8284479}]}]}
{"op":"mcm","clk":"1009220860","pt":1580664283219,"mc":[{"id":"1.168236371","rc":[{"batb":[[0,1.68,25.34],[1,1.01,10.51],[2,1.68,0]],"batl":[[0,2.4,289.78],[1,2.4,0]],"ltp":0.0,"tv":0.0,"id":4520808},{"batb":[[0,2.12,23.76],[1,1.01,10.51],[2,2.06,0]],"batl":[[0,2.84,228.62],[1,2.84,0]],"ltp":2.1,"tv":18.0,"id":8284479}]}]}
{"op":"mcm","clk":"1009222941","pt":1580664296239,"mc":[{"id":"1.168236371","rc":[{"batb":[[0,1.68,86.67]],"batl":[[0,1.85,42.01],[1,2.4,289.78]],"ltp":0.0,"tv":0.0,"id":4520808},{"batb":[[0,2.18,35.29],[1,2.12,23.76],[2,1.01,10.51]],"batl":[[0,2.48,27.73],[1,2.84,228.62]],"ltp":2.1,"tv":18.0,"id":8284479}]}]}
{"op":"mcm","clk":"1009223094","pt":1580664297145,"mc":[{"id":"1.168236371","rc":[{"batb":[[1,1.65,26.83],[2,1.01,10.51]],"batl":[[0,2.4,289.78],[1,2.4,0]],"ltp":0.0,"tv":0.0,"id":4520808},{"batb":[[0,2.3,18.65],[1,2.2,21.17],[2,2.18,35.29]],"ltp":2.1,"tv":18.0,"id":8284479}]}]}
{"op":"mcm","clk":"1009223337","pt":1580664298635,"mc":[{"id":"1.168236371","rc":[{"batl":[[0,1.84,42.01],[1,2.4,289.78]],"ltp":0.0,"tv":0.0,"id":4520808}]}]}
{"op":"mcm","clk":"1009227147","pt":1580664323183,"mc":[{"id":"1.168236371","rc":[{"batb":[[0,1.68,61.33],[1,1.67,25.89],[2,1.64,27.46]],"ltp":0.0,"tv":0.0,"id":4520808},{"batb":[[0,2.32,18.18],[1,2.22,20.61]],"ltp":2.1,"tv":18.0,"id":8284479}]}]}
{"op":"mcm","clk":"1009227588","pt":1580664326179,"mc":[{"id":"1.168236371","rc":[{"batb":[[0,1.68,453.69]],"ltp":0.0,"tv":0.0,"id":4520808}]}]}
{"op":"mcm","clk":"1009239757","pt":1580664412200,"mc":[{"id":"1.168236371","rc":[{"batb":[[0,1.68,61.33],[1,1.64,27.46],[2,1.01,10.51]],"ltp":0.0,"tv":0.0,"id":4520808},{"batb":[[0,2.22,20.61],[1,2.18,35.29],[2,1.01,10.51]],"ltp":2.1,"tv":18.0,"id":8284479}]}]}
{"op":"mcm","clk":"1009239992","pt":1580664414092,"mc":[{"id":"1.168236371","rc":[{"batb":[[0,1.64,27.46],[1,1.01,10.51],[2,1.01,0]],"batl":[[0,2.4,289.78],[1,2.4,0]],"ltp":0.0,"tv":0.0,"id":4520808},{"batb":[[1,1.01,10.51],[2,1.01,0]],"batl":[[0,2.84,228.62],[1,2.84,0]],"ltp":2.1,"tv":18.0,"id":8284479}]}]}
{"op":"mcm","clk":"1009241969","pt":1580664428219,"mc":[{"id":"1.168236371","rc":[{"batb":[[0,1.66,63.01],[1,1.64,27.46],[2,1.01,10.51]],"batl":[[0,1.83,42.01]],"ltp":0.0,"tv":0.0,"id":4520808},{"batb":[[0,2.22,54.22]],"batl":[[0,2.5,27.73],[1,2.84,228.62]],"ltp":2.1,"tv":18.0,"id":8284479}]}]}
{"op":"mcm","clk":"1009242065","pt":1580664428837,"mc":[{"id":"1.168236371","rc":[{"batb":[[2,1.61,29.19]],"ltp":0.0,"tv":0.0,"id":4520808},{"batb":[[0,2.38,17],[1,2.26,19.43],[2,2.22,33.61]],"ltp":2.1,"tv":18.0,"id":8284479}]}]}
{"op":"mcm","clk":"1009242238","pt":1580664430029,"mc":[{"id":"1.168236371","rc":[{"batl":[[1,2.3,309.75]],"ltp":0.0,"tv":0.0,"id":4520808}]}]}
{"op":"mcm","clk":"1009244093","pt":1580664442171,"mc":[{"id":"1.168236371","rc":[{"batb":[[0,1.61,29.19],[1,1.01,10.51],[2,1.61,0]],"batl":[[0,2.3,309.75],[1,2.3,0]],"ltp":0.0,"tv":0.0,"id":4520808},{"batb":[[0,2.26,19.43],[1,1.01,10.51],[2,2.22,0]],"batl":[[0,2.84,228.62],[1,2.84,0]],"ltp":2.1,"tv":18.0,"id":8284479}]}]}
{"op":"mcm","clk":"1009246082","pt":1580664455934,"mc":[{"id":"1.168236371","rc":[{"batb":[[1,1.58,31.16],[2,1.01,10.51]],"ltp":0.0,"tv":0.0,"id":4520808},{"batb":[[0,2.44,15.89],[1,2.34,17.94],[2,2.26,19.43]],"ltp":2.1,"tv":18.0,"id":8284479}]}]}
{"op":"mcm","clk":"1009246246","pt":1580664457051,"mc":[{"id":"1.168236371","rc":[{"batb":[[0,1.65,63.85],[1,1.61,29.19],[2,1.58,31.16]],"batl":[[0,1.81,42.01],[1,2.3,309.75]],"ltp":0.0,"tv":0.0,"id":4520808},{"batb":[[2,2.26,32.77]],"batl":[[0,2.54,26.89],[1,2.84,228.62]],"ltp":2.1,"tv":18.0,"id":8284479}]}]}
{"op":"mcm","clk":"1009248998","pt":1580664475335,"mc":[{"id":"1.168236371","rc":[{"batb":[[0,1.58,31.16],[1,1.01,10.51],[2,1.58,0]],"batl":[[0,2.3,309.75],[1,2.3,0]],"ltp":0.0,"tv":0.0,"id":4520808},{"batb":[[0,2.34,17.94],[1,1.01,10.51],[2,2.26,0]],"batl":[[0,2.84,228.62],[1,2.84,0]],"ltp":2.1,"tv":18.0,"id":8284479}]}]}
{"op":"mcm","clk":"1009252924","pt":1580664501051,"mc":[{"id":"1.168236371","rc":[{"batb":[[1,1.56,32.81],[2,1.01,10.51]],"ltp":0.0,"tv":0.0,"id":4520808},{"batb":[[0,2.52,14.71],[1,2.38,16.92],[2,1.01,10.51]],"ltp":2.1,"tv":18.0,"id":8284479}]}]}
{"op":"mcm","clk":"1009253270","pt":1580664502938,"mc":[{"id":"1.168236371","rc":[{"batb":[[0,1.63,66.38],[1,1.58,31.16],[2,1.56,32.81]],"batl":[[0,1.79,42.01],[1,2.3,309.75]],"ltp":0.0,"tv":0.0,"id":4520808},{"batb":[[2,2.28,32.77]],"batl":[[0,2.58,26.05]],"ltp":2.1,"tv":18.0,"id":8284479}]}]}
{"op":"mcm","clk":"1009253376","pt":1580664503675,"mc":[{"id":"1.168236371","rc":[{"batl":[[1,3.15,200.42]],"ltp":2.1,"tv":18.0,"id":8284479}]}]}
{"op":"mcm","clk":"1009255277","pt":1580664516166,"mc":[{"id":"1.168236371","rc":[{"batb":[[0,1.56,32.81],[1,1.01,10.51],[2,1.56,0]],"batl":[[0,2.3,309.75],[1,2.3,0]],"ltp":0.0,"tv":0.0,"id":4520808},{"batb":[[0,2.38,16.92],[1,1.01,10.51],[2,2.28,0]],"batl":[[0,3.15,200.42],[1,3.15,0]],"ltp":2.1,"tv":18.0,"id":8284479}]}]}
{"op":"mcm","clk":"1009257350","pt":1580664530169,"mc":[{"id":"1.168236371","rc":[{"batb":[[0,1.59,437.33],[1,1.56,32.81],[2,1.01,10.51]],"ltp":0.0,"tv":0.0,"id":4520808}]}]}
{"op":"mcm","clk":"1009257503","pt":1580664531093,"mc":[{"id":"1.168236371","rc":[{"batb":[[0,1.64,27.54],[1,1.61,29.58]],"batl":[[0,1.82,42.01],[1,2.3,309.75]],"ltp":0.0,"tv":0.0,"id":4520808},{"batb":[[1,2.3,18.73],[2,2.24,33.61]],"batl":[[0,2.52,26.89]],"ltp":2.1,"tv":18.0,"id":8284479}]}]}
{"op":"mcm","clk":"1009257646","pt":1580664532093,"mc":[{"id":"1.168236371","rc":[{"batl":[[1,3,213.45]],"ltp":2.1,"tv":18.0,"id":8284479}]}]}
{"op":"mcm","clk":"1009257829","pt":1580664533196,"mc":[{"id":"1.168236371","rc":[{"batb":[[0,1.66,63.01],[1,1.64,27.54],[2,1.61,29.58]],"ltp":0.0,"tv":0.0,"id":4520808}]}]}
{"op":"mcm","clk":"1009259878","pt":1580664547089,"mc":[{"id":"1.168236371","rc":[{"trd":[[2.38,33.5]],"batb":[[0,2.3,18.89],[1,2.24,33.61],[2,1.01,10.51]],"ltp":2.38,"tv":51.5,"id":8284479}],"tv":51.5}]}
{"op":"mcm","clk":"1009260289","pt":1580664550019,"mc":[{"id":"1.168236371","rc":[{"batb":[[1,1.61,29.58],[2,1.01,10.51]],"ltp":0.0,"tv":0.0,"id":4520808},{"batb":[[0,2.3,18.73]],"ltp":2.38,"tv":51.5,"id":8284479}]}]}
{"op":"mcm","clk":"1009260597","pt":1580664552010,"mc":[{"id":"1.168236371","rc":[{"batb":[[0,1.61,29.58],[1,1.01,10.51],[2,1.01,0]],"batl":[[0,2.3,309.75],[1,2.3,0]],"ltp":0.0,"tv":0.0,"id":4520808},{"batb":[[1,1.01,10.51],[2,1.01,0]],"batl":[[0,3,213.45],[1,3,0]],"ltp":2.38,"tv":51.5,"id":8284479}]}]}
{"op":"mcm","clk":"1009260766","pt":1580664553106,"mc":[{"id":"1.168236371","rc":[{"batb":[[0,1.63,29.03]],"ltp":0.0,"tv":0.0,"id":4520808},{"batb":[[0,2.28,19.12]],"ltp":2.38,"tv":51.5,"id":8284479}]}]}
{"op":"mcm","clk":"1009265788","pt":1580664587110,"mc":[{"id":"1.168236371","rc":[{"batb":[[0,1.64,189.31],[1,1.63,155],[2,1.01,10.51]],"batl":[[0,1.7,121.82],[1,1.72,209.03],[2,2.3,309.75]],"ltp":0.0,"tv":0.0,"id":4520808}]}]}
{"op":"mcm","clk":"1009265943","pt":1580664588224,"mc":[{"id":"1.168236371","rc":[{"batb":[[2,1.5,39.42]],"ltp":0.0,"tv":0.0,"id":4520808},{"batb":[[0,2.44,15.89],[1,2.26,19.91],[2,1.01,10.51]],"ltp":2.38,"tv":51.5,"id":8284479}]}]}
{"op":"mcm","clk":"1009266072","pt":1580664589118,"mc":[{"id":"1.168236371","rc":[{"batb":[[0,1.64,254.85]],"batl":[[2,1.81,42.01]],"ltp":0.0,"tv":0.0,"id":4520808},{"batb":[[1,2.26,52.67]],"batl":[[0,2.54,26.89],[1,3,213.45]],"ltp":2.38,"tv":51.5,"id":8284479}]}]}
{"op":"mcm","clk":"1009267280","pt":1580664597013,"mc":[{"id":"1.168236371","rc":[{"batl":[[2,1.75,4.22]],"ltp":0.0,"tv":0.0,"id":4520808}]}]}
{"op":"mcm","clk":"1009269312","pt":1580664609970,"mc":[{"id":"1.168236371","rc":[{"batl":[[0,1.75,4.22],[1,1.81,42.01],[2,2.3,309.75]],"ltp":0.0,"tv":0.0,"id":4520808}]}]}
{"op":"mcm","clk":"1009269837","pt":1580664613110,"mc":[{"id":"1.168236371","rc":[{"batl":[[0,1.71,206.89],[1,1.73,204.5],[2,1.75,4.22]],"ltp":0.0,"tv":0.0,"id":4520808}]}]}
{"op":"mcm","clk":"1009270373","pt":1580664616613,"mc":[{"id":"1.168236371","rc":[{"batb":[[0,1.64,283.56],[1,1.63,125.97],[2,1.51,38.95]],"ltp":0.0,"tv":0.0,"id":4520808},{"batb":[[0,2.42,16.13],[1,2.26,32.77],[2,2.24,20.14]],"ltp":2.38,"tv":51.5,"id":8284479}]}]}
{"op":"mcm","clk":"1009271038","pt":1580664620705,"mc":[{"id":"1.168236371","rc":[{"batb":[[0,1.64,305.05]],"ltp":0.0,"tv":0.0,"id":4520808}]}]}
{"op":"mcm","clk":"1009271234","pt":1580664621884,"mc":[{"id":"1.168236371","rc":[{"batb":[[0,1.64,304.9],[2,1.51,38.79]],"ltp":0.0,"tv":0.0,"id":4520808}]}]}
{"op":"mcm","clk":"1009271385","pt":1580664622997,"mc":[{"id":"1.168236371","rc":[{"batb":[[0,1.64,216.97],[1,1.51,38.79],[2,1.01,10.51]],"batl":[[0,1.71,173.16]],"ltp":0.0,"tv":0.0,"id":4520808}]}]}
{"op":"mcm","clk":"1009271870","pt":1580664626136,"mc":[{"id":"1.168236371","rc":[{"batb":[[0,1.65,122.03],[1,1.64,216.97],[2,1.51,38.79]],"ltp":0.0,"tv":0.0,"id":4520808}]}]}
{"op":"mcm","clk":"1009272319","pt":1580664629101,"mc":[{"id":"1.168236371","rc":[{"trd":[[2.42,32.12]],"batb":[[0,2.26,32.84],[1,2.24,20.14],[2,1.01,10.51]],"ltp":2.42,"tv":83.62,"id":8284479}],"tv":83.62}]}
{"op":"mcm","clk":"1009272473","pt":1580664630208,"mc":[{"id":"1.168236371","rc":[{"batb":[[1,1.64,151.43]],"ltp":0.0,"tv":0.0,"id":4520808}]}]}
{"op":"mcm","clk":"1009272782","pt":1580664632227,"mc":[{"id":"1.168236371","rc":[{"batb":[[0,1.65,150.04],[2,1.52,38.08]],"ltp":0.0,"tv":0.0,"id":4520808},{"batb":[[0,2.4,16.67],[1,2.26,32.77],[2,2.24,20.14]],"ltp":2.42,"tv":83.62,"id":8284479}]}]}
{"op":"mcm","clk":"1009272930","pt":1580664633244,"mc":[{"id":"1.168236371","rc":[{"batb":[[0,1.65,213.9],[1,1.64,122.87]],"ltp":0.0,"tv":0.0,"id":4520808},{"batb":[[0,2.4,16.6],[2,2.22,20.69]],"ltp":2.42,"tv":83.62,"id":8284479}]}]}
{"op":"mcm","clk":"1009273678","pt":1580664638233,"mc":[{"id":"1.168236371","rc":[{"batb":[[2,1.52,37.92]],"ltp":0.0,"tv":0.0,"id":4520808}]}]}
{"op":"mcm","clk":"1009274891","pt":1580664646167,"mc":[{"id":"1.168236371","rc":[{"batb":[[0,1.65,213.74]],"ltp":0.0,"tv":0.0,"id":4520808}]}]}
{"op":"mcm","clk":"1009278154","pt":1580664666601,"mc":[{"id":"1.168236371","rc":[{"batb":[[0,1.65,91.71]],"batl":[[0,1.75,4.22],[1,1.81,42.01],[2,2.3,309.75]],"ltp":0.0,"tv":0.0,"id":4520808}]}]}
{"op":"mcm","clk":"1009278684","pt":1580664669688,"mc":[{"id":"1.168236371","rc":[{"batb":[[0,1.65,63.85],[1,1.64,203.25],[2,1.63,126]],"batl":[[0,1.7,136.13],[1,1.72,209.07],[2,1.75,4.22]],"ltp":0.0,"tv":0.0,"id":4520808},{"batb":[[0,2.42,16.21],[2,2.24,20.22]],"ltp":2.42,"tv":83.62,"id":8284479}]}]}
{"op":"mcm","clk":"1009284078","pt":1580664705721,"mc":[{"id":"1.168236371","rc":[{"trd":[[2.42,41.21]],"batb":[[0,2.42,11.66]],"ltp":2.42,"tv":92.71,"id":8284479}],"tv":92.71}]}
{"op":"mcm","clk":"1009286194","pt":1580664720103,"mc":[{"id":"1.168236371","rc":[{"batl":[[2,1.81,42.01]],"ltp":0.0,"tv":0.0,"id":4520808}]}]}
{"op":"mcm","clk":"1009290447","pt":1580664748167,"mc":[{"id":"1.168236371","rc":[{"batb":[[0,1.64,203.25],[1,1.63,126],[2,1.51,38.87]],"batl":[[2,2.3,309.75]],"ltp":0.0,"tv":0.0,"id":4520808},{"batb":[[1,2.24,20.22],[2,1.01,10.51]],"batl":[[0,3,213.45],[1,3,0]],"ltp":2.42,"tv":92.71,"id":8284479}]}]}
{"op":"mcm","clk":"1009290894","pt":1580664751054,"mc":[{"id":"1.168236371","rc":[{"batb":[[0,1.64,268.79]],"batl":[[2,1.78,42.01]],"ltp":0.0,"tv":0.0,"id":4520808},{"batb":[[1,2.3,31.93],[2,2.24,20.22]],"batl":[[0,2.58,26.05],[1,3,213.45]],"ltp":2.42,"tv":92.71,"id":8284479}]}]}
{"op":"mcm","clk":"1009292854","pt":1580664764096,"mc":[{"id":"1.168236371","rc":[{"batb":[[0,1.64,94.18],[1,1.51,38.87],[2,1.01,10.51]],"batl":[[0,1.78,42.01],[1,2.3,309.75],[2,3,2.27]],"ltp":0.0,"tv":0.0,"id":4520808}]}]}
{"op":"mcm","clk":"1009293296","pt":1580664767011,"mc":[{"id":"1.168236371","rc":[{"batb":[[1,1.51,319.18],[2,1.5,174.21]],"batl":[[1,1.8,174.25],[2,1.82,173.52]],"ltp":0.0,"tv":0.0,"id":4520808}]}]}
{"op":"mcm","clk":"1009311171","pt":1580664880221,"mc":[{"id":"1.168236371","rc":[{"trd":[[1.63,34.43],[1.64,188.36]],"batb":[[0,1.51,319.18],[1,1.5,174.21],[2,1.01,10.51]],"ltp":1.63,"tv":222.78,"id":4520808},{"trd":[[2.58,21.75]],"batl":[[0,2.58,4.29]],"ltp":2.58,"tv":114.46,"id":8284479}],"tv":337.24}]}
{"op":"mcm","clk":"1009311235","pt":1580664880597,"mc":[{"id":"1.168236371","rc":[{"batl":[[0,3,213.45],[1,3,0]],"ltp":2.58,"tv":114.46,"id":8284479}]}]}
{"op":"mcm","clk":"1009311688","pt":1580664883497,"mc":[{"id":"1.168236371","rc":[{"batb":[[0,1.62,67.22],[1,1.51,319.18],[2,1.5,174.21]],"ltp":1.63,"tv":222.78,"id":4520808},{"batl":[[0,2.64,25.21],[1,3,213.45]],"ltp":2.58,"tv":114.46,"id":8284479}]}]}
{"op":"mcm","clk":"1009314566","pt":1580664901137,"mc":[{"id":"1.168236371","rc":[{"batb":[[0,2.3,31.93],[1,2.24,20.22],[2,1.01,10.51]],"ltp":2.58,"tv":114.46,"id":8284479}]}]}
{"op":"mcm","clk":"1009314742","pt":1580664902244,"mc":[{"id":"1.168236371","rc":[{"batb":[[0,1.51,319.18],[1,1.5,174.21],[2,1.01,10.51]],"batl":[[0,1.8,174.25],[1,1.82,173.52],[2,2.3,309.75]],"ltp":1.63,"tv":222.78,"id":4520808},{"batb":[[0,2.24,20.22],[1,1.01,10.51],[2,1.01,0]],"batl":[[0,3,213.45],[1,3,0]],"ltp":2.58,"tv":114.46,"id":8284479}]}]}
{"op":"mcm","clk":"1009315236","pt":1580664905037,"mc":[{"id":"1.168236371","rc":[{"batb":[[0,1.51,38.87],[1,1.01,10.51],[2,1.01,0]],"ltp":1.63,"tv":222.78,"id":4520808}]}]}
{"op":"mcm","clk":"1009315808","pt":1580664908228,"mc":[{"id":"1.168236371","rc":[{"batb":[[0,1.73,131.18],[1,1.71,210.97],[2,1.51,38.87]],"ltp":1.63,"tv":222.78,"id":4520808}]}]}
{"op":"mcm","clk":"1009315916","pt":1580664908866,"mc":[{"id":"1.168236371","rc":[{"batb":[[0,1.74,23.45],[1,1.73,131.18],[2,1.71,210.97]],"ltp":1.63,"tv":222.78,"id":4520808},{"batb":[[1,2.1,24.39],[2,1.01,10.51]],"batl":[[0,2.48,27.73]],"ltp":2.58,"tv":114.46,"id":8284479}]}]}
{"op":"mcm","clk":"1009316146","pt":1580664910270,"mc":[{"id":"1.168236371","rc":[{"batl":[[1,2.82,231.28]],"ltp":2.58,"tv":114.46,"id":8284479}]}]}
{"op":"mcm","clk":"1009317267","pt":1580664916963,"mc":[{"id":"1.168236371","rc":[{"batb":[[0,1.67,62.17],[1,1.61,30.21],[2,1.01,10.51]],"batl":[[0,2.3,309.75],[1,3,2.27],[2,2.3,0]],"ltp":1.63,"tv":222.78,"id":4520808},{"batb":[[0,2.1,24.23],[1,1.01,10.51],[2,1.01,0]],"ltp":2.58,"tv":114.46,"id":8284479}]}]}
{"op":"mcm","clk":"1009317436","pt":1580664918049,"mc":[{"id":"1.168236371","rc":[{"batb":[[0,1.61,30.21],[1,1.01,10.51],[2,1.01,0]],"ltp":1.63,"tv":222.78,"id":4520808},{"batl":[[0,2.82,231.28],[1,2.82,0]],"ltp":2.58,"tv":114.46,"id":8284479}]}]}
{"op":"mcm","clk":"1009317953","pt":1580664921097,"mc":[{"id":"1.168236371","rc":[{"batb":[[0,1.7,195.9],[1,1.68,224.72],[2,1.61,30.21]],"batl":[[0,1.77,145.36],[1,1.79,183.16],[2,2.3,309.75]],"ltp":1.63,"tv":222.78,"id":4520808}]}]}
{"op":"mcm","clk":"1009318573","pt":1580664924955,"mc":[{"id":"1.168236371","rc":[{"batb":[[0,1.61,30.21],[1,1.01,10.51],[2,1.61,0]],"batl":[[0,2.3,309.75],[1,3,2.27],[2,2.3,0]],"ltp":1.63,"tv":222.78,"id":4520808}]}]}
{"op":"mcm","clk":"1009319146","pt":1580664928185,"mc":[{"id":"1.168236371","rc":[{"batb":[[0,1.61,241.88],[1,1.6,135.09],[2,1.01,10.51]],"batl":[[0,1.88,129.45],[1,1.9,151.62],[2,2.3,309.75]],"ltp":1.63,"tv":222.78,"id":4520808}]}]}
{"op":"mcm","clk":"1009319767","pt":1580664932096,"mc":[{"id":"1.168236371","rc":[{"batl":[[0,2.3,309.75],[1,3,2.27],[2,2.3,0]],"ltp":1.63,"tv":222.78,"id":4520808}]}]}
{"op":"mcm","clk":"1009320307","pt":1580664935173,"mc":[{"id":"1.168236371","rc":[{"batl":[[0,1.67,139.22],[1,1.69,221.99],[2,2.3,309.75]],"ltp":1.63,"tv":222.78,"id":4520808}]}]}
{"op":"mcm","clk":"1009320454","pt":1580664936090,"mc":[{"id":"1.168236371","rc":[{"batb":[[2,1.46,43.75]],"ltp":1.63,"tv":222.78,"id":4520808},{"batb":[[0,2.48,15.11],[1,2.26,19.67],[2,1.01,10.51]],"ltp":2.58,"tv":114.46,"id":8284479}]}]}
{"op":"mcm","clk":"1009320533","pt":1580664936451,"mc":[{"id":"1.168236371","rc":[{"batb":[[2,1.58,72.26]],"ltp":1.63,"tv":222.78,"id":4520808},{"batl":[[0,2.74,23.53]],"ltp":2.58,"tv":114.46,"id":8284479}]}]}
{"op":"mcm","clk":"1009320896","pt":1580664938670,"mc":[{"id":"1.168236371","rc":[{"batl":[[1,3.15,200.42]],"ltp":2.58,"tv":114.46,"id":8284479}]}]}
{"op":"mcm","clk":"1009322966","pt":1580664950819,"mc":[{"id":"1.168236371","rc":[{"trd":[[1.61,0.03]],"batb":[[0,1.61,241.87]],"ltp":1.61,"tv":222.81,"id":4520808}],"tv":337.27}]}
{"op":"mcm","clk":"1009323307","pt":1580664952790,"mc":[{"id":"1.168236371","rc":[{"batb":[[0,1.58,72.26],[1,1.46,43.75],[2,1.01,10.51]],"batl":[[0,2.3,309.75],[1,3,2.27],[2,2.3,0]],"ltp":1.61,"tv":222.81,"id":4520808},{"batb":[[0,2.26,19.67],[1,1.01,10.51],[2,1.01,0]],"ltp":2.58,"tv":114.46,"id":8284479}]}]}
{"op":"mcm","clk":"1009323518","pt":1580664954189,"mc":[{"id":"1.168236371","rc":[{"batb":[[0,1.46,43.75],[1,1.01,10.51],[2,1.01,0]],"ltp":1.61,"tv":222.81,"id":4520808},{"batl":[[0,3.15,200.42],[1,3.15,0]],"ltp":2.58,"tv":114.46,"id":8284479}]}]}
{"op":"mcm","clk":"1009323691","pt":1580664955205,"mc":[{"id":"1.168236371","rc":[{"batb":[[0,1.47,177.33],[1,1.46,238.02],[2,1.01,10.51]],"batl":[[0,1.79,182.26],[1,1.81,176.58],[2,2.3,309.75]],"ltp":1.61,"tv":222.81,"id":4520808}]}]}
{"op":"mcm","clk":"1009324298","pt":1580664959082,"mc":[{"id":"1.168236371","rc":[{"batl":[[0,2.3,309.75],[1,3,2.27],[2,2.3,0]],"ltp":1.61,"tv":222.81,"id":4520808}]}]}
{"op":"mcm","clk":"1009324374","pt":1580664959620,"mc":[{"id":"1.168236371","rc":[{"batl":[[0,3,2.27],[1,3,0]],"ltp":1.61,"tv":222.81,"id":4520808}]}]}
{"op":"mcm","clk":"1009324788","pt":1580664962207,"mc":[{"id":"1.168236371","rc":[{"batb":[[2,1.32,68.61]],"batl":[[0,1.52,267.31],[1,1.53,157.67],[2,3,2.27]],"ltp":1.61,"tv":222.81,"id":4520808},{"batb":[[0,2.92,24.63],[1,2.54,14.16],[2,2.26,19.67]],"ltp":2.58,"tv":114.46,"id":8284479}]}]}
{"op":"mcm","clk":"1009324848","pt":1580664962613,"mc":[{"id":"1.168236371","rc":[{"batb":[[1,1.46,328.76]],"ltp":1.61,"tv":222.81,"id":4520808},{"batb":[[2,1.01,10.51]],"batl":[[0,3.15,19.32]],"ltp":2.58,"tv":114.46,"id":8284479}]}]}
{"op":"mcm","clk":"1009325038","pt":1580664963790,"mc":[{"id":"1.168236371","rc":[{"batl":[[2,1.95,409.86]],"ltp":1.61,"tv":222.81,"id":4520808},{"batl":[[1,3.9,158.24]],"ltp":2.58,"tv":114.46,"id":8284479}]}]}
{"op":"mcm","clk":"1009326721","pt":1580664974146,"mc":[{"id":"1.168236371","rc":[{"batl":[[0,3.9,158.24],[1,3.9,0]],"ltp":2.58,"tv":114.46,"id":8284479}]}]}
{"op":"mcm","clk":"1009326848","pt":1580664974841,"mc":[{"id":"1.168236371","rc":[{"batb":[[0,1.46,90.74],[1,1.32,68.61],[2,1.01,10.51]],"batl":[[0,1.95,409.86],[1,3,2.27],[2,1.95,0]],"ltp":1.61,"tv":222.81,"id":4520808},{"batb":[[0,2.54,14.16],[1,1.01,10.51],[2,1.01,0]],"ltp":2.58,"tv":114.46,"id":8284479}]}]}
{"op":"mcm","clk":"1009326980","pt":1580664975668,"mc":[{"id":"1.168236371","rc":[{"batb":[[0,1.32,68.61],[1,1.01,10.51],[2,1.01,0]],"ltp":1.61,"tv":222.81,"id":4520808}]}]}
{"op":"mcm","clk":"1009327263","pt":1580664977237,"mc":[{"id":"1.168236371","rc":[{"batb":[[1,1.31,433.69],[2,1.3,341.87]],"batl":[[0,1.64,121.54],[1,1.65,119.98],[2,1.95,409.86]],"ltp":1.61,"tv":222.81,"id":4520808}]}]}
{"op":"mcm","clk":"1009327933","pt":1580664981234,"mc":[{"id":"1.168236371","rc":[{"batb":[[1,1.01,10.51],[2,1.3,0]],"batl":[[0,1.95,409.86],[1,3,2.27],[2,1.95,0]],"ltp":1.61,"tv":222.81,"id":4520808}]}]}
{"op":"mcm","clk":"1009328391","pt":1580664984130,"mc":[{"id":"1.168236371","rc":[{"batb":[[0,1.43,320.89],[1,1.42,220.48],[2,1.32,68.61]],"batl":[[0,1.48,222.63],[1,1.49,175.31],[2,1.95,409.86]],"ltp":1.61,"tv":222.81,"id":4520808}]}]}
{"op":"mcm","clk":"1009328577","pt":1580664985152,"mc":[{"id":"1.168236371","rc":[{"batb":[[0,1.32,68.61],[1,1.01,10.51],[2,1.32,0]],"batl":[[0,1.95,409.86],[1,3,2.27],[2,1.95,0]],"ltp":1.61,"tv":222.81,"id":4520808}]}]}
{"op":"mcm","clk":"1009328938","pt":1580664987447,"mc":[{"id":"1.168236371","rc":[{"batb":[[1,1.31,433.99],[2,1.3,341.86]],"batl":[[0,1.64,121.3],[1,1.65,119.97],[2,1.95,409.86]],"ltp":1.61,"tv":222.81,"id":4520808}]}]}
{"op":"mcm","clk":"1009329252","pt":1580664989116,"mc":[{"id":"1.168236371","rc":[{"batb":[[1,1.01,10.51],[2,1.3,0]],"ltp":1.61,"tv":222.81,"id":4520808}]}]}
{"op":"mcm","clk":"1009329529","pt":1580664990855,"mc":[{"id":"1.168236371","rc":[{"batl":[[2,3,2.27]],"ltp":1.61,"tv":222.81,"id":4520808}]}]}
{"op":"mcm","clk":"1009329724","pt":1580664992130,"mc":[{"id":"1.168236371","rc":[{"batb":[[0,1.59,133.81],[1,1.58,141.35],[2,1.32,68.61]],"ltp":1.61,"tv":222.81,"id":4520808}]}]}
{"op":"mcm","clk":"1009329871","pt":1580664992940,"mc":[{"id":"1.168236371","rc":[{"batb":[[1,1.58,173.61],[2,1.55,75.62]],"ltp":1.61,"tv":222.81,"id":4520808},{"batb":[[1,2.24,19.99],[2,1.01,10.51]],"batl":[[0,2.82,22.69]],"ltp":2.58,"tv":114.46,"id":8284479}]}]}
{"op":"mcm","clk":"1009330050","pt":1580664994038,"mc":[{"id":"1.168236371","rc":[{"batl":[[2,2.16,342.82]],"ltp":1.61,"tv":222.81,"id":4520808},{"batl":[[1,3.3,191.92]],"ltp":2.58,"tv":114.46,"id":8284479}]}]}
{"op":"mcm","clk":"1009331978","pt":1580665005974,"mc":[{"id":"1.168236371","rc":[{"batb":[[0,1.55,75.62],[1,1.4,51.77],[2,1.01,10.51]],"batl":[[0,2.16,342.82],[1,3,2.27],[2,2.16,0]],"ltp":1.61,"tv":222.81,"id":4520808},{"batb":[[0,2.24,19.99],[1,1.01,10.51],[2,1.01,0]],"ltp":2.58,"tv":114.46,"id":8284479}]}]}
{"op":"mcm","clk":"1009332333","pt":1580665008164,"mc":[{"id":"1.168236371","rc":[{"batb":[[0,1.4,51.77],[1,1.01,10.51],[2,1.01,0]],"ltp":1.61,"tv":222.81,"id":4520808},{"batl":[[0,3.3,191.92],[1,3.3,0]],"ltp":2.58,"tv":114.46,"id":8284479}]}]}
{"op":"mcm","clk":"1009332687","pt":1580665010156,"mc":[{"id":"1.168236371","rc":[{"batb":[[1,1.01,13.55]],"ltp":1.61,"tv":222.81,"id":4520808}]}]}
{"op":"mcm","clk":"1009332831","pt":1580665010974,"mc":[{"id":"1.168236371","rc":[{"batb":[[1,1.01,10.51]],"ltp":1.61,"tv":222.81,"id":4520808}]}]}
{"op":"mcm","clk":"1009332989","pt":1580665011871,"mc":[{"id":"1.168236371","rc":[{"batb":[[0,1.55,134.71],[1,1.54,156.05],[2,1.4,51.77]],"batl":[[0,1.6,172.45],[1,1.61,130.77],[2,2.16,342.82]],"ltp":1.61,"tv":222.81,"id":4520808}]}]}
{"op":"mcm","clk":"1009333341","pt":1580665013959,"mc":[{"id":"1.168236371","rc":[{"trd":[[1.6,0.04]],"batl":[[0,1.6,172.43]],"ltp":1.6,"tv":222.85,"id":4520808}],"tv":337.31}]}
{"op":"mcm","clk":"1009333536","pt":1580665015164,"mc":[{"id":"1.168236371","rc":[{"batb":[[0,1.4,51.77],[1,1.01,10.51],[2,1.4,0]],"batl":[[0,2.16,342.82],[1,3,2.27],[2,2.16,0]],"ltp":1.6,"tv":222.85,"id":4520808}]}]}
{"op":"mcm","clk":"1009333896","pt":1580665017367,"mc":[{"id":"1.168236371","rc":[{"batb":[[0,1.4,402.48],[1,1.39,243.34],[2,1.01,10.51]],"batl":[[0,1.8,179.17],[1,1.82,173.48],[2,2.16,342.82]],"ltp":1.6,"tv":222.85,"id":4520808}]}]}
{"op":"mcm","clk":"1009334515","pt":1580665021095,"mc":[{"id":"1.168236371","rc":[{"batb":[[0,1.4,51.77],[1,1.01,10.51],[2,1.01,0]],"ltp":1.6,"tv":222.85,"id":4520808}]}]}
{"op":"mcm","clk":"1009334990","pt":1580665023970,"mc":[{"id":"1.168236371","rc":[{"batb":[[0,1.73,125.89],[1,1.71,210.93],[2,1.4,51.77]],"ltp":1.6,"tv":222.85,"id":4520808}]}]}
{"op":"mcm","clk":"1009335203","pt":1580665025199,"mc":[{"id":"1.168236371","rc":[{"batb":[[0,1.73,149.65],[2,1.57,33.36]],"ltp":1.6,"tv":222.85,"id":4520808},{"batb":[[1,2.08,25.18],[2,1.01,10.51]],"ltp":2.58,"tv":114.46,"id":8284479}]}]}
{"op":"mcm","clk":"1009335282","pt":1580665025696,"mc":[{"id":"1.168236371","rc":[{"batl":[[0,2.92,221.26]],"ltp":2.58,"tv":114.46,"id":8284479}]}]}
{"op":"mcm","clk":"1009336899","pt":1580665034976,"mc":[{"id":"1.168236371","rc":[{"batb":[[0,1.73,23.76],[1,1.57,33.36],[2,1.01,10.51]],"batl":[[0,2.16,342.82],[1,3,2.27],[2,2.16,0]],"ltp":1.6,"tv":222.85,"id":4520808}]}]}
{"op":"mcm","clk":"1009337011","pt":1580665035616,"mc":[{"id":"1.168236371","rc":[{"batb":[[0,1.57,33.36],[1,1.01,10.51],[2,1.01,0]],"ltp":1.6,"tv":222.85,"id":4520808},{"batb":[[0,2.08,25.18],[1,1.01,10.51],[2,1.01,0]],"ltp":2.58,"tv":114.46,"id":8284479}]}]}
{"op":"mcm","clk":"1009337424","pt":1580665038092,"mc":[{"id":"1.168236371","rc":[{"batb":[[0,1.58,147.49],[1,1.57,178.22],[2,1.01,10.51]],"batl":[[0,1.91,116.43],[1,1.93,144.46],[2,2.16,342.82]],"ltp":1.6,"tv":222.85,"id":4520808}]}]}
{"op":"mcm","clk":"1009338603","pt":1580665045010,"mc":[{"id":"1.168236371","rc":[{"batb":[[0,1.57,33.36],[1,1.01,10.51],[2,1.01,0]],"ltp":1.6,"tv":222.85,"id":4520808}]}]}
{"op":"mcm","clk":"1009338960","pt":1580665046904,"mc":[{"id":"1.168236371","rc":[{"batl":[[2,3,2.27]],"ltp":1.6,"tv":222.85,"id":4520808}]}]}
{"op":"mcm","clk":"1009339188","pt":1580665048241,"mc":[{"id":"1.168236371","rc":[{"batb":[[0,1.85,19.12],[1,1.83,176.5],[2,1.81,174.16]],"ltp":1.6,"tv":222.85,"id":4520808},{"batb":[[1,1.86,17.7],[2,1.01,10.51]],"ltp":2.58,"tv":114.46,"id":8284479}]}]}
{"op":"mcm","clk":"1009339240","pt":1580665048516,"mc":[{"id":"1.168236371","rc":[{"batl":[[0,2.32,31.09]],"ltp":2.58,"tv":114.46,"id":8284479}]}]}
{"op":"mcm","clk":"1009339638","pt":1580665051026,"mc":[{"id":"1.168236371","rc":[{"batl":[[2,2.5,274.54]],"ltp":1.6,"tv":222.85,"id":4520808},{"batl":[[1,2.72,241.55]],"ltp":2.58,"tv":114.46,"id":8284479}]}]}
{"op":"mcm","clk":"1009341133","pt":1580665060226,"mc":[{"id":"1.168236371","rc":[{"batl":[[0,1.87,10.4],[1,1.91,116.43],[2,1.93,144.46]],"ltp":1.6,"tv":222.85,"id":4520808}]}]}
{"op":"mcm","clk":"1009345026","pt":1580665083172,"mc":[{"id":"1.168236371","rc":[{"batl":[[0,1.91,116.43],[1,1.93,144.46],[2,2.5,274.54]],"ltp":1.6,"tv":222.85,"id":4520808}]}]}
{"op":"mcm","clk":"1009345368","pt":1580665085168,"mc":[{"id":"1.168236371","rc":[{"batb":[[1,1.75,78.19],[2,1.01,10.51]],"batl":[[0,2.5,274.54],[1,3,2.27],[2,2.5,0]],"ltp":1.6,"tv":222.85,"id":4520808}]}]}
{"op":"mcm","clk":"1009345564","pt":1580665086249,"mc":[{"id":"1.168236371","rc":[{"trd":[[1.85,20.81]],"batb":[[0,1.85,8.72]],"ltp":1.85,"tv":243.65,"id":4520808}],"tv":358.12}]}
{"op":"mcm","clk":"1009345839","pt":1580665087845,"mc":[{"id":"1.168236371","rc":[{"batb":[[2,1.74,179.03]],"batl":[[0,2.14,141.29],[1,2.16,103.65],[2,2.5,274.54]],"ltp":1.85,"tv":243.65,"id":4520808}]}]}
{"op":"mcm","clk":"1009346771","pt":1580665093254,"mc":[{"id":"1.168236371","rc":[{"trd":[[2.08,49.88]],"batb":[[0,1.86,17.94],[1,1.01,10.51],[2,1.01,0]],"ltp":2.08,"tv":164.34,"id":8284479}],"tv":408.0}]}
{"op":"mcm","clk":"1009347782","pt":1580665099187,"mc":[{"id":"1.168236371","rc":[{"batb":[[0,1.75,78.19],[1,1.74,179.03],[2,1.72,206.88]],"ltp":1.85,"tv":243.65,"id":4520808},{"batb":[[0,1.86,17.7]],"ltp":2.08,"tv":164.34,"id":8284479}]}]}
{"op":"mcm","clk":"1009347854","pt":1580665099587,"mc":[{"id":"1.168236371","rc":[{"batb":[[0,1.75,22.74]],"ltp":1.85,"tv":243.65,"id":4520808},{"batl":[[0,2.72,241.55],[1,2.72,0]],"ltp":2.08,"tv":164.34,"id":8284479}]}]}
{"op":"mcm","clk":"1009348116","pt":1580665101218,"mc":[{"id":"1.168236371","rc":[{"batb":[[1,1.01,10.51],[2,1.72,0]],"batl":[[0,2.5,274.54],[1,3,2.27],[2,2.5,0]],"ltp":1.85,"tv":243.65,"id":4520808}]}]}
{"op":"mcm","clk":"1009348266","pt":1580665102078,"mc":[{"id":"1.168236371","rc":[{"batb":[[0,1.76,22.35],[1,1.75,22.74],[2,1.01,10.51]],"ltp":1.85,"tv":243.65,"id":4520808},{"batb":[[1,1.85,18.02],[2,1.01,10.51]],"ltp":2.08,"tv":164.34,"id":8284479}]}]}
{"op":"mcm","clk":"1009348461","pt":1580665103095,"mc":[{"id":"1.168236371","rc":[{"batb":[[1,1.01,10.51],[2,1.01,0]],"ltp":1.85,"tv":243.65,"id":4520808},{"batb":[[0,1.85,18.02],[1,1.01,10.51],[2,1.01,0]],"ltp":2.08,"tv":164.34,"id":8284479}]}]}
{"op":"mcm","clk":"1009348615","pt":1580665103997,"mc":[{"id":"1.168236371","rc":[{"batb":[[0,1.87,151.21],[1,1.85,162.13],[2,1.76,22.35]],"batl":[[0,1.95,107.6],[1,1.97,135.73],[2,2.5,274.54]],"ltp":1.85,"tv":243.65,"id":4520808}]}]}
{"op":"mcm","clk":"1009349137","pt":1580665106787,"mc":[{"id":"1.168236371","rc":[{"batb":[[0,1.76,22.35],[1,1.01,10.51],[2,1.76,0]],"batl":[[0,2.5,274.54],[1,3,2.27],[2,2.5,0]],"ltp":1.85,"tv":243.65,"id":4520808},{"batl":[[0,2.6,257.57]],"ltp":2.08,"tv":164.34,"id":8284479}]}]}
{"op":"mcm","clk":"1009349700","pt":1580665109980,"mc":[{"id":"1.168236371","rc":[{"batb":[[1,1.74,180.31],[2,1.72,206.88]],"batl":[[0,2.14,140.26],[1,2.16,103.66],[2,2.5,274.54]],"ltp":1.85,"tv":243.65,"id":4520808}]}]}
{"op":"mcm","clk":"1009350035","pt":1580665112097,"mc":[{"id":"1.168236371","rc":[{"batl":[[0,2.5,274.54],[1,3,2.27],[2,2.5,0]],"ltp":1.85,"tv":243.65,"id":4520808}]}]}
{"op":"mcm","clk":"1009350441","pt":1580665114088,"mc":[{"id":"1.168236371","rc":[{"batl":[[0,3,2.27],[1,3,0]],"ltp":1.85,"tv":243.65,"id":4520808}]}]}
{"op":"mcm","clk":"1009350637","pt":1580665115233,"mc":[{"id":"1.168236371","rc":[{"batl":[[0,1.81,117.25],[1,1.83,170.61],[2,3,2.27]],"ltp":1.85,"tv":243.65,"id":4520808}]}]}
{"op":"mcm","clk":"1009350791","pt":1580665116121,"mc":[{"id":"1.168236371","rc":[{"batb":[[0,2.2,21.32],[1,1.99,28.48],[2,1.01,10.51]],"ltp":2.08,"tv":164.34,"id":8284479}]}]}
{"op":"mcm","clk":"1009350855","pt":1580665116499,"mc":[{"id":"1.168236371","rc":[{"batl":[[0,2.46,28.57]],"ltp":2.08,"tv":164.34,"id":8284479}]}]}
{"op":"mcm","clk":"1009351113","pt":1580665118007,"mc":[{"id":"1.168236371","rc":[{"batl":[[2,2.36,299.17]],"ltp":1.85,"tv":243.65,"id":4520808},{"batl":[[1,2.92,221.26]],"ltp":2.08,"tv":164.34,"id":8284479}]}]}
{"op":"mcm","clk":"1009353214","pt":1580665129817,"mc":[{"id":"1.168236371","rc":[{"batb":[[0,1.68,26.12],[1,1.01,10.51],[2,1.72,0]],"batl":[[0,2.36,299.17],[1,3,2.27],[2,2.36,0]],"ltp":1.85,"tv":243.65,"id":4520808},{"batb":[[0,1.99,28.48],[1,1.01,10.51],[2,1.01,0]],"batl":[[0,2.92,221.26],[1,2.92,0]],"ltp":2.08,"tv":164.34,"id":8284479}]}]}
{"op":"mcm","clk":"1009353765","pt":1580665132924,"mc":[{"id":"1.168236371","rc":[{"batb":[[0,1.68,180.97],[1,1.67,115.37],[2,1.01,10.51]],"ltp":1.85,"tv":243.65,"id":4520808}]}]}
{"op":"mcm","clk":"1009354329","pt":1580665136139,"mc":[{"id":"1.168236371","rc":[{"batb":[[2,1.63,29.03]],"batl":[[0,1.74,110.11],[1,1.76,193.68],[2,2.36,299.17]],"ltp":1.85,"tv":243.65,"id":4520808},{"batb":[[0,2.34,18.02],[1,2.16,22.42],[2,1.01,10.51]],"ltp":2.08,"tv":164.34,"id":8284479}]}]}
{"op":"mcm","clk":"1009354501","pt":1580665137116,"mc":[{"id":"1.168236371","rc":[{"batb":[[2,1.64,65.54]],"ltp":1.85,"tv":243.65,"id":4520808},{"batl":[[0,2.58,26.05],[1,2.92,221.26]],"ltp":2.08,"tv":164.34,"id":8284479}]}]}
{"op":"mcm","clk":"1009356443","pt":1580665148033,"mc":[{"id":"1.168236371","rc":[{"batb":[[0,1.64,65.54],[1,1.63,29.03],[2,1.01,10.51]],"batl":[[0,2.36,299.17],[1,3,2.27],[2,2.36,0]],"ltp":1.85,"tv":243.65,"id":4520808},{"batb":[[0,2.16,22.42],[1,1.01,10.51],[2,1.01,0]],"ltp":2.08,"tv":164.34,"id":8284479}]}]}
{"op":"mcm","clk":"1009356702","pt":1580665149670,"mc":[{"id":"1.168236371","rc":[{"batb":[[0,1.63,29.03],[1,1.01,10.51],[2,1.01,0]],"ltp":1.85,"tv":243.65,"id":4520808},{"batl":[[0,2.92,221.26],[1,2.92,0]],"ltp":2.08,"tv":164.34,"id":8284479}]}]}
{"op":"mcm","clk":"1009356972","pt":1580665151142,"mc":[{"id":"1.168236371","rc":[{"batb":[[0,1.64,176.49],[1,1.63,155],[2,1.01,10.51]],"batl":[[0,1.83,115.17],[1,1.85,164.83],[2,2.36,299.17]],"ltp":1.85,"tv":243.65,"id":4520808}]}]}
{"op":"mcm","clk":"1009357696","pt":1580665155130,"mc":[{"id":"1.168236371","rc":[{"batb":[[0,1.63,29.03],[1,1.01,10.51],[2,1.01,0]],"ltp":1.85,"tv":243.65,"id":4520808}]}]}
{"op":"mcm","clk":"1009358156","pt":1580665158050,"mc":[{"id":"1.168236371","rc":[{"batb":[[0,1.76,162.19],[1,1.74,198.79],[2,1.63,29.03]],"ltp":1.85,"tv":243.65,"id":4520808}]}]}
{"op":"mcm","clk":"1009358356","pt":1580665159237,"mc":[{"id":"1.168236371","rc":[{"batb":[[0,1.78,21.48],[1,1.76,162.19],[2,1.74,198.79]],"ltp":1.85,"tv":243.65,"id":4520808},{"batb":[[1,1.93,15.58],[2,1.01,10.51]],"batl":[[0,2.44,28.57],[1,2.92,221.26]],"ltp":2.08,"tv":164.34,"id":8284479}]}]}
{"op":"mcm","clk":"1009359897","pt":1580665168188,"mc":[{"id":"1.168236371","rc":[{"batb":[[1,1.71,58.81],[2,1.69,25.57]],"batl":[[0,2.36,299.17],[1,3,2.27],[2,2.36,0]],"ltp":1.85,"tv":243.65,"id":4520808}]}]}
{"op":"mcm","clk":"1009359929","pt":1580665168347,"mc":[{"id":"1.168236371","rc":[{"batb":[[0,1.71,58.81],[1,1.01,10.51],[2,1.69,0]],"ltp":1.85,"tv":243.65,"id":4520808},{"batb":[[0,1.01,10.51],[1,1.93,0],[2,1.01,0]],"ltp":2.08,"tv":164.34,"id":8284479}]}]}
{"op":"mcm","clk":"1009360120","pt":1580665169681,"mc":[{"id":"1.168236371","rc":[{"batb":[[0,1.01,10.51],[1,1.01,0]],"ltp":1.85,"tv":243.65,"id":4520808},{"batl":[[0,2.92,221.26],[1,2.92,0]],"ltp":2.08,"tv":164.34,"id":8284479}]}]}
{"op":"mcm","clk":"1009363213","pt":1580665188587,"mc":[{"id":"1.168236371","rc":[{"batb":[[0,1.63,66.38],[1,1.01,10.51]],"ltp":1.85,"tv":243.65,"id":4520808},{"batl":[[0,2.58,26.05],[1,2.92,221.26]],"ltp":2.08,"tv":164.34,"id":8284479}]}]}
{"op":"mcm","clk":"1009366400","pt":1580665207611,"mc":[{"id":"1.168236371","rc":[{"batb":[[0,1.01,10.51],[1,1.01,0]],"ltp":1.85,"tv":243.65,"id":4520808},{"batl":[[0,2.92,221.26],[1,2.92,0]],"ltp":2.08,"tv":164.34,"id":8284479}]}]}
{"op":"mcm","clk":"1009369909","pt":1580665228042,"mc":[{"id":"1.168236371","rc":[{"batl":[[0,3,2.27],[1,3,0]],"ltp":1.85,"tv":243.65,"id":4520808}]}]}
{"op":"mcm","clk":"1009370416","pt":1580665231146,"mc":[{"id":"1.168236371","rc":[{"batb":[[0,1.59,70.58],[1,1.01,10.51]],"batl":[[0,2.22,329.01],[1,3,2.27]],"ltp":1.85,"tv":243.65,"id":4520808},{"batl":[[0,2.68,24.37],[1,2.92,221.26]],"ltp":2.08,"tv":164.34,"id":8284479}]}]}
{"op":"mcm","clk":"1009374735","pt":1580665258200,"mc":[{"id":"1.168236371","rc":[{"trd":[[2.22,2.75]],"batl":[[0,2.22,326.26]],"ltp":2.22,"tv":246.4,"id":4520808},{"trd":[[1.81,3.37]],"ltp":1.81,"tv":167.71,"id":8284479}],"tv":414.12}]}
{"op":"mcm","clk":"1009375031","pt":1580665259900,"mc":[{"id":"1.168236371","rc":[{"batb":[[0,1.01,10.51],[1,1.01,0]],"ltp":2.22,"tv":246.4,"id":4520808},{"batl":[[0,2.92,221.26],[1,2.92,0]],"ltp":1.81,"tv":167.71,"id":8284479}]}]}
{"op":"mcm","clk":"1009375867","pt":1580665264912,"mc":[{"id":"1.168236371","rc":[{"batl":[[0,3.3,193.79]],"ltp":1.81,"tv":167.71,"id":8284479}]}]}
{"op":"mcm","clk":"1009377944","pt":1580665277130,"mc":[{"id":"1.168236371","rc":[{"batb":[[0,1.67,62.17],[1,1.01,10.51]],"ltp":2.22,"tv":246.4,"id":4520808},{"batl":[[0,2.5,27.73]],"ltp":1.81,"tv":167.71,"id":8284479}]}]}
{"op":"mcm","clk":"1009378098","pt":1580665278053,"mc":[{"id":"1.168236371","rc":[{"batl":[[1,2.92,223.36]],"ltp":1.81,"tv":167.71,"id":8284479}]}]}
{"op":"mcm","clk":"1009379792","pt":1580665288148,"mc":[{"id":"1.168236371","rc":[{"batb":[[0,1.01,10.51],[1,1.01,0]],"ltp":2.22,"tv":246.4,"id":4520808},{"batl":[[0,2.92,223.36],[1,2.92,0]],"ltp":1.81,"tv":167.71,"id":8284479}]}]}
{"op":"mcm","clk":"1009380486","pt":1580665292167,"mc":[{"id":"1.168236371","rc":[{"batl":[[0,3,2.27],[1,3,0]],"ltp":2.22,"tv":246.4,"id":4520808}]}]}
{"op":"mcm","clk":"1009380644","pt":1580665293034,"mc":[{"id":"1.168236371","rc":[{"batb":[[0,1.73,57.13],[1,1.01,10.51]],"ltp":2.22,"tv":246.4,"id":4520808},{"batl":[[0,2.36,30.25]],"ltp":1.81,"tv":167.71,"id":8284479}]}]}
{"op":"mcm","clk":"1009381003","pt":1580665295222,"mc":[{"id":"1.168236371","rc":[{"batl":[[0,2.5,272.07],[1,3,2.27]],"ltp":2.22,"tv":246.4,"id":4520808},{"batl":[[1,2.72,243.8]],"ltp":1.81,"tv":167.71,"id":8284479}]}]}
{"op":"mcm","clk":"1009382397","pt":1580665303579,"mc":[{"id":"1.168236371","rc":[{"batb":[[0,1.01,10.51],[1,1.01,0]],"ltp":2.22,"tv":246.4,"id":4520808},{"batl":[[0,2.72,243.8],[1,2.72,0]],"ltp":1.81,"tv":167.71,"id":8284479}]}]}
{"op":"mcm","clk":"1009383554","pt":1580665310576,"mc":[{"id":"1.168236371","rc":[{"batb":[[0,1.77,53.77],[1,1.01,10.51]],"ltp":2.22,"tv":246.4,"id":4520808},{"batl":[[0,2.3,31.93]],"ltp":1.81,"tv":167.71,"id":8284479}]}]}
{"op":"mcm","clk":"1009383917","pt":1580665312879,"mc":[{"id":"1.168236371","rc":[{"batl":[[1,2.6,259.92]],"ltp":1.81,"tv":167.71,"id":8284479}]}]}
{"op":"mcm","clk":"1009385410","pt":1580665322181,"mc":[{"id":"1.168236371","rc":[{"batb":[[0,1.01,10.51],[1,1.01,0]],"ltp":2.22,"tv":246.4,"id":4520808},{"batl":[[0,2.6,259.92],[1,2.6,0]],"ltp":1.81,"tv":167.71,"id":8284479}]}]}
{"op":"mcm","clk":"1009386428","pt":1580665328768,"mc":[{"id":"1.168236371","rc":[{"batb":[[0,1.81,51.25],[1,1.01,10.51]],"ltp":2.22,"tv":246.4,"id":4520808},{"batl":[[0,2.24,33.61],[1,2.6,259.92]],"ltp":1.81,"tv":167.71,"id":8284479}]}]}
{"op":"mcm","clk":"1009390087","pt":1580665353817,"mc":[{"id":"1.168236371","rc":[{"batb":[[0,1.01,10.51],[1,1.01,0]],"ltp":2.22,"tv":246.4,"id":4520808},{"batl":[[0,2.6,259.92],[1,2.6,0]],"ltp":1.81,"tv":167.71,"id":8284479}]}]}
{"op":"mcm","clk":"1009390533","pt":1580665356741,"mc":[{"id":"1.168236371","rc":[{"batl":[[0,3,2.27],[1,3,0]],"ltp":2.22,"tv":246.4,"id":4520808}]}]}
{"op":"mcm","clk":"1009411292","pt":1580665504867,"mc":[{"id":"1.168236371","rc":[{"batb":[[0,1.73,57.13],[1,1.01,10.51]],"batl":[[0,2.5,272.07],[1,3,2.27]],"ltp":2.22,"tv":246.4,"id":4520808},{"batl":[[0,2.36,30.25],[1,2.72,243.8]],"ltp":1.81,"tv":167.71,"id":8284479}]}]}
{"op":"mcm","clk":"1009412468","pt":1580665513660,"mc":[{"id":"1.168236371","rc":[{"batb":[[0,1.01,10.51],[1,1.01,0]],"ltp":2.22,"tv":246.4,"id":4520808},{"batl":[[0,2.72,243.8],[1,2.72,0]],"ltp":1.81,"tv":167.71,"id":8284479}]}]}
{"op":"mcm","clk":"1009414693","pt":1580665531004,"mc":[{"id":"1.168236371","rc":[{"batl":[[0,3,2.27],[1,3,0]],"ltp":2.22,"tv":246.4,"id":4520808}]}]}
{"op":"mcm","clk":"1009414931","pt":1580665532717,"mc":[{"id":"1.168236371","rc":[{"batb":[[0,1.67,62.17],[1,1.01,10.51]],"ltp":2.22,"tv":246.4,"id":4520808},{"batl":[[0,2.48,27.73],[1,2.72,243.8]],"ltp":1.81,"tv":167.71,"id":8284479}]}]}
{"op":"mcm","clk":"1009415192","pt":1580665534678,"mc":[{"id":"1.168236371","rc":[{"batl":[[0,2.36,296.56],[1,3,2.27]],"ltp":2.22,"tv":246.4,"id":4520808}]}]}
{"op":"mcm","clk":"1009417692","pt":1580665554012,"mc":[{"id":"1.168236371","rc":[{"batb":[[0,1.01,10.51],[1,1.01,0]],"ltp":2.22,"tv":246.4,"id":4520808},{"batl":[[0,2.72,243.8],[1,2.72,0]],"ltp":1.81,"tv":167.71,"id":8284479}]}]}
{"op":"mcm","clk":"1009418536","pt":1580665561040,"mc":[{"id":"1.168236371","rc":[{"batb":[[0,1.74,56.29],[1,1.01,10.51]],"ltp":2.22,"tv":246.4,"id":4520808},{"batl":[[0,2.34,31.09],[1,2.72,243.8]],"ltp":1.81,"tv":167.71,"id":8284479}]}]}
{"op":"mcm","clk":"1009420524","pt":1580665577784,"mc":[{"id":"1.168236371","rc":[{"batb":[[0,1.01,10.51],[1,1.01,0]],"ltp":2.22,"tv":246.4,"id":4520808},{"batl":[[0,2.72,243.8],[1,2.72,0]],"ltp":1.81,"tv":167.71,"id":8284479}]}]}
{"op":"mcm","clk":"1009422676","pt":1580665594662,"mc":[{"id":"1.168236371","rc":[{"batb":[[0,1.67,62.17],[1,1.01,10.51]],"ltp":2.22,"tv":246.4,"id":4520808},{"batl":[[0,2.48,27.73],[1,2.72,243.8]],"ltp":1.81,"tv":167.71,"id":8284479}]}]}
{"op":"mcm","clk":"1009424249","pt":1580665607772,"mc":[{"id":"1.168236371","rc":[{"batb":[[0,1.01,10.51],[1,1.01,0]],"ltp":2.22,"tv":246.4,"id":4520808},{"batl":[[0,2.72,243.8],[1,2.72,0]],"ltp":1.81,"tv":167.71,"id":8284479}]}]}
{"op":"mcm","clk":"1009426585","pt":1580665628753,"mc":[{"id":"1.168236371","rc":[{"batb":[[0,1.63,66.38],[1,1.01,10.51]],"ltp":2.22,"tv":246.4,"id":4520808},{"batl":[[0,2.58,26.05],[1,2.72,243.8]],"ltp":1.81,"tv":167.71,"id":8284479}]}]}
{"op":"mcm","clk":"1009429303","pt":1580665652240,"mc":[{"id":"1.168236371","rc":[{"trd":[[1.63,118.45]],"batb":[[0,1.63,24.37]],"ltp":1.63,"tv":330.42,"id":4520808}],"tv":498.14}]}
{"op":"mcm","clk":"1009429663","pt":1580665655528,"mc":[{"id":"1.168236371","rc":[{"batb":[[0,1.63,66.38]],"ltp":1.63,"tv":330.42,"id":4520808}]}]}
{"op":"mcm","clk":"1009429923","pt":1580665657759,"mc":[{"id":"1.168236371","rc":[{"batb":[[0,1.01,10.51],[1,1.01,0]],"ltp":1.63,"tv":330.42,"id":4520808},{"batl":[[0,2.72,243.8],[1,2.72,0]],"ltp":1.81,"tv":167.71,"id":8284479}]}]}
{"op":"mcm","clk":"1009430661","pt":1580665663940,"mc":[{"id":"1.168236371","rc":[{"batl":[[0,3,2.27],[1,3,0]],"ltp":1.63,"tv":330.42,"id":4520808}]}]}
{"op":"mcm","clk":"1009430795","pt":1580665665040,"mc":[{"id":"1.168236371","rc":[{"batb":[[0,1.5,84.02],[1,1.01,10.51]],"ltp":1.63,"tv":330.42,"id":4520808}]}]}
{"op":"mcm","clk":"1009431075","pt":1580665667671,"mc":[{"id":"1.168236371","rc":[{"batl":[[0,2.04,380.01],[1,3,2.27]],"ltp":1.63,"tv":330.42,"id":4520808},{"batl":[[0,2.96,21],[1,3.65,172.1]],"ltp":1.81,"tv":167.71,"id":8284479}]}]}
{"op":"mcm","clk":"1009431909","pt":1580665675169,"mc":[{"id":"1.168236371","rc":[{"batb":[[0,1.01,10.51],[1,1.01,0]],"ltp":1.63,"tv":330.42,"id":4520808}]}]}
{"op":"mcm","clk":"1009431967","pt":1580665675702,"mc":[{"id":"1.168236371","rc":[{"batl":[[0,3.65,172.1],[1,3.65,0]],"ltp":1.81,"tv":167.71,"id":8284479}]}]}
{"op":"mcm","clk":"1009432224","pt":1580665677982,"mc":[{"id":"1.168236371","rc":[{"batb":[[0,1.51,82.34],[1,1.01,10.51]],"ltp":1.63,"tv":330.42,"id":4520808}]}]}
{"op":"mcm","clk":"1009432369","pt":1580665679200,"mc":[{"id":"1.168236371","rc":[{"batb":[[0,1.01,10.51],[1,1.01,0]],"ltp":1.63,"tv":330.42,"id":4520808}]}]}
{"op":"mcm","clk":"1009432844","pt":1580665683189,"mc":[{"id":"1.168236371","rc":[{"batb":[[0,1.6,69.74],[1,1.01,10.51]],"ltp":1.63,"tv":330.42,"id":4520808},{"batl":[[0,2.66,25.21]],"ltp":1.81,"tv":167.71,"id":8284479}]}]}
{"op":"mcm","clk":"1009432959","pt":1580665684104,"mc":[{"id":"1.168236371","rc":[{"trd":[[1.6,153.79]],"batb":[[0,1.01,10.51],[1,1.01,0]],"ltp":1.6,"tv":484.17,"id":4520808},{"trd":[[2.66,8.6]],"batl":[[0,2.66,16.61],[1,3.15,202.37]],"ltp":2.66,"tv":176.31,"id":8284479}],"tv":660.49}]}
{"op":"mcm","clk":"1009433381","pt":1580665687373,"mc":[{"id":"1.168236371","rc":[{"batb":[[0,1.6,69.74],[1,1.01,10.51]],"ltp":1.6,"tv":484.17,"id":4520808},{"batl":[[0,2.66,25.01]],"ltp":2.66,"tv":176.31,"id":8284479}]}]}
{"op":"mcm","clk":"1009434436","pt":1580665695821,"mc":[{"id":"1.168236371","rc":[{"batb":[[0,1.01,10.51],[1,1.01,0]],"ltp":1.6,"tv":484.17,"id":4520808},{"batl":[[0,3.15,202.37],[1,3.15,0]],"ltp":2.66,"tv":176.31,"id":8284479}]}]}
{"op":"mcm","clk":"1009435972","pt":1580665709026,"mc":[{"id":"1.168236371","rc":[{"batb":[[0,1.44,94.94],[1,1.01,10.51]],"ltp":1.6,"tv":484.17,"id":4520808},{"batl":[[0,3.25,18.48]],"ltp":2.66,"tv":176.31,"id":8284479}]}]}
{"op":"mcm","clk":"1009436075","pt":1580665710228,"mc":[{"id":"1.168236371","rc":[{"batl":[[1,3.9,159.82]],"ltp":2.66,"tv":176.31,"id":8284479}]}]}
{"op":"mcm","clk":"1009437296","pt":1580665721217,"mc":[{"id":"1.168236371","rc":[{"trd":[[1.44,58.81]],"batb":[[0,1.44,65.54]],"ltp":1.44,"tv":542.99,"id":4520808}],"tv":719.3}]}
{"op":"mcm","clk":"1009437605","pt":1580665724135,"mc":[{"id":"1.168236371","rc":[{"batb":[[0,1.44,94.94]],"ltp":1.44,"tv":542.99,"id":4520808}]}]}
{"op":"mcm","clk":"1009438017","pt":1580665727719,"mc":[{"id":"1.168236371","rc":[{"batb":[[0,1.01,10.51],[1,1.01,0]],"ltp":1.44,"tv":542.99,"id":4520808},{"batl":[[0,3.9,159.82],[1,3.9,0]],"ltp":2.66,"tv":176.31,"id":8284479}]}]}
{"op":"mcm","clk":"1009438147","pt":1580665729040,"mc":[{"id":"1.168236371","rc":[{"batb":[[0,1.99,8.44],[1,1.01,10.51]],"ltp":2.66,"tv":176.31,"id":8284479}]}]}
{"op":"mcm","clk":"1009438795","pt":1580665735185,"mc":[{"id":"1.168236371","rc":[{"batb":[[0,1.56,74.78],[1,1.01,10.51]],"ltp":1.44,"tv":542.99,"id":4520808},{"batl":[[0,2.78,23.53]],"ltp":2.66,"tv":176.31,"id":8284479}]}]}
{"op":"mcm","clk":"1009438992","pt":1580665737008,"mc":[{"id":"1.168236371","rc":[{"batl":[[1,3.15,202.37]],"ltp":2.66,"tv":176.31,"id":8284479}]}]}
{"op":"mcm","clk":"1009440393","pt":1580665749886,"mc":[{"id":"1.168236371","rc":[{"batb":[[0,1.01,10.51],[1,1.01,0]],"ltp":1.44,"tv":542.99,"id":4520808},{"batl":[[0,3.15,202.37],[1,3.15,0]],"ltp":2.66,"tv":176.31,"id":8284479}]}]}
{"op":"mcm","clk":"1009442027","pt":1580665765679,"mc":[{"id":"1.168236371","rc":[{"batl":[[0,3,2.27],[1,3,0]],"ltp":1.44,"tv":542.99,"id":4520808}]}]}
{"op":"mcm","clk":"1009442389","pt":1580665769105,"mc":[{"id":"1.168236371","rc":[{"batb":[[0,1.7,59.65],[1,1.01,10.51]],"batl":[[0,2.5,272.07],[1,3,2.27]],"ltp":1.44,"tv":542.99,"id":4520808},{"batl":[[0,2.42,29.41],[1,2.72,243.8]],"ltp":2.66,"tv":176.31,"id":8284479}]}]}
{"op":"mcm","clk":"1009442876","pt":1580665773223,"mc":[{"id":"1.168236371","rc":[{"batb":[[0,1.01,10.51],[1,1.01,0]],"ltp":2.66,"tv":176.31,"id":8284479}]}]}
{"op":"mcm","clk":"1009444266","pt":1580665788132,"mc":[{"id":"1.168236371","rc":[{"batb":[[0,1.01,10.51],[1,1.01,0]],"ltp":1.44,"tv":542.99,"id":4520808},{"batl":[[0,2.72,243.8],[1,2.72,0]],"ltp":2.66,"tv":176.31,"id":8284479}]}]}
{"op":"mcm","clk":"1009446902","pt":1580665816116,"mc":[{"id":"1.168236371","rc":[{"batl":[[0,3,2.27],[1,3,0]],"ltp":1.44,"tv":542.99,"id":4520808}]}]}
{"op":"mcm","clk":"1009446976","pt":1580665816892,"mc":[{"id":"1.168236371","rc":[{"batb":[[0,1.56,74.78],[1,1.01,10.51]],"ltp":1.44,"tv":542.99,"id":4520808},{"batl":[[0,2.76,23.53]],"ltp":2.66,"tv":176.31,"id":8284479}]}]}
{"op":"mcm","clk":"1009447235","pt":1580665819732,"mc":[{"id":"1.168236371","rc":[{"batl":[[0,2.16,339.98],[1,3,2.27]],"ltp":1.44,"tv":542.99,"id":4520808},{"batl":[[1,3.3,193.79]],"ltp":2.66,"tv":176.31,"id":8284479}]}]}
{"op":"mcm","clk":"1009448839","pt":1580665835742,"mc":[{"id":"1.168236371","rc":[{"batb":[[0,1.01,10.51],[1,1.01,0]],"ltp":1.44,"tv":542.99,"id":4520808},{"batl":[[0,3.3,193.79],[1,3.3,0]],"ltp":2.66,"tv":176.31,"id":8284479}]}]}
{"op":"mcm","clk":"1009451330","pt":1580665861042,"mc":[{"id":"1.168236371","rc":[{"batl":[[0,3,2.27],[1,3,0]],"ltp":1.44,"tv":542.99,"id":4520808}]}]}
{"op":"mcm","clk":"1009452541","pt":1580665872779,"mc":[{"id":"1.168236371","rc":[{"batb":[[0,1.69,60.49],[1,1.01,10.51]],"ltp":1.44,"tv":542.99,"id":4520808},{"batl":[[0,2.44,28.57]],"ltp":2.66,"tv":176.31,"id":8284479}]}]}
{"op":"mcm","clk":"1009452803","pt":1580665875235,"mc":[{"id":"1.168236371","rc":[{"batb":[[0,1.01,10.51],[1,1.01,0]],"batl":[[0,2.42,283.99],[1,3,2.27]],"ltp":1.44,"tv":542.99,"id":4520808},{"batl":[[1,2.82,233.45]],"ltp":2.66,"tv":176.31,"id":8284479}]}]}
{"op":"mcm","clk":"1009453102","pt":1580665878154,"mc":[{"id":"1.168236371","rc":[{"batb":[[0,1.7,59.65],[1,1.01,10.51]],"ltp":1.44,"tv":542.99,"id":4520808}]}]}
{"op":"mcm","clk":"1009453147","pt":1580665878674,"mc":[{"id":"1.168236371","rc":[{"batl":[[0,2.82,233.45],[1,2.82,0]],"ltp":2.66,"tv":176.31,"id":8284479}]}]}
{"op":"mcm","clk":"1009453456","pt":1580665881904,"mc":[{"id":"1.168236371","rc":[{"batb":[[0,1.01,10.51],[1,1.01,0]],"ltp":1.44,"tv":542.99,"id":4520808}]}]}
{"op":"mcm","clk":"1009455655","pt":1580665903204,"mc":[{"id":"1.168236371","rc":[{"batl":[[0,3,2.27],[1,3,0]],"ltp":1.44,"tv":542.99,"id":4520808}]}]}
{"op":"mcm","clk":"1009455790","pt":1580665904719,"mc":[{"id":"1.168236371","rc":[{"batb":[[0,1.55,75.62],[1,1.01,10.51]],"ltp":1.44,"tv":542.99,"id":4520808},{"batl":[[0,2.8,22.69]],"ltp":2.66,"tv":176.31,"id":8284479}]}]}
{"op":"mcm","clk":"1009456018","pt":1580665907004,"mc":[{"id":"1.168236371","rc":[{"batl":[[0,2.16,339.98],[1,3,2.27]],"ltp":1.44,"tv":542.99,"id":4520808},{"batl":[[1,3.3,193.79]],"ltp":2.66,"tv":176.31,"id":8284479}]}]}
{"op":"mcm","clk":"1009456587","pt":1580665912816,"mc":[{"id":"1.168236371","rc":[{"batb":[[0,1.01,10.51],[1,1.01,0]],"ltp":1.44,"tv":542.99,"id":4520808}]}]}
{"op":"mcm","clk":"1009456948","pt":1580665915727,"mc":[{"id":"1.168236371","rc":[{"batb":[[0,1.56,74.78],[1,1.01,10.51]],"ltp":1.44,"tv":542.99,"id":4520808}]}]}
{"op":"mcm","clk":"1009458452","pt":1580665930045,"mc":[{"id":"1.168236371","rc":[{"batb":[[0,1.01,10.51],[1,1.01,0]],"ltp":1.44,"tv":542.99,"id":4520808},{"batl":[[0,3.3,193.79],[1,3.3,0]],"ltp":2.66,"tv":176.31,"id":8284479}]}]}
{"op":"mcm","clk":"1009459302","pt":1580665937956,"mc":[{"id":"1.168236371","rc":[{"batl":[[0,2,6.45],[1,2.16,339.98],[2,3,2.27]],"ltp":1.44,"tv":542.99,"id":4520808}]}]}
{"op":"mcm","clk":"1009460087","pt":1580665945889,"mc":[{"id":"1.168236371","rc":[{"batl":[[2,3,0]],"ltp":1.44,"tv":542.99,"id":4520808}]}]}
{"op":"mcm","clk":"1009461728","pt":1580665965237,"mc":[{"id":"1.168236371","rc":[{"batl":[[1,2.16,0]],"ltp":1.44,"tv":542.99,"id":4520808}]}]}
{"op":"mcm","clk":"1009461890","pt":1580665967219,"mc":[{"id":"1.168236371","rc":[{"batb":[[0,1.37,113.43],[1,1.01,10.51]],"ltp":1.44,"tv":542.99,"id":4520808},{"batl":[[0,3.7,15.12]],"ltp":2.66,"tv":176.31,"id":8284479}]}]}
{"op":"mcm","clk":"1009462026","pt":1580665968903,"mc":[{"id":"1.168236371","rc":[{"batl":[[0,1.82,465.8],[1,2,6.45]],"ltp":1.44,"tv":542.99,"id":4520808},{"batl":[[1,4.6,137.41]],"ltp":2.66,"tv":176.31,"id":8284479}]}]}
{"op":"mcm","clk":"1009463072","pt":1580665980166,"mc":[{"id":"1.168236371","rc":[{"batl":[[0,1.45,42.01],[1,1.82,465.8],[2,2,6.45]],"ltp":1.44,"tv":542.99,"id":4520808}]}]}
{"op":"mcm","clk":"1009463752","pt":1580665987041,"mc":[{"id":"1.168236371","rc":[{"batb":[[1,1.01,682.66]],"ltp":1.44,"tv":542.99,"id":4520808}]}]}
{"op":"mcm","clk":"1009463849","pt":1580665987941,"mc":[{"id":"1.168236371","rc":[{"batb":[[0,1.01,682.66],[1,1.01,0]],"batl":[[0,1.82,465.8],[1,2,6.45],[2,2,0]],"ltp":1.44,"tv":542.99,"id":4520808},{"batl":[[0,4.6,137.41],[1,4.6,0]],"ltp":2.66,"tv":176.31,"id":8284479}]}]}
{"op":"mcm","clk":"1009464053","pt":1580665989870,"mc":[{"id":"1.168236371","rc":[{"batl":[[0,2,6.45],[1,2,0]],"ltp":1.44,"tv":542.99,"id":4520808}]}]}
{"op":"mcm","clk":"1009464549","pt":1580665995040,"mc":[{"id":"1.168236371","rc":[{"batb":[[0,1.55,75.62],[1,1.01,682.66]],"batl":[[0,1.67,42.01],[1,2,6.45]],"ltp":1.44,"tv":542.99,"id":4520808},{"batl":[[0,2.8,22.69]],"ltp":2.66,"tv":176.31,"id":8284479}]}]}
{"op":"mcm","clk":"1009464642","pt":1580665996133,"mc":[{"id":"1.168236371","rc":[{"batl":[[2,2.16,339.98]],"ltp":1.44,"tv":542.99,"id":4520808},{"batl":[[1,3.3,193.79]],"ltp":2.66,"tv":176.31,"id":8284479}]}]}
{"op":"mcm","clk":"1009466440","pt":1580666013079,"mc":[{"id":"1.168236371","rc":[{"batb":[[1,1.01,10.51]],"ltp":1.44,"tv":542.99,"id":4520808}]}]}
{"op":"mcm","clk":"1009466675","pt":1580666015184,"mc":[{"id":"1.168236371","rc":[{"batb":[[0,1.01,10.51],[1,1.01,0]],"ltp":1.44,"tv":542.99,"id":4520808},{"batl":[[0,3.3,193.79],[1,3.3,0]],"ltp":2.66,"tv":176.31,"id":8284479}]}]}
{"op":"mcm","clk":"1009466771","pt":1580666016201,"mc":[{"id":"1.168236371","rc":[{"batl":[[0,2,6.45],[1,2.16,339.98],[2,2.16,0]],"ltp":1.44,"tv":542.99,"id":4520808}]}]}
{"op":"mcm","clk":"1009467496","pt":1580666023064,"mc":[{"id":"1.168236371","rc":[{"batl":[[1,2.16,0]],"ltp":1.44,"tv":542.99,"id":4520808}]}]}
{"op":"mcm","clk":"1009467677","pt":1580666025063,"mc":[{"id":"1.168236371","rc":[{"batb":[[0,1.36,115.95],[1,1.01,10.51]],"ltp":1.44,"tv":542.99,"id":4520808},{"batl":[[0,3.75,15.12]],"ltp":2.66,"tv":176.31,"id":8284479}]}]}
{"op":"mcm","clk":"1009467790","pt":1580666026538,"mc":[{"id":"1.168236371","rc":[{"batl":[[0,1.82,465.8],[1,2,6.45]],"ltp":1.44,"tv":542.99,"id":4520808},{"batl":[[1,4.6,137.41]],"ltp":2.66,"tv":176.31,"id":8284479}]}]}
{"op":"mcm","clk":"1009468713","pt":1580666036000,"mc":[{"id":"1.168236371","rc":[{"batl":[[0,2,6.45],[1,2,0]],"ltp":1.44,"tv":542.99,"id":4520808},{"batl":[[1,4.6,0]],"ltp":2.66,"tv":176.31,"id":8284479}]}]}
{"op":"mcm","clk":"1009469310","pt":1580666042124,"mc":[{"id":"1.168236371","rc":[{"batb":[[0,1.01,10.51],[1,1.01,0]],"ltp":1.44,"tv":542.99,"id":4520808}]}]}
{"op":"mcm","clk":"1009470474","pt":1580666052802,"mc":[{"id":"1.168236371","rc":[{"batb":[[0,1.54,77.3],[1,1.01,10.51]],"ltp":1.44,"tv":542.99,"id":4520808},{"batl":[[0,2.84,22.69]],"ltp":2.66,"tv":176.31,"id":8284479}]}]}
{"op":"mcm","clk":"1009471117","pt":1580666059830,"mc":[{"id":"1.168236371","rc":[{"batb":[[0,2.52,26.89],[1,1.01,10.51]],"ltp":2.66,"tv":176.31,"id":8284479}]}]}
{"op":"mcm","clk":"1009472231","pt":1580666071848,"mc":[{"id":"1.168236371","rc":[{"batb":[[0,1.01,10.51],[1,1.01,0]],"ltp":1.44,"tv":542.99,"id":4520808},{"batb":[[0,1.01,10.51],[1,1.01,0]],"ltp":2.66,"tv":176.31,"id":8284479}]}]}
{"op":"mcm","clk":"1009472536","pt":1580666075050,"mc":[{"id":"1.168236371","rc":[{"batl":[[0,1.54,47.28],[1,2,6.45]],"ltp":1.44,"tv":542.99,"id":4520808}]}]}
{"op":"mcm","clk":"1009474385","pt":1580666093158,"mc":[{"id":"1.168236371","rc":[{"batb":[[0,1.36,115.95],[1,1.01,10.51]],"ltp":1.44,"tv":542.99,"id":4520808},{"batl":[[0,3.8,14.28]],"ltp":2.66,"tv":176.31,"id":8284479}]}]}
{"op":"mcm","clk":"1009474497","pt":1580666094165,"mc":[{"id":"1.168236371","rc":[{"batl":[[1,1.82,465.8],[2,2,6.45]],"ltp":1.44,"tv":542.99,"id":4520808},{"batl":[[1,4.6,137.41]],"ltp":2.66,"tv":176.31,"id":8284479}]}]}
{"op":"mcm","clk":"1009476306","pt":1580666112076,"mc":[{"id":"1.168236371","rc":[{"batb":[[0,1.01,10.51],[1,1.01,0]],"ltp":1.44,"tv":542.99,"id":4520808},{"batl":[[0,4.6,137.41],[1,4.6,0]],"ltp":2.66,"tv":176.31,"id":8284479}]}]}
{"op":"mcm","clk":"1009476494","pt":1580666114218,"mc":[{"id":"1.168236371","rc":[{"batl":[[1,2,6.45],[2,2,0]],"ltp":1.44,"tv":542.99,"id":4520808}]}]}
{"op":"mcm","clk":"1009477001","pt":1580666119992,"mc":[{"id":"1.168236371","rc":[{"batl":[[1,1.73,524.08],[2,2,6.45]],"ltp":1.44,"tv":542.99,"id":4520808},{"batl":[[0,5.3,119.96]],"ltp":2.66,"tv":176.31,"id":8284479}]}]}
{"op":"mcm","clk":"1009477732","pt":1580666127988,"mc":[{"id":"1.168236371","rc":[{"batl":[[1,2,6.45],[2,2,0]],"ltp":1.44,"tv":542.99,"id":4520808}]}]}
{"op":"mcm","clk":"1009478360","pt":1580666135206,"mc":[{"id":"1.168236371","rc":[{"trd":[[1.54,63.84]],"batb":[[0,1.53,78.98],[1,1.01,10.51]],"batl":[[0,1.54,15.36]],"ltp":1.54,"tv":606.83,"id":4520808},{"batl":[[0,2.88,21.85]],"ltp":2.66,"tv":176.31,"id":8284479}],"tv":783.14}]}
{"op":"mcm","clk":"1009478460","pt":1580666136111,"mc":[{"id":"1.168236371","rc":[{"batl":[[2,2.1,360.39]],"ltp":1.54,"tv":606.83,"id":4520808},{"batl":[[1,3.45,182.18]],"ltp":2.66,"tv":176.31,"id":8284479}]}]}
{"op":"mcm","clk":"1009478671","pt":1580666138212,"mc":[{"id":"1.168236371","rc":[{"trd":[[1.54,94.08]],"batl":[[0,2,6.7],[1,2.1,360.39],[2,2.1,0]],"ltp":1.54,"tv":637.07,"id":4520808}],"tv":813.38}]}
{"op":"mcm","clk":"1009480257","pt":1580666154141,"mc":[{"id":"1.168236371","rc":[{"batb":[[0,1.01,10.51],[1,1.01,0]],"ltp":1.54,"tv":637.07,"id":4520808},{"batl":[[0,3.45,182.18],[1,3.45,0]],"ltp":2.66,"tv":176.31,"id":8284479}]}]}
{"op":"mcm","clk":"1009482326","pt":1580666175245,"mc":[{"id":"1.168236371","rc":[{"batl":[[1,2.1,0]],"ltp":1.54,"tv":637.07,"id":4520808}]}]}
{"op":"mcm","clk":"1009482491","pt":1580666177041,"mc":[{"id":"1.168236371","rc":[{"batb":[[0,1.35,119.31],[1,1.01,10.51]],"ltp":1.54,"tv":637.07,"id":4520808},{"batl":[[0,3.8,14.28]],"ltp":2.66,"tv":176.31,"id":8284479}]}]}
{"op":"mcm","clk":"1009482691","pt":1580666179069,"mc":[{"id":"1.168236371","rc":[{"batl":[[0,1.77,497.45],[1,2,6.45]],"ltp":1.54,"tv":637.07,"id":4520808},{"batl":[[1,4.9,127.52]],"ltp":2.66,"tv":176.31,"id":8284479}]}]}
{"op":"mcm","clk":"1009483939","pt":1580666192070,"mc":[{"id":"1.168236371","rc":[{"batl":[[0,4.9,127.52],[1,4.9,0]],"ltp":2.66,"tv":176.31,"id":8284479}]}]}
{"op":"mcm","clk":"1009484214","pt":1580666195164,"mc":[{"id":"1.168236371","rc":[{"batl":[[0,3.85,14.28],[1,4.9,127.52]],"ltp":2.66,"tv":176.31,"id":8284479}]}]}
{"op":"mcm","clk":"1009484637","pt":1580666199866,"mc":[{"id":"1.168236371","rc":[{"batb":[[0,1.01,10.51],[1,1.01,0]],"ltp":1.54,"tv":637.07,"id":4520808},{"batl":[[0,4.9,127.52],[1,4.9,0]],"ltp":2.66,"tv":176.31,"id":8284479}]}]}
{"op":"mcm","clk":"1009484731","pt":1580666200869,"mc":[{"id":"1.168236371","rc":[{"batl":[[0,2,6.7],[1,2,0]],"ltp":1.54,"tv":637.07,"id":4520808}]}]}
{"op":"mcm","clk":"1009487842","pt":1580666230939,"mc":[{"id":"1.168236371","rc":[{"batl":[[0,1.16,42.01],[1,2,6.7]],"ltp":1.54,"tv":637.07,"id":4520808},{"batb":[[0,7.4,5.88],[1,1.01,10.51]],"batl":[[0,9.2,5.04]],"ltp":2.66,"tv":176.31,"id":8284479}]}]}
{"op":"mcm","clk":"1009488204","pt":1580666234106,"mc":[{"id":"1.168236371","rc":[{"batb":[[0,1.12,168.04],[1,1.01,10.51]],"batl":[[1,1.49,757.71],[2,2,6.7]],"ltp":1.54,"tv":637.07,"id":4520808},{"batl":[[1,9.8,75.9]],"ltp":2.66,"tv":176.31,"id":8284479}]}]}
{"op":"mcm","clk":"1009490016","pt":1580666252242,"mc":[{"id":"1.168236371","rc":[{"trd":[[1.16,121.01]],"batl":[[0,1.49,757.71],[1,2,6.7],[2,2,0]],"ltp":1.16,"tv":758.08,"id":4520808},{"trd":[[7.4,5.8]],"batb":[[0,1.01,10.59],[1,1.01,0]],"batl":[[0,9.8,75.9],[1,9.8,0]],"ltp":7.4,"tv":182.11,"id":8284479}],"tv":940.19}]}
{"op":"mcm","clk":"1009490309","pt":1580666255028,"mc":[{"id":"1.168236371","rc":[{"batl":[[0,1.16,42.01],[1,1.49,757.71],[2,2,6.7]],"ltp":1.16,"tv":758.08,"id":4520808},{"batb":[[0,7.4,5.13],[1,1.01,10.51]],"batl":[[0,9,5.04],[1,9.8,75.9]],"ltp":7.4,"tv":182.11,"id":8284479}]}]}
{"op":"mcm","clk":"1009492464","pt":1580666275772,"mc":[{"id":"1.168236371","rc":[{"trd":[[1.16,237.02]],"batl":[[0,1.49,757.71],[1,2,6.7],[2,2,0]],"ltp":1.16,"tv":874.09,"id":4520808},{"trd":[[7.4,10.81]],"batb":[[0,1.01,10.51],[1,1.01,0]],"ltp":7.4,"tv":187.12,"id":8284479}],"tv":1061.22}]}
{"op":"mcm","clk":"1009492788","pt":1580666278749,"mc":[{"id":"1.168236371","rc":[{"batl":[[0,1.16,42.01],[1,1.49,757.71],[2,2,6.7]],"ltp":1.16,"tv":874.09,"id":4520808},{"batb":[[0,7.2,6.72],[1,1.01,10.51]],"ltp":7.4,"tv":187.12,"id":8284479}]}]}
{"op":"mcm","clk":"1009497427","pt":1580666324027,"mc":[{"id":"1.168236371","rc":[{"batb":[[0,1.01,10.51],[1,1.01,0]],"batl":[[0,1.49,757.71],[1,2,6.7],[2,2,0]],"ltp":1.16,"tv":874.09,"id":4520808},{"batb":[[0,1.01,10.51],[1,1.01,0]],"batl":[[0,9.8,75.9],[1,9.8,0]],"ltp":7.4,"tv":187.12,"id":8284479}]}]}
{"op":"mcm","clk":"1009498099","pt":1580666331245,"mc":[{"id":"1.168236371","rc":[{"batb":[[0,1.1,168.04],[1,1.01,10.51]],"batl":[[0,1.13,42.01],[1,1.49,757.71],[2,2,6.7]],"ltp":1.16,"tv":874.09,"id":4520808},{"batb":[[0,8.6,5.04],[1,1.01,10.51]],"batl":[[0,11,4.2]],"ltp":7.4,"tv":187.12,"id":8284479}]}]}
{"op":"mcm","clk":"1009498242","pt":1580666332818,"mc":[{"id":"1.168236371","rc":[{"batl":[[1,12.5,66.47]],"ltp":7.4,"tv":187.12,"id":8284479}]}]}
{"op":"mcm","clk":"1009499135","pt":1580666342160,"mc":[{"id":"1.168236371","rc":[{"batb":[[0,1.01,10.51],[1,1.01,0]],"batl":[[0,1.49,757.71],[1,2,6.7],[2,2,0]],"ltp":1.16,"tv":874.09,"id":4520808},{"batb":[[0,1.01,10.51],[1,1.01,0]],"batl":[[0,12.5,66.47],[1,12.5,0]],"ltp":7.4,"tv":187.12,"id":8284479}]}]}
{"op":"mcm","clk":"1009501042","pt":1580666361150,"mc":[{"id":"1.168236371","rc":[{"batl":[[0,1.17,42.01],[1,1.49,757.71],[2,2,6.7]],"ltp":1.16,"tv":874.09,"id":4520808},{"batb":[[0,6.8,6.72],[1,1.01,10.51]],"batl":[[0,8.2,5.04],[1,8.4,5.04]],"ltp":7.4,"tv":187.12,"id":8284479}]}]}
{"op":"mcm","clk":"1009501053","pt":1580666361291,"mc":[{"id":"1.168236371","rc":[{"batl":[[1,8.4,0]],"ltp":7.4,"tv":187.12,"id":8284479}]}]}
{"op":"mcm","clk":"1009501245","pt":1580666363186,"mc":[{"id":"1.168236371","rc":[{"batl":[[1,9.8,75.9]],"ltp":7.4,"tv":187.12,"id":8284479}]}]}
{"op":"mcm","clk":"1009502409","pt":1580666374892,"mc":[{"id":"1.168236371","rc":[{"batl":[[0,1.49,757.71],[1,2,6.7],[2,2,0]],"ltp":1.16,"tv":874.09,"id":4520808}]}]}
{"op":"mcm","clk":"1009502692","pt":1580666378071,"mc":[{"id":"1.168236371","rc":[{"batb":[[0,1.14,168.04],[1,1.01,10.51]],"ltp":1.16,"tv":874.09,"id":4520808}]}]}
{"op":"mcm","clk":"1009503259","pt":1580666384103,"mc":[{"id":"1.168236371","rc":[{"batb":[[0,1.01,10.51],[1,1.01,0]],"ltp":1.16,"tv":874.09,"id":4520808},{"batb":[[0,1.01,10.51],[1,1.01,0]],"batl":[[0,9.8,75.9],[1,9.8,0]],"ltp":7.4,"tv":187.12,"id":8284479}]}]}
{"op":"mcm","clk":"1009503310","pt":1580666384582,"mc":[{"id":"1.168236371","rc":[{"batl":[[0,1.14,8.4],[1,1.49,757.71],[2,2,6.7]],"ltp":1.16,"tv":874.09,"id":4520808}]}]}
{"op":"mcm","clk":"1009506015","pt":1580666411036,"mc":[{"id":"1.168236371","rc":[{"batb":[[0,8.4,5.04],[1,1.01,10.51]],"batl":[[0,10.5,4.2]],"ltp":7.4,"tv":187.12,"id":8284479}]}]}
{"op":"mcm","clk":"1009506187","pt":1580666413221,"mc":[{"id":"1.168236371","rc":[{"batl":[[1,12.5,66.47]],"ltp":7.4,"tv":187.12,"id":8284479}]}]}
{"op":"mcm","clk":"1009507953","pt":1580666433058,"mc":[{"id":"1.168236371","rc":[{"batl":[[1,1.36,56.24],[2,1.49,757.71]],"ltp":1.16,"tv":874.09,"id":4520808}]}]}
{"op":"mcm","clk":"1009508853","pt":1580666442049,"mc":[{"id":"1.168236371","rc":[{"batb":[[0,1.01,10.51],[1,1.01,0]],"batl":[[0,12.5,66.47],[1,12.5,0]],"ltp":7.4,"tv":187.12,"id":8284479}]}]}
{"op":"mcm","clk":"1009509508","pt":1580666449154,"mc":[{"id":"1.168236371","rc":[{"batl":[[2,2,6.7]],"ltp":1.16,"tv":874.09,"id":4520808}]}]}
{"op":"mcm","clk":"1009509730","pt":1580666451071,"mc":[{"id":"1.168236371","rc":[{"batl":[[0,1.11,42.01],[1,1.14,8.4],[2,1.36,56.24]],"ltp":1.16,"tv":874.09,"id":4520808},{"batb":[[0,10,4.2],[1,1.01,10.51]],"batl":[[0,13,3.36]],"ltp":7.4,"tv":187.12,"id":8284479}]}]}
{"op":"mcm","clk":"1009509814","pt":1580666452068,"mc":[{"id":"1.168236371","rc":[{"batl":[[2,1.4,923.53]],"ltp":1.16,"tv":874.09,"id":4520808},{"batl":[[1,17,57.7]],"ltp":7.4,"tv":187.12,"id":8284479}]}]}
{"op":"mcm","clk":"1009510477","pt":1580666459158,"mc":[{"id":"1.168236371","rc":[{"batb":[[0,1.07,332.59],[1,1.01,10.51]],"ltp":1.16,"tv":874.09,"id":4520808},{"batb":[[1,7.4,10.62],[2,1.01,10.51]],"ltp":7.4,"tv":187.12,"id":8284479}]}]}
{"op":"mcm","clk":"1009511201","pt":1580666466179,"mc":[{"id":"1.168236371","rc":[{"batl":[[0,1.14,8.4],[1,1.4,923.53],[2,2,6.7]],"ltp":1.16,"tv":874.09,"id":4520808},{"batb":[[0,7.4,10.62],[1,1.01,10.51],[2,1.01,0]],"batl":[[0,17,57.7],[1,17,0]],"ltp":7.4,"tv":187.12,"id":8284479}]}]}
{"op":"mcm","clk":"1009514298","pt":1580666498112,"mc":[{"id":"1.168236371","rc":[{"batb":[[1,1.05,472.8],[2,1.01,10.51]],"ltp":1.16,"tv":874.09,"id":4520808},{"batb":[[0,10.5,11.33],[1,9.4,15.42],[2,1.01,10.51]],"ltp":7.4,"tv":187.12,"id":8284479}]}]}
{"op":"mcm","clk":"1009514400","pt":1580666499223,"mc":[{"id":"1.168236371","rc":[{"batb":[[0,11.5,3.36],[1,10.5,11.33],[2,9.4,15.42]],"ltp":7.4,"tv":187.12,"id":8284479}]}]}
{"op":"mcm","clk":"1009514492","pt":1580666500115,"mc":[{"id":"1.168236371","rc":[{"batl":[[0,21,53.78]],"ltp":7.4,"tv":187.12,"id":8284479}]}]}
{"op":"mcm","clk":"1009516473","pt":1580666521032,"mc":[{"id":"1.168236371","rc":[{"batl":[[2,1.54,84.69]],"ltp":1.16,"tv":874.09,"id":4520808}]}]}
{"op":"mcm","clk":"1009517728","pt":1580666534125,"mc":[{"id":"1.168236371","rc":[{"batl":[[2,2,6.7]],"ltp":1.16,"tv":874.09,"id":4520808}]}]}
{"op":"mcm","clk":"1009519208","pt":1580666550145,"mc":[{"id":"1.168236371","rc":[{"batb":[[0,1.05,470.36],[1,1.01,10.51],[2,1.01,0]],"ltp":1.16,"tv":874.09,"id":4520808},{"batb":[[0,9.4,15.42],[1,1.01,10.51],[2,9.4,0]],"ltp":7.4,"tv":187.12,"id":8284479}]}]}
{"op":"mcm","clk":"1009520401","pt":1580666562098,"mc":[{"id":"1.168236371","rc":[{"batl":[[2,1.54,84.69]],"ltp":1.16,"tv":874.09,"id":4520808}]}]}
{"op":"mcm","clk":"1009520595","pt":1580666564003,"mc":[{"id":"1.168236371","rc":[{"batb":[[0,1.08,286.64],[1,1.06,361.94],[2,1.01,10.51]],"ltp":1.16,"tv":874.09,"id":4520808},{"batb":[[1,8.4,7.79],[2,1.01,10.51]],"ltp":7.4,"tv":187.12,"id":8284479}]}]}
{"op":"mcm","clk":"1009520710","pt":1580666565074,"mc":[{"id":"1.168236371","rc":[{"batb":[[0,1.08,454.68]],"batl":[[0,1.11,42.01],[1,1.14,8.4],[2,1.4,923.53]],"ltp":1.16,"tv":874.09,"id":4520808},{"batb":[[0,10.5,4.2],[1,9.4,15.42],[2,8.4,7.79]],"batl":[[0,13.5,3.36]],"ltp":7.4,"tv":187.12,"id":8284479}]}]}
{"op":"mcm","clk":"1009520892","pt":1580666566760,"mc":[{"id":"1.168236371","rc":[{"batl":[[1,17,57.7]],"ltp":7.4,"tv":187.12,"id":8284479}]}]}
{"op":"mcm","clk":"1009521647","pt":1580666574212,"mc":[{"id":"1.168236371","rc":[{"batb":[[0,1.06,361.94],[1,1.01,10.51],[2,1.01,0]],"batl":[[0,1.14,8.4],[1,1.4,923.53],[2,1.54,84.69]],"ltp":1.16,"tv":874.09,"id":4520808},{"batb":[[0,8.4,7.79],[1,1.01,10.51],[2,8.4,0]],"batl":[[0,17,57.7],[1,17,0]],"ltp":7.4,"tv":187.12,"id":8284479}]}]}
{"op":"mcm","clk":"1009521821","pt":1580666576213,"mc":[{"id":"1.168236371","rc":[{"batl":[[2,2,6.7]],"ltp":1.16,"tv":874.09,"id":4520808}]}]}
{"op":"mcm","clk":"1009522021","pt":1580666578319,"mc":[{"id":"1.168236371","rc":[{"batl":[[0,1.08,3.03],[1,1.14,8.4],[2,1.4,923.53]],"ltp":1.16,"tv":874.09,"id":4520808}]}]}
{"op":"mcm","clk":"1009522567","pt":1580666584128,"mc":[{"id":"1.168236371","rc":[{"batb":[[1,1.04,540.07],[2,1.01,10.51]],"ltp":1.16,"tv":874.09,"id":4520808},{"batb":[[0,11,10.39],[1,9.4,15.82],[2,1.01,10.51]],"ltp":7.4,"tv":187.12,"id":8284479}]}]}
{"op":"mcm","clk":"1009522684","pt":1580666585123,"mc":[{"id":"1.168236371","rc":[{"batb":[[0,1.07,168.04],[1,1.06,361.94],[2,1.04,540.07]],"ltp":1.16,"tv":874.09,"id":4520808},{"batb":[[0,11.5,3.36],[1,11,10.39],[2,9.4,15.82]],"ltp":7.4,"tv":187.12,"id":8284479}]}]}
{"op":"mcm","clk":"1009522886","pt":1580666587030,"mc":[{"id":"1.168236371","rc":[{"batl":[[0,21,53.78]],"ltp":7.4,"tv":187.12,"id":8284479}]}]}
{"op":"mcm","clk":"1009524352","pt":1580666601137,"mc":[{"id":"1.168236371","rc":[{"batb":[[1,1.04,540.07],[2,1.01,10.51]],"ltp":1.16,"tv":874.09,"id":4520808},{"batb":[[1,9.4,15.82],[2,1.01,10.51]],"ltp":7.4,"tv":187.12,"id":8284479}]}]}
{"op":"mcm","clk":"1009524442","pt":1580666602097,"mc":[{"id":"1.168236371","rc":[{"batb":[[0,1.04,540.07],[1,1.01,10.51],[2,1.01,0]],"ltp":1.16,"tv":874.09,"id":4520808},{"batb":[[0,9.4,15.82],[1,1.01,10.51],[2,1.01,0]],"ltp":7.4,"tv":187.12,"id":8284479}]}]}
{"op":"mcm","clk":"1009524721","pt":1580666604102,"mc":[{"id":"1.168236371","rc":[{"batb":[[1,9.2,15.82],[2,1.01,10.51]],"ltp":7.4,"tv":187.12,"id":8284479}]}]}
{"op":"mcm","clk":"1009524811","pt":1580666604999,"mc":[{"id":"1.168236371","rc":[{"batb":[[0,1.04,538.97]],"ltp":1.16,"tv":874.09,"id":4520808},{"batb":[[0,9.2,15.82],[1,1.01,10.51],[2,1.01,0]],"ltp":7.4,"tv":187.12,"id":8284479}]}]}
{"op":"mcm","clk":"1009524916","pt":1580666606013,"mc":[{"id":"1.168236371","rc":[{"batb":[[1,2.84,84.44],[2,1.01,10.51]],"ltp":7.4,"tv":187.12,"id":8284479}]}]}
{"op":"mcm","clk":"1009525275","pt":1580666609112,"mc":[{"id":"1.168236371","rc":[{"trd":[[1.08,6.06]],"batb":[[0,1.08,280.46],[1,1.06,377.2],[2,1.01,10.51]],"batl":[[0,1.14,8.4],[1,1.4,923.53],[2,2,6.7]],"ltp":1.08,"tv":880.15,"id":4520808},{"batb":[[0,10.5,4.2],[1,9.2,15.82],[2,8.4,7.95]],"batl":[[0,13.5,3.36]],"ltp":7.4,"tv":187.12,"id":8284479}],"tv":1067.27}]}
{"op":"mcm","clk":"1009525492","pt":1580666611137,"mc":[{"id":"1.168236371","rc":[{"batl":[[1,17,57.7]],"ltp":7.4,"tv":187.12,"id":8284479}]}]}
{"op":"mcm","clk":"1009525605","pt":1580666612040,"mc":[{"id":"1.168236371","rc":[{"batb":[[0,1.08,448.5]],"ltp":1.08,"tv":880.15,"id":4520808}]}]}
{"op":"mcm","clk":"1009526369","pt":1580666619035,"mc":[{"id":"1.168236371","rc":[{"batb":[[0,1.08,168.04]],"ltp":1.08,"tv":880.15,"id":4520808},{"batb":[[1,8.4,7.95],[2,1.01,10.51]],"ltp":7.4,"tv":187.12,"id":8284479}]}]}
{"op":"mcm","clk":"1009526476","pt":1580666620161,"mc":[{"id":"1.168236371","rc":[{"batb":[[0,1.06,377.2],[1,1.01,10.51],[2,1.01,0]],"ltp":1.08,"tv":880.15,"id":4520808},{"batb":[[0,8.4,7.95],[1,1.01,10.51],[2,1.01,0]],"batl":[[0,17,57.7],[1,17,0]],"ltp":7.4,"tv":187.12,"id":8284479}]}]}
{"op":"mcm","clk":"1009528903","pt":1580666643156,"mc":[{"id":"1.168236371","rc":[{"batb":[[1,1.03,679.81],[2,1.01,10.51]],"batl":[[0,1.09,42.01],[1,1.14,8.4],[2,1.4,923.53]],"ltp":1.08,"tv":880.15,"id":4520808},{"batb":[[0,12,3.36],[1,11.5,9.68],[2,9.2,16.21]],"ltp":7.4,"tv":187.12,"id":8284479}]}]}
{"op":"mcm","clk":"1009529165","pt":1580666645589,"mc":[{"id":"1.168236371","rc":[{"batl":[[0,24,50.78]],"ltp":7.4,"tv":187.12,"id":8284479}]}]}
{"op":"mcm","clk":"1009530977","pt":1580666662172,"mc":[{"id":"1.168236371","rc":[{"batb":[[0,1.03,679.81],[1,1.01,10.51],[2,1.01,0]],"batl":[[0,1.14,8.4],[1,1.4,923.53],[2,2,6.7]],"ltp":1.08,"tv":880.15,"id":4520808},{"batb":[[0,9.2,16.21],[1,1.01,10.51],[2,9.2,0]],"ltp":7.4,"tv":187.12,"id":8284479}]}]}
{"op":"mcm","clk":"1009532096","pt":1580666672077,"mc":[{"id":"1.168236371","rc":[{"batl":[[1,2,6.7],[2,2,0]],"ltp":1.08,"tv":880.15,"id":4520808}]}]}
{"op":"mcm","clk":"1009532569","pt":1580666676223,"mc":[{"id":"1.168236371","rc":[{"batb":[[0,17.5,7.24],[1,11.5,9.76],[2,9.2,16.21]],"ltp":7.4,"tv":187.12,"id":8284479}]}]}
{"op":"mcm","clk":"1009532684","pt":1580666677174,"mc":[{"id":"1.168236371","rc":[{"batl":[[0,1.06,42.01],[1,1.14,8.4],[2,2,6.7]],"ltp":1.08,"tv":880.15,"id":4520808},{"batb":[[2,1.01,10.51]],"ltp":7.4,"tv":187.12,"id":8284479}]}]}
{"op":"mcm","clk":"1009532867","pt":1580666678718,"mc":[{"id":"1.168236371","rc":[{"batl":[[2,1.34,1105.48]],"ltp":1.08,"tv":880.15,"id":4520808},{"batl":[[0,42,43.83]],"ltp":7.4,"tv":187.12,"id":8284479}]}]}
{"op":"mcm","clk":"1009533493","pt":1580666684672,"mc":[{"id":"1.168236371","rc":[{"batl":[[0,1.06,110.16]],"ltp":1.08,"tv":880.15,"id":4520808}]}]}
{"op":"mcm","clk":"1009534006","pt":1580666689768,"mc":[{"id":"1.168236371","rc":[{"batl":[[0,1.06,42.01]],"ltp":1.08,"tv":880.15,"id":4520808}]}]}
{"op":"mcm","clk":"1009534469","pt":1580666694196,"mc":[{"id":"1.168236371","rc":[{"batb":[[0,1.01,10.51],[1,1.01,0]],"batl":[[0,1.14,8.4],[1,1.34,1105.48],[2,2,6.7]],"ltp":1.08,"tv":880.15,"id":4520808},{"batb":[[0,11.5,9.76],[1,1.01,10.51],[2,1.01,0]],"ltp":7.4,"tv":187.12,"id":8284479}]}]}
{"op":"mcm","clk":"1009534572","pt":1580666695200,"mc":[{"id":"1.168236371","rc":[{"batl":[[1,2,6.7],[2,2,0]],"ltp":1.08,"tv":880.15,"id":4520808}]}]}
{"op":"mcm","clk":"1009535249","pt":1580666702494,"mc":[{"id":"1.168236371","rc":[{"batl":[[1,1.32,1155.45],[2,2,6.7]],"ltp":1.08,"tv":880.15,"id":4520808},{"batl":[[0,65,40.77]],"ltp":7.4,"tv":187.12,"id":8284479}]}]}
{"op":"mcm","clk":"1009535387","pt":1580666704134,"mc":[{"id":"1.168236371","rc":[{"batl":[[1,2,6.7],[2,2,0]],"ltp":1.08,"tv":880.15,"id":4520808}]}]}
{"op":"mcm","clk":"1009536834","pt":1580666718217,"mc":[{"id":"1.168236371","rc":[{"batb":[[0,1.01,10.51],[1,1.01,0]],"ltp":7.4,"tv":187.12,"id":8284479}]}]}
{"op":"mcm","clk":"1009537314","pt":1580666723488,"mc":[{"id":"1.168236371","rc":[{"batl":[[1,1.27,1355.93],[2,2,6.7]],"ltp":1.08,"tv":880.15,"id":4520808}]}]}
{"op":"mcm","clk":"1009538458","pt":1580666736138,"mc":[{"id":"1.168236371","rc":[{"trd":[[1.01,0.04]],"batb":[[0,1.01,10.49]],"ltp":1.01,"tv":880.18,"id":4520808}],"tv":1067.31}]}
{"op":"mcm","clk":"1009541519","pt":1580666768180,"mc":[{"id":"1.168236371","rc":[{"trd":[[1.01,21.01]],"batl":[[0,1.01,3.51],[1,1.14,8.4],[2,1.27,1355.93]],"ltp":1.01,"tv":901.16,"id":4520808}],"tv":1088.29}]}
{"op":"mcm","clk":"1009541648","pt":1580666769197,"mc":[{"id":"1.168236371","rc":[{"trd":[[1.01,27.1]],"batl":[[0,1.27,1356.4],[1,2,6.7],[2,1.27,0]],"ltp":1.01,"tv":907.24,"id":4520808}],"tv":1094.37}]}
{"op":"mcm","clk":"1009541969","pt":1580666772196,"mc":[{"id":"1.168236371","rc":[{"batl":[[0,1.1,819.66],[1,1.27,1355.93],[2,2,6.7]],"ltp":1.01,"tv":907.24,"id":4520808}]}]}
{"op":"mcm","clk":"1009545768","pt":1580666806011,"mc":[{"id":"1.168236371","rc":[{"trd":[[1.01,28.04]],"batb":[[0,1.01,2.57]],"batl":[[0,1.1,819.19]],"ltp":1.01,"tv":908.18,"id":4520808}],"tv":1095.31}]}
{"op":"mcm","clk":"1009547055","pt":1580666817477,"mc":[{"id":"1.168236371","rc":[{"batl":[[1,2,6.7],[2,2,0]],"ltp":1.01,"tv":908.18,"id":4520808}]}]}
{"op":"mcm","clk":"1009547738","pt":1580666824058,"mc":[{"id":"1.168236371","rc":[{"batl":[[1,1.27,1387.89],[2,2,6.7]],"ltp":1.01,"tv":908.18,"id":4520808}]}]}
{"op":"mcm","clk":"1009548445","pt":1580666830577,"mc":[{"id":"1.168236371","rc":[{"batl":[[1,2,6.7],[2,2,0]],"ltp":1.01,"tv":908.18,"id":4520808}]}]}
{"op":"mcm","clk":"1009549804","pt":1580666843090,"mc":[{"id":"1.168236371","rc":[{"batb":[[0,1.01,3.04]],"ltp":1.01,"tv":908.18,"id":4520808}]}]}
{"op":"mcm","clk":"1009550075","pt":1580666845964,"mc":[{"id":"1.168236371","rc":[{"batb":[[0,1.01,29.41]],"ltp":1.01,"tv":908.18,"id":4520808}]}]}
{"op":"mcm","clk":"1009550192","pt":1580666847185,"mc":[{"id":"1.168236371","rc":[{"batb":[[0,1.01,29.42]],"ltp":1.01,"tv":908.18,"id":4520808}]}]}
{"op":"mcm","clk":"1009550474","pt":1580666849784,"mc":[{"id":"1.168236371","rc":[{"batl":[[1,1.26,1409.25],[2,2,6.7]],"ltp":1.01,"tv":908.18,"id":4520808}]}]}
{"op":"mcm","clk":"1009551347","pt":1580666858567,"mc":[{"id":"1.168236371","rc":[{"batl":[[1,2,6.7],[2,2,0]],"ltp":1.01,"tv":908.18,"id":4520808}]}]}
{"op":"mcm","clk":"1009556764","pt":1580666910251,"mc":[{"id":"1.168236371","marketDefinition":{"bspMarket":false,"turnInPlayEnabled":true,"persistenceEnabled":true,"marketBaseRate":5.0,"eventId":"29681838","eventTypeId":"2","numberOfWinners":1,"bettingType":"ODDS","marketType":"SET_WINNER","marketTime":"2020-02-02T16:35:00.000Z","suspendTime":"2020-02-02T16:35:00.000Z","bspReconciled":false,"complete":true,"inPlay":true,"crossMatching":true,"runnersVoidable":false,"numberOfActiveRunners":2,"betDelay":3,"status":"SUSPENDED","runners":[{"status":"ACTIVE","sortPriority":1,"id":4520808,"name":"Facundo Bagnis"},{"status":"ACTIVE","sortPriority":2,"id":8284479,"name":"Federico Gaio"}],"regulators":["MR_INT"],"countryCode":"AR","discountAllowed":true,"timezone":"UTC","openDate":"2020-02-02T16:35:00.000Z","version":3150177350,"name":"Set 2 Winner","eventName":"Bagnis v Gaio"}}]}
{"op":"mcm","clk":"1009560305","pt":1580666943380,"mc":[{"id":"1.168236371","tv":0.0}]}
{"op":"mcm","clk":"1009560420","pt":1580666944329,"mc":[{"id":"1.168236371","marketDefinition":{"bspMarket":false,"turnInPlayEnabled":true,"persistenceEnabled":true,"marketBaseRate":5.0,"eventId":"29681838","eventTypeId":"2","numberOfWinners":1,"bettingType":"ODDS","marketType":"SET_WINNER","marketTime":"2020-02-02T16:35:00.000Z","suspendTime":"2020-02-02T16:35:00.000Z","bspReconciled":false,"complete":true,"inPlay":true,"crossMatching":false,"runnersVoidable":false,"numberOfActiveRunners":0,"betDelay":3,"status":"CLOSED","settledTime":"2020-02-02T18:09:01.000Z","runners":[{"status":"WINNER","sortPriority":1,"id":4520808,"name":"Facundo Bagnis"},{"status":"LOSER","sortPriority":2,"id":8284479,"name":"Federico Gaio"}],"regulators":["MR_INT"],"countryCode":"AR","discountAllowed":true,"timezone":"UTC","openDate":"2020-02-02T16:35:00.000Z","version":3150177672,"name":"Set 2 Winner","eventName":"Bagnis v Gaio"}}]}
