{"op":"mcm","clk":"1002113593","pt":1580590610212,"mc":[{"id":"1.168236370","marketDefinition":{"bspMarket":false,"turnInPlayEnabled":true,"persistenceEnabled":true,"marketBaseRate":5.0,"eventId":"29681838","eventTypeId":"2","numberOfWinners":1,"bettingType":"ODDS","marketType":"SET_WINNER","marketTime":"2020-02-02T16:00:00.000Z","suspendTime":"2020-02-02T16:00:00.000Z","bspReconciled":false,"complete":true,"inPlay":false,"crossMatching":false,"runnersVoidable":false,"numberOfActiveRunners":2,"betDelay":0,"status":"OPEN","runners":[{"status":"ACTIVE","sortPriority":1,"id":4520808,"name":"Facundo Bagnis"},{"status":"ACTIVE","sortPriority":2,"id":8284479,"name":"Federico Gaio"}],"regulators":["MR_INT"],"countryCode":"AR","discountAllowed":false,"timezone":"UTC","openDate":"2020-02-02T16:00:00.000Z","version":3147446738,"name":"Set 1 Winner","eventName":"Bagnis v Gaio"},"rc":[{"batb":[[0,1.01,20]],"ltp":0.0,"tv":0.0,"id":4520808},{"batb":[[0,1.01,20]],"ltp":0.0,"tv":0.0,"id":8284479}]}]}
{"op":"mcm","clk":"1002113713","pt":1580590611242,"mc":[{"id":"1.168236370","marketDefinition":{"bspMarket":false,"turnInPlayEnabled":true,"persistenceEnabled":true,"marketBaseRate":5.0,"eventId":"29681838","eventTypeId":"2","numberOfWinners":1,"bettingType":"ODDS","marketType":"SET_WINNER","marketTime":"2020-02-02T16:00:00.000Z","suspendTime":"2020-02-02T16:00:00.000Z","bspReconciled":false,"complete":true,"inPlay":false,"crossMatching":false,"runnersVoidable":false,"numberOfActiveRunners":2,"betDelay":0,"status":"OPEN","runners":[{"status":"ACTIVE","sortPriority":1,"id":4520808,"name":"Facundo Bagnis"},{"status":"ACTIVE","sortPriority":2,"id":8284479,"name":"Federico Gaio"}],"regulators":["MR_INT"],"countryCode":"AR","discountAllowed":false,"timezone":"UTC","openDate":"2020-02-02T16:00:00.000Z","version":3147446738,"name":"Set 1 Winner","eventName":"Bagnis v Gaio"}}]}
{"op":"mcm","clk":"1002113926","pt":1580590613250,"mc":[{"id":"1.168236370","marketDefinition":{"bspMarket":false,"turnInPlayEnabled":true,"persistenceEnabled":true,"marketBaseRate":5.0,"eventId":"29681838","eventTypeId":"2","numberOfWinners":1,"bettingType":"ODDS","marketType":"SET_WINNER","marketTime":"2020-02-02T16:00:00.000Z","suspendTime":"2020-02-02T16:00:00.000Z","bspReconciled":false,"complete":true,"inPlay":false,"crossMatching":false,"runnersVoidable":false,"numberOfActiveRunners":2,"betDelay":0,"status":"OPEN","runners":[{"status":"ACTIVE","sortPriority":1,"id":4520808,"name":"Facundo Bagnis"},{"status":"ACTIVE","sortPriority":2,"id":8284479,"name":"Federico Gaio"}],"regulators":["MR_INT"],"countryCode":"AR","discountAllowed":true,"timezone":"UTC","openDate":"2020-02-02T16:00:00.000Z","version":3147446738,"name":"Set 1 Winner","eventName":"Bagnis v Gaio"}}]}
{"op":"mcm","clk":"1002136314","pt":1580590825589,"mc":[{"id":"1.168236370","rc":[{"batb":[[0,1.01,10]],"ltp":0.0,"tv":0.0,"id":4520808},{"batb":[[0,1.01,10]],"ltp":0.0,"tv":0.0,"id":8284479}]}]}
{"op":"mcm","clk":"1003084143","pt":1580602759997,"mc":[{"id":"1.168236370","rc":[{"batb":[[0,1.01,12.53]],"ltp":0.0,"tv":0.0,"id":4520808},{"batb":[[0,1.01,12.53]],"ltp":0.0,"tv":0.0,"id":8284479}]}]}
{"op":"mcm","clk":"1003084232","pt":1580602761087,"mc":[{"id":"1.168236370","rc":[{"batb":[[0,1.01,10.51]],"ltp":0.0,"tv":0.0,"id":4520808},{"batb":[[0,1.01,10.51]],"ltp":0.0,"tv":0.0,"id":8284479}]}]}
{"op":"mcm","clk":"1003143159","pt":1580603525188,"mc":[{"id":"1.168236370","rc":[{"batb":[[0,1.01,11.01]],"ltp":0.0,"tv":0.0,"id":4520808},{"batb":[[0,1.01,11.01]],"ltp":0.0,"tv":0.0,"id":8284479}]}]}
{"op":"mcm","clk":"1006051113","pt":1580646201031,"mc":[{"id":"1.168236370","rc":[{"batl":[[0,2.96,4.54]],"ltp":0.0,"tv":0.0,"id":4520808},{"batl":[[0,3.15,3.79]],"ltp":0.0,"tv":0.0,"id":8284479}]}]}
{"op":"mcm","clk":"1007506823","pt":1580655622323,"mc":[{"id":"1.168236370","rc":[{"batb":[[0,1.02,2],[1,1.01,11.01]],"ltp":0.0,"tv":0.0,"id":4520808},{"batb":[[0,1.02,2],[1,1.01,11.01]],"ltp":0.0,"tv":0.0,"id":8284479}]}]}
{"op":"mcm","clk":"1007510485","pt":1580655647549,"mc":[{"id":"1.168236370","marketDefinition":{"bspMarket":false,"turnInPlayEnabled":true,"persistenceEnabled":true,"marketBaseRate":5.0,"eventId":"29681838","eventTypeId":"2","numberOfWinners":1,"bettingType":"ODDS","marketType":"SET_WINNER","marketTime":"2020-02-02T16:00:00.000Z","suspendTime":"2020-02-02T16:00:00.000Z","bspReconciled":false,"complete":true,"inPlay":false,"crossMatching":true,"runnersVoidable":false,"numberOfActiveRunners":2,"betDelay":0,"status":"OPEN","runners":[{"status":"ACTIVE","sortPriority":1,"id":4520808,"name":"Facundo Bagnis"},{"status":"ACTIVE","sortPriority":2,"id":8284479,"name":"Federico Gaio"}],"regulators":["MR_INT"],"countryCode":"AR","discountAllowed":true,"timezone":"UTC","openDate":"2020-02-02T16:00:00.000Z","version":3147446738,"name":"Set 1 Winner","eventName":"Bagnis v Gaio"}}]}
{"op":"mcm","clk":"1007628365","pt":1580656221220,"mc":[{"id":"1.168236370","rc":[{"batb":[[0,1.01,11.01],[1,1.01,0]],"ltp":0.0,"tv":0.0,"id":8284479}]}]}
{"op":"mcm","clk":"1007628428","pt":1580656221444,"mc":[{"id":"1.168236370","rc":[{"batb":[[0,1.01,11.01],[1,1.01,0]],"ltp":0.0,"tv":0.0,"id":4520808}]}]}
{"op":"mcm","clk":"1007628973","pt":1580656223492,"mc":[{"id":"1.168236370","rc":[{"batb":[[0,1.47,2],[1,1.01,11.01]],"ltp":0.0,"tv":0.0,"id":4520808},{"batb":[[0,1.52,2],[1,1.01,11.01]],"ltp":0.0,"tv":0.0,"id":8284479}]}]}
{"op":"mcm","clk":"1007769267","pt":1580656823105,"mc":[{"id":"1.168236370","rc":[{"batb":[[0,1.01,11.01],[1,1.01,0]],"ltp":0.0,"tv":0.0,"id":4520808},{"batb":[[0,1.01,11.01],[1,1.01,0]],"ltp":0.0,"tv":0.0,"id":8284479}]}]}
{"op":"mcm","clk":"1007770707","pt":1580656828967,"mc":[{"id":"1.168236370","rc":[{"batb":[[0,1.47,2],[1,1.01,11.01]],"ltp":0.0,"tv":0.0,"id":4520808},{"batb":[[0,1.52,2],[1,1.01,11.01]],"ltp":0.0,"tv":0.0,"id":8284479}]}]}
{"op":"mcm","clk":"1007906155","pt":1580657428098,"mc":[{"id":"1.168236370","rc":[{"batb":[[0,1.01,11.01],[1,1.01,0]],"ltp":0.0,"tv":0.0,"id":4520808}]}]}
{"op":"mcm","clk":"1007906280","pt":1580657428704,"mc":[{"id":"1.168236370","rc":[{"batb":[[0,1.01,11.01],[1,1.01,0]],"ltp":0.0,"tv":0.0,"id":8284479}]}]}
{"op":"mcm","clk":"1007908097","pt":1580657437035,"mc":[{"id":"1.168236370","rc":[{"batb":[[0,1.47,2],[1,1.01,11.01]],"ltp":0.0,"tv":0.0,"id":4520808},{"batb":[[0,1.52,2],[1,1.01,11.01]],"ltp":0.0,"tv":0.0,"id":8284479}]}]}
{"op":"mcm","clk":"1008043407","pt":1580658035908,"mc":[{"id":"1.168236370","rc":[{"batb":[[0,1.01,11.01],[1,1.01,0]],"ltp":0.0,"tv":0.0,"id":4520808},{"batb":[[0,1.01,11.01],[1,1.01,0]],"ltp":0.0,"tv":0.0,"id":8284479}]}]}
{"op":"mcm","clk":"1008044466","pt":1580658040234,"mc":[{"id":"1.168236370","rc":[{"batb":[[0,1.47,2],[1,1.01,11.01]],"ltp":0.0,"tv":0.0,"id":4520808},{"batb":[[0,1.52,2],[1,1.01,11.01]],"ltp":0.0,"tv":0.0,"id":8284479}]}]}
{"op":"mcm","clk":"1008172296","pt":1580658638977,"mc":[{"id":"1.168236370","rc":[{"batb":[[0,1.01,11.01],[1,1.01,0]],"ltp":0.0,"tv":0.0,"id":4520808}]}]}
{"op":"mcm","clk":"1008172366","pt":1580658640703,"mc":[{"id":"1.168236370","rc":[{"batb":[[0,1.01,11.01],[1,1.01,0]],"ltp":0.0,"tv":0.0,"id":8284479}]}]}
{"op":"mcm","clk":"1008236370","pt":1580659034008,"mc":[{"id":"1.168236370","rc":[{"batb":[[0,1.47,2],[1,1.01,11.01]],"ltp":0.0,"tv":0.0,"id":4520808},{"batb":[[0,1.52,2],[1,1.01,11.01]],"ltp":0.0,"tv":0.0,"id":8284479}]}]}
{"op":"mcm","clk":"1008245449","pt":1580659093242,"mc":[{"id":"1.168236370","rc":[{"batb":[[0,1.01,11.01],[1,1.01,0]],"ltp":0.0,"tv":0.0,"id":8284479}]}]}
{"op":"mcm","clk":"1008245578","pt":1580659094042,"mc":[{"id":"1.168236370","rc":[{"batb":[[0,1.52,2],[1,1.01,11.01]],"ltp":0.0,"tv":0.0,"id":8284479}]}]}
{"op":"mcm","clk":"1008280601","pt":1580659302802,"mc":[{"id":"1.168236370","marketDefinition":{"bspMarket":false,"turnInPlayEnabled":true,"persistenceEnabled":true,"marketBaseRate":5.0,"eventId":"29681838","eventTypeId":"2","numberOfWinners":1,"bettingType":"ODDS","marketType":"SET_WINNER","marketTime":"2020-02-02T16:15:00.000Z","suspendTime":"2020-02-02T16:15:00.000Z","bspReconciled":false,"complete":true,"inPlay":false,"crossMatching":true,"runnersVoidable":false,"numberOfActiveRunners":2,"betDelay":0,"status":"OPEN","runners":[{"status":"ACTIVE","sortPriority":1,"id":4520808,"name":"Facundo Bagnis"},{"status":"ACTIVE","sortPriority":2,"id":8284479,"name":"Federico Gaio"}],"regulators":["MR_INT"],"countryCode":"AR","discountAllowed":true,"timezone":"UTC","openDate":"2020-02-02T16:00:00.000Z","version":3149673261,"name":"Set 1 Winner","eventName":"Bagnis v Gaio"}}]}
{"op":"mcm","clk":"1008281157","pt":1580659305787,"mc":[{"id":"1.168236370","marketDefinition":{"bspMarket":false,"turnInPlayEnabled":true,"persistenceEnabled":true,"marketBaseRate":5.0,"eventId":"29681838","eventTypeId":"2","numberOfWinners":1,"bettingType":"ODDS","marketType":"SET_WINNER","marketTime":"2020-02-02T16:15:00.000Z","suspendTime":"2020-02-02T16:15:00.000Z","bspReconciled":false,"complete":true,"inPlay":false,"crossMatching":true,"runnersVoidable":false,"numberOfActiveRunners":2,"betDelay":0,"status":"OPEN","runners":[{"status":"ACTIVE","sortPriority":1,"id":4520808,"name":"Facundo Bagnis"},{"status":"ACTIVE","sortPriority":2,"id":8284479,"name":"Federico Gaio"}],"regulators":["MR_INT"],"countryCode":"AR","discountAllowed":true,"timezone":"UTC","openDate":"2020-02-02T16:15:00.000Z","version":3149673261,"name":"Set 1 Winner","eventName":"Bagnis v Gaio"}}]}
{"op":"mcm","clk":"1008474745","pt":1580660203653,"mc":[{"id":"1.168236370","marketDefinition":{"bspMarket":false,"turnInPlayEnabled":true,"persistenceEnabled":true,"marketBaseRate":5.0,"eventId":"29681838","eventTypeId":"2","numberOfWinners":1,"bettingType":"ODDS","marketType":"SET_WINNER","marketTime":"2020-02-02T16:30:00.000Z","suspendTime":"2020-02-02T16:30:00.000Z","bspReconciled":false,"complete":true,"inPlay":false,"crossMatching":true,"runnersVoidable":false,"numberOfActiveRunners":2,"betDelay":0,"status":"OPEN","runners":[{"status":"ACTIVE","sortPriority":1,"id":4520808,"name":"Facundo Bagnis"},{"status":"ACTIVE","sortPriority":2,"id":8284479,"name":"Federico Gaio"}],"regulators":["MR_INT"],"countryCode":"AR","discountAllowed":true,"timezone":"UTC","openDate":"2020-02-02T16:15:00.000Z","version":3149737478,"name":"Set 1 Winner","eventName":"Bagnis v Gaio"}}]}
{"op":"mcm","clk":"1008475458","pt":1580660206679,"mc":[{"id":"1.168236370","marketDefinition":{"bspMarket":false,"turnInPlayEnabled":true,"persistenceEnabled":true,"marketBaseRate":5.0,"eventId":"29681838","eventTypeId":"2","numberOfWinners":1,"bettingType":"ODDS","marketType":"SET_WINNER","marketTime":"2020-02-02T16:30:00.000Z","suspendTime":"2020-02-02T16:30:00.000Z","bspReconciled":false,"complete":true,"inPlay":false,"crossMatching":true,"runnersVoidable":false,"numberOfActiveRunners":2,"betDelay":0,"status":"OPEN","runners":[{"status":"ACTIVE","sortPriority":1,"id":4520808,"name":"Facundo Bagnis"},{"status":"ACTIVE","sortPriority":2,"id":8284479,"name":"Federico Gaio"}],"regulators":["MR_INT"],"countryCode":"AR","discountAllowed":true,"timezone":"UTC","openDate":"2020-02-02T16:30:00.000Z","version":3149737478,"name":"Set 1 Winner","eventName":"Bagnis v Gaio"}}]}
{"op":"mcm","clk":"1008675211","pt":1580661104119,"mc":[{"id":"1.168236370","marketDefinition":{"bspMarket":false,"turnInPlayEnabled":true,"persistenceEnabled":true,"marketBaseRate":5.0,"eventId":"29681838","eventTypeId":"2","numberOfWinners":1,"bettingType":"ODDS","marketType":"SET_WINNER","marketTime":"2020-02-02T16:45:00.000Z","suspendTime":"2020-02-02T16:45:00.000Z","bspReconciled":false,"complete":true,"inPlay":false,"crossMatching":true,"runnersVoidable":false,"numberOfActiveRunners":2,"betDelay":0,"status":"OPEN","runners":[{"status":"ACTIVE","sortPriority":1,"id":4520808,"name":"Facundo Bagnis"},{"status":"ACTIVE","sortPriority":2,"id":8284479,"name":"Federico Gaio"}],"regulators":["MR_INT"],"countryCode":"AR","discountAllowed":true,"timezone":"UTC","openDate":"2020-02-02T16:30:00.000Z","version":3149796841,"name":"Set 1 Winner","eventName":"Bagnis v Gaio"}}]}
{"op":"mcm","clk":"1008675568","pt":1580661105685,"mc":[{"id":"1.168236370","marketDefinition":{"bspMarket":false,"turnInPlayEnabled":true,"persistenceEnabled":true,"marketBaseRate":5.0,"eventId":"29681838","eventTypeId":"2","numberOfWinners":1,"bettingType":"ODDS","marketType":"SET_WINNER","marketTime":"2020-02-02T16:45:00.000Z","suspendTime":"2020-02-02T16:45:00.000Z","bspReconciled":false,"complete":true,"inPlay":false,"crossMatching":true,"runnersVoidable":false,"numberOfActiveRunners":2,"betDelay":0,"status":"OPEN","runners":[{"status":"ACTIVE","sortPriority":1,"id":4520808,"name":"Facundo Bagnis"},{"status":"ACTIVE","sortPriority":2,"id":8284479,"name":"Federico Gaio"}],"regulators":["MR_INT"],"countryCode":"AR","discountAllowed":true,"timezone":"UTC","openDate":"2020-02-02T16:45:00.000Z","version":3149796841,"name":"Set 1 Winner","eventName":"Bagnis v Gaio"}}]}
{"op":"mcm","clk":"1008739976","pt":1580661402947,"mc":[{"id":"1.168236370","marketDefinition":{"bspMarket":false,"turnInPlayEnabled":true,"persistenceEnabled":true,"marketBaseRate":5.0,"eventId":"29681838","eventTypeId":"2","numberOfWinners":1,"bettingType":"ODDS","marketType":"SET_WINNER","marketTime":"2020-02-02T16:35:00.000Z","suspendTime":"2020-02-02T16:35:00.000Z","bspReconciled":false,"complete":true,"inPlay":false,"crossMatching":true,"runnersVoidable":false,"numberOfActiveRunners":2,"betDelay":0,"status":"OPEN","runners":[{"status":"ACTIVE","sortPriority":1,"id":4520808,"name":"Facundo Bagnis"},{"status":"ACTIVE","sortPriority":2,"id":8284479,"name":"Federico Gaio"}],"regulators":["MR_INT"],"countryCode":"AR","discountAllowed":true,"timezone":"UTC","openDate":"2020-02-02T16:45:00.000Z","version":3149819974,"name":"Set 1 Winner","eventName":"Bagnis v Gaio"}}]}
{"op":"mcm","clk":"1008740299","pt":1580661404236,"mc":[{"id":"1.168236370","rc":[{"batb":[[0,1.82,18.88],[1,1.47,2],[2,1.01,11.01]],"ltp":0.0,"tv":0.0,"id":4520808},{"batb":[[0,2.06,25.57],[1,1.52,2],[2,1.01,11.01]],"ltp":0.0,"tv":0.0,"id":8284479}]}]}
{"op":"mcm","clk":"1008740488","pt":1580661404960,"mc":[{"id":"1.168236370","marketDefinition":{"bspMarket":false,"turnInPlayEnabled":true,"persistenceEnabled":true,"marketBaseRate":5.0,"eventId":"29681838","eventTypeId":"2","numberOfWinners":1,"bettingType":"ODDS","marketType":"SET_WINNER","marketTime":"2020-02-02T16:35:00.000Z","suspendTime":"2020-02-02T16:35:00.000Z","bspReconciled":false,"complete":true,"inPlay":false,"crossMatching":true,"runnersVoidable":false,"numberOfActiveRunners":2,"betDelay":0,"status":"OPEN","runners":[{"status":"ACTIVE","sortPriority":1,"id":4520808,"name":"Facundo Bagnis"},{"status":"ACTIVE","sortPriority":2,"id":8284479,"name":"Federico Gaio"}],"regulators":["MR_INT"],"countryCode":"AR","discountAllowed":true,"timezone":"UTC","openDate":"2020-02-02T16:35:00.000Z","version":3149819974,"name":"Set 1 Winner","eventName":"Bagnis v Gaio"}}]}
{"op":"mcm","clk":"1008891322","pt":1580662142430,"mc":[{"id":"1.168236370","rc":[{"batb":[[1,1.78,53.77],[2,1.47,2]],"batl":[[0,1.97,42.01],[1,2.96,4.54]],"ltp":0.0,"tv":0.0,"id":4520808},{"batb":[[0,2.06,65.06]],"batl":[[0,2.3,31.93],[1,3.15,3.79]],"ltp":0.0,"tv":0.0,"id":8284479}]}]}
{"op":"mcm","clk":"1008895958","pt":1580662172116,"mc":[{"id":"1.168236370","marketDefinition":{"bspMarket":false,"turnInPlayEnabled":true,"persistenceEnabled":true,"marketBaseRate":5.0,"eventId":"29681838","eventTypeId":"2","numberOfWinners":1,"bettingType":"ODDS","marketType":"SET_WINNER","marketTime":"2020-02-02T16:35:00.000Z","suspendTime":"2020-02-02T16:35:00.000Z","bspReconciled":false,"complete":true,"inPlay":true,"crossMatching":true,"runnersVoidable":false,"numberOfActiveRunners":2,"betDelay":3,"status":"OPEN","runners":[{"status":"ACTIVE","sortPriority":1,"id":4520808,"name":"Facundo Bagnis"},{"status":"ACTIVE","sortPriority":2,"id":8284479,"name":"Federico Gaio"}],"regulators":["MR_INT"],"countryCode":"AR","discountAllowed":true,"timezone":"UTC","openDate":"2020-02-02T16:35:00.000Z","version":3149870685,"name":"Set 1 Winner","eventName":"Bagnis v Gaio"},"rc":[{"batb":[[0,1.01,10.51],[1,1.78,0],[2,1.47,0]],"ltp":0.0,"tv":0.0,"id":4520808},{"batb":[[0,1.01,10.51],[1,1.52,0],[2,1.01,0]],"ltp":0.0,"tv":0.0,"id":8284479}]}]}
{"op":"mcm","clk":"1008897442","pt":1580662182386,"mc":[{"id":"1.168236370","rc":[{"batb":[[0,1.94,15.5],[1,1.78,20.22],[2,1.01,10.51]],"ltp":0.0,"tv":0.0,"id":4520808},{"batb":[[0,1.93,15.66],[1,1.83,18.57],[2,1.01,10.51]],"ltp":0.0,"tv":0.0,"id":8284479}]}]}
{"op":"mcm","clk":"1008897607","pt":1580662183556,"mc":[{"id":"1.168236370","rc":[{"batb":[[1,1.86,48.73],[2,1.78,20.22]],"batl":[[0,2.08,38.65]],"ltp":0.0,"tv":0.0,"id":4520808},{"batb":[[0,1.93,60.19]],"batl":[[0,2.16,36.13]],"ltp":0.0,"tv":0.0,"id":8284479}]}]}
{"op":"mcm","clk":"1008898149","pt":1580662187004,"mc":[{"id":"1.168236370","rc":[{"batb":[[0,1.95,281.51],[1,1.94,15.5],[2,1.86,48.73]],"ltp":0.0,"tv":0.0,"id":4520808},{"batb":[[1,1.89,169.34],[2,1.87,156.32]],"batl":[[0,1.98,138.53],[1,2,129.39],[2,2.16,36.13]],"ltp":0.0,"tv":0.0,"id":8284479}]}]}
{"op":"mcm","clk":"1008898190","pt":1580662187295,"mc":[{"id":"1.168236370","rc":[{"batb":[[0,1.94,15.5],[1,1.86,48.73],[2,1.78,20.22]],"ltp":0.0,"tv":0.0,"id":4520808}]}]}
{"op":"mcm","clk":"1008898916","pt":1580662192125,"mc":[{"id":"1.168236370","rc":[{"batb":[[0,1.86,48.73],[1,1.78,20.22],[2,1.01,10.51]],"ltp":0.0,"tv":0.0,"id":4520808},{"batb":[[0,1.93,44.53],[1,1.83,18.57],[2,1.01,10.51]],"batl":[[0,2.16,36.13],[1,2,0],[2,2.16,0]],"ltp":0.0,"tv":0.0,"id":8284479}]}]}
{"op":"mcm","clk":"1008899078","pt":1580662193124,"mc":[{"id":"1.168236370","rc":[{"batb":[[0,1.78,20.22],[1,1.01,10.51],[2,1.01,0]],"ltp":0.0,"tv":0.0,"id":4520808},{"batb":[[0,1.83,18.57],[1,1.01,10.51],[2,1.01,0]],"ltp":0.0,"tv":0.0,"id":8284479}]}]}
{"op":"mcm","clk":"1008899782","pt":1580662197655,"mc":[{"id":"1.168236370","rc":[{"batb":[[0,1.92,172.31],[1,1.9,148.63],[2,1.83,18.57]],"batl":[[0,2.02,173.95],[1,2.04,122.05]],"ltp":0.0,"tv":0.0,"id":8284479}]}]}
{"op":"mcm","clk":"1008900314","pt":1580662201141,"mc":[{"id":"1.168236370","rc":[{"batb":[[0,1.83,18.57],[1,1.01,10.51],[2,1.83,0]],"ltp":0.0,"tv":0.0,"id":8284479}]}]}
{"op":"mcm","clk":"1008900764","pt":1580662203977,"mc":[{"id":"1.168236370","rc":[{"batb":[[1,1.81,160.71],[2,1.79,180.15]],"batl":[[0,2.16,123.57],[1,2.18,100.9]],"ltp":0.0,"tv":0.0,"id":8284479}]}]}
{"op":"mcm","clk":"1008901297","pt":1580662207152,"mc":[{"id":"1.168236370","rc":[{"batb":[[1,1.01,10.51],[2,1.79,0]],"ltp":0.0,"tv":0.0,"id":8284479}]}]}
{"op":"mcm","clk":"1008901361","pt":1580662207593,"mc":[{"id":"1.168236370","rc":[{"batb":[[0,2.06,25.97],[1,1.93,44.53],[2,1.92,15.89]],"batl":[[0,2.16,36.13]],"ltp":0.0,"tv":0.0,"id":4520808},{"batb":[[0,1.85,48.73],[1,1.83,18.57],[2,1.76,21.32]],"batl":[[0,2.06,39.49]],"ltp":0.0,"tv":0.0,"id":8284479}]}]}
{"op":"mcm","clk":"1008901731","pt":1580662210062,"mc":[{"id":"1.168236370","rc":[{"batb":[[2,1.82,185.25]],"batl":[[0,1.9,113.17],[1,1.92,146.19],[2,2.06,39.49]],"ltp":0.0,"tv":0.0,"id":8284479}]}]}
{"op":"mcm","clk":"1008901915","pt":1580662211241,"mc":[{"id":"1.168236370","rc":[{"batb":[[2,1.76,21.32]],"batl":[[0,2.06,39.49],[1,1.92,0],[2,2.06,0]],"ltp":0.0,"tv":0.0,"id":8284479}]}]}
{"op":"mcm","clk":"1008902237","pt":1580662213357,"mc":[{"id":"1.168236370","rc":[{"batb":[[1,1.83,165.78],[2,1.81,173.47]],"batl":[[0,1.91,140.38],[1,1.93,143.79],[2,2.06,39.49]],"ltp":0.0,"tv":0.0,"id":8284479}]}]}
{"op":"mcm","clk":"1008902997","pt":1580662218242,"mc":[{"id":"1.168236370","rc":[{"batb":[[1,1.83,18.57],[2,1.76,21.32]],"batl":[[0,2.06,39.49],[1,1.93,0],[2,2.06,0]],"ltp":0.0,"tv":0.0,"id":8284479}]}]}
{"op":"mcm","clk":"1008903038","pt":1580662218556,"mc":[{"id":"1.168236370","rc":[{"batb":[[0,1.92,15.89],[1,1.01,10.51],[2,1.92,0]],"ltp":0.0,"tv":0.0,"id":4520808},{"batb":[[0,1.76,21.32],[1,1.01,10.51],[2,1.76,0]],"ltp":0.0,"tv":0.0,"id":8284479}]}]}
{"op":"mcm","clk":"1008903424","pt":1580662221198,"mc":[{"id":"1.168236370","rc":[{"batb":[[0,1.78,130.81],[1,1.76,211.54],[2,1.01,10.51]],"batl":[[0,2.02,129.92],[1,2.04,121.96]],"ltp":0.0,"tv":0.0,"id":8284479}]}]}
{"op":"mcm","clk":"1008904290","pt":1580662226773,"mc":[{"id":"1.168236370","rc":[{"batb":[[0,1.76,21.32],[1,1.01,10.51],[2,1.01,0]],"ltp":0.0,"tv":0.0,"id":8284479}]}]}
{"op":"mcm","clk":"1008904749","pt":1580662229794,"mc":[{"id":"1.168236370","rc":[{"batb":[[0,1.93,145.24],[1,1.91,146.1],[2,1.76,21.32]],"ltp":0.0,"tv":0.0,"id":8284479}]}]}
{"op":"mcm","clk":"1008904915","pt":1580662230674,"mc":[{"id":"1.168236370","rc":[{"batb":[[1,1.75,21.72],[2,1.01,10.51]],"ltp":0.0,"tv":0.0,"id":4520808},{"batb":[[0,1.95,30.61],[1,1.93,145.24],[2,1.91,146.1]],"ltp":0.0,"tv":0.0,"id":8284479}]}]}
{"op":"mcm","clk":"1008905059","pt":1580662231480,"mc":[{"id":"1.168236370","rc":[{"batb":[[1,1.86,48.73],[2,1.75,21.72]],"batl":[[0,2.04,40.33]],"ltp":0.0,"tv":0.0,"id":4520808},{"batb":[[0,1.95,74.3]],"batl":[[2,2.16,36.13]],"ltp":0.0,"tv":0.0,"id":8284479}]}]}
{"op":"mcm","clk":"1008906803","pt":1580662242017,"mc":[{"id":"1.168236370","rc":[{"batb":[[0,1.86,48.73],[1,1.75,21.72],[2,1.01,10.51]],"ltp":0.0,"tv":0.0,"id":4520808},{"batb":[[0,1.95,43.69],[1,1.83,18.73],[2,1.01,10.51]],"batl":[[0,2.16,36.13],[1,2.04,0],[2,2.16,0]],"ltp":0.0,"tv":0.0,"id":8284479}]}]}
{"op":"mcm","clk":"1008907000","pt":1580662243085,"mc":[{"id":"1.168236370","rc":[{"batb":[[0,1.75,21.72],[1,1.01,10.51],[2,1.01,0]],"ltp":0.0,"tv":0.0,"id":4520808},{"batb":[[0,1.83,18.73],[1,1.01,10.51],[2,1.01,0]],"ltp":0.0,"tv":0.0,"id":8284479}]}]}
{"op":"mcm","clk":"1008907326","pt":1580662245194,"mc":[{"id":"1.168236370","rc":[{"batb":[[0,1.83,156.15],[1,1.82,19.04],[2,1.81,173.43]],"ltp":0.0,"tv":0.0,"id":8284479}]}]}
{"op":"mcm","clk":"1008907343","pt":1580662245294,"mc":[{"id":"1.168236370","rc":[{"batb":[[0,1.75,21.4]],"ltp":0.0,"tv":0.0,"id":4520808},{"batb":[[0,1.83,137.42]],"ltp":0.0,"tv":0.0,"id":8284479}]}]}
{"op":"mcm","clk":"1008907719","pt":1580662247849,"mc":[{"id":"1.168236370","rc":[{"batl":[[0,1.91,149.65],[1,1.93,143.77]],"ltp":0.0,"tv":0.0,"id":8284479}]}]}
{"op":"mcm","clk":"1008907873","pt":1580662248906,"mc":[{"id":"1.168236370","rc":[{"batb":[[0,2.06,25.41],[1,1.93,15.66],[2,1.01,10.51]],"ltp":0.0,"tv":0.0,"id":4520808}]}]}
{"op":"mcm","clk":"1008907960","pt":1580662249502,"mc":[{"id":"1.168236370","rc":[{"batb":[[1,1.93,60.19]],"batl":[[0,2.16,36.13]],"ltp":0.0,"tv":0.0,"id":4520808},{"batb":[[0,1.85,48.73],[1,1.83,137.42],[2,1.82,19.04]],"batl":[[2,2.06,39.49]],"ltp":0.0,"tv":0.0,"id":8284479}]}]}
{"op":"mcm","clk":"1008909188","pt":1580662258233,"mc":[{"id":"1.168236370","rc":[{"batb":[[0,1.83,137.42],[1,1.82,19.04],[2,1.81,173.43]],"ltp":0.0,"tv":0.0,"id":8284479}]}]}
{"op":"mcm","clk":"1008909274","pt":1580662258809,"mc":[{"id":"1.168236370","rc":[{"batb":[[0,1.93,60.19],[1,1.01,10.51],[2,1.01,0]],"ltp":0.0,"tv":0.0,"id":4520808},{"batb":[[0,1.75,21.48],[1,1.01,10.51],[2,1.81,0]],"batl":[[0,2.06,39.49],[1,1.93,0],[2,2.06,0]],"ltp":0.0,"tv":0.0,"id":8284479}]}]}
{"op":"mcm","clk":"1008909650","pt":1580662261139,"mc":[{"id":"1.168236370","rc":[{"batb":[[0,1.93,15.66]],"ltp":0.0,"tv":0.0,"id":4520808},{"batb":[[0,1.86,48.73],[1,1.75,21.48],[2,1.01,10.51]],"ltp":0.0,"tv":0.0,"id":8284479}]}]}
{"op":"mcm","clk":"1008909784","pt":1580662262132,"mc":[{"id":"1.168236370","rc":[{"batb":[[0,1.75,21.48],[1,1.01,10.51],[2,1.01,0]],"ltp":0.0,"tv":0.0,"id":8284479}]}]}
{"op":"mcm","clk":"1008910308","pt":1580662265849,"mc":[{"id":"1.168236370","rc":[{"batb":[[0,1.85,121.66],[1,1.83,167.33],[2,1.75,21.48]],"batl":[[0,1.93,148.07],[1,1.95,139.37]],"ltp":0.0,"tv":0.0,"id":8284479}]}]}
{"op":"mcm","clk":"1008910587","pt":1580662267647,"mc":[{"id":"1.168236370","rc":[{"batb":[[0,1.75,21.48],[1,1.01,10.51],[2,1.75,0]],"ltp":0.0,"tv":0.0,"id":8284479}]}]}
{"op":"mcm","clk":"1008911013","pt":1580662270537,"mc":[{"id":"1.168236370","rc":[{"batb":[[0,1.78,140.14],[1,1.76,190.24],[2,1.75,21.48]],"batl":[[0,2.02,177.15],[1,2.04,121.94]],"ltp":0.0,"tv":0.0,"id":8284479}]}]}
{"op":"mcm","clk":"1008911659","pt":1580662275218,"mc":[{"id":"1.168236370","rc":[{"batb":[[0,2.16,22.35],[1,2.02,27.54],[2,1.01,10.51]],"ltp":0.0,"tv":0.0,"id":4520808}]}]}
{"op":"mcm","clk":"1008911762","pt":1580662275951,"mc":[{"id":"1.168236370","rc":[{"batb":[[2,2,42.01]],"batl":[[0,2.26,32.77]],"ltp":0.0,"tv":0.0,"id":4520808},{"batb":[[0,1.8,52.09],[1,1.78,140.14],[2,1.76,190.24]],"batl":[[0,1.98,42.01]],"ltp":0.0,"tv":0.0,"id":8284479}]}]}
{"op":"mcm","clk":"1008912113","pt":1580662278230,"mc":[{"id":"1.168236370","rc":[{"batb":[[1,1.78,195.86]],"batl":[[0,1.86,139.77],[1,1.88,155.68],[2,1.98,42.01]],"ltp":0.0,"tv":0.0,"id":8284479}]}]}
{"op":"mcm","clk":"1008912757","pt":1580662283035,"mc":[{"id":"1.168236370","rc":[{"batb":[[1,2.14,22.74],[2,2.02,27.54]],"ltp":0.0,"tv":0.0,"id":4520808},{"batb":[[2,1.76,211.41]],"ltp":0.0,"tv":0.0,"id":8284479}]}]}
{"op":"mcm","clk":"1008912786","pt":1580662283248,"mc":[{"id":"1.168236370","rc":[{"batb":[[0,2.14,22.74],[1,2,70.02],[2,1.01,10.51]],"ltp":0.0,"tv":0.0,"id":4520808}]}]}
{"op":"mcm","clk":"1008916307","pt":1580662311404,"mc":[{"id":"1.168236370","rc":[{"batb":[[1,1.76,21.17],[2,1.61,28.95]],"batl":[[0,1.98,42.01],[1,1.88,0],[2,1.98,0]],"ltp":0.0,"tv":0.0,"id":8284479}]}]}
{"op":"mcm","clk":"1008916915","pt":1580662315626,"mc":[{"id":"1.168236370","rc":[{"batb":[[2,1.63,165.5]],"batl":[[0,1.97,112.54],[1,1.98,42.01],[2,1.99,131.15]],"ltp":0.0,"tv":0.0,"id":8284479}]}]}
{"op":"mcm","clk":"1008917784","pt":1580662321399,"mc":[{"id":"1.168236370","rc":[{"batb":[[0,2,70.02],[1,1.01,10.51],[2,1.01,0]],"ltp":0.0,"tv":0.0,"id":4520808},{"batb":[[1,1.63,165.5],[2,1.62,127.65]],"ltp":0.0,"tv":0.0,"id":8284479}]}]}
{"op":"mcm","clk":"1008917925","pt":1580662322516,"mc":[{"id":"1.168236370","rc":[{"batb":[[0,2,28.01]],"ltp":0.0,"tv":0.0,"id":4520808},{"batb":[[0,1.63,165.5],[1,1.62,127.65],[2,1.61,28.95]],"batl":[[1,1.99,131.15],[2,1.99,0]],"ltp":0.0,"tv":0.0,"id":8284479}]}]}
{"op":"mcm","clk":"1008918294","pt":1580662325285,"mc":[{"id":"1.168236370","rc":[{"batb":[[0,1.61,28.95],[1,1.01,10.51],[2,1.61,0]],"ltp":0.0,"tv":0.0,"id":8284479}]}]}
{"op":"mcm","clk":"1008918668","pt":1580662328199,"mc":[{"id":"1.168236370","rc":[{"batb":[[0,1.89,126.75],[1,1.87,156.09],[2,1.61,28.95]],"ltp":0.0,"tv":0.0,"id":8284479}]}]}
{"op":"mcm","clk":"1008918793","pt":1580662329089,"mc":[{"id":"1.168236370","rc":[{"batb":[[1,1.89,16.68],[2,1.01,10.51]],"ltp":0.0,"tv":0.0,"id":4520808},{"batb":[[1,1.87,173.4],[2,1.73,22.58]],"ltp":0.0,"tv":0.0,"id":8284479}]}]}
{"op":"mcm","clk":"1008918847","pt":1580662329507,"mc":[{"id":"1.168236370","rc":[{"batb":[[1,1.92,45.37],[2,1.89,16.68]],"batl":[[0,2.12,36.97]],"ltp":0.0,"tv":0.0,"id":4520808},{"batb":[[1,1.88,47.05],[2,1.87,173.4]],"batl":[[2,2.1,37.81]],"ltp":0.0,"tv":0.0,"id":8284479}]}]}
{"op":"mcm","clk":"1008920806","pt":1580662343231,"mc":[{"id":"1.168236370","rc":[{"batb":[[0,1.92,45.37],[1,1.89,16.68],[2,1.01,10.51]],"ltp":0.0,"tv":0.0,"id":4520808},{"batb":[[0,1.88,47.05],[1,1.73,22.58],[2,1.01,10.51]],"batl":[[0,2.1,37.81],[1,1.99,0],[2,2.1,0]],"ltp":0.0,"tv":0.0,"id":8284479}]}]}
{"op":"mcm","clk":"1008921086","pt":1580662345243,"mc":[{"id":"1.168236370","rc":[{"batb":[[0,1.89,16.68],[1,1.01,10.51],[2,1.01,0]],"ltp":0.0,"tv":0.0,"id":4520808},{"batb":[[0,1.73,22.58],[1,1.01,10.51],[2,1.01,0]],"ltp":0.0,"tv":0.0,"id":8284479}]}]}
{"op":"mcm","clk":"1008921183","pt":1580662346016,"mc":[{"id":"1.168236370","rc":[{"batb":[[0,1.75,138.44],[1,1.73,223.98],[2,1.01,10.51]],"batl":[[0,2.08,171.82],[1,2.1,112.14]],"ltp":0.0,"tv":0.0,"id":8284479}]}]}
{"op":"mcm","clk":"1008921410","pt":1580662347745,"mc":[{"id":"1.168236370","rc":[{"batb":[[0,1.73,22.58],[1,1.01,10.51],[2,1.01,0]],"ltp":0.0,"tv":0.0,"id":8284479}]}]}
{"op":"mcm","clk":"1008921883","pt":1580662351222,"mc":[{"id":"1.168236370","rc":[{"batb":[[0,1.86,136.39],[1,1.84,164.37],[2,1.73,22.58]],"batl":[[0,1.94,125.79],[1,1.96,137.19]],"ltp":0.0,"tv":0.0,"id":8284479}]}]}
{"op":"mcm","clk":"1008922019","pt":1580662352218,"mc":[{"id":"1.168236370","rc":[{"batb":[[0,1.73,22.58],[1,1.01,10.51],[2,1.73,0]],"ltp":0.0,"tv":0.0,"id":8284479}]}]}
{"op":"mcm","clk":"1008922422","pt":1580662355127,"mc":[{"id":"1.168236370","rc":[{"batb":[[0,1.75,138.44],[1,1.73,223.98],[2,1.01,10.51]],"batl":[[0,2.08,171.82],[1,2.1,112.14]],"ltp":0.0,"tv":0.0,"id":8284479}]}]}
{"op":"mcm","clk":"1008923262","pt":1580662361212,"mc":[{"id":"1.168236370","rc":[{"batb":[[0,2.2,21.17],[1,2.02,27.15],[2,1.89,16.68]],"ltp":0.0,"tv":0.0,"id":4520808},{"batb":[[2,1.55,33.28]],"batl":[[0,1.82,141.63],[1,1.84,166.44]],"ltp":0.0,"tv":0.0,"id":8284479}]}]}
{"op":"mcm","clk":"1008923401","pt":1580662362053,"mc":[{"id":"1.168236370","rc":[{"batb":[[1,2.06,39.49],[2,2.02,27.15]],"batl":[[0,2.32,31.09]],"ltp":0.0,"tv":0.0,"id":4520808},{"batb":[[0,1.76,54.61],[1,1.75,138.44],[2,1.73,223.98]],"batl":[[2,1.95,42.01]],"ltp":0.0,"tv":0.0,"id":8284479}]}]}
{"op":"mcm","clk":"1008924838","pt":1580662373173,"mc":[{"id":"1.168236370","rc":[{"batb":[[0,2.06,39.49],[1,2.02,27.15],[2,1.01,10.51]],"ltp":0.0,"tv":0.0,"id":4520808},{"batb":[[1,1.55,33.28],[2,1.01,10.51]],"batl":[[0,1.95,42.01],[1,1.84,0],[2,1.95,0]],"ltp":0.0,"tv":0.0,"id":8284479}]}]}
{"op":"mcm","clk":"1008925042","pt":1580662374564,"mc":[{"id":"1.168236370","rc":[{"batb":[[0,2.02,27.15],[1,1.01,10.51],[2,1.01,0]],"ltp":0.0,"tv":0.0,"id":4520808},{"batb":[[0,1.55,33.28],[1,1.01,10.51],[2,1.01,0]],"ltp":0.0,"tv":0.0,"id":8284479}]}]}
{"op":"mcm","clk":"1008925245","pt":1580662376162,"mc":[{"id":"1.168236370","rc":[{"batl":[[0,1.96,155.63],[1,1.98,133.08]],"ltp":0.0,"tv":0.0,"id":8284479}]}]}
{"op":"mcm","clk":"1008925633","pt":1580662378989,"mc":[{"id":"1.168236370","rc":[{"batb":[[0,1.87,168.76],[1,1.85,161.6],[2,1.55,33.28]],"ltp":0.0,"tv":0.0,"id":8284479}]}]}
{"op":"mcm","clk":"1008925777","pt":1580662379938,"mc":[{"id":"1.168236370","rc":[{"batb":[[1,1.94,44.53],[2,1.9,16.52]],"batl":[[0,2.16,36.13]],"ltp":0.0,"tv":0.0,"id":4520808},{"batb":[[1,1.86,48.73],[2,1.85,179.46]],"batl":[[2,2.06,39.49]],"ltp":0.0,"tv":0.0,"id":8284479}]}]}
{"op":"mcm","clk":"1008927672","pt":1580662393210,"mc":[{"id":"1.168236370","rc":[{"batb":[[0,1.86,48.73],[1,1.85,17.86],[2,1.69,24.39]],"ltp":0.0,"tv":0.0,"id":8284479}]}]}
{"op":"mcm","clk":"1008927788","pt":1580662394097,"mc":[{"id":"1.168236370","rc":[{"batb":[[0,1.94,44.53],[1,1.9,16.52],[2,1.01,10.51]],"ltp":0.0,"tv":0.0,"id":4520808},{"batb":[[1,1.69,24.39],[2,1.01,10.51]],"batl":[[0,2.06,39.49],[1,1.98,0],[2,2.06,0]],"ltp":0.0,"tv":0.0,"id":8284479}]}]}
{"op":"mcm","clk":"1008927854","pt":1580662394572,"mc":[{"id":"1.168236370","rc":[{"batb":[[0,1.9,16.52],[1,1.01,10.51],[2,1.01,0]],"ltp":0.0,"tv":0.0,"id":4520808},{"batb":[[0,1.69,24.39],[1,1.01,10.51],[2,1.01,0]],"ltp":0.0,"tv":0.0,"id":8284479}]}]}
{"op":"mcm","clk":"1008928141","pt":1580662396675,"mc":[{"id":"1.168236370","rc":[{"batb":[[0,1.71,195.29],[1,1.69,242.84],[2,1.01,10.51]],"batl":[[0,2.08,148.8],[1,2.1,112.15]],"ltp":0.0,"tv":0.0,"id":8284479}]}]}
{"op":"mcm","clk":"1008928755","pt":1580662400802,"mc":[{"id":"1.168236370","rc":[{"batb":[[0,1.69,24.39],[1,1.01,10.51],[2,1.01,0]],"ltp":0.0,"tv":0.0,"id":8284479}]}]}
{"op":"mcm","clk":"1008929196","pt":1580662403701,"mc":[{"id":"1.168236370","rc":[{"batb":[[0,1.93,131.18],[1,1.91,146.08],[2,1.9,16.52]],"batl":[[0,2.02,143.41],[1,2.04,122.02]],"ltp":0.0,"tv":0.0,"id":4520808}]}]}
{"op":"mcm","clk":"1008929316","pt":1580662404648,"mc":[{"id":"1.168236370","rc":[{"batb":[[0,1.97,29.35],[1,1.85,17.86],[2,1.01,10.51]],"ltp":0.0,"tv":0.0,"id":8284479}]}]}
{"op":"mcm","clk":"1008929413","pt":1580662405478,"mc":[{"id":"1.168236370","rc":[{"batl":[[1,2.04,162.35]],"ltp":0.0,"tv":0.0,"id":4520808},{"batb":[[1,1.95,43.69],[2,1.85,17.86]],"batl":[[0,2.18,35.29]],"ltp":0.0,"tv":0.0,"id":8284479}]}]}
{"op":"mcm","clk":"1008930906","pt":1580662416831,"mc":[{"id":"1.168236370","rc":[{"batb":[[0,1.83,18.73],[1,1.01,10.51],[2,1.9,0]],"ltp":0.0,"tv":0.0,"id":4520808},{"batb":[[0,1.85,17.86],[1,1.01,10.51],[2,1.85,0]],"ltp":0.0,"tv":0.0,"id":8284479}]}]}
{"op":"mcm","clk":"1008931562","pt":1580662422116,"mc":[{"id":"1.168236370","rc":[{"batb":[[0,1.95,132.39],[1,1.93,141.38],[2,1.83,18.73]],"batl":[[0,2.04,127.79],[1,2.06,118.57]],"ltp":0.0,"tv":0.0,"id":4520808}]}]}
{"op":"mcm","clk":"1008931802","pt":1580662424005,"mc":[{"id":"1.168236370","rc":[{"batb":[[0,1.83,18.73],[1,1.01,10.51],[2,1.83,0]],"ltp":0.0,"tv":0.0,"id":4520808}]}]}
{"op":"mcm","clk":"1008932199","pt":1580662426937,"mc":[{"id":"1.168236370","rc":[{"batb":[[0,1.87,179.28],[1,1.85,161.75],[2,1.83,18.73]],"batl":[[0,2.14,151.3],[1,2.16,103.46]],"ltp":0.0,"tv":0.0,"id":4520808}]}]}
{"op":"mcm","clk":"1008932488","pt":1580662429245,"mc":[{"id":"1.168236370","rc":[{"batb":[[0,1.83,18.73],[1,1.01,10.51],[2,1.83,0]],"ltp":0.0,"tv":0.0,"id":4520808}]}]}
{"op":"mcm","clk":"1008932847","pt":1580662432150,"mc":[{"id":"1.168236370","rc":[{"batb":[[0,1.88,150.41],[1,1.86,158.83],[2,1.85,17.86]],"batl":[[0,1.97,164.04],[1,1.99,131.11]],"ltp":0.0,"tv":0.0,"id":8284479}]}]}
{"op":"mcm","clk":"1008932951","pt":1580662432923,"mc":[{"id":"1.168236370","rc":[{"batb":[[0,2.02,27.07],[1,1.89,16.92],[2,1.01,10.51]],"ltp":0.0,"tv":0.0,"id":4520808}]}]}
{"op":"mcm","clk":"1008933026","pt":1580662433546,"mc":[{"id":"1.168236370","rc":[{"batb":[[1,1.92,45.37],[2,1.89,16.92]],"batl":[[0,2.16,36.13]],"ltp":0.0,"tv":0.0,"id":4520808},{"batb":[[1,1.86,207.56]],"batl":[[2,2.08,38.65]],"ltp":0.0,"tv":0.0,"id":8284479}]}]}
{"op":"mcm","clk":"1008933856","pt":1580662440143,"mc":[{"id":"1.168236370","rc":[{"batb":[[0,1.86,48.73],[1,1.85,17.86],[2,1.67,25.34]],"batl":[[0,1.97,138.64]],"ltp":0.0,"tv":0.0,"id":8284479}]}]}
{"op":"mcm","clk":"1008934205","pt":1580662443054,"mc":[{"id":"1.168236370","rc":[{"batb":[[0,1.89,105.37],[1,1.87,156.05],[2,1.86,48.73]],"ltp":0.0,"tv":0.0,"id":8284479}]}]}
{"op":"mcm","clk":"1008934458","pt":1580662444954,"mc":[{"id":"1.168236370","rc":[{"batl":[[0,1.97,111.86]],"ltp":0.0,"tv":0.0,"id":8284479}]}]}
{"op":"mcm","clk":"1008934843","pt":1580662447959,"mc":[{"id":"1.168236370","rc":[{"batb":[[0,1.89,127.3]],"ltp":0.0,"tv":0.0,"id":8284479}]}]}
{"op":"mcm","clk":"1008934963","pt":1580662448860,"mc":[{"id":"1.168236370","rc":[{"batb":[[0,1.89,16.92],[1,1.01,10.51],[2,1.89,0]],"ltp":0.0,"tv":0.0,"id":4520808},{"batb":[[0,1.67,25.34],[1,1.01,10.51],[2,1.86,0]],"ltp":0.0,"tv":0.0,"id":8284479}]}]}
{"op":"mcm","clk":"1008935072","pt":1580662449664,"mc":[{"id":"1.168236370","rc":[{"batl":[[0,2.02,19.69]],"ltp":0.0,"tv":0.0,"id":4520808}]}]}
{"op":"mcm","clk":"1008935654","pt":1580662454161,"mc":[{"id":"1.168236370","rc":[{"trd":[[2.02,19.69]],"ltp":2.02,"tv":19.68,"id":4520808},{"trd":[[1.98,20.09]],"batb":[[0,1.85,133.25],[1,1.83,167.22],[2,1.67,25.34]],"batl":[[0,1.93,116.41],[1,1.95,139.24]],"ltp":1.98,"tv":20.09,"id":8284479}],"tv":39.77}]}
{"op":"mcm","clk":"1008935900","pt":1580662455970,"mc":[{"id":"1.168236370","rc":[{"batb":[[1,1.74,404.28],[2,1.01,10.51]],"ltp":2.02,"tv":19.68,"id":4520808}]}]}
{"op":"mcm","clk":"1008936461","pt":1580662459957,"mc":[{"id":"1.168236370","rc":[{"batb":[[0,1.67,25.34],[1,1.52,425.49],[2,1.01,10.51]],"ltp":1.98,"tv":20.09,"id":8284479}]}]}
{"op":"mcm","clk":"1008936869","pt":1580662463180,"mc":[{"id":"1.168236370","rc":[{"batb":[[0,1.71,128.54],[1,1.69,217.93],[2,1.67,25.34]],"batl":[[0,2.12,170.21],[1,2.14,106.29]],"ltp":1.98,"tv":20.09,"id":8284479}]}]}
{"op":"mcm","clk":"1008936911","pt":1580662463494,"mc":[{"id":"1.168236370","rc":[{"batl":[[0,2.06,84.69]],"ltp":2.02,"tv":19.68,"id":4520808}]}]}
{"op":"mcm","clk":"1008937801","pt":1580662470206,"mc":[{"id":"1.168236370","rc":[{"batb":[[1,1.01,10.51],[2,1.01,0]],"ltp":2.02,"tv":19.68,"id":4520808},{"batb":[[0,1.67,25.34],[1,1.01,10.51],[2,1.67,0]],"ltp":1.98,"tv":20.09,"id":8284479}]}]}
{"op":"mcm","clk":"1008938062","pt":1580662472214,"mc":[{"id":"1.168236370","rc":[{"batb":[[0,1.9,136.05],[1,1.89,16.92],[2,1.88,153.6]],"batl":[[0,1.99,161.96],[1,2.02,189.38],[2,2.06,84.69]],"ltp":2.02,"tv":19.68,"id":4520808}]}]}
{"op":"mcm","clk":"1008938187","pt":1580662473217,"mc":[{"id":"1.168236370","rc":[{"batb":[[0,1.99,28.64],[1,1.86,17.62],[2,1.01,10.51]],"ltp":1.98,"tv":20.09,"id":8284479}]}]}
{"op":"mcm","clk":"1008938334","pt":1580662474157,"mc":[{"id":"1.168236370","rc":[{"batl":[[1,2.02,230.55]],"ltp":2.02,"tv":19.68,"id":4520808},{"batb":[[1,1.98,42.85],[2,1.86,17.62]],"batl":[[0,2.22,33.61]],"ltp":1.98,"tv":20.09,"id":8284479}]}]}
{"op":"mcm","clk":"1008942763","pt":1580662507014,"mc":[{"id":"1.168236370","rc":[{"batb":[[0,1.83,50.41],[1,1.7,23.92],[2,1.62,415.43]],"batl":[[0,2.02,41.17],[1,2.06,84.69],[2,2.06,0]],"ltp":2.02,"tv":19.68,"id":4520808},{"batb":[[0,1.98,42.85],[1,1.86,17.62],[2,1.62,415.43]],"ltp":1.98,"tv":20.09,"id":8284479}]}]}
{"op":"mcm","clk":"1008942912","pt":1580662508059,"mc":[{"id":"1.168236370","rc":[{"batl":[[0,2,151.45],[1,2.22,33.61]],"ltp":1.98,"tv":20.09,"id":8284479}]}]}
{"op":"mcm","clk":"1008943066","pt":1580662509216,"mc":[{"id":"1.168236370","rc":[{"batb":[[0,1.7,23.92],[1,1.62,415.43],[2,1.01,10.51]],"batl":[[0,2.06,84.69],[1,2.06,0]],"ltp":2.02,"tv":19.68,"id":4520808},{"batb":[[0,1.86,17.62],[1,1.62,415.43],[2,1.01,10.51]],"batl":[[1,2.22,0]],"ltp":1.98,"tv":20.09,"id":8284479}]}]}
{"op":"mcm","clk":"1008943467","pt":1580662512213,"mc":[{"id":"1.168236370","rc":[{"batb":[[0,1.86,140.13],[1,1.84,164.63],[2,1.7,23.92]],"batl":[[0,1.94,123.32],[1,1.96,137.51],[2,2.06,84.69]],"ltp":2.02,"tv":19.68,"id":4520808},{"trd":[[2,84.02]],"ltp":2.0,"tv":104.11,"id":8284479}],"tv":123.79}]}
{"op":"mcm","clk":"1008943817","pt":1580662515210,"mc":[{"id":"1.168236370","rc":[{"batb":[[0,1.7,23.92],[1,1.62,415.43],[2,1.01,10.51]],"batl":[[0,2.06,84.69],[1,1.96,0],[2,2.06,0]],"ltp":2.02,"tv":19.68,"id":4520808}]}]}
{"op":"mcm","clk":"1008944133","pt":1580662517826,"mc":[{"id":"1.168236370","rc":[{"batb":[[0,1.72,134.15],[1,1.7,238.72],[2,1.62,415.43]],"batl":[[1,2.12,102.64],[2,2.14,106.16]],"ltp":2.02,"tv":19.68,"id":4520808}]}]}
{"op":"mcm","clk":"1008945246","pt":1580662526235,"mc":[{"id":"1.168236370","rc":[{"batb":[[0,1.7,23.92],[1,1.62,415.43],[2,1.01,10.51]],"batl":[[1,2.12,0],[2,2.14,0]],"ltp":2.02,"tv":19.68,"id":4520808}]}]}
{"op":"mcm","clk":"1008945582","pt":1580662529164,"mc":[{"id":"1.168236370","rc":[{"batb":[[1,1.01,10.51],[2,1.01,0]],"ltp":2.02,"tv":19.68,"id":4520808},{"batb":[[0,1.89,136.88],[1,1.87,156.09],[2,1.86,17.62]],"batl":[[0,1.97,102.68],[1,1.99,131.12]],"ltp":2.0,"tv":104.11,"id":8284479}]}]}
{"op":"mcm","clk":"1008945694","pt":1580662530058,"mc":[{"id":"1.168236370","rc":[{"batb":[[0,2.02,27.46],[1,1.96,43.69],[2,1.84,18.33]],"batl":[[1,2.14,36.13]],"ltp":2.02,"tv":19.68,"id":4520808},{"batb":[[2,1.86,66.36]],"batl":[[2,2.04,40.33]],"ltp":2.0,"tv":104.11,"id":8284479}]}]}
{"op":"mcm","clk":"1008947260","pt":1580662543167,"mc":[{"id":"1.168236370","rc":[{"trd":[[2.06,71.32]],"batl":[[0,2.06,13.38]],"ltp":2.06,"tv":91.0,"id":4520808},{"trd":[[1.94,75.72]],"ltp":1.94,"tv":179.83,"id":8284479}],"tv":270.83}]}
{"op":"mcm","clk":"1008947336","pt":1580662543856,"mc":[{"id":"1.168236370","rc":[{"batb":[[0,1.96,43.69],[1,1.84,18.33],[2,1.7,409.32]],"ltp":2.06,"tv":91.0,"id":4520808},{"batb":[[0,1.86,48.73],[1,1.76,21.17],[2,1.62,415.43]],"batl":[[0,2.04,40.33],[1,1.99,0],[2,2.04,0]],"ltp":1.94,"tv":179.83,"id":8284479}]}]}
{"op":"mcm","clk":"1008947427","pt":1580662544591,"mc":[{"id":"1.168236370","rc":[{"batb":[[0,1.84,18.33],[1,1.7,409.32],[2,1.01,10.51]],"batl":[[1,2.14,0]],"ltp":2.06,"tv":91.0,"id":4520808},{"batb":[[0,1.76,21.17],[1,1.62,415.43],[2,1.01,10.51]],"ltp":1.94,"tv":179.83,"id":8284479}]}]}
{"op":"mcm","clk":"1008947743","pt":1580662547080,"mc":[{"id":"1.168236370","rc":[{"batb":[[0,1.8,185.28],[1,1.78,183.16],[2,1.76,21.17]],"batl":[[0,2.16,91.32],[1,2.18,100.87]],"ltp":1.94,"tv":179.83,"id":8284479}]}]}
{"op":"mcm","clk":"1008948348","pt":1580662551596,"mc":[{"id":"1.168236370","rc":[{"batb":[[1,1.01,10.51],[2,1.01,0]],"ltp":2.06,"tv":91.0,"id":4520808}]}]}
{"op":"mcm","clk":"1008948553","pt":1580662553172,"mc":[{"id":"1.168236370","rc":[{"trd":[[2.06,84.69]],"ltp":2.06,"tv":104.37,"id":4520808},{"trd":[[1.94,89.92]],"batl":[[0,1.88,116.05],[1,1.9,150.64]],"ltp":1.94,"tv":194.03,"id":8284479}],"tv":298.41}]}
{"op":"mcm","clk":"1008948701","pt":1580662554204,"mc":[{"id":"1.168236370","rc":[{"batb":[[0,2.14,22.66],[1,2,28.4],[2,1.84,18.33]],"batl":[[0,2.24,33.61]],"ltp":2.06,"tv":104.37,"id":4520808},{"batb":[[1,1.79,52.93],[2,1.78,183.16]],"batl":[[2,1.95,42.01]],"ltp":1.94,"tv":194.03,"id":8284479}]}]}
{"op":"mcm","clk":"1008948813","pt":1580662555080,"mc":[{"id":"1.168236370","rc":[{"batb":[[1,2.06,13.24],[2,2,28.4]],"ltp":2.06,"tv":104.37,"id":4520808}]}]}
{"op":"mcm","clk":"1008948945","pt":1580662556191,"mc":[{"id":"1.168236370","rc":[{"batb":[[1,2,28.4],[2,1.84,18.33]],"ltp":2.06,"tv":104.37,"id":4520808}]}]}
{"op":"mcm","clk":"1008949049","pt":1580662556979,"mc":[{"id":"1.168236370","rc":[{"batb":[[1,2.06,39.49],[2,2,28.4]],"ltp":2.06,"tv":104.37,"id":4520808}]}]}
{"op":"mcm","clk":"1008950000","pt":1580662563778,"mc":[{"id":"1.168236370","rc":[{"batb":[[0,2.06,39.49],[1,2,28.4],[2,1.77,402.27]],"ltp":2.06,"tv":104.37,"id":4520808},{"batb":[[0,1.79,52.93],[1,1.69,24.08],[2,1.5,426.9]],"batl":[[0,1.95,42.01],[1,1.9,0],[2,1.95,0]],"ltp":1.94,"tv":194.03,"id":8284479}]}]}
{"op":"mcm","clk":"1008950136","pt":1580662564677,"mc":[{"id":"1.168236370","rc":[{"batb":[[0,2,28.4],[1,1.77,402.27],[2,1.01,10.51]],"ltp":2.06,"tv":104.37,"id":4520808},{"batb":[[0,1.69,24.08],[1,1.5,426.9],[2,1.01,10.51]],"ltp":1.94,"tv":194.03,"id":8284479}]}]}
{"op":"mcm","clk":"1008950466","pt":1580662567117,"mc":[{"id":"1.168236370","rc":[{"batb":[[0,1.75,181.67],[1,1.73,201.47],[2,1.69,24.08]],"batl":[[0,1.99,106.24],[1,2.02,189.07]],"ltp":1.94,"tv":194.03,"id":8284479}]}]}
{"op":"mcm","clk":"1008951076","pt":1580662571226,"mc":[{"id":"1.168236370","rc":[{"batb":[[0,2.26,19.67],[1,2.16,279.03],[2,2.14,22.98]],"ltp":2.06,"tv":104.37,"id":4520808},{"batl":[[0,1.83,183.84],[1,1.85,163.41]],"ltp":1.94,"tv":194.03,"id":8284479}]}]}
{"op":"mcm","clk":"1008951217","pt":1580662572226,"mc":[{"id":"1.168236370","rc":[{"batl":[[0,2.32,31.09]],"ltp":2.06,"tv":104.37,"id":4520808},{"batb":[[1,1.74,56.29],[2,1.73,201.47]],"batl":[[2,1.88,42.01]],"ltp":1.94,"tv":194.03,"id":8284479}]}]}
{"op":"mcm","clk":"1008952428","pt":1580662581208,"mc":[{"id":"1.168236370","rc":[{"batb":[[1,2.14,22.98],[2,2.12,36.97]],"ltp":2.06,"tv":104.37,"id":4520808}]}]}
{"op":"mcm","clk":"1008952458","pt":1580662581421,"mc":[{"id":"1.168236370","rc":[{"batb":[[0,2.14,22.98],[1,2.12,36.97],[2,1.77,402.27]],"ltp":2.06,"tv":104.37,"id":4520808},{"batb":[[0,1.74,56.29],[1,1.73,128.5],[2,1.65,26.12]],"batl":[[0,1.88,42.01],[1,1.85,0],[2,1.88,0]],"ltp":1.94,"tv":194.03,"id":8284479}]}]}
{"op":"mcm","clk":"1008952621","pt":1580662582928,"mc":[{"id":"1.168236370","rc":[{"batb":[[1,1.77,402.27],[2,1.01,10.51]],"ltp":2.06,"tv":104.37,"id":4520808},{"batb":[[0,1.73,128.5],[1,1.65,26.12],[2,1.5,426.9]],"ltp":1.94,"tv":194.03,"id":8284479}]}]}
{"op":"mcm","clk":"1008952785","pt":1580662584240,"mc":[{"id":"1.168236370","rc":[{"batb":[[1,1.71,209.4],[2,1.65,26.12]],"batl":[[0,1.88,132.45],[1,1.9,150.6]],"ltp":1.94,"tv":194.03,"id":8284479}]}]}
{"op":"mcm","clk":"1008953839","pt":1580662592133,"mc":[{"id":"1.168236370","rc":[{"batb":[[1,1.01,10.51],[2,1.01,0]],"ltp":2.06,"tv":104.37,"id":4520808}]}]}
{"op":"mcm","clk":"1008953992","pt":1580662593129,"mc":[{"id":"1.168236370","rc":[{"batl":[[0,1.8,170.13],[1,1.82,172.07]],"ltp":1.94,"tv":194.03,"id":8284479}]}]}
{"op":"mcm","clk":"1008954110","pt":1580662594043,"mc":[{"id":"1.168236370","rc":[{"batb":[[0,2.34,18.02],[1,2.18,35.29],[2,2.14,22.74]],"batl":[[0,2.38,30.25]],"ltp":2.06,"tv":104.37,"id":4520808},{"batb":[[1,1.71,268.21]],"batl":[[2,1.84,42.01]],"ltp":1.94,"tv":194.03,"id":8284479}]}]}
{"op":"mcm","clk":"1008955126","pt":1580662602046,"mc":[{"id":"1.168236370","rc":[{"batb":[[0,2.32,18.25]],"ltp":2.06,"tv":104.37,"id":4520808},{"batb":[[2,1.66,25.73]],"ltp":1.94,"tv":194.03,"id":8284479}]}]}
{"op":"mcm","clk":"1008955809","pt":1580662607061,"mc":[{"id":"1.168236370","rc":[{"trd":[[2.32,18.25]],"batb":[[0,2.18,35.29],[1,2.14,22.74],[2,1.86,398.62]],"ltp":2.32,"tv":122.63,"id":4520808},{"trd":[[1.76,24.06],[1.8,205.64]],"batl":[[0,1.8,67.31]],"ltp":1.8,"tv":423.73,"id":8284479}],"tv":546.36}]}
{"op":"mcm","clk":"1008956157","pt":1580662610091,"mc":[{"id":"1.168236370","rc":[{"batb":[[0,2.32,18.25],[1,2.18,35.29],[2,2.14,22.74]],"ltp":2.32,"tv":122.63,"id":4520808},{"batb":[[0,1.73,162.71],[2,1.69,25.73]],"batl":[[0,1.8,137.26]],"ltp":1.8,"tv":423.73,"id":8284479}]}]}
{"op":"mcm","clk":"1008956431","pt":1580662612459,"mc":[{"id":"1.168236370","rc":[{"batb":[[0,1.73,133.94]],"ltp":1.8,"tv":423.73,"id":8284479}]}]}
{"op":"mcm","clk":"1008956902","pt":1580662616129,"mc":[{"id":"1.168236370","rc":[{"trd":[[2.32,19.72]],"batb":[[0,2.32,16.78]],"ltp":2.32,"tv":124.1,"id":4520808},{"trd":[[1.76,26]],"batl":[[0,1.8,164.98]],"ltp":1.76,"tv":425.67,"id":8284479}],"tv":549.77}]}
{"op":"mcm","clk":"1008957178","pt":1580662618207,"mc":[{"id":"1.168236370","rc":[{"batb":[[0,2.3,18.73],[2,2.12,23.6]],"ltp":2.32,"tv":124.1,"id":4520808},{"batb":[[2,1.7,25.26]],"ltp":1.76,"tv":425.67,"id":8284479}]}]}
{"op":"mcm","clk":"1008960167","pt":1580662641721,"mc":[{"id":"1.168236370","rc":[{"batb":[[0,1.71,58.81],[1,1.7,25.26],[2,1.54,35.8]],"batl":[[0,1.84,42.01],[1,1.82,0],[2,1.84,0]],"ltp":1.76,"tv":425.67,"id":8284479}]}]}
{"op":"mcm","clk":"1008960565","pt":1580662644736,"mc":[{"id":"1.168236370","rc":[{"batb":[[0,1.72,196.2],[1,1.71,58.81],[2,1.7,239.43]],"batl":[[0,1.79,116.77],[1,1.81,175.47],[2,1.84,42.01]],"ltp":1.76,"tv":425.67,"id":8284479}]}]}
{"op":"mcm","clk":"1008960917","pt":1580662647532,"mc":[{"id":"1.168236370","rc":[{"batl":[[0,1.73,30.29],[1,1.79,116.77],[2,1.81,175.47]],"ltp":1.76,"tv":425.67,"id":8284479}]}]}
{"op":"mcm","clk":"1008961989","pt":1580662656243,"mc":[{"id":"1.168236370","rc":[{"batl":[[0,1.79,116.77],[1,1.81,175.47],[2,1.84,42.01]],"ltp":1.76,"tv":425.67,"id":8284479}]}]}
{"op":"mcm","clk":"1008962316","pt":1580662659336,"mc":[{"id":"1.168236370","rc":[{"trd":[[1.72,60.58]],"batb":[[0,1.72,165.91]],"ltp":1.72,"tv":486.25,"id":8284479}],"tv":610.35}]}
{"op":"mcm","clk":"1008963990","pt":1580662673232,"mc":[{"id":"1.168236370","rc":[{"batl":[[0,1.84,42.01],[1,1.81,0],[2,1.84,0]],"ltp":1.72,"tv":486.25,"id":8284479}]}]}
{"op":"mcm","clk":"1008964296","pt":1580662676138,"mc":[{"id":"1.168236370","rc":[{"batb":[[0,1.72,206.6]],"batl":[[0,1.8,195.08],[1,1.82,172.12],[2,1.84,42.01]],"ltp":1.72,"tv":486.25,"id":8284479}]}]}
{"op":"mcm","clk":"1008964964","pt":1580662682173,"mc":[{"id":"1.168236370","rc":[{"batb":[[0,2.18,35.29],[1,2.12,23.6],[2,1.86,398.62]],"ltp":2.32,"tv":124.1,"id":4520808},{"batb":[[0,1.71,58.81],[1,1.54,35.8],[2,1.5,426.9]],"batl":[[0,1.84,42.01],[1,1.82,0],[2,1.84,0]],"ltp":1.72,"tv":486.25,"id":8284479}]}]}
{"op":"mcm","clk":"1008965026","pt":1580662682664,"mc":[{"id":"1.168236370","rc":[{"batb":[[0,2.12,23.6],[1,1.86,398.62],[2,1.01,10.51]],"ltp":2.32,"tv":124.1,"id":4520808},{"batb":[[0,1.54,35.8],[1,1.5,426.9],[2,1.01,10.51]],"ltp":1.72,"tv":486.25,"id":8284479}]}]}
{"op":"mcm","clk":"1008965297","pt":1580662685172,"mc":[{"id":"1.168236370","rc":[{"batb":[[1,2.1,24.08],[2,1.86,398.62]],"ltp":2.32,"tv":124.1,"id":4520808},{"batb":[[0,1.57,199.26],[1,1.56,147.05],[2,1.54,35.8]],"batl":[[0,1.91,163.38],[1,1.93,143.71]],"ltp":1.72,"tv":486.25,"id":8284479}]}]}
{"op":"mcm","clk":"1008965386","pt":1580662685861,"mc":[{"id":"1.168236370","rc":[{"batb":[[0,2.1,24.08],[1,1.86,398.62],[2,1.01,10.51]],"ltp":2.32,"tv":124.1,"id":4520808},{"batb":[[2,1.54,35.17]],"ltp":1.72,"tv":486.25,"id":8284479}]}]}
{"op":"mcm","clk":"1008967030","pt":1580662698094,"mc":[{"id":"1.168236370","rc":[{"batb":[[1,1.01,10.51],[2,1.01,0]],"ltp":2.32,"tv":124.1,"id":4520808}]}]}
{"op":"mcm","clk":"1008967188","pt":1580662699194,"mc":[{"id":"1.168236370","rc":[{"batl":[[0,1.63,198.16],[1,1.64,120.8]],"ltp":1.72,"tv":486.25,"id":8284479}]}]}
{"op":"mcm","clk":"1008967307","pt":1580662699983,"mc":[{"id":"1.168236370","rc":[{"batb":[[0,2.66,12.75],[1,2.44,28.57],[2,2.34,17.62]],"batl":[[0,2.74,23.53]],"ltp":2.32,"tv":124.1,"id":4520808},{"batb":[[0,1.58,72.26],[1,1.57,199.26],[2,1.56,147.05]],"batl":[[2,1.69,42.01]],"ltp":1.72,"tv":486.25,"id":8284479}]}]}
{"op":"mcm","clk":"1008969832","pt":1580662718111,"mc":[{"id":"1.168236370","rc":[{"batb":[[0,2.44,28.57],[1,2.34,17.62],[2,2.04,394.09]],"ltp":2.32,"tv":124.1,"id":4520808},{"batb":[[1,1.39,54.05],[2,1.34,465.43]],"batl":[[0,1.69,42.01],[1,1.64,0],[2,1.69,0]],"ltp":1.72,"tv":486.25,"id":8284479}]}]}
{"op":"mcm","clk":"1008969938","pt":1580662718789,"mc":[{"id":"1.168236370","rc":[{"batb":[[0,2.34,17.62],[1,2.04,394.09],[2,1.01,10.51]],"ltp":2.32,"tv":124.1,"id":4520808},{"batb":[[0,1.39,54.05],[1,1.34,465.43],[2,1.01,10.51]],"ltp":1.72,"tv":486.25,"id":8284479}]}]}
{"op":"mcm","clk":"1008970218","pt":1580662720984,"mc":[{"id":"1.168236370","rc":[{"batb":[[0,1.4,306.98],[1,1.39,292.81],[2,1.34,465.43]],"batl":[[0,1.76,184.7],[1,1.78,184.78]],"ltp":1.72,"tv":486.25,"id":8284479}]}]}
{"op":"mcm","clk":"1008970601","pt":1580662724231,"mc":[{"id":"1.168236370","rc":[{"batb":[[0,1.39,54.05],[1,1.34,465.43],[2,1.01,10.51]],"ltp":1.72,"tv":486.25,"id":8284479}]}]}
{"op":"mcm","clk":"1008970824","pt":1580662726216,"mc":[{"id":"1.168236370","rc":[{"batb":[[1,1.01,10.51],[2,1.01,0]],"ltp":1.72,"tv":486.25,"id":8284479}]}]}
{"op":"mcm","clk":"1008970954","pt":1580662727209,"mc":[{"id":"1.168236370","rc":[{"batb":[[0,1.69,158.93],[1,1.67,227.63],[2,1.39,54.05]],"batl":[[0,1.76,184.7],[1,1.78,184.78]],"ltp":1.72,"tv":486.25,"id":8284479}]}]}
{"op":"mcm","clk":"1008971064","pt":1580662727993,"mc":[{"id":"1.168236370","rc":[{"batb":[[1,2.26,32.77],[2,2.12,23.29]],"batl":[[0,2.48,27.73]],"ltp":2.32,"tv":124.1,"id":4520808},{"batb":[[1,1.67,316.4],[2,1.49,40.29]],"batl":[[2,1.81,42.01]],"ltp":1.72,"tv":486.25,"id":8284479}]}]}
{"op":"mcm","clk":"1008973184","pt":1580662744620,"mc":[{"id":"1.168236370","rc":[{"batb":[[0,2.12,23.29],[1,2.04,394.09],[2,1.01,10.51]],"ltp":2.32,"tv":124.1,"id":4520808},{"batb":[[0,1.49,40.29],[1,1.4,451],[2,1.01,10.51]],"ltp":1.72,"tv":486.25,"id":8284479}]}]}
{"op":"mcm","clk":"1008973496","pt":1580662747228,"mc":[{"id":"1.168236370","rc":[{"batb":[[0,2.14,23.05],[1,2.12,23.29],[2,2.04,394.09]],"ltp":2.32,"tv":124.1,"id":4520808}]}]}
{"op":"mcm","clk":"1008973566","pt":1580662747755,"mc":[{"id":"1.168236370","rc":[{"batb":[[1,2.04,394.09],[2,1.01,10.51]],"ltp":2.32,"tv":124.1,"id":4520808}]}]}
{"op":"mcm","clk":"1008973627","pt":1580662748411,"mc":[{"id":"1.168236370","rc":[{"batb":[[0,1.51,188.73],[1,1.5,171.47],[2,1.49,40.29]],"batl":[[0,1.89,139.86],[1,1.91,148.43]],"ltp":1.72,"tv":486.25,"id":8284479}]}]}
{"op":"mcm","clk":"1008973903","pt":1580662750948,"mc":[{"id":"1.168236370","rc":[{"batb":[[1,1.01,10.51],[2,1.01,0]],"ltp":2.32,"tv":124.1,"id":4520808}]}]}
{"op":"mcm","clk":"1008974140","pt":1580662753200,"mc":[{"id":"1.168236370","rc":[{"batb":[[0,2.84,10.7],[1,2.44,15.97],[2,1.01,10.51]],"ltp":2.32,"tv":124.1,"id":4520808},{"batl":[[0,1.56,171.13],[1,1.57,141.46]],"ltp":1.72,"tv":486.25,"id":8284479}]}]}
{"op":"mcm","clk":"1008974222","pt":1580662753655,"mc":[{"id":"1.168236370","rc":[{"batb":[[1,2.62,25.21],[2,2.44,15.97]],"batl":[[0,2.94,21]],"ltp":2.32,"tv":124.1,"id":4520808},{"batb":[[0,1.51,271.07]],"batl":[[2,1.62,42.01]],"ltp":1.72,"tv":486.25,"id":8284479}]}]}
{"op":"mcm","clk":"1008976123","pt":1580662770194,"mc":[{"id":"1.168236370","rc":[{"trd":[[2.84,2.07]],"batb":[[0,2.84,8.63]],"ltp":2.84,"tv":126.17,"id":4520808},{"trd":[[1.55,3.79]],"ltp":1.55,"tv":490.03,"id":8284479}],"tv":616.21}]}
{"op":"mcm","clk":"1008976306","pt":1580662771779,"mc":[{"id":"1.168236370","rc":[{"batb":[[0,2.62,25.21],[1,2.44,15.97],[2,2.22,384.52]],"ltp":2.84,"tv":126.17,"id":4520808},{"batb":[[0,1.51,82.34],[1,1.31,71.36],[2,1.28,485.89]],"batl":[[0,1.62,42.01],[1,1.57,0],[2,1.62,0]],"ltp":1.55,"tv":490.03,"id":8284479}]}]}
{"op":"mcm","clk":"1008976427","pt":1580662772760,"mc":[{"id":"1.168236370","rc":[{"batb":[[0,2.44,15.97],[1,2.22,384.52],[2,1.01,10.51]],"ltp":2.84,"tv":126.17,"id":4520808},{"batb":[[0,1.31,71.36],[1,1.28,485.89],[2,1.01,10.51]],"ltp":1.55,"tv":490.03,"id":8284479}]}]}
{"op":"mcm","clk":"1008976578","pt":1580662774179,"mc":[{"id":"1.168236370","rc":[{"batb":[[0,1.32,173.47],[1,1.31,388.62],[2,1.28,485.89]],"batl":[[0,1.72,184.42],[1,1.74,199.04]],"ltp":1.55,"tv":490.03,"id":8284479}]}]}
{"op":"mcm","clk":"1008976638","pt":1580662774666,"mc":[{"id":"1.168236370","rc":[{"batb":[[0,2.42,16.13]],"ltp":2.84,"tv":126.17,"id":4520808},{"batb":[[1,1.31,388.15]],"ltp":1.55,"tv":490.03,"id":8284479}]}]}
{"op":"mcm","clk":"1008977137","pt":1580662779000,"mc":[{"id":"1.168236370","rc":[{"batb":[[0,1.31,70.89],[1,1.28,485.89],[2,1.01,10.51]],"ltp":1.55,"tv":490.03,"id":8284479}]}]}
{"op":"mcm","clk":"1008977349","pt":1580662780371,"mc":[{"id":"1.168236370","rc":[{"batb":[[1,1.01,10.51],[2,1.01,0]],"ltp":2.84,"tv":126.17,"id":4520808},{"batb":[[1,1.01,10.51],[2,1.01,0]],"ltp":1.55,"tv":490.03,"id":8284479}]}]}
{"op":"mcm","clk":"1008977517","pt":1580662781688,"mc":[{"id":"1.168236370","rc":[{"batb":[[0,1.65,211.72],[1,1.64,122.32],[2,1.31,70.89]],"ltp":1.55,"tv":490.03,"id":8284479}]}]}
{"op":"mcm","clk":"1008977612","pt":1580662782610,"mc":[{"id":"1.168236370","rc":[{"batb":[[1,2.12,23.45],[2,1.01,10.51]],"ltp":2.84,"tv":126.17,"id":4520808},{"batb":[[1,1.64,151.12],[2,1.42,49.88]],"ltp":1.55,"tv":490.03,"id":8284479}]}]}
{"op":"mcm","clk":"1008977739","pt":1580662783667,"mc":[{"id":"1.168236370","rc":[{"batb":[[1,2.32,31.09],[2,2.12,23.45]],"batl":[[0,2.56,26.89]],"ltp":2.84,"tv":126.17,"id":4520808},{"batb":[[1,1.64,216.65]],"batl":[[2,1.76,42.01]],"ltp":1.55,"tv":490.03,"id":8284479}]}]}
{"op":"mcm","clk":"1008978599","pt":1580662791120,"mc":[{"id":"1.168236370","rc":[{"trd":[[2.54,2.29]],"ltp":2.54,"tv":128.45,"id":4520808},{"trd":[[1.65,3.52]],"batb":[[0,1.65,208.2]],"ltp":1.65,"tv":493.55,"id":8284479}],"tv":622.01}]}
{"op":"mcm","clk":"1008979953","pt":1580662801703,"mc":[{"id":"1.168236370","rc":[{"batb":[[0,1.65,185.59]],"ltp":1.65,"tv":493.55,"id":8284479}]}]}
{"op":"mcm","clk":"1008980429","pt":1580662805012,"mc":[{"id":"1.168236370","rc":[{"batb":[[0,2.12,23.45],[1,1.97,394.86],[2,1.01,10.51]],"ltp":2.54,"tv":128.45,"id":4520808},{"batb":[[0,1.42,49.88],[1,1.38,448.45],[2,1.01,10.51]],"ltp":1.65,"tv":493.55,"id":8284479}]}]}
{"op":"mcm","clk":"1008980885","pt":1580662808245,"mc":[{"id":"1.168236370","rc":[{"batb":[[0,2.14,23.21]],"batl":[[0,2.42,63.61]],"ltp":2.54,"tv":128.45,"id":4520808},{"batb":[[0,1.43,134.61],[1,1.42,215.61],[2,1.41,50.36]],"batl":[[0,1.9,161.19],[1,1.92,146.15]],"ltp":1.65,"tv":493.55,"id":8284479}]}]}
{"op":"mcm","clk":"1008983205","pt":1580662827223,"mc":[{"id":"1.168236370","rc":[{"batb":[[0,1.41,50.36],[1,1.38,448.45],[2,1.01,10.51]],"ltp":1.65,"tv":493.55,"id":8284479}]}]}
{"op":"mcm","clk":"1008983372","pt":1580662828645,"mc":[{"id":"1.168236370","rc":[{"batb":[[1,1.01,10.51],[2,1.01,0]],"ltp":2.54,"tv":128.45,"id":4520808},{"batb":[[1,1.01,10.51],[2,1.01,0]],"ltp":1.65,"tv":493.55,"id":8284479}]}]}
{"op":"mcm","clk":"1008983557","pt":1580662830226,"mc":[{"id":"1.168236370","rc":[{"batb":[[0,1.82,134.96],[1,1.8,176.77],[2,1.41,50.36]],"ltp":1.65,"tv":493.55,"id":8284479}]}]}
{"op":"mcm","clk":"1008983644","pt":1580662830923,"mc":[{"id":"1.168236370","rc":[{"batb":[[1,1.97,29.74],[2,1.01,10.51]],"ltp":2.54,"tv":128.45,"id":4520808},{"batb":[[1,1.8,197.46],[2,1.61,30.21]],"ltp":1.65,"tv":493.55,"id":8284479}]}]}
{"op":"mcm","clk":"1008983756","pt":1580662831733,"mc":[{"id":"1.168236370","rc":[{"batb":[[1,2.08,38.65],[2,1.97,29.74]],"batl":[[0,2.28,32.77]],"ltp":2.54,"tv":128.45,"id":4520808},{"batb":[[2,1.78,53.77]],"batl":[[1,1.92,188.16]],"ltp":1.65,"tv":493.55,"id":8284479}]}]}
{"op":"mcm","clk":"1008986740","pt":1580662854136,"mc":[{"id":"1.168236370","rc":[{"batb":[[0,1.82,114.43]],"batl":[[0,1.92,42.01],[1,1.92,0]],"ltp":1.65,"tv":493.55,"id":8284479}]}]}
{"op":"mcm","clk":"1008986869","pt":1580662855081,"mc":[{"id":"1.168236370","rc":[{"batb":[[0,2.08,38.65],[1,1.97,29.35],[2,1.77,402.27]],"ltp":2.54,"tv":128.45,"id":4520808},{"batb":[[0,1.78,53.77],[1,1.61,30.21],[2,1.5,426.9]],"ltp":1.65,"tv":493.55,"id":8284479}]}]}
{"op":"mcm","clk":"1008987137","pt":1580662857048,"mc":[{"id":"1.168236370","rc":[{"batb":[[0,1.97,29.35],[1,1.77,402.27],[2,1.01,10.51]],"ltp":2.54,"tv":128.45,"id":4520808},{"batb":[[0,1.61,30.21],[1,1.5,426.9],[2,1.01,10.51]],"ltp":1.65,"tv":493.55,"id":8284479}]}]}
{"op":"mcm","clk":"1008987295","pt":1580662858156,"mc":[{"id":"1.168236370","rc":[{"batb":[[0,1.64,147.22],[1,1.63,125],[2,1.61,30.21]],"batl":[[0,2.02,100.43],[1,2.04,122.15]],"ltp":1.65,"tv":493.55,"id":8284479}]}]}
{"op":"mcm","clk":"1008987513","pt":1580662859954,"mc":[{"id":"1.168236370","rc":[{"batb":[[0,1.61,30.21],[1,1.5,426.9],[2,1.01,10.51]],"ltp":1.65,"tv":493.55,"id":8284479}]}]}
{"op":"mcm","clk":"1008987677","pt":1580662861178,"mc":[{"id":"1.168236370","rc":[{"batb":[[1,1.01,10.51],[2,1.01,0]],"ltp":1.65,"tv":493.55,"id":8284479}]}]}
{"op":"mcm","clk":"1008987946","pt":1580662863188,"mc":[{"id":"1.168236370","rc":[{"batb":[[2,1.75,21.4]],"ltp":2.54,"tv":128.45,"id":4520808},{"batb":[[0,1.94,121.82],[1,1.92,143.94],[2,1.81,20.61]],"ltp":1.65,"tv":493.55,"id":8284479}]}]}
{"op":"mcm","clk":"1008988076","pt":1580662864085,"mc":[{"id":"1.168236370","rc":[{"batb":[[1,1.95,43.69],[2,1.77,402.27]],"batl":[[0,2.12,36.97]],"ltp":2.54,"tv":128.45,"id":4520808},{"batb":[[2,1.89,47.05]],"batl":[[2,2.06,39.49]],"ltp":1.65,"tv":493.55,"id":8284479}]}]}
{"op":"mcm","clk":"1008989263","pt":1580662873104,"mc":[{"id":"1.168236370","rc":[{"batl":[[0,2.04,122.15],[1,2.06,39.49],[2,2.06,0]],"ltp":1.65,"tv":493.55,"id":8284479}]}]}
{"op":"mcm","clk":"1008989567","pt":1580662875237,"mc":[{"id":"1.168236370","rc":[{"batl":[[0,2.04,209.03],[1,2.06,158.19]],"ltp":1.65,"tv":493.55,"id":8284479}]}]}
{"op":"mcm","clk":"1008991561","pt":1580662889116,"mc":[{"id":"1.168236370","rc":[{"batb":[[0,1.95,43.69],[1,1.77,402.27],[2,1.75,21.4]],"ltp":2.54,"tv":128.45,"id":4520808},{"batb":[[0,1.89,47.05],[1,1.81,20.61],[2,1.55,420.5]],"batl":[[0,2.06,39.49],[1,2.06,0]],"ltp":1.65,"tv":493.55,"id":8284479}]}]}
{"op":"mcm","clk":"1008991803","pt":1580662890701,"mc":[{"id":"1.168236370","rc":[{"batb":[[0,1.77,402.27],[1,1.75,21.4],[2,1.01,10.51]],"ltp":2.54,"tv":128.45,"id":4520808},{"batb":[[0,1.81,20.61],[1,1.55,420.5],[2,1.01,10.51]],"ltp":1.65,"tv":493.55,"id":8284479}]}]}
{"op":"mcm","clk":"1008992486","pt":1580662895232,"mc":[{"id":"1.168236370","rc":[{"batl":[[0,2.02,99.21],[1,2.04,122.24]],"ltp":2.54,"tv":128.45,"id":4520808}]}]}
{"op":"mcm","clk":"1008992877","pt":1580662898129,"mc":[{"id":"1.168236370","rc":[{"batb":[[0,1.94,106.89],[1,1.92,144],[2,1.77,402.27]],"ltp":2.54,"tv":128.45,"id":4520808}]}]}
{"op":"mcm","clk":"1008993020","pt":1580662899037,"mc":[{"id":"1.168236370","rc":[{"batl":[[0,2.04,122.24],[1,2.04,0]],"ltp":2.54,"tv":128.45,"id":4520808}]}]}
{"op":"mcm","clk":"1008993207","pt":1580662900056,"mc":[{"id":"1.168236370","rc":[{"batb":[[0,1.77,402.27],[1,1.75,21.4],[2,1.01,10.51]],"ltp":2.54,"tv":128.45,"id":4520808}]}]}
{"op":"mcm","clk":"1008993536","pt":1580662902068,"mc":[{"id":"1.168236370","rc":[{"batl":[[0,2.04,89.67],[1,2.06,118.83]],"ltp":2.54,"tv":128.45,"id":4520808}]}]}
{"op":"mcm","clk":"1008993670","pt":1580662902937,"mc":[{"id":"1.168236370","rc":[{"batb":[[0,1.77,540.12],[1,1.75,216.09]],"batl":[[0,2.24,139.84],[1,2.26,91.33]],"ltp":2.54,"tv":128.45,"id":4520808}]}]}
{"op":"mcm","clk":"1008993849","pt":1580662903942,"mc":[{"id":"1.168236370","rc":[{"batb":[[0,1.77,402.27],[1,1.75,21.4]],"ltp":2.54,"tv":128.45,"id":4520808}]}]}
{"op":"mcm","clk":"1008994393","pt":1580662907132,"mc":[{"id":"1.168236370","rc":[{"batb":[[0,1.81,162.34],[1,1.79,180.19],[2,1.55,420.5]],"batl":[[0,1.89,164.24],[1,1.91,148.63]],"ltp":1.65,"tv":493.55,"id":8284479}]}]}
{"op":"mcm","clk":"1008994539","pt":1580662908076,"mc":[{"id":"1.168236370","rc":[{"batb":[[0,2.12,23.29],[1,2.06,39.49],[2,1.92,16.05]],"batl":[[0,2.26,32.77]],"ltp":2.54,"tv":128.45,"id":4520808},{"batb":[[1,1.8,52.09],[2,1.79,180.19]],"batl":[[2,1.95,42.01]],"ltp":1.65,"tv":493.55,"id":8284479}]}]}
{"op":"mcm","clk":"1008996503","pt":1580662921204,"mc":[{"id":"1.168236370","rc":[{"batb":[[0,2.06,39.49],[1,1.92,16.05],[2,1.77,402.27]],"ltp":2.54,"tv":128.45,"id":4520808},{"batb":[[0,1.8,52.09],[1,1.71,24.55],[2,1.55,420.5]],"batl":[[0,1.95,42.01],[1,1.91,0],[2,1.95,0]],"ltp":1.65,"tv":493.55,"id":8284479}]}]}
{"op":"mcm","clk":"1008996747","pt":1580662922894,"mc":[{"id":"1.168236370","rc":[{"batb":[[0,1.92,16.05],[1,1.77,402.27],[2,1.01,10.51]],"ltp":2.54,"tv":128.45,"id":4520808},{"batb":[[0,1.71,24.55],[1,1.55,420.5],[2,1.01,10.51]],"ltp":1.65,"tv":493.55,"id":8284479}]}]}
{"op":"mcm","clk":"1008996924","pt":1580662924052,"mc":[{"id":"1.168236370","rc":[{"batb":[[0,1.73,145.65],[1,1.71,234.66],[2,1.55,420.5]],"batl":[[0,2.08,159.54],[1,2.1,112.38]],"ltp":1.65,"tv":493.55,"id":8284479}]}]}
{"op":"mcm","clk":"1008998479","pt":1580662934100,"mc":[{"id":"1.168236370","rc":[{"batb":[[0,1.71,24.55],[1,1.55,420.5],[2,1.01,10.51]],"ltp":1.65,"tv":493.55,"id":8284479}]}]}
{"op":"mcm","clk":"1008998760","pt":1580662936169,"mc":[{"id":"1.168236370","rc":[{"batb":[[1,1.01,10.51],[2,1.01,0]],"ltp":2.54,"tv":128.45,"id":4520808},{"batb":[[1,1.01,10.51],[2,1.01,0]],"ltp":1.65,"tv":493.55,"id":8284479}]}]}
{"op":"mcm","clk":"1009005242","pt":1580662978140,"mc":[{"id":"1.168236370","rc":[{"batb":[[0,1.73,145.65],[1,1.71,234.66],[2,1.01,10.51]],"batl":[[0,1.8,155.92],[1,1.82,172.69]],"ltp":1.65,"tv":493.55,"id":8284479}]}]}
{"op":"mcm","clk":"1009005421","pt":1580662979171,"mc":[{"id":"1.168236370","rc":[{"batb":[[0,2.28,19.28],[1,2.08,24.63],[2,1.01,10.51]],"ltp":2.54,"tv":128.45,"id":4520808},{"batb":[[2,1.65,27.7]],"ltp":1.65,"tv":493.55,"id":8284479}]}]}
{"op":"mcm","clk":"1009005557","pt":1580662979845,"mc":[{"id":"1.168236370","rc":[{"batb":[[1,2.16,36.13],[2,2.08,24.63]],"batl":[[0,2.38,30.25]],"ltp":2.54,"tv":128.45,"id":4520808},{"batb":[[1,1.72,57.97],[2,1.71,234.66]],"batl":[[2,1.87,42.01]],"ltp":1.65,"tv":493.55,"id":8284479}]}]}
{"op":"mcm","clk":"1009007329","pt":1580662991244,"mc":[{"id":"1.168236370","rc":[{"batb":[[0,2.16,36.13],[1,2.08,24.63],[2,1.86,398.62]],"ltp":2.54,"tv":128.45,"id":4520808},{"batb":[[0,1.72,57.97],[1,1.65,27.7],[2,1.44,436.18]],"batl":[[0,1.87,42.01],[1,1.82,0],[2,1.87,0]],"ltp":1.65,"tv":493.55,"id":8284479}]}]}
{"op":"mcm","clk":"1009007665","pt":1580662993172,"mc":[{"id":"1.168236370","rc":[{"batb":[[0,2.08,24.63],[1,1.86,398.62],[2,1.01,10.51]],"ltp":2.54,"tv":128.45,"id":4520808},{"batb":[[0,1.65,27.7],[1,1.44,436.18],[2,1.01,10.51]],"ltp":1.65,"tv":493.55,"id":8284479}]}]}
{"op":"mcm","clk":"1009007832","pt":1580662994166,"mc":[{"id":"1.168236370","rc":[{"batb":[[0,1.68,178.07],[1,1.66,233.19],[2,1.65,27.7]],"batl":[[0,1.91,171.21],[1,1.93,143.98]],"ltp":1.65,"tv":493.55,"id":8284479}]}]}
{"op":"mcm","clk":"1009008775","pt":1580662999979,"mc":[{"id":"1.168236370","rc":[{"batb":[[0,2.38,16.84],[1,2.26,19.59],[2,2.22,33.61]],"batl":[[0,2.48,27.73]],"ltp":2.54,"tv":128.45,"id":4520808},{"batb":[[0,1.68,239.4]],"batl":[[0,1.75,180.18],[1,1.77,188.72],[2,1.8,42.01]],"ltp":1.65,"tv":493.55,"id":8284479}]}]}
{"op":"mcm","clk":"1009010403","pt":1580663009977,"mc":[{"id":"1.168236370","rc":[{"batb":[[0,2.26,19.59],[1,2.22,33.61],[2,1.86,398.62]],"ltp":2.54,"tv":128.45,"id":4520808},{"batb":[[0,1.68,61.33],[1,1.66,159.78],[2,1.61,30.29]],"batl":[[0,1.8,42.01],[1,1.77,0],[2,1.8,0]],"ltp":1.65,"tv":493.55,"id":8284479}]}]}
{"op":"mcm","clk":"1009010533","pt":1580663010772,"mc":[{"id":"1.168236370","rc":[{"batb":[[1,1.86,398.62],[2,1.01,10.51]],"ltp":2.54,"tv":128.45,"id":4520808},{"batb":[[0,1.66,159.78],[1,1.61,30.29],[2,1.44,436.18]],"ltp":1.65,"tv":493.55,"id":8284479}]}]}
{"op":"mcm","clk":"1009010958","pt":1580663013168,"mc":[{"id":"1.168236370","rc":[{"batb":[[1,1.65,119.83],[2,1.61,30.29]],"ltp":1.65,"tv":493.55,"id":8284479}]}]}
{"op":"mcm","clk":"1009011166","pt":1580663014285,"mc":[{"id":"1.168236370","rc":[{"batb":[[1,1.01,10.51],[2,1.01,0]],"ltp":2.54,"tv":128.45,"id":4520808}]}]}
{"op":"mcm","clk":"1009011475","pt":1580663016064,"mc":[{"id":"1.168236370","rc":[{"batb":[[0,2.3,31.93],[1,2.26,19.59],[2,1.01,10.51]],"batl":[[0,2.54,26.89]],"ltp":2.54,"tv":128.45,"id":4520808},{"batb":[[1,1.65,183.68]],"batl":[[0,1.72,121.62],[1,1.74,199.89],[2,1.77,42.01]],"ltp":1.65,"tv":493.55,"id":8284479}]}]}
{"op":"mcm","clk":"1009011560","pt":1580663016585,"mc":[{"id":"1.168236370","rc":[{"batb":[[0,2.48,15.19],[1,2.3,31.93],[2,2.26,19.59]],"ltp":2.54,"tv":128.45,"id":4520808}]}]}
{"op":"mcm","clk":"1009012198","pt":1580663020420,"mc":[{"id":"1.168236370","rc":[{"batb":[[0,1.65,183.68],[1,1.61,30.29],[2,1.46,43.67]],"batl":[[0,1.77,42.01],[1,1.74,0],[2,1.77,0]],"ltp":1.65,"tv":493.55,"id":8284479}]}]}
{"op":"mcm","clk":"1009012846","pt":1580663024005,"mc":[{"id":"1.168236370","rc":[{"batb":[[0,1.65,214.71],[1,1.64,122.83],[2,1.61,30.29]],"batl":[[0,1.71,120.24],[1,1.73,204.34],[2,1.77,42.01]],"ltp":1.65,"tv":493.55,"id":8284479}]}]}
{"op":"mcm","clk":"1009013396","pt":1580663027235,"mc":[{"id":"1.168236370","rc":[{"batl":[[0,1.71,143.46]],"ltp":1.65,"tv":493.55,"id":8284479}]}]}
{"op":"mcm","clk":"1009015798","pt":1580663041028,"mc":[{"id":"1.168236370","rc":[{"batb":[[0,2.46,15.42],[2,2.24,20.06]],"ltp":2.54,"tv":128.45,"id":4520808},{"batb":[[2,1.62,29.9]],"ltp":1.65,"tv":493.55,"id":8284479}]}]}
{"op":"mcm","clk":"1009018168","pt":1580663054416,"mc":[{"id":"1.168236370","rc":[{"batb":[[0,2.48,15.34]],"ltp":2.54,"tv":128.45,"id":4520808}]}]}
{"op":"mcm","clk":"1009019523","pt":1580663062171,"mc":[{"id":"1.168236370","rc":[{"batb":[[2,2.26,19.91]],"ltp":2.54,"tv":128.45,"id":4520808}]}]}
{"op":"mcm","clk":"1009019732","pt":1580663063169,"mc":[{"id":"1.168236370","rc":[{"batb":[[2,1.61,30.14]],"ltp":1.65,"tv":493.55,"id":8284479}]}]}
{"op":"mcm","clk":"1009027700","pt":1580663107036,"mc":[{"id":"1.168236370","rc":[{"batb":[[0,2.26,19.91],[1,1.97,394.86],[2,1.01,10.51]],"ltp":2.54,"tv":128.45,"id":4520808},{"batb":[[0,1.46,43.43],[1,1.44,436.18],[2,1.01,10.51]],"ltp":1.65,"tv":493.55,"id":8284479}]}]}
{"op":"mcm","clk":"1009028190","pt":1580663109913,"mc":[{"id":"1.168236370","rc":[{"batb":[[0,1.5,193.23],[1,1.49,177.56],[2,1.46,43.43]],"batl":[[0,1.82,145.29],[1,1.84,167.34]],"ltp":1.65,"tv":493.55,"id":8284479}]}]}
{"op":"mcm","clk":"1009029494","pt":1580663117201,"mc":[{"id":"1.168236370","rc":[{"batb":[[1,1.01,10.51],[2,1.01,0]],"ltp":2.54,"tv":128.45,"id":4520808},{"batl":[[0,1.55,189.82],[1,1.56,145.95]],"ltp":1.65,"tv":493.55,"id":8284479}]}]}
{"op":"mcm","clk":"1009029654","pt":1580663118217,"mc":[{"id":"1.168236370","rc":[{"batb":[[0,2.92,24.86],[1,2.56,14.08],[2,1.01,10.51]],"batl":[[0,2.94,21]],"ltp":2.54,"tv":128.45,"id":4520808}]}]}
{"op":"mcm","clk":"1009030001","pt":1580663120215,"mc":[{"id":"1.168236370","rc":[{"batb":[[2,2.12,388.65]],"ltp":2.54,"tv":128.45,"id":4520808}]}]}
{"op":"mcm","clk":"1009030174","pt":1580663121131,"mc":[{"id":"1.168236370","rc":[{"trd":[[2.92,43.69]],"batb":[[0,2.92,3.02],[1,2.62,25.21],[2,2.56,14.08]],"ltp":2.92,"tv":172.14,"id":4520808},{"batb":[[0,1.51,82.34],[1,1.5,193.23],[2,1.49,177.56]],"batl":[[2,1.6,42.01]],"ltp":1.65,"tv":493.55,"id":8284479}],"tv":665.7}]}
{"op":"mcm","clk":"1009031385","pt":1580663128209,"mc":[{"id":"1.168236370","rc":[{"batb":[[1,1.46,43.43],[2,1.31,549.74]],"batl":[[0,1.6,42.01],[1,1.56,0],[2,1.6,0]],"ltp":1.65,"tv":493.55,"id":8284479}]}]}
{"op":"mcm","clk":"1009031568","pt":1580663129211,"mc":[{"id":"1.168236370","rc":[{"trd":[[2.92,49.31]],"batb":[[0,2.56,14.08],[1,2.12,388.65],[2,1.01,10.51]],"ltp":2.92,"tv":177.76,"id":4520808},{"batb":[[0,1.31,549.74],[1,1.01,10.51],[2,1.31,0]],"ltp":1.65,"tv":493.55,"id":8284479}],"tv":671.32}]}
{"op":"mcm","clk":"1009031923","pt":1580663131212,"mc":[{"id":"1.168236370","rc":[{"batb":[[0,1.34,158.01],[1,1.33,296.49],[2,1.31,549.74]],"batl":[[0,1.68,218.77],[1,1.7,216.27]],"ltp":1.65,"tv":493.55,"id":8284479}]}]}
{"op":"mcm","clk":"1009032032","pt":1580663131958,"mc":[{"id":"1.168236370","rc":[{"batb":[[0,2.52,14.56]],"ltp":2.92,"tv":177.76,"id":4520808},{"batb":[[2,1.32,70.34]],"ltp":1.65,"tv":493.55,"id":8284479}]}]}
{"op":"mcm","clk":"1009033083","pt":1580663138141,"mc":[{"id":"1.168236370","rc":[{"batb":[[0,1.34,623.44]],"ltp":1.65,"tv":493.55,"id":8284479}]}]}
{"op":"mcm","clk":"1009033229","pt":1580663138937,"mc":[{"id":"1.168236370","rc":[{"trd":[[2.52,8.44]],"batb":[[0,2.52,10.33]],"ltp":2.52,"tv":186.21,"id":4520808}],"tv":679.77}]}
{"op":"mcm","clk":"1009034109","pt":1580663143950,"mc":[{"id":"1.168236370","rc":[{"batb":[[0,1.34,465.43],[1,1.32,70.34],[2,1.01,10.51]],"ltp":1.65,"tv":493.55,"id":8284479}]}]}
{"op":"mcm","clk":"1009034710","pt":1580663147232,"mc":[{"id":"1.168236370","rc":[{"batb":[[0,1.46,283.68],[1,1.45,199.67],[2,1.34,465.43]],"batl":[[0,1.51,181.31],[1,1.52,161.17]],"ltp":1.65,"tv":493.55,"id":8284479}]}]}
{"op":"mcm","clk":"1009035153","pt":1580663149559,"mc":[{"id":"1.168236370","rc":[{"batb":[[0,1.34,465.43],[1,1.32,70.34],[2,1.01,10.51]],"ltp":1.65,"tv":493.55,"id":8284479}]}]}
{"op":"mcm","clk":"1009035651","pt":1580663152352,"mc":[{"id":"1.168236370","rc":[{"batb":[[0,1.34,623.44],[1,1.33,296.49],[2,1.32,70.34]],"batl":[[0,1.68,218.77],[1,1.7,216.27]],"ltp":1.65,"tv":493.55,"id":8284479}]}]}
{"op":"mcm","clk":"1009037329","pt":1580663161874,"mc":[{"id":"1.168236370","rc":[{"batb":[[0,1.34,465.43],[1,1.32,70.34],[2,1.01,10.51]],"ltp":1.65,"tv":493.55,"id":8284479}]}]}
{"op":"mcm","clk":"1009037481","pt":1580663162700,"mc":[{"id":"1.168236370","rc":[{"batb":[[1,1.01,10.51],[2,1.01,0]],"ltp":2.52,"tv":186.21,"id":4520808},{"batb":[[0,1.32,70.34],[1,1.01,10.51],[2,1.01,0]],"ltp":1.65,"tv":493.55,"id":8284479}]}]}
{"op":"mcm","clk":"1009037835","pt":1580663164578,"mc":[{"id":"1.168236370","rc":[{"batb":[[0,1.61,241.32],[1,1.6,134.77],[2,1.32,70.34]],"ltp":1.65,"tv":493.55,"id":8284479}]}]}
{"op":"mcm","clk":"1009038050","pt":1580663165768,"mc":[{"id":"1.168236370","rc":[{"batb":[[1,2.38,30.25],[2,2.24,20.14]],"batl":[[0,2.64,25.21]],"ltp":2.52,"tv":186.21,"id":4520808},{"batb":[[0,1.61,309.38],[1,1.6,165.93],[2,1.42,49.25]],"batl":[[2,1.72,42.01]],"ltp":1.65,"tv":493.55,"id":8284479}]}]}
{"op":"mcm","clk":"1009038251","pt":1580663166998,"mc":[{"id":"1.168236370","rc":[{"batb":[[2,1.44,436.18]],"ltp":1.65,"tv":493.55,"id":8284479}]}]}
{"op":"mcm","clk":"1009041080","pt":1580663181998,"mc":[{"id":"1.168236370","rc":[{"trd":[[2.52,28.96]],"batb":[[0,2.38,30.32],[1,2.24,20.14],[2,1.86,398.62]],"ltp":2.52,"tv":206.73,"id":4520808}],"tv":700.29}]}
{"op":"mcm","clk":"1009042335","pt":1580663189215,"mc":[{"id":"1.168236370","rc":[{"batb":[[0,1.61,68.06],[1,1.6,31.16]],"batl":[[0,1.72,42.01],[1,1.7,0],[2,1.72,0]],"ltp":1.65,"tv":493.55,"id":8284479}]}]}
{"op":"mcm","clk":"1009042401","pt":1580663189500,"mc":[{"id":"1.168236370","rc":[{"batb":[[0,2.38,30.25]],"ltp":2.52,"tv":206.73,"id":4520808},{"batb":[[1,1.44,436.18],[2,1.42,49.25]],"ltp":1.65,"tv":493.55,"id":8284479}]}]}
{"op":"mcm","clk":"1009042615","pt":1580663190908,"mc":[{"id":"1.168236370","rc":[{"batb":[[0,2.24,20.14],[1,1.86,398.62],[2,1.01,10.51]],"ltp":2.52,"tv":206.73,"id":4520808},{"batb":[[0,1.44,436.18],[1,1.42,49.25],[2,1.01,10.51]],"ltp":1.65,"tv":493.55,"id":8284479}]}]}
{"op":"mcm","clk":"1009043065","pt":1580663193200,"mc":[{"id":"1.168236370","rc":[{"batb":[[0,1.44,615.54],[1,1.43,211.51],[2,1.42,49.25]],"batl":[[0,1.8,128.1],[1,1.82,173.49]],"ltp":1.65,"tv":493.55,"id":8284479}]}]}
{"op":"mcm","clk":"1009043175","pt":1580663193853,"mc":[{"id":"1.168236370","rc":[{"batb":[[0,1.42,49.25],[1,1.01,10.51],[2,1.42,0]],"ltp":1.65,"tv":493.55,"id":8284479}]}]}
{"op":"mcm","clk":"1009043576","pt":1580663196187,"mc":[{"id":"1.168236370","rc":[{"batb":[[1,2.18,35.29],[2,2.06,25.41]],"batl":[[0,2.4,29.41]],"ltp":2.52,"tv":206.73,"id":4520808},{"batb":[[0,1.73,201.26],[1,1.71,269.86],[2,1.56,33.91]],"batl":[[2,1.86,42.01]],"ltp":1.65,"tv":493.55,"id":8284479}]}]}
{"op":"mcm","clk":"1009046268","pt":1580663211218,"mc":[{"id":"1.168236370","rc":[{"batb":[[0,2.06,25.41],[1,1.86,398.62],[2,1.01,10.51]],"ltp":2.52,"tv":206.73,"id":4520808},{"batb":[[0,1.56,33.91],[1,1.52,425.49],[2,1.01,10.51]],"ltp":1.65,"tv":493.55,"id":8284479}]}]}
{"op":"mcm","clk":"1009046666","pt":1580663213315,"mc":[{"id":"1.168236370","rc":[{"batb":[[0,1.58,133.1],[1,1.57,144.49],[2,1.56,33.91]],"batl":[[0,1.91,122.23],[1,1.93,144.55]],"ltp":1.65,"tv":493.55,"id":8284479}]}]}
{"op":"mcm","clk":"1009048632","pt":1580663223750,"mc":[{"id":"1.168236370","rc":[{"batb":[[0,1.56,33.91],[1,1.52,425.49],[2,1.01,10.51]],"ltp":1.65,"tv":493.55,"id":8284479}]}]}
{"op":"mcm","clk":"1009048854","pt":1580663224939,"mc":[{"id":"1.168236370","rc":[{"batb":[[1,1.01,10.51],[2,1.01,0]],"ltp":2.52,"tv":206.73,"id":4520808},{"batb":[[1,1.01,10.51],[2,1.01,0]],"ltp":1.65,"tv":493.55,"id":8284479}]}]}
{"op":"mcm","clk":"1009056335","pt":1580663266521,"mc":[{"id":"1.168236370","rc":[{"batb":[[0,1.7,136.76],[1,1.68,224.33],[2,1.56,33.91]],"batl":[[0,1.77,199.3],[1,1.79,182.78]],"ltp":1.65,"tv":493.55,"id":8284479}]}]}
{"op":"mcm","clk":"1009056891","pt":1580663269412,"mc":[{"id":"1.168236370","rc":[{"batb":[[1,1.77,402.27],[2,1.01,10.51]],"ltp":2.52,"tv":206.73,"id":4520808}]}]}
{"op":"mcm","clk":"1009057692","pt":1580663273733,"mc":[{"id":"1.168236370","rc":[{"batb":[[0,1.56,33.91],[1,1.5,426.9],[2,1.01,10.51]],"ltp":1.65,"tv":493.55,"id":8284479}]}]}
{"op":"mcm","clk":"1009058219","pt":1580663276635,"mc":[{"id":"1.168236370","rc":[{"batb":[[0,1.58,133.1],[1,1.57,144.49],[2,1.56,33.91]],"batl":[[0,1.91,122.23],[1,1.93,144.55]],"ltp":1.65,"tv":493.55,"id":8284479}]}]}
{"op":"mcm","clk":"1009059776","pt":1580663284843,"mc":[{"id":"1.168236370","rc":[{"batb":[[0,1.56,33.91],[1,1.5,426.9],[2,1.01,10.51]],"ltp":1.65,"tv":493.55,"id":8284479}]}]}
{"op":"mcm","clk":"1009060010","pt":1580663286142,"mc":[{"id":"1.168236370","rc":[{"batb":[[1,1.01,10.51],[2,1.01,0]],"ltp":1.65,"tv":493.55,"id":8284479}]}]}
{"op":"mcm","clk":"1009060366","pt":1580663288161,"mc":[{"id":"1.168236370","rc":[{"batb":[[0,2.06,64.9],[1,1.99,28.72],[2,1.77,402.27]],"batl":[[0,2.26,32.77]],"ltp":2.52,"tv":206.73,"id":4520808},{"batb":[[0,1.85,19.04],[1,1.83,169.51],[2,1.81,174.34]],"batl":[[2,1.94,42.01]],"ltp":1.65,"tv":493.55,"id":8284479}]}]}
{"op":"mcm","clk":"1009063063","pt":1580663303056,"mc":[{"id":"1.168236370","rc":[{"trd":[[1.85,38.07]],"batb":[[0,1.83,169.51],[1,1.81,174.34],[2,1.8,52.09]],"batl":[[0,1.85,16.12],[1,1.91,122.23],[2,1.93,144.55]],"ltp":1.85,"tv":531.63,"id":8284479}],"tv":738.36}]}
{"op":"mcm","clk":"1009063226","pt":1580663304084,"mc":[{"id":"1.168236370","rc":[{"batb":[[0,2.06,39.49]],"ltp":2.52,"tv":206.73,"id":4520808},{"batb":[[0,1.8,52.09],[1,1.73,23.68],[2,1.58,416.47]],"batl":[[1,1.94,42.01],[2,1.93,0]],"ltp":1.85,"tv":531.63,"id":8284479}]}]}
{"op":"mcm","clk":"1009063355","pt":1580663304887,"mc":[{"id":"1.168236370","rc":[{"batb":[[0,1.99,28.72],[1,1.77,402.27],[2,1.01,10.51]],"ltp":2.52,"tv":206.73,"id":4520808},{"batb":[[0,1.73,23.68],[1,1.58,416.47],[2,1.01,10.51]],"batl":[[1,1.94,0]],"ltp":1.85,"tv":531.63,"id":8284479}]}]}
{"op":"mcm","clk":"1009063703","pt":1580663306984,"mc":[{"id":"1.168236370","rc":[{"batb":[[0,2,28.25]],"ltp":2.52,"tv":206.73,"id":4520808},{"batb":[[0,1.72,24.08]],"ltp":1.85,"tv":531.63,"id":8284479}]}]}
{"op":"mcm","clk":"1009064142","pt":1580663309672,"mc":[{"id":"1.168236370","rc":[{"batb":[[0,1.81,178.48],[1,1.79,180.86],[2,1.72,24.08]],"batl":[[1,1.89,131.53],[2,1.91,149.21]],"ltp":1.85,"tv":531.63,"id":8284479}]}]}
{"op":"mcm","clk":"1009064544","pt":1580663312089,"mc":[{"id":"1.168236370","rc":[{"batb":[[0,1.72,24.08],[1,1.58,416.47],[2,1.01,10.51]],"batl":[[1,1.89,0],[2,1.91,0]],"ltp":1.85,"tv":531.63,"id":8284479}]}]}
{"op":"mcm","clk":"1009064944","pt":1580663314508,"mc":[{"id":"1.168236370","rc":[{"batb":[[0,1.74,157.82],[1,1.72,230.89],[2,1.58,416.47]],"batl":[[1,1.97,127.06],[2,1.99,131.88]],"ltp":1.85,"tv":531.63,"id":8284479}]}]}
{"op":"mcm","clk":"1009067503","pt":1580663330229,"mc":[{"id":"1.168236370","rc":[{"batb":[[0,1.72,24.08],[1,1.58,416.47],[2,1.01,10.51]],"ltp":1.85,"tv":531.63,"id":8284479}]}]}
{"op":"mcm","clk":"1009067673","pt":1580663331099,"mc":[{"id":"1.168236370","rc":[{"batb":[[1,1.01,10.51],[2,1.01,0]],"ltp":2.52,"tv":206.73,"id":4520808},{"batb":[[1,1.01,10.51],[2,1.01,0]],"ltp":1.85,"tv":531.63,"id":8284479}]}]}
{"op":"mcm","clk":"1009067937","pt":1580663332713,"mc":[{"id":"1.168236370","rc":[{"trd":[[1.85,70.31]],"batb":[[0,1.89,98.61],[1,1.87,156.84],[2,1.72,24.08]],"batl":[[0,1.97,127.06],[1,1.99,131.88],[2,1.99,0]],"ltp":1.85,"tv":563.87,"id":8284479}],"tv":770.6}]}
{"op":"mcm","clk":"1009068174","pt":1580663334136,"mc":[{"id":"1.168236370","rc":[{"batb":[[1,1.98,42.85],[2,1.74,21.79]],"ltp":2.52,"tv":206.73,"id":4520808},{"batb":[[0,1.91,17.15],[1,1.89,98.61],[2,1.87,156.84]],"ltp":1.85,"tv":563.87,"id":8284479}]}]}
{"op":"mcm","clk":"1009068531","pt":1580663336228,"mc":[{"id":"1.168236370","rc":[{"batl":[[0,2.16,36.13]],"ltp":2.52,"tv":206.73,"id":4520808},{"batl":[[2,2.02,41.17]],"ltp":1.85,"tv":563.87,"id":8284479}]}]}
{"op":"mcm","clk":"1009072789","pt":1580663362140,"mc":[{"id":"1.168236370","rc":[{"batb":[[0,1.98,42.85],[1,1.74,21.79],[2,1.62,415.43]],"ltp":2.52,"tv":206.73,"id":4520808},{"batb":[[0,1.85,48.73],[1,1.78,21.48],[2,1.62,415.43]],"batl":[[0,2.02,41.17],[1,1.99,0],[2,2.02,0]],"ltp":1.85,"tv":563.87,"id":8284479}]}]}
{"op":"mcm","clk":"1009072965","pt":1580663363241,"mc":[{"id":"1.168236370","rc":[{"batb":[[0,1.74,21.79],[1,1.62,415.43],[2,1.01,10.51]],"ltp":2.52,"tv":206.73,"id":4520808},{"batb":[[0,1.78,21.48],[1,1.62,415.43],[2,1.01,10.51]],"ltp":1.85,"tv":563.87,"id":8284479}]}]}
{"op":"mcm","clk":"1009073266","pt":1580663365159,"mc":[{"id":"1.168236370","rc":[{"batb":[[0,1.75,21.56],[1,1.74,21.79],[2,1.62,415.43]],"ltp":2.52,"tv":206.73,"id":4520808}]}]}
{"op":"mcm","clk":"1009073437","pt":1580663366052,"mc":[{"id":"1.168236370","rc":[{"batb":[[1,1.62,415.43],[2,1.01,10.51]],"ltp":2.52,"tv":206.73,"id":4520808}]}]}
{"op":"mcm","clk":"1009073767","pt":1580663367950,"mc":[{"id":"1.168236370","rc":[{"batl":[[0,2.02,101.1],[1,2.04,122.51]],"ltp":1.85,"tv":563.87,"id":8284479}]}]}
{"op":"mcm","clk":"1009074757","pt":1580663374173,"mc":[{"id":"1.168236370","rc":[{"batb":[[1,1.76,164.72],[2,1.74,198.9]],"batl":[[0,2.28,167.62],[1,2.3,87.34]],"ltp":1.85,"tv":563.87,"id":8284479}]}]}
{"op":"mcm","clk":"1009075908","pt":1580663381182,"mc":[{"id":"1.168236370","rc":[{"batb":[[1,1.62,415.43],[2,1.01,10.51]],"ltp":1.85,"tv":563.87,"id":8284479}]}]}
{"op":"mcm","clk":"1009076165","pt":1580663384192,"mc":[{"id":"1.168236370","rc":[{"batb":[[1,1.01,10.51],[2,1.01,0]],"ltp":2.52,"tv":206.73,"id":4520808},{"batb":[[1,1.01,10.51],[2,1.01,0]],"ltp":1.85,"tv":563.87,"id":8284479}]}]}
{"op":"mcm","clk":"1009076542","pt":1580663385199,"mc":[{"id":"1.168236370","rc":[{"batb":[[0,1.79,133.02],[1,1.77,187.55],[2,1.75,21.56]],"batl":[[0,1.86,114.85],[1,1.88,156.63]],"ltp":2.52,"tv":206.73,"id":4520808},{"batb":[[0,2.22,22.19],[1,1.98,15.42],[2,1.01,10.51]],"ltp":1.85,"tv":563.87,"id":8284479}]}]}
{"op":"mcm","clk":"1009076730","pt":1580663386210,"mc":[{"id":"1.168236370","rc":[{"batb":[[2,1.76,54.61]],"batl":[[2,1.92,42.01]],"ltp":2.52,"tv":206.73,"id":4520808},{"batb":[[1,2.1,37.81],[2,1.98,15.42]],"batl":[[0,2.3,31.93]],"ltp":1.85,"tv":563.87,"id":8284479}]}]}
{"op":"mcm","clk":"1009078772","pt":1580663399222,"mc":[{"id":"1.168236370","rc":[{"batb":[[0,1.76,54.61],[1,1.75,21.56],[2,1.5,464.75]],"ltp":2.52,"tv":206.73,"id":4520808}]}]}
{"op":"mcm","clk":"1009079228","pt":1580663402021,"mc":[{"id":"1.168236370","rc":[{"batb":[[0,1.78,160.23],[1,1.76,246.02],[2,1.75,21.56]],"batl":[[0,1.86,153.87]],"ltp":2.52,"tv":206.73,"id":4520808}]}]}
{"op":"mcm","clk":"1009079403","pt":1580663403133,"mc":[{"id":"1.168236370","rc":[{"batb":[[0,1.5,464.2],[1,1.01,10.51],[2,1.75,0]],"ltp":2.52,"tv":206.73,"id":4520808},{"batb":[[0,1.98,15.42],[1,1.77,402.27],[2,1.01,10.51]],"ltp":1.85,"tv":563.87,"id":8284479}]}]}
{"op":"mcm","clk":"1009080413","pt":1580663409014,"mc":[{"id":"1.168236370","rc":[{"batb":[[0,1.72,201.6],[1,1.7,215.54],[2,1.5,464.2]],"batl":[[0,1.79,116.22],[1,1.81,176.65]],"ltp":2.52,"tv":206.73,"id":4520808}]}]}
{"op":"mcm","clk":"1009081216","pt":1580663414051,"mc":[{"id":"1.168236370","rc":[{"batb":[[0,1.5,464.2],[1,1.01,10.51],[2,1.5,0]],"ltp":2.52,"tv":206.73,"id":4520808}]}]}
{"op":"mcm","clk":"1009081624","pt":1580663416738,"mc":[{"id":"1.168236370","rc":[{"batb":[[0,1.52,212.79],[1,1.51,168.56],[2,1.5,464.2]],"batl":[[0,2.06,119.6],[1,2.08,115.84]],"ltp":2.52,"tv":206.73,"id":4520808}]}]}
{"op":"mcm","clk":"1009083673","pt":1580663429245,"mc":[{"id":"1.168236370","rc":[{"batb":[[2,1.5,37.3]],"ltp":2.52,"tv":206.73,"id":4520808},{"batb":[[1,1.01,10.51],[2,1.01,0]],"ltp":1.85,"tv":563.87,"id":8284479}]}]}
{"op":"mcm","clk":"1009083844","pt":1580663430245,"mc":[{"id":"1.168236370","rc":[{"batb":[[0,1.52,293.45]],"batl":[[0,1.57,139.44],[1,1.58,139.65]],"ltp":2.52,"tv":206.73,"id":4520808},{"batb":[[0,2.8,11.88],[1,2.38,18.18],[2,1.98,15.42]],"batl":[[0,2.92,21.85]],"ltp":1.85,"tv":563.87,"id":8284479}]}]}
{"op":"mcm","clk":"1009083888","pt":1580663430462,"mc":[{"id":"1.168236370","rc":[{"batl":[[2,1.63,42.01]],"ltp":2.52,"tv":206.73,"id":4520808},{"batb":[[1,2.6,26.05],[2,2.38,18.18]],"ltp":1.85,"tv":563.87,"id":8284479}]}]}
{"op":"mcm","clk":"1009087393","pt":1580663452171,"mc":[{"id":"1.168236370","rc":[{"batb":[[0,1.52,80.66],[1,1.34,465.43],[2,1.3,71.6]],"batl":[[0,1.63,42.01],[1,1.58,0],[2,1.63,0]],"ltp":2.52,"tv":206.73,"id":4520808},{"batb":[[0,2.6,26.05],[1,2.38,18.18],[2,2.04,394.09]],"ltp":1.85,"tv":563.87,"id":8284479}]}]}
{"op":"mcm","clk":"1009087520","pt":1580663452983,"mc":[{"id":"1.168236370","rc":[{"batb":[[0,1.34,465.43],[1,1.3,71.6],[2,1.01,10.51]],"ltp":2.52,"tv":206.73,"id":4520808},{"batb":[[0,2.38,18.18],[1,2.04,394.09],[2,1.01,10.51]],"ltp":1.85,"tv":563.87,"id":8284479}]}]}
{"op":"mcm","clk":"1009087846","pt":1580663455127,"mc":[{"id":"1.168236370","rc":[{"batb":[[1,1.3,334.02],[2,1.29,350.53]],"batl":[[0,1.75,161.39],[1,1.77,189.69]],"ltp":2.52,"tv":206.73,"id":4520808}]}]}
{"op":"mcm","clk":"1009087955","pt":1580663455864,"mc":[{"id":"1.168236370","rc":[{"batb":[[1,1.3,71.6],[2,1.01,10.51]],"ltp":2.52,"tv":206.73,"id":4520808}]}]}
{"op":"mcm","clk":"1009088639","pt":1580663460226,"mc":[{"id":"1.168236370","rc":[{"batb":[[0,1.47,223.15],[1,1.46,193.67],[2,1.34,465.43]],"batl":[[0,1.52,218.59],[1,1.53,157.09]],"ltp":2.52,"tv":206.73,"id":4520808}]}]}
{"op":"mcm","clk":"1009088958","pt":1580663462176,"mc":[{"id":"1.168236370","rc":[{"batb":[[0,1.34,465.43],[1,1.3,71.6],[2,1.01,10.51]],"ltp":2.52,"tv":206.73,"id":4520808}]}]}
{"op":"mcm","clk":"1009089304","pt":1580663464788,"mc":[{"id":"1.168236370","rc":[{"batb":[[1,1.3,334.02],[2,1.29,350.53]],"ltp":2.52,"tv":206.73,"id":4520808}]}]}
{"op":"mcm","clk":"1009089669","pt":1580663467228,"mc":[{"id":"1.168236370","rc":[{"batb":[[0,1.3,334.02],[1,1.29,350.53],[2,1.01,10.51]],"batl":[[0,1.33,185.32],[1,1.34,278.06]],"ltp":2.52,"tv":206.73,"id":4520808},{"batb":[[1,1.01,10.51],[2,1.01,0]],"ltp":1.85,"tv":563.87,"id":8284479}]}]}
{"op":"mcm","clk":"1009089812","pt":1580663468179,"mc":[{"id":"1.168236370","rc":[{"batb":[[0,1.3,473.49],[2,1.18,129.98]],"batl":[[2,1.36,42.01]],"ltp":2.52,"tv":206.73,"id":4520808},{"batb":[[0,3.9,12.98],[1,3.75,15.12],[2,3.3,19.12]],"batl":[[0,4.3,12.6]],"ltp":1.85,"tv":563.87,"id":8284479}]}]}
{"op":"mcm","clk":"1009090092","pt":1580663470291,"mc":[{"id":"1.168236370","rc":[{"batb":[[2,1.2,530.86]],"ltp":2.52,"tv":206.73,"id":4520808}]}]}
{"op":"mcm","clk":"1009091068","pt":1580663477199,"mc":[{"id":"1.168236370","rc":[{"trd":[[1.3,3.36]],"batb":[[0,1.3,471.81]],"ltp":1.3,"tv":210.09,"id":4520808}],"tv":773.96}]}
{"op":"mcm","clk":"1009091887","pt":1580663482699,"mc":[{"id":"1.168236370","rc":[{"batb":[[0,1.3,332.34]],"ltp":1.3,"tv":210.09,"id":4520808}]}]}
{"op":"mcm","clk":"1009092375","pt":1580663486146,"mc":[{"id":"1.168236370","rc":[{"batb":[[1,1.29,495.04]],"ltp":1.3,"tv":210.09,"id":4520808}]}]}
{"op":"mcm","clk":"1009092655","pt":1580663488041,"mc":[{"id":"1.168236370","rc":[{"trd":[[1.3,6.72]],"batb":[[0,1.33,7.57],[1,1.3,68.24],[2,1.29,144.51]],"batl":[[0,1.36,42.01],[1,1.34,0],[2,1.36,0]],"ltp":1.3,"tv":213.45,"id":4520808}],"tv":777.32}]}
{"op":"mcm","clk":"1009092809","pt":1580663489055,"mc":[{"id":"1.168236370","rc":[{"batb":[[1,1.2,530.86],[2,1.18,129.98]],"ltp":1.3,"tv":213.45,"id":4520808},{"batb":[[0,3.3,19.12],[1,2.52,381.46],[2,1.01,10.51]],"ltp":1.85,"tv":563.87,"id":8284479}]}]}
{"op":"mcm","clk":"1009093130","pt":1580663491038,"mc":[{"id":"1.168236370","rc":[{"batl":[[0,1.43,242.81],[1,1.44,200.15]],"ltp":1.3,"tv":213.45,"id":4520808},{"batb":[[0,3.35,18.8],[1,3.3,19.12],[2,2.52,381.46]],"ltp":1.85,"tv":563.87,"id":8284479}]}]}
{"op":"mcm","clk":"1009093277","pt":1580663491456,"mc":[{"id":"1.168236370","rc":[{"batb":[[1,2.52,381.46],[2,1.01,10.51]],"ltp":1.85,"tv":563.87,"id":8284479}]}]}
{"op":"mcm","clk":"1009093634","pt":1580663493728,"mc":[{"id":"1.168236370","rc":[{"batb":[[0,1.2,530.86],[1,1.18,129.98],[2,1.01,10.51]],"ltp":1.3,"tv":213.45,"id":4520808}]}]}
{"op":"mcm","clk":"1009093883","pt":1580663495149,"mc":[{"id":"1.168236370","rc":[{"batb":[[0,1.39,191.87],[1,1.38,248.37],[2,1.18,129.98]],"ltp":1.3,"tv":213.45,"id":4520808}]}]}
{"op":"mcm","clk":"1009094033","pt":1580663496159,"mc":[{"id":"1.168236370","rc":[{"batb":[[1,1.38,358.44]],"batl":[[2,1.46,42.01]],"ltp":1.3,"tv":213.45,"id":4520808},{"batb":[[1,3.2,18.48],[2,2.52,381.46]],"batl":[[0,3.6,15.96]],"ltp":1.85,"tv":563.87,"id":8284479}]}]}
{"op":"mcm","clk":"1009094126","pt":1580663496740,"mc":[{"id":"1.168236370","rc":[{"batb":[[1,1.38,412.33],[2,1.18,127.86]],"ltp":1.3,"tv":213.45,"id":4520808},{"batb":[[2,2.7,12.9]],"ltp":1.85,"tv":563.87,"id":8284479}]}]}
{"op":"mcm","clk":"1009094416","pt":1580663498436,"mc":[{"id":"1.168236370","rc":[{"batb":[[2,1.23,516.48]],"ltp":1.3,"tv":213.45,"id":4520808}]}]}
{"op":"mcm","clk":"1009094723","pt":1580663500566,"mc":[{"id":"1.168236370","rc":[{"batb":[[0,1.38,412.33],[1,1.23,516.48],[2,1.18,127.86]],"batl":[[0,1.43,208.25],[1,1.46,42.01],[2,1.46,0]],"ltp":1.3,"tv":213.45,"id":4520808}]}]}
{"op":"mcm","clk":"1009095219","pt":1580663503231,"mc":[{"id":"1.168236370","rc":[{"batb":[[0,1.38,467.88],[1,1.37,259.95],[2,1.23,516.48]],"batl":[[0,1.42,168.85],[1,1.43,208.25],[2,1.46,42.01]],"ltp":1.3,"tv":213.45,"id":4520808}]}]}
{"op":"mcm","clk":"1009096146","pt":1580663508754,"mc":[{"id":"1.168236370","rc":[{"batb":[[0,1.38,357.82]],"batl":[[2,1.46,0]],"ltp":1.3,"tv":213.45,"id":4520808}]}]}
{"op":"mcm","clk":"1009096509","pt":1580663511071,"mc":[{"id":"1.168236370","rc":[{"batb":[[0,1.23,516.48],[1,1.18,127.86],[2,1.01,10.51]],"ltp":1.3,"tv":213.45,"id":4520808},{"batb":[[0,2.7,12.9],[1,2.52,381.46],[2,1.01,10.51]],"ltp":1.85,"tv":563.87,"id":8284479}]}]}
{"op":"mcm","clk":"1009096666","pt":1580663512075,"mc":[{"id":"1.168236370","rc":[{"batb":[[0,1.18,127.86],[1,1.01,10.51],[2,1.01,0]],"ltp":1.3,"tv":213.45,"id":4520808},{"batb":[[1,1.01,10.51],[2,1.01,0]],"ltp":1.85,"tv":563.87,"id":8284479}]}]}
{"op":"mcm","clk":"1009097032","pt":1580663514157,"mc":[{"id":"1.168236370","rc":[{"batb":[[1,1.17,413.72],[2,1.16,687.01]],"batl":[[0,1.6,218.63],[1,1.61,130.76]],"ltp":1.3,"tv":213.45,"id":4520808},{"batb":[[0,2.72,12.67]],"ltp":1.85,"tv":563.87,"id":8284479}]}]}
{"op":"mcm","clk":"1009098211","pt":1580663521197,"mc":[{"id":"1.168236370","rc":[{"batb":[[1,1.01,10.51],[2,1.16,0]],"ltp":1.3,"tv":213.45,"id":4520808}]}]}
{"op":"mcm","clk":"1009098707","pt":1580663524184,"mc":[{"id":"1.168236370","rc":[{"batb":[[0,1.54,242.25],[1,1.53,160.93],[2,1.18,127.86]],"ltp":1.3,"tv":213.45,"id":4520808}]}]}
{"op":"mcm","clk":"1009098884","pt":1580663525156,"mc":[{"id":"1.168236370","rc":[{"batb":[[2,1.52,35.33]],"ltp":1.3,"tv":213.45,"id":4520808},{"batb":[[1,2.08,26.36],[2,1.01,10.51]],"ltp":1.85,"tv":563.87,"id":8284479}]}]}
{"op":"mcm","clk":"1009099033","pt":1580663526182,"mc":[{"id":"1.168236370","rc":[{"batl":[[2,1.62,42.01]],"ltp":1.3,"tv":213.45,"id":4520808},{"batb":[[1,2.6,26.05],[2,2.08,26.36]],"ltp":1.85,"tv":563.87,"id":8284479}]}]}
{"op":"mcm","clk":"1009099206","pt":1580663527216,"mc":[{"id":"1.168236370","rc":[{"batl":[[2,1.63,42.01]],"ltp":1.3,"tv":213.45,"id":4520808}]}]}
{"op":"mcm","clk":"1009101309","pt":1580663540010,"mc":[{"id":"1.168236370","rc":[{"batb":[[1,1.53,239.91]],"ltp":1.3,"tv":213.45,"id":4520808},{"batl":[[0,2.88,21.85]],"ltp":1.85,"tv":563.87,"id":8284479}]}]}
{"op":"mcm","clk":"1009101844","pt":1580663543207,"mc":[{"id":"1.168236370","rc":[{"batb":[[0,1.53,78.98],[1,1.52,35.33],[2,1.34,465.43]],"batl":[[0,1.63,42.01],[1,1.61,0],[2,1.63,0]],"ltp":1.3,"tv":213.45,"id":4520808}]}]}
{"op":"mcm","clk":"1009101962","pt":1580663543890,"mc":[{"id":"1.168236370","rc":[{"batb":[[1,1.34,465.43],[2,1.18,125.89]],"ltp":1.3,"tv":213.45,"id":4520808},{"batb":[[0,2.6,26.05],[1,2.08,26.36],[2,2.04,394.09]],"ltp":1.85,"tv":563.87,"id":8284479}]}]}
{"op":"mcm","clk":"1009102128","pt":1580663545017,"mc":[{"id":"1.168236370","rc":[{"batb":[[0,1.18,125.89],[1,1.01,10.51],[2,1.18,0]],"ltp":1.3,"tv":213.45,"id":4520808},{"batb":[[0,2.08,26.36],[1,1.01,10.51],[2,2.04,0]],"ltp":1.85,"tv":563.87,"id":8284479}]}]}
{"op":"mcm","clk":"1009102434","pt":1580663547002,"mc":[{"id":"1.168236370","rc":[{"batb":[[1,1.17,552.22],[2,1.16,547.32]],"batl":[[0,1.96,121.56],[1,1.98,134.39]],"ltp":1.3,"tv":213.45,"id":4520808}]}]}
{"op":"mcm","clk":"1009102941","pt":1580663550210,"mc":[{"id":"1.168236370","rc":[{"batb":[[1,1.01,10.51],[2,1.16,0]],"ltp":1.3,"tv":213.45,"id":4520808}]}]}
{"op":"mcm","clk":"1009103358","pt":1580663552610,"mc":[{"id":"1.168236370","rc":[{"batb":[[0,1.88,130.65],[1,1.86,160.22],[2,1.18,125.89]],"ltp":1.3,"tv":213.45,"id":4520808}]}]}
{"op":"mcm","clk":"1009103651","pt":1580663554014,"mc":[{"id":"1.168236370","rc":[{"batb":[[2,1.84,67.9]],"batl":[[2,1.99,42.01]],"ltp":1.3,"tv":213.45,"id":4520808},{"batb":[[1,2,42.01],[2,1.83,19.75]],"batl":[[0,2.18,35.29]],"ltp":1.85,"tv":563.87,"id":8284479}]}]}
{"op":"mcm","clk":"1009105124","pt":1580663561538,"mc":[{"id":"1.168236370","rc":[{"trd":[[2.08,52.72]],"batb":[[0,2,42.01],[1,1.83,19.75],[2,1.7,409.32]],"batl":[[0,2.08,8.09],[1,2.18,35.29]],"ltp":2.08,"tv":616.58,"id":8284479}],"tv":830.04}]}
{"op":"mcm","clk":"1009106408","pt":1580663569139,"mc":[{"id":"1.168236370","rc":[{"batl":[[0,2.18,35.29],[1,2.18,0]],"ltp":2.08,"tv":616.58,"id":8284479}]}]}
{"op":"mcm","clk":"1009106443","pt":1580663569357,"mc":[{"id":"1.168236370","rc":[{"batb":[[0,1.84,49.57],[1,1.55,420.5],[2,1.5,37.22]],"batl":[[0,1.99,42.01],[1,1.98,0],[2,1.99,0]],"ltp":1.3,"tv":213.45,"id":4520808}]}]}
{"op":"mcm","clk":"1009106736","pt":1580663571020,"mc":[{"id":"1.168236370","rc":[{"batb":[[0,1.55,420.5],[1,1.5,37.22],[2,1.01,10.51]],"ltp":1.3,"tv":213.45,"id":4520808},{"batb":[[0,1.83,19.75],[1,1.7,409.32],[2,1.01,10.51]],"ltp":2.08,"tv":616.58,"id":8284479}]}]}
{"op":"mcm","clk":"1009106968","pt":1580663572219,"mc":[{"id":"1.168236370","rc":[{"batb":[[1,1.53,219.05],[2,1.52,165.12]],"batl":[[0,2.26,127.54],[1,2.28,89.7]],"ltp":1.3,"tv":213.45,"id":4520808},{"batb":[[1,1.81,20.3],[2,1.7,409.32]],"batl":[[0,1.99,8.09]],"ltp":2.08,"tv":616.58,"id":8284479}]}]}
{"op":"mcm","clk":"1009107071","pt":1580663572843,"mc":[{"id":"1.168236370","rc":[{"batb":[[0,1.81,20.3],[1,1.7,409.32],[2,1.01,10.51]],"ltp":2.08,"tv":616.58,"id":8284479}]}]}
{"op":"mcm","clk":"1009108492","pt":1580663580936,"mc":[{"id":"1.168236370","rc":[{"batb":[[1,1.51,36.27],[2,1.01,10.51]],"ltp":1.3,"tv":213.45,"id":4520808}]}]}
{"op":"mcm","clk":"1009108787","pt":1580663582964,"mc":[{"id":"1.168236370","rc":[{"batb":[[0,1.51,36.27],[1,1.01,10.51],[2,1.01,0]],"ltp":1.3,"tv":213.45,"id":4520808},{"batb":[[1,1.01,10.51],[2,1.01,0]],"ltp":2.08,"tv":616.58,"id":8284479}]}]}
{"op":"mcm","clk":"1009109012","pt":1580663584239,"mc":[{"id":"1.168236370","rc":[{"batb":[[0,2.12,23.68],[1,1.82,18.96],[2,1.51,36.27]],"batl":[[0,2.28,32.77]],"ltp":1.3,"tv":213.45,"id":4520808},{"batb":[[1,1.79,247.4],[2,1.77,188.4]],"batl":[[0,1.87,137.57],[1,1.89,154.59]],"ltp":2.08,"tv":616.58,"id":8284479}]}]}
{"op":"mcm","clk":"1009109131","pt":1580663585043,"mc":[{"id":"1.168236370","rc":[{"batb":[[1,2.08,38.65],[2,1.82,18.96]],"ltp":1.3,"tv":213.45,"id":4520808},{"batl":[[2,1.94,42.01]],"ltp":2.08,"tv":616.58,"id":8284479}]}]}
{"op":"mcm","clk":"1009110781","pt":1580663594747,"mc":[{"id":"1.168236370","rc":[{"trd":[[1.81,16.18]],"batb":[[0,1.81,12.21]],"ltp":1.81,"tv":632.76,"id":8284479}],"tv":846.22}]}
{"op":"mcm","clk":"1009111886","pt":1580663600987,"mc":[{"id":"1.168236370","rc":[{"batb":[[0,1.82,18.96],[1,1.7,409.32],[2,1.01,10.51]],"ltp":1.3,"tv":213.45,"id":4520808},{"batb":[[0,1.68,26.36],[1,1.55,420.5],[2,1.01,10.51]],"ltp":1.81,"tv":632.76,"id":8284479}]}]}
{"op":"mcm","clk":"1009112293","pt":1580663603171,"mc":[{"id":"1.168236370","rc":[{"batb":[[0,1.68,183.72],[1,1.67,115.58],[2,1.55,420.5]],"batl":[[0,2.16,113.93],[1,2.18,101.68]],"ltp":1.81,"tv":632.76,"id":8284479}]}]}
{"op":"mcm","clk":"1009112459","pt":1580663604071,"mc":[{"id":"1.168236370","rc":[{"batb":[[0,1.82,18.8]],"ltp":1.3,"tv":213.45,"id":4520808},{"batb":[[0,1.68,157.36],[1,1.67,142.1]],"ltp":1.81,"tv":632.76,"id":8284479}]}]}
{"op":"mcm","clk":"1009113577","pt":1580663611216,"mc":[{"id":"1.168236370","rc":[{"batb":[[0,1.67,26.52],[1,1.55,420.5],[2,1.01,10.51]],"ltp":1.81,"tv":632.76,"id":8284479}]}]}
{"op":"mcm","clk":"1009114037","pt":1580663614088,"mc":[{"id":"1.168236370","rc":[{"batb":[[0,1.86,149.05],[1,1.84,165.92],[2,1.82,18.8]],"batl":[[0,1.94,119.5],[1,1.96,138.55]],"ltp":1.3,"tv":213.45,"id":4520808},{"batb":[[1,1.01,10.51],[2,1.01,0]],"ltp":1.81,"tv":632.76,"id":8284479}]}]}
{"op":"mcm","clk":"1009114174","pt":1580663615092,"mc":[{"id":"1.168236370","rc":[{"batb":[[0,2.1,25.65],[1,1.84,19.43],[2,1.01,10.51]],"ltp":1.81,"tv":632.76,"id":8284479}]}]}
{"op":"mcm","clk":"1009114324","pt":1580663615992,"mc":[{"id":"1.168236370","rc":[{"batb":[[2,1.83,50.41]],"batl":[[2,2,42.01]],"ltp":1.3,"tv":213.45,"id":4520808},{"batb":[[1,2,42.01],[2,1.84,19.43]],"batl":[[0,2.2,34.45]],"ltp":1.81,"tv":632.76,"id":8284479}]}]}
{"op":"mcm","clk":"1009116761","pt":1580663630619,"mc":[{"id":"1.168236370","rc":[{"batb":[[0,1.83,50.41],[1,1.82,18.8],[2,1.58,416.47]],"batl":[[0,2,42.01],[1,1.96,0],[2,2,0]],"ltp":1.3,"tv":213.45,"id":4520808}]}]}
{"op":"mcm","clk":"1009117362","pt":1580663634188,"mc":[{"id":"1.168236370","rc":[{"batb":[[0,1.87,147.93],[1,1.85,162.99],[2,1.83,50.41]],"batl":[[0,1.95,112.49],[1,1.97,136.39],[2,2,42.01]],"ltp":1.3,"tv":213.45,"id":4520808}]}]}
{"op":"mcm","clk":"1009118383","pt":1580663640117,"mc":[{"id":"1.168236370","rc":[{"batb":[[0,1.83,50.41],[1,1.58,416.47],[2,1.5,37.92]],"batl":[[0,2,42.01],[1,1.97,0],[2,2,0]],"ltp":1.3,"tv":213.45,"id":4520808},{"batb":[[0,2,42.01],[1,1.84,19.43],[2,1.67,409.76]],"ltp":1.81,"tv":632.76,"id":8284479}]}]}
{"op":"mcm","clk":"1009118529","pt":1580663641033,"mc":[{"id":"1.168236370","rc":[{"batb":[[0,1.58,416.47],[1,1.5,37.92],[2,1.01,10.51]],"ltp":1.3,"tv":213.45,"id":4520808},{"batb":[[0,1.84,19.43],[1,1.67,409.76],[2,1.01,10.51]],"ltp":1.81,"tv":632.76,"id":8284479}]}]}
{"op":"mcm","clk":"1009118883","pt":1580663643108,"mc":[{"id":"1.168236370","rc":[{"batb":[[1,1.53,143.17],[2,1.52,164.42]],"batl":[[0,2.26,164.17],[1,2.28,89.8]],"ltp":1.3,"tv":213.45,"id":4520808},{"batb":[[0,1.83,19.75]],"ltp":1.81,"tv":632.76,"id":8284479}]}]}
{"op":"mcm","clk":"1009119497","pt":1580663646820,"mc":[{"id":"1.168236370","rc":[{"batb":[[1,1.5,37.37],[2,1.01,10.51]],"ltp":1.3,"tv":213.45,"id":4520808}]}]}
{"op":"mcm","clk":"1009119696","pt":1580663648089,"mc":[{"id":"1.168236370","rc":[{"batb":[[0,1.5,37.37],[1,1.01,10.51],[2,1.01,0]],"ltp":1.3,"tv":213.45,"id":4520808},{"batb":[[1,1.01,10.51],[2,1.01,0]],"ltp":1.81,"tv":632.76,"id":8284479}]}]}
{"op":"mcm","clk":"1009119876","pt":1580663649210,"mc":[{"id":"1.168236370","rc":[{"batb":[[1,1.8,148.64],[2,1.78,184.86]],"batl":[[0,1.88,171.74],[1,1.9,152.12]],"ltp":1.81,"tv":632.76,"id":8284479}]}]}
{"op":"mcm","clk":"1009120017","pt":1580663650112,"mc":[{"id":"1.168236370","rc":[{"batb":[[0,2.1,24.39],[1,2.06,39.49],[2,1.8,19.51]],"batl":[[0,2.26,32.77]],"ltp":1.3,"tv":213.45,"id":4520808},{"batb":[[1,1.8,200.73]],"batl":[[2,1.95,42.01]],"ltp":1.81,"tv":632.76,"id":8284479}]}]}
{"op":"mcm","clk":"1009122811","pt":1580663667035,"mc":[{"id":"1.168236370","rc":[{"batb":[[0,1.8,19.51],[1,1.7,409.32],[2,1.01,10.51]],"ltp":1.3,"tv":213.45,"id":4520808},{"batb":[[0,1.68,25.73],[1,1.55,420.5],[2,1.01,10.51]],"ltp":1.81,"tv":632.76,"id":8284479}]}]}
{"op":"mcm","clk":"1009123323","pt":1580663670159,"mc":[{"id":"1.168236370","rc":[{"batb":[[0,1.68,208.85],[1,1.67,115.75],[2,1.55,420.5]],"batl":[[0,2.18,164.82],[1,2.2,99.13]],"ltp":1.81,"tv":632.76,"id":8284479}]}]}
{"op":"mcm","clk":"1009125355","pt":1580663682782,"mc":[{"id":"1.168236370","rc":[{"batb":[[0,1.68,25.73],[1,1.55,420.5],[2,1.01,10.51]],"ltp":1.81,"tv":632.76,"id":8284479}]}]}
{"op":"mcm","clk":"1009125751","pt":1580663685160,"mc":[{"id":"1.168236370","rc":[{"batb":[[1,1.01,10.51],[2,1.01,0]],"ltp":1.3,"tv":213.45,"id":4520808},{"batb":[[1,1.01,10.51],[2,1.01,0]],"ltp":1.81,"tv":632.76,"id":8284479}]}]}
{"op":"mcm","clk":"1009125877","pt":1580663685957,"mc":[{"id":"1.168236370","rc":[{"batb":[[0,1.85,172.95],[1,1.83,168.86],[2,1.82,50.41]],"batl":[[0,1.93,104.58],[1,1.95,140.66]],"ltp":1.3,"tv":213.45,"id":4520808},{"batl":[[0,2.2,34.45]],"ltp":1.81,"tv":632.76,"id":8284479}]}]}
{"op":"mcm","clk":"1009126056","pt":1580663686877,"mc":[{"id":"1.168236370","rc":[{"batl":[[2,1.98,42.01]],"ltp":1.3,"tv":213.45,"id":4520808},{"batb":[[0,2.12,24.78],[1,2.02,41.17],[2,1.87,132.27]],"ltp":1.81,"tv":632.76,"id":8284479}]}]}
{"op":"mcm","clk":"1009129259","pt":1580663705144,"mc":[{"id":"1.168236370","rc":[{"batb":[[0,1.55,420.5],[1,1.49,39.03],[2,1.01,10.51]],"ltp":1.3,"tv":213.45,"id":4520808},{"batb":[[0,1.86,18.73],[1,1.7,409.32],[2,1.01,10.51]],"ltp":1.81,"tv":632.76,"id":8284479}]}]}
{"op":"mcm","clk":"1009129747","pt":1580663707968,"mc":[{"id":"1.168236370","rc":[{"batb":[[1,1.52,139.19],[2,1.51,168.78]],"batl":[[0,2.24,173.39],[1,2.26,92.01]],"ltp":1.3,"tv":213.45,"id":4520808},{"batb":[[0,1.85,18.96]],"ltp":1.81,"tv":632.76,"id":8284479}]}]}
{"op":"mcm","clk":"1009129922","pt":1580663708986,"mc":[{"id":"1.168236370","rc":[{"batb":[[1,1.49,38.71],[2,1.01,10.51]],"ltp":1.3,"tv":213.45,"id":4520808}]}]}
{"op":"mcm","clk":"1009130466","pt":1580663711943,"mc":[{"id":"1.168236370","rc":[{"batb":[[0,1.77,194.86],[1,1.75,195.83],[2,1.55,420.5]],"batl":[[0,1.85,157.81],[1,1.87,159.84]],"ltp":1.3,"tv":213.45,"id":4520808}]}]}
{"op":"mcm","clk":"1009131544","pt":1580663718066,"mc":[{"id":"1.168236370","rc":[{"batb":[[0,1.55,420.5],[1,1.49,38.71],[2,1.01,10.51]],"ltp":1.3,"tv":213.45,"id":4520808}]}]}
{"op":"mcm","clk":"1009132048","pt":1580663720867,"mc":[{"id":"1.168236370","rc":[{"batb":[[1,1.52,139.19],[2,1.51,168.78]],"batl":[[0,2.24,173.39],[1,2.26,92.01]],"ltp":1.3,"tv":213.45,"id":4520808}]}]}
{"op":"mcm","clk":"1009133544","pt":1580663729773,"mc":[{"id":"1.168236370","rc":[{"batb":[[1,1.49,38.71],[2,1.01,10.51]],"ltp":1.3,"tv":213.45,"id":4520808}]}]}
{"op":"mcm","clk":"1009133781","pt":1580663731278,"mc":[{"id":"1.168236370","rc":[{"batb":[[0,1.49,38.71],[1,1.01,10.51],[2,1.01,0]],"ltp":1.3,"tv":213.45,"id":4520808},{"batb":[[1,1.01,10.51],[2,1.01,0]],"ltp":1.81,"tv":632.76,"id":8284479}]}]}
{"op":"mcm","clk":"1009134106","pt":1580663733186,"mc":[{"id":"1.168236370","rc":[{"batb":[[0,2.06,25.49],[1,1.78,20.3],[2,1.55,406.39]],"ltp":1.3,"tv":213.45,"id":4520808},{"batb":[[1,1.81,183.09],[2,1.79,181.54]],"batl":[[0,1.89,129.68],[1,1.91,149.76]],"ltp":1.81,"tv":632.76,"id":8284479}]}]}
{"op":"mcm","clk":"1009134230","pt":1580663733974,"mc":[{"id":"1.168236370","rc":[{"batb":[[1,2.04,40.33],[2,1.78,20.3]],"batl":[[0,2.24,33.61]],"ltp":1.3,"tv":213.45,"id":4520808},{"batb":[[1,1.81,234.34]],"batl":[[2,1.96,42.01]],"ltp":1.81,"tv":632.76,"id":8284479}]}]}
{"op":"mcm","clk":"1009137713","pt":1580663755144,"mc":[{"id":"1.168236370","rc":[{"batb":[[0,1.78,20.3],[1,1.7,409.32],[2,1.01,10.51]],"ltp":1.3,"tv":213.45,"id":4520808},{"batb":[[0,1.7,25.1],[1,1.55,420.5],[2,1.01,10.51]],"ltp":1.81,"tv":632.76,"id":8284479}]}]}
{"op":"mcm","clk":"1009138266","pt":1580663758239,"mc":[{"id":"1.168236370","rc":[{"batb":[[1,1.69,184.76],[2,1.67,230.08]],"batl":[[0,2.2,145.63],[1,2.22,96.64]],"ltp":1.81,"tv":632.76,"id":8284479}]}]}
{"op":"mcm","clk":"1009138768","pt":1580663761031,"mc":[{"id":"1.168236370","rc":[{"batb":[[1,1.01,10.51],[2,1.01,0]],"ltp":1.3,"tv":213.45,"id":4520808}]}]}
{"op":"mcm","clk":"1009138978","pt":1580663762228,"mc":[{"id":"1.168236370","rc":[{"batl":[[0,1.76,168.13],[1,1.78,186.85]],"ltp":1.81,"tv":632.76,"id":8284479}]}]}
{"op":"mcm","clk":"1009139164","pt":1580663763211,"mc":[{"id":"1.168236370","rc":[{"batb":[[0,2.3,18.8],[1,2.08,24.71],[2,1.01,10.51]],"ltp":1.3,"tv":213.45,"id":4520808}]}]}
{"op":"mcm","clk":"1009139305","pt":1580663764005,"mc":[{"id":"1.168236370","rc":[{"batb":[[1,2.22,33.61],[2,2.08,24.71]],"batl":[[0,2.46,28.57]],"ltp":1.3,"tv":213.45,"id":4520808},{"batb":[[1,1.69,245.25]],"batl":[[2,1.82,42.01]],"ltp":1.81,"tv":632.76,"id":8284479}]}]}
{"op":"mcm","clk":"1009144991","pt":1580663797694,"mc":[{"id":"1.168236370","rc":[{"batb":[[0,2.28,19.04]],"ltp":1.3,"tv":213.45,"id":4520808},{"batb":[[0,1.7,24.86]],"ltp":1.81,"tv":632.76,"id":8284479}]}]}
{"op":"mcm","clk":"1009145371","pt":1580663799987,"mc":[{"id":"1.168236370","rc":[{"trd":[[2.3,30]],"ltp":2.3,"tv":243.45,"id":4520808},{"trd":[[1.76,65.2]],"batl":[[0,1.76,128.93]],"ltp":1.76,"tv":671.96,"id":8284479}],"tv":915.42}]}
{"op":"mcm","clk":"1009145850","pt":1580663802778,"mc":[{"id":"1.168236370","rc":[{"batl":[[0,1.76,152.8]],"ltp":1.76,"tv":671.96,"id":8284479}]}]}
{"op":"mcm","clk":"1009149315","pt":1580663824122,"mc":[{"id":"1.168236370","rc":[{"batb":[[0,1.71,24.71]],"ltp":1.76,"tv":671.96,"id":8284479}]}]}
{"op":"mcm","clk":"1009150707","pt":1580663833006,"mc":[{"id":"1.168236370","rc":[{"batb":[[1,1.69,266.41]],"ltp":1.76,"tv":671.96,"id":8284479}]}]}
{"op":"mcm","clk":"1009154558","pt":1580663856164,"mc":[{"id":"1.168236370","rc":[{"batb":[[0,2.22,33.61],[1,2.08,24.71],[2,1.82,401.24]],"ltp":2.3,"tv":243.45,"id":4520808},{"batb":[[0,1.69,60.49],[1,1.51,38.16],[2,1.46,435.7]],"batl":[[0,1.82,42.01],[1,1.78,0],[2,1.82,0]],"ltp":1.76,"tv":671.96,"id":8284479}]}]}
{"op":"mcm","clk":"1009154717","pt":1580663857171,"mc":[{"id":"1.168236370","rc":[{"batb":[[0,2.08,24.71],[1,1.82,401.24],[2,1.01,10.51]],"ltp":2.3,"tv":243.45,"id":4520808},{"batb":[[0,1.51,38.16],[1,1.46,435.7],[2,1.01,10.51]],"ltp":1.76,"tv":671.96,"id":8284479}]}]}
{"op":"mcm","clk":"1009154898","pt":1580663858229,"mc":[{"id":"1.168236370","rc":[{"batb":[[0,1.52,149.39],[1,1.51,206.78],[2,1.46,435.7]],"batl":[[0,1.89,137.78],[1,1.91,149.67]],"ltp":1.76,"tv":671.96,"id":8284479}]}]}
{"op":"mcm","clk":"1009155039","pt":1580663858978,"mc":[{"id":"1.168236370","rc":[{"batb":[[0,2.06,25.41]],"ltp":2.3,"tv":243.45,"id":4520808},{"batb":[[0,1.52,37.77],[1,1.46,435.7],[2,1.01,10.51]],"ltp":1.76,"tv":671.96,"id":8284479}]}]}
{"op":"mcm","clk":"1009155433","pt":1580663861139,"mc":[{"id":"1.168236370","rc":[{"batb":[[0,1.66,118.13],[1,1.65,120.56],[2,1.52,37.77]],"batl":[[0,1.72,166.11],[1,1.74,201.17]],"ltp":1.76,"tv":671.96,"id":8284479}]}]}
{"op":"mcm","clk":"1009155468","pt":1580663861356,"mc":[{"id":"1.168236370","rc":[{"batl":[[0,1.72,125.52]],"ltp":1.76,"tv":671.96,"id":8284479}]}]}
{"op":"mcm","clk":"1009155944","pt":1580663864142,"mc":[{"id":"1.168236370","rc":[{"batb":[[0,1.52,37.77],[1,1.46,435.7],[2,1.01,10.51]],"ltp":1.76,"tv":671.96,"id":8284479}]}]}
{"op":"mcm","clk":"1009156295","pt":1580663866527,"mc":[{"id":"1.168236370","rc":[{"batb":[[0,1.52,233.63],[1,1.51,168.7],[2,1.46,435.7]],"batl":[[0,1.9,175.64],[1,1.92,147.14]],"ltp":1.76,"tv":671.96,"id":8284479}]}]}
{"op":"mcm","clk":"1009157156","pt":1580663872002,"mc":[{"id":"1.168236370","rc":[{"batb":[[0,1.52,37.77],[1,1.46,435.7],[2,1.01,10.51]],"ltp":1.76,"tv":671.96,"id":8284479}]}]}
{"op":"mcm","clk":"1009157464","pt":1580663873707,"mc":[{"id":"1.168236370","rc":[{"batb":[[1,1.01,10.51],[2,1.01,0]],"ltp":1.76,"tv":671.96,"id":8284479}]}]}
{"op":"mcm","clk":"1009157713","pt":1580663875156,"mc":[{"id":"1.168236370","rc":[{"batb":[[0,1.82,132.82],[1,1.8,177.91],[2,1.52,37.77]],"ltp":1.76,"tv":671.96,"id":8284479}]}]}
{"op":"mcm","clk":"1009157865","pt":1580663876058,"mc":[{"id":"1.168236370","rc":[{"batb":[[0,2.06,64.9],[1,1.94,15.58],[2,1.82,401.24]],"ltp":2.3,"tv":243.45,"id":4520808},{"batb":[[0,1.85,19.04],[1,1.82,132.82],[2,1.8,177.91]],"batl":[[1,1.92,189.15]],"ltp":1.76,"tv":671.96,"id":8284479}]}]}
{"op":"mcm","clk":"1009160377","pt":1580663891204,"mc":[{"id":"1.168236370","rc":[{"batb":[[0,1.94,15.58],[1,1.82,401.24],[2,1.01,10.51]],"ltp":2.3,"tv":243.45,"id":4520808},{"batb":[[0,1.66,27.15],[1,1.55,420.5],[2,1.01,10.51]],"ltp":1.76,"tv":671.96,"id":8284479}]}]}
{"op":"mcm","clk":"1009161256","pt":1580663896223,"mc":[{"id":"1.168236370","rc":[{"batb":[[0,1.78,189.48],[1,1.76,191.81],[2,1.66,27.15]],"batl":[[0,1.86,151.58],[1,1.88,156.97]],"ltp":1.76,"tv":671.96,"id":8284479}]}]}
{"op":"mcm","clk":"1009161679","pt":1580663899034,"mc":[{"id":"1.168236370","rc":[{"batb":[[0,1.66,27.15],[1,1.55,420.5],[2,1.01,10.51]],"ltp":1.76,"tv":671.96,"id":8284479}]}]}
{"op":"mcm","clk":"1009162169","pt":1580663902220,"mc":[{"id":"1.168236370","rc":[{"batb":[[0,1.66,162.88],[1,1.65,120.47],[2,1.55,420.5]],"batl":[[0,2.02,201.36],[1,2.04,122.82]],"ltp":1.76,"tv":671.96,"id":8284479}]}]}
{"op":"mcm","clk":"1009162254","pt":1580663902748,"mc":[{"id":"1.168236370","rc":[{"batb":[[2,1.01,10.51]],"ltp":1.76,"tv":671.96,"id":8284479}]}]}
{"op":"mcm","clk":"1009162659","pt":1580663905240,"mc":[{"id":"1.168236370","rc":[{"batb":[[0,2.36,17.23],[1,2.1,24.16],[2,1.82,401.24]],"ltp":2.3,"tv":243.45,"id":4520808},{"batb":[[2,1.44,46.66]],"batl":[[0,1.72,148.62],[1,1.74,201.01]],"ltp":1.76,"tv":671.96,"id":8284479}]}]}
{"op":"mcm","clk":"1009162771","pt":1580663906047,"mc":[{"id":"1.168236370","rc":[{"batb":[[1,2.3,31.93],[2,2.1,24.16]],"batl":[[0,2.56,26.89]],"ltp":2.3,"tv":243.45,"id":4520808},{"batb":[[1,1.65,184.32]],"batl":[[2,1.77,42.01]],"ltp":1.76,"tv":671.96,"id":8284479}]}]}
{"op":"mcm","clk":"1009162909","pt":1580663906945,"mc":[{"id":"1.168236370","rc":[{"batb":[[2,1.44,482.84]],"ltp":1.76,"tv":671.96,"id":8284479}]}]}
{"op":"mcm","clk":"1009165808","pt":1580663925150,"mc":[{"id":"1.168236370","rc":[{"batb":[[0,2.1,24.16],[1,1.82,401.24],[2,1.01,10.51]],"ltp":2.3,"tv":243.45,"id":4520808},{"batb":[[0,1.44,482.84],[1,1.01,10.51],[2,1.44,0]],"ltp":1.76,"tv":671.96,"id":8284479}]}]}
{"op":"mcm","clk":"1009166216","pt":1580663927874,"mc":[{"id":"1.168236370","rc":[{"batb":[[0,1.45,203.69],[1,1.44,688.27],[2,1.01,10.51]],"batl":[[0,1.88,139.72],[1,1.9,151.96]],"ltp":1.76,"tv":671.96,"id":8284479}]}]}
{"op":"mcm","clk":"1009166374","pt":1580663929037,"mc":[{"id":"1.168236370","rc":[{"batb":[[0,1.44,482.84],[1,1.01,10.51],[2,1.01,0]],"ltp":1.76,"tv":671.96,"id":8284479}]}]}
{"op":"mcm","clk":"1009166665","pt":1580663930841,"mc":[{"id":"1.168236370","rc":[{"batb":[[0,1.44,46.66]],"ltp":1.76,"tv":671.96,"id":8284479}]}]}
{"op":"mcm","clk":"1009166891","pt":1580663932170,"mc":[{"id":"1.168236370","rc":[{"batb":[[0,2.1,61.96]],"ltp":2.3,"tv":243.45,"id":4520808},{"batb":[[0,1.8,181.43],[1,1.78,184.7],[2,1.44,46.66]],"batl":[[1,1.9,193.97]],"ltp":1.76,"tv":671.96,"id":8284479}]}]}
{"op":"mcm","clk":"1009167010","pt":1580663932952,"mc":[{"id":"1.168236370","rc":[{"batb":[[1,1.94,15.5],[2,1.82,401.24]],"batl":[[0,2.3,31.93]],"ltp":2.3,"tv":243.45,"id":4520808},{"batb":[[0,1.82,19.99],[1,1.8,181.43],[2,1.78,184.7]],"ltp":1.76,"tv":671.96,"id":8284479}]}]}
{"op":"mcm","clk":"1009169194","pt":1580663947217,"mc":[{"id":"1.168236370","rc":[{"batb":[[1,1.77,53.77],[2,1.61,30.14]],"batl":[[0,1.9,42.01],[1,1.9,0]],"ltp":1.76,"tv":671.96,"id":8284479}]}]}
{"op":"mcm","clk":"1009169266","pt":1580663947593,"mc":[{"id":"1.168236370","rc":[{"batb":[[0,2.1,37.81]],"ltp":2.3,"tv":243.45,"id":4520808},{"batb":[[0,1.77,53.77],[1,1.61,30.14],[2,1.52,425.49]],"ltp":1.76,"tv":671.96,"id":8284479}]}]}
{"op":"mcm","clk":"1009169515","pt":1580663949100,"mc":[{"id":"1.168236370","rc":[{"batb":[[0,1.94,15.5],[1,1.82,401.24],[2,1.01,10.51]],"ltp":2.3,"tv":243.45,"id":4520808},{"batb":[[0,1.61,30.14],[1,1.52,425.49],[2,1.01,10.51]],"ltp":1.76,"tv":671.96,"id":8284479}]}]}
{"op":"mcm","clk":"1009169679","pt":1580663950231,"mc":[{"id":"1.168236370","rc":[{"batb":[[0,1.61,277.87],[1,1.6,135.16],[2,1.52,425.49]],"batl":[[0,2.02,153.6],[1,2.04,122.84]],"ltp":1.76,"tv":671.96,"id":8284479}]}]}
{"op":"mcm","clk":"1009169794","pt":1580663950799,"mc":[{"id":"1.168236370","rc":[{"batb":[[0,1.61,30.14],[1,1.52,425.49],[2,1.01,10.51]],"ltp":1.76,"tv":671.96,"id":8284479}]}]}
{"op":"mcm","clk":"1009170383","pt":1580663954516,"mc":[{"id":"1.168236370","rc":[{"batb":[[0,1.76,178.37],[1,1.74,199.31],[2,1.61,30.14]],"batl":[[0,1.84,182.8],[1,1.86,162.19]],"ltp":1.76,"tv":671.96,"id":8284479}]}]}
{"op":"mcm","clk":"1009171273","pt":1580663960219,"mc":[{"id":"1.168236370","rc":[{"batb":[[0,1.61,30.14],[1,1.52,425.49],[2,1.01,10.51]],"ltp":1.76,"tv":671.96,"id":8284479}]}]}
{"op":"mcm","clk":"1009171830","pt":1580663963099,"mc":[{"id":"1.168236370","rc":[{"batb":[[0,1.61,277.87],[1,1.6,135.16],[2,1.52,425.49]],"batl":[[0,2.02,153.6],[1,2.04,122.84]],"ltp":1.76,"tv":671.96,"id":8284479}]}]}
{"op":"mcm","clk":"1009174333","pt":1580663978218,"mc":[{"id":"1.168236370","rc":[{"batb":[[0,1.61,30.14],[1,1.52,425.49],[2,1.01,10.51]],"ltp":1.76,"tv":671.96,"id":8284479}]}]}
{"op":"mcm","clk":"1009174628","pt":1580663980017,"mc":[{"id":"1.168236370","rc":[{"batb":[[1,1.01,10.51],[2,1.01,0]],"ltp":2.3,"tv":243.45,"id":4520808},{"batb":[[1,1.01,10.51],[2,1.01,0]],"ltp":1.76,"tv":671.96,"id":8284479}]}]}
{"op":"mcm","clk":"1009174826","pt":1580663981132,"mc":[{"id":"1.168236370","rc":[{"batb":[[1,1.86,17.7],[2,1.01,10.51]],"ltp":2.3,"tv":243.45,"id":4520808},{"batb":[[0,1.97,15.66],[1,1.93,125.01],[2,1.91,147.14]],"ltp":1.76,"tv":671.96,"id":8284479}]}]}
{"op":"mcm","clk":"1009174984","pt":1580663982135,"mc":[{"id":"1.168236370","rc":[{"batb":[[0,1.96,43.69],[1,1.94,15.5],[2,1.86,17.7]],"batl":[[0,2.14,36.13]],"ltp":2.3,"tv":243.45,"id":4520808},{"batl":[[0,2.02,194.77]],"ltp":1.76,"tv":671.96,"id":8284479}]}]}
{"op":"mcm","clk":"1009178379","pt":1580664003747,"mc":[{"id":"1.168236370","rc":[{"batb":[[1,1.86,17.7],[2,1.67,409.76]],"ltp":2.3,"tv":243.45,"id":4520808},{"batb":[[0,1.87,47.89],[1,1.82,19.91],[2,1.58,416.47]],"batl":[[0,2.02,41.17],[1,2.04,0]],"ltp":1.76,"tv":671.96,"id":8284479}]}]}
{"op":"mcm","clk":"1009178595","pt":1580664005168,"mc":[{"id":"1.168236370","rc":[{"batb":[[0,1.86,17.7],[1,1.67,409.76],[2,1.01,10.51]],"ltp":2.3,"tv":243.45,"id":4520808},{"batb":[[0,1.82,19.91],[1,1.58,416.47],[2,1.01,10.51]],"ltp":1.76,"tv":671.96,"id":8284479}]}]}
{"op":"mcm","clk":"1009178784","pt":1580664006439,"mc":[{"id":"1.168236370","rc":[{"batb":[[0,1.82,132.38],[1,1.8,177.86],[2,1.58,416.47]],"batl":[[0,2.1,199.9],[1,2.12,109.98]],"ltp":1.76,"tv":671.96,"id":8284479}]}]}
{"op":"mcm","clk":"1009179951","pt":1580664014075,"mc":[{"id":"1.168236370","rc":[{"batb":[[0,2.08,38.65],[1,1.86,17.7],[2,1.67,409.76]],"batl":[[0,2.28,32.77]],"ltp":2.3,"tv":243.45,"id":4520808},{"batb":[[2,1.79,52.93]],"batl":[[0,1.89,111.89],[1,1.91,149.59],[2,1.93,42.01]],"ltp":1.76,"tv":671.96,"id":8284479}]}]}
{"op":"mcm","clk":"1009180131","pt":1580664015069,"mc":[{"id":"1.168236370","rc":[{"batb":[[0,2.1,24.16],[1,2.08,38.65],[2,1.91,16.13]],"ltp":2.3,"tv":243.45,"id":4520808}]}]}
{"op":"mcm","clk":"1009183121","pt":1580664035910,"mc":[{"id":"1.168236370","rc":[{"batb":[[0,2.08,38.65],[1,1.91,16.13],[2,1.67,409.76]],"ltp":2.3,"tv":243.45,"id":4520808},{"batb":[[0,1.79,52.93],[1,1.59,31.71],[2,1.58,416.47]],"batl":[[0,1.93,42.01],[1,1.91,0],[2,1.93,0]],"ltp":1.76,"tv":671.96,"id":8284479}]}]}
{"op":"mcm","clk":"1009183324","pt":1580664037191,"mc":[{"id":"1.168236370","rc":[{"batb":[[0,1.91,16.13],[1,1.67,409.76],[2,1.01,10.51]],"ltp":2.3,"tv":243.45,"id":4520808},{"batb":[[0,1.59,31.71],[1,1.58,416.47],[2,1.01,10.51]],"ltp":1.76,"tv":671.96,"id":8284479}]}]}
{"op":"mcm","clk":"1009183579","pt":1580664039100,"mc":[{"id":"1.168236370","rc":[{"batb":[[0,1.6,224.2],[1,1.59,169.97],[2,1.58,416.47]],"batl":[[0,2.06,184.65],[1,2.08,116.13]],"ltp":1.76,"tv":671.96,"id":8284479}]}]}
{"op":"mcm","clk":"1009184483","pt":1580664046197,"mc":[{"id":"1.168236370","rc":[{"batb":[[0,1.59,31.71],[1,1.58,416.47],[2,1.01,10.51]],"ltp":1.76,"tv":671.96,"id":8284479}]}]}
{"op":"mcm","clk":"1009184730","pt":1580664048207,"mc":[{"id":"1.168236370","rc":[{"batb":[[1,1.01,10.51],[2,1.01,0]],"ltp":1.76,"tv":671.96,"id":8284479}]}]}
{"op":"mcm","clk":"1009184868","pt":1580664049210,"mc":[{"id":"1.168236370","rc":[{"batb":[[0,1.95,148.83],[1,1.93,142.43],[2,1.91,16.13]],"batl":[[0,2.04,116.46],[1,2.06,119.43]],"ltp":2.3,"tv":243.45,"id":4520808}]}]}
{"op":"mcm","clk":"1009185009","pt":1580664050226,"mc":[{"id":"1.168236370","rc":[{"batb":[[2,1.92,45.37]],"batl":[[2,2.1,37.81]],"ltp":2.3,"tv":243.45,"id":4520808},{"batb":[[0,1.99,30.06],[1,1.9,46.21],[2,1.82,19.91]],"batl":[[0,2.08,38.65]],"ltp":1.76,"tv":671.96,"id":8284479}]}]}
{"op":"mcm","clk":"1009187553","pt":1580664067645,"mc":[{"id":"1.168236370","rc":[{"trd":[[1.99,9.09]],"batb":[[0,1.99,25.51]],"ltp":1.99,"tv":681.05,"id":8284479}],"tv":924.51}]}
{"op":"mcm","clk":"1009189420","pt":1580664080126,"mc":[{"id":"1.168236370","rc":[{"batb":[[0,1.92,45.37],[1,1.67,409.76],[2,1.65,26.28]],"batl":[[0,2.1,37.81],[1,3,2.27],[2,2.1,0]],"ltp":2.3,"tv":243.45,"id":4520808},{"batb":[[0,1.9,46.21],[1,1.82,19.91],[2,1.62,415.43]],"ltp":1.99,"tv":681.05,"id":8284479}]}]}
{"op":"mcm","clk":"1009189684","pt":1580664082057,"mc":[{"id":"1.168236370","rc":[{"batb":[[0,1.67,409.76],[1,1.65,26.28],[2,1.01,10.51]],"batl":[[0,3,2.27],[1,3,0]],"ltp":2.3,"tv":243.45,"id":4520808},{"batb":[[0,1.82,19.91],[1,1.62,415.43],[2,1.01,10.51]],"ltp":1.99,"tv":681.05,"id":8284479}]}]}
{"op":"mcm","clk":"1009189872","pt":1580664083228,"mc":[{"id":"1.168236370","rc":[{"batb":[[1,1.66,26.04],[2,1.65,26.28]],"ltp":2.3,"tv":243.45,"id":4520808},{"batb":[[1,1.81,20.14]],"ltp":1.99,"tv":681.05,"id":8284479}]}]}
{"op":"mcm","clk":"1009189975","pt":1580664083959,"mc":[{"id":"1.168236370","rc":[{"batb":[[2,1.01,10.51]],"ltp":2.3,"tv":243.45,"id":4520808},{"batb":[[0,1.81,20.14],[1,1.01,10.51],[2,1.01,0]],"ltp":1.99,"tv":681.05,"id":8284479}]}]}
{"op":"mcm","clk":"1009190112","pt":1580664084753,"mc":[{"id":"1.168236370","rc":[{"batb":[[0,1.89,168.49],[1,1.87,157.38],[2,1.67,409.76]],"batl":[[0,1.98,143.84],[1,2,130.28],[2,3,2.27]],"ltp":2.3,"tv":243.45,"id":4520808}]}]}
{"op":"mcm","clk":"1009190332","pt":1580664086131,"mc":[{"id":"1.168236370","rc":[{"batb":[[0,1.67,409.76],[1,1.66,26.04],[2,1.01,10.51]],"batl":[[0,1.98,125.14]],"ltp":2.3,"tv":243.45,"id":4520808}]}]}
{"op":"mcm","clk":"1009190501","pt":1580664087463,"mc":[{"id":"1.168236370","rc":[{"batb":[[1,1.67,409.76],[2,1.01,10.51]],"ltp":1.99,"tv":681.05,"id":8284479}]}]}
{"op":"mcm","clk":"1009190660","pt":1580664088632,"mc":[{"id":"1.168236370","rc":[{"batb":[[0,1.9,111.06],[1,1.88,154.69],[2,1.67,409.76]],"ltp":2.3,"tv":243.45,"id":4520808}]}]}
{"op":"mcm","clk":"1009190870","pt":1580664090088,"mc":[{"id":"1.168236370","rc":[{"batb":[[0,1.67,409.76],[1,1.66,26.04],[2,1.01,10.51]],"batl":[[0,3,2.27],[1,2,0],[2,3,0]],"ltp":2.3,"tv":243.45,"id":4520808}]}]}
{"op":"mcm","clk":"1009191303","pt":1580664093063,"mc":[{"id":"1.168236370","rc":[{"batb":[[0,1.69,204.62],[1,1.67,639.96],[2,1.66,26.04]],"batl":[[0,2.24,97.36],[1,2.26,91.79],[2,3,2.27]],"ltp":2.3,"tv":243.45,"id":4520808}]}]}
{"op":"mcm","clk":"1009192965","pt":1580664104366,"mc":[{"id":"1.168236370","rc":[{"batl":[[0,3,2.27],[1,2.26,0],[2,3,0]],"ltp":2.3,"tv":243.45,"id":4520808}]}]}
{"op":"mcm","clk":"1009193365","pt":1580664107209,"mc":[{"id":"1.168236370","rc":[{"batb":[[1,1.67,230.2]],"ltp":2.3,"tv":243.45,"id":4520808},{"batb":[[1,1.01,10.51],[2,1.01,0]],"ltp":1.99,"tv":681.05,"id":8284479}]}]}
{"op":"mcm","clk":"1009193515","pt":1580664108161,"mc":[{"id":"1.168236370","rc":[{"batb":[[0,1.69,265.11]],"batl":[[0,1.76,149.23],[1,1.78,186.97],[2,3,2.27]],"ltp":2.3,"tv":243.45,"id":4520808},{"batb":[[0,2.36,18.1],[1,2.04,27.3],[2,1.81,20.14]],"batl":[[0,2.44,28.57]],"ltp":1.99,"tv":681.05,"id":8284479}]}]}
{"op":"mcm","clk":"1009193628","pt":1580664108964,"mc":[{"id":"1.168236370","rc":[{"batb":[[2,1.01,10.51]],"ltp":1.99,"tv":681.05,"id":8284479}]}]}
{"op":"mcm","clk":"1009193935","pt":1580664111193,"mc":[{"id":"1.168236370","rc":[{"batb":[[2,1.82,401.24]],"ltp":1.99,"tv":681.05,"id":8284479}]}]}
{"op":"mcm","clk":"1009195779","pt":1580664123180,"mc":[{"id":"1.168236370","rc":[{"batb":[[0,1.66,26.04],[1,1.46,435.7],[2,1.4,50.12]],"batl":[[0,3,2.27],[1,1.78,0],[2,3,0]],"ltp":2.3,"tv":243.45,"id":4520808}]}]}
{"op":"mcm","clk":"1009195939","pt":1580664124187,"mc":[{"id":"1.168236370","rc":[{"batb":[[0,1.46,435.7],[1,1.4,49.49],[2,1.01,10.51]],"ltp":2.3,"tv":243.45,"id":4520808},{"batb":[[0,2.04,27.3],[1,1.82,401.24],[2,1.01,10.51]],"ltp":1.99,"tv":681.05,"id":8284479}]}]}
{"op":"mcm","clk":"1009196223","pt":1580664125992,"mc":[{"id":"1.168236370","rc":[{"batb":[[1,1.43,181.73],[2,1.42,219.09]],"batl":[[0,1.98,140.26],[1,2,130.28],[2,3,2.27]],"ltp":2.3,"tv":243.45,"id":4520808}]}]}
{"op":"mcm","clk":"1009196558","pt":1580664128108,"mc":[{"id":"1.168236370","rc":[{"batb":[[1,1.4,49.49],[2,1.01,10.51]],"batl":[[0,3,2.27],[1,2,0],[2,3,0]],"ltp":2.3,"tv":243.45,"id":4520808}]}]}
{"op":"mcm","clk":"1009197040","pt":1580664131191,"mc":[{"id":"1.168236370","rc":[{"batb":[[0,1.63,208.48],[1,1.62,129.25],[2,1.46,435.7]],"batl":[[0,1.69,116.26],[1,1.71,213.73],[2,3,2.27]],"ltp":2.3,"tv":243.45,"id":4520808}]}]}
{"op":"mcm","clk":"1009197104","pt":1580664131609,"mc":[{"id":"1.168236370","rc":[{"batl":[[0,3,2.27],[1,1.71,0],[2,3,0]],"ltp":2.3,"tv":243.45,"id":4520808}]}]}
{"op":"mcm","clk":"1009197526","pt":1580664134117,"mc":[{"id":"1.168236370","rc":[{"batb":[[0,1.46,435.7],[1,1.4,49.49],[2,1.01,10.51]],"ltp":2.3,"tv":243.45,"id":4520808}]}]}
{"op":"mcm","clk":"1009198012","pt":1580664137203,"mc":[{"id":"1.168236370","rc":[{"batb":[[1,1.43,187.24],[2,1.42,219.1]],"batl":[[0,1.98,136.29],[1,2,130.27],[2,3,2.27]],"ltp":2.3,"tv":243.45,"id":4520808}]}]}
{"op":"mcm","clk":"1009200432","pt":1580664153136,"mc":[{"id":"1.168236370","rc":[{"batb":[[1,1.4,49.49],[2,1.01,10.51]],"batl":[[0,3,2.27],[1,2,0],[2,3,0]],"ltp":2.3,"tv":243.45,"id":4520808}]}]}
{"op":"mcm","clk":"1009200912","pt":1580664156165,"mc":[{"id":"1.168236370","rc":[{"batb":[[0,1.44,94.94],[1,1.43,187.24],[2,1.42,219.1]],"batl":[[0,1.47,164.79],[1,1.48,180.32],[2,3,2.27]],"ltp":2.3,"tv":243.45,"id":4520808},{"batb":[[1,1.01,10.51],[2,1.01,0]],"batl":[[0,3.25,18.48]],"ltp":1.99,"tv":681.05,"id":8284479}]}]}
{"op":"mcm","clk":"1009201061","pt":1580664157073,"mc":[{"id":"1.168236370","rc":[{"batl":[[2,1.53,42.01]],"ltp":2.3,"tv":243.45,"id":4520808},{"batb":[[0,3.15,21.01],[1,2.88,21.85],[2,2.58,14.32]],"ltp":1.99,"tv":681.05,"id":8284479}]}]}
{"op":"mcm","clk":"1009203286","pt":1580664171057,"mc":[{"id":"1.168236370","rc":[{"trd":[[1.44,137.79],[1.47,15.14]],"batb":[[0,1.43,187.24],[1,1.42,219.1],[2,1.4,49.49]],"batl":[[0,1.47,157.22],[2,3,2.27]],"ltp":1.47,"tv":396.39,"id":4520808},{"batb":[[1,2.58,14.32],[2,2.22,384.52]],"ltp":1.99,"tv":681.05,"id":8284479}],"tv":1077.44}]}
{"op":"mcm","clk":"1009203752","pt":1580664174177,"mc":[{"id":"1.168236370","rc":[{"batb":[[0,1.43,284.7]],"batl":[[2,1.52,42.01]],"ltp":1.47,"tv":396.39,"id":4520808},{"batb":[[1,2.92,21.85],[2,2.58,14.32]],"batl":[[0,3.35,17.64]],"ltp":1.99,"tv":681.05,"id":8284479}]}]}
{"op":"mcm","clk":"1009203905","pt":1580664175244,"mc":[{"id":"1.168236370","rc":[{"batb":[[0,1.43,97.46]],"ltp":1.47,"tv":396.39,"id":4520808}]}]}
{"op":"mcm","clk":"1009204336","pt":1580664178147,"mc":[{"id":"1.168236370","rc":[{"batb":[[1,1.28,485.89],[2,1.2,112.04]],"batl":[[0,1.52,42.01],[1,3,2.27],[2,1.52,0]],"ltp":1.47,"tv":396.39,"id":4520808},{"batb":[[0,2.92,21.85],[1,2.58,14.32],[2,2.22,384.52]],"ltp":1.99,"tv":681.05,"id":8284479}]}]}
{"op":"mcm","clk":"1009204487","pt":1580664179173,"mc":[{"id":"1.168236370","rc":[{"batb":[[0,1.28,485.89],[1,1.2,112.04],[2,1.01,10.51]],"batl":[[0,3,2.27],[1,3,0]],"ltp":1.47,"tv":396.39,"id":4520808},{"batb":[[0,2.58,14.32],[1,2.22,384.52],[2,1.01,10.51]],"ltp":1.99,"tv":681.05,"id":8284479}]}]}
{"op":"mcm","clk":"1009204663","pt":1580664180176,"mc":[{"id":"1.168236370","rc":[{"batb":[[0,1.2,112.04],[1,1.01,10.51],[2,1.01,0]],"ltp":1.47,"tv":396.39,"id":4520808},{"batb":[[1,1.01,10.51],[2,1.01,0]],"ltp":1.99,"tv":681.05,"id":8284479}]}]}
{"op":"mcm","clk":"1009204819","pt":1580664181202,"mc":[{"id":"1.168236370","rc":[{"batb":[[0,1.21,419.51],[1,1.2,672.05],[2,1.01,10.51]],"batl":[[0,1.65,221.7],[1,1.66,117.66],[2,3,2.27]],"ltp":1.47,"tv":396.39,"id":4520808}]}]}
{"op":"mcm","clk":"1009204962","pt":1580664182066,"mc":[{"id":"1.168236370","rc":[{"batl":[[0,1.42,2.52],[1,1.65,221.7],[2,1.66,117.66]],"ltp":1.47,"tv":396.39,"id":4520808}]}]}
{"op":"mcm","clk":"1009205238","pt":1580664183891,"mc":[{"id":"1.168236370","rc":[{"batl":[[0,1.65,221.7],[1,1.66,117.66],[2,3,2.27]],"ltp":1.47,"tv":396.39,"id":4520808}]}]}
{"op":"mcm","clk":"1009207997","pt":1580664201702,"mc":[{"id":"1.168236370","rc":[{"batb":[[0,1.2,112.04],[1,1.01,10.51],[2,1.01,0]],"batl":[[0,3,2.27],[1,1.66,0],[2,3,0]],"ltp":1.47,"tv":396.39,"id":4520808}]}]}
{"op":"mcm","clk":"1009208532","pt":1580664205101,"mc":[{"id":"1.168236370","rc":[{"batb":[[0,1.37,309.9],[1,1.36,271.05],[2,1.2,112.04]],"batl":[[0,1.42,215.84],[1,3,2.27]],"ltp":1.47,"tv":396.39,"id":4520808}]}]}
{"op":"mcm","clk":"1009208716","pt":1580664206166,"mc":[{"id":"1.168236370","rc":[{"batb":[[2,1.25,505.09]],"ltp":1.47,"tv":396.39,"id":4520808},{"batb":[[1,2.3,385.09],[2,1.01,10.51]],"ltp":1.99,"tv":681.05,"id":8284479}]}]}
{"op":"mcm","clk":"1009209055","pt":1580664208704,"mc":[{"id":"1.168236370","rc":[{"batl":[[0,1.41,195.96],[1,1.42,215.84],[2,3,2.27]],"ltp":1.47,"tv":396.39,"id":4520808}]}]}
{"op":"mcm","clk":"1009209231","pt":1580664210019,"mc":[{"id":"1.168236370","rc":[{"batb":[[0,1.25,505.09],[1,1.2,112.04],[2,1.01,10.51]],"batl":[[0,3,2.27],[1,1.42,0],[2,3,0]],"ltp":1.47,"tv":396.39,"id":4520808}]}]}
{"op":"mcm","clk":"1009209506","pt":1580664211828,"mc":[{"id":"1.168236370","rc":[{"batb":[[0,1.2,112.04],[1,1.01,10.51],[2,1.01,0]],"ltp":1.47,"tv":396.39,"id":4520808},{"batb":[[1,1.01,10.51],[2,1.01,0]],"ltp":1.99,"tv":681.05,"id":8284479}]}]}
{"op":"mcm","clk":"1009209824","pt":1580664213942,"mc":[{"id":"1.168236370","rc":[{"batb":[[0,1.21,334.92],[1,1.2,671.65],[2,1.01,10.51]],"batl":[[0,1.64,163.63],[1,1.65,120.69],[2,3,2.27]],"ltp":1.47,"tv":396.39,"id":4520808}]}]}
{"op":"mcm","clk":"1009210152","pt":1580664216134,"mc":[{"id":"1.168236370","rc":[{"batl":[[0,3,2.27],[1,1.65,0],[2,3,0]],"ltp":1.47,"tv":396.39,"id":4520808}]}]}
{"op":"mcm","clk":"1009210591","pt":1580664219031,"mc":[{"id":"1.168236370","rc":[{"batl":[[0,1.24,554.51],[1,1.25,401.63],[2,3,2.27]],"ltp":1.47,"tv":396.39,"id":4520808}]}]}
{"op":"mcm","clk":"1009210780","pt":1580664220245,"mc":[{"id":"1.168236370","rc":[{"batb":[[0,1.21,502.96],[2,1.09,248.63]],"ltp":1.47,"tv":396.39,"id":4520808},{"batb":[[0,5.1,13.45],[1,4,23.76],[2,1.01,10.51]],"batl":[[0,5.8,8.4]],"ltp":1.99,"tv":681.05,"id":8284479}]}]}
{"op":"mcm","clk":"1009210911","pt":1580664221104,"mc":[{"id":"1.168236370","rc":[{"batb":[[2,1.14,627.92]],"ltp":1.47,"tv":396.39,"id":4520808},{"batb":[[2,2.8,375.33]],"ltp":1.99,"tv":681.05,"id":8284479}]}]}
{"op":"mcm","clk":"1009211517","pt":1580664225031,"mc":[{"id":"1.168236370","rc":[{"batl":[[0,1.24,516.02]],"ltp":1.47,"tv":396.39,"id":4520808}]}]}
{"op":"mcm","clk":"1009212025","pt":1580664228158,"mc":[{"id":"1.168236370","rc":[{"batb":[[0,1.21,542.51]],"ltp":1.47,"tv":396.39,"id":4520808}]}]}
{"op":"mcm","clk":"1009212196","pt":1580664229173,"mc":[{"id":"1.168236370","rc":[{"trd":[[1.21,5.04]],"batb":[[0,1.21,539.99]],"ltp":1.21,"tv":401.43,"id":4520808}],"tv":1082.48}]}
{"op":"mcm","clk":"1009212441","pt":1580664230728,"mc":[{"id":"1.168236370","rc":[{"trd":[[1.21,72.26]],"batb":[[0,1.21,506.38]],"ltp":1.21,"tv":468.64,"id":4520808}],"tv":1149.7}]}
{"op":"mcm","clk":"1009212976","pt":1580664234239,"mc":[{"id":"1.168236370","rc":[{"batb":[[0,1.21,542.33]],"ltp":1.21,"tv":468.64,"id":4520808}]}]}
{"op":"mcm","clk":"1009213251","pt":1580664236069,"mc":[{"id":"1.168236370","rc":[{"batb":[[0,1.21,572.33]],"ltp":1.21,"tv":468.64,"id":4520808}]}]}
{"op":"mcm","clk":"1009214175","pt":1580664241958,"mc":[{"id":"1.168236370","rc":[{"trd":[[1.21,89.06]],"batb":[[0,1.21,563.93]],"ltp":1.21,"tv":485.45,"id":4520808}],"tv":1166.5}]}
{"op":"mcm","clk":"1009216434","pt":1580664256122,"mc":[{"id":"1.168236370","rc":[{"batb":[[0,1.21,198.04],[1,1.2,112.04]],"batl":[[0,3,2.27],[1,1.25,0],[2,3,0]],"ltp":1.21,"tv":485.45,"id":4520808}]}]}
{"op":"mcm","clk":"1009216944","pt":1580664259189,"mc":[{"id":"1.168236370","rc":[{"batl":[[0,1.33,333.15],[1,1.34,279.53],[2,3,2.27]],"ltp":1.21,"tv":485.45,"id":4520808}]}]}
{"op":"mcm","clk":"1009217705","pt":1580664263989,"mc":[{"id":"1.168236370","rc":[{"batb":[[0,1.21,30],[1,1.14,627.92],[2,1.09,1112.31]],"ltp":1.21,"tv":485.45,"id":4520808},{"batb":[[0,4,23.76],[1,2.8,375.33],[2,1.01,10.51]],"ltp":1.99,"tv":681.05,"id":8284479}]}]}
{"op":"mcm","clk":"1009217996","pt":1580664265923,"mc":[{"id":"1.168236370","rc":[{"batb":[[1,1.09,1112.31],[2,1.08,313.82]],"ltp":1.21,"tv":485.45,"id":4520808},{"batb":[[1,1.01,10.51],[2,1.01,0]],"ltp":1.99,"tv":681.05,"id":8284479}]}]}
{"op":"mcm","clk":"1009218254","pt":1580664267205,"mc":[{"id":"1.168236370","rc":[{"batb":[[1,1.09,248.16],[2,1.01,10.51]],"ltp":1.21,"tv":485.45,"id":4520808}]}]}
{"op":"mcm","clk":"1009218722","pt":1580664270199,"mc":[{"id":"1.168236370","rc":[{"batb":[[0,1.29,469.26],[1,1.28,374.51],[2,1.21,30]],"ltp":1.21,"tv":485.45,"id":4520808}]}]}
{"op":"mcm","clk":"1009218877","pt":1580664271196,"mc":[{"id":"1.168236370","rc":[{"batb":[[1,1.28,451.7]],"ltp":1.21,"tv":485.45,"id":4520808},{"batb":[[0,4,23.29],[1,3,23.92],[2,1.01,10.51]],"ltp":1.99,"tv":681.05,"id":8284479}]}]}
{"op":"mcm","clk":"1009219045","pt":1580664272212,"mc":[{"id":"1.168236370","rc":[{"batb":[[0,1.29,613.77]],"batl":[[2,1.35,42.01]],"ltp":1.21,"tv":485.45,"id":4520808},{"batb":[[1,3.85,14.28],[2,3,23.92]],"batl":[[0,4.5,11.76]],"ltp":1.99,"tv":681.05,"id":8284479}]}]}
{"op":"mcm","clk":"1009219860","pt":1580664277117,"mc":[{"id":"1.168236370","rc":[{"batb":[[2,1.2,530.86]],"ltp":1.21,"tv":485.45,"id":4520808}]}]}
{"op":"mcm","clk":"1009220860","pt":1580664283219,"mc":[{"id":"1.168236370","rc":[{"batb":[[0,1.2,530.86],[1,1.1,244.39],[2,1.01,10.51]],"batl":[[0,3,2.27],[1,1.34,0],[2,1.35,0]],"ltp":1.21,"tv":485.45,"id":4520808},{"batb":[[0,3,23.92],[1,2.52,381.46],[2,1.01,10.51]],"ltp":1.99,"tv":681.05,"id":8284479}]}]}
{"op":"mcm","clk":"1009221009","pt":1580664284218,"mc":[{"id":"1.168236370","rc":[{"batb":[[0,1.1,244.39],[1,1.01,10.51],[2,1.01,0]],"ltp":1.21,"tv":485.45,"id":4520808},{"batb":[[1,1.01,10.51],[2,1.01,0]],"ltp":1.99,"tv":681.05,"id":8284479}]}]}
{"op":"mcm","clk":"1009221449","pt":1580664287112,"mc":[{"id":"1.168236370","rc":[{"batb":[[1,1.09,1020.63],[2,1.01,10.51]],"batl":[[0,1.5,160.63],[1,1.51,167.44],[2,3,2.27]],"ltp":1.21,"tv":485.45,"id":4520808}]}]}
{"op":"mcm","clk":"1009222414","pt":1580664293144,"mc":[{"id":"1.168236370","rc":[{"batl":[[0,3,2.27],[1,1.51,0],[2,3,0]],"ltp":1.21,"tv":485.45,"id":4520808}]}]}
{"op":"mcm","clk":"1009222941","pt":1580664296239,"mc":[{"id":"1.168236370","rc":[{"batl":[[0,1.11,796.92],[1,1.12,354.3],[2,3,2.27]],"ltp":1.21,"tv":485.45,"id":4520808}]}]}
{"op":"mcm","clk":"1009223094","pt":1580664297145,"mc":[{"id":"1.168236370","rc":[{"batb":[[2,1.04,497.43]],"ltp":1.21,"tv":485.45,"id":4520808},{"batb":[[0,10.5,4.2],[1,8.6,7.87],[2,5.1,13.14]],"ltp":1.99,"tv":681.05,"id":8284479}]}]}
{"op":"mcm","clk":"1009223207","pt":1580664297838,"mc":[{"id":"1.168236370","rc":[{"batb":[[2,1.06,955.61]],"ltp":1.21,"tv":485.45,"id":4520808}]}]}
{"op":"mcm","clk":"1009223337","pt":1580664298635,"mc":[{"id":"1.168236370","rc":[{"trd":[[1.1,73.94]],"batb":[[0,1.1,207.41]],"ltp":1.1,"tv":559.39,"id":4520808}],"tv":1240.44}]}
{"op":"mcm","clk":"1009224409","pt":1580664304929,"mc":[{"id":"1.168236370","rc":[{"batb":[[0,1.09,1268.79],[1,1.06,955.61],[2,1.04,497.43]],"ltp":1.1,"tv":559.39,"id":4520808},{"batb":[[1,8.8,7.71],[2,5.2,12.83]],"ltp":1.99,"tv":681.05,"id":8284479}]}]}
{"op":"mcm","clk":"1009225047","pt":1580664309059,"mc":[{"id":"1.168236370","rc":[{"batl":[[0,1.1,145.4],[1,1.11,796.92],[2,1.12,354.3]],"ltp":1.1,"tv":559.39,"id":4520808}]}]}
{"op":"mcm","clk":"1009226086","pt":1580664315952,"mc":[{"id":"1.168236370","rc":[{"trd":[[1.1,198.26]],"batl":[[0,1.1,83.24]],"ltp":1.1,"tv":683.71,"id":4520808}],"tv":1364.76}]}
{"op":"mcm","clk":"1009226720","pt":1580664320168,"mc":[{"id":"1.168236370","rc":[{"batb":[[0,1.09,1166.56]],"batl":[[2,1.12,254.2]],"ltp":1.1,"tv":683.71,"id":4520808}]}]}
{"op":"mcm","clk":"1009227147","pt":1580664323183,"mc":[{"id":"1.168236370","rc":[{"batb":[[1,1.08,259.58],[2,1.06,955.61]],"batl":[[1,1.11,897.92]],"ltp":1.1,"tv":683.71,"id":4520808},{"batb":[[1,9,7.47],[2,5.3,12.43]],"ltp":1.99,"tv":681.05,"id":8284479}]}]}
{"op":"mcm","clk":"1009227821","pt":1580664327868,"mc":[{"id":"1.168236370","rc":[{"batl":[[0,1.11,897.92],[1,1.12,254.2],[2,3,2.27]],"ltp":1.1,"tv":683.71,"id":4520808}]}]}
{"op":"mcm","clk":"1009228294","pt":1580664331168,"mc":[{"id":"1.168236370","rc":[{"trd":[[1.09,166.48]],"batb":[[0,1.09,1083.32]],"batl":[[0,1.1,2.53],[1,1.11,897.92],[2,1.12,254.2]],"ltp":1.09,"tv":850.19,"id":4520808}],"tv":1531.24}]}
{"op":"mcm","clk":"1009228854","pt":1580664334966,"mc":[{"id":"1.168236370","rc":[{"batb":[[0,1.09,1136.07]],"ltp":1.09,"tv":850.19,"id":4520808}]}]}
{"op":"mcm","clk":"1009230262","pt":1580664345059,"mc":[{"id":"1.168236370","rc":[{"trd":[[1.1,198.65]],"batl":[[0,1.1,2.34]],"ltp":1.1,"tv":850.58,"id":4520808}],"tv":1531.63}]}
{"op":"mcm","clk":"1009230414","pt":1580664346030,"mc":[{"id":"1.168236370","rc":[{"batb":[[0,1.09,1083.32]],"batl":[[2,3,2.27]],"ltp":1.1,"tv":850.58,"id":4520808}]}]}
{"op":"mcm","clk":"1009230566","pt":1580664347095,"mc":[{"id":"1.168236370","rc":[{"trd":[[1.1,200.99]],"batl":[[0,1.11,897.92],[1,3,2.27],[2,3,0]],"ltp":1.1,"tv":852.91,"id":4520808},{"trd":[[10.5,6.08],[11,0.24]],"batb":[[0,10.5,1.16]],"ltp":10.5,"tv":687.37,"id":8284479}],"tv":1540.29}]}
{"op":"mcm","clk":"1009230722","pt":1580664348216,"mc":[{"id":"1.168236370","rc":[{"batb":[[1,1.08,352.46]],"batl":[[0,1.11,988.4]],"ltp":1.1,"tv":852.91,"id":4520808}]}]}
{"op":"mcm","clk":"1009230881","pt":1580664349234,"mc":[{"id":"1.168236370","rc":[{"batb":[[1,1.08,296.03]],"batl":[[0,1.11,933.75]],"ltp":1.1,"tv":852.91,"id":4520808}]}]}
{"op":"mcm","clk":"1009231221","pt":1580664351631,"mc":[{"id":"1.168236370","rc":[{"batb":[[0,1.09,1130.44]],"batl":[[1,1.12,218.69],[2,3,2.27]],"ltp":1.1,"tv":852.91,"id":4520808}]}]}
{"op":"mcm","clk":"1009231987","pt":1580664357131,"mc":[{"id":"1.168236370","rc":[{"trd":[[1.09,167.93]],"batb":[[0,1.09,1128.99]],"ltp":1.09,"tv":854.36,"id":4520808},{"trd":[[12.5,0.13]],"ltp":12.5,"tv":687.5,"id":8284479}],"tv":1541.87}]}
{"op":"mcm","clk":"1009233992","pt":1580664371032,"mc":[{"id":"1.168236370","rc":[{"batb":[[1,1.08,217.57]],"batl":[[0,1.11,857.73]],"ltp":1.09,"tv":854.36,"id":4520808}]}]}
{"op":"mcm","clk":"1009234371","pt":1580664373634,"mc":[{"id":"1.168236370","rc":[{"batb":[[0,1.09,1208.18]],"batl":[[1,1.12,294.04]],"ltp":1.09,"tv":854.36,"id":4520808}]}]}
{"op":"mcm","clk":"1009238792","pt":1580664405390,"mc":[{"id":"1.168236370","rc":[{"batl":[[1,1.12,294.24]],"ltp":1.09,"tv":854.36,"id":4520808}]}]}
{"op":"mcm","clk":"1009239757","pt":1580664412200,"mc":[{"id":"1.168236370","rc":[{"batb":[[0,1.06,955.61],[1,1.04,497.43],[2,1.01,10.51]],"batl":[[0,3,2.47],[1,1.12,0],[2,3,0]],"ltp":1.09,"tv":854.36,"id":4520808},{"batb":[[1,5.3,12.43],[2,3.5,371.08]],"ltp":12.5,"tv":687.5,"id":8284479}]}]}
{"op":"mcm","clk":"1009239992","pt":1580664414092,"mc":[{"id":"1.168236370","rc":[{"batb":[[0,1.04,497.43],[1,1.01,10.51],[2,1.01,0]],"ltp":1.09,"tv":854.36,"id":4520808},{"batb":[[0,5.3,12.43],[1,1.01,10.51],[2,3.5,0]],"ltp":12.5,"tv":687.5,"id":8284479}]}]}
{"op":"mcm","clk":"1009240156","pt":1580664415204,"mc":[{"id":"1.168236370","rc":[{"batb":[[0,1.05,404.12],[1,1.04,1321.54],[2,1.01,10.51]],"batl":[[0,1.21,439.42],[1,1.22,472.15],[2,3,2.27]],"ltp":1.09,"tv":854.36,"id":4520808}]}]}
{"op":"mcm","clk":"1009240181","pt":1580664415416,"mc":[{"id":"1.168236370","rc":[{"batb":[[0,1.04,497.43],[1,1.01,10.51],[2,1.01,0]],"batl":[[0,3,2.47],[1,1.22,0],[2,3,0]],"ltp":1.09,"tv":854.36,"id":4520808}]}]}
{"op":"mcm","clk":"1009240721","pt":1580664419226,"mc":[{"id":"1.168236370","rc":[{"batb":[[0,1.11,501.7],[1,1.1,658.65],[2,1.04,497.43]],"batl":[[0,1.13,858.57],[1,1.14,273.19],[2,3,2.27]],"ltp":1.09,"tv":854.36,"id":4520808}]}]}
{"op":"mcm","clk":"1009240820","pt":1580664419919,"mc":[{"id":"1.168236370","rc":[{"batb":[[2,1.07,893.98]],"ltp":1.09,"tv":854.36,"id":4520808},{"batb":[[1,3.35,371.23],[2,1.01,10.51]],"ltp":12.5,"tv":687.5,"id":8284479}]}]}
{"op":"mcm","clk":"1009240991","pt":1580664421236,"mc":[{"id":"1.168236370","rc":[{"batb":[[0,1.07,893.98],[1,1.04,497.43],[2,1.01,10.51]],"batl":[[0,3,2.47],[1,1.14,0],[2,3,0]],"ltp":1.09,"tv":854.36,"id":4520808}]}]}
{"op":"mcm","clk":"1009241134","pt":1580664422202,"mc":[{"id":"1.168236370","rc":[{"batb":[[0,1.04,497.43],[1,1.01,10.51],[2,1.01,0]],"ltp":1.09,"tv":854.36,"id":4520808},{"batb":[[1,1.01,10.51],[2,1.01,0]],"ltp":12.5,"tv":687.5,"id":8284479}]}]}
{"op":"mcm","clk":"1009241403","pt":1580664424209,"mc":[{"id":"1.168236370","rc":[{"batb":[[0,1.05,404.12],[1,1.04,1321.54],[2,1.01,10.51]],"batl":[[0,1.21,439.42],[1,1.22,472.15],[2,3,2.27]],"ltp":1.09,"tv":854.36,"id":4520808}]}]}
{"op":"mcm","clk":"1009241499","pt":1580664424928,"mc":[{"id":"1.168236370","rc":[{"batl":[[0,3,2.47],[1,1.22,0],[2,3,0]],"ltp":1.09,"tv":854.36,"id":4520808}]}]}
{"op":"mcm","clk":"1009241969","pt":1580664428219,"mc":[{"id":"1.168236370","rc":[{"batb":[[1,1.04,1489.58]],"batl":[[0,1.06,1192.23],[1,3,2.47]],"ltp":1.09,"tv":854.36,"id":4520808}]}]}
{"op":"mcm","clk":"1009242065","pt":1580664428837,"mc":[{"id":"1.168236370","rc":[{"batl":[[0,1.06,1234.24]],"ltp":1.09,"tv":854.36,"id":4520808},{"batb":[[0,15,5.67],[1,7.8,9.84],[2,1.01,10.51]],"ltp":12.5,"tv":687.5,"id":8284479}]}]}
{"op":"mcm","clk":"1009242238","pt":1580664430029,"mc":[{"id":"1.168236370","rc":[{"batb":[[2,1.02,2184.08]],"ltp":1.09,"tv":854.36,"id":4520808},{"batb":[[2,4,369.93]],"ltp":12.5,"tv":687.5,"id":8284479}]}]}
{"op":"mcm","clk":"1009243502","pt":1580664438132,"mc":[{"id":"1.168236370","rc":[{"batl":[[1,3,2.27]],"ltp":1.09,"tv":854.36,"id":4520808}]}]}
{"op":"mcm","clk":"1009243912","pt":1580664441053,"mc":[{"id":"1.168236370","rc":[{"batb":[[0,1.04,665.47],[1,1.02,2184.08],[2,1.01,10.51]],"batl":[[0,1.06,42.01]],"ltp":1.09,"tv":854.36,"id":4520808}]}]}
{"op":"mcm","clk":"1009244093","pt":1580664442171,"mc":[{"id":"1.168236370","rc":[{"batb":[[0,1.02,2184.08],[1,1.01,10.51],[2,1.01,0]],"batl":[[0,3,2.27],[1,3,0]],"ltp":1.09,"tv":854.36,"id":4520808},{"batb":[[0,7.8,9.84],[1,4,369.93],[2,1.01,10.51]],"ltp":12.5,"tv":687.5,"id":8284479}]}]}
{"op":"mcm","clk":"1009244259","pt":1580664443238,"mc":[{"id":"1.168236370","rc":[{"batb":[[0,1.01,10.51],[1,1.01,0]],"ltp":1.09,"tv":854.36,"id":4520808},{"batb":[[1,1.01,10.51],[2,1.01,0]],"ltp":12.5,"tv":687.5,"id":8284479}]}]}
{"op":"mcm","clk":"1009244362","pt":1580664443976,"mc":[{"id":"1.168236370","rc":[{"batb":[[0,1.02,805.83],[1,1.01,465.42]],"batl":[[0,1.13,975.62],[1,3,2.27]],"ltp":1.09,"tv":854.36,"id":4520808}]}]}
{"op":"mcm","clk":"1009245580","pt":1580664452691,"mc":[{"id":"1.168236370","rc":[{"batl":[[0,3,2.27],[1,3,0]],"ltp":1.09,"tv":854.36,"id":4520808}]}]}
{"op":"mcm","clk":"1009246082","pt":1580664455934,"mc":[{"id":"1.168236370","rc":[{"batl":[[0,1.03,1244.08],[1,3,2.27]],"ltp":1.09,"tv":854.36,"id":4520808},{"batb":[[0,29,2.42],[1,14.5,6.14],[2,7.8,9.84]],"ltp":12.5,"tv":687.5,"id":8284479}]}]}
{"op":"mcm","clk":"1009246246","pt":1580664457051,"mc":[{"id":"1.168236370","rc":[{"batb":[[2,4.4,375.46]],"ltp":12.5,"tv":687.5,"id":8284479}]}]}
{"op":"mcm","clk":"1009248043","pt":1580664469053,"mc":[{"id":"1.168236370","rc":[{"trd":[[1.03,1.18]],"batl":[[0,1.03,1243.49]],"ltp":1.03,"tv":855.54,"id":4520808}],"tv":1543.05}]}
{"op":"mcm","clk":"1009248380","pt":1580664471534,"mc":[{"id":"1.168236370","rc":[{"trd":[[1.02,0.4]],"batb":[[0,1.02,805.63]],"ltp":1.02,"tv":855.94,"id":4520808}],"tv":1543.44}]}
{"op":"mcm","clk":"1009248971","pt":1580664475156,"mc":[{"id":"1.168236370","rc":[{"batb":[[0,1.01,10.51],[1,1.01,0]],"batl":[[0,3,2.27],[1,3,0]],"ltp":1.02,"tv":855.94,"id":4520808}]}]}
{"op":"mcm","clk":"1009248998","pt":1580664475335,"mc":[{"id":"1.168236370","rc":[{"batb":[[0,14.5,6.14],[1,4.4,375.46],[2,1.01,10.51]],"ltp":12.5,"tv":687.5,"id":8284479}]}]}
{"op":"mcm","clk":"1009249246","pt":1580664476929,"mc":[{"id":"1.168236370","rc":[{"batb":[[1,1.01,10.51],[2,1.01,0]],"ltp":12.5,"tv":687.5,"id":8284479}]}]}
{"op":"mcm","clk":"1009249419","pt":1580664478148,"mc":[{"id":"1.168236370","rc":[{"batl":[[0,1.06,828.39],[1,1.07,376.92],[2,3,2.27]],"ltp":1.02,"tv":855.94,"id":4520808}]}]}
{"op":"mcm","clk":"1009249491","pt":1580664478635,"mc":[{"id":"1.168236370","rc":[{"batl":[[0,3,2.27],[1,1.07,0],[2,3,0]],"ltp":1.02,"tv":855.94,"id":4520808}]}]}
{"op":"mcm","clk":"1009249907","pt":1580664481738,"mc":[{"id":"1.168236370","rc":[{"batb":[[0,1.02,1256.28],[1,1.01,10.51]],"batl":[[0,1.03,490.24],[1,1.04,746.59],[2,3,2.27]],"ltp":1.02,"tv":855.94,"id":4520808}]}]}
{"op":"mcm","clk":"1009250136","pt":1580664483217,"mc":[{"id":"1.168236370","rc":[{"batb":[[1,4.4,369.4],[2,1.01,10.51]],"batl":[[0,520,35.52]],"ltp":12.5,"tv":687.5,"id":8284479}]}]}
{"op":"mcm","clk":"1009250551","pt":1580664486141,"mc":[{"id":"1.168236370","rc":[{"batb":[[0,1.01,10.51],[1,1.01,0]],"batl":[[0,3,2.27],[1,1.04,0],[2,3,0]],"ltp":1.02,"tv":855.94,"id":4520808}]}]}
{"op":"mcm","clk":"1009250729","pt":1580664487365,"mc":[{"id":"1.168236370","rc":[{"batb":[[1,1.01,10.51],[2,1.01,0]],"ltp":12.5,"tv":687.5,"id":8284479}]}]}
{"op":"mcm","clk":"1009251008","pt":1580664489057,"mc":[{"id":"1.168236370","rc":[{"batl":[[0,1.06,828.39],[1,1.07,376.92],[2,3,2.27]],"ltp":1.02,"tv":855.94,"id":4520808}]}]}
{"op":"mcm","clk":"1009252364","pt":1580664497540,"mc":[{"id":"1.168236370","rc":[{"batl":[[0,3,2.27],[1,1.07,0],[2,3,0]],"ltp":1.02,"tv":855.94,"id":4520808}]}]}
{"op":"mcm","clk":"1009252787","pt":1580664500240,"mc":[{"id":"1.168236370","rc":[{"trd":[[1.01,21.02]],"batl":[[0,1.01,1258.21],[1,3,2.27]],"ltp":1.01,"tv":876.96,"id":4520808}],"tv":1564.46}]}
{"op":"mcm","clk":"1009252924","pt":1580664501051,"mc":[{"id":"1.168236370","rc":[{"batb":[[0,30,2.87]],"ltp":12.5,"tv":687.5,"id":8284479}]}]}
{"op":"mcm","clk":"1009253270","pt":1580664502938,"mc":[{"id":"1.168236370","rc":[{"batb":[[1,4.8,367.63],[2,1.01,10.51]],"ltp":12.5,"tv":687.5,"id":8284479}]}]}
{"op":"mcm","clk":"1009254243","pt":1580664509242,"mc":[{"id":"1.168236370","rc":[{"batl":[[0,1.01,1358.21]],"ltp":1.01,"tv":876.96,"id":4520808}]}]}
{"op":"mcm","clk":"1009254497","pt":1580664511010,"mc":[{"id":"1.168236370","rc":[{"trd":[[1.01,42.08]],"batl":[[0,1.01,1347.68]],"ltp":1.01,"tv":898.02,"id":4520808}],"tv":1585.52}]}
{"op":"mcm","clk":"1009255120","pt":1580664515175,"mc":[{"id":"1.168236370","rc":[{"batl":[[0,1.01,100]],"ltp":1.01,"tv":898.02,"id":4520808}]}]}
{"op":"mcm","clk":"1009255380","pt":1580664516861,"mc":[{"id":"1.168236370","rc":[{"batb":[[1,1.01,10.51],[2,1.01,0]],"ltp":12.5,"tv":687.5,"id":8284479}]}]}
{"op":"mcm","clk":"1009255556","pt":1580664518182,"mc":[{"id":"1.168236370","rc":[{"batl":[[1,1.02,1256.28],[2,3,2.27]],"ltp":1.01,"tv":898.02,"id":4520808}]}]}
{"op":"mcm","clk":"1009255707","pt":1580664519202,"mc":[{"id":"1.168236370","rc":[{"batl":[[1,3,2.27],[2,3,0]],"ltp":1.01,"tv":898.02,"id":4520808}]}]}
{"op":"mcm","clk":"1009255978","pt":1580664521144,"mc":[{"id":"1.168236370","rc":[{"batl":[[0,1.01,1368.72]],"ltp":1.01,"tv":898.02,"id":4520808}]}]}
{"op":"mcm","clk":"1009256207","pt":1580664522676,"mc":[{"id":"1.168236370","rc":[{"batb":[[1,4.7,374.21],[2,1.01,10.51]],"ltp":12.5,"tv":687.5,"id":8284479}]}]}
{"op":"mcm","clk":"1009256444","pt":1580664524172,"mc":[{"id":"1.168236370","rc":[{"batl":[[0,1.01,100]],"ltp":1.01,"tv":898.02,"id":4520808}]}]}
{"op":"mcm","clk":"1009256640","pt":1580664525455,"mc":[{"id":"1.168236370","rc":[{"batb":[[1,1.01,10.51],[2,1.01,0]],"ltp":12.5,"tv":687.5,"id":8284479}]}]}
{"op":"mcm","clk":"1009256885","pt":1580664527143,"mc":[{"id":"1.168236370","rc":[{"batl":[[1,1.02,1256.28],[2,3,2.27]],"ltp":1.01,"tv":898.02,"id":4520808}]}]}
{"op":"mcm","clk":"1009257350","pt":1580664530169,"mc":[{"id":"1.168236370","rc":[{"trd":[[1.01,242.08]],"batb":[[0,1.01,1168.72]],"batl":[[0,1.02,1256.28],[1,3,2.27],[2,3,0]],"ltp":1.01,"tv":1098.02,"id":4520808}],"tv":1785.52}]}
{"op":"mcm","clk":"1009257503","pt":1580664531093,"mc":[{"id":"1.168236370","rc":[{"batb":[[0,1.01,1336.76]],"ltp":1.01,"tv":1098.02,"id":4520808},{"batb":[[1,16.5,4.33],[2,1.01,10.51]],"ltp":12.5,"tv":687.5,"id":8284479}]}]}
{"op":"mcm","clk":"1009257646","pt":1580664532093,"mc":[{"id":"1.168236370","rc":[{"batb":[[2,4.6,368.39]],"ltp":12.5,"tv":687.5,"id":8284479}]}]}
{"op":"mcm","clk":"1009257829","pt":1580664533196,"mc":[{"id":"1.168236370","rc":[{"batb":[[0,1.01,1436.76]],"batl":[[0,1.02,1298.29]],"ltp":1.01,"tv":1098.02,"id":4520808}]}]}
{"op":"mcm","clk":"1009260289","pt":1580664550019,"mc":[{"id":"1.168236370","rc":[{"batb":[[0,1.01,168.04]],"batl":[[0,1.02,42.01]],"ltp":1.01,"tv":1098.02,"id":4520808},{"batb":[[0,16.5,4.33],[1,4.6,368.39],[2,1.01,10.51]],"ltp":12.5,"tv":687.5,"id":8284479}]}]}
{"op":"mcm","clk":"1009260424","pt":1580664551004,"mc":[{"id":"1.168236370","rc":[{"batb":[[1,1.01,10.51],[2,1.01,0]],"ltp":12.5,"tv":687.5,"id":8284479}]}]}
{"op":"mcm","clk":"1009260597","pt":1580664552010,"mc":[{"id":"1.168236370","rc":[{"batl":[[0,3,2.27],[1,3,0]],"ltp":1.01,"tv":1098.02,"id":4520808}]}]}
{"op":"mcm","clk":"1009261058","pt":1580664555218,"mc":[{"id":"1.168236370","rc":[{"batb":[[0,1.02,322.07],[1,1.01,943.45]],"batl":[[0,1.03,1244.08],[1,3,2.27]],"ltp":1.01,"tv":1098.02,"id":4520808}]}]}
{"op":"mcm","clk":"1009261321","pt":1580664557235,"mc":[{"id":"1.168236370","rc":[{"batb":[[1,4.4,375.46],[2,1.01,10.51]],"ltp":12.5,"tv":687.5,"id":8284479}]}]}
{"op":"mcm","clk":"1009261730","pt":1580664560112,"mc":[{"id":"1.168236370","rc":[{"batl":[[0,3,2.27],[1,3,0]],"ltp":1.01,"tv":1098.02,"id":4520808}]}]}
{"op":"mcm","clk":"1009261945","pt":1580664561603,"mc":[{"id":"1.168236370","rc":[{"batb":[[1,1.01,10.51],[2,1.01,0]],"ltp":12.5,"tv":687.5,"id":8284479}]}]}
{"op":"mcm","clk":"1009262147","pt":1580664563027,"mc":[{"id":"1.168236370","rc":[{"batl":[[0,1.05,1027.14],[1,1.06,191.42],[2,3,2.27]],"ltp":1.01,"tv":1098.02,"id":4520808}]}]}
{"op":"mcm","clk":"1009265345","pt":1580664584032,"mc":[{"id":"1.168236370","rc":[{"batl":[[0,3,2.27],[1,1.06,0],[2,3,0]],"ltp":1.01,"tv":1098.02,"id":4520808}]}]}
{"op":"mcm","clk":"1009265466","pt":1580664584936,"mc":[{"id":"1.168236370","rc":[{"batb":[[0,1.01,10.51],[1,1.01,0]],"ltp":12.5,"tv":687.5,"id":8284479}]}]}
{"op":"mcm","clk":"1009265584","pt":1580664585791,"mc":[{"id":"1.168236370","marketDefinition":{"bspMarket":false,"turnInPlayEnabled":true,"persistenceEnabled":true,"marketBaseRate":5.0,"eventId":"29681838","eventTypeId":"2","numberOfWinners":1,"bettingType":"ODDS","marketType":"SET_WINNER","marketTime":"2020-02-02T16:35:00.000Z","suspendTime":"2020-02-02T16:35:00.000Z","bspReconciled":false,"complete":true,"inPlay":true,"crossMatching":true,"runnersVoidable":false,"numberOfActiveRunners":2,"betDelay":3,"status":"SUSPENDED","runners":[{"status":"ACTIVE","sortPriority":1,"id":4520808,"name":"Facundo Bagnis"},{"status":"ACTIVE","sortPriority":2,"id":8284479,"name":"Federico Gaio"}],"regulators":["MR_INT"],"countryCode":"AR","discountAllowed":true,"timezone":"UTC","openDate":"2020-02-02T16:35:00.000Z","version":3150044438,"name":"Set 1 Winner","eventName":"Bagnis v Gaio"}}]}
{"op":"mcm","clk":"1009270782","pt":1580664619103,"mc":[{"id":"1.168236370","tv":0.0}]}
{"op":"mcm","clk":"1009270911","pt":1580664619947,"mc":[{"id":"1.168236370","marketDefinition":{"bspMarket":false,"turnInPlayEnabled":true,"persistenceEnabled":true,"marketBaseRate":5.0,"eventId":"29681838","eventTypeId":"2","numberOfWinners":1,"bettingType":"ODDS","marketType":"SET_WINNER","marketTime":"2020-02-02T16:35:00.000Z","suspendTime":"2020-02-02T16:35:00.000Z","bspReconciled":false,"complete":true,"inPlay":true,"crossMatching":false,"runnersVoidable":false,"numberOfActiveRunners":0,"betDelay":3,"status":"CLOSED","settledTime":"2020-02-02T17:30:17.000Z","runners":[{"status":"WINNER","sortPriority":1,"id":4520808,"name":"Facundo Bagnis"},{"status":"LOSER","sortPriority":2,"id":8284479,"name":"Federico Gaio"}],"regulators":["MR_INT"],"countryCode":"AR","discountAllowed":true,"timezone":"UTC","openDate":"2020-02-02T16:35:00.000Z","version":3150057283,"name":"Set 1 Winner","eventName":"Bagnis v Gaio"}}]}
