{"op":"mcm","clk":"1002113593","pt":1580590610212,"mc":[{"id":"1.168236369","marketDefinition":{"bspMarket":false,"turnInPlayEnabled":true,"persistenceEnabled":true,"marketBaseRate":5.0,"eventId":"29681838","eventTypeId":"2","numberOfWinners":1,"bettingType":"ODDS","marketType":"SET_BETTING","marketTime":"2020-02-02T16:00:00.000Z","suspendTime":"2020-02-02T16:00:00.000Z","bspReconciled":false,"complete":true,"inPlay":false,"crossMatching":false,"runnersVoidable":false,"numberOfActiveRunners":4,"betDelay":0,"status":"OPEN","runners":[{"status":"ACTIVE","sortPriority":1,"id":13117300,"name":"Bagnis 2-0"},{"status":"ACTIVE","sortPriority":2,"id":13117301,"name":"Bagnis 2-1"},{"status":"ACTIVE","sortPriority":3,"id":13117373,"name":"Gaio 2-0"},{"status":"ACTIVE","sortPriority":4,"id":13117374,"name":"Gaio 2-1"}],"regulators":["MR_INT"],"countryCode":"AR","discountAllowed":false,"timezone":"UTC","openDate":"2020-02-02T16:00:00.000Z","version":3147446751,"name":"Set Betting","eventName":"Bagnis v Gaio"}}]}
{"op":"mcm","clk":"1002113713","pt":1580590611242,"mc":[{"id":"1.168236369","marketDefinition":{"bspMarket":false,"turnInPlayEnabled":true,"persistenceEnabled":true,"marketBaseRate":5.0,"eventId":"29681838","eventTypeId":"2","numberOfWinners":1,"bettingType":"ODDS","marketType":"SET_BETTING","marketTime":"2020-02-02T16:00:00.000Z","suspendTime":"2020-02-02T16:00:00.000Z","bspReconciled":false,"complete":true,"inPlay":false,"crossMatching":false,"runnersVoidable":false,"numberOfActiveRunners":4,"betDelay":0,"status":"OPEN","runners":[{"status":"ACTIVE","sortPriority":1,"id":13117300,"name":"Bagnis 2-0"},{"status":"ACTIVE","sortPriority":2,"id":13117301,"name":"Bagnis 2-1"},{"status":"ACTIVE","sortPriority":3,"id":13117373,"name":"Gaio 2-0"},{"status":"ACTIVE","sortPriority":4,"id":13117374,"name":"Gaio 2-1"}],"regulators":["MR_INT"],"countryCode":"AR","discountAllowed":false,"timezone":"UTC","openDate":"2020-02-02T16:00:00.000Z","version":3147446751,"name":"Set Betting","eventName":"Bagnis v Gaio"}}]}
{"op":"mcm","clk":"1002113926","pt":1580590613250,"mc":[{"id":"1.168236369","marketDefinition":{"bspMarket":false,"turnInPlayEnabled":true,"persistenceEnabled":true,"marketBaseRate":5.0,"eventId":"29681838","eventTypeId":"2","numberOfWinners":1,"bettingType":"ODDS","marketType":"SET_BETTING","marketTime":"2020-02-02T16:00:00.000Z","suspendTime":"2020-02-02T16:00:00.000Z","bspReconciled":false,"complete":true,"inPlay":false,"crossMatching":false,"runnersVoidable":false,"numberOfActiveRunners":4,"betDelay":0,"status":"OPEN","runners":[{"status":"ACTIVE","sortPriority":1,"id":13117300,"name":"Bagnis 2-0"},{"status":"ACTIVE","sortPriority":2,"id":13117301,"name":"Bagnis 2-1"},{"status":"ACTIVE","sortPriority":3,"id":13117373,"name":"Gaio 2-0"},{"status":"ACTIVE","sortPriority":4,"id":13117374,"name":"Gaio 2-1"}],"regulators":["MR_INT"],"countryCode":"AR","discountAllowed":true,"timezone":"UTC","openDate":"2020-02-02T16:00:00.000Z","version":3147446751,"name":"Set Betting","eventName":"Bagnis v Gaio"}}]}
{"op":"mcm","clk":"1002548565","pt":1580595201242,"mc":[{"id":"1.168236369","rc":[{"batb":[[0,1.02,2]],"ltp":0.0,"tv":0.0,"id":13117301},{"batb":[[0,1.02,2]],"ltp":0.0,"tv":0.0,"id":13117300},{"batb":[[0,1.02,2]],"ltp":0.0,"tv":0.0,"id":13117373},{"batb":[[0,1.02,2]],"ltp":0.0,"tv":0.0,"id":13117374}]}]}
{"op":"mcm","clk":"1003084143","pt":1580602759997,"mc":[{"id":"1.168236369","rc":[{"batb":[[1,1.01,2.53]],"ltp":0.0,"tv":0.0,"id":13117301},{"batb":[[1,1.01,2.53]],"ltp":0.0,"tv":0.0,"id":13117300},{"batb":[[1,1.01,2.53]],"ltp":0.0,"tv":0.0,"id":13117373},{"batb":[[1,1.01,2.53]],"ltp":0.0,"tv":0.0,"id":13117374}]}]}
{"op":"mcm","clk":"1003084232","pt":1580602761087,"mc":[{"id":"1.168236369","rc":[{"batb":[[1,1.01,0.51]],"ltp":0.0,"tv":0.0,"id":13117301},{"batb":[[1,1.01,0.51]],"ltp":0.0,"tv":0.0,"id":13117300},{"batb":[[1,1.01,0.51]],"ltp":0.0,"tv":0.0,"id":13117373},{"batb":[[1,1.01,0.51]],"ltp":0.0,"tv":0.0,"id":13117374}]}]}
{"op":"mcm","clk":"1003143057","pt":1580603524150,"mc":[{"id":"1.168236369","rc":[{"batb":[[1,1.01,3.04]],"ltp":0.0,"tv":0.0,"id":13117301},{"batb":[[1,1.01,3.04]],"ltp":0.0,"tv":0.0,"id":13117300},{"batb":[[1,1.01,3.04]],"ltp":0.0,"tv":0.0,"id":13117373},{"batb":[[1,1.01,3.04]],"ltp":0.0,"tv":0.0,"id":13117374}]}]}
{"op":"mcm","clk":"1003143159","pt":1580603525188,"mc":[{"id":"1.168236369","rc":[{"batb":[[1,1.01,1.01]],"ltp":0.0,"tv":0.0,"id":13117301},{"batb":[[1,1.01,1.01]],"ltp":0.0,"tv":0.0,"id":13117300},{"batb":[[1,1.01,1.01]],"ltp":0.0,"tv":0.0,"id":13117373},{"batb":[[1,1.01,1.01]],"ltp":0.0,"tv":0.0,"id":13117374}]}]}
{"op":"mcm","clk":"1003541174","pt":1580609252952,"mc":[{"id":"1.168236369","rc":[{"batb":[[0,2.34,30.29],[1,1.02,2],[2,1.01,1.01]],"ltp":0.0,"tv":0.0,"id":13117300}]}]}
{"op":"mcm","clk":"1004794566","pt":1580637491702,"mc":[{"id":"1.168236369","rc":[{"batb":[[0,2.46,30.29]],"ltp":0.0,"tv":0.0,"id":13117300}]}]}
{"op":"mcm","clk":"1007200961","pt":1580653550578,"mc":[{"id":"1.168236369","rc":[{"batb":[[0,1.03,137],[1,1.02,2],[2,1.01,1.01]],"ltp":0.0,"tv":0.0,"id":13117301},{"batb":[[0,2.48,6],[1,2.46,30.29],[2,1.02,2]],"ltp":0.0,"tv":0.0,"id":13117300},{"batb":[[0,1.03,137],[1,1.02,2],[2,1.01,1.01]],"ltp":0.0,"tv":0.0,"id":13117373},{"batb":[[0,1.03,137],[1,1.02,2],[2,1.01,1.01]],"ltp":0.0,"tv":0.0,"id":13117374}]}]}
{"op":"mcm","clk":"1007204688","pt":1580653576189,"mc":[{"id":"1.168236369","marketDefinition":{"bspMarket":false,"turnInPlayEnabled":true,"persistenceEnabled":true,"marketBaseRate":5.0,"eventId":"29681838","eventTypeId":"2","numberOfWinners":1,"bettingType":"ODDS","marketType":"SET_BETTING","marketTime":"2020-02-02T16:00:00.000Z","suspendTime":"2020-02-02T16:00:00.000Z","bspReconciled":false,"complete":true,"inPlay":false,"crossMatching":true,"runnersVoidable":false,"numberOfActiveRunners":4,"betDelay":0,"status":"OPEN","runners":[{"status":"ACTIVE","sortPriority":1,"id":13117300,"name":"Bagnis 2-0"},{"status":"ACTIVE","sortPriority":2,"id":13117301,"name":"Bagnis 2-1"},{"status":"ACTIVE","sortPriority":3,"id":13117373,"name":"Gaio 2-0"},{"status":"ACTIVE","sortPriority":4,"id":13117374,"name":"Gaio 2-1"}],"regulators":["MR_INT"],"countryCode":"AR","discountAllowed":true,"timezone":"UTC","openDate":"2020-02-02T16:00:00.000Z","version":3147446751,"name":"Set Betting","eventName":"Bagnis v Gaio"}}]}
{"op":"mcm","clk":"1007341007","pt":1580654400500,"mc":[{"id":"1.168236369","rc":[{"batl":[[0,5.2,4]],"ltp":0.0,"tv":0.0,"id":13117301},{"batl":[[0,3.2,5]],"ltp":0.0,"tv":0.0,"id":13117300},{"batl":[[0,3.7,5]],"ltp":0.0,"tv":0.0,"id":13117373},{"batl":[[0,5.5,4]],"ltp":0.0,"tv":0.0,"id":13117374}]}]}
{"op":"mcm","clk":"1007399680","pt":1580654774205,"mc":[{"id":"1.168236369","rc":[{"batb":[[1,1.02,2],[2,1.01,1.01]],"ltp":0.0,"tv":0.0,"id":13117300}]}]}
{"op":"mcm","clk":"1007506949","pt":1580655623425,"mc":[{"id":"1.168236369","rc":[{"batb":[[0,4.3,2],[1,1.03,137],[2,1.02,2]],"ltp":0.0,"tv":0.0,"id":13117301},{"batb":[[0,2.82,2],[1,2.48,6],[2,1.02,2]],"ltp":0.0,"tv":0.0,"id":13117300},{"batb":[[0,3.2,2],[1,1.03,137],[2,1.02,2]],"ltp":0.0,"tv":0.0,"id":13117373},{"batb":[[0,4.5,2],[1,1.03,137],[2,1.02,2]],"ltp":0.0,"tv":0.0,"id":13117374}]}]}
{"op":"mcm","clk":"1007628880","pt":1580656223099,"mc":[{"id":"1.168236369","rc":[{"batb":[[0,1.03,137],[1,1.02,2],[2,1.01,1.01]],"ltp":0.0,"tv":0.0,"id":13117301},{"batb":[[0,2.48,6],[1,1.02,2],[2,1.01,1.01]],"ltp":0.0,"tv":0.0,"id":13117300},{"batb":[[0,1.03,137],[1,1.02,2],[2,1.01,1.01]],"ltp":0.0,"tv":0.0,"id":13117373},{"batb":[[0,1.03,137],[1,1.02,2],[2,1.01,1.01]],"ltp":0.0,"tv":0.0,"id":13117374}]}]}
{"op":"mcm","clk":"1007629200","pt":1580656224521,"mc":[{"id":"1.168236369","rc":[{"batb":[[0,4.3,2],[1,1.03,137],[2,1.02,2]],"ltp":0.0,"tv":0.0,"id":13117301},{"batb":[[0,2.82,2],[1,2.48,6],[2,1.02,2]],"ltp":0.0,"tv":0.0,"id":13117300},{"batb":[[0,3.2,2],[1,1.03,137],[2,1.02,2]],"ltp":0.0,"tv":0.0,"id":13117373},{"batb":[[0,4.5,2],[1,1.03,137],[2,1.02,2]],"ltp":0.0,"tv":0.0,"id":13117374}]}]}
{"op":"mcm","clk":"1007674401","pt":1580656412835,"mc":[{"id":"1.168236369","rc":[{"batb":[[0,4.4,2.02],[1,4.3,2],[2,1.03,137]],"ltp":0.0,"tv":0.0,"id":13117301},{"batb":[[0,2.84,2.02],[1,2.82,2],[2,2.48,6]],"ltp":0.0,"tv":0.0,"id":13117300},{"batb":[[0,3.25,2.02],[1,3.2,2],[2,1.03,137]],"ltp":0.0,"tv":0.0,"id":13117373}]}]}
{"op":"mcm","clk":"1007712766","pt":1580656577808,"mc":[{"id":"1.168236369","rc":[{"batl":[[0,5.3,4]],"ltp":0.0,"tv":0.0,"id":13117301},{"batl":[[0,3.3,5]],"ltp":0.0,"tv":0.0,"id":13117300},{"batl":[[0,3.55,5]],"ltp":0.0,"tv":0.0,"id":13117373}]}]}
{"op":"mcm","clk":"1007769517","pt":1580656824147,"mc":[{"id":"1.168236369","rc":[{"batb":[[1,1.03,137],[2,1.02,2]],"ltp":0.0,"tv":0.0,"id":13117301},{"batb":[[1,2.48,6],[2,1.02,2]],"ltp":0.0,"tv":0.0,"id":13117300},{"batb":[[0,1.03,137],[1,1.02,2],[2,1.01,1.01]],"ltp":0.0,"tv":0.0,"id":13117374}]}]}
{"op":"mcm","clk":"1007769560","pt":1580656824323,"mc":[{"id":"1.168236369","rc":[{"batb":[[1,1.03,137],[2,1.02,2]],"ltp":0.0,"tv":0.0,"id":13117373}]}]}
{"op":"mcm","clk":"1007878552","pt":1580657304128,"mc":[{"id":"1.168236369","rc":[{"batl":[[0,3.25,5]],"ltp":0.0,"tv":0.0,"id":13117300},{"batl":[[0,3.65,5]],"ltp":0.0,"tv":0.0,"id":13117373},{"batl":[[0,5.6,4]],"ltp":0.0,"tv":0.0,"id":13117374}]}]}
{"op":"mcm","clk":"1007967798","pt":1580657701836,"mc":[{"id":"1.168236369","rc":[{"batb":[[0,4.4,2],[1,1.03,137],[2,1.02,2]],"ltp":0.0,"tv":0.0,"id":13117374}]}]}
{"op":"mcm","clk":"1007973819","pt":1580657728760,"mc":[{"id":"1.168236369","rc":[{"batl":[[0,3.6,5]],"ltp":0.0,"tv":0.0,"id":13117373},{"batl":[[0,5.5,4]],"ltp":0.0,"tv":0.0,"id":13117374}]}]}
{"op":"mcm","clk":"1008105605","pt":1580658301113,"mc":[{"id":"1.168236369","rc":[{"batb":[[0,1.03,137],[1,1.02,2],[2,1.01,1.01]],"ltp":0.0,"tv":0.0,"id":13117374}]}]}
{"op":"mcm","clk":"1008137638","pt":1580658454136,"mc":[{"id":"1.168236369","rc":[{"batb":[[1,1.02,2],[2,1.01,1.01]],"ltp":0.0,"tv":0.0,"id":13117301},{"batb":[[1,1.02,2],[2,1.01,1.01]],"ltp":0.0,"tv":0.0,"id":13117300},{"batb":[[1,1.02,2],[2,1.01,1.01]],"ltp":0.0,"tv":0.0,"id":13117373},{"batb":[[0,1.02,2],[1,1.01,1.01],[2,1.01,0]],"ltp":0.0,"tv":0.0,"id":13117374}]}]}
{"op":"mcm","clk":"1008138348","pt":1580658457617,"mc":[{"id":"1.168236369","rc":[{"batb":[[0,4.5,5],[1,4.4,2.02],[2,1.02,2]],"ltp":0.0,"tv":0.0,"id":13117301},{"batb":[[0,2.86,6],[1,2.84,2.02],[2,1.02,2]],"ltp":0.0,"tv":0.0,"id":13117300},{"batb":[[0,3.25,7.02]],"ltp":0.0,"tv":0.0,"id":13117373},{"batb":[[0,1.03,137],[1,1.02,2],[2,1.01,1.01]],"ltp":0.0,"tv":0.0,"id":13117374}]}]}
{"op":"mcm","clk":"1008150522","pt":1580658518302,"mc":[{"id":"1.168236369","rc":[{"batl":[[0,5.3,4]],"ltp":0.0,"tv":0.0,"id":13117301},{"batl":[[0,3.3,5]],"ltp":0.0,"tv":0.0,"id":13117300},{"batl":[[0,3.55,5]],"ltp":0.0,"tv":0.0,"id":13117373},{"batl":[[0,5.4,4]],"ltp":0.0,"tv":0.0,"id":13117374}]}]}
{"op":"mcm","clk":"1008280601","pt":1580659302802,"mc":[{"id":"1.168236369","marketDefinition":{"bspMarket":false,"turnInPlayEnabled":true,"persistenceEnabled":true,"marketBaseRate":5.0,"eventId":"29681838","eventTypeId":"2","numberOfWinners":1,"bettingType":"ODDS","marketType":"SET_BETTING","marketTime":"2020-02-02T16:15:00.000Z","suspendTime":"2020-02-02T16:15:00.000Z","bspReconciled":false,"complete":true,"inPlay":false,"crossMatching":true,"runnersVoidable":false,"numberOfActiveRunners":4,"betDelay":0,"status":"OPEN","runners":[{"status":"ACTIVE","sortPriority":1,"id":13117300,"name":"Bagnis 2-0"},{"status":"ACTIVE","sortPriority":2,"id":13117301,"name":"Bagnis 2-1"},{"status":"ACTIVE","sortPriority":3,"id":13117373,"name":"Gaio 2-0"},{"status":"ACTIVE","sortPriority":4,"id":13117374,"name":"Gaio 2-1"}],"regulators":["MR_INT"],"countryCode":"AR","discountAllowed":true,"timezone":"UTC","openDate":"2020-02-02T16:00:00.000Z","version":3149673259,"name":"Set Betting","eventName":"Bagnis v Gaio"}}]}
{"op":"mcm","clk":"1008281157","pt":1580659305787,"mc":[{"id":"1.168236369","marketDefinition":{"bspMarket":false,"turnInPlayEnabled":true,"persistenceEnabled":true,"marketBaseRate":5.0,"eventId":"29681838","eventTypeId":"2","numberOfWinners":1,"bettingType":"ODDS","marketType":"SET_BETTING","marketTime":"2020-02-02T16:15:00.000Z","suspendTime":"2020-02-02T16:15:00.000Z","bspReconciled":false,"complete":true,"inPlay":false,"crossMatching":true,"runnersVoidable":false,"numberOfActiveRunners":4,"betDelay":0,"status":"OPEN","runners":[{"status":"ACTIVE","sortPriority":1,"id":13117300,"name":"Bagnis 2-0"},{"status":"ACTIVE","sortPriority":2,"id":13117301,"name":"Bagnis 2-1"},{"status":"ACTIVE","sortPriority":3,"id":13117373,"name":"Gaio 2-0"},{"status":"ACTIVE","sortPriority":4,"id":13117374,"name":"Gaio 2-1"}],"regulators":["MR_INT"],"countryCode":"AR","discountAllowed":true,"timezone":"UTC","openDate":"2020-02-02T16:15:00.000Z","version":3149673259,"name":"Set Betting","eventName":"Bagnis v Gaio"}}]}
{"op":"mcm","clk":"1008474745","pt":1580660203653,"mc":[{"id":"1.168236369","marketDefinition":{"bspMarket":false,"turnInPlayEnabled":true,"persistenceEnabled":true,"marketBaseRate":5.0,"eventId":"29681838","eventTypeId":"2","numberOfWinners":1,"bettingType":"ODDS","marketType":"SET_BETTING","marketTime":"2020-02-02T16:30:00.000Z","suspendTime":"2020-02-02T16:30:00.000Z","bspReconciled":false,"complete":true,"inPlay":false,"crossMatching":true,"runnersVoidable":false,"numberOfActiveRunners":4,"betDelay":0,"status":"OPEN","runners":[{"status":"ACTIVE","sortPriority":1,"id":13117300,"name":"Bagnis 2-0"},{"status":"ACTIVE","sortPriority":2,"id":13117301,"name":"Bagnis 2-1"},{"status":"ACTIVE","sortPriority":3,"id":13117373,"name":"Gaio 2-0"},{"status":"ACTIVE","sortPriority":4,"id":13117374,"name":"Gaio 2-1"}],"regulators":["MR_INT"],"countryCode":"AR","discountAllowed":true,"timezone":"UTC","openDate":"2020-02-02T16:15:00.000Z","version":3149737476,"name":"Set Betting","eventName":"Bagnis v Gaio"}}]}
{"op":"mcm","clk":"1008475458","pt":1580660206679,"mc":[{"id":"1.168236369","marketDefinition":{"bspMarket":false,"turnInPlayEnabled":true,"persistenceEnabled":true,"marketBaseRate":5.0,"eventId":"29681838","eventTypeId":"2","numberOfWinners":1,"bettingType":"ODDS","marketType":"SET_BETTING","marketTime":"2020-02-02T16:30:00.000Z","suspendTime":"2020-02-02T16:30:00.000Z","bspReconciled":false,"complete":true,"inPlay":false,"crossMatching":true,"runnersVoidable":false,"numberOfActiveRunners":4,"betDelay":0,"status":"OPEN","runners":[{"status":"ACTIVE","sortPriority":1,"id":13117300,"name":"Bagnis 2-0"},{"status":"ACTIVE","sortPriority":2,"id":13117301,"name":"Bagnis 2-1"},{"status":"ACTIVE","sortPriority":3,"id":13117373,"name":"Gaio 2-0"},{"status":"ACTIVE","sortPriority":4,"id":13117374,"name":"Gaio 2-1"}],"regulators":["MR_INT"],"countryCode":"AR","discountAllowed":true,"timezone":"UTC","openDate":"2020-02-02T16:30:00.000Z","version":3149737476,"name":"Set Betting","eventName":"Bagnis v Gaio"}}]}
{"op":"mcm","clk":"1008504988","pt":1580660331107,"mc":[{"id":"1.168236369","rc":[{"batb":[[0,2.84,2.02],[1,1.02,2],[2,1.01,1.01]],"ltp":0.0,"tv":0.0,"id":13117300}]}]}
{"op":"mcm","clk":"1008505139","pt":1580660331811,"mc":[{"id":"1.168236369","rc":[{"batb":[[0,4.4,2.02],[1,1.02,2],[2,1.01,1.01]],"ltp":0.0,"tv":0.0,"id":13117301},{"batb":[[0,3.25,2.02]],"ltp":0.0,"tv":0.0,"id":13117373},{"batb":[[0,1.02,2],[1,1.01,1.01],[2,1.01,0]],"ltp":0.0,"tv":0.0,"id":13117374}]}]}
{"op":"mcm","clk":"1008505265","pt":1580660332345,"mc":[{"id":"1.168236369","rc":[{"batb":[[0,4.5,5],[1,4.4,2.02],[2,1.02,2]],"ltp":0.0,"tv":0.0,"id":13117301},{"batb":[[0,2.86,6],[1,2.84,2.02],[2,1.02,2]],"ltp":0.0,"tv":0.0,"id":13117300},{"batb":[[0,3.3,5],[1,3.25,2.02],[2,1.02,2]],"ltp":0.0,"tv":0.0,"id":13117373},{"batb":[[0,1.03,137],[1,1.02,2],[2,1.01,1.01]],"ltp":0.0,"tv":0.0,"id":13117374}]}]}
{"op":"mcm","clk":"1008519446","pt":1580660394272,"mc":[{"id":"1.168236369","rc":[{"batl":[[0,5.1,4]],"ltp":0.0,"tv":0.0,"id":13117301},{"batl":[[0,3.15,5]],"ltp":0.0,"tv":0.0,"id":13117300},{"batl":[[0,7.6,6]],"ltp":0.0,"tv":0.0,"id":13117373},{"batl":[[0,9.6,6]],"ltp":0.0,"tv":0.0,"id":13117374}]}]}
{"op":"mcm","clk":"1008675211","pt":1580661104119,"mc":[{"id":"1.168236369","marketDefinition":{"bspMarket":false,"turnInPlayEnabled":true,"persistenceEnabled":true,"marketBaseRate":5.0,"eventId":"29681838","eventTypeId":"2","numberOfWinners":1,"bettingType":"ODDS","marketType":"SET_BETTING","marketTime":"2020-02-02T16:45:00.000Z","suspendTime":"2020-02-02T16:45:00.000Z","bspReconciled":false,"complete":true,"inPlay":false,"crossMatching":true,"runnersVoidable":false,"numberOfActiveRunners":4,"betDelay":0,"status":"OPEN","runners":[{"status":"ACTIVE","sortPriority":1,"id":13117300,"name":"Bagnis 2-0"},{"status":"ACTIVE","sortPriority":2,"id":13117301,"name":"Bagnis 2-1"},{"status":"ACTIVE","sortPriority":3,"id":13117373,"name":"Gaio 2-0"},{"status":"ACTIVE","sortPriority":4,"id":13117374,"name":"Gaio 2-1"}],"regulators":["MR_INT"],"countryCode":"AR","discountAllowed":true,"timezone":"UTC","openDate":"2020-02-02T16:30:00.000Z","version":3149796839,"name":"Set Betting","eventName":"Bagnis v Gaio"}}]}
{"op":"mcm","clk":"1008675568","pt":1580661105685,"mc":[{"id":"1.168236369","marketDefinition":{"bspMarket":false,"turnInPlayEnabled":true,"persistenceEnabled":true,"marketBaseRate":5.0,"eventId":"29681838","eventTypeId":"2","numberOfWinners":1,"bettingType":"ODDS","marketType":"SET_BETTING","marketTime":"2020-02-02T16:45:00.000Z","suspendTime":"2020-02-02T16:45:00.000Z","bspReconciled":false,"complete":true,"inPlay":false,"crossMatching":true,"runnersVoidable":false,"numberOfActiveRunners":4,"betDelay":0,"status":"OPEN","runners":[{"status":"ACTIVE","sortPriority":1,"id":13117300,"name":"Bagnis 2-0"},{"status":"ACTIVE","sortPriority":2,"id":13117301,"name":"Bagnis 2-1"},{"status":"ACTIVE","sortPriority":3,"id":13117373,"name":"Gaio 2-0"},{"status":"ACTIVE","sortPriority":4,"id":13117374,"name":"Gaio 2-1"}],"regulators":["MR_INT"],"countryCode":"AR","discountAllowed":true,"timezone":"UTC","openDate":"2020-02-02T16:45:00.000Z","version":3149796839,"name":"Set Betting","eventName":"Bagnis v Gaio"}}]}
{"op":"mcm","clk":"1008678848","pt":1580661120182,"mc":[{"id":"1.168236369","rc":[{"batb":[[0,4.4,2.02],[1,1.02,2],[2,1.01,1.01]],"ltp":0.0,"tv":0.0,"id":13117301},{"batb":[[0,2.84,2.02],[1,1.02,2],[2,1.01,1.01]],"ltp":0.0,"tv":0.0,"id":13117300},{"batb":[[0,3.25,2.02],[1,1.02,2],[2,1.01,1.01]],"ltp":0.0,"tv":0.0,"id":13117373},{"batb":[[0,1.02,2],[1,1.01,1.01],[2,1.01,0]],"ltp":0.0,"tv":0.0,"id":13117374}]}]}
{"op":"mcm","clk":"1008678970","pt":1580661120668,"mc":[{"id":"1.168236369","rc":[{"batb":[[0,4.5,5],[1,4.4,2.02],[2,1.02,2]],"ltp":0.0,"tv":0.0,"id":13117301},{"batb":[[0,2.86,6],[1,2.84,2.02],[2,1.02,2]],"ltp":0.0,"tv":0.0,"id":13117300},{"batb":[[0,3.3,5],[1,3.25,2.02],[2,1.02,2]],"ltp":0.0,"tv":0.0,"id":13117373},{"batb":[[0,1.04,104],[1,1.02,2],[2,1.01,1.01]],"ltp":0.0,"tv":0.0,"id":13117374}]}]}
{"op":"mcm","clk":"1008739976","pt":1580661402947,"mc":[{"id":"1.168236369","marketDefinition":{"bspMarket":false,"turnInPlayEnabled":true,"persistenceEnabled":true,"marketBaseRate":5.0,"eventId":"29681838","eventTypeId":"2","numberOfWinners":1,"bettingType":"ODDS","marketType":"SET_BETTING","marketTime":"2020-02-02T16:35:00.000Z","suspendTime":"2020-02-02T16:35:00.000Z","bspReconciled":false,"complete":true,"inPlay":false,"crossMatching":true,"runnersVoidable":false,"numberOfActiveRunners":4,"betDelay":0,"status":"OPEN","runners":[{"status":"ACTIVE","sortPriority":1,"id":13117300,"name":"Bagnis 2-0"},{"status":"ACTIVE","sortPriority":2,"id":13117301,"name":"Bagnis 2-1"},{"status":"ACTIVE","sortPriority":3,"id":13117373,"name":"Gaio 2-0"},{"status":"ACTIVE","sortPriority":4,"id":13117374,"name":"Gaio 2-1"}],"regulators":["MR_INT"],"countryCode":"AR","discountAllowed":true,"timezone":"UTC","openDate":"2020-02-02T16:45:00.000Z","version":3149819972,"name":"Set Betting","eventName":"Bagnis v Gaio"}}]}
{"op":"mcm","clk":"1008740299","pt":1580661404236,"mc":[{"id":"1.168236369","rc":[{"batb":[[1,4.4,19.88]],"batl":[[0,5.1,21]],"ltp":0.0,"tv":0.0,"id":13117301},{"batb":[[0,2.86,16.46]],"batl":[[0,3.15,15.31]],"ltp":0.0,"tv":0.0,"id":13117300},{"batb":[[0,3.55,15.26],[1,3.3,5],[2,3.25,2.02]],"batl":[[0,3.95,14.79],[1,7.6,6]],"ltp":0.0,"tv":0.0,"id":13117373},{"batb":[[0,4.9,13.53],[1,1.04,104],[2,1.02,2]],"batl":[[0,5.8,12.98],[1,9.6,6]],"ltp":0.0,"tv":0.0,"id":13117374}]}]}
{"op":"mcm","clk":"1008740488","pt":1580661404960,"mc":[{"id":"1.168236369","marketDefinition":{"bspMarket":false,"turnInPlayEnabled":true,"persistenceEnabled":true,"marketBaseRate":5.0,"eventId":"29681838","eventTypeId":"2","numberOfWinners":1,"bettingType":"ODDS","marketType":"SET_BETTING","marketTime":"2020-02-02T16:35:00.000Z","suspendTime":"2020-02-02T16:35:00.000Z","bspReconciled":false,"complete":true,"inPlay":false,"crossMatching":true,"runnersVoidable":false,"numberOfActiveRunners":4,"betDelay":0,"status":"OPEN","runners":[{"status":"ACTIVE","sortPriority":1,"id":13117300,"name":"Bagnis 2-0"},{"status":"ACTIVE","sortPriority":2,"id":13117301,"name":"Bagnis 2-1"},{"status":"ACTIVE","sortPriority":3,"id":13117373,"name":"Gaio 2-0"},{"status":"ACTIVE","sortPriority":4,"id":13117374,"name":"Gaio 2-1"}],"regulators":["MR_INT"],"countryCode":"AR","discountAllowed":true,"timezone":"UTC","openDate":"2020-02-02T16:35:00.000Z","version":3149819972,"name":"Set Betting","eventName":"Bagnis v Gaio"}}]}
{"op":"mcm","clk":"1008891322","pt":1580662142430,"mc":[{"id":"1.168236369","rc":[{"batb":[[2,4.3,12.6]],"batl":[[0,5.1,31.08]],"ltp":0.0,"tv":0.0,"id":13117301},{"batb":[[2,2.82,22.69]],"batl":[[1,3.2,18.48]],"ltp":0.0,"tv":0.0,"id":13117300},{"batb":[[0,3.55,31.23]],"batl":[[1,4.2,12.6],[2,7.6,6]],"ltp":0.0,"tv":0.0,"id":13117373},{"batb":[[1,4.7,10.92],[2,1.04,104]],"batl":[[0,5.8,21.38]],"ltp":0.0,"tv":0.0,"id":13117374}]}]}
{"op":"mcm","clk":"1008895958","pt":1580662172116,"mc":[{"id":"1.168236369","marketDefinition":{"bspMarket":false,"turnInPlayEnabled":true,"persistenceEnabled":true,"marketBaseRate":5.0,"eventId":"29681838","eventTypeId":"2","numberOfWinners":1,"bettingType":"ODDS","marketType":"SET_BETTING","marketTime":"2020-02-02T16:35:00.000Z","suspendTime":"2020-02-02T16:35:00.000Z","bspReconciled":false,"complete":true,"inPlay":true,"crossMatching":true,"runnersVoidable":false,"numberOfActiveRunners":4,"betDelay":3,"status":"OPEN","runners":[{"status":"ACTIVE","sortPriority":1,"id":13117300,"name":"Bagnis 2-0"},{"status":"ACTIVE","sortPriority":2,"id":13117301,"name":"Bagnis 2-1"},{"status":"ACTIVE","sortPriority":3,"id":13117373,"name":"Gaio 2-0"},{"status":"ACTIVE","sortPriority":4,"id":13117374,"name":"Gaio 2-1"}],"regulators":["MR_INT"],"countryCode":"AR","discountAllowed":true,"timezone":"UTC","openDate":"2020-02-02T16:35:00.000Z","version":3149870719,"name":"Set Betting","eventName":"Bagnis v Gaio"},"rc":[{"batb":[[0,1.01,0.51],[1,4.4,0],[2,4.3,0]],"ltp":0.0,"tv":0.0,"id":13117301},{"batb":[[0,1.01,0.51],[1,2.84,0],[2,2.82,0]],"ltp":0.0,"tv":0.0,"id":13117300},{"batb":[[0,1.01,0.51],[1,3.3,0],[2,3.25,0]],"ltp":0.0,"tv":0.0,"id":13117373},{"batb":[[0,1.01,0.51],[1,4.7,0],[2,1.04,0]],"ltp":0.0,"tv":0.0,"id":13117374}]}]}
{"op":"mcm","clk":"1008897442","pt":1580662182386,"mc":[{"id":"1.168236369","rc":[{"batb":[[0,4.3,18.41],[1,1.01,0.51]],"batl":[[0,5.1,16.84]],"ltp":0.0,"tv":0.0,"id":13117301},{"batb":[[0,3.05,22.03],[1,2.8,11.09],[2,1.01,0.51]],"batl":[[0,3.4,21.24],[1,3.65,18.1]],"ltp":0.0,"tv":0.0,"id":13117300},{"batb":[[0,3.25,18.41],[1,3.1,21.24],[2,1.01,0.51]],"batl":[[0,3.65,17.78],[1,4.1,13.93]],"ltp":0.0,"tv":0.0,"id":13117373},{"batb":[[0,4.9,13.69],[1,1.01,0.51]],"batl":[[0,5.8,12.98]],"ltp":0.0,"tv":0.0,"id":13117374}]}]}
{"op":"mcm","clk":"1008897607","pt":1580662183556,"mc":[{"id":"1.168236369","rc":[{"batb":[[1,4.2,12.6],[2,1.01,0.51]],"batl":[[0,5.1,26.92]],"ltp":0.0,"tv":0.0,"id":13117301},{"batb":[[1,2.92,21.85],[2,2.8,11.09]],"batl":[[0,3.4,38.05]],"ltp":0.0,"tv":0.0,"id":13117300},{"batb":[[0,3.35,17.64],[1,3.25,18.41],[2,3.1,21.24]],"batl":[[1,3.95,13.44],[2,4.1,13.93]],"ltp":0.0,"tv":0.0,"id":13117373},{"batb":[[1,4.6,10.92],[2,1.01,0.51]],"batl":[[0,5.7,8.4],[1,5.8,12.98]],"ltp":0.0,"tv":0.0,"id":13117374}]}]}
{"op":"mcm","clk":"1008898149","pt":1580662187004,"mc":[{"id":"1.168236369","rc":[{"batb":[[0,4.5,51.54],[1,4.4,42.64],[2,4.3,18.41]],"ltp":0.0,"tv":0.0,"id":13117301},{"batb":[[0,3.3,62.93],[1,3.25,44.43],[2,3.05,22.03]],"ltp":0.0,"tv":0.0,"id":13117300},{"batb":[[1,3.25,64.16],[2,3.2,46.33]],"ltp":0.0,"tv":0.0,"id":13117373},{"batb":[[1,4.8,43.43],[2,4.7,36.75]],"ltp":0.0,"tv":0.0,"id":13117374}]}]}
{"op":"mcm","clk":"1008898916","pt":1580662192125,"mc":[{"id":"1.168236369","rc":[{"batb":[[0,2.92,21.85],[1,2.8,11.09],[2,1.01,0.51]],"batl":[[0,3.4,16.8]],"ltp":0.0,"tv":0.0,"id":13117300},{"batb":[[1,3.1,21.24],[2,1.01,0.51]],"batl":[[0,3.95,13.44],[1,4.1,13.93],[2,4.1,0]],"ltp":0.0,"tv":0.0,"id":13117373}]}]}
{"op":"mcm","clk":"1008899078","pt":1580662193124,"mc":[{"id":"1.168236369","rc":[{"batl":[[0,5.1,16.84]],"ltp":0.0,"tv":0.0,"id":13117301},{"batb":[[0,2.8,11.09],[1,1.01,0.51],[2,1.01,0]],"batl":[[0,3.65,18.1],[1,3.65,0]],"ltp":0.0,"tv":0.0,"id":13117300},{"batb":[[0,3.1,21.24],[1,1.01,0.51],[2,1.01,0]],"batl":[[0,4.1,13.93],[1,4.1,0]],"ltp":0.0,"tv":0.0,"id":13117373},{"batl":[[0,5.8,12.98],[1,5.8,0]],"ltp":0.0,"tv":0.0,"id":13117374}]}]}
{"op":"mcm","clk":"1008899782","pt":1580662197655,"mc":[{"id":"1.168236369","rc":[{"batb":[[0,3.25,55.01],[1,3.2,46.24],[2,2.8,11.09]],"ltp":0.0,"tv":0.0,"id":13117300},{"batb":[[0,3.3,51.07],[1,3.25,44.55],[2,3.1,21.24]],"ltp":0.0,"tv":0.0,"id":13117373}]}]}
{"op":"mcm","clk":"1008900314","pt":1580662201141,"mc":[{"id":"1.168236369","rc":[{"batb":[[0,2.8,11.09],[1,1.01,0.51],[2,2.8,0]],"ltp":0.0,"tv":0.0,"id":13117300},{"batb":[[0,3.1,21.24],[1,1.01,0.51],[2,3.1,0]],"ltp":0.0,"tv":0.0,"id":13117373}]}]}
{"op":"mcm","clk":"1008900764","pt":1580662203977,"mc":[{"id":"1.168236369","rc":[{"batb":[[0,3.05,39.65],[1,3,54.49],[2,2.8,11.09]],"ltp":0.0,"tv":0.0,"id":13117300},{"batb":[[0,3.1,69.55],[1,3.05,52.21],[2,1.01,0.51]],"ltp":0.0,"tv":0.0,"id":13117373}]}]}
{"op":"mcm","clk":"1008900809","pt":1580662204271,"mc":[{"id":"1.168236369","rc":[{"batb":[[0,2.8,11.09],[1,1.01,0.51],[2,2.8,0]],"ltp":0.0,"tv":0.0,"id":13117300}]}]}
{"op":"mcm","clk":"1008901297","pt":1580662207152,"mc":[{"id":"1.168236369","rc":[{"batb":[[0,4.4,42.64],[1,4.3,18.41],[2,1.01,0.51]],"ltp":0.0,"tv":0.0,"id":13117301},{"batb":[[0,3.45,38.52],[1,2.8,11.09],[2,1.01,0.51]],"ltp":0.0,"tv":0.0,"id":13117300},{"batb":[[1,1.01,0.51],[2,1.01,0]],"ltp":0.0,"tv":0.0,"id":13117373},{"batb":[[1,4.8,35.64],[2,1.01,0.51]],"ltp":0.0,"tv":0.0,"id":13117374}]}]}
{"op":"mcm","clk":"1008901361","pt":1580662207593,"mc":[{"id":"1.168236369","rc":[{"batb":[[2,4.2,12.6]],"batl":[[0,5.1,26.92]],"ltp":0.0,"tv":0.0,"id":13117301},{"batb":[[1,3.25,18.8],[2,3.05,20.16]],"batl":[[0,3.6,15.96],[1,3.65,18.1],[2,3.85,16.05]],"ltp":0.0,"tv":0.0,"id":13117300},{"batb":[[0,3.2,18.48],[1,3.1,69.55],[2,2.96,24.08]],"batl":[[0,3.45,20.46],[1,3.7,17.15],[2,3.75,15.12]],"ltp":0.0,"tv":0.0,"id":13117373},{"batb":[[2,4.6,10.92]],"batl":[[0,5.7,21.54],[1,5.8,12.83]],"ltp":0.0,"tv":0.0,"id":13117374}]}]}
{"op":"mcm","clk":"1008901731","pt":1580662210062,"mc":[{"id":"1.168236369","rc":[{"batb":[[0,4.4,63.52],[1,4.3,62.72]],"ltp":0.0,"tv":0.0,"id":13117301},{"batb":[[1,3.4,39.57],[2,3.25,18.8]],"ltp":0.0,"tv":0.0,"id":13117300},{"batb":[[1,3.15,39.28],[2,3.1,69.55]],"ltp":0.0,"tv":0.0,"id":13117373},{"batb":[[0,4.9,42.72]],"ltp":0.0,"tv":0.0,"id":13117374}]}]}
{"op":"mcm","clk":"1008901915","pt":1580662211241,"mc":[{"id":"1.168236369","rc":[{"batb":[[0,4.4,52.13]],"ltp":0.0,"tv":0.0,"id":13117301}]}]}
{"op":"mcm","clk":"1008902237","pt":1580662213357,"mc":[{"id":"1.168236369","rc":[{"batb":[[1,3.15,57.41]],"ltp":0.0,"tv":0.0,"id":13117373},{"batb":[[0,4.9,52.79]],"ltp":0.0,"tv":0.0,"id":13117374}]}]}
{"op":"mcm","clk":"1008902997","pt":1580662218242,"mc":[{"id":"1.168236369","rc":[{"batb":[[0,3.25,18.8],[1,3.05,20.16],[2,3,22.9]],"ltp":0.0,"tv":0.0,"id":13117300},{"batb":[[1,3.1,21.24],[2,2.96,24.08]],"ltp":0.0,"tv":0.0,"id":13117373}]}]}
{"op":"mcm","clk":"1008903038","pt":1580662218556,"mc":[{"id":"1.168236369","rc":[{"batb":[[2,1.01,0.51]],"batl":[[0,5.1,16.84]],"ltp":0.0,"tv":0.0,"id":13117301},{"batb":[[0,3,22.9],[1,1.01,0.51],[2,3,0]],"batl":[[0,3.85,16.05],[1,3.65,0],[2,3.85,0]],"ltp":0.0,"tv":0.0,"id":13117300},{"batb":[[0,2.96,24.08],[1,1.01,0.51],[2,2.96,0]],"batl":[[0,3.7,17.15],[1,3.7,0],[2,3.75,0]],"ltp":0.0,"tv":0.0,"id":13117373},{"batb":[[2,1.01,0.51]],"batl":[[0,5.8,12.83],[1,5.8,0]],"ltp":0.0,"tv":0.0,"id":13117374}]}]}
{"op":"mcm","clk":"1008903424","pt":1580662221198,"mc":[{"id":"1.168236369","rc":[{"batb":[[0,3.2,62.26],[1,3.15,47.46],[2,3,22.9]],"ltp":0.0,"tv":0.0,"id":13117300},{"batb":[[0,3.05,57.97],[1,3,54.94],[2,2.96,24.08]],"ltp":0.0,"tv":0.0,"id":13117373}]}]}
{"op":"mcm","clk":"1008904290","pt":1580662226773,"mc":[{"id":"1.168236369","rc":[{"batb":[[0,2.96,24.08],[1,1.01,0.51],[2,2.96,0]],"ltp":0.0,"tv":0.0,"id":13117373}]}]}
{"op":"mcm","clk":"1008904749","pt":1580662229794,"mc":[{"id":"1.168236369","rc":[{"batb":[[0,3.35,51.48],[1,3.3,43.4],[2,2.96,24.08]],"ltp":0.0,"tv":0.0,"id":13117373}]}]}
{"op":"mcm","clk":"1008904915","pt":1580662230674,"mc":[{"id":"1.168236369","rc":[{"batl":[[0,3.35,22.03],[1,3.6,18.33]],"ltp":0.0,"tv":0.0,"id":13117300},{"batb":[[1,3.3,61.1],[2,3.1,20.93]],"batl":[[1,4.2,13.06]],"ltp":0.0,"tv":0.0,"id":13117373}]}]}
{"op":"mcm","clk":"1008905059","pt":1580662231480,"mc":[{"id":"1.168236369","rc":[{"batb":[[2,4.2,12.6]],"batl":[[0,5.1,26.92]],"ltp":0.0,"tv":0.0,"id":13117301},{"batl":[[0,3.35,39.68]],"ltp":0.0,"tv":0.0,"id":13117300},{"batb":[[0,3.4,16.8],[1,3.35,51.48],[2,3.3,61.1]],"batl":[[1,4,13.44],[2,4.2,13.06]],"ltp":0.0,"tv":0.0,"id":13117373},{"batb":[[2,4.7,10.92]],"batl":[[0,5.8,21.23]],"ltp":0.0,"tv":0.0,"id":13117374}]}]}
{"op":"mcm","clk":"1008906803","pt":1580662242017,"mc":[{"id":"1.168236369","rc":[{"batb":[[0,2.92,21.85],[1,2.74,11.8],[2,1.01,0.51]],"batl":[[0,3.35,17.64]],"ltp":0.0,"tv":0.0,"id":13117300},{"batb":[[1,3.1,20.93],[2,1.01,0.51]],"batl":[[0,4,13.44],[1,4.2,13.06],[2,4.2,0]],"ltp":0.0,"tv":0.0,"id":13117373}]}]}
{"op":"mcm","clk":"1008907000","pt":1580662243085,"mc":[{"id":"1.168236369","rc":[{"batb":[[2,1.01,0.51]],"batl":[[0,5.1,16.84]],"ltp":0.0,"tv":0.0,"id":13117301},{"batb":[[0,2.74,11.8],[1,1.01,0.51],[2,1.01,0]],"batl":[[0,3.6,18.33],[1,3.6,0]],"ltp":0.0,"tv":0.0,"id":13117300},{"batb":[[0,3.1,20.93],[1,1.01,0.51],[2,1.01,0]],"batl":[[0,4.2,13.06],[1,4.2,0]],"ltp":0.0,"tv":0.0,"id":13117373},{"batb":[[2,1.01,0.51]],"batl":[[0,5.8,12.83]],"ltp":0.0,"tv":0.0,"id":13117374}]}]}
{"op":"mcm","clk":"1008907326","pt":1580662245194,"mc":[{"id":"1.168236369","rc":[{"batb":[[0,4.4,70.38],[1,4.3,44.31]],"batl":[[0,5.2,16.6]],"ltp":0.0,"tv":0.0,"id":13117301},{"batb":[[0,2.76,11.57]],"batl":[[0,3.65,17.94]],"ltp":0.0,"tv":0.0,"id":13117300},{"batb":[[0,3.15,69.46],[1,3.1,71.43],[2,1.01,0.51]],"ltp":0.0,"tv":0.0,"id":13117373}]}]}
{"op":"mcm","clk":"1008907719","pt":1580662247849,"mc":[{"id":"1.168236369","rc":[{"batb":[[0,3.4,62.79],[1,3.35,40.73],[2,2.76,11.57]],"ltp":0.0,"tv":0.0,"id":13117300}]}]}
{"op":"mcm","clk":"1008907873","pt":1580662248906,"mc":[{"id":"1.168236369","rc":[{"batb":[[0,4.4,52.13],[1,4.3,62.56]],"batl":[[0,5.1,17.15]],"ltp":0.0,"tv":0.0,"id":13117301},{"batb":[[2,3.25,18.65]],"batl":[[1,3.85,15.89]],"ltp":0.0,"tv":0.0,"id":13117300},{"batb":[[2,2.96,24.08]],"batl":[[0,3.45,20.61],[1,3.7,17.31]],"ltp":0.0,"tv":0.0,"id":13117373}]}]}
{"op":"mcm","clk":"1008907960","pt":1580662249502,"mc":[{"id":"1.168236369","rc":[{"batb":[[2,4.2,12.6]],"batl":[[0,5.1,27.23]],"ltp":0.0,"tv":0.0,"id":13117301},{"batl":[[0,3.6,15.96],[1,3.65,17.94],[2,3.85,15.89]],"ltp":0.0,"tv":0.0,"id":13117300},{"batb":[[0,3.25,18.48],[1,3.15,69.46],[2,3.1,71.43]],"batl":[[2,3.8,14.28]],"ltp":0.0,"tv":0.0,"id":13117373},{"batb":[[2,4.7,10.92]],"batl":[[0,5.7,8.4],[1,5.8,12.83]],"ltp":0.0,"tv":0.0,"id":13117374}]}]}
{"op":"mcm","clk":"1008909188","pt":1580662258233,"mc":[{"id":"1.168236369","rc":[{"batl":[[0,3.65,17.94],[1,3.85,15.89],[2,3.85,0]],"ltp":0.0,"tv":0.0,"id":13117300}]}]}
{"op":"mcm","clk":"1008909274","pt":1580662258809,"mc":[{"id":"1.168236369","rc":[{"batb":[[0,3.05,20.16],[1,3,22.66],[2,1.01,0.51]],"batl":[[0,3.85,15.89],[1,3.85,0]],"ltp":0.0,"tv":0.0,"id":13117300},{"batb":[[1,2.96,24.08],[2,1.01,0.51]],"batl":[[0,3.7,17.31],[1,3.8,14.28],[2,3.8,0]],"ltp":0.0,"tv":0.0,"id":13117373}]}]}
{"op":"mcm","clk":"1008909650","pt":1580662261139,"mc":[{"id":"1.168236369","rc":[{"batb":[[2,1.01,0.51]],"batl":[[0,5.1,17.15]],"ltp":0.0,"tv":0.0,"id":13117301},{"batb":[[0,3,22.66],[1,1.01,0.51],[2,1.01,0]],"batl":[[0,3.55,15.96],[1,3.85,15.89]],"ltp":0.0,"tv":0.0,"id":13117300},{"batb":[[0,2.96,24.08],[1,1.01,0.51],[2,1.01,0]],"batl":[[1,3.8,0]],"ltp":0.0,"tv":0.0,"id":13117373},{"batb":[[2,1.01,0.51]],"batl":[[0,5.8,12.83],[1,5.8,0]],"ltp":0.0,"tv":0.0,"id":13117374}]}]}
{"op":"mcm","clk":"1008909784","pt":1580662262132,"mc":[{"id":"1.168236369","rc":[{"batl":[[0,3.85,15.89],[1,3.85,0]],"ltp":0.0,"tv":0.0,"id":13117300}]}]}
{"op":"mcm","clk":"1008910308","pt":1580662265849,"mc":[{"id":"1.168236369","rc":[{"batb":[[0,3.35,69.34],[1,3.3,42.21],[2,3,22.66]],"ltp":0.0,"tv":0.0,"id":13117300},{"batb":[[0,3.2,54.83],[1,3.15,48.65],[2,2.96,24.08]],"ltp":0.0,"tv":0.0,"id":13117373}]}]}
{"op":"mcm","clk":"1008910587","pt":1580662267647,"mc":[{"id":"1.168236369","rc":[{"batb":[[0,3,22.66],[1,1.01,0.51],[2,3,0]],"ltp":0.0,"tv":0.0,"id":13117300},{"batb":[[0,2.96,24.08],[1,1.01,0.51],[2,2.96,0]],"ltp":0.0,"tv":0.0,"id":13117373}]}]}
{"op":"mcm","clk":"1008911013","pt":1580662270537,"mc":[{"id":"1.168236369","rc":[{"batb":[[0,3.2,61.53],[1,3.15,47.47],[2,3,22.66]],"ltp":0.0,"tv":0.0,"id":13117300},{"batb":[[0,3.05,74.01],[1,3,54.8],[2,2.96,24.08]],"ltp":0.0,"tv":0.0,"id":13117373}]}]}
{"op":"mcm","clk":"1008911139","pt":1580662271445,"mc":[{"id":"1.168236369","rc":[{"batb":[[0,3,22.66],[1,1.01,0.51],[2,3,0]],"ltp":0.0,"tv":0.0,"id":13117300}]}]}
{"op":"mcm","clk":"1008911659","pt":1580662275218,"mc":[{"id":"1.168236369","rc":[{"batb":[[0,4.4,31.54]],"ltp":0.0,"tv":0.0,"id":13117301},{"batb":[[0,3.5,36.74],[1,3.4,16.44],[2,3.2,19.59]],"batl":[[1,4.5,22.9]],"ltp":0.0,"tv":0.0,"id":13117300},{"batb":[[0,3.05,53.03],[1,2.96,24.08],[2,2.7,12.12]],"batl":[[0,3.3,23.13],[1,3.55,19.36]],"ltp":0.0,"tv":0.0,"id":13117373},{"batl":[[0,5.7,13.3]],"ltp":0.0,"tv":0.0,"id":13117374}]}]}
{"op":"mcm","clk":"1008911762","pt":1580662275951,"mc":[{"id":"1.168236369","rc":[{"batb":[[1,4.3,75.17]],"batl":[[0,5.1,27.23]],"ltp":0.0,"tv":0.0,"id":13117301},{"batb":[[2,3.2,38.08]],"batl":[[0,3.75,15.12],[1,3.85,15.89],[2,4.5,22.9]],"ltp":0.0,"tv":0.0,"id":13117300},{"batb":[[0,3.1,19.32],[1,3.05,53.03],[2,2.96,24.08]],"batl":[[2,3.65,15.12]],"ltp":0.0,"tv":0.0,"id":13117373},{"batb":[[2,4.6,10.92]],"batl":[[0,5.6,8.4],[1,5.7,13.3]],"ltp":0.0,"tv":0.0,"id":13117374}]}]}
{"op":"mcm","clk":"1008912113","pt":1580662278230,"mc":[{"id":"1.168236369","rc":[{"batb":[[0,3.5,65.18],[1,3.45,37.69],[2,3.4,16.44]],"ltp":0.0,"tv":0.0,"id":13117300},{"batb":[[0,3.1,60.88]],"ltp":0.0,"tv":0.0,"id":13117373},{"batb":[[0,4.9,63.97]],"ltp":0.0,"tv":0.0,"id":13117374}]}]}
{"op":"mcm","clk":"1008912757","pt":1580662283035,"mc":[{"id":"1.168236369","rc":[{"batl":[[0,5,17.7],[1,5.1,27.23]],"ltp":0.0,"tv":0.0,"id":13117301},{"batl":[[1,3.8,16.29],[2,3.85,15.89]],"ltp":0.0,"tv":0.0,"id":13117300},{"batb":[[2,2.98,23.45]],"ltp":0.0,"tv":0.0,"id":13117373},{"batl":[[2,5.8,12.98]],"ltp":0.0,"tv":0.0,"id":13117374}]}]}
{"op":"mcm","clk":"1008912786","pt":1580662283248,"mc":[{"id":"1.168236369","rc":[{"batl":[[1,5.1,10.08]],"ltp":0.0,"tv":0.0,"id":13117301},{"batl":[[2,4.4,23.45]],"ltp":0.0,"tv":0.0,"id":13117300},{"batl":[[0,3.3,22.58],[1,3.55,18.96]],"ltp":0.0,"tv":0.0,"id":13117373},{"batl":[[1,5.8,12.98],[2,5.8,0]],"ltp":0.0,"tv":0.0,"id":13117374}]}]}
{"op":"mcm","clk":"1008916307","pt":1580662311404,"mc":[{"id":"1.168236369","rc":[{"batb":[[0,4.3,75.17],[1,1.01,0.51],[2,1.01,0]],"ltp":0.0,"tv":0.0,"id":13117301},{"batb":[[0,3.4,16.44],[1,3.2,18.48],[2,3.15,20.06]],"ltp":0.0,"tv":0.0,"id":13117300},{"batb":[[0,3.1,19.32],[1,2.98,23.45],[2,2.72,11.8]],"ltp":0.0,"tv":0.0,"id":13117373}]}]}
{"op":"mcm","clk":"1008916915","pt":1580662315626,"mc":[{"id":"1.168236369","rc":[{"batb":[[0,4.3,98.77],[1,4.2,46.32],[2,1.01,0.51]],"ltp":0.0,"tv":0.0,"id":13117301},{"batb":[[1,3.3,48.39],[2,3.25,43.84]],"ltp":0.0,"tv":0.0,"id":13117300},{"batb":[[2,2.82,36.31]],"ltp":0.0,"tv":0.0,"id":13117373}]}]}
{"op":"mcm","clk":"1008917784","pt":1580662321399,"mc":[{"id":"1.168236369","rc":[{"batb":[[0,3.3,48.39],[1,3.25,43.84],[2,3.2,18.48]],"batl":[[1,4.4,23.45],[2,4.4,0]],"ltp":0.0,"tv":0.0,"id":13117300},{"batb":[[1,2.82,36.31],[2,2.78,53.86]],"batl":[[0,3.55,18.96],[1,3.65,15.12],[2,3.65,0]],"ltp":0.0,"tv":0.0,"id":13117373}]}]}
{"op":"mcm","clk":"1008917925","pt":1580662322516,"mc":[{"id":"1.168236369","rc":[{"batb":[[0,4.3,86.16]],"batl":[[1,5.1,0]],"ltp":0.0,"tv":0.0,"id":13117301},{"batb":[[2,3.15,20.06]],"batl":[[0,4.4,23.45],[1,4.4,0]],"ltp":0.0,"tv":0.0,"id":13117300},{"batb":[[0,2.82,36.31],[1,2.78,53.86],[2,2.72,11.8]],"batl":[[1,3.65,0]],"ltp":0.0,"tv":0.0,"id":13117373},{"batb":[[2,1.01,0.51]],"batl":[[0,5.8,12.98],[1,5.8,0]],"ltp":0.0,"tv":0.0,"id":13117374}]}]}
{"op":"mcm","clk":"1008918294","pt":1580662325285,"mc":[{"id":"1.168236369","rc":[{"batb":[[0,4.3,62.59],[1,1.01,0.51],[2,1.01,0]],"ltp":0.0,"tv":0.0,"id":13117301},{"batb":[[0,2.72,11.8],[1,1.01,0.51],[2,2.72,0]],"ltp":0.0,"tv":0.0,"id":13117373}]}]}
{"op":"mcm","clk":"1008918668","pt":1580662328199,"mc":[{"id":"1.168236369","rc":[{"batb":[[0,4.4,36.6],[1,4.3,62.59],[2,1.01,0.51]],"ltp":0.0,"tv":0.0,"id":13117301},{"batb":[[0,3.3,32.77],[1,3.25,45.39],[2,2.72,11.8]],"ltp":0.0,"tv":0.0,"id":13117373}]}]}
{"op":"mcm","clk":"1008918793","pt":1580662329089,"mc":[{"id":"1.168236369","rc":[{"batl":[[0,3.55,19.36],[1,3.9,15.19],[2,4.4,23.45]],"ltp":0.0,"tv":0.0,"id":13117300},{"batb":[[2,3.2,19.59]],"batl":[[1,3.8,16.37]],"ltp":0.0,"tv":0.0,"id":13117373}]}]}
{"op":"mcm","clk":"1008918847","pt":1580662329507,"mc":[{"id":"1.168236369","rc":[{"batb":[[1,4.3,75.2]],"batl":[[0,5,17.55],[1,5.1,10.08]],"ltp":0.0,"tv":0.0,"id":13117301},{"batl":[[0,3.55,35.32],[2,4.4,0]],"ltp":0.0,"tv":0.0,"id":13117300},{"batb":[[1,3.25,63.87]],"batl":[[1,3.8,30.65]],"ltp":0.0,"tv":0.0,"id":13117373},{"batb":[[2,4.6,10.92]],"batl":[[0,5.6,8.4],[1,5.8,12.98]],"ltp":0.0,"tv":0.0,"id":13117374}]}]}
{"op":"mcm","clk":"1008920806","pt":1580662343231,"mc":[{"id":"1.168236369","rc":[{"batb":[[0,3.05,20.16],[1,2.98,23.45],[2,1.01,0.51]],"batl":[[0,3.55,15.96]],"ltp":0.0,"tv":0.0,"id":13117300},{"batb":[[0,3.25,18.48],[1,2.92,24.71],[2,1.01,0.51]],"batl":[[0,3.8,30.65],[1,3.8,0]],"ltp":0.0,"tv":0.0,"id":13117373}]}]}
{"op":"mcm","clk":"1008921086","pt":1580662345243,"mc":[{"id":"1.168236369","rc":[{"batb":[[1,4.3,62.59]],"batl":[[1,5.1,0]],"ltp":0.0,"tv":0.0,"id":13117301},{"batb":[[0,2.98,23.45],[1,1.01,0.51],[2,1.01,0]],"batl":[[0,3.9,15.19],[1,3.9,0]],"ltp":0.0,"tv":0.0,"id":13117300},{"batb":[[0,2.92,24.71],[1,1.01,0.51],[2,1.01,0]],"batl":[[0,3.8,16.37]],"ltp":0.0,"tv":0.0,"id":13117373},{"batb":[[2,1.01,0.51]],"batl":[[0,5.8,12.98],[1,5.8,0]],"ltp":0.0,"tv":0.0,"id":13117374}]}]}
{"op":"mcm","clk":"1008921183","pt":1580662346016,"mc":[{"id":"1.168236369","rc":[{"batb":[[0,3.15,37.71],[1,3.1,49.4],[2,2.98,23.45]],"ltp":0.0,"tv":0.0,"id":13117300},{"batb":[[0,3,73.83],[1,2.96,45.69],[2,2.92,24.71]],"ltp":0.0,"tv":0.0,"id":13117373}]}]}
{"op":"mcm","clk":"1008921410","pt":1580662347745,"mc":[{"id":"1.168236369","rc":[{"batb":[[0,2.98,23.45],[1,1.01,0.51],[2,2.98,0]],"ltp":0.0,"tv":0.0,"id":13117300},{"batb":[[0,2.92,24.71],[1,1.01,0.51],[2,2.92,0]],"ltp":0.0,"tv":0.0,"id":13117373}]}]}
{"op":"mcm","clk":"1008921883","pt":1580662351222,"mc":[{"id":"1.168236369","rc":[{"batb":[[0,3.35,54.78],[1,3.3,42.14],[2,2.98,23.45]],"ltp":0.0,"tv":0.0,"id":13117300},{"batb":[[0,3.2,76.64],[1,3.15,48.66],[2,2.92,24.71]],"ltp":0.0,"tv":0.0,"id":13117373}]}]}
{"op":"mcm","clk":"1008922019","pt":1580662352218,"mc":[{"id":"1.168236369","rc":[{"batb":[[0,2.98,23.45],[1,1.01,0.51],[2,2.98,0]],"ltp":0.0,"tv":0.0,"id":13117300},{"batb":[[0,2.92,24.71],[1,1.01,0.51],[2,2.92,0]],"ltp":0.0,"tv":0.0,"id":13117373}]}]}
{"op":"mcm","clk":"1008922422","pt":1580662355127,"mc":[{"id":"1.168236369","rc":[{"batb":[[0,3.15,37.71],[1,3.1,49.4],[2,2.98,23.45]],"ltp":0.0,"tv":0.0,"id":13117300},{"batb":[[0,3,73.83],[1,2.96,45.69],[2,2.92,24.71]],"ltp":0.0,"tv":0.0,"id":13117373}]}]}
{"op":"mcm","clk":"1008922745","pt":1580662357559,"mc":[{"id":"1.168236369","rc":[{"batb":[[0,2.98,23.45],[1,1.01,0.51],[2,2.98,0]],"ltp":0.0,"tv":0.0,"id":13117300}]}]}
{"op":"mcm","clk":"1008923262","pt":1580662361212,"mc":[{"id":"1.168236369","rc":[{"batb":[[0,3.65,29.77],[1,3.6,34.28],[2,3.5,15.66]],"batl":[[1,4.7,20.61]],"ltp":0.0,"tv":0.0,"id":13117300},{"batl":[[0,3.25,23.76],[1,3.5,19.75],[2,3.8,16.37]],"ltp":0.0,"tv":0.0,"id":13117373}]}]}
{"op":"mcm","clk":"1008923401","pt":1580662362053,"mc":[{"id":"1.168236369","rc":[{"batb":[[1,4.3,75.2]],"batl":[[1,5.1,10.08]],"ltp":0.0,"tv":0.0,"id":13117301},{"batl":[[0,3.9,29.47]],"ltp":0.0,"tv":0.0,"id":13117300},{"batb":[[0,3,94.83]],"batl":[[2,3.55,15.96]],"ltp":0.0,"tv":0.0,"id":13117373},{"batb":[[2,4.6,10.92]],"batl":[[0,5.5,9.24],[1,5.8,12.83]],"ltp":0.0,"tv":0.0,"id":13117374}]}]}
{"op":"mcm","clk":"1008924838","pt":1580662373173,"mc":[{"id":"1.168236369","rc":[{"batb":[[0,4.3,75.2],[1,1.01,0.51],[2,1.01,0]],"ltp":0.0,"tv":0.0,"id":13117301},{"batb":[[0,3.3,17.64],[1,3.2,19.43],[2,1.01,0.51]],"batl":[[0,3.9,14.28]],"ltp":0.0,"tv":0.0,"id":13117300},{"batb":[[0,3,21],[1,2.62,13.14],[2,1.01,0.51]],"batl":[[0,3.5,19.75],[1,3.55,15.96],[2,3.55,0]],"ltp":0.0,"tv":0.0,"id":13117373}]}]}
{"op":"mcm","clk":"1008925042","pt":1580662374564,"mc":[{"id":"1.168236369","rc":[{"batb":[[0,4.3,62.59]],"batl":[[1,5.1,0]],"ltp":0.0,"tv":0.0,"id":13117301},{"batb":[[0,3.2,19.43],[1,1.01,0.51],[2,1.01,0]],"batl":[[0,4.7,20.61],[1,4.7,0]],"ltp":0.0,"tv":0.0,"id":13117300},{"batb":[[0,2.62,13.14],[1,1.01,0.51],[2,1.01,0]],"batl":[[1,3.55,0]],"ltp":0.0,"tv":0.0,"id":13117373},{"batb":[[2,1.01,0.51]],"batl":[[0,5.8,12.83],[1,5.8,0]],"ltp":0.0,"tv":0.0,"id":13117374}]}]}
{"op":"mcm","clk":"1008925245","pt":1580662376162,"mc":[{"id":"1.168236369","rc":[{"batb":[[0,4.3,62.56]],"ltp":0.0,"tv":0.0,"id":13117301},{"batb":[[0,3.35,39.14],[1,3.3,42.29],[2,3.2,19.43]],"ltp":0.0,"tv":0.0,"id":13117300}]}]}
{"op":"mcm","clk":"1008925633","pt":1580662378989,"mc":[{"id":"1.168236369","rc":[{"batb":[[0,4.4,38.16],[1,4.3,62.56],[2,1.01,0.51]],"ltp":0.0,"tv":0.0,"id":13117301},{"batb":[[0,3.25,44.73],[1,3.2,47.08],[2,2.62,13.14]],"ltp":0.0,"tv":0.0,"id":13117373}]}]}
{"op":"mcm","clk":"1008925777","pt":1580662379938,"mc":[{"id":"1.168236369","rc":[{"batb":[[1,4.3,75.17]],"batl":[[0,5.1,27.47]],"ltp":0.0,"tv":0.0,"id":13117301},{"batl":[[0,3.6,18.73],[1,3.65,15.12],[2,4.1,14.08]],"ltp":0.0,"tv":0.0,"id":13117300},{"batb":[[1,3.2,65.56],[2,3.15,20.54]],"batl":[[1,3.75,31.73]],"ltp":0.0,"tv":0.0,"id":13117373},{"batb":[[2,4.6,10.92]],"batl":[[0,5.5,9.24],[1,5.8,12.83]],"ltp":0.0,"tv":0.0,"id":13117374}]}]}
{"op":"mcm","clk":"1008927788","pt":1580662394097,"mc":[{"id":"1.168236369","rc":[{"batb":[[0,4.4,26.08]],"ltp":0.0,"tv":0.0,"id":13117301},{"batb":[[0,3.1,19.32],[1,3,22.98],[2,1.01,0.51]],"batl":[[0,3.65,15.12],[1,4.1,14.08],[2,4.1,0]],"ltp":0.0,"tv":0.0,"id":13117300},{"batb":[[0,3.2,18.48],[1,2.86,10.46],[2,1.01,0.51]],"batl":[[0,3.75,31.73],[1,3.75,0]],"ltp":0.0,"tv":0.0,"id":13117373}]}]}
{"op":"mcm","clk":"1008927854","pt":1580662394572,"mc":[{"id":"1.168236369","rc":[{"batb":[[1,4.3,62.56]],"batl":[[0,5.1,17.39]],"ltp":0.0,"tv":0.0,"id":13117301},{"batb":[[0,3,22.98],[1,1.01,0.51],[2,1.01,0]],"batl":[[0,4.1,14.08],[1,4.1,0]],"ltp":0.0,"tv":0.0,"id":13117300},{"batb":[[0,2.86,10.46],[1,1.01,0.51],[2,1.01,0]],"batl":[[0,3.75,16.6]],"ltp":0.0,"tv":0.0,"id":13117373},{"batb":[[2,1.01,0.51]],"batl":[[0,5.8,12.83],[1,5.8,0]],"ltp":0.0,"tv":0.0,"id":13117374}]}]}
{"op":"mcm","clk":"1008928141","pt":1580662396675,"mc":[{"id":"1.168236369","rc":[{"batb":[[0,3.15,41.79],[1,3.1,49.31],[2,3,22.98]],"ltp":0.0,"tv":0.0,"id":13117300},{"batb":[[0,2.96,44.62],[1,2.92,47.54],[2,2.86,10.46]],"ltp":0.0,"tv":0.0,"id":13117373}]}]}
{"op":"mcm","clk":"1008928755","pt":1580662400802,"mc":[{"id":"1.168236369","rc":[{"batb":[[0,2.86,10.46],[1,1.01,0.51],[2,2.86,0]],"ltp":0.0,"tv":0.0,"id":13117373}]}]}
{"op":"mcm","clk":"1008929196","pt":1580662403701,"mc":[{"id":"1.168236369","rc":[{"batb":[[0,4.4,39.23]],"ltp":0.0,"tv":0.0,"id":13117301},{"batb":[[0,3.45,47.56],[1,3.4,40.61],[2,2.86,10.46]],"ltp":0.0,"tv":0.0,"id":13117373}]}]}
{"op":"mcm","clk":"1008929316","pt":1580662404648,"mc":[{"id":"1.168236369","rc":[{"batl":[[0,5.1,17.23]],"ltp":0.0,"tv":0.0,"id":13117301},{"batl":[[0,3.35,22.11],[1,3.6,18.41]],"ltp":0.0,"tv":0.0,"id":13117300},{"batb":[[2,3.35,17.15]],"batl":[[1,3.95,14.79]],"ltp":0.0,"tv":0.0,"id":13117373},{"batl":[[0,5.7,13.3]],"ltp":0.0,"tv":0.0,"id":13117374}]}]}
{"op":"mcm","clk":"1008929413","pt":1580662405478,"mc":[{"id":"1.168236369","rc":[{"batb":[[1,4.3,75.17]],"batl":[[0,5.1,27.31]],"ltp":0.0,"tv":0.0,"id":13117301},{"batl":[[1,3.45,16.8],[2,3.6,18.41]],"ltp":0.0,"tv":0.0,"id":13117300},{"batb":[[2,3.35,34.8]],"batl":[[1,3.95,28.24]],"ltp":0.0,"tv":0.0,"id":13117373},{"batb":[[2,4.6,10.92]],"batl":[[0,5.6,8.4],[1,5.7,13.3]],"ltp":0.0,"tv":0.0,"id":13117374}]}]}
{"op":"mcm","clk":"1008930906","pt":1580662416831,"mc":[{"id":"1.168236369","rc":[{"batb":[[1,4.3,62.56]],"batl":[[0,5.1,17.23]],"ltp":0.0,"tv":0.0,"id":13117301},{"batb":[[0,2.88,10.31],[1,1.01,0.51],[2,3,0]],"batl":[[0,3.6,18.41],[1,3.45,0],[2,3.6,0]],"ltp":0.0,"tv":0.0,"id":13117300},{"batb":[[0,3.1,20.77],[1,1.01,0.51],[2,3.35,0]],"batl":[[0,3.95,14.79],[1,3.95,0]],"ltp":0.0,"tv":0.0,"id":13117373},{"batb":[[2,1.01,0.51]],"batl":[[0,5.7,13.3],[1,5.7,0]],"ltp":0.0,"tv":0.0,"id":13117374}]}]}
{"op":"mcm","clk":"1008931270","pt":1580662419612,"mc":[{"id":"1.168236369","rc":[{"batb":[[0,2.88,25.65]],"ltp":0.0,"tv":0.0,"id":13117300}]}]}
{"op":"mcm","clk":"1008931562","pt":1580662422116,"mc":[{"id":"1.168236369","rc":[{"batb":[[0,3.15,77.35],[1,3.1,48.97],[2,2.88,25.65]],"ltp":0.0,"tv":0.0,"id":13117300},{"batb":[[0,3.4,54.01],[1,3.35,42.04],[2,3.1,20.77]],"ltp":0.0,"tv":0.0,"id":13117373}]}]}
{"op":"mcm","clk":"1008931802","pt":1580662424005,"mc":[{"id":"1.168236369","rc":[{"batb":[[0,2.88,25.65],[1,1.01,0.51],[2,2.88,0]],"ltp":0.0,"tv":0.0,"id":13117300},{"batb":[[0,3.1,20.77],[1,1.01,0.51],[2,3.1,0]],"ltp":0.0,"tv":0.0,"id":13117373}]}]}
{"op":"mcm","clk":"1008932199","pt":1580662426937,"mc":[{"id":"1.168236369","rc":[{"batb":[[0,3.05,43.66],[1,3,53.53],[2,2.88,25.65]],"ltp":0.0,"tv":0.0,"id":13117300},{"batb":[[0,3.25,45.74],[1,3.2,47.12],[2,3.1,20.77]],"ltp":0.0,"tv":0.0,"id":13117373}]}]}
{"op":"mcm","clk":"1008932488","pt":1580662429245,"mc":[{"id":"1.168236369","rc":[{"batb":[[0,2.88,25.65],[1,1.01,0.51],[2,2.88,0]],"ltp":0.0,"tv":0.0,"id":13117300}]}]}
{"op":"mcm","clk":"1008932847","pt":1580662432150,"mc":[{"id":"1.168236369","rc":[{"batb":[[0,3.35,36.17],[1,3.3,42.26],[2,2.88,25.65]],"ltp":0.0,"tv":0.0,"id":13117300}]}]}
{"op":"mcm","clk":"1008932951","pt":1580662432923,"mc":[{"id":"1.168236369","rc":[{"batb":[[2,3.25,18.96]],"batl":[[1,4.2,13.38]],"ltp":0.0,"tv":0.0,"id":13117300},{"batl":[[0,3.5,20.06],[1,3.75,16.68]],"ltp":0.0,"tv":0.0,"id":13117373},{"batl":[[0,5.8,13.06]],"ltp":0.0,"tv":0.0,"id":13117374}]}]}
{"op":"mcm","clk":"1008933026","pt":1580662433546,"mc":[{"id":"1.168236369","rc":[{"batb":[[1,4.3,75.17]],"batl":[[1,5.2,9.24]],"ltp":0.0,"tv":0.0,"id":13117301},{"batl":[[1,3.65,15.12],[2,4.2,13.38]],"ltp":0.0,"tv":0.0,"id":13117300},{"batb":[[1,3.2,65.6]],"batl":[[1,3.75,31.8]],"ltp":0.0,"tv":0.0,"id":13117373},{"batb":[[2,4.5,11.76]],"batl":[[0,5.5,9.24],[1,5.8,13.06]],"ltp":0.0,"tv":0.0,"id":13117374}]}]}
{"op":"mcm","clk":"1008933856","pt":1580662440143,"mc":[{"id":"1.168236369","rc":[{"batb":[[0,3.3,42.26],[1,3.25,18.96],[2,3.15,19.32]],"ltp":0.0,"tv":0.0,"id":13117300}]}]}
{"op":"mcm","clk":"1008934205","pt":1580662443054,"mc":[{"id":"1.168236369","rc":[{"batb":[[0,3.3,69.73],[1,3.25,62.43]],"ltp":0.0,"tv":0.0,"id":13117300},{"batb":[[0,3.25,58.21]],"ltp":0.0,"tv":0.0,"id":13117373}]}]}
{"op":"mcm","clk":"1008934458","pt":1580662444954,"mc":[{"id":"1.168236369","rc":[{"batb":[[0,4.4,28.17]],"ltp":0.0,"tv":0.0,"id":13117301},{"batb":[[0,4.9,52.79],[1,4.5,11.76],[2,1.01,0.51]],"ltp":0.0,"tv":0.0,"id":13117374}]}]}
{"op":"mcm","clk":"1008934843","pt":1580662447959,"mc":[{"id":"1.168236369","rc":[{"batb":[[0,5,22.79],[1,4.9,52.79],[2,4.5,11.76]],"ltp":0.0,"tv":0.0,"id":13117374}]}]}
{"op":"mcm","clk":"1008934963","pt":1580662448860,"mc":[{"id":"1.168236369","rc":[{"batb":[[0,4.3,62.56],[1,1.01,0.51],[2,1.01,0]],"batl":[[1,5.2,0]],"ltp":0.0,"tv":0.0,"id":13117301},{"batb":[[0,3,23.13],[1,1.01,0.51],[2,3.15,0]],"batl":[[0,4.2,13.38],[1,3.65,0],[2,4.2,0]],"ltp":0.0,"tv":0.0,"id":13117300},{"batb":[[0,2.8,11.02],[1,1.01,0.51],[2,3.1,0]],"batl":[[0,3.75,16.68],[1,3.75,0]],"ltp":0.0,"tv":0.0,"id":13117373},{"batb":[[2,1.01,0.51]],"batl":[[0,5.8,13.06],[1,5.8,0]],"ltp":0.0,"tv":0.0,"id":13117374}]}]}
{"op":"mcm","clk":"1008935654","pt":1580662454161,"mc":[{"id":"1.168236369","rc":[{"batb":[[0,4.4,26.09],[1,4.3,62.56],[2,1.01,0.51]],"ltp":0.0,"tv":0.0,"id":13117301},{"batb":[[0,3.4,42.28],[1,3.35,40.49],[2,3,23.13]],"ltp":0.0,"tv":0.0,"id":13117300},{"batb":[[0,3.2,46.47],[1,3.15,49.17],[2,2.8,11.02]],"ltp":0.0,"tv":0.0,"id":13117373}]}]}
{"op":"mcm","clk":"1008936461","pt":1580662459957,"mc":[{"id":"1.168236369","rc":[{"batb":[[0,4.3,62.56],[1,1.01,0.51],[2,1.01,0]],"ltp":0.0,"tv":0.0,"id":13117301},{"batb":[[0,3,23.13],[1,1.01,0.51],[2,3,0]],"ltp":0.0,"tv":0.0,"id":13117300},{"batb":[[0,2.8,11.02],[1,1.01,0.51],[2,2.8,0]],"ltp":0.0,"tv":0.0,"id":13117373}]}]}
{"op":"mcm","clk":"1008936869","pt":1580662463180,"mc":[{"id":"1.168236369","rc":[{"batb":[[0,4.3,78.73],[1,4.2,46.07],[2,1.01,0.51]],"ltp":0.0,"tv":0.0,"id":13117301},{"batb":[[0,3.1,49.32],[1,3.05,51.02],[2,3,23.13]],"ltp":0.0,"tv":0.0,"id":13117300},{"batb":[[0,2.94,53.61],[1,2.9,48.53],[2,2.8,11.02]],"ltp":0.0,"tv":0.0,"id":13117373}]}]}
{"op":"mcm","clk":"1008937801","pt":1580662470206,"mc":[{"id":"1.168236369","rc":[{"batb":[[0,4.3,62.56],[1,1.01,0.51],[2,1.01,0]],"ltp":0.0,"tv":0.0,"id":13117301},{"batb":[[0,2.8,11.02],[1,1.01,0.51],[2,2.8,0]],"ltp":0.0,"tv":0.0,"id":13117373}]}]}
{"op":"mcm","clk":"1008938062","pt":1580662472214,"mc":[{"id":"1.168236369","rc":[{"batb":[[0,4.4,32.27],[1,4.3,62.56],[2,1.01,0.51]],"ltp":0.0,"tv":0.0,"id":13117301},{"batb":[[0,3.5,48.57],[1,3.45,39.38],[2,2.8,11.02]],"ltp":0.0,"tv":0.0,"id":13117373}]}]}
{"op":"mcm","clk":"1008938187","pt":1580662473217,"mc":[{"id":"1.168236369","rc":[{"batl":[[0,5.1,16.84]],"ltp":0.0,"tv":0.0,"id":13117301},{"batl":[[0,3.35,22.27],[1,3.6,18.49]],"ltp":0.0,"tv":0.0,"id":13117300},{"batb":[[2,3.35,17.23]],"batl":[[1,4.4,24.08]],"ltp":0.0,"tv":0.0,"id":13117373},{"batl":[[0,5.7,13.22]],"ltp":0.0,"tv":0.0,"id":13117374}]}]}
{"op":"mcm","clk":"1008938334","pt":1580662474157,"mc":[{"id":"1.168236369","rc":[{"batb":[[1,4.3,75.17]],"batl":[[1,5.2,9.24]],"ltp":0.0,"tv":0.0,"id":13117301},{"batl":[[1,3.4,16.8],[2,3.6,18.49]],"ltp":0.0,"tv":0.0,"id":13117300},{"batb":[[2,3.4,16.8]],"batl":[[1,4,13.44],[2,4.4,24.08]],"ltp":0.0,"tv":0.0,"id":13117373},{"batb":[[2,4.5,11.76]],"batl":[[0,5.5,9.24],[1,5.7,13.22]],"ltp":0.0,"tv":0.0,"id":13117374}]}]}
{"op":"mcm","clk":"1008942763","pt":1580662507014,"mc":[{"id":"1.168236369","rc":[{"batb":[[0,4.3,75.17],[1,1.01,0.51],[2,1.01,0]],"ltp":0.0,"tv":0.0,"id":13117301},{"batb":[[0,2.96,21],[1,2.72,12.04],[2,1.01,0.51]],"batl":[[0,3.4,16.8],[1,3.6,18.49],[2,3.6,0]],"ltp":0.0,"tv":0.0,"id":13117300},{"batb":[[0,3.4,16.8],[1,3.15,20.61],[2,1.01,0.51]],"batl":[[0,4,13.44],[1,4.4,24.08],[2,4.4,0]],"ltp":0.0,"tv":0.0,"id":13117373}]}]}
{"op":"mcm","clk":"1008943066","pt":1580662509216,"mc":[{"id":"1.168236369","rc":[{"batb":[[0,4.3,62.56]],"batl":[[1,5.2,0]],"ltp":0.0,"tv":0.0,"id":13117301},{"batb":[[0,2.72,12.04],[1,1.01,0.51],[2,1.01,0]],"batl":[[0,3.6,18.49],[1,3.6,0]],"ltp":0.0,"tv":0.0,"id":13117300},{"batb":[[0,3.15,20.61],[1,1.01,0.51],[2,1.01,0]],"batl":[[0,4.4,24.08],[1,4.4,0]],"ltp":0.0,"tv":0.0,"id":13117373},{"batb":[[2,1.01,0.51]],"batl":[[0,5.7,13.22],[1,5.7,0]],"ltp":0.0,"tv":0.0,"id":13117374}]}]}
{"op":"mcm","clk":"1008943199","pt":1580662510217,"mc":[{"id":"1.168236369","rc":[{"batb":[[0,3.1,20.69]],"ltp":0.0,"tv":0.0,"id":13117373}]}]}
{"op":"mcm","clk":"1008943467","pt":1580662512213,"mc":[{"id":"1.168236369","rc":[{"batb":[[0,4.4,35.73],[1,4.3,62.56],[2,1.01,0.51]],"ltp":0.0,"tv":0.0,"id":13117301},{"batb":[[0,3,84.91],[1,2.96,43.92],[2,2.72,12.04]],"ltp":0.0,"tv":0.0,"id":13117300},{"batb":[[0,3.6,36.54],[1,3.55,36.87],[2,3.1,20.69]],"ltp":0.0,"tv":0.0,"id":13117373}]}]}
{"op":"mcm","clk":"1008943531","pt":1580662512739,"mc":[{"id":"1.168236369","rc":[{"batb":[[0,3,53.39],[1,2.72,12.04],[2,1.01,0.51]],"ltp":0.0,"tv":0.0,"id":13117300}]}]}
{"op":"mcm","clk":"1008943817","pt":1580662515210,"mc":[{"id":"1.168236369","rc":[{"batb":[[0,4.4,26.39]],"ltp":0.0,"tv":0.0,"id":13117301},{"batb":[[0,2.72,12.04],[1,1.01,0.51],[2,1.01,0]],"ltp":0.0,"tv":0.0,"id":13117300},{"batb":[[0,3.1,20.69],[1,1.01,0.51],[2,3.1,0]],"ltp":0.0,"tv":0.0,"id":13117373},{"batb":[[0,4.9,52.79],[1,1.01,0.51],[2,1.01,0]],"ltp":0.0,"tv":0.0,"id":13117374}]}]}
{"op":"mcm","clk":"1008944133","pt":1580662517826,"mc":[{"id":"1.168236369","rc":[{"batb":[[0,2.8,43.92],[1,2.76,53.03],[2,2.72,12.04]],"ltp":0.0,"tv":0.0,"id":13117300},{"batb":[[0,3.25,71.56],[1,3.2,47.07],[2,3.1,20.69]],"ltp":0.0,"tv":0.0,"id":13117373},{"batb":[[0,4.9,66.12],[1,4.8,35.85],[2,1.01,0.51]],"ltp":0.0,"tv":0.0,"id":13117374}]}]}
{"op":"mcm","clk":"1008945246","pt":1580662526235,"mc":[{"id":"1.168236369","rc":[{"batb":[[0,2.72,12.04],[1,1.01,0.51],[2,2.72,0]],"ltp":0.0,"tv":0.0,"id":13117300}]}]}
{"op":"mcm","clk":"1008945582","pt":1580662529164,"mc":[{"id":"1.168236369","rc":[{"batb":[[0,3.3,63.31],[1,3.25,43.44],[2,2.72,12.04]],"ltp":0.0,"tv":0.0,"id":13117300}]}]}
{"op":"mcm","clk":"1008945694","pt":1580662530058,"mc":[{"id":"1.168236369","rc":[{"batb":[[1,4.3,75.17]],"batl":[[0,5.1,26.92]],"ltp":0.0,"tv":0.0,"id":13117301},{"batb":[[2,3.2,19.12]],"batl":[[0,3.6,34.45],[1,3.9,15.5]],"ltp":0.0,"tv":0.0,"id":13117300},{"batb":[[0,3.25,90.04]],"batl":[[0,3.5,19.91],[1,3.8,14.28],[2,3.9,15.5]],"ltp":0.0,"tv":0.0,"id":13117373},{"batb":[[2,4.5,11.76]],"batl":[[0,5.5,9.24],[1,5.7,13.22]],"ltp":0.0,"tv":0.0,"id":13117374}]}]}
{"op":"mcm","clk":"1008947336","pt":1580662543856,"mc":[{"id":"1.168236369","rc":[{"batb":[[0,4.3,75.17],[1,1.01,0.51],[2,1.01,0]],"ltp":0.0,"tv":0.0,"id":13117301},{"batb":[[0,3.1,19.32],[1,2.92,24.78],[2,1.01,0.51]],"batl":[[0,3.6,15.96]],"ltp":0.0,"tv":0.0,"id":13117300},{"batb":[[0,3.25,18.48],[1,2.96,24],[2,1.01,0.51]],"batl":[[0,3.8,14.28],[1,3.9,15.5],[2,3.9,0]],"ltp":0.0,"tv":0.0,"id":13117373}]}]}
{"op":"mcm","clk":"1008947427","pt":1580662544591,"mc":[{"id":"1.168236369","rc":[{"batb":[[0,4.3,62.56]],"batl":[[0,5.1,16.84]],"ltp":0.0,"tv":0.0,"id":13117301},{"batb":[[0,2.92,24.78],[1,1.01,0.51],[2,1.01,0]],"batl":[[0,3.9,15.5],[1,3.9,0]],"ltp":0.0,"tv":0.0,"id":13117300},{"batb":[[0,2.96,24],[1,1.01,0.51],[2,1.01,0]],"batl":[[0,3.9,15.5],[1,3.9,0]],"ltp":0.0,"tv":0.0,"id":13117373},{"batb":[[2,1.01,0.51]],"batl":[[0,5.7,13.22],[1,5.7,0]],"ltp":0.0,"tv":0.0,"id":13117374}]}]}
{"op":"mcm","clk":"1008947743","pt":1580662547080,"mc":[{"id":"1.168236369","rc":[{"batb":[[0,4.3,84.35],[1,4.2,46.03],[2,1.01,0.51]],"ltp":0.0,"tv":0.0,"id":13117301},{"batb":[[0,3,77.67],[1,2.96,44.03],[2,2.92,24.78]],"ltp":0.0,"tv":0.0,"id":13117300},{"batb":[[0,3.1,68.21],[1,3.05,53.08],[2,2.96,24]],"ltp":0.0,"tv":0.0,"id":13117373}]}]}
{"op":"mcm","clk":"1008948166","pt":1580662550179,"mc":[{"id":"1.168236369","rc":[{"batb":[[0,2.92,24.78],[1,1.01,0.51],[2,2.92,0]],"ltp":0.0,"tv":0.0,"id":13117300}]}]}
{"op":"mcm","clk":"1008948553","pt":1580662553172,"mc":[{"id":"1.168236369","rc":[{"batb":[[0,3.5,52.57],[1,3.45,37.58],[2,2.92,24.78]],"ltp":0.0,"tv":0.0,"id":13117300}]}]}
{"op":"mcm","clk":"1008948701","pt":1580662554204,"mc":[{"id":"1.168236369","rc":[{"batb":[[0,4.3,96.96]],"batl":[[0,5,17.62],[1,5.1,10.08]],"ltp":0.0,"tv":0.0,"id":13117301},{"batb":[[1,3.45,53.63],[2,3.25,18.48]],"batl":[[0,3.85,14.28],[1,3.9,15.5],[2,4.1,13.69]],"ltp":0.0,"tv":0.0,"id":13117300},{"batb":[[0,3.1,87.53]],"batl":[[0,3.3,23.05],[1,3.55,18.96],[2,3.6,15.96]],"ltp":0.0,"tv":0.0,"id":13117373},{"batb":[[2,4.5,11.76]],"batl":[[0,5.5,9.24],[1,5.7,13.22]],"ltp":0.0,"tv":0.0,"id":13117374}]}]}
{"op":"mcm","clk":"1008950000","pt":1580662563778,"mc":[{"id":"1.168236369","rc":[{"batb":[[0,3.25,18.48],[1,3.15,19.91],[2,1.01,0.51]],"batl":[[1,4.1,13.69],[2,4.1,0]],"ltp":0.0,"tv":0.0,"id":13117300},{"batb":[[0,3.1,19.32],[1,2.84,10.62],[2,1.01,0.51]],"batl":[[0,3.55,18.96],[1,3.6,15.96],[2,3.6,0]],"ltp":0.0,"tv":0.0,"id":13117373}]}]}
{"op":"mcm","clk":"1008950136","pt":1580662564677,"mc":[{"id":"1.168236369","rc":[{"batb":[[0,4.3,84.35]],"batl":[[1,5.1,0]],"ltp":0.0,"tv":0.0,"id":13117301},{"batb":[[0,3.15,19.91],[1,1.01,0.51],[2,1.01,0]],"batl":[[0,4.1,13.69],[1,4.1,0]],"ltp":0.0,"tv":0.0,"id":13117300},{"batb":[[0,2.84,10.62],[1,1.01,0.51],[2,1.01,0]],"batl":[[1,3.6,0]],"ltp":0.0,"tv":0.0,"id":13117373},{"batb":[[2,1.01,0.51]],"batl":[[0,5.7,13.22],[1,5.7,0]],"ltp":0.0,"tv":0.0,"id":13117374}]}]}
{"op":"mcm","clk":"1008950466","pt":1580662567117,"mc":[{"id":"1.168236369","rc":[{"batb":[[0,3.25,68.33],[1,3.2,45.1],[2,3.15,19.91]],"ltp":0.0,"tv":0.0,"id":13117300},{"batb":[[0,3,69.89],[1,2.96,45.94],[2,2.84,10.62]],"ltp":0.0,"tv":0.0,"id":13117373}]}]}
{"op":"mcm","clk":"1008950510","pt":1580662567351,"mc":[{"id":"1.168236369","rc":[{"batb":[[0,3.15,19.91],[1,1.01,0.51],[2,3.15,0]],"ltp":0.0,"tv":0.0,"id":13117300}]}]}
{"op":"mcm","clk":"1008951076","pt":1580662571226,"mc":[{"id":"1.168236369","rc":[{"batb":[[0,3.65,60.05],[1,3.6,33.93],[2,3.4,16.44]],"batl":[[1,4.3,24.31]],"ltp":0.0,"tv":0.0,"id":13117300},{"batl":[[0,3.1,10.39],[1,3.35,22.27]],"ltp":0.0,"tv":0.0,"id":13117373}]}]}
{"op":"mcm","clk":"1008951217","pt":1580662572226,"mc":[{"id":"1.168236369","rc":[{"batb":[[0,4.3,96.96]],"batl":[[1,5.1,10.08]],"ltp":0.0,"tv":0.0,"id":13117301},{"batb":[[2,3.4,33.25]],"batl":[[0,4,13.44],[1,4.1,13.69],[2,4.3,24.31]],"ltp":0.0,"tv":0.0,"id":13117300},{"batb":[[1,2.96,66.94]],"batl":[[2,3.5,16.8]],"ltp":0.0,"tv":0.0,"id":13117373},{"batb":[[2,4.5,11.76]],"batl":[[0,5.4,9.24],[1,5.7,13.22]],"ltp":0.0,"tv":0.0,"id":13117374}]}]}
{"op":"mcm","clk":"1008952458","pt":1580662581421,"mc":[{"id":"1.168236369","rc":[{"batb":[[0,4.3,88.8]],"ltp":0.0,"tv":0.0,"id":13117301},{"batb":[[0,3.4,33.25],[1,1.01,0.51],[2,3.4,0]],"batl":[[1,4.3,24.31],[2,4.3,0]],"ltp":0.0,"tv":0.0,"id":13117300},{"batb":[[0,2.96,66.94],[1,2.76,11.41],[2,1.01,0.51]],"batl":[[0,3.35,22.27],[1,3.5,16.8],[2,3.5,0]],"ltp":0.0,"tv":0.0,"id":13117373},{"batb":[[0,4.9,56.01]],"ltp":0.0,"tv":0.0,"id":13117374}]}]}
{"op":"mcm","clk":"1008952621","pt":1580662582928,"mc":[{"id":"1.168236369","rc":[{"batb":[[0,4.3,76.19]],"batl":[[1,5.1,0]],"ltp":0.0,"tv":0.0,"id":13117301},{"batb":[[0,3.4,16.44]],"batl":[[0,4.3,24.31],[1,4.3,0]],"ltp":0.0,"tv":0.0,"id":13117300},{"batb":[[0,2.96,45.94]],"batl":[[1,3.5,0]],"ltp":0.0,"tv":0.0,"id":13117373},{"batb":[[2,1.01,0.51]],"batl":[[0,5.7,13.22],[1,5.7,0]],"ltp":0.0,"tv":0.0,"id":13117374}]}]}
{"op":"mcm","clk":"1008952785","pt":1580662584240,"mc":[{"id":"1.168236369","rc":[{"batb":[[0,3.5,40.97],[1,3.45,37.68],[2,3.4,16.44]],"ltp":0.0,"tv":0.0,"id":13117300},{"batb":[[1,2.92,47.69],[2,2.76,11.41]],"ltp":0.0,"tv":0.0,"id":13117373}]}]}
{"op":"mcm","clk":"1008953583","pt":1580662590214,"mc":[{"id":"1.168236369","rc":[{"batb":[[0,4.3,62.56],[1,1.01,0.51],[2,1.01,0]],"ltp":0.0,"tv":0.0,"id":13117301},{"batb":[[0,3.4,16.44],[1,1.01,0.51],[2,3.4,0]],"ltp":0.0,"tv":0.0,"id":13117300}]}]}
{"op":"mcm","clk":"1008953992","pt":1580662593129,"mc":[{"id":"1.168236369","rc":[{"batb":[[0,4.4,26.2],[1,4.3,62.56],[2,1.01,0.51]],"ltp":0.0,"tv":0.0,"id":13117301},{"batb":[[0,3.75,38.28],[1,3.7,31.83],[2,3.4,16.44]],"ltp":0.0,"tv":0.0,"id":13117300}]}]}
{"op":"mcm","clk":"1008954110","pt":1580662594043,"mc":[{"id":"1.168236369","rc":[{"batb":[[1,4.3,75.17]],"batl":[[0,5,17.47],[1,5.2,9.24]],"ltp":0.0,"tv":0.0,"id":13117301},{"batb":[[0,3.8,12.9],[1,3.75,38.28],[2,3.7,31.83]],"batl":[[0,4.2,12.6],[1,4.3,24.31],[2,5.1,16.92]],"ltp":0.0,"tv":0.0,"id":13117300},{"batb":[[2,2.88,21.85]],"batl":[[0,3.05,11.25],[1,3.25,23.68],[2,3.35,17.64]],"ltp":0.0,"tv":0.0,"id":13117373},{"batb":[[0,4.9,42.32],[1,4.8,50.17],[2,4.4,11.76]],"ltp":0.0,"tv":0.0,"id":13117374}]}]}
{"op":"mcm","clk":"1008954250","pt":1580662595145,"mc":[{"id":"1.168236369","rc":[{"batb":[[1,4.3,62.56]],"ltp":0.0,"tv":0.0,"id":13117301}]}]}
{"op":"mcm","clk":"1008954535","pt":1580662597236,"mc":[{"id":"1.168236369","rc":[{"batl":[[0,5.3,9.24],[1,5.7,13.22]],"ltp":0.0,"tv":0.0,"id":13117374}]}]}
{"op":"mcm","clk":"1008954621","pt":1580662598050,"mc":[{"id":"1.168236369","rc":[{"batb":[[0,4.4,37.96]],"ltp":0.0,"tv":0.0,"id":13117301}]}]}
{"op":"mcm","clk":"1008955126","pt":1580662602046,"mc":[{"id":"1.168236369","rc":[{"batb":[[0,3.75,51.42],[1,3.7,31.83],[2,3.55,15.96]],"ltp":0.0,"tv":0.0,"id":13117300},{"batl":[[0,3.05,11.02],[1,3.25,23.21]],"ltp":0.0,"tv":0.0,"id":13117373},{"batb":[[0,4.9,56.33],[1,4.8,35.85]],"ltp":0.0,"tv":0.0,"id":13117374}]}]}
{"op":"mcm","clk":"1008956157","pt":1580662610091,"mc":[{"id":"1.168236369","rc":[{"batl":[[2,3.3,23.21]],"ltp":0.0,"tv":0.0,"id":13117373}]}]}
{"op":"mcm","clk":"1008956221","pt":1580662610784,"mc":[{"id":"1.168236369","rc":[{"batl":[[1,3.3,23.21],[2,3.35,17.64]],"ltp":0.0,"tv":0.0,"id":13117373}]}]}
{"op":"mcm","clk":"1008956431","pt":1580662612459,"mc":[{"id":"1.168236369","rc":[{"batb":[[0,4.9,53.11]],"ltp":0.0,"tv":0.0,"id":13117374}]}]}
{"op":"mcm","clk":"1008956902","pt":1580662616129,"mc":[{"id":"1.168236369","rc":[{"batb":[[0,4.4,46.02]],"ltp":0.0,"tv":0.0,"id":13117301}]}]}
{"op":"mcm","clk":"1008957178","pt":1580662618207,"mc":[{"id":"1.168236369","rc":[{"batl":[[0,4.2,25.43],[1,5,17.62],[2,5.1,0]],"ltp":0.0,"tv":0.0,"id":13117300},{"batl":[[0,3.05,10.86],[1,3.3,22.82]],"ltp":0.0,"tv":0.0,"id":13117373}]}]}
{"op":"mcm","clk":"1008960167","pt":1580662641721,"mc":[{"id":"1.168236369","rc":[{"batb":[[0,2.88,21.85],[1,2.8,11.02],[2,2.54,14.4]],"ltp":0.0,"tv":0.0,"id":13117373},{"batb":[[0,4.9,43.04]],"ltp":0.0,"tv":0.0,"id":13117374}]}]}
{"op":"mcm","clk":"1008960565","pt":1580662644736,"mc":[{"id":"1.168236369","rc":[{"batb":[[0,4.4,55.71]],"ltp":0.0,"tv":0.0,"id":13117301},{"batb":[[0,3.75,65.89]],"ltp":0.0,"tv":0.0,"id":13117300},{"batb":[[0,2.94,52.11],[1,2.9,48.39],[2,2.88,21.85]],"ltp":0.0,"tv":0.0,"id":13117373}]}]}
{"op":"mcm","clk":"1008964477","pt":1580662677747,"mc":[{"id":"1.168236369","rc":[{"batb":[[0,2.88,21.85],[1,2.8,11.02],[2,2.54,14.4]],"ltp":0.0,"tv":0.0,"id":13117373}]}]}
{"op":"mcm","clk":"1008964787","pt":1580662680651,"mc":[{"id":"1.168236369","rc":[{"batb":[[0,2.96,35.34],[1,2.92,47.71],[2,2.88,21.85]],"ltp":0.0,"tv":0.0,"id":13117373}]}]}
{"op":"mcm","clk":"1008964964","pt":1580662682173,"mc":[{"id":"1.168236369","rc":[{"batb":[[0,3.55,15.96],[1,3.45,15.89],[2,1.01,0.51]],"batl":[[0,4.2,12.6]],"ltp":0.0,"tv":0.0,"id":13117300},{"batb":[[0,2.88,21.85],[1,2.54,14.4],[2,1.01,0.51]],"batl":[[0,3.3,22.82],[1,3.35,17.64],[2,3.35,0]],"ltp":0.0,"tv":0.0,"id":13117373}]}]}
{"op":"mcm","clk":"1008965026","pt":1580662682664,"mc":[{"id":"1.168236369","rc":[{"batb":[[0,4.4,43.95]],"batl":[[1,5.2,0]],"ltp":0.0,"tv":0.0,"id":13117301},{"batb":[[0,3.45,15.89],[1,1.01,0.51],[2,1.01,0]],"batl":[[0,5,17.62],[1,5,0]],"ltp":0.0,"tv":0.0,"id":13117300},{"batb":[[0,2.54,14.4],[1,1.01,0.51],[2,1.01,0]],"batl":[[1,3.35,0]],"ltp":0.0,"tv":0.0,"id":13117373},{"batb":[[2,1.01,0.51]],"batl":[[0,5.7,13.22],[1,5.7,0]],"ltp":0.0,"tv":0.0,"id":13117374}]}]}
{"op":"mcm","clk":"1008965297","pt":1580662685172,"mc":[{"id":"1.168236369","rc":[{"batb":[[0,3.5,40.05],[1,3.45,53.7],[2,1.01,0.51]],"ltp":0.0,"tv":0.0,"id":13117300},{"batb":[[0,2.66,64.85],[1,2.62,62.89],[2,2.54,14.4]],"ltp":0.0,"tv":0.0,"id":13117373}]}]}
{"op":"mcm","clk":"1008965386","pt":1580662685861,"mc":[{"id":"1.168236369","rc":[{"batb":[[1,4.3,44.31],[2,4.2,19.67]],"batl":[[0,4.9,18.25]],"ltp":0.0,"tv":0.0,"id":13117301},{"batb":[[1,3.45,37.81],[2,3.4,16.6]],"ltp":0.0,"tv":0.0,"id":13117300},{"batb":[[2,2.56,14.08]],"batl":[[0,3.35,22.19]],"ltp":0.0,"tv":0.0,"id":13117373},{"batb":[[0,4.9,42.72]],"batl":[[0,5.8,12.9]],"ltp":0.0,"tv":0.0,"id":13117374}]}]}
{"op":"mcm","clk":"1008966784","pt":1580662696161,"mc":[{"id":"1.168236369","rc":[{"batb":[[0,3.4,16.6],[1,1.01,0.51],[2,3.4,0]],"ltp":0.0,"tv":0.0,"id":13117300}]}]}
{"op":"mcm","clk":"1008967188","pt":1580662699194,"mc":[{"id":"1.168236369","rc":[{"batb":[[0,4.3,54.39],[1,4.2,46.41],[2,3.4,16.6]],"ltp":0.0,"tv":0.0,"id":13117300},{"batb":[[0,4.9,53.99]],"ltp":0.0,"tv":0.0,"id":13117374}]}]}
{"op":"mcm","clk":"1008967307","pt":1580662699983,"mc":[{"id":"1.168236369","rc":[{"batl":[[1,5.2,9.24]],"ltp":0.0,"tv":0.0,"id":13117301},{"batb":[[0,4.3,73.43],[2,3.95,13.44]],"batl":[[0,4.7,10.92],[1,5,17.62],[2,6.2,11.33]],"ltp":0.0,"tv":0.0,"id":13117300},{"batb":[[0,2.66,90.06]],"batl":[[0,2.78,13.77],[1,3.05,31.42]],"ltp":0.0,"tv":0.0,"id":13117373},{"batb":[[0,5,13.45],[1,4.9,53.83],[2,4.8,35.85]],"batl":[[0,5.9,12.35]],"ltp":0.0,"tv":0.0,"id":13117374}]}]}
{"op":"mcm","clk":"1008967797","pt":1580662703174,"mc":[{"id":"1.168236369","rc":[{"batb":[[0,4.4,55.71]],"ltp":0.0,"tv":0.0,"id":13117301},{"batl":[[0,5.3,9.24],[1,5.9,12.35]],"ltp":0.0,"tv":0.0,"id":13117374}]}]}
{"op":"mcm","clk":"1008969832","pt":1580662718111,"mc":[{"id":"1.168236369","rc":[{"batb":[[0,4.4,46.02]],"ltp":0.0,"tv":0.0,"id":13117301},{"batb":[[0,3.95,13.44],[1,3.8,25.65],[2,1.01,0.51]],"batl":[[1,6.2,11.33],[2,6.2,0]],"ltp":0.0,"tv":0.0,"id":13117300},{"batb":[[0,2.66,25.21],[1,2.28,19.04],[2,1.01,0.51]],"batl":[[0,3.05,31.42],[1,3.05,0]],"ltp":0.0,"tv":0.0,"id":13117373},{"batb":[[0,4.9,45.03],[1,4.8,35.85],[2,4.4,11.76]],"ltp":0.0,"tv":0.0,"id":13117374}]}]}
{"op":"mcm","clk":"1008969938","pt":1580662718789,"mc":[{"id":"1.168236369","rc":[{"batb":[[0,4.4,34.26]],"batl":[[1,5.2,0]],"ltp":0.0,"tv":0.0,"id":13117301},{"batb":[[0,3.8,25.65],[1,1.01,0.51],[2,1.01,0]],"batl":[[0,6.2,11.33],[1,6.2,0]],"ltp":0.0,"tv":0.0,"id":13117300},{"batb":[[0,2.28,19.04],[1,1.01,0.51],[2,1.01,0]],"batl":[[0,3.05,11.25]],"ltp":0.0,"tv":0.0,"id":13117373},{"batb":[[2,1.01,0.51]],"batl":[[0,5.9,12.35],[1,5.9,0]],"ltp":0.0,"tv":0.0,"id":13117374}]}]}
{"op":"mcm","clk":"1008970218","pt":1580662720984,"mc":[{"id":"1.168236369","rc":[{"batb":[[0,3.9,28.48],[1,3.85,29.12],[2,3.8,25.65]],"ltp":0.0,"tv":0.0,"id":13117300},{"batb":[[0,2.36,80.79],[1,2.32,87.26],[2,2.28,19.04]],"ltp":0.0,"tv":0.0,"id":13117373}]}]}
{"op":"mcm","clk":"1008970601","pt":1580662724231,"mc":[{"id":"1.168236369","rc":[{"batb":[[0,3.8,25.65],[1,1.01,0.51],[2,3.8,0]],"ltp":0.0,"tv":0.0,"id":13117300},{"batb":[[0,2.28,19.04],[1,1.01,0.51],[2,2.28,0]],"ltp":0.0,"tv":0.0,"id":13117373}]}]}
{"op":"mcm","clk":"1008970954","pt":1580662727209,"mc":[{"id":"1.168236369","rc":[{"batb":[[0,3.9,28.48],[1,3.85,29.12],[2,3.8,25.65]],"ltp":0.0,"tv":0.0,"id":13117300},{"batb":[[0,2.88,48.64],[1,2.84,51.11],[2,2.28,19.04]],"ltp":0.0,"tv":0.0,"id":13117373}]}]}
{"op":"mcm","clk":"1008971064","pt":1580662727993,"mc":[{"id":"1.168236369","rc":[{"batb":[[0,4.4,46.02]],"batl":[[0,5,18.18],[1,5.2,9.24]],"ltp":0.0,"tv":0.0,"id":13117301},{"batl":[[0,4.3,12.6],[1,4.4,24.23],[2,5.3,15.74]],"ltp":0.0,"tv":0.0,"id":13117300},{"batb":[[2,2.8,22.69]],"batl":[[1,3.25,18.48],[2,3.3,22.82]],"ltp":0.0,"tv":0.0,"id":13117373},{"batb":[[2,4.4,11.76]],"batl":[[0,5.3,9.24],[1,5.8,12.75]],"ltp":0.0,"tv":0.0,"id":13117374}]}]}
{"op":"mcm","clk":"1008972728","pt":1580662741132,"mc":[{"id":"1.168236369","rc":[{"batb":[[0,4.9,42.56]],"ltp":0.0,"tv":0.0,"id":13117374}]}]}
{"op":"mcm","clk":"1008973112","pt":1580662744141,"mc":[{"id":"1.168236369","rc":[{"batb":[[0,4.4,55.44]],"ltp":0.0,"tv":0.0,"id":13117301}]}]}
{"op":"mcm","clk":"1008973184","pt":1580662744620,"mc":[{"id":"1.168236369","rc":[{"batb":[[0,4.4,43.68]],"batl":[[1,5.2,0]],"ltp":0.0,"tv":0.0,"id":13117301},{"batb":[[0,3.45,16.13],[1,1.01,0.51],[2,3.8,0]],"batl":[[0,5.3,15.74],[1,4.4,0],[2,5.3,0]],"ltp":0.0,"tv":0.0,"id":13117300},{"batb":[[0,2.46,15.58],[1,1.01,0.51],[2,2.8,0]],"batl":[[0,3.3,22.82],[1,3.25,0],[2,3.3,0]],"ltp":0.0,"tv":0.0,"id":13117373},{"batb":[[0,4.9,35.14],[2,1.01,0.51]],"batl":[[0,5.8,12.75],[1,5.8,0]],"ltp":0.0,"tv":0.0,"id":13117374}]}]}
{"op":"mcm","clk":"1008973496","pt":1580662747228,"mc":[{"id":"1.168236369","rc":[{"batb":[[1,2.44,15.82],[2,1.01,0.51]],"ltp":0.0,"tv":0.0,"id":13117373}]}]}
{"op":"mcm","clk":"1008973566","pt":1580662747755,"mc":[{"id":"1.168236369","rc":[{"batb":[[2,4.2,19.36]],"batl":[[0,5,17.94]],"ltp":0.0,"tv":0.0,"id":13117301},{"batb":[[0,3.45,15.89]],"batl":[[0,5.3,15.5]],"ltp":0.0,"tv":0.0,"id":13117300},{"batb":[[0,2.44,15.82],[1,1.01,0.51],[2,1.01,0]],"ltp":0.0,"tv":0.0,"id":13117373}]}]}
{"op":"mcm","clk":"1008973627","pt":1580662748411,"mc":[{"id":"1.168236369","rc":[{"batb":[[0,3.55,40.22],[1,3.5,36.56],[2,3.45,15.89]],"ltp":0.0,"tv":0.0,"id":13117300},{"batb":[[0,2.56,47.9],[1,2.52,69.78],[2,2.44,15.82]],"ltp":0.0,"tv":0.0,"id":13117373}]}]}
{"op":"mcm","clk":"1008973715","pt":1580662749347,"mc":[{"id":"1.168236369","rc":[{"batb":[[0,3.45,15.89],[1,1.01,0.51],[2,3.45,0]],"ltp":0.0,"tv":0.0,"id":13117300}]}]}
{"op":"mcm","clk":"1008974140","pt":1580662753200,"mc":[{"id":"1.168236369","rc":[{"batb":[[0,4.7,24.17],[1,4.6,54.4],[2,3.95,23.21]],"batl":[[1,7.4,15.97]],"ltp":0.0,"tv":0.0,"id":13117300},{"batl":[[0,2.66,15.42],[1,2.9,12.27]],"ltp":0.0,"tv":0.0,"id":13117373},{"batb":[[0,5,13.38],[1,4.9,53.84],[2,4.8,35.85]],"batl":[[0,5.9,12.35]],"ltp":0.0,"tv":0.0,"id":13117374}]}]}
{"op":"mcm","clk":"1008974222","pt":1580662753655,"mc":[{"id":"1.168236369","rc":[{"batb":[[1,4.3,56.91]],"batl":[[1,5.2,9.24]],"ltp":0.0,"tv":0.0,"id":13117301},{"batb":[[2,4.2,12.6]],"batl":[[0,5.1,10.08],[1,5.3,15.5],[2,7.4,15.97]],"ltp":0.0,"tv":0.0,"id":13117300},{"batb":[[0,2.56,74.79]],"batl":[[2,2.92,21.85]],"ltp":0.0,"tv":0.0,"id":13117373},{"batl":[[0,5.3,9.24],[1,5.9,12.35]],"ltp":0.0,"tv":0.0,"id":13117374}]}]}
{"op":"mcm","clk":"1008976306","pt":1580662771779,"mc":[{"id":"1.168236369","rc":[{"batb":[[0,4.4,26.2]],"ltp":0.0,"tv":0.0,"id":13117301},{"batb":[[0,4.2,12.6],[1,3.95,23.21],[2,1.01,0.51]],"batl":[[1,7.4,15.97],[2,7.4,0]],"ltp":0.0,"tv":0.0,"id":13117300},{"batb":[[0,2.56,26.89],[1,2.16,22.5],[2,1.01,0.51]],"batl":[[0,2.9,12.27],[1,2.92,21.85],[2,2.92,0]],"ltp":0.0,"tv":0.0,"id":13117373},{"batb":[[0,4.9,42.12],[1,4.8,35.85],[2,4.4,11.76]],"ltp":0.0,"tv":0.0,"id":13117374}]}]}
{"op":"mcm","clk":"1008976427","pt":1580662772760,"mc":[{"id":"1.168236369","rc":[{"batb":[[1,4.3,44.31]],"batl":[[1,5.2,0]],"ltp":0.0,"tv":0.0,"id":13117301},{"batb":[[0,3.95,23.21],[1,1.01,0.51],[2,1.01,0]],"batl":[[0,7.4,15.97],[1,7.4,0]],"ltp":0.0,"tv":0.0,"id":13117300},{"batb":[[0,2.16,22.5],[1,1.01,0.51],[2,1.01,0]],"batl":[[1,2.92,0]],"ltp":0.0,"tv":0.0,"id":13117373},{"batb":[[2,1.01,0.51]],"batl":[[0,5.9,12.35],[1,5.9,0]],"ltp":0.0,"tv":0.0,"id":13117374}]}]}
{"op":"mcm","clk":"1008976578","pt":1580662774179,"mc":[{"id":"1.168236369","rc":[{"batb":[[0,4,48.16],[1,3.95,50.47],[2,1.01,0.51]],"ltp":0.0,"tv":0.0,"id":13117300},{"batb":[[0,2.22,67.62],[1,2.2,51.13],[2,2.16,22.5]],"ltp":0.0,"tv":0.0,"id":13117373}]}]}
{"op":"mcm","clk":"1008976638","pt":1580662774666,"mc":[{"id":"1.168236369","rc":[{"batb":[[2,2.16,22.35]],"batl":[[0,2.92,12.2]],"ltp":0.0,"tv":0.0,"id":13117373}]}]}
{"op":"mcm","clk":"1008977137","pt":1580662779000,"mc":[{"id":"1.168236369","rc":[{"batb":[[0,2.16,22.35],[1,1.01,0.51],[2,2.16,0]],"ltp":0.0,"tv":0.0,"id":13117373}]}]}
{"op":"mcm","clk":"1008977517","pt":1580662781688,"mc":[{"id":"1.168236369","rc":[{"batb":[[0,4.4,43.88]],"ltp":0.0,"tv":0.0,"id":13117301},{"batb":[[0,2.8,61.38],[1,2.76,54.89],[2,2.16,22.35]],"ltp":0.0,"tv":0.0,"id":13117373}]}]}
{"op":"mcm","clk":"1008977612","pt":1580662782610,"mc":[{"id":"1.168236369","rc":[{"batb":[[2,3.5,15.82]],"batl":[[0,4.5,22.19],[1,5.9,12.27]],"ltp":0.0,"tv":0.0,"id":13117300},{"batb":[[2,2.68,12.43]],"batl":[[1,3.3,23.05]],"ltp":0.0,"tv":0.0,"id":13117373},{"batl":[[0,5.8,12.67]],"ltp":0.0,"tv":0.0,"id":13117374}]}]}
{"op":"mcm","clk":"1008977739","pt":1580662783667,"mc":[{"id":"1.168236369","rc":[{"batb":[[0,4.4,55.64]],"batl":[[1,5.2,9.24]],"ltp":0.0,"tv":0.0,"id":13117301},{"batb":[[2,3.8,14.28]],"batl":[[0,4.5,33.95]],"ltp":0.0,"tv":0.0,"id":13117300},{"batb":[[2,2.74,23.53]],"batl":[[1,3.15,19.32],[2,3.3,23.05]],"ltp":0.0,"tv":0.0,"id":13117373},{"batb":[[2,4.4,11.76]],"batl":[[0,5.3,9.24],[1,5.8,12.67]],"ltp":0.0,"tv":0.0,"id":13117374}]}]}
{"op":"mcm","clk":"1008980429","pt":1580662805012,"mc":[{"id":"1.168236369","rc":[{"batb":[[0,4.4,43.88]],"batl":[[1,5.2,0]],"ltp":0.0,"tv":0.0,"id":13117301},{"batb":[[0,3.5,15.82],[1,1.01,0.51],[2,3.8,0]],"batl":[[0,5.9,12.27],[1,5.9,0]],"ltp":0.0,"tv":0.0,"id":13117300},{"batb":[[0,2.34,18.02],[1,1.01,0.51],[2,2.74,0]],"batl":[[0,3.3,23.05],[1,3.15,0],[2,3.3,0]],"ltp":0.0,"tv":0.0,"id":13117373},{"batb":[[0,4.9,13.53],[2,1.01,0.51]],"batl":[[0,5.8,12.67],[1,5.8,0]],"ltp":0.0,"tv":0.0,"id":13117374}]}]}
{"op":"mcm","clk":"1008980885","pt":1580662808245,"mc":[{"id":"1.168236369","rc":[{"batl":[[0,5,17.78]],"ltp":0.0,"tv":0.0,"id":13117301},{"batb":[[0,3.55,43.7],[1,3.5,52.19],[2,1.01,0.51]],"batl":[[0,6,12.12]],"ltp":0.0,"tv":0.0,"id":13117300},{"batb":[[0,2.4,77.81],[1,2.36,83.11],[2,2.32,18.25]],"batl":[[0,3.25,23.37]],"ltp":0.0,"tv":0.0,"id":13117373},{"batb":[[0,4.8,62.57],[1,4.7,37.44]],"ltp":0.0,"tv":0.0,"id":13117374}]}]}
{"op":"mcm","clk":"1008983205","pt":1580662827223,"mc":[{"id":"1.168236369","rc":[{"batb":[[0,2.32,18.25],[1,1.01,0.51],[2,2.32,0]],"ltp":0.0,"tv":0.0,"id":13117373}]}]}
{"op":"mcm","clk":"1008983557","pt":1580662830226,"mc":[{"id":"1.168236369","rc":[{"batb":[[0,4.4,59.27]],"ltp":0.0,"tv":0.0,"id":13117301},{"batb":[[0,3.1,37.06],[1,3.05,53.17],[2,2.32,18.25]],"ltp":0.0,"tv":0.0,"id":13117373}]}]}
{"op":"mcm","clk":"1008983644","pt":1580662830923,"mc":[{"id":"1.168236369","rc":[{"batb":[[1,4.3,63.19],[2,1.01,0.51]],"batl":[[0,5,17.55]],"ltp":0.0,"tv":0.0,"id":13117301},{"batb":[[2,3.2,19.36]],"batl":[[0,3.95,15.11],[1,4.7,20.69]],"ltp":0.0,"tv":0.0,"id":13117300},{"batb":[[2,2.94,24.31]],"batl":[[1,3.55,19.36]],"ltp":0.0,"tv":0.0,"id":13117373},{"batl":[[0,5.7,13.3]],"ltp":0.0,"tv":0.0,"id":13117374}]}]}
{"op":"mcm","clk":"1008983756","pt":1580662831733,"mc":[{"id":"1.168236369","rc":[{"batb":[[0,4.4,71.03]],"batl":[[1,5.3,9.24]],"ltp":0.0,"tv":0.0,"id":13117301},{"batb":[[2,3.45,16.8]],"batl":[[1,4,13.44],[2,4.7,20.69]],"ltp":0.0,"tv":0.0,"id":13117300},{"batb":[[2,2.96,21]],"batl":[[1,3.45,16.8],[2,3.55,19.36]],"ltp":0.0,"tv":0.0,"id":13117373},{"batb":[[2,4.3,12.6]],"batl":[[0,5.2,9.24],[1,5.7,13.3]],"ltp":0.0,"tv":0.0,"id":13117374}]}]}
{"op":"mcm","clk":"1008985692","pt":1580662846748,"mc":[{"id":"1.168236369","rc":[{"trd":[[3.95,4]],"batl":[[0,3.95,13.11]],"ltp":3.95,"tv":4.0,"id":13117300}],"tv":4.0}]}
{"op":"mcm","clk":"1008986740","pt":1580662854136,"mc":[{"id":"1.168236369","rc":[{"batb":[[0,3.05,53.17],[1,2.96,21],[2,2.94,24.31]],"ltp":0.0,"tv":0.0,"id":13117373}]}]}
{"op":"mcm","clk":"1008986869","pt":1580662855081,"mc":[{"id":"1.168236369","rc":[{"batb":[[0,3.45,16.8],[1,3.2,19.36],[2,1.01,0.51]],"batl":[[0,4,13.44],[1,4.7,20.69],[2,4.7,0]],"ltp":3.95,"tv":4.0,"id":13117300},{"batb":[[0,2.96,21],[1,2.64,12.98],[2,1.01,0.51]],"batl":[[0,3.45,16.8],[1,3.55,19.36],[2,3.55,0]],"ltp":0.0,"tv":0.0,"id":13117373},{"batb":[[0,4.8,52.11]],"ltp":0.0,"tv":0.0,"id":13117374}]}]}
{"op":"mcm","clk":"1008987137","pt":1580662857048,"mc":[{"id":"1.168236369","rc":[{"batb":[[0,4.4,59.27]],"batl":[[1,5.3,0]],"ltp":0.0,"tv":0.0,"id":13117301},{"batb":[[0,3.2,19.36],[1,1.01,0.51],[2,1.01,0]],"batl":[[0,4.7,20.69],[1,4.7,0]],"ltp":3.95,"tv":4.0,"id":13117300},{"batb":[[0,2.64,12.98],[1,1.01,0.51],[2,1.01,0]],"batl":[[0,3.55,19.36],[1,3.55,0]],"ltp":0.0,"tv":0.0,"id":13117373},{"batb":[[2,1.01,0.51]],"batl":[[0,5.7,13.3],[1,5.7,0]],"ltp":0.0,"tv":0.0,"id":13117374}]}]}
{"op":"mcm","clk":"1008987295","pt":1580662858156,"mc":[{"id":"1.168236369","rc":[{"batb":[[1,4.3,62.96]],"batl":[[0,5,17.39]],"ltp":0.0,"tv":0.0,"id":13117301},{"batb":[[0,3.3,58.59],[1,3.25,62.89],[2,1.01,0.51]],"batl":[[0,4.7,20.3]],"ltp":3.95,"tv":4.0,"id":13117300},{"batb":[[0,2.76,55.81],[1,2.72,56.91],[2,2.62,13.14]],"batl":[[0,3.5,19.59]],"ltp":0.0,"tv":0.0,"id":13117373}]}]}
{"op":"mcm","clk":"1008987513","pt":1580662859954,"mc":[{"id":"1.168236369","rc":[{"batb":[[0,2.62,13.14],[1,1.01,0.51],[2,2.62,0]],"ltp":0.0,"tv":0.0,"id":13117373}]}]}
{"op":"mcm","clk":"1008987946","pt":1580662863188,"mc":[{"id":"1.168236369","rc":[{"batl":[[1,5.1,17.23]],"ltp":0.0,"tv":0.0,"id":13117301},{"batb":[[2,2.88,10.46]],"batl":[[0,3.6,18.33],[1,3.95,15.03],[2,4.7,20.3]],"ltp":3.95,"tv":4.0,"id":13117300},{"batb":[[0,3.3,44.53],[1,3.25,45.31],[2,3.15,20.38]],"batl":[[1,4.1,13.93]],"ltp":0.0,"tv":0.0,"id":13117373},{"batl":[[0,5.6,13.93],[1,5.7,13.3]],"ltp":0.0,"tv":0.0,"id":13117374}]}]}
{"op":"mcm","clk":"1008988076","pt":1580662864085,"mc":[{"id":"1.168236369","rc":[{"batb":[[1,4.3,75.32]],"batl":[[0,5.1,17.23],[1,5.2,9.24]],"ltp":0.0,"tv":0.0,"id":13117301},{"batb":[[2,3.2,18.48]],"batl":[[1,3.75,15.12],[2,3.95,15.03]],"ltp":3.95,"tv":4.0,"id":13117300},{"batb":[[2,3.2,18.48]],"batl":[[1,3.7,15.12],[2,4.1,13.93]],"ltp":0.0,"tv":0.0,"id":13117373},{"batb":[[2,4.3,12.6]],"batl":[[0,5.2,9.24],[1,5.6,13.93]],"ltp":0.0,"tv":0.0,"id":13117374}]}]}
{"op":"mcm","clk":"1008989712","pt":1580662876082,"mc":[{"id":"1.168236369","rc":[{"batb":[[1,4.3,62.72]],"ltp":0.0,"tv":0.0,"id":13117301}]}]}
{"op":"mcm","clk":"1008990162","pt":1580662879149,"mc":[{"id":"1.168236369","rc":[{"batb":[[0,4.4,71.03]],"ltp":0.0,"tv":0.0,"id":13117301}]}]}
{"op":"mcm","clk":"1008991561","pt":1580662889116,"mc":[{"id":"1.168236369","rc":[{"batb":[[0,3.2,18.48],[1,2.88,10.46],[2,1.01,0.51]],"batl":[[0,3.75,15.12],[1,3.95,15.03],[2,3.95,0]],"ltp":3.95,"tv":4.0,"id":13117300},{"batb":[[0,3.2,18.48],[1,2.94,24.47],[2,1.01,0.51]],"batl":[[0,3.7,15.12],[1,4.1,13.93],[2,4.1,0]],"ltp":0.0,"tv":0.0,"id":13117373}]}]}
{"op":"mcm","clk":"1008991803","pt":1580662890701,"mc":[{"id":"1.168236369","rc":[{"batb":[[0,4.4,59.27]],"batl":[[1,5.2,0]],"ltp":0.0,"tv":0.0,"id":13117301},{"batb":[[0,2.88,10.46],[1,1.01,0.51],[2,1.01,0]],"batl":[[0,3.95,15.03],[1,3.95,0]],"ltp":3.95,"tv":4.0,"id":13117300},{"batb":[[0,2.94,24.47],[1,1.01,0.51],[2,1.01,0]],"batl":[[0,4.1,13.93],[1,4.1,0]],"ltp":0.0,"tv":0.0,"id":13117373},{"batb":[[2,1.01,0.51]],"batl":[[0,5.6,13.93],[1,5.6,0]],"ltp":0.0,"tv":0.0,"id":13117374}]}]}
{"op":"mcm","clk":"1008992486","pt":1580662895232,"mc":[{"id":"1.168236369","rc":[{"batb":[[0,4.4,43.88],[1,4.3,18.41]],"ltp":0.0,"tv":0.0,"id":13117301},{"batb":[[0,3.2,45.86],[1,2.88,10.46],[2,1.01,0.51]],"ltp":3.95,"tv":4.0,"id":13117300},{"batb":[[0,3.35,42.19],[1,2.94,24.47],[2,1.01,0.51]],"ltp":0.0,"tv":0.0,"id":13117373},{"batb":[[0,4.8,39.45]],"ltp":0.0,"tv":0.0,"id":13117374}]}]}
{"op":"mcm","clk":"1008992877","pt":1580662898129,"mc":[{"id":"1.168236369","rc":[{"batb":[[0,4.5,35.79],[1,4.4,43.88],[2,4.3,18.41]],"ltp":0.0,"tv":0.0,"id":13117301},{"batb":[[0,3.25,49.2],[1,3.2,45.86],[2,2.88,10.46]],"ltp":3.95,"tv":4.0,"id":13117300},{"batb":[[0,3.35,54.34],[1,3.3,43.4],[2,2.94,24.47]],"ltp":0.0,"tv":0.0,"id":13117373}]}]}
{"op":"mcm","clk":"1008993207","pt":1580662900056,"mc":[{"id":"1.168236369","rc":[{"batb":[[0,2.88,10.46],[1,1.01,0.51],[2,2.88,0]],"ltp":3.95,"tv":4.0,"id":13117300},{"batb":[[0,2.94,24.47],[1,1.01,0.51],[2,2.94,0]],"ltp":0.0,"tv":0.0,"id":13117373},{"batb":[[0,4.8,14.16]],"ltp":0.0,"tv":0.0,"id":13117374}]}]}
{"op":"mcm","clk":"1008993670","pt":1580662902937,"mc":[{"id":"1.168236369","rc":[{"batb":[[0,2.96,52.42],[1,2.92,46.38],[2,2.88,10.46]],"ltp":3.95,"tv":4.0,"id":13117300},{"batb":[[0,3.05,64.04],[1,3,54.88],[2,2.94,24.47]],"ltp":0.0,"tv":0.0,"id":13117373},{"batb":[[1,4.7,56.88],[2,4.6,38.86]],"ltp":0.0,"tv":0.0,"id":13117374}]}]}
{"op":"mcm","clk":"1008993849","pt":1580662903942,"mc":[{"id":"1.168236369","rc":[{"batb":[[0,2.88,10.46],[1,1.01,0.51],[2,2.88,0]],"ltp":3.95,"tv":4.0,"id":13117300},{"batb":[[1,4.7,37.49],[2,1.01,0.51]],"ltp":0.0,"tv":0.0,"id":13117374}]}]}
{"op":"mcm","clk":"1008994393","pt":1580662907132,"mc":[{"id":"1.168236369","rc":[{"batb":[[0,3.6,37.76],[1,3.55,35.68],[2,2.88,10.46]],"ltp":3.95,"tv":4.0,"id":13117300},{"batb":[[0,4.8,41.02]],"ltp":0.0,"tv":0.0,"id":13117374}]}]}
{"op":"mcm","clk":"1008994539","pt":1580662908076,"mc":[{"id":"1.168236369","rc":[{"batb":[[2,4.3,31.01]],"batl":[[0,5,17.39],[1,5.2,9.24]],"ltp":0.0,"tv":0.0,"id":13117301},{"batb":[[2,3.5,15.5]],"batl":[[0,3.95,28.47],[1,4.3,24.86]],"ltp":3.95,"tv":4.0,"id":13117300},{"batb":[[0,3.05,84.2]],"batl":[[0,3.25,23.53],[1,3.55,15.96],[2,3.65,17.94]],"ltp":0.0,"tv":0.0,"id":13117373},{"batl":[[0,5.2,9.24],[1,5.6,13.93]],"ltp":0.0,"tv":0.0,"id":13117374}]}]}
{"op":"mcm","clk":"1008994721","pt":1580662909137,"mc":[{"id":"1.168236369","rc":[{"batb":[[2,4.4,11.76]],"ltp":0.0,"tv":0.0,"id":13117374}]}]}
{"op":"mcm","clk":"1008994843","pt":1580662909974,"mc":[{"id":"1.168236369","rc":[{"batb":[[2,1.01,0.51]],"ltp":0.0,"tv":0.0,"id":13117374}]}]}
{"op":"mcm","clk":"1008995164","pt":1580662912043,"mc":[{"id":"1.168236369","rc":[{"batb":[[2,4.3,12.6]],"ltp":0.0,"tv":0.0,"id":13117374}]}]}
{"op":"mcm","clk":"1008996194","pt":1580662919236,"mc":[{"id":"1.168236369","rc":[{"trd":[[3.05,0.44]],"batb":[[0,3.05,83.98]],"ltp":3.05,"tv":0.44,"id":13117373}],"tv":4.44}]}
{"op":"mcm","clk":"1008996503","pt":1580662921204,"mc":[{"id":"1.168236369","rc":[{"batb":[[0,3.4,16.8],[1,3.15,20.54],[2,1.01,0.51]],"batl":[[0,3.95,13.44]],"ltp":3.95,"tv":4.0,"id":13117300},{"batb":[[0,3.05,20.16],[1,2.8,11.09],[2,1.01,0.51]],"batl":[[0,3.55,15.96],[1,3.65,17.94],[2,3.65,0]],"ltp":3.05,"tv":0.44,"id":13117373}]}]}
{"op":"mcm","clk":"1008996747","pt":1580662922894,"mc":[{"id":"1.168236369","rc":[{"batb":[[2,4.3,18.41]],"batl":[[1,5.2,0]],"ltp":0.0,"tv":0.0,"id":13117301},{"batb":[[0,3.15,20.54],[1,1.01,0.51],[2,1.01,0]],"batl":[[0,4.3,24.86],[1,4.3,0]],"ltp":3.95,"tv":4.0,"id":13117300},{"batb":[[0,2.8,11.09],[1,1.01,0.51],[2,1.01,0]],"batl":[[0,3.65,17.94],[1,3.65,0]],"ltp":3.05,"tv":0.44,"id":13117373},{"batb":[[2,1.01,0.51]],"batl":[[0,5.6,13.93],[1,5.6,0]],"ltp":0.0,"tv":0.0,"id":13117374}]}]}
{"op":"mcm","clk":"1008996924","pt":1580662924052,"mc":[{"id":"1.168236369","rc":[{"batb":[[0,3.25,36.03],[1,3.2,46.02],[2,3.15,20.54]],"ltp":3.95,"tv":4.0,"id":13117300},{"batb":[[0,2.92,47.73],[1,2.88,48.98],[2,2.8,11.09]],"ltp":3.05,"tv":0.44,"id":13117373}]}]}
{"op":"mcm","clk":"1008998479","pt":1580662934100,"mc":[{"id":"1.168236369","rc":[{"batb":[[0,4.3,18.41],[1,1.01,0.51],[2,4.3,0]],"ltp":0.0,"tv":0.0,"id":13117301},{"batb":[[0,3.15,20.54],[1,1.01,0.51],[2,3.15,0]],"ltp":3.95,"tv":4.0,"id":13117300},{"batb":[[0,2.8,11.09],[1,1.01,0.51],[2,2.8,0]],"ltp":3.05,"tv":0.44,"id":13117373},{"batb":[[0,4.8,14.16],[1,1.01,0.51],[2,1.01,0]],"ltp":0.0,"tv":0.0,"id":13117374}]}]}
{"op":"mcm","clk":"1009005242","pt":1580662978140,"mc":[{"id":"1.168236369","rc":[{"batb":[[0,4.5,31.89],[1,4.4,42.6],[2,4.3,18.41]],"ltp":0.0,"tv":0.0,"id":13117301},{"batb":[[0,3.8,51.85],[1,3.75,31.14],[2,3.15,20.54]],"ltp":3.95,"tv":4.0,"id":13117300},{"batb":[[0,2.92,47.73],[1,2.88,48.98],[2,2.8,11.09]],"ltp":3.05,"tv":0.44,"id":13117373},{"batb":[[0,4.8,42.28],[1,4.7,37.48],[2,1.01,0.51]],"ltp":0.0,"tv":0.0,"id":13117374}]}]}
{"op":"mcm","clk":"1009005421","pt":1580662979171,"mc":[{"id":"1.168236369","rc":[{"batb":[[1,3.75,44.28],[2,3.45,16.37]],"batl":[[1,4.6,21.95]],"ltp":3.95,"tv":4.0,"id":13117300},{"batl":[[0,3.05,10.94],[1,3.35,22.03]],"ltp":3.05,"tv":0.44,"id":13117373},{"batl":[[0,5.6,13.77]],"ltp":0.0,"tv":0.0,"id":13117374}]}]}
{"op":"mcm","clk":"1009005557","pt":1580662979845,"mc":[{"id":"1.168236369","rc":[{"batb":[[2,4.3,31.01]],"batl":[[1,5.2,9.24]],"ltp":0.0,"tv":0.0,"id":13117301},{"batb":[[2,3.55,15.96]],"batl":[[0,4.2,12.6],[1,4.3,24.86],[2,4.6,21.95]],"ltp":3.95,"tv":4.0,"id":13117300},{"batb":[[1,2.88,70.83]],"batl":[[2,3.4,16.8]],"ltp":3.05,"tv":0.44,"id":13117373},{"batb":[[2,4.3,12.6]],"batl":[[0,5.2,9.24],[1,5.6,13.77]],"ltp":0.0,"tv":0.0,"id":13117374}]}]}
{"op":"mcm","clk":"1009007329","pt":1580662991244,"mc":[{"id":"1.168236369","rc":[{"batb":[[0,3.55,15.96],[1,3.45,16.37],[2,1.01,0.51]],"batl":[[1,4.6,21.95],[2,4.6,0]],"ltp":3.95,"tv":4.0,"id":13117300},{"batb":[[0,2.88,21.85],[1,2.68,12.35],[2,1.01,0.51]],"batl":[[0,3.35,22.03],[1,3.4,16.8],[2,3.4,0]],"ltp":3.05,"tv":0.44,"id":13117373}]}]}
{"op":"mcm","clk":"1009007665","pt":1580662993172,"mc":[{"id":"1.168236369","rc":[{"batb":[[2,4.3,18.41]],"batl":[[1,5.2,0]],"ltp":0.0,"tv":0.0,"id":13117301},{"batb":[[0,3.45,16.37],[1,1.01,0.51],[2,1.01,0]],"batl":[[0,4.6,21.95],[1,4.6,0]],"ltp":3.95,"tv":4.0,"id":13117300},{"batb":[[0,2.68,12.35],[1,1.01,0.51],[2,1.01,0]],"batl":[[1,3.4,0]],"ltp":3.05,"tv":0.44,"id":13117373},{"batb":[[2,1.01,0.51]],"batl":[[0,5.6,13.77],[1,5.6,0]],"ltp":0.0,"tv":0.0,"id":13117374}]}]}
{"op":"mcm","clk":"1009007832","pt":1580662994166,"mc":[{"id":"1.168236369","rc":[{"batb":[[0,3.55,33.33],[1,3.5,36.97],[2,3.45,16.37]],"ltp":3.95,"tv":4.0,"id":13117300},{"batb":[[0,2.82,57.93],[1,2.78,53.56],[2,2.68,12.35]],"ltp":3.05,"tv":0.44,"id":13117373}]}]}
{"op":"mcm","clk":"1009008186","pt":1580662996553,"mc":[{"id":"1.168236369","rc":[{"batb":[[0,3.45,16.37],[1,1.01,0.51],[2,3.45,0]],"ltp":3.95,"tv":4.0,"id":13117300}]}]}
{"op":"mcm","clk":"1009008775","pt":1580662999979,"mc":[{"id":"1.168236369","rc":[{"batb":[[1,4.4,54.36]],"batl":[[1,5.2,9.24]],"ltp":0.0,"tv":0.0,"id":13117301},{"batb":[[0,4,31.64],[1,3.95,50.81],[2,3.75,13.53]],"batl":[[0,4.4,11.76],[1,4.6,21.95],[2,4.8,19.2]],"ltp":3.95,"tv":4.0,"id":13117300},{"batb":[[1,2.8,22.69],[2,2.78,53.56]],"batl":[[0,2.92,12.12],[1,3.1,10.54],[2,3.25,18.48]],"ltp":3.05,"tv":0.44,"id":13117373},{"batb":[[2,4.3,12.6]],"batl":[[0,5.2,9.24],[1,5.6,13.77]],"ltp":0.0,"tv":0.0,"id":13117374}]}]}
{"op":"mcm","clk":"1009010403","pt":1580663009977,"mc":[{"id":"1.168236369","rc":[{"batb":[[0,4.4,54.36],[1,4.3,18.41],[2,1.01,0.51]],"ltp":0.0,"tv":0.0,"id":13117301},{"batb":[[0,3.75,13.53],[1,3.7,15.12],[2,1.01,0.51]],"batl":[[1,4.8,19.2],[2,4.8,0]],"ltp":3.95,"tv":4.0,"id":13117300},{"batb":[[0,2.8,22.69],[1,2.78,53.56],[2,2.6,13.38]],"batl":[[0,3.1,10.54],[1,3.25,18.48],[2,3.25,0]],"ltp":3.05,"tv":0.44,"id":13117373}]}]}
{"op":"mcm","clk":"1009010533","pt":1580663010772,"mc":[{"id":"1.168236369","rc":[{"batb":[[0,4.4,42.6]],"batl":[[1,5.2,0]],"ltp":0.0,"tv":0.0,"id":13117301},{"batb":[[1,1.01,0.51],[2,1.01,0]],"batl":[[0,4.8,19.2],[1,4.8,0]],"ltp":3.95,"tv":4.0,"id":13117300},{"batb":[[0,2.78,53.56],[1,2.6,13.38],[2,1.01,0.51]],"batl":[[1,3.25,0]],"ltp":3.05,"tv":0.44,"id":13117373},{"batb":[[2,1.01,0.51]],"batl":[[0,5.6,13.77],[1,5.6,0]],"ltp":0.0,"tv":0.0,"id":13117374}]}]}
{"op":"mcm","clk":"1009010958","pt":1580663013168,"mc":[{"id":"1.168236369","rc":[{"batb":[[1,2.74,55.72],[2,2.6,13.38]],"ltp":3.05,"tv":0.44,"id":13117373}]}]}
{"op":"mcm","clk":"1009011475","pt":1580663016064,"mc":[{"id":"1.168236369","rc":[{"batb":[[0,4.5,43.4],[1,4.4,54.36],[2,4.3,18.41]],"batl":[[1,5.3,9.24]],"ltp":0.0,"tv":0.0,"id":13117301},{"batb":[[0,4.1,30.91],[1,4,53.09],[2,3.9,14.28]],"batl":[[0,4.6,10.92],[1,4.8,19.2]],"ltp":3.95,"tv":4.0,"id":13117300},{"batb":[[2,2.72,24.37]],"batl":[[1,3.15,19.32]],"ltp":3.05,"tv":0.44,"id":13117373},{"batb":[[2,4.2,12.6]],"batl":[[0,5.1,10.08],[1,5.6,13.77]],"ltp":0.0,"tv":0.0,"id":13117374}]}]}
{"op":"mcm","clk":"1009011560","pt":1580663016585,"mc":[{"id":"1.168236369","rc":[{"batl":[[0,5.1,17.07]],"ltp":0.0,"tv":0.0,"id":13117301},{"batb":[[0,4.2,20.22],[1,4.1,30.91],[2,4,53.09]],"batl":[[2,5.8,13.06]],"ltp":3.95,"tv":4.0,"id":13117300},{"batl":[[0,2.82,13.14],[1,3.05,10.94],[2,3.15,19.32]],"ltp":3.05,"tv":0.44,"id":13117373},{"batl":[[1,5.7,13.38]],"ltp":0.0,"tv":0.0,"id":13117374}]}]}
{"op":"mcm","clk":"1009012198","pt":1580663020420,"mc":[{"id":"1.168236369","rc":[{"batb":[[1,4.4,11.76]],"ltp":0.0,"tv":0.0,"id":13117301},{"batb":[[0,2.74,55.72],[1,2.72,24.37],[2,2.6,13.38]],"ltp":3.05,"tv":0.44,"id":13117373},{"batb":[[0,4.8,14.16]],"ltp":0.0,"tv":0.0,"id":13117374}]}]}
{"op":"mcm","clk":"1009012846","pt":1580663024005,"mc":[{"id":"1.168236369","rc":[{"batb":[[0,4.6,26.28],[1,4.5,43.4],[2,4.4,11.76]],"ltp":0.0,"tv":0.0,"id":13117301},{"batb":[[1,4.1,58.56]],"ltp":3.95,"tv":4.0,"id":13117300},{"batb":[[2,2.7,57.51]],"ltp":3.05,"tv":0.44,"id":13117373},{"batb":[[2,4.6,38.82]],"ltp":0.0,"tv":0.0,"id":13117374}]}]}
{"op":"mcm","clk":"1009015798","pt":1580663041028,"mc":[{"id":"1.168236369","rc":[{"batl":[[0,5,17.39]],"ltp":0.0,"tv":0.0,"id":13117301},{"batb":[[0,4.1,79.17],[1,4,53.09],[2,3.9,14.28]],"batl":[[2,5.7,13.38]],"ltp":3.95,"tv":4.0,"id":13117300},{"batl":[[0,2.84,12.9],[1,3.05,10.78]],"ltp":3.05,"tv":0.44,"id":13117373},{"batl":[[1,5.7,13.22]],"ltp":0.0,"tv":0.0,"id":13117374}]}]}
{"op":"mcm","clk":"1009018168","pt":1580663054416,"mc":[{"id":"1.168236369","rc":[{"batl":[[0,5.1,17.39]],"ltp":0.0,"tv":0.0,"id":13117301}]}]}
{"op":"mcm","clk":"1009019523","pt":1580663062171,"mc":[{"id":"1.168236369","rc":[{"batb":[[0,4.2,20.46],[1,4.1,79.17],[2,4,53.09]],"ltp":3.95,"tv":4.0,"id":13117300},{"batl":[[1,5.6,14.08],[2,5.7,13.22]],"ltp":0.0,"tv":0.0,"id":13117374}]}]}
{"op":"mcm","clk":"1009019732","pt":1580663063169,"mc":[{"id":"1.168236369","rc":[{"batl":[[0,5.1,17.23]],"ltp":0.0,"tv":0.0,"id":13117301},{"batb":[[1,4.1,58.56]],"batl":[[2,5.7,13.22]],"ltp":3.95,"tv":4.0,"id":13117300}]}]}
{"op":"mcm","clk":"1009027700","pt":1580663107036,"mc":[{"id":"1.168236369","rc":[{"batb":[[2,4.3,18.41]],"batl":[[1,5.3,0]],"ltp":0.0,"tv":0.0,"id":13117301},{"batb":[[0,3.8,13.06],[1,1.01,0.51],[2,4,0]],"batl":[[0,5.7,13.22],[1,4.8,0],[2,5.7,0]],"ltp":3.95,"tv":4.0,"id":13117300},{"batb":[[0,2.34,17.78],[1,1.01,0.51],[2,2.7,0]],"batl":[[0,3.05,10.78],[1,3.05,0],[2,3.15,0]],"ltp":3.05,"tv":0.44,"id":13117373},{"batb":[[1,4.7,28.41]],"batl":[[0,5.7,13.22],[1,5.6,0],[2,5.7,0]],"ltp":0.0,"tv":0.0,"id":13117374}]}]}
{"op":"mcm","clk":"1009028190","pt":1580663109913,"mc":[{"id":"1.168236369","rc":[{"batb":[[0,3.8,66.51],[1,3.75,31.47],[2,1.01,0.51]],"ltp":3.95,"tv":4.0,"id":13117300},{"batb":[[0,2.48,42.78],[1,2.44,75.39],[2,2.34,17.78]],"ltp":3.05,"tv":0.44,"id":13117373}]}]}
{"op":"mcm","clk":"1009028934","pt":1580663114147,"mc":[{"id":"1.168236369","rc":[{"batb":[[0,3.8,13.06],[1,1.01,0.51],[2,1.01,0]],"ltp":3.95,"tv":4.0,"id":13117300},{"batb":[[2,1.01,0.51]],"ltp":0.0,"tv":0.0,"id":13117374}]}]}
{"op":"mcm","clk":"1009029494","pt":1580663117201,"mc":[{"id":"1.168236369","rc":[{"batb":[[0,4.6,41.35]],"ltp":0.0,"tv":0.0,"id":13117301},{"batb":[[0,4.9,30.93],[1,4.8,35.27],[2,3.8,13.06]],"ltp":3.95,"tv":4.0,"id":13117300},{"batb":[[0,4.8,35.33],[1,4.7,37.28]],"ltp":0.0,"tv":0.0,"id":13117374}]}]}
{"op":"mcm","clk":"1009029654","pt":1580663118217,"mc":[{"id":"1.168236369","rc":[{"batb":[[2,4.4,11.76]],"batl":[[0,5.1,17.07],[1,5.3,9.24]],"ltp":0.0,"tv":0.0,"id":13117301},{"batb":[[0,4.9,44.7],[2,4.4,11.76]],"batl":[[0,5.3,9.24],[1,5.7,13.22],[2,7.8,14.32]],"ltp":3.95,"tv":4.0,"id":13117300},{"batb":[[0,2.5,27.73],[1,2.48,42.78],[2,2.44,75.39]],"batl":[[0,2.54,17.39],[1,2.76,13.93]],"ltp":3.05,"tv":0.44,"id":13117373},{"batb":[[0,4.9,13.85],[1,4.8,35.33],[2,4.7,37.28]],"batl":[[0,5.2,9.24],[1,5.7,13.22],[2,5.9,12.43]],"ltp":0.0,"tv":0.0,"id":13117374}]}]}
{"op":"mcm","clk":"1009030174","pt":1580663121131,"mc":[{"id":"1.168236369","rc":[{"batl":[[2,2.86,21.85]],"ltp":3.05,"tv":0.44,"id":13117373}]}]}
{"op":"mcm","clk":"1009030375","pt":1580663122248,"mc":[{"id":"1.168236369","rc":[{"batb":[[1,4.8,14.16]],"ltp":0.0,"tv":0.0,"id":13117374}]}]}
{"op":"mcm","clk":"1009030876","pt":1580663125215,"mc":[{"id":"1.168236369","rc":[{"batb":[[2,4.7,58.6]],"ltp":0.0,"tv":0.0,"id":13117374}]}]}
{"op":"mcm","clk":"1009031385","pt":1580663128209,"mc":[{"id":"1.168236369","rc":[{"batb":[[0,4.9,13.77],[1,4.4,11.76],[2,4.3,18.96]],"ltp":3.95,"tv":4.0,"id":13117300},{"batb":[[1,2.34,17.78],[2,2.08,24.71]],"ltp":3.05,"tv":0.44,"id":13117373},{"batb":[[2,4.7,40.14]],"ltp":0.0,"tv":0.0,"id":13117374}]}]}
{"op":"mcm","clk":"1009031568","pt":1580663129211,"mc":[{"id":"1.168236369","rc":[{"batb":[[2,4.3,18.41]],"batl":[[1,5.3,0]],"ltp":0.0,"tv":0.0,"id":13117301},{"batb":[[0,4.3,18.96],[1,1.01,0.51],[2,4.3,0]],"batl":[[0,7.8,14.32],[1,5.7,0],[2,7.8,0]],"ltp":3.95,"tv":4.0,"id":13117300},{"batb":[[0,2.08,24.71],[1,1.01,0.51],[2,2.08,0]],"batl":[[0,2.76,13.93],[1,2.76,0],[2,2.86,0]],"ltp":3.05,"tv":0.44,"id":13117373},{"batb":[[0,4.8,14.16],[1,4.7,40.14],[2,4.6,38.53]],"batl":[[0,5.9,12.43],[1,5.7,0],[2,5.9,0]],"ltp":0.0,"tv":0.0,"id":13117374}]}]}
{"op":"mcm","clk":"1009031923","pt":1580663131212,"mc":[{"id":"1.168236369","rc":[{"batb":[[0,4.3,56.15],[1,4.2,47.83],[2,1.01,0.51]],"ltp":3.95,"tv":4.0,"id":13117300},{"batb":[[0,2.18,88.7],[1,2.16,53.43],[2,2.08,24.71]],"ltp":3.05,"tv":0.44,"id":13117373}]}]}
{"op":"mcm","clk":"1009032032","pt":1580663131958,"mc":[{"id":"1.168236369","rc":[{"batb":[[0,4.3,37.19],[1,4.2,67.34]],"batl":[[0,7.6,14.79]],"ltp":3.95,"tv":4.0,"id":13117300},{"batb":[[2,2.1,24.39]],"batl":[[0,2.78,13.69]],"ltp":3.05,"tv":0.44,"id":13117373}]}]}
{"op":"mcm","clk":"1009034109","pt":1580663143950,"mc":[{"id":"1.168236369","rc":[{"batb":[[0,4.2,19.51],[1,1.01,0.51],[2,1.01,0]],"ltp":3.95,"tv":4.0,"id":13117300},{"batb":[[0,2.1,24.39],[1,1.01,0.51],[2,2.1,0]],"ltp":3.05,"tv":0.44,"id":13117373},{"batb":[[1,4.7,37.28],[2,1.01,0.51]],"ltp":0.0,"tv":0.0,"id":13117374}]}]}
{"op":"mcm","clk":"1009034710","pt":1580663147232,"mc":[{"id":"1.168236369","rc":[{"batb":[[0,5.1,44],[1,5,31.95],[2,4.2,19.51]],"ltp":3.95,"tv":4.0,"id":13117300},{"batb":[[0,2.4,78.05],[1,2.36,82.41],[2,2.1,24.39]],"ltp":3.05,"tv":0.44,"id":13117373},{"batb":[[0,4.8,41.3]],"ltp":0.0,"tv":0.0,"id":13117374}]}]}
{"op":"mcm","clk":"1009035153","pt":1580663149559,"mc":[{"id":"1.168236369","rc":[{"batb":[[0,4.2,19.51],[1,1.01,0.51],[2,4.2,0]],"ltp":3.95,"tv":4.0,"id":13117300},{"batb":[[0,2.1,24.39],[1,1.01,0.51],[2,2.1,0]],"ltp":3.05,"tv":0.44,"id":13117373},{"batb":[[0,4.8,14.16]],"ltp":0.0,"tv":0.0,"id":13117374}]}]}
{"op":"mcm","clk":"1009035651","pt":1580663152352,"mc":[{"id":"1.168236369","rc":[{"batb":[[0,4.3,37.19],[1,4.2,67.34],[2,1.01,0.51]],"ltp":3.95,"tv":4.0,"id":13117300},{"batb":[[0,2.18,88.7],[1,2.16,53.43],[2,2.1,24.39]],"ltp":3.05,"tv":0.44,"id":13117373},{"batb":[[2,4.6,38.81]],"ltp":0.0,"tv":0.0,"id":13117374}]}]}
{"op":"mcm","clk":"1009037329","pt":1580663161874,"mc":[{"id":"1.168236369","rc":[{"batb":[[0,2.1,24.39],[1,1.01,0.51],[2,2.1,0]],"ltp":3.05,"tv":0.44,"id":13117373}]}]}
{"op":"mcm","clk":"1009037835","pt":1580663164578,"mc":[{"id":"1.168236369","rc":[{"batb":[[0,2.68,43.95],[1,2.64,61.06],[2,2.1,24.39]],"ltp":3.05,"tv":0.44,"id":13117373}]}]}
{"op":"mcm","clk":"1009038050","pt":1580663165768,"mc":[{"id":"1.168236369","rc":[{"batb":[[1,4.5,55.16]],"batl":[[1,5.3,9.24]],"ltp":0.0,"tv":0.0,"id":13117301},{"batb":[[2,4,13.44]],"batl":[[0,4.8,10.92],[1,4.9,18.73],[2,6.2,11.25]],"ltp":3.95,"tv":4.0,"id":13117300},{"batb":[[1,2.64,86.27],[2,2.58,13.85]],"batl":[[0,2.78,13.53],[1,3.05,31.1]],"ltp":3.05,"tv":0.44,"id":13117373},{"batl":[[0,5.1,10.08],[1,5.6,13.85],[2,5.7,13.14]],"ltp":0.0,"tv":0.0,"id":13117374}]}]}
{"op":"mcm","clk":"1009042335","pt":1580663189215,"mc":[{"id":"1.168236369","rc":[{"batb":[[0,4.2,19.51],[1,4,13.44],[2,3.75,13.14]],"ltp":3.95,"tv":4.0,"id":13117300},{"batb":[[0,2.64,25.21],[1,2.58,13.85],[2,2.26,19.51]],"ltp":3.05,"tv":0.44,"id":13117373},{"batb":[[1,4.6,38.81],[2,4.2,12.6]],"ltp":0.0,"tv":0.0,"id":13117374}]}]}
{"op":"mcm","clk":"1009042401","pt":1580663189500,"mc":[{"id":"1.168236369","rc":[{"batb":[[0,4,13.44],[1,3.75,13.14],[2,1.01,0.51]],"batl":[[1,6.2,11.25],[2,6.2,0]],"ltp":3.95,"tv":4.0,"id":13117300},{"batb":[[1,2.26,19.51],[2,1.01,0.51]],"batl":[[0,3.05,31.1],[1,3.05,0]],"ltp":3.05,"tv":0.44,"id":13117373},{"batl":[[1,5.7,13.14],[2,5.7,0]],"ltp":0.0,"tv":0.0,"id":13117374}]}]}
{"op":"mcm","clk":"1009042615","pt":1580663190908,"mc":[{"id":"1.168236369","rc":[{"batb":[[1,4.5,43.4]],"batl":[[1,5.3,0]],"ltp":0.0,"tv":0.0,"id":13117301},{"batb":[[0,3.75,13.14],[1,1.01,0.51],[2,1.01,0]],"batl":[[0,6.2,11.25],[1,6.2,0]],"ltp":3.95,"tv":4.0,"id":13117300},{"batb":[[0,2.26,19.51],[1,1.01,0.51],[2,1.01,0]],"batl":[[0,3.05,10.94]],"ltp":3.05,"tv":0.44,"id":13117373},{"batb":[[2,1.01,0.51]],"batl":[[0,5.7,13.14],[1,5.7,0]],"ltp":0.0,"tv":0.0,"id":13117374}]}]}
{"op":"mcm","clk":"1009043065","pt":1580663193200,"mc":[{"id":"1.168236369","rc":[{"batb":[[2,4.4,18.18]],"batl":[[0,5.1,16.92]],"ltp":0.0,"tv":0.0,"id":13117301},{"batb":[[0,3.9,36.44],[1,3.85,29.83],[2,3.8,13.06]],"ltp":3.95,"tv":4.0,"id":13117300},{"batb":[[0,2.36,60.9],[1,2.32,86.37],[2,2.26,19.51]],"ltp":3.05,"tv":0.44,"id":13117373},{"batb":[[0,4.7,15.03],[1,4.6,56.16],[2,4.5,40.4]],"ltp":0.0,"tv":0.0,"id":13117374}]}]}
{"op":"mcm","clk":"1009043175","pt":1580663193853,"mc":[{"id":"1.168236369","rc":[{"batb":[[0,2.26,19.51],[1,1.01,0.51],[2,2.26,0]],"ltp":3.05,"tv":0.44,"id":13117373}]}]}
{"op":"mcm","clk":"1009043576","pt":1580663196187,"mc":[{"id":"1.168236369","rc":[{"batb":[[2,4.4,29.94]],"batl":[[1,5.3,9.24]],"ltp":0.0,"tv":0.0,"id":13117301},{"batl":[[0,4.3,24.63],[1,4.4,11.76],[2,5.1,16.84]],"ltp":3.95,"tv":4.0,"id":13117300},{"batb":[[0,2.88,43.33],[1,2.84,50.39],[2,2.82,22.69]],"batl":[[1,3.25,18.48],[2,3.3,22.82]],"ltp":3.05,"tv":0.44,"id":13117373},{"batl":[[0,5,10.08],[1,5.6,14.08]],"ltp":0.0,"tv":0.0,"id":13117374}]}]}
{"op":"mcm","clk":"1009046268","pt":1580663211218,"mc":[{"id":"1.168236369","rc":[{"batb":[[2,4.4,18.18]],"batl":[[1,5.3,0]],"ltp":0.0,"tv":0.0,"id":13117301},{"batb":[[0,3.5,15.5],[1,1.01,0.51],[2,3.8,0]],"batl":[[0,5.1,16.84],[1,4.4,0],[2,5.1,0]],"ltp":3.95,"tv":4.0,"id":13117300},{"batb":[[0,2.5,14.95],[1,1.01,0.51],[2,2.82,0]],"batl":[[0,3.3,22.82],[1,3.25,0],[2,3.3,0]],"ltp":3.05,"tv":0.44,"id":13117373},{"batb":[[1,4.6,44.34]],"batl":[[0,5.6,14.08],[1,5.6,0]],"ltp":0.0,"tv":0.0,"id":13117374}]}]}
{"op":"mcm","clk":"1009046666","pt":1580663213315,"mc":[{"id":"1.168236369","rc":[{"batb":[[0,3.6,60.29],[1,3.55,36.03],[2,3.5,15.5]],"ltp":3.95,"tv":4.0,"id":13117300},{"batb":[[0,2.6,46.18],[1,2.56,66.07],[2,2.5,14.95]],"ltp":3.05,"tv":0.44,"id":13117373}]}]}
{"op":"mcm","clk":"1009048632","pt":1580663223750,"mc":[{"id":"1.168236369","rc":[{"batb":[[0,4.4,18.18],[1,1.01,0.51],[2,4.4,0]],"ltp":0.0,"tv":0.0,"id":13117301},{"batb":[[0,3.5,15.5],[1,1.01,0.51],[2,3.5,0]],"ltp":3.95,"tv":4.0,"id":13117300},{"batb":[[0,2.5,14.95],[1,1.01,0.51],[2,2.5,0]],"ltp":3.05,"tv":0.44,"id":13117373},{"batb":[[1,1.01,0.51],[2,4.5,0]],"ltp":0.0,"tv":0.0,"id":13117374}]}]}
{"op":"mcm","clk":"1009056335","pt":1580663266521,"mc":[{"id":"1.168236369","rc":[{"batb":[[0,4.6,46.56],[1,4.5,40.94],[2,4.4,18.18]],"ltp":0.0,"tv":0.0,"id":13117301},{"batb":[[0,4,42.56],[1,3.95,28.05],[2,3.5,15.5]],"ltp":3.95,"tv":4.0,"id":13117300},{"batb":[[0,2.82,39.92],[1,2.78,53.24],[2,2.5,14.95]],"ltp":3.05,"tv":0.44,"id":13117373},{"batb":[[1,4.6,57.68],[2,4.5,40.35]],"ltp":0.0,"tv":0.0,"id":13117374}]}]}
{"op":"mcm","clk":"1009057692","pt":1580663273733,"mc":[{"id":"1.168236369","rc":[{"batb":[[0,3.5,15.5],[1,1.01,0.51],[2,3.5,0]],"ltp":3.95,"tv":4.0,"id":13117300},{"batb":[[0,2.5,14.95],[1,1.01,0.51],[2,2.5,0]],"ltp":3.05,"tv":0.44,"id":13117373},{"batb":[[1,4.6,44.34]],"ltp":0.0,"tv":0.0,"id":13117374}]}]}
{"op":"mcm","clk":"1009058219","pt":1580663276635,"mc":[{"id":"1.168236369","rc":[{"batb":[[0,3.6,60.29],[1,3.55,36.03],[2,3.5,15.5]],"ltp":3.95,"tv":4.0,"id":13117300},{"batb":[[0,2.6,46.18],[1,2.56,66.07],[2,2.5,14.95]],"ltp":3.05,"tv":0.44,"id":13117373}]}]}
{"op":"mcm","clk":"1009059776","pt":1580663284843,"mc":[{"id":"1.168236369","rc":[{"batb":[[0,2.5,14.95],[1,1.01,0.51],[2,2.5,0]],"ltp":3.05,"tv":0.44,"id":13117373}]}]}
{"op":"mcm","clk":"1009060366","pt":1580663288161,"mc":[{"id":"1.168236369","rc":[{"batb":[[2,4.4,29.94]],"batl":[[1,5.3,9.24]],"ltp":0.0,"tv":0.0,"id":13117301},{"batb":[[2,3.5,32.3]],"batl":[[0,3.95,15.03],[1,4.1,13.44],[2,4.4,23.84]],"ltp":3.95,"tv":4.0,"id":13117300},{"batb":[[0,3.05,54.29],[1,3,54.46],[2,2.98,44.77]],"batl":[[1,3.45,36.87]],"ltp":3.05,"tv":0.44,"id":13117373},{"batl":[[0,5,10.08],[1,5.5,14.48],[2,5.6,14.08]],"ltp":0.0,"tv":0.0,"id":13117374}]}]}
{"op":"mcm","clk":"1009060419","pt":1580663288439,"mc":[{"id":"1.168236369","rc":[{"batb":[[2,4.4,11.76]],"ltp":0.0,"tv":0.0,"id":13117301},{"batl":[[2,5.6,0]],"ltp":0.0,"tv":0.0,"id":13117374}]}]}
{"op":"mcm","clk":"1009063226","pt":1580663304084,"mc":[{"id":"1.168236369","rc":[{"batb":[[0,4.6,31.98]],"ltp":0.0,"tv":0.0,"id":13117301},{"batb":[[0,3.5,16.8],[1,3.35,17.23],[2,1.01,0.51]],"batl":[[0,4.1,13.44],[1,4.4,23.53],[2,4.4,0]],"ltp":3.95,"tv":4.0,"id":13117300},{"batb":[[0,2.98,21],[1,2.76,11.49],[2,1.01,0.51]],"batl":[[0,3.45,36.87],[1,3.45,0]],"ltp":3.05,"tv":0.44,"id":13117373}]}]}
{"op":"mcm","clk":"1009063355","pt":1580663304887,"mc":[{"id":"1.168236369","rc":[{"batb":[[2,4.3,18.41]],"batl":[[1,5.3,0]],"ltp":0.0,"tv":0.0,"id":13117301},{"batb":[[0,3.35,17.23],[1,1.01,0.51],[2,1.01,0]],"batl":[[0,4.4,23.53],[1,4.4,0]],"ltp":3.95,"tv":4.0,"id":13117300},{"batb":[[0,2.76,11.49],[1,1.01,0.51],[2,1.01,0]],"batl":[[0,3.45,20.06]],"ltp":3.05,"tv":0.44,"id":13117373},{"batl":[[0,5.5,14.48],[1,5.5,0]],"ltp":0.0,"tv":0.0,"id":13117374}]}]}
{"op":"mcm","clk":"1009064142","pt":1580663309672,"mc":[{"id":"1.168236369","rc":[{"batb":[[0,4.6,41.84]],"ltp":0.0,"tv":0.0,"id":13117301},{"batb":[[0,3.65,59.83],[1,3.6,34.84],[2,3.35,17.23]],"ltp":3.95,"tv":4.0,"id":13117300},{"batb":[[0,3,67.82],[1,2.96,45.13],[2,2.76,11.49]],"ltp":3.05,"tv":0.44,"id":13117373}]}]}
{"op":"mcm","clk":"1009064544","pt":1580663312089,"mc":[{"id":"1.168236369","rc":[{"batb":[[0,4.6,31.98]],"ltp":0.0,"tv":0.0,"id":13117301},{"batb":[[0,3.35,17.23],[1,1.01,0.51],[2,3.35,0]],"ltp":3.95,"tv":4.0,"id":13117300},{"batb":[[0,2.76,11.49],[1,1.01,0.51],[2,2.76,0]],"ltp":3.05,"tv":0.44,"id":13117373}]}]}
{"op":"mcm","clk":"1009064944","pt":1580663314508,"mc":[{"id":"1.168236369","rc":[{"batb":[[0,3.5,39.73],[1,3.45,38.83],[2,3.35,17.23]],"ltp":3.95,"tv":4.0,"id":13117300},{"batb":[[0,2.88,40.64],[1,2.84,50.38],[2,2.76,11.49]],"ltp":3.05,"tv":0.44,"id":13117373}]}]}
{"op":"mcm","clk":"1009067503","pt":1580663330229,"mc":[{"id":"1.168236369","rc":[{"batb":[[0,2.76,11.49],[1,1.01,0.51],[2,2.76,0]],"ltp":3.05,"tv":0.44,"id":13117373}]}]}
{"op":"mcm","clk":"1009067937","pt":1580663332713,"mc":[{"id":"1.168236369","rc":[{"batb":[[0,3.15,61.41],[1,3.1,50.07],[2,2.76,11.49]],"ltp":3.05,"tv":0.44,"id":13117373}]}]}
{"op":"mcm","clk":"1009068174","pt":1580663334136,"mc":[{"id":"1.168236369","rc":[{"batb":[[2,4.3,31.01]],"batl":[[0,5,17.47],[1,5.2,9.24]],"ltp":0.0,"tv":0.0,"id":13117301},{"batb":[[2,3.35,34.88]],"batl":[[0,3.75,16.68],[1,3.95,13.44],[2,4.1,13.53]],"ltp":3.95,"tv":4.0,"id":13117300},{"batb":[[0,3.15,80.73],[1,3.1,71.24],[2,2.88,25.57]],"batl":[[1,3.65,15.12],[2,4.1,13.77]],"ltp":3.05,"tv":0.44,"id":13117373},{"batl":[[0,5.1,10.08],[1,5.4,14.71]],"ltp":0.0,"tv":0.0,"id":13117374}]}]}
{"op":"mcm","clk":"1009072789","pt":1580663362140,"mc":[{"id":"1.168236369","rc":[{"batb":[[0,3.35,17.64],[1,2.9,25.26],[2,1.01,0.51]],"batl":[[0,3.95,13.44],[1,4.1,13.53],[2,4.1,0]],"ltp":3.95,"tv":4.0,"id":13117300},{"batb":[[0,3.15,19.32],[1,2.88,25.57],[2,1.01,0.51]],"batl":[[0,3.65,15.12],[1,4.1,13.77],[2,4.1,0]],"ltp":3.05,"tv":0.44,"id":13117373},{"batb":[[1,4.6,29.18]],"ltp":0.0,"tv":0.0,"id":13117374}]}]}
{"op":"mcm","clk":"1009072965","pt":1580663363241,"mc":[{"id":"1.168236369","rc":[{"batb":[[2,4.3,18.41]],"batl":[[1,5.2,0]],"ltp":0.0,"tv":0.0,"id":13117301},{"batb":[[0,2.9,25.26],[1,1.01,0.51],[2,1.01,0]],"batl":[[0,4.1,13.53],[1,4.1,0]],"ltp":3.95,"tv":4.0,"id":13117300},{"batb":[[0,2.88,25.57],[1,1.01,0.51],[2,1.01,0]],"batl":[[0,4.1,13.77],[1,4.1,0]],"ltp":3.05,"tv":0.44,"id":13117373},{"batl":[[0,5.4,14.71],[1,5.4,0]],"ltp":0.0,"tv":0.0,"id":13117374}]}]}
{"op":"mcm","clk":"1009073266","pt":1580663365159,"mc":[{"id":"1.168236369","rc":[{"batl":[[1,5.1,17.23]],"ltp":0.0,"tv":0.0,"id":13117301},{"batb":[[0,2.92,25.02],[1,2.9,25.26],[2,1.01,0.51]],"batl":[[1,4.2,13.38]],"ltp":3.95,"tv":4.0,"id":13117300},{"batb":[[1,4.6,44.92]],"ltp":0.0,"tv":0.0,"id":13117374}]}]}
{"op":"mcm","clk":"1009073437","pt":1580663366052,"mc":[{"id":"1.168236369","rc":[{"batl":[[0,5.1,17.23],[1,5.1,0]],"ltp":0.0,"tv":0.0,"id":13117301},{"batb":[[1,1.01,0.51],[2,1.01,0]],"batl":[[0,4.2,13.38],[1,4.2,0]],"ltp":3.95,"tv":4.0,"id":13117300},{"batb":[[0,2.88,10.39]],"ltp":3.05,"tv":0.44,"id":13117373},{"batb":[[0,4.6,44.92],[1,4.5,40.35],[2,1.01,0.51]],"ltp":0.0,"tv":0.0,"id":13117374}]}]}
{"op":"mcm","clk":"1009073767","pt":1580663367950,"mc":[{"id":"1.168236369","rc":[{"batb":[[0,3.4,43.12],[1,3.35,41.67],[2,2.92,25.02]],"ltp":3.95,"tv":4.0,"id":13117300},{"batb":[[0,3.25,46.95],[1,3.2,46.38],[2,2.88,10.39]],"ltp":3.05,"tv":0.44,"id":13117373},{"batb":[[0,4.6,55.72]],"ltp":0.0,"tv":0.0,"id":13117374}]}]}
{"op":"mcm","clk":"1009073943","pt":1580663368958,"mc":[{"id":"1.168236369","rc":[{"batb":[[0,3.25,32.02]],"ltp":3.05,"tv":0.44,"id":13117373},{"batb":[[0,4.6,46.37]],"ltp":0.0,"tv":0.0,"id":13117374}]}]}
{"op":"mcm","clk":"1009074294","pt":1580663371178,"mc":[{"id":"1.168236369","rc":[{"batb":[[0,2.92,25.02],[1,1.01,0.51],[2,2.92,0]],"ltp":3.95,"tv":4.0,"id":13117300},{"batb":[[0,2.88,10.39],[1,1.01,0.51],[2,2.88,0]],"ltp":3.05,"tv":0.44,"id":13117373},{"batb":[[0,4.6,15.74]],"ltp":0.0,"tv":0.0,"id":13117374}]}]}
{"op":"mcm","clk":"1009074467","pt":1580663372180,"mc":[{"id":"1.168236369","rc":[{"batb":[[0,4.6,42.17]],"ltp":0.0,"tv":0.0,"id":13117301}]}]}
{"op":"mcm","clk":"1009074757","pt":1580663374173,"mc":[{"id":"1.168236369","rc":[{"batb":[[0,3.05,70.32],[1,3,54.72],[2,2.92,25.02]],"ltp":3.95,"tv":4.0,"id":13117300},{"batb":[[0,2.94,48.12],[1,2.9,47.55],[2,2.88,10.39]],"ltp":3.05,"tv":0.44,"id":13117373},{"batb":[[1,4.5,60.32],[2,4.4,42.27]],"ltp":0.0,"tv":0.0,"id":13117374}]}]}
{"op":"mcm","clk":"1009075908","pt":1580663381182,"mc":[{"id":"1.168236369","rc":[{"batb":[[0,2.88,10.39],[1,1.01,0.51],[2,2.88,0]],"ltp":3.05,"tv":0.44,"id":13117373}]}]}
{"op":"mcm","clk":"1009076542","pt":1580663385199,"mc":[{"id":"1.168236369","rc":[{"batl":[[0,5.1,17.07]],"ltp":0.0,"tv":0.0,"id":13117301},{"batl":[[0,3.25,24],[1,3.6,18.49]],"ltp":3.95,"tv":4.0,"id":13117300},{"batb":[[0,3.65,33.72],[1,3.6,49.1],[2,3.25,19.04]],"batl":[[1,5.3,15.66]],"ltp":3.05,"tv":0.44,"id":13117373},{"batb":[[1,4.5,76.76]],"ltp":0.0,"tv":0.0,"id":13117374}]}]}
{"op":"mcm","clk":"1009076730","pt":1580663386210,"mc":[{"id":"1.168236369","rc":[{"batb":[[2,4.4,11.76]],"batl":[[1,5.2,9.24]],"ltp":0.0,"tv":0.0,"id":13117301},{"batb":[[1,3,75.72]],"batl":[[1,3.5,16.8],[2,3.6,18.49]],"ltp":3.95,"tv":4.0,"id":13117300},{"batb":[[2,3.55,15.96]],"batl":[[1,4.2,12.6],[2,5.3,15.66]],"ltp":3.05,"tv":0.44,"id":13117373},{"batl":[[0,5,10.08],[1,5.4,14.71]],"ltp":0.0,"tv":0.0,"id":13117374}]}]}
{"op":"mcm","clk":"1009078772","pt":1580663399222,"mc":[{"id":"1.168236369","rc":[{"batb":[[0,4.6,31.98]],"ltp":0.0,"tv":0.0,"id":13117301},{"batb":[[0,3.05,45.94]],"ltp":3.95,"tv":4.0,"id":13117300},{"batb":[[1,4.5,57.26],[2,4.2,12.6]],"ltp":0.0,"tv":0.0,"id":13117374}]}]}
{"op":"mcm","clk":"1009079228","pt":1580663402021,"mc":[{"id":"1.168236369","rc":[{"batb":[[0,3.65,54.56]],"ltp":3.05,"tv":0.44,"id":13117373},{"batb":[[0,4.6,50.21]],"ltp":0.0,"tv":0.0,"id":13117374}]}]}
{"op":"mcm","clk":"1009079403","pt":1580663403133,"mc":[{"id":"1.168236369","rc":[{"batb":[[2,4.3,18.41]],"batl":[[1,5.2,0]],"ltp":0.0,"tv":0.0,"id":13117301},{"batb":[[0,2.52,14.63],[1,1.01,0.51],[2,2.92,0]],"batl":[[0,3.6,18.49],[1,3.5,0],[2,3.6,0]],"ltp":3.95,"tv":4.0,"id":13117300},{"batb":[[0,3.25,19.04],[1,1.01,0.51],[2,3.55,0]],"batl":[[0,5.3,15.66],[1,4.2,0],[2,5.3,0]],"ltp":3.05,"tv":0.44,"id":13117373},{"batb":[[0,4.5,57.26],[1,1.01,0.51],[2,4.2,0]],"batl":[[0,5.4,14.71],[1,5.4,0]],"ltp":0.0,"tv":0.0,"id":13117374}]}]}
{"op":"mcm","clk":"1009079909","pt":1580663406241,"mc":[{"id":"1.168236369","rc":[{"batb":[[2,4.4,18.1]],"batl":[[0,5.1,16.76]],"ltp":0.0,"tv":0.0,"id":13117301},{"batb":[[0,2.54,14.32]],"batl":[[0,3.65,18.1]],"ltp":3.95,"tv":4.0,"id":13117300},{"batb":[[0,3.2,19.43]],"batl":[[0,5.2,16.05]],"ltp":3.05,"tv":0.44,"id":13117373}]}]}
{"op":"mcm","clk":"1009080413","pt":1580663409014,"mc":[{"id":"1.168236369","rc":[{"batb":[[0,2.96,41.49],[1,2.92,47.15],[2,2.54,14.32]],"ltp":3.95,"tv":4.0,"id":13117300},{"batb":[[0,3.8,53.62],[1,3.75,31.48],[2,3.2,19.43]],"ltp":3.05,"tv":0.44,"id":13117373},{"batb":[[0,4.6,23.98],[1,4.5,57.26],[2,1.01,0.51]],"ltp":0.0,"tv":0.0,"id":13117374}]}]}
{"op":"mcm","clk":"1009081216","pt":1580663414051,"mc":[{"id":"1.168236369","rc":[{"batb":[[0,2.54,14.32],[1,1.01,0.51],[2,2.54,0]],"ltp":3.95,"tv":4.0,"id":13117300},{"batb":[[0,3.2,19.43],[1,1.01,0.51],[2,3.2,0]],"ltp":3.05,"tv":0.44,"id":13117373},{"batb":[[0,4.5,57.26],[1,1.01,0.51],[2,1.01,0]],"ltp":0.0,"tv":0.0,"id":13117374}]}]}
{"op":"mcm","clk":"1009081624","pt":1580663416738,"mc":[{"id":"1.168236369","rc":[{"batb":[[0,2.6,56.76],[1,2.56,66.25],[2,2.54,14.32]],"ltp":3.95,"tv":4.0,"id":13117300},{"batb":[[0,3.25,67.98],[1,3.2,65.64],[2,1.01,0.51]],"ltp":3.05,"tv":0.44,"id":13117373},{"batb":[[1,4.4,42.66],[2,1.01,0.51]],"ltp":0.0,"tv":0.0,"id":13117374}]}]}
{"op":"mcm","clk":"1009083235","pt":1580663426438,"mc":[{"id":"1.168236369","rc":[{"batb":[[0,3.2,19.43],[1,1.01,0.51],[2,1.01,0]],"ltp":3.05,"tv":0.44,"id":13117373}]}]}
{"op":"mcm","clk":"1009083844","pt":1580663430245,"mc":[{"id":"1.168236369","rc":[{"batb":[[0,4.6,47.34],[2,4.4,29.86]],"batl":[[1,5.2,15.97],[2,5.3,9.24]],"ltp":0.0,"tv":0.0,"id":13117301},{"batb":[[0,2.6,82.81]],"batl":[[0,2.76,14.08],[1,3,21],[2,3.05,10.94]],"ltp":3.95,"tv":4.0,"id":13117300},{"batb":[[0,4.6,59.79],[1,4.5,57.14],[2,4.4,11.76]],"batl":[[1,5.3,9.24],[2,7.6,14.56]],"ltp":3.05,"tv":0.44,"id":13117373},{"batb":[[1,4.4,60.13],[2,4.1,13.44]],"batl":[[0,4.9,10.08],[1,5.2,16.13],[2,5.3,15.82]],"ltp":0.0,"tv":0.0,"id":13117374}]}]}
{"op":"mcm","clk":"1009083888","pt":1580663430462,"mc":[{"id":"1.168236369","rc":[{"batb":[[2,4.4,29.47]],"batl":[[0,5.2,15.97],[1,5.3,9.24],[2,5.3,0]],"ltp":0.0,"tv":0.0,"id":13117301},{"batb":[[0,4.5,40.82]],"ltp":0.0,"tv":0.0,"id":13117374}]}]}
{"op":"mcm","clk":"1009087393","pt":1580663452171,"mc":[{"id":"1.168236369","rc":[{"batb":[[0,4.6,34.82]],"ltp":0.0,"tv":0.0,"id":13117301},{"batb":[[0,2.6,26.05],[1,2.2,21.72],[2,1.01,0.51]],"batl":[[0,3,21],[1,3.05,10.94],[2,3.05,0]],"ltp":3.95,"tv":4.0,"id":13117300},{"batb":[[0,4.4,11.76],[1,3.85,24.55],[2,1.01,0.51]],"batl":[[0,5.3,9.24],[1,7.6,14.56],[2,7.6,0]],"ltp":3.05,"tv":0.44,"id":13117373},{"batb":[[0,4.4,60.13],[1,4.1,13.44],[2,1.01,0.51]],"batl":[[1,5.3,15.82],[2,5.3,0]],"ltp":0.0,"tv":0.0,"id":13117374}]}]}
{"op":"mcm","clk":"1009087520","pt":1580663452983,"mc":[{"id":"1.168236369","rc":[{"batb":[[2,4.4,17.7]],"batl":[[1,5.3,0]],"ltp":0.0,"tv":0.0,"id":13117301},{"batb":[[0,2.2,21.72],[1,1.01,0.51],[2,1.01,0]],"batl":[[0,3.05,10.94],[1,3.05,0]],"ltp":3.95,"tv":4.0,"id":13117300},{"batb":[[0,3.85,24.55],[1,1.01,0.51],[2,1.01,0]],"batl":[[0,7.6,14.56],[1,7.6,0]],"ltp":3.05,"tv":0.44,"id":13117373},{"batb":[[1,1.01,0.51],[2,1.01,0]],"batl":[[0,5.3,15.82],[1,5.3,0]],"ltp":0.0,"tv":0.0,"id":13117374}]}]}
{"op":"mcm","clk":"1009087846","pt":1580663455127,"mc":[{"id":"1.168236369","rc":[{"batb":[[2,4.4,17.47]],"batl":[[0,5.3,15.82]],"ltp":0.0,"tv":0.0,"id":13117301},{"batb":[[0,2.22,59.68],[1,2.2,72.13],[2,1.01,0.51]],"batl":[[0,3.1,10.78]],"ltp":3.95,"tv":4.0,"id":13117300},{"batb":[[0,3.95,45.45],[1,3.9,28.73],[2,3.85,24.55]],"ltp":3.05,"tv":0.44,"id":13117373},{"batb":[[0,4.4,82.7],[1,4.3,44.68],[2,1.01,0.51]],"ltp":0.0,"tv":0.0,"id":13117374}]}]}
{"op":"mcm","clk":"1009087955","pt":1580663455864,"mc":[{"id":"1.168236369","rc":[{"batb":[[0,2.2,21.4],[1,1.01,0.51],[2,1.01,0]],"ltp":3.95,"tv":4.0,"id":13117300},{"batb":[[0,3.85,24.55],[1,1.01,0.51],[2,3.85,0]],"ltp":3.05,"tv":0.44,"id":13117373},{"batb":[[0,4.4,60.21],[1,1.01,0.51],[2,1.01,0]],"ltp":0.0,"tv":0.0,"id":13117374}]}]}
{"op":"mcm","clk":"1009088639","pt":1580663460226,"mc":[{"id":"1.168236369","rc":[{"batb":[[0,4.6,51.92]],"ltp":0.0,"tv":0.0,"id":13117301},{"batb":[[0,2.52,46.47],[1,2.48,72.2],[2,2.2,21.4]],"ltp":3.95,"tv":4.0,"id":13117300},{"batb":[[0,5,25.48],[1,4.9,33.72],[2,3.85,24.55]],"ltp":3.05,"tv":0.44,"id":13117373},{"batb":[[0,4.5,42.03],[1,4.4,60.21],[2,1.01,0.51]],"ltp":0.0,"tv":0.0,"id":13117374}]}]}
{"op":"mcm","clk":"1009088958","pt":1580663462176,"mc":[{"id":"1.168236369","rc":[{"batb":[[0,4.6,34.82]],"ltp":0.0,"tv":0.0,"id":13117301},{"batb":[[0,2.2,21.4],[1,1.01,0.51],[2,2.2,0]],"ltp":3.95,"tv":4.0,"id":13117300},{"batb":[[0,3.85,24.55],[1,1.01,0.51],[2,3.85,0]],"ltp":3.05,"tv":0.44,"id":13117373},{"batb":[[0,4.4,60.21],[1,1.01,0.51],[2,1.01,0]],"ltp":0.0,"tv":0.0,"id":13117374}]}]}
{"op":"mcm","clk":"1009089304","pt":1580663464788,"mc":[{"id":"1.168236369","rc":[{"batb":[[1,4.4,17.47],[2,1.01,0.51]],"ltp":0.0,"tv":0.0,"id":13117301},{"batb":[[0,2.22,59.68],[1,2.2,72.13],[2,1.01,0.51]],"ltp":3.95,"tv":4.0,"id":13117300},{"batb":[[0,4.4,82.7],[1,4.3,44.68],[2,1.01,0.51]],"ltp":0.0,"tv":0.0,"id":13117374}]}]}
{"op":"mcm","clk":"1009089669","pt":1580663467228,"mc":[{"id":"1.168236369","rc":[{"batb":[[0,4.7,30.1],[1,4.6,34.82],[2,4.4,17.47]],"ltp":0.0,"tv":0.0,"id":13117301},{"batb":[[0,6.8,31.09],[1,6.6,34.05],[2,3.85,24.55]],"ltp":3.05,"tv":0.44,"id":13117373}]}]}
{"op":"mcm","clk":"1009089812","pt":1580663468179,"mc":[{"id":"1.168236369","rc":[{"batb":[[2,4.5,16.76]],"batl":[[0,5.3,25.06],[1,5.4,15.03]],"ltp":0.0,"tv":0.0,"id":13117301},{"batb":[[0,2.24,33.61],[1,2.22,59.68],[2,2.2,72.13]],"batl":[[0,2.36,20.85],[1,2.54,44.27]],"ltp":3.95,"tv":4.0,"id":13117300},{"batb":[[2,6.2,23.38]],"batl":[[1,7.8,5.88],[2,11.5,15.97]],"ltp":3.05,"tv":0.44,"id":13117373},{"batb":[[2,4,13.44]],"batl":[[0,4.8,10.92],[1,5.1,16.84]],"ltp":0.0,"tv":0.0,"id":13117374}]}]}
{"op":"mcm","clk":"1009091068","pt":1580663477199,"mc":[{"id":"1.168236369","rc":[{"batb":[[2,4.5,28.52]],"ltp":0.0,"tv":0.0,"id":13117301}]}]}
{"op":"mcm","clk":"1009091180","pt":1580663477988,"mc":[{"id":"1.168236369","rc":[{"batb":[[2,4.5,16.76]],"ltp":0.0,"tv":0.0,"id":13117301}]}]}
{"op":"mcm","clk":"1009091887","pt":1580663482699,"mc":[{"id":"1.168236369","rc":[{"batl":[[1,2.54,17.39]],"ltp":3.95,"tv":4.0,"id":13117300}]}]}
{"op":"mcm","clk":"1009092375","pt":1580663486146,"mc":[{"id":"1.168236369","rc":[{"batl":[[1,2.52,26.89],[2,2.54,17.39]],"ltp":3.95,"tv":4.0,"id":13117300}]}]}
{"op":"mcm","clk":"1009092655","pt":1580663488041,"mc":[{"id":"1.168236369","rc":[{"batb":[[0,4.6,34.82],[1,4.5,16.76],[2,4.4,11.76]],"ltp":0.0,"tv":0.0,"id":13117301},{"batb":[[1,2.2,21.4],[2,1.98,29.27]],"ltp":3.95,"tv":4.0,"id":13117300},{"batb":[[0,6.2,23.38],[1,5.4,11.33],[2,1.01,0.51]],"ltp":3.05,"tv":0.44,"id":13117373}]}]}
{"op":"mcm","clk":"1009092809","pt":1580663489055,"mc":[{"id":"1.168236369","rc":[{"batb":[[2,1.01,0.51]],"batl":[[0,5.4,15.03],[1,5.4,0]],"ltp":0.0,"tv":0.0,"id":13117301},{"batb":[[0,1.98,29.27],[1,1.01,0.51],[2,1.98,0]],"batl":[[0,2.54,17.39],[1,2.52,0],[2,2.54,0]],"ltp":3.95,"tv":4.0,"id":13117300},{"batb":[[0,5.4,11.33],[1,1.01,0.51],[2,1.01,0]],"batl":[[0,11.5,15.97],[1,7.8,0],[2,11.5,0]],"ltp":3.05,"tv":0.44,"id":13117373},{"batb":[[2,1.01,0.51]],"batl":[[0,5.1,16.84],[1,5.1,0]],"ltp":0.0,"tv":0.0,"id":13117374}]}]}
{"op":"mcm","clk":"1009093130","pt":1580663491038,"mc":[{"id":"1.168236369","rc":[{"batb":[[0,4.6,56.8],[1,4.5,57.52]],"ltp":0.0,"tv":0.0,"id":13117301},{"batb":[[0,1.99,59.67],[1,1.98,29.27],[2,1.97,70.31]],"batl":[[0,2.52,17.55],[1,2.54,17.39]],"ltp":3.95,"tv":4.0,"id":13117300},{"batb":[[0,5.7,22.74],[1,5.6,25.01],[2,5.4,11.33]],"batl":[[1,12,15.74]],"ltp":3.05,"tv":0.44,"id":13117373},{"batl":[[1,5.2,16.52]],"ltp":0.0,"tv":0.0,"id":13117374}]}]}
{"op":"mcm","clk":"1009093277","pt":1580663491456,"mc":[{"id":"1.168236369","rc":[{"batl":[[1,2.54,0]],"ltp":3.95,"tv":4.0,"id":13117300},{"batb":[[2,5.4,11.09]],"batl":[[0,12,15.74],[1,12,0]],"ltp":3.05,"tv":0.44,"id":13117373},{"batl":[[0,5.2,16.52],[1,5.2,0]],"ltp":0.0,"tv":0.0,"id":13117374}]}]}
{"op":"mcm","clk":"1009093431","pt":1580663492521,"mc":[{"id":"1.168236369","rc":[{"batb":[[0,1.98,29.27],[1,1.01,0.51],[2,1.97,0]],"ltp":3.95,"tv":4.0,"id":13117300},{"batb":[[0,4.4,60.49],[1,1.01,0.51],[2,1.01,0]],"ltp":0.0,"tv":0.0,"id":13117374}]}]}
{"op":"mcm","clk":"1009093883","pt":1580663495149,"mc":[{"id":"1.168236369","rc":[{"batb":[[0,2.38,55.89],[1,2.34,84.55],[2,1.98,29.27]],"ltp":3.95,"tv":4.0,"id":13117300},{"batb":[[0,4.5,25.47],[1,4.4,60.49],[2,1.01,0.51]],"ltp":0.0,"tv":0.0,"id":13117374}]}]}
{"op":"mcm","clk":"1009094033","pt":1580663496159,"mc":[{"id":"1.168236369","rc":[{"batb":[[2,4.4,11.76]],"batl":[[0,5.3,9.24]],"ltp":0.0,"tv":0.0,"id":13117301},{"batb":[[1,2.36,30.25],[2,2.34,84.55]],"batl":[[1,2.68,24.37]],"ltp":3.95,"tv":4.0,"id":13117300},{"batb":[[2,5.4,20.34]],"batl":[[0,6.6,6.72],[1,12,15.74]],"ltp":3.05,"tv":0.44,"id":13117373},{"batb":[[2,4.1,13.44]],"batl":[[0,4.9,10.08],[1,5.2,16.52]],"ltp":0.0,"tv":0.0,"id":13117374}]}]}
{"op":"mcm","clk":"1009094126","pt":1580663496740,"mc":[{"id":"1.168236369","rc":[{"batb":[[2,4.4,29.31]],"batl":[[0,5.2,16.29],[1,5.3,24.66]],"ltp":0.0,"tv":0.0,"id":13117301},{"batb":[[2,2.34,102.49]],"batl":[[2,2.82,13.38]],"ltp":3.95,"tv":4.0,"id":13117300},{"batl":[[0,6.4,10.7],[1,6.6,6.72],[2,11,6.92]],"ltp":3.05,"tv":0.44,"id":13117373},{"batl":[[1,5.1,16.84],[2,5.2,16.05]],"ltp":0.0,"tv":0.0,"id":13117374}]}]}
{"op":"mcm","clk":"1009094723","pt":1580663500566,"mc":[{"id":"1.168236369","rc":[{"batb":[[0,4.6,38.76]],"ltp":0.0,"tv":0.0,"id":13117301},{"batb":[[0,2.36,30.25],[1,2.34,17.94],[2,2,28.25]],"ltp":3.95,"tv":4.0,"id":13117300},{"batb":[[1,5.4,20.34],[2,4.3,18.33]],"ltp":3.05,"tv":0.44,"id":13117373}]}]}
{"op":"mcm","clk":"1009095219","pt":1580663503231,"mc":[{"id":"1.168236369","rc":[{"batb":[[0,2.36,80.91],[2,2.32,86.37]],"ltp":3.95,"tv":4.0,"id":13117300},{"batb":[[0,5.8,20.53],[1,5.7,22.74],[2,5.4,20.34]],"ltp":3.05,"tv":0.44,"id":13117373},{"batb":[[0,4.5,55.72]],"ltp":0.0,"tv":0.0,"id":13117374}]}]}
{"op":"mcm","clk":"1009096146","pt":1580663508754,"mc":[{"id":"1.168236369","rc":[{"batb":[[2,4.4,17.55]],"batl":[[1,5.3,15.42]],"ltp":0.0,"tv":0.0,"id":13117301},{"batl":[[1,2.82,13.38],[2,2.82,0]],"ltp":3.95,"tv":4.0,"id":13117300},{"batl":[[1,11,6.92],[2,11,0]],"ltp":3.05,"tv":0.44,"id":13117373}]}]}
{"op":"mcm","clk":"1009096509","pt":1580663511071,"mc":[{"id":"1.168236369","rc":[{"batb":[[0,4.5,40.76],[1,4.4,17.55],[2,1.01,0.51]],"batl":[[0,5.3,15.42],[1,5.3,0]],"ltp":0.0,"tv":0.0,"id":13117301},{"batb":[[0,2,28.25],[1,1.01,0.51],[2,2.32,0]],"batl":[[0,2.82,13.38],[1,2.82,0]],"ltp":3.95,"tv":4.0,"id":13117300},{"batb":[[0,4.3,18.33],[1,1.01,0.51],[2,5.4,0]],"batl":[[0,11,6.92],[1,11,0]],"ltp":3.05,"tv":0.44,"id":13117373},{"batb":[[0,4.5,25.47],[2,1.01,0.51]],"batl":[[0,5.2,16.05],[1,5.1,0],[2,5.2,0]],"ltp":0.0,"tv":0.0,"id":13117374}]}]}
{"op":"mcm","clk":"1009097032","pt":1580663514157,"mc":[{"id":"1.168236369","rc":[{"batb":[[0,4.5,61.97],[1,4.4,60.12]],"ltp":0.0,"tv":0.0,"id":13117301},{"batb":[[0,1.99,105.47],[1,1.97,70.16],[2,1.01,0.51]],"batl":[[0,2.78,13.61]],"ltp":3.95,"tv":4.0,"id":13117300},{"batb":[[0,4.6,26.17],[1,4.5,41.44],[2,4.4,17.78]],"batl":[[0,11.5,16.21]],"ltp":3.05,"tv":0.44,"id":13117373},{"batl":[[0,5.3,15.66]],"ltp":0.0,"tv":0.0,"id":13117374}]}]}
{"op":"mcm","clk":"1009098211","pt":1580663521197,"mc":[{"id":"1.168236369","rc":[{"batb":[[0,1.99,28.8],[1,1.01,0.51],[2,1.01,0]],"ltp":3.95,"tv":4.0,"id":13117300},{"batb":[[1,4.4,17.47]],"ltp":0.0,"tv":0.0,"id":13117374}]}]}
{"op":"mcm","clk":"1009098707","pt":1580663524184,"mc":[{"id":"1.168236369","rc":[{"batb":[[0,2.64,39.3],[1,2.6,63.48],[2,1.99,28.8]],"ltp":3.95,"tv":4.0,"id":13117300},{"batb":[[0,4.6,30.43],[1,4.5,41.28],[2,4.4,17.47]],"ltp":0.0,"tv":0.0,"id":13117374}]}]}
{"op":"mcm","clk":"1009098884","pt":1580663525156,"mc":[{"id":"1.168236369","rc":[{"batb":[[2,4.3,18.73]],"batl":[[0,5.1,17.07],[1,5.2,15.97]],"ltp":0.0,"tv":0.0,"id":13117301},{"batb":[[2,2.58,13.93]],"batl":[[1,3.4,21.48]],"ltp":3.95,"tv":4.0,"id":13117300},{"batl":[[0,5.1,17],[1,11,7.08]],"ltp":3.05,"tv":0.44,"id":13117373},{"batb":[[0,4.6,46.8],[2,4.3,18.41]],"batl":[[1,5.4,14.71]],"ltp":0.0,"tv":0.0,"id":13117374}]}]}
{"op":"mcm","clk":"1009099033","pt":1580663526182,"mc":[{"id":"1.168236369","rc":[{"batb":[[2,4.3,31.33]],"batl":[[0,5.1,27.16]],"ltp":0.0,"tv":0.0,"id":13117301},{"batb":[[2,2.58,39.97]],"ltp":3.95,"tv":4.0,"id":13117300}]}]}
{"op":"mcm","clk":"1009099206","pt":1580663527216,"mc":[{"id":"1.168236369","rc":[{"batl":[[1,2.96,21],[2,3.4,21.48]],"ltp":3.95,"tv":4.0,"id":13117300},{"batb":[[2,4.4,29.54]],"batl":[[1,5.3,9.24],[2,11,7.08]],"ltp":3.05,"tv":0.44,"id":13117373},{"batl":[[0,5,10.08],[1,5.3,15.66],[2,5.4,14.71]],"ltp":0.0,"tv":0.0,"id":13117374}]}]}
{"op":"mcm","clk":"1009100543","pt":1580663535186,"mc":[{"id":"1.168236369","rc":[{"trd":[[2.64,76]],"batb":[[0,2.64,1.3]],"ltp":2.64,"tv":80.0,"id":13117300}],"tv":80.44}]}
{"op":"mcm","clk":"1009100679","pt":1580663536058,"mc":[{"id":"1.168236369","rc":[{"batb":[[0,4.5,41.09],[1,4.4,17.55]],"ltp":0.0,"tv":0.0,"id":13117301},{"batb":[[0,2.58,39.97],[1,2.02,27.3],[2,1.01,0.51]],"ltp":2.64,"tv":80.0,"id":13117300}]}]}
{"op":"mcm","clk":"1009101088","pt":1580663538617,"mc":[{"id":"1.168236369","rc":[{"batb":[[0,4.6,22.4],[1,4.5,41.09],[2,4.4,17.55]],"ltp":0.0,"tv":0.0,"id":13117301},{"batb":[[0,2.62,63.34],[1,2.58,104.56],[2,2.02,27.3]],"ltp":2.64,"tv":80.0,"id":13117300}]}]}
{"op":"mcm","clk":"1009101844","pt":1580663543207,"mc":[{"id":"1.168236369","rc":[{"batb":[[0,4.4,17.55],[1,4.3,31.33],[2,1.01,0.51]],"ltp":0.0,"tv":0.0,"id":13117301},{"batb":[[0,2.58,39.97],[1,2.02,27.3],[2,1.01,0.51]],"ltp":2.64,"tv":80.0,"id":13117300},{"batb":[[0,4.4,29.54],[1,3.45,16.21],[2,1.01,0.51]],"ltp":3.05,"tv":0.44,"id":13117373},{"batb":[[0,4.6,16.37],[1,4.3,18.41],[2,4.2,12.6]],"ltp":0.0,"tv":0.0,"id":13117374}]}]}
{"op":"mcm","clk":"1009101962","pt":1580663543890,"mc":[{"id":"1.168236369","rc":[{"batb":[[0,4.3,31.33],[1,1.01,0.51],[2,1.01,0]],"batl":[[0,5.1,10.08]],"ltp":0.0,"tv":0.0,"id":13117301},{"batb":[[0,2.58,26.05]],"batl":[[0,2.96,21],[1,3.4,21.48],[2,3.4,0]],"ltp":2.64,"tv":80.0,"id":13117300},{"batb":[[0,4.4,11.76]],"batl":[[0,5.3,9.24],[1,11,7.08],[2,11,0]],"ltp":3.05,"tv":0.44,"id":13117373},{"batb":[[0,4.3,18.41],[1,4.2,12.6],[2,1.01,0.51]],"batl":[[1,5.4,14.71],[2,5.4,0]],"ltp":0.0,"tv":0.0,"id":13117374}]}]}
{"op":"mcm","clk":"1009102128","pt":1580663545017,"mc":[{"id":"1.168236369","rc":[{"batb":[[0,4.3,18.73]],"batl":[[0,5.2,15.97],[1,5.2,0]],"ltp":0.0,"tv":0.0,"id":13117301},{"batb":[[0,2.02,27.3],[1,1.01,0.51],[2,1.01,0]],"batl":[[0,3.4,21.48],[1,3.4,0]],"ltp":2.64,"tv":80.0,"id":13117300},{"batb":[[0,3.45,16.21],[1,1.01,0.51],[2,1.01,0]],"batl":[[0,11,7.08],[1,11,0]],"ltp":3.05,"tv":0.44,"id":13117373},{"batb":[[1,1.01,0.51],[2,1.01,0]],"batl":[[0,5.4,14.71],[1,5.4,0]],"ltp":0.0,"tv":0.0,"id":13117374}]}]}
{"op":"mcm","clk":"1009102434","pt":1580663547002,"mc":[{"id":"1.168236369","rc":[{"batb":[[0,4.5,38.53],[1,4.4,43.03],[2,4.3,18.73]],"ltp":0.0,"tv":0.0,"id":13117301},{"batb":[[1,2,99.09],[2,1.98,69.04]],"ltp":2.64,"tv":80.0,"id":13117300},{"batb":[[0,3.5,38.2],[1,3.45,55.32],[2,1.01,0.51]],"ltp":3.05,"tv":0.44,"id":13117373},{"batb":[[0,4.4,49.05],[1,4.3,63.9],[2,1.01,0.51]],"ltp":0.0,"tv":0.0,"id":13117374}]}]}
{"op":"mcm","clk":"1009102941","pt":1580663550210,"mc":[{"id":"1.168236369","rc":[{"batb":[[1,1.01,0.51],[2,1.98,0]],"ltp":2.64,"tv":80.0,"id":13117300},{"batb":[[0,4.3,18.41],[1,1.01,0.51],[2,1.01,0]],"ltp":0.0,"tv":0.0,"id":13117374}]}]}
{"op":"mcm","clk":"1009103358","pt":1580663552610,"mc":[{"id":"1.168236369","rc":[{"batb":[[0,3.15,71.98],[1,3.1,49.99],[2,2.02,27.3]],"ltp":2.64,"tv":80.0,"id":13117300},{"batb":[[0,4.7,31.32],[1,4.6,39.3],[2,4.3,18.41]],"ltp":0.0,"tv":0.0,"id":13117374}]}]}
{"op":"mcm","clk":"1009103651","pt":1580663554014,"mc":[{"id":"1.168236369","rc":[{"batl":[[0,5,27.94],[1,5.1,17]],"ltp":0.0,"tv":0.0,"id":13117301},{"batb":[[2,3.05,42.51]],"batl":[[1,3.55,15.96],[2,3.9,15.42]],"ltp":2.64,"tv":80.0,"id":13117300},{"batb":[[0,3.5,55],[2,3,22.58]],"batl":[[0,3.85,15.66],[1,4.1,13.44],[2,5.3,15.66]],"ltp":3.05,"tv":0.44,"id":13117373},{"batb":[[1,4.6,55.51],[2,4.3,12.6]],"batl":[[0,5.2,9.24],[1,5.4,14.71],[2,5.5,14.4]],"ltp":0.0,"tv":0.0,"id":13117374}]}]}
{"op":"mcm","clk":"1009106443","pt":1580663569357,"mc":[{"id":"1.168236369","rc":[{"batb":[[0,4.5,24.83]],"batl":[[0,5,10.08]],"ltp":0.0,"tv":0.0,"id":13117301},{"batb":[[0,3.05,20.16],[1,2.52,14.79],[2,1.01,0.51]],"batl":[[0,3.55,15.96],[1,3.9,15.42],[2,3.9,0]],"ltp":2.64,"tv":80.0,"id":13117300},{"batb":[[0,3.5,16.8],[1,3,22.58],[2,1.01,0.51]],"batl":[[0,4.1,13.44],[1,5.3,15.66],[2,5.3,0]],"ltp":3.05,"tv":0.44,"id":13117373},{"batb":[[0,4.6,55.51],[1,4.3,12.6],[2,1.01,0.51]],"batl":[[1,5.5,14.4],[2,5.5,0]],"ltp":0.0,"tv":0.0,"id":13117374}]}]}
{"op":"mcm","clk":"1009106736","pt":1580663571020,"mc":[{"id":"1.168236369","rc":[{"batl":[[0,5.1,17],[1,5.1,0]],"ltp":0.0,"tv":0.0,"id":13117301},{"batb":[[0,2.52,14.79],[1,1.01,0.51],[2,1.01,0]],"batl":[[0,3.9,15.42],[1,3.9,0]],"ltp":2.64,"tv":80.0,"id":13117300},{"batb":[[0,3,22.58],[1,1.01,0.51],[2,1.01,0]],"batl":[[0,5.3,15.66],[1,5.3,0]],"ltp":3.05,"tv":0.44,"id":13117373},{"batb":[[1,1.01,0.51],[2,1.01,0]],"batl":[[0,5.5,14.4],[1,5.5,0]],"ltp":0.0,"tv":0.0,"id":13117374}]}]}
{"op":"mcm","clk":"1009106968","pt":1580663572219,"mc":[{"id":"1.168236369","rc":[{"batb":[[0,2.6,40.29],[1,2.56,66.09],[2,2.54,14.56]],"batl":[[1,3.95,15.11]],"ltp":2.64,"tv":80.0,"id":13117300},{"batb":[[0,3.05,69.08],[1,3,77.52],[2,1.01,0.51]],"batl":[[0,5.2,16.05],[1,5.3,15.66]],"ltp":3.05,"tv":0.44,"id":13117373},{"batb":[[1,4.5,41.09],[2,1.01,0.51]],"ltp":0.0,"tv":0.0,"id":13117374}]}]}
{"op":"mcm","clk":"1009107071","pt":1580663572843,"mc":[{"id":"1.168236369","rc":[{"batl":[[0,3.95,15.11],[1,3.95,0]],"ltp":2.64,"tv":80.0,"id":13117300},{"batl":[[1,5.3,0]],"ltp":3.05,"tv":0.44,"id":13117373}]}]}
{"op":"mcm","clk":"1009108492","pt":1580663580936,"mc":[{"id":"1.168236369","rc":[{"batb":[[0,2.54,14.56],[1,1.01,0.51],[2,2.54,0]],"ltp":2.64,"tv":80.0,"id":13117300},{"batb":[[1,1.01,0.51],[2,1.01,0]],"ltp":0.0,"tv":0.0,"id":13117374}]}]}
{"op":"mcm","clk":"1009109012","pt":1580663584239,"mc":[{"id":"1.168236369","rc":[{"batl":[[0,5,28.1],[1,5.1,17]],"ltp":0.0,"tv":0.0,"id":13117301},{"batb":[[0,3.65,28.17],[1,3.6,34.95],[2,3.5,15.58]],"batl":[[1,4,13.44],[2,4.5,22.98]],"ltp":2.64,"tv":80.0,"id":13117300},{"batb":[[0,3.1,19.32],[1,3.05,69.08],[2,3,77.52]],"batl":[[0,3.35,22.11],[1,3.65,15.12],[2,3.95,14.87]],"ltp":3.05,"tv":0.44,"id":13117373},{"batb":[[0,4.7,61.46],[1,4.6,55.51],[2,4.4,11.76]],"batl":[[0,5.3,9.24],[1,5.5,14.4]],"ltp":0.0,"tv":0.0,"id":13117374}]}]}
{"op":"mcm","clk":"1009109131","pt":1580663585043,"mc":[{"id":"1.168236369","rc":[{"batl":[[1,5.1,0]],"ltp":0.0,"tv":0.0,"id":13117301},{"batb":[[1,4.6,39.3]],"ltp":0.0,"tv":0.0,"id":13117374}]}]}
{"op":"mcm","clk":"1009111886","pt":1580663600987,"mc":[{"id":"1.168236369","rc":[{"batb":[[0,4.4,43.03],[1,4.3,18.73],[2,1.01,0.51]],"batl":[[0,5,18.02]],"ltp":0.0,"tv":0.0,"id":13117301},{"batb":[[0,3,23.29],[1,1.01,0.51],[2,3.5,0]],"batl":[[0,4.5,22.82],[1,4,0],[2,4.5,0]],"ltp":2.64,"tv":80.0,"id":13117300},{"batb":[[0,2.78,11.25],[1,1.01,0.51],[2,3,0]],"batl":[[0,3.95,14.87],[1,3.65,0],[2,3.95,0]],"ltp":3.05,"tv":0.44,"id":13117373},{"batb":[[0,4.7,53.98],[2,1.01,0.51]],"batl":[[0,5.5,14.4],[1,5.5,0]],"ltp":0.0,"tv":0.0,"id":13117374}]}]}
{"op":"mcm","clk":"1009112293","pt":1580663603171,"mc":[{"id":"1.168236369","rc":[{"batb":[[0,4.4,63.94],[1,4.3,63.72]],"ltp":0.0,"tv":0.0,"id":13117301},{"batb":[[0,3.1,74.31],[1,3.05,52.06],[2,3,23.29]],"ltp":2.64,"tv":80.0,"id":13117300},{"batb":[[0,2.86,54.41],[1,2.82,51.76],[2,2.78,11.25]],"ltp":3.05,"tv":0.44,"id":13117373}]}]}
{"op":"mcm","clk":"1009113577","pt":1580663611216,"mc":[{"id":"1.168236369","rc":[{"batb":[[0,4.4,43.11],[1,4.3,18.73]],"ltp":0.0,"tv":0.0,"id":13117301},{"batb":[[0,2.78,11.25],[1,1.01,0.51],[2,2.78,0]],"ltp":3.05,"tv":0.44,"id":13117373}]}]}
{"op":"mcm","clk":"1009114037","pt":1580663614088,"mc":[{"id":"1.168236369","rc":[{"batb":[[0,4.5,33.84],[1,4.4,43.11],[2,4.3,18.73]],"ltp":0.0,"tv":0.0,"id":13117301},{"batb":[[0,3.55,43.62],[1,3.5,37.72],[2,2.78,11.25]],"ltp":3.05,"tv":0.44,"id":13117373}]}]}
{"op":"mcm","clk":"1009114174","pt":1580663615092,"mc":[{"id":"1.168236369","rc":[{"batl":[[1,5.1,17.07]],"ltp":0.0,"tv":0.0,"id":13117301},{"batl":[[0,3.3,22.42],[1,3.85,15.97]],"ltp":2.64,"tv":80.0,"id":13117300},{"batb":[[1,3.5,53.14],[2,3.05,21.64]],"batl":[[1,5.4,14.95]],"ltp":3.05,"tv":0.44,"id":13117373},{"batb":[[0,4.7,38.79],[1,4.6,55.12]],"ltp":0.0,"tv":0.0,"id":13117374}]}]}
{"op":"mcm","clk":"1009114324","pt":1580663615992,"mc":[{"id":"1.168236369","rc":[{"batl":[[0,5,28.1]],"ltp":0.0,"tv":0.0,"id":13117301},{"batb":[[1,3.05,72.22]],"batl":[[1,3.55,15.96],[2,3.85,15.97]],"ltp":2.64,"tv":80.0,"id":13117300},{"batb":[[1,3.5,69.95]],"batl":[[1,4.1,13.44],[2,5.4,14.95]],"ltp":3.05,"tv":0.44,"id":13117373},{"batb":[[2,4.4,11.76]],"batl":[[0,5.3,9.24],[1,5.5,14.4]],"ltp":0.0,"tv":0.0,"id":13117374}]}]}
{"op":"mcm","clk":"1009116761","pt":1580663630619,"mc":[{"id":"1.168236369","rc":[{"batb":[[0,3.1,50.45],[1,3.05,20.16]],"ltp":2.64,"tv":80.0,"id":13117300},{"batb":[[0,3.5,69.95],[1,3.05,21.64],[2,1.01,0.51]],"ltp":3.05,"tv":0.44,"id":13117373},{"batb":[[0,4.6,55.12],[1,4.4,11.76],[2,1.01,0.51]],"ltp":0.0,"tv":0.0,"id":13117374}]}]}
{"op":"mcm","clk":"1009117362","pt":1580663634188,"mc":[{"id":"1.168236369","rc":[{"batb":[[0,4.5,52.08]],"ltp":0.0,"tv":0.0,"id":13117301},{"batb":[[0,3.15,53.18],[1,3.1,50.45],[2,3.05,20.16]],"ltp":2.64,"tv":80.0,"id":13117300},{"batb":[[0,3.5,86.47],[1,3.45,38.71],[2,3.05,21.64]],"ltp":3.05,"tv":0.44,"id":13117373},{"batb":[[0,4.6,75.35],[1,4.5,40.55],[2,4.4,11.76]],"ltp":0.0,"tv":0.0,"id":13117374}]}]}
{"op":"mcm","clk":"1009118383","pt":1580663640117,"mc":[{"id":"1.168236369","rc":[{"batb":[[0,4.5,37.13],[2,4.2,32.04]],"batl":[[0,5,10.08]],"ltp":0.0,"tv":0.0,"id":13117301},{"batb":[[0,3.05,20.16],[1,2.48,15.42],[2,1.01,0.51]],"batl":[[0,3.55,15.96],[1,3.85,15.97],[2,3.85,0]],"ltp":2.64,"tv":80.0,"id":13117300},{"batb":[[0,3.5,16.8],[1,3.05,21.64],[2,1.01,0.51]],"batl":[[0,4.1,13.44],[1,5.4,14.95],[2,5.4,0]],"ltp":3.05,"tv":0.44,"id":13117373},{"batb":[[0,4.6,55.12]],"ltp":0.0,"tv":0.0,"id":13117374}]}]}
{"op":"mcm","clk":"1009118529","pt":1580663641033,"mc":[{"id":"1.168236369","rc":[{"batb":[[2,4.2,19.43]],"batl":[[0,5.1,17.07],[1,5.1,0]],"ltp":0.0,"tv":0.0,"id":13117301},{"batb":[[0,2.48,15.42],[1,1.01,0.51],[2,1.01,0]],"batl":[[0,3.85,15.97],[1,3.85,0]],"ltp":2.64,"tv":80.0,"id":13117300},{"batb":[[0,3.05,21.64],[1,1.01,0.51],[2,1.01,0]],"batl":[[0,5.4,14.95],[1,5.4,0]],"ltp":3.05,"tv":0.44,"id":13117373},{"batb":[[2,1.01,0.51]],"batl":[[0,5.5,14.4],[1,5.5,0]],"ltp":0.0,"tv":0.0,"id":13117374}]}]}
{"op":"mcm","clk":"1009118883","pt":1580663643108,"mc":[{"id":"1.168236369","rc":[{"batb":[[2,1.01,0.51]],"batl":[[0,5.1,16.76]],"ltp":0.0,"tv":0.0,"id":13117301},{"batb":[[0,2.58,50.94],[1,2.54,67.75],[2,2.5,15.11]],"batl":[[0,3.9,15.58]],"ltp":2.64,"tv":80.0,"id":13117300},{"batb":[[0,3.05,104.48],[1,3,54.49],[2,1.01,0.51]],"batl":[[0,5.3,15.34]],"ltp":3.05,"tv":0.44,"id":13117373}]}]}
{"op":"mcm","clk":"1009119497","pt":1580663646820,"mc":[{"id":"1.168236369","rc":[{"batb":[[0,2.5,15.11],[1,1.01,0.51],[2,2.5,0]],"ltp":2.64,"tv":80.0,"id":13117300},{"batb":[[1,1.01,0.51],[2,1.01,0]],"ltp":0.0,"tv":0.0,"id":13117374}]}]}
{"op":"mcm","clk":"1009119876","pt":1580663649210,"mc":[{"id":"1.168236369","rc":[{"batb":[[0,3.6,50.79],[1,3.55,36.17],[2,2.5,15.11]],"ltp":2.64,"tv":80.0,"id":13117300},{"batb":[[0,4.7,33.92],[1,4.6,55.12],[2,1.01,0.51]],"ltp":0.0,"tv":0.0,"id":13117374}]}]}
{"op":"mcm","clk":"1009120017","pt":1580663650112,"mc":[{"id":"1.168236369","rc":[{"batb":[[2,4.3,19.12]],"batl":[[0,4.9,10.08],[1,5,17.7]],"ltp":0.0,"tv":0.0,"id":13117301},{"batb":[[2,3.45,16.13]],"batl":[[1,3.95,13.44],[2,4.4,23.92]],"ltp":2.64,"tv":80.0,"id":13117300},{"batb":[[0,3.15,19.32],[1,3.05,104.48],[2,3,54.49]],"batl":[[0,3.4,21.4],[1,3.7,15.12],[2,4,14.24]],"ltp":3.05,"tv":0.44,"id":13117373},{"batb":[[0,4.7,49.5],[1,4.6,39.3],[2,4.4,11.76]],"batl":[[0,5.3,9.24],[1,5.5,14.4]],"ltp":0.0,"tv":0.0,"id":13117374}]}]}
{"op":"mcm","clk":"1009122811","pt":1580663667035,"mc":[{"id":"1.168236369","rc":[{"batb":[[0,4.5,33.84]],"batl":[[0,5,17.7],[1,5,0]],"ltp":0.0,"tv":0.0,"id":13117301},{"batb":[[0,2.96,24.31],[1,1.01,0.51],[2,3.45,0]],"batl":[[0,4.4,23.92],[1,3.95,0],[2,4.4,0]],"ltp":2.64,"tv":80.0,"id":13117300},{"batb":[[0,2.82,10.94],[1,1.01,0.51],[2,3,0]],"batl":[[0,4,14.24],[1,3.7,0],[2,4,0]],"ltp":3.05,"tv":0.44,"id":13117373},{"batb":[[2,1.01,0.51]],"batl":[[0,5.5,14.4],[1,5.5,0]],"ltp":0.0,"tv":0.0,"id":13117374}]}]}
{"op":"mcm","clk":"1009123323","pt":1580663670159,"mc":[{"id":"1.168236369","rc":[{"batb":[[0,3.1,56.8],[1,3.05,52.52],[2,2.96,24.31]],"ltp":2.64,"tv":80.0,"id":13117300},{"batb":[[0,2.88,39.41],[1,2.84,50.64],[2,2.82,10.94]],"ltp":3.05,"tv":0.44,"id":13117373}]}]}
{"op":"mcm","clk":"1009125355","pt":1580663682782,"mc":[{"id":"1.168236369","rc":[{"batb":[[0,2.96,24.31],[1,1.01,0.51],[2,2.96,0]],"ltp":2.64,"tv":80.0,"id":13117300},{"batb":[[0,2.82,10.94],[1,1.01,0.51],[2,2.82,0]],"ltp":3.05,"tv":0.44,"id":13117373}]}]}
{"op":"mcm","clk":"1009125877","pt":1580663685957,"mc":[{"id":"1.168236369","rc":[{"batb":[[0,4.5,47.68]],"batl":[[0,5,27.79]],"ltp":0.0,"tv":0.0,"id":13117301},{"batb":[[0,3.1,56.74],[1,3.05,52.52],[2,3,21]],"batl":[[0,3.5,16.8],[1,4.4,23.92]],"ltp":2.64,"tv":80.0,"id":13117300},{"batb":[[0,3.55,73.96],[1,3.5,37.35],[2,2.82,10.94]],"batl":[[1,4.2,12.6]],"ltp":3.05,"tv":0.44,"id":13117373},{"batb":[[2,4.4,11.76]],"batl":[[0,5.3,9.24],[1,5.5,14.4]],"ltp":0.0,"tv":0.0,"id":13117374}]}]}
{"op":"mcm","clk":"1009126056","pt":1580663686877,"mc":[{"id":"1.168236369","rc":[{"batl":[[1,5.1,16.84]],"ltp":0.0,"tv":0.0,"id":13117301},{"batl":[[0,3.25,23.29],[1,3.5,16.8],[2,3.75,16.76]],"ltp":2.64,"tv":80.0,"id":13117300},{"batb":[[0,3.6,14.71],[1,3.55,73.96],[2,3.5,37.35]],"batl":[[2,5.5,14.32]],"ltp":3.05,"tv":0.44,"id":13117373}]}]}
{"op":"mcm","clk":"1009129259","pt":1580663705144,"mc":[{"id":"1.168236369","rc":[{"batb":[[0,4.5,33.84]],"batl":[[0,5.1,16.84],[1,5.1,0]],"ltp":0.0,"tv":0.0,"id":13117301},{"batb":[[0,2.44,16.05],[1,1.01,0.51],[2,3,0]],"batl":[[0,3.75,16.76],[1,3.5,0],[2,3.75,0]],"ltp":2.64,"tv":80.0,"id":13117300},{"batb":[[0,3.1,20.85],[1,1.01,0.51],[2,3.5,0]],"batl":[[0,5.5,14.32],[1,4.2,0],[2,5.5,0]],"ltp":3.05,"tv":0.44,"id":13117373},{"batb":[[0,4.7,15.58],[2,1.01,0.51]],"batl":[[0,5.5,14.4],[1,5.5,0]],"ltp":0.0,"tv":0.0,"id":13117374}]}]}
{"op":"mcm","clk":"1009129747","pt":1580663707968,"mc":[{"id":"1.168236369","rc":[{"batb":[[2,4.3,18.8]],"batl":[[0,5.1,16.6]],"ltp":0.0,"tv":0.0,"id":13117301},{"batb":[[0,2.54,63.3],[1,2.5,70.62],[2,2.46,15.82]],"batl":[[0,3.8,16.44]],"ltp":2.64,"tv":80.0,"id":13117300},{"batb":[[0,3.1,93.38],[1,3.05,52.35],[2,1.01,0.51]],"ltp":3.05,"tv":0.44,"id":13117373},{"batb":[[0,4.6,55.19],[1,4.5,40.76]],"batl":[[0,5.4,14.79]],"ltp":0.0,"tv":0.0,"id":13117374}]}]}
{"op":"mcm","clk":"1009129922","pt":1580663708986,"mc":[{"id":"1.168236369","rc":[{"batb":[[0,2.46,15.82],[1,1.01,0.51],[2,2.46,0]],"ltp":2.64,"tv":80.0,"id":13117300},{"batb":[[0,3.1,20.85],[1,1.01,0.51],[2,1.01,0]],"ltp":3.05,"tv":0.44,"id":13117373},{"batb":[[1,1.01,0.51],[2,1.01,0]],"ltp":0.0,"tv":0.0,"id":13117374}]}]}
{"op":"mcm","clk":"1009130466","pt":1580663711943,"mc":[{"id":"1.168236369","rc":[{"batb":[[0,4.5,53.9]],"ltp":0.0,"tv":0.0,"id":13117301},{"batb":[[0,2.98,45.07],[1,2.94,46.34],[2,2.46,15.82]],"ltp":2.64,"tv":80.0,"id":13117300},{"batb":[[0,3.75,47.99],[1,3.7,32.74],[2,3.1,20.85]],"ltp":3.05,"tv":0.44,"id":13117373},{"batb":[[0,4.7,23.05],[1,4.6,55.19],[2,1.01,0.51]],"ltp":0.0,"tv":0.0,"id":13117374}]}]}
{"op":"mcm","clk":"1009131544","pt":1580663718066,"mc":[{"id":"1.168236369","rc":[{"batb":[[0,4.5,33.84]],"ltp":0.0,"tv":0.0,"id":13117301},{"batb":[[0,2.46,15.82],[1,1.01,0.51],[2,2.46,0]],"ltp":2.64,"tv":80.0,"id":13117300},{"batb":[[0,3.1,20.85],[1,1.01,0.51],[2,3.1,0]],"ltp":3.05,"tv":0.44,"id":13117373},{"batb":[[0,4.6,55.19],[1,1.01,0.51],[2,1.01,0]],"ltp":0.0,"tv":0.0,"id":13117374}]}]}
{"op":"mcm","clk":"1009132048","pt":1580663720867,"mc":[{"id":"1.168236369","rc":[{"batb":[[0,2.54,63.3],[1,2.5,70.62],[2,2.46,15.82]],"ltp":2.64,"tv":80.0,"id":13117300},{"batb":[[0,3.1,93.38],[1,3.05,52.35],[2,1.01,0.51]],"ltp":3.05,"tv":0.44,"id":13117373},{"batb":[[1,4.5,40.76],[2,1.01,0.51]],"ltp":0.0,"tv":0.0,"id":13117374}]}]}
{"op":"mcm","clk":"1009133544","pt":1580663729773,"mc":[{"id":"1.168236369","rc":[{"batb":[[0,2.46,15.82],[1,1.01,0.51],[2,2.46,0]],"ltp":2.64,"tv":80.0,"id":13117300},{"batb":[[1,1.01,0.51],[2,1.01,0]],"ltp":0.0,"tv":0.0,"id":13117374}]}]}
{"op":"mcm","clk":"1009134106","pt":1580663733186,"mc":[{"id":"1.168236369","rc":[{"batl":[[0,5,17.39],[1,5.1,16.6]],"ltp":0.0,"tv":0.0,"id":13117301},{"batb":[[0,3.55,49.16],[1,3.5,37.45],[2,3.4,17]],"batl":[[1,4.3,25.34]],"ltp":2.64,"tv":80.0,"id":13117300},{"batb":[[2,2.86,10.54]],"batl":[[0,3.45,20.38],[1,4.1,13.61],[2,5.5,14.32]],"ltp":3.05,"tv":0.44,"id":13117373},{"batb":[[0,4.7,54.68],[1,4.6,55.19],[2,1.01,0.51]],"batl":[[1,5.5,14.56]],"ltp":0.0,"tv":0.0,"id":13117374}]}]}
{"op":"mcm","clk":"1009134230","pt":1580663733974,"mc":[{"id":"1.168236369","rc":[{"batl":[[0,4.9,10.08],[1,5,17.39]],"ltp":0.0,"tv":0.0,"id":13117301},{"batl":[[1,3.9,14.28],[2,4.3,25.34]],"ltp":2.64,"tv":80.0,"id":13117300},{"batb":[[0,3.2,18.48],[1,3.1,93.38],[2,3.05,52.35]],"batl":[[1,3.75,15.12],[2,4.1,13.61]],"ltp":3.05,"tv":0.44,"id":13117373},{"batb":[[1,4.6,39.3],[2,4.4,11.76]],"batl":[[0,5.4,9.24]],"ltp":0.0,"tv":0.0,"id":13117374}]}]}
{"op":"mcm","clk":"1009137713","pt":1580663755144,"mc":[{"id":"1.168236369","rc":[{"batb":[[0,4.4,43.11],[1,4.3,18.8],[2,1.01,0.51]],"batl":[[0,5,17.39],[1,5,0]],"ltp":0.0,"tv":0.0,"id":13117301},{"batb":[[0,2.9,25.49],[1,1.01,0.51],[2,3.4,0]],"batl":[[0,4.3,25.34],[1,3.9,0],[2,4.3,0]],"ltp":2.64,"tv":80.0,"id":13117300},{"batb":[[0,2.86,10.54],[1,1.01,0.51],[2,3.05,0]],"batl":[[0,4.1,13.61],[1,3.75,0],[2,4.1,0]],"ltp":3.05,"tv":0.44,"id":13117373},{"batb":[[2,1.01,0.51]],"batl":[[0,5.5,14.56],[1,5.5,0]],"ltp":0.0,"tv":0.0,"id":13117374}]}]}
{"op":"mcm","clk":"1009138266","pt":1580663758239,"mc":[{"id":"1.168236369","rc":[{"batb":[[0,4.4,65.81],[1,4.3,64.06]],"ltp":0.0,"tv":0.0,"id":13117301},{"batb":[[0,3.05,61.93],[1,3,54.69],[2,2.9,25.34]],"batl":[[0,4.3,24.86]],"ltp":2.64,"tv":80.0,"id":13117300},{"batb":[[0,2.9,57.57],[1,2.86,49.63],[2,2.84,10.62]],"ltp":3.05,"tv":0.44,"id":13117373},{"batb":[[0,4.7,39.02],[1,4.6,54.96]],"ltp":0.0,"tv":0.0,"id":13117374}]}]}
{"op":"mcm","clk":"1009138571","pt":1580663760065,"mc":[{"id":"1.168236369","rc":[{"batb":[[0,2.9,25.34],[1,1.01,0.51],[2,2.9,0]],"ltp":2.64,"tv":80.0,"id":13117300}]}]}
{"op":"mcm","clk":"1009138978","pt":1580663762228,"mc":[{"id":"1.168236369","rc":[{"batb":[[0,3.9,41.46],[1,3.85,29.84],[2,2.9,25.34]],"ltp":2.64,"tv":80.0,"id":13117300}]}]}
{"op":"mcm","clk":"1009139164","pt":1580663763211,"mc":[{"id":"1.168236369","rc":[{"batb":[[1,4.3,45.26],[2,4.2,19.43]],"ltp":0.0,"tv":0.0,"id":13117301},{"batb":[[2,3.75,13.22]],"batl":[[1,5.3,15.74]],"ltp":2.64,"tv":80.0,"id":13117300},{"batl":[[0,3.1,10.46],[1,3.45,20.69]],"ltp":3.05,"tv":0.44,"id":13117373},{"batb":[[0,4.7,54.52],[1,4.6,39.3]],"ltp":0.0,"tv":0.0,"id":13117374}]}]}
{"op":"mcm","clk":"1009139305","pt":1580663764005,"mc":[{"id":"1.168236369","rc":[{"batl":[[0,4.9,10.08],[1,5,17.39]],"ltp":0.0,"tv":0.0,"id":13117301},{"batl":[[0,4.3,37.47]],"ltp":2.64,"tv":80.0,"id":13117300},{"batb":[[0,2.94,21],[1,2.9,57.57],[2,2.86,49.63]],"batl":[[1,3.45,37.5]],"ltp":3.05,"tv":0.44,"id":13117373},{"batb":[[2,4.4,11.76]],"batl":[[0,5.3,9.24],[1,5.5,14.56]],"ltp":0.0,"tv":0.0,"id":13117374}]}]}
{"op":"mcm","clk":"1009142442","pt":1580663781968,"mc":[{"id":"1.168236369","rc":[{"batb":[[1,4.3,64.38],[2,4.1,13.44]],"ltp":0.0,"tv":0.0,"id":13117301},{"batl":[[1,3.4,20.77],[2,3.45,16.8]],"ltp":3.05,"tv":0.44,"id":13117373},{"batl":[[1,5.5,14.24]],"ltp":0.0,"tv":0.0,"id":13117374}]}]}
{"op":"mcm","clk":"1009143724","pt":1580663790107,"mc":[{"id":"1.168236369","rc":[{"batb":[[2,3.8,13.06]],"ltp":2.64,"tv":80.0,"id":13117300},{"trd":[[3.1,16.8]],"batb":[[2,2.86,60.17]],"batl":[[0,3.1,2.06]],"ltp":3.1,"tv":17.24,"id":13117373}],"tv":97.24}]}
{"op":"mcm","clk":"1009144206","pt":1580663793085,"mc":[{"id":"1.168236369","rc":[{"trd":[[3.9,4.1]],"batb":[[0,3.9,39.41]],"ltp":3.9,"tv":84.1,"id":13117300}],"tv":101.34}]}
{"op":"mcm","clk":"1009144991","pt":1580663797694,"mc":[{"id":"1.168236369","rc":[{"batb":[[1,4.3,45.26],[2,4.2,19.43]],"batl":[[0,4.9,28.26],[1,5,0]],"ltp":0.0,"tv":0.0,"id":13117301},{"batb":[[2,3.75,13.22]],"batl":[[0,4.2,25.65],[1,4.3,12.6],[2,5.2,16.13]],"ltp":3.9,"tv":84.1,"id":13117300},{"batb":[[1,2.92,10.39],[2,2.9,57.57]],"batl":[[0,3.15,25.49],[1,3.45,37.18],[2,3.45,0]],"ltp":3.1,"tv":17.24,"id":13117373}]}]}
{"op":"mcm","clk":"1009145371","pt":1580663799987,"mc":[{"id":"1.168236369","rc":[{"batb":[[2,2.56,14.48]],"ltp":3.1,"tv":17.24,"id":13117373}]}]}
{"op":"mcm","clk":"1009145850","pt":1580663802778,"mc":[{"id":"1.168236369","rc":[{"batb":[[1,2.92,46.54],[2,2.88,48.92]],"ltp":3.1,"tv":17.24,"id":13117373}]}]}
{"op":"mcm","clk":"1009149315","pt":1580663824122,"mc":[{"id":"1.168236369","rc":[{"batl":[[0,4.2,12.9]],"ltp":3.9,"tv":84.1,"id":13117300},{"batl":[[0,3.15,25.02],[1,3.45,37.03]],"ltp":3.1,"tv":17.24,"id":13117373}]}]}
{"op":"mcm","clk":"1009150200","pt":1580663830045,"mc":[{"id":"1.168236369","rc":[{"trd":[[3.9,26.1]],"batb":[[0,3.9,28.41]],"ltp":3.9,"tv":106.1,"id":13117300}],"tv":123.34}]}
{"op":"mcm","clk":"1009154558","pt":1580663856164,"mc":[{"id":"1.168236369","rc":[{"batb":[[0,3.65,15.12],[1,3.4,16.6],[2,1.01,0.51]],"batl":[[0,4.3,12.6],[1,5.2,16.13],[2,5.2,0]],"ltp":3.9,"tv":106.1,"id":13117300},{"batb":[[1,2.58,14.4],[2,1.01,0.51]],"batl":[[0,3.45,37.03],[1,3.45,0]],"ltp":3.1,"tv":17.24,"id":13117373}]}]}
{"op":"mcm","clk":"1009154717","pt":1580663857171,"mc":[{"id":"1.168236369","rc":[{"batl":[[0,4.9,18.18]],"ltp":0.0,"tv":0.0,"id":13117301},{"batb":[[0,3.4,16.6],[1,1.01,0.51],[2,1.01,0]],"batl":[[0,5.2,16.13],[1,5.2,0]],"ltp":3.9,"tv":106.1,"id":13117300},{"batb":[[0,2.58,14.4],[1,1.01,0.51],[2,1.01,0]],"batl":[[0,3.45,20.22]],"ltp":3.1,"tv":17.24,"id":13117373},{"batb":[[2,1.01,0.51]],"batl":[[0,5.5,14.24],[1,5.5,0]],"ltp":0.0,"tv":0.0,"id":13117374}]}]}
{"op":"mcm","clk":"1009154898","pt":1580663858229,"mc":[{"id":"1.168236369","rc":[{"batb":[[0,3.55,50.1],[1,3.5,37.35],[2,3.4,16.6]],"ltp":3.9,"tv":106.1,"id":13117300},{"batb":[[0,2.58,84.11],[1,2.54,67.73],[2,1.01,0.51]],"ltp":3.1,"tv":17.24,"id":13117373}]}]}
{"op":"mcm","clk":"1009155039","pt":1580663858978,"mc":[{"id":"1.168236369","rc":[{"batb":[[0,3.4,16.6],[1,1.01,0.51],[2,3.4,0]],"batl":[[0,5.1,16.52]],"ltp":3.9,"tv":106.1,"id":13117300},{"batb":[[0,2.58,14.16],[1,1.01,0.51],[2,1.01,0]],"batl":[[0,3.5,19.91]],"ltp":3.1,"tv":17.24,"id":13117373},{"batb":[[0,4.7,54.21]],"batl":[[0,5.5,14.01]],"ltp":0.0,"tv":0.0,"id":13117374}]}]}
{"op":"mcm","clk":"1009155433","pt":1580663861139,"mc":[{"id":"1.168236369","rc":[{"batb":[[0,4,52.55],[1,3.95,27.92],[2,3.4,16.6]],"ltp":3.9,"tv":106.1,"id":13117300},{"batb":[[0,2.84,52.19],[1,2.8,52.51],[2,2.58,14.16]],"ltp":3.1,"tv":17.24,"id":13117373}]}]}
{"op":"mcm","clk":"1009155468","pt":1580663861356,"mc":[{"id":"1.168236369","rc":[{"batb":[[0,4.4,53.65]],"ltp":0.0,"tv":0.0,"id":13117301},{"batb":[[0,4,41.24]],"ltp":3.9,"tv":106.1,"id":13117300},{"batb":[[0,2.58,14.16],[1,1.01,0.51],[2,2.58,0]],"ltp":3.1,"tv":17.24,"id":13117373}]}]}
{"op":"mcm","clk":"1009155944","pt":1580663864142,"mc":[{"id":"1.168236369","rc":[{"batb":[[0,3.4,16.6],[1,1.01,0.51],[2,3.4,0]],"ltp":3.9,"tv":106.1,"id":13117300}]}]}
{"op":"mcm","clk":"1009156029","pt":1580663864687,"mc":[{"id":"1.168236369","rc":[{"batb":[[0,4.7,69.14]],"ltp":0.0,"tv":0.0,"id":13117374}]}]}
{"op":"mcm","clk":"1009156295","pt":1580663866527,"mc":[{"id":"1.168236369","rc":[{"batb":[[0,3.55,37.44],[1,3.5,37.34],[2,3.4,16.6]],"ltp":3.9,"tv":106.1,"id":13117300},{"batb":[[0,2.6,53.23],[1,2.58,14.16],[2,2.56,66.56]],"ltp":3.1,"tv":17.24,"id":13117373}]}]}
{"op":"mcm","clk":"1009157156","pt":1580663872002,"mc":[{"id":"1.168236369","rc":[{"batb":[[0,2.58,14.16],[1,1.01,0.51],[2,2.56,0]],"ltp":3.1,"tv":17.24,"id":13117373}]}]}
{"op":"mcm","clk":"1009157713","pt":1580663875156,"mc":[{"id":"1.168236369","rc":[{"batb":[[0,3.15,44.32],[1,3.1,50.72],[2,2.58,14.16]],"ltp":3.1,"tv":17.24,"id":13117373}]}]}
{"op":"mcm","clk":"1009157865","pt":1580663876058,"mc":[{"id":"1.168236369","rc":[{"batl":[[0,4.9,28.26]],"ltp":0.0,"tv":0.0,"id":13117301},{"batb":[[2,3.45,16.8]],"batl":[[0,3.75,16.6],[1,4,13.44],[2,4.4,23.13]],"ltp":3.9,"tv":106.1,"id":13117300},{"batb":[[0,3.15,84.34],[2,2.86,11.02]],"batl":[[1,3.65,15.12],[2,3.75,16.76]],"ltp":3.1,"tv":17.24,"id":13117373},{"batb":[[2,4.4,11.76]],"batl":[[0,5.3,9.24],[1,5.4,14.48],[2,5.5,14.01]],"ltp":0.0,"tv":0.0,"id":13117374}]}]}
{"op":"mcm","clk":"1009159829","pt":1580663887994,"mc":[{"id":"1.168236369","rc":[{"trd":[[3.55,20]],"batb":[[0,3.55,27.44]],"ltp":3.55,"tv":126.1,"id":13117300}],"tv":143.34}]}
{"op":"mcm","clk":"1009160377","pt":1580663891204,"mc":[{"id":"1.168236369","rc":[{"batl":[[0,4.9,18.18]],"ltp":0.0,"tv":0.0,"id":13117301},{"batb":[[0,3.15,20.69],[1,1.01,0.51],[2,3.45,0]],"batl":[[0,4.4,23.13],[1,4,0],[2,4.4,0]],"ltp":3.55,"tv":126.1,"id":13117300},{"batb":[[0,2.86,11.02],[1,1.01,0.51],[2,2.86,0]],"batl":[[0,3.75,16.76],[1,3.65,0],[2,3.75,0]],"ltp":3.1,"tv":17.24,"id":13117373},{"batb":[[2,1.01,0.51]],"batl":[[0,5.5,14.01],[1,5.4,0],[2,5.5,0]],"ltp":0.0,"tv":0.0,"id":13117374}]}]}
{"op":"mcm","clk":"1009161256","pt":1580663896223,"mc":[{"id":"1.168236369","rc":[{"batb":[[0,3.6,59.14],[1,3.55,35.84],[2,3.15,20.69]],"ltp":3.55,"tv":126.1,"id":13117300},{"batb":[[0,3.05,82.58],[1,3,54.73],[2,2.86,11.02]],"ltp":3.1,"tv":17.24,"id":13117373}]}]}
{"op":"mcm","clk":"1009161679","pt":1580663899034,"mc":[{"id":"1.168236369","rc":[{"batb":[[0,3.15,20.69],[1,1.01,0.51],[2,3.15,0]],"ltp":3.55,"tv":126.1,"id":13117300},{"batb":[[0,2.86,11.02],[1,1.01,0.51],[2,2.86,0]],"ltp":3.1,"tv":17.24,"id":13117373}]}]}
{"op":"mcm","clk":"1009162169","pt":1580663902220,"mc":[{"id":"1.168236369","rc":[{"batb":[[0,3.3,60.42],[1,3.25,44.49],[2,3.15,20.69]],"ltp":3.55,"tv":126.1,"id":13117300},{"batb":[[1,2.84,55.46],[2,2.8,52.63]],"ltp":3.1,"tv":17.24,"id":13117373}]}]}
{"op":"mcm","clk":"1009162254","pt":1580663902748,"mc":[{"id":"1.168236369","rc":[{"batb":[[0,3.15,20.69],[1,1.01,0.51],[2,3.15,0]],"ltp":3.55,"tv":126.1,"id":13117300}]}]}
{"op":"mcm","clk":"1009162659","pt":1580663905240,"mc":[{"id":"1.168236369","rc":[{"batb":[[0,4,51.97],[1,3.95,27.79],[2,3.9,24.47]],"batl":[[1,5.8,12.9]],"ltp":3.55,"tv":126.1,"id":13117300},{"batl":[[0,3.05,10.86],[1,3.4,21.24]],"ltp":3.1,"tv":17.24,"id":13117373}]}]}
{"op":"mcm","clk":"1009162771","pt":1580663906047,"mc":[{"id":"1.168236369","rc":[{"batl":[[0,4.9,28.26]],"ltp":0.0,"tv":0.0,"id":13117301},{"batl":[[1,4.5,11.76],[2,5.8,12.9]],"ltp":3.55,"tv":126.1,"id":13117300},{"batb":[[0,2.86,32.86]],"batl":[[1,3.35,17.64],[2,3.4,21.24]],"ltp":3.1,"tv":17.24,"id":13117373},{"batb":[[2,4.4,11.76]],"batl":[[0,5.3,9.24],[1,5.5,14.01]],"ltp":0.0,"tv":0.0,"id":13117374}]}]}
{"op":"mcm","clk":"1009165808","pt":1580663925150,"mc":[{"id":"1.168236369","rc":[{"batb":[[0,4.4,43.03]],"batl":[[0,4.9,18.18]],"ltp":0.0,"tv":0.0,"id":13117301},{"batb":[[0,3.5,15.97],[1,1.01,0.51],[2,3.9,0]],"batl":[[0,5.8,12.9],[1,4.5,0],[2,5.8,0]],"ltp":3.55,"tv":126.1,"id":13117300},{"batb":[[0,2.44,16.52],[1,1.01,0.51],[2,2.8,0]],"batl":[[0,3.4,21.24],[1,3.35,0],[2,3.4,0]],"ltp":3.1,"tv":17.24,"id":13117373},{"batb":[[0,4.7,60.4],[2,1.01,0.51]],"batl":[[0,5.5,14.01],[1,5.5,0]],"ltp":0.0,"tv":0.0,"id":13117374}]}]}
{"op":"mcm","clk":"1009166216","pt":1580663927874,"mc":[{"id":"1.168236369","rc":[{"batb":[[0,3.6,36.3],[1,3.55,36.04],[2,3.5,15.97]],"ltp":3.55,"tv":126.1,"id":13117300},{"batb":[[0,2.48,45.41],[1,2.44,92.35],[2,1.01,0.51]],"ltp":3.1,"tv":17.24,"id":13117373}]}]}
{"op":"mcm","clk":"1009166374","pt":1580663929037,"mc":[{"id":"1.168236369","rc":[{"batb":[[0,2.44,16.52],[1,1.01,0.51],[2,1.01,0]],"ltp":3.1,"tv":17.24,"id":13117373}]}]}
{"op":"mcm","clk":"1009166891","pt":1580663932170,"mc":[{"id":"1.168236369","rc":[{"batb":[[0,4.4,62.07]],"batl":[[0,4.9,28.26]],"ltp":0.0,"tv":0.0,"id":13117301},{"batb":[[2,3.5,32.78]],"batl":[[0,4.1,13.44],[1,5.8,12.9]],"ltp":3.55,"tv":126.1,"id":13117300},{"batb":[[0,3.1,72.9],[1,3.05,52.75],[2,2.44,16.52]],"batl":[[1,3.55,15.96]],"ltp":3.1,"tv":17.24,"id":13117373},{"batb":[[2,4.3,12.6]],"batl":[[0,5.2,9.24],[1,5.5,14.01]],"ltp":0.0,"tv":0.0,"id":13117374}]}]}
{"op":"mcm","clk":"1009167010","pt":1580663932952,"mc":[{"id":"1.168236369","rc":[{"batl":[[0,3.85,15.5],[1,4.1,13.44],[2,4.7,20.38]],"ltp":3.55,"tv":126.1,"id":13117300},{"batb":[[1,3.05,74.78],[2,2.74,12.2]],"batl":[[1,3.6,15.96],[2,3.7,17.31]],"ltp":3.1,"tv":17.24,"id":13117373}]}]}
{"op":"mcm","clk":"1009169194","pt":1580663947217,"mc":[{"id":"1.168236369","rc":[{"batb":[[0,3.5,32.78],[1,3.2,19.83],[2,1.01,0.51]],"ltp":3.55,"tv":126.1,"id":13117300},{"batb":[[0,3.1,19.32],[1,3.05,22.03]],"ltp":3.1,"tv":17.24,"id":13117373}]}]}
{"op":"mcm","clk":"1009169266","pt":1580663947593,"mc":[{"id":"1.168236369","rc":[{"batb":[[0,3.5,16.8]],"batl":[[0,4.1,13.44],[1,4.7,20.38],[2,4.7,0]],"ltp":3.55,"tv":126.1,"id":13117300},{"batb":[[1,2.74,12.2],[2,1.01,0.51]],"batl":[[0,3.6,15.96],[1,3.7,17.31],[2,3.7,0]],"ltp":3.1,"tv":17.24,"id":13117373}]}]}
{"op":"mcm","clk":"1009169515","pt":1580663949100,"mc":[{"id":"1.168236369","rc":[{"batl":[[0,4.9,18.18]],"ltp":0.0,"tv":0.0,"id":13117301},{"batb":[[0,3.2,19.83],[1,1.01,0.51],[2,1.01,0]],"batl":[[0,4.7,20.38],[1,4.7,0]],"ltp":3.55,"tv":126.1,"id":13117300},{"batb":[[0,2.74,12.2],[1,1.01,0.51],[2,1.01,0]],"batl":[[0,3.7,17.31],[1,3.7,0]],"ltp":3.1,"tv":17.24,"id":13117373},{"batb":[[2,1.01,0.51]],"batl":[[0,5.5,14.01],[1,5.5,0]],"ltp":0.0,"tv":0.0,"id":13117374}]}]}
{"op":"mcm","clk":"1009169679","pt":1580663950231,"mc":[{"id":"1.168236369","rc":[{"batb":[[0,3.3,66.47],[1,3.25,44.43],[2,3.2,19.83]],"ltp":3.55,"tv":126.1,"id":13117300},{"batb":[[0,2.76,53.88],[1,2.74,12.2],[2,2.72,56.76]],"ltp":3.1,"tv":17.24,"id":13117373}]}]}
{"op":"mcm","clk":"1009169794","pt":1580663950799,"mc":[{"id":"1.168236369","rc":[{"batb":[[0,3.2,19.83],[1,1.01,0.51],[2,3.2,0]],"ltp":3.55,"tv":126.1,"id":13117300},{"batb":[[0,2.74,12.2],[1,1.01,0.51],[2,2.72,0]],"ltp":3.1,"tv":17.24,"id":13117373}]}]}
{"op":"mcm","clk":"1009170383","pt":1580663954516,"mc":[{"id":"1.168236369","rc":[{"batb":[[0,3.7,40.66],[1,3.65,33.67],[2,3.2,19.83]],"ltp":3.55,"tv":126.1,"id":13117300},{"batb":[[0,3,82.46],[1,2.96,45.46],[2,2.74,12.2]],"ltp":3.1,"tv":17.24,"id":13117373}]}]}
{"op":"mcm","clk":"1009171273","pt":1580663960219,"mc":[{"id":"1.168236369","rc":[{"batb":[[0,3.2,19.83],[1,1.01,0.51],[2,3.2,0]],"ltp":3.55,"tv":126.1,"id":13117300},{"batb":[[0,2.74,12.2],[1,1.01,0.51],[2,2.74,0]],"ltp":3.1,"tv":17.24,"id":13117373}]}]}
{"op":"mcm","clk":"1009171830","pt":1580663963099,"mc":[{"id":"1.168236369","rc":[{"batb":[[0,3.3,66.47],[1,3.25,44.43],[2,3.2,19.83]],"ltp":3.55,"tv":126.1,"id":13117300},{"batb":[[0,2.76,53.88],[1,2.74,12.2],[2,2.72,56.76]],"ltp":3.1,"tv":17.24,"id":13117373}]}]}
{"op":"mcm","clk":"1009174333","pt":1580663978218,"mc":[{"id":"1.168236369","rc":[{"batb":[[0,2.74,12.2],[1,1.01,0.51],[2,2.72,0]],"ltp":3.1,"tv":17.24,"id":13117373}]}]}
{"op":"mcm","clk":"1009174826","pt":1580663981132,"mc":[{"id":"1.168236369","rc":[{"batl":[[0,3.55,19.12],[1,3.9,15.03],[2,4.7,20.38]],"ltp":3.55,"tv":126.1,"id":13117300},{"batb":[[0,3.35,51.44],[1,3.3,43.55],[2,3.05,22.58]],"batl":[[1,3.95,15.03]],"ltp":3.1,"tv":17.24,"id":13117373},{"batl":[[0,5.4,14.56],[1,5.5,14.01]],"ltp":0.0,"tv":0.0,"id":13117374}]}]}
{"op":"mcm","clk":"1009174984","pt":1580663982135,"mc":[{"id":"1.168236369","rc":[{"batl":[[0,4.9,28.26]],"ltp":0.0,"tv":0.0,"id":13117301},{"batb":[[0,3.3,84.11]],"batl":[[1,3.85,14.28],[2,3.9,15.03]],"ltp":3.55,"tv":126.1,"id":13117300},{"batb":[[1,3.3,61.19]],"batl":[[1,3.85,14.28],[2,3.95,15.03]],"ltp":3.1,"tv":17.24,"id":13117373},{"batb":[[2,4.3,12.6]],"batl":[[0,5.2,9.24],[1,5.4,14.56]],"ltp":0.0,"tv":0.0,"id":13117374}]}]}
{"op":"mcm","clk":"1009178379","pt":1580664003747,"mc":[{"id":"1.168236369","rc":[{"batb":[[0,3.3,17.64],[1,3,22.82],[2,1.01,0.51]],"batl":[[0,3.85,14.28],[1,3.9,15.03],[2,3.9,0]],"ltp":3.55,"tv":126.1,"id":13117300},{"batb":[[0,3.3,17.64],[1,3.05,22.58],[2,1.01,0.51]],"batl":[[0,3.85,14.28],[1,3.95,15.03],[2,3.95,0]],"ltp":3.1,"tv":17.24,"id":13117373},{"batb":[[0,4.7,54.21]],"ltp":0.0,"tv":0.0,"id":13117374}]}]}
{"op":"mcm","clk":"1009178595","pt":1580664005168,"mc":[{"id":"1.168236369","rc":[{"batl":[[0,4.9,18.18]],"ltp":0.0,"tv":0.0,"id":13117301},{"batb":[[0,3,22.82],[1,1.01,0.51],[2,1.01,0]],"batl":[[0,3.9,15.03],[1,3.9,0]],"ltp":3.55,"tv":126.1,"id":13117300},{"batb":[[0,3.05,22.58],[1,1.01,0.51],[2,1.01,0]],"batl":[[0,3.95,15.03],[1,3.95,0]],"ltp":3.1,"tv":17.24,"id":13117373},{"batb":[[2,1.01,0.51]],"batl":[[0,5.4,14.56],[1,5.4,0]],"ltp":0.0,"tv":0.0,"id":13117374}]}]}
{"op":"mcm","clk":"1009178784","pt":1580664006439,"mc":[{"id":"1.168236369","rc":[{"batb":[[0,3.2,48.28],[1,3.15,48.2],[2,3,22.82]],"ltp":3.55,"tv":126.1,"id":13117300},{"batb":[[0,3.1,55.36],[1,3.05,75.32],[2,1.01,0.51]],"ltp":3.1,"tv":17.24,"id":13117373}]}]}
{"op":"mcm","clk":"1009179461","pt":1580664011078,"mc":[{"id":"1.168236369","rc":[{"batb":[[0,4.4,43.31],[1,4.2,19.43],[2,1.01,0.51]],"ltp":0.0,"tv":0.0,"id":13117301},{"batb":[[0,3,22.82],[1,1.01,0.51],[2,3,0]],"ltp":3.55,"tv":126.1,"id":13117300}]}]}
{"op":"mcm","clk":"1009179951","pt":1580664014075,"mc":[{"id":"1.168236369","rc":[{"batb":[[0,4.5,27.93],[1,4.4,43.31],[2,4.2,19.43]],"batl":[[1,5,10.08]],"ltp":0.0,"tv":0.0,"id":13117301},{"batb":[[0,3.6,31.85],[1,3.55,36.08],[2,3.45,16.8]],"batl":[[1,4.1,13.44]],"ltp":3.55,"tv":126.1,"id":13117300},{"batb":[[0,3.1,74.68]],"batl":[[0,3.6,15.96],[1,3.95,15.03]],"ltp":3.1,"tv":17.24,"id":13117373},{"batb":[[2,4.3,12.6]],"batl":[[0,5.2,9.24],[1,5.4,14.56]],"ltp":0.0,"tv":0.0,"id":13117374}]}]}
{"op":"mcm","clk":"1009180131","pt":1580664015069,"mc":[{"id":"1.168236369","rc":[{"batb":[[2,4.3,19.36]],"batl":[[0,4.9,17.94]],"ltp":0.0,"tv":0.0,"id":13117301},{"batb":[[1,3.55,51.58]],"batl":[[2,4.8,19.04]],"ltp":3.55,"tv":126.1,"id":13117300},{"batb":[[2,2.68,12.9]],"batl":[[0,3.35,21.72],[1,3.6,15.96],[2,3.75,16.92]],"ltp":3.1,"tv":17.24,"id":13117373},{"batb":[[0,4.7,39.02],[1,4.6,55.19]],"ltp":0.0,"tv":0.0,"id":13117374}]}]}
{"op":"mcm","clk":"1009183121","pt":1580664035910,"mc":[{"id":"1.168236369","rc":[{"batb":[[0,4.4,43.31],[1,4.3,19.36],[2,4.1,13.44]],"ltp":0.0,"tv":0.0,"id":13117301},{"batb":[[0,3.45,16.8],[1,3.15,20.22],[2,1.01,0.51]],"batl":[[0,4.1,13.44],[1,4.8,19.04],[2,4.8,0]],"ltp":3.55,"tv":126.1,"id":13117300},{"batb":[[0,3.1,19.32],[1,2.68,12.9],[2,1.01,0.51]],"batl":[[0,3.6,15.96],[1,3.75,16.92],[2,3.75,0]],"ltp":3.1,"tv":17.24,"id":13117373}]}]}
{"op":"mcm","clk":"1009183324","pt":1580664037191,"mc":[{"id":"1.168236369","rc":[{"batb":[[2,1.01,0.51]],"batl":[[1,5,0]],"ltp":0.0,"tv":0.0,"id":13117301},{"batb":[[0,3.15,20.22],[1,1.01,0.51],[2,1.01,0]],"batl":[[0,4.8,19.04],[1,4.8,0]],"ltp":3.55,"tv":126.1,"id":13117300},{"batb":[[0,2.68,12.9],[1,1.01,0.51],[2,1.01,0]],"batl":[[0,3.75,16.92],[1,3.75,0]],"ltp":3.1,"tv":17.24,"id":13117373},{"batb":[[2,1.01,0.51]],"batl":[[0,5.4,14.56],[1,5.4,0]],"ltp":0.0,"tv":0.0,"id":13117374}]}]}
{"op":"mcm","clk":"1009183579","pt":1580664039100,"mc":[{"id":"1.168236369","rc":[{"batb":[[0,4.4,66.27],[1,4.3,64.41]],"ltp":0.0,"tv":0.0,"id":13117301},{"batb":[[0,3.3,39.99],[1,3.25,44.68],[2,3.15,20.22]],"ltp":3.55,"tv":126.1,"id":13117300},{"batb":[[0,2.72,59.87],[1,2.68,71.86],[2,1.01,0.51]],"ltp":3.1,"tv":17.24,"id":13117373}]}]}
{"op":"mcm","clk":"1009184118","pt":1580664043312,"mc":[{"id":"1.168236369","rc":[{"batb":[[0,3.35,3],[1,2.72,59.87],[2,2.68,71.86]],"ltp":3.1,"tv":17.24,"id":13117373}]}]}
{"op":"mcm","clk":"1009184547","pt":1580664046716,"mc":[{"id":"1.168236369","rc":[{"batb":[[0,4.4,43.31],[1,4.3,19.36]],"ltp":0.0,"tv":0.0,"id":13117301},{"batb":[[0,2.68,12.9],[1,1.01,0.51],[2,2.68,0]],"ltp":3.1,"tv":17.24,"id":13117373}]}]}
{"op":"mcm","clk":"1009184868","pt":1580664049210,"mc":[{"id":"1.168236369","rc":[{"batb":[[0,4.5,30.91],[1,4.4,43.31],[2,4.3,19.36]],"ltp":0.0,"tv":0.0,"id":13117301},{"batb":[[0,3.35,60.89],[1,3.3,43.3],[2,2.68,12.9]],"ltp":3.1,"tv":17.24,"id":13117373}]}]}
{"op":"mcm","clk":"1009185009","pt":1580664050226,"mc":[{"id":"1.168236369","rc":[{"batb":[[2,4.2,19.43]],"batl":[[0,4.9,10.08],[1,5,17.62]],"ltp":0.0,"tv":0.0,"id":13117301},{"batb":[[1,3.25,63.16]],"batl":[[0,3.5,19.51],[1,3.8,14.28],[2,3.9,15.03]],"ltp":3.55,"tv":126.1,"id":13117300},{"batb":[[0,3.4,17.47],[1,3.35,78.53],[2,3.3,43.3]],"batl":[[1,3.9,14.28],[2,4.7,20.93]],"ltp":3.1,"tv":17.24,"id":13117373},{"batb":[[2,4.3,12.6]],"batl":[[0,5.2,9.24],[1,5.4,14.56]],"ltp":0.0,"tv":0.0,"id":13117374}]}]}
{"op":"mcm","clk":"1009185400","pt":1580664052824,"mc":[{"id":"1.168236369","rc":[{"batl":[[0,3.45,4.45],[1,3.5,19.51],[2,3.8,14.28]],"ltp":3.55,"tv":126.1,"id":13117300}]}]}
{"op":"mcm","clk":"1009186154","pt":1580664058009,"mc":[{"id":"1.168236369","rc":[{"batl":[[0,3.5,19.51],[1,3.8,14.28],[2,3.9,15.03]],"ltp":3.55,"tv":126.1,"id":13117300}]}]}
{"op":"mcm","clk":"1009186520","pt":1580664060610,"mc":[{"id":"1.168236369","rc":[{"trd":[[3.75,6]],"batl":[[0,3.75,13.92]],"ltp":3.75,"tv":23.24,"id":13117373}],"tv":149.34}]}
{"op":"mcm","clk":"1009189420","pt":1580664080126,"mc":[{"id":"1.168236369","rc":[{"batb":[[0,3.25,18.48],[1,2.74,11.96],[2,1.01,0.51]],"batl":[[0,3.8,14.28],[1,3.9,15.03],[2,3.9,0]],"ltp":3.55,"tv":126.1,"id":13117300},{"batb":[[0,3.35,17.64],[1,3.05,22.42],[2,1.01,0.51]],"batl":[[0,3.9,14.28],[1,4.7,20.93],[2,4.7,0]],"ltp":3.75,"tv":23.24,"id":13117373},{"batb":[[0,4.7,22.1]],"ltp":0.0,"tv":0.0,"id":13117374}]}]}
{"op":"mcm","clk":"1009189684","pt":1580664082057,"mc":[{"id":"1.168236369","rc":[{"batl":[[0,5,17.62],[1,5,0]],"ltp":0.0,"tv":0.0,"id":13117301},{"batb":[[0,2.74,11.96],[1,1.01,0.51],[2,1.01,0]],"batl":[[0,3.9,15.03],[1,3.9,0]],"ltp":3.55,"tv":126.1,"id":13117300},{"batb":[[0,3.05,22.42],[1,1.01,0.51],[2,1.01,0]],"batl":[[0,4.7,20.93],[1,4.7,0]],"ltp":3.75,"tv":23.24,"id":13117373},{"batb":[[2,1.01,0.51]],"batl":[[0,5.4,14.56],[1,5.4,0]],"ltp":0.0,"tv":0.0,"id":13117374}]}]}
{"op":"mcm","clk":"1009189872","pt":1580664083228,"mc":[{"id":"1.168236369","rc":[{"batb":[[2,4.3,19.2]],"ltp":0.0,"tv":0.0,"id":13117301},{"batb":[[0,2.76,11.8],[1,2.74,11.96],[2,1.01,0.51]],"batl":[[1,3.95,14.87]],"ltp":3.55,"tv":126.1,"id":13117300},{"batl":[[0,4.6,21.17],[1,4.7,20.93]],"ltp":3.75,"tv":23.24,"id":13117373}]}]}
{"op":"mcm","clk":"1009189975","pt":1580664083959,"mc":[{"id":"1.168236369","rc":[{"batl":[[0,5,17.47]],"ltp":0.0,"tv":0.0,"id":13117301},{"batb":[[1,1.01,0.51],[2,1.01,0]],"batl":[[0,3.95,14.87],[1,3.95,0]],"ltp":3.55,"tv":126.1,"id":13117300},{"batl":[[1,4.7,0]],"ltp":3.75,"tv":23.24,"id":13117373}]}]}
{"op":"mcm","clk":"1009190112","pt":1580664084753,"mc":[{"id":"1.168236369","rc":[{"batb":[[0,3.2,39.67],[1,3.15,48.28],[2,2.76,11.8]],"ltp":3.55,"tv":126.1,"id":13117300},{"batb":[[0,3.45,68.44],[1,3.4,40.17],[2,3.05,22.42]],"ltp":3.75,"tv":23.24,"id":13117373},{"batb":[[0,4.7,30.14]],"ltp":0.0,"tv":0.0,"id":13117374}]}]}
{"op":"mcm","clk":"1009190870","pt":1580664090088,"mc":[{"id":"1.168236369","rc":[{"batb":[[0,2.76,11.8],[1,1.01,0.51],[2,2.76,0]],"ltp":3.55,"tv":126.1,"id":13117300},{"batb":[[0,3.05,22.42],[1,1.01,0.51],[2,3.05,0]],"ltp":3.75,"tv":23.24,"id":13117373},{"batb":[[0,4.6,55.19],[1,1.01,0.51],[2,1.01,0]],"ltp":0.0,"tv":0.0,"id":13117374}]}]}
{"op":"mcm","clk":"1009191303","pt":1580664093063,"mc":[{"id":"1.168236369","rc":[{"batb":[[0,2.86,38.43],[1,2.82,51.35],[2,2.76,11.8]],"ltp":3.55,"tv":126.1,"id":13117300},{"batb":[[0,3.1,33.42],[1,3.05,75.27],[2,1.01,0.51]],"ltp":3.75,"tv":23.24,"id":13117373},{"batb":[[0,4.6,72.72],[1,4.5,40.71],[2,1.01,0.51]],"ltp":0.0,"tv":0.0,"id":13117374}]}]}
{"op":"mcm","clk":"1009192965","pt":1580664104366,"mc":[{"id":"1.168236369","rc":[{"batb":[[1,4.4,43.03]],"ltp":0.0,"tv":0.0,"id":13117301},{"batb":[[0,3.05,22.42],[1,1.01,0.51],[2,1.01,0]],"ltp":3.75,"tv":23.24,"id":13117373}]}]}
{"op":"mcm","clk":"1009193515","pt":1580664108161,"mc":[{"id":"1.168236369","rc":[{"batb":[[0,4.5,47.18],[1,4.4,61.36]],"batl":[[0,5,27.55],[1,5.1,16.52]],"ltp":0.0,"tv":0.0,"id":13117301},{"batb":[[0,2.86,60.28]],"batl":[[0,2.96,11.57],[1,3.3,17.64],[2,3.4,21.17]],"ltp":3.55,"tv":126.1,"id":13117300},{"batb":[[0,4,66.16],[1,3.95,28.15],[2,3.85,14.28]],"batl":[[0,4.6,32.09],[1,6.4,10.54]],"ltp":3.75,"tv":23.24,"id":13117373},{"batb":[[2,4.3,12.6]],"batl":[[0,5.1,10.08],[1,5.3,15.19],[2,5.4,14.56]],"ltp":0.0,"tv":0.0,"id":13117374}]}]}
{"op":"mcm","clk":"1009193628","pt":1580664108964,"mc":[{"id":"1.168236369","rc":[{"batb":[[2,4.3,18.73]],"batl":[[0,5,10.08]],"ltp":0.0,"tv":0.0,"id":13117301},{"batl":[[2,5.4,0]],"ltp":0.0,"tv":0.0,"id":13117374}]}]}
{"op":"mcm","clk":"1009195779","pt":1580664123180,"mc":[{"id":"1.168236369","rc":[{"batb":[[0,4.5,31.51]],"batl":[[0,5.1,16.52],[1,5.1,0]],"ltp":0.0,"tv":0.0,"id":13117301},{"batb":[[0,2.76,11.8],[1,2.32,18.57],[2,1.01,0.51]],"batl":[[1,3.4,21.17],[2,3.4,0]],"ltp":3.55,"tv":126.1,"id":13117300},{"batb":[[0,4,22.35],[1,3.5,16.05],[2,1.01,0.51]],"batl":[[0,4.6,21.17]],"ltp":3.75,"tv":23.24,"id":13117373},{"batb":[[0,4.6,55.34],[2,1.01,0.51]],"batl":[[0,5.3,15.19],[1,5.3,0]],"ltp":0.0,"tv":0.0,"id":13117374}]}]}
{"op":"mcm","clk":"1009195939","pt":1580664124187,"mc":[{"id":"1.168236369","rc":[{"batb":[[1,4.4,43.03]],"ltp":0.0,"tv":0.0,"id":13117301},{"batb":[[0,2.32,18.57],[1,1.01,0.51],[2,1.01,0]],"batl":[[0,3.4,21.17],[1,3.4,0]],"ltp":3.55,"tv":126.1,"id":13117300},{"batb":[[0,3.5,16.05],[1,1.01,0.51],[2,1.01,0]],"batl":[[0,6.4,10.54],[1,6.4,0]],"ltp":3.75,"tv":23.24,"id":13117373}]}]}
{"op":"mcm","clk":"1009196223","pt":1580664125992,"mc":[{"id":"1.168236369","rc":[{"batb":[[0,2.4,58.94],[1,2.36,82.33],[2,2.32,18.57]],"ltp":3.55,"tv":126.1,"id":13117300},{"batb":[[0,3.5,53.02],[1,3.45,38.99],[2,1.01,0.51]],"ltp":3.75,"tv":23.24,"id":13117373}]}]}
{"op":"mcm","clk":"1009196301","pt":1580664126475,"mc":[{"id":"1.168236369","rc":[{"batb":[[2,1.01,0.51]],"batl":[[0,5.2,16.29]],"ltp":0.0,"tv":0.0,"id":13117301},{"batb":[[2,2.34,18.25]],"batl":[[0,3.4,20.77]],"ltp":3.55,"tv":126.1,"id":13117300},{"batb":[[0,4.6,39.45],[1,4.5,57.63]],"ltp":0.0,"tv":0.0,"id":13117374}]}]}
{"op":"mcm","clk":"1009196558","pt":1580664128108,"mc":[{"id":"1.168236369","rc":[{"batb":[[0,2.34,18.25],[1,1.01,0.51],[2,2.34,0]],"ltp":3.55,"tv":126.1,"id":13117300},{"batb":[[0,3.5,16.05],[1,1.01,0.51],[2,1.01,0]],"ltp":3.75,"tv":23.24,"id":13117373}]}]}
{"op":"mcm","clk":"1009197040","pt":1580664131191,"mc":[{"id":"1.168236369","rc":[{"batb":[[0,4.5,52.69]],"ltp":0.0,"tv":0.0,"id":13117301},{"batb":[[0,2.74,62.39],[1,2.7,57.32],[2,2.34,18.25]],"ltp":3.55,"tv":126.1,"id":13117300},{"batb":[[0,4.2,52.61],[1,4.1,50.78],[2,3.5,16.05]],"ltp":3.75,"tv":23.24,"id":13117373},{"batb":[[0,4.6,53.33]],"ltp":0.0,"tv":0.0,"id":13117374}]}]}
{"op":"mcm","clk":"1009197526","pt":1580664134117,"mc":[{"id":"1.168236369","rc":[{"batb":[[0,4.5,32.48]],"ltp":0.0,"tv":0.0,"id":13117301},{"batb":[[0,2.34,18.25],[1,1.01,0.51],[2,2.34,0]],"ltp":3.55,"tv":126.1,"id":13117300},{"batb":[[0,3.5,16.05],[1,1.01,0.51],[2,3.5,0]],"ltp":3.75,"tv":23.24,"id":13117373},{"batb":[[0,4.6,39.3]],"ltp":0.0,"tv":0.0,"id":13117374}]}]}
{"op":"mcm","clk":"1009198012","pt":1580664137203,"mc":[{"id":"1.168236369","rc":[{"batb":[[0,2.4,60.87],[1,2.36,82.33],[2,2.34,18.25]],"ltp":3.55,"tv":126.1,"id":13117300},{"batb":[[0,3.5,51.56],[1,3.45,38.99],[2,1.01,0.51]],"ltp":3.75,"tv":23.24,"id":13117373}]}]}
{"op":"mcm","clk":"1009200432","pt":1580664153136,"mc":[{"id":"1.168236369","rc":[{"batb":[[1,1.01,0.51],[2,1.01,0]],"ltp":0.0,"tv":0.0,"id":13117301},{"batb":[[0,2.34,18.25],[1,1.01,0.51],[2,2.34,0]],"ltp":3.55,"tv":126.1,"id":13117300},{"batb":[[0,3.5,16.05],[1,1.01,0.51],[2,1.01,0]],"ltp":3.75,"tv":23.24,"id":13117373}]}]}
{"op":"mcm","clk":"1009200912","pt":1580664156165,"mc":[{"id":"1.168236369","rc":[{"batb":[[0,4.6,33.63],[1,4.5,41.06],[2,4.2,12.6]],"batl":[[0,5.1,10.08],[1,5.2,16.29]],"ltp":0.0,"tv":0.0,"id":13117301},{"batb":[[0,2.42,29.41],[1,2.4,60.87],[2,2.36,82.33]],"batl":[[0,2.78,23.53],[1,3.4,20.77]],"ltp":3.55,"tv":126.1,"id":13117300},{"batb":[[0,5.4,40.82],[1,5.3,28.29],[2,5,10.08]],"batl":[[0,6.2,7.56],[1,6.4,10.54]],"ltp":3.75,"tv":23.24,"id":13117373},{"batb":[[2,4.2,12.6]],"batl":[[0,5,10.08],[1,5.3,15.19]],"ltp":0.0,"tv":0.0,"id":13117374}]}]}
{"op":"mcm","clk":"1009201061","pt":1580664157073,"mc":[{"id":"1.168236369","rc":[{"batb":[[1,4.5,58.53]],"batl":[[2,5.4,14.95]],"ltp":0.0,"tv":0.0,"id":13117301},{"batl":[[0,2.5,17.86],[1,2.78,23.53],[2,2.8,13.3]],"ltp":3.55,"tv":126.1,"id":13117300},{"batb":[[0,5.5,11.25],[1,5.4,40.82],[2,5.3,28.29]],"batl":[[2,11,7.55]],"ltp":3.75,"tv":23.24,"id":13117373},{"batl":[[1,5.2,16.13]],"ltp":0.0,"tv":0.0,"id":13117374}]}]}
{"op":"mcm","clk":"1009203286","pt":1580664171057,"mc":[{"id":"1.168236369","rc":[{"batl":[[1,2.8,13.3],[2,2.8,0]],"ltp":3.55,"tv":126.1,"id":13117300}]}]}
{"op":"mcm","clk":"1009203752","pt":1580664174177,"mc":[{"id":"1.168236369","rc":[{"batl":[[1,2.76,23.53],[2,2.8,13.3]],"ltp":3.55,"tv":126.1,"id":13117300}]}]}
{"op":"mcm","clk":"1009203905","pt":1580664175244,"mc":[{"id":"1.168236369","rc":[{"batb":[[0,4.5,58.53],[1,4.2,12.6],[2,1.01,0.51]],"ltp":0.0,"tv":0.0,"id":13117301},{"trd":[[2.42,8.9]],"batb":[[0,2.42,24.95],[1,2.34,18.25],[2,1.99,28.88]],"batl":[[1,2.8,13.3],[2,2.8,0]],"ltp":2.42,"tv":135.0,"id":13117300},{"batb":[[1,5.4,27.54],[2,5.1,10.08]],"ltp":3.75,"tv":23.24,"id":13117373}],"tv":158.24}]}
{"op":"mcm","clk":"1009204336","pt":1580664178147,"mc":[{"id":"1.168236369","rc":[{"batb":[[1,4.4,42.53],[2,4.2,12.6]],"batl":[[1,5.4,14.95],[2,5.4,0]],"ltp":0.0,"tv":0.0,"id":13117301},{"batb":[[0,2.42,29.15],[1,1.99,28.88],[2,1.01,0.51]],"batl":[[0,2.74,23.53]],"ltp":2.42,"tv":135.0,"id":13117300},{"batb":[[0,5.1,10.08],[1,4.4,18.33],[2,1.01,0.51]],"batl":[[1,11,7.55],[2,11,0]],"ltp":3.75,"tv":23.24,"id":13117373},{"batb":[[0,4.6,45.5]],"ltp":0.0,"tv":0.0,"id":13117374}]}]}
{"op":"mcm","clk":"1009204487","pt":1580664179173,"mc":[{"id":"1.168236369","rc":[{"batb":[[2,1.01,0.51]],"batl":[[0,5.4,14.95],[1,5.4,0]],"ltp":0.0,"tv":0.0,"id":13117301},{"batb":[[0,1.99,28.88],[1,1.01,0.51],[2,1.01,0]],"batl":[[0,2.8,13.3],[1,2.8,0]],"ltp":2.42,"tv":135.0,"id":13117300},{"batb":[[0,4.4,18.33],[1,1.01,0.51],[2,1.01,0]],"batl":[[0,11,7.55],[1,11,0]],"ltp":3.75,"tv":23.24,"id":13117373},{"batb":[[2,1.01,0.51]],"batl":[[0,5.2,16.13],[1,5.2,0]],"ltp":0.0,"tv":0.0,"id":13117374}]}]}
{"op":"mcm","clk":"1009204819","pt":1580664181202,"mc":[{"id":"1.168236369","rc":[{"batb":[[0,2.02,83.32],[1,2,66.89],[2,1.99,28.88]],"ltp":2.42,"tv":135.0,"id":13117300},{"batb":[[0,4.4,78.67],[1,4.3,45.69],[2,1.01,0.51]],"ltp":3.75,"tv":23.24,"id":13117373}]}]}
{"op":"mcm","clk":"1009207997","pt":1580664201702,"mc":[{"id":"1.168236369","rc":[{"batb":[[1,1.01,0.51],[2,1.01,0]],"ltp":0.0,"tv":0.0,"id":13117301},{"batb":[[0,1.99,28.88],[1,1.01,0.51],[2,1.99,0]],"ltp":2.42,"tv":135.0,"id":13117300},{"batb":[[0,4.4,18.33],[1,1.01,0.51],[2,1.01,0]],"ltp":3.75,"tv":23.24,"id":13117373}]}]}
{"op":"mcm","clk":"1009208532","pt":1580664205101,"mc":[{"id":"1.168236369","rc":[{"batb":[[0,2.28,45.61],[1,1.99,28.88],[2,1.01,0.51]],"ltp":2.42,"tv":135.0,"id":13117300},{"batb":[[0,6,23.69],[1,5.9,22.68],[2,4.4,18.33]],"ltp":3.75,"tv":23.24,"id":13117373},{"batb":[[1,4.5,16.92]],"ltp":0.0,"tv":0.0,"id":13117374}]}]}
{"op":"mcm","clk":"1009209055","pt":1580664208704,"mc":[{"id":"1.168236369","rc":[{"batb":[[0,4.5,78.38],[1,4.4,42.37],[2,1.01,0.51]],"ltp":0.0,"tv":0.0,"id":13117301},{"batb":[[0,2.28,86.73],[1,2.26,46.64],[2,1.99,28.88]],"ltp":2.42,"tv":135.0,"id":13117300},{"batb":[[0,6,35.86]],"ltp":3.75,"tv":23.24,"id":13117373},{"batb":[[0,4.7,32.63],[1,4.6,45.5],[2,4.5,16.92]],"ltp":0.0,"tv":0.0,"id":13117374}]}]}
{"op":"mcm","clk":"1009209231","pt":1580664210019,"mc":[{"id":"1.168236369","rc":[{"batb":[[0,4.5,48.38]],"ltp":0.0,"tv":0.0,"id":13117301},{"batb":[[0,1.99,28.88],[1,1.01,0.51],[2,1.99,0]],"ltp":2.42,"tv":135.0,"id":13117300},{"batb":[[0,4.4,18.33],[1,1.01,0.51],[2,4.4,0]],"ltp":3.75,"tv":23.24,"id":13117373},{"batb":[[0,4.7,22.77]],"ltp":0.0,"tv":0.0,"id":13117374}]}]}
{"op":"mcm","clk":"1009209824","pt":1580664213942,"mc":[{"id":"1.168236369","rc":[{"batb":[[0,2.02,55.97],[1,2,66.83],[2,1.99,28.88]],"ltp":2.42,"tv":135.0,"id":13117300},{"batb":[[0,4.5,31.24],[1,4.4,62.42],[2,1.01,0.51]],"ltp":3.75,"tv":23.24,"id":13117373}]}]}
{"op":"mcm","clk":"1009210152","pt":1580664216134,"mc":[{"id":"1.168236369","rc":[{"batb":[[1,1.01,0.51],[2,1.01,0]],"ltp":0.0,"tv":0.0,"id":13117301},{"batb":[[0,4.4,18.33],[1,1.01,0.51],[2,1.01,0]],"ltp":3.75,"tv":23.24,"id":13117373}]}]}
{"op":"mcm","clk":"1009210591","pt":1580664219031,"mc":[{"id":"1.168236369","rc":[{"batb":[[0,4.6,53.79],[1,4.5,57.76],[2,1.01,0.51]],"ltp":0.0,"tv":0.0,"id":13117301},{"batb":[[0,9.4,12.62],[1,9.2,17.42],[2,4.4,18.33]],"ltp":3.75,"tv":23.24,"id":13117373}]}]}
{"op":"mcm","clk":"1009210780","pt":1580664220245,"mc":[{"id":"1.168236369","rc":[{"batb":[[0,4.7,15.74],[1,4.6,70.31],[2,4.5,40.29]],"batl":[[0,5.2,9.24],[1,5.4,14.95],[2,5.6,14.01]],"ltp":0.0,"tv":0.0,"id":13117301},{"batb":[[0,2.06,39.49],[1,2.02,55.97],[2,2,66.83]],"batl":[[0,2.12,28.25],[1,2.28,22.82],[2,2.32,31.09]],"ltp":2.42,"tv":135.0,"id":13117300},{"batb":[[2,8.6,7.79]],"batl":[[0,10.5,4.2],[1,11,7.55],[2,21,5.51]],"ltp":3.75,"tv":23.24,"id":13117373},{"batl":[[0,4.9,10.08],[1,5.2,16.13]],"ltp":0.0,"tv":0.0,"id":13117374}]}]}
{"op":"mcm","clk":"1009211517","pt":1580664225031,"mc":[{"id":"1.168236369","rc":[{"batb":[[0,9.2,17.42],[1,8.6,7.79],[2,8.2,5.04]],"ltp":3.75,"tv":23.24,"id":13117373},{"batb":[[0,4.6,45.5],[1,4.5,16.92],[2,4.1,13.44]],"ltp":0.0,"tv":0.0,"id":13117374}]}]}
{"op":"mcm","clk":"1009211698","pt":1580664226147,"mc":[{"id":"1.168236369","rc":[{"batb":[[2,6.8,13.3]],"ltp":3.75,"tv":23.24,"id":13117373}]}]}
{"op":"mcm","clk":"1009212025","pt":1580664228158,"mc":[{"id":"1.168236369","rc":[{"batb":[[0,9.2,26.66],[1,9,17.9],[2,8.6,7.79]],"ltp":3.75,"tv":23.24,"id":13117373},{"batb":[[0,4.6,54.78],[1,4.5,58.08]],"ltp":0.0,"tv":0.0,"id":13117374}]}]}
{"op":"mcm","clk":"1009216434","pt":1580664256122,"mc":[{"id":"1.168236369","rc":[{"batb":[[1,4.6,51.84]],"ltp":0.0,"tv":0.0,"id":13117301},{"batb":[[1,1.99,28.88],[2,1.8,19.99]],"ltp":2.42,"tv":135.0,"id":13117300},{"batb":[[0,8.6,7.79],[1,8.4,5.04],[2,6.8,13.3]],"ltp":3.75,"tv":23.24,"id":13117373}]}]}
{"op":"mcm","clk":"1009216944","pt":1580664259189,"mc":[{"id":"1.168236369","rc":[{"batb":[[2,1.81,82.05]],"ltp":2.42,"tv":135.0,"id":13117300},{"batb":[[2,7.2,14.89]],"ltp":3.75,"tv":23.24,"id":13117373}]}]}
{"op":"mcm","clk":"1009217705","pt":1580664263989,"mc":[{"id":"1.168236369","rc":[{"batb":[[0,4.6,51.84],[1,4.5,40.29],[2,1.01,0.51]],"batl":[[1,5.6,14.01],[2,5.6,0]],"ltp":0.0,"tv":0.0,"id":13117301},{"batb":[[1,1.81,82.05],[2,1.8,19.99]],"batl":[[0,2.28,22.82],[1,2.28,0],[2,2.32,0]],"ltp":2.42,"tv":135.0,"id":13117300},{"batb":[[0,8.4,5.04],[1,7.2,14.89],[2,7,31.06]],"batl":[[0,21,5.51],[1,11,0],[2,21,0]],"ltp":3.75,"tv":23.24,"id":13117373},{"batb":[[2,1.01,0.51]],"ltp":0.0,"tv":0.0,"id":13117374}]}]}
{"op":"mcm","clk":"1009217884","pt":1580664265195,"mc":[{"id":"1.168236369","rc":[{"batl":[[0,5.6,14.01],[1,5.6,0]],"ltp":0.0,"tv":0.0,"id":13117301},{"batb":[[0,1.81,82.05],[1,1.8,19.99],[2,1.79,94.93]],"ltp":2.42,"tv":135.0,"id":13117300},{"batb":[[0,7.2,14.89],[1,7,31.06],[2,6.8,13.3]],"ltp":3.75,"tv":23.24,"id":13117373},{"batl":[[0,5.2,16.13],[1,5.2,0]],"ltp":0.0,"tv":0.0,"id":13117374}]}]}
{"op":"mcm","clk":"1009218254","pt":1580664267205,"mc":[{"id":"1.168236369","rc":[{"batb":[[0,1.8,19.99],[1,1.01,0.51],[2,1.79,0]],"ltp":2.42,"tv":135.0,"id":13117300}]}]}
{"op":"mcm","clk":"1009218722","pt":1580664270199,"mc":[{"id":"1.168236369","rc":[{"batb":[[0,2.16,95.78],[1,2.14,54.61],[2,1.8,19.99]],"ltp":2.42,"tv":135.0,"id":13117300}]}]}
{"op":"mcm","clk":"1009218877","pt":1580664271196,"mc":[{"id":"1.168236369","rc":[{"batb":[[0,4.6,35.32],[1,4.5,57.68]],"batl":[[0,5.2,16.05],[1,5.5,14.32]],"ltp":0.0,"tv":0.0,"id":13117301},{"batb":[[2,2.12,23.84]],"batl":[[0,2.26,23.21],[1,2.56,16.76]],"ltp":2.42,"tv":135.0,"id":13117300},{"batb":[[2,6.8,12.98]],"batl":[[0,8.4,12.27],[1,20,5.74]],"ltp":3.75,"tv":23.24,"id":13117373},{"batl":[[0,5.2,15.89]],"ltp":0.0,"tv":0.0,"id":13117374}]}]}
{"op":"mcm","clk":"1009219045","pt":1580664272212,"mc":[{"id":"1.168236369","rc":[{"batb":[[2,4.2,12.6]],"batl":[[0,5.1,10.08],[1,5.2,16.05],[2,5.5,14.32]],"ltp":0.0,"tv":0.0,"id":13117301},{"batb":[[0,2.18,35.29],[1,2.16,95.78],[2,2.14,54.61]],"batl":[[1,2.44,28.57],[2,2.56,16.76]],"ltp":2.42,"tv":135.0,"id":13117300},{"batb":[[2,6.8,19.7]],"batl":[[1,8.6,5.04],[2,20,5.74]],"ltp":3.75,"tv":23.24,"id":13117373},{"batb":[[2,4.2,12.6]],"batl":[[0,5,10.08],[1,5.2,15.89]],"ltp":0.0,"tv":0.0,"id":13117374}]}]}
{"op":"mcm","clk":"1009219090","pt":1580664272541,"mc":[{"id":"1.168236369","rc":[{"batl":[[0,8.4,17.32],[1,20,5.74],[2,20,0]],"ltp":3.75,"tv":23.24,"id":13117373}]}]}
{"op":"mcm","clk":"1009220860","pt":1580664283219,"mc":[{"id":"1.168236369","rc":[{"batb":[[0,4.5,57.68],[1,1.01,0.51],[2,4.2,0]],"batl":[[0,5.5,14.32],[1,5.2,0],[2,5.5,0]],"ltp":0.0,"tv":0.0,"id":13117301},{"batb":[[0,1.82,19.36],[1,1.01,0.51],[2,2.14,0]],"batl":[[0,2.56,16.76],[1,2.44,0],[2,2.56,0]],"ltp":2.42,"tv":135.0,"id":13117300},{"batb":[[0,5.2,12.59],[1,1.01,0.51],[2,6.8,0]],"batl":[[0,20,5.74],[1,20,0]],"ltp":3.75,"tv":23.24,"id":13117373},{"batb":[[0,4.6,28.37],[2,1.01,0.51]],"batl":[[0,5.2,15.89],[1,5.2,0]],"ltp":0.0,"tv":0.0,"id":13117374}]}]}
{"op":"mcm","clk":"1009221449","pt":1580664287112,"mc":[{"id":"1.168236369","rc":[{"batb":[[1,4.4,42.74],[2,1.01,0.51]],"ltp":0.0,"tv":0.0,"id":13117301},{"batb":[[0,1.83,74.64],[1,1.82,19.36],[2,1.81,91.5]],"ltp":2.42,"tv":135.0,"id":13117300},{"batb":[[0,5.2,61.14],[1,5.1,31.13],[2,1.01,0.51]],"ltp":3.75,"tv":23.24,"id":13117373}]}]}
{"op":"mcm","clk":"1009222414","pt":1580664293144,"mc":[{"id":"1.168236369","rc":[{"batb":[[0,4.5,17.39],[1,1.01,0.51],[2,1.01,0]],"ltp":0.0,"tv":0.0,"id":13117301},{"batb":[[0,5.2,12.59],[1,1.01,0.51],[2,1.01,0]],"ltp":3.75,"tv":23.24,"id":13117373}]}]}
{"op":"mcm","clk":"1009222941","pt":1580664296239,"mc":[{"id":"1.168236369","rc":[{"batb":[[0,4.7,47.28],[1,4.6,38.45],[2,4.5,17.39]],"batl":[[0,5.3,9.24],[1,5.5,14.32]],"ltp":0.0,"tv":0.0,"id":13117301},{"batl":[[0,1.98,42.01],[1,2.56,16.76]],"ltp":2.42,"tv":135.0,"id":13117300},{"batb":[[0,18.5,7.73],[1,18,10.56],[2,5.2,12.59]],"ltp":3.75,"tv":23.24,"id":13117373},{"batb":[[2,4.3,12.6]],"batl":[[0,5.1,10.08],[1,5.2,15.89]],"ltp":0.0,"tv":0.0,"id":13117374}]}]}
{"op":"mcm","clk":"1009223094","pt":1580664297145,"mc":[{"id":"1.168236369","rc":[{"batb":[[0,4.8,14.95],[1,4.7,47.28],[2,4.6,54.74]],"batl":[[2,5.6,13.85]],"ltp":0.0,"tv":0.0,"id":13117301},{"batl":[[0,1.91,19.04],[1,2.14,27.38]],"ltp":2.42,"tv":135.0,"id":13117300},{"batb":[[2,14.5,6.14]],"ltp":3.75,"tv":23.24,"id":13117373}]}]}
{"op":"mcm","clk":"1009223337","pt":1580664298635,"mc":[{"id":"1.168236369","rc":[{"batl":[[1,1.97,42.01],[2,2.14,27.38]],"ltp":2.42,"tv":135.0,"id":13117300}]}]}
{"op":"mcm","clk":"1009224409","pt":1580664304929,"mc":[{"id":"1.168236369","rc":[{"batb":[[2,14.5,5.98]],"batl":[[0,21,5.59]],"ltp":3.75,"tv":23.24,"id":13117373},{"batb":[[1,4.5,41.16],[2,4.4,17.55]],"ltp":0.0,"tv":0.0,"id":13117374}]}]}
{"op":"mcm","clk":"1009226720","pt":1580664320168,"mc":[{"id":"1.168236369","rc":[{"batb":[[0,1.82,19.36],[1,1.79,52.93],[2,1.72,23.05]],"ltp":2.42,"tv":135.0,"id":13117300}]}]}
{"op":"mcm","clk":"1009227147","pt":1580664323183,"mc":[{"id":"1.168236369","rc":[{"batb":[[0,4.7,62.47],[1,4.6,54.74],[2,4.4,11.76]],"ltp":0.0,"tv":0.0,"id":13117301},{"batb":[[0,1.82,89.42],[1,1.8,113.2],[2,1.79,52.93]],"batl":[[0,1.89,19.59],[2,2.12,28.33]],"ltp":2.42,"tv":135.0,"id":13117300},{"batb":[[0,18.5,12.04],[2,14.5,5.74]],"batl":[[0,21,5.35]],"ltp":3.75,"tv":23.24,"id":13117373},{"batb":[[0,4.6,49.05],[1,4.5,58],[2,4.3,12.6]],"batl":[[1,5.3,15.5]],"ltp":0.0,"tv":0.0,"id":13117374}]}]}
{"op":"mcm","clk":"1009230414","pt":1580664346030,"mc":[{"id":"1.168236369","rc":[{"batb":[[0,4.7,51.62]],"ltp":0.0,"tv":0.0,"id":13117301},{"batb":[[0,1.82,69.46]],"ltp":2.42,"tv":135.0,"id":13117300}]}]}
{"op":"mcm","clk":"1009230722","pt":1580664348216,"mc":[{"id":"1.168236369","rc":[{"batb":[[0,18.5,15.53]],"ltp":3.75,"tv":23.24,"id":13117373},{"batb":[[0,4.6,61.34]],"ltp":0.0,"tv":0.0,"id":13117374}]}]}
{"op":"mcm","clk":"1009230881","pt":1580664349234,"mc":[{"id":"1.168236369","rc":[{"batb":[[0,18.5,13.19]],"ltp":3.75,"tv":23.24,"id":13117373},{"batb":[[0,4.6,50.1]],"ltp":0.0,"tv":0.0,"id":13117374}]}]}
{"op":"mcm","clk":"1009232667","pt":1580664361746,"mc":[{"id":"1.168236369","rc":[{"batb":[[0,4.6,49.05]],"ltp":0.0,"tv":0.0,"id":13117374}]}]}
{"op":"mcm","clk":"1009233110","pt":1580664364924,"mc":[{"id":"1.168236369","rc":[{"batb":[[0,1.82,92.12]],"ltp":2.42,"tv":135.0,"id":13117300}]}]}
{"op":"mcm","clk":"1009233992","pt":1580664371032,"mc":[{"id":"1.168236369","rc":[{"batb":[[0,1.8,19.91],[1,1.79,52.93],[2,1.71,23.68]],"ltp":2.42,"tv":135.0,"id":13117300},{"batb":[[0,18.5,9.93]],"ltp":3.75,"tv":23.24,"id":13117373},{"batb":[[0,4.6,34.4]],"ltp":0.0,"tv":0.0,"id":13117374}]}]}
{"op":"mcm","clk":"1009234371","pt":1580664373634,"mc":[{"id":"1.168236369","rc":[{"batb":[[0,4.7,60.52]],"ltp":0.0,"tv":0.0,"id":13117301},{"batb":[[0,1.83,63.89],[1,1.81,91.57],[2,1.8,19.91]],"ltp":2.42,"tv":135.0,"id":13117300}]}]}
{"op":"mcm","clk":"1009239114","pt":1580664407906,"mc":[{"id":"1.168236369","rc":[{"trd":[[1.83,127.78]],"batb":[[0,1.8,19.91],[1,1.79,52.93],[2,1.71,23.68]],"batl":[[0,1.83,75.58],[1,1.89,19.59],[2,1.97,42.01]],"ltp":1.83,"tv":262.78,"id":13117300}],"tv":286.02}]}
{"op":"mcm","clk":"1009239560","pt":1580664410909,"mc":[{"id":"1.168236369","rc":[{"batb":[[0,1.82,97.09],[1,1.8,113.24],[2,1.79,52.93]],"batl":[[0,1.89,19.59],[1,1.97,42.01],[2,2.12,28.33]],"ltp":1.83,"tv":262.78,"id":13117300}]}]}
{"op":"mcm","clk":"1009239757","pt":1580664412200,"mc":[{"id":"1.168236369","rc":[{"batb":[[0,4.6,54.74],[1,4.4,11.76],[2,1.01,0.51]],"batl":[[1,5.6,13.85],[2,5.6,0]],"ltp":0.0,"tv":0.0,"id":13117301},{"batb":[[0,1.79,52.93],[1,1.71,23.68],[2,1.01,0.51]],"batl":[[0,1.97,42.01],[1,2.12,28.33],[2,2.12,0]],"ltp":1.83,"tv":262.78,"id":13117300},{"batb":[[0,9,7.24],[1,1.01,0.51],[2,14.5,0]],"ltp":3.75,"tv":23.24,"id":13117373},{"batb":[[0,4.6,28.37]],"ltp":0.0,"tv":0.0,"id":13117374}]}]}
{"op":"mcm","clk":"1009239992","pt":1580664414092,"mc":[{"id":"1.168236369","rc":[{"batb":[[1,1.01,0.51],[2,1.01,0]],"batl":[[0,5.6,13.85],[1,5.6,0]],"ltp":0.0,"tv":0.0,"id":13117301},{"batb":[[0,1.71,23.68],[1,1.01,0.51],[2,1.01,0]],"batl":[[0,2.12,28.33],[1,2.12,0]],"ltp":1.83,"tv":262.78,"id":13117300},{"batb":[[2,1.01,0.51]],"batl":[[0,5.3,15.5],[1,5.3,0]],"ltp":0.0,"tv":0.0,"id":13117374}]}]}
{"op":"mcm","clk":"1009240156","pt":1580664415204,"mc":[{"id":"1.168236369","rc":[{"batb":[[0,4.6,73.15],[1,4.5,40.37],[2,1.01,0.51]],"ltp":0.0,"tv":0.0,"id":13117301},{"batb":[[0,1.74,97.11],[1,1.72,108.73],[2,1.71,23.68]],"ltp":1.83,"tv":262.78,"id":13117300},{"batb":[[0,10,33.79],[1,9.8,14.9],[2,9,7.24]],"ltp":3.75,"tv":23.24,"id":13117373}]}]}
{"op":"mcm","clk":"1009240181","pt":1580664415416,"mc":[{"id":"1.168236369","rc":[{"batb":[[0,4.6,54.86],[1,1.01,0.51],[2,1.01,0]],"ltp":0.0,"tv":0.0,"id":13117301},{"batb":[[0,1.71,23.68],[1,1.01,0.51],[2,1.71,0]],"ltp":1.83,"tv":262.78,"id":13117300},{"batb":[[0,9,7.24],[1,1.01,0.51],[2,9,0]],"ltp":3.75,"tv":23.24,"id":13117373}]}]}
{"op":"mcm","clk":"1009240721","pt":1580664419226,"mc":[{"id":"1.168236369","rc":[{"batb":[[0,4.7,42.38],[1,4.6,54.86],[2,1.01,0.51]],"ltp":0.0,"tv":0.0,"id":13117301},{"batb":[[0,1.86,59.76],[1,1.84,86.82],[2,1.71,23.68]],"ltp":1.83,"tv":262.78,"id":13117300},{"batb":[[0,16,9.72],[1,15.5,14.41],[2,9,7.24]],"ltp":3.75,"tv":23.24,"id":13117373}]}]}
{"op":"mcm","clk":"1009240991","pt":1580664421236,"mc":[{"id":"1.168236369","rc":[{"batb":[[0,4.6,54.86],[1,1.01,0.51],[2,1.01,0]],"ltp":0.0,"tv":0.0,"id":13117301},{"batb":[[0,1.71,23.68],[1,1.01,0.51],[2,1.71,0]],"ltp":1.83,"tv":262.78,"id":13117300},{"batb":[[0,9,7.24],[1,1.01,0.51],[2,9,0]],"ltp":3.75,"tv":23.24,"id":13117373}]}]}
{"op":"mcm","clk":"1009241261","pt":1580664423107,"mc":[{"id":"1.168236369","rc":[{"batl":[[0,1.79,82.34],[1,2.12,28.33]],"ltp":1.83,"tv":262.78,"id":13117300}]}]}
{"op":"mcm","clk":"1009241403","pt":1580664424209,"mc":[{"id":"1.168236369","rc":[{"batb":[[0,4.6,73.15],[1,4.5,40.37],[2,1.01,0.51]],"ltp":0.0,"tv":0.0,"id":13117301},{"batb":[[0,1.74,97.11],[1,1.72,108.73],[2,1.71,23.68]],"ltp":1.83,"tv":262.78,"id":13117300},{"batb":[[0,10,33.79],[1,9.8,14.9],[2,9,7.24]],"ltp":3.75,"tv":23.24,"id":13117373}]}]}
{"op":"mcm","clk":"1009241499","pt":1580664424928,"mc":[{"id":"1.168236369","rc":[{"batb":[[0,4.6,16.29],[1,1.01,0.51],[2,1.01,0]],"ltp":0.0,"tv":0.0,"id":13117301},{"batb":[[0,9,7.24],[1,1.01,0.51],[2,9,0]],"ltp":3.75,"tv":23.24,"id":13117373}]}]}
{"op":"mcm","clk":"1009241568","pt":1580664425297,"mc":[{"id":"1.168236369","rc":[{"batl":[[0,2.12,28.33],[1,2.12,0]],"ltp":1.83,"tv":262.78,"id":13117300}]}]}
{"op":"mcm","clk":"1009241969","pt":1580664428219,"mc":[{"id":"1.168236369","rc":[{"batb":[[0,4.8,27.99],[1,4.7,36.91],[2,4.6,16.29]],"batl":[[0,5.4,9.24],[1,5.6,13.85]],"ltp":0.0,"tv":0.0,"id":13117301},{"batb":[[1,1.72,166.7]],"batl":[[0,1.88,42.01],[1,2.12,28.33]],"ltp":1.83,"tv":262.78,"id":13117300},{"batb":[[0,32,14.16],[1,30,7.38],[2,9,7.24]],"ltp":3.75,"tv":23.24,"id":13117373},{"batb":[[0,4.6,45.55],[2,4.3,12.6]],"batl":[[0,5.1,10.08],[1,5.3,15.5]],"ltp":0.0,"tv":0.0,"id":13117374}]}]}
{"op":"mcm","clk":"1009242065","pt":1580664428837,"mc":[{"id":"1.168236369","rc":[{"batb":[[0,4.8,42.62],[1,4.7,52.8],[2,4.5,11.76]],"batl":[[0,5.6,13.61],[1,5.6,0]],"ltp":0.0,"tv":0.0,"id":13117301},{"batl":[[0,1.8,23.21],[1,1.88,42.01],[2,1.95,17.78]],"ltp":1.83,"tv":262.78,"id":13117300},{"batb":[[2,23,3.15]],"ltp":3.75,"tv":23.24,"id":13117373},{"batb":[[0,4.6,61.76]],"batl":[[2,5.4,14.95]],"ltp":0.0,"tv":0.0,"id":13117374}]}]}
{"op":"mcm","clk":"1009242386","pt":1580664430939,"mc":[{"id":"1.168236369","rc":[{"batl":[[0,5.3,9.24],[1,5.6,13.61]],"ltp":0.0,"tv":0.0,"id":13117301}]}]}
{"op":"mcm","clk":"1009243029","pt":1580664435147,"mc":[{"id":"1.168236369","rc":[{"trd":[[1.74,164.68]],"batb":[[0,1.74,14.77]],"ltp":1.74,"tv":427.46,"id":13117300}],"tv":450.7}]}
{"op":"mcm","clk":"1009243502","pt":1580664438132,"mc":[{"id":"1.168236369","rc":[{"batb":[[0,1.74,81.23]],"ltp":1.74,"tv":427.46,"id":13117300}]}]}
{"op":"mcm","clk":"1009243912","pt":1580664441053,"mc":[{"id":"1.168236369","rc":[{"batb":[[0,4.8,14.63]],"ltp":0.0,"tv":0.0,"id":13117301},{"batb":[[0,1.72,57.97],[1,1.71,23.68],[2,1.64,27.3]],"ltp":1.74,"tv":427.46,"id":13117300},{"batb":[[0,23,3.15],[1,13,7.55],[2,1.01,0.51]],"ltp":3.75,"tv":23.24,"id":13117373},{"batb":[[0,4.6,16.21]],"ltp":0.0,"tv":0.0,"id":13117374}]}]}
{"op":"mcm","clk":"1009244093","pt":1580664442171,"mc":[{"id":"1.168236369","rc":[{"batb":[[0,4.7,52.8],[1,1.01,0.51],[2,4.5,0]],"batl":[[0,5.6,13.61],[1,5.6,0]],"ltp":0.0,"tv":0.0,"id":13117301},{"batb":[[0,1.64,27.3],[1,1.01,0.51],[2,1.64,0]],"batl":[[0,1.95,17.78],[1,1.88,0],[2,1.95,0]],"ltp":1.74,"tv":427.46,"id":13117300},{"batb":[[0,13,7.55],[1,1.01,0.51],[2,1.01,0]],"ltp":3.75,"tv":23.24,"id":13117373},{"batb":[[0,4.5,58],[1,1.01,0.51],[2,4.3,0]],"batl":[[0,5.4,14.95],[1,5.3,0],[2,5.4,0]],"ltp":0.0,"tv":0.0,"id":13117374}]}]}
{"op":"mcm","clk":"1009244362","pt":1580664443976,"mc":[{"id":"1.168236369","rc":[{"batb":[[1,4.6,38.67],[2,1.01,0.51]],"ltp":0.0,"tv":0.0,"id":13117301},{"batb":[[0,1.68,96.96],[1,1.67,60.64],[2,1.64,27.3]],"ltp":1.74,"tv":427.46,"id":13117300},{"batb":[[0,16,14.26],[1,15.5,14.3],[2,13,7.55]],"ltp":3.75,"tv":23.24,"id":13117373},{"batb":[[0,4.5,80.1],[1,4.4,43.38],[2,1.01,0.51]],"ltp":0.0,"tv":0.0,"id":13117374}]}]}
{"op":"mcm","clk":"1009245580","pt":1580664452691,"mc":[{"id":"1.168236369","rc":[{"batb":[[1,1.01,0.51],[2,1.01,0]],"ltp":0.0,"tv":0.0,"id":13117301},{"batb":[[0,13,7.55],[1,1.01,0.51],[2,13,0]],"ltp":3.75,"tv":23.24,"id":13117373},{"batb":[[0,4.5,16.84],[1,1.01,0.51],[2,1.01,0]],"ltp":0.0,"tv":0.0,"id":13117374}]}]}
{"op":"mcm","clk":"1009246082","pt":1580664455934,"mc":[{"id":"1.168236369","rc":[{"batb":[[0,4.9,14.16],[1,4.8,62.82],[2,4.7,52.8]],"batl":[[1,5.8,12.9]],"ltp":0.0,"tv":0.0,"id":13117301},{"batl":[[0,1.72,26.75],[1,1.82,22.03],[2,1.95,17.78]],"ltp":1.74,"tv":427.46,"id":13117300},{"batb":[[0,75,6.34],[1,70,2.84],[2,23,3.27]],"ltp":3.75,"tv":23.24,"id":13117373},{"batb":[[0,4.7,40.2],[1,4.6,39.71],[2,4.5,16.84]],"batl":[[1,5.5,14.16]],"ltp":0.0,"tv":0.0,"id":13117374}]}]}
{"op":"mcm","clk":"1009246246","pt":1580664457051,"mc":[{"id":"1.168236369","rc":[{"batb":[[2,4.7,36.91]],"batl":[[0,5.4,9.24],[1,5.6,13.61],[2,5.8,12.9]],"ltp":0.0,"tv":0.0,"id":13117301},{"batb":[[1,1.67,122.81]],"batl":[[2,1.83,42.01]],"ltp":1.74,"tv":427.46,"id":13117300},{"batl":[[0,5.2,9.24],[1,5.4,14.95],[2,5.5,14.16]],"ltp":0.0,"tv":0.0,"id":13117374}]}]}
{"op":"mcm","clk":"1009248971","pt":1580664475156,"mc":[{"id":"1.168236369","rc":[{"batb":[[1,4.8,36.86]],"ltp":0.0,"tv":0.0,"id":13117301},{"batb":[[0,1.67,62.17],[1,1.64,27.3],[2,1.59,30.69]],"ltp":1.74,"tv":427.46,"id":13117300},{"batb":[[0,23,3.27],[1,1.01,0.51],[2,23,0]],"ltp":3.75,"tv":23.24,"id":13117373},{"batb":[[0,4.7,15.58],[1,4.5,16.84],[2,4.4,11.76]],"ltp":0.0,"tv":0.0,"id":13117374}]}]}
{"op":"mcm","clk":"1009248998","pt":1580664475335,"mc":[{"id":"1.168236369","rc":[{"batb":[[0,4.8,36.86],[1,4.7,36.91],[2,1.01,0.51]],"batl":[[0,5.8,12.9],[1,5.6,0],[2,5.8,0]],"ltp":0.0,"tv":0.0,"id":13117301},{"batb":[[0,1.59,30.69],[1,1.01,0.51],[2,1.59,0]],"batl":[[0,1.82,22.03],[1,1.82,0],[2,1.83,0]],"ltp":1.74,"tv":427.46,"id":13117300},{"batb":[[0,4.5,16.84],[1,1.01,0.51],[2,4.4,0]],"batl":[[0,5.5,14.16],[1,5.4,0],[2,5.5,0]],"ltp":0.0,"tv":0.0,"id":13117374}]}]}
{"op":"mcm","clk":"1009249419","pt":1580664478148,"mc":[{"id":"1.168236369","rc":[{"batb":[[0,1.64,121.67],[1,1.63,66.23],[2,1.59,30.69]],"ltp":1.74,"tv":427.46,"id":13117300},{"batb":[[0,32,7.56],[1,30,14.24],[2,23,3.27]],"ltp":3.75,"tv":23.24,"id":13117373},{"batb":[[0,4.5,80],[1,4.4,43.35],[2,1.01,0.51]],"ltp":0.0,"tv":0.0,"id":13117374}]}]}
{"op":"mcm","clk":"1009249491","pt":1580664478635,"mc":[{"id":"1.168236369","rc":[{"batb":[[0,1.59,30.69],[1,1.01,0.51],[2,1.59,0]],"ltp":1.74,"tv":427.46,"id":13117300},{"batb":[[0,23,3.27],[1,1.01,0.51],[2,23,0]],"ltp":3.75,"tv":23.24,"id":13117373},{"batb":[[0,4.5,58.09],[1,1.01,0.51],[2,1.01,0]],"ltp":0.0,"tv":0.0,"id":13117374}]}]}
{"op":"mcm","clk":"1009249907","pt":1580664481738,"mc":[{"id":"1.168236369","rc":[{"batb":[[0,4.8,57.61]],"ltp":0.0,"tv":0.0,"id":13117301},{"batb":[[0,1.7,63.07],[1,1.68,117.88],[2,1.59,30.69]],"ltp":1.74,"tv":427.46,"id":13117300},{"batb":[[0,60,4.86],[1,55,6.96],[2,23,3.27]],"ltp":3.75,"tv":23.24,"id":13117373},{"batb":[[0,4.6,56.15],[1,4.5,58.09],[2,1.01,0.51]],"ltp":0.0,"tv":0.0,"id":13117374}]}]}
{"op":"mcm","clk":"1009250551","pt":1580664486141,"mc":[{"id":"1.168236369","rc":[{"batb":[[0,4.8,36.86]],"ltp":0.0,"tv":0.0,"id":13117301},{"batb":[[0,1.59,30.69],[1,1.01,0.51],[2,1.59,0]],"ltp":1.74,"tv":427.46,"id":13117300},{"batb":[[0,23,3.27],[1,1.01,0.51],[2,23,0]],"ltp":3.75,"tv":23.24,"id":13117373},{"batb":[[0,4.5,58.09],[1,1.01,0.51],[2,1.01,0]],"ltp":0.0,"tv":0.0,"id":13117374}]}]}
{"op":"mcm","clk":"1009251008","pt":1580664489057,"mc":[{"id":"1.168236369","rc":[{"batb":[[0,1.64,121.67],[1,1.63,66.23],[2,1.59,30.69]],"ltp":1.74,"tv":427.46,"id":13117300},{"batb":[[0,32,7.56],[1,30,14.24],[2,23,3.27]],"ltp":3.75,"tv":23.24,"id":13117373},{"batb":[[0,4.5,80],[1,4.4,43.35],[2,1.01,0.51]],"ltp":0.0,"tv":0.0,"id":13117374}]}]}
{"op":"mcm","clk":"1009252364","pt":1580664497540,"mc":[{"id":"1.168236369","rc":[{"batb":[[1,1.01,0.51],[2,1.01,0]],"ltp":0.0,"tv":0.0,"id":13117301},{"batb":[[0,23,3.27],[1,1.01,0.51],[2,23,0]],"ltp":3.75,"tv":23.24,"id":13117373},{"batb":[[0,4.5,16.84],[1,1.01,0.51],[2,1.01,0]],"ltp":0.0,"tv":0.0,"id":13117374}]}]}
{"op":"mcm","clk":"1009252787","pt":1580664500240,"mc":[{"id":"1.168236369","rc":[{"batb":[[0,4.9,25.72],[1,4.8,50.37],[2,1.01,0.51]],"ltp":0.0,"tv":0.0,"id":13117301},{"batb":[[0,4.7,47.39],[1,4.6,39.34],[2,4.5,16.84]],"ltp":0.0,"tv":0.0,"id":13117374}]}]}
{"op":"mcm","clk":"1009252924","pt":1580664501051,"mc":[{"id":"1.168236369","rc":[{"batb":[[0,5,13.45],[1,4.9,25.72],[2,4.8,49.97]],"batl":[[1,5.9,12.51]],"ltp":0.0,"tv":0.0,"id":13117301},{"batl":[[0,1.67,29.98],[1,1.74,25.89]],"ltp":1.74,"tv":427.46,"id":13117300},{"batb":[[0,1.01,0.51],[1,1.01,0]],"ltp":3.75,"tv":23.24,"id":13117373},{"batb":[[0,4.8,14.79],[1,4.7,47.39],[2,4.6,39.34]],"batl":[[1,5.7,13.38]],"ltp":0.0,"tv":0.0,"id":13117374}]}]}
{"op":"mcm","clk":"1009253270","pt":1580664502938,"mc":[{"id":"1.168236369","rc":[{"batl":[[0,5.4,9.24],[1,5.8,12.9],[2,5.9,12.51]],"ltp":0.0,"tv":0.0,"id":13117301},{"batb":[[0,1.64,187.21]],"batl":[[2,1.78,42.01]],"ltp":1.74,"tv":427.46,"id":13117300},{"batl":[[0,5.3,9.24],[1,5.5,14.16],[2,5.7,13.38]],"ltp":0.0,"tv":0.0,"id":13117374}]}]}
{"op":"mcm","clk":"1009254384","pt":1580664510132,"mc":[{"id":"1.168236369","rc":[{"batb":[[1,4.8,49.97],[2,4.5,11.76]],"ltp":0.0,"tv":0.0,"id":13117301},{"batb":[[0,1.64,132.47]],"ltp":1.74,"tv":427.46,"id":13117300},{"batb":[[1,4.7,38.06],[2,4.5,16.84]],"ltp":0.0,"tv":0.0,"id":13117374}]}]}
{"op":"mcm","clk":"1009254826","pt":1580664513053,"mc":[{"id":"1.168236369","rc":[{"batb":[[1,4.8,67.05],[2,4.7,36.4]],"ltp":0.0,"tv":0.0,"id":13117301},{"batb":[[0,4.8,61.3]],"ltp":0.0,"tv":0.0,"id":13117374}]}]}
{"op":"mcm","clk":"1009255120","pt":1580664515175,"mc":[{"id":"1.168236369","rc":[{"batb":[[1,4.8,49.97]],"ltp":0.0,"tv":0.0,"id":13117301},{"batb":[[0,1.64,65.54],[1,1.59,30.69],[2,1.56,32.81]],"ltp":1.74,"tv":427.46,"id":13117300},{"batb":[[0,4.8,14.79],[1,4.7,28.21]],"ltp":0.0,"tv":0.0,"id":13117374}]}]}
{"op":"mcm","clk":"1009255277","pt":1580664516166,"mc":[{"id":"1.168236369","rc":[{"batb":[[0,4.8,49.97],[1,4.7,36.4],[2,1.01,0.51]],"batl":[[0,5.9,12.51],[1,5.8,0],[2,5.9,0]],"ltp":0.0,"tv":0.0,"id":13117301},{"batb":[[0,1.56,32.81],[1,1.01,0.51],[2,1.56,0]],"batl":[[0,1.74,25.89],[1,1.74,0],[2,1.78,0]],"ltp":1.74,"tv":427.46,"id":13117300},{"batb":[[0,4.7,28.21],[1,4.5,16.84],[2,1.01,0.51]],"batl":[[0,5.7,13.38],[1,5.5,0],[2,5.7,0]],"ltp":0.0,"tv":0.0,"id":13117374}]}]}
{"op":"mcm","clk":"1009255556","pt":1580664518182,"mc":[{"id":"1.168236369","rc":[{"batb":[[0,1.62,66.43],[1,1.61,69.53],[2,1.56,32.81]],"ltp":1.74,"tv":427.46,"id":13117300},{"batb":[[0,110,2.38],[1,100,4.12],[2,1.01,0.51]],"ltp":3.75,"tv":23.24,"id":13117373},{"batb":[[1,4.6,40.27],[2,4.5,16.84]],"ltp":0.0,"tv":0.0,"id":13117374}]}]}
{"op":"mcm","clk":"1009255707","pt":1580664519202,"mc":[{"id":"1.168236369","rc":[{"batb":[[0,1.56,32.81],[1,1.01,0.51],[2,1.56,0]],"ltp":1.74,"tv":427.46,"id":13117300},{"batb":[[0,1.01,0.51],[1,100,0],[2,1.01,0]],"ltp":3.75,"tv":23.24,"id":13117373},{"batb":[[1,4.5,16.84],[2,1.01,0.51]],"ltp":0.0,"tv":0.0,"id":13117374}]}]}
{"op":"mcm","clk":"1009255978","pt":1580664521144,"mc":[{"id":"1.168236369","rc":[{"batb":[[0,4.8,62.24]],"ltp":0.0,"tv":0.0,"id":13117301},{"batb":[[0,1.64,118.55],[1,1.63,66.35],[2,1.56,32.81]],"ltp":1.74,"tv":427.46,"id":13117300},{"batb":[[0,4.8,35.21],[1,4.7,38.24],[2,4.5,16.84]],"ltp":0.0,"tv":0.0,"id":13117374}]}]}
{"op":"mcm","clk":"1009256444","pt":1580664524172,"mc":[{"id":"1.168236369","rc":[{"batb":[[0,4.8,49.97]],"ltp":0.0,"tv":0.0,"id":13117301},{"batb":[[0,1.56,32.81],[1,1.01,0.51],[2,1.56,0]],"ltp":1.74,"tv":427.46,"id":13117300},{"batb":[[0,4.7,28.21],[1,4.5,16.84],[2,1.01,0.51]],"ltp":0.0,"tv":0.0,"id":13117374}]}]}
{"op":"mcm","clk":"1009256885","pt":1580664527143,"mc":[{"id":"1.168236369","rc":[{"batb":[[0,1.62,66.43],[1,1.61,69.53],[2,1.56,32.81]],"ltp":1.74,"tv":427.46,"id":13117300},{"batb":[[0,110,2.38],[1,100,4.12],[2,1.01,0.51]],"ltp":3.75,"tv":23.24,"id":13117373},{"batb":[[1,4.6,40.27],[2,4.5,16.84]],"ltp":0.0,"tv":0.0,"id":13117374}]}]}
{"op":"mcm","clk":"1009257045","pt":1580664528202,"mc":[{"id":"1.168236369","rc":[{"batb":[[0,1.56,32.81],[1,1.01,0.51],[2,1.56,0]],"ltp":1.74,"tv":427.46,"id":13117300}]}]}
{"op":"mcm","clk":"1009257350","pt":1580664530169,"mc":[{"id":"1.168236369","rc":[{"batb":[[0,1.68,69.83],[1,1.67,60.69],[2,1.56,32.81]],"ltp":1.74,"tv":427.46,"id":13117300}]}]}
{"op":"mcm","clk":"1009257503","pt":1580664531093,"mc":[{"id":"1.168236369","rc":[{"batb":[[1,4.7,51.74],[2,4.5,11.76]],"batl":[[0,5.3,9.24],[1,5.5,14.08],[2,5.7,13.3]],"ltp":0.0,"tv":0.0,"id":13117301},{"batb":[[1,1.67,122.86],[2,1.66,26.36]],"batl":[[1,1.83,21.72]],"ltp":1.74,"tv":427.46,"id":13117300},{"batb":[[2,26,4.02]],"ltp":3.75,"tv":23.24,"id":13117373},{"batl":[[0,5.1,10.08],[1,5.2,16.05],[2,5.3,15.34]],"ltp":0.0,"tv":0.0,"id":13117374}]}]}
{"op":"mcm","clk":"1009257829","pt":1580664533196,"mc":[{"id":"1.168236369","rc":[{"batl":[[1,1.83,63.73]],"ltp":1.74,"tv":427.46,"id":13117300}]}]}
{"op":"mcm","clk":"1009260289","pt":1580664550019,"mc":[{"id":"1.168236369","rc":[{"batb":[[0,4.7,51.74],[1,4.5,11.76],[2,1.01,0.51]],"batl":[[1,5.7,13.3],[2,5.7,0]],"ltp":0.0,"tv":0.0,"id":13117301},{"batb":[[0,1.67,62.17],[1,1.6,29.58],[2,1.01,0.51]],"batl":[[0,1.83,63.73],[1,1.83,0]],"ltp":1.74,"tv":427.46,"id":13117300},{"batb":[[0,26,4.02],[1,1.01,0.51],[2,26,0]],"ltp":3.75,"tv":23.24,"id":13117373},{"batb":[[0,4.6,24.44],[1,4.4,18.25],[2,4.3,12.6]],"batl":[[1,5.3,15.34],[2,5.3,0]],"ltp":0.0,"tv":0.0,"id":13117374}]}]}
{"op":"mcm","clk":"1009260597","pt":1580664552010,"mc":[{"id":"1.168236369","rc":[{"batb":[[1,1.01,0.51],[2,1.01,0]],"batl":[[0,5.7,13.3],[1,5.7,0]],"ltp":0.0,"tv":0.0,"id":13117301},{"batb":[[0,1.6,29.58],[1,1.01,0.51],[2,1.01,0]],"batl":[[0,1.83,21.72]],"ltp":1.74,"tv":427.46,"id":13117300},{"batb":[[2,1.01,0.51]],"batl":[[0,5.3,15.34],[1,5.3,0]],"ltp":0.0,"tv":0.0,"id":13117374}]}]}
{"op":"mcm","clk":"1009260766","pt":1580664553106,"mc":[{"id":"1.168236369","rc":[{"batl":[[0,5.6,13.53]],"ltp":0.0,"tv":0.0,"id":13117301},{"batb":[[0,1.61,29.03]],"batl":[[0,1.84,21.32]],"ltp":1.74,"tv":427.46,"id":13117300},{"batb":[[1,4.5,42.44],[2,4.3,18.57]],"ltp":0.0,"tv":0.0,"id":13117374}]}]}
{"op":"mcm","clk":"1009261058","pt":1580664555218,"mc":[{"id":"1.168236369","rc":[{"batb":[[0,4.8,23.06],[1,4.7,51.74],[2,1.01,0.51]],"ltp":0.0,"tv":0.0,"id":13117301},{"batb":[[0,1.69,88.29],[1,1.67,120.75],[2,1.61,29.03]],"ltp":1.74,"tv":427.46,"id":13117300},{"batb":[[0,80,3.7],[1,75,5.03],[2,26,4.02]],"ltp":3.75,"tv":23.24,"id":13117373},{"batb":[[0,4.6,61.1]],"ltp":0.0,"tv":0.0,"id":13117374}]}]}
{"op":"mcm","clk":"1009261730","pt":1580664560112,"mc":[{"id":"1.168236369","rc":[{"batb":[[0,4.7,51.74],[1,1.01,0.51],[2,1.01,0]],"ltp":0.0,"tv":0.0,"id":13117301},{"batb":[[0,1.61,29.03],[1,1.01,0.51],[2,1.61,0]],"ltp":1.74,"tv":427.46,"id":13117300},{"batb":[[0,26,4.02],[1,1.01,0.51],[2,26,0]],"ltp":3.75,"tv":23.24,"id":13117373},{"batb":[[0,4.6,24.44]],"ltp":0.0,"tv":0.0,"id":13117374}]}]}
{"op":"mcm","clk":"1009262147","pt":1580664563027,"mc":[{"id":"1.168236369","rc":[{"batb":[[1,4.6,38.49],[2,1.01,0.51]],"ltp":0.0,"tv":0.0,"id":13117301},{"batb":[[0,1.64,101.5],[1,1.63,66.55],[2,1.61,29.03]],"ltp":1.74,"tv":427.46,"id":13117300},{"batb":[[0,38,9.37],[1,36,8.84],[2,26,4.02]],"ltp":3.75,"tv":23.24,"id":13117373}]}]}
{"op":"mcm","clk":"1009265345","pt":1580664584032,"mc":[{"id":"1.168236369","rc":[{"batb":[[1,1.01,0.51],[2,1.01,0]],"ltp":0.0,"tv":0.0,"id":13117301},{"batb":[[0,26,4.02],[1,1.01,0.51],[2,26,0]],"ltp":3.75,"tv":23.24,"id":13117373},{"batb":[[1,4.3,18.57],[2,1.01,0.51]],"ltp":0.0,"tv":0.0,"id":13117374}]}]}
{"op":"mcm","clk":"1009265788","pt":1580664587110,"mc":[{"id":"1.168236369","rc":[{"batb":[[0,4.8,42.09],[1,4.7,51.74],[2,1.01,0.51]],"ltp":0.0,"tv":0.0,"id":13117301},{"batb":[[0,4.7,53.39],[1,4.6,39.88],[2,4.3,18.57]],"ltp":0.0,"tv":0.0,"id":13117374}]}]}
{"op":"mcm","clk":"1009265943","pt":1580664588224,"mc":[{"id":"1.168236369","rc":[{"batb":[[0,4.9,14.16],[1,4.8,42.09],[2,4.7,36.4]],"batl":[[1,6.6,19.67]],"ltp":0.0,"tv":0.0,"id":13117301},{"batl":[[0,1.69,28.48],[1,1.79,23.45]],"ltp":1.74,"tv":427.46,"id":13117300},{"batb":[[0,1.01,0.51],[1,1.01,0]],"ltp":3.75,"tv":23.24,"id":13117373},{"batb":[[1,4.6,56.17],[2,4.2,19.75]],"batl":[[1,6.2,11.41]],"ltp":0.0,"tv":0.0,"id":13117374}]}]}
{"op":"mcm","clk":"1009266072","pt":1580664589118,"mc":[{"id":"1.168236369","rc":[{"batl":[[0,5.4,9.24],[1,5.6,13.53],[2,6.6,19.67]],"ltp":0.0,"tv":0.0,"id":13117301},{"batb":[[0,1.64,167.04]],"batl":[[1,1.79,65.46]],"ltp":1.74,"tv":427.46,"id":13117300},{"batb":[[2,4.3,12.6]],"batl":[[0,5.1,10.08],[1,5.3,15.34],[2,6.2,11.41]],"ltp":0.0,"tv":0.0,"id":13117374}]}]}
{"op":"mcm","clk":"1009269312","pt":1580664609970,"mc":[{"id":"1.168236369","rc":[{"batb":[[0,4.7,45.73]],"ltp":0.0,"tv":0.0,"id":13117374}]}]}
{"op":"mcm","clk":"1009270373","pt":1580664616613,"mc":[{"id":"1.168236369","rc":[{"batl":[[1,5.7,13.45]],"ltp":0.0,"tv":0.0,"id":13117301},{"batb":[[2,1.62,28.72]],"batl":[[0,1.7,28.09],[1,1.79,42.01],[2,1.8,23.13]],"ltp":1.74,"tv":427.46,"id":13117300},{"batb":[[1,4.6,39.88],[2,4.5,16.84]],"batl":[[1,5.2,16.05],[2,6,11.72]],"ltp":0.0,"tv":0.0,"id":13117374}]}]}
{"op":"mcm","clk":"1009271234","pt":1580664621884,"mc":[{"id":"1.168236369","rc":[{"batb":[[0,4.9,14.01]],"batl":[[2,6.6,19.51]],"ltp":0.0,"tv":0.0,"id":13117301},{"batb":[[2,1.62,28.56]],"batl":[[0,1.7,27.93]],"ltp":1.74,"tv":427.46,"id":13117300}]}]}
