{"op":"mcm","clk":"1002113593","pt":1580590610212,"mc":[{"id":"1.168236368","marketDefinition":{"bspMarket":false,"turnInPlayEnabled":true,"persistenceEnabled":true,"marketBaseRate":5.0,"eventId":"29681838","eventTypeId":"2","numberOfWinners":1,"bettingType":"ODDS","marketType":"MATCH_ODDS","marketTime":"2020-02-02T16:00:00.000Z","suspendTime":"2020-02-02T16:00:00.000Z","bspReconciled":false,"complete":true,"inPlay":false,"crossMatching":false,"runnersVoidable":false,"numberOfActiveRunners":2,"betDelay":0,"status":"OPEN","runners":[{"status":"ACTIVE","sortPriority":1,"id":4520808,"name":"Facundo Bagnis"},{"status":"ACTIVE","sortPriority":2,"id":8284479,"name":"Federico Gaio"}],"regulators":["MR_INT"],"countryCode":"AR","discountAllowed":false,"timezone":"UTC","openDate":"2020-02-02T16:00:00.000Z","version":3147446749,"name":"Match Odds","eventName":"Bagnis v Gaio"},"rc":[{"batb":[[0,1.05,152.2],[1,1.04,168.86],[2,1.03,190.07]],"ltp":0.0,"tv":0.0,"id":4520808},{"batb":[[0,1.05,152.2],[1,1.04,168.86],[2,1.03,190.07]],"ltp":0.0,"tv":0.0,"id":8284479}]}]}
{"op":"mcm","clk":"1002113713","pt":1580590611242,"mc":[{"id":"1.168236368","marketDefinition":{"bspMarket":false,"turnInPlayEnabled":true,"persistenceEnabled":true,"marketBaseRate":5.0,"eventId":"29681838","eventTypeId":"2","numberOfWinners":1,"bettingType":"ODDS","marketType":"MATCH_ODDS","marketTime":"2020-02-02T16:00:00.000Z","suspendTime":"2020-02-02T16:00:00.000Z","bspReconciled":false,"complete":true,"inPlay":false,"crossMatching":false,"runnersVoidable":false,"numberOfActiveRunners":2,"betDelay":0,"status":"OPEN","runners":[{"status":"ACTIVE","sortPriority":1,"id":4520808,"name":"Facundo Bagnis"},{"status":"ACTIVE","sortPriority":2,"id":8284479,"name":"Federico Gaio"}],"regulators":["MR_INT"],"countryCode":"AR","discountAllowed":false,"timezone":"UTC","openDate":"2020-02-02T16:00:00.000Z","version":3147446749,"name":"Match Odds","eventName":"Bagnis v Gaio"}}]}
{"op":"mcm","clk":"1002113926","pt":1580590613250,"mc":[{"id":"1.168236368","marketDefinition":{"bspMarket":false,"turnInPlayEnabled":true,"persistenceEnabled":true,"marketBaseRate":5.0,"eventId":"29681838","eventTypeId":"2","numberOfWinners":1,"bettingType":"ODDS","marketType":"MATCH_ODDS","marketTime":"2020-02-02T16:00:00.000Z","suspendTime":"2020-02-02T16:00:00.000Z","bspReconciled":false,"complete":true,"inPlay":false,"crossMatching":false,"runnersVoidable":false,"numberOfActiveRunners":2,"betDelay":0,"status":"OPEN","runners":[{"status":"ACTIVE","sortPriority":1,"id":4520808,"name":"Facundo Bagnis"},{"status":"ACTIVE","sortPriority":2,"id":8284479,"name":"Federico Gaio"}],"regulators":["MR_INT"],"countryCode":"AR","discountAllowed":true,"timezone":"UTC","openDate":"2020-02-02T16:00:00.000Z","version":3147446749,"name":"Match Odds","eventName":"Bagnis v Gaio"}}]}
{"op":"mcm","clk":"1002169358","pt":1580591112869,"mc":[{"id":"1.168236368","rc":[{"batl":[[0,990,1.51]],"ltp":0.0,"tv":0.0,"id":4520808},{"batl":[[0,990,1.51]],"ltp":0.0,"tv":0.0,"id":8284479}]}]}
{"op":"mcm","clk":"1002171585","pt":1580591130783,"mc":[{"id":"1.168236368","rc":[{"batb":[[2,1.03,237.77]],"ltp":0.0,"tv":0.0,"id":4520808},{"batb":[[2,1.03,237.77]],"ltp":0.0,"tv":0.0,"id":8284479}]}]}
{"op":"mcm","clk":"1002175620","pt":1580591163394,"mc":[{"id":"1.168236368","marketDefinition":{"bspMarket":false,"turnInPlayEnabled":true,"persistenceEnabled":true,"marketBaseRate":5.0,"eventId":"29681838","eventTypeId":"2","numberOfWinners":1,"bettingType":"ODDS","marketType":"MATCH_ODDS","marketTime":"2020-02-02T16:00:00.000Z","suspendTime":"2020-02-02T16:00:00.000Z","bspReconciled":false,"complete":true,"inPlay":false,"crossMatching":true,"runnersVoidable":false,"numberOfActiveRunners":2,"betDelay":0,"status":"OPEN","runners":[{"status":"ACTIVE","sortPriority":1,"id":4520808,"name":"Facundo Bagnis"},{"status":"ACTIVE","sortPriority":2,"id":8284479,"name":"Federico Gaio"}],"regulators":["MR_INT"],"countryCode":"AR","discountAllowed":true,"timezone":"UTC","openDate":"2020-02-02T16:00:00.000Z","version":3147446749,"name":"Match Odds","eventName":"Bagnis v Gaio"}}]}
{"op":"mcm","clk":"1002216070","pt":1580591500536,"mc":[{"id":"1.168236368","rc":[{"batb":[[0,1.06,50.48],[1,1.05,152.2],[2,1.04,168.86]],"ltp":0.0,"tv":0.0,"id":4520808},{"batb":[[0,1.06,50.48],[1,1.05,152.2],[2,1.04,168.86]],"ltp":0.0,"tv":0.0,"id":8284479}]}]}
{"op":"mcm","clk":"1002548565","pt":1580595201242,"mc":[{"id":"1.168236368","rc":[{"batl":[[0,990,3.71]],"ltp":0.0,"tv":0.0,"id":4520808},{"batl":[[0,990,3.71]],"ltp":0.0,"tv":0.0,"id":8284479}]}]}
{"op":"mcm","clk":"1002656448","pt":1580596737309,"mc":[{"id":"1.168236368","rc":[{"batb":[[0,1.5,681.51],[1,1.06,50.48],[2,1.05,152.2]],"ltp":0.0,"tv":0.0,"id":4520808}]}]}
{"op":"mcm","clk":"1002662283","pt":1580596835114,"mc":[{"id":"1.168236368","rc":[{"batb":[[0,1.51,6.59],[1,1.5,681.51],[2,1.06,50.48]],"ltp":0.0,"tv":0.0,"id":4520808}]}]}
{"op":"mcm","clk":"1002962018","pt":1580601235531,"mc":[{"id":"1.168236368","rc":[{"batb":[[0,1.6,1950.93],[1,1.06,50.48],[2,1.05,152.2]],"ltp":0.0,"tv":0.0,"id":8284479}]}]}
{"op":"mcm","clk":"1002962313","pt":1580601239634,"mc":[{"id":"1.168236368","rc":[{"batb":[[0,1.61,8.4],[1,1.6,1950.93],[2,1.06,50.48]],"ltp":0.0,"tv":0.0,"id":8284479}]}]}
{"op":"mcm","clk":"1002962834","pt":1580601247131,"mc":[{"id":"1.168236368","rc":[{"batb":[[2,1.24,260.46]],"ltp":0.0,"tv":0.0,"id":4520808}]}]}
{"op":"mcm","clk":"1002962978","pt":1580601249250,"mc":[{"id":"1.168236368","rc":[{"batb":[[2,1.06,50.48]],"ltp":0.0,"tv":0.0,"id":4520808}]}]}
{"op":"mcm","clk":"1002963257","pt":1580601253554,"mc":[{"id":"1.168236368","rc":[{"batb":[[2,1.24,2680.22]],"ltp":0.0,"tv":0.0,"id":4520808}]}]}
{"op":"mcm","clk":"1002963473","pt":1580601256569,"mc":[{"id":"1.168236368","rc":[{"batb":[[2,1.25,8.4]],"ltp":0.0,"tv":0.0,"id":4520808}]}]}
{"op":"mcm","clk":"1002984545","pt":1580601551019,"mc":[{"id":"1.168236368","rc":[{"batl":[[1,1000,0.02]],"ltp":0.0,"tv":0.0,"id":4520808},{"batl":[[1,1000,0.02]],"ltp":0.0,"tv":0.0,"id":8284479}]}]}
{"op":"mcm","clk":"1002984566","pt":1580601551429,"mc":[{"id":"1.168236368","rc":[{"batb":[[2,1.06,50.58]],"ltp":0.0,"tv":0.0,"id":8284479}]}]}
{"op":"mcm","clk":"1002990180","pt":1580601627509,"mc":[{"id":"1.168236368","rc":[{"batb":[[2,1.06,50.68]],"ltp":0.0,"tv":0.0,"id":8284479}]}]}
{"op":"mcm","clk":"1003007370","pt":1580601890395,"mc":[{"id":"1.168236368","rc":[{"batb":[[0,1.61,15.3]],"ltp":0.0,"tv":0.0,"id":8284479}]}]}
{"op":"mcm","clk":"1003325754","pt":1580606249158,"mc":[{"id":"1.168236368","rc":[{"batb":[[0,1.54,28.62],[1,1.51,6.59],[2,1.5,681.51]],"ltp":0.0,"tv":0.0,"id":4520808},{"batb":[[0,1.65,23.93],[1,1.61,15.3],[2,1.6,1950.93]],"ltp":0.0,"tv":0.0,"id":8284479}]}]}
{"op":"mcm","clk":"1003335755","pt":1580606373086,"mc":[{"id":"1.168236368","rc":[{"batb":[[0,1.57,57.55],[1,1.54,28.62],[2,1.51,6.59]],"ltp":0.0,"tv":0.0,"id":4520808}]}]}
{"op":"mcm","clk":"1003335805","pt":1580606373708,"mc":[{"id":"1.168236368","rc":[{"batb":[[0,1.59,27.72],[1,1.57,57.55]],"ltp":0.0,"tv":0.0,"id":4520808},{"batb":[[0,1.83,21.56],[1,1.74,52.25],[2,1.61,15.3]],"ltp":0.0,"tv":0.0,"id":8284479}]}]}
{"op":"mcm","clk":"1003339769","pt":1580606429204,"mc":[{"id":"1.168236368","rc":[{"batb":[[0,1.67,57.55],[1,1.51,6.59],[2,1.5,681.51]],"ltp":0.0,"tv":0.0,"id":4520808},{"batb":[[0,1.86,52.25],[1,1.61,15.3],[2,1.6,1950.93]],"ltp":0.0,"tv":0.0,"id":8284479}]}]}
{"op":"mcm","clk":"1003339776","pt":1580606429258,"mc":[{"id":"1.168236368","rc":[{"batb":[[0,1.73,25.65],[1,1.67,57.55],[2,1.51,6.59]],"ltp":0.0,"tv":0.0,"id":4520808},{"batb":[[0,1.88,20.96],[1,1.86,52.25],[2,1.61,15.3]],"ltp":0.0,"tv":0.0,"id":8284479}]}]}
{"op":"mcm","clk":"1003364501","pt":1580606784138,"mc":[{"id":"1.168236368","rc":[{"batb":[[1,1.72,57.55]],"ltp":0.0,"tv":0.0,"id":4520808},{"batb":[[0,1.97,19.85],[1,1.92,52.25]],"ltp":0.0,"tv":0.0,"id":8284479}]}]}
{"op":"mcm","clk":"1003392677","pt":1580607130513,"mc":[{"id":"1.168236368","rc":[{"batb":[[2,1.61,8.4]],"ltp":0.0,"tv":0.0,"id":8284479}]}]}
{"op":"mcm","clk":"1003414130","pt":1580607421107,"mc":[{"id":"1.168236368","rc":[{"batl":[[0,11.5,3.36],[1,990,3.71],[2,1000,0.02]],"ltp":0.0,"tv":0.0,"id":4520808},{"batl":[[0,13,3.36],[1,990,3.71],[2,1000,0.02]],"ltp":0.0,"tv":0.0,"id":8284479}]}]}
{"op":"mcm","clk":"1003447380","pt":1580607862122,"mc":[{"id":"1.168236368","rc":[{"batb":[[2,1.51,8.4]],"ltp":0.0,"tv":0.0,"id":8284479}]}]}
{"op":"mcm","clk":"1003584700","pt":1580609866765,"mc":[{"id":"1.168236368","rc":[{"batb":[[0,1.73,38.13]],"ltp":0.0,"tv":0.0,"id":4520808},{"batb":[[0,1.97,29.84]],"ltp":0.0,"tv":0.0,"id":8284479}]}]}
{"op":"mcm","clk":"1003721698","pt":1580611865644,"mc":[{"id":"1.168236368","rc":[{"batb":[[2,1.66,43.6]],"ltp":0.0,"tv":0.0,"id":4520808},{"batb":[[2,1.85,33.86]],"ltp":0.0,"tv":0.0,"id":8284479}]}]}
{"op":"mcm","clk":"1003805795","pt":1580613450817,"mc":[{"id":"1.168236368","rc":[{"batb":[[0,1.75,37.79]],"ltp":0.0,"tv":0.0,"id":4520808},{"batb":[[0,1.98,29.76]],"ltp":0.0,"tv":0.0,"id":8284479}]}]}
{"op":"mcm","clk":"1003810332","pt":1580613588533,"mc":[{"id":"1.168236368","rc":[{"batb":[[0,1.75,50.23]],"ltp":0.0,"tv":0.0,"id":4520808},{"batb":[[0,1.98,39.76]],"ltp":0.0,"tv":0.0,"id":8284479}]}]}
{"op":"mcm","clk":"1003810376","pt":1580613589927,"mc":[{"id":"1.168236368","rc":[{"batb":[[2,1.51,6.59]],"ltp":0.0,"tv":0.0,"id":4520808},{"batb":[[2,1.51,8.4]],"ltp":0.0,"tv":0.0,"id":8284479}]}]}
{"op":"mcm","clk":"1003810407","pt":1580613590653,"mc":[{"id":"1.168236368","rc":[{"batb":[[2,1.66,57.37]],"ltp":0.0,"tv":0.0,"id":4520808},{"batb":[[2,1.85,44.54]],"ltp":0.0,"tv":0.0,"id":8284479}]}]}
{"op":"mcm","clk":"1003844035","pt":1580614311665,"mc":[{"id":"1.168236368","rc":[{"batl":[[0,1.82,2.52],[1,11.5,3.36],[2,990,3.71]],"ltp":0.0,"tv":0.0,"id":4520808},{"batb":[[0,1.92,52.25],[1,1.85,44.54],[2,1.51,8.4]],"ltp":0.0,"tv":0.0,"id":8284479}]}]}
{"op":"mcm","clk":"1003844587","pt":1580614321297,"mc":[{"id":"1.168236368","rc":[{"batl":[[1,990,3.71],[2,1000,0.02]],"ltp":0.0,"tv":0.0,"id":4520808}]}]}
{"op":"mcm","clk":"1003914287","pt":1580616046685,"mc":[{"id":"1.168236368","rc":[{"batb":[[0,1.93,52.25]],"ltp":0.0,"tv":0.0,"id":8284479}]}]}
{"op":"mcm","clk":"1003946878","pt":1580616810074,"mc":[{"id":"1.168236368","rc":[{"batl":[[1,95,15.9],[2,990,3.71]],"ltp":0.0,"tv":0.0,"id":4520808},{"batl":[[1,95,15.9],[2,990,3.71]],"ltp":0.0,"tv":0.0,"id":8284479}]}]}
{"op":"mcm","clk":"1003959800","pt":1580617051836,"mc":[{"id":"1.168236368","rc":[{"batb":[[0,1.76,50.48]],"ltp":0.0,"tv":0.0,"id":4520808}]}]}
{"op":"mcm","clk":"1003969418","pt":1580617260894,"mc":[{"id":"1.168236368","rc":[{"batb":[[0,1.76,62.98]],"ltp":0.0,"tv":0.0,"id":4520808}]}]}
{"op":"mcm","clk":"1003969470","pt":1580617261976,"mc":[{"id":"1.168236368","rc":[{"batb":[[2,1.51,6.59]],"ltp":0.0,"tv":0.0,"id":4520808},{"batb":[[1,1.51,8.4],[2,1.5,1950.93]],"ltp":0.0,"tv":0.0,"id":8284479}]}]}
{"op":"mcm","clk":"1003969506","pt":1580617262595,"mc":[{"id":"1.168236368","rc":[{"batb":[[2,1.66,72.28]],"ltp":0.0,"tv":0.0,"id":4520808},{"batb":[[1,1.85,56.13],[2,1.51,8.4]],"ltp":0.0,"tv":0.0,"id":8284479}]}]}
{"op":"mcm","clk":"1004024915","pt":1580618475196,"mc":[{"id":"1.168236368","rc":[{"batb":[[2,1.52,75.72]],"ltp":0.0,"tv":0.0,"id":8284479}]}]}
{"op":"mcm","clk":"1004049985","pt":1580618989559,"mc":[{"id":"1.168236368","rc":[{"batb":[[2,1.52,30.29]],"ltp":0.0,"tv":0.0,"id":8284479}]}]}
{"op":"mcm","clk":"1004053365","pt":1580619080530,"mc":[{"id":"1.168236368","rc":[{"batb":[[0,1.76,113.23]],"ltp":0.0,"tv":0.0,"id":4520808}]}]}
{"op":"mcm","clk":"1004053474","pt":1580619082696,"mc":[{"id":"1.168236368","rc":[{"batb":[[2,1.51,36.88]],"ltp":0.0,"tv":0.0,"id":4520808},{"batb":[[1,1.52,30.29],[2,1.51,8.4]],"ltp":0.0,"tv":0.0,"id":8284479}]}]}
{"op":"mcm","clk":"1004053508","pt":1580619083318,"mc":[{"id":"1.168236368","rc":[{"batb":[[2,1.68,125.84]],"ltp":0.0,"tv":0.0,"id":4520808},{"batb":[[1,1.88,97.24],[2,1.52,30.29]],"ltp":0.0,"tv":0.0,"id":8284479}]}]}
{"op":"mcm","clk":"1004079049","pt":1580619780348,"mc":[{"id":"1.168236368","rc":[{"batb":[[0,1.77,6.59],[1,1.76,113.23],[2,1.72,57.55]],"ltp":0.0,"tv":0.0,"id":4520808}]}]}
{"op":"mcm","clk":"1004085962","pt":1580619956389,"mc":[{"id":"1.168236368","rc":[{"batb":[[1,1.72,57.55],[2,1.68,125.84]],"ltp":0.0,"tv":0.0,"id":4520808}]}]}
{"op":"mcm","clk":"1004126353","pt":1580620901955,"mc":[{"id":"1.168236368","rc":[{"batb":[[2,1.51,30.29]],"ltp":0.0,"tv":0.0,"id":4520808},{"batb":[[1,1.52,30.29],[2,1.51,8.4]],"ltp":0.0,"tv":0.0,"id":8284479}]}]}
{"op":"mcm","clk":"1004126381","pt":1580620902573,"mc":[{"id":"1.168236368","rc":[{"batb":[[2,1.7,168.76]],"ltp":0.0,"tv":0.0,"id":4520808},{"batb":[[1,1.92,128.4],[2,1.52,30.29]],"ltp":0.0,"tv":0.0,"id":8284479}]}]}
{"op":"mcm","clk":"1004177909","pt":1580622259100,"mc":[{"id":"1.168236368","rc":[{"batb":[[0,1.73,160.76],[2,1.71,6.59]],"ltp":0.0,"tv":0.0,"id":4520808}]}]}
{"op":"mcm","clk":"1004212363","pt":1580623326952,"mc":[{"id":"1.168236368","rc":[{"batb":[[1,1.52,30.29],[2,1.51,8.4]],"ltp":0.0,"tv":0.0,"id":8284479}]}]}
{"op":"mcm","clk":"1004212389","pt":1580623327522,"mc":[{"id":"1.168236368","rc":[{"batb":[[2,1.71,172.97]],"ltp":0.0,"tv":0.0,"id":4520808},{"batb":[[1,1.9,131.25],[2,1.52,30.29]],"ltp":0.0,"tv":0.0,"id":8284479}]}]}
{"op":"mcm","clk":"1004212444","pt":1580623329110,"mc":[{"id":"1.168236368","rc":[{"batb":[[0,1.74,57.55],[1,1.73,160.76]],"ltp":0.0,"tv":0.0,"id":4520808}]}]}
{"op":"mcm","clk":"1004213037","pt":1580623344856,"mc":[{"id":"1.168236368","rc":[{"batb":[[0,1.76,157.98],[1,1.73,57.55]],"ltp":0.0,"tv":0.0,"id":4520808},{"batb":[[0,1.91,52.25]],"ltp":0.0,"tv":0.0,"id":8284479}]}]}
{"op":"mcm","clk":"1004216282","pt":1580623443006,"mc":[{"id":"1.168236368","rc":[{"batb":[[0,1.91,182.06],[1,1.52,30.29],[2,1.51,8.4]],"ltp":0.0,"tv":0.0,"id":8284479}]}]}
{"op":"mcm","clk":"1004216483","pt":1580623449087,"mc":[{"id":"1.168236368","rc":[{"batb":[[1,1.72,57.55]],"ltp":0.0,"tv":0.0,"id":4520808},{"batb":[[0,1.92,52.25],[1,1.91,129.81],[2,1.52,30.29]],"ltp":0.0,"tv":0.0,"id":8284479}]}]}
{"op":"mcm","clk":"1004232781","pt":1580624003971,"mc":[{"id":"1.168236368","rc":[{"trd":[[1.82,4.84]],"batb":[[0,1.72,57.55],[1,1.71,172.97],[2,1.51,30.29]],"batl":[[0,95,16],[1,990,3.71],[2,1000,0.02]],"ltp":1.82,"tv":4.83,"id":4520808}],"tv":4.83}]}
{"op":"mcm","clk":"1004232841","pt":1580624006082,"mc":[{"id":"1.168236368","rc":[{"batb":[[1,1.71,6.59]],"ltp":1.82,"tv":4.83,"id":4520808},{"batb":[[0,1.93,129.36],[1,1.92,52.25]],"ltp":0.0,"tv":0.0,"id":8284479}]}]}
{"op":"mcm","clk":"1004232858","pt":1580624006449,"mc":[{"id":"1.168236368","rc":[{"batb":[[0,1.75,157.5],[1,1.72,57.55],[2,1.71,6.59]],"ltp":1.82,"tv":4.83,"id":4520808},{"batb":[[2,1.86,137.36]],"ltp":0.0,"tv":0.0,"id":8284479}]}]}
{"op":"mcm","clk":"1004232909","pt":1580624007938,"mc":[{"id":"1.168236368","rc":[{"batb":[[0,1.77,57.55],[1,1.75,157.5]],"ltp":1.82,"tv":4.83,"id":4520808},{"batb":[[1,1.86,137.36],[2,1.52,30.29]],"ltp":0.0,"tv":0.0,"id":8284479}]}]}
{"op":"mcm","clk":"1004232961","pt":1580624009543,"mc":[{"id":"1.168236368","rc":[{"batb":[[0,1.75,215.05],[1,1.71,6.59],[2,1.51,30.29]],"ltp":1.82,"tv":4.83,"id":4520808},{"batb":[[1,1.87,48.46],[2,1.86,137.36]],"ltp":0.0,"tv":0.0,"id":8284479}]}]}
{"op":"mcm","clk":"1004233535","pt":1580624026895,"mc":[{"id":"1.168236368","rc":[{"batb":[[0,1.78,150.66],[1,1.75,215.05],[2,1.71,6.59]],"batl":[[0,11.5,3.46],[1,95,15.9],[2,990,3.71]],"ltp":1.82,"tv":4.83,"id":4520808}]}]}
{"op":"mcm","clk":"1004234640","pt":1580624066971,"mc":[{"id":"1.168236368","rc":[{"batb":[[0,1.78,143.16]],"ltp":1.82,"tv":4.83,"id":4520808},{"batb":[[0,1.87,48.46],[1,1.86,137.36],[2,1.52,30.29]],"ltp":0.0,"tv":0.0,"id":8284479}]}]}
{"op":"mcm","clk":"1004234716","pt":1580624068983,"mc":[{"id":"1.168236368","rc":[{"trd":[[1.82,5.04]],"batb":[[0,1.82,143.96],[1,1.78,143.16],[2,1.75,57.55]],"batl":[[0,11.5,3.36]],"ltp":1.82,"tv":5.03,"id":4520808},{"batb":[[1,1.79,149.53]],"ltp":0.0,"tv":0.0,"id":8284479}],"tv":5.03}]}
{"op":"mcm","clk":"1004234817","pt":1580624071767,"mc":[{"id":"1.168236368","rc":[{"batb":[[1,1.79,57.55],[2,1.78,143.16]],"ltp":1.82,"tv":5.03,"id":4520808},{"batb":[[0,1.79,149.53],[1,1.52,30.29],[2,1.51,8.4]],"ltp":0.0,"tv":0.0,"id":8284479}]}]}
{"op":"mcm","clk":"1004235218","pt":1580624084184,"mc":[{"id":"1.168236368","rc":[{"batb":[[1,1.78,143.16],[2,1.77,57.55]],"ltp":1.82,"tv":5.03,"id":4520808},{"batb":[[0,1.8,50.73],[1,1.79,149.53],[2,1.52,30.29]],"ltp":0.0,"tv":0.0,"id":8284479}]}]}
{"op":"mcm","clk":"1004242420","pt":1580624314344,"mc":[{"id":"1.168236368","rc":[{"batb":[[1,1.78,200.71],[2,1.71,6.59]],"ltp":1.82,"tv":5.03,"id":4520808}]}]}
{"op":"mcm","clk":"1004243806","pt":1580624356916,"mc":[{"id":"1.168236368","rc":[{"batb":[[1,1.78,143.16],[2,1.77,57.55]],"ltp":1.82,"tv":5.03,"id":4520808}]}]}
{"op":"mcm","clk":"1004245163","pt":1580624399450,"mc":[{"id":"1.168236368","rc":[{"batb":[[1,1.78,200.71],[2,1.71,6.59]],"ltp":1.82,"tv":5.03,"id":4520808}]}]}
{"op":"mcm","clk":"1004256802","pt":1580624758073,"mc":[{"id":"1.168236368","rc":[{"batb":[[0,1.84,139.22],[1,1.82,143.96],[2,1.8,57.55]],"ltp":1.82,"tv":5.03,"id":4520808}]}]}
{"op":"mcm","clk":"1004260380","pt":1580624873559,"mc":[{"id":"1.168236368","rc":[{"batb":[[0,1.88,136.21],[1,1.85,6.59],[2,1.82,143.96]],"ltp":1.82,"tv":5.03,"id":4520808}]}]}
{"op":"mcm","clk":"1004281152","pt":1580625566440,"mc":[{"id":"1.168236368","rc":[{"batb":[[2,1.83,57.55]],"ltp":1.82,"tv":5.03,"id":4520808}]}]}
{"op":"mcm","clk":"1004288388","pt":1580625768840,"mc":[{"id":"1.168236368","rc":[{"batb":[[2,1.82,143.96]],"ltp":1.82,"tv":5.03,"id":4520808}]}]}
{"op":"mcm","clk":"1004290316","pt":1580625864990,"mc":[{"id":"1.168236368","rc":[{"batb":[[2,1.8,57.55]],"ltp":1.82,"tv":5.03,"id":4520808},{"batb":[[1,1.52,30.29],[2,1.51,8.4]],"ltp":0.0,"tv":0.0,"id":8284479}]}]}
{"op":"mcm","clk":"1004290328","pt":1580625865562,"mc":[{"id":"1.168236368","rc":[{"batb":[[2,1.84,140.63]],"ltp":1.82,"tv":5.03,"id":4520808},{"batb":[[0,1.82,146.14],[1,1.8,50.73],[2,1.76,155.43]],"ltp":0.0,"tv":0.0,"id":8284479}]}]}
{"op":"mcm","clk":"1004290374","pt":1580625867673,"mc":[{"id":"1.168236368","rc":[{"batb":[[1,1.76,155.43],[2,1.52,30.29]],"ltp":0.0,"tv":0.0,"id":8284479}]}]}
{"op":"mcm","clk":"1004320985","pt":1580626857337,"mc":[{"id":"1.168236368","rc":[{"batb":[[1,1.77,51.49],[2,1.76,155.43]],"ltp":0.0,"tv":0.0,"id":8284479}]}]}
{"op":"mcm","clk":"1004323957","pt":1580626970508,"mc":[{"id":"1.168236368","rc":[{"batb":[[0,1.88,203.21]],"ltp":1.82,"tv":5.03,"id":4520808},{"batb":[[0,1.82,221.14]],"ltp":0.0,"tv":0.0,"id":8284479}]}]}
{"op":"mcm","clk":"1004323995","pt":1580626971941,"mc":[{"id":"1.168236368","rc":[{"batb":[[2,1.81,57.55]],"ltp":1.82,"tv":5.03,"id":4520808},{"batb":[[2,1.52,30.29]],"ltp":0.0,"tv":0.0,"id":8284479}]}]}
{"op":"mcm","clk":"1004324007","pt":1580626972504,"mc":[{"id":"1.168236368","rc":[{"batb":[[2,1.84,214.55]],"ltp":1.82,"tv":5.03,"id":4520808},{"batb":[[2,1.76,237.13]],"ltp":0.0,"tv":0.0,"id":8284479}]}]}
{"op":"mcm","clk":"1004341180","pt":1580627475065,"mc":[{"id":"1.168236368","rc":[{"batb":[[0,1.89,6.59],[1,1.88,203.21]],"ltp":1.82,"tv":5.03,"id":4520808}]}]}
{"op":"mcm","clk":"1004341209","pt":1580627475862,"mc":[{"id":"1.168236368","rc":[{"batb":[[0,1.91,200.84],[1,1.89,6.59]],"ltp":1.82,"tv":5.03,"id":4520808},{"batb":[[0,1.83,226.99]],"ltp":0.0,"tv":0.0,"id":8284479}]}]}
{"op":"mcm","clk":"1004346657","pt":1580627627522,"mc":[{"id":"1.168236368","rc":[{"batb":[[0,1.9,201.76]],"ltp":1.82,"tv":5.03,"id":4520808}]}]}
{"op":"mcm","clk":"1004373053","pt":1580628247105,"mc":[{"id":"1.168236368","rc":[{"batb":[[0,1.96,57.7]],"ltp":1.82,"tv":5.03,"id":4520808},{"batb":[[0,1.87,59.58],[1,1.83,6.19],[2,1.77,51.49]],"ltp":0.0,"tv":0.0,"id":8284479}]}]}
{"op":"mcm","clk":"1004412319","pt":1580629248816,"mc":[{"id":"1.168236368","rc":[{"batb":[[2,1.78,57.55]],"ltp":1.82,"tv":5.03,"id":4520808}]}]}
{"op":"mcm","clk":"1004412330","pt":1580629249427,"mc":[{"id":"1.168236368","rc":[{"batb":[[2,1.83,217.14]],"ltp":1.82,"tv":5.03,"id":4520808},{"batb":[[2,1.78,231.05]],"ltp":0.0,"tv":0.0,"id":8284479}]}]}
{"op":"mcm","clk":"1004415043","pt":1580629312814,"mc":[{"id":"1.168236368","rc":[{"batb":[[2,1.79,51.49]],"ltp":0.0,"tv":0.0,"id":8284479}]}]}
{"op":"mcm","clk":"1004448534","pt":1580630091777,"mc":[{"id":"1.168236368","rc":[{"batb":[[1,1.84,6.59]],"ltp":1.82,"tv":5.03,"id":4520808}]}]}
{"op":"mcm","clk":"1004448566","pt":1580630092395,"mc":[{"id":"1.168236368","rc":[{"batb":[[1,1.79,57.69],[2,1.78,231.05]],"ltp":0.0,"tv":0.0,"id":8284479}]}]}
{"op":"mcm","clk":"1004467123","pt":1580630471563,"mc":[{"id":"1.168236368","rc":[{"batb":[[1,1.84,64.14]],"ltp":1.82,"tv":5.03,"id":4520808}]}]}
{"op":"mcm","clk":"1004472114","pt":1580630577016,"mc":[{"id":"1.168236368","rc":[{"batb":[[1,1.84,6.59]],"ltp":1.82,"tv":5.03,"id":4520808}]}]}
{"op":"mcm","clk":"1004524675","pt":1580631784217,"mc":[{"id":"1.168236368","rc":[{"batb":[[2,1.82,219.78]],"ltp":1.82,"tv":5.03,"id":4520808},{"batb":[[1,1.79,285.82],[2,1.71,37.86]],"ltp":0.0,"tv":0.0,"id":8284479}]}]}
{"op":"mcm","clk":"1004553820","pt":1580632434609,"mc":[{"id":"1.168236368","rc":[{"batb":[[0,1.87,269.62]],"ltp":0.0,"tv":0.0,"id":8284479}]}]}
{"op":"mcm","clk":"1004553866","pt":1580632436002,"mc":[{"id":"1.168236368","rc":[{"batb":[[2,1.78,57.55]],"ltp":1.82,"tv":5.03,"id":4520808},{"batb":[[1,1.79,57.69]],"ltp":0.0,"tv":0.0,"id":8284479}]}]}
{"op":"mcm","clk":"1004553903","pt":1580632436623,"mc":[{"id":"1.168236368","rc":[{"batb":[[2,1.83,217.14]],"ltp":1.82,"tv":5.03,"id":4520808},{"batb":[[1,1.8,225.28],[2,1.79,57.69]],"ltp":0.0,"tv":0.0,"id":8284479}]}]}
{"op":"mcm","clk":"1004567117","pt":1580632760231,"mc":[{"id":"1.168236368","rc":[{"batb":[[1,1.83,217.14],[2,1.78,57.55]],"ltp":1.82,"tv":5.03,"id":4520808},{"batb":[[0,1.88,6.19],[1,1.87,59.58],[2,1.8,225.28]],"ltp":0.0,"tv":0.0,"id":8284479}]}]}
{"op":"mcm","clk":"1004568940","pt":1580632806534,"mc":[{"id":"1.168236368","rc":[{"batb":[[0,1.89,44.07],[1,1.88,6.19]],"ltp":0.0,"tv":0.0,"id":8284479}]}]}
{"op":"mcm","clk":"1004602219","pt":1580633506036,"mc":[{"id":"1.168236368","rc":[{"trd":[[1.96,115]],"batb":[[0,1.88,207.96],[1,1.87,66.45],[2,1.83,217.14]],"ltp":1.96,"tv":120.04,"id":4520808},{"batb":[[0,1.95,58.03]],"ltp":0.0,"tv":0.0,"id":8284479}],"tv":120.04}]}
{"op":"mcm","clk":"1004602288","pt":1580633507878,"mc":[{"id":"1.168236368","rc":[{"batb":[[2,1.78,57.55]],"ltp":1.96,"tv":120.04,"id":4520808},{"batb":[[2,1.79,51.49]],"ltp":0.0,"tv":0.0,"id":8284479}]}]}
{"op":"mcm","clk":"1004602314","pt":1580633508448,"mc":[{"id":"1.168236368","rc":[{"batb":[[2,1.81,222.5]],"ltp":1.96,"tv":120.04,"id":4520808},{"batb":[[2,1.82,219.78]],"ltp":0.0,"tv":0.0,"id":8284479}]}]}
{"op":"mcm","clk":"1004604945","pt":1580633572218,"mc":[{"id":"1.168236368","rc":[{"batb":[[0,1.89,50.9],[1,1.81,222.5],[2,1.71,37.86]],"ltp":1.96,"tv":120.04,"id":4520808}]}]}
{"op":"mcm","clk":"1004605232","pt":1580633580122,"mc":[{"id":"1.168236368","rc":[{"trd":[[1.96,142.84]],"batl":[[0,1.96,17.75],[1,11.5,3.36],[2,95,15.9]],"ltp":1.96,"tv":147.88,"id":4520808}],"tv":147.88}]}
{"op":"mcm","clk":"1004606292","pt":1580633607079,"mc":[{"id":"1.168236368","rc":[{"batl":[[1,95,15.9],[2,990,3.71]],"ltp":1.96,"tv":147.88,"id":4520808}]}]}
{"op":"mcm","clk":"1004610764","pt":1580633704709,"mc":[{"id":"1.168236368","rc":[{"batb":[[0,1.87,275.72]],"ltp":1.96,"tv":147.88,"id":4520808}]}]}
{"op":"mcm","clk":"1004617999","pt":1580633849045,"mc":[{"id":"1.168236368","rc":[{"trd":[[1.87,16.8]],"batb":[[0,1.87,267.32]],"ltp":1.87,"tv":164.68,"id":4520808},{"batb":[[0,1.88,6.19],[1,1.82,219.78],[2,1.79,51.49]],"ltp":0.0,"tv":0.0,"id":8284479}],"tv":164.68}]}
{"op":"mcm","clk":"1004618008","pt":1580633849253,"mc":[{"id":"1.168236368","rc":[{"batb":[[0,1.96,58.98],[1,1.88,6.19],[2,1.82,219.78]],"ltp":0.0,"tv":0.0,"id":8284479}]}]}
{"op":"mcm","clk":"1004630937","pt":1580634070960,"mc":[{"id":"1.168236368","rc":[{"batb":[[2,1.83,51.49]],"ltp":0.0,"tv":0.0,"id":8284479}]}]}
{"op":"mcm","clk":"1004632598","pt":1580634098792,"mc":[{"id":"1.168236368","rc":[{"batb":[[1,1.81,272.47]],"ltp":1.87,"tv":164.68,"id":4520808}]}]}
{"op":"mcm","clk":"1004643199","pt":1580634328563,"mc":[{"id":"1.168236368","rc":[{"batl":[[2,990,2.2]],"ltp":1.87,"tv":164.68,"id":4520808}]}]}
{"op":"mcm","clk":"1004651468","pt":1580634495595,"mc":[{"id":"1.168236368","rc":[{"batl":[[2,990,2.2]],"ltp":0.0,"tv":0.0,"id":8284479}]}]}
{"op":"mcm","clk":"1004653559","pt":1580634545053,"mc":[{"id":"1.168236368","rc":[{"batb":[[0,1.9,2.53],[1,1.87,267.32],[2,1.81,272.47]],"ltp":1.87,"tv":164.68,"id":4520808}]}]}
{"op":"mcm","clk":"1004672028","pt":1580634920823,"mc":[{"id":"1.168236368","rc":[{"batb":[[1,1.87,58.05]],"ltp":1.87,"tv":164.68,"id":4520808}]}]}
{"op":"mcm","clk":"1004677284","pt":1580635021023,"mc":[{"id":"1.168236368","rc":[{"batb":[[1,1.86,66.22]],"ltp":1.87,"tv":164.68,"id":4520808}]}]}
{"op":"mcm","clk":"1004682909","pt":1580635127225,"mc":[{"id":"1.168236368","rc":[{"batl":[[1,2.28,18.48],[2,95,15.9]],"ltp":1.87,"tv":164.68,"id":4520808}]}]}
{"op":"mcm","clk":"1004683704","pt":1580635142252,"mc":[{"id":"1.168236368","rc":[{"batl":[[0,2.28,18.48],[1,13,3.36],[2,95,15.9]],"ltp":0.0,"tv":0.0,"id":8284479}]}]}
{"op":"mcm","clk":"1004684294","pt":1580635153752,"mc":[{"id":"1.168236368","rc":[{"batl":[[1,95,15.9],[2,990,2.2]],"ltp":0.0,"tv":0.0,"id":8284479}]}]}
{"op":"mcm","clk":"1004696803","pt":1580635446826,"mc":[{"id":"1.168236368","rc":[{"batb":[[1,1.83,51.49],[2,1.82,219.78]],"ltp":0.0,"tv":0.0,"id":8284479}]}]}
{"op":"mcm","clk":"1004732146","pt":1580636281793,"mc":[{"id":"1.168236368","rc":[{"trd":[[1.96,178.33]],"batl":[[0,2.28,18.48],[1,95,15.9],[2,990,2.2]],"ltp":1.96,"tv":200.17,"id":4520808}],"tv":200.17}]}
{"op":"mcm","clk":"1004732213","pt":1580636282837,"mc":[{"id":"1.168236368","rc":[{"batb":[[0,1.96,10.72],[1,1.9,2.53],[2,1.86,66.22]],"ltp":1.96,"tv":200.17,"id":4520808},{"batb":[[2,1.81,37.86]],"ltp":0.0,"tv":0.0,"id":8284479}]}]}
{"op":"mcm","clk":"1004732238","pt":1580636283451,"mc":[{"id":"1.168236368","rc":[{"batb":[[2,1.88,204.79]],"ltp":1.96,"tv":200.17,"id":4520808},{"batb":[[1,1.81,37.86],[2,1.75,240.29]],"ltp":0.0,"tv":0.0,"id":8284479}]}]}
{"op":"mcm","clk":"1004732473","pt":1580636288160,"mc":[{"id":"1.168236368","rc":[{"batb":[[2,1.86,66.22]],"ltp":1.96,"tv":200.17,"id":4520808},{"batb":[[2,1.71,37.86]],"ltp":0.0,"tv":0.0,"id":8284479}]}]}
{"op":"mcm","clk":"1004732500","pt":1580636288734,"mc":[{"id":"1.168236368","rc":[{"batb":[[2,1.87,207.15]],"ltp":1.96,"tv":200.17,"id":4520808},{"batb":[[2,1.76,237.13]],"ltp":0.0,"tv":0.0,"id":8284479}]}]}
{"op":"mcm","clk":"1004735348","pt":1580636351771,"mc":[{"id":"1.168236368","rc":[{"trd":[[1.96,192.65]],"batb":[[0,1.96,3.56],[2,1.88,57.73]],"ltp":1.96,"tv":214.49,"id":4520808},{"batb":[[0,1.95,58.87]],"ltp":0.0,"tv":0.0,"id":8284479}],"tv":214.49}]}
{"op":"mcm","clk":"1004741596","pt":1580636479169,"mc":[{"id":"1.168236368","rc":[{"batb":[[2,1.88,64.52]],"ltp":1.96,"tv":214.49,"id":4520808},{"batb":[[0,1.94,59.33]],"ltp":0.0,"tv":0.0,"id":8284479}]}]}
{"op":"mcm","clk":"1004748869","pt":1580636605091,"mc":[{"id":"1.168236368","rc":[{"batl":[[0,2,7.57],[1,2.28,18.48],[2,95,15.9]],"ltp":0.0,"tv":0.0,"id":8284479}]}]}
{"op":"mcm","clk":"1004749024","pt":1580636608182,"mc":[{"id":"1.168236368","rc":[{"batb":[[2,1.89,64.64]],"ltp":1.96,"tv":214.49,"id":4520808},{"trd":[[2,15.14]],"batb":[[0,1.99,7.61],[1,1.93,58.8],[2,1.81,37.86]],"batl":[[0,2.28,18.48],[1,95,15.9],[2,990,2.2]],"ltp":2.0,"tv":15.14,"id":8284479}],"tv":229.63}]}
{"op":"mcm","clk":"1004749215","pt":1580636611991,"mc":[{"id":"1.168236368","rc":[{"batb":[[0,1.93,58.8],[1,1.81,37.86],[2,1.76,237.13]],"ltp":2.0,"tv":15.14,"id":8284479}]}]}
{"op":"mcm","clk":"1004749343","pt":1580636614616,"mc":[{"id":"1.168236368","rc":[{"batl":[[0,2.04,7.57],[1,2.28,18.48],[2,95,15.9]],"ltp":2.0,"tv":15.14,"id":8284479}]}]}
{"op":"mcm","clk":"1004749597","pt":1580636619825,"mc":[{"id":"1.168236368","rc":[{"batl":[[0,2.28,18.48],[1,95,15.9],[2,990,2.2]],"ltp":2.0,"tv":15.14,"id":8284479}]}]}
{"op":"mcm","clk":"1004749646","pt":1580636620611,"mc":[{"id":"1.168236368","rc":[{"batl":[[0,2,7.57],[1,2.28,18.48],[2,95,15.9]],"ltp":2.0,"tv":15.14,"id":8284479}]}]}
{"op":"mcm","clk":"1004749681","pt":1580636621327,"mc":[{"id":"1.168236368","rc":[{"batb":[[0,1.95,7.77],[1,1.93,58.8],[2,1.81,37.86]],"ltp":2.0,"tv":15.14,"id":8284479}]}]}
{"op":"mcm","clk":"1004749741","pt":1580636623225,"mc":[{"id":"1.168236368","rc":[{"batl":[[0,2.28,18.48],[1,95,15.9],[2,990,2.2]],"ltp":2.0,"tv":15.14,"id":8284479}]}]}
{"op":"mcm","clk":"1004749744","pt":1580636623328,"mc":[{"id":"1.168236368","rc":[{"batl":[[0,2.02,7.57],[1,2.28,18.48],[2,95,15.9]],"ltp":2.0,"tv":15.14,"id":8284479}]}]}
{"op":"mcm","clk":"1004754924","pt":1580636741225,"mc":[{"id":"1.168236368","rc":[{"batb":[[0,1.96,37.84],[1,1.95,7.77]],"ltp":2.0,"tv":15.14,"id":8284479}]}]}
{"op":"mcm","clk":"1004756434","pt":1580636777107,"mc":[{"id":"1.168236368","rc":[{"batl":[[1,2.6,74.21],[2,95,15.9]],"ltp":1.96,"tv":214.49,"id":4520808}]}]}
{"op":"mcm","clk":"1004762321","pt":1580636900943,"mc":[{"id":"1.168236368","rc":[{"batb":[[1,1.81,37.86],[2,1.76,237.13]],"batl":[[0,2.28,18.48],[1,95,15.9],[2,990,2.2]],"ltp":2.0,"tv":15.14,"id":8284479}]}]}
{"op":"mcm","clk":"1004762408","pt":1580636902231,"mc":[{"id":"1.168236368","rc":[{"batb":[[0,1.98,7.65],[1,1.96,37.84],[2,1.81,37.86]],"batl":[[0,2.02,7.57],[1,2.28,18.48],[2,95,15.9]],"ltp":2.0,"tv":15.14,"id":8284479}]}]}
{"op":"mcm","clk":"1004767805","pt":1580636999364,"mc":[{"id":"1.168236368","rc":[{"batb":[[1,1.93,58.8]],"ltp":2.0,"tv":15.14,"id":8284479}]}]}
{"op":"mcm","clk":"1004772566","pt":1580637085356,"mc":[{"id":"1.168236368","rc":[{"batb":[[0,1.93,58.8],[1,1.81,37.86],[2,1.76,237.13]],"batl":[[0,2.28,18.48],[1,95,15.9],[2,990,2.2]],"ltp":2.0,"tv":15.14,"id":8284479}]}]}
{"op":"mcm","clk":"1004772630","pt":1580637086544,"mc":[{"id":"1.168236368","rc":[{"batb":[[0,1.95,7.77],[1,1.93,58.8],[2,1.81,37.86]],"ltp":2.0,"tv":15.14,"id":8284479}]}]}
{"op":"mcm","clk":"1004774650","pt":1580637127932,"mc":[{"id":"1.168236368","rc":[{"batb":[[0,1.96,37.84],[1,1.95,7.77]],"ltp":2.0,"tv":15.14,"id":8284479}]}]}
{"op":"mcm","clk":"1004779155","pt":1580637208757,"mc":[{"id":"1.168236368","rc":[{"batb":[[1,1.81,37.86],[2,1.76,237.13]],"ltp":2.0,"tv":15.14,"id":8284479}]}]}
{"op":"mcm","clk":"1004779216","pt":1580637209841,"mc":[{"id":"1.168236368","rc":[{"batb":[[0,1.99,7.61],[1,1.96,37.84],[2,1.81,37.86]],"ltp":2.0,"tv":15.14,"id":8284479}]}]}
{"op":"mcm","clk":"1004781479","pt":1580637256306,"mc":[{"id":"1.168236368","rc":[{"batb":[[1,1.93,58.8]],"ltp":2.0,"tv":15.14,"id":8284479}]}]}
{"op":"mcm","clk":"1004784883","pt":1580637325757,"mc":[{"id":"1.168236368","rc":[{"batb":[[0,1.93,58.8],[1,1.81,37.86],[2,1.76,237.13]],"ltp":2.0,"tv":15.14,"id":8284479}]}]}
{"op":"mcm","clk":"1004784939","pt":1580637326855,"mc":[{"id":"1.168236368","rc":[{"batb":[[0,1.96,7.72],[1,1.93,58.8],[2,1.81,37.86]],"ltp":2.0,"tv":15.14,"id":8284479}]}]}
{"op":"mcm","clk":"1004788198","pt":1580637389183,"mc":[{"id":"1.168236368","rc":[{"batb":[[1,1.81,37.86],[2,1.76,237.13]],"ltp":2.0,"tv":15.14,"id":8284479}]}]}
{"op":"mcm","clk":"1004788203","pt":1580637389286,"mc":[{"id":"1.168236368","rc":[{"batb":[[0,1.97,31.11],[1,1.96,7.72],[2,1.81,37.86]],"ltp":2.0,"tv":15.14,"id":8284479}]}]}
{"op":"mcm","clk":"1004813081","pt":1580637759782,"mc":[{"id":"1.168236368","rc":[{"batb":[[1,1.81,37.86],[2,1.76,237.13]],"ltp":2.0,"tv":15.14,"id":8284479}]}]}
{"op":"mcm","clk":"1004813183","pt":1580637760979,"mc":[{"id":"1.168236368","rc":[{"batb":[[0,1.99,7.61],[1,1.97,31.11],[2,1.81,37.86]],"ltp":2.0,"tv":15.14,"id":8284479}]}]}
{"op":"mcm","clk":"1004813375","pt":1580637763183,"mc":[{"id":"1.168236368","rc":[{"batl":[[0,2.04,7.57],[1,2.28,18.48],[2,95,15.9]],"ltp":2.0,"tv":15.14,"id":8284479}]}]}
{"op":"mcm","clk":"1004814343","pt":1580637777002,"mc":[{"id":"1.168236368","rc":[{"batb":[[1,1.93,58.8]],"ltp":2.0,"tv":15.14,"id":8284479}]}]}
{"op":"mcm","clk":"1004819336","pt":1580637850465,"mc":[{"id":"1.168236368","rc":[{"batb":[[0,1.93,58.8],[1,1.81,37.86],[2,1.77,51.49]],"batl":[[0,2.28,18.48],[1,95,15.9],[2,990,2.2]],"ltp":2.0,"tv":15.14,"id":8284479}]}]}
{"op":"mcm","clk":"1004819417","pt":1580637851763,"mc":[{"id":"1.168236368","rc":[{"batb":[[0,1.95,7.77],[1,1.93,58.8],[2,1.81,37.86]],"ltp":2.0,"tv":15.14,"id":8284479}]}]}
{"op":"mcm","clk":"1004822785","pt":1580637906749,"mc":[{"id":"1.168236368","rc":[{"batb":[[0,1.96,37.84],[1,1.95,7.77]],"ltp":2.0,"tv":15.14,"id":8284479}]}]}
{"op":"mcm","clk":"1004826054","pt":1580637958869,"mc":[{"id":"1.168236368","rc":[{"batb":[[1,1.81,37.86],[2,1.78,303.86]],"ltp":2.0,"tv":15.14,"id":8284479}]}]}
{"op":"mcm","clk":"1004826120","pt":1580637959967,"mc":[{"id":"1.168236368","rc":[{"batb":[[0,1.98,7.65],[1,1.96,37.84],[2,1.81,37.86]],"ltp":2.0,"tv":15.14,"id":8284479}]}]}
{"op":"mcm","clk":"1004831429","pt":1580638042060,"mc":[{"id":"1.168236368","rc":[{"batb":[[1,1.93,58.8]],"ltp":2.0,"tv":15.14,"id":8284479}]}]}
{"op":"mcm","clk":"1004835238","pt":1580638100090,"mc":[{"id":"1.168236368","rc":[{"batb":[[2,1.81,89.35]],"ltp":2.0,"tv":15.14,"id":8284479}]}]}
{"op":"mcm","clk":"1004835565","pt":1580638105088,"mc":[{"id":"1.168236368","rc":[{"batb":[[2,1.81,37.86]],"ltp":2.0,"tv":15.14,"id":8284479}]}]}
{"op":"mcm","clk":"1004852535","pt":1580638338086,"mc":[{"id":"1.168236368","rc":[{"batb":[[0,1.93,58.8],[1,1.81,37.86],[2,1.79,351.51]],"ltp":2.0,"tv":15.14,"id":8284479}]}]}
{"op":"mcm","clk":"1004852621","pt":1580638339234,"mc":[{"id":"1.168236368","rc":[{"batb":[[0,1.95,7.77],[1,1.93,58.8],[2,1.81,37.86]],"ltp":2.0,"tv":15.14,"id":8284479}]}]}
{"op":"mcm","clk":"1004859596","pt":1580638431514,"mc":[{"id":"1.168236368","rc":[{"batb":[[0,1.96,37.84],[1,1.95,7.77]],"ltp":2.0,"tv":15.14,"id":8284479}]}]}
{"op":"mcm","clk":"1004875615","pt":1580638629218,"mc":[{"id":"1.168236368","rc":[{"trd":[[1.96,33.61]],"batb":[[0,1.96,21.04]],"ltp":1.96,"tv":48.75,"id":8284479}],"tv":263.24}]}
{"op":"mcm","clk":"1004875648","pt":1580638629736,"mc":[{"id":"1.168236368","rc":[{"batb":[[1,1.92,59.12],[2,1.9,2.53]],"ltp":1.96,"tv":214.49,"id":4520808},{"batb":[[0,1.95,7.77],[1,1.9,64.05]],"ltp":1.96,"tv":48.75,"id":8284479}]}]}
{"op":"mcm","clk":"1004952692","pt":1580639441021,"mc":[{"id":"1.168236368","rc":[{"batb":[[1,1.94,61.03]],"ltp":1.96,"tv":214.49,"id":4520808},{"trd":[[1.95,15.54]],"batb":[[0,1.88,62.75],[1,1.81,37.86],[2,1.79,351.51]],"ltp":1.95,"tv":64.29,"id":8284479}],"tv":278.78}]}
{"op":"mcm","clk":"1004953806","pt":1580639452025,"mc":[{"id":"1.168236368","rc":[{"batb":[[0,1.95,7.77],[1,1.88,62.75],[2,1.81,37.86]],"ltp":1.95,"tv":64.29,"id":8284479}]}]}
{"op":"mcm","clk":"1004954043","pt":1580639454424,"mc":[{"id":"1.168236368","rc":[{"batb":[[0,1.88,62.75],[1,1.81,37.86],[2,1.79,351.51]],"ltp":1.95,"tv":64.29,"id":8284479}]}]}
{"op":"mcm","clk":"1004954224","pt":1580639456156,"mc":[{"id":"1.168236368","rc":[{"batl":[[0,2,7.57],[1,2.28,18.48],[2,95,15.9]],"ltp":1.95,"tv":64.29,"id":8284479}]}]}
{"op":"mcm","clk":"1004961849","pt":1580639530181,"mc":[{"id":"1.168236368","rc":[{"batl":[[0,2,15.14]],"ltp":1.95,"tv":64.29,"id":8284479}]}]}
{"op":"mcm","clk":"1004961959","pt":1580639530592,"mc":[{"id":"1.168236368","rc":[{"trd":[[2,34.86]],"batl":[[0,2,5.29]],"ltp":2.0,"tv":84.01,"id":8284479}],"tv":298.5}]}
{"op":"mcm","clk":"1004962198","pt":1580639532760,"mc":[{"id":"1.168236368","rc":[{"trd":[[1.99,4.6]],"ltp":1.99,"tv":88.61,"id":8284479}],"tv":303.1}]}
{"op":"mcm","clk":"1004962395","pt":1580639534700,"mc":[{"id":"1.168236368","rc":[{"batl":[[0,2,12.86]],"ltp":1.99,"tv":88.61,"id":8284479}]}]}
{"op":"mcm","clk":"1004962618","pt":1580639537211,"mc":[{"id":"1.168236368","rc":[{"batl":[[0,2.28,18.48],[1,95,15.9],[2,990,2.2]],"ltp":1.99,"tv":88.61,"id":8284479}]}]}
{"op":"mcm","clk":"1004962716","pt":1580639537997,"mc":[{"id":"1.168236368","rc":[{"batl":[[0,2,7.57],[1,2.28,18.48],[2,95,15.9]],"ltp":1.99,"tv":88.61,"id":8284479}]}]}
{"op":"mcm","clk":"1004962767","pt":1580639538573,"mc":[{"id":"1.168236368","rc":[{"trd":[[1.95,31.06]],"ltp":1.95,"tv":104.13,"id":8284479}],"tv":318.62}]}
{"op":"mcm","clk":"1004962934","pt":1580639540387,"mc":[{"id":"1.168236368","rc":[{"batl":[[0,2,15.14]],"ltp":1.95,"tv":104.13,"id":8284479}]}]}
{"op":"mcm","clk":"1004963210","pt":1580639543171,"mc":[{"id":"1.168236368","rc":[{"batl":[[0,2,22.72]],"ltp":1.95,"tv":104.13,"id":8284479}]}]}
{"op":"mcm","clk":"1004963854","pt":1580639549985,"mc":[{"id":"1.168236368","rc":[{"batl":[[0,2,37.86]],"ltp":1.95,"tv":104.13,"id":8284479}]}]}
{"op":"mcm","clk":"1004964129","pt":1580639552790,"mc":[{"id":"1.168236368","rc":[{"batl":[[0,2,7.57]],"ltp":1.95,"tv":104.13,"id":8284479}]}]}
{"op":"mcm","clk":"1004964215","pt":1580639553578,"mc":[{"id":"1.168236368","rc":[{"batl":[[0,2,15.14]],"ltp":1.95,"tv":104.13,"id":8284479}]}]}
{"op":"mcm","clk":"1004964987","pt":1580639559578,"mc":[{"id":"1.168236368","rc":[{"trd":[[2,54.62]],"batl":[[0,2,5.26]],"ltp":2.0,"tv":123.89,"id":8284479}],"tv":338.39}]}
{"op":"mcm","clk":"1004965787","pt":1580639566080,"mc":[{"id":"1.168236368","rc":[{"batl":[[0,2,12.84]],"ltp":2.0,"tv":123.89,"id":8284479}]}]}
{"op":"mcm","clk":"1004966094","pt":1580639569231,"mc":[{"id":"1.168236368","rc":[{"batl":[[0,2.28,18.48],[1,95,15.9],[2,990,2.2]],"ltp":2.0,"tv":123.89,"id":8284479}]}]}
{"op":"mcm","clk":"1004966200","pt":1580639570223,"mc":[{"id":"1.168236368","rc":[{"batl":[[0,2,15.14],[1,2.28,18.48],[2,95,15.9]],"ltp":2.0,"tv":123.89,"id":8284479}]}]}
{"op":"mcm","clk":"1004966223","pt":1580639570489,"mc":[{"id":"1.168236368","rc":[{"trd":[[1.95,51.32]],"ltp":1.95,"tv":144.15,"id":8284479}],"tv":358.65}]}
{"op":"mcm","clk":"1004966427","pt":1580639572742,"mc":[{"id":"1.168236368","rc":[{"batl":[[0,2,30.29]],"ltp":1.95,"tv":144.15,"id":8284479}]}]}
{"op":"mcm","clk":"1004966917","pt":1580639577743,"mc":[{"id":"1.168236368","rc":[{"batl":[[0,2,37.86]],"ltp":1.95,"tv":144.15,"id":8284479}]}]}
{"op":"mcm","clk":"1004967246","pt":1580639581118,"mc":[{"id":"1.168236368","rc":[{"batl":[[0,2.28,18.48],[1,95,15.9],[2,990,2.2]],"ltp":1.95,"tv":144.15,"id":8284479}]}]}
{"op":"mcm","clk":"1004967296","pt":1580639581644,"mc":[{"id":"1.168236368","rc":[{"batl":[[0,2,7.57],[1,2.28,18.48],[2,95,15.9]],"ltp":1.95,"tv":144.15,"id":8284479}]}]}
{"op":"mcm","clk":"1004967369","pt":1580639582548,"mc":[{"id":"1.168236368","rc":[{"batl":[[0,2,15.14]],"ltp":1.95,"tv":144.15,"id":8284479}]}]}
{"op":"mcm","clk":"1004968176","pt":1580639591242,"mc":[{"id":"1.168236368","rc":[{"batl":[[0,2,22.72]],"ltp":1.95,"tv":144.15,"id":8284479}]}]}
{"op":"mcm","clk":"1004969629","pt":1580639605594,"mc":[{"id":"1.168236368","rc":[{"trd":[[2,90.63]],"batl":[[0,2,19.85]],"ltp":2.0,"tv":180.16,"id":8284479}],"tv":394.65}]}
{"op":"mcm","clk":"1004969908","pt":1580639608578,"mc":[{"id":"1.168236368","rc":[{"batl":[[0,2.28,18.48],[1,95,15.9],[2,990,2.2]],"ltp":2.0,"tv":180.16,"id":8284479}]}]}
{"op":"mcm","clk":"1004969993","pt":1580639609682,"mc":[{"id":"1.168236368","rc":[{"batb":[[0,1.94,18.57],[1,1.88,62.75],[2,1.81,37.86]],"batl":[[0,2,15.14],[1,2.28,18.48],[2,95,15.9]],"ltp":2.0,"tv":180.16,"id":8284479}]}]}
{"op":"mcm","clk":"1004970215","pt":1580639612213,"mc":[{"id":"1.168236368","rc":[{"trd":[[1.95,55.32]],"batb":[[0,1.95,16.57]],"ltp":1.95,"tv":184.16,"id":8284479}],"tv":398.65}]}
{"op":"mcm","clk":"1004970809","pt":1580639618898,"mc":[{"id":"1.168236368","rc":[{"batb":[[0,1.88,62.75],[1,1.81,37.86],[2,1.79,351.51]],"ltp":1.95,"tv":184.16,"id":8284479}]}]}
{"op":"mcm","clk":"1004970928","pt":1580639620307,"mc":[{"id":"1.168236368","rc":[{"batb":[[0,1.95,7.57],[1,1.88,62.75],[2,1.81,37.86]],"ltp":1.95,"tv":184.16,"id":8284479}]}]}
{"op":"mcm","clk":"1004971175","pt":1580639622927,"mc":[{"id":"1.168236368","rc":[{"batb":[[0,1.96,7.57],[1,1.95,7.57],[2,1.88,62.75]],"ltp":1.95,"tv":184.16,"id":8284479}]}]}
{"op":"mcm","clk":"1004971292","pt":1580639624396,"mc":[{"id":"1.168236368","rc":[{"batb":[[1,1.88,62.75],[2,1.81,37.86]],"ltp":1.95,"tv":184.16,"id":8284479}]}]}
{"op":"mcm","clk":"1004971463","pt":1580639626298,"mc":[{"id":"1.168236368","rc":[{"batb":[[0,1.88,62.75],[1,1.81,37.86],[2,1.79,351.51]],"batl":[[0,2.28,18.48],[1,95,15.9],[2,990,2.2]],"ltp":1.95,"tv":184.16,"id":8284479}]}]}
{"op":"mcm","clk":"1004971592","pt":1580639627704,"mc":[{"id":"1.168236368","rc":[{"batb":[[0,1.95,16.47],[1,1.88,62.75],[2,1.81,37.86]],"batl":[[0,2.04,7.57],[1,2.28,18.48],[2,95,15.9]],"ltp":1.95,"tv":184.16,"id":8284479}]}]}
{"op":"mcm","clk":"1004971741","pt":1580639629385,"mc":[{"id":"1.168236368","rc":[{"batl":[[0,2,7.57],[1,2.04,7.57],[2,2.28,18.48]],"ltp":1.95,"tv":184.16,"id":8284479}]}]}
{"op":"mcm","clk":"1004972636","pt":1580639641137,"mc":[{"id":"1.168236368","rc":[{"batl":[[0,2,15.14]],"ltp":1.95,"tv":184.16,"id":8284479}]}]}
{"op":"mcm","clk":"1004972682","pt":1580639641655,"mc":[{"id":"1.168236368","rc":[{"trd":[[2,110.51]],"batl":[[0,2,5.2]],"ltp":2.0,"tv":204.04,"id":8284479}],"tv":418.54}]}
{"op":"mcm","clk":"1004972855","pt":1580639643855,"mc":[{"id":"1.168236368","rc":[{"batb":[[0,1.98,7.57],[1,1.95,16.47],[2,1.88,62.75]],"ltp":2.0,"tv":204.04,"id":8284479}]}]}
{"op":"mcm","clk":"1004973430","pt":1580639650227,"mc":[{"id":"1.168236368","rc":[{"batb":[[0,1.88,62.75],[1,1.81,37.86],[2,1.79,351.51]],"batl":[[0,2.28,18.48],[1,95,15.9],[2,990,2.2]],"ltp":2.0,"tv":204.04,"id":8284479}]}]}
{"op":"mcm","clk":"1004973552","pt":1580639651430,"mc":[{"id":"1.168236368","rc":[{"batb":[[0,1.95,16.47],[1,1.88,62.75],[2,1.81,37.86]],"ltp":2.0,"tv":204.04,"id":8284479}]}]}
{"op":"mcm","clk":"1004973631","pt":1580639652371,"mc":[{"id":"1.168236368","rc":[{"batl":[[0,2.04,7.57],[1,2.28,18.48],[2,95,15.9]],"ltp":2.0,"tv":204.04,"id":8284479}]}]}
{"op":"mcm","clk":"1004974299","pt":1580639659949,"mc":[{"id":"1.168236368","rc":[{"batl":[[0,2,7.57],[1,2.04,7.57],[2,2.28,18.48]],"ltp":2.0,"tv":204.04,"id":8284479}]}]}
{"op":"mcm","clk":"1004976064","pt":1580639681170,"mc":[{"id":"1.168236368","rc":[{"batl":[[0,2.04,7.57],[1,2.28,18.48],[2,95,15.9]],"ltp":2.0,"tv":204.04,"id":8284479}]}]}
{"op":"mcm","clk":"1004976100","pt":1580639681698,"mc":[{"id":"1.168236368","rc":[{"trd":[[2.04,9.3]],"batl":[[0,2.04,2.92]],"ltp":2.04,"tv":213.34,"id":8284479}],"tv":427.84}]}
{"op":"mcm","clk":"1004976452","pt":1580639685605,"mc":[{"id":"1.168236368","rc":[{"batb":[[0,1.88,62.75],[1,1.81,37.86],[2,1.79,351.51]],"batl":[[0,2.28,18.48],[1,95,15.9],[2,990,2.2]],"ltp":2.04,"tv":213.34,"id":8284479}]}]}
{"op":"mcm","clk":"1004976579","pt":1580639686879,"mc":[{"id":"1.168236368","rc":[{"batb":[[0,1.95,31.53],[1,1.88,62.75],[2,1.81,37.86]],"batl":[[0,2.04,7.57],[1,2.28,18.48],[2,95,15.9]],"ltp":2.04,"tv":213.34,"id":8284479}]}]}
{"op":"mcm","clk":"1004976960","pt":1580639691106,"mc":[{"id":"1.168236368","rc":[{"batb":[[0,1.99,7.57],[1,1.95,31.53],[2,1.88,62.75]],"ltp":2.04,"tv":213.34,"id":8284479}]}]}
{"op":"mcm","clk":"1004977182","pt":1580639693323,"mc":[{"id":"1.168236368","rc":[{"batb":[[0,1.95,31.53],[1,1.88,62.75],[2,1.81,37.86]],"ltp":2.04,"tv":213.34,"id":8284479}]}]}
{"op":"mcm","clk":"1004979387","pt":1580639716757,"mc":[{"id":"1.168236368","rc":[{"batb":[[0,1.97,40.39],[1,1.96,3.56]],"ltp":1.96,"tv":214.49,"id":4520808},{"trd":[[2.04,18.62]],"batl":[[0,2.04,2.92]],"ltp":2.04,"tv":222.66,"id":8284479}],"tv":437.15}]}
{"op":"mcm","clk":"1004983637","pt":1580639759782,"mc":[{"id":"1.168236368","rc":[{"batb":[[0,1.88,62.75],[1,1.81,37.86],[2,1.79,351.51]],"ltp":2.04,"tv":222.66,"id":8284479}]}]}
{"op":"mcm","clk":"1004983738","pt":1580639760773,"mc":[{"id":"1.168236368","rc":[{"trd":[[1.97,46]],"batb":[[0,1.97,17.39]],"ltp":1.97,"tv":260.49,"id":4520808}],"tv":483.15}]}
{"op":"mcm","clk":"1004983821","pt":1580639761717,"mc":[{"id":"1.168236368","rc":[{"batb":[[0,1.95,7.57],[1,1.88,62.75],[2,1.81,37.86]],"ltp":2.04,"tv":222.66,"id":8284479}]}]}
{"op":"mcm","clk":"1004984006","pt":1580639763704,"mc":[{"id":"1.168236368","rc":[{"batb":[[0,1.96,3.56],[1,1.91,59.74]],"ltp":1.97,"tv":260.49,"id":4520808},{"batb":[[0,1.96,27.89],[1,1.95,7.57]],"ltp":2.04,"tv":222.66,"id":8284479}]}]}
{"op":"mcm","clk":"1004984266","pt":1580639766207,"mc":[{"id":"1.168236368","rc":[{"batb":[[1,1.81,37.86],[2,1.79,351.51]],"ltp":2.04,"tv":222.66,"id":8284479}]}]}
{"op":"mcm","clk":"1004984275","pt":1580639766308,"mc":[{"id":"1.168236368","rc":[{"batb":[[0,1.97,7.57],[1,1.96,27.89],[2,1.81,37.86]],"ltp":2.04,"tv":222.66,"id":8284479}]}]}
{"op":"mcm","clk":"1004984534","pt":1580639769224,"mc":[{"id":"1.168236368","rc":[{"batb":[[0,1.97,15.14]],"ltp":2.04,"tv":222.66,"id":8284479}]}]}
{"op":"mcm","clk":"1004984563","pt":1580639769592,"mc":[{"id":"1.168236368","rc":[{"batb":[[0,1.97,22.72]],"ltp":2.04,"tv":222.66,"id":8284479}]}]}
{"op":"mcm","clk":"1004986408","pt":1580639789435,"mc":[{"id":"1.168236368","rc":[{"batb":[[0,1.97,30.29]],"ltp":2.04,"tv":222.66,"id":8284479}]}]}
{"op":"mcm","clk":"1004991232","pt":1580639839209,"mc":[{"id":"1.168236368","rc":[{"batb":[[0,1.98,14.59],[1,1.97,30.29]],"ltp":2.04,"tv":222.66,"id":8284479}]}]}
{"op":"mcm","clk":"1004991514","pt":1580639842110,"mc":[{"id":"1.168236368","rc":[{"batb":[[0,1.99,7.57],[1,1.98,14.59],[2,1.97,30.29]],"ltp":2.04,"tv":222.66,"id":8284479}]}]}
{"op":"mcm","clk":"1004991631","pt":1580639843303,"mc":[{"id":"1.168236368","rc":[{"batb":[[2,1.81,37.86]],"ltp":2.04,"tv":222.66,"id":8284479}]}]}
{"op":"mcm","clk":"1004991939","pt":1580639847126,"mc":[{"id":"1.168236368","rc":[{"batb":[[2,1.95,22.72]],"ltp":2.04,"tv":222.66,"id":8284479}]}]}
{"op":"mcm","clk":"1005003340","pt":1580639966002,"mc":[{"id":"1.168236368","rc":[{"batb":[[1,1.96,27.89]],"ltp":2.04,"tv":222.66,"id":8284479}]}]}
{"op":"mcm","clk":"1005015328","pt":1580640095211,"mc":[{"id":"1.168236368","rc":[{"batb":[[0,1.97,7.57]],"ltp":2.04,"tv":222.66,"id":8284479}]}]}
{"op":"mcm","clk":"1005015555","pt":1580640097506,"mc":[{"id":"1.168236368","rc":[{"batb":[[1,1.96,50.6],[2,1.81,37.86]],"ltp":2.04,"tv":222.66,"id":8284479}]}]}
{"op":"mcm","clk":"1005015750","pt":1580640099734,"mc":[{"id":"1.168236368","rc":[{"batb":[[0,1.96,27.89],[1,1.81,37.86],[2,1.79,351.51]],"ltp":2.04,"tv":222.66,"id":8284479}]}]}
{"op":"mcm","clk":"1005016265","pt":1580640105031,"mc":[{"id":"1.168236368","rc":[{"batl":[[0,2.28,18.48],[1,95,15.9],[2,990,2.2]],"ltp":2.04,"tv":222.66,"id":8284479}]}]}
{"op":"mcm","clk":"1005016379","pt":1580640106237,"mc":[{"id":"1.168236368","rc":[{"batb":[[0,1.97,36.04],[1,1.96,27.89],[2,1.81,37.86]],"ltp":2.04,"tv":222.66,"id":8284479}]}]}
{"op":"mcm","clk":"1005016441","pt":1580640106818,"mc":[{"id":"1.168236368","rc":[{"batl":[[0,2.06,7.57],[1,2.28,18.48],[2,95,15.9]],"ltp":2.04,"tv":222.66,"id":8284479}]}]}
{"op":"mcm","clk":"1005032194","pt":1580640224234,"mc":[{"id":"1.168236368","rc":[{"batb":[[1,1.95,31.17]],"ltp":1.97,"tv":260.49,"id":4520808},{"trd":[[2.06,9.6]],"batb":[[0,1.98,14.59],[1,1.97,36.04]],"batl":[[0,2.06,2.77]],"ltp":2.06,"tv":232.26,"id":8284479}],"tv":492.75}]}
{"op":"mcm","clk":"1005032615","pt":1580640227270,"mc":[{"id":"1.168236368","rc":[{"batb":[[0,1.99,7.57],[1,1.98,14.59],[2,1.97,36.04]],"ltp":2.06,"tv":232.26,"id":8284479}]}]}
{"op":"mcm","clk":"1005032819","pt":1580640228529,"mc":[{"id":"1.168236368","rc":[{"batb":[[2,1.81,37.86]],"ltp":2.06,"tv":232.26,"id":8284479}]}]}
{"op":"mcm","clk":"1005033919","pt":1580640237163,"mc":[{"id":"1.168236368","rc":[{"batb":[[0,1.99,22.72]],"ltp":2.06,"tv":232.26,"id":8284479}]}]}
{"op":"mcm","clk":"1005034496","pt":1580640241170,"mc":[{"id":"1.168236368","rc":[{"batb":[[0,2,22.72]],"ltp":2.06,"tv":232.26,"id":8284479}]}]}
{"op":"mcm","clk":"1005034754","pt":1580640242793,"mc":[{"id":"1.168236368","rc":[{"batb":[[0,1.98,14.59],[1,1.81,37.86],[2,1.79,351.51]],"ltp":2.06,"tv":232.26,"id":8284479}]}]}
{"op":"mcm","clk":"1005034852","pt":1580640243393,"mc":[{"id":"1.168236368","rc":[{"batb":[[0,2,7.57],[1,1.98,14.59],[2,1.81,37.86]],"ltp":2.06,"tv":232.26,"id":8284479}]}]}
{"op":"mcm","clk":"1005035105","pt":1580640245186,"mc":[{"id":"1.168236368","rc":[{"batb":[[0,2,15.14],[2,1.95,7.57]],"ltp":2.06,"tv":232.26,"id":8284479}]}]}
{"op":"mcm","clk":"1005035123","pt":1580640245348,"mc":[{"id":"1.168236368","rc":[{"batb":[[2,1.95,15.14]],"ltp":2.06,"tv":232.26,"id":8284479}]}]}
{"op":"mcm","clk":"1005050444","pt":1580640360657,"mc":[{"id":"1.168236368","rc":[{"batb":[[1,1.91,59.74]],"ltp":1.97,"tv":260.49,"id":4520808},{"batb":[[1,1.96,27.89]],"ltp":2.06,"tv":232.26,"id":8284479}]}]}
{"op":"mcm","clk":"1005127077","pt":1580640979969,"mc":[{"id":"1.168236368","rc":[{"batb":[[1,1.97,15.14],[2,1.96,27.89]],"ltp":2.06,"tv":232.26,"id":8284479}]}]}
{"op":"mcm","clk":"1005127431","pt":1580640982744,"mc":[{"id":"1.168236368","rc":[{"batb":[[0,1.99,15.14]],"ltp":2.06,"tv":232.26,"id":8284479}]}]}
{"op":"mcm","clk":"1005134540","pt":1580641038215,"mc":[{"id":"1.168236368","rc":[{"batb":[[2,1.81,37.86]],"ltp":2.06,"tv":232.26,"id":8284479}]}]}
{"op":"mcm","clk":"1005134553","pt":1580641038315,"mc":[{"id":"1.168236368","rc":[{"batb":[[2,1.91,63.32]],"ltp":2.06,"tv":232.26,"id":8284479}]}]}
{"op":"mcm","clk":"1005140427","pt":1580641084908,"mc":[{"id":"1.168236368","rc":[{"batb":[[0,2,15.14]],"ltp":2.06,"tv":232.26,"id":8284479}]}]}
{"op":"mcm","clk":"1005171175","pt":1580641284513,"mc":[{"id":"1.168236368","rc":[{"batb":[[0,1.97,15.14],[1,1.91,63.32],[2,1.81,37.86]],"ltp":2.06,"tv":232.26,"id":8284479}]}]}
{"op":"mcm","clk":"1005171639","pt":1580641287407,"mc":[{"id":"1.168236368","rc":[{"batb":[[0,1.91,63.32],[1,1.81,37.86],[2,1.79,351.51]],"batl":[[0,2.28,18.48],[1,95,15.9],[2,990,2.2]],"ltp":2.06,"tv":232.26,"id":8284479}]}]}
{"op":"mcm","clk":"1005171884","pt":1580641288682,"mc":[{"id":"1.168236368","rc":[{"batb":[[0,1.95,41.47],[1,1.91,63.32],[2,1.81,37.86]],"ltp":2.06,"tv":232.26,"id":8284479}]}]}
{"op":"mcm","clk":"1005174329","pt":1580641302227,"mc":[{"id":"1.168236368","rc":[{"batb":[[0,1.96,41.47]],"ltp":2.06,"tv":232.26,"id":8284479}]}]}
{"op":"mcm","clk":"1005176392","pt":1580641313239,"mc":[{"id":"1.168236368","rc":[{"batb":[[1,1.81,37.86],[2,1.79,351.51]],"ltp":2.06,"tv":232.26,"id":8284479}]}]}
{"op":"mcm","clk":"1005176442","pt":1580641313511,"mc":[{"id":"1.168236368","rc":[{"batb":[[0,1.97,21.17],[1,1.96,41.47],[2,1.81,37.86]],"ltp":2.06,"tv":232.26,"id":8284479}]}]}
{"op":"mcm","clk":"1005177420","pt":1580641318719,"mc":[{"id":"1.168236368","rc":[{"batb":[[1,1.81,37.86],[2,1.79,351.51]],"ltp":2.06,"tv":232.26,"id":8284479}]}]}
{"op":"mcm","clk":"1005177643","pt":1580641319840,"mc":[{"id":"1.168236368","rc":[{"batb":[[0,1.98,40.85],[1,1.97,21.17],[2,1.81,37.86]],"ltp":2.06,"tv":232.26,"id":8284479}]}]}
{"op":"mcm","clk":"1005202167","pt":1580641445772,"mc":[{"id":"1.168236368","rc":[{"batb":[[1,1.91,63.32]],"ltp":2.06,"tv":232.26,"id":8284479}]}]}
{"op":"mcm","clk":"1005203429","pt":1580641452199,"mc":[{"id":"1.168236368","rc":[{"batb":[[0,1.95,40.85]],"ltp":2.06,"tv":232.26,"id":8284479}]}]}
{"op":"mcm","clk":"1005203978","pt":1580641454588,"mc":[{"id":"1.168236368","rc":[{"batb":[[0,1.96,40.85]],"ltp":2.06,"tv":232.26,"id":8284479}]}]}
{"op":"mcm","clk":"1005229640","pt":1580641578199,"mc":[{"id":"1.168236368","rc":[{"batb":[[0,1.97,21.17],[1,1.96,40.85]],"ltp":2.06,"tv":232.26,"id":8284479}]}]}
{"op":"mcm","clk":"1005261464","pt":1580641737063,"mc":[{"id":"1.168236368","rc":[{"trd":[[1.96,41.68],[1.97,42.35]],"batb":[[0,1.96,36.81],[1,1.81,37.86],[2,1.79,351.51]],"ltp":1.96,"tv":282.67,"id":8284479}],"tv":543.16}]}
{"op":"mcm","clk":"1005261565","pt":1580641737598,"mc":[{"id":"1.168236368","rc":[{"batb":[[1,1.94,59.23]],"ltp":1.97,"tv":260.49,"id":4520808},{"batb":[[1,1.88,64.62],[2,1.81,37.86]],"ltp":1.96,"tv":282.67,"id":8284479}]}]}
{"op":"mcm","clk":"1005268914","pt":1580641774857,"mc":[{"id":"1.168236368","rc":[{"trd":[[1.96,115.29]],"batb":[[0,1.88,64.62],[1,1.81,37.86],[2,1.79,351.51]],"ltp":1.96,"tv":356.29,"id":8284479}],"tv":616.78}]}
{"op":"mcm","clk":"1005269189","pt":1580641776051,"mc":[{"id":"1.168236368","rc":[{"batb":[[1,1.95,57.44]],"ltp":1.97,"tv":260.49,"id":4520808},{"batb":[[0,1.88,59.22]],"ltp":1.96,"tv":356.29,"id":8284479}]}]}
{"op":"mcm","clk":"1005315252","pt":1580642029662,"mc":[{"id":"1.168236368","rc":[{"batb":[[0,1.88,59.63]],"ltp":1.96,"tv":356.29,"id":8284479}]}]}
{"op":"mcm","clk":"1005315748","pt":1580642032596,"mc":[{"id":"1.168236368","rc":[{"batb":[[0,1.88,59.22]],"ltp":1.96,"tv":356.29,"id":8284479}]}]}
{"op":"mcm","clk":"1005316309","pt":1580642036025,"mc":[{"id":"1.168236368","rc":[{"batl":[[0,2,15.14],[1,2.28,18.48],[2,95,15.9]],"ltp":1.96,"tv":356.29,"id":8284479}]}]}
{"op":"mcm","clk":"1005340678","pt":1580642171062,"mc":[{"id":"1.168236368","rc":[{"batb":[[0,1.89,420.1],[1,1.88,59.22],[2,1.81,37.86]],"ltp":1.96,"tv":356.29,"id":8284479}]}]}
{"op":"mcm","clk":"1005340892","pt":1580642172176,"mc":[{"id":"1.168236368","rc":[{"trd":[[2,132.96]],"batl":[[0,2,3.92]],"ltp":2.0,"tv":378.73,"id":8284479}],"tv":639.22}]}
{"op":"mcm","clk":"1005341187","pt":1580642173773,"mc":[{"id":"1.168236368","rc":[{"batb":[[1,1.88,479.31]],"ltp":2.0,"tv":378.73,"id":8284479}]}]}
{"op":"mcm","clk":"1005341683","pt":1580642176200,"mc":[{"id":"1.168236368","rc":[{"batb":[[2,1.87,420.1]],"ltp":2.0,"tv":378.73,"id":8284479}]}]}
{"op":"mcm","clk":"1005342330","pt":1580642179509,"mc":[{"id":"1.168236368","rc":[{"batl":[[0,2,11.49]],"ltp":2.0,"tv":378.73,"id":8284479}]}]}
{"op":"mcm","clk":"1005351637","pt":1580642230662,"mc":[{"id":"1.168236368","rc":[{"batl":[[0,2.28,18.48],[1,95,15.9],[2,990,2.2]],"ltp":2.0,"tv":378.73,"id":8284479}]}]}
{"op":"mcm","clk":"1005351896","pt":1580642231943,"mc":[{"id":"1.168236368","rc":[{"batb":[[0,1.96,11.87],[1,1.89,420.1],[2,1.88,479.31]],"ltp":2.0,"tv":378.73,"id":8284479}]}]}
{"op":"mcm","clk":"1005352522","pt":1580642235065,"mc":[{"id":"1.168236368","rc":[{"batl":[[0,2,7.57],[1,2.28,18.48],[2,95,15.9]],"ltp":2.0,"tv":378.73,"id":8284479}]}]}
{"op":"mcm","clk":"1005355905","pt":1580642253677,"mc":[{"id":"1.168236368","rc":[{"batb":[[1,1.9,43.96],[2,1.89,420.1]],"ltp":2.0,"tv":378.73,"id":8284479}]}]}
{"op":"mcm","clk":"1005358758","pt":1580642268778,"mc":[{"id":"1.168236368","rc":[{"trd":[[1.96,139.04]],"batb":[[0,1.9,43.96],[1,1.89,420.1],[2,1.88,420.1]],"batl":[[0,1.96,4.93],[1,2,7.57],[2,2.28,18.48]],"ltp":1.96,"tv":402.48,"id":8284479}],"tv":662.97}]}
{"op":"mcm","clk":"1005359774","pt":1580642274015,"mc":[{"id":"1.168236368","rc":[{"batl":[[1,2,15.14]],"ltp":1.96,"tv":402.48,"id":8284479}]}]}
{"op":"mcm","clk":"1005360003","pt":1580642275202,"mc":[{"id":"1.168236368","rc":[{"batb":[[1,1.95,62.13]],"ltp":1.97,"tv":260.49,"id":4520808},{"trd":[[1.9,9.86]],"batb":[[0,1.9,39.03]],"batl":[[0,2,15.14],[1,2.28,18.48],[2,95,15.9]],"ltp":1.9,"tv":412.34,"id":8284479}],"tv":672.83}]}
{"op":"mcm","clk":"1005386298","pt":1580642412591,"mc":[{"id":"1.168236368","rc":[{"trd":[[2,155.6]],"batl":[[0,2,3.82]],"ltp":2.0,"tv":434.98,"id":8284479}],"tv":695.47}]}
{"op":"mcm","clk":"1005389082","pt":1580642427994,"mc":[{"id":"1.168236368","rc":[{"trd":[[1.9,19.36]],"batb":[[0,1.9,34.28]],"ltp":1.9,"tv":444.48,"id":8284479}],"tv":704.97}]}
{"op":"mcm","clk":"1005389210","pt":1580642428733,"mc":[{"id":"1.168236368","rc":[{"batb":[[0,1.97,52.94],[1,1.96,3.56]],"ltp":1.97,"tv":260.49,"id":4520808}]}]}
{"op":"mcm","clk":"1005389668","pt":1580642431441,"mc":[{"id":"1.168236368","rc":[{"batl":[[0,2.28,18.48],[1,95,15.9],[2,990,2.2]],"ltp":1.9,"tv":444.48,"id":8284479}]}]}
{"op":"mcm","clk":"1005389887","pt":1580642432612,"mc":[{"id":"1.168236368","rc":[{"batb":[[0,1.91,11.85],[1,1.9,34.28],[2,1.89,420.1]],"batl":[[0,2,15.14],[1,2.28,18.48],[2,95,15.9]],"ltp":1.9,"tv":444.48,"id":8284479}]}]}
{"op":"mcm","clk":"1005394454","pt":1580642457463,"mc":[{"id":"1.168236368","rc":[{"batl":[[0,2,22.72]],"ltp":1.9,"tv":444.48,"id":8284479}]}]}
{"op":"mcm","clk":"1005394711","pt":1580642458679,"mc":[{"id":"1.168236368","rc":[{"trd":[[2,188.86]],"batl":[[0,2,6.08]],"ltp":2.0,"tv":477.75,"id":8284479}],"tv":738.24}]}
{"op":"mcm","clk":"1005395570","pt":1580642463566,"mc":[{"id":"1.168236368","rc":[{"batb":[[0,1.96,15.14],[1,1.91,11.85],[2,1.9,34.28]],"ltp":2.0,"tv":477.75,"id":8284479}]}]}
{"op":"mcm","clk":"1005403677","pt":1580642510142,"mc":[{"id":"1.168236368","rc":[{"batb":[[0,1.91,11.85],[1,1.9,34.28],[2,1.89,420.1]],"ltp":2.0,"tv":477.75,"id":8284479}]}]}
{"op":"mcm","clk":"1005403786","pt":1580642510747,"mc":[{"id":"1.168236368","rc":[{"trd":[[1.97,105.84],[2,6.08]],"batb":[[0,1.97,23.02]],"ltp":1.97,"tv":326.41,"id":4520808},{"trd":[[2,194.94]],"batl":[[0,2.28,18.48],[1,95,15.9],[2,990,2.2]],"ltp":2.0,"tv":483.83,"id":8284479}],"tv":810.24}]}
{"op":"mcm","clk":"1005403924","pt":1580642511537,"mc":[{"id":"1.168236368","rc":[{"batb":[[0,1.96,3.56],[1,1.92,58.29]],"ltp":1.97,"tv":326.41,"id":4520808},{"batb":[[0,1.92,50.08],[1,1.91,11.85]],"ltp":2.0,"tv":483.83,"id":8284479}]}]}
{"op":"mcm","clk":"1005404943","pt":1580642517062,"mc":[{"id":"1.168236368","rc":[{"batb":[[1,1.89,420.1],[2,1.88,420.1]],"ltp":2.0,"tv":483.83,"id":8284479}]}]}
{"op":"mcm","clk":"1005405146","pt":1580642518166,"mc":[{"id":"1.168236368","rc":[{"batb":[[0,1.96,28.52],[1,1.92,50.08],[2,1.89,420.1]],"batl":[[0,2.04,7.57],[1,2.28,18.48],[2,95,15.9]],"ltp":2.0,"tv":483.83,"id":8284479}]}]}
{"op":"mcm","clk":"1005405184","pt":1580642518329,"mc":[{"id":"1.168236368","rc":[{"batl":[[0,2.04,15.14]],"ltp":2.0,"tv":483.83,"id":8284479}]}]}
{"op":"mcm","clk":"1005405974","pt":1580642522371,"mc":[{"id":"1.168236368","rc":[{"batl":[[0,2.04,22.72]],"ltp":2.0,"tv":483.83,"id":8284479}]}]}
{"op":"mcm","clk":"1005408572","pt":1580642536174,"mc":[{"id":"1.168236368","rc":[{"batb":[[2,1.9,7.57]],"ltp":2.0,"tv":483.83,"id":8284479}]}]}
{"op":"mcm","clk":"1005408605","pt":1580642536389,"mc":[{"id":"1.168236368","rc":[{"batb":[[2,1.9,15.14]],"ltp":2.0,"tv":483.83,"id":8284479}]}]}
{"op":"mcm","clk":"1005408933","pt":1580642537981,"mc":[{"id":"1.168236368","rc":[{"batb":[[2,1.9,22.72]],"ltp":2.0,"tv":483.83,"id":8284479}]}]}
{"op":"mcm","clk":"1005423533","pt":1580642612235,"mc":[{"id":"1.168236368","rc":[{"batl":[[2,4.2,153.72]],"ltp":1.97,"tv":326.41,"id":4520808},{"batl":[[2,4.2,153.72]],"ltp":2.0,"tv":483.83,"id":8284479}]}]}
{"op":"mcm","clk":"1005423676","pt":1580642612913,"mc":[{"id":"1.168236368","rc":[{"trd":[[2.04,52.04]],"batl":[[0,2.04,6]],"ltp":2.04,"tv":517.25,"id":8284479}],"tv":843.66}]}
{"op":"mcm","clk":"1005430908","pt":1580642651060,"mc":[{"id":"1.168236368","rc":[{"batb":[[0,1.97,15.35],[1,1.96,28.52]],"ltp":2.04,"tv":517.25,"id":8284479}]}]}
{"op":"mcm","clk":"1005431101","pt":1580642652064,"mc":[{"id":"1.168236368","rc":[{"trd":[[2.04,61.16]],"batl":[[0,2.04,1.45]],"ltp":2.04,"tv":526.37,"id":8284479}],"tv":852.78}]}
{"op":"mcm","clk":"1005441000","pt":1580642703454,"mc":[{"id":"1.168236368","rc":[{"batb":[[0,1.98,7.57],[1,1.97,15.35],[2,1.96,28.52]],"ltp":2.04,"tv":526.37,"id":8284479}]}]}
{"op":"mcm","clk":"1005451005","pt":1580642757872,"mc":[{"id":"1.168236368","rc":[{"batl":[[2,4,3.03]],"ltp":1.97,"tv":326.41,"id":4520808}]}]}
{"op":"mcm","clk":"1005452024","pt":1580642762920,"mc":[{"id":"1.168236368","rc":[{"batl":[[2,4,3.48]],"ltp":1.97,"tv":326.41,"id":4520808}]}]}
{"op":"mcm","clk":"1005453688","pt":1580642772057,"mc":[{"id":"1.168236368","rc":[{"batl":[[0,2.28,18.94],[2,4.2,153.72]],"ltp":1.97,"tv":326.41,"id":4520808}]}]}
{"op":"mcm","clk":"1005547092","pt":1580643268774,"mc":[{"id":"1.168236368","rc":[{"batb":[[2,1.89,420.1]],"ltp":2.04,"tv":526.37,"id":8284479}]}]}
{"op":"mcm","clk":"1005555530","pt":1580643312727,"mc":[{"id":"1.168236368","rc":[{"batb":[[1,1.9,64.88]],"ltp":2.04,"tv":526.37,"id":8284479}]}]}
{"op":"mcm","clk":"1005620620","pt":1580643627183,"mc":[{"id":"1.168236368","rc":[{"batb":[[1,1.96,15.14],[2,1.9,64.88]],"ltp":2.04,"tv":526.37,"id":8284479}]}]}
{"op":"mcm","clk":"1005621185","pt":1580643630011,"mc":[{"id":"1.168236368","rc":[{"batb":[[0,1.96,22.72],[1,1.9,64.88],[2,1.89,420.1]],"ltp":2.04,"tv":526.37,"id":8284479}]}]}
{"op":"mcm","clk":"1005623961","pt":1580643644728,"mc":[{"id":"1.168236368","rc":[{"batb":[[0,1.96,37.86]],"ltp":2.04,"tv":526.37,"id":8284479}]}]}
{"op":"mcm","clk":"1005624736","pt":1580643648420,"mc":[{"id":"1.168236368","rc":[{"batb":[[0,1.9,64.88],[1,1.89,420.1],[2,1.88,420.1]],"batl":[[0,2.28,18.48],[1,4.2,153.72],[2,95,15.9]],"ltp":2.04,"tv":526.37,"id":8284479}]}]}
{"op":"mcm","clk":"1005624943","pt":1580643649541,"mc":[{"id":"1.168236368","rc":[{"batb":[[0,1.96,56.87],[1,1.9,64.88],[2,1.89,420.1]],"ltp":2.04,"tv":526.37,"id":8284479}]}]}
{"op":"mcm","clk":"1005625876","pt":1580643654506,"mc":[{"id":"1.168236368","rc":[{"batl":[[0,2.04,1.51],[1,2.28,18.48],[2,4.2,153.72]],"ltp":2.04,"tv":526.37,"id":8284479}]}]}
{"op":"mcm","clk":"1005635285","pt":1580643701854,"mc":[{"id":"1.168236368","rc":[{"batb":[[0,1.97,15.35],[1,1.96,56.87]],"ltp":2.04,"tv":526.37,"id":8284479}]}]}
{"op":"mcm","clk":"1005636138","pt":1580643706215,"mc":[{"id":"1.168236368","rc":[{"batb":[[0,1.98,1.51],[1,1.97,15.35]],"ltp":2.04,"tv":526.37,"id":8284479}]}]}
{"op":"mcm","clk":"1005636740","pt":1580643708913,"mc":[{"id":"1.168236368","rc":[{"batb":[[0,1.98,3.03]],"ltp":2.04,"tv":526.37,"id":8284479}]}]}
{"op":"mcm","clk":"1005637025","pt":1580643710208,"mc":[{"id":"1.168236368","rc":[{"batb":[[0,1.98,25.75]],"ltp":2.04,"tv":526.37,"id":8284479}]}]}
{"op":"mcm","clk":"1005637044","pt":1580643710307,"mc":[{"id":"1.168236368","rc":[{"batb":[[0,1.98,48.46]],"ltp":2.04,"tv":526.37,"id":8284479}]}]}
{"op":"mcm","clk":"1005637909","pt":1580643714694,"mc":[{"id":"1.168236368","rc":[{"batb":[[2,1.96,7.57]],"ltp":2.04,"tv":526.37,"id":8284479}]}]}
{"op":"mcm","clk":"1005659313","pt":1580643824040,"mc":[{"id":"1.168236368","rc":[{"batb":[[2,1.95,7.57]],"ltp":2.04,"tv":526.37,"id":8284479}]}]}
{"op":"mcm","clk":"1005661259","pt":1580643834398,"mc":[{"id":"1.168236368","rc":[{"batb":[[1,1.95,7.57],[2,1.9,64.88]],"ltp":2.04,"tv":526.37,"id":8284479}]}]}
{"op":"mcm","clk":"1005675202","pt":1580643910451,"mc":[{"id":"1.168236368","rc":[{"batb":[[0,1.97,48.46]],"ltp":2.04,"tv":526.37,"id":8284479}]}]}
{"op":"mcm","clk":"1005675752","pt":1580643913152,"mc":[{"id":"1.168236368","rc":[{"batb":[[1,1.91,7.57]],"ltp":2.04,"tv":526.37,"id":8284479}]}]}
{"op":"mcm","clk":"1005676518","pt":1580643917144,"mc":[{"id":"1.168236368","rc":[{"batb":[[0,1.91,56.04],[1,1.9,64.88],[2,1.89,420.1]],"ltp":2.04,"tv":526.37,"id":8284479}]}]}
{"op":"mcm","clk":"1005686404","pt":1580643970086,"mc":[{"id":"1.168236368","rc":[{"batb":[[1,1.89,420.1],[2,1.88,420.1]],"ltp":2.04,"tv":526.37,"id":8284479}]}]}
{"op":"mcm","clk":"1005686433","pt":1580643970247,"mc":[{"id":"1.168236368","rc":[{"batb":[[0,1.92,50.08],[1,1.91,56.04],[2,1.89,420.1]],"ltp":2.04,"tv":526.37,"id":8284479}]}]}
{"op":"mcm","clk":"1005694780","pt":1580644020183,"mc":[{"id":"1.168236368","rc":[{"batb":[[0,1.95,56.04],[1,1.92,50.08]],"ltp":2.04,"tv":526.37,"id":8284479}]}]}
{"op":"mcm","clk":"1005695208","pt":1580644023168,"mc":[{"id":"1.168236368","rc":[{"batb":[[0,1.92,50.08],[1,1.89,420.1],[2,1.88,420.1]],"ltp":2.04,"tv":526.37,"id":8284479}]}]}
{"op":"mcm","clk":"1005695228","pt":1580644023271,"mc":[{"id":"1.168236368","rc":[{"batb":[[0,1.93,56.04],[1,1.92,50.08],[2,1.89,420.1]],"ltp":2.04,"tv":526.37,"id":8284479}]}]}
{"op":"mcm","clk":"1005707356","pt":1580644100698,"mc":[{"id":"1.168236368","rc":[{"batb":[[0,1.94,35.81],[1,1.93,56.04]],"ltp":2.04,"tv":526.37,"id":8284479}]}]}
{"op":"mcm","clk":"1005737977","pt":1580644320433,"mc":[{"id":"1.168236368","rc":[{"batl":[[1,2.12,8.4],[2,2.28,18.48]],"ltp":2.04,"tv":526.37,"id":8284479}]}]}
{"op":"mcm","clk":"1005740613","pt":1580644340851,"mc":[{"id":"1.168236368","rc":[{"batb":[[0,1.96,15.14],[1,1.94,35.81],[2,1.93,56.04]],"ltp":2.04,"tv":526.37,"id":8284479}]}]}
{"op":"mcm","clk":"1005740909","pt":1580644342892,"mc":[{"id":"1.168236368","rc":[{"batb":[[2,1.89,420.1]],"ltp":2.04,"tv":526.37,"id":8284479}]}]}
{"op":"mcm","clk":"1005741038","pt":1580644343879,"mc":[{"id":"1.168236368","rc":[{"batb":[[0,1.96,30.29]],"ltp":2.04,"tv":526.37,"id":8284479}]}]}
{"op":"mcm","clk":"1005741281","pt":1580644345681,"mc":[{"id":"1.168236368","rc":[{"batb":[[0,1.96,45.43]],"ltp":2.04,"tv":526.37,"id":8284479}]}]}
{"op":"mcm","clk":"1005741585","pt":1580644348098,"mc":[{"id":"1.168236368","rc":[{"batb":[[2,1.9,7.57]],"ltp":2.04,"tv":526.37,"id":8284479}]}]}
{"op":"mcm","clk":"1005741628","pt":1580644348376,"mc":[{"id":"1.168236368","rc":[{"batb":[[2,1.9,15.14]],"ltp":2.04,"tv":526.37,"id":8284479}]}]}
{"op":"mcm","clk":"1005743537","pt":1580644363698,"mc":[{"id":"1.168236368","rc":[{"batb":[[0,1.97,15.35],[1,1.96,45.43]],"ltp":2.04,"tv":526.37,"id":8284479}]}]}
{"op":"mcm","clk":"1005760582","pt":1580644497004,"mc":[{"id":"1.168236368","rc":[{"batb":[[1,1.9,15.14],[2,1.89,420.1]],"ltp":2.04,"tv":526.37,"id":8284479}]}]}
{"op":"mcm","clk":"1005760709","pt":1580644497998,"mc":[{"id":"1.168236368","rc":[{"batb":[[0,1.98,7.57],[1,1.97,15.35],[2,1.9,15.14]],"ltp":2.04,"tv":526.37,"id":8284479}]}]}
{"op":"mcm","clk":"1005760762","pt":1580644498403,"mc":[{"id":"1.168236368","rc":[{"batb":[[0,1.98,15.14]],"ltp":2.04,"tv":526.37,"id":8284479}]}]}
{"op":"mcm","clk":"1005761088","pt":1580644501015,"mc":[{"id":"1.168236368","rc":[{"batb":[[2,1.96,7.57]],"ltp":2.04,"tv":526.37,"id":8284479}]}]}
{"op":"mcm","clk":"1005761215","pt":1580644502115,"mc":[{"id":"1.168236368","rc":[{"batb":[[2,1.96,22.72]],"ltp":2.04,"tv":526.37,"id":8284479}]}]}
{"op":"mcm","clk":"1005761304","pt":1580644502800,"mc":[{"id":"1.168236368","rc":[{"batb":[[2,1.96,30.29]],"ltp":2.04,"tv":526.37,"id":8284479}]}]}
{"op":"mcm","clk":"1005767669","pt":1580644553584,"mc":[{"id":"1.168236368","rc":[{"batb":[[0,1.98,22.72]],"ltp":2.04,"tv":526.37,"id":8284479}]}]}
{"op":"mcm","clk":"1005811029","pt":1580644878410,"mc":[{"id":"1.168236368","rc":[{"trd":[[1.98,30.29]],"batb":[[0,1.98,7.57]],"ltp":1.98,"tv":556.66,"id":8284479}],"tv":883.07}]}
{"op":"mcm","clk":"1005812478","pt":1580644888863,"mc":[{"id":"1.168236368","rc":[{"batb":[[0,1.98,15.14]],"ltp":1.98,"tv":556.66,"id":8284479}]}]}
{"op":"mcm","clk":"1005825072","pt":1580644963863,"mc":[{"id":"1.168236368","rc":[{"batb":[[0,1.98,15.27]],"ltp":1.98,"tv":556.66,"id":8284479}]}]}
{"op":"mcm","clk":"1005825956","pt":1580644969192,"mc":[{"id":"1.168236368","rc":[{"batb":[[2,1.9,15.14]],"ltp":1.98,"tv":556.66,"id":8284479}]}]}
{"op":"mcm","clk":"1005826528","pt":1580644972494,"mc":[{"id":"1.168236368","rc":[{"batb":[[0,1.98,22.84]],"ltp":1.98,"tv":556.66,"id":8284479}]}]}
{"op":"mcm","clk":"1005826849","pt":1580644974178,"mc":[{"id":"1.168236368","rc":[{"batb":[[0,1.97,15.47],[1,1.9,15.14],[2,1.89,420.1]],"ltp":1.98,"tv":556.66,"id":8284479}]}]}
{"op":"mcm","clk":"1005827363","pt":1580644976894,"mc":[{"id":"1.168236368","rc":[{"batb":[[0,1.97,30.62]],"ltp":1.98,"tv":556.66,"id":8284479}]}]}
{"op":"mcm","clk":"1005827705","pt":1580644978913,"mc":[{"id":"1.168236368","rc":[{"batb":[[0,1.97,38.19]],"ltp":1.98,"tv":556.66,"id":8284479}]}]}
{"op":"mcm","clk":"1005836270","pt":1580645025872,"mc":[{"id":"1.168236368","rc":[{"batb":[[0,1.97,22.84],[1,1.91,57.41],[2,1.9,15.14]],"ltp":1.98,"tv":556.66,"id":8284479}]}]}
{"op":"mcm","clk":"1005841326","pt":1580645052010,"mc":[{"id":"1.168236368","rc":[{"trd":[[1.92,2.65],[1.96,196.21]],"batb":[[0,1.92,55.65],[1,1.9,2.53],[2,1.89,9.54]],"ltp":1.92,"tv":332.61,"id":4520808},{"trd":[[2.04,64.18],[2.06,12.99],[2.1,2.42]],"batl":[[0,2.12,8.4],[1,2.28,18.48],[2,4.2,153.72]],"ltp":2.1,"tv":565.49,"id":8284479}],"tv":898.11}]}
{"op":"mcm","clk":"1005841506","pt":1580645053013,"mc":[{"id":"1.168236368","rc":[{"batb":[[0,1.94,9.03],[1,1.93,257.79],[2,1.91,63.05]],"ltp":1.92,"tv":332.61,"id":4520808},{"batb":[[1,1.91,60.01]],"batl":[[0,2.06,8.4]],"ltp":2.1,"tv":565.49,"id":8284479}]}]}
{"op":"mcm","clk":"1005841560","pt":1580645053293,"mc":[{"id":"1.168236368","rc":[{"batb":[[1,1.91,63.05],[2,1.9,2.53]],"ltp":1.92,"tv":332.61,"id":4520808}]}]}
{"op":"mcm","clk":"1005841773","pt":1580645054511,"mc":[{"id":"1.168236368","rc":[{"batb":[[0,1.91,63.05],[1,1.9,2.53],[2,1.88,269.33]],"ltp":1.92,"tv":332.61,"id":4520808},{"batl":[[0,2.28,18.48],[1,4.2,153.72],[2,95,15.9]],"ltp":2.1,"tv":565.49,"id":8284479}]}]}
{"op":"mcm","clk":"1005841966","pt":1580645055514,"mc":[{"id":"1.168236368","rc":[{"batb":[[0,1.93,257.79],[1,1.91,63.05],[2,1.9,2.53]],"ltp":1.92,"tv":332.61,"id":4520808}]}]}
{"op":"mcm","clk":"1005842450","pt":1580645057919,"mc":[{"id":"1.168236368","rc":[{"batb":[[0,1.99,7.69],[1,1.97,22.72],[2,1.91,60.01]],"ltp":2.1,"tv":565.49,"id":8284479}]}]}
{"op":"mcm","clk":"1005843931","pt":1580645066177,"mc":[{"id":"1.168236368","rc":[{"batb":[[2,1.92,15.14]],"ltp":2.1,"tv":565.49,"id":8284479}]}]}
{"op":"mcm","clk":"1005861545","pt":1580645157561,"mc":[{"id":"1.168236368","rc":[{"batb":[[0,1.94,41.4],[1,1.93,257.79]],"ltp":1.92,"tv":332.61,"id":4520808},{"batb":[[2,1.93,45.46]],"ltp":2.1,"tv":565.49,"id":8284479}]}]}
{"op":"mcm","clk":"1005861839","pt":1580645159098,"mc":[{"id":"1.168236368","rc":[{"trd":[[1.94,82]],"batb":[[0,1.93,257.79],[1,1.9,2.53],[2,1.88,269.33]],"ltp":1.94,"tv":414.61,"id":4520808},{"batb":[[2,1.92,15.14]],"ltp":2.1,"tv":565.49,"id":8284479}],"tv":980.11}]}
{"op":"mcm","clk":"1005861880","pt":1580645159312,"mc":[{"id":"1.168236368","rc":[{"batb":[[0,1.94,14.27],[1,1.93,257.79],[2,1.9,2.53]],"ltp":1.94,"tv":414.61,"id":4520808},{"batb":[[1,1.98,37.93],[2,1.97,22.72]],"ltp":2.1,"tv":565.49,"id":8284479}]}]}
{"op":"mcm","clk":"1005862814","pt":1580645164226,"mc":[{"id":"1.168236368","rc":[{"batb":[[2,1.92,15.14]],"ltp":2.1,"tv":565.49,"id":8284479}]}]}
{"op":"mcm","clk":"1005862833","pt":1580645164278,"mc":[{"id":"1.168236368","rc":[{"batb":[[2,1.96,22.72]],"ltp":2.1,"tv":565.49,"id":8284479}]}]}
{"op":"mcm","clk":"1005866378","pt":1580645181829,"mc":[{"id":"1.168236368","rc":[{"batb":[[0,1.99,15.27]],"ltp":2.1,"tv":565.49,"id":8284479}]}]}
{"op":"mcm","clk":"1005866852","pt":1580645183801,"mc":[{"id":"1.168236368","rc":[{"batb":[[0,1.98,38.06],[1,1.96,22.72],[2,1.92,15.14]],"ltp":2.1,"tv":565.49,"id":8284479}]}]}
{"op":"mcm","clk":"1005867260","pt":1580645185822,"mc":[{"id":"1.168236368","rc":[{"batb":[[0,1.99,15.27],[1,1.98,37.93],[2,1.96,22.72]],"ltp":2.1,"tv":565.49,"id":8284479}]}]}
{"op":"mcm","clk":"1005867597","pt":1580645187530,"mc":[{"id":"1.168236368","rc":[{"batb":[[0,1.94,23.17]],"ltp":1.94,"tv":414.61,"id":4520808},{"batl":[[0,2.06,8.4],[1,2.28,18.48],[2,4.2,153.72]],"ltp":2.1,"tv":565.49,"id":8284479}]}]}
{"op":"mcm","clk":"1005868706","pt":1580645193631,"mc":[{"id":"1.168236368","rc":[{"batb":[[0,2,7.57],[1,1.99,15.27],[2,1.98,37.93]],"ltp":2.1,"tv":565.49,"id":8284479}]}]}
{"op":"mcm","clk":"1005868853","pt":1580645194323,"mc":[{"id":"1.168236368","rc":[{"trd":[[2.06,26.03]],"batl":[[0,2.06,1.88]],"ltp":2.06,"tv":578.53,"id":8284479}],"tv":993.15}]}
{"op":"mcm","clk":"1005869053","pt":1580645195257,"mc":[{"id":"1.168236368","rc":[{"batb":[[0,1.99,15.27],[1,1.98,37.93],[2,1.96,22.72]],"ltp":2.06,"tv":578.53,"id":8284479}]}]}
{"op":"mcm","clk":"1005869513","pt":1580645197706,"mc":[{"id":"1.168236368","rc":[{"batb":[[0,1.99,22.84]],"ltp":2.06,"tv":578.53,"id":8284479}]}]}
{"op":"mcm","clk":"1005869978","pt":1580645200433,"mc":[{"id":"1.168236368","rc":[{"batb":[[2,1.92,15.14]],"ltp":2.06,"tv":578.53,"id":8284479}]}]}
{"op":"mcm","clk":"1005870356","pt":1580645202136,"mc":[{"id":"1.168236368","rc":[{"batb":[[0,1.98,38.06],[1,1.92,15.14],[2,1.89,420.1]],"ltp":2.06,"tv":578.53,"id":8284479}]}]}
{"op":"mcm","clk":"1005870557","pt":1580645203140,"mc":[{"id":"1.168236368","rc":[{"batb":[[0,1.99,15.27],[1,1.98,37.93],[2,1.92,15.14]],"ltp":2.06,"tv":578.53,"id":8284479}]}]}
{"op":"mcm","clk":"1005876059","pt":1580645232066,"mc":[{"id":"1.168236368","rc":[{"batb":[[0,1.94,30.3]],"ltp":1.94,"tv":414.61,"id":4520808}]}]}
{"op":"mcm","clk":"1005876186","pt":1580645232649,"mc":[{"id":"1.168236368","rc":[{"trd":[[1.94,131]],"batb":[[0,1.94,262.22],[1,1.9,2.53],[2,1.88,269.33]],"ltp":1.94,"tv":463.62,"id":4520808}],"tv":1042.15}]}
{"op":"mcm","clk":"1005876756","pt":1580645235469,"mc":[{"id":"1.168236368","rc":[{"batb":[[2,1.89,50.67]],"ltp":1.94,"tv":463.62,"id":4520808},{"batb":[[1,1.95,58.25]],"ltp":2.06,"tv":578.53,"id":8284479}]}]}
{"op":"mcm","clk":"1005882173","pt":1580645263429,"mc":[{"id":"1.168236368","rc":[{"batb":[[0,1.94,262.35]],"ltp":1.94,"tv":463.62,"id":4520808}]}]}
{"op":"mcm","clk":"1005882513","pt":1580645265225,"mc":[{"id":"1.168236368","rc":[{"trd":[[1.94,226.74],[1.95,0.26]],"batb":[[0,1.94,256.42]],"ltp":1.94,"tv":559.61,"id":4520808}],"tv":1138.15}]}
{"op":"mcm","clk":"1005888005","pt":1580645293070,"mc":[{"id":"1.168236368","rc":[{"batb":[[0,1.94,259.61]],"ltp":1.94,"tv":559.61,"id":4520808}]}]}
{"op":"mcm","clk":"1005888852","pt":1580645297072,"mc":[{"id":"1.168236368","rc":[{"batb":[[0,1.94,3.19]],"ltp":1.94,"tv":559.61,"id":4520808},{"batl":[[0,2.28,18.48],[1,4.2,153.72],[2,95,15.9]],"ltp":2.06,"tv":578.53,"id":8284479}]}]}
{"op":"mcm","clk":"1005898101","pt":1580645341100,"mc":[{"id":"1.168236368","rc":[{"batb":[[0,1.95,58.37],[1,1.92,15.14],[2,1.89,420.1]],"ltp":2.06,"tv":578.53,"id":8284479}]}]}
{"op":"mcm","clk":"1005898451","pt":1580645342925,"mc":[{"id":"1.168236368","rc":[{"batb":[[0,1.99,7.69],[1,1.95,58.25],[2,1.92,15.14]],"ltp":2.06,"tv":578.53,"id":8284479}]}]}
{"op":"mcm","clk":"1005898856","pt":1580645345246,"mc":[{"id":"1.168236368","rc":[{"batb":[[0,1.99,15.27]],"ltp":2.06,"tv":578.53,"id":8284479}]}]}
{"op":"mcm","clk":"1005899808","pt":1580645350052,"mc":[{"id":"1.168236368","rc":[{"batl":[[0,2.04,8.46],[1,2.28,18.94],[2,2.6,74.21]],"ltp":1.94,"tv":559.61,"id":4520808},{"batb":[[1,1.96,15.14],[2,1.95,58.25]],"ltp":2.06,"tv":578.53,"id":8284479}]}]}
{"op":"mcm","clk":"1005900131","pt":1580645351836,"mc":[{"id":"1.168236368","rc":[{"batb":[[0,1.95,58.37],[1,1.89,420.1],[2,1.88,420.1]],"ltp":2.06,"tv":578.53,"id":8284479}]}]}
{"op":"mcm","clk":"1005900347","pt":1580645352926,"mc":[{"id":"1.168236368","rc":[{"batb":[[0,1.96,43.27],[1,1.95,58.25],[2,1.89,420.1]],"ltp":2.06,"tv":578.53,"id":8284479}]}]}
{"op":"mcm","clk":"1005900488","pt":1580645353730,"mc":[{"id":"1.168236368","rc":[{"batb":[[0,1.96,50.12]],"ltp":2.06,"tv":578.53,"id":8284479}]}]}
{"op":"mcm","clk":"1005900751","pt":1580645355148,"mc":[{"id":"1.168236368","rc":[{"batb":[[0,1.99,7.69],[1,1.96,6.86],[2,1.95,58.25]],"ltp":2.06,"tv":578.53,"id":8284479}]}]}
{"op":"mcm","clk":"1005900804","pt":1580645355433,"mc":[{"id":"1.168236368","rc":[{"batl":[[0,2.28,18.94],[1,2.6,74.21],[2,4.2,153.72]],"ltp":1.94,"tv":559.61,"id":4520808},{"batb":[[1,1.95,58.25],[2,1.89,420.1]],"ltp":2.06,"tv":578.53,"id":8284479}]}]}
{"op":"mcm","clk":"1005901107","pt":1580645356947,"mc":[{"id":"1.168236368","rc":[{"batb":[[0,1.99,15.27],[1,1.96,15.14],[2,1.95,58.25]],"ltp":2.06,"tv":578.53,"id":8284479}]}]}
{"op":"mcm","clk":"1005901374","pt":1580645358447,"mc":[{"id":"1.168236368","rc":[{"batb":[[1,1.96,22.72]],"ltp":2.06,"tv":578.53,"id":8284479}]}]}
{"op":"mcm","clk":"1005909357","pt":1580645399612,"mc":[{"id":"1.168236368","rc":[{"batb":[[0,1.96,22.84],[1,1.95,58.25],[2,1.89,420.1]],"ltp":2.06,"tv":578.53,"id":8284479}]}]}
{"op":"mcm","clk":"1005909572","pt":1580645400787,"mc":[{"id":"1.168236368","rc":[{"batb":[[0,2,78.75],[1,1.94,3.19],[2,1.9,2.53]],"ltp":1.94,"tv":559.61,"id":4520808}]}]}
{"op":"mcm","clk":"1005910576","pt":1580645406111,"mc":[{"id":"1.168236368","rc":[{"trd":[[1.99,4.75]],"batb":[[0,1.96,22.76]],"ltp":1.99,"tv":578.68,"id":8284479}],"tv":1138.3}]}
{"op":"mcm","clk":"1005911334","pt":1580645410154,"mc":[{"id":"1.168236368","rc":[{"trd":[[1.99,4.84]],"batb":[[0,1.96,22.72]],"batl":[[0,2.28,18.51]],"ltp":1.99,"tv":578.77,"id":8284479}],"tv":1138.39}]}
{"op":"mcm","clk":"1005912144","pt":1580645414937,"mc":[{"id":"1.168236368","rc":[{"batb":[[0,1.96,30.29]],"ltp":1.99,"tv":578.77,"id":8284479}]}]}
{"op":"mcm","clk":"1005912596","pt":1580645417431,"mc":[{"id":"1.168236368","rc":[{"batb":[[1,1.9,2.53],[2,1.89,50.67]],"ltp":1.94,"tv":559.61,"id":4520808}]}]}
{"op":"mcm","clk":"1005915690","pt":1580645433929,"mc":[{"id":"1.168236368","rc":[{"trd":[[2,118.01]],"batb":[[0,2,10.31],[1,1.91,61.4],[2,1.9,2.53]],"ltp":2.0,"tv":671.54,"id":4520808},{"trd":[[1.99,4.91],[2,219.9]],"batb":[[0,1.97,19.54],[1,1.96,30.29]],"batl":[[0,2.28,18.48]],"ltp":2.0,"tv":603.79,"id":8284479}],"tv":1275.34}]}
{"op":"mcm","clk":"1005916197","pt":1580645436550,"mc":[{"id":"1.168236368","rc":[{"trd":[[2,125.58]],"batb":[[0,2,2.74]],"ltp":2.0,"tv":679.12,"id":4520808},{"trd":[[2,227.47]],"ltp":2.0,"tv":611.36,"id":8284479}],"tv":1290.48}]}
{"op":"mcm","clk":"1005916444","pt":1580645437875,"mc":[{"id":"1.168236368","rc":[{"trd":[[2,128.32]],"batb":[[0,1.91,61.4],[1,1.9,2.53],[2,1.82,289.04]],"ltp":2.0,"tv":681.86,"id":4520808},{"trd":[[2,230.21]],"batb":[[0,2,4.83],[1,1.97,19.54],[2,1.96,30.29]],"ltp":2.0,"tv":614.1,"id":8284479}],"tv":1295.97}]}
{"op":"mcm","clk":"1005916800","pt":1580645439845,"mc":[{"id":"1.168236368","rc":[{"batb":[[0,1.97,19.54],[1,1.96,30.29],[2,1.89,420.1]],"ltp":2.0,"tv":614.1,"id":8284479}]}]}
{"op":"mcm","clk":"1005917281","pt":1580645442771,"mc":[{"id":"1.168236368","rc":[{"batb":[[1,1.89,420.1],[2,1.88,420.1]],"ltp":2.0,"tv":614.1,"id":8284479}]}]}
{"op":"mcm","clk":"1005917625","pt":1580645444745,"mc":[{"id":"1.168236368","rc":[{"batb":[[0,1.98,7.57],[1,1.97,19.54],[2,1.89,420.1]],"ltp":2.0,"tv":614.1,"id":8284479}]}]}
{"op":"mcm","clk":"1005917778","pt":1580645445735,"mc":[{"id":"1.168236368","rc":[{"batb":[[0,1.98,15.14]],"ltp":2.0,"tv":614.1,"id":8284479}]}]}
{"op":"mcm","clk":"1005918945","pt":1580645452390,"mc":[{"id":"1.168236368","rc":[{"batl":[[0,2.06,7.57],[1,2.28,18.48],[2,4.2,153.72]],"ltp":2.0,"tv":614.1,"id":8284479}]}]}
{"op":"mcm","clk":"1005920292","pt":1580645459862,"mc":[{"id":"1.168236368","rc":[{"batb":[[2,1.95,15.14]],"ltp":2.0,"tv":614.1,"id":8284479}]}]}
{"op":"mcm","clk":"1005920382","pt":1580645460398,"mc":[{"id":"1.168236368","rc":[{"batl":[[1,4.2,153.72],[2,95,15.9]],"ltp":2.0,"tv":614.1,"id":8284479}]}]}
{"op":"mcm","clk":"1005921488","pt":1580645465914,"mc":[{"id":"1.168236368","rc":[{"batl":[[0,2.6,74.66],[1,4.2,153.72],[2,95,15.9]],"ltp":2.0,"tv":681.86,"id":4520808},{"trd":[[2.06,37.51]],"batl":[[0,2.06,1.83]],"ltp":2.06,"tv":625.58,"id":8284479}],"tv":1307.45}]}
{"op":"mcm","clk":"1005922101","pt":1580645469313,"mc":[{"id":"1.168236368","rc":[{"batb":[[0,2,7.57],[1,1.98,15.14],[2,1.97,19.54]],"ltp":2.06,"tv":625.58,"id":8284479}]}]}
{"op":"mcm","clk":"1005923630","pt":1580645477529,"mc":[{"id":"1.168236368","rc":[{"batb":[[1,1.97,19.54],[2,1.95,15.14]],"ltp":2.06,"tv":625.58,"id":8284479}]}]}
{"op":"mcm","clk":"1005924206","pt":1580645480716,"mc":[{"id":"1.168236368","rc":[{"batb":[[2,1.96,15.14]],"ltp":2.06,"tv":625.58,"id":8284479}]}]}
{"op":"mcm","clk":"1005924451","pt":1580645482094,"mc":[{"id":"1.168236368","rc":[{"batb":[[2,1.96,30.29]],"ltp":2.06,"tv":625.58,"id":8284479}]}]}
{"op":"mcm","clk":"1005931312","pt":1580645520947,"mc":[{"id":"1.168236368","rc":[{"trd":[[1.91,96.42],[1.94,228.69]],"batb":[[0,1.91,13.19]],"ltp":1.91,"tv":780.23,"id":4520808},{"trd":[[2.06,39.34]],"batl":[[0,4.2,153.72],[1,95,15.9],[2,990,2.2]],"ltp":2.06,"tv":627.42,"id":8284479}],"tv":1407.65}]}
{"op":"mcm","clk":"1005931703","pt":1580645523245,"mc":[{"id":"1.168236368","rc":[{"batb":[[0,1.9,2.53],[1,1.85,60.18]],"ltp":1.91,"tv":780.23,"id":4520808},{"batb":[[0,2.02,33.13],[1,2,7.57]],"ltp":2.06,"tv":627.42,"id":8284479}]}]}
{"op":"mcm","clk":"1005932736","pt":1580645528767,"mc":[{"id":"1.168236368","rc":[{"batb":[[1,1.98,7.57]],"ltp":2.06,"tv":627.42,"id":8284479}]}]}
{"op":"mcm","clk":"1005934560","pt":1580645538894,"mc":[{"id":"1.168236368","rc":[{"batb":[[1,1.89,420.1],[2,1.88,420.1]],"ltp":2.06,"tv":627.42,"id":8284479}]}]}
{"op":"mcm","clk":"1005934787","pt":1580645540083,"mc":[{"id":"1.168236368","rc":[{"batb":[[1,1.96,40.73],[2,1.89,420.1]],"ltp":2.06,"tv":627.42,"id":8284479}]}]}
{"op":"mcm","clk":"1005940062","pt":1580645569418,"mc":[{"id":"1.168236368","rc":[{"batl":[[0,4.1,3.36],[1,4.2,153.72],[2,95,15.9]],"ltp":2.06,"tv":627.42,"id":8284479}]}]}
{"op":"mcm","clk":"1005966919","pt":1580645719212,"mc":[{"id":"1.168236368","rc":[{"batb":[[0,1.96,40.73],[1,1.89,420.1],[2,1.88,420.1]],"ltp":2.06,"tv":627.42,"id":8284479}]}]}
{"op":"mcm","clk":"1005967106","pt":1580645720230,"mc":[{"id":"1.168236368","rc":[{"batl":[[0,2.04,8.46],[1,2.6,74.66],[2,4.2,153.72]],"ltp":1.91,"tv":780.23,"id":4520808},{"batb":[[0,1.98,58.81],[1,1.97,6.81],[2,1.96,40.73]],"ltp":2.06,"tv":627.42,"id":8284479}]}]}
{"op":"mcm","clk":"1005971014","pt":1580645741945,"mc":[{"id":"1.168236368","rc":[{"batb":[[0,1.94,37.86],[1,1.9,2.53],[2,1.85,60.18]],"ltp":1.91,"tv":780.23,"id":4520808}]}]}
{"op":"mcm","clk":"1005975391","pt":1580645766569,"mc":[{"id":"1.168236368","rc":[{"batb":[[0,1.9,2.53],[1,1.85,60.18],[2,1.82,289.04]],"ltp":1.91,"tv":780.23,"id":4520808}]}]}
{"op":"mcm","clk":"1005984437","pt":1580645819223,"mc":[{"id":"1.168236368","rc":[{"batb":[[0,1.99,15.14],[1,1.98,58.81],[2,1.97,6.81]],"ltp":2.06,"tv":627.42,"id":8284479}]}]}
{"op":"mcm","clk":"1005985128","pt":1580645823549,"mc":[{"id":"1.168236368","rc":[{"batl":[[0,2.6,74.66],[1,4.2,153.72],[2,95,15.9]],"ltp":1.91,"tv":780.23,"id":4520808}]}]}
{"op":"mcm","clk":"1005985465","pt":1580645825448,"mc":[{"id":"1.168236368","rc":[{"batb":[[2,1.89,420.1]],"ltp":2.06,"tv":627.42,"id":8284479}]}]}
{"op":"mcm","clk":"1005990738","pt":1580645856452,"mc":[{"id":"1.168236368","rc":[{"batb":[[0,2,45.74],[1,1.99,15.14]],"ltp":2.06,"tv":627.42,"id":8284479}]}]}
{"op":"mcm","clk":"1005990893","pt":1580645857248,"mc":[{"id":"1.168236368","rc":[{"batb":[[1,1.99,22.72]],"ltp":2.06,"tv":627.42,"id":8284479}]}]}
{"op":"mcm","clk":"1005991108","pt":1580645858428,"mc":[{"id":"1.168236368","rc":[{"batb":[[1,1.89,420.1],[2,1.88,420.1]],"ltp":2.06,"tv":627.42,"id":8284479}]}]}
{"op":"mcm","clk":"1005991746","pt":1580645862223,"mc":[{"id":"1.168236368","rc":[{"batb":[[1,1.96,15.14],[2,1.89,420.1]],"ltp":2.06,"tv":627.42,"id":8284479}]}]}
{"op":"mcm","clk":"1005991778","pt":1580645862428,"mc":[{"id":"1.168236368","rc":[{"batb":[[1,1.96,22.72]],"ltp":2.06,"tv":627.42,"id":8284479}]}]}
{"op":"mcm","clk":"1005991998","pt":1580645863716,"mc":[{"id":"1.168236368","rc":[{"batb":[[1,1.96,37.86]],"ltp":2.06,"tv":627.42,"id":8284479}]}]}
{"op":"mcm","clk":"1006000528","pt":1580645911862,"mc":[{"id":"1.168236368","rc":[{"batb":[[0,2.02,7.57],[1,2,45.74],[2,1.96,37.86]],"ltp":2.06,"tv":627.42,"id":8284479}]}]}
{"op":"mcm","clk":"1006000737","pt":1580645913066,"mc":[{"id":"1.168236368","rc":[{"batl":[[0,2.04,8.46],[1,2.6,74.66],[2,4.2,153.72]],"ltp":1.91,"tv":780.23,"id":4520808}]}]}
{"op":"mcm","clk":"1006002873","pt":1580645925965,"mc":[{"id":"1.168236368","rc":[{"batb":[[0,2.04,7.57],[1,2.02,7.57],[2,2,45.74]],"ltp":2.06,"tv":627.42,"id":8284479}]}]}
{"op":"mcm","clk":"1006003554","pt":1580645929795,"mc":[{"id":"1.168236368","rc":[{"batb":[[1,2.02,22.72]],"ltp":2.06,"tv":627.42,"id":8284479}]}]}
{"op":"mcm","clk":"1006003786","pt":1580645931155,"mc":[{"id":"1.168236368","rc":[{"batb":[[0,2.02,22.72],[1,2,45.74],[2,1.96,37.86]],"ltp":2.06,"tv":627.42,"id":8284479}]}]}
{"op":"mcm","clk":"1006004123","pt":1580645933061,"mc":[{"id":"1.168236368","rc":[{"batb":[[2,1.89,420.1]],"ltp":2.06,"tv":627.42,"id":8284479}]}]}
{"op":"mcm","clk":"1006004387","pt":1580645934789,"mc":[{"id":"1.168236368","rc":[{"batl":[[0,2.6,74.66],[1,4.2,153.72],[2,95,15.9]],"ltp":1.91,"tv":780.23,"id":4520808}]}]}
{"op":"mcm","clk":"1006005580","pt":1580645942107,"mc":[{"id":"1.168236368","rc":[{"batb":[[0,2.02,7.57]],"ltp":2.06,"tv":627.42,"id":8284479}]}]}
{"op":"mcm","clk":"1006005654","pt":1580645942383,"mc":[{"id":"1.168236368","rc":[{"batb":[[0,2.02,15.14]],"ltp":2.06,"tv":627.42,"id":8284479}]}]}
{"op":"mcm","clk":"1006006032","pt":1580645944579,"mc":[{"id":"1.168236368","rc":[{"batb":[[1,2,60.88]],"ltp":2.06,"tv":627.42,"id":8284479}]}]}
{"op":"mcm","clk":"1006006277","pt":1580645945789,"mc":[{"id":"1.168236368","rc":[{"batb":[[0,2,60.88],[1,1.89,420.1],[2,1.88,420.1]],"ltp":2.06,"tv":627.42,"id":8284479}]}]}
{"op":"mcm","clk":"1006007301","pt":1580645951907,"mc":[{"id":"1.168236368","rc":[{"batb":[[1,1.85,110.16]],"ltp":1.91,"tv":780.23,"id":4520808}]}]}
{"op":"mcm","clk":"1006007490","pt":1580645952909,"mc":[{"id":"1.168236368","rc":[{"batb":[[2,1.83,285.56]],"ltp":1.91,"tv":780.23,"id":4520808}]}]}
{"op":"mcm","clk":"1006008233","pt":1580645957234,"mc":[{"id":"1.168236368","rc":[{"batb":[[1,1.85,60.18],[2,1.83,335.54]],"ltp":1.91,"tv":780.23,"id":4520808}]}]}
{"op":"mcm","clk":"1006009832","pt":1580645967010,"mc":[{"id":"1.168236368","rc":[{"batb":[[0,2,45.74]],"ltp":2.06,"tv":627.42,"id":8284479}]}]}
{"op":"mcm","clk":"1006010129","pt":1580645968914,"mc":[{"id":"1.168236368","rc":[{"batb":[[1,1.98,22.72],[2,1.89,420.1]],"ltp":2.06,"tv":627.42,"id":8284479}]}]}
{"op":"mcm","clk":"1006013675","pt":1580645990540,"mc":[{"id":"1.168236368","rc":[{"batb":[[0,2.02,7.57],[1,2,45.74],[2,1.98,22.72]],"ltp":2.06,"tv":627.42,"id":8284479}]}]}
{"op":"mcm","clk":"1006013942","pt":1580645992073,"mc":[{"id":"1.168236368","rc":[{"batb":[[2,1.89,420.1]],"ltp":2.06,"tv":627.42,"id":8284479}]}]}
{"op":"mcm","clk":"1006014056","pt":1580645992652,"mc":[{"id":"1.168236368","rc":[{"batb":[[1,1.98,58.81]],"ltp":2.06,"tv":627.42,"id":8284479}]}]}
{"op":"mcm","clk":"1006014196","pt":1580645993553,"mc":[{"id":"1.168236368","rc":[{"batb":[[2,1.97,15.14]],"ltp":2.06,"tv":627.42,"id":8284479}]}]}
{"op":"mcm","clk":"1006014389","pt":1580645994846,"mc":[{"id":"1.168236368","rc":[{"batb":[[1,1.99,15.14],[2,1.98,58.81]],"ltp":2.06,"tv":627.42,"id":8284479}]}]}
{"op":"mcm","clk":"1006014477","pt":1580645995365,"mc":[{"id":"1.168236368","rc":[{"batl":[[0,2.02,8.54],[1,2.6,74.66],[2,4.2,153.72]],"ltp":1.91,"tv":780.23,"id":4520808},{"batb":[[2,1.98,65.59]],"ltp":2.06,"tv":627.42,"id":8284479}]}]}
{"op":"mcm","clk":"1006014708","pt":1580645996677,"mc":[{"id":"1.168236368","rc":[{"batb":[[0,1.99,15.14],[1,1.98,65.59],[2,1.97,15.14]],"ltp":2.06,"tv":627.42,"id":8284479}]}]}
{"op":"mcm","clk":"1006015111","pt":1580645998961,"mc":[{"id":"1.168236368","rc":[{"batb":[[0,1.99,22.72],[2,1.89,420.1]],"ltp":2.06,"tv":627.42,"id":8284479}]}]}
{"op":"mcm","clk":"1006025105","pt":1580646055018,"mc":[{"id":"1.168236368","rc":[{"batb":[[0,1.99,30.29]],"ltp":2.06,"tv":627.42,"id":8284479}]}]}
{"op":"mcm","clk":"1006025769","pt":1580646058768,"mc":[{"id":"1.168236368","rc":[{"batb":[[0,1.98,65.59],[1,1.89,420.1],[2,1.88,420.1]],"ltp":2.06,"tv":627.42,"id":8284479}]}]}
{"op":"mcm","clk":"1006025979","pt":1580646059923,"mc":[{"id":"1.168236368","rc":[{"batl":[[0,2.6,74.66],[1,4.2,153.72],[2,95,15.9]],"ltp":1.91,"tv":780.23,"id":4520808},{"batb":[[0,1.99,40.12],[1,1.98,58.81],[2,1.89,420.1]],"ltp":2.06,"tv":627.42,"id":8284479}]}]}
{"op":"mcm","clk":"1006026356","pt":1580646061948,"mc":[{"id":"1.168236368","rc":[{"batb":[[0,1.99,6.75]],"ltp":2.06,"tv":627.42,"id":8284479}]}]}
{"op":"mcm","clk":"1006026610","pt":1580646063123,"mc":[{"id":"1.168236368","rc":[{"batb":[[0,1.99,29.46]],"ltp":2.06,"tv":627.42,"id":8284479}]}]}
{"op":"mcm","clk":"1006026645","pt":1580646063335,"mc":[{"id":"1.168236368","rc":[{"batb":[[0,1.99,22.72]],"ltp":2.06,"tv":627.42,"id":8284479}]}]}
{"op":"mcm","clk":"1006026963","pt":1580646065135,"mc":[{"id":"1.168236368","rc":[{"batb":[[0,1.99,37.86]],"ltp":2.06,"tv":627.42,"id":8284479}]}]}
{"op":"mcm","clk":"1006027288","pt":1580646066965,"mc":[{"id":"1.168236368","rc":[{"batb":[[0,1.98,58.81],[1,1.89,420.1],[2,1.88,420.1]],"ltp":2.06,"tv":627.42,"id":8284479}]}]}
{"op":"mcm","clk":"1006027453","pt":1580646067870,"mc":[{"id":"1.168236368","rc":[{"batb":[[0,1.99,22.72],[1,1.98,58.81],[2,1.89,420.1]],"ltp":2.06,"tv":627.42,"id":8284479}]}]}
{"op":"mcm","clk":"1006027710","pt":1580646069343,"mc":[{"id":"1.168236368","rc":[{"batb":[[0,1.99,30.29]],"ltp":2.06,"tv":627.42,"id":8284479}]}]}
{"op":"mcm","clk":"1006028542","pt":1580646073982,"mc":[{"id":"1.168236368","rc":[{"batb":[[0,2.02,7.57],[1,1.99,30.29],[2,1.98,58.81]],"ltp":2.06,"tv":627.42,"id":8284479}]}]}
{"op":"mcm","clk":"1006028870","pt":1580646075775,"mc":[{"id":"1.168236368","rc":[{"batb":[[0,1.99,30.29],[1,1.98,58.81],[2,1.89,420.1]],"ltp":2.06,"tv":627.42,"id":8284479}]}]}
{"op":"mcm","clk":"1006037955","pt":1580646124818,"mc":[{"id":"1.168236368","rc":[{"batb":[[0,2,45.74],[1,1.99,30.29]],"ltp":2.06,"tv":627.42,"id":8284479}]}]}
{"op":"mcm","clk":"1006038437","pt":1580646127628,"mc":[{"id":"1.168236368","rc":[{"batb":[[0,2.02,7.57],[1,2,45.74],[2,1.99,30.29]],"ltp":2.06,"tv":627.42,"id":8284479}]}]}
{"op":"mcm","clk":"1006038801","pt":1580646129646,"mc":[{"id":"1.168236368","rc":[{"batb":[[2,1.89,420.1]],"ltp":2.06,"tv":627.42,"id":8284479}]}]}
{"op":"mcm","clk":"1006041517","pt":1580646145137,"mc":[{"id":"1.168236368","rc":[{"batb":[[2,1.98,15.14]],"ltp":2.06,"tv":627.42,"id":8284479}]}]}
{"op":"mcm","clk":"1006061060","pt":1580646258227,"mc":[{"id":"1.168236368","rc":[{"batb":[[1,1.99,52.22]],"ltp":2.06,"tv":627.42,"id":8284479}]}]}
{"op":"mcm","clk":"1006154796","pt":1580646797180,"mc":[{"id":"1.168236368","rc":[{"trd":[[2.02,4]],"batb":[[0,2.02,5.57]],"ltp":2.02,"tv":631.42,"id":8284479}],"tv":1411.65}]}
{"op":"mcm","clk":"1006160023","pt":1580646826631,"mc":[{"id":"1.168236368","rc":[{"batb":[[0,2.02,13.15]],"ltp":2.02,"tv":631.42,"id":8284479}]}]}
{"op":"mcm","clk":"1006160685","pt":1580646830050,"mc":[{"id":"1.168236368","rc":[{"batb":[[2,1.97,15.14]],"ltp":2.02,"tv":631.42,"id":8284479}]}]}
{"op":"mcm","clk":"1006180659","pt":1580646934134,"mc":[{"id":"1.168236368","rc":[{"batb":[[1,1.98,58.81]],"ltp":2.02,"tv":631.42,"id":8284479}]}]}
{"op":"mcm","clk":"1006180940","pt":1580646935526,"mc":[{"id":"1.168236368","rc":[{"batl":[[0,2.02,8.54],[1,2.6,74.66],[2,4.2,153.72]],"ltp":1.91,"tv":780.23,"id":4520808}]}]}
{"op":"mcm","clk":"1006261451","pt":1580647338445,"mc":[{"id":"1.168236368","rc":[{"batb":[[0,1.99,13.15]],"ltp":2.02,"tv":631.42,"id":8284479}]}]}
{"op":"mcm","clk":"1006261709","pt":1580647339816,"mc":[{"id":"1.168236368","rc":[{"batb":[[1,1.98,65.59]],"ltp":2.02,"tv":631.42,"id":8284479}]}]}
{"op":"mcm","clk":"1006261973","pt":1580647341047,"mc":[{"id":"1.168236368","rc":[{"batb":[[2,1.89,420.1]],"ltp":2.02,"tv":631.42,"id":8284479}]}]}
{"op":"mcm","clk":"1006262323","pt":1580647342927,"mc":[{"id":"1.168236368","rc":[{"batl":[[0,2.6,74.66],[1,4.2,153.72],[2,95,15.9]],"ltp":1.91,"tv":780.23,"id":4520808},{"batb":[[1,1.98,58.81]],"ltp":2.02,"tv":631.42,"id":8284479}]}]}
{"op":"mcm","clk":"1006285036","pt":1580647459075,"mc":[{"id":"1.168236368","rc":[{"batb":[[0,2,45.74],[1,1.99,13.15]],"ltp":2.02,"tv":631.42,"id":8284479}]}]}
{"op":"mcm","clk":"1006314187","pt":1580647620827,"mc":[{"id":"1.168236368","rc":[{"batb":[[1,1.89,420.1],[2,1.88,420.1]],"ltp":2.02,"tv":631.42,"id":8284479}]}]}
{"op":"mcm","clk":"1006329045","pt":1580647714366,"mc":[{"id":"1.168236368","rc":[{"batb":[[1,1.96,38.67],[2,1.89,420.1]],"ltp":2.02,"tv":631.42,"id":8284479}]}]}
{"op":"mcm","clk":"1006330429","pt":1580647723600,"mc":[{"id":"1.168236368","rc":[{"batb":[[0,1.98,58.81]],"ltp":2.02,"tv":631.42,"id":8284479}]}]}
{"op":"mcm","clk":"1006330627","pt":1580647724715,"mc":[{"id":"1.168236368","rc":[{"batl":[[0,2.04,8.46],[1,2.6,74.66],[2,4.2,153.72]],"ltp":1.91,"tv":780.23,"id":4520808},{"batb":[[1,1.97,6.81],[2,1.96,38.67]],"ltp":2.02,"tv":631.42,"id":8284479}]}]}
{"op":"mcm","clk":"1006330893","pt":1580647726365,"mc":[{"id":"1.168236368","rc":[{"batb":[[0,1.99,7.57],[1,1.98,58.81],[2,1.97,6.81]],"ltp":2.02,"tv":631.42,"id":8284479}]}]}
{"op":"mcm","clk":"1006331846","pt":1580647733085,"mc":[{"id":"1.168236368","rc":[{"batl":[[0,2.6,74.66],[1,4.2,153.72],[2,95,15.9]],"ltp":1.91,"tv":780.23,"id":4520808},{"batb":[[2,1.89,420.1]],"ltp":2.02,"tv":631.42,"id":8284479}]}]}
{"op":"mcm","clk":"1006351219","pt":1580647859959,"mc":[{"id":"1.168236368","rc":[{"batb":[[0,2,45.74],[1,1.99,7.57]],"ltp":2.02,"tv":631.42,"id":8284479}]}]}
{"op":"mcm","clk":"1006356371","pt":1580647893890,"mc":[{"id":"1.168236368","rc":[{"batb":[[1,1.89,420.1],[2,1.88,420.1]],"ltp":2.02,"tv":631.42,"id":8284479}]}]}
{"op":"mcm","clk":"1006356874","pt":1580647897401,"mc":[{"id":"1.168236368","rc":[{"batb":[[0,2.02,7.57],[1,2,45.74],[2,1.89,420.1]],"ltp":2.02,"tv":631.42,"id":8284479}]}]}
{"op":"mcm","clk":"1006364890","pt":1580647957238,"mc":[{"id":"1.168236368","rc":[{"batb":[[2,1.96,15.14]],"ltp":2.02,"tv":631.42,"id":8284479}]}]}
{"op":"mcm","clk":"1006364909","pt":1580647957442,"mc":[{"id":"1.168236368","rc":[{"batb":[[2,1.96,22.72]],"ltp":2.02,"tv":631.42,"id":8284479}]}]}
{"op":"mcm","clk":"1006371062","pt":1580648000784,"mc":[{"id":"1.168236368","rc":[{"batb":[[1,1.98,58.81]],"ltp":2.02,"tv":631.42,"id":8284479}]}]}
{"op":"mcm","clk":"1006371189","pt":1580648001800,"mc":[{"id":"1.168236368","rc":[{"batl":[[0,2.04,8.46],[1,2.6,74.66],[2,4.2,153.72]],"ltp":1.91,"tv":780.23,"id":4520808},{"batb":[[2,1.97,6.81]],"ltp":2.02,"tv":631.42,"id":8284479}]}]}
{"op":"mcm","clk":"1006371865","pt":1580648007006,"mc":[{"id":"1.168236368","rc":[{"batb":[[0,1.91,420.1],[1,1.9,2.53],[2,1.85,60.18]],"ltp":1.91,"tv":780.23,"id":4520808}]}]}
{"op":"mcm","clk":"1006372231","pt":1580648009635,"mc":[{"id":"1.168236368","rc":[{"batb":[[1,1.9,422.63]],"ltp":1.91,"tv":780.23,"id":4520808}]}]}
{"op":"mcm","clk":"1006372654","pt":1580648012438,"mc":[{"id":"1.168236368","rc":[{"batb":[[2,1.89,420.1]],"ltp":1.91,"tv":780.23,"id":4520808}]}]}
{"op":"mcm","clk":"1006373477","pt":1580648018037,"mc":[{"id":"1.168236368","rc":[{"batb":[[1,1.99,22.72],[2,1.98,58.81]],"ltp":2.02,"tv":631.42,"id":8284479}]}]}
{"op":"mcm","clk":"1006373768","pt":1580648019815,"mc":[{"id":"1.168236368","rc":[{"batl":[[0,2,369.69],[1,2.04,8.46],[2,2.6,74.66]],"ltp":1.91,"tv":780.23,"id":4520808},{"batb":[[1,1.99,37.04]],"ltp":2.02,"tv":631.42,"id":8284479}]}]}
{"op":"mcm","clk":"1006373951","pt":1580648021040,"mc":[{"id":"1.168236368","rc":[{"batl":[[1,2.6,74.66],[2,4.2,153.72]],"ltp":1.91,"tv":780.23,"id":4520808},{"batb":[[1,1.99,30.29]],"ltp":2.02,"tv":631.42,"id":8284479}]}]}
{"op":"mcm","clk":"1006374305","pt":1580648023409,"mc":[{"id":"1.168236368","rc":[{"batb":[[1,1.98,58.81],[2,1.82,289.04]],"ltp":2.02,"tv":631.42,"id":8284479}]}]}
{"op":"mcm","clk":"1006374961","pt":1580648027747,"mc":[{"id":"1.168236368","rc":[{"batb":[[1,1.98,81.52]],"ltp":2.02,"tv":631.42,"id":8284479}]}]}
{"op":"mcm","clk":"1006375210","pt":1580648029304,"mc":[{"id":"1.168236368","rc":[{"batb":[[0,2.02,15.14]],"ltp":2.02,"tv":631.42,"id":8284479}]}]}
{"op":"mcm","clk":"1006375346","pt":1580648030259,"mc":[{"id":"1.168236368","rc":[{"trd":[[1.91,218.42]],"batb":[[0,1.91,359.1]],"ltp":1.91,"tv":902.23,"id":4520808}],"tv":1533.65}]}
{"op":"mcm","clk":"1006375657","pt":1580648032330,"mc":[{"id":"1.168236368","rc":[{"batl":[[0,1.99,8.67],[1,2,369.69],[2,2.6,74.66]],"ltp":1.91,"tv":902.23,"id":4520808}]}]}
{"op":"mcm","clk":"1006378152","pt":1580648049779,"mc":[{"id":"1.168236368","rc":[{"batb":[[0,2.02,21.79]],"ltp":2.02,"tv":631.42,"id":8284479}]}]}
{"op":"mcm","clk":"1006385387","pt":1580648100657,"mc":[{"id":"1.168236368","rc":[{"batl":[[0,1.99,17.27]],"ltp":1.91,"tv":902.23,"id":4520808},{"batb":[[0,2.02,30.19]],"ltp":2.02,"tv":631.42,"id":8284479}]}]}
{"op":"mcm","clk":"1006385515","pt":1580648101507,"mc":[{"id":"1.168236368","rc":[{"trd":[[1.91,352.42]],"batb":[[0,1.91,292.1]],"ltp":1.91,"tv":1036.22,"id":4520808}],"tv":1667.64}]}
{"op":"mcm","clk":"1006390331","pt":1580648133967,"mc":[{"id":"1.168236368","rc":[{"batb":[[0,1.91,305.96]],"ltp":1.91,"tv":1036.22,"id":4520808},{"batb":[[0,2.04,20.94],[1,2.02,30.19],[2,1.98,22.72]],"ltp":2.02,"tv":631.42,"id":8284479}]}]}
{"op":"mcm","clk":"1006390432","pt":1580648134662,"mc":[{"id":"1.168236368","rc":[{"trd":[[1.91,500.41]],"batb":[[0,1.91,231.96]],"ltp":1.91,"tv":1184.22,"id":4520808}],"tv":1815.64}]}
{"op":"mcm","clk":"1006435768","pt":1580648474362,"mc":[{"id":"1.168236368","rc":[{"trd":[[1.91,636.41]],"batb":[[0,1.91,163.96]],"ltp":1.91,"tv":1320.22,"id":4520808}],"tv":1951.64}]}
{"op":"mcm","clk":"1006446690","pt":1580648557480,"mc":[{"id":"1.168236368","rc":[{"batb":[[2,1.89,422.1]],"batl":[[0,1.99,19.39],[1,2,371.69]],"ltp":1.91,"tv":1320.22,"id":4520808},{"batb":[[2,2,2]],"batl":[[0,2.14,2.11],[1,2.16,2.22],[2,4.1,3.36]],"ltp":2.02,"tv":631.42,"id":8284479}]}]}
{"op":"mcm","clk":"1006446843","pt":1580648558552,"mc":[{"id":"1.168236368","rc":[{"trd":[[1.91,738.41]],"batb":[[0,1.91,112.96]],"ltp":1.91,"tv":1422.21,"id":4520808}],"tv":2053.64}]}
{"op":"mcm","clk":"1006454161","pt":1580648614899,"mc":[{"id":"1.168236368","rc":[{"trd":[[1.91,814.41]],"batb":[[0,1.91,74.96]],"ltp":1.91,"tv":1498.22,"id":4520808},{"batl":[[2,4.2,153.72]],"ltp":2.02,"tv":631.42,"id":8284479}],"tv":2129.64}]}
{"op":"mcm","clk":"1006464986","pt":1580648695149,"mc":[{"id":"1.168236368","rc":[{"trd":[[1.91,824.41]],"batb":[[0,1.91,69.96]],"batl":[[1,2,369.69]],"ltp":1.91,"tv":1508.22,"id":4520808},{"batl":[[1,4.2,153.72],[2,95,15.9]],"ltp":2.02,"tv":631.42,"id":8284479}],"tv":2139.64}]}
{"op":"mcm","clk":"1006465085","pt":1580648695733,"mc":[{"id":"1.168236368","rc":[{"trd":[[1.91,888.41]],"batb":[[0,1.91,37.96]],"batl":[[1,2,371.69]],"ltp":1.91,"tv":1572.22,"id":4520808},{"batl":[[1,2.16,2.22],[2,4.2,153.72]],"ltp":2.02,"tv":631.42,"id":8284479}],"tv":2203.64}]}
{"op":"mcm","clk":"1006478210","pt":1580648789184,"mc":[{"id":"1.168236368","rc":[{"trd":[[1.91,936.41]],"batb":[[0,1.91,13.96]],"ltp":1.91,"tv":1620.22,"id":4520808}],"tv":2251.64}]}
{"op":"mcm","clk":"1006495916","pt":1580648909233,"mc":[{"id":"1.168236368","rc":[{"trd":[[1.91,959.23]],"batb":[[0,1.91,4.3]],"ltp":1.91,"tv":1643.03,"id":4520808},{"batb":[[0,2.04,19.31]],"batl":[[1,4.2,153.72],[2,95,15.9]],"ltp":2.02,"tv":631.42,"id":8284479}],"tv":2274.46}]}
{"op":"mcm","clk":"1006496040","pt":1580648910142,"mc":[{"id":"1.168236368","rc":[{"batb":[[0,1.9,422.63],[1,1.89,422.1],[2,1.88,2.21]],"ltp":1.91,"tv":1643.03,"id":4520808},{"batl":[[1,2.16,2.16],[2,4.2,153.72]],"ltp":2.02,"tv":631.42,"id":8284479}]}]}
{"op":"mcm","clk":"1006496133","pt":1580648910634,"mc":[{"id":"1.168236368","rc":[{"batb":[[1,1.89,420.1]],"ltp":1.91,"tv":1643.03,"id":4520808},{"batb":[[0,2.04,28.58]],"batl":[[0,2.16,2.16],[1,2.18,2.03]],"ltp":2.02,"tv":631.42,"id":8284479}]}]}
{"op":"mcm","clk":"1006513213","pt":1580649031145,"mc":[{"id":"1.168236368","rc":[{"trd":[[1.9,4]],"batb":[[0,1.9,420.63]],"batl":[[1,2,369.69]],"ltp":1.9,"tv":1647.04,"id":4520808},{"batl":[[1,4.2,153.72],[2,95,15.9]],"ltp":2.02,"tv":631.42,"id":8284479}],"tv":2278.46}]}
{"op":"mcm","clk":"1006513255","pt":1580649031322,"mc":[{"id":"1.168236368","rc":[{"trd":[[1.9,36]],"batb":[[0,1.9,404.63]],"batl":[[1,2,371.69]],"ltp":1.9,"tv":1679.04,"id":4520808},{"batl":[[1,2.18,2.03],[2,4.2,153.72]],"ltp":2.02,"tv":631.42,"id":8284479}],"tv":2310.46}]}
{"op":"mcm","clk":"1006593101","pt":1580649560946,"mc":[{"id":"1.168236368","rc":[{"trd":[[1.9,86.67]],"batb":[[0,1.9,379.28]],"ltp":1.9,"tv":1729.71,"id":4520808}],"tv":2361.13}]}
{"op":"mcm","clk":"1006593179","pt":1580649561477,"mc":[{"id":"1.168236368","rc":[{"trd":[[1.9,148.68]],"batb":[[0,1.9,348.28]],"ltp":1.9,"tv":1791.71,"id":4520808}],"tv":2423.13}]}
{"op":"mcm","clk":"1006599244","pt":1580649604234,"mc":[{"id":"1.168236368","rc":[{"batl":[[1,2,369.69]],"ltp":1.9,"tv":1791.71,"id":4520808},{"batb":[[0,2.06,7.57],[1,2.04,28.58],[2,2.02,32.43]],"batl":[[1,4.2,153.72],[2,95,15.9]],"ltp":2.02,"tv":631.42,"id":8284479}]}]}
{"op":"mcm","clk":"1006599303","pt":1580649604603,"mc":[{"id":"1.168236368","rc":[{"trd":[[1.9,194.67]],"batb":[[0,1.9,325.28]],"batl":[[0,1.97,2.16],[1,1.98,2],[2,1.99,17.27]],"ltp":1.9,"tv":1837.71,"id":4520808},{"batl":[[1,2.18,2],[2,4.2,153.72]],"ltp":2.02,"tv":631.42,"id":8284479}],"tv":2469.13}]}
{"op":"mcm","clk":"1006599748","pt":1580649607909,"mc":[{"id":"1.168236368","rc":[{"batb":[[2,2.02,17.29]],"ltp":2.02,"tv":631.42,"id":8284479}]}]}
{"op":"mcm","clk":"1006599958","pt":1580649609208,"mc":[{"id":"1.168236368","rc":[{"batl":[[0,1.99,19.4],[1,2,371.69],[2,2.6,74.66]],"ltp":1.9,"tv":1837.71,"id":4520808},{"batb":[[0,2.04,28.58],[1,2.02,15.05],[2,2,2]],"ltp":2.02,"tv":631.42,"id":8284479}]}]}
{"op":"mcm","clk":"1006600034","pt":1580649609727,"mc":[{"id":"1.168236368","rc":[{"batl":[[0,1.99,19.52],[2,2.02,2]],"ltp":1.9,"tv":1837.71,"id":4520808}]}]}
{"op":"mcm","clk":"1006600259","pt":1580649611223,"mc":[{"id":"1.168236368","rc":[{"batb":[[0,2.04,36.15]],"ltp":2.02,"tv":631.42,"id":8284479}]}]}
{"op":"mcm","clk":"1006600318","pt":1580649611624,"mc":[{"id":"1.168236368","rc":[{"batl":[[1,2.18,2.03]],"ltp":2.02,"tv":631.42,"id":8284479}]}]}
{"op":"mcm","clk":"1006600685","pt":1580649614009,"mc":[{"id":"1.168236368","rc":[{"batb":[[1,2.02,30.19]],"ltp":2.02,"tv":631.42,"id":8284479}]}]}
{"op":"mcm","clk":"1006601265","pt":1580649618023,"mc":[{"id":"1.168236368","rc":[{"batl":[[2,2.6,74.66]],"ltp":1.9,"tv":1837.71,"id":4520808}]}]}
{"op":"mcm","clk":"1006601373","pt":1580649618831,"mc":[{"id":"1.168236368","rc":[{"batb":[[0,2.04,28.58]],"ltp":2.02,"tv":631.42,"id":8284479}]}]}
{"op":"mcm","clk":"1006601472","pt":1580649619517,"mc":[{"id":"1.168236368","rc":[{"batb":[[1,2.02,15.05]],"ltp":2.02,"tv":631.42,"id":8284479}]}]}
{"op":"mcm","clk":"1006602953","pt":1580649630133,"mc":[{"id":"1.168236368","rc":[{"batb":[[0,2.04,36.15]],"ltp":2.02,"tv":631.42,"id":8284479}]}]}
{"op":"mcm","clk":"1006621670","pt":1580649762161,"mc":[{"id":"1.168236368","rc":[{"batl":[[1,2,369.69]],"ltp":1.9,"tv":1837.71,"id":4520808},{"batb":[[0,2.06,7.57],[1,2.04,36.15],[2,2.02,17.08]],"ltp":2.02,"tv":631.42,"id":8284479}]}]}
{"op":"mcm","clk":"1006621771","pt":1580649762852,"mc":[{"id":"1.168236368","rc":[{"trd":[[1.9,228.67]],"batb":[[0,1.9,308.28]],"batl":[[0,1.97,2.16],[1,1.98,2.13],[2,1.99,17.27]],"ltp":1.9,"tv":1871.71,"id":4520808}],"tv":2503.13}]}
{"op":"mcm","clk":"1006626769","pt":1580649799003,"mc":[{"id":"1.168236368","rc":[{"batb":[[1,2.04,43.72]],"ltp":2.02,"tv":631.42,"id":8284479}]}]}
{"op":"mcm","clk":"1006626908","pt":1580649800029,"mc":[{"id":"1.168236368","rc":[{"trd":[[1.9,254.67]],"batb":[[0,1.9,295.29]],"batl":[[1,1.98,2.2]],"ltp":1.9,"tv":1897.7,"id":4520808},{"batl":[[1,2.18,2]],"ltp":2.02,"tv":631.42,"id":8284479}],"tv":2529.13}]}
{"op":"mcm","clk":"1006629986","pt":1580649821060,"mc":[{"id":"1.168236368","rc":[{"trd":[[1.9,274.67]],"batb":[[0,1.9,285.29]],"ltp":1.9,"tv":1917.7,"id":4520808}],"tv":2549.12}]}
{"op":"mcm","clk":"1006630089","pt":1580649821643,"mc":[{"id":"1.168236368","rc":[{"batl":[[1,1.98,2.15]],"ltp":1.9,"tv":1917.7,"id":4520808}]}]}
{"op":"mcm","clk":"1006640853","pt":1580649894241,"mc":[{"id":"1.168236368","rc":[{"batb":[[0,1.91,4.5],[1,1.9,285.29],[2,1.89,422.15]],"batl":[[0,1.95,3],[1,1.97,2.16],[2,1.98,2.15]],"ltp":1.9,"tv":1917.7,"id":4520808}]}]}
{"op":"mcm","clk":"1006640981","pt":1580649895050,"mc":[{"id":"1.168236368","rc":[{"batl":[[2,1.98,2.25]],"ltp":1.9,"tv":1917.7,"id":4520808},{"batl":[[0,2.14,2.04],[1,2.16,2]],"ltp":2.02,"tv":631.42,"id":8284479}]}]}
{"op":"mcm","clk":"1006652487","pt":1580649972735,"mc":[{"id":"1.168236368","rc":[{"batb":[[1,2.04,28.58]],"batl":[[1,2.16,2.22]],"ltp":2.02,"tv":631.42,"id":8284479}]}]}
{"op":"mcm","clk":"1006652772","pt":1580649974607,"mc":[{"id":"1.168236368","rc":[{"batb":[[1,2.04,36.15]],"ltp":2.02,"tv":631.42,"id":8284479}]}]}
{"op":"mcm","clk":"1006653101","pt":1580649976644,"mc":[{"id":"1.168236368","rc":[{"batb":[[2,2.02,24.65]],"ltp":2.02,"tv":631.42,"id":8284479}]}]}
{"op":"mcm","clk":"1006679559","pt":1580650164144,"mc":[{"id":"1.168236368","rc":[{"batl":[[2,1.99,17.27]],"ltp":1.9,"tv":1917.7,"id":4520808},{"batl":[[1,4.2,153.72],[2,95,15.9]],"ltp":2.02,"tv":631.42,"id":8284479}]}]}
{"op":"mcm","clk":"1006679620","pt":1580650164463,"mc":[{"id":"1.168236368","rc":[{"batl":[[2,1.98,2.02]],"ltp":1.9,"tv":1917.7,"id":4520808},{"batl":[[1,2.16,2.22],[2,4.2,153.72]],"ltp":2.02,"tv":631.42,"id":8284479}]}]}
{"op":"mcm","clk":"1006683712","pt":1580650194194,"mc":[{"id":"1.168236368","rc":[{"batl":[[2,1.98,2.03]],"ltp":1.9,"tv":1917.7,"id":4520808}]}]}
{"op":"mcm","clk":"1006687123","pt":1580650214161,"mc":[{"id":"1.168236368","rc":[{"batl":[[1,4.2,153.72],[2,95,15.9]],"ltp":2.02,"tv":631.42,"id":8284479}]}]}
{"op":"mcm","clk":"1006687146","pt":1580650214328,"mc":[{"id":"1.168236368","rc":[{"batl":[[1,2.16,2.22],[2,4.2,153.72]],"ltp":2.02,"tv":631.42,"id":8284479}]}]}
{"op":"mcm","clk":"1006687392","pt":1580650216033,"mc":[{"id":"1.168236368","rc":[{"batb":[[0,2.04,36.15],[1,2.02,22.62],[2,2,2]],"ltp":2.02,"tv":631.42,"id":8284479}]}]}
{"op":"mcm","clk":"1006688803","pt":1580650227167,"mc":[{"id":"1.168236368","rc":[{"batl":[[2,1.98,2.2]],"ltp":1.9,"tv":1917.7,"id":4520808},{"batl":[[1,2.16,2.1]],"ltp":2.02,"tv":631.42,"id":8284479}]}]}
{"op":"mcm","clk":"1006690834","pt":1580650243065,"mc":[{"id":"1.168236368","rc":[{"batl":[[2,1.99,17.27]],"ltp":1.9,"tv":1917.7,"id":4520808},{"batb":[[0,2.04,43.72]],"batl":[[1,4.2,153.72],[2,95,15.9]],"ltp":2.02,"tv":631.42,"id":8284479}]}]}
{"op":"mcm","clk":"1006690860","pt":1580650243279,"mc":[{"id":"1.168236368","rc":[{"batl":[[2,1.98,2.25]],"ltp":1.9,"tv":1917.7,"id":4520808},{"batl":[[1,2.16,2.16],[2,4.2,153.72]],"ltp":2.02,"tv":631.42,"id":8284479}]}]}
{"op":"mcm","clk":"1006691682","pt":1580650250181,"mc":[{"id":"1.168236368","rc":[{"batb":[[0,2.04,28.58]],"ltp":2.02,"tv":631.42,"id":8284479}]}]}
{"op":"mcm","clk":"1006691741","pt":1580650250691,"mc":[{"id":"1.168236368","rc":[{"batl":[[1,2.16,2.1]],"ltp":2.02,"tv":631.42,"id":8284479}]}]}
{"op":"mcm","clk":"1006699823","pt":1580650303148,"mc":[{"id":"1.168236368","rc":[{"batb":[[0,2.04,36.15]],"ltp":2.02,"tv":631.42,"id":8284479}]}]}
{"op":"mcm","clk":"1006699890","pt":1580650303630,"mc":[{"id":"1.168236368","rc":[{"batl":[[2,1.98,2.07]],"ltp":1.9,"tv":1917.7,"id":4520808},{"batl":[[1,2.16,2.04]],"ltp":2.02,"tv":631.42,"id":8284479}]}]}
{"op":"mcm","clk":"1006755708","pt":1580650692024,"mc":[{"id":"1.168236368","rc":[{"trd":[[2.04,97.79]],"batb":[[0,2.04,19.34]],"ltp":2.04,"tv":665.02,"id":8284479}],"tv":2582.73}]}
{"op":"mcm","clk":"1006755786","pt":1580650692621,"mc":[{"id":"1.168236368","rc":[{"batb":[[0,1.91,28]],"batl":[[2,1.98,2.25]],"ltp":1.9,"tv":1917.7,"id":4520808},{"batb":[[0,2.04,7.57],[1,2.02,46.67]],"batl":[[1,2.16,2.1]],"ltp":2.04,"tv":665.02,"id":8284479}]}]}
{"op":"mcm","clk":"1006762048","pt":1580650735092,"mc":[{"id":"1.168236368","rc":[{"batl":[[2,1.99,17.27]],"ltp":1.9,"tv":1917.7,"id":4520808},{"trd":[[2.04,107.87]],"batb":[[0,2.04,2.53]],"batl":[[1,4.2,153.72],[2,95,15.9]],"ltp":2.04,"tv":675.11,"id":8284479}],"tv":2592.82}]}
{"op":"mcm","clk":"1006762189","pt":1580650735907,"mc":[{"id":"1.168236368","rc":[{"trd":[[1.91,1007.23]],"batb":[[0,1.91,4]],"batl":[[2,1.98,2.25]],"ltp":1.91,"tv":1965.7,"id":4520808},{"batl":[[1,2.16,2.16],[2,4.2,153.72]],"ltp":2.04,"tv":675.11,"id":8284479}],"tv":2640.82}]}
{"op":"mcm","clk":"1006762705","pt":1580650739205,"mc":[{"id":"1.168236368","rc":[{"batb":[[0,1.9,285.29],[1,1.89,422.15],[2,1.88,2.21]],"ltp":1.91,"tv":1965.7,"id":4520808},{"batb":[[0,2.04,20.72]],"ltp":2.04,"tv":675.11,"id":8284479}]}]}
{"op":"mcm","clk":"1006762748","pt":1580650739409,"mc":[{"id":"1.168236368","rc":[{"batb":[[1,1.89,420.1]],"ltp":1.91,"tv":1965.7,"id":4520808},{"batl":[[0,2.16,2.16],[1,2.18,2.03]],"ltp":2.04,"tv":675.11,"id":8284479}]}]}
{"op":"mcm","clk":"1006776791","pt":1580650832101,"mc":[{"id":"1.168236368","rc":[{"trd":[[1.9,318.02]],"batb":[[0,1.9,263.61]],"ltp":1.9,"tv":2009.06,"id":4520808}],"tv":2684.17}]}
{"op":"mcm","clk":"1006783629","pt":1580650878085,"mc":[{"id":"1.168236368","rc":[{"batl":[[2,1.99,17.27]],"ltp":1.9,"tv":2009.06,"id":4520808}]}]}
{"op":"mcm","clk":"1006783802","pt":1580650879180,"mc":[{"id":"1.168236368","rc":[{"trd":[[1.9,348.02]],"batb":[[0,1.9,248.61]],"batl":[[2,1.98,2.01]],"ltp":1.9,"tv":2039.06,"id":4520808}],"tv":2714.17}]}
{"op":"mcm","clk":"1006792173","pt":1580650932959,"mc":[{"id":"1.168236368","rc":[{"trd":[[1.9,370.02]],"batb":[[0,1.9,237.62]],"batl":[[2,1.98,2.05]],"ltp":1.9,"tv":2061.06,"id":4520808}],"tv":2736.17}]}
{"op":"mcm","clk":"1006797611","pt":1580650967176,"mc":[{"id":"1.168236368","rc":[{"batl":[[2,1.99,17.27]],"ltp":1.9,"tv":2061.06,"id":4520808},{"batb":[[0,2.04,28.29]],"batl":[[1,4.2,153.72],[2,95,15.9]],"ltp":2.04,"tv":675.11,"id":8284479}]}]}
{"op":"mcm","clk":"1006797649","pt":1580650967403,"mc":[{"id":"1.168236368","rc":[{"trd":[[1.9,386.02]],"batb":[[0,1.9,229.62]],"batl":[[2,1.98,2.22]],"ltp":1.9,"tv":2077.06,"id":4520808},{"batl":[[1,2.18,2],[2,4.2,153.72]],"ltp":2.04,"tv":675.11,"id":8284479}],"tv":2752.17}]}
{"op":"mcm","clk":"1006798010","pt":1580650969592,"mc":[{"id":"1.168236368","rc":[{"batb":[[1,2.02,39.1]],"ltp":2.04,"tv":675.11,"id":8284479}]}]}
{"op":"mcm","clk":"1006827886","pt":1580651158102,"mc":[{"id":"1.168236368","rc":[{"trd":[[1.9,398.02]],"batb":[[0,1.9,223.62]],"batl":[[2,1.99,17.27]],"ltp":1.9,"tv":2089.05,"id":4520808},{"batl":[[1,4.2,153.72],[2,95,15.9]],"ltp":2.04,"tv":675.11,"id":8284479}],"tv":2764.17}]}
{"op":"mcm","clk":"1006827948","pt":1580651158324,"mc":[{"id":"1.168236368","rc":[{"batl":[[2,1.98,2.09]],"ltp":1.9,"tv":2089.05,"id":4520808},{"batl":[[1,2.18,2],[2,4.2,153.72]],"ltp":2.04,"tv":675.11,"id":8284479}]}]}
{"op":"mcm","clk":"1006832815","pt":1580651189211,"mc":[{"id":"1.168236368","rc":[{"batl":[[2,1.98,2.25]],"ltp":1.9,"tv":2089.05,"id":4520808},{"batl":[[1,2.18,2.03]],"ltp":2.04,"tv":675.11,"id":8284479}]}]}
{"op":"mcm","clk":"1006866438","pt":1580651447820,"mc":[{"id":"1.168236368","rc":[{"batl":[[0,1.95,115.44],[2,1.99,17.27]],"ltp":1.9,"tv":2089.05,"id":4520808},{"batl":[[1,4.2,153.72],[2,95,15.9]],"ltp":2.04,"tv":675.11,"id":8284479}]}]}
{"op":"mcm","clk":"1006866587","pt":1580651449011,"mc":[{"id":"1.168236368","rc":[{"batl":[[0,1.94,17.86],[1,1.95,115.44],[2,1.96,2.12]],"ltp":1.9,"tv":2089.05,"id":4520808},{"batb":[[0,2.06,6.52],[1,2.04,28.29],[2,2.02,26.29]],"batl":[[1,2.18,2.03],[2,4.2,153.72]],"ltp":2.04,"tv":675.11,"id":8284479}]}]}
{"op":"mcm","clk":"1006866953","pt":1580651451915,"mc":[{"id":"1.168236368","rc":[{"batb":[[0,2.06,14.09]],"ltp":2.04,"tv":675.11,"id":8284479}]}]}
{"op":"mcm","clk":"1006869747","pt":1580651475106,"mc":[{"id":"1.168236368","rc":[{"batb":[[0,2.06,25.91],[2,2.02,2.24]],"batl":[[1,4.2,153.72],[2,95,15.9]],"ltp":2.04,"tv":675.11,"id":8284479}]}]}
{"op":"mcm","clk":"1006869766","pt":1580651475280,"mc":[{"id":"1.168236368","rc":[{"batl":[[1,2.18,2],[2,4.2,153.72]],"ltp":2.04,"tv":675.11,"id":8284479}]}]}
{"op":"mcm","clk":"1006890316","pt":1580651633914,"mc":[{"id":"1.168236368","rc":[{"batl":[[1,2.18,2.03]],"ltp":2.04,"tv":675.11,"id":8284479}]}]}
{"op":"mcm","clk":"1006940325","pt":1580652003179,"mc":[{"id":"1.168236368","rc":[{"batl":[[0,1.94,8.9]],"ltp":1.9,"tv":2089.05,"id":4520808},{"batl":[[1,4.2,153.72],[2,95,15.9]],"ltp":2.04,"tv":675.11,"id":8284479}]}]}
{"op":"mcm","clk":"1006940384","pt":1580652003360,"mc":[{"id":"1.168236368","rc":[{"batl":[[1,2.18,2.03],[2,4.2,153.72]],"ltp":2.04,"tv":675.11,"id":8284479}]}]}
{"op":"mcm","clk":"1006949356","pt":1580652064520,"mc":[{"id":"1.168236368","rc":[{"batb":[[0,2.06,51.72]],"ltp":2.04,"tv":675.11,"id":8284479}]}]}
{"op":"mcm","clk":"1006949865","pt":1580652068035,"mc":[{"id":"1.168236368","rc":[{"batl":[[1,2.18,2]],"ltp":2.04,"tv":675.11,"id":8284479}]}]}
{"op":"mcm","clk":"1006951917","pt":1580652082062,"mc":[{"id":"1.168236368","rc":[{"batl":[[1,4.2,153.72],[2,95,15.9]],"ltp":2.04,"tv":675.11,"id":8284479}]}]}
{"op":"mcm","clk":"1006951947","pt":1580652082270,"mc":[{"id":"1.168236368","rc":[{"batl":[[1,2.18,2.03],[2,4.2,153.72]],"ltp":2.04,"tv":675.11,"id":8284479}]}]}
{"op":"mcm","clk":"1006954439","pt":1580652099081,"mc":[{"id":"1.168236368","rc":[{"batl":[[0,1.94,76.95]],"ltp":1.9,"tv":2089.05,"id":4520808},{"batl":[[1,4.2,153.72],[2,95,15.9]],"ltp":2.04,"tv":675.11,"id":8284479}]}]}
{"op":"mcm","clk":"1006954471","pt":1580652099294,"mc":[{"id":"1.168236368","rc":[{"batl":[[1,2.18,2.03],[2,4.2,153.72]],"ltp":2.04,"tv":675.11,"id":8284479}]}]}
{"op":"mcm","clk":"1006958861","pt":1580652127242,"mc":[{"id":"1.168236368","rc":[{"batl":[[1,1.95,117.54]],"ltp":1.9,"tv":2089.05,"id":4520808},{"batb":[[0,2.08,7.57],[1,2.06,51.72],[2,2.04,30.4]],"ltp":2.04,"tv":675.11,"id":8284479}]}]}
{"op":"mcm","clk":"1006959181","pt":1580652129212,"mc":[{"id":"1.168236368","rc":[{"batb":[[0,2.06,51.72],[1,2.04,30.4],[2,2.02,2.18]],"ltp":2.04,"tv":675.11,"id":8284479}]}]}
{"op":"mcm","clk":"1006959212","pt":1580652129420,"mc":[{"id":"1.168236368","rc":[{"batl":[[1,1.95,115.44]],"ltp":1.9,"tv":2089.05,"id":4520808},{"batb":[[1,2.04,28.29]],"ltp":2.04,"tv":675.11,"id":8284479}]}]}
{"op":"mcm","clk":"1007028577","pt":1580652529113,"mc":[{"id":"1.168236368","rc":[{"trd":[[1.9,401.82]],"batb":[[0,1.9,221.72]],"ltp":1.9,"tv":2092.85,"id":4520808}],"tv":2767.97}]}
{"op":"mcm","clk":"1007028701","pt":1580652529701,"mc":[{"id":"1.168236368","rc":[{"trd":[[1.9,413.82]],"batb":[[0,1.9,215.72]],"ltp":1.9,"tv":2104.85,"id":4520808}],"tv":2779.97}]}
{"op":"mcm","clk":"1007056187","pt":1580652687152,"mc":[{"id":"1.168236368","rc":[{"trd":[[1.94,305.65],[1.95,115.7],[1.96,198.33],[1.97,107.86]],"batl":[[0,2,369.69],[1,2.6,74.66],[2,4.2,153.72]],"ltp":1.97,"tv":2301.39,"id":4520808},{"trd":[[2.02,10.32],[2.04,276.82],[2.06,215.24]],"batb":[[0,2,2],[1,1.85,26.72],[2,1.83,337.05]],"batl":[[0,2.16,2.19]],"ltp":2.02,"tv":1026.28,"id":8284479}],"tv":3327.67}]}
{"op":"mcm","clk":"1007056371","pt":1580652688234,"mc":[{"id":"1.168236368","rc":[{"trd":[[1.9,691.82]],"batb":[[0,1.92,2.69],[1,1.91,2.51],[2,1.9,76.72]],"ltp":1.9,"tv":2579.39,"id":4520808},{"batb":[[0,1.85,26.72],[1,1.83,337.05],[2,1.81,37.86]],"batl":[[0,2.12,2.21],[1,2.14,2.25],[2,2.16,2.16]],"ltp":2.02,"tv":1026.28,"id":8284479}],"tv":3605.67}]}
{"op":"mcm","clk":"1007056516","pt":1580652689132,"mc":[{"id":"1.168236368","rc":[{"batb":[[0,1.9,76.72],[1,1.89,420.1],[2,1.88,2.96]],"ltp":1.9,"tv":2579.39,"id":4520808},{"batl":[[0,2.14,2.25],[1,2.16,2.22],[2,2.18,2.03]],"ltp":2.02,"tv":1026.28,"id":8284479}]}]}
{"op":"mcm","clk":"1007056559","pt":1580652689423,"mc":[{"id":"1.168236368","rc":[{"batl":[[0,2.16,2.22],[1,2.18,2.03],[2,4.2,153.72]],"ltp":2.02,"tv":1026.28,"id":8284479}]}]}
{"op":"mcm","clk":"1007057082","pt":1580652692148,"mc":[{"id":"1.168236368","rc":[{"batb":[[0,1.91,109.19],[1,1.9,76.72],[2,1.89,420.1]],"ltp":1.9,"tv":2579.39,"id":4520808},{"batb":[[0,1.92,122.16],[1,1.85,26.72],[2,1.83,337.05]],"ltp":2.02,"tv":1026.28,"id":8284479}]}]}
{"op":"mcm","clk":"1007057148","pt":1580652692428,"mc":[{"id":"1.168236368","rc":[{"batb":[[2,1.89,422.7]],"ltp":1.9,"tv":2579.39,"id":4520808},{"batl":[[0,2.14,2.18],[1,2.16,2.22],[2,2.18,2.03]],"ltp":2.02,"tv":1026.28,"id":8284479}]}]}
{"op":"mcm","clk":"1007057758","pt":1580652696054,"mc":[{"id":"1.168236368","rc":[{"batb":[[0,2.02,7.57],[1,1.92,122.16],[2,1.85,26.72]],"ltp":2.02,"tv":1026.28,"id":8284479}]}]}
{"op":"mcm","clk":"1007057861","pt":1580652696542,"mc":[{"id":"1.168236368","rc":[{"trd":[[2.02,25.46]],"batb":[[0,1.92,122.16],[1,1.85,26.72],[2,1.83,337.05]],"batl":[[1,2.16,2.16],[2,4.2,153.72]],"ltp":2.02,"tv":1041.42,"id":8284479}],"tv":3620.81}]}
{"op":"mcm","clk":"1007058502","pt":1580652700154,"mc":[{"id":"1.168236368","rc":[{"batl":[[0,2.06,7.57],[1,2.14,2.18],[2,2.16,2.16]],"ltp":2.02,"tv":1041.42,"id":8284479}]}]}
{"op":"mcm","clk":"1007058641","pt":1580652700956,"mc":[{"id":"1.168236368","rc":[{"batb":[[0,1.92,2.69],[1,1.91,112.03],[2,1.9,76.72]],"ltp":1.9,"tv":2579.39,"id":4520808},{"batl":[[1,2.1,2.05],[2,2.12,2.21]],"ltp":2.02,"tv":1041.42,"id":8284479}]}]}
{"op":"mcm","clk":"1007059777","pt":1580652707153,"mc":[{"id":"1.168236368","rc":[{"batb":[[0,1.91,109.19],[1,1.9,79.38],[2,1.89,422.97]],"ltp":1.9,"tv":2579.39,"id":4520808},{"batl":[[0,2.14,2.25],[1,4.2,153.72],[2,95,15.9]],"ltp":2.02,"tv":1041.42,"id":8284479}]}]}
{"op":"mcm","clk":"1007059880","pt":1580652707765,"mc":[{"id":"1.168236368","rc":[{"batb":[[1,1.9,76.72]],"ltp":1.9,"tv":2579.39,"id":4520808},{"batb":[[0,2.02,14.51],[1,1.92,122.16],[2,1.85,26.72]],"batl":[[1,2.16,2.1],[2,4.2,153.72]],"ltp":2.02,"tv":1041.42,"id":8284479}]}]}
{"op":"mcm","clk":"1007059990","pt":1580652708405,"mc":[{"id":"1.168236368","rc":[{"trd":[[2.02,54.48]],"batb":[[0,1.92,122.16],[1,1.85,26.72],[2,1.83,337.05]],"ltp":2.02,"tv":1070.44,"id":8284479}],"tv":3649.83}]}
{"op":"mcm","clk":"1007060279","pt":1580652710106,"mc":[{"id":"1.168236368","rc":[{"batb":[[0,1.92,2.94],[1,1.91,111.7],[2,1.9,76.72]],"ltp":1.9,"tv":2579.39,"id":4520808},{"batl":[[0,2.06,7.57],[1,2.1,2.05],[2,2.12,2.13]],"ltp":2.02,"tv":1070.44,"id":8284479}]}]}
{"op":"mcm","clk":"1007061171","pt":1580652715099,"mc":[{"id":"1.168236368","rc":[{"batl":[[0,2.04,7.57],[1,2.06,7.57],[2,2.08,2.19]],"ltp":2.02,"tv":1070.44,"id":8284479}]}]}
{"op":"mcm","clk":"1007061351","pt":1580652716196,"mc":[{"id":"1.168236368","rc":[{"batb":[[0,1.94,2.92],[1,1.93,2.79],[2,1.91,109.19]],"ltp":1.9,"tv":2579.39,"id":4520808},{"trd":[[2.04,289.82]],"batl":[[0,2.04,1.08],[2,2.1,2.05]],"ltp":2.04,"tv":1083.43,"id":8284479}],"tv":3662.83}]}
{"op":"mcm","clk":"1007061517","pt":1580652717108,"mc":[{"id":"1.168236368","rc":[{"batb":[[0,1.92,3.19],[1,1.91,112.03],[2,1.9,79.58]],"ltp":1.9,"tv":2579.39,"id":4520808}]}]}
{"op":"mcm","clk":"1007061692","pt":1580652718003,"mc":[{"id":"1.168236368","rc":[{"batb":[[0,2.02,7.57],[1,1.92,122.16],[2,1.85,26.72]],"ltp":2.04,"tv":1083.43,"id":8284479}]}]}
{"op":"mcm","clk":"1007061783","pt":1580652718496,"mc":[{"id":"1.168236368","rc":[{"trd":[[2.02,68.41],[2.04,293.18]],"batb":[[0,1.92,122.77],[1,1.85,26.72],[2,1.83,337.05]],"batl":[[0,2.06,7.57],[1,2.1,2.05],[2,2.12,2.21]],"ltp":2.02,"tv":1100.73,"id":8284479}],"tv":3680.12}]}
{"op":"mcm","clk":"1007062170","pt":1580652720790,"mc":[{"id":"1.168236368","rc":[{"batb":[[0,1.94,2.59],[1,1.93,3.08],[2,1.92,3.19]],"ltp":1.9,"tv":2579.39,"id":4520808},{"batl":[[0,2.04,7.57],[1,2.06,7.57],[2,2.08,2.19]],"ltp":2.02,"tv":1100.73,"id":8284479}]}]}
{"op":"mcm","clk":"1007062715","pt":1580652724023,"mc":[{"id":"1.168236368","rc":[{"batl":[[1,2.08,2.19],[2,2.1,2.05]],"ltp":2.02,"tv":1100.73,"id":8284479}]}]}
{"op":"mcm","clk":"1007062931","pt":1580652725226,"mc":[{"id":"1.168236368","rc":[{"batb":[[2,1.91,109.19]],"ltp":1.9,"tv":2579.39,"id":4520808},{"batb":[[0,1.92,122.16]],"batl":[[0,2.08,2.19],[1,2.1,2.05],[2,4.2,153.72]],"ltp":2.02,"tv":1100.73,"id":8284479}]}]}
{"op":"mcm","clk":"1007063077","pt":1580652726119,"mc":[{"id":"1.168236368","rc":[{"batb":[[0,1.92,3.19],[1,1.91,111.7],[2,1.9,76.72]],"ltp":1.9,"tv":2579.39,"id":4520808},{"batl":[[0,2.12,2.21],[1,2.14,2.25]],"ltp":2.02,"tv":1100.73,"id":8284479}]}]}
{"op":"mcm","clk":"1007063211","pt":1580652726821,"mc":[{"id":"1.168236368","rc":[{"batb":[[0,1.96,2.88],[1,1.95,3.11],[2,1.91,109.19]],"ltp":1.9,"tv":2579.39,"id":4520808},{"batl":[[0,2.02,6.89],[1,2.04,7.57],[2,2.06,2.25]],"ltp":2.02,"tv":1100.73,"id":8284479}]}]}
{"op":"mcm","clk":"1007063611","pt":1580652729212,"mc":[{"id":"1.168236368","rc":[{"batb":[[0,1.94,2.92],[1,1.93,2.65],[2,1.92,2.69]],"ltp":1.9,"tv":2579.39,"id":4520808},{"batl":[[0,2.04,15.14],[1,2.08,2.19],[2,2.1,2.05]],"ltp":2.02,"tv":1100.73,"id":8284479}]}]}
{"op":"mcm","clk":"1007063662","pt":1580652729507,"mc":[{"id":"1.168236368","rc":[{"batb":[[0,1.94,3.09],[1,1.93,2.79]],"ltp":1.9,"tv":2579.39,"id":4520808}]}]}
{"op":"mcm","clk":"1007064373","pt":1580652733149,"mc":[{"id":"1.168236368","rc":[{"batl":[[0,2.04,22.72]],"ltp":2.02,"tv":1100.73,"id":8284479}]}]}
{"op":"mcm","clk":"1007065270","pt":1580652738160,"mc":[{"id":"1.168236368","rc":[{"batb":[[1,1.93,2.93],[2,1.91,109.19]],"ltp":1.9,"tv":2579.39,"id":4520808},{"batl":[[0,2.04,30.29]],"ltp":2.02,"tv":1100.73,"id":8284479}]}]}
{"op":"mcm","clk":"1007065638","pt":1580652740165,"mc":[{"id":"1.168236368","rc":[{"batb":[[0,1.92,2.69],[1,1.91,112.25],[2,1.9,79.58]],"ltp":1.9,"tv":2579.39,"id":4520808},{"batl":[[0,2.04,7.57]],"ltp":2.02,"tv":1100.73,"id":8284479}]}]}
{"op":"mcm","clk":"1007065709","pt":1580652740567,"mc":[{"id":"1.168236368","rc":[{"batb":[[0,1.94,2.92],[1,1.93,2.93],[2,1.91,109.19]],"ltp":1.9,"tv":2579.39,"id":4520808}]}]}
{"op":"mcm","clk":"1007066632","pt":1580652745975,"mc":[{"id":"1.168236368","rc":[{"batl":[[0,2.04,15.14]],"ltp":2.02,"tv":1100.73,"id":8284479}]}]}
{"op":"mcm","clk":"1007067372","pt":1580652749980,"mc":[{"id":"1.168236368","rc":[{"trd":[[2,498.01]],"batl":[[0,2.6,74.66],[1,4.2,153.72],[2,95,15.9]],"ltp":2.0,"tv":2949.07,"id":4520808},{"trd":[[2,599.9]],"ltp":2.0,"tv":1470.41,"id":8284479}],"tv":4419.49}]}
{"op":"mcm","clk":"1007067509","pt":1580652750561,"mc":[{"id":"1.168236368","rc":[{"batb":[[1,1.93,2.65]],"ltp":2.0,"tv":2949.07,"id":4520808}]}]}
{"op":"mcm","clk":"1007067935","pt":1580652752994,"mc":[{"id":"1.168236368","rc":[{"batb":[[0,1.93,7.57],[1,1.92,122.16],[2,1.85,26.72]],"ltp":2.0,"tv":1470.41,"id":8284479}]}]}
{"op":"mcm","clk":"1007068017","pt":1580652753483,"mc":[{"id":"1.168236368","rc":[{"batb":[[0,1.94,7.57],[1,1.93,7.57],[2,1.92,122.16]],"ltp":2.0,"tv":1470.41,"id":8284479}]}]}
{"op":"mcm","clk":"1007070363","pt":1580652767008,"mc":[{"id":"1.168236368","rc":[{"batb":[[1,1.91,109.19],[2,1.9,76.72]],"ltp":2.0,"tv":2949.07,"id":4520808},{"trd":[[2.04,334.11]],"batl":[[0,2.04,2.25],[2,4.2,153.72]],"ltp":2.04,"tv":1511.34,"id":8284479}],"tv":4460.42}]}
{"op":"mcm","clk":"1007070534","pt":1580652768002,"mc":[{"id":"1.168236368","rc":[{"batb":[[1,1.93,2.79],[2,1.91,109.19]],"ltp":2.0,"tv":2949.07,"id":4520808},{"batb":[[0,1.93,7.57],[1,1.92,122.16],[2,1.85,26.72]],"batl":[[2,2.1,2.05]],"ltp":2.04,"tv":1511.34,"id":8284479}]}]}
{"op":"mcm","clk":"1007071783","pt":1580652775207,"mc":[{"id":"1.168236368","rc":[{"batb":[[0,1.92,2.94],[1,1.91,111.92],[2,1.9,76.72]],"ltp":2.0,"tv":2949.07,"id":4520808},{"batb":[[0,1.92,122.16],[1,1.85,26.72],[2,1.83,337.05]],"batl":[[0,2.12,2.21],[1,2.14,2.25],[2,4.2,153.72]],"ltp":2.04,"tv":1511.34,"id":8284479}]}]}
{"op":"mcm","clk":"1007071950","pt":1580652776107,"mc":[{"id":"1.168236368","rc":[{"batb":[[1,1.91,112.25],[2,1.9,79.38]],"ltp":2.0,"tv":2949.07,"id":4520808},{"batb":[[0,2,13.92],[1,1.92,122.16],[2,1.85,26.72]],"batl":[[0,2.06,7.57],[1,2.1,2.05],[2,2.12,2.21]],"ltp":2.04,"tv":1511.34,"id":8284479}]}]}
{"op":"mcm","clk":"1007072013","pt":1580652776509,"mc":[{"id":"1.168236368","rc":[{"trd":[[2,627.74]],"batb":[[0,1.92,122.16],[1,1.85,26.72],[2,1.83,337.05]],"ltp":2.0,"tv":1539.18,"id":8284479}],"tv":4488.26}]}
{"op":"mcm","clk":"1007072284","pt":1580652778111,"mc":[{"id":"1.168236368","rc":[{"batl":[[0,2.06,15.14]],"ltp":2.0,"tv":1539.18,"id":8284479}]}]}
{"op":"mcm","clk":"1007072436","pt":1580652778921,"mc":[{"id":"1.168236368","rc":[{"batb":[[0,1.94,2.59],[1,1.93,3.08],[2,1.92,2.94]],"ltp":2.0,"tv":2949.07,"id":4520808},{"batl":[[0,2.04,15.14],[1,2.06,15.14],[2,2.08,2.19]],"ltp":2.0,"tv":1539.18,"id":8284479}]}]}
{"op":"mcm","clk":"1007073156","pt":1580652783061,"mc":[{"id":"1.168236368","rc":[{"batb":[[0,1.96,7.56],[1,1.94,2.59],[2,1.93,3.08]],"batl":[[0,2.08,7.56],[1,2.6,74.66],[2,4.2,153.72]],"ltp":2.0,"tv":2949.07,"id":4520808},{"batb":[[0,1.93,7.56],[1,1.92,122.16],[2,1.85,26.72]],"batl":[[0,2.04,22.71],[1,2.08,2.19],[2,2.1,2.05]],"ltp":2.0,"tv":1539.18,"id":8284479}]}]}
{"op":"mcm","clk":"1007073821","pt":1580652786911,"mc":[{"id":"1.168236368","rc":[{"batb":[[2,1.93,2.79]],"ltp":2.0,"tv":2949.07,"id":4520808},{"batb":[[0,1.94,7.57],[1,1.93,7.56],[2,1.92,122.16]],"ltp":2.0,"tv":1539.18,"id":8284479}]}]}
{"op":"mcm","clk":"1007073943","pt":1580652787623,"mc":[{"id":"1.168236368","rc":[{"batl":[[0,2.04,30.28]],"ltp":2.0,"tv":1539.18,"id":8284479}]}]}
{"op":"mcm","clk":"1007075611","pt":1580652796145,"mc":[{"id":"1.168236368","rc":[{"batb":[[2,1.93,2.65]],"ltp":2.0,"tv":2949.07,"id":4520808},{"trd":[[2.04,402.96]],"batl":[[0,2.04,3.42]],"ltp":2.04,"tv":1608.03,"id":8284479}],"tv":4557.11}]}
{"op":"mcm","clk":"1007076324","pt":1580652800007,"mc":[{"id":"1.168236368","rc":[{"batb":[[0,2,7.57],[1,1.94,7.57],[2,1.93,7.56]],"ltp":2.04,"tv":1608.03,"id":8284479}]}]}
{"op":"mcm","clk":"1007076452","pt":1580652800541,"mc":[{"id":"1.168236368","rc":[{"trd":[[2,642.88]],"batb":[[0,1.94,7.57],[1,1.93,7.56],[2,1.92,122.16]],"ltp":2.0,"tv":1623.17,"id":8284479}],"tv":4572.25}]}
{"op":"mcm","clk":"1007076794","pt":1580652802158,"mc":[{"id":"1.168236368","rc":[{"trd":[[1.93,5.3],[1.94,310.83],[1.96,217.02]],"batb":[[0,1.91,109.19],[1,1.9,76.72],[2,1.89,420.1]],"batl":[[1,2.12,2.05],[2,2.14,2.7]],"ltp":1.93,"tv":2978.23,"id":4520808},{"trd":[[2.04,406.38]],"batb":[[0,2,7.57],[1,1.94,7.57],[2,1.93,7.56]],"batl":[[0,2.12,2.21],[1,2.14,2.11],[2,4.2,153.72]],"ltp":2.04,"tv":1626.59,"id":8284479}],"tv":4604.83}]}
{"op":"mcm","clk":"1007076939","pt":1580652802953,"mc":[{"id":"1.168236368","rc":[{"batl":[[0,2.08,9.75],[1,2.1,2.05],[2,2.12,2.05]],"ltp":1.93,"tv":2978.23,"id":4520808},{"trd":[[2,658.02]],"batb":[[0,1.94,7.57],[1,1.93,7.56],[2,1.92,122.16]],"batl":[[0,2.14,2.11],[1,2.16,2.1]],"ltp":2.0,"tv":1641.74,"id":8284479}],"tv":4619.98}]}
{"op":"mcm","clk":"1007077005","pt":1580652803266,"mc":[{"id":"1.168236368","rc":[{"batl":[[0,2.08,7.56],[1,2.12,2.05],[2,2.14,2.7]],"ltp":1.93,"tv":2978.23,"id":4520808}]}]}
{"op":"mcm","clk":"1007077352","pt":1580652805136,"mc":[{"id":"1.168236368","rc":[{"batl":[[0,2.04,2.13],[1,2.06,2.25],[2,2.08,7.56]],"ltp":1.93,"tv":2978.23,"id":4520808},{"batb":[[0,2,7.57],[1,1.94,7.57],[2,1.93,7.56]],"ltp":2.0,"tv":1641.74,"id":8284479}]}]}
{"op":"mcm","clk":"1007077529","pt":1580652806150,"mc":[{"id":"1.168236368","rc":[{"batl":[[0,2.08,9.56],[1,2.1,2.05],[2,2.12,2.05]],"ltp":1.93,"tv":2978.23,"id":4520808},{"trd":[[2,673.16]],"batb":[[0,1.94,7.57],[1,1.93,7.56],[2,1.92,122.16]],"ltp":2.0,"tv":1656.88,"id":8284479}],"tv":4635.12}]}
{"op":"mcm","clk":"1007077657","pt":1580652806855,"mc":[{"id":"1.168236368","rc":[{"batl":[[0,2.08,7.56],[1,2.12,2.05],[2,2.14,2.7]],"ltp":1.93,"tv":2978.23,"id":4520808}]}]}
{"op":"mcm","clk":"1007077893","pt":1580652808165,"mc":[{"id":"1.168236368","rc":[{"batl":[[2,2.6,74.66]],"ltp":1.93,"tv":2978.23,"id":4520808}]}]}
{"op":"mcm","clk":"1007078069","pt":1580652809078,"mc":[{"id":"1.168236368","rc":[{"batl":[[2,2.14,2.7]],"ltp":1.93,"tv":2978.23,"id":4520808},{"batl":[[1,2.16,2.22]],"ltp":2.0,"tv":1656.88,"id":8284479}]}]}
{"op":"mcm","clk":"1007078417","pt":1580652810876,"mc":[{"id":"1.168236368","rc":[{"batl":[[0,2.04,2.13],[1,2.06,2.09],[2,2.08,7.56]],"ltp":1.93,"tv":2978.23,"id":4520808},{"batb":[[0,2,7.57],[1,1.94,7.57],[2,1.93,7.56]],"ltp":2.0,"tv":1656.88,"id":8284479}]}]}
{"op":"mcm","clk":"1007078639","pt":1580652812042,"mc":[{"id":"1.168236368","rc":[{"batl":[[0,2.08,9.75],[1,2.1,2.05],[2,2.14,2.7]],"ltp":1.93,"tv":2978.23,"id":4520808},{"trd":[[2,688.31]],"batb":[[0,1.94,7.57],[1,1.93,7.56],[2,1.92,122.16]],"ltp":2.0,"tv":1672.02,"id":8284479}],"tv":4650.26}]}
{"op":"mcm","clk":"1007078691","pt":1580652812332,"mc":[{"id":"1.168236368","rc":[{"batl":[[0,2.08,7.56],[1,2.12,2.05]],"ltp":1.93,"tv":2978.23,"id":4520808}]}]}
{"op":"mcm","clk":"1007079045","pt":1580652814185,"mc":[{"id":"1.168236368","rc":[{"batl":[[0,2.04,15.14],[1,2.08,2.19],[2,2.1,2.05]],"ltp":2.0,"tv":1672.02,"id":8284479}]}]}
{"op":"mcm","clk":"1007079860","pt":1580652818478,"mc":[{"id":"1.168236368","rc":[{"batl":[[0,2.04,22.72]],"ltp":2.0,"tv":1672.02,"id":8284479}]}]}
{"op":"mcm","clk":"1007080372","pt":1580652821176,"mc":[{"id":"1.168236368","rc":[{"trd":[[2.04,447.32]],"batb":[[0,1.94,15.14]],"batl":[[0,2.04,2.24],[2,4.2,153.72]],"ltp":2.04,"tv":1712.97,"id":8284479}],"tv":4691.21}]}
{"op":"mcm","clk":"1007080398","pt":1580652821335,"mc":[{"id":"1.168236368","rc":[{"batl":[[2,2.1,2.05]],"ltp":2.04,"tv":1712.97,"id":8284479}]}]}
{"op":"mcm","clk":"1007080750","pt":1580652823155,"mc":[{"id":"1.168236368","rc":[{"batb":[[0,2,7.57],[1,1.94,15.14],[2,1.93,7.56]],"ltp":2.04,"tv":1712.97,"id":8284479}]}]}
{"op":"mcm","clk":"1007080962","pt":1580652824176,"mc":[{"id":"1.168236368","rc":[{"batl":[[0,2.04,2.13],[1,2.08,9.63],[2,2.1,2.05]],"ltp":1.93,"tv":2978.23,"id":4520808},{"trd":[[2,703.45]],"batb":[[0,1.94,15.14],[1,1.93,7.56],[2,1.92,122.16]],"ltp":2.0,"tv":1728.11,"id":8284479}],"tv":4706.35}]}
{"op":"mcm","clk":"1007081113","pt":1580652824947,"mc":[{"id":"1.168236368","rc":[{"batl":[[0,2.08,7.56],[1,2.12,2.21],[2,2.14,2.7]],"ltp":1.93,"tv":2978.23,"id":4520808}]}]}
{"op":"mcm","clk":"1007081248","pt":1580652825781,"mc":[{"id":"1.168236368","rc":[{"batl":[[0,2.04,17.39]],"ltp":2.0,"tv":1728.11,"id":8284479}]}]}
{"op":"mcm","clk":"1007081683","pt":1580652828098,"mc":[{"id":"1.168236368","rc":[{"batl":[[0,2.04,24.96]],"ltp":2.0,"tv":1728.11,"id":8284479}]}]}
{"op":"mcm","clk":"1007082200","pt":1580652830889,"mc":[{"id":"1.168236368","rc":[{"batl":[[0,2.04,2],[1,2.06,2.25],[2,2.08,7.56]],"ltp":1.93,"tv":2978.23,"id":4520808},{"batb":[[0,2,7.57],[1,1.94,15.14],[2,1.93,7.56]],"ltp":2.0,"tv":1728.11,"id":8284479}]}]}
{"op":"mcm","clk":"1007082482","pt":1580652832180,"mc":[{"id":"1.168236368","rc":[{"batl":[[2,2.08,9.63]],"ltp":1.93,"tv":2978.23,"id":4520808},{"trd":[[2,718.59]],"batb":[[0,1.94,15.14],[1,1.93,7.56],[2,1.92,122.16]],"ltp":2.0,"tv":1743.25,"id":8284479}],"tv":4721.49}]}
{"op":"mcm","clk":"1007082560","pt":1580652832593,"mc":[{"id":"1.168236368","rc":[{"batl":[[0,2.08,7.56],[1,2.12,2.21],[2,2.14,2.56]],"ltp":1.93,"tv":2978.23,"id":4520808}]}]}
{"op":"mcm","clk":"1007083964","pt":1580652840181,"mc":[{"id":"1.168236368","rc":[{"batl":[[2,2.14,2.63]],"ltp":1.93,"tv":2978.23,"id":4520808},{"batb":[[0,1.93,7.56],[1,1.92,122.16],[2,1.86,327.09]],"batl":[[0,2.12,2.21],[1,2.14,2.18],[2,4.2,153.72]],"ltp":2.0,"tv":1743.25,"id":8284479}]}]}
{"op":"mcm","clk":"1007084103","pt":1580652841007,"mc":[{"id":"1.168236368","rc":[{"batb":[[0,2,13.92],[1,1.93,7.56],[2,1.92,122.16]],"batl":[[0,2.04,15.14],[1,2.08,2.19],[2,2.1,2.05]],"ltp":2.0,"tv":1743.25,"id":8284479}]}]}
{"op":"mcm","clk":"1007084252","pt":1580652841815,"mc":[{"id":"1.168236368","rc":[{"batl":[[0,2.04,2],[1,2.06,2.25],[2,2.08,7.56]],"ltp":1.93,"tv":2978.23,"id":4520808}]}]}
{"op":"mcm","clk":"1007084564","pt":1580652843215,"mc":[{"id":"1.168236368","rc":[{"batl":[[0,2.08,7.56],[1,2.12,2.21],[2,2.14,2.63]],"ltp":1.93,"tv":2978.23,"id":4520808},{"trd":[[2,746.43]],"batb":[[0,1.93,7.56],[1,1.92,122.16],[2,1.86,327.09]],"batl":[[0,2.04,22.72]],"ltp":2.0,"tv":1771.09,"id":8284479}],"tv":4749.33}]}
{"op":"mcm","clk":"1007085097","pt":1580652846218,"mc":[{"id":"1.168236368","rc":[{"trd":[[2.04,503.19]],"batl":[[0,2.04,2.35]],"ltp":2.04,"tv":1826.96,"id":8284479}],"tv":4805.19}]}
{"op":"mcm","clk":"1007085543","pt":1580652848117,"mc":[{"id":"1.168236368","rc":[{"batb":[[0,1.95,7.57],[1,1.93,7.56],[2,1.92,122.16]],"ltp":2.04,"tv":1826.96,"id":8284479}]}]}
{"op":"mcm","clk":"1007085758","pt":1580652849209,"mc":[{"id":"1.168236368","rc":[{"batl":[[1,2.1,2.05],[2,2.12,2.05]],"ltp":1.93,"tv":2978.23,"id":4520808},{"batb":[[0,2,7.57],[1,1.95,7.57],[2,1.93,7.56]],"ltp":2.04,"tv":1826.96,"id":8284479}]}]}
{"op":"mcm","clk":"1007085839","pt":1580652849608,"mc":[{"id":"1.168236368","rc":[{"batl":[[0,2.04,2],[1,2.06,2.09],[2,2.08,7.56]],"ltp":1.93,"tv":2978.23,"id":4520808},{"trd":[[2,761.57]],"ltp":2.0,"tv":1842.1,"id":8284479}],"tv":4820.34}]}
{"op":"mcm","clk":"1007086136","pt":1580652851194,"mc":[{"id":"1.168236368","rc":[{"batl":[[0,2.08,7.56],[1,2.1,2.05],[2,2.12,2.05]],"ltp":1.93,"tv":2978.23,"id":4520808},{"trd":[[2,776.72]],"batb":[[0,1.95,7.57],[1,1.93,7.56],[2,1.92,122.16]],"ltp":2.0,"tv":1857.24,"id":8284479}],"tv":4835.48}]}
{"op":"mcm","clk":"1007086169","pt":1580652851401,"mc":[{"id":"1.168236368","rc":[{"batl":[[1,2.12,2.05],[2,2.14,2.56]],"ltp":1.93,"tv":2978.23,"id":4520808}]}]}
{"op":"mcm","clk":"1007086469","pt":1580652853126,"mc":[{"id":"1.168236368","rc":[{"batl":[[0,2.06,2],[1,2.08,9.75],[2,2.12,2.05]],"ltp":1.93,"tv":2978.23,"id":4520808},{"batb":[[0,1.99,7.57],[1,1.95,7.57],[2,1.93,7.56]],"ltp":2.0,"tv":1857.24,"id":8284479}]}]}
{"op":"mcm","clk":"1007087162","pt":1580652857022,"mc":[{"id":"1.168236368","rc":[{"batl":[[0,2.06,9.56],[1,2.08,2.19]],"ltp":1.93,"tv":2978.23,"id":4520808},{"batb":[[2,1.94,7.56]],"ltp":2.0,"tv":1857.24,"id":8284479}]}]}
{"op":"mcm","clk":"1007087284","pt":1580652857761,"mc":[{"id":"1.168236368","rc":[{"batl":[[2,2.6,74.66]],"ltp":1.93,"tv":2978.23,"id":4520808}]}]}
{"op":"mcm","clk":"1007087790","pt":1580652860244,"mc":[{"id":"1.168236368","rc":[{"batl":[[0,2.06,7.56],[1,2.1,2.05],[2,2.12,2.21]],"ltp":1.93,"tv":2978.23,"id":4520808},{"batb":[[0,1.94,7.56],[1,1.92,122.16],[2,1.86,327.09]],"batl":[[0,2.14,2.11],[1,2.16,2.22],[2,4.2,153.72]],"ltp":2.0,"tv":1857.24,"id":8284479}]}]}
{"op":"mcm","clk":"1007087923","pt":1580652861023,"mc":[{"id":"1.168236368","rc":[{"batl":[[0,2.04,2],[1,2.06,9.81],[2,2.1,2.05]],"ltp":1.93,"tv":2978.23,"id":4520808},{"batb":[[0,2,5.78],[1,1.94,7.56],[2,1.92,122.16]],"ltp":2.0,"tv":1857.24,"id":8284479}]}]}
{"op":"mcm","clk":"1007088097","pt":1580652862057,"mc":[{"id":"1.168236368","rc":[{"batl":[[0,2.06,7.56],[1,2.08,2.19]],"ltp":1.93,"tv":2978.23,"id":4520808},{"trd":[[2,788.27]],"batb":[[0,1.94,7.56],[1,1.92,122.16],[2,1.86,327.09]],"ltp":2.0,"tv":1868.8,"id":8284479}],"tv":4847.04}]}
{"op":"mcm","clk":"1007088141","pt":1580652862311,"mc":[{"id":"1.168236368","rc":[{"batl":[[1,2.1,2.05],[2,2.12,2.21]],"ltp":1.93,"tv":2978.23,"id":4520808}]}]}
{"op":"mcm","clk":"1007089006","pt":1580652867237,"mc":[{"id":"1.168236368","rc":[{"batl":[[2,2.6,74.66]],"ltp":1.93,"tv":2978.23,"id":4520808},{"batl":[[0,2.04,7.57],[1,2.08,2.19],[2,2.1,2.05]],"ltp":2.0,"tv":1868.8,"id":8284479}]}]}
{"op":"mcm","clk":"1007089050","pt":1580652867523,"mc":[{"id":"1.168236368","rc":[{"batl":[[2,2.12,2.05]],"ltp":1.93,"tv":2978.23,"id":4520808}]}]}
{"op":"mcm","clk":"1007089189","pt":1580652868334,"mc":[{"id":"1.168236368","rc":[{"batl":[[0,2.04,15.14]],"ltp":2.0,"tv":1868.8,"id":8284479}]}]}
{"op":"mcm","clk":"1007089871","pt":1580652872233,"mc":[{"id":"1.168236368","rc":[{"trd":[[2.04,544.18]],"batl":[[0,2.04,2.22]],"ltp":2.04,"tv":1909.79,"id":8284479}],"tv":4888.03}]}
{"op":"mcm","clk":"1007090012","pt":1580652873162,"mc":[{"id":"1.168236368","rc":[{"batl":[[0,2.04,2.13],[1,2.06,9.56],[2,2.1,2.05]],"ltp":1.93,"tv":2978.23,"id":4520808},{"batb":[[0,2,20.91],[1,1.94,7.56],[2,1.92,122.16]],"ltp":2.04,"tv":1909.79,"id":8284479}]}]}
{"op":"mcm","clk":"1007090168","pt":1580652874041,"mc":[{"id":"1.168236368","rc":[{"batl":[[0,2.06,7.56],[1,2.08,2]],"ltp":1.93,"tv":2978.23,"id":4520808},{"trd":[[2,830.08]],"batb":[[0,1.94,7.56],[1,1.92,122.16],[2,1.86,327.09]],"batl":[[2,4.2,153.72]],"ltp":2.0,"tv":1951.6,"id":8284479}],"tv":4929.84}]}
{"op":"mcm","clk":"1007090214","pt":1580652874252,"mc":[{"id":"1.168236368","rc":[{"batl":[[1,2.1,2.05],[2,2.12,2.21]],"ltp":1.93,"tv":2978.23,"id":4520808},{"batl":[[2,2.1,2.05]],"ltp":2.0,"tv":1951.6,"id":8284479}]}]}
{"op":"mcm","clk":"1007090583","pt":1580652876240,"mc":[{"id":"1.168236368","rc":[{"batl":[[0,2.04,9.79]],"ltp":2.0,"tv":1951.6,"id":8284479}]}]}
{"op":"mcm","clk":"1007090620","pt":1580652876453,"mc":[{"id":"1.168236368","rc":[{"batl":[[0,2.04,17.36]],"ltp":2.0,"tv":1951.6,"id":8284479}]}]}
{"op":"mcm","clk":"1007092282","pt":1580652885183,"mc":[{"id":"1.168236368","rc":[{"batl":[[2,2.6,74.66]],"ltp":1.93,"tv":2978.23,"id":4520808},{"batl":[[0,2.04,24.94]],"ltp":2.0,"tv":1951.6,"id":8284479}]}]}
{"op":"mcm","clk":"1007092363","pt":1580652885553,"mc":[{"id":"1.168236368","rc":[{"batl":[[2,2.12,2.21]],"ltp":1.93,"tv":2978.23,"id":4520808},{"batb":[[0,1.95,79.57],[1,1.94,7.56]],"ltp":2.0,"tv":1951.6,"id":8284479}]}]}
{"op":"mcm","clk":"1007092591","pt":1580652886893,"mc":[{"id":"1.168236368","rc":[{"batl":[[0,2.04,32.51]],"ltp":2.0,"tv":1951.6,"id":8284479}]}]}
{"op":"mcm","clk":"1007093050","pt":1580652889166,"mc":[{"id":"1.168236368","rc":[{"batl":[[0,2.08,2.19],[1,2.1,2.05],[2,4.2,153.72]],"ltp":2.0,"tv":1951.6,"id":8284479}]}]}
{"op":"mcm","clk":"1007093187","pt":1580652889752,"mc":[{"id":"1.168236368","rc":[{"batl":[[0,2.04,7.57],[1,2.08,2.19],[2,2.1,2.05]],"ltp":2.0,"tv":1951.6,"id":8284479}]}]}
{"op":"mcm","clk":"1007093436","pt":1580652890968,"mc":[{"id":"1.168236368","rc":[{"batl":[[0,2.04,15.14]],"ltp":2.0,"tv":1951.6,"id":8284479}]}]}
{"op":"mcm","clk":"1007093965","pt":1580652894058,"mc":[{"id":"1.168236368","rc":[{"batl":[[0,2.04,22.72]],"ltp":2.0,"tv":1951.6,"id":8284479}]}]}
{"op":"mcm","clk":"1007094073","pt":1580652894673,"mc":[{"id":"1.168236368","rc":[{"batl":[[2,2.12,2.13]],"ltp":1.93,"tv":2978.23,"id":4520808}]}]}
{"op":"mcm","clk":"1007094680","pt":1580652898077,"mc":[{"id":"1.168236368","rc":[{"batl":[[0,2.04,7.56],[1,2.08,2],[2,2.1,2.05]],"ltp":1.93,"tv":2978.23,"id":4520808}]}]}
{"op":"mcm","clk":"1007094855","pt":1580652899093,"mc":[{"id":"1.168236368","rc":[{"batl":[[0,2.04,9.69],[1,2.06,2.25],[2,2.08,2]],"ltp":1.93,"tv":2978.23,"id":4520808},{"trd":[[2.04,585.17]],"batb":[[0,2,20.91],[1,1.95,79.57],[2,1.94,7.56]],"batl":[[0,2.04,2.22]],"ltp":2.04,"tv":1992.59,"id":8284479}],"tv":4970.83}]}
{"op":"mcm","clk":"1007094977","pt":1580652899801,"mc":[{"id":"1.168236368","rc":[{"batl":[[0,2.04,7.56],[1,2.08,2],[2,2.1,2.05]],"ltp":1.93,"tv":2978.23,"id":4520808},{"trd":[[2,871.9]],"batb":[[0,1.95,79.57],[1,1.94,7.56],[2,1.86,327.09]],"ltp":2.0,"tv":2034.4,"id":8284479}],"tv":5012.64}]}
{"op":"mcm","clk":"1007095589","pt":1580652903094,"mc":[{"id":"1.168236368","rc":[{"batl":[[0,2.04,9.79]],"ltp":2.0,"tv":2034.4,"id":8284479}]}]}
{"op":"mcm","clk":"1007095737","pt":1580652903985,"mc":[{"id":"1.168236368","rc":[{"batl":[[0,2.04,17.36]],"ltp":2.0,"tv":2034.4,"id":8284479}]}]}
{"op":"mcm","clk":"1007095913","pt":1580652905004,"mc":[{"id":"1.168236368","rc":[{"batl":[[0,2.04,24.94]],"ltp":2.0,"tv":2034.4,"id":8284479}]}]}
{"op":"mcm","clk":"1007098903","pt":1580652922098,"mc":[{"id":"1.168236368","rc":[{"batl":[[0,2.04,32.51]],"ltp":2.0,"tv":2034.4,"id":8284479}]}]}
{"op":"mcm","clk":"1007099089","pt":1580652923102,"mc":[{"id":"1.168236368","rc":[{"batl":[[0,2.04,9.56],[1,2.06,2],[2,2.08,2]],"ltp":1.93,"tv":2978.23,"id":4520808},{"trd":[[2.04,644.81]],"batb":[[0,2,28.16],[1,1.95,79.57],[2,1.94,7.56]],"batl":[[0,2.04,2.68]],"ltp":2.04,"tv":2094.05,"id":8284479}],"tv":5072.28}]}
{"op":"mcm","clk":"1007099229","pt":1580652923907,"mc":[{"id":"1.168236368","rc":[{"batl":[[0,2.04,7.56],[1,2.08,2.19],[2,2.1,2.05]],"ltp":1.93,"tv":2978.23,"id":4520808},{"trd":[[2,928.21]],"batb":[[0,1.95,79.57],[1,1.94,7.56],[2,1.86,327.09]],"ltp":2.0,"tv":2150.36,"id":8284479}],"tv":5128.6}]}
{"op":"mcm","clk":"1007099348","pt":1580652924715,"mc":[{"id":"1.168236368","rc":[{"batl":[[0,2.04,9.56],[1,2.06,2.25],[2,2.08,2.19]],"ltp":1.93,"tv":2978.23,"id":4520808},{"batb":[[0,2,2.26],[1,1.95,79.57],[2,1.94,7.56]],"ltp":2.0,"tv":2150.36,"id":8284479}]}]}
{"op":"mcm","clk":"1007099558","pt":1580652925906,"mc":[{"id":"1.168236368","rc":[{"batl":[[0,2.04,7.56],[1,2.08,2.19],[2,2.1,2.05]],"ltp":1.93,"tv":2978.23,"id":4520808},{"trd":[[2,932.74]],"batb":[[0,1.95,79.57],[1,1.94,7.56],[2,1.86,327.09]],"batl":[[0,2.04,10.25]],"ltp":2.0,"tv":2154.89,"id":8284479}],"tv":5133.12}]}
{"op":"mcm","clk":"1007099828","pt":1580652927540,"mc":[{"id":"1.168236368","rc":[{"batl":[[0,2.04,17.83]],"ltp":2.0,"tv":2154.89,"id":8284479}]}]}
{"op":"mcm","clk":"1007100084","pt":1580652929084,"mc":[{"id":"1.168236368","rc":[{"batl":[[2,2.6,74.66]],"ltp":1.93,"tv":2978.23,"id":4520808},{"batl":[[0,2.04,25.4],[2,4.2,153.72]],"ltp":2.0,"tv":2154.89,"id":8284479}]}]}
{"op":"mcm","clk":"1007100190","pt":1580652929813,"mc":[{"id":"1.168236368","rc":[{"batl":[[2,2.1,2.05]],"ltp":1.93,"tv":2978.23,"id":4520808},{"batl":[[0,2.04,32.97],[2,2.1,2.05]],"ltp":2.0,"tv":2154.89,"id":8284479}]}]}
{"op":"mcm","clk":"1007100847","pt":1580652933940,"mc":[{"id":"1.168236368","rc":[{"batl":[[0,2.04,36.76]],"ltp":2.0,"tv":2154.89,"id":8284479}]}]}
{"op":"mcm","clk":"1007103447","pt":1580652949145,"mc":[{"id":"1.168236368","rc":[{"batl":[[2,2.6,74.66]],"ltp":1.93,"tv":2978.23,"id":4520808},{"batl":[[0,2.04,44.33],[2,4.2,153.72]],"ltp":2.0,"tv":2154.89,"id":8284479}]}]}
{"op":"mcm","clk":"1007103631","pt":1580652950122,"mc":[{"id":"1.168236368","rc":[{"batl":[[0,2.04,9.56],[1,2.06,2.09],[2,2.08,2.19]],"ltp":1.93,"tv":2978.23,"id":4520808},{"trd":[[2.04,726.86]],"batb":[[0,2,39.11],[1,1.95,79.57],[2,1.94,7.56]],"batl":[[0,2.04,3.3],[2,2.1,2.05]],"ltp":2.04,"tv":2236.93,"id":8284479}],"tv":5215.17}]}
{"op":"mcm","clk":"1007103833","pt":1580652951218,"mc":[{"id":"1.168236368","rc":[{"batl":[[0,2.04,7.56],[1,2.08,2],[2,2.1,2.05]],"ltp":1.93,"tv":2978.23,"id":4520808},{"trd":[[2,1010.95]],"batb":[[0,1.95,79.57],[1,1.94,7.56],[2,1.86,327.09]],"ltp":2.0,"tv":2315.15,"id":8284479}],"tv":5293.39}]}
{"op":"mcm","clk":"1007103915","pt":1580652951709,"mc":[{"id":"1.168236368","rc":[{"batl":[[0,2.04,9.69],[1,2.06,2.25],[2,2.08,2]],"ltp":1.93,"tv":2978.23,"id":4520808},{"batb":[[0,2,2.73],[1,1.95,79.57],[2,1.94,7.56]],"ltp":2.0,"tv":2315.15,"id":8284479}]}]}
{"op":"mcm","clk":"1007104164","pt":1580652953126,"mc":[{"id":"1.168236368","rc":[{"batl":[[0,2.04,7.56],[1,2.08,2],[2,2.1,2.05]],"ltp":1.93,"tv":2978.23,"id":4520808},{"trd":[[2,1016.41]],"batb":[[0,1.95,79.57],[1,1.94,7.56],[2,1.86,327.09]],"batl":[[0,2.04,10.87]],"ltp":2.0,"tv":2320.61,"id":8284479}],"tv":5298.85}]}
{"op":"mcm","clk":"1007104347","pt":1580652954145,"mc":[{"id":"1.168236368","rc":[{"batl":[[0,2.04,18.45]],"ltp":2.0,"tv":2320.61,"id":8284479}]}]}
{"op":"mcm","clk":"1007104651","pt":1580652955942,"mc":[{"id":"1.168236368","rc":[{"batl":[[0,2.04,26.02]],"ltp":2.0,"tv":2320.61,"id":8284479}]}]}
{"op":"mcm","clk":"1007104759","pt":1580652956531,"mc":[{"id":"1.168236368","rc":[{"batl":[[2,2.1,2]],"ltp":1.93,"tv":2978.23,"id":4520808}]}]}
{"op":"mcm","clk":"1007105565","pt":1580652960948,"mc":[{"id":"1.168236368","rc":[{"batl":[[0,2.04,33.59]],"ltp":2.0,"tv":2320.61,"id":8284479}]}]}
{"op":"mcm","clk":"1007107725","pt":1580652973136,"mc":[{"id":"1.168236368","rc":[{"batl":[[2,2.1,2.05]],"ltp":1.93,"tv":2978.23,"id":4520808},{"batl":[[0,2.04,41.16]],"ltp":2.0,"tv":2320.61,"id":8284479}]}]}
{"op":"mcm","clk":"1007107924","pt":1580652974165,"mc":[{"id":"1.168236368","rc":[{"batl":[[0,2.04,9.56],[1,2.06,2.25],[2,2.08,2]],"ltp":1.93,"tv":2978.23,"id":4520808},{"trd":[[2.04,803.33]],"batb":[[0,2,39],[1,1.95,79.57],[2,1.94,7.56]],"batl":[[0,2.04,2.92]],"ltp":2.04,"tv":2397.08,"id":8284479}],"tv":5375.32}]}
{"op":"mcm","clk":"1007108112","pt":1580652975052,"mc":[{"id":"1.168236368","rc":[{"batl":[[0,2.04,7.56],[1,2.08,2.19],[2,2.1,2.05]],"ltp":1.93,"tv":2978.23,"id":4520808},{"trd":[[2,1094.41]],"batb":[[0,1.95,79.57],[1,1.94,7.56],[2,1.86,327.09]],"ltp":2.0,"tv":2475.08,"id":8284479}],"tv":5453.32}]}
{"op":"mcm","clk":"1007108695","pt":1580652978143,"mc":[{"id":"1.168236368","rc":[{"batl":[[0,2.04,10.5]],"ltp":2.0,"tv":2475.08,"id":8284479}]}]}
{"op":"mcm","clk":"1007108807","pt":1580652978859,"mc":[{"id":"1.168236368","rc":[{"batl":[[0,2.04,25.64]],"ltp":2.0,"tv":2475.08,"id":8284479}]}]}
{"op":"mcm","clk":"1007109030","pt":1580652980158,"mc":[{"id":"1.168236368","rc":[{"batl":[[0,2.04,33.21]],"ltp":2.0,"tv":2475.08,"id":8284479}]}]}
{"op":"mcm","clk":"1007109115","pt":1580652980649,"mc":[{"id":"1.168236368","rc":[{"batl":[[0,2.04,40.78]],"ltp":2.0,"tv":2475.08,"id":8284479}]}]}
{"op":"mcm","clk":"1007110196","pt":1580652987072,"mc":[{"id":"1.168236368","rc":[{"batl":[[0,2.04,48.36]],"ltp":2.0,"tv":2475.08,"id":8284479}]}]}
{"op":"mcm","clk":"1007110956","pt":1580652991485,"mc":[{"id":"1.168236368","rc":[{"batl":[[0,2.04,55.93]],"ltp":2.0,"tv":2475.08,"id":8284479}]}]}
{"op":"mcm","clk":"1007111396","pt":1580652993990,"mc":[{"id":"1.168236368","rc":[{"batl":[[0,2.04,15.14],[1,2.08,2.07]],"ltp":2.0,"tv":2475.08,"id":8284479}]}]}
{"op":"mcm","clk":"1007111684","pt":1580652995602,"mc":[{"id":"1.168236368","rc":[{"batl":[[0,2.04,22.72]],"ltp":2.0,"tv":2475.08,"id":8284479}]}]}
{"op":"mcm","clk":"1007112158","pt":1580652998245,"mc":[{"id":"1.168236368","rc":[{"batl":[[0,2.04,30.29]],"ltp":2.0,"tv":2475.08,"id":8284479}]}]}
{"op":"mcm","clk":"1007112240","pt":1580652998625,"mc":[{"id":"1.168236368","rc":[{"trd":[[2.04,859.3]],"batl":[[0,2.04,2.3]],"ltp":2.04,"tv":2531.05,"id":8284479}],"tv":5509.29}]}
{"op":"mcm","clk":"1007112537","pt":1580653000196,"mc":[{"id":"1.168236368","rc":[{"batl":[[0,2.04,9.69],[1,2.06,2.25],[2,2.6,74.66]],"ltp":1.93,"tv":2978.23,"id":4520808},{"batb":[[0,2,28.55],[1,1.95,79.57],[2,1.94,7.56]],"ltp":2.04,"tv":2531.05,"id":8284479}]}]}
{"op":"mcm","clk":"1007112695","pt":1580653001134,"mc":[{"id":"1.168236368","rc":[{"batl":[[0,2.04,7.56],[1,2.08,2.19],[2,2.1,2.05]],"ltp":1.93,"tv":2978.23,"id":4520808},{"trd":[[2,1151.5]],"batb":[[0,1.95,79.57],[1,1.94,7.56],[2,1.86,327.09]],"ltp":2.0,"tv":2588.14,"id":8284479}],"tv":5566.37}]}
{"op":"mcm","clk":"1007113407","pt":1580653005000,"mc":[{"id":"1.168236368","rc":[{"batl":[[0,2.04,15.14],[1,2.08,2.19]],"ltp":2.0,"tv":2588.14,"id":8284479}]}]}
{"op":"mcm","clk":"1007113805","pt":1580653007218,"mc":[{"id":"1.168236368","rc":[{"batl":[[0,2.08,2.19],[1,2.1,2.05],[2,2.12,2.05]],"ltp":2.0,"tv":2588.14,"id":8284479}]}]}
{"op":"mcm","clk":"1007113897","pt":1580653007721,"mc":[{"id":"1.168236368","rc":[{"batl":[[0,2.06,15.14]],"ltp":2.0,"tv":2588.14,"id":8284479}]}]}
{"op":"mcm","clk":"1007114666","pt":1580653012096,"mc":[{"id":"1.168236368","rc":[{"batl":[[2,2.12,2.13]],"ltp":2.0,"tv":2588.14,"id":8284479}]}]}
{"op":"mcm","clk":"1007114969","pt":1580653014023,"mc":[{"id":"1.168236368","rc":[{"batl":[[0,2.06,30.29]],"ltp":2.0,"tv":2588.14,"id":8284479}]}]}
{"op":"mcm","clk":"1007115840","pt":1580653019233,"mc":[{"id":"1.168236368","rc":[{"trd":[[1.94,316.71]],"ltp":1.94,"tv":2984.11,"id":4520808},{"trd":[[2.06,220.78]],"batb":[[0,2,5.7],[1,1.95,79.57],[2,1.94,7.56]],"batl":[[0,2.06,24.75]],"ltp":2.06,"tv":2593.67,"id":8284479}],"tv":5577.79}]}
{"op":"mcm","clk":"1007115934","pt":1580653019825,"mc":[{"id":"1.168236368","rc":[{"batl":[[0,2.04,9.69],[1,2.06,2.09],[2,2.6,74.66]],"ltp":1.94,"tv":2984.11,"id":4520808}]}]}
{"op":"mcm","clk":"1007116171","pt":1580653021114,"mc":[{"id":"1.168236368","rc":[{"batl":[[0,2.04,7.56],[1,2.08,2.07],[2,2.1,2.05]],"ltp":1.94,"tv":2984.11,"id":4520808},{"trd":[[2,1162.91]],"batb":[[0,1.95,79.57],[1,1.94,7.56],[2,1.86,327.09]],"ltp":2.0,"tv":2605.08,"id":8284479}],"tv":5589.2}]}
{"op":"mcm","clk":"1007116318","pt":1580653022025,"mc":[{"id":"1.168236368","rc":[{"batl":[[0,2.06,32.33]],"ltp":2.0,"tv":2605.08,"id":8284479}]}]}
{"op":"mcm","clk":"1007116516","pt":1580653023198,"mc":[{"id":"1.168236368","rc":[{"trd":[[2.06,280.5]],"batb":[[0,2,28.66],[1,1.95,79.57],[2,1.94,7.56]],"batl":[[0,2.06,2.46]],"ltp":2.06,"tv":2664.8,"id":8284479}],"tv":5648.92}]}
{"op":"mcm","clk":"1007116632","pt":1580653023925,"mc":[{"id":"1.168236368","rc":[{"batl":[[0,2.04,9.56],[1,2.06,2.09],[2,2.08,2.07]],"ltp":1.94,"tv":2984.11,"id":4520808}]}]}
{"op":"mcm","clk":"1007116829","pt":1580653025135,"mc":[{"id":"1.168236368","rc":[{"batl":[[0,2.04,9.69]],"ltp":1.94,"tv":2984.11,"id":4520808},{"trd":[[2,1220.22]],"batb":[[0,2,2.1]],"ltp":2.0,"tv":2722.12,"id":8284479}],"tv":5706.24}]}
{"op":"mcm","clk":"1007117019","pt":1580653026235,"mc":[{"id":"1.168236368","rc":[{"trd":[[2,1224.42]],"batb":[[0,1.94,7.56],[1,1.86,327.09],[2,1.85,26.72]],"batl":[[0,2.06,10.03],[2,4.2,153.72]],"ltp":2.0,"tv":2726.31,"id":8284479}],"tv":5710.43}]}
{"op":"mcm","clk":"1007117165","pt":1580653026933,"mc":[{"id":"1.168236368","rc":[{"batl":[[0,2.04,7.56],[1,2.08,2.07],[2,2.1,2.05]],"ltp":1.94,"tv":2984.11,"id":4520808},{"batb":[[0,1.97,52.44],[1,1.94,7.56],[2,1.86,327.09]],"batl":[[2,2.12,2.21]],"ltp":2.0,"tv":2726.31,"id":8284479}]}]}
{"op":"mcm","clk":"1007117249","pt":1580653027435,"mc":[{"id":"1.168236368","rc":[{"batl":[[0,2.06,17.61]],"ltp":2.0,"tv":2726.31,"id":8284479}]}]}
{"op":"mcm","clk":"1007117524","pt":1580653028836,"mc":[{"id":"1.168236368","rc":[{"batl":[[0,2.06,25.18]],"ltp":2.0,"tv":2726.31,"id":8284479}]}]}
{"op":"mcm","clk":"1007118278","pt":1580653033236,"mc":[{"id":"1.168236368","rc":[{"batl":[[0,2.06,28.96],[2,4.2,153.72]],"ltp":2.0,"tv":2726.31,"id":8284479}]}]}
{"op":"mcm","clk":"1007118300","pt":1580653033342,"mc":[{"id":"1.168236368","rc":[{"batl":[[2,2.12,2.21]],"ltp":2.0,"tv":2726.31,"id":8284479}]}]}
{"op":"mcm","clk":"1007118652","pt":1580653035459,"mc":[{"id":"1.168236368","rc":[{"batl":[[0,2.06,36.54]],"ltp":2.0,"tv":2726.31,"id":8284479}]}]}
{"op":"mcm","clk":"1007119770","pt":1580653042069,"mc":[{"id":"1.168236368","rc":[{"batl":[[0,2.06,44.11]],"ltp":2.0,"tv":2726.31,"id":8284479}]}]}
{"op":"mcm","clk":"1007120053","pt":1580653043727,"mc":[{"id":"1.168236368","rc":[{"batl":[[0,2.06,51.68]],"ltp":2.0,"tv":2726.31,"id":8284479}]}]}
{"op":"mcm","clk":"1007120528","pt":1580653046862,"mc":[{"id":"1.168236368","rc":[{"batl":[[0,2.06,15.14]],"ltp":2.0,"tv":2726.31,"id":8284479}]}]}
{"op":"mcm","clk":"1007120744","pt":1580653048186,"mc":[{"id":"1.168236368","rc":[{"trd":[[2.06,293.56]],"batl":[[0,2.06,8.62]],"ltp":2.06,"tv":2739.37,"id":8284479}],"tv":5723.49}]}
{"op":"mcm","clk":"1007120875","pt":1580653048909,"mc":[{"id":"1.168236368","rc":[{"batl":[[0,2.04,9.69],[1,2.06,2.09]],"ltp":1.94,"tv":2984.11,"id":4520808},{"batb":[[0,2,6.72],[1,1.97,52.44],[2,1.94,7.56]],"batl":[[0,2.06,16.19]],"ltp":2.06,"tv":2739.37,"id":8284479}]}]}
{"op":"mcm","clk":"1007121078","pt":1580653050036,"mc":[{"id":"1.168236368","rc":[{"batl":[[0,2.04,7.56],[1,2.08,2.19]],"ltp":1.94,"tv":2984.11,"id":4520808},{"trd":[[2,1237.86]],"batb":[[0,1.97,52.44],[1,1.94,7.56],[2,1.86,327.09]],"ltp":2.0,"tv":2752.82,"id":8284479}],"tv":5736.94}]}
{"op":"mcm","clk":"1007121235","pt":1580653051072,"mc":[{"id":"1.168236368","rc":[{"batl":[[0,2.06,23.76]],"ltp":2.0,"tv":2752.82,"id":8284479}]}]}
{"op":"mcm","clk":"1007121664","pt":1580653053955,"mc":[{"id":"1.168236368","rc":[{"batl":[[0,2.06,31.33],[2,2.12,2.13]],"ltp":2.0,"tv":2752.82,"id":8284479}]}]}
{"op":"mcm","clk":"1007123165","pt":1580653062852,"mc":[{"id":"1.168236368","rc":[{"batl":[[0,2.06,38.91]],"ltp":2.0,"tv":2752.82,"id":8284479}]}]}
{"op":"mcm","clk":"1007123543","pt":1580653065168,"mc":[{"id":"1.168236368","rc":[{"batl":[[0,2.06,7.57],[1,2.14,2.25],[2,2.16,2.16]],"ltp":2.0,"tv":2752.82,"id":8284479}]}]}
{"op":"mcm","clk":"1007123616","pt":1580653065596,"mc":[{"id":"1.168236368","rc":[{"batl":[[0,2.06,15.14],[1,2.1,2.05],[2,2.12,2.21]],"ltp":2.0,"tv":2752.82,"id":8284479}]}]}
{"op":"mcm","clk":"1007123794","pt":1580653066569,"mc":[{"id":"1.168236368","rc":[{"batl":[[0,2.06,22.72]],"ltp":2.0,"tv":2752.82,"id":8284479}]}]}
{"op":"mcm","clk":"1007124042","pt":1580653068093,"mc":[{"id":"1.168236368","rc":[{"batl":[[0,2.06,30.29]],"ltp":2.0,"tv":2752.82,"id":8284479}]}]}
{"op":"mcm","clk":"1007124495","pt":1580653071235,"mc":[{"id":"1.168236368","rc":[{"batl":[[0,2.1,2.05],[1,2.12,2.21],[2,2.18,2.03]],"ltp":2.0,"tv":2752.82,"id":8284479}]}]}
{"op":"mcm","clk":"1007124682","pt":1580653072181,"mc":[{"id":"1.168236368","rc":[{"trd":[[1.91,1210.81],[1.94,319.32]],"batb":[[0,1.91,7.4]],"batl":[[2,2.1,2]],"ltp":1.94,"tv":3190.31,"id":4520808},{"trd":[[2.06,300.94]],"batl":[[0,2.06,10.22],[1,2.1,2.05],[2,2.12,2.21]],"ltp":2.06,"tv":2760.2,"id":8284479}],"tv":5950.51}]}
{"op":"mcm","clk":"1007124840","pt":1580653073202,"mc":[{"id":"1.168236368","rc":[{"trd":[[1.94,322.13]],"batb":[[0,1.9,116.2],[1,1.89,420.1],[2,1.81,37.86]],"batl":[[0,2.04,9.69],[1,2.06,2.25],[2,2.08,2.19]],"ltp":1.94,"tv":3193.12,"id":4520808},{"trd":[[2.06,318.73]],"batb":[[0,2,12.87],[1,1.98,120.38],[2,1.94,7.56]],"batl":[[0,2.18,2.03],[1,2.2,2.08],[2,4.2,153.72]],"ltp":2.06,"tv":2777.99,"id":8284479}],"tv":5971.12}]}
{"op":"mcm","clk":"1007124970","pt":1580653073966,"mc":[{"id":"1.168236368","rc":[{"batl":[[0,2.04,7.56],[1,2.08,2],[2,2.1,2]],"ltp":1.94,"tv":3193.12,"id":4520808},{"trd":[[2,1263.61]],"batb":[[0,1.98,120.38],[1,1.94,7.56],[2,1.86,327.09]],"batl":[[0,2.16,2.22],[1,2.18,2.03],[2,2.2,2.08]],"ltp":2.0,"tv":2803.74,"id":8284479}],"tv":5996.86}]}
{"op":"mcm","clk":"1007125127","pt":1580653074993,"mc":[{"id":"1.168236368","rc":[{"batl":[[0,2.04,9.56],[1,2.06,2],[2,2.08,2]],"ltp":1.94,"tv":3193.12,"id":4520808},{"batb":[[0,2,2.73],[1,1.98,120.38],[2,1.94,7.56]],"batl":[[0,2.06,7.57],[1,2.1,2.05],[2,2.12,2.21]],"ltp":2.0,"tv":2803.74,"id":8284479}]}]}
{"op":"mcm","clk":"1007125230","pt":1580653075725,"mc":[{"id":"1.168236368","rc":[{"trd":[[2,1269.06]],"batb":[[0,1.98,120.38],[1,1.94,7.56],[2,1.86,327.09]],"batl":[[0,2.06,15.14]],"ltp":2.0,"tv":2809.19,"id":8284479}],"tv":6002.31}]}
{"op":"mcm","clk":"1007125445","pt":1580653077012,"mc":[{"id":"1.168236368","rc":[{"batl":[[0,2.04,7.56],[1,2.08,2],[2,2.1,2]],"ltp":1.94,"tv":3193.12,"id":4520808},{"batl":[[0,2.06,22.72]],"ltp":2.0,"tv":2809.19,"id":8284479}]}]}
{"op":"mcm","clk":"1007126037","pt":1580653080811,"mc":[{"id":"1.168236368","rc":[{"batl":[[0,2.06,30.29]],"ltp":2.0,"tv":2809.19,"id":8284479}]}]}
{"op":"mcm","clk":"1007126206","pt":1580653081696,"mc":[{"id":"1.168236368","rc":[{"batl":[[2,2.1,2.05]],"ltp":1.94,"tv":3193.12,"id":4520808}]}]}
{"op":"mcm","clk":"1007127308","pt":1580653088135,"mc":[{"id":"1.168236368","rc":[{"batl":[[0,2.06,37.86]],"ltp":2.0,"tv":2809.19,"id":8284479}]}]}
{"op":"mcm","clk":"1007127929","pt":1580653092065,"mc":[{"id":"1.168236368","rc":[{"batl":[[0,2.06,45.43]],"ltp":2.0,"tv":2809.19,"id":8284479}]}]}
{"op":"mcm","clk":"1007128282","pt":1580653094172,"mc":[{"id":"1.168236368","rc":[{"batl":[[0,2.1,2.05],[1,2.12,2.21],[2,4.2,153.72]],"ltp":2.0,"tv":2809.19,"id":8284479}]}]}
{"op":"mcm","clk":"1007128394","pt":1580653094771,"mc":[{"id":"1.168236368","rc":[{"batl":[[0,2.06,15.14],[1,2.1,2.05],[2,2.12,2.13]],"ltp":2.0,"tv":2809.19,"id":8284479}]}]}
{"op":"mcm","clk":"1007128627","pt":1580653095947,"mc":[{"id":"1.168236368","rc":[{"trd":[[2.06,331.79]],"batb":[[0,2,6.72],[1,1.98,120.38],[2,1.94,7.56]],"batl":[[0,2.06,8.62]],"ltp":2.06,"tv":2822.24,"id":8284479}],"tv":6015.37}]}
{"op":"mcm","clk":"1007128838","pt":1580653097058,"mc":[{"id":"1.168236368","rc":[{"batl":[[1,2.08,2.19]],"ltp":1.94,"tv":3193.12,"id":4520808},{"trd":[[2,1282.5]],"batb":[[0,1.98,120.38],[1,1.94,7.56],[2,1.86,327.09]],"ltp":2.0,"tv":2835.69,"id":8284479}],"tv":6028.82}]}
{"op":"mcm","clk":"1007129089","pt":1580653098469,"mc":[{"id":"1.168236368","rc":[{"batl":[[0,2.06,23.76]],"ltp":2.0,"tv":2835.69,"id":8284479}]}]}
{"op":"mcm","clk":"1007129486","pt":1580653101069,"mc":[{"id":"1.168236368","rc":[{"batl":[[2,2.1,2]],"ltp":1.94,"tv":3193.12,"id":4520808},{"batl":[[0,2.06,31.33],[2,2.12,2.21]],"ltp":2.0,"tv":2835.69,"id":8284479}]}]}
{"op":"mcm","clk":"1007130152","pt":1580653105674,"mc":[{"id":"1.168236368","rc":[{"batl":[[0,2.06,38.91]],"ltp":2.0,"tv":2835.69,"id":8284479}]}]}
{"op":"mcm","clk":"1007130649","pt":1580653109084,"mc":[{"id":"1.168236368","rc":[{"batl":[[0,2.1,2.05],[1,2.12,2.21],[2,4.2,153.72]],"ltp":2.0,"tv":2835.69,"id":8284479}]}]}
{"op":"mcm","clk":"1007130754","pt":1580653109788,"mc":[{"id":"1.168236368","rc":[{"batl":[[2,2.1,2.05]],"ltp":1.94,"tv":3193.12,"id":4520808},{"batl":[[0,2.06,22.72],[1,2.1,2.05],[2,2.12,2.21]],"ltp":2.0,"tv":2835.69,"id":8284479}]}]}
{"op":"mcm","clk":"1007131036","pt":1580653111668,"mc":[{"id":"1.168236368","rc":[{"batl":[[0,2.06,30.29]],"ltp":2.0,"tv":2835.69,"id":8284479}]}]}
{"op":"mcm","clk":"1007133123","pt":1580653126111,"mc":[{"id":"1.168236368","rc":[{"trd":[[2.06,400.94]],"batl":[[0,2.06,3.28],[2,2.12,2.13]],"ltp":2.06,"tv":2904.84,"id":8284479}],"tv":6097.97}]}
{"op":"mcm","clk":"1007133300","pt":1580653127098,"mc":[{"id":"1.168236368","rc":[{"trd":[[2,1353.73]],"ltp":2.0,"tv":2976.07,"id":8284479}],"tv":6169.2}]}
{"op":"mcm","clk":"1007133614","pt":1580653129227,"mc":[{"id":"1.168236368","rc":[{"batl":[[0,2.06,33.57]],"ltp":2.0,"tv":2976.07,"id":8284479}]}]}
{"op":"mcm","clk":"1007133870","pt":1580653130838,"mc":[{"id":"1.168236368","rc":[{"batl":[[0,2.06,41.14]],"ltp":2.0,"tv":2976.07,"id":8284479}]}]}
{"op":"mcm","clk":"1007134510","pt":1580653134843,"mc":[{"id":"1.168236368","rc":[{"batl":[[0,2.06,48.71]],"ltp":2.0,"tv":2976.07,"id":8284479}]}]}
{"op":"mcm","clk":"1007134949","pt":1580653137226,"mc":[{"id":"1.168236368","rc":[{"batl":[[0,2.06,15.14],[2,2.12,2.21]],"ltp":2.0,"tv":2976.07,"id":8284479}]}]}
{"op":"mcm","clk":"1007134964","pt":1580653137322,"mc":[{"id":"1.168236368","rc":[{"batl":[[0,2.06,22.72]],"ltp":2.0,"tv":2976.07,"id":8284479}]}]}
{"op":"mcm","clk":"1007135195","pt":1580653138814,"mc":[{"id":"1.168236368","rc":[{"batl":[[0,2.06,37.86]],"ltp":2.0,"tv":2976.07,"id":8284479}]}]}
{"op":"mcm","clk":"1007135720","pt":1580653142245,"mc":[{"id":"1.168236368","rc":[{"batl":[[2,2.6,74.66]],"ltp":1.94,"tv":3193.12,"id":4520808},{"batl":[[0,2.06,45.43]],"ltp":2.0,"tv":2976.07,"id":8284479}]}]}
{"op":"mcm","clk":"1007135796","pt":1580653142740,"mc":[{"id":"1.168236368","rc":[{"batl":[[2,2.1,2.05]],"ltp":1.94,"tv":3193.12,"id":4520808}]}]}
{"op":"mcm","clk":"1007135995","pt":1580653144147,"mc":[{"id":"1.168236368","rc":[{"batl":[[0,2.14,2.25],[1,2.16,2.22],[2,4.2,153.72]],"ltp":2.0,"tv":2976.07,"id":8284479}]}]}
{"op":"mcm","clk":"1007136059","pt":1580653144657,"mc":[{"id":"1.168236368","rc":[{"batl":[[0,2.06,7.57],[1,2.1,2.05],[2,2.12,2.05]],"ltp":2.0,"tv":2976.07,"id":8284479}]}]}
{"op":"mcm","clk":"1007136178","pt":1580653145448,"mc":[{"id":"1.168236368","rc":[{"batl":[[0,2.06,15.14]],"ltp":2.0,"tv":2976.07,"id":8284479}]}]}
{"op":"mcm","clk":"1007136391","pt":1580653146741,"mc":[{"id":"1.168236368","rc":[{"batl":[[0,2.06,22.72]],"ltp":2.0,"tv":2976.07,"id":8284479}]}]}
{"op":"mcm","clk":"1007136705","pt":1580653148983,"mc":[{"id":"1.168236368","rc":[{"batl":[[0,2.06,30.29]],"ltp":2.0,"tv":2976.07,"id":8284479}]}]}
{"op":"mcm","clk":"1007136849","pt":1580653149861,"mc":[{"id":"1.168236368","rc":[{"trd":[[2.06,457.03]],"batl":[[0,2.06,2.24]],"ltp":2.06,"tv":3032.16,"id":8284479}],"tv":6225.28}]}
{"op":"mcm","clk":"1007137051","pt":1580653151067,"mc":[{"id":"1.168236368","rc":[{"batl":[[0,2.04,9.69],[1,2.06,2.09],[2,2.08,2.19]],"ltp":1.94,"tv":3193.12,"id":4520808},{"batb":[[0,2,28.89],[1,1.98,120.38],[2,1.94,7.56]],"batl":[[2,2.12,2.21]],"ltp":2.06,"tv":3032.16,"id":8284479}]}]}
{"op":"mcm","clk":"1007137222","pt":1580653152081,"mc":[{"id":"1.168236368","rc":[{"batl":[[0,2.04,7.56],[1,2.08,2],[2,2.1,2.05]],"ltp":1.94,"tv":3193.12,"id":4520808},{"trd":[[2,1411.5]],"batb":[[0,1.98,120.38],[1,1.94,7.56],[2,1.86,327.09]],"ltp":2.0,"tv":3089.92,"id":8284479}],"tv":6283.05}]}
{"op":"mcm","clk":"1007137672","pt":1580653155242,"mc":[{"id":"1.168236368","rc":[{"batl":[[2,2.1,2]],"ltp":1.94,"tv":3193.12,"id":4520808},{"batl":[[0,2.06,24.96]],"ltp":2.0,"tv":3089.92,"id":8284479}]}]}
{"op":"mcm","clk":"1007138099","pt":1580653158048,"mc":[{"id":"1.168236368","rc":[{"batl":[[0,2.06,32.53],[2,2.12,2.05]],"ltp":2.0,"tv":3089.92,"id":8284479}]}]}
{"op":"mcm","clk":"1007138688","pt":1580653162242,"mc":[{"id":"1.168236368","rc":[{"batl":[[2,2.1,2.05]],"ltp":1.94,"tv":3193.12,"id":4520808},{"batl":[[0,2.06,40.1]],"ltp":2.0,"tv":3089.92,"id":8284479}]}]}
{"op":"mcm","clk":"1007138865","pt":1580653163367,"mc":[{"id":"1.168236368","rc":[{"batl":[[0,2.06,47.68]],"ltp":2.0,"tv":3089.92,"id":8284479}]}]}
{"op":"mcm","clk":"1007139399","pt":1580653167150,"mc":[{"id":"1.168236368","rc":[{"batl":[[0,2.14,2.25],[1,2.16,2.1],[2,4.2,153.72]],"ltp":2.0,"tv":3089.92,"id":8284479}]}]}
{"op":"mcm","clk":"1007139462","pt":1580653167663,"mc":[{"id":"1.168236368","rc":[{"batl":[[0,2.06,15.14],[1,2.1,2.05],[2,2.12,2.21]],"ltp":2.0,"tv":3089.92,"id":8284479}]}]}
{"op":"mcm","clk":"1007139642","pt":1580653169057,"mc":[{"id":"1.168236368","rc":[{"batl":[[0,2.06,22.72]],"ltp":2.0,"tv":3089.92,"id":8284479}]}]}
{"op":"mcm","clk":"1007139806","pt":1580653170164,"mc":[{"id":"1.168236368","rc":[{"trd":[[2.06,499.1]],"batb":[[0,1.94,7.56],[1,1.86,327.09],[2,1.85,26.72]],"batl":[[0,2.06,1.68],[1,2.14,2.18],[2,2.16,2.1]],"ltp":2.06,"tv":3131.99,"id":8284479}],"tv":6325.12}]}
{"op":"mcm","clk":"1007139948","pt":1580653170978,"mc":[{"id":"1.168236368","rc":[{"batb":[[0,1.91,22.59],[1,1.9,116.2],[2,1.89,420.1]],"batl":[[0,2.04,9.69],[1,2.06,2.25],[2,2.08,2]],"ltp":1.94,"tv":3193.12,"id":4520808},{"batb":[[0,2,21.66],[1,1.97,112.33],[2,1.94,7.56]],"batl":[[0,2.06,9.25],[1,2.1,2.05],[2,2.12,2.13]],"ltp":2.06,"tv":3131.99,"id":8284479}]}]}
{"op":"mcm","clk":"1007140158","pt":1580653171971,"mc":[{"id":"1.168236368","rc":[{"batl":[[0,2.04,7.56],[1,2.08,2],[2,2.1,2.05]],"ltp":1.94,"tv":3193.12,"id":4520808},{"trd":[[2,1454.82]],"batb":[[0,1.97,112.33],[1,1.94,7.56],[2,1.86,327.09]],"ltp":2.0,"tv":3175.31,"id":8284479}],"tv":6368.44}]}
{"op":"mcm","clk":"1007140371","pt":1580653173166,"mc":[{"id":"1.168236368","rc":[{"trd":[[2.06,515.92]],"batl":[[0,2.06,8.41]],"ltp":2.06,"tv":3192.14,"id":8284479}],"tv":6385.26}]}
{"op":"mcm","clk":"1007140473","pt":1580653173870,"mc":[{"id":"1.168236368","rc":[{"batl":[[0,2.04,9.69],[1,2.06,2.25],[2,2.08,2]],"ltp":1.94,"tv":3193.12,"id":4520808},{"batb":[[0,2,6.94],[1,1.97,112.33],[2,1.94,7.56]],"batl":[[0,2.06,15.99]],"ltp":2.06,"tv":3192.14,"id":8284479}]}]}
{"op":"mcm","clk":"1007140649","pt":1580653175172,"mc":[{"id":"1.168236368","rc":[{"batl":[[0,2.04,7.56],[1,2.08,2],[2,2.6,74.66]],"ltp":1.94,"tv":3193.12,"id":4520808},{"trd":[[2,1468.7]],"batb":[[0,2,1.73]],"ltp":2.0,"tv":3206.01,"id":8284479}],"tv":6399.14}]}
{"op":"mcm","clk":"1007140761","pt":1580653175880,"mc":[{"id":"1.168236368","rc":[{"batl":[[2,2.1,2.05]],"ltp":1.94,"tv":3193.12,"id":4520808},{"trd":[[2,1472.16]],"batb":[[0,1.97,112.33],[1,1.94,7.56],[2,1.86,327.09]],"batl":[[0,2.06,23.56]],"ltp":2.0,"tv":3209.48,"id":8284479}],"tv":6402.61}]}
{"op":"mcm","clk":"1007141114","pt":1580653178267,"mc":[{"id":"1.168236368","rc":[{"batl":[[0,2.06,31.13]],"ltp":2.0,"tv":3209.48,"id":8284479}]}]}
{"op":"mcm","clk":"1007141924","pt":1580653183184,"mc":[{"id":"1.168236368","rc":[{"batl":[[0,2.06,38.7]],"ltp":2.0,"tv":3209.48,"id":8284479}]}]}
{"op":"mcm","clk":"1007143314","pt":1580653191774,"mc":[{"id":"1.168236368","rc":[{"batl":[[0,2.06,46.27],[2,2.12,2.21]],"ltp":2.0,"tv":3209.48,"id":8284479}]}]}
{"op":"mcm","clk":"1007143737","pt":1580653194219,"mc":[{"id":"1.168236368","rc":[{"batl":[[0,2.06,53.85]],"ltp":2.0,"tv":3209.48,"id":8284479}]}]}
{"op":"mcm","clk":"1007144022","pt":1580653196011,"mc":[{"id":"1.168236368","rc":[{"trd":[[1.91,1235.87],[1.94,330.17]],"batb":[[0,1.91,10.07]],"ltp":1.91,"tv":3226.22,"id":4520808},{"trd":[[2.06,523.49]],"batl":[[0,2.14,2.25],[1,2.16,2.22],[2,4.2,153.72]],"ltp":2.06,"tv":3217.05,"id":8284479}],"tv":6443.27}]}
{"op":"mcm","clk":"1007144213","pt":1580653197229,"mc":[{"id":"1.168236368","rc":[{"batl":[[0,2.04,9.56],[1,2.06,2]],"ltp":1.91,"tv":3226.22,"id":4520808},{"batb":[[0,2,7.8],[1,1.97,112.33],[2,1.94,7.56]],"batl":[[0,2.06,7.57],[1,2.1,2.05],[2,2.12,2.05]],"ltp":2.06,"tv":3217.05,"id":8284479}]}]}
{"op":"mcm","clk":"1007144380","pt":1580653198210,"mc":[{"id":"1.168236368","rc":[{"batl":[[1,2.08,2.19],[2,2.6,74.66]],"ltp":1.91,"tv":3226.22,"id":4520808},{"trd":[[2,1487.76]],"batb":[[0,1.97,112.33],[1,1.94,7.56],[2,1.86,327.09]],"batl":[[0,2.06,15.14]],"ltp":2.0,"tv":3232.65,"id":8284479}],"tv":6458.87}]}
{"op":"mcm","clk":"1007144432","pt":1580653198490,"mc":[{"id":"1.168236368","rc":[{"batl":[[0,2.04,7.56],[2,2.1,2.05]],"ltp":1.91,"tv":3226.22,"id":4520808},{"batb":[[0,1.97,124.2]],"ltp":2.0,"tv":3232.65,"id":8284479}]}]}
{"op":"mcm","clk":"1007144589","pt":1580653199503,"mc":[{"id":"1.168236368","rc":[{"batl":[[0,2.06,22.72]],"ltp":2.0,"tv":3232.65,"id":8284479}]}]}
{"op":"mcm","clk":"1007145004","pt":1580653201612,"mc":[{"id":"1.168236368","rc":[{"batl":[[0,2.06,30.29]],"ltp":2.0,"tv":3232.65,"id":8284479}]}]}
{"op":"mcm","clk":"1007145417","pt":1580653204212,"mc":[{"id":"1.168236368","rc":[{"batl":[[0,2.06,37.86]],"ltp":2.0,"tv":3232.65,"id":8284479}]}]}
{"op":"mcm","clk":"1007145546","pt":1580653205010,"mc":[{"id":"1.168236368","rc":[{"batl":[[2,2.12,2.21]],"ltp":2.0,"tv":3232.65,"id":8284479}]}]}
{"op":"mcm","clk":"1007145919","pt":1580653207192,"mc":[{"id":"1.168236368","rc":[{"batl":[[0,2.06,7.57],[1,2.14,2.18],[2,2.18,2.14]],"ltp":2.0,"tv":3232.65,"id":8284479}]}]}
{"op":"mcm","clk":"1007145971","pt":1580653207510,"mc":[{"id":"1.168236368","rc":[{"batl":[[0,2.06,15.14],[1,2.1,2.05],[2,2.12,2.21]],"ltp":2.0,"tv":3232.65,"id":8284479}]}]}
{"op":"mcm","clk":"1007146137","pt":1580653208537,"mc":[{"id":"1.168236368","rc":[{"batl":[[0,2.06,30.29]],"ltp":2.0,"tv":3232.65,"id":8284479}]}]}
{"op":"mcm","clk":"1007147064","pt":1580653214098,"mc":[{"id":"1.168236368","rc":[{"batl":[[0,2.06,37.86]],"ltp":2.0,"tv":3232.65,"id":8284479}]}]}
{"op":"mcm","clk":"1007147132","pt":1580653214623,"mc":[{"id":"1.168236368","rc":[{"batl":[[2,2.1,2]],"ltp":1.91,"tv":3226.22,"id":4520808}]}]}
{"op":"mcm","clk":"1007147379","pt":1580653216129,"mc":[{"id":"1.168236368","rc":[{"batl":[[0,2.06,45.43]],"ltp":2.0,"tv":3232.65,"id":8284479}]}]}
{"op":"mcm","clk":"1007147752","pt":1580653218213,"mc":[{"id":"1.168236368","rc":[{"batl":[[0,2.14,2.25],[1,2.16,2.22],[2,4.2,153.72]],"ltp":2.0,"tv":3232.65,"id":8284479}]}]}
{"op":"mcm","clk":"1007147824","pt":1580653218601,"mc":[{"id":"1.168236368","rc":[{"batl":[[0,2.06,15.14],[1,2.1,2.05],[2,2.12,2.21]],"ltp":2.0,"tv":3232.65,"id":8284479}]}]}
{"op":"mcm","clk":"1007148050","pt":1580653220052,"mc":[{"id":"1.168236368","rc":[{"trd":[[2.06,564.66]],"batl":[[0,2.06,9.71]],"ltp":2.06,"tv":3273.81,"id":8284479}],"tv":6500.03}]}
{"op":"mcm","clk":"1007148203","pt":1580653221049,"mc":[{"id":"1.168236368","rc":[{"batl":[[0,2.04,9.56],[1,2.06,2],[2,2.08,2.19]],"ltp":1.91,"tv":3226.22,"id":4520808},{"batb":[[0,2,21.2],[1,1.97,124.2],[2,1.94,7.56]],"ltp":2.06,"tv":3273.81,"id":8284479}]}]}
{"op":"mcm","clk":"1007148403","pt":1580653222234,"mc":[{"id":"1.168236368","rc":[{"batl":[[2,2.6,74.66]],"ltp":1.91,"tv":3226.22,"id":4520808},{"trd":[[2,1530.16]],"batb":[[0,1.97,124.2],[1,1.94,7.56],[2,1.86,327.09]],"ltp":2.0,"tv":3316.21,"id":8284479}],"tv":6542.43}]}
{"op":"mcm","clk":"1007148446","pt":1580653222455,"mc":[{"id":"1.168236368","rc":[{"batl":[[0,2.04,7.56],[1,2.08,2],[2,2.1,2.05]],"ltp":1.91,"tv":3226.22,"id":4520808}]}]}
{"op":"mcm","clk":"1007148655","pt":1580653223720,"mc":[{"id":"1.168236368","rc":[{"batl":[[0,2.06,24.85]],"ltp":2.0,"tv":3316.21,"id":8284479}]}]}
{"op":"mcm","clk":"1007149066","pt":1580653226221,"mc":[{"id":"1.168236368","rc":[{"batl":[[0,2.06,55.14],[2,4.2,153.72]],"ltp":2.0,"tv":3316.21,"id":8284479}]}]}
{"op":"mcm","clk":"1007149108","pt":1580653226541,"mc":[{"id":"1.168236368","rc":[{"batl":[[2,2.12,2.21]],"ltp":2.0,"tv":3316.21,"id":8284479}]}]}
{"op":"mcm","clk":"1007149847","pt":1580653231067,"mc":[{"id":"1.168236368","rc":[{"batb":[[0,1.98,23.18],[1,1.97,124.2],[2,1.94,7.56]],"batl":[[0,2.06,62.71]],"ltp":2.0,"tv":3316.21,"id":8284479}]}]}
{"op":"mcm","clk":"1007150133","pt":1580653233036,"mc":[{"id":"1.168236368","rc":[{"batb":[[0,1.99,22.94],[1,1.98,23.18],[2,1.97,124.2]],"ltp":2.0,"tv":3316.21,"id":8284479}]}]}
{"op":"mcm","clk":"1007150278","pt":1580653233840,"mc":[{"id":"1.168236368","rc":[{"batl":[[1,2.06,2.09],[2,2.08,2.19]],"ltp":1.91,"tv":3226.22,"id":4520808}]}]}
{"op":"mcm","clk":"1007150460","pt":1580653235037,"mc":[{"id":"1.168236368","rc":[{"batl":[[1,2.08,2.19],[2,2.1,2.05]],"ltp":1.91,"tv":3226.22,"id":4520808},{"batb":[[0,2,22.72]],"ltp":2.0,"tv":3316.21,"id":8284479}]}]}
{"op":"mcm","clk":"1007150627","pt":1580653236061,"mc":[{"id":"1.168236368","rc":[{"trd":[[2,1575.6]],"batb":[[0,1.98,23.18],[1,1.97,124.2],[2,1.94,7.56]],"ltp":2.0,"tv":3361.64,"id":8284479}],"tv":6587.87}]}
{"op":"mcm","clk":"1007150960","pt":1580653237958,"mc":[{"id":"1.168236368","rc":[{"batl":[[0,2.06,85.43]],"ltp":2.0,"tv":3361.64,"id":8284479}]}]}
{"op":"mcm","clk":"1007151014","pt":1580653238250,"mc":[{"id":"1.168236368","rc":[{"batl":[[0,2.06,93]],"ltp":2.0,"tv":3361.64,"id":8284479}]}]}
{"op":"mcm","clk":"1007151405","pt":1580653240853,"mc":[{"id":"1.168236368","rc":[{"batl":[[0,2.06,100.58],[2,2.12,2.13]],"ltp":2.0,"tv":3361.64,"id":8284479}]}]}
{"op":"mcm","clk":"1007152066","pt":1580653245167,"mc":[{"id":"1.168236368","rc":[{"trd":[[2.06,751.84]],"batl":[[0,2.06,6.98],[1,2.08,22.72],[2,2.1,2.05]],"ltp":2.06,"tv":3548.83,"id":8284479}],"tv":6775.05}]}
{"op":"mcm","clk":"1007152137","pt":1580653245918,"mc":[{"id":"1.168236368","rc":[{"batb":[[0,2,46.8],[1,1.98,23.18],[2,1.97,124.2]],"batl":[[1,2.1,2.05],[2,2.12,2.13]],"ltp":2.06,"tv":3548.83,"id":8284479}]}]}
{"op":"mcm","clk":"1007152362","pt":1580653247065,"mc":[{"id":"1.168236368","rc":[{"batl":[[0,2.04,9.69],[1,2.06,2.09]],"ltp":1.91,"tv":3226.22,"id":4520808},{"trd":[[2,1669.21]],"batb":[[0,2,26.26]],"batl":[[2,2.12,2.21]],"ltp":2.0,"tv":3642.44,"id":8284479}],"tv":6868.66}]}
{"op":"mcm","clk":"1007152480","pt":1580653247873,"mc":[{"id":"1.168236368","rc":[{"trd":[[2,1721.74]],"batb":[[0,2,22.71]],"ltp":2.0,"tv":3694.97,"id":8284479}],"tv":6921.2}]}
{"op":"mcm","clk":"1007152644","pt":1580653249108,"mc":[{"id":"1.168236368","rc":[{"batl":[[0,2.04,7.56],[1,2.08,2]],"ltp":1.91,"tv":3226.22,"id":4520808},{"trd":[[2,1767.16]],"batb":[[0,1.98,23.18],[1,1.97,124.2],[2,1.94,7.56]],"ltp":2.0,"tv":3740.39,"id":8284479}],"tv":6966.62}]}
{"op":"mcm","clk":"1007152750","pt":1580653249764,"mc":[{"id":"1.168236368","rc":[{"batb":[[0,1.98,23.78]],"batl":[[0,2.06,29.7]],"ltp":2.0,"tv":3740.39,"id":8284479}]}]}
{"op":"mcm","clk":"1007153005","pt":1580653250859,"mc":[{"id":"1.168236368","rc":[{"batl":[[0,2.06,52.42]],"ltp":2.0,"tv":3740.39,"id":8284479}]}]}
{"op":"mcm","clk":"1007153359","pt":1580653252172,"mc":[{"id":"1.168236368","rc":[{"batb":[[0,2,23.32],[1,1.98,23.18],[2,1.97,124.2]],"batl":[[0,2.06,67.56]],"ltp":2.0,"tv":3740.39,"id":8284479}]}]}
{"op":"mcm","clk":"1007153562","pt":1580653253172,"mc":[{"id":"1.168236368","rc":[{"trd":[[2,1813.81]],"batb":[[0,1.98,23.18],[1,1.97,124.2],[2,1.94,7.56]],"batl":[[0,2.06,82.7]],"ltp":2.0,"tv":3787.04,"id":8284479}],"tv":7013.26}]}
{"op":"mcm","clk":"1007153655","pt":1580653253776,"mc":[{"id":"1.168236368","rc":[{"batl":[[0,2.06,105.42]],"ltp":2.0,"tv":3787.04,"id":8284479}]}]}
{"op":"mcm","clk":"1007153913","pt":1580653255380,"mc":[{"id":"1.168236368","rc":[{"batl":[[0,2.06,128.14]],"ltp":2.0,"tv":3787.04,"id":8284479}]}]}
{"op":"mcm","clk":"1007154339","pt":1580653258093,"mc":[{"id":"1.168236368","rc":[{"batl":[[2,2.6,74.66]],"ltp":1.91,"tv":3226.22,"id":4520808},{"batl":[[0,2.06,143.28]],"ltp":2.0,"tv":3787.04,"id":8284479}]}]}
{"op":"mcm","clk":"1007154486","pt":1580653258983,"mc":[{"id":"1.168236368","rc":[{"batl":[[2,2.1,2.05]],"ltp":1.91,"tv":3226.22,"id":4520808},{"batl":[[2,2.12,2.13]],"ltp":2.0,"tv":3787.04,"id":8284479}]}]}
{"op":"mcm","clk":"1007155285","pt":1580653263999,"mc":[{"id":"1.168236368","rc":[{"batl":[[0,2.06,90.87]],"ltp":2.0,"tv":3787.04,"id":8284479}]}]}
{"op":"mcm","clk":"1007155382","pt":1580653264705,"mc":[{"id":"1.168236368","rc":[{"batl":[[2,2.12,2.21]],"ltp":2.0,"tv":3787.04,"id":8284479}]}]}
{"op":"mcm","clk":"1007155750","pt":1580653266207,"mc":[{"id":"1.168236368","rc":[{"batl":[[0,2.06,106.01]],"ltp":2.0,"tv":3787.04,"id":8284479}]}]}
{"op":"mcm","clk":"1007155843","pt":1580653266692,"mc":[{"id":"1.168236368","rc":[{"trd":[[1.94,331.85]],"ltp":1.94,"tv":3227.9,"id":4520808},{"trd":[[2.06,753.42]],"batl":[[0,2.06,112]],"ltp":2.06,"tv":3788.62,"id":8284479}],"tv":7016.53}]}
{"op":"mcm","clk":"1007156094","pt":1580653268188,"mc":[{"id":"1.168236368","rc":[{"trd":[[2.06,963.12]],"batl":[[0,2.06,7.16],[1,2.1,47.48]],"ltp":2.06,"tv":3998.32,"id":8284479}],"tv":7226.22}]}
{"op":"mcm","clk":"1007156258","pt":1580653269210,"mc":[{"id":"1.168236368","rc":[{"batl":[[0,2.04,9.69],[1,2.06,2],[2,2.08,2]],"ltp":1.94,"tv":3227.9,"id":4520808},{"batb":[[0,2,15.6],[1,1.98,23.18],[2,1.97,124.2]],"ltp":2.06,"tv":3998.32,"id":8284479}]}]}
{"op":"mcm","clk":"1007156403","pt":1580653270167,"mc":[{"id":"1.168236368","rc":[{"batl":[[2,2.6,74.66]],"ltp":1.94,"tv":3227.9,"id":4520808},{"trd":[[2,1845.01]],"batb":[[0,2,70.87]],"batl":[[2,2.12,2.13]],"ltp":2.0,"tv":4029.53,"id":8284479}],"tv":7257.43}]}
{"op":"mcm","clk":"1007156538","pt":1580653270989,"mc":[{"id":"1.168236368","rc":[{"batl":[[0,2.04,7.56],[1,2.08,2.19],[2,2.1,2.05]],"ltp":1.94,"tv":3227.9,"id":4520808},{"trd":[[2,1986.75]],"batb":[[0,1.98,23.61],[1,1.97,124.2],[2,1.94,7.56]],"ltp":2.0,"tv":4171.27,"id":8284479}],"tv":7399.17}]}
{"op":"mcm","clk":"1007156740","pt":1580653272199,"mc":[{"id":"1.168236368","rc":[{"batl":[[0,2.06,52.59]],"ltp":2.0,"tv":4171.27,"id":8284479}]}]}
{"op":"mcm","clk":"1007156767","pt":1580653272301,"mc":[{"id":"1.168236368","rc":[{"batl":[[0,2.06,75.31]],"ltp":2.0,"tv":4171.27,"id":8284479}]}]}
{"op":"mcm","clk":"1007157116","pt":1580653274213,"mc":[{"id":"1.168236368","rc":[{"batl":[[0,2.06,98.02]],"ltp":2.0,"tv":4171.27,"id":8284479}]}]}
{"op":"mcm","clk":"1007157150","pt":1580653274380,"mc":[{"id":"1.168236368","rc":[{"batl":[[0,2.06,105.6]],"ltp":2.0,"tv":4171.27,"id":8284479}]}]}
{"op":"mcm","clk":"1007157428","pt":1580653276086,"mc":[{"id":"1.168236368","rc":[{"batl":[[0,2.04,9.56],[1,2.06,2.25],[2,2.6,74.66]],"ltp":1.94,"tv":3227.9,"id":4520808},{"batb":[[0,2,23.15],[1,1.98,23.18],[2,1.97,124.2]],"batl":[[0,2.06,113.17],[2,2.12,2.21]],"ltp":2.0,"tv":4171.27,"id":8284479}]}]}
{"op":"mcm","clk":"1007157608","pt":1580653277202,"mc":[{"id":"1.168236368","rc":[{"batl":[[2,2.08,2]],"ltp":1.94,"tv":3227.9,"id":4520808},{"trd":[[2,2033.05]],"batb":[[0,1.98,23.18],[1,1.97,124.2],[2,1.94,7.56]],"batl":[[0,2.06,128.31]],"ltp":2.0,"tv":4217.56,"id":8284479}],"tv":7445.47}]}
{"op":"mcm","clk":"1007157638","pt":1580653277403,"mc":[{"id":"1.168236368","rc":[{"batl":[[0,2.04,7.56],[1,2.08,2],[2,2.1,2]],"ltp":1.94,"tv":3227.9,"id":4520808}]}]}
{"op":"mcm","clk":"1007157858","pt":1580653278712,"mc":[{"id":"1.168236368","rc":[{"batl":[[0,2.06,135.89]],"ltp":2.0,"tv":4217.56,"id":8284479}]}]}
{"op":"mcm","clk":"1007158090","pt":1580653280202,"mc":[{"id":"1.168236368","rc":[{"batl":[[0,2.06,166.17]],"ltp":2.0,"tv":4217.56,"id":8284479}]}]}
{"op":"mcm","clk":"1007159046","pt":1580653285923,"mc":[{"id":"1.168236368","rc":[{"batl":[[2,2.1,2.05]],"ltp":1.94,"tv":3227.9,"id":4520808},{"batl":[[0,2.06,173.75],[2,2.12,2.13]],"ltp":2.0,"tv":4217.56,"id":8284479}]}]}
{"op":"mcm","clk":"1007160966","pt":1580653295924,"mc":[{"id":"1.168236368","rc":[{"batl":[[0,2.06,181.32],[2,2.12,2.21]],"ltp":2.0,"tv":4217.56,"id":8284479}]}]}
{"op":"mcm","clk":"1007161198","pt":1580653297213,"mc":[{"id":"1.168236368","rc":[{"batl":[[0,2.04,9.56],[1,2.06,2.09]],"ltp":1.94,"tv":3227.9,"id":4520808},{"trd":[[2.06,1302.14]],"batb":[[0,2,81],[1,1.98,23.18],[2,1.97,124.2]],"batl":[[0,2.06,11.81]],"ltp":2.06,"tv":4556.59,"id":8284479}],"tv":7784.49}]}
{"op":"mcm","clk":"1007161353","pt":1580653298024,"mc":[{"id":"1.168236368","rc":[{"batl":[[0,2.04,7.56],[1,2.08,2.07]],"ltp":1.94,"tv":3227.9,"id":4520808},{"trd":[[2,2195.03]],"batb":[[0,1.98,23.18],[1,1.97,124.2],[2,1.94,7.56]],"batl":[[0,2.06,11.83]],"ltp":2.0,"tv":4718.57,"id":8284479}],"tv":7946.47}]}
{"op":"mcm","clk":"1007162052","pt":1580653301930,"mc":[{"id":"1.168236368","rc":[{"batl":[[0,2.06,34.55]],"ltp":2.0,"tv":4718.57,"id":8284479}]}]}
{"op":"mcm","clk":"1007162158","pt":1580653302546,"mc":[{"id":"1.168236368","rc":[{"batl":[[0,2.06,57.26],[2,2.12,2.13]],"ltp":2.0,"tv":4718.57,"id":8284479}]}]}
{"op":"mcm","clk":"1007162442","pt":1580653304241,"mc":[{"id":"1.168236368","rc":[{"batl":[[0,2.06,79.98]],"ltp":2.0,"tv":4718.57,"id":8284479}]}]}
{"op":"mcm","clk":"1007163276","pt":1580653309135,"mc":[{"id":"1.168236368","rc":[{"batl":[[2,2.6,74.66]],"ltp":1.94,"tv":3227.9,"id":4520808},{"trd":[[2,2195.08]],"batb":[[0,2,48.14],[1,1.98,23.18],[2,1.97,124.2]],"batl":[[0,2.06,87.53],[2,4.2,153.72]],"ltp":2.0,"tv":4718.61,"id":8284479}],"tv":7946.52}]}
{"op":"mcm","clk":"1007163455","pt":1580653310148,"mc":[{"id":"1.168236368","rc":[{"batl":[[2,2.1,2]],"ltp":1.94,"tv":3227.9,"id":4520808},{"trd":[[2,2291.35]],"batb":[[0,2,22.72]],"batl":[[2,2.12,2.21]],"ltp":2.0,"tv":4814.88,"id":8284479}],"tv":8042.79}]}
{"op":"mcm","clk":"1007163619","pt":1580653311081,"mc":[{"id":"1.168236368","rc":[{"trd":[[2,2382.22],[2.06,1465.12]],"batb":[[0,2,82.36]],"batl":[[0,2.06,6.04]],"ltp":2.0,"tv":5068.73,"id":8284479}],"tv":8296.64}]}
{"op":"mcm","clk":"1007163853","pt":1580653312230,"mc":[{"id":"1.168236368","rc":[{"trd":[[2,2546.93]],"batb":[[0,1.98,23.18],[1,1.97,124.2],[2,1.94,7.56]],"batl":[[0,2.06,74.19]],"ltp":2.0,"tv":5233.44,"id":8284479}],"tv":8461.35}]}
{"op":"mcm","clk":"1007163873","pt":1580653312333,"mc":[{"id":"1.168236368","rc":[{"batb":[[0,2,1.58],[1,1.98,23.18],[2,1.97,124.2]],"batl":[[0,2.06,96.91]],"ltp":2.0,"tv":5233.44,"id":8284479}]}]}
{"op":"mcm","clk":"1007164118","pt":1580653313866,"mc":[{"id":"1.168236368","rc":[{"batl":[[0,2.06,112.06]],"ltp":2.0,"tv":5233.44,"id":8284479}]}]}
{"op":"mcm","clk":"1007164329","pt":1580653315054,"mc":[{"id":"1.168236368","rc":[{"batl":[[0,2.04,9.56],[1,2.06,2.09],[2,2.08,2.07]],"ltp":1.94,"tv":3227.9,"id":4520808},{"batb":[[0,2,24.29]],"batl":[[2,2.12,2.13]],"ltp":2.0,"tv":5233.44,"id":8284479}]}]}
{"op":"mcm","clk":"1007164558","pt":1580653316245,"mc":[{"id":"1.168236368","rc":[{"batl":[[0,2.04,7.56],[1,2.08,2.07],[2,2.1,2.05]],"ltp":1.94,"tv":3227.9,"id":4520808},{"trd":[[2,2595.52]],"batb":[[0,2.02,59.53],[2,1.94,7.56]],"batl":[[0,2.06,157.49]],"ltp":2.0,"tv":5282.03,"id":8284479}],"tv":8509.93}]}
{"op":"mcm","clk":"1007164754","pt":1580653317235,"mc":[{"id":"1.168236368","rc":[{"batb":[[0,1.9,76.72],[1,1.89,420.1],[2,1.81,37.86]],"batl":[[1,2.06,2],[2,2.08,2.07]],"ltp":1.94,"tv":3227.9,"id":4520808},{"trd":[[2.02,187.47]],"batb":[[0,1.98,23.18],[1,1.94,7.56],[2,1.87,78.94]],"batl":[[0,2.06,180.21]],"ltp":2.02,"tv":5401.08,"id":8284479}],"tv":8628.99}]}
{"op":"mcm","clk":"1007164844","pt":1580653317729,"mc":[{"id":"1.168236368","rc":[{"batb":[[0,1.95,40.18],[1,1.9,76.72],[2,1.89,420.1]],"batl":[[1,2.06,2.25]],"ltp":1.94,"tv":3227.9,"id":4520808},{"batb":[[0,1.99,38.04],[1,1.98,23.18],[2,1.94,7.56]],"ltp":2.02,"tv":5401.08,"id":8284479}]}]}
{"op":"mcm","clk":"1007164966","pt":1580653318506,"mc":[{"id":"1.168236368","rc":[{"batl":[[0,2.06,202.92]],"ltp":2.02,"tv":5401.08,"id":8284479}]}]}
{"op":"mcm","clk":"1007165420","pt":1580653321143,"mc":[{"id":"1.168236368","rc":[{"batl":[[0,2.06,225.64]],"ltp":2.02,"tv":5401.08,"id":8284479}]}]}
{"op":"mcm","clk":"1007165550","pt":1580653322056,"mc":[{"id":"1.168236368","rc":[{"batl":[[2,2.08,2.19]],"ltp":1.94,"tv":3227.9,"id":4520808},{"batl":[[2,2.12,2.21]],"ltp":2.02,"tv":5401.08,"id":8284479}]}]}
{"op":"mcm","clk":"1007165895","pt":1580653324077,"mc":[{"id":"1.168236368","rc":[{"batb":[[1,1.96,47.33]],"ltp":2.02,"tv":5401.08,"id":8284479}]}]}
{"op":"mcm","clk":"1007166659","pt":1580653329074,"mc":[{"id":"1.168236368","rc":[{"batl":[[2,2.08,2.07]],"ltp":1.94,"tv":3227.9,"id":4520808},{"batl":[[0,2.06,248.36]],"ltp":2.02,"tv":5401.08,"id":8284479}]}]}
{"op":"mcm","clk":"1007167253","pt":1580653332796,"mc":[{"id":"1.168236368","rc":[{"batl":[[1,2.08,22.72],[2,2.1,47.48]],"ltp":2.02,"tv":5401.08,"id":8284479}]}]}
{"op":"mcm","clk":"1007167473","pt":1580653334164,"mc":[{"id":"1.168236368","rc":[{"trd":[[1.95,190.66]],"batb":[[0,1.93,30.58]],"batl":[[2,2.08,4.38]],"ltp":1.95,"tv":3302.86,"id":4520808},{"batb":[[0,1.97,100.78]],"batl":[[1,2.1,47.48],[2,2.12,4.26]],"ltp":2.02,"tv":5401.08,"id":8284479}],"tv":8703.95}]}
{"op":"mcm","clk":"1007167502","pt":1580653334292,"mc":[{"id":"1.168236368","rc":[{"batl":[[1,2.08,4.38],[2,2.1,2.05]],"ltp":1.95,"tv":3302.86,"id":4520808}]}]}
{"op":"mcm","clk":"1007168304","pt":1580653339181,"mc":[{"id":"1.168236368","rc":[{"batl":[[1,2.08,2.19]],"ltp":1.95,"tv":3302.86,"id":4520808},{"batl":[[0,2.06,271.07],[2,2.12,2.05]],"ltp":2.02,"tv":5401.08,"id":8284479}]}]}
{"op":"mcm","clk":"1007168594","pt":1580653341044,"mc":[{"id":"1.168236368","rc":[{"batl":[[1,2.08,22.72],[2,2.1,47.48]],"ltp":2.02,"tv":5401.08,"id":8284479}]}]}
{"op":"mcm","clk":"1007168663","pt":1580653341425,"mc":[{"id":"1.168236368","rc":[{"batl":[[1,2.1,47.48],[2,2.12,2.21]],"ltp":2.02,"tv":5401.08,"id":8284479}]}]}
{"op":"mcm","clk":"1007168893","pt":1580653342787,"mc":[{"id":"1.168236368","rc":[{"batb":[[0,1.98,46.36],[1,1.97,100.78],[2,1.96,47.33]],"ltp":2.02,"tv":5401.08,"id":8284479}]}]}
{"op":"mcm","clk":"1007169091","pt":1580653344107,"mc":[{"id":"1.168236368","rc":[{"batb":[[2,1.94,7.56]],"ltp":2.02,"tv":5401.08,"id":8284479}]}]}
{"op":"mcm","clk":"1007169184","pt":1580653344892,"mc":[{"id":"1.168236368","rc":[{"batl":[[0,2.06,136.3]],"ltp":2.02,"tv":5401.08,"id":8284479}]}]}
{"op":"mcm","clk":"1007169398","pt":1580653346176,"mc":[{"id":"1.168236368","rc":[{"batl":[[0,2.04,22.72],[1,2.06,136.3],[2,2.08,2.19]],"ltp":2.02,"tv":5401.08,"id":8284479}]}]}
{"op":"mcm","clk":"1007169588","pt":1580653347605,"mc":[{"id":"1.168236368","rc":[{"batl":[[0,2.04,89.54]],"ltp":2.02,"tv":5401.08,"id":8284479}]}]}
{"op":"mcm","clk":"1007169904","pt":1580653349485,"mc":[{"id":"1.168236368","rc":[{"batl":[[0,2.04,112.25]],"ltp":2.02,"tv":5401.08,"id":8284479}]}]}
{"op":"mcm","clk":"1007170612","pt":1580653353984,"mc":[{"id":"1.168236368","rc":[{"batl":[[2,2.08,24.91]],"ltp":2.02,"tv":5401.08,"id":8284479}]}]}
{"op":"mcm","clk":"1007170728","pt":1580653354845,"mc":[{"id":"1.168236368","rc":[{"batl":[[2,2.08,2.19]],"ltp":2.02,"tv":5401.08,"id":8284479}]}]}
{"op":"mcm","clk":"1007171060","pt":1580653356954,"mc":[{"id":"1.168236368","rc":[{"batl":[[0,2.04,134.97]],"ltp":2.02,"tv":5401.08,"id":8284479}]}]}
{"op":"mcm","clk":"1007171193","pt":1580653357626,"mc":[{"id":"1.168236368","rc":[{"trd":[[2.04,1110.47]],"batl":[[0,2.04,9.39],[2,2.08,47.62]],"ltp":2.04,"tv":5652.25,"id":8284479}],"tv":8955.12}]}
{"op":"mcm","clk":"1007171351","pt":1580653358826,"mc":[{"id":"1.168236368","rc":[{"batl":[[0,2.04,9.56],[1,2.06,2.25]],"ltp":1.95,"tv":3302.86,"id":4520808},{"batb":[[0,2,59.93],[1,1.98,46.36],[2,1.97,100.78]],"batl":[[2,2.08,2.19]],"ltp":2.04,"tv":5652.25,"id":8284479}]}]}
{"op":"mcm","clk":"1007171511","pt":1580653359887,"mc":[{"id":"1.168236368","rc":[{"batl":[[2,2.6,74.66]],"ltp":1.95,"tv":3302.86,"id":4520808},{"batb":[[0,2,128.09]],"ltp":2.04,"tv":5652.25,"id":8284479}]}]}
{"op":"mcm","clk":"1007171882","pt":1580653362121,"mc":[{"id":"1.168236368","rc":[{"batl":[[0,2.1,47.48],[1,2.12,2.21],[2,4.2,153.72]],"ltp":2.04,"tv":5652.25,"id":8284479}]}]}
{"op":"mcm","clk":"1007171926","pt":1580653362348,"mc":[{"id":"1.168236368","rc":[{"batl":[[0,2.1,45.43],[2,2.14,2.25]],"ltp":2.04,"tv":5652.25,"id":8284479}]}]}
{"op":"mcm","clk":"1007172883","pt":1580653368241,"mc":[{"id":"1.168236368","rc":[{"batl":[[1,2.06,2]],"ltp":1.95,"tv":3302.86,"id":4520808},{"batb":[[0,2,68.15]],"batl":[[2,2.14,2.18]],"ltp":2.04,"tv":5652.25,"id":8284479}]}]}
{"op":"mcm","clk":"1007173003","pt":1580653368953,"mc":[{"id":"1.168236368","rc":[{"batb":[[0,2.02,59.34],[1,2,68.15],[2,1.98,46.36]],"ltp":2.04,"tv":5652.25,"id":8284479}]}]}
{"op":"mcm","clk":"1007173160","pt":1580653369880,"mc":[{"id":"1.168236368","rc":[{"batl":[[0,2.02,2.25],[1,2.04,9.56],[2,2.06,2]],"ltp":1.95,"tv":3302.86,"id":4520808}]}]}
{"op":"mcm","clk":"1007173441","pt":1580653371659,"mc":[{"id":"1.168236368","rc":[{"batl":[[0,2.12,2.21],[1,2.14,2.18],[2,4.2,153.72]],"ltp":2.04,"tv":5652.25,"id":8284479}]}]}
{"op":"mcm","clk":"1007173587","pt":1580653372611,"mc":[{"id":"1.168236368","rc":[{"batb":[[1,1.98,46.36],[2,1.97,100.78]],"ltp":2.04,"tv":5652.25,"id":8284479}]}]}
{"op":"mcm","clk":"1007173804","pt":1580653374125,"mc":[{"id":"1.168236368","rc":[{"batb":[[0,2.04,21.85],[1,2.02,59.34],[2,1.98,46.36]],"ltp":2.04,"tv":5652.25,"id":8284479}]}]}
{"op":"mcm","clk":"1007173910","pt":1580653375044,"mc":[{"id":"1.168236368","rc":[{"batl":[[0,1.99,2.26],[1,2,2],[2,2.04,7.56]],"ltp":1.95,"tv":3302.86,"id":4520808},{"batl":[[1,2.14,2.25]],"ltp":2.04,"tv":5652.25,"id":8284479}]}]}
{"op":"mcm","clk":"1007174855","pt":1580653381216,"mc":[{"id":"1.168236368","rc":[{"batb":[[1,2,59.34]],"ltp":2.04,"tv":5652.25,"id":8284479}]}]}
{"op":"mcm","clk":"1007174926","pt":1580653381548,"mc":[{"id":"1.168236368","rc":[{"trd":[[1.93,61.54]],"batb":[[0,1.93,2.46]],"ltp":1.93,"tv":3359.1,"id":4520808}],"tv":9011.36}]}
{"op":"mcm","clk":"1007175930","pt":1580653388048,"mc":[{"id":"1.168236368","rc":[{"batb":[[0,1.91,31.17]],"ltp":1.93,"tv":3359.1,"id":4520808},{"batb":[[1,2.02,63.01],[2,2,59.34]],"batl":[[0,2.14,2.18],[1,2.16,2.22]],"ltp":2.04,"tv":5652.25,"id":8284479}]}]}
{"op":"mcm","clk":"1007177794","pt":1580653399194,"mc":[{"id":"1.168236368","rc":[{"batb":[[2,1.98,46.36]],"ltp":2.04,"tv":5652.25,"id":8284479}]}]}
{"op":"mcm","clk":"1007178035","pt":1580653400461,"mc":[{"id":"1.168236368","rc":[{"batb":[[0,2.04,80.61]],"ltp":2.04,"tv":5652.25,"id":8284479}]}]}
{"op":"mcm","clk":"1007178450","pt":1580653403195,"mc":[{"id":"1.168236368","rc":[{"batb":[[0,2.04,21.85]],"ltp":2.04,"tv":5652.25,"id":8284479}]}]}
{"op":"mcm","clk":"1007178920","pt":1580653406103,"mc":[{"id":"1.168236368","rc":[{"batb":[[0,2.04,44.56]],"ltp":2.04,"tv":5652.25,"id":8284479}]}]}
{"op":"mcm","clk":"1007179064","pt":1580653406966,"mc":[{"id":"1.168236368","rc":[{"trd":[[1.91,1294.01]],"batb":[[0,1.91,2.1]],"ltp":1.91,"tv":3417.24,"id":4520808},{"batl":[[0,2.16,2.22],[1,2.18,2.03]],"ltp":2.04,"tv":5652.25,"id":8284479}],"tv":9069.5}]}
{"op":"mcm","clk":"1007179149","pt":1580653407610,"mc":[{"id":"1.168236368","rc":[{"batb":[[2,2,22.72]],"ltp":2.04,"tv":5652.25,"id":8284479}]}]}
{"op":"mcm","clk":"1007179562","pt":1580653410188,"mc":[{"id":"1.168236368","rc":[{"batb":[[0,1.9,76.72],[1,1.89,420.1],[2,1.83,135.78]],"batl":[[0,1.97,2.16],[1,1.98,2.13],[2,1.99,2.26]],"ltp":1.91,"tv":3417.24,"id":4520808},{"batb":[[0,2.06,34.57],[1,2.04,44.56]],"ltp":2.04,"tv":5652.25,"id":8284479}]}]}
{"op":"mcm","clk":"1007179608","pt":1580653410508,"mc":[{"id":"1.168236368","rc":[{"batl":[[2,2,2]],"ltp":1.91,"tv":3417.24,"id":4520808}]}]}
{"op":"mcm","clk":"1007179965","pt":1580653412994,"mc":[{"id":"1.168236368","rc":[{"batl":[[2,2.04,7.56]],"ltp":1.91,"tv":3417.24,"id":4520808},{"batb":[[1,2.04,21.85]],"batl":[[1,4.2,153.72],[2,95,15.9]],"ltp":2.04,"tv":5652.25,"id":8284479}]}]}
{"op":"mcm","clk":"1007180035","pt":1580653413414,"mc":[{"id":"1.168236368","rc":[{"batl":[[1,2.18,2.03],[2,4.2,153.72]],"ltp":2.04,"tv":5652.25,"id":8284479}]}]}
{"op":"mcm","clk":"1007183039","pt":1580653433213,"mc":[{"id":"1.168236368","rc":[{"batb":[[2,1.98,46.36]],"ltp":2.04,"tv":5652.25,"id":8284479}]}]}
{"op":"mcm","clk":"1007183175","pt":1580653434217,"mc":[{"id":"1.168236368","rc":[{"trd":[[1.9,834.42]],"batb":[[0,1.9,5.42]],"batl":[[1,2.04,7.56],[2,2.6,74.66]],"ltp":1.9,"tv":3559.84,"id":4520808},{"batl":[[1,4.2,153.72],[2,95,15.9]],"ltp":2.04,"tv":5652.25,"id":8284479}],"tv":9212.1}]}
{"op":"mcm","clk":"1007183207","pt":1580653434435,"mc":[{"id":"1.168236368","rc":[{"batl":[[1,1.98,2.25],[2,2.04,7.56]],"ltp":1.9,"tv":3559.84,"id":4520808},{"batl":[[1,2.18,2.03],[2,4.2,153.72]],"ltp":2.04,"tv":5652.25,"id":8284479}]}]}
{"op":"mcm","clk":"1007184344","pt":1580653442245,"mc":[{"id":"1.168236368","rc":[{"batb":[[1,1.98,46.36],[2,1.94,7.56]],"ltp":2.04,"tv":5652.25,"id":8284479}]}]}
{"op":"mcm","clk":"1007184419","pt":1580653442624,"mc":[{"id":"1.168236368","rc":[{"batl":[[1,1.98,2.2]],"ltp":1.9,"tv":3559.84,"id":4520808}]}]}
{"op":"mcm","clk":"1007185418","pt":1580653449055,"mc":[{"id":"1.168236368","rc":[{"batl":[[1,2.04,7.56],[2,2.6,74.66]],"ltp":1.9,"tv":3559.84,"id":4520808},{"batb":[[1,1.94,7.56],[2,1.87,157.27]],"batl":[[1,4.2,153.72],[2,95,15.9]],"ltp":2.04,"tv":5652.25,"id":8284479}]}]}
{"op":"mcm","clk":"1007185483","pt":1580653449454,"mc":[{"id":"1.168236368","rc":[{"batl":[[1,1.98,2.06],[2,2.04,7.56]],"ltp":1.9,"tv":3559.84,"id":4520808},{"batb":[[1,2.02,59.34],[2,1.96,47.33]],"batl":[[1,2.18,2.03],[2,4.2,153.72]],"ltp":2.04,"tv":5652.25,"id":8284479}]}]}
{"op":"mcm","clk":"1007186871","pt":1580653458162,"mc":[{"id":"1.168236368","rc":[{"batl":[[1,1.99,2.14],[2,2,2]],"ltp":1.9,"tv":3559.84,"id":4520808},{"batb":[[0,2.04,58.22]],"ltp":2.04,"tv":5652.25,"id":8284479}]}]}
{"op":"mcm","clk":"1007186968","pt":1580653458759,"mc":[{"id":"1.168236368","rc":[{"batl":[[0,1.99,2.22],[1,2,2],[2,2.02,2.25]],"ltp":1.9,"tv":3559.84,"id":4520808}]}]}
{"op":"mcm","clk":"1007187366","pt":1580653461584,"mc":[{"id":"1.168236368","rc":[{"batb":[[1,2,59.34]],"ltp":2.04,"tv":5652.25,"id":8284479}]}]}
{"op":"mcm","clk":"1007188204","pt":1580653467044,"mc":[{"id":"1.168236368","rc":[{"batl":[[1,2.04,7.56],[2,2.1,50.41]],"ltp":1.9,"tv":3559.84,"id":4520808},{"batl":[[1,4.2,153.72],[2,95,15.9]],"ltp":2.04,"tv":5652.25,"id":8284479}]}]}
{"op":"mcm","clk":"1007188233","pt":1580653467257,"mc":[{"id":"1.168236368","rc":[{"batl":[[1,2,2],[2,2.04,7.56]],"ltp":1.9,"tv":3559.84,"id":4520808},{"batl":[[1,2.18,2.03],[2,4.2,153.72]],"ltp":2.04,"tv":5652.25,"id":8284479}]}]}
{"op":"mcm","clk":"1007197247","pt":1580653526182,"mc":[{"id":"1.168236368","rc":[{"batb":[[1,1.96,47.33],[2,1.94,7.56]],"ltp":2.04,"tv":5652.25,"id":8284479}]}]}
{"op":"mcm","clk":"1007198890","pt":1580653537062,"mc":[{"id":"1.168236368","rc":[{"batl":[[0,2.1,3.03],[1,2.16,2.22],[2,2.18,2.03]],"ltp":2.04,"tv":5652.25,"id":8284479}]}]}
{"op":"mcm","clk":"1007199052","pt":1580653537979,"mc":[{"id":"1.168236368","rc":[{"batl":[[1,2.14,2.25],[2,2.16,2.16]],"ltp":2.04,"tv":5652.25,"id":8284479}]}]}
{"op":"mcm","clk":"1007199535","pt":1580653540979,"mc":[{"id":"1.168236368","rc":[{"batb":[[0,2.04,64.27]],"ltp":2.04,"tv":5652.25,"id":8284479}]}]}
{"op":"mcm","clk":"1007199692","pt":1580653542171,"mc":[{"id":"1.168236368","rc":[{"batb":[[1,2.02,3.03],[2,1.96,47.33]],"ltp":2.04,"tv":5652.25,"id":8284479}]}]}
{"op":"mcm","clk":"1007199725","pt":1580653542334,"mc":[{"id":"1.168236368","rc":[{"batb":[[1,2.02,6.06]],"ltp":2.04,"tv":5652.25,"id":8284479}]}]}
{"op":"mcm","clk":"1007200303","pt":1580653546179,"mc":[{"id":"1.168236368","rc":[{"batl":[[1,2.04,7.56],[2,2.1,50.41]],"ltp":1.9,"tv":3559.84,"id":4520808},{"batb":[[1,2.02,9.09]],"batl":[[2,4.2,153.72]],"ltp":2.04,"tv":5652.25,"id":8284479}]}]}
{"op":"mcm","clk":"1007200340","pt":1580653546363,"mc":[{"id":"1.168236368","rc":[{"batl":[[1,2,2],[2,2.04,7.56]],"ltp":1.9,"tv":3559.84,"id":4520808},{"batl":[[2,2.16,2.16]],"ltp":2.04,"tv":5652.25,"id":8284479}]}]}
{"op":"mcm","clk":"1007200843","pt":1580653549769,"mc":[{"id":"1.168236368","rc":[{"batb":[[1,2,9.09]],"ltp":2.04,"tv":5652.25,"id":8284479}]}]}
{"op":"mcm","clk":"1007207847","pt":1580653596856,"mc":[{"id":"1.168236368","rc":[{"batl":[[2,2.16,2.22]],"ltp":2.04,"tv":5652.25,"id":8284479}]}]}
{"op":"mcm","clk":"1007208315","pt":1580653600046,"mc":[{"id":"1.168236368","rc":[{"batb":[[0,2.04,6.06],[1,2.02,82.68],[2,2,9.09]],"ltp":2.04,"tv":5652.25,"id":8284479}]}]}
{"op":"mcm","clk":"1007209186","pt":1580653605887,"mc":[{"id":"1.168236368","rc":[{"batb":[[2,1.98,9.09]],"ltp":2.04,"tv":5652.25,"id":8284479}]}]}
{"op":"mcm","clk":"1007209529","pt":1580653608146,"mc":[{"id":"1.168236368","rc":[{"batb":[[0,2.02,82.68],[1,1.98,9.09],[2,1.96,47.33]],"ltp":2.04,"tv":5652.25,"id":8284479}]}]}
{"op":"mcm","clk":"1007209629","pt":1580653608794,"mc":[{"id":"1.168236368","rc":[{"batl":[[0,2.02,2],[1,2.04,9.56],[2,2.1,50.41]],"ltp":1.9,"tv":3559.84,"id":4520808},{"batb":[[0,2.02,88.73]],"ltp":2.04,"tv":5652.25,"id":8284479}]}]}
{"op":"mcm","clk":"1007210333","pt":1580653612979,"mc":[{"id":"1.168236368","rc":[{"batb":[[0,2.02,91.76]],"ltp":2.04,"tv":5652.25,"id":8284479}]}]}
{"op":"mcm","clk":"1007212075","pt":1580653624001,"mc":[{"id":"1.168236368","rc":[{"batl":[[0,2.14,2.25],[1,2.16,2.22],[2,4.2,153.72]],"ltp":2.04,"tv":5652.25,"id":8284479}]}]}
{"op":"mcm","clk":"1007212167","pt":1580653624492,"mc":[{"id":"1.168236368","rc":[{"batl":[[1,2.04,9.69]],"ltp":1.9,"tv":3559.84,"id":4520808},{"batl":[[0,2.16,2.22],[1,2.18,2.03]],"ltp":2.04,"tv":5652.25,"id":8284479}]}]}
{"op":"mcm","clk":"1007212437","pt":1580653626100,"mc":[{"id":"1.168236368","rc":[{"batl":[[0,1.99,2.2],[1,2,2],[2,2.04,9.69]],"ltp":1.9,"tv":3559.84,"id":4520808},{"batb":[[0,2.06,3.03],[1,2.04,6.06],[2,2.02,91.76]],"ltp":2.04,"tv":5652.25,"id":8284479}]}]}
{"op":"mcm","clk":"1007212483","pt":1580653626375,"mc":[{"id":"1.168236368","rc":[{"batl":[[0,1.97,2.16],[1,1.98,2.25],[2,1.99,2.2]],"ltp":1.9,"tv":3559.84,"id":4520808}]}]}
{"op":"mcm","clk":"1007213402","pt":1580653631986,"mc":[{"id":"1.168236368","rc":[{"batl":[[1,1.98,2.05],[2,2.04,7.56]],"ltp":1.9,"tv":3559.84,"id":4520808},{"batb":[[1,2.04,15.14],[2,2.02,82.68]],"ltp":2.04,"tv":5652.25,"id":8284479}]}]}
{"op":"mcm","clk":"1007213742","pt":1580653634098,"mc":[{"id":"1.168236368","rc":[{"batb":[[0,2.02,82.68],[1,1.96,47.33],[2,1.94,7.56]],"ltp":2.04,"tv":5652.25,"id":8284479}]}]}
{"op":"mcm","clk":"1007213943","pt":1580653635114,"mc":[{"id":"1.168236368","rc":[{"batl":[[0,2.04,7.56],[1,2.06,2.09],[2,2.08,2.19]],"ltp":1.9,"tv":3559.84,"id":4520808}]}]}
{"op":"mcm","clk":"1007214021","pt":1580653635711,"mc":[{"id":"1.168236368","rc":[{"batl":[[0,1.99,2.09],[1,2,2],[2,2.02,2.25]],"ltp":1.9,"tv":3559.84,"id":4520808},{"batb":[[0,2.04,58.76],[1,2.02,82.68],[2,1.96,47.33]],"ltp":2.04,"tv":5652.25,"id":8284479}]}]}
{"op":"mcm","clk":"1007216466","pt":1580653651221,"mc":[{"id":"1.168236368","rc":[{"batl":[[1,2.04,7.56],[2,2.1,50.41]],"ltp":1.9,"tv":3559.84,"id":4520808},{"batl":[[1,4.2,153.72],[2,95,15.9]],"ltp":2.04,"tv":5652.25,"id":8284479}]}]}
{"op":"mcm","clk":"1007216505","pt":1580653651432,"mc":[{"id":"1.168236368","rc":[{"batl":[[1,2,2],[2,2.04,7.56]],"ltp":1.9,"tv":3559.84,"id":4520808},{"batl":[[1,2.18,2.03],[2,4.2,153.72]],"ltp":2.04,"tv":5652.25,"id":8284479}]}]}
{"op":"mcm","clk":"1007232047","pt":1580653746107,"mc":[{"id":"1.168236368","rc":[{"batl":[[1,2.04,7.56],[2,2.1,50.41]],"ltp":1.9,"tv":3559.84,"id":4520808},{"batb":[[0,2.06,34.57],[1,2.04,58.76]],"batl":[[1,4.2,153.72],[2,95,15.9]],"ltp":2.04,"tv":5652.25,"id":8284479}]}]}
{"op":"mcm","clk":"1007232097","pt":1580653746426,"mc":[{"id":"1.168236368","rc":[{"batl":[[0,1.97,2.01],[1,1.98,2.25],[2,2.04,7.56]],"ltp":1.9,"tv":3559.84,"id":4520808},{"batl":[[1,2.18,2.03],[2,4.2,153.72]],"ltp":2.04,"tv":5652.25,"id":8284479}]}]}
{"op":"mcm","clk":"1007232650","pt":1580653749758,"mc":[{"id":"1.168236368","rc":[{"batb":[[0,2.06,93.33],[1,1.96,47.33],[2,1.94,7.56]],"ltp":2.04,"tv":5652.25,"id":8284479}]}]}
{"op":"mcm","clk":"1007233516","pt":1580653754242,"mc":[{"id":"1.168236368","rc":[{"batl":[[0,1.95,2.1],[1,1.96,2.12]],"ltp":1.9,"tv":3559.84,"id":4520808},{"batb":[[0,2.08,3.03],[1,2.06,93.33],[2,1.96,47.33]],"ltp":2.04,"tv":5652.25,"id":8284479}]}]}
{"op":"mcm","clk":"1007233828","pt":1580653756046,"mc":[{"id":"1.168236368","rc":[{"batb":[[1,2.06,34.57]],"ltp":2.04,"tv":5652.25,"id":8284479}]}]}
{"op":"mcm","clk":"1007234371","pt":1580653759228,"mc":[{"id":"1.168236368","rc":[{"batb":[[0,2.08,6.06]],"ltp":2.04,"tv":5652.25,"id":8284479}]}]}
{"op":"mcm","clk":"1007234457","pt":1580653759838,"mc":[{"id":"1.168236368","rc":[{"batb":[[0,2.08,9.09]],"ltp":2.04,"tv":5652.25,"id":8284479}]}]}
{"op":"mcm","clk":"1007234564","pt":1580653760424,"mc":[{"id":"1.168236368","rc":[{"batb":[[1,2.06,40.62]],"ltp":2.04,"tv":5652.25,"id":8284479}]}]}
{"op":"mcm","clk":"1007234855","pt":1580653762047,"mc":[{"id":"1.168236368","rc":[{"batb":[[2,2.04,9.09]],"ltp":2.04,"tv":5652.25,"id":8284479}]}]}
{"op":"mcm","clk":"1007252825","pt":1580653874614,"mc":[{"id":"1.168236368","rc":[{"batl":[[1,2.04,7.56],[2,2.1,50.41]],"ltp":1.9,"tv":3559.84,"id":4520808},{"batl":[[1,4.2,153.72],[2,95,15.9]],"ltp":2.04,"tv":5652.25,"id":8284479}]}]}
{"op":"mcm","clk":"1007252945","pt":1580653875308,"mc":[{"id":"1.168236368","rc":[{"batl":[[1,1.96,2.12],[2,2.04,7.56]],"ltp":1.9,"tv":3559.84,"id":4520808},{"batl":[[1,2.18,2.03],[2,4.2,153.72]],"ltp":2.04,"tv":5652.25,"id":8284479}]}]}
{"op":"mcm","clk":"1007255378","pt":1580653888016,"mc":[{"id":"1.168236368","rc":[{"batb":[[1,2.06,6.06],[2,2.04,67.3]],"ltp":2.04,"tv":5652.25,"id":8284479}]}]}
{"op":"mcm","clk":"1007255867","pt":1580653891236,"mc":[{"id":"1.168236368","rc":[{"batb":[[0,2.06,6.06],[1,2.04,67.3],[2,2.02,9.09]],"ltp":2.04,"tv":5652.25,"id":8284479}]}]}
{"op":"mcm","clk":"1007256037","pt":1580653892234,"mc":[{"id":"1.168236368","rc":[{"batl":[[0,1.99,2.08],[1,2,2]],"ltp":1.9,"tv":3559.84,"id":4520808},{"batb":[[0,2.06,15.14]],"ltp":2.04,"tv":5652.25,"id":8284479}]}]}
{"op":"mcm","clk":"1007256082","pt":1580653892427,"mc":[{"id":"1.168236368","rc":[{"batl":[[0,1.97,2.16],[1,1.98,2.25],[2,1.99,2.08]],"ltp":1.9,"tv":3559.84,"id":4520808}]}]}
{"op":"mcm","clk":"1007266279","pt":1580653958800,"mc":[{"id":"1.168236368","rc":[{"batl":[[1,1.98,2.22],[2,2.04,7.56]],"ltp":1.9,"tv":3559.84,"id":4520808},{"batb":[[2,1.96,47.33]],"ltp":2.04,"tv":5652.25,"id":8284479}]}]}
{"op":"mcm","clk":"1007266496","pt":1580653960190,"mc":[{"id":"1.168236368","rc":[{"batb":[[2,1.97,6.06]],"ltp":2.04,"tv":5652.25,"id":8284479}]}]}
{"op":"mcm","clk":"1007266653","pt":1580653961086,"mc":[{"id":"1.168236368","rc":[{"batb":[[2,1.97,9.09]],"ltp":2.04,"tv":5652.25,"id":8284479}]}]}
{"op":"mcm","clk":"1007266754","pt":1580653961832,"mc":[{"id":"1.168236368","rc":[{"batb":[[2,1.97,18.17]],"ltp":2.04,"tv":5652.25,"id":8284479}]}]}
{"op":"mcm","clk":"1007270798","pt":1580653987834,"mc":[{"id":"1.168236368","rc":[{"trd":[[1.9,839.46]],"batb":[[0,1.9,2.9]],"ltp":1.9,"tv":3564.88,"id":4520808}],"tv":9217.14}]}
{"op":"mcm","clk":"1007270908","pt":1580653988441,"mc":[{"id":"1.168236368","rc":[{"batl":[[1,1.98,2.25]],"ltp":1.9,"tv":3564.88,"id":4520808}]}]}
{"op":"mcm","clk":"1007278288","pt":1580654032198,"mc":[{"id":"1.168236368","rc":[{"batl":[[1,2.04,7.56],[2,2.1,50.41]],"ltp":1.9,"tv":3564.88,"id":4520808},{"batb":[[0,2.06,18.17]],"batl":[[1,4.2,153.72],[2,95,15.9]],"ltp":2.04,"tv":5652.25,"id":8284479}]}]}
{"op":"mcm","clk":"1007278339","pt":1580654032418,"mc":[{"id":"1.168236368","rc":[{"batl":[[1,1.98,2.13],[2,2.04,7.56]],"ltp":1.9,"tv":3564.88,"id":4520808},{"batl":[[1,2.18,2.14],[2,4.2,153.72]],"ltp":2.04,"tv":5652.25,"id":8284479}]}]}
{"op":"mcm","clk":"1007280976","pt":1580654047184,"mc":[{"id":"1.168236368","rc":[{"trd":[[1.9,845.26]],"batb":[[0,1.89,420.1],[1,1.83,135.78],[2,1.81,37.86]],"batl":[[0,1.9,7.18],[1,1.92,2.06],[2,1.93,2.07]],"ltp":1.9,"tv":3570.68,"id":4520808}],"tv":9222.94}]}
{"op":"mcm","clk":"1007281154","pt":1580654048113,"mc":[{"id":"1.168236368","rc":[{"trd":[[1.9,858.88]],"batb":[[2,1.78,303.86]],"batl":[[0,1.96,2.49],[1,1.97,2.16],[2,2.04,7.56]],"ltp":1.9,"tv":3584.31,"id":4520808},{"batl":[[0,2.18,2.03],[1,2.2,2.03]],"ltp":2.04,"tv":5652.25,"id":8284479}],"tv":9236.57}]}
{"op":"mcm","clk":"1007281228","pt":1580654048599,"mc":[{"id":"1.168236368","rc":[{"batl":[[0,1.97,2.53],[1,1.98,2.25],[2,1.99,2.13]],"ltp":1.9,"tv":3584.31,"id":4520808}]}]}
{"op":"mcm","clk":"1007282094","pt":1580654053216,"mc":[{"id":"1.168236368","rc":[{"batb":[[0,2.06,21.2]],"batl":[[1,4.2,153.72],[2,95,15.9]],"ltp":2.04,"tv":5652.25,"id":8284479}]}]}
{"op":"mcm","clk":"1007282273","pt":1580654054201,"mc":[{"id":"1.168236368","rc":[{"batl":[[0,1.97,2.16],[1,1.98,2.13],[2,2.04,7.56]],"ltp":1.9,"tv":3584.31,"id":4520808},{"batl":[[1,2.2,2.03],[2,4.2,153.72]],"ltp":2.04,"tv":5652.25,"id":8284479}]}]}
{"op":"mcm","clk":"1007282306","pt":1580654054412,"mc":[{"id":"1.168236368","rc":[{"trd":[[1.89,728.74]],"batb":[[0,1.89,55.73]],"ltp":1.89,"tv":4313.05,"id":4520808}],"tv":9965.3}]}
{"op":"mcm","clk":"1007285169","pt":1580654070848,"mc":[{"id":"1.168236368","rc":[{"batb":[[2,1.97,24.23]],"ltp":2.04,"tv":5652.25,"id":8284479}]}]}
{"op":"mcm","clk":"1007285275","pt":1580654071549,"mc":[{"id":"1.168236368","rc":[{"batl":[[1,1.98,2.17]],"ltp":1.89,"tv":4313.05,"id":4520808}]}]}
{"op":"mcm","clk":"1007285408","pt":1580654072344,"mc":[{"id":"1.168236368","rc":[{"batb":[[2,1.97,27.26]],"ltp":2.04,"tv":5652.25,"id":8284479}]}]}
