{"op":"mcm","clk":"1001176140","pt":1580585265724,"mc":[{"id":"1.168224296","marketDefinition":{"bspMarket":false,"turnInPlayEnabled":true,"persistenceEnabled":true,"marketBaseRate":5.0,"eventId":"29681712","eventTypeId":"2","numberOfWinners":1,"bettingType":"ODDS","marketType":"SET_WINNER","marketTime":"2020-02-02T09:00:00.000Z","suspendTime":"2020-02-02T09:00:00.000Z","bspReconciled":false,"complete":true,"inPlay":false,"crossMatching":false,"runnersVoidable":false,"numberOfActiveRunners":2,"betDelay":0,"status":"OPEN","runners":[{"status":"ACTIVE","sortPriority":1,"id":10303696,"name":"Hugo Gaston"},{"status":"ACTIVE","sortPriority":2,"id":2257317,"name":"Nicolas Mahut"}],"regulators":["MR_INT"],"countryCode":"FR","discountAllowed":false,"timezone":"UTC","openDate":"2020-02-02T09:00:00.000Z","version":3147097864,"name":"Set 1 Winner","eventName":"Hug Gaston v Mahut"},"rc":[{"batb":[[0,1.01,20]],"ltp":0.0,"tv":0.0,"id":2257317},{"batb":[[0,1.01,20]],"ltp":0.0,"tv":0.0,"id":10303696}]}]}
{"op":"mcm","clk":"1001176494","pt":1580585267445,"mc":[{"id":"1.168224296","marketDefinition":{"bspMarket":false,"turnInPlayEnabled":true,"persistenceEnabled":true,"marketBaseRate":5.0,"eventId":"29681712","eventTypeId":"2","numberOfWinners":1,"bettingType":"ODDS","marketType":"SET_WINNER","marketTime":"2020-02-02T09:00:00.000Z","suspendTime":"2020-02-02T09:00:00.000Z","bspReconciled":false,"complete":true,"inPlay":false,"crossMatching":false,"runnersVoidable":false,"numberOfActiveRunners":2,"betDelay":0,"status":"OPEN","runners":[{"status":"ACTIVE","sortPriority":1,"id":10303696,"name":"Hugo Gaston"},{"status":"ACTIVE","sortPriority":2,"id":2257317,"name":"Nicolas Mahut"}],"regulators":["MR_INT"],"countryCode":"FR","discountAllowed":false,"timezone":"UTC","openDate":"2020-02-02T09:00:00.000Z","version":3147097864,"name":"Set 1 Winner","eventName":"Hug Gaston v Mahut"}}]}
{"op":"mcm","clk":"1001177167","pt":1580585270503,"mc":[{"id":"1.168224296","marketDefinition":{"bspMarket":false,"turnInPlayEnabled":true,"persistenceEnabled":true,"marketBaseRate":5.0,"eventId":"29681712","eventTypeId":"2","numberOfWinners":1,"bettingType":"ODDS","marketType":"SET_WINNER","marketTime":"2020-02-02T09:00:00.000Z","suspendTime":"2020-02-02T09:00:00.000Z","bspReconciled":false,"complete":true,"inPlay":false,"crossMatching":false,"runnersVoidable":false,"numberOfActiveRunners":2,"betDelay":0,"status":"OPEN","runners":[{"status":"ACTIVE","sortPriority":1,"id":10303696,"name":"Hugo Gaston"},{"status":"ACTIVE","sortPriority":2,"id":2257317,"name":"Nicolas Mahut"}],"regulators":["MR_INT"],"countryCode":"FR","discountAllowed":true,"timezone":"UTC","openDate":"2020-02-02T09:00:00.000Z","version":3147097864,"name":"Set 1 Winner","eventName":"Hug Gaston v Mahut"}}]}
{"op":"mcm","clk":"1001204315","pt":1580585416134,"mc":[{"id":"1.168224296","rc":[{"batb":[[0,1.01,15]],"ltp":0.0,"tv":0.0,"id":2257317},{"batb":[[0,1.01,15]],"ltp":0.0,"tv":0.0,"id":10303696}]}]}
{"op":"mcm","clk":"1001221984","pt":1580585512416,"mc":[{"id":"1.168224296","marketDefinition":{"bspMarket":false,"turnInPlayEnabled":true,"persistenceEnabled":true,"marketBaseRate":5.0,"eventId":"29681712","eventTypeId":"2","numberOfWinners":1,"bettingType":"ODDS","marketType":"SET_WINNER","marketTime":"2020-02-02T11:30:00.000Z","suspendTime":"2020-02-02T11:30:00.000Z","bspReconciled":false,"complete":true,"inPlay":false,"crossMatching":false,"runnersVoidable":false,"numberOfActiveRunners":2,"betDelay":0,"status":"OPEN","runners":[{"status":"ACTIVE","sortPriority":1,"id":10303696,"name":"Hugo Gaston"},{"status":"ACTIVE","sortPriority":2,"id":2257317,"name":"Nicolas Mahut"}],"regulators":["MR_INT"],"countryCode":"FR","discountAllowed":true,"timezone":"UTC","openDate":"2020-02-02T09:00:00.000Z","version":3147124631,"name":"Set 1 Winner","eventName":"Hug Gaston v Mahut"}}]}
{"op":"mcm","clk":"1001222392","pt":1580585514425,"mc":[{"id":"1.168224296","marketDefinition":{"bspMarket":false,"turnInPlayEnabled":true,"persistenceEnabled":true,"marketBaseRate":5.0,"eventId":"29681712","eventTypeId":"2","numberOfWinners":1,"bettingType":"ODDS","marketType":"SET_WINNER","marketTime":"2020-02-02T11:30:00.000Z","suspendTime":"2020-02-02T11:30:00.000Z","bspReconciled":false,"complete":true,"inPlay":false,"crossMatching":false,"runnersVoidable":false,"numberOfActiveRunners":2,"betDelay":0,"status":"OPEN","runners":[{"status":"ACTIVE","sortPriority":1,"id":10303696,"name":"Hugo Gaston"},{"status":"ACTIVE","sortPriority":2,"id":2257317,"name":"Nicolas Mahut"}],"regulators":["MR_INT"],"countryCode":"FR","discountAllowed":true,"timezone":"UTC","openDate":"2020-02-02T11:30:00.000Z","version":3147124631,"name":"Set 1 Winner","eventName":"Hug Gaston v Mahut"}}]}
{"op":"mcm","clk":"1003032597","pt":1580602186346,"mc":[{"id":"1.168224296","rc":[{"batb":[[0,1.01,17.53]],"ltp":0.0,"tv":0.0,"id":2257317},{"batb":[[0,1.01,17.53]],"ltp":0.0,"tv":0.0,"id":10303696}]}]}
{"op":"mcm","clk":"1003032708","pt":1580602187338,"mc":[{"id":"1.168224296","rc":[{"batb":[[0,1.01,15.51]],"ltp":0.0,"tv":0.0,"id":2257317},{"batb":[[0,1.01,15.51]],"ltp":0.0,"tv":0.0,"id":10303696}]}]}
{"op":"mcm","clk":"1003160396","pt":1580603726344,"mc":[{"id":"1.168224296","rc":[{"batb":[[0,1.01,18.04]],"ltp":0.0,"tv":0.0,"id":2257317},{"batb":[[0,1.01,18.04]],"ltp":0.0,"tv":0.0,"id":10303696}]}]}
{"op":"mcm","clk":"1003160475","pt":1580603727376,"mc":[{"id":"1.168224296","rc":[{"batb":[[0,1.01,16.01]],"ltp":0.0,"tv":0.0,"id":2257317},{"batb":[[0,1.01,16.01]],"ltp":0.0,"tv":0.0,"id":10303696}]}]}
{"op":"mcm","clk":"1003389769","pt":1580607093375,"mc":[{"id":"1.168224296","rc":[{"batb":[[0,1.01,18.01]],"ltp":0.0,"tv":0.0,"id":2257317},{"batb":[[0,1.01,18.01]],"ltp":0.0,"tv":0.0,"id":10303696}]}]}
{"op":"mcm","clk":"1003389825","pt":1580607093946,"mc":[{"id":"1.168224296","rc":[{"batb":[[0,1.01,16.02]],"ltp":0.0,"tv":0.0,"id":2257317},{"batb":[[0,1.01,16.02]],"ltp":0.0,"tv":0.0,"id":10303696}]}]}
{"op":"mcm","clk":"1004691909","pt":1580635315872,"mc":[{"id":"1.168224296","marketDefinition":{"bspMarket":false,"turnInPlayEnabled":true,"persistenceEnabled":true,"marketBaseRate":5.0,"eventId":"29681712","eventTypeId":"2","numberOfWinners":1,"bettingType":"ODDS","marketType":"SET_WINNER","marketTime":"2020-02-02T11:19:00.000Z","suspendTime":"2020-02-02T11:19:00.000Z","bspReconciled":false,"complete":true,"inPlay":false,"crossMatching":false,"runnersVoidable":false,"numberOfActiveRunners":2,"betDelay":0,"status":"OPEN","runners":[{"status":"ACTIVE","sortPriority":1,"id":10303696,"name":"Hugo Gaston"},{"status":"ACTIVE","sortPriority":2,"id":2257317,"name":"Nicolas Mahut"}],"regulators":["MR_INT"],"countryCode":"FR","discountAllowed":true,"timezone":"UTC","openDate":"2020-02-02T11:30:00.000Z","version":3148342768,"name":"Set 1 Winner","eventName":"Hug Gaston v Mahut"}}]}
{"op":"mcm","clk":"1004692044","pt":1580635317946,"mc":[{"id":"1.168224296","marketDefinition":{"bspMarket":false,"turnInPlayEnabled":true,"persistenceEnabled":true,"marketBaseRate":5.0,"eventId":"29681712","eventTypeId":"2","numberOfWinners":1,"bettingType":"ODDS","marketType":"SET_WINNER","marketTime":"2020-02-02T11:19:00.000Z","suspendTime":"2020-02-02T11:19:00.000Z","bspReconciled":false,"complete":true,"inPlay":false,"crossMatching":false,"runnersVoidable":false,"numberOfActiveRunners":2,"betDelay":0,"status":"OPEN","runners":[{"status":"ACTIVE","sortPriority":1,"id":10303696,"name":"Hugo Gaston"},{"status":"ACTIVE","sortPriority":2,"id":2257317,"name":"Nicolas Mahut"}],"regulators":["MR_INT"],"countryCode":"FR","discountAllowed":true,"timezone":"UTC","openDate":"2020-02-02T11:19:00.000Z","version":3148342768,"name":"Set 1 Winner","eventName":"Hug Gaston v Mahut"}}]}
{"op":"mcm","clk":"1005237285","pt":1580641615820,"mc":[{"id":"1.168224296","marketDefinition":{"bspMarket":false,"turnInPlayEnabled":true,"persistenceEnabled":true,"marketBaseRate":5.0,"eventId":"29681712","eventTypeId":"2","numberOfWinners":1,"bettingType":"ODDS","marketType":"SET_WINNER","marketTime":"2020-02-02T11:10:00.000Z","suspendTime":"2020-02-02T11:10:00.000Z","bspReconciled":false,"complete":true,"inPlay":false,"crossMatching":false,"runnersVoidable":false,"numberOfActiveRunners":2,"betDelay":0,"status":"OPEN","runners":[{"status":"ACTIVE","sortPriority":1,"id":10303696,"name":"Hugo Gaston"},{"status":"ACTIVE","sortPriority":2,"id":2257317,"name":"Nicolas Mahut"}],"regulators":["MR_INT"],"countryCode":"FR","discountAllowed":true,"timezone":"UTC","openDate":"2020-02-02T11:19:00.000Z","version":3148499317,"name":"Set 1 Winner","eventName":"Hug Gaston v Mahut"}}]}
{"op":"mcm","clk":"1005237918","pt":1580641618828,"mc":[{"id":"1.168224296","marketDefinition":{"bspMarket":false,"turnInPlayEnabled":true,"persistenceEnabled":true,"marketBaseRate":5.0,"eventId":"29681712","eventTypeId":"2","numberOfWinners":1,"bettingType":"ODDS","marketType":"SET_WINNER","marketTime":"2020-02-02T11:10:00.000Z","suspendTime":"2020-02-02T11:10:00.000Z","bspReconciled":false,"complete":true,"inPlay":false,"crossMatching":false,"runnersVoidable":false,"numberOfActiveRunners":2,"betDelay":0,"status":"OPEN","runners":[{"status":"ACTIVE","sortPriority":1,"id":10303696,"name":"Hugo Gaston"},{"status":"ACTIVE","sortPriority":2,"id":2257317,"name":"Nicolas Mahut"}],"regulators":["MR_INT"],"countryCode":"FR","discountAllowed":true,"timezone":"UTC","openDate":"2020-02-02T11:10:00.000Z","version":3148499317,"name":"Set 1 Winner","eventName":"Hug Gaston v Mahut"}}]}
{"op":"mcm","clk":"1005278032","pt":1580641823336,"mc":[{"id":"1.168224296","rc":[{"batb":[[0,1.84,18.25],[1,1.01,16.02]],"ltp":0.0,"tv":0.0,"id":2257317},{"batb":[[0,2.04,26.52],[1,1.01,16.02]],"ltp":0.0,"tv":0.0,"id":10303696}]}]}
{"op":"mcm","clk":"1005281397","pt":1580641841436,"mc":[{"id":"1.168224296","marketDefinition":{"bspMarket":false,"turnInPlayEnabled":true,"persistenceEnabled":true,"marketBaseRate":5.0,"eventId":"29681712","eventTypeId":"2","numberOfWinners":1,"bettingType":"ODDS","marketType":"SET_WINNER","marketTime":"2020-02-02T11:10:00.000Z","suspendTime":"2020-02-02T11:10:00.000Z","bspReconciled":false,"complete":true,"inPlay":false,"crossMatching":true,"runnersVoidable":false,"numberOfActiveRunners":2,"betDelay":0,"status":"OPEN","runners":[{"status":"ACTIVE","sortPriority":1,"id":10303696,"name":"Hugo Gaston"},{"status":"ACTIVE","sortPriority":2,"id":2257317,"name":"Nicolas Mahut"}],"regulators":["MR_INT"],"countryCode":"FR","discountAllowed":true,"timezone":"UTC","openDate":"2020-02-02T11:10:00.000Z","version":3148499317,"name":"Set 1 Winner","eventName":"Hug Gaston v Mahut"}}]}
{"op":"mcm","clk":"1005286499","pt":1580641868328,"mc":[{"id":"1.168224296","rc":[{"batb":[[0,1.85,18.02]],"ltp":0.0,"tv":0.0,"id":2257317},{"batb":[[1,2.02,26.91],[2,1.01,16.02]],"ltp":0.0,"tv":0.0,"id":10303696}]}]}
{"op":"mcm","clk":"1005288384","pt":1580641878348,"mc":[{"id":"1.168224296","rc":[{"batb":[[0,1.86,17.7]],"ltp":0.0,"tv":0.0,"id":2257317},{"batb":[[0,2.02,26.91],[1,1.01,16.02],[2,1.01,0]],"ltp":0.0,"tv":0.0,"id":10303696}]}]}
{"op":"mcm","clk":"1005295265","pt":1580641914070,"mc":[{"id":"1.168224296","marketDefinition":{"bspMarket":false,"turnInPlayEnabled":true,"persistenceEnabled":true,"marketBaseRate":5.0,"eventId":"29681712","eventTypeId":"2","numberOfWinners":1,"bettingType":"ODDS","marketType":"SET_WINNER","marketTime":"2020-02-02T11:08:00.000Z","suspendTime":"2020-02-02T11:08:00.000Z","bspReconciled":false,"complete":true,"inPlay":false,"crossMatching":true,"runnersVoidable":false,"numberOfActiveRunners":2,"betDelay":0,"status":"OPEN","runners":[{"status":"ACTIVE","sortPriority":1,"id":10303696,"name":"Hugo Gaston"},{"status":"ACTIVE","sortPriority":2,"id":2257317,"name":"Nicolas Mahut"}],"regulators":["MR_INT"],"countryCode":"FR","discountAllowed":true,"timezone":"UTC","openDate":"2020-02-02T11:10:00.000Z","version":3148508262,"name":"Set 1 Winner","eventName":"Hug Gaston v Mahut"}}]}
{"op":"mcm","clk":"1005295749","pt":1580641916624,"mc":[{"id":"1.168224296","marketDefinition":{"bspMarket":false,"turnInPlayEnabled":true,"persistenceEnabled":true,"marketBaseRate":5.0,"eventId":"29681712","eventTypeId":"2","numberOfWinners":1,"bettingType":"ODDS","marketType":"SET_WINNER","marketTime":"2020-02-02T11:08:00.000Z","suspendTime":"2020-02-02T11:08:00.000Z","bspReconciled":false,"complete":true,"inPlay":false,"crossMatching":true,"runnersVoidable":false,"numberOfActiveRunners":2,"betDelay":0,"status":"OPEN","runners":[{"status":"ACTIVE","sortPriority":1,"id":10303696,"name":"Hugo Gaston"},{"status":"ACTIVE","sortPriority":2,"id":2257317,"name":"Nicolas Mahut"}],"regulators":["MR_INT"],"countryCode":"FR","discountAllowed":true,"timezone":"UTC","openDate":"2020-02-02T11:08:00.000Z","version":3148508262,"name":"Set 1 Winner","eventName":"Hug Gaston v Mahut"}}]}
{"op":"mcm","clk":"1005296185","pt":1580641918761,"mc":[{"id":"1.168224296","rc":[{"batb":[[1,1.68,132.35],[2,1.01,16.02]],"ltp":0.0,"tv":0.0,"id":2257317},{"batb":[[1,1.96,93.75],[2,1.01,16.02]],"ltp":0.0,"tv":0.0,"id":10303696}]}]}
{"op":"mcm","clk":"1005299284","pt":1580641936272,"mc":[{"id":"1.168224296","rc":[{"batb":[[2,1.01,17.7]],"ltp":0.0,"tv":0.0,"id":2257317},{"batb":[[2,1.01,17.7]],"ltp":0.0,"tv":0.0,"id":10303696}]}]}
{"op":"mcm","clk":"1005299499","pt":1580641937384,"mc":[{"id":"1.168224296","rc":[{"batb":[[0,1.87,1.34],[1,1.86,17.7],[2,1.68,132.35]],"ltp":0.0,"tv":0.0,"id":2257317}]}]}
{"op":"mcm","clk":"1005299554","pt":1580641937760,"mc":[{"id":"1.168224296","rc":[{"batb":[[0,2.04,1.24],[1,2.02,26.91],[2,1.96,93.75]],"ltp":0.0,"tv":0.0,"id":10303696}]}]}
{"op":"mcm","clk":"1005299870","pt":1580641939348,"mc":[{"id":"1.168224296","rc":[{"batb":[[2,1.85,17.94]],"ltp":0.0,"tv":0.0,"id":2257317}]}]}
{"op":"mcm","clk":"1005310474","pt":1580642001967,"mc":[{"id":"1.168224296","rc":[{"batb":[[1,1.85,17.94],[2,1.68,132.35]],"ltp":0.0,"tv":0.0,"id":2257317}]}]}
{"op":"mcm","clk":"1005324117","pt":1580642078032,"mc":[{"id":"1.168224296","rc":[{"batb":[[1,1.84,18.18]],"ltp":0.0,"tv":0.0,"id":2257317},{"batb":[[0,2.04,27.91],[1,1.96,93.75],[2,1.01,16.02]],"ltp":0.0,"tv":0.0,"id":10303696}]}]}
{"op":"mcm","clk":"1005335757","pt":1580642143190,"mc":[{"id":"1.168224296","rc":[{"batb":[[1,1.85,17.86],[2,1.84,18.18]],"ltp":0.0,"tv":0.0,"id":2257317},{"batb":[[1,2.02,27.07],[2,1.96,93.75]],"ltp":0.0,"tv":0.0,"id":10303696}]}]}
{"op":"mcm","clk":"1005335826","pt":1580642143570,"mc":[{"id":"1.168224296","rc":[{"batb":[[2,1.68,132.35]],"ltp":0.0,"tv":0.0,"id":2257317}]}]}
{"op":"mcm","clk":"1005340337","pt":1580642168995,"mc":[{"id":"1.168224296","rc":[{"batb":[[0,2.04,1.24],[1,2.02,26.83]],"ltp":0.0,"tv":0.0,"id":10303696}]}]}
{"op":"mcm","clk":"1005342581","pt":1580642180737,"mc":[{"id":"1.168224296","rc":[{"batb":[[2,1.82,50.41]],"batl":[[0,2,42.01]],"ltp":0.0,"tv":0.0,"id":2257317},{"batb":[[2,2,42.01]],"batl":[[0,2.24,33.61]],"ltp":0.0,"tv":0.0,"id":10303696}]}]}
{"op":"mcm","clk":"1005345137","pt":1580642194229,"mc":[{"id":"1.168224296","rc":[{"batb":[[1,1.84,18.18]],"ltp":0.0,"tv":0.0,"id":2257317},{"batb":[[0,2.04,27.83],[1,2,42.01],[2,1.96,93.75]],"ltp":0.0,"tv":0.0,"id":10303696}]}]}
{"op":"mcm","clk":"1005348091","pt":1580642210398,"mc":[{"id":"1.168224296","rc":[{"batb":[[1,1.85,2],[2,1.84,18.18]],"ltp":0.0,"tv":0.0,"id":2257317},{"batb":[[0,2.06,2],[1,2.04,27.83],[2,2,42.01]],"ltp":0.0,"tv":0.0,"id":10303696}]}]}
{"op":"mcm","clk":"1005358852","pt":1580642269258,"mc":[{"id":"1.168224296","rc":[{"batb":[[1,1.84,18.18],[2,1.82,50.41]],"ltp":0.0,"tv":0.0,"id":2257317},{"batb":[[0,2.04,27.83],[1,2,42.01],[2,1.96,93.75]],"ltp":0.0,"tv":0.0,"id":10303696}]}]}
{"op":"mcm","clk":"1005361714","pt":1580642284125,"mc":[{"id":"1.168224296","rc":[{"batb":[[1,1.85,2],[2,1.84,18.18]],"ltp":0.0,"tv":0.0,"id":2257317},{"batb":[[0,2.06,2],[1,2.04,27.83],[2,2,42.01]],"ltp":0.0,"tv":0.0,"id":10303696}]}]}
{"op":"mcm","clk":"1005373216","pt":1580642343236,"mc":[{"id":"1.168224296","rc":[{"batb":[[1,1.84,18.18],[2,1.82,50.41]],"ltp":0.0,"tv":0.0,"id":2257317},{"batb":[[0,2.04,27.83],[1,2,42.01],[2,1.96,93.75]],"ltp":0.0,"tv":0.0,"id":10303696}]}]}
{"op":"mcm","clk":"1005387359","pt":1580642418354,"mc":[{"id":"1.168224296","rc":[{"batb":[[1,1.85,17.94],[2,1.84,18.18]],"ltp":0.0,"tv":0.0,"id":2257317},{"batb":[[1,2.02,26.99],[2,2,42.01]],"ltp":0.0,"tv":0.0,"id":10303696}]}]}
{"op":"mcm","clk":"1005387443","pt":1580642418825,"mc":[{"id":"1.168224296","rc":[{"batb":[[2,1.82,50.41]],"ltp":0.0,"tv":0.0,"id":2257317}]}]}
{"op":"mcm","clk":"1005389093","pt":1580642428061,"mc":[{"id":"1.168224296","rc":[{"batb":[[1,1.82,50.41],[2,1.68,132.35]],"ltp":0.0,"tv":0.0,"id":2257317},{"batb":[[0,2.04,1.24],[1,2,42.01],[2,1.96,93.75]],"ltp":0.0,"tv":0.0,"id":10303696}]}]}
{"op":"mcm","clk":"1005389199","pt":1580642428705,"mc":[{"id":"1.168224296","marketDefinition":{"bspMarket":false,"turnInPlayEnabled":true,"persistenceEnabled":true,"marketBaseRate":5.0,"eventId":"29681712","eventTypeId":"2","numberOfWinners":1,"bettingType":"ODDS","marketType":"SET_WINNER","marketTime":"2020-02-02T11:08:00.000Z","suspendTime":"2020-02-02T11:08:00.000Z","bspReconciled":false,"complete":true,"inPlay":true,"crossMatching":true,"runnersVoidable":false,"numberOfActiveRunners":2,"betDelay":3,"status":"OPEN","runners":[{"status":"ACTIVE","sortPriority":1,"id":10303696,"name":"Hugo Gaston"},{"status":"ACTIVE","sortPriority":2,"id":2257317,"name":"Nicolas Mahut"}],"regulators":["MR_INT"],"countryCode":"FR","discountAllowed":true,"timezone":"UTC","openDate":"2020-02-02T11:08:00.000Z","version":3148525267,"name":"Set 1 Winner","eventName":"Hug Gaston v Mahut"},"rc":[{"batb":[[0,1.01,15.52],[1,1.82,0],[2,1.68,0]],"ltp":0.0,"tv":0.0,"id":2257317},{"batb":[[0,1.01,15.52],[1,2,0],[2,1.96,0]],"ltp":0.0,"tv":0.0,"id":10303696}]}]}
{"op":"mcm","clk":"1005391132","pt":1580642439381,"mc":[{"id":"1.168224296","rc":[{"batb":[[0,1.96,30.06],[1,1.81,19.36],[2,1.01,15.52]],"ltp":0.0,"tv":0.0,"id":2257317},{"batb":[[0,1.91,16.13],[1,1.84,18.41],[2,1.01,15.52]],"ltp":0.0,"tv":0.0,"id":10303696}]}]}
{"op":"mcm","clk":"1005391169","pt":1580642439597,"mc":[{"id":"1.168224296","rc":[{"batb":[[1,1.9,46.21],[2,1.81,19.36]],"batl":[[0,2.12,36.97]],"ltp":0.0,"tv":0.0,"id":2257317},{"batb":[[1,1.89,47.05],[2,1.84,18.41]],"batl":[[0,2.1,37.81]],"ltp":0.0,"tv":0.0,"id":10303696}]}]}
{"op":"mcm","clk":"1005392607","pt":1580642447277,"mc":[{"id":"1.168224296","rc":[{"batb":[[0,1.9,46.21],[1,1.81,19.36],[2,1.01,15.52]],"ltp":0.0,"tv":0.0,"id":2257317},{"batb":[[0,1.89,47.05],[1,1.84,18.41],[2,1.01,15.52]],"ltp":0.0,"tv":0.0,"id":10303696}]}]}
{"op":"mcm","clk":"1005392859","pt":1580642448667,"mc":[{"id":"1.168224296","rc":[{"batb":[[0,1.81,19.36],[1,1.01,15.52],[2,1.01,0]],"ltp":0.0,"tv":0.0,"id":2257317},{"batb":[[0,1.84,18.41],[1,1.01,15.52],[2,1.01,0]],"ltp":0.0,"tv":0.0,"id":10303696}]}]}
{"op":"mcm","clk":"1005395475","pt":1580642463030,"mc":[{"id":"1.168224296","rc":[{"batb":[[1,1.61,29.03],[2,1.01,15.52]],"ltp":0.0,"tv":0.0,"id":2257317},{"batb":[[0,2.08,24.86],[1,1.95,30.61],[2,1.01,15.52]],"ltp":0.0,"tv":0.0,"id":10303696}]}]}
{"op":"mcm","clk":"1005395627","pt":1580642463923,"mc":[{"id":"1.168224296","rc":[{"batb":[[1,1.78,53.77],[2,1.61,29.03]],"batl":[[0,1.97,42.01]],"ltp":0.0,"tv":0.0,"id":2257317},{"batb":[[1,2.04,40.33],[2,1.95,30.61]],"batl":[[0,2.3,31.93]],"ltp":0.0,"tv":0.0,"id":10303696}]}]}
{"op":"mcm","clk":"1005397004","pt":1580642471757,"mc":[{"id":"1.168224296","rc":[{"batb":[[0,1.78,53.77],[1,1.61,29.03],[2,1.01,15.52]],"ltp":0.0,"tv":0.0,"id":2257317},{"batb":[[0,2.04,40.33],[1,1.95,30.61],[2,1.01,15.52]],"ltp":0.0,"tv":0.0,"id":10303696}]}]}
{"op":"mcm","clk":"1005397159","pt":1580642472550,"mc":[{"id":"1.168224296","rc":[{"batb":[[0,1.61,29.03],[1,1.01,15.52],[2,1.01,0]],"ltp":0.0,"tv":0.0,"id":2257317},{"batb":[[0,1.95,30.61],[1,1.01,15.52],[2,1.01,0]],"ltp":0.0,"tv":0.0,"id":10303696}]}]}
{"op":"mcm","clk":"1005403302","pt":1580642507796,"mc":[{"id":"1.168224296","rc":[{"batb":[[0,1.61,97.09],[1,1.4,50.92],[2,1.01,15.51]],"batl":[[0,1.76,42.01]],"ltp":0.0,"tv":0.0,"id":2257317},{"batb":[[0,2.44,15.89],[1,2.32,31.09],[2,2.16,22.5]],"batl":[[0,2.64,25.21]],"ltp":0.0,"tv":0.0,"id":10303696}]}]}
{"op":"mcm","clk":"1005404979","pt":1580642517321,"mc":[{"id":"1.168224296","rc":[{"batb":[[0,1.61,68.06]],"ltp":0.0,"tv":0.0,"id":2257317},{"batb":[[0,2.32,31.09],[1,2.16,22.5],[2,1.01,15.52]],"ltp":0.0,"tv":0.0,"id":10303696}]}]}
{"op":"mcm","clk":"1005405224","pt":1580642518601,"mc":[{"id":"1.168224296","rc":[{"batb":[[0,1.4,50.92],[1,1.01,15.51],[2,1.01,0]],"ltp":0.0,"tv":0.0,"id":2257317},{"batb":[[0,2.16,22.5],[1,1.01,15.52],[2,1.01,0]],"ltp":0.0,"tv":0.0,"id":10303696}]}]}
{"op":"mcm","clk":"1005405564","pt":1580642520332,"mc":[{"id":"1.168224296","rc":[{"batb":[[1,1.39,50.99],[2,1.01,15.51]],"ltp":0.0,"tv":0.0,"id":2257317}]}]}
{"op":"mcm","clk":"1005405625","pt":1580642520659,"mc":[{"id":"1.168224296","rc":[{"batb":[[0,1.39,51],[1,1.01,15.51],[2,1.01,0]],"ltp":0.0,"tv":0.0,"id":2257317}]}]}
{"op":"mcm","clk":"1005408691","pt":1580642536859,"mc":[{"id":"1.168224296","rc":[{"trd":[[1.48,0.01]],"batb":[[0,1.39,50.99],[1,1.23,97.01],[2,1.01,15.51]],"ltp":1.48,"tv":0.01,"id":2257317},{"trd":[[3.1,0]],"batb":[[0,3.15,20.22],[1,2.68,12.35],[2,1.01,15.52]],"ltp":3.1,"tv":0.0,"id":10303696}],"tv":0.01}]}
{"op":"mcm","clk":"1005408904","pt":1580642537870,"mc":[{"id":"1.168224296","rc":[{"batb":[[0,1.43,97.46],[1,1.39,50.99],[2,1.23,97.01]],"batl":[[0,1.53,42.01]],"ltp":1.48,"tv":0.01,"id":2257317},{"batb":[[1,2.86,21.85],[2,2.68,12.35]],"batl":[[0,3.35,17.64]],"ltp":3.1,"tv":0.0,"id":10303696}]}]}
{"op":"mcm","clk":"1005410187","pt":1580642544898,"mc":[{"id":"1.168224296","rc":[{"batb":[[1,1.23,97.01],[2,1.01,15.51]],"ltp":1.48,"tv":0.01,"id":2257317},{"batb":[[0,2.86,21.85],[1,2.68,12.35],[2,1.01,15.52]],"ltp":3.1,"tv":0.0,"id":10303696}]}]}
{"op":"mcm","clk":"1005410500","pt":1580642546551,"mc":[{"id":"1.168224296","rc":[{"batb":[[0,1.23,97.01],[1,1.01,15.51],[2,1.01,0]],"ltp":1.48,"tv":0.01,"id":2257317},{"batb":[[0,2.68,12.35],[1,1.01,15.52],[2,1.01,0]],"ltp":3.1,"tv":0.0,"id":10303696}]}]}
{"op":"mcm","clk":"1005414101","pt":1580642564947,"mc":[{"id":"1.168224296","rc":[{"batb":[[1,1.19,119.12],[2,1.01,15.51]],"ltp":1.48,"tv":0.01,"id":2257317},{"batb":[[0,4.5,16.68],[1,3.65,13.85],[2,1.01,15.52]],"ltp":3.1,"tv":0.0,"id":10303696}]}]}
{"op":"mcm","clk":"1005414283","pt":1580642565866,"mc":[{"id":"1.168224296","rc":[{"batb":[[0,1.25,168.04],[1,1.23,97.01],[2,1.19,119.12]],"batl":[[0,1.32,42.01]],"ltp":1.48,"tv":0.01,"id":2257317},{"batb":[[1,4.1,13.44],[2,3.65,13.85]],"batl":[[0,4.9,10.08]],"ltp":3.1,"tv":0.0,"id":10303696}]}]}
{"op":"mcm","clk":"1005415473","pt":1580642571858,"mc":[{"id":"1.168224296","rc":[{"batb":[[0,1.25,585.21]],"batl":[[0,1.29,339.38],[1,1.32,42.01]],"ltp":1.48,"tv":0.01,"id":2257317}]}]}
{"op":"mcm","clk":"1005415647","pt":1580642572764,"mc":[{"id":"1.168224296","rc":[{"batb":[[0,4.6,16.29],[2,3.7,13.61]],"ltp":3.1,"tv":0.0,"id":10303696}]}]}
{"op":"mcm","clk":"1005416067","pt":1580642574856,"mc":[{"id":"1.168224296","rc":[{"batb":[[1,1.24,448.48],[2,1.23,97.01]],"batl":[[0,1.28,221.18],[1,1.29,339.38],[2,1.32,42.01]],"ltp":1.48,"tv":0.01,"id":2257317}]}]}
{"op":"mcm","clk":"1005421129","pt":1580642600918,"mc":[{"id":"1.168224296","rc":[{"batb":[[0,1.25,168.04],[1,1.23,97.01],[2,1.19,119.12]],"batl":[[0,1.32,42.01],[1,1.29,0],[2,1.32,0]],"ltp":1.48,"tv":0.01,"id":2257317}]}]}
{"op":"mcm","clk":"1005421744","pt":1580642603909,"mc":[{"id":"1.168224296","rc":[{"batb":[[2,1.21,584.49]],"batl":[[1,1.37,229.02],[2,1.38,242.75]],"ltp":1.48,"tv":0.01,"id":2257317}]}]}
{"op":"mcm","clk":"1005423496","pt":1580642612066,"mc":[{"id":"1.168224296","rc":[{"batb":[[1,1.21,584.49],[2,1.2,478.73]],"ltp":1.48,"tv":0.01,"id":2257317},{"batb":[[0,4.1,13.44],[1,3.7,13.61],[2,1.01,15.52]],"ltp":3.1,"tv":0.0,"id":10303696}]}]}
{"op":"mcm","clk":"1005423604","pt":1580642612544,"mc":[{"id":"1.168224296","rc":[{"batb":[[0,1.21,584.49],[1,1.2,478.73],[2,1.19,119.12]],"batl":[[0,1.37,229.02],[1,1.38,242.75],[2,1.38,0]],"ltp":1.48,"tv":0.01,"id":2257317},{"batb":[[0,3.7,13.61],[1,1.01,15.52],[2,1.01,0]],"ltp":3.1,"tv":0.0,"id":10303696}]}]}
{"op":"mcm","clk":"1005424752","pt":1580642618788,"mc":[{"id":"1.168224296","rc":[{"batb":[[0,1.19,119.12],[1,1.01,15.51],[2,1.19,0]],"ltp":1.48,"tv":0.01,"id":2257317}]}]}
{"op":"mcm","clk":"1005425351","pt":1580642621928,"mc":[{"id":"1.168224296","rc":[{"batb":[[0,1.27,236.54],[1,1.26,402.6],[2,1.19,119.12]],"batl":[[0,1.3,321.91],[1,1.31,311.14]],"ltp":1.48,"tv":0.01,"id":2257317}]}]}
{"op":"mcm","clk":"1005425800","pt":1580642624268,"mc":[{"id":"1.168224296","rc":[{"batb":[[0,1.19,119.12],[1,1.01,15.51],[2,1.19,0]],"ltp":1.48,"tv":0.01,"id":2257317}]}]}
{"op":"mcm","clk":"1005426621","pt":1580642628403,"mc":[{"id":"1.168224296","rc":[{"batl":[[0,1.37,234.14],[1,1.38,242.76]],"ltp":1.48,"tv":0.01,"id":2257317}]}]}
{"op":"mcm","clk":"1005426955","pt":1580642630244,"mc":[{"id":"1.168224296","rc":[{"batb":[[0,1.33,393.95],[1,1.32,313.74],[2,1.19,119.12]],"ltp":1.48,"tv":0.01,"id":2257317}]}]}
{"op":"mcm","clk":"1005427088","pt":1580642630996,"mc":[{"id":"1.168224296","rc":[{"batb":[[2,1.31,68.61]],"ltp":1.48,"tv":0.01,"id":2257317},{"batb":[[1,2.92,24.71],[2,1.01,15.52]],"ltp":3.1,"tv":0.0,"id":10303696}]}]}
{"op":"mcm","clk":"1005427217","pt":1580642631581,"mc":[{"id":"1.168224296","rc":[{"batb":[[1,1.32,444.81]],"batl":[[2,1.4,42.01]],"ltp":1.48,"tv":0.01,"id":2257317},{"batb":[[1,3.5,16.8],[2,2.92,24.71]],"batl":[[0,4.1,13.44]],"ltp":3.1,"tv":0.0,"id":10303696}]}]}
{"op":"mcm","clk":"1005429244","pt":1580642642373,"mc":[{"id":"1.168224296","rc":[{"batb":[[0,1.32,131.07],[1,1.25,89.62],[2,1.01,15.51]],"batl":[[0,1.4,42.01],[1,1.38,0],[2,1.4,0]],"ltp":1.48,"tv":0.01,"id":2257317},{"batb":[[0,3.5,16.8],[1,2.92,24.71],[2,1.01,15.52]],"ltp":3.1,"tv":0.0,"id":10303696}]}]}
{"op":"mcm","clk":"1005429293","pt":1580642642599,"mc":[{"id":"1.168224296","rc":[{"batb":[[0,1.25,89.62],[1,1.01,15.51],[2,1.01,0]],"ltp":1.48,"tv":0.01,"id":2257317},{"batb":[[0,2.92,24.71],[1,1.01,15.52],[2,1.01,0]],"ltp":3.1,"tv":0.0,"id":10303696}]}]}
{"op":"mcm","clk":"1005429816","pt":1580642645280,"mc":[{"id":"1.168224296","rc":[{"batb":[[0,1.27,359.17],[1,1.26,405.34],[2,1.25,89.62]],"batl":[[0,1.52,217.64],[1,1.53,157.79]],"ltp":1.48,"tv":0.01,"id":2257317}]}]}
{"op":"mcm","clk":"1005431093","pt":1580642651965,"mc":[{"id":"1.168224296","rc":[{"batb":[[0,1.25,89.62],[1,1.01,15.51],[2,1.25,0]],"ltp":1.48,"tv":0.01,"id":2257317}]}]}
{"op":"mcm","clk":"1005431792","pt":1580642655329,"mc":[{"id":"1.168224296","rc":[{"batb":[[0,1.47,227.71],[1,1.46,194.48],[2,1.45,43.67]],"ltp":1.48,"tv":0.01,"id":2257317},{"batb":[[1,2.34,17.94],[2,1.01,15.52]],"ltp":3.1,"tv":0.0,"id":10303696}]}]}
{"op":"mcm","clk":"1005431858","pt":1580642655605,"mc":[{"id":"1.168224296","rc":[{"batl":[[2,1.54,42.01]],"ltp":1.48,"tv":0.01,"id":2257317},{"batb":[[1,2.86,21.85],[2,2.34,17.94]],"batl":[[0,3.3,17.64]],"ltp":3.1,"tv":0.0,"id":10303696}]}]}
{"op":"mcm","clk":"1005433488","pt":1580642663345,"mc":[{"id":"1.168224296","rc":[{"batb":[[0,1.45,43.67],[1,1.43,97.46],[2,1.35,58.38]],"batl":[[0,1.54,42.01],[1,1.53,0],[2,1.54,0]],"ltp":1.48,"tv":0.01,"id":2257317}]}]}
{"op":"mcm","clk":"1005433533","pt":1580642663558,"mc":[{"id":"1.168224296","rc":[{"batb":[[0,1.43,97.46],[1,1.35,58.38],[2,1.28,485.89]],"ltp":1.48,"tv":0.01,"id":2257317},{"batb":[[0,2.86,21.85],[1,2.34,17.94],[2,2.22,384.52]],"ltp":3.1,"tv":0.0,"id":10303696}]}]}
{"op":"mcm","clk":"1005433741","pt":1580642664542,"mc":[{"id":"1.168224296","rc":[{"batb":[[0,1.35,58.38],[1,1.28,485.89],[2,1.01,15.51]],"ltp":1.48,"tv":0.01,"id":2257317},{"batb":[[0,2.34,17.94],[1,2.22,384.52],[2,1.01,15.52]],"ltp":3.1,"tv":0.0,"id":10303696}]}]}
{"op":"mcm","clk":"1005434085","pt":1580642666225,"mc":[{"id":"1.168224296","rc":[{"batb":[[0,1.38,216.91],[1,1.37,258.53],[2,1.35,58.38]],"batl":[[0,1.74,157.48],[1,1.76,193.72]],"ltp":1.48,"tv":0.01,"id":2257317}]}]}
{"op":"mcm","clk":"1005434578","pt":1580642668665,"mc":[{"id":"1.168224296","rc":[{"batb":[[1,1.01,15.52],[2,1.01,0]],"ltp":3.1,"tv":0.0,"id":10303696}]}]}
{"op":"mcm","clk":"1005434849","pt":1580642670164,"mc":[{"id":"1.168224296","rc":[{"batl":[[0,1.42,248.16],[1,1.43,207.14]],"ltp":1.48,"tv":0.01,"id":2257317}]}]}
{"op":"mcm","clk":"1005434939","pt":1580642670646,"mc":[{"id":"1.168224296","rc":[{"batb":[[0,3.4,16.92],[1,2.58,13.77],[2,1.01,15.52]],"ltp":3.1,"tv":0.0,"id":10303696}]}]}
{"op":"mcm","clk":"1005435214","pt":1580642672255,"mc":[{"id":"1.168224296","rc":[{"batb":[[2,1.36,115.95]],"batl":[[2,1.45,42.01]],"ltp":1.48,"tv":0.01,"id":2257317},{"batb":[[1,3.2,18.48],[2,2.58,13.77]],"batl":[[0,3.8,14.28]],"ltp":3.1,"tv":0.0,"id":10303696}]}]}
{"op":"mcm","clk":"1005436857","pt":1580642680722,"mc":[{"id":"1.168224296","rc":[{"batb":[[0,1.27,81.51],[1,1.22,523],[2,1.01,15.51]],"ltp":1.48,"tv":0.01,"id":2257317},{"batb":[[0,2.58,13.77],[1,2.42,381.73],[2,1.01,15.52]],"ltp":3.1,"tv":0.0,"id":10303696}]}]}
{"op":"mcm","clk":"1005437417","pt":1580642683727,"mc":[{"id":"1.168224296","rc":[{"batb":[[0,1.29,349.59],[1,1.28,369.73],[2,1.27,81.51]],"batl":[[0,1.63,137.62],[1,1.64,122.52]],"ltp":1.48,"tv":0.01,"id":2257317}]}]}
{"op":"mcm","clk":"1005438511","pt":1580642690035,"mc":[{"id":"1.168224296","rc":[{"batb":[[0,1.27,81.51],[1,1.22,523],[2,1.01,15.51]],"ltp":1.48,"tv":0.01,"id":2257317}]}]}
{"op":"mcm","clk":"1005439091","pt":1580642693199,"mc":[{"id":"1.168224296","rc":[{"batb":[[0,1.41,325.37],[1,1.4,234.76],[2,1.27,81.51]],"batl":[[0,1.46,266.51],[1,1.47,184.43]],"ltp":1.48,"tv":0.01,"id":2257317}]}]}
{"op":"mcm","clk":"1005439451","pt":1580642695115,"mc":[{"id":"1.168224296","rc":[{"batb":[[0,1.27,81.51],[1,1.22,523],[2,1.01,15.51]],"ltp":1.48,"tv":0.01,"id":2257317}]}]}
{"op":"mcm","clk":"1005439989","pt":1580642698135,"mc":[{"id":"1.168224296","rc":[{"batb":[[0,1.29,349.59],[1,1.28,369.73],[2,1.27,81.51]],"batl":[[0,1.63,137.62],[1,1.64,122.52]],"ltp":1.48,"tv":0.01,"id":2257317}]}]}
{"op":"mcm","clk":"1005440973","pt":1580642703342,"mc":[{"id":"1.168224296","rc":[{"batb":[[1,1.01,15.52],[2,1.01,0]],"ltp":3.1,"tv":0.0,"id":10303696}]}]}
{"op":"mcm","clk":"1005441159","pt":1580642704355,"mc":[{"id":"1.168224296","rc":[{"batl":[[0,1.33,432.63],[1,1.34,275.96]],"ltp":1.48,"tv":0.01,"id":2257317},{"batb":[[0,4,21.56],[1,3,23.05],[2,1.01,15.52]],"ltp":3.1,"tv":0.0,"id":10303696}]}]}
{"op":"mcm","clk":"1005441383","pt":1580642705535,"mc":[{"id":"1.168224296","rc":[{"batb":[[1,1.28,519.28]],"batl":[[2,1.36,42.01]],"ltp":1.48,"tv":0.01,"id":2257317},{"batb":[[1,3.8,14.28],[2,3,23.05]],"batl":[[0,4.5,11.76]],"ltp":3.1,"tv":0.0,"id":10303696}]}]}
{"op":"mcm","clk":"1005443898","pt":1580642719164,"mc":[{"id":"1.168224296","rc":[{"batb":[[0,1.28,149.55],[1,1.2,114.56],[2,1.16,576.13]],"batl":[[0,1.36,42.01],[1,1.34,0],[2,1.36,0]],"ltp":1.48,"tv":0.01,"id":2257317},{"batb":[[0,3.8,14.28],[1,3,23.05],[2,2.72,378.25]],"ltp":3.1,"tv":0.0,"id":10303696}]}]}
{"op":"mcm","clk":"1005444112","pt":1580642720558,"mc":[{"id":"1.168224296","rc":[{"batb":[[0,1.2,114.56],[1,1.16,576.13],[2,1.01,15.51]],"ltp":1.48,"tv":0.01,"id":2257317},{"batb":[[0,3,23.05],[1,2.72,378.25],[2,1.01,15.52]],"ltp":3.1,"tv":0.0,"id":10303696}]}]}
{"op":"mcm","clk":"1005444421","pt":1580642722165,"mc":[{"id":"1.168224296","rc":[{"batb":[[0,1.22,364.77],[1,1.21,523.97],[2,1.2,114.56]],"batl":[[0,1.5,226.8],[1,1.51,165.9]],"ltp":1.48,"tv":0.01,"id":2257317}]}]}
{"op":"mcm","clk":"1005444752","pt":1580642724153,"mc":[{"id":"1.168224296","rc":[{"batb":[[0,1.2,114.56],[1,1.01,15.51],[2,1.2,0]],"ltp":1.48,"tv":0.01,"id":2257317}]}]}
{"op":"mcm","clk":"1005445281","pt":1580642727003,"mc":[{"id":"1.168224296","rc":[{"batb":[[0,1.32,303.05],[1,1.31,324.86],[2,1.2,114.56]],"batl":[[0,1.36,352.56],[1,1.37,249.33]],"ltp":1.48,"tv":0.01,"id":2257317}]}]}
{"op":"mcm","clk":"1005445866","pt":1580642730315,"mc":[{"id":"1.168224296","rc":[{"batb":[[0,1.2,114.56],[1,1.18,549.72],[2,1.01,15.51]],"ltp":1.48,"tv":0.01,"id":2257317}]}]}
{"op":"mcm","clk":"1005446432","pt":1580642733287,"mc":[{"id":"1.168224296","rc":[{"batb":[[0,1.22,364.77],[1,1.21,523.97],[2,1.2,114.56]],"batl":[[0,1.5,226.8],[1,1.51,165.9]],"ltp":1.48,"tv":0.01,"id":2257317}]}]}
{"op":"mcm","clk":"1005446763","pt":1580642735248,"mc":[{"id":"1.168224296","rc":[{"batb":[[1,1.01,15.52],[2,1.01,0]],"ltp":3.1,"tv":0.0,"id":10303696}]}]}
{"op":"mcm","clk":"1005447130","pt":1580642737271,"mc":[{"id":"1.168224296","rc":[{"batl":[[0,1.25,450.49],[1,1.26,381.68]],"ltp":1.48,"tv":0.01,"id":2257317},{"batb":[[0,5,13.06],[1,3.95,23.53],[2,1.01,15.52]],"ltp":3.1,"tv":0.0,"id":10303696}]}]}
{"op":"mcm","clk":"1005447240","pt":1580642737870,"mc":[{"id":"1.168224296","rc":[{"batb":[[0,1.22,532.81]],"batl":[[2,1.28,42.01]],"ltp":1.48,"tv":0.01,"id":2257317},{"batb":[[1,4.6,10.92],[2,3.95,23.53]],"batl":[[0,5.6,8.4]],"ltp":3.1,"tv":0.0,"id":10303696}]}]}
{"op":"mcm","clk":"1005448951","pt":1580642747034,"mc":[{"id":"1.168224296","rc":[{"batb":[[0,1.22,168.04],[1,1.16,144.07],[2,1.11,684.32]],"batl":[[0,1.28,42.01],[1,1.26,0],[2,1.28,0]],"ltp":1.48,"tv":0.01,"id":2257317},{"batb":[[0,4.6,10.92],[1,3.95,23.53],[2,3,380.84]],"ltp":3.1,"tv":0.0,"id":10303696}]}]}
{"op":"mcm","clk":"1005449255","pt":1580642748630,"mc":[{"id":"1.168224296","rc":[{"batb":[[0,1.16,144.07],[1,1.11,684.32],[2,1.01,15.51]],"ltp":1.48,"tv":0.01,"id":2257317},{"batb":[[0,3.95,23.53],[1,3,380.84],[2,1.01,15.52]],"ltp":3.1,"tv":0.0,"id":10303696}]}]}
{"op":"mcm","clk":"1005449505","pt":1580642749795,"mc":[{"id":"1.168224296","rc":[{"batb":[[0,1.18,494.16],[1,1.17,597.09],[2,1.16,144.07]],"batl":[[0,1.34,399.46],[1,1.35,266.59]],"ltp":1.48,"tv":0.01,"id":2257317}]}]}
{"op":"mcm","clk":"1005451053","pt":1580642758033,"mc":[{"id":"1.168224296","rc":[{"batl":[[0,1.21,628.95],[1,1.22,426.79]],"ltp":1.48,"tv":0.01,"id":2257317}]}]}
{"op":"mcm","clk":"1005451195","pt":1580642758724,"mc":[{"id":"1.168224296","rc":[{"batb":[[0,5.8,18.65],[1,5.4,11.25],[2,3,380.84]],"ltp":3.1,"tv":0.0,"id":10303696}]}]}
{"op":"mcm","clk":"1005451447","pt":1580642760021,"mc":[{"id":"1.168224296","rc":[{"batb":[[0,1.18,662.2]],"batl":[[2,1.23,42.01]],"ltp":1.48,"tv":0.01,"id":2257317},{"batb":[[2,5.3,9.24]],"batl":[[0,6.6,6.72]],"ltp":3.1,"tv":0.0,"id":10303696}]}]}
{"op":"mcm","clk":"1005454974","pt":1580642778902,"mc":[{"id":"1.168224296","rc":[{"batb":[[0,1.13,185.22],[1,1.09,779.05],[2,1.01,15.51]],"ltp":1.48,"tv":0.01,"id":2257317},{"batb":[[0,5.4,11.25],[1,3,380.84],[2,1.01,15.52]],"ltp":3.1,"tv":0.0,"id":10303696}]}]}
{"op":"mcm","clk":"1005455408","pt":1580642781364,"mc":[{"id":"1.168224296","rc":[{"batb":[[0,1.14,942.91],[1,1.13,368.22],[2,1.09,779.05]],"batl":[[0,1.23,352.22],[1,1.24,422.14]],"ltp":1.48,"tv":0.01,"id":2257317}]}]}
{"op":"mcm","clk":"1005459147","pt":1580642800150,"mc":[{"id":"1.168224296","rc":[{"batb":[[0,1.13,185.22],[1,1.09,779.05],[2,1.01,15.51]],"ltp":1.48,"tv":0.01,"id":2257317}]}]}
{"op":"mcm","clk":"1005459455","pt":1580642801955,"mc":[{"id":"1.168224296","rc":[{"batb":[[1,1.01,15.51],[2,1.01,0]],"ltp":1.48,"tv":0.01,"id":2257317}]}]}
{"op":"mcm","clk":"1005459733","pt":1580642803353,"mc":[{"id":"1.168224296","rc":[{"batb":[[0,1.2,622.86],[1,1.19,448.97],[2,1.13,185.22]],"ltp":1.48,"tv":0.01,"id":2257317}]}]}
{"op":"mcm","clk":"1005459853","pt":1580642803944,"mc":[{"id":"1.168224296","rc":[{"batb":[[0,1.2,790.9],[2,1.18,126.13]],"batl":[[2,1.26,42.01]],"ltp":1.48,"tv":0.01,"id":2257317},{"batb":[[1,5,13.38],[2,4.9,10.08]],"batl":[[0,6,8.4]],"ltp":3.1,"tv":0.0,"id":10303696}]}]}
{"op":"mcm","clk":"1005460453","pt":1580642806465,"mc":[{"id":"1.168224296","rc":[{"trd":[[1.2,6.06]],"batb":[[0,1.2,787.87]],"ltp":1.2,"tv":6.06,"id":2257317}],"tv":6.07}]}
{"op":"mcm","clk":"1005461245","pt":1580642810350,"mc":[{"id":"1.168224296","rc":[{"batb":[[0,1.2,168.04],[1,1.15,152.33],[2,1.11,684.32]],"batl":[[0,1.26,42.01],[1,1.24,0],[2,1.26,0]],"ltp":1.2,"tv":6.06,"id":2257317},{"batb":[[0,5,13.38],[1,4.9,10.08],[2,3,380.84]],"ltp":3.1,"tv":0.0,"id":10303696}]}]}
{"op":"mcm","clk":"1005461352","pt":1580642810850,"mc":[{"id":"1.168224296","rc":[{"batb":[[0,1.15,152.33],[1,1.11,684.32],[2,1.01,15.51]],"ltp":1.2,"tv":6.06,"id":2257317},{"batb":[[1,3,380.84],[2,1.01,15.52]],"ltp":3.1,"tv":0.0,"id":10303696}]}]}
{"op":"mcm","clk":"1005461785","pt":1580642812942,"mc":[{"id":"1.168224296","rc":[{"batb":[[0,1.17,667.21],[1,1.16,431.96],[2,1.15,152.33]],"batl":[[0,1.25,299.27],[1,1.26,385]],"ltp":1.2,"tv":6.06,"id":2257317}]}]}
{"op":"mcm","clk":"1005462881","pt":1580642818364,"mc":[{"id":"1.168224296","rc":[{"batl":[[0,1.2,572.06],[1,1.21,486.87]],"ltp":1.2,"tv":6.06,"id":2257317}]}]}
{"op":"mcm","clk":"1005463037","pt":1580642819204,"mc":[{"id":"1.168224296","rc":[{"batb":[[0,6,17.07],[1,5.4,10.86],[2,3,380.84]],"ltp":3.1,"tv":0.0,"id":10303696}]}]}
{"op":"mcm","clk":"1005463124","pt":1580642819580,"mc":[{"id":"1.168224296","rc":[{"batb":[[0,1.17,835.25]],"batl":[[2,1.22,42.01]],"ltp":1.2,"tv":6.06,"id":2257317},{"batb":[[1,5.4,20.1]],"batl":[[0,6.8,6.72]],"ltp":3.1,"tv":0.0,"id":10303696}]}]}
{"op":"mcm","clk":"1005464536","pt":1580642826879,"mc":[{"id":"1.168224296","rc":[{"batb":[[0,1.17,168.04],[1,1.11,207.88],[2,1.08,824.68]],"batl":[[0,1.22,42.01],[1,1.21,0],[2,1.22,0]],"ltp":1.2,"tv":6.06,"id":2257317},{"batb":[[0,5.4,20.1],[1,3,380.84],[2,1.01,15.52]],"ltp":3.1,"tv":0.0,"id":10303696}]}]}
{"op":"mcm","clk":"1005464857","pt":1580642828594,"mc":[{"id":"1.168224296","rc":[{"batb":[[0,1.11,207.88],[1,1.08,824.68],[2,1.01,15.51]],"ltp":1.2,"tv":6.06,"id":2257317},{"batb":[[0,5.4,10.86]],"ltp":3.1,"tv":0.0,"id":10303696}]}]}
{"op":"mcm","clk":"1005465051","pt":1580642829753,"mc":[{"id":"1.168224296","rc":[{"batb":[[0,1.13,611.95],[1,1.12,526.97],[2,1.11,207.88]],"batl":[[0,1.23,492.45],[1,1.24,418.43]],"ltp":1.2,"tv":6.06,"id":2257317}]}]}
{"op":"mcm","clk":"1005465411","pt":1580642831795,"mc":[{"id":"1.168224296","rc":[{"batb":[[0,1.11,207.88],[1,1.08,824.68],[2,1.01,15.51]],"ltp":1.2,"tv":6.06,"id":2257317}]}]}
{"op":"mcm","clk":"1005465986","pt":1580642834987,"mc":[{"id":"1.168224296","rc":[{"batb":[[0,1.16,790.56],[1,1.15,317.09],[2,1.11,207.88]],"batl":[[0,1.19,571.49],[1,1.2,501.36]],"ltp":1.2,"tv":6.06,"id":2257317}]}]}
{"op":"mcm","clk":"1005466239","pt":1580642836287,"mc":[{"id":"1.168224296","rc":[{"batb":[[0,1.11,207.88],[1,1.08,824.68],[2,1.01,15.51]],"ltp":1.2,"tv":6.06,"id":2257317}]}]}
{"op":"mcm","clk":"1005466700","pt":1580642838783,"mc":[{"id":"1.168224296","rc":[{"batb":[[0,1.13,611.95],[1,1.12,526.97],[2,1.11,207.88]],"batl":[[0,1.23,492.45],[1,1.24,418.43]],"ltp":1.2,"tv":6.06,"id":2257317}]}]}
{"op":"mcm","clk":"1005467476","pt":1580642843298,"mc":[{"id":"1.168224296","rc":[{"batb":[[1,1.01,15.52],[2,1.01,0]],"ltp":3.1,"tv":0.0,"id":10303696}]}]}
{"op":"mcm","clk":"1005467819","pt":1580642845171,"mc":[{"id":"1.168224296","rc":[{"batb":[[0,1.13,510.11]],"batl":[[0,1.15,460.78],[1,1.16,548.88]],"ltp":1.2,"tv":6.06,"id":2257317}]}]}
{"op":"mcm","clk":"1005468028","pt":1580642846200,"mc":[{"id":"1.168224296","rc":[{"batl":[[2,1.18,42.01]],"ltp":1.2,"tv":6.06,"id":2257317},{"batb":[[0,7.4,10.31],[1,6.6,6.72],[2,6.2,15.82]],"batl":[[0,8.4,5.04]],"ltp":3.1,"tv":0.0,"id":10303696}]}]}
{"op":"mcm","clk":"1005468379","pt":1580642847918,"mc":[{"id":"1.168224296","rc":[{"batb":[[1,1.12,629.72]],"batl":[[0,1.15,560.88]],"ltp":1.2,"tv":6.06,"id":2257317}]}]}
{"op":"mcm","clk":"1005469543","pt":1580642853930,"mc":[{"id":"1.168224296","rc":[{"batb":[[0,1.07,349.11],[1,1.06,955.61],[2,1.01,15.51]],"batl":[[0,1.18,42.01],[1,1.16,0],[2,1.18,0]],"ltp":1.2,"tv":6.06,"id":2257317},{"batb":[[0,6.6,6.72],[1,6.2,15.82],[2,3.5,371.08]],"ltp":3.1,"tv":0.0,"id":10303696}]}]}
{"op":"mcm","clk":"1005469729","pt":1580642854591,"mc":[{"id":"1.168224296","rc":[{"batb":[[0,6.2,15.82],[1,3.5,371.08],[2,1.01,15.52]],"ltp":3.1,"tv":0.0,"id":10303696}]}]}
{"op":"mcm","clk":"1005470167","pt":1580642856900,"mc":[{"id":"1.168224296","rc":[{"batb":[[0,1.08,624.01],[1,1.07,917.12],[2,1.06,955.61]],"batl":[[0,1.19,591.94],[1,1.2,481.08]],"ltp":1.2,"tv":6.06,"id":2257317}]}]}
{"op":"mcm","clk":"1005470422","pt":1580642858291,"mc":[{"id":"1.168224296","rc":[{"batb":[[0,1.07,349.11],[1,1.06,955.61],[2,1.01,15.51]],"ltp":1.2,"tv":6.06,"id":2257317}]}]}
{"op":"mcm","clk":"1005471083","pt":1580642862212,"mc":[{"id":"1.168224296","rc":[{"batb":[[0,1.12,488.78],[1,1.11,661.51],[2,1.07,349.11]],"batl":[[0,1.14,707.89],[1,1.15,412.79]],"ltp":1.2,"tv":6.06,"id":2257317}]}]}
{"op":"mcm","clk":"1005471160","pt":1580642862623,"mc":[{"id":"1.168224296","rc":[{"batb":[[0,1.07,349.11],[1,1.06,955.61],[2,1.01,15.51]],"ltp":1.2,"tv":6.06,"id":2257317}]}]}
{"op":"mcm","clk":"1005471667","pt":1580642865390,"mc":[{"id":"1.168224296","rc":[{"batb":[[0,1.08,624.01],[1,1.07,917.12]],"ltp":1.2,"tv":6.06,"id":2257317}]}]}
{"op":"mcm","clk":"1005472051","pt":1580642867405,"mc":[{"id":"1.168224296","rc":[{"batl":[[0,1.09,226.16],[1,1.1,941.08]],"ltp":1.2,"tv":6.06,"id":2257317}]}]}
{"op":"mcm","clk":"1005472228","pt":1580642868125,"mc":[{"id":"1.168224296","rc":[{"batb":[[2,1.02,793.11]],"batl":[[2,1.12,42.01]],"ltp":1.2,"tv":6.06,"id":2257317},{"batb":[[0,10.5,11.09],[1,8.4,7.79],[2,3.5,371.08]],"batl":[[0,12.5,3.36]],"ltp":3.1,"tv":0.0,"id":10303696}]}]}
{"op":"mcm","clk":"1005472463","pt":1580642869245,"mc":[{"id":"1.168224296","rc":[{"batb":[[2,1.03,1571.88]],"ltp":1.2,"tv":6.06,"id":2257317}]}]}
{"op":"mcm","clk":"1005472738","pt":1580642870741,"mc":[{"id":"1.168224296","rc":[{"trd":[[1.09,21.84]],"batl":[[0,1.09,215.24]],"ltp":1.09,"tv":27.91,"id":2257317},{"batb":[[1,9.4,4.2],[2,8.4,7.79]],"ltp":3.1,"tv":0.0,"id":10303696}],"tv":27.91}]}
{"op":"mcm","clk":"1005473481","pt":1580642874800,"mc":[{"id":"1.168224296","rc":[{"batb":[[0,1.03,1571.88],[1,1.02,793.11],[2,1.01,15.51]],"ltp":1.09,"tv":27.91,"id":2257317},{"batb":[[0,8.4,7.79],[1,3.5,371.08],[2,1.01,15.52]],"ltp":3.1,"tv":0.0,"id":10303696}]}]}
{"op":"mcm","clk":"1005473640","pt":1580642875608,"mc":[{"id":"1.168224296","rc":[{"batb":[[0,1.02,793.11],[1,1.01,15.51],[2,1.01,0]],"ltp":1.09,"tv":27.91,"id":2257317},{"batb":[[1,1.01,15.52],[2,1.01,0]],"ltp":3.1,"tv":0.0,"id":10303696}]}]}
{"op":"mcm","clk":"1005474522","pt":1580642880609,"mc":[{"id":"1.168224296","rc":[{"batb":[[0,1.07,864.96],[1,1.06,336.04],[2,1.02,793.11]],"batl":[[0,1.08,204.61],[1,1.09,973.14]],"ltp":1.09,"tv":27.91,"id":2257317}]}]}
{"op":"mcm","clk":"1005475019","pt":1580642883490,"mc":[{"id":"1.168224296","rc":[{"batb":[[0,1.02,2977.19],[1,1.01,15.51],[2,1.02,0]],"ltp":1.09,"tv":27.91,"id":2257317},{"batb":[[1,4,369.93],[2,1.01,15.52]],"ltp":3.1,"tv":0.0,"id":10303696}]}]}
{"op":"mcm","clk":"1005475297","pt":1580642884978,"mc":[{"id":"1.168224296","rc":[{"batb":[[0,1.02,793.11]],"ltp":1.09,"tv":27.91,"id":2257317},{"batb":[[1,1.01,15.52],[2,1.01,0]],"ltp":3.1,"tv":0.0,"id":10303696}]}]}
{"op":"mcm","clk":"1005475518","pt":1580642886398,"mc":[{"id":"1.168224296","rc":[{"batb":[[0,1.03,1244.38],[1,1.02,793.11],[2,1.01,15.51]],"batl":[[0,1.13,794.76],[1,1.14,336.51]],"ltp":1.09,"tv":27.91,"id":2257317}]}]}
{"op":"mcm","clk":"1005476749","pt":1580642893571,"mc":[{"id":"1.168224296","rc":[{"batb":[[0,1.02,793.11],[1,1.01,15.51],[2,1.01,0]],"ltp":1.09,"tv":27.91,"id":2257317}]}]}
{"op":"mcm","clk":"1005477374","pt":1580642897189,"mc":[{"id":"1.168224296","rc":[{"batb":[[0,1.11,560.76],[1,1.1,846.08],[2,1.02,793.11]],"ltp":1.09,"tv":27.91,"id":2257317},{"batb":[[1,6.2,15.74],[2,1.01,15.52]],"ltp":3.1,"tv":0.0,"id":10303696}]}]}
{"op":"mcm","clk":"1005477465","pt":1580642897735,"mc":[{"id":"1.168224296","rc":[{"batb":[[2,1.02,770.45]],"batl":[[2,1.15,42.01]],"ltp":1.09,"tv":27.91,"id":2257317},{"batb":[[1,7.6,5.88],[2,6.2,15.74]],"batl":[[0,9.8,4.2]],"ltp":3.1,"tv":0.0,"id":10303696}]}]}
{"op":"mcm","clk":"1005477562","pt":1580642898408,"mc":[{"id":"1.168224296","rc":[{"batb":[[2,1.05,1069.56]],"ltp":1.09,"tv":27.91,"id":2257317}]}]}
{"op":"mcm","clk":"1005480211","pt":1580642913400,"mc":[{"id":"1.168224296","rc":[{"batb":[[0,1.05,1069.56],[1,1.02,770.45],[2,1.01,15.51]],"batl":[[0,1.15,42.01],[1,1.14,0],[2,1.15,0]],"ltp":1.09,"tv":27.91,"id":2257317},{"batb":[[0,7.6,5.88],[1,6.2,15.74],[2,3.6,374.22]],"ltp":3.1,"tv":0.0,"id":10303696}]}]}
{"op":"mcm","clk":"1005480482","pt":1580642914987,"mc":[{"id":"1.168224296","rc":[{"batb":[[0,1.02,770.45],[1,1.01,15.51],[2,1.01,0]],"ltp":1.09,"tv":27.91,"id":2257317},{"batb":[[0,6.2,15.74],[1,1.01,15.52],[2,3.6,0]],"ltp":3.1,"tv":0.0,"id":10303696}]}]}
{"op":"mcm","clk":"1005480671","pt":1580642916309,"mc":[{"id":"1.168224296","rc":[{"batb":[[0,1.03,1244.38],[1,1.02,770.45],[2,1.01,15.51]],"batl":[[0,1.18,165.42],[1,1.19,565.27]],"ltp":1.09,"tv":27.91,"id":2257317}]}]}
{"op":"mcm","clk":"1005483445","pt":1580642932268,"mc":[{"id":"1.168224296","rc":[{"batb":[[0,1.02,770.45],[1,1.01,15.51],[2,1.01,0]],"ltp":1.09,"tv":27.91,"id":2257317}]}]}
{"op":"mcm","clk":"1005483909","pt":1580642935186,"mc":[{"id":"1.168224296","rc":[{"batb":[[0,1.16,620.77],[1,1.15,488.36],[2,1.02,770.45]],"ltp":1.09,"tv":27.91,"id":2257317}]}]}
{"op":"mcm","clk":"1005484070","pt":1580642936100,"mc":[{"id":"1.168224296","rc":[{"batb":[[0,1.16,788.81],[1,1.15,648.32],[2,1.09,248.71]],"batl":[[2,1.21,42.01]],"ltp":1.09,"tv":27.91,"id":2257317},{"batb":[[1,5.8,8.4],[2,5.5,10.78]],"batl":[[0,7.2,6.72]],"ltp":3.1,"tv":0.0,"id":10303696}]}]}
{"op":"mcm","clk":"1005487342","pt":1580642953971,"mc":[{"id":"1.168224296","rc":[{"batb":[[0,1.16,168.04],[1,1.09,248.71],[2,1.08,824.68]],"batl":[[0,1.21,42.01],[1,1.19,0],[2,1.21,0]],"ltp":1.09,"tv":27.91,"id":2257317},{"batb":[[0,5.8,8.4],[1,5.5,10.78],[2,3.25,373.26]],"ltp":3.1,"tv":0.0,"id":10303696}]}]}
{"op":"mcm","clk":"1005487467","pt":1580642954768,"mc":[{"id":"1.168224296","rc":[{"batb":[[0,1.09,248.71],[1,1.08,824.68],[2,1.01,15.51]],"ltp":1.09,"tv":27.91,"id":2257317},{"batb":[[0,5.5,10.78],[1,3.25,373.26],[2,1.01,15.52]],"ltp":3.1,"tv":0.0,"id":10303696}]}]}
{"op":"mcm","clk":"1005488236","pt":1580642959192,"mc":[{"id":"1.168224296","rc":[{"batb":[[0,1.15,551.96],[1,1.14,567.5],[2,1.09,248.71]],"batl":[[0,1.17,314.17],[1,1.18,595.89]],"ltp":1.09,"tv":27.91,"id":2257317}]}]}
{"op":"mcm","clk":"1005488676","pt":1580642961589,"mc":[{"id":"1.168224296","rc":[{"batb":[[0,1.09,248.71],[1,1.08,824.68],[2,1.01,15.51]],"ltp":1.09,"tv":27.91,"id":2257317}]}]}
{"op":"mcm","clk":"1005489180","pt":1580642964493,"mc":[{"id":"1.168224296","rc":[{"batb":[[0,1.11,364.73],[1,1.1,797.14],[2,1.09,248.71]],"batl":[[0,1.23,606.81],[1,1.24,418.1]],"ltp":1.09,"tv":27.91,"id":2257317}]}]}
{"op":"mcm","clk":"1005490454","pt":1580642971509,"mc":[{"id":"1.168224296","rc":[{"batb":[[1,1.01,15.52],[2,1.01,0]],"ltp":3.1,"tv":0.0,"id":10303696}]}]}
{"op":"mcm","clk":"1005490843","pt":1580642973295,"mc":[{"id":"1.168224296","rc":[{"batl":[[0,1.13,963.83],[1,1.14,168.93]],"ltp":1.09,"tv":27.91,"id":2257317}]}]}
{"op":"mcm","clk":"1005490974","pt":1580642974095,"mc":[{"id":"1.168224296","rc":[{"batl":[[2,1.15,42.01]],"ltp":1.09,"tv":27.91,"id":2257317},{"batb":[[0,8.6,7.63],[1,7.6,5.88],[2,6.2,15.42]],"batl":[[0,9.8,4.2]],"ltp":3.1,"tv":0.0,"id":10303696}]}]}
{"op":"mcm","clk":"1005492589","pt":1580642983342,"mc":[{"id":"1.168224296","rc":[{"batb":[[0,1.05,1069.56],[1,1.02,767.86],[2,1.01,15.51]],"batl":[[0,1.15,42.01],[1,1.14,0],[2,1.15,0]],"ltp":1.09,"tv":27.91,"id":2257317},{"batb":[[0,7.6,5.88],[1,6.2,15.42],[2,3.6,374.22]],"ltp":3.1,"tv":0.0,"id":10303696}]}]}
{"op":"mcm","clk":"1005492698","pt":1580642983825,"mc":[{"id":"1.168224296","rc":[{"batb":[[0,1.02,767.86],[1,1.01,15.51],[2,1.01,0]],"ltp":1.09,"tv":27.91,"id":2257317},{"batb":[[2,1.01,15.52]],"ltp":3.1,"tv":0.0,"id":10303696}]}]}
{"op":"mcm","clk":"1005492895","pt":1580642984839,"mc":[{"id":"1.168224296","rc":[{"batb":[[0,6.2,15.42],[1,1.01,15.52],[2,1.01,0]],"ltp":3.1,"tv":0.0,"id":10303696}]}]}
{"op":"mcm","clk":"1005493115","pt":1580642986128,"mc":[{"id":"1.168224296","rc":[{"batb":[[0,1.03,1244.38],[1,1.02,767.86],[2,1.01,15.51]],"batl":[[0,1.18,318.46],[1,1.19,559.69]],"ltp":1.09,"tv":27.91,"id":2257317}]}]}
{"op":"mcm","clk":"1005495257","pt":1580642997399,"mc":[{"id":"1.168224296","rc":[{"batl":[[0,1.05,1229]],"ltp":1.09,"tv":27.91,"id":2257317}]}]}
{"op":"mcm","clk":"1005495407","pt":1580642998270,"mc":[{"id":"1.168224296","rc":[{"batb":[[0,1.04,168.04],[1,1.03,1244.38],[2,1.02,767.86]],"batl":[[1,1.06,42.01]],"ltp":1.09,"tv":27.91,"id":2257317},{"batb":[[0,19,5.9],[1,13.5,6.69],[2,6.2,15.42]],"ltp":3.1,"tv":0.0,"id":10303696}]}]}
{"op":"mcm","clk":"1005495426","pt":1580642998428,"mc":[{"id":"1.168224296","rc":[{"batb":[[2,1.01,15.52]],"ltp":3.1,"tv":0.0,"id":10303696}]}]}
{"op":"mcm","clk":"1005495646","pt":1580642999502,"mc":[{"id":"1.168224296","rc":[{"batb":[[2,4.3,371.17]],"batl":[[0,160,37.1]],"ltp":3.1,"tv":0.0,"id":10303696}]}]}
{"op":"mcm","clk":"1005512289","pt":1580643088114,"mc":[{"id":"1.168224296","rc":[{"batb":[[1,1.01,15.51],[2,1.02,0]],"batl":[[0,1.06,42.01],[1,1.06,0]],"ltp":1.09,"tv":27.91,"id":2257317},{"batb":[[0,13.5,6.69],[1,4.3,371.17],[2,1.01,15.52]],"ltp":3.1,"tv":0.0,"id":10303696}]}]}
{"op":"mcm","clk":"1005512409","pt":1580643088813,"mc":[{"id":"1.168224296","rc":[{"batb":[[0,1.01,15.51],[1,1.01,0]],"ltp":1.09,"tv":27.91,"id":2257317}]}]}
{"op":"mcm","clk":"1005512842","pt":1580643091199,"mc":[{"id":"1.168224296","rc":[{"batb":[[0,1.02,1265.15],[1,1.01,15.51]],"batl":[[0,1.07,1132.45]],"ltp":1.09,"tv":27.91,"id":2257317}]}]}
{"op":"mcm","clk":"1005514781","pt":1580643101300,"mc":[{"id":"1.168224296","rc":[{"batl":[[0,1.04,1240.82]],"ltp":1.09,"tv":27.91,"id":2257317},{"batb":[[0,24,5.41],[1,17,7.55],[2,13.5,6.69]],"ltp":3.1,"tv":0.0,"id":10303696}]}]}
{"op":"mcm","clk":"1005514874","pt":1580643101839,"mc":[{"id":"1.168224296","rc":[{"batb":[[0,1.03,168.04],[1,1.02,1265.15],[2,1.01,15.51]],"ltp":1.09,"tv":27.91,"id":2257317},{"batb":[[2,4.3,371.17]],"ltp":3.1,"tv":0.0,"id":10303696}]}]}
{"op":"mcm","clk":"1005516952","pt":1580643113263,"mc":[{"id":"1.168224296","rc":[{"batb":[[0,1.02,1265.15],[1,1.01,15.51],[2,1.01,0]],"ltp":1.09,"tv":27.91,"id":2257317},{"batb":[[0,17,7.55],[1,4.3,371.17],[2,1.01,15.52]],"ltp":3.1,"tv":0.0,"id":10303696}]}]}
{"op":"mcm","clk":"1005517541","pt":1580643116356,"mc":[{"id":"1.168224296","rc":[{"batl":[[0,1.05,801.64],[1,1.06,423.33]],"ltp":1.09,"tv":27.91,"id":2257317}]}]}
{"op":"mcm","clk":"1005518048","pt":1580643119244,"mc":[{"id":"1.168224296","rc":[{"batb":[[0,1.01,15.51],[1,1.01,0]],"ltp":1.09,"tv":27.91,"id":2257317}]}]}
{"op":"mcm","clk":"1005518626","pt":1580643122381,"mc":[{"id":"1.168224296","rc":[{"batb":[[0,1.04,1240.82],[1,1.01,15.51]],"ltp":1.09,"tv":27.91,"id":2257317}]}]}
{"op":"mcm","clk":"1005518813","pt":1580643123383,"mc":[{"id":"1.168224296","rc":[{"batb":[[1,1.03,663.52],[2,1.02,995.56]],"ltp":1.09,"tv":27.91,"id":2257317},{"batb":[[1,11.5,9.52],[2,4.3,371.17]],"ltp":3.1,"tv":0.0,"id":10303696}]}]}
{"op":"mcm","clk":"1005520718","pt":1580643134273,"mc":[{"id":"1.168224296","rc":[{"batb":[[0,1.02,995.56],[1,1.01,3892.94],[2,1.02,0]],"ltp":1.09,"tv":27.91,"id":2257317},{"batb":[[0,11.5,9.52],[1,4.3,371.17],[2,1.01,15.52]],"ltp":3.1,"tv":0.0,"id":10303696}]}]}
{"op":"mcm","clk":"1005521180","pt":1580643137302,"mc":[{"id":"1.168224296","rc":[{"batb":[[0,1.03,567.73],[1,1.02,1687.41],[2,1.01,3892.94]],"batl":[[0,1.08,668.45],[1,1.09,521.57]],"ltp":1.09,"tv":27.91,"id":2257317}]}]}
{"op":"mcm","clk":"1005521551","pt":1580643139481,"mc":[{"id":"1.168224296","rc":[{"batb":[[0,1.02,995.56],[1,1.01,3892.94],[2,1.01,0]],"ltp":1.09,"tv":27.91,"id":2257317}]}]}
{"op":"mcm","clk":"1005522050","pt":1580643142374,"mc":[{"id":"1.168224296","rc":[{"batb":[[0,1.04,1240.82],[1,1.02,995.56],[2,1.01,3892.94]],"batl":[[0,1.06,1217.41]],"ltp":1.09,"tv":27.91,"id":2257317}]}]}
{"op":"mcm","clk":"1005522708","pt":1580643145283,"mc":[{"id":"1.168224296","rc":[{"batb":[[0,1.02,995.56],[1,1.01,3892.94],[2,1.01,0]],"ltp":1.09,"tv":27.91,"id":2257317}]}]}
{"op":"mcm","clk":"1005523354","pt":1580643148896,"mc":[{"id":"1.168224296","rc":[{"batb":[[0,1.03,567.73],[1,1.02,1687.41],[2,1.01,3892.94]],"batl":[[0,1.08,668.45],[1,1.09,521.57]],"ltp":1.09,"tv":27.91,"id":2257317}]}]}
{"op":"mcm","clk":"1005524297","pt":1580643154304,"mc":[{"id":"1.168224296","rc":[{"batb":[[0,1.02,995.56],[1,1.01,3892.94],[2,1.01,0]],"ltp":1.09,"tv":27.91,"id":2257317}]}]}
{"op":"mcm","clk":"1005524825","pt":1580643157317,"mc":[{"id":"1.168224296","rc":[{"batb":[[0,1.07,360.68],[1,1.06,853.32],[2,1.02,995.56]],"batl":[[0,1.08,668.45],[1,1.09,521.57]],"ltp":1.09,"tv":27.91,"id":2257317}]}]}
{"op":"mcm","clk":"1005525028","pt":1580643158289,"mc":[{"id":"1.168224296","rc":[{"batb":[[1,1.06,1235.56],[2,1.04,580.12]],"ltp":1.09,"tv":27.91,"id":2257317},{"batb":[[0,11.5,12.88],[1,7.8,9.28],[2,4.3,371.17]],"ltp":3.1,"tv":0.0,"id":10303696}]}]}
{"op":"mcm","clk":"1005528531","pt":1580643175315,"mc":[{"id":"1.168224296","rc":[{"batb":[[0,1.04,580.12],[1,1.02,2184.08],[2,1.01,15.51]],"ltp":1.09,"tv":27.91,"id":2257317},{"batb":[[0,7.8,9.28],[1,4.3,371.17],[2,1.01,15.52]],"ltp":3.1,"tv":0.0,"id":10303696}]}]}
{"op":"mcm","clk":"1005529243","pt":1580643178653,"mc":[{"id":"1.168224296","rc":[{"batb":[[1,1.01,15.51],[2,1.01,0]],"ltp":1.09,"tv":27.91,"id":2257317}]}]}
{"op":"mcm","clk":"1005529892","pt":1580643181846,"mc":[{"id":"1.168224296","rc":[{"batb":[[0,1.07,1206.03],[1,1.04,580.12],[2,1.01,15.51]],"batl":[[0,1.09,694.56],[1,1.1,484.88]],"ltp":1.09,"tv":27.91,"id":2257317}]}]}
{"op":"mcm","clk":"1005530087","pt":1580643182862,"mc":[{"id":"1.168224296","rc":[{"batb":[[0,1.04,580.12],[1,1.03,1571.88]],"ltp":1.09,"tv":27.91,"id":2257317}]}]}
{"op":"mcm","clk":"1005530742","pt":1580643186041,"mc":[{"id":"1.168224296","rc":[{"batb":[[0,1.04,1820.94]],"batl":[[0,1.13,595.8],[1,1.14,541.39]],"ltp":1.09,"tv":27.91,"id":2257317}]}]}
{"op":"mcm","clk":"1005532148","pt":1580643193759,"mc":[{"id":"1.168224296","rc":[{"batb":[[1,1.01,15.51],[2,1.01,0]],"ltp":1.09,"tv":27.91,"id":2257317}]}]}
{"op":"mcm","clk":"1005532399","pt":1580643195079,"mc":[{"id":"1.168224296","rc":[{"batl":[[0,1.06,1217.41]],"ltp":1.09,"tv":27.91,"id":2257317}]}]}
{"op":"mcm","clk":"1005532614","pt":1580643196165,"mc":[{"id":"1.168224296","rc":[{"batb":[[1,1.02,1011.69],[2,1.01,15.51]],"batl":[[1,1.07,42.01]],"ltp":1.09,"tv":27.91,"id":2257317},{"batb":[[0,15.5,4.64],[1,9.8,14.24],[2,4.3,371.17]],"ltp":3.1,"tv":0.0,"id":10303696}]}]}
{"op":"mcm","clk":"1005532927","pt":1580643197769,"mc":[{"id":"1.168224296","rc":[{"batb":[[2,1.01,3892.94]],"ltp":1.09,"tv":27.91,"id":2257317}]}]}
{"op":"mcm","clk":"1005535430","pt":1580643209334,"mc":[{"id":"1.168224296","rc":[{"batb":[[0,1.02,1011.69],[1,1.01,3892.94],[2,1.01,0]],"ltp":1.09,"tv":27.91,"id":2257317},{"batb":[[0,9.8,14.24],[1,4.3,371.17],[2,1.01,15.52]],"ltp":3.1,"tv":0.0,"id":10303696}]}]}
{"op":"mcm","clk":"1005535917","pt":1580643211656,"mc":[{"id":"1.168224296","rc":[{"batb":[[0,1.03,255.83],[1,1.02,2018.49],[2,1.01,3892.94]],"batl":[[0,1.1,702.17],[1,1.11,466.72]],"ltp":1.09,"tv":27.91,"id":2257317}]}]}
{"op":"mcm","clk":"1005536604","pt":1580643214937,"mc":[{"id":"1.168224296","rc":[{"batb":[[0,1.02,1011.69],[1,1.01,3892.94],[2,1.01,0]],"ltp":1.09,"tv":27.91,"id":2257317}]}]}
{"op":"mcm","clk":"1005536833","pt":1580643215966,"mc":[{"id":"1.168224296","rc":[{"batb":[[1,1.01,15.51]],"ltp":1.09,"tv":27.91,"id":2257317}]}]}
{"op":"mcm","clk":"1005537593","pt":1580643219335,"mc":[{"id":"1.168224296","rc":[{"batb":[[0,1.05,1229],[1,1.02,1011.69],[2,1.01,15.51]],"batl":[[0,1.07,1206.03]],"ltp":1.09,"tv":27.91,"id":2257317}]}]}
{"op":"mcm","clk":"1005537744","pt":1580643220169,"mc":[{"id":"1.168224296","rc":[{"batb":[[0,1.02,1011.69],[1,1.01,4081.97],[2,1.01,0]],"ltp":1.09,"tv":27.91,"id":2257317}]}]}
{"op":"mcm","clk":"1005538343","pt":1580643223279,"mc":[{"id":"1.168224296","rc":[{"batb":[[0,1.03,255.83],[1,1.02,2018.49],[2,1.01,4081.97]],"batl":[[0,1.1,702.17],[1,1.11,466.72]],"ltp":1.09,"tv":27.91,"id":2257317}]}]}
{"op":"mcm","clk":"1005539641","pt":1580643230360,"mc":[{"id":"1.168224296","rc":[{"batb":[[2,1.01,15.51]],"ltp":1.09,"tv":27.91,"id":2257317}]}]}
{"op":"mcm","clk":"1005539965","pt":1580643232000,"mc":[{"id":"1.168224296","rc":[{"batb":[[0,1.03,423.87]],"batl":[[0,1.04,1240.82]],"ltp":1.09,"tv":27.91,"id":2257317}]}]}
{"op":"mcm","clk":"1005540102","pt":1580643232701,"mc":[{"id":"1.168224296","rc":[{"batb":[[0,23,3.15],[1,15,5.11],[2,4.3,371.17]],"ltp":3.1,"tv":0.0,"id":10303696}]}]}
{"op":"mcm","clk":"1005540391","pt":1580643234305,"mc":[{"id":"1.168224296","rc":[{"batl":[[0,520,35.52]],"ltp":3.1,"tv":0.0,"id":10303696}]}]}
{"op":"mcm","clk":"1005542765","pt":1580643246278,"mc":[{"id":"1.168224296","rc":[{"batb":[[0,1.03,168.04],[1,1.01,15.51],[2,1.01,0]],"ltp":1.09,"tv":27.91,"id":2257317},{"batb":[[0,15,5.11],[1,4.3,371.17],[2,1.01,15.52]],"ltp":3.1,"tv":0.0,"id":10303696}]}]}
{"op":"mcm","clk":"1005542969","pt":1580643247290,"mc":[{"id":"1.168224296","rc":[{"batb":[[0,1.01,15.51],[1,1.01,0]],"ltp":1.09,"tv":27.91,"id":2257317}]}]}
{"op":"mcm","clk":"1005543339","pt":1580643249137,"mc":[{"id":"1.168224296","rc":[{"batb":[[0,1.01,1293.18]],"batl":[[0,1.06,1044.4]],"ltp":1.09,"tv":27.91,"id":2257317}]}]}
{"op":"mcm","clk":"1005543827","pt":1580643251820,"mc":[{"id":"1.168224296","rc":[{"batb":[[0,1.01,15.51]],"ltp":1.09,"tv":27.91,"id":2257317}]}]}
{"op":"mcm","clk":"1005544549","pt":1580643255334,"mc":[{"id":"1.168224296","rc":[{"batb":[[0,1.03,1252.86],[1,1.01,15.51]],"batl":[[0,1.04,1074.16]],"ltp":1.09,"tv":27.91,"id":2257317}]}]}
{"op":"mcm","clk":"1005544710","pt":1580643256135,"mc":[{"id":"1.168224296","rc":[{"batb":[[0,1.01,15.51],[1,1.01,0]],"ltp":1.09,"tv":27.91,"id":2257317}]}]}
{"op":"mcm","clk":"1005544948","pt":1580643257315,"mc":[{"id":"1.168224296","rc":[{"batb":[[1,1.01,15.52],[2,1.01,0]],"ltp":3.1,"tv":0.0,"id":10303696}]}]}
{"op":"mcm","clk":"1005545284","pt":1580643259031,"mc":[{"id":"1.168224296","rc":[{"batb":[[0,1.01,1293.18]],"batl":[[0,1.06,1044.4]],"ltp":1.09,"tv":27.91,"id":2257317}]}]}
{"op":"mcm","clk":"1005547032","pt":1580643268556,"mc":[{"id":"1.168224296","rc":[{"batb":[[0,1.01,15.51]],"ltp":1.09,"tv":27.91,"id":2257317}]}]}
{"op":"mcm","clk":"1005547711","pt":1580643272248,"mc":[{"id":"1.168224296","rc":[{"batb":[[0,1.05,598.27],[1,1.04,1185.6],[2,1.02,941.74]],"batl":[[1,1.07,42.01]],"ltp":1.09,"tv":27.91,"id":2257317},{"batb":[[1,9.4,15.5],[2,1.01,15.52]],"ltp":3.1,"tv":0.0,"id":10303696}]}]}
{"op":"mcm","clk":"1005547979","pt":1580643273530,"mc":[{"id":"1.168224296","rc":[{"batb":[[2,4.1,374.13]],"ltp":3.1,"tv":0.0,"id":10303696}]}]}
{"op":"mcm","clk":"1005551203","pt":1580643290301,"mc":[{"id":"1.168224296","rc":[{"batb":[[0,1.02,941.74],[1,1.01,4081.97],[2,1.02,0]],"batl":[[0,1.07,42.01],[1,1.07,0]],"ltp":1.09,"tv":27.91,"id":2257317},{"batb":[[0,9.4,15.5],[1,4.1,374.13],[2,1.01,15.52]],"ltp":3.1,"tv":0.0,"id":10303696}]}]}
{"op":"mcm","clk":"1005551615","pt":1580643292612,"mc":[{"id":"1.168224296","rc":[{"batb":[[0,1.03,942.06],[1,1.02,1255.59],[2,1.01,4081.97]],"batl":[[0,1.1,229.47],[1,1.11,935.15]],"ltp":1.09,"tv":27.91,"id":2257317}]}]}
{"op":"mcm","clk":"1005553483","pt":1580643302231,"mc":[{"id":"1.168224296","rc":[{"batb":[[0,1.02,941.74],[1,1.01,4081.97],[2,1.01,0]],"ltp":1.09,"tv":27.91,"id":2257317}]}]}
{"op":"mcm","clk":"1005554027","pt":1580643305304,"mc":[{"id":"1.168224296","rc":[{"batb":[[0,1.09,469.66],[1,1.08,720.85],[2,1.02,941.74]],"batl":[[0,1.1,229.47],[1,1.11,935.15]],"ltp":1.09,"tv":27.91,"id":2257317}]}]}
{"op":"mcm","clk":"1005554218","pt":1580643306204,"mc":[{"id":"1.168224296","rc":[{"batb":[[1,1.08,1007.96],[2,1.04,513.24]],"ltp":1.09,"tv":27.91,"id":2257317},{"batb":[[0,9.6,4.2],[1,9.4,15.5],[2,5.8,18.8]],"ltp":3.1,"tv":0.0,"id":10303696}]}]}
{"op":"mcm","clk":"1005554750","pt":1580643308715,"mc":[{"id":"1.168224296","rc":[{"batb":[[2,1.04,1776.24]],"ltp":1.09,"tv":27.91,"id":2257317}]}]}
{"op":"mcm","clk":"1005557646","pt":1580643323149,"mc":[{"id":"1.168224296","rc":[{"batb":[[0,1.04,1776.24],[1,1.01,15.51],[2,1.04,0]],"ltp":1.09,"tv":27.91,"id":2257317},{"batb":[[0,5.8,18.41],[1,4.1,374.13],[2,1.01,15.52]],"ltp":3.1,"tv":0.0,"id":10303696}]}]}
{"op":"mcm","clk":"1005558710","pt":1580643327837,"mc":[{"id":"1.168224296","rc":[{"batb":[[0,1.04,513.24]],"ltp":1.09,"tv":27.91,"id":2257317}]}]}
{"op":"mcm","clk":"1005559223","pt":1580643330337,"mc":[{"id":"1.168224296","rc":[{"batb":[[1,1.01,15.52],[2,1.01,0]],"ltp":3.1,"tv":0.0,"id":10303696}]}]}
{"op":"mcm","clk":"1005559381","pt":1580643331108,"mc":[{"id":"1.168224296","rc":[{"batb":[[0,1.05,1069.56],[1,1.04,513.24],[2,1.01,15.51]],"ltp":1.09,"tv":27.91,"id":2257317}]}]}
{"op":"mcm","clk":"1005559541","pt":1580643331908,"mc":[{"id":"1.168224296","rc":[{"batb":[[0,1.05,1202.33]],"batl":[[0,1.19,449.15],[1,1.2,532.02]],"ltp":1.09,"tv":27.91,"id":2257317}]}]}
{"op":"mcm","clk":"1005562316","pt":1580643345242,"mc":[{"id":"1.168224296","rc":[{"batl":[[0,1.06,536.36],[1,1.07,674.68]],"ltp":1.09,"tv":27.91,"id":2257317}]}]}
{"op":"mcm","clk":"1005562533","pt":1580643346254,"mc":[{"id":"1.168224296","rc":[{"batb":[[0,1.05,1370.37],[2,1.02,893.35]],"batl":[[1,1.07,716.69]],"ltp":1.09,"tv":27.91,"id":2257317},{"batb":[[0,14.5,5.59],[1,9,16.84],[2,1.01,15.52]],"ltp":3.1,"tv":0.0,"id":10303696}]}]}
{"op":"mcm","clk":"1005562722","pt":1580643347155,"mc":[{"id":"1.168224296","rc":[{"batb":[[2,4.1,374.13]],"ltp":3.1,"tv":0.0,"id":10303696}]}]}
{"op":"mcm","clk":"1005565330","pt":1580643360380,"mc":[{"id":"1.168224296","rc":[{"batb":[[0,1.05,168.04],[1,1.02,893.35],[2,1.01,4081.97]],"batl":[[0,1.07,42.01],[1,1.07,0]],"ltp":1.09,"tv":27.91,"id":2257317},{"batb":[[0,9,16.84],[1,4.1,374.13],[2,1.01,15.52]],"ltp":3.1,"tv":0.0,"id":10303696}]}]}
{"op":"mcm","clk":"1005565457","pt":1580643361082,"mc":[{"id":"1.168224296","rc":[{"batb":[[0,1.02,893.35],[1,1.01,4081.97],[2,1.01,0]],"ltp":1.09,"tv":27.91,"id":2257317}]}]}
{"op":"mcm","clk":"1005565913","pt":1580643363265,"mc":[{"id":"1.168224296","rc":[{"batb":[[0,1.03,1252.86],[1,1.02,893.35],[2,1.01,4081.97]],"batl":[[0,1.11,882.42],[1,1.12,277.65]],"ltp":1.09,"tv":27.91,"id":2257317}]}]}
{"op":"mcm","clk":"1005566708","pt":1580643367306,"mc":[{"id":"1.168224296","rc":[{"batb":[[0,1.02,893.35],[1,1.01,4081.97],[2,1.01,0]],"ltp":1.09,"tv":27.91,"id":2257317}]}]}
{"op":"mcm","clk":"1005567209","pt":1580643369204,"mc":[{"id":"1.168224296","rc":[{"batb":[[1,1.01,15.51]],"ltp":1.09,"tv":27.91,"id":2257317}]}]}
{"op":"mcm","clk":"1005567425","pt":1580643370302,"mc":[{"id":"1.168224296","rc":[{"batb":[[0,1.06,605.53],[1,1.05,617.7],[2,1.02,893.35]],"batl":[[0,1.07,702.79],[1,1.08,498.57]],"ltp":1.09,"tv":27.91,"id":2257317}]}]}
{"op":"mcm","clk":"1005567741","pt":1580643371895,"mc":[{"id":"1.168224296","rc":[{"batb":[[0,1.02,893.35],[1,1.01,15.51],[2,1.02,0]],"ltp":1.09,"tv":27.91,"id":2257317}]}]}
{"op":"mcm","clk":"1005568047","pt":1580643373484,"mc":[{"id":"1.168224296","rc":[{"batb":[[0,1.02,3077.43]],"ltp":1.09,"tv":27.91,"id":2257317}]}]}
{"op":"mcm","clk":"1005568419","pt":1580643375384,"mc":[{"id":"1.168224296","rc":[{"batb":[[0,1.03,1252.86],[1,1.02,3077.43],[2,1.01,15.51]],"batl":[[0,1.11,882.42],[1,1.12,277.65]],"ltp":1.09,"tv":27.91,"id":2257317}]}]}
{"op":"mcm","clk":"1005569008","pt":1580643378285,"mc":[{"id":"1.168224296","rc":[{"batb":[[1,1.02,893.35]],"ltp":1.09,"tv":27.91,"id":2257317}]}]}
{"op":"mcm","clk":"1005569335","pt":1580643379989,"mc":[{"id":"1.168224296","rc":[{"batb":[[0,1.03,1420.9]],"batl":[[0,1.04,1240.82]],"ltp":1.09,"tv":27.91,"id":2257317}]}]}
{"op":"mcm","clk":"1005569539","pt":1580643381023,"mc":[{"id":"1.168224296","rc":[{"batb":[[0,21,4.34],[1,14,6.22],[2,4.1,374.13]],"ltp":3.1,"tv":0.0,"id":10303696}]}]}
{"op":"mcm","clk":"1005569807","pt":1580643382403,"mc":[{"id":"1.168224296","rc":[{"batl":[[0,520,35.52]],"ltp":3.1,"tv":0.0,"id":10303696}]}]}
{"op":"mcm","clk":"1005572334","pt":1580643395204,"mc":[{"id":"1.168224296","rc":[{"batb":[[0,1.01,15.51],[1,1.02,0],[2,1.01,0]],"ltp":1.09,"tv":27.91,"id":2257317},{"batb":[[0,14,6.22],[1,4.1,374.13],[2,1.01,15.52]],"ltp":3.1,"tv":0.0,"id":10303696}]}]}
{"op":"mcm","clk":"1005572969","pt":1580643398142,"mc":[{"id":"1.168224296","rc":[{"batb":[[0,1.02,1169.48],[1,1.01,15.51]],"batl":[[0,1.07,1206.03]],"ltp":1.09,"tv":27.91,"id":2257317}]}]}
{"op":"mcm","clk":"1005577430","pt":1580643420328,"mc":[{"id":"1.168224296","rc":[{"batl":[[0,1.03,1252.86]],"ltp":1.09,"tv":27.91,"id":2257317}]}]}
{"op":"mcm","clk":"1005577551","pt":1580643421028,"mc":[{"id":"1.168224296","rc":[{"batb":[[0,26,3.64]],"ltp":3.1,"tv":0.0,"id":10303696}]}]}
{"op":"mcm","clk":"1005577761","pt":1580643422053,"mc":[{"id":"1.168224296","rc":[{"batb":[[0,1.02,1337.52]],"ltp":1.09,"tv":27.91,"id":2257317}]}]}
{"op":"mcm","clk":"1005581847","pt":1580643441139,"mc":[{"id":"1.168224296","rc":[{"batb":[[0,1.01,15.51],[1,1.01,0]],"ltp":1.09,"tv":27.91,"id":2257317}]}]}
{"op":"mcm","clk":"1005582438","pt":1580643444304,"mc":[{"id":"1.168224296","rc":[{"batb":[[0,1.01,1293.18]],"ltp":1.09,"tv":27.91,"id":2257317}]}]}
{"op":"mcm","clk":"1005583796","pt":1580643451313,"mc":[{"id":"1.168224296","rc":[{"batb":[[0,1.01,15.51]],"ltp":1.09,"tv":27.91,"id":2257317}]}]}
{"op":"mcm","clk":"1005584434","pt":1580643454407,"mc":[{"id":"1.168224296","rc":[{"batb":[[0,1.02,1265.15],[1,1.01,15.51]],"ltp":1.09,"tv":27.91,"id":2257317}]}]}
{"op":"mcm","clk":"1005584571","pt":1580643455098,"mc":[{"id":"1.168224296","rc":[{"batb":[[1,24,5.1],[2,4.1,374.13]],"ltp":3.1,"tv":0.0,"id":10303696}]}]}
{"op":"mcm","clk":"1005585388","pt":1580643459088,"mc":[{"id":"1.168224296","rc":[{"batb":[[0,1.02,565.3]],"batl":[[0,1.03,395.08]],"ltp":1.09,"tv":27.91,"id":2257317},{"batb":[[0,24,5.1],[1,4.1,374.13],[2,1.01,15.52]],"ltp":3.1,"tv":0.0,"id":10303696}]}]}
{"op":"mcm","clk":"1005585868","pt":1580643461438,"mc":[{"id":"1.168224296","rc":[{"batb":[[1,1.01,722.28]],"batl":[[1,1.04,849.53]],"ltp":1.09,"tv":27.91,"id":2257317}]}]}
{"op":"mcm","clk":"1005586612","pt":1580643464948,"mc":[{"id":"1.168224296","rc":[{"trd":[[1.02,16.8]],"batb":[[0,1.02,556.9],[1,1.01,15.51]],"ltp":1.02,"tv":44.71,"id":2257317}],"tv":44.71}]}
{"op":"mcm","clk":"1005587096","pt":1580643467371,"mc":[{"id":"1.168224296","rc":[{"batb":[[0,1.02,1256.75]],"ltp":1.02,"tv":44.71,"id":2257317}]}]}
{"op":"mcm","clk":"1005587285","pt":1580643468375,"mc":[{"id":"1.168224296","rc":[{"batl":[[1,1.04,891.54]],"ltp":1.02,"tv":44.71,"id":2257317},{"batb":[[1,23,3.01],[2,4.1,374.13]],"ltp":3.1,"tv":0.0,"id":10303696}]}]}
{"op":"mcm","clk":"1005587857","pt":1580643471456,"mc":[{"id":"1.168224296","rc":[{"batb":[[0,1.02,3718.29]],"ltp":1.02,"tv":44.71,"id":2257317}]}]}
{"op":"mcm","clk":"1005588416","pt":1580643474271,"mc":[{"id":"1.168224296","rc":[{"batb":[[0,1.02,1256.75]],"batl":[[0,1.04,891.54],[1,1.04,0]],"ltp":1.02,"tv":44.71,"id":2257317},{"batb":[[0,23,3.01],[1,4.1,374.13],[2,1.01,15.52]],"ltp":3.1,"tv":0.0,"id":10303696}]}]}
{"op":"mcm","clk":"1005588606","pt":1580643475178,"mc":[{"id":"1.168224296","rc":[{"batl":[[0,1.04,849.53]],"ltp":1.02,"tv":44.71,"id":2257317}]}]}
{"op":"mcm","clk":"1005589024","pt":1580643477260,"mc":[{"id":"1.168224296","rc":[{"batl":[[0,1.04,1240.82]],"ltp":1.02,"tv":44.71,"id":2257317}]}]}
{"op":"mcm","clk":"1005590582","pt":1580643484700,"mc":[{"id":"1.168224296","rc":[{"batl":[[0,1.03,1252.86]],"ltp":1.02,"tv":44.71,"id":2257317}]}]}
{"op":"mcm","clk":"1005590953","pt":1580643486342,"mc":[{"id":"1.168224296","rc":[{"batb":[[0,27,3.23],[1,24,5.1],[2,4.1,374.13]],"ltp":3.1,"tv":0.0,"id":10303696}]}]}
{"op":"mcm","clk":"1005592018","pt":1580643491329,"mc":[{"id":"1.168224296","rc":[{"batb":[[0,1.01,15.51],[1,1.01,0]],"batl":[[0,1.03,310.98]],"ltp":1.02,"tv":44.71,"id":2257317}]}]}
{"op":"mcm","clk":"1005592124","pt":1580643491754,"mc":[{"id":"1.168224296","rc":[{"batb":[[0,24,5.1],[1,4.1,374.13],[2,1.01,15.52]],"ltp":3.1,"tv":0.0,"id":10303696}]}]}
{"op":"mcm","clk":"1005592632","pt":1580643494046,"mc":[{"id":"1.168224296","rc":[{"batb":[[0,1.01,1293.18]],"batl":[[1,1.04,932.82]],"ltp":1.02,"tv":44.71,"id":2257317}]}]}
{"op":"mcm","clk":"1005593027","pt":1580643495957,"mc":[{"id":"1.168224296","rc":[{"batb":[[0,1.01,15.51]],"batl":[[1,1.04,0]],"ltp":1.02,"tv":44.71,"id":2257317}]}]}
{"op":"mcm","clk":"1005594127","pt":1580643500837,"mc":[{"id":"1.168224296","rc":[{"batb":[[0,1.01,1293.18]],"batl":[[1,1.04,932.82]],"ltp":1.02,"tv":44.71,"id":2257317}]}]}
{"op":"mcm","clk":"1005595998","pt":1580643509045,"mc":[{"id":"1.168224296","rc":[{"batb":[[0,1.01,15.51]],"batl":[[1,1.04,0]],"ltp":1.02,"tv":44.71,"id":2257317}]}]}
{"op":"mcm","clk":"1005596691","pt":1580643512365,"mc":[{"id":"1.168224296","rc":[{"batb":[[0,1.01,1293.18]],"batl":[[0,1.03,1294.87]],"ltp":1.02,"tv":44.71,"id":2257317},{"batb":[[0,26,3.52],[1,24,5.1],[2,4.1,374.13]],"ltp":3.1,"tv":0.0,"id":10303696}]}]}
{"op":"mcm","clk":"1005596834","pt":1580643512956,"mc":[{"id":"1.168224296","rc":[{"batl":[[0,1.03,1683.07]],"ltp":1.02,"tv":44.71,"id":2257317},{"batb":[[1,4.1,374.13],[2,1.01,15.52]],"ltp":3.1,"tv":0.0,"id":10303696}]}]}
{"op":"mcm","clk":"1005597498","pt":1580643516197,"mc":[{"id":"1.168224296","rc":[{"batl":[[0,1.03,1294.87]],"ltp":1.02,"tv":44.71,"id":2257317}]}]}
{"op":"mcm","clk":"1005597730","pt":1580643517177,"mc":[{"id":"1.168224296","rc":[{"batl":[[0,1.03,1252.86]],"ltp":1.02,"tv":44.71,"id":2257317}]}]}
{"op":"mcm","clk":"1005598920","pt":1580643522593,"mc":[{"id":"1.168224296","rc":[{"batl":[[0,1.03,798.18]],"ltp":1.02,"tv":44.71,"id":2257317}]}]}
{"op":"mcm","clk":"1005599633","pt":1580643525692,"mc":[{"id":"1.168224296","rc":[{"batb":[[1,1.01,15.52],[2,1.01,0]],"ltp":3.1,"tv":0.0,"id":10303696}]}]}
{"op":"mcm","clk":"1005599875","pt":1580643526718,"mc":[{"id":"1.168224296","rc":[{"batl":[[0,1.03,1252.86]],"ltp":1.02,"tv":44.71,"id":2257317}]}]}
{"op":"mcm","clk":"1005601753","pt":1580643535202,"mc":[{"id":"1.168224296","rc":[{"batb":[[0,1.01,15.52],[1,1.01,0]],"ltp":3.1,"tv":0.0,"id":10303696}]}]}
{"op":"mcm","clk":"1005602405","pt":1580643538402,"mc":[{"id":"1.168224296","rc":[{"batl":[[0,1.02,1307.16]],"ltp":1.02,"tv":44.71,"id":2257317}]}]}
{"op":"mcm","clk":"1005602742","pt":1580643540018,"mc":[{"id":"1.168224296","rc":[{"batb":[[0,4.6,373.8],[1,1.01,15.52]],"ltp":3.1,"tv":0.0,"id":10303696}]}]}
{"op":"mcm","clk":"1005603656","pt":1580643544406,"mc":[{"id":"1.168224296","rc":[{"trd":[[1.01,1573.59]],"batl":[[0,1.02,42.01]],"ltp":1.01,"tv":1618.29,"id":2257317}],"tv":1618.3}]}
{"op":"mcm","clk":"1005604106","pt":1580643546651,"mc":[{"id":"1.168224296","rc":[{"batb":[[0,1.01,15.52],[1,1.01,0]],"ltp":3.1,"tv":0.0,"id":10303696}]}]}
{"op":"mcm","clk":"1005604463","pt":1580643548205,"mc":[{"id":"1.168224296","rc":[{"batl":[[0,1.03,1252.86]],"ltp":1.01,"tv":1618.29,"id":2257317}]}]}
{"op":"mcm","clk":"1005605358","pt":1580643552213,"mc":[{"id":"1.168224296","rc":[{"batl":[[0,1.02,1265.15]],"ltp":1.01,"tv":1618.29,"id":2257317}]}]}
{"op":"mcm","clk":"1005605726","pt":1580643553926,"mc":[{"id":"1.168224296","rc":[{"batb":[[0,4.7,367.67],[1,1.01,15.52]],"ltp":3.1,"tv":0.0,"id":10303696}]}]}
{"op":"mcm","clk":"1005606013","pt":1580643555379,"mc":[{"id":"1.168224296","rc":[{"batl":[[0,1.03,1252.86]],"ltp":1.01,"tv":1618.29,"id":2257317},{"batb":[[0,1.01,15.52],[1,1.01,0]],"ltp":3.1,"tv":0.0,"id":10303696}]}]}
{"op":"mcm","clk":"1005607063","pt":1580643560325,"mc":[{"id":"1.168224296","rc":[{"batl":[[0,1.01,1277.67]],"ltp":1.01,"tv":1618.29,"id":2257317}]}]}
{"op":"mcm","clk":"1005607643","pt":1580643563328,"mc":[{"id":"1.168224296","rc":[{"batb":[[0,4.8,370.06],[1,1.01,15.52]],"ltp":3.1,"tv":0.0,"id":10303696}]}]}
{"op":"mcm","clk":"1005625460","pt":1580643652368,"mc":[{"id":"1.168224296","rc":[{"batb":[[0,1.01,15.52],[1,1.01,0]],"ltp":3.1,"tv":0.0,"id":10303696}]}]}
{"op":"mcm","clk":"1005639874","pt":1580643723855,"mc":[{"id":"1.168224296","rc":[{"batb":[[0,4.8,367.63],[1,1.01,15.52]],"ltp":3.1,"tv":0.0,"id":10303696}]}]}
{"op":"mcm","clk":"1005652510","pt":1580643788364,"mc":[{"id":"1.168224296","rc":[{"batb":[[0,1.01,15.52],[1,1.01,0]],"ltp":3.1,"tv":0.0,"id":10303696}]}]}
{"op":"mcm","clk":"1005656446","pt":1580643808379,"mc":[{"id":"1.168224296","rc":[{"batl":[[0,1.01,1319.68]],"ltp":1.01,"tv":1618.29,"id":2257317}]}]}
{"op":"mcm","clk":"1005656626","pt":1580643809351,"mc":[{"id":"1.168224296","rc":[{"batb":[[0,4.8,367.63],[1,1.01,15.52]],"ltp":3.1,"tv":0.0,"id":10303696}]}]}
{"op":"mcm","clk":"1005659010","pt":1580643822391,"mc":[{"id":"1.168224296","rc":[{"batl":[[0,1.01,42.01]],"ltp":1.01,"tv":1618.29,"id":2257317}]}]}
{"op":"mcm","clk":"1005659301","pt":1580643823973,"mc":[{"id":"1.168224296","rc":[{"batb":[[0,1.01,15.52],[1,1.01,0]],"ltp":3.1,"tv":0.0,"id":10303696}]}]}
{"op":"mcm","clk":"1005659529","pt":1580643825188,"mc":[{"id":"1.168224296","rc":[{"batl":[[0,1.02,1265.15]],"ltp":1.01,"tv":1618.29,"id":2257317}]}]}
{"op":"mcm","clk":"1005661070","pt":1580643833350,"mc":[{"id":"1.168224296","rc":[{"batl":[[0,1.02,1265.15]],"ltp":1.01,"tv":1618.29,"id":2257317}]}]}
{"op":"mcm","clk":"1005662749","pt":1580643842342,"mc":[{"id":"1.168224296","rc":[{"batb":[[0,1.01,1282.17]],"ltp":1.01,"tv":1618.29,"id":2257317},{"batb":[[0,30,2.44],[1,1.01,15.52]],"ltp":3.1,"tv":0.0,"id":10303696}]}]}
{"op":"mcm","clk":"1005662899","pt":1580643843224,"mc":[{"id":"1.168224296","rc":[{"batb":[[1,4.7,367.67],[2,1.01,15.52]],"ltp":3.1,"tv":0.0,"id":10303696}]}]}
{"op":"mcm","clk":"1005668360","pt":1580643874295,"mc":[{"id":"1.168224296","rc":[{"batb":[[0,4.7,367.67],[1,1.01,15.52],[2,1.01,0]],"ltp":3.1,"tv":0.0,"id":10303696}]}]}
{"op":"mcm","clk":"1005668901","pt":1580643877377,"mc":[{"id":"1.168224296","rc":[{"batl":[[0,1.01,1282.17]],"ltp":1.01,"tv":1618.29,"id":2257317}]}]}
{"op":"mcm","clk":"1005671505","pt":1580643891834,"mc":[{"id":"1.168224296","rc":[{"batl":[[0,1.02,1269.61]],"ltp":1.01,"tv":1618.29,"id":2257317}]}]}
{"op":"mcm","clk":"1005675587","pt":1580643912326,"mc":[{"id":"1.168224296","rc":[{"batb":[[0,1.01,833]],"ltp":1.01,"tv":1618.29,"id":2257317},{"batb":[[0,30,2.52],[1,4.7,367.67],[2,1.01,15.52]],"ltp":3.1,"tv":0.0,"id":10303696}]}]}
{"op":"mcm","clk":"1005680134","pt":1580643936369,"mc":[{"id":"1.168224296","rc":[{"batb":[[0,1.01,1450.21]],"batl":[[0,1.02,1311.62]],"ltp":1.01,"tv":1618.29,"id":2257317}]}]}
{"op":"mcm","clk":"1005681992","pt":1580643946368,"mc":[{"id":"1.168224296","rc":[{"trd":[[1.01,2573.59]],"batb":[[0,1.01,950.21]],"ltp":1.01,"tv":2618.29,"id":2257317}],"tv":2618.3}]}
{"op":"mcm","clk":"1005682120","pt":1580643947108,"mc":[{"id":"1.168224296","rc":[{"batb":[[0,1.01,168.04]],"ltp":1.01,"tv":2618.29,"id":2257317},{"batb":[[0,4.7,367.67],[1,1.01,15.52],[2,1.01,0]],"ltp":3.1,"tv":0.0,"id":10303696}]}]}
{"op":"mcm","clk":"1005682288","pt":1580643947967,"mc":[{"id":"1.168224296","rc":[{"batl":[[0,1.02,1269.61]],"ltp":1.01,"tv":2618.29,"id":2257317}]}]}
{"op":"mcm","clk":"1005684744","pt":1580643961212,"mc":[{"id":"1.168224296","rc":[{"batl":[[0,1.02,1661.86]],"ltp":1.01,"tv":2618.29,"id":2257317},{"batb":[[0,30,2.6],[1,4.7,367.67],[2,1.01,15.52]],"ltp":3.1,"tv":0.0,"id":10303696}]}]}
{"op":"mcm","clk":"1005686424","pt":1580643970192,"mc":[{"id":"1.168224296","rc":[{"batl":[[0,1.02,1269.61]],"ltp":1.01,"tv":2618.29,"id":2257317}]}]}
{"op":"mcm","clk":"1005686601","pt":1580643971215,"mc":[{"id":"1.168224296","rc":[{"batb":[[1,1.01,15.52],[2,1.01,0]],"ltp":3.1,"tv":0.0,"id":10303696}]}]}
{"op":"mcm","clk":"1005687818","pt":1580643978397,"mc":[{"id":"1.168224296","rc":[{"batb":[[0,1.01,1450.21]],"batl":[[0,1.02,1311.62]],"ltp":1.01,"tv":2618.29,"id":2257317}]}]}
{"op":"mcm","clk":"1005688084","pt":1580643979885,"mc":[{"id":"1.168224296","rc":[{"batb":[[1,4.6,373.8],[2,1.01,15.52]],"ltp":3.1,"tv":0.0,"id":10303696}]}]}
{"op":"mcm","clk":"1005689158","pt":1580643986008,"mc":[{"id":"1.168224296","rc":[{"batl":[[0,1.02,1269.61]],"ltp":1.01,"tv":2618.29,"id":2257317},{"batb":[[0,4.6,373.8],[1,1.01,15.52],[2,1.01,0]],"ltp":3.1,"tv":0.0,"id":10303696}]}]}
{"op":"mcm","clk":"1005692918","pt":1580644008366,"mc":[{"id":"1.168224296","rc":[{"batl":[[0,1.02,1661.51]],"ltp":1.01,"tv":2618.29,"id":2257317},{"batb":[[0,30,2.56],[1,4.6,373.8],[2,1.01,15.52]],"ltp":3.1,"tv":0.0,"id":10303696}]}]}
{"op":"mcm","clk":"1005694462","pt":1580644018293,"mc":[{"id":"1.168224296","rc":[{"batl":[[0,1.02,1269.61]],"ltp":1.01,"tv":2618.29,"id":2257317}]}]}
{"op":"mcm","clk":"1005694802","pt":1580644020315,"mc":[{"id":"1.168224296","rc":[{"batb":[[1,1.01,15.52],[2,1.01,0]],"ltp":3.1,"tv":0.0,"id":10303696}]}]}
{"op":"mcm","clk":"1005695456","pt":1580644024714,"mc":[{"id":"1.168224296","rc":[{"batl":[[0,1.02,391.72]],"ltp":1.01,"tv":2618.29,"id":2257317}]}]}
{"op":"mcm","clk":"1005696343","pt":1580644030128,"mc":[{"id":"1.168224296","rc":[{"batl":[[0,1.02,1269.61]],"ltp":1.01,"tv":2618.29,"id":2257317}]}]}
{"op":"mcm","clk":"1005697610","pt":1580644037799,"mc":[{"id":"1.168224296","rc":[{"batb":[[0,1.01,15.52],[1,1.01,0]],"ltp":3.1,"tv":0.0,"id":10303696}]}]}
{"op":"mcm","clk":"1005698037","pt":1580644040405,"mc":[{"id":"1.168224296","rc":[{"batl":[[0,1.01,1282.17]],"ltp":1.01,"tv":2618.29,"id":2257317},{"batb":[[0,32,12.5],[1,1.01,15.52]],"ltp":3.1,"tv":0.0,"id":10303696}]}]}
{"op":"mcm","clk":"1005698185","pt":1580644041402,"mc":[{"id":"1.168224296","rc":[{"batb":[[0,1.01,15.52],[1,1.01,0]],"ltp":3.1,"tv":0.0,"id":10303696}]}]}
{"op":"mcm","clk":"1005698510","pt":1580644043278,"mc":[{"id":"1.168224296","rc":[{"batb":[[0,4.7,374.21],[1,1.01,15.52]],"ltp":3.1,"tv":0.0,"id":10303696}]}]}
{"op":"mcm","clk":"1005700496","pt":1580644054823,"mc":[{"id":"1.168224296","rc":[{"batb":[[0,1.01,15.52],[1,1.01,0]],"ltp":3.1,"tv":0.0,"id":10303696}]}]}
{"op":"mcm","clk":"1005700722","pt":1580644056199,"mc":[{"id":"1.168224296","rc":[{"batl":[[0,1.02,1269.61]],"ltp":1.01,"tv":2618.29,"id":2257317}]}]}
{"op":"mcm","clk":"1005702109","pt":1580644065402,"mc":[{"id":"1.168224296","rc":[{"batb":[[0,30,2.48],[1,1.01,15.52]],"batl":[[0,920,2.69]],"ltp":3.1,"tv":0.0,"id":10303696}]}]}
{"op":"mcm","clk":"1005702178","pt":1580644065829,"mc":[{"id":"1.168224296","rc":[{"batb":[[1,4.7,367.67],[2,1.01,15.52]],"ltp":3.1,"tv":0.0,"id":10303696}]}]}
{"op":"mcm","clk":"1005703423","pt":1580644073944,"mc":[{"id":"1.168224296","rc":[{"batb":[[1,1.01,15.52],[2,1.01,0]],"ltp":3.1,"tv":0.0,"id":10303696}]}]}
{"op":"mcm","clk":"1005705354","pt":1580644087130,"mc":[{"id":"1.168224296","rc":[{"batb":[[0,1.01,1282.17]],"ltp":1.01,"tv":2618.29,"id":2257317}]}]}
{"op":"mcm","clk":"1005705493","pt":1580644088039,"mc":[{"id":"1.168224296","rc":[{"batb":[[1,4.6,373.8],[2,1.01,15.52]],"ltp":3.1,"tv":0.0,"id":10303696}]}]}
{"op":"mcm","clk":"1005705599","pt":1580644088927,"mc":[{"id":"1.168224296","rc":[{"batb":[[0,1.01,1450.21]],"batl":[[0,1.02,1311.62]],"ltp":1.01,"tv":2618.29,"id":2257317}]}]}
{"op":"mcm","clk":"1005706640","pt":1580644096275,"mc":[{"id":"1.168224296","rc":[{"batb":[[0,1.01,168.04]],"ltp":1.01,"tv":2618.29,"id":2257317},{"batb":[[0,4.6,373.8],[1,1.01,15.52],[2,1.01,0]],"ltp":3.1,"tv":0.0,"id":10303696}]}]}
{"op":"mcm","clk":"1005706823","pt":1580644097594,"mc":[{"id":"1.168224296","rc":[{"batl":[[0,1.02,1269.61]],"ltp":1.01,"tv":2618.29,"id":2257317}]}]}
{"op":"mcm","clk":"1005708005","pt":1580644105389,"mc":[{"id":"1.168224296","rc":[{"batb":[[0,1.01,1282.17]],"ltp":1.01,"tv":2618.29,"id":2257317}]}]}
{"op":"mcm","clk":"1005708066","pt":1580644105766,"mc":[{"id":"1.168224296","rc":[{"batb":[[0,22,3.61],[1,4.6,373.8],[2,1.01,15.52]],"ltp":3.1,"tv":0.0,"id":10303696}]}]}
{"op":"mcm","clk":"1005710578","pt":1580644124011,"mc":[{"id":"1.168224296","rc":[{"trd":[[1.01,2849.43]],"batb":[[0,1.01,1006.33]],"ltp":1.01,"tv":2894.13,"id":2257317},{"trd":[[110,2.53]],"ltp":110.0,"tv":2.53,"id":10303696}],"tv":2896.67}]}
{"op":"mcm","clk":"1005710887","pt":1580644126320,"mc":[{"id":"1.168224296","rc":[{"trd":[[1.01,3043.13]],"batb":[[0,1.01,909.48]],"ltp":1.01,"tv":3087.83,"id":2257317}],"tv":3090.37}]}
{"op":"mcm","clk":"1005711019","pt":1580644127431,"mc":[{"id":"1.168224296","rc":[{"batb":[[0,1.01,1185.32]],"ltp":1.01,"tv":3087.83,"id":2257317}]}]}
{"op":"mcm","clk":"1005711327","pt":1580644129629,"mc":[{"id":"1.168224296","rc":[{"batb":[[0,1.01,1282.17]],"ltp":1.01,"tv":3087.83,"id":2257317}]}]}
{"op":"mcm","clk":"1005715868","pt":1580644163497,"mc":[{"id":"1.168224296","rc":[{"trd":[[1.01,3083.13]],"batb":[[0,1.01,1262.17]],"ltp":1.01,"tv":3127.83,"id":2257317}],"tv":3130.37}]}
{"op":"mcm","clk":"1005718859","pt":1580644186669,"mc":[{"id":"1.168224296","rc":[{"trd":[[1.01,3159.22]],"batb":[[0,1.01,1224.1]],"ltp":1.01,"tv":3203.93,"id":2257317}],"tv":3206.47}]}
{"op":"mcm","clk":"1005719304","pt":1580644190185,"mc":[{"id":"1.168224296","rc":[{"batb":[[0,1.01,1282.17]],"ltp":1.01,"tv":3203.93,"id":2257317}]}]}
{"op":"mcm","clk":"1005719782","pt":1580644193875,"mc":[{"id":"1.168224296","rc":[{"batb":[[1,1.01,15.52],[2,1.01,0]],"ltp":110.0,"tv":2.53,"id":10303696}]}]}
{"op":"mcm","clk":"1005719951","pt":1580644195186,"mc":[{"id":"1.168224296","rc":[{"batl":[[0,1.03,848.67],[1,1.04,404.67]],"ltp":1.01,"tv":3203.93,"id":2257317}]}]}
{"op":"mcm","clk":"1005721018","pt":1580644202391,"mc":[{"id":"1.168224296","rc":[{"batb":[[0,1.01,15.52],[1,1.01,0]],"ltp":110.0,"tv":2.53,"id":10303696}]}]}
{"op":"mcm","clk":"1005721414","pt":1580644205193,"mc":[{"id":"1.168224296","rc":[{"batl":[[0,1.01,1282.17]],"ltp":1.01,"tv":3203.93,"id":2257317}]}]}
{"op":"mcm","clk":"1005721692","pt":1580644207184,"mc":[{"id":"1.168224296","rc":[{"batb":[[0,4.7,367.67],[1,1.01,15.52]],"ltp":110.0,"tv":2.53,"id":10303696}]}]}
{"op":"mcm","clk":"1005723153","pt":1580644216992,"mc":[{"id":"1.168224296","rc":[{"batb":[[0,1.01,15.52],[1,1.01,0]],"ltp":110.0,"tv":2.53,"id":10303696}]}]}
{"op":"mcm","clk":"1005723520","pt":1580644219101,"mc":[{"id":"1.168224296","rc":[{"batl":[[0,1.02,1269.61]],"ltp":1.01,"tv":3203.93,"id":2257317}]}]}
{"op":"mcm","clk":"1005726418","pt":1580644238393,"mc":[{"id":"1.168224296","rc":[{"batb":[[0,1.01,1282.17]],"ltp":1.01,"tv":3203.93,"id":2257317},{"batb":[[0,19,5.74],[1,1.01,15.52]],"ltp":110.0,"tv":2.53,"id":10303696}]}]}
{"op":"mcm","clk":"1005726699","pt":1580644240297,"mc":[{"id":"1.168224296","rc":[{"batb":[[1,4.5,371.06],[2,1.01,15.52]],"ltp":110.0,"tv":2.53,"id":10303696}]}]}
{"op":"mcm","clk":"1005726958","pt":1580644241981,"mc":[{"id":"1.168224296","rc":[{"batb":[[0,1.01,3744.29]],"ltp":1.01,"tv":3203.93,"id":2257317}]}]}
{"op":"mcm","clk":"1005727750","pt":1580644247295,"mc":[{"id":"1.168224296","rc":[{"batb":[[1,1.01,15.52],[2,1.01,0]],"ltp":110.0,"tv":2.53,"id":10303696}]}]}
{"op":"mcm","clk":"1005727926","pt":1580644248393,"mc":[{"id":"1.168224296","rc":[{"batl":[[0,1.04,1245.19]],"ltp":1.01,"tv":3203.93,"id":2257317}]}]}
{"op":"mcm","clk":"1005729857","pt":1580644262630,"mc":[{"id":"1.168224296","rc":[{"batb":[[0,1.01,15.52],[1,1.01,0]],"ltp":110.0,"tv":2.53,"id":10303696}]}]}
{"op":"mcm","clk":"1005730272","pt":1580644265331,"mc":[{"id":"1.168224296","rc":[{"batl":[[0,1.01,1282.17]],"ltp":1.01,"tv":3203.93,"id":2257317}]}]}
{"op":"mcm","clk":"1005730556","pt":1580644267469,"mc":[{"id":"1.168224296","rc":[{"batb":[[0,4.7,367.67],[1,1.01,15.52]],"ltp":110.0,"tv":2.53,"id":10303696}]}]}
{"op":"mcm","clk":"1005731603","pt":1580644275379,"mc":[{"id":"1.168224296","rc":[{"batb":[[0,1.01,15.52],[1,1.01,0]],"ltp":110.0,"tv":2.53,"id":10303696}]}]}
{"op":"mcm","clk":"1005731753","pt":1580644276385,"mc":[{"id":"1.168224296","rc":[{"batl":[[0,1.03,1257.28]],"ltp":1.01,"tv":3203.93,"id":2257317}]}]}
{"op":"mcm","clk":"1005734621","pt":1580644296398,"mc":[{"id":"1.168224296","rc":[{"batl":[[0,1.01,1282.17]],"ltp":1.01,"tv":3203.93,"id":2257317}]}]}
{"op":"mcm","clk":"1005734806","pt":1580644297716,"mc":[{"id":"1.168224296","rc":[{"batb":[[0,4.8,370.06],[1,1.01,15.52]],"ltp":110.0,"tv":2.53,"id":10303696}]}]}
{"op":"mcm","clk":"1005736081","pt":1580644306748,"mc":[{"id":"1.168224296","rc":[{"batb":[[0,1.01,15.52],[1,1.01,0]],"ltp":110.0,"tv":2.53,"id":10303696}]}]}
{"op":"mcm","clk":"1005738436","pt":1580644323795,"mc":[{"id":"1.168224296","marketDefinition":{"bspMarket":false,"turnInPlayEnabled":true,"persistenceEnabled":true,"marketBaseRate":5.0,"eventId":"29681712","eventTypeId":"2","numberOfWinners":1,"bettingType":"ODDS","marketType":"SET_WINNER","marketTime":"2020-02-02T11:08:00.000Z","suspendTime":"2020-02-02T11:08:00.000Z","bspReconciled":false,"complete":true,"inPlay":true,"crossMatching":true,"runnersVoidable":false,"numberOfActiveRunners":2,"betDelay":3,"status":"SUSPENDED","runners":[{"status":"ACTIVE","sortPriority":1,"id":10303696,"name":"Hugo Gaston"},{"status":"ACTIVE","sortPriority":2,"id":2257317,"name":"Nicolas Mahut"}],"regulators":["MR_INT"],"countryCode":"FR","discountAllowed":true,"timezone":"UTC","openDate":"2020-02-02T11:08:00.000Z","version":3148615871,"name":"Set 1 Winner","eventName":"Hug Gaston v Mahut"}}]}
{"op":"mcm","clk":"1005742612","pt":1580644356054,"mc":[{"id":"1.168224296","tv":0.0}]}
{"op":"mcm","clk":"1005742718","pt":1580644356879,"mc":[{"id":"1.168224296","marketDefinition":{"bspMarket":false,"turnInPlayEnabled":true,"persistenceEnabled":true,"marketBaseRate":5.0,"eventId":"29681712","eventTypeId":"2","numberOfWinners":1,"bettingType":"ODDS","marketType":"SET_WINNER","marketTime":"2020-02-02T11:08:00.000Z","suspendTime":"2020-02-02T11:08:00.000Z","bspReconciled":false,"complete":true,"inPlay":true,"crossMatching":false,"runnersVoidable":false,"numberOfActiveRunners":0,"betDelay":3,"status":"CLOSED","settledTime":"2020-02-02T11:52:35.000Z","runners":[{"status":"LOSER","sortPriority":1,"id":10303696,"name":"Hugo Gaston"},{"status":"WINNER","sortPriority":2,"id":2257317,"name":"Nicolas Mahut"}],"regulators":["MR_INT"],"countryCode":"FR","discountAllowed":true,"timezone":"UTC","openDate":"2020-02-02T11:08:00.000Z","version":3148616623,"name":"Set 1 Winner","eventName":"Hug Gaston v Mahut"}}]}
