{"op":"mcm","clk":"1001176140","pt":1580585265724,"mc":[{"id":"1.168224295","marketDefinition":{"bspMarket":false,"turnInPlayEnabled":true,"persistenceEnabled":true,"marketBaseRate":5.0,"eventId":"29681712","eventTypeId":"2","numberOfWinners":1,"bettingType":"ODDS","marketType":"SET_BETTING","marketTime":"2020-02-02T09:00:00.000Z","suspendTime":"2020-02-02T09:00:00.000Z","bspReconciled":false,"complete":true,"inPlay":false,"crossMatching":false,"runnersVoidable":false,"numberOfActiveRunners":4,"betDelay":0,"status":"OPEN","runners":[{"status":"ACTIVE","sortPriority":1,"id":17293893,"name":"Hug Gaston 2-0"},{"status":"ACTIVE","sortPriority":2,"id":17293892,"name":"Hug Gaston 2-1"},{"status":"ACTIVE","sortPriority":3,"id":13010435,"name":"Mahut 2-0"},{"status":"ACTIVE","sortPriority":4,"id":13010434,"name":"Mahut 2-1"}],"regulators":["MR_INT"],"countryCode":"FR","discountAllowed":false,"timezone":"UTC","openDate":"2020-02-02T09:00:00.000Z","version":3147097868,"name":"Set Betting","eventName":"Hug Gaston v Mahut"}}]}
{"op":"mcm","clk":"1001176494","pt":1580585267445,"mc":[{"id":"1.168224295","marketDefinition":{"bspMarket":false,"turnInPlayEnabled":true,"persistenceEnabled":true,"marketBaseRate":5.0,"eventId":"29681712","eventTypeId":"2","numberOfWinners":1,"bettingType":"ODDS","marketType":"SET_BETTING","marketTime":"2020-02-02T09:00:00.000Z","suspendTime":"2020-02-02T09:00:00.000Z","bspReconciled":false,"complete":true,"inPlay":false,"crossMatching":false,"runnersVoidable":false,"numberOfActiveRunners":4,"betDelay":0,"status":"OPEN","runners":[{"status":"ACTIVE","sortPriority":1,"id":17293893,"name":"Hug Gaston 2-0"},{"status":"ACTIVE","sortPriority":2,"id":17293892,"name":"Hug Gaston 2-1"},{"status":"ACTIVE","sortPriority":3,"id":13010435,"name":"Mahut 2-0"},{"status":"ACTIVE","sortPriority":4,"id":13010434,"name":"Mahut 2-1"}],"regulators":["MR_INT"],"countryCode":"FR","discountAllowed":false,"timezone":"UTC","openDate":"2020-02-02T09:00:00.000Z","version":3147097868,"name":"Set Betting","eventName":"Hug Gaston v Mahut"}}]}
{"op":"mcm","clk":"1001177167","pt":1580585270503,"mc":[{"id":"1.168224295","marketDefinition":{"bspMarket":false,"turnInPlayEnabled":true,"persistenceEnabled":true,"marketBaseRate":5.0,"eventId":"29681712","eventTypeId":"2","numberOfWinners":1,"bettingType":"ODDS","marketType":"SET_BETTING","marketTime":"2020-02-02T09:00:00.000Z","suspendTime":"2020-02-02T09:00:00.000Z","bspReconciled":false,"complete":true,"inPlay":false,"crossMatching":false,"runnersVoidable":false,"numberOfActiveRunners":4,"betDelay":0,"status":"OPEN","runners":[{"status":"ACTIVE","sortPriority":1,"id":17293893,"name":"Hug Gaston 2-0"},{"status":"ACTIVE","sortPriority":2,"id":17293892,"name":"Hug Gaston 2-1"},{"status":"ACTIVE","sortPriority":3,"id":13010435,"name":"Mahut 2-0"},{"status":"ACTIVE","sortPriority":4,"id":13010434,"name":"Mahut 2-1"}],"regulators":["MR_INT"],"countryCode":"FR","discountAllowed":true,"timezone":"UTC","openDate":"2020-02-02T09:00:00.000Z","version":3147097868,"name":"Set Betting","eventName":"Hug Gaston v Mahut"}}]}
{"op":"mcm","clk":"1001221984","pt":1580585512416,"mc":[{"id":"1.168224295","marketDefinition":{"bspMarket":false,"turnInPlayEnabled":true,"persistenceEnabled":true,"marketBaseRate":5.0,"eventId":"29681712","eventTypeId":"2","numberOfWinners":1,"bettingType":"ODDS","marketType":"SET_BETTING","marketTime":"2020-02-02T11:30:00.000Z","suspendTime":"2020-02-02T11:30:00.000Z","bspReconciled":false,"complete":true,"inPlay":false,"crossMatching":false,"runnersVoidable":false,"numberOfActiveRunners":4,"betDelay":0,"status":"OPEN","runners":[{"status":"ACTIVE","sortPriority":1,"id":17293893,"name":"Hug Gaston 2-0"},{"status":"ACTIVE","sortPriority":2,"id":17293892,"name":"Hug Gaston 2-1"},{"status":"ACTIVE","sortPriority":3,"id":13010435,"name":"Mahut 2-0"},{"status":"ACTIVE","sortPriority":4,"id":13010434,"name":"Mahut 2-1"}],"regulators":["MR_INT"],"countryCode":"FR","discountAllowed":true,"timezone":"UTC","openDate":"2020-02-02T09:00:00.000Z","version":3147124629,"name":"Set Betting","eventName":"Hug Gaston v Mahut"}}]}
{"op":"mcm","clk":"1001222392","pt":1580585514425,"mc":[{"id":"1.168224295","marketDefinition":{"bspMarket":false,"turnInPlayEnabled":true,"persistenceEnabled":true,"marketBaseRate":5.0,"eventId":"29681712","eventTypeId":"2","numberOfWinners":1,"bettingType":"ODDS","marketType":"SET_BETTING","marketTime":"2020-02-02T11:30:00.000Z","suspendTime":"2020-02-02T11:30:00.000Z","bspReconciled":false,"complete":true,"inPlay":false,"crossMatching":false,"runnersVoidable":false,"numberOfActiveRunners":4,"betDelay":0,"status":"OPEN","runners":[{"status":"ACTIVE","sortPriority":1,"id":17293893,"name":"Hug Gaston 2-0"},{"status":"ACTIVE","sortPriority":2,"id":17293892,"name":"Hug Gaston 2-1"},{"status":"ACTIVE","sortPriority":3,"id":13010435,"name":"Mahut 2-0"},{"status":"ACTIVE","sortPriority":4,"id":13010434,"name":"Mahut 2-1"}],"regulators":["MR_INT"],"countryCode":"FR","discountAllowed":true,"timezone":"UTC","openDate":"2020-02-02T11:30:00.000Z","version":3147124629,"name":"Set Betting","eventName":"Hug Gaston v Mahut"}}]}
{"op":"mcm","clk":"1001665533","pt":1580587946904,"mc":[{"id":"1.168224295","rc":[{"batb":[[0,1.02,2]],"ltp":0.0,"tv":0.0,"id":13010435},{"batb":[[0,1.02,2]],"ltp":0.0,"tv":0.0,"id":13010434},{"batb":[[0,1.02,2]],"ltp":0.0,"tv":0.0,"id":17293893},{"batb":[[0,1.02,2]],"ltp":0.0,"tv":0.0,"id":17293892}]}]}
{"op":"mcm","clk":"1003032708","pt":1580602187338,"mc":[{"id":"1.168224295","rc":[{"batb":[[1,1.01,2.53]],"ltp":0.0,"tv":0.0,"id":13010435},{"batb":[[1,1.01,2.53]],"ltp":0.0,"tv":0.0,"id":13010434},{"batb":[[1,1.01,2.53]],"ltp":0.0,"tv":0.0,"id":17293893},{"batb":[[1,1.01,2.53]],"ltp":0.0,"tv":0.0,"id":17293892}]}]}
{"op":"mcm","clk":"1003032806","pt":1580602188370,"mc":[{"id":"1.168224295","rc":[{"batb":[[1,1.01,0.51]],"ltp":0.0,"tv":0.0,"id":13010435},{"batb":[[1,1.01,0.51]],"ltp":0.0,"tv":0.0,"id":13010434},{"batb":[[1,1.01,0.51]],"ltp":0.0,"tv":0.0,"id":17293893},{"batb":[[1,1.01,0.51]],"ltp":0.0,"tv":0.0,"id":17293892}]}]}
{"op":"mcm","clk":"1003160475","pt":1580603727376,"mc":[{"id":"1.168224295","rc":[{"batb":[[1,1.01,1.01]],"ltp":0.0,"tv":0.0,"id":13010435},{"batb":[[1,1.01,1.01]],"ltp":0.0,"tv":0.0,"id":13010434},{"batb":[[1,1.01,1.01]],"ltp":0.0,"tv":0.0,"id":17293893},{"batb":[[1,1.01,1.01]],"ltp":0.0,"tv":0.0,"id":17293892}]}]}
{"op":"mcm","clk":"1004449771","pt":1580630119195,"mc":[{"id":"1.168224295","rc":[{"batb":[[0,2.34,30.29],[1,1.02,2],[2,1.01,1.01]],"ltp":0.0,"tv":0.0,"id":13010435}]}]}
{"op":"mcm","clk":"1004691909","pt":1580635315872,"mc":[{"id":"1.168224295","marketDefinition":{"bspMarket":false,"turnInPlayEnabled":true,"persistenceEnabled":true,"marketBaseRate":5.0,"eventId":"29681712","eventTypeId":"2","numberOfWinners":1,"bettingType":"ODDS","marketType":"SET_BETTING","marketTime":"2020-02-02T11:19:00.000Z","suspendTime":"2020-02-02T11:19:00.000Z","bspReconciled":false,"complete":true,"inPlay":false,"crossMatching":false,"runnersVoidable":false,"numberOfActiveRunners":4,"betDelay":0,"status":"OPEN","runners":[{"status":"ACTIVE","sortPriority":1,"id":17293893,"name":"Hug Gaston 2-0"},{"status":"ACTIVE","sortPriority":2,"id":17293892,"name":"Hug Gaston 2-1"},{"status":"ACTIVE","sortPriority":3,"id":13010435,"name":"Mahut 2-0"},{"status":"ACTIVE","sortPriority":4,"id":13010434,"name":"Mahut 2-1"}],"regulators":["MR_INT"],"countryCode":"FR","discountAllowed":true,"timezone":"UTC","openDate":"2020-02-02T11:30:00.000Z","version":3148342766,"name":"Set Betting","eventName":"Hug Gaston v Mahut"}}]}
{"op":"mcm","clk":"1004692044","pt":1580635317946,"mc":[{"id":"1.168224295","marketDefinition":{"bspMarket":false,"turnInPlayEnabled":true,"persistenceEnabled":true,"marketBaseRate":5.0,"eventId":"29681712","eventTypeId":"2","numberOfWinners":1,"bettingType":"ODDS","marketType":"SET_BETTING","marketTime":"2020-02-02T11:19:00.000Z","suspendTime":"2020-02-02T11:19:00.000Z","bspReconciled":false,"complete":true,"inPlay":false,"crossMatching":false,"runnersVoidable":false,"numberOfActiveRunners":4,"betDelay":0,"status":"OPEN","runners":[{"status":"ACTIVE","sortPriority":1,"id":17293893,"name":"Hug Gaston 2-0"},{"status":"ACTIVE","sortPriority":2,"id":17293892,"name":"Hug Gaston 2-1"},{"status":"ACTIVE","sortPriority":3,"id":13010435,"name":"Mahut 2-0"},{"status":"ACTIVE","sortPriority":4,"id":13010434,"name":"Mahut 2-1"}],"regulators":["MR_INT"],"countryCode":"FR","discountAllowed":true,"timezone":"UTC","openDate":"2020-02-02T11:19:00.000Z","version":3148342766,"name":"Set Betting","eventName":"Hug Gaston v Mahut"}}]}
{"op":"mcm","clk":"1004867084","pt":1580638518849,"mc":[{"id":"1.168224295","rc":[{"batb":[[0,1.02,2],[1,1.01,1.01],[2,1.01,0]],"ltp":0.0,"tv":0.0,"id":13010435}]}]}
{"op":"mcm","clk":"1005237285","pt":1580641615820,"mc":[{"id":"1.168224295","marketDefinition":{"bspMarket":false,"turnInPlayEnabled":true,"persistenceEnabled":true,"marketBaseRate":5.0,"eventId":"29681712","eventTypeId":"2","numberOfWinners":1,"bettingType":"ODDS","marketType":"SET_BETTING","marketTime":"2020-02-02T11:10:00.000Z","suspendTime":"2020-02-02T11:10:00.000Z","bspReconciled":false,"complete":true,"inPlay":false,"crossMatching":false,"runnersVoidable":false,"numberOfActiveRunners":4,"betDelay":0,"status":"OPEN","runners":[{"status":"ACTIVE","sortPriority":1,"id":17293893,"name":"Hug Gaston 2-0"},{"status":"ACTIVE","sortPriority":2,"id":17293892,"name":"Hug Gaston 2-1"},{"status":"ACTIVE","sortPriority":3,"id":13010435,"name":"Mahut 2-0"},{"status":"ACTIVE","sortPriority":4,"id":13010434,"name":"Mahut 2-1"}],"regulators":["MR_INT"],"countryCode":"FR","discountAllowed":true,"timezone":"UTC","openDate":"2020-02-02T11:19:00.000Z","version":3148499315,"name":"Set Betting","eventName":"Hug Gaston v Mahut"}}]}
{"op":"mcm","clk":"1005237918","pt":1580641618828,"mc":[{"id":"1.168224295","marketDefinition":{"bspMarket":false,"turnInPlayEnabled":true,"persistenceEnabled":true,"marketBaseRate":5.0,"eventId":"29681712","eventTypeId":"2","numberOfWinners":1,"bettingType":"ODDS","marketType":"SET_BETTING","marketTime":"2020-02-02T11:10:00.000Z","suspendTime":"2020-02-02T11:10:00.000Z","bspReconciled":false,"complete":true,"inPlay":false,"crossMatching":false,"runnersVoidable":false,"numberOfActiveRunners":4,"betDelay":0,"status":"OPEN","runners":[{"status":"ACTIVE","sortPriority":1,"id":17293893,"name":"Hug Gaston 2-0"},{"status":"ACTIVE","sortPriority":2,"id":17293892,"name":"Hug Gaston 2-1"},{"status":"ACTIVE","sortPriority":3,"id":13010435,"name":"Mahut 2-0"},{"status":"ACTIVE","sortPriority":4,"id":13010434,"name":"Mahut 2-1"}],"regulators":["MR_INT"],"countryCode":"FR","discountAllowed":true,"timezone":"UTC","openDate":"2020-02-02T11:10:00.000Z","version":3148499315,"name":"Set Betting","eventName":"Hug Gaston v Mahut"}}]}
{"op":"mcm","clk":"1005278032","pt":1580641823336,"mc":[{"id":"1.168224295","rc":[{"batb":[[0,2.92,24.78],[1,1.02,2],[2,1.01,1.01]],"batl":[[0,3.25,23.84]],"ltp":0.0,"tv":0.0,"id":13010435},{"batb":[[0,4.4,17.86],[1,1.02,2],[2,1.01,1.01]],"batl":[[0,5.1,17]],"ltp":0.0,"tv":0.0,"id":13010434},{"batb":[[0,3.5,15.82],[1,1.02,2],[2,1.01,1.01]],"batl":[[0,3.9,15.34]],"ltp":0.0,"tv":0.0,"id":17293893},{"batb":[[0,4.8,14.24],[1,1.02,2],[2,1.01,1.01]],"batl":[[0,5.7,13.61]],"ltp":0.0,"tv":0.0,"id":17293892}]}]}
{"op":"mcm","clk":"1005278222","pt":1580641824341,"mc":[{"id":"1.168224295","rc":[{"batb":[[1,1.79,21.55],[2,1.02,2]],"ltp":0.0,"tv":0.0,"id":13010435},{"batb":[[1,2.12,19.54],[2,1.02,2]],"ltp":0.0,"tv":0.0,"id":13010434},{"batb":[[1,1.91,15.28],[2,1.02,2]],"ltp":0.0,"tv":0.0,"id":17293893},{"batb":[[1,2.48,14.51],[2,1.02,2]],"ltp":0.0,"tv":0.0,"id":17293892}]}]}
{"op":"mcm","clk":"1005281397","pt":1580641841436,"mc":[{"id":"1.168224295","marketDefinition":{"bspMarket":false,"turnInPlayEnabled":true,"persistenceEnabled":true,"marketBaseRate":5.0,"eventId":"29681712","eventTypeId":"2","numberOfWinners":1,"bettingType":"ODDS","marketType":"SET_BETTING","marketTime":"2020-02-02T11:10:00.000Z","suspendTime":"2020-02-02T11:10:00.000Z","bspReconciled":false,"complete":true,"inPlay":false,"crossMatching":true,"runnersVoidable":false,"numberOfActiveRunners":4,"betDelay":0,"status":"OPEN","runners":[{"status":"ACTIVE","sortPriority":1,"id":17293893,"name":"Hug Gaston 2-0"},{"status":"ACTIVE","sortPriority":2,"id":17293892,"name":"Hug Gaston 2-1"},{"status":"ACTIVE","sortPriority":3,"id":13010435,"name":"Mahut 2-0"},{"status":"ACTIVE","sortPriority":4,"id":13010434,"name":"Mahut 2-1"}],"regulators":["MR_INT"],"countryCode":"FR","discountAllowed":true,"timezone":"UTC","openDate":"2020-02-02T11:10:00.000Z","version":3148499315,"name":"Set Betting","eventName":"Hug Gaston v Mahut"}}]}
{"op":"mcm","clk":"1005286499","pt":1580641868328,"mc":[{"id":"1.168224295","rc":[{"batb":[[0,2.94,24.31]],"batl":[[0,3.25,23.37]],"ltp":0.0,"tv":0.0,"id":13010435},{"batb":[[0,4.4,17.55]],"batl":[[0,5.1,16.68]],"ltp":0.0,"tv":0.0,"id":13010434},{"batb":[[0,3.45,16.21]],"batl":[[0,3.85,15.66]],"ltp":0.0,"tv":0.0,"id":17293893},{"batl":[[0,5.6,13.93]],"ltp":0.0,"tv":0.0,"id":17293892}]}]}
{"op":"mcm","clk":"1005288384","pt":1580641878348,"mc":[{"id":"1.168224295","rc":[{"batb":[[0,2.96,23.76]],"batl":[[0,3.3,22.82]],"ltp":0.0,"tv":0.0,"id":13010435},{"batb":[[0,4.5,17.15]],"batl":[[0,5.2,16.37]],"ltp":0.0,"tv":0.0,"id":13010434},{"batb":[[0,3.4,16.6]],"ltp":0.0,"tv":0.0,"id":17293893},{"batb":[[0,4.7,14.87]],"batl":[[0,5.5,14.24]],"ltp":0.0,"tv":0.0,"id":17293892}]}]}
{"op":"mcm","clk":"1005290305","pt":1580641888350,"mc":[{"id":"1.168224295","rc":[{"batb":[[0,2.98,23.6]],"batl":[[0,3.3,22.66]],"ltp":0.0,"tv":0.0,"id":13010435},{"batl":[[0,3.8,16.21]],"ltp":0.0,"tv":0.0,"id":17293893}]}]}
{"op":"mcm","clk":"1005294742","pt":1580641911370,"mc":[{"id":"1.168224295","rc":[{"batb":[[1,2.96,23.92],[2,1.79,21.55]],"ltp":0.0,"tv":0.0,"id":13010435},{"batl":[[1,3.85,15.97]],"ltp":0.0,"tv":0.0,"id":17293893},{"batb":[[0,4.8,14.79],[1,4.7,14.87],[2,2.48,14.51]],"batl":[[1,5.6,14.16]],"ltp":0.0,"tv":0.0,"id":17293892}]}]}
{"op":"mcm","clk":"1005294946","pt":1580641912377,"mc":[{"id":"1.168224295","rc":[{"batb":[[0,2.96,23.92],[1,1.79,21.55],[2,1.02,2]],"ltp":0.0,"tv":0.0,"id":13010435},{"batl":[[0,3.85,15.97],[1,3.85,0]],"ltp":0.0,"tv":0.0,"id":17293893},{"batb":[[1,2.48,14.51],[2,1.02,2]],"batl":[[0,5.6,14.16],[1,5.6,0]],"ltp":0.0,"tv":0.0,"id":17293892}]}]}
{"op":"mcm","clk":"1005295265","pt":1580641914070,"mc":[{"id":"1.168224295","marketDefinition":{"bspMarket":false,"turnInPlayEnabled":true,"persistenceEnabled":true,"marketBaseRate":5.0,"eventId":"29681712","eventTypeId":"2","numberOfWinners":1,"bettingType":"ODDS","marketType":"SET_BETTING","marketTime":"2020-02-02T11:08:00.000Z","suspendTime":"2020-02-02T11:08:00.000Z","bspReconciled":false,"complete":true,"inPlay":false,"crossMatching":true,"runnersVoidable":false,"numberOfActiveRunners":4,"betDelay":0,"status":"OPEN","runners":[{"status":"ACTIVE","sortPriority":1,"id":17293893,"name":"Hug Gaston 2-0"},{"status":"ACTIVE","sortPriority":2,"id":17293892,"name":"Hug Gaston 2-1"},{"status":"ACTIVE","sortPriority":3,"id":13010435,"name":"Mahut 2-0"},{"status":"ACTIVE","sortPriority":4,"id":13010434,"name":"Mahut 2-1"}],"regulators":["MR_INT"],"countryCode":"FR","discountAllowed":true,"timezone":"UTC","openDate":"2020-02-02T11:10:00.000Z","version":3148508260,"name":"Set Betting","eventName":"Hug Gaston v Mahut"},"rc":[{"batb":[[1,1.02,2],[2,1.01,1.01]],"ltp":0.0,"tv":0.0,"id":13010435},{"batb":[[1,1.02,2],[2,1.01,1.01]],"ltp":0.0,"tv":0.0,"id":13010434},{"batb":[[1,1.02,2],[2,1.01,1.01]],"ltp":0.0,"tv":0.0,"id":17293893},{"batb":[[1,1.02,2],[2,1.01,1.01]],"ltp":0.0,"tv":0.0,"id":17293892}]}]}
{"op":"mcm","clk":"1005295749","pt":1580641916624,"mc":[{"id":"1.168224295","marketDefinition":{"bspMarket":false,"turnInPlayEnabled":true,"persistenceEnabled":true,"marketBaseRate":5.0,"eventId":"29681712","eventTypeId":"2","numberOfWinners":1,"bettingType":"ODDS","marketType":"SET_BETTING","marketTime":"2020-02-02T11:08:00.000Z","suspendTime":"2020-02-02T11:08:00.000Z","bspReconciled":false,"complete":true,"inPlay":false,"crossMatching":true,"runnersVoidable":false,"numberOfActiveRunners":4,"betDelay":0,"status":"OPEN","runners":[{"status":"ACTIVE","sortPriority":1,"id":17293893,"name":"Hug Gaston 2-0"},{"status":"ACTIVE","sortPriority":2,"id":17293892,"name":"Hug Gaston 2-1"},{"status":"ACTIVE","sortPriority":3,"id":13010435,"name":"Mahut 2-0"},{"status":"ACTIVE","sortPriority":4,"id":13010434,"name":"Mahut 2-1"}],"regulators":["MR_INT"],"countryCode":"FR","discountAllowed":true,"timezone":"UTC","openDate":"2020-02-02T11:08:00.000Z","version":3148508260,"name":"Set Betting","eventName":"Hug Gaston v Mahut"}}]}
{"op":"mcm","clk":"1005297809","pt":1580641927883,"mc":[{"id":"1.168224295","rc":[{"batb":[[1,2.62,55.56],[2,1.02,2]],"ltp":0.0,"tv":0.0,"id":13010435},{"batb":[[1,4,30],[2,1.02,2]],"ltp":0.0,"tv":0.0,"id":13010434},{"batb":[[0,3.5,36],[1,3.4,16.6],[2,1.02,2]],"ltp":0.0,"tv":0.0,"id":17293893},{"batb":[[0,5,22.5],[1,4.8,14.79],[2,1.02,2]],"ltp":0.0,"tv":0.0,"id":17293892}]}]}
{"op":"mcm","clk":"1005299870","pt":1580641939348,"mc":[{"id":"1.168224295","rc":[{"batb":[[0,2.94,24.23]],"batl":[[0,3.25,23.29]],"ltp":0.0,"tv":0.0,"id":13010435},{"batb":[[0,4.4,17.47]],"ltp":0.0,"tv":0.0,"id":13010434},{"batb":[[1,3.45,16.29]],"batl":[[0,3.85,15.74]],"ltp":0.0,"tv":0.0,"id":17293893},{"batb":[[1,4.8,14.63]],"batl":[[0,5.6,14.01]],"ltp":0.0,"tv":0.0,"id":17293892}]}]}
{"op":"mcm","clk":"1005324117","pt":1580642078032,"mc":[{"id":"1.168224295","rc":[{"batb":[[0,2.92,24.55]],"ltp":0.0,"tv":0.0,"id":13010435},{"batl":[[0,5.1,16.92]],"ltp":0.0,"tv":0.0,"id":13010434},{"batb":[[1,3.45,15.97]],"batl":[[0,3.9,15.5]],"ltp":0.0,"tv":0.0,"id":17293893},{"batb":[[1,4.8,14.4]],"batl":[[0,5.6,13.77]],"ltp":0.0,"tv":0.0,"id":17293892}]}]}
{"op":"mcm","clk":"1005335757","pt":1580642143190,"mc":[{"id":"1.168224295","rc":[{"batb":[[0,2.96,24.08],[1,2.92,24.55],[2,2.62,55.56]],"batl":[[1,3.3,23.13]],"ltp":0.0,"tv":0.0,"id":13010435},{"batl":[[1,5.2,16.6]],"ltp":0.0,"tv":0.0,"id":13010434},{"batl":[[0,3.85,15.82],[1,3.9,15.5]],"ltp":0.0,"tv":0.0,"id":17293893}]}]}
{"op":"mcm","clk":"1005335826","pt":1580642143570,"mc":[{"id":"1.168224295","rc":[{"batb":[[1,2.62,55.56],[2,1.02,2]],"batl":[[0,3.3,23.13],[1,3.3,0]],"ltp":0.0,"tv":0.0,"id":13010435},{"batl":[[0,5.2,16.6],[1,5.2,0]],"ltp":0.0,"tv":0.0,"id":13010434},{"batl":[[1,3.9,0]],"ltp":0.0,"tv":0.0,"id":17293893}]}]}
{"op":"mcm","clk":"1005340337","pt":1580642168995,"mc":[{"id":"1.168224295","rc":[{"batb":[[0,2.94,24.39]],"batl":[[0,3.25,23.37]],"ltp":0.0,"tv":0.0,"id":13010435},{"batl":[[0,5.1,16.76]],"ltp":0.0,"tv":0.0,"id":13010434},{"batl":[[0,3.85,15.66]],"ltp":0.0,"tv":0.0,"id":17293893}]}]}
{"op":"mcm","clk":"1005342581","pt":1580642180737,"mc":[{"id":"1.168224295","rc":[{"batb":[[1,2.9,21.85],[2,2.62,55.56]],"batl":[[1,3.3,17.64]],"ltp":0.0,"tv":0.0,"id":13010435},{"batb":[[0,4.4,29.23]],"batl":[[1,5.2,9.24]],"ltp":0.0,"tv":0.0,"id":13010434},{"batb":[[2,3.4,16.8]],"batl":[[1,3.95,13.44]],"ltp":0.0,"tv":0.0,"id":17293893},{"batb":[[2,4.7,10.92]],"batl":[[0,5.6,22.17]],"ltp":0.0,"tv":0.0,"id":17293892}]}]}
{"op":"mcm","clk":"1005345137","pt":1580642194229,"mc":[{"id":"1.168224295","rc":[{"batb":[[1,2.92,24.71],[2,2.9,21.85]],"ltp":0.0,"tv":0.0,"id":13010435},{"batl":[[1,3.9,15.42],[2,3.95,13.44]],"ltp":0.0,"tv":0.0,"id":17293893}]}]}
{"op":"mcm","clk":"1005345184","pt":1580642194435,"mc":[{"id":"1.168224295","rc":[{"batb":[[0,2.92,24.71],[1,2.9,21.85],[2,2.62,55.56]],"ltp":0.0,"tv":0.0,"id":13010435},{"batl":[[0,3.9,15.42],[1,3.95,13.44],[2,3.95,0]],"ltp":0.0,"tv":0.0,"id":17293893}]}]}
{"op":"mcm","clk":"1005348190","pt":1580642210978,"mc":[{"id":"1.168224295","rc":[{"batb":[[0,2.94,2],[1,2.92,24.71],[2,2.9,21.85]],"ltp":0.0,"tv":0.0,"id":13010435},{"batb":[[0,4.5,2],[1,4.4,29.23],[2,4,30]],"ltp":0.0,"tv":0.0,"id":13010434},{"batb":[[0,3.55,2],[1,3.5,36],[2,3.45,15.97]],"ltp":0.0,"tv":0.0,"id":17293893},{"batb":[[0,5.1,2],[1,5,22.5],[2,4.8,14.4]],"ltp":0.0,"tv":0.0,"id":17293892}]}]}
{"op":"mcm","clk":"1005359050","pt":1580642270265,"mc":[{"id":"1.168224295","rc":[{"batb":[[0,4.4,29.23],[1,4,30],[2,1.02,2]],"ltp":0.0,"tv":0.0,"id":13010434},{"batb":[[0,3.5,36],[1,3.45,15.97],[2,3.4,16.8]],"ltp":0.0,"tv":0.0,"id":17293893}]}]}
{"op":"mcm","clk":"1005359142","pt":1580642270653,"mc":[{"id":"1.168224295","rc":[{"batb":[[0,2.92,24.71],[1,2.9,21.85],[2,2.62,55.56]],"ltp":0.0,"tv":0.0,"id":13010435},{"batb":[[0,5,22.5],[1,4.8,14.4],[2,4.7,10.92]],"ltp":0.0,"tv":0.0,"id":17293892}]}]}
{"op":"mcm","clk":"1005361952","pt":1580642285213,"mc":[{"id":"1.168224295","rc":[{"batb":[[0,2.94,2],[1,2.92,24.71],[2,2.9,21.85]],"ltp":0.0,"tv":0.0,"id":13010435},{"batb":[[0,4.5,2],[1,4.4,29.23],[2,4,30]],"ltp":0.0,"tv":0.0,"id":13010434},{"batb":[[0,3.55,2],[1,3.5,36],[2,3.45,15.97]],"ltp":0.0,"tv":0.0,"id":17293893},{"batb":[[0,5.1,2],[1,5,22.5],[2,4.8,14.4]],"ltp":0.0,"tv":0.0,"id":17293892}]}]}
{"op":"mcm","clk":"1005373437","pt":1580642344347,"mc":[{"id":"1.168224295","rc":[{"batb":[[0,2.92,24.71],[1,2.9,21.85],[2,2.62,55.56]],"ltp":0.0,"tv":0.0,"id":13010435},{"batb":[[0,4.4,29.23],[1,4,30],[2,1.02,2]],"ltp":0.0,"tv":0.0,"id":13010434},{"batb":[[0,3.5,36],[1,3.45,15.97],[2,3.4,16.8]],"ltp":0.0,"tv":0.0,"id":17293893},{"batb":[[0,5,22.5],[1,4.8,14.4],[2,4.7,10.92]],"ltp":0.0,"tv":0.0,"id":17293892}]}]}
{"op":"mcm","clk":"1005387359","pt":1580642418354,"mc":[{"id":"1.168224295","rc":[{"batb":[[0,2.94,24.23],[1,2.92,24.71],[2,2.9,21.85]],"ltp":0.0,"tv":0.0,"id":13010435},{"batl":[[1,5.2,25.92]],"ltp":0.0,"tv":0.0,"id":13010434},{"batl":[[0,3.85,15.74],[1,3.9,15.42],[2,3.95,13.44]],"ltp":0.0,"tv":0.0,"id":17293893}]}]}
{"op":"mcm","clk":"1005387443","pt":1580642418825,"mc":[{"id":"1.168224295","rc":[{"batb":[[1,2.9,21.85],[2,2.62,55.56]],"ltp":0.0,"tv":0.0,"id":13010435},{"batl":[[0,5.2,25.92],[1,5.2,0]],"ltp":0.0,"tv":0.0,"id":13010434},{"batl":[[1,3.95,13.44],[2,3.95,0]],"ltp":0.0,"tv":0.0,"id":17293893}]}]}
{"op":"mcm","clk":"1005389093","pt":1580642428061,"mc":[{"id":"1.168224295","rc":[{"batb":[[0,2.9,21.85],[1,2.62,55.56],[2,1.02,2]],"batl":[[0,3.3,17.64],[1,3.3,0]],"ltp":0.0,"tv":0.0,"id":13010435},{"batb":[[0,4.4,11.76]],"batl":[[0,5.2,9.24]],"ltp":0.0,"tv":0.0,"id":13010434},{"batb":[[1,3.4,16.8],[2,1.02,2]],"batl":[[0,3.95,13.44],[1,3.95,0]],"ltp":0.0,"tv":0.0,"id":17293893},{"batb":[[1,4.7,10.92],[2,1.02,2]],"batl":[[0,5.6,8.4]],"ltp":0.0,"tv":0.0,"id":17293892}]}]}
{"op":"mcm","clk":"1005389199","pt":1580642428705,"mc":[{"id":"1.168224295","marketDefinition":{"bspMarket":false,"turnInPlayEnabled":true,"persistenceEnabled":true,"marketBaseRate":5.0,"eventId":"29681712","eventTypeId":"2","numberOfWinners":1,"bettingType":"ODDS","marketType":"SET_BETTING","marketTime":"2020-02-02T11:08:00.000Z","suspendTime":"2020-02-02T11:08:00.000Z","bspReconciled":false,"complete":true,"inPlay":true,"crossMatching":true,"runnersVoidable":false,"numberOfActiveRunners":4,"betDelay":3,"status":"OPEN","runners":[{"status":"ACTIVE","sortPriority":1,"id":17293893,"name":"Hug Gaston 2-0"},{"status":"ACTIVE","sortPriority":2,"id":17293892,"name":"Hug Gaston 2-1"},{"status":"ACTIVE","sortPriority":3,"id":13010435,"name":"Mahut 2-0"},{"status":"ACTIVE","sortPriority":4,"id":13010434,"name":"Mahut 2-1"}],"regulators":["MR_INT"],"countryCode":"FR","discountAllowed":true,"timezone":"UTC","openDate":"2020-02-02T11:08:00.000Z","version":3148525270,"name":"Set Betting","eventName":"Hug Gaston v Mahut"},"rc":[{"batb":[[0,1.01,0.51],[1,2.62,0],[2,1.02,0]],"ltp":0.0,"tv":0.0,"id":13010435},{"batb":[[0,1.01,0.51],[1,4,0],[2,1.02,0]],"ltp":0.0,"tv":0.0,"id":13010434},{"batb":[[0,1.01,0.51],[1,3.4,0],[2,1.02,0]],"ltp":0.0,"tv":0.0,"id":17293893},{"batb":[[0,1.01,0.51],[1,4.7,0],[2,1.02,0]],"ltp":0.0,"tv":0.0,"id":17293892}]}]}
{"op":"mcm","clk":"1005391132","pt":1580642439381,"mc":[{"id":"1.168224295","rc":[{"batb":[[0,3.15,20.46],[1,2.88,10.31],[2,1.01,0.51]],"batl":[[0,3.5,19.75],[1,3.7,17.47]],"ltp":0.0,"tv":0.0,"id":13010435},{"batb":[[0,4.4,17.62],[1,1.01,0.51]],"batl":[[0,5.2,16.52]],"ltp":0.0,"tv":0.0,"id":13010434},{"batb":[[0,3.2,19.36],[1,3.05,21.48],[2,1.01,0.51]],"batl":[[0,3.6,18.65],[1,3.95,14.79]],"ltp":0.0,"tv":0.0,"id":17293893},{"batb":[[0,4.7,14.87],[1,1.01,0.51]],"batl":[[0,5.6,14.01]],"ltp":0.0,"tv":0.0,"id":17293892}]}]}
{"op":"mcm","clk":"1005391169","pt":1580642439597,"mc":[{"id":"1.168224295","rc":[{"batb":[[1,3,21],[2,2.88,10.31]],"batl":[[1,3.55,15.96],[2,3.7,17.47]],"ltp":0.0,"tv":0.0,"id":13010435},{"batb":[[0,4.4,29.39]],"batl":[[0,5.2,25.77]],"ltp":0.0,"tv":0.0,"id":13010434},{"batb":[[0,3.2,37.84]],"batl":[[1,3.75,15.12],[2,3.95,14.79]],"ltp":0.0,"tv":0.0,"id":17293893},{"batb":[[1,4.6,10.92],[2,1.01,0.51]],"batl":[[0,5.6,22.41]],"ltp":0.0,"tv":0.0,"id":17293892}]}]}
{"op":"mcm","clk":"1005392607","pt":1580642447277,"mc":[{"id":"1.168224295","rc":[{"batb":[[0,3,21],[1,2.88,10.31],[2,1.01,0.51]],"batl":[[0,3.55,15.96],[1,3.7,17.47],[2,3.7,0]],"ltp":0.0,"tv":0.0,"id":13010435},{"batb":[[0,3.2,18.48]],"batl":[[0,3.75,15.12],[1,3.95,14.79],[2,3.95,0]],"ltp":0.0,"tv":0.0,"id":17293893}]}]}
{"op":"mcm","clk":"1005392859","pt":1580642448667,"mc":[{"id":"1.168224295","rc":[{"batb":[[0,2.88,10.31],[1,1.01,0.51],[2,1.01,0]],"batl":[[0,3.7,17.47],[1,3.7,0]],"ltp":0.0,"tv":0.0,"id":13010435},{"batb":[[0,4.4,17.62]],"batl":[[0,5.2,16.52]],"ltp":0.0,"tv":0.0,"id":13010434},{"batb":[[0,3.05,21.48],[1,1.01,0.51],[2,1.01,0]],"batl":[[0,3.95,14.79],[1,3.95,0]],"ltp":0.0,"tv":0.0,"id":17293893},{"batb":[[1,1.01,0.51],[2,1.01,0]],"batl":[[0,5.6,14.01]],"ltp":0.0,"tv":0.0,"id":17293892}]}]}
{"op":"mcm","clk":"1005393148","pt":1580642450240,"mc":[{"id":"1.168224295","rc":[{"batb":[[0,3.1,21.4],[1,3.05,21.48],[2,1.01,0.51]],"batl":[[1,4,14.71]],"ltp":0.0,"tv":0.0,"id":17293893},{"batb":[[0,4.8,14.87],[1,4.7,14.87],[2,1.01,0.51]],"ltp":0.0,"tv":0.0,"id":17293892}]}]}
{"op":"mcm","clk":"1005393201","pt":1580642450543,"mc":[{"id":"1.168224295","rc":[{"batb":[[1,1.01,0.51],[2,1.01,0]],"batl":[[0,4,14.71],[1,4,0]],"ltp":0.0,"tv":0.0,"id":17293893},{"batb":[[1,1.01,0.51],[2,1.01,0]],"ltp":0.0,"tv":0.0,"id":17293892}]}]}
{"op":"mcm","clk":"1005395475","pt":1580642463030,"mc":[{"id":"1.168224295","rc":[{"batb":[[1,2.56,14.01],[2,1.01,0.51]],"batl":[[0,3.2,24.78],[1,3.4,20.93]],"ltp":0.0,"tv":0.0,"id":13010435},{"batl":[[1,5.3,15.89]],"ltp":0.0,"tv":0.0,"id":13010434},{"batb":[[0,3.55,15.19],[1,3.3,17.86],[2,1.01,0.51]],"batl":[[1,4.8,19.91]],"ltp":0.0,"tv":0.0,"id":17293893},{"batl":[[0,5.6,13.77]],"ltp":0.0,"tv":0.0,"id":17293892}]}]}
{"op":"mcm","clk":"1005395627","pt":1580642463923,"mc":[{"id":"1.168224295","rc":[{"batb":[[1,2.82,22.69],[2,2.56,14.01]],"batl":[[1,3.25,18.48],[2,3.4,20.93]],"ltp":0.0,"tv":0.0,"id":13010435},{"batb":[[1,4.3,12.6],[2,1.01,0.51]],"batl":[[0,5.2,25.77]],"ltp":0.0,"tv":0.0,"id":13010434},{"batb":[[1,3.45,16.8],[2,3.3,17.86]],"batl":[[1,4.1,13.44],[2,4.8,19.91]],"ltp":0.0,"tv":0.0,"id":17293893},{"batb":[[1,4.7,10.92],[2,1.01,0.51]],"batl":[[1,5.7,8.4]],"ltp":0.0,"tv":0.0,"id":17293892}]}]}
{"op":"mcm","clk":"1005397004","pt":1580642471757,"mc":[{"id":"1.168224295","rc":[{"batb":[[0,2.82,22.69],[1,2.56,14.01],[2,1.01,0.51]],"batl":[[0,3.25,18.48],[1,3.4,20.93],[2,3.4,0]],"ltp":0.0,"tv":0.0,"id":13010435},{"batl":[[0,5.2,9.24]],"ltp":0.0,"tv":0.0,"id":13010434},{"batb":[[0,3.45,16.8],[1,3.3,17.86],[2,1.01,0.51]],"batl":[[0,4.1,13.44],[1,4.8,19.91],[2,4.8,0]],"ltp":0.0,"tv":0.0,"id":17293893}]}]}
{"op":"mcm","clk":"1005397159","pt":1580642472550,"mc":[{"id":"1.168224295","rc":[{"batb":[[0,2.56,14.01],[1,1.01,0.51],[2,1.01,0]],"batl":[[0,3.4,20.93],[1,3.4,0]],"ltp":0.0,"tv":0.0,"id":13010435},{"batb":[[1,1.01,0.51],[2,1.01,0]],"batl":[[0,5.3,15.89],[1,5.3,0]],"ltp":0.0,"tv":0.0,"id":13010434},{"batb":[[0,3.3,17.86],[1,1.01,0.51],[2,1.01,0]],"batl":[[0,4.8,19.91],[1,4.8,0]],"ltp":0.0,"tv":0.0,"id":17293893},{"batb":[[1,1.01,0.51],[2,1.01,0]],"batl":[[1,5.7,0]],"ltp":0.0,"tv":0.0,"id":17293892}]}]}
{"op":"mcm","clk":"1005403302","pt":1580642507796,"mc":[{"id":"1.168224295","rc":[{"batb":[[0,2.56,40.89],[1,2.22,20.54],[2,1.01,0.51]],"batl":[[0,2.78,13.77],[1,2.92,21.85],[2,3.05,10.86]],"ltp":0.0,"tv":0.0,"id":13010435},{"batb":[[0,4.5,16.76],[1,4.4,29.15],[2,1.01,0.51]],"batl":[[0,5.3,25.14],[1,5.4,15.03]],"ltp":0.0,"tv":0.0,"id":13010434},{"batb":[[0,4.1,20.85],[1,3.95,13.44],[2,3.7,13.77]],"batl":[[0,4.8,30.83],[1,6.2,11.02]],"ltp":0.0,"tv":0.0,"id":17293893},{"batb":[[1,4.7,10.92],[2,1.01,0.51]],"batl":[[1,5.7,8.4]],"ltp":0.0,"tv":0.0,"id":17293892}]}]}
{"op":"mcm","clk":"1005404979","pt":1580642517321,"mc":[{"id":"1.168224295","rc":[{"batb":[[0,2.56,26.89]],"batl":[[0,2.92,21.85],[1,3.05,10.86],[2,3.05,0]],"ltp":0.0,"tv":0.0,"id":13010435},{"batb":[[0,4.4,29.15],[1,1.01,0.51],[2,1.01,0]],"batl":[[0,5.3,9.24]],"ltp":0.0,"tv":0.0,"id":13010434},{"batb":[[0,3.95,13.44],[1,3.7,13.77],[2,1.01,0.51]],"batl":[[0,4.8,10.92]],"ltp":0.0,"tv":0.0,"id":17293893}]}]}
{"op":"mcm","clk":"1005405224","pt":1580642518601,"mc":[{"id":"1.168224295","rc":[{"batb":[[0,2.22,20.54],[1,1.01,0.51],[2,1.01,0]],"batl":[[0,3.05,10.86],[1,3.05,0]],"ltp":0.0,"tv":0.0,"id":13010435},{"batb":[[0,4.4,17.39]],"batl":[[0,5.4,15.03],[1,5.4,0]],"ltp":0.0,"tv":0.0,"id":13010434},{"batb":[[0,3.7,13.77],[1,1.01,0.51],[2,1.01,0]],"batl":[[0,6.2,11.02],[1,6.2,0]],"ltp":0.0,"tv":0.0,"id":17293893},{"batb":[[1,1.01,0.51],[2,1.01,0]],"batl":[[1,5.7,0]],"ltp":0.0,"tv":0.0,"id":17293892}]}]}
{"op":"mcm","clk":"1005405625","pt":1580642520659,"mc":[{"id":"1.168224295","rc":[{"batl":[[0,6.4,11.02]],"ltp":0.0,"tv":0.0,"id":17293893},{"batb":[[0,4.8,14.71]],"ltp":0.0,"tv":0.0,"id":17293892}]}]}
{"op":"mcm","clk":"1005408691","pt":1580642536859,"mc":[{"id":"1.168224295","rc":[{"batb":[[1,1.96,29.98],[2,1.01,0.51]],"batl":[[0,2.4,20.06],[1,2.62,15.97]],"ltp":0.0,"tv":0.0,"id":13010435},{"batb":[[0,4.6,16.37]],"batl":[[1,5.6,14.01]],"ltp":0.0,"tv":0.0,"id":13010434},{"batb":[[0,5.3,11.41],[1,4.5,16.76],[2,1.01,0.51]],"batl":[[1,9.4,9.76]],"ltp":0.0,"tv":0.0,"id":17293893}]}]}
{"op":"mcm","clk":"1005408904","pt":1580642537870,"mc":[{"id":"1.168224295","rc":[{"batb":[[0,2.26,32.77],[1,2.22,20.54],[2,1.96,29.98]],"batl":[[1,2.58,26.05],[2,2.62,15.97]],"ltp":0.0,"tv":0.0,"id":13010435},{"batb":[[1,4.5,11.76],[2,1.01,0.51]],"batl":[[0,5.4,24.27]],"ltp":0.0,"tv":0.0,"id":13010434},{"batl":[[0,6,8.4],[1,6.4,11.02],[2,9.4,9.76]],"ltp":0.0,"tv":0.0,"id":17293893},{"batb":[[1,4.7,10.92],[2,1.01,0.51]],"batl":[[0,5.6,22.17]],"ltp":0.0,"tv":0.0,"id":17293892}]}]}
{"op":"mcm","clk":"1005409138","pt":1580642539054,"mc":[{"id":"1.168224295","rc":[{"batb":[[1,4.9,10.08],[2,4.5,16.76]],"ltp":0.0,"tv":0.0,"id":17293893}]}]}
{"op":"mcm","clk":"1005410187","pt":1580642544898,"mc":[{"id":"1.168224295","rc":[{"batb":[[1,1.96,29.98],[2,1.01,0.51]],"batl":[[0,2.58,26.05],[1,2.62,15.97],[2,2.62,0]],"ltp":0.0,"tv":0.0,"id":13010435},{"batl":[[0,5.4,9.24]],"ltp":0.0,"tv":0.0,"id":13010434},{"batb":[[0,4.9,10.08],[1,4.5,16.76],[2,1.01,0.51]],"batl":[[1,9.4,9.76],[2,9.4,0]],"ltp":0.0,"tv":0.0,"id":17293893}]}]}
{"op":"mcm","clk":"1005410500","pt":1580642546551,"mc":[{"id":"1.168224295","rc":[{"batb":[[0,1.96,29.98],[1,1.01,0.51],[2,1.01,0]],"batl":[[0,2.62,15.97],[1,2.62,0]],"ltp":0.0,"tv":0.0,"id":13010435},{"batb":[[1,1.01,0.51],[2,1.01,0]],"batl":[[0,5.6,14.01],[1,5.6,0]],"ltp":0.0,"tv":0.0,"id":13010434},{"batb":[[0,4.5,16.76],[1,1.01,0.51],[2,1.01,0]],"batl":[[0,9.4,9.76],[1,9.4,0]],"ltp":0.0,"tv":0.0,"id":17293893},{"batb":[[1,1.01,0.51],[2,1.01,0]],"batl":[[0,5.6,13.77]],"ltp":0.0,"tv":0.0,"id":17293892}]}]}
{"op":"mcm","clk":"1005414101","pt":1580642564947,"mc":[{"id":"1.168224295","rc":[{"batb":[[1,1.9,16.52],[2,1.01,0.51]],"batl":[[0,2.1,29.19],[1,2.28,23.45]],"ltp":0.0,"tv":0.0,"id":13010435},{"batb":[[0,4.7,15.34]],"batl":[[0,5.6,13.85]],"ltp":0.0,"tv":0.0,"id":13010434},{"batb":[[0,7.6,10.23],[1,6,16.84],[2,1.01,0.51]],"batl":[[1,11,7.32]],"ltp":0.0,"tv":0.0,"id":17293893},{"batb":[[0,4.7,14.95]],"ltp":0.0,"tv":0.0,"id":17293892}]}]}
{"op":"mcm","clk":"1005414283","pt":1580642565866,"mc":[{"id":"1.168224295","rc":[{"batb":[[0,1.96,73.67]],"batl":[[1,2.18,35.29],[2,2.28,23.45]],"ltp":0.0,"tv":0.0,"id":13010435},{"batb":[[1,4.5,11.76],[2,1.01,0.51]],"batl":[[0,5.4,9.24],[1,5.6,13.85]],"ltp":0.0,"tv":0.0,"id":13010434},{"batb":[[1,7,6.72],[2,6,16.84]],"batl":[[0,9,5.04],[1,9.4,9.76],[2,11,7.32]],"ltp":0.0,"tv":0.0,"id":17293893},{"batb":[[0,4.9,10.08],[1,4.7,14.95],[2,1.01,0.51]],"batl":[[1,5.9,8.4]],"ltp":0.0,"tv":0.0,"id":17293892}]}]}
{"op":"mcm","clk":"1005415473","pt":1580642571858,"mc":[{"id":"1.168224295","rc":[{"batb":[[0,1.97,69.93],[1,1.96,73.67],[2,1.9,16.52]],"ltp":0.0,"tv":0.0,"id":13010435},{"batb":[[0,4.8,35.2],[1,4.7,15.34],[2,4.5,11.76]],"ltp":0.0,"tv":0.0,"id":13010434},{"batb":[[0,7.8,20.1],[1,7.6,10.23],[2,7,6.72]],"ltp":0.0,"tv":0.0,"id":17293893},{"batb":[[0,5.1,27.03],[1,4.9,10.08],[2,4.7,14.95]],"ltp":0.0,"tv":0.0,"id":17293892}]}]}
{"op":"mcm","clk":"1005415647","pt":1580642572764,"mc":[{"id":"1.168224295","rc":[{"batb":[[1,1.96,43.69],[2,1.95,30.69]],"batl":[[0,2.08,29.74],[2,2.26,23.92]],"ltp":0.0,"tv":0.0,"id":13010435},{"batb":[[1,4.7,14.87],[2,4.6,15.66]],"batl":[[1,5.5,14.24],[2,5.6,13.85]],"ltp":0.0,"tv":0.0,"id":13010434},{"batb":[[1,7.6,9.84]],"batl":[[1,9.6,9.36],[2,11,7.08]],"ltp":0.0,"tv":0.0,"id":17293893},{"batb":[[2,4.8,14.48]],"batl":[[0,5.7,13.38]],"ltp":0.0,"tv":0.0,"id":17293892}]}]}
{"op":"mcm","clk":"1005416067","pt":1580642574856,"mc":[{"id":"1.168224295","rc":[{"batb":[[2,1.95,102.84]],"ltp":0.0,"tv":0.0,"id":13010435},{"batb":[[0,4.8,54.09],[1,4.7,51.22]],"ltp":0.0,"tv":0.0,"id":13010434},{"batb":[[0,8,13.16],[1,7.8,20.1],[2,7.6,9.84]],"ltp":0.0,"tv":0.0,"id":17293893},{"batb":[[0,5.2,24.77],[1,5.1,27.03],[2,4.9,10.08]],"ltp":0.0,"tv":0.0,"id":17293892}]}]}
{"op":"mcm","clk":"1005421129","pt":1580642600918,"mc":[{"id":"1.168224295","rc":[{"batb":[[0,1.96,43.69],[1,1.95,30.69],[2,1.89,16.92]],"ltp":0.0,"tv":0.0,"id":13010435},{"batb":[[0,4.8,27.01]],"ltp":0.0,"tv":0.0,"id":13010434},{"batb":[[0,7.6,9.84],[1,7.2,6.72],[2,6.2,16.29]],"ltp":0.0,"tv":0.0,"id":17293893},{"batb":[[0,5.1,27.03],[1,4.9,10.08],[2,4.8,14.48]],"ltp":0.0,"tv":0.0,"id":17293892}]}]}
{"op":"mcm","clk":"1005421744","pt":1580642603909,"mc":[{"id":"1.168224295","rc":[{"batb":[[2,1.9,89.48]],"ltp":0.0,"tv":0.0,"id":13010435},{"batb":[[2,6.4,29.81]],"ltp":0.0,"tv":0.0,"id":17293893},{"batb":[[0,5.1,38.84],[1,5,32.47],[2,4.9,10.08]],"ltp":0.0,"tv":0.0,"id":17293892}]}]}
{"op":"mcm","clk":"1005423496","pt":1580642612066,"mc":[{"id":"1.168224295","rc":[{"batb":[[1,1.9,89.48],[2,1.89,16.92]],"batl":[[0,2.18,35.29],[1,2.26,23.92],[2,2.26,0]],"ltp":0.0,"tv":0.0,"id":13010435},{"batb":[[1,4.7,36.35]],"batl":[[1,5.6,13.85],[2,5.6,0]],"ltp":0.0,"tv":0.0,"id":13010434},{"batb":[[0,7.2,6.72],[1,6.4,29.81],[2,6.2,56]],"batl":[[1,11,7.08],[2,11,0]],"ltp":0.0,"tv":0.0,"id":17293893}]}]}
{"op":"mcm","clk":"1005423604","pt":1580642612544,"mc":[{"id":"1.168224295","rc":[{"batb":[[0,1.9,89.48],[1,1.89,16.92],[2,1.88,80.93]],"batl":[[0,2.26,23.92],[1,2.26,0]],"ltp":0.0,"tv":0.0,"id":13010435},{"batl":[[0,5.6,13.85],[1,5.6,0]],"ltp":0.0,"tv":0.0,"id":13010434},{"batb":[[0,6.4,29.81],[1,6.2,56],[2,1.01,0.51]],"batl":[[0,11,7.08],[1,11,0]],"ltp":0.0,"tv":0.0,"id":17293893},{"batb":[[2,4.8,14.48]],"batl":[[1,5.9,0]],"ltp":0.0,"tv":0.0,"id":17293892}]}]}
{"op":"mcm","clk":"1005424752","pt":1580642618788,"mc":[{"id":"1.168224295","rc":[{"batb":[[0,1.89,16.92],[1,1.01,0.51],[2,1.88,0]],"ltp":0.0,"tv":0.0,"id":13010435},{"batb":[[0,6.2,16.29],[1,1.01,0.51],[2,1.01,0]],"ltp":0.0,"tv":0.0,"id":17293893},{"batb":[[0,5.1,31.3],[1,4.8,14.48],[2,1.01,0.51]],"ltp":0.0,"tv":0.0,"id":17293892}]}]}
{"op":"mcm","clk":"1005425351","pt":1580642621928,"mc":[{"id":"1.168224295","rc":[{"batb":[[0,2,59.85],[1,1.98,68.85],[2,1.89,16.92]],"ltp":0.0,"tv":0.0,"id":13010435},{"batb":[[0,4.8,48.34]],"ltp":0.0,"tv":0.0,"id":13010434},{"batb":[[0,7.6,19.39],[1,7.4,27.24],[2,6.2,16.29]],"ltp":0.0,"tv":0.0,"id":17293893},{"batb":[[0,5.2,21.93],[1,5.1,31.3],[2,4.8,14.48]],"ltp":0.0,"tv":0.0,"id":17293892}]}]}
{"op":"mcm","clk":"1005425800","pt":1580642624268,"mc":[{"id":"1.168224295","rc":[{"batb":[[0,1.89,16.92],[1,1.01,0.51],[2,1.89,0]],"ltp":0.0,"tv":0.0,"id":13010435},{"batb":[[0,4.8,27.01]],"ltp":0.0,"tv":0.0,"id":13010434},{"batb":[[0,6.2,16.29],[1,1.01,0.51],[2,6.2,0]],"ltp":0.0,"tv":0.0,"id":17293893},{"batb":[[0,5.1,31.3],[1,4.8,14.48],[2,1.01,0.51]],"ltp":0.0,"tv":0.0,"id":17293892}]}]}
{"op":"mcm","clk":"1005426621","pt":1580642628403,"mc":[{"id":"1.168224295","rc":[{"batb":[[0,6.4,30.56],[1,6.2,56],[2,1.01,0.51]],"ltp":0.0,"tv":0.0,"id":17293893},{"batb":[[0,5.1,39.84],[1,5,32.47],[2,4.8,14.48]],"ltp":0.0,"tv":0.0,"id":17293892}]}]}
{"op":"mcm","clk":"1005426955","pt":1580642630244,"mc":[{"id":"1.168224295","rc":[{"batb":[[0,2.1,100.21],[1,2.08,59.3],[2,1.89,16.92]],"ltp":0.0,"tv":0.0,"id":13010435}]}]}
{"op":"mcm","clk":"1005427088","pt":1580642630996,"mc":[{"id":"1.168224295","rc":[{"batb":[[0,2.1,124.76],[2,1.99,28.64]],"batl":[[1,2.5,18.02]],"ltp":0.0,"tv":0.0,"id":13010435},{"batl":[[0,5.4,14.95],[1,5.5,14.63]],"ltp":0.0,"tv":0.0,"id":13010434},{"batb":[[2,4.9,13.77]],"batl":[[0,7.6,15.26],[1,9,10.78]],"ltp":0.0,"tv":0.0,"id":17293893},{"batl":[[0,5.6,13.77]],"ltp":0.0,"tv":0.0,"id":17293892}]}]}
{"op":"mcm","clk":"1005427217","pt":1580642631581,"mc":[{"id":"1.168224295","rc":[{"batb":[[1,2.08,97.95]],"batl":[[1,2.32,31.09],[2,2.5,18.02]],"ltp":0.0,"tv":0.0,"id":13010435},{"batl":[[0,5.3,9.24],[1,5.4,14.95],[2,5.5,14.63]],"ltp":0.0,"tv":0.0,"id":13010434},{"batb":[[2,6,8.4]],"batl":[[0,7.6,21.15]],"ltp":0.0,"tv":0.0,"id":17293893},{"batb":[[2,4.8,25.4]],"batl":[[1,5.8,8.4]],"ltp":0.0,"tv":0.0,"id":17293892}]}]}
{"op":"mcm","clk":"1005429244","pt":1580642642373,"mc":[{"id":"1.168224295","rc":[{"batb":[[0,2.08,38.65],[1,1.99,28.64],[2,1.01,0.51]],"batl":[[0,2.32,31.09],[1,2.5,18.02],[2,2.5,0]],"ltp":0.0,"tv":0.0,"id":13010435},{"batb":[[0,4.7,36.35],[1,4.6,15.66],[2,4.4,11.76]],"batl":[[1,5.5,14.63],[2,5.5,0]],"ltp":0.0,"tv":0.0,"id":13010434},{"batb":[[0,6,8.4],[1,4.9,13.77],[2,1.01,0.51]],"batl":[[0,7.6,5.88]],"ltp":0.0,"tv":0.0,"id":17293893},{"batb":[[0,5.1,31.3]],"ltp":0.0,"tv":0.0,"id":17293892}]}]}
{"op":"mcm","clk":"1005429293","pt":1580642642599,"mc":[{"id":"1.168224295","rc":[{"batb":[[0,1.99,28.64],[1,1.01,0.51],[2,1.01,0]],"batl":[[0,2.5,18.02],[1,2.5,0]],"ltp":0.0,"tv":0.0,"id":13010435},{"batb":[[2,1.01,0.51]],"batl":[[0,5.5,14.63],[1,5.5,0]],"ltp":0.0,"tv":0.0,"id":13010434},{"batb":[[0,4.9,13.77],[1,1.01,0.51],[2,1.01,0]],"batl":[[0,9,10.78],[1,9,0]],"ltp":0.0,"tv":0.0,"id":17293893},{"batb":[[2,4.8,14.48]],"batl":[[1,5.8,0]],"ltp":0.0,"tv":0.0,"id":17293892}]}]}
{"op":"mcm","clk":"1005429816","pt":1580642645280,"mc":[{"id":"1.168224295","rc":[{"batb":[[0,2,97.02],[1,1.99,28.64],[2,1.98,68.83]],"ltp":0.0,"tv":0.0,"id":13010435},{"batb":[[1,4.6,54.27]],"ltp":0.0,"tv":0.0,"id":13010434},{"batb":[[0,5.1,21.87],[1,5,32.75],[2,4.9,13.77]],"ltp":0.0,"tv":0.0,"id":17293893}]}]}
{"op":"mcm","clk":"1005431093","pt":1580642651965,"mc":[{"id":"1.168224295","rc":[{"batb":[[0,1.99,28.64],[1,1.01,0.51],[2,1.98,0]],"ltp":0.0,"tv":0.0,"id":13010435}]}]}
{"op":"mcm","clk":"1005431792","pt":1580642655329,"mc":[{"id":"1.168224295","rc":[{"batb":[[0,2.34,56.14],[1,2.32,18.49],[2,2.3,88.08]],"batl":[[1,2.88,12.59]],"ltp":0.0,"tv":0.0,"id":13010435},{"batb":[[1,4.6,38.61],[2,4.5,17.23]],"batl":[[0,5.3,15.5],[1,5.4,15.03]],"ltp":0.0,"tv":0.0,"id":13010434},{"batl":[[0,5.7,13.22],[1,6.8,18.57]],"ltp":0.0,"tv":0.0,"id":17293893},{"batl":[[0,5.7,13.61]],"ltp":0.0,"tv":0.0,"id":17293892}]}]}
{"op":"mcm","clk":"1005431858","pt":1580642655605,"mc":[{"id":"1.168224295","rc":[{"batl":[[1,2.54,26.89],[2,2.88,12.59]],"ltp":0.0,"tv":0.0,"id":13010435},{"batl":[[0,5.2,9.24],[1,5.3,15.5],[2,5.4,15.03]],"ltp":0.0,"tv":0.0,"id":13010434},{"batb":[[1,5,42.83]],"batl":[[1,6.2,7.56],[2,6.8,18.57]],"ltp":0.0,"tv":0.0,"id":17293893},{"batb":[[2,4.8,25.4]],"batl":[[0,5.7,22.01]],"ltp":0.0,"tv":0.0,"id":17293892}]}]}
{"op":"mcm","clk":"1005433488","pt":1580642663345,"mc":[{"id":"1.168224295","rc":[{"batb":[[0,2.32,18.49],[1,2.26,32.77],[2,2.16,22.42]],"ltp":0.0,"tv":0.0,"id":13010435},{"batb":[[0,4.6,38.61],[1,4.5,17.23],[2,4.3,12.6]],"ltp":0.0,"tv":0.0,"id":13010434},{"batb":[[0,5,10.08],[1,4.9,13.77],[2,3.9,23.68]],"ltp":0.0,"tv":0.0,"id":17293893},{"batb":[[0,5.1,27.03]],"ltp":0.0,"tv":0.0,"id":17293892}]}]}
{"op":"mcm","clk":"1005433533","pt":1580642663558,"mc":[{"id":"1.168224295","rc":[{"batb":[[0,2.26,32.77],[1,2.16,22.42],[2,1.01,0.51]],"batl":[[0,2.54,26.89],[1,2.88,12.59],[2,2.88,0]],"ltp":0.0,"tv":0.0,"id":13010435},{"batl":[[1,5.4,15.03],[2,5.4,0]],"ltp":0.0,"tv":0.0,"id":13010434},{"batb":[[1,3.9,23.68],[2,1.01,0.51]],"batl":[[0,6.2,7.56],[1,6.8,18.57],[2,6.8,0]],"ltp":0.0,"tv":0.0,"id":17293893}]}]}
{"op":"mcm","clk":"1005433741","pt":1580642664542,"mc":[{"id":"1.168224295","rc":[{"batb":[[0,2.16,22.42],[1,1.01,0.51],[2,1.01,0]],"batl":[[0,2.88,12.59],[1,2.88,0]],"ltp":0.0,"tv":0.0,"id":13010435},{"batb":[[2,1.01,0.51]],"batl":[[0,5.4,15.03],[1,5.4,0]],"ltp":0.0,"tv":0.0,"id":13010434},{"batb":[[0,3.9,23.68],[1,1.01,0.51],[2,1.01,0]],"batl":[[0,6.8,18.57],[1,6.8,0]],"ltp":0.0,"tv":0.0,"id":17293893},{"batb":[[2,4.8,14.48]],"batl":[[0,5.7,13.61]],"ltp":0.0,"tv":0.0,"id":17293892}]}]}
{"op":"mcm","clk":"1005434085","pt":1580642666225,"mc":[{"id":"1.168224295","rc":[{"batb":[[0,2.18,88.39],[1,2.16,75.51],[2,1.01,0.51]],"ltp":0.0,"tv":0.0,"id":13010435},{"batb":[[1,4.5,57.81]],"ltp":0.0,"tv":0.0,"id":13010434},{"batb":[[0,4,73.22],[1,3.95,28.01],[2,3.9,23.68]],"ltp":0.0,"tv":0.0,"id":17293893}]}]}
{"op":"mcm","clk":"1005434251","pt":1580642667026,"mc":[{"id":"1.168224295","rc":[{"batb":[[1,4.5,17.23]],"ltp":0.0,"tv":0.0,"id":13010434},{"batb":[[0,3.9,23.68],[1,1.01,0.51],[2,3.9,0]],"ltp":0.0,"tv":0.0,"id":17293893}]}]}
{"op":"mcm","clk":"1005434849","pt":1580642670164,"mc":[{"id":"1.168224295","rc":[{"batb":[[0,4.7,50.05],[1,4.6,38.61],[2,4.5,17.23]],"ltp":0.0,"tv":0.0,"id":13010434},{"batb":[[0,5.9,21.97],[1,5.8,23.5],[2,3.9,23.68]],"ltp":0.0,"tv":0.0,"id":17293893}]}]}
{"op":"mcm","clk":"1005434939","pt":1580642670646,"mc":[{"id":"1.168224295","rc":[{"batb":[[2,2.02,26.91]],"batl":[[0,2.32,21.87],[1,2.7,14.79]],"ltp":0.0,"tv":0.0,"id":13010435},{"batb":[[1,4.6,54.35]],"batl":[[1,5.5,14.79]],"ltp":0.0,"tv":0.0,"id":13010434},{"batb":[[2,5.7,19.91]],"batl":[[1,8.4,12.27]],"ltp":0.0,"tv":0.0,"id":17293893},{"batl":[[0,5.6,13.77]],"ltp":0.0,"tv":0.0,"id":17293892}]}]}
{"op":"mcm","clk":"1005435214","pt":1580642672255,"mc":[{"id":"1.168224295","rc":[{"batb":[[1,2.16,111.64]],"batl":[[1,2.42,29.41],[2,2.7,14.79]],"ltp":0.0,"tv":0.0,"id":13010435},{"batl":[[0,5.3,9.24],[1,5.4,15.03],[2,5.5,14.79]],"ltp":0.0,"tv":0.0,"id":13010434},{"batl":[[1,7,6.72],[2,8.4,12.27]],"ltp":0.0,"tv":0.0,"id":17293893},{"batb":[[2,4.8,25.4]],"batl":[[1,5.8,8.4]],"ltp":0.0,"tv":0.0,"id":17293892}]}]}
{"op":"mcm","clk":"1005436857","pt":1580642680722,"mc":[{"id":"1.168224295","rc":[{"batb":[[0,2.02,26.91],[1,1.01,0.51],[2,2.02,0]],"batl":[[0,2.7,14.79],[1,2.42,0],[2,2.7,0]],"ltp":0.0,"tv":0.0,"id":13010435},{"batb":[[0,4.6,38.61],[1,4.5,17.23],[2,1.01,0.51]],"batl":[[0,5.5,14.79],[1,5.4,0],[2,5.5,0]],"ltp":0.0,"tv":0.0,"id":13010434},{"batb":[[0,4.3,18.41],[1,1.01,0.51],[2,5.7,0]],"batl":[[0,8.4,12.27],[1,7,0],[2,8.4,0]],"ltp":0.0,"tv":0.0,"id":17293893},{"batb":[[2,4.8,14.48]],"batl":[[1,5.8,0]],"ltp":0.0,"tv":0.0,"id":17293892}]}]}
{"op":"mcm","clk":"1005437417","pt":1580642683727,"mc":[{"id":"1.168224295","rc":[{"batb":[[0,2.04,95.29],[1,2.02,91.67],[2,1.01,0.51]],"ltp":0.0,"tv":0.0,"id":13010435},{"batb":[[1,4.5,57.57]],"ltp":0.0,"tv":0.0,"id":13010434},{"batb":[[0,4.5,22.79],[1,4.4,43.76],[2,4.3,18.41]],"ltp":0.0,"tv":0.0,"id":17293893}]}]}
{"op":"mcm","clk":"1005438511","pt":1580642690035,"mc":[{"id":"1.168224295","rc":[{"batb":[[0,2.02,26.91],[1,1.01,0.51],[2,1.01,0]],"ltp":0.0,"tv":0.0,"id":13010435},{"batb":[[1,4.5,17.23]],"ltp":0.0,"tv":0.0,"id":13010434},{"batb":[[0,4.3,18.41],[1,1.01,0.51],[2,4.3,0]],"ltp":0.0,"tv":0.0,"id":17293893}]}]}
{"op":"mcm","clk":"1005439091","pt":1580642693199,"mc":[{"id":"1.168224295","rc":[{"batb":[[0,2.24,77.51],[1,2.22,49.08],[2,2.02,26.91]],"ltp":0.0,"tv":0.0,"id":13010435},{"batb":[[0,4.7,41.46],[1,4.6,38.61],[2,4.5,17.23]],"ltp":0.0,"tv":0.0,"id":13010434},{"batb":[[0,5.5,36.89],[1,5.4,27.33],[2,4.3,18.41]],"ltp":0.0,"tv":0.0,"id":17293893}]}]}
{"op":"mcm","clk":"1005439451","pt":1580642695115,"mc":[{"id":"1.168224295","rc":[{"batb":[[0,2.02,26.91],[1,1.01,0.51],[2,2.02,0]],"ltp":0.0,"tv":0.0,"id":13010435},{"batb":[[0,4.6,38.61],[1,4.5,17.23],[2,1.01,0.51]],"ltp":0.0,"tv":0.0,"id":13010434},{"batb":[[0,4.3,18.41],[1,1.01,0.51],[2,4.3,0]],"ltp":0.0,"tv":0.0,"id":17293893}]}]}
{"op":"mcm","clk":"1005439989","pt":1580642698135,"mc":[{"id":"1.168224295","rc":[{"batb":[[0,2.04,95.29],[1,2.02,91.67],[2,1.01,0.51]],"ltp":0.0,"tv":0.0,"id":13010435},{"batb":[[1,4.5,57.57]],"ltp":0.0,"tv":0.0,"id":13010434},{"batb":[[0,4.5,22.79],[1,4.4,43.76],[2,4.3,18.41]],"ltp":0.0,"tv":0.0,"id":17293893}]}]}
{"op":"mcm","clk":"1005440606","pt":1580642701343,"mc":[{"id":"1.168224295","rc":[{"batb":[[0,4.5,17.23],[1,1.01,0.51],[2,1.01,0]],"ltp":0.0,"tv":0.0,"id":13010434},{"batb":[[0,4.3,18.41],[1,1.01,0.51],[2,4.3,0]],"ltp":0.0,"tv":0.0,"id":17293893}]}]}
{"op":"mcm","clk":"1005441159","pt":1580642704355,"mc":[{"id":"1.168224295","rc":[{"batb":[[2,1.92,15.89]],"batl":[[0,2.18,26.12],[1,2.48,18.57]],"ltp":0.0,"tv":0.0,"id":13010435},{"batb":[[0,4.8,36.02],[1,4.7,36.64],[2,4.6,16.37]],"batl":[[0,5.5,14.24]],"ltp":0.0,"tv":0.0,"id":13010434},{"batb":[[0,7,37.74],[1,6.8,45.23],[2,5,12.98]],"batl":[[1,10.5,7.79]],"ltp":0.0,"tv":0.0,"id":17293893},{"batb":[[0,5.1,34.12]],"ltp":0.0,"tv":0.0,"id":17293892}]}]}
{"op":"mcm","clk":"1005441383","pt":1580642705535,"mc":[{"id":"1.168224295","rc":[{"batb":[[0,2.04,135.62]],"batl":[[1,2.28,32.77],[2,2.48,18.57]],"ltp":0.0,"tv":0.0,"id":13010435},{"batl":[[0,5.3,9.24],[1,5.5,14.24]],"ltp":0.0,"tv":0.0,"id":13010434},{"batb":[[2,6.6,6.72]],"batl":[[0,8.4,17.32]],"ltp":0.0,"tv":0.0,"id":17293893},{"batb":[[2,4.8,25.4]],"batl":[[1,5.8,8.4]],"ltp":0.0,"tv":0.0,"id":17293892}]}]}
{"op":"mcm","clk":"1005443898","pt":1580642719164,"mc":[{"id":"1.168224295","rc":[{"batb":[[0,2.04,40.33],[1,1.92,15.89],[2,1.01,0.51]],"batl":[[0,2.28,32.77],[1,2.48,18.57],[2,2.48,0]],"ltp":0.0,"tv":0.0,"id":13010435},{"batb":[[0,4.7,36.64],[1,4.6,16.37],[2,4.4,11.76]],"ltp":0.0,"tv":0.0,"id":13010434},{"batb":[[0,6.6,6.72],[1,5,12.98],[2,1.01,0.51]],"batl":[[0,8.4,5.04]],"ltp":0.0,"tv":0.0,"id":17293893},{"batb":[[0,5.1,27.03]],"ltp":0.0,"tv":0.0,"id":17293892}]}]}
{"op":"mcm","clk":"1005444112","pt":1580642720558,"mc":[{"id":"1.168224295","rc":[{"batb":[[0,1.92,15.89],[1,1.01,0.51],[2,1.01,0]],"batl":[[0,2.48,18.57],[1,2.48,0]],"ltp":0.0,"tv":0.0,"id":13010435},{"batb":[[2,1.01,0.51]],"batl":[[0,5.5,14.24],[1,5.5,0]],"ltp":0.0,"tv":0.0,"id":13010434},{"batb":[[0,5,12.98],[1,1.01,0.51],[2,1.01,0]],"batl":[[0,10.5,7.79],[1,10.5,0]],"ltp":0.0,"tv":0.0,"id":17293893},{"batb":[[2,4.8,14.48]],"batl":[[1,5.8,0]],"ltp":0.0,"tv":0.0,"id":17293892}]}]}
{"op":"mcm","clk":"1005444421","pt":1580642722165,"mc":[{"id":"1.168224295","rc":[{"batb":[[0,1.93,80.44],[1,1.92,15.89],[2,1.91,76.98]],"ltp":0.0,"tv":0.0,"id":13010435},{"batb":[[1,4.6,54.96]],"ltp":0.0,"tv":0.0,"id":13010434},{"batb":[[0,5.2,35.21],[1,5.1,31.1],[2,5,12.98]],"ltp":0.0,"tv":0.0,"id":17293893}]}]}
{"op":"mcm","clk":"1005444752","pt":1580642724153,"mc":[{"id":"1.168224295","rc":[{"batb":[[0,1.92,15.89],[1,1.01,0.51],[2,1.91,0]],"ltp":0.0,"tv":0.0,"id":13010435},{"batb":[[1,4.6,16.37]],"ltp":0.0,"tv":0.0,"id":13010434},{"batb":[[0,5,12.98],[1,1.01,0.51],[2,5,0]],"ltp":0.0,"tv":0.0,"id":17293893}]}]}
{"op":"mcm","clk":"1005445281","pt":1580642727003,"mc":[{"id":"1.168224295","rc":[{"batb":[[0,2.1,55.78],[1,2.08,59.37],[2,1.92,15.89]],"ltp":0.0,"tv":0.0,"id":13010435},{"batb":[[0,4.8,27.49],[1,4.7,36.64],[2,4.6,16.37]],"ltp":0.0,"tv":0.0,"id":13010434},{"batb":[[0,6.6,26.82],[1,6.4,37.1],[2,5,12.98]],"ltp":0.0,"tv":0.0,"id":17293893}]}]}
{"op":"mcm","clk":"1005445866","pt":1580642730315,"mc":[{"id":"1.168224295","rc":[{"batb":[[0,1.92,15.89],[1,1.01,0.51],[2,1.92,0]],"ltp":0.0,"tv":0.0,"id":13010435},{"batb":[[0,4.7,36.64],[1,4.6,16.37],[2,1.01,0.51]],"ltp":0.0,"tv":0.0,"id":13010434},{"batb":[[0,5,12.98],[1,1.01,0.51],[2,5,0]],"ltp":0.0,"tv":0.0,"id":17293893}]}]}
{"op":"mcm","clk":"1005446432","pt":1580642733287,"mc":[{"id":"1.168224295","rc":[{"batb":[[0,1.93,80.44],[1,1.92,15.89],[2,1.91,76.98]],"ltp":0.0,"tv":0.0,"id":13010435},{"batb":[[1,4.6,54.96]],"ltp":0.0,"tv":0.0,"id":13010434},{"batb":[[0,5.2,35.21],[1,5.1,31.1],[2,5,12.98]],"ltp":0.0,"tv":0.0,"id":17293893}]}]}
{"op":"mcm","clk":"1005446568","pt":1580642734078,"mc":[{"id":"1.168224295","rc":[{"batb":[[0,4.6,16.37],[1,1.01,0.51],[2,1.01,0]],"ltp":0.0,"tv":0.0,"id":13010434},{"batb":[[0,5,12.98],[1,1.01,0.51],[2,5,0]],"ltp":0.0,"tv":0.0,"id":17293893}]}]}
{"op":"mcm","clk":"1005447130","pt":1580642737271,"mc":[{"id":"1.168224295","rc":[{"batl":[[0,2.06,15.66],[1,2.22,25.02]],"ltp":0.0,"tv":0.0,"id":13010435},{"batb":[[0,4.9,23.14],[1,4.8,35.12],[2,4.7,14.87]],"batl":[[1,5.6,14.01]],"ltp":0.0,"tv":0.0,"id":13010434},{"batb":[[0,8.8,16.84],[1,8.6,19.77],[2,8.4,8.18]],"batl":[[1,12.5,13.69]],"ltp":0.0,"tv":0.0,"id":17293893},{"batb":[[0,5.1,38.99]],"ltp":0.0,"tv":0.0,"id":17293892}]}]}
{"op":"mcm","clk":"1005447240","pt":1580642737870,"mc":[{"id":"1.168224295","rc":[{"batb":[[0,1.93,124.97]],"batl":[[1,2.14,36.13],[2,2.22,25.02]],"ltp":0.0,"tv":0.0,"id":13010435},{"batl":[[0,5.4,9.24],[1,5.5,14.24],[2,5.6,14.01]],"ltp":0.0,"tv":0.0,"id":13010434},{"batl":[[0,10,4.2],[1,10.5,7.79],[2,12.5,13.69]],"ltp":0.0,"tv":0.0,"id":17293893},{"batb":[[2,4.8,25.4]],"batl":[[1,5.8,8.4]],"ltp":0.0,"tv":0.0,"id":17293892}]}]}
{"op":"mcm","clk":"1005448951","pt":1580642747034,"mc":[{"id":"1.168224295","rc":[{"batb":[[0,1.93,44.53],[1,1.86,17.62],[2,1.01,0.51]],"batl":[[0,2.14,36.13],[1,2.22,25.02],[2,2.22,0]],"ltp":0.0,"tv":0.0,"id":13010435},{"batb":[[0,4.8,35.12],[1,4.6,15.66],[2,4.5,11.76]],"batl":[[1,5.6,14.01],[2,5.6,0]],"ltp":0.0,"tv":0.0,"id":13010434},{"batb":[[0,7.8,5.88],[1,6.6,14.08],[2,1.01,0.51]],"batl":[[1,12.5,13.69],[2,12.5,0]],"ltp":0.0,"tv":0.0,"id":17293893},{"batb":[[0,5.1,27.03]],"ltp":0.0,"tv":0.0,"id":17293892}]}]}
{"op":"mcm","clk":"1005449255","pt":1580642748630,"mc":[{"id":"1.168224295","rc":[{"batb":[[0,1.86,17.62],[1,1.01,0.51],[2,1.01,0]],"batl":[[0,2.22,25.02],[1,2.22,0]],"ltp":0.0,"tv":0.0,"id":13010435},{"batb":[[2,1.01,0.51]],"batl":[[0,5.6,14.01],[1,5.6,0]],"ltp":0.0,"tv":0.0,"id":13010434},{"batb":[[0,6.6,14.08],[1,1.01,0.51],[2,1.01,0]],"batl":[[0,12.5,13.69],[1,12.5,0]],"ltp":0.0,"tv":0.0,"id":17293893},{"batb":[[2,4.8,14.48]],"batl":[[1,5.8,0]],"ltp":0.0,"tv":0.0,"id":17293892}]}]}
{"op":"mcm","clk":"1005449505","pt":1580642749795,"mc":[{"id":"1.168224295","rc":[{"batb":[[0,1.86,112.98],[1,1.84,86.72],[2,1.01,0.51]],"ltp":0.0,"tv":0.0,"id":13010435},{"batb":[[1,4.7,36.7],[2,4.6,15.66]],"ltp":0.0,"tv":0.0,"id":13010434},{"batb":[[0,6.8,37.61],[1,6.6,48.49],[2,1.01,0.51]],"ltp":0.0,"tv":0.0,"id":17293893}]}]}
{"op":"mcm","clk":"1005450459","pt":1580642755217,"mc":[{"id":"1.168224295","rc":[{"batb":[[1,4.6,15.66],[2,1.01,0.51]],"ltp":0.0,"tv":0.0,"id":13010434},{"batb":[[0,6.6,14.08],[1,1.01,0.51],[2,1.01,0]],"ltp":0.0,"tv":0.0,"id":17293893}]}]}
{"op":"mcm","clk":"1005451053","pt":1580642758033,"mc":[{"id":"1.168224295","rc":[{"batb":[[0,4.9,37.11],[1,4.8,35.12],[2,4.6,15.66]],"ltp":0.0,"tv":0.0,"id":13010434},{"batb":[[0,10,36.49],[1,9.8,14.61],[2,6.6,14.08]],"ltp":0.0,"tv":0.0,"id":17293893},{"batb":[[0,5.1,48.32]],"ltp":0.0,"tv":0.0,"id":17293892}]}]}
{"op":"mcm","clk":"1005451195","pt":1580642758724,"mc":[{"id":"1.168224295","rc":[{"batb":[[2,1.78,20.22]],"batl":[[0,1.98,17.39],[1,2.02,16.21]],"ltp":0.0,"tv":0.0,"id":13010435},{"batb":[[1,4.8,49.75],[2,4.7,15.03]],"batl":[[1,5.7,13.53]],"ltp":0.0,"tv":0.0,"id":13010434},{"batb":[[2,9.6,15.03]],"batl":[[1,15.5,9.28]],"ltp":0.0,"tv":0.0,"id":17293893},{"batl":[[0,5.7,13.3]],"ltp":0.0,"tv":0.0,"id":17293892}]}]}
{"op":"mcm","clk":"1005451447","pt":1580642760021,"mc":[{"id":"1.168224295","rc":[{"batb":[[1,1.84,136.29]],"batl":[[2,2.04,40.33]],"ltp":0.0,"tv":0.0,"id":13010435},{"batl":[[0,5.5,9.24],[1,5.6,14.01],[2,5.7,13.53]],"ltp":0.0,"tv":0.0,"id":13010434},{"batl":[[0,12,3.36],[1,12.5,13.69],[2,15.5,9.28]],"ltp":0.0,"tv":0.0,"id":17293893},{"batb":[[2,4.9,10.08]],"batl":[[1,5.9,8.4]],"ltp":0.0,"tv":0.0,"id":17293892}]}]}
{"op":"mcm","clk":"1005454974","pt":1580642778902,"mc":[{"id":"1.168224295","rc":[{"batb":[[0,1.78,20.22],[1,1.01,0.51],[2,1.78,0]],"batl":[[0,2.02,16.21],[1,2.02,0],[2,2.04,0]],"ltp":0.0,"tv":0.0,"id":13010435},{"batb":[[0,4.9,22.18],[1,4.8,35.12]],"batl":[[0,5.7,13.53],[1,5.6,0],[2,5.7,0]],"ltp":0.0,"tv":0.0,"id":13010434},{"batb":[[0,8.8,7.08],[1,1.01,0.51],[2,9.6,0]],"batl":[[0,15.5,9.28],[1,12.5,0],[2,15.5,0]],"ltp":0.0,"tv":0.0,"id":17293893},{"batb":[[0,5.1,29.13],[2,4.8,14.48]],"batl":[[1,5.9,0]],"ltp":0.0,"tv":0.0,"id":17293892}]}]}
{"op":"mcm","clk":"1005455408","pt":1580642781364,"mc":[{"id":"1.168224295","rc":[{"batb":[[0,1.79,78.71],[1,1.78,20.22],[2,1.77,98.61]],"ltp":0.0,"tv":0.0,"id":13010435},{"batb":[[0,9.2,27.68],[1,9,17.72],[2,8.8,7.08]],"ltp":0.0,"tv":0.0,"id":17293893}]}]}
{"op":"mcm","clk":"1005459147","pt":1580642800150,"mc":[{"id":"1.168224295","rc":[{"batb":[[0,1.78,20.22],[1,1.01,0.51],[2,1.77,0]],"ltp":0.0,"tv":0.0,"id":13010435}]}]}
{"op":"mcm","clk":"1005459733","pt":1580642803353,"mc":[{"id":"1.168224295","rc":[{"batb":[[0,1.91,87.16],[1,1.89,79.51],[2,1.78,20.22]],"ltp":0.0,"tv":0.0,"id":13010435}]}]}
{"op":"mcm","clk":"1005459853","pt":1580642803944,"mc":[{"id":"1.168224295","rc":[{"batb":[[1,1.9,16.44],[2,1.89,79.51]],"batl":[[1,2.08,68.39]],"ltp":0.0,"tv":0.0,"id":13010435},{"batl":[[0,5.5,9.24],[1,5.6,13.85]],"ltp":0.0,"tv":0.0,"id":13010434},{"batl":[[0,11,4.2],[1,11.5,17],[2,13.5,12.51]],"ltp":0.0,"tv":0.0,"id":17293893},{"batb":[[2,4.8,25.4]],"batl":[[0,5.6,14.01],[1,5.7,13.3],[2,5.8,8.4]],"ltp":0.0,"tv":0.0,"id":17293892}]}]}
{"op":"mcm","clk":"1005461245","pt":1580642810350,"mc":[{"id":"1.168224295","rc":[{"batb":[[0,1.88,47.05],[1,1.84,18.41],[2,1.01,0.51]],"batl":[[0,2.08,68.39],[1,2.08,0]],"ltp":0.0,"tv":0.0,"id":13010435},{"batb":[[0,4.8,35.12],[1,4.7,15.03],[2,4.5,11.76]],"ltp":0.0,"tv":0.0,"id":13010434},{"batb":[[0,8.4,5.04],[1,8.2,8.58],[2,1.01,0.51]],"batl":[[1,13.5,12.51],[2,13.5,0]],"ltp":0.0,"tv":0.0,"id":17293893},{"batb":[[0,5,32.47],[1,4.8,10.92],[2,4.7,15.11]],"batl":[[0,5.7,13.3],[1,5.8,8.4],[2,5.8,0]],"ltp":0.0,"tv":0.0,"id":17293892}]}]}
{"op":"mcm","clk":"1005461352","pt":1580642810850,"mc":[{"id":"1.168224295","rc":[{"batb":[[0,1.84,18.41],[1,1.01,0.51],[2,1.01,0]],"batl":[[0,2.08,29.74]],"ltp":0.0,"tv":0.0,"id":13010435},{"batb":[[2,1.01,0.51]],"batl":[[0,5.6,13.85],[1,5.6,0]],"ltp":0.0,"tv":0.0,"id":13010434},{"batb":[[0,8.2,8.58],[1,1.01,0.51],[2,1.01,0]],"batl":[[0,13.5,12.51],[1,13.5,0]],"ltp":0.0,"tv":0.0,"id":17293893},{"batb":[[1,4.7,15.11],[2,1.01,0.51]],"batl":[[1,5.8,0]],"ltp":0.0,"tv":0.0,"id":17293892}]}]}
{"op":"mcm","clk":"1005461785","pt":1580642812942,"mc":[{"id":"1.168224295","rc":[{"batb":[[0,1.85,54.81],[1,1.84,18.41],[2,1.83,88.23]],"ltp":0.0,"tv":0.0,"id":13010435},{"batb":[[0,4.8,45.29],[1,4.7,51.46]],"ltp":0.0,"tv":0.0,"id":13010434},{"batb":[[0,8.6,24],[1,8.4,20.63],[2,8.2,8.58]],"ltp":0.0,"tv":0.0,"id":17293893},{"batb":[[0,5,43.71],[1,4.9,33.88],[2,4.7,15.11]],"ltp":0.0,"tv":0.0,"id":17293892}]}]}
{"op":"mcm","clk":"1005462275","pt":1580642815258,"mc":[{"id":"1.168224295","rc":[{"batb":[[0,4.8,35.12],[1,4.7,15.03]],"ltp":0.0,"tv":0.0,"id":13010434},{"batb":[[0,8.2,8.58],[1,1.01,0.51],[2,8.2,0]],"ltp":0.0,"tv":0.0,"id":17293893},{"batb":[[0,4.7,15.11],[1,1.01,0.51],[2,4.7,0]],"ltp":0.0,"tv":0.0,"id":17293892}]}]}
{"op":"mcm","clk":"1005462881","pt":1580642818364,"mc":[{"id":"1.168224295","rc":[{"batb":[[0,4.9,43.26],[1,4.8,35.12],[2,4.7,15.03]],"ltp":0.0,"tv":0.0,"id":13010434},{"batb":[[0,10.5,28.28],[1,10,34.29],[2,8.2,8.58]],"ltp":0.0,"tv":0.0,"id":17293893},{"batb":[[0,5.2,28.3],[1,5.1,31.22],[2,4.7,15.11]],"ltp":0.0,"tv":0.0,"id":17293892}]}]}
{"op":"mcm","clk":"1005463037","pt":1580642819204,"mc":[{"id":"1.168224295","rc":[{"batl":[[0,1.95,18.18],[1,2,16.68]],"ltp":0.0,"tv":0.0,"id":13010435},{"batb":[[1,4.8,49.91],[2,1.01,0.51]],"batl":[[0,5.7,13.38]],"ltp":0.0,"tv":0.0,"id":13010434},{"batb":[[1,10,47.98],[2,8.8,7.08]],"batl":[[1,17,7.79]],"ltp":0.0,"tv":0.0,"id":17293893},{"batb":[[2,4.9,14.16]],"batl":[[1,5.8,12.9]],"ltp":0.0,"tv":0.0,"id":17293892}]}]}
{"op":"mcm","clk":"1005463124","pt":1580642819580,"mc":[{"id":"1.168224295","rc":[{"batl":[[2,2.02,41.17]],"ltp":0.0,"tv":0.0,"id":13010435},{"batb":[[2,4.5,11.76]],"batl":[[0,5.5,9.24],[1,5.7,13.38]],"ltp":0.0,"tv":0.0,"id":13010434},{"batb":[[2,9.2,5.04]],"batl":[[0,12.5,3.36],[1,13.5,12.51],[2,17,7.79]],"ltp":0.0,"tv":0.0,"id":17293893},{"batb":[[2,5,10.08]],"batl":[[2,6,8.4]],"ltp":0.0,"tv":0.0,"id":17293892}]}]}
{"op":"mcm","clk":"1005464536","pt":1580642826879,"mc":[{"id":"1.168224295","rc":[{"batb":[[0,1.82,50.41],[1,1.75,21.48],[2,1.01,0.51]],"batl":[[0,2,16.68],[1,2.02,41.17],[2,2.02,0]],"ltp":0.0,"tv":0.0,"id":13010435},{"batb":[[0,4.9,26.03]],"ltp":0.0,"tv":0.0,"id":13010434},{"batb":[[0,9.2,5.04],[1,8.8,7.08],[2,1.01,0.51]],"batl":[[1,17,7.79],[2,17,0]],"ltp":0.0,"tv":0.0,"id":17293893},{"batb":[[0,5.1,31.22],[1,5,10.08],[2,4.8,14.32]],"batl":[[0,5.8,12.9],[1,6,8.4],[2,6,0]],"ltp":0.0,"tv":0.0,"id":17293892}]}]}
{"op":"mcm","clk":"1005464857","pt":1580642828594,"mc":[{"id":"1.168224295","rc":[{"batb":[[0,1.75,21.48],[1,1.01,0.51],[2,1.01,0]],"batl":[[1,2.02,0]],"ltp":0.0,"tv":0.0,"id":13010435},{"batb":[[2,1.01,0.51]],"batl":[[0,5.7,13.38],[1,5.7,0]],"ltp":0.0,"tv":0.0,"id":13010434},{"batb":[[0,8.8,7.08],[1,1.01,0.51],[2,1.01,0]],"batl":[[0,17,7.79],[1,17,0]],"ltp":0.0,"tv":0.0,"id":17293893},{"batb":[[1,4.8,14.32],[2,1.01,0.51]],"batl":[[1,6,0]],"ltp":0.0,"tv":0.0,"id":17293892}]}]}
{"op":"mcm","clk":"1005465051","pt":1580642829753,"mc":[{"id":"1.168224295","rc":[{"batb":[[0,1.76,85.76],[1,1.75,21.48],[2,1.74,104.53]],"ltp":0.0,"tv":0.0,"id":13010435},{"batb":[[0,9.4,22.48],[1,9.2,17],[2,8.8,7.08]],"ltp":0.0,"tv":0.0,"id":17293893},{"batb":[[0,5.1,40.76],[1,5,32.42],[2,4.8,14.32]],"ltp":0.0,"tv":0.0,"id":17293892}]}]}
{"op":"mcm","clk":"1005465411","pt":1580642831795,"mc":[{"id":"1.168224295","rc":[{"batb":[[0,1.75,21.48],[1,1.01,0.51],[2,1.74,0]],"ltp":0.0,"tv":0.0,"id":13010435},{"batb":[[0,8.8,7.08],[1,1.01,0.51],[2,8.8,0]],"ltp":0.0,"tv":0.0,"id":17293893},{"batb":[[0,5.1,31.22],[1,4.8,14.32],[2,1.01,0.51]],"ltp":0.0,"tv":0.0,"id":17293892}]}]}
{"op":"mcm","clk":"1005465986","pt":1580642834987,"mc":[{"id":"1.168224295","rc":[{"batb":[[0,1.83,66.39],[1,1.81,91.49],[2,1.75,21.48]],"ltp":0.0,"tv":0.0,"id":13010435},{"batb":[[0,4.9,48.87]],"ltp":0.0,"tv":0.0,"id":13010434},{"batb":[[0,11,24.84],[1,10.5,31.09],[2,8.8,7.08]],"ltp":0.0,"tv":0.0,"id":17293893},{"batb":[[0,5.2,34.5],[1,5.1,31.22],[2,4.8,14.32]],"ltp":0.0,"tv":0.0,"id":17293892}]}]}
{"op":"mcm","clk":"1005466239","pt":1580642836287,"mc":[{"id":"1.168224295","rc":[{"batb":[[0,1.75,21.48],[1,1.01,0.51],[2,1.75,0]],"ltp":0.0,"tv":0.0,"id":13010435},{"batb":[[0,4.9,26.03]],"ltp":0.0,"tv":0.0,"id":13010434},{"batb":[[0,8.8,7.08],[1,1.01,0.51],[2,8.8,0]],"ltp":0.0,"tv":0.0,"id":17293893},{"batb":[[0,5.1,31.22],[1,4.8,14.32],[2,1.01,0.51]],"ltp":0.0,"tv":0.0,"id":17293892}]}]}
{"op":"mcm","clk":"1005466700","pt":1580642838783,"mc":[{"id":"1.168224295","rc":[{"batb":[[0,1.76,85.76],[1,1.75,21.48],[2,1.74,104.53]],"ltp":0.0,"tv":0.0,"id":13010435},{"batb":[[0,9.4,22.48],[1,9.2,17],[2,8.8,7.08]],"ltp":0.0,"tv":0.0,"id":17293893},{"batb":[[0,5.1,40.76],[1,5,32.42],[2,4.8,14.32]],"ltp":0.0,"tv":0.0,"id":17293892}]}]}
{"op":"mcm","clk":"1005467281","pt":1580642842312,"mc":[{"id":"1.168224295","rc":[{"batb":[[1,4.8,14.79]],"ltp":0.0,"tv":0.0,"id":13010434},{"batb":[[0,8.8,7.08],[1,1.01,0.51],[2,8.8,0]],"ltp":0.0,"tv":0.0,"id":17293893},{"batb":[[0,4.8,14.32],[1,1.01,0.51],[2,4.8,0]],"ltp":0.0,"tv":0.0,"id":17293892}]}]}
{"op":"mcm","clk":"1005467819","pt":1580642845171,"mc":[{"id":"1.168224295","rc":[{"batb":[[0,1.75,21.48],[1,1.01,0.51],[2,1.74,0]],"ltp":0.0,"tv":0.0,"id":13010435},{"batb":[[0,5,37.31],[1,4.9,33.35],[2,4.8,14.79]],"ltp":0.0,"tv":0.0,"id":13010434},{"batb":[[0,13.5,15.1],[1,13,20.21],[2,8.8,7.08]],"ltp":0.0,"tv":0.0,"id":17293893},{"batb":[[0,5.3,28.7],[1,5.2,29.93],[2,4.8,14.32]],"ltp":0.0,"tv":0.0,"id":17293892}]}]}
{"op":"mcm","clk":"1005468028","pt":1580642846200,"mc":[{"id":"1.168224295","rc":[{"batb":[[0,1.76,54.61],[1,1.75,21.48],[2,1.66,25.97]],"batl":[[0,1.86,21.09],[1,1.93,60.74]],"ltp":0.0,"tv":0.0,"id":13010435},{"batb":[[1,4.9,47.28],[2,4.8,14.48]],"batl":[[0,5.5,9.24],[1,5.7,13.38],[2,5.9,12.51]],"ltp":0.0,"tv":0.0,"id":13010434},{"batb":[[2,12,8.34]],"batl":[[1,28,6.69]],"ltp":0.0,"tv":0.0,"id":17293893},{"batb":[[2,5,23.54]],"batl":[[1,5.9,12.27],[2,6.2,7.56]],"ltp":0.0,"tv":0.0,"id":17293892}]}]}
{"op":"mcm","clk":"1005468379","pt":1580642847918,"mc":[{"id":"1.168224295","rc":[{"batb":[[1,1.75,127.26],[2,1.73,106.74]],"ltp":0.0,"tv":0.0,"id":13010435},{"batb":[[0,13.5,21.13]],"ltp":0.0,"tv":0.0,"id":17293893},{"batb":[[0,5.3,46.06]],"ltp":0.0,"tv":0.0,"id":17293892}]}]}
{"op":"mcm","clk":"1005469543","pt":1580642853930,"mc":[{"id":"1.168224295","rc":[{"batb":[[1,1.66,25.97],[2,1.01,0.51]],"batl":[[0,1.93,60.74],[1,1.93,0]],"ltp":0.0,"tv":0.0,"id":13010435},{"batb":[[0,4.9,33.35],[1,4.8,14.48],[2,4.5,11.76]],"batl":[[1,5.9,12.51],[2,5.9,0]],"ltp":0.0,"tv":0.0,"id":13010434},{"batb":[[0,11.5,3.36],[1,10,12.59],[2,1.01,0.51]],"batl":[[0,28,6.69],[1,28,0]],"ltp":0.0,"tv":0.0,"id":17293893},{"batb":[[0,5.3,28.7],[2,5,10.08]],"batl":[[0,5.9,12.27],[1,6.2,7.56],[2,6.2,0]],"ltp":0.0,"tv":0.0,"id":17293892}]}]}
{"op":"mcm","clk":"1005469729","pt":1580642854591,"mc":[{"id":"1.168224295","rc":[{"batb":[[0,1.66,25.97],[1,1.01,0.51],[2,1.01,0]],"batl":[[0,1.93,18.73]],"ltp":0.0,"tv":0.0,"id":13010435},{"batb":[[2,1.01,0.51]],"batl":[[0,5.9,12.51],[1,5.9,0]],"ltp":0.0,"tv":0.0,"id":13010434},{"batb":[[0,10,12.59],[1,1.01,0.51],[2,1.01,0]],"ltp":0.0,"tv":0.0,"id":17293893},{"batb":[[2,4.9,13.77]],"batl":[[1,6.2,0]],"ltp":0.0,"tv":0.0,"id":17293892}]}]}
{"op":"mcm","clk":"1005470167","pt":1580642856900,"mc":[{"id":"1.168224295","rc":[{"batb":[[0,1.66,118.76],[1,1.65,63.5],[2,1.01,0.51]],"ltp":0.0,"tv":0.0,"id":13010435},{"batb":[[0,4.9,42.35],[1,4.8,49.2]],"ltp":0.0,"tv":0.0,"id":13010434},{"batb":[[0,11,30.05],[1,10.5,31.19],[2,10,12.59]],"ltp":0.0,"tv":0.0,"id":17293893}]}]}
{"op":"mcm","clk":"1005470422","pt":1580642858291,"mc":[{"id":"1.168224295","rc":[{"batb":[[0,1.66,25.97],[1,1.01,0.51],[2,1.01,0]],"ltp":0.0,"tv":0.0,"id":13010435},{"batb":[[0,4.9,33.35],[1,4.8,14.48]],"ltp":0.0,"tv":0.0,"id":13010434},{"batb":[[0,10,12.59],[1,1.01,0.51],[2,10,0]],"ltp":0.0,"tv":0.0,"id":17293893},{"batb":[[1,4.9,13.77],[2,1.01,0.51]],"ltp":0.0,"tv":0.0,"id":17293892}]}]}
{"op":"mcm","clk":"1005471083","pt":1580642862212,"mc":[{"id":"1.168224295","rc":[{"batb":[[0,1.73,110.13],[1,1.71,111.17],[2,1.66,25.97]],"ltp":0.0,"tv":0.0,"id":13010435},{"batb":[[0,5,38.42],[1,4.9,33.35],[2,4.8,14.48]],"ltp":0.0,"tv":0.0,"id":13010434},{"batb":[[0,14.5,19.89],[1,14,17.36],[2,10,12.59]],"ltp":0.0,"tv":0.0,"id":17293893},{"batb":[[0,5.4,23.16],[1,5.3,28.7],[2,4.9,13.77]],"ltp":0.0,"tv":0.0,"id":17293892}]}]}
{"op":"mcm","clk":"1005471160","pt":1580642862623,"mc":[{"id":"1.168224295","rc":[{"batb":[[0,1.66,25.97],[1,1.01,0.51],[2,1.66,0]],"ltp":0.0,"tv":0.0,"id":13010435},{"batb":[[0,4.9,33.35],[1,4.8,14.48],[2,1.01,0.51]],"ltp":0.0,"tv":0.0,"id":13010434},{"batb":[[0,10,12.59],[1,1.01,0.51],[2,10,0]],"ltp":0.0,"tv":0.0,"id":17293893},{"batb":[[0,5.3,28.7],[1,4.9,13.77],[2,1.01,0.51]],"ltp":0.0,"tv":0.0,"id":17293892}]}]}
{"op":"mcm","clk":"1005471460","pt":1580642864318,"mc":[{"id":"1.168224295","rc":[{"batb":[[0,4.8,14.48],[1,1.01,0.51],[2,1.01,0]],"ltp":0.0,"tv":0.0,"id":13010434},{"batb":[[0,4.9,13.77],[1,1.01,0.51],[2,1.01,0]],"ltp":0.0,"tv":0.0,"id":17293892}]}]}
{"op":"mcm","clk":"1005471667","pt":1580642865390,"mc":[{"id":"1.168224295","rc":[{"batb":[[0,1.66,118.76],[1,1.65,63.5],[2,1.01,0.51]],"ltp":0.0,"tv":0.0,"id":13010435}]}]}
{"op":"mcm","clk":"1005472051","pt":1580642867405,"mc":[{"id":"1.168224295","rc":[{"batb":[[0,5.1,34.81],[1,5,31.86],[2,4.8,14.48]],"ltp":0.0,"tv":0.0,"id":13010434},{"batb":[[0,21,8.86],[1,20,16.62],[2,10,12.59]],"ltp":0.0,"tv":0.0,"id":17293893},{"batb":[[0,5.5,20.95],[1,5.4,27.92],[2,4.9,13.77]],"ltp":0.0,"tv":0.0,"id":17293892}]}]}
{"op":"mcm","clk":"1005472228","pt":1580642868125,"mc":[{"id":"1.168224295","rc":[{"batb":[[0,1.68,61.33],[1,1.66,118.76],[2,1.65,63.5]],"batl":[[0,1.75,25.49],[1,1.82,22.5],[2,1.84,42.01]],"ltp":0.0,"tv":0.0,"id":13010435},{"batb":[[1,5,44.92],[2,4.9,13.69]],"batl":[[0,5.6,8.4],[1,5.9,12.51],[2,6.2,11.72]],"ltp":0.0,"tv":0.0,"id":13010434},{"batb":[[2,17.5,7.4]],"ltp":0.0,"tv":0.0,"id":17293893},{"batb":[[2,5.1,22.83]],"batl":[[1,6.2,19.05]],"ltp":0.0,"tv":0.0,"id":17293892}]}]}
{"op":"mcm","clk":"1005473481","pt":1580642874800,"mc":[{"id":"1.168224295","rc":[{"batb":[[0,1.57,31.63],[1,1.01,0.51],[2,1.65,0]],"batl":[[0,1.82,22.5],[1,1.82,0],[2,1.84,0]],"ltp":0.0,"tv":0.0,"id":13010435},{"batb":[[0,5,31.86],[1,4.9,13.69],[2,1.01,0.51]],"batl":[[0,6.2,11.72],[1,5.9,0],[2,6.2,0]],"ltp":0.0,"tv":0.0,"id":13010434},{"batb":[[0,13.5,6.37],[1,1.01,0.51],[2,17.5,0]],"ltp":0.0,"tv":0.0,"id":17293893},{"batb":[[0,5.4,27.92],[1,5,13.22],[2,1.01,0.51]],"batl":[[0,6.2,11.49],[1,6.2,0]],"ltp":0.0,"tv":0.0,"id":17293892}]}]}
{"op":"mcm","clk":"1005474522","pt":1580642880609,"mc":[{"id":"1.168224295","rc":[{"batb":[[0,1.64,112.47],[1,1.63,66.45],[2,1.57,31.63]],"ltp":0.0,"tv":0.0,"id":13010435},{"batb":[[0,5.1,42.16],[1,5,31.86],[2,4.9,13.69]],"ltp":0.0,"tv":0.0,"id":13010434},{"batb":[[0,23,12.52],[1,22,13.54],[2,13.5,6.37]],"ltp":0.0,"tv":0.0,"id":17293893},{"batb":[[0,5.5,28.86],[1,5.4,27.92],[2,5,13.22]],"ltp":0.0,"tv":0.0,"id":17293892}]}]}
{"op":"mcm","clk":"1005475019","pt":1580642883490,"mc":[{"id":"1.168224295","rc":[{"batb":[[0,1.57,31.63],[1,1.01,0.51],[2,1.57,0]],"ltp":0.0,"tv":0.0,"id":13010435},{"batb":[[0,5,31.86],[1,4.9,13.69],[2,1.01,0.51]],"ltp":0.0,"tv":0.0,"id":13010434},{"batb":[[0,13.5,6.37],[1,1.01,0.51],[2,13.5,0]],"ltp":0.0,"tv":0.0,"id":17293893},{"batb":[[0,5.4,27.92],[1,5,13.22],[2,1.01,0.51]],"ltp":0.0,"tv":0.0,"id":17293892}]}]}
{"op":"mcm","clk":"1005475518","pt":1580642886398,"mc":[{"id":"1.168224295","rc":[{"batb":[[0,1.58,82.56],[1,1.57,107.54],[2,1.01,0.51]],"ltp":0.0,"tv":0.0,"id":13010435},{"batb":[[0,5,42.53],[1,4.9,46.88]],"ltp":0.0,"tv":0.0,"id":13010434},{"batb":[[0,16,6.84],[1,15.5,14.43],[2,13.5,6.37]],"ltp":0.0,"tv":0.0,"id":17293893},{"batb":[[1,5.3,29],[2,5,13.22]],"ltp":0.0,"tv":0.0,"id":17293892}]}]}
{"op":"mcm","clk":"1005476749","pt":1580642893571,"mc":[{"id":"1.168224295","rc":[{"batb":[[0,1.57,31.63],[1,1.01,0.51],[2,1.01,0]],"ltp":0.0,"tv":0.0,"id":13010435}]}]}
{"op":"mcm","clk":"1005477374","pt":1580642897189,"mc":[{"id":"1.168224295","rc":[{"batb":[[0,1.72,101.57],[1,1.7,113.38],[2,1.59,30.29]],"batl":[[1,1.93,18.8]],"ltp":0.0,"tv":0.0,"id":13010435},{"batb":[[2,4.8,14.32]],"batl":[[0,5.8,13.06],[1,6,12.04],[2,6.2,11.72]],"ltp":0.0,"tv":0.0,"id":13010434},{"batl":[[0,20,5.98]],"ltp":0.0,"tv":0.0,"id":17293893},{"batl":[[0,5.8,12.75],[1,6,12.12],[2,6.2,11.49]],"ltp":0.0,"tv":0.0,"id":17293892}]}]}
{"op":"mcm","clk":"1005477465","pt":1580642897735,"mc":[{"id":"1.168224295","rc":[{"batb":[[0,1.72,159.54]],"batl":[[1,1.89,42.01],[2,1.93,18.8]],"ltp":0.0,"tv":0.0,"id":13010435},{"batl":[[0,5.5,9.24],[1,5.8,13.06],[2,6,12.04]],"ltp":0.0,"tv":0.0,"id":13010434},{"batb":[[2,5,23.3]],"batl":[[2,6.2,7.56]],"ltp":0.0,"tv":0.0,"id":17293892}]}]}
{"op":"mcm","clk":"1005480211","pt":1580642913400,"mc":[{"id":"1.168224295","rc":[{"batb":[[0,1.72,57.97],[1,1.59,30.29],[2,1.01,0.51]],"batl":[[0,1.89,42.01],[1,1.93,18.8],[2,1.93,0]],"ltp":0.0,"tv":0.0,"id":13010435},{"batb":[[0,4.9,33.19],[1,4.8,14.32],[2,4.5,11.76]],"batl":[[1,6,12.04],[2,6,0]],"ltp":0.0,"tv":0.0,"id":13010434},{"batb":[[0,13,3.36],[1,10,12.59],[2,1.01,0.51]],"ltp":0.0,"tv":0.0,"id":17293893},{"batb":[[0,5.3,29],[1,5,10.08],[2,4.9,13.85]],"batl":[[0,6,12.12],[1,6.2,7.56],[2,6.2,0]],"ltp":0.0,"tv":0.0,"id":17293892}]}]}
{"op":"mcm","clk":"1005480482","pt":1580642914987,"mc":[{"id":"1.168224295","rc":[{"batb":[[0,1.59,30.29],[1,1.01,0.51],[2,1.01,0]],"batl":[[0,1.93,18.8],[1,1.93,0]],"ltp":0.0,"tv":0.0,"id":13010435},{"batb":[[2,1.01,0.51]],"batl":[[0,6,12.04],[1,6,0]],"ltp":0.0,"tv":0.0,"id":13010434},{"batb":[[0,10,12.59],[1,1.01,0.51],[2,1.01,0]],"ltp":0.0,"tv":0.0,"id":17293893},{"batb":[[1,4.9,13.85],[2,1.01,0.51]],"batl":[[1,6.2,0]],"ltp":0.0,"tv":0.0,"id":17293892}]}]}
{"op":"mcm","clk":"1005480671","pt":1580642916309,"mc":[{"id":"1.168224295","rc":[{"batb":[[0,1.59,144.66],[1,1.58,74.23],[2,1.01,0.51]],"ltp":0.0,"tv":0.0,"id":13010435},{"batb":[[0,4.9,46.15],[1,4.8,48.97]],"ltp":0.0,"tv":0.0,"id":13010434},{"batb":[[0,11.5,9.59],[1,11,29.13],[2,10,12.59]],"ltp":0.0,"tv":0.0,"id":17293893},{"batb":[[1,5.2,30.06],[2,4.9,13.85]],"ltp":0.0,"tv":0.0,"id":17293892}]}]}
{"op":"mcm","clk":"1005483445","pt":1580642932268,"mc":[{"id":"1.168224295","rc":[{"batb":[[0,1.59,30.29],[1,1.01,0.51],[2,1.01,0]],"ltp":0.0,"tv":0.0,"id":13010435}]}]}
{"op":"mcm","clk":"1005483909","pt":1580642935186,"mc":[{"id":"1.168224295","rc":[{"batb":[[0,1.81,81.09],[1,1.79,94.98],[2,1.59,30.29]],"ltp":0.0,"tv":0.0,"id":13010435}]}]}
{"op":"mcm","clk":"1005484070","pt":1580642936100,"mc":[{"id":"1.168224295","rc":[{"batb":[[0,1.82,19.12],[1,1.81,81.09],[2,1.79,147.91]],"batl":[[1,1.97,42.01],[2,2,16.84]],"ltp":0.0,"tv":0.0,"id":13010435},{"batb":[[2,4.5,11.76]],"batl":[[0,5.5,9.24],[1,5.8,12.98]],"ltp":0.0,"tv":0.0,"id":13010434},{"batb":[[2,10,16.79]],"batl":[[0,13.5,3.36],[1,14,11.57],[2,20,5.82]],"ltp":0.0,"tv":0.0,"id":17293893},{"batb":[[2,5.1,10.08]],"batl":[[0,5.7,13.3],[1,5.9,12.59],[2,6.2,7.56]],"ltp":0.0,"tv":0.0,"id":17293892}]}]}
{"op":"mcm","clk":"1005487342","pt":1580642953971,"mc":[{"id":"1.168224295","rc":[{"batb":[[0,1.79,52.93],[1,1.71,23.29],[2,1.01,0.51]],"batl":[[0,1.97,42.01],[1,2,16.84],[2,2,0]],"ltp":0.0,"tv":0.0,"id":13010435},{"batb":[[0,4.9,23.76]],"ltp":0.0,"tv":0.0,"id":13010434},{"batb":[[0,10,4.2],[1,9,6.92],[2,1.01,0.51]],"batl":[[1,20,5.82],[2,20,0]],"ltp":0.0,"tv":0.0,"id":17293893},{"batb":[[0,5.2,30.06],[1,5.1,10.08],[2,4.8,14.32]],"batl":[[0,5.9,12.59],[1,6.2,7.56],[2,6.2,0]],"ltp":0.0,"tv":0.0,"id":17293892}]}]}
{"op":"mcm","clk":"1005487467","pt":1580642954768,"mc":[{"id":"1.168224295","rc":[{"batb":[[0,1.71,23.29],[1,1.01,0.51],[2,1.01,0]],"batl":[[0,2,16.84],[1,2,0]],"ltp":0.0,"tv":0.0,"id":13010435},{"batb":[[2,1.01,0.51]],"batl":[[0,5.8,12.98],[1,5.8,0]],"ltp":0.0,"tv":0.0,"id":13010434},{"batb":[[0,9,6.92],[1,1.01,0.51],[2,1.01,0]],"batl":[[0,20,5.82],[1,20,0]],"ltp":0.0,"tv":0.0,"id":17293893},{"batb":[[1,4.8,14.32],[2,1.01,0.51]],"batl":[[1,6.2,0]],"ltp":0.0,"tv":0.0,"id":17293892}]}]}
{"op":"mcm","clk":"1005488236","pt":1580642959192,"mc":[{"id":"1.168224295","rc":[{"batb":[[0,1.79,77.06],[1,1.77,98.64],[2,1.71,23.29]],"ltp":0.0,"tv":0.0,"id":13010435},{"batb":[[0,4.9,53.16]],"ltp":0.0,"tv":0.0,"id":13010434},{"batb":[[0,12,20.03],[1,11.5,26.16],[2,9,6.92]],"ltp":0.0,"tv":0.0,"id":17293893},{"batb":[[0,5.3,41.88],[1,5.2,30.06],[2,4.8,14.32]],"ltp":0.0,"tv":0.0,"id":17293892}]}]}
{"op":"mcm","clk":"1005488676","pt":1580642961589,"mc":[{"id":"1.168224295","rc":[{"batb":[[0,1.71,23.29],[1,1.01,0.51],[2,1.71,0]],"ltp":0.0,"tv":0.0,"id":13010435},{"batb":[[0,4.9,23.76]],"ltp":0.0,"tv":0.0,"id":13010434},{"batb":[[0,9,6.92],[1,1.01,0.51],[2,9,0]],"ltp":0.0,"tv":0.0,"id":17293893},{"batb":[[0,5.2,30.06],[1,4.8,14.32],[2,1.01,0.51]],"ltp":0.0,"tv":0.0,"id":17293892}]}]}
{"op":"mcm","clk":"1005489180","pt":1580642964493,"mc":[{"id":"1.168224295","rc":[{"batb":[[0,1.71,109.36],[1,1.69,115.76],[2,1.01,0.51]],"ltp":0.0,"tv":0.0,"id":13010435},{"batb":[[0,9.6,21.25],[1,9.4,16.44],[2,9,6.92]],"ltp":0.0,"tv":0.0,"id":17293893},{"batb":[[0,5.2,46.47],[1,5.1,31.2],[2,4.8,14.32]],"ltp":0.0,"tv":0.0,"id":17293892}]}]}
{"op":"mcm","clk":"1005490257","pt":1580642970324,"mc":[{"id":"1.168224295","rc":[{"batb":[[1,4.8,14.32]],"ltp":0.0,"tv":0.0,"id":13010434},{"batb":[[0,9,6.92],[1,1.01,0.51],[2,9,0]],"ltp":0.0,"tv":0.0,"id":17293893},{"batb":[[0,4.8,14.32],[1,1.01,0.51],[2,4.8,0]],"ltp":0.0,"tv":0.0,"id":17293892}]}]}
{"op":"mcm","clk":"1005490843","pt":1580642973295,"mc":[{"id":"1.168224295","rc":[{"batb":[[0,5,47.73],[1,4.9,33.11],[2,4.8,14.32]],"ltp":0.0,"tv":0.0,"id":13010434},{"batb":[[0,16,14.39],[1,15.5,14.21],[2,9,6.92]],"ltp":0.0,"tv":0.0,"id":17293893},{"batb":[[0,5.4,37.4],[1,5.3,28.84],[2,4.8,14.32]],"ltp":0.0,"tv":0.0,"id":17293892}]}]}
{"op":"mcm","clk":"1005490974","pt":1580642974095,"mc":[{"id":"1.168224295","rc":[{"batb":[[0,1.71,168.17],[2,1.58,30.45]],"batl":[[0,1.81,22.82],[1,1.9,42.01],[2,1.92,19.04]],"ltp":0.0,"tv":0.0,"id":13010435},{"batb":[[1,4.9,46.64]],"batl":[[0,5.5,9.24],[1,5.8,12.98],[2,6,12.04]],"ltp":0.0,"tv":0.0,"id":13010434},{"batb":[[2,14,6.22]],"ltp":0.0,"tv":0.0,"id":17293893},{"batb":[[2,5.1,10.08]],"batl":[[1,6,11.96],[2,6.2,7.56]],"ltp":0.0,"tv":0.0,"id":17293892}]}]}
{"op":"mcm","clk":"1005492589","pt":1580642983342,"mc":[{"id":"1.168224295","rc":[{"batb":[[0,1.71,58.81],[1,1.58,30.45],[2,1.01,0.51]],"batl":[[0,1.9,42.01],[1,1.92,19.04],[2,1.92,0]],"ltp":0.0,"tv":0.0,"id":13010435},{"batb":[[0,4.9,33.11],[1,4.8,14.32],[2,4.5,11.76]],"batl":[[1,6,12.04],[2,6,0]],"ltp":0.0,"tv":0.0,"id":13010434},{"batb":[[0,13,3.36],[1,10.5,12.2],[2,1.01,0.51]],"ltp":0.0,"tv":0.0,"id":17293893},{"batb":[[0,5.3,28.84],[1,5.1,10.08],[2,4.9,13.61]],"batl":[[0,6,11.96],[1,6.2,7.56],[2,6.2,0]],"ltp":0.0,"tv":0.0,"id":17293892}]}]}
{"op":"mcm","clk":"1005492895","pt":1580642984839,"mc":[{"id":"1.168224295","rc":[{"batb":[[0,1.58,30.45],[1,1.01,0.51],[2,1.01,0]],"batl":[[0,1.92,19.04],[1,1.92,0]],"ltp":0.0,"tv":0.0,"id":13010435},{"batb":[[2,1.01,0.51]],"batl":[[0,6,12.04],[1,6,0]],"ltp":0.0,"tv":0.0,"id":13010434},{"batb":[[0,10.5,12.2],[1,1.01,0.51],[2,1.01,0]],"ltp":0.0,"tv":0.0,"id":17293893},{"batb":[[1,4.9,13.61],[2,1.01,0.51]],"batl":[[1,6.2,0]],"ltp":0.0,"tv":0.0,"id":17293892}]}]}
{"op":"mcm","clk":"1005493115","pt":1580642986128,"mc":[{"id":"1.168224295","rc":[{"batb":[[0,1.59,66.32],[1,1.58,104.49],[2,1.01,0.51]],"ltp":0.0,"tv":0.0,"id":13010435},{"batb":[[0,4.9,50.44],[1,4.8,48.9]],"ltp":0.0,"tv":0.0,"id":13010434},{"batb":[[0,11.5,19.14],[1,11,28.74],[2,10.5,12.2]],"ltp":0.0,"tv":0.0,"id":17293893},{"batb":[[0,5.3,45.67],[1,5.2,29.91],[2,4.9,13.61]],"ltp":0.0,"tv":0.0,"id":17293892}]}]}
{"op":"mcm","clk":"1005494667","pt":1580642994393,"mc":[{"id":"1.168224295","rc":[{"batb":[[0,4.8,14.32],[1,1.01,0.51],[2,1.01,0]],"ltp":0.0,"tv":0.0,"id":13010434},{"batb":[[0,10.5,12.2],[1,1.01,0.51],[2,10.5,0]],"ltp":0.0,"tv":0.0,"id":17293893},{"batb":[[0,4.9,13.61],[1,1.01,0.51],[2,4.9,0]],"ltp":0.0,"tv":0.0,"id":17293892}]}]}
{"op":"mcm","clk":"1005495257","pt":1580642997399,"mc":[{"id":"1.168224295","rc":[{"batb":[[0,5.2,32.69],[1,5.1,30.56],[2,4.8,14.32]],"ltp":0.0,"tv":0.0,"id":13010434},{"batb":[[0,42,2.88],[1,40,8.2],[2,10.5,12.2]],"ltp":0.0,"tv":0.0,"id":17293893},{"batb":[[0,5.5,42.07],[1,5.4,27.68],[2,4.9,13.61]],"ltp":0.0,"tv":0.0,"id":17293892}]}]}
{"op":"mcm","clk":"1005495407","pt":1580642998270,"mc":[{"id":"1.168224295","rc":[{"batb":[[0,1.59,136.9],[2,1.55,32.81]],"batl":[[0,1.67,29.82],[1,1.73,42.01],[2,1.74,26.28]],"ltp":0.0,"tv":0.0,"id":13010435},{"batb":[[1,5.1,43.07],[2,5,13.14]],"batl":[[0,5.6,8.4],[1,6,12.04],[2,6.2,11.64]],"ltp":0.0,"tv":0.0,"id":13010434},{"batb":[[2,21,4.41]],"ltp":0.0,"tv":0.0,"id":17293893},{"batb":[[2,5.3,9.24]],"batl":[[1,6.2,11.49],[2,6.6,6.72]],"ltp":0.0,"tv":0.0,"id":17293892}]}]}
{"op":"mcm","clk":"1005498771","pt":1580643015118,"mc":[{"id":"1.168224295","rc":[{"batb":[[0,1.59,70.58]],"ltp":0.0,"tv":0.0,"id":13010435},{"batb":[[0,5.5,26.95],[1,5.3,9.24],[2,5.1,12.43]],"ltp":0.0,"tv":0.0,"id":17293892}]}]}
{"op":"mcm","clk":"1005499333","pt":1580643018323,"mc":[{"id":"1.168224295","rc":[{"batb":[[1,1.58,166.03],[2,1.57,76.66]],"ltp":0.0,"tv":0.0,"id":13010435},{"batb":[[0,5.6,18.2],[1,5.5,26.95],[2,5.3,9.24]],"ltp":0.0,"tv":0.0,"id":17293892}]}]}
{"op":"mcm","clk":"1005508175","pt":1580643066373,"mc":[{"id":"1.168224295","rc":[{"batb":[[1,1.58,134.92]],"ltp":0.0,"tv":0.0,"id":13010435}]}]}
{"op":"mcm","clk":"1005508747","pt":1580643069358,"mc":[{"id":"1.168224295","rc":[{"batb":[[0,42,5.2]],"ltp":0.0,"tv":0.0,"id":17293893},{"batb":[[0,5.6,35.26]],"ltp":0.0,"tv":0.0,"id":17293892}]}]}
{"op":"mcm","clk":"1005512289","pt":1580643088114,"mc":[{"id":"1.168224295","rc":[{"batb":[[1,1.55,32.81],[2,1.01,0.51]],"batl":[[0,1.73,42.01],[1,1.74,26.28],[2,1.74,0]],"ltp":0.0,"tv":0.0,"id":13010435},{"batb":[[0,5.1,30.56],[1,5,13.14],[2,4.6,10.92]],"batl":[[1,6.2,11.64],[2,6.2,0]],"ltp":0.0,"tv":0.0,"id":13010434},{"batb":[[0,21,4.41],[1,1.01,0.51],[2,21,0]],"ltp":0.0,"tv":0.0,"id":17293893},{"batb":[[0,5.5,19.51],[1,5.3,9.24],[2,5,13.3]],"batl":[[0,6.2,11.49],[1,6.6,6.72],[2,6.6,0]],"ltp":0.0,"tv":0.0,"id":17293892}]}]}
{"op":"mcm","clk":"1005512409","pt":1580643088813,"mc":[{"id":"1.168224295","rc":[{"batb":[[0,1.55,32.81],[1,1.01,0.51],[2,1.01,0]],"batl":[[0,1.74,26.28],[1,1.74,0]],"ltp":0.0,"tv":0.0,"id":13010435},{"batb":[[2,1.01,0.51]],"batl":[[0,6.2,11.64],[1,6.2,0]],"ltp":0.0,"tv":0.0,"id":13010434},{"batb":[[1,5,13.3],[2,1.01,0.51]],"batl":[[1,6.6,0]],"ltp":0.0,"tv":0.0,"id":17293892}]}]}
{"op":"mcm","clk":"1005512842","pt":1580643091199,"mc":[{"id":"1.168224295","rc":[{"batb":[[0,1.56,79.84],[1,1.55,113.19],[2,1.01,0.51]],"ltp":0.0,"tv":0.0,"id":13010435},{"batb":[[1,5,45.03]],"ltp":0.0,"tv":0.0,"id":13010434},{"batb":[[0,28,8.58],[1,27,9.21],[2,21,4.41]],"ltp":0.0,"tv":0.0,"id":17293893},{"batb":[[1,5.4,28.31],[2,5,13.3]],"ltp":0.0,"tv":0.0,"id":17293892}]}]}
{"op":"mcm","clk":"1005514127","pt":1580643097827,"mc":[{"id":"1.168224295","rc":[{"batb":[[1,5,13.14]],"ltp":0.0,"tv":0.0,"id":13010434},{"batb":[[0,21,4.41],[1,1.01,0.51],[2,21,0]],"ltp":0.0,"tv":0.0,"id":17293893},{"batb":[[0,5,13.3],[1,1.01,0.51],[2,5,0]],"ltp":0.0,"tv":0.0,"id":17293892}]}]}
{"op":"mcm","clk":"1005514781","pt":1580643101300,"mc":[{"id":"1.168224295","rc":[{"batb":[[2,1.53,34.38]],"batl":[[0,1.64,32.1],[1,1.7,28.33],[2,1.74,26.28]],"ltp":0.0,"tv":0.0,"id":13010435},{"batb":[[0,5.2,40.89],[1,5.1,30.56],[2,5,13.14]],"ltp":0.0,"tv":0.0,"id":13010434},{"batb":[[0,55,5.29],[1,50,7.76],[2,30,2.99]],"ltp":0.0,"tv":0.0,"id":17293893},{"batb":[[0,5.7,29.81],[1,5.6,25.97],[2,5.2,11.96]],"batl":[[1,6.4,11.02]],"ltp":0.0,"tv":0.0,"id":17293892}]}]}
{"op":"mcm","clk":"1005514874","pt":1580643101839,"mc":[{"id":"1.168224295","rc":[{"batb":[[0,1.56,154.62]],"batl":[[1,1.69,42.01],[2,1.7,28.33]],"ltp":0.0,"tv":0.0,"id":13010435},{"batb":[[2,5,12.98]],"batl":[[0,5.7,8.4],[1,6.2,11.64]],"ltp":0.0,"tv":0.0,"id":13010434},{"batb":[[2,5.4,9.24]],"batl":[[2,6.6,6.72]],"ltp":0.0,"tv":0.0,"id":17293892}]}]}
{"op":"mcm","clk":"1005516952","pt":1580643113263,"mc":[{"id":"1.168224295","rc":[{"batb":[[0,1.53,34.38],[1,1.01,0.51],[2,1.53,0]],"batl":[[0,1.7,28.33],[1,1.69,0],[2,1.7,0]],"ltp":0.0,"tv":0.0,"id":13010435},{"batb":[[0,5.1,30.56],[1,5,12.98],[2,1.01,0.51]],"batl":[[0,6.2,11.64],[1,6.2,0]],"ltp":0.0,"tv":0.0,"id":13010434},{"batb":[[0,26,3.69],[1,1.01,0.51],[2,30,0]],"ltp":0.0,"tv":0.0,"id":17293893},{"batb":[[0,5.1,12.9],[1,1.01,0.51],[2,5.4,0]],"batl":[[0,6.4,11.02],[1,6.4,0],[2,6.6,0]],"ltp":0.0,"tv":0.0,"id":17293892}]}]}
{"op":"mcm","clk":"1005517541","pt":1580643116356,"mc":[{"id":"1.168224295","rc":[{"batb":[[0,1.54,88.16],[1,1.53,118.98],[2,1.01,0.51]],"ltp":0.0,"tv":0.0,"id":13010435},{"batb":[[0,5.1,45.77],[1,5,44.65]],"ltp":0.0,"tv":0.0,"id":13010434},{"batb":[[0,38,3.29],[1,36,10.24],[2,26,3.69]],"ltp":0.0,"tv":0.0,"id":17293893},{"batb":[[0,5.5,37.93],[1,5.4,28.05],[2,5.1,12.9]],"ltp":0.0,"tv":0.0,"id":17293892}]}]}
{"op":"mcm","clk":"1005518048","pt":1580643119244,"mc":[{"id":"1.168224295","rc":[{"batb":[[0,1.53,34.38],[1,1.01,0.51],[2,1.01,0]],"ltp":0.0,"tv":0.0,"id":13010435}]}]}
{"op":"mcm","clk":"1005518626","pt":1580643122381,"mc":[{"id":"1.168224295","rc":[{"batb":[[0,1.6,87.5],[1,1.59,73],[2,1.53,34.38]],"ltp":0.0,"tv":0.0,"id":13010435}]}]}
{"op":"mcm","clk":"1005518813","pt":1580643123383,"mc":[{"id":"1.168224295","rc":[{"batb":[[0,1.61,28.95],[1,1.6,87.5],[2,1.59,73]],"batl":[[1,1.77,24.55]],"ltp":0.0,"tv":0.0,"id":13010435},{"batl":[[0,5.9,12.43],[1,6,11.96]],"ltp":0.0,"tv":0.0,"id":13010434},{"batb":[[2,4.9,13.85]],"batl":[[0,5.9,12.35],[1,6,12.04]],"ltp":0.0,"tv":0.0,"id":17293892}]}]}
{"op":"mcm","clk":"1005518893","pt":1580643123778,"mc":[{"id":"1.168224295","rc":[{"batb":[[1,1.6,157.24]],"batl":[[1,1.74,42.01],[2,1.77,24.55]],"ltp":0.0,"tv":0.0,"id":13010435},{"batb":[[2,4.6,10.92]],"batl":[[0,5.6,8.4],[1,5.9,12.43],[2,6,11.96]],"ltp":0.0,"tv":0.0,"id":13010434},{"batb":[[2,5.2,9.24]],"batl":[[2,6.4,7.56]],"ltp":0.0,"tv":0.0,"id":17293892}]}]}
{"op":"mcm","clk":"1005520718","pt":1580643134273,"mc":[{"id":"1.168224295","rc":[{"batb":[[0,1.6,69.74],[1,1.57,31.24],[2,1.01,0.51]],"batl":[[0,1.74,42.01],[1,1.77,24.55],[2,1.77,0]],"ltp":0.0,"tv":0.0,"id":13010435},{"batb":[[0,5,44.65],[1,4.6,10.92],[2,1.01,0.51]],"batl":[[1,6,11.96],[2,6,0]],"ltp":0.0,"tv":0.0,"id":13010434},{"batb":[[0,18,6.53],[1,1.01,0.51],[2,26,0]],"ltp":0.0,"tv":0.0,"id":17293893},{"batb":[[0,5.4,28.05],[1,5.2,9.24],[2,4.9,13.85]],"batl":[[0,6,12.04],[1,6.4,7.56],[2,6.4,0]],"ltp":0.0,"tv":0.0,"id":17293892}]}]}
{"op":"mcm","clk":"1005520825","pt":1580643134908,"mc":[{"id":"1.168224295","rc":[{"batb":[[0,1.57,31.24],[1,1.01,0.51],[2,1.01,0]],"batl":[[0,1.77,24.55],[1,1.77,0]],"ltp":0.0,"tv":0.0,"id":13010435},{"batb":[[1,1.01,0.51],[2,1.01,0]],"batl":[[0,6,11.96],[1,6,0]],"ltp":0.0,"tv":0.0,"id":13010434},{"batb":[[1,4.9,13.85],[2,1.01,0.51]],"batl":[[1,6.4,0]],"ltp":0.0,"tv":0.0,"id":17293892}]}]}
{"op":"mcm","clk":"1005521180","pt":1580643137302,"mc":[{"id":"1.168224295","rc":[{"batb":[[0,1.57,132.86],[1,1.56,78.52],[2,1.01,0.51]],"ltp":0.0,"tv":0.0,"id":13010435},{"batb":[[0,5,62.58],[1,4.9,33.11],[2,1.01,0.51]],"ltp":0.0,"tv":0.0,"id":13010434},{"batb":[[0,24,7.65],[1,23,12.8],[2,18,6.53]],"ltp":0.0,"tv":0.0,"id":17293893},{"batb":[[1,5.3,29.44],[2,4.9,13.85]],"ltp":0.0,"tv":0.0,"id":17293892}]}]}
{"op":"mcm","clk":"1005521551","pt":1580643139481,"mc":[{"id":"1.168224295","rc":[{"batb":[[0,1.57,31.24],[1,1.01,0.51],[2,1.01,0]],"ltp":0.0,"tv":0.0,"id":13010435},{"batb":[[0,5,44.74],[1,1.01,0.51],[2,1.01,0]],"ltp":0.0,"tv":0.0,"id":13010434},{"batb":[[0,18,6.53],[1,1.01,0.51],[2,18,0]],"ltp":0.0,"tv":0.0,"id":17293893},{"batb":[[1,4.9,13.85],[2,1.01,0.51]],"ltp":0.0,"tv":0.0,"id":17293892}]}]}
{"op":"mcm","clk":"1005522050","pt":1580643142374,"mc":[{"id":"1.168224295","rc":[{"batb":[[0,1.61,97.96],[1,1.6,71.35],[2,1.57,31.24]],"ltp":0.0,"tv":0.0,"id":13010435},{"batb":[[0,5.1,40.03],[1,5,44.74],[2,1.01,0.51]],"ltp":0.0,"tv":0.0,"id":13010434},{"batb":[[0,34,4.36],[1,32,12.88],[2,18,6.53]],"ltp":0.0,"tv":0.0,"id":17293893},{"batb":[[0,5.5,29.62],[1,5.4,28.05],[2,4.9,13.85]],"ltp":0.0,"tv":0.0,"id":17293892}]}]}
{"op":"mcm","clk":"1005522708","pt":1580643145283,"mc":[{"id":"1.168224295","rc":[{"batb":[[0,1.57,31.24],[1,1.01,0.51],[2,1.57,0]],"ltp":0.0,"tv":0.0,"id":13010435},{"batb":[[0,5,44.74],[1,1.01,0.51],[2,1.01,0]],"ltp":0.0,"tv":0.0,"id":13010434},{"batb":[[0,18,6.53],[1,1.01,0.51],[2,18,0]],"ltp":0.0,"tv":0.0,"id":17293893},{"batb":[[0,5.4,28.05],[1,4.9,13.85],[2,1.01,0.51]],"ltp":0.0,"tv":0.0,"id":17293892}]}]}
{"op":"mcm","clk":"1005523354","pt":1580643148896,"mc":[{"id":"1.168224295","rc":[{"batb":[[0,1.57,132.86],[1,1.56,78.52],[2,1.01,0.51]],"ltp":0.0,"tv":0.0,"id":13010435},{"batb":[[0,5,62.58],[1,4.9,33.11],[2,1.01,0.51]],"ltp":0.0,"tv":0.0,"id":13010434},{"batb":[[0,24,7.65],[1,23,12.8],[2,18,6.53]],"ltp":0.0,"tv":0.0,"id":17293893},{"batb":[[1,5.3,29.44],[2,4.9,13.85]],"ltp":0.0,"tv":0.0,"id":17293892}]}]}
{"op":"mcm","clk":"1005524324","pt":1580643154457,"mc":[{"id":"1.168224295","rc":[{"batb":[[0,1.57,31.24],[1,1.01,0.51],[2,1.01,0]],"ltp":0.0,"tv":0.0,"id":13010435},{"batb":[[0,5,44.74],[1,1.01,0.51],[2,1.01,0]],"ltp":0.0,"tv":0.0,"id":13010434},{"batb":[[0,18,6.53],[1,1.01,0.51],[2,18,0]],"ltp":0.0,"tv":0.0,"id":17293893},{"batb":[[1,4.9,13.85],[2,1.01,0.51]],"ltp":0.0,"tv":0.0,"id":17293892}]}]}
{"op":"mcm","clk":"1005524825","pt":1580643157317,"mc":[{"id":"1.168224295","rc":[{"batb":[[0,1.66,82.8],[1,1.65,63.72],[2,1.57,31.24]],"ltp":0.0,"tv":0.0,"id":13010435},{"batb":[[0,5,62.58],[1,4.9,33.11],[2,1.01,0.51]],"ltp":0.0,"tv":0.0,"id":13010434},{"batb":[[0,24,7.65],[1,23,12.8],[2,18,6.53]],"ltp":0.0,"tv":0.0,"id":17293893},{"batb":[[1,5.3,29.44],[2,4.9,13.85]],"ltp":0.0,"tv":0.0,"id":17293892}]}]}
{"op":"mcm","clk":"1005525028","pt":1580643158289,"mc":[{"id":"1.168224295","rc":[{"batb":[[0,1.67,25.02],[1,1.66,82.8],[2,1.65,127.57]],"batl":[[1,1.8,42.01],[2,1.88,20.38]],"ltp":0.0,"tv":0.0,"id":13010435},{"batb":[[0,5,49.6],[2,4.8,14.24]],"batl":[[0,5.5,9.24],[1,5.8,12.98],[2,5.9,12.51]],"ltp":0.0,"tv":0.0,"id":13010434},{"batl":[[0,30,5.98]],"ltp":0.0,"tv":0.0,"id":17293893},{"batb":[[2,5.1,10.08]],"batl":[[0,5.7,13.22],[1,5.8,12.83],[2,6.2,7.56]],"ltp":0.0,"tv":0.0,"id":17293892}]}]}
{"op":"mcm","clk":"1005528531","pt":1580643175315,"mc":[{"id":"1.168224295","rc":[{"batb":[[0,1.62,27.85],[1,1.01,0.51],[2,1.65,0]],"batl":[[0,1.88,20.38],[1,1.8,0],[2,1.88,0]],"ltp":0.0,"tv":0.0,"id":13010435},{"batb":[[0,4.9,33.11],[1,4.8,14.24],[2,1.01,0.51]],"batl":[[0,5.9,12.51],[1,5.8,0],[2,5.9,0]],"ltp":0.0,"tv":0.0,"id":13010434},{"batb":[[0,12.5,7.63],[1,1.01,0.51],[2,18,0]],"ltp":0.0,"tv":0.0,"id":17293893},{"batb":[[0,4.8,14.63],[1,1.01,0.51],[2,5.1,0]],"batl":[[0,5.8,12.83],[1,5.8,0],[2,6.2,0]],"ltp":0.0,"tv":0.0,"id":17293892}]}]}
{"op":"mcm","clk":"1005529132","pt":1580643178181,"mc":[{"id":"1.168224295","rc":[{"batb":[[0,4.9,33.21]],"ltp":0.0,"tv":0.0,"id":13010434},{"batb":[[0,5.2,30.39],[1,4.8,14.63],[2,1.01,0.51]],"ltp":0.0,"tv":0.0,"id":17293892}]}]}
{"op":"mcm","clk":"1005529892","pt":1580643181846,"mc":[{"id":"1.168224295","rc":[{"batb":[[0,1.68,61.64],[1,1.66,123.85],[2,1.62,27.85]],"ltp":0.0,"tv":0.0,"id":13010435},{"batb":[[0,5,43.21],[1,4.9,33.21],[2,4.8,14.24]],"ltp":0.0,"tv":0.0,"id":13010434},{"batb":[[0,21,17.99],[1,20,15.07],[2,12.5,7.63]],"ltp":0.0,"tv":0.0,"id":17293893},{"batb":[[0,5.3,47.29],[1,5.2,30.39],[2,4.8,14.63]],"ltp":0.0,"tv":0.0,"id":17293892}]}]}
{"op":"mcm","clk":"1005530087","pt":1580643182862,"mc":[{"id":"1.168224295","rc":[{"batb":[[0,1.62,27.85],[1,1.01,0.51],[2,1.62,0]],"ltp":0.0,"tv":0.0,"id":13010435},{"batb":[[0,4.9,33.21],[1,4.8,14.24],[2,1.01,0.51]],"ltp":0.0,"tv":0.0,"id":13010434},{"batb":[[0,12.5,7.63],[1,1.01,0.51],[2,12.5,0]],"ltp":0.0,"tv":0.0,"id":17293893},{"batb":[[0,5.2,30.39],[1,4.8,14.63],[2,1.01,0.51]],"ltp":0.0,"tv":0.0,"id":17293892}]}]}
{"op":"mcm","clk":"1005530742","pt":1580643186041,"mc":[{"id":"1.168224295","rc":[{"batb":[[0,1.62,100.83],[1,1.61,69.63],[2,1.01,0.51]],"ltp":0.0,"tv":0.0,"id":13010435},{"batb":[[0,4.9,51.63],[1,4.8,48.93]],"ltp":0.0,"tv":0.0,"id":13010434},{"batb":[[0,15.5,8.76],[1,15,15.69],[2,12.5,7.63]],"ltp":0.0,"tv":0.0,"id":17293893},{"batb":[[0,5.2,49.02],[1,5.1,31.74],[2,4.8,14.63]],"ltp":0.0,"tv":0.0,"id":17293892}]}]}
{"op":"mcm","clk":"1005531794","pt":1580643191874,"mc":[{"id":"1.168224295","rc":[{"batb":[[0,4.8,14.24],[1,1.01,0.51],[2,1.01,0]],"ltp":0.0,"tv":0.0,"id":13010434},{"batb":[[0,12.5,7.63],[1,1.01,0.51],[2,12.5,0]],"ltp":0.0,"tv":0.0,"id":17293893},{"batb":[[0,4.8,14.63],[1,1.01,0.51],[2,4.8,0]],"ltp":0.0,"tv":0.0,"id":17293892}]}]}
{"op":"mcm","clk":"1005532399","pt":1580643195079,"mc":[{"id":"1.168224295","rc":[{"batb":[[0,5.1,33.65],[1,5,31.86],[2,4.8,14.24]],"ltp":0.0,"tv":0.0,"id":13010434},{"batb":[[0,34,4.45],[1,32,12.87],[2,12.5,7.63]],"ltp":0.0,"tv":0.0,"id":17293893},{"batb":[[0,5.4,43.18],[1,5.3,29.17],[2,4.8,14.63]],"ltp":0.0,"tv":0.0,"id":17293892}]}]}
{"op":"mcm","clk":"1005532614","pt":1580643196165,"mc":[{"id":"1.168224295","rc":[{"batb":[[1,1.61,137.69],[2,1.59,30.21]],"batl":[[0,1.72,27.3],[1,1.77,42.01],[2,1.82,22.66]],"ltp":0.0,"tv":0.0,"id":13010435},{"batb":[[2,4.9,13.93]],"batl":[[0,5.5,9.24],[1,5.9,12.51]],"ltp":0.0,"tv":0.0,"id":13010434},{"batb":[[2,24,5.29]],"ltp":0.0,"tv":0.0,"id":17293893},{"batb":[[2,5.1,10.08]],"batl":[[1,5.9,12.51],[2,6.2,7.56]],"ltp":0.0,"tv":0.0,"id":17293892}]}]}
{"op":"mcm","clk":"1005535430","pt":1580643209334,"mc":[{"id":"1.168224295","rc":[{"batb":[[0,1.59,30.21],[1,1.01,0.51],[2,1.59,0]],"batl":[[0,1.82,22.66],[1,1.77,0],[2,1.82,0]],"ltp":0.0,"tv":0.0,"id":13010435},{"batb":[[0,5,31.86],[1,4.9,13.93],[2,1.01,0.51]],"batl":[[0,5.9,12.51],[1,5.9,0]],"ltp":0.0,"tv":0.0,"id":13010434},{"batb":[[0,15.5,4.64],[1,1.01,0.51],[2,24,0]],"ltp":0.0,"tv":0.0,"id":17293893},{"batb":[[0,5.3,29.17],[1,4.8,14.24],[2,1.01,0.51]],"batl":[[0,5.9,12.51],[1,5.9,0],[2,6.2,0]],"ltp":0.0,"tv":0.0,"id":17293892}]}]}
{"op":"mcm","clk":"1005535917","pt":1580643211656,"mc":[{"id":"1.168224295","rc":[{"batb":[[1,1.58,94.71],[2,1.57,76.59]],"ltp":0.0,"tv":0.0,"id":13010435},{"batb":[[1,4.9,47.29]],"ltp":0.0,"tv":0.0,"id":13010434},{"batb":[[0,19.5,12.12],[1,19,9.56],[2,15.5,4.64]],"ltp":0.0,"tv":0.0,"id":17293893},{"batb":[[1,5.2,30.59],[2,4.8,14.24]],"ltp":0.0,"tv":0.0,"id":17293892}]}]}
{"op":"mcm","clk":"1005536604","pt":1580643214937,"mc":[{"id":"1.168224295","rc":[{"batb":[[1,1.01,0.51],[2,1.57,0]],"ltp":0.0,"tv":0.0,"id":13010435},{"batb":[[1,4.9,13.93]],"ltp":0.0,"tv":0.0,"id":13010434},{"batb":[[0,15.5,4.64],[1,1.01,0.51],[2,15.5,0]],"ltp":0.0,"tv":0.0,"id":17293893},{"batb":[[1,4.8,14.24],[2,1.01,0.51]],"ltp":0.0,"tv":0.0,"id":17293892}]}]}
{"op":"mcm","clk":"1005537593","pt":1580643219335,"mc":[{"id":"1.168224295","rc":[{"batb":[[0,1.63,106.44],[1,1.62,68.18],[2,1.59,30.21]],"ltp":0.0,"tv":0.0,"id":13010435},{"batb":[[0,5.1,27.21],[1,5,31.86],[2,4.9,13.93]],"ltp":0.0,"tv":0.0,"id":13010434},{"batb":[[0,29,11],[1,28,8.47],[2,15.5,4.64]],"ltp":0.0,"tv":0.0,"id":17293893},{"batb":[[0,5.4,35.36],[1,5.3,29.17],[2,4.8,14.24]],"ltp":0.0,"tv":0.0,"id":17293892}]}]}
{"op":"mcm","clk":"1005537744","pt":1580643220169,"mc":[{"id":"1.168224295","rc":[{"batb":[[0,1.59,30.21],[1,1.01,0.51],[2,1.59,0]],"ltp":0.0,"tv":0.0,"id":13010435},{"batb":[[0,5,31.86],[1,4.9,13.93],[2,1.01,0.51]],"ltp":0.0,"tv":0.0,"id":13010434},{"batb":[[0,15.5,4.64],[1,1.01,0.51],[2,15.5,0]],"ltp":0.0,"tv":0.0,"id":17293893},{"batb":[[0,5.3,29.17],[1,4.8,14.24],[2,1.01,0.51]],"ltp":0.0,"tv":0.0,"id":17293892}]}]}
{"op":"mcm","clk":"1005538343","pt":1580643223279,"mc":[{"id":"1.168224295","rc":[{"batb":[[1,1.58,94.71],[2,1.57,76.59]],"ltp":0.0,"tv":0.0,"id":13010435},{"batb":[[1,4.9,47.29]],"ltp":0.0,"tv":0.0,"id":13010434},{"batb":[[0,19.5,12.12],[1,19,9.56],[2,15.5,4.64]],"ltp":0.0,"tv":0.0,"id":17293893},{"batb":[[1,5.2,30.59],[2,4.8,14.24]],"ltp":0.0,"tv":0.0,"id":17293892}]}]}
{"op":"mcm","clk":"1005539368","pt":1580643228809,"mc":[{"id":"1.168224295","rc":[{"batb":[[1,4.9,13.93]],"ltp":0.0,"tv":0.0,"id":13010434},{"batb":[[0,15.5,4.64],[1,1.01,0.51],[2,15.5,0]],"ltp":0.0,"tv":0.0,"id":17293893},{"batb":[[0,4.8,14.24],[1,1.01,0.51],[2,4.8,0]],"ltp":0.0,"tv":0.0,"id":17293892}]}]}
{"op":"mcm","clk":"1005539965","pt":1580643232000,"mc":[{"id":"1.168224295","rc":[{"batb":[[1,1.58,166.97]],"batl":[[0,1.73,42.01],[1,1.82,22.66]],"ltp":0.0,"tv":0.0,"id":13010435},{"batb":[[0,5.1,50.23],[1,5,31.86],[2,4.9,13.93]],"batl":[[0,5.6,8.4],[1,5.9,12.51]],"ltp":0.0,"tv":0.0,"id":13010434},{"batb":[[0,50,13.23],[1,15.5,4.64],[2,1.01,0.51]],"ltp":0.0,"tv":0.0,"id":17293893},{"batb":[[0,5.5,34.41],[1,5.4,28.09],[2,5.2,9.24]],"batl":[[1,6.4,7.56]],"ltp":0.0,"tv":0.0,"id":17293892}]}]}
{"op":"mcm","clk":"1005540102","pt":1580643232701,"mc":[{"id":"1.168224295","rc":[{"batl":[[0,1.68,29.58],[1,1.73,42.01],[2,1.74,26.04]],"ltp":0.0,"tv":0.0,"id":13010435},{"batb":[[1,5,45.31],[2,4.6,10.92]],"batl":[[2,6,11.96]],"ltp":0.0,"tv":0.0,"id":13010434},{"batb":[[1,23,3.21]],"ltp":0.0,"tv":0.0,"id":17293893},{"batl":[[1,6,12.04],[2,6.4,7.56]],"ltp":0.0,"tv":0.0,"id":17293892}]}]}
{"op":"mcm","clk":"1005542765","pt":1580643246278,"mc":[{"id":"1.168224295","rc":[{"batb":[[0,1.58,72.26],[1,1.56,32.65],[2,1.01,0.51]],"batl":[[0,1.73,42.01],[1,1.74,26.04],[2,1.74,0]],"ltp":0.0,"tv":0.0,"id":13010435},{"batb":[[0,5.1,22.83]],"batl":[[1,6,11.96],[2,6,0]],"ltp":0.0,"tv":0.0,"id":13010434},{"batb":[[0,23,3.21],[1,1.01,0.51],[2,1.01,0]],"ltp":0.0,"tv":0.0,"id":17293893},{"batb":[[0,5.2,9.24],[1,4.9,13.93],[2,1.01,0.51]],"batl":[[0,6,12.04],[1,6.4,7.56],[2,6.4,0]],"ltp":0.0,"tv":0.0,"id":17293892}]}]}
{"op":"mcm","clk":"1005542969","pt":1580643247290,"mc":[{"id":"1.168224295","rc":[{"batb":[[0,1.56,32.65],[1,1.01,0.51],[2,1.01,0]],"batl":[[0,1.74,26.04],[1,1.74,0]],"ltp":0.0,"tv":0.0,"id":13010435},{"batb":[[2,1.01,0.51]],"batl":[[0,6,11.96],[1,6,0]],"ltp":0.0,"tv":0.0,"id":13010434},{"batb":[[0,4.9,13.93],[1,1.01,0.51],[2,1.01,0]],"batl":[[1,6.4,0]],"ltp":0.0,"tv":0.0,"id":17293892}]}]}
{"op":"mcm","clk":"1005543339","pt":1580643249137,"mc":[{"id":"1.168224295","rc":[{"batb":[[1,1.55,137.32],[2,1.54,82.7]],"ltp":0.0,"tv":0.0,"id":13010435},{"batb":[[0,32,6.57],[1,30,14.51],[2,23,3.21]],"ltp":0.0,"tv":0.0,"id":17293893},{"batb":[[0,5.3,48.15],[1,5.2,30.37],[2,4.9,13.93]],"ltp":0.0,"tv":0.0,"id":17293892}]}]}
{"op":"mcm","clk":"1005543827","pt":1580643251820,"mc":[{"id":"1.168224295","rc":[{"batb":[[1,1.01,0.51],[2,1.54,0]],"ltp":0.0,"tv":0.0,"id":13010435},{"batb":[[0,23,3.21],[1,1.01,0.51],[2,23,0]],"ltp":0.0,"tv":0.0,"id":17293893},{"batb":[[0,4.9,13.93],[1,1.01,0.51],[2,4.9,0]],"ltp":0.0,"tv":0.0,"id":17293892}]}]}
{"op":"mcm","clk":"1005544549","pt":1580643255334,"mc":[{"id":"1.168224295","rc":[{"batb":[[0,1.59,94.77],[1,1.58,74.77],[2,1.56,32.65]],"ltp":0.0,"tv":0.0,"id":13010435},{"batb":[[0,5.1,44.74]],"ltp":0.0,"tv":0.0,"id":13010434},{"batb":[[0,46,8.33],[1,44,6.63],[2,23,3.21]],"ltp":0.0,"tv":0.0,"id":17293893},{"batb":[[0,5.5,25.57],[1,5.4,28.22],[2,4.9,13.93]],"ltp":0.0,"tv":0.0,"id":17293892}]}]}
{"op":"mcm","clk":"1005544710","pt":1580643256135,"mc":[{"id":"1.168224295","rc":[{"batb":[[0,1.56,32.65],[1,1.01,0.51],[2,1.56,0]],"ltp":0.0,"tv":0.0,"id":13010435},{"batb":[[0,5.1,22.83]],"ltp":0.0,"tv":0.0,"id":13010434},{"batb":[[0,23,3.21],[1,1.01,0.51],[2,23,0]],"ltp":0.0,"tv":0.0,"id":17293893},{"batb":[[0,4.9,13.93],[1,1.01,0.51],[2,4.9,0]],"ltp":0.0,"tv":0.0,"id":17293892}]}]}
{"op":"mcm","clk":"1005545284","pt":1580643259031,"mc":[{"id":"1.168224295","rc":[{"batb":[[1,1.55,137.32],[2,1.54,82.7]],"ltp":0.0,"tv":0.0,"id":13010435},{"batb":[[0,32,6.57],[1,30,14.51],[2,23,3.21]],"ltp":0.0,"tv":0.0,"id":17293893},{"batb":[[0,5.3,48.15],[1,5.2,30.37],[2,4.9,13.93]],"ltp":0.0,"tv":0.0,"id":17293892}]}]}
{"op":"mcm","clk":"1005547032","pt":1580643268556,"mc":[{"id":"1.168224295","rc":[{"batb":[[1,1.01,0.51],[2,1.54,0]],"ltp":0.0,"tv":0.0,"id":13010435}]}]}
{"op":"mcm","clk":"1005547711","pt":1580643272248,"mc":[{"id":"1.168224295","rc":[{"batb":[[0,1.65,26.52],[1,1.63,171.85],[2,1.62,68.17]],"batl":[[1,1.78,42.01],[2,1.84,21.79]],"ltp":0.0,"tv":0.0,"id":13010435},{"batb":[[2,4.9,14.01]],"batl":[[0,5.5,9.24],[1,5.8,12.9],[2,5.9,12.67]],"ltp":0.0,"tv":0.0,"id":13010434},{"batb":[[2,5,10.08]],"batl":[[0,5.7,13.38],[1,5.8,12.98],[2,6,12.04]],"ltp":0.0,"tv":0.0,"id":17293892}]}]}
{"op":"mcm","clk":"1005547771","pt":1580643272456,"mc":[{"id":"1.168224295","rc":[{"batb":[[1,5,31.86]],"ltp":0.0,"tv":0.0,"id":13010434},{"batl":[[2,6.2,7.56]],"ltp":0.0,"tv":0.0,"id":17293892}]}]}
{"op":"mcm","clk":"1005551203","pt":1580643290301,"mc":[{"id":"1.168224295","rc":[{"batb":[[0,1.63,66.38],[1,1.6,29.11],[2,1.01,0.51]],"batl":[[0,1.78,42.01],[1,1.84,21.79],[2,1.84,0]],"ltp":0.0,"tv":0.0,"id":13010435},{"batb":[[0,5,24.57],[1,4.9,14.01],[2,4.5,11.76]],"batl":[[1,5.9,12.67],[2,5.9,0]],"ltp":0.0,"tv":0.0,"id":13010434},{"batb":[[0,15,5.11],[1,1.01,0.51],[2,23,0]],"ltp":0.0,"tv":0.0,"id":17293893},{"batb":[[0,5.2,30.37],[1,5,10.08],[2,4.8,14.79]],"batl":[[0,5.8,12.98],[1,6.2,7.56],[2,6.2,0]],"ltp":0.0,"tv":0.0,"id":17293892}]}]}
{"op":"mcm","clk":"1005551328","pt":1580643291007,"mc":[{"id":"1.168224295","rc":[{"batb":[[0,1.6,29.11],[1,1.01,0.51],[2,1.01,0]],"batl":[[0,1.84,21.79],[1,1.84,0]],"ltp":0.0,"tv":0.0,"id":13010435},{"batb":[[2,1.01,0.51]],"batl":[[0,5.9,12.67],[1,5.9,0]],"ltp":0.0,"tv":0.0,"id":13010434},{"batb":[[1,4.8,14.79],[2,1.01,0.51]],"batl":[[1,6.2,0]],"ltp":0.0,"tv":0.0,"id":17293892}]}]}
{"op":"mcm","clk":"1005551615","pt":1580643292612,"mc":[{"id":"1.168224295","rc":[{"batb":[[1,1.59,117.77],[2,1.58,74.86]],"ltp":0.0,"tv":0.0,"id":13010435},{"batb":[[1,4.9,47.52]],"ltp":0.0,"tv":0.0,"id":13010434},{"batb":[[0,19,5.82],[1,18.5,10.27],[2,15,5.11]],"ltp":0.0,"tv":0.0,"id":17293893},{"batb":[[0,5.2,41.99],[1,5.1,31.83],[2,4.8,14.79]],"ltp":0.0,"tv":0.0,"id":17293892}]}]}
{"op":"mcm","clk":"1005553483","pt":1580643302231,"mc":[{"id":"1.168224295","rc":[{"batb":[[1,1.01,0.51],[2,1.58,0]],"ltp":0.0,"tv":0.0,"id":13010435},{"batb":[[1,4.9,14.01]],"ltp":0.0,"tv":0.0,"id":13010434},{"batb":[[0,15,5.11],[1,1.01,0.51],[2,15,0]],"ltp":0.0,"tv":0.0,"id":17293893},{"batb":[[0,5.2,30.37],[1,4.8,14.79],[2,1.01,0.51]],"ltp":0.0,"tv":0.0,"id":17293892}]}]}
{"op":"mcm","clk":"1005554027","pt":1580643305304,"mc":[{"id":"1.168224295","rc":[{"batb":[[0,1.71,100.86],[1,1.69,116.45],[2,1.6,29.11]],"ltp":0.0,"tv":0.0,"id":13010435},{"batb":[[1,4.9,47.52]],"ltp":0.0,"tv":0.0,"id":13010434},{"batb":[[0,19,5.82],[1,18.5,10.27],[2,15,5.11]],"ltp":0.0,"tv":0.0,"id":17293893},{"batb":[[0,5.2,41.99],[1,5.1,31.83],[2,4.8,14.79]],"ltp":0.0,"tv":0.0,"id":17293892}]}]}
{"op":"mcm","clk":"1005554218","pt":1580643306204,"mc":[{"id":"1.168224295","rc":[{"batb":[[0,1.73,22.19],[1,1.71,100.86],[2,1.7,59.65]],"batl":[[1,1.87,42.01],[2,2.02,16.6]],"ltp":0.0,"tv":0.0,"id":13010435},{"batb":[[1,4.9,33.51],[2,4.7,14.95]],"batl":[[0,5.4,9.24],[1,5.7,13.38],[2,5.8,13.06]],"ltp":0.0,"tv":0.0,"id":13010434},{"batl":[[0,22,4.88]],"ltp":0.0,"tv":0.0,"id":17293893},{"batb":[[2,4.9,10.08]],"batl":[[0,5.6,14.16],[1,5.7,13.61],[2,5.9,8.4]],"ltp":0.0,"tv":0.0,"id":17293892}]}]}
{"op":"mcm","clk":"1005557646","pt":1580643323149,"mc":[{"id":"1.168224295","rc":[{"batb":[[0,1.66,25.89],[1,1.01,0.51],[2,1.7,0]],"batl":[[0,2.02,16.6],[1,1.87,0],[2,2.02,0]],"ltp":0.0,"tv":0.0,"id":13010435},{"batb":[[0,4.7,14.95],[1,1.01,0.51],[2,4.7,0]],"batl":[[0,5.8,13.06],[1,5.7,0],[2,5.8,0]],"ltp":0.0,"tv":0.0,"id":13010434},{"batb":[[0,9.4,15.58],[1,1.01,0.51],[2,15,0]],"ltp":0.0,"tv":0.0,"id":17293893},{"batb":[[0,5.1,31.83],[1,4.7,15.34],[2,1.01,0.51]],"batl":[[0,5.7,13.61],[1,5.7,0],[2,5.9,0]],"ltp":0.0,"tv":0.0,"id":17293892}]}]}
{"op":"mcm","clk":"1005558270","pt":1580643326150,"mc":[{"id":"1.168224295","rc":[{"batb":[[0,1.65,26.28]],"batl":[[0,2,16.84]],"ltp":0.0,"tv":0.0,"id":13010435},{"batb":[[0,9.4,15.19]],"ltp":0.0,"tv":0.0,"id":17293893},{"batb":[[1,4.7,14.95]],"batl":[[0,5.7,13.22]],"ltp":0.0,"tv":0.0,"id":17293892}]}]}
{"op":"mcm","clk":"1005559223","pt":1580643330337,"mc":[{"id":"1.168224295","rc":[{"batb":[[0,4.8,34.7],[1,4.7,14.95],[2,1.01,0.51]],"ltp":0.0,"tv":0.0,"id":13010434}]}]}
{"op":"mcm","clk":"1005559541","pt":1580643331908,"mc":[{"id":"1.168224295","rc":[{"batb":[[0,1.65,91.54],[1,1.64,65.07],[2,1.01,0.51]],"ltp":0.0,"tv":0.0,"id":13010435},{"batb":[[0,4.8,55.45],[1,4.7,51.32]],"ltp":0.0,"tv":0.0,"id":13010434},{"batb":[[0,11,14.45],[1,10.5,32.54],[2,9.4,15.19]],"ltp":0.0,"tv":0.0,"id":17293893},{"batb":[[0,5.1,47.81],[1,5,33.22],[2,4.7,14.95]],"ltp":0.0,"tv":0.0,"id":17293892}]}]}
{"op":"mcm","clk":"1005561692","pt":1580643342253,"mc":[{"id":"1.168224295","rc":[{"batb":[[0,4.7,14.95],[1,1.01,0.51],[2,1.01,0]],"ltp":0.0,"tv":0.0,"id":13010434},{"batb":[[0,9.4,15.19],[1,1.01,0.51],[2,9.4,0]],"ltp":0.0,"tv":0.0,"id":17293893},{"batb":[[0,4.7,14.95],[1,1.01,0.51],[2,4.7,0]],"ltp":0.0,"tv":0.0,"id":17293892}]}]}
{"op":"mcm","clk":"1005562316","pt":1580643345242,"mc":[{"id":"1.168224295","rc":[{"batb":[[0,5,45.47],[1,4.9,33.17],[2,4.7,14.95]],"ltp":0.0,"tv":0.0,"id":13010434},{"batb":[[0,30,11.08],[1,29,7.88],[2,9.4,15.19]],"ltp":0.0,"tv":0.0,"id":17293893},{"batb":[[0,5.3,25.02],[1,5.2,30.71],[2,4.7,14.95]],"ltp":0.0,"tv":0.0,"id":17293892}]}]}
{"op":"mcm","clk":"1005562533","pt":1580643346254,"mc":[{"id":"1.168224295","rc":[{"batb":[[1,1.64,130.61],[2,1.61,28.95]],"batl":[[0,1.75,25.73],[1,1.81,42.01],[2,1.85,21.24]],"ltp":0.0,"tv":0.0,"id":13010435},{"batb":[[1,4.9,46.86],[2,4.8,14.48]],"batl":[[0,5.5,9.24],[1,5.7,13.14],[2,5.8,12.75]],"ltp":0.0,"tv":0.0,"id":13010434},{"batb":[[2,22,3.54]],"ltp":0.0,"tv":0.0,"id":17293893},{"batb":[[2,5,10.08]],"batl":[[1,5.8,12.98],[2,6,8.4]],"ltp":0.0,"tv":0.0,"id":17293892}]}]}
{"op":"mcm","clk":"1005565330","pt":1580643360380,"mc":[{"id":"1.168224295","rc":[{"batb":[[0,1.64,65.54],[1,1.61,28.95],[2,1.01,0.51]],"batl":[[0,1.81,42.01],[1,1.85,21.24],[2,1.85,0]],"ltp":0.0,"tv":0.0,"id":13010435},{"batb":[[0,4.9,33.17],[1,4.8,14.48],[2,4.5,11.76]],"batl":[[1,5.8,12.75],[2,5.8,0]],"ltp":0.0,"tv":0.0,"id":13010434},{"batb":[[0,14.5,5.59],[1,1.01,0.51],[2,22,0]],"ltp":0.0,"tv":0.0,"id":17293893},{"batb":[[0,5.2,20.91],[1,5,10.08],[2,4.8,14.71]],"batl":[[0,5.8,12.98],[1,6,8.4],[2,6,0]],"ltp":0.0,"tv":0.0,"id":17293892}]}]}
{"op":"mcm","clk":"1005565457","pt":1580643361082,"mc":[{"id":"1.168224295","rc":[{"batb":[[0,1.61,28.95],[1,1.01,0.51],[2,1.01,0]],"batl":[[0,1.85,21.24],[1,1.85,0]],"ltp":0.0,"tv":0.0,"id":13010435},{"batb":[[2,1.01,0.51]],"batl":[[0,5.8,12.75],[1,5.8,0]],"ltp":0.0,"tv":0.0,"id":13010434},{"batb":[[1,4.8,14.71],[2,1.01,0.51]],"batl":[[1,6,0]],"ltp":0.0,"tv":0.0,"id":17293892}]}]}
{"op":"mcm","clk":"1005565913","pt":1580643363265,"mc":[{"id":"1.168224295","rc":[{"batb":[[1,1.6,134.2],[2,1.59,73.16]],"ltp":0.0,"tv":0.0,"id":13010435},{"batb":[[0,4.9,50.17],[1,4.8,49.19]],"ltp":0.0,"tv":0.0,"id":13010434},{"batb":[[0,18,12.04],[1,17.5,11.34],[2,14.5,5.59]],"ltp":0.0,"tv":0.0,"id":17293893},{"batb":[[1,5.1,32.15],[2,4.8,14.71]],"ltp":0.0,"tv":0.0,"id":17293892}]}]}
{"op":"mcm","clk":"1005566708","pt":1580643367306,"mc":[{"id":"1.168224295","rc":[{"batb":[[1,1.01,0.51],[2,1.59,0]],"ltp":0.0,"tv":0.0,"id":13010435},{"batb":[[0,4.9,33.27],[1,4.8,14.48]],"ltp":0.0,"tv":0.0,"id":13010434},{"batb":[[0,14.5,5.59],[1,1.01,0.51],[2,14.5,0]],"ltp":0.0,"tv":0.0,"id":17293893}]}]}
{"op":"mcm","clk":"1005566996","pt":1580643368293,"mc":[{"id":"1.168224295","rc":[{"batb":[[0,5.7,2.28],[1,5.2,20.91],[2,5.1,32.15]],"ltp":0.0,"tv":0.0,"id":17293892}]}]}
{"op":"mcm","clk":"1005567425","pt":1580643370302,"mc":[{"id":"1.168224295","rc":[{"batb":[[0,1.66,101.67],[1,1.65,63.77],[2,1.61,28.95]],"ltp":0.0,"tv":0.0,"id":13010435},{"batb":[[0,5,39.6],[1,4.9,33.27],[2,4.8,14.48]],"ltp":0.0,"tv":0.0,"id":13010434},{"batb":[[0,27,5.97],[1,26,10.04],[2,14.5,5.59]],"ltp":0.0,"tv":0.0,"id":17293893},{"batb":[[1,5.2,49.21]],"ltp":0.0,"tv":0.0,"id":17293892}]}]}
{"op":"mcm","clk":"1005567741","pt":1580643371895,"mc":[{"id":"1.168224295","rc":[{"batb":[[0,1.61,28.95],[1,1.01,0.51],[2,1.61,0]],"ltp":0.0,"tv":0.0,"id":13010435},{"batb":[[0,4.9,33.27],[1,4.8,14.48],[2,1.01,0.51]],"ltp":0.0,"tv":0.0,"id":13010434},{"batb":[[0,14.5,5.59],[1,1.01,0.51],[2,14.5,0]],"ltp":0.0,"tv":0.0,"id":17293893},{"batb":[[1,5.2,20.91]],"ltp":0.0,"tv":0.0,"id":17293892}]}]}
{"op":"mcm","clk":"1005568419","pt":1580643375384,"mc":[{"id":"1.168224295","rc":[{"batb":[[1,1.6,134.2],[2,1.59,73.16]],"ltp":0.0,"tv":0.0,"id":13010435},{"batb":[[0,4.9,50.17],[1,4.8,49.19]],"ltp":0.0,"tv":0.0,"id":13010434},{"batb":[[0,18,12.04],[1,17.5,11.34],[2,14.5,5.59]],"ltp":0.0,"tv":0.0,"id":17293893}]}]}
{"op":"mcm","clk":"1005568624","pt":1580643376301,"mc":[{"id":"1.168224295","rc":[{"batb":[[0,5.2,20.91],[1,5.1,32.15],[2,4.8,14.71]],"ltp":0.0,"tv":0.0,"id":17293892}]}]}
{"op":"mcm","clk":"1005568744","pt":1580643376906,"mc":[{"id":"1.168224295","rc":[{"batb":[[0,4.8,14.48],[1,1.01,0.51],[2,1.01,0]],"ltp":0.0,"tv":0.0,"id":13010434},{"batb":[[0,14.5,5.59],[1,1.01,0.51],[2,14.5,0]],"ltp":0.0,"tv":0.0,"id":17293893},{"batb":[[1,4.8,14.71],[2,1.01,0.51]],"ltp":0.0,"tv":0.0,"id":17293892}]}]}
{"op":"mcm","clk":"1005569335","pt":1580643379989,"mc":[{"id":"1.168224295","rc":[{"batb":[[0,1.61,97.01]],"batl":[[0,1.76,42.01],[1,1.85,21.24]],"ltp":0.0,"tv":0.0,"id":13010435},{"batb":[[0,5.1,28.57],[1,5,31.94],[2,4.8,14.48]],"batl":[[0,5.5,9.24],[1,5.8,12.75]],"ltp":0.0,"tv":0.0,"id":13010434},{"batb":[[0,48,5.34],[1,46,6.18],[2,14.5,5.59]],"ltp":0.0,"tv":0.0,"id":17293893},{"batb":[[0,5.3,43.46],[1,5.2,30.44],[2,5,10.08]],"batl":[[1,6,8.4]],"ltp":0.0,"tv":0.0,"id":17293892}]}]}
{"op":"mcm","clk":"1005569539","pt":1580643381023,"mc":[{"id":"1.168224295","rc":[{"batl":[[0,1.7,28.33],[1,1.76,66.95]],"ltp":0.0,"tv":0.0,"id":13010435},{"batb":[[2,4.9,13.93]],"batl":[[2,5.9,12.51]],"ltp":0.0,"tv":0.0,"id":13010434},{"batb":[[2,21,4.26]],"ltp":0.0,"tv":0.0,"id":17293893},{"batl":[[1,5.9,12.67],[2,6,8.4]],"ltp":0.0,"tv":0.0,"id":17293892}]}]}
{"op":"mcm","clk":"1005572334","pt":1580643395204,"mc":[{"id":"1.168224295","rc":[{"batb":[[0,1.58,30.92],[1,1.01,0.51],[2,1.59,0]],"batl":[[0,1.76,24.94],[1,1.76,0]],"ltp":0.0,"tv":0.0,"id":13010435},{"batb":[[0,5,31.94],[1,4.9,13.93],[2,1.01,0.51]],"batl":[[0,5.9,12.51],[1,5.8,0],[2,5.9,0]],"ltp":0.0,"tv":0.0,"id":13010434},{"batb":[[0,21,4.26],[1,1.01,0.51],[2,21,0]],"ltp":0.0,"tv":0.0,"id":17293893},{"batb":[[0,5.2,30.44],[1,4.8,14.16],[2,1.01,0.51]],"batl":[[0,5.9,12.67],[1,5.9,0],[2,6,0]],"ltp":0.0,"tv":0.0,"id":17293892}]}]}
{"op":"mcm","clk":"1005572969","pt":1580643398142,"mc":[{"id":"1.168224295","rc":[{"batb":[[0,1.58,114.33],[1,1.57,76.53],[2,1.01,0.51]],"ltp":0.0,"tv":0.0,"id":13010435},{"batb":[[1,4.9,47.26]],"ltp":0.0,"tv":0.0,"id":13010434},{"batb":[[0,29,8.24],[1,28,8.56],[2,21,4.26]],"ltp":0.0,"tv":0.0,"id":17293893},{"batb":[[1,5.1,31.97],[2,4.9,14.01]],"batl":[[0,5.9,12.43]],"ltp":0.0,"tv":0.0,"id":17293892}]}]}
{"op":"mcm","clk":"1005576091","pt":1580643413304,"mc":[{"id":"1.168224295","rc":[{"trd":[[5.9,4.22]],"batl":[[0,5.9,10.32]],"ltp":5.9,"tv":4.21,"id":17293892}],"tv":4.21}]}
{"op":"mcm","clk":"1005576822","pt":1580643417231,"mc":[{"id":"1.168224295","rc":[{"batb":[[1,4.9,13.93]],"ltp":0.0,"tv":0.0,"id":13010434},{"batb":[[0,21,4.26],[1,1.01,0.51],[2,21,0]],"ltp":0.0,"tv":0.0,"id":17293893},{"batb":[[0,4.9,14.01],[1,1.01,0.51],[2,4.9,0]],"ltp":5.9,"tv":4.21,"id":17293892}]}]}
{"op":"mcm","clk":"1005577430","pt":1580643420328,"mc":[{"id":"1.168224295","rc":[{"batb":[[0,5.1,41.9],[1,5,31.94],[2,4.9,13.93]],"ltp":0.0,"tv":0.0,"id":13010434},{"batb":[[0,70,7.89],[1,21,4.26],[2,1.01,0.51]],"ltp":0.0,"tv":0.0,"id":17293893},{"batb":[[0,5.4,35.16],[1,5.3,29.28],[2,4.9,14.01]],"ltp":5.9,"tv":4.21,"id":17293892}]}]}
{"op":"mcm","clk":"1005577551","pt":1580643421028,"mc":[{"id":"1.168224295","rc":[{"batb":[[2,1.54,34.31]],"batl":[[0,1.66,30.53],[1,1.69,28.64]],"ltp":0.0,"tv":0.0,"id":13010435},{"batb":[[1,5,45],[2,4.9,13.69]],"batl":[[1,6,11.96]],"ltp":0.0,"tv":0.0,"id":13010434},{"batb":[[1,30,2.4]],"ltp":0.0,"tv":0.0,"id":17293893},{"batb":[[2,5.1,12.9]],"batl":[[1,6.2,11.09]],"ltp":5.9,"tv":4.21,"id":17293892}]}]}
{"op":"mcm","clk":"1005577761","pt":1580643422053,"mc":[{"id":"1.168224295","rc":[{"batb":[[1,1.57,149.63]],"batl":[[2,1.71,42.01]],"ltp":0.0,"tv":0.0,"id":13010435},{"batl":[[0,5.6,8.4],[1,5.9,12.51],[2,6,11.96]],"ltp":0.0,"tv":0.0,"id":13010434},{"batb":[[2,5.2,9.24]],"batl":[[1,6.2,18.66]],"ltp":5.9,"tv":4.21,"id":17293892}]}]}
{"op":"mcm","clk":"1005581847","pt":1580643441139,"mc":[{"id":"1.168224295","rc":[{"batb":[[0,1.54,34.31],[1,1.01,0.51],[2,1.54,0]],"batl":[[0,1.69,28.64],[1,1.69,0],[2,1.71,0]],"ltp":0.0,"tv":0.0,"id":13010435},{"batb":[[0,5.1,24.85],[1,5,31.94]],"batl":[[0,6,11.96],[1,5.9,0],[2,6,0]],"ltp":0.0,"tv":0.0,"id":13010434},{"batb":[[0,30,2.4],[1,1.01,0.51],[2,1.01,0]],"ltp":0.0,"tv":0.0,"id":17293893},{"batb":[[0,5.3,29.28],[1,4.9,13.69],[2,1.01,0.51]],"batl":[[0,6.2,11.09],[1,6.2,0]],"ltp":5.9,"tv":4.21,"id":17293892}]}]}
{"op":"mcm","clk":"1005582438","pt":1580643444304,"mc":[{"id":"1.168224295","rc":[{"batb":[[0,1.55,95.97],[1,1.54,116.81],[2,1.01,0.51]],"ltp":0.0,"tv":0.0,"id":13010435},{"batb":[[1,5.2,30.62],[2,4.9,13.69]],"ltp":5.9,"tv":4.21,"id":17293892}]}]}
{"op":"mcm","clk":"1005583796","pt":1580643451313,"mc":[{"id":"1.168224295","rc":[{"batb":[[0,1.54,34.31],[1,1.01,0.51],[2,1.01,0]],"ltp":0.0,"tv":0.0,"id":13010435}]}]}
{"op":"mcm","clk":"1005584434","pt":1580643454407,"mc":[{"id":"1.168224295","rc":[{"batb":[[0,1.6,79.35],[1,1.59,72.95],[2,1.54,34.31]],"ltp":0.0,"tv":0.0,"id":13010435}]}]}
{"op":"mcm","clk":"1005584571","pt":1580643455098,"mc":[{"id":"1.168224295","rc":[{"batb":[[0,1.6,108.62],[2,1.56,31.94]],"batl":[[1,1.71,27.22]],"ltp":0.0,"tv":0.0,"id":13010435},{"batl":[[0,5.7,13.14],[1,5.9,12.51]],"ltp":0.0,"tv":0.0,"id":13010434},{"batl":[[0,5.8,13.14],[1,6,11.96]],"ltp":5.9,"tv":4.21,"id":17293892}]}]}
{"op":"mcm","clk":"1005584760","pt":1580643456115,"mc":[{"id":"1.168224295","rc":[{"batb":[[2,1.58,72.26]],"batl":[[1,1.71,69.23]],"ltp":0.0,"tv":0.0,"id":13010435},{"batl":[[0,5.6,8.4],[1,5.7,13.14],[2,5.9,12.51]],"ltp":0.0,"tv":0.0,"id":13010434},{"batb":[[2,5.1,10.08]],"batl":[[2,6.2,7.56]],"ltp":5.9,"tv":4.21,"id":17293892}]}]}
{"op":"mcm","clk":"1005585388","pt":1580643459088,"mc":[{"id":"1.168224295","rc":[{"batb":[[0,1.56,31.94],[1,1.01,0.51],[2,1.58,0]],"batl":[[0,1.71,27.22],[1,1.71,0]],"ltp":0.0,"tv":0.0,"id":13010435},{"batb":[[0,5,31.94],[1,4.8,14.32],[2,1.01,0.51]],"batl":[[0,5.9,12.51],[1,5.7,0],[2,5.9,0]],"ltp":0.0,"tv":0.0,"id":13010434},{"batb":[[0,5.2,30.62],[1,4.9,13.69],[2,1.01,0.51]],"batl":[[0,6,11.96],[1,6,0],[2,6.2,0]],"ltp":5.9,"tv":4.21,"id":17293892}]}]}
{"op":"mcm","clk":"1005585868","pt":1580643461438,"mc":[{"id":"1.168224295","rc":[{"batb":[[0,1.57,96.53],[1,1.56,110.43],[2,1.01,0.51]],"ltp":0.0,"tv":0.0,"id":13010435},{"batb":[[0,5,41.5],[1,4.9,33.23],[2,4.8,14.32]],"ltp":0.0,"tv":0.0,"id":13010434},{"batb":[[0,55,10.24],[1,50,2.31],[2,30,2.4]],"ltp":0.0,"tv":0.0,"id":17293893},{"batb":[[1,5.1,32],[2,4.9,13.69]],"ltp":5.9,"tv":4.21,"id":17293892}]}]}
{"op":"mcm","clk":"1005586612","pt":1580643464948,"mc":[{"id":"1.168224295","rc":[{"batb":[[0,1.56,31.94],[1,1.01,0.51],[2,1.01,0]],"ltp":0.0,"tv":0.0,"id":13010435}]}]}
{"op":"mcm","clk":"1005587096","pt":1580643467371,"mc":[{"id":"1.168224295","rc":[{"batb":[[0,1.62,68.57],[1,1.61,69.6],[2,1.56,31.94]],"ltp":0.0,"tv":0.0,"id":13010435}]}]}
{"op":"mcm","clk":"1005587285","pt":1580643468375,"mc":[{"id":"1.168224295","rc":[{"batb":[[0,1.63,27.77],[1,1.62,68.57],[2,1.61,69.6]],"batl":[[1,1.73,42.01],[2,1.74,25.97]],"ltp":0.0,"tv":0.0,"id":13010435},{"batl":[[0,5.6,8.4],[1,5.8,13.06],[2,5.9,12.51]],"ltp":0.0,"tv":0.0,"id":13010434},{"batb":[[2,5,10.08]],"batl":[[0,5.6,13.69],[1,5.8,12.75],[2,6,20.36]],"ltp":5.9,"tv":4.21,"id":17293892}]}]}
{"op":"mcm","clk":"1005587296","pt":1580643468477,"mc":[{"id":"1.168224295","rc":[{"batl":[[2,5.9,0]],"ltp":0.0,"tv":0.0,"id":13010434},{"batl":[[2,6,8.4]],"ltp":5.9,"tv":4.21,"id":17293892}]}]}
{"op":"mcm","clk":"1005588416","pt":1580643474271,"mc":[{"id":"1.168224295","rc":[{"batb":[[0,1.59,100.4],[1,1.01,0.51],[2,1.61,0]],"batl":[[0,1.73,42.01],[1,1.74,25.97],[2,1.74,0]],"ltp":0.0,"tv":0.0,"id":13010435},{"batb":[[0,5,31.94]],"ltp":0.0,"tv":0.0,"id":13010434},{"batb":[[0,1.01,0.51],[1,50,0],[2,30,0]],"ltp":0.0,"tv":0.0,"id":17293893},{"batb":[[0,5.1,32],[1,5,10.08],[2,4.7,15.19]],"batl":[[0,5.8,12.75],[1,6,8.4],[2,6,0]],"ltp":5.9,"tv":4.21,"id":17293892}]}]}
{"op":"mcm","clk":"1005588606","pt":1580643475178,"mc":[{"id":"1.168224295","rc":[{"batb":[[0,1.59,29.82]],"batl":[[0,1.74,25.97],[1,1.74,0]],"ltp":0.0,"tv":0.0,"id":13010435},{"batl":[[0,5.8,13.06],[1,5.8,0]],"ltp":0.0,"tv":0.0,"id":13010434},{"batb":[[1,4.7,15.19],[2,1.01,0.51]],"batl":[[1,6,0]],"ltp":5.9,"tv":4.21,"id":17293892}]}]}
{"op":"mcm","clk":"1005589024","pt":1580643477260,"mc":[{"id":"1.168224295","rc":[{"batb":[[0,1.59,125.37],[1,1.58,74.76],[2,1.01,0.51]],"ltp":0.0,"tv":0.0,"id":13010435},{"batb":[[1,5,33.45],[2,4.7,15.19]],"ltp":5.9,"tv":4.21,"id":17293892}]}]}
{"op":"mcm","clk":"1005589979","pt":1580643481868,"mc":[{"id":"1.168224295","rc":[{"batb":[[1,4.8,14.32],[2,1.01,0.51]],"ltp":0.0,"tv":0.0,"id":13010434},{"batb":[[0,4.7,15.19],[1,1.01,0.51],[2,4.7,0]],"ltp":5.9,"tv":4.21,"id":17293892}]}]}
{"op":"mcm","clk":"1005590582","pt":1580643484700,"mc":[{"id":"1.168224295","rc":[{"batb":[[0,5.1,32.83],[1,5,31.94],[2,4.8,14.32]],"ltp":0.0,"tv":0.0,"id":13010434},{"batb":[[0,65,3.57],[1,60,7.45],[2,1.01,0.51]],"ltp":0.0,"tv":0.0,"id":17293893},{"batb":[[0,5.3,48.18],[1,5.2,30.37],[2,4.7,15.19]],"ltp":5.9,"tv":4.21,"id":17293892}]}]}
{"op":"mcm","clk":"1005590953","pt":1580643486342,"mc":[{"id":"1.168224295","rc":[{"batb":[[1,1.58,147.02],[2,1.55,32.97]],"batl":[[0,1.68,29.19],[1,1.7,27.77],[2,1.71,42.01]],"ltp":0.0,"tv":0.0,"id":13010435},{"batb":[[2,4.9,14.01]],"batl":[[0,5.6,8.4],[1,5.8,13.06],[2,5.9,12.2]],"ltp":0.0,"tv":0.0,"id":13010434},{"batb":[[2,30,2.99]],"ltp":0.0,"tv":0.0,"id":17293893},{"batb":[[2,5.1,10.08]],"batl":[[1,6.2,19.13]],"ltp":5.9,"tv":4.21,"id":17293892}]}]}
{"op":"mcm","clk":"1005592018","pt":1580643491329,"mc":[{"id":"1.168224295","rc":[{"batb":[[0,1.59,29.82],[1,1.58,72.26]],"ltp":0.0,"tv":0.0,"id":13010435},{"batb":[[0,5,31.94],[1,4.9,14.01],[2,4.6,10.92]],"ltp":0.0,"tv":0.0,"id":13010434},{"batb":[[0,30,2.99],[1,1.01,0.51],[2,30,0]],"ltp":0.0,"tv":0.0,"id":17293893},{"batb":[[0,5.2,30.37],[1,5.1,10.08],[2,5,13.3]],"ltp":5.9,"tv":4.21,"id":17293892}]}]}
{"op":"mcm","clk":"1005592124","pt":1580643491754,"mc":[{"id":"1.168224295","rc":[{"batb":[[0,1.58,72.26],[1,1.55,32.97],[2,1.01,0.51]],"batl":[[0,1.7,27.77],[1,1.71,42.01],[2,1.71,0]],"ltp":0.0,"tv":0.0,"id":13010435},{"batl":[[1,5.9,12.2],[2,5.9,0]],"ltp":0.0,"tv":0.0,"id":13010434},{"batb":[[2,4.9,13.93]],"batl":[[0,6.2,19.13],[1,6.2,0]],"ltp":5.9,"tv":4.21,"id":17293892}]}]}
{"op":"mcm","clk":"1005592453","pt":1580643493230,"mc":[{"id":"1.168224295","rc":[{"batb":[[0,1.55,32.97],[1,1.01,0.51],[2,1.01,0]],"batl":[[1,1.71,0]],"ltp":0.0,"tv":0.0,"id":13010435},{"batb":[[2,1.01,0.51]],"batl":[[0,5.9,12.2],[1,5.9,0]],"ltp":0.0,"tv":0.0,"id":13010434},{"batb":[[1,4.9,13.93],[2,1.01,0.51]],"batl":[[0,6.2,11.57]],"ltp":5.9,"tv":4.21,"id":17293892}]}]}
{"op":"mcm","clk":"1005592632","pt":1580643494046,"mc":[{"id":"1.168224295","rc":[{"batb":[[0,1.56,108.19],[1,1.55,113.48],[2,1.01,0.51]],"ltp":0.0,"tv":0.0,"id":13010435},{"batb":[[0,5,49],[1,4.9,47.12]],"ltp":0.0,"tv":0.0,"id":13010434},{"batb":[[0,55,10.01],[1,50,2.57],[2,30,2.99]],"ltp":0.0,"tv":0.0,"id":17293893},{"batb":[[0,5.2,46.28],[1,5.1,31.76],[2,4.9,13.93]],"ltp":5.9,"tv":4.21,"id":17293892}]}]}
{"op":"mcm","clk":"1005593027","pt":1580643495957,"mc":[{"id":"1.168224295","rc":[{"batb":[[0,1.55,32.97],[1,1.01,0.51],[2,1.01,0]],"ltp":0.0,"tv":0.0,"id":13010435},{"batb":[[0,5,31.94],[1,4.9,14.01]],"ltp":0.0,"tv":0.0,"id":13010434},{"batb":[[0,30,2.99],[1,1.01,0.51],[2,30,0]],"ltp":0.0,"tv":0.0,"id":17293893},{"batb":[[0,4.9,13.93],[1,1.01,0.51],[2,4.9,0]],"ltp":5.9,"tv":4.21,"id":17293892}]}]}
{"op":"mcm","clk":"1005594127","pt":1580643500837,"mc":[{"id":"1.168224295","rc":[{"batb":[[0,1.56,108.19],[1,1.55,113.48],[2,1.01,0.51]],"ltp":0.0,"tv":0.0,"id":13010435},{"batb":[[0,5,49],[1,4.9,47.12]],"ltp":0.0,"tv":0.0,"id":13010434},{"batb":[[0,55,10.01],[1,50,2.57],[2,30,2.99]],"ltp":0.0,"tv":0.0,"id":17293893},{"batb":[[0,5.2,46.28],[1,5.1,31.76],[2,4.9,13.93]],"ltp":5.9,"tv":4.21,"id":17293892}]}]}
{"op":"mcm","clk":"1005595998","pt":1580643509045,"mc":[{"id":"1.168224295","rc":[{"batb":[[0,1.55,32.97],[1,1.01,0.51],[2,1.01,0]],"ltp":0.0,"tv":0.0,"id":13010435},{"batb":[[0,4.9,14.01],[1,1.01,0.51],[2,1.01,0]],"ltp":0.0,"tv":0.0,"id":13010434},{"batb":[[0,30,2.99],[1,1.01,0.51],[2,30,0]],"ltp":0.0,"tv":0.0,"id":17293893},{"batb":[[0,4.9,13.93],[1,1.01,0.51],[2,4.9,0]],"ltp":5.9,"tv":4.21,"id":17293892}]}]}
{"op":"mcm","clk":"1005596691","pt":1580643512365,"mc":[{"id":"1.168224295","rc":[{"batb":[[0,1.56,182.97],[1,1.55,113.48],[2,1.51,37.06]],"batl":[[0,1.63,32.18],[1,1.67,29.74],[2,1.69,42.01]],"ltp":0.0,"tv":0.0,"id":13010435},{"batb":[[0,5.2,27.41],[1,5.1,43.22],[2,5,13.45]],"batl":[[0,5.6,8.4],[1,5.9,12.2],[2,6.2,11.33]],"ltp":0.0,"tv":0.0,"id":13010434},{"batb":[[0,80,3.65],[1,75,5.16],[2,30,2.99]],"ltp":0.0,"tv":0.0,"id":17293893},{"batb":[[0,5.5,39.34],[1,5.4,28.02],[2,5.3,9.24]],"batl":[[1,6.4,17.87]],"ltp":5.9,"tv":4.21,"id":17293892}]}]}
{"op":"mcm","clk":"1005596834","pt":1580643512956,"mc":[{"id":"1.168224295","rc":[{"batb":[[2,1.01,0.51]],"ltp":0.0,"tv":0.0,"id":17293893}]}]}
{"op":"mcm","clk":"1005597498","pt":1580643516197,"mc":[{"id":"1.168224295","rc":[{"batb":[[0,1.56,74.78],[1,1.51,37.06],[2,1.01,0.51]],"batl":[[0,1.67,29.74],[1,1.69,42.01],[2,1.69,0]],"ltp":0.0,"tv":0.0,"id":13010435},{"batb":[[0,5.1,30.55],[1,5,13.45],[2,4.6,10.92]],"batl":[[1,6.2,11.33],[2,6.2,0]],"ltp":0.0,"tv":0.0,"id":13010434},{"batb":[[0,1.01,0.51],[1,75,0],[2,1.01,0]],"ltp":0.0,"tv":0.0,"id":17293893},{"batb":[[0,5.4,28.02],[1,5.3,9.24],[2,5.1,12.9]],"batl":[[0,6.4,17.87],[1,6.4,0]],"ltp":5.9,"tv":4.21,"id":17293892}]}]}
{"op":"mcm","clk":"1005597730","pt":1580643517177,"mc":[{"id":"1.168224295","rc":[{"batb":[[0,1.51,37.06],[1,1.01,0.51],[2,1.01,0]],"batl":[[1,1.69,0]],"ltp":0.0,"tv":0.0,"id":13010435},{"batb":[[2,1.01,0.51]],"batl":[[0,6.2,11.33],[1,6.2,0]],"ltp":0.0,"tv":0.0,"id":13010434},{"batb":[[1,5.1,12.9],[2,1.01,0.51]],"batl":[[0,6.4,10.31]],"ltp":5.9,"tv":4.21,"id":17293892}]}]}
{"op":"mcm","clk":"1005598140","pt":1580643519002,"mc":[{"id":"1.168224295","rc":[{"batb":[[0,1.53,87.12],[1,1.52,86.81],[2,1.51,37.06]],"ltp":0.0,"tv":0.0,"id":13010435},{"batb":[[0,5.1,39.51],[1,5,45.21]],"ltp":0.0,"tv":0.0,"id":13010434},{"batb":[[0,65,2.48],[1,60,8.63],[2,1.01,0.51]],"ltp":0.0,"tv":0.0,"id":17293893},{"batb":[[1,5.3,29.32],[2,5.1,12.9]],"ltp":5.9,"tv":4.21,"id":17293892}]}]}
{"op":"mcm","clk":"1005598920","pt":1580643522593,"mc":[{"id":"1.168224295","rc":[{"batb":[[0,1.51,37.06],[1,1.01,0.51],[2,1.51,0]],"ltp":0.0,"tv":0.0,"id":13010435},{"batb":[[0,5.1,30.55],[1,5,13.45]],"ltp":0.0,"tv":0.0,"id":13010434},{"batb":[[0,1.01,0.51],[1,60,0],[2,1.01,0]],"ltp":0.0,"tv":0.0,"id":17293893},{"batb":[[0,5.1,12.9],[1,1.01,0.51],[2,5.1,0]],"ltp":5.9,"tv":4.21,"id":17293892}]}]}
{"op":"mcm","clk":"1005599875","pt":1580643526718,"mc":[{"id":"1.168224295","rc":[{"batb":[[0,1.53,87.12],[1,1.52,86.81],[2,1.51,37.06]],"ltp":0.0,"tv":0.0,"id":13010435},{"batb":[[0,5.1,39.51],[1,5,45.21]],"ltp":0.0,"tv":0.0,"id":13010434},{"batb":[[0,65,2.48],[1,60,8.63],[2,1.01,0.51]],"ltp":0.0,"tv":0.0,"id":17293893},{"batb":[[0,5.4,32.63],[1,5.3,29.32],[2,5.1,12.9]],"ltp":5.9,"tv":4.21,"id":17293892}]}]}
{"op":"mcm","clk":"1005601753","pt":1580643535202,"mc":[{"id":"1.168224295","rc":[{"batb":[[0,5,13.45],[1,1.01,0.51],[2,1.01,0]],"ltp":0.0,"tv":0.0,"id":13010434},{"batb":[[0,1.01,0.51],[1,60,0],[2,1.01,0]],"ltp":0.0,"tv":0.0,"id":17293893},{"batb":[[0,5.1,12.9],[1,1.01,0.51],[2,5.1,0]],"ltp":5.9,"tv":4.21,"id":17293892}]}]}
{"op":"mcm","clk":"1005602405","pt":1580643538402,"mc":[{"id":"1.168224295","rc":[{"batb":[[0,1.54,77.3],[1,1.53,87.12],[2,1.52,86.81]],"batl":[[0,1.58,36.12],[1,1.63,32.26],[2,1.66,42.01]],"ltp":0.0,"tv":0.0,"id":13010435},{"batb":[[0,5.3,38.34],[1,5.2,29.25],[2,5.1,12.75]],"batl":[[0,5.6,8.4],[1,6.2,11.33],[2,6.4,10.31]],"ltp":0.0,"tv":0.0,"id":13010434},{"batb":[[0,5.7,36.65],[1,5.6,25.87],[2,5.5,10.7]],"batl":[[1,6.6,6.72],[2,7,17.39]],"ltp":5.9,"tv":4.21,"id":17293892}]}]}
{"op":"mcm","clk":"1005603656","pt":1580643544406,"mc":[{"id":"1.168224295","rc":[{"batb":[[1,1.51,37.06],[2,1.45,43.35]],"ltp":0.0,"tv":0.0,"id":13010435},{"batb":[[0,5.3,11.8]],"ltp":0.0,"tv":0.0,"id":13010434},{"batb":[[0,5.6,25.87],[1,5.5,10.7],[2,5.4,9.24]],"ltp":5.9,"tv":4.21,"id":17293892}]}]}
{"op":"mcm","clk":"1005603798","pt":1580643545118,"mc":[{"id":"1.168224295","rc":[{"batb":[[0,1.45,43.35],[1,1.01,0.51],[2,1.45,0]],"batl":[[0,1.63,32.26],[1,1.63,0],[2,1.66,0]],"ltp":0.0,"tv":0.0,"id":13010435},{"batb":[[0,5.2,29.25],[1,5.1,12.75],[2,1.01,0.51]],"batl":[[0,6.4,10.31],[1,6.2,0],[2,6.4,0]],"ltp":0.0,"tv":0.0,"id":13010434},{"batb":[[1,5.3,11.88],[2,1.01,0.51]],"batl":[[0,7,17.39],[1,6.6,0],[2,7,0]],"ltp":5.9,"tv":4.21,"id":17293892}]}]}
{"op":"mcm","clk":"1005604463","pt":1580643548205,"mc":[{"id":"1.168224295","rc":[{"batb":[[0,1.49,106.97],[1,1.48,96.84],[2,1.45,43.35]],"ltp":0.0,"tv":0.0,"id":13010435},{"batb":[[1,5.1,43.21]],"ltp":0.0,"tv":0.0,"id":13010434},{"batb":[[1,5.5,27.11],[2,5.3,11.88]],"ltp":5.9,"tv":4.21,"id":17293892}]}]}
{"op":"mcm","clk":"1005604666","pt":1580643549228,"mc":[{"id":"1.168224295","rc":[{"batb":[[0,1.45,43.35],[1,1.01,0.51],[2,1.45,0]],"ltp":0.0,"tv":0.0,"id":13010435},{"batb":[[1,5.1,12.75]],"ltp":0.0,"tv":0.0,"id":13010434},{"batb":[[0,5.3,11.88],[1,1.01,0.51],[2,5.3,0]],"ltp":5.9,"tv":4.21,"id":17293892}]}]}
{"op":"mcm","clk":"1005605358","pt":1580643552213,"mc":[{"id":"1.168224295","rc":[{"batb":[[0,1.52,102.29],[1,1.51,89.23],[2,1.45,43.35]],"ltp":0.0,"tv":0.0,"id":13010435},{"batb":[[0,5.3,33.15],[1,5.2,29.25],[2,5.1,12.75]],"ltp":0.0,"tv":0.0,"id":13010434},{"batb":[[0,5.8,23.67],[1,5.7,25.06],[2,5.3,11.88]],"ltp":5.9,"tv":4.21,"id":17293892}]}]}
{"op":"mcm","clk":"1005605563","pt":1580643553140,"mc":[{"id":"1.168224295","rc":[{"batb":[[0,1.45,43.35],[1,1.01,0.51],[2,1.45,0]],"ltp":0.0,"tv":0.0,"id":13010435},{"batb":[[0,5.2,29.25],[1,5.1,12.75],[2,1.01,0.51]],"ltp":0.0,"tv":0.0,"id":13010434},{"batb":[[0,5.3,11.88],[1,1.01,0.51],[2,5.3,0]],"ltp":5.9,"tv":4.21,"id":17293892}]}]}
{"op":"mcm","clk":"1005606013","pt":1580643555379,"mc":[{"id":"1.168224295","rc":[{"batb":[[0,1.49,106.39],[1,1.48,96.82],[2,1.45,43.35]],"ltp":0.0,"tv":0.0,"id":13010435},{"batb":[[1,5.1,43.21]],"ltp":0.0,"tv":0.0,"id":13010434},{"batb":[[0,5.6,24.98],[1,5.5,27.12],[2,5.3,11.88]],"ltp":5.9,"tv":4.21,"id":17293892}]}]}
{"op":"mcm","clk":"1005606454","pt":1580643557295,"mc":[{"id":"1.168224295","rc":[{"batb":[[0,5.1,12.75],[1,1.01,0.51],[2,1.01,0]],"ltp":0.0,"tv":0.0,"id":13010434},{"batb":[[0,5.3,11.88],[1,1.01,0.51],[2,5.3,0]],"ltp":5.9,"tv":4.21,"id":17293892}]}]}
{"op":"mcm","clk":"1005607063","pt":1580643560325,"mc":[{"id":"1.168224295","rc":[{"batb":[[0,5.4,31.86],[1,5.3,27.93],[2,5.1,12.75]],"ltp":0.0,"tv":0.0,"id":13010434},{"batb":[[0,6,19.83],[1,5.9,23.27],[2,5.3,11.88]],"ltp":5.9,"tv":4.21,"id":17293892}]}]}
{"op":"mcm","clk":"1005607178","pt":1580643560932,"mc":[{"id":"1.168224295","rc":[{"batl":[[0,1.52,42.25],[1,1.56,38.24]],"ltp":0.0,"tv":0.0,"id":13010435},{"batb":[[0,5.5,10.7],[1,5.4,31.86],[2,5.3,39.5]],"batl":[[1,6.8,19.2]],"ltp":0.0,"tv":0.0,"id":13010434},{"batb":[[2,5.8,18.65]],"batl":[[1,7.2,16.21]],"ltp":5.9,"tv":4.21,"id":17293892}]}]}
{"op":"mcm","clk":"1005607411","pt":1580643562207,"mc":[{"id":"1.168224295","rc":[{"batb":[[0,1.5,84.02],[1,1.49,106.39],[2,1.48,96.82]],"batl":[[2,1.62,42.01]],"ltp":0.0,"tv":0.0,"id":13010435},{"batl":[[0,5.7,8.4],[1,6.4,10.31],[2,6.8,19.2]],"ltp":0.0,"tv":0.0,"id":13010434},{"batl":[[0,7,24.11]],"ltp":5.9,"tv":4.21,"id":17293892}]}]}
{"op":"mcm","clk":"1005612600","pt":1580643587485,"mc":[{"id":"1.168224295","rc":[{"batb":[[0,6,31.1]],"ltp":5.9,"tv":4.21,"id":17293892}]}]}
{"op":"mcm","clk":"1005613325","pt":1580643591000,"mc":[{"id":"1.168224295","rc":[{"batl":[[0,7,435.24]],"ltp":5.9,"tv":4.21,"id":17293892}]}]}
{"op":"mcm","clk":"1005621639","pt":1580643632535,"mc":[{"id":"1.168224295","rc":[{"batl":[[0,7,24.11]],"ltp":5.9,"tv":4.21,"id":17293892}]}]}
{"op":"mcm","clk":"1005625082","pt":1580643650252,"mc":[{"id":"1.168224295","rc":[{"batb":[[1,1.43,45.95],[2,1.01,0.51]],"batl":[[0,1.56,38.24],[1,1.62,42.01],[2,1.62,0]],"ltp":0.0,"tv":0.0,"id":13010435},{"batb":[[0,5.3,39.5],[1,4.6,10.92],[2,1.01,0.51]],"batl":[[1,6.8,19.2],[2,6.8,0]],"ltp":0.0,"tv":0.0,"id":13010434},{"batb":[[0,5.5,19.86],[1,1.01,0.51],[2,5.8,0]],"batl":[[0,7,6.72]],"ltp":5.9,"tv":4.21,"id":17293892}]}]}
{"op":"mcm","clk":"1005625279","pt":1580643651265,"mc":[{"id":"1.168224295","rc":[{"batb":[[0,1.43,45.95],[1,1.01,0.51],[2,1.01,0]],"batl":[[1,1.62,0]],"ltp":0.0,"tv":0.0,"id":13010435},{"batb":[[1,1.01,0.51],[2,1.01,0]],"batl":[[0,6.8,19.2],[1,6.8,0]],"ltp":0.0,"tv":0.0,"id":13010434},{"batb":[[0,5.5,10.62]],"batl":[[0,7.2,16.21],[1,7.2,0]],"ltp":5.9,"tv":4.21,"id":17293892}]}]}
{"op":"mcm","clk":"1005625636","pt":1580643653349,"mc":[{"id":"1.168224295","rc":[{"batb":[[0,1.47,166.08],[1,1.46,103.02],[2,1.43,45.95]],"ltp":0.0,"tv":0.0,"id":13010435},{"batb":[[1,5.2,29.18],[2,1.01,0.51]],"ltp":0.0,"tv":0.0,"id":13010434},{"batb":[[0,5.8,19.54],[1,5.7,25.29],[2,5.5,10.62]],"ltp":5.9,"tv":4.21,"id":17293892}]}]}
{"op":"mcm","clk":"1005627628","pt":1580643663325,"mc":[{"id":"1.168224295","rc":[{"batb":[[0,1.43,45.95],[1,1.01,0.51],[2,1.43,0]],"ltp":0.0,"tv":0.0,"id":13010435},{"batb":[[1,1.01,0.51],[2,1.01,0]],"ltp":0.0,"tv":0.0,"id":13010434},{"batb":[[0,5.5,10.62],[1,1.01,0.51],[2,5.5,0]],"ltp":5.9,"tv":4.21,"id":17293892}]}]}
{"op":"mcm","clk":"1005628480","pt":1580643667247,"mc":[{"id":"1.168224295","rc":[{"batb":[[0,1.47,166.08],[1,1.46,103.02],[2,1.43,45.95]],"batl":[[0,1.5,44.61],[1,1.54,40.29]],"ltp":0.0,"tv":0.0,"id":13010435},{"batb":[[0,5.6,10.31],[1,5.4,54.74],[2,5.3,27.93]],"batl":[[0,6.8,18.57]],"ltp":0.0,"tv":0.0,"id":13010434},{"batb":[[0,6,76.85],[1,5.9,22.88],[2,5.7,19.83]],"batl":[[1,7.6,15.26]],"ltp":5.9,"tv":4.21,"id":17293892}]}]}
{"op":"mcm","clk":"1005628684","pt":1580643668250,"mc":[{"id":"1.168224295","rc":[{"batb":[[0,1.49,85.7],[1,1.47,166.08],[2,1.46,103.02]],"batl":[[2,1.6,42.01]],"ltp":0.0,"tv":0.0,"id":13010435},{"batl":[[0,5.7,8.4],[1,6.8,18.57]],"ltp":0.0,"tv":0.0,"id":13010434},{"batb":[[2,5.7,28.23]],"batl":[[0,7,6.72],[1,7.2,16.21],[2,7.6,15.26]],"ltp":5.9,"tv":4.21,"id":17293892}]}]}
{"op":"mcm","clk":"1005629196","pt":1580643670942,"mc":[{"id":"1.168224295","rc":[{"trd":[[1.5,13.44]],"batl":[[0,1.5,37.89],[2,1.6,0]],"ltp":1.5,"tv":13.44,"id":13010435},{"trd":[[5.6,16.8]],"batb":[[0,5.6,1.9]],"ltp":5.6,"tv":16.8,"id":13010434}],"tv":34.46}]}
{"op":"mcm","clk":"1005629761","pt":1580643673865,"mc":[{"id":"1.168224295","rc":[{"trd":[[1.5,38.65]],"batl":[[0,1.5,25.29],[2,1.58,42.01]],"ltp":1.5,"tv":38.65,"id":13010435}],"tv":59.67}]}
{"op":"mcm","clk":"1005630439","pt":1580643677349,"mc":[{"id":"1.168224295","rc":[{"batb":[[0,1.46,103.02],[1,1.43,45.95],[2,1.41,48.15]],"batl":[[2,1.58,0]],"ltp":1.5,"tv":38.65,"id":13010435},{"batb":[[1,5.4,11.09]],"batl":[[0,6.8,18.57],[1,6.8,0]],"ltp":5.6,"tv":16.8,"id":13010434},{"batb":[[0,6,17.39],[2,5.7,19.83]],"batl":[[0,7.2,16.21],[1,7.6,15.26],[2,7.6,0]],"ltp":5.9,"tv":4.21,"id":17293892}]}]}
{"op":"mcm","clk":"1005630579","pt":1580643678044,"mc":[{"id":"1.168224295","rc":[{"batb":[[1,1.41,48.15],[2,1.01,0.51]],"batl":[[0,1.54,40.29],[1,1.54,0]],"ltp":1.5,"tv":38.65,"id":13010435},{"batb":[[0,5.4,11.09],[1,5.3,27.93],[2,1.01,0.51]],"ltp":5.6,"tv":16.8,"id":13010434},{"batb":[[0,5.9,22.88],[1,5.7,19.83],[2,1.01,0.51]],"batl":[[0,7.6,15.26],[1,7.6,0]],"ltp":5.9,"tv":4.21,"id":17293892}]}]}
{"op":"mcm","clk":"1005631027","pt":1580643680288,"mc":[{"id":"1.168224295","rc":[{"batb":[[0,1.46,154.51],[1,1.45,105.97],[2,1.41,48.15]],"ltp":1.5,"tv":38.65,"id":13010435},{"batb":[[1,5.3,42.57],[2,5.2,28.96]],"ltp":5.6,"tv":16.8,"id":13010434},{"batb":[[1,5.8,24.29],[2,5.7,19.83]],"ltp":5.9,"tv":4.21,"id":17293892}]}]}
{"op":"mcm","clk":"1005631120","pt":1580643680721,"mc":[{"id":"1.168224295","rc":[{"batb":[[2,1.01,0.51]],"batl":[[0,1.55,39.42]],"ltp":1.5,"tv":38.65,"id":13010435},{"batb":[[0,5.3,54.14],[1,5.2,28.96],[2,1.01,0.51]],"batl":[[0,6.6,19.43]],"ltp":5.6,"tv":16.8,"id":13010434},{"batl":[[0,7.4,15.34]],"ltp":5.9,"tv":4.21,"id":17293892}]}]}
{"op":"mcm","clk":"1005633209","pt":1580643691213,"mc":[{"id":"1.168224295","rc":[{"batb":[[0,1.01,0.51],[1,1.45,0],[2,1.01,0]],"ltp":1.5,"tv":38.65,"id":13010435}]}]}
{"op":"mcm","clk":"1005633821","pt":1580643694351,"mc":[{"id":"1.168224295","rc":[{"batb":[[0,1.51,82.34],[1,1.5,97.62],[2,1.49,94.32]],"batl":[[1,1.61,42.01]],"ltp":1.5,"tv":38.65,"id":13010435},{"batb":[[2,4.8,10.92]],"batl":[[0,5.6,8.4],[1,6.6,19.43]],"ltp":5.6,"tv":16.8,"id":13010434},{"batb":[[0,5.9,30.53]],"batl":[[0,6.8,6.72],[1,7.4,15.34]],"ltp":5.9,"tv":4.21,"id":17293892}]}]}
{"op":"mcm","clk":"1005633961","pt":1580643695053,"mc":[{"id":"1.168224295","rc":[{"batb":[[2,1.49,134.76]],"batl":[[1,1.6,35.33],[2,1.61,42.01]],"ltp":1.5,"tv":38.65,"id":13010435},{"batb":[[2,5.1,12.51]],"batl":[[1,6,11.17],[2,6.2,10.54]],"ltp":5.6,"tv":16.8,"id":13010434},{"batl":[[0,6.8,25.29],[1,7,17.47]],"ltp":5.9,"tv":4.21,"id":17293892}]}]}
{"op":"mcm","clk":"1005636820","pt":1580643709250,"mc":[{"id":"1.168224295","rc":[{"batb":[[0,1.49,94.32],[1,1.46,42.96],[2,1.01,0.51]],"batl":[[0,1.6,35.33],[1,1.6,0],[2,1.61,0]],"ltp":1.5,"tv":38.65,"id":13010435},{"batb":[[0,5.2,28.96],[1,5.1,12.51],[2,1.01,0.51]],"batl":[[0,6.2,10.54],[1,6,0],[2,6.2,0]],"ltp":5.6,"tv":16.8,"id":13010434},{"batb":[[0,5.4,11.33],[1,1.01,0.51],[2,5.7,0]],"batl":[[0,7,17.47],[1,7,0]],"ltp":5.9,"tv":4.21,"id":17293892}]}]}
{"op":"mcm","clk":"1005637383","pt":1580643712032,"mc":[{"id":"1.168224295","rc":[{"batb":[[1,1.48,96.76],[2,1.46,42.96]],"ltp":1.5,"tv":38.65,"id":13010435},{"batb":[[0,5.2,41.61],[1,5.1,42.79]],"ltp":5.6,"tv":16.8,"id":13010434},{"batb":[[0,5.7,19.91],[1,5.6,26.42],[2,5.4,11.33]],"ltp":5.9,"tv":4.21,"id":17293892}]}]}
{"op":"mcm","clk":"1005638858","pt":1580643718962,"mc":[{"id":"1.168224295","rc":[{"batb":[[0,1.46,42.96],[1,1.01,0.51],[2,1.46,0]],"ltp":1.5,"tv":38.65,"id":13010435}]}]}
{"op":"mcm","clk":"1005639548","pt":1580643722272,"mc":[{"id":"1.168224295","rc":[{"batb":[[0,1.53,148.6],[1,1.52,86.96],[2,1.46,42.96]],"batl":[[1,1.64,42.01]],"ltp":1.5,"tv":38.65,"id":13010435},{"batb":[[2,4.7,10.92]],"batl":[[0,5.6,8.4],[1,6.2,10.54]],"ltp":5.6,"tv":16.8,"id":13010434},{"batb":[[2,5.4,20.57]],"batl":[[0,6.4,7.56],[1,7,17.47]],"ltp":5.9,"tv":4.21,"id":17293892}]}]}
{"op":"mcm","clk":"1005639675","pt":1580643722873,"mc":[{"id":"1.168224295","rc":[{"batb":[[0,1.53,184.87],[2,1.5,39.03]],"batl":[[2,1.65,31.39]],"ltp":1.5,"tv":38.65,"id":13010435},{"batb":[[2,5,13.45]],"batl":[[1,5.8,12.04],[2,6,11.33]],"ltp":5.6,"tv":16.8,"id":13010434},{"batl":[[0,6.2,10.86],[1,6.4,7.56],[2,6.6,19.67]],"ltp":5.9,"tv":4.21,"id":17293892}]}]}
{"op":"mcm","clk":"1005642320","pt":1580643736392,"mc":[{"id":"1.168224295","rc":[{"batb":[[0,1.53,78.98],[1,1.5,39.03],[2,1.01,0.51]],"batl":[[0,1.64,42.01],[1,1.65,31.39],[2,1.65,0]],"ltp":1.5,"tv":38.65,"id":13010435},{"batb":[[0,5.1,30.28],[1,5,13.45],[2,4.7,10.92]],"batl":[[1,6,11.33],[2,6,0]],"ltp":5.6,"tv":16.8,"id":13010434},{"batb":[[0,5.4,9.24],[1,5,13.06],[2,1.01,0.51]],"batl":[[0,6.4,7.56],[1,6.6,19.67],[2,6.6,0]],"ltp":5.9,"tv":4.21,"id":17293892}]}]}
{"op":"mcm","clk":"1005642504","pt":1580643737300,"mc":[{"id":"1.168224295","rc":[{"batb":[[0,1.5,39.03],[1,1.01,0.51],[2,1.01,0]],"batl":[[0,1.65,31.39],[1,1.65,0]],"ltp":1.5,"tv":38.65,"id":13010435},{"batb":[[2,1.01,0.51]],"batl":[[0,6,11.33],[1,6,0]],"ltp":5.6,"tv":16.8,"id":13010434},{"batb":[[0,5,13.06],[1,1.01,0.51],[2,1.01,0]],"batl":[[0,6.6,19.67],[1,6.6,0]],"ltp":5.9,"tv":4.21,"id":17293892}]}]}
{"op":"mcm","clk":"1005642880","pt":1580643739247,"mc":[{"id":"1.168224295","rc":[{"batb":[[0,1.51,119.11],[1,1.5,130.96],[2,1.01,0.51]],"ltp":1.5,"tv":38.65,"id":13010435},{"batb":[[0,5.1,44.46],[1,5,45.13]],"ltp":5.6,"tv":16.8,"id":13010434},{"batb":[[0,5.4,41.65],[1,5.3,29.58],[2,5,13.06]],"ltp":5.9,"tv":4.21,"id":17293892}]}]}
{"op":"mcm","clk":"1005647466","pt":1580643762107,"mc":[{"id":"1.168224295","rc":[{"batb":[[0,5,13.45],[1,1.01,0.51],[2,1.01,0]],"ltp":5.6,"tv":16.8,"id":13010434},{"batb":[[0,5,13.06],[1,1.01,0.51],[2,5,0]],"ltp":5.9,"tv":4.21,"id":17293892}]}]}
{"op":"mcm","clk":"1005648098","pt":1580643765270,"mc":[{"id":"1.168224295","rc":[{"batb":[[2,1.47,41.78]],"batl":[[0,1.56,38],[1,1.62,33.68],[2,1.65,31.39]],"ltp":1.5,"tv":38.65,"id":13010435},{"batb":[[0,5.3,26.45],[1,5.2,40.98],[2,5,13.45]],"batl":[[1,6.2,10.78]],"ltp":5.6,"tv":16.8,"id":13010434},{"batb":[[0,5.8,24.53],[1,5.7,25.33],[2,5.5,10.62]],"batl":[[1,6.8,18.18]],"ltp":5.9,"tv":4.21,"id":17293892}]}]}
{"op":"mcm","clk":"1005648281","pt":1580643766279,"mc":[{"id":"1.168224295","rc":[{"batb":[[0,1.52,80.66],[1,1.51,119.11],[2,1.5,130.96]],"batl":[[1,1.62,75.69],[2,1.65,0]],"ltp":1.5,"tv":38.65,"id":13010435},{"batb":[[2,5,12.9]],"batl":[[0,5.6,8.4],[1,6,11.33],[2,6.2,10.78]],"ltp":5.6,"tv":16.8,"id":13010434},{"batb":[[2,5.5,19.86]],"batl":[[0,6.6,26.39]],"ltp":5.9,"tv":4.21,"id":17293892}]}]}
{"op":"mcm","clk":"1005651912","pt":1580643785260,"mc":[{"id":"1.168224295","rc":[{"batb":[[1,1.51,93]],"ltp":1.5,"tv":38.65,"id":13010435}]}]}
{"op":"mcm","clk":"1005652320","pt":1580643787390,"mc":[{"id":"1.168224295","rc":[{"batb":[[0,1.47,41.78],[1,1.01,0.51],[2,1.5,0]],"batl":[[0,1.62,33.68],[1,1.62,0]],"ltp":1.5,"tv":38.65,"id":13010435},{"batb":[[0,5.2,29.18],[1,5,12.9],[2,1.01,0.51]],"batl":[[0,6.2,10.78],[1,6,0],[2,6.2,0]],"ltp":5.6,"tv":16.8,"id":13010434},{"batb":[[0,5.2,12.04],[1,1.01,0.51],[2,5.5,0]],"batl":[[0,6.8,18.18],[1,6.8,0]],"ltp":5.9,"tv":4.21,"id":17293892}]}]}
{"op":"mcm","clk":"1005652841","pt":1580643790084,"mc":[{"id":"1.168224295","rc":[{"batb":[[0,1.49,150.55],[1,1.48,97.39],[2,1.47,41.78]],"ltp":1.5,"tv":38.65,"id":13010435},{"batb":[[1,5.1,30.53],[2,5,12.9]],"ltp":5.6,"tv":16.8,"id":13010434},{"batb":[[0,5.6,29.68],[1,5.5,27.59],[2,5.2,12.04]],"ltp":5.9,"tv":4.21,"id":17293892}]}]}
{"op":"mcm","clk":"1005653737","pt":1580643794679,"mc":[{"id":"1.168224295","rc":[{"batb":[[0,1.47,41.78],[1,1.01,0.51],[2,1.47,0]],"ltp":1.5,"tv":38.65,"id":13010435},{"batb":[[0,5.2,12.04],[1,1.01,0.51],[2,5.2,0]],"ltp":5.9,"tv":4.21,"id":17293892}]}]}
{"op":"mcm","clk":"1005654414","pt":1580643797960,"mc":[{"id":"1.168224295","rc":[{"batb":[[0,1.51,144.01],[1,1.5,92.21],[2,1.47,41.78]],"ltp":1.5,"tv":38.65,"id":13010435},{"batb":[[0,5.2,47.03]],"ltp":5.6,"tv":16.8,"id":13010434},{"batb":[[0,5.8,26.98],[1,5.7,25.51],[2,5.2,12.04]],"ltp":5.9,"tv":4.21,"id":17293892}]}]}
{"op":"mcm","clk":"1005654725","pt":1580643799466,"mc":[{"id":"1.168224295","rc":[{"batb":[[0,1.47,41.78],[1,1.01,0.51],[2,1.47,0]],"ltp":1.5,"tv":38.65,"id":13010435},{"batb":[[0,5.2,29.18]],"ltp":5.6,"tv":16.8,"id":13010434},{"batb":[[0,5.2,12.04],[1,1.01,0.51],[2,5.2,0]],"ltp":5.9,"tv":4.21,"id":17293892}]}]}
{"op":"mcm","clk":"1005655342","pt":1580643802573,"mc":[{"id":"1.168224295","rc":[{"batb":[[0,1.49,142.79],[1,1.48,97.38],[2,1.47,41.78]],"ltp":1.5,"tv":38.65,"id":13010435},{"batb":[[0,5.6,34.22],[1,5.5,27.6],[2,5.2,12.04]],"ltp":5.9,"tv":4.21,"id":17293892}]}]}
{"op":"mcm","clk":"1005655638","pt":1580643804158,"mc":[{"id":"1.168224295","rc":[{"batb":[[0,1.47,41.78],[1,1.01,0.51],[2,1.47,0]],"ltp":1.5,"tv":38.65,"id":13010435}]}]}
{"op":"mcm","clk":"1005656189","pt":1580643807055,"mc":[{"id":"1.168224295","rc":[{"batb":[[0,1.54,75.17],[1,1.53,84.94],[2,1.47,41.78]],"ltp":1.5,"tv":38.65,"id":13010435}]}]}
{"op":"mcm","clk":"1005656446","pt":1580643808379,"mc":[{"id":"1.168224295","rc":[{"batb":[[0,1.55,34.46],[1,1.54,152.47],[2,1.53,84.94]],"batl":[[1,1.65,42.01],[2,1.69,28.8]],"ltp":1.5,"tv":38.65,"id":13010435},{"batl":[[0,5.5,9.24],[1,5.7,12.43],[2,5.9,11.72]],"ltp":5.6,"tv":16.8,"id":13010434},{"batb":[[2,5.3,9.24]],"batl":[[0,6,11.57],[1,6.4,18.03]],"ltp":5.9,"tv":4.21,"id":17293892}]}]}
{"op":"mcm","clk":"1005659010","pt":1580643822391,"mc":[{"id":"1.168224295","rc":[{"batb":[[0,1.54,77.3],[1,1.51,37.61],[2,1.01,0.51]],"batl":[[0,1.65,42.01],[1,1.69,28.8],[2,1.69,0]],"ltp":1.5,"tv":38.65,"id":13010435},{"batb":[[0,5.1,30.53],[1,4.8,14.32],[2,4.7,10.92]],"batl":[[1,5.9,11.72],[2,5.9,0]],"ltp":5.6,"tv":16.8,"id":13010434},{"batb":[[0,5.3,9.24],[1,4.9,14.24],[2,1.01,0.51]],"batl":[[0,6.4,18.03],[1,6.4,0]],"ltp":5.9,"tv":4.21,"id":17293892}]}]}
{"op":"mcm","clk":"1005659301","pt":1580643823973,"mc":[{"id":"1.168224295","rc":[{"batb":[[0,1.51,37.61],[1,1.01,0.51],[2,1.01,0]],"batl":[[0,1.69,28.8],[1,1.69,0]],"ltp":1.5,"tv":38.65,"id":13010435},{"batb":[[2,1.01,0.51]],"batl":[[0,5.9,11.72],[1,5.9,0]],"ltp":5.6,"tv":16.8,"id":13010434},{"batb":[[0,4.9,14.24],[1,1.01,0.51],[2,1.01,0]],"batl":[[0,6.4,10.46]],"ltp":5.9,"tv":4.21,"id":17293892}]}]}
{"op":"mcm","clk":"1005659529","pt":1580643825188,"mc":[{"id":"1.168224295","rc":[{"batb":[[0,1.52,105.96],[1,1.51,127.18],[2,1.01,0.51]],"ltp":1.5,"tv":38.65,"id":13010435},{"batb":[[1,5,31.84],[2,4.8,14.32]],"ltp":5.6,"tv":16.8,"id":13010434},{"batb":[[0,140,2.37],[1,130,2.66],[2,1.01,0.51]],"ltp":0.0,"tv":0.0,"id":17293893},{"batb":[[0,5.4,28.38],[1,5.3,30.01],[2,4.9,14.24]],"ltp":5.9,"tv":4.21,"id":17293892}]}]}
{"op":"mcm","clk":"1005659949","pt":1580643827220,"mc":[{"id":"1.168224295","rc":[{"batb":[[0,1.51,37.61],[1,1.01,0.51],[2,1.01,0]],"ltp":1.5,"tv":38.65,"id":13010435},{"batb":[[0,1.01,0.51],[1,130,0],[2,1.01,0]],"ltp":0.0,"tv":0.0,"id":17293893},{"batb":[[0,4.9,14.24],[1,1.01,0.51],[2,4.9,0]],"ltp":5.9,"tv":4.21,"id":17293892}]}]}
{"op":"mcm","clk":"1005660857","pt":1580643832200,"mc":[{"id":"1.168224295","rc":[{"batb":[[0,5.1,19.99]],"ltp":5.6,"tv":16.8,"id":13010434}]}]}
{"op":"mcm","clk":"1005661070","pt":1580643833350,"mc":[{"id":"1.168224295","rc":[{"batb":[[0,140,2.58],[1,1.01,0.51]],"ltp":0.0,"tv":0.0,"id":17293893},{"batb":[[0,5.4,34.8],[1,4.9,14.24],[2,1.01,0.51]],"ltp":5.9,"tv":4.21,"id":17293892}]}]}
{"op":"mcm","clk":"1005661396","pt":1580643835203,"mc":[{"id":"1.168224295","rc":[{"batb":[[0,5.5,22.58],[1,5.4,34.8],[2,4.9,14.24]],"ltp":5.9,"tv":4.21,"id":17293892}]}]}
{"op":"mcm","clk":"1005662749","pt":1580643842342,"mc":[{"id":"1.168224295","rc":[{"batb":[[0,1.62,96.64],[1,1.58,32.02],[2,1.56,140.31]],"batl":[[1,1.72,27.22],[2,1.75,42.01]],"ltp":1.5,"tv":38.65,"id":13010435},{"batl":[[0,5.3,9.24],[1,5.5,13.69],[2,5.6,12.98]],"ltp":5.6,"tv":16.8,"id":13010434},{"batl":[[0,5.6,13.61],[1,5.7,8.4],[2,5.8,12.43]],"ltp":5.9,"tv":4.21,"id":17293892}]}]}
{"op":"mcm","clk":"1005665887","pt":1580643860189,"mc":[{"id":"1.168224295","rc":[{"batb":[[0,1.62,67.22],[2,1.01,0.51]],"batl":[[0,1.72,27.22],[1,1.75,42.01],[2,1.75,0]],"ltp":1.5,"tv":38.65,"id":13010435},{"batb":[[0,5,31.84],[1,4.8,14.32],[2,4.5,11.76]],"batl":[[1,5.6,12.98],[2,5.6,0]],"ltp":5.6,"tv":16.8,"id":13010434},{"batb":[[0,1.01,0.51],[1,1.01,0]],"ltp":0.0,"tv":0.0,"id":17293893},{"batb":[[0,4.8,10.92],[1,4.7,15.11],[2,1.01,0.51]],"batl":[[0,5.7,8.4],[1,5.8,12.43],[2,5.8,0]],"ltp":5.9,"tv":4.21,"id":17293892}]}]}
{"op":"mcm","clk":"1005666227","pt":1580643862061,"mc":[{"id":"1.168224295","rc":[{"batb":[[0,1.58,32.02],[1,1.01,0.51],[2,1.01,0]],"batl":[[1,1.75,0]],"ltp":1.5,"tv":38.65,"id":13010435},{"batb":[[2,1.01,0.51]],"batl":[[0,5.6,12.98],[1,5.6,0]],"ltp":5.6,"tv":16.8,"id":13010434},{"batb":[[0,4.7,15.11],[1,1.01,0.51],[2,1.01,0]],"batl":[[0,5.8,12.43],[1,5.8,0]],"ltp":5.9,"tv":4.21,"id":17293892}]}]}
{"op":"mcm","clk":"1005666442","pt":1580643863393,"mc":[{"id":"1.168224295","rc":[{"batb":[[1,1.54,83.47],[2,1.53,85.33]],"ltp":1.5,"tv":38.65,"id":13010435},{"batb":[[1,4.9,33.26],[2,4.8,14.32]],"ltp":5.6,"tv":16.8,"id":13010434},{"batb":[[0,120,3.53],[1,110,2.33],[2,1.01,0.51]],"ltp":0.0,"tv":0.0,"id":17293893},{"batb":[[0,5.3,45.15],[1,5.2,31.55],[2,4.7,15.11]],"ltp":5.9,"tv":4.21,"id":17293892}]}]}
{"op":"mcm","clk":"1005668360","pt":1580643874295,"mc":[{"id":"1.168224295","rc":[{"batb":[[1,4.8,14.32],[2,1.01,0.51]],"ltp":5.6,"tv":16.8,"id":13010434},{"batb":[[0,1.01,0.51],[1,110,0],[2,1.01,0]],"ltp":0.0,"tv":0.0,"id":17293893},{"batb":[[0,4.7,15.11],[1,1.01,0.51],[2,4.7,0]],"ltp":5.9,"tv":4.21,"id":17293892}]}]}
{"op":"mcm","clk":"1005668901","pt":1580643877377,"mc":[{"id":"1.168224295","rc":[{"batb":[[1,1.55,34.7],[2,1.54,83.47]],"batl":[[0,1.65,31.32],[1,1.68,29.35],[2,1.72,27.22]],"ltp":1.5,"tv":38.65,"id":13010435},{"batb":[[0,5.1,49.72],[1,5,31.84],[2,4.9,14.16]],"batl":[[1,5.7,12.51]],"ltp":5.6,"tv":16.8,"id":13010434},{"batb":[[0,5.7,22.19],[1,5.6,27.05],[2,5.1,12.98]],"batl":[[1,6.2,11.33]],"ltp":5.9,"tv":4.21,"id":17293892}]}]}
{"op":"mcm","clk":"1005669076","pt":1580643878385,"mc":[{"id":"1.168224295","rc":[{"batb":[[0,1.61,68.06],[1,1.58,32.02],[2,1.55,34.7]],"batl":[[2,1.73,42.01]],"ltp":1.5,"tv":38.65,"id":13010435},{"batl":[[0,5.3,9.24],[1,5.6,12.98],[2,5.7,12.51]],"ltp":5.6,"tv":16.8,"id":13010434},{"batl":[[0,5.8,20.83]],"ltp":5.9,"tv":4.21,"id":17293892}]}]}
{"op":"mcm","clk":"1005669222","pt":1580643879203,"mc":[{"id":"1.168224295","rc":[{"batl":[[0,5.6,12.98],[1,5.7,12.51],[2,5.7,0]],"ltp":5.6,"tv":16.8,"id":13010434}]}]}
{"op":"mcm","clk":"1005669338","pt":1580643879787,"mc":[{"id":"1.168224295","rc":[{"batl":[[0,5.2,9.24],[1,5.6,12.98],[2,5.7,12.51]],"ltp":5.6,"tv":16.8,"id":13010434},{"trd":[[5.7,16.8]],"batb":[[0,5.7,13.79]],"ltp":5.7,"tv":21.02,"id":17293892}],"tv":76.47}]}
{"op":"mcm","clk":"1005669914","pt":1580643883224,"mc":[{"id":"1.168224295","rc":[{"trd":[[5.7,33.6]],"batb":[[0,5.7,12.17]],"ltp":5.7,"tv":37.82,"id":17293892}],"tv":93.27}]}
{"op":"mcm","clk":"1005670531","pt":1580643886570,"mc":[{"id":"1.168224295","rc":[{"batb":[[0,5.7,18.95]],"ltp":5.7,"tv":37.82,"id":17293892}]}]}
{"op":"mcm","clk":"1005671013","pt":1580643889200,"mc":[{"id":"1.168224295","rc":[{"batb":[[0,5.1,28.63]],"ltp":5.6,"tv":16.8,"id":13010434},{"batb":[[0,5.1,12.98],[1,4.9,24.01],[2,1.01,0.51]],"ltp":5.7,"tv":37.82,"id":17293892}]}]}
{"op":"mcm","clk":"1005671104","pt":1580643889683,"mc":[{"id":"1.168224295","rc":[{"batb":[[0,1.55,34.7],[1,1.01,0.51],[2,1.55,0]],"batl":[[0,1.68,29.35],[1,1.68,0],[2,1.73,0]],"ltp":1.5,"tv":38.65,"id":13010435},{"batl":[[0,5.7,12.51],[1,5.6,0],[2,5.7,0]],"ltp":5.6,"tv":16.8,"id":13010434},{"batb":[[0,4.9,13.93],[1,1.01,0.51],[2,1.01,0]],"batl":[[0,6.2,11.33],[1,6.2,0]],"ltp":5.7,"tv":37.82,"id":17293892}]}]}
{"op":"mcm","clk":"1005671505","pt":1580643891834,"mc":[{"id":"1.168224295","rc":[{"batb":[[1,1.51,110.86],[2,1.5,92.49]],"ltp":1.5,"tv":38.65,"id":13010435},{"batb":[[0,5.5,35.54],[1,5.4,29.08],[2,4.9,13.93]],"ltp":5.7,"tv":37.82,"id":17293892}]}]}
{"op":"mcm","clk":"1005671712","pt":1580643892784,"mc":[{"id":"1.168224295","rc":[{"batb":[[0,1.54,35.49]],"batl":[[0,1.67,29.98]],"ltp":1.5,"tv":38.65,"id":13010435},{"batb":[[2,4.9,13.85]],"batl":[[0,5.8,12.2]],"ltp":5.6,"tv":16.8,"id":13010434},{"batb":[[2,5,13.61]],"batl":[[0,6.2,11.09]],"ltp":5.7,"tv":37.82,"id":17293892}]}]}
{"op":"mcm","clk":"1005674821","pt":1580643908719,"mc":[{"id":"1.168224295","rc":[{"batb":[[1,1.01,0.51],[2,1.5,0]],"ltp":1.5,"tv":38.65,"id":13010435}]}]}
{"op":"mcm","clk":"1005675587","pt":1580643912326,"mc":[{"id":"1.168224295","rc":[{"batb":[[0,1.61,68.06],[1,1.6,30.69],[2,1.57,32.97]],"batl":[[1,1.7,28.33],[2,1.73,42.01]],"ltp":1.5,"tv":38.65,"id":13010435},{"batl":[[0,5.2,9.24],[1,5.6,13.3],[2,5.7,12.75]],"ltp":5.6,"tv":16.8,"id":13010434},{"batl":[[0,5.7,13.06],[1,5.8,8.4],[2,5.9,12.04]],"ltp":5.7,"tv":37.82,"id":17293892}]}]}
{"op":"mcm","clk":"1005677075","pt":1580643919916,"mc":[{"id":"1.168224295","rc":[{"batb":[[1,1.57,32.97],[2,1.01,0.51]],"batl":[[0,1.7,28.33],[1,1.73,42.01],[2,1.73,0]],"ltp":1.5,"tv":38.65,"id":13010435},{"batb":[[0,5,31.84],[1,4.8,14.32],[2,4.5,11.76]],"batl":[[1,5.7,12.75],[2,5.7,0]],"ltp":5.6,"tv":16.8,"id":13010434},{"batb":[[0,5.4,29.08],[1,4.9,10.08],[2,4.8,14.4]],"batl":[[0,5.8,8.4],[1,5.9,12.04],[2,5.9,0]],"ltp":5.7,"tv":37.82,"id":17293892}]}]}
{"op":"mcm","clk":"1005677377","pt":1580643921526,"mc":[{"id":"1.168224295","rc":[{"batb":[[0,1.57,32.97],[1,1.01,0.51],[2,1.01,0]],"batl":[[1,1.73,0]],"ltp":1.5,"tv":38.65,"id":13010435},{"batb":[[2,1.01,0.51]],"batl":[[0,5.7,12.75],[1,5.7,0]],"ltp":5.6,"tv":16.8,"id":13010434},{"batb":[[1,4.8,14.4],[2,1.01,0.51]],"batl":[[0,5.9,12.04],[1,5.9,0]],"ltp":5.7,"tv":37.82,"id":17293892}]}]}
{"op":"mcm","clk":"1005677693","pt":1580643923121,"mc":[{"id":"1.168224295","rc":[{"batb":[[1,1.53,103.74],[2,1.52,87.66]],"ltp":1.5,"tv":38.65,"id":13010435},{"batb":[[0,5,39.92],[1,4.9,33.15],[2,4.8,14.32]],"ltp":5.6,"tv":16.8,"id":13010434},{"batb":[[0,120,4.17],[1,1.01,0.51]],"ltp":0.0,"tv":0.0,"id":17293893},{"batb":[[1,5.3,30.45],[2,4.8,14.4]],"ltp":5.7,"tv":37.82,"id":17293892}]}]}
{"op":"mcm","clk":"1005679535","pt":1580643933168,"mc":[{"id":"1.168224295","rc":[{"batb":[[1,1.01,0.51],[2,1.52,0]],"ltp":1.5,"tv":38.65,"id":13010435}]}]}
{"op":"mcm","clk":"1005680134","pt":1580643936369,"mc":[{"id":"1.168224295","rc":[{"batb":[[0,1.62,67.22],[1,1.58,85.8],[2,1.57,110.19]],"batl":[[1,1.73,42.01]],"ltp":1.5,"tv":38.65,"id":13010435},{"batl":[[0,5.2,9.24],[1,5.7,12.75]],"ltp":5.6,"tv":16.8,"id":13010434},{"batb":[[2,4.9,10.08]],"batl":[[0,5.8,8.4],[1,5.9,12.04]],"ltp":5.7,"tv":37.82,"id":17293892}]}]}
{"op":"mcm","clk":"1005680290","pt":1580643937178,"mc":[{"id":"1.168224295","rc":[{"batb":[[0,1.63,28.88],[1,1.62,67.22],[2,1.59,31.32]],"batl":[[1,1.72,27.15],[2,1.73,42.01]],"ltp":1.5,"tv":38.65,"id":13010435},{"batl":[[1,5.5,13.77],[2,5.6,12.98]],"ltp":5.6,"tv":16.8,"id":13010434},{"batl":[[0,5.6,13.85],[1,5.8,21.23]],"ltp":5.7,"tv":37.82,"id":17293892}]}]}
{"op":"mcm","clk":"1005682120","pt":1580643947108,"mc":[{"id":"1.168224295","rc":[{"batb":[[0,1.62,67.22],[1,1.59,31.32],[2,1.01,0.51]],"batl":[[0,1.72,27.15],[1,1.73,42.01],[2,1.73,0]],"ltp":1.5,"tv":38.65,"id":13010435},{"batb":[[0,4.9,33.15],[1,4.8,14.32],[2,4.5,11.76]],"batl":[[1,5.6,12.98],[2,5.6,0]],"ltp":5.6,"tv":16.8,"id":13010434},{"batb":[[0,1.01,0.51],[1,1.01,0]],"ltp":0.0,"tv":0.0,"id":17293893},{"batb":[[0,5.3,19.51],[1,4.9,10.08],[2,4.7,15.11]],"batl":[[0,5.8,21.23],[1,5.8,0]],"ltp":5.7,"tv":37.82,"id":17293892}]}]}
{"op":"mcm","clk":"1005682288","pt":1580643947967,"mc":[{"id":"1.168224295","rc":[{"batb":[[0,1.59,31.32],[1,1.01,0.51],[2,1.01,0]],"batl":[[1,1.73,0]],"ltp":1.5,"tv":38.65,"id":13010435},{"batb":[[2,1.01,0.51]],"batl":[[0,5.6,12.98],[1,5.6,0]],"ltp":5.6,"tv":16.8,"id":13010434},{"batb":[[1,4.7,15.11],[2,1.01,0.51]],"batl":[[0,5.8,12.83]],"ltp":5.7,"tv":37.82,"id":17293892}]}]}
{"op":"mcm","clk":"1005682750","pt":1580643950314,"mc":[{"id":"1.168224295","rc":[{"batb":[[1,1.55,105.87],[2,1.54,83.27]],"ltp":1.5,"tv":38.65,"id":13010435},{"batb":[[0,4.9,54.16],[1,4.8,48.85]],"ltp":5.6,"tv":16.8,"id":13010434},{"batb":[[1,5.2,31.87],[2,4.7,15.11]],"ltp":5.7,"tv":37.82,"id":17293892}]}]}
{"op":"mcm","clk":"1005682796","pt":1580643950526,"mc":[{"id":"1.168224295","rc":[{"batb":[[0,110,2.35],[1,100,4.22],[2,1.01,0.51]],"ltp":0.0,"tv":0.0,"id":17293893}]}]}
{"op":"mcm","clk":"1005683995","pt":1580643957219,"mc":[{"id":"1.168224295","rc":[{"batb":[[0,4.8,14.32],[1,1.01,0.51],[2,1.01,0]],"ltp":5.6,"tv":16.8,"id":13010434},{"batb":[[0,1.01,0.51],[1,100,0],[2,1.01,0]],"ltp":0.0,"tv":0.0,"id":17293893},{"batb":[[0,4.7,15.11],[1,1.01,0.51],[2,4.7,0]],"ltp":5.7,"tv":37.82,"id":17293892}]}]}
{"op":"mcm","clk":"1005684581","pt":1580643960387,"mc":[{"id":"1.168224295","rc":[{"batb":[[0,1.61,68.06],[1,1.59,31.32],[2,1.55,105.87]],"batl":[[0,1.72,69.16]],"ltp":1.5,"tv":38.65,"id":13010435},{"batb":[[0,5.1,37.08],[1,5,31.69],[2,4.8,14.32]],"batl":[[0,5.2,9.24],[1,5.6,12.98]],"ltp":5.6,"tv":16.8,"id":13010434},{"batb":[[0,5.6,24.23],[1,5.5,28.08],[2,5,10.08]],"batl":[[0,5.8,21.23]],"ltp":5.7,"tv":37.82,"id":17293892}]}]}
{"op":"mcm","clk":"1005684744","pt":1580643961212,"mc":[{"id":"1.168224295","rc":[{"batb":[[2,1.56,33.83]],"batl":[[0,1.66,30.61],[1,1.69,28.8],[2,1.72,42.01]],"ltp":1.5,"tv":38.65,"id":13010435},{"batb":[[2,4.9,14.08]],"batl":[[2,5.7,12.59]],"ltp":5.6,"tv":16.8,"id":13010434},{"batb":[[2,5,23.46]],"batl":[[1,6,11.8]],"ltp":5.7,"tv":37.82,"id":17293892}]}]}
{"op":"mcm","clk":"1005686424","pt":1580643970192,"mc":[{"id":"1.168224295","rc":[{"batb":[[1,1.56,33.83],[2,1.01,0.51]],"batl":[[0,1.69,28.8],[1,1.72,42.01],[2,1.72,0]],"ltp":1.5,"tv":38.65,"id":13010435},{"batb":[[0,5,31.69],[1,4.9,14.08],[2,4.5,11.76]],"batl":[[1,5.7,12.59],[2,5.7,0]],"ltp":5.6,"tv":16.8,"id":13010434},{"batb":[[0,5,10.08],[1,4.9,14.24],[2,1.01,0.51]],"batl":[[0,5.8,8.4]],"ltp":5.7,"tv":37.82,"id":17293892}]}]}
{"op":"mcm","clk":"1005686636","pt":1580643971418,"mc":[{"id":"1.168224295","rc":[{"batb":[[0,1.56,33.83],[1,1.01,0.51],[2,1.01,0]],"batl":[[1,1.72,0]],"ltp":1.5,"tv":38.65,"id":13010435},{"batb":[[2,1.01,0.51]],"batl":[[0,5.7,12.59],[1,5.7,0]],"ltp":5.6,"tv":16.8,"id":13010434},{"batb":[[0,4.9,14.24],[1,1.01,0.51],[2,1.01,0]],"batl":[[0,6,11.8],[1,6,0]],"ltp":5.7,"tv":37.82,"id":17293892}]}]}
{"op":"mcm","clk":"1005686994","pt":1580643973399,"mc":[{"id":"1.168224295","rc":[{"batb":[[0,1.55,34.31],[1,1.52,107.03],[2,1.51,90.02]],"batl":[[0,1.68,29.19]],"ltp":1.5,"tv":38.65,"id":13010435},{"batb":[[0,5,47.04],[1,4.9,33.04],[2,4.8,14.24]],"ltp":5.6,"tv":16.8,"id":13010434},{"batb":[[0,120,4.08],[1,1.01,0.51]],"ltp":0.0,"tv":0.0,"id":17293893},{"batb":[[0,5.4,42.72],[1,5.3,30.22],[2,4.9,13.77]],"batl":[[0,6.2,11.41]],"ltp":5.7,"tv":37.82,"id":17293892}]}]}
{"op":"mcm","clk":"1005687227","pt":1580643974760,"mc":[{"id":"1.168224295","rc":[{"batb":[[1,1.01,0.51],[2,1.51,0]],"ltp":1.5,"tv":38.65,"id":13010435}]}]}
{"op":"mcm","clk":"1005687818","pt":1580643978397,"mc":[{"id":"1.168224295","rc":[{"batb":[[0,1.61,97.88],[1,1.58,31.79],[2,1.57,113.34]],"batl":[[1,1.71,27.85],[2,1.72,42.01]],"ltp":1.5,"tv":38.65,"id":13010435},{"batl":[[0,5.3,9.24],[1,5.5,13.61],[2,5.6,13.14]],"ltp":5.6,"tv":16.8,"id":13010434},{"batb":[[2,4.9,23.85]],"batl":[[0,5.7,13.14],[1,5.8,8.4],[2,5.9,12.35]],"ltp":5.7,"tv":37.82,"id":17293892}]}]}
{"op":"mcm","clk":"1005689158","pt":1580643986008,"mc":[{"id":"1.168224295","rc":[{"batb":[[0,1.58,31.79],[1,1.01,0.51],[2,1.57,0]],"batl":[[0,1.71,27.85],[1,1.71,0],[2,1.72,0]],"ltp":1.5,"tv":38.65,"id":13010435},{"batb":[[0,5,31.69]],"batl":[[0,5.6,13.14],[1,5.5,0],[2,5.6,0]],"ltp":5.6,"tv":16.8,"id":13010434},{"batb":[[0,1.01,0.51],[1,1.01,0]],"ltp":0.0,"tv":0.0,"id":17293893},{"batb":[[0,5.3,30.22],[1,4.8,14.4],[2,1.01,0.51]],"batl":[[0,5.9,12.35],[1,5.8,0],[2,5.9,0]],"ltp":5.7,"tv":37.82,"id":17293892}]}]}
{"op":"mcm","clk":"1005689505","pt":1580643988318,"mc":[{"id":"1.168224295","rc":[{"batb":[[1,1.54,137.37],[2,1.53,85.6]],"ltp":1.5,"tv":38.65,"id":13010435},{"batb":[[0,100,6.81],[1,1.01,0.51]],"ltp":0.0,"tv":0.0,"id":17293893},{"batb":[[1,5.2,31.64],[2,4.8,14.4]],"ltp":5.7,"tv":37.82,"id":17293892}]}]}
{"op":"mcm","clk":"1005689641","pt":1580643989186,"mc":[{"id":"1.168224295","rc":[{"batl":[[0,1.7,28.09]],"ltp":1.5,"tv":38.65,"id":13010435},{"batb":[[2,4.9,14.24]],"ltp":5.7,"tv":37.82,"id":17293892}]}]}
{"op":"mcm","clk":"1005689890","pt":1580643990727,"mc":[{"id":"1.168224295","rc":[{"batb":[[1,1.01,0.51],[2,1.53,0]],"ltp":1.5,"tv":38.65,"id":13010435},{"batb":[[1,4.8,14.24],[2,1.01,0.51]],"ltp":5.6,"tv":16.8,"id":13010434},{"batb":[[0,1.01,0.51],[1,1.01,0]],"ltp":0.0,"tv":0.0,"id":17293893},{"batb":[[0,4.9,14.24],[1,1.01,0.51],[2,4.9,0]],"ltp":5.7,"tv":37.82,"id":17293892}]}]}
{"op":"mcm","clk":"1005690631","pt":1580643995023,"mc":[{"id":"1.168224295","rc":[{"batb":[[1,1.54,137.37],[2,1.53,85.6]],"ltp":1.5,"tv":38.65,"id":13010435},{"batb":[[1,4.9,33.36],[2,4.8,14.24]],"ltp":5.6,"tv":16.8,"id":13010434},{"batb":[[0,100,6.81],[1,1.01,0.51]],"ltp":0.0,"tv":0.0,"id":17293893},{"batb":[[0,5.3,36.24],[1,5.2,31.64],[2,4.9,14.24]],"ltp":5.7,"tv":37.82,"id":17293892}]}]}
{"op":"mcm","clk":"1005692034","pt":1580644003240,"mc":[{"id":"1.168224295","rc":[{"batb":[[0,5.3,43.43]],"ltp":5.7,"tv":37.82,"id":17293892}]}]}
{"op":"mcm","clk":"1005692380","pt":1580644005269,"mc":[{"id":"1.168224295","rc":[{"batb":[[1,4.8,14.24],[2,1.01,0.51]],"ltp":5.6,"tv":16.8,"id":13010434},{"batb":[[0,1.01,0.51],[1,1.01,0]],"ltp":0.0,"tv":0.0,"id":17293893},{"batb":[[0,4.9,14.24],[1,1.01,0.51],[2,4.9,0]],"ltp":5.7,"tv":37.82,"id":17293892}]}]}
{"op":"mcm","clk":"1005692751","pt":1580644007293,"mc":[{"id":"1.168224295","rc":[{"batb":[[0,5.1,42.54],[1,5,31.69],[2,4.8,14.24]],"ltp":5.6,"tv":16.8,"id":13010434},{"batb":[[0,160,2.76],[1,1.01,0.51]],"ltp":0.0,"tv":0.0,"id":17293893},{"batb":[[0,5.7,18.1],[1,5.6,27.16],[2,4.9,14.24]],"ltp":5.7,"tv":37.82,"id":17293892}]}]}
{"op":"mcm","clk":"1005692918","pt":1580644008366,"mc":[{"id":"1.168224295","rc":[{"batb":[[0,1.6,69.74],[1,1.58,31.79],[2,1.55,34.46]],"batl":[[0,1.65,31.16],[1,1.68,29.11],[2,1.71,42.01]],"ltp":1.5,"tv":38.65,"id":13010435},{"batb":[[2,4.9,13.61]],"batl":[[0,5.3,9.24],[1,5.6,13.14],[2,5.7,12.59]],"ltp":5.6,"tv":16.8,"id":13010434},{"batb":[[2,5.1,12.83]],"batl":[[0,5.9,20.76],[1,6.2,11.33]],"ltp":5.7,"tv":37.82,"id":17293892}]}]}
{"op":"mcm","clk":"1005694462","pt":1580644018293,"mc":[{"id":"1.168224295","rc":[{"batb":[[0,5,31.69],[1,4.9,13.61],[2,4.8,14.24]],"ltp":5.6,"tv":16.8,"id":13010434},{"batb":[[0,1.01,0.51],[1,1.01,0]],"ltp":0.0,"tv":0.0,"id":17293893},{"batb":[[0,5.1,12.83],[1,5,23.69],[2,1.01,0.51]],"ltp":5.7,"tv":37.82,"id":17293892}]}]}
{"op":"mcm","clk":"1005694554","pt":1580644018923,"mc":[{"id":"1.168224295","rc":[{"batb":[[1,1.55,34.46],[2,1.01,0.51]],"batl":[[0,1.68,29.11],[1,1.71,42.01],[2,1.71,0]],"ltp":1.5,"tv":38.65,"id":13010435},{"batb":[[1,4.8,14.24],[2,4.5,11.76]],"batl":[[1,5.7,12.59],[2,5.7,0]],"ltp":5.6,"tv":16.8,"id":13010434},{"batb":[[0,5,23.69],[1,1.01,0.51],[2,1.01,0]],"batl":[[0,5.9,8.4]],"ltp":5.7,"tv":37.82,"id":17293892}]}]}
{"op":"mcm","clk":"1005694802","pt":1580644020315,"mc":[{"id":"1.168224295","rc":[{"batb":[[0,1.55,34.46],[1,1.01,0.51],[2,1.01,0]],"batl":[[1,1.71,0]],"ltp":1.5,"tv":38.65,"id":13010435},{"batb":[[2,1.01,0.51]],"batl":[[0,5.7,12.59],[1,5.7,0]],"ltp":5.6,"tv":16.8,"id":13010434},{"batb":[[0,5,13.61]],"batl":[[0,6.2,11.33],[1,6.2,0]],"ltp":5.7,"tv":37.82,"id":17293892}]}]}
{"op":"mcm","clk":"1005694938","pt":1580644021326,"mc":[{"id":"1.168224295","rc":[{"batb":[[1,1.51,133.99],[2,1.5,92.66]],"ltp":1.5,"tv":38.65,"id":13010435},{"batb":[[0,5,52.15],[1,4.9,32.93],[2,4.8,14.24]],"ltp":5.6,"tv":16.8,"id":13010434},{"batb":[[0,120,5.39],[1,1.01,0.51]],"ltp":0.0,"tv":0.0,"id":17293893},{"batb":[[0,5.5,34.46],[1,5.4,29.2],[2,5,13.61]],"ltp":5.7,"tv":37.82,"id":17293892}]}]}
{"op":"mcm","clk":"1005695456","pt":1580644024714,"mc":[{"id":"1.168224295","rc":[{"batb":[[1,1.01,0.51],[2,1.5,0]],"ltp":1.5,"tv":38.65,"id":13010435},{"batb":[[0,5,31.69],[1,4.8,14.24],[2,1.01,0.51]],"ltp":5.6,"tv":16.8,"id":13010434},{"batb":[[0,1.01,0.51],[1,1.01,0]],"ltp":0.0,"tv":0.0,"id":17293893},{"batb":[[0,5,13.61],[1,1.01,0.51],[2,5,0]],"ltp":5.7,"tv":37.82,"id":17293892}]}]}
{"op":"mcm","clk":"1005696343","pt":1580644030128,"mc":[{"id":"1.168224295","rc":[{"batb":[[1,1.51,133.99],[2,1.5,92.66]],"ltp":1.5,"tv":38.65,"id":13010435},{"batb":[[0,5,52.15],[1,4.9,32.93],[2,4.8,14.24]],"ltp":5.6,"tv":16.8,"id":13010434},{"batb":[[0,120,5.39],[1,1.01,0.51]],"ltp":0.0,"tv":0.0,"id":17293893},{"batb":[[0,5.5,34.46],[1,5.4,29.2],[2,5,13.61]],"ltp":5.7,"tv":37.82,"id":17293892}]}]}
{"op":"mcm","clk":"1005697522","pt":1580644037165,"mc":[{"id":"1.168224295","rc":[{"batb":[[0,4.8,14.24],[1,1.01,0.51],[2,4.8,0]],"ltp":5.6,"tv":16.8,"id":13010434},{"batb":[[0,1.01,0.51],[1,1.01,0]],"ltp":0.0,"tv":0.0,"id":17293893},{"batb":[[0,5,13.61],[1,1.01,0.51],[2,5,0]],"ltp":5.7,"tv":37.82,"id":17293892}]}]}
{"op":"mcm","clk":"1005698037","pt":1580644040405,"mc":[{"id":"1.168224295","rc":[{"batb":[[0,1.59,70.58],[1,1.55,34.46],[2,1.51,133.99]],"batl":[[1,1.7,42.01]],"ltp":1.5,"tv":38.65,"id":13010435},{"batb":[[0,5.2,44.3],[1,5.1,30.15],[2,4.8,14.24]],"batl":[[0,5.3,9.24],[1,5.7,12.59]],"ltp":5.6,"tv":16.8,"id":13010434},{"batb":[[0,5.9,23.05],[1,5.8,25.07],[2,5.1,10.08]],"batl":[[0,6,8.4],[1,6.2,11.33]],"ltp":5.7,"tv":37.82,"id":17293892}]}]}
{"op":"mcm","clk":"1005698185","pt":1580644041402,"mc":[{"id":"1.168224295","rc":[{"batl":[[0,1.62,33.6],[1,1.66,30.84],[2,1.7,42.01]],"ltp":1.5,"tv":38.65,"id":13010435},{"batb":[[2,5,13.14]],"batl":[[2,5.9,11.64]],"ltp":5.6,"tv":16.8,"id":13010434},{"batb":[[2,5.3,11.8]],"batl":[[2,6.6,19.59]],"ltp":5.7,"tv":37.82,"id":17293892}]}]}
{"op":"mcm","clk":"1005698510","pt":1580644043278,"mc":[{"id":"1.168224295","rc":[{"trd":[[5.9,21.02]],"batb":[[0,5.9,14.65]],"ltp":5.9,"tv":54.62,"id":17293892}],"tv":110.07}]}
{"op":"mcm","clk":"1005699125","pt":1580644047020,"mc":[{"id":"1.168224295","rc":[{"trd":[[5.2,8.4]],"batb":[[0,5.2,40.1]],"ltp":5.2,"tv":25.2,"id":13010434},{"batb":[[0,5.9,21.43]],"ltp":5.9,"tv":54.62,"id":17293892}],"tv":118.48}]}
{"op":"mcm","clk":"1005699675","pt":1580644050203,"mc":[{"id":"1.168224295","rc":[{"trd":[[5.9,34.46]],"batb":[[0,5.9,14.71]],"ltp":5.9,"tv":68.06,"id":17293892}],"tv":131.92}]}
{"op":"mcm","clk":"1005700226","pt":1580644053387,"mc":[{"id":"1.168224295","rc":[{"batb":[[0,1.5,39.03],[1,1.01,0.51],[2,1.51,0]],"batl":[[0,1.66,30.84],[1,1.66,0],[2,1.7,0]],"ltp":1.5,"tv":38.65,"id":13010435},{"batb":[[0,5.1,30.15],[1,4.9,13.93],[2,1.01,0.51]],"batl":[[0,5.2,9.24],[1,5.9,11.64],[2,5.9,0]],"ltp":5.2,"tv":25.2,"id":13010434},{"batb":[[0,5.1,12.83],[1,1.01,0.51],[2,5.3,0]],"batl":[[0,6.6,19.59],[1,6.2,0],[2,6.6,0]],"ltp":5.9,"tv":68.06,"id":17293892}]}]}
{"op":"mcm","clk":"1005700301","pt":1580644053813,"mc":[{"id":"1.168224295","rc":[{"batl":[[0,5.9,11.64],[1,5.9,0]],"ltp":5.2,"tv":25.2,"id":13010434}]}]}
{"op":"mcm","clk":"1005700722","pt":1580644056199,"mc":[{"id":"1.168224295","rc":[{"batb":[[1,1.48,116.72],[2,1.47,100.56]],"batl":[[0,1.65,31.08],[1,1.66,30.84]],"ltp":1.5,"tv":38.65,"id":13010435},{"batb":[[0,5.1,48.38],[1,5,31.49],[2,4.9,13.93]],"ltp":5.2,"tv":25.2,"id":13010434},{"batb":[[0,5.7,27.73],[1,5.6,26.99],[2,5.1,12.83]],"ltp":5.9,"tv":68.06,"id":17293892}]}]}
{"op":"mcm","clk":"1005700830","pt":1580644056892,"mc":[{"id":"1.168224295","rc":[{"batl":[[1,1.66,0]],"ltp":1.5,"tv":38.65,"id":13010435},{"batl":[[0,6.6,19.43]],"ltp":5.9,"tv":68.06,"id":17293892}]}]}
{"op":"mcm","clk":"1005701443","pt":1580644061324,"mc":[{"id":"1.168224295","rc":[{"batb":[[1,1.01,0.51],[2,1.47,0]],"ltp":1.5,"tv":38.65,"id":13010435}]}]}
{"op":"mcm","clk":"1005701914","pt":1580644064235,"mc":[{"id":"1.168224295","rc":[{"batb":[[0,1.54,88.4],[1,1.53,85.36],[2,1.5,39.03]],"ltp":1.5,"tv":38.65,"id":13010435}]}]}
{"op":"mcm","clk":"1005702109","pt":1580644065402,"mc":[{"id":"1.168224295","rc":[{"batb":[[0,1.59,70.58],[1,1.58,31.79],[2,1.55,34.62]],"batl":[[1,1.68,29.43],[2,1.7,42.01]],"ltp":1.5,"tv":38.65,"id":13010435},{"batl":[[0,5.3,9.24],[1,5.6,13.3],[2,5.7,12.51]],"ltp":5.2,"tv":25.2,"id":13010434},{"batb":[[2,5.1,22.91]],"batl":[[0,5.9,12.2],[1,6,8.4],[2,6.2,11.33]],"ltp":5.9,"tv":68.06,"id":17293892}]}]}
{"op":"mcm","clk":"1005703328","pt":1580644073355,"mc":[{"id":"1.168224295","rc":[{"batb":[[1,1.55,34.62],[2,1.01,0.51]],"batl":[[0,1.68,29.43],[1,1.7,42.01],[2,1.7,0]],"ltp":1.5,"tv":38.65,"id":13010435},{"batb":[[0,5.1,30.15],[2,4.8,14.24]],"batl":[[1,5.7,12.51],[2,5.7,0]],"ltp":5.2,"tv":25.2,"id":13010434},{"batb":[[0,5.1,10.08],[1,5,13.45],[2,1.01,0.51]],"batl":[[0,6,8.4],[1,6.2,11.33],[2,6.2,0]],"ltp":5.9,"tv":68.06,"id":17293892}]}]}
{"op":"mcm","clk":"1005703423","pt":1580644073944,"mc":[{"id":"1.168224295","rc":[{"batb":[[0,1.55,34.62],[1,1.01,0.51],[2,1.01,0]],"batl":[[1,1.7,0]],"ltp":1.5,"tv":38.65,"id":13010435},{"batl":[[0,5.7,12.51],[1,5.7,0]],"ltp":5.2,"tv":25.2,"id":13010434},{"batb":[[0,5,13.45],[1,1.01,0.51],[2,1.01,0]],"batl":[[0,6.2,11.33],[1,6.2,0]],"ltp":5.9,"tv":68.06,"id":17293892}]}]}
{"op":"mcm","clk":"1005703795","pt":1580644076149,"mc":[{"id":"1.168224295","rc":[{"batb":[[1,1.51,95.38],[2,1.5,92.41]],"ltp":1.5,"tv":38.65,"id":13010435},{"batb":[[0,5.5,43.97],[1,5.4,29.03],[2,5,13.45]],"ltp":5.9,"tv":68.06,"id":17293892}]}]}
{"op":"mcm","clk":"1005704882","pt":1580644083735,"mc":[{"id":"1.168224295","rc":[{"batb":[[1,1.01,0.51],[2,1.5,0]],"ltp":1.5,"tv":38.65,"id":13010435},{"batb":[[0,5,13.45],[1,1.01,0.51],[2,5,0]],"ltp":5.9,"tv":68.06,"id":17293892}]}]}
{"op":"mcm","clk":"1005705354","pt":1580644087130,"mc":[{"id":"1.168224295","rc":[{"batb":[[0,1.61,30.06],[1,1.59,31.63],[2,1.56,96.79]],"batl":[[1,1.7,28.09]],"ltp":1.5,"tv":38.65,"id":13010435},{"batl":[[0,5.5,13.69],[1,5.6,13.22]],"ltp":5.2,"tv":25.2,"id":13010434},{"batb":[[0,5.5,43.97],[1,5.4,29.03],[2,5,13.45]],"batl":[[0,5.7,12.9],[1,5.8,12.43]],"ltp":5.9,"tv":68.06,"id":17293892}]}]}
{"op":"mcm","clk":"1005705599","pt":1580644088927,"mc":[{"id":"1.168224295","rc":[{"batb":[[1,1.6,69.74],[2,1.59,31.63]],"batl":[[2,1.71,42.01]],"ltp":1.5,"tv":38.65,"id":13010435},{"batl":[[0,5.3,9.24],[1,5.5,13.69],[2,5.6,13.22]],"ltp":5.2,"tv":25.2,"id":13010434},{"batb":[[2,5.1,10.08]],"batl":[[2,6,8.4]],"ltp":5.9,"tv":68.06,"id":17293892}]}]}
{"op":"mcm","clk":"1005706640","pt":1580644096275,"mc":[{"id":"1.168224295","rc":[{"batb":[[0,1.6,69.74],[1,1.59,31.63],[2,1.01,0.51]],"batl":[[0,1.7,28.09],[1,1.71,42.01],[2,1.71,0]],"ltp":1.5,"tv":38.65,"id":13010435},{"batb":[[0,5,31.49],[1,4.8,14.24],[2,4.5,11.76]],"batl":[[1,5.6,13.22],[2,5.6,0]],"ltp":5.2,"tv":25.2,"id":13010434},{"batb":[[0,5.4,29.03],[1,5.1,10.08],[2,4.9,14.16]],"batl":[[0,5.8,12.43],[1,6,8.4],[2,6,0]],"ltp":5.9,"tv":68.06,"id":17293892}]}]}
{"op":"mcm","clk":"1005706823","pt":1580644097594,"mc":[{"id":"1.168224295","rc":[{"batb":[[0,1.59,31.63],[1,1.01,0.51],[2,1.01,0]],"batl":[[1,1.71,0]],"ltp":1.5,"tv":38.65,"id":13010435},{"batb":[[2,1.01,0.51]],"batl":[[0,5.6,13.22],[1,5.6,0]],"ltp":5.2,"tv":25.2,"id":13010434},{"batb":[[1,4.9,14.16],[2,1.01,0.51]],"batl":[[1,6,0]],"ltp":5.9,"tv":68.06,"id":17293892}]}]}
{"op":"mcm","clk":"1005707093","pt":1580644099329,"mc":[{"id":"1.168224295","rc":[{"batb":[[1,1.53,125.76],[2,1.52,87.8]],"ltp":1.5,"tv":38.65,"id":13010435},{"batb":[[1,4.9,33.16],[2,4.8,14.24]],"ltp":5.2,"tv":25.2,"id":13010434},{"batb":[[0,110,2.41],[1,100,4.15],[2,1.01,0.51]],"ltp":0.0,"tv":0.0,"id":17293893},{"batb":[[0,5.4,36.49],[1,5.3,30.37],[2,4.9,14.16]],"ltp":5.9,"tv":68.06,"id":17293892}]}]}
{"op":"mcm","clk":"1005707600","pt":1580644102375,"mc":[{"id":"1.168224295","rc":[{"batb":[[1,1.01,0.51],[2,1.52,0]],"ltp":1.5,"tv":38.65,"id":13010435},{"batb":[[1,4.8,14.24],[2,1.01,0.51]],"ltp":5.2,"tv":25.2,"id":13010434},{"batb":[[0,1.01,0.51],[1,100,0],[2,1.01,0]],"ltp":0.0,"tv":0.0,"id":17293893},{"batb":[[0,5.4,29.03],[1,4.9,14.16],[2,1.01,0.51]],"ltp":5.9,"tv":68.06,"id":17293892}]}]}
{"op":"mcm","clk":"1005708005","pt":1580644105389,"mc":[{"id":"1.168224295","rc":[{"batb":[[1,1.58,88.28],[2,1.57,77.26]],"ltp":1.5,"tv":38.65,"id":13010435},{"batb":[[1,4.9,33.16],[2,4.8,14.24]],"ltp":5.2,"tv":25.2,"id":13010434},{"batb":[[0,110,2.41],[1,100,4.15],[2,1.01,0.51]],"ltp":0.0,"tv":0.0,"id":17293893},{"batb":[[0,5.4,36.49],[1,5.3,30.37],[2,4.9,14.16]],"ltp":5.9,"tv":68.06,"id":17293892}]}]}
{"op":"mcm","clk":"1005708066","pt":1580644105766,"mc":[{"id":"1.168224295","rc":[{"batb":[[0,1.63,28.88],[1,1.59,30.92],[2,1.58,88.28]],"batl":[[1,1.76,25.1]],"ltp":1.5,"tv":38.65,"id":13010435},{"batb":[[2,4.7,15.42]],"batl":[[0,5.4,14.08],[1,5.5,13.61]],"ltp":5.2,"tv":25.2,"id":13010434},{"batb":[[2,4.9,13.85]],"batl":[[0,5.7,13.3],[1,5.8,12.43]],"ltp":5.9,"tv":68.06,"id":17293892}]}]}
{"op":"mcm","clk":"1005708268","pt":1580644107090,"mc":[{"id":"1.168224295","rc":[{"batb":[[1,1.6,69.74],[2,1.59,30.92]],"batl":[[1,1.72,42.01],[2,1.76,25.1]],"ltp":1.5,"tv":38.65,"id":13010435},{"batl":[[0,5.3,9.24],[1,5.4,14.08],[2,5.5,13.61]],"ltp":5.2,"tv":25.2,"id":13010434},{"batb":[[2,5,10.08]],"batl":[[2,5.9,8.4]],"ltp":5.9,"tv":68.06,"id":17293892}]}]}
{"op":"mcm","clk":"1005710030","pt":1580644120091,"mc":[{"id":"1.168224295","rc":[{"batl":[[1,1.76,25.1],[2,1.76,0]],"ltp":1.5,"tv":38.65,"id":13010435}]}]}
{"op":"mcm","clk":"1005710435","pt":1580644123011,"mc":[{"id":"1.168224295","rc":[{"batl":[[0,1.7,70.1]],"ltp":1.5,"tv":38.65,"id":13010435}]}]}
{"op":"mcm","clk":"1005710658","pt":1580644124707,"mc":[{"id":"1.168224295","rc":[{"batb":[[0,1.62,29.51]],"batl":[[0,1.69,28.88],[1,1.7,42.01],[2,1.75,25.65]],"ltp":1.5,"tv":38.65,"id":13010435},{"batb":[[2,4.8,14.4]],"batl":[[1,5.5,13.61],[2,5.6,13.3]],"ltp":5.2,"tv":25.2,"id":13010434},{"batb":[[1,100,3.62]],"ltp":0.0,"tv":0.0,"id":17293893},{"batb":[[2,5,23.69]],"batl":[[0,5.7,13.06]],"ltp":5.9,"tv":68.06,"id":17293892}]}]}
{"op":"mcm","clk":"1005719570","pt":1580644192398,"mc":[{"id":"1.168224295","rc":[{"batb":[[0,1.6,69.74],[1,1.59,30.92],[2,1.01,0.51]],"batl":[[0,1.7,42.01],[1,1.75,25.65],[2,1.75,0]],"ltp":1.5,"tv":38.65,"id":13010435},{"batb":[[0,4.9,33.16],[1,4.7,15.11],[2,4.5,11.76]],"batl":[[1,5.6,13.3],[2,5.6,0]],"ltp":5.2,"tv":25.2,"id":13010434},{"batb":[[0,1.01,0.51],[1,100,0],[2,1.01,0]],"ltp":0.0,"tv":0.0,"id":17293893},{"batb":[[0,5,10.08],[1,4.8,14.87],[2,1.01,0.51]],"batl":[[0,5.8,12.43],[1,5.9,8.4],[2,5.9,0]],"ltp":5.9,"tv":68.06,"id":17293892}]}]}
{"op":"mcm","clk":"1005719782","pt":1580644193875,"mc":[{"id":"1.168224295","rc":[{"batb":[[0,1.59,30.92],[1,1.01,0.51],[2,1.01,0]],"batl":[[0,1.75,25.65],[1,1.75,0]],"ltp":1.5,"tv":38.65,"id":13010435},{"batb":[[2,1.01,0.51]],"batl":[[0,5.6,13.3],[1,5.6,0]],"ltp":5.2,"tv":25.2,"id":13010434},{"batb":[[0,4.8,14.87],[1,1.01,0.51],[2,1.01,0]],"batl":[[1,5.9,0]],"ltp":5.9,"tv":68.06,"id":17293892}]}]}
{"op":"mcm","clk":"1005719951","pt":1580644195186,"mc":[{"id":"1.168224295","rc":[{"batb":[[1,1.56,74.73],[2,1.55,81.06]],"ltp":1.5,"tv":38.65,"id":13010435},{"batb":[[0,4.9,43.75],[1,4.8,34.7],[2,4.7,15.11]],"ltp":5.2,"tv":25.2,"id":13010434},{"batb":[[0,60,5.95],[1,55,5.9],[2,1.01,0.51]],"ltp":0.0,"tv":0.0,"id":17293893},{"batb":[[0,5.2,45.28],[1,5.1,33.01],[2,4.8,14.87]],"ltp":5.9,"tv":68.06,"id":17293892}]}]}
{"op":"mcm","clk":"1005721018","pt":1580644202391,"mc":[{"id":"1.168224295","rc":[{"batb":[[0,4.7,15.11],[1,1.01,0.51],[2,4.7,0]],"ltp":5.2,"tv":25.2,"id":13010434},{"batb":[[0,1.01,0.51],[1,55,0],[2,1.01,0]],"ltp":0.0,"tv":0.0,"id":17293893},{"batb":[[0,4.8,14.87],[1,1.01,0.51],[2,4.8,0]],"ltp":5.9,"tv":68.06,"id":17293892}]}]}
{"op":"mcm","clk":"1005721414","pt":1580644205193,"mc":[{"id":"1.168224295","rc":[{"batb":[[2,1.55,115.05]],"batl":[[0,1.62,2.12],[1,1.66,30.92],[2,1.71,27.85]],"ltp":1.5,"tv":38.65,"id":13010435},{"batb":[[0,5.1,20.42],[1,5,31.92],[2,4.9,13.93]],"batl":[[1,5.7,12.75]],"ltp":5.2,"tv":25.2,"id":13010434},{"batb":[[0,5.5,36.02],[1,5.4,29.13],[2,5.1,12.98]],"batl":[[1,6,11.8]],"ltp":5.9,"tv":68.06,"id":17293892}]}]}
{"op":"mcm","clk":"1005721692","pt":1580644207184,"mc":[{"id":"1.168224295","rc":[{"batb":[[1,1.58,72.26],[2,1.56,74.73]],"batl":[[0,1.66,30.92],[1,1.69,42.01]],"ltp":1.5,"tv":38.65,"id":13010435},{"batl":[[0,5.4,9.24],[1,5.6,13.3],[2,5.7,12.75]],"ltp":5.2,"tv":25.2,"id":13010434},{"batb":[[2,5.2,9.24]],"batl":[[1,6,20.2]],"ltp":5.9,"tv":68.06,"id":17293892}]}]}
{"op":"mcm","clk":"1005723018","pt":1580644216216,"mc":[{"id":"1.168224295","rc":[{"batb":[[0,1.58,72.26],[1,1.55,33.99],[2,1.01,0.51]],"batl":[[0,1.69,42.01],[1,1.71,27.85],[2,1.71,0]],"ltp":1.5,"tv":38.65,"id":13010435},{"batb":[[0,4.8,14.79],[1,4.6,10.92],[2,1.01,0.51]],"batl":[[1,5.7,12.75],[2,5.7,0]],"ltp":5.2,"tv":25.2,"id":13010434},{"batb":[[0,5.2,9.24],[1,4.9,14.08],[2,1.01,0.51]],"batl":[[0,6,20.2],[1,6,0]],"ltp":5.9,"tv":68.06,"id":17293892}]}]}
{"op":"mcm","clk":"1005723365","pt":1580644218307,"mc":[{"id":"1.168224295","rc":[{"batb":[[0,1.55,33.99],[1,1.01,0.51],[2,1.01,0]],"batl":[[0,1.59,2.12]],"ltp":1.5,"tv":38.65,"id":13010435},{"batb":[[1,1.01,0.51],[2,1.01,0]],"batl":[[0,5.7,12.75],[1,5.7,0]],"ltp":5.2,"tv":25.2,"id":13010434},{"batb":[[0,4.9,14.08],[1,1.01,0.51],[2,1.01,0]],"batl":[[0,6,11.8]],"ltp":5.9,"tv":68.06,"id":17293892}]}]}
{"op":"mcm","clk":"1005723520","pt":1580644219101,"mc":[{"id":"1.168224295","rc":[{"batb":[[1,1.54,87.3],[2,1.53,85.3]],"ltp":1.5,"tv":38.65,"id":13010435},{"batb":[[0,5,24.62],[1,4.9,33.38],[2,4.8,14.79]],"ltp":5.2,"tv":25.2,"id":13010434},{"batb":[[0,95,3.76],[1,90,3.6],[2,1.01,0.51]],"ltp":0.0,"tv":0.0,"id":17293893},{"batb":[[0,5.3,38.7],[1,5.2,31.67],[2,4.9,14.08]],"ltp":5.9,"tv":68.06,"id":17293892}]}]}
{"op":"mcm","clk":"1005723654","pt":1580644219928,"mc":[{"id":"1.168224295","rc":[{"batl":[[0,1.71,27.85],[1,1.71,0]],"ltp":1.5,"tv":38.65,"id":13010435}]}]}
{"op":"mcm","clk":"1005724021","pt":1580644222227,"mc":[{"id":"1.168224295","rc":[{"batb":[[1,1.01,0.51],[2,1.53,0]],"ltp":1.5,"tv":38.65,"id":13010435},{"batb":[[0,1.01,0.51],[1,90,0],[2,1.01,0]],"ltp":0.0,"tv":0.0,"id":17293893},{"batb":[[0,4.9,14.08],[1,1.01,0.51],[2,4.9,0]],"ltp":5.9,"tv":68.06,"id":17293892}]}]}
{"op":"mcm","clk":"1005724524","pt":1580644225154,"mc":[{"id":"1.168224295","rc":[{"batb":[[0,1.56,131.76],[1,1.55,115.32],[2,1.01,0.51]],"ltp":1.5,"tv":38.65,"id":13010435},{"batb":[[0,5,47.13]],"ltp":5.2,"tv":25.2,"id":13010434},{"batb":[[0,160,3.13],[1,1.01,0.51]],"ltp":0.0,"tv":0.0,"id":17293893},{"batb":[[0,5.5,24.64],[1,5.4,29.3],[2,4.9,14.08]],"ltp":5.9,"tv":68.06,"id":17293892}]}]}
{"op":"mcm","clk":"1005724800","pt":1580644226955,"mc":[{"id":"1.168224295","rc":[{"batb":[[0,1.55,33.99],[1,1.01,0.51],[2,1.01,0]],"ltp":1.5,"tv":38.65,"id":13010435},{"batb":[[0,5,24.62]],"ltp":5.2,"tv":25.2,"id":13010434},{"batb":[[0,1.01,0.51],[1,1.01,0]],"ltp":0.0,"tv":0.0,"id":17293893},{"batb":[[0,4.9,14.08],[1,1.01,0.51],[2,4.9,0]],"ltp":5.9,"tv":68.06,"id":17293892}]}]}
{"op":"mcm","clk":"1005725277","pt":1580644230381,"mc":[{"id":"1.168224295","rc":[{"batb":[[1,1.54,87.3],[2,1.53,85.3]],"ltp":1.5,"tv":38.65,"id":13010435},{"batb":[[0,95,3.76],[1,90,3.6],[2,1.01,0.51]],"ltp":0.0,"tv":0.0,"id":17293893},{"batb":[[0,5.3,38.7],[1,5.2,31.67],[2,4.9,14.08]],"ltp":5.9,"tv":68.06,"id":17293892}]}]}
{"op":"mcm","clk":"1005725945","pt":1580644234876,"mc":[{"id":"1.168224295","rc":[{"batb":[[1,1.01,0.51],[2,1.53,0]],"ltp":1.5,"tv":38.65,"id":13010435}]}]}
{"op":"mcm","clk":"1005726418","pt":1580644238393,"mc":[{"id":"1.168224295","rc":[{"batb":[[0,1.63,28.4],[1,1.6,30.92],[2,1.59,124.72]],"batl":[[1,1.77,24.39]],"ltp":1.5,"tv":38.65,"id":13010435},{"batl":[[0,5.4,14.16],[1,5.5,13.45],[2,5.7,12.75]],"ltp":5.2,"tv":25.2,"id":13010434},{"batl":[[0,5.6,13.45],[1,5.7,12.9],[2,6,11.8]],"ltp":5.9,"tv":68.06,"id":17293892}]}]}
{"op":"mcm","clk":"1005726459","pt":1580644238662,"mc":[{"id":"1.168224295","rc":[{"batb":[[1,1.61,68.06],[2,1.6,30.92]],"batl":[[1,1.73,42.01],[2,1.77,24.39]],"ltp":1.5,"tv":38.65,"id":13010435},{"batl":[[0,5.3,9.24],[1,5.4,14.16],[2,5.5,13.45]],"ltp":5.2,"tv":25.2,"id":13010434},{"batb":[[2,5,10.08]],"batl":[[2,5.8,8.4]],"ltp":5.9,"tv":68.06,"id":17293892}]}]}
{"op":"mcm","clk":"1005727462","pt":1580644245397,"mc":[{"id":"1.168224295","rc":[{"batb":[[0,1.61,68.06],[1,1.6,30.92],[2,1.01,0.51]],"batl":[[0,1.73,42.01],[1,1.77,24.39],[2,1.77,0]],"ltp":1.5,"tv":38.65,"id":13010435},{"batb":[[0,4.9,33.38],[1,4.7,15.34],[2,4.5,11.76]],"batl":[[1,5.5,13.45],[2,5.5,0]],"ltp":5.2,"tv":25.2,"id":13010434},{"batb":[[0,1.01,0.51],[1,90,0],[2,1.01,0]],"ltp":0.0,"tv":0.0,"id":17293893},{"batb":[[0,5,10.08],[1,4.7,15.5],[2,1.01,0.51]],"batl":[[0,5.7,12.9],[1,5.8,8.4],[2,5.8,0]],"ltp":5.9,"tv":68.06,"id":17293892}]}]}
{"op":"mcm","clk":"1005727580","pt":1580644246200,"mc":[{"id":"1.168224295","rc":[{"batb":[[0,1.6,30.92],[1,1.01,0.51],[2,1.01,0]],"batl":[[0,1.77,24.39],[1,1.77,0]],"ltp":1.5,"tv":38.65,"id":13010435},{"batb":[[2,1.01,0.51]],"batl":[[0,5.5,13.45],[1,5.5,0]],"ltp":5.2,"tv":25.2,"id":13010434},{"batb":[[0,4.7,15.5],[1,1.01,0.51],[2,1.01,0]],"batl":[[1,5.8,0]],"ltp":5.9,"tv":68.06,"id":17293892}]}]}
{"op":"mcm","clk":"1005727926","pt":1580644248393,"mc":[{"id":"1.168224295","rc":[{"batb":[[1,1.59,31.55],[2,1.57,90.57]],"batl":[[0,1.76,24.94],[1,1.77,24.39]],"ltp":1.5,"tv":38.65,"id":13010435},{"batb":[[1,4.8,34.94],[2,4.7,15.34]],"batl":[[1,5.6,13.22]],"ltp":5.2,"tv":25.2,"id":13010434},{"batb":[[0,50,5.24],[1,48,6.26],[2,1.01,0.51]],"ltp":0.0,"tv":0.0,"id":17293893},{"batb":[[0,5.1,51.42],[1,5,34.43],[2,4.7,15.5]],"batl":[[1,5.8,12.67]],"ltp":5.9,"tv":68.06,"id":17293892}]}]}
{"op":"mcm","clk":"1005728077","pt":1580644249321,"mc":[{"id":"1.168224295","rc":[{"batb":[[0,1.59,31.55],[1,1.57,90.57],[2,1.56,79.14]],"batl":[[1,1.77,0]],"ltp":1.5,"tv":38.65,"id":13010435},{"batb":[[2,4.7,15.03]],"batl":[[0,5.6,13.22],[1,5.6,0]],"ltp":5.2,"tv":25.2,"id":13010434},{"batb":[[2,4.7,15.19]],"batl":[[0,5.8,12.67],[1,5.8,0]],"ltp":5.9,"tv":68.06,"id":17293892}]}]}
{"op":"mcm","clk":"1005729789","pt":1580644262103,"mc":[{"id":"1.168224295","rc":[{"batb":[[1,1.01,0.51],[2,1.56,0]],"ltp":1.5,"tv":38.65,"id":13010435},{"batb":[[1,4.7,15.03],[2,1.01,0.51]],"ltp":5.2,"tv":25.2,"id":13010434},{"batb":[[0,1.01,0.51],[1,48,0],[2,1.01,0]],"ltp":0.0,"tv":0.0,"id":17293893},{"batb":[[0,4.7,15.19],[1,1.01,0.51],[2,4.7,0]],"ltp":5.9,"tv":68.06,"id":17293892}]}]}
{"op":"mcm","clk":"1005730272","pt":1580644265331,"mc":[{"id":"1.168224295","rc":[{"batb":[[1,1.57,90.57],[2,1.56,79.14]],"ltp":1.5,"tv":38.65,"id":13010435},{"batb":[[0,5,40.17],[1,4.9,33.38],[2,4.7,15.03]],"ltp":5.2,"tv":25.2,"id":13010434},{"batb":[[0,190,2.22],[1,1.01,0.51]],"ltp":0.0,"tv":0.0,"id":17293893},{"batb":[[0,5.4,36.19],[1,5.3,30.37],[2,4.7,15.19]],"ltp":5.9,"tv":68.06,"id":17293892}]}]}
{"op":"mcm","clk":"1005730361","pt":1580644265953,"mc":[{"id":"1.168224295","rc":[{"batb":[[2,1.56,112.89]],"batl":[[0,1.66,30.84],[1,1.71,27.46]],"ltp":1.5,"tv":38.65,"id":13010435},{"batb":[[1,4.9,47.15],[2,4.8,14.63]],"batl":[[0,5.6,12.9]],"ltp":5.2,"tv":25.2,"id":13010434},{"batb":[[2,5,13.22]],"batl":[[1,5.9,11.96]],"ltp":5.9,"tv":68.06,"id":17293892}]}]}
{"op":"mcm","clk":"1005730428","pt":1580644266477,"mc":[{"id":"1.168224295","rc":[{"batb":[[1,1.58,72.26],[2,1.57,90.57]],"batl":[[1,1.7,42.01],[2,1.71,27.46]],"ltp":1.5,"tv":38.65,"id":13010435},{"batl":[[0,5.3,9.24],[1,5.6,12.9]],"ltp":5.2,"tv":25.2,"id":13010434},{"batb":[[2,5.1,10.08]],"batl":[[1,5.9,20.36]],"ltp":5.9,"tv":68.06,"id":17293892}]}]}
{"op":"mcm","clk":"1005731423","pt":1580644274081,"mc":[{"id":"1.168224295","rc":[{"batb":[[0,1.56,33.75],[1,1.01,0.51],[2,1.57,0]],"batl":[[0,1.71,27.46],[1,1.7,0],[2,1.71,0]],"ltp":1.5,"tv":38.65,"id":13010435},{"batb":[[0,4.9,33.38],[1,4.8,14.63],[2,1.01,0.51]],"batl":[[0,5.6,12.9],[1,5.6,0]],"ltp":5.2,"tv":25.2,"id":13010434},{"batb":[[0,1.01,0.51],[1,1.01,0]],"ltp":0.0,"tv":0.0,"id":17293893},{"batb":[[0,4.8,14.4],[1,1.01,0.51],[2,5.1,0]],"batl":[[0,5.9,11.96],[1,5.9,0]],"ltp":5.9,"tv":68.06,"id":17293892}]}]}
{"op":"mcm","clk":"1005731753","pt":1580644276385,"mc":[{"id":"1.168224295","rc":[{"batb":[[1,1.55,86.11],[2,1.54,83.13]],"ltp":1.5,"tv":38.65,"id":13010435},{"batb":[[0,4.9,45.71],[1,4.8,49.28]],"ltp":5.2,"tv":25.2,"id":13010434},{"batb":[[0,5.2,42.13],[1,5.1,33.04],[2,4.8,14.4]],"ltp":5.9,"tv":68.06,"id":17293892}]}]}
{"op":"mcm","clk":"1005734117","pt":1580644292794,"mc":[{"id":"1.168224295","rc":[{"batb":[[0,4.8,14.63],[1,1.01,0.51],[2,1.01,0]],"ltp":5.2,"tv":25.2,"id":13010434},{"batb":[[0,4.8,14.4],[1,1.01,0.51],[2,4.8,0]],"ltp":5.9,"tv":68.06,"id":17293892}]}]}
{"op":"mcm","clk":"1005734621","pt":1580644296398,"mc":[{"id":"1.168224295","rc":[{"batb":[[2,1.54,118.54]],"batl":[[0,1.63,32.97],[1,1.67,29.74]],"ltp":1.5,"tv":38.65,"id":13010435},{"batb":[[0,5.1,23.09],[1,5,31.87],[2,4.9,14.16]],"batl":[[1,5.7,12.51]],"ltp":5.2,"tv":25.2,"id":13010434},{"batb":[[0,5.5,36.37],[1,5.4,29.12],[2,5.1,12.43]],"batl":[[1,6.2,11.41]],"ltp":5.9,"tv":68.06,"id":17293892}]}]}
{"op":"mcm","clk":"1005734650","pt":1580644296616,"mc":[{"id":"1.168224295","rc":[{"batb":[[0,1.57,73.1],[1,1.56,33.75],[2,1.55,86.11]],"batl":[[2,1.68,42.01]],"ltp":1.5,"tv":38.65,"id":13010435},{"batl":[[0,5.4,9.24],[1,5.6,12.9],[2,5.7,12.51]],"ltp":5.2,"tv":25.2,"id":13010434},{"batb":[[2,5.2,9.24]],"batl":[[1,6,8.4],[2,6.2,11.41]],"ltp":5.9,"tv":68.06,"id":17293892}]}]}
{"op":"mcm","clk":"1005735843","pt":1580644304962,"mc":[{"id":"1.168224295","rc":[{"batb":[[1,1.54,35.41],[2,1.01,0.51]],"batl":[[0,1.67,29.74],[1,1.68,42.01],[2,1.68,0]],"ltp":1.5,"tv":38.65,"id":13010435},{"batb":[[0,5,31.87],[1,4.9,14.16],[2,4.6,10.92]],"batl":[[1,5.7,12.51],[2,5.7,0]],"ltp":5.2,"tv":25.2,"id":13010434},{"batb":[[0,5.2,9.24],[1,4.9,14.01],[2,1.01,0.51]],"batl":[[0,6,8.4],[1,6.2,11.41],[2,6.2,0]],"ltp":5.9,"tv":68.06,"id":17293892}]}]}
{"op":"mcm","clk":"1005735914","pt":1580644305552,"mc":[{"id":"1.168224295","rc":[{"batb":[[0,1.54,35.41],[1,1.01,0.51],[2,1.01,0]],"batl":[[1,1.68,0]],"ltp":1.5,"tv":38.65,"id":13010435},{"batb":[[2,1.01,0.51]],"batl":[[0,5.7,12.51],[1,5.7,0]],"ltp":5.2,"tv":25.2,"id":13010434},{"batb":[[0,4.9,14.01],[1,1.01,0.51],[2,1.01,0]],"batl":[[0,6.2,11.41],[1,6.2,0]],"ltp":5.9,"tv":68.06,"id":17293892}]}]}
{"op":"mcm","clk":"1005736310","pt":1580644308365,"mc":[{"id":"1.168224295","rc":[{"batb":[[1,1.53,121.68],[2,1.52,87.73]],"ltp":1.5,"tv":38.65,"id":13010435},{"batb":[[1,4.9,47.47]],"ltp":5.2,"tv":25.2,"id":13010434},{"batb":[[0,5.3,35.12],[1,5.2,31.71],[2,4.9,14.01]],"ltp":5.9,"tv":68.06,"id":17293892}]}]}
{"op":"mcm","clk":"1005738370","pt":1580644323282,"mc":[{"id":"1.168224295","rc":[{"batb":[[1,4.9,14.16]],"ltp":5.2,"tv":25.2,"id":13010434},{"batb":[[0,4.9,14.01],[1,1.01,0.51],[2,4.9,0]],"ltp":5.9,"tv":68.06,"id":17293892}]}]}
{"op":"mcm","clk":"1005738781","pt":1580644326386,"mc":[{"id":"1.168224295","rc":[{"batb":[[0,5.1,37.87],[1,5,31.87],[2,4.9,14.16]],"ltp":5.2,"tv":25.2,"id":13010434},{"batb":[[0,5.6,39.73],[1,5.5,27.9],[2,4.9,14.01]],"ltp":5.9,"tv":68.06,"id":17293892}]}]}
{"op":"mcm","clk":"1005738914","pt":1580644327386,"mc":[{"id":"1.168224295","rc":[{"batb":[[0,1.55,75.62],[1,1.54,35.41],[2,1.53,121.68]],"batl":[[0,1.61,34.54],[1,1.65,42.01],[2,1.7,28.48]],"ltp":1.5,"tv":38.65,"id":13010435},{"batb":[[1,5,44.85],[2,4.6,26.74]],"batl":[[0,5.4,9.24],[1,5.7,12.51],[2,6.8,17.62]],"ltp":5.2,"tv":25.2,"id":13010434},{"batb":[[2,5.2,21.12]],"batl":[[0,6.2,18.97],[1,7.2,16.13]],"ltp":5.9,"tv":68.06,"id":17293892}]}]}
{"op":"mcm","clk":"1005739506","pt":1580644332106,"mc":[{"id":"1.168224295","rc":[{"trd":[[1.55,6.01]],"batb":[[0,1.55,72.61]],"ltp":1.55,"tv":44.66,"id":13010435}],"tv":137.93}]}
{"op":"mcm","clk":"1005751751","pt":1580644427443,"mc":[{"id":"1.168224295","rc":[{"batb":[[0,5.6,30.15]],"ltp":5.9,"tv":68.06,"id":17293892}]}]}
{"op":"mcm","clk":"1005752517","pt":1580644433180,"mc":[{"id":"1.168224295","rc":[{"batb":[[1,1.42,48.23],[2,1.01,0.51]],"batl":[[0,1.65,42.01],[1,1.7,28.48],[2,1.7,0]],"ltp":1.55,"tv":44.66,"id":13010435},{"batb":[[0,4.6,26.74],[1,1.01,0.51],[2,4.6,0]],"batl":[[1,6.8,17.62],[2,6.8,0]],"ltp":5.2,"tv":25.2,"id":13010434},{"batb":[[0,5.2,9.24],[1,4.8,14.63],[2,1.01,0.51]],"batl":[[0,6.2,7.56]],"ltp":5.9,"tv":68.06,"id":17293892}]}]}
{"op":"mcm","clk":"1005752590","pt":1580644433679,"mc":[{"id":"1.168224295","rc":[{"batb":[[0,1.42,48.23],[1,1.01,0.51],[2,1.01,0]],"batl":[[0,1.7,28.48],[1,1.7,0]],"ltp":1.55,"tv":44.66,"id":13010435},{"batb":[[0,4.6,15.82]],"batl":[[0,6.8,17.62],[1,6.8,0]],"ltp":5.2,"tv":25.2,"id":13010434},{"batb":[[0,4.8,14.63],[1,1.01,0.51],[2,1.01,0]],"batl":[[0,7.2,16.13],[1,7.2,0]],"ltp":5.9,"tv":68.06,"id":17293892}]}]}
{"op":"mcm","clk":"1005752925","pt":1580644436377,"mc":[{"id":"1.168224295","rc":[{"batb":[[0,1.43,122.28],[1,1.42,116.42],[2,1.01,0.51]],"batl":[[0,1.7,28.01]],"ltp":1.55,"tv":44.66,"id":13010435},{"batb":[[0,4.7,35.72],[1,4.6,54.04],[2,1.01,0.51]],"batl":[[0,6.8,17.47]],"ltp":5.2,"tv":25.2,"id":13010434},{"batb":[[0,5.1,40.15],[1,5,34.36],[2,4.7,15.19]],"batl":[[0,7,16.76]],"ltp":5.9,"tv":68.06,"id":17293892}]}]}
{"op":"mcm","clk":"1005754559","pt":1580644450113,"mc":[{"id":"1.168224295","rc":[{"batb":[[0,1.43,47.52],[1,1.01,0.51],[2,1.01,0]],"ltp":1.55,"tv":44.66,"id":13010435},{"batb":[[0,4.6,15.66],[1,1.01,0.51],[2,1.01,0]],"ltp":5.2,"tv":25.2,"id":13010434},{"batb":[[0,4.7,15.19],[1,1.01,0.51],[2,4.7,0]],"ltp":5.9,"tv":68.06,"id":17293892}]}]}
{"op":"mcm","clk":"1005755142","pt":1580644454121,"mc":[{"id":"1.168224295","rc":[{"batb":[[0,1.43,122.28],[1,1.42,116.42],[2,1.01,0.51]],"ltp":1.55,"tv":44.66,"id":13010435},{"batb":[[0,4.7,35.72],[1,4.6,54.04],[2,1.01,0.51]],"ltp":5.2,"tv":25.2,"id":13010434},{"batb":[[0,5.1,40.15],[1,5,34.36],[2,4.7,15.19]],"ltp":5.9,"tv":68.06,"id":17293892}]}]}
{"op":"mcm","clk":"1005755497","pt":1580644456634,"mc":[{"id":"1.168224295","rc":[{"batb":[[0,1.43,47.52],[1,1.01,0.51],[2,1.01,0]],"ltp":1.55,"tv":44.66,"id":13010435}]}]}
{"op":"mcm","clk":"1005755984","pt":1580644460307,"mc":[{"id":"1.168224295","rc":[{"batb":[[0,1.63,28.64],[1,1.62,64.74],[2,1.61,70.02]],"batl":[[1,1.79,23.92]],"ltp":1.55,"tv":44.66,"id":13010435},{"batb":[[2,4.3,18.33]],"batl":[[0,5.3,15.03],[1,5.9,11.64],[2,6.8,17.47]],"ltp":5.2,"tv":25.2,"id":13010434},{"batl":[[0,5.4,14.56],[1,6.2,11.33],[2,7,16.76]],"ltp":5.9,"tv":68.06,"id":17293892}]}]}
{"op":"mcm","clk":"1005756033","pt":1580644460717,"mc":[{"id":"1.168224295","rc":[{"batb":[[2,1.61,138.08]],"batl":[[1,1.74,42.01],[2,1.79,23.92]],"ltp":1.55,"tv":44.66,"id":13010435},{"batb":[[2,4.3,30.94]],"batl":[[0,5.1,10.08],[1,5.3,15.03],[2,5.9,11.64]],"ltp":5.2,"tv":25.2,"id":13010434},{"batb":[[2,4.9,10.08]],"batl":[[1,5.8,8.4],[2,6.2,11.33]],"ltp":5.9,"tv":68.06,"id":17293892}]}]}
{"op":"mcm","clk":"1005756960","pt":1580644468734,"mc":[{"id":"1.168224295","rc":[{"batb":[[0,20,12.6],[1,1.01,0.51]],"ltp":0.0,"tv":0.0,"id":17293893}]}]}
{"op":"mcm","clk":"1005757434","pt":1580644472351,"mc":[{"id":"1.168224295","rc":[{"batb":[[0,1.61,68.06],[1,1.52,36.82],[2,1.01,0.51]],"batl":[[0,1.74,42.01],[1,1.79,23.92],[2,1.79,0]],"ltp":1.55,"tv":44.66,"id":13010435},{"batb":[[0,4.3,30.94],[1,1.01,0.51],[2,4.3,0]],"batl":[[1,5.9,11.64],[2,5.9,0]],"ltp":5.2,"tv":25.2,"id":13010434},{"batb":[[0,4.9,10.08],[1,4.4,17.62],[2,1.01,0.51]],"batl":[[0,5.8,8.4],[1,6.2,11.33],[2,6.2,0]],"ltp":5.9,"tv":68.06,"id":17293892}]}]}
{"op":"mcm","clk":"1005757638","pt":1580644473965,"mc":[{"id":"1.168224295","rc":[{"batb":[[0,1.52,36.82],[1,1.01,0.51],[2,1.01,0]],"batl":[[0,1.79,23.92],[1,1.79,0]],"ltp":1.55,"tv":44.66,"id":13010435},{"batb":[[0,4.3,18.33]],"batl":[[0,5.9,11.64],[1,5.9,0]],"ltp":5.2,"tv":25.2,"id":13010434},{"batb":[[0,4.4,17.62],[1,1.01,0.51],[2,1.01,0]],"batl":[[0,6.2,11.33],[1,6.2,0]],"ltp":5.9,"tv":68.06,"id":17293892}]}]}
{"op":"mcm","clk":"1005757771","pt":1580644474860,"mc":[{"id":"1.168224295","rc":[{"batb":[[1,1.51,137.07],[2,1.5,92.55]],"ltp":1.55,"tv":44.66,"id":13010435},{"batb":[[0,4.4,41.01],[1,4.3,63.11],[2,1.01,0.51]],"ltp":5.2,"tv":25.2,"id":13010434},{"batb":[[0,4.8,25.67],[1,4.7,39.73],[2,4.4,17.62]],"ltp":5.9,"tv":68.06,"id":17293892}]}]}
{"op":"mcm","clk":"1005759172","pt":1580644486271,"mc":[{"id":"1.168224295","rc":[{"batb":[[0,4.3,18.33],[1,1.01,0.51],[2,1.01,0]],"ltp":5.2,"tv":25.2,"id":13010434},{"batb":[[0,4.4,17.62],[1,1.01,0.51],[2,4.4,0]],"ltp":5.9,"tv":68.06,"id":17293892}]}]}
{"op":"mcm","clk":"1005759576","pt":1580644489251,"mc":[{"id":"1.168224295","rc":[{"batb":[[0,5.2,42.8],[1,5.1,30.2],[2,4.3,18.33]],"ltp":5.2,"tv":25.2,"id":13010434},{"batb":[[0,5.8,19.26],[1,5.7,25.93],[2,4.4,17.62]],"ltp":5.9,"tv":68.06,"id":17293892}]}]}
{"op":"mcm","clk":"1005759644","pt":1580644489772,"mc":[{"id":"1.168224295","rc":[{"batl":[[0,1.59,35.96],[1,1.69,28.8]],"ltp":1.55,"tv":44.66,"id":13010435},{"batb":[[0,5.2,54.92],[2,4.7,15.5]],"batl":[[1,7.2,15.66]],"ltp":5.2,"tv":25.2,"id":13010434},{"batb":[[2,5.3,11.8]],"batl":[[1,7.4,14.95]],"ltp":5.9,"tv":68.06,"id":17293892}]}]}
{"op":"mcm","clk":"1005759813","pt":1580644491244,"mc":[{"id":"1.168224295","rc":[{"batb":[[0,1.54,77.3],[1,1.52,36.82],[2,1.51,137.07]],"batl":[[1,1.64,42.01],[2,1.69,28.8]],"ltp":1.55,"tv":44.66,"id":13010435},{"batb":[[2,4.7,26.42]],"batl":[[0,5.5,9.24],[1,5.9,11.64],[2,7.2,15.66]],"ltp":5.2,"tv":25.2,"id":13010434},{"batb":[[2,5.3,21.04]],"batl":[[0,6.2,18.89]],"ltp":5.9,"tv":68.06,"id":17293892}]}]}
{"op":"mcm","clk":"1005760494","pt":1580644496355,"mc":[{"id":"1.168224295","rc":[{"batb":[[1,1.4,52.48],[2,1.01,0.51]],"batl":[[0,1.64,42.01],[1,1.69,28.8],[2,1.69,0]],"ltp":1.55,"tv":44.66,"id":13010435},{"batb":[[0,4.7,26.42],[1,1.01,0.51],[2,4.7,0]],"batl":[[1,7.2,15.66],[2,7.2,0]],"ltp":5.2,"tv":25.2,"id":13010434},{"batb":[[0,5.3,9.24],[1,4.8,14.56],[2,1.01,0.51]],"batl":[[0,6.2,7.56]],"ltp":5.9,"tv":68.06,"id":17293892}]}]}
{"op":"mcm","clk":"1005760677","pt":1580644497778,"mc":[{"id":"1.168224295","rc":[{"batb":[[0,1.4,52.48],[1,1.01,0.51],[2,1.01,0]],"batl":[[0,1.69,28.8],[1,1.69,0]],"ltp":1.55,"tv":44.66,"id":13010435},{"batb":[[0,4.7,15.5]],"batl":[[0,7.2,15.66],[1,7.2,0]],"ltp":5.2,"tv":25.2,"id":13010434},{"batb":[[0,4.8,14.56],[1,1.01,0.51],[2,1.01,0]],"batl":[[0,7.4,14.95],[1,7.4,0]],"ltp":5.9,"tv":68.06,"id":17293892}]}]}
{"op":"mcm","clk":"1005760838","pt":1580644499097,"mc":[{"id":"1.168224295","rc":[{"batb":[[1,1.39,125.88],[2,1.38,133.24]],"ltp":1.55,"tv":44.66,"id":13010435},{"batb":[[0,4.7,54.13],[1,4.6,38.33],[2,1.01,0.51]],"ltp":5.2,"tv":25.2,"id":13010434},{"batb":[[0,1.01,0.51],[1,1.01,0]],"ltp":0.0,"tv":0.0,"id":17293893},{"batb":[[0,5.2,23.55],[1,5.1,33.11],[2,4.8,14.56]],"ltp":5.9,"tv":68.06,"id":17293892}]}]}
{"op":"mcm","clk":"1005762857","pt":1580644514721,"mc":[{"id":"1.168224295","rc":[{"batb":[[0,4.7,15.5],[1,1.01,0.51],[2,1.01,0]],"ltp":5.2,"tv":25.2,"id":13010434},{"batb":[[0,4.8,14.56],[1,1.01,0.51],[2,4.8,0]],"ltp":5.9,"tv":68.06,"id":17293892}]}]}
{"op":"mcm","clk":"1005763326","pt":1580644518324,"mc":[{"id":"1.168224295","rc":[{"batl":[[0,1.46,50.91],[1,1.57,37.77],[2,1.69,28.8]],"ltp":1.55,"tv":44.66,"id":13010435},{"batb":[[0,6.2,44.08],[1,6,57.78],[2,5.3,11.8]],"batl":[[1,9.8,8.5]],"ltp":5.2,"tv":25.2,"id":13010434},{"batb":[[0,6.8,48.8],[1,6.6,36.36],[2,6.2,15.97]],"batl":[[1,10,8.42]],"ltp":5.9,"tv":68.06,"id":17293892}]}]}
{"op":"mcm","clk":"1005763478","pt":1580644519335,"mc":[{"id":"1.168224295","rc":[{"batl":[[2,1.69,0]],"ltp":1.55,"tv":44.66,"id":13010435}]}]}
{"op":"mcm","clk":"1005763720","pt":1580644521322,"mc":[{"id":"1.168224295","rc":[{"batl":[[1,1.51,42.01],[2,1.57,37.77]],"ltp":1.55,"tv":44.66,"id":13010435},{"batl":[[0,6.6,6.72],[1,7.2,15.66],[2,9.8,8.5]],"ltp":5.2,"tv":25.2,"id":13010434}]}]}
{"op":"mcm","clk":"1005763844","pt":1580644522215,"mc":[{"id":"1.168224295","rc":[{"batb":[[0,1.41,101.66],[1,1.4,52.48],[2,1.39,125.88]],"ltp":1.55,"tv":44.66,"id":13010435},{"batb":[[2,5.5,9.24]],"ltp":5.2,"tv":25.2,"id":13010434},{"batl":[[0,7.4,20.83]],"ltp":5.9,"tv":68.06,"id":17293892}]}]}
{"op":"mcm","clk":"1005763872","pt":1580644522425,"mc":[{"id":"1.168224295","rc":[{"batb":[[0,6.2,36.72]],"ltp":5.2,"tv":25.2,"id":13010434},{"batb":[[0,6.8,42.31]],"ltp":5.9,"tv":68.06,"id":17293892}]}]}
{"op":"mcm","clk":"1005764360","pt":1580644526341,"mc":[{"id":"1.168224295","rc":[{"batb":[[1,1.27,84.82],[2,1.01,0.51]],"batl":[[0,1.51,42.01],[1,1.57,37.77],[2,1.57,0]],"ltp":1.55,"tv":44.66,"id":13010435},{"batb":[[0,5.5,9.24],[1,5.3,11.8],[2,1.01,0.51]],"batl":[[1,9.8,8.5],[2,9.8,0]],"ltp":5.2,"tv":25.2,"id":13010434},{"batb":[[0,6,8.4],[1,5.5,10.86],[2,1.01,0.51]],"batl":[[0,7.4,5.88]],"ltp":5.9,"tv":68.06,"id":17293892}]}]}
{"op":"mcm","clk":"1005764542","pt":1580644527821,"mc":[{"id":"1.168224295","rc":[{"batb":[[0,1.27,84.82],[1,1.01,0.51],[2,1.01,0]],"batl":[[0,1.57,37.77],[1,1.57,0]],"ltp":1.55,"tv":44.66,"id":13010435},{"batb":[[0,5.3,11.8],[1,1.01,0.51],[2,1.01,0]],"batl":[[0,9.8,8.5],[1,9.8,0]],"ltp":5.2,"tv":25.2,"id":13010434},{"batb":[[0,5.5,10.86],[1,1.01,0.51],[2,1.01,0]],"batl":[[0,10,8.42],[1,10,0]],"ltp":5.9,"tv":68.06,"id":17293892}]}]}
{"op":"mcm","clk":"1005764650","pt":1580644528853,"mc":[{"id":"1.168224295","rc":[{"batb":[[1,1.26,277.26],[2,1.25,228.21]],"ltp":1.55,"tv":44.66,"id":13010435},{"batb":[[0,5.3,49.75],[1,5.2,28.83],[2,1.01,0.51]],"ltp":5.2,"tv":25.2,"id":13010434},{"batb":[[0,5.9,27.27],[1,5.8,24.75],[2,5.5,10.86]],"ltp":5.9,"tv":68.06,"id":17293892}]}]}
{"op":"mcm","clk":"1005764818","pt":1580644530322,"mc":[{"id":"1.168224295","rc":[{"batb":[[1,1.01,0.51],[2,1.25,0]],"ltp":1.55,"tv":44.66,"id":13010435},{"batb":[[0,5.3,11.8],[1,1.01,0.51],[2,1.01,0]],"ltp":5.2,"tv":25.2,"id":13010434},{"batb":[[0,5.5,10.86],[1,1.01,0.51],[2,5.5,0]],"ltp":5.9,"tv":68.06,"id":17293892}]}]}
{"op":"mcm","clk":"1005765165","pt":1580644533243,"mc":[{"id":"1.168224295","rc":[{"batb":[[0,1.36,208.29],[1,1.35,148.74],[2,1.27,84.82]],"ltp":1.55,"tv":44.66,"id":13010435},{"batb":[[0,6.6,22.3],[1,6.4,36.02],[2,5.3,11.8]],"ltp":5.2,"tv":25.2,"id":13010434},{"batb":[[0,7.2,32.73],[1,7,32.21],[2,5.5,10.86]],"ltp":5.9,"tv":68.06,"id":17293892}]}]}
{"op":"mcm","clk":"1005765181","pt":1580644533450,"mc":[{"id":"1.168224295","rc":[{"batb":[[0,1.27,84.82],[1,1.01,0.51],[2,1.27,0]],"ltp":1.55,"tv":44.66,"id":13010435},{"batb":[[0,5.3,11.8],[1,1.01,0.51],[2,5.3,0]],"ltp":5.2,"tv":25.2,"id":13010434},{"batb":[[0,5.5,10.86],[1,1.01,0.51],[2,5.5,0]],"ltp":5.9,"tv":68.06,"id":17293892}]}]}
{"op":"mcm","clk":"1005765407","pt":1580644535335,"mc":[{"id":"1.168224295","rc":[{"batb":[[1,1.26,277.26],[2,1.25,228.21]],"ltp":1.55,"tv":44.66,"id":13010435},{"batb":[[0,5.3,49.75],[1,5.2,28.83],[2,1.01,0.51]],"ltp":5.2,"tv":25.2,"id":13010434},{"batb":[[0,5.9,27.27],[1,5.8,24.75],[2,5.5,10.86]],"ltp":5.9,"tv":68.06,"id":17293892}]}]}
{"op":"mcm","clk":"1005765675","pt":1580644537542,"mc":[{"id":"1.168224295","rc":[{"batb":[[0,7,15.12],[1,1.01,0.51]],"ltp":0.0,"tv":0.0,"id":17293893}]}]}
{"op":"mcm","clk":"1005766017","pt":1580644540272,"mc":[{"id":"1.168224295","rc":[{"batb":[[1,1.01,0.51],[2,1.25,0]],"ltp":1.55,"tv":44.66,"id":13010435}]}]}
{"op":"mcm","clk":"1005766405","pt":1580644543350,"mc":[{"id":"1.168224295","rc":[{"batb":[[0,1.5,88.52],[1,1.49,94.58],[2,1.27,84.82]],"ltp":1.55,"tv":44.66,"id":13010435}]}]}
{"op":"mcm","clk":"1005766492","pt":1580644544035,"mc":[{"id":"1.168224295","rc":[{"batb":[[0,1.5,127.23],[2,1.35,61.61]],"batl":[[1,1.7,28.17]],"ltp":1.55,"tv":44.66,"id":13010435},{"batb":[[2,4.6,16.13]],"batl":[[0,6,11.33],[1,8,12.83]],"ltp":5.2,"tv":25.2,"id":13010434},{"batl":[[0,6.4,10.46],[1,8.2,12.59]],"ltp":5.9,"tv":68.06,"id":17293892}]}]}
{"op":"mcm","clk":"1005766585","pt":1580644544868,"mc":[{"id":"1.168224295","rc":[{"batb":[[0,1.5,211.25]],"ltp":1.55,"tv":44.66,"id":13010435},{"batb":[[2,4.9,10.08]],"batl":[[0,5.8,8.4],[1,6,11.33],[2,8,12.83]],"ltp":5.2,"tv":25.2,"id":13010434},{"batl":[[1,6.6,6.72],[2,8.2,12.59]],"ltp":5.9,"tv":68.06,"id":17293892}]}]}
{"op":"mcm","clk":"1005766852","pt":1580644547178,"mc":[{"id":"1.168224295","rc":[{"batb":[[0,5.9,35.05]],"ltp":5.9,"tv":68.06,"id":17293892}]}]}
{"op":"mcm","clk":"1005768155","pt":1580644557375,"mc":[{"id":"1.168224295","rc":[{"batb":[[0,1.5,122.73],[1,1.35,61.61],[2,1.01,0.51]],"ltp":1.55,"tv":44.66,"id":13010435},{"batb":[[0,5.3,11.8],[1,4.9,10.08],[2,4.6,16.13]],"ltp":5.2,"tv":25.2,"id":13010434},{"batb":[[0,5.5,10.86],[1,4.8,14.63],[2,1.01,0.51]],"ltp":5.9,"tv":68.06,"id":17293892}]}]}
{"op":"mcm","clk":"1005768218","pt":1580644557862,"mc":[{"id":"1.168224295","rc":[{"batb":[[0,1.35,61.61],[1,1.01,0.51],[2,1.01,0]],"batl":[[0,1.7,28.17],[1,1.7,0]],"ltp":1.55,"tv":44.66,"id":13010435},{"batb":[[0,4.6,16.13],[1,1.01,0.51],[2,4.6,0]],"batl":[[0,8,12.83],[1,6,0],[2,8,0]],"ltp":5.2,"tv":25.2,"id":13010434},{"batb":[[0,4.8,14.63],[1,1.01,0.51],[2,1.01,0]],"batl":[[0,8.2,12.59],[1,6.6,0],[2,8.2,0]],"ltp":5.9,"tv":68.06,"id":17293892}]}]}
{"op":"mcm","clk":"1005768509","pt":1580644560062,"mc":[{"id":"1.168224295","rc":[{"batb":[[1,1.34,160.99],[2,1.33,159.84]],"ltp":1.55,"tv":44.66,"id":13010435},{"batb":[[0,4.6,55.38],[1,4.5,40.09],[2,1.01,0.51]],"ltp":5.2,"tv":25.2,"id":13010434},{"batb":[[0,5.1,48.05],[1,5,34.25],[2,4.8,14.63]],"ltp":5.9,"tv":68.06,"id":17293892}]}]}
{"op":"mcm","clk":"1005768863","pt":1580644562512,"mc":[{"id":"1.168224295","rc":[{"batb":[[1,1.01,0.51],[2,1.33,0]],"ltp":1.55,"tv":44.66,"id":13010435}]}]}
{"op":"mcm","clk":"1005769367","pt":1580644566321,"mc":[{"id":"1.168224295","rc":[{"batb":[[0,1.63,28.8],[1,1.62,122.44],[2,1.61,70.06]],"batl":[[1,1.81,22.82]],"ltp":1.55,"tv":44.66,"id":13010435},{"batb":[[2,4.2,19.67]],"batl":[[0,5.2,15.42],[1,6,11.09],[2,8,12.83]],"ltp":5.2,"tv":25.2,"id":13010434},{"batl":[[0,5.5,14.01],[1,6.4,10.39],[2,8.2,12.59]],"ltp":5.9,"tv":68.06,"id":17293892}]}]}
{"op":"mcm","clk":"1005769437","pt":1580644566846,"mc":[{"id":"1.168224295","rc":[{"batb":[[2,4.4,11.76]],"batl":[[0,5.1,10.08],[1,5.2,15.42],[2,6,11.09]],"ltp":5.2,"tv":25.2,"id":13010434},{"batb":[[1,5,44.33]],"batl":[[1,5.9,8.4],[2,6.4,10.39]],"ltp":5.9,"tv":68.06,"id":17293892}]}]}
{"op":"mcm","clk":"1005769697","pt":1580644568753,"mc":[{"id":"1.168224295","rc":[{"batb":[[0,1.01,0.51],[1,1.01,0]],"ltp":0.0,"tv":0.0,"id":17293893}]}]}
{"op":"mcm","clk":"1005771914","pt":1580644584400,"mc":[{"id":"1.168224295","rc":[{"batb":[[0,1.5,39.18],[1,1.01,0.51],[2,1.61,0]],"batl":[[0,1.81,22.82],[1,1.81,0]],"ltp":1.55,"tv":44.66,"id":13010435},{"batb":[[0,4.2,19.67],[1,1.01,0.51],[2,4.4,0]],"batl":[[0,6,11.09],[1,5.2,0],[2,6,0]],"ltp":5.2,"tv":25.2,"id":13010434},{"batb":[[0,4.4,17.86],[1,1.01,0.51],[2,4.8,0]],"batl":[[0,6.4,10.39],[1,5.9,0],[2,6.4,0]],"ltp":5.9,"tv":68.06,"id":17293892}]}]}
{"op":"mcm","clk":"1005772267","pt":1580644586658,"mc":[{"id":"1.168224295","rc":[{"batb":[[1,1.49,107.03],[2,1.48,97.42]],"ltp":1.55,"tv":44.66,"id":13010435},{"batb":[[0,4.2,69.39],[1,4.1,49.64],[2,1.01,0.51]],"ltp":5.2,"tv":25.2,"id":13010434},{"batb":[[0,4.7,37.25],[1,4.6,41.53],[2,4.4,17.86]],"ltp":5.9,"tv":68.06,"id":17293892}]}]}
{"op":"mcm","clk":"1005774221","pt":1580644601191,"mc":[{"id":"1.168224295","rc":[{"batb":[[0,4.2,19.67],[1,1.01,0.51],[2,1.01,0]],"ltp":5.2,"tv":25.2,"id":13010434},{"batb":[[0,4.4,17.86],[1,1.01,0.51],[2,4.4,0]],"ltp":5.9,"tv":68.06,"id":17293892}]}]}
{"op":"mcm","clk":"1005774638","pt":1580644604313,"mc":[{"id":"1.168224295","rc":[{"batb":[[0,5.3,45.43],[1,5.2,28.69],[2,4.2,19.67]],"ltp":5.2,"tv":25.2,"id":13010434},{"batb":[[0,6,27.31],[1,5.9,23.93],[2,4.4,17.86]],"ltp":5.9,"tv":68.06,"id":17293892}]}]}
{"op":"mcm","clk":"1005774766","pt":1580644605099,"mc":[{"id":"1.168224295","rc":[{"batb":[[0,1.5,123.2]],"batl":[[0,1.56,38.24],[1,1.7,28.25]],"ltp":1.55,"tv":44.66,"id":13010435},{"batb":[[0,5.3,57],[2,4.9,10.08]],"batl":[[0,5.8,8.4],[1,6,11.09],[2,8,12.75]],"ltp":5.2,"tv":25.2,"id":13010434},{"batb":[[2,5.5,20.02]],"batl":[[1,6.6,6.72],[2,8.4,12.04]],"ltp":5.9,"tv":68.06,"id":17293892}]}]}
{"op":"mcm","clk":"1005774905","pt":1580644606098,"mc":[{"id":"1.168224295","rc":[{"batb":[[0,9,13.44],[1,1.01,0.51]],"ltp":0.0,"tv":0.0,"id":17293893}]}]}
{"op":"mcm","clk":"1005776260","pt":1580644616337,"mc":[{"id":"1.168224295","rc":[{"batb":[[0,1.34,62.79],[1,1.01,0.51],[2,1.48,0]],"batl":[[0,1.7,28.25],[1,1.7,0]],"ltp":1.55,"tv":44.66,"id":13010435},{"batb":[[0,4.6,15.82],[1,1.01,0.51],[2,4.9,0]],"batl":[[0,8,12.75],[1,6,0],[2,8,0]],"ltp":5.2,"tv":25.2,"id":13010434},{"batb":[[0,4.8,14.79],[1,1.01,0.51],[2,5.5,0]],"batl":[[0,8.4,12.04],[1,6.6,0],[2,8.4,0]],"ltp":5.9,"tv":68.06,"id":17293892}]}]}
{"op":"mcm","clk":"1005776568","pt":1580644618815,"mc":[{"id":"1.168224295","rc":[{"batb":[[0,1.34,152.3],[1,1.33,158.82],[2,1.01,0.51]],"ltp":1.55,"tv":44.66,"id":13010435},{"batb":[[0,4.6,63.33],[1,4.5,39.95],[2,1.01,0.51]],"ltp":5.2,"tv":25.2,"id":13010434},{"batb":[[0,5.2,31.93],[1,5.1,32.99],[2,4.8,14.79]],"ltp":5.9,"tv":68.06,"id":17293892}]}]}
{"op":"mcm","clk":"1005776865","pt":1580644621311,"mc":[{"id":"1.168224295","rc":[{"batb":[[0,1.34,62.79],[1,1.01,0.51],[2,1.01,0]],"ltp":1.55,"tv":44.66,"id":13010435},{"batb":[[0,4.6,15.82],[1,1.01,0.51],[2,1.01,0]],"ltp":5.2,"tv":25.2,"id":13010434},{"batb":[[0,4.8,14.79],[1,1.01,0.51],[2,4.8,0]],"ltp":5.9,"tv":68.06,"id":17293892}]}]}
{"op":"mcm","clk":"1005777258","pt":1580644624361,"mc":[{"id":"1.168224295","rc":[{"batb":[[0,1.46,75.18],[1,1.45,106],[2,1.34,62.79]],"ltp":1.55,"tv":44.66,"id":13010435},{"batb":[[0,5.6,31.58],[1,5.5,25.46],[2,4.6,15.82]],"ltp":5.2,"tv":25.2,"id":13010434},{"batb":[[0,6.2,44.52],[1,6,44.93],[2,4.8,14.79]],"ltp":5.9,"tv":68.06,"id":17293892}]}]}
{"op":"mcm","clk":"1005777339","pt":1580644624927,"mc":[{"id":"1.168224295","rc":[{"batb":[[0,1.34,62.79],[1,1.01,0.51],[2,1.34,0]],"ltp":1.55,"tv":44.66,"id":13010435},{"batb":[[0,4.6,15.82],[1,1.01,0.51],[2,4.6,0]],"ltp":5.2,"tv":25.2,"id":13010434},{"batb":[[0,4.8,14.79],[1,1.01,0.51],[2,4.8,0]],"ltp":5.9,"tv":68.06,"id":17293892}]}]}
{"op":"mcm","clk":"1005777427","pt":1580644625754,"mc":[{"id":"1.168224295","rc":[{"batb":[[0,1.34,152.3],[1,1.33,158.82],[2,1.01,0.51]],"ltp":1.55,"tv":44.66,"id":13010435},{"batb":[[0,4.6,63.33],[1,4.5,39.95],[2,1.01,0.51]],"ltp":5.2,"tv":25.2,"id":13010434},{"batb":[[0,5.2,31.93],[1,5.1,32.99],[2,4.8,14.79]],"ltp":5.9,"tv":68.06,"id":17293892}]}]}
{"op":"mcm","clk":"1005778256","pt":1580644632847,"mc":[{"id":"1.168224295","rc":[{"batb":[[0,1.34,62.79],[1,1.01,0.51],[2,1.01,0]],"ltp":1.55,"tv":44.66,"id":13010435}]}]}
{"op":"mcm","clk":"1005778661","pt":1580644635943,"mc":[{"id":"1.168224295","rc":[{"batb":[[0,1.62,70.36],[1,1.61,69.89],[2,1.34,62.79]],"ltp":1.55,"tv":44.66,"id":13010435}]}]}
{"op":"mcm","clk":"1005778792","pt":1580644636825,"mc":[{"id":"1.168224295","rc":[{"batb":[[0,1.63,28.88],[1,1.62,70.36],[2,1.61,69.89]],"batl":[[1,1.8,23.13]],"ltp":1.55,"tv":44.66,"id":13010435},{"batb":[[2,4.4,11.76]],"batl":[[0,5.1,10.08],[1,5.3,15.11],[2,6.2,11.09]],"ltp":5.2,"tv":25.2,"id":13010434},{"batl":[[0,5.5,14.16],[1,6,8.4],[2,6.4,20.54]],"ltp":5.9,"tv":68.06,"id":17293892}]}]}
{"op":"mcm","clk":"1005780923","pt":1580644653043,"mc":[{"id":"1.168224295","rc":[{"batb":[[1,1.6,69.74],[2,1.49,39.5]],"ltp":1.55,"tv":44.66,"id":13010435},{"batb":[[0,4.6,15.82],[1,4.4,11.76],[2,4.3,19.28]],"ltp":5.2,"tv":25.2,"id":13010434},{"batb":[[0,4.8,14.79],[1,4.4,17.86],[2,1.01,0.51]],"ltp":5.9,"tv":68.06,"id":17293892}]}]}
{"op":"mcm","clk":"1005781042","pt":1580644653830,"mc":[{"id":"1.168224295","rc":[{"batb":[[0,1.49,39.5],[1,1.01,0.51],[2,1.49,0]],"batl":[[0,1.8,23.13],[1,1.8,0]],"ltp":1.55,"tv":44.66,"id":13010435},{"batb":[[0,4.3,19.28],[1,1.01,0.51],[2,4.3,0]],"batl":[[0,6.2,11.09],[1,5.3,0],[2,6.2,0]],"ltp":5.2,"tv":25.2,"id":13010434},{"batb":[[0,4.4,17.86],[1,1.01,0.51],[2,1.01,0]],"batl":[[0,6.4,20.54],[1,6,0],[2,6.4,0]],"ltp":5.9,"tv":68.06,"id":17293892}]}]}
{"op":"mcm","clk":"1005781299","pt":1580644655931,"mc":[{"id":"1.168224295","rc":[{"batb":[[1,1.48,143.67],[2,1.47,100.46]],"ltp":1.55,"tv":44.66,"id":13010435},{"batb":[[1,4.2,56.47],[2,4.1,49.51]],"ltp":5.2,"tv":25.2,"id":13010434},{"batb":[[0,4.7,54.66],[1,4.6,41.26],[2,4.4,17.86]],"ltp":5.9,"tv":68.06,"id":17293892}]}]}
{"op":"mcm","clk":"1005782047","pt":1580644661955,"mc":[{"id":"1.168224295","rc":[{"batb":[[1,1.01,0.51],[2,4.1,0]],"ltp":5.2,"tv":25.2,"id":13010434},{"batb":[[0,4.4,17.86],[1,1.01,0.51],[2,4.4,0]],"ltp":5.9,"tv":68.06,"id":17293892}]}]}
{"op":"mcm","clk":"1005782479","pt":1580644665365,"mc":[{"id":"1.168224295","rc":[{"batb":[[0,1.5,84.02],[1,1.49,39.5],[2,1.48,143.67]],"batl":[[0,1.56,38.48],[1,1.69,28.64]],"ltp":1.55,"tv":44.66,"id":13010435},{"batb":[[0,5.4,25.98],[1,5.3,39.25],[2,4.9,10.08]],"batl":[[0,5.8,8.4],[1,6.2,11.09],[2,8,12.59]],"ltp":5.2,"tv":25.2,"id":13010434},{"batb":[[0,6,43.3],[1,5.9,23.72],[2,5.5,19.86]],"batl":[[1,6.6,6.72],[2,8.4,11.96]],"ltp":5.9,"tv":68.06,"id":17293892}]}]}
