{"op":"mcm","clk":"1001176140","pt":1580585265724,"mc":[{"id":"1.168224297","marketDefinition":{"bspMarket":false,"turnInPlayEnabled":true,"persistenceEnabled":true,"marketBaseRate":5.0,"eventId":"29681712","eventTypeId":"2","numberOfWinners":1,"bettingType":"ODDS","marketType":"SET_WINNER","marketTime":"2020-02-02T09:00:00.000Z","suspendTime":"2020-02-02T09:00:00.000Z","bspReconciled":false,"complete":true,"inPlay":false,"crossMatching":false,"runnersVoidable":false,"numberOfActiveRunners":2,"betDelay":0,"status":"OPEN","runners":[{"status":"ACTIVE","sortPriority":1,"id":10303696,"name":"Hugo Gaston"},{"status":"ACTIVE","sortPriority":2,"id":2257317,"name":"Nicolas Mahut"}],"regulators":["MR_INT"],"countryCode":"FR","discountAllowed":false,"timezone":"UTC","openDate":"2020-02-02T09:00:00.000Z","version":3147097873,"name":"Set 2 Winner","eventName":"Hug Gaston v Mahut"},"rc":[{"batb":[[0,1.01,20]],"ltp":0.0,"tv":0.0,"id":2257317},{"batb":[[0,1.01,20]],"ltp":0.0,"tv":0.0,"id":10303696}]}]}
{"op":"mcm","clk":"1001176494","pt":1580585267445,"mc":[{"id":"1.168224297","marketDefinition":{"bspMarket":false,"turnInPlayEnabled":true,"persistenceEnabled":true,"marketBaseRate":5.0,"eventId":"29681712","eventTypeId":"2","numberOfWinners":1,"bettingType":"ODDS","marketType":"SET_WINNER","marketTime":"2020-02-02T09:00:00.000Z","suspendTime":"2020-02-02T09:00:00.000Z","bspReconciled":false,"complete":true,"inPlay":false,"crossMatching":false,"runnersVoidable":false,"numberOfActiveRunners":2,"betDelay":0,"status":"OPEN","runners":[{"status":"ACTIVE","sortPriority":1,"id":10303696,"name":"Hugo Gaston"},{"status":"ACTIVE","sortPriority":2,"id":2257317,"name":"Nicolas Mahut"}],"regulators":["MR_INT"],"countryCode":"FR","discountAllowed":false,"timezone":"UTC","openDate":"2020-02-02T09:00:00.000Z","version":3147097873,"name":"Set 2 Winner","eventName":"Hug Gaston v Mahut"}}]}
{"op":"mcm","clk":"1001177167","pt":1580585270503,"mc":[{"id":"1.168224297","marketDefinition":{"bspMarket":false,"turnInPlayEnabled":true,"persistenceEnabled":true,"marketBaseRate":5.0,"eventId":"29681712","eventTypeId":"2","numberOfWinners":1,"bettingType":"ODDS","marketType":"SET_WINNER","marketTime":"2020-02-02T09:00:00.000Z","suspendTime":"2020-02-02T09:00:00.000Z","bspReconciled":false,"complete":true,"inPlay":false,"crossMatching":false,"runnersVoidable":false,"numberOfActiveRunners":2,"betDelay":0,"status":"OPEN","runners":[{"status":"ACTIVE","sortPriority":1,"id":10303696,"name":"Hugo Gaston"},{"status":"ACTIVE","sortPriority":2,"id":2257317,"name":"Nicolas Mahut"}],"regulators":["MR_INT"],"countryCode":"FR","discountAllowed":true,"timezone":"UTC","openDate":"2020-02-02T09:00:00.000Z","version":3147097873,"name":"Set 2 Winner","eventName":"Hug Gaston v Mahut"}}]}
{"op":"mcm","clk":"1001204315","pt":1580585416134,"mc":[{"id":"1.168224297","rc":[{"batb":[[0,1.01,15]],"ltp":0.0,"tv":0.0,"id":2257317},{"batb":[[0,1.01,15]],"ltp":0.0,"tv":0.0,"id":10303696}]}]}
{"op":"mcm","clk":"1001221984","pt":1580585512416,"mc":[{"id":"1.168224297","marketDefinition":{"bspMarket":false,"turnInPlayEnabled":true,"persistenceEnabled":true,"marketBaseRate":5.0,"eventId":"29681712","eventTypeId":"2","numberOfWinners":1,"bettingType":"ODDS","marketType":"SET_WINNER","marketTime":"2020-02-02T11:30:00.000Z","suspendTime":"2020-02-02T11:30:00.000Z","bspReconciled":false,"complete":true,"inPlay":false,"crossMatching":false,"runnersVoidable":false,"numberOfActiveRunners":2,"betDelay":0,"status":"OPEN","runners":[{"status":"ACTIVE","sortPriority":1,"id":10303696,"name":"Hugo Gaston"},{"status":"ACTIVE","sortPriority":2,"id":2257317,"name":"Nicolas Mahut"}],"regulators":["MR_INT"],"countryCode":"FR","discountAllowed":true,"timezone":"UTC","openDate":"2020-02-02T09:00:00.000Z","version":3147124633,"name":"Set 2 Winner","eventName":"Hug Gaston v Mahut"}}]}
{"op":"mcm","clk":"1001222392","pt":1580585514425,"mc":[{"id":"1.168224297","marketDefinition":{"bspMarket":false,"turnInPlayEnabled":true,"persistenceEnabled":true,"marketBaseRate":5.0,"eventId":"29681712","eventTypeId":"2","numberOfWinners":1,"bettingType":"ODDS","marketType":"SET_WINNER","marketTime":"2020-02-02T11:30:00.000Z","suspendTime":"2020-02-02T11:30:00.000Z","bspReconciled":false,"complete":true,"inPlay":false,"crossMatching":false,"runnersVoidable":false,"numberOfActiveRunners":2,"betDelay":0,"status":"OPEN","runners":[{"status":"ACTIVE","sortPriority":1,"id":10303696,"name":"Hugo Gaston"},{"status":"ACTIVE","sortPriority":2,"id":2257317,"name":"Nicolas Mahut"}],"regulators":["MR_INT"],"countryCode":"FR","discountAllowed":true,"timezone":"UTC","openDate":"2020-02-02T11:30:00.000Z","version":3147124633,"name":"Set 2 Winner","eventName":"Hug Gaston v Mahut"}}]}
{"op":"mcm","clk":"1003032708","pt":1580602187338,"mc":[{"id":"1.168224297","rc":[{"batb":[[0,1.01,17.53]],"ltp":0.0,"tv":0.0,"id":2257317},{"batb":[[0,1.01,17.53]],"ltp":0.0,"tv":0.0,"id":10303696}]}]}
{"op":"mcm","clk":"1003032806","pt":1580602188370,"mc":[{"id":"1.168224297","rc":[{"batb":[[0,1.01,15.51]],"ltp":0.0,"tv":0.0,"id":2257317},{"batb":[[0,1.01,15.51]],"ltp":0.0,"tv":0.0,"id":10303696}]}]}
{"op":"mcm","clk":"1003160475","pt":1580603727376,"mc":[{"id":"1.168224297","rc":[{"batb":[[0,1.01,18.04]],"ltp":0.0,"tv":0.0,"id":2257317},{"batb":[[0,1.01,18.04]],"ltp":0.0,"tv":0.0,"id":10303696}]}]}
{"op":"mcm","clk":"1003160544","pt":1580603728156,"mc":[{"id":"1.168224297","rc":[{"batb":[[0,1.01,16.01]],"ltp":0.0,"tv":0.0,"id":2257317},{"batb":[[0,1.01,16.01]],"ltp":0.0,"tv":0.0,"id":10303696}]}]}
{"op":"mcm","clk":"1003389769","pt":1580607093375,"mc":[{"id":"1.168224297","rc":[{"batb":[[0,1.01,18.01]],"ltp":0.0,"tv":0.0,"id":2257317},{"batb":[[0,1.01,18.01]],"ltp":0.0,"tv":0.0,"id":10303696}]}]}
{"op":"mcm","clk":"1003389825","pt":1580607093946,"mc":[{"id":"1.168224297","rc":[{"batb":[[0,1.01,16.02]],"ltp":0.0,"tv":0.0,"id":2257317},{"batb":[[0,1.01,16.02]],"ltp":0.0,"tv":0.0,"id":10303696}]}]}
{"op":"mcm","clk":"1004691909","pt":1580635315872,"mc":[{"id":"1.168224297","marketDefinition":{"bspMarket":false,"turnInPlayEnabled":true,"persistenceEnabled":true,"marketBaseRate":5.0,"eventId":"29681712","eventTypeId":"2","numberOfWinners":1,"bettingType":"ODDS","marketType":"SET_WINNER","marketTime":"2020-02-02T11:19:00.000Z","suspendTime":"2020-02-02T11:19:00.000Z","bspReconciled":false,"complete":true,"inPlay":false,"crossMatching":false,"runnersVoidable":false,"numberOfActiveRunners":2,"betDelay":0,"status":"OPEN","runners":[{"status":"ACTIVE","sortPriority":1,"id":10303696,"name":"Hugo Gaston"},{"status":"ACTIVE","sortPriority":2,"id":2257317,"name":"Nicolas Mahut"}],"regulators":["MR_INT"],"countryCode":"FR","discountAllowed":true,"timezone":"UTC","openDate":"2020-02-02T11:30:00.000Z","version":3148342770,"name":"Set 2 Winner","eventName":"Hug Gaston v Mahut"}}]}
{"op":"mcm","clk":"1004692044","pt":1580635317946,"mc":[{"id":"1.168224297","marketDefinition":{"bspMarket":false,"turnInPlayEnabled":true,"persistenceEnabled":true,"marketBaseRate":5.0,"eventId":"29681712","eventTypeId":"2","numberOfWinners":1,"bettingType":"ODDS","marketType":"SET_WINNER","marketTime":"2020-02-02T11:19:00.000Z","suspendTime":"2020-02-02T11:19:00.000Z","bspReconciled":false,"complete":true,"inPlay":false,"crossMatching":false,"runnersVoidable":false,"numberOfActiveRunners":2,"betDelay":0,"status":"OPEN","runners":[{"status":"ACTIVE","sortPriority":1,"id":10303696,"name":"Hugo Gaston"},{"status":"ACTIVE","sortPriority":2,"id":2257317,"name":"Nicolas Mahut"}],"regulators":["MR_INT"],"countryCode":"FR","discountAllowed":true,"timezone":"UTC","openDate":"2020-02-02T11:19:00.000Z","version":3148342770,"name":"Set 2 Winner","eventName":"Hug Gaston v Mahut"}}]}
{"op":"mcm","clk":"1005237285","pt":1580641615820,"mc":[{"id":"1.168224297","marketDefinition":{"bspMarket":false,"turnInPlayEnabled":true,"persistenceEnabled":true,"marketBaseRate":5.0,"eventId":"29681712","eventTypeId":"2","numberOfWinners":1,"bettingType":"ODDS","marketType":"SET_WINNER","marketTime":"2020-02-02T11:10:00.000Z","suspendTime":"2020-02-02T11:10:00.000Z","bspReconciled":false,"complete":true,"inPlay":false,"crossMatching":false,"runnersVoidable":false,"numberOfActiveRunners":2,"betDelay":0,"status":"OPEN","runners":[{"status":"ACTIVE","sortPriority":1,"id":10303696,"name":"Hugo Gaston"},{"status":"ACTIVE","sortPriority":2,"id":2257317,"name":"Nicolas Mahut"}],"regulators":["MR_INT"],"countryCode":"FR","discountAllowed":true,"timezone":"UTC","openDate":"2020-02-02T11:19:00.000Z","version":3148499319,"name":"Set 2 Winner","eventName":"Hug Gaston v Mahut"}}]}
{"op":"mcm","clk":"1005237918","pt":1580641618828,"mc":[{"id":"1.168224297","marketDefinition":{"bspMarket":false,"turnInPlayEnabled":true,"persistenceEnabled":true,"marketBaseRate":5.0,"eventId":"29681712","eventTypeId":"2","numberOfWinners":1,"bettingType":"ODDS","marketType":"SET_WINNER","marketTime":"2020-02-02T11:10:00.000Z","suspendTime":"2020-02-02T11:10:00.000Z","bspReconciled":false,"complete":true,"inPlay":false,"crossMatching":false,"runnersVoidable":false,"numberOfActiveRunners":2,"betDelay":0,"status":"OPEN","runners":[{"status":"ACTIVE","sortPriority":1,"id":10303696,"name":"Hugo Gaston"},{"status":"ACTIVE","sortPriority":2,"id":2257317,"name":"Nicolas Mahut"}],"regulators":["MR_INT"],"countryCode":"FR","discountAllowed":true,"timezone":"UTC","openDate":"2020-02-02T11:10:00.000Z","version":3148499319,"name":"Set 2 Winner","eventName":"Hug Gaston v Mahut"}}]}
{"op":"mcm","clk":"1005278032","pt":1580641823336,"mc":[{"id":"1.168224297","rc":[{"batb":[[0,1.84,18.25],[1,1.01,16.02]],"ltp":0.0,"tv":0.0,"id":2257317},{"batb":[[0,2.04,26.44],[1,1.01,16.02]],"ltp":0.0,"tv":0.0,"id":10303696}]}]}
{"op":"mcm","clk":"1005281397","pt":1580641841436,"mc":[{"id":"1.168224297","marketDefinition":{"bspMarket":false,"turnInPlayEnabled":true,"persistenceEnabled":true,"marketBaseRate":5.0,"eventId":"29681712","eventTypeId":"2","numberOfWinners":1,"bettingType":"ODDS","marketType":"SET_WINNER","marketTime":"2020-02-02T11:10:00.000Z","suspendTime":"2020-02-02T11:10:00.000Z","bspReconciled":false,"complete":true,"inPlay":false,"crossMatching":true,"runnersVoidable":false,"numberOfActiveRunners":2,"betDelay":0,"status":"OPEN","runners":[{"status":"ACTIVE","sortPriority":1,"id":10303696,"name":"Hugo Gaston"},{"status":"ACTIVE","sortPriority":2,"id":2257317,"name":"Nicolas Mahut"}],"regulators":["MR_INT"],"countryCode":"FR","discountAllowed":true,"timezone":"UTC","openDate":"2020-02-02T11:10:00.000Z","version":3148499319,"name":"Set 2 Winner","eventName":"Hug Gaston v Mahut"}}]}
{"op":"mcm","clk":"1005286499","pt":1580641868328,"mc":[{"id":"1.168224297","rc":[{"batb":[[0,1.85,18.02],[1,1.84,18.25],[2,1.01,16.02]],"ltp":0.0,"tv":0.0,"id":2257317},{"batb":[[0,2.02,26.91]],"ltp":0.0,"tv":0.0,"id":10303696}]}]}
{"op":"mcm","clk":"1005288384","pt":1580641878348,"mc":[{"id":"1.168224297","rc":[{"batb":[[0,1.86,17.7],[1,1.85,18.02]],"ltp":0.0,"tv":0.0,"id":2257317}]}]}
{"op":"mcm","clk":"1005290305","pt":1580641888350,"mc":[{"id":"1.168224297","rc":[{"batb":[[0,1.86,17.55],[1,1.01,16.02],[2,1.01,0]],"ltp":0.0,"tv":0.0,"id":2257317}]}]}
{"op":"mcm","clk":"1005295265","pt":1580641914070,"mc":[{"id":"1.168224297","marketDefinition":{"bspMarket":false,"turnInPlayEnabled":true,"persistenceEnabled":true,"marketBaseRate":5.0,"eventId":"29681712","eventTypeId":"2","numberOfWinners":1,"bettingType":"ODDS","marketType":"SET_WINNER","marketTime":"2020-02-02T11:08:00.000Z","suspendTime":"2020-02-02T11:08:00.000Z","bspReconciled":false,"complete":true,"inPlay":false,"crossMatching":true,"runnersVoidable":false,"numberOfActiveRunners":2,"betDelay":0,"status":"OPEN","runners":[{"status":"ACTIVE","sortPriority":1,"id":10303696,"name":"Hugo Gaston"},{"status":"ACTIVE","sortPriority":2,"id":2257317,"name":"Nicolas Mahut"}],"regulators":["MR_INT"],"countryCode":"FR","discountAllowed":true,"timezone":"UTC","openDate":"2020-02-02T11:10:00.000Z","version":3148508264,"name":"Set 2 Winner","eventName":"Hug Gaston v Mahut"}}]}
{"op":"mcm","clk":"1005295749","pt":1580641916624,"mc":[{"id":"1.168224297","marketDefinition":{"bspMarket":false,"turnInPlayEnabled":true,"persistenceEnabled":true,"marketBaseRate":5.0,"eventId":"29681712","eventTypeId":"2","numberOfWinners":1,"bettingType":"ODDS","marketType":"SET_WINNER","marketTime":"2020-02-02T11:08:00.000Z","suspendTime":"2020-02-02T11:08:00.000Z","bspReconciled":false,"complete":true,"inPlay":false,"crossMatching":true,"runnersVoidable":false,"numberOfActiveRunners":2,"betDelay":0,"status":"OPEN","runners":[{"status":"ACTIVE","sortPriority":1,"id":10303696,"name":"Hugo Gaston"},{"status":"ACTIVE","sortPriority":2,"id":2257317,"name":"Nicolas Mahut"}],"regulators":["MR_INT"],"countryCode":"FR","discountAllowed":true,"timezone":"UTC","openDate":"2020-02-02T11:08:00.000Z","version":3148508264,"name":"Set 2 Winner","eventName":"Hug Gaston v Mahut"}}]}
{"op":"mcm","clk":"1005299284","pt":1580641936272,"mc":[{"id":"1.168224297","rc":[{"batb":[[1,1.01,17.7]],"ltp":0.0,"tv":0.0,"id":2257317},{"batb":[[1,1.01,17.7]],"ltp":0.0,"tv":0.0,"id":10303696}]}]}
{"op":"mcm","clk":"1005299499","pt":1580641937384,"mc":[{"id":"1.168224297","rc":[{"batb":[[0,1.87,1.34],[1,1.86,17.55],[2,1.01,16.02]],"ltp":0.0,"tv":0.0,"id":2257317},{"batb":[[0,2.04,1.24],[1,2.02,26.91],[2,1.01,16.02]],"ltp":0.0,"tv":0.0,"id":10303696}]}]}
{"op":"mcm","clk":"1005299870","pt":1580641939348,"mc":[{"id":"1.168224297","rc":[{"batb":[[1,1.85,17.94]],"ltp":0.0,"tv":0.0,"id":2257317}]}]}
{"op":"mcm","clk":"1005324117","pt":1580642078032,"mc":[{"id":"1.168224297","rc":[{"batb":[[2,1.84,18.18]],"ltp":0.0,"tv":0.0,"id":2257317},{"batb":[[0,2.04,27.91]],"ltp":0.0,"tv":0.0,"id":10303696}]}]}
{"op":"mcm","clk":"1005335757","pt":1580642143190,"mc":[{"id":"1.168224297","rc":[{"batb":[[0,2.04,1.24]],"ltp":0.0,"tv":0.0,"id":10303696}]}]}
{"op":"mcm","clk":"1005340337","pt":1580642168995,"mc":[{"id":"1.168224297","rc":[{"batb":[[2,1.01,16.02]],"ltp":0.0,"tv":0.0,"id":2257317}]}]}
{"op":"mcm","clk":"1005342581","pt":1580642180737,"mc":[{"id":"1.168224297","rc":[{"batb":[[2,1.82,50.41]],"batl":[[0,2,42.01]],"ltp":0.0,"tv":0.0,"id":2257317},{"batb":[[2,2,42.01]],"batl":[[0,2.24,33.61]],"ltp":0.0,"tv":0.0,"id":10303696}]}]}
{"op":"mcm","clk":"1005345137","pt":1580642194229,"mc":[{"id":"1.168224297","rc":[{"batb":[[2,1.84,18.25]],"ltp":0.0,"tv":0.0,"id":2257317},{"batb":[[0,2.04,27.75]],"ltp":0.0,"tv":0.0,"id":10303696}]}]}
{"op":"mcm","clk":"1005348091","pt":1580642210398,"mc":[{"id":"1.168224297","rc":[{"batb":[[1,1.86,2],[2,1.85,17.94]],"ltp":0.0,"tv":0.0,"id":2257317},{"batb":[[0,2.06,2],[1,2.04,27.75],[2,2.02,26.91]],"ltp":0.0,"tv":0.0,"id":10303696}]}]}
{"op":"mcm","clk":"1005359050","pt":1580642270265,"mc":[{"id":"1.168224297","rc":[{"batb":[[1,1.85,17.94],[2,1.84,18.25]],"ltp":0.0,"tv":0.0,"id":2257317},{"batb":[[0,2.04,27.75],[1,2.02,26.91],[2,2,42.01]],"ltp":0.0,"tv":0.0,"id":10303696}]}]}
{"op":"mcm","clk":"1005361714","pt":1580642284125,"mc":[{"id":"1.168224297","rc":[{"batb":[[1,1.86,2],[2,1.85,17.94]],"ltp":0.0,"tv":0.0,"id":2257317},{"batb":[[0,2.06,2],[1,2.04,27.75],[2,2.02,26.91]],"ltp":0.0,"tv":0.0,"id":10303696}]}]}
{"op":"mcm","clk":"1005373216","pt":1580642343236,"mc":[{"id":"1.168224297","rc":[{"batb":[[1,1.85,17.94],[2,1.84,18.25]],"ltp":0.0,"tv":0.0,"id":2257317}]}]}
{"op":"mcm","clk":"1005373437","pt":1580642344347,"mc":[{"id":"1.168224297","rc":[{"batb":[[0,2.04,27.75],[1,2.02,26.91],[2,2,42.01]],"ltp":0.0,"tv":0.0,"id":10303696}]}]}
{"op":"mcm","clk":"1005387359","pt":1580642418354,"mc":[{"id":"1.168224297","rc":[{"batb":[[0,2.04,1.24]],"ltp":0.0,"tv":0.0,"id":10303696}]}]}
{"op":"mcm","clk":"1005389093","pt":1580642428061,"mc":[{"id":"1.168224297","rc":[{"batb":[[1,1.82,50.41],[2,1.01,16.02]],"ltp":0.0,"tv":0.0,"id":2257317},{"batb":[[1,2,42.01],[2,1.01,16.02]],"ltp":0.0,"tv":0.0,"id":10303696}]}]}
{"op":"mcm","clk":"1005389199","pt":1580642428705,"mc":[{"id":"1.168224297","marketDefinition":{"bspMarket":false,"turnInPlayEnabled":true,"persistenceEnabled":true,"marketBaseRate":5.0,"eventId":"29681712","eventTypeId":"2","numberOfWinners":1,"bettingType":"ODDS","marketType":"SET_WINNER","marketTime":"2020-02-02T11:08:00.000Z","suspendTime":"2020-02-02T11:08:00.000Z","bspReconciled":false,"complete":true,"inPlay":true,"crossMatching":true,"runnersVoidable":false,"numberOfActiveRunners":2,"betDelay":3,"status":"OPEN","runners":[{"status":"ACTIVE","sortPriority":1,"id":10303696,"name":"Hugo Gaston"},{"status":"ACTIVE","sortPriority":2,"id":2257317,"name":"Nicolas Mahut"}],"regulators":["MR_INT"],"countryCode":"FR","discountAllowed":true,"timezone":"UTC","openDate":"2020-02-02T11:08:00.000Z","version":3148525258,"name":"Set 2 Winner","eventName":"Hug Gaston v Mahut"},"rc":[{"batb":[[0,1.01,15.52],[1,1.82,0],[2,1.01,0]],"ltp":0.0,"tv":0.0,"id":2257317},{"batb":[[0,1.01,15.52],[1,2,0],[2,1.01,0]],"ltp":0.0,"tv":0.0,"id":10303696}]}]}
{"op":"mcm","clk":"1005391132","pt":1580642439381,"mc":[{"id":"1.168224297","rc":[{"batb":[[0,1.89,16.84],[1,1.84,18.25],[2,1.01,15.52]],"ltp":0.0,"tv":0.0,"id":2257317},{"batb":[[0,1.99,28.8],[1,1.96,29.9],[2,1.01,15.52]],"ltp":0.0,"tv":0.0,"id":10303696}]}]}
{"op":"mcm","clk":"1005391169","pt":1580642439597,"mc":[{"id":"1.168224297","rc":[{"batb":[[2,1.83,50.41]],"batl":[[0,2.04,40.33]],"ltp":0.0,"tv":0.0,"id":2257317},{"batb":[[1,1.96,73.59]],"batl":[[0,2.2,34.45]],"ltp":0.0,"tv":0.0,"id":10303696}]}]}
{"op":"mcm","clk":"1005392607","pt":1580642447277,"mc":[{"id":"1.168224297","rc":[{"batb":[[0,1.84,18.25],[1,1.83,50.41],[2,1.01,15.52]],"ltp":0.0,"tv":0.0,"id":2257317},{"batb":[[0,1.96,73.59],[1,1.01,15.52],[2,1.01,0]],"ltp":0.0,"tv":0.0,"id":10303696}]}]}
{"op":"mcm","clk":"1005392859","pt":1580642448667,"mc":[{"id":"1.168224297","rc":[{"batb":[[1,1.01,15.52],[2,1.01,0]],"ltp":0.0,"tv":0.0,"id":2257317},{"batb":[[0,1.96,29.9]],"ltp":0.0,"tv":0.0,"id":10303696}]}]}
{"op":"mcm","clk":"1005395475","pt":1580642463030,"mc":[{"id":"1.168224297","rc":[{"batb":[[1,1.79,19.99],[2,1.01,15.52]],"ltp":0.0,"tv":0.0,"id":2257317},{"batb":[[0,2.04,26.44],[1,2,27.62],[2,1.01,15.52]],"ltp":0.0,"tv":0.0,"id":10303696}]}]}
{"op":"mcm","clk":"1005395627","pt":1580642463923,"mc":[{"id":"1.168224297","rc":[{"batb":[[1,1.79,72.92]],"batl":[[0,1.99,42.01]],"ltp":0.0,"tv":0.0,"id":2257317},{"batb":[[1,2.02,41.17],[2,2,27.62]],"batl":[[0,2.26,32.77]],"ltp":0.0,"tv":0.0,"id":10303696}]}]}
{"op":"mcm","clk":"1005397004","pt":1580642471757,"mc":[{"id":"1.168224297","rc":[{"batb":[[0,1.79,72.92],[1,1.01,15.52],[2,1.01,0]],"ltp":0.0,"tv":0.0,"id":2257317},{"batb":[[0,2.02,41.17],[1,2,27.62],[2,1.01,15.52]],"ltp":0.0,"tv":0.0,"id":10303696}]}]}
{"op":"mcm","clk":"1005397159","pt":1580642472550,"mc":[{"id":"1.168224297","rc":[{"batb":[[0,1.79,19.99]],"ltp":0.0,"tv":0.0,"id":2257317},{"batb":[[0,2,27.62],[1,1.01,15.52],[2,1.01,0]],"ltp":0.0,"tv":0.0,"id":10303696}]}]}
{"op":"mcm","clk":"1005397570","pt":1580642474886,"mc":[{"id":"1.168224297","rc":[{"batb":[[0,2.02,27.62]],"ltp":0.0,"tv":0.0,"id":10303696}]}]}
{"op":"mcm","clk":"1005403302","pt":1580642507796,"mc":[{"id":"1.168224297","rc":[{"batb":[[1,1.76,54.61],[2,1.74,22.11]],"batl":[[0,1.95,42.01]],"ltp":0.0,"tv":0.0,"id":2257317},{"batb":[[0,2.1,24.08],[1,2.06,65.14],[2,1.01,15.52]],"batl":[[0,2.32,31.09]],"ltp":0.0,"tv":0.0,"id":10303696}]}]}
{"op":"mcm","clk":"1005404979","pt":1580642517321,"mc":[{"id":"1.168224297","rc":[{"batb":[[0,1.76,54.61],[1,1.74,22.11],[2,1.01,15.52]],"ltp":0.0,"tv":0.0,"id":2257317},{"batb":[[0,2.06,65.14],[1,1.01,15.52],[2,1.01,0]],"ltp":0.0,"tv":0.0,"id":10303696}]}]}
{"op":"mcm","clk":"1005405224","pt":1580642518601,"mc":[{"id":"1.168224297","rc":[{"batb":[[0,1.74,22.11],[1,1.01,15.52],[2,1.01,0]],"ltp":0.0,"tv":0.0,"id":2257317},{"batb":[[0,2.06,25.65]],"ltp":0.0,"tv":0.0,"id":10303696}]}]}
{"op":"mcm","clk":"1005408691","pt":1580642536859,"mc":[{"id":"1.168224297","rc":[{"batb":[[1,1.68,24.78],[2,1.01,15.52]],"ltp":0.0,"tv":0.0,"id":2257317},{"batb":[[0,2.18,21.64],[1,2.14,23.13],[2,1.01,15.52]],"ltp":0.0,"tv":0.0,"id":10303696}]}]}
{"op":"mcm","clk":"1005408904","pt":1580642537870,"mc":[{"id":"1.168224297","rc":[{"batb":[[1,1.73,57.13],[2,1.68,24.78]],"batl":[[0,1.91,42.01]],"ltp":0.0,"tv":0.0,"id":2257317},{"batb":[[2,2.12,36.97]],"batl":[[0,2.38,30.25]],"ltp":0.0,"tv":0.0,"id":10303696}]}]}
{"op":"mcm","clk":"1005410187","pt":1580642544898,"mc":[{"id":"1.168224297","rc":[{"batb":[[0,1.73,57.13],[1,1.68,24.78],[2,1.01,15.52]],"ltp":0.0,"tv":0.0,"id":2257317},{"batb":[[0,2.14,23.13],[1,2.12,36.97],[2,1.01,15.52]],"ltp":0.0,"tv":0.0,"id":10303696}]}]}
{"op":"mcm","clk":"1005410500","pt":1580642546551,"mc":[{"id":"1.168224297","rc":[{"batb":[[0,1.68,24.78],[1,1.01,15.52],[2,1.01,0]],"ltp":0.0,"tv":0.0,"id":2257317},{"batb":[[1,1.01,15.52],[2,1.01,0]],"ltp":0.0,"tv":0.0,"id":10303696}]}]}
{"op":"mcm","clk":"1005414101","pt":1580642564947,"mc":[{"id":"1.168224297","rc":[{"batb":[[1,1.66,25.81],[2,1.01,15.52]],"ltp":0.0,"tv":0.0,"id":2257317},{"batb":[[0,2.28,19.04],[1,2.2,21.01],[2,1.01,15.52]],"ltp":0.0,"tv":0.0,"id":10303696}]}]}
{"op":"mcm","clk":"1005414283","pt":1580642565866,"mc":[{"id":"1.168224297","rc":[{"batb":[[2,1.65,63.85]],"ltp":0.0,"tv":0.0,"id":2257317},{"batl":[[0,2.56,26.89]],"ltp":0.0,"tv":0.0,"id":10303696}]}]}
{"op":"mcm","clk":"1005414509","pt":1580642566987,"mc":[{"id":"1.168224297","rc":[{"batl":[[0,1.8,42.01]],"ltp":0.0,"tv":0.0,"id":2257317},{"batb":[[1,2.26,32.77],[2,2.2,21.01]],"ltp":0.0,"tv":0.0,"id":10303696}]}]}
{"op":"mcm","clk":"1005415647","pt":1580642572764,"mc":[{"id":"1.168224297","rc":[{"batb":[[0,1.67,25.26],[1,1.65,90.13],[2,1.01,15.52]],"ltp":0.0,"tv":0.0,"id":2257317},{"batb":[[0,2.3,18.65],[2,2.22,20.61]],"ltp":0.0,"tv":0.0,"id":10303696}]}]}
{"op":"mcm","clk":"1005423496","pt":1580642612066,"mc":[{"id":"1.168224297","rc":[{"batb":[[0,1.65,90.13],[1,1.01,15.52],[2,1.01,0]],"ltp":0.0,"tv":0.0,"id":2257317},{"batb":[[0,2.26,32.77],[1,2.22,20.61],[2,1.01,15.52]],"ltp":0.0,"tv":0.0,"id":10303696}]}]}
{"op":"mcm","clk":"1005423604","pt":1580642612544,"mc":[{"id":"1.168224297","rc":[{"batb":[[0,1.65,26.28]],"ltp":0.0,"tv":0.0,"id":2257317},{"batb":[[0,2.22,20.61],[1,1.01,15.52],[2,1.01,0]],"ltp":0.0,"tv":0.0,"id":10303696}]}]}
{"op":"mcm","clk":"1005427088","pt":1580642630996,"mc":[{"id":"1.168224297","rc":[{"batb":[[0,1.71,23.13],[1,1.69,24.39],[2,1.65,522.93]],"ltp":0.0,"tv":0.0,"id":2257317},{"batb":[[1,2.16,22.58],[2,1.01,15.52]],"ltp":0.0,"tv":0.0,"id":10303696}]}]}
{"op":"mcm","clk":"1005427217","pt":1580642631581,"mc":[{"id":"1.168224297","rc":[{"batb":[[2,1.68,61.33]],"batl":[[0,1.84,42.01]],"ltp":0.0,"tv":0.0,"id":2257317},{"batb":[[1,2.2,34.45],[2,2.16,22.58]],"batl":[[0,2.5,27.73]],"ltp":0.0,"tv":0.0,"id":10303696}]}]}
{"op":"mcm","clk":"1005429244","pt":1580642642373,"mc":[{"id":"1.168224297","rc":[{"batb":[[0,1.69,24.39],[1,1.68,61.33],[2,1.01,15.52]],"ltp":0.0,"tv":0.0,"id":2257317},{"batb":[[0,2.2,34.45],[1,2.16,22.58],[2,1.01,15.52]],"ltp":0.0,"tv":0.0,"id":10303696}]}]}
{"op":"mcm","clk":"1005429293","pt":1580642642599,"mc":[{"id":"1.168224297","rc":[{"batb":[[1,1.01,15.52],[2,1.01,0]],"ltp":0.0,"tv":0.0,"id":2257317},{"batb":[[0,2.16,22.58],[1,1.01,15.52],[2,1.01,0]],"ltp":0.0,"tv":0.0,"id":10303696}]}]}
{"op":"mcm","clk":"1005429925","pt":1580642645859,"mc":[{"id":"1.168224297","rc":[{"batl":[[0,2.22,329.01]],"ltp":0.0,"tv":0.0,"id":2257317},{"batl":[[0,3.15,200.42]],"ltp":0.0,"tv":0.0,"id":10303696}]}]}
{"op":"mcm","clk":"1005431792","pt":1580642655329,"mc":[{"id":"1.168224297","rc":[{"batb":[[0,1.76,21.24],[1,1.72,22.66],[2,1.7,590.62]],"ltp":0.0,"tv":0.0,"id":2257317},{"batb":[[1,2.08,25.1],[2,1.01,15.52]],"ltp":0.0,"tv":0.0,"id":10303696}]}]}
{"op":"mcm","clk":"1005431858","pt":1580642655605,"mc":[{"id":"1.168224297","rc":[{"batb":[[2,1.71,58.81]],"batl":[[0,1.87,42.01],[1,2.22,329.01]],"ltp":0.0,"tv":0.0,"id":2257317},{"batb":[[1,2.14,36.13],[2,2.08,25.1]],"batl":[[0,2.44,28.57]],"ltp":0.0,"tv":0.0,"id":10303696}]}]}
{"op":"mcm","clk":"1005432133","pt":1580642656933,"mc":[{"id":"1.168224297","rc":[{"batl":[[1,3,213.45]],"ltp":0.0,"tv":0.0,"id":10303696}]}]}
{"op":"mcm","clk":"1005433533","pt":1580642663558,"mc":[{"id":"1.168224297","rc":[{"batb":[[0,1.72,22.66],[1,1.71,58.81],[2,1.01,15.52]],"ltp":0.0,"tv":0.0,"id":2257317},{"batb":[[0,2.14,36.13],[1,2.08,25.1],[2,1.01,15.52]],"ltp":0.0,"tv":0.0,"id":10303696}]}]}
{"op":"mcm","clk":"1005433741","pt":1580642664542,"mc":[{"id":"1.168224297","rc":[{"batb":[[1,1.01,15.52],[2,1.01,0]],"batl":[[0,2.22,329.01],[1,2.22,0]],"ltp":0.0,"tv":0.0,"id":2257317},{"batb":[[0,2.08,25.1],[1,1.01,15.52],[2,1.01,0]],"batl":[[0,3,213.45],[1,3,0]],"ltp":0.0,"tv":0.0,"id":10303696}]}]}
{"op":"mcm","clk":"1005434939","pt":1580642670646,"mc":[{"id":"1.168224297","rc":[{"batb":[[1,1.7,23.68],[2,1.01,15.52]],"ltp":0.0,"tv":0.0,"id":2257317},{"batb":[[0,2.2,21.09],[1,2.12,23.76],[2,1.01,15.52]],"ltp":0.0,"tv":0.0,"id":10303696}]}]}
{"op":"mcm","clk":"1005435214","pt":1580642672255,"mc":[{"id":"1.168224297","rc":[{"batb":[[2,1.69,60.49]],"batl":[[0,1.85,42.01],[1,2.22,329.01]],"ltp":0.0,"tv":0.0,"id":2257317},{"batb":[[1,2.18,35.29],[2,2.12,23.76]],"batl":[[0,2.46,28.57],[1,3,213.45]],"ltp":0.0,"tv":0.0,"id":10303696}]}]}
{"op":"mcm","clk":"1005436857","pt":1580642680722,"mc":[{"id":"1.168224297","rc":[{"batb":[[0,1.7,23.68],[1,1.01,15.52],[2,1.69,0]],"batl":[[0,2.22,329.01],[1,2.22,0]],"ltp":0.0,"tv":0.0,"id":2257317},{"batb":[[0,2.12,23.76],[1,1.01,15.52],[2,2.12,0]],"batl":[[0,3,213.45],[1,3,0]],"ltp":0.0,"tv":0.0,"id":10303696}]}]}
{"op":"mcm","clk":"1005441159","pt":1580642704355,"mc":[{"id":"1.168224297","rc":[{"batb":[[1,1.67,25.02],[2,1.01,15.52]],"ltp":0.0,"tv":0.0,"id":2257317},{"batb":[[0,2.24,20.06],[1,2.16,22.58],[2,2.14,123.6]],"ltp":0.0,"tv":0.0,"id":10303696}]}]}
{"op":"mcm","clk":"1005441189","pt":1580642704515,"mc":[{"id":"1.168224297","rc":[{"batb":[[2,1.01,15.52]],"ltp":0.0,"tv":0.0,"id":10303696}]}]}
{"op":"mcm","clk":"1005441383","pt":1580642705535,"mc":[{"id":"1.168224297","rc":[{"batb":[[1,1.68,61.33],[2,1.67,25.02]],"batl":[[0,1.83,42.01],[1,2.22,329.01]],"ltp":0.0,"tv":0.0,"id":2257317},{"batb":[[1,2.2,34.45],[2,2.16,22.58]],"batl":[[0,2.5,27.73],[1,3,213.45]],"ltp":0.0,"tv":0.0,"id":10303696}]}]}
{"op":"mcm","clk":"1005443898","pt":1580642719164,"mc":[{"id":"1.168224297","rc":[{"batb":[[0,1.68,61.33],[1,1.67,25.02],[2,1.01,15.52]],"ltp":0.0,"tv":0.0,"id":2257317},{"batb":[[0,2.2,34.45],[1,2.16,22.58],[2,1.01,15.52]],"ltp":0.0,"tv":0.0,"id":10303696}]}]}
{"op":"mcm","clk":"1005444112","pt":1580642720558,"mc":[{"id":"1.168224297","rc":[{"batb":[[0,1.67,25.02],[1,1.01,15.52],[2,1.01,0]],"batl":[[0,2.22,329.01],[1,2.22,0]],"ltp":0.0,"tv":0.0,"id":2257317},{"batb":[[0,2.16,22.58],[1,1.01,15.52],[2,1.01,0]],"batl":[[0,3,213.45],[1,3,0]],"ltp":0.0,"tv":0.0,"id":10303696}]}]}
{"op":"mcm","clk":"1005447130","pt":1580642737271,"mc":[{"id":"1.168224297","rc":[{"batb":[[1,1.66,25.89],[2,1.01,15.52]],"ltp":0.0,"tv":0.0,"id":2257317},{"batb":[[0,2.3,18.88],[1,2.22,20.54],[2,1.01,15.52]],"ltp":0.0,"tv":0.0,"id":10303696}]}]}
{"op":"mcm","clk":"1005447240","pt":1580642737870,"mc":[{"id":"1.168224297","rc":[{"batb":[[1,1.66,88.9]],"batl":[[0,1.81,42.01],[1,2.22,329.01]],"ltp":0.0,"tv":0.0,"id":2257317},{"batb":[[1,2.24,33.61],[2,2.22,20.54]],"batl":[[0,2.54,26.89],[1,3,213.45]],"ltp":0.0,"tv":0.0,"id":10303696}]}]}
{"op":"mcm","clk":"1005448951","pt":1580642747034,"mc":[{"id":"1.168224297","rc":[{"batb":[[0,1.66,88.9],[1,1.01,15.52],[2,1.01,0]],"ltp":0.0,"tv":0.0,"id":2257317},{"batb":[[0,2.24,33.61],[1,2.22,20.54],[2,1.01,15.52]],"ltp":0.0,"tv":0.0,"id":10303696}]}]}
{"op":"mcm","clk":"1005449255","pt":1580642748630,"mc":[{"id":"1.168224297","rc":[{"batb":[[0,1.66,25.89]],"batl":[[0,2.22,329.01],[1,2.22,0]],"ltp":0.0,"tv":0.0,"id":2257317},{"batb":[[0,2.22,20.54],[1,1.01,15.52],[2,1.01,0]],"batl":[[0,3,213.45],[1,3,0]],"ltp":0.0,"tv":0.0,"id":10303696}]}]}
{"op":"mcm","clk":"1005451195","pt":1580642758724,"mc":[{"id":"1.168224297","rc":[{"batb":[[1,1.62,27.93],[2,1.01,15.52]],"ltp":0.0,"tv":0.0,"id":2257317},{"batb":[[0,2.32,18.18],[1,2.3,18.8],[2,1.01,15.52]],"ltp":0.0,"tv":0.0,"id":10303696}]}]}
{"op":"mcm","clk":"1005451447","pt":1580642760021,"mc":[{"id":"1.168224297","rc":[{"batb":[[1,1.63,66.38],[2,1.62,27.93]],"batl":[[0,1.78,42.01],[1,2.1,363.31]],"ltp":0.0,"tv":0.0,"id":2257317},{"batb":[[1,2.3,50.73]],"batl":[[0,2.6,26.05],[1,3.45,180.4]],"ltp":0.0,"tv":0.0,"id":10303696}]}]}
{"op":"mcm","clk":"1005454974","pt":1580642778902,"mc":[{"id":"1.168224297","rc":[{"batb":[[0,1.62,27.93],[1,1.01,15.52],[2,1.62,0]],"batl":[[0,2.1,363.31],[1,2.1,0]],"ltp":0.0,"tv":0.0,"id":2257317},{"batb":[[0,2.3,18.8],[1,1.01,15.52],[2,1.01,0]],"batl":[[0,3.45,180.4],[1,3.45,0]],"ltp":0.0,"tv":0.0,"id":10303696}]}]}
{"op":"mcm","clk":"1005459853","pt":1580642803944,"mc":[{"id":"1.168224297","rc":[{"batb":[[0,1.67,25.1],[1,1.64,92.21],[2,1.01,15.52]],"batl":[[0,1.8,42.01],[1,2.1,363.31]],"ltp":0.0,"tv":0.0,"id":2257317},{"batb":[[1,2.28,32.77],[2,2.26,19.91]],"batl":[[0,2.58,26.05]],"ltp":0.0,"tv":0.0,"id":10303696}]}]}
{"op":"mcm","clk":"1005460233","pt":1580642805553,"mc":[{"id":"1.168224297","rc":[{"batl":[[1,3.3,191.92]],"ltp":0.0,"tv":0.0,"id":10303696}]}]}
{"op":"mcm","clk":"1005461245","pt":1580642810350,"mc":[{"id":"1.168224297","rc":[{"batb":[[0,1.64,92.21],[1,1.01,15.52],[2,1.01,0]],"ltp":0.0,"tv":0.0,"id":2257317},{"batb":[[0,2.28,32.77],[1,2.26,19.91],[2,1.01,15.52]],"ltp":0.0,"tv":0.0,"id":10303696}]}]}
{"op":"mcm","clk":"1005461352","pt":1580642810850,"mc":[{"id":"1.168224297","rc":[{"batb":[[0,1.64,26.67]],"batl":[[0,2.1,363.31],[1,2.1,0]],"ltp":0.0,"tv":0.0,"id":2257317},{"batb":[[0,2.26,19.91],[1,1.01,15.52],[2,1.01,0]],"batl":[[0,3.3,191.92],[1,3.3,0]],"ltp":0.0,"tv":0.0,"id":10303696}]}]}
{"op":"mcm","clk":"1005463037","pt":1580642819204,"mc":[{"id":"1.168224297","rc":[{"batb":[[1,1.61,28.8],[2,1.01,15.52]],"ltp":0.0,"tv":0.0,"id":2257317},{"batb":[[0,2.36,17.55],[1,2.32,18.33],[2,1.01,15.52]],"ltp":0.0,"tv":0.0,"id":10303696}]}]}
{"op":"mcm","clk":"1005463124","pt":1580642819580,"mc":[{"id":"1.168224297","rc":[{"batb":[[1,1.62,67.22],[2,1.61,28.8]],"batl":[[0,1.77,42.01],[1,2.1,363.31]],"ltp":0.0,"tv":0.0,"id":2257317},{"batb":[[1,2.32,49.42]],"batl":[[0,2.64,25.21],[1,3.3,191.92]],"ltp":0.0,"tv":0.0,"id":10303696}]}]}
{"op":"mcm","clk":"1005464536","pt":1580642826879,"mc":[{"id":"1.168224297","rc":[{"batb":[[0,1.62,67.22],[1,1.61,28.8],[2,1.01,15.52]],"ltp":0.0,"tv":0.0,"id":2257317},{"batb":[[0,2.32,49.42],[1,1.01,15.52],[2,1.01,0]],"ltp":0.0,"tv":0.0,"id":10303696}]}]}
{"op":"mcm","clk":"1005464857","pt":1580642828594,"mc":[{"id":"1.168224297","rc":[{"batb":[[0,1.61,28.8],[1,1.01,15.52],[2,1.01,0]],"batl":[[0,2.1,363.31],[1,2.1,0]],"ltp":0.0,"tv":0.0,"id":2257317},{"batb":[[0,2.32,18.33]],"batl":[[0,3.3,191.92],[1,3.3,0]],"ltp":0.0,"tv":0.0,"id":10303696}]}]}
{"op":"mcm","clk":"1005468028","pt":1580642846200,"mc":[{"id":"1.168224297","rc":[{"batb":[[1,1.6,69.74],[2,1.57,31.55]],"batl":[[0,1.74,42.01],[1,2.1,363.31]],"ltp":0.0,"tv":0.0,"id":2257317},{"batb":[[0,2.42,16.13],[1,2.38,17.15],[2,2.36,30.25]],"batl":[[0,2.68,24.37]],"ltp":0.0,"tv":0.0,"id":10303696}]}]}
{"op":"mcm","clk":"1005468259","pt":1580642847293,"mc":[{"id":"1.168224297","rc":[{"batl":[[1,3.65,170.41]],"ltp":0.0,"tv":0.0,"id":10303696}]}]}
{"op":"mcm","clk":"1005469543","pt":1580642853930,"mc":[{"id":"1.168224297","rc":[{"batb":[[0,1.6,69.74],[1,1.57,31.55],[2,1.01,15.52]],"ltp":0.0,"tv":0.0,"id":2257317},{"batb":[[0,2.38,17.15],[1,2.36,30.25],[2,1.01,15.52]],"ltp":0.0,"tv":0.0,"id":10303696}]}]}
{"op":"mcm","clk":"1005469729","pt":1580642854591,"mc":[{"id":"1.168224297","rc":[{"batb":[[0,1.57,31.55],[1,1.01,15.52],[2,1.01,0]],"batl":[[0,2.1,363.31],[1,2.1,0]],"ltp":0.0,"tv":0.0,"id":2257317},{"batb":[[1,1.01,15.52],[2,1.01,0]],"batl":[[0,3.65,170.41],[1,3.65,0]],"ltp":0.0,"tv":0.0,"id":10303696}]}]}
{"op":"mcm","clk":"1005472228","pt":1580642868125,"mc":[{"id":"1.168224297","rc":[{"batb":[[0,1.58,72.26],[1,1.57,31.55],[2,1.53,34.93]],"batl":[[0,1.72,42.01]],"ltp":0.0,"tv":0.0,"id":2257317},{"batb":[[0,2.52,14.48],[1,2.46,15.58],[2,2.4,29.41]],"batl":[[0,2.74,23.53],[1,3.65,170.41]],"ltp":0.0,"tv":0.0,"id":10303696}]}]}
{"op":"mcm","clk":"1005472463","pt":1580642869245,"mc":[{"id":"1.168224297","rc":[{"batl":[[1,1.95,409.86]],"ltp":0.0,"tv":0.0,"id":2257317}]}]}
{"op":"mcm","clk":"1005473481","pt":1580642874800,"mc":[{"id":"1.168224297","rc":[{"batb":[[0,1.53,34.93],[1,1.01,15.52],[2,1.53,0]],"batl":[[0,1.95,409.86],[1,1.95,0]],"ltp":0.0,"tv":0.0,"id":2257317},{"batb":[[0,2.46,15.58],[1,1.01,15.52],[2,2.4,0]],"batl":[[0,3.65,170.41],[1,3.65,0]],"ltp":0.0,"tv":0.0,"id":10303696}]}]}
{"op":"mcm","clk":"1005477374","pt":1580642897189,"mc":[{"id":"1.168224297","rc":[{"batb":[[0,1.6,29.66],[1,1.55,33.44],[2,1.53,34.93]],"ltp":0.0,"tv":0.0,"id":2257317},{"batb":[[1,2.38,17.07],[2,1.01,15.52]],"ltp":0.0,"tv":0.0,"id":10303696}]}]}
{"op":"mcm","clk":"1005477465","pt":1580642897735,"mc":[{"id":"1.168224297","rc":[{"batb":[[1,1.59,70.58],[2,1.55,33.44]],"batl":[[0,1.73,42.01],[1,1.95,409.86]],"ltp":0.0,"tv":0.0,"id":2257317},{"batb":[[1,2.38,47.32]],"batl":[[0,2.7,24.37],[1,3.65,170.41]],"ltp":0.0,"tv":0.0,"id":10303696}]}]}
{"op":"mcm","clk":"1005480211","pt":1580642913400,"mc":[{"id":"1.168224297","rc":[{"batb":[[0,1.59,70.58],[1,1.55,33.44],[2,1.01,15.52]],"ltp":0.0,"tv":0.0,"id":2257317},{"batb":[[0,2.38,47.32],[1,1.01,15.52],[2,1.01,0]],"ltp":0.0,"tv":0.0,"id":10303696}]}]}
{"op":"mcm","clk":"1005480482","pt":1580642914987,"mc":[{"id":"1.168224297","rc":[{"batb":[[0,1.55,33.44],[1,1.01,15.52],[2,1.01,0]],"batl":[[0,1.95,409.86],[1,1.95,0]],"ltp":0.0,"tv":0.0,"id":2257317},{"batb":[[0,2.38,17.07]],"batl":[[0,3.65,170.41],[1,3.65,0]],"ltp":0.0,"tv":0.0,"id":10303696}]}]}
{"op":"mcm","clk":"1005484070","pt":1580642936100,"mc":[{"id":"1.168224297","rc":[{"batb":[[0,1.63,27.3],[1,1.59,100.63],[2,1.01,15.52]],"batl":[[0,1.75,42.01],[1,1.95,409.86]],"ltp":0.0,"tv":0.0,"id":2257317},{"batb":[[1,2.36,30.25],[2,2.34,18.02]],"batl":[[0,2.68,24.37],[1,3.65,170.41]],"ltp":0.0,"tv":0.0,"id":10303696}]}]}
{"op":"mcm","clk":"1005487342","pt":1580642953971,"mc":[{"id":"1.168224297","rc":[{"batb":[[0,1.59,100.63],[1,1.01,15.52],[2,1.01,0]],"ltp":0.0,"tv":0.0,"id":2257317},{"batb":[[0,2.36,30.25],[1,2.34,18.02],[2,1.01,15.52]],"ltp":0.0,"tv":0.0,"id":10303696}]}]}
{"op":"mcm","clk":"1005487467","pt":1580642954768,"mc":[{"id":"1.168224297","rc":[{"batb":[[0,1.59,30.06]],"batl":[[0,1.95,409.86],[1,1.95,0]],"ltp":0.0,"tv":0.0,"id":2257317},{"batb":[[0,2.34,18.02],[1,1.01,15.52],[2,1.01,0]],"batl":[[0,3.65,170.41],[1,3.65,0]],"ltp":0.0,"tv":0.0,"id":10303696}]}]}
{"op":"mcm","clk":"1005490974","pt":1580642974095,"mc":[{"id":"1.168224297","rc":[{"batb":[[1,1.58,72.26],[2,1.54,33.75]],"batl":[[0,1.73,42.01],[1,1.95,409.86]],"ltp":0.0,"tv":0.0,"id":2257317},{"batb":[[0,2.48,15.34],[1,2.4,29.41],[2,2.38,16.84]],"batl":[[0,2.72,24.37],[1,3.65,170.41]],"ltp":0.0,"tv":0.0,"id":10303696}]}]}
{"op":"mcm","clk":"1005492589","pt":1580642983342,"mc":[{"id":"1.168224297","rc":[{"batb":[[0,1.58,72.26],[1,1.54,33.75],[2,1.01,15.52]],"ltp":0.0,"tv":0.0,"id":2257317},{"batb":[[0,2.4,29.41],[1,2.38,16.84],[2,1.01,15.52]],"ltp":0.0,"tv":0.0,"id":10303696}]}]}
{"op":"mcm","clk":"1005492895","pt":1580642984839,"mc":[{"id":"1.168224297","rc":[{"batb":[[0,1.54,33.75],[1,1.01,15.52],[2,1.01,0]],"batl":[[0,1.95,409.86],[1,1.95,0]],"ltp":0.0,"tv":0.0,"id":2257317},{"batb":[[0,2.38,16.84],[1,1.01,15.52],[2,1.01,0]],"batl":[[0,3.65,170.41],[1,3.65,0]],"ltp":0.0,"tv":0.0,"id":10303696}]}]}
{"op":"mcm","clk":"1005495407","pt":1580642998270,"mc":[{"id":"1.168224297","rc":[{"batb":[[1,1.53,78.98],[2,1.52,35.41]],"batl":[[0,1.67,42.01],[1,1.95,409.86]],"ltp":0.0,"tv":0.0,"id":2257317},{"batb":[[0,2.6,13.38],[1,2.5,42.44],[2,2.42,166.44]],"batl":[[0,2.88,21.85]],"ltp":0.0,"tv":0.0,"id":10303696}]}]}
{"op":"mcm","clk":"1005495426","pt":1580642998428,"mc":[{"id":"1.168224297","rc":[{"batb":[[2,1.01,15.52]],"ltp":0.0,"tv":0.0,"id":10303696}]}]}
{"op":"mcm","clk":"1005495646","pt":1580642999502,"mc":[{"id":"1.168224297","rc":[{"batl":[[1,4.2,148.03]],"ltp":0.0,"tv":0.0,"id":10303696}]}]}
{"op":"mcm","clk":"1005512289","pt":1580643088114,"mc":[{"id":"1.168224297","rc":[{"batb":[[0,1.53,78.98],[1,1.52,35.41],[2,1.01,15.52]],"ltp":0.0,"tv":0.0,"id":2257317},{"batb":[[0,2.5,42.44],[1,1.01,15.52],[2,1.01,0]],"ltp":0.0,"tv":0.0,"id":10303696}]}]}
{"op":"mcm","clk":"1005512409","pt":1580643088813,"mc":[{"id":"1.168224297","rc":[{"batb":[[0,1.52,35.41],[1,1.01,15.52],[2,1.01,0]],"batl":[[0,1.95,409.86],[1,1.95,0]],"ltp":0.0,"tv":0.0,"id":2257317},{"batb":[[0,2.5,14.71]],"batl":[[0,4.2,148.03],[1,4.2,0]],"ltp":0.0,"tv":0.0,"id":10303696}]}]}
{"op":"mcm","clk":"1005514781","pt":1580643101300,"mc":[{"id":"1.168224297","rc":[{"batb":[[1,1.51,36.51],[2,1.01,15.52]],"ltp":0.0,"tv":0.0,"id":2257317},{"batb":[[0,2.66,12.59],[1,2.56,14.01],[2,2.5,14.71]],"ltp":0.0,"tv":0.0,"id":10303696}]}]}
{"op":"mcm","clk":"1005514874","pt":1580643101839,"mc":[{"id":"1.168224297","rc":[{"batb":[[0,1.52,116.07]],"batl":[[0,1.65,42.01],[1,1.95,409.86]],"ltp":0.0,"tv":0.0,"id":2257317},{"batb":[[1,2.56,40.89],[2,1.01,15.52]],"batl":[[0,2.92,21.85],[1,4.2,148.03]],"ltp":0.0,"tv":0.0,"id":10303696}]}]}
{"op":"mcm","clk":"1005516952","pt":1580643113263,"mc":[{"id":"1.168224297","rc":[{"batb":[[0,1.51,36.51],[1,1.01,15.52],[2,1.01,0]],"batl":[[0,1.95,409.86],[1,1.95,0]],"ltp":0.0,"tv":0.0,"id":2257317},{"batb":[[0,2.56,14.01],[1,1.01,15.52],[2,1.01,0]],"batl":[[0,4.2,148.03],[1,4.2,0]],"ltp":0.0,"tv":0.0,"id":10303696}]}]}
{"op":"mcm","clk":"1005518813","pt":1580643123383,"mc":[{"id":"1.168224297","rc":[{"batb":[[0,1.56,32.42],[1,1.54,33.91],[2,1.01,15.52]],"ltp":0.0,"tv":0.0,"id":2257317},{"batb":[[1,2.46,15.42],[2,1.01,15.52]],"ltp":0.0,"tv":0.0,"id":10303696}]}]}
{"op":"mcm","clk":"1005518893","pt":1580643123778,"mc":[{"id":"1.168224297","rc":[{"batb":[[1,1.55,75.62],[2,1.54,33.91]],"batl":[[0,1.68,42.01],[1,1.95,409.86]],"ltp":0.0,"tv":0.0,"id":2257317},{"batb":[[1,2.5,27.73],[2,2.46,15.42]],"batl":[[0,2.84,22.69]],"ltp":0.0,"tv":0.0,"id":10303696}]}]}
{"op":"mcm","clk":"1005519125","pt":1580643125089,"mc":[{"id":"1.168224297","rc":[{"batl":[[1,3.9,158.24]],"ltp":0.0,"tv":0.0,"id":10303696}]}]}
{"op":"mcm","clk":"1005520718","pt":1580643134273,"mc":[{"id":"1.168224297","rc":[{"batb":[[0,1.55,75.62],[1,1.54,33.91],[2,1.01,15.52]],"ltp":0.0,"tv":0.0,"id":2257317},{"batb":[[0,2.5,27.73],[1,2.46,15.42],[2,1.01,15.52]],"ltp":0.0,"tv":0.0,"id":10303696}]}]}
{"op":"mcm","clk":"1005520825","pt":1580643134908,"mc":[{"id":"1.168224297","rc":[{"batb":[[0,1.54,33.91],[1,1.01,15.52],[2,1.01,0]],"batl":[[0,1.95,409.86],[1,1.95,0]],"ltp":0.0,"tv":0.0,"id":2257317},{"batb":[[0,2.46,15.42],[1,1.01,15.52],[2,1.01,0]],"batl":[[0,3.9,158.24],[1,3.9,0]],"ltp":0.0,"tv":0.0,"id":10303696}]}]}
{"op":"mcm","clk":"1005525028","pt":1580643158289,"mc":[{"id":"1.168224297","rc":[{"batb":[[0,1.59,29.82],[1,1.57,104.73],[2,1.01,15.52]],"batl":[[0,1.71,42.01],[1,1.95,409.86]],"ltp":0.0,"tv":0.0,"id":2257317},{"batb":[[1,2.42,29.41],[2,2.38,17.07]],"batl":[[0,2.76,23.53]],"ltp":0.0,"tv":0.0,"id":10303696}]}]}
{"op":"mcm","clk":"1005525525","pt":1580643161441,"mc":[{"id":"1.168224297","rc":[{"batl":[[1,3.65,170.41]],"ltp":0.0,"tv":0.0,"id":10303696}]}]}
{"op":"mcm","clk":"1005528531","pt":1580643175315,"mc":[{"id":"1.168224297","rc":[{"batb":[[0,1.57,31.63],[1,1.01,15.52],[2,1.01,0]],"batl":[[0,1.95,409.86],[1,1.95,0]],"ltp":0.0,"tv":0.0,"id":2257317},{"batb":[[0,2.38,17.07],[1,1.01,15.52],[2,2.38,0]],"batl":[[0,3.65,170.41],[1,3.65,0]],"ltp":0.0,"tv":0.0,"id":10303696}]}]}
{"op":"mcm","clk":"1005532614","pt":1580643196165,"mc":[{"id":"1.168224297","rc":[{"batb":[[1,1.56,74.78],[2,1.55,32.73]],"batl":[[0,1.7,42.01],[1,1.95,409.86]],"ltp":0.0,"tv":0.0,"id":2257317},{"batb":[[0,2.52,14.48],[1,2.44,28.57],[2,2.42,16.21]],"batl":[[0,2.8,22.69],[1,3.65,170.41]],"ltp":0.0,"tv":0.0,"id":10303696}]}]}
{"op":"mcm","clk":"1005535430","pt":1580643209334,"mc":[{"id":"1.168224297","rc":[{"batb":[[0,1.55,32.73],[1,1.01,15.52],[2,1.55,0]],"batl":[[0,1.95,409.86],[1,1.95,0]],"ltp":0.0,"tv":0.0,"id":2257317},{"batb":[[0,2.42,16.21],[1,1.01,15.52],[2,2.42,0]],"batl":[[0,3.65,170.41],[1,3.65,0]],"ltp":0.0,"tv":0.0,"id":10303696}]}]}
{"op":"mcm","clk":"1005539965","pt":1580643232000,"mc":[{"id":"1.168224297","rc":[{"batb":[[0,1.55,108.35]],"batl":[[0,1.68,42.01],[1,1.95,409.86]],"ltp":0.0,"tv":0.0,"id":2257317},{"batb":[[0,2.48,27.73],[1,2.42,16.21],[2,1.01,15.52]],"batl":[[0,2.84,22.69],[1,3.65,170.41]],"ltp":0.0,"tv":0.0,"id":10303696}]}]}
{"op":"mcm","clk":"1005540102","pt":1580643232701,"mc":[{"id":"1.168224297","rc":[{"batb":[[1,1.53,34.38],[2,1.01,15.52]],"ltp":0.0,"tv":0.0,"id":2257317},{"batb":[[0,2.56,13.85],[1,2.48,42.99]],"ltp":0.0,"tv":0.0,"id":10303696}]}]}
{"op":"mcm","clk":"1005540693","pt":1580643235781,"mc":[{"id":"1.168224297","rc":[{"batb":[[2,2.44,67.67]],"ltp":0.0,"tv":0.0,"id":10303696}]}]}
{"op":"mcm","clk":"1005542765","pt":1580643246278,"mc":[{"id":"1.168224297","rc":[{"batb":[[0,1.55,75.62]],"ltp":0.0,"tv":0.0,"id":2257317},{"batb":[[0,2.48,42.99],[1,1.01,15.52],[2,2.44,0]],"ltp":0.0,"tv":0.0,"id":10303696}]}]}
{"op":"mcm","clk":"1005542969","pt":1580643247290,"mc":[{"id":"1.168224297","rc":[{"batb":[[0,1.53,34.38],[1,1.01,15.52],[2,1.01,0]],"batl":[[0,1.95,409.86],[1,1.95,0]],"ltp":0.0,"tv":0.0,"id":2257317},{"batb":[[0,2.48,15.26]],"batl":[[0,3.65,170.41],[1,3.65,0]],"ltp":0.0,"tv":0.0,"id":10303696}]}]}
{"op":"mcm","clk":"1005547711","pt":1580643272248,"mc":[{"id":"1.168224297","rc":[{"batb":[[0,1.59,30.21],[1,1.57,104.65],[2,1.53,873.71]],"batl":[[0,1.71,42.01],[1,1.95,409.86]],"ltp":0.0,"tv":0.0,"id":2257317},{"batb":[[1,2.42,29.41],[2,2.4,16.84]],"batl":[[0,2.76,23.53],[1,3.65,170.41]],"ltp":0.0,"tv":0.0,"id":10303696}]}]}
{"op":"mcm","clk":"1005547771","pt":1580643272456,"mc":[{"id":"1.168224297","rc":[{"batb":[[2,1.53,839.33]],"ltp":0.0,"tv":0.0,"id":2257317}]}]}
{"op":"mcm","clk":"1005549004","pt":1580643278989,"mc":[{"id":"1.168224297","rc":[{"batb":[[2,1.01,15.52]],"ltp":0.0,"tv":0.0,"id":2257317}]}]}
{"op":"mcm","clk":"1005549678","pt":1580643282474,"mc":[{"id":"1.168224297","rc":[{"batb":[[2,1.53,783.65]],"ltp":0.0,"tv":0.0,"id":2257317}]}]}
{"op":"mcm","clk":"1005551203","pt":1580643290301,"mc":[{"id":"1.168224297","rc":[{"batb":[[0,1.57,104.65],[1,1.01,15.52],[2,1.53,0]],"ltp":0.0,"tv":0.0,"id":2257317},{"batb":[[0,2.42,29.41],[1,2.4,16.84],[2,1.01,15.52]],"ltp":0.0,"tv":0.0,"id":10303696}]}]}
{"op":"mcm","clk":"1005551328","pt":1580643291007,"mc":[{"id":"1.168224297","rc":[{"batb":[[0,1.57,31.55]],"batl":[[0,1.95,409.86],[1,1.95,0]],"ltp":0.0,"tv":0.0,"id":2257317},{"batb":[[0,2.4,16.84],[1,1.01,15.52],[2,1.01,0]],"batl":[[0,3.65,170.41],[1,3.65,0]],"ltp":0.0,"tv":0.0,"id":10303696}]}]}
{"op":"mcm","clk":"1005554218","pt":1580643306204,"mc":[{"id":"1.168224297","rc":[{"batb":[[0,1.63,27.7],[1,1.6,99.48],[2,1.01,15.52]],"batl":[[0,1.74,42.01],[1,1.95,409.86]],"ltp":0.0,"tv":0.0,"id":2257317},{"batb":[[1,2.36,30.25],[2,2.28,19.28]],"batl":[[0,2.7,24.37],[1,3.65,170.41]],"ltp":0.0,"tv":0.0,"id":10303696}]}]}
{"op":"mcm","clk":"1005554880","pt":1580643309417,"mc":[{"id":"1.168224297","rc":[{"batb":[[2,1.55,737.79]],"ltp":0.0,"tv":0.0,"id":2257317}]}]}
{"op":"mcm","clk":"1005557478","pt":1580643322348,"mc":[{"id":"1.168224297","rc":[{"batb":[[2,1.01,15.52]],"ltp":0.0,"tv":0.0,"id":2257317}]}]}
{"op":"mcm","clk":"1005557646","pt":1580643323149,"mc":[{"id":"1.168224297","rc":[{"batb":[[0,1.6,29.74],[1,1.01,15.52],[2,1.01,0]],"batl":[[0,1.95,409.86],[1,1.95,0]],"ltp":0.0,"tv":0.0,"id":2257317},{"batb":[[0,2.28,19.28],[1,1.01,15.52],[2,2.28,0]],"batl":[[0,3.65,170.41],[1,3.65,0]],"ltp":0.0,"tv":0.0,"id":10303696}]}]}
{"op":"mcm","clk":"1005558270","pt":1580643326150,"mc":[{"id":"1.168224297","rc":[{"batb":[[0,1.59,30.14]],"ltp":0.0,"tv":0.0,"id":2257317},{"batb":[[0,2.28,18.96]],"ltp":0.0,"tv":0.0,"id":10303696}]}]}
{"op":"mcm","clk":"1005562533","pt":1580643346254,"mc":[{"id":"1.168224297","rc":[{"batb":[[0,1.59,100.71],[1,1.57,31.55],[2,1.01,15.52]],"batl":[[0,1.73,42.01],[1,1.95,409.86]],"ltp":0.0,"tv":0.0,"id":2257317},{"batb":[[0,2.48,15.26],[1,2.38,47.4],[2,1.01,15.52]],"batl":[[0,2.72,24.37],[1,3.65,170.41]],"ltp":0.0,"tv":0.0,"id":10303696}]}]}
{"op":"mcm","clk":"1005562722","pt":1580643347155,"mc":[{"id":"1.168224297","rc":[{"batb":[[2,2.3,80.88]],"ltp":0.0,"tv":0.0,"id":10303696}]}]}
{"op":"mcm","clk":"1005565330","pt":1580643360380,"mc":[{"id":"1.168224297","rc":[{"batb":[[0,1.59,70.58]],"ltp":0.0,"tv":0.0,"id":2257317},{"batb":[[0,2.38,47.4],[1,1.01,15.52],[2,2.3,0]],"ltp":0.0,"tv":0.0,"id":10303696}]}]}
{"op":"mcm","clk":"1005565457","pt":1580643361082,"mc":[{"id":"1.168224297","rc":[{"batb":[[0,1.57,31.55],[1,1.01,15.52],[2,1.01,0]],"batl":[[0,1.95,409.86],[1,1.95,0]],"ltp":0.0,"tv":0.0,"id":2257317},{"batb":[[0,2.38,17.15]],"batl":[[0,3.65,170.41],[1,3.65,0]],"ltp":0.0,"tv":0.0,"id":10303696}]}]}
{"op":"mcm","clk":"1005569335","pt":1580643379989,"mc":[{"id":"1.168224297","rc":[{"batb":[[0,1.57,104.65]],"batl":[[0,1.71,42.01],[1,1.95,409.86]],"ltp":0.0,"tv":0.0,"id":2257317},{"batb":[[0,2.44,28.57],[1,2.38,17.15],[2,1.01,15.52]],"batl":[[0,2.76,23.53],[1,3.65,170.41]],"ltp":0.0,"tv":0.0,"id":10303696}]}]}
{"op":"mcm","clk":"1005569539","pt":1580643381023,"mc":[{"id":"1.168224297","rc":[{"batb":[[1,1.55,32.73],[2,1.01,15.52]],"ltp":0.0,"tv":0.0,"id":2257317},{"batb":[[0,2.52,14.48],[1,2.44,44.38],[2,2.42,72.44]],"ltp":0.0,"tv":0.0,"id":10303696}]}]}
{"op":"mcm","clk":"1005572334","pt":1580643395204,"mc":[{"id":"1.168224297","rc":[{"batb":[[0,1.55,32.73],[1,1.01,15.52],[2,1.01,0]],"batl":[[0,1.95,409.86],[1,1.95,0]],"ltp":0.0,"tv":0.0,"id":2257317},{"batb":[[0,2.44,15.82],[1,1.01,15.52],[2,2.42,0]],"batl":[[0,3.65,170.41],[1,3.65,0]],"ltp":0.0,"tv":0.0,"id":10303696}]}]}
{"op":"mcm","clk":"1005572969","pt":1580643398142,"mc":[{"id":"1.168224297","rc":[{"batb":[[0,2.46,15.66]],"ltp":0.0,"tv":0.0,"id":10303696}]}]}
{"op":"mcm","clk":"1005577551","pt":1580643421028,"mc":[{"id":"1.168224297","rc":[{"batb":[[1,1.52,35.88],[2,1.01,15.52]],"ltp":0.0,"tv":0.0,"id":2257317},{"batb":[[0,2.58,13.69],[1,2.52,14.63],[2,1.01,15.52]],"ltp":0.0,"tv":0.0,"id":10303696}]}]}
{"op":"mcm","clk":"1005577761","pt":1580643422053,"mc":[{"id":"1.168224297","rc":[{"batb":[[1,1.54,77.3],[2,1.52,35.88]],"batl":[[0,1.68,42.01],[1,1.95,409.86]],"ltp":0.0,"tv":0.0,"id":2257317},{"batb":[[2,2.5,27.73]],"batl":[[0,2.84,22.69],[1,3.65,170.41]],"ltp":0.0,"tv":0.0,"id":10303696}]}]}
{"op":"mcm","clk":"1005581847","pt":1580643441139,"mc":[{"id":"1.168224297","rc":[{"batb":[[0,1.52,35.88],[1,1.01,15.52],[2,1.52,0]],"batl":[[0,1.95,409.86],[1,1.95,0]],"ltp":0.0,"tv":0.0,"id":2257317},{"batb":[[0,2.52,14.63],[1,1.01,15.52],[2,2.5,0]],"batl":[[0,3.65,170.41],[1,3.65,0]],"ltp":0.0,"tv":0.0,"id":10303696}]}]}
{"op":"mcm","clk":"1005584571","pt":1580643455098,"mc":[{"id":"1.168224297","rc":[{"batb":[[0,1.57,31.24],[1,1.54,33.75],[2,1.01,15.52]],"ltp":0.0,"tv":0.0,"id":2257317},{"batb":[[1,2.46,15.42],[2,1.01,15.52]],"ltp":0.0,"tv":0.0,"id":10303696}]}]}
{"op":"mcm","clk":"1005584760","pt":1580643456115,"mc":[{"id":"1.168224297","rc":[{"batb":[[1,1.55,75.62],[2,1.54,33.75]],"batl":[[0,1.69,42.01],[1,1.95,409.86]],"ltp":0.0,"tv":0.0,"id":2257317},{"batb":[[1,2.48,27.73],[2,2.46,15.42]],"batl":[[0,2.82,22.69],[1,3.65,170.41]],"ltp":0.0,"tv":0.0,"id":10303696}]}]}
{"op":"mcm","clk":"1005585388","pt":1580643459088,"mc":[{"id":"1.168224297","rc":[{"batb":[[0,1.54,33.75],[1,1.01,15.52],[2,1.54,0]],"batl":[[0,1.95,409.86],[1,1.95,0]],"ltp":0.0,"tv":0.0,"id":2257317},{"batb":[[0,2.46,15.42],[1,1.01,15.52],[2,2.46,0]],"batl":[[0,3.65,170.41],[1,3.65,0]],"ltp":0.0,"tv":0.0,"id":10303696}]}]}
{"op":"mcm","clk":"1005587285","pt":1580643468375,"mc":[{"id":"1.168224297","rc":[{"batb":[[0,1.59,29.82],[1,1.57,31.79],[2,1.56,74.78]],"batl":[[0,1.7,42.01],[1,1.95,409.86]],"ltp":0.0,"tv":0.0,"id":2257317},{"batb":[[0,2.46,43.99],[1,2.42,16.29],[2,1.01,15.52]],"batl":[[0,2.78,23.53],[1,3.65,170.41]],"ltp":0.0,"tv":0.0,"id":10303696}]}]}
{"op":"mcm","clk":"1005588416","pt":1580643474271,"mc":[{"id":"1.168224297","rc":[{"batb":[[0,1.57,31.79],[1,1.56,74.78],[2,1.01,15.52]],"ltp":0.0,"tv":0.0,"id":2257317},{"batb":[[0,2.46,28.57]],"ltp":0.0,"tv":0.0,"id":10303696}]}]}
{"op":"mcm","clk":"1005588606","pt":1580643475178,"mc":[{"id":"1.168224297","rc":[{"batb":[[1,1.01,15.52],[2,1.01,0]],"batl":[[0,1.95,409.86],[1,1.95,0]],"ltp":0.0,"tv":0.0,"id":2257317},{"batb":[[0,2.42,16.29],[1,1.01,15.52],[2,1.01,0]],"batl":[[0,3.65,170.41],[1,3.65,0]],"ltp":0.0,"tv":0.0,"id":10303696}]}]}
{"op":"mcm","clk":"1005590953","pt":1580643486342,"mc":[{"id":"1.168224297","rc":[{"batb":[[1,1.55,75.62],[2,1.53,34.78]],"batl":[[0,1.68,42.01],[1,1.95,409.86]],"ltp":0.0,"tv":0.0,"id":2257317},{"batb":[[0,2.54,14.4],[1,2.48,42.83],[2,1.01,15.52]],"batl":[[0,2.84,22.69],[1,3.65,170.41]],"ltp":0.0,"tv":0.0,"id":10303696}]}]}
{"op":"mcm","clk":"1005591140","pt":1580643487252,"mc":[{"id":"1.168224297","rc":[{"batb":[[2,2.46,448.38]],"ltp":0.0,"tv":0.0,"id":10303696}]}]}
{"op":"mcm","clk":"1005592018","pt":1580643491329,"mc":[{"id":"1.168224297","rc":[{"batb":[[2,1.01,15.52]],"ltp":0.0,"tv":0.0,"id":10303696}]}]}
{"op":"mcm","clk":"1005592124","pt":1580643491754,"mc":[{"id":"1.168224297","rc":[{"batb":[[0,1.55,75.62],[1,1.53,34.78],[2,1.01,15.52]],"ltp":0.0,"tv":0.0,"id":2257317},{"batb":[[0,2.48,42.83],[1,1.01,15.52],[2,1.01,0]],"ltp":0.0,"tv":0.0,"id":10303696}]}]}
{"op":"mcm","clk":"1005592453","pt":1580643493230,"mc":[{"id":"1.168224297","rc":[{"batb":[[0,1.53,34.78],[1,1.01,15.52],[2,1.01,0]],"batl":[[0,1.95,409.86],[1,1.95,0]],"ltp":0.0,"tv":0.0,"id":2257317},{"batb":[[0,2.48,15.11]],"batl":[[0,3.65,170.41],[1,3.65,0]],"ltp":0.0,"tv":0.0,"id":10303696}]}]}
{"op":"mcm","clk":"1005596691","pt":1580643512365,"mc":[{"id":"1.168224297","rc":[{"batb":[[0,1.53,113.76],[1,1.49,38.32],[2,1.01,15.52]],"batl":[[0,1.67,42.01],[1,1.95,409.86]],"ltp":0.0,"tv":0.0,"id":2257317},{"batb":[[0,2.64,12.9],[1,2.56,14.01],[2,2.52,26.89]],"batl":[[0,2.88,21.85],[1,3.65,170.41]],"ltp":0.0,"tv":0.0,"id":10303696}]}]}
{"op":"mcm","clk":"1005597498","pt":1580643516197,"mc":[{"id":"1.168224297","rc":[{"batb":[[0,1.53,78.98]],"ltp":0.0,"tv":0.0,"id":2257317},{"batb":[[0,2.56,14.01],[1,2.52,26.89],[2,1.01,15.52]],"ltp":0.0,"tv":0.0,"id":10303696}]}]}
{"op":"mcm","clk":"1005597730","pt":1580643517177,"mc":[{"id":"1.168224297","rc":[{"batb":[[0,1.49,38.32],[1,1.01,15.52],[2,1.01,0]],"batl":[[0,1.95,409.86],[1,1.95,0]],"ltp":0.0,"tv":0.0,"id":2257317},{"batb":[[1,1.01,15.52],[2,1.01,0]],"batl":[[0,3.65,170.41],[1,3.65,0]],"ltp":0.0,"tv":0.0,"id":10303696}]}]}
{"op":"mcm","clk":"1005602405","pt":1580643538402,"mc":[{"id":"1.168224297","rc":[{"batb":[[0,1.52,80.66],[1,1.49,38.32],[2,1.45,43.68]],"batl":[[0,1.66,42.01],[1,1.95,409.86]],"ltp":0.0,"tv":0.0,"id":2257317},{"batb":[[0,2.76,11.49],[1,2.64,12.9],[2,2.54,26.89]],"batl":[[0,2.92,21.85]],"ltp":0.0,"tv":0.0,"id":10303696}]}]}
{"op":"mcm","clk":"1005602742","pt":1580643540018,"mc":[{"id":"1.168224297","rc":[{"batl":[[1,4.2,148.03]],"ltp":0.0,"tv":0.0,"id":10303696}]}]}
{"op":"mcm","clk":"1005603798","pt":1580643545118,"mc":[{"id":"1.168224297","rc":[{"batb":[[0,1.45,43.68],[1,1.01,15.51],[2,1.45,0]],"batl":[[0,1.95,409.86],[1,1.95,0]],"ltp":0.0,"tv":0.0,"id":2257317},{"batb":[[0,2.64,12.9],[1,1.01,15.52],[2,2.54,0]],"batl":[[0,4.2,148.03],[1,4.2,0]],"ltp":0.0,"tv":0.0,"id":10303696}]}]}
{"op":"mcm","clk":"1005607178","pt":1580643560932,"mc":[{"id":"1.168224297","rc":[{"batb":[[1,1.43,46.11],[2,1.01,15.51]],"ltp":0.0,"tv":0.0,"id":2257317},{"batb":[[0,2.92,24.71],[1,2.8,11.02],[2,1.01,15.52]],"ltp":0.0,"tv":0.0,"id":10303696}]}]}
{"op":"mcm","clk":"1005607411","pt":1580643562207,"mc":[{"id":"1.168224297","rc":[{"batb":[[0,1.5,84.02],[1,1.45,43.68],[2,1.43,46.11]],"batl":[[0,1.63,42.01]],"ltp":0.0,"tv":0.0,"id":2257317},{"batb":[[2,2.62,25.21]],"batl":[[0,3,21],[1,4.2,148.03]],"ltp":0.0,"tv":0.0,"id":10303696}]}]}
{"op":"mcm","clk":"1005607643","pt":1580643563328,"mc":[{"id":"1.168224297","rc":[{"batl":[[1,1.82,469.11]],"ltp":0.0,"tv":0.0,"id":2257317}]}]}
{"op":"mcm","clk":"1005625082","pt":1580643650252,"mc":[{"id":"1.168224297","rc":[{"batb":[[1,1.43,46.12],[2,1.01,15.51]],"ltp":0.0,"tv":0.0,"id":2257317},{"batb":[[0,2.8,11.02],[1,2.62,25.21],[2,1.01,15.52]],"ltp":0.0,"tv":0.0,"id":10303696}]}]}
{"op":"mcm","clk":"1005625279","pt":1580643651265,"mc":[{"id":"1.168224297","rc":[{"batb":[[0,1.43,46.12],[1,1.01,15.51],[2,1.01,0]],"batl":[[0,1.82,469.11],[1,1.82,0]],"ltp":0.0,"tv":0.0,"id":2257317},{"batb":[[1,1.01,15.52],[2,1.01,0]],"batl":[[0,4.2,148.03],[1,4.2,0]],"ltp":0.0,"tv":0.0,"id":10303696}]}]}
{"op":"mcm","clk":"1005628480","pt":1580643667247,"mc":[{"id":"1.168224297","rc":[{"batb":[[1,1.41,48.15],[2,1.01,15.51]],"ltp":0.0,"tv":0.0,"id":2257317},{"batb":[[0,3,23.05],[1,2.86,10.46],[2,1.01,15.52]],"ltp":0.0,"tv":0.0,"id":10303696}]}]}
{"op":"mcm","clk":"1005628684","pt":1580643668250,"mc":[{"id":"1.168224297","rc":[{"batb":[[0,1.49,85.7],[1,1.43,46.12],[2,1.41,48.15]],"batl":[[0,1.61,42.01],[1,1.82,469.11]],"ltp":0.0,"tv":0.0,"id":2257317},{"batb":[[2,2.66,25.21]],"batl":[[0,3.05,20.16],[1,4.2,148.03]],"ltp":0.0,"tv":0.0,"id":10303696}]}]}
{"op":"mcm","clk":"1005630439","pt":1580643677349,"mc":[{"id":"1.168224297","rc":[{"batb":[[0,1.43,46.12],[1,1.41,48.15],[2,1.01,15.51]],"batl":[[0,1.82,469.11],[1,1.82,0]],"ltp":0.0,"tv":0.0,"id":2257317},{"batb":[[2,1.01,15.52]],"batl":[[0,4.2,148.03],[1,4.2,0]],"ltp":0.0,"tv":0.0,"id":10303696}]}]}
{"op":"mcm","clk":"1005630579","pt":1580643678044,"mc":[{"id":"1.168224297","rc":[{"batb":[[0,1.41,48.16],[1,1.01,15.51],[2,1.01,0]],"ltp":0.0,"tv":0.0,"id":2257317},{"batb":[[0,2.86,10.46],[1,1.01,15.52],[2,1.01,0]],"ltp":0.0,"tv":0.0,"id":10303696}]}]}
{"op":"mcm","clk":"1005631120","pt":1580643680721,"mc":[{"id":"1.168224297","rc":[{"batb":[[0,1.42,47.06]],"ltp":0.0,"tv":0.0,"id":2257317},{"batb":[[0,2.84,10.62]],"ltp":0.0,"tv":0.0,"id":10303696}]}]}
{"op":"mcm","clk":"1005633821","pt":1580643694351,"mc":[{"id":"1.168224297","rc":[{"batb":[[0,1.5,84.02],[1,1.42,47.06],[2,1.01,15.51]],"batl":[[0,1.63,42.01],[1,1.82,469.11]],"ltp":0.0,"tv":0.0,"id":2257317},{"batb":[[1,2.6,26.05],[2,1.01,15.52]],"batl":[[0,2.98,21],[1,4.2,148.03]],"ltp":0.0,"tv":0.0,"id":10303696}]}]}
{"op":"mcm","clk":"1005633961","pt":1580643695053,"mc":[{"id":"1.168224297","rc":[{"batb":[[1,1.47,40.69],[2,1.45,43.12]],"ltp":0.0,"tv":0.0,"id":2257317},{"batb":[[1,2.7,12.04],[2,2.6,26.05]],"ltp":0.0,"tv":0.0,"id":10303696}]}]}
{"op":"mcm","clk":"1005636820","pt":1580643709250,"mc":[{"id":"1.168224297","rc":[{"batb":[[0,1.45,43.13],[1,1.01,15.51],[2,1.45,0]],"batl":[[0,1.82,469.11],[1,1.82,0]],"ltp":0.0,"tv":0.0,"id":2257317},{"batb":[[0,2.7,12.04],[1,1.01,15.52],[2,2.6,0]],"batl":[[0,4.2,148.03],[1,4.2,0]],"ltp":0.0,"tv":0.0,"id":10303696}]}]}
{"op":"mcm","clk":"1005639548","pt":1580643722272,"mc":[{"id":"1.168224297","rc":[{"batb":[[0,1.53,78.98],[1,1.45,43.13],[2,1.01,15.51]],"batl":[[0,1.66,42.01],[1,1.82,469.11]],"ltp":0.0,"tv":0.0,"id":2257317},{"batb":[[1,2.54,26.89],[2,1.01,15.52]],"batl":[[0,2.9,21.85],[1,4.2,148.03]],"ltp":0.0,"tv":0.0,"id":10303696}]}]}
{"op":"mcm","clk":"1005639675","pt":1580643722873,"mc":[{"id":"1.168224297","rc":[{"batb":[[1,1.51,36.74],[2,1.48,39.35]],"ltp":0.0,"tv":0.0,"id":2257317},{"batb":[[1,2.58,13.77],[2,2.54,26.89]],"ltp":0.0,"tv":0.0,"id":10303696}]}]}
{"op":"mcm","clk":"1005642320","pt":1580643736392,"mc":[{"id":"1.168224297","rc":[{"batb":[[1,1.48,39.35],[2,1.01,15.51]],"ltp":0.0,"tv":0.0,"id":2257317},{"batb":[[0,2.58,13.77],[1,2.54,26.89],[2,1.01,15.52]],"ltp":0.0,"tv":0.0,"id":10303696}]}]}
{"op":"mcm","clk":"1005642504","pt":1580643737300,"mc":[{"id":"1.168224297","rc":[{"batb":[[0,1.48,39.35],[1,1.01,15.51],[2,1.01,0]],"batl":[[0,1.82,469.11],[1,1.82,0]],"ltp":0.0,"tv":0.0,"id":2257317},{"batb":[[1,1.01,15.52],[2,1.01,0]],"batl":[[0,4.2,148.03],[1,4.2,0]],"ltp":0.0,"tv":0.0,"id":10303696}]}]}
{"op":"mcm","clk":"1005648098","pt":1580643765270,"mc":[{"id":"1.168224297","rc":[{"batb":[[1,1.46,41.86],[2,1.01,15.51]],"ltp":0.0,"tv":0.0,"id":2257317},{"batb":[[0,2.8,11.09],[1,2.64,12.75],[2,2.58,13.77]],"ltp":0.0,"tv":0.0,"id":10303696}]}]}
{"op":"mcm","clk":"1005648281","pt":1580643766279,"mc":[{"id":"1.168224297","rc":[{"batb":[[0,1.51,82.34],[1,1.48,39.35],[2,1.46,41.86]],"batl":[[0,1.65,42.01],[1,1.82,469.11]],"ltp":0.0,"tv":0.0,"id":2257317},{"batb":[[2,2.58,26.05]],"batl":[[0,2.94,21],[1,4.2,148.03]],"ltp":0.0,"tv":0.0,"id":10303696}]}]}
{"op":"mcm","clk":"1005652320","pt":1580643787390,"mc":[{"id":"1.168224297","rc":[{"batb":[[0,1.46,41.87],[1,1.01,15.51],[2,1.46,0]],"batl":[[0,1.82,469.11],[1,1.82,0]],"ltp":0.0,"tv":0.0,"id":2257317},{"batb":[[0,2.64,12.75],[1,1.01,15.52],[2,2.58,0]],"batl":[[0,4.2,148.03],[1,4.2,0]],"ltp":0.0,"tv":0.0,"id":10303696}]}]}
{"op":"mcm","clk":"1005656446","pt":1580643808379,"mc":[{"id":"1.168224297","rc":[{"batb":[[0,1.54,77.3],[1,1.53,35.09],[2,1.5,38]],"batl":[[0,1.67,42.01],[1,1.82,469.11]],"ltp":0.0,"tv":0.0,"id":2257317},{"batb":[[1,2.52,26.89],[2,2.48,15.11]],"batl":[[0,2.86,21.85]],"ltp":0.0,"tv":0.0,"id":10303696}]}]}
{"op":"mcm","clk":"1005656626","pt":1580643809351,"mc":[{"id":"1.168224297","rc":[{"batl":[[1,3.9,158.24]],"ltp":0.0,"tv":0.0,"id":10303696}]}]}
{"op":"mcm","clk":"1005659010","pt":1580643822391,"mc":[{"id":"1.168224297","rc":[{"batb":[[1,1.5,38],[2,1.01,15.52]],"ltp":0.0,"tv":0.0,"id":2257317},{"batb":[[0,2.52,26.89],[1,2.48,15.11],[2,1.01,15.52]],"ltp":0.0,"tv":0.0,"id":10303696}]}]}
{"op":"mcm","clk":"1005659194","pt":1580643823386,"mc":[{"id":"1.168224297","rc":[{"batb":[[0,1.5,38],[1,1.01,15.52],[2,1.01,0]],"batl":[[0,1.82,469.11],[1,1.82,0]],"ltp":0.0,"tv":0.0,"id":2257317},{"batb":[[0,2.48,15.11],[1,1.01,15.52],[2,1.01,0]],"batl":[[0,3.9,158.24],[1,3.9,0]],"ltp":0.0,"tv":0.0,"id":10303696}]}]}
{"op":"mcm","clk":"1005662749","pt":1580643842342,"mc":[{"id":"1.168224297","rc":[{"batb":[[0,1.59,30.37],[1,1.55,32.81],[2,1.01,15.52]],"batl":[[0,1.76,42.01],[1,1.82,469.11]],"ltp":0.0,"tv":0.0,"id":2257317},{"batb":[[1,2.44,16.05],[2,2.34,31.09]],"ltp":0.0,"tv":0.0,"id":10303696}]}]}
{"op":"mcm","clk":"1005662899","pt":1580643843224,"mc":[{"id":"1.168224297","rc":[{"batb":[[0,1.61,68.06],[1,1.59,30.37],[2,1.55,32.81]],"ltp":0.0,"tv":0.0,"id":2257317},{"batl":[[0,2.64,25.21],[1,3.9,158.24]],"ltp":0.0,"tv":0.0,"id":10303696}]}]}
{"op":"mcm","clk":"1005665887","pt":1580643860189,"mc":[{"id":"1.168224297","rc":[{"batb":[[1,1.55,32.81],[2,1.01,15.52]],"ltp":0.0,"tv":0.0,"id":2257317},{"batb":[[0,2.44,16.05],[1,2.34,31.09],[2,1.01,15.52]],"ltp":0.0,"tv":0.0,"id":10303696}]}]}
{"op":"mcm","clk":"1005666227","pt":1580643862061,"mc":[{"id":"1.168224297","rc":[{"batb":[[0,1.55,32.81],[1,1.01,15.52],[2,1.01,0]],"batl":[[0,1.82,469.11],[1,1.82,0]],"ltp":0.0,"tv":0.0,"id":2257317},{"batb":[[1,1.01,15.52],[2,1.01,0]],"batl":[[0,3.9,158.24],[1,3.9,0]],"ltp":0.0,"tv":0.0,"id":10303696}]}]}
{"op":"mcm","clk":"1005668901","pt":1580643877377,"mc":[{"id":"1.168224297","rc":[{"batb":[[1,1.52,35.25],[2,1.01,15.52]],"ltp":0.0,"tv":0.0,"id":2257317},{"batb":[[0,2.58,13.85],[1,2.5,14.79],[2,1.01,15.52]],"ltp":0.0,"tv":0.0,"id":10303696}]}]}
{"op":"mcm","clk":"1005669076","pt":1580643878385,"mc":[{"id":"1.168224297","rc":[{"trd":[[1.55,65.4]],"batb":[[0,1.52,35.36],[1,1.01,15.52],[2,1.01,0]],"batl":[[0,1.75,42.01],[1,1.82,469.11]],"ltp":1.55,"tv":65.4,"id":2257317},{"batb":[[2,2.36,30.25]],"ltp":0.0,"tv":0.0,"id":10303696}],"tv":65.4}]}
{"op":"mcm","clk":"1005669914","pt":1580643883224,"mc":[{"id":"1.168224297","rc":[{"batb":[[0,1.59,70.58],[1,1.52,35.36],[2,1.01,15.52]],"ltp":1.55,"tv":65.4,"id":2257317}]}]}
{"op":"mcm","clk":"1005670068","pt":1580643884075,"mc":[{"id":"1.168224297","rc":[{"batb":[[0,2.6,441.99],[1,2.58,13.85],[2,2.5,14.79]],"ltp":0.0,"tv":0.0,"id":10303696}]}]}
{"op":"mcm","clk":"1005671013","pt":1580643889200,"mc":[{"id":"1.168224297","rc":[{"batb":[[0,2.58,13.85],[1,2.5,14.79],[2,2.36,30.25]],"ltp":0.0,"tv":0.0,"id":10303696}]}]}
{"op":"mcm","clk":"1005671104","pt":1580643889683,"mc":[{"id":"1.168224297","rc":[{"batb":[[0,1.52,35.25],[1,1.01,15.52],[2,1.01,0]],"batl":[[0,1.82,469.11],[1,1.82,0]],"ltp":1.55,"tv":65.4,"id":2257317},{"batb":[[0,2.5,14.79],[1,1.01,15.52],[2,2.36,0]],"ltp":0.0,"tv":0.0,"id":10303696}]}]}
{"op":"mcm","clk":"1005671712","pt":1580643892784,"mc":[{"id":"1.168224297","rc":[{"batb":[[0,2.6,14.4]],"ltp":0.0,"tv":0.0,"id":10303696}]}]}
{"op":"mcm","clk":"1005675587","pt":1580643912326,"mc":[{"id":"1.168224297","rc":[{"batb":[[0,1.57,31.71],[1,1.54,33.75],[2,1.52,35.25]],"ltp":1.55,"tv":65.4,"id":2257317},{"batb":[[1,2.54,15.34],[2,1.01,15.52]],"ltp":0.0,"tv":0.0,"id":10303696}]}]}
{"op":"mcm","clk":"1005675723","pt":1580643913032,"mc":[{"id":"1.168224297","rc":[{"batb":[[0,1.6,69.74],[1,1.57,31.71],[2,1.54,33.75]],"batl":[[0,1.75,42.01],[1,1.82,469.11]],"ltp":1.55,"tv":65.4,"id":2257317},{"batb":[[2,2.36,30.25]],"batl":[[0,2.66,25.21],[1,3.9,158.24]],"ltp":0.0,"tv":0.0,"id":10303696}]}]}
{"op":"mcm","clk":"1005677075","pt":1580643919916,"mc":[{"id":"1.168224297","rc":[{"batb":[[1,1.54,33.75],[2,1.01,15.52]],"ltp":1.55,"tv":65.4,"id":2257317},{"batb":[[0,2.54,15.34],[1,2.36,30.25],[2,1.01,15.52]],"ltp":0.0,"tv":0.0,"id":10303696}]}]}
{"op":"mcm","clk":"1005677377","pt":1580643921526,"mc":[{"id":"1.168224297","rc":[{"batb":[[0,1.54,33.75],[1,1.01,15.52],[2,1.01,0]],"batl":[[0,1.82,469.11],[1,1.82,0]],"ltp":1.55,"tv":65.4,"id":2257317},{"batb":[[1,1.01,15.52],[2,1.01,0]],"batl":[[0,3.9,158.24],[1,3.9,0]],"ltp":0.0,"tv":0.0,"id":10303696}]}]}
{"op":"mcm","clk":"1005680134","pt":1580643936369,"mc":[{"id":"1.168224297","rc":[{"batb":[[0,1.6,69.74],[1,1.54,33.75],[2,1.01,15.52]],"batl":[[0,1.76,42.01],[1,1.82,469.11]],"ltp":1.55,"tv":65.4,"id":2257317},{"batb":[[1,2.34,31.09],[2,1.01,15.52]],"batl":[[0,2.66,25.21],[1,3.9,158.24]],"ltp":0.0,"tv":0.0,"id":10303696}]}]}
{"op":"mcm","clk":"1005680290","pt":1580643937178,"mc":[{"id":"1.168224297","rc":[{"batb":[[1,1.59,30.06],[2,1.56,32.34]],"ltp":1.55,"tv":65.4,"id":2257317},{"batb":[[1,2.5,15.97],[2,2.34,31.09]],"ltp":0.0,"tv":0.0,"id":10303696}]}]}
{"op":"mcm","clk":"1005682120","pt":1580643947108,"mc":[{"id":"1.168224297","rc":[{"batb":[[1,1.56,32.34],[2,1.01,15.52]],"ltp":1.55,"tv":65.4,"id":2257317},{"batb":[[0,2.5,15.97],[1,2.34,31.09],[2,1.01,15.52]],"ltp":0.0,"tv":0.0,"id":10303696}]}]}
{"op":"mcm","clk":"1005682288","pt":1580643947967,"mc":[{"id":"1.168224297","rc":[{"batb":[[0,1.56,32.34],[1,1.01,15.52],[2,1.01,0]],"batl":[[0,1.82,469.11],[1,1.82,0]],"ltp":1.55,"tv":65.4,"id":2257317},{"batb":[[1,1.01,15.52],[2,1.01,0]],"batl":[[0,3.9,158.24],[1,3.9,0]],"ltp":0.0,"tv":0.0,"id":10303696}]}]}
{"op":"mcm","clk":"1005684581","pt":1580643960387,"mc":[{"id":"1.168224297","rc":[{"batb":[[0,1.6,69.74],[1,1.56,32.34],[2,1.01,15.52]],"batl":[[0,1.75,42.01],[1,1.82,469.11]],"ltp":1.55,"tv":65.4,"id":2257317},{"batb":[[1,2.36,30.25],[2,1.01,15.52]],"batl":[[0,2.68,24.37],[1,3.9,158.24]],"ltp":0.0,"tv":0.0,"id":10303696}]}]}
{"op":"mcm","clk":"1005684744","pt":1580643961212,"mc":[{"id":"1.168224297","rc":[{"trd":[[1.6,64.34]],"batb":[[0,1.6,37.57],[2,1.53,34.46]],"batl":[[0,1.82,469.11],[1,1.82,0]],"ltp":1.6,"tv":129.74,"id":2257317},{"batb":[[0,2.62,14.08],[1,2.56,15.03]],"ltp":0.0,"tv":0.0,"id":10303696}],"tv":129.74}]}
{"op":"mcm","clk":"1005685334","pt":1580643964216,"mc":[{"id":"1.168224297","rc":[{"batb":[[0,1.6,69.49]],"batl":[[0,1.72,42.01],[1,1.82,469.11]],"ltp":1.6,"tv":129.74,"id":2257317},{"batb":[[2,2.42,29.41]],"ltp":0.0,"tv":0.0,"id":10303696}]}]}
{"op":"mcm","clk":"1005686424","pt":1580643970192,"mc":[{"id":"1.168224297","rc":[{"batb":[[1,1.53,34.46],[2,1.01,15.52]],"ltp":1.6,"tv":129.74,"id":2257317},{"batb":[[0,2.56,15.03],[1,2.42,29.41],[2,1.01,15.52]],"ltp":0.0,"tv":0.0,"id":10303696}]}]}
{"op":"mcm","clk":"1005686636","pt":1580643971418,"mc":[{"id":"1.168224297","rc":[{"batb":[[0,1.53,34.46],[1,1.01,15.52],[2,1.01,0]],"batl":[[0,1.82,469.11],[1,1.82,0]],"ltp":1.6,"tv":129.74,"id":2257317},{"batb":[[1,1.01,15.52],[2,1.01,0]],"batl":[[0,3.9,158.24],[1,3.9,0]],"ltp":0.0,"tv":0.0,"id":10303696}]}]}
{"op":"mcm","clk":"1005686994","pt":1580643973399,"mc":[{"id":"1.168224297","rc":[{"batb":[[0,2.58,14.71]],"ltp":0.0,"tv":0.0,"id":10303696}]}]}
{"op":"mcm","clk":"1005687818","pt":1580643978397,"mc":[{"id":"1.168224297","rc":[{"batb":[[0,1.59,70.58],[1,1.58,31.08],[2,1.55,32.81]],"batl":[[0,1.73,42.01],[1,1.82,469.11]],"ltp":1.6,"tv":129.74,"id":2257317},{"batb":[[1,2.52,15.42],[2,2.4,29.41]],"batl":[[0,2.68,24.37],[1,3.9,158.24]],"ltp":0.0,"tv":0.0,"id":10303696}]}]}
{"op":"mcm","clk":"1005689158","pt":1580643986008,"mc":[{"id":"1.168224297","rc":[{"batb":[[0,1.55,32.81],[1,1.01,15.52],[2,1.55,0]],"batl":[[0,1.82,469.11],[1,1.82,0]],"ltp":1.6,"tv":129.74,"id":2257317},{"batb":[[0,2.52,15.42],[1,1.01,15.52],[2,2.4,0]],"batl":[[0,3.9,158.24],[1,3.9,0]],"ltp":0.0,"tv":0.0,"id":10303696}]}]}
{"op":"mcm","clk":"1005689641","pt":1580643989186,"mc":[{"id":"1.168224297","rc":[{"batb":[[0,2.54,15.34]],"ltp":0.0,"tv":0.0,"id":10303696}]}]}
{"op":"mcm","clk":"1005692918","pt":1580644008366,"mc":[{"id":"1.168224297","rc":[{"batb":[[0,1.59,70.58],[1,1.55,32.81],[2,1.53,35.09]],"batl":[[0,1.72,42.01],[1,1.82,469.11]],"ltp":1.6,"tv":129.74,"id":2257317},{"batb":[[0,2.64,13.77],[1,2.58,14.79],[2,2.42,29.41]],"batl":[[0,2.7,24.37],[1,3.9,158.24]],"ltp":0.0,"tv":0.0,"id":10303696}]}]}
{"op":"mcm","clk":"1005694554","pt":1580644018923,"mc":[{"id":"1.168224297","rc":[{"batb":[[1,1.53,35.09],[2,1.01,15.52]],"ltp":1.6,"tv":129.74,"id":2257317},{"batb":[[0,2.58,14.79],[1,2.42,29.41],[2,1.01,15.52]],"ltp":0.0,"tv":0.0,"id":10303696}]}]}
{"op":"mcm","clk":"1005694802","pt":1580644020315,"mc":[{"id":"1.168224297","rc":[{"batb":[[0,1.53,35.09],[1,1.01,15.52],[2,1.01,0]],"batl":[[0,1.82,469.11],[1,1.82,0]],"ltp":1.6,"tv":129.74,"id":2257317},{"batb":[[1,1.01,15.52],[2,1.01,0]],"batl":[[0,3.9,158.24],[1,3.9,0]],"ltp":0.0,"tv":0.0,"id":10303696}]}]}
{"op":"mcm","clk":"1005698037","pt":1580644040405,"mc":[{"id":"1.168224297","rc":[{"batl":[[0,1.71,42.01],[1,1.82,469.11]],"ltp":1.6,"tv":129.74,"id":2257317},{"batb":[[0,2.6,441.99],[1,2.58,14.79],[2,2.44,28.57]],"ltp":0.0,"tv":0.0,"id":10303696}]}]}
{"op":"mcm","clk":"1005698185","pt":1580644041402,"mc":[{"id":"1.168224297","rc":[{"trd":[[1.53,69.68]],"batb":[[0,1.49,39.28]],"ltp":1.53,"tv":199.42,"id":2257317},{"batb":[[0,2.72,12.75],[1,2.62,13.93]],"ltp":0.0,"tv":0.0,"id":10303696}],"tv":199.42}]}
{"op":"mcm","clk":"1005698707","pt":1580644044400,"mc":[{"id":"1.168224297","rc":[{"batl":[[0,1.82,469.11],[1,1.82,0]],"ltp":1.53,"tv":199.42,"id":2257317}]}]}
{"op":"mcm","clk":"1005699125","pt":1580644047020,"mc":[{"id":"1.168224297","rc":[{"batl":[[0,1.69,42.01],[1,1.82,469.11]],"ltp":1.53,"tv":199.42,"id":2257317},{"trd":[[2.72,25.21]],"batb":[[0,2.62,14.07],[1,2.44,28.57],[2,1.01,15.52]],"ltp":2.72,"tv":25.2,"id":10303696}],"tv":224.63}]}
{"op":"mcm","clk":"1005699675","pt":1580644050203,"mc":[{"id":"1.168224297","rc":[{"batb":[[1,1.01,15.52],[2,1.01,0]],"ltp":2.72,"tv":25.2,"id":10303696}]}]}
{"op":"mcm","clk":"1005700226","pt":1580644053387,"mc":[{"id":"1.168224297","rc":[{"batb":[[0,1.49,39.03]],"batl":[[0,1.82,469.11],[1,1.82,0]],"ltp":1.53,"tv":199.42,"id":2257317},{"batb":[[0,2.62,13.93],[1,2.48,27.73],[2,1.01,15.52]],"batl":[[0,2.76,23.53],[1,3.9,158.24]],"ltp":2.72,"tv":25.2,"id":10303696}]}]}
{"op":"mcm","clk":"1005700301","pt":1580644053813,"mc":[{"id":"1.168224297","rc":[{"batb":[[1,1.01,15.52],[2,1.01,0]],"batl":[[0,3.9,158.24],[1,3.9,0]],"ltp":2.72,"tv":25.2,"id":10303696}]}]}
{"op":"mcm","clk":"1005700722","pt":1580644056199,"mc":[{"id":"1.168224297","rc":[{"batb":[[1,1.48,39.43],[2,1.01,15.51]],"ltp":1.53,"tv":199.42,"id":2257317},{"batb":[[0,2.64,13.85],[1,2.62,13.93],[2,1.01,15.52]],"ltp":2.72,"tv":25.2,"id":10303696}]}]}
{"op":"mcm","clk":"1005700830","pt":1580644056892,"mc":[{"id":"1.168224297","rc":[{"batb":[[0,1.48,39.43],[1,1.01,15.51],[2,1.01,0]],"ltp":1.53,"tv":199.42,"id":2257317},{"batb":[[1,1.01,15.52],[2,1.01,0]],"ltp":2.72,"tv":25.2,"id":10303696}]}]}
{"op":"mcm","clk":"1005702109","pt":1580644065402,"mc":[{"id":"1.168224297","rc":[{"batb":[[0,1.57,73.1],[1,1.55,32.81],[2,1.52,35.25]],"batl":[[0,1.69,42.01],[1,1.82,469.11]],"ltp":1.53,"tv":199.42,"id":2257317},{"batb":[[1,2.58,14.63],[2,1.01,15.52]],"batl":[[0,2.74,23.53],[1,3.9,158.24]],"ltp":2.72,"tv":25.2,"id":10303696}]}]}
{"op":"mcm","clk":"1005702178","pt":1580644065829,"mc":[{"id":"1.168224297","rc":[{"batb":[[0,1.55,32.81],[1,1.52,35.25],[2,1.49,1024.01]],"ltp":1.53,"tv":199.42,"id":2257317}]}]}
{"op":"mcm","clk":"1005702360","pt":1580644067035,"mc":[{"id":"1.168224297","rc":[{"batb":[[0,1.58,72.26],[1,1.55,32.81],[2,1.52,35.25]],"ltp":1.53,"tv":199.42,"id":2257317},{"batb":[[2,2.46,28.57]],"ltp":2.72,"tv":25.2,"id":10303696}]}]}
{"op":"mcm","clk":"1005703328","pt":1580644073355,"mc":[{"id":"1.168224297","rc":[{"batb":[[1,1.52,35.25],[2,1.01,15.52]],"ltp":1.53,"tv":199.42,"id":2257317},{"batb":[[0,2.58,14.63],[1,2.46,28.57],[2,1.01,15.52]],"ltp":2.72,"tv":25.2,"id":10303696}]}]}
{"op":"mcm","clk":"1005703423","pt":1580644073944,"mc":[{"id":"1.168224297","rc":[{"batb":[[0,1.52,35.25],[1,1.01,15.52],[2,1.01,0]],"batl":[[0,1.82,469.11],[1,1.82,0]],"ltp":1.53,"tv":199.42,"id":2257317},{"batb":[[1,1.01,15.52],[2,1.01,0]],"batl":[[0,3.9,158.24],[1,3.9,0]],"ltp":2.72,"tv":25.2,"id":10303696}]}]}
{"op":"mcm","clk":"1005705354","pt":1580644087130,"mc":[{"id":"1.168224297","rc":[{"batb":[[0,1.57,31.24],[1,1.56,32.65],[2,1.01,15.52]],"ltp":1.53,"tv":199.42,"id":2257317},{"batb":[[1,2.54,15.34],[2,1.01,15.52]],"ltp":2.72,"tv":25.2,"id":10303696}]}]}
{"op":"mcm","clk":"1005705599","pt":1580644088927,"mc":[{"id":"1.168224297","rc":[{"batb":[[0,1.58,72.26],[1,1.57,31.24],[2,1.56,32.65]],"batl":[[0,1.7,42.01],[1,1.82,469.11]],"ltp":1.53,"tv":199.42,"id":2257317},{"batb":[[2,2.46,28.57]],"batl":[[0,2.72,24.37],[1,3.9,158.24]],"ltp":2.72,"tv":25.2,"id":10303696}]}]}
{"op":"mcm","clk":"1005706640","pt":1580644096275,"mc":[{"id":"1.168224297","rc":[{"batb":[[1,1.56,32.65],[2,1.01,15.52]],"ltp":1.53,"tv":199.42,"id":2257317},{"batb":[[0,2.54,15.34],[1,2.46,28.57],[2,1.01,15.52]],"ltp":2.72,"tv":25.2,"id":10303696}]}]}
{"op":"mcm","clk":"1005706823","pt":1580644097594,"mc":[{"id":"1.168224297","rc":[{"batb":[[0,1.56,32.65],[1,1.01,15.52],[2,1.01,0]],"batl":[[0,1.82,469.11],[1,1.82,0]],"ltp":1.53,"tv":199.42,"id":2257317},{"batb":[[1,1.01,15.52],[2,1.01,0]],"batl":[[0,3.9,158.24],[1,3.9,0]],"ltp":2.72,"tv":25.2,"id":10303696}]}]}
{"op":"mcm","clk":"1005708066","pt":1580644105766,"mc":[{"id":"1.168224297","rc":[{"batb":[[0,1.59,30.29],[1,1.57,31.79],[2,1.01,15.52]],"ltp":1.53,"tv":199.42,"id":2257317},{"batb":[[0,2.54,15.19],[1,2.46,16.76],[2,1.01,15.52]],"ltp":2.72,"tv":25.2,"id":10303696}]}]}
{"op":"mcm","clk":"1005708268","pt":1580644107090,"mc":[{"id":"1.168224297","rc":[{"batb":[[0,1.59,100.87]],"batl":[[0,1.7,42.01],[1,1.82,469.11]],"ltp":1.53,"tv":199.42,"id":2257317},{"batb":[[2,2.44,28.57]],"batl":[[0,2.7,24.37],[1,3.9,158.24]],"ltp":2.72,"tv":25.2,"id":10303696}]}]}
{"op":"mcm","clk":"1005708836","pt":1580644111315,"mc":[{"id":"1.168224297","rc":[{"batl":[[1,1.82,0]],"ltp":1.53,"tv":199.42,"id":2257317},{"batl":[[1,3.9,0]],"ltp":2.72,"tv":25.2,"id":10303696}]}]}
{"op":"mcm","clk":"1005709498","pt":1580644116418,"mc":[{"id":"1.168224297","rc":[{"batl":[[1,2.1,363.31]],"ltp":1.53,"tv":199.42,"id":2257317},{"batl":[[1,3.45,180.4]],"ltp":2.72,"tv":25.2,"id":10303696}]}]}
{"op":"mcm","clk":"1005710030","pt":1580644120091,"mc":[{"id":"1.168224297","rc":[{"trd":[[1.59,201.35]],"batb":[[0,1.57,31.79],[1,1.01,15.52],[2,1.01,0]],"batl":[[0,2.1,363.31],[1,2.1,0]],"ltp":1.59,"tv":400.77,"id":2257317}],"tv":425.97}]}
{"op":"mcm","clk":"1005710100","pt":1580644120607,"mc":[{"id":"1.168224297","rc":[{"batb":[[2,1.01,15.52]],"ltp":2.72,"tv":25.2,"id":10303696}]}]}
{"op":"mcm","clk":"1005710435","pt":1580644123011,"mc":[{"id":"1.168224297","rc":[{"batb":[[0,1.58,72.26],[1,1.57,31.79],[2,1.01,15.52]],"batl":[[0,1.69,42.01],[1,2.1,363.31]],"ltp":1.59,"tv":400.77,"id":2257317}]}]}
{"op":"mcm","clk":"1005710578","pt":1580644124011,"mc":[{"id":"1.168224297","rc":[{"batb":[[1,2.48,27.73],[2,2.46,16.76]],"ltp":2.72,"tv":25.2,"id":10303696}]}]}
{"op":"mcm","clk":"1005710658","pt":1580644124707,"mc":[{"id":"1.168224297","rc":[{"batb":[[0,1.58,103.26],[1,1.56,32.5]],"ltp":1.59,"tv":400.77,"id":2257317},{"batb":[[0,2.56,14.79],[1,2.48,44.01],[2,1.01,15.52]],"ltp":2.72,"tv":25.2,"id":10303696}]}]}
{"op":"mcm","clk":"1005719570","pt":1580644192398,"mc":[{"id":"1.168224297","rc":[{"batb":[[0,1.58,72.26]],"ltp":1.59,"tv":400.77,"id":2257317},{"batb":[[0,2.48,44.01],[1,1.01,15.52],[2,1.01,0]],"ltp":2.72,"tv":25.2,"id":10303696}]}]}
{"op":"mcm","clk":"1005719782","pt":1580644193875,"mc":[{"id":"1.168224297","rc":[{"batb":[[0,1.56,32.5],[1,1.01,15.52],[2,1.01,0]],"batl":[[0,2.1,363.31],[1,2.1,0]],"ltp":1.59,"tv":400.77,"id":2257317},{"batb":[[0,2.48,16.29]],"batl":[[0,3.45,180.4],[1,3.45,0]],"ltp":2.72,"tv":25.2,"id":10303696}]}]}
{"op":"mcm","clk":"1005721414","pt":1580644205193,"mc":[{"id":"1.168224297","rc":[{"batb":[[1,1.53,34.38],[2,1.01,15.52]],"ltp":1.59,"tv":400.77,"id":2257317},{"batb":[[0,2.62,14.01],[1,2.54,15.34],[2,2.48,16.29]],"ltp":2.72,"tv":25.2,"id":10303696}]}]}
{"op":"mcm","clk":"1005721438","pt":1580644205408,"mc":[{"id":"1.168224297","rc":[{"batb":[[2,1.01,15.52]],"ltp":2.72,"tv":25.2,"id":10303696}]}]}
{"op":"mcm","clk":"1005721692","pt":1580644207184,"mc":[{"id":"1.168224297","rc":[{"batb":[[0,1.56,107.27]],"batl":[[0,1.68,42.01],[1,2.1,363.31]],"ltp":1.59,"tv":400.77,"id":2257317},{"batb":[[1,2.58,437.37],[2,2.54,15.34]],"batl":[[0,2.78,23.53],[1,3.45,180.4]],"ltp":2.72,"tv":25.2,"id":10303696}]}]}
{"op":"mcm","clk":"1005723018","pt":1580644216216,"mc":[{"id":"1.168224297","rc":[{"batb":[[0,1.56,74.78]],"ltp":1.59,"tv":400.77,"id":2257317},{"batb":[[0,2.54,15.34],[1,2.5,27.73],[2,1.01,15.52]],"ltp":2.72,"tv":25.2,"id":10303696}]}]}
{"op":"mcm","clk":"1005723365","pt":1580644218307,"mc":[{"id":"1.168224297","rc":[{"batb":[[0,1.53,34.38],[1,1.01,15.52],[2,1.01,0]],"batl":[[0,2.1,363.31],[1,2.1,0]],"ltp":1.59,"tv":400.77,"id":2257317},{"batb":[[0,2.78,23.48],[1,2.54,15.34]],"batl":[[0,3.45,180.4],[1,3.45,0]],"ltp":2.72,"tv":25.2,"id":10303696}]}]}
{"op":"mcm","clk":"1005723520","pt":1580644219101,"mc":[{"id":"1.168224297","rc":[{"batb":[[0,2.54,15.34],[1,1.01,15.52],[2,1.01,0]],"ltp":2.72,"tv":25.2,"id":10303696}]}]}
{"op":"mcm","clk":"1005726418","pt":1580644238393,"mc":[{"id":"1.168224297","rc":[{"batb":[[0,1.59,29.98],[1,1.57,31.71],[2,1.53,34.38]],"ltp":1.59,"tv":400.77,"id":2257317},{"batb":[[1,2.44,17],[2,1.01,15.52]],"ltp":2.72,"tv":25.2,"id":10303696}]}]}
{"op":"mcm","clk":"1005726459","pt":1580644238662,"mc":[{"id":"1.168224297","rc":[{"batb":[[1,1.58,72.26],[2,1.57,31.71]],"batl":[[0,1.7,42.01],[1,2.1,363.31]],"ltp":1.59,"tv":400.77,"id":2257317},{"batb":[[1,2.44,45.56]],"batl":[[0,2.7,24.37],[1,3.45,180.4]],"ltp":2.72,"tv":25.2,"id":10303696}]}]}
{"op":"mcm","clk":"1005727155","pt":1580644243184,"mc":[{"id":"1.168224297","rc":[{"trd":[[1.59,261.13]],"batb":[[0,1.58,72.34],[1,1.57,31.71],[2,1.01,15.52]],"ltp":1.59,"tv":460.55,"id":2257317}],"tv":485.75}]}
{"op":"mcm","clk":"1005727462","pt":1580644245397,"mc":[{"id":"1.168224297","rc":[{"batb":[[0,1.58,72.26]],"ltp":1.59,"tv":460.55,"id":2257317},{"batb":[[0,2.44,45.56],[1,1.01,15.52],[2,1.01,0]],"ltp":2.72,"tv":25.2,"id":10303696}]}]}
{"op":"mcm","clk":"1005727580","pt":1580644246200,"mc":[{"id":"1.168224297","rc":[{"batb":[[0,1.57,31.71],[1,1.01,15.52],[2,1.01,0]],"batl":[[0,2.1,363.31],[1,2.1,0]],"ltp":1.59,"tv":460.55,"id":2257317},{"batb":[[0,2.44,17]],"batl":[[0,3.45,180.4],[1,3.45,0]],"ltp":2.72,"tv":25.2,"id":10303696}]}]}
{"op":"mcm","clk":"1005727926","pt":1580644248393,"mc":[{"id":"1.168224297","rc":[{"batb":[[1,1.56,32.42],[2,1.01,15.52]],"ltp":1.59,"tv":460.55,"id":2257317},{"batb":[[0,2.46,16.52],[1,2.44,17],[2,1.01,15.52]],"ltp":2.72,"tv":25.2,"id":10303696}]}]}
{"op":"mcm","clk":"1005728077","pt":1580644249321,"mc":[{"id":"1.168224297","rc":[{"batb":[[0,1.56,32.42],[1,1.01,15.52],[2,1.01,0]],"ltp":1.59,"tv":460.55,"id":2257317},{"batb":[[1,1.01,15.52],[2,1.01,0]],"ltp":2.72,"tv":25.2,"id":10303696}]}]}
{"op":"mcm","clk":"1005730361","pt":1580644265953,"mc":[{"id":"1.168224297","rc":[{"batb":[[1,1.54,34.07],[2,1.01,15.52]],"ltp":1.59,"tv":460.55,"id":2257317},{"batb":[[0,2.62,14.01],[1,2.52,15.5],[2,2.46,451.88]],"ltp":2.72,"tv":25.2,"id":10303696}]}]}
{"op":"mcm","clk":"1005730428","pt":1580644266477,"mc":[{"id":"1.168224297","rc":[{"batb":[[0,1.57,73.1],[1,1.56,32.42],[2,1.54,34.07]],"batl":[[0,1.69,42.01],[1,2.1,363.31]],"ltp":1.59,"tv":460.55,"id":2257317},{"batb":[[2,2.48,27.73]],"batl":[[0,2.74,23.53],[1,3.45,180.4]],"ltp":2.72,"tv":25.2,"id":10303696}]}]}
{"op":"mcm","clk":"1005731423","pt":1580644274081,"mc":[{"id":"1.168224297","rc":[{"batb":[[0,1.54,34.07],[1,1.01,15.52],[2,1.54,0]],"batl":[[0,2.1,363.31],[1,2.1,0]],"ltp":1.59,"tv":460.55,"id":2257317},{"batb":[[0,2.52,15.5],[1,1.01,15.52],[2,2.48,0]],"batl":[[0,3.45,180.4],[1,3.45,0]],"ltp":2.72,"tv":25.2,"id":10303696}]}]}
{"op":"mcm","clk":"1005734621","pt":1580644296398,"mc":[{"id":"1.168224297","rc":[{"batb":[[1,1.52,35.41],[2,1.01,15.52]],"ltp":1.59,"tv":460.55,"id":2257317},{"batb":[[0,2.68,13.22],[1,2.58,14.71],[2,2.46,453.51]],"ltp":2.72,"tv":25.2,"id":10303696}]}]}
{"op":"mcm","clk":"1005734650","pt":1580644296616,"mc":[{"id":"1.168224297","rc":[{"batb":[[0,1.56,74.78],[1,1.54,34.07],[2,1.52,35.41]],"batl":[[0,1.68,42.01],[1,2.1,363.31]],"ltp":1.59,"tv":460.55,"id":2257317},{"batb":[[2,2.5,27.73]],"batl":[[0,2.78,23.53],[1,3.45,180.4]],"ltp":2.72,"tv":25.2,"id":10303696}]}]}
{"op":"mcm","clk":"1005735843","pt":1580644304962,"mc":[{"id":"1.168224297","rc":[{"batb":[[1,1.52,35.41],[2,1.01,15.52]],"ltp":1.59,"tv":460.55,"id":2257317},{"batb":[[0,2.58,14.71],[1,2.5,27.73],[2,1.01,15.52]],"ltp":2.72,"tv":25.2,"id":10303696}]}]}
{"op":"mcm","clk":"1005735914","pt":1580644305552,"mc":[{"id":"1.168224297","rc":[{"batb":[[0,1.52,35.41],[1,1.01,15.52],[2,1.01,0]],"batl":[[0,2.1,363.31],[1,2.1,0]],"ltp":1.59,"tv":460.55,"id":2257317},{"batb":[[1,1.01,15.52],[2,1.01,0]],"batl":[[0,3.45,180.4],[1,3.45,0]],"ltp":2.72,"tv":25.2,"id":10303696}]}]}
{"op":"mcm","clk":"1005738781","pt":1580644326386,"mc":[{"id":"1.168224297","rc":[{"batb":[[0,1.53,218.85],[1,1.52,202.34],[2,1.01,15.52]],"batl":[[0,1.58,126.38],[1,1.59,138.9],[2,2.1,363.31]],"ltp":1.59,"tv":460.55,"id":2257317}]}]}
{"op":"mcm","clk":"1005738914","pt":1580644327386,"mc":[{"id":"1.168224297","rc":[{"batb":[[0,1.55,75.62],[1,1.53,218.85],[2,1.52,202.34]],"batl":[[2,1.66,42.01]],"ltp":1.59,"tv":460.55,"id":2257317},{"batb":[[0,2.72,12.67],[1,2.54,26.89],[2,2.5,15.89]],"batl":[[0,2.82,22.69],[1,3.45,180.4]],"ltp":2.72,"tv":25.2,"id":10303696}]}]}
{"op":"mcm","clk":"1005748080","pt":1580644399122,"mc":[{"id":"1.168224297","rc":[{"batl":[[0,1.59,138.9],[1,1.66,42.01],[2,2.1,363.31]],"ltp":1.59,"tv":460.55,"id":2257317}]}]}
{"op":"mcm","clk":"1005748491","pt":1580644402126,"mc":[{"id":"1.168224297","rc":[{"batl":[[0,1.59,252.97],[1,1.6,135.16],[2,1.66,42.01]],"ltp":1.59,"tv":460.55,"id":2257317}]}]}
{"op":"mcm","clk":"1005752118","pt":1580644430338,"mc":[{"id":"1.168224297","rc":[{"batb":[[1,1.53,250.78]],"ltp":1.59,"tv":460.55,"id":2257317}]}]}
{"op":"mcm","clk":"1005752517","pt":1580644433180,"mc":[{"id":"1.168224297","rc":[{"batb":[[1,1.41,48.24],[2,1.01,15.51]],"batl":[[0,1.66,42.01],[1,2.1,363.31],[2,1.66,0]],"ltp":1.59,"tv":460.55,"id":2257317},{"batb":[[0,2.54,26.89],[1,2.5,15.89],[2,1.01,15.52]],"ltp":2.72,"tv":25.2,"id":10303696}]}]}
{"op":"mcm","clk":"1005752590","pt":1580644433679,"mc":[{"id":"1.168224297","rc":[{"batb":[[0,1.41,48.24],[1,1.01,15.51],[2,1.01,0]],"batl":[[0,2.1,363.31],[1,2.1,0]],"ltp":1.59,"tv":460.55,"id":2257317},{"batb":[[0,2.5,15.89],[1,1.01,15.52],[2,1.01,0]],"batl":[[0,3.45,180.4],[1,3.45,0]],"ltp":2.72,"tv":25.2,"id":10303696}]}]}
{"op":"mcm","clk":"1005752925","pt":1580644436377,"mc":[{"id":"1.168224297","rc":[{"batb":[[0,1.42,400.55],[1,1.41,230.71],[2,1.01,15.51]],"batl":[[0,1.68,222.72],[1,1.7,219.73],[2,2.1,363.31]],"ltp":1.59,"tv":460.55,"id":2257317},{"batb":[[0,2.48,16.21]],"ltp":2.72,"tv":25.2,"id":10303696}]}]}
{"op":"mcm","clk":"1005754559","pt":1580644450113,"mc":[{"id":"1.168224297","rc":[{"batb":[[0,1.42,47.53],[1,1.01,15.51],[2,1.01,0]],"batl":[[0,2.1,363.31],[1,1.7,0],[2,2.1,0]],"ltp":1.59,"tv":460.55,"id":2257317}]}]}
{"op":"mcm","clk":"1005755142","pt":1580644454121,"mc":[{"id":"1.168224297","rc":[{"batb":[[0,1.42,400.55],[1,1.41,230.71],[2,1.01,15.51]],"batl":[[0,1.68,222.72],[1,1.7,219.73],[2,2.1,363.31]],"ltp":1.59,"tv":460.55,"id":2257317}]}]}
{"op":"mcm","clk":"1005755497","pt":1580644456634,"mc":[{"id":"1.168224297","rc":[{"batb":[[0,1.42,47.53],[1,1.01,15.51],[2,1.01,0]],"ltp":1.59,"tv":460.55,"id":2257317}]}]}
{"op":"mcm","clk":"1005755984","pt":1580644460307,"mc":[{"id":"1.168224297","rc":[{"batb":[[0,1.61,275.42],[1,1.6,136.82],[2,1.51,36.82]],"ltp":1.59,"tv":460.55,"id":2257317},{"batb":[[1,2.32,19.43],[2,1.01,15.52]],"ltp":2.72,"tv":25.2,"id":10303696}]}]}
{"op":"mcm","clk":"1005756033","pt":1580644460717,"mc":[{"id":"1.168224297","rc":[{"batb":[[0,1.61,343.48]],"batl":[[2,1.74,42.01]],"ltp":1.59,"tv":460.55,"id":2257317},{"batb":[[1,2.38,30.25],[2,2.32,19.43]],"batl":[[0,2.62,25.21]],"ltp":2.72,"tv":25.2,"id":10303696}]}]}
{"op":"mcm","clk":"1005756305","pt":1580644463010,"mc":[{"id":"1.168224297","rc":[{"batl":[[1,3.3,191.92]],"ltp":2.72,"tv":25.2,"id":10303696}]}]}
{"op":"mcm","clk":"1005757434","pt":1580644472351,"mc":[{"id":"1.168224297","rc":[{"batb":[[0,1.61,68.06],[1,1.51,36.82],[2,1.01,15.52]],"batl":[[0,1.74,42.01],[1,2.1,363.31],[2,1.74,0]],"ltp":1.59,"tv":460.55,"id":2257317},{"batb":[[0,2.38,30.25],[1,2.32,19.43],[2,1.01,15.52]],"ltp":2.72,"tv":25.2,"id":10303696}]}]}
{"op":"mcm","clk":"1005757638","pt":1580644473965,"mc":[{"id":"1.168224297","rc":[{"batb":[[0,1.51,36.82],[1,1.01,15.52],[2,1.01,0]],"batl":[[0,2.1,363.31],[1,2.1,0]],"ltp":1.59,"tv":460.55,"id":2257317},{"batb":[[0,2.32,19.43],[1,1.01,15.52],[2,1.01,0]],"batl":[[0,3.3,191.92],[1,3.3,0]],"ltp":2.72,"tv":25.2,"id":10303696}]}]}
{"op":"mcm","clk":"1005757771","pt":1580644474860,"mc":[{"id":"1.168224297","rc":[{"batb":[[0,1.51,286.49],[1,1.5,176.13],[2,1.01,15.52]],"batl":[[0,1.76,191.77],[1,1.78,188.6],[2,2.1,363.31]],"ltp":1.59,"tv":460.55,"id":2257317}]}]}
{"op":"mcm","clk":"1005759172","pt":1580644486271,"mc":[{"id":"1.168224297","rc":[{"batl":[[0,2.1,363.31],[1,1.78,0],[2,2.1,0]],"ltp":1.59,"tv":460.55,"id":2257317}]}]}
{"op":"mcm","clk":"1005759576","pt":1580644489251,"mc":[{"id":"1.168224297","rc":[{"batl":[[0,1.56,129.32],[1,1.57,145.43]],"ltp":1.59,"tv":460.55,"id":2257317}]}]}
{"op":"mcm","clk":"1005759644","pt":1580644489772,"mc":[{"id":"1.168224297","rc":[{"batb":[[2,1.39,52.49]],"ltp":1.59,"tv":460.55,"id":2257317},{"batb":[[0,2.78,12.04],[1,2.52,15.74],[2,1.01,15.52]],"ltp":2.72,"tv":25.2,"id":10303696}]}]}
{"op":"mcm","clk":"1005759813","pt":1580644491244,"mc":[{"id":"1.168224297","rc":[{"batb":[[0,1.54,77.3],[1,1.51,286.49],[2,1.5,176.13]],"batl":[[2,1.64,42.01]],"ltp":1.59,"tv":460.55,"id":2257317},{"batb":[[1,2.54,26.89],[2,2.52,15.74]],"batl":[[0,2.86,21.85],[1,3.9,158.24]],"ltp":2.72,"tv":25.2,"id":10303696}]}]}
{"op":"mcm","clk":"1005760494","pt":1580644496355,"mc":[{"id":"1.168224297","rc":[{"batb":[[1,1.39,52.49],[2,1.01,15.51]],"batl":[[0,1.64,42.01],[1,1.95,409.86],[2,1.64,0]],"ltp":1.59,"tv":460.55,"id":2257317},{"batb":[[0,2.54,26.89],[1,2.52,15.74],[2,1.01,15.52]],"ltp":2.72,"tv":25.2,"id":10303696}]}]}
{"op":"mcm","clk":"1005760677","pt":1580644497778,"mc":[{"id":"1.168224297","rc":[{"batb":[[0,1.39,52.49],[1,1.01,15.51],[2,1.01,0]],"batl":[[0,1.95,409.86],[1,1.95,0]],"ltp":1.59,"tv":460.55,"id":2257317},{"batb":[[0,2.52,15.74],[1,1.01,15.52],[2,1.01,0]],"batl":[[0,3.9,158.24],[1,3.9,0]],"ltp":2.72,"tv":25.2,"id":10303696}]}]}
{"op":"mcm","clk":"1005760838","pt":1580644499097,"mc":[{"id":"1.168224297","rc":[{"batb":[[0,1.39,279.89],[1,1.38,253.57],[2,1.01,15.51]],"batl":[[0,1.67,181.69],[1,1.69,224.41],[2,1.95,409.86]],"ltp":1.59,"tv":460.55,"id":2257317}]}]}
{"op":"mcm","clk":"1005762857","pt":1580644514721,"mc":[{"id":"1.168224297","rc":[{"batl":[[0,1.95,409.86],[1,1.69,0],[2,1.95,0]],"ltp":1.59,"tv":460.55,"id":2257317}]}]}
{"op":"mcm","clk":"1005763326","pt":1580644518324,"mc":[{"id":"1.168224297","rc":[{"trd":[[1.48,0.02]],"batb":[[0,1.39,279.88],[2,1.26,84.82]],"batl":[[0,1.43,222.17],[1,1.44,204.44]],"ltp":1.48,"tv":460.57,"id":2257317},{"batb":[[0,3.3,19.51],[1,2.84,11.33],[2,2.52,15.74]],"ltp":2.72,"tv":25.2,"id":10303696}],"tv":485.77}]}
{"op":"mcm","clk":"1005763478","pt":1580644519335,"mc":[{"id":"1.168224297","rc":[{"trd":[[1.43,194.92]],"batl":[[0,1.43,124.71]],"ltp":1.43,"tv":655.49,"id":2257317},{"batb":[[2,1.01,15.52]],"ltp":2.72,"tv":25.2,"id":10303696}],"tv":680.7}]}
{"op":"mcm","clk":"1005763720","pt":1580644521322,"mc":[{"id":"1.168224297","rc":[{"batb":[[0,1.42,99.98],[1,1.39,279.88],[2,1.38,253.57]],"batl":[[2,1.51,42.01]],"ltp":1.43,"tv":655.49,"id":2257317},{"batb":[[1,2.96,21],[2,2.84,11.33]],"batl":[[0,3.35,17.64]],"ltp":2.72,"tv":25.2,"id":10303696}]}]}
{"op":"mcm","clk":"1005763844","pt":1580644522215,"mc":[{"id":"1.168224297","rc":[{"trd":[[1.43,389.85]],"batb":[[1,1.39,316.71]],"batl":[[0,1.43,88.99]],"ltp":1.43,"tv":850.41,"id":2257317},{"batl":[[0,3.4,16.8],[1,4.6,136.05]],"ltp":2.72,"tv":25.2,"id":10303696}],"tv":875.62}]}
{"op":"mcm","clk":"1005764360","pt":1580644526341,"mc":[{"id":"1.168224297","rc":[{"batb":[[1,1.26,84.82],[2,1.01,15.51]],"batl":[[0,1.51,42.01],[1,1.82,469.11],[2,1.51,0]],"ltp":1.43,"tv":850.41,"id":2257317},{"batb":[[0,2.96,21],[1,2.84,11.33],[2,1.01,15.52]],"ltp":2.72,"tv":25.2,"id":10303696}]}]}
{"op":"mcm","clk":"1005764542","pt":1580644527821,"mc":[{"id":"1.168224297","rc":[{"batb":[[0,1.26,84.82],[1,1.01,15.51],[2,1.01,0]],"batl":[[0,1.82,469.11],[1,1.82,0]],"ltp":1.43,"tv":850.41,"id":2257317},{"batb":[[0,2.84,11.33],[1,1.01,15.52],[2,1.01,0]],"batl":[[0,4.6,136.05],[1,4.6,0]],"ltp":2.72,"tv":25.2,"id":10303696}]}]}
{"op":"mcm","clk":"1005764650","pt":1580644528853,"mc":[{"id":"1.168224297","rc":[{"batb":[[0,1.26,598.95],[1,1.25,434.33],[2,1.01,15.51]],"batl":[[0,1.55,231.69],[1,1.56,148.03],[2,1.82,469.11]],"ltp":1.43,"tv":850.41,"id":2257317}]}]}
{"op":"mcm","clk":"1005764818","pt":1580644530322,"mc":[{"id":"1.168224297","rc":[{"batb":[[0,1.26,84.82],[1,1.01,15.51],[2,1.01,0]],"batl":[[0,1.82,469.11],[1,1.56,0],[2,1.82,0]],"ltp":1.43,"tv":850.41,"id":2257317}]}]}
{"op":"mcm","clk":"1005765407","pt":1580644535335,"mc":[{"id":"1.168224297","rc":[{"batb":[[0,1.26,598.95],[1,1.25,434.33],[2,1.01,15.51]],"batl":[[0,1.55,231.69],[1,1.56,148.03],[2,1.82,469.11]],"ltp":1.43,"tv":850.41,"id":2257317}]}]}
{"op":"mcm","clk":"1005766017","pt":1580644540272,"mc":[{"id":"1.168224297","rc":[{"batb":[[0,1.26,84.82],[1,1.01,15.51],[2,1.01,0]],"ltp":1.43,"tv":850.41,"id":2257317}]}]}
{"op":"mcm","clk":"1005766405","pt":1580644543350,"mc":[{"id":"1.168224297","rc":[{"batb":[[0,1.5,129.54],[1,1.49,180],[2,1.26,84.82]],"ltp":1.43,"tv":850.41,"id":2257317}]}]}
{"op":"mcm","clk":"1005766492","pt":1580644544035,"mc":[{"id":"1.168224297","rc":[{"batb":[[1,1.49,218.71],[2,1.34,61.61]],"ltp":1.43,"tv":850.41,"id":2257317},{"batb":[[1,2.48,16.13],[2,1.01,15.52]],"ltp":2.72,"tv":25.2,"id":10303696}]}]}
{"op":"mcm","clk":"1005766585","pt":1580644544868,"mc":[{"id":"1.168224297","rc":[{"batb":[[0,1.5,213.56]],"ltp":1.43,"tv":850.41,"id":2257317},{"batl":[[0,3,21]],"ltp":2.72,"tv":25.2,"id":10303696}]}]}
{"op":"mcm","clk":"1005766665","pt":1580644545452,"mc":[{"id":"1.168224297","rc":[{"batl":[[1,3.9,158.24]],"ltp":2.72,"tv":25.2,"id":10303696}]}]}
{"op":"mcm","clk":"1005766852","pt":1580644547178,"mc":[{"id":"1.168224297","rc":[{"batl":[[0,1.55,258.39]],"ltp":1.43,"tv":850.41,"id":2257317}]}]}
{"op":"mcm","clk":"1005768155","pt":1580644557375,"mc":[{"id":"1.168224297","rc":[{"batb":[[0,1.5,84.02],[1,1.49,38.71]],"batl":[[0,1.82,469.11],[1,1.56,0],[2,1.82,0]],"ltp":1.43,"tv":850.41,"id":2257317}]}]}
{"op":"mcm","clk":"1005768218","pt":1580644557862,"mc":[{"id":"1.168224297","rc":[{"batb":[[0,1.34,61.61],[1,1.01,15.51],[2,1.34,0]],"ltp":1.43,"tv":850.41,"id":2257317},{"batb":[[0,2.48,16.13],[1,1.01,15.52],[2,1.01,0]],"batl":[[0,3.9,158.24],[1,3.9,0]],"ltp":2.72,"tv":25.2,"id":10303696}]}]}
{"op":"mcm","clk":"1005768509","pt":1580644560062,"mc":[{"id":"1.168224297","rc":[{"batb":[[0,1.34,353.75],[1,1.33,304.29],[2,1.01,15.51]],"batl":[[0,1.68,118.84],[1,1.7,219.89],[2,1.82,469.11]],"ltp":1.43,"tv":850.41,"id":2257317}]}]}
{"op":"mcm","clk":"1005768863","pt":1580644562512,"mc":[{"id":"1.168224297","rc":[{"batb":[[0,1.34,61.61],[1,1.01,15.51],[2,1.01,0]],"ltp":1.43,"tv":850.41,"id":2257317}]}]}
{"op":"mcm","clk":"1005769252","pt":1580644565326,"mc":[{"id":"1.168224297","rc":[{"batl":[[2,1.82,0]],"ltp":1.43,"tv":850.41,"id":2257317}]}]}
{"op":"mcm","clk":"1005769367","pt":1580644566321,"mc":[{"id":"1.168224297","rc":[{"batb":[[0,1.62,221.26],[1,1.61,162.17],[2,1.48,39.18]],"ltp":1.43,"tv":850.41,"id":2257317},{"batb":[[1,2.28,20.46],[2,1.01,15.52]],"ltp":2.72,"tv":25.2,"id":10303696}]}]}
{"op":"mcm","clk":"1005769437","pt":1580644566846,"mc":[{"id":"1.168224297","rc":[{"batb":[[2,1.6,69.74]],"ltp":1.43,"tv":850.41,"id":2257317},{"batl":[[0,2.66,25.21]],"ltp":2.72,"tv":25.2,"id":10303696}]}]}
{"op":"mcm","clk":"1005769597","pt":1580644568057,"mc":[{"id":"1.168224297","rc":[{"batl":[[2,2.16,342.82]],"ltp":1.43,"tv":850.41,"id":2257317},{"batl":[[1,3.3,191.92]],"ltp":2.72,"tv":25.2,"id":10303696}]}]}
{"op":"mcm","clk":"1005771914","pt":1580644584400,"mc":[{"id":"1.168224297","rc":[{"batb":[[0,1.48,39.18],[1,1.01,15.51],[2,1.6,0]],"batl":[[0,2.16,342.82],[1,1.7,0],[2,2.16,0]],"ltp":1.43,"tv":850.41,"id":2257317},{"batb":[[0,2.28,20.46],[1,1.01,15.52],[2,1.01,0]],"batl":[[0,3.3,191.92],[1,3.3,0]],"ltp":2.72,"tv":25.2,"id":10303696}]}]}
{"op":"mcm","clk":"1005772267","pt":1580644586658,"mc":[{"id":"1.168224297","rc":[{"batb":[[0,1.49,190.88],[1,1.48,224.64],[2,1.01,15.51]],"batl":[[0,1.8,179.96],[1,1.82,175.26],[2,2.16,342.82]],"ltp":1.43,"tv":850.41,"id":2257317}]}]}
{"op":"mcm","clk":"1005774221","pt":1580644601191,"mc":[{"id":"1.168224297","rc":[{"batl":[[0,2.16,342.82],[1,1.82,0],[2,2.16,0]],"ltp":1.43,"tv":850.41,"id":2257317}]}]}
{"op":"mcm","clk":"1005774638","pt":1580644604313,"mc":[{"id":"1.168224297","rc":[{"batl":[[0,1.54,218.78],[1,1.55,151.88]],"ltp":1.43,"tv":850.41,"id":2257317}]}]}
{"op":"mcm","clk":"1005774766","pt":1580644605099,"mc":[{"id":"1.168224297","rc":[{"batb":[[0,1.5,84.02],[1,1.49,190.88],[2,1.48,224.64]],"ltp":1.43,"tv":850.41,"id":2257317},{"batb":[[0,2.86,11.17],[1,2.5,16.05],[2,1.01,15.52]],"batl":[[0,3,21]],"ltp":2.72,"tv":25.2,"id":10303696}]}]}
{"op":"mcm","clk":"1005775033","pt":1580644607098,"mc":[{"id":"1.168224297","rc":[{"batl":[[2,1.95,409.86]],"ltp":1.43,"tv":850.41,"id":2257317},{"batl":[[1,3.9,158.24]],"ltp":2.72,"tv":25.2,"id":10303696}]}]}
{"op":"mcm","clk":"1005776260","pt":1580644616337,"mc":[{"id":"1.168224297","rc":[{"batb":[[0,1.33,62.79],[1,1.01,15.51],[2,1.48,0]],"batl":[[0,1.95,409.86],[1,1.55,0],[2,1.95,0]],"ltp":1.43,"tv":850.41,"id":2257317},{"batb":[[0,2.5,16.05],[1,1.01,15.52],[2,1.01,0]],"batl":[[0,3.9,158.24],[1,3.9,0]],"ltp":2.72,"tv":25.2,"id":10303696}]}]}
{"op":"mcm","clk":"1005776568","pt":1580644618815,"mc":[{"id":"1.168224297","rc":[{"batb":[[0,1.34,156.07],[1,1.33,365.15],[2,1.01,15.51]],"batl":[[0,1.68,212.59],[1,1.7,219.38],[2,1.95,409.86]],"ltp":1.43,"tv":850.41,"id":2257317}]}]}
{"op":"mcm","clk":"1005776865","pt":1580644621311,"mc":[{"id":"1.168224297","rc":[{"batb":[[0,1.33,62.79],[1,1.01,15.51],[2,1.01,0]],"batl":[[0,1.95,409.86],[1,1.7,0],[2,1.95,0]],"ltp":1.43,"tv":850.41,"id":2257317}]}]}
{"op":"mcm","clk":"1005777258","pt":1580644624361,"mc":[{"id":"1.168224297","rc":[{"batb":[[0,1.45,332.74],[1,1.44,209.5],[2,1.33,62.79]],"batl":[[0,1.5,168.09],[1,1.51,168.36],[2,1.95,409.86]],"ltp":1.43,"tv":850.41,"id":2257317}]}]}
{"op":"mcm","clk":"1005777339","pt":1580644624927,"mc":[{"id":"1.168224297","rc":[{"batb":[[0,1.33,62.79],[1,1.01,15.51],[2,1.33,0]],"batl":[[0,1.95,409.86],[1,1.51,0],[2,1.95,0]],"ltp":1.43,"tv":850.41,"id":2257317}]}]}
{"op":"mcm","clk":"1005777427","pt":1580644625754,"mc":[{"id":"1.168224297","rc":[{"batb":[[0,1.34,156.07],[1,1.33,365.15],[2,1.01,15.51]],"batl":[[0,1.68,212.59],[1,1.7,219.38],[2,1.95,409.86]],"ltp":1.43,"tv":850.41,"id":2257317}]}]}
{"op":"mcm","clk":"1005778256","pt":1580644632847,"mc":[{"id":"1.168224297","rc":[{"batb":[[0,1.33,62.79],[1,1.01,15.51],[2,1.01,0]],"ltp":1.43,"tv":850.41,"id":2257317}]}]}
{"op":"mcm","clk":"1005778529","pt":1580644634975,"mc":[{"id":"1.168224297","rc":[{"batl":[[2,1.95,0]],"ltp":1.43,"tv":850.41,"id":2257317}]}]}
{"op":"mcm","clk":"1005778661","pt":1580644635943,"mc":[{"id":"1.168224297","rc":[{"batb":[[0,1.62,122.13],[1,1.61,133.03],[2,1.33,62.79]],"ltp":1.43,"tv":850.41,"id":2257317}]}]}
{"op":"mcm","clk":"1005778792","pt":1580644636825,"mc":[{"id":"1.168224297","rc":[{"batb":[[1,1.61,161.91],[2,1.6,69.74]],"ltp":1.43,"tv":850.41,"id":2257317},{"batb":[[1,2.3,20.22],[2,1.01,15.52]],"batl":[[0,2.68,24.37]],"ltp":2.72,"tv":25.2,"id":10303696}]}]}
{"op":"mcm","clk":"1005779105","pt":1580644639033,"mc":[{"id":"1.168224297","rc":[{"batl":[[2,2.16,342.82]],"ltp":1.43,"tv":850.41,"id":2257317},{"batl":[[1,3.3,191.92]],"ltp":2.72,"tv":25.2,"id":10303696}]}]}
{"op":"mcm","clk":"1005780923","pt":1580644653043,"mc":[{"id":"1.168224297","rc":[{"batb":[[0,1.61,28.88],[1,1.6,69.74],[2,1.48,39.5]],"batl":[[0,2.16,342.82],[1,1.7,0],[2,2.16,0]],"ltp":1.43,"tv":850.41,"id":2257317}]}]}
{"op":"mcm","clk":"1005781042","pt":1580644653830,"mc":[{"id":"1.168224297","rc":[{"batb":[[0,1.48,39.5],[1,1.01,15.51],[2,1.48,0]],"ltp":1.43,"tv":850.41,"id":2257317},{"batb":[[0,2.3,20.22],[1,1.01,15.52],[2,1.01,0]],"batl":[[0,3.3,191.92],[1,3.3,0]],"ltp":2.72,"tv":25.2,"id":10303696}]}]}
{"op":"mcm","clk":"1005781299","pt":1580644655931,"mc":[{"id":"1.168224297","rc":[{"batb":[[0,1.48,300.04],[1,1.47,191.25],[2,1.01,15.51]],"batl":[[0,1.79,168.63],[1,1.81,178.4],[2,2.16,342.82]],"ltp":1.43,"tv":850.41,"id":2257317}]}]}
{"op":"mcm","clk":"1005782047","pt":1580644661955,"mc":[{"id":"1.168224297","rc":[{"batl":[[0,2.16,342.82],[1,1.81,0],[2,2.16,0]],"ltp":1.43,"tv":850.41,"id":2257317}]}]}
{"op":"mcm","clk":"1005782479","pt":1580644665365,"mc":[{"id":"1.168224297","rc":[{"batb":[[0,1.5,84.02],[1,1.48,300.04],[2,1.47,191.25]],"batl":[[0,1.53,172.39],[1,1.54,155.91]],"ltp":1.43,"tv":850.41,"id":2257317},{"batb":[[0,2.88,11.02],[1,2.5,15.82],[2,1.01,15.52]],"batl":[[0,3,21]],"ltp":2.72,"tv":25.2,"id":10303696}]}]}
{"op":"mcm","clk":"1005782679","pt":1580644666777,"mc":[{"id":"1.168224297","rc":[{"batl":[[2,1.95,409.86]],"ltp":1.43,"tv":850.41,"id":2257317},{"batl":[[1,3.9,158.24]],"ltp":2.72,"tv":25.2,"id":10303696}]}]}
{"op":"mcm","clk":"1005782842","pt":1580644667876,"mc":[{"id":"1.168224297","rc":[{"batb":[[1,2.5,508.38]],"ltp":2.72,"tv":25.2,"id":10303696}]}]}
{"op":"mcm","clk":"1005783377","pt":1580644672380,"mc":[{"id":"1.168224297","rc":[{"batb":[[1,1.48,39.5],[2,1.33,63.34]],"batl":[[0,1.95,409.86],[1,1.54,0],[2,1.95,0]],"ltp":1.43,"tv":850.41,"id":2257317},{"batb":[[1,2.5,15.82]],"ltp":2.72,"tv":25.2,"id":10303696}]}]}
{"op":"mcm","clk":"1005783476","pt":1580644673209,"mc":[{"id":"1.168224297","rc":[{"batb":[[1,1.33,63.34],[2,1.01,15.51]],"ltp":1.43,"tv":850.41,"id":2257317},{"batb":[[0,2.5,15.82],[1,1.01,15.52],[2,1.01,0]],"ltp":2.72,"tv":25.2,"id":10303696}]}]}
{"op":"mcm","clk":"1005783564","pt":1580644673912,"mc":[{"id":"1.168224297","rc":[{"batb":[[0,1.33,63.34],[1,1.01,15.51],[2,1.01,0]],"ltp":1.43,"tv":850.41,"id":2257317},{"batl":[[0,3.9,158.24],[1,3.9,0]],"ltp":2.72,"tv":25.2,"id":10303696}]}]}
{"op":"mcm","clk":"1005783738","pt":1580644675213,"mc":[{"id":"1.168224297","rc":[{"batb":[[0,1.33,388.78],[1,1.32,316.83],[2,1.01,15.51]],"batl":[[0,1.67,190.96],[1,1.69,223.96],[2,1.95,409.86]],"ltp":1.43,"tv":850.41,"id":2257317}]}]}
{"op":"mcm","clk":"1005784905","pt":1580644684502,"mc":[{"id":"1.168224297","rc":[{"batl":[[0,1.95,409.86],[1,1.69,0],[2,1.95,0]],"ltp":1.43,"tv":850.41,"id":2257317}]}]}
{"op":"mcm","clk":"1005785399","pt":1580644688331,"mc":[{"id":"1.168224297","rc":[{"batb":[[2,1.17,139.66]],"batl":[[0,1.37,306.9],[1,1.38,245.26]],"ltp":1.43,"tv":850.41,"id":2257317},{"batb":[[0,3.65,15.19],[1,2.88,11.09],[2,2.5,15.82]],"ltp":2.72,"tv":25.2,"id":10303696}]}]}
{"op":"mcm","clk":"1005785523","pt":1580644689218,"mc":[{"id":"1.168224297","rc":[{"batb":[[2,1.01,15.52]],"batl":[[0,3.75,15.12]],"ltp":2.72,"tv":25.2,"id":10303696}]}]}
{"op":"mcm","clk":"1005785610","pt":1580644689931,"mc":[{"id":"1.168224297","rc":[{"batl":[[2,1.73,527.57]],"ltp":1.43,"tv":850.41,"id":2257317},{"batl":[[1,5.3,118.79]],"ltp":2.72,"tv":25.2,"id":10303696}]}]}
{"op":"mcm","clk":"1005785820","pt":1580644691135,"mc":[{"id":"1.168224297","rc":[{"trd":[[1.37,67.22]],"batb":[[0,1.36,115.95],[1,1.33,388.78],[2,1.32,316.83]],"batl":[[0,1.37,273.29]],"ltp":1.37,"tv":917.63,"id":2257317}],"tv":942.84}]}
{"op":"mcm","clk":"1005786263","pt":1580644694311,"mc":[{"id":"1.168224297","rc":[{"trd":[[1.37,268.86]],"batl":[[0,1.37,172.47]],"ltp":1.37,"tv":1119.27,"id":2257317}],"tv":1144.48}]}
{"op":"mcm","clk":"1005786384","pt":1580644695217,"mc":[{"id":"1.168224297","rc":[{"batb":[[1,1.33,63.34],[2,1.17,139.66]],"batl":[[0,1.73,527.57],[1,1.38,0],[2,1.73,0]],"ltp":1.37,"tv":1119.27,"id":2257317}]}]}
{"op":"mcm","clk":"1005786491","pt":1580644695944,"mc":[{"id":"1.168224297","rc":[{"batb":[[0,1.17,139.66],[1,1.01,15.51],[2,1.17,0]],"ltp":1.37,"tv":1119.27,"id":2257317},{"batb":[[0,2.88,11.09],[1,1.01,15.52],[2,1.01,0]],"batl":[[0,5.3,118.79],[1,5.3,0]],"ltp":2.72,"tv":25.2,"id":10303696}]}]}
{"op":"mcm","clk":"1005786767","pt":1580644698029,"mc":[{"id":"1.168224297","rc":[{"batb":[[0,1.17,617.51],[1,1.16,633.86],[2,1.01,15.51]],"batl":[[0,1.53,222.29],[1,1.54,155.31],[2,1.73,527.57]],"ltp":1.37,"tv":1119.27,"id":2257317}]}]}
{"op":"mcm","clk":"1005787160","pt":1580644700860,"mc":[{"id":"1.168224297","rc":[{"batb":[[0,1.17,139.66],[1,1.01,15.51],[2,1.01,0]],"ltp":1.37,"tv":1119.27,"id":2257317}]}]}
{"op":"mcm","clk":"1005787403","pt":1580644702751,"mc":[{"id":"1.168224297","rc":[{"batl":[[2,1.73,0]],"ltp":1.37,"tv":1119.27,"id":2257317}]}]}
{"op":"mcm","clk":"1005787631","pt":1580644704338,"mc":[{"id":"1.168224297","rc":[{"batb":[[0,1.48,245],[1,1.47,190.5],[2,1.33,63.81]],"ltp":1.37,"tv":1119.27,"id":2257317},{"batb":[[1,2.5,16.05],[2,1.01,15.52]],"ltp":2.72,"tv":25.2,"id":10303696}]}]}
{"op":"mcm","clk":"1005787702","pt":1580644704954,"mc":[{"id":"1.168224297","rc":[{"batb":[[0,1.48,332.38]],"ltp":1.37,"tv":1119.27,"id":2257317},{"batl":[[0,3.05,20.16]],"ltp":2.72,"tv":25.2,"id":10303696}]}]}
{"op":"mcm","clk":"1005787818","pt":1580644705965,"mc":[{"id":"1.168224297","rc":[{"batl":[[2,1.95,409.86]],"ltp":1.37,"tv":1119.27,"id":2257317},{"batl":[[1,3.9,158.24]],"ltp":2.72,"tv":25.2,"id":10303696}]}]}
{"op":"mcm","clk":"1005789015","pt":1580644716177,"mc":[{"id":"1.168224297","rc":[{"batb":[[0,1.48,126.88],[1,1.33,63.81],[2,1.01,15.51]],"batl":[[0,1.95,409.86],[1,1.54,0],[2,1.95,0]],"ltp":1.37,"tv":1119.27,"id":2257317}]}]}
{"op":"mcm","clk":"1005789111","pt":1580644717068,"mc":[{"id":"1.168224297","rc":[{"batb":[[0,1.48,87.38]],"ltp":1.37,"tv":1119.27,"id":2257317},{"batb":[[0,2.5,16.05],[1,1.01,15.52],[2,1.01,0]],"ltp":2.72,"tv":25.2,"id":10303696}]}]}
{"op":"mcm","clk":"1005789222","pt":1580644718107,"mc":[{"id":"1.168224297","rc":[{"batb":[[0,1.33,63.81],[1,1.01,15.51],[2,1.01,0]],"ltp":1.37,"tv":1119.27,"id":2257317},{"batl":[[0,3.9,158.24],[1,3.9,0]],"ltp":2.72,"tv":25.2,"id":10303696}]}]}
{"op":"mcm","clk":"1005789339","pt":1580644719195,"mc":[{"id":"1.168224297","rc":[{"batb":[[0,1.33,324.77],[1,1.32,315.14],[2,1.01,15.51]],"batl":[[0,1.67,229.56],[1,1.69,223.33],[2,1.95,409.86]],"ltp":1.37,"tv":1119.27,"id":2257317}]}]}
{"op":"mcm","clk":"1005789576","pt":1580644721291,"mc":[{"id":"1.168224297","rc":[{"batb":[[0,1.33,63.81],[1,1.01,15.51],[2,1.01,0]],"batl":[[0,1.95,409.86],[1,1.69,0],[2,1.95,0]],"ltp":1.37,"tv":1119.27,"id":2257317}]}]}
{"op":"mcm","clk":"1005789931","pt":1580644724311,"mc":[{"id":"1.168224297","rc":[{"batb":[[0,1.45,157.3],[1,1.44,207.69],[2,1.33,63.81]],"batl":[[0,1.49,158.12],[1,1.5,172.53],[2,1.95,409.86]],"ltp":1.37,"tv":1119.27,"id":2257317}]}]}
{"op":"mcm","clk":"1005790027","pt":1580644725202,"mc":[{"id":"1.168224297","rc":[{"batb":[[0,1.33,63.81],[1,1.01,15.51],[2,1.33,0]],"batl":[[0,1.95,409.86],[1,1.5,0],[2,1.95,0]],"ltp":1.37,"tv":1119.27,"id":2257317}]}]}
{"op":"mcm","clk":"1005790392","pt":1580644728184,"mc":[{"id":"1.168224297","rc":[{"batb":[[0,1.33,324.77],[1,1.32,315.14],[2,1.01,15.51]],"batl":[[0,1.67,229.56],[1,1.69,223.33],[2,1.95,409.86]],"ltp":1.37,"tv":1119.27,"id":2257317}]}]}
{"op":"mcm","clk":"1005790708","pt":1580644730938,"mc":[{"id":"1.168224297","rc":[{"batb":[[0,1.33,63.81],[1,1.01,15.51],[2,1.01,0]],"ltp":1.37,"tv":1119.27,"id":2257317}]}]}
{"op":"mcm","clk":"1005790992","pt":1580644733405,"mc":[{"id":"1.168224297","rc":[{"batb":[[0,1.6,253.45],[1,1.59,139.62],[2,1.33,63.81]],"ltp":1.37,"tv":1119.27,"id":2257317}]}]}
{"op":"mcm","clk":"1005791071","pt":1580644734187,"mc":[{"id":"1.168224297","rc":[{"batb":[[0,1.61,28.88],[1,1.6,253.45],[2,1.59,139.62]],"ltp":1.37,"tv":1119.27,"id":2257317},{"batb":[[1,2.3,19.91],[2,1.01,15.52]],"ltp":2.72,"tv":25.2,"id":10303696}]}]}
{"op":"mcm","clk":"1005791143","pt":1580644734921,"mc":[{"id":"1.168224297","rc":[{"batl":[[0,2.74,23.53]],"ltp":2.72,"tv":25.2,"id":10303696}]}]}
{"op":"mcm","clk":"1005791301","pt":1580644736230,"mc":[{"id":"1.168224297","rc":[{"batl":[[1,3.45,180.4]],"ltp":2.72,"tv":25.2,"id":10303696}]}]}
{"op":"mcm","clk":"1005791927","pt":1580644741266,"mc":[{"id":"1.168224297","rc":[{"batb":[[0,1.58,72.26],[1,1.48,39.97],[2,1.01,15.51]],"batl":[[0,1.95,409.86],[1,1.69,0],[2,1.95,0]],"ltp":1.37,"tv":1119.27,"id":2257317},{"batb":[[0,2.3,19.91],[1,1.01,15.52],[2,1.01,0]],"ltp":2.72,"tv":25.2,"id":10303696}]}]}
{"op":"mcm","clk":"1005792099","pt":1580644742031,"mc":[{"id":"1.168224297","rc":[{"batb":[[0,1.48,39.97],[1,1.01,15.51],[2,1.01,0]],"ltp":1.37,"tv":1119.27,"id":2257317},{"batl":[[0,3.45,180.4],[1,3.45,0]],"ltp":2.72,"tv":25.2,"id":10303696}]}]}
{"op":"mcm","clk":"1005792436","pt":1580644744331,"mc":[{"id":"1.168224297","rc":[{"batb":[[1,1.47,285.91],[2,1.46,196.63]],"batl":[[0,1.78,182.93],[1,1.8,181.28],[2,1.95,409.86]],"ltp":1.37,"tv":1119.27,"id":2257317}]}]}
{"op":"mcm","clk":"1005793565","pt":1580644753060,"mc":[{"id":"1.168224297","rc":[{"batl":[[0,1.95,409.86],[1,1.8,0],[2,1.95,0]],"ltp":1.37,"tv":1119.27,"id":2257317}]}]}
{"op":"mcm","clk":"1005793945","pt":1580644756126,"mc":[{"id":"1.168224297","rc":[{"batl":[[0,1.52,166.83],[1,1.53,159.56],[2,1.95,409.86]],"ltp":1.37,"tv":1119.27,"id":2257317}]}]}
{"op":"mcm","clk":"1005794061","pt":1580644756973,"mc":[{"id":"1.168224297","rc":[{"batb":[[0,1.48,127.35]],"ltp":1.37,"tv":1119.27,"id":2257317},{"batb":[[0,2.9,10.86],[1,2.5,15.74],[2,1.01,15.52]],"batl":[[0,3.05,20.16]],"ltp":2.72,"tv":25.2,"id":10303696}]}]}
{"op":"mcm","clk":"1005794360","pt":1580644759380,"mc":[{"id":"1.168224297","rc":[{"batl":[[1,4.2,148.03]],"ltp":2.72,"tv":25.2,"id":10303696}]}]}
{"op":"mcm","clk":"1005795569","pt":1580644769245,"mc":[{"id":"1.168224297","rc":[{"batb":[[0,1.48,87.38],[1,1.33,63.42],[2,1.01,15.51]],"batl":[[0,1.95,409.86],[1,1.53,0],[2,1.95,0]],"ltp":1.37,"tv":1119.27,"id":2257317},{"batb":[[0,2.5,15.74],[1,1.01,15.52],[2,1.01,0]],"ltp":2.72,"tv":25.2,"id":10303696}]}]}
{"op":"mcm","clk":"1005795670","pt":1580644770086,"mc":[{"id":"1.168224297","rc":[{"batb":[[0,1.33,63.42],[1,1.01,15.51],[2,1.01,0]],"ltp":1.37,"tv":1119.27,"id":2257317},{"batl":[[0,4.2,148.03],[1,4.2,0]],"ltp":2.72,"tv":25.2,"id":10303696}]}]}
{"op":"mcm","clk":"1005795829","pt":1580644771456,"mc":[{"id":"1.168224297","rc":[{"batb":[[1,1.32,449.55],[2,1.31,330.9]],"batl":[[0,1.66,201.45],[1,1.68,228.08],[2,1.95,409.86]],"ltp":1.37,"tv":1119.27,"id":2257317}]}]}
{"op":"mcm","clk":"1005796006","pt":1580644772981,"mc":[{"id":"1.168224297","rc":[{"batb":[[1,1.01,15.51],[2,1.31,0]],"batl":[[0,1.95,409.86],[1,1.68,0],[2,1.95,0]],"ltp":1.37,"tv":1119.27,"id":2257317}]}]}
{"op":"mcm","clk":"1005796428","pt":1580644776168,"mc":[{"id":"1.168224297","rc":[{"batb":[[0,1.44,252.31],[1,1.43,214.88],[2,1.33,63.42]],"batl":[[0,1.49,263.91],[1,1.5,171.79],[2,1.95,409.86]],"ltp":1.37,"tv":1119.27,"id":2257317}]}]}
{"op":"mcm","clk":"1005796670","pt":1580644778264,"mc":[{"id":"1.168224297","rc":[{"batb":[[0,1.33,63.42],[1,1.01,15.51],[2,1.33,0]],"batl":[[0,1.95,409.86],[1,1.5,0],[2,1.95,0]],"ltp":1.37,"tv":1119.27,"id":2257317}]}]}
{"op":"mcm","clk":"1005796945","pt":1580644780383,"mc":[{"id":"1.168224297","rc":[{"batb":[[1,1.32,449.55],[2,1.31,330.9]],"batl":[[0,1.66,201.45],[1,1.68,228.08],[2,1.95,409.86]],"ltp":1.37,"tv":1119.27,"id":2257317}]}]}
{"op":"mcm","clk":"1005797788","pt":1580644786602,"mc":[{"id":"1.168224297","rc":[{"batl":[[0,1.95,409.86],[1,1.68,0],[2,1.95,0]],"ltp":1.37,"tv":1119.27,"id":2257317}]}]}
{"op":"mcm","clk":"1005798302","pt":1580644790395,"mc":[{"id":"1.168224297","rc":[{"batl":[[0,1.36,226.74],[1,1.37,254.02]],"ltp":1.37,"tv":1119.27,"id":2257317},{"batb":[[0,3.65,15.11],[1,2.88,11.09],[2,2.5,15.74]],"ltp":2.72,"tv":25.2,"id":10303696}]}]}
{"op":"mcm","clk":"1005798424","pt":1580644791289,"mc":[{"id":"1.168224297","rc":[{"batb":[[0,1.35,119.31],[1,1.33,63.42],[2,1.32,449.55]],"ltp":1.37,"tv":1119.27,"id":2257317},{"batb":[[2,1.01,15.52]],"batl":[[0,3.8,14.28]],"ltp":2.72,"tv":25.2,"id":10303696}]}]}
{"op":"mcm","clk":"1005798584","pt":1580644792391,"mc":[{"id":"1.168224297","rc":[{"batl":[[2,1.71,542.06]],"ltp":1.37,"tv":1119.27,"id":2257317},{"batl":[[0,5.5,115.06]],"ltp":2.72,"tv":25.2,"id":10303696}]}]}
{"op":"mcm","clk":"1005798689","pt":1580644793334,"mc":[{"id":"1.168224297","rc":[{"trd":[[1.36,231.9]],"batb":[[2,1.32,313.25]],"batl":[[0,1.36,110.79]],"ltp":1.36,"tv":1351.17,"id":2257317},{"batl":[[0,3.9,14.28],[1,5.5,115.06]],"ltp":2.72,"tv":25.2,"id":10303696}],"tv":1376.38}]}
{"op":"mcm","clk":"1005799128","pt":1580644796320,"mc":[{"id":"1.168224297","rc":[{"batb":[[0,1.33,178.72],[1,1.17,138.72],[2,1.01,15.51]],"batl":[[0,1.36,73.44],[1,1.71,542.06],[2,1.71,0]],"ltp":1.36,"tv":1351.17,"id":2257317},{"batb":[[0,2.88,11.09],[1,1.01,15.52],[2,1.01,0]],"batl":[[0,5.5,115.06],[1,5.5,0]],"ltp":2.72,"tv":25.2,"id":10303696}]}]}
{"op":"mcm","clk":"1005799257","pt":1580644797114,"mc":[{"id":"1.168224297","rc":[{"batb":[[0,1.17,138.72],[1,1.01,15.51],[2,1.01,0]],"batl":[[0,1.71,542.06],[1,1.71,0]],"ltp":1.36,"tv":1351.17,"id":2257317}]}]}
{"op":"mcm","clk":"1005799439","pt":1580644798526,"mc":[{"id":"1.168224297","rc":[{"batb":[[0,1.17,416.92],[1,1.16,724.99],[2,1.01,15.51]],"batl":[[0,1.52,217.5],[1,1.53,158.97],[2,1.71,542.06]],"ltp":1.36,"tv":1351.17,"id":2257317}]}]}
{"op":"mcm","clk":"1005800157","pt":1580644803229,"mc":[{"id":"1.168224297","rc":[{"batb":[[0,1.17,138.72],[1,1.01,15.51],[2,1.01,0]],"batl":[[0,1.71,542.06],[1,1.53,0],[2,1.71,0]],"ltp":1.36,"tv":1351.17,"id":2257317}]}]}
{"op":"mcm","clk":"1005801141","pt":1580644808580,"mc":[{"id":"1.168224297","rc":[{"batb":[[0,1.17,416.92],[1,1.16,724.99],[2,1.01,15.51]],"batl":[[0,1.52,217.5],[1,1.53,158.97],[2,1.71,542.06]],"ltp":1.36,"tv":1351.17,"id":2257317}]}]}
{"op":"mcm","clk":"1005804940","pt":1580644835266,"mc":[{"id":"1.168224297","rc":[{"batl":[[0,1.71,542.06],[1,1.53,0],[2,1.71,0]],"ltp":1.36,"tv":1351.17,"id":2257317}]}]}
{"op":"mcm","clk":"1005805320","pt":1580644838161,"mc":[{"id":"1.168224297","rc":[{"batl":[[0,1.19,402.92],[1,1.2,528.01]],"ltp":1.36,"tv":1351.17,"id":2257317}]}]}
{"op":"mcm","clk":"1005805463","pt":1580644839221,"mc":[{"id":"1.168224297","rc":[{"batb":[[2,1.14,170.82]],"ltp":1.36,"tv":1351.17,"id":2257317},{"batb":[[0,5.9,19.75],[1,4.7,16.37],[2,1.01,15.52]],"ltp":2.72,"tv":25.2,"id":10303696}]}]}
{"op":"mcm","clk":"1005805536","pt":1580644839953,"mc":[{"id":"1.168224297","rc":[{"batl":[[2,1.49,761.67]],"ltp":1.36,"tv":1351.17,"id":2257317},{"batl":[[0,9.8,75.27]],"ltp":2.72,"tv":25.2,"id":10303696}]}]}
{"op":"mcm","clk":"1005805754","pt":1580644841223,"mc":[{"id":"1.168224297","rc":[{"trd":[[1.19,396.58]],"batl":[[0,1.19,204.63]],"ltp":1.19,"tv":1747.75,"id":2257317},{"batl":[[0,6.4,7.56],[1,9.8,75.27]],"ltp":2.72,"tv":25.2,"id":10303696}],"tv":1772.95}]}
{"op":"mcm","clk":"1005806298","pt":1580644845166,"mc":[{"id":"1.168224297","rc":[{"trd":[[1.19,804.91]],"batb":[[0,1.18,168.04],[1,1.17,490.96],[2,1.16,683.65]],"batl":[[0,1.19,126.04]],"ltp":1.19,"tv":2156.08,"id":2257317}],"tv":2181.29}]}
{"op":"mcm","clk":"1005806724","pt":1580644848075,"mc":[{"id":"1.168224297","rc":[{"batb":[[1,1.17,567.21]],"batl":[[0,1.19,255.34]],"ltp":1.19,"tv":2156.08,"id":2257317}]}]}
{"op":"mcm","clk":"1005810570","pt":1580644875135,"mc":[{"id":"1.168224297","rc":[{"batb":[[1,1.17,138.72],[2,1.14,170.82]],"batl":[[0,1.49,761.67],[1,1.2,0],[2,1.49,0]],"ltp":1.19,"tv":2156.08,"id":2257317}]}]}
{"op":"mcm","clk":"1005810953","pt":1580644877932,"mc":[{"id":"1.168224297","rc":[{"batb":[[2,1.14,873.43]],"batl":[[0,1.26,483.69],[1,1.27,365.35],[2,1.49,761.67]],"ltp":1.19,"tv":2156.08,"id":2257317}]}]}
{"op":"mcm","clk":"1005811241","pt":1580644880184,"mc":[{"id":"1.168224297","rc":[{"trd":[[1.18,100]],"batb":[[0,1.18,118.04]],"ltp":1.18,"tv":2256.08,"id":2257317}],"tv":2281.29}]}
{"op":"mcm","clk":"1005811447","pt":1580644881623,"mc":[{"id":"1.168224297","rc":[{"batb":[[0,6,225.56],[1,5.9,19.75],[2,4.7,16.37]],"ltp":2.72,"tv":25.2,"id":10303696}]}]}
{"op":"mcm","clk":"1005811653","pt":1580644883033,"mc":[{"id":"1.168224297","rc":[{"batb":[[0,1.18,167.61]],"ltp":1.18,"tv":2256.08,"id":2257317}]}]}
{"op":"mcm","clk":"1005812667","pt":1580644890342,"mc":[{"id":"1.168224297","rc":[{"batb":[[0,1.14,873.43],[1,1.13,436.63],[2,1.01,15.51]],"ltp":1.18,"tv":2256.08,"id":2257317},{"batb":[[0,4.7,16.37],[1,1.01,15.52],[2,4.7,0]],"batl":[[0,9.8,75.27],[1,9.8,0]],"ltp":2.72,"tv":25.2,"id":10303696}]}]}
{"op":"mcm","clk":"1005814385","pt":1580644901189,"mc":[{"id":"1.168224297","rc":[{"batb":[[0,1.14,170.82],[1,1.01,15.51],[2,1.01,0]],"ltp":1.18,"tv":2256.08,"id":2257317}]}]}
{"op":"mcm","clk":"1005814856","pt":1580644904190,"mc":[{"id":"1.168224297","rc":[{"batb":[[0,1.23,263.44],[1,1.22,494.6],[2,1.14,170.82]],"ltp":1.18,"tv":2256.08,"id":2257317}]}]}
{"op":"mcm","clk":"1005814976","pt":1580644904985,"mc":[{"id":"1.168224297","rc":[{"batb":[[0,1.23,530.07],[2,1.18,126.91]],"ltp":1.18,"tv":2256.08,"id":2257317},{"batb":[[1,3.7,14.63],[2,1.01,15.52]],"batl":[[0,5.3,9.24]],"ltp":2.72,"tv":25.2,"id":10303696}]}]}
{"op":"mcm","clk":"1005815273","pt":1580644906987,"mc":[{"id":"1.168224297","rc":[{"batl":[[1,7.2,92.18]],"ltp":2.72,"tv":25.2,"id":10303696}]}]}
{"op":"mcm","clk":"1005815971","pt":1580644911300,"mc":[{"id":"1.168224297","rc":[{"batb":[[0,1.23,168.04],[1,1.18,126.91],[2,1.01,15.51]],"batl":[[0,1.49,761.67],[1,1.27,0],[2,1.49,0]],"ltp":1.18,"tv":2256.08,"id":2257317},{"batb":[[0,3.7,14.63],[1,1.01,15.52],[2,1.01,0]],"ltp":2.72,"tv":25.2,"id":10303696}]}]}
{"op":"mcm","clk":"1005816132","pt":1580644912103,"mc":[{"id":"1.168224297","rc":[{"batb":[[0,1.18,126.91],[1,1.01,15.51],[2,1.01,0]],"ltp":1.18,"tv":2256.08,"id":2257317},{"batl":[[0,7.2,92.18],[1,7.2,0]],"ltp":2.72,"tv":25.2,"id":10303696}]}]}
{"op":"mcm","clk":"1005816486","pt":1580644913917,"mc":[{"id":"1.168224297","rc":[{"batb":[[0,1.18,773.02],[1,1.17,454.66],[2,1.01,15.51]],"batl":[[0,1.36,282.78],[1,1.37,250.93],[2,1.49,761.67]],"ltp":1.18,"tv":2256.08,"id":2257317}]}]}
{"op":"mcm","clk":"1005817075","pt":1580644917019,"mc":[{"id":"1.168224297","rc":[{"batb":[[0,1.18,126.91],[1,1.01,15.51],[2,1.01,0]],"batl":[[0,1.49,761.67],[1,1.37,0],[2,1.49,0]],"ltp":1.18,"tv":2256.08,"id":2257317}]}]}
{"op":"mcm","clk":"1005817594","pt":1580644920216,"mc":[{"id":"1.168224297","rc":[{"batb":[[0,1.25,159.33],[1,1.24,442.99],[2,1.18,126.91]],"batl":[[0,1.28,477.07],[1,1.29,335.33],[2,1.49,761.67]],"ltp":1.18,"tv":2256.08,"id":2257317}]}]}
{"op":"mcm","clk":"1005817754","pt":1580644921029,"mc":[{"id":"1.168224297","rc":[{"batb":[[0,1.18,126.91],[1,1.01,15.51],[2,1.18,0]],"batl":[[0,1.49,761.67],[1,1.29,0],[2,1.49,0]],"ltp":1.18,"tv":2256.08,"id":2257317}]}]}
{"op":"mcm","clk":"1005818049","pt":1580644922519,"mc":[{"id":"1.168224297","rc":[{"batl":[[0,6.6,98.95]],"ltp":2.72,"tv":25.2,"id":10303696}]}]}
{"op":"mcm","clk":"1005818315","pt":1580644924012,"mc":[{"id":"1.168224297","rc":[{"batb":[[0,1.18,773.02],[1,1.17,454.66],[2,1.01,15.51]],"batl":[[0,1.36,282.78],[1,1.37,250.93],[2,1.49,761.67]],"ltp":1.18,"tv":2256.08,"id":2257317}]}]}
{"op":"mcm","clk":"1005818966","pt":1580644928114,"mc":[{"id":"1.168224297","rc":[{"batb":[[0,1.18,126.91],[1,1.01,15.51],[2,1.01,0]],"ltp":1.18,"tv":2256.08,"id":2257317}]}]}
{"op":"mcm","clk":"1005819312","pt":1580644930110,"mc":[{"id":"1.168224297","rc":[{"batl":[[2,1.49,0]],"ltp":1.18,"tv":2256.08,"id":2257317}]}]}
{"op":"mcm","clk":"1005819490","pt":1580644931186,"mc":[{"id":"1.168224297","rc":[{"batb":[[0,1.32,377.52],[1,1.31,326.92],[2,1.18,126.91]],"ltp":1.18,"tv":2256.08,"id":2257317}]}]}
{"op":"mcm","clk":"1005819625","pt":1580644931929,"mc":[{"id":"1.168224297","rc":[{"batb":[[0,1.32,444.08],[2,1.25,87.1]],"ltp":1.18,"tv":2256.08,"id":2257317},{"batb":[[0,3.75,14.16],[1,2.96,25.65],[2,1.01,15.52]],"ltp":2.72,"tv":25.2,"id":10303696}]}]}
{"op":"mcm","clk":"1005819825","pt":1580644932993,"mc":[{"id":"1.168224297","rc":[{"batb":[[1,1.31,462.19]],"ltp":1.18,"tv":2256.08,"id":2257317},{"batl":[[0,4.2,12.6]],"ltp":2.72,"tv":25.2,"id":10303696}]}]}
{"op":"mcm","clk":"1005819950","pt":1580644933689,"mc":[{"id":"1.168224297","rc":[{"batl":[[2,1.71,542.06]],"ltp":1.18,"tv":2256.08,"id":2257317},{"batl":[[1,5.5,115.06]],"ltp":2.72,"tv":25.2,"id":10303696}]}]}
{"op":"mcm","clk":"1005820578","pt":1580644937138,"mc":[{"id":"1.168224297","rc":[{"batb":[[0,1.32,416.71]],"ltp":1.18,"tv":2256.08,"id":2257317}]}]}
{"op":"mcm","clk":"1005821109","pt":1580644940224,"mc":[{"id":"1.168224297","rc":[{"batl":[[0,1.36,309.37]],"ltp":1.18,"tv":2256.08,"id":2257317}]}]}
{"op":"mcm","clk":"1005821408","pt":1580644942021,"mc":[{"id":"1.168224297","rc":[{"batb":[[2,1.3,6.46]],"ltp":1.18,"tv":2256.08,"id":2257317}]}]}
{"op":"mcm","clk":"1005821531","pt":1580644942715,"mc":[{"id":"1.168224297","rc":[{"batb":[[2,1.25,87.1]],"ltp":1.18,"tv":2256.08,"id":2257317}]}]}
{"op":"mcm","clk":"1005821989","pt":1580644945308,"mc":[{"id":"1.168224297","rc":[{"batb":[[0,1.32,66.56],[1,1.31,135.27]],"batl":[[0,1.71,542.06],[1,1.37,0],[2,1.71,0]],"ltp":1.18,"tv":2256.08,"id":2257317}]}]}
{"op":"mcm","clk":"1005822100","pt":1580644946042,"mc":[{"id":"1.168224297","rc":[{"batb":[[0,1.25,87.1],[1,1.01,15.51],[2,1.25,0]],"ltp":1.18,"tv":2256.08,"id":2257317},{"batb":[[0,2.96,25.65],[1,1.01,15.52],[2,1.01,0]],"batl":[[0,5.5,115.06],[1,5.5,0]],"ltp":2.72,"tv":25.2,"id":10303696}]}]}
{"op":"mcm","clk":"1005822453","pt":1580644948216,"mc":[{"id":"1.168224297","rc":[{"batb":[[0,1.26,285.15],[1,1.25,512.24],[2,1.01,15.51]],"batl":[[0,1.5,132.67],[1,1.51,167.06],[2,1.71,542.06]],"ltp":1.18,"tv":2256.08,"id":2257317}]}]}
{"op":"mcm","clk":"1005822905","pt":1580644951021,"mc":[{"id":"1.168224297","rc":[{"batl":[[0,1.71,542.06],[1,1.51,0],[2,1.71,0]],"ltp":1.18,"tv":2256.08,"id":2257317}]}]}
{"op":"mcm","clk":"1005823434","pt":1580644954261,"mc":[{"id":"1.168224297","rc":[{"batl":[[0,1.29,318.46],[1,1.3,325.3]],"ltp":1.18,"tv":2256.08,"id":2257317}]}]}
{"op":"mcm","clk":"1005823583","pt":1580644955064,"mc":[{"id":"1.168224297","rc":[{"batb":[[0,1.26,446.47],[2,1.19,120.23]],"ltp":1.18,"tv":2256.08,"id":2257317},{"batb":[[0,4.4,19.59],[1,3.3,19.43],[2,1.01,15.52]],"batl":[[0,4.9,10.08]],"ltp":2.72,"tv":25.2,"id":10303696}]}]}
{"op":"mcm","clk":"1005823835","pt":1580644956658,"mc":[{"id":"1.168224297","rc":[{"batl":[[2,1.62,614.4]],"ltp":1.18,"tv":2256.08,"id":2257317},{"batl":[[1,6.6,98.95]],"ltp":2.72,"tv":25.2,"id":10303696}]}]}
{"op":"mcm","clk":"1005825312","pt":1580644965251,"mc":[{"id":"1.168224297","rc":[{"batb":[[0,1.26,161.32],[1,1.19,120.23],[2,1.01,15.51]],"batl":[[0,1.62,614.4],[1,1.3,0],[2,1.62,0]],"ltp":1.18,"tv":2256.08,"id":2257317},{"batb":[[0,3.3,19.43],[1,1.01,15.52],[2,1.01,0]],"ltp":2.72,"tv":25.2,"id":10303696}]}]}
{"op":"mcm","clk":"1005825442","pt":1580644966052,"mc":[{"id":"1.168224297","rc":[{"batb":[[0,1.19,120.23],[1,1.01,15.51],[2,1.01,0]],"ltp":1.18,"tv":2256.08,"id":2257317},{"batl":[[0,6.6,98.95],[1,6.6,0]],"ltp":2.72,"tv":25.2,"id":10303696}]}]}
{"op":"mcm","clk":"1005825699","pt":1580644967642,"mc":[{"id":"1.168224297","rc":[{"batb":[[0,1.2,265.53],[1,1.19,709.59],[2,1.01,15.51]],"batl":[[0,1.44,327.28],[1,1.45,195.26],[2,1.62,614.4]],"ltp":1.18,"tv":2256.08,"id":2257317}]}]}
{"op":"mcm","clk":"1005825987","pt":1580644969344,"mc":[{"id":"1.168224297","rc":[{"batl":[[0,1.26,115.25],[1,1.44,327.28],[2,1.45,195.26]],"ltp":1.18,"tv":2256.08,"id":2257317}]}]}
{"op":"mcm","clk":"1005826020","pt":1580644969558,"mc":[{"id":"1.168224297","rc":[{"batl":[[0,1.44,327.28],[1,1.45,195.26],[2,1.62,614.4]],"ltp":1.18,"tv":2256.08,"id":2257317}]}]}
{"op":"mcm","clk":"1005826317","pt":1580644971150,"mc":[{"id":"1.168224297","rc":[{"batb":[[0,1.19,120.23],[1,1.01,15.51],[2,1.01,0]],"batl":[[0,1.62,614.4],[1,1.45,0],[2,1.62,0]],"ltp":1.18,"tv":2256.08,"id":2257317}]}]}
{"op":"mcm","clk":"1005826896","pt":1580644974396,"mc":[{"id":"1.168224297","rc":[{"batb":[[0,1.28,441.44],[1,1.27,390.04],[2,1.19,120.23]],"batl":[[0,1.32,396.7],[1,1.33,288.09],[2,1.62,614.4]],"ltp":1.18,"tv":2256.08,"id":2257317}]}]}
{"op":"mcm","clk":"1005827029","pt":1580644975186,"mc":[{"id":"1.168224297","rc":[{"batb":[[0,1.19,120.23],[1,1.01,15.51],[2,1.19,0]],"batl":[[0,1.62,614.4],[1,1.33,0],[2,1.62,0]],"ltp":1.18,"tv":2256.08,"id":2257317}]}]}
{"op":"mcm","clk":"1005827383","pt":1580644977051,"mc":[{"id":"1.168224297","rc":[{"batl":[[0,6,106.18]],"ltp":2.72,"tv":25.2,"id":10303696}]}]}
{"op":"mcm","clk":"1005827543","pt":1580644978007,"mc":[{"id":"1.168224297","rc":[{"batb":[[0,1.2,265.53],[1,1.19,709.59],[2,1.01,15.51]],"batl":[[0,1.44,327.28],[1,1.45,195.26],[2,1.62,614.4]],"ltp":1.18,"tv":2256.08,"id":2257317}]}]}
{"op":"mcm","clk":"1005828800","pt":1580644984711,"mc":[{"id":"1.168224297","rc":[{"batb":[[0,1.19,120.23],[1,1.01,15.51],[2,1.01,0]],"ltp":1.18,"tv":2256.08,"id":2257317}]}]}
{"op":"mcm","clk":"1005829154","pt":1580644986714,"mc":[{"id":"1.168224297","rc":[{"batl":[[2,1.62,0]],"ltp":1.18,"tv":2256.08,"id":2257317}]}]}
{"op":"mcm","clk":"1005829422","pt":1580644988319,"mc":[{"id":"1.168224297","rc":[{"batb":[[0,1.39,372.73],[1,1.38,251.71],[2,1.3,71.29]],"ltp":1.18,"tv":2256.08,"id":2257317},{"batb":[[1,2.6,14.48],[2,1.01,15.52]],"ltp":2.72,"tv":25.2,"id":10303696}]}]}
{"op":"mcm","clk":"1005829558","pt":1580644989115,"mc":[{"id":"1.168224297","rc":[{"batb":[[2,1.37,113.43]],"ltp":1.18,"tv":2256.08,"id":2257317},{"batl":[[0,3.7,15.12]],"ltp":2.72,"tv":25.2,"id":10303696}]}]}
{"op":"mcm","clk":"1005829717","pt":1580644990088,"mc":[{"id":"1.168224297","rc":[{"batl":[[2,1.82,469.11]],"ltp":1.18,"tv":2256.08,"id":2257317},{"batl":[[1,4.6,136.05]],"ltp":2.72,"tv":25.2,"id":10303696}]}]}
{"op":"mcm","clk":"1005831319","pt":1580644999206,"mc":[{"id":"1.168224297","rc":[{"trd":[[1.39,50.42]],"batb":[[0,1.39,347.52]],"ltp":1.39,"tv":2306.5,"id":2257317}],"tv":2331.71}]}
{"op":"mcm","clk":"1005831692","pt":1580645001342,"mc":[{"id":"1.168224297","rc":[{"batb":[[0,1.39,52.48],[1,1.37,113.43],[2,1.3,71.29]],"batl":[[0,1.82,469.11],[1,1.45,0],[2,1.82,0]],"ltp":1.39,"tv":2306.5,"id":2257317}]}]}
{"op":"mcm","clk":"1005831815","pt":1580645002081,"mc":[{"id":"1.168224297","rc":[{"batb":[[0,1.3,71.29],[1,1.01,15.51],[2,1.3,0]],"ltp":1.39,"tv":2306.5,"id":2257317},{"batb":[[0,2.6,14.48],[1,1.01,15.52],[2,1.01,0]],"batl":[[0,4.6,136.05],[1,4.6,0]],"ltp":2.72,"tv":25.2,"id":10303696}]}]}
{"op":"mcm","clk":"1005831967","pt":1580645003042,"mc":[{"id":"1.168224297","rc":[{"batl":[[0,3.7,2.27],[1,4.6,136.05]],"ltp":2.72,"tv":25.2,"id":10303696}]}]}
{"op":"mcm","clk":"1005832169","pt":1580645004220,"mc":[{"id":"1.168224297","rc":[{"batb":[[0,1.31,263.1],[1,1.3,410.63],[2,1.01,15.51]],"batl":[[0,1.63,151.65],[1,1.64,122.78],[2,1.82,469.11]],"ltp":1.39,"tv":2306.5,"id":2257317},{"batl":[[0,4.6,136.05],[1,4.6,0]],"ltp":2.72,"tv":25.2,"id":10303696}]}]}
{"op":"mcm","clk":"1005834612","pt":1580645017251,"mc":[{"id":"1.168224297","rc":[{"batb":[[0,1.3,71.29],[1,1.01,15.51],[2,1.01,0]],"batl":[[0,1.82,469.11],[1,1.64,0],[2,1.82,0]],"ltp":1.39,"tv":2306.5,"id":2257317}]}]}
{"op":"mcm","clk":"1005835181","pt":1580645020219,"mc":[{"id":"1.168224297","rc":[{"batb":[[0,1.31,263.1],[1,1.3,410.63],[2,1.01,15.51]],"batl":[[0,1.34,157.49],[1,1.35,271.32]],"ltp":1.39,"tv":2306.5,"id":2257317}]}]}
{"op":"mcm","clk":"1005835307","pt":1580645021032,"mc":[{"id":"1.168224297","rc":[{"batb":[[1,1.3,550.1],[2,1.19,117.47]],"ltp":1.39,"tv":2306.5,"id":2257317},{"batb":[[0,3.9,13.06],[1,2.66,13.53],[2,1.01,15.52]],"batl":[[0,4.3,12.6]],"ltp":2.72,"tv":25.2,"id":10303696}]}]}
{"op":"mcm","clk":"1005835765","pt":1580645023458,"mc":[{"id":"1.168224297","rc":[{"batl":[[2,1.71,542.06]],"ltp":1.39,"tv":2306.5,"id":2257317},{"batl":[[1,5.5,115.06]],"ltp":2.72,"tv":25.2,"id":10303696}]}]}
{"op":"mcm","clk":"1005836083","pt":1580645025064,"mc":[{"id":"1.168224297","rc":[{"batb":[[0,1.3,210.76],[1,1.19,117.47],[2,1.01,15.51]],"batl":[[0,1.71,542.06],[1,1.35,0],[2,1.71,0]],"ltp":1.39,"tv":2306.5,"id":2257317}]}]}
{"op":"mcm","clk":"1005836316","pt":1580645026023,"mc":[{"id":"1.168224297","rc":[{"batb":[[0,1.19,117.47],[1,1.01,15.51],[2,1.01,0]],"ltp":1.39,"tv":2306.5,"id":2257317},{"batb":[[0,2.66,13.53],[1,1.01,15.52],[2,1.01,0]],"batl":[[0,5.5,115.06],[1,5.5,0]],"ltp":2.72,"tv":25.2,"id":10303696}]}]}
{"op":"mcm","clk":"1005836686","pt":1580645027960,"mc":[{"id":"1.168224297","rc":[{"batb":[[0,1.2,625.31],[1,1.19,574.6],[2,1.01,15.51]],"batl":[[0,1.62,200.31],[1,1.63,125.26],[2,1.71,542.06]],"ltp":1.39,"tv":2306.5,"id":2257317}]}]}
{"op":"mcm","clk":"1005837576","pt":1580645032364,"mc":[{"id":"1.168224297","rc":[{"batb":[[0,1.19,117.47],[1,1.01,15.51],[2,1.01,0]],"batl":[[0,1.71,542.06],[1,1.63,0],[2,1.71,0]],"ltp":1.39,"tv":2306.5,"id":2257317}]}]}
{"op":"mcm","clk":"1005838185","pt":1580645035255,"mc":[{"id":"1.168224297","rc":[{"batb":[[0,1.35,343.85],[1,1.34,290.84],[2,1.19,117.47]],"batl":[[0,1.39,213.84],[1,1.4,228.5],[2,1.71,542.06]],"ltp":1.39,"tv":2306.5,"id":2257317}]}]}
{"op":"mcm","clk":"1005838267","pt":1580645035574,"mc":[{"id":"1.168224297","rc":[{"batb":[[0,1.19,117.47],[1,1.01,15.51],[2,1.19,0]],"batl":[[0,1.71,542.06],[1,1.4,0],[2,1.71,0]],"ltp":1.39,"tv":2306.5,"id":2257317}]}]}
{"op":"mcm","clk":"1005838831","pt":1580645038479,"mc":[{"id":"1.168224297","rc":[{"batb":[[0,1.2,625.31],[1,1.19,574.6],[2,1.01,15.51]],"batl":[[0,1.62,200.31],[1,1.63,125.26],[2,1.71,542.06]],"ltp":1.39,"tv":2306.5,"id":2257317}]}]}
{"op":"mcm","clk":"1005840400","pt":1580645047090,"mc":[{"id":"1.168224297","rc":[{"batb":[[0,1.19,117.47],[1,1.01,15.51],[2,1.01,0]],"ltp":1.39,"tv":2306.5,"id":2257317}]}]}
{"op":"mcm","clk":"1005840712","pt":1580645048995,"mc":[{"id":"1.168224297","rc":[{"batl":[[2,1.71,0]],"ltp":1.39,"tv":2306.5,"id":2257317}]}]}
{"op":"mcm","clk":"1005840960","pt":1580645050208,"mc":[{"id":"1.168224297","rc":[{"batb":[[0,1.56,221.66],[1,1.55,152.92],[2,1.19,117.47]],"ltp":1.39,"tv":2306.5,"id":2257317}]}]}
{"op":"mcm","clk":"1005841105","pt":1580645051011,"mc":[{"id":"1.168224297","rc":[{"batb":[[1,1.55,186.44],[2,1.54,77.3]],"ltp":1.39,"tv":2306.5,"id":2257317},{"batb":[[1,2.42,17.47],[2,1.01,15.52]],"batl":[[0,2.84,22.69]],"ltp":2.72,"tv":25.2,"id":10303696}]}]}
{"op":"mcm","clk":"1005841588","pt":1580645053395,"mc":[{"id":"1.168224297","rc":[{"batl":[[2,2.04,383.01]],"ltp":1.39,"tv":2306.5,"id":2257317},{"batl":[[1,3.65,170.41]],"ltp":2.72,"tv":25.2,"id":10303696}]}]}
{"op":"mcm","clk":"1005844692","pt":1580645070375,"mc":[{"id":"1.168224297","rc":[{"batb":[[0,1.55,33.52],[1,1.54,77.3],[2,1.43,46.34]],"batl":[[0,2.04,383.01],[1,1.63,0],[2,2.04,0]],"ltp":1.39,"tv":2306.5,"id":2257317}]}]}
{"op":"mcm","clk":"1005844829","pt":1580645071068,"mc":[{"id":"1.168224297","rc":[{"batb":[[0,1.54,77.3],[1,1.43,46.34],[2,1.01,15.51]],"ltp":1.39,"tv":2306.5,"id":2257317},{"batb":[[0,2.42,17.47],[1,1.01,15.52],[2,1.01,0]],"ltp":2.72,"tv":25.2,"id":10303696}]}]}
{"op":"mcm","clk":"1005845005","pt":1580645072035,"mc":[{"id":"1.168224297","rc":[{"batb":[[0,1.43,46.34],[1,1.01,15.51],[2,1.01,0]],"ltp":1.39,"tv":2306.5,"id":2257317},{"batl":[[0,3.65,170.41],[1,3.65,0]],"ltp":2.72,"tv":25.2,"id":10303696}]}]}
{"op":"mcm","clk":"1005845267","pt":1580645073363,"mc":[{"id":"1.168224297","rc":[{"batb":[[0,1.44,260.87],[1,1.43,259.85],[2,1.01,15.51]],"batl":[[0,1.72,125.56],[1,1.74,201.72],[2,2.04,383.01]],"ltp":1.39,"tv":2306.5,"id":2257317}]}]}
{"op":"mcm","clk":"1005846574","pt":1580645080663,"mc":[{"id":"1.168224297","rc":[{"batl":[[0,2.04,383.01],[1,1.74,0],[2,2.04,0]],"ltp":1.39,"tv":2306.5,"id":2257317}]}]}
{"op":"mcm","clk":"1005847148","pt":1580645083874,"mc":[{"id":"1.168224297","rc":[{"batl":[[0,1.49,249.57],[1,1.5,170.67]],"ltp":1.39,"tv":2306.5,"id":2257317}]}]}
{"op":"mcm","clk":"1005847325","pt":1580645085093,"mc":[{"id":"1.168224297","rc":[{"batb":[[0,1.45,93.26],[1,1.44,260.87],[2,1.43,259.85]],"ltp":1.39,"tv":2306.5,"id":2257317},{"batb":[[0,3.1,22.9],[1,2.72,12.83],[2,1.01,15.52]],"batl":[[0,3.2,18.48]],"ltp":2.72,"tv":25.2,"id":10303696}]}]}
{"op":"mcm","clk":"1005847659","pt":1580645086997,"mc":[{"id":"1.168224297","rc":[{"batl":[[2,1.82,469.11]],"ltp":1.39,"tv":2306.5,"id":2257317},{"batb":[[1,2.74,480.29],[2,2.72,12.83]],"batl":[[1,4.6,136.05]],"ltp":2.72,"tv":25.2,"id":10303696}]}]}
{"op":"mcm","clk":"1005848213","pt":1580645090304,"mc":[{"id":"1.168224297","rc":[{"batb":[[1,1.31,68.61],[2,1.01,15.51]],"batl":[[0,1.82,469.11],[1,1.5,0],[2,1.82,0]],"ltp":1.39,"tv":2306.5,"id":2257317},{"batb":[[0,2.72,12.83],[1,1.01,15.52],[2,2.72,0]],"ltp":2.72,"tv":25.2,"id":10303696}]}]}
{"op":"mcm","clk":"1005848563","pt":1580645092113,"mc":[{"id":"1.168224297","rc":[{"batb":[[0,1.31,68.61],[1,1.01,15.51],[2,1.01,0]],"ltp":1.39,"tv":2306.5,"id":2257317},{"batl":[[0,4.6,136.05],[1,4.6,0]],"ltp":2.72,"tv":25.2,"id":10303696}]}]}
{"op":"mcm","clk":"1005848741","pt":1580645092920,"mc":[{"id":"1.168224297","rc":[{"batb":[[0,1.32,323.89],[1,1.31,395.06],[2,1.01,15.51]],"batl":[[0,1.6,223.64],[1,1.61,130.8],[2,1.82,469.11]],"ltp":1.39,"tv":2306.5,"id":2257317}]}]}
{"op":"mcm","clk":"1005849087","pt":1580645094726,"mc":[{"id":"1.168224297","rc":[{"batb":[[0,1.31,68.61],[1,1.01,15.51],[2,1.01,0]],"batl":[[0,1.82,469.11],[1,1.61,0],[2,1.82,0]],"ltp":1.39,"tv":2306.5,"id":2257317}]}]}
{"op":"mcm","clk":"1005850355","pt":1580645101015,"mc":[{"id":"1.168224297","rc":[{"batb":[[0,1.32,326.64],[1,1.31,395.07],[2,1.01,15.51]],"batl":[[0,1.6,221.39],[1,1.61,130.8],[2,1.82,469.11]],"ltp":1.39,"tv":2306.5,"id":2257317}]}]}
{"op":"mcm","clk":"1005851205","pt":1580645105235,"mc":[{"id":"1.168224297","rc":[{"batb":[[0,1.31,68.61],[1,1.01,15.51],[2,1.01,0]],"ltp":1.39,"tv":2306.5,"id":2257317}]}]}
{"op":"mcm","clk":"1005851828","pt":1580645108341,"mc":[{"id":"1.168224297","rc":[{"batb":[[0,1.54,235.2],[1,1.53,160.94],[2,1.31,68.61]],"ltp":1.39,"tv":2306.5,"id":2257317}]}]}
{"op":"mcm","clk":"1005851980","pt":1580645109141,"mc":[{"id":"1.168224297","rc":[{"batb":[[1,1.53,274.85],[2,1.39,51.14]],"ltp":1.39,"tv":2306.5,"id":2257317},{"batb":[[1,2.42,17.47],[2,1.01,15.52]],"batl":[[0,2.88,21.85]],"ltp":2.72,"tv":25.2,"id":10303696}]}]}
{"op":"mcm","clk":"1005852370","pt":1580645111124,"mc":[{"id":"1.168224297","rc":[{"batl":[[1,3.9,158.24]],"ltp":2.72,"tv":25.2,"id":10303696}]}]}
{"op":"mcm","clk":"1005855224","pt":1580645125342,"mc":[{"id":"1.168224297","rc":[{"batb":[[0,1.53,113.91],[1,1.39,51.14],[2,1.01,15.51]],"batl":[[0,1.82,469.11],[1,1.61,0],[2,1.82,0]],"ltp":1.39,"tv":2306.5,"id":2257317}]}]}
{"op":"mcm","clk":"1005855374","pt":1580645126146,"mc":[{"id":"1.168224297","rc":[{"batb":[[0,1.39,51.14],[1,1.01,15.51],[2,1.01,0]],"ltp":1.39,"tv":2306.5,"id":2257317},{"batb":[[0,2.42,17.47],[1,1.01,15.52],[2,1.01,0]],"batl":[[0,3.9,158.24],[1,3.9,0]],"ltp":2.72,"tv":25.2,"id":10303696}]}]}
{"op":"mcm","clk":"1005855743","pt":1580645128153,"mc":[{"id":"1.168224297","rc":[{"batb":[[0,1.4,351.79],[1,1.39,294.72],[2,1.01,15.51]],"batl":[[0,1.72,148.91],[1,1.74,201.57],[2,1.82,469.11]],"ltp":1.39,"tv":2306.5,"id":2257317}]}]}
{"op":"mcm","clk":"1005856532","pt":1580645131930,"mc":[{"id":"1.168224297","rc":[{"batb":[[0,1.39,51.14],[1,1.01,15.51],[2,1.01,0]],"ltp":1.39,"tv":2306.5,"id":2257317}]}]}
{"op":"mcm","clk":"1005856950","pt":1580645134248,"mc":[{"id":"1.168224297","rc":[{"batl":[[2,1.82,0]],"ltp":1.39,"tv":2306.5,"id":2257317}]}]}
{"op":"mcm","clk":"1005857106","pt":1580645135028,"mc":[{"id":"1.168224297","rc":[{"batb":[[0,1.66,133.13],[1,1.65,120.76],[2,1.39,51.14]],"ltp":1.39,"tv":2306.5,"id":2257317}]}]}
{"op":"mcm","clk":"1005857305","pt":1580645136054,"mc":[{"id":"1.168224297","rc":[{"batb":[[2,1.64,26.83]],"ltp":1.39,"tv":2306.5,"id":2257317},{"batb":[[1,2.22,22.11],[2,1.01,15.52]],"ltp":2.72,"tv":25.2,"id":10303696}]}]}
{"op":"mcm","clk":"1005857523","pt":1580645137272,"mc":[{"id":"1.168224297","rc":[{"batl":[[2,2.16,342.82]],"ltp":1.39,"tv":2306.5,"id":2257317},{"batl":[[0,2.62,25.21],[1,3.3,191.92]],"ltp":2.72,"tv":25.2,"id":10303696}]}]}
{"op":"mcm","clk":"1005858465","pt":1580645142068,"mc":[{"id":"1.168224297","rc":[{"batb":[[0,1.51,36.67],[1,1.01,15.51],[2,1.64,0]],"batl":[[0,2.16,342.82],[1,1.74,0],[2,2.16,0]],"ltp":1.39,"tv":2306.5,"id":2257317},{"batb":[[0,2.22,22.11],[1,1.01,15.52],[2,1.01,0]],"batl":[[0,3.3,191.92],[1,3.3,0]],"ltp":2.72,"tv":25.2,"id":10303696}]}]}
{"op":"mcm","clk":"1005858903","pt":1580645144403,"mc":[{"id":"1.168224297","rc":[{"batb":[[0,1.52,241.53],[1,1.51,206.31],[2,1.01,15.51]],"batl":[[0,1.84,168.57],[1,1.86,162.47],[2,2.16,342.82]],"ltp":1.39,"tv":2306.5,"id":2257317}]}]}
{"op":"mcm","clk":"1005859225","pt":1580645146271,"mc":[{"id":"1.168224297","rc":[{"batb":[[0,1.51,36.67],[1,1.01,15.51],[2,1.01,0]],"batl":[[0,2.16,342.82],[1,1.86,0],[2,2.16,0]],"ltp":1.39,"tv":2306.5,"id":2257317}]}]}
{"op":"mcm","clk":"1005860394","pt":1580645152076,"mc":[{"id":"1.168224297","rc":[{"batb":[[0,1.52,241.53],[1,1.51,206.31],[2,1.01,15.51]],"batl":[[0,1.84,168.57],[1,1.86,162.47],[2,2.16,342.82]],"ltp":1.39,"tv":2306.5,"id":2257317}]}]}
{"op":"mcm","clk":"1005863184","pt":1580645166163,"mc":[{"id":"1.168224297","rc":[{"batb":[[0,1.51,36.67],[1,1.01,15.51],[2,1.01,0]],"ltp":1.39,"tv":2306.5,"id":2257317}]}]}
{"op":"mcm","clk":"1005863754","pt":1580645169271,"mc":[{"id":"1.168224297","rc":[{"batb":[[0,1.76,190.52],[1,1.74,199.55],[2,1.51,36.67]],"ltp":1.39,"tv":2306.5,"id":2257317}]}]}
{"op":"mcm","clk":"1005863972","pt":1580645170277,"mc":[{"id":"1.168224297","rc":[{"batb":[[1,1.75,21.72],[2,1.74,199.55]],"ltp":1.39,"tv":2306.5,"id":2257317},{"batb":[[1,2.12,25.34],[2,1.01,15.52]],"ltp":2.72,"tv":25.2,"id":10303696}]}]}
{"op":"mcm","clk":"1005864146","pt":1580645171077,"mc":[{"id":"1.168224297","rc":[{"batl":[[0,2.44,28.57]],"ltp":2.72,"tv":25.2,"id":10303696}]}]}
{"op":"mcm","clk":"1005864296","pt":1580645171771,"mc":[{"id":"1.168224297","rc":[{"batl":[[1,3,213.45]],"ltp":2.72,"tv":25.2,"id":10303696}]}]}
{"op":"mcm","clk":"1005865663","pt":1580645178375,"mc":[{"id":"1.168224297","rc":[{"trd":[[1.76,0.04]],"batb":[[0,1.69,60.49],[1,1.66,25.81],[2,1.01,15.51]],"batl":[[0,2.16,342.82],[1,1.86,0],[2,2.16,0]],"ltp":1.76,"tv":2306.54,"id":2257317},{"batb":[[0,2.12,25.34],[1,1.01,15.52],[2,1.01,0]],"ltp":2.72,"tv":25.2,"id":10303696}],"tv":2331.74}]}
{"op":"mcm","clk":"1005866022","pt":1580645180185,"mc":[{"id":"1.168224297","rc":[{"batb":[[0,1.66,25.81],[1,1.01,15.51],[2,1.01,0]],"ltp":1.76,"tv":2306.54,"id":2257317},{"batl":[[0,3,213.45],[1,3,0]],"ltp":2.72,"tv":25.2,"id":10303696}]}]}
{"op":"mcm","clk":"1005866147","pt":1580645180675,"mc":[{"id":"1.168224297","rc":[{"batb":[[0,1.67,192.59],[1,1.66,144.11],[2,1.01,15.51]],"batl":[[0,1.91,119.05],[1,1.93,145],[2,2.16,342.82]],"ltp":1.76,"tv":2306.54,"id":2257317}]}]}
{"op":"mcm","clk":"1005867527","pt":1580645187103,"mc":[{"id":"1.168224297","rc":[{"batb":[[0,1.66,25.81],[1,1.01,15.51],[2,1.01,0]],"ltp":1.76,"tv":2306.54,"id":2257317}]}]}
{"op":"mcm","clk":"1005867940","pt":1580645189394,"mc":[{"id":"1.168224297","rc":[{"batl":[[2,2.16,0]],"ltp":1.76,"tv":2306.54,"id":2257317}]}]}
{"op":"mcm","clk":"1005868098","pt":1580645190297,"mc":[{"id":"1.168224297","rc":[{"batb":[[0,1.83,171.31],[1,1.81,174.85],[2,1.66,25.81]],"ltp":1.76,"tv":2306.54,"id":2257317}]}]}
{"op":"mcm","clk":"1005868253","pt":1580645191109,"mc":[{"id":"1.168224297","rc":[{"batb":[[1,1.82,19.04],[2,1.81,174.85]],"ltp":1.76,"tv":2306.54,"id":2257317},{"batb":[[1,1.88,18.1],[2,1.01,15.52]],"batl":[[0,2.36,30.25]],"ltp":2.72,"tv":25.2,"id":10303696}]}]}
{"op":"mcm","clk":"1005868537","pt":1580645192712,"mc":[{"id":"1.168224297","rc":[{"batl":[[2,2.42,286.52]],"ltp":1.76,"tv":2306.54,"id":2257317},{"batl":[[1,2.82,231.28]],"ltp":2.72,"tv":25.2,"id":10303696}]}]}
{"op":"mcm","clk":"1005871320","pt":1580645207001,"mc":[{"id":"1.168224297","rc":[{"trd":[[1.83,342.52]],"batb":[[0,1.82,19.09],[1,1.81,174.85],[2,1.73,57.13]],"ltp":1.83,"tv":2649.06,"id":2257317}],"tv":2674.26}]}
{"op":"mcm","clk":"1005871470","pt":1580645207711,"mc":[{"id":"1.168224297","rc":[{"batl":[[0,2.42,286.52],[1,1.93,0],[2,2.42,0]],"ltp":1.83,"tv":2649.06,"id":2257317}]}]}
{"op":"mcm","clk":"1005871991","pt":1580645210828,"mc":[{"id":"1.168224297","rc":[{"trd":[[1.9,61.12]],"batb":[[0,1.83,108.53],[1,1.82,19.04],[2,1.81,174.85]],"ltp":1.9,"tv":2710.18,"id":2257317}],"tv":2735.38}]}
{"op":"mcm","clk":"1005872505","pt":1580645213742,"mc":[{"id":"1.168224297","rc":[{"batl":[[0,1.91,168.08],[1,1.93,145.03],[2,2.42,286.52]],"ltp":1.9,"tv":2710.18,"id":2257317}]}]}
{"op":"mcm","clk":"1005876644","pt":1580645234886,"mc":[{"id":"1.168224297","rc":[{"trd":[[2.12,38.76]],"batb":[[0,2.12,5.95]],"ltp":2.12,"tv":63.96,"id":10303696}],"tv":2774.14}]}
{"op":"mcm","clk":"1005877465","pt":1580645238677,"mc":[{"id":"1.168224297","rc":[{"batb":[[0,1.83,127.18],[1,1.81,174.85],[2,1.73,57.13]],"ltp":1.9,"tv":2710.18,"id":2257317},{"batb":[[0,2.1,25.89],[1,1.87,18.49]],"ltp":2.12,"tv":63.96,"id":10303696}]}]}
{"op":"mcm","clk":"1005877897","pt":1580645241009,"mc":[{"id":"1.168224297","rc":[{"batb":[[2,1.73,57.15]],"ltp":1.9,"tv":2710.18,"id":2257317}]}]}
{"op":"mcm","clk":"1005885273","pt":1580645279316,"mc":[{"id":"1.168224297","rc":[{"batb":[[0,1.83,18.65],[1,1.73,57.15],[2,1.72,22.9]],"batl":[[0,2.42,286.52],[1,1.93,0],[2,2.42,0]],"ltp":1.9,"tv":2710.18,"id":2257317}]}]}
{"op":"mcm","clk":"1005885466","pt":1580645280244,"mc":[{"id":"1.168224297","rc":[{"batb":[[0,1.72,22.91],[1,1.01,15.51],[2,1.72,0]],"ltp":1.9,"tv":2710.18,"id":2257317},{"batb":[[0,1.87,18.49],[1,1.01,15.52],[2,1.01,0]],"batl":[[0,2.82,231.28],[1,2.82,0]],"ltp":2.12,"tv":63.96,"id":10303696}]}]}
{"op":"mcm","clk":"1005885903","pt":1580645282296,"mc":[{"id":"1.168224297","rc":[{"batb":[[0,1.72,176.53],[1,1.7,216.24],[2,1.01,15.51]],"batl":[[0,2.16,130.32],[1,2.18,101.47],[2,2.42,286.52]],"ltp":1.9,"tv":2710.18,"id":2257317}]}]}
{"op":"mcm","clk":"1005886774","pt":1580645286734,"mc":[{"id":"1.168224297","rc":[{"batl":[[0,2.42,286.52],[1,2.18,0],[2,2.42,0]],"ltp":1.9,"tv":2710.18,"id":2257317}]}]}
{"op":"mcm","clk":"1005887469","pt":1580645290359,"mc":[{"id":"1.168224297","rc":[{"batb":[[2,1.64,27.07]],"batl":[[0,1.79,160.89],[1,1.81,177.31]],"ltp":1.9,"tv":2710.18,"id":2257317},{"batb":[[0,2.26,20.77],[1,2.04,28.09],[2,1.87,18.49]],"ltp":2.12,"tv":63.96,"id":10303696}]}]}
{"op":"mcm","clk":"1005887628","pt":1580645291117,"mc":[{"id":"1.168224297","rc":[{"batb":[[2,1.65,63.85]],"ltp":1.9,"tv":2710.18,"id":2257317},{"batb":[[1,2.14,129.82],[2,2.04,28.09]],"batl":[[0,2.56,26.89]],"ltp":2.12,"tv":63.96,"id":10303696}]}]}
{"op":"mcm","clk":"1005887984","pt":1580645292915,"mc":[{"id":"1.168224297","rc":[{"batl":[[2,2.22,329.01]],"ltp":1.9,"tv":2710.18,"id":2257317},{"batb":[[1,2.04,28.09],[2,1.01,15.52]],"batl":[[1,3.15,200.42]],"ltp":2.12,"tv":63.96,"id":10303696}]}]}
{"op":"mcm","clk":"1005889545","pt":1580645300238,"mc":[{"id":"1.168224297","rc":[{"batb":[[0,1.72,22.91],[1,1.65,63.85],[2,1.64,27.07]],"batl":[[0,2.22,329.01],[1,1.81,0],[2,2.22,0]],"ltp":1.9,"tv":2710.18,"id":2257317}]}]}
{"op":"mcm","clk":"1005889772","pt":1580645301267,"mc":[{"id":"1.168224297","rc":[{"batb":[[0,1.65,63.87],[1,1.64,27.07],[2,1.01,15.51]],"ltp":1.9,"tv":2710.18,"id":2257317},{"batb":[[0,2.04,28.09],[1,1.01,15.52],[2,1.01,0]],"ltp":2.12,"tv":63.96,"id":10303696}]}]}
{"op":"mcm","clk":"1005890065","pt":1580645302345,"mc":[{"id":"1.168224297","rc":[{"batb":[[0,1.64,27.08],[1,1.01,15.51],[2,1.01,0]],"ltp":1.9,"tv":2710.18,"id":2257317},{"batl":[[0,3.15,200.42],[1,3.15,0]],"ltp":2.12,"tv":63.96,"id":10303696}]}]}
{"op":"mcm","clk":"1005890229","pt":1580645303036,"mc":[{"id":"1.168224297","rc":[{"batb":[[0,1.64,259.7],[1,1.63,126.61],[2,1.01,15.51]],"batl":[[0,1.96,146.03],[1,1.98,134.26],[2,2.22,329.01]],"ltp":1.9,"tv":2710.18,"id":2257317}]}]}
{"op":"mcm","clk":"1005891245","pt":1580645307876,"mc":[{"id":"1.168224297","rc":[{"batl":[[0,2.22,329.01],[1,1.98,0],[2,2.22,0]],"ltp":1.9,"tv":2710.18,"id":2257317}]}]}
{"op":"mcm","clk":"1005891915","pt":1580645311343,"mc":[{"id":"1.168224297","rc":[{"trd":[[1.76,0.07]],"batb":[[0,1.64,259.69],[2,1.59,100.63]],"batl":[[0,1.71,184.2],[1,1.73,205.51],[2,2.22,329.01]],"ltp":1.76,"tv":2710.21,"id":2257317},{"batb":[[0,2.42,17.23],[1,2.28,96.91],[2,2.24,21.64]],"batl":[[0,2.72,24.37],[1,3.15,200.42]],"ltp":2.12,"tv":63.96,"id":10303696}],"tv":2774.17}]}
{"op":"mcm","clk":"1005892084","pt":1580645312132,"mc":[{"id":"1.168224297","rc":[{"trd":[[1.64,519.37]],"batb":[[0,1.63,126.61],[1,1.59,100.63],[2,1.01,15.51]],"ltp":1.64,"tv":3229.58,"id":2257317},{"batb":[[1,2.24,21.64],[2,1.01,15.52]],"ltp":2.12,"tv":63.96,"id":10303696}],"tv":3293.54}]}
{"op":"mcm","clk":"1005892241","pt":1580645312826,"mc":[{"id":"1.168224297","rc":[{"batl":[[0,2.22,329.01],[1,1.73,0],[2,2.22,0]],"ltp":1.64,"tv":3229.58,"id":2257317}]}]}
{"op":"mcm","clk":"1005892967","pt":1580645315906,"mc":[{"id":"1.168224297","rc":[{"batb":[[0,1.64,147.36],[1,1.63,126.61],[2,1.59,100.63]],"batl":[[0,1.7,160.43],[1,1.72,210.11],[2,2.22,329.01]],"ltp":1.64,"tv":3229.58,"id":2257317}]}]}
{"op":"mcm","clk":"1005894271","pt":1580645322229,"mc":[{"id":"1.168224297","rc":[{"batb":[[0,1.59,30.06],[1,1.01,15.51],[2,1.59,0]],"batl":[[0,2.22,329.01],[1,1.72,0],[2,2.22,0]],"ltp":1.64,"tv":3229.58,"id":2257317},{"batb":[[0,2.24,21.64],[1,1.01,15.52],[2,1.01,0]],"batl":[[0,3.15,200.42],[1,3.15,0]],"ltp":2.12,"tv":63.96,"id":10303696}]}]}
{"op":"mcm","clk":"1005894891","pt":1580645325136,"mc":[{"id":"1.168224297","rc":[{"batb":[[0,1.59,226.66],[1,1.58,173.15],[2,1.01,15.51]],"batl":[[0,1.8,165.42],[1,1.82,174.54],[2,2.22,329.01]],"ltp":1.64,"tv":3229.58,"id":2257317},{"batb":[[0,2.26,21.17]],"ltp":2.12,"tv":63.96,"id":10303696}]}]}
{"op":"mcm","clk":"1005896378","pt":1580645332237,"mc":[{"id":"1.168224297","rc":[{"batl":[[0,2.22,329.01],[1,1.82,0],[2,2.22,0]],"ltp":1.64,"tv":3229.58,"id":2257317}]}]}
{"op":"mcm","clk":"1005897002","pt":1580645335346,"mc":[{"id":"1.168224297","rc":[{"batl":[[0,1.65,151.57],[1,1.66,117.98]],"ltp":1.64,"tv":3229.58,"id":2257317}]}]}
{"op":"mcm","clk":"1005897148","pt":1580645336051,"mc":[{"id":"1.168224297","rc":[{"batb":[[2,1.55,33.05]],"ltp":1.64,"tv":3229.58,"id":2257317},{"batb":[[0,2.56,14.95],[1,2.42,17.39],[2,1.01,15.52]],"ltp":2.12,"tv":63.96,"id":10303696}]}]}
{"op":"mcm","clk":"1005897377","pt":1580645337159,"mc":[{"id":"1.168224297","rc":[{"trd":[[1.59,349.56]],"batb":[[0,1.59,182.43],[2,1.55,108.66]],"ltp":1.59,"tv":3318.01,"id":2257317},{"batl":[[0,2.84,22.69]],"ltp":2.12,"tv":63.96,"id":10303696}],"tv":3381.97}]}
{"op":"mcm","clk":"1005897592","pt":1580645338344,"mc":[{"id":"1.168224297","rc":[{"batl":[[2,2.04,383.01]],"ltp":1.59,"tv":3318.01,"id":2257317},{"batl":[[1,3.65,170.41]],"ltp":2.12,"tv":63.96,"id":10303696}]}]}
{"op":"mcm","clk":"1005897760","pt":1580645339247,"mc":[{"id":"1.168224297","rc":[{"trd":[[1.59,714.42]],"batb":[[0,1.58,173.15],[1,1.55,108.66],[2,1.01,15.51]],"ltp":1.59,"tv":3682.87,"id":2257317}],"tv":3746.83}]}
{"op":"mcm","clk":"1005897876","pt":1580645339829,"mc":[{"id":"1.168224297","rc":[{"batb":[[0,1.59,28.02],[1,1.58,173.15],[2,1.55,108.66]],"ltp":1.59,"tv":3682.87,"id":2257317}]}]}
{"op":"mcm","clk":"1005898339","pt":1580645342371,"mc":[{"id":"1.168224297","rc":[{"batb":[[0,1.59,143.57]],"batl":[[0,1.65,231.64]],"ltp":1.59,"tv":3682.87,"id":2257317}]}]}
{"op":"mcm","clk":"1005899483","pt":1580645348200,"mc":[{"id":"1.168224297","rc":[{"batb":[[0,1.55,33.05],[1,1.01,15.51],[2,1.55,0]],"batl":[[0,2.04,383.01],[1,1.66,0],[2,2.04,0]],"ltp":1.59,"tv":3682.87,"id":2257317},{"batb":[[0,2.42,17.39],[1,1.01,15.52],[2,1.01,0]],"batl":[[0,3.65,170.41],[1,3.65,0]],"ltp":2.12,"tv":63.96,"id":10303696}]}]}
{"op":"mcm","clk":"1005900030","pt":1580645351338,"mc":[{"id":"1.168224297","rc":[{"batb":[[0,1.56,242.82],[1,1.55,186.81],[2,1.01,15.51]],"batl":[[0,1.69,122.24],[1,1.71,215.01],[2,2.04,383.01]],"ltp":1.59,"tv":3682.87,"id":2257317}]}]}
{"op":"mcm","clk":"1005900929","pt":1580645356114,"mc":[{"id":"1.168224297","rc":[{"batb":[[0,1.55,33.05],[1,1.01,15.51],[2,1.01,0]],"batl":[[0,2.04,383.01],[1,1.71,0],[2,2.04,0]],"ltp":1.59,"tv":3682.87,"id":2257317}]}]}
{"op":"mcm","clk":"1005901539","pt":1580645359339,"mc":[{"id":"1.168224297","rc":[{"batb":[[0,1.6,125.43],[1,1.59,139.05],[2,1.55,33.05]],"batl":[[0,1.66,234.56],[1,1.68,227.76],[2,2.04,383.01]],"ltp":1.59,"tv":3682.87,"id":2257317}]}]}
{"op":"mcm","clk":"1005901614","pt":1580645359734,"mc":[{"id":"1.168224297","rc":[{"batb":[[0,1.55,33.05],[1,1.01,15.51],[2,1.55,0]],"batl":[[0,2.04,383.01],[1,1.68,0],[2,2.04,0]],"ltp":1.59,"tv":3682.87,"id":2257317}]}]}
{"op":"mcm","clk":"1005902157","pt":1580645362217,"mc":[{"id":"1.168224297","rc":[{"batl":[[0,3.45,180.4]],"ltp":2.12,"tv":63.96,"id":10303696}]}]}
{"op":"mcm","clk":"1005902222","pt":1580645362646,"mc":[{"id":"1.168224297","rc":[{"batb":[[0,1.56,242.82],[1,1.55,186.81],[2,1.01,15.51]],"batl":[[0,1.69,122.24],[1,1.71,215.01],[2,2.04,383.01]],"ltp":1.59,"tv":3682.87,"id":2257317}]}]}
{"op":"mcm","clk":"1005903317","pt":1580645368394,"mc":[{"id":"1.168224297","rc":[{"batb":[[0,1.55,33.05],[1,1.01,15.51],[2,1.01,0]],"ltp":1.59,"tv":3682.87,"id":2257317}]}]}
{"op":"mcm","clk":"1005903925","pt":1580645371322,"mc":[{"id":"1.168224297","rc":[{"batb":[[0,1.63,202.31],[1,1.62,129.97],[2,1.55,33.05]],"ltp":1.59,"tv":3682.87,"id":2257317}]}]}
{"op":"mcm","clk":"1005904067","pt":1580645371905,"mc":[{"id":"1.168224297","rc":[{"batb":[[0,1.64,26.91],[1,1.63,202.31],[2,1.62,129.97]],"ltp":1.59,"tv":3682.87,"id":2257317},{"batb":[[1,2.24,21.24],[2,1.01,15.52]],"ltp":2.12,"tv":63.96,"id":10303696}]}]}
{"op":"mcm","clk":"1005904316","pt":1580645373184,"mc":[{"id":"1.168224297","rc":[{"batl":[[0,2.74,23.53]],"ltp":2.12,"tv":63.96,"id":10303696}]}]}
{"op":"mcm","clk":"1005904559","pt":1580645374301,"mc":[{"id":"1.168224297","rc":[{"batl":[[1,3.3,191.92]],"ltp":2.12,"tv":63.96,"id":10303696}]}]}
{"op":"mcm","clk":"1005905960","pt":1580645381311,"mc":[{"id":"1.168224297","rc":[{"batb":[[1,1.59,30.14],[2,1.58,72.26]],"batl":[[0,2.04,383.01],[1,1.71,0],[2,2.04,0]],"ltp":1.59,"tv":3682.87,"id":2257317}]}]}
{"op":"mcm","clk":"1005906131","pt":1580645382215,"mc":[{"id":"1.168224297","rc":[{"batb":[[0,1.59,30.14],[1,1.01,15.51],[2,1.58,0]],"ltp":1.59,"tv":3682.87,"id":2257317},{"batb":[[0,2.24,21.24],[1,1.01,15.52],[2,1.01,0]],"batl":[[0,3.3,191.92],[1,3.3,0]],"ltp":2.12,"tv":63.96,"id":10303696}]}]}
{"op":"mcm","clk":"1005906527","pt":1580645384322,"mc":[{"id":"1.168224297","rc":[{"batb":[[0,1.59,192.07],[1,1.58,142.57],[2,1.01,15.51]],"batl":[[0,1.79,190.63],[1,1.81,177.96],[2,2.04,383.01]],"ltp":1.59,"tv":3682.87,"id":2257317}]}]}
{"op":"mcm","clk":"1005907798","pt":1580645391313,"mc":[{"id":"1.168224297","rc":[{"batl":[[0,2.04,383.01],[1,1.81,0],[2,2.04,0]],"ltp":1.59,"tv":3682.87,"id":2257317}]}]}
{"op":"mcm","clk":"1005908398","pt":1580645394337,"mc":[{"id":"1.168224297","rc":[{"batl":[[0,1.65,214.51],[1,1.66,118.09],[2,2.04,383.01]],"ltp":1.59,"tv":3682.87,"id":2257317}]}]}
{"op":"mcm","clk":"1005908565","pt":1580645395263,"mc":[{"id":"1.168224297","rc":[{"batb":[[2,1.54,77.3]],"ltp":1.59,"tv":3682.87,"id":2257317},{"batb":[[0,2.54,15.26],[1,2.3,19.75],[2,1.01,15.52]],"batl":[[0,2.86,21.85],[1,3.3,191.92]],"ltp":2.12,"tv":63.96,"id":10303696}]}]}
{"op":"mcm","clk":"1005912392","pt":1580645416224,"mc":[{"id":"1.168224297","rc":[{"batb":[[0,1.46,42.41],[1,1.01,15.51],[2,1.54,0]],"batl":[[0,2.04,383.01],[1,1.66,0],[2,2.04,0]],"ltp":1.59,"tv":3682.87,"id":2257317},{"batb":[[0,2.3,19.75],[1,1.01,15.52],[2,1.01,0]],"batl":[[0,3.3,191.92],[1,3.3,0]],"ltp":2.12,"tv":63.96,"id":10303696}]}]}
{"op":"mcm","clk":"1005912940","pt":1580645419142,"mc":[{"id":"1.168224297","rc":[{"batb":[[1,1.45,287.73],[2,1.44,208.7]],"batl":[[0,1.76,147.63],[1,1.78,187.91],[2,2.04,383.01]],"ltp":1.59,"tv":3682.87,"id":2257317}]}]}
{"op":"mcm","clk":"1005914003","pt":1580645424947,"mc":[{"id":"1.168224297","rc":[{"batl":[[0,2.04,383.01],[1,1.78,0],[2,2.04,0]],"ltp":1.59,"tv":3682.87,"id":2257317}]}]}
{"op":"mcm","clk":"1005914669","pt":1580645428381,"mc":[{"id":"1.168224297","rc":[{"batl":[[0,1.5,208.1],[1,1.51,167.74]],"ltp":1.59,"tv":3682.87,"id":2257317}]}]}
{"op":"mcm","clk":"1005914819","pt":1580645429133,"mc":[{"id":"1.168224297","rc":[{"batb":[[2,1.44,303.64]],"ltp":1.59,"tv":3682.87,"id":2257317},{"batb":[[0,2.96,25.65],[1,2.6,14.4],[2,1.01,15.52]],"batl":[[0,3.3,17.64]],"ltp":2.12,"tv":63.96,"id":10303696}]}]}
{"op":"mcm","clk":"1005915173","pt":1580645431164,"mc":[{"id":"1.168224297","rc":[{"batl":[[2,1.89,435.28]],"ltp":1.59,"tv":3682.87,"id":2257317},{"batl":[[1,4.2,148.03]],"ltp":2.12,"tv":63.96,"id":10303696}]}]}
{"op":"mcm","clk":"1005916127","pt":1580645436181,"mc":[{"id":"1.168224297","rc":[{"batb":[[0,1.32,67.19],[1,1.01,15.51],[2,1.44,0]],"batl":[[0,1.89,435.28],[1,1.51,0],[2,1.89,0]],"ltp":1.59,"tv":3682.87,"id":2257317},{"batb":[[0,2.6,14.4],[1,1.01,15.52],[2,1.01,0]],"batl":[[0,4.2,148.03],[1,4.2,0]],"ltp":2.12,"tv":63.96,"id":10303696}]}]}
{"op":"mcm","clk":"1005916574","pt":1580645438510,"mc":[{"id":"1.168224297","rc":[{"batb":[[0,1.32,261.73],[1,1.31,327.22],[2,1.01,15.51]],"batl":[[0,1.62,174.72],[1,1.63,126.07],[2,1.89,435.28]],"ltp":1.59,"tv":3682.87,"id":2257317}]}]}
{"op":"mcm","clk":"1005916820","pt":1580645440009,"mc":[{"id":"1.168224297","rc":[{"batb":[[0,1.32,67.19],[1,1.01,15.51],[2,1.01,0]],"batl":[[0,1.89,435.28],[1,1.63,0],[2,1.89,0]],"ltp":1.59,"tv":3682.87,"id":2257317}]}]}
{"op":"mcm","clk":"1005917392","pt":1580645443407,"mc":[{"id":"1.168224297","rc":[{"batb":[[0,1.42,315.11],[1,1.41,229.45],[2,1.32,67.19]],"batl":[[0,1.47,255.45],[1,1.48,181.44],[2,1.89,435.28]],"ltp":1.59,"tv":3682.87,"id":2257317}]}]}
{"op":"mcm","clk":"1005917701","pt":1580645445210,"mc":[{"id":"1.168224297","rc":[{"batb":[[0,1.32,67.19],[1,1.01,15.51],[2,1.32,0]],"batl":[[0,1.89,435.28],[1,1.48,0],[2,1.89,0]],"ltp":1.59,"tv":3682.87,"id":2257317}]}]}
{"op":"mcm","clk":"1005918239","pt":1580645448366,"mc":[{"id":"1.168224297","rc":[{"batb":[[0,1.32,261.73],[1,1.31,327.22],[2,1.01,15.51]],"batl":[[0,1.62,174.72],[1,1.63,126.07],[2,1.89,435.28]],"ltp":1.59,"tv":3682.87,"id":2257317}]}]}
{"op":"mcm","clk":"1005920454","pt":1580645460694,"mc":[{"id":"1.168224297","rc":[{"batl":[[0,1.89,435.28],[1,1.63,0],[2,1.89,0]],"ltp":1.59,"tv":3682.87,"id":2257317}]}]}
{"op":"mcm","clk":"1005921163","pt":1580645464324,"mc":[{"id":"1.168224297","rc":[{"batb":[[2,1.2,114.4]],"batl":[[0,1.35,199.4],[1,1.36,263.59]],"ltp":1.59,"tv":3682.87,"id":2257317},{"batb":[[0,3.75,14.01],[1,3.15,21.87],[2,2.6,14.4]],"ltp":2.12,"tv":63.96,"id":10303696}]}]}
{"op":"mcm","clk":"1005921345","pt":1580645465225,"mc":[{"id":"1.168224297","rc":[{"batb":[[0,1.32,392.8]],"ltp":1.59,"tv":3682.87,"id":2257317},{"batb":[[2,1.01,15.52]],"batl":[[0,4.1,13.44]],"ltp":2.12,"tv":63.96,"id":10303696}]}]}
{"op":"mcm","clk":"1005921559","pt":1580645466231,"mc":[{"id":"1.168224297","rc":[{"batl":[[2,1.71,542.06]],"ltp":1.59,"tv":3682.87,"id":2257317},{"batl":[[1,5.5,115.06]],"ltp":2.12,"tv":63.96,"id":10303696}]}]}
{"op":"mcm","clk":"1005922304","pt":1580645470333,"mc":[{"id":"1.168224297","rc":[{"batb":[[0,1.32,198.26],[1,1.2,114.4],[2,1.01,15.51]],"batl":[[0,1.71,542.06],[1,1.36,0],[2,1.71,0]],"ltp":1.59,"tv":3682.87,"id":2257317}]}]}
{"op":"mcm","clk":"1005922410","pt":1580645470814,"mc":[{"id":"1.168224297","rc":[{"batb":[[0,1.32,131.07]],"ltp":1.59,"tv":3682.87,"id":2257317},{"batb":[[0,3.15,21.87],[1,1.01,15.52],[2,1.01,0]],"ltp":2.12,"tv":63.96,"id":10303696}]}]}
{"op":"mcm","clk":"1005922683","pt":1580645472224,"mc":[{"id":"1.168224297","rc":[{"batb":[[0,1.2,114.4],[1,1.01,15.51],[2,1.01,0]],"ltp":1.59,"tv":3682.87,"id":2257317},{"batl":[[0,5.5,115.06],[1,5.5,0]],"ltp":2.12,"tv":63.96,"id":10303696}]}]}
{"op":"mcm","clk":"1005922871","pt":1580645473346,"mc":[{"id":"1.168224297","rc":[{"batb":[[0,1.2,800.89],[1,1.19,395.44],[2,1.01,15.51]],"batl":[[0,1.45,166.88],[1,1.46,192.57],[2,1.71,542.06]],"ltp":1.59,"tv":3682.87,"id":2257317}]}]}
{"op":"mcm","clk":"1005926808","pt":1580645494963,"mc":[{"id":"1.168224297","rc":[{"batb":[[0,1.2,114.4],[1,1.01,15.51],[2,1.01,0]],"ltp":1.59,"tv":3682.87,"id":2257317}]}]}
{"op":"mcm","clk":"1005927360","pt":1580645497949,"mc":[{"id":"1.168224297","rc":[{"batb":[[0,1.41,232.73],[1,1.4,236.24],[2,1.2,114.4]],"ltp":1.59,"tv":3682.87,"id":2257317}]}]}
{"op":"mcm","clk":"1005927560","pt":1580645499175,"mc":[{"id":"1.168224297","rc":[{"batb":[[0,1.41,280.8],[1,1.4,341.26],[2,1.25,86.71]],"ltp":1.59,"tv":3682.87,"id":2257317},{"batb":[[1,2.66,13.45],[2,1.01,15.52]],"batl":[[0,3.5,16.8]],"ltp":2.12,"tv":63.96,"id":10303696}]}]}
{"op":"mcm","clk":"1005927983","pt":1580645501691,"mc":[{"id":"1.168224297","rc":[{"batl":[[1,4.6,136.05]],"ltp":2.12,"tv":63.96,"id":10303696}]}]}
{"op":"mcm","clk":"1005929174","pt":1580645508392,"mc":[{"id":"1.168224297","rc":[{"trd":[[1.4,184.5],[1.41,561.61]],"batb":[[0,1.4,249.01],[1,1.25,86.71],[2,1.01,15.51]],"ltp":1.4,"tv":4428.97,"id":2257317}],"tv":4492.93}]}
{"op":"mcm","clk":"1005929646","pt":1580645511222,"mc":[{"id":"1.168224297","rc":[{"batb":[[0,1.4,456.01],[1,1.39,246.54],[2,1.25,86.71]],"batl":[[0,1.45,282.48]],"ltp":1.4,"tv":4428.97,"id":2257317}]}]}
{"op":"mcm","clk":"1005932481","pt":1580645527336,"mc":[{"id":"1.168224297","rc":[{"batb":[[0,1.4,105.02],[1,1.25,86.71],[2,1.01,15.51]],"batl":[[0,1.71,542.06],[1,1.46,0],[2,1.71,0]],"ltp":1.4,"tv":4428.97,"id":2257317}]}]}
{"op":"mcm","clk":"1005932648","pt":1580645528236,"mc":[{"id":"1.168224297","rc":[{"batb":[[0,1.25,86.71],[1,1.01,15.51],[2,1.01,0]],"ltp":1.4,"tv":4428.97,"id":2257317},{"batb":[[0,2.66,13.45],[1,1.01,15.52],[2,1.01,0]],"batl":[[0,4.6,136.05],[1,4.6,0]],"ltp":2.12,"tv":63.96,"id":10303696}]}]}
{"op":"mcm","clk":"1005933012","pt":1580645530349,"mc":[{"id":"1.168224297","rc":[{"batb":[[0,1.25,517.36],[1,1.24,457.06],[2,1.01,15.51]],"batl":[[0,1.59,217.21],[1,1.6,135.21],[2,1.71,542.06]],"ltp":1.4,"tv":4428.97,"id":2257317}]}]}
{"op":"mcm","clk":"1005933113","pt":1580645530943,"mc":[{"id":"1.168224297","rc":[{"batb":[[0,2.7,12.98]],"ltp":2.12,"tv":63.96,"id":10303696}]}]}
{"op":"mcm","clk":"1005936474","pt":1580645549689,"mc":[{"id":"1.168224297","rc":[{"batl":[[0,1.71,542.06],[1,1.6,0],[2,1.71,0]],"ltp":1.4,"tv":4428.97,"id":2257317}]}]}
{"op":"mcm","clk":"1005937107","pt":1580645553377,"mc":[{"id":"1.168224297","rc":[{"batb":[[2,1.13,173.81]],"batl":[[0,1.28,248.59],[1,1.29,346.08]],"ltp":1.4,"tv":4428.97,"id":2257317},{"batb":[[0,4.4,18.96],[1,3.55,16.05],[2,1.01,15.52]],"batl":[[0,4.7,10.92]],"ltp":2.12,"tv":63.96,"id":10303696}]}]}
{"op":"mcm","clk":"1005937701","pt":1580645556300,"mc":[{"id":"1.168224297","rc":[{"batl":[[2,1.62,614.4]],"ltp":1.4,"tv":4428.97,"id":2257317},{"batl":[[1,6.6,98.95]],"ltp":2.12,"tv":63.96,"id":10303696}]}]}
{"op":"mcm","clk":"1005939352","pt":1580645565393,"mc":[{"id":"1.168224297","rc":[{"batb":[[0,1.13,173.81],[1,1.01,15.51],[2,1.13,0]],"batl":[[0,1.62,614.4],[1,1.29,0],[2,1.62,0]],"ltp":1.4,"tv":4428.97,"id":2257317},{"batb":[[0,3.55,16.05],[1,1.01,15.52],[2,1.01,0]],"ltp":2.12,"tv":63.96,"id":10303696}]}]}
{"op":"mcm","clk":"1005939485","pt":1580645566241,"mc":[{"id":"1.168224297","rc":[{"batl":[[0,6.6,98.95],[1,6.6,0]],"ltp":2.12,"tv":63.96,"id":10303696}]}]}
{"op":"mcm","clk":"1005939710","pt":1580645567391,"mc":[{"id":"1.168224297","rc":[{"batb":[[0,1.14,788.08],[1,1.13,524.21],[2,1.01,15.51]],"batl":[[0,1.38,230.95],[1,1.39,239.08],[2,1.62,614.4]],"ltp":1.4,"tv":4428.97,"id":2257317}]}]}
{"op":"mcm","clk":"1005939892","pt":1580645568404,"mc":[{"id":"1.168224297","rc":[{"batb":[[0,1.13,173.81],[1,1.01,15.51],[2,1.01,0]],"ltp":1.4,"tv":4428.97,"id":2257317}]}]}
{"op":"mcm","clk":"1005940381","pt":1580645571310,"mc":[{"id":"1.168224297","rc":[{"batb":[[0,1.34,374.73],[1,1.33,306.41],[2,1.13,173.81]],"ltp":1.4,"tv":4428.97,"id":2257317}]}]}
{"op":"mcm","clk":"1005940510","pt":1580645571892,"mc":[{"id":"1.168224297","rc":[{"batb":[[0,1.34,435.39],[2,1.14,166.41]],"ltp":1.4,"tv":4428.97,"id":2257317},{"batb":[[1,2.7,12.9],[2,1.01,15.52]],"ltp":2.12,"tv":63.96,"id":10303696}]}]}
{"op":"mcm","clk":"1005940730","pt":1580645573212,"mc":[{"id":"1.168224297","rc":[{"batb":[[0,1.34,558.9]],"ltp":1.4,"tv":4428.97,"id":2257317},{"batl":[[0,3.9,14.28]],"ltp":2.12,"tv":63.96,"id":10303696}]}]}
{"op":"mcm","clk":"1005940934","pt":1580645574410,"mc":[{"id":"1.168224297","rc":[{"batl":[[1,5.3,118.79]],"ltp":2.12,"tv":63.96,"id":10303696}]}]}
{"op":"mcm","clk":"1005942442","pt":1580645582967,"mc":[{"id":"1.168224297","rc":[{"batl":[[0,1.38,195.22]],"ltp":1.4,"tv":4428.97,"id":2257317}]}]}
{"op":"mcm","clk":"1005942945","pt":1580645585837,"mc":[{"id":"1.168224297","rc":[{"batb":[[0,1.34,595.82]],"ltp":1.4,"tv":4428.97,"id":2257317}]}]}
{"op":"mcm","clk":"1005943380","pt":1580645588242,"mc":[{"id":"1.168224297","rc":[{"batb":[[0,1.14,166.41],[1,1.01,15.51],[2,1.14,0]],"batl":[[0,1.62,614.4],[1,1.39,0],[2,1.62,0]],"ltp":1.4,"tv":4428.97,"id":2257317},{"batb":[[0,2.7,12.9],[1,1.01,15.52],[2,1.01,0]],"batl":[[0,5.3,118.79],[1,5.3,0]],"ltp":2.12,"tv":63.96,"id":10303696}]}]}
{"op":"mcm","clk":"1005943780","pt":1580645590370,"mc":[{"id":"1.168224297","rc":[{"batb":[[0,1.15,258.34],[1,1.14,1018.06],[2,1.01,15.51]],"batl":[[0,1.58,136.27],[1,1.59,138.51]],"ltp":1.4,"tv":4428.97,"id":2257317}]}]}
{"op":"mcm","clk":"1005946311","pt":1580645603914,"mc":[{"id":"1.168224297","rc":[{"batb":[[0,1.14,166.41],[1,1.01,15.51],[2,1.01,0]],"ltp":1.4,"tv":4428.97,"id":2257317}]}]}
{"op":"mcm","clk":"1005946984","pt":1580645607208,"mc":[{"id":"1.168224297","rc":[{"batb":[[0,1.53,206.43],[1,1.52,166.44],[2,1.14,166.41]],"ltp":1.4,"tv":4428.97,"id":2257317}]}]}
{"op":"mcm","clk":"1005947090","pt":1580645607727,"mc":[{"id":"1.168224297","rc":[{"batb":[[0,1.53,241.13],[2,1.34,61.21]],"ltp":1.4,"tv":4428.97,"id":2257317},{"batb":[[1,2.3,19.83],[2,1.01,15.52]],"ltp":2.12,"tv":63.96,"id":10303696}]}]}
{"op":"mcm","clk":"1005947287","pt":1580645608737,"mc":[{"id":"1.168224297","rc":[{"batb":[[2,1.5,84.02]],"ltp":1.4,"tv":4428.97,"id":2257317},{"batl":[[0,2.98,21]],"ltp":2.12,"tv":63.96,"id":10303696}]}]}
{"op":"mcm","clk":"1005947440","pt":1580645609654,"mc":[{"id":"1.168224297","rc":[{"batl":[[2,2.04,383.01]],"ltp":1.4,"tv":4428.97,"id":2257317},{"batl":[[1,3.65,170.41]],"ltp":2.12,"tv":63.96,"id":10303696}]}]}
{"op":"mcm","clk":"1005949569","pt":1580645621374,"mc":[{"id":"1.168224297","rc":[{"trd":[[1.53,70]],"batb":[[0,1.53,34.7],[1,1.5,84.02],[2,1.34,61.21]],"batl":[[0,2.04,383.01],[1,1.59,0],[2,2.04,0]],"ltp":1.53,"tv":4429.29,"id":2257317}],"tv":4493.25}]}
{"op":"mcm","clk":"1005949777","pt":1580645622381,"mc":[{"id":"1.168224297","rc":[{"batb":[[0,1.34,61.21],[1,1.01,15.51],[2,1.34,0]],"ltp":1.53,"tv":4429.29,"id":2257317},{"batb":[[0,2.3,19.83],[1,1.01,15.52],[2,1.01,0]],"batl":[[0,3.65,170.41],[1,3.65,0]],"ltp":2.12,"tv":63.96,"id":10303696}]}]}
{"op":"mcm","clk":"1005950160","pt":1580645624356,"mc":[{"id":"1.168224297","rc":[{"batb":[[0,1.34,348.97],[1,1.33,304.69],[2,1.01,15.51]],"batl":[[0,1.76,135.43],[1,1.78,188.32],[2,2.04,383.01]],"ltp":1.53,"tv":4429.29,"id":2257317}]}]}
{"op":"mcm","clk":"1005950347","pt":1580645625263,"mc":[{"id":"1.168224297","rc":[{"batb":[[0,2.32,19.51]],"ltp":2.12,"tv":63.96,"id":10303696}]}]}
{"op":"mcm","clk":"1005951497","pt":1580645631277,"mc":[{"id":"1.168224297","rc":[{"batl":[[0,2.04,383.01],[1,1.78,0],[2,2.04,0]],"ltp":1.53,"tv":4429.29,"id":2257317}]}]}
{"op":"mcm","clk":"1005952017","pt":1580645634267,"mc":[{"id":"1.168224297","rc":[{"batl":[[0,1.38,309.36],[1,1.39,237.75]],"ltp":1.53,"tv":4429.29,"id":2257317}]}]}
{"op":"mcm","clk":"1005952198","pt":1580645635269,"mc":[{"id":"1.168224297","rc":[{"batb":[[0,1.34,472.48],[2,1.14,169.48]],"ltp":1.53,"tv":4429.29,"id":2257317},{"batb":[[0,3.6,15.66],[1,2.72,12.67],[2,1.01,15.52]],"batl":[[0,3.85,14.28]],"ltp":2.12,"tv":63.96,"id":10303696}]}]}
{"op":"mcm","clk":"1005952667","pt":1580645637977,"mc":[{"id":"1.168224297","rc":[{"batl":[[2,1.73,527.57]],"ltp":1.53,"tv":4429.29,"id":2257317},{"batl":[[1,5.3,118.79]],"ltp":2.12,"tv":63.96,"id":10303696}]}]}
{"op":"mcm","clk":"1005954104","pt":1580645646089,"mc":[{"id":"1.168224297","rc":[{"batb":[[0,1.34,123.51],[1,1.14,169.48],[2,1.01,15.51]],"batl":[[0,1.73,527.57],[1,1.39,0],[2,1.73,0]],"ltp":1.53,"tv":4429.29,"id":2257317},{"batb":[[0,2.72,12.67],[1,1.01,15.52],[2,1.01,0]],"ltp":2.12,"tv":63.96,"id":10303696}]}]}
{"op":"mcm","clk":"1005954162","pt":1580645646414,"mc":[{"id":"1.168224297","rc":[{"batb":[[0,1.14,169.48],[1,1.01,15.51],[2,1.01,0]],"ltp":1.53,"tv":4429.29,"id":2257317},{"batl":[[0,5.3,118.79],[1,5.3,0]],"ltp":2.12,"tv":63.96,"id":10303696}]}]}
{"op":"mcm","clk":"1005954569","pt":1580645648563,"mc":[{"id":"1.168224297","rc":[{"batb":[[0,1.14,1149.17]],"batl":[[0,1.58,231.54],[1,1.59,138.08]],"ltp":1.53,"tv":4429.29,"id":2257317}]}]}
{"op":"mcm","clk":"1005954928","pt":1580645650691,"mc":[{"id":"1.168224297","rc":[{"batb":[[0,1.14,169.48]],"ltp":1.53,"tv":4429.29,"id":2257317}]}]}
{"op":"mcm","clk":"1005955501","pt":1580645653898,"mc":[{"id":"1.168224297","rc":[{"batb":[[0,1.3,156.45],[1,1.29,356.39],[2,1.14,169.48]],"batl":[[0,1.33,299.55],[1,1.34,282.9]],"ltp":1.53,"tv":4429.29,"id":2257317}]}]}
{"op":"mcm","clk":"1005955720","pt":1580645655177,"mc":[{"id":"1.168224297","rc":[{"batb":[[0,1.14,169.48],[1,1.01,15.51],[2,1.14,0]],"batl":[[0,1.66,579.81],[1,1.34,0]],"ltp":1.53,"tv":4429.29,"id":2257317},{"batl":[[0,6,106.18]],"ltp":2.12,"tv":63.96,"id":10303696}]}]}
{"op":"mcm","clk":"1005956176","pt":1580645657807,"mc":[{"id":"1.168224297","rc":[{"batb":[[0,1.14,1167.28]],"batl":[[0,1.58,219.14],[1,1.59,138.06]],"ltp":1.53,"tv":4429.29,"id":2257317}]}]}
{"op":"mcm","clk":"1005957282","pt":1580645664406,"mc":[{"id":"1.168224297","rc":[{"batl":[[0,1.17,689.78],[1,1.18,412.98]],"ltp":1.53,"tv":4429.29,"id":2257317}]}]}
{"op":"mcm","clk":"1005957411","pt":1580645665304,"mc":[{"id":"1.168224297","rc":[{"batb":[[0,1.16,168.04],[1,1.14,1167.28],[2,1.1,227.71]],"ltp":1.53,"tv":4429.29,"id":2257317},{"batb":[[0,6.8,14.4],[1,5,14.16],[2,1.01,15.52]],"batl":[[0,7.2,6.72]],"ltp":2.12,"tv":63.96,"id":10303696}]}]}
{"op":"mcm","clk":"1005957549","pt":1580645666079,"mc":[{"id":"1.168224297","rc":[{"batl":[[2,1.49,761.67]],"ltp":1.53,"tv":4429.29,"id":2257317},{"batl":[[1,9.8,75.27]],"ltp":2.12,"tv":63.96,"id":10303696}]}]}
{"op":"mcm","clk":"1005959169","pt":1580645675433,"mc":[{"id":"1.168224297","rc":[{"trd":[[1.16,140]],"batb":[[0,1.16,98.04]],"ltp":1.16,"tv":4569.28,"id":2257317}],"tv":4633.24}]}
{"op":"mcm","clk":"1005959772","pt":1580645678723,"mc":[{"id":"1.168224297","rc":[{"batb":[[0,1.16,167.78]],"ltp":1.16,"tv":4569.28,"id":2257317}]}]}
{"op":"mcm","clk":"1005973044","pt":1580645753230,"mc":[{"id":"1.168224297","rc":[{"batb":[[1,1.14,169.48]],"batl":[[0,1.49,761.67],[1,1.18,0],[2,1.49,0]],"ltp":1.16,"tv":4569.28,"id":2257317}]}]}
{"op":"mcm","clk":"1005973115","pt":1580645753635,"mc":[{"id":"1.168224297","rc":[{"batb":[[1,1.1,227.71],[2,1.01,15.51]],"ltp":1.16,"tv":4569.28,"id":2257317},{"batb":[[0,5,14.16],[1,1.01,15.52],[2,1.01,0]],"ltp":2.12,"tv":63.96,"id":10303696}]}]}
{"op":"mcm","clk":"1005973292","pt":1580645754538,"mc":[{"id":"1.168224297","rc":[{"batb":[[0,1.1,227.71],[1,1.01,15.51],[2,1.01,0]],"ltp":1.16,"tv":4569.28,"id":2257317},{"batl":[[0,9.8,75.27],[1,9.8,0]],"ltp":2.12,"tv":63.96,"id":10303696}]}]}
{"op":"mcm","clk":"1005973595","pt":1580645756308,"mc":[{"id":"1.168224297","rc":[{"batb":[[0,1.11,1056.88],[1,1.1,227.71],[2,1.01,15.51]],"batl":[[0,1.24,422.14],[1,1.25,409.12],[2,1.49,761.67]],"ltp":1.16,"tv":4569.28,"id":2257317}]}]}
{"op":"mcm","clk":"1005975817","pt":1580645769058,"mc":[{"id":"1.168224297","rc":[{"batl":[[0,1.49,761.67],[1,1.25,0],[2,1.49,0]],"ltp":1.16,"tv":4569.28,"id":2257317}]}]}
{"op":"mcm","clk":"1005976375","pt":1580645772074,"mc":[{"id":"1.168224297","rc":[{"batl":[[0,1.13,390.13],[1,1.14,748.7]],"ltp":1.16,"tv":4569.28,"id":2257317}]}]}
{"op":"mcm","clk":"1005976505","pt":1580645772865,"mc":[{"id":"1.168224297","rc":[{"batb":[[2,1.08,293.72]],"ltp":1.16,"tv":4569.28,"id":2257317},{"batb":[[0,8.4,8.89],[1,6.2,16.92],[2,1.01,15.52]],"ltp":2.12,"tv":63.96,"id":10303696}]}]}
{"op":"mcm","clk":"1005976746","pt":1580645774233,"mc":[{"id":"1.168224297","rc":[{"trd":[[1.13,336.08]],"batl":[[0,1.13,222.09],[2,1.43,872.38]],"ltp":1.13,"tv":4905.36,"id":2257317},{"batl":[[0,8.8,5.04],[1,14,62.58]],"ltp":2.12,"tv":63.96,"id":10303696}],"tv":4969.32}]}
{"op":"mcm","clk":"1005977159","pt":1580645776761,"mc":[{"id":"1.168224297","rc":[{"batb":[[0,1.11,1119.78]],"batl":[[0,1.13,328.51],[1,1.14,801.22]],"ltp":1.13,"tv":4905.36,"id":2257317}]}]}
{"op":"mcm","clk":"1005978290","pt":1580645783290,"mc":[{"id":"1.168224297","rc":[{"batb":[[0,1.08,293.72],[1,1.01,15.51],[2,1.08,0]],"batl":[[0,1.43,872.38],[1,1.14,0],[2,1.43,0]],"ltp":1.13,"tv":4905.36,"id":2257317},{"batb":[[0,6.2,16.92],[1,1.01,15.52],[2,1.01,0]],"ltp":2.12,"tv":63.96,"id":10303696}]}]}
{"op":"mcm","clk":"1005978499","pt":1580645784457,"mc":[{"id":"1.168224297","rc":[{"batl":[[0,14,62.58],[1,14,0]],"ltp":2.12,"tv":63.96,"id":10303696}]}]}
{"op":"mcm","clk":"1005978756","pt":1580645786063,"mc":[{"id":"1.168224297","rc":[{"batb":[[0,1.09,1029.47],[1,1.08,293.72],[2,1.01,15.51]],"batl":[[0,1.18,253.35],[1,1.19,568.77],[2,1.43,872.38]],"ltp":1.13,"tv":4905.36,"id":2257317}]}]}
{"op":"mcm","clk":"1005979442","pt":1580645789862,"mc":[{"id":"1.168224297","rc":[{"batb":[[0,1.08,293.72],[1,1.01,15.51],[2,1.01,0]],"batl":[[0,1.43,872.38],[1,1.19,0],[2,1.43,0]],"ltp":1.13,"tv":4905.36,"id":2257317}]}]}
{"op":"mcm","clk":"1005980062","pt":1580645793178,"mc":[{"id":"1.168224297","rc":[{"batb":[[0,1.12,926.27],[1,1.11,231.48],[2,1.08,293.72]],"batl":[[0,1.14,339.96],[1,1.15,740.86],[2,1.43,872.38]],"ltp":1.13,"tv":4905.36,"id":2257317}]}]}
{"op":"mcm","clk":"1005980253","pt":1580645794196,"mc":[{"id":"1.168224297","rc":[{"batb":[[0,1.08,293.72],[1,1.01,15.51],[2,1.08,0]],"batl":[[0,1.43,872.38],[1,1.15,0],[2,1.43,0]],"ltp":1.13,"tv":4905.36,"id":2257317}]}]}
{"op":"mcm","clk":"1005980437","pt":1580645795187,"mc":[{"id":"1.168224297","rc":[{"batl":[[0,12.5,65.97]],"ltp":2.12,"tv":63.96,"id":10303696}]}]}
{"op":"mcm","clk":"1005980696","pt":1580645796909,"mc":[{"id":"1.168224297","rc":[{"batb":[[0,1.09,1029.47],[1,1.08,293.72],[2,1.01,15.51]],"batl":[[0,1.18,253.35],[1,1.19,568.77],[2,1.43,872.38]],"ltp":1.13,"tv":4905.36,"id":2257317}]}]}
{"op":"mcm","clk":"1005982013","pt":1580645804718,"mc":[{"id":"1.168224297","rc":[{"batl":[[0,1.43,872.38],[1,1.19,0],[2,1.43,0]],"ltp":1.13,"tv":4905.36,"id":2257317}]}]}
{"op":"mcm","clk":"1005982614","pt":1580645808321,"mc":[{"id":"1.168224297","rc":[{"batb":[[2,1.06,353.28]],"batl":[[0,1.11,808.58],[1,1.12,354.32],[2,1.43,872.38]],"ltp":1.13,"tv":4905.36,"id":2257317},{"batb":[[0,10,14.95],[1,8,9.76],[2,1.01,15.52]],"ltp":2.12,"tv":63.96,"id":10303696}]}]}
{"op":"mcm","clk":"1005982892","pt":1580645809975,"mc":[{"id":"1.168224297","rc":[{"batl":[[2,1.16,958.72]],"ltp":1.13,"tv":4905.36,"id":2257317},{"batl":[[0,10.5,4.2]],"ltp":2.12,"tv":63.96,"id":10303696}]}]}
{"op":"mcm","clk":"1005982964","pt":1580645810516,"mc":[{"id":"1.168224297","rc":[{"batl":[[1,17,57.33]],"ltp":2.12,"tv":63.96,"id":10303696}]}]}
{"op":"mcm","clk":"1005984623","pt":1580645820362,"mc":[{"id":"1.168224297","rc":[{"batb":[[0,1.06,353.28],[1,1.01,15.51],[2,1.06,0]],"batl":[[0,1.43,872.38],[1,1.12,0],[2,1.16,0]],"ltp":1.13,"tv":4905.36,"id":2257317},{"batb":[[0,8,9.76],[1,1.01,15.52],[2,1.01,0]],"ltp":2.12,"tv":63.96,"id":10303696}]}]}
{"op":"mcm","clk":"1005984686","pt":1580645820629,"mc":[{"id":"1.168224297","rc":[{"batl":[[0,17,57.33],[1,17,0]],"ltp":2.12,"tv":63.96,"id":10303696}]}]}
{"op":"mcm","clk":"1005984964","pt":1580645822458,"mc":[{"id":"1.168224297","rc":[{"batb":[[0,1.08,659.9],[1,1.07,543.62],[2,1.06,353.28]],"batl":[[0,1.14,723.86],[1,1.15,407.97],[2,1.43,872.38]],"ltp":1.13,"tv":4905.36,"id":2257317}]}]}
{"op":"mcm","clk":"1005986423","pt":1580645830897,"mc":[{"id":"1.168224297","rc":[{"batl":[[0,1.43,872.38],[1,1.15,0],[2,1.43,0]],"ltp":1.13,"tv":4905.36,"id":2257317}]}]}
{"op":"mcm","clk":"1005987024","pt":1580645834398,"mc":[{"id":"1.168224297","rc":[{"batl":[[0,1.09,202.93],[1,1.1,975.61],[2,1.15,348.5]],"ltp":1.13,"tv":4905.36,"id":2257317},{"batb":[[0,11.5,10.86],[1,9.8,15.26],[2,1.01,15.52]],"ltp":2.12,"tv":63.96,"id":10303696}]}]}
{"op":"mcm","clk":"1005987281","pt":1580645835890,"mc":[{"id":"1.168224297","rc":[{"trd":[[1.09,368.86]],"batb":[[1,1.07,467.73]],"batl":[[0,1.1,975.61],[1,1.15,348.5],[2,1.43,872.38]],"ltp":1.09,"tv":5274.22,"id":2257317},{"trd":[[12,3.36]],"ltp":12.0,"tv":67.32,"id":10303696}],"tv":5341.54}]}
{"op":"mcm","clk":"1005987473","pt":1580645836990,"mc":[{"id":"1.168224297","rc":[{"batl":[[0,12.5,3.36],[1,21,53.48]],"ltp":12.0,"tv":67.32,"id":10303696}]}]}
{"op":"mcm","clk":"1005987796","pt":1580645838895,"mc":[{"id":"1.168224297","rc":[{"batb":[[0,1.08,735.09]],"batl":[[0,1.1,1176.7]],"ltp":1.09,"tv":5274.22,"id":2257317}]}]}
{"op":"mcm","clk":"1005988487","pt":1580645842897,"mc":[{"id":"1.168224297","rc":[{"batb":[[0,1.07,467.73],[1,1.06,353.28],[2,1.01,15.51]],"batl":[[0,1.43,872.38],[1,1.15,0],[2,1.43,0]],"ltp":1.09,"tv":5274.22,"id":2257317},{"batb":[[0,9.8,15.26],[1,1.01,15.52],[2,1.01,0]],"ltp":12.0,"tv":67.32,"id":10303696}]}]}
{"op":"mcm","clk":"1005988755","pt":1580645844599,"mc":[{"id":"1.168224297","rc":[{"batl":[[0,21,53.48],[1,21,0]],"ltp":12.0,"tv":67.32,"id":10303696}]}]}
{"op":"mcm","clk":"1005988913","pt":1580645845502,"mc":[{"id":"1.168224297","rc":[{"batb":[[0,1.07,1209.69]],"batl":[[0,1.11,848.27],[1,1.12,314.98],[2,1.43,872.38]],"ltp":1.09,"tv":5274.22,"id":2257317}]}]}
{"op":"mcm","clk":"1005989899","pt":1580645851572,"mc":[{"id":"1.168224297","rc":[{"batb":[[0,1.06,353.28],[1,1.01,15.51],[2,1.01,0]],"batl":[[0,1.11,180.41],[1,1.43,872.38],[2,1.43,0]],"ltp":1.09,"tv":5274.22,"id":2257317}]}]}
{"op":"mcm","clk":"1005990503","pt":1580645855076,"mc":[{"id":"1.168224297","rc":[{"batb":[[0,1.08,1109.1],[1,1.06,353.28],[2,1.01,15.51]],"batl":[[0,1.1,994.65],[1,1.11,180.41],[2,1.43,872.38]],"ltp":1.09,"tv":5274.22,"id":2257317}]}]}
{"op":"mcm","clk":"1005991051","pt":1580645858098,"mc":[{"id":"1.168224297","rc":[{"batb":[[0,1.06,353.28],[1,1.01,15.51],[2,1.01,0]],"batl":[[0,1.11,180.41],[1,1.43,872.38],[2,1.43,0]],"ltp":1.09,"tv":5274.22,"id":2257317}]}]}
{"op":"mcm","clk":"1005991541","pt":1580645861101,"mc":[{"id":"1.168224297","rc":[{"batb":[[0,1.07,1209.69],[1,1.06,353.28],[2,1.01,15.51]],"batl":[[0,1.11,836.86],[1,1.12,326.3],[2,1.43,872.38]],"ltp":1.09,"tv":5274.22,"id":2257317}]}]}
{"op":"mcm","clk":"1005992415","pt":1580645866114,"mc":[{"id":"1.168224297","rc":[{"batl":[[0,1.43,872.38],[1,1.12,0],[2,1.43,0]],"ltp":1.09,"tv":5274.22,"id":2257317}]}]}
{"op":"mcm","clk":"1005992800","pt":1580645868391,"mc":[{"id":"1.168224297","rc":[{"batl":[[0,1.09,979.51],[1,1.1,206.09]],"ltp":1.09,"tv":5274.22,"id":2257317}]}]}
{"op":"mcm","clk":"1005992984","pt":1580645869405,"mc":[{"id":"1.168224297","rc":[{"batb":[[2,1.04,536.06]],"batl":[[2,1.15,1185.9]],"ltp":1.09,"tv":5274.22,"id":2257317},{"batb":[[0,12,9.05],[1,10.5,12.43],[2,1.01,15.52]],"ltp":12.0,"tv":67.32,"id":10303696}]}]}
{"op":"mcm","clk":"1005993004","pt":1580645869508,"mc":[{"id":"1.168224297","rc":[{"batb":[[0,1.08,168.04],[1,1.07,1209.69],[2,1.06,353.28]],"ltp":1.09,"tv":5274.22,"id":2257317},{"batl":[[0,13.5,3.36]],"ltp":12.0,"tv":67.32,"id":10303696}]}]}
{"op":"mcm","clk":"1005993453","pt":1580645872136,"mc":[{"id":"1.168224297","rc":[{"batl":[[1,24,50.52]],"ltp":12.0,"tv":67.32,"id":10303696}]}]}
{"op":"mcm","clk":"1005993621","pt":1580645873141,"mc":[{"id":"1.168224297","rc":[{"trd":[[1.09,497.85]],"batl":[[0,1.09,915]],"ltp":1.09,"tv":5403.21,"id":2257317}],"tv":5470.53}]}
{"op":"mcm","clk":"1005994112","pt":1580645876120,"mc":[{"id":"1.168224297","rc":[{"batl":[[0,1.09,955.86]],"ltp":1.09,"tv":5403.21,"id":2257317}]}]}
{"op":"mcm","clk":"1005995319","pt":1580645882947,"mc":[{"id":"1.168224297","rc":[{"batl":[[0,1.09,995.46]],"ltp":1.09,"tv":5403.21,"id":2257317}]}]}
{"op":"mcm","clk":"1005996069","pt":1580645887160,"mc":[{"id":"1.168224297","rc":[{"batb":[[1,1.04,536.06],[2,1.01,15.51]],"batl":[[0,1.1,206.09],[1,1.37,1010.69],[2,1.15,0]],"ltp":1.09,"tv":5403.21,"id":2257317},{"batb":[[0,10.5,12.43],[1,1.01,15.52],[2,1.01,0]],"ltp":12.0,"tv":67.32,"id":10303696}]}]}
{"op":"mcm","clk":"1005996348","pt":1580645888751,"mc":[{"id":"1.168224297","rc":[{"batb":[[0,1.04,536.06],[1,1.01,15.51],[2,1.01,0]],"ltp":1.09,"tv":5403.21,"id":2257317},{"batl":[[0,24,50.52],[1,24,0]],"ltp":12.0,"tv":67.32,"id":10303696}]}]}
{"op":"mcm","clk":"1005996512","pt":1580645889649,"mc":[{"id":"1.168224297","rc":[{"batb":[[0,1.05,1232.73],[1,1.04,536.06],[2,1.01,15.51]],"batl":[[0,1.1,301.04],[1,1.11,867.76],[2,1.37,1010.69]],"ltp":1.09,"tv":5403.21,"id":2257317}]}]}
{"op":"mcm","clk":"1005997979","pt":1580645897166,"mc":[{"id":"1.168224297","rc":[{"batb":[[0,1.04,536.06],[1,1.01,15.51],[2,1.01,0]],"ltp":1.09,"tv":5403.21,"id":2257317}]}]}
{"op":"mcm","clk":"1005998527","pt":1580645900255,"mc":[{"id":"1.168224297","rc":[{"batb":[[0,1.09,377.09],[1,1.08,817.9],[2,1.04,536.06]],"ltp":1.09,"tv":5403.21,"id":2257317}]}]}
{"op":"mcm","clk":"1005998686","pt":1580645901155,"mc":[{"id":"1.168224297","rc":[{"batb":[[2,1.07,326.69]],"ltp":1.09,"tv":5403.21,"id":2257317},{"batb":[[1,9.8,15.5],[2,1.01,15.52]],"ltp":12.0,"tv":67.32,"id":10303696}]}]}
{"op":"mcm","clk":"1005999229","pt":1580645904317,"mc":[{"id":"1.168224297","rc":[{"batl":[[0,17,57.33]],"ltp":12.0,"tv":67.32,"id":10303696}]}]}
{"op":"mcm","clk":"1005999727","pt":1580645907346,"mc":[{"id":"1.168224297","rc":[{"batb":[[0,1.07,326.69],[1,1.06,406.86],[2,1.01,15.51]],"batl":[[0,1.37,1010.69],[1,1.11,0],[2,1.37,0]],"ltp":1.09,"tv":5403.21,"id":2257317}]}]}
{"op":"mcm","clk":"1005999792","pt":1580645907721,"mc":[{"id":"1.168224297","rc":[{"batb":[[0,1.06,406.86],[1,1.01,15.51],[2,1.01,0]],"ltp":1.09,"tv":5403.21,"id":2257317},{"batb":[[0,9.8,15.5],[1,1.01,15.52],[2,1.01,0]],"ltp":12.0,"tv":67.32,"id":10303696}]}]}
{"op":"mcm","clk":"1006000233","pt":1580645910225,"mc":[{"id":"1.168224297","rc":[{"batb":[[0,1.07,1012.16],[1,1.06,606.25],[2,1.01,15.51]],"batl":[[0,1.12,936.39],[1,1.13,217.35],[2,1.37,1010.69]],"ltp":1.09,"tv":5403.21,"id":2257317}]}]}
{"op":"mcm","clk":"1006000430","pt":1580645911339,"mc":[{"id":"1.168224297","rc":[{"batl":[[0,1.37,1010.69],[1,1.13,0],[2,1.37,0]],"ltp":1.09,"tv":5403.21,"id":2257317}]}]}
{"op":"mcm","clk":"1006000913","pt":1580645914335,"mc":[{"id":"1.168224297","rc":[{"batl":[[0,1.09,1187.49],[1,1.37,1010.69]],"ltp":1.09,"tv":5403.21,"id":2257317}]}]}
{"op":"mcm","clk":"1006001073","pt":1580645915129,"mc":[{"id":"1.168224297","rc":[{"batb":[[2,1.03,600.42]],"ltp":1.09,"tv":5403.21,"id":2257317},{"batb":[[0,12.5,8.5],[1,10.5,12.43],[2,1.01,15.52]],"ltp":12.0,"tv":67.32,"id":10303696}]}]}
{"op":"mcm","clk":"1006001152","pt":1580645915654,"mc":[{"id":"1.168224297","rc":[{"batb":[[0,1.08,168.04],[1,1.07,1012.16],[2,1.06,606.25]],"ltp":1.09,"tv":5403.21,"id":2257317}]}]}
{"op":"mcm","clk":"1006001522","pt":1580645917746,"mc":[{"id":"1.168224297","rc":[{"batl":[[1,1.15,1226.7],[2,1.37,1010.69]],"ltp":1.09,"tv":5403.21,"id":2257317}]}]}
{"op":"mcm","clk":"1006001622","pt":1580645918426,"mc":[{"id":"1.168224297","rc":[{"batl":[[0,24,50.52]],"ltp":12.0,"tv":67.32,"id":10303696}]}]}
{"op":"mcm","clk":"1006002419","pt":1580645923164,"mc":[{"id":"1.168224297","rc":[{"batb":[[1,1.03,600.42],[2,1.01,15.51]],"batl":[[0,1.37,1010.69],[1,1.15,0],[2,1.37,0]],"ltp":1.09,"tv":5403.21,"id":2257317},{"batb":[[0,10.5,12.43],[1,1.01,15.52],[2,1.01,0]],"ltp":12.0,"tv":67.32,"id":10303696}]}]}
{"op":"mcm","clk":"1006002692","pt":1580645924748,"mc":[{"id":"1.168224297","rc":[{"batb":[[0,1.03,600.42],[1,1.01,15.51],[2,1.01,0]],"ltp":1.09,"tv":5403.21,"id":2257317}]}]}
{"op":"mcm","clk":"1006002826","pt":1580645925693,"mc":[{"id":"1.168224297","rc":[{"batb":[[0,1.05,826.65],[1,1.04,409.98],[2,1.03,600.42]],"batl":[[0,1.1,317.04],[1,1.11,851.91],[2,1.37,1010.69]],"ltp":1.09,"tv":5403.21,"id":2257317}]}]}
{"op":"mcm","clk":"1006003285","pt":1580645928264,"mc":[{"id":"1.168224297","rc":[{"batb":[[0,1.03,600.42],[1,1.01,15.51],[2,1.03,0]],"batl":[[0,1.37,1010.69],[1,1.11,0],[2,1.37,0]],"ltp":1.09,"tv":5403.21,"id":2257317}]}]}
{"op":"mcm","clk":"1006004038","pt":1580645932590,"mc":[{"id":"1.168224297","rc":[{"batb":[[0,1.05,835.18],[1,1.04,401.37],[2,1.03,600.42]],"batl":[[0,1.1,308.92],[1,1.11,859.96],[2,1.37,1010.69]],"ltp":1.09,"tv":5403.21,"id":2257317}]}]}
{"op":"mcm","clk":"1006005412","pt":1580645941039,"mc":[{"id":"1.168224297","rc":[{"batl":[[0,1.37,1010.69],[1,1.11,0],[2,1.37,0]],"ltp":1.09,"tv":5403.21,"id":2257317}]}]}
{"op":"mcm","clk":"1006005985","pt":1580645944372,"mc":[{"id":"1.168224297","rc":[{"batl":[[0,1.06,825.33],[1,1.07,392.07],[2,1.37,1010.69]],"ltp":1.09,"tv":5403.21,"id":2257317},{"batb":[[0,17,4.33],[1,13,7.95],[2,10.5,12.43]],"ltp":12.0,"tv":67.32,"id":10303696}]}]}
{"op":"mcm","clk":"1006006046","pt":1580645944668,"mc":[{"id":"1.168224297","rc":[{"batb":[[2,1.01,15.52]],"ltp":12.0,"tv":67.32,"id":10303696}]}]}
{"op":"mcm","clk":"1006006421","pt":1580645946635,"mc":[{"id":"1.168224297","rc":[{"batl":[[0,42,43.68]],"ltp":12.0,"tv":67.32,"id":10303696}]}]}
{"op":"mcm","clk":"1006007328","pt":1580645952066,"mc":[{"id":"1.168224297","rc":[{"batb":[[0,1.01,15.51],[1,1.04,0],[2,1.03,0]],"batl":[[0,1.37,1010.69],[1,1.07,0],[2,1.37,0]],"ltp":1.09,"tv":5403.21,"id":2257317},{"batb":[[0,13,7.95],[1,1.01,15.52],[2,1.01,0]],"ltp":12.0,"tv":67.32,"id":10303696}]}]}
{"op":"mcm","clk":"1006007904","pt":1580645955392,"mc":[{"id":"1.168224297","rc":[{"batb":[[0,1.02,1268.99],[1,1.01,15.51]],"batl":[[0,1.08,491.75],[1,1.09,700.25]],"ltp":1.09,"tv":5403.21,"id":2257317}]}]}
{"op":"mcm","clk":"1006008044","pt":1580645956193,"mc":[{"id":"1.168224297","rc":[{"batb":[[0,1.01,15.51],[1,1.01,0]],"ltp":1.09,"tv":5403.21,"id":2257317}]}]}
{"op":"mcm","clk":"1006009023","pt":1580645962072,"mc":[{"id":"1.168224297","rc":[{"batb":[[0,1.02,1268.99],[1,1.01,15.51]],"batl":[[0,1.08,491.75],[1,1.09,700.25]],"ltp":1.09,"tv":5403.21,"id":2257317}]}]}
{"op":"mcm","clk":"1006009230","pt":1580645963375,"mc":[{"id":"1.168224297","rc":[{"batb":[[0,1.01,15.51],[1,1.01,0]],"ltp":1.09,"tv":5403.21,"id":2257317}]}]}
{"op":"mcm","clk":"1006009694","pt":1580645966275,"mc":[{"id":"1.168224297","rc":[{"batb":[[0,1.07,543.59],[1,1.06,672.38],[2,1.01,15.51]],"ltp":1.09,"tv":5403.21,"id":2257317}]}]}
{"op":"mcm","clk":"1006009827","pt":1580645967008,"mc":[{"id":"1.168224297","rc":[{"batb":[[2,1.05,423.15]],"ltp":1.09,"tv":5403.21,"id":2257317},{"batb":[[1,10,13.38],[2,1.01,15.52]],"ltp":12.0,"tv":67.32,"id":10303696}]}]}
{"op":"mcm","clk":"1006010102","pt":1580645968806,"mc":[{"id":"1.168224297","rc":[{"batl":[[2,1.37,1010.69]],"ltp":1.09,"tv":5403.21,"id":2257317},{"batl":[[0,24,50.52]],"ltp":12.0,"tv":67.32,"id":10303696}]}]}
{"op":"mcm","clk":"1006011820","pt":1580645979406,"mc":[{"id":"1.168224297","rc":[{"batb":[[0,1.05,423.15],[1,1.03,738.27],[2,1.01,15.51]],"batl":[[0,1.37,1010.69],[1,1.09,0],[2,1.37,0]],"ltp":1.09,"tv":5403.21,"id":2257317}]}]}
{"op":"mcm","clk":"1006011862","pt":1580645979739,"mc":[{"id":"1.168224297","rc":[{"batb":[[0,1.03,738.27],[1,1.01,15.51],[2,1.01,0]],"ltp":1.09,"tv":5403.21,"id":2257317},{"batb":[[0,10,13.38],[1,1.01,15.52],[2,1.01,0]],"ltp":12.0,"tv":67.32,"id":10303696}]}]}
{"op":"mcm","clk":"1006012319","pt":1580645982318,"mc":[{"id":"1.168224297","rc":[{"batb":[[0,1.04,1229.44],[1,1.03,738.27],[2,1.01,15.51]],"batl":[[0,1.11,1031.75],[1,1.37,1010.69]],"ltp":1.09,"tv":5403.21,"id":2257317}]}]}
{"op":"mcm","clk":"1006014685","pt":1580645996534,"mc":[{"id":"1.168224297","rc":[{"batl":[[0,1.37,1010.69],[1,1.37,0]],"ltp":1.09,"tv":5403.21,"id":2257317}]}]}
{"op":"mcm","clk":"1006015315","pt":1580646000235,"mc":[{"id":"1.168224297","rc":[{"batl":[[0,1.05,983.72],[1,1.06,246.65],[2,1.37,1010.69]],"ltp":1.09,"tv":5403.21,"id":2257317},{"batb":[[0,19.5,6.29],[1,13,7.95],[2,10,13.38]],"ltp":12.0,"tv":67.32,"id":10303696}]}]}
{"op":"mcm","clk":"1006015392","pt":1580646000661,"mc":[{"id":"1.168224297","rc":[{"batb":[[2,1.01,15.52]],"ltp":12.0,"tv":67.32,"id":10303696}]}]}
{"op":"mcm","clk":"1006015690","pt":1580646002234,"mc":[{"id":"1.168224297","rc":[{"batl":[[0,65,40.67]],"ltp":12.0,"tv":67.32,"id":10303696}]}]}
{"op":"mcm","clk":"1006017452","pt":1580646012240,"mc":[{"id":"1.168224297","rc":[{"batb":[[0,1.01,15.51],[1,1.03,0],[2,1.01,0]],"batl":[[0,1.37,1010.69],[1,1.06,0],[2,1.37,0]],"ltp":1.09,"tv":5403.21,"id":2257317},{"batb":[[0,13,7.95],[1,1.01,15.52],[2,1.01,0]],"ltp":12.0,"tv":67.32,"id":10303696}]}]}
{"op":"mcm","clk":"1006017926","pt":1580646014621,"mc":[{"id":"1.168224297","rc":[{"batl":[[0,1.08,590.21],[1,1.09,602.69]],"ltp":1.09,"tv":5403.21,"id":2257317}]}]}
{"op":"mcm","clk":"1006019361","pt":1580646022364,"mc":[{"id":"1.168224297","rc":[{"batb":[[0,1.07,431.98],[1,1.06,785.04],[2,1.01,15.51]],"ltp":1.09,"tv":5403.21,"id":2257317}]}]}
{"op":"mcm","clk":"1006019441","pt":1580646022739,"mc":[{"id":"1.168224297","rc":[{"batb":[[2,1.05,422.76]],"ltp":1.09,"tv":5403.21,"id":2257317},{"batb":[[1,10.5,13.06],[2,1.01,15.52]],"ltp":12.0,"tv":67.32,"id":10303696}]}]}
{"op":"mcm","clk":"1006019802","pt":1580646024532,"mc":[{"id":"1.168224297","rc":[{"batl":[[2,1.37,1010.69]],"ltp":1.09,"tv":5403.21,"id":2257317},{"batl":[[0,24,50.52]],"ltp":12.0,"tv":67.32,"id":10303696}]}]}
{"op":"mcm","clk":"1006021642","pt":1580646035252,"mc":[{"id":"1.168224297","rc":[{"batb":[[0,1.03,745.04],[1,1.01,15.51],[2,1.05,0]],"batl":[[0,1.37,1010.69],[1,1.09,0],[2,1.37,0]],"ltp":1.09,"tv":5403.21,"id":2257317},{"batb":[[0,10.5,13.06],[1,1.01,15.52],[2,1.01,0]],"ltp":12.0,"tv":67.32,"id":10303696}]}]}
{"op":"mcm","clk":"1006022188","pt":1580646038161,"mc":[{"id":"1.168224297","rc":[{"batb":[[0,1.04,1097.35],[1,1.03,745.04],[2,1.01,15.51]],"batl":[[0,1.11,1113.96],[1,1.37,1010.69]],"ltp":1.09,"tv":5403.21,"id":2257317}]}]}
{"op":"mcm","clk":"1006022622","pt":1580646040666,"mc":[{"id":"1.168224297","rc":[{"batl":[[0,1.37,1010.69],[1,1.37,0]],"ltp":1.09,"tv":5403.21,"id":2257317}]}]}
{"op":"mcm","clk":"1006023316","pt":1580646044395,"mc":[{"id":"1.168224297","rc":[{"batl":[[0,1.05,1090.21],[1,1.37,1010.69]],"ltp":1.09,"tv":5403.21,"id":2257317},{"batb":[[0,19.5,6.22],[1,13,8.1],[2,1.01,15.52]],"ltp":12.0,"tv":67.32,"id":10303696}]}]}
{"op":"mcm","clk":"1006023702","pt":1580646046626,"mc":[{"id":"1.168224297","rc":[{"batl":[[0,65,40.67]],"ltp":12.0,"tv":67.32,"id":10303696}]}]}
{"op":"mcm","clk":"1006024483","pt":1580646051367,"mc":[{"id":"1.168224297","rc":[{"batb":[[0,1.03,745.04],[1,1.01,15.51],[2,1.01,0]],"batl":[[0,1.37,1010.69],[1,1.37,0]],"ltp":1.09,"tv":5403.21,"id":2257317}]}]}
{"op":"mcm","clk":"1006024622","pt":1580646052284,"mc":[{"id":"1.168224297","rc":[{"batb":[[0,1.01,15.51],[1,1.01,0]],"ltp":1.09,"tv":5403.21,"id":2257317},{"batb":[[0,13,8.1],[1,1.01,15.52],[2,1.01,0]],"ltp":12.0,"tv":67.32,"id":10303696}]}]}
{"op":"mcm","clk":"1006024977","pt":1580646054220,"mc":[{"id":"1.168224297","rc":[{"batl":[[0,1.08,685.97],[1,1.09,507.81]],"ltp":1.09,"tv":5403.21,"id":2257317}]}]}
{"op":"mcm","clk":"1006025885","pt":1580646059360,"mc":[{"id":"1.168224297","rc":[{"batb":[[0,1.03,1256.67],[1,1.01,15.51]],"batl":[[0,1.04,649.27],[1,1.05,589.64]],"ltp":1.09,"tv":5403.21,"id":2257317}]}]}
{"op":"mcm","clk":"1006025972","pt":1580646059886,"mc":[{"id":"1.168224297","rc":[{"batb":[[0,1.01,15.51],[1,1.01,0]],"ltp":1.09,"tv":5403.21,"id":2257317}]}]}
{"op":"mcm","clk":"1006026429","pt":1580646062282,"mc":[{"id":"1.168224297","rc":[{"batl":[[0,1.08,685.97],[1,1.09,507.81]],"ltp":1.09,"tv":5403.21,"id":2257317}]}]}
{"op":"mcm","clk":"1006028263","pt":1580646072306,"mc":[{"id":"1.168224297","rc":[{"batb":[[0,1.07,324.7],[1,1.06,893.34],[2,1.01,15.51]],"ltp":1.09,"tv":5403.21,"id":2257317}]}]}
{"op":"mcm","clk":"1006028361","pt":1580646072879,"mc":[{"id":"1.168224297","rc":[{"batb":[[2,1.05,419.69]],"ltp":1.09,"tv":5403.21,"id":2257317},{"batb":[[1,10.5,13.14],[2,1.01,15.52]],"ltp":12.0,"tv":67.32,"id":10303696}]}]}
{"op":"mcm","clk":"1006028532","pt":1580646073887,"mc":[{"id":"1.168224297","rc":[{"batl":[[2,1.37,1010.69]],"ltp":1.09,"tv":5403.21,"id":2257317},{"batl":[[0,24,50.52]],"ltp":12.0,"tv":67.32,"id":10303696}]}]}
{"op":"mcm","clk":"1006030611","pt":1580646085059,"mc":[{"id":"1.168224297","rc":[{"batb":[[0,1.03,745.98],[1,1.01,15.51],[2,1.05,0]],"batl":[[0,1.37,1010.69],[1,1.09,0],[2,1.37,0]],"ltp":1.09,"tv":5403.21,"id":2257317},{"batb":[[0,10.5,13.14],[1,1.01,15.52],[2,1.01,0]],"ltp":12.0,"tv":67.32,"id":10303696}]}]}
{"op":"mcm","clk":"1006031114","pt":1580646087743,"mc":[{"id":"1.168224297","rc":[{"batb":[[0,1.04,970.21],[1,1.03,1023.01],[2,1.01,15.51]],"batl":[[0,1.11,1166.1],[1,1.37,1010.69]],"ltp":1.09,"tv":5403.21,"id":2257317}]}]}
{"op":"mcm","clk":"1006032029","pt":1580646092823,"mc":[{"id":"1.168224297","rc":[{"batl":[[0,1.37,1010.69],[1,1.37,0]],"ltp":1.09,"tv":5403.21,"id":2257317}]}]}
{"op":"mcm","clk":"1006032656","pt":1580646096330,"mc":[{"id":"1.168224297","rc":[{"batl":[[0,1.05,1192.52],[1,1.37,1010.69]],"ltp":1.09,"tv":5403.21,"id":2257317},{"batb":[[0,19.5,6.14],[1,13,8.03],[2,10.5,13.14]],"ltp":12.0,"tv":67.32,"id":10303696}]}]}
{"op":"mcm","clk":"1006032714","pt":1580646096650,"mc":[{"id":"1.168224297","rc":[{"batb":[[2,1.01,15.52]],"ltp":12.0,"tv":67.32,"id":10303696}]}]}
{"op":"mcm","clk":"1006033154","pt":1580646099128,"mc":[{"id":"1.168224297","rc":[{"batl":[[0,65,40.67]],"ltp":12.0,"tv":67.32,"id":10303696}]}]}
{"op":"mcm","clk":"1006034484","pt":1580646106266,"mc":[{"id":"1.168224297","rc":[{"batb":[[0,1.01,15.51],[1,1.03,0],[2,1.01,0]],"batl":[[0,1.37,1010.69],[1,1.37,0]],"ltp":1.09,"tv":5403.21,"id":2257317},{"batb":[[0,13,8.03],[1,1.01,15.52],[2,1.01,0]],"ltp":12.0,"tv":67.32,"id":10303696}]}]}
{"op":"mcm","clk":"1006035097","pt":1580646109232,"mc":[{"id":"1.168224297","rc":[{"batl":[[0,1.08,778.66],[1,1.09,415.98]],"ltp":1.09,"tv":5403.21,"id":2257317}]}]}
{"op":"mcm","clk":"1006038432","pt":1580646127577,"mc":[{"id":"1.168224297","rc":[{"batb":[[0,1.04,22],[1,1.01,15.51]],"ltp":1.09,"tv":5403.21,"id":2257317}]}]}
{"op":"mcm","clk":"1006039778","pt":1580646135304,"mc":[{"id":"1.168224297","rc":[{"trd":[[1.01,31.02],[1.04,44]],"batl":[[0,1.01,1244.04]],"ltp":1.01,"tv":5478.22,"id":2257317}],"tv":5545.55}]}
{"op":"mcm","clk":"1006039935","pt":1580646136119,"mc":[{"id":"1.168224297","rc":[{"batb":[[0,30,2.44]],"ltp":12.0,"tv":67.32,"id":10303696}]}]}
{"op":"mcm","clk":"1006040315","pt":1580646138320,"mc":[{"id":"1.168224297","rc":[{"batl":[[0,1.01,1281.55],[1,1.28,1345.7]],"ltp":1.01,"tv":5478.22,"id":2257317}]}]}
{"op":"mcm","clk":"1006041822","pt":1580646146865,"mc":[{"id":"1.168224297","rc":[{"batl":[[0,1.01,1320.67]],"ltp":1.01,"tv":5478.22,"id":2257317}]}]}
{"op":"mcm","clk":"1006054952","pt":1580646222400,"mc":[{"id":"1.168224297","rc":[{"batl":[[0,1.01,39.12]],"ltp":1.01,"tv":5478.22,"id":2257317}]}]}
{"op":"mcm","clk":"1006055289","pt":1580646224298,"mc":[{"id":"1.168224297","rc":[{"batl":[[1,1.28,0]],"ltp":1.01,"tv":5478.22,"id":2257317}]}]}
{"op":"mcm","clk":"1006055448","pt":1580646225212,"mc":[{"id":"1.168224297","rc":[{"batl":[[1,1.02,1268.99]],"ltp":1.01,"tv":5478.22,"id":2257317}]}]}
{"op":"mcm","clk":"1006058169","pt":1580646241020,"mc":[{"id":"1.168224297","rc":[{"batl":[[1,1.02,0]],"ltp":1.01,"tv":5478.22,"id":2257317}]}]}
{"op":"mcm","clk":"1006058232","pt":1580646241449,"mc":[{"id":"1.168224297","rc":[{"batb":[[0,1.01,15.52],[1,1.01,0]],"ltp":12.0,"tv":67.32,"id":10303696}]}]}
{"op":"mcm","clk":"1006058761","pt":1580646244058,"mc":[{"id":"1.168224297","rc":[{"batl":[[0,1.01,1320.67]],"ltp":1.01,"tv":5478.22,"id":2257317}]}]}
{"op":"mcm","clk":"1006059073","pt":1580646245871,"mc":[{"id":"1.168224297","rc":[{"batl":[[0,1.01,1362.68]],"ltp":1.01,"tv":5478.22,"id":2257317}]}]}
{"op":"mcm","clk":"1006059187","pt":1580646246560,"mc":[{"id":"1.168224297","rc":[{"batl":[[1,1.27,1384.57]],"ltp":1.01,"tv":5478.22,"id":2257317}]}]}
{"op":"mcm","clk":"1006060595","pt":1580646255456,"mc":[{"id":"1.168224297","rc":[{"batl":[[0,1.01,81.13]],"ltp":1.01,"tv":5478.22,"id":2257317}]}]}
{"op":"mcm","clk":"1006060800","pt":1580646256762,"mc":[{"id":"1.168224297","rc":[{"batl":[[0,1.01,39.12]],"ltp":1.01,"tv":5478.22,"id":2257317}]}]}
{"op":"mcm","clk":"1006060964","pt":1580646257697,"mc":[{"id":"1.168224297","rc":[{"batl":[[1,1.27,0]],"ltp":1.01,"tv":5478.22,"id":2257317}]}]}
{"op":"mcm","clk":"1006061106","pt":1580646258496,"mc":[{"id":"1.168224297","rc":[{"batl":[[1,1.02,1268.99]],"ltp":1.01,"tv":5478.22,"id":2257317}]}]}
{"op":"mcm","clk":"1006061926","pt":1580646263301,"mc":[{"id":"1.168224297","rc":[{"batl":[[1,1.02,0]],"ltp":1.01,"tv":5478.22,"id":2257317}]}]}
{"op":"mcm","clk":"1006062419","pt":1580646266307,"mc":[{"id":"1.168224297","rc":[{"batl":[[0,1.01,1320.67]],"ltp":1.01,"tv":5478.22,"id":2257317}]}]}
{"op":"mcm","clk":"1006062457","pt":1580646266512,"mc":[{"id":"1.168224297","rc":[{"batl":[[0,1.01,39.12]],"ltp":1.01,"tv":5478.22,"id":2257317}]}]}
{"op":"mcm","clk":"1006062867","pt":1580646268905,"mc":[{"id":"1.168224297","rc":[{"batl":[[1,1.02,1268.99]],"ltp":1.01,"tv":5478.22,"id":2257317}]}]}
{"op":"mcm","clk":"1006064382","pt":1580646277838,"mc":[{"id":"1.168224297","rc":[{"trd":[[1.01,108.28]],"batl":[[0,1.02,1269.5],[1,1.02,0]],"ltp":1.01,"tv":5555.48,"id":2257317}],"tv":5622.81}]}
{"op":"mcm","clk":"1006064568","pt":1580646278826,"mc":[{"id":"1.168224297","rc":[{"batl":[[1,1.28,1345.7]],"ltp":1.01,"tv":5555.48,"id":2257317}]}]}
{"op":"mcm","clk":"1006065714","pt":1580646285320,"mc":[{"id":"1.168224297","rc":[{"batl":[[0,1.28,1346.2],[1,1.28,0]],"ltp":1.01,"tv":5555.48,"id":2257317}]}]}
{"op":"mcm","clk":"1006066237","pt":1580646288319,"mc":[{"id":"1.168224297","rc":[{"batl":[[0,1.03,1257.18]],"ltp":1.01,"tv":5555.48,"id":2257317}]}]}
{"op":"mcm","clk":"1006066875","pt":1580646291952,"mc":[{"id":"1.168224297","rc":[{"batl":[[0,1.01,0.51]],"ltp":1.01,"tv":5555.48,"id":2257317}]}]}
{"op":"mcm","clk":"1006067469","pt":1580646295122,"mc":[{"id":"1.168224297","rc":[{"trd":[[1.01,109.29]],"ltp":1.01,"tv":5556.5,"id":2257317}],"tv":5623.82}]}
{"op":"mcm","clk":"1006067880","pt":1580646297270,"mc":[{"id":"1.168224297","rc":[{"batl":[[0,1.03,1256.67],[1,1.28,1326.22]],"ltp":1.01,"tv":5556.5,"id":2257317}]}]}
{"op":"mcm","clk":"1006067935","pt":1580646297546,"mc":[{"id":"1.168224297","rc":[{"batl":[[1,1.28,0]],"ltp":1.01,"tv":5556.5,"id":2257317}]}]}
{"op":"mcm","clk":"1006070132","pt":1580646309878,"mc":[{"id":"1.168224297","rc":[{"batl":[[0,1.01,1323.56]],"ltp":1.01,"tv":5556.5,"id":2257317}]}]}
{"op":"mcm","clk":"1006070517","pt":1580646311988,"mc":[{"id":"1.168224297","rc":[{"batl":[[1,1.27,1384.57]],"ltp":1.01,"tv":5556.5,"id":2257317}]}]}
{"op":"mcm","clk":"1006071887","pt":1580646319776,"mc":[{"id":"1.168224297","rc":[{"batl":[[0,1.01,42.01]],"ltp":1.01,"tv":5556.5,"id":2257317}]}]}
{"op":"mcm","clk":"1006072106","pt":1580646320897,"mc":[{"id":"1.168224297","rc":[{"batl":[[0,1.27,1384.57],[1,1.27,0]],"ltp":1.01,"tv":5556.5,"id":2257317}]}]}
{"op":"mcm","clk":"1006072461","pt":1580646322801,"mc":[{"id":"1.168224297","rc":[{"batl":[[0,1.02,1268.99]],"ltp":1.01,"tv":5556.5,"id":2257317}]}]}
{"op":"mcm","clk":"1006073638","pt":1580646329582,"mc":[{"id":"1.168224297","rc":[{"batl":[[0,1.01,1281.55]],"ltp":1.01,"tv":5556.5,"id":2257317}]}]}
{"op":"mcm","clk":"1006074491","pt":1580646334923,"mc":[{"id":"1.168224297","rc":[{"batl":[[0,1.02,1268.99]],"ltp":1.01,"tv":5556.5,"id":2257317}]}]}
{"op":"mcm","clk":"1006076249","pt":1580646345116,"mc":[{"id":"1.168224297","rc":[{"batb":[[0,1.01,1281.55]],"ltp":1.01,"tv":5556.5,"id":2257317}]}]}
{"op":"mcm","clk":"1006076369","pt":1580646345849,"mc":[{"id":"1.168224297","rc":[{"batl":[[0,1.02,1311]],"ltp":1.01,"tv":5556.5,"id":2257317},{"batb":[[0,27,3.38],[1,1.01,15.52]],"ltp":12.0,"tv":67.32,"id":10303696}]}]}
{"op":"mcm","clk":"1006076607","pt":1580646347535,"mc":[{"id":"1.168224297","rc":[{"batl":[[1,1.28,1326.22]],"ltp":1.01,"tv":5556.5,"id":2257317}]}]}
{"op":"mcm","clk":"1006078120","pt":1580646357145,"mc":[{"id":"1.168224297","rc":[{"batl":[[0,1.02,1352]],"ltp":1.01,"tv":5556.5,"id":2257317}]}]}
{"op":"mcm","clk":"1006079340","pt":1580646364651,"mc":[{"id":"1.168224297","rc":[{"batl":[[0,1.02,1311]],"ltp":1.01,"tv":5556.5,"id":2257317}]}]}
{"op":"mcm","clk":"1006079547","pt":1580646365964,"mc":[{"id":"1.168224297","rc":[{"batl":[[0,1.02,42.01]],"ltp":1.01,"tv":5556.5,"id":2257317}]}]}
{"op":"mcm","clk":"1006079717","pt":1580646366864,"mc":[{"id":"1.168224297","rc":[{"batl":[[0,1.28,1326.22],[1,1.28,0]],"ltp":1.01,"tv":5556.5,"id":2257317}]}]}
{"op":"mcm","clk":"1006079885","pt":1580646367776,"mc":[{"id":"1.168224297","rc":[{"batl":[[0,1.01,41],[1,1.28,1326.22]],"ltp":1.01,"tv":5556.5,"id":2257317}]}]}
{"op":"mcm","clk":"1006080100","pt":1580646368874,"mc":[{"id":"1.168224297","rc":[{"batl":[[1,1.03,719.13],[2,1.04,532.37]],"ltp":1.01,"tv":5556.5,"id":2257317}]}]}
{"op":"mcm","clk":"1006080255","pt":1580646369777,"mc":[{"id":"1.168224297","rc":[{"batl":[[0,1.03,719.13],[1,1.04,532.37],[2,1.04,0]],"ltp":1.01,"tv":5556.5,"id":2257317}]}]}
{"op":"mcm","clk":"1006082736","pt":1580646383793,"mc":[{"id":"1.168224297","rc":[{"batl":[[0,1.03,719.13],[1,1.04,532.37],[2,1.29,1298.72]],"ltp":1.01,"tv":5556.5,"id":2257317}]}]}
{"op":"mcm","clk":"1006082891","pt":1580646384792,"mc":[{"id":"1.168224297","rc":[{"batl":[[2,1.29,0]],"ltp":1.01,"tv":5556.5,"id":2257317}]}]}
{"op":"mcm","clk":"1006084723","pt":1580646393804,"mc":[{"id":"1.168224297","rc":[{"batb":[[0,1.01,15.52],[1,1.01,0]],"ltp":12.0,"tv":67.32,"id":10303696}]}]}
{"op":"mcm","clk":"1006085144","pt":1580646396107,"mc":[{"id":"1.168224297","rc":[{"batl":[[0,1.01,1281.55]],"ltp":1.01,"tv":5556.5,"id":2257317}]}]}
{"op":"mcm","clk":"1006085445","pt":1580646397919,"mc":[{"id":"1.168224297","rc":[{"batl":[[0,1.01,1323.56]],"ltp":1.01,"tv":5556.5,"id":2257317}]}]}
{"op":"mcm","clk":"1006085598","pt":1580646398804,"mc":[{"id":"1.168224297","rc":[{"batl":[[1,1.27,1384.57]],"ltp":1.01,"tv":5556.5,"id":2257317}]}]}
{"op":"mcm","clk":"1006088147","pt":1580646413154,"mc":[{"id":"1.168224297","rc":[{"batl":[[0,1.01,42.01]],"ltp":1.01,"tv":5556.5,"id":2257317}]}]}
{"op":"mcm","clk":"1006088290","pt":1580646413942,"mc":[{"id":"1.168224297","rc":[{"batl":[[1,1.27,0]],"ltp":1.01,"tv":5556.5,"id":2257317}]}]}
{"op":"mcm","clk":"1006088622","pt":1580646415949,"mc":[{"id":"1.168224297","rc":[{"batl":[[0,1.02,1268.99]],"ltp":1.01,"tv":5556.5,"id":2257317}]}]}
{"op":"mcm","clk":"1006089624","pt":1580646421631,"mc":[{"id":"1.168224297","marketDefinition":{"bspMarket":false,"turnInPlayEnabled":true,"persistenceEnabled":true,"marketBaseRate":5.0,"eventId":"29681712","eventTypeId":"2","numberOfWinners":1,"bettingType":"ODDS","marketType":"SET_WINNER","marketTime":"2020-02-02T11:08:00.000Z","suspendTime":"2020-02-02T11:08:00.000Z","bspReconciled":false,"complete":true,"inPlay":true,"crossMatching":true,"runnersVoidable":false,"numberOfActiveRunners":2,"betDelay":3,"status":"SUSPENDED","runners":[{"status":"ACTIVE","sortPriority":1,"id":10303696,"name":"Hugo Gaston"},{"status":"ACTIVE","sortPriority":2,"id":2257317,"name":"Nicolas Mahut"}],"regulators":["MR_INT"],"countryCode":"FR","discountAllowed":true,"timezone":"UTC","openDate":"2020-02-02T11:08:00.000Z","version":3148711776,"name":"Set 2 Winner","eventName":"Hug Gaston v Mahut"}}]}
{"op":"mcm","clk":"1006096663","pt":1580646461446,"mc":[{"id":"1.168224297","tv":0.0}]}
{"op":"mcm","clk":"1006096877","pt":1580646462747,"mc":[{"id":"1.168224297","marketDefinition":{"bspMarket":false,"turnInPlayEnabled":true,"persistenceEnabled":true,"marketBaseRate":5.0,"eventId":"29681712","eventTypeId":"2","numberOfWinners":1,"bettingType":"ODDS","marketType":"SET_WINNER","marketTime":"2020-02-02T11:08:00.000Z","suspendTime":"2020-02-02T11:08:00.000Z","bspReconciled":false,"complete":true,"inPlay":true,"crossMatching":false,"runnersVoidable":false,"numberOfActiveRunners":0,"betDelay":3,"status":"CLOSED","settledTime":"2020-02-02T12:27:40.000Z","runners":[{"status":"LOSER","sortPriority":1,"id":10303696,"name":"Hugo Gaston"},{"status":"WINNER","sortPriority":2,"id":2257317,"name":"Nicolas Mahut"}],"regulators":["MR_INT"],"countryCode":"FR","discountAllowed":true,"timezone":"UTC","openDate":"2020-02-02T11:08:00.000Z","version":3148712558,"name":"Set 2 Winner","eventName":"Hug Gaston v Mahut"}}]}
