{"op":"mcm","clk":"1001176140","pt":1580585265724,"mc":[{"id":"1.168224294","marketDefinition":{"bspMarket":false,"turnInPlayEnabled":true,"persistenceEnabled":true,"marketBaseRate":5.0,"eventId":"29681712","eventTypeId":"2","numberOfWinners":1,"bettingType":"ODDS","marketType":"MATCH_ODDS","marketTime":"2020-02-02T09:00:00.000Z","suspendTime":"2020-02-02T09:00:00.000Z","bspReconciled":false,"complete":true,"inPlay":false,"crossMatching":false,"runnersVoidable":false,"numberOfActiveRunners":2,"betDelay":0,"status":"OPEN","runners":[{"status":"ACTIVE","sortPriority":1,"id":10303696,"name":"Hugo Gaston"},{"status":"ACTIVE","sortPriority":2,"id":2257317,"name":"Nicolas Mahut"}],"regulators":["MR_INT"],"countryCode":"FR","discountAllowed":false,"timezone":"UTC","openDate":"2020-02-02T09:00:00.000Z","version":3147097874,"name":"Match Odds","eventName":"Hug Gaston v Mahut"},"rc":[{"batb":[[0,1.02,3786.16],[1,1.01,3816.16]],"ltp":0.0,"tv":0.0,"id":2257317},{"batb":[[0,1.02,3786.16],[1,1.01,3816.16]],"ltp":0.0,"tv":0.0,"id":10303696}]}]}
{"op":"mcm","clk":"1001176494","pt":1580585267445,"mc":[{"id":"1.168224294","marketDefinition":{"bspMarket":false,"turnInPlayEnabled":true,"persistenceEnabled":true,"marketBaseRate":5.0,"eventId":"29681712","eventTypeId":"2","numberOfWinners":1,"bettingType":"ODDS","marketType":"MATCH_ODDS","marketTime":"2020-02-02T09:00:00.000Z","suspendTime":"2020-02-02T09:00:00.000Z","bspReconciled":false,"complete":true,"inPlay":false,"crossMatching":false,"runnersVoidable":false,"numberOfActiveRunners":2,"betDelay":0,"status":"OPEN","runners":[{"status":"ACTIVE","sortPriority":1,"id":10303696,"name":"Hugo Gaston"},{"status":"ACTIVE","sortPriority":2,"id":2257317,"name":"Nicolas Mahut"}],"regulators":["MR_INT"],"countryCode":"FR","discountAllowed":false,"timezone":"UTC","openDate":"2020-02-02T09:00:00.000Z","version":3147097874,"name":"Match Odds","eventName":"Hug Gaston v Mahut"}}]}
{"op":"mcm","clk":"1001177167","pt":1580585270503,"mc":[{"id":"1.168224294","marketDefinition":{"bspMarket":false,"turnInPlayEnabled":true,"persistenceEnabled":true,"marketBaseRate":5.0,"eventId":"29681712","eventTypeId":"2","numberOfWinners":1,"bettingType":"ODDS","marketType":"MATCH_ODDS","marketTime":"2020-02-02T09:00:00.000Z","suspendTime":"2020-02-02T09:00:00.000Z","bspReconciled":false,"complete":true,"inPlay":false,"crossMatching":false,"runnersVoidable":false,"numberOfActiveRunners":2,"betDelay":0,"status":"OPEN","runners":[{"status":"ACTIVE","sortPriority":1,"id":10303696,"name":"Hugo Gaston"},{"status":"ACTIVE","sortPriority":2,"id":2257317,"name":"Nicolas Mahut"}],"regulators":["MR_INT"],"countryCode":"FR","discountAllowed":true,"timezone":"UTC","openDate":"2020-02-02T09:00:00.000Z","version":3147097874,"name":"Match Odds","eventName":"Hug Gaston v Mahut"}}]}
{"op":"mcm","clk":"1001186261","pt":1580585317838,"mc":[{"id":"1.168224294","rc":[{"batb":[[1,1.01,4116.16]],"ltp":0.0,"tv":0.0,"id":10303696}]}]}
{"op":"mcm","clk":"1001186462","pt":1580585319023,"mc":[{"id":"1.168224294","rc":[{"batb":[[1,1.01,4116.16]],"ltp":0.0,"tv":0.0,"id":2257317}]}]}
{"op":"mcm","clk":"1001186847","pt":1580585321333,"mc":[{"id":"1.168224294","rc":[{"batb":[[1,1.01,3816.16]],"ltp":0.0,"tv":0.0,"id":10303696}]}]}
{"op":"mcm","clk":"1001187069","pt":1580585322596,"mc":[{"id":"1.168224294","rc":[{"batb":[[1,1.01,3816.16]],"ltp":0.0,"tv":0.0,"id":2257317}]}]}
{"op":"mcm","clk":"1001204240","pt":1580585415385,"mc":[{"id":"1.168224294","rc":[{"batb":[[1,1.01,3806.16]],"ltp":0.0,"tv":0.0,"id":2257317},{"batb":[[1,1.01,3806.16]],"ltp":0.0,"tv":0.0,"id":10303696}]}]}
{"op":"mcm","clk":"1001221984","pt":1580585512416,"mc":[{"id":"1.168224294","marketDefinition":{"bspMarket":false,"turnInPlayEnabled":true,"persistenceEnabled":true,"marketBaseRate":5.0,"eventId":"29681712","eventTypeId":"2","numberOfWinners":1,"bettingType":"ODDS","marketType":"MATCH_ODDS","marketTime":"2020-02-02T11:30:00.000Z","suspendTime":"2020-02-02T11:30:00.000Z","bspReconciled":false,"complete":true,"inPlay":false,"crossMatching":false,"runnersVoidable":false,"numberOfActiveRunners":2,"betDelay":0,"status":"OPEN","runners":[{"status":"ACTIVE","sortPriority":1,"id":10303696,"name":"Hugo Gaston"},{"status":"ACTIVE","sortPriority":2,"id":2257317,"name":"Nicolas Mahut"}],"regulators":["MR_INT"],"countryCode":"FR","discountAllowed":true,"timezone":"UTC","openDate":"2020-02-02T09:00:00.000Z","version":3147124627,"name":"Match Odds","eventName":"Hug Gaston v Mahut"}}]}
{"op":"mcm","clk":"1001222392","pt":1580585514425,"mc":[{"id":"1.168224294","marketDefinition":{"bspMarket":false,"turnInPlayEnabled":true,"persistenceEnabled":true,"marketBaseRate":5.0,"eventId":"29681712","eventTypeId":"2","numberOfWinners":1,"bettingType":"ODDS","marketType":"MATCH_ODDS","marketTime":"2020-02-02T11:30:00.000Z","suspendTime":"2020-02-02T11:30:00.000Z","bspReconciled":false,"complete":true,"inPlay":false,"crossMatching":false,"runnersVoidable":false,"numberOfActiveRunners":2,"betDelay":0,"status":"OPEN","runners":[{"status":"ACTIVE","sortPriority":1,"id":10303696,"name":"Hugo Gaston"},{"status":"ACTIVE","sortPriority":2,"id":2257317,"name":"Nicolas Mahut"}],"regulators":["MR_INT"],"countryCode":"FR","discountAllowed":true,"timezone":"UTC","openDate":"2020-02-02T11:30:00.000Z","version":3147124627,"name":"Match Odds","eventName":"Hug Gaston v Mahut"}}]}
{"op":"mcm","clk":"1001228001","pt":1580585544104,"mc":[{"id":"1.168224294","rc":[{"batb":[[0,1.03,100.96],[1,1.02,3786.16],[2,1.01,3806.16]],"ltp":0.0,"tv":0.0,"id":2257317},{"batb":[[0,1.03,100.96],[1,1.02,3786.16],[2,1.01,3806.16]],"ltp":0.0,"tv":0.0,"id":10303696}]}]}
{"op":"mcm","clk":"1001296027","pt":1580585887803,"mc":[{"id":"1.168224294","rc":[{"batl":[[0,48,31.05]],"ltp":0.0,"tv":0.0,"id":2257317},{"batl":[[0,48,31.05]],"ltp":0.0,"tv":0.0,"id":10303696}]}]}
{"op":"mcm","clk":"1001300617","pt":1580585911111,"mc":[{"id":"1.168224294","marketDefinition":{"bspMarket":false,"turnInPlayEnabled":true,"persistenceEnabled":true,"marketBaseRate":5.0,"eventId":"29681712","eventTypeId":"2","numberOfWinners":1,"bettingType":"ODDS","marketType":"MATCH_ODDS","marketTime":"2020-02-02T11:30:00.000Z","suspendTime":"2020-02-02T11:30:00.000Z","bspReconciled":false,"complete":true,"inPlay":false,"crossMatching":true,"runnersVoidable":false,"numberOfActiveRunners":2,"betDelay":0,"status":"OPEN","runners":[{"status":"ACTIVE","sortPriority":1,"id":10303696,"name":"Hugo Gaston"},{"status":"ACTIVE","sortPriority":2,"id":2257317,"name":"Nicolas Mahut"}],"regulators":["MR_INT"],"countryCode":"FR","discountAllowed":true,"timezone":"UTC","openDate":"2020-02-02T11:30:00.000Z","version":3147124627,"name":"Match Odds","eventName":"Hug Gaston v Mahut"}}]}
{"op":"mcm","clk":"1001378578","pt":1580586316080,"mc":[{"id":"1.168224294","rc":[{"batb":[[0,1.03,109.36],[1,1.02,3811.36]],"ltp":0.0,"tv":0.0,"id":2257317},{"batb":[[0,1.03,109.36],[1,1.02,3811.36]],"ltp":0.0,"tv":0.0,"id":10303696}]}]}
{"op":"mcm","clk":"1001665533","pt":1580587946904,"mc":[{"id":"1.168224294","rc":[{"batl":[[1,990,2.2]],"ltp":0.0,"tv":0.0,"id":2257317},{"batl":[[1,990,2.2]],"ltp":0.0,"tv":0.0,"id":10303696}]}]}
{"op":"mcm","clk":"1001976604","pt":1580589675084,"mc":[{"id":"1.168224294","rc":[{"batb":[[1,1.02,25.21],[2,1.01,20]],"ltp":0.0,"tv":0.0,"id":2257317},{"batb":[[1,1.02,25.21],[2,1.01,20]],"ltp":0.0,"tv":0.0,"id":10303696}]}]}
{"op":"mcm","clk":"1002985859","pt":1580601567356,"mc":[{"id":"1.168224294","rc":[{"batb":[[2,1.01,22]],"batl":[[2,1000,2]],"ltp":0.0,"tv":0.0,"id":2257317},{"batb":[[2,1.01,22]],"batl":[[2,1000,2]],"ltp":0.0,"tv":0.0,"id":10303696}]}]}
{"op":"mcm","clk":"1002985870","pt":1580601567461,"mc":[{"id":"1.168224294","rc":[{"batb":[[0,1.03,109.96]],"batl":[[2,1000,0.02]],"ltp":0.0,"tv":0.0,"id":2257317},{"batb":[[0,1.03,109.96]],"batl":[[2,1000,0.02]],"ltp":0.0,"tv":0.0,"id":10303696}]}]}
{"op":"mcm","clk":"1002989804","pt":1580601622449,"mc":[{"id":"1.168224294","rc":[{"batb":[[0,1.03,110.06]],"ltp":0.0,"tv":0.0,"id":2257317},{"batb":[[0,1.03,110.06]],"ltp":0.0,"tv":0.0,"id":10303696}]}]}
{"op":"mcm","clk":"1003032708","pt":1580602187338,"mc":[{"id":"1.168224294","rc":[{"batb":[[2,1.01,22.51]],"ltp":0.0,"tv":0.0,"id":2257317},{"batb":[[2,1.01,22.51]],"ltp":0.0,"tv":0.0,"id":10303696}]}]}
{"op":"mcm","clk":"1003160396","pt":1580603726344,"mc":[{"id":"1.168224294","rc":[{"batb":[[2,1.01,25.04]],"ltp":0.0,"tv":0.0,"id":2257317},{"batb":[[2,1.01,25.04]],"ltp":0.0,"tv":0.0,"id":10303696}]}]}
{"op":"mcm","clk":"1003160475","pt":1580603727376,"mc":[{"id":"1.168224294","rc":[{"batb":[[2,1.01,23.01]],"ltp":0.0,"tv":0.0,"id":2257317},{"batb":[[2,1.01,23.01]],"ltp":0.0,"tv":0.0,"id":10303696}]}]}
{"op":"mcm","clk":"1003384837","pt":1580607031303,"mc":[{"id":"1.168224294","rc":[{"batb":[[0,1.03,110.07]],"ltp":0.0,"tv":0.0,"id":10303696}]}]}
{"op":"mcm","clk":"1003384845","pt":1580607031411,"mc":[{"id":"1.168224294","rc":[{"batb":[[0,1.03,110.07]],"ltp":0.0,"tv":0.0,"id":2257317}]}]}
{"op":"mcm","clk":"1003881058","pt":1580615093094,"mc":[{"id":"1.168224294","rc":[{"batl":[[0,990,2.2],[1,1000,0.02],[2,1000,0]],"ltp":0.0,"tv":0.0,"id":2257317},{"batl":[[0,990,2.2],[1,1000,0.02],[2,1000,0]],"ltp":0.0,"tv":0.0,"id":10303696}]}]}
{"op":"mcm","clk":"1003927545","pt":1580616390700,"mc":[{"id":"1.168224294","rc":[{"batl":[[0,95,15.9],[1,990,2.2],[2,1000,0.02]],"ltp":0.0,"tv":0.0,"id":2257317},{"batl":[[0,95,15.9],[1,990,2.2],[2,1000,0.02]],"ltp":0.0,"tv":0.0,"id":10303696}]}]}
{"op":"mcm","clk":"1003932269","pt":1580616500061,"mc":[{"id":"1.168224294","rc":[{"batb":[[0,1.13,75.83],[1,1.03,109.96],[2,1.02,25.21]],"ltp":0.0,"tv":0.0,"id":2257317},{"batb":[[0,1.13,75.83],[1,1.03,109.96],[2,1.02,25.21]],"ltp":0.0,"tv":0.0,"id":10303696}]}]}
{"op":"mcm","clk":"1004099068","pt":1580620301620,"mc":[{"id":"1.168224294","rc":[{"batl":[[0,4.3,153.72],[1,95,15.9],[2,990,2.2]],"ltp":0.0,"tv":0.0,"id":2257317},{"batl":[[0,4.3,153.72],[1,95,15.9],[2,990,2.2]],"ltp":0.0,"tv":0.0,"id":10303696}]}]}
{"op":"mcm","clk":"1004161080","pt":1580621763327,"mc":[{"id":"1.168224294","rc":[{"batl":[[0,2.08,1.68],[1,4.3,153.72],[2,95,15.9]],"ltp":0.0,"tv":0.0,"id":2257317}]}]}
{"op":"mcm","clk":"1004194645","pt":1580622734808,"mc":[{"id":"1.168224294","rc":[{"batb":[[0,1.32,75.73],[1,1.03,110.06]],"ltp":0.0,"tv":0.0,"id":2257317},{"batb":[[0,1.32,75.73],[1,1.03,110.06]],"ltp":0.0,"tv":0.0,"id":10303696}]}]}
{"op":"mcm","clk":"1004243314","pt":1580624341263,"mc":[{"id":"1.168224294","rc":[{"trd":[[1.32,25.19],[1.48,0.02]],"batb":[[0,1.32,63.13]],"ltp":1.32,"tv":25.2,"id":2257317}],"tv":25.2}]}
{"op":"mcm","clk":"1004254201","pt":1580624674209,"mc":[{"id":"1.168224294","rc":[{"batb":[[0,1.32,138.85]],"ltp":1.32,"tv":25.2,"id":2257317}]}]}
{"op":"mcm","clk":"1004254325","pt":1580624678641,"mc":[{"id":"1.168224294","rc":[{"batb":[[0,1.32,75.72]],"ltp":1.32,"tv":25.2,"id":2257317}]}]}
{"op":"mcm","clk":"1004278089","pt":1580625481772,"mc":[{"id":"1.168224294","rc":[{"batl":[[1,4.1,153.72]],"ltp":1.32,"tv":25.2,"id":2257317},{"batl":[[0,4.1,153.72]],"ltp":0.0,"tv":0.0,"id":10303696}]}]}
{"op":"mcm","clk":"1004279775","pt":1580625532155,"mc":[{"id":"1.168224294","rc":[{"batb":[[0,1.34,75.72]],"ltp":1.32,"tv":25.2,"id":2257317},{"batb":[[0,1.34,75.73]],"ltp":0.0,"tv":0.0,"id":10303696}]}]}
{"op":"mcm","clk":"1004281928","pt":1580625583934,"mc":[{"id":"1.168224294","rc":[{"batl":[[1,3.9,153.72]],"ltp":1.32,"tv":25.2,"id":2257317},{"batl":[[0,3.9,153.72]],"ltp":0.0,"tv":0.0,"id":10303696}]}]}
{"op":"mcm","clk":"1004282176","pt":1580625589552,"mc":[{"id":"1.168224294","rc":[{"batl":[[1,3,42.01],[2,3.9,153.72]],"ltp":1.32,"tv":25.2,"id":2257317}]}]}
{"op":"mcm","clk":"1004282307","pt":1580625592389,"mc":[{"id":"1.168224294","rc":[{"batb":[[0,1.36,75.72]],"ltp":1.32,"tv":25.2,"id":2257317},{"batb":[[0,1.36,75.73]],"ltp":0.0,"tv":0.0,"id":10303696}]}]}
{"op":"mcm","clk":"1004282625","pt":1580625599248,"mc":[{"id":"1.168224294","rc":[{"batb":[[0,1.52,75.72],[1,1.03,110.07]],"ltp":0.0,"tv":0.0,"id":10303696}]}]}
{"op":"mcm","clk":"1004286958","pt":1580625713663,"mc":[{"id":"1.168224294","rc":[{"batb":[[0,1.37,15.12],[1,1.36,75.72],[2,1.03,110.06]],"ltp":1.32,"tv":25.2,"id":2257317},{"batb":[[0,1.53,12.6],[1,1.52,75.72],[2,1.03,110.07]],"ltp":0.0,"tv":0.0,"id":10303696}]}]}
{"op":"mcm","clk":"1004287997","pt":1580625749050,"mc":[{"id":"1.168224294","rc":[{"batb":[[0,1.38,15.14],[1,1.37,15.12],[2,1.36,75.72]],"ltp":1.32,"tv":25.2,"id":2257317},{"batb":[[0,1.55,15.14],[1,1.53,12.6],[2,1.52,75.72]],"ltp":0.0,"tv":0.0,"id":10303696}]}]}
{"op":"mcm","clk":"1004288538","pt":1580625776012,"mc":[{"id":"1.168224294","rc":[{"batb":[[1,1.36,75.72],[2,1.03,110.06]],"ltp":1.32,"tv":25.2,"id":2257317},{"batb":[[1,1.52,75.72],[2,1.03,110.07]],"ltp":0.0,"tv":0.0,"id":10303696}]}]}
{"op":"mcm","clk":"1004289721","pt":1580625832369,"mc":[{"id":"1.168224294","rc":[{"batb":[[0,1.39,15.12],[1,1.38,15.14],[2,1.36,75.72]],"ltp":1.32,"tv":25.2,"id":2257317},{"batb":[[0,1.56,12.6],[1,1.55,15.14],[2,1.52,75.72]],"ltp":0.0,"tv":0.0,"id":10303696}]}]}
{"op":"mcm","clk":"1004289861","pt":1580625838707,"mc":[{"id":"1.168224294","rc":[{"batb":[[0,1.4,15.14],[1,1.39,15.12]],"ltp":1.32,"tv":25.2,"id":2257317},{"batb":[[0,1.57,15.14],[1,1.56,12.6]],"ltp":0.0,"tv":0.0,"id":10303696}]}]}
{"op":"mcm","clk":"1004290715","pt":1580625891070,"mc":[{"id":"1.168224294","rc":[{"batb":[[1,1.36,75.72],[2,1.03,110.06]],"ltp":1.32,"tv":25.2,"id":2257317},{"batb":[[1,1.52,75.72],[2,1.03,110.07]],"ltp":0.0,"tv":0.0,"id":10303696}]}]}
{"op":"mcm","clk":"1004291898","pt":1580625947071,"mc":[{"id":"1.168224294","rc":[{"batb":[[0,1.41,15.12],[1,1.4,15.14],[2,1.36,75.72]],"ltp":1.32,"tv":25.2,"id":2257317},{"batb":[[0,1.58,12.6],[1,1.57,15.14],[2,1.52,75.72]],"ltp":0.0,"tv":0.0,"id":10303696}]}]}
{"op":"mcm","clk":"1004292198","pt":1580625959111,"mc":[{"id":"1.168224294","rc":[{"batl":[[0,3.75,153.72]],"ltp":0.0,"tv":0.0,"id":10303696}]}]}
{"op":"mcm","clk":"1004292312","pt":1580625963481,"mc":[{"id":"1.168224294","rc":[{"batb":[[2,1.52,81.46]],"ltp":0.0,"tv":0.0,"id":10303696}]}]}
{"op":"mcm","clk":"1004292700","pt":1580625978217,"mc":[{"id":"1.168224294","rc":[{"batb":[[0,1.42,15.14],[1,1.41,15.12]],"ltp":1.32,"tv":25.2,"id":2257317},{"batb":[[0,1.59,15.14],[1,1.58,12.6]],"ltp":0.0,"tv":0.0,"id":10303696}]}]}
{"op":"mcm","clk":"1004293131","pt":1580625996617,"mc":[{"id":"1.168224294","rc":[{"batb":[[2,1.37,75.72]],"ltp":1.32,"tv":25.2,"id":2257317}]}]}
{"op":"mcm","clk":"1004293246","pt":1580626001332,"mc":[{"id":"1.168224294","rc":[{"batb":[[2,1.38,75.72]],"ltp":1.32,"tv":25.2,"id":2257317}]}]}
{"op":"mcm","clk":"1004293286","pt":1580626003073,"mc":[{"id":"1.168224294","rc":[{"batb":[[1,1.38,75.72],[2,1.03,110.06]],"ltp":1.32,"tv":25.2,"id":2257317},{"batb":[[1,1.52,81.46],[2,1.03,110.07]],"ltp":0.0,"tv":0.0,"id":10303696}]}]}
{"op":"mcm","clk":"1004294826","pt":1580626059724,"mc":[{"id":"1.168224294","rc":[{"batb":[[0,1.43,14.28],[1,1.42,15.14],[2,1.38,75.72]],"ltp":1.32,"tv":25.2,"id":2257317},{"batb":[[0,1.6,11.76],[1,1.59,15.14],[2,1.52,75.72]],"ltp":0.0,"tv":0.0,"id":10303696}]}]}
{"op":"mcm","clk":"1004295330","pt":1580626078375,"mc":[{"id":"1.168224294","rc":[{"batb":[[1,1.38,75.72],[2,1.03,110.06]],"ltp":1.32,"tv":25.2,"id":2257317},{"batb":[[1,1.52,75.72],[2,1.03,110.07]],"ltp":0.0,"tv":0.0,"id":10303696}]}]}
{"op":"mcm","clk":"1004295334","pt":1580626078480,"mc":[{"id":"1.168224294","rc":[{"batb":[[0,1.44,15.14],[1,1.43,14.28],[2,1.38,75.72]],"ltp":1.32,"tv":25.2,"id":2257317},{"batb":[[0,1.61,15.14],[1,1.6,11.76],[2,1.52,75.72]],"ltp":0.0,"tv":0.0,"id":10303696}]}]}
{"op":"mcm","clk":"1004296212","pt":1580626116106,"mc":[{"id":"1.168224294","rc":[{"batb":[[1,1.38,75.72],[2,1.03,110.06]],"ltp":1.32,"tv":25.2,"id":2257317},{"batb":[[1,1.52,75.72],[2,1.03,110.07]],"ltp":0.0,"tv":0.0,"id":10303696}]}]}
{"op":"mcm","clk":"1004297666","pt":1580626172313,"mc":[{"id":"1.168224294","rc":[{"batb":[[0,1.62,11.76],[1,1.61,15.14],[2,1.52,75.72]],"ltp":0.0,"tv":0.0,"id":10303696}]}]}
{"op":"mcm","clk":"1004297672","pt":1580626172518,"mc":[{"id":"1.168224294","rc":[{"batb":[[0,1.45,14.28],[1,1.44,15.14],[2,1.38,75.72]],"ltp":1.32,"tv":25.2,"id":2257317}]}]}
{"op":"mcm","clk":"1004299011","pt":1580626212368,"mc":[{"id":"1.168224294","rc":[{"batb":[[1,1.38,75.72],[2,1.03,110.06]],"ltp":1.32,"tv":25.2,"id":2257317},{"batb":[[1,1.52,75.72],[2,1.03,110.07]],"ltp":0.0,"tv":0.0,"id":10303696}]}]}
{"op":"mcm","clk":"1004299016","pt":1580626212467,"mc":[{"id":"1.168224294","rc":[{"batb":[[0,1.46,15.14],[1,1.45,14.28],[2,1.38,75.72]],"ltp":1.32,"tv":25.2,"id":2257317},{"batb":[[0,1.63,15.14],[1,1.62,11.76],[2,1.52,75.72]],"ltp":0.0,"tv":0.0,"id":10303696}]}]}
{"op":"mcm","clk":"1004299614","pt":1580626230249,"mc":[{"id":"1.168224294","rc":[{"batb":[[1,1.38,75.72],[2,1.03,110.06]],"ltp":1.32,"tv":25.2,"id":2257317},{"batb":[[1,1.52,75.72],[2,1.03,110.07]],"ltp":0.0,"tv":0.0,"id":10303696}]}]}
{"op":"mcm","clk":"1004301349","pt":1580626286215,"mc":[{"id":"1.168224294","rc":[{"batb":[[0,1.64,10.92],[1,1.63,15.14],[2,1.52,75.72]],"ltp":0.0,"tv":0.0,"id":10303696}]}]}
{"op":"mcm","clk":"1004301354","pt":1580626286422,"mc":[{"id":"1.168224294","rc":[{"batb":[[0,1.47,14.28],[1,1.46,15.14],[2,1.38,75.72]],"ltp":1.32,"tv":25.2,"id":2257317}]}]}
{"op":"mcm","clk":"1004301699","pt":1580626298944,"mc":[{"id":"1.168224294","rc":[{"batb":[[0,1.48,15.14],[1,1.47,14.28]],"ltp":1.32,"tv":25.2,"id":2257317},{"batb":[[0,1.65,15.14],[1,1.64,10.92]],"ltp":0.0,"tv":0.0,"id":10303696}]}]}
{"op":"mcm","clk":"1004303185","pt":1580626343369,"mc":[{"id":"1.168224294","rc":[{"batb":[[1,1.38,75.72],[2,1.03,110.06]],"ltp":1.32,"tv":25.2,"id":2257317}]}]}
{"op":"mcm","clk":"1004303195","pt":1580626343676,"mc":[{"id":"1.168224294","rc":[{"batb":[[1,1.52,75.72],[2,1.03,110.07]],"ltp":0.0,"tv":0.0,"id":10303696}]}]}
{"op":"mcm","clk":"1004305326","pt":1580626400172,"mc":[{"id":"1.168224294","rc":[{"batb":[[0,1.49,13.44],[1,1.48,15.14],[2,1.38,75.72]],"ltp":1.32,"tv":25.2,"id":2257317},{"batb":[[0,1.66,10.92],[1,1.65,15.14],[2,1.52,75.72]],"ltp":0.0,"tv":0.0,"id":10303696}]}]}
{"op":"mcm","clk":"1004305978","pt":1580626415707,"mc":[{"id":"1.168224294","rc":[{"batb":[[0,1.5,15.14],[1,1.49,13.44]],"ltp":1.32,"tv":25.2,"id":2257317},{"batb":[[0,1.67,15.14],[1,1.66,10.92]],"ltp":0.0,"tv":0.0,"id":10303696}]}]}
{"op":"mcm","clk":"1004307485","pt":1580626458956,"mc":[{"id":"1.168224294","rc":[{"batb":[[1,1.38,75.72],[2,1.03,110.06]],"ltp":1.32,"tv":25.2,"id":2257317},{"batb":[[1,1.52,75.72],[2,1.03,110.07]],"ltp":0.0,"tv":0.0,"id":10303696}]}]}
{"op":"mcm","clk":"1004308838","pt":1580626499289,"mc":[{"id":"1.168224294","rc":[{"batb":[[0,1.69,38.21],[1,1.5,15.14],[2,1.38,75.72]],"ltp":1.32,"tv":25.2,"id":2257317}]}]}
{"op":"mcm","clk":"1004308906","pt":1580626500992,"mc":[{"id":"1.168224294","rc":[{"batl":[[0,2.04,31.13],[1,2.08,1.68],[2,3,42.01]],"ltp":1.32,"tv":25.2,"id":2257317}]}]}
{"op":"mcm","clk":"1004308955","pt":1580626502279,"mc":[{"id":"1.168224294","rc":[{"batb":[[0,1.56,48.83]],"ltp":1.32,"tv":25.2,"id":2257317}]}]}
{"op":"mcm","clk":"1004309243","pt":1580626509115,"mc":[{"id":"1.168224294","rc":[{"batb":[[0,1.53,50.16]],"batl":[[0,2.06,32.75]],"ltp":1.32,"tv":25.2,"id":2257317}]}]}
{"op":"mcm","clk":"1004309511","pt":1580626516404,"mc":[{"id":"1.168224294","rc":[{"batb":[[0,1.68,10.92],[1,1.67,15.14],[2,1.52,75.72]],"ltp":0.0,"tv":0.0,"id":10303696}]}]}
{"op":"mcm","clk":"1004309537","pt":1580626516919,"mc":[{"id":"1.168224294","rc":[{"batb":[[0,1.55,49.39],[1,1.54,12.6],[2,1.5,15.14]],"ltp":1.32,"tv":25.2,"id":2257317}]}]}
{"op":"mcm","clk":"1004311001","pt":1580626555553,"mc":[{"id":"1.168224294","rc":[{"batb":[[2,1.38,75.72]],"ltp":1.32,"tv":25.2,"id":2257317},{"batb":[[1,1.52,75.72],[2,1.03,110.07]],"ltp":0.0,"tv":0.0,"id":10303696}]}]}
{"op":"mcm","clk":"1004311664","pt":1580626572559,"mc":[{"id":"1.168224294","rc":[{"batb":[[1,1.38,75.72],[2,1.03,110.06]],"ltp":1.32,"tv":25.2,"id":2257317}]}]}
{"op":"mcm","clk":"1004312273","pt":1580626586295,"mc":[{"id":"1.168224294","rc":[{"batl":[[0,2.04,7.57],[1,2.06,32.75],[2,2.08,1.68]],"ltp":1.32,"tv":25.2,"id":2257317}]}]}
{"op":"mcm","clk":"1004312298","pt":1580626586553,"mc":[{"id":"1.168224294","rc":[{"batl":[[0,2.02,32.25],[1,2.04,7.57]],"ltp":1.32,"tv":25.2,"id":2257317}]}]}
{"op":"mcm","clk":"1004312540","pt":1580626591145,"mc":[{"id":"1.168224294","rc":[{"batl":[[0,1.98,33.08],[1,2,7.57]],"ltp":1.32,"tv":25.2,"id":2257317}]}]}
{"op":"mcm","clk":"1004312678","pt":1580626595789,"mc":[{"id":"1.168224294","rc":[{"batl":[[0,1.96,33.37],[1,1.97,7.57]],"ltp":1.32,"tv":25.2,"id":2257317}]}]}
{"op":"mcm","clk":"1004312802","pt":1580626600373,"mc":[{"id":"1.168224294","rc":[{"batl":[[1,2.08,1.68],[2,3,42.01]],"ltp":1.32,"tv":25.2,"id":2257317}]}]}
{"op":"mcm","clk":"1004312821","pt":1580626600886,"mc":[{"id":"1.168224294","rc":[{"batl":[[0,1.93,33.78],[1,1.95,7.57],[2,2.08,1.68]],"ltp":1.32,"tv":25.2,"id":2257317}]}]}
{"op":"mcm","clk":"1004312982","pt":1580626606196,"mc":[{"id":"1.168224294","rc":[{"batl":[[0,1.92,7.57],[1,1.93,33.78]],"ltp":1.32,"tv":25.2,"id":2257317}]}]}
{"op":"mcm","clk":"1004313003","pt":1580626606608,"mc":[{"id":"1.168224294","rc":[{"batl":[[0,1.91,34.05],[1,1.92,7.57]],"ltp":1.32,"tv":25.2,"id":2257317}]}]}
{"op":"mcm","clk":"1004313133","pt":1580626611377,"mc":[{"id":"1.168224294","rc":[{"batl":[[0,1.9,7.57],[1,2.08,1.68],[2,3,42.01]],"ltp":1.32,"tv":25.2,"id":2257317}]}]}
{"op":"mcm","clk":"1004313137","pt":1580626611477,"mc":[{"id":"1.168224294","rc":[{"batl":[[0,1.9,41.82]],"ltp":1.32,"tv":25.2,"id":2257317}]}]}
{"op":"mcm","clk":"1004313764","pt":1580626628919,"mc":[{"id":"1.168224294","rc":[{"batb":[[0,1.57,46.92],[1,1.56,12.6],[2,1.38,75.72]],"ltp":1.32,"tv":25.2,"id":2257317}]}]}
{"op":"mcm","clk":"1004315662","pt":1580626688577,"mc":[{"id":"1.168224294","rc":[{"batb":[[1,1.38,75.72],[2,1.03,110.06]],"ltp":1.32,"tv":25.2,"id":2257317}]}]}
{"op":"mcm","clk":"1004319085","pt":1580626804008,"mc":[{"id":"1.168224294","rc":[{"batb":[[0,1.58,12.6],[1,1.57,46.92],[2,1.38,75.72]],"ltp":1.32,"tv":25.2,"id":2257317}]}]}
{"op":"mcm","clk":"1004322169","pt":1580626897058,"mc":[{"id":"1.168224294","rc":[{"batb":[[0,1.65,35.59],[1,1.58,12.6],[2,1.57,46.92]],"ltp":1.32,"tv":25.2,"id":2257317},{"batb":[[0,1.93,46.95],[1,1.68,10.92],[2,1.52,75.72]],"ltp":0.0,"tv":0.0,"id":10303696}]}]}
{"op":"mcm","clk":"1004322722","pt":1580626919179,"mc":[{"id":"1.168224294","rc":[{"batb":[[1,1.57,46.92],[2,1.38,75.72]],"ltp":1.32,"tv":25.2,"id":2257317},{"batb":[[1,1.52,75.72],[2,1.03,110.07]],"ltp":0.0,"tv":0.0,"id":10303696}]}]}
{"op":"mcm","clk":"1004326299","pt":1580627056812,"mc":[{"id":"1.168224294","rc":[{"batb":[[0,1.68,44.11],[1,1.65,35.59]],"ltp":1.32,"tv":25.2,"id":2257317},{"batb":[[0,1.9,46.95]],"ltp":0.0,"tv":0.0,"id":10303696}]}]}
{"op":"mcm","clk":"1004330333","pt":1580627175751,"mc":[{"id":"1.168224294","rc":[{"batl":[[0,1.89,7.57],[1,1.9,7.57],[2,2.08,1.68]],"ltp":1.32,"tv":25.2,"id":2257317},{"batl":[[0,2.52,3.79],[1,3.75,153.72],[2,95,15.9]],"ltp":0.0,"tv":0.0,"id":10303696}]}]}
{"op":"mcm","clk":"1004331306","pt":1580627205181,"mc":[{"id":"1.168224294","rc":[{"batl":[[0,1.9,42.02],[1,2.08,9.25],[2,3,42.01]],"ltp":1.32,"tv":25.2,"id":2257317}]}]}
{"op":"mcm","clk":"1004331348","pt":1580627206366,"mc":[{"id":"1.168224294","rc":[{"batl":[[0,1.88,7.57]],"ltp":1.32,"tv":25.2,"id":2257317}]}]}
{"op":"mcm","clk":"1004364861","pt":1580628063184,"mc":[{"id":"1.168224294","rc":[{"batb":[[0,1.91,46.95]],"ltp":0.0,"tv":0.0,"id":10303696}]}]}
{"op":"mcm","clk":"1004372197","pt":1580628221775,"mc":[{"id":"1.168224294","rc":[{"batb":[[0,1.92,46.95]],"ltp":0.0,"tv":0.0,"id":10303696}]}]}
{"op":"mcm","clk":"1004385682","pt":1580628577358,"mc":[{"id":"1.168224294","rc":[{"batb":[[0,1.72,64.84]],"ltp":1.32,"tv":25.2,"id":2257317},{"batb":[[0,2.16,52.31],[1,1.92,46.95],[2,1.52,75.72]],"ltp":0.0,"tv":0.0,"id":10303696}]}]}
{"op":"mcm","clk":"1004394237","pt":1580628780795,"mc":[{"id":"1.168224294","rc":[{"batb":[[0,2.16,52.39]],"ltp":0.0,"tv":0.0,"id":10303696}]}]}
{"op":"mcm","clk":"1004394683","pt":1580628789806,"mc":[{"id":"1.168224294","rc":[{"batb":[[1,1.89,46.95]],"ltp":0.0,"tv":0.0,"id":10303696}]}]}
{"op":"mcm","clk":"1004396330","pt":1580628833966,"mc":[{"id":"1.168224294","rc":[{"batb":[[1,1.92,46.95]],"ltp":0.0,"tv":0.0,"id":10303696}]}]}
{"op":"mcm","clk":"1004405367","pt":1580629081185,"mc":[{"id":"1.168224294","rc":[{"batb":[[0,1.72,64.91]],"ltp":1.32,"tv":25.2,"id":2257317}]}]}
{"op":"mcm","clk":"1004413136","pt":1580629274052,"mc":[{"id":"1.168224294","rc":[{"batb":[[2,1.41,37.86]],"ltp":1.32,"tv":25.2,"id":2257317}]}]}
{"op":"mcm","clk":"1004413198","pt":1580629275242,"mc":[{"id":"1.168224294","rc":[{"batb":[[2,1.61,37.86]],"ltp":1.32,"tv":25.2,"id":2257317},{"batb":[[2,1.71,37.86]],"ltp":0.0,"tv":0.0,"id":10303696}]}]}
{"op":"mcm","clk":"1004413206","pt":1580629275450,"mc":[{"id":"1.168224294","rc":[{"batb":[[2,1.81,37.86]],"ltp":0.0,"tv":0.0,"id":10303696}]}]}
{"op":"mcm","clk":"1004427694","pt":1580629616043,"mc":[{"id":"1.168224294","rc":[{"batb":[[1,2.02,46.95]],"ltp":0.0,"tv":0.0,"id":10303696}]}]}
{"op":"mcm","clk":"1004462765","pt":1580630390657,"mc":[{"id":"1.168224294","rc":[{"batb":[[2,1.92,31.27]],"ltp":0.0,"tv":0.0,"id":10303696}]}]}
{"op":"mcm","clk":"1004466417","pt":1580630455929,"mc":[{"id":"1.168224294","rc":[{"batb":[[1,1.61,37.86],[2,1.59,48.77]],"ltp":1.32,"tv":25.2,"id":2257317},{"batb":[[1,1.92,31.27],[2,1.87,46.95]],"ltp":0.0,"tv":0.0,"id":10303696}]}]}
{"op":"mcm","clk":"1004474096","pt":1580630626273,"mc":[{"id":"1.168224294","rc":[{"batb":[[1,1.65,45.43],[2,1.61,37.86]],"ltp":1.32,"tv":25.2,"id":2257317},{"batb":[[1,2.02,46.95],[2,1.92,31.27]],"ltp":0.0,"tv":0.0,"id":10303696}]}]}
{"op":"mcm","clk":"1004474880","pt":1580630644198,"mc":[{"id":"1.168224294","rc":[{"batb":[[1,1.65,55.28]],"ltp":1.32,"tv":25.2,"id":2257317}]}]}
{"op":"mcm","clk":"1004476777","pt":1580630680360,"mc":[{"id":"1.168224294","rc":[{"batl":[[0,1.75,2.52],[1,1.88,7.57],[2,2.08,9.25]],"ltp":1.32,"tv":25.2,"id":2257317},{"batb":[[2,2,37.86]],"ltp":0.0,"tv":0.0,"id":10303696}]}]}
{"op":"mcm","clk":"1004480539","pt":1580630768190,"mc":[{"id":"1.168224294","rc":[{"trd":[[1.75,5.04]],"batb":[[0,1.71,72.87]],"batl":[[0,1.88,7.57],[1,2.08,9.25],[2,3,42.01]],"ltp":1.75,"tv":30.24,"id":2257317},{"batb":[[0,2.16,54.38]],"ltp":0.0,"tv":0.0,"id":10303696}],"tv":30.24}]}
{"op":"mcm","clk":"1004489909","pt":1580630992022,"mc":[{"id":"1.168224294","rc":[{"batl":[[0,1.86,7.57]],"ltp":1.75,"tv":30.24,"id":2257317}]}]}
{"op":"mcm","clk":"1004492145","pt":1580631036583,"mc":[{"id":"1.168224294","rc":[{"batl":[[2,2.4,15.14]],"ltp":1.75,"tv":30.24,"id":2257317}]}]}
{"op":"mcm","clk":"1004501584","pt":1580631249834,"mc":[{"id":"1.168224294","rc":[{"batl":[[0,1.86,61.39]],"ltp":1.75,"tv":30.24,"id":2257317}]}]}
{"op":"mcm","clk":"1004501781","pt":1580631253316,"mc":[{"id":"1.168224294","rc":[{"batb":[[1,1.61,37.86],[2,1.51,37.86]],"ltp":1.75,"tv":30.24,"id":2257317}]}]}
{"op":"mcm","clk":"1004501797","pt":1580631253931,"mc":[{"id":"1.168224294","rc":[{"batb":[[2,1.56,51.39]],"ltp":1.75,"tv":30.24,"id":2257317}]}]}
{"op":"mcm","clk":"1004523569","pt":1580631756175,"mc":[{"id":"1.168224294","rc":[{"batb":[[2,1.51,37.86]],"ltp":1.75,"tv":30.24,"id":2257317}]}]}
{"op":"mcm","clk":"1004523593","pt":1580631756790,"mc":[{"id":"1.168224294","rc":[{"batb":[[2,1.54,53.29]],"ltp":1.75,"tv":30.24,"id":2257317},{"batb":[[2,2,66.64]],"ltp":0.0,"tv":0.0,"id":10303696}]}]}
{"op":"mcm","clk":"1004527500","pt":1580631853054,"mc":[{"id":"1.168224294","rc":[{"batb":[[2,1.56,51.39]],"ltp":1.75,"tv":30.24,"id":2257317},{"batb":[[1,2,37.86],[2,1.96,29.97]],"ltp":0.0,"tv":0.0,"id":10303696}]}]}
{"op":"mcm","clk":"1004529477","pt":1580631892215,"mc":[{"id":"1.168224294","rc":[{"batl":[[1,4.2,153.72]],"ltp":0.0,"tv":0.0,"id":10303696}]}]}
{"op":"mcm","clk":"1004538837","pt":1580632093756,"mc":[{"id":"1.168224294","rc":[{"batb":[[0,1.71,383.34]],"ltp":1.75,"tv":30.24,"id":2257317}]}]}
{"op":"mcm","clk":"1004544348","pt":1580632232395,"mc":[{"id":"1.168224294","rc":[{"batb":[[2,1.55,52.32]],"ltp":1.75,"tv":30.24,"id":2257317},{"batb":[[2,1.98,29.37]],"ltp":0.0,"tv":0.0,"id":10303696}]}]}
{"op":"mcm","clk":"1004546859","pt":1580632285000,"mc":[{"id":"1.168224294","rc":[{"batb":[[0,1.73,61.84],[1,1.71,383.26],[2,1.61,37.86]],"batl":[[0,1.86,7.57]],"ltp":1.75,"tv":30.24,"id":2257317}]}]}
{"op":"mcm","clk":"1004547078","pt":1580632289392,"mc":[{"id":"1.168224294","rc":[{"batb":[[2,1.81,37.86]],"ltp":0.0,"tv":0.0,"id":10303696}]}]}
{"op":"mcm","clk":"1004547118","pt":1580632290003,"mc":[{"id":"1.168224294","rc":[{"batb":[[2,1.63,45.68]],"ltp":1.75,"tv":30.24,"id":2257317},{"batb":[[2,1.88,32.7]],"ltp":0.0,"tv":0.0,"id":10303696}]}]}
{"op":"mcm","clk":"1004547722","pt":1580632303918,"mc":[{"id":"1.168224294","rc":[{"batb":[[0,1.74,42.05],[1,1.73,61.84],[2,1.71,310.46]],"ltp":1.75,"tv":30.24,"id":2257317}]}]}
{"op":"mcm","clk":"1004547932","pt":1580632308771,"mc":[{"id":"1.168224294","rc":[{"batb":[[1,1.72,62.67]],"ltp":1.75,"tv":30.24,"id":2257317}]}]}
{"op":"mcm","clk":"1004548043","pt":1580632311204,"mc":[{"id":"1.168224294","rc":[{"batb":[[2,1.81,37.86]],"ltp":0.0,"tv":0.0,"id":10303696}]}]}
{"op":"mcm","clk":"1004548076","pt":1580632311822,"mc":[{"id":"1.168224294","rc":[{"batb":[[2,1.88,32.7]],"ltp":0.0,"tv":0.0,"id":10303696}]}]}
{"op":"mcm","clk":"1004548249","pt":1580632315643,"mc":[{"id":"1.168224294","rc":[{"batb":[[1,1.72,62.59]],"ltp":1.75,"tv":30.24,"id":2257317}]}]}
{"op":"mcm","clk":"1004553708","pt":1580632431727,"mc":[{"id":"1.168224294","rc":[{"batb":[[0,1.73,52.08]],"ltp":1.75,"tv":30.24,"id":2257317}]}]}
{"op":"mcm","clk":"1004562092","pt":1580632639313,"mc":[{"id":"1.168224294","rc":[{"batb":[[0,1.73,362.54],[2,1.62,46.41]],"ltp":1.75,"tv":30.24,"id":2257317}]}]}
{"op":"mcm","clk":"1004563565","pt":1580632675944,"mc":[{"id":"1.168224294","rc":[{"batb":[[0,1.73,362.62]],"ltp":1.75,"tv":30.24,"id":2257317}]}]}
{"op":"mcm","clk":"1004583550","pt":1580633091884,"mc":[{"id":"1.168224294","rc":[{"batb":[[1,1.62,46.41],[2,1.61,37.86]],"ltp":1.75,"tv":30.24,"id":2257317}]}]}
{"op":"mcm","clk":"1004583717","pt":1580633094982,"mc":[{"id":"1.168224294","rc":[{"batb":[[1,1.61,85.04],[2,1.51,37.86]],"ltp":1.75,"tv":30.24,"id":2257317},{"batb":[[2,1.9,31.97]],"ltp":0.0,"tv":0.0,"id":10303696}]}]}
{"op":"mcm","clk":"1004584948","pt":1580633122240,"mc":[{"id":"1.168224294","rc":[{"batb":[[0,1.74,7.32],[1,1.73,362.54],[2,1.61,85.04]],"ltp":1.75,"tv":30.24,"id":2257317}]}]}
{"op":"mcm","clk":"1004587371","pt":1580633172258,"mc":[{"id":"1.168224294","rc":[{"trd":[[1.74,10.14]],"batb":[[0,1.74,2.25]],"ltp":1.74,"tv":40.38,"id":2257317}],"tv":40.38}]}
{"op":"mcm","clk":"1004587423","pt":1580633173278,"mc":[{"id":"1.168224294","rc":[{"batb":[[0,1.75,59.91],[1,1.74,2.25],[2,1.73,362.54]],"ltp":1.74,"tv":40.38,"id":2257317},{"batb":[[2,1.81,37.86]],"ltp":0.0,"tv":0.0,"id":10303696}]}]}
{"op":"mcm","clk":"1004587458","pt":1580633173896,"mc":[{"id":"1.168224294","rc":[{"batb":[[2,1.86,33.46]],"ltp":0.0,"tv":0.0,"id":10303696}]}]}
{"op":"mcm","clk":"1004588723","pt":1580633199260,"mc":[{"id":"1.168224294","rc":[{"batb":[[0,1.76,22.66],[1,1.75,59.91],[2,1.74,2.25]],"ltp":1.74,"tv":40.38,"id":2257317}]}]}
{"op":"mcm","clk":"1004588735","pt":1580633199466,"mc":[{"id":"1.168224294","rc":[{"batb":[[1,1.74,2.25],[2,1.73,310.46]],"ltp":1.74,"tv":40.38,"id":2257317}]}]}
{"op":"mcm","clk":"1004594100","pt":1580633328097,"mc":[{"id":"1.168224294","rc":[{"batb":[[0,1.75,59.91],[1,1.74,44.3]],"ltp":1.74,"tv":40.38,"id":2257317}]}]}
{"op":"mcm","clk":"1004594474","pt":1580633337123,"mc":[{"id":"1.168224294","rc":[{"batb":[[0,1.74,105.59],[1,1.73,310.46],[2,1.65,44.27]],"ltp":1.74,"tv":40.38,"id":2257317}]}]}
{"op":"mcm","clk":"1004594559","pt":1580633339127,"mc":[{"id":"1.168224294","rc":[{"batb":[[2,1.63,45.68]],"ltp":1.74,"tv":40.38,"id":2257317},{"batb":[[2,1.88,32.7]],"ltp":0.0,"tv":0.0,"id":10303696}]}]}
{"op":"mcm","clk":"1004601439","pt":1580633486307,"mc":[{"id":"1.168224294","rc":[{"batb":[[2,1.67,42.95]],"ltp":1.74,"tv":40.38,"id":2257317},{"batb":[[2,1.84,34.26]],"ltp":0.0,"tv":0.0,"id":10303696}]}]}
{"op":"mcm","clk":"1004608410","pt":1580633657274,"mc":[{"id":"1.168224294","rc":[{"trd":[[1.83,5.06]],"batb":[[0,1.74,44.3]],"ltp":1.83,"tv":45.44,"id":2257317}],"tv":45.44}]}
{"op":"mcm","clk":"1004608430","pt":1580633657740,"mc":[{"id":"1.168224294","rc":[{"batb":[[0,1.75,58.63],[1,1.74,44.3],[2,1.73,310.46]],"ltp":1.83,"tv":45.44,"id":2257317}]}]}
{"op":"mcm","clk":"1004611331","pt":1580633716954,"mc":[{"id":"1.168224294","rc":[{"batb":[[0,1.77,58.11],[1,1.76,22.66],[2,1.74,2.25]],"ltp":1.83,"tv":45.44,"id":2257317}]}]}
{"op":"mcm","clk":"1004617858","pt":1580633846009,"mc":[{"id":"1.168224294","rc":[{"batb":[[1,1.74,44.3],[2,1.73,310.46]],"ltp":1.83,"tv":45.44,"id":2257317}]}]}
{"op":"mcm","clk":"1004623676","pt":1580633953112,"mc":[{"id":"1.168224294","rc":[{"batb":[[0,1.77,77.37]],"ltp":1.83,"tv":45.44,"id":2257317}]}]}
{"op":"mcm","clk":"1004623791","pt":1580633954810,"mc":[{"id":"1.168224294","rc":[{"batb":[[2,1.81,37.86]],"ltp":0.0,"tv":0.0,"id":10303696}]}]}
{"op":"mcm","clk":"1004623829","pt":1580633955425,"mc":[{"id":"1.168224294","rc":[{"batb":[[2,1.84,45.07]],"ltp":0.0,"tv":0.0,"id":10303696}]}]}
{"op":"mcm","clk":"1004632831","pt":1580634103373,"mc":[{"id":"1.168224294","rc":[{"batb":[[0,1.78,23.06],[1,1.77,77.37],[2,1.74,2.25]],"ltp":1.83,"tv":45.44,"id":2257317},{"batb":[[0,2.16,39.02]],"ltp":0.0,"tv":0.0,"id":10303696}]}]}
{"op":"mcm","clk":"1004632844","pt":1580634103580,"mc":[{"id":"1.168224294","rc":[{"batb":[[1,1.74,2.25],[2,1.73,310.46]],"ltp":1.83,"tv":45.44,"id":2257317}]}]}
{"op":"mcm","clk":"1004632917","pt":1580634105065,"mc":[{"id":"1.168224294","rc":[{"batb":[[2,1.85,44.54]],"ltp":0.0,"tv":0.0,"id":10303696}]}]}
{"op":"mcm","clk":"1004633211","pt":1580634111110,"mc":[{"id":"1.168224294","rc":[{"batb":[[2,1.93,46.95]],"ltp":0.0,"tv":0.0,"id":10303696}]}]}
{"op":"mcm","clk":"1004638946","pt":1580634235032,"mc":[{"id":"1.168224294","rc":[{"batb":[[0,1.74,63.5],[1,1.73,310.46],[2,1.72,53.01]],"ltp":1.83,"tv":45.44,"id":2257317}]}]}
{"op":"mcm","clk":"1004639017","pt":1580634236421,"mc":[{"id":"1.168224294","rc":[{"batb":[[0,1.75,78.91],[1,1.74,63.5],[2,1.73,310.46]],"ltp":1.83,"tv":45.44,"id":2257317}]}]}
{"op":"mcm","clk":"1004645244","pt":1580634367103,"mc":[{"id":"1.168224294","rc":[{"batb":[[0,1.77,78.24],[1,1.76,41.74],[2,1.74,2.25]],"ltp":1.83,"tv":45.44,"id":2257317}]}]}
{"op":"mcm","clk":"1004651654","pt":1580634500164,"mc":[{"id":"1.168224294","rc":[{"batb":[[0,1.78,23.06],[1,1.74,2.25],[2,1.73,310.46]],"ltp":1.83,"tv":45.44,"id":2257317}]}]}
{"op":"mcm","clk":"1004652810","pt":1580634528080,"mc":[{"id":"1.168224294","rc":[{"batl":[[0,1.86,9.84]],"ltp":1.83,"tv":45.44,"id":2257317}]}]}
{"op":"mcm","clk":"1004657310","pt":1580634632904,"mc":[{"id":"1.168224294","rc":[{"batb":[[0,1.75,78.91],[1,1.74,63.5]],"ltp":1.83,"tv":45.44,"id":2257317}]}]}
{"op":"mcm","clk":"1004663526","pt":1580634766397,"mc":[{"id":"1.168224294","rc":[{"batb":[[0,1.77,78.24],[1,1.76,41.74],[2,1.74,2.25]],"ltp":1.83,"tv":45.44,"id":2257317}]}]}
{"op":"mcm","clk":"1004670807","pt":1580634898374,"mc":[{"id":"1.168224294","rc":[{"batb":[[1,1.74,2.25],[2,1.73,310.46]],"ltp":1.83,"tv":45.44,"id":2257317}]}]}
{"op":"mcm","clk":"1004670821","pt":1580634898635,"mc":[{"id":"1.168224294","rc":[{"batb":[[0,1.78,23.06]],"ltp":1.83,"tv":45.44,"id":2257317}]}]}
{"op":"mcm","clk":"1004677384","pt":1580635023117,"mc":[{"id":"1.168224294","rc":[{"batl":[[0,1.86,82.09]],"ltp":1.83,"tv":45.44,"id":2257317}]}]}
{"op":"mcm","clk":"1004677488","pt":1580635024819,"mc":[{"id":"1.168224294","rc":[{"batb":[[2,1.96,39.44]],"ltp":0.0,"tv":0.0,"id":10303696}]}]}
{"op":"mcm","clk":"1004677558","pt":1580635026109,"mc":[{"id":"1.168224294","rc":[{"batb":[[1,2.1,46.95],[2,2,37.86]],"ltp":0.0,"tv":0.0,"id":10303696}]}]}
{"op":"mcm","clk":"1004677810","pt":1580635031102,"mc":[{"id":"1.168224294","rc":[{"batb":[[0,1.74,63.5],[1,1.73,310.46],[2,1.61,37.86]],"ltp":1.83,"tv":45.44,"id":2257317}]}]}
{"op":"mcm","clk":"1004678081","pt":1580635036132,"mc":[{"id":"1.168224294","rc":[{"batb":[[2,1.61,93.9]],"ltp":1.83,"tv":45.44,"id":2257317},{"batb":[[1,2.08,46.95]],"ltp":0.0,"tv":0.0,"id":10303696}]}]}
{"op":"mcm","clk":"1004678428","pt":1580635043042,"mc":[{"id":"1.168224294","rc":[{"trd":[[1.74,52.15]],"batb":[[0,1.74,42.5]],"batl":[[0,1.86,9.84]],"ltp":1.74,"tv":87.45,"id":2257317},{"batb":[[0,2.18,14.85],[1,2.16,38.94],[2,2.08,46.95]],"ltp":0.0,"tv":0.0,"id":10303696}],"tv":87.45}]}
{"op":"mcm","clk":"1004678808","pt":1580635051320,"mc":[{"id":"1.168224294","rc":[{"batl":[[1,1.9,10.13],[2,2.08,9.25]],"ltp":1.74,"tv":87.45,"id":2257317}]}]}
{"op":"mcm","clk":"1004680059","pt":1580635074950,"mc":[{"id":"1.168224294","rc":[{"batl":[[1,1.9,20.26]],"ltp":1.74,"tv":87.45,"id":2257317}]}]}
{"op":"mcm","clk":"1004682486","pt":1580635118768,"mc":[{"id":"1.168224294","rc":[{"batl":[[0,1.84,7.57],[1,1.86,9.84],[2,1.9,20.26]],"ltp":1.74,"tv":87.45,"id":2257317}]}]}
{"op":"mcm","clk":"1004684867","pt":1580635164834,"mc":[{"id":"1.168224294","rc":[{"batb":[[0,2.2,28.79],[1,2.18,14.85]],"ltp":0.0,"tv":0.0,"id":10303696}]}]}
{"op":"mcm","clk":"1004688340","pt":1580635240244,"mc":[{"id":"1.168224294","rc":[{"trd":[[1.74,65.71]],"batb":[[0,1.74,28.94]],"ltp":1.74,"tv":101.01,"id":2257317},{"trd":[[2.36,10]],"batb":[[0,2.2,39.36]],"ltp":2.36,"tv":10.0,"id":10303696}],"tv":111.01}]}
{"op":"mcm","clk":"1004688770","pt":1580635249437,"mc":[{"id":"1.168224294","rc":[{"batl":[[0,1.79,7.57],[1,1.84,7.57],[2,1.86,9.84]],"ltp":1.74,"tv":101.01,"id":2257317}]}]}
{"op":"mcm","clk":"1004691742","pt":1580635312785,"mc":[{"id":"1.168224294","rc":[{"batb":[[1,2.18,14.78]],"ltp":2.36,"tv":10.0,"id":10303696}]}]}
{"op":"mcm","clk":"1004691909","pt":1580635315872,"mc":[{"id":"1.168224294","marketDefinition":{"bspMarket":false,"turnInPlayEnabled":true,"persistenceEnabled":true,"marketBaseRate":5.0,"eventId":"29681712","eventTypeId":"2","numberOfWinners":1,"bettingType":"ODDS","marketType":"MATCH_ODDS","marketTime":"2020-02-02T11:19:00.000Z","suspendTime":"2020-02-02T11:19:00.000Z","bspReconciled":false,"complete":true,"inPlay":false,"crossMatching":true,"runnersVoidable":false,"numberOfActiveRunners":2,"betDelay":0,"status":"OPEN","runners":[{"status":"ACTIVE","sortPriority":1,"id":10303696,"name":"Hugo Gaston"},{"status":"ACTIVE","sortPriority":2,"id":2257317,"name":"Nicolas Mahut"}],"regulators":["MR_INT"],"countryCode":"FR","discountAllowed":true,"timezone":"UTC","openDate":"2020-02-02T11:30:00.000Z","version":3148342764,"name":"Match Odds","eventName":"Hug Gaston v Mahut"}}]}
{"op":"mcm","clk":"1004692044","pt":1580635317946,"mc":[{"id":"1.168224294","marketDefinition":{"bspMarket":false,"turnInPlayEnabled":true,"persistenceEnabled":true,"marketBaseRate":5.0,"eventId":"29681712","eventTypeId":"2","numberOfWinners":1,"bettingType":"ODDS","marketType":"MATCH_ODDS","marketTime":"2020-02-02T11:19:00.000Z","suspendTime":"2020-02-02T11:19:00.000Z","bspReconciled":false,"complete":true,"inPlay":false,"crossMatching":true,"runnersVoidable":false,"numberOfActiveRunners":2,"betDelay":0,"status":"OPEN","runners":[{"status":"ACTIVE","sortPriority":1,"id":10303696,"name":"Hugo Gaston"},{"status":"ACTIVE","sortPriority":2,"id":2257317,"name":"Nicolas Mahut"}],"regulators":["MR_INT"],"countryCode":"FR","discountAllowed":true,"timezone":"UTC","openDate":"2020-02-02T11:19:00.000Z","version":3148342764,"name":"Match Odds","eventName":"Hug Gaston v Mahut"}}]}
{"op":"mcm","clk":"1004693964","pt":1580635373055,"mc":[{"id":"1.168224294","rc":[{"batb":[[0,2.2,39.44]],"ltp":2.36,"tv":10.0,"id":10303696}]}]}
{"op":"mcm","clk":"1004695191","pt":1580635407299,"mc":[{"id":"1.168224294","rc":[{"batb":[[2,1.61,37.86]],"ltp":1.74,"tv":101.01,"id":2257317},{"batb":[[2,2,37.86]],"ltp":2.36,"tv":10.0,"id":10303696}]}]}
{"op":"mcm","clk":"1004713315","pt":1580635831617,"mc":[{"id":"1.168224294","rc":[{"batb":[[0,1.74,58.74]],"ltp":1.74,"tv":101.01,"id":2257317},{"batb":[[0,2.2,88.57]],"ltp":2.36,"tv":10.0,"id":10303696}]}]}
{"op":"mcm","clk":"1004717454","pt":1580635932949,"mc":[{"id":"1.168224294","rc":[{"batl":[[2,1.86,10.45]],"ltp":1.74,"tv":101.01,"id":2257317}]}]}
{"op":"mcm","clk":"1004752711","pt":1580636696393,"mc":[{"id":"1.168224294","rc":[{"batl":[[1,95,15.9],[2,990,2.2]],"ltp":2.36,"tv":10.0,"id":10303696}]}]}
{"op":"mcm","clk":"1004752716","pt":1580636696492,"mc":[{"id":"1.168224294","rc":[{"batl":[[1,3.75,153.72],[2,95,15.9]],"ltp":2.36,"tv":10.0,"id":10303696}]}]}
{"op":"mcm","clk":"1004758383","pt":1580636823025,"mc":[{"id":"1.168224294","rc":[{"batl":[[1,1.83,2.27],[2,1.84,7.57]],"ltp":1.74,"tv":101.01,"id":2257317}]}]}
{"op":"mcm","clk":"1004773072","pt":1580637097323,"mc":[{"id":"1.168224294","rc":[{"batl":[[0,1.83,2.27],[1,1.84,7.57],[2,1.86,8.18]],"ltp":1.74,"tv":101.01,"id":2257317}]}]}
{"op":"mcm","clk":"1004773098","pt":1580637097937,"mc":[{"id":"1.168224294","rc":[{"batl":[[0,1.82,7.57],[1,1.83,2.27],[2,1.84,7.57]],"ltp":1.74,"tv":101.01,"id":2257317}]}]}
{"op":"mcm","clk":"1004773150","pt":1580637099437,"mc":[{"id":"1.168224294","rc":[{"batl":[[2,1.86,8.18]],"ltp":1.74,"tv":101.01,"id":2257317}]}]}
{"op":"mcm","clk":"1004775435","pt":1580637140020,"mc":[{"id":"1.168224294","rc":[{"batb":[[1,2,37.86],[2,1.96,39.44]],"ltp":2.36,"tv":10.0,"id":10303696}]}]}
{"op":"mcm","clk":"1004791498","pt":1580637436175,"mc":[{"id":"1.168224294","rc":[{"batb":[[2,1.81,37.86]],"ltp":2.36,"tv":10.0,"id":10303696}]}]}
{"op":"mcm","clk":"1004791540","pt":1580637436814,"mc":[{"id":"1.168224294","rc":[{"batb":[[2,1.94,40.28]],"ltp":2.36,"tv":10.0,"id":10303696}]}]}
{"op":"mcm","clk":"1004800702","pt":1580637599351,"mc":[{"id":"1.168224294","rc":[{"batb":[[2,1.94,50.75]],"ltp":2.36,"tv":10.0,"id":10303696}]}]}
{"op":"mcm","clk":"1004816463","pt":1580637808731,"mc":[{"id":"1.168224294","rc":[{"batb":[[0,1.75,97.83],[1,1.74,58.74],[2,1.73,310.46]],"ltp":1.74,"tv":101.01,"id":2257317}]}]}
{"op":"mcm","clk":"1004816634","pt":1580637811037,"mc":[{"id":"1.168224294","rc":[{"batb":[[2,1.84,56.79]],"ltp":2.36,"tv":10.0,"id":10303696}]}]}
{"op":"mcm","clk":"1004820114","pt":1580637862410,"mc":[{"id":"1.168224294","rc":[{"trd":[[1.82,7.57],[1.83,7.21]],"batl":[[0,1.86,8.3],[1,1.9,20.26],[2,2.08,9.25]],"ltp":1.83,"tv":110.73,"id":2257317},{"trd":[[2.2,185.04],[2.28,0.15]],"batb":[[0,2,37.86],[1,1.84,56.79],[2,1.81,37.86]],"ltp":2.2,"tv":195.18,"id":10303696}],"tv":305.92}]}
{"op":"mcm","clk":"1004820246","pt":1580637864284,"mc":[{"id":"1.168224294","rc":[{"batb":[[1,1.73,310.46],[2,1.67,71.2]],"ltp":1.83,"tv":110.73,"id":2257317}]}]}
{"op":"mcm","clk":"1004820260","pt":1580637864491,"mc":[{"id":"1.168224294","rc":[{"batb":[[0,1.76,129.45],[1,1.75,97.83],[2,1.73,310.46]],"ltp":1.83,"tv":110.73,"id":2257317},{"batb":[[0,2.12,82.25],[1,2,37.86],[2,1.84,56.79]],"ltp":2.2,"tv":195.18,"id":10303696}]}]}
{"op":"mcm","clk":"1004820412","pt":1580637867805,"mc":[{"id":"1.168224294","rc":[{"batb":[[0,1.78,7.74],[1,1.76,129.45],[2,1.75,97.83]],"ltp":1.83,"tv":110.73,"id":2257317}]}]}
{"op":"mcm","clk":"1004821260","pt":1580637883398,"mc":[{"id":"1.168224294","rc":[{"batb":[[0,1.76,129.45],[1,1.75,97.83],[2,1.73,310.46]],"ltp":1.83,"tv":110.73,"id":2257317}]}]}
{"op":"mcm","clk":"1004821341","pt":1580637884685,"mc":[{"id":"1.168224294","rc":[{"trd":[[1.82,22.71]],"ltp":1.82,"tv":125.88,"id":2257317}],"tv":321.06}]}
{"op":"mcm","clk":"1004821478","pt":1580637887118,"mc":[{"id":"1.168224294","rc":[{"batl":[[0,1.83,7.69],[1,1.86,8.18],[2,1.9,20.26]],"ltp":1.82,"tv":125.88,"id":2257317}]}]}
{"op":"mcm","clk":"1004821569","pt":1580637888827,"mc":[{"id":"1.168224294","rc":[{"batl":[[0,1.86,8.3],[1,1.9,20.26],[2,2.08,9.25]],"ltp":1.82,"tv":125.88,"id":2257317}]}]}
{"op":"mcm","clk":"1004821661","pt":1580637890600,"mc":[{"id":"1.168224294","rc":[{"batb":[[0,1.79,7.57],[1,1.76,129.45],[2,1.75,97.83]],"ltp":1.82,"tv":125.88,"id":2257317}]}]}
{"op":"mcm","clk":"1004824592","pt":1580637932925,"mc":[{"id":"1.168224294","rc":[{"batl":[[0,1.89,8.3]],"ltp":1.82,"tv":125.88,"id":2257317}]}]}
{"op":"mcm","clk":"1004825038","pt":1580637940094,"mc":[{"id":"1.168224294","rc":[{"batl":[[0,1.83,7.69],[1,1.89,8.18],[2,1.9,20.26]],"ltp":1.82,"tv":125.88,"id":2257317}]}]}
{"op":"mcm","clk":"1004825121","pt":1580637941625,"mc":[{"id":"1.168224294","rc":[{"batl":[[0,1.89,8.3],[1,1.9,20.26],[2,2.08,9.25]],"ltp":1.82,"tv":125.88,"id":2257317}]}]}
{"op":"mcm","clk":"1004825326","pt":1580637945564,"mc":[{"id":"1.168224294","rc":[{"batb":[[0,1.77,7.57]],"ltp":1.82,"tv":125.88,"id":2257317}]}]}
{"op":"mcm","clk":"1004829664","pt":1580638015552,"mc":[{"id":"1.168224294","rc":[{"batb":[[0,1.78,2.27],[1,1.77,7.57],[2,1.76,129.45]],"ltp":1.82,"tv":125.88,"id":2257317}]}]}
{"op":"mcm","clk":"1004832263","pt":1580638054292,"mc":[{"id":"1.168224294","rc":[{"batb":[[0,1.78,94.1],[2,1.75,97.83]],"ltp":1.82,"tv":125.88,"id":2257317}]}]}
{"op":"mcm","clk":"1004843585","pt":1580638219069,"mc":[{"id":"1.168224294","rc":[{"batb":[[0,1.78,91.82]],"ltp":1.82,"tv":125.88,"id":2257317}]}]}
{"op":"mcm","clk":"1004854933","pt":1580638369572,"mc":[{"id":"1.168224294","rc":[{"batl":[[0,1.83,7.69],[1,1.89,8.18],[2,1.9,20.26]],"ltp":1.82,"tv":125.88,"id":2257317}]}]}
{"op":"mcm","clk":"1004855179","pt":1580638372856,"mc":[{"id":"1.168224294","rc":[{"batl":[[0,1.89,8.3],[1,1.9,20.26],[2,2.08,9.25]],"ltp":1.82,"tv":125.88,"id":2257317}]}]}
{"op":"mcm","clk":"1004855944","pt":1580638382693,"mc":[{"id":"1.168224294","rc":[{"batb":[[0,1.79,7.57],[1,1.78,91.82],[2,1.77,7.57]],"ltp":1.82,"tv":125.88,"id":2257317}]}]}
{"op":"mcm","clk":"1004856047","pt":1580638384061,"mc":[{"id":"1.168224294","rc":[{"batb":[[2,1.75,97.83]],"ltp":1.82,"tv":125.88,"id":2257317}]}]}
{"op":"mcm","clk":"1004860613","pt":1580638444113,"mc":[{"id":"1.168224294","rc":[{"batb":[[1,1.76,129.45],[2,1.73,310.46]],"ltp":1.82,"tv":125.88,"id":2257317}]}]}
{"op":"mcm","clk":"1004860805","pt":1580638446365,"mc":[{"id":"1.168224294","rc":[{"trd":[[1.79,0.24]],"batb":[[0,1.79,7.45]],"batl":[[0,1.89,8.18]],"ltp":1.79,"tv":126.12,"id":2257317}],"tv":321.31}]}
{"op":"mcm","clk":"1004861023","pt":1580638448673,"mc":[{"id":"1.168224294","rc":[{"trd":[[1.8,0.24]],"ltp":1.8,"tv":126.36,"id":2257317}],"tv":321.55}]}
{"op":"mcm","clk":"1004861199","pt":1580638451094,"mc":[{"id":"1.168224294","rc":[{"trd":[[1.79,9.86]],"batb":[[0,1.79,2.64]],"ltp":1.79,"tv":135.98,"id":2257317}],"tv":331.17}]}
{"op":"mcm","clk":"1004861329","pt":1580638452357,"mc":[{"id":"1.168224294","rc":[{"trd":[[1.8,9.8]],"batb":[[0,1.8,19.6],[1,1.79,2.64],[2,1.76,129.45]],"ltp":1.8,"tv":145.54,"id":2257317}],"tv":340.72}]}
{"op":"mcm","clk":"1004861738","pt":1580638456907,"mc":[{"id":"1.168224294","rc":[{"batb":[[0,1.79,2.64],[1,1.76,129.45],[2,1.73,310.46]],"ltp":1.8,"tv":145.54,"id":2257317}]}]}
{"op":"mcm","clk":"1004878497","pt":1580638668268,"mc":[{"id":"1.168224294","rc":[{"batb":[[1,1.77,6.94],[2,1.76,129.45]],"ltp":1.8,"tv":145.54,"id":2257317},{"batb":[[0,2.14,5.89],[1,2.12,82.25],[2,2,37.86]],"ltp":2.2,"tv":195.18,"id":10303696}]}]}
{"op":"mcm","clk":"1004881505","pt":1580638705589,"mc":[{"id":"1.168224294","rc":[{"batb":[[1,1.78,91.82],[2,1.77,6.94]],"ltp":1.8,"tv":145.54,"id":2257317}]}]}
{"op":"mcm","clk":"1004884660","pt":1580638745245,"mc":[{"id":"1.168224294","rc":[{"batb":[[2,1.77,39.68]],"ltp":1.8,"tv":145.54,"id":2257317},{"batb":[[2,2.1,22.91]],"ltp":2.2,"tv":195.18,"id":10303696}]}]}
{"op":"mcm","clk":"1004919230","pt":1580639122947,"mc":[{"id":"1.168224294","rc":[{"batl":[[0,1.85,1.49],[1,1.89,7.57],[2,1.9,20.26]],"ltp":1.8,"tv":145.54,"id":2257317}]}]}
{"op":"mcm","clk":"1004937218","pt":1580639287780,"mc":[{"id":"1.168224294","rc":[{"batl":[[0,2.22,168.04],[1,2.52,3.79],[2,3.75,153.72]],"ltp":2.2,"tv":195.18,"id":10303696}]}]}
{"op":"mcm","clk":"1004937321","pt":1580639288569,"mc":[{"id":"1.168224294","rc":[{"batb":[[1,1.78,124.14]],"ltp":1.8,"tv":145.54,"id":2257317},{"batb":[[2,2.08,23.34]],"ltp":2.2,"tv":195.18,"id":10303696}]}]}
{"op":"mcm","clk":"1004942414","pt":1580639339978,"mc":[{"id":"1.168224294","rc":[{"batb":[[0,1.78,124.14],[1,1.77,39.68],[2,1.73,310.46]],"ltp":1.8,"tv":145.54,"id":2257317}]}]}
{"op":"mcm","clk":"1004944698","pt":1580639361936,"mc":[{"id":"1.168224294","rc":[{"batl":[[0,2.52,3.79],[1,3.75,153.72],[2,95,15.9]],"ltp":2.2,"tv":195.18,"id":10303696}]}]}
{"op":"mcm","clk":"1004944769","pt":1580639362622,"mc":[{"id":"1.168224294","rc":[{"batb":[[0,1.78,91.82]],"ltp":1.8,"tv":145.54,"id":2257317},{"batb":[[2,2.1,22.91]],"ltp":2.2,"tv":195.18,"id":10303696}]}]}
{"op":"mcm","clk":"1004948822","pt":1580639402974,"mc":[{"id":"1.168224294","rc":[{"batb":[[0,1.78,98.23]],"ltp":1.8,"tv":145.54,"id":2257317}]}]}
{"op":"mcm","clk":"1004950652","pt":1580639419168,"mc":[{"id":"1.168224294","rc":[{"batb":[[0,1.8,132.62],[1,1.78,6.41],[2,1.77,39.68]],"ltp":1.8,"tv":145.54,"id":2257317},{"batb":[[1,2.1,61.28],[2,2.08,23.34]],"ltp":2.2,"tv":195.18,"id":10303696}]}]}
{"op":"mcm","clk":"1004950699","pt":1580639419631,"mc":[{"id":"1.168224294","rc":[{"batb":[[1,1.78,38.72]],"ltp":1.8,"tv":145.54,"id":2257317},{"batb":[[1,2.1,38.37]],"ltp":2.2,"tv":195.18,"id":10303696}]}]}
{"op":"mcm","clk":"1004972780","pt":1580639642872,"mc":[{"id":"1.168224294","rc":[{"batl":[[0,2.22,135.75],[1,2.52,3.79],[2,3.75,153.72]],"ltp":2.2,"tv":195.18,"id":10303696}]}]}
{"op":"mcm","clk":"1004972848","pt":1580639643754,"mc":[{"id":"1.168224294","rc":[{"batb":[[2,2.06,23.78]],"ltp":2.2,"tv":195.18,"id":10303696}]}]}
{"op":"mcm","clk":"1004976127","pt":1580639682018,"mc":[{"id":"1.168224294","rc":[{"trd":[[1.85,1.49]],"batl":[[0,1.89,7.57],[1,1.9,20.26],[2,2.08,9.25]],"ltp":1.85,"tv":147.03,"id":2257317},{"trd":[[2.14,5.04],[2.16,1.28]],"batb":[[0,2.14,3.37]],"ltp":2.14,"tv":201.5,"id":10303696}],"tv":348.53}]}
{"op":"mcm","clk":"1004976210","pt":1580639682706,"mc":[{"id":"1.168224294","rc":[{"batb":[[1,1.79,31.9],[2,1.78,38.72]],"ltp":1.85,"tv":147.03,"id":2257317}]}]}
{"op":"mcm","clk":"1004980635","pt":1580639729240,"mc":[{"id":"1.168224294","rc":[{"batb":[[0,1.82,97.59]],"ltp":1.85,"tv":147.03,"id":2257317},{"batb":[[1,2.08,60.74]],"ltp":2.14,"tv":201.5,"id":10303696}]}]}
{"op":"mcm","clk":"1004981213","pt":1580639734970,"mc":[{"id":"1.168224294","rc":[{"batl":[[0,1.87,7.57],[1,1.89,7.57],[2,1.9,20.26]],"ltp":1.85,"tv":147.03,"id":2257317}]}]}
{"op":"mcm","clk":"1004981289","pt":1580639735772,"mc":[{"id":"1.168224294","rc":[{"batb":[[1,2.08,84.08]],"ltp":2.14,"tv":201.5,"id":10303696}]}]}
{"op":"mcm","clk":"1004992428","pt":1580639852274,"mc":[{"id":"1.168224294","rc":[{"trd":[[1.87,15.14]],"batb":[[0,1.82,89.93]],"batl":[[0,1.89,7.57],[1,1.9,20.26],[2,2.08,9.25]],"ltp":1.87,"tv":162.17,"id":2257317},{"batb":[[1,2.1,6.71],[2,2.08,84.08]],"ltp":2.14,"tv":201.5,"id":10303696}],"tv":363.67}]}
{"op":"mcm","clk":"1004992481","pt":1580639852916,"mc":[{"id":"1.168224294","rc":[{"batb":[[0,1.86,7.61],[1,1.82,89.93],[2,1.79,31.9]],"ltp":1.87,"tv":162.17,"id":2257317},{"batb":[[2,2.08,60.74]],"ltp":2.14,"tv":201.5,"id":10303696}]}]}
{"op":"mcm","clk":"1004995541","pt":1580639883023,"mc":[{"id":"1.168224294","rc":[{"batb":[[1,1.83,7.57],[2,1.82,89.93]],"ltp":1.87,"tv":162.17,"id":2257317}]}]}
{"op":"mcm","clk":"1004996010","pt":1580639887940,"mc":[{"id":"1.168224294","rc":[{"batb":[[0,1.83,7.57],[1,1.82,89.93],[2,1.79,31.9]],"ltp":1.87,"tv":162.17,"id":2257317}]}]}
{"op":"mcm","clk":"1004996225","pt":1580639890646,"mc":[{"id":"1.168224294","rc":[{"batb":[[0,1.82,89.93],[1,1.79,31.9],[2,1.78,38.72]],"ltp":1.87,"tv":162.17,"id":2257317}]}]}
{"op":"mcm","clk":"1004996337","pt":1580639891734,"mc":[{"id":"1.168224294","rc":[{"batb":[[0,1.86,7.61],[1,1.83,7.57],[2,1.82,89.93]],"ltp":1.87,"tv":162.17,"id":2257317}]}]}
{"op":"mcm","clk":"1005004589","pt":1580639979957,"mc":[{"id":"1.168224294","rc":[{"batb":[[1,1.84,56.34],[2,1.83,7.57]],"ltp":1.87,"tv":162.17,"id":2257317},{"batb":[[1,2.08,67.45],[2,2.06,23.78]],"ltp":2.14,"tv":201.5,"id":10303696}]}]}
{"op":"mcm","clk":"1005004678","pt":1580639980855,"mc":[{"id":"1.168224294","rc":[{"batb":[[2,2.04,24.24]],"ltp":2.14,"tv":201.5,"id":10303696}]}]}
{"op":"mcm","clk":"1005004934","pt":1580639983882,"mc":[{"id":"1.168224294","rc":[{"batl":[[0,2.52,3.79],[1,3.75,153.72],[2,95,15.9]],"ltp":2.14,"tv":201.5,"id":10303696}]}]}
{"op":"mcm","clk":"1005009350","pt":1580640028984,"mc":[{"id":"1.168224294","rc":[{"batb":[[2,1.8,31.51]],"ltp":1.87,"tv":162.17,"id":2257317}]}]}
{"op":"mcm","clk":"1005011220","pt":1580640049795,"mc":[{"id":"1.168224294","rc":[{"batl":[[0,2.5,10.13],[1,2.52,3.79],[2,3.75,153.72]],"ltp":2.14,"tv":201.5,"id":10303696}]}]}
{"op":"mcm","clk":"1005016480","pt":1580640107181,"mc":[{"id":"1.168224294","rc":[{"batb":[[1,1.81,107.25]],"ltp":1.87,"tv":162.17,"id":2257317},{"batb":[[1,2.06,90.6]],"ltp":2.14,"tv":201.5,"id":10303696}]}]}
{"op":"mcm","clk":"1005016549","pt":1580640107905,"mc":[{"id":"1.168224294","rc":[{"batb":[[2,1.79,31.9]],"ltp":1.87,"tv":162.17,"id":2257317},{"batb":[[1,2.06,114.38]],"ltp":2.14,"tv":201.5,"id":10303696}]}]}
{"op":"mcm","clk":"1005033995","pt":1580640237783,"mc":[{"id":"1.168224294","rc":[{"batb":[[1,1.8,124.92]],"ltp":1.87,"tv":162.17,"id":2257317}]}]}
{"op":"mcm","clk":"1005034162","pt":1580640238874,"mc":[{"id":"1.168224294","rc":[{"batb":[[2,1.78,38.72]],"ltp":1.87,"tv":162.17,"id":2257317},{"batb":[[1,2.08,23.34],[2,2.06,114.38]],"ltp":2.14,"tv":201.5,"id":10303696}]}]}
{"op":"mcm","clk":"1005052361","pt":1580640374229,"mc":[{"id":"1.168224294","rc":[{"batb":[[1,2.1,45.05],[2,2.08,23.34]],"ltp":2.14,"tv":201.5,"id":10303696}]}]}
{"op":"mcm","clk":"1005109283","pt":1580640834060,"mc":[{"id":"1.168224294","rc":[{"trd":[[1.86,15.14]],"batb":[[0,1.81,165.12]],"batl":[[0,1.9,20.26],[1,2.08,9.25],[2,2.4,15.14]],"ltp":1.86,"tv":177.31,"id":2257317}],"tv":378.82}]}
{"op":"mcm","clk":"1005109409","pt":1580640835081,"mc":[{"id":"1.168224294","rc":[{"batb":[[2,1.79,31.9]],"ltp":1.86,"tv":177.31,"id":2257317},{"batb":[[2,2.06,23.78]],"ltp":2.14,"tv":201.5,"id":10303696}]}]}
{"op":"mcm","clk":"1005110001","pt":1580640840195,"mc":[{"id":"1.168224294","rc":[{"batb":[[0,1.83,163.25],[1,1.82,7.57],[2,1.8,124.92]],"ltp":1.86,"tv":177.31,"id":2257317}]}]}
{"op":"mcm","clk":"1005110130","pt":1580640841292,"mc":[{"id":"1.168224294","rc":[{"batb":[[0,1.83,163.21],[2,1.8,156.43]],"ltp":1.86,"tv":177.31,"id":2257317}]}]}
{"op":"mcm","clk":"1005110226","pt":1580640842055,"mc":[{"id":"1.168224294","rc":[{"batb":[[0,1.84,7.57]],"ltp":1.86,"tv":177.31,"id":2257317}]}]}
{"op":"mcm","clk":"1005110344","pt":1580640843095,"mc":[{"id":"1.168224294","rc":[{"batb":[[2,1.8,124.92]],"ltp":1.86,"tv":177.31,"id":2257317},{"batb":[[2,2.08,23.34]],"ltp":2.14,"tv":201.5,"id":10303696}]}]}
{"op":"mcm","clk":"1005110577","pt":1580640845085,"mc":[{"id":"1.168224294","rc":[{"batb":[[0,1.83,163.21],[2,1.8,156.43]],"ltp":1.86,"tv":177.31,"id":2257317},{"batb":[[2,2.06,23.78]],"ltp":2.14,"tv":201.5,"id":10303696}]}]}
{"op":"mcm","clk":"1005110638","pt":1580640845762,"mc":[{"id":"1.168224294","rc":[{"batb":[[0,1.83,170.78]],"ltp":1.86,"tv":177.31,"id":2257317}]}]}
{"op":"mcm","clk":"1005110768","pt":1580640846903,"mc":[{"id":"1.168224294","rc":[{"batb":[[0,1.84,7.57],[1,1.83,7.57],[2,1.82,7.57]],"ltp":1.86,"tv":177.31,"id":2257317}]}]}
{"op":"mcm","clk":"1005110936","pt":1580640848377,"mc":[{"id":"1.168224294","rc":[{"batb":[[2,1.8,124.92]],"ltp":1.86,"tv":177.31,"id":2257317}]}]}
{"op":"mcm","clk":"1005111060","pt":1580640849367,"mc":[{"id":"1.168224294","rc":[{"batb":[[0,1.83,170.78],[1,1.8,124.92],[2,1.78,38.72]],"ltp":1.86,"tv":177.31,"id":2257317},{"batb":[[2,2.08,23.34]],"ltp":2.14,"tv":201.5,"id":10303696}]}]}
{"op":"mcm","clk":"1005111163","pt":1580640850094,"mc":[{"id":"1.168224294","rc":[{"batb":[[1,1.8,156.43]],"ltp":1.86,"tv":177.31,"id":2257317},{"batb":[[2,2.06,23.78]],"ltp":2.14,"tv":201.5,"id":10303696}]}]}
{"op":"mcm","clk":"1005119536","pt":1580640918164,"mc":[{"id":"1.168224294","rc":[{"batb":[[0,1.84,56.34],[1,1.83,7.57],[2,1.8,31.51]],"ltp":1.86,"tv":177.31,"id":2257317},{"batb":[[1,2.08,67.45],[2,2.04,24.24]],"ltp":2.14,"tv":201.5,"id":10303696}]}]}
{"op":"mcm","clk":"1005136167","pt":1580641050285,"mc":[{"id":"1.168224294","rc":[{"batb":[[1,2.06,90.6]],"ltp":2.14,"tv":201.5,"id":10303696}]}]}
{"op":"mcm","clk":"1005184668","pt":1580641358310,"mc":[{"id":"1.168224294","rc":[{"batb":[[1,1.8,31.51],[2,1.78,38.72]],"ltp":1.86,"tv":177.31,"id":2257317}]}]}
{"op":"mcm","clk":"1005190964","pt":1580641391265,"mc":[{"id":"1.168224294","rc":[{"batb":[[1,1.78,38.72],[2,1.77,39.68]],"batl":[[0,1.86,75.98],[1,1.9,20.26],[2,2.08,9.25]],"ltp":1.86,"tv":177.31,"id":2257317},{"batb":[[1,2.08,23.34],[2,2.06,90.6]],"ltp":2.14,"tv":201.5,"id":10303696}]}]}
{"op":"mcm","clk":"1005204727","pt":1580641458303,"mc":[{"id":"1.168224294","rc":[{"trd":[[1.86,63.25]],"batb":[[0,1.8,230.63],[1,1.79,118.48],[2,1.78,38.72]],"batl":[[0,1.86,51.94]],"ltp":1.86,"tv":225.42,"id":2257317},{"batb":[[1,2.1,66.11],[2,2.08,23.34]],"ltp":2.14,"tv":201.5,"id":10303696}],"tv":426.92}]}
{"op":"mcm","clk":"1005204914","pt":1580641459200,"mc":[{"id":"1.168224294","rc":[{"batb":[[2,1.78,6.41]],"ltp":1.86,"tv":225.42,"id":2257317},{"batb":[[1,2.1,89.02]],"ltp":2.14,"tv":201.5,"id":10303696}]}]}
{"op":"mcm","clk":"1005206655","pt":1580641467359,"mc":[{"id":"1.168224294","rc":[{"batb":[[0,1.81,7.57]],"ltp":1.86,"tv":225.42,"id":2257317}]}]}
{"op":"mcm","clk":"1005206843","pt":1580641468223,"mc":[{"id":"1.168224294","rc":[{"batb":[[0,1.82,228.14],[1,1.81,7.57],[2,1.79,118.48]],"ltp":1.86,"tv":225.42,"id":2257317}]}]}
{"op":"mcm","clk":"1005207269","pt":1580641470248,"mc":[{"id":"1.168224294","rc":[{"batb":[[0,1.83,7.57],[1,1.82,228.14],[2,1.81,7.57]],"ltp":1.86,"tv":225.42,"id":2257317}]}]}
{"op":"mcm","clk":"1005207522","pt":1580641471365,"mc":[{"id":"1.168224294","rc":[{"batb":[[1,1.81,7.57],[2,1.79,118.48]],"ltp":1.86,"tv":225.42,"id":2257317}]}]}
{"op":"mcm","clk":"1005207747","pt":1580641472367,"mc":[{"id":"1.168224294","rc":[{"batb":[[0,1.83,234.37],[1,1.79,118.48],[2,1.78,38.72]],"ltp":1.86,"tv":225.42,"id":2257317},{"batb":[[1,2.1,66.11]],"ltp":2.14,"tv":201.5,"id":10303696}]}]}
{"op":"mcm","clk":"1005207891","pt":1580641473167,"mc":[{"id":"1.168224294","rc":[{"batb":[[0,2.1,66.11],[1,2.08,23.34],[2,2.04,24.24]],"ltp":2.14,"tv":201.5,"id":10303696}]}]}
{"op":"mcm","clk":"1005208130","pt":1580641474278,"mc":[{"id":"1.168224294","rc":[{"trd":[[1.86,115.18]],"batb":[[1,1.8,31.51],[2,1.79,118.48]],"batl":[[0,1.9,20.26],[1,2.08,9.25],[2,2.4,15.14]],"ltp":1.86,"tv":277.35,"id":2257317},{"trd":[[2.16,46.04]],"batb":[[1,2.06,23.78]],"ltp":2.16,"tv":246.27,"id":10303696}],"tv":523.62}]}
{"op":"mcm","clk":"1005232541","pt":1580641592038,"mc":[{"id":"1.168224294","rc":[{"batb":[[0,1.84,32.2],[1,1.83,234.37],[2,1.8,31.51]],"ltp":1.86,"tv":277.35,"id":2257317},{"batb":[[0,2.08,88.61]],"ltp":2.16,"tv":246.27,"id":10303696}]}]}
{"op":"mcm","clk":"1005232818","pt":1580641593325,"mc":[{"id":"1.168224294","rc":[{"batb":[[1,1.83,7.57]],"ltp":1.86,"tv":277.35,"id":2257317},{"batb":[[1,2.04,24.24],[2,2,37.86]],"ltp":2.16,"tv":246.27,"id":10303696}]}]}
{"op":"mcm","clk":"1005237285","pt":1580641615820,"mc":[{"id":"1.168224294","marketDefinition":{"bspMarket":false,"turnInPlayEnabled":true,"persistenceEnabled":true,"marketBaseRate":5.0,"eventId":"29681712","eventTypeId":"2","numberOfWinners":1,"bettingType":"ODDS","marketType":"MATCH_ODDS","marketTime":"2020-02-02T11:10:00.000Z","suspendTime":"2020-02-02T11:10:00.000Z","bspReconciled":false,"complete":true,"inPlay":false,"crossMatching":true,"runnersVoidable":false,"numberOfActiveRunners":2,"betDelay":0,"status":"OPEN","runners":[{"status":"ACTIVE","sortPriority":1,"id":10303696,"name":"Hugo Gaston"},{"status":"ACTIVE","sortPriority":2,"id":2257317,"name":"Nicolas Mahut"}],"regulators":["MR_INT"],"countryCode":"FR","discountAllowed":true,"timezone":"UTC","openDate":"2020-02-02T11:19:00.000Z","version":3148499313,"name":"Match Odds","eventName":"Hug Gaston v Mahut"}}]}
{"op":"mcm","clk":"1005237918","pt":1580641618828,"mc":[{"id":"1.168224294","marketDefinition":{"bspMarket":false,"turnInPlayEnabled":true,"persistenceEnabled":true,"marketBaseRate":5.0,"eventId":"29681712","eventTypeId":"2","numberOfWinners":1,"bettingType":"ODDS","marketType":"MATCH_ODDS","marketTime":"2020-02-02T11:10:00.000Z","suspendTime":"2020-02-02T11:10:00.000Z","bspReconciled":false,"complete":true,"inPlay":false,"crossMatching":true,"runnersVoidable":false,"numberOfActiveRunners":2,"betDelay":0,"status":"OPEN","runners":[{"status":"ACTIVE","sortPriority":1,"id":10303696,"name":"Hugo Gaston"},{"status":"ACTIVE","sortPriority":2,"id":2257317,"name":"Nicolas Mahut"}],"regulators":["MR_INT"],"countryCode":"FR","discountAllowed":true,"timezone":"UTC","openDate":"2020-02-02T11:10:00.000Z","version":3148499313,"name":"Match Odds","eventName":"Hug Gaston v Mahut"}}]}
{"op":"mcm","clk":"1005250573","pt":1580641681379,"mc":[{"id":"1.168224294","rc":[{"batl":[[0,1.89,74.21],[1,1.9,20.26],[2,2.08,9.25]],"ltp":1.86,"tv":277.35,"id":2257317}]}]}
{"op":"mcm","clk":"1005250769","pt":1580641682289,"mc":[{"id":"1.168224294","rc":[{"batb":[[1,2.06,23.78],[2,2.04,24.24]],"ltp":2.16,"tv":246.27,"id":10303696}]}]}
{"op":"mcm","clk":"1005259828","pt":1580641728318,"mc":[{"id":"1.168224294","rc":[{"batb":[[0,1.83,7.57],[1,1.81,82.9],[2,1.78,38.72]],"ltp":1.86,"tv":277.35,"id":2257317},{"batb":[[0,2.08,111.95]],"ltp":2.16,"tv":246.27,"id":10303696}]}]}
{"op":"mcm","clk":"1005272401","pt":1580641793010,"mc":[{"id":"1.168224294","rc":[{"trd":[[1.83,7.24]],"batb":[[0,1.83,7.56]],"ltp":1.83,"tv":277.38,"id":2257317}],"tv":523.65}]}
{"op":"mcm","clk":"1005272772","pt":1580641794915,"mc":[{"id":"1.168224294","rc":[{"trd":[[1.84,0.04]],"ltp":1.84,"tv":277.42,"id":2257317}],"tv":523.69}]}
{"op":"mcm","clk":"1005278032","pt":1580641823336,"mc":[{"id":"1.168224294","rc":[{"batb":[[0,1.84,224.72],[1,1.83,7.56],[2,1.81,160.4]],"ltp":1.84,"tv":277.42,"id":2257317},{"batb":[[0,2.1,99.53],[1,2.08,111.95],[2,2.06,23.78]],"ltp":2.16,"tv":246.27,"id":10303696}]}]}
{"op":"mcm","clk":"1005278222","pt":1580641824341,"mc":[{"id":"1.168224294","rc":[{"batb":[[1,2.08,88.61]],"ltp":2.16,"tv":246.27,"id":10303696}]}]}
{"op":"mcm","clk":"1005283742","pt":1580641853585,"mc":[{"id":"1.168224294","rc":[{"batb":[[1,1.83,7.57]],"ltp":1.84,"tv":277.42,"id":2257317}]}]}
{"op":"mcm","clk":"1005285138","pt":1580641860898,"mc":[{"id":"1.168224294","rc":[{"batb":[[0,2.12,44.32],[1,2.1,99.53]],"ltp":2.16,"tv":246.27,"id":10303696}]}]}
{"op":"mcm","clk":"1005286309","pt":1580641867308,"mc":[{"id":"1.168224294","rc":[{"trd":[[1.89,148.41],[1.9,90],[1.91,109.43],[1.95,25.12],[1.97,25.11],[2,37.86],[2.04,0.25],[2.08,18.5],[2.24,30.59],[2.4,30.29]],"batb":[[0,1.83,7.57],[1,1.81,77.5],[2,1.78,6.41]],"batl":[[0,1.97,396.21],[1,2.5,10.13],[2,2.6,74.21]],"ltp":2.4,"tv":792.98,"id":2257317},{"trd":[[1.81,37.86],[1.98,0.26],[2,37.86],[2.04,24.24],[2.06,23.78],[2.1,99.53],[2.12,44.32]],"batb":[[0,1.71,37.86],[1,1.61,37.86],[2,1.51,37.86]],"ltp":1.81,"tv":514.12,"id":10303696}],"tv":1307.11}]}
{"op":"mcm","clk":"1005286499","pt":1580641868328,"mc":[{"id":"1.168224294","rc":[{"batb":[[0,1.84,61.63],[1,1.83,83.19],[2,1.81,31.12]],"ltp":2.4,"tv":792.98,"id":2257317},{"batb":[[0,2.08,134.1],[1,1.81,37.86],[2,1.73,227.17]],"ltp":1.81,"tv":514.12,"id":10303696}]}]}
{"op":"mcm","clk":"1005286669","pt":1580641869339,"mc":[{"id":"1.168224294","rc":[{"batb":[[0,1.84,131.81],[1,1.83,113.55]],"ltp":2.4,"tv":792.98,"id":2257317},{"trd":[[2.08,264.89]],"batb":[[0,2.08,1.65],[1,2.04,46.51],[2,2,25.21]],"ltp":2.08,"tv":779.01,"id":10303696}],"tv":1571.99}]}
{"op":"mcm","clk":"1005286831","pt":1580641870305,"mc":[{"id":"1.168224294","rc":[{"batb":[[2,2.02,24.71]],"ltp":2.08,"tv":779.01,"id":10303696}]}]}
{"op":"mcm","clk":"1005288384","pt":1580641878348,"mc":[{"id":"1.168224294","rc":[{"batb":[[0,1.88,73.57],[1,1.84,161.81],[2,1.83,37.94]],"ltp":2.4,"tv":792.98,"id":2257317},{"batb":[[0,2.06,105.28]],"ltp":2.08,"tv":779.01,"id":10303696}]}]}
{"op":"mcm","clk":"1005288580","pt":1580641879352,"mc":[{"id":"1.168224294","rc":[{"batb":[[1,1.86,216.11],[2,1.85,74.21]],"ltp":2.4,"tv":792.98,"id":2257317},{"trd":[[2.06,120.86]],"batb":[[0,2.06,56.73],[2,2,25.21]],"ltp":2.06,"tv":876.09,"id":10303696}],"tv":1669.08}]}
{"op":"mcm","clk":"1005289171","pt":1580641882350,"mc":[{"id":"1.168224294","rc":[{"batb":[[2,1.85,103.86]],"ltp":2.4,"tv":792.98,"id":2257317},{"trd":[[2.06,259.58]],"batb":[[0,2.04,46.51],[1,2,25.21],[2,1.81,37.86]],"batl":[[0,2.5,10.8]],"ltp":2.06,"tv":1014.81,"id":10303696}],"tv":1807.8}]}
{"op":"mcm","clk":"1005289720","pt":1580641885334,"mc":[{"id":"1.168224294","rc":[{"batl":[[2,2.96,153.72]],"ltp":2.4,"tv":792.98,"id":2257317}]}]}
{"op":"mcm","clk":"1005289909","pt":1580641886344,"mc":[{"id":"1.168224294","rc":[{"trd":[[1.88,142.96],[1.94,0.71]],"batb":[[0,1.88,2.08],[2,1.85,74.21]],"batl":[[0,1.96,74.21],[1,1.97,396.21],[2,2.5,10.13]],"ltp":1.88,"tv":936.66,"id":2257317},{"trd":[[2.06,260.25]],"batl":[[0,2.5,10.13]],"ltp":2.06,"tv":1015.48,"id":10303696}],"tv":1952.14}]}
{"op":"mcm","clk":"1005290305","pt":1580641888350,"mc":[{"id":"1.168224294","rc":[{"batb":[[0,1.89,72.78],[2,1.85,103.86]],"ltp":1.88,"tv":936.66,"id":2257317},{"batb":[[0,2.04,152.89],[1,1.99,25.46]],"ltp":2.06,"tv":1015.48,"id":10303696}]}]}
{"op":"mcm","clk":"1005291191","pt":1580641893066,"mc":[{"id":"1.168224294","rc":[{"trd":[[1.89,149.53]],"batb":[[0,1.89,72.22]],"ltp":1.89,"tv":937.78,"id":2257317}],"tv":1953.26}]}
{"op":"mcm","clk":"1005292301","pt":1580641899070,"mc":[{"id":"1.168224294","rc":[{"batb":[[1,1.85,103.86],[2,1.84,161.81]],"ltp":1.89,"tv":937.78,"id":2257317}]}]}
{"op":"mcm","clk":"1005294450","pt":1580641909876,"mc":[{"id":"1.168224294","rc":[{"batb":[[0,2.04,239.43]],"ltp":2.06,"tv":1015.48,"id":10303696}]}]}
{"op":"mcm","clk":"1005294742","pt":1580641911370,"mc":[{"id":"1.168224294","rc":[{"trd":[[1.89,291.98]],"batb":[[0,1.88,75.04]],"ltp":1.89,"tv":1080.22,"id":2257317},{"batb":[[0,2.06,104.57],[1,2.04,239.43],[2,2.02,24.71]],"ltp":2.06,"tv":1015.48,"id":10303696}],"tv":2095.71}]}
{"op":"mcm","clk":"1005294946","pt":1580641912377,"mc":[{"id":"1.168224294","rc":[{"batb":[[0,1.88,74.04],[1,1.85,74.21]],"ltp":1.89,"tv":1080.22,"id":2257317},{"batb":[[1,2.04,133.05],[2,2,25.21]],"ltp":2.06,"tv":1015.48,"id":10303696}]}]}
{"op":"mcm","clk":"1005295265","pt":1580641914070,"mc":[{"id":"1.168224294","marketDefinition":{"bspMarket":false,"turnInPlayEnabled":true,"persistenceEnabled":true,"marketBaseRate":5.0,"eventId":"29681712","eventTypeId":"2","numberOfWinners":1,"bettingType":"ODDS","marketType":"MATCH_ODDS","marketTime":"2020-02-02T11:08:00.000Z","suspendTime":"2020-02-02T11:08:00.000Z","bspReconciled":false,"complete":true,"inPlay":false,"crossMatching":true,"runnersVoidable":false,"numberOfActiveRunners":2,"betDelay":0,"status":"OPEN","runners":[{"status":"ACTIVE","sortPriority":1,"id":10303696,"name":"Hugo Gaston"},{"status":"ACTIVE","sortPriority":2,"id":2257317,"name":"Nicolas Mahut"}],"regulators":["MR_INT"],"countryCode":"FR","discountAllowed":true,"timezone":"UTC","openDate":"2020-02-02T11:10:00.000Z","version":3148508258,"name":"Match Odds","eventName":"Hug Gaston v Mahut"}}]}
{"op":"mcm","clk":"1005295749","pt":1580641916624,"mc":[{"id":"1.168224294","marketDefinition":{"bspMarket":false,"turnInPlayEnabled":true,"persistenceEnabled":true,"marketBaseRate":5.0,"eventId":"29681712","eventTypeId":"2","numberOfWinners":1,"bettingType":"ODDS","marketType":"MATCH_ODDS","marketTime":"2020-02-02T11:08:00.000Z","suspendTime":"2020-02-02T11:08:00.000Z","bspReconciled":false,"complete":true,"inPlay":false,"crossMatching":true,"runnersVoidable":false,"numberOfActiveRunners":2,"betDelay":0,"status":"OPEN","runners":[{"status":"ACTIVE","sortPriority":1,"id":10303696,"name":"Hugo Gaston"},{"status":"ACTIVE","sortPriority":2,"id":2257317,"name":"Nicolas Mahut"}],"regulators":["MR_INT"],"countryCode":"FR","discountAllowed":true,"timezone":"UTC","openDate":"2020-02-02T11:08:00.000Z","version":3148508258,"name":"Match Odds","eventName":"Hug Gaston v Mahut"}}]}
{"op":"mcm","clk":"1005299499","pt":1580641937384,"mc":[{"id":"1.168224294","rc":[{"batl":[[0,1.94,74.21]],"ltp":1.89,"tv":1080.22,"id":2257317}]}]}
{"op":"mcm","clk":"1005299554","pt":1580641937760,"mc":[{"id":"1.168224294","rc":[{"trd":[[1.88,289.41]],"batb":[[0,1.85,75.02],[1,1.84,161.81],[2,1.83,37.94]],"ltp":1.88,"tv":1226.67,"id":2257317}],"tv":2242.15}]}
{"op":"mcm","clk":"1005299870","pt":1580641939348,"mc":[{"id":"1.168224294","rc":[{"batb":[[0,1.87,75.22],[1,1.85,74.21],[2,1.84,131.81]],"ltp":1.88,"tv":1226.67,"id":2257317},{"batb":[[0,2.06,102.76]],"ltp":2.06,"tv":1015.48,"id":10303696}]}]}
{"op":"mcm","clk":"1005300054","pt":1580641940403,"mc":[{"id":"1.168224294","rc":[{"batb":[[2,2.02,24.71]],"ltp":2.06,"tv":1015.48,"id":10303696}]}]}
{"op":"mcm","clk":"1005310219","pt":1580642000347,"mc":[{"id":"1.168224294","rc":[{"batb":[[2,1.83,37.94]],"ltp":1.88,"tv":1226.67,"id":2257317}]}]}
{"op":"mcm","clk":"1005310291","pt":1580642000866,"mc":[{"id":"1.168224294","rc":[{"trd":[[1.87,28.28],[1.88,424.79]],"batb":[[0,1.87,68.65]],"ltp":1.87,"tv":1375.18,"id":2257317}],"tv":2390.67}]}
{"op":"mcm","clk":"1005310474","pt":1580642001967,"mc":[{"id":"1.168224294","rc":[{"batb":[[0,1.86,75.38]],"ltp":1.87,"tv":1375.18,"id":2257317},{"batb":[[0,2.06,102.6]],"ltp":2.06,"tv":1015.48,"id":10303696}]}]}
{"op":"mcm","clk":"1005310664","pt":1580642002936,"mc":[{"id":"1.168224294","rc":[{"batb":[[0,1.86,106.85]],"ltp":1.87,"tv":1375.18,"id":2257317},{"batb":[[0,2.08,60.88],[1,2.06,102.6],[2,2.04,86.54]],"ltp":2.06,"tv":1015.48,"id":10303696}]}]}
{"op":"mcm","clk":"1005310760","pt":1580642003466,"mc":[{"id":"1.168224294","rc":[{"batb":[[2,1.83,7.57]],"ltp":1.87,"tv":1375.18,"id":2257317}]}]}
{"op":"mcm","clk":"1005312367","pt":1580642012870,"mc":[{"id":"1.168224294","rc":[{"batb":[[0,1.87,214.81],[1,1.86,106.85],[2,1.85,74.21]],"ltp":1.87,"tv":1375.18,"id":2257317}]}]}
{"op":"mcm","clk":"1005313611","pt":1580642020359,"mc":[{"id":"1.168224294","rc":[{"batb":[[0,1.87,218.26]],"ltp":1.87,"tv":1375.18,"id":2257317}]}]}
{"op":"mcm","clk":"1005313782","pt":1580642021375,"mc":[{"id":"1.168224294","rc":[{"trd":[[1.87,286.28]],"batb":[[0,1.87,3.45]],"ltp":1.87,"tv":1633.18,"id":2257317}],"tv":2648.67}]}
{"op":"mcm","clk":"1005316993","pt":1580642039584,"mc":[{"id":"1.168224294","rc":[{"trd":[[2.08,265.86]],"batb":[[0,2.08,60.39]],"ltp":2.08,"tv":1016.45,"id":10303696}],"tv":2649.64}]}
{"op":"mcm","clk":"1005319973","pt":1580642054856,"mc":[{"id":"1.168224294","rc":[{"batb":[[0,1.87,3.49]],"ltp":1.87,"tv":1633.18,"id":2257317}]}]}
{"op":"mcm","clk":"1005320837","pt":1580642059702,"mc":[{"id":"1.168224294","rc":[{"batb":[[0,1.87,77.7],[2,1.82,30.76]],"ltp":1.87,"tv":1633.18,"id":2257317}]}]}
{"op":"mcm","clk":"1005321052","pt":1580642060939,"mc":[{"id":"1.168224294","rc":[{"trd":[[1.87,438.77],[1.89,292.06]],"batb":[[0,1.87,1.42],[2,1.83,30.38]],"ltp":1.87,"tv":1785.74,"id":2257317}],"tv":2802.2}]}
{"op":"mcm","clk":"1005321160","pt":1580642061504,"mc":[{"id":"1.168224294","rc":[{"batb":[[2,1.82,30.76]],"ltp":1.87,"tv":1785.74,"id":2257317}]}]}
{"op":"mcm","clk":"1005323040","pt":1580642072224,"mc":[{"id":"1.168224294","rc":[{"batl":[[0,1.92,74.21]],"ltp":1.87,"tv":1785.74,"id":2257317}]}]}
{"op":"mcm","clk":"1005323909","pt":1580642076925,"mc":[{"id":"1.168224294","rc":[{"trd":[[1.86,326.55],[1.87,441.6]],"batb":[[0,1.86,1.17],[1,1.82,30.76],[2,1.81,68.98]],"ltp":1.86,"tv":1999.94,"id":2257317}],"tv":3016.4}]}
{"op":"mcm","clk":"1005324117","pt":1580642078032,"mc":[{"id":"1.168224294","rc":[{"batb":[[0,1.84,300.11],[1,1.82,67.44],[2,1.81,37.86]],"ltp":1.86,"tv":1999.94,"id":2257317},{"batb":[[0,2.1,26.68],[1,2.08,161.18]],"ltp":2.08,"tv":1016.45,"id":10303696}]}]}
{"op":"mcm","clk":"1005324191","pt":1580642078460,"mc":[{"id":"1.168224294","rc":[{"batb":[[2,2.04,110.78]],"ltp":2.08,"tv":1016.45,"id":10303696}]}]}
{"op":"mcm","clk":"1005324967","pt":1580642082826,"mc":[{"id":"1.168224294","rc":[{"batb":[[2,1.8,31.51]],"batl":[[0,1.89,3.41],[1,1.92,74.21],[2,1.97,396.21]],"ltp":1.86,"tv":1999.94,"id":2257317}]}]}
{"op":"mcm","clk":"1005325963","pt":1580642088813,"mc":[{"id":"1.168224294","rc":[{"batb":[[0,1.84,76.64]],"ltp":1.86,"tv":1999.94,"id":2257317}]}]}
{"op":"mcm","clk":"1005331123","pt":1580642116816,"mc":[{"id":"1.168224294","rc":[{"batb":[[0,1.85,222.37],[1,1.84,76.64],[2,1.82,67.44]],"ltp":1.86,"tv":1999.94,"id":2257317}]}]}
{"op":"mcm","clk":"1005333808","pt":1580642132058,"mc":[{"id":"1.168224294","rc":[{"batb":[[0,1.86,159.64],[1,1.85,222.37],[2,1.84,76.64]],"batl":[[1,1.9,156.28],[2,1.92,74.21]],"ltp":1.86,"tv":1999.94,"id":2257317}]}]}
{"op":"mcm","clk":"1005334025","pt":1580642133280,"mc":[{"id":"1.168224294","rc":[{"batb":[[0,2.12,37.9],[1,2.1,26.68],[2,2.08,100.79]],"ltp":2.08,"tv":1016.45,"id":10303696}]}]}
{"op":"mcm","clk":"1005334165","pt":1580642134036,"mc":[{"id":"1.168224294","rc":[{"trd":[[1.86,506.55]],"batb":[[0,1.86,69.64]],"ltp":1.86,"tv":2179.94,"id":2257317}],"tv":3196.4}]}
{"op":"mcm","clk":"1005335622","pt":1580642142377,"mc":[{"id":"1.168224294","rc":[{"trd":[[1.89,298.52],[1.9,246.27],[1.92,74.21]],"batb":[[1,1.84,76.64],[2,1.82,67.44]],"batl":[[0,1.96,398.24],[1,2.5,10.13],[2,2.96,153.72]],"ltp":1.92,"tv":2416.89,"id":2257317},{"trd":[[2.04,181.52],[2.08,535.93],[2.1,294.28],[2.12,120.44]],"batb":[[0,2.04,32.14],[1,2.02,24.71],[2,1.81,37.86]],"ltp":2.04,"tv":1714.68,"id":10303696}],"tv":4131.57}]}
{"op":"mcm","clk":"1005335757","pt":1580642143190,"mc":[{"id":"1.168224294","rc":[{"trd":[[1.93,170.38]],"batb":[[0,1.87,147.6],[1,1.86,69.64],[2,1.84,76.64]],"ltp":1.93,"tv":2587.27,"id":2257317},{"trd":[[2.08,694.02]],"batb":[[0,2.08,296.93],[1,2.06,135.91],[2,2.04,32.14]],"ltp":2.08,"tv":1872.77,"id":10303696}],"tv":4460.05}]}
{"op":"mcm","clk":"1005335826","pt":1580642143570,"mc":[{"id":"1.168224294","rc":[{"batb":[[2,2.04,7.9]],"ltp":2.08,"tv":1872.77,"id":10303696}]}]}
{"op":"mcm","clk":"1005336119","pt":1580642145273,"mc":[{"id":"1.168224294","rc":[{"batb":[[1,1.86,73.13]],"batl":[[0,1.92,7.57],[1,1.96,398.24],[2,2.5,10.13]],"ltp":1.93,"tv":2587.27,"id":2257317}]}]}
{"op":"mcm","clk":"1005336966","pt":1580642150059,"mc":[{"id":"1.168224294","rc":[{"batl":[[0,1.96,398.24],[1,2.5,10.13],[2,2.96,153.72]],"ltp":1.93,"tv":2587.27,"id":2257317}]}]}
{"op":"mcm","clk":"1005340187","pt":1580642168093,"mc":[{"id":"1.168224294","rc":[{"trd":[[1.87,713.61]],"batb":[[0,1.87,11.59]],"ltp":1.87,"tv":2859.28,"id":2257317}],"tv":4732.05}]}
{"op":"mcm","clk":"1005340337","pt":1580642168995,"mc":[{"id":"1.168224294","rc":[{"batb":[[0,1.86,148.97],[1,1.85,32.07]],"ltp":1.87,"tv":2859.28,"id":2257317},{"trd":[[2.08,1282.16]],"batb":[[0,2.1,52.04],[1,2.08,104.84]],"ltp":2.08,"tv":2460.91,"id":10303696}],"tv":5320.19}]}
{"op":"mcm","clk":"1005340526","pt":1580642170105,"mc":[{"id":"1.168224294","rc":[{"trd":[[1.86,521.61]],"batb":[[0,1.86,141.45]],"ltp":1.86,"tv":2874.34,"id":2257317},{"batb":[[2,2.04,32.14]],"ltp":2.08,"tv":2460.91,"id":10303696}],"tv":5335.25}]}
{"op":"mcm","clk":"1005342581","pt":1580642180737,"mc":[{"id":"1.168224294","rc":[{"batl":[[0,1.96,440.25]],"ltp":1.86,"tv":2874.34,"id":2257317},{"batb":[[2,2.04,72.47]],"batl":[[0,2.28,32.77],[1,2.5,10.13],[2,2.52,3.79]],"ltp":2.08,"tv":2460.91,"id":10303696}]}]}
{"op":"mcm","clk":"1005344937","pt":1580642193121,"mc":[{"id":"1.168224294","rc":[{"trd":[[1.86,799.74]],"batb":[[0,1.86,1.2]],"ltp":1.86,"tv":3152.47,"id":2257317},{"trd":[[2.18,2]],"ltp":2.18,"tv":2462.91,"id":10303696}],"tv":5615.38}]}
{"op":"mcm","clk":"1005345137","pt":1580642194229,"mc":[{"id":"1.168224294","rc":[{"batb":[[0,1.85,109.18],[1,1.81,31.14],[2,1.8,83.6]],"ltp":1.86,"tv":3152.47,"id":2257317},{"batb":[[1,2.08,103.03]],"ltp":2.18,"tv":2462.91,"id":10303696}]}]}
{"op":"mcm","clk":"1005347291","pt":1580642206121,"mc":[{"id":"1.168224294","rc":[{"batl":[[0,1.88,3.45],[1,1.96,440.25],[2,2.5,10.13]],"ltp":1.86,"tv":3152.47,"id":2257317}]}]}
{"op":"mcm","clk":"1005350194","pt":1580642222499,"mc":[{"id":"1.168224294","rc":[{"trd":[[1.88,431.21]],"batl":[[0,1.96,440.49],[1,2.5,10.13],[2,2.96,153.72]],"ltp":1.88,"tv":3158.89,"id":2257317}],"tv":5621.8}]}
{"op":"mcm","clk":"1005352238","pt":1580642233482,"mc":[{"id":"1.168224294","rc":[{"batb":[[0,1.86,216.11],[1,1.85,109.18],[2,1.81,31.14]],"ltp":1.88,"tv":3158.89,"id":2257317}]}]}
{"op":"mcm","clk":"1005356570","pt":1580642257357,"mc":[{"id":"1.168224294","rc":[{"batb":[[0,1.87,74.21],[1,1.86,216.11],[2,1.85,109.18]],"ltp":1.88,"tv":3158.89,"id":2257317}]}]}
{"op":"mcm","clk":"1005356729","pt":1580642258259,"mc":[{"id":"1.168224294","rc":[{"trd":[[1.88,578.61]],"batb":[[0,1.88,140.01],[1,1.87,74.21]],"batl":[[0,1.96,440.25]],"ltp":1.88,"tv":3306.29,"id":2257317}],"tv":5769.2}]}
{"op":"mcm","clk":"1005356849","pt":1580642258863,"mc":[{"id":"1.168224294","rc":[{"batb":[[0,1.87,74.21],[1,1.85,109.18],[2,1.82,30.76]],"ltp":1.88,"tv":3306.29,"id":2257317},{"batb":[[2,2.04,48.23]],"ltp":2.18,"tv":2462.91,"id":10303696}]}]}
{"op":"mcm","clk":"1005357005","pt":1580642259642,"mc":[{"id":"1.168224294","rc":[{"batb":[[0,1.87,291.02]],"ltp":1.88,"tv":3306.29,"id":2257317},{"batb":[[2,2.04,72.47]],"ltp":2.18,"tv":2462.91,"id":10303696}]}]}
{"op":"mcm","clk":"1005358251","pt":1580642266153,"mc":[{"id":"1.168224294","rc":[{"batb":[[1,1.85,77.11],[2,1.83,64.96]],"ltp":1.88,"tv":3306.29,"id":2257317}]}]}
{"op":"mcm","clk":"1005358629","pt":1580642268076,"mc":[{"id":"1.168224294","rc":[{"batb":[[0,1.88,74.21],[1,1.87,216.81],[2,1.85,77.11]],"ltp":1.88,"tv":3306.29,"id":2257317}]}]}
{"op":"mcm","clk":"1005358852","pt":1580642269258,"mc":[{"id":"1.168224294","rc":[{"batb":[[2,2.04,48.23]],"ltp":2.18,"tv":2462.91,"id":10303696}]}]}
{"op":"mcm","clk":"1005360419","pt":1580642277286,"mc":[{"id":"1.168224294","rc":[{"trd":[[1.88,725.54],[1.91,136.41]],"batb":[[0,1.87,217.55],[1,1.85,77.11],[2,1.83,64.96]],"ltp":1.88,"tv":3480.21,"id":2257317},{"trd":[[2.1,318.82]],"batb":[[0,2.1,27.5]],"ltp":2.1,"tv":2487.45,"id":10303696}],"tv":5967.66}]}
{"op":"mcm","clk":"1005360631","pt":1580642278332,"mc":[{"id":"1.168224294","rc":[{"batb":[[1,1.86,43.67],[2,1.85,77.11]],"ltp":1.88,"tv":3480.21,"id":2257317}]}]}
{"op":"mcm","clk":"1005360667","pt":1580642278542,"mc":[{"id":"1.168224294","rc":[{"batb":[[2,2.04,72.47]],"ltp":2.1,"tv":2487.45,"id":10303696}]}]}
{"op":"mcm","clk":"1005361952","pt":1580642285213,"mc":[{"id":"1.168224294","rc":[{"trd":[[1.91,139.47]],"batb":[[0,1.87,216.81]],"ltp":1.91,"tv":3483.27,"id":2257317},{"trd":[[2.1,321.6]],"batb":[[0,2.1,24.72]],"ltp":2.1,"tv":2490.23,"id":10303696}],"tv":5973.5}]}
{"op":"mcm","clk":"1005362059","pt":1580642285798,"mc":[{"id":"1.168224294","rc":[{"batb":[[1,1.86,46.79]],"ltp":1.91,"tv":3483.27,"id":2257317}]}]}
{"op":"mcm","clk":"1005365883","pt":1580642305316,"mc":[{"id":"1.168224294","rc":[{"trd":[[1.87,1142.65]],"batb":[[0,1.87,2.29]],"ltp":1.87,"tv":3912.31,"id":2257317},{"batl":[[0,2.16,16.8],[1,2.28,32.77],[2,2.5,10.13]],"ltp":2.1,"tv":2490.23,"id":10303696}],"tv":6402.54}]}
{"op":"mcm","clk":"1005365923","pt":1580642305532,"mc":[{"id":"1.168224294","rc":[{"batb":[[0,1.86,46.79],[1,1.85,77.11],[2,1.82,30.76]],"ltp":1.87,"tv":3912.31,"id":2257317}]}]}
{"op":"mcm","clk":"1005366259","pt":1580642307339,"mc":[{"id":"1.168224294","rc":[{"batl":[[0,2.14,16.8]],"ltp":2.1,"tv":2490.23,"id":10303696}]}]}
{"op":"mcm","clk":"1005370149","pt":1580642328076,"mc":[{"id":"1.168224294","rc":[{"trd":[[1.87,1156.93]],"ltp":1.87,"tv":3926.59,"id":2257317},{"trd":[[2.14,17.54]],"batl":[[0,2.14,4.31]],"ltp":2.14,"tv":2502.72,"id":10303696}],"tv":6429.32}]}
{"op":"mcm","clk":"1005370280","pt":1580642328660,"mc":[{"id":"1.168224294","rc":[{"trd":[[1.86,881.26],[1.87,1161.86]],"batb":[[0,1.86,6.03],[2,1.81,31.14]],"ltp":1.86,"tv":4013.04,"id":2257317},{"trd":[[2.14,21.85]],"batl":[[0,2.28,32.77],[1,2.5,10.13],[2,2.52,3.79]],"ltp":2.14,"tv":2507.03,"id":10303696}],"tv":6520.08}]}
{"op":"mcm","clk":"1005370739","pt":1580642330748,"mc":[{"id":"1.168224294","rc":[{"batb":[[0,1.85,77.11],[1,1.83,55],[2,1.81,31.12]],"ltp":1.86,"tv":4013.04,"id":2257317},{"batb":[[0,2.1,60.71]],"ltp":2.14,"tv":2507.03,"id":10303696}]}]}
{"op":"mcm","clk":"1005371562","pt":1580642334973,"mc":[{"id":"1.168224294","rc":[{"batb":[[0,1.86,3.49],[1,1.85,77.11],[2,1.83,55]],"ltp":1.86,"tv":4013.04,"id":2257317}]}]}
{"op":"mcm","clk":"1005383110","pt":1580642396164,"mc":[{"id":"1.168224294","rc":[{"batb":[[2,1.82,71.91]],"ltp":1.86,"tv":4013.04,"id":2257317}]}]}
{"op":"mcm","clk":"1005386011","pt":1580642411254,"mc":[{"id":"1.168224294","rc":[{"trd":[[2.1,323.08]],"batb":[[0,2.1,59.97]],"ltp":2.1,"tv":2508.51,"id":10303696}],"tv":6521.56}]}
{"op":"mcm","clk":"1005387160","pt":1580642417263,"mc":[{"id":"1.168224294","rc":[{"batb":[[0,1.86,77.53],[2,1.81,31.14]],"ltp":1.86,"tv":4013.04,"id":2257317},{"trd":[[2.1,442.58]],"batb":[[0,2.08,103.03],[1,2.06,45.75]],"ltp":2.1,"tv":2628.01,"id":10303696}],"tv":6641.05}]}
{"op":"mcm","clk":"1005387359","pt":1580642418354,"mc":[{"id":"1.168224294","rc":[{"batb":[[2,1.84,75.14]],"batl":[[0,1.96,398.24],[1,1.97,42.01],[2,2.5,10.13]],"ltp":1.86,"tv":4013.04,"id":2257317},{"trd":[[2.08,1482.48]],"batb":[[0,2.06,148.59],[1,2.04,48.23],[2,2.02,24.71]],"ltp":2.08,"tv":2828.33,"id":10303696}],"tv":6841.38}]}
{"op":"mcm","clk":"1005387443","pt":1580642418825,"mc":[{"id":"1.168224294","rc":[{"batb":[[0,1.87,213.81],[1,1.86,77.53]],"ltp":1.86,"tv":4013.04,"id":2257317},{"trd":[[2.06,384.5]],"batb":[[0,2.06,86.46]],"ltp":2.06,"tv":2952.58,"id":10303696}],"tv":6965.63}]}
{"op":"mcm","clk":"1005387549","pt":1580642419557,"mc":[{"id":"1.168224294","rc":[{"batb":[[2,1.84,105.14]],"ltp":1.86,"tv":4013.04,"id":2257317}]}]}
{"op":"mcm","clk":"1005388013","pt":1580642422160,"mc":[{"id":"1.168224294","rc":[{"batb":[[0,1.88,92.27],[1,1.87,213.81],[2,1.86,3.49]],"ltp":1.86,"tv":4013.04,"id":2257317}]}]}
{"op":"mcm","clk":"1005388172","pt":1580642422855,"mc":[{"id":"1.168224294","rc":[{"batb":[[0,1.89,211.41],[1,1.88,92.27]],"ltp":1.86,"tv":4013.04,"id":2257317},{"batb":[[2,2,25.21]],"ltp":2.06,"tv":2952.58,"id":10303696}]}]}
{"op":"mcm","clk":"1005388481","pt":1580642424464,"mc":[{"id":"1.168224294","rc":[{"batb":[[0,1.88,92.27],[1,1.86,3.49],[2,1.84,105.14]],"ltp":1.86,"tv":4013.04,"id":2257317}]}]}
{"op":"mcm","clk":"1005389093","pt":1580642428061,"mc":[{"id":"1.168224294","rc":[{"batb":[[1,1.84,30],[2,1.83,30.38]],"ltp":1.86,"tv":4013.04,"id":2257317},{"batb":[[0,2.04,48.23],[1,2,25.21],[2,1.96,126.11]],"ltp":2.06,"tv":2952.58,"id":10303696}]}]}
{"op":"mcm","clk":"1005389199","pt":1580642428705,"mc":[{"id":"1.168224294","marketDefinition":{"bspMarket":false,"turnInPlayEnabled":true,"persistenceEnabled":true,"marketBaseRate":5.0,"eventId":"29681712","eventTypeId":"2","numberOfWinners":1,"bettingType":"ODDS","marketType":"MATCH_ODDS","marketTime":"2020-02-02T11:08:00.000Z","suspendTime":"2020-02-02T11:08:00.000Z","bspReconciled":false,"complete":true,"inPlay":true,"crossMatching":true,"runnersVoidable":false,"numberOfActiveRunners":2,"betDelay":3,"status":"OPEN","runners":[{"status":"ACTIVE","sortPriority":1,"id":10303696,"name":"Hugo Gaston"},{"status":"ACTIVE","sortPriority":2,"id":2257317,"name":"Nicolas Mahut"}],"regulators":["MR_INT"],"countryCode":"FR","discountAllowed":true,"timezone":"UTC","openDate":"2020-02-02T11:08:00.000Z","version":3148525268,"name":"Match Odds","eventName":"Hug Gaston v Mahut"},"rc":[{"batb":[[0,1.11,37.98],[1,1.03,9],[2,1.02,25.41]],"batl":[[1,2.5,10.13],[2,3,42.01]],"ltp":1.86,"tv":4013.04,"id":2257317},{"batb":[[0,1.77,20.32],[1,1.11,37.97],[2,1.03,9]],"batl":[[0,2.5,10.13],[1,1000,0.02],[2,2.52,0]],"ltp":2.06,"tv":2952.58,"id":10303696}]}]}
{"op":"mcm","clk":"1005390939","pt":1580642438273,"mc":[{"id":"1.168224294","rc":[{"trd":[[1.92,472.39]],"batl":[[1,2.02,504],[2,2.5,10.13]],"ltp":1.92,"tv":4411.22,"id":2257317},{"trd":[[2.08,1850.04]],"batl":[[0,2.08,2518.44],[1,2.12,393],[2,2.16,7.69]],"ltp":2.08,"tv":3320.14,"id":10303696}],"tv":7731.37}]}
{"op":"mcm","clk":"1005391132","pt":1580642439381,"mc":[{"id":"1.168224294","rc":[{"batb":[[0,1.94,66.33],[1,1.84,78.68],[2,1.11,37.98]],"ltp":1.92,"tv":4411.22,"id":2257317},{"batb":[[0,1.98,117],[1,1.94,63.18],[2,1.77,20.32]],"batl":[[0,2.12,393],[1,2.16,7.69],[2,2.2,429.99]],"ltp":2.08,"tv":3320.14,"id":10303696}]}]}
{"op":"mcm","clk":"1005391169","pt":1580642439597,"mc":[{"id":"1.168224294","rc":[{"batb":[[1,1.86,48.73],[2,1.84,78.68]],"batl":[[2,2.04,40.33]],"ltp":1.92,"tv":4411.22,"id":2257317},{"batb":[[1,1.95,43.69],[2,1.94,63.18]],"batl":[[2,2.18,35.29]],"ltp":2.08,"tv":3320.14,"id":10303696}]}]}
{"op":"mcm","clk":"1005392060","pt":1580642444383,"mc":[{"id":"1.168224294","rc":[{"trd":[[1.94,34.21]],"batb":[[0,1.94,49.58]],"ltp":1.94,"tv":4444.72,"id":2257317}],"tv":7764.87}]}
{"op":"mcm","clk":"1005392607","pt":1580642447277,"mc":[{"id":"1.168224294","rc":[{"batb":[[0,1.86,48.73],[1,1.84,78.68],[2,1.11,37.98]],"batl":[[1,2.04,40.33],[2,2.5,10.13]],"ltp":1.94,"tv":4444.72,"id":2257317},{"batb":[[0,1.95,43.69],[1,1.94,62.95],[2,1.77,20.32]],"batl":[[0,2.18,35.29],[1,2.5,10.13],[2,1000,0.02]],"ltp":2.08,"tv":3320.14,"id":10303696}]}]}
{"op":"mcm","clk":"1005392859","pt":1580642448667,"mc":[{"id":"1.168224294","rc":[{"batb":[[0,1.84,78.68],[1,1.11,37.98],[2,1.03,9]],"batl":[[1,2.5,10.13],[2,3,42.01]],"ltp":1.94,"tv":4444.72,"id":2257317},{"batb":[[0,1.94,62.95],[1,1.77,20.32],[2,1.11,37.97]],"batl":[[0,2.5,10.13],[1,1000,0.02],[2,1000,0]],"ltp":2.08,"tv":3320.14,"id":10303696}]}]}
{"op":"mcm","clk":"1005395321","pt":1580642462235,"mc":[{"id":"1.168224294","rc":[{"trd":[[1.84,30.34]],"batb":[[0,1.84,63.53],[1,1.74,548.8],[2,1.11,37.96]],"batl":[[0,1.86,774.58],[1,1.9,477],[2,1.96,398.24]],"ltp":1.84,"tv":4475.02,"id":2257317},{"batl":[[0,2.28,509.88],[1,2.5,10.13],[2,1000,0.02]],"ltp":2.08,"tv":3320.14,"id":10303696}],"tv":7795.17}]}
{"op":"mcm","clk":"1005395475","pt":1580642463030,"mc":[{"id":"1.168224294","rc":[{"batb":[[2,1.71,99.53]],"ltp":1.84,"tv":4475.02,"id":2257317},{"batb":[[0,2.1,97.64],[1,2.02,110.55],[2,1.77,20.32]],"ltp":2.08,"tv":3320.14,"id":10303696}]}]}
{"op":"mcm","clk":"1005395627","pt":1580642463923,"mc":[{"id":"1.168224294","rc":[{"batb":[[1,1.77,53.79],[2,1.74,548.78]],"batl":[[2,1.93,42.01]],"ltp":1.84,"tv":4475.02,"id":2257317},{"batb":[[1,2.06,39.49],[2,2.02,110.55]],"batl":[[1,2.32,31.09],[2,2.5,10.13]],"ltp":2.08,"tv":3320.14,"id":10303696}]}]}
{"op":"mcm","clk":"1005396930","pt":1580642471271,"mc":[{"id":"1.168224294","rc":[{"batb":[[2,1.71,99.53]],"batl":[[0,1.93,42.01],[1,1.96,398.24],[2,2.5,10.13]],"ltp":1.84,"tv":4475.02,"id":2257317},{"batl":[[0,2.32,31.09],[1,2.5,10.13],[2,1000,0.02]],"ltp":2.08,"tv":3320.14,"id":10303696}]}]}
{"op":"mcm","clk":"1005397004","pt":1580642471757,"mc":[{"id":"1.168224294","rc":[{"batb":[[0,1.77,53.79],[1,1.71,99.53],[2,1.11,37.96]],"ltp":1.84,"tv":4475.02,"id":2257317},{"batb":[[0,2.06,39.49],[1,2.02,110.15],[2,1.77,20.32]],"ltp":2.08,"tv":3320.14,"id":10303696}]}]}
{"op":"mcm","clk":"1005397159","pt":1580642472550,"mc":[{"id":"1.168224294","rc":[{"batb":[[0,1.71,99.55],[1,1.11,37.96],[2,1.1,568.02]],"batl":[[0,1.96,398.24],[1,2.5,10.13],[2,3,42.01]],"ltp":1.84,"tv":4475.02,"id":2257317},{"batb":[[0,2.02,110.15],[1,1.77,20.32],[2,1.11,37.97]],"batl":[[0,2.5,10.13],[1,1000,0.02],[2,1000,0]],"ltp":2.08,"tv":3320.14,"id":10303696}]}]}
{"op":"mcm","clk":"1005397404","pt":1580642473973,"mc":[{"id":"1.168224294","rc":[{"batb":[[1,1.2,284.06],[2,1.11,37.86]],"ltp":1.84,"tv":4475.02,"id":2257317},{"batb":[[2,1.2,284.07]],"ltp":2.08,"tv":3320.14,"id":10303696}]}]}
{"op":"mcm","clk":"1005398048","pt":1580642477386,"mc":[{"id":"1.168224294","rc":[{"batb":[[1,1.3,113.58],[2,1.2,284.06]],"ltp":1.84,"tv":4475.02,"id":2257317},{"batb":[[2,1.4,75.73]],"ltp":2.08,"tv":3320.14,"id":10303696}]}]}
{"op":"mcm","clk":"1005398586","pt":1580642480664,"mc":[{"id":"1.168224294","rc":[{"batb":[[2,1.5,113.58]],"ltp":2.08,"tv":3320.14,"id":10303696}]}]}
{"op":"mcm","clk":"1005400541","pt":1580642491900,"mc":[{"id":"1.168224294","rc":[{"batb":[[1,1.5,20],[2,1.3,113.58]],"ltp":1.84,"tv":4475.02,"id":2257317}]}]}
{"op":"mcm","clk":"1005403117","pt":1580642506829,"mc":[{"id":"1.168224294","rc":[{"trd":[[1.71,9.5],[1.83,7.28]],"batb":[[0,1.71,90.03]],"batl":[[0,1.76,516],[1,1.96,398.24],[2,2.5,10.13]],"ltp":1.71,"tv":4484.56,"id":2257317},{"trd":[[2.42,6.71]],"batb":[[0,2.4,540.84],[1,2.02,110.15],[2,1.77,20.32]],"batl":[[0,2.5,366.73],[1,2.66,522.49],[2,1000,0.02]],"ltp":2.42,"tv":3326.85,"id":10303696}],"tv":7811.41}]}
{"op":"mcm","clk":"1005403302","pt":1580642507796,"mc":[{"id":"1.168224294","rc":[{"batb":[[1,1.67,62.17],[2,1.57,135.41]],"ltp":1.71,"tv":4484.56,"id":2257317},{"batb":[[1,2.3,75.69],[2,2.16,91.66]],"batl":[[0,2.5,394.46]],"ltp":2.42,"tv":3326.85,"id":10303696}]}]}
{"op":"mcm","clk":"1005404270","pt":1580642513320,"mc":[{"id":"1.168224294","rc":[{"batb":[[1,1.68,494.03],[2,1.67,62.17]],"batl":[[0,1.76,996.59],[1,1.78,497.4],[2,1.96,398.24]],"ltp":1.71,"tv":4484.56,"id":2257317},{"trd":[[2.4,21.18]],"batb":[[0,2.4,530.25]],"ltp":2.4,"tv":3348.03,"id":10303696}],"tv":7832.59}]}
{"op":"mcm","clk":"1005404979","pt":1580642517321,"mc":[{"id":"1.168224294","rc":[{"batb":[[0,1.68,494.03],[1,1.67,62.17],[2,1.66,510.84]],"batl":[[0,1.76,480.59]],"ltp":1.71,"tv":4484.56,"id":2257317},{"batb":[[0,2.16,91.66],[1,2.02,110.15],[2,1.77,20.32]],"batl":[[0,2.5,37.86],[1,1000,0.02],[2,1000,0]],"ltp":2.4,"tv":3348.03,"id":10303696}]}]}
{"op":"mcm","clk":"1005405224","pt":1580642518601,"mc":[{"id":"1.168224294","rc":[{"batb":[[1,1.66,510.84],[2,1.57,135.41]],"ltp":1.71,"tv":4484.56,"id":2257317},{"batl":[[0,2.5,10.13]],"ltp":2.4,"tv":3348.03,"id":10303696}]}]}
{"op":"mcm","clk":"1005405625","pt":1580642520659,"mc":[{"id":"1.168224294","rc":[{"batb":[[2,1.56,135.65]],"ltp":1.71,"tv":4484.56,"id":2257317},{"batb":[[0,2.16,91.51],[1,1.77,20.32],[2,1.5,113.58]],"ltp":2.4,"tv":3348.03,"id":10303696}]}]}
{"op":"mcm","clk":"1005406776","pt":1580642526662,"mc":[{"id":"1.168224294","rc":[{"batb":[[2,1.6,75.72]],"ltp":2.4,"tv":3348.03,"id":10303696}]}]}
{"op":"mcm","clk":"1005407416","pt":1580642529947,"mc":[{"id":"1.168224294","rc":[{"batb":[[2,1.7,75.72]],"ltp":2.4,"tv":3348.03,"id":10303696}]}]}
{"op":"mcm","clk":"1005408064","pt":1580642533365,"mc":[{"id":"1.168224294","rc":[{"batb":[[0,1.56,135.65],[1,1.5,20],[2,1.3,113.58]],"ltp":1.71,"tv":4484.56,"id":2257317}]}]}
{"op":"mcm","clk":"1005408559","pt":1580642536162,"mc":[{"id":"1.168224294","rc":[{"trd":[[1.56,25.52]],"batb":[[0,1.56,122.89],[2,1.25,378.62]],"batl":[[0,1.6,603],[1,1.76,480.59],[2,1.78,497.4]],"ltp":1.56,"tv":4510.08,"id":2257317},{"trd":[[2.5,20.27]],"batb":[[0,2.64,155.15],[1,2.36,3338.18],[2,2.16,91.51]],"batl":[[0,2.88,7.68],[1,2.92,343],[2,3.15,438.21]],"ltp":2.5,"tv":3368.3,"id":10303696}],"tv":7878.38}]}
{"op":"mcm","clk":"1005408691","pt":1580642536859,"mc":[{"id":"1.168224294","rc":[{"batb":[[2,1.44,188.05]],"ltp":1.56,"tv":4510.08,"id":2257317},{"batb":[[1,2.62,53.19],[2,2.42,66.09]],"ltp":2.5,"tv":3368.3,"id":10303696}]}]}
{"op":"mcm","clk":"1005408904","pt":1580642537870,"mc":[{"id":"1.168224294","rc":[{"batl":[[1,1.69,42.01],[2,1.76,480.59]],"ltp":1.56,"tv":4510.08,"id":2257317},{"batb":[[2,2.46,28.57]],"ltp":2.5,"tv":3368.3,"id":10303696}]}]}
{"op":"mcm","clk":"1005409138","pt":1580642539054,"mc":[{"id":"1.168224294","rc":[{"trd":[[1.6,29.48]],"batb":[[1,1.55,75.62],[2,1.5,20]],"batl":[[0,1.6,588.26]],"ltp":1.6,"tv":4539.56,"id":2257317},{"batl":[[0,2.8,22.69],[1,2.88,7.68],[2,2.92,343]],"ltp":2.5,"tv":3368.3,"id":10303696}],"tv":7907.86}]}
{"op":"mcm","clk":"1005409540","pt":1580642541451,"mc":[{"id":"1.168224294","rc":[{"batl":[[2,1.96,398.24]],"ltp":1.6,"tv":4539.56,"id":2257317}]}]}
{"op":"mcm","clk":"1005410082","pt":1580642544357,"mc":[{"id":"1.168224294","rc":[{"batl":[[0,1.69,42.01],[1,1.96,398.24],[2,2.5,10.13]],"ltp":1.6,"tv":4539.56,"id":2257317},{"batl":[[2,3.15,438.21]],"ltp":2.5,"tv":3368.3,"id":10303696}]}]}
{"op":"mcm","clk":"1005410187","pt":1580642544898,"mc":[{"id":"1.168224294","rc":[{"batb":[[0,1.55,75.62],[1,1.5,20],[2,1.44,188.05]],"batl":[[1,1.7,26.05],[2,1.96,398.24]],"ltp":1.6,"tv":4539.56,"id":2257317},{"batb":[[0,2.46,28.57],[1,2.42,70.3],[2,1.77,20.32]],"batl":[[1,3.35,2.7],[2,1000,0.02]],"ltp":2.5,"tv":3368.3,"id":10303696}]}]}
{"op":"mcm","clk":"1005410500","pt":1580642546551,"mc":[{"id":"1.168224294","rc":[{"batb":[[0,1.5,20],[1,1.44,188.05],[2,1.43,35.43]],"batl":[[0,1.7,26.05],[1,1.96,398.24],[2,2.5,10.13]],"ltp":1.6,"tv":4539.56,"id":2257317},{"batb":[[0,2.42,70.3],[1,1.77,20.32],[2,1.7,75.72]],"batl":[[0,3.35,2.7],[1,1000,0.02],[2,1000,0]],"ltp":2.5,"tv":3368.3,"id":10303696}]}]}
{"op":"mcm","clk":"1005411470","pt":1580642551290,"mc":[{"id":"1.168224294","rc":[{"batl":[[0,1.67,28.5],[1,1.7,26.05],[2,1.96,398.24]],"ltp":1.6,"tv":4539.56,"id":2257317},{"batb":[[0,2.48,4.26],[1,2.42,70.3],[2,1.77,20.32]],"ltp":2.5,"tv":3368.3,"id":10303696}]}]}
{"op":"mcm","clk":"1005411507","pt":1580642551476,"mc":[{"id":"1.168224294","rc":[{"batl":[[0,1.7,26.05],[1,1.96,398.24],[2,2.5,10.13]],"ltp":1.6,"tv":4539.56,"id":2257317},{"batb":[[0,2.42,70.3],[1,1.77,20.32],[2,1.7,75.72]],"ltp":2.5,"tv":3368.3,"id":10303696}]}]}
{"op":"mcm","clk":"1005413914","pt":1580642564043,"mc":[{"id":"1.168224294","rc":[{"trd":[[1.43,35.43],[1.44,188.05],[1.5,20]],"batb":[[0,1.4,11.28],[1,1.34,1238.51],[2,1.15,378.72]],"batl":[[0,1.44,10.13],[1,1.46,867],[2,1.56,136.37]],"ltp":1.43,"tv":4783.04,"id":2257317},{"trd":[[3,10],[3.3,82.05],[3.35,20.52]],"batb":[[0,3.4,280.25],[1,3.35,5.47],[2,3,65.24]],"batl":[[0,3.5,4.51],[1,3.55,288],[2,1000,0.02]],"ltp":3.35,"tv":3480.87,"id":10303696}],"tv":8263.91}]}
{"op":"mcm","clk":"1005414101","pt":1580642564947,"mc":[{"id":"1.168224294","rc":[{"batb":[[0,1.4,219.87]],"ltp":1.43,"tv":4783.04,"id":2257317},{"batb":[[2,3.05,89.62]],"ltp":3.35,"tv":3480.87,"id":10303696}]}]}
{"op":"mcm","clk":"1005414283","pt":1580642565866,"mc":[{"id":"1.168224294","rc":[{"trd":[[3.4,33.6]],"batb":[[0,3.4,263.45]],"ltp":3.4,"tv":3514.47,"id":10303696}],"tv":8297.52}]}
{"op":"mcm","clk":"1005414509","pt":1580642566987,"mc":[{"id":"1.168224294","rc":[{"batb":[[0,1.4,324.89]],"batl":[[2,1.48,42.01]],"ltp":1.43,"tv":4783.04,"id":2257317},{"batb":[[2,3.1,19.32]],"batl":[[0,3.5,21.31]],"ltp":3.4,"tv":3514.47,"id":10303696}]}]}
{"op":"mcm","clk":"1005415473","pt":1580642571858,"mc":[{"id":"1.168224294","rc":[{"trd":[[1.42,630.79],[1.43,48.24]],"batb":[[0,1.43,63.96],[1,1.4,324.89],[2,1.34,1238.51]],"batl":[[2,1.48,314.3]],"ltp":1.43,"tv":5426.64,"id":2257317},{"trd":[[3.35,25.99],[3.4,297.05]],"batb":[[0,3.1,19.32],[1,3.05,89.62],[2,3,65.24]],"ltp":3.35,"tv":3783.39,"id":10303696}],"tv":9210.04}]}
{"op":"mcm","clk":"1005415647","pt":1580642572764,"mc":[{"id":"1.168224294","rc":[{"batb":[[1,1.42,194.11],[2,1.4,116.3]],"ltp":1.43,"tv":5426.64,"id":2257317},{"batb":[[0,3.1,105.64],[1,3,65.24],[2,2.86,43.59]],"ltp":3.35,"tv":3783.39,"id":10303696}]}]}
{"op":"mcm","clk":"1005416067","pt":1580642574856,"mc":[{"id":"1.168224294","rc":[{"batb":[[0,1.43,357.32],[1,1.42,524.88]],"batl":[[2,1.47,386.79]],"ltp":1.43,"tv":5426.64,"id":2257317}]}]}
{"op":"mcm","clk":"1005417302","pt":1580642581076,"mc":[{"id":"1.168224294","rc":[{"trd":[[1.43,65.04]],"batb":[[0,1.43,348.92]],"ltp":1.43,"tv":5443.44,"id":2257317}],"tv":9226.84}]}
{"op":"mcm","clk":"1005417390","pt":1580642581553,"mc":[{"id":"1.168224294","rc":[{"batb":[[2,1.4,105.02]],"ltp":1.43,"tv":5443.44,"id":2257317},{"batl":[[0,3.5,16.8]],"ltp":3.35,"tv":3783.39,"id":10303696}]}]}
{"op":"mcm","clk":"1005417981","pt":1580642584581,"mc":[{"id":"1.168224294","rc":[{"batb":[[0,3.3,5.16],[1,3.1,105.64],[2,3,65.24]],"batl":[[0,3.4,4.95],[1,3.5,16.8],[2,3.55,288]],"ltp":3.35,"tv":3783.39,"id":10303696}]}]}
{"op":"mcm","clk":"1005418886","pt":1580642589495,"mc":[{"id":"1.168224294","rc":[{"batl":[[0,1.46,867],[1,1.47,386.79],[2,1.48,314.3]],"ltp":1.43,"tv":5443.44,"id":2257317}]}]}
{"op":"mcm","clk":"1005419500","pt":1580642592590,"mc":[{"id":"1.168224294","rc":[{"trd":[[1.43,85.31]],"batb":[[0,1.43,338.78]],"ltp":1.43,"tv":5463.71,"id":2257317}],"tv":9247.11}]}
{"op":"mcm","clk":"1005421129","pt":1580642600918,"mc":[{"id":"1.168224294","rc":[{"batb":[[0,1.42,194.11],[1,1.4,105.02],[2,1.38,214.72]],"batl":[[1,1.48,42.01],[2,1.56,136.37]],"ltp":1.43,"tv":5463.71,"id":2257317}]}]}
{"op":"mcm","clk":"1005421744","pt":1580642603909,"mc":[{"id":"1.168224294","rc":[{"batb":[[1,1.4,426.55],[2,1.39,364.12]],"batl":[[2,1.54,382.98]],"ltp":1.43,"tv":5463.71,"id":2257317}]}]}
{"op":"mcm","clk":"1005422651","pt":1580642608055,"mc":[{"id":"1.168224294","rc":[{"batb":[[1,1.4,435.12]],"ltp":1.43,"tv":5463.71,"id":2257317}]}]}
{"op":"mcm","clk":"1005423496","pt":1580642612066,"mc":[{"id":"1.168224294","rc":[{"batb":[[0,1.4,435.12],[1,1.39,364.12],[2,1.38,214.72]],"batl":[[0,1.48,42.01],[1,1.54,382.98],[2,1.55,227.28]],"ltp":1.43,"tv":5463.71,"id":2257317},{"batb":[[0,3.1,19.32],[1,2.86,43.59],[2,2.42,4.44]],"batl":[[0,3.5,16.8],[1,1000,0.02],[2,3.55,0]],"ltp":3.35,"tv":3783.39,"id":10303696}]}]}
{"op":"mcm","clk":"1005423604","pt":1580642612544,"mc":[{"id":"1.168224294","rc":[{"batb":[[0,1.4,330.1]],"batl":[[0,1.54,382.98],[1,1.55,227.28],[2,1.7,26.05]],"ltp":1.43,"tv":5463.71,"id":2257317},{"batb":[[0,2.86,43.59],[1,2.42,4.44],[2,2,75.72]],"batl":[[0,1000,0.02],[1,1000,0]],"ltp":3.35,"tv":3783.39,"id":10303696}]}]}
{"op":"mcm","clk":"1005424050","pt":1580642614946,"mc":[{"id":"1.168224294","rc":[{"batb":[[0,1.4,377.44],[1,1.39,410.03]],"batl":[[1,1.55,260.38],[2,1.59,25.89]],"ltp":1.43,"tv":5463.71,"id":2257317},{"batb":[[1,2.8,3.63],[2,2.68,3.61]],"batl":[[0,3.5,2.09],[1,3.6,2.36],[2,1000,0.02]],"ltp":3.35,"tv":3783.39,"id":10303696}]}]}
{"op":"mcm","clk":"1005424752","pt":1580642618788,"mc":[{"id":"1.168224294","rc":[{"batb":[[0,1.4,9.45],[1,1.39,45.91]],"batl":[[0,1.59,25.89],[1,1.96,398.24],[2,2.5,10.13]],"ltp":1.43,"tv":5463.71,"id":2257317},{"batb":[[1,2.68,3.61],[2,2,75.72]],"batl":[[0,3.6,2.36],[1,1000,0.02],[2,1000,0]],"ltp":3.35,"tv":3783.39,"id":10303696}]}]}
{"op":"mcm","clk":"1005425351","pt":1580642621928,"mc":[{"id":"1.168224294","rc":[{"trd":[[1.44,234.21]],"batb":[[0,1.44,394.46],[1,1.43,321.26],[2,1.4,55.13]],"batl":[[0,1.48,300.94],[1,1.49,265.69],[2,1.55,36.5]],"ltp":1.44,"tv":5509.87,"id":2257317},{"batb":[[1,2.8,3.63],[2,2.68,3.61]],"batl":[[0,3.5,2.65],[1,3.6,2.36],[2,1000,0.02]],"ltp":3.35,"tv":3783.39,"id":10303696}],"tv":9293.27}]}
{"op":"mcm","clk":"1005425800","pt":1580642624268,"mc":[{"id":"1.168224294","rc":[{"batb":[[0,1.4,55.13],[1,1.39,45.91],[2,1.38,214.72]],"batl":[[0,1.55,36.5],[1,1.59,25.89],[2,1.96,398.24]],"ltp":1.44,"tv":5509.87,"id":2257317}]}]}
{"op":"mcm","clk":"1005425833","pt":1580642624486,"mc":[{"id":"1.168224294","rc":[{"batb":[[0,1.4,8.57]],"batl":[[0,1.59,25.89],[1,1.96,398.24],[2,2.5,10.13]],"ltp":1.44,"tv":5509.87,"id":2257317},{"batb":[[1,2.68,3.61],[2,2,75.72]],"batl":[[0,3.6,2.36],[1,1000,0.02],[2,1000,0]],"ltp":3.35,"tv":3783.39,"id":10303696}]}]}
{"op":"mcm","clk":"1005426621","pt":1580642628403,"mc":[{"id":"1.168224294","rc":[{"batl":[[0,1.54,394.47],[1,1.55,227.29],[2,1.59,25.89]],"ltp":1.44,"tv":5509.87,"id":2257317}]}]}
{"op":"mcm","clk":"1005426955","pt":1580642630244,"mc":[{"id":"1.168224294","rc":[{"batb":[[0,1.49,425.34],[1,1.48,277.59],[2,1.41,2069.11]],"batl":[[0,1.52,13.52],[1,1.53,639],[2,1.54,394.47]],"ltp":1.44,"tv":5509.87,"id":2257317},{"batb":[[0,2.96,320.56],[1,2.86,43.59],[2,2.68,3.61]],"batl":[[0,3.05,10.06],[1,3.2,450.69],[2,3.5,59.37]],"ltp":3.35,"tv":3783.39,"id":10303696}]}]}
{"op":"mcm","clk":"1005427088","pt":1580642630996,"mc":[{"id":"1.168224294","rc":[{"batb":[[1,1.48,437.47],[2,1.46,202.88]],"ltp":1.44,"tv":5509.87,"id":2257317}]}]}
{"op":"mcm","clk":"1005427217","pt":1580642631581,"mc":[{"id":"1.168224294","rc":[{"batb":[[2,1.46,293.62]],"ltp":1.44,"tv":5509.87,"id":2257317},{"batb":[[1,2.86,65.43]],"batl":[[1,3.2,469.17]],"ltp":3.35,"tv":3783.39,"id":10303696}]}]}
{"op":"mcm","clk":"1005427692","pt":1580642634047,"mc":[{"id":"1.168224294","rc":[{"batb":[[2,1.46,90.74]],"ltp":1.44,"tv":5509.87,"id":2257317}]}]}
{"op":"mcm","clk":"1005428063","pt":1580642636162,"mc":[{"id":"1.168224294","rc":[{"batb":[[2,1.46,584.78]],"batl":[[2,1.54,875.06]],"ltp":1.44,"tv":5509.87,"id":2257317}]}]}
{"op":"mcm","clk":"1005428249","pt":1580642637286,"mc":[{"id":"1.168224294","rc":[{"batb":[[2,1.46,623.16]],"ltp":1.44,"tv":5509.87,"id":2257317},{"batl":[[1,3.2,471.95],[2,3.3,2.65]],"ltp":3.35,"tv":3783.39,"id":10303696}]}]}
{"op":"mcm","clk":"1005428373","pt":1580642637996,"mc":[{"id":"1.168224294","rc":[{"batl":[[2,3.3,5]],"ltp":3.35,"tv":3783.39,"id":10303696}]}]}
{"op":"mcm","clk":"1005429244","pt":1580642642373,"mc":[{"id":"1.168224294","rc":[{"batb":[[0,1.46,623.16],[1,1.44,554.01],[2,1.43,183.88]],"batl":[[0,1.54,480.59],[1,1.55,42.01],[2,1.56,497.4]],"ltp":1.44,"tv":5509.87,"id":2257317},{"batb":[[0,2.86,21.85],[1,2.62,4.04],[2,2.56,58.62]],"batl":[[0,3.2,21.26],[1,3.3,5],[2,3.6,2.36]],"ltp":3.35,"tv":3783.39,"id":10303696}]}]}
{"op":"mcm","clk":"1005429293","pt":1580642642599,"mc":[{"id":"1.168224294","rc":[{"batb":[[0,1.46,532.41]],"batl":[[1,1.56,497.4],[2,1.61,26.91]],"ltp":1.44,"tv":5509.87,"id":2257317},{"batb":[[0,2.62,4.04],[1,2.56,58.62],[2,2.52,4.24]],"batl":[[0,3.2,2.78]],"ltp":3.35,"tv":3783.39,"id":10303696}]}]}
{"op":"mcm","clk":"1005429816","pt":1580642645280,"mc":[{"id":"1.168224294","rc":[{"batb":[[1,1.45,249.13],[2,1.44,864.41]],"ltp":1.44,"tv":5509.87,"id":2257317}]}]}
{"op":"mcm","clk":"1005431093","pt":1580642651965,"mc":[{"id":"1.168224294","rc":[{"batb":[[1,1.44,554.01],[2,1.43,183.88]],"batl":[[0,1.64,278.34],[1,1.65,208.11],[2,1.96,398.24]],"ltp":1.44,"tv":5509.87,"id":2257317},{"batb":[[0,2.56,58.62],[1,2.52,4.24],[2,1.8,75.72]],"ltp":3.35,"tv":3783.39,"id":10303696}]}]}
{"op":"mcm","clk":"1005431583","pt":1580642654315,"mc":[{"id":"1.168224294","rc":[{"batb":[[0,1.54,1913.57],[1,1.46,532.41],[2,1.44,554.01]],"batl":[[0,1.64,1495.4]],"ltp":1.44,"tv":5509.87,"id":2257317},{"batl":[[0,2.66,12.67],[1,2.7,2680.27],[2,2.78,333]],"ltp":3.35,"tv":3783.39,"id":10303696}]}]}
{"op":"mcm","clk":"1005431792","pt":1580642655329,"mc":[{"id":"1.168224294","rc":[{"batb":[[0,1.59,297.84],[1,1.58,338.7],[2,1.54,191.36]],"ltp":1.44,"tv":5509.87,"id":2257317},{"batb":[[2,2.28,80.81]],"batl":[[1,2.7,268.03]],"ltp":3.35,"tv":3783.39,"id":10303696}]}]}
{"op":"mcm","clk":"1005431858","pt":1580642655605,"mc":[{"id":"1.168224294","rc":[{"batl":[[0,1.64,1537.41]],"ltp":1.44,"tv":5509.87,"id":2257317},{"batb":[[0,2.56,85.5]],"ltp":3.35,"tv":3783.39,"id":10303696}]}]}
{"op":"mcm","clk":"1005432951","pt":1580642660922,"mc":[{"id":"1.168224294","rc":[{"batb":[[2,1.56,494.03]],"batl":[[2,1.68,480.59]],"ltp":1.44,"tv":5509.87,"id":2257317}]}]}
{"op":"mcm","clk":"1005433218","pt":1580642662119,"mc":[{"id":"1.168224294","rc":[{"batb":[[2,2.32,4.64]],"ltp":3.35,"tv":3783.39,"id":10303696}]}]}
{"op":"mcm","clk":"1005433488","pt":1580642663345,"mc":[{"id":"1.168224294","rc":[{"batb":[[0,1.58,124.95],[1,1.56,494.03],[2,1.54,510.84]],"batl":[[0,1.64,42.01],[1,1.68,480.59],[2,1.7,497.4]],"ltp":1.44,"tv":5509.87,"id":2257317},{"batb":[[1,2.32,4.64],[2,2.28,80.81]],"batl":[[0,2.9,21.85],[1,2.94,2.91],[2,3.1,2.95]],"ltp":3.35,"tv":3783.39,"id":10303696}]}]}
{"op":"mcm","clk":"1005433533","pt":1580642663558,"mc":[{"id":"1.168224294","rc":[{"batb":[[0,1.56,494.03],[1,1.54,510.84],[2,1.53,78.98]],"ltp":1.44,"tv":5509.87,"id":2257317},{"batb":[[0,2.56,26.89]],"ltp":3.35,"tv":3783.39,"id":10303696}]}]}
{"op":"mcm","clk":"1005433741","pt":1580642664542,"mc":[{"id":"1.168224294","rc":[{"batb":[[2,1.52,176.88]],"batl":[[0,1.68,480.59],[1,1.7,497.4],[2,1.75,26.06]],"ltp":1.44,"tv":5509.87,"id":2257317},{"batb":[[0,2.32,4.64],[1,2.28,80.81],[2,2.26,4.98]],"batl":[[0,2.94,2.91],[1,3.1,2.95],[2,3.2,2.78]],"ltp":3.35,"tv":3783.39,"id":10303696}]}]}
{"op":"mcm","clk":"1005434085","pt":1580642666225,"mc":[{"id":"1.168224294","rc":[{"batb":[[2,1.53,246.38]],"ltp":1.44,"tv":5509.87,"id":2257317}]}]}
{"op":"mcm","clk":"1005434251","pt":1580642667026,"mc":[{"id":"1.168224294","rc":[{"batb":[[0,1.53,246.38],[1,1.52,424.95],[2,1.48,34.01]],"ltp":1.44,"tv":5509.87,"id":2257317}]}]}
{"op":"mcm","clk":"1005434849","pt":1580642670164,"mc":[{"id":"1.168224294","rc":[{"batl":[[0,1.56,738.53],[1,1.57,811.4],[2,1.58,235.68]],"ltp":1.44,"tv":5509.87,"id":2257317},{"trd":[[2.88,10.54]],"batb":[[0,2.88,255.15],[1,2.74,4.79],[2,2.32,4.64]],"batl":[[1,3,283],[2,3.05,288.11]],"ltp":2.88,"tv":3793.93,"id":10303696}],"tv":9303.81}]}
{"op":"mcm","clk":"1005434939","pt":1580642670646,"mc":[{"id":"1.168224294","rc":[{"batb":[[1,2.76,48.23],[2,2.74,4.79]],"ltp":2.88,"tv":3793.93,"id":10303696}]}]}
{"op":"mcm","clk":"1005435214","pt":1580642672255,"mc":[{"id":"1.168224294","rc":[{"batb":[[2,1.48,121.39]],"batl":[[2,1.58,277.69]],"ltp":1.44,"tv":5509.87,"id":2257317},{"batl":[[2,3.05,308.27]],"ltp":2.88,"tv":3793.93,"id":10303696}]}]}
{"op":"mcm","clk":"1005435934","pt":1580642676081,"mc":[{"id":"1.168224294","rc":[{"batb":[[2,1.5,494.03]],"batl":[[0,1.56,1219.12],[2,1.58,775.09]],"ltp":1.44,"tv":5509.87,"id":2257317}]}]}
{"op":"mcm","clk":"1005436753","pt":1580642680338,"mc":[{"id":"1.168224294","rc":[{"batl":[[0,1.56,480.59],[1,1.57,270.4],[2,1.58,751.66]],"ltp":1.44,"tv":5509.87,"id":2257317},{"batl":[[1,3.05,20.16],[2,3.1,2.95]],"ltp":2.88,"tv":3793.93,"id":10303696}]}]}
{"op":"mcm","clk":"1005436857","pt":1580642680722,"mc":[{"id":"1.168224294","rc":[{"batb":[[0,1.5,494.03],[1,1.48,510.84],[2,1.47,39.67]],"batl":[[1,1.57,24.5],[2,1.58,497.4]],"ltp":1.44,"tv":5509.87,"id":2257317},{"batb":[[0,2.74,4.79],[1,2.46,4.38],[2,2.4,69.32]],"batl":[[0,3.15,2.9],[1,3.2,2.78],[2,3.25,2.34]],"ltp":2.88,"tv":3793.93,"id":10303696}]}]}
{"op":"mcm","clk":"1005437284","pt":1580642683042,"mc":[{"id":"1.168224294","rc":[{"batl":[[1,1.58,497.4],[2,1.68,26.39]],"ltp":1.44,"tv":5509.87,"id":2257317},{"batb":[[0,2.46,4.38],[1,2.4,69.32],[2,2.36,4.68]],"ltp":2.88,"tv":3793.93,"id":10303696}]}]}
{"op":"mcm","clk":"1005439091","pt":1580642693199,"mc":[{"id":"1.168224294","rc":[{"batb":[[0,1.55,341.8],[1,1.54,236.08],[2,1.5,494.03]],"batl":[[2,1.6,319.69]],"ltp":1.44,"tv":5509.87,"id":2257317}]}]}
{"op":"mcm","clk":"1005439451","pt":1580642695115,"mc":[{"id":"1.168224294","rc":[{"batb":[[0,1.5,494.03],[1,1.48,510.84],[2,1.47,39.67]],"batl":[[2,1.68,26.39]],"ltp":1.44,"tv":5509.87,"id":2257317}]}]}
{"op":"mcm","clk":"1005440606","pt":1580642701343,"mc":[{"id":"1.168224294","rc":[{"batb":[[0,1.46,524.67],[1,1.45,514.37],[2,1.44,43.17]],"ltp":1.44,"tv":5509.87,"id":2257317},{"batl":[[0,3.2,2.78],[1,3.25,2.34],[2,3.3,5]],"ltp":2.88,"tv":3793.93,"id":10303696}]}]}
{"op":"mcm","clk":"1005440973","pt":1580642703342,"mc":[{"id":"1.168224294","rc":[{"batl":[[0,1.5,2005.54],[1,1.51,817],[2,1.56,480.59]],"ltp":1.44,"tv":5509.87,"id":2257317},{"batb":[[0,3.1,2394.71],[1,3.05,347.11],[2,2.46,4.38]],"batl":[[0,3.15,5.35],[1,3.2,2.78],[2,3.25,2.34]],"ltp":2.88,"tv":3793.93,"id":10303696}]}]}
{"op":"mcm","clk":"1005441159","pt":1580642704355,"mc":[{"id":"1.168224294","rc":[{"trd":[[1.48,2.62]],"batb":[[0,1.46,330.57],[1,1.45,211.3]],"batl":[[0,1.49,26.5],[1,1.5,135.88],[2,1.51,1247.54]],"ltp":1.48,"tv":5512.48,"id":2257317},{"trd":[[3.1,1.24]],"batb":[[0,3.1,238.23],[2,3,5]],"ltp":3.1,"tv":3795.17,"id":10303696}],"tv":9307.65}]}
{"op":"mcm","clk":"1005441631","pt":1580642706847,"mc":[{"id":"1.168224294","rc":[{"batb":[[0,1.47,198.39],[1,1.46,330.57],[2,1.45,211.3]],"ltp":1.48,"tv":5512.48,"id":2257317}]}]}
{"op":"mcm","clk":"1005442271","pt":1580642710154,"mc":[{"id":"1.168224294","rc":[{"batl":[[1,1.5,616.47]],"ltp":1.48,"tv":5512.48,"id":2257317}]}]}
{"op":"mcm","clk":"1005443691","pt":1580642718039,"mc":[{"id":"1.168224294","rc":[{"trd":[[3.1,3.92]],"batb":[[0,3.1,236.89]],"ltp":3.1,"tv":3797.86,"id":10303696}],"tv":9310.34}]}
{"op":"mcm","clk":"1005443898","pt":1580642719164,"mc":[{"id":"1.168224294","rc":[{"batb":[[0,1.44,689.8],[1,1.43,97.46],[2,1.42,548.28]],"batl":[[0,1.5,480.59],[1,1.52,539.41],[2,1.61,27.91]],"ltp":1.48,"tv":5512.48,"id":2257317},{"batb":[[0,2.9,21.85],[1,2.82,2.7],[2,2.62,4.04]],"batl":[[0,3.3,19.99],[1,3.4,2.09],[2,3.5,2.55]],"ltp":3.1,"tv":3797.86,"id":10303696}]}]}
{"op":"mcm","clk":"1005444112","pt":1580642720558,"mc":[{"id":"1.168224294","rc":[{"batb":[[1,1.42,548.28],[2,1.4,255.23]],"batl":[[1,1.52,497.4]],"ltp":1.48,"tv":5512.48,"id":2257317},{"batb":[[0,2.82,2.7],[1,2.62,4.04],[2,2.6,56.57]],"batl":[[0,3.3,2.35]],"ltp":3.1,"tv":3797.86,"id":10303696}]}]}
{"op":"mcm","clk":"1005444421","pt":1580642722165,"mc":[{"id":"1.168224294","rc":[{"batb":[[2,1.41,408.88]],"ltp":1.48,"tv":5512.48,"id":2257317}]}]}
{"op":"mcm","clk":"1005444752","pt":1580642724153,"mc":[{"id":"1.168224294","rc":[{"batb":[[2,1.4,255.23]],"ltp":1.48,"tv":5512.48,"id":2257317}]}]}
{"op":"mcm","clk":"1005445281","pt":1580642727003,"mc":[{"id":"1.168224294","rc":[{"batb":[[0,1.49,231.42],[1,1.48,276.27],[2,1.44,689.8]],"batl":[[2,1.53,345.19]],"ltp":1.48,"tv":5512.48,"id":2257317}]}]}
{"op":"mcm","clk":"1005445520","pt":1580642728246,"mc":[{"id":"1.168224294","rc":[{"batb":[[2,1.45,94.1]],"ltp":1.48,"tv":5512.48,"id":2257317}]}]}
{"op":"mcm","clk":"1005445866","pt":1580642730315,"mc":[{"id":"1.168224294","rc":[{"batb":[[0,1.45,94.1],[1,1.44,494.03],[2,1.42,548.28]],"batl":[[2,1.61,27.91]],"ltp":1.48,"tv":5512.48,"id":2257317}]}]}
{"op":"mcm","clk":"1005446194","pt":1580642732101,"mc":[{"id":"1.168224294","rc":[{"batb":[[0,2.62,4.04],[1,2.6,56.57],[2,2.5,3.87]],"ltp":3.1,"tv":3797.86,"id":10303696}]}]}
{"op":"mcm","clk":"1005446568","pt":1580642734078,"mc":[{"id":"1.168224294","rc":[{"batb":[[1,1.41,408.88],[2,1.4,608.46]],"ltp":1.48,"tv":5512.48,"id":2257317},{"batl":[[1,3.5,2.55],[2,3.6,2.36]],"ltp":3.1,"tv":3797.86,"id":10303696}]}]}
{"op":"mcm","clk":"1005446763","pt":1580642735248,"mc":[{"id":"1.168224294","rc":[{"batb":[[0,1.41,408.88],[1,1.4,608.46],[2,1.39,45.91]],"ltp":1.48,"tv":5512.48,"id":2257317}]}]}
{"op":"mcm","clk":"1005446959","pt":1580642736364,"mc":[{"id":"1.168224294","rc":[{"trd":[[1.43,90.73]],"batb":[[0,1.41,419.01]],"batl":[[0,1.43,967.71],[1,1.45,948.32],[2,1.5,480.59]],"ltp":1.43,"tv":5517.9,"id":2257317},{"trd":[[3.3,84.4]],"batb":[[0,3.35,4.63],[1,2.62,4.04],[2,2.6,56.57]],"batl":[[0,3.5,2.55],[1,3.6,298.36],[2,3.7,305.67]],"ltp":3.3,"tv":3800.21,"id":10303696}],"tv":9318.11}]}
{"op":"mcm","clk":"1005447130","pt":1580642737271,"mc":[{"id":"1.168224294","rc":[{"batl":[[1,1.44,26.58],[2,1.45,1352.46]],"ltp":1.43,"tv":5517.9,"id":2257317},{"batb":[[1,3.25,3.89],[2,3.2,81.12]],"ltp":3.3,"tv":3800.21,"id":10303696}]}]}
{"op":"mcm","clk":"1005447240","pt":1580642737870,"mc":[{"id":"1.168224294","rc":[{"batb":[[2,1.39,153.45]],"ltp":1.43,"tv":5517.9,"id":2257317},{"batb":[[1,3.3,2.67],[2,3.25,3.89]],"batl":[[1,3.55,15.96],[2,3.6,298.36]],"ltp":3.3,"tv":3800.21,"id":10303696}]}]}
{"op":"mcm","clk":"1005448048","pt":1580642742262,"mc":[{"id":"1.168224294","rc":[{"batb":[[2,1.39,387.03]],"ltp":1.43,"tv":5517.9,"id":2257317}]}]}
{"op":"mcm","clk":"1005448244","pt":1580642743368,"mc":[{"id":"1.168224294","rc":[{"batl":[[2,1.45,1833.05]],"ltp":1.43,"tv":5517.9,"id":2257317}]}]}
{"op":"mcm","clk":"1005448404","pt":1580642744157,"mc":[{"id":"1.168224294","rc":[{"batb":[[1,1.4,710.12]],"batl":[[0,1.42,22.33],[1,1.43,967.71],[2,1.44,26.58]],"ltp":1.43,"tv":5517.9,"id":2257317},{"trd":[[3.35,35.25]],"batb":[[0,3.3,2.67],[1,3.25,3.89],[2,3.2,81.12]],"ltp":3.35,"tv":3809.47,"id":10303696}],"tv":9327.37}]}
{"op":"mcm","clk":"1005448481","pt":1580642744577,"mc":[{"id":"1.168224294","rc":[{"trd":[[1.42,646.43]],"batl":[[0,1.42,6.69]],"ltp":1.42,"tv":5533.54,"id":2257317},{"trd":[[3.35,41.88]],"ltp":3.35,"tv":3816.1,"id":10303696}],"tv":9349.64}]}
{"op":"mcm","clk":"1005448781","pt":1580642746226,"mc":[{"id":"1.168224294","rc":[{"trd":[[1.42,651.15]],"batb":[[0,1.41,408.88]],"batl":[[0,1.42,1.97],[1,1.43,193.78]],"ltp":1.42,"tv":5538.26,"id":2257317},{"trd":[[3.35,43.88]],"batl":[[2,3.6,2.36]],"ltp":3.35,"tv":3818.1,"id":10303696}],"tv":9356.36}]}
{"op":"mcm","clk":"1005448951","pt":1580642747034,"mc":[{"id":"1.168224294","rc":[{"batb":[[0,1.4,110.23],[1,1.39,387.03],[2,1.38,543.99]],"batl":[[1,1.44,26.58],[2,1.45,480.59]],"ltp":1.42,"tv":5538.26,"id":2257317},{"batb":[[2,3.15,19.32]],"batl":[[0,3.55,15.96],[1,3.6,2.36],[2,3.65,2.3]],"ltp":3.35,"tv":3818.1,"id":10303696}]}]}
{"op":"mcm","clk":"1005449255","pt":1580642748630,"mc":[{"id":"1.168224294","rc":[{"batb":[[1,1.39,279.48]],"ltp":1.42,"tv":5538.26,"id":2257317},{"batb":[[2,3.05,3.69]],"batl":[[0,3.6,2.36],[1,3.65,2.3],[2,4.6,136.05]],"ltp":3.35,"tv":3818.1,"id":10303696}]}]}
{"op":"mcm","clk":"1005449505","pt":1580642749795,"mc":[{"id":"1.168224294","rc":[{"batb":[[2,1.38,873.23]],"batl":[[1,1.45,480.59],[2,1.47,497.4]],"ltp":1.42,"tv":5538.26,"id":2257317},{"batb":[[1,3.05,3.69],[2,3,3.56]],"ltp":3.35,"tv":3818.1,"id":10303696}]}]}
{"op":"mcm","clk":"1005450459","pt":1580642755217,"mc":[{"id":"1.168224294","rc":[{"batb":[[2,1.38,379.2]],"ltp":1.42,"tv":5538.26,"id":2257317}]}]}
{"op":"mcm","clk":"1005450619","pt":1580642756038,"mc":[{"id":"1.168224294","rc":[{"batb":[[0,1.4,8.57],[1,1.38,379.2],[2,1.37,614.83]],"ltp":1.42,"tv":5538.26,"id":2257317},{"batl":[[0,3.65,2.3],[1,4.6,136.05],[2,1000,0.02]],"ltp":3.35,"tv":3818.1,"id":10303696}]}]}
{"op":"mcm","clk":"1005450740","pt":1580642756533,"mc":[{"id":"1.168224294","rc":[{"batl":[[1,1000,0.02],[2,1000,0]],"ltp":3.35,"tv":3818.1,"id":10303696}]}]}
{"op":"mcm","clk":"1005451053","pt":1580642758033,"mc":[{"id":"1.168224294","rc":[{"trd":[[1.4,14.62],[1.41,20.41]],"batb":[[0,1.4,1.26],[1,1.38,393.84]],"batl":[[0,1.41,282.78],[1,1.42,1311.3],[2,1.43,127.51]],"ltp":1.41,"tv":5573.29,"id":2257317},{"batb":[[0,3.45,59.54],[1,3.4,3.56],[2,3.3,2.67]],"batl":[[1,3.85,346],[2,1000,0.02]],"ltp":3.35,"tv":3818.1,"id":10303696}],"tv":9391.39}]}
{"op":"mcm","clk":"1005451195","pt":1580642758724,"mc":[{"id":"1.168224294","rc":[{"batb":[[2,3.35,71.13]],"ltp":3.35,"tv":3818.1,"id":10303696}]}]}
{"op":"mcm","clk":"1005451447","pt":1580642760021,"mc":[{"id":"1.168224294","rc":[{"batl":[[1,1.42,1353.31]],"ltp":1.41,"tv":5573.29,"id":2257317},{"batb":[[2,3.35,88.77]],"batl":[[1,3.8,14.28],[2,3.85,346]],"ltp":3.35,"tv":3818.1,"id":10303696}]}]}
{"op":"mcm","clk":"1005452388","pt":1580642765122,"mc":[{"id":"1.168224294","rc":[{"batb":[[2,1.37,661.6]],"batl":[[2,1.43,172.01]],"ltp":1.41,"tv":5573.29,"id":2257317},{"batl":[[1,3.75,2.22],[2,3.8,14.28]],"ltp":3.35,"tv":3818.1,"id":10303696}]}]}
{"op":"mcm","clk":"1005452436","pt":1580642765431,"mc":[{"id":"1.168224294","rc":[{"batl":[[1,1.42,1351.34]],"ltp":1.41,"tv":5573.29,"id":2257317}]}]}
{"op":"mcm","clk":"1005452933","pt":1580642768084,"mc":[{"id":"1.168224294","rc":[{"batb":[[1,1.38,379.2]],"ltp":1.41,"tv":5573.29,"id":2257317}]}]}
{"op":"mcm","clk":"1005453126","pt":1580642768987,"mc":[{"id":"1.168224294","rc":[{"trd":[[1.38,4.5],[1.4,17.14]],"batb":[[0,1.38,376.95],[1,1.37,661.6],[2,1.36,251.22]],"ltp":1.38,"tv":5580.31,"id":2257317}],"tv":9398.41}]}
{"op":"mcm","clk":"1005453534","pt":1580642771185,"mc":[{"id":"1.168224294","rc":[{"batl":[[0,1.41,287.4]],"ltp":1.38,"tv":5580.31,"id":2257317},{"batl":[[0,3.6,5.77],[1,3.65,2.3],[2,3.75,2.22]],"ltp":3.35,"tv":3818.1,"id":10303696}]}]}
{"op":"mcm","clk":"1005453678","pt":1580642771993,"mc":[{"id":"1.168224294","rc":[{"trd":[[1.41,20.55]],"batl":[[0,1.41,287.33]],"ltp":1.41,"tv":5580.45,"id":2257317}],"tv":9398.55}]}
{"op":"mcm","clk":"1005454146","pt":1580642774194,"mc":[{"id":"1.168224294","rc":[{"batb":[[2,1.36,295.65]],"ltp":1.41,"tv":5580.45,"id":2257317}]}]}
{"op":"mcm","clk":"1005454845","pt":1580642778197,"mc":[{"id":"1.168224294","rc":[{"batb":[[0,1.38,329.24],[1,1.37,614.83]],"batl":[[0,1.41,266.42],[1,1.42,367.34],[2,1.43,44.5]],"ltp":1.41,"tv":5580.45,"id":2257317},{"batb":[[0,3.35,88.77],[1,3.3,2.68],[2,3.25,77.11]],"batl":[[0,3.8,16.3],[1,3.9,2.05],[2,3.95,2.3]],"ltp":3.35,"tv":3818.1,"id":10303696}]}]}
{"op":"mcm","clk":"1005454974","pt":1580642778902,"mc":[{"id":"1.168224294","rc":[{"batb":[[0,1.36,295.65],[1,1.35,44.47],[2,1.34,57.72]],"batl":[[0,1.45,44.1],[1,1.96,398.24],[2,2.5,10.13]],"ltp":1.41,"tv":5580.45,"id":2257317},{"batb":[[0,3.25,77.11],[1,3.2,2.82],[2,2.42,381.73]],"batl":[[0,3.8,2.02]],"ltp":3.35,"tv":3818.1,"id":10303696}]}]}
{"op":"mcm","clk":"1005455408","pt":1580642781364,"mc":[{"id":"1.168224294","rc":[{"batb":[[2,1.34,616.12]],"batl":[[0,1.44,440.42],[1,1.45,339.83],[2,1.96,398.24]],"ltp":1.41,"tv":5580.45,"id":2257317}]}]}
{"op":"mcm","clk":"1005456236","pt":1580642785693,"mc":[{"id":"1.168224294","rc":[{"batl":[[0,1.43,147.87],[1,1.44,440.42],[2,1.45,339.83]],"ltp":1.41,"tv":5580.45,"id":2257317}]}]}
{"op":"mcm","clk":"1005457661","pt":1580642792307,"mc":[{"id":"1.168224294","rc":[{"batl":[[0,1.43,189.37]],"ltp":1.41,"tv":5580.45,"id":2257317},{"batb":[[0,3.3,2.78],[1,3.25,77.11],[2,3.2,2.82]],"ltp":3.35,"tv":3818.1,"id":10303696}]}]}
{"op":"mcm","clk":"1005457750","pt":1580642792717,"mc":[{"id":"1.168224294","rc":[{"batl":[[0,1.4,3.79],[1,1.43,147.87],[2,1.44,440.42]],"ltp":1.41,"tv":5580.45,"id":2257317},{"batb":[[0,3.25,77.11],[1,3.2,2.82],[2,2.42,381.73]],"ltp":3.35,"tv":3818.1,"id":10303696}]}]}
{"op":"mcm","clk":"1005459147","pt":1580642800150,"mc":[{"id":"1.168224294","rc":[{"batb":[[2,1.34,57.72]],"ltp":1.41,"tv":5580.45,"id":2257317}]}]}
{"op":"mcm","clk":"1005459455","pt":1580642801955,"mc":[{"id":"1.168224294","rc":[{"batl":[[1,1.44,440.42],[2,1.45,339.83]],"ltp":1.41,"tv":5580.45,"id":2257317}]}]}
{"op":"mcm","clk":"1005459733","pt":1580642803353,"mc":[{"id":"1.168224294","rc":[{"trd":[[1.4,20.93]],"batb":[[0,1.41,17.51],[1,1.4,2013.98],[2,1.39,364.79]],"batl":[[0,1.44,2771.92],[1,1.45,339.83],[2,1.96,398.24]],"ltp":1.4,"tv":5584.24,"id":2257317},{"trd":[[3.5,1.51]],"batb":[[0,3.4,272.61],[1,3.3,6.58],[2,3.25,77.11]],"batl":[[0,3.65,280],[1,3.7,211.79],[2,3.8,2.02]],"ltp":3.5,"tv":3819.61,"id":10303696}],"tv":9403.85}]}
{"op":"mcm","clk":"1005459853","pt":1580642803944,"mc":[{"id":"1.168224294","rc":[{"trd":[[1.41,27.14]],"batb":[[0,1.41,10.92],[2,1.39,576.44]],"batl":[[0,1.44,2813.93]],"ltp":1.41,"tv":5590.83,"id":2257317},{"trd":[[3.45,2.69]],"batb":[[2,3.25,95.59]],"batl":[[0,3.65,295.12]],"ltp":3.45,"tv":3822.3,"id":10303696}],"tv":9413.13}]}
{"op":"mcm","clk":"1005461245","pt":1580642810350,"mc":[{"id":"1.168224294","rc":[{"batb":[[0,1.39,541.94],[1,1.38,236.23],[2,1.37,624.26]],"batl":[[0,1.43,35.5],[1,1.44,82.34],[2,1.45,524.69]],"ltp":1.41,"tv":5590.83,"id":2257317},{"batb":[[0,3.3,2.88],[1,3.25,21.37],[2,3.2,2.82]],"batl":[[0,3.6,2.06],[1,3.65,17.42]],"ltp":3.45,"tv":3822.3,"id":10303696}]}]}
{"op":"mcm","clk":"1005461352","pt":1580642810850,"mc":[{"id":"1.168224294","rc":[{"batb":[[2,1.37,510.84]],"batl":[[0,1.44,40.33],[1,1.45,524.69],[2,1.47,497.4]],"ltp":1.41,"tv":5590.83,"id":2257317},{"batb":[[0,3.25,2.89],[1,3.2,2.82],[2,3.15,84.98]],"batl":[[1,3.65,2.3]],"ltp":3.45,"tv":3822.3,"id":10303696}]}]}
{"op":"mcm","clk":"1005461785","pt":1580642812942,"mc":[{"id":"1.168224294","rc":[{"batb":[[2,1.37,878]],"batl":[[2,1.46,396.98]],"ltp":1.41,"tv":5590.83,"id":2257317}]}]}
{"op":"mcm","clk":"1005462275","pt":1580642815258,"mc":[{"id":"1.168224294","rc":[{"batb":[[0,1.38,236.23],[1,1.37,367.16],[2,1.36,682.81]],"batl":[[2,1.47,497.4]],"ltp":1.41,"tv":5590.83,"id":2257317},{"batl":[[0,3.65,2.3],[1,3.8,2.02],[2,3.9,2.05]],"ltp":3.45,"tv":3822.3,"id":10303696}]}]}
{"op":"mcm","clk":"1005462358","pt":1580642815672,"mc":[{"id":"1.168224294","rc":[{"batb":[[0,1.38,40.46]],"ltp":1.41,"tv":5590.83,"id":2257317}]}]}
{"op":"mcm","clk":"1005462881","pt":1580642818364,"mc":[{"id":"1.168224294","rc":[{"batb":[[1,1.37,2009.5]],"batl":[[0,1.4,2661],[1,1.41,335.69],[2,1.43,2889.58]],"ltp":1.41,"tv":5590.83,"id":2257317},{"batb":[[0,3.6,6.1],[1,3.5,2.9],[2,3.25,2.89]],"batl":[[1,3.75,5.98],[2,3.8,2.02]],"ltp":3.45,"tv":3822.3,"id":10303696}]}]}
{"op":"mcm","clk":"1005463037","pt":1580642819204,"mc":[{"id":"1.168224294","rc":[{"batb":[[2,3.45,67.43]],"ltp":3.45,"tv":3822.3,"id":10303696}]}]}
{"op":"mcm","clk":"1005463124","pt":1580642819580,"mc":[{"id":"1.168224294","rc":[{"batl":[[1,1.41,377.7]],"ltp":1.41,"tv":5590.83,"id":2257317},{"batb":[[2,3.45,84.23]],"ltp":3.45,"tv":3822.3,"id":10303696}]}]}
{"op":"mcm","clk":"1005464100","pt":1580642824347,"mc":[{"id":"1.168224294","rc":[{"batb":[[2,1.36,1176.84]],"batl":[[2,1.42,480.59]],"ltp":1.41,"tv":5590.83,"id":2257317}]}]}
{"op":"mcm","clk":"1005464444","pt":1580642826358,"mc":[{"id":"1.168224294","rc":[{"batl":[[0,1.4,1891],[2,1.42,519.84]],"ltp":1.41,"tv":5590.83,"id":2257317},{"batb":[[0,3.5,2.9],[1,3.45,84.23],[2,3.35,2.87]],"batl":[[1,3.8,2.02],[2,3.9,16.33]],"ltp":3.45,"tv":3822.3,"id":10303696}]}]}
{"op":"mcm","clk":"1005464536","pt":1580642826879,"mc":[{"id":"1.168224294","rc":[{"batb":[[0,1.36,494.03],[1,1.35,233.57],[2,1.34,925.64]],"batl":[[0,1.4,21.49],[1,1.41,42.01]],"ltp":1.41,"tv":5590.83,"id":2257317},{"batb":[[1,3.45,16.8]],"batl":[[0,3.9,14.28],[1,3.95,2.3],[2,4.2,2.03]],"ltp":3.45,"tv":3822.3,"id":10303696}]}]}
{"op":"mcm","clk":"1005464857","pt":1580642828594,"mc":[{"id":"1.168224294","rc":[{"batb":[[2,1.34,802.13]],"batl":[[1,1.42,519.84],[2,1.44,537.73]],"ltp":1.41,"tv":5590.83,"id":2257317},{"batb":[[1,3.35,2.87],[2,3.3,74.83]],"batl":[[0,3.95,2.3],[1,4.2,2.03],[2,5.5,115.06]],"ltp":3.45,"tv":3822.3,"id":10303696}]}]}
{"op":"mcm","clk":"1005465051","pt":1580642829753,"mc":[{"id":"1.168224294","rc":[{"batl":[[2,1.43,323.38]],"ltp":1.41,"tv":5590.83,"id":2257317}]}]}
{"op":"mcm","clk":"1005465411","pt":1580642831795,"mc":[{"id":"1.168224294","rc":[{"batl":[[0,1.42,519.84],[1,1.44,537.73],[2,1.45,44.1]],"ltp":1.41,"tv":5590.83,"id":2257317},{"batb":[[0,3.35,2.87],[1,3.3,74.83],[2,3.25,2.89]],"ltp":3.45,"tv":3822.3,"id":10303696}]}]}
{"op":"mcm","clk":"1005465986","pt":1580642834987,"mc":[{"id":"1.168224294","rc":[{"batb":[[0,1.36,939.82],[1,1.35,653.9]],"batl":[[0,1.39,221.96],[1,1.4,347.05],[2,1.42,519.84]],"ltp":1.41,"tv":5590.83,"id":2257317}]}]}
{"op":"mcm","clk":"1005466239","pt":1580642836287,"mc":[{"id":"1.168224294","rc":[{"batb":[[0,1.36,494.03],[1,1.34,568.56],[2,1.32,320.34]],"batl":[[0,1.42,519.84],[1,1.44,537.73],[2,1.45,44.1]],"ltp":1.41,"tv":5590.83,"id":2257317}]}]}
{"op":"mcm","clk":"1005466275","pt":1580642836444,"mc":[{"id":"1.168224294","rc":[{"batb":[[0,1.37,166.36],[1,1.36,494.03],[2,1.34,568.56]],"ltp":1.41,"tv":5590.83,"id":2257317}]}]}
{"op":"mcm","clk":"1005466700","pt":1580642838783,"mc":[{"id":"1.168224294","rc":[{"batl":[[1,1.43,323.38],[2,1.44,843.29]],"ltp":1.41,"tv":5590.83,"id":2257317}]}]}
{"op":"mcm","clk":"1005467281","pt":1580642842312,"mc":[{"id":"1.168224294","rc":[{"batb":[[1,1.34,57.72],[2,1.33,391.34]],"batl":[[1,1.44,537.73],[2,1.45,44.1]],"ltp":1.41,"tv":5590.83,"id":2257317}]}]}
{"op":"mcm","clk":"1005467476","pt":1580642843298,"mc":[{"id":"1.168224294","rc":[{"batb":[[0,1.33,391.34],[1,1.32,791.02],[2,1.15,378.72]],"ltp":1.41,"tv":5590.83,"id":2257317},{"batl":[[0,4.2,2.03],[1,1000,0.02],[2,5.5,0]],"ltp":3.45,"tv":3822.3,"id":10303696}]}]}
{"op":"mcm","clk":"1005467819","pt":1580642845171,"mc":[{"id":"1.168224294","rc":[{"trd":[[1.33,1725.62]],"batb":[[0,1.33,1220.26],[2,1.28,1052.61]],"batl":[[0,1.36,3135.3],[1,1.37,381.68],[2,1.42,519.84]],"ltp":1.33,"tv":7316.45,"id":2257317},{"batb":[[0,4,4.59],[1,3.75,2.71],[2,3.35,2.87]],"batl":[[0,4.2,9.84],[1,4.4,393],[2,1000,0.02]],"ltp":3.45,"tv":3822.3,"id":10303696}],"tv":11138.75}]}
{"op":"mcm","clk":"1005468028","pt":1580642846200,"mc":[{"id":"1.168224294","rc":[{"batb":[[2,1.31,135.27]],"batl":[[1,1.37,423.69]],"ltp":1.33,"tv":7316.45,"id":2257317},{"batb":[[1,3.75,57.79],[2,3.7,15.12]],"batl":[[0,4.2,22.44]],"ltp":3.45,"tv":3822.3,"id":10303696}]}]}
{"op":"mcm","clk":"1005468259","pt":1580642847293,"mc":[{"id":"1.168224294","rc":[{"batl":[[2,6.6,98.95]],"ltp":3.45,"tv":3822.3,"id":10303696}]}]}
{"op":"mcm","clk":"1005468379","pt":1580642847918,"mc":[{"id":"1.168224294","rc":[{"batb":[[1,1.32,967.54],[2,1.31,632.47]],"batl":[[0,1.36,3346.85]],"ltp":1.33,"tv":7316.45,"id":2257317}]}]}
{"op":"mcm","clk":"1005468869","pt":1580642850389,"mc":[{"id":"1.168224294","rc":[{"batl":[[2,1.42,39.25]],"ltp":1.33,"tv":7316.45,"id":2257317}]}]}
{"op":"mcm","clk":"1005469141","pt":1580642851793,"mc":[{"id":"1.168224294","rc":[{"batb":[[2,1.31,1126.51]],"batl":[[1,1.37,904.28],[2,1.39,497.4]],"ltp":1.33,"tv":7316.45,"id":2257317},{"batl":[[2,4.6,2]],"ltp":3.45,"tv":3822.3,"id":10303696}]}]}
{"op":"mcm","clk":"1005469543","pt":1580642853930,"mc":[{"id":"1.168224294","rc":[{"batb":[[0,1.31,629.31],[1,1.3,196.61],[2,1.29,510.84]],"batl":[[0,1.36,22.57],[1,1.37,522.6]],"ltp":1.33,"tv":7316.45,"id":2257317},{"batb":[[0,3.75,2.71],[1,3.7,15.12],[2,3.5,67]],"batl":[[0,4.2,12.6],[1,4.6,2],[2,4.9,2.05]],"ltp":3.45,"tv":3822.3,"id":10303696}]}]}
{"op":"mcm","clk":"1005469729","pt":1580642854591,"mc":[{"id":"1.168224294","rc":[{"batb":[[0,1.31,494.03]],"batl":[[1,1.37,480.59]],"ltp":1.33,"tv":7316.45,"id":2257317},{"batb":[[1,3.5,67],[2,3.35,2.87]],"batl":[[0,4.6,2],[1,4.9,2.05],[2,6.6,98.95]],"ltp":3.45,"tv":3822.3,"id":10303696}]}]}
{"op":"mcm","clk":"1005470167","pt":1580642856900,"mc":[{"id":"1.168224294","rc":[{"batl":[[2,1.38,205.85]],"ltp":1.33,"tv":7316.45,"id":2257317}]}]}
{"op":"mcm","clk":"1005470422","pt":1580642858291,"mc":[{"id":"1.168224294","rc":[{"batl":[[0,1.37,480.59],[1,1.38,205.85],[2,1.39,497.4]],"ltp":1.33,"tv":7316.45,"id":2257317},{"batb":[[0,3.5,67],[1,3.35,2.87],[2,3.3,2.88]],"ltp":3.45,"tv":3822.3,"id":10303696}]}]}
{"op":"mcm","clk":"1005470750","pt":1580642860316,"mc":[{"id":"1.168224294","rc":[{"batl":[[1,1.39,497.4],[2,1.4,50.24]],"ltp":1.33,"tv":7316.45,"id":2257317}]}]}
{"op":"mcm","clk":"1005470888","pt":1580642861086,"mc":[{"id":"1.168224294","rc":[{"trd":[[1.37,0.05]],"batb":[[1,1.29,510.84],[2,1.28,64.91]],"batl":[[0,1.37,480.57]],"ltp":1.37,"tv":7316.5,"id":2257317}],"tv":11138.8}]}
{"op":"mcm","clk":"1005471083","pt":1580642862212,"mc":[{"id":"1.168224294","rc":[{"batb":[[0,1.31,1184.3],[1,1.3,519.04],[2,1.29,510.84]],"batl":[[0,1.35,621.5],[1,1.36,395.07],[2,1.37,480.57]],"ltp":1.37,"tv":7316.5,"id":2257317}]}]}
{"op":"mcm","clk":"1005471160","pt":1580642862623,"mc":[{"id":"1.168224294","rc":[{"batb":[[0,1.31,494.03],[1,1.29,510.84],[2,1.28,64.91]],"batl":[[0,1.36,251.22],[1,1.37,480.57],[2,1.39,497.4]],"ltp":1.37,"tv":7316.5,"id":2257317}]}]}
{"op":"mcm","clk":"1005471667","pt":1580642865390,"mc":[{"id":"1.168224294","rc":[{"batb":[[0,1.28,384.06],[1,1.27,914.19],[2,1.26,64.48]],"ltp":1.37,"tv":7316.5,"id":2257317},{"batl":[[0,4.9,2.05],[1,6.6,98.95],[2,1000,0.02]],"ltp":3.45,"tv":3822.3,"id":10303696}]}]}
{"op":"mcm","clk":"1005471687","pt":1580642865499,"mc":[{"id":"1.168224294","rc":[{"batl":[[1,1000,0.02],[2,1000,0]],"ltp":3.45,"tv":3822.3,"id":10303696}]}]}
{"op":"mcm","clk":"1005472051","pt":1580642867405,"mc":[{"id":"1.168224294","rc":[{"trd":[[1.28,28.86]],"batb":[[0,1.28,2127.44]],"batl":[[0,1.29,744.65],[1,1.31,3642.6],[2,1.32,480.74]],"ltp":1.28,"tv":7345.36,"id":2257317},{"batb":[[0,4.1,2.44],[1,3.5,67],[2,3.35,2.87]],"batl":[[0,4.8,6.34],[1,4.9,223.05],[2,5.1,291.72]],"ltp":3.45,"tv":3822.3,"id":10303696}],"tv":11167.66}]}
{"op":"mcm","clk":"1005472228","pt":1580642868125,"mc":[{"id":"1.168224294","rc":[{"batb":[[1,1.27,1069.63]],"ltp":1.28,"tv":7345.36,"id":2257317},{"batb":[[0,4.1,101.65],[1,3.85,102.21],[2,3.5,2.64]],"batl":[[0,4.7,10.92],[1,4.8,6.34],[2,4.9,223.05]],"ltp":3.45,"tv":3822.3,"id":10303696}]}]}
{"op":"mcm","clk":"1005473406","pt":1580642874380,"mc":[{"id":"1.168224294","rc":[{"batb":[[2,1.25,502.44]],"batl":[[0,1.3,488.99],[1,1.31,2878.4]],"ltp":1.28,"tv":7345.36,"id":2257317},{"batb":[[1,3.85,104.38],[2,3.7,2.32]],"batl":[[1,5.2,2],[2,5.6,2]],"ltp":3.45,"tv":3822.3,"id":10303696}]}]}
{"op":"mcm","clk":"1005473481","pt":1580642874800,"mc":[{"id":"1.168224294","rc":[{"batb":[[0,1.25,502.44],[1,1.24,595.26],[2,1.23,401.67]],"batl":[[1,1.31,505.8],[2,1.32,22.86]],"ltp":1.28,"tv":7345.36,"id":2257317},{"batb":[[0,4.1,2.44]],"batl":[[0,5.2,2],[1,5.6,2],[2,7.8,87.91]],"ltp":3.45,"tv":3822.3,"id":10303696}]}]}
{"op":"mcm","clk":"1005474239","pt":1580642878899,"mc":[{"id":"1.168224294","rc":[{"batb":[[0,1.25,502.46]],"ltp":1.28,"tv":7345.36,"id":2257317}]}]}
{"op":"mcm","clk":"1005474484","pt":1580642880395,"mc":[{"id":"1.168224294","rc":[{"trd":[[1.29,0.06]],"batb":[[0,1.27,10.24],[1,1.25,502.44],[2,1.24,595.26]],"batl":[[0,1.29,10.47],[1,1.3,488.99],[2,1.31,505.8]],"ltp":1.29,"tv":7345.41,"id":2257317},{"batb":[[0,4.5,12.3]],"batl":[[0,4.7,11.35],[1,5.2,2],[2,5.6,2]],"ltp":3.45,"tv":3822.3,"id":10303696}],"tv":11167.71}]}
{"op":"mcm","clk":"1005474522","pt":1580642880609,"mc":[{"id":"1.168224294","rc":[{"batb":[[0,1.27,472.3],[1,1.26,616.79],[2,1.25,502.44]],"batl":[[0,1.3,1124.63],[1,1.31,982.65],[2,1.35,54.1]],"ltp":1.29,"tv":7345.41,"id":2257317},{"batb":[[0,3.85,104.38],[1,3.7,2.32],[2,3.5,2.64]],"batl":[[0,5.2,2],[1,5.6,2],[2,7.8,87.91]],"ltp":3.45,"tv":3822.3,"id":10303696}]}]}
{"op":"mcm","clk":"1005475019","pt":1580642883490,"mc":[{"id":"1.168224294","rc":[{"batb":[[0,1.25,502.44],[1,1.24,595.26],[2,1.23,401.67]],"batl":[[0,1.3,488.99],[1,1.31,505.8]],"ltp":1.29,"tv":7345.41,"id":2257317}]}]}
{"op":"mcm","clk":"1005475297","pt":1580642884978,"mc":[{"id":"1.168224294","rc":[{"batb":[[0,1.26,94.1],[1,1.25,502.44],[2,1.24,595.26]],"ltp":1.29,"tv":7345.41,"id":2257317}]}]}
{"op":"mcm","clk":"1005475518","pt":1580642886398,"mc":[{"id":"1.168224294","rc":[{"batb":[[2,1.24,869.22]],"batl":[[2,1.34,583.4]],"ltp":1.29,"tv":7345.41,"id":2257317}]}]}
{"op":"mcm","clk":"1005476749","pt":1580642893571,"mc":[{"id":"1.168224294","rc":[{"batb":[[2,1.24,595.26]],"batl":[[0,1.34,583.4],[1,1.35,464.17],[2,1.37,48.5]],"ltp":1.29,"tv":7345.41,"id":2257317}]}]}
{"op":"mcm","clk":"1005476925","pt":1580642894579,"mc":[{"id":"1.168224294","rc":[{"trd":[[1.34,0.06]],"batl":[[0,1.34,583.37]],"ltp":1.34,"tv":7345.47,"id":2257317}],"tv":11167.77}]}
{"op":"mcm","clk":"1005477241","pt":1580642896391,"mc":[{"id":"1.168224294","rc":[{"batb":[[0,1.31,1717.56],[1,1.26,94.1],[2,1.25,502.44]],"batl":[[0,1.32,735.94],[1,1.34,3460.47],[2,1.35,464.17]],"ltp":1.34,"tv":7345.47,"id":2257317},{"batl":[[0,4.2,499.56],[1,4.3,4.83],[2,4.6,331]],"ltp":3.45,"tv":3822.3,"id":10303696}]}]}
{"op":"mcm","clk":"1005477374","pt":1580642897189,"mc":[{"id":"1.168224294","rc":[{"batb":[[0,1.31,2006.45],[1,1.3,802.25],[2,1.26,94.1]],"ltp":1.34,"tv":7345.47,"id":2257317},{"batb":[[2,3.5,67.16]],"batl":[[0,4.3,4.83],[1,4.6,331],[2,4.7,367.29]],"ltp":3.45,"tv":3822.3,"id":10303696}]}]}
{"op":"mcm","clk":"1005477465","pt":1580642897735,"mc":[{"id":"1.168224294","rc":[{"batb":[[2,1.29,144.51]],"batl":[[2,1.35,506.18]],"ltp":1.34,"tv":7345.47,"id":2257317},{"batb":[[0,3.85,118.66]],"batl":[[1,4.4,11.76],[2,4.6,331]],"ltp":3.45,"tv":3822.3,"id":10303696}]}]}
{"op":"mcm","clk":"1005478026","pt":1580642901088,"mc":[{"id":"1.168224294","rc":[{"batb":[[1,3.75,2.24],[2,3.7,2.32]],"ltp":3.45,"tv":3822.3,"id":10303696}]}]}
{"op":"mcm","clk":"1005478192","pt":1580642901909,"mc":[{"id":"1.168224294","rc":[{"batb":[[1,3.7,2.32],[2,3.5,67.16]],"ltp":3.45,"tv":3822.3,"id":10303696}]}]}
{"op":"mcm","clk":"1005478523","pt":1580642903391,"mc":[{"id":"1.168224294","rc":[{"batl":[[1,1.34,3946.52]],"ltp":1.34,"tv":7345.47,"id":2257317}]}]}
{"op":"mcm","clk":"1005478660","pt":1580642904084,"mc":[{"id":"1.168224294","rc":[{"batl":[[1,1.34,3943.33]],"ltp":1.34,"tv":7345.47,"id":2257317},{"batb":[[2,3.6,2.39]],"ltp":3.45,"tv":3822.3,"id":10303696}]}]}
{"op":"mcm","clk":"1005478886","pt":1580642905359,"mc":[{"id":"1.168224294","rc":[{"trd":[[1.31,1520]],"batb":[[0,1.31,1246.45]],"ltp":1.31,"tv":8865.47,"id":2257317}],"tv":12687.77}]}
{"op":"mcm","clk":"1005479060","pt":1580642906501,"mc":[{"id":"1.168224294","rc":[{"trd":[[1.31,1520.02]],"batb":[[0,1.31,1246.44]],"ltp":1.31,"tv":8865.48,"id":2257317}],"tv":12687.79}]}
{"op":"mcm","clk":"1005480211","pt":1580642913400,"mc":[{"id":"1.168224294","rc":[{"batb":[[0,1.29,144.51],[1,1.28,158.8],[2,1.26,588.14]],"batl":[[0,1.34,482.86],[1,1.35,42.01],[2,1.36,497.4]],"ltp":1.31,"tv":8865.48,"id":2257317},{"batb":[[0,3.85,14.28],[1,3.6,2.39],[2,3.5,67.16]],"batl":[[0,4.4,11.76],[1,5.2,2],[2,5.6,2]],"ltp":3.45,"tv":3822.3,"id":10303696}]}]}
{"op":"mcm","clk":"1005480242","pt":1580642913610,"mc":[{"id":"1.168224294","rc":[{"batl":[[0,1.3,7],[1,1.34,482.86],[2,1.35,42.01]],"ltp":1.31,"tv":8865.48,"id":2257317}]}]}
{"op":"mcm","clk":"1005480482","pt":1580642914987,"mc":[{"id":"1.168224294","rc":[{"batb":[[0,1.26,588.14],[1,1.24,972.95],[2,1.22,79.84]],"batl":[[2,1.36,497.4]],"ltp":1.31,"tv":8865.48,"id":2257317},{"batb":[[0,3.6,2.39],[1,3.5,67.16],[2,3.35,2.87]],"batl":[[0,5.2,2],[1,5.6,2],[2,5.8,2]],"ltp":3.45,"tv":3822.3,"id":10303696}]}]}
{"op":"mcm","clk":"1005480671","pt":1580642916309,"mc":[{"id":"1.168224294","rc":[{"batb":[[1,1.24,1653.87],[2,1.23,717.83]],"ltp":1.31,"tv":8865.48,"id":2257317}]}]}
{"op":"mcm","clk":"1005482286","pt":1580642925802,"mc":[{"id":"1.168224294","rc":[{"batl":[[0,1.34,482.86],[1,1.36,497.4],[2,1.38,288.62]],"ltp":1.31,"tv":8865.48,"id":2257317}]}]}
{"op":"mcm","clk":"1005483238","pt":1580642931079,"mc":[{"id":"1.168224294","rc":[{"trd":[[1.34,0.11]],"batl":[[0,1.34,482.83]],"ltp":1.34,"tv":8865.53,"id":2257317}],"tv":12687.84}]}
{"op":"mcm","clk":"1005483445","pt":1580642932268,"mc":[{"id":"1.168224294","rc":[{"batb":[[1,1.24,972.95],[2,1.22,79.84]],"batl":[[0,1.34,2.27],[1,1.38,288.62],[2,1.39,360.75]],"ltp":1.34,"tv":8865.53,"id":2257317}]}]}
{"op":"mcm","clk":"1005483909","pt":1580642935186,"mc":[{"id":"1.168224294","rc":[{"trd":[[1.34,2.37]],"batb":[[0,1.35,465.16],[1,1.34,439.52],[2,1.32,153.61]],"batl":[[0,1.37,869.99],[1,1.38,1233.62]],"ltp":1.34,"tv":8867.8,"id":2257317},{"trd":[[3.9,0.78]],"batb":[[0,3.75,4.61],[1,3.6,2.39],[2,3.5,67.16]],"batl":[[0,3.85,194.81],[1,3.9,6.21],[2,4.1,239]],"ltp":3.9,"tv":3823.08,"id":10303696}],"tv":12690.89}]}
{"op":"mcm","clk":"1005484070","pt":1580642936100,"mc":[{"id":"1.168224294","rc":[{"batb":[[0,1.35,707.11],[2,1.32,284.68]],"batl":[[2,1.39,402.76]],"ltp":1.34,"tv":8867.8,"id":2257317},{"batb":[[1,3.6,18.35]],"batl":[[2,4.1,252.44]],"ltp":3.9,"tv":3823.08,"id":10303696}]}]}
{"op":"mcm","clk":"1005485069","pt":1580642941322,"mc":[{"id":"1.168224294","rc":[{"batb":[[2,1.33,494.03]],"ltp":1.34,"tv":8867.8,"id":2257317}]}]}
{"op":"mcm","clk":"1005486134","pt":1580642947005,"mc":[{"id":"1.168224294","rc":[{"trd":[[1.37,0.11]],"batl":[[0,1.37,869.96]],"ltp":1.37,"tv":8867.86,"id":2257317}],"tv":12690.94}]}
{"op":"mcm","clk":"1005486348","pt":1580642948285,"mc":[{"id":"1.168224294","rc":[{"trd":[[1.35,14]],"batb":[[0,1.35,700.11]],"ltp":1.35,"tv":8881.86,"id":2257317}],"tv":12704.94}]}
{"op":"mcm","clk":"1005487255","pt":1580642953374,"mc":[{"id":"1.168224294","rc":[{"batl":[[1,1.38,288.62]],"ltp":1.35,"tv":8881.86,"id":2257317},{"batl":[[2,4.1,13.44]],"ltp":3.9,"tv":3823.08,"id":10303696}]}]}
{"op":"mcm","clk":"1005487342","pt":1580642953971,"mc":[{"id":"1.168224294","rc":[{"batb":[[0,1.33,494.2],[1,1.32,131.07],[2,1.31,510.84]],"batl":[[0,1.39,42.01],[1,1.4,530.83],[2,1.42,536.65]],"ltp":1.35,"tv":8881.86,"id":2257317},{"batb":[[0,3.6,15.96],[1,3.5,2.64],[2,3.35,2.87]],"batl":[[0,4.1,13.44],[1,4.4,2.04],[2,4.6,2]],"ltp":3.9,"tv":3823.08,"id":10303696}]}]}
{"op":"mcm","clk":"1005487467","pt":1580642954768,"mc":[{"id":"1.168224294","rc":[{"batb":[[1,1.31,510.84],[2,1.3,352.06]],"batl":[[0,1.4,530.83],[1,1.42,536.65],[2,1.43,40.5]],"ltp":1.35,"tv":8881.86,"id":2257317},{"batb":[[0,3.5,2.64],[1,3.35,2.87],[2,3.3,76.92]],"batl":[[0,4.4,2.04],[1,4.6,2],[2,5.2,2]],"ltp":3.9,"tv":3823.08,"id":10303696}]}]}
{"op":"mcm","clk":"1005488236","pt":1580642959192,"mc":[{"id":"1.168224294","rc":[{"batb":[[0,1.34,473.76],[1,1.33,950.73],[2,1.31,510.84]],"batl":[[0,1.37,278.38],[1,1.38,372.76],[2,1.4,530.83]],"ltp":1.35,"tv":8881.86,"id":2257317}]}]}
{"op":"mcm","clk":"1005488676","pt":1580642961589,"mc":[{"id":"1.168224294","rc":[{"batb":[[0,1.33,494.2],[1,1.31,510.84],[2,1.3,352.06]],"batl":[[0,1.4,530.83],[1,1.42,536.65],[2,1.43,40.5]],"ltp":1.35,"tv":8881.86,"id":2257317}]}]}
{"op":"mcm","clk":"1005489180","pt":1580642964493,"mc":[{"id":"1.168224294","rc":[{"batb":[[2,1.3,956.25]],"batl":[[1,1.42,960.73],[2,1.43,356.54]],"ltp":1.35,"tv":8881.86,"id":2257317}]}]}
{"op":"mcm","clk":"1005490257","pt":1580642970324,"mc":[{"id":"1.168224294","rc":[{"batl":[[1,1.42,536.65],[2,1.43,40.5]],"ltp":1.35,"tv":8881.86,"id":2257317}]}]}
{"op":"mcm","clk":"1005490275","pt":1580642970438,"mc":[{"id":"1.168224294","rc":[{"batb":[[0,1.3,956.41],[1,1.29,540.41],[2,1.28,57.66]],"ltp":1.35,"tv":8881.86,"id":2257317}]}]}
{"op":"mcm","clk":"1005490843","pt":1580642973295,"mc":[{"id":"1.168224294","rc":[{"trd":[[1.34,2.71]],"batb":[[0,1.3,2687.02]],"batl":[[0,1.31,16.86],[1,1.33,3187.4],[2,1.34,428.88]],"ltp":1.34,"tv":8882.2,"id":2257317},{"batb":[[0,4.2,244.55],[1,4,2.68],[2,3.5,2.64]],"batl":[[0,4.4,6.28],[2,4.7,329]],"ltp":3.9,"tv":3823.08,"id":10303696}],"tv":12705.28}]}
{"op":"mcm","clk":"1005490974","pt":1580642974095,"mc":[{"id":"1.168224294","rc":[{"batb":[[2,1.28,207.21]],"ltp":1.34,"tv":8882.2,"id":2257317},{"batb":[[2,3.9,100.63]],"batl":[[1,4.5,11.76],[2,4.6,2]],"ltp":3.9,"tv":3823.08,"id":10303696}]}]}
{"op":"mcm","clk":"1005492589","pt":1580642983342,"mc":[{"id":"1.168224294","rc":[{"batb":[[0,1.28,149.55],[1,1.23,464.95],[2,1.22,79.84]],"batl":[[0,1.33,23.5],[1,1.35,42.01],[2,1.39,42.5]],"ltp":1.34,"tv":8882.2,"id":2257317},{"batb":[[0,4,2.68],[1,3.85,14.28],[2,3.55,65.81]],"batl":[[0,4.5,11.76],[1,5.4,2],[2,5.6,2]],"ltp":3.9,"tv":3823.08,"id":10303696}]}]}
{"op":"mcm","clk":"1005492698","pt":1580642983825,"mc":[{"id":"1.168224294","rc":[{"batl":[[0,1.33,23.67]],"ltp":1.34,"tv":8882.2,"id":2257317}]}]}
{"op":"mcm","clk":"1005492895","pt":1580642984839,"mc":[{"id":"1.168224294","rc":[{"batb":[[0,1.23,464.95],[1,1.22,79.84],[2,1.21,86.69]],"batl":[[1,1.39,42.5],[2,1.96,398.24]],"ltp":1.34,"tv":8882.2,"id":2257317},{"batb":[[1,3.55,65.81],[2,2.62,379.26]],"batl":[[0,5.4,2],[1,5.6,2],[2,5.8,2]],"ltp":3.9,"tv":3823.08,"id":10303696}]}]}
{"op":"mcm","clk":"1005493115","pt":1580642986128,"mc":[{"id":"1.168224294","rc":[{"batb":[[0,1.24,490.94],[1,1.23,1178.05],[2,1.22,79.84]],"batl":[[0,1.38,421.84],[1,1.39,401.32]],"ltp":1.34,"tv":8882.2,"id":2257317},{"batb":[[0,3.55,65.81],[1,2.62,379.26],[2,2.2,75.72]],"ltp":3.9,"tv":3823.08,"id":10303696}]}]}
{"op":"mcm","clk":"1005493434","pt":1580642987946,"mc":[{"id":"1.168224294","rc":[{"batl":[[0,1.3,70.72],[1,1.38,421.84],[2,1.39,401.32]],"ltp":1.34,"tv":8882.2,"id":2257317}]}]}
{"op":"mcm","clk":"1005494667","pt":1580642994393,"mc":[{"id":"1.168224294","rc":[{"batl":[[1,1.39,42.67],[2,1.96,398.24]],"ltp":1.34,"tv":8882.2,"id":2257317}]}]}
{"op":"mcm","clk":"1005494690","pt":1580642994501,"mc":[{"id":"1.168224294","rc":[{"batb":[[2,1.2,74.32]],"ltp":1.34,"tv":8882.2,"id":2257317},{"batl":[[1,6,2],[2,7.2,92.18]],"ltp":3.9,"tv":3823.08,"id":10303696}]}]}
{"op":"mcm","clk":"1005494975","pt":1580642996004,"mc":[{"id":"1.168224294","rc":[{"batb":[[1,2.2,75.72],[2,2,75.72]],"batl":[[2,1000,0.02]],"ltp":3.9,"tv":3823.08,"id":10303696}]}]}
{"op":"mcm","clk":"1005495257","pt":1580642997399,"mc":[{"id":"1.168224294","rc":[{"batb":[[0,1.24,2305.46],[1,1.23,1192.74],[2,1.2,872.01]],"batl":[[0,1.25,543.87],[1,1.26,3166.43],[2,1.27,573.81]],"ltp":1.34,"tv":8882.2,"id":2257317},{"batb":[[0,5.1,5.29],[1,5,135.97],[2,4.8,2.33]],"batl":[[1,5.7,264],[2,6,161.54]],"ltp":3.9,"tv":3823.08,"id":10303696}]}]}
{"op":"mcm","clk":"1005495407","pt":1580642998270,"mc":[{"id":"1.168224294","rc":[{"trd":[[1.24,20.27]],"batb":[[0,1.24,2295.32],[2,1.22,418.51]],"batl":[[2,1.27,615.82]],"ltp":1.24,"tv":8902.47,"id":2257317},{"batl":[[1,5.6,8.4],[2,5.7,264]],"ltp":3.9,"tv":3823.08,"id":10303696}],"tv":12725.55}]}
{"op":"mcm","clk":"1005498179","pt":1580643012125,"mc":[{"id":"1.168224294","rc":[{"trd":[[1.25,28.04]],"batl":[[0,1.25,529.85]],"ltp":1.25,"tv":8930.5,"id":2257317}],"tv":12753.59}]}
{"op":"mcm","clk":"1005498771","pt":1580643015118,"mc":[{"id":"1.168224294","rc":[{"trd":[[1.24,161.75]],"batb":[[0,1.24,2224.56]],"ltp":1.24,"tv":9071.98,"id":2257317}],"tv":12895.07}]}
{"op":"mcm","clk":"1005499333","pt":1580643018323,"mc":[{"id":"1.168224294","rc":[{"trd":[[1.24,232.5]],"batb":[[0,1.24,2193.35]],"batl":[[1,1.26,3210.42]],"ltp":1.24,"tv":9142.73,"id":2257317},{"trd":[[5.2,16.87]],"ltp":5.2,"tv":3839.95,"id":10303696}],"tv":12982.69}]}
{"op":"mcm","clk":"1005499889","pt":1580643021344,"mc":[{"id":"1.168224294","rc":[{"trd":[[1.25,28.09]],"batb":[[0,1.24,2225.01]],"batl":[[0,1.25,529.82],[1,1.26,3248.89]],"ltp":1.25,"tv":9142.79,"id":2257317}],"tv":12982.74}]}
{"op":"mcm","clk":"1005501260","pt":1580643028459,"mc":[{"id":"1.168224294","rc":[{"trd":[[1.24,303.25]],"batb":[[0,1.24,2154.26]],"ltp":1.24,"tv":9213.54,"id":2257317},{"trd":[[5.2,33.74]],"ltp":5.2,"tv":3856.82,"id":10303696}],"tv":13070.37}]}
{"op":"mcm","clk":"1005501917","pt":1580643031847,"mc":[{"id":"1.168224294","rc":[{"batb":[[0,1.24,2185.91]],"batl":[[1,1.26,3287.36]],"ltp":1.24,"tv":9213.54,"id":2257317}]}]}
{"op":"mcm","clk":"1005502960","pt":1580643037962,"mc":[{"id":"1.168224294","rc":[{"trd":[[5.1,2.12]],"batb":[[0,5.1,4.23]],"ltp":5.1,"tv":3858.94,"id":10303696}],"tv":13072.49}]}
{"op":"mcm","clk":"1005504636","pt":1580643048082,"mc":[{"id":"1.168224294","rc":[{"batb":[[1,1.23,1178.05]],"ltp":1.24,"tv":9213.54,"id":2257317},{"batb":[[0,5,135.97],[1,4.8,2.33],[2,4.7,10.92]],"ltp":5.1,"tv":3858.94,"id":10303696}]}]}
{"op":"mcm","clk":"1005505305","pt":1580643051373,"mc":[{"id":"1.168224294","rc":[{"batb":[[1,1.23,1197.13]],"ltp":1.24,"tv":9213.54,"id":2257317},{"batb":[[0,5.1,4.23],[1,5,135.97],[2,4.8,2.33]],"ltp":5.1,"tv":3858.94,"id":10303696}]}]}
{"op":"mcm","clk":"1005505871","pt":1580643054540,"mc":[{"id":"1.168224294","rc":[{"trd":[[1.25,29.67]],"batl":[[0,1.25,529.03]],"ltp":1.25,"tv":9215.12,"id":2257317}],"tv":13074.06}]}
{"op":"mcm","clk":"1005507578","pt":1580643063147,"mc":[{"id":"1.168224294","rc":[{"trd":[[1.24,303.57]],"batb":[[0,1.24,2185.75]],"ltp":1.24,"tv":9215.43,"id":2257317}],"tv":13074.38}]}
{"op":"mcm","clk":"1005508175","pt":1580643066373,"mc":[{"id":"1.168224294","rc":[{"trd":[[1.24,1457.34]],"batb":[[0,1.24,929.13]],"ltp":1.24,"tv":10369.2,"id":2257317},{"trd":[[5.2,308.6]],"ltp":5.2,"tv":4133.79,"id":10303696}],"tv":14503.0}]}
{"op":"mcm","clk":"1005508747","pt":1580643069358,"mc":[{"id":"1.168224294","rc":[{"batb":[[1,1.23,1426.99],[2,1.22,1063.96]],"batl":[[1,1.26,3433.39]],"ltp":1.24,"tv":10369.2,"id":2257317}]}]}
{"op":"mcm","clk":"1005510902","pt":1580643081266,"mc":[{"id":"1.168224294","rc":[{"trd":[[1.24,1661.34]],"batb":[[0,1.24,827.15],[1,1.23,1427],[2,1.22,1063.98]],"ltp":1.24,"tv":10573.2,"id":2257317}],"tv":14707.0}]}
{"op":"mcm","clk":"1005511529","pt":1580643084352,"mc":[{"id":"1.168224294","rc":[{"trd":[[1.25,38.41]],"batl":[[0,1.25,524.66],[1,1.26,2337.39]],"ltp":1.25,"tv":10581.94,"id":2257317},{"batl":[[2,6,161.54]],"ltp":5.2,"tv":4133.79,"id":10303696}],"tv":14715.74}]}
{"op":"mcm","clk":"1005512289","pt":1580643088114,"mc":[{"id":"1.168224294","rc":[{"batb":[[0,1.23,75.66],[1,1.22,1137.82],[2,1.05,378.82]],"batl":[[0,1.27,42.01],[1,1.29,60.5],[2,1.31,57.5]],"ltp":1.25,"tv":10581.94,"id":2257317},{"batb":[[0,4.7,10.92],[1,4.4,2.01],[2,4.2,83.06]],"batl":[[1,5.6,10.4],[2,9.8,75.27]],"ltp":5.2,"tv":4133.79,"id":10303696}]}]}
{"op":"mcm","clk":"1005512409","pt":1580643088813,"mc":[{"id":"1.168224294","rc":[{"batb":[[0,1.22,1137.85],[1,1.05,378.82],[2,1.03,388.36]],"batl":[[0,1.31,57.5],[1,1.96,398.41],[2,2.5,10.13]],"ltp":1.25,"tv":10581.94,"id":2257317},{"batb":[[0,4.2,83.06],[1,3,380.95],[2,2.6,75.72]],"batl":[[0,5.6,2],[1,9.8,75.27],[2,1000,0.02]],"ltp":5.2,"tv":4133.79,"id":10303696}]}]}
{"op":"mcm","clk":"1005512842","pt":1580643091199,"mc":[{"id":"1.168224294","rc":[{"batb":[[0,1.22,1346.7],[1,1.21,747.96],[2,1.05,378.82]],"batl":[[0,1.29,688.32],[1,1.3,501.72],[2,1.31,57.5]],"ltp":1.25,"tv":10581.94,"id":2257317}]}]}
{"op":"mcm","clk":"1005512960","pt":1580643091844,"mc":[{"id":"1.168224294","rc":[{"batl":[[0,1.29,740.82]],"ltp":1.25,"tv":10581.94,"id":2257317},{"batb":[[0,4.4,2.01],[1,4.2,83.06],[2,3,380.95]],"ltp":5.2,"tv":4133.79,"id":10303696}]}]}
{"op":"mcm","clk":"1005514127","pt":1580643097827,"mc":[{"id":"1.168224294","rc":[{"batl":[[0,1.31,57.5],[1,1.96,398.41],[2,2.5,10.13]],"ltp":1.25,"tv":10581.94,"id":2257317},{"batb":[[0,4.2,83.06],[1,3,380.95],[2,2.6,75.72]],"ltp":5.2,"tv":4133.79,"id":10303696}]}]}
{"op":"mcm","clk":"1005514587","pt":1580643100340,"mc":[{"id":"1.168224294","rc":[{"trd":[[1.23,0.04],[1.24,1661.35]],"batb":[[0,1.22,1346.67]],"batl":[[0,1.23,19.95],[1,1.25,7498.8],[2,1.26,1683.24]],"ltp":1.23,"tv":10582.0,"id":2257317},{"batb":[[0,5.2,827.15],[1,5.1,490.82],[2,4.2,83.06]],"batl":[[1,5.7,6.2],[2,5.9,207]],"ltp":5.2,"tv":4133.79,"id":10303696}],"tv":14715.8}]}
{"op":"mcm","clk":"1005514781","pt":1580643101300,"mc":[{"id":"1.168224294","rc":[{"batb":[[1,1.21,1193.38]],"batl":[[1,1.25,2024.77],[2,1.26,787.31]],"ltp":1.23,"tv":10582.0,"id":2257317},{"batb":[[0,5.2,82.72],[2,4.8,61.83]],"ltp":5.2,"tv":4133.79,"id":10303696}]}]}
{"op":"mcm","clk":"1005514874","pt":1580643101839,"mc":[{"id":"1.168224294","rc":[{"batb":[[2,1.2,168.14]],"batl":[[1,1.25,2066.78]],"ltp":1.23,"tv":10582.0,"id":2257317},{"batb":[[2,4.9,10.08]],"batl":[[2,5.8,8.4]],"ltp":5.2,"tv":4133.79,"id":10303696}]}]}
{"op":"mcm","clk":"1005516265","pt":1580643109521,"mc":[{"id":"1.168224294","rc":[{"batb":[[1,1.21,1271.07]],"ltp":1.23,"tv":10582.0,"id":2257317},{"batl":[[2,5.8,10.4]],"ltp":5.2,"tv":4133.79,"id":10303696}]}]}
{"op":"mcm","clk":"1005516510","pt":1580643110814,"mc":[{"id":"1.168224294","rc":[{"batl":[[0,1.25,2066.78],[1,1.26,787.31],[2,1.27,59.5]],"ltp":1.23,"tv":10582.0,"id":2257317},{"batl":[[1,5.8,10.4],[2,5.9,207]],"ltp":5.2,"tv":4133.79,"id":10303696}]}]}
{"op":"mcm","clk":"1005516952","pt":1580643113263,"mc":[{"id":"1.168224294","rc":[{"batb":[[0,1.21,1271.09],[1,1.05,378.82],[2,1.03,388.37]],"batl":[[0,1.26,22.25],[1,1.29,59.5],[2,1.31,57.5]],"ltp":1.23,"tv":10582.0,"id":2257317},{"batb":[[0,4.8,2.03],[1,4.5,71.13],[2,4.4,2.01]],"batl":[[0,5.8,2],[1,9.8,75.27],[2,1000,0.02]],"ltp":5.2,"tv":4133.79,"id":10303696}]}]}
{"op":"mcm","clk":"1005517107","pt":1580643113960,"mc":[{"id":"1.168224294","rc":[{"batl":[[0,1.29,59.5],[1,1.31,57.5],[2,1.96,398.41]],"ltp":1.23,"tv":10582.0,"id":2257317},{"batb":[[0,4.5,71.13],[1,4.4,2.01],[2,4.2,2.02]],"ltp":5.2,"tv":4133.79,"id":10303696}]}]}
{"op":"mcm","clk":"1005517343","pt":1580643115130,"mc":[{"id":"1.168224294","rc":[{"batb":[[0,1.23,4.09],[1,1.21,1271.09],[2,1.05,378.82]],"ltp":1.23,"tv":10582.0,"id":2257317}]}]}
{"op":"mcm","clk":"1005517541","pt":1580643116356,"mc":[{"id":"1.168224294","rc":[{"batb":[[1,1.22,74.36],[2,1.21,1461.4]],"batl":[[0,1.27,572.34],[1,1.28,548.18],[2,1.29,59.5]],"ltp":1.23,"tv":10582.0,"id":2257317},{"batl":[[0,5.6,2],[1,5.8,2],[2,9.8,75.27]],"ltp":5.2,"tv":4133.79,"id":10303696}]}]}
{"op":"mcm","clk":"1005517584","pt":1580643116520,"mc":[{"id":"1.168224294","rc":[{"batb":[[1,1.21,1461.42],[2,1.2,676.73]],"batl":[[0,1.27,630.84]],"ltp":1.23,"tv":10582.0,"id":2257317},{"batb":[[0,4.7,2.02],[1,4.5,71.13],[2,4.4,2.01]],"batl":[[0,5.8,2],[1,9.8,75.27],[2,1000,0.02]],"ltp":5.2,"tv":4133.79,"id":10303696}]}]}
{"op":"mcm","clk":"1005518048","pt":1580643119244,"mc":[{"id":"1.168224294","rc":[{"batb":[[1,1.21,523.13],[2,1.05,378.82]],"ltp":1.23,"tv":10582.0,"id":2257317}]}]}
{"op":"mcm","clk":"1005518254","pt":1580643120274,"mc":[{"id":"1.168224294","rc":[{"batb":[[0,1.21,523.13],[1,1.05,378.82],[2,1.03,388.36]],"ltp":1.23,"tv":10582.0,"id":2257317}]}]}
{"op":"mcm","clk":"1005518388","pt":1580643120984,"mc":[{"id":"1.168224294","rc":[{"batl":[[1,1000,0.02],[2,1000,0]],"ltp":5.2,"tv":4133.79,"id":10303696}]}]}
{"op":"mcm","clk":"1005518626","pt":1580643122381,"mc":[{"id":"1.168224294","rc":[{"batb":[[0,1.24,796.25],[1,1.23,732.43],[2,1.21,523.13]],"batl":[[0,1.26,1010.74],[1,1.27,1630.84],[2,1.28,548.18]],"ltp":1.23,"tv":10582.0,"id":2257317},{"batl":[[0,5.1,4.02],[1,5.5,315.21],[2,5.6,34.8]],"ltp":5.2,"tv":4133.79,"id":10303696}]}]}
{"op":"mcm","clk":"1005518813","pt":1580643123383,"mc":[{"id":"1.168224294","rc":[{"batb":[[0,1.24,1168.67],[1,1.23,1133.33],[2,1.21,77.72]],"ltp":1.23,"tv":10582.0,"id":2257317}]}]}
{"op":"mcm","clk":"1005518893","pt":1580643123778,"mc":[{"id":"1.168224294","rc":[{"batb":[[2,1.22,168.06]],"batl":[[1,1.27,1672.85]],"ltp":1.23,"tv":10582.0,"id":2257317},{"batb":[[0,4.7,12.94]],"batl":[[1,5.5,324.45]],"ltp":5.2,"tv":4133.79,"id":10303696}]}]}
{"op":"mcm","clk":"1005519811","pt":1580643128990,"mc":[{"id":"1.168224294","rc":[{"batb":[[1,1.23,1200.96]],"batl":[[2,1.28,610.02]],"ltp":1.23,"tv":10582.0,"id":2257317},{"batb":[[1,4.5,73.23]],"batl":[[1,5.4,2],[2,5.5,324.45]],"ltp":5.2,"tv":4133.79,"id":10303696}]}]}
{"op":"mcm","clk":"1005520718","pt":1580643134273,"mc":[{"id":"1.168224294","rc":[{"batb":[[0,1.23,981.63],[1,1.22,168.06],[2,1.21,77.71]],"batl":[[0,1.27,42.01],[1,1.29,59.5],[2,1.96,398.41]],"ltp":1.23,"tv":10582.0,"id":2257317},{"batb":[[0,4.7,10.92],[1,4.4,2.01],[2,4.1,89.3]],"batl":[[0,5.4,2],[1,5.5,9.24],[2,5.8,2]],"ltp":5.2,"tv":4133.79,"id":10303696}]}]}
{"op":"mcm","clk":"1005520825","pt":1580643134908,"mc":[{"id":"1.168224294","rc":[{"batb":[[1,1.21,77.72],[2,1.05,378.82]],"batl":[[0,1.29,59.5],[1,1.96,398.41],[2,2.5,10.13]],"ltp":1.23,"tv":10582.0,"id":2257317},{"batb":[[0,4.4,2.01],[1,4.1,89.3],[2,3,380.95]],"batl":[[1,5.8,2],[2,8.6,81.89]],"ltp":5.2,"tv":4133.79,"id":10303696}]}]}
{"op":"mcm","clk":"1005521180","pt":1580643137302,"mc":[{"id":"1.168224294","rc":[{"batb":[[1,1.22,765.15],[2,1.21,77.71]],"batl":[[0,1.28,65.84],[1,1.29,59.5],[2,1.3,440.99]],"ltp":1.23,"tv":10582.0,"id":2257317},{"batb":[[0,4.5,2.1],[1,4.4,2.01],[2,4.1,89.3]],"ltp":5.2,"tv":4133.79,"id":10303696}]}]}
{"op":"mcm","clk":"1005521269","pt":1580643137890,"mc":[{"id":"1.168224294","rc":[{"batb":[[0,1.25,2.18],[1,1.23,981.63],[2,1.22,765.15]],"batl":[[0,1.29,59.5],[1,1.3,440.99],[2,1.31,486.15]],"ltp":1.23,"tv":10582.0,"id":2257317},{"batb":[[0,4.4,2.01],[1,4.1,89.3],[2,3,380.95]],"ltp":5.2,"tv":4133.79,"id":10303696}]}]}
{"op":"mcm","clk":"1005521551","pt":1580643139481,"mc":[{"id":"1.168224294","rc":[{"batb":[[1,1.23,468.55],[2,1.21,77.72]],"batl":[[1,1.96,398.41],[2,2.5,10.13]],"ltp":1.23,"tv":10582.0,"id":2257317}]}]}
{"op":"mcm","clk":"1005522050","pt":1580643142374,"mc":[{"id":"1.168224294","rc":[{"batb":[[0,1.25,498.18],[1,1.24,688.55],[2,1.23,468.53]],"batl":[[0,1.28,768.08],[1,1.29,580.93],[2,1.96,398.41]],"ltp":1.23,"tv":10582.0,"id":2257317}]}]}
{"op":"mcm","clk":"1005522456","pt":1580643144296,"mc":[{"id":"1.168224294","rc":[{"batl":[[0,1.28,832.92]],"ltp":1.23,"tv":10582.0,"id":2257317},{"batb":[[0,4.5,2.1],[1,4.4,2.01],[2,4.1,89.3]],"ltp":5.2,"tv":4133.79,"id":10303696}]}]}
{"op":"mcm","clk":"1005522708","pt":1580643145283,"mc":[{"id":"1.168224294","rc":[{"batb":[[0,1.25,2.18],[1,1.23,468.55],[2,1.21,77.72]],"batl":[[0,1.28,64.84],[1,1.29,59.5]],"ltp":1.23,"tv":10582.0,"id":2257317}]}]}
{"op":"mcm","clk":"1005522741","pt":1580643145494,"mc":[{"id":"1.168224294","rc":[{"batl":[[0,1.29,59.5],[1,1.96,398.41],[2,2.5,10.13]],"ltp":1.23,"tv":10582.0,"id":2257317},{"batb":[[0,4.4,2.01],[1,4.1,89.3],[2,3,380.95]],"ltp":5.2,"tv":4133.79,"id":10303696}]}]}
{"op":"mcm","clk":"1005523354","pt":1580643148896,"mc":[{"id":"1.168224294","rc":[{"batb":[[1,1.23,981.63],[2,1.22,765.15]],"batl":[[1,1.3,440.99],[2,1.31,486.15]],"ltp":1.23,"tv":10582.0,"id":2257317}]}]}
{"op":"mcm","clk":"1005524297","pt":1580643154304,"mc":[{"id":"1.168224294","rc":[{"batb":[[1,1.23,468.55],[2,1.21,77.72]],"batl":[[1,1.96,398.41],[2,2.5,10.13]],"ltp":1.23,"tv":10582.0,"id":2257317}]}]}
{"op":"mcm","clk":"1005524825","pt":1580643157317,"mc":[{"id":"1.168224294","rc":[{"batb":[[0,1.28,17.54],[1,1.27,700.07],[2,1.26,628.72]],"batl":[[1,1.3,2197.09],[2,1.31,486.15]],"ltp":1.23,"tv":10582.0,"id":2257317},{"batb":[[0,4.4,5.55]],"batl":[[0,4.7,159.57],[1,5,474.79],[2,5.4,2]],"ltp":5.2,"tv":4133.79,"id":10303696}]}]}
{"op":"mcm","clk":"1005525028","pt":1580643158289,"mc":[{"id":"1.168224294","rc":[{"batb":[[0,1.28,335.89]],"batl":[[1,1.3,2239.1]],"ltp":1.23,"tv":10582.0,"id":2257317},{"batb":[[1,4.3,12.6],[2,4.1,89.3]],"batl":[[1,5,484.87]],"ltp":5.2,"tv":4133.79,"id":10303696}]}]}
{"op":"mcm","clk":"1005526333","pt":1580643164578,"mc":[{"id":"1.168224294","rc":[{"batl":[[1,5,486.87]],"ltp":5.2,"tv":4133.79,"id":10303696}]}]}
{"op":"mcm","clk":"1005528318","pt":1580643174305,"mc":[{"id":"1.168224294","rc":[{"batb":[[0,1.28,318.35]],"batl":[[0,1.3,483],[1,1.31,486.15],[2,1.33,54.67]],"ltp":1.23,"tv":10582.0,"id":2257317},{"batb":[[0,4.3,12.6],[1,4.1,89.3],[2,4,2.18]],"batl":[[1,5,12.08]],"ltp":5.2,"tv":4133.79,"id":10303696}]}]}
{"op":"mcm","clk":"1005528531","pt":1580643175315,"mc":[{"id":"1.168224294","rc":[{"batb":[[0,1.25,422.5],[1,1.23,67.66],[2,1.21,77.72]],"batl":[[0,1.35,50.87],[1,1.96,398.24],[2,2.5,10.13]],"ltp":1.23,"tv":10582.0,"id":2257317},{"batb":[[0,3.85,2.37],[1,3.7,57.28],[2,3,380.95]],"batl":[[0,5,2],[1,5.4,2],[2,5.8,2]],"ltp":5.2,"tv":4133.79,"id":10303696}]}]}
{"op":"mcm","clk":"1005529892","pt":1580643181846,"mc":[{"id":"1.168224294","rc":[{"batb":[[0,1.28,586.52],[1,1.27,597.93],[2,1.25,422.5]],"batl":[[0,1.31,483.34],[1,1.32,466.7],[2,1.33,50.67]],"ltp":1.23,"tv":10582.0,"id":2257317},{"batb":[[0,4,2.18],[1,3.85,2.37],[2,3.7,57.28]],"ltp":5.2,"tv":4133.79,"id":10303696}]}]}
{"op":"mcm","clk":"1005530087","pt":1580643182862,"mc":[{"id":"1.168224294","rc":[{"batb":[[0,1.25,422.5],[1,1.23,67.66],[2,1.21,77.72]],"batl":[[0,1.35,50.87],[1,1.96,398.24],[2,2.5,10.13]],"ltp":1.23,"tv":10582.0,"id":2257317},{"batb":[[0,3.85,2.37],[1,3.7,57.28],[2,3,380.95]],"ltp":5.2,"tv":4133.79,"id":10303696}]}]}
{"op":"mcm","clk":"1005530742","pt":1580643186041,"mc":[{"id":"1.168224294","rc":[{"batb":[[0,1.25,1090.87],[1,1.24,692.61],[2,1.23,67.65]],"batl":[[0,1.35,613.18],[1,1.36,401.66],[2,1.96,398.24]],"ltp":1.23,"tv":10582.0,"id":2257317}]}]}
{"op":"mcm","clk":"1005531342","pt":1580643189275,"mc":[{"id":"1.168224294","rc":[{"batl":[[0,1.33,44.67],[1,1.35,613.01],[2,1.36,401.66]],"ltp":1.23,"tv":10582.0,"id":2257317},{"batb":[[0,4,2.18],[1,3.85,2.37],[2,3.7,57.28]],"ltp":5.2,"tv":4133.79,"id":10303696}]}]}
{"op":"mcm","clk":"1005531381","pt":1580643189491,"mc":[{"id":"1.168224294","rc":[{"batl":[[0,1.35,613.18],[1,1.36,401.66],[2,1.96,398.24]],"ltp":1.23,"tv":10582.0,"id":2257317},{"batb":[[0,3.85,2.37],[1,3.7,57.28],[2,3,380.95]],"ltp":5.2,"tv":4133.79,"id":10303696}]}]}
{"op":"mcm","clk":"1005531794","pt":1580643191874,"mc":[{"id":"1.168224294","rc":[{"batl":[[0,1.35,50.87],[1,1.96,398.24],[2,2.5,10.13]],"ltp":1.23,"tv":10582.0,"id":2257317}]}]}
{"op":"mcm","clk":"1005532399","pt":1580643195079,"mc":[{"id":"1.168224294","rc":[{"batb":[[0,1.25,2908.22]],"batl":[[0,1.27,778.94],[1,1.28,3247.12],[2,1.29,524.48]],"ltp":1.23,"tv":10582.0,"id":2257317},{"batb":[[0,4.7,2.22],[1,3.85,2.37],[2,3.7,57.28]],"batl":[[0,5,6.34],[1,5.3,518.66],[2,5.4,2]],"ltp":5.2,"tv":4133.79,"id":10303696}]}]}
{"op":"mcm","clk":"1005532614","pt":1580643196165,"mc":[{"id":"1.168224294","rc":[{"batb":[[2,1.23,628.07]],"batl":[[1,1.28,3289.13]],"ltp":1.23,"tv":10582.0,"id":2257317},{"batb":[[1,4.5,11.76],[2,4.3,75.93]],"batl":[[1,5.3,527.9]],"ltp":5.2,"tv":4133.79,"id":10303696}]}]}
{"op":"mcm","clk":"1005533779","pt":1580643201858,"mc":[{"id":"1.168224294","rc":[{"batb":[[1,1.24,768.13]],"ltp":1.23,"tv":10582.0,"id":2257317},{"batb":[[2,4.3,78.01]],"batl":[[1,5.2,2],[2,5.3,527.9]],"ltp":5.2,"tv":4133.79,"id":10303696}]}]}
{"op":"mcm","clk":"1005535206","pt":1580643208368,"mc":[{"id":"1.168224294","rc":[{"batb":[[0,1.25,2890.87]],"batl":[[0,1.27,24.5],[1,1.28,2410.13]],"ltp":1.23,"tv":10582.0,"id":2257317},{"batl":[[0,5,2],[2,5.3,9.24]],"ltp":5.2,"tv":4133.79,"id":10303696}]}]}
{"op":"mcm","clk":"1005535430","pt":1580643209334,"mc":[{"id":"1.168224294","rc":[{"batb":[[0,1.25,2.18],[1,1.23,460.05],[2,1.21,77.72]],"batl":[[0,1.32,47.61],[1,1.35,50.87],[2,1.96,398.24]],"ltp":1.23,"tv":10582.0,"id":2257317},{"batb":[[0,4.1,2.04],[1,3.9,99.93],[2,3.85,2.37]],"batl":[[0,5.4,2],[1,5.8,2],[2,8.6,81.89]],"ltp":5.2,"tv":4133.79,"id":10303696}]}]}
{"op":"mcm","clk":"1005535917","pt":1580643211656,"mc":[{"id":"1.168224294","rc":[{"batb":[[1,1.23,1241.72],[2,1.22,772.38]],"batl":[[0,1.32,508.79],[1,1.33,449.68],[2,1.35,50.7]],"ltp":1.23,"tv":10582.0,"id":2257317}]}]}
{"op":"mcm","clk":"1005536604","pt":1580643214937,"mc":[{"id":"1.168224294","rc":[{"batb":[[1,1.23,460.05],[2,1.21,77.72]],"batl":[[0,1.32,47.61],[1,1.35,50.87],[2,1.96,398.24]],"ltp":1.23,"tv":10582.0,"id":2257317}]}]}
{"op":"mcm","clk":"1005537593","pt":1580643219335,"mc":[{"id":"1.168224294","rc":[{"batb":[[0,1.26,499.78],[1,1.25,657.45],[2,1.24,70.04]],"batl":[[0,1.29,692.54],[1,1.3,557.99],[2,1.32,47.61]],"ltp":1.23,"tv":10582.0,"id":2257317},{"batb":[[0,4.3,2.08],[1,4.1,2.04],[2,3.9,99.93]],"batl":[[0,5.2,2],[1,5.4,2],[2,5.8,2]],"ltp":5.2,"tv":4133.79,"id":10303696}]}]}
{"op":"mcm","clk":"1005537744","pt":1580643220169,"mc":[{"id":"1.168224294","rc":[{"batb":[[0,1.25,2.18],[1,1.23,460.05],[2,1.21,77.72]],"batl":[[0,1.32,47.61],[1,1.35,50.87],[2,1.96,398.24]],"ltp":1.23,"tv":10582.0,"id":2257317},{"batb":[[0,4.1,2.04],[1,3.9,99.93],[2,3.85,2.37]],"batl":[[0,5.4,2],[1,5.8,2],[2,8.6,81.89]],"ltp":5.2,"tv":4133.79,"id":10303696}]}]}
{"op":"mcm","clk":"1005538343","pt":1580643223279,"mc":[{"id":"1.168224294","rc":[{"batb":[[1,1.24,84.29],[2,1.23,1241.7]],"batl":[[0,1.3,56.65],[1,1.32,508.79],[2,1.33,449.68]],"ltp":1.23,"tv":10582.0,"id":2257317},{"batb":[[0,4.3,2.08],[1,4.1,2.04],[2,3.9,99.93]],"batl":[[0,5.2,2],[1,5.4,2],[2,5.8,2]],"ltp":5.2,"tv":4133.79,"id":10303696}]}]}
{"op":"mcm","clk":"1005538407","pt":1580643223595,"mc":[{"id":"1.168224294","rc":[{"batb":[[1,1.23,1241.72],[2,1.22,772.38]],"batl":[[0,1.32,508.79],[1,1.33,449.68],[2,1.35,50.7]],"ltp":1.23,"tv":10582.0,"id":2257317},{"batb":[[0,4.1,2.04],[1,3.9,99.93],[2,3.85,2.37]],"batl":[[0,5.4,2],[1,5.8,2],[2,8.6,81.89]],"ltp":5.2,"tv":4133.79,"id":10303696}]}]}
{"op":"mcm","clk":"1005539368","pt":1580643228809,"mc":[{"id":"1.168224294","rc":[{"batl":[[0,1.32,47.61],[1,1.35,50.87],[2,1.96,398.24]],"ltp":1.23,"tv":10582.0,"id":2257317}]}]}
{"op":"mcm","clk":"1005539641","pt":1580643230360,"mc":[{"id":"1.168224294","rc":[{"batl":[[2,1000,0.02]],"ltp":5.2,"tv":4133.79,"id":10303696}]}]}
{"op":"mcm","clk":"1005539834","pt":1580643231392,"mc":[{"id":"1.168224294","rc":[{"trd":[[1.25,42.77]],"batb":[[0,1.23,3070.99],[1,1.22,772.38],[2,1.21,77.71]],"batl":[[0,1.25,1806.1],[1,1.26,6569.2],[2,1.29,14.09]],"ltp":1.25,"tv":10586.36,"id":2257317},{"batl":[[0,5.3,6.63],[1,5.4,2],[2,5.6,238]],"ltp":5.2,"tv":4133.79,"id":10303696}],"tv":14720.16}]}
{"op":"mcm","clk":"1005539965","pt":1580643232000,"mc":[{"id":"1.168224294","rc":[{"batb":[[2,1.21,245.75]],"batl":[[0,1.25,2255.89],[1,1.26,1548.28],[2,1.27,570.79]],"ltp":1.25,"tv":10586.36,"id":2257317},{"batb":[[0,5,108.39],[1,4.8,10.92],[2,4.1,2.04]],"batl":[[2,5.6,246.4]],"ltp":5.2,"tv":4133.79,"id":10303696}]}]}
{"op":"mcm","clk":"1005540102","pt":1580643232701,"mc":[{"id":"1.168224294","rc":[{"batb":[[1,1.22,1195.84]],"ltp":1.25,"tv":10586.36,"id":2257317},{"batb":[[2,4.6,65.86]],"ltp":5.2,"tv":4133.79,"id":10303696}]}]}
{"op":"mcm","clk":"1005540542","pt":1580643235115,"mc":[{"id":"1.168224294","rc":[{"trd":[[1.25,42.83]],"batl":[[0,1.25,2255.86]],"ltp":1.25,"tv":10586.41,"id":2257317}],"tv":14720.21}]}
{"op":"mcm","clk":"1005541325","pt":1580643238776,"mc":[{"id":"1.168224294","rc":[{"batb":[[1,1.22,1284.18]],"batl":[[1,1.26,1607.53],[2,1.27,642.29]],"ltp":1.25,"tv":10586.41,"id":2257317},{"batb":[[1,4.8,12.95],[2,4.7,2.02]],"batl":[[2,5.6,248.4]],"ltp":5.2,"tv":4133.79,"id":10303696}]}]}
{"op":"mcm","clk":"1005542145","pt":1580643243115,"mc":[{"id":"1.168224294","rc":[{"trd":[[1.25,51.01]],"batl":[[0,1.25,2251.77]],"ltp":1.25,"tv":10594.6,"id":2257317}],"tv":14728.4}]}
{"op":"mcm","clk":"1005542765","pt":1580643246278,"mc":[{"id":"1.168224294","rc":[{"batb":[[0,1.23,1896.93],[1,1.22,1086.02]],"batl":[[0,1.25,1793.7],[1,1.26,101.26],[2,1.27,71.5]],"ltp":1.25,"tv":10594.6,"id":2257317},{"batb":[[0,4.8,12.95],[1,4.7,2.02],[2,4.2,80.81]],"batl":[[0,5.4,2],[1,5.6,10.4],[2,5.8,2]],"ltp":5.2,"tv":4133.79,"id":10303696}]}]}
{"op":"mcm","clk":"1005542969","pt":1580643247290,"mc":[{"id":"1.168224294","rc":[{"batb":[[0,1.22,1086.06],[1,1.21,77.71],[2,1.05,378.87]],"batl":[[0,1.27,71.5],[1,1.32,47.61],[2,1.35,50.87]],"ltp":1.25,"tv":10594.6,"id":2257317},{"batb":[[0,4.7,2.02],[1,4.2,80.81],[2,4.1,2.04]],"batl":[[0,5.6,2],[1,5.8,2],[2,9.8,75.27]],"ltp":5.2,"tv":4133.79,"id":10303696}]}]}
{"op":"mcm","clk":"1005543339","pt":1580643249137,"mc":[{"id":"1.168224294","rc":[{"batb":[[1,1.21,888.34]],"batl":[[1,1.29,743.49],[2,1.3,500.71]],"ltp":1.25,"tv":10594.6,"id":2257317}]}]}
{"op":"mcm","clk":"1005543827","pt":1580643251820,"mc":[{"id":"1.168224294","rc":[{"batb":[[0,1.22,511.86],[1,1.21,77.71]],"batl":[[1,1.32,47.61],[2,1.35,50.87]],"ltp":1.25,"tv":10594.6,"id":2257317}]}]}
{"op":"mcm","clk":"1005544549","pt":1580643255334,"mc":[{"id":"1.168224294","rc":[{"batb":[[0,1.24,415.16],[1,1.23,722.86],[2,1.22,511.82]],"batl":[[0,1.26,344.56],[1,1.27,649.32],[2,1.32,47.61]],"ltp":1.25,"tv":10594.6,"id":2257317}]}]}
{"op":"mcm","clk":"1005544710","pt":1580643256135,"mc":[{"id":"1.168224294","rc":[{"batb":[[0,1.22,511.86],[1,1.21,77.71],[2,1.05,378.87]],"batl":[[0,1.27,71.5],[1,1.32,47.61],[2,1.35,50.87]],"ltp":1.25,"tv":10594.6,"id":2257317}]}]}
{"op":"mcm","clk":"1005544948","pt":1580643257315,"mc":[{"id":"1.168224294","rc":[{"batb":[[0,1.23,76.66],[1,1.22,511.82],[2,1.21,77.71]],"batl":[[0,1.26,68.25],[1,1.27,71.5],[2,1.32,47.61]],"ltp":1.25,"tv":10594.6,"id":2257317},{"batb":[[0,4.8,2.03],[1,4.7,2.02],[2,4.2,80.81]],"batl":[[0,5.4,2],[1,5.6,2],[2,5.8,2]],"ltp":5.2,"tv":4133.79,"id":10303696}]}]}
{"op":"mcm","clk":"1005545023","pt":1580643257638,"mc":[{"id":"1.168224294","rc":[{"batb":[[0,1.22,511.86],[1,1.21,77.71],[2,1.05,378.87]],"batl":[[0,1.27,71.5],[1,1.32,47.61],[2,1.35,50.87]],"ltp":1.25,"tv":10594.6,"id":2257317},{"batb":[[0,4.7,2.02],[1,4.2,80.81],[2,4.1,2.04]],"batl":[[0,5.6,2],[1,5.8,2],[2,9.8,75.27]],"ltp":5.2,"tv":4133.79,"id":10303696}]}]}
{"op":"mcm","clk":"1005545284","pt":1580643259031,"mc":[{"id":"1.168224294","rc":[{"batb":[[0,1.22,1086.06],[1,1.21,888.34]],"batl":[[1,1.29,743.49],[2,1.3,500.71]],"ltp":1.25,"tv":10594.6,"id":2257317}]}]}
{"op":"mcm","clk":"1005546219","pt":1580643264252,"mc":[{"id":"1.168224294","rc":[{"batb":[[0,1.23,72.66],[1,1.22,1086.02],[2,1.21,888.34]],"batl":[[0,1.26,62.75],[1,1.27,71.5],[2,1.29,743.49]],"ltp":1.25,"tv":10594.6,"id":2257317},{"batb":[[0,4.8,2.03],[1,4.7,2.02],[2,4.2,80.81]],"batl":[[0,5.4,2],[1,5.6,2],[2,5.8,2]],"ltp":5.2,"tv":4133.79,"id":10303696}]}]}
{"op":"mcm","clk":"1005546259","pt":1580643264414,"mc":[{"id":"1.168224294","rc":[{"batb":[[0,1.22,1086.06],[1,1.21,888.34],[2,1.05,378.87]],"batl":[[0,1.27,71.5],[1,1.29,743.49],[2,1.3,500.71]],"ltp":1.25,"tv":10594.6,"id":2257317},{"batb":[[0,4.7,2.02],[1,4.2,80.81],[2,4.1,2.04]],"batl":[[0,5.6,2],[1,5.8,2],[2,9.8,75.27]],"ltp":5.2,"tv":4133.79,"id":10303696}]}]}
{"op":"mcm","clk":"1005547032","pt":1580643268556,"mc":[{"id":"1.168224294","rc":[{"batb":[[0,1.22,511.86],[1,1.21,77.71]],"ltp":1.25,"tv":10594.6,"id":2257317}]}]}
{"op":"mcm","clk":"1005547558","pt":1580643271338,"mc":[{"id":"1.168224294","rc":[{"trd":[[1.26,6.63]],"batb":[[0,1.23,161.97],[1,1.22,511.82],[2,1.21,77.71]],"batl":[[1,1.29,1638.49]],"ltp":1.26,"tv":10601.23,"id":2257317},{"trd":[[4.8,5.8]],"batb":[[1,4.5,258.37],[2,4.2,80.81]],"batl":[[0,4.9,153.06],[1,5,598.8],[2,5.1,453.51]],"ltp":4.8,"tv":4139.59,"id":10303696}],"tv":14740.83}]}
{"op":"mcm","clk":"1005547711","pt":1580643272248,"mc":[{"id":"1.168224294","rc":[{"batb":[[0,1.26,785.75],[1,1.25,654.03],[2,1.24,378.24]],"batl":[[1,1.29,1680.5]],"ltp":1.26,"tv":10601.23,"id":2257317},{"batb":[[1,4.5,270.13]],"batl":[[1,5.1,453.51],[2,5.2,9.24]],"ltp":4.8,"tv":4139.59,"id":10303696}]}]}
{"op":"mcm","clk":"1005549004","pt":1580643278989,"mc":[{"id":"1.168224294","rc":[{"batb":[[2,1.24,460.01]],"batl":[[2,1.3,560.56]],"ltp":1.26,"tv":10601.23,"id":2257317},{"batb":[[2,4.3,2.01]],"batl":[[2,5.2,11.24]],"ltp":4.8,"tv":4139.59,"id":10303696}]}]}
{"op":"mcm","clk":"1005549457","pt":1580643281395,"mc":[{"id":"1.168224294","rc":[{"batb":[[1,4.5,264.58]],"ltp":4.8,"tv":4139.59,"id":10303696}]}]}
{"op":"mcm","clk":"1005550062","pt":1580643284380,"mc":[{"id":"1.168224294","rc":[{"batl":[[1,1.28,21.67],[2,1.29,1680.5]],"ltp":1.26,"tv":10601.23,"id":2257317},{"batl":[[0,4.8,4.29],[1,4.9,153.06],[2,5.1,453.51]],"ltp":4.8,"tv":4139.59,"id":10303696}]}]}
{"op":"mcm","clk":"1005551203","pt":1580643290301,"mc":[{"id":"1.168224294","rc":[{"batb":[[0,1.24,460.01],[1,1.23,81.65],[2,1.22,88.36]],"batl":[[0,1.29,42.01],[1,1.31,59.5],[2,1.33,55.5]],"ltp":1.26,"tv":10601.23,"id":2257317},{"batb":[[0,4.5,11.76],[1,4.2,2.02],[2,4,2.02]],"batl":[[0,5.2,11.24],[1,5.4,2],[2,5.6,2]],"ltp":4.8,"tv":4139.59,"id":10303696}]}]}
{"op":"mcm","clk":"1005551328","pt":1580643291007,"mc":[{"id":"1.168224294","rc":[{"batl":[[0,1.33,55.5],[1,1.96,398.24],[2,2.5,10.13]],"ltp":1.26,"tv":10601.23,"id":2257317},{"batb":[[0,4,2.02],[1,3.8,52.8],[2,3,380.95]],"batl":[[0,5.2,2]],"ltp":4.8,"tv":4139.59,"id":10303696}]}]}
{"op":"mcm","clk":"1005551615","pt":1580643292612,"mc":[{"id":"1.168224294","rc":[{"batb":[[0,1.24,931.49],[1,1.23,805.92]],"batl":[[0,1.33,581.12],[1,1.34,432.11],[2,1.96,398.24]],"ltp":1.26,"tv":10601.23,"id":2257317}]}]}
{"op":"mcm","clk":"1005553483","pt":1580643302231,"mc":[{"id":"1.168224294","rc":[{"batb":[[0,1.24,460.01],[1,1.23,81.65]],"batl":[[0,1.33,55.5],[1,1.96,398.24],[2,2.5,10.13]],"ltp":1.26,"tv":10601.23,"id":2257317}]}]}
{"op":"mcm","clk":"1005554027","pt":1580643305304,"mc":[{"id":"1.168224294","rc":[{"batb":[[0,1.31,14.58],[1,1.3,2151.32],[2,1.29,544.31]],"batl":[[0,1.33,2295.24],[1,1.34,1611.11],[2,1.96,398.24]],"ltp":1.26,"tv":10601.23,"id":2257317},{"batb":[[0,4,234.26]],"batl":[[0,4.5,264.43],[1,4.6,337],[2,5.2,2]],"ltp":4.8,"tv":4139.59,"id":10303696}]}]}
{"op":"mcm","clk":"1005554218","pt":1580643306204,"mc":[{"id":"1.168224294","rc":[{"batb":[[0,1.31,297.52]],"batl":[[0,1.33,2337.25]],"ltp":1.26,"tv":10601.23,"id":2257317},{"batb":[[0,4,247.7],[2,3.3,75.1]],"batl":[[2,4.7,10.92]],"ltp":4.8,"tv":4139.59,"id":10303696}]}]}
{"op":"mcm","clk":"1005555339","pt":1580643311823,"mc":[{"id":"1.168224294","rc":[{"trd":[[1.31,1685.5]],"batb":[[0,1.31,132.04]],"ltp":1.31,"tv":10766.71,"id":2257317},{"trd":[[4.3,50.41]],"ltp":4.3,"tv":4190.01,"id":10303696}],"tv":14956.72}]}
{"op":"mcm","clk":"1005555682","pt":1580643313631,"mc":[{"id":"1.168224294","rc":[{"trd":[[1.33,1725.68]],"batl":[[0,1.33,2337.22],[2,1.39,49.5]],"ltp":1.33,"tv":10766.77,"id":2257317},{"batb":[[2,3.55,2.39]],"ltp":4.3,"tv":4190.01,"id":10303696}],"tv":14956.78}]}
{"op":"mcm","clk":"1005557478","pt":1580643322348,"mc":[{"id":"1.168224294","rc":[{"batl":[[0,1.33,2259.36],[1,1.34,432.11]],"ltp":1.33,"tv":10766.77,"id":2257317},{"batb":[[0,4,13.44]],"batl":[[0,4.7,10.92],[1,5,2],[2,5.2,2]],"ltp":4.3,"tv":4190.01,"id":10303696}]}]}
{"op":"mcm","clk":"1005557646","pt":1580643323149,"mc":[{"id":"1.168224294","rc":[{"batb":[[0,1.27,334],[1,1.25,75.09],[2,1.24,81.79]],"batl":[[0,1.39,49.5],[1,1.42,46.75],[2,1.96,398.24]],"ltp":1.33,"tv":10766.77,"id":2257317},{"batb":[[0,3.55,2.39],[1,3.35,2.39],[2,3.3,74.98]],"batl":[[0,5,2],[1,5.2,2],[2,5.4,2]],"ltp":4.3,"tv":4190.01,"id":10303696}]}]}
{"op":"mcm","clk":"1005557705","pt":1580643323437,"mc":[{"id":"1.168224294","rc":[{"batl":[[0,1.42,46.75],[1,1.96,398.24],[2,2.5,10.13]],"ltp":1.33,"tv":10766.77,"id":2257317},{"batb":[[0,3.35,2.39],[1,3.3,74.98],[2,3,380.84]],"ltp":4.3,"tv":4190.01,"id":10303696}]}]}
{"op":"mcm","clk":"1005558270","pt":1580643326150,"mc":[{"id":"1.168224294","rc":[{"batb":[[0,1.26,340.85]],"ltp":1.33,"tv":10766.77,"id":2257317},{"batb":[[0,3.35,75.25],[1,3,380.84],[2,2.6,75.72]],"ltp":4.3,"tv":4190.01,"id":10303696}]}]}
{"op":"mcm","clk":"1005559008","pt":1580643329331,"mc":[{"id":"1.168224294","rc":[{"batb":[[0,1.32,11.14],[1,1.26,340.85],[2,1.25,75.09]],"batl":[[0,1.34,10.25],[1,1.42,46.75],[2,1.96,398.24]],"ltp":1.33,"tv":10766.77,"id":2257317},{"batb":[[0,3.9,9.86],[1,3.35,75.25],[2,3,380.84]],"batl":[[0,4.2,10.43],[1,5,2],[2,5.2,2]],"ltp":4.3,"tv":4190.01,"id":10303696}]}]}
{"op":"mcm","clk":"1005559223","pt":1580643330337,"mc":[{"id":"1.168224294","rc":[{"batb":[[0,1.26,340.85],[1,1.25,75.09],[2,1.24,81.79]],"batl":[[0,1.39,49.5]],"ltp":1.33,"tv":10766.77,"id":2257317},{"batb":[[0,3.55,2.39]],"batl":[[0,5,2],[1,5.2,2],[2,5.4,2]],"ltp":4.3,"tv":4190.01,"id":10303696}]}]}
{"op":"mcm","clk":"1005559381","pt":1580643331108,"mc":[{"id":"1.168224294","rc":[{"batl":[[0,1.42,46.75],[1,1.96,398.24],[2,2.5,10.13]],"ltp":1.33,"tv":10766.77,"id":2257317},{"batb":[[0,3.35,75.25],[1,3,380.84],[2,2.6,75.72]],"ltp":4.3,"tv":4190.01,"id":10303696}]}]}
{"op":"mcm","clk":"1005559541","pt":1580643331908,"mc":[{"id":"1.168224294","rc":[{"batb":[[0,1.26,1176.86],[1,1.25,737.77]],"batl":[[0,1.4,347.82],[1,1.41,342.53],[2,1.42,46.75]],"ltp":1.33,"tv":10766.77,"id":2257317}]}]}
{"op":"mcm","clk":"1005561692","pt":1580643342253,"mc":[{"id":"1.168224294","rc":[{"batl":[[0,1.42,46.75],[1,1.96,398.24],[2,2.5,10.13]],"ltp":1.33,"tv":10766.77,"id":2257317}]}]}
{"op":"mcm","clk":"1005562316","pt":1580643345242,"mc":[{"id":"1.168224294","rc":[{"trd":[[1.26,31.73],[1.27,16.96]],"batb":[[0,1.26,2950.02],[1,1.25,1379.87]],"batl":[[0,1.29,2127.77],[1,1.3,1415.25],[2,1.32,2065.98]],"ltp":1.26,"tv":10808.83,"id":2257317},{"trd":[[4.8,7.8]],"batb":[[0,4.5,6.46],[1,3.35,75.25],[2,3,380.84]],"batl":[[0,5,442.53]],"ltp":4.8,"tv":4192.01,"id":10303696}],"tv":15000.84}]}
{"op":"mcm","clk":"1005562533","pt":1580643346254,"mc":[{"id":"1.168224294","rc":[{"batb":[[2,1.24,627.26]],"batl":[[1,1.3,1457.26]],"ltp":1.26,"tv":10808.83,"id":2257317},{"batb":[[1,4.4,11.76],[2,4.3,80.96]],"batl":[[1,5.1,10.08],[2,5.2,2]],"ltp":4.8,"tv":4192.01,"id":10303696}]}]}
{"op":"mcm","clk":"1005563701","pt":1580643352179,"mc":[{"id":"1.168224294","rc":[{"batl":[[2,1.32,2124.59]],"ltp":1.26,"tv":10808.83,"id":2257317}]}]}
{"op":"mcm","clk":"1005563770","pt":1580643352447,"mc":[{"id":"1.168224294","rc":[{"batb":[[2,4.3,85.17]],"ltp":4.8,"tv":4192.01,"id":10303696}]}]}
{"op":"mcm","clk":"1005564059","pt":1580643353738,"mc":[{"id":"1.168224294","rc":[{"trd":[[1.29,0.11]],"batl":[[0,1.29,2127.74]],"ltp":1.29,"tv":10808.88,"id":2257317}],"tv":15000.89}]}
{"op":"mcm","clk":"1005564367","pt":1580643355463,"mc":[{"id":"1.168224294","rc":[{"batb":[[0,4.4,11.76],[1,4.3,85.17],[2,4.1,2.24]],"ltp":4.8,"tv":4192.01,"id":10303696}]}]}
{"op":"mcm","clk":"1005564927","pt":1580643358331,"mc":[{"id":"1.168224294","rc":[{"batl":[[0,1.28,22.57],[1,1.29,2127.74],[2,1.3,1457.26]],"ltp":1.29,"tv":10808.88,"id":2257317},{"batl":[[0,4.8,4.32],[1,5,442.53],[2,5.1,10.08]],"ltp":4.8,"tv":4192.01,"id":10303696}]}]}
{"op":"mcm","clk":"1005565330","pt":1580643360380,"mc":[{"id":"1.168224294","rc":[{"batb":[[0,1.24,627.26],[1,1.23,81.65],[2,1.22,88.36]],"batl":[[0,1.3,42.01],[1,1.32,58.61],[2,1.34,51.75]],"ltp":1.29,"tv":10808.88,"id":2257317},{"batb":[[1,4.3,4.21]],"batl":[[0,5.1,10.08],[1,5.2,2],[2,5.4,2]],"ltp":4.8,"tv":4192.01,"id":10303696}]}]}
{"op":"mcm","clk":"1005565457","pt":1580643361082,"mc":[{"id":"1.168224294","rc":[{"batb":[[0,1.24,459.22]],"batl":[[0,1.34,51.75],[1,1.42,46.75],[2,1.96,398.24]],"ltp":1.29,"tv":10808.88,"id":2257317},{"batb":[[0,4.3,4.21],[1,3.9,2.06],[2,3.85,52.8]],"batl":[[0,5.2,2],[1,5.4,2],[2,5.6,2]],"ltp":4.8,"tv":4192.01,"id":10303696}]}]}
{"op":"mcm","clk":"1005565707","pt":1580643362263,"mc":[{"id":"1.168224294","rc":[{"batl":[[0,1.33,45.5],[1,1.34,51.75],[2,1.42,46.75]],"ltp":1.29,"tv":10808.88,"id":2257317},{"batb":[[1,4,2.18],[2,3.9,2.06]],"ltp":4.8,"tv":4192.01,"id":10303696}]}]}
{"op":"mcm","clk":"1005565913","pt":1580643363265,"mc":[{"id":"1.168224294","rc":[{"batb":[[0,1.24,1307.52],[1,1.23,809.62]],"batl":[[1,1.34,658.91],[2,1.35,415.54]],"ltp":1.29,"tv":10808.88,"id":2257317},{"batb":[[2,3.9,54.78]],"ltp":4.8,"tv":4192.01,"id":10303696}]}]}
{"op":"mcm","clk":"1005566102","pt":1580643364294,"mc":[{"id":"1.168224294","rc":[{"batl":[[0,1.32,59.36],[1,1.33,45.5],[2,1.34,658.91]],"ltp":1.29,"tv":10808.88,"id":2257317},{"batb":[[1,4.1,2.04],[2,4,2.18]],"ltp":4.8,"tv":4192.01,"id":10303696}]}]}
{"op":"mcm","clk":"1005566158","pt":1580643364592,"mc":[{"id":"1.168224294","rc":[{"batl":[[0,1.33,45.5],[1,1.34,658.91],[2,1.35,415.54]],"ltp":1.29,"tv":10808.88,"id":2257317},{"batb":[[1,4,2.18],[2,3.9,54.78]],"ltp":4.8,"tv":4192.01,"id":10303696}]}]}
{"op":"mcm","clk":"1005566708","pt":1580643367306,"mc":[{"id":"1.168224294","rc":[{"batb":[[0,1.24,459.22],[1,1.23,81.65]],"batl":[[1,1.34,51.75],[2,1.42,46.75]],"ltp":1.29,"tv":10808.88,"id":2257317}]}]}
{"op":"mcm","clk":"1005567425","pt":1580643370302,"mc":[{"id":"1.168224294","rc":[{"batb":[[0,1.27,691.69],[1,1.26,628.55],[2,1.24,459.22]],"batl":[[0,1.3,448.72],[1,1.31,486.01],[2,1.33,45.5]],"ltp":1.29,"tv":10808.88,"id":2257317}]}]}
{"op":"mcm","clk":"1005567607","pt":1580643371295,"mc":[{"id":"1.168224294","rc":[{"batl":[[2,1.32,52.86]],"ltp":1.29,"tv":10808.88,"id":2257317},{"batb":[[1,4.1,2.14],[2,4,2.18]],"ltp":4.8,"tv":4192.01,"id":10303696}]}]}
{"op":"mcm","clk":"1005567741","pt":1580643371895,"mc":[{"id":"1.168224294","rc":[{"batb":[[0,1.24,459.22],[1,1.23,81.65],[2,1.22,88.36]],"batl":[[0,1.33,45.5],[1,1.34,51.75],[2,1.42,46.75]],"ltp":1.29,"tv":10808.88,"id":2257317},{"batb":[[1,4,2.18],[2,3.9,54.78]],"ltp":4.8,"tv":4192.01,"id":10303696}]}]}
{"op":"mcm","clk":"1005568419","pt":1580643375384,"mc":[{"id":"1.168224294","rc":[{"batb":[[0,1.24,1307.52],[1,1.23,809.62]],"batl":[[1,1.34,658.91],[2,1.35,415.54]],"ltp":1.29,"tv":10808.88,"id":2257317},{"batb":[[1,4.1,2.04],[2,4,2.18]],"ltp":4.8,"tv":4192.01,"id":10303696}]}]}
{"op":"mcm","clk":"1005568624","pt":1580643376301,"mc":[{"id":"1.168224294","rc":[{"batb":[[1,4,2.18],[2,3.9,54.78]],"ltp":4.8,"tv":4192.01,"id":10303696}]}]}
{"op":"mcm","clk":"1005568744","pt":1580643376906,"mc":[{"id":"1.168224294","rc":[{"batl":[[1,1.34,51.75],[2,1.42,46.75]],"ltp":1.29,"tv":10808.88,"id":2257317}]}]}
{"op":"mcm","clk":"1005569335","pt":1580643379989,"mc":[{"id":"1.168224294","rc":[{"batb":[[0,1.24,3144.54],[2,1.22,256.4]],"batl":[[0,1.26,1814.3],[1,1.27,524.91],[2,1.28,2851.65]],"ltp":1.29,"tv":10808.88,"id":2257317},{"batb":[[0,4.6,10.92],[1,4.3,4.21],[2,4,2.18]],"batl":[[1,5.3,520.2],[2,5.4,11.24]],"ltp":4.8,"tv":4192.01,"id":10303696}]}]}
{"op":"mcm","clk":"1005569539","pt":1580643381023,"mc":[{"id":"1.168224294","rc":[{"batb":[[1,1.23,1214.91]],"ltp":1.29,"tv":10808.88,"id":2257317},{"batb":[[0,4.6,80.48],[2,4.2,84.82]],"ltp":4.8,"tv":4192.01,"id":10303696}]}]}
{"op":"mcm","clk":"1005569807","pt":1580643382403,"mc":[{"id":"1.168224294","rc":[{"trd":[[1.24,1997.44]],"batb":[[0,1.24,2976.5]],"ltp":1.24,"tv":11144.97,"id":2257317}],"tv":15336.98}]}
{"op":"mcm","clk":"1005569845","pt":1580643382614,"mc":[{"id":"1.168224294","rc":[{"batl":[[0,5.3,520.2],[1,5.4,11.24],[2,5.6,2]],"ltp":4.8,"tv":4192.01,"id":10303696}]}]}
{"op":"mcm","clk":"1005570292","pt":1580643385005,"mc":[{"id":"1.168224294","rc":[{"trd":[[1.26,59.77]],"batl":[[0,1.26,1800.28]],"ltp":1.26,"tv":11173.0,"id":2257317}],"tv":15365.01}]}
{"op":"mcm","clk":"1005570842","pt":1580643387708,"mc":[{"id":"1.168224294","rc":[{"batl":[[1,1.27,584.41],[2,1.28,2922.99]],"ltp":1.26,"tv":11173.0,"id":2257317},{"batb":[[0,4.7,4.12],[1,4.6,80.48],[2,4.5,4.2]],"ltp":4.8,"tv":4192.01,"id":10303696}]}]}
{"op":"mcm","clk":"1005571391","pt":1580643390688,"mc":[{"id":"1.168224294","rc":[{"trd":[[1.26,59.82]],"batl":[[0,1.26,1800.25]],"ltp":1.26,"tv":11173.06,"id":2257317}],"tv":15365.07}]}
{"op":"mcm","clk":"1005572140","pt":1580643394402,"mc":[{"id":"1.168224294","rc":[{"batb":[[0,1.24,2954]],"batl":[[0,1.26,1771.66],[2,1.28,662.5]],"ltp":1.26,"tv":11173.06,"id":2257317},{"batl":[[0,5.4,11.24],[1,5.6,2],[2,5.8,2]],"ltp":4.8,"tv":4192.01,"id":10303696}]}]}
{"op":"mcm","clk":"1005572334","pt":1580643395204,"mc":[{"id":"1.168224294","rc":[{"batb":[[0,1.23,1058.19],[1,1.22,88.36],[2,1.21,77.71]],"batl":[[0,1.27,59.5],[1,1.28,71.34],[2,1.33,45.5]],"ltp":1.26,"tv":11173.06,"id":2257317},{"batb":[[1,4.5,4.2],[2,4.3,4.21]],"batl":[[0,5.4,2]],"ltp":4.8,"tv":4192.01,"id":10303696}]}]}
{"op":"mcm","clk":"1005572391","pt":1580643395419,"mc":[{"id":"1.168224294","rc":[{"batl":[[0,1.28,71.34],[1,1.33,45.5],[2,1.34,51.75]],"ltp":1.26,"tv":11173.06,"id":2257317},{"batb":[[0,4.5,4.2],[1,4.3,4.21],[2,4.2,84.82]],"ltp":4.8,"tv":4192.01,"id":10303696}]}]}
{"op":"mcm","clk":"1005572969","pt":1580643398142,"mc":[{"id":"1.168224294","rc":[{"batb":[[0,1.23,652.9],[1,1.22,1264.76]],"batl":[[1,1.3,525.23],[2,1.31,484.7]],"ltp":1.26,"tv":11173.06,"id":2257317},{"batb":[[1,4.3,87.69],[2,4,2.18]],"ltp":4.8,"tv":4192.01,"id":10303696}]}]}
{"op":"mcm","clk":"1005573749","pt":1580643402034,"mc":[{"id":"1.168224294","rc":[{"batl":[[0,1.27,68.5],[1,1.28,71.34],[2,1.3,525.23]],"ltp":1.26,"tv":11173.06,"id":2257317},{"batb":[[0,4.7,4.12],[1,4.5,4.2],[2,4.3,87.69]],"ltp":4.8,"tv":4192.01,"id":10303696}]}]}
{"op":"mcm","clk":"1005574537","pt":1580643406010,"mc":[{"id":"1.168224294","rc":[{"batl":[[0,1.27,68.67]],"ltp":1.26,"tv":11173.06,"id":2257317},{"batb":[[2,4.3,83.48]],"ltp":4.8,"tv":4192.01,"id":10303696}]}]}
{"op":"mcm","clk":"1005575454","pt":1580643410112,"mc":[{"id":"1.168224294","rc":[{"trd":[[1.24,1997.47]],"batl":[[0,1.28,71.49],[1,1.3,525.23],[2,1.31,484.7]],"ltp":1.24,"tv":11173.09,"id":2257317},{"batb":[[0,4.3,83.48],[1,4,2.18],[2,3.9,2.06]],"ltp":4.8,"tv":4192.01,"id":10303696}],"tv":15365.1}]}
{"op":"mcm","clk":"1005576091","pt":1580643413304,"mc":[{"id":"1.168224294","rc":[{"batb":[[0,4.5,4.2],[1,4.3,83.48],[2,4,2.18]],"ltp":4.8,"tv":4192.01,"id":10303696}]}]}
{"op":"mcm","clk":"1005576822","pt":1580643417231,"mc":[{"id":"1.168224294","rc":[{"batl":[[1,1.33,45.5],[2,1.34,51.75]],"ltp":1.24,"tv":11173.09,"id":2257317}]}]}
{"op":"mcm","clk":"1005576861","pt":1580643417454,"mc":[{"id":"1.168224294","rc":[{"trd":[[1.23,5.96]],"batb":[[0,1.23,646.97]],"ltp":1.23,"tv":11179.02,"id":2257317},{"trd":[[5.4,5.35]],"batl":[[0,5.6,2],[1,5.8,2],[2,8.6,81.89]],"ltp":5.4,"tv":4197.36,"id":10303696}],"tv":15376.38}]}
{"op":"mcm","clk":"1005577430","pt":1580643420328,"mc":[{"id":"1.168224294","rc":[{"batl":[[0,1.24,17.97],[1,1.25,306.16],[2,1.26,1729.42]],"ltp":1.23,"tv":11179.02,"id":2257317},{"batb":[[0,5,4.06],[1,4.9,43.25],[2,4.7,47.17]],"batl":[[0,5.5,405.55],[1,5.6,2],[2,5.8,2]],"ltp":5.4,"tv":4197.36,"id":10303696}]}]}
{"op":"mcm","clk":"1005577551","pt":1580643421028,"mc":[{"id":"1.168224294","rc":[{"trd":[[1.24,2017.11]],"batl":[[0,1.24,8.15]],"ltp":1.24,"tv":11198.66,"id":2257317},{"batb":[[1,4.9,104.54],[2,4.7,113.66]],"ltp":5.4,"tv":4197.36,"id":10303696}],"tv":15396.02}]}
{"op":"mcm","clk":"1005577761","pt":1580643422053,"mc":[{"id":"1.168224294","rc":[{"batb":[[2,1.21,245.75]],"batl":[[2,1.26,1771.43]],"ltp":1.24,"tv":11198.66,"id":2257317},{"batb":[[1,4.9,114.63]],"batl":[[2,5.8,10.4]],"ltp":5.4,"tv":4197.36,"id":10303696}]}]}
{"op":"mcm","clk":"1005578851","pt":1580643427183,"mc":[{"id":"1.168224294","rc":[{"trd":[[1.24,2032.23]],"batl":[[0,1.25,306.75],[1,1.26,1829.68],[2,1.27,1310.5]],"ltp":1.24,"tv":11213.78,"id":2257317},{"batb":[[2,4.8,4.58]],"ltp":5.4,"tv":4197.36,"id":10303696}],"tv":15411.14}]}
{"op":"mcm","clk":"1005579631","pt":1580643430992,"mc":[{"id":"1.168224294","rc":[{"batl":[[0,1.25,306.16]],"ltp":1.24,"tv":11213.78,"id":2257317},{"batl":[[0,5.5,398.29]],"ltp":5.4,"tv":4197.36,"id":10303696}]}]}
{"op":"mcm","clk":"1005580144","pt":1580643433608,"mc":[{"id":"1.168224294","rc":[{"batl":[[0,1.25,319.13]],"ltp":1.24,"tv":11213.78,"id":2257317},{"batl":[[0,5.3,4.58],[1,5.5,398.29],[2,5.6,2]],"ltp":5.4,"tv":4197.36,"id":10303696}]}]}
{"op":"mcm","clk":"1005580320","pt":1580643434518,"mc":[{"id":"1.168224294","rc":[{"trd":[[1.25,51.63]],"batl":[[0,1.25,318.82]],"ltp":1.25,"tv":11214.4,"id":2257317}],"tv":15411.76}]}
{"op":"mcm","clk":"1005580974","pt":1580643436995,"mc":[{"id":"1.168224294","rc":[{"batl":[[0,1.25,305.85]],"ltp":1.25,"tv":11214.4,"id":2257317},{"batl":[[0,5.5,398.29],[1,5.6,2],[2,5.8,10.4]],"ltp":5.4,"tv":4197.36,"id":10303696}]}]}
{"op":"mcm","clk":"1005581654","pt":1580643440307,"mc":[{"id":"1.168224294","rc":[{"batl":[[0,1.25,318.82],[2,1.27,64.5]],"ltp":1.25,"tv":11214.4,"id":2257317},{"batl":[[0,5.3,4.58],[1,5.5,185.29],[2,5.6,2]],"ltp":5.4,"tv":4197.36,"id":10303696}]}]}
{"op":"mcm","clk":"1005581847","pt":1580643441139,"mc":[{"id":"1.168224294","rc":[{"batb":[[0,1.22,479.7],[1,1.21,77.71],[2,1.2,452.07]],"batl":[[0,1.26,364.24],[1,1.27,64.5],[2,1.28,71.34]],"ltp":1.25,"tv":11214.4,"id":2257317},{"batb":[[0,4.8,4.58],[1,4.7,70.61],[2,4.5,4.2]],"batl":[[0,5.6,2],[1,5.8,2],[2,9.8,75.27]],"ltp":5.4,"tv":4197.36,"id":10303696}]}]}
{"op":"mcm","clk":"1005582438","pt":1580643444304,"mc":[{"id":"1.168224294","rc":[{"batb":[[0,1.23,77.63],[1,1.22,479.7],[2,1.21,883.03]],"batl":[[0,1.25,76.82],[1,1.26,364.24],[2,1.27,643.14]],"ltp":1.25,"tv":11214.4,"id":2257317},{"batb":[[0,5,4.63],[1,4.8,4.58],[2,4.7,70.61]],"ltp":5.4,"tv":4197.36,"id":10303696}]}]}
{"op":"mcm","clk":"1005582510","pt":1580643444618,"mc":[{"id":"1.168224294","rc":[{"batb":[[0,1.22,479.7],[1,1.21,883.03],[2,1.2,452.07]],"batl":[[0,1.26,364.24],[1,1.27,643.14],[2,1.28,71.34]],"ltp":1.25,"tv":11214.4,"id":2257317},{"batb":[[0,4.8,4.58],[1,4.7,70.61],[2,4.5,4.2]],"ltp":5.4,"tv":4197.36,"id":10303696}]}]}
{"op":"mcm","clk":"1005583181","pt":1580643448115,"mc":[{"id":"1.168224294","rc":[{"batl":[[0,1.25,2.18],[1,1.26,364.24],[2,1.27,643.14]],"ltp":1.25,"tv":11214.4,"id":2257317}]}]}
{"op":"mcm","clk":"1005583796","pt":1580643451313,"mc":[{"id":"1.168224294","rc":[{"batb":[[0,1.23,79.63],[1,1.22,88.36],[2,1.21,77.71]],"batl":[[0,1.25,78.72]],"ltp":1.25,"tv":11214.4,"id":2257317},{"batb":[[0,5,4.63],[1,4.8,4.58],[2,4.7,70.61]],"ltp":5.4,"tv":4197.36,"id":10303696}]}]}
{"op":"mcm","clk":"1005583839","pt":1580643451524,"mc":[{"id":"1.168224294","rc":[{"batb":[[0,1.22,88.36],[1,1.2,452.07],[2,1.05,378.72]],"batl":[[0,1.25,2.18]],"ltp":1.25,"tv":11214.4,"id":2257317},{"batb":[[0,4.8,4.58],[1,4.7,70.61],[2,4.5,4.2]],"batl":[[1,9.8,75.27],[2,1000,0.02]],"ltp":5.4,"tv":4197.36,"id":10303696}]}]}
{"op":"mcm","clk":"1005584434","pt":1580643454407,"mc":[{"id":"1.168224294","rc":[{"batb":[[0,1.24,456.26],[1,1.23,881.47],[2,1.22,242.94]],"batl":[[1,1.26,381.53],[2,1.27,1505.67]],"ltp":1.25,"tv":11214.4,"id":2257317},{"batl":[[0,5.1,5.62],[1,5.3,232.45],[2,5.4,359.59]],"ltp":5.4,"tv":4197.36,"id":10303696}]}]}
{"op":"mcm","clk":"1005584571","pt":1580643455098,"mc":[{"id":"1.168224294","rc":[{"batb":[[1,1.23,1271.18],[2,1.22,666.17]],"ltp":1.25,"tv":11214.4,"id":2257317},{"batb":[[2,4.6,70.5]],"batl":[[2,5.4,301]],"ltp":5.4,"tv":4197.36,"id":10303696}]}]}
{"op":"mcm","clk":"1005584760","pt":1580643456115,"mc":[{"id":"1.168224294","rc":[{"batl":[[1,1.26,423.54]],"ltp":1.25,"tv":11214.4,"id":2257317},{"batb":[[0,4.8,15.5]],"ltp":5.4,"tv":4197.36,"id":10303696}]}]}
{"op":"mcm","clk":"1005585162","pt":1580643458137,"mc":[{"id":"1.168224294","rc":[{"batl":[[1,1.26,406.25],[2,1.27,643.14]],"ltp":1.25,"tv":11214.4,"id":2257317},{"batl":[[0,5.6,10.4],[1,8.6,81.89],[2,1000,0.02]],"ltp":5.4,"tv":4197.36,"id":10303696}]}]}
{"op":"mcm","clk":"1005585388","pt":1580643459088,"mc":[{"id":"1.168224294","rc":[{"batb":[[0,1.23,470.43],[1,1.22,666.17],[2,1.05,378.83]],"batl":[[1,1.26,58.25],[2,1.27,447.73]],"ltp":1.25,"tv":11214.4,"id":2257317},{"batb":[[0,4.8,4.58],[1,4.7,4.12]],"batl":[[0,5.6,2]],"ltp":5.4,"tv":4197.36,"id":10303696}]}]}
{"op":"mcm","clk":"1005585535","pt":1580643459792,"mc":[{"id":"1.168224294","rc":[{"batb":[[0,1.23,312.87],[1,1.22,511.59]],"ltp":1.25,"tv":11214.4,"id":2257317}]}]}
{"op":"mcm","clk":"1005585815","pt":1580643461176,"mc":[{"id":"1.168224294","rc":[{"batb":[[0,1.23,387.5]],"ltp":1.25,"tv":11214.4,"id":2257317},{"batl":[[0,5.4,2],[1,5.6,2],[2,8.6,81.89]],"ltp":5.4,"tv":4197.36,"id":10303696}]}]}
{"op":"mcm","clk":"1005585868","pt":1580643461438,"mc":[{"id":"1.168224294","rc":[{"batb":[[1,1.22,1271.29]],"ltp":1.25,"tv":11214.4,"id":2257317}]}]}
{"op":"mcm","clk":"1005586478","pt":1580643464363,"mc":[{"id":"1.168224294","rc":[{"batb":[[0,1.24,61.79],[1,1.23,387.49],[2,1.22,1271.29]],"batl":[[0,1.25,71.72]],"ltp":1.25,"tv":11214.4,"id":2257317},{"batb":[[0,5,4.7],[1,4.8,4.58],[2,4.7,4.12]],"batl":[[0,5.2,2],[1,5.4,2],[2,5.6,2]],"ltp":5.4,"tv":4197.36,"id":10303696}]}]}
{"op":"mcm","clk":"1005586612","pt":1580643464948,"mc":[{"id":"1.168224294","rc":[{"batb":[[0,1.23,74.66],[1,1.22,511.59],[2,1.05,378.83]],"batl":[[0,1.25,2.18]],"ltp":1.25,"tv":11214.4,"id":2257317},{"batb":[[0,4.8,4.58],[1,4.7,4.12],[2,4.6,70.5]],"batl":[[0,5.4,2],[1,5.6,2],[2,8.6,81.89]],"ltp":5.4,"tv":4197.36,"id":10303696}]}]}
{"op":"mcm","clk":"1005586832","pt":1580643465971,"mc":[{"id":"1.168224294","rc":[{"batl":[[2,1000,0.02]],"ltp":5.4,"tv":4197.36,"id":10303696}]}]}
{"op":"mcm","clk":"1005587096","pt":1580643467371,"mc":[{"id":"1.168224294","rc":[{"trd":[[1.25,56],[1.26,83.16]],"batb":[[0,1.25,316.62],[1,1.24,852.82],[2,1.23,74.65]],"batl":[[0,1.26,46.58],[1,1.27,447.73],[2,1.28,1280.98]],"ltp":1.26,"tv":11242.11,"id":2257317},{"batl":[[0,5.1,255.02],[1,5.2,271],[2,5.4,2]],"ltp":5.4,"tv":4197.36,"id":10303696}],"tv":15439.47}]}
{"op":"mcm","clk":"1005587285","pt":1580643468375,"mc":[{"id":"1.168224294","rc":[{"batb":[[1,1.24,1227.58],[2,1.23,473.09]],"batl":[[1,1.27,489.74]],"ltp":1.26,"tv":11242.11,"id":2257317},{"batb":[[1,4.7,15.04]],"ltp":5.4,"tv":4197.36,"id":10303696}]}]}
{"op":"mcm","clk":"1005587754","pt":1580643470870,"mc":[{"id":"1.168224294","rc":[{"batl":[[1,1.27,425.24]],"ltp":1.26,"tv":11242.11,"id":2257317},{"batb":[[1,4.7,10.92]],"ltp":5.4,"tv":4197.36,"id":10303696}]}]}
{"op":"mcm","clk":"1005588416","pt":1580643474271,"mc":[{"id":"1.168224294","rc":[{"batb":[[0,1.24,243.56],[1,1.23,473.09],[2,1.22,417.67]],"batl":[[0,1.27,111.51],[1,1.28,568],[2,1.33,45.5]],"ltp":1.26,"tv":11242.11,"id":2257317},{"batb":[[0,4.7,15.24],[1,4.5,79.58],[2,4,2.18]],"batl":[[0,5.2,2],[1,5.4,2],[2,5.5,9.24]],"ltp":5.4,"tv":4197.36,"id":10303696}]}]}
{"op":"mcm","clk":"1005588606","pt":1580643475178,"mc":[{"id":"1.168224294","rc":[{"batb":[[0,1.23,473.11],[1,1.22,88.36],[2,1.05,378.83]],"batl":[[0,1.27,69.5]],"ltp":1.26,"tv":11242.11,"id":2257317},{"batb":[[0,4.7,4.32]],"batl":[[0,5.4,2],[1,5.6,2],[2,7.8,87.91]],"ltp":5.4,"tv":4197.36,"id":10303696}]}]}
{"op":"mcm","clk":"1005589024","pt":1580643477260,"mc":[{"id":"1.168224294","rc":[{"batb":[[0,1.23,1428.48],[1,1.22,721.29]],"batl":[[2,1.29,526.68]],"ltp":1.26,"tv":11242.11,"id":2257317}]}]}
{"op":"mcm","clk":"1005589866","pt":1580643481266,"mc":[{"id":"1.168224294","rc":[{"batb":[[0,1.24,62.54],[1,1.23,1428.46],[2,1.22,721.29]],"ltp":1.26,"tv":11242.11,"id":2257317},{"batl":[[0,5.2,2],[1,5.4,2],[2,5.6,2]],"ltp":5.4,"tv":4197.36,"id":10303696}]}]}
{"op":"mcm","clk":"1005589979","pt":1580643481868,"mc":[{"id":"1.168224294","rc":[{"batb":[[0,1.23,1428.48],[1,1.22,721.29],[2,1.05,378.83]],"batl":[[1,1.33,45.5],[2,1.34,51.75]],"ltp":1.26,"tv":11242.11,"id":2257317},{"batb":[[1,4.5,75.38]],"batl":[[0,5.4,2],[1,5.6,2],[2,7.8,87.91]],"ltp":5.4,"tv":4197.36,"id":10303696}]}]}
{"op":"mcm","clk":"1005590229","pt":1580643483057,"mc":[{"id":"1.168224294","rc":[{"batl":[[2,1000,0.02]],"ltp":5.4,"tv":4197.36,"id":10303696}]}]}
{"op":"mcm","clk":"1005590496","pt":1580643484301,"mc":[{"id":"1.168224294","rc":[{"batl":[[0,1.25,6119.11],[1,1.26,66.25],[2,1.27,3984.34]],"ltp":1.26,"tv":11242.11,"id":2257317},{"batb":[[0,4.8,4.28],[1,4.7,4.32],[2,4.6,452.76]],"batl":[[0,5.3,4.87],[1,5.4,2],[2,5.5,561.65]],"ltp":5.4,"tv":4197.36,"id":10303696}]}]}
{"op":"mcm","clk":"1005590582","pt":1580643484700,"mc":[{"id":"1.168224294","rc":[{"batl":[[0,1.25,12.71],[1,1.26,579.95],[2,1.27,3140.23]],"ltp":1.26,"tv":11242.11,"id":2257317},{"batb":[[2,4.6,45.28]],"ltp":5.4,"tv":4197.36,"id":10303696}]}]}
{"op":"mcm","clk":"1005590953","pt":1580643486342,"mc":[{"id":"1.168224294","rc":[{"batb":[[2,1.21,601.59]],"batl":[[1,1.26,621.96]],"ltp":1.26,"tv":11242.11,"id":2257317},{"batb":[[0,4.9,10.08],[1,4.8,68.64],[2,4.7,4.32]],"ltp":5.4,"tv":4197.36,"id":10303696}]}]}
{"op":"mcm","clk":"1005592018","pt":1580643491329,"mc":[{"id":"1.168224294","rc":[{"batb":[[0,1.23,473.11]],"batl":[[0,1.26,108.26],[1,1.27,643.7],[2,1.33,45.5]],"ltp":1.26,"tv":11242.11,"id":2257317},{"batl":[[0,5.4,2],[1,5.6,2],[2,5.7,8.4]],"ltp":5.4,"tv":4197.36,"id":10303696}]}]}
{"op":"mcm","clk":"1005592124","pt":1580643491754,"mc":[{"id":"1.168224294","rc":[{"batb":[[0,1.22,721.32],[1,1.21,601.59],[2,1.05,378.82]],"ltp":1.26,"tv":11242.11,"id":2257317},{"batb":[[1,4.8,4.28]],"batl":[[0,5.6,2],[1,5.7,8.4],[2,8.6,81.89]],"ltp":5.4,"tv":4197.36,"id":10303696}]}]}
{"op":"mcm","clk":"1005592453","pt":1580643493230,"mc":[{"id":"1.168224294","rc":[{"batb":[[1,1.21,433.55]],"batl":[[0,1.26,66.25]],"ltp":1.26,"tv":11242.11,"id":2257317},{"batb":[[0,4.8,4.28],[1,4.7,4.32],[2,4.6,69]],"batl":[[1,8.6,81.89],[2,1000,0.02]],"ltp":5.4,"tv":4197.36,"id":10303696}]}]}
{"op":"mcm","clk":"1005592632","pt":1580643494046,"mc":[{"id":"1.168224294","rc":[{"batb":[[0,1.22,885.61],[1,1.21,1239.07]],"batl":[[2,1.28,548.51]],"ltp":1.26,"tv":11242.11,"id":2257317}]}]}
{"op":"mcm","clk":"1005593027","pt":1580643495957,"mc":[{"id":"1.168224294","rc":[{"batb":[[1,1.21,433.55]],"batl":[[2,1.33,45.5]],"ltp":1.26,"tv":11242.11,"id":2257317}]}]}
{"op":"mcm","clk":"1005594127","pt":1580643500837,"mc":[{"id":"1.168224294","rc":[{"batb":[[1,1.21,1239.07]],"batl":[[2,1.28,548.51]],"ltp":1.26,"tv":11242.11,"id":2257317}]}]}
{"op":"mcm","clk":"1005595144","pt":1580643505353,"mc":[{"id":"1.168224294","rc":[{"batb":[[0,1.23,78.66],[1,1.22,885.58],[2,1.21,1239.07]],"ltp":1.26,"tv":11242.11,"id":2257317},{"batl":[[0,5.4,2],[1,5.6,2],[2,8.6,81.89]],"ltp":5.4,"tv":4197.36,"id":10303696}]}]}
{"op":"mcm","clk":"1005595212","pt":1580643505663,"mc":[{"id":"1.168224294","rc":[{"batb":[[0,1.22,885.61],[1,1.21,1239.07],[2,1.05,378.82]],"ltp":1.26,"tv":11242.11,"id":2257317},{"batl":[[0,5.6,2],[1,8.6,81.89],[2,1000,0.02]],"ltp":5.4,"tv":4197.36,"id":10303696}]}]}
{"op":"mcm","clk":"1005595998","pt":1580643509045,"mc":[{"id":"1.168224294","rc":[{"batb":[[1,1.21,433.55]],"batl":[[1,1.33,45.5],[2,1.34,51.75]],"ltp":1.26,"tv":11242.11,"id":2257317},{"batb":[[1,4.6,69],[2,4,2.18]],"ltp":5.4,"tv":4197.36,"id":10303696}]}]}
{"op":"mcm","clk":"1005596225","pt":1580643510255,"mc":[{"id":"1.168224294","rc":[{"batl":[[1,1000,0.02],[2,1000,0]],"ltp":5.4,"tv":4197.36,"id":10303696}]}]}
{"op":"mcm","clk":"1005596484","pt":1580643511350,"mc":[{"id":"1.168224294","rc":[{"trd":[[1.23,6],[1.24,2032.27]],"batb":[[0,1.22,885.58],[1,1.21,1156.57]],"batl":[[0,1.23,25.97],[1,1.24,739.55],[2,1.25,3699.72]],"ltp":1.23,"tv":11242.18,"id":2257317},{"batb":[[0,5.1,40.06],[1,5,39],[2,4.8,4.28]],"batl":[[1,5.7,5.26],[2,5.8,246]],"ltp":5.4,"tv":4197.36,"id":10303696}],"tv":15439.54}]}
{"op":"mcm","clk":"1005596691","pt":1580643512365,"mc":[{"id":"1.168224294","rc":[{"batb":[[1,1.21,1962.09],[2,1.2,168.14]],"batl":[[2,1.25,840.92]],"ltp":1.23,"tv":11242.18,"id":2257317},{"batb":[[0,5.1,96.79],[1,5,53.13],[2,4.8,66.99]],"ltp":5.4,"tv":4197.36,"id":10303696}]}]}
{"op":"mcm","clk":"1005597498","pt":1580643516197,"mc":[{"id":"1.168224294","rc":[{"batb":[[0,1.21,429.3],[1,1.2,168.14],[2,1.19,484.29]],"batl":[[0,1.25,90.59],[1,1.26,661.82],[2,1.33,45.5]],"ltp":1.23,"tv":11242.18,"id":2257317},{"batb":[[0,5,14.13],[1,4.8,66.99],[2,4,2.18]],"batl":[[0,5.9,8.4],[1,9.8,75.27],[2,1000,0.02]],"ltp":5.4,"tv":4197.36,"id":10303696}]}]}
{"op":"mcm","clk":"1005597730","pt":1580643517177,"mc":[{"id":"1.168224294","rc":[{"batb":[[1,1.19,484.39],[2,1.05,378.72]],"batl":[[0,1.25,48.58]],"ltp":1.23,"tv":11242.18,"id":2257317},{"batb":[[0,5,4.05]],"batl":[[0,9.8,75.27],[1,1000,0.02],[2,1000,0]],"ltp":5.4,"tv":4197.36,"id":10303696}]}]}
{"op":"mcm","clk":"1005598140","pt":1580643519002,"mc":[{"id":"1.168224294","rc":[{"batb":[[0,1.21,515.99],[1,1.2,956.36],[2,1.19,484.29]],"batl":[[1,1.26,724.9],[2,1.27,571.07]],"ltp":1.23,"tv":11242.18,"id":2257317},{"batl":[[0,5.8,2],[1,6,2],[2,9.8,75.27]],"ltp":5.4,"tv":4197.36,"id":10303696}]}]}
{"op":"mcm","clk":"1005598920","pt":1580643522593,"mc":[{"id":"1.168224294","rc":[{"batb":[[1,1.2,101.87]],"batl":[[1,1.26,66.25],[2,1.33,45.5]],"ltp":1.23,"tv":11242.18,"id":2257317}]}]}
{"op":"mcm","clk":"1005599385","pt":1580643524689,"mc":[{"id":"1.168224294","rc":[{"batl":[[0,1.26,66.25],[1,1.33,45.5],[2,1.34,51.75]],"ltp":1.23,"tv":11242.18,"id":2257317},{"batb":[[0,4.8,66.99],[1,4,2.18],[2,3.9,2.06]],"ltp":5.4,"tv":4197.36,"id":10303696}]}]}
{"op":"mcm","clk":"1005599875","pt":1580643526718,"mc":[{"id":"1.168224294","rc":[{"batb":[[1,1.2,956.36]],"batl":[[0,1.26,724.9],[1,1.27,571.07],[2,1.33,45.5]],"ltp":1.23,"tv":11242.18,"id":2257317}]}]}
{"op":"mcm","clk":"1005600874","pt":1580643531320,"mc":[{"id":"1.168224294","rc":[{"batl":[[0,1.25,68.82],[1,1.26,724.9],[2,1.27,571.07]],"ltp":1.23,"tv":11242.18,"id":2257317},{"batb":[[0,5,3.84],[1,4.8,66.99],[2,4,2.18]],"ltp":5.4,"tv":4197.36,"id":10303696}]}]}
{"op":"mcm","clk":"1005600915","pt":1580643531495,"mc":[{"id":"1.168224294","rc":[{"batl":[[0,1.26,724.9],[1,1.27,571.07],[2,1.33,45.5]],"ltp":1.23,"tv":11242.18,"id":2257317},{"batb":[[0,4.8,66.99],[1,4,2.18],[2,3.9,2.06]],"ltp":5.4,"tv":4197.36,"id":10303696}]}]}
{"op":"mcm","clk":"1005601753","pt":1580643535202,"mc":[{"id":"1.168224294","rc":[{"batl":[[0,1.26,66.25],[1,1.33,45.5],[2,1.34,51.75]],"ltp":1.23,"tv":11242.18,"id":2257317}]}]}
{"op":"mcm","clk":"1005602184","pt":1580643537294,"mc":[{"id":"1.168224294","rc":[{"trd":[[1.21,54.42],[1.22,0.04]],"batb":[[0,1.21,488.77],[2,1.19,1345.34]],"batl":[[0,1.23,1625.36],[1,1.24,9425.59],[2,1.26,66.25]],"ltp":1.21,"tv":11296.63,"id":2257317},{"batb":[[0,5.4,367.39],[1,4.8,66.99],[2,4,2.18]],"batl":[[2,6.2,244]],"ltp":5.4,"tv":4197.36,"id":10303696}],"tv":15493.99}]}
{"op":"mcm","clk":"1005602405","pt":1580643538402,"mc":[{"id":"1.168224294","rc":[{"batb":[[2,1.19,1513.38]],"batl":[[0,1.23,2150.41],[1,1.24,2374.78]],"ltp":1.21,"tv":11296.63,"id":2257317},{"batb":[[0,5.5,47.92],[1,5.4,36.74],[2,5.2,9.24]],"batl":[[2,6.2,251.56]],"ltp":5.4,"tv":4197.36,"id":10303696}]}]}
{"op":"mcm","clk":"1005603656","pt":1580643544406,"mc":[{"id":"1.168224294","rc":[{"batb":[[0,1.21,86.69],[1,1.2,101.87],[2,1.19,652.33]],"batl":[[0,1.24,548.35],[1,1.26,66.25],[2,1.33,45.5]],"ltp":1.21,"tv":11296.63,"id":2257317},{"batl":[[2,6.2,7.56]],"ltp":5.4,"tv":4197.36,"id":10303696}]}]}
{"op":"mcm","clk":"1005603798","pt":1580643545118,"mc":[{"id":"1.168224294","rc":[{"batb":[[0,1.17,568.5],[1,1.05,378.72],[2,1.03,388.36]],"batl":[[0,1.24,336.06]],"ltp":1.21,"tv":11296.63,"id":2257317},{"batb":[[0,5.1,59.86],[1,4.8,4.28],[2,4,2.18]],"batl":[[0,11.5,70.11],[1,1000,0.02],[2,6.2,0]],"ltp":5.4,"tv":4197.36,"id":10303696}]}]}
{"op":"mcm","clk":"1005604106","pt":1580643546651,"mc":[{"id":"1.168224294","rc":[{"batb":[[0,1.19,88.81],[1,1.17,568.4],[2,1.05,378.72]],"batl":[[1,1.25,79.9],[2,1.26,66.25]],"ltp":1.21,"tv":11296.63,"id":2257317},{"batb":[[1,5,3.77],[2,4.8,4.28]],"batl":[[0,6.4,2],[1,11.5,70.11],[2,1000,0.02]],"ltp":5.4,"tv":4197.36,"id":10303696}]}]}
{"op":"mcm","clk":"1005604463","pt":1580643548205,"mc":[{"id":"1.168224294","rc":[{"batb":[[0,1.19,676.93],[1,1.18,973.37],[2,1.17,568.4]],"batl":[[1,1.25,715.75]],"ltp":1.21,"tv":11296.63,"id":2257317}]}]}
{"op":"mcm","clk":"1005604666","pt":1580643549228,"mc":[{"id":"1.168224294","rc":[{"batb":[[1,1.17,568.4],[2,1.05,378.72]],"batl":[[1,1.25,79.9]],"ltp":1.21,"tv":11296.63,"id":2257317}]}]}
{"op":"mcm","clk":"1005605358","pt":1580643552213,"mc":[{"id":"1.168224294","rc":[{"batb":[[0,1.2,951.83],[1,1.19,765.36],[2,1.17,568.4]],"batl":[[0,1.23,827.51],[1,1.24,654.21],[2,1.25,79.9]],"ltp":1.21,"tv":11296.63,"id":2257317},{"batb":[[0,5.1,56.02]],"ltp":5.4,"tv":4197.36,"id":10303696}]}]}
{"op":"mcm","clk":"1005605563","pt":1580643553140,"mc":[{"id":"1.168224294","rc":[{"batb":[[0,1.19,676.93],[1,1.17,568.4],[2,1.05,378.72]],"batl":[[0,1.24,315],[1,1.25,79.9],[2,1.26,66.25]],"ltp":1.21,"tv":11296.63,"id":2257317}]}]}
{"op":"mcm","clk":"1005606013","pt":1580643555379,"mc":[{"id":"1.168224294","rc":[{"batb":[[1,1.18,973.2],[2,1.17,568.4]],"batl":[[1,1.25,715.9]],"ltp":1.21,"tv":11296.63,"id":2257317}]}]}
{"op":"mcm","clk":"1005606454","pt":1580643557295,"mc":[{"id":"1.168224294","rc":[{"batl":[[0,1.25,79.9],[1,1.26,66.25],[2,1.33,45.5]],"ltp":1.21,"tv":11296.63,"id":2257317}]}]}
{"op":"mcm","clk":"1005606518","pt":1580643557616,"mc":[{"id":"1.168224294","rc":[{"batl":[[0,1.26,66.25],[1,1.96,398.24],[2,2.5,10.13]],"ltp":1.21,"tv":11296.63,"id":2257317},{"batb":[[1,4.8,4.28],[2,3,456.68]],"ltp":5.4,"tv":4197.36,"id":10303696}]}]}
{"op":"mcm","clk":"1005607063","pt":1580643560325,"mc":[{"id":"1.168224294","rc":[{"trd":[[1.2,0.2]],"batb":[[0,1.19,676.83],[1,1.18,1005.77],[2,1.17,1527.4]],"batl":[[0,1.2,17.69],[1,1.21,545.53],[2,1.22,4902.07]],"ltp":1.2,"tv":11296.83,"id":2257317},{"batb":[[0,6,3.56],[1,5.6,38.75],[2,5.3,3.78]],"batl":[[1,6.8,281]],"ltp":5.4,"tv":4197.36,"id":10303696}],"tv":15494.19}]}
{"op":"mcm","clk":"1005607178","pt":1580643560932,"mc":[{"id":"1.168224294","rc":[{"trd":[[1.19,20.27]],"batb":[[0,1.19,666.69]],"ltp":1.19,"tv":11317.1,"id":2257317},{"batb":[[0,6,79.72],[1,5.7,43.28],[2,5.6,38.75]],"ltp":5.4,"tv":4197.36,"id":10303696}],"tv":15514.47}]}
{"op":"mcm","clk":"1005607411","pt":1580643562207,"mc":[{"id":"1.168224294","rc":[{"batb":[[2,1.17,1695.44]],"batl":[[1,1.21,587.54]],"ltp":1.19,"tv":11317.1,"id":2257317},{"batb":[[1,5.7,51.68]],"batl":[[1,6.8,287.72]],"ltp":5.4,"tv":4197.36,"id":10303696}]}]}
{"op":"mcm","clk":"1005607643","pt":1580643563328,"mc":[{"id":"1.168224294","rc":[{"batl":[[2,14,62.58]],"ltp":5.4,"tv":4197.36,"id":10303696}]}]}
{"op":"mcm","clk":"1005609008","pt":1580643570148,"mc":[{"id":"1.168224294","rc":[{"batb":[[1,1.18,973.2]],"batl":[[0,1.21,587.54],[1,1.22,4902.07],[2,1.23,216.07]],"ltp":1.19,"tv":11317.1,"id":2257317},{"batb":[[0,6,76.16]],"ltp":5.4,"tv":4197.36,"id":10303696}]}]}
{"op":"mcm","clk":"1005609625","pt":1580643573138,"mc":[{"id":"1.168224294","rc":[{"batb":[[1,1.18,1005.87]],"batl":[[0,1.2,17.74],[1,1.21,587.54],[2,1.22,4902.07]],"ltp":1.19,"tv":11317.1,"id":2257317},{"batb":[[0,6,79.71]],"ltp":5.4,"tv":4197.36,"id":10303696}]}]}
{"op":"mcm","clk":"1005611875","pt":1580643584074,"mc":[{"id":"1.168224294","rc":[{"trd":[[1.19,393.6]],"batb":[[0,1.19,293.36]],"ltp":1.19,"tv":11690.43,"id":2257317},{"trd":[[6.4,73.42]],"batl":[[0,6.8,287.72],[1,14,62.58],[2,1000,0.02]],"ltp":6.4,"tv":4270.77,"id":10303696}],"tv":15961.21}]}
{"op":"mcm","clk":"1005612600","pt":1580643587485,"mc":[{"id":"1.168224294","rc":[{"batb":[[0,1.19,421.47]],"batl":[[1,1.21,748.21]],"ltp":1.19,"tv":11690.43,"id":2257317}]}]}
{"op":"mcm","clk":"1005618559","pt":1580643616831,"mc":[{"id":"1.168224294","rc":[{"trd":[[6,4.54]],"batb":[[0,6,77.44]],"ltp":6.0,"tv":4275.32,"id":10303696}],"tv":15965.75}]}
{"op":"mcm","clk":"1005618761","pt":1580643617844,"mc":[{"id":"1.168224294","rc":[{"batb":[[2,1.17,1694.65]],"ltp":1.19,"tv":11690.43,"id":2257317}]}]}
