{"op":"mcm","clk":"978249338","pt":1580359851794,"mc":[{"id":"1.168081835","marketDefinition":{"bspMarket":false,"turnInPlayEnabled":true,"persistenceEnabled":true,"marketBaseRate":5.0,"eventId":"29676917","eventTypeId":"2","numberOfWinners":0,"bettingType":"ASIAN_HANDICAP_DOUBLE_LINE","marketType":"HANDICAP","marketTime":"2020-02-02T05:00:00.000Z","suspendTime":"2020-02-02T05:00:00.000Z","bspReconciled":false,"complete":true,"inPlay":false,"crossMatching":false,"runnersVoidable":false,"numberOfActiveRunners":48,"betDelay":0,"status":"OPEN","runners":[{"status":"ACTIVE","sortPriority":1,"id":22229228,"hc":-11.5,"name":"Ram/Salisbury"},{"status":"ACTIVE","sortPriority":2,"id":15256065,"hc":11.5,"name":"Purcell/Saville"},{"status":"ACTIVE","sortPriority":3,"id":22229228,"hc":-10.5,"name":"Ram/Salisbury"},{"status":"ACTIVE","sortPriority":4,"id":15256065,"hc":10.5,"name":"Purcell/Saville"},{"status":"ACTIVE","sortPriority":5,"id":22229228,"hc":-9.5,"name":"Ram/Salisbury"},{"status":"ACTIVE","sortPriority":6,"id":15256065,"hc":9.5,"name":"Purcell/Saville"},{"status":"ACTIVE","sortPriority":7,"id":22229228,"hc":-8.5,"name":"Ram/Salisbury"},{"status":"ACTIVE","sortPriority":8,"id":15256065,"hc":8.5,"name":"Purcell/Saville"},{"status":"ACTIVE","sortPriority":9,"id":22229228,"hc":-7.5,"name":"Ram/Salisbury"},{"status":"ACTIVE","sortPriority":10,"id":15256065,"hc":7.5,"name":"Purcell/Saville"},{"status":"ACTIVE","sortPriority":11,"id":22229228,"hc":-6.5,"name":"Ram/Salisbury"},{"status":"ACTIVE","sortPriority":12,"id":15256065,"hc":6.5,"name":"Purcell/Saville"},{"status":"ACTIVE","sortPriority":13,"id":22229228,"hc":-5.5,"name":"Ram/Salisbury"},{"status":"ACTIVE","sortPriority":14,"id":15256065,"hc":5.5,"name":"Purcell/Saville"},{"status":"ACTIVE","sortPriority":15,"id":22229228,"hc":-4.5,"name":"Ram/Salisbury"},{"status":"ACTIVE","sortPriority":16,"id":15256065,"hc":4.5,"name":"Purcell/Saville"},{"status":"ACTIVE","sortPriority":17,"id":22229228,"hc":-3.5,"name":"Ram/Salisbury"},{"status":"ACTIVE","sortPriority":18,"id":15256065,"hc":3.5,"name":"Purcell/Saville"},{"status":"ACTIVE","sortPriority":19,"id":22229228,"hc":-2.5,"name":"Ram/Salisbury"},{"status":"ACTIVE","sortPriority":20,"id":15256065,"hc":2.5,"name":"Purcell/Saville"},{"status":"ACTIVE","sortPriority":21,"id":22229228,"hc":-1.5,"name":"Ram/Salisbury"},{"status":"ACTIVE","sortPriority":22,"id":15256065,"hc":1.5,"name":"Purcell/Saville"},{"status":"ACTIVE","sortPriority":23,"id":22229228,"hc":-0.5,"name":"Ram/Salisbury"},{"status":"ACTIVE","sortPriority":24,"id":15256065,"hc":0.5,"name":"Purcell/Saville"},{"status":"ACTIVE","sortPriority":25,"id":22229228,"hc":0.5,"name":"Ram/Salisbury"},{"status":"ACTIVE","sortPriority":26,"id":15256065,"hc":-0.5,"name":"Purcell/Saville"},{"status":"ACTIVE","sortPriority":27,"id":22229228,"hc":1.5,"name":"Ram/Salisbury"},{"status":"ACTIVE","sortPriority":28,"id":15256065,"hc":-1.5,"name":"Purcell/Saville"},{"status":"ACTIVE","sortPriority":29,"id":22229228,"hc":2.5,"name":"Ram/Salisbury"},{"status":"ACTIVE","sortPriority":30,"id":15256065,"hc":-2.5,"name":"Purcell/Saville"},{"status":"ACTIVE","sortPriority":31,"id":22229228,"hc":3.5,"name":"Ram/Salisbury"},{"status":"ACTIVE","sortPriority":32,"id":15256065,"hc":-3.5,"name":"Purcell/Saville"},{"status":"ACTIVE","sortPriority":33,"id":22229228,"hc":4.5,"name":"Ram/Salisbury"},{"status":"ACTIVE","sortPriority":34,"id":15256065,"hc":-4.5,"name":"Purcell/Saville"},{"status":"ACTIVE","sortPriority":35,"id":22229228,"hc":5.5,"name":"Ram/Salisbury"},{"status":"ACTIVE","sortPriority":36,"id":15256065,"hc":-5.5,"name":"Purcell/Saville"},{"status":"ACTIVE","sortPriority":37,"id":22229228,"hc":6.5,"name":"Ram/Salisbury"},{"status":"ACTIVE","sortPriority":38,"id":15256065,"hc":-6.5,"name":"Purcell/Saville"},{"status":"ACTIVE","sortPriority":39,"id":22229228,"hc":7.5,"name":"Ram/Salisbury"},{"status":"ACTIVE","sortPriority":40,"id":15256065,"hc":-7.5,"name":"Purcell/Saville"},{"status":"ACTIVE","sortPriority":41,"id":22229228,"hc":8.5,"name":"Ram/Salisbury"},{"status":"ACTIVE","sortPriority":42,"id":15256065,"hc":-8.5,"name":"Purcell/Saville"},{"status":"ACTIVE","sortPriority":43,"id":22229228,"hc":9.5,"name":"Ram/Salisbury"},{"status":"ACTIVE","sortPriority":44,"id":15256065,"hc":-9.5,"name":"Purcell/Saville"},{"status":"ACTIVE","sortPriority":45,"id":22229228,"hc":10.5,"name":"Ram/Salisbury"},{"status":"ACTIVE","sortPriority":46,"id":15256065,"hc":-10.5,"name":"Purcell/Saville"},{"status":"ACTIVE","sortPriority":47,"id":22229228,"hc":11.5,"name":"Ram/Salisbury"},{"status":"ACTIVE","sortPriority":48,"id":15256065,"hc":-11.5,"name":"Purcell/Saville"}],"regulators":["MR_INT"],"countryCode":"AU","discountAllowed":false,"timezone":"GMT","openDate":"2020-02-02T05:00:00.000Z","version":3141663929,"name":"Handicap","eventName":"Ram/Salisbury v Purcell/Saville"}}]}
{"op":"mcm","clk":"978249383","pt":1580359853794,"mc":[{"id":"1.168081835","marketDefinition":{"bspMarket":false,"turnInPlayEnabled":true,"persistenceEnabled":true,"marketBaseRate":5.0,"eventId":"29676917","eventTypeId":"2","numberOfWinners":0,"bettingType":"ASIAN_HANDICAP_DOUBLE_LINE","marketType":"HANDICAP","marketTime":"2020-02-02T05:00:00.000Z","suspendTime":"2020-02-02T05:00:00.000Z","bspReconciled":false,"complete":true,"inPlay":false,"crossMatching":false,"runnersVoidable":false,"numberOfActiveRunners":48,"betDelay":0,"status":"OPEN","runners":[{"status":"ACTIVE","sortPriority":1,"id":22229228,"hc":-11.5,"name":"Ram/Salisbury"},{"status":"ACTIVE","sortPriority":2,"id":15256065,"hc":11.5,"name":"Purcell/Saville"},{"status":"ACTIVE","sortPriority":3,"id":22229228,"hc":-10.5,"name":"Ram/Salisbury"},{"status":"ACTIVE","sortPriority":4,"id":15256065,"hc":10.5,"name":"Purcell/Saville"},{"status":"ACTIVE","sortPriority":5,"id":22229228,"hc":-9.5,"name":"Ram/Salisbury"},{"status":"ACTIVE","sortPriority":6,"id":15256065,"hc":9.5,"name":"Purcell/Saville"},{"status":"ACTIVE","sortPriority":7,"id":22229228,"hc":-8.5,"name":"Ram/Salisbury"},{"status":"ACTIVE","sortPriority":8,"id":15256065,"hc":8.5,"name":"Purcell/Saville"},{"status":"ACTIVE","sortPriority":9,"id":22229228,"hc":-7.5,"name":"Ram/Salisbury"},{"status":"ACTIVE","sortPriority":10,"id":15256065,"hc":7.5,"name":"Purcell/Saville"},{"status":"ACTIVE","sortPriority":11,"id":22229228,"hc":-6.5,"name":"Ram/Salisbury"},{"status":"ACTIVE","sortPriority":12,"id":15256065,"hc":6.5,"name":"Purcell/Saville"},{"status":"ACTIVE","sortPriority":13,"id":22229228,"hc":-5.5,"name":"Ram/Salisbury"},{"status":"ACTIVE","sortPriority":14,"id":15256065,"hc":5.5,"name":"Purcell/Saville"},{"status":"ACTIVE","sortPriority":15,"id":22229228,"hc":-4.5,"name":"Ram/Salisbury"},{"status":"ACTIVE","sortPriority":16,"id":15256065,"hc":4.5,"name":"Purcell/Saville"},{"status":"ACTIVE","sortPriority":17,"id":22229228,"hc":-3.5,"name":"Ram/Salisbury"},{"status":"ACTIVE","sortPriority":18,"id":15256065,"hc":3.5,"name":"Purcell/Saville"},{"status":"ACTIVE","sortPriority":19,"id":22229228,"hc":-2.5,"name":"Ram/Salisbury"},{"status":"ACTIVE","sortPriority":20,"id":15256065,"hc":2.5,"name":"Purcell/Saville"},{"status":"ACTIVE","sortPriority":21,"id":22229228,"hc":-1.5,"name":"Ram/Salisbury"},{"status":"ACTIVE","sortPriority":22,"id":15256065,"hc":1.5,"name":"Purcell/Saville"},{"status":"ACTIVE","sortPriority":23,"id":22229228,"hc":-0.5,"name":"Ram/Salisbury"},{"status":"ACTIVE","sortPriority":24,"id":15256065,"hc":0.5,"name":"Purcell/Saville"},{"status":"ACTIVE","sortPriority":25,"id":22229228,"hc":0.5,"name":"Ram/Salisbury"},{"status":"ACTIVE","sortPriority":26,"id":15256065,"hc":-0.5,"name":"Purcell/Saville"},{"status":"ACTIVE","sortPriority":27,"id":22229228,"hc":1.5,"name":"Ram/Salisbury"},{"status":"ACTIVE","sortPriority":28,"id":15256065,"hc":-1.5,"name":"Purcell/Saville"},{"status":"ACTIVE","sortPriority":29,"id":22229228,"hc":2.5,"name":"Ram/Salisbury"},{"status":"ACTIVE","sortPriority":30,"id":15256065,"hc":-2.5,"name":"Purcell/Saville"},{"status":"ACTIVE","sortPriority":31,"id":22229228,"hc":3.5,"name":"Ram/Salisbury"},{"status":"ACTIVE","sortPriority":32,"id":15256065,"hc":-3.5,"name":"Purcell/Saville"},{"status":"ACTIVE","sortPriority":33,"id":22229228,"hc":4.5,"name":"Ram/Salisbury"},{"status":"ACTIVE","sortPriority":34,"id":15256065,"hc":-4.5,"name":"Purcell/Saville"},{"status":"ACTIVE","sortPriority":35,"id":22229228,"hc":5.5,"name":"Ram/Salisbury"},{"status":"ACTIVE","sortPriority":36,"id":15256065,"hc":-5.5,"name":"Purcell/Saville"},{"status":"ACTIVE","sortPriority":37,"id":22229228,"hc":6.5,"name":"Ram/Salisbury"},{"status":"ACTIVE","sortPriority":38,"id":15256065,"hc":-6.5,"name":"Purcell/Saville"},{"status":"ACTIVE","sortPriority":39,"id":22229228,"hc":7.5,"name":"Ram/Salisbury"},{"status":"ACTIVE","sortPriority":40,"id":15256065,"hc":-7.5,"name":"Purcell/Saville"},{"status":"ACTIVE","sortPriority":41,"id":22229228,"hc":8.5,"name":"Ram/Salisbury"},{"status":"ACTIVE","sortPriority":42,"id":15256065,"hc":-8.5,"name":"Purcell/Saville"},{"status":"ACTIVE","sortPriority":43,"id":22229228,"hc":9.5,"name":"Ram/Salisbury"},{"status":"ACTIVE","sortPriority":44,"id":15256065,"hc":-9.5,"name":"Purcell/Saville"},{"status":"ACTIVE","sortPriority":45,"id":22229228,"hc":10.5,"name":"Ram/Salisbury"},{"status":"ACTIVE","sortPriority":46,"id":15256065,"hc":-10.5,"name":"Purcell/Saville"},{"status":"ACTIVE","sortPriority":47,"id":22229228,"hc":11.5,"name":"Ram/Salisbury"},{"status":"ACTIVE","sortPriority":48,"id":15256065,"hc":-11.5,"name":"Purcell/Saville"}],"regulators":["MR_INT"],"countryCode":"AU","discountAllowed":true,"timezone":"GMT","openDate":"2020-02-02T05:00:00.000Z","version":3141663929,"name":"Handicap","eventName":"Ram/Salisbury v Purcell/Saville"}}]}
{"op":"mcm","clk":"997608128","pt":1580581829319,"mc":[{"id":"1.168081835","marketDefinition":{"bspMarket":false,"turnInPlayEnabled":true,"persistenceEnabled":true,"marketBaseRate":5.0,"eventId":"29676917","eventTypeId":"2","numberOfWinners":0,"bettingType":"ASIAN_HANDICAP_DOUBLE_LINE","marketType":"HANDICAP","marketTime":"2020-02-02T05:00:00.000Z","suspendTime":"2020-02-02T05:00:00.000Z","bspReconciled":false,"complete":true,"inPlay":false,"crossMatching":false,"runnersVoidable":false,"numberOfActiveRunners":48,"betDelay":0,"status":"OPEN","runners":[{"status":"ACTIVE","sortPriority":1,"id":22229228,"hc":-11.5,"name":"Ram/Salisbury"},{"status":"ACTIVE","sortPriority":2,"id":15256065,"hc":11.5,"name":"Purcell/Saville"},{"status":"ACTIVE","sortPriority":3,"id":22229228,"hc":-10.5,"name":"Ram/Salisbury"},{"status":"ACTIVE","sortPriority":4,"id":15256065,"hc":10.5,"name":"Purcell/Saville"},{"status":"ACTIVE","sortPriority":5,"id":22229228,"hc":-9.5,"name":"Ram/Salisbury"},{"status":"ACTIVE","sortPriority":6,"id":15256065,"hc":9.5,"name":"Purcell/Saville"},{"status":"ACTIVE","sortPriority":7,"id":22229228,"hc":-8.5,"name":"Ram/Salisbury"},{"status":"ACTIVE","sortPriority":8,"id":15256065,"hc":8.5,"name":"Purcell/Saville"},{"status":"ACTIVE","sortPriority":9,"id":22229228,"hc":-7.5,"name":"Ram/Salisbury"},{"status":"ACTIVE","sortPriority":10,"id":15256065,"hc":7.5,"name":"Purcell/Saville"},{"status":"ACTIVE","sortPriority":11,"id":22229228,"hc":-6.5,"name":"Ram/Salisbury"},{"status":"ACTIVE","sortPriority":12,"id":15256065,"hc":6.5,"name":"Purcell/Saville"},{"status":"ACTIVE","sortPriority":13,"id":22229228,"hc":-5.5,"name":"Ram/Salisbury"},{"status":"ACTIVE","sortPriority":14,"id":15256065,"hc":5.5,"name":"Purcell/Saville"},{"status":"ACTIVE","sortPriority":15,"id":22229228,"hc":-4.5,"name":"Ram/Salisbury"},{"status":"ACTIVE","sortPriority":16,"id":15256065,"hc":4.5,"name":"Purcell/Saville"},{"status":"ACTIVE","sortPriority":17,"id":22229228,"hc":-3.5,"name":"Ram/Salisbury"},{"status":"ACTIVE","sortPriority":18,"id":15256065,"hc":3.5,"name":"Purcell/Saville"},{"status":"ACTIVE","sortPriority":19,"id":22229228,"hc":-2.5,"name":"Ram/Salisbury"},{"status":"ACTIVE","sortPriority":20,"id":15256065,"hc":2.5,"name":"Purcell/Saville"},{"status":"ACTIVE","sortPriority":21,"id":22229228,"hc":-1.5,"name":"Ram/Salisbury"},{"status":"ACTIVE","sortPriority":22,"id":15256065,"hc":1.5,"name":"Purcell/Saville"},{"status":"ACTIVE","sortPriority":23,"id":22229228,"hc":-0.5,"name":"Ram/Salisbury"},{"status":"ACTIVE","sortPriority":24,"id":15256065,"hc":0.5,"name":"Purcell/Saville"},{"status":"ACTIVE","sortPriority":25,"id":22229228,"hc":0.5,"name":"Ram/Salisbury"},{"status":"ACTIVE","sortPriority":26,"id":15256065,"hc":-0.5,"name":"Purcell/Saville"},{"status":"ACTIVE","sortPriority":27,"id":22229228,"hc":1.5,"name":"Ram/Salisbury"},{"status":"ACTIVE","sortPriority":28,"id":15256065,"hc":-1.5,"name":"Purcell/Saville"},{"status":"ACTIVE","sortPriority":29,"id":22229228,"hc":2.5,"name":"Ram/Salisbury"},{"status":"ACTIVE","sortPriority":30,"id":15256065,"hc":-2.5,"name":"Purcell/Saville"},{"status":"ACTIVE","sortPriority":31,"id":22229228,"hc":3.5,"name":"Ram/Salisbury"},{"status":"ACTIVE","sortPriority":32,"id":15256065,"hc":-3.5,"name":"Purcell/Saville"},{"status":"ACTIVE","sortPriority":33,"id":22229228,"hc":4.5,"name":"Ram/Salisbury"},{"status":"ACTIVE","sortPriority":34,"id":15256065,"hc":-4.5,"name":"Purcell/Saville"},{"status":"ACTIVE","sortPriority":35,"id":22229228,"hc":5.5,"name":"Ram/Salisbury"},{"status":"ACTIVE","sortPriority":36,"id":15256065,"hc":-5.5,"name":"Purcell/Saville"},{"status":"ACTIVE","sortPriority":37,"id":22229228,"hc":6.5,"name":"Ram/Salisbury"},{"status":"ACTIVE","sortPriority":38,"id":15256065,"hc":-6.5,"name":"Purcell/Saville"},{"status":"ACTIVE","sortPriority":39,"id":22229228,"hc":7.5,"name":"Ram/Salisbury"},{"status":"ACTIVE","sortPriority":40,"id":15256065,"hc":-7.5,"name":"Purcell/Saville"},{"status":"ACTIVE","sortPriority":41,"id":22229228,"hc":8.5,"name":"Ram/Salisbury"},{"status":"ACTIVE","sortPriority":42,"id":15256065,"hc":-8.5,"name":"Purcell/Saville"},{"status":"ACTIVE","sortPriority":43,"id":22229228,"hc":9.5,"name":"Ram/Salisbury"},{"status":"ACTIVE","sortPriority":44,"id":15256065,"hc":-9.5,"name":"Purcell/Saville"},{"status":"ACTIVE","sortPriority":45,"id":22229228,"hc":10.5,"name":"Ram/Salisbury"},{"status":"ACTIVE","sortPriority":46,"id":15256065,"hc":-10.5,"name":"Purcell/Saville"},{"status":"ACTIVE","sortPriority":47,"id":22229228,"hc":11.5,"name":"Ram/Salisbury"},{"status":"ACTIVE","sortPriority":48,"id":15256065,"hc":-11.5,"name":"Purcell/Saville"}],"regulators":["MR_INT"],"countryCode":"AU","discountAllowed":true,"timezone":"GMT","openDate":"2020-02-02T05:00:00.000Z","version":3141663929,"name":"Handicap","eventName":"Ram/Salisbury v Purcell/Saville"},"rc":[{"batb":[[0,1.02,4.99]],"ltp":0.0,"tv":0.0,"id":22229228,"hc":-9.5},{"batb":[[0,1.02,4.99]],"ltp":0.0,"tv":0.0,"id":22229228,"hc":-10.5},{"batb":[[0,1.02,4.99]],"ltp":0.0,"tv":0.0,"id":22229228,"hc":-11.5}]}]}
{"op":"mcm","clk":"997622038","pt":1580581911693,"mc":[{"id":"1.168081835","rc":[{"batb":[[0,1.02,8.92]],"ltp":0.0,"tv":0.0,"id":22229228,"hc":-11.5}]}]}
{"op":"mcm","clk":"997622745","pt":1580581915691,"mc":[{"id":"1.168081835","rc":[{"batl":[[0,1000,2.36]],"ltp":0.0,"tv":0.0,"id":22229228,"hc":-11.5}]}]}
{"op":"mcm","clk":"997622842","pt":1580581916277,"mc":[{"id":"1.168081835","rc":[{"batl":[[0,990,0.01]],"ltp":0.0,"tv":0.0,"id":22229228,"hc":-11.5}]}]}
{"op":"mcm","clk":"997624435","pt":1580581925767,"mc":[{"id":"1.168081835","rc":[{"batl":[[0,990,0.01]],"ltp":0.0,"tv":0.0,"id":22229228,"hc":-11.5}]}]}
{"op":"mcm","clk":"997626468","pt":1580581936685,"mc":[{"id":"1.168081835","rc":[{"batl":[[0,1000,0.02]],"ltp":0.0,"tv":0.0,"id":22229228,"hc":-11.5}]}]}
{"op":"mcm","clk":"997626539","pt":1580581937072,"mc":[{"id":"1.168081835","rc":[{"trd":[[1.02,0.02]],"batb":[[0,1.02,8.91]],"batl":[[0,990,0.01]],"ltp":1.02,"tv":0.01,"id":22229228,"hc":-11.5}],"tv":0.01}]}
{"op":"mcm","clk":"997630727","pt":1580581961159,"mc":[{"id":"1.168081835","rc":[{"batb":[[0,1.02,8.92]],"ltp":0.0,"tv":0.0,"id":22229228,"hc":-10.5}]}]}
{"op":"mcm","clk":"997631717","pt":1580581966681,"mc":[{"id":"1.168081835","rc":[{"batl":[[0,990,0.01]],"ltp":0.0,"tv":0.0,"id":22229228,"hc":-10.5}]}]}
{"op":"mcm","clk":"997633384","pt":1580581975803,"mc":[{"id":"1.168081835","rc":[{"batl":[[0,990,0.01]],"ltp":0.0,"tv":0.0,"id":22229228,"hc":-10.5}]}]}
{"op":"mcm","clk":"997633632","pt":1580581976965,"mc":[{"id":"1.168081835","rc":[{"batb":[[0,1.02,8.92]],"ltp":0.0,"tv":0.0,"id":22229228,"hc":-9.5}]}]}
{"op":"mcm","clk":"997634459","pt":1580581981390,"mc":[{"id":"1.168081835","rc":[{"batl":[[0,990,0.01]],"ltp":0.0,"tv":0.0,"id":22229228,"hc":-9.5}]}]}
{"op":"mcm","clk":"997635796","pt":1580581988632,"mc":[{"id":"1.168081835","rc":[{"batl":[[0,1000,2.37]],"ltp":0.0,"tv":0.0,"id":22229228,"hc":-10.5}]}]}
{"op":"mcm","clk":"997635963","pt":1580581989602,"mc":[{"id":"1.168081835","rc":[{"batl":[[0,990,0.01]],"ltp":0.0,"tv":0.0,"id":22229228,"hc":-9.5}]}]}
{"op":"mcm","clk":"997636048","pt":1580581990023,"mc":[{"id":"1.168081835","rc":[{"trd":[[1.02,0.02]],"batb":[[0,1.02,8.91]],"batl":[[0,990,0.01]],"ltp":1.02,"tv":0.01,"id":22229228,"hc":-10.5}],"tv":0.03}]}
{"op":"mcm","clk":"997638129","pt":1580582002522,"mc":[{"id":"1.168081835","rc":[{"batl":[[0,1000,0.02]],"ltp":0.0,"tv":0.0,"id":22229228,"hc":-9.5}]}]}
{"op":"mcm","clk":"997638183","pt":1580582002846,"mc":[{"id":"1.168081835","rc":[{"trd":[[1.02,0.02]],"batb":[[0,1.02,8.91]],"batl":[[0,990,0.01]],"ltp":1.02,"tv":0.01,"id":22229228,"hc":-9.5}],"tv":0.04}]}
{"op":"mcm","clk":"997639259","pt":1580582009663,"mc":[{"id":"1.168081835","rc":[{"batl":[[0,1000,2.37]],"ltp":1.02,"tv":0.01,"id":22229228,"hc":-11.5}]}]}
{"op":"mcm","clk":"997639370","pt":1580582010249,"mc":[{"id":"1.168081835","rc":[{"trd":[[1.02,0.03]],"batb":[[0,1.02,8.9]],"batl":[[0,990,0.01]],"ltp":1.02,"tv":0.03,"id":22229228,"hc":-11.5}],"tv":0.06}]}
{"op":"mcm","clk":"997642099","pt":1580582026669,"mc":[{"id":"1.168081835","rc":[{"batl":[[0,1000,2.37]],"ltp":1.02,"tv":0.03,"id":22229228,"hc":-11.5}]}]}
{"op":"mcm","clk":"997642225","pt":1580582027368,"mc":[{"id":"1.168081835","rc":[{"trd":[[1.02,0.05]],"batb":[[0,1.02,8.89]],"batl":[[0,990,0.01]],"ltp":1.02,"tv":0.04,"id":22229228,"hc":-11.5}],"tv":0.07}]}
{"op":"mcm","clk":"997643093","pt":1580582032556,"mc":[{"id":"1.168081835","rc":[{"batl":[[0,1000,0.02]],"ltp":1.02,"tv":0.01,"id":22229228,"hc":-9.5}]}]}
{"op":"mcm","clk":"997643154","pt":1580582032973,"mc":[{"id":"1.168081835","rc":[{"trd":[[1.02,0.03]],"batb":[[0,1.02,8.9]],"batl":[[0,990,0.01]],"ltp":1.02,"tv":0.03,"id":22229228,"hc":-9.5}],"tv":0.09}]}
{"op":"mcm","clk":"997644896","pt":1580582043704,"mc":[{"id":"1.168081835","rc":[{"trd":[[1.02,0.06]],"batb":[[0,1.02,8.88]],"ltp":1.02,"tv":0.06,"id":22229228,"hc":-11.5}],"tv":0.1}]}
{"op":"mcm","clk":"997645933","pt":1580582049606,"mc":[{"id":"1.168081835","rc":[{"batl":[[0,1000,0.02]],"ltp":1.02,"tv":0.03,"id":22229228,"hc":-9.5}]}]}
{"op":"mcm","clk":"997646065","pt":1580582050346,"mc":[{"id":"1.168081835","rc":[{"trd":[[1.02,0.05]],"batb":[[0,1.02,8.89]],"batl":[[0,990,0.01]],"ltp":1.02,"tv":0.04,"id":22229228,"hc":-9.5},{"trd":[[1.02,0.03]],"batb":[[0,1.02,8.9]],"ltp":1.02,"tv":0.03,"id":22229228,"hc":-10.5}],"tv":0.13}]}
{"op":"mcm","clk":"997647599","pt":1580582059560,"mc":[{"id":"1.168081835","rc":[{"trd":[[1.02,0.08]],"batb":[[0,1.02,8.87]],"ltp":1.02,"tv":0.07,"id":22229228,"hc":-11.5}],"tv":0.15}]}
{"op":"mcm","clk":"997648781","pt":1580582066492,"mc":[{"id":"1.168081835","rc":[{"batl":[[0,1000,0.02]],"ltp":1.02,"tv":0.04,"id":22229228,"hc":-9.5}]}]}
{"op":"mcm","clk":"997648938","pt":1580582067395,"mc":[{"id":"1.168081835","rc":[{"trd":[[1.02,0.06]],"batb":[[0,1.02,8.88]],"batl":[[0,990,0.01]],"ltp":1.02,"tv":0.06,"id":22229228,"hc":-9.5},{"trd":[[1.02,0.05]],"batb":[[0,1.02,8.89]],"ltp":1.02,"tv":0.04,"id":22229228,"hc":-10.5}],"tv":0.18}]}
{"op":"mcm","clk":"997650339","pt":1580582075700,"mc":[{"id":"1.168081835","rc":[{"trd":[[1.02,0.09]],"batb":[[0,1.02,8.86]],"ltp":1.02,"tv":0.09,"id":22229228,"hc":-11.5}],"tv":0.2}]}
{"op":"mcm","clk":"997651626","pt":1580582083530,"mc":[{"id":"1.168081835","rc":[{"batl":[[0,1000,0.02]],"ltp":1.02,"tv":0.06,"id":22229228,"hc":-9.5},{"batl":[[0,1000,2.37]],"ltp":1.02,"tv":0.04,"id":22229228,"hc":-10.5}]}]}
{"op":"mcm","clk":"997651763","pt":1580582084329,"mc":[{"id":"1.168081835","rc":[{"trd":[[1.02,0.08]],"batb":[[0,1.02,8.87]],"batl":[[0,990,0.01]],"ltp":1.02,"tv":0.07,"id":22229228,"hc":-9.5},{"trd":[[1.02,0.06]],"batb":[[0,1.02,8.88]],"batl":[[0,990,0.01]],"ltp":1.02,"tv":0.06,"id":22229228,"hc":-10.5}],"tv":0.23}]}
{"op":"mcm","clk":"997652927","pt":1580582091516,"mc":[{"id":"1.168081835","rc":[{"batl":[[0,1000,0.02]],"ltp":1.02,"tv":0.09,"id":22229228,"hc":-11.5}]}]}
{"op":"mcm","clk":"997653080","pt":1580582092482,"mc":[{"id":"1.168081835","rc":[{"trd":[[1.02,0.11]],"batb":[[0,1.02,8.85]],"batl":[[0,990,0.01]],"ltp":1.02,"tv":0.1,"id":22229228,"hc":-11.5}],"tv":0.24}]}
{"op":"mcm","clk":"997654297","pt":1580582100570,"mc":[{"id":"1.168081835","rc":[{"batl":[[0,1000,0.02]],"ltp":1.02,"tv":0.07,"id":22229228,"hc":-9.5},{"batl":[[0,1000,2.37]],"ltp":1.02,"tv":0.06,"id":22229228,"hc":-10.5}]}]}
{"op":"mcm","clk":"997654404","pt":1580582101177,"mc":[{"id":"1.168081835","rc":[{"trd":[[1.02,0.09]],"batb":[[0,1.02,8.86]],"batl":[[0,990,0.01]],"ltp":1.02,"tv":0.09,"id":22229228,"hc":-9.5},{"trd":[[1.02,0.08]],"batb":[[0,1.02,8.87]],"batl":[[0,990,0.01]],"ltp":1.02,"tv":0.07,"id":22229228,"hc":-10.5}],"tv":0.27}]}
{"op":"mcm","clk":"997655526","pt":1580582108482,"mc":[{"id":"1.168081835","rc":[{"trd":[[1.02,0.12]],"batb":[[0,1.02,8.84]],"ltp":1.02,"tv":0.12,"id":22229228,"hc":-11.5}],"tv":0.29}]}
{"op":"mcm","clk":"997657038","pt":1580582117683,"mc":[{"id":"1.168081835","rc":[{"batl":[[0,1000,2.37]],"ltp":1.02,"tv":0.07,"id":22229228,"hc":-10.5}]}]}
{"op":"mcm","clk":"997657129","pt":1580582118267,"mc":[{"id":"1.168081835","rc":[{"trd":[[1.02,0.11]],"batb":[[0,1.02,8.85]],"ltp":1.02,"tv":0.1,"id":22229228,"hc":-9.5},{"trd":[[1.02,0.09]],"batb":[[0,1.02,8.86]],"batl":[[0,990,0.01]],"ltp":1.02,"tv":0.09,"id":22229228,"hc":-10.5}],"tv":0.32}]}
{"op":"mcm","clk":"997658077","pt":1580582124512,"mc":[{"id":"1.168081835","rc":[{"batl":[[0,1000,2.37]],"ltp":1.02,"tv":0.12,"id":22229228,"hc":-11.5}]}]}
{"op":"mcm","clk":"997658245","pt":1580582125600,"mc":[{"id":"1.168081835","rc":[{"trd":[[1.02,0.14]],"batb":[[0,1.02,8.83]],"batl":[[0,990,0.01]],"ltp":1.02,"tv":0.13,"id":22229228,"hc":-11.5}],"tv":0.34}]}
{"op":"mcm","clk":"997659494","pt":1580582133362,"mc":[{"id":"1.168081835","rc":[{"batl":[[0,1000,0.02]],"ltp":1.02,"tv":0.1,"id":22229228,"hc":-9.5}]}]}
{"op":"mcm","clk":"997659579","pt":1580582133856,"mc":[{"id":"1.168081835","rc":[{"trd":[[1.02,0.12]],"batb":[[0,1.02,8.84]],"batl":[[0,990,0.01]],"ltp":1.02,"tv":0.12,"id":22229228,"hc":-9.5}],"tv":0.35}]}
{"op":"mcm","clk":"997659860","pt":1580582135592,"mc":[{"id":"1.168081835","rc":[{"trd":[[1.02,0.11]],"batb":[[0,1.02,8.85]],"ltp":1.02,"tv":0.1,"id":22229228,"hc":-10.5}],"tv":0.37}]}
{"op":"mcm","clk":"997660849","pt":1580582141758,"mc":[{"id":"1.168081835","rc":[{"trd":[[1.02,0.16]],"batb":[[0,1.02,8.82]],"ltp":1.02,"tv":0.15,"id":22229228,"hc":-11.5}],"tv":0.38}]}
{"op":"mcm","clk":"997662205","pt":1580582149782,"mc":[{"id":"1.168081835","rc":[{"trd":[[1.02,0.14]],"batb":[[0,1.02,8.83]],"ltp":1.02,"tv":0.13,"id":22229228,"hc":-9.5}],"tv":0.4}]}
{"op":"mcm","clk":"997662436","pt":1580582151172,"mc":[{"id":"1.168081835","rc":[{"batl":[[0,1000,0.02]],"ltp":1.02,"tv":0.1,"id":22229228,"hc":-10.5}]}]}
{"op":"mcm","clk":"997662544","pt":1580582151815,"mc":[{"id":"1.168081835","rc":[{"trd":[[1.02,0.12]],"batb":[[0,1.02,8.84]],"batl":[[0,990,0.01]],"ltp":1.02,"tv":0.12,"id":22229228,"hc":-10.5}],"tv":0.41}]}
{"op":"mcm","clk":"997663698","pt":1580582158570,"mc":[{"id":"1.168081835","rc":[{"trd":[[1.02,0.17]],"batb":[[0,1.02,8.81]],"ltp":1.02,"tv":0.17,"id":22229228,"hc":-11.5}],"tv":0.43}]}
{"op":"mcm","clk":"997664885","pt":1580582165582,"mc":[{"id":"1.168081835","rc":[{"batl":[[0,1000,0.02]],"ltp":1.02,"tv":0.13,"id":22229228,"hc":-9.5}]}]}
{"op":"mcm","clk":"997664932","pt":1580582165888,"mc":[{"id":"1.168081835","rc":[{"trd":[[1.02,0.16]],"batb":[[0,1.02,8.82]],"batl":[[0,990,0.01]],"ltp":1.02,"tv":0.15,"id":22229228,"hc":-9.5}],"tv":0.44}]}
{"op":"mcm","clk":"997665201","pt":1580582167558,"mc":[{"id":"1.168081835","rc":[{"batl":[[0,1000,0.02]],"ltp":1.02,"tv":0.12,"id":22229228,"hc":-10.5}]}]}
{"op":"mcm","clk":"997665271","pt":1580582167936,"mc":[{"id":"1.168081835","rc":[{"trd":[[1.02,0.14]],"batb":[[0,1.02,8.83]],"batl":[[0,990,0.01]],"ltp":1.02,"tv":0.13,"id":22229228,"hc":-10.5}],"tv":0.46}]}
{"op":"mcm","clk":"997666351","pt":1580582174693,"mc":[{"id":"1.168081835","rc":[{"batl":[[0,1000,2.37]],"ltp":1.02,"tv":0.17,"id":22229228,"hc":-11.5}]}]}
{"op":"mcm","clk":"997666454","pt":1580582175188,"mc":[{"id":"1.168081835","rc":[{"trd":[[1.02,0.19]],"batb":[[0,1.02,8.8]],"batl":[[0,990,0.01]],"ltp":1.02,"tv":0.18,"id":22229228,"hc":-11.5}],"tv":0.48}]}
{"op":"mcm","clk":"997667546","pt":1580582181493,"mc":[{"id":"1.168081835","rc":[{"batl":[[0,1000,2.37]],"ltp":1.02,"tv":0.15,"id":22229228,"hc":-9.5}]}]}
{"op":"mcm","clk":"997667696","pt":1580582182313,"mc":[{"id":"1.168081835","rc":[{"trd":[[1.02,0.17]],"batb":[[0,1.02,8.81]],"batl":[[0,990,0.01]],"ltp":1.02,"tv":0.17,"id":22229228,"hc":-9.5}],"tv":0.49}]}
{"op":"mcm","clk":"997667951","pt":1580582183700,"mc":[{"id":"1.168081835","rc":[{"batl":[[0,1000,0.02]],"ltp":1.02,"tv":0.13,"id":22229228,"hc":-10.5}]}]}
{"op":"mcm","clk":"997668035","pt":1580582184110,"mc":[{"id":"1.168081835","rc":[{"trd":[[1.02,0.16]],"batb":[[0,1.02,8.82]],"batl":[[0,990,0.01]],"ltp":1.02,"tv":0.15,"id":22229228,"hc":-10.5}],"tv":0.51}]}
{"op":"mcm","clk":"997669431","pt":1580582191735,"mc":[{"id":"1.168081835","rc":[{"trd":[[1.02,0.2]],"batb":[[0,1.02,8.79]],"ltp":1.02,"tv":0.2,"id":22229228,"hc":-11.5}],"tv":0.52}]}
{"op":"mcm","clk":"997670690","pt":1580582198321,"mc":[{"id":"1.168081835","rc":[{"trd":[[1.02,0.19]],"batb":[[0,1.02,8.8]],"ltp":1.02,"tv":0.18,"id":22229228,"hc":-9.5}],"tv":0.54}]}
{"op":"mcm","clk":"997670921","pt":1580582199604,"mc":[{"id":"1.168081835","rc":[{"batl":[[0,1000,2.37]],"ltp":1.02,"tv":0.15,"id":22229228,"hc":-10.5}]}]}
{"op":"mcm","clk":"997671050","pt":1580582200254,"mc":[{"id":"1.168081835","rc":[{"trd":[[1.02,0.17]],"batb":[[0,1.02,8.81]],"batl":[[0,990,0.01]],"ltp":1.02,"tv":0.17,"id":22229228,"hc":-10.5}],"tv":0.55}]}
{"op":"mcm","clk":"997672558","pt":1580582208549,"mc":[{"id":"1.168081835","rc":[{"batl":[[0,1000,0.02]],"ltp":1.02,"tv":0.2,"id":22229228,"hc":-11.5}]}]}
{"op":"mcm","clk":"997672633","pt":1580582208931,"mc":[{"id":"1.168081835","rc":[{"trd":[[1.02,0.22]],"batb":[[0,1.02,8.78]],"batl":[[0,990,0.01]],"ltp":1.02,"tv":0.21,"id":22229228,"hc":-11.5}],"tv":0.57}]}
{"op":"mcm","clk":"997673721","pt":1580582214671,"mc":[{"id":"1.168081835","rc":[{"trd":[[1.02,0.2]],"batb":[[0,1.02,8.79]],"ltp":1.02,"tv":0.2,"id":22229228,"hc":-9.5}],"tv":0.58}]}
{"op":"mcm","clk":"997674152","pt":1580582216793,"mc":[{"id":"1.168081835","rc":[{"trd":[[1.02,0.19]],"batb":[[0,1.02,8.8]],"ltp":1.02,"tv":0.18,"id":22229228,"hc":-10.5}],"tv":0.6}]}
{"op":"mcm","clk":"997675769","pt":1580582225495,"mc":[{"id":"1.168081835","rc":[{"batl":[[0,1000,2.37]],"ltp":1.02,"tv":0.21,"id":22229228,"hc":-11.5}]}]}
{"op":"mcm","clk":"997675871","pt":1580582226007,"mc":[{"id":"1.168081835","rc":[{"trd":[[1.02,0.23]],"batb":[[0,1.02,8.77]],"batl":[[0,990,0.01]],"ltp":1.02,"tv":0.23,"id":22229228,"hc":-11.5}],"tv":0.62}]}
{"op":"mcm","clk":"997676818","pt":1580582230601,"mc":[{"id":"1.168081835","rc":[{"batl":[[0,1000,2.37]],"ltp":1.02,"tv":0.2,"id":22229228,"hc":-9.5}]}]}
{"op":"mcm","clk":"997676962","pt":1580582231303,"mc":[{"id":"1.168081835","rc":[{"trd":[[1.02,0.22]],"batb":[[0,1.02,8.78]],"batl":[[0,990,0.01]],"ltp":1.02,"tv":0.21,"id":22229228,"hc":-9.5}],"tv":0.63}]}
{"op":"mcm","clk":"997677396","pt":1580582233511,"mc":[{"id":"1.168081835","rc":[{"trd":[[1.02,0.2]],"batb":[[0,1.02,8.79]],"ltp":1.02,"tv":0.2,"id":22229228,"hc":-10.5}],"tv":0.65}]}
{"op":"mcm","clk":"997679009","pt":1580582242466,"mc":[{"id":"1.168081835","rc":[{"batl":[[0,1000,0.02]],"ltp":1.02,"tv":0.23,"id":22229228,"hc":-11.5}]}]}
{"op":"mcm","clk":"997679077","pt":1580582242906,"mc":[{"id":"1.168081835","rc":[{"trd":[[1.02,0.25]],"batb":[[0,1.02,8.76]],"batl":[[0,990,0.01]],"ltp":1.02,"tv":0.24,"id":22229228,"hc":-11.5}],"tv":0.66}]}
{"op":"mcm","clk":"997679928","pt":1580582247799,"mc":[{"id":"1.168081835","rc":[{"trd":[[1.02,0.23]],"batb":[[0,1.02,8.77]],"ltp":1.02,"tv":0.23,"id":22229228,"hc":-9.5}],"tv":0.68}]}
{"op":"mcm","clk":"997680254","pt":1580582249629,"mc":[{"id":"1.168081835","rc":[{"batl":[[0,1000,0.02]],"ltp":1.02,"tv":0.2,"id":22229228,"hc":-10.5}]}]}
{"op":"mcm","clk":"997680301","pt":1580582249911,"mc":[{"id":"1.168081835","rc":[{"trd":[[1.02,0.22]],"batb":[[0,1.02,8.78]],"batl":[[0,990,0.01]],"ltp":1.02,"tv":0.21,"id":22229228,"hc":-10.5}],"tv":0.69}]}
{"op":"mcm","clk":"997681976","pt":1580582259497,"mc":[{"id":"1.168081835","rc":[{"batl":[[0,1000,2.37]],"ltp":1.02,"tv":0.24,"id":22229228,"hc":-11.5}]}]}
{"op":"mcm","clk":"997682073","pt":1580582260108,"mc":[{"id":"1.168081835","rc":[{"trd":[[1.02,0.26]],"batb":[[0,1.02,8.75]],"batl":[[0,990,0.01]],"ltp":1.02,"tv":0.26,"id":22229228,"hc":-11.5}],"tv":0.71}]}
{"op":"mcm","clk":"997682810","pt":1580582264417,"mc":[{"id":"1.168081835","rc":[{"trd":[[1.02,0.25]],"batb":[[0,1.02,8.76]],"ltp":1.02,"tv":0.24,"id":22229228,"hc":-9.5}],"tv":0.72}]}
{"op":"mcm","clk":"997683201","pt":1580582266640,"mc":[{"id":"1.168081835","rc":[{"trd":[[1.02,0.23]],"batb":[[0,1.02,8.77]],"ltp":1.02,"tv":0.23,"id":22229228,"hc":-10.5}],"tv":0.74}]}
{"op":"mcm","clk":"997684786","pt":1580582275561,"mc":[{"id":"1.168081835","rc":[{"batl":[[0,1000,2.37]],"ltp":1.02,"tv":0.26,"id":22229228,"hc":-11.5}]}]}
{"op":"mcm","clk":"997684891","pt":1580582276165,"mc":[{"id":"1.168081835","rc":[{"trd":[[1.02,0.28]],"batb":[[0,1.02,8.74]],"batl":[[0,990,0.01]],"ltp":1.02,"tv":0.27,"id":22229228,"hc":-11.5}],"tv":0.75}]}
{"op":"mcm","clk":"997685667","pt":1580582280542,"mc":[{"id":"1.168081835","rc":[{"batl":[[0,1000,2.37]],"ltp":1.02,"tv":0.24,"id":22229228,"hc":-9.5}]}]}
{"op":"mcm","clk":"997685796","pt":1580582281268,"mc":[{"id":"1.168081835","rc":[{"trd":[[1.02,0.26]],"batb":[[0,1.02,8.75]],"batl":[[0,990,0.01]],"ltp":1.02,"tv":0.26,"id":22229228,"hc":-9.5}],"tv":0.77}]}
{"op":"mcm","clk":"997686195","pt":1580582283441,"mc":[{"id":"1.168081835","rc":[{"trd":[[1.02,0.25]],"batb":[[0,1.02,8.76]],"ltp":1.02,"tv":0.24,"id":22229228,"hc":-10.5}],"tv":0.79}]}
{"op":"mcm","clk":"997687621","pt":1580582291598,"mc":[{"id":"1.168081835","rc":[{"batl":[[0,1000,2.37]],"ltp":1.02,"tv":0.27,"id":22229228,"hc":-11.5}]}]}
{"op":"mcm","clk":"997687734","pt":1580582292322,"mc":[{"id":"1.168081835","rc":[{"trd":[[1.02,0.29]],"batb":[[0,1.02,8.73]],"batl":[[0,990,0.01]],"ltp":1.02,"tv":0.29,"id":22229228,"hc":-11.5}],"tv":0.8}]}
{"op":"mcm","clk":"997688630","pt":1580582297417,"mc":[{"id":"1.168081835","rc":[{"batl":[[0,1000,2.37]],"ltp":1.02,"tv":0.26,"id":22229228,"hc":-9.5}]}]}
{"op":"mcm","clk":"997688768","pt":1580582298135,"mc":[{"id":"1.168081835","rc":[{"trd":[[1.02,0.28]],"batb":[[0,1.02,8.74]],"batl":[[0,990,0.01]],"ltp":1.02,"tv":0.27,"id":22229228,"hc":-9.5}],"tv":0.82}]}
{"op":"mcm","clk":"997689029","pt":1580582299651,"mc":[{"id":"1.168081835","rc":[{"batl":[[0,1000,2.37]],"ltp":1.02,"tv":0.24,"id":22229228,"hc":-10.5}]}]}
{"op":"mcm","clk":"997689153","pt":1580582300212,"mc":[{"id":"1.168081835","rc":[{"trd":[[1.02,0.26]],"batb":[[0,1.02,8.75]],"batl":[[0,990,0.01]],"ltp":1.02,"tv":0.26,"id":22229228,"hc":-10.5}],"tv":0.83}]}
{"op":"mcm","clk":"997690682","pt":1580582308433,"mc":[{"id":"1.168081835","rc":[{"trd":[[1.02,0.31]],"batb":[[0,1.02,8.72]],"ltp":1.02,"tv":0.31,"id":22229228,"hc":-11.5}],"tv":0.85}]}
{"op":"mcm","clk":"997691732","pt":1580582314756,"mc":[{"id":"1.168081835","rc":[{"trd":[[1.02,0.29]],"batb":[[0,1.02,8.73]],"ltp":1.02,"tv":0.29,"id":22229228,"hc":-9.5}],"tv":0.86}]}
{"op":"mcm","clk":"997692023","pt":1580582316652,"mc":[{"id":"1.168081835","rc":[{"batl":[[0,1000,0.02]],"ltp":1.02,"tv":0.26,"id":22229228,"hc":-10.5}]}]}
{"op":"mcm","clk":"997692072","pt":1580582316964,"mc":[{"id":"1.168081835","rc":[{"trd":[[1.02,0.28]],"batb":[[0,1.02,8.74]],"batl":[[0,990,0.01]],"ltp":1.02,"tv":0.27,"id":22229228,"hc":-10.5}],"tv":0.88}]}
{"op":"mcm","clk":"997693408","pt":1580582324517,"mc":[{"id":"1.168081835","rc":[{"batl":[[0,1000,0.02]],"ltp":1.02,"tv":0.31,"id":22229228,"hc":-11.5}]}]}
{"op":"mcm","clk":"997693488","pt":1580582324990,"mc":[{"id":"1.168081835","rc":[{"trd":[[1.02,0.33]],"batb":[[0,1.02,8.71]],"batl":[[0,990,0.01]],"ltp":1.02,"tv":0.32,"id":22229228,"hc":-11.5}],"tv":0.89}]}
{"op":"mcm","clk":"997694712","pt":1580582331818,"mc":[{"id":"1.168081835","rc":[{"trd":[[1.02,0.31]],"batb":[[0,1.02,8.72]],"ltp":1.02,"tv":0.31,"id":22229228,"hc":-9.5}],"tv":0.91}]}
{"op":"mcm","clk":"997694982","pt":1580582333383,"mc":[{"id":"1.168081835","rc":[{"batl":[[0,1000,2.37]],"ltp":1.02,"tv":0.27,"id":22229228,"hc":-10.5}]}]}
{"op":"mcm","clk":"997695080","pt":1580582333979,"mc":[{"id":"1.168081835","rc":[{"trd":[[1.02,0.29]],"batb":[[0,1.02,8.73]],"batl":[[0,990,0.01]],"ltp":1.02,"tv":0.29,"id":22229228,"hc":-10.5}],"tv":0.93}]}
{"op":"mcm","clk":"997696286","pt":1580582340493,"mc":[{"id":"1.168081835","rc":[{"batl":[[0,1000,2.37]],"ltp":1.02,"tv":0.32,"id":22229228,"hc":-11.5}]}]}
{"op":"mcm","clk":"997696387","pt":1580582341136,"mc":[{"id":"1.168081835","rc":[{"trd":[[1.02,0.34]],"batb":[[0,1.02,8.7]],"batl":[[0,990,0.01]],"ltp":1.02,"tv":0.34,"id":22229228,"hc":-11.5}],"tv":0.94}]}
{"op":"mcm","clk":"997697672","pt":1580582347802,"mc":[{"id":"1.168081835","rc":[{"trd":[[1.02,0.33]],"batb":[[0,1.02,8.71]],"ltp":1.02,"tv":0.32,"id":22229228,"hc":-9.5}],"tv":0.96}]}
{"op":"mcm","clk":"997698195","pt":1580582350368,"mc":[{"id":"1.168081835","rc":[{"trd":[[1.02,0.31]],"batb":[[0,1.02,8.72]],"ltp":1.02,"tv":0.31,"id":22229228,"hc":-10.5}],"tv":0.97}]}
{"op":"mcm","clk":"997699592","pt":1580582357689,"mc":[{"id":"1.168081835","rc":[{"trd":[[1.02,0.36]],"batb":[[0,1.02,8.69]],"ltp":1.02,"tv":0.35,"id":22229228,"hc":-11.5}],"tv":0.99}]}
{"op":"mcm","clk":"997700869","pt":1580582364703,"mc":[{"id":"1.168081835","rc":[{"batl":[[0,1000,0.02]],"ltp":1.02,"tv":0.32,"id":22229228,"hc":-9.5}]}]}
{"op":"mcm","clk":"997700947","pt":1580582365100,"mc":[{"id":"1.168081835","rc":[{"trd":[[1.02,0.34]],"batb":[[0,1.02,8.7]],"batl":[[0,990,0.01]],"ltp":1.02,"tv":0.34,"id":22229228,"hc":-9.5}],"tv":1.0}]}
{"op":"mcm","clk":"997701240","pt":1580582366691,"mc":[{"id":"1.168081835","rc":[{"trd":[[1.02,0.33]],"batb":[[0,1.02,8.71]],"ltp":1.02,"tv":0.32,"id":22229228,"hc":-10.5}],"tv":1.02}]}
{"op":"mcm","clk":"997702550","pt":1580582373625,"mc":[{"id":"1.168081835","rc":[{"batl":[[0,1000,0.02]],"ltp":1.02,"tv":0.35,"id":22229228,"hc":-11.5}]}]}
{"op":"mcm","clk":"997702621","pt":1580582373999,"mc":[{"id":"1.168081835","rc":[{"trd":[[1.02,0.37]],"batb":[[0,1.02,8.68]],"batl":[[0,990,0.01]],"ltp":1.02,"tv":0.37,"id":22229228,"hc":-11.5}],"tv":1.03}]}
{"op":"mcm","clk":"997703792","pt":1580582381603,"mc":[{"id":"1.168081835","rc":[{"batl":[[0,1000,0.02]],"ltp":1.02,"tv":0.34,"id":22229228,"hc":-9.5}]}]}
{"op":"mcm","clk":"997703878","pt":1580582382146,"mc":[{"id":"1.168081835","rc":[{"trd":[[1.02,0.36]],"batb":[[0,1.02,8.69]],"batl":[[0,990,0.01]],"ltp":1.02,"tv":0.35,"id":22229228,"hc":-9.5}],"tv":1.05}]}
{"op":"mcm","clk":"997704082","pt":1580582383398,"mc":[{"id":"1.168081835","rc":[{"batl":[[0,1000,0.02]],"ltp":1.02,"tv":0.32,"id":22229228,"hc":-10.5}]}]}
{"op":"mcm","clk":"997704135","pt":1580582384663,"mc":[{"id":"1.168081835","rc":[{"trd":[[1.02,0.34]],"batb":[[0,1.02,8.7]],"batl":[[0,990,0.01]],"ltp":1.02,"tv":0.34,"id":22229228,"hc":-10.5}],"tv":1.07}]}
{"op":"mcm","clk":"997705146","pt":1580582390320,"mc":[{"id":"1.168081835","rc":[{"trd":[[1.02,0.39]],"batb":[[0,1.02,8.67]],"ltp":1.02,"tv":0.38,"id":22229228,"hc":-11.5}],"tv":1.08}]}
{"op":"mcm","clk":"997706673","pt":1580582399474,"mc":[{"id":"1.168081835","rc":[{"trd":[[1.02,0.37]],"batb":[[0,1.02,8.68]],"ltp":1.02,"tv":0.37,"id":22229228,"hc":-9.5}],"tv":1.1}]}
{"op":"mcm","clk":"997706894","pt":1580582400664,"mc":[{"id":"1.168081835","rc":[{"batl":[[0,1000,0.02]],"ltp":1.02,"tv":0.34,"id":22229228,"hc":-10.5}]}]}
{"op":"mcm","clk":"997706958","pt":1580582400988,"mc":[{"id":"1.168081835","rc":[{"trd":[[1.02,0.36]],"batb":[[0,1.02,8.69]],"batl":[[0,990,0.01]],"ltp":1.02,"tv":0.35,"id":22229228,"hc":-10.5}],"tv":1.11}]}
{"op":"mcm","clk":"997708018","pt":1580582406545,"mc":[{"id":"1.168081835","rc":[{"batl":[[0,1000,2.37]],"ltp":1.02,"tv":0.38,"id":22229228,"hc":-11.5}]}]}
{"op":"mcm","clk":"997708105","pt":1580582407075,"mc":[{"id":"1.168081835","rc":[{"trd":[[1.02,0.4]],"batb":[[0,1.02,8.66]],"batl":[[0,990,0.01]],"ltp":1.02,"tv":0.4,"id":22229228,"hc":-11.5}],"tv":1.13}]}
{"op":"mcm","clk":"997709625","pt":1580582415669,"mc":[{"id":"1.168081835","rc":[{"trd":[[1.02,0.39]],"batb":[[0,1.02,8.67]],"ltp":1.02,"tv":0.38,"id":22229228,"hc":-9.5}],"tv":1.14}]}
{"op":"mcm","clk":"997709790","pt":1580582416683,"mc":[{"id":"1.168081835","rc":[{"batl":[[0,1000,0.02]],"ltp":1.02,"tv":0.35,"id":22229228,"hc":-10.5}]}]}
{"op":"mcm","clk":"997709864","pt":1580582417085,"mc":[{"id":"1.168081835","rc":[{"trd":[[1.02,0.37]],"batb":[[0,1.02,8.68]],"batl":[[0,990,0.01]],"ltp":1.02,"tv":0.37,"id":22229228,"hc":-10.5}],"tv":1.16}]}
{"op":"mcm","clk":"997711015","pt":1580582423500,"mc":[{"id":"1.168081835","rc":[{"batl":[[0,1000,0.02]],"ltp":1.02,"tv":0.4,"id":22229228,"hc":-11.5}]}]}
{"op":"mcm","clk":"997711097","pt":1580582423883,"mc":[{"id":"1.168081835","rc":[{"trd":[[1.02,0.42]],"batb":[[0,1.02,8.65]],"batl":[[0,990,0.01]],"ltp":1.02,"tv":0.41,"id":22229228,"hc":-11.5}],"tv":1.17}]}
{"op":"mcm","clk":"997712378","pt":1580582431551,"mc":[{"id":"1.168081835","rc":[{"batl":[[0,1000,0.02]],"ltp":1.02,"tv":0.38,"id":22229228,"hc":-9.5}]}]}
{"op":"mcm","clk":"997712566","pt":1580582432655,"mc":[{"id":"1.168081835","rc":[{"trd":[[1.02,0.4]],"batb":[[0,1.02,8.66]],"batl":[[0,990,0.01]],"ltp":1.02,"tv":0.4,"id":22229228,"hc":-9.5},{"batl":[[0,1000,2.37]],"ltp":1.02,"tv":0.37,"id":22229228,"hc":-10.5}],"tv":1.19}]}
{"op":"mcm","clk":"997712660","pt":1580582433154,"mc":[{"id":"1.168081835","rc":[{"trd":[[1.02,0.39]],"batb":[[0,1.02,8.67]],"batl":[[0,990,0.01]],"ltp":1.02,"tv":0.38,"id":22229228,"hc":-10.5}],"tv":1.2}]}
{"op":"mcm","clk":"997713915","pt":1580582440587,"mc":[{"id":"1.168081835","rc":[{"trd":[[1.02,0.43]],"batb":[[0,1.02,8.64]],"ltp":1.02,"tv":0.43,"id":22229228,"hc":-11.5}],"tv":1.22}]}
{"op":"mcm","clk":"997715030","pt":1580582447647,"mc":[{"id":"1.168081835","rc":[{"batl":[[0,1000,2.37]],"ltp":1.02,"tv":0.4,"id":22229228,"hc":-9.5}]}]}
{"op":"mcm","clk":"997715157","pt":1580582448263,"mc":[{"id":"1.168081835","rc":[{"trd":[[1.02,0.42]],"batb":[[0,1.02,8.65]],"batl":[[0,990,0.01]],"ltp":1.02,"tv":0.41,"id":22229228,"hc":-9.5}],"tv":1.24}]}
{"op":"mcm","clk":"997715404","pt":1580582449764,"mc":[{"id":"1.168081835","rc":[{"trd":[[1.02,0.4]],"batb":[[0,1.02,8.66]],"ltp":1.02,"tv":0.4,"id":22229228,"hc":-10.5}],"tv":1.25}]}
{"op":"mcm","clk":"997716708","pt":1580582457919,"mc":[{"id":"1.168081835","rc":[{"trd":[[1.02,0.45]],"batb":[[0,1.02,8.63]],"ltp":1.02,"tv":0.44,"id":22229228,"hc":-11.5}],"tv":1.27}]}
{"op":"mcm","clk":"997717920","pt":1580582465563,"mc":[{"id":"1.168081835","rc":[{"trd":[[1.02,0.43]],"batb":[[0,1.02,8.64]],"ltp":1.02,"tv":0.43,"id":22229228,"hc":-9.5},{"batl":[[0,1000,0.02]],"ltp":1.02,"tv":0.4,"id":22229228,"hc":-10.5}],"tv":1.28}]}
{"op":"mcm","clk":"997717988","pt":1580582466001,"mc":[{"id":"1.168081835","rc":[{"trd":[[1.02,0.42]],"batb":[[0,1.02,8.65]],"batl":[[0,990,0.01]],"ltp":1.02,"tv":0.41,"id":22229228,"hc":-10.5}],"tv":1.3}]}
{"op":"mcm","clk":"997719485","pt":1580582474564,"mc":[{"id":"1.168081835","rc":[{"trd":[[1.02,0.47]],"batb":[[0,1.02,8.62]],"ltp":1.02,"tv":0.46,"id":22229228,"hc":-11.5}],"tv":1.31}]}
{"op":"mcm","clk":"997720593","pt":1580582481296,"mc":[{"id":"1.168081835","rc":[{"trd":[[1.02,0.45]],"batb":[[0,1.02,8.63]],"ltp":1.02,"tv":0.44,"id":22229228,"hc":-9.5}],"tv":1.33}]}
{"op":"mcm","clk":"997720783","pt":1580582482368,"mc":[{"id":"1.168081835","rc":[{"trd":[[1.02,0.43]],"batb":[[0,1.02,8.64]],"ltp":1.02,"tv":0.43,"id":22229228,"hc":-10.5}],"tv":1.34}]}
{"op":"mcm","clk":"997722293","pt":1580582491387,"mc":[{"id":"1.168081835","rc":[{"batl":[[0,1000,0.02]],"ltp":1.02,"tv":0.46,"id":22229228,"hc":-11.5}]}]}
{"op":"mcm","clk":"997722365","pt":1580582491773,"mc":[{"id":"1.168081835","rc":[{"trd":[[1.02,0.48]],"batb":[[0,1.02,8.61]],"batl":[[0,990,0.01]],"ltp":1.02,"tv":0.48,"id":22229228,"hc":-11.5}],"tv":1.36}]}
{"op":"mcm","clk":"997723484","pt":1580582498441,"mc":[{"id":"1.168081835","rc":[{"trd":[[1.02,0.47]],"batb":[[0,1.02,8.62]],"ltp":1.02,"tv":0.46,"id":22229228,"hc":-9.5},{"batl":[[0,1000,0.02]],"ltp":1.02,"tv":0.43,"id":22229228,"hc":-10.5}],"tv":1.38}]}
{"op":"mcm","clk":"997723550","pt":1580582498872,"mc":[{"id":"1.168081835","rc":[{"trd":[[1.02,0.45]],"batb":[[0,1.02,8.63]],"batl":[[0,990,0.01]],"ltp":1.02,"tv":0.44,"id":22229228,"hc":-10.5}],"tv":1.39}]}
{"op":"mcm","clk":"997725212","pt":1580582508586,"mc":[{"id":"1.168081835","rc":[{"batl":[[0,1000,0.02]],"ltp":1.02,"tv":0.48,"id":22229228,"hc":-11.5}]}]}
{"op":"mcm","clk":"997725261","pt":1580582508856,"mc":[{"id":"1.168081835","rc":[{"trd":[[1.02,0.5]],"batb":[[0,1.02,8.6]],"batl":[[0,990,0.01]],"ltp":1.02,"tv":0.49,"id":22229228,"hc":-11.5}],"tv":1.41}]}
{"op":"mcm","clk":"997726023","pt":1580582513684,"mc":[{"id":"1.168081835","rc":[{"batl":[[0,1000,2.37]],"ltp":1.02,"tv":0.46,"id":22229228,"hc":-9.5}]}]}
{"op":"mcm","clk":"997726125","pt":1580582514283,"mc":[{"id":"1.168081835","rc":[{"trd":[[1.02,0.48]],"batb":[[0,1.02,8.61]],"batl":[[0,990,0.01]],"ltp":1.02,"tv":0.48,"id":22229228,"hc":-9.5}],"tv":1.42}]}
{"op":"mcm","clk":"997726323","pt":1580582515583,"mc":[{"id":"1.168081835","rc":[{"trd":[[1.02,0.47]],"batb":[[0,1.02,8.62]],"ltp":1.02,"tv":0.46,"id":22229228,"hc":-10.5}],"tv":1.44}]}
{"op":"mcm","clk":"997728001","pt":1580582525597,"mc":[{"id":"1.168081835","rc":[{"batl":[[0,1000,2.37]],"ltp":1.02,"tv":0.49,"id":22229228,"hc":-11.5}]}]}
{"op":"mcm","clk":"997728131","pt":1580582526307,"mc":[{"id":"1.168081835","rc":[{"trd":[[1.02,0.51]],"batb":[[0,1.02,8.59]],"batl":[[0,990,0.01]],"ltp":1.02,"tv":0.51,"id":22229228,"hc":-11.5}],"tv":1.45}]}
{"op":"mcm","clk":"997729159","pt":1580582531700,"mc":[{"id":"1.168081835","rc":[{"trd":[[1.02,0.5]],"batb":[[0,1.02,8.6]],"ltp":1.02,"tv":0.49,"id":22229228,"hc":-9.5},{"batl":[[0,1000,2.37]],"ltp":1.02,"tv":0.46,"id":22229228,"hc":-10.5}],"tv":1.47}]}
{"op":"mcm","clk":"997729247","pt":1580582532206,"mc":[{"id":"1.168081835","rc":[{"trd":[[1.02,0.48]],"batb":[[0,1.02,8.61]],"batl":[[0,990,0.01]],"ltp":1.02,"tv":0.48,"id":22229228,"hc":-10.5}],"tv":1.48}]}
{"op":"mcm","clk":"997731203","pt":1580582543396,"mc":[{"id":"1.168081835","rc":[{"trd":[[1.02,0.53]],"batb":[[0,1.02,8.58]],"ltp":1.02,"tv":0.52,"id":22229228,"hc":-11.5}],"tv":1.5}]}
{"op":"mcm","clk":"997731895","pt":1580582547438,"mc":[{"id":"1.168081835","rc":[{"trd":[[1.02,0.51]],"batb":[[0,1.02,8.59]],"ltp":1.02,"tv":0.51,"id":22229228,"hc":-9.5}],"tv":1.51}]}
{"op":"mcm","clk":"997732071","pt":1580582548434,"mc":[{"id":"1.168081835","rc":[{"batl":[[0,1000,0.02]],"ltp":1.02,"tv":0.48,"id":22229228,"hc":-10.5}]}]}
{"op":"mcm","clk":"997732147","pt":1580582548813,"mc":[{"id":"1.168081835","rc":[{"trd":[[1.02,0.5]],"batb":[[0,1.02,8.6]],"batl":[[0,990,0.01]],"ltp":1.02,"tv":0.49,"id":22229228,"hc":-10.5}],"tv":1.53}]}
{"op":"mcm","clk":"997733990","pt":1580582559539,"mc":[{"id":"1.168081835","rc":[{"trd":[[1.02,0.54]],"batb":[[0,1.02,8.57]],"ltp":1.02,"tv":0.54,"id":22229228,"hc":-11.5}],"tv":1.55}]}
{"op":"mcm","clk":"997734865","pt":1580582564354,"mc":[{"id":"1.168081835","rc":[{"trd":[[1.02,0.53]],"batb":[[0,1.02,8.58]],"ltp":1.02,"tv":0.52,"id":22229228,"hc":-9.5}],"tv":1.56}]}
{"op":"mcm","clk":"997735073","pt":1580582565445,"mc":[{"id":"1.168081835","rc":[{"batl":[[0,1000,0.02]],"ltp":1.02,"tv":0.49,"id":22229228,"hc":-10.5}]}]}
{"op":"mcm","clk":"997735146","pt":1580582565872,"mc":[{"id":"1.168081835","rc":[{"trd":[[1.02,0.51]],"batb":[[0,1.02,8.59]],"batl":[[0,990,0.01]],"ltp":1.02,"tv":0.51,"id":22229228,"hc":-10.5}],"tv":1.58}]}
{"op":"mcm","clk":"997737027","pt":1580582575700,"mc":[{"id":"1.168081835","rc":[{"trd":[[1.02,0.56]],"batb":[[0,1.02,8.56]],"ltp":1.02,"tv":0.55,"id":22229228,"hc":-11.5}],"tv":1.59}]}
{"op":"mcm","clk":"997738022","pt":1580582580619,"mc":[{"id":"1.168081835","rc":[{"batl":[[0,1000,2.37]],"ltp":1.02,"tv":0.52,"id":22229228,"hc":-9.5}]}]}
{"op":"mcm","clk":"997738170","pt":1580582581253,"mc":[{"id":"1.168081835","rc":[{"trd":[[1.02,0.54]],"batb":[[0,1.02,8.57]],"batl":[[0,990,0.01]],"ltp":1.02,"tv":0.54,"id":22229228,"hc":-9.5}],"tv":1.61}]}
{"op":"mcm","clk":"997738415","pt":1580582582500,"mc":[{"id":"1.168081835","rc":[{"batl":[[0,1000,0.02]],"ltp":1.02,"tv":0.51,"id":22229228,"hc":-10.5}]}]}
{"op":"mcm","clk":"997738482","pt":1580582582807,"mc":[{"id":"1.168081835","rc":[{"trd":[[1.02,0.53]],"batb":[[0,1.02,8.58]],"batl":[[0,990,0.01]],"ltp":1.02,"tv":0.52,"id":22229228,"hc":-10.5}],"tv":1.62}]}
{"op":"mcm","clk":"997740037","pt":1580582591517,"mc":[{"id":"1.168081835","rc":[{"batl":[[0,1000,0.02]],"ltp":1.02,"tv":0.55,"id":22229228,"hc":-11.5}]}]}
{"op":"mcm","clk":"997740100","pt":1580582591882,"mc":[{"id":"1.168081835","rc":[{"trd":[[1.02,0.57]],"batb":[[0,1.02,8.55]],"batl":[[0,990,0.01]],"ltp":1.02,"tv":0.57,"id":22229228,"hc":-11.5}],"tv":1.64}]}
{"op":"mcm","clk":"997741086","pt":1580582597496,"mc":[{"id":"1.168081835","rc":[{"batl":[[0,1000,2.37]],"ltp":1.02,"tv":0.54,"id":22229228,"hc":-9.5}]}]}
{"op":"mcm","clk":"997741205","pt":1580582598213,"mc":[{"id":"1.168081835","rc":[{"trd":[[1.02,0.56]],"batb":[[0,1.02,8.56]],"batl":[[0,990,0.01]],"ltp":1.02,"tv":0.55,"id":22229228,"hc":-9.5}],"tv":1.65}]}
{"op":"mcm","clk":"997741441","pt":1580582599536,"mc":[{"id":"1.168081835","rc":[{"batl":[[0,1000,0.02]],"ltp":1.02,"tv":0.52,"id":22229228,"hc":-10.5}]}]}
{"op":"mcm","clk":"997741503","pt":1580582599790,"mc":[{"id":"1.168081835","rc":[{"trd":[[1.02,0.54]],"batb":[[0,1.02,8.57]],"batl":[[0,990,0.01]],"ltp":1.02,"tv":0.54,"id":22229228,"hc":-10.5}],"tv":1.67}]}
{"op":"mcm","clk":"997743075","pt":1580582608307,"mc":[{"id":"1.168081835","rc":[{"trd":[[1.02,0.59]],"batb":[[0,1.02,8.54]],"ltp":1.02,"tv":0.58,"id":22229228,"hc":-11.5}],"tv":1.69}]}
{"op":"mcm","clk":"997744135","pt":1580582614549,"mc":[{"id":"1.168081835","rc":[{"batl":[[0,1000,2.37]],"ltp":1.02,"tv":0.55,"id":22229228,"hc":-9.5}]}]}
{"op":"mcm","clk":"997744243","pt":1580582615150,"mc":[{"id":"1.168081835","rc":[{"trd":[[1.02,0.57]],"batb":[[0,1.02,8.55]],"batl":[[0,990,0.01]],"ltp":1.02,"tv":0.57,"id":22229228,"hc":-9.5}],"tv":1.7}]}
{"op":"mcm","clk":"997744525","pt":1580582616753,"mc":[{"id":"1.168081835","rc":[{"trd":[[1.02,0.56]],"batb":[[0,1.02,8.56]],"ltp":1.02,"tv":0.55,"id":22229228,"hc":-10.5}],"tv":1.72}]}
{"op":"mcm","clk":"997746013","pt":1580582624867,"mc":[{"id":"1.168081835","rc":[{"trd":[[1.02,0.6]],"batb":[[0,1.02,8.53]],"ltp":1.02,"tv":0.6,"id":22229228,"hc":-11.5}],"tv":1.73}]}
{"op":"mcm","clk":"997747423","pt":1580582632372,"mc":[{"id":"1.168081835","rc":[{"trd":[[1.02,0.59]],"batb":[[0,1.02,8.54]],"ltp":1.02,"tv":0.58,"id":22229228,"hc":-9.5}],"tv":1.75}]}
{"op":"mcm","clk":"997747674","pt":1580582633782,"mc":[{"id":"1.168081835","rc":[{"trd":[[1.02,0.57]],"batb":[[0,1.02,8.55]],"ltp":1.02,"tv":0.57,"id":22229228,"hc":-10.5}],"tv":1.76}]}
{"op":"mcm","clk":"997749089","pt":1580582641703,"mc":[{"id":"1.168081835","rc":[{"trd":[[1.02,0.62]],"batb":[[0,1.02,8.52]],"ltp":1.02,"tv":0.62,"id":22229228,"hc":-11.5}],"tv":1.78}]}
{"op":"mcm","clk":"997750471","pt":1580582649617,"mc":[{"id":"1.168081835","rc":[{"trd":[[1.02,0.6]],"batb":[[0,1.02,8.53]],"ltp":1.02,"tv":0.6,"id":22229228,"hc":-9.5}],"tv":1.79}]}
{"op":"mcm","clk":"997750608","pt":1580582650434,"mc":[{"id":"1.168081835","rc":[{"batl":[[0,1000,2.37]],"ltp":1.02,"tv":0.57,"id":22229228,"hc":-10.5}]}]}
{"op":"mcm","clk":"997750753","pt":1580582651140,"mc":[{"id":"1.168081835","rc":[{"trd":[[1.02,0.59]],"batb":[[0,1.02,8.54]],"batl":[[0,990,0.01]],"ltp":1.02,"tv":0.58,"id":22229228,"hc":-10.5}],"tv":1.81}]}
{"op":"mcm","clk":"997751844","pt":1580582657532,"mc":[{"id":"1.168081835","rc":[{"batl":[[0,1000,0.02]],"ltp":1.02,"tv":0.62,"id":22229228,"hc":-11.5}]}]}
{"op":"mcm","clk":"997751920","pt":1580582657898,"mc":[{"id":"1.168081835","rc":[{"trd":[[1.02,0.64]],"batb":[[0,1.02,8.51]],"batl":[[0,990,0.01]],"ltp":1.02,"tv":0.63,"id":22229228,"hc":-11.5}],"tv":1.82}]}
{"op":"mcm","clk":"997753346","pt":1580582666512,"mc":[{"id":"1.168081835","rc":[{"batl":[[0,1000,0.02]],"ltp":1.02,"tv":0.6,"id":22229228,"hc":-9.5}]}]}
{"op":"mcm","clk":"997753430","pt":1580582666924,"mc":[{"id":"1.168081835","rc":[{"trd":[[1.02,0.62]],"batb":[[0,1.02,8.52]],"batl":[[0,990,0.01]],"ltp":1.02,"tv":0.62,"id":22229228,"hc":-9.5}],"tv":1.84}]}
{"op":"mcm","clk":"997753678","pt":1580582668513,"mc":[{"id":"1.168081835","rc":[{"trd":[[1.02,0.6]],"batb":[[0,1.02,8.53]],"ltp":1.02,"tv":0.6,"id":22229228,"hc":-10.5}],"tv":1.86}]}
{"op":"mcm","clk":"997754760","pt":1580582674887,"mc":[{"id":"1.168081835","rc":[{"trd":[[1.02,0.65]],"batb":[[0,1.02,8.5]],"ltp":1.02,"tv":0.65,"id":22229228,"hc":-11.5}],"tv":1.87}]}
{"op":"mcm","clk":"997756016","pt":1580582682668,"mc":[{"id":"1.168081835","rc":[{"batl":[[0,1000,0.02]],"ltp":1.02,"tv":0.62,"id":22229228,"hc":-9.5}]}]}
{"op":"mcm","clk":"997756078","pt":1580582683017,"mc":[{"id":"1.168081835","rc":[{"trd":[[1.02,0.64]],"batb":[[0,1.02,8.51]],"batl":[[0,990,0.01]],"ltp":1.02,"tv":0.63,"id":22229228,"hc":-9.5}],"tv":1.89}]}
{"op":"mcm","clk":"997756425","pt":1580582685227,"mc":[{"id":"1.168081835","rc":[{"batl":[[0,1000,0.02]],"ltp":1.02,"tv":0.6,"id":22229228,"hc":-10.5}]}]}
{"op":"mcm","clk":"997756518","pt":1580582685833,"mc":[{"id":"1.168081835","rc":[{"trd":[[1.02,0.62]],"batb":[[0,1.02,8.52]],"batl":[[0,990,0.01]],"ltp":1.02,"tv":0.62,"id":22229228,"hc":-10.5}],"tv":1.9}]}
{"op":"mcm","clk":"997757384","pt":1580582691465,"mc":[{"id":"1.168081835","rc":[{"trd":[[1.02,0.67]],"batb":[[0,1.02,8.49]],"ltp":1.02,"tv":0.66,"id":22229228,"hc":-11.5}],"tv":1.92}]}
{"op":"mcm","clk":"997758440","pt":1580582698641,"mc":[{"id":"1.168081835","rc":[{"batl":[[0,1000,0.02]],"ltp":1.02,"tv":0.63,"id":22229228,"hc":-9.5}]}]}
{"op":"mcm","clk":"997758526","pt":1580582699065,"mc":[{"id":"1.168081835","rc":[{"trd":[[1.02,0.65]],"batb":[[0,1.02,8.5]],"batl":[[0,990,0.01]],"ltp":1.02,"tv":0.65,"id":22229228,"hc":-9.5}],"tv":1.93}]}
{"op":"mcm","clk":"997759112","pt":1580582702634,"mc":[{"id":"1.168081835","rc":[{"batl":[[0,1000,2.37]],"ltp":1.02,"tv":0.62,"id":22229228,"hc":-10.5}]}]}
{"op":"mcm","clk":"997759221","pt":1580582703274,"mc":[{"id":"1.168081835","rc":[{"trd":[[1.02,0.64]],"batb":[[0,1.02,8.51]],"batl":[[0,990,0.01]],"ltp":1.02,"tv":0.63,"id":22229228,"hc":-10.5}],"tv":1.95}]}
{"op":"mcm","clk":"997759968","pt":1580582707620,"mc":[{"id":"1.168081835","rc":[{"batl":[[0,1000,2.37]],"ltp":1.02,"tv":0.66,"id":22229228,"hc":-11.5}]}]}
{"op":"mcm","clk":"997760101","pt":1580582708308,"mc":[{"id":"1.168081835","rc":[{"trd":[[1.02,0.68]],"batb":[[0,1.02,8.48]],"batl":[[0,990,0.01]],"ltp":1.02,"tv":0.68,"id":22229228,"hc":-11.5}],"tv":1.96}]}
{"op":"mcm","clk":"997761182","pt":1580582714516,"mc":[{"id":"1.168081835","rc":[{"batl":[[0,1000,2.37]],"ltp":1.02,"tv":0.65,"id":22229228,"hc":-9.5}]}]}
{"op":"mcm","clk":"997761302","pt":1580582715215,"mc":[{"id":"1.168081835","rc":[{"trd":[[1.02,0.67]],"batb":[[0,1.02,8.49]],"batl":[[0,990,0.01]],"ltp":1.02,"tv":0.66,"id":22229228,"hc":-9.5}],"tv":1.98}]}
{"op":"mcm","clk":"997761975","pt":1580582719378,"mc":[{"id":"1.168081835","rc":[{"trd":[[1.02,0.65]],"batb":[[0,1.02,8.5]],"ltp":1.02,"tv":0.65,"id":22229228,"hc":-10.5}],"tv":2.0}]}
{"op":"mcm","clk":"997762804","pt":1580582724514,"mc":[{"id":"1.168081835","rc":[{"batl":[[0,1000,2.37]],"ltp":1.02,"tv":0.68,"id":22229228,"hc":-11.5}]}]}
{"op":"mcm","clk":"997762896","pt":1580582725103,"mc":[{"id":"1.168081835","rc":[{"trd":[[1.02,0.7]],"batb":[[0,1.02,8.47]],"batl":[[0,990,0.01]],"ltp":1.02,"tv":0.69,"id":22229228,"hc":-11.5}],"tv":2.01}]}
{"op":"mcm","clk":"997763842","pt":1580582731327,"mc":[{"id":"1.168081835","rc":[{"trd":[[1.02,0.68]],"batb":[[0,1.02,8.48]],"ltp":1.02,"tv":0.68,"id":22229228,"hc":-9.5}],"tv":2.03}]}
{"op":"mcm","clk":"997764461","pt":1580582735658,"mc":[{"id":"1.168081835","rc":[{"trd":[[1.02,0.67]],"batb":[[0,1.02,8.49]],"ltp":1.02,"tv":0.66,"id":22229228,"hc":-10.5}],"tv":2.04}]}
{"op":"mcm","clk":"997765382","pt":1580582741549,"mc":[{"id":"1.168081835","rc":[{"batl":[[0,1000,0.02]],"ltp":1.02,"tv":0.69,"id":22229228,"hc":-11.5}]}]}
{"op":"mcm","clk":"997765446","pt":1580582741982,"mc":[{"id":"1.168081835","rc":[{"trd":[[1.02,0.71]],"batb":[[0,1.02,8.46]],"batl":[[0,990,0.01]],"ltp":1.02,"tv":0.71,"id":22229228,"hc":-11.5}],"tv":2.06}]}
{"op":"mcm","clk":"997766252","pt":1580582747493,"mc":[{"id":"1.168081835","rc":[{"batl":[[0,1000,0.02]],"ltp":1.02,"tv":0.68,"id":22229228,"hc":-9.5}]}]}
{"op":"mcm","clk":"997766308","pt":1580582747872,"mc":[{"id":"1.168081835","rc":[{"trd":[[1.02,0.7]],"batb":[[0,1.02,8.47]],"batl":[[0,990,0.01]],"ltp":1.02,"tv":0.69,"id":22229228,"hc":-9.5}],"tv":2.07}]}
{"op":"mcm","clk":"997766828","pt":1580582751504,"mc":[{"id":"1.168081835","rc":[{"batl":[[0,1000,2.37]],"ltp":1.02,"tv":0.66,"id":22229228,"hc":-10.5}]}]}
{"op":"mcm","clk":"997766937","pt":1580582752192,"mc":[{"id":"1.168081835","rc":[{"trd":[[1.02,0.68]],"batb":[[0,1.02,8.48]],"batl":[[0,990,0.01]],"ltp":1.02,"tv":0.68,"id":22229228,"hc":-10.5}],"tv":2.09}]}
{"op":"mcm","clk":"997768012","pt":1580582758492,"mc":[{"id":"1.168081835","rc":[{"batl":[[0,1000,0.02]],"ltp":1.02,"tv":0.71,"id":22229228,"hc":-11.5}]}]}
{"op":"mcm","clk":"997768089","pt":1580582758891,"mc":[{"id":"1.168081835","rc":[{"trd":[[1.02,0.73]],"batb":[[0,1.02,8.45]],"batl":[[0,990,0.01]],"ltp":1.02,"tv":0.72,"id":22229228,"hc":-11.5}],"tv":2.1}]}
{"op":"mcm","clk":"997769000","pt":1580582764402,"mc":[{"id":"1.168081835","rc":[{"trd":[[1.02,0.71]],"batb":[[0,1.02,8.46]],"ltp":1.02,"tv":0.71,"id":22229228,"hc":-9.5}],"tv":2.12}]}
{"op":"mcm","clk":"997769632","pt":1580582768425,"mc":[{"id":"1.168081835","rc":[{"trd":[[1.02,0.7]],"batb":[[0,1.02,8.47]],"ltp":1.02,"tv":0.69,"id":22229228,"hc":-10.5}],"tv":2.14}]}
{"op":"mcm","clk":"997770720","pt":1580582775753,"mc":[{"id":"1.168081835","rc":[{"trd":[[1.02,0.74]],"batb":[[0,1.02,8.44]],"ltp":1.02,"tv":0.74,"id":22229228,"hc":-11.5}],"tv":2.15}]}
{"op":"mcm","clk":"997771472","pt":1580582780649,"mc":[{"id":"1.168081835","rc":[{"trd":[[1.02,0.73]],"batb":[[0,1.02,8.45]],"ltp":1.02,"tv":0.72,"id":22229228,"hc":-9.5}],"tv":2.17}]}
{"op":"mcm","clk":"997772122","pt":1580582784721,"mc":[{"id":"1.168081835","rc":[{"trd":[[1.02,0.71]],"batb":[[0,1.02,8.46]],"ltp":1.02,"tv":0.71,"id":22229228,"hc":-10.5}],"tv":2.18}]}
{"op":"mcm","clk":"997773346","pt":1580582792505,"mc":[{"id":"1.168081835","rc":[{"batl":[[0,1000,0.02]],"ltp":1.02,"tv":0.74,"id":22229228,"hc":-11.5}]}]}
{"op":"mcm","clk":"997773410","pt":1580582792886,"mc":[{"id":"1.168081835","rc":[{"trd":[[1.02,0.76]],"batb":[[0,1.02,8.43]],"batl":[[0,990,0.01]],"ltp":1.02,"tv":0.75,"id":22229228,"hc":-11.5}],"tv":2.2}]}
{"op":"mcm","clk":"997774116","pt":1580582797406,"mc":[{"id":"1.168081835","rc":[{"trd":[[1.02,0.74]],"batb":[[0,1.02,8.44]],"ltp":1.02,"tv":0.74,"id":22229228,"hc":-9.5}],"tv":2.21}]}
{"op":"mcm","clk":"997774598","pt":1580582800412,"mc":[{"id":"1.168081835","rc":[{"batl":[[0,1000,2.37]],"ltp":1.02,"tv":0.71,"id":22229228,"hc":-10.5}]}]}
{"op":"mcm","clk":"997774699","pt":1580582801011,"mc":[{"id":"1.168081835","rc":[{"trd":[[1.02,0.73]],"batb":[[0,1.02,8.45]],"batl":[[0,990,0.01]],"ltp":1.02,"tv":0.72,"id":22229228,"hc":-10.5}],"tv":2.23}]}
{"op":"mcm","clk":"997776259","pt":1580582809536,"mc":[{"id":"1.168081835","rc":[{"batl":[[0,1000,0.02]],"ltp":1.02,"tv":0.75,"id":22229228,"hc":-11.5}]}]}
{"op":"mcm","clk":"997776335","pt":1580582809912,"mc":[{"id":"1.168081835","rc":[{"trd":[[1.02,0.78]],"batb":[[0,1.02,8.42]],"batl":[[0,990,0.01]],"ltp":1.02,"tv":0.77,"id":22229228,"hc":-11.5}],"tv":2.24}]}
{"op":"mcm","clk":"997776916","pt":1580582813405,"mc":[{"id":"1.168081835","rc":[{"batl":[[0,1000,0.02]],"ltp":1.02,"tv":0.74,"id":22229228,"hc":-9.5}]}]}
{"op":"mcm","clk":"997776982","pt":1580582813830,"mc":[{"id":"1.168081835","rc":[{"trd":[[1.02,0.76]],"batb":[[0,1.02,8.43]],"batl":[[0,990,0.01]],"ltp":1.02,"tv":0.75,"id":22229228,"hc":-9.5}],"tv":2.26}]}
{"op":"mcm","clk":"997777567","pt":1580582817621,"mc":[{"id":"1.168081835","rc":[{"trd":[[1.02,0.74]],"batb":[[0,1.02,8.44]],"ltp":1.02,"tv":0.74,"id":22229228,"hc":-10.5}],"tv":2.27}]}
{"op":"mcm","clk":"997778961","pt":1580582826531,"mc":[{"id":"1.168081835","rc":[{"batl":[[0,1000,2.37]],"ltp":1.02,"tv":0.77,"id":22229228,"hc":-11.5}]}]}
{"op":"mcm","clk":"997779090","pt":1580582827129,"mc":[{"id":"1.168081835","rc":[{"trd":[[1.02,0.79]],"batb":[[0,1.02,8.41]],"batl":[[0,990,0.01]],"ltp":1.02,"tv":0.79,"id":22229228,"hc":-11.5}],"tv":2.29}]}
{"op":"mcm","clk":"997779665","pt":1580582830779,"mc":[{"id":"1.168081835","rc":[{"trd":[[1.02,0.78]],"batb":[[0,1.02,8.42]],"ltp":1.02,"tv":0.77,"id":22229228,"hc":-9.5}],"tv":2.31}]}
{"op":"mcm","clk":"997780220","pt":1580582834431,"mc":[{"id":"1.168081835","rc":[{"trd":[[1.02,0.76]],"batb":[[0,1.02,8.43]],"ltp":1.02,"tv":0.75,"id":22229228,"hc":-10.5}],"tv":2.32}]}
{"op":"mcm","clk":"997781529","pt":1580582842553,"mc":[{"id":"1.168081835","rc":[{"batl":[[0,1000,2.37]],"ltp":1.02,"tv":0.79,"id":22229228,"hc":-11.5}]}]}
{"op":"mcm","clk":"997781632","pt":1580582843184,"mc":[{"id":"1.168081835","rc":[{"trd":[[1.02,0.81]],"batb":[[0,1.02,8.4]],"batl":[[0,990,0.01]],"ltp":1.02,"tv":0.8,"id":22229228,"hc":-11.5}],"tv":2.34}]}
{"op":"mcm","clk":"997782299","pt":1580582847490,"mc":[{"id":"1.168081835","rc":[{"trd":[[1.02,0.79]],"batb":[[0,1.02,8.41]],"ltp":1.02,"tv":0.79,"id":22229228,"hc":-9.5}],"tv":2.35}]}
{"op":"mcm","clk":"997782765","pt":1580582850466,"mc":[{"id":"1.168081835","rc":[{"batl":[[0,1000,2.37]],"ltp":1.02,"tv":0.75,"id":22229228,"hc":-10.5}]}]}
{"op":"mcm","clk":"997782891","pt":1580582851250,"mc":[{"id":"1.168081835","rc":[{"trd":[[1.02,0.78]],"batb":[[0,1.02,8.42]],"batl":[[0,990,0.01]],"ltp":1.02,"tv":0.77,"id":22229228,"hc":-10.5}],"tv":2.37}]}
{"op":"mcm","clk":"997784038","pt":1580582858702,"mc":[{"id":"1.168081835","rc":[{"batl":[[0,1000,2.37]],"ltp":1.02,"tv":0.8,"id":22229228,"hc":-11.5}]}]}
{"op":"mcm","clk":"997784149","pt":1580582859389,"mc":[{"id":"1.168081835","rc":[{"trd":[[1.02,0.82]],"batb":[[0,1.02,8.39]],"batl":[[0,990,0.01]],"ltp":1.02,"tv":0.82,"id":22229228,"hc":-11.5}],"tv":2.38}]}
{"op":"mcm","clk":"997784933","pt":1580582864610,"mc":[{"id":"1.168081835","rc":[{"trd":[[1.02,0.81]],"batb":[[0,1.02,8.4]],"ltp":1.02,"tv":0.8,"id":22229228,"hc":-9.5}],"tv":2.4}]}
{"op":"mcm","clk":"997785339","pt":1580582867503,"mc":[{"id":"1.168081835","rc":[{"batl":[[0,1000,0.02]],"ltp":1.02,"tv":0.77,"id":22229228,"hc":-10.5}]}]}
{"op":"mcm","clk":"997785397","pt":1580582867880,"mc":[{"id":"1.168081835","rc":[{"trd":[[1.02,0.79]],"batb":[[0,1.02,8.41]],"batl":[[0,990,0.01]],"ltp":1.02,"tv":0.79,"id":22229228,"hc":-10.5}],"tv":2.41}]}
{"op":"mcm","clk":"997786394","pt":1580582874611,"mc":[{"id":"1.168081835","rc":[{"batl":[[0,1000,2.37]],"ltp":1.02,"tv":0.82,"id":22229228,"hc":-11.5}]}]}
{"op":"mcm","clk":"997786490","pt":1580582875179,"mc":[{"id":"1.168081835","rc":[{"trd":[[1.02,0.84]],"batb":[[0,1.02,8.38]],"batl":[[0,990,0.01]],"ltp":1.02,"tv":0.83,"id":22229228,"hc":-11.5}],"tv":2.43}]}
{"op":"mcm","clk":"997787510","pt":1580582881706,"mc":[{"id":"1.168081835","rc":[{"trd":[[1.02,0.82]],"batb":[[0,1.02,8.39]],"ltp":1.02,"tv":0.82,"id":22229228,"hc":-9.5}],"tv":2.45}]}
{"op":"mcm","clk":"997787941","pt":1580582884729,"mc":[{"id":"1.168081835","rc":[{"trd":[[1.02,0.81]],"batb":[[0,1.02,8.4]],"ltp":1.02,"tv":0.8,"id":22229228,"hc":-10.5}],"tv":2.46}]}
{"op":"mcm","clk":"997788963","pt":1580582891703,"mc":[{"id":"1.168081835","rc":[{"trd":[[1.02,0.85]],"batb":[[0,1.02,8.37]],"ltp":1.02,"tv":0.85,"id":22229228,"hc":-11.5}],"tv":2.48}]}
{"op":"mcm","clk":"997789932","pt":1580582898439,"mc":[{"id":"1.168081835","rc":[{"trd":[[1.02,0.84]],"batb":[[0,1.02,8.38]],"ltp":1.02,"tv":0.83,"id":22229228,"hc":-9.5}],"tv":2.49}]}
{"op":"mcm","clk":"997790436","pt":1580582901551,"mc":[{"id":"1.168081835","rc":[{"trd":[[1.02,0.82]],"batb":[[0,1.02,8.39]],"ltp":1.02,"tv":0.82,"id":22229228,"hc":-10.5}],"tv":2.51}]}
{"op":"mcm","clk":"997791378","pt":1580582907655,"mc":[{"id":"1.168081835","rc":[{"batl":[[0,1000,0.02]],"ltp":1.02,"tv":0.85,"id":22229228,"hc":-11.5}]}]}
{"op":"mcm","clk":"997791442","pt":1580582908036,"mc":[{"id":"1.168081835","rc":[{"trd":[[1.02,0.87]],"batb":[[0,1.02,8.36]],"batl":[[0,990,0.01]],"ltp":1.02,"tv":0.86,"id":22229228,"hc":-11.5}],"tv":2.52}]}
{"op":"mcm","clk":"997792474","pt":1580582915682,"mc":[{"id":"1.168081835","rc":[{"trd":[[1.02,0.85]],"batb":[[0,1.02,8.37]],"ltp":1.02,"tv":0.85,"id":22229228,"hc":-9.5}],"tv":2.54}]}
{"op":"mcm","clk":"997792880","pt":1580582918377,"mc":[{"id":"1.168081835","rc":[{"trd":[[1.02,0.84]],"batb":[[0,1.02,8.38]],"ltp":1.02,"tv":0.83,"id":22229228,"hc":-10.5}],"tv":2.55}]}
{"op":"mcm","clk":"997793828","pt":1580582924598,"mc":[{"id":"1.168081835","rc":[{"trd":[[1.02,0.88]],"batb":[[0,1.02,8.35]],"ltp":1.02,"tv":0.88,"id":22229228,"hc":-11.5}],"tv":2.57}]}
{"op":"mcm","clk":"997795015","pt":1580582932466,"mc":[{"id":"1.168081835","rc":[{"batl":[[0,1000,0.02]],"ltp":1.02,"tv":0.85,"id":22229228,"hc":-9.5}]}]}
{"op":"mcm","clk":"997795083","pt":1580582932882,"mc":[{"id":"1.168081835","rc":[{"trd":[[1.02,0.87]],"batb":[[0,1.02,8.36]],"batl":[[0,990,0.01]],"ltp":1.02,"tv":0.86,"id":22229228,"hc":-9.5}],"tv":2.58}]}
{"op":"mcm","clk":"997795481","pt":1580582935458,"mc":[{"id":"1.168081835","rc":[{"trd":[[1.02,0.85]],"batb":[[0,1.02,8.37]],"ltp":1.02,"tv":0.85,"id":22229228,"hc":-10.5}],"tv":2.6}]}
{"op":"mcm","clk":"997796288","pt":1580582940524,"mc":[{"id":"1.168081835","rc":[{"batl":[[0,1000,0.02]],"ltp":1.02,"tv":0.88,"id":22229228,"hc":-11.5}]}]}
{"op":"mcm","clk":"997796336","pt":1580582940878,"mc":[{"id":"1.168081835","rc":[{"trd":[[1.02,0.9]],"batb":[[0,1.02,8.34]],"batl":[[0,990,0.01]],"ltp":1.02,"tv":0.89,"id":22229228,"hc":-11.5}],"tv":2.62}]}
{"op":"mcm","clk":"997797450","pt":1580582948598,"mc":[{"id":"1.168081835","rc":[{"batl":[[0,1000,0.02]],"ltp":1.02,"tv":0.86,"id":22229228,"hc":-9.5}]}]}
{"op":"mcm","clk":"997797505","pt":1580582949015,"mc":[{"id":"1.168081835","rc":[{"trd":[[1.02,0.88]],"batb":[[0,1.02,8.35]],"batl":[[0,990,0.01]],"ltp":1.02,"tv":0.88,"id":22229228,"hc":-9.5}],"tv":2.63}]}
{"op":"mcm","clk":"997797916","pt":1580582952580,"mc":[{"id":"1.168081835","rc":[{"batl":[[0,1000,0.02]],"ltp":1.02,"tv":0.85,"id":22229228,"hc":-10.5}]}]}
{"op":"mcm","clk":"997797961","pt":1580582953009,"mc":[{"id":"1.168081835","rc":[{"trd":[[1.02,0.87]],"batb":[[0,1.02,8.36]],"batl":[[0,990,0.01]],"ltp":1.02,"tv":0.86,"id":22229228,"hc":-10.5}],"tv":2.65}]}
{"op":"mcm","clk":"997798523","pt":1580582957408,"mc":[{"id":"1.168081835","rc":[{"trd":[[1.02,0.91]],"batb":[[0,1.02,8.33]],"ltp":1.02,"tv":0.91,"id":22229228,"hc":-11.5}],"tv":2.66}]}
{"op":"mcm","clk":"997799518","pt":1580582965629,"mc":[{"id":"1.168081835","rc":[{"batl":[[0,1000,2.37]],"ltp":1.02,"tv":0.88,"id":22229228,"hc":-9.5}]}]}
{"op":"mcm","clk":"997799600","pt":1580582966316,"mc":[{"id":"1.168081835","rc":[{"trd":[[1.02,0.9]],"batb":[[0,1.02,8.34]],"batl":[[0,990,0.01]],"ltp":1.02,"tv":0.89,"id":22229228,"hc":-9.5}],"tv":2.68}]}
{"op":"mcm","clk":"997800078","pt":1580582970501,"mc":[{"id":"1.168081835","rc":[{"trd":[[1.02,0.88]],"batb":[[0,1.02,8.35]],"ltp":1.02,"tv":0.88,"id":22229228,"hc":-10.5}],"tv":2.69}]}
{"op":"mcm","clk":"997800470","pt":1580582973689,"mc":[{"id":"1.168081835","rc":[{"batl":[[0,1000,0.02]],"ltp":1.02,"tv":0.91,"id":22229228,"hc":-11.5}]}]}
{"op":"mcm","clk":"997800492","pt":1580582973903,"mc":[{"id":"1.168081835","rc":[{"trd":[[1.02,0.93]],"batb":[[0,1.02,8.32]],"batl":[[0,990,0.01]],"ltp":1.02,"tv":0.93,"id":22229228,"hc":-11.5}],"tv":2.71}]}
{"op":"mcm","clk":"997801658","pt":1580582983740,"mc":[{"id":"1.168081835","rc":[{"trd":[[1.02,0.91]],"batb":[[0,1.02,8.33]],"ltp":1.02,"tv":0.91,"id":22229228,"hc":-9.5}],"tv":2.72}]}
{"op":"mcm","clk":"997802097","pt":1580582987432,"mc":[{"id":"1.168081835","rc":[{"batl":[[0,1000,0.02]],"ltp":1.02,"tv":0.88,"id":22229228,"hc":-10.5}]}]}
{"op":"mcm","clk":"997802246","pt":1580582988530,"mc":[{"id":"1.168081835","rc":[{"trd":[[1.02,0.9]],"batb":[[0,1.02,8.34]],"batl":[[0,990,0.01]],"ltp":1.02,"tv":0.89,"id":22229228,"hc":-10.5}],"tv":2.74}]}
{"op":"mcm","clk":"997802547","pt":1580582990556,"mc":[{"id":"1.168081835","rc":[{"trd":[[1.02,0.95]],"batb":[[0,1.02,8.31]],"ltp":1.02,"tv":0.94,"id":22229228,"hc":-11.5}],"tv":2.76}]}
{"op":"mcm","clk":"997803646","pt":1580582999670,"mc":[{"id":"1.168081835","rc":[{"trd":[[1.02,0.93]],"batb":[[0,1.02,8.32]],"ltp":1.02,"tv":0.93,"id":22229228,"hc":-9.5}],"tv":2.77}]}
{"op":"mcm","clk":"997804340","pt":1580583004575,"mc":[{"id":"1.168081835","rc":[{"batl":[[0,1000,2.37]],"ltp":1.02,"tv":0.89,"id":22229228,"hc":-10.5}]}]}
{"op":"mcm","clk":"997804422","pt":1580583005162,"mc":[{"id":"1.168081835","rc":[{"trd":[[1.02,0.91]],"batb":[[0,1.02,8.33]],"batl":[[0,990,0.01]],"ltp":1.02,"tv":0.91,"id":22229228,"hc":-10.5}],"tv":2.79}]}
{"op":"mcm","clk":"997804627","pt":1580583006693,"mc":[{"id":"1.168081835","rc":[{"batl":[[0,1000,0.02]],"ltp":1.02,"tv":0.94,"id":22229228,"hc":-11.5}]}]}
{"op":"mcm","clk":"997804697","pt":1580583007076,"mc":[{"id":"1.168081835","rc":[{"trd":[[1.02,0.96]],"batb":[[0,1.02,8.3]],"batl":[[0,990,0.01]],"ltp":1.02,"tv":0.96,"id":22229228,"hc":-11.5}],"tv":2.8}]}
{"op":"mcm","clk":"997805984","pt":1580583016701,"mc":[{"id":"1.168081835","rc":[{"batl":[[0,1000,0.02]],"ltp":1.02,"tv":0.93,"id":22229228,"hc":-9.5}]}]}
{"op":"mcm","clk":"997806038","pt":1580583017086,"mc":[{"id":"1.168081835","rc":[{"trd":[[1.02,0.95]],"batb":[[0,1.02,8.31]],"batl":[[0,990,0.01]],"ltp":1.02,"tv":0.94,"id":22229228,"hc":-9.5}],"tv":2.82}]}
{"op":"mcm","clk":"997806746","pt":1580583022703,"mc":[{"id":"1.168081835","rc":[{"trd":[[1.02,0.93]],"batb":[[0,1.02,8.32]],"ltp":1.02,"tv":0.93,"id":22229228,"hc":-10.5}],"tv":2.83}]}
{"op":"mcm","clk":"997807009","pt":1580583024601,"mc":[{"id":"1.168081835","rc":[{"trd":[[1.02,0.98]],"batb":[[0,1.02,8.29]],"ltp":1.02,"tv":0.97,"id":22229228,"hc":-11.5}],"tv":2.85}]}
{"op":"mcm","clk":"997808353","pt":1580583034623,"mc":[{"id":"1.168081835","rc":[{"trd":[[1.02,0.96]],"batb":[[0,1.02,8.3]],"ltp":1.02,"tv":0.96,"id":22229228,"hc":-9.5}],"tv":2.86}]}
{"op":"mcm","clk":"997808978","pt":1580583039431,"mc":[{"id":"1.168081835","rc":[{"trd":[[1.02,0.95]],"batb":[[0,1.02,8.31]],"ltp":1.02,"tv":0.94,"id":22229228,"hc":-10.5}],"tv":2.88}]}
{"op":"mcm","clk":"997809128","pt":1580583040501,"mc":[{"id":"1.168081835","rc":[{"trd":[[1.02,0.99]],"batb":[[0,1.02,8.28]],"ltp":1.02,"tv":0.99,"id":22229228,"hc":-11.5}],"tv":2.89}]}
{"op":"mcm","clk":"997810525","pt":1580583050732,"mc":[{"id":"1.168081835","rc":[{"trd":[[1.02,0.98]],"batb":[[0,1.02,8.29]],"ltp":1.02,"tv":0.97,"id":22229228,"hc":-9.5}],"tv":2.91}]}
{"op":"mcm","clk":"997811035","pt":1580583054615,"mc":[{"id":"1.168081835","rc":[{"trd":[[1.02,0.96]],"batb":[[0,1.02,8.3]],"ltp":1.02,"tv":0.96,"id":22229228,"hc":-10.5}],"tv":2.93}]}
{"op":"mcm","clk":"997811429","pt":1580583057738,"mc":[{"id":"1.168081835","rc":[{"trd":[[1.02,1.01]],"batb":[[0,1.02,8.27]],"ltp":1.02,"tv":1.0,"id":22229228,"hc":-11.5}],"tv":2.94}]}
{"op":"mcm","clk":"997812807","pt":1580583068745,"mc":[{"id":"1.168081835","rc":[{"trd":[[1.02,0.99]],"batb":[[0,1.02,8.28]],"ltp":1.02,"tv":0.99,"id":22229228,"hc":-9.5}],"tv":2.96}]}
{"op":"mcm","clk":"997813010","pt":1580583070525,"mc":[{"id":"1.168081835","rc":[{"trd":[[1.02,0.98]],"batb":[[0,1.02,8.29]],"ltp":1.02,"tv":0.97,"id":22229228,"hc":-10.5}],"tv":2.97}]}
{"op":"mcm","clk":"997813524","pt":1580583074452,"mc":[{"id":"1.168081835","rc":[{"trd":[[1.02,1.02]],"batb":[[0,1.02,8.26]],"ltp":1.02,"tv":1.02,"id":22229228,"hc":-11.5}],"tv":2.99}]}
{"op":"mcm","clk":"997815066","pt":1580583086490,"mc":[{"id":"1.168081835","rc":[{"trd":[[1.02,1.01]],"batb":[[0,1.02,8.27]],"ltp":1.02,"tv":1.0,"id":22229228,"hc":-9.5},{"batl":[[0,1000,2.37]],"ltp":1.02,"tv":0.97,"id":22229228,"hc":-10.5}],"tv":3.0}]}
{"op":"mcm","clk":"997815214","pt":1580583087616,"mc":[{"id":"1.168081835","rc":[{"trd":[[1.02,0.99]],"batb":[[0,1.02,8.28]],"batl":[[0,990,0.01]],"ltp":1.02,"tv":0.99,"id":22229228,"hc":-10.5}],"tv":3.02}]}
{"op":"mcm","clk":"997815707","pt":1580583091699,"mc":[{"id":"1.168081835","rc":[{"trd":[[1.02,1.04]],"batb":[[0,1.02,8.25]],"ltp":1.02,"tv":1.03,"id":22229228,"hc":-11.5}],"tv":3.03}]}
{"op":"mcm","clk":"997817038","pt":1580583102721,"mc":[{"id":"1.168081835","rc":[{"trd":[[1.02,1.02]],"batb":[[0,1.02,8.26]],"ltp":1.02,"tv":1.02,"id":22229228,"hc":-9.5}],"tv":3.05}]}
{"op":"mcm","clk":"997817287","pt":1580583104608,"mc":[{"id":"1.168081835","rc":[{"trd":[[1.02,1.01]],"batb":[[0,1.02,8.27]],"ltp":1.02,"tv":1.0,"id":22229228,"hc":-10.5}],"tv":3.07}]}
{"op":"mcm","clk":"997817777","pt":1580583108442,"mc":[{"id":"1.168081835","rc":[{"batl":[[0,1000,0.02]],"ltp":1.02,"tv":1.03,"id":22229228,"hc":-11.5}]}]}
{"op":"mcm","clk":"997817827","pt":1580583108809,"mc":[{"id":"1.168081835","rc":[{"trd":[[1.02,1.05]],"batb":[[0,1.02,8.24]],"batl":[[0,990,0.01]],"ltp":1.02,"tv":1.05,"id":22229228,"hc":-11.5}],"tv":3.08}]}
{"op":"mcm","clk":"997819021","pt":1580583118480,"mc":[{"id":"1.168081835","rc":[{"batl":[[0,1000,2.37]],"ltp":1.02,"tv":1.02,"id":22229228,"hc":-9.5}]}]}
{"op":"mcm","clk":"997819097","pt":1580583119071,"mc":[{"id":"1.168081835","rc":[{"trd":[[1.02,1.04]],"batb":[[0,1.02,8.25]],"batl":[[0,990,0.01]],"ltp":1.02,"tv":1.03,"id":22229228,"hc":-9.5}],"tv":3.1}]}
{"op":"mcm","clk":"997819286","pt":1580583120410,"mc":[{"id":"1.168081835","rc":[{"batl":[[0,1000,2.37]],"ltp":1.02,"tv":1.0,"id":22229228,"hc":-10.5}]}]}
{"op":"mcm","clk":"997819394","pt":1580583121195,"mc":[{"id":"1.168081835","rc":[{"trd":[[1.02,1.02]],"batb":[[0,1.02,8.26]],"batl":[[0,990,0.01]],"ltp":1.02,"tv":1.02,"id":22229228,"hc":-10.5}],"tv":3.11}]}
{"op":"mcm","clk":"997819871","pt":1580583124599,"mc":[{"id":"1.168081835","rc":[{"batl":[[0,1000,0.02]],"ltp":1.02,"tv":1.05,"id":22229228,"hc":-11.5}]}]}
{"op":"mcm","clk":"997819928","pt":1580583124972,"mc":[{"id":"1.168081835","rc":[{"trd":[[1.02,1.07]],"batb":[[0,1.02,8.23]],"batl":[[0,990,0.01]],"ltp":1.02,"tv":1.07,"id":22229228,"hc":-11.5}],"tv":3.13}]}
{"op":"mcm","clk":"997821123","pt":1580583134697,"mc":[{"id":"1.168081835","rc":[{"batl":[[0,1000,0.02]],"ltp":1.02,"tv":1.03,"id":22229228,"hc":-9.5}]}]}
{"op":"mcm","clk":"997821164","pt":1580583135068,"mc":[{"id":"1.168081835","rc":[{"trd":[[1.02,1.05]],"batb":[[0,1.02,8.24]],"batl":[[0,990,0.01]],"ltp":1.02,"tv":1.05,"id":22229228,"hc":-9.5}],"tv":3.14}]}
{"op":"mcm","clk":"997821456","pt":1580583137620,"mc":[{"id":"1.168081835","rc":[{"trd":[[1.02,1.04]],"batb":[[0,1.02,8.25]],"ltp":1.02,"tv":1.03,"id":22229228,"hc":-10.5}],"tv":3.16}]}
{"op":"mcm","clk":"997821945","pt":1580583141512,"mc":[{"id":"1.168081835","rc":[{"batl":[[0,1000,2.37]],"ltp":1.02,"tv":1.07,"id":22229228,"hc":-11.5}]}]}
{"op":"mcm","clk":"997822042","pt":1580583142106,"mc":[{"id":"1.168081835","rc":[{"trd":[[1.02,1.09]],"batb":[[0,1.02,8.22]],"batl":[[0,990,0.01]],"ltp":1.02,"tv":1.08,"id":22229228,"hc":-11.5}],"tv":3.17}]}
{"op":"mcm","clk":"997823200","pt":1580583153647,"mc":[{"id":"1.168081835","rc":[{"batl":[[0,1000,2.37]],"ltp":1.02,"tv":1.05,"id":22229228,"hc":-9.5}]}]}
{"op":"mcm","clk":"997823472","pt":1580583154595,"mc":[{"id":"1.168081835","rc":[{"trd":[[1.02,1.07]],"batb":[[0,1.02,8.23]],"batl":[[0,990,0.01]],"ltp":1.02,"tv":1.07,"id":22229228,"hc":-9.5},{"trd":[[1.02,1.05]],"batb":[[0,1.02,8.24]],"ltp":1.02,"tv":1.05,"id":22229228,"hc":-10.5}],"tv":3.21}]}
{"op":"mcm","clk":"997824071","pt":1580583159488,"mc":[{"id":"1.168081835","rc":[{"trd":[[1.02,1.1]],"batb":[[0,1.02,8.21]],"ltp":1.02,"tv":1.1,"id":22229228,"hc":-11.5}],"tv":3.22}]}
{"op":"mcm","clk":"997825269","pt":1580583169489,"mc":[{"id":"1.168081835","rc":[{"trd":[[1.02,1.09]],"batb":[[0,1.02,8.22]],"ltp":1.02,"tv":1.08,"id":22229228,"hc":-9.5}],"tv":3.24}]}
{"op":"mcm","clk":"997825397","pt":1580583170603,"mc":[{"id":"1.168081835","rc":[{"batl":[[0,1000,2.37]],"ltp":1.02,"tv":1.05,"id":22229228,"hc":-10.5}]}]}
{"op":"mcm","clk":"997825484","pt":1580583171302,"mc":[{"id":"1.168081835","rc":[{"trd":[[1.02,1.07]],"batb":[[0,1.02,8.23]],"batl":[[0,990,0.01]],"ltp":1.02,"tv":1.07,"id":22229228,"hc":-10.5}],"tv":3.25}]}
{"op":"mcm","clk":"997825994","pt":1580583175400,"mc":[{"id":"1.168081835","rc":[{"trd":[[1.02,1.12]],"batb":[[0,1.02,8.2]],"ltp":1.02,"tv":1.11,"id":22229228,"hc":-11.5}],"tv":3.27}]}
{"op":"mcm","clk":"997827196","pt":1580583185620,"mc":[{"id":"1.168081835","rc":[{"batl":[[0,1000,0.02]],"ltp":1.02,"tv":1.08,"id":22229228,"hc":-9.5}]}]}
{"op":"mcm","clk":"997827241","pt":1580583186028,"mc":[{"id":"1.168081835","rc":[{"trd":[[1.02,1.1]],"batb":[[0,1.02,8.21]],"batl":[[0,990,0.01]],"ltp":1.02,"tv":1.1,"id":22229228,"hc":-9.5}],"tv":3.28}]}
{"op":"mcm","clk":"997827426","pt":1580583187626,"mc":[{"id":"1.168081835","rc":[{"batl":[[0,1000,0.02]],"ltp":1.02,"tv":1.07,"id":22229228,"hc":-10.5}]}]}
{"op":"mcm","clk":"997827468","pt":1580583188013,"mc":[{"id":"1.168081835","rc":[{"trd":[[1.02,1.09]],"batb":[[0,1.02,8.22]],"batl":[[0,990,0.01]],"ltp":1.02,"tv":1.08,"id":22229228,"hc":-10.5}],"tv":3.3}]}
{"op":"mcm","clk":"997828004","pt":1580583192716,"mc":[{"id":"1.168081835","rc":[{"trd":[[1.02,1.13]],"batb":[[0,1.02,8.19]],"ltp":1.02,"tv":1.13,"id":22229228,"hc":-11.5}],"tv":3.31}]}
{"op":"mcm","clk":"997829162","pt":1580583202729,"mc":[{"id":"1.168081835","rc":[{"trd":[[1.02,1.12]],"batb":[[0,1.02,8.2]],"ltp":1.02,"tv":1.11,"id":22229228,"hc":-9.5}],"tv":3.33}]}
{"op":"mcm","clk":"997829367","pt":1580583204658,"mc":[{"id":"1.168081835","rc":[{"trd":[[1.02,1.1]],"batb":[[0,1.02,8.21]],"ltp":1.02,"tv":1.1,"id":22229228,"hc":-10.5}],"tv":3.34}]}
{"op":"mcm","clk":"997829988","pt":1580583209649,"mc":[{"id":"1.168081835","rc":[{"batl":[[0,1000,2.37]],"ltp":1.02,"tv":1.13,"id":22229228,"hc":-11.5}]}]}
{"op":"mcm","clk":"997830086","pt":1580583210326,"mc":[{"id":"1.168081835","rc":[{"trd":[[1.02,1.15]],"batb":[[0,1.02,8.18]],"batl":[[0,990,0.01]],"ltp":1.02,"tv":1.14,"id":22229228,"hc":-11.5}],"tv":3.36}]}
{"op":"mcm","clk":"997831114","pt":1580583219556,"mc":[{"id":"1.168081835","rc":[{"trd":[[1.02,1.13]],"batb":[[0,1.02,8.19]],"ltp":1.02,"tv":1.13,"id":22229228,"hc":-9.5}],"tv":3.38}]}
{"op":"mcm","clk":"997831325","pt":1580583221553,"mc":[{"id":"1.168081835","rc":[{"trd":[[1.02,1.12]],"batb":[[0,1.02,8.2]],"ltp":1.02,"tv":1.11,"id":22229228,"hc":-10.5}],"tv":3.39}]}
{"op":"mcm","clk":"997831798","pt":1580583225676,"mc":[{"id":"1.168081835","rc":[{"batl":[[0,1000,2.37]],"ltp":1.02,"tv":1.14,"id":22229228,"hc":-11.5}]}]}
{"op":"mcm","clk":"997831884","pt":1580583226368,"mc":[{"id":"1.168081835","rc":[{"trd":[[1.02,1.16]],"batb":[[0,1.02,8.17]],"batl":[[0,990,0.01]],"ltp":1.02,"tv":1.16,"id":22229228,"hc":-11.5}],"tv":3.41}]}
{"op":"mcm","clk":"997833064","pt":1580583236576,"mc":[{"id":"1.168081835","rc":[{"trd":[[1.02,1.15]],"batb":[[0,1.02,8.18]],"ltp":1.02,"tv":1.14,"id":22229228,"hc":-9.5}],"tv":3.42}]}
{"op":"mcm","clk":"997833337","pt":1580583238784,"mc":[{"id":"1.168081835","rc":[{"trd":[[1.02,1.13]],"batb":[[0,1.02,8.19]],"ltp":1.02,"tv":1.13,"id":22229228,"hc":-10.5}],"tv":3.44}]}
{"op":"mcm","clk":"997833709","pt":1580583241607,"mc":[{"id":"1.168081835","rc":[{"batl":[[0,1000,2.37]],"ltp":1.02,"tv":1.16,"id":22229228,"hc":-11.5}]}]}
{"op":"mcm","clk":"997833814","pt":1580583242409,"mc":[{"id":"1.168081835","rc":[{"trd":[[1.02,1.18]],"batb":[[0,1.02,8.16]],"batl":[[0,990,0.01]],"ltp":1.02,"tv":1.17,"id":22229228,"hc":-11.5}],"tv":3.45}]}
{"op":"mcm","clk":"997835324","pt":1580583253530,"mc":[{"id":"1.168081835","rc":[{"trd":[[1.02,1.16]],"batb":[[0,1.02,8.17]],"ltp":1.02,"tv":1.16,"id":22229228,"hc":-9.5}],"tv":3.47}]}
{"op":"mcm","clk":"997835595","pt":1580583255420,"mc":[{"id":"1.168081835","rc":[{"batl":[[0,1000,0.02]],"ltp":1.02,"tv":1.13,"id":22229228,"hc":-10.5}]}]}
{"op":"mcm","clk":"997835664","pt":1580583255946,"mc":[{"id":"1.168081835","rc":[{"trd":[[1.02,1.15]],"batb":[[0,1.02,8.18]],"batl":[[0,990,0.01]],"ltp":1.02,"tv":1.14,"id":22229228,"hc":-10.5}],"tv":3.48}]}
{"op":"mcm","clk":"997835990","pt":1580583258348,"mc":[{"id":"1.168081835","rc":[{"trd":[[1.02,1.19]],"batb":[[0,1.02,8.15]],"ltp":1.02,"tv":1.19,"id":22229228,"hc":-11.5}],"tv":3.5}]}
{"op":"mcm","clk":"997837557","pt":1580583270464,"mc":[{"id":"1.168081835","rc":[{"trd":[[1.02,1.18]],"batb":[[0,1.02,8.16]],"ltp":1.02,"tv":1.17,"id":22229228,"hc":-9.5}],"tv":3.52}]}
{"op":"mcm","clk":"997837790","pt":1580583272480,"mc":[{"id":"1.168081835","rc":[{"batl":[[0,1000,2.37]],"ltp":1.02,"tv":1.14,"id":22229228,"hc":-10.5}]}]}
{"op":"mcm","clk":"997837866","pt":1580583273177,"mc":[{"id":"1.168081835","rc":[{"trd":[[1.02,1.16]],"batb":[[0,1.02,8.17]],"batl":[[0,990,0.01]],"ltp":1.02,"tv":1.16,"id":22229228,"hc":-10.5}],"tv":3.53}]}
{"op":"mcm","clk":"997838066","pt":1580583274769,"mc":[{"id":"1.168081835","rc":[{"trd":[[1.02,1.21]],"batb":[[0,1.02,8.14]],"ltp":1.02,"tv":1.2,"id":22229228,"hc":-11.5}],"tv":3.55}]}
{"op":"mcm","clk":"997839658","pt":1580583287515,"mc":[{"id":"1.168081835","rc":[{"trd":[[1.02,1.19]],"batb":[[0,1.02,8.15]],"ltp":1.02,"tv":1.19,"id":22229228,"hc":-9.5}],"tv":3.56}]}
{"op":"mcm","clk":"997839972","pt":1580583289625,"mc":[{"id":"1.168081835","rc":[{"batl":[[0,1000,2.37]],"ltp":1.02,"tv":1.16,"id":22229228,"hc":-10.5}]}]}
{"op":"mcm","clk":"997840076","pt":1580583290418,"mc":[{"id":"1.168081835","rc":[{"trd":[[1.02,1.18]],"batb":[[0,1.02,8.16]],"batl":[[0,990,0.01]],"ltp":1.02,"tv":1.17,"id":22229228,"hc":-10.5},{"batl":[[0,1000,2.37]],"ltp":1.02,"tv":1.2,"id":22229228,"hc":-11.5}],"tv":3.58}]}
{"op":"mcm","clk":"997840251","pt":1580583291646,"mc":[{"id":"1.168081835","rc":[{"trd":[[1.02,1.23]],"batb":[[0,1.02,8.13]],"batl":[[0,990,0.01]],"ltp":1.02,"tv":1.22,"id":22229228,"hc":-11.5}],"tv":3.59}]}
{"op":"mcm","clk":"997841964","pt":1580583304442,"mc":[{"id":"1.168081835","rc":[{"batl":[[0,1000,0.02]],"ltp":1.02,"tv":1.19,"id":22229228,"hc":-9.5}]}]}
{"op":"mcm","clk":"997842013","pt":1580583304821,"mc":[{"id":"1.168081835","rc":[{"trd":[[1.02,1.21]],"batb":[[0,1.02,8.14]],"batl":[[0,990,0.01]],"ltp":1.02,"tv":1.2,"id":22229228,"hc":-9.5}],"tv":3.61}]}
{"op":"mcm","clk":"997842412","pt":1580583307652,"mc":[{"id":"1.168081835","rc":[{"trd":[[1.02,1.19]],"batb":[[0,1.02,8.15]],"ltp":1.02,"tv":1.19,"id":22229228,"hc":-10.5},{"trd":[[1.02,1.24]],"batb":[[0,1.02,8.12]],"ltp":1.02,"tv":1.24,"id":22229228,"hc":-11.5}],"tv":3.64}]}
{"op":"mcm","clk":"997843968","pt":1580583321464,"mc":[{"id":"1.168081835","rc":[{"batl":[[0,1000,0.02]],"ltp":1.02,"tv":1.2,"id":22229228,"hc":-9.5}]}]}
{"op":"mcm","clk":"997844013","pt":1580583321839,"mc":[{"id":"1.168081835","rc":[{"trd":[[1.02,1.23]],"batb":[[0,1.02,8.13]],"batl":[[0,990,0.01]],"ltp":1.02,"tv":1.22,"id":22229228,"hc":-9.5}],"tv":3.65}]}
{"op":"mcm","clk":"997844237","pt":1580583323570,"mc":[{"id":"1.168081835","rc":[{"batl":[[0,1000,0.02]],"ltp":1.02,"tv":1.24,"id":22229228,"hc":-11.5}]}]}
{"op":"mcm","clk":"997844354","pt":1580583324549,"mc":[{"id":"1.168081835","rc":[{"batl":[[0,1000,0.02]],"ltp":1.02,"tv":1.19,"id":22229228,"hc":-10.5},{"trd":[[1.02,1.26]],"batb":[[0,1.02,8.11]],"batl":[[0,990,0.01]],"ltp":1.02,"tv":1.25,"id":22229228,"hc":-11.5}],"tv":3.67}]}
{"op":"mcm","clk":"997844409","pt":1580583324960,"mc":[{"id":"1.168081835","rc":[{"trd":[[1.02,1.21]],"batb":[[0,1.02,8.14]],"batl":[[0,990,0.01]],"ltp":1.02,"tv":1.2,"id":22229228,"hc":-10.5}],"tv":3.69}]}
{"op":"mcm","clk":"997845825","pt":1580583337496,"mc":[{"id":"1.168081835","rc":[{"batl":[[0,1000,0.02]],"ltp":1.02,"tv":1.22,"id":22229228,"hc":-9.5}]}]}
{"op":"mcm","clk":"997845876","pt":1580583337859,"mc":[{"id":"1.168081835","rc":[{"trd":[[1.02,1.24]],"batb":[[0,1.02,8.12]],"batl":[[0,990,0.01]],"ltp":1.02,"tv":1.24,"id":22229228,"hc":-9.5}],"tv":3.7}]}
{"op":"mcm","clk":"997846230","pt":1580583340701,"mc":[{"id":"1.168081835","rc":[{"trd":[[1.02,1.27]],"batb":[[0,1.02,8.1]],"ltp":1.02,"tv":1.27,"id":22229228,"hc":-11.5}],"tv":3.72}]}
{"op":"mcm","clk":"997846428","pt":1580583342257,"mc":[{"id":"1.168081835","rc":[{"trd":[[1.02,1.23]],"batb":[[0,1.02,8.13]],"ltp":1.02,"tv":1.22,"id":22229228,"hc":-10.5}],"tv":3.73}]}
{"op":"mcm","clk":"997848105","pt":1580583355598,"mc":[{"id":"1.168081835","rc":[{"trd":[[1.02,1.26]],"batb":[[0,1.02,8.11]],"ltp":1.02,"tv":1.25,"id":22229228,"hc":-9.5}],"tv":3.75}]}
{"op":"mcm","clk":"997848308","pt":1580583357204,"mc":[{"id":"1.168081835","rc":[{"trd":[[1.02,1.29]],"batb":[[0,1.02,8.09]],"ltp":1.02,"tv":1.28,"id":22229228,"hc":-11.5}],"tv":3.76}]}
{"op":"mcm","clk":"997848596","pt":1580583359627,"mc":[{"id":"1.168081835","rc":[{"trd":[[1.02,1.24]],"batb":[[0,1.02,8.12]],"ltp":1.02,"tv":1.24,"id":22229228,"hc":-10.5}],"tv":3.78}]}
{"op":"mcm","clk":"997850207","pt":1580583372658,"mc":[{"id":"1.168081835","rc":[{"batl":[[0,1000,0.02]],"ltp":1.02,"tv":1.25,"id":22229228,"hc":-9.5}]}]}
{"op":"mcm","clk":"997850347","pt":1580583373662,"mc":[{"id":"1.168081835","rc":[{"trd":[[1.02,1.27]],"batb":[[0,1.02,8.1]],"batl":[[0,990,0.01]],"ltp":1.02,"tv":1.27,"id":22229228,"hc":-9.5},{"batl":[[0,1000,0.02]],"ltp":1.02,"tv":1.28,"id":22229228,"hc":-11.5}],"tv":3.79}]}
{"op":"mcm","clk":"997850401","pt":1580583374041,"mc":[{"id":"1.168081835","rc":[{"trd":[[1.02,1.3]],"batb":[[0,1.02,8.08]],"batl":[[0,990,0.01]],"ltp":1.02,"tv":1.3,"id":22229228,"hc":-11.5}],"tv":3.81}]}
{"op":"mcm","clk":"997850589","pt":1580583375587,"mc":[{"id":"1.168081835","rc":[{"batl":[[0,1000,0.02]],"ltp":1.02,"tv":1.24,"id":22229228,"hc":-10.5}]}]}
{"op":"mcm","clk":"997850735","pt":1580583376694,"mc":[{"id":"1.168081835","rc":[{"trd":[[1.02,1.26]],"batb":[[0,1.02,8.11]],"batl":[[0,990,0.01]],"ltp":1.02,"tv":1.25,"id":22229228,"hc":-10.5}],"tv":3.83}]}
{"op":"mcm","clk":"997852402","pt":1580583390690,"mc":[{"id":"1.168081835","rc":[{"trd":[[1.02,1.29]],"batb":[[0,1.02,8.09]],"ltp":1.02,"tv":1.28,"id":22229228,"hc":-9.5},{"trd":[[1.02,1.32]],"batb":[[0,1.02,8.07]],"ltp":1.02,"tv":1.31,"id":22229228,"hc":-11.5}],"tv":3.86}]}
{"op":"mcm","clk":"997852759","pt":1580583393588,"mc":[{"id":"1.168081835","rc":[{"trd":[[1.02,1.27]],"batb":[[0,1.02,8.1]],"ltp":1.02,"tv":1.27,"id":22229228,"hc":-10.5}],"tv":3.87}]}
{"op":"mcm","clk":"997854421","pt":1580583407663,"mc":[{"id":"1.168081835","rc":[{"batl":[[0,1000,2.37]],"ltp":1.02,"tv":1.28,"id":22229228,"hc":-9.5}]}]}
{"op":"mcm","clk":"997854493","pt":1580583408148,"mc":[{"id":"1.168081835","rc":[{"trd":[[1.02,1.3]],"batb":[[0,1.02,8.08]],"batl":[[0,990,0.01]],"ltp":1.02,"tv":1.3,"id":22229228,"hc":-9.5},{"trd":[[1.02,1.33]],"batb":[[0,1.02,8.06]],"ltp":1.02,"tv":1.33,"id":22229228,"hc":-11.5}],"tv":3.9}]}
{"op":"mcm","clk":"997854775","pt":1580583410558,"mc":[{"id":"1.168081835","rc":[{"batl":[[0,1000,2.37]],"ltp":1.02,"tv":1.27,"id":22229228,"hc":-10.5}]}]}
{"op":"mcm","clk":"997854907","pt":1580583411542,"mc":[{"id":"1.168081835","rc":[{"trd":[[1.02,1.29]],"batb":[[0,1.02,8.09]],"batl":[[0,990,0.01]],"ltp":1.02,"tv":1.28,"id":22229228,"hc":-10.5}],"tv":3.92}]}
{"op":"mcm","clk":"997856428","pt":1580583424673,"mc":[{"id":"1.168081835","rc":[{"trd":[[1.02,1.35]],"batb":[[0,1.02,8.05]],"ltp":1.02,"tv":1.34,"id":22229228,"hc":-11.5}],"tv":3.93}]}
{"op":"mcm","clk":"997856546","pt":1580583425682,"mc":[{"id":"1.168081835","rc":[{"trd":[[1.02,1.32]],"batb":[[0,1.02,8.07]],"ltp":1.02,"tv":1.31,"id":22229228,"hc":-9.5}],"tv":3.95}]}
{"op":"mcm","clk":"997856886","pt":1580583428699,"mc":[{"id":"1.168081835","rc":[{"batl":[[0,1000,0.02]],"ltp":1.02,"tv":1.28,"id":22229228,"hc":-10.5}]}]}
{"op":"mcm","clk":"997856995","pt":1580583429551,"mc":[{"id":"1.168081835","rc":[{"trd":[[1.02,1.3]],"batb":[[0,1.02,8.08]],"batl":[[0,990,0.01]],"ltp":1.02,"tv":1.3,"id":22229228,"hc":-10.5}],"tv":3.96}]}
{"op":"mcm","clk":"997858295","pt":1580583441647,"mc":[{"id":"1.168081835","rc":[{"batl":[[0,1000,0.02]],"ltp":1.02,"tv":1.31,"id":22229228,"hc":-9.5},{"trd":[[1.02,1.36]],"batb":[[0,1.02,8.04]],"ltp":1.02,"tv":1.36,"id":22229228,"hc":-11.5}],"tv":3.98}]}
{"op":"mcm","clk":"997858352","pt":1580583442081,"mc":[{"id":"1.168081835","rc":[{"trd":[[1.02,1.33]],"batb":[[0,1.02,8.06]],"batl":[[0,990,0.01]],"ltp":1.02,"tv":1.33,"id":22229228,"hc":-9.5}],"tv":4.0}]}
{"op":"mcm","clk":"997858629","pt":1580583444655,"mc":[{"id":"1.168081835","rc":[{"batl":[[0,1000,2.37]],"ltp":1.02,"tv":1.3,"id":22229228,"hc":-10.5}]}]}
{"op":"mcm","clk":"997858763","pt":1580583445677,"mc":[{"id":"1.168081835","rc":[{"trd":[[1.02,1.32]],"batb":[[0,1.02,8.07]],"batl":[[0,990,0.01]],"ltp":1.02,"tv":1.31,"id":22229228,"hc":-10.5}],"tv":4.01}]}
{"op":"mcm","clk":"997860125","pt":1580583457562,"mc":[{"id":"1.168081835","rc":[{"batl":[[0,1000,2.37]],"ltp":1.02,"tv":1.33,"id":22229228,"hc":-9.5}]}]}
{"op":"mcm","clk":"997860264","pt":1580583458683,"mc":[{"id":"1.168081835","rc":[{"trd":[[1.02,1.35]],"batb":[[0,1.02,8.05]],"batl":[[0,990,0.01]],"ltp":1.02,"tv":1.34,"id":22229228,"hc":-9.5},{"trd":[[1.02,1.38]],"batb":[[0,1.02,8.03]],"ltp":1.02,"tv":1.38,"id":22229228,"hc":-11.5}],"tv":4.04}]}
{"op":"mcm","clk":"997860615","pt":1580583461565,"mc":[{"id":"1.168081835","rc":[{"batl":[[0,1000,0.02]],"ltp":1.02,"tv":1.31,"id":22229228,"hc":-10.5}]}]}
{"op":"mcm","clk":"997860705","pt":1580583462199,"mc":[{"id":"1.168081835","rc":[{"trd":[[1.02,1.33]],"batb":[[0,1.02,8.06]],"batl":[[0,990,0.01]],"ltp":1.02,"tv":1.33,"id":22229228,"hc":-10.5}],"tv":4.06}]}
{"op":"mcm","clk":"997862255","pt":1580583475652,"mc":[{"id":"1.168081835","rc":[{"trd":[[1.02,1.36]],"batb":[[0,1.02,8.04]],"ltp":1.02,"tv":1.36,"id":22229228,"hc":-9.5},{"trd":[[1.02,1.4]],"batb":[[0,1.02,8.02]],"ltp":1.02,"tv":1.39,"id":22229228,"hc":-11.5}],"tv":4.09}]}
{"op":"mcm","clk":"997862459","pt":1580583477535,"mc":[{"id":"1.168081835","rc":[{"batl":[[0,1000,2.37]],"ltp":1.02,"tv":1.33,"id":22229228,"hc":-10.5}]}]}
{"op":"mcm","clk":"997862533","pt":1580583478173,"mc":[{"id":"1.168081835","rc":[{"trd":[[1.02,1.35]],"batb":[[0,1.02,8.05]],"batl":[[0,990,0.01]],"ltp":1.02,"tv":1.34,"id":22229228,"hc":-10.5}],"tv":4.1}]}
{"op":"mcm","clk":"997864215","pt":1580583491667,"mc":[{"id":"1.168081835","rc":[{"batl":[[0,1000,0.02]],"ltp":1.02,"tv":1.36,"id":22229228,"hc":-9.5}]}]}
{"op":"mcm","clk":"997864361","pt":1580583492667,"mc":[{"id":"1.168081835","rc":[{"trd":[[1.02,1.38]],"batb":[[0,1.02,8.03]],"batl":[[0,990,0.01]],"ltp":1.02,"tv":1.38,"id":22229228,"hc":-9.5}],"tv":4.12}]}
{"op":"mcm","clk":"997864377","pt":1580583492771,"mc":[{"id":"1.168081835","rc":[{"trd":[[1.02,1.41]],"batb":[[0,1.02,8.01]],"ltp":1.02,"tv":1.41,"id":22229228,"hc":-11.5}],"tv":4.14}]}
{"op":"mcm","clk":"997864582","pt":1580583494575,"mc":[{"id":"1.168081835","rc":[{"trd":[[1.02,1.36]],"batb":[[0,1.02,8.04]],"ltp":1.02,"tv":1.36,"id":22229228,"hc":-10.5}],"tv":4.15}]}
{"op":"mcm","clk":"997866212","pt":1580583508374,"mc":[{"id":"1.168081835","rc":[{"trd":[[1.02,1.4]],"batb":[[0,1.02,8.02]],"ltp":1.02,"tv":1.39,"id":22229228,"hc":-9.5}],"tv":4.17}]}
{"op":"mcm","clk":"997866370","pt":1580583509683,"mc":[{"id":"1.168081835","rc":[{"batl":[[0,1000,2.37]],"ltp":1.02,"tv":1.41,"id":22229228,"hc":-11.5}]}]}
{"op":"mcm","clk":"997866497","pt":1580583510602,"mc":[{"id":"1.168081835","rc":[{"batl":[[0,1000,0.02]],"ltp":1.02,"tv":1.36,"id":22229228,"hc":-10.5},{"trd":[[1.02,1.43]],"batb":[[0,1.02,8]],"batl":[[0,990,0.01]],"ltp":1.02,"tv":1.42,"id":22229228,"hc":-11.5}],"tv":4.18}]}
{"op":"mcm","clk":"997866549","pt":1580583510977,"mc":[{"id":"1.168081835","rc":[{"trd":[[1.02,1.38]],"batb":[[0,1.02,8.03]],"batl":[[0,990,0.01]],"ltp":1.02,"tv":1.38,"id":22229228,"hc":-10.5}],"tv":4.2}]}
{"op":"mcm","clk":"997868185","pt":1580583524546,"mc":[{"id":"1.168081835","rc":[{"batl":[[0,1000,0.02]],"ltp":1.02,"tv":1.39,"id":22229228,"hc":-9.5}]}]}
{"op":"mcm","clk":"997868235","pt":1580583524928,"mc":[{"id":"1.168081835","rc":[{"trd":[[1.02,1.41]],"batb":[[0,1.02,8.01]],"batl":[[0,990,0.01]],"ltp":1.02,"tv":1.41,"id":22229228,"hc":-9.5}],"tv":4.21}]}
{"op":"mcm","clk":"997868543","pt":1580583527537,"mc":[{"id":"1.168081835","rc":[{"trd":[[1.02,1.4]],"batb":[[0,1.02,8.02]],"ltp":1.02,"tv":1.39,"id":22229228,"hc":-10.5},{"trd":[[1.02,1.44]],"batb":[[0,1.02,7.99]],"ltp":1.02,"tv":1.44,"id":22229228,"hc":-11.5}],"tv":4.24}]}
{"op":"mcm","clk":"997870268","pt":1580583541574,"mc":[{"id":"1.168081835","rc":[{"batl":[[0,1000,0.02]],"ltp":1.02,"tv":1.41,"id":22229228,"hc":-9.5}]}]}
{"op":"mcm","clk":"997870306","pt":1580583541918,"mc":[{"id":"1.168081835","rc":[{"trd":[[1.02,1.43]],"batb":[[0,1.02,8]],"batl":[[0,990,0.01]],"ltp":1.02,"tv":1.42,"id":22229228,"hc":-9.5}],"tv":4.26}]}
{"op":"mcm","clk":"997870533","pt":1580583543672,"mc":[{"id":"1.168081835","rc":[{"batl":[[0,1000,2.37]],"ltp":1.02,"tv":1.39,"id":22229228,"hc":-10.5}]}]}
{"op":"mcm","clk":"997870683","pt":1580583544683,"mc":[{"id":"1.168081835","rc":[{"trd":[[1.02,1.41]],"batb":[[0,1.02,8.01]],"batl":[[0,990,0.01]],"ltp":1.02,"tv":1.41,"id":22229228,"hc":-10.5}],"tv":4.28}]}
{"op":"mcm","clk":"997870821","pt":1580583545696,"mc":[{"id":"1.168081835","rc":[{"trd":[[1.02,1.46]],"batb":[[0,1.02,7.98]],"ltp":1.02,"tv":1.45,"id":22229228,"hc":-11.5}],"tv":4.29}]}
{"op":"mcm","clk":"997872513","pt":1580583558614,"mc":[{"id":"1.168081835","rc":[{"trd":[[1.02,1.44]],"batb":[[0,1.02,7.99]],"ltp":1.02,"tv":1.44,"id":22229228,"hc":-9.5}],"tv":4.31}]}
{"op":"mcm","clk":"997872756","pt":1580583560415,"mc":[{"id":"1.168081835","rc":[{"batl":[[0,1000,0.02]],"ltp":1.02,"tv":1.41,"id":22229228,"hc":-10.5}]}]}
{"op":"mcm","clk":"997872907","pt":1580583561630,"mc":[{"id":"1.168081835","rc":[{"trd":[[1.02,1.43]],"batb":[[0,1.02,8]],"batl":[[0,990,0.01]],"ltp":1.02,"tv":1.42,"id":22229228,"hc":-10.5},{"batl":[[0,1000,2.37]],"ltp":1.02,"tv":1.45,"id":22229228,"hc":-11.5}],"tv":4.32}]}
{"op":"mcm","clk":"997872986","pt":1580583562098,"mc":[{"id":"1.168081835","rc":[{"trd":[[1.02,1.47]],"batb":[[0,1.02,7.97]],"batl":[[0,990,0.01]],"ltp":1.02,"tv":1.47,"id":22229228,"hc":-11.5}],"tv":4.34}]}
{"op":"mcm","clk":"997874646","pt":1580583574629,"mc":[{"id":"1.168081835","rc":[{"batl":[[0,1000,2.37]],"ltp":1.02,"tv":1.44,"id":22229228,"hc":-9.5}]}]}
{"op":"mcm","clk":"997874725","pt":1580583575165,"mc":[{"id":"1.168081835","rc":[{"trd":[[1.02,1.46]],"batb":[[0,1.02,7.98]],"batl":[[0,990,0.01]],"ltp":1.02,"tv":1.45,"id":22229228,"hc":-9.5}],"tv":4.35}]}
{"op":"mcm","clk":"997875012","pt":1580583577375,"mc":[{"id":"1.168081835","rc":[{"trd":[[1.02,1.44]],"batb":[[0,1.02,7.99]],"ltp":1.02,"tv":1.44,"id":22229228,"hc":-10.5}],"tv":4.37}]}
{"op":"mcm","clk":"997875377","pt":1580583579725,"mc":[{"id":"1.168081835","rc":[{"trd":[[1.02,1.49]],"batb":[[0,1.02,7.96]],"ltp":1.02,"tv":1.48,"id":22229228,"hc":-11.5}],"tv":4.38}]}
{"op":"mcm","clk":"997876840","pt":1580583591553,"mc":[{"id":"1.168081835","rc":[{"batl":[[0,1000,0.02]],"ltp":1.02,"tv":1.45,"id":22229228,"hc":-9.5}]}]}
{"op":"mcm","clk":"997876876","pt":1580583591872,"mc":[{"id":"1.168081835","rc":[{"trd":[[1.02,1.47]],"batb":[[0,1.02,7.97]],"batl":[[0,990,0.01]],"ltp":1.02,"tv":1.47,"id":22229228,"hc":-9.5}],"tv":4.4}]}
{"op":"mcm","clk":"997877121","pt":1580583593746,"mc":[{"id":"1.168081835","rc":[{"trd":[[1.02,1.46]],"batb":[[0,1.02,7.98]],"ltp":1.02,"tv":1.45,"id":22229228,"hc":-10.5}],"tv":4.41}]}
{"op":"mcm","clk":"997877490","pt":1580583596600,"mc":[{"id":"1.168081835","rc":[{"batl":[[0,1000,2.37]],"ltp":1.02,"tv":1.48,"id":22229228,"hc":-11.5}]}]}
{"op":"mcm","clk":"997877570","pt":1580583597145,"mc":[{"id":"1.168081835","rc":[{"trd":[[1.02,1.5]],"batb":[[0,1.02,7.95]],"batl":[[0,990,0.01]],"ltp":1.02,"tv":1.5,"id":22229228,"hc":-11.5}],"tv":4.43}]}
{"op":"mcm","clk":"997879290","pt":1580583609047,"mc":[{"id":"1.168081835","rc":[{"trd":[[1.02,1.49]],"batb":[[0,1.02,7.96]],"ltp":1.02,"tv":1.48,"id":22229228,"hc":-9.5}],"tv":4.45}]}
{"op":"mcm","clk":"997879611","pt":1580583610929,"mc":[{"id":"1.168081835","rc":[{"trd":[[1.02,1.47]],"batb":[[0,1.02,7.97]],"ltp":1.02,"tv":1.47,"id":22229228,"hc":-10.5}],"tv":4.46}]}
{"op":"mcm","clk":"997880053","pt":1580583615457,"mc":[{"id":"1.168081835","rc":[{"trd":[[1.02,1.52]],"batb":[[0,1.02,7.94]],"ltp":1.02,"tv":1.51,"id":22229228,"hc":-11.5}],"tv":4.48}]}
{"op":"mcm","clk":"997881491","pt":1580583624103,"mc":[{"id":"1.168081835","rc":[{"batl":[[0,1000,2.37]],"ltp":1.02,"tv":1.48,"id":22229228,"hc":-9.5}]}]}
{"op":"mcm","clk":"997881566","pt":1580583625055,"mc":[{"id":"1.168081835","rc":[{"trd":[[1.02,1.5]],"batb":[[0,1.02,7.95]],"batl":[[0,990,0.01]],"ltp":1.02,"tv":1.5,"id":22229228,"hc":-9.5}],"tv":4.49}]}
{"op":"mcm","clk":"997881800","pt":1580583626602,"mc":[{"id":"1.168081835","rc":[{"batl":[[0,1000,2.37]],"ltp":1.02,"tv":1.47,"id":22229228,"hc":-10.5}]}]}
{"op":"mcm","clk":"997881875","pt":1580583627193,"mc":[{"id":"1.168081835","rc":[{"trd":[[1.02,1.49]],"batb":[[0,1.02,7.96]],"batl":[[0,990,0.01]],"ltp":1.02,"tv":1.48,"id":22229228,"hc":-10.5}],"tv":4.51}]}
{"op":"mcm","clk":"997882203","pt":1580583629502,"mc":[{"id":"1.168081835","rc":[{"trd":[[1.02,1.54]],"batb":[[0,1.02,7.93]],"ltp":1.02,"tv":1.53,"id":22229228,"hc":-11.5}],"tv":4.52}]}
{"op":"mcm","clk":"997883636","pt":1580583641232,"mc":[{"id":"1.168081835","rc":[{"trd":[[1.02,1.52]],"batb":[[0,1.02,7.94]],"ltp":1.02,"tv":1.51,"id":22229228,"hc":-9.5}],"tv":4.54}]}
{"op":"mcm","clk":"997883884","pt":1580583643363,"mc":[{"id":"1.168081835","rc":[{"trd":[[1.02,1.5]],"batb":[[0,1.02,7.95]],"ltp":1.02,"tv":1.5,"id":22229228,"hc":-10.5}],"tv":4.55}]}
{"op":"mcm","clk":"997884201","pt":1580583645773,"mc":[{"id":"1.168081835","rc":[{"trd":[[1.02,1.55]],"batb":[[0,1.02,7.92]],"ltp":1.02,"tv":1.55,"id":22229228,"hc":-11.5}],"tv":4.57}]}
{"op":"mcm","clk":"997885575","pt":1580583657679,"mc":[{"id":"1.168081835","rc":[{"trd":[[1.02,1.54]],"batb":[[0,1.02,7.93]],"ltp":1.02,"tv":1.53,"id":22229228,"hc":-9.5}],"tv":4.59}]}
{"op":"mcm","clk":"997885817","pt":1580583659596,"mc":[{"id":"1.168081835","rc":[{"batl":[[0,1000,0.02]],"ltp":1.02,"tv":1.5,"id":22229228,"hc":-10.5}]}]}
{"op":"mcm","clk":"997885860","pt":1580583659865,"mc":[{"id":"1.168081835","rc":[{"trd":[[1.02,1.52]],"batb":[[0,1.02,7.94]],"batl":[[0,990,0.01]],"ltp":1.02,"tv":1.51,"id":22229228,"hc":-10.5}],"tv":4.6}]}
{"op":"mcm","clk":"997886107","pt":1580583661562,"mc":[{"id":"1.168081835","rc":[{"trd":[[1.02,1.57]],"batb":[[0,1.02,7.91]],"ltp":1.02,"tv":1.56,"id":22229228,"hc":-11.5}],"tv":4.62}]}
{"op":"mcm","clk":"997887830","pt":1580583673407,"mc":[{"id":"1.168081835","rc":[{"trd":[[1.02,1.55]],"batb":[[0,1.02,7.92]],"ltp":1.02,"tv":1.55,"id":22229228,"hc":-9.5}],"tv":4.63}]}
{"op":"mcm","clk":"997888528","pt":1580583677421,"mc":[{"id":"1.168081835","rc":[{"trd":[[1.02,1.54]],"batb":[[0,1.02,7.93]],"ltp":1.02,"tv":1.53,"id":22229228,"hc":-10.5},{"batl":[[0,1000,2.37]],"ltp":1.02,"tv":1.56,"id":22229228,"hc":-11.5}],"tv":4.65}]}
{"op":"mcm","clk":"997888733","pt":1580583678509,"mc":[{"id":"1.168081835","rc":[{"trd":[[1.02,1.58]],"batb":[[0,1.02,7.9]],"batl":[[0,990,0.01]],"ltp":1.02,"tv":1.58,"id":22229228,"hc":-11.5}],"tv":4.66}]}
{"op":"mcm","clk":"997890328","pt":1580583689538,"mc":[{"id":"1.168081835","rc":[{"trd":[[1.02,1.57]],"batb":[[0,1.02,7.91]],"ltp":1.02,"tv":1.56,"id":22229228,"hc":-9.5}],"tv":4.68}]}
{"op":"mcm","clk":"997890968","pt":1580583693497,"mc":[{"id":"1.168081835","rc":[{"trd":[[1.02,1.55]],"batb":[[0,1.02,7.92]],"ltp":1.02,"tv":1.55,"id":22229228,"hc":-10.5}],"tv":4.69}]}
{"op":"mcm","clk":"997891146","pt":1580583694476,"mc":[{"id":"1.168081835","rc":[{"trd":[[1.02,1.6]],"batb":[[0,1.02,7.89]],"ltp":1.02,"tv":1.59,"id":22229228,"hc":-11.5}],"tv":4.71}]}
{"op":"mcm","clk":"997892787","pt":1580583705703,"mc":[{"id":"1.168081835","rc":[{"trd":[[1.02,1.58]],"batb":[[0,1.02,7.9]],"ltp":1.02,"tv":1.58,"id":22229228,"hc":-9.5}],"tv":4.72}]}
{"op":"mcm","clk":"997893360","pt":1580583709525,"mc":[{"id":"1.168081835","rc":[{"trd":[[1.02,1.57]],"batb":[[0,1.02,7.91]],"ltp":1.02,"tv":1.56,"id":22229228,"hc":-10.5}],"tv":4.74}]}
{"op":"mcm","clk":"997893499","pt":1580583710492,"mc":[{"id":"1.168081835","rc":[{"batl":[[0,1000,2.37]],"ltp":1.02,"tv":1.59,"id":22229228,"hc":-11.5}]}]}
{"op":"mcm","clk":"997893579","pt":1580583711084,"mc":[{"id":"1.168081835","rc":[{"trd":[[1.02,1.61]],"batb":[[0,1.02,7.88]],"batl":[[0,990,0.01]],"ltp":1.02,"tv":1.61,"id":22229228,"hc":-11.5}],"tv":4.76}]}
{"op":"mcm","clk":"997895154","pt":1580583721445,"mc":[{"id":"1.168081835","rc":[{"batl":[[0,1000,2.37]],"ltp":1.02,"tv":1.58,"id":22229228,"hc":-9.5}]}]}
{"op":"mcm","clk":"997895258","pt":1580583722112,"mc":[{"id":"1.168081835","rc":[{"trd":[[1.02,1.6]],"batb":[[0,1.02,7.89]],"batl":[[0,990,0.01]],"ltp":1.02,"tv":1.59,"id":22229228,"hc":-9.5}],"tv":4.77}]}
{"op":"mcm","clk":"997895779","pt":1580583725531,"mc":[{"id":"1.168081835","rc":[{"batl":[[0,1000,0.02]],"ltp":1.02,"tv":1.56,"id":22229228,"hc":-10.5}]}]}
{"op":"mcm","clk":"997895967","pt":1580583726637,"mc":[{"id":"1.168081835","rc":[{"trd":[[1.02,1.58]],"batb":[[0,1.02,7.9]],"batl":[[0,990,0.01]],"ltp":1.02,"tv":1.58,"id":22229228,"hc":-10.5},{"batl":[[0,1000,2.37]],"ltp":1.02,"tv":1.61,"id":22229228,"hc":-11.5}],"tv":4.79}]}
{"op":"mcm","clk":"997896074","pt":1580583727215,"mc":[{"id":"1.168081835","rc":[{"trd":[[1.02,1.63]],"batb":[[0,1.02,7.87]],"batl":[[0,990,0.01]],"ltp":1.02,"tv":1.62,"id":22229228,"hc":-11.5}],"tv":4.8}]}
{"op":"mcm","clk":"997897706","pt":1580583738539,"mc":[{"id":"1.168081835","rc":[{"batl":[[0,1000,0.02]],"ltp":1.02,"tv":1.59,"id":22229228,"hc":-9.5}]}]}
{"op":"mcm","clk":"997897760","pt":1580583738875,"mc":[{"id":"1.168081835","rc":[{"trd":[[1.02,1.61]],"batb":[[0,1.02,7.88]],"batl":[[0,990,0.01]],"ltp":1.02,"tv":1.61,"id":22229228,"hc":-9.5}],"tv":4.82}]}
{"op":"mcm","clk":"997898164","pt":1580583741476,"mc":[{"id":"1.168081835","rc":[{"batl":[[0,1000,0.02]],"ltp":1.02,"tv":1.58,"id":22229228,"hc":-10.5}]}]}
{"op":"mcm","clk":"997898227","pt":1580583741877,"mc":[{"id":"1.168081835","rc":[{"trd":[[1.02,1.6]],"batb":[[0,1.02,7.89]],"batl":[[0,990,0.01]],"ltp":1.02,"tv":1.59,"id":22229228,"hc":-10.5}],"tv":4.83}]}
{"op":"mcm","clk":"997898535","pt":1580583743903,"mc":[{"id":"1.168081835","rc":[{"trd":[[1.02,1.64]],"batb":[[0,1.02,7.86]],"ltp":1.02,"tv":1.64,"id":22229228,"hc":-11.5}],"tv":4.85}]}
{"op":"mcm","clk":"997900131","pt":1580583754619,"mc":[{"id":"1.168081835","rc":[{"batl":[[0,1000,0.02]],"ltp":1.02,"tv":1.61,"id":22229228,"hc":-9.5}]}]}
{"op":"mcm","clk":"997900183","pt":1580583755000,"mc":[{"id":"1.168081835","rc":[{"trd":[[1.02,1.63]],"batb":[[0,1.02,7.87]],"batl":[[0,990,0.01]],"ltp":1.02,"tv":1.62,"id":22229228,"hc":-9.5}],"tv":4.86}]}
{"op":"mcm","clk":"997900590","pt":1580583757695,"mc":[{"id":"1.168081835","rc":[{"batl":[[0,1000,2.37]],"ltp":1.02,"tv":1.59,"id":22229228,"hc":-10.5}]}]}
{"op":"mcm","clk":"997900668","pt":1580583758228,"mc":[{"id":"1.168081835","rc":[{"trd":[[1.02,1.61]],"batb":[[0,1.02,7.88]],"batl":[[0,990,0.01]],"ltp":1.02,"tv":1.61,"id":22229228,"hc":-10.5}],"tv":4.88}]}
{"op":"mcm","clk":"997901076","pt":1580583760618,"mc":[{"id":"1.168081835","rc":[{"trd":[[1.02,1.66]],"batb":[[0,1.02,7.85]],"ltp":1.02,"tv":1.65,"id":22229228,"hc":-11.5}],"tv":4.9}]}
{"op":"mcm","clk":"997902514","pt":1580583771638,"mc":[{"id":"1.168081835","rc":[{"trd":[[1.02,1.64]],"batb":[[0,1.02,7.86]],"ltp":1.02,"tv":1.64,"id":22229228,"hc":-9.5}],"tv":4.91}]}
{"op":"mcm","clk":"997902996","pt":1580583774740,"mc":[{"id":"1.168081835","rc":[{"trd":[[1.02,1.63]],"batb":[[0,1.02,7.87]],"ltp":1.02,"tv":1.62,"id":22229228,"hc":-10.5}],"tv":4.93}]}
{"op":"mcm","clk":"997903303","pt":1580583776640,"mc":[{"id":"1.168081835","rc":[{"batl":[[0,1000,0.02]],"ltp":1.02,"tv":1.65,"id":22229228,"hc":-11.5}]}]}
{"op":"mcm","clk":"997903348","pt":1580583776949,"mc":[{"id":"1.168081835","rc":[{"trd":[[1.02,1.67]],"batb":[[0,1.02,7.84]],"batl":[[0,990,0.01]],"ltp":1.02,"tv":1.67,"id":22229228,"hc":-11.5}],"tv":4.94}]}
{"op":"mcm","clk":"997904856","pt":1580583787702,"mc":[{"id":"1.168081835","rc":[{"batl":[[0,1000,2.37]],"ltp":1.02,"tv":1.64,"id":22229228,"hc":-9.5}]}]}
{"op":"mcm","clk":"997904989","pt":1580583788634,"mc":[{"id":"1.168081835","rc":[{"trd":[[1.02,1.66]],"batb":[[0,1.02,7.85]],"batl":[[0,990,0.01]],"ltp":1.02,"tv":1.65,"id":22229228,"hc":-9.5}],"tv":4.96}]}
{"op":"mcm","clk":"997905276","pt":1580583790628,"mc":[{"id":"1.168081835","rc":[{"batl":[[0,1000,2.37]],"ltp":1.02,"tv":1.62,"id":22229228,"hc":-10.5}]}]}
{"op":"mcm","clk":"997905360","pt":1580583791112,"mc":[{"id":"1.168081835","rc":[{"trd":[[1.02,1.64]],"batb":[[0,1.02,7.86]],"batl":[[0,990,0.01]],"ltp":1.02,"tv":1.64,"id":22229228,"hc":-10.5}],"tv":4.97}]}
{"op":"mcm","clk":"997905579","pt":1580583792629,"mc":[{"id":"1.168081835","rc":[{"batl":[[0,1000,0.02]],"ltp":1.02,"tv":1.67,"id":22229228,"hc":-11.5}]}]}
{"op":"mcm","clk":"997905671","pt":1580583793330,"mc":[{"id":"1.168081835","rc":[{"trd":[[1.02,1.69]],"batb":[[0,1.02,7.83]],"batl":[[0,990,0.01]],"ltp":1.02,"tv":1.69,"id":22229228,"hc":-11.5}],"tv":4.99}]}
{"op":"mcm","clk":"997907423","pt":1580583804773,"mc":[{"id":"1.168081835","rc":[{"trd":[[1.02,1.67]],"batb":[[0,1.02,7.84]],"ltp":1.02,"tv":1.67,"id":22229228,"hc":-9.5}],"tv":5.0}]}
{"op":"mcm","clk":"997907885","pt":1580583807675,"mc":[{"id":"1.168081835","rc":[{"trd":[[1.02,1.66]],"batb":[[0,1.02,7.85]],"ltp":1.02,"tv":1.65,"id":22229228,"hc":-10.5}],"tv":5.02}]}
{"op":"mcm","clk":"997908313","pt":1580583810316,"mc":[{"id":"1.168081835","rc":[{"trd":[[1.02,1.71]],"batb":[[0,1.02,7.82]],"ltp":1.02,"tv":1.7,"id":22229228,"hc":-11.5}],"tv":5.04}]}
{"op":"mcm","clk":"997909765","pt":1580583820712,"mc":[{"id":"1.168081835","rc":[{"trd":[[1.02,1.69]],"batb":[[0,1.02,7.83]],"ltp":1.02,"tv":1.69,"id":22229228,"hc":-9.5}],"tv":5.05}]}
{"op":"mcm","clk":"997910166","pt":1580583823642,"mc":[{"id":"1.168081835","rc":[{"batl":[[0,1000,2.37]],"ltp":1.02,"tv":1.65,"id":22229228,"hc":-10.5}]}]}
{"op":"mcm","clk":"997910267","pt":1580583824238,"mc":[{"id":"1.168081835","rc":[{"trd":[[1.02,1.67]],"batb":[[0,1.02,7.84]],"batl":[[0,990,0.01]],"ltp":1.02,"tv":1.67,"id":22229228,"hc":-10.5}],"tv":5.07}]}
{"op":"mcm","clk":"997910470","pt":1580583825545,"mc":[{"id":"1.168081835","rc":[{"batl":[[0,1000,2.37]],"ltp":1.02,"tv":1.7,"id":22229228,"hc":-11.5}]}]}
{"op":"mcm","clk":"997910624","pt":1580583826540,"mc":[{"id":"1.168081835","rc":[{"trd":[[1.02,1.72]],"batb":[[0,1.02,7.81]],"batl":[[0,990,0.01]],"ltp":1.02,"tv":1.72,"id":22229228,"hc":-11.5}],"tv":5.08}]}
{"op":"mcm","clk":"997912180","pt":1580583837552,"mc":[{"id":"1.168081835","rc":[{"trd":[[1.02,1.71]],"batb":[[0,1.02,7.82]],"ltp":1.02,"tv":1.7,"id":22229228,"hc":-9.5}],"tv":5.1}]}
{"op":"mcm","clk":"997912638","pt":1580583840772,"mc":[{"id":"1.168081835","rc":[{"trd":[[1.02,1.69]],"batb":[[0,1.02,7.83]],"ltp":1.02,"tv":1.69,"id":22229228,"hc":-10.5}],"tv":5.11}]}
{"op":"mcm","clk":"997912941","pt":1580583842697,"mc":[{"id":"1.168081835","rc":[{"batl":[[0,1000,0.02]],"ltp":1.02,"tv":1.72,"id":22229228,"hc":-11.5}]}]}
{"op":"mcm","clk":"997913007","pt":1580583843128,"mc":[{"id":"1.168081835","rc":[{"trd":[[1.02,1.74]],"batb":[[0,1.02,7.8]],"batl":[[0,990,0.01]],"ltp":1.02,"tv":1.73,"id":22229228,"hc":-11.5}],"tv":5.13}]}
{"op":"mcm","clk":"997914629","pt":1580583853640,"mc":[{"id":"1.168081835","rc":[{"batl":[[0,1000,0.02]],"ltp":1.02,"tv":1.7,"id":22229228,"hc":-9.5}]}]}
{"op":"mcm","clk":"997914682","pt":1580583854014,"mc":[{"id":"1.168081835","rc":[{"trd":[[1.02,1.72]],"batb":[[0,1.02,7.81]],"batl":[[0,990,0.01]],"ltp":1.02,"tv":1.72,"id":22229228,"hc":-9.5}],"tv":5.14}]}
{"op":"mcm","clk":"997915097","pt":1580583856608,"mc":[{"id":"1.168081835","rc":[{"batl":[[0,1000,2.37]],"ltp":1.02,"tv":1.69,"id":22229228,"hc":-10.5}]}]}
{"op":"mcm","clk":"997915178","pt":1580583857243,"mc":[{"id":"1.168081835","rc":[{"trd":[[1.02,1.71]],"batb":[[0,1.02,7.82]],"batl":[[0,990,0.01]],"ltp":1.02,"tv":1.7,"id":22229228,"hc":-10.5}],"tv":5.16}]}
{"op":"mcm","clk":"997915539","pt":1580583859435,"mc":[{"id":"1.168081835","rc":[{"trd":[[1.02,1.75]],"batb":[[0,1.02,7.79]],"ltp":1.02,"tv":1.75,"id":22229228,"hc":-11.5}],"tv":5.17}]}
{"op":"mcm","clk":"997917126","pt":1580583869548,"mc":[{"id":"1.168081835","rc":[{"batl":[[0,1000,0.02]],"ltp":1.02,"tv":1.72,"id":22229228,"hc":-9.5}]}]}
{"op":"mcm","clk":"997917187","pt":1580583869913,"mc":[{"id":"1.168081835","rc":[{"trd":[[1.02,1.74]],"batb":[[0,1.02,7.8]],"batl":[[0,990,0.01]],"ltp":1.02,"tv":1.73,"id":22229228,"hc":-9.5}],"tv":5.19}]}
{"op":"mcm","clk":"997917758","pt":1580583873646,"mc":[{"id":"1.168081835","rc":[{"batl":[[0,1000,0.02]],"ltp":1.02,"tv":1.7,"id":22229228,"hc":-10.5}]}]}
{"op":"mcm","clk":"997917801","pt":1580583873964,"mc":[{"id":"1.168081835","rc":[{"trd":[[1.02,1.72]],"batb":[[0,1.02,7.81]],"batl":[[0,990,0.01]],"ltp":1.02,"tv":1.72,"id":22229228,"hc":-10.5}],"tv":5.21}]}
{"op":"mcm","clk":"997918103","pt":1580583875627,"mc":[{"id":"1.168081835","rc":[{"batl":[[0,1000,0.02]],"ltp":1.02,"tv":1.75,"id":22229228,"hc":-11.5}]}]}
{"op":"mcm","clk":"997918135","pt":1580583875844,"mc":[{"id":"1.168081835","rc":[{"trd":[[1.02,1.77]],"batb":[[0,1.02,7.78]],"batl":[[0,990,0.01]],"ltp":1.02,"tv":1.76,"id":22229228,"hc":-11.5}],"tv":5.22}]}
{"op":"mcm","clk":"997919649","pt":1580583885685,"mc":[{"id":"1.168081835","rc":[{"batl":[[0,1000,2.37]],"ltp":1.02,"tv":1.73,"id":22229228,"hc":-9.5}]}]}
{"op":"mcm","clk":"997919774","pt":1580583886496,"mc":[{"id":"1.168081835","rc":[{"trd":[[1.02,1.75]],"batb":[[0,1.02,7.79]],"batl":[[0,990,0.01]],"ltp":1.02,"tv":1.75,"id":22229228,"hc":-9.5}],"tv":5.24}]}
{"op":"mcm","clk":"997920449","pt":1580583890577,"mc":[{"id":"1.168081835","rc":[{"trd":[[1.02,1.74]],"batb":[[0,1.02,7.8]],"ltp":1.02,"tv":1.73,"id":22229228,"hc":-10.5}],"tv":5.25}]}
{"op":"mcm","clk":"997920812","pt":1580583892397,"mc":[{"id":"1.168081835","rc":[{"trd":[[1.02,1.78]],"batb":[[0,1.02,7.77]],"ltp":1.02,"tv":1.78,"id":22229228,"hc":-11.5}],"tv":5.27}]}
{"op":"mcm","clk":"997922465","pt":1580583902562,"mc":[{"id":"1.168081835","rc":[{"batl":[[0,1000,0.02]],"ltp":1.02,"tv":1.75,"id":22229228,"hc":-9.5}]}]}
{"op":"mcm","clk":"997922513","pt":1580583902814,"mc":[{"id":"1.168081835","rc":[{"trd":[[1.02,1.77]],"batb":[[0,1.02,7.78]],"batl":[[0,990,0.01]],"ltp":1.02,"tv":1.76,"id":22229228,"hc":-9.5}],"tv":5.28}]}
{"op":"mcm","clk":"997923131","pt":1580583906650,"mc":[{"id":"1.168081835","rc":[{"batl":[[0,1000,0.02]],"ltp":1.02,"tv":1.73,"id":22229228,"hc":-10.5}]}]}
{"op":"mcm","clk":"997923268","pt":1580583907444,"mc":[{"id":"1.168081835","rc":[{"trd":[[1.02,1.75]],"batb":[[0,1.02,7.79]],"batl":[[0,990,0.01]],"ltp":1.02,"tv":1.75,"id":22229228,"hc":-10.5}],"tv":5.3}]}
{"op":"mcm","clk":"997923474","pt":1580583908551,"mc":[{"id":"1.168081835","rc":[{"batl":[[0,1000,2.37]],"ltp":1.02,"tv":1.78,"id":22229228,"hc":-11.5}]}]}
{"op":"mcm","clk":"997923604","pt":1580583909244,"mc":[{"id":"1.168081835","rc":[{"trd":[[1.02,1.8]],"batb":[[0,1.02,7.76]],"batl":[[0,990,0.01]],"ltp":1.02,"tv":1.79,"id":22229228,"hc":-11.5}],"tv":5.31}]}
{"op":"mcm","clk":"997925273","pt":1580583919633,"mc":[{"id":"1.168081835","rc":[{"trd":[[1.02,1.78]],"batb":[[0,1.02,7.77]],"ltp":1.02,"tv":1.78,"id":22229228,"hc":-9.5}],"tv":5.33}]}
{"op":"mcm","clk":"997925892","pt":1580583923531,"mc":[{"id":"1.168081835","rc":[{"batl":[[0,1000,0.02]],"ltp":1.02,"tv":1.75,"id":22229228,"hc":-10.5}]}]}
{"op":"mcm","clk":"997926085","pt":1580583924643,"mc":[{"id":"1.168081835","rc":[{"trd":[[1.02,1.77]],"batb":[[0,1.02,7.78]],"batl":[[0,990,0.01]],"ltp":1.02,"tv":1.76,"id":22229228,"hc":-10.5},{"batl":[[0,1000,2.37]],"ltp":1.02,"tv":1.79,"id":22229228,"hc":-11.5}],"tv":5.35}]}
{"op":"mcm","clk":"997926212","pt":1580583925367,"mc":[{"id":"1.168081835","rc":[{"trd":[[1.02,1.81]],"batb":[[0,1.02,7.75]],"batl":[[0,990,0.01]],"ltp":1.02,"tv":1.81,"id":22229228,"hc":-11.5}],"tv":5.36}]}
{"op":"mcm","clk":"997927921","pt":1580583935774,"mc":[{"id":"1.168081835","rc":[{"trd":[[1.02,1.8]],"batb":[[0,1.02,7.76]],"ltp":1.02,"tv":1.79,"id":22229228,"hc":-9.5}],"tv":5.38}]}
{"op":"mcm","clk":"997928517","pt":1580583939600,"mc":[{"id":"1.168081835","rc":[{"batl":[[0,1000,2.37]],"ltp":1.02,"tv":1.76,"id":22229228,"hc":-10.5}]}]}
{"op":"mcm","clk":"997928674","pt":1580583940476,"mc":[{"id":"1.168081835","rc":[{"trd":[[1.02,1.78]],"batb":[[0,1.02,7.77]],"batl":[[0,990,0.01]],"ltp":1.02,"tv":1.78,"id":22229228,"hc":-10.5},{"batl":[[0,1000,2.37]],"ltp":1.02,"tv":1.81,"id":22229228,"hc":-11.5}],"tv":5.39}]}
{"op":"mcm","clk":"997928782","pt":1580583941077,"mc":[{"id":"1.168081835","rc":[{"trd":[[1.02,1.83]],"batb":[[0,1.02,7.74]],"batl":[[0,990,0.01]],"ltp":1.02,"tv":1.82,"id":22229228,"hc":-11.5}],"tv":5.41}]}
{"op":"mcm","clk":"997930478","pt":1580583951684,"mc":[{"id":"1.168081835","rc":[{"batl":[[0,1000,0.02]],"ltp":1.02,"tv":1.79,"id":22229228,"hc":-9.5}]}]}
{"op":"mcm","clk":"997930523","pt":1580583952011,"mc":[{"id":"1.168081835","rc":[{"trd":[[1.02,1.81]],"batb":[[0,1.02,7.75]],"batl":[[0,990,0.01]],"ltp":1.02,"tv":1.81,"id":22229228,"hc":-9.5}],"tv":5.42}]}
{"op":"mcm","clk":"997931249","pt":1580583956545,"mc":[{"id":"1.168081835","rc":[{"batl":[[0,1000,0.02]],"ltp":1.02,"tv":1.78,"id":22229228,"hc":-10.5}]}]}
{"op":"mcm","clk":"997931408","pt":1580583957433,"mc":[{"id":"1.168081835","rc":[{"trd":[[1.02,1.8]],"batb":[[0,1.02,7.76]],"batl":[[0,990,0.01]],"ltp":1.02,"tv":1.79,"id":22229228,"hc":-10.5},{"trd":[[1.02,1.85]],"batb":[[0,1.02,7.73]],"ltp":1.02,"tv":1.84,"id":22229228,"hc":-11.5}],"tv":5.45}]}
{"op":"mcm","clk":"997933293","pt":1580583968528,"mc":[{"id":"1.168081835","rc":[{"trd":[[1.02,1.83]],"batb":[[0,1.02,7.74]],"ltp":1.02,"tv":1.82,"id":22229228,"hc":-9.5}],"tv":5.47}]}
{"op":"mcm","clk":"997933987","pt":1580583972549,"mc":[{"id":"1.168081835","rc":[{"batl":[[0,1000,2.37]],"ltp":1.02,"tv":1.79,"id":22229228,"hc":-10.5}]}]}
{"op":"mcm","clk":"997934195","pt":1580583973645,"mc":[{"id":"1.168081835","rc":[{"trd":[[1.02,1.81]],"batb":[[0,1.02,7.75]],"batl":[[0,990,0.01]],"ltp":1.02,"tv":1.81,"id":22229228,"hc":-10.5},{"trd":[[1.02,1.86]],"batb":[[0,1.02,7.72]],"ltp":1.02,"tv":1.86,"id":22229228,"hc":-11.5}],"tv":5.5}]}
{"op":"mcm","clk":"997935926","pt":1580583984582,"mc":[{"id":"1.168081835","rc":[{"batl":[[0,1000,0.02]],"ltp":1.02,"tv":1.82,"id":22229228,"hc":-9.5}]}]}
{"op":"mcm","clk":"997935989","pt":1580583984962,"mc":[{"id":"1.168081835","rc":[{"trd":[[1.02,1.85]],"batb":[[0,1.02,7.73]],"batl":[[0,990,0.01]],"ltp":1.02,"tv":1.84,"id":22229228,"hc":-9.5}],"tv":5.52}]}
{"op":"mcm","clk":"997936608","pt":1580583988674,"mc":[{"id":"1.168081835","rc":[{"batl":[[0,1000,0.02]],"ltp":1.02,"tv":1.81,"id":22229228,"hc":-10.5}]}]}
{"op":"mcm","clk":"997936775","pt":1580583989551,"mc":[{"id":"1.168081835","rc":[{"trd":[[1.02,1.83]],"batb":[[0,1.02,7.74]],"batl":[[0,990,0.01]],"ltp":1.02,"tv":1.82,"id":22229228,"hc":-10.5},{"trd":[[1.02,1.88]],"batb":[[0,1.02,7.71]],"ltp":1.02,"tv":1.87,"id":22229228,"hc":-11.5}],"tv":5.55}]}
{"op":"mcm","clk":"997938739","pt":1580584001581,"mc":[{"id":"1.168081835","rc":[{"batl":[[0,1000,0.02]],"ltp":1.02,"tv":1.84,"id":22229228,"hc":-9.5}]}]}
{"op":"mcm","clk":"997938804","pt":1580584001996,"mc":[{"id":"1.168081835","rc":[{"trd":[[1.02,1.86]],"batb":[[0,1.02,7.72]],"batl":[[0,990,0.01]],"ltp":1.02,"tv":1.86,"id":22229228,"hc":-9.5}],"tv":5.56}]}
{"op":"mcm","clk":"997939380","pt":1580584005496,"mc":[{"id":"1.168081835","rc":[{"batl":[[0,1000,0.02]],"ltp":1.02,"tv":1.82,"id":22229228,"hc":-10.5},{"batl":[[0,1000,2.37]],"ltp":1.02,"tv":1.87,"id":22229228,"hc":-11.5}]}]}
{"op":"mcm","clk":"997939485","pt":1580584006162,"mc":[{"id":"1.168081835","rc":[{"trd":[[1.02,1.85]],"batb":[[0,1.02,7.73]],"batl":[[0,990,0.01]],"ltp":1.02,"tv":1.84,"id":22229228,"hc":-10.5},{"trd":[[1.02,1.89]],"batb":[[0,1.02,7.7]],"batl":[[0,990,0.01]],"ltp":1.02,"tv":1.89,"id":22229228,"hc":-11.5}],"tv":5.59}]}
{"op":"mcm","clk":"997941397","pt":1580584018562,"mc":[{"id":"1.168081835","rc":[{"batl":[[0,1000,0.02]],"ltp":1.02,"tv":1.86,"id":22229228,"hc":-9.5}]}]}
{"op":"mcm","clk":"997941458","pt":1580584018990,"mc":[{"id":"1.168081835","rc":[{"trd":[[1.02,1.88]],"batb":[[0,1.02,7.71]],"batl":[[0,990,0.01]],"ltp":1.02,"tv":1.87,"id":22229228,"hc":-9.5}],"tv":5.61}]}
{"op":"mcm","clk":"997941885","pt":1580584021604,"mc":[{"id":"1.168081835","rc":[{"batl":[[0,1000,0.02]],"ltp":1.02,"tv":1.84,"id":22229228,"hc":-10.5},{"batl":[[0,1000,0.02]],"ltp":1.02,"tv":1.89,"id":22229228,"hc":-11.5}]}]}
{"op":"mcm","clk":"997941959","pt":1580584021983,"mc":[{"id":"1.168081835","rc":[{"trd":[[1.02,1.86]],"batb":[[0,1.02,7.72]],"batl":[[0,990,0.01]],"ltp":1.02,"tv":1.86,"id":22229228,"hc":-10.5},{"trd":[[1.02,1.91]],"batb":[[0,1.02,7.69]],"batl":[[0,990,0.01]],"ltp":1.02,"tv":1.9,"id":22229228,"hc":-11.5}],"tv":5.64}]}
{"op":"mcm","clk":"997944154","pt":1580584035617,"mc":[{"id":"1.168081835","rc":[{"trd":[[1.02,1.89]],"batb":[[0,1.02,7.7]],"ltp":1.02,"tv":1.89,"id":22229228,"hc":-9.5}],"tv":5.66}]}
{"op":"mcm","clk":"997944506","pt":1580584037527,"mc":[{"id":"1.168081835","rc":[{"batl":[[0,1000,2.37]],"ltp":1.02,"tv":1.9,"id":22229228,"hc":-11.5}]}]}
{"op":"mcm","clk":"997944651","pt":1580584038539,"mc":[{"id":"1.168081835","rc":[{"trd":[[1.02,1.88]],"batb":[[0,1.02,7.71]],"ltp":1.02,"tv":1.87,"id":22229228,"hc":-10.5},{"trd":[[1.02,1.92]],"batb":[[0,1.02,7.68]],"batl":[[0,990,0.01]],"ltp":1.02,"tv":1.92,"id":22229228,"hc":-11.5}],"tv":5.69}]}
{"op":"mcm","clk":"997946706","pt":1580584051579,"mc":[{"id":"1.168081835","rc":[{"trd":[[1.02,1.91]],"batb":[[0,1.02,7.69]],"ltp":1.02,"tv":1.9,"id":22229228,"hc":-9.5}],"tv":5.7}]}
{"op":"mcm","clk":"997947152","pt":1580584054513,"mc":[{"id":"1.168081835","rc":[{"trd":[[1.02,1.89]],"batb":[[0,1.02,7.7]],"ltp":1.02,"tv":1.89,"id":22229228,"hc":-10.5},{"trd":[[1.02,1.94]],"batb":[[0,1.02,7.67]],"ltp":1.02,"tv":1.93,"id":22229228,"hc":-11.5}],"tv":5.73}]}
{"op":"mcm","clk":"997949265","pt":1580584067616,"mc":[{"id":"1.168081835","rc":[{"batl":[[0,1000,0.02]],"ltp":1.02,"tv":1.9,"id":22229228,"hc":-9.5}]}]}
{"op":"mcm","clk":"997949309","pt":1580584067941,"mc":[{"id":"1.168081835","rc":[{"trd":[[1.02,1.92]],"batb":[[0,1.02,7.68]],"batl":[[0,990,0.01]],"ltp":1.02,"tv":1.92,"id":22229228,"hc":-9.5}],"tv":5.75}]}
{"op":"mcm","clk":"997949734","pt":1580584070511,"mc":[{"id":"1.168081835","rc":[{"trd":[[1.02,1.91]],"batb":[[0,1.02,7.69]],"ltp":1.02,"tv":1.9,"id":22229228,"hc":-10.5}],"tv":5.76}]}
{"op":"mcm","clk":"997949891","pt":1580584071455,"mc":[{"id":"1.168081835","rc":[{"trd":[[1.02,1.95]],"batb":[[0,1.02,7.66]],"ltp":1.02,"tv":1.95,"id":22229228,"hc":-11.5}],"tv":5.78}]}
{"op":"mcm","clk":"997952034","pt":1580584084744,"mc":[{"id":"1.168081835","rc":[{"trd":[[1.02,1.94]],"batb":[[0,1.02,7.67]],"ltp":1.02,"tv":1.93,"id":22229228,"hc":-9.5}],"tv":5.79}]}
{"op":"mcm","clk":"997952360","pt":1580584086645,"mc":[{"id":"1.168081835","rc":[{"batl":[[0,1000,0.02]],"ltp":1.02,"tv":1.9,"id":22229228,"hc":-10.5}]}]}
{"op":"mcm","clk":"997952520","pt":1580584087672,"mc":[{"id":"1.168081835","rc":[{"trd":[[1.02,1.92]],"batb":[[0,1.02,7.68]],"batl":[[0,990,0.01]],"ltp":1.02,"tv":1.92,"id":22229228,"hc":-10.5},{"trd":[[1.02,1.97]],"batb":[[0,1.02,7.65]],"ltp":1.02,"tv":1.96,"id":22229228,"hc":-11.5}],"tv":5.83}]}
{"op":"mcm","clk":"997954540","pt":1580584100695,"mc":[{"id":"1.168081835","rc":[{"trd":[[1.02,1.95]],"batb":[[0,1.02,7.66]],"ltp":1.02,"tv":1.95,"id":22229228,"hc":-9.5}],"tv":5.84}]}
{"op":"mcm","clk":"997954988","pt":1580584103678,"mc":[{"id":"1.168081835","rc":[{"batl":[[0,1000,0.02]],"ltp":1.02,"tv":1.96,"id":22229228,"hc":-11.5}]}]}
{"op":"mcm","clk":"997955140","pt":1580584104651,"mc":[{"id":"1.168081835","rc":[{"trd":[[1.02,1.94]],"batb":[[0,1.02,7.67]],"ltp":1.02,"tv":1.93,"id":22229228,"hc":-10.5},{"trd":[[1.02,1.98]],"batb":[[0,1.02,7.64]],"batl":[[0,990,0.01]],"ltp":1.02,"tv":1.98,"id":22229228,"hc":-11.5}],"tv":5.87}]}
{"op":"mcm","clk":"997957153","pt":1580584117514,"mc":[{"id":"1.168081835","rc":[{"trd":[[1.02,1.97]],"batb":[[0,1.02,7.65]],"ltp":1.02,"tv":1.96,"id":22229228,"hc":-9.5}],"tv":5.89}]}
{"op":"mcm","clk":"997957503","pt":1580584119681,"mc":[{"id":"1.168081835","rc":[{"batl":[[0,1000,2.37]],"ltp":1.02,"tv":1.93,"id":22229228,"hc":-10.5}]}]}
{"op":"mcm","clk":"997957643","pt":1580584120625,"mc":[{"id":"1.168081835","rc":[{"trd":[[1.02,1.95]],"batb":[[0,1.02,7.66]],"batl":[[0,990,0.01]],"ltp":1.02,"tv":1.95,"id":22229228,"hc":-10.5},{"trd":[[1.02,2]],"batb":[[0,1.02,7.63]],"ltp":1.02,"tv":2.0,"id":22229228,"hc":-11.5}],"tv":5.92}]}
{"op":"mcm","clk":"997959697","pt":1580584133675,"mc":[{"id":"1.168081835","rc":[{"batl":[[0,1000,2.37]],"ltp":1.02,"tv":1.96,"id":22229228,"hc":-9.5}]}]}
{"op":"mcm","clk":"997959783","pt":1580584134179,"mc":[{"id":"1.168081835","rc":[{"trd":[[1.02,1.98]],"batb":[[0,1.02,7.64]],"batl":[[0,990,0.01]],"ltp":1.02,"tv":1.98,"id":22229228,"hc":-9.5}],"tv":5.93}]}
{"op":"mcm","clk":"997960212","pt":1580584136664,"mc":[{"id":"1.168081835","rc":[{"batl":[[0,1000,2.37]],"ltp":1.02,"tv":1.95,"id":22229228,"hc":-10.5}]}]}
{"op":"mcm","clk":"997960345","pt":1580584137502,"mc":[{"id":"1.168081835","rc":[{"batl":[[0,1000,0.02]],"ltp":1.02,"tv":1.95,"id":22229228,"hc":-10.5},{"trd":[[1.02,2.02]],"batb":[[0,1.02,7.62]],"ltp":1.02,"tv":2.01,"id":22229228,"hc":-11.5}],"tv":5.95}]}
{"op":"mcm","clk":"997960417","pt":1580584137965,"mc":[{"id":"1.168081835","rc":[{"trd":[[1.02,1.97]],"batb":[[0,1.02,7.65]],"batl":[[0,990,0.01]],"ltp":1.02,"tv":1.96,"id":22229228,"hc":-10.5}],"tv":5.97}]}
{"op":"mcm","clk":"997962521","pt":1580584150443,"mc":[{"id":"1.168081835","rc":[{"batl":[[0,1000,0.02]],"ltp":1.02,"tv":1.98,"id":22229228,"hc":-9.5}]}]}
{"op":"mcm","clk":"997962592","pt":1580584150859,"mc":[{"id":"1.168081835","rc":[{"trd":[[1.02,2]],"batb":[[0,1.02,7.63]],"batl":[[0,990,0.01]],"ltp":1.02,"tv":2.0,"id":22229228,"hc":-9.5}],"tv":5.98}]}
{"op":"mcm","clk":"997963027","pt":1580584153632,"mc":[{"id":"1.168081835","rc":[{"trd":[[1.02,2.03]],"batb":[[0,1.02,7.61]],"ltp":1.02,"tv":2.03,"id":22229228,"hc":-11.5}],"tv":6.0}]}
{"op":"mcm","clk":"997963167","pt":1580584154430,"mc":[{"id":"1.168081835","rc":[{"trd":[[1.02,1.98]],"batb":[[0,1.02,7.64]],"ltp":1.02,"tv":1.98,"id":22229228,"hc":-10.5}],"tv":6.01}]}
{"op":"mcm","clk":"997965433","pt":1580584167442,"mc":[{"id":"1.168081835","rc":[{"batl":[[0,1000,0.02]],"ltp":1.02,"tv":2.0,"id":22229228,"hc":-9.5}]}]}
{"op":"mcm","clk":"997965607","pt":1580584168464,"mc":[{"id":"1.168081835","rc":[{"trd":[[1.02,2.02]],"batb":[[0,1.02,7.62]],"batl":[[0,990,0.01]],"ltp":1.02,"tv":2.01,"id":22229228,"hc":-9.5},{"batl":[[0,1000,2.37]],"ltp":1.02,"tv":2.03,"id":22229228,"hc":-11.5}],"tv":6.03}]}
{"op":"mcm","clk":"997965714","pt":1580584169056,"mc":[{"id":"1.168081835","rc":[{"trd":[[1.02,2.05]],"batb":[[0,1.02,7.6]],"batl":[[0,990,0.01]],"ltp":1.02,"tv":2.04,"id":22229228,"hc":-11.5}],"tv":6.04}]}
{"op":"mcm","clk":"997965970","pt":1580584170444,"mc":[{"id":"1.168081835","rc":[{"trd":[[1.02,2]],"batb":[[0,1.02,7.63]],"ltp":1.02,"tv":2.0,"id":22229228,"hc":-10.5}],"tv":6.06}]}
{"op":"mcm","clk":"997968274","pt":1580584184514,"mc":[{"id":"1.168081835","rc":[{"batl":[[0,1000,0.02]],"ltp":1.02,"tv":2.01,"id":22229228,"hc":-9.5}]}]}
{"op":"mcm","clk":"997968453","pt":1580584185598,"mc":[{"id":"1.168081835","rc":[{"trd":[[1.02,2.03]],"batb":[[0,1.02,7.61]],"batl":[[0,990,0.01]],"ltp":1.02,"tv":2.03,"id":22229228,"hc":-9.5}],"tv":6.07}]}
{"op":"mcm","clk":"997968590","pt":1580584186424,"mc":[{"id":"1.168081835","rc":[{"trd":[[1.02,2.02]],"batb":[[0,1.02,7.62]],"ltp":1.02,"tv":2.01,"id":22229228,"hc":-10.5},{"trd":[[1.02,2.06]],"batb":[[0,1.02,7.59]],"ltp":1.02,"tv":2.06,"id":22229228,"hc":-11.5}],"tv":6.11}]}
{"op":"mcm","clk":"997971056","pt":1580584201591,"mc":[{"id":"1.168081835","rc":[{"batl":[[0,1000,0.02]],"ltp":1.02,"tv":2.06,"id":22229228,"hc":-11.5}]}]}
{"op":"mcm","clk":"997971261","pt":1580584202680,"mc":[{"id":"1.168081835","rc":[{"trd":[[1.02,2.05]],"batb":[[0,1.02,7.6]],"ltp":1.02,"tv":2.04,"id":22229228,"hc":-9.5},{"batl":[[0,1000,2.37]],"ltp":1.02,"tv":2.01,"id":22229228,"hc":-10.5},{"trd":[[1.02,2.08]],"batb":[[0,1.02,7.58]],"batl":[[0,990,0.01]],"ltp":1.02,"tv":2.07,"id":22229228,"hc":-11.5}],"tv":6.14}]}
{"op":"mcm","clk":"997971342","pt":1580584203211,"mc":[{"id":"1.168081835","rc":[{"trd":[[1.02,2.03]],"batb":[[0,1.02,7.61]],"batl":[[0,990,0.01]],"ltp":1.02,"tv":2.03,"id":22229228,"hc":-10.5}],"tv":6.15}]}
{"op":"mcm","clk":"997973707","pt":1580584217610,"mc":[{"id":"1.168081835","rc":[{"batl":[[0,1000,0.02]],"ltp":1.02,"tv":2.04,"id":22229228,"hc":-9.5}]}]}
{"op":"mcm","clk":"997973814","pt":1580584218342,"mc":[{"id":"1.168081835","rc":[{"trd":[[1.02,2.06]],"batb":[[0,1.02,7.59]],"batl":[[0,990,0.01]],"ltp":1.02,"tv":2.06,"id":22229228,"hc":-9.5},{"trd":[[1.02,2.09]],"batb":[[0,1.02,7.57]],"ltp":1.02,"tv":2.09,"id":22229228,"hc":-11.5}],"tv":6.18}]}
{"op":"mcm","clk":"997974019","pt":1580584219410,"mc":[{"id":"1.168081835","rc":[{"trd":[[1.02,2.05]],"batb":[[0,1.02,7.6]],"ltp":1.02,"tv":2.04,"id":22229228,"hc":-10.5}],"tv":6.2}]}
{"op":"mcm","clk":"997976514","pt":1580584234638,"mc":[{"id":"1.168081835","rc":[{"batl":[[0,1000,0.02]],"ltp":1.02,"tv":2.06,"id":22229228,"hc":-9.5},{"batl":[[0,1000,2.37]],"ltp":1.02,"tv":2.09,"id":22229228,"hc":-11.5}]}]}
{"op":"mcm","clk":"997976634","pt":1580584235449,"mc":[{"id":"1.168081835","rc":[{"trd":[[1.02,2.08]],"batb":[[0,1.02,7.58]],"batl":[[0,990,0.01]],"ltp":1.02,"tv":2.07,"id":22229228,"hc":-9.5},{"batl":[[0,1000,0.02]],"ltp":1.02,"tv":2.04,"id":22229228,"hc":-10.5},{"trd":[[1.02,2.11]],"batb":[[0,1.02,7.56]],"batl":[[0,990,0.01]],"ltp":1.02,"tv":2.1,"id":22229228,"hc":-11.5}],"tv":6.23}]}
{"op":"mcm","clk":"997976713","pt":1580584235982,"mc":[{"id":"1.168081835","rc":[{"trd":[[1.02,2.06]],"batb":[[0,1.02,7.59]],"batl":[[0,990,0.01]],"ltp":1.02,"tv":2.06,"id":22229228,"hc":-10.5}],"tv":6.24}]}
{"op":"mcm","clk":"997979098","pt":1580584251428,"mc":[{"id":"1.168081835","rc":[{"trd":[[1.02,2.09]],"batb":[[0,1.02,7.57]],"ltp":1.02,"tv":2.09,"id":22229228,"hc":-9.5},{"batl":[[0,1000,0.02]],"ltp":1.02,"tv":2.1,"id":22229228,"hc":-11.5}],"tv":6.26}]}
{"op":"mcm","clk":"997979317","pt":1580584252694,"mc":[{"id":"1.168081835","rc":[{"trd":[[1.02,2.08]],"batb":[[0,1.02,7.58]],"ltp":1.02,"tv":2.07,"id":22229228,"hc":-10.5},{"trd":[[1.02,2.12]],"batb":[[0,1.02,7.55]],"batl":[[0,990,0.01]],"ltp":1.02,"tv":2.12,"id":22229228,"hc":-11.5}],"tv":6.29}]}
{"op":"mcm","clk":"997981835","pt":1580584267644,"mc":[{"id":"1.168081835","rc":[{"batl":[[0,1000,2.37]],"ltp":1.02,"tv":2.09,"id":22229228,"hc":-9.5}]}]}
{"op":"mcm","clk":"997982030","pt":1580584268644,"mc":[{"id":"1.168081835","rc":[{"trd":[[1.02,2.11]],"batb":[[0,1.02,7.56]],"batl":[[0,990,0.01]],"ltp":1.02,"tv":2.1,"id":22229228,"hc":-9.5},{"trd":[[1.02,2.09]],"batb":[[0,1.02,7.57]],"ltp":1.02,"tv":2.09,"id":22229228,"hc":-10.5},{"trd":[[1.02,2.14]],"batb":[[0,1.02,7.54]],"ltp":1.02,"tv":2.14,"id":22229228,"hc":-11.5}],"tv":6.34}]}
{"op":"mcm","clk":"997984808","pt":1580584284682,"mc":[{"id":"1.168081835","rc":[{"batl":[[0,1000,2.37]],"ltp":1.02,"tv":2.1,"id":22229228,"hc":-9.5},{"batl":[[0,1000,0.02]],"ltp":1.02,"tv":2.14,"id":22229228,"hc":-11.5}]}]}
{"op":"mcm","clk":"997984957","pt":1580584285590,"mc":[{"id":"1.168081835","rc":[{"trd":[[1.02,2.12]],"batb":[[0,1.02,7.55]],"batl":[[0,990,0.01]],"ltp":1.02,"tv":2.12,"id":22229228,"hc":-9.5},{"trd":[[1.02,2.11]],"batb":[[0,1.02,7.56]],"ltp":1.02,"tv":2.1,"id":22229228,"hc":-10.5},{"trd":[[1.02,2.16]],"batb":[[0,1.02,7.53]],"batl":[[0,990,0.01]],"ltp":1.02,"tv":2.15,"id":22229228,"hc":-11.5}],"tv":6.38}]}
{"op":"mcm","clk":"997987520","pt":1580584300609,"mc":[{"id":"1.168081835","rc":[{"batl":[[0,1000,2.37]],"ltp":1.02,"tv":2.15,"id":22229228,"hc":-11.5}]}]}
{"op":"mcm","clk":"997987715","pt":1580584301702,"mc":[{"id":"1.168081835","rc":[{"batl":[[0,1000,0.02]],"ltp":1.02,"tv":2.12,"id":22229228,"hc":-9.5},{"batl":[[0,1000,2.37]],"ltp":1.02,"tv":2.1,"id":22229228,"hc":-10.5},{"trd":[[1.02,2.17]],"batb":[[0,1.02,7.52]],"batl":[[0,990,0.01]],"ltp":1.02,"tv":2.17,"id":22229228,"hc":-11.5}],"tv":6.4}]}
{"op":"mcm","clk":"997987828","pt":1580584302300,"mc":[{"id":"1.168081835","rc":[{"trd":[[1.02,2.14]],"batb":[[0,1.02,7.54]],"batl":[[0,990,0.01]],"ltp":1.02,"tv":2.14,"id":22229228,"hc":-9.5},{"trd":[[1.02,2.12]],"batb":[[0,1.02,7.55]],"batl":[[0,990,0.01]],"ltp":1.02,"tv":2.12,"id":22229228,"hc":-10.5}],"tv":6.43}]}
{"op":"mcm","clk":"997990504","pt":1580584317655,"mc":[{"id":"1.168081835","rc":[{"batl":[[0,1000,0.02]],"ltp":1.02,"tv":2.17,"id":22229228,"hc":-11.5}]}]}
{"op":"mcm","clk":"997990667","pt":1580584318552,"mc":[{"id":"1.168081835","rc":[{"trd":[[1.02,2.16]],"batb":[[0,1.02,7.53]],"ltp":1.02,"tv":2.15,"id":22229228,"hc":-9.5},{"batl":[[0,1000,0.02]],"ltp":1.02,"tv":2.12,"id":22229228,"hc":-10.5},{"trd":[[1.02,2.19]],"batb":[[0,1.02,7.51]],"batl":[[0,990,0.01]],"ltp":1.02,"tv":2.18,"id":22229228,"hc":-11.5}],"tv":6.46}]}
{"op":"mcm","clk":"997990720","pt":1580584318834,"mc":[{"id":"1.168081835","rc":[{"trd":[[1.02,2.14]],"batb":[[0,1.02,7.54]],"batl":[[0,990,0.01]],"ltp":1.02,"tv":2.14,"id":22229228,"hc":-10.5}],"tv":6.48}]}
{"op":"mcm","clk":"997993318","pt":1580584333699,"mc":[{"id":"1.168081835","rc":[{"batl":[[0,1000,2.37]],"ltp":1.02,"tv":2.18,"id":22229228,"hc":-11.5}]}]}
{"op":"mcm","clk":"997993422","pt":1580584334313,"mc":[{"id":"1.168081835","rc":[{"trd":[[1.02,2.17]],"batb":[[0,1.02,7.52]],"ltp":1.02,"tv":2.17,"id":22229228,"hc":-9.5},{"trd":[[1.02,2.2]],"batb":[[0,1.02,7.5]],"batl":[[0,990,0.01]],"ltp":1.02,"tv":2.2,"id":22229228,"hc":-11.5}],"tv":6.51}]}
{"op":"mcm","clk":"997993699","pt":1580584335528,"mc":[{"id":"1.168081835","rc":[{"trd":[[1.02,2.16]],"batb":[[0,1.02,7.53]],"ltp":1.02,"tv":2.15,"id":22229228,"hc":-10.5}],"tv":6.52}]}
{"op":"mcm","clk":"997996182","pt":1580584350326,"mc":[{"id":"1.168081835","rc":[{"trd":[[1.02,2.22]],"batb":[[0,1.02,7.49]],"ltp":1.02,"tv":2.21,"id":22229228,"hc":-11.5}],"tv":6.54}]}
{"op":"mcm","clk":"997996403","pt":1580584351681,"mc":[{"id":"1.168081835","rc":[{"trd":[[1.02,2.19]],"batb":[[0,1.02,7.51]],"ltp":1.02,"tv":2.18,"id":22229228,"hc":-9.5},{"batl":[[0,1000,2.37]],"ltp":1.02,"tv":2.15,"id":22229228,"hc":-10.5}],"tv":6.55}]}
{"op":"mcm","clk":"997996508","pt":1580584352275,"mc":[{"id":"1.168081835","rc":[{"trd":[[1.02,2.17]],"batb":[[0,1.02,7.52]],"batl":[[0,990,0.01]],"ltp":1.02,"tv":2.17,"id":22229228,"hc":-10.5}],"tv":6.57}]}
{"op":"mcm","clk":"997998978","pt":1580584366514,"mc":[{"id":"1.168081835","rc":[{"batl":[[0,1000,2.37]],"ltp":1.02,"tv":2.21,"id":22229228,"hc":-11.5}]}]}
{"op":"mcm","clk":"997999142","pt":1580584367304,"mc":[{"id":"1.168081835","rc":[{"trd":[[1.02,2.2]],"batb":[[0,1.02,7.5]],"ltp":1.02,"tv":2.2,"id":22229228,"hc":-9.5},{"trd":[[1.02,2.23]],"batb":[[0,1.02,7.48]],"batl":[[0,990,0.01]],"ltp":1.02,"tv":2.23,"id":22229228,"hc":-11.5}],"tv":6.6}]}
{"op":"mcm","clk":"997999370","pt":1580584368493,"mc":[{"id":"1.168081835","rc":[{"trd":[[1.02,2.19]],"batb":[[0,1.02,7.51]],"ltp":1.02,"tv":2.18,"id":22229228,"hc":-10.5}],"tv":6.62}]}
{"op":"mcm","clk":"998001746","pt":1580584382628,"mc":[{"id":"1.168081835","rc":[{"batl":[[0,1000,2.37]],"ltp":1.02,"tv":2.2,"id":22229228,"hc":-9.5}]}]}
{"op":"mcm","clk":"998001924","pt":1580584383541,"mc":[{"id":"1.168081835","rc":[{"trd":[[1.02,2.22]],"batb":[[0,1.02,7.49]],"batl":[[0,990,0.01]],"ltp":1.02,"tv":2.21,"id":22229228,"hc":-9.5},{"batl":[[0,1000,0.02]],"ltp":1.02,"tv":2.23,"id":22229228,"hc":-11.5}],"tv":6.63}]}
{"op":"mcm","clk":"998002088","pt":1580584384423,"mc":[{"id":"1.168081835","rc":[{"trd":[[1.02,2.2]],"batb":[[0,1.02,7.5]],"ltp":1.02,"tv":2.2,"id":22229228,"hc":-10.5},{"trd":[[1.02,2.25]],"batb":[[0,1.02,7.47]],"batl":[[0,990,0.01]],"ltp":1.02,"tv":2.24,"id":22229228,"hc":-11.5}],"tv":6.66}]}
{"op":"mcm","clk":"998004899","pt":1580584399661,"mc":[{"id":"1.168081835","rc":[{"trd":[[1.02,2.23]],"batb":[[0,1.02,7.48]],"ltp":1.02,"tv":2.23,"id":22229228,"hc":-9.5},{"batl":[[0,1000,0.02]],"ltp":1.02,"tv":2.24,"id":22229228,"hc":-11.5}],"tv":6.68}]}
{"op":"mcm","clk":"998004937","pt":1580584399875,"mc":[{"id":"1.168081835","rc":[{"trd":[[1.02,2.26]],"batb":[[0,1.02,7.46]],"batl":[[0,990,0.01]],"ltp":1.02,"tv":2.26,"id":22229228,"hc":-11.5}],"tv":6.69}]}
{"op":"mcm","clk":"998005229","pt":1580584401365,"mc":[{"id":"1.168081835","rc":[{"trd":[[1.02,2.22]],"batb":[[0,1.02,7.49]],"ltp":1.02,"tv":2.21,"id":22229228,"hc":-10.5}],"tv":6.71}]}
{"op":"mcm","clk":"998007776","pt":1580584415606,"mc":[{"id":"1.168081835","rc":[{"batl":[[0,1000,0.02]],"ltp":1.02,"tv":2.23,"id":22229228,"hc":-9.5},{"batl":[[0,1000,0.02]],"ltp":1.02,"tv":2.26,"id":22229228,"hc":-11.5}]}]}
{"op":"mcm","clk":"998007843","pt":1580584415982,"mc":[{"id":"1.168081835","rc":[{"trd":[[1.02,2.25]],"batb":[[0,1.02,7.47]],"batl":[[0,990,0.01]],"ltp":1.02,"tv":2.24,"id":22229228,"hc":-9.5},{"trd":[[1.02,2.28]],"batb":[[0,1.02,7.45]],"batl":[[0,990,0.01]],"ltp":1.02,"tv":2.27,"id":22229228,"hc":-11.5}],"tv":6.74}]}
{"op":"mcm","clk":"998008111","pt":1580584417613,"mc":[{"id":"1.168081835","rc":[{"batl":[[0,1000,0.02]],"ltp":1.02,"tv":2.21,"id":22229228,"hc":-10.5}]}]}
{"op":"mcm","clk":"998008294","pt":1580584418594,"mc":[{"id":"1.168081835","rc":[{"trd":[[1.02,2.23]],"batb":[[0,1.02,7.48]],"batl":[[0,990,0.01]],"ltp":1.02,"tv":2.23,"id":22229228,"hc":-10.5}],"tv":6.76}]}
{"op":"mcm","clk":"998010649","pt":1580584431618,"mc":[{"id":"1.168081835","rc":[{"batl":[[0,1000,2.37]],"ltp":1.02,"tv":2.24,"id":22229228,"hc":-9.5}]}]}
{"op":"mcm","clk":"998010854","pt":1580584432647,"mc":[{"id":"1.168081835","rc":[{"trd":[[1.02,2.26]],"batb":[[0,1.02,7.46]],"batl":[[0,990,0.01]],"ltp":1.02,"tv":2.26,"id":22229228,"hc":-9.5}],"tv":6.77}]}
{"op":"mcm","clk":"998010875","pt":1580584432706,"mc":[{"id":"1.168081835","rc":[{"trd":[[1.02,2.3]],"batb":[[0,1.02,7.44]],"ltp":1.02,"tv":2.29,"id":22229228,"hc":-11.5}],"tv":6.79}]}
{"op":"mcm","clk":"998011222","pt":1580584434542,"mc":[{"id":"1.168081835","rc":[{"trd":[[1.02,2.25]],"batb":[[0,1.02,7.47]],"ltp":1.02,"tv":2.24,"id":22229228,"hc":-10.5}],"tv":6.8}]}
{"op":"mcm","clk":"998013756","pt":1580584448685,"mc":[{"id":"1.168081835","rc":[{"batl":[[0,1000,2.37]],"ltp":1.02,"tv":2.26,"id":22229228,"hc":-9.5},{"batl":[[0,1000,0.02]],"ltp":1.02,"tv":2.29,"id":22229228,"hc":-11.5}]}]}
{"op":"mcm","clk":"998013856","pt":1580584449246,"mc":[{"id":"1.168081835","rc":[{"trd":[[1.02,2.28]],"batb":[[0,1.02,7.45]],"batl":[[0,990,0.01]],"ltp":1.02,"tv":2.27,"id":22229228,"hc":-9.5},{"trd":[[1.02,2.31]],"batb":[[0,1.02,7.43]],"batl":[[0,990,0.01]],"ltp":1.02,"tv":2.31,"id":22229228,"hc":-11.5}],"tv":6.83}]}
{"op":"mcm","clk":"998014229","pt":1580584451270,"mc":[{"id":"1.168081835","rc":[{"trd":[[1.02,2.26]],"batb":[[0,1.02,7.46]],"ltp":1.02,"tv":2.26,"id":22229228,"hc":-10.5}],"tv":6.85}]}
{"op":"mcm","clk":"998016760","pt":1580584465606,"mc":[{"id":"1.168081835","rc":[{"batl":[[0,1000,0.02]],"ltp":1.02,"tv":2.27,"id":22229228,"hc":-9.5},{"batl":[[0,1000,0.02]],"ltp":1.02,"tv":2.31,"id":22229228,"hc":-11.5}]}]}
{"op":"mcm","clk":"998016836","pt":1580584465994,"mc":[{"id":"1.168081835","rc":[{"trd":[[1.02,2.3]],"batb":[[0,1.02,7.44]],"batl":[[0,990,0.01]],"ltp":1.02,"tv":2.29,"id":22229228,"hc":-9.5},{"trd":[[1.02,2.33]],"batb":[[0,1.02,7.42]],"batl":[[0,990,0.01]],"ltp":1.02,"tv":2.32,"id":22229228,"hc":-11.5}],"tv":6.88}]}
{"op":"mcm","clk":"998017105","pt":1580584467587,"mc":[{"id":"1.168081835","rc":[{"batl":[[0,1000,2.37]],"ltp":1.02,"tv":2.26,"id":22229228,"hc":-10.5}]}]}
{"op":"mcm","clk":"998017227","pt":1580584468194,"mc":[{"id":"1.168081835","rc":[{"trd":[[1.02,2.28]],"batb":[[0,1.02,7.45]],"batl":[[0,990,0.01]],"ltp":1.02,"tv":2.27,"id":22229228,"hc":-10.5}],"tv":6.9}]}
{"op":"mcm","clk":"998019709","pt":1580584481628,"mc":[{"id":"1.168081835","rc":[{"batl":[[0,1000,2.37]],"ltp":1.02,"tv":2.29,"id":22229228,"hc":-9.5}]}]}
{"op":"mcm","clk":"998019912","pt":1580584482626,"mc":[{"id":"1.168081835","rc":[{"trd":[[1.02,2.31]],"batb":[[0,1.02,7.43]],"batl":[[0,990,0.01]],"ltp":1.02,"tv":2.31,"id":22229228,"hc":-9.5},{"trd":[[1.02,2.34]],"batb":[[0,1.02,7.41]],"ltp":1.02,"tv":2.34,"id":22229228,"hc":-11.5}],"tv":6.93}]}
{"op":"mcm","clk":"998020282","pt":1580584484472,"mc":[{"id":"1.168081835","rc":[{"trd":[[1.02,2.3]],"batb":[[0,1.02,7.44]],"ltp":1.02,"tv":2.29,"id":22229228,"hc":-10.5}],"tv":6.94}]}
{"op":"mcm","clk":"998022854","pt":1580584498592,"mc":[{"id":"1.168081835","rc":[{"trd":[[1.02,2.36]],"batb":[[0,1.02,7.4]],"ltp":1.02,"tv":2.35,"id":22229228,"hc":-11.5}],"tv":6.96}]}
{"op":"mcm","clk":"998023008","pt":1580584499376,"mc":[{"id":"1.168081835","rc":[{"trd":[[1.02,2.33]],"batb":[[0,1.02,7.42]],"ltp":1.02,"tv":2.32,"id":22229228,"hc":-9.5}],"tv":6.97}]}
{"op":"mcm","clk":"998023248","pt":1580584500698,"mc":[{"id":"1.168081835","rc":[{"batl":[[0,1000,0.02]],"ltp":1.02,"tv":2.29,"id":22229228,"hc":-10.5}]}]}
{"op":"mcm","clk":"998023315","pt":1580584501038,"mc":[{"id":"1.168081835","rc":[{"trd":[[1.02,2.31]],"batb":[[0,1.02,7.43]],"batl":[[0,990,0.01]],"ltp":1.02,"tv":2.31,"id":22229228,"hc":-10.5}],"tv":6.99}]}
{"op":"mcm","clk":"998026049","pt":1580584515629,"mc":[{"id":"1.168081835","rc":[{"batl":[[0,1000,0.02]],"ltp":1.02,"tv":2.32,"id":22229228,"hc":-9.5},{"trd":[[1.02,2.37]],"batb":[[0,1.02,7.39]],"ltp":1.02,"tv":2.37,"id":22229228,"hc":-11.5}],"tv":7.0}]}
{"op":"mcm","clk":"998026130","pt":1580584516018,"mc":[{"id":"1.168081835","rc":[{"trd":[[1.02,2.34]],"batb":[[0,1.02,7.41]],"batl":[[0,990,0.01]],"ltp":1.02,"tv":2.34,"id":22229228,"hc":-9.5}],"tv":7.02}]}
{"op":"mcm","clk":"998026443","pt":1580584517614,"mc":[{"id":"1.168081835","rc":[{"batl":[[0,1000,0.02]],"ltp":1.02,"tv":2.31,"id":22229228,"hc":-10.5}]}]}
{"op":"mcm","clk":"998026674","pt":1580584518701,"mc":[{"id":"1.168081835","rc":[{"trd":[[1.02,2.33]],"batb":[[0,1.02,7.42]],"batl":[[0,990,0.01]],"ltp":1.02,"tv":2.32,"id":22229228,"hc":-10.5}],"tv":7.04}]}
{"op":"mcm","clk":"998029044","pt":1580584531678,"mc":[{"id":"1.168081835","rc":[{"batl":[[0,1000,0.02]],"ltp":1.02,"tv":2.37,"id":22229228,"hc":-11.5}]}]}
{"op":"mcm","clk":"998029206","pt":1580584532572,"mc":[{"id":"1.168081835","rc":[{"batl":[[0,1000,0.02]],"ltp":1.02,"tv":2.34,"id":22229228,"hc":-9.5},{"trd":[[1.02,2.39]],"batb":[[0,1.02,7.38]],"batl":[[0,990,0.01]],"ltp":1.02,"tv":2.38,"id":22229228,"hc":-11.5}],"tv":7.05}]}
{"op":"mcm","clk":"998029265","pt":1580584532857,"mc":[{"id":"1.168081835","rc":[{"trd":[[1.02,2.36]],"batb":[[0,1.02,7.4]],"batl":[[0,990,0.01]],"ltp":1.02,"tv":2.35,"id":22229228,"hc":-9.5}],"tv":7.07}]}
{"op":"mcm","clk":"998029596","pt":1580584534646,"mc":[{"id":"1.168081835","rc":[{"batl":[[0,1000,2.37]],"ltp":1.02,"tv":2.32,"id":22229228,"hc":-10.5}]}]}
{"op":"mcm","clk":"998029745","pt":1580584535391,"mc":[{"id":"1.168081835","rc":[{"trd":[[1.02,2.34]],"batb":[[0,1.02,7.41]],"batl":[[0,990,0.01]],"ltp":1.02,"tv":2.34,"id":22229228,"hc":-10.5}],"tv":7.08}]}
{"op":"mcm","clk":"998032281","pt":1580584548685,"mc":[{"id":"1.168081835","rc":[{"batl":[[0,1000,2.37]],"ltp":1.02,"tv":2.35,"id":22229228,"hc":-9.5},{"trd":[[1.02,2.4]],"batb":[[0,1.02,7.37]],"ltp":1.02,"tv":2.4,"id":22229228,"hc":-11.5}],"tv":7.1}]}
{"op":"mcm","clk":"998032375","pt":1580584549172,"mc":[{"id":"1.168081835","rc":[{"trd":[[1.02,2.37]],"batb":[[0,1.02,7.39]],"batl":[[0,990,0.01]],"ltp":1.02,"tv":2.37,"id":22229228,"hc":-9.5}],"tv":7.11}]}
{"op":"mcm","clk":"998032851","pt":1580584551516,"mc":[{"id":"1.168081835","rc":[{"batl":[[0,1000,2.37]],"ltp":1.02,"tv":2.34,"id":22229228,"hc":-10.5}]}]}
{"op":"mcm","clk":"998032972","pt":1580584552105,"mc":[{"id":"1.168081835","rc":[{"trd":[[1.02,2.36]],"batb":[[0,1.02,7.4]],"batl":[[0,990,0.01]],"ltp":1.02,"tv":2.35,"id":22229228,"hc":-10.5}],"tv":7.13}]}
{"op":"mcm","clk":"998035779","pt":1580584566292,"mc":[{"id":"1.168081835","rc":[{"trd":[[1.02,2.39]],"batb":[[0,1.02,7.38]],"ltp":1.02,"tv":2.38,"id":22229228,"hc":-9.5},{"trd":[[1.02,2.42]],"batb":[[0,1.02,7.36]],"ltp":1.02,"tv":2.41,"id":22229228,"hc":-11.5}],"tv":7.16}]}
{"op":"mcm","clk":"998036425","pt":1580584569517,"mc":[{"id":"1.168081835","rc":[{"trd":[[1.02,2.37]],"batb":[[0,1.02,7.39]],"ltp":1.02,"tv":2.37,"id":22229228,"hc":-10.5}],"tv":7.18}]}
{"op":"mcm","clk":"998038932","pt":1580584582538,"mc":[{"id":"1.168081835","rc":[{"trd":[[1.02,2.43]],"batb":[[0,1.02,7.35]],"ltp":1.02,"tv":2.43,"id":22229228,"hc":-11.5}],"tv":7.19}]}
{"op":"mcm","clk":"998039097","pt":1580584583347,"mc":[{"id":"1.168081835","rc":[{"trd":[[1.02,2.4]],"batb":[[0,1.02,7.37]],"ltp":1.02,"tv":2.4,"id":22229228,"hc":-9.5}],"tv":7.21}]}
{"op":"mcm","clk":"998039312","pt":1580584584545,"mc":[{"id":"1.168081835","rc":[{"batl":[[0,1000,2.37]],"ltp":1.02,"tv":2.37,"id":22229228,"hc":-10.5}]}]}
{"op":"mcm","clk":"998039431","pt":1580584585151,"mc":[{"id":"1.168081835","rc":[{"trd":[[1.02,2.39]],"batb":[[0,1.02,7.38]],"batl":[[0,990,0.01]],"ltp":1.02,"tv":2.38,"id":22229228,"hc":-10.5}],"tv":7.22}]}
{"op":"mcm","clk":"998041957","pt":1580584598596,"mc":[{"id":"1.168081835","rc":[{"batl":[[0,1000,2.37]],"ltp":1.02,"tv":2.43,"id":22229228,"hc":-11.5}]}]}
{"op":"mcm","clk":"998042164","pt":1580584599611,"mc":[{"id":"1.168081835","rc":[{"trd":[[1.02,2.42]],"batb":[[0,1.02,7.36]],"ltp":1.02,"tv":2.41,"id":22229228,"hc":-9.5},{"trd":[[1.02,2.45]],"batb":[[0,1.02,7.34]],"batl":[[0,990,0.01]],"ltp":1.02,"tv":2.45,"id":22229228,"hc":-11.5}],"tv":7.25}]}
{"op":"mcm","clk":"998042378","pt":1580584600688,"mc":[{"id":"1.168081835","rc":[{"batl":[[0,1000,2.37]],"ltp":1.02,"tv":2.38,"id":22229228,"hc":-10.5}]}]}
{"op":"mcm","clk":"998042490","pt":1580584601310,"mc":[{"id":"1.168081835","rc":[{"trd":[[1.02,2.4]],"batb":[[0,1.02,7.37]],"batl":[[0,990,0.01]],"ltp":1.02,"tv":2.4,"id":22229228,"hc":-10.5}],"tv":7.27}]}
{"op":"mcm","clk":"998045160","pt":1580584615505,"mc":[{"id":"1.168081835","rc":[{"batl":[[0,1000,2.37]],"ltp":1.02,"tv":2.45,"id":22229228,"hc":-11.5}]}]}
{"op":"mcm","clk":"998045330","pt":1580584616343,"mc":[{"id":"1.168081835","rc":[{"trd":[[1.02,2.43]],"batb":[[0,1.02,7.35]],"ltp":1.02,"tv":2.43,"id":22229228,"hc":-9.5},{"trd":[[1.02,2.47]],"batb":[[0,1.02,7.33]],"batl":[[0,990,0.01]],"ltp":1.02,"tv":2.46,"id":22229228,"hc":-11.5}],"tv":7.3}]}
{"op":"mcm","clk":"998045587","pt":1580584617606,"mc":[{"id":"1.168081835","rc":[{"trd":[[1.02,2.42]],"batb":[[0,1.02,7.36]],"ltp":1.02,"tv":2.41,"id":22229228,"hc":-10.5}],"tv":7.31}]}
{"op":"mcm","clk":"998048511","pt":1580584632696,"mc":[{"id":"1.168081835","rc":[{"trd":[[1.02,2.45]],"batb":[[0,1.02,7.34]],"ltp":1.02,"tv":2.45,"id":22229228,"hc":-9.5},{"trd":[[1.02,2.48]],"batb":[[0,1.02,7.32]],"ltp":1.02,"tv":2.48,"id":22229228,"hc":-11.5}],"tv":7.35}]}
{"op":"mcm","clk":"998048973","pt":1580584634785,"mc":[{"id":"1.168081835","rc":[{"trd":[[1.02,2.43]],"batb":[[0,1.02,7.35]],"ltp":1.02,"tv":2.43,"id":22229228,"hc":-10.5}],"tv":7.36}]}
{"op":"mcm","clk":"998051675","pt":1580584648645,"mc":[{"id":"1.168081835","rc":[{"trd":[[1.02,2.5]],"batb":[[0,1.02,7.31]],"ltp":1.02,"tv":2.49,"id":22229228,"hc":-11.5}],"tv":7.38}]}
{"op":"mcm","clk":"998051831","pt":1580584649449,"mc":[{"id":"1.168081835","rc":[{"trd":[[1.02,2.47]],"batb":[[0,1.02,7.33]],"ltp":1.02,"tv":2.46,"id":22229228,"hc":-9.5}],"tv":7.39}]}
{"op":"mcm","clk":"998052273","pt":1580584651442,"mc":[{"id":"1.168081835","rc":[{"batl":[[0,1000,0.02]],"ltp":1.02,"tv":2.43,"id":22229228,"hc":-10.5}]}]}
{"op":"mcm","clk":"998052355","pt":1580584651854,"mc":[{"id":"1.168081835","rc":[{"trd":[[1.02,2.45]],"batb":[[0,1.02,7.34]],"batl":[[0,990,0.01]],"ltp":1.02,"tv":2.45,"id":22229228,"hc":-10.5}],"tv":7.41}]}
{"op":"mcm","clk":"998055130","pt":1580584665671,"mc":[{"id":"1.168081835","rc":[{"trd":[[1.02,2.48]],"batb":[[0,1.02,7.32]],"ltp":1.02,"tv":2.48,"id":22229228,"hc":-9.5}],"tv":7.42}]}
{"op":"mcm","clk":"998055153","pt":1580584665798,"mc":[{"id":"1.168081835","rc":[{"trd":[[1.02,2.51]],"batb":[[0,1.02,7.3]],"ltp":1.02,"tv":2.51,"id":22229228,"hc":-11.5}],"tv":7.44}]}
{"op":"mcm","clk":"998055747","pt":1580584668616,"mc":[{"id":"1.168081835","rc":[{"trd":[[1.02,2.47]],"batb":[[0,1.02,7.33]],"ltp":1.02,"tv":2.46,"id":22229228,"hc":-10.5}],"tv":7.45}]}
{"op":"mcm","clk":"998058123","pt":1580584681517,"mc":[{"id":"1.168081835","rc":[{"trd":[[1.02,2.5]],"batb":[[0,1.02,7.31]],"ltp":1.02,"tv":2.49,"id":22229228,"hc":-9.5}],"tv":7.47}]}
{"op":"mcm","clk":"998058316","pt":1580584682514,"mc":[{"id":"1.168081835","rc":[{"trd":[[1.02,2.53]],"batb":[[0,1.02,7.29]],"ltp":1.02,"tv":2.52,"id":22229228,"hc":-11.5}],"tv":7.49}]}
{"op":"mcm","clk":"998058764","pt":1580584684904,"mc":[{"id":"1.168081835","rc":[{"batl":[[0,1000,0.02]],"ltp":1.02,"tv":2.46,"id":22229228,"hc":-10.5}]}]}
{"op":"mcm","clk":"998059086","pt":1580584686523,"mc":[{"id":"1.168081835","rc":[{"trd":[[1.02,2.48]],"batb":[[0,1.02,7.32]],"batl":[[0,990,0.01]],"ltp":1.02,"tv":2.48,"id":22229228,"hc":-10.5}],"tv":7.5}]}
{"op":"mcm","clk":"998061015","pt":1580584697534,"mc":[{"id":"1.168081835","rc":[{"batl":[[0,1000,2.37]],"ltp":1.02,"tv":2.49,"id":22229228,"hc":-9.5}]}]}
{"op":"mcm","clk":"998061158","pt":1580584698257,"mc":[{"id":"1.168081835","rc":[{"trd":[[1.02,2.51]],"batb":[[0,1.02,7.3]],"batl":[[0,990,0.01]],"ltp":1.02,"tv":2.51,"id":22229228,"hc":-9.5}],"tv":7.52}]}
{"op":"mcm","clk":"998061381","pt":1580584699459,"mc":[{"id":"1.168081835","rc":[{"trd":[[1.02,2.54]],"batb":[[0,1.02,7.28]],"ltp":1.02,"tv":2.54,"id":22229228,"hc":-11.5}],"tv":7.53}]}
{"op":"mcm","clk":"998061952","pt":1580584702581,"mc":[{"id":"1.168081835","rc":[{"batl":[[0,1000,2.37]],"ltp":1.02,"tv":2.48,"id":22229228,"hc":-10.5}]}]}
{"op":"mcm","clk":"998062059","pt":1580584703184,"mc":[{"id":"1.168081835","rc":[{"trd":[[1.02,2.5]],"batb":[[0,1.02,7.31]],"batl":[[0,990,0.01]],"ltp":1.02,"tv":2.49,"id":22229228,"hc":-10.5}],"tv":7.55}]}
{"op":"mcm","clk":"998064159","pt":1580584714483,"mc":[{"id":"1.168081835","rc":[{"trd":[[1.02,2.53]],"batb":[[0,1.02,7.29]],"ltp":1.02,"tv":2.52,"id":22229228,"hc":-9.5}],"tv":7.56}]}
{"op":"mcm","clk":"998064392","pt":1580584715677,"mc":[{"id":"1.168081835","rc":[{"batl":[[0,1000,0.02]],"ltp":1.02,"tv":2.54,"id":22229228,"hc":-11.5}]}]}
{"op":"mcm","clk":"998064444","pt":1580584715968,"mc":[{"id":"1.168081835","rc":[{"trd":[[1.02,2.56]],"batb":[[0,1.02,7.27]],"batl":[[0,990,0.01]],"ltp":1.02,"tv":2.55,"id":22229228,"hc":-11.5}],"tv":7.58}]}
{"op":"mcm","clk":"998065105","pt":1580584719495,"mc":[{"id":"1.168081835","rc":[{"batl":[[0,1000,0.02]],"ltp":1.02,"tv":2.49,"id":22229228,"hc":-10.5}]}]}
{"op":"mcm","clk":"998065182","pt":1580584719878,"mc":[{"id":"1.168081835","rc":[{"trd":[[1.02,2.51]],"batb":[[0,1.02,7.3]],"batl":[[0,990,0.01]],"ltp":1.02,"tv":2.51,"id":22229228,"hc":-10.5}],"tv":7.59}]}
{"op":"mcm","clk":"998067175","pt":1580584730635,"mc":[{"id":"1.168081835","rc":[{"batl":[[0,1000,0.02]],"ltp":1.02,"tv":2.52,"id":22229228,"hc":-9.5}]}]}
{"op":"mcm","clk":"998067265","pt":1580584731018,"mc":[{"id":"1.168081835","rc":[{"trd":[[1.02,2.54]],"batb":[[0,1.02,7.28]],"batl":[[0,990,0.01]],"ltp":1.02,"tv":2.54,"id":22229228,"hc":-9.5}],"tv":7.61}]}
{"op":"mcm","clk":"998067603","pt":1580584732623,"mc":[{"id":"1.168081835","rc":[{"batl":[[0,1000,0.02]],"ltp":1.02,"tv":2.55,"id":22229228,"hc":-11.5}]}]}
{"op":"mcm","clk":"998067693","pt":1580584733007,"mc":[{"id":"1.168081835","rc":[{"trd":[[1.02,2.57]],"batb":[[0,1.02,7.26]],"batl":[[0,990,0.01]],"ltp":1.02,"tv":2.57,"id":22229228,"hc":-11.5}],"tv":7.62}]}
{"op":"mcm","clk":"998068389","pt":1580584736691,"mc":[{"id":"1.168081835","rc":[{"batl":[[0,1000,0.02]],"ltp":1.02,"tv":2.51,"id":22229228,"hc":-10.5}]}]}
{"op":"mcm","clk":"998068452","pt":1580584737008,"mc":[{"id":"1.168081835","rc":[{"trd":[[1.02,2.53]],"batb":[[0,1.02,7.29]],"batl":[[0,990,0.01]],"ltp":1.02,"tv":2.52,"id":22229228,"hc":-10.5}],"tv":7.64}]}
{"op":"mcm","clk":"998070105","pt":1580584746651,"mc":[{"id":"1.168081835","rc":[{"batl":[[0,1000,0.02]],"ltp":1.02,"tv":2.54,"id":22229228,"hc":-9.5}]}]}
{"op":"mcm","clk":"998070173","pt":1580584747018,"mc":[{"id":"1.168081835","rc":[{"trd":[[1.02,2.56]],"batb":[[0,1.02,7.27]],"batl":[[0,990,0.01]],"ltp":1.02,"tv":2.55,"id":22229228,"hc":-9.5}],"tv":7.66}]}
{"op":"mcm","clk":"998070475","pt":1580584748647,"mc":[{"id":"1.168081835","rc":[{"batl":[[0,1000,2.37]],"ltp":1.02,"tv":2.57,"id":22229228,"hc":-11.5}]}]}
{"op":"mcm","clk":"998070577","pt":1580584749249,"mc":[{"id":"1.168081835","rc":[{"trd":[[1.02,2.59]],"batb":[[0,1.02,7.25]],"batl":[[0,990,0.01]],"ltp":1.02,"tv":2.58,"id":22229228,"hc":-11.5}],"tv":7.67}]}
{"op":"mcm","clk":"998071309","pt":1580584753439,"mc":[{"id":"1.168081835","rc":[{"trd":[[1.02,2.54]],"batb":[[0,1.02,7.28]],"ltp":1.02,"tv":2.54,"id":22229228,"hc":-10.5}],"tv":7.69}]}
{"op":"mcm","clk":"998073131","pt":1580584763739,"mc":[{"id":"1.168081835","rc":[{"trd":[[1.02,2.57]],"batb":[[0,1.02,7.26]],"ltp":1.02,"tv":2.57,"id":22229228,"hc":-9.5}],"tv":7.7}]}
{"op":"mcm","clk":"998073510","pt":1580584765735,"mc":[{"id":"1.168081835","rc":[{"trd":[[1.02,2.61]],"batb":[[0,1.02,7.24]],"ltp":1.02,"tv":2.6,"id":22229228,"hc":-11.5}],"tv":7.72}]}
{"op":"mcm","clk":"998074236","pt":1580584769629,"mc":[{"id":"1.168081835","rc":[{"trd":[[1.02,2.56]],"batb":[[0,1.02,7.27]],"ltp":1.02,"tv":2.55,"id":22229228,"hc":-10.5}],"tv":7.73}]}
{"op":"mcm","clk":"998076004","pt":1580584780462,"mc":[{"id":"1.168081835","rc":[{"batl":[[0,1000,2.37]],"ltp":1.02,"tv":2.57,"id":22229228,"hc":-9.5}]}]}
{"op":"mcm","clk":"998076174","pt":1580584781376,"mc":[{"id":"1.168081835","rc":[{"trd":[[1.02,2.59]],"batb":[[0,1.02,7.25]],"batl":[[0,990,0.01]],"ltp":1.02,"tv":2.58,"id":22229228,"hc":-9.5},{"batl":[[0,1000,2.37]],"ltp":1.02,"tv":2.6,"id":22229228,"hc":-11.5}],"tv":7.75}]}
{"op":"mcm","clk":"998076313","pt":1580584782174,"mc":[{"id":"1.168081835","rc":[{"trd":[[1.02,2.62]],"batb":[[0,1.02,7.23]],"batl":[[0,990,0.01]],"ltp":1.02,"tv":2.62,"id":22229228,"hc":-11.5}],"tv":7.76}]}
{"op":"mcm","clk":"998077031","pt":1580584786677,"mc":[{"id":"1.168081835","rc":[{"trd":[[1.02,2.57]],"batb":[[0,1.02,7.26]],"ltp":1.02,"tv":2.57,"id":22229228,"hc":-10.5}],"tv":7.78}]}
{"op":"mcm","clk":"998078780","pt":1580584797402,"mc":[{"id":"1.168081835","rc":[{"batl":[[0,1000,2.37]],"ltp":1.02,"tv":2.58,"id":22229228,"hc":-9.5}]}]}
{"op":"mcm","clk":"998079008","pt":1580584798629,"mc":[{"id":"1.168081835","rc":[{"trd":[[1.02,2.61]],"batb":[[0,1.02,7.24]],"batl":[[0,990,0.01]],"ltp":1.02,"tv":2.6,"id":22229228,"hc":-9.5},{"trd":[[1.02,2.64]],"batb":[[0,1.02,7.22]],"ltp":1.02,"tv":2.63,"id":22229228,"hc":-11.5}],"tv":7.81}]}
{"op":"mcm","clk":"998079846","pt":1580584803528,"mc":[{"id":"1.168081835","rc":[{"batl":[[0,1000,0.02]],"ltp":1.02,"tv":2.57,"id":22229228,"hc":-10.5}]}]}
{"op":"mcm","clk":"998080043","pt":1580584804606,"mc":[{"id":"1.168081835","rc":[{"trd":[[1.02,2.59]],"batb":[[0,1.02,7.25]],"batl":[[0,990,0.01]],"ltp":1.02,"tv":2.58,"id":22229228,"hc":-10.5}],"tv":7.83}]}
{"op":"mcm","clk":"998081490","pt":1580584813693,"mc":[{"id":"1.168081835","rc":[{"batl":[[0,1000,0.02]],"ltp":1.02,"tv":2.6,"id":22229228,"hc":-9.5}]}]}
{"op":"mcm","clk":"998081659","pt":1580584814665,"mc":[{"id":"1.168081835","rc":[{"trd":[[1.02,2.62]],"batb":[[0,1.02,7.23]],"batl":[[0,990,0.01]],"ltp":1.02,"tv":2.62,"id":22229228,"hc":-9.5},{"batl":[[0,1000,0.02]],"ltp":1.02,"tv":2.63,"id":22229228,"hc":-11.5}],"tv":7.84}]}
{"op":"mcm","clk":"998081732","pt":1580584815090,"mc":[{"id":"1.168081835","rc":[{"trd":[[1.02,2.65]],"batb":[[0,1.02,7.21]],"batl":[[0,990,0.01]],"ltp":1.02,"tv":2.65,"id":22229228,"hc":-11.5}],"tv":7.86}]}
{"op":"mcm","clk":"998082633","pt":1580584820673,"mc":[{"id":"1.168081835","rc":[{"batl":[[0,1000,0.02]],"ltp":1.02,"tv":2.58,"id":22229228,"hc":-10.5}]}]}
{"op":"mcm","clk":"998082801","pt":1580584821684,"mc":[{"id":"1.168081835","rc":[{"trd":[[1.02,2.61]],"batb":[[0,1.02,7.24]],"batl":[[0,990,0.01]],"ltp":1.02,"tv":2.6,"id":22229228,"hc":-10.5}],"tv":7.87}]}
{"op":"mcm","clk":"998084190","pt":1580584830602,"mc":[{"id":"1.168081835","rc":[{"batl":[[0,1000,2.37]],"ltp":1.02,"tv":2.62,"id":22229228,"hc":-9.5},{"batl":[[0,1000,2.37]],"ltp":1.02,"tv":2.65,"id":22229228,"hc":-11.5}]}]}
{"op":"mcm","clk":"998084300","pt":1580584831311,"mc":[{"id":"1.168081835","rc":[{"trd":[[1.02,2.64]],"batb":[[0,1.02,7.22]],"batl":[[0,990,0.01]],"ltp":1.02,"tv":2.63,"id":22229228,"hc":-9.5},{"trd":[[1.02,2.67]],"batb":[[0,1.02,7.2]],"batl":[[0,990,0.01]],"ltp":1.02,"tv":2.66,"id":22229228,"hc":-11.5}],"tv":7.9}]}
{"op":"mcm","clk":"998085397","pt":1580584837616,"mc":[{"id":"1.168081835","rc":[{"batl":[[0,1000,0.02]],"ltp":1.02,"tv":2.6,"id":22229228,"hc":-10.5}]}]}
{"op":"mcm","clk":"998085625","pt":1580584838699,"mc":[{"id":"1.168081835","rc":[{"trd":[[1.02,2.62]],"batb":[[0,1.02,7.23]],"batl":[[0,990,0.01]],"ltp":1.02,"tv":2.62,"id":22229228,"hc":-10.5}],"tv":7.92}]}
{"op":"mcm","clk":"998087151","pt":1580584847521,"mc":[{"id":"1.168081835","rc":[{"batl":[[0,1000,0.02]],"ltp":1.02,"tv":2.63,"id":22229228,"hc":-9.5},{"trd":[[1.02,2.68]],"batb":[[0,1.02,7.19]],"ltp":1.02,"tv":2.68,"id":22229228,"hc":-11.5}],"tv":7.93}]}
{"op":"mcm","clk":"998087208","pt":1580584847854,"mc":[{"id":"1.168081835","rc":[{"trd":[[1.02,2.65]],"batb":[[0,1.02,7.21]],"batl":[[0,990,0.01]],"ltp":1.02,"tv":2.65,"id":22229228,"hc":-9.5}],"tv":7.95}]}
{"op":"mcm","clk":"998088537","pt":1580584855480,"mc":[{"id":"1.168081835","rc":[{"trd":[[1.02,2.64]],"batb":[[0,1.02,7.22]],"ltp":1.02,"tv":2.63,"id":22229228,"hc":-10.5}],"tv":7.97}]}
{"op":"mcm","clk":"998089912","pt":1580584863442,"mc":[{"id":"1.168081835","rc":[{"batl":[[0,1000,2.37]],"ltp":1.02,"tv":2.65,"id":22229228,"hc":-9.5},{"batl":[[0,1000,2.37]],"ltp":1.02,"tv":2.68,"id":22229228,"hc":-11.5}]}]}
{"op":"mcm","clk":"998090031","pt":1580584864188,"mc":[{"id":"1.168081835","rc":[{"trd":[[1.02,2.67]],"batb":[[0,1.02,7.2]],"batl":[[0,990,0.01]],"ltp":1.02,"tv":2.66,"id":22229228,"hc":-9.5},{"trd":[[1.02,2.7]],"batb":[[0,1.02,7.18]],"batl":[[0,990,0.01]],"ltp":1.02,"tv":2.69,"id":22229228,"hc":-11.5}],"tv":8.0}]}
{"op":"mcm","clk":"998091160","pt":1580584870602,"mc":[{"id":"1.168081835","rc":[{"batl":[[0,1000,2.37]],"ltp":1.02,"tv":2.63,"id":22229228,"hc":-10.5}]}]}
{"op":"mcm","clk":"998091309","pt":1580584871273,"mc":[{"id":"1.168081835","rc":[{"trd":[[1.02,2.65]],"batb":[[0,1.02,7.21]],"batl":[[0,990,0.01]],"ltp":1.02,"tv":2.65,"id":22229228,"hc":-10.5}],"tv":8.01}]}
{"op":"mcm","clk":"998092951","pt":1580584880696,"mc":[{"id":"1.168081835","rc":[{"trd":[[1.02,2.68]],"batb":[[0,1.02,7.19]],"ltp":1.02,"tv":2.68,"id":22229228,"hc":-9.5},{"batl":[[0,1000,0.02]],"ltp":1.02,"tv":2.69,"id":22229228,"hc":-11.5}],"tv":8.03}]}
{"op":"mcm","clk":"998093023","pt":1580584881185,"mc":[{"id":"1.168081835","rc":[{"trd":[[1.02,2.71]],"batb":[[0,1.02,7.17]],"batl":[[0,990,0.01]],"ltp":1.02,"tv":2.71,"id":22229228,"hc":-11.5}],"tv":8.04}]}
{"op":"mcm","clk":"998094298","pt":1580584888285,"mc":[{"id":"1.168081835","rc":[{"trd":[[1.02,2.67]],"batb":[[0,1.02,7.2]],"ltp":1.02,"tv":2.66,"id":22229228,"hc":-10.5}],"tv":8.06}]}
{"op":"mcm","clk":"998095836","pt":1580584897527,"mc":[{"id":"1.168081835","rc":[{"trd":[[1.02,2.7]],"batb":[[0,1.02,7.18]],"ltp":1.02,"tv":2.69,"id":22229228,"hc":-9.5},{"batl":[[0,1000,2.37]],"ltp":1.02,"tv":2.71,"id":22229228,"hc":-11.5}],"tv":8.07}]}
{"op":"mcm","clk":"998095913","pt":1580584898060,"mc":[{"id":"1.168081835","rc":[{"trd":[[1.02,2.73]],"batb":[[0,1.02,7.16]],"batl":[[0,990,0.01]],"ltp":1.02,"tv":2.72,"id":22229228,"hc":-11.5}],"tv":8.09}]}
{"op":"mcm","clk":"998097214","pt":1580584905766,"mc":[{"id":"1.168081835","rc":[{"trd":[[1.02,2.68]],"batb":[[0,1.02,7.19]],"ltp":1.02,"tv":2.68,"id":22229228,"hc":-10.5}],"tv":8.11}]}
{"op":"mcm","clk":"998098510","pt":1580584913479,"mc":[{"id":"1.168081835","rc":[{"batl":[[0,1000,0.02]],"ltp":1.02,"tv":2.69,"id":22229228,"hc":-9.5}]}]}
{"op":"mcm","clk":"998098692","pt":1580584914571,"mc":[{"id":"1.168081835","rc":[{"trd":[[1.02,2.71]],"batb":[[0,1.02,7.17]],"batl":[[0,990,0.01]],"ltp":1.02,"tv":2.71,"id":22229228,"hc":-9.5},{"batl":[[0,1000,0.02]],"ltp":1.02,"tv":2.72,"id":22229228,"hc":-11.5}],"tv":8.12}]}
{"op":"mcm","clk":"998098793","pt":1580584915159,"mc":[{"id":"1.168081835","rc":[{"trd":[[1.02,2.74]],"batb":[[0,1.02,7.15]],"batl":[[0,990,0.01]],"ltp":1.02,"tv":2.74,"id":22229228,"hc":-11.5}],"tv":8.14}]}
{"op":"mcm","clk":"998099995","pt":1580584922362,"mc":[{"id":"1.168081835","rc":[{"trd":[[1.02,2.7]],"batb":[[0,1.02,7.18]],"ltp":1.02,"tv":2.69,"id":22229228,"hc":-10.5}],"tv":8.15}]}
{"op":"mcm","clk":"998101308","pt":1580584930553,"mc":[{"id":"1.168081835","rc":[{"trd":[[1.02,2.73]],"batb":[[0,1.02,7.16]],"ltp":1.02,"tv":2.72,"id":22229228,"hc":-9.5}],"tv":8.17}]}
{"op":"mcm","clk":"998101431","pt":1580584931364,"mc":[{"id":"1.168081835","rc":[{"trd":[[1.02,2.76]],"batb":[[0,1.02,7.14]],"ltp":1.02,"tv":2.76,"id":22229228,"hc":-11.5}],"tv":8.18}]}
{"op":"mcm","clk":"998102625","pt":1580584938609,"mc":[{"id":"1.168081835","rc":[{"batl":[[0,1000,0.02]],"ltp":1.02,"tv":2.69,"id":22229228,"hc":-10.5}]}]}
{"op":"mcm","clk":"998102816","pt":1580584939682,"mc":[{"id":"1.168081835","rc":[{"trd":[[1.02,2.71]],"batb":[[0,1.02,7.17]],"batl":[[0,990,0.01]],"ltp":1.02,"tv":2.71,"id":22229228,"hc":-10.5}],"tv":8.2}]}
{"op":"mcm","clk":"998104070","pt":1580584947609,"mc":[{"id":"1.168081835","rc":[{"batl":[[0,1000,0.02]],"ltp":1.02,"tv":2.72,"id":22229228,"hc":-9.5}]}]}
{"op":"mcm","clk":"998104237","pt":1580584948521,"mc":[{"id":"1.168081835","rc":[{"trd":[[1.02,2.74]],"batb":[[0,1.02,7.15]],"batl":[[0,990,0.01]],"ltp":1.02,"tv":2.74,"id":22229228,"hc":-9.5},{"trd":[[1.02,2.78]],"batb":[[0,1.02,7.13]],"ltp":1.02,"tv":2.77,"id":22229228,"hc":-11.5}],"tv":8.23}]}
{"op":"mcm","clk":"998105247","pt":1580584954554,"mc":[{"id":"1.168081835","rc":[{"trd":[[1.02,2.73]],"batb":[[0,1.02,7.16]],"ltp":1.02,"tv":2.72,"id":22229228,"hc":-10.5}],"tv":8.25}]}
{"op":"mcm","clk":"998106789","pt":1580584964510,"mc":[{"id":"1.168081835","rc":[{"batl":[[0,1000,2.37]],"ltp":1.02,"tv":2.74,"id":22229228,"hc":-9.5},{"batl":[[0,1000,2.37]],"ltp":1.02,"tv":2.77,"id":22229228,"hc":-11.5}]}]}
{"op":"mcm","clk":"998106860","pt":1580584964988,"mc":[{"id":"1.168081835","rc":[{"trd":[[1.02,2.76]],"batb":[[0,1.02,7.14]],"batl":[[0,990,0.01]],"ltp":1.02,"tv":2.76,"id":22229228,"hc":-9.5},{"trd":[[1.02,2.79]],"batb":[[0,1.02,7.12]],"batl":[[0,990,0.01]],"ltp":1.02,"tv":2.79,"id":22229228,"hc":-11.5}],"tv":8.28}]}
{"op":"mcm","clk":"998107694","pt":1580584971440,"mc":[{"id":"1.168081835","rc":[{"trd":[[1.02,2.74]],"batb":[[0,1.02,7.15]],"ltp":1.02,"tv":2.74,"id":22229228,"hc":-10.5}],"tv":8.29}]}
{"op":"mcm","clk":"998109395","pt":1580584981667,"mc":[{"id":"1.168081835","rc":[{"batl":[[0,1000,0.02]],"ltp":1.02,"tv":2.76,"id":22229228,"hc":-9.5},{"trd":[[1.02,2.81]],"batb":[[0,1.02,7.11]],"ltp":1.02,"tv":2.8,"id":22229228,"hc":-11.5}],"tv":8.31}]}
{"op":"mcm","clk":"998109468","pt":1580584982149,"mc":[{"id":"1.168081835","rc":[{"trd":[[1.02,2.78]],"batb":[[0,1.02,7.13]],"batl":[[0,990,0.01]],"ltp":1.02,"tv":2.77,"id":22229228,"hc":-9.5}],"tv":8.32}]}
{"op":"mcm","clk":"998110187","pt":1580584986683,"mc":[{"id":"1.168081835","rc":[{"batl":[[0,1000,0.02]],"ltp":1.02,"tv":2.74,"id":22229228,"hc":-10.5}]}]}
{"op":"mcm","clk":"998110245","pt":1580584987076,"mc":[{"id":"1.168081835","rc":[{"trd":[[1.02,2.76]],"batb":[[0,1.02,7.14]],"batl":[[0,990,0.01]],"ltp":1.02,"tv":2.76,"id":22229228,"hc":-10.5}],"tv":8.34}]}
{"op":"mcm","clk":"998112001","pt":1580584998272,"mc":[{"id":"1.168081835","rc":[{"trd":[[1.02,2.79]],"batb":[[0,1.02,7.12]],"ltp":1.02,"tv":2.79,"id":22229228,"hc":-9.5},{"trd":[[1.02,2.82]],"batb":[[0,1.02,7.1]],"ltp":1.02,"tv":2.82,"id":22229228,"hc":-11.5}],"tv":8.37}]}
{"op":"mcm","clk":"998112789","pt":1580585003489,"mc":[{"id":"1.168081835","rc":[{"batl":[[0,1000,0.02]],"ltp":1.02,"tv":2.76,"id":22229228,"hc":-10.5}]}]}
{"op":"mcm","clk":"998112826","pt":1580585003802,"mc":[{"id":"1.168081835","rc":[{"trd":[[1.02,2.78]],"batb":[[0,1.02,7.13]],"batl":[[0,990,0.01]],"ltp":1.02,"tv":2.77,"id":22229228,"hc":-10.5}],"tv":8.38}]}
{"op":"mcm","clk":"998114322","pt":1580585014426,"mc":[{"id":"1.168081835","rc":[{"batl":[[0,1000,0.02]],"ltp":1.02,"tv":2.82,"id":22229228,"hc":-11.5}]}]}
{"op":"mcm","clk":"998114524","pt":1580585015620,"mc":[{"id":"1.168081835","rc":[{"trd":[[1.02,2.84]],"batb":[[0,1.02,7.09]],"batl":[[0,990,0.01]],"ltp":1.02,"tv":2.83,"id":22229228,"hc":-11.5}],"tv":8.4}]}
{"op":"mcm","clk":"998114551","pt":1580585015832,"mc":[{"id":"1.168081835","rc":[{"trd":[[1.02,2.81]],"batb":[[0,1.02,7.11]],"ltp":1.02,"tv":2.8,"id":22229228,"hc":-9.5}],"tv":8.42}]}
{"op":"mcm","clk":"998115284","pt":1580585020769,"mc":[{"id":"1.168081835","rc":[{"trd":[[1.02,2.79]],"batb":[[0,1.02,7.12]],"ltp":1.02,"tv":2.79,"id":22229228,"hc":-10.5}],"tv":8.43}]}
{"op":"mcm","clk":"998116730","pt":1580585030545,"mc":[{"id":"1.168081835","rc":[{"batl":[[0,1000,2.37]],"ltp":1.02,"tv":2.83,"id":22229228,"hc":-11.5}]}]}
{"op":"mcm","clk":"998116835","pt":1580585031171,"mc":[{"id":"1.168081835","rc":[{"trd":[[1.02,2.85]],"batb":[[0,1.02,7.08]],"batl":[[0,990,0.01]],"ltp":1.02,"tv":2.85,"id":22229228,"hc":-11.5}],"tv":8.45}]}
{"op":"mcm","clk":"998117062","pt":1580585032637,"mc":[{"id":"1.168081835","rc":[{"batl":[[0,1000,2.37]],"ltp":1.02,"tv":2.8,"id":22229228,"hc":-9.5}]}]}
{"op":"mcm","clk":"998117158","pt":1580585033276,"mc":[{"id":"1.168081835","rc":[{"trd":[[1.02,2.82]],"batb":[[0,1.02,7.1]],"batl":[[0,990,0.01]],"ltp":1.02,"tv":2.82,"id":22229228,"hc":-9.5}],"tv":8.46}]}
{"op":"mcm","clk":"998117655","pt":1580585036674,"mc":[{"id":"1.168081835","rc":[{"batl":[[0,1000,2.37]],"ltp":1.02,"tv":2.79,"id":22229228,"hc":-10.5}]}]}
{"op":"mcm","clk":"998117761","pt":1580585037372,"mc":[{"id":"1.168081835","rc":[{"trd":[[1.02,2.81]],"batb":[[0,1.02,7.11]],"batl":[[0,990,0.01]],"ltp":1.02,"tv":2.8,"id":22229228,"hc":-10.5}],"tv":8.48}]}
{"op":"mcm","clk":"998119115","pt":1580585046700,"mc":[{"id":"1.168081835","rc":[{"batl":[[0,1000,0.02]],"ltp":1.02,"tv":2.85,"id":22229228,"hc":-11.5}]}]}
{"op":"mcm","clk":"998119179","pt":1580585047075,"mc":[{"id":"1.168081835","rc":[{"trd":[[1.02,2.87]],"batb":[[0,1.02,7.07]],"batl":[[0,990,0.01]],"ltp":1.02,"tv":2.86,"id":22229228,"hc":-11.5}],"tv":8.49}]}
{"op":"mcm","clk":"998119531","pt":1580585049492,"mc":[{"id":"1.168081835","rc":[{"batl":[[0,1000,0.02]],"ltp":1.02,"tv":2.82,"id":22229228,"hc":-9.5}]}]}
{"op":"mcm","clk":"998119595","pt":1580585049871,"mc":[{"id":"1.168081835","rc":[{"trd":[[1.02,2.84]],"batb":[[0,1.02,7.09]],"batl":[[0,990,0.01]],"ltp":1.02,"tv":2.83,"id":22229228,"hc":-9.5}],"tv":8.51}]}
{"op":"mcm","clk":"998120196","pt":1580585053662,"mc":[{"id":"1.168081835","rc":[{"trd":[[1.02,2.82]],"batb":[[0,1.02,7.1]],"ltp":1.02,"tv":2.82,"id":22229228,"hc":-10.5}],"tv":8.52}]}
{"op":"mcm","clk":"998121691","pt":1580585063342,"mc":[{"id":"1.168081835","rc":[{"trd":[[1.02,2.88]],"batb":[[0,1.02,7.06]],"ltp":1.02,"tv":2.88,"id":22229228,"hc":-11.5}],"tv":8.54}]}
{"op":"mcm","clk":"998122176","pt":1580585066717,"mc":[{"id":"1.168081835","rc":[{"trd":[[1.02,2.85]],"batb":[[0,1.02,7.08]],"ltp":1.02,"tv":2.85,"id":22229228,"hc":-9.5}],"tv":8.56}]}
{"op":"mcm","clk":"998122582","pt":1580585069418,"mc":[{"id":"1.168081835","rc":[{"trd":[[1.02,2.84]],"batb":[[0,1.02,7.09]],"ltp":1.02,"tv":2.83,"id":22229228,"hc":-10.5}],"tv":8.57}]}
{"op":"mcm","clk":"998124083","pt":1580585079482,"mc":[{"id":"1.168081835","rc":[{"batl":[[0,1000,0.02]],"ltp":1.02,"tv":2.88,"id":22229228,"hc":-11.5}]}]}
{"op":"mcm","clk":"998124148","pt":1580585079848,"mc":[{"id":"1.168081835","rc":[{"trd":[[1.02,2.9]],"batb":[[0,1.02,7.05]],"batl":[[0,990,0.01]],"ltp":1.02,"tv":2.89,"id":22229228,"hc":-11.5}],"tv":8.59}]}
{"op":"mcm","clk":"998124716","pt":1580585083761,"mc":[{"id":"1.168081835","rc":[{"trd":[[1.02,2.87]],"batb":[[0,1.02,7.07]],"ltp":1.02,"tv":2.86,"id":22229228,"hc":-9.5}],"tv":8.6}]}
{"op":"mcm","clk":"998124978","pt":1580585085635,"mc":[{"id":"1.168081835","rc":[{"batl":[[0,1000,2.37]],"ltp":1.02,"tv":2.83,"id":22229228,"hc":-10.5}]}]}
{"op":"mcm","clk":"998125070","pt":1580585086291,"mc":[{"id":"1.168081835","rc":[{"trd":[[1.02,2.85]],"batb":[[0,1.02,7.08]],"batl":[[0,990,0.01]],"ltp":1.02,"tv":2.85,"id":22229228,"hc":-10.5}],"tv":8.62}]}
{"op":"mcm","clk":"998126596","pt":1580585095598,"mc":[{"id":"1.168081835","rc":[{"batl":[[0,1000,2.37]],"ltp":1.02,"tv":2.89,"id":22229228,"hc":-11.5}]}]}
{"op":"mcm","clk":"998126700","pt":1580585096225,"mc":[{"id":"1.168081835","rc":[{"trd":[[1.02,2.92]],"batb":[[0,1.02,7.04]],"batl":[[0,990,0.01]],"ltp":1.02,"tv":2.91,"id":22229228,"hc":-11.5}],"tv":8.63}]}
{"op":"mcm","clk":"998127332","pt":1580585100459,"mc":[{"id":"1.168081835","rc":[{"batl":[[0,1000,2.37]],"ltp":1.02,"tv":2.86,"id":22229228,"hc":-9.5}]}]}
{"op":"mcm","clk":"998127449","pt":1580585101045,"mc":[{"id":"1.168081835","rc":[{"trd":[[1.02,2.88]],"batb":[[0,1.02,7.06]],"batl":[[0,990,0.01]],"ltp":1.02,"tv":2.88,"id":22229228,"hc":-9.5}],"tv":8.65}]}
{"op":"mcm","clk":"998127665","pt":1580585102459,"mc":[{"id":"1.168081835","rc":[{"batl":[[0,1000,2.37]],"ltp":1.02,"tv":2.85,"id":22229228,"hc":-10.5}]}]}
{"op":"mcm","clk":"998127792","pt":1580585103254,"mc":[{"id":"1.168081835","rc":[{"trd":[[1.02,2.87]],"batb":[[0,1.02,7.07]],"batl":[[0,990,0.01]],"ltp":1.02,"tv":2.86,"id":22229228,"hc":-10.5}],"tv":8.66}]}
{"op":"mcm","clk":"998129305","pt":1580585112702,"mc":[{"id":"1.168081835","rc":[{"batl":[[0,1000,2.37]],"ltp":1.02,"tv":2.91,"id":22229228,"hc":-11.5}]}]}
{"op":"mcm","clk":"998129407","pt":1580585113399,"mc":[{"id":"1.168081835","rc":[{"trd":[[1.02,2.93]],"batb":[[0,1.02,7.03]],"batl":[[0,990,0.01]],"ltp":1.02,"tv":2.93,"id":22229228,"hc":-11.5}],"tv":8.68}]}
{"op":"mcm","clk":"998129977","pt":1580585117588,"mc":[{"id":"1.168081835","rc":[{"trd":[[1.02,2.9]],"batb":[[0,1.02,7.05]],"ltp":1.02,"tv":2.89,"id":22229228,"hc":-9.5}],"tv":8.69}]}
{"op":"mcm","clk":"998130126","pt":1580585118672,"mc":[{"id":"1.168081835","rc":[{"batl":[[0,1000,2.37]],"ltp":1.02,"tv":2.86,"id":22229228,"hc":-10.5}]}]}
{"op":"mcm","clk":"998130207","pt":1580585119270,"mc":[{"id":"1.168081835","rc":[{"trd":[[1.02,2.88]],"batb":[[0,1.02,7.06]],"batl":[[0,990,0.01]],"ltp":1.02,"tv":2.88,"id":22229228,"hc":-10.5}],"tv":8.71}]}
{"op":"mcm","clk":"998131744","pt":1580585129696,"mc":[{"id":"1.168081835","rc":[{"trd":[[1.02,2.95]],"batb":[[0,1.02,7.02]],"ltp":1.02,"tv":2.94,"id":22229228,"hc":-11.5}],"tv":8.73}]}
{"op":"mcm","clk":"998132436","pt":1580585134416,"mc":[{"id":"1.168081835","rc":[{"trd":[[1.02,2.92]],"batb":[[0,1.02,7.04]],"ltp":1.02,"tv":2.91,"id":22229228,"hc":-9.5}],"tv":8.74}]}
{"op":"mcm","clk":"998132731","pt":1580585136434,"mc":[{"id":"1.168081835","rc":[{"trd":[[1.02,2.9]],"batb":[[0,1.02,7.05]],"ltp":1.02,"tv":2.89,"id":22229228,"hc":-10.5}],"tv":8.76}]}
{"op":"mcm","clk":"998134270","pt":1580585146647,"mc":[{"id":"1.168081835","rc":[{"trd":[[1.02,2.96]],"batb":[[0,1.02,7.01]],"ltp":1.02,"tv":2.96,"id":22229228,"hc":-11.5}],"tv":8.77}]}
{"op":"mcm","clk":"998134862","pt":1580585150550,"mc":[{"id":"1.168081835","rc":[{"batl":[[0,1000,2.37]],"ltp":1.02,"tv":2.91,"id":22229228,"hc":-9.5}]}]}
{"op":"mcm","clk":"998134948","pt":1580585151148,"mc":[{"id":"1.168081835","rc":[{"trd":[[1.02,2.93]],"batb":[[0,1.02,7.03]],"batl":[[0,990,0.01]],"ltp":1.02,"tv":2.93,"id":22229228,"hc":-9.5}],"tv":8.79}]}
{"op":"mcm","clk":"998135349","pt":1580585153654,"mc":[{"id":"1.168081835","rc":[{"trd":[[1.02,2.92]],"batb":[[0,1.02,7.04]],"ltp":1.02,"tv":2.91,"id":22229228,"hc":-10.5}],"tv":8.8}]}
{"op":"mcm","clk":"998136830","pt":1580585163488,"mc":[{"id":"1.168081835","rc":[{"trd":[[1.02,2.98]],"batb":[[0,1.02,7]],"ltp":1.02,"tv":2.97,"id":22229228,"hc":-11.5}],"tv":8.82}]}
{"op":"mcm","clk":"998137446","pt":1580585167575,"mc":[{"id":"1.168081835","rc":[{"trd":[[1.02,2.95]],"batb":[[0,1.02,7.02]],"ltp":1.02,"tv":2.94,"id":22229228,"hc":-9.5}],"tv":8.83}]}
{"op":"mcm","clk":"998137903","pt":1580585170497,"mc":[{"id":"1.168081835","rc":[{"batl":[[0,1000,0.02]],"ltp":1.02,"tv":2.91,"id":22229228,"hc":-10.5}]}]}
{"op":"mcm","clk":"998137948","pt":1580585170817,"mc":[{"id":"1.168081835","rc":[{"trd":[[1.02,2.93]],"batb":[[0,1.02,7.03]],"batl":[[0,990,0.01]],"ltp":1.02,"tv":2.93,"id":22229228,"hc":-10.5}],"tv":8.85}]}
{"op":"mcm","clk":"998139317","pt":1580585179637,"mc":[{"id":"1.168081835","rc":[{"trd":[[1.02,2.99]],"batb":[[0,1.02,6.99]],"ltp":1.02,"tv":2.99,"id":22229228,"hc":-11.5}],"tv":8.87}]}
{"op":"mcm","clk":"998140060","pt":1580585184553,"mc":[{"id":"1.168081835","rc":[{"batl":[[0,1000,2.37]],"ltp":1.02,"tv":2.94,"id":22229228,"hc":-9.5}]}]}
{"op":"mcm","clk":"998140157","pt":1580585185122,"mc":[{"id":"1.168081835","rc":[{"trd":[[1.02,2.96]],"batb":[[0,1.02,7.01]],"batl":[[0,990,0.01]],"ltp":1.02,"tv":2.96,"id":22229228,"hc":-9.5}],"tv":8.88}]}
{"op":"mcm","clk":"998140411","pt":1580585186662,"mc":[{"id":"1.168081835","rc":[{"batl":[[0,1000,0.02]],"ltp":1.02,"tv":2.93,"id":22229228,"hc":-10.5}]}]}
{"op":"mcm","clk":"998140481","pt":1580585187050,"mc":[{"id":"1.168081835","rc":[{"trd":[[1.02,2.95]],"batb":[[0,1.02,7.02]],"batl":[[0,990,0.01]],"ltp":1.02,"tv":2.94,"id":22229228,"hc":-10.5}],"tv":8.9}]}
{"op":"mcm","clk":"998142028","pt":1580585196756,"mc":[{"id":"1.168081835","rc":[{"trd":[[1.02,3.01]],"batb":[[0,1.02,6.98]],"ltp":1.02,"tv":3.0,"id":22229228,"hc":-11.5}],"tv":8.91}]}
{"op":"mcm","clk":"998142764","pt":1580585201357,"mc":[{"id":"1.168081835","rc":[{"trd":[[1.02,2.98]],"batb":[[0,1.02,7]],"ltp":1.02,"tv":2.97,"id":22229228,"hc":-9.5}],"tv":8.93}]}
{"op":"mcm","clk":"998143100","pt":1580585203584,"mc":[{"id":"1.168081835","rc":[{"trd":[[1.02,2.96]],"batb":[[0,1.02,7.01]],"ltp":1.02,"tv":2.96,"id":22229228,"hc":-10.5}],"tv":8.94}]}
{"op":"mcm","clk":"998144619","pt":1580585213324,"mc":[{"id":"1.168081835","rc":[{"trd":[[1.02,3.02]],"batb":[[0,1.02,6.97]],"ltp":1.02,"tv":3.02,"id":22229228,"hc":-11.5}],"tv":8.96}]}
{"op":"mcm","clk":"998145225","pt":1580585217394,"mc":[{"id":"1.168081835","rc":[{"batl":[[0,1000,0.02]],"ltp":1.02,"tv":2.97,"id":22229228,"hc":-9.5}]}]}
{"op":"mcm","clk":"998145291","pt":1580585217788,"mc":[{"id":"1.168081835","rc":[{"trd":[[1.02,2.99]],"batb":[[0,1.02,6.99]],"batl":[[0,990,0.01]],"ltp":1.02,"tv":2.99,"id":22229228,"hc":-9.5}],"tv":8.97}]}
{"op":"mcm","clk":"998145571","pt":1580585219696,"mc":[{"id":"1.168081835","rc":[{"batl":[[0,1000,0.02]],"ltp":1.02,"tv":2.96,"id":22229228,"hc":-10.5}]}]}
{"op":"mcm","clk":"998145639","pt":1580585220187,"mc":[{"id":"1.168081835","rc":[{"trd":[[1.02,2.98]],"batb":[[0,1.02,7]],"batl":[[0,990,0.01]],"ltp":1.02,"tv":2.97,"id":22229228,"hc":-10.5}],"tv":8.99}]}
{"op":"mcm","clk":"998147163","pt":1580585229510,"mc":[{"id":"1.168081835","rc":[{"batl":[[0,1000,0.02]],"ltp":1.02,"tv":3.02,"id":22229228,"hc":-11.5}]}]}
{"op":"mcm","clk":"998147213","pt":1580585229791,"mc":[{"id":"1.168081835","rc":[{"trd":[[1.02,3.04]],"batb":[[0,1.02,6.96]],"batl":[[0,990,0.01]],"ltp":1.02,"tv":3.03,"id":22229228,"hc":-11.5}],"tv":9.0}]}
{"op":"mcm","clk":"998148114","pt":1580585235253,"mc":[{"id":"1.168081835","rc":[{"batl":[[0,1000,2.37]],"ltp":1.02,"tv":2.99,"id":22229228,"hc":-9.5}]}]}
{"op":"mcm","clk":"998148268","pt":1580585236135,"mc":[{"id":"1.168081835","rc":[{"trd":[[1.02,3.01]],"batb":[[0,1.02,6.98]],"batl":[[0,990,0.01]],"ltp":1.02,"tv":3.0,"id":22229228,"hc":-9.5}],"tv":9.02}]}
{"op":"mcm","clk":"998148515","pt":1580585237624,"mc":[{"id":"1.168081835","rc":[{"trd":[[1.02,2.99]],"batb":[[0,1.02,6.99]],"ltp":1.02,"tv":2.99,"id":22229228,"hc":-10.5}],"tv":9.04}]}
{"op":"mcm","clk":"998150023","pt":1580585246673,"mc":[{"id":"1.168081835","rc":[{"batl":[[0,1000,0.02]],"ltp":1.02,"tv":3.03,"id":22229228,"hc":-11.5}]}]}
{"op":"mcm","clk":"998150097","pt":1580585247118,"mc":[{"id":"1.168081835","rc":[{"trd":[[1.02,3.06]],"batb":[[0,1.02,6.95]],"batl":[[0,990,0.01]],"ltp":1.02,"tv":3.05,"id":22229228,"hc":-11.5}],"tv":9.05}]}
{"op":"mcm","clk":"998151129","pt":1580585253504,"mc":[{"id":"1.168081835","rc":[{"trd":[[1.02,3.02]],"batb":[[0,1.02,6.97]],"ltp":1.02,"tv":3.02,"id":22229228,"hc":-9.5},{"batl":[[0,1000,2.37]],"ltp":1.02,"tv":2.99,"id":22229228,"hc":-10.5}],"tv":9.07}]}
{"op":"mcm","clk":"998151237","pt":1580585254149,"mc":[{"id":"1.168081835","rc":[{"trd":[[1.02,3.01]],"batb":[[0,1.02,6.98]],"batl":[[0,990,0.01]],"ltp":1.02,"tv":3.0,"id":22229228,"hc":-10.5}],"tv":9.08}]}
{"op":"mcm","clk":"998152873","pt":1580585263733,"mc":[{"id":"1.168081835","rc":[{"trd":[[1.02,3.07]],"batb":[[0,1.02,6.94]],"ltp":1.02,"tv":3.07,"id":22229228,"hc":-11.5}],"tv":9.1}]}
{"op":"mcm","clk":"998154111","pt":1580585270583,"mc":[{"id":"1.168081835","rc":[{"trd":[[1.02,3.04]],"batb":[[0,1.02,6.96]],"ltp":1.02,"tv":3.03,"id":22229228,"hc":-9.5},{"batl":[[0,1000,0.02]],"ltp":1.02,"tv":3.0,"id":22229228,"hc":-10.5}],"tv":9.11}]}
{"op":"mcm","clk":"998154181","pt":1580585270964,"mc":[{"id":"1.168081835","rc":[{"trd":[[1.02,3.02]],"batb":[[0,1.02,6.97]],"batl":[[0,990,0.01]],"ltp":1.02,"tv":3.02,"id":22229228,"hc":-10.5}],"tv":9.13}]}
{"op":"mcm","clk":"998155670","pt":1580585279574,"mc":[{"id":"1.168081835","rc":[{"batl":[[0,1000,2.37]],"ltp":1.02,"tv":3.07,"id":22229228,"hc":-11.5}]}]}
{"op":"mcm","clk":"998155772","pt":1580585280325,"mc":[{"id":"1.168081835","rc":[{"trd":[[1.02,3.09]],"batb":[[0,1.02,6.93]],"batl":[[0,990,0.01]],"ltp":1.02,"tv":3.08,"id":22229228,"hc":-11.5}],"tv":9.14}]}
{"op":"mcm","clk":"998157058","pt":1580585287585,"mc":[{"id":"1.168081835","rc":[{"batl":[[0,1000,0.02]],"ltp":1.02,"tv":3.03,"id":22229228,"hc":-9.5},{"batl":[[0,1000,0.02]],"ltp":1.02,"tv":3.02,"id":22229228,"hc":-10.5}]}]}
{"op":"mcm","clk":"998157268","pt":1580585288545,"mc":[{"id":"1.168081835","rc":[{"trd":[[1.02,3.06]],"batb":[[0,1.02,6.95]],"batl":[[0,990,0.01]],"ltp":1.02,"tv":3.05,"id":22229228,"hc":-9.5},{"trd":[[1.02,3.04]],"batb":[[0,1.02,6.96]],"batl":[[0,990,0.01]],"ltp":1.02,"tv":3.03,"id":22229228,"hc":-10.5}],"tv":9.18}]}
{"op":"mcm","clk":"998158773","pt":1580585296500,"mc":[{"id":"1.168081835","rc":[{"batl":[[0,1000,0.02]],"ltp":1.02,"tv":3.08,"id":22229228,"hc":-11.5}]}]}
{"op":"mcm","clk":"998158836","pt":1580585296830,"mc":[{"id":"1.168081835","rc":[{"trd":[[1.02,3.1]],"batb":[[0,1.02,6.92]],"batl":[[0,990,0.01]],"ltp":1.02,"tv":3.1,"id":22229228,"hc":-11.5}],"tv":9.19}]}
{"op":"mcm","clk":"998160042","pt":1580585303489,"mc":[{"id":"1.168081835","rc":[{"batl":[[0,1000,0.02]],"ltp":1.02,"tv":3.05,"id":22229228,"hc":-9.5}]}]}
{"op":"mcm","clk":"998160235","pt":1580585304504,"mc":[{"id":"1.168081835","rc":[{"trd":[[1.02,3.07]],"batb":[[0,1.02,6.94]],"batl":[[0,990,0.01]],"ltp":1.02,"tv":3.07,"id":22229228,"hc":-9.5},{"batl":[[0,1000,2.37]],"ltp":1.02,"tv":3.03,"id":22229228,"hc":-10.5}],"tv":9.21}]}
{"op":"mcm","clk":"998160363","pt":1580585305206,"mc":[{"id":"1.168081835","rc":[{"trd":[[1.02,3.06]],"batb":[[0,1.02,6.95]],"batl":[[0,990,0.01]],"ltp":1.02,"tv":3.05,"id":22229228,"hc":-10.5}],"tv":9.22}]}
{"op":"mcm","clk":"998161900","pt":1580585314495,"mc":[{"id":"1.168081835","rc":[{"trd":[[1.02,3.12]],"batb":[[0,1.02,6.91]],"ltp":1.02,"tv":3.11,"id":22229228,"hc":-11.5}],"tv":9.24}]}
{"op":"mcm","clk":"998162663","pt":1580585319508,"mc":[{"id":"1.168081835","rc":[{"batl":[[0,1000,2.37]],"ltp":1.02,"tv":3.07,"id":22229228,"hc":-9.5}]}]}
{"op":"mcm","clk":"998162757","pt":1580585320090,"mc":[{"id":"1.168081835","rc":[{"trd":[[1.02,3.09]],"batb":[[0,1.02,6.93]],"batl":[[0,990,0.01]],"ltp":1.02,"tv":3.08,"id":22229228,"hc":-9.5}],"tv":9.25}]}
{"op":"mcm","clk":"998163012","pt":1580585321642,"mc":[{"id":"1.168081835","rc":[{"batl":[[0,1000,2.37]],"ltp":1.02,"tv":3.05,"id":22229228,"hc":-10.5}]}]}
{"op":"mcm","clk":"998163130","pt":1580585322332,"mc":[{"id":"1.168081835","rc":[{"trd":[[1.02,3.07]],"batb":[[0,1.02,6.94]],"batl":[[0,990,0.01]],"ltp":1.02,"tv":3.07,"id":22229228,"hc":-10.5}],"tv":9.27}]}
{"op":"mcm","clk":"998164615","pt":1580585331432,"mc":[{"id":"1.168081835","rc":[{"batl":[[0,1000,0.02]],"ltp":1.02,"tv":3.11,"id":22229228,"hc":-11.5}]}]}
{"op":"mcm","clk":"998164663","pt":1580585331802,"mc":[{"id":"1.168081835","rc":[{"trd":[[1.02,3.13]],"batb":[[0,1.02,6.9]],"batl":[[0,990,0.01]],"ltp":1.02,"tv":3.13,"id":22229228,"hc":-11.5}],"tv":9.28}]}
{"op":"mcm","clk":"998165570","pt":1580585337664,"mc":[{"id":"1.168081835","rc":[{"batl":[[0,1000,0.02]],"ltp":1.02,"tv":3.08,"id":22229228,"hc":-9.5}]}]}
{"op":"mcm","clk":"998165632","pt":1580585338076,"mc":[{"id":"1.168081835","rc":[{"trd":[[1.02,3.1]],"batb":[[0,1.02,6.92]],"batl":[[0,990,0.01]],"ltp":1.02,"tv":3.1,"id":22229228,"hc":-9.5}],"tv":9.3}]}
{"op":"mcm","clk":"998165840","pt":1580585339478,"mc":[{"id":"1.168081835","rc":[{"batl":[[0,1000,2.37]],"ltp":1.02,"tv":3.07,"id":22229228,"hc":-10.5}]}]}
{"op":"mcm","clk":"998165947","pt":1580585340199,"mc":[{"id":"1.168081835","rc":[{"trd":[[1.02,3.09]],"batb":[[0,1.02,6.93]],"batl":[[0,990,0.01]],"ltp":1.02,"tv":3.08,"id":22229228,"hc":-10.5}],"tv":9.32}]}
{"op":"mcm","clk":"998167232","pt":1580585348324,"mc":[{"id":"1.168081835","rc":[{"trd":[[1.02,3.15]],"batb":[[0,1.02,6.89]],"ltp":1.02,"tv":3.14,"id":22229228,"hc":-11.5}],"tv":9.33}]}
{"op":"mcm","clk":"998168337","pt":1580585355537,"mc":[{"id":"1.168081835","rc":[{"trd":[[1.02,3.12]],"batb":[[0,1.02,6.91]],"ltp":1.02,"tv":3.11,"id":22229228,"hc":-9.5}],"tv":9.35}]}
{"op":"mcm","clk":"998168494","pt":1580585356593,"mc":[{"id":"1.168081835","rc":[{"batl":[[0,1000,2.37]],"ltp":1.02,"tv":3.08,"id":22229228,"hc":-10.5}]}]}
{"op":"mcm","clk":"998168596","pt":1580585357285,"mc":[{"id":"1.168081835","rc":[{"trd":[[1.02,3.1]],"batb":[[0,1.02,6.92]],"batl":[[0,990,0.01]],"ltp":1.02,"tv":3.1,"id":22229228,"hc":-10.5}],"tv":9.36}]}
{"op":"mcm","clk":"998169781","pt":1580585364601,"mc":[{"id":"1.168081835","rc":[{"batl":[[0,1000,2.37]],"ltp":1.02,"tv":3.14,"id":22229228,"hc":-11.5}]}]}
{"op":"mcm","clk":"998169890","pt":1580585365323,"mc":[{"id":"1.168081835","rc":[{"trd":[[1.02,3.16]],"batb":[[0,1.02,6.88]],"batl":[[0,990,0.01]],"ltp":1.02,"tv":3.16,"id":22229228,"hc":-11.5}],"tv":9.38}]}
{"op":"mcm","clk":"998171214","pt":1580585373510,"mc":[{"id":"1.168081835","rc":[{"batl":[[0,1000,2.37]],"ltp":1.02,"tv":3.11,"id":22229228,"hc":-9.5}]}]}
{"op":"mcm","clk":"998171412","pt":1580585374637,"mc":[{"id":"1.168081835","rc":[{"trd":[[1.02,3.13]],"batb":[[0,1.02,6.9]],"batl":[[0,990,0.01]],"ltp":1.02,"tv":3.13,"id":22229228,"hc":-9.5},{"trd":[[1.02,3.12]],"batb":[[0,1.02,6.91]],"ltp":1.02,"tv":3.11,"id":22229228,"hc":-10.5}],"tv":9.41}]}
{"op":"mcm","clk":"998172594","pt":1580585381557,"mc":[{"id":"1.168081835","rc":[{"batl":[[0,1000,0.02]],"ltp":1.02,"tv":3.16,"id":22229228,"hc":-11.5}]}]}
{"op":"mcm","clk":"998172657","pt":1580585381931,"mc":[{"id":"1.168081835","rc":[{"trd":[[1.02,3.18]],"batb":[[0,1.02,6.87]],"batl":[[0,990,0.01]],"ltp":1.02,"tv":3.17,"id":22229228,"hc":-11.5}],"tv":9.42}]}
{"op":"mcm","clk":"998173839","pt":1580585389562,"mc":[{"id":"1.168081835","rc":[{"batl":[[0,1000,2.37]],"ltp":1.02,"tv":3.13,"id":22229228,"hc":-9.5}]}]}
{"op":"mcm","clk":"998174025","pt":1580585390663,"mc":[{"id":"1.168081835","rc":[{"trd":[[1.02,3.15]],"batb":[[0,1.02,6.89]],"batl":[[0,990,0.01]],"ltp":1.02,"tv":3.14,"id":22229228,"hc":-9.5},{"batl":[[0,1000,0.02]],"ltp":1.02,"tv":3.11,"id":22229228,"hc":-10.5}],"tv":9.44}]}
{"op":"mcm","clk":"998174073","pt":1580585390933,"mc":[{"id":"1.168081835","rc":[{"trd":[[1.02,3.13]],"batb":[[0,1.02,6.9]],"batl":[[0,990,0.01]],"ltp":1.02,"tv":3.13,"id":22229228,"hc":-10.5}],"tv":9.45}]}
{"op":"mcm","clk":"998175311","pt":1580585398656,"mc":[{"id":"1.168081835","rc":[{"batl":[[0,1000,0.02]],"ltp":1.02,"tv":3.17,"id":22229228,"hc":-11.5}]}]}
{"op":"mcm","clk":"998175369","pt":1580585398976,"mc":[{"id":"1.168081835","rc":[{"trd":[[1.02,3.19]],"batb":[[0,1.02,6.86]],"batl":[[0,990,0.01]],"ltp":1.02,"tv":3.19,"id":22229228,"hc":-11.5}],"tv":9.47}]}
{"op":"mcm","clk":"998176777","pt":1580585406457,"mc":[{"id":"1.168081835","rc":[{"trd":[[1.02,3.16]],"batb":[[0,1.02,6.88]],"ltp":1.02,"tv":3.16,"id":22229228,"hc":-9.5}],"tv":9.49}]}
{"op":"mcm","clk":"998177025","pt":1580585407736,"mc":[{"id":"1.168081835","rc":[{"trd":[[1.02,3.15]],"batb":[[0,1.02,6.89]],"ltp":1.02,"tv":3.14,"id":22229228,"hc":-10.5}],"tv":9.5}]}
{"op":"mcm","clk":"998178427","pt":1580585416062,"mc":[{"id":"1.168081835","rc":[{"trd":[[1.02,3.21]],"batb":[[0,1.02,6.85]],"ltp":1.02,"tv":3.21,"id":22229228,"hc":-11.5}],"tv":9.52}]}
{"op":"mcm","clk":"998179650","pt":1580585422861,"mc":[{"id":"1.168081835","rc":[{"batl":[[0,1000,2.37]],"ltp":1.02,"tv":3.16,"id":22229228,"hc":-9.5}]}]}
{"op":"mcm","clk":"998179890","pt":1580585424686,"mc":[{"id":"1.168081835","rc":[{"trd":[[1.02,3.18]],"batb":[[0,1.02,6.87]],"batl":[[0,990,0.01]],"ltp":1.02,"tv":3.17,"id":22229228,"hc":-9.5},{"trd":[[1.02,3.16]],"batb":[[0,1.02,6.88]],"ltp":1.02,"tv":3.16,"id":22229228,"hc":-10.5}],"tv":9.55}]}
{"op":"mcm","clk":"998181402","pt":1580585432612,"mc":[{"id":"1.168081835","rc":[{"trd":[[1.02,3.23]],"batb":[[0,1.02,6.84]],"ltp":1.02,"tv":3.22,"id":22229228,"hc":-11.5}],"tv":9.56}]}
{"op":"mcm","clk":"998183051","pt":1580585441605,"mc":[{"id":"1.168081835","rc":[{"batl":[[0,1000,0.02]],"ltp":1.02,"tv":3.16,"id":22229228,"hc":-10.5}]}]}
{"op":"mcm","clk":"998183121","pt":1580585442028,"mc":[{"id":"1.168081835","rc":[{"trd":[[1.02,3.18]],"batb":[[0,1.02,6.87]],"batl":[[0,990,0.01]],"ltp":1.02,"tv":3.17,"id":22229228,"hc":-10.5}],"tv":9.58}]}
{"op":"mcm","clk":"998183356","pt":1580585443324,"mc":[{"id":"1.168081835","rc":[{"trd":[[1.02,3.19]],"batb":[[0,1.02,6.86]],"ltp":1.02,"tv":3.19,"id":22229228,"hc":-9.5}],"tv":9.59}]}
{"op":"mcm","clk":"998184472","pt":1580585449439,"mc":[{"id":"1.168081835","rc":[{"batl":[[0,1000,2.37]],"ltp":1.02,"tv":3.22,"id":22229228,"hc":-11.5}]}]}
{"op":"mcm","clk":"998184607","pt":1580585450130,"mc":[{"id":"1.168081835","rc":[{"trd":[[1.02,3.24]],"batb":[[0,1.02,6.83]],"batl":[[0,990,0.01]],"ltp":1.02,"tv":3.24,"id":22229228,"hc":-11.5}],"tv":9.61}]}
{"op":"mcm","clk":"998186269","pt":1580585459661,"mc":[{"id":"1.168081835","rc":[{"batl":[[0,1000,0.02]],"ltp":1.02,"tv":3.19,"id":22229228,"hc":-9.5},{"trd":[[1.02,3.19]],"batb":[[0,1.02,6.86]],"ltp":1.02,"tv":3.19,"id":22229228,"hc":-10.5}],"tv":9.63}]}
{"op":"mcm","clk":"998186322","pt":1580585459934,"mc":[{"id":"1.168081835","rc":[{"trd":[[1.02,3.21]],"batb":[[0,1.02,6.85]],"batl":[[0,990,0.01]],"ltp":1.02,"tv":3.21,"id":22229228,"hc":-9.5}],"tv":9.64}]}
{"op":"mcm","clk":"998187442","pt":1580585466294,"mc":[{"id":"1.168081835","rc":[{"batl":[[0,1000,2.37]],"ltp":1.02,"tv":3.24,"id":22229228,"hc":-11.5}]}]}
{"op":"mcm","clk":"998187595","pt":1580585467133,"mc":[{"id":"1.168081835","rc":[{"trd":[[1.02,3.26]],"batb":[[0,1.02,6.82]],"batl":[[0,990,0.01]],"ltp":1.02,"tv":3.25,"id":22229228,"hc":-11.5}],"tv":9.66}]}
{"op":"mcm","clk":"998189222","pt":1580585475514,"mc":[{"id":"1.168081835","rc":[{"batl":[[0,1000,2.37]],"ltp":1.02,"tv":3.19,"id":22229228,"hc":-10.5}]}]}
{"op":"mcm","clk":"998189459","pt":1580585476691,"mc":[{"id":"1.168081835","rc":[{"trd":[[1.02,3.23]],"batb":[[0,1.02,6.84]],"ltp":1.02,"tv":3.22,"id":22229228,"hc":-9.5},{"trd":[[1.02,3.21]],"batb":[[0,1.02,6.85]],"batl":[[0,990,0.01]],"ltp":1.02,"tv":3.21,"id":22229228,"hc":-10.5}],"tv":9.69}]}
{"op":"mcm","clk":"998190703","pt":1580585483641,"mc":[{"id":"1.168081835","rc":[{"batl":[[0,1000,2.37]],"ltp":1.02,"tv":3.25,"id":22229228,"hc":-11.5}]}]}
{"op":"mcm","clk":"998190840","pt":1580585484341,"mc":[{"id":"1.168081835","rc":[{"trd":[[1.02,3.27]],"batb":[[0,1.02,6.81]],"batl":[[0,990,0.01]],"ltp":1.02,"tv":3.27,"id":22229228,"hc":-11.5}],"tv":9.7}]}
{"op":"mcm","clk":"998192369","pt":1580585492698,"mc":[{"id":"1.168081835","rc":[{"batl":[[0,1000,0.02]],"ltp":1.02,"tv":3.21,"id":22229228,"hc":-10.5}]}]}
{"op":"mcm","clk":"998192518","pt":1580585493606,"mc":[{"id":"1.168081835","rc":[{"trd":[[1.02,3.23]],"batb":[[0,1.02,6.84]],"batl":[[0,990,0.01]],"ltp":1.02,"tv":3.22,"id":22229228,"hc":-10.5}],"tv":9.72}]}
{"op":"mcm","clk":"998192554","pt":1580585493817,"mc":[{"id":"1.168081835","rc":[{"trd":[[1.02,3.24]],"batb":[[0,1.02,6.83]],"ltp":1.02,"tv":3.24,"id":22229228,"hc":-9.5}],"tv":9.73}]}
{"op":"mcm","clk":"998193992","pt":1580585501514,"mc":[{"id":"1.168081835","rc":[{"trd":[[1.02,3.29]],"batb":[[0,1.02,6.8]],"ltp":1.02,"tv":3.28,"id":22229228,"hc":-11.5}],"tv":9.75}]}
{"op":"mcm","clk":"998195430","pt":1580585509525,"mc":[{"id":"1.168081835","rc":[{"batl":[[0,1000,0.02]],"ltp":1.02,"tv":3.22,"id":22229228,"hc":-10.5}]}]}
{"op":"mcm","clk":"998195587","pt":1580585510319,"mc":[{"id":"1.168081835","rc":[{"trd":[[1.02,3.26]],"batb":[[0,1.02,6.82]],"ltp":1.02,"tv":3.25,"id":22229228,"hc":-9.5},{"trd":[[1.02,3.24]],"batb":[[0,1.02,6.83]],"batl":[[0,990,0.01]],"ltp":1.02,"tv":3.24,"id":22229228,"hc":-10.5}],"tv":9.78}]}
{"op":"mcm","clk":"998197267","pt":1580585518538,"mc":[{"id":"1.168081835","rc":[{"batl":[[0,1000,2.37]],"ltp":1.02,"tv":3.28,"id":22229228,"hc":-11.5}]}]}
{"op":"mcm","clk":"998197353","pt":1580585519032,"mc":[{"id":"1.168081835","rc":[{"trd":[[1.02,3.3]],"batb":[[0,1.02,6.79]],"batl":[[0,990,0.01]],"ltp":1.02,"tv":3.3,"id":22229228,"hc":-11.5}],"tv":9.8}]}
{"op":"mcm","clk":"998198816","pt":1580585526561,"mc":[{"id":"1.168081835","rc":[{"batl":[[0,1000,2.37]],"ltp":1.02,"tv":3.24,"id":22229228,"hc":-10.5}]}]}
{"op":"mcm","clk":"998199036","pt":1580585527675,"mc":[{"id":"1.168081835","rc":[{"trd":[[1.02,3.26]],"batb":[[0,1.02,6.82]],"batl":[[0,990,0.01]],"ltp":1.02,"tv":3.25,"id":22229228,"hc":-10.5}],"tv":9.81}]}
{"op":"mcm","clk":"998199052","pt":1580585527781,"mc":[{"id":"1.168081835","rc":[{"trd":[[1.02,3.27]],"batb":[[0,1.02,6.81]],"ltp":1.02,"tv":3.27,"id":22229228,"hc":-9.5}],"tv":9.83}]}
{"op":"mcm","clk":"998200307","pt":1580585534580,"mc":[{"id":"1.168081835","rc":[{"batl":[[0,1000,2.37]],"ltp":1.02,"tv":3.3,"id":22229228,"hc":-11.5}]}]}
{"op":"mcm","clk":"998200420","pt":1580585535183,"mc":[{"id":"1.168081835","rc":[{"trd":[[1.02,3.32]],"batb":[[0,1.02,6.78]],"batl":[[0,990,0.01]],"ltp":1.02,"tv":3.31,"id":22229228,"hc":-11.5}],"tv":9.84}]}
{"op":"mcm","clk":"998202074","pt":1580585544507,"mc":[{"id":"1.168081835","rc":[{"trd":[[1.02,3.27]],"batb":[[0,1.02,6.81]],"ltp":1.02,"tv":3.27,"id":22229228,"hc":-10.5}],"tv":9.86}]}
{"op":"mcm","clk":"998202308","pt":1580585545665,"mc":[{"id":"1.168081835","rc":[{"batl":[[0,1000,2.37]],"ltp":1.02,"tv":3.27,"id":22229228,"hc":-9.5}]}]}
{"op":"mcm","clk":"998202373","pt":1580585546017,"mc":[{"id":"1.168081835","rc":[{"trd":[[1.02,3.29]],"batb":[[0,1.02,6.8]],"batl":[[0,990,0.01]],"ltp":1.02,"tv":3.28,"id":22229228,"hc":-9.5}],"tv":9.87}]}
{"op":"mcm","clk":"998203372","pt":1580585551357,"mc":[{"id":"1.168081835","rc":[{"batl":[[0,1000,0.02]],"ltp":1.02,"tv":3.31,"id":22229228,"hc":-11.5}]}]}
{"op":"mcm","clk":"998203610","pt":1580585552629,"mc":[{"id":"1.168081835","rc":[{"batl":[[0,990,0.01]],"ltp":1.02,"tv":3.31,"id":22229228,"hc":-11.5}]}]}
{"op":"mcm","clk":"998203657","pt":1580585552855,"mc":[{"id":"1.168081835","rc":[{"trd":[[1.02,3.33]],"batb":[[0,1.02,6.77]],"ltp":1.02,"tv":3.33,"id":22229228,"hc":-11.5}],"tv":9.89}]}
{"op":"mcm","clk":"998205277","pt":1580585561466,"mc":[{"id":"1.168081835","rc":[{"batl":[[0,1000,0.02]],"ltp":1.02,"tv":3.27,"id":22229228,"hc":-10.5}]}]}
{"op":"mcm","clk":"998205359","pt":1580585561877,"mc":[{"id":"1.168081835","rc":[{"trd":[[1.02,3.29]],"batb":[[0,1.02,6.8]],"batl":[[0,990,0.01]],"ltp":1.02,"tv":3.28,"id":22229228,"hc":-10.5}],"tv":9.9}]}
{"op":"mcm","clk":"998205728","pt":1580585563668,"mc":[{"id":"1.168081835","rc":[{"trd":[[1.02,3.3]],"batb":[[0,1.02,6.79]],"ltp":1.02,"tv":3.3,"id":22229228,"hc":-9.5}],"tv":9.92}]}
{"op":"mcm","clk":"998206607","pt":1580585568477,"mc":[{"id":"1.168081835","rc":[{"batl":[[0,1000,2.37]],"ltp":1.02,"tv":3.33,"id":22229228,"hc":-11.5}]}]}
{"op":"mcm","clk":"998206753","pt":1580585569284,"mc":[{"id":"1.168081835","rc":[{"trd":[[1.02,3.35]],"batb":[[0,1.02,6.76]],"batl":[[0,990,0.01]],"ltp":1.02,"tv":3.34,"id":22229228,"hc":-11.5}],"tv":9.94}]}
{"op":"mcm","clk":"998208179","pt":1580585577493,"mc":[{"id":"1.168081835","rc":[{"batl":[[0,1000,0.02]],"ltp":1.02,"tv":3.28,"id":22229228,"hc":-10.5}]}]}
{"op":"mcm","clk":"998208231","pt":1580585577772,"mc":[{"id":"1.168081835","rc":[{"trd":[[1.02,3.3]],"batb":[[0,1.02,6.79]],"batl":[[0,990,0.01]],"ltp":1.02,"tv":3.3,"id":22229228,"hc":-10.5}],"tv":9.95}]}
{"op":"mcm","clk":"998208735","pt":1580585580637,"mc":[{"id":"1.168081835","rc":[{"batl":[[0,1000,0.02]],"ltp":1.02,"tv":3.3,"id":22229228,"hc":-9.5}]}]}
{"op":"mcm","clk":"998208939","pt":1580585581668,"mc":[{"id":"1.168081835","rc":[{"trd":[[1.02,3.32]],"batb":[[0,1.02,6.78]],"batl":[[0,990,0.01]],"ltp":1.02,"tv":3.31,"id":22229228,"hc":-9.5}],"tv":9.97}]}
{"op":"mcm","clk":"998209643","pt":1580585585639,"mc":[{"id":"1.168081835","rc":[{"trd":[[1.02,3.37]],"batb":[[0,1.02,6.75]],"ltp":1.02,"tv":3.36,"id":22229228,"hc":-11.5}],"tv":9.98}]}
{"op":"mcm","clk":"998211454","pt":1580585595440,"mc":[{"id":"1.168081835","rc":[{"trd":[[1.02,3.32]],"batb":[[0,1.02,6.78]],"ltp":1.02,"tv":3.31,"id":22229228,"hc":-10.5}],"tv":10.0}]}
{"op":"mcm","clk":"998211908","pt":1580585597666,"mc":[{"id":"1.168081835","rc":[{"batl":[[0,1000,2.37]],"ltp":1.02,"tv":3.31,"id":22229228,"hc":-9.5}]}]}
{"op":"mcm","clk":"998212010","pt":1580585598158,"mc":[{"id":"1.168081835","rc":[{"trd":[[1.02,3.33]],"batb":[[0,1.02,6.77]],"batl":[[0,990,0.01]],"ltp":1.02,"tv":3.33,"id":22229228,"hc":-9.5}],"tv":10.01}]}
{"op":"mcm","clk":"998212602","pt":1580585601632,"mc":[{"id":"1.168081835","rc":[{"batl":[[0,1000,0.02]],"ltp":1.02,"tv":3.36,"id":22229228,"hc":-11.5}]}]}
{"op":"mcm","clk":"998212652","pt":1580585601956,"mc":[{"id":"1.168081835","rc":[{"trd":[[1.02,3.38]],"batb":[[0,1.02,6.74]],"batl":[[0,990,0.01]],"ltp":1.02,"tv":3.38,"id":22229228,"hc":-11.5}],"tv":10.03}]}
{"op":"mcm","clk":"998214657","pt":1580585612632,"mc":[{"id":"1.168081835","rc":[{"batl":[[0,1000,0.02]],"ltp":1.02,"tv":3.31,"id":22229228,"hc":-10.5}]}]}
{"op":"mcm","clk":"998214735","pt":1580585613021,"mc":[{"id":"1.168081835","rc":[{"trd":[[1.02,3.33]],"batb":[[0,1.02,6.77]],"batl":[[0,990,0.01]],"ltp":1.02,"tv":3.33,"id":22229228,"hc":-10.5}],"tv":10.04}]}
{"op":"mcm","clk":"998215167","pt":1580585615037,"mc":[{"id":"1.168081835","rc":[{"trd":[[1.02,3.35]],"batb":[[0,1.02,6.76]],"ltp":1.02,"tv":3.34,"id":22229228,"hc":-9.5}],"tv":10.06}]}
{"op":"mcm","clk":"998216061","pt":1580585619730,"mc":[{"id":"1.168081835","rc":[{"trd":[[1.02,3.4]],"batb":[[0,1.02,6.73]],"ltp":1.02,"tv":3.39,"id":22229228,"hc":-11.5}],"tv":10.08}]}
{"op":"mcm","clk":"998218145","pt":1580585630645,"mc":[{"id":"1.168081835","rc":[{"trd":[[1.02,3.35]],"batb":[[0,1.02,6.76]],"ltp":1.02,"tv":3.34,"id":22229228,"hc":-10.5}],"tv":10.09}]}
{"op":"mcm","clk":"998218518","pt":1580585632646,"mc":[{"id":"1.168081835","rc":[{"trd":[[1.02,3.37]],"batb":[[0,1.02,6.75]],"ltp":1.02,"tv":3.36,"id":22229228,"hc":-9.5}],"tv":10.11}]}
{"op":"mcm","clk":"998219265","pt":1580585636778,"mc":[{"id":"1.168081835","rc":[{"trd":[[1.02,3.41]],"batb":[[0,1.02,6.72]],"ltp":1.02,"tv":3.41,"id":22229228,"hc":-11.5}],"tv":10.12}]}
{"op":"mcm","clk":"998221040","pt":1580585646588,"mc":[{"id":"1.168081835","rc":[{"batl":[[0,1000,2.37]],"ltp":1.02,"tv":3.34,"id":22229228,"hc":-10.5}]}]}
{"op":"mcm","clk":"998221159","pt":1580585647175,"mc":[{"id":"1.168081835","rc":[{"trd":[[1.02,3.37]],"batb":[[0,1.02,6.75]],"batl":[[0,990,0.01]],"ltp":1.02,"tv":3.36,"id":22229228,"hc":-10.5}],"tv":10.14}]}
{"op":"mcm","clk":"998221746","pt":1580585650500,"mc":[{"id":"1.168081835","rc":[{"batl":[[0,1000,0.02]],"ltp":1.02,"tv":3.36,"id":22229228,"hc":-9.5}]}]}
{"op":"mcm","clk":"998221835","pt":1580585650980,"mc":[{"id":"1.168081835","rc":[{"trd":[[1.02,3.38]],"batb":[[0,1.02,6.74]],"batl":[[0,990,0.01]],"ltp":1.02,"tv":3.38,"id":22229228,"hc":-9.5}],"tv":10.15}]}
{"op":"mcm","clk":"998222161","pt":1580585652697,"mc":[{"id":"1.168081835","rc":[{"trd":[[1.02,3.43]],"batb":[[0,1.02,6.71]],"ltp":1.02,"tv":3.42,"id":22229228,"hc":-11.5}],"tv":10.17}]}
{"op":"mcm","clk":"998224295","pt":1580585664627,"mc":[{"id":"1.168081835","rc":[{"trd":[[1.02,3.38]],"batb":[[0,1.02,6.74]],"ltp":1.02,"tv":3.38,"id":22229228,"hc":-10.5}],"tv":10.18}]}
{"op":"mcm","clk":"998224670","pt":1580585666608,"mc":[{"id":"1.168081835","rc":[{"batl":[[0,1000,0.02]],"ltp":1.02,"tv":3.38,"id":22229228,"hc":-9.5}]}]}
{"op":"mcm","clk":"998224757","pt":1580585667133,"mc":[{"id":"1.168081835","rc":[{"trd":[[1.02,3.4]],"batb":[[0,1.02,6.73]],"batl":[[0,990,0.01]],"ltp":1.02,"tv":3.39,"id":22229228,"hc":-9.5}],"tv":10.2}]}
{"op":"mcm","clk":"998225360","pt":1580585670553,"mc":[{"id":"1.168081835","rc":[{"trd":[[1.02,3.44]],"batb":[[0,1.02,6.7]],"ltp":1.02,"tv":3.44,"id":22229228,"hc":-11.5}],"tv":10.21}]}
{"op":"mcm","clk":"998227243","pt":1580585681454,"mc":[{"id":"1.168081835","rc":[{"trd":[[1.02,3.4]],"batb":[[0,1.02,6.73]],"ltp":1.02,"tv":3.39,"id":22229228,"hc":-10.5}],"tv":10.23}]}
{"op":"mcm","clk":"998227855","pt":1580585684689,"mc":[{"id":"1.168081835","rc":[{"batl":[[0,1000,0.02]],"ltp":1.02,"tv":3.39,"id":22229228,"hc":-9.5}]}]}
{"op":"mcm","clk":"998227930","pt":1580585685066,"mc":[{"id":"1.168081835","rc":[{"trd":[[1.02,3.41]],"batb":[[0,1.02,6.72]],"batl":[[0,990,0.01]],"ltp":1.02,"tv":3.41,"id":22229228,"hc":-9.5}],"tv":10.25}]}
{"op":"mcm","clk":"998228346","pt":1580585687496,"mc":[{"id":"1.168081835","rc":[{"batl":[[0,1000,0.02]],"ltp":1.02,"tv":3.44,"id":22229228,"hc":-11.5}]}]}
{"op":"mcm","clk":"998228438","pt":1580585687875,"mc":[{"id":"1.168081835","rc":[{"trd":[[1.02,3.46]],"batb":[[0,1.02,6.69]],"batl":[[0,990,0.01]],"ltp":1.02,"tv":3.45,"id":22229228,"hc":-11.5}],"tv":10.26}]}
{"op":"mcm","clk":"998230118","pt":1580585697514,"mc":[{"id":"1.168081835","rc":[{"trd":[[1.02,3.41]],"batb":[[0,1.02,6.72]],"ltp":1.02,"tv":3.41,"id":22229228,"hc":-10.5}],"tv":10.28}]}
{"op":"mcm","clk":"998230658","pt":1580585700495,"mc":[{"id":"1.168081835","rc":[{"batl":[[0,1000,2.37]],"ltp":1.02,"tv":3.41,"id":22229228,"hc":-9.5}]}]}
{"op":"mcm","clk":"998230772","pt":1580585701097,"mc":[{"id":"1.168081835","rc":[{"trd":[[1.02,3.43]],"batb":[[0,1.02,6.71]],"batl":[[0,990,0.01]],"ltp":1.02,"tv":3.42,"id":22229228,"hc":-9.5}],"tv":10.29}]}
{"op":"mcm","clk":"998231374","pt":1580585704668,"mc":[{"id":"1.168081835","rc":[{"batl":[[0,1000,2.37]],"ltp":1.02,"tv":3.45,"id":22229228,"hc":-11.5}]}]}
{"op":"mcm","clk":"998231490","pt":1580585705263,"mc":[{"id":"1.168081835","rc":[{"trd":[[1.02,3.47]],"batb":[[0,1.02,6.68]],"batl":[[0,990,0.01]],"ltp":1.02,"tv":3.47,"id":22229228,"hc":-11.5}],"tv":10.31}]}
{"op":"mcm","clk":"998232917","pt":1580585713573,"mc":[{"id":"1.168081835","rc":[{"batl":[[0,1000,2.37]],"ltp":1.02,"tv":3.41,"id":22229228,"hc":-10.5}]}]}
{"op":"mcm","clk":"998233063","pt":1580585714375,"mc":[{"id":"1.168081835","rc":[{"trd":[[1.02,3.43]],"batb":[[0,1.02,6.71]],"batl":[[0,990,0.01]],"ltp":1.02,"tv":3.42,"id":22229228,"hc":-10.5}],"tv":10.32}]}
{"op":"mcm","clk":"998233683","pt":1580585717592,"mc":[{"id":"1.168081835","rc":[{"batl":[[0,1000,0.02]],"ltp":1.02,"tv":3.42,"id":22229228,"hc":-9.5}]}]}
{"op":"mcm","clk":"998233752","pt":1580585718007,"mc":[{"id":"1.168081835","rc":[{"trd":[[1.02,3.44]],"batb":[[0,1.02,6.7]],"batl":[[0,990,0.01]],"ltp":1.02,"tv":3.44,"id":22229228,"hc":-9.5}],"tv":10.34}]}
{"op":"mcm","clk":"998234414","pt":1580585721615,"mc":[{"id":"1.168081835","rc":[{"batl":[[0,1000,0.02]],"ltp":1.02,"tv":3.47,"id":22229228,"hc":-11.5}]}]}
{"op":"mcm","clk":"998234487","pt":1580585721999,"mc":[{"id":"1.168081835","rc":[{"trd":[[1.02,3.49]],"batb":[[0,1.02,6.67]],"batl":[[0,990,0.01]],"ltp":1.02,"tv":3.48,"id":22229228,"hc":-11.5}],"tv":10.35}]}
{"op":"mcm","clk":"998235906","pt":1580585730501,"mc":[{"id":"1.168081835","rc":[{"trd":[[1.02,3.44]],"batb":[[0,1.02,6.7]],"ltp":1.02,"tv":3.44,"id":22229228,"hc":-10.5}],"tv":10.37}]}
{"op":"mcm","clk":"998236846","pt":1580585735610,"mc":[{"id":"1.168081835","rc":[{"batl":[[0,1000,0.02]],"ltp":1.02,"tv":3.44,"id":22229228,"hc":-9.5}]}]}
{"op":"mcm","clk":"998236928","pt":1580585736053,"mc":[{"id":"1.168081835","rc":[{"trd":[[1.02,3.46]],"batb":[[0,1.02,6.69]],"batl":[[0,990,0.01]],"ltp":1.02,"tv":3.45,"id":22229228,"hc":-9.5}],"tv":10.39}]}
{"op":"mcm","clk":"998237362","pt":1580585738430,"mc":[{"id":"1.168081835","rc":[{"batl":[[0,1000,0.02]],"ltp":1.02,"tv":3.48,"id":22229228,"hc":-11.5}]}]}
{"op":"mcm","clk":"998237433","pt":1580585738811,"mc":[{"id":"1.168081835","rc":[{"trd":[[1.02,3.5]],"batb":[[0,1.02,6.66]],"batl":[[0,990,0.01]],"ltp":1.02,"tv":3.5,"id":22229228,"hc":-11.5}],"tv":10.4}]}
{"op":"mcm","clk":"998239046","pt":1580585747750,"mc":[{"id":"1.168081835","rc":[{"trd":[[1.02,3.46]],"batb":[[0,1.02,6.69]],"ltp":1.02,"tv":3.45,"id":22229228,"hc":-10.5}],"tv":10.42}]}
{"op":"mcm","clk":"998240131","pt":1580585753666,"mc":[{"id":"1.168081835","rc":[{"batl":[[0,1000,2.37]],"ltp":1.02,"tv":3.45,"id":22229228,"hc":-9.5}]}]}
{"op":"mcm","clk":"998240231","pt":1580585754262,"mc":[{"id":"1.168081835","rc":[{"trd":[[1.02,3.47]],"batb":[[0,1.02,6.68]],"batl":[[0,990,0.01]],"ltp":1.02,"tv":3.47,"id":22229228,"hc":-9.5}],"tv":10.43}]}
{"op":"mcm","clk":"998240512","pt":1580585755776,"mc":[{"id":"1.168081835","rc":[{"trd":[[1.02,3.52]],"batb":[[0,1.02,6.65]],"ltp":1.02,"tv":3.52,"id":22229228,"hc":-11.5}],"tv":10.45}]}
{"op":"mcm","clk":"998242163","pt":1580585765588,"mc":[{"id":"1.168081835","rc":[{"batl":[[0,1000,0.02]],"ltp":1.02,"tv":3.45,"id":22229228,"hc":-10.5}]}]}
{"op":"mcm","clk":"998242226","pt":1580585765988,"mc":[{"id":"1.168081835","rc":[{"trd":[[1.02,3.47]],"batb":[[0,1.02,6.68]],"batl":[[0,990,0.01]],"ltp":1.02,"tv":3.47,"id":22229228,"hc":-10.5}],"tv":10.46}]}
{"op":"mcm","clk":"998243012","pt":1580585770661,"mc":[{"id":"1.168081835","rc":[{"batl":[[0,1000,2.37]],"ltp":1.02,"tv":3.47,"id":22229228,"hc":-9.5}]}]}
{"op":"mcm","clk":"998243117","pt":1580585771247,"mc":[{"id":"1.168081835","rc":[{"trd":[[1.02,3.49]],"batb":[[0,1.02,6.67]],"batl":[[0,990,0.01]],"ltp":1.02,"tv":3.48,"id":22229228,"hc":-9.5}],"tv":10.48}]}
{"op":"mcm","clk":"998243353","pt":1580585772589,"mc":[{"id":"1.168081835","rc":[{"batl":[[0,1000,0.02]],"ltp":1.02,"tv":3.52,"id":22229228,"hc":-11.5}]}]}
{"op":"mcm","clk":"998243420","pt":1580585772959,"mc":[{"id":"1.168081835","rc":[{"trd":[[1.02,3.54]],"batb":[[0,1.02,6.64]],"batl":[[0,990,0.01]],"ltp":1.02,"tv":3.53,"id":22229228,"hc":-11.5}],"tv":10.49}]}
{"op":"mcm","clk":"998245046","pt":1580585782596,"mc":[{"id":"1.168081835","rc":[{"trd":[[1.02,3.49]],"batb":[[0,1.02,6.67]],"ltp":1.02,"tv":3.48,"id":22229228,"hc":-10.5}],"tv":10.51}]}
{"op":"mcm","clk":"998246016","pt":1580585788489,"mc":[{"id":"1.168081835","rc":[{"trd":[[1.02,3.5]],"batb":[[0,1.02,6.66]],"ltp":1.02,"tv":3.5,"id":22229228,"hc":-9.5}],"tv":10.52}]}
{"op":"mcm","clk":"998246348","pt":1580585790481,"mc":[{"id":"1.168081835","rc":[{"trd":[[1.02,3.55]],"batb":[[0,1.02,6.63]],"ltp":1.02,"tv":3.55,"id":22229228,"hc":-11.5}],"tv":10.54}]}
{"op":"mcm","clk":"998247866","pt":1580585799383,"mc":[{"id":"1.168081835","rc":[{"batl":[[0,1000,0.02]],"ltp":1.02,"tv":3.48,"id":22229228,"hc":-10.5}]}]}
{"op":"mcm","clk":"998247930","pt":1580585799814,"mc":[{"id":"1.168081835","rc":[{"trd":[[1.02,3.5]],"batb":[[0,1.02,6.66]],"batl":[[0,990,0.01]],"ltp":1.02,"tv":3.5,"id":22229228,"hc":-10.5}],"tv":10.56}]}
{"op":"mcm","clk":"998248898","pt":1580585805221,"mc":[{"id":"1.168081835","rc":[{"trd":[[1.02,3.52]],"batb":[[0,1.02,6.65]],"ltp":1.02,"tv":3.52,"id":22229228,"hc":-9.5}],"tv":10.57}]}
{"op":"mcm","clk":"998249293","pt":1580585807440,"mc":[{"id":"1.168081835","rc":[{"batl":[[0,1000,2.37]],"ltp":1.02,"tv":3.55,"id":22229228,"hc":-11.5}]}]}
{"op":"mcm","clk":"998249415","pt":1580585808033,"mc":[{"id":"1.168081835","rc":[{"trd":[[1.02,3.57]],"batb":[[0,1.02,6.62]],"batl":[[0,990,0.01]],"ltp":1.02,"tv":3.56,"id":22229228,"hc":-11.5}],"tv":10.59}]}
{"op":"mcm","clk":"998250897","pt":1580585816631,"mc":[{"id":"1.168081835","rc":[{"trd":[[1.02,3.52]],"batb":[[0,1.02,6.65]],"ltp":1.02,"tv":3.52,"id":22229228,"hc":-10.5}],"tv":10.6}]}
{"op":"mcm","clk":"998251778","pt":1580585821683,"mc":[{"id":"1.168081835","rc":[{"trd":[[1.02,3.54]],"batb":[[0,1.02,6.64]],"ltp":1.02,"tv":3.53,"id":22229228,"hc":-9.5}],"tv":10.62}]}
{"op":"mcm","clk":"998252431","pt":1580585825562,"mc":[{"id":"1.168081835","rc":[{"batl":[[0,1000,0.02]],"ltp":1.02,"tv":3.56,"id":22229228,"hc":-11.5}]}]}
{"op":"mcm","clk":"998252504","pt":1580585826054,"mc":[{"id":"1.168081835","rc":[{"trd":[[1.02,3.58]],"batb":[[0,1.02,6.61]],"batl":[[0,990,0.01]],"ltp":1.02,"tv":3.58,"id":22229228,"hc":-11.5}],"tv":10.63}]}
{"op":"mcm","clk":"998253795","pt":1580585833361,"mc":[{"id":"1.168081835","rc":[{"trd":[[1.02,3.54]],"batb":[[0,1.02,6.64]],"ltp":1.02,"tv":3.53,"id":22229228,"hc":-10.5}],"tv":10.65}]}
{"op":"mcm","clk":"998254639","pt":1580585838390,"mc":[{"id":"1.168081835","rc":[{"batl":[[0,1000,0.02]],"ltp":1.02,"tv":3.53,"id":22229228,"hc":-9.5}]}]}
{"op":"mcm","clk":"998254710","pt":1580585838815,"mc":[{"id":"1.168081835","rc":[{"trd":[[1.02,3.55]],"batb":[[0,1.02,6.63]],"batl":[[0,990,0.01]],"ltp":1.02,"tv":3.55,"id":22229228,"hc":-9.5}],"tv":10.66}]}
{"op":"mcm","clk":"998255338","pt":1580585842694,"mc":[{"id":"1.168081835","rc":[{"batl":[[0,1000,2.37]],"ltp":1.02,"tv":3.58,"id":22229228,"hc":-11.5}]}]}
{"op":"mcm","clk":"998255420","pt":1580585843198,"mc":[{"id":"1.168081835","rc":[{"trd":[[1.02,3.6]],"batb":[[0,1.02,6.6]],"batl":[[0,990,0.01]],"ltp":1.02,"tv":3.59,"id":22229228,"hc":-11.5}],"tv":10.68}]}
{"op":"mcm","clk":"998256511","pt":1580585849708,"mc":[{"id":"1.168081835","rc":[{"trd":[[1.02,3.55]],"batb":[[0,1.02,6.63]],"ltp":1.02,"tv":3.55,"id":22229228,"hc":-10.5}],"tv":10.7}]}
{"op":"mcm","clk":"998257475","pt":1580585855531,"mc":[{"id":"1.168081835","rc":[{"batl":[[0,1000,0.02]],"ltp":1.02,"tv":3.55,"id":22229228,"hc":-9.5}]}]}
{"op":"mcm","clk":"998257549","pt":1580585855945,"mc":[{"id":"1.168081835","rc":[{"trd":[[1.02,3.57]],"batb":[[0,1.02,6.62]],"batl":[[0,990,0.01]],"ltp":1.02,"tv":3.56,"id":22229228,"hc":-9.5}],"tv":10.71}]}
{"op":"mcm","clk":"998257988","pt":1580585858546,"mc":[{"id":"1.168081835","rc":[{"batl":[[0,1000,2.37]],"ltp":1.02,"tv":3.59,"id":22229228,"hc":-11.5}]}]}
{"op":"mcm","clk":"998258116","pt":1580585859243,"mc":[{"id":"1.168081835","rc":[{"trd":[[1.02,3.61]],"batb":[[0,1.02,6.59]],"batl":[[0,990,0.01]],"ltp":1.02,"tv":3.61,"id":22229228,"hc":-11.5}],"tv":10.73}]}
{"op":"mcm","clk":"998259639","pt":1580585867640,"mc":[{"id":"1.168081835","rc":[{"trd":[[1.02,3.57]],"batb":[[0,1.02,6.62]],"ltp":1.02,"tv":3.56,"id":22229228,"hc":-10.5}],"tv":10.74}]}
{"op":"mcm","clk":"998260516","pt":1580585872647,"mc":[{"id":"1.168081835","rc":[{"batl":[[0,1000,2.37]],"ltp":1.02,"tv":3.56,"id":22229228,"hc":-9.5}]}]}
