{"op":"mcm","clk":"978249338","pt":1580359851794,"mc":[{"id":"1.168081860","marketDefinition":{"bspMarket":false,"turnInPlayEnabled":true,"persistenceEnabled":true,"marketBaseRate":5.0,"eventId":"29676917","eventTypeId":"2","numberOfWinners":0,"bettingType":"ASIAN_HANDICAP_DOUBLE_LINE","marketType":"COMBINED_TOTAL","marketTime":"2020-02-02T05:00:00.000Z","suspendTime":"2020-02-02T05:00:00.000Z","bspReconciled":false,"complete":true,"inPlay":false,"crossMatching":false,"runnersVoidable":false,"numberOfActiveRunners":54,"betDelay":0,"status":"OPEN","runners":[{"status":"ACTIVE","sortPriority":1,"id":7698577,"hc":12.5,"name":"Under"},{"status":"ACTIVE","sortPriority":2,"id":7698572,"hc":12.5,"name":"Over"},{"status":"ACTIVE","sortPriority":3,"id":7698577,"hc":13.5,"name":"Under"},{"status":"ACTIVE","sortPriority":4,"id":7698572,"hc":13.5,"name":"Over"},{"status":"ACTIVE","sortPriority":5,"id":7698577,"hc":14.5,"name":"Under"},{"status":"ACTIVE","sortPriority":6,"id":7698572,"hc":14.5,"name":"Over"},{"status":"ACTIVE","sortPriority":7,"id":7698577,"hc":15.5,"name":"Under"},{"status":"ACTIVE","sortPriority":8,"id":7698572,"hc":15.5,"name":"Over"},{"status":"ACTIVE","sortPriority":9,"id":7698577,"hc":16.5,"name":"Under"},{"status":"ACTIVE","sortPriority":10,"id":7698572,"hc":16.5,"name":"Over"},{"status":"ACTIVE","sortPriority":11,"id":7698577,"hc":17.5,"name":"Under"},{"status":"ACTIVE","sortPriority":12,"id":7698572,"hc":17.5,"name":"Over"},{"status":"ACTIVE","sortPriority":13,"id":7698577,"hc":18.5,"name":"Under"},{"status":"ACTIVE","sortPriority":14,"id":7698572,"hc":18.5,"name":"Over"},{"status":"ACTIVE","sortPriority":15,"id":7698577,"hc":19.5,"name":"Under"},{"status":"ACTIVE","sortPriority":16,"id":7698572,"hc":19.5,"name":"Over"},{"status":"ACTIVE","sortPriority":17,"id":7698577,"hc":20.5,"name":"Under"},{"status":"ACTIVE","sortPriority":18,"id":7698572,"hc":20.5,"name":"Over"},{"status":"ACTIVE","sortPriority":19,"id":7698577,"hc":21.5,"name":"Under"},{"status":"ACTIVE","sortPriority":20,"id":7698572,"hc":21.5,"name":"Over"},{"status":"ACTIVE","sortPriority":21,"id":7698577,"hc":22.5,"name":"Under"},{"status":"ACTIVE","sortPriority":22,"id":7698572,"hc":22.5,"name":"Over"},{"status":"ACTIVE","sortPriority":23,"id":7698577,"hc":23.5,"name":"Under"},{"status":"ACTIVE","sortPriority":24,"id":7698572,"hc":23.5,"name":"Over"},{"status":"ACTIVE","sortPriority":25,"id":7698577,"hc":24.5,"name":"Under"},{"status":"ACTIVE","sortPriority":26,"id":7698572,"hc":24.5,"name":"Over"},{"status":"ACTIVE","sortPriority":27,"id":7698577,"hc":25.5,"name":"Under"},{"status":"ACTIVE","sortPriority":28,"id":7698572,"hc":25.5,"name":"Over"},{"status":"ACTIVE","sortPriority":29,"id":7698577,"hc":26.5,"name":"Under"},{"status":"ACTIVE","sortPriority":30,"id":7698572,"hc":26.5,"name":"Over"},{"status":"ACTIVE","sortPriority":31,"id":7698577,"hc":27.5,"name":"Under"},{"status":"ACTIVE","sortPriority":32,"id":7698572,"hc":27.5,"name":"Over"},{"status":"ACTIVE","sortPriority":33,"id":7698577,"hc":28.5,"name":"Under"},{"status":"ACTIVE","sortPriority":34,"id":7698572,"hc":28.5,"name":"Over"},{"status":"ACTIVE","sortPriority":35,"id":7698577,"hc":29.5,"name":"Under"},{"status":"ACTIVE","sortPriority":36,"id":7698572,"hc":29.5,"name":"Over"},{"status":"ACTIVE","sortPriority":37,"id":7698577,"hc":30.5,"name":"Under"},{"status":"ACTIVE","sortPriority":38,"id":7698572,"hc":30.5,"name":"Over"},{"status":"ACTIVE","sortPriority":39,"id":7698577,"hc":31.5,"name":"Under"},{"status":"ACTIVE","sortPriority":40,"id":7698572,"hc":31.5,"name":"Over"},{"status":"ACTIVE","sortPriority":41,"id":7698577,"hc":32.5,"name":"Under"},{"status":"ACTIVE","sortPriority":42,"id":7698572,"hc":32.5,"name":"Over"},{"status":"ACTIVE","sortPriority":43,"id":7698577,"hc":33.5,"name":"Under"},{"status":"ACTIVE","sortPriority":44,"id":7698572,"hc":33.5,"name":"Over"},{"status":"ACTIVE","sortPriority":45,"id":7698577,"hc":34.5,"name":"Under"},{"status":"ACTIVE","sortPriority":46,"id":7698572,"hc":34.5,"name":"Over"},{"status":"ACTIVE","sortPriority":47,"id":7698577,"hc":35.5,"name":"Under"},{"status":"ACTIVE","sortPriority":48,"id":7698572,"hc":35.5,"name":"Over"},{"status":"ACTIVE","sortPriority":49,"id":7698577,"hc":36.5,"name":"Under"},{"status":"ACTIVE","sortPriority":50,"id":7698572,"hc":36.5,"name":"Over"},{"status":"ACTIVE","sortPriority":51,"id":7698577,"hc":37.5,"name":"Under"},{"status":"ACTIVE","sortPriority":52,"id":7698572,"hc":37.5,"name":"Over"},{"status":"ACTIVE","sortPriority":53,"id":7698577,"hc":38.5,"name":"Under"},{"status":"ACTIVE","sortPriority":54,"id":7698572,"hc":38.5,"name":"Over"}],"regulators":["MR_INT"],"countryCode":"AU","discountAllowed":false,"timezone":"GMT","openDate":"2020-02-02T05:00:00.000Z","version":3141663939,"name":"Total Games","eventName":"Ram/Salisbury v Purcell/Saville"}}]}
{"op":"mcm","clk":"978249383","pt":1580359853794,"mc":[{"id":"1.168081860","marketDefinition":{"bspMarket":false,"turnInPlayEnabled":true,"persistenceEnabled":true,"marketBaseRate":5.0,"eventId":"29676917","eventTypeId":"2","numberOfWinners":0,"bettingType":"ASIAN_HANDICAP_DOUBLE_LINE","marketType":"COMBINED_TOTAL","marketTime":"2020-02-02T05:00:00.000Z","suspendTime":"2020-02-02T05:00:00.000Z","bspReconciled":false,"complete":true,"inPlay":false,"crossMatching":false,"runnersVoidable":false,"numberOfActiveRunners":54,"betDelay":0,"status":"OPEN","runners":[{"status":"ACTIVE","sortPriority":1,"id":7698577,"hc":12.5,"name":"Under"},{"status":"ACTIVE","sortPriority":2,"id":7698572,"hc":12.5,"name":"Over"},{"status":"ACTIVE","sortPriority":3,"id":7698577,"hc":13.5,"name":"Under"},{"status":"ACTIVE","sortPriority":4,"id":7698572,"hc":13.5,"name":"Over"},{"status":"ACTIVE","sortPriority":5,"id":7698577,"hc":14.5,"name":"Under"},{"status":"ACTIVE","sortPriority":6,"id":7698572,"hc":14.5,"name":"Over"},{"status":"ACTIVE","sortPriority":7,"id":7698577,"hc":15.5,"name":"Under"},{"status":"ACTIVE","sortPriority":8,"id":7698572,"hc":15.5,"name":"Over"},{"status":"ACTIVE","sortPriority":9,"id":7698577,"hc":16.5,"name":"Under"},{"status":"ACTIVE","sortPriority":10,"id":7698572,"hc":16.5,"name":"Over"},{"status":"ACTIVE","sortPriority":11,"id":7698577,"hc":17.5,"name":"Under"},{"status":"ACTIVE","sortPriority":12,"id":7698572,"hc":17.5,"name":"Over"},{"status":"ACTIVE","sortPriority":13,"id":7698577,"hc":18.5,"name":"Under"},{"status":"ACTIVE","sortPriority":14,"id":7698572,"hc":18.5,"name":"Over"},{"status":"ACTIVE","sortPriority":15,"id":7698577,"hc":19.5,"name":"Under"},{"status":"ACTIVE","sortPriority":16,"id":7698572,"hc":19.5,"name":"Over"},{"status":"ACTIVE","sortPriority":17,"id":7698577,"hc":20.5,"name":"Under"},{"status":"ACTIVE","sortPriority":18,"id":7698572,"hc":20.5,"name":"Over"},{"status":"ACTIVE","sortPriority":19,"id":7698577,"hc":21.5,"name":"Under"},{"status":"ACTIVE","sortPriority":20,"id":7698572,"hc":21.5,"name":"Over"},{"status":"ACTIVE","sortPriority":21,"id":7698577,"hc":22.5,"name":"Under"},{"status":"ACTIVE","sortPriority":22,"id":7698572,"hc":22.5,"name":"Over"},{"status":"ACTIVE","sortPriority":23,"id":7698577,"hc":23.5,"name":"Under"},{"status":"ACTIVE","sortPriority":24,"id":7698572,"hc":23.5,"name":"Over"},{"status":"ACTIVE","sortPriority":25,"id":7698577,"hc":24.5,"name":"Under"},{"status":"ACTIVE","sortPriority":26,"id":7698572,"hc":24.5,"name":"Over"},{"status":"ACTIVE","sortPriority":27,"id":7698577,"hc":25.5,"name":"Under"},{"status":"ACTIVE","sortPriority":28,"id":7698572,"hc":25.5,"name":"Over"},{"status":"ACTIVE","sortPriority":29,"id":7698577,"hc":26.5,"name":"Under"},{"status":"ACTIVE","sortPriority":30,"id":7698572,"hc":26.5,"name":"Over"},{"status":"ACTIVE","sortPriority":31,"id":7698577,"hc":27.5,"name":"Under"},{"status":"ACTIVE","sortPriority":32,"id":7698572,"hc":27.5,"name":"Over"},{"status":"ACTIVE","sortPriority":33,"id":7698577,"hc":28.5,"name":"Under"},{"status":"ACTIVE","sortPriority":34,"id":7698572,"hc":28.5,"name":"Over"},{"status":"ACTIVE","sortPriority":35,"id":7698577,"hc":29.5,"name":"Under"},{"status":"ACTIVE","sortPriority":36,"id":7698572,"hc":29.5,"name":"Over"},{"status":"ACTIVE","sortPriority":37,"id":7698577,"hc":30.5,"name":"Under"},{"status":"ACTIVE","sortPriority":38,"id":7698572,"hc":30.5,"name":"Over"},{"status":"ACTIVE","sortPriority":39,"id":7698577,"hc":31.5,"name":"Under"},{"status":"ACTIVE","sortPriority":40,"id":7698572,"hc":31.5,"name":"Over"},{"status":"ACTIVE","sortPriority":41,"id":7698577,"hc":32.5,"name":"Under"},{"status":"ACTIVE","sortPriority":42,"id":7698572,"hc":32.5,"name":"Over"},{"status":"ACTIVE","sortPriority":43,"id":7698577,"hc":33.5,"name":"Under"},{"status":"ACTIVE","sortPriority":44,"id":7698572,"hc":33.5,"name":"Over"},{"status":"ACTIVE","sortPriority":45,"id":7698577,"hc":34.5,"name":"Under"},{"status":"ACTIVE","sortPriority":46,"id":7698572,"hc":34.5,"name":"Over"},{"status":"ACTIVE","sortPriority":47,"id":7698577,"hc":35.5,"name":"Under"},{"status":"ACTIVE","sortPriority":48,"id":7698572,"hc":35.5,"name":"Over"},{"status":"ACTIVE","sortPriority":49,"id":7698577,"hc":36.5,"name":"Under"},{"status":"ACTIVE","sortPriority":50,"id":7698572,"hc":36.5,"name":"Over"},{"status":"ACTIVE","sortPriority":51,"id":7698577,"hc":37.5,"name":"Under"},{"status":"ACTIVE","sortPriority":52,"id":7698572,"hc":37.5,"name":"Over"},{"status":"ACTIVE","sortPriority":53,"id":7698577,"hc":38.5,"name":"Under"},{"status":"ACTIVE","sortPriority":54,"id":7698572,"hc":38.5,"name":"Over"}],"regulators":["MR_INT"],"countryCode":"AU","discountAllowed":true,"timezone":"GMT","openDate":"2020-02-02T05:00:00.000Z","version":3141663939,"name":"Total Games","eventName":"Ram/Salisbury v Purcell/Saville"}}]}
{"op":"mcm","clk":"979661860","pt":1580391110276,"mc":[{"id":"1.168081860","rc":[{"batb":[[0,2.1,458.51]],"ltp":0.0,"tv":0.0,"id":7698577,"hc":12.5},{"batl":[[0,2.1,458.51]],"ltp":0.0,"tv":0.0,"id":7698572,"hc":12.5}]}]}
{"op":"mcm","clk":"979756007","pt":1580392193018,"mc":[{"id":"1.168081860","rc":[{"batb":[[0,2.12,6.79],[1,2.1,458.51]],"ltp":0.0,"tv":0.0,"id":7698577,"hc":12.5}]}]}
{"op":"mcm","clk":"979815299","pt":1580392951883,"mc":[{"id":"1.168081860","rc":[{"batb":[[0,2.12,6.76],[1,2.1,455.62]],"ltp":0.0,"tv":0.0,"id":7698577,"hc":12.5},{"batl":[[0,2.1,455.62]],"ltp":0.0,"tv":0.0,"id":7698572,"hc":12.5}]}]}
{"op":"mcm","clk":"980193878","pt":1580400151879,"mc":[{"id":"1.168081860","rc":[{"batb":[[0,2.12,6.75],[1,2.1,454.48]],"ltp":0.0,"tv":0.0,"id":7698577,"hc":12.5},{"batl":[[0,2.1,454.48]],"ltp":0.0,"tv":0.0,"id":7698572,"hc":12.5}]}]}
{"op":"mcm","clk":"980489115","pt":1580407351884,"mc":[{"id":"1.168081860","rc":[{"batb":[[0,2.12,6.76],[1,2.1,454.75]],"ltp":0.0,"tv":0.0,"id":7698577,"hc":12.5},{"batl":[[0,2.1,454.75]],"ltp":0.0,"tv":0.0,"id":7698572,"hc":12.5}]}]}
{"op":"mcm","clk":"980906850","pt":1580414551883,"mc":[{"id":"1.168081860","rc":[{"batb":[[0,2.12,6.76],[1,2.1,455.59]],"ltp":0.0,"tv":0.0,"id":7698577,"hc":12.5},{"batl":[[0,2.1,455.59]],"ltp":0.0,"tv":0.0,"id":7698572,"hc":12.5}]}]}
{"op":"mcm","clk":"981330261","pt":1580421751925,"mc":[{"id":"1.168081860","rc":[{"batb":[[0,2.12,6.76],[1,2.1,455.9]],"ltp":0.0,"tv":0.0,"id":7698577,"hc":12.5},{"batl":[[0,2.1,455.9]],"ltp":0.0,"tv":0.0,"id":7698572,"hc":12.5}]}]}
{"op":"mcm","clk":"981763507","pt":1580428951899,"mc":[{"id":"1.168081860","rc":[{"batb":[[0,2.12,6.76],[1,2.1,455.17]],"ltp":0.0,"tv":0.0,"id":7698577,"hc":12.5},{"batl":[[0,2.1,455.17]],"ltp":0.0,"tv":0.0,"id":7698572,"hc":12.5}]}]}
{"op":"mcm","clk":"982219421","pt":1580436151918,"mc":[{"id":"1.168081860","rc":[{"batb":[[0,2.12,6.76],[1,2.1,455.29]],"ltp":0.0,"tv":0.0,"id":7698577,"hc":12.5},{"batl":[[0,2.1,455.29]],"ltp":0.0,"tv":0.0,"id":7698572,"hc":12.5}]}]}
{"op":"mcm","clk":"982562468","pt":1580443351901,"mc":[{"id":"1.168081860","rc":[{"batb":[[0,2.12,6.76],[1,2.1,455.22]],"ltp":0.0,"tv":0.0,"id":7698577,"hc":12.5},{"batl":[[0,2.1,455.22]],"ltp":0.0,"tv":0.0,"id":7698572,"hc":12.5}]}]}
{"op":"mcm","clk":"982840736","pt":1580450551921,"mc":[{"id":"1.168081860","rc":[{"batb":[[0,2.12,6.76],[1,2.1,455.69]],"ltp":0.0,"tv":0.0,"id":7698577,"hc":12.5},{"batl":[[0,2.1,455.69]],"ltp":0.0,"tv":0.0,"id":7698572,"hc":12.5}]}]}
{"op":"mcm","clk":"983196589","pt":1580457751914,"mc":[{"id":"1.168081860","rc":[{"batb":[[0,2.12,6.74],[1,2.1,453.92]],"ltp":0.0,"tv":0.0,"id":7698577,"hc":12.5},{"batl":[[0,2.1,453.92]],"ltp":0.0,"tv":0.0,"id":7698572,"hc":12.5}]}]}
{"op":"mcm","clk":"983817390","pt":1580464951885,"mc":[{"id":"1.168081860","rc":[{"batb":[[0,2.12,6.75],[1,2.1,452.71]],"ltp":0.0,"tv":0.0,"id":7698577,"hc":12.5},{"batl":[[0,2.1,452.71]],"ltp":0.0,"tv":0.0,"id":7698572,"hc":12.5}]}]}
{"op":"mcm","clk":"984674416","pt":1580472151902,"mc":[{"id":"1.168081860","rc":[{"batb":[[0,2.12,6.74],[1,2.1,452.74]],"ltp":0.0,"tv":0.0,"id":7698577,"hc":12.5},{"batl":[[0,2.1,452.74]],"ltp":0.0,"tv":0.0,"id":7698572,"hc":12.5}]}]}
{"op":"mcm","clk":"985712801","pt":1580479351896,"mc":[{"id":"1.168081860","rc":[{"batb":[[0,2.12,6.73],[1,2.1,452.85]],"ltp":0.0,"tv":0.0,"id":7698577,"hc":12.5},{"batl":[[0,2.1,452.85]],"ltp":0.0,"tv":0.0,"id":7698572,"hc":12.5}]}]}
{"op":"mcm","clk":"986471952","pt":1580486551903,"mc":[{"id":"1.168081860","rc":[{"batb":[[0,2.12,6.71],[1,2.1,451.08]],"ltp":0.0,"tv":0.0,"id":7698577,"hc":12.5},{"batl":[[0,2.1,451.08]],"ltp":0.0,"tv":0.0,"id":7698572,"hc":12.5}]}]}
{"op":"mcm","clk":"987055242","pt":1580493751895,"mc":[{"id":"1.168081860","rc":[{"batb":[[0,2.12,6.71],[1,2.1,450.65]],"ltp":0.0,"tv":0.0,"id":7698577,"hc":12.5},{"batl":[[0,2.1,450.65]],"ltp":0.0,"tv":0.0,"id":7698572,"hc":12.5}]}]}
{"op":"mcm","clk":"987924238","pt":1580500951900,"mc":[{"id":"1.168081860","rc":[{"batb":[[0,2.12,6.7],[1,2.1,450.42]],"ltp":0.0,"tv":0.0,"id":7698577,"hc":12.5},{"batl":[[0,2.1,450.42]],"ltp":0.0,"tv":0.0,"id":7698572,"hc":12.5}]}]}
{"op":"mcm","clk":"988687952","pt":1580508151902,"mc":[{"id":"1.168081860","rc":[{"batb":[[0,2.12,6.7],[1,2.1,449.78]],"ltp":0.0,"tv":0.0,"id":7698577,"hc":12.5},{"batl":[[0,2.1,449.78]],"ltp":0.0,"tv":0.0,"id":7698572,"hc":12.5}]}]}
{"op":"mcm","clk":"997608128","pt":1580581829319,"mc":[{"id":"1.168081860","rc":[{"batb":[[2,1.02,4.99]],"ltp":0.0,"tv":0.0,"id":7698577,"hc":12.5},{"batb":[[0,1.02,4.99]],"ltp":0.0,"tv":0.0,"id":7698577,"hc":13.5},{"batb":[[0,1.02,4.99]],"ltp":0.0,"tv":0.0,"id":7698577,"hc":14.5}]}]}
{"op":"mcm","clk":"997609864","pt":1580581839393,"mc":[{"id":"1.168081860","rc":[{"batb":[[2,1.02,0]],"ltp":0.0,"tv":0.0,"id":7698577,"hc":12.5}]}]}
{"op":"mcm","clk":"997630727","pt":1580581961159,"mc":[{"id":"1.168081860","rc":[{"batb":[[0,1.02,8.92]],"ltp":0.0,"tv":0.0,"id":7698577,"hc":13.5}]}]}
{"op":"mcm","clk":"997631717","pt":1580581966681,"mc":[{"id":"1.168081860","rc":[{"batl":[[0,990,0.01]],"ltp":0.0,"tv":0.0,"id":7698577,"hc":13.5}]}]}
{"op":"mcm","clk":"997633299","pt":1580581975336,"mc":[{"id":"1.168081860","rc":[{"batl":[[0,990,0.01]],"ltp":0.0,"tv":0.0,"id":7698577,"hc":13.5}]}]}
{"op":"mcm","clk":"997633632","pt":1580581976965,"mc":[{"id":"1.168081860","rc":[{"batb":[[0,1.02,8.92]],"ltp":0.0,"tv":0.0,"id":7698577,"hc":14.5}]}]}
{"op":"mcm","clk":"997634262","pt":1580581980403,"mc":[{"id":"1.168081860","rc":[{"batl":[[0,1000,0.01]],"ltp":0.0,"tv":0.0,"id":7698577,"hc":14.5}]}]}
{"op":"mcm","clk":"997634459","pt":1580581981390,"mc":[{"id":"1.168081860","rc":[{"batl":[[0,990,0.01]],"ltp":0.0,"tv":0.0,"id":7698577,"hc":14.5}]}]}
{"op":"mcm","clk":"997635796","pt":1580581988632,"mc":[{"id":"1.168081860","rc":[{"batl":[[0,1000,0.02]],"ltp":0.0,"tv":0.0,"id":7698577,"hc":13.5}]}]}
{"op":"mcm","clk":"997635963","pt":1580581989602,"mc":[{"id":"1.168081860","rc":[{"batl":[[0,990,0.01]],"ltp":0.0,"tv":0.0,"id":7698577,"hc":14.5}]}]}
{"op":"mcm","clk":"997636048","pt":1580581990023,"mc":[{"id":"1.168081860","rc":[{"trd":[[1.02,0.02]],"batb":[[0,1.02,8.91]],"batl":[[0,990,0.01]],"ltp":1.02,"tv":0.01,"id":7698577,"hc":13.5}],"tv":0.01}]}
{"op":"mcm","clk":"997638129","pt":1580582002522,"mc":[{"id":"1.168081860","rc":[{"batl":[[0,1000,0.02]],"ltp":0.0,"tv":0.0,"id":7698577,"hc":14.5}]}]}
{"op":"mcm","clk":"997638183","pt":1580582002846,"mc":[{"id":"1.168081860","rc":[{"trd":[[1.02,0.02]],"batb":[[0,1.02,8.91]],"batl":[[0,990,0.01]],"ltp":1.02,"tv":0.01,"id":7698577,"hc":14.5}],"tv":0.03}]}
{"op":"mcm","clk":"997641912","pt":1580582025674,"mc":[{"id":"1.168081860","rc":[{"batl":[[0,1000,0.02]],"ltp":1.02,"tv":0.01,"id":7698577,"hc":13.5}]}]}
{"op":"mcm","clk":"997642099","pt":1580582026669,"mc":[{"id":"1.168081860","rc":[{"trd":[[1.02,0.03]],"batb":[[0,1.02,8.9]],"batl":[[0,990,0.01]],"ltp":1.02,"tv":0.03,"id":7698577,"hc":13.5}],"tv":0.04}]}
{"op":"mcm","clk":"997643525","pt":1580582035477,"mc":[{"id":"1.168081860","rc":[{"trd":[[1.02,0.03]],"batb":[[0,1.02,8.9]],"ltp":1.02,"tv":0.03,"id":7698577,"hc":14.5}],"tv":0.06}]}
{"op":"mcm","clk":"997644659","pt":1580582042302,"mc":[{"id":"1.168081860","rc":[{"trd":[[1.02,0.05]],"batb":[[0,1.02,8.89]],"ltp":1.02,"tv":0.04,"id":7698577,"hc":13.5}],"tv":0.07}]}
{"op":"mcm","clk":"997646473","pt":1580582052717,"mc":[{"id":"1.168081860","rc":[{"trd":[[1.02,0.05]],"batb":[[0,1.02,8.89]],"ltp":1.02,"tv":0.04,"id":7698577,"hc":14.5}],"tv":0.09}]}
{"op":"mcm","clk":"997647408","pt":1580582058547,"mc":[{"id":"1.168081860","rc":[{"trd":[[1.02,0.06]],"batb":[[0,1.02,8.88]],"ltp":1.02,"tv":0.06,"id":7698577,"hc":13.5}],"tv":0.1}]}
{"op":"mcm","clk":"997649297","pt":1580582069495,"mc":[{"id":"1.168081860","rc":[{"trd":[[1.02,0.06]],"batb":[[0,1.02,8.88]],"ltp":1.02,"tv":0.06,"id":7698577,"hc":14.5}],"tv":0.12}]}
{"op":"mcm","clk":"997650339","pt":1580582075700,"mc":[{"id":"1.168081860","rc":[{"trd":[[1.02,0.08]],"batb":[[0,1.02,8.87]],"ltp":1.02,"tv":0.07,"id":7698577,"hc":13.5}],"tv":0.13}]}
{"op":"mcm","clk":"997652109","pt":1580582086535,"mc":[{"id":"1.168081860","rc":[{"trd":[[1.02,0.08]],"batb":[[0,1.02,8.87]],"ltp":1.02,"tv":0.07,"id":7698577,"hc":14.5}],"tv":0.15}]}
{"op":"mcm","clk":"997653080","pt":1580582092482,"mc":[{"id":"1.168081860","rc":[{"trd":[[1.02,0.09]],"batb":[[0,1.02,8.86]],"ltp":1.02,"tv":0.09,"id":7698577,"hc":13.5}],"tv":0.17}]}
{"op":"mcm","clk":"997654763","pt":1580582103595,"mc":[{"id":"1.168081860","rc":[{"trd":[[1.02,0.09]],"batb":[[0,1.02,8.86]],"ltp":1.02,"tv":0.09,"id":7698577,"hc":14.5}],"tv":0.18}]}
{"op":"mcm","clk":"997655739","pt":1580582109670,"mc":[{"id":"1.168081860","rc":[{"trd":[[1.02,0.11]],"batb":[[0,1.02,8.85]],"ltp":1.02,"tv":0.1,"id":7698577,"hc":13.5}],"tv":0.2}]}
{"op":"mcm","clk":"997657459","pt":1580582120582,"mc":[{"id":"1.168081860","rc":[{"trd":[[1.02,0.11]],"batb":[[0,1.02,8.85]],"ltp":1.02,"tv":0.1,"id":7698577,"hc":14.5}],"tv":0.21}]}
{"op":"mcm","clk":"997658245","pt":1580582125600,"mc":[{"id":"1.168081860","rc":[{"trd":[[1.02,0.12]],"batb":[[0,1.02,8.84]],"ltp":1.02,"tv":0.12,"id":7698577,"hc":13.5}],"tv":0.23}]}
{"op":"mcm","clk":"997660194","pt":1580582137742,"mc":[{"id":"1.168081860","rc":[{"trd":[[1.02,0.12]],"batb":[[0,1.02,8.84]],"ltp":1.02,"tv":0.12,"id":7698577,"hc":14.5}],"tv":0.24}]}
{"op":"mcm","clk":"997660849","pt":1580582141758,"mc":[{"id":"1.168081860","rc":[{"trd":[[1.02,0.14]],"batb":[[0,1.02,8.83]],"ltp":1.02,"tv":0.13,"id":7698577,"hc":13.5}],"tv":0.26}]}
{"op":"mcm","clk":"997662834","pt":1580582153582,"mc":[{"id":"1.168081860","rc":[{"batl":[[0,1000,0.02]],"ltp":1.02,"tv":0.12,"id":7698577,"hc":14.5}]}]}
{"op":"mcm","clk":"997662890","pt":1580582154013,"mc":[{"id":"1.168081860","rc":[{"trd":[[1.02,0.14]],"batb":[[0,1.02,8.83]],"batl":[[0,990,0.01]],"ltp":1.02,"tv":0.13,"id":7698577,"hc":14.5}],"tv":0.27}]}
{"op":"mcm","clk":"997663526","pt":1580582157610,"mc":[{"id":"1.168081860","rc":[{"batl":[[0,1000,0.02]],"ltp":1.02,"tv":0.13,"id":7698577,"hc":13.5}]}]}
{"op":"mcm","clk":"997663698","pt":1580582158570,"mc":[{"id":"1.168081860","rc":[{"trd":[[1.02,0.16]],"batb":[[0,1.02,8.82]],"batl":[[0,990,0.01]],"ltp":1.02,"tv":0.15,"id":7698577,"hc":13.5}],"tv":0.29}]}
{"op":"mcm","clk":"997665489","pt":1580582169509,"mc":[{"id":"1.168081860","rc":[{"batl":[[0,1000,2.37]],"ltp":1.02,"tv":0.13,"id":7698577,"hc":14.5}]}]}
{"op":"mcm","clk":"997665626","pt":1580582170361,"mc":[{"id":"1.168081860","rc":[{"trd":[[1.02,0.16]],"batb":[[0,1.02,8.82]],"batl":[[0,990,0.01]],"ltp":1.02,"tv":0.15,"id":7698577,"hc":14.5}],"tv":0.31}]}
{"op":"mcm","clk":"997666172","pt":1580582173620,"mc":[{"id":"1.168081860","rc":[{"batl":[[0,1000,2.37]],"ltp":1.02,"tv":0.15,"id":7698577,"hc":13.5}]}]}
{"op":"mcm","clk":"997666351","pt":1580582174693,"mc":[{"id":"1.168081860","rc":[{"trd":[[1.02,0.17]],"batb":[[0,1.02,8.81]],"batl":[[0,990,0.01]],"ltp":1.02,"tv":0.17,"id":7698577,"hc":13.5}],"tv":0.32}]}
{"op":"mcm","clk":"997668453","pt":1580582186427,"mc":[{"id":"1.168081860","rc":[{"trd":[[1.02,0.17]],"batb":[[0,1.02,8.81]],"ltp":1.02,"tv":0.17,"id":7698577,"hc":14.5}],"tv":0.34}]}
{"op":"mcm","clk":"997669161","pt":1580582190405,"mc":[{"id":"1.168081860","rc":[{"trd":[[1.02,0.19]],"batb":[[0,1.02,8.8]],"ltp":1.02,"tv":0.18,"id":7698577,"hc":13.5}],"tv":0.35}]}
{"op":"mcm","clk":"997671499","pt":1580582202752,"mc":[{"id":"1.168081860","rc":[{"trd":[[1.02,0.19]],"batb":[[0,1.02,8.8]],"ltp":1.02,"tv":0.18,"id":7698577,"hc":14.5}],"tv":0.37}]}
{"op":"mcm","clk":"997672230","pt":1580582206737,"mc":[{"id":"1.168081860","rc":[{"trd":[[1.02,0.2]],"batb":[[0,1.02,8.79]],"ltp":1.02,"tv":0.2,"id":7698577,"hc":13.5}],"tv":0.38}]}
{"op":"mcm","clk":"997674478","pt":1580582218491,"mc":[{"id":"1.168081860","rc":[{"batl":[[0,1000,2.37]],"ltp":1.02,"tv":0.18,"id":7698577,"hc":14.5}]}]}
{"op":"mcm","clk":"997674643","pt":1580582219408,"mc":[{"id":"1.168081860","rc":[{"trd":[[1.02,0.2]],"batb":[[0,1.02,8.79]],"batl":[[0,990,0.01]],"ltp":1.02,"tv":0.2,"id":7698577,"hc":14.5}],"tv":0.4}]}
{"op":"mcm","clk":"997675247","pt":1580582222616,"mc":[{"id":"1.168081860","rc":[{"batl":[[0,1000,2.37]],"ltp":1.02,"tv":0.2,"id":7698577,"hc":13.5}]}]}
{"op":"mcm","clk":"997675383","pt":1580582223282,"mc":[{"id":"1.168081860","rc":[{"trd":[[1.02,0.22]],"batb":[[0,1.02,8.78]],"batl":[[0,990,0.01]],"ltp":1.02,"tv":0.21,"id":7698577,"hc":13.5}],"tv":0.41}]}
{"op":"mcm","clk":"997677753","pt":1580582235498,"mc":[{"id":"1.168081860","rc":[{"trd":[[1.02,0.22]],"batb":[[0,1.02,8.78]],"ltp":1.02,"tv":0.21,"id":7698577,"hc":14.5}],"tv":0.43}]}
{"op":"mcm","clk":"997678455","pt":1580582239608,"mc":[{"id":"1.168081860","rc":[{"batl":[[0,1000,0.02]],"ltp":1.02,"tv":0.21,"id":7698577,"hc":13.5}]}]}
{"op":"mcm","clk":"997678533","pt":1580582240023,"mc":[{"id":"1.168081860","rc":[{"trd":[[1.02,0.23]],"batb":[[0,1.02,8.77]],"batl":[[0,990,0.01]],"ltp":1.02,"tv":0.23,"id":7698577,"hc":13.5}],"tv":0.44}]}
{"op":"mcm","clk":"997680613","pt":1580582251684,"mc":[{"id":"1.168081860","rc":[{"batl":[[0,1000,0.02]],"ltp":1.02,"tv":0.21,"id":7698577,"hc":14.5}]}]}
{"op":"mcm","clk":"997680661","pt":1580582251958,"mc":[{"id":"1.168081860","rc":[{"trd":[[1.02,0.23]],"batb":[[0,1.02,8.77]],"batl":[[0,990,0.01]],"ltp":1.02,"tv":0.23,"id":7698577,"hc":14.5}],"tv":0.46}]}
{"op":"mcm","clk":"997681431","pt":1580582256521,"mc":[{"id":"1.168081860","rc":[{"trd":[[1.02,0.25]],"batb":[[0,1.02,8.76]],"ltp":1.02,"tv":0.24,"id":7698577,"hc":13.5}],"tv":0.48}]}
{"op":"mcm","clk":"997683558","pt":1580582268638,"mc":[{"id":"1.168081860","rc":[{"trd":[[1.02,0.25]],"batb":[[0,1.02,8.76]],"ltp":1.02,"tv":0.24,"id":7698577,"hc":14.5}],"tv":0.49}]}
{"op":"mcm","clk":"997684431","pt":1580582273456,"mc":[{"id":"1.168081860","rc":[{"trd":[[1.02,0.26]],"batb":[[0,1.02,8.75]],"ltp":1.02,"tv":0.26,"id":7698577,"hc":13.5}],"tv":0.51}]}
{"op":"mcm","clk":"997686569","pt":1580582285582,"mc":[{"id":"1.168081860","rc":[{"trd":[[1.02,0.26]],"batb":[[0,1.02,8.75]],"ltp":1.02,"tv":0.26,"id":7698577,"hc":14.5}],"tv":0.52}]}
{"op":"mcm","clk":"997687252","pt":1580582289601,"mc":[{"id":"1.168081860","rc":[{"batl":[[0,1000,2.37]],"ltp":1.02,"tv":0.26,"id":7698577,"hc":13.5}]}]}
{"op":"mcm","clk":"997687375","pt":1580582290306,"mc":[{"id":"1.168081860","rc":[{"trd":[[1.02,0.28]],"batb":[[0,1.02,8.74]],"batl":[[0,990,0.01]],"ltp":1.02,"tv":0.27,"id":7698577,"hc":13.5}],"tv":0.54}]}
{"op":"mcm","clk":"997689530","pt":1580582302312,"mc":[{"id":"1.168081860","rc":[{"trd":[[1.02,0.28]],"batb":[[0,1.02,8.74]],"ltp":1.02,"tv":0.27,"id":7698577,"hc":14.5}],"tv":0.55}]}
{"op":"mcm","clk":"997690321","pt":1580582306429,"mc":[{"id":"1.168081860","rc":[{"batl":[[0,1000,2.37]],"ltp":1.02,"tv":0.27,"id":7698577,"hc":13.5}]}]}
{"op":"mcm","clk":"997690467","pt":1580582307244,"mc":[{"id":"1.168081860","rc":[{"trd":[[1.02,0.29]],"batb":[[0,1.02,8.73]],"batl":[[0,990,0.01]],"ltp":1.02,"tv":0.29,"id":7698577,"hc":13.5}],"tv":0.57}]}
{"op":"mcm","clk":"997692361","pt":1580582318656,"mc":[{"id":"1.168081860","rc":[{"batl":[[0,1000,2.37]],"ltp":1.02,"tv":0.27,"id":7698577,"hc":14.5}]}]}
{"op":"mcm","clk":"997692455","pt":1580582319254,"mc":[{"id":"1.168081860","rc":[{"trd":[[1.02,0.29]],"batb":[[0,1.02,8.73]],"batl":[[0,990,0.01]],"ltp":1.02,"tv":0.29,"id":7698577,"hc":14.5}],"tv":0.58}]}
{"op":"mcm","clk":"997693408","pt":1580582324517,"mc":[{"id":"1.168081860","rc":[{"trd":[[1.02,0.31]],"batb":[[0,1.02,8.72]],"ltp":1.02,"tv":0.31,"id":7698577,"hc":13.5}],"tv":0.6}]}
{"op":"mcm","clk":"997695501","pt":1580582336397,"mc":[{"id":"1.168081860","rc":[{"trd":[[1.02,0.31]],"batb":[[0,1.02,8.72]],"ltp":1.02,"tv":0.31,"id":7698577,"hc":14.5}],"tv":0.62}]}
{"op":"mcm","clk":"997696286","pt":1580582340493,"mc":[{"id":"1.168081860","rc":[{"batl":[[0,1000,0.02]],"ltp":1.02,"tv":0.31,"id":7698577,"hc":13.5}]}]}
{"op":"mcm","clk":"997696387","pt":1580582341136,"mc":[{"id":"1.168081860","rc":[{"trd":[[1.02,0.33]],"batb":[[0,1.02,8.71]],"batl":[[0,990,0.01]],"ltp":1.02,"tv":0.32,"id":7698577,"hc":13.5}],"tv":0.63}]}
{"op":"mcm","clk":"997698798","pt":1580582353589,"mc":[{"id":"1.168081860","rc":[{"trd":[[1.02,0.33]],"batb":[[0,1.02,8.71]],"ltp":1.02,"tv":0.32,"id":7698577,"hc":14.5}],"tv":0.65}]}
{"op":"mcm","clk":"997699592","pt":1580582357689,"mc":[{"id":"1.168081860","rc":[{"trd":[[1.02,0.34]],"batb":[[0,1.02,8.7]],"ltp":1.02,"tv":0.34,"id":7698577,"hc":13.5}],"tv":0.66}]}
{"op":"mcm","clk":"997701927","pt":1580582370622,"mc":[{"id":"1.168081860","rc":[{"trd":[[1.02,0.34]],"batb":[[0,1.02,8.7]],"ltp":1.02,"tv":0.34,"id":7698577,"hc":14.5}],"tv":0.68}]}
{"op":"mcm","clk":"997702550","pt":1580582373625,"mc":[{"id":"1.168081860","rc":[{"trd":[[1.02,0.36]],"batb":[[0,1.02,8.69]],"ltp":1.02,"tv":0.35,"id":7698577,"hc":13.5}],"tv":0.69}]}
{"op":"mcm","clk":"997704759","pt":1580582387735,"mc":[{"id":"1.168081860","rc":[{"trd":[[1.02,0.36]],"batb":[[0,1.02,8.69]],"ltp":1.02,"tv":0.35,"id":7698577,"hc":14.5}],"tv":0.71}]}
{"op":"mcm","clk":"997705029","pt":1580582389609,"mc":[{"id":"1.168081860","rc":[{"trd":[[1.02,0.37]],"batb":[[0,1.02,8.68]],"ltp":1.02,"tv":0.37,"id":7698577,"hc":13.5}],"tv":0.72}]}
{"op":"mcm","clk":"997707441","pt":1580582403474,"mc":[{"id":"1.168081860","rc":[{"batl":[[0,1000,2.37]],"ltp":1.02,"tv":0.35,"id":7698577,"hc":14.5}]}]}
{"op":"mcm","clk":"997707557","pt":1580582404072,"mc":[{"id":"1.168081860","rc":[{"trd":[[1.02,0.37]],"batb":[[0,1.02,8.68]],"batl":[[0,990,0.01]],"ltp":1.02,"tv":0.37,"id":7698577,"hc":14.5}],"tv":0.74}]}
{"op":"mcm","clk":"997707841","pt":1580582405551,"mc":[{"id":"1.168081860","rc":[{"trd":[[1.02,0.39]],"batb":[[0,1.02,8.67]],"ltp":1.02,"tv":0.38,"id":7698577,"hc":13.5}],"tv":0.75}]}
{"op":"mcm","clk":"997710291","pt":1580582419587,"mc":[{"id":"1.168081860","rc":[{"batl":[[0,1000,2.37]],"ltp":1.02,"tv":0.37,"id":7698577,"hc":14.5}]}]}
{"op":"mcm","clk":"997710403","pt":1580582420187,"mc":[{"id":"1.168081860","rc":[{"trd":[[1.02,0.39]],"batb":[[0,1.02,8.67]],"batl":[[0,990,0.01]],"ltp":1.02,"tv":0.38,"id":7698577,"hc":14.5}],"tv":0.77}]}
{"op":"mcm","clk":"997710644","pt":1580582421469,"mc":[{"id":"1.168081860","rc":[{"trd":[[1.02,0.4]],"batb":[[0,1.02,8.66]],"ltp":1.02,"tv":0.4,"id":7698577,"hc":13.5}],"tv":0.79}]}
{"op":"mcm","clk":"997713190","pt":1580582436363,"mc":[{"id":"1.168081860","rc":[{"trd":[[1.02,0.4]],"batb":[[0,1.02,8.66]],"ltp":1.02,"tv":0.4,"id":7698577,"hc":14.5}],"tv":0.8}]}
{"op":"mcm","clk":"997713424","pt":1580582437754,"mc":[{"id":"1.168081860","rc":[{"trd":[[1.02,0.42]],"batb":[[0,1.02,8.65]],"ltp":1.02,"tv":0.41,"id":7698577,"hc":13.5}],"tv":0.82}]}
{"op":"mcm","clk":"997715830","pt":1580582452535,"mc":[{"id":"1.168081860","rc":[{"batl":[[0,1000,0.02]],"ltp":1.02,"tv":0.4,"id":7698577,"hc":14.5}]}]}
{"op":"mcm","clk":"997715992","pt":1580582453586,"mc":[{"id":"1.168081860","rc":[{"batl":[[0,1000,2.37]],"ltp":1.02,"tv":0.41,"id":7698577,"hc":13.5},{"trd":[[1.02,0.42]],"batb":[[0,1.02,8.65]],"batl":[[0,990,0.01]],"ltp":1.02,"tv":0.41,"id":7698577,"hc":14.5}],"tv":0.83}]}
{"op":"mcm","clk":"997716077","pt":1580582454070,"mc":[{"id":"1.168081860","rc":[{"trd":[[1.02,0.43]],"batb":[[0,1.02,8.64]],"batl":[[0,990,0.01]],"ltp":1.02,"tv":0.43,"id":7698577,"hc":13.5}],"tv":0.85}]}
{"op":"mcm","clk":"997718464","pt":1580582468692,"mc":[{"id":"1.168081860","rc":[{"batl":[[0,1000,2.37]],"ltp":1.02,"tv":0.41,"id":7698577,"hc":14.5}]}]}
{"op":"mcm","clk":"997718570","pt":1580582469282,"mc":[{"id":"1.168081860","rc":[{"trd":[[1.02,0.43]],"batb":[[0,1.02,8.64]],"batl":[[0,990,0.01]],"ltp":1.02,"tv":0.43,"id":7698577,"hc":14.5}],"tv":0.86}]}
{"op":"mcm","clk":"997718809","pt":1580582470727,"mc":[{"id":"1.168081860","rc":[{"trd":[[1.02,0.45]],"batb":[[0,1.02,8.63]],"ltp":1.02,"tv":0.44,"id":7698577,"hc":13.5}],"tv":0.88}]}
{"op":"mcm","clk":"997721282","pt":1580582485613,"mc":[{"id":"1.168081860","rc":[{"batl":[[0,1000,0.02]],"ltp":1.02,"tv":0.43,"id":7698577,"hc":14.5}]}]}
{"op":"mcm","clk":"997721415","pt":1580582486425,"mc":[{"id":"1.168081860","rc":[{"batl":[[0,1000,2.37]],"ltp":1.02,"tv":0.44,"id":7698577,"hc":13.5},{"trd":[[1.02,0.45]],"batb":[[0,1.02,8.63]],"batl":[[0,990,0.01]],"ltp":1.02,"tv":0.44,"id":7698577,"hc":14.5}],"tv":0.89}]}
{"op":"mcm","clk":"997721544","pt":1580582487106,"mc":[{"id":"1.168081860","rc":[{"trd":[[1.02,0.47]],"batb":[[0,1.02,8.62]],"batl":[[0,990,0.01]],"ltp":1.02,"tv":0.46,"id":7698577,"hc":13.5}],"tv":0.91}]}
{"op":"mcm","clk":"997724163","pt":1580582502481,"mc":[{"id":"1.168081860","rc":[{"trd":[[1.02,0.47]],"batb":[[0,1.02,8.62]],"ltp":1.02,"tv":0.46,"id":7698577,"hc":14.5}],"tv":0.93}]}
{"op":"mcm","clk":"997724388","pt":1580582503562,"mc":[{"id":"1.168081860","rc":[{"trd":[[1.02,0.48]],"batb":[[0,1.02,8.61]],"ltp":1.02,"tv":0.48,"id":7698577,"hc":13.5}],"tv":0.94}]}
{"op":"mcm","clk":"997726959","pt":1580582519587,"mc":[{"id":"1.168081860","rc":[{"batl":[[0,1000,2.37]],"ltp":1.02,"tv":0.48,"id":7698577,"hc":13.5},{"trd":[[1.02,0.48]],"batb":[[0,1.02,8.61]],"ltp":1.02,"tv":0.48,"id":7698577,"hc":14.5}],"tv":0.96}]}
{"op":"mcm","clk":"997727061","pt":1580582520190,"mc":[{"id":"1.168081860","rc":[{"trd":[[1.02,0.5]],"batb":[[0,1.02,8.6]],"batl":[[0,990,0.01]],"ltp":1.02,"tv":0.49,"id":7698577,"hc":13.5}],"tv":0.97}]}
{"op":"mcm","clk":"997729804","pt":1580582535319,"mc":[{"id":"1.168081860","rc":[{"trd":[[1.02,0.5]],"batb":[[0,1.02,8.6]],"ltp":1.02,"tv":0.49,"id":7698577,"hc":14.5}],"tv":0.99}]}
{"op":"mcm","clk":"997730027","pt":1580582536636,"mc":[{"id":"1.168081860","rc":[{"batl":[[0,1000,0.02]],"ltp":1.02,"tv":0.49,"id":7698577,"hc":13.5}]}]}
{"op":"mcm","clk":"997730098","pt":1580582537003,"mc":[{"id":"1.168081860","rc":[{"trd":[[1.02,0.51]],"batb":[[0,1.02,8.59]],"batl":[[0,990,0.01]],"ltp":1.02,"tv":0.51,"id":7698577,"hc":13.5}],"tv":1.0}]}
{"op":"mcm","clk":"997732626","pt":1580582551617,"mc":[{"id":"1.168081860","rc":[{"batl":[[0,1000,2.37]],"ltp":1.02,"tv":0.49,"id":7698577,"hc":14.5}]}]}
{"op":"mcm","clk":"997732762","pt":1580582552421,"mc":[{"id":"1.168081860","rc":[{"trd":[[1.02,0.51]],"batb":[[0,1.02,8.59]],"batl":[[0,990,0.01]],"ltp":1.02,"tv":0.51,"id":7698577,"hc":14.5}],"tv":1.02}]}
{"op":"mcm","clk":"997732947","pt":1580582553447,"mc":[{"id":"1.168081860","rc":[{"trd":[[1.02,0.53]],"batb":[[0,1.02,8.58]],"ltp":1.02,"tv":0.52,"id":7698577,"hc":13.5}],"tv":1.03}]}
{"op":"mcm","clk":"997735632","pt":1580582568676,"mc":[{"id":"1.168081860","rc":[{"batl":[[0,1000,0.02]],"ltp":1.02,"tv":0.51,"id":7698577,"hc":14.5}]}]}
{"op":"mcm","clk":"997735699","pt":1580582569089,"mc":[{"id":"1.168081860","rc":[{"trd":[[1.02,0.53]],"batb":[[0,1.02,8.58]],"batl":[[0,990,0.01]],"ltp":1.02,"tv":0.52,"id":7698577,"hc":14.5}],"tv":1.05}]}
{"op":"mcm","clk":"997736021","pt":1580582570466,"mc":[{"id":"1.168081860","rc":[{"trd":[[1.02,0.54]],"batb":[[0,1.02,8.57]],"ltp":1.02,"tv":0.54,"id":7698577,"hc":13.5}],"tv":1.07}]}
{"op":"mcm","clk":"997739045","pt":1580582585624,"mc":[{"id":"1.168081860","rc":[{"batl":[[0,1000,0.02]],"ltp":1.02,"tv":0.52,"id":7698577,"hc":14.5}]}]}
{"op":"mcm","clk":"997739127","pt":1580582586084,"mc":[{"id":"1.168081860","rc":[{"trd":[[1.02,0.54]],"batb":[[0,1.02,8.57]],"batl":[[0,990,0.01]],"ltp":1.02,"tv":0.54,"id":7698577,"hc":14.5}],"tv":1.08}]}
{"op":"mcm","clk":"997739403","pt":1580582587703,"mc":[{"id":"1.168081860","rc":[{"trd":[[1.02,0.56]],"batb":[[0,1.02,8.56]],"ltp":1.02,"tv":0.55,"id":7698577,"hc":13.5}],"tv":1.1}]}
{"op":"mcm","clk":"997741986","pt":1580582602446,"mc":[{"id":"1.168081860","rc":[{"batl":[[0,1000,0.02]],"ltp":1.02,"tv":0.54,"id":7698577,"hc":14.5}]}]}
{"op":"mcm","clk":"997742064","pt":1580582602821,"mc":[{"id":"1.168081860","rc":[{"trd":[[1.02,0.56]],"batb":[[0,1.02,8.56]],"batl":[[0,990,0.01]],"ltp":1.02,"tv":0.55,"id":7698577,"hc":14.5}],"tv":1.11}]}
{"op":"mcm","clk":"997742389","pt":1580582604604,"mc":[{"id":"1.168081860","rc":[{"trd":[[1.02,0.57]],"batb":[[0,1.02,8.55]],"ltp":1.02,"tv":0.57,"id":7698577,"hc":13.5}],"tv":1.13}]}
{"op":"mcm","clk":"997745014","pt":1580582619542,"mc":[{"id":"1.168081860","rc":[{"batl":[[0,1000,0.02]],"ltp":1.02,"tv":0.55,"id":7698577,"hc":14.5}]}]}
{"op":"mcm","clk":"997745091","pt":1580582619939,"mc":[{"id":"1.168081860","rc":[{"trd":[[1.02,0.57]],"batb":[[0,1.02,8.55]],"batl":[[0,990,0.01]],"ltp":1.02,"tv":0.57,"id":7698577,"hc":14.5}],"tv":1.14}]}
{"op":"mcm","clk":"997745352","pt":1580582621450,"mc":[{"id":"1.168081860","rc":[{"batl":[[0,1000,0.02]],"ltp":1.02,"tv":0.57,"id":7698577,"hc":13.5}]}]}
{"op":"mcm","clk":"997745418","pt":1580582621851,"mc":[{"id":"1.168081860","rc":[{"trd":[[1.02,0.59]],"batb":[[0,1.02,8.54]],"batl":[[0,990,0.01]],"ltp":1.02,"tv":0.58,"id":7698577,"hc":13.5}],"tv":1.16}]}
{"op":"mcm","clk":"997748193","pt":1580582636638,"mc":[{"id":"1.168081860","rc":[{"batl":[[0,1000,2.37]],"ltp":1.02,"tv":0.57,"id":7698577,"hc":14.5}]}]}
{"op":"mcm","clk":"997748330","pt":1580582637453,"mc":[{"id":"1.168081860","rc":[{"trd":[[1.02,0.59]],"batb":[[0,1.02,8.54]],"batl":[[0,990,0.01]],"ltp":1.02,"tv":0.58,"id":7698577,"hc":14.5}],"tv":1.17}]}
{"op":"mcm","clk":"997748570","pt":1580582638739,"mc":[{"id":"1.168081860","rc":[{"trd":[[1.02,0.6]],"batb":[[0,1.02,8.53]],"ltp":1.02,"tv":0.6,"id":7698577,"hc":13.5}],"tv":1.19}]}
{"op":"mcm","clk":"997751334","pt":1580582654518,"mc":[{"id":"1.168081860","rc":[{"trd":[[1.02,0.6]],"batb":[[0,1.02,8.53]],"ltp":1.02,"tv":0.6,"id":7698577,"hc":14.5}],"tv":1.2}]}
{"op":"mcm","clk":"997751491","pt":1580582655510,"mc":[{"id":"1.168081860","rc":[{"batl":[[0,1000,0.02]],"ltp":1.02,"tv":0.6,"id":7698577,"hc":13.5}]}]}
{"op":"mcm","clk":"997751560","pt":1580582655892,"mc":[{"id":"1.168081860","rc":[{"trd":[[1.02,0.62]],"batb":[[0,1.02,8.52]],"batl":[[0,990,0.01]],"ltp":1.02,"tv":0.62,"id":7698577,"hc":13.5}],"tv":1.22}]}
{"op":"mcm","clk":"997754213","pt":1580582671510,"mc":[{"id":"1.168081860","rc":[{"batl":[[0,1000,2.37]],"ltp":1.02,"tv":0.6,"id":7698577,"hc":14.5}]}]}
{"op":"mcm","clk":"997754401","pt":1580582672638,"mc":[{"id":"1.168081860","rc":[{"batl":[[0,1000,2.37]],"ltp":1.02,"tv":0.62,"id":7698577,"hc":13.5},{"trd":[[1.02,0.62]],"batb":[[0,1.02,8.52]],"batl":[[0,990,0.01]],"ltp":1.02,"tv":0.62,"id":7698577,"hc":14.5}],"tv":1.24}]}
{"op":"mcm","clk":"997754522","pt":1580582673338,"mc":[{"id":"1.168081860","rc":[{"trd":[[1.02,0.64]],"batb":[[0,1.02,8.51]],"batl":[[0,990,0.01]],"ltp":1.02,"tv":0.63,"id":7698577,"hc":13.5}],"tv":1.25}]}
{"op":"mcm","clk":"997756794","pt":1580582687455,"mc":[{"id":"1.168081860","rc":[{"batl":[[0,1000,2.37]],"ltp":1.02,"tv":0.62,"id":7698577,"hc":14.5}]}]}
{"op":"mcm","clk":"997756902","pt":1580582688140,"mc":[{"id":"1.168081860","rc":[{"trd":[[1.02,0.64]],"batb":[[0,1.02,8.51]],"batl":[[0,990,0.01]],"ltp":1.02,"tv":0.63,"id":7698577,"hc":14.5}],"tv":1.27}]}
{"op":"mcm","clk":"997757263","pt":1580582690661,"mc":[{"id":"1.168081860","rc":[{"trd":[[1.02,0.65]],"batb":[[0,1.02,8.5]],"ltp":1.02,"tv":0.65,"id":7698577,"hc":13.5}],"tv":1.28}]}
{"op":"mcm","clk":"997759624","pt":1580582705570,"mc":[{"id":"1.168081860","rc":[{"trd":[[1.02,0.65]],"batb":[[0,1.02,8.5]],"ltp":1.02,"tv":0.65,"id":7698577,"hc":14.5}],"tv":1.3}]}
{"op":"mcm","clk":"997759761","pt":1580582706599,"mc":[{"id":"1.168081860","rc":[{"batl":[[0,1000,0.02]],"ltp":1.02,"tv":0.65,"id":7698577,"hc":13.5}]}]}
{"op":"mcm","clk":"997759968","pt":1580582707620,"mc":[{"id":"1.168081860","rc":[{"trd":[[1.02,0.67]],"batb":[[0,1.02,8.49]],"batl":[[0,990,0.01]],"ltp":1.02,"tv":0.66,"id":7698577,"hc":13.5}],"tv":1.31}]}
{"op":"mcm","clk":"997762331","pt":1580582721489,"mc":[{"id":"1.168081860","rc":[{"batl":[[0,1000,0.02]],"ltp":1.02,"tv":0.65,"id":7698577,"hc":14.5}]}]}
{"op":"mcm","clk":"997762512","pt":1580582722685,"mc":[{"id":"1.168081860","rc":[{"trd":[[1.02,0.68]],"batb":[[0,1.02,8.48]],"ltp":1.02,"tv":0.68,"id":7698577,"hc":13.5},{"trd":[[1.02,0.67]],"batb":[[0,1.02,8.49]],"batl":[[0,990,0.01]],"ltp":1.02,"tv":0.66,"id":7698577,"hc":14.5}],"tv":1.34}]}
{"op":"mcm","clk":"997764784","pt":1580582737577,"mc":[{"id":"1.168081860","rc":[{"batl":[[0,1000,2.37]],"ltp":1.02,"tv":0.66,"id":7698577,"hc":14.5}]}]}
{"op":"mcm","clk":"997764937","pt":1580582738697,"mc":[{"id":"1.168081860","rc":[{"batl":[[0,1000,0.02]],"ltp":1.02,"tv":0.68,"id":7698577,"hc":13.5},{"trd":[[1.02,0.68]],"batb":[[0,1.02,8.48]],"batl":[[0,990,0.01]],"ltp":1.02,"tv":0.68,"id":7698577,"hc":14.5}],"tv":1.36}]}
{"op":"mcm","clk":"997764981","pt":1580582738970,"mc":[{"id":"1.168081860","rc":[{"trd":[[1.02,0.7]],"batb":[[0,1.02,8.47]],"batl":[[0,990,0.01]],"ltp":1.02,"tv":0.69,"id":7698577,"hc":13.5}],"tv":1.38}]}
{"op":"mcm","clk":"997767448","pt":1580582755405,"mc":[{"id":"1.168081860","rc":[{"trd":[[1.02,0.71]],"batb":[[0,1.02,8.46]],"ltp":1.02,"tv":0.71,"id":7698577,"hc":13.5},{"trd":[[1.02,0.7]],"batb":[[0,1.02,8.47]],"ltp":1.02,"tv":0.69,"id":7698577,"hc":14.5}],"tv":1.41}]}
{"op":"mcm","clk":"997769946","pt":1580582770536,"mc":[{"id":"1.168081860","rc":[{"batl":[[0,1000,2.37]],"ltp":1.02,"tv":0.69,"id":7698577,"hc":14.5}]}]}
{"op":"mcm","clk":"997770072","pt":1580582771433,"mc":[{"id":"1.168081860","rc":[{"batl":[[0,1000,0.02]],"ltp":1.02,"tv":0.71,"id":7698577,"hc":13.5},{"trd":[[1.02,0.71]],"batb":[[0,1.02,8.46]],"batl":[[0,990,0.01]],"ltp":1.02,"tv":0.71,"id":7698577,"hc":14.5}],"tv":1.42}]}
{"op":"mcm","clk":"997770133","pt":1580582771843,"mc":[{"id":"1.168081860","rc":[{"trd":[[1.02,0.73]],"batb":[[0,1.02,8.45]],"batl":[[0,990,0.01]],"ltp":1.02,"tv":0.72,"id":7698577,"hc":13.5}],"tv":1.44}]}
{"op":"mcm","clk":"997772553","pt":1580582787535,"mc":[{"id":"1.168081860","rc":[{"batl":[[0,1000,2.37]],"ltp":1.02,"tv":0.72,"id":7698577,"hc":13.5},{"trd":[[1.02,0.73]],"batb":[[0,1.02,8.45]],"ltp":1.02,"tv":0.72,"id":7698577,"hc":14.5}],"tv":1.45}]}
{"op":"mcm","clk":"997772647","pt":1580582788163,"mc":[{"id":"1.168081860","rc":[{"trd":[[1.02,0.74]],"batb":[[0,1.02,8.44]],"batl":[[0,990,0.01]],"ltp":1.02,"tv":0.74,"id":7698577,"hc":13.5}],"tv":1.47}]}
{"op":"mcm","clk":"997775123","pt":1580582803700,"mc":[{"id":"1.168081860","rc":[{"batl":[[0,1000,2.37]],"ltp":1.02,"tv":0.74,"id":7698577,"hc":13.5},{"batl":[[0,1000,2.37]],"ltp":1.02,"tv":0.72,"id":7698577,"hc":14.5}]}]}
{"op":"mcm","clk":"997775258","pt":1580582804501,"mc":[{"id":"1.168081860","rc":[{"trd":[[1.02,0.76]],"batb":[[0,1.02,8.43]],"batl":[[0,990,0.01]],"ltp":1.02,"tv":0.75,"id":7698577,"hc":13.5},{"trd":[[1.02,0.74]],"batb":[[0,1.02,8.44]],"batl":[[0,990,0.01]],"ltp":1.02,"tv":0.74,"id":7698577,"hc":14.5}],"tv":1.5}]}
{"op":"mcm","clk":"997778042","pt":1580582820656,"mc":[{"id":"1.168081860","rc":[{"batl":[[0,1000,0.02]],"ltp":1.02,"tv":0.75,"id":7698577,"hc":13.5}]}]}
{"op":"mcm","clk":"997778090","pt":1580582820931,"mc":[{"id":"1.168081860","rc":[{"trd":[[1.02,0.78]],"batb":[[0,1.02,8.42]],"batl":[[0,990,0.01]],"ltp":1.02,"tv":0.77,"id":7698577,"hc":13.5},{"trd":[[1.02,0.76]],"batb":[[0,1.02,8.43]],"ltp":1.02,"tv":0.75,"id":7698577,"hc":14.5}],"tv":1.53}]}
{"op":"mcm","clk":"997780760","pt":1580582837685,"mc":[{"id":"1.168081860","rc":[{"trd":[[1.02,0.78]],"batb":[[0,1.02,8.42]],"ltp":1.02,"tv":0.77,"id":7698577,"hc":14.5}],"tv":1.55}]}
{"op":"mcm","clk":"997780775","pt":1580582837743,"mc":[{"id":"1.168081860","rc":[{"trd":[[1.02,0.79]],"batb":[[0,1.02,8.41]],"ltp":1.02,"tv":0.79,"id":7698577,"hc":13.5}],"tv":1.56}]}
{"op":"mcm","clk":"997783423","pt":1580582854606,"mc":[{"id":"1.168081860","rc":[{"trd":[[1.02,0.81]],"batb":[[0,1.02,8.4]],"ltp":1.02,"tv":0.8,"id":7698577,"hc":13.5},{"trd":[[1.02,0.79]],"batb":[[0,1.02,8.41]],"ltp":1.02,"tv":0.79,"id":7698577,"hc":14.5}],"tv":1.59}]}
{"op":"mcm","clk":"997785792","pt":1580582870561,"mc":[{"id":"1.168081860","rc":[{"batl":[[0,1000,2.37]],"ltp":1.02,"tv":0.8,"id":7698577,"hc":13.5}]}]}
{"op":"mcm","clk":"997785985","pt":1580582871693,"mc":[{"id":"1.168081860","rc":[{"trd":[[1.02,0.82]],"batb":[[0,1.02,8.39]],"batl":[[0,990,0.01]],"ltp":1.02,"tv":0.82,"id":7698577,"hc":13.5},{"trd":[[1.02,0.81]],"batb":[[0,1.02,8.4]],"ltp":1.02,"tv":0.8,"id":7698577,"hc":14.5}],"tv":1.62}]}
{"op":"mcm","clk":"997788342","pt":1580582887625,"mc":[{"id":"1.168081860","rc":[{"batl":[[0,1000,0.02]],"ltp":1.02,"tv":0.82,"id":7698577,"hc":13.5}]}]}
{"op":"mcm","clk":"997788510","pt":1580582888604,"mc":[{"id":"1.168081860","rc":[{"trd":[[1.02,0.84]],"batb":[[0,1.02,8.38]],"batl":[[0,990,0.01]],"ltp":1.02,"tv":0.83,"id":7698577,"hc":13.5}],"tv":1.64}]}
{"op":"mcm","clk":"997788525","pt":1580582888706,"mc":[{"id":"1.168081860","rc":[{"trd":[[1.02,0.82]],"batb":[[0,1.02,8.39]],"ltp":1.02,"tv":0.82,"id":7698577,"hc":14.5}],"tv":1.65}]}
{"op":"mcm","clk":"997790908","pt":1580582904441,"mc":[{"id":"1.168081860","rc":[{"batl":[[0,1000,0.02]],"ltp":1.02,"tv":0.83,"id":7698577,"hc":13.5}]}]}
{"op":"mcm","clk":"997791093","pt":1580582905576,"mc":[{"id":"1.168081860","rc":[{"trd":[[1.02,0.85]],"batb":[[0,1.02,8.37]],"batl":[[0,990,0.01]],"ltp":1.02,"tv":0.85,"id":7698577,"hc":13.5},{"trd":[[1.02,0.84]],"batb":[[0,1.02,8.38]],"ltp":1.02,"tv":0.83,"id":7698577,"hc":14.5}],"tv":1.69}]}
{"op":"mcm","clk":"997793352","pt":1580582921545,"mc":[{"id":"1.168081860","rc":[{"batl":[[0,1000,0.02]],"ltp":1.02,"tv":0.85,"id":7698577,"hc":13.5}]}]}
{"op":"mcm","clk":"997793531","pt":1580582922664,"mc":[{"id":"1.168081860","rc":[{"trd":[[1.02,0.87]],"batb":[[0,1.02,8.36]],"batl":[[0,990,0.01]],"ltp":1.02,"tv":0.86,"id":7698577,"hc":13.5}],"tv":1.7}]}
{"op":"mcm","clk":"997793548","pt":1580582922758,"mc":[{"id":"1.168081860","rc":[{"trd":[[1.02,0.85]],"batb":[[0,1.02,8.37]],"ltp":1.02,"tv":0.85,"id":7698577,"hc":14.5}],"tv":1.72}]}
{"op":"mcm","clk":"997795987","pt":1580582938695,"mc":[{"id":"1.168081860","rc":[{"batl":[[0,1000,0.02]],"ltp":1.02,"tv":0.86,"id":7698577,"hc":13.5},{"batl":[[0,1000,2.37]],"ltp":1.02,"tv":0.85,"id":7698577,"hc":14.5}]}]}
{"op":"mcm","clk":"997796116","pt":1580582939388,"mc":[{"id":"1.168081860","rc":[{"trd":[[1.02,0.88]],"batb":[[0,1.02,8.35]],"batl":[[0,990,0.01]],"ltp":1.02,"tv":0.88,"id":7698577,"hc":13.5},{"trd":[[1.02,0.87]],"batb":[[0,1.02,8.36]],"batl":[[0,990,0.01]],"ltp":1.02,"tv":0.86,"id":7698577,"hc":14.5}],"tv":1.75}]}
{"op":"mcm","clk":"997798292","pt":1580582955495,"mc":[{"id":"1.168081860","rc":[{"trd":[[1.02,0.88]],"batb":[[0,1.02,8.35]],"ltp":1.02,"tv":0.88,"id":7698577,"hc":14.5}],"tv":1.76}]}
{"op":"mcm","clk":"997798404","pt":1580582956506,"mc":[{"id":"1.168081860","rc":[{"trd":[[1.02,0.9]],"batb":[[0,1.02,8.34]],"ltp":1.02,"tv":0.89,"id":7698577,"hc":13.5}],"tv":1.78}]}
{"op":"mcm","clk":"997800320","pt":1580582972637,"mc":[{"id":"1.168081860","rc":[{"batl":[[0,1000,0.02]],"ltp":1.02,"tv":0.88,"id":7698577,"hc":14.5}]}]}
{"op":"mcm","clk":"997800470","pt":1580582973689,"mc":[{"id":"1.168081860","rc":[{"trd":[[1.02,0.91]],"batb":[[0,1.02,8.33]],"ltp":1.02,"tv":0.91,"id":7698577,"hc":13.5},{"trd":[[1.02,0.9]],"batb":[[0,1.02,8.34]],"batl":[[0,990,0.01]],"ltp":1.02,"tv":0.89,"id":7698577,"hc":14.5}],"tv":1.81}]}
{"op":"mcm","clk":"997802246","pt":1580582988530,"mc":[{"id":"1.168081860","rc":[{"batl":[[0,1000,0.02]],"ltp":1.02,"tv":0.89,"id":7698577,"hc":14.5}]}]}
{"op":"mcm","clk":"997802299","pt":1580582989010,"mc":[{"id":"1.168081860","rc":[{"trd":[[1.02,0.91]],"batb":[[0,1.02,8.33]],"batl":[[0,990,0.01]],"ltp":1.02,"tv":0.91,"id":7698577,"hc":14.5}],"tv":1.82}]}
{"op":"mcm","clk":"997802547","pt":1580582990556,"mc":[{"id":"1.168081860","rc":[{"batl":[[0,1000,2.37]],"ltp":1.02,"tv":0.91,"id":7698577,"hc":13.5}]}]}
{"op":"mcm","clk":"997802616","pt":1580582991255,"mc":[{"id":"1.168081860","rc":[{"trd":[[1.02,0.93]],"batb":[[0,1.02,8.32]],"batl":[[0,990,0.01]],"ltp":1.02,"tv":0.93,"id":7698577,"hc":13.5}],"tv":1.84}]}
{"op":"mcm","clk":"997804340","pt":1580583004575,"mc":[{"id":"1.168081860","rc":[{"batl":[[0,1000,0.02]],"ltp":1.02,"tv":0.91,"id":7698577,"hc":14.5}]}]}
{"op":"mcm","clk":"997804422","pt":1580583005162,"mc":[{"id":"1.168081860","rc":[{"trd":[[1.02,0.93]],"batb":[[0,1.02,8.32]],"batl":[[0,990,0.01]],"ltp":1.02,"tv":0.93,"id":7698577,"hc":14.5}],"tv":1.86}]}
{"op":"mcm","clk":"997804627","pt":1580583006693,"mc":[{"id":"1.168081860","rc":[{"batl":[[0,1000,0.02]],"ltp":1.02,"tv":0.93,"id":7698577,"hc":13.5}]}]}
{"op":"mcm","clk":"997804697","pt":1580583007076,"mc":[{"id":"1.168081860","rc":[{"trd":[[1.02,0.95]],"batb":[[0,1.02,8.31]],"batl":[[0,990,0.01]],"ltp":1.02,"tv":0.94,"id":7698577,"hc":13.5}],"tv":1.87}]}
{"op":"mcm","clk":"997806746","pt":1580583022703,"mc":[{"id":"1.168081860","rc":[{"trd":[[1.02,0.95]],"batb":[[0,1.02,8.31]],"ltp":1.02,"tv":0.94,"id":7698577,"hc":14.5}],"tv":1.89}]}
{"op":"mcm","clk":"997807009","pt":1580583024601,"mc":[{"id":"1.168081860","rc":[{"trd":[[1.02,0.96]],"batb":[[0,1.02,8.3]],"ltp":1.02,"tv":0.96,"id":7698577,"hc":13.5}],"tv":1.9}]}
{"op":"mcm","clk":"997808886","pt":1580583038703,"mc":[{"id":"1.168081860","rc":[{"batl":[[0,1000,2.37]],"ltp":1.02,"tv":0.94,"id":7698577,"hc":14.5}]}]}
{"op":"mcm","clk":"997808978","pt":1580583039431,"mc":[{"id":"1.168081860","rc":[{"trd":[[1.02,0.96]],"batb":[[0,1.02,8.3]],"batl":[[0,990,0.01]],"ltp":1.02,"tv":0.96,"id":7698577,"hc":14.5}],"tv":1.92}]}
{"op":"mcm","clk":"997809128","pt":1580583040501,"mc":[{"id":"1.168081860","rc":[{"trd":[[1.02,0.98]],"batb":[[0,1.02,8.29]],"ltp":1.02,"tv":0.97,"id":7698577,"hc":13.5}],"tv":1.93}]}
{"op":"mcm","clk":"997811147","pt":1580583055518,"mc":[{"id":"1.168081860","rc":[{"batl":[[0,1000,0.02]],"ltp":1.02,"tv":0.96,"id":7698577,"hc":14.5}]}]}
{"op":"mcm","clk":"997811267","pt":1580583056513,"mc":[{"id":"1.168081860","rc":[{"trd":[[1.02,0.99]],"batb":[[0,1.02,8.28]],"ltp":1.02,"tv":0.99,"id":7698577,"hc":13.5},{"trd":[[1.02,0.98]],"batb":[[0,1.02,8.29]],"batl":[[0,990,0.01]],"ltp":1.02,"tv":0.97,"id":7698577,"hc":14.5}],"tv":1.96}]}
{"op":"mcm","clk":"997813181","pt":1580583071641,"mc":[{"id":"1.168081860","rc":[{"batl":[[0,1000,0.02]],"ltp":1.02,"tv":0.97,"id":7698577,"hc":14.5}]}]}
{"op":"mcm","clk":"997813223","pt":1580583072017,"mc":[{"id":"1.168081860","rc":[{"trd":[[1.02,0.99]],"batb":[[0,1.02,8.28]],"batl":[[0,990,0.01]],"ltp":1.02,"tv":0.99,"id":7698577,"hc":14.5}],"tv":1.98}]}
{"op":"mcm","clk":"997813399","pt":1580583073545,"mc":[{"id":"1.168081860","rc":[{"batl":[[0,1000,0.02]],"ltp":1.02,"tv":0.99,"id":7698577,"hc":13.5}]}]}
{"op":"mcm","clk":"997813524","pt":1580583074452,"mc":[{"id":"1.168081860","rc":[{"trd":[[1.02,1.01]],"batb":[[0,1.02,8.27]],"batl":[[0,990,0.01]],"ltp":1.02,"tv":1.0,"id":7698577,"hc":13.5}],"tv":2.0}]}
{"op":"mcm","clk":"997815214","pt":1580583087616,"mc":[{"id":"1.168081860","rc":[{"batl":[[0,1000,2.37]],"ltp":1.02,"tv":0.99,"id":7698577,"hc":14.5}]}]}
{"op":"mcm","clk":"997815281","pt":1580583088201,"mc":[{"id":"1.168081860","rc":[{"trd":[[1.02,1.01]],"batb":[[0,1.02,8.27]],"batl":[[0,990,0.01]],"ltp":1.02,"tv":1.0,"id":7698577,"hc":14.5}],"tv":2.01}]}
{"op":"mcm","clk":"997815451","pt":1580583089695,"mc":[{"id":"1.168081860","rc":[{"batl":[[0,1000,0.02]],"ltp":1.02,"tv":1.0,"id":7698577,"hc":13.5}]}]}
{"op":"mcm","clk":"997815515","pt":1580583090182,"mc":[{"id":"1.168081860","rc":[{"trd":[[1.02,1.02]],"batb":[[0,1.02,8.26]],"batl":[[0,990,0.01]],"ltp":1.02,"tv":1.02,"id":7698577,"hc":13.5}],"tv":2.03}]}
{"op":"mcm","clk":"997817287","pt":1580583104608,"mc":[{"id":"1.168081860","rc":[{"trd":[[1.02,1.02]],"batb":[[0,1.02,8.26]],"ltp":1.02,"tv":1.02,"id":7698577,"hc":14.5}],"tv":2.04}]}
{"op":"mcm","clk":"997817544","pt":1580583106422,"mc":[{"id":"1.168081860","rc":[{"trd":[[1.02,1.04]],"batb":[[0,1.02,8.25]],"ltp":1.02,"tv":1.03,"id":7698577,"hc":13.5}],"tv":2.06}]}
{"op":"mcm","clk":"997819286","pt":1580583120410,"mc":[{"id":"1.168081860","rc":[{"batl":[[0,1000,2.37]],"ltp":1.02,"tv":1.02,"id":7698577,"hc":14.5}]}]}
{"op":"mcm","clk":"997819394","pt":1580583121195,"mc":[{"id":"1.168081860","rc":[{"trd":[[1.02,1.04]],"batb":[[0,1.02,8.25]],"batl":[[0,990,0.01]],"ltp":1.02,"tv":1.03,"id":7698577,"hc":14.5}],"tv":2.07}]}
{"op":"mcm","clk":"997819588","pt":1580583122679,"mc":[{"id":"1.168081860","rc":[{"trd":[[1.02,1.05]],"batb":[[0,1.02,8.24]],"ltp":1.02,"tv":1.05,"id":7698577,"hc":13.5}],"tv":2.09}]}
{"op":"mcm","clk":"997821456","pt":1580583137620,"mc":[{"id":"1.168081860","rc":[{"trd":[[1.02,1.05]],"batb":[[0,1.02,8.24]],"ltp":1.02,"tv":1.05,"id":7698577,"hc":14.5}],"tv":2.1}]}
{"op":"mcm","clk":"997821709","pt":1580583139503,"mc":[{"id":"1.168081860","rc":[{"trd":[[1.02,1.07]],"batb":[[0,1.02,8.23]],"ltp":1.02,"tv":1.07,"id":7698577,"hc":13.5}],"tv":2.12}]}
{"op":"mcm","clk":"997823472","pt":1580583154595,"mc":[{"id":"1.168081860","rc":[{"trd":[[1.02,1.07]],"batb":[[0,1.02,8.23]],"ltp":1.02,"tv":1.07,"id":7698577,"hc":14.5}],"tv":2.14}]}
{"op":"mcm","clk":"997823711","pt":1580583156362,"mc":[{"id":"1.168081860","rc":[{"trd":[[1.02,1.09]],"batb":[[0,1.02,8.22]],"ltp":1.02,"tv":1.08,"id":7698577,"hc":13.5}],"tv":2.15}]}
{"op":"mcm","clk":"997825484","pt":1580583171302,"mc":[{"id":"1.168081860","rc":[{"trd":[[1.02,1.09]],"batb":[[0,1.02,8.22]],"ltp":1.02,"tv":1.08,"id":7698577,"hc":14.5}],"tv":2.17}]}
{"op":"mcm","clk":"997825651","pt":1580583172586,"mc":[{"id":"1.168081860","rc":[{"batl":[[0,1000,0.02]],"ltp":1.02,"tv":1.08,"id":7698577,"hc":13.5}]}]}
{"op":"mcm","clk":"997825709","pt":1580583173004,"mc":[{"id":"1.168081860","rc":[{"trd":[[1.02,1.1]],"batb":[[0,1.02,8.21]],"batl":[[0,990,0.01]],"ltp":1.02,"tv":1.1,"id":7698577,"hc":13.5}],"tv":2.18}]}
{"op":"mcm","clk":"997827426","pt":1580583187626,"mc":[{"id":"1.168081860","rc":[{"batl":[[0,1000,0.02]],"ltp":1.02,"tv":1.08,"id":7698577,"hc":14.5}]}]}
{"op":"mcm","clk":"997827468","pt":1580583188013,"mc":[{"id":"1.168081860","rc":[{"trd":[[1.02,1.1]],"batb":[[0,1.02,8.21]],"batl":[[0,990,0.01]],"ltp":1.02,"tv":1.1,"id":7698577,"hc":14.5}],"tv":2.2}]}
{"op":"mcm","clk":"997827657","pt":1580583189625,"mc":[{"id":"1.168081860","rc":[{"trd":[[1.02,1.12]],"batb":[[0,1.02,8.2]],"ltp":1.02,"tv":1.11,"id":7698577,"hc":13.5}],"tv":2.21}]}
{"op":"mcm","clk":"997829367","pt":1580583204658,"mc":[{"id":"1.168081860","rc":[{"trd":[[1.02,1.12]],"batb":[[0,1.02,8.2]],"ltp":1.02,"tv":1.11,"id":7698577,"hc":14.5}],"tv":2.23}]}
{"op":"mcm","clk":"997829601","pt":1580583206455,"mc":[{"id":"1.168081860","rc":[{"trd":[[1.02,1.13]],"batb":[[0,1.02,8.19]],"ltp":1.02,"tv":1.13,"id":7698577,"hc":13.5}],"tv":2.24}]}
{"op":"mcm","clk":"997831325","pt":1580583221553,"mc":[{"id":"1.168081860","rc":[{"trd":[[1.02,1.13]],"batb":[[0,1.02,8.19]],"ltp":1.02,"tv":1.13,"id":7698577,"hc":14.5}],"tv":2.26}]}
{"op":"mcm","clk":"997831562","pt":1580583223658,"mc":[{"id":"1.168081860","rc":[{"trd":[[1.02,1.15]],"batb":[[0,1.02,8.18]],"ltp":1.02,"tv":1.14,"id":7698577,"hc":13.5}],"tv":2.27}]}
{"op":"mcm","clk":"997833279","pt":1580583238371,"mc":[{"id":"1.168081860","rc":[{"trd":[[1.02,1.15]],"batb":[[0,1.02,8.18]],"ltp":1.02,"tv":1.14,"id":7698577,"hc":14.5}],"tv":2.29}]}
{"op":"mcm","clk":"997833566","pt":1580583240607,"mc":[{"id":"1.168081860","rc":[{"trd":[[1.02,1.16]],"batb":[[0,1.02,8.17]],"ltp":1.02,"tv":1.16,"id":7698577,"hc":13.5}],"tv":2.31}]}
{"op":"mcm","clk":"997835595","pt":1580583255420,"mc":[{"id":"1.168081860","rc":[{"trd":[[1.02,1.16]],"batb":[[0,1.02,8.17]],"ltp":1.02,"tv":1.16,"id":7698577,"hc":14.5}],"tv":2.32}]}
{"op":"mcm","clk":"997835888","pt":1580583257643,"mc":[{"id":"1.168081860","rc":[{"trd":[[1.02,1.18]],"batb":[[0,1.02,8.16]],"ltp":1.02,"tv":1.17,"id":7698577,"hc":13.5}],"tv":2.34}]}
{"op":"mcm","clk":"997837689","pt":1580583271677,"mc":[{"id":"1.168081860","rc":[{"batl":[[0,1000,2.37]],"ltp":1.02,"tv":1.16,"id":7698577,"hc":14.5}]}]}
{"op":"mcm","clk":"997837790","pt":1580583272480,"mc":[{"id":"1.168081860","rc":[{"trd":[[1.02,1.18]],"batb":[[0,1.02,8.16]],"batl":[[0,990,0.01]],"ltp":1.02,"tv":1.17,"id":7698577,"hc":14.5}],"tv":2.35}]}
{"op":"mcm","clk":"997838066","pt":1580583274769,"mc":[{"id":"1.168081860","rc":[{"trd":[[1.02,1.19]],"batb":[[0,1.02,8.15]],"ltp":1.02,"tv":1.19,"id":7698577,"hc":13.5}],"tv":2.37}]}
{"op":"mcm","clk":"997839972","pt":1580583289625,"mc":[{"id":"1.168081860","rc":[{"trd":[[1.02,1.19]],"batb":[[0,1.02,8.15]],"ltp":1.02,"tv":1.19,"id":7698577,"hc":14.5}],"tv":2.38}]}
{"op":"mcm","clk":"997840251","pt":1580583291646,"mc":[{"id":"1.168081860","rc":[{"batl":[[0,1000,0.02]],"ltp":1.02,"tv":1.19,"id":7698577,"hc":13.5}]}]}
{"op":"mcm","clk":"997840303","pt":1580583292004,"mc":[{"id":"1.168081860","rc":[{"trd":[[1.02,1.21]],"batb":[[0,1.02,8.14]],"batl":[[0,990,0.01]],"ltp":1.02,"tv":1.2,"id":7698577,"hc":13.5}],"tv":2.4}]}
{"op":"mcm","clk":"997842242","pt":1580583306424,"mc":[{"id":"1.168081860","rc":[{"trd":[[1.02,1.21]],"batb":[[0,1.02,8.14]],"ltp":1.02,"tv":1.2,"id":7698577,"hc":14.5}],"tv":2.41}]}
{"op":"mcm","clk":"997842639","pt":1580583309542,"mc":[{"id":"1.168081860","rc":[{"trd":[[1.02,1.23]],"batb":[[0,1.02,8.13]],"ltp":1.02,"tv":1.22,"id":7698577,"hc":13.5}],"tv":2.43}]}
{"op":"mcm","clk":"997844237","pt":1580583323570,"mc":[{"id":"1.168081860","rc":[{"batl":[[0,1000,0.02]],"ltp":1.02,"tv":1.2,"id":7698577,"hc":14.5}]}]}
{"op":"mcm","clk":"997844354","pt":1580583324549,"mc":[{"id":"1.168081860","rc":[{"trd":[[1.02,1.23]],"batb":[[0,1.02,8.13]],"batl":[[0,990,0.01]],"ltp":1.02,"tv":1.22,"id":7698577,"hc":14.5}],"tv":2.45}]}
{"op":"mcm","clk":"997844613","pt":1580583326645,"mc":[{"id":"1.168081860","rc":[{"trd":[[1.02,1.24]],"batb":[[0,1.02,8.12]],"ltp":1.02,"tv":1.24,"id":7698577,"hc":13.5}],"tv":2.46}]}
{"op":"mcm","clk":"997846358","pt":1580583341678,"mc":[{"id":"1.168081860","rc":[{"batl":[[0,1000,0.02]],"ltp":1.02,"tv":1.22,"id":7698577,"hc":14.5}]}]}
{"op":"mcm","clk":"997846428","pt":1580583342257,"mc":[{"id":"1.168081860","rc":[{"trd":[[1.02,1.24]],"batb":[[0,1.02,8.12]],"batl":[[0,990,0.01]],"ltp":1.02,"tv":1.24,"id":7698577,"hc":14.5}],"tv":2.48}]}
{"op":"mcm","clk":"997846593","pt":1580583343698,"mc":[{"id":"1.168081860","rc":[{"batl":[[0,1000,2.37]],"ltp":1.02,"tv":1.24,"id":7698577,"hc":13.5}]}]}
{"op":"mcm","clk":"997846687","pt":1580583344413,"mc":[{"id":"1.168081860","rc":[{"trd":[[1.02,1.26]],"batb":[[0,1.02,8.11]],"batl":[[0,990,0.01]],"ltp":1.02,"tv":1.25,"id":7698577,"hc":13.5}],"tv":2.49}]}
{"op":"mcm","clk":"997848596","pt":1580583359627,"mc":[{"id":"1.168081860","rc":[{"trd":[[1.02,1.26]],"batb":[[0,1.02,8.11]],"ltp":1.02,"tv":1.25,"id":7698577,"hc":14.5}],"tv":2.51}]}
{"op":"mcm","clk":"997848716","pt":1580583360610,"mc":[{"id":"1.168081860","rc":[{"trd":[[1.02,1.27]],"batb":[[0,1.02,8.1]],"ltp":1.02,"tv":1.27,"id":7698577,"hc":13.5}],"tv":2.52}]}
{"op":"mcm","clk":"997850735","pt":1580583376694,"mc":[{"id":"1.168081860","rc":[{"batl":[[0,1000,0.02]],"ltp":1.02,"tv":1.25,"id":7698577,"hc":14.5}]}]}
{"op":"mcm","clk":"997850866","pt":1580583377578,"mc":[{"id":"1.168081860","rc":[{"batl":[[0,1000,0.02]],"ltp":1.02,"tv":1.27,"id":7698577,"hc":13.5},{"trd":[[1.02,1.27]],"batb":[[0,1.02,8.1]],"batl":[[0,990,0.01]],"ltp":1.02,"tv":1.27,"id":7698577,"hc":14.5}],"tv":2.54}]}
{"op":"mcm","clk":"997850921","pt":1580583377950,"mc":[{"id":"1.168081860","rc":[{"trd":[[1.02,1.29]],"batb":[[0,1.02,8.09]],"batl":[[0,990,0.01]],"ltp":1.02,"tv":1.28,"id":7698577,"hc":13.5}],"tv":2.55}]}
{"op":"mcm","clk":"997852887","pt":1580583394596,"mc":[{"id":"1.168081860","rc":[{"trd":[[1.02,1.29]],"batb":[[0,1.02,8.09]],"ltp":1.02,"tv":1.28,"id":7698577,"hc":14.5}],"tv":2.57}]}
{"op":"mcm","clk":"997852990","pt":1580583395380,"mc":[{"id":"1.168081860","rc":[{"trd":[[1.02,1.3]],"batb":[[0,1.02,8.08]],"ltp":1.02,"tv":1.3,"id":7698577,"hc":13.5}],"tv":2.58}]}
{"op":"mcm","clk":"997854907","pt":1580583411542,"mc":[{"id":"1.168081860","rc":[{"batl":[[0,1000,2.37]],"ltp":1.02,"tv":1.28,"id":7698577,"hc":14.5}]}]}
{"op":"mcm","clk":"997855023","pt":1580583412438,"mc":[{"id":"1.168081860","rc":[{"batl":[[0,1000,2.37]],"ltp":1.02,"tv":1.3,"id":7698577,"hc":13.5},{"trd":[[1.02,1.3]],"batb":[[0,1.02,8.08]],"batl":[[0,990,0.01]],"ltp":1.02,"tv":1.3,"id":7698577,"hc":14.5}],"tv":2.6}]}
{"op":"mcm","clk":"997855103","pt":1580583413074,"mc":[{"id":"1.168081860","rc":[{"trd":[[1.02,1.32]],"batb":[[0,1.02,8.07]],"batl":[[0,990,0.01]],"ltp":1.02,"tv":1.31,"id":7698577,"hc":13.5}],"tv":2.62}]}
{"op":"mcm","clk":"997856886","pt":1580583428699,"mc":[{"id":"1.168081860","rc":[{"batl":[[0,1000,0.02]],"ltp":1.02,"tv":1.31,"id":7698577,"hc":13.5}]}]}
{"op":"mcm","clk":"997856995","pt":1580583429551,"mc":[{"id":"1.168081860","rc":[{"trd":[[1.02,1.33]],"batb":[[0,1.02,8.06]],"batl":[[0,990,0.01]],"ltp":1.02,"tv":1.33,"id":7698577,"hc":13.5},{"trd":[[1.02,1.32]],"batb":[[0,1.02,8.07]],"ltp":1.02,"tv":1.31,"id":7698577,"hc":14.5}],"tv":2.65}]}
{"op":"mcm","clk":"997858629","pt":1580583444655,"mc":[{"id":"1.168081860","rc":[{"batl":[[0,1000,2.37]],"ltp":1.02,"tv":1.33,"id":7698577,"hc":13.5}]}]}
{"op":"mcm","clk":"997858763","pt":1580583445677,"mc":[{"id":"1.168081860","rc":[{"trd":[[1.02,1.35]],"batb":[[0,1.02,8.05]],"batl":[[0,990,0.01]],"ltp":1.02,"tv":1.34,"id":7698577,"hc":13.5},{"batl":[[0,1000,0.02]],"ltp":1.02,"tv":1.31,"id":7698577,"hc":14.5}],"tv":2.66}]}
{"op":"mcm","clk":"997858807","pt":1580583446109,"mc":[{"id":"1.168081860","rc":[{"trd":[[1.02,1.33]],"batb":[[0,1.02,8.06]],"batl":[[0,990,0.01]],"ltp":1.02,"tv":1.33,"id":7698577,"hc":14.5}],"tv":2.68}]}
{"op":"mcm","clk":"997860615","pt":1580583461565,"mc":[{"id":"1.168081860","rc":[{"batl":[[0,1000,0.02]],"ltp":1.02,"tv":1.34,"id":7698577,"hc":13.5},{"batl":[[0,1000,2.37]],"ltp":1.02,"tv":1.33,"id":7698577,"hc":14.5}]}]}
{"op":"mcm","clk":"997860705","pt":1580583462199,"mc":[{"id":"1.168081860","rc":[{"trd":[[1.02,1.36]],"batb":[[0,1.02,8.04]],"batl":[[0,990,0.01]],"ltp":1.02,"tv":1.36,"id":7698577,"hc":13.5},{"trd":[[1.02,1.35]],"batb":[[0,1.02,8.05]],"batl":[[0,990,0.01]],"ltp":1.02,"tv":1.34,"id":7698577,"hc":14.5}],"tv":2.71}]}
{"op":"mcm","clk":"997862459","pt":1580583477535,"mc":[{"id":"1.168081860","rc":[{"batl":[[0,1000,2.37]],"ltp":1.02,"tv":1.36,"id":7698577,"hc":13.5}]}]}
{"op":"mcm","clk":"997862533","pt":1580583478173,"mc":[{"id":"1.168081860","rc":[{"trd":[[1.02,1.38]],"batb":[[0,1.02,8.03]],"batl":[[0,990,0.01]],"ltp":1.02,"tv":1.38,"id":7698577,"hc":13.5}],"tv":2.72}]}
{"op":"mcm","clk":"997862745","pt":1580583479456,"mc":[{"id":"1.168081860","rc":[{"batl":[[0,1000,0.02]],"ltp":1.02,"tv":1.34,"id":7698577,"hc":14.5}]}]}
{"op":"mcm","clk":"997862796","pt":1580583479882,"mc":[{"id":"1.168081860","rc":[{"trd":[[1.02,1.36]],"batb":[[0,1.02,8.04]],"batl":[[0,990,0.01]],"ltp":1.02,"tv":1.36,"id":7698577,"hc":14.5}],"tv":2.74}]}
{"op":"mcm","clk":"997864693","pt":1580583495584,"mc":[{"id":"1.168081860","rc":[{"trd":[[1.02,1.4]],"batb":[[0,1.02,8.02]],"ltp":1.02,"tv":1.39,"id":7698577,"hc":13.5},{"batl":[[0,1000,2.37]],"ltp":1.02,"tv":1.36,"id":7698577,"hc":14.5}],"tv":2.76}]}
{"op":"mcm","clk":"997864776","pt":1580583496285,"mc":[{"id":"1.168081860","rc":[{"trd":[[1.02,1.38]],"batb":[[0,1.02,8.03]],"batl":[[0,990,0.01]],"ltp":1.02,"tv":1.38,"id":7698577,"hc":14.5}],"tv":2.77}]}
{"op":"mcm","clk":"997866497","pt":1580583510602,"mc":[{"id":"1.168081860","rc":[{"batl":[[0,1000,0.02]],"ltp":1.02,"tv":1.39,"id":7698577,"hc":13.5}]}]}
{"op":"mcm","clk":"997866549","pt":1580583510977,"mc":[{"id":"1.168081860","rc":[{"trd":[[1.02,1.41]],"batb":[[0,1.02,8.01]],"batl":[[0,990,0.01]],"ltp":1.02,"tv":1.41,"id":7698577,"hc":13.5}],"tv":2.79}]}
{"op":"mcm","clk":"997866790","pt":1580583512410,"mc":[{"id":"1.168081860","rc":[{"trd":[[1.02,1.4]],"batb":[[0,1.02,8.02]],"ltp":1.02,"tv":1.39,"id":7698577,"hc":14.5}],"tv":2.8}]}
{"op":"mcm","clk":"997868543","pt":1580583527537,"mc":[{"id":"1.168081860","rc":[{"trd":[[1.02,1.43]],"batb":[[0,1.02,8]],"ltp":1.02,"tv":1.42,"id":7698577,"hc":13.5}],"tv":2.82}]}
{"op":"mcm","clk":"997868688","pt":1580583528612,"mc":[{"id":"1.168081860","rc":[{"batl":[[0,1000,0.02]],"ltp":1.02,"tv":1.39,"id":7698577,"hc":14.5}]}]}
{"op":"mcm","clk":"997868737","pt":1580583529029,"mc":[{"id":"1.168081860","rc":[{"trd":[[1.02,1.41]],"batb":[[0,1.02,8.01]],"batl":[[0,990,0.01]],"ltp":1.02,"tv":1.41,"id":7698577,"hc":14.5}],"tv":2.83}]}
{"op":"mcm","clk":"997870533","pt":1580583543672,"mc":[{"id":"1.168081860","rc":[{"batl":[[0,1000,0.02]],"ltp":1.02,"tv":1.42,"id":7698577,"hc":13.5}]}]}
{"op":"mcm","clk":"997870683","pt":1580583544683,"mc":[{"id":"1.168081860","rc":[{"trd":[[1.02,1.44]],"batb":[[0,1.02,7.99]],"batl":[[0,990,0.01]],"ltp":1.02,"tv":1.44,"id":7698577,"hc":13.5}],"tv":2.85}]}
{"op":"mcm","clk":"997870821","pt":1580583545696,"mc":[{"id":"1.168081860","rc":[{"batl":[[0,1000,0.02]],"ltp":1.02,"tv":1.41,"id":7698577,"hc":14.5}]}]}
{"op":"mcm","clk":"997870863","pt":1580583546008,"mc":[{"id":"1.168081860","rc":[{"trd":[[1.02,1.43]],"batb":[[0,1.02,8]],"batl":[[0,990,0.01]],"ltp":1.02,"tv":1.42,"id":7698577,"hc":14.5}],"tv":2.86}]}
{"op":"mcm","clk":"997872756","pt":1580583560415,"mc":[{"id":"1.168081860","rc":[{"batl":[[0,1000,0.02]],"ltp":1.02,"tv":1.44,"id":7698577,"hc":13.5}]}]}
{"op":"mcm","clk":"997872907","pt":1580583561630,"mc":[{"id":"1.168081860","rc":[{"trd":[[1.02,1.46]],"batb":[[0,1.02,7.98]],"batl":[[0,990,0.01]],"ltp":1.02,"tv":1.45,"id":7698577,"hc":13.5}],"tv":2.88}]}
{"op":"mcm","clk":"997873075","pt":1580583562728,"mc":[{"id":"1.168081860","rc":[{"trd":[[1.02,1.44]],"batb":[[0,1.02,7.99]],"ltp":1.02,"tv":1.44,"id":7698577,"hc":14.5}],"tv":2.89}]}
{"op":"mcm","clk":"997874926","pt":1580583576664,"mc":[{"id":"1.168081860","rc":[{"batl":[[0,1000,2.37]],"ltp":1.02,"tv":1.45,"id":7698577,"hc":13.5}]}]}
{"op":"mcm","clk":"997875012","pt":1580583577375,"mc":[{"id":"1.168081860","rc":[{"trd":[[1.02,1.47]],"batb":[[0,1.02,7.97]],"batl":[[0,990,0.01]],"ltp":1.02,"tv":1.47,"id":7698577,"hc":13.5}],"tv":2.91}]}
{"op":"mcm","clk":"997875306","pt":1580583579346,"mc":[{"id":"1.168081860","rc":[{"trd":[[1.02,1.46]],"batb":[[0,1.02,7.98]],"ltp":1.02,"tv":1.45,"id":7698577,"hc":14.5}],"tv":2.93}]}
{"op":"mcm","clk":"997877109","pt":1580583593682,"mc":[{"id":"1.168081860","rc":[{"trd":[[1.02,1.49]],"batb":[[0,1.02,7.96]],"ltp":1.02,"tv":1.48,"id":7698577,"hc":13.5}],"tv":2.94}]}
{"op":"mcm","clk":"997877380","pt":1580583595654,"mc":[{"id":"1.168081860","rc":[{"batl":[[0,1000,0.02]],"ltp":1.02,"tv":1.45,"id":7698577,"hc":14.5}]}]}
{"op":"mcm","clk":"997877490","pt":1580583596600,"mc":[{"id":"1.168081860","rc":[{"trd":[[1.02,1.47]],"batb":[[0,1.02,7.97]],"batl":[[0,990,0.01]],"ltp":1.02,"tv":1.47,"id":7698577,"hc":14.5}],"tv":2.96}]}
{"op":"mcm","clk":"997879611","pt":1580583610929,"mc":[{"id":"1.168081860","rc":[{"trd":[[1.02,1.5]],"batb":[[0,1.02,7.95]],"ltp":1.02,"tv":1.5,"id":7698577,"hc":13.5}],"tv":2.97}]}
{"op":"mcm","clk":"997879835","pt":1580583612953,"mc":[{"id":"1.168081860","rc":[{"batl":[[0,1000,0.02]],"ltp":1.02,"tv":1.47,"id":7698577,"hc":14.5}]}]}
{"op":"mcm","clk":"997879889","pt":1580583613849,"mc":[{"id":"1.168081860","rc":[{"trd":[[1.02,1.49]],"batb":[[0,1.02,7.96]],"batl":[[0,990,0.01]],"ltp":1.02,"tv":1.48,"id":7698577,"hc":14.5}],"tv":2.99}]}
{"op":"mcm","clk":"997881800","pt":1580583626602,"mc":[{"id":"1.168081860","rc":[{"batl":[[0,1000,2.37]],"ltp":1.02,"tv":1.5,"id":7698577,"hc":13.5}]}]}
{"op":"mcm","clk":"997881875","pt":1580583627193,"mc":[{"id":"1.168081860","rc":[{"trd":[[1.02,1.52]],"batb":[[0,1.02,7.94]],"batl":[[0,990,0.01]],"ltp":1.02,"tv":1.51,"id":7698577,"hc":13.5}],"tv":3.0}]}
{"op":"mcm","clk":"997882051","pt":1580583628487,"mc":[{"id":"1.168081860","rc":[{"batl":[[0,1000,0.02]],"ltp":1.02,"tv":1.48,"id":7698577,"hc":14.5}]}]}
{"op":"mcm","clk":"997882203","pt":1580583629502,"mc":[{"id":"1.168081860","rc":[{"trd":[[1.02,1.5]],"batb":[[0,1.02,7.95]],"batl":[[0,990,0.01]],"ltp":1.02,"tv":1.5,"id":7698577,"hc":14.5}],"tv":3.02}]}
{"op":"mcm","clk":"997883802","pt":1580583642617,"mc":[{"id":"1.168081860","rc":[{"batl":[[0,1000,2.37]],"ltp":1.02,"tv":1.51,"id":7698577,"hc":13.5}]}]}
{"op":"mcm","clk":"997883884","pt":1580583643363,"mc":[{"id":"1.168081860","rc":[{"trd":[[1.02,1.54]],"batb":[[0,1.02,7.93]],"batl":[[0,990,0.01]],"ltp":1.02,"tv":1.53,"id":7698577,"hc":13.5}],"tv":3.03}]}
{"op":"mcm","clk":"997884155","pt":1580583645457,"mc":[{"id":"1.168081860","rc":[{"trd":[[1.02,1.52]],"batb":[[0,1.02,7.94]],"ltp":1.02,"tv":1.51,"id":7698577,"hc":14.5}],"tv":3.05}]}
{"op":"mcm","clk":"997885860","pt":1580583659865,"mc":[{"id":"1.168081860","rc":[{"trd":[[1.02,1.55]],"batb":[[0,1.02,7.92]],"ltp":1.02,"tv":1.55,"id":7698577,"hc":13.5}],"tv":3.07}]}
{"op":"mcm","clk":"997886107","pt":1580583661562,"mc":[{"id":"1.168081860","rc":[{"trd":[[1.02,1.54]],"batb":[[0,1.02,7.93]],"ltp":1.02,"tv":1.53,"id":7698577,"hc":14.5}],"tv":3.08}]}
{"op":"mcm","clk":"997888169","pt":1580583675610,"mc":[{"id":"1.168081860","rc":[{"trd":[[1.02,1.57]],"batb":[[0,1.02,7.91]],"ltp":1.02,"tv":1.56,"id":7698577,"hc":13.5}],"tv":3.1}]}
{"op":"mcm","clk":"997888733","pt":1580583678509,"mc":[{"id":"1.168081860","rc":[{"trd":[[1.02,1.55]],"batb":[[0,1.02,7.92]],"ltp":1.02,"tv":1.55,"id":7698577,"hc":14.5}],"tv":3.11}]}
{"op":"mcm","clk":"997890777","pt":1580583692443,"mc":[{"id":"1.168081860","rc":[{"trd":[[1.02,1.58]],"batb":[[0,1.02,7.9]],"ltp":1.02,"tv":1.58,"id":7698577,"hc":13.5}],"tv":3.13}]}
{"op":"mcm","clk":"997891146","pt":1580583694476,"mc":[{"id":"1.168081860","rc":[{"trd":[[1.02,1.57]],"batb":[[0,1.02,7.91]],"ltp":1.02,"tv":1.56,"id":7698577,"hc":14.5}],"tv":3.14}]}
{"op":"mcm","clk":"997893360","pt":1580583709525,"mc":[{"id":"1.168081860","rc":[{"trd":[[1.02,1.6]],"batb":[[0,1.02,7.89]],"ltp":1.02,"tv":1.59,"id":7698577,"hc":13.5}],"tv":3.16}]}
{"op":"mcm","clk":"997893499","pt":1580583710492,"mc":[{"id":"1.168081860","rc":[{"batl":[[0,1000,0.02]],"ltp":1.02,"tv":1.56,"id":7698577,"hc":14.5}]}]}
{"op":"mcm","clk":"997893579","pt":1580583711084,"mc":[{"id":"1.168081860","rc":[{"trd":[[1.02,1.58]],"batb":[[0,1.02,7.9]],"batl":[[0,990,0.01]],"ltp":1.02,"tv":1.58,"id":7698577,"hc":14.5}],"tv":3.17}]}
{"op":"mcm","clk":"997895967","pt":1580583726637,"mc":[{"id":"1.168081860","rc":[{"trd":[[1.02,1.61]],"batb":[[0,1.02,7.88]],"ltp":1.02,"tv":1.61,"id":7698577,"hc":13.5},{"batl":[[0,1000,0.02]],"ltp":1.02,"tv":1.58,"id":7698577,"hc":14.5}],"tv":3.19}]}
{"op":"mcm","clk":"997896074","pt":1580583727215,"mc":[{"id":"1.168081860","rc":[{"trd":[[1.02,1.6]],"batb":[[0,1.02,7.89]],"batl":[[0,990,0.01]],"ltp":1.02,"tv":1.59,"id":7698577,"hc":14.5}],"tv":3.21}]}
{"op":"mcm","clk":"997898227","pt":1580583741877,"mc":[{"id":"1.168081860","rc":[{"trd":[[1.02,1.63]],"batb":[[0,1.02,7.87]],"ltp":1.02,"tv":1.62,"id":7698577,"hc":13.5}],"tv":3.22}]}
{"op":"mcm","clk":"997898478","pt":1580583743516,"mc":[{"id":"1.168081860","rc":[{"trd":[[1.02,1.61]],"batb":[[0,1.02,7.88]],"ltp":1.02,"tv":1.61,"id":7698577,"hc":14.5}],"tv":3.24}]}
{"op":"mcm","clk":"997900590","pt":1580583757695,"mc":[{"id":"1.168081860","rc":[{"batl":[[0,1000,2.37]],"ltp":1.02,"tv":1.62,"id":7698577,"hc":13.5}]}]}
{"op":"mcm","clk":"997900668","pt":1580583758228,"mc":[{"id":"1.168081860","rc":[{"trd":[[1.02,1.64]],"batb":[[0,1.02,7.86]],"batl":[[0,990,0.01]],"ltp":1.02,"tv":1.64,"id":7698577,"hc":13.5}],"tv":3.25}]}
{"op":"mcm","clk":"997900920","pt":1580583759637,"mc":[{"id":"1.168081860","rc":[{"batl":[[0,1000,2.37]],"ltp":1.02,"tv":1.61,"id":7698577,"hc":14.5}]}]}
{"op":"mcm","clk":"997901076","pt":1580583760618,"mc":[{"id":"1.168081860","rc":[{"trd":[[1.02,1.63]],"batb":[[0,1.02,7.87]],"batl":[[0,990,0.01]],"ltp":1.02,"tv":1.62,"id":7698577,"hc":14.5}],"tv":3.27}]}
{"op":"mcm","clk":"997902996","pt":1580583774740,"mc":[{"id":"1.168081860","rc":[{"trd":[[1.02,1.66]],"batb":[[0,1.02,7.85]],"ltp":1.02,"tv":1.65,"id":7698577,"hc":13.5}],"tv":3.28}]}
{"op":"mcm","clk":"997903303","pt":1580583776640,"mc":[{"id":"1.168081860","rc":[{"batl":[[0,1000,0.02]],"ltp":1.02,"tv":1.62,"id":7698577,"hc":14.5}]}]}
{"op":"mcm","clk":"997903348","pt":1580583776949,"mc":[{"id":"1.168081860","rc":[{"trd":[[1.02,1.64]],"batb":[[0,1.02,7.86]],"batl":[[0,990,0.01]],"ltp":1.02,"tv":1.64,"id":7698577,"hc":14.5}],"tv":3.3}]}
{"op":"mcm","clk":"997905276","pt":1580583790628,"mc":[{"id":"1.168081860","rc":[{"batl":[[0,1000,2.37]],"ltp":1.02,"tv":1.65,"id":7698577,"hc":13.5}]}]}
{"op":"mcm","clk":"997905360","pt":1580583791112,"mc":[{"id":"1.168081860","rc":[{"trd":[[1.02,1.67]],"batb":[[0,1.02,7.84]],"batl":[[0,990,0.01]],"ltp":1.02,"tv":1.67,"id":7698577,"hc":13.5}],"tv":3.31}]}
{"op":"mcm","clk":"997905671","pt":1580583793330,"mc":[{"id":"1.168081860","rc":[{"trd":[[1.02,1.66]],"batb":[[0,1.02,7.85]],"ltp":1.02,"tv":1.65,"id":7698577,"hc":14.5}],"tv":3.33}]}
{"op":"mcm","clk":"997907885","pt":1580583807675,"mc":[{"id":"1.168081860","rc":[{"trd":[[1.02,1.69]],"batb":[[0,1.02,7.83]],"ltp":1.02,"tv":1.69,"id":7698577,"hc":13.5}],"tv":3.34}]}
{"op":"mcm","clk":"997908313","pt":1580583810316,"mc":[{"id":"1.168081860","rc":[{"trd":[[1.02,1.67]],"batb":[[0,1.02,7.84]],"ltp":1.02,"tv":1.67,"id":7698577,"hc":14.5}],"tv":3.36}]}
{"op":"mcm","clk":"997910166","pt":1580583823642,"mc":[{"id":"1.168081860","rc":[{"batl":[[0,1000,2.37]],"ltp":1.02,"tv":1.69,"id":7698577,"hc":13.5}]}]}
{"op":"mcm","clk":"997910267","pt":1580583824238,"mc":[{"id":"1.168081860","rc":[{"trd":[[1.02,1.71]],"batb":[[0,1.02,7.82]],"batl":[[0,990,0.01]],"ltp":1.02,"tv":1.7,"id":7698577,"hc":13.5}],"tv":3.38}]}
{"op":"mcm","clk":"997910624","pt":1580583826540,"mc":[{"id":"1.168081860","rc":[{"trd":[[1.02,1.69]],"batb":[[0,1.02,7.83]],"ltp":1.02,"tv":1.69,"id":7698577,"hc":14.5}],"tv":3.39}]}
{"op":"mcm","clk":"997912638","pt":1580583840772,"mc":[{"id":"1.168081860","rc":[{"trd":[[1.02,1.72]],"batb":[[0,1.02,7.81]],"ltp":1.02,"tv":1.72,"id":7698577,"hc":13.5}],"tv":3.41}]}
{"op":"mcm","clk":"997912941","pt":1580583842697,"mc":[{"id":"1.168081860","rc":[{"batl":[[0,1000,2.37]],"ltp":1.02,"tv":1.69,"id":7698577,"hc":14.5}]}]}
{"op":"mcm","clk":"997913007","pt":1580583843128,"mc":[{"id":"1.168081860","rc":[{"trd":[[1.02,1.71]],"batb":[[0,1.02,7.82]],"batl":[[0,990,0.01]],"ltp":1.02,"tv":1.7,"id":7698577,"hc":14.5}],"tv":3.42}]}
{"op":"mcm","clk":"997915097","pt":1580583856608,"mc":[{"id":"1.168081860","rc":[{"batl":[[0,1000,2.37]],"ltp":1.02,"tv":1.72,"id":7698577,"hc":13.5}]}]}
{"op":"mcm","clk":"997915178","pt":1580583857243,"mc":[{"id":"1.168081860","rc":[{"trd":[[1.02,1.74]],"batb":[[0,1.02,7.8]],"batl":[[0,990,0.01]],"ltp":1.02,"tv":1.73,"id":7698577,"hc":13.5}],"tv":3.44}]}
{"op":"mcm","clk":"997915539","pt":1580583859435,"mc":[{"id":"1.168081860","rc":[{"trd":[[1.02,1.72]],"batb":[[0,1.02,7.81]],"ltp":1.02,"tv":1.72,"id":7698577,"hc":14.5}],"tv":3.45}]}
{"op":"mcm","clk":"997917758","pt":1580583873646,"mc":[{"id":"1.168081860","rc":[{"batl":[[0,1000,0.02]],"ltp":1.02,"tv":1.73,"id":7698577,"hc":13.5}]}]}
{"op":"mcm","clk":"997917801","pt":1580583873964,"mc":[{"id":"1.168081860","rc":[{"trd":[[1.02,1.75]],"batb":[[0,1.02,7.79]],"batl":[[0,990,0.01]],"ltp":1.02,"tv":1.75,"id":7698577,"hc":13.5}],"tv":3.47}]}
{"op":"mcm","clk":"997918103","pt":1580583875627,"mc":[{"id":"1.168081860","rc":[{"trd":[[1.02,1.74]],"batb":[[0,1.02,7.8]],"ltp":1.02,"tv":1.73,"id":7698577,"hc":14.5}],"tv":3.48}]}
{"op":"mcm","clk":"997920449","pt":1580583890577,"mc":[{"id":"1.168081860","rc":[{"trd":[[1.02,1.77]],"batb":[[0,1.02,7.78]],"ltp":1.02,"tv":1.76,"id":7698577,"hc":13.5}],"tv":3.5}]}
{"op":"mcm","clk":"997920678","pt":1580583891697,"mc":[{"id":"1.168081860","rc":[{"trd":[[1.02,1.75]],"batb":[[0,1.02,7.79]],"ltp":1.02,"tv":1.75,"id":7698577,"hc":14.5}],"tv":3.52}]}
{"op":"mcm","clk":"997923131","pt":1580583906650,"mc":[{"id":"1.168081860","rc":[{"batl":[[0,1000,0.02]],"ltp":1.02,"tv":1.76,"id":7698577,"hc":13.5}]}]}
{"op":"mcm","clk":"997923268","pt":1580583907444,"mc":[{"id":"1.168081860","rc":[{"trd":[[1.02,1.78]],"batb":[[0,1.02,7.77]],"batl":[[0,990,0.01]],"ltp":1.02,"tv":1.78,"id":7698577,"hc":13.5}],"tv":3.53}]}
{"op":"mcm","clk":"997923474","pt":1580583908551,"mc":[{"id":"1.168081860","rc":[{"trd":[[1.02,1.77]],"batb":[[0,1.02,7.78]],"ltp":1.02,"tv":1.76,"id":7698577,"hc":14.5}],"tv":3.55}]}
{"op":"mcm","clk":"997925892","pt":1580583923531,"mc":[{"id":"1.168081860","rc":[{"batl":[[0,1000,0.02]],"ltp":1.02,"tv":1.78,"id":7698577,"hc":13.5}]}]}
{"op":"mcm","clk":"997926085","pt":1580583924643,"mc":[{"id":"1.168081860","rc":[{"trd":[[1.02,1.8]],"batb":[[0,1.02,7.76]],"batl":[[0,990,0.01]],"ltp":1.02,"tv":1.79,"id":7698577,"hc":13.5}],"tv":3.56}]}
{"op":"mcm","clk":"997926212","pt":1580583925367,"mc":[{"id":"1.168081860","rc":[{"trd":[[1.02,1.78]],"batb":[[0,1.02,7.77]],"ltp":1.02,"tv":1.78,"id":7698577,"hc":14.5}],"tv":3.58}]}
{"op":"mcm","clk":"997928517","pt":1580583939600,"mc":[{"id":"1.168081860","rc":[{"batl":[[0,1000,2.37]],"ltp":1.02,"tv":1.79,"id":7698577,"hc":13.5}]}]}
{"op":"mcm","clk":"997928674","pt":1580583940476,"mc":[{"id":"1.168081860","rc":[{"trd":[[1.02,1.81]],"batb":[[0,1.02,7.75]],"batl":[[0,990,0.01]],"ltp":1.02,"tv":1.81,"id":7698577,"hc":13.5}],"tv":3.59}]}
{"op":"mcm","clk":"997928917","pt":1580583941812,"mc":[{"id":"1.168081860","rc":[{"trd":[[1.02,1.8]],"batb":[[0,1.02,7.76]],"ltp":1.02,"tv":1.79,"id":7698577,"hc":14.5}],"tv":3.61}]}
{"op":"mcm","clk":"997931249","pt":1580583956545,"mc":[{"id":"1.168081860","rc":[{"batl":[[0,1000,0.02]],"ltp":1.02,"tv":1.81,"id":7698577,"hc":13.5}]}]}
{"op":"mcm","clk":"997931408","pt":1580583957433,"mc":[{"id":"1.168081860","rc":[{"trd":[[1.02,1.83]],"batb":[[0,1.02,7.74]],"batl":[[0,990,0.01]],"ltp":1.02,"tv":1.82,"id":7698577,"hc":13.5}],"tv":3.62}]}
{"op":"mcm","clk":"997931591","pt":1580583958411,"mc":[{"id":"1.168081860","rc":[{"trd":[[1.02,1.81]],"batb":[[0,1.02,7.75]],"ltp":1.02,"tv":1.81,"id":7698577,"hc":14.5}],"tv":3.64}]}
{"op":"mcm","clk":"997933987","pt":1580583972549,"mc":[{"id":"1.168081860","rc":[{"batl":[[0,1000,2.37]],"ltp":1.02,"tv":1.82,"id":7698577,"hc":13.5}]}]}
{"op":"mcm","clk":"997934195","pt":1580583973645,"mc":[{"id":"1.168081860","rc":[{"trd":[[1.02,1.85]],"batb":[[0,1.02,7.73]],"batl":[[0,990,0.01]],"ltp":1.02,"tv":1.84,"id":7698577,"hc":13.5}],"tv":3.65}]}
{"op":"mcm","clk":"997934363","pt":1580583974522,"mc":[{"id":"1.168081860","rc":[{"batl":[[0,1000,0.02]],"ltp":1.02,"tv":1.81,"id":7698577,"hc":14.5}]}]}
{"op":"mcm","clk":"997934423","pt":1580583974980,"mc":[{"id":"1.168081860","rc":[{"trd":[[1.02,1.83]],"batb":[[0,1.02,7.74]],"batl":[[0,990,0.01]],"ltp":1.02,"tv":1.82,"id":7698577,"hc":14.5}],"tv":3.67}]}
{"op":"mcm","clk":"997936608","pt":1580583988674,"mc":[{"id":"1.168081860","rc":[{"batl":[[0,1000,0.02]],"ltp":1.02,"tv":1.84,"id":7698577,"hc":13.5}]}]}
{"op":"mcm","clk":"997936775","pt":1580583989551,"mc":[{"id":"1.168081860","rc":[{"trd":[[1.02,1.86]],"batb":[[0,1.02,7.72]],"batl":[[0,990,0.01]],"ltp":1.02,"tv":1.86,"id":7698577,"hc":13.5}],"tv":3.69}]}
{"op":"mcm","clk":"997937187","pt":1580583991670,"mc":[{"id":"1.168081860","rc":[{"trd":[[1.02,1.85]],"batb":[[0,1.02,7.73]],"ltp":1.02,"tv":1.84,"id":7698577,"hc":14.5}],"tv":3.7}]}
{"op":"mcm","clk":"997939380","pt":1580584005496,"mc":[{"id":"1.168081860","rc":[{"batl":[[0,1000,0.02]],"ltp":1.02,"tv":1.86,"id":7698577,"hc":13.5}]}]}
{"op":"mcm","clk":"997939485","pt":1580584006162,"mc":[{"id":"1.168081860","rc":[{"trd":[[1.02,1.88]],"batb":[[0,1.02,7.71]],"batl":[[0,990,0.01]],"ltp":1.02,"tv":1.87,"id":7698577,"hc":13.5}],"tv":3.72}]}
{"op":"mcm","clk":"997939889","pt":1580584008681,"mc":[{"id":"1.168081860","rc":[{"trd":[[1.02,1.86]],"batb":[[0,1.02,7.72]],"ltp":1.02,"tv":1.86,"id":7698577,"hc":14.5}],"tv":3.73}]}
{"op":"mcm","clk":"997941885","pt":1580584021604,"mc":[{"id":"1.168081860","rc":[{"batl":[[0,1000,0.02]],"ltp":1.02,"tv":1.87,"id":7698577,"hc":13.5}]}]}
{"op":"mcm","clk":"997941959","pt":1580584021983,"mc":[{"id":"1.168081860","rc":[{"trd":[[1.02,1.89]],"batb":[[0,1.02,7.7]],"batl":[[0,990,0.01]],"ltp":1.02,"tv":1.89,"id":7698577,"hc":13.5}],"tv":3.75}]}
{"op":"mcm","clk":"997942571","pt":1580584025662,"mc":[{"id":"1.168081860","rc":[{"trd":[[1.02,1.88]],"batb":[[0,1.02,7.71]],"ltp":1.02,"tv":1.87,"id":7698577,"hc":14.5}],"tv":3.76}]}
{"op":"mcm","clk":"997944651","pt":1580584038539,"mc":[{"id":"1.168081860","rc":[{"trd":[[1.02,1.91]],"batb":[[0,1.02,7.69]],"ltp":1.02,"tv":1.9,"id":7698577,"hc":13.5}],"tv":3.78}]}
{"op":"mcm","clk":"997945123","pt":1580584041437,"mc":[{"id":"1.168081860","rc":[{"batl":[[0,1000,0.02]],"ltp":1.02,"tv":1.87,"id":7698577,"hc":14.5}]}]}
{"op":"mcm","clk":"997945185","pt":1580584041830,"mc":[{"id":"1.168081860","rc":[{"trd":[[1.02,1.89]],"batb":[[0,1.02,7.7]],"batl":[[0,990,0.01]],"ltp":1.02,"tv":1.89,"id":7698577,"hc":14.5}],"tv":3.79}]}
{"op":"mcm","clk":"997947280","pt":1580584055311,"mc":[{"id":"1.168081860","rc":[{"trd":[[1.02,1.92]],"batb":[[0,1.02,7.68]],"ltp":1.02,"tv":1.92,"id":7698577,"hc":13.5}],"tv":3.81}]}
{"op":"mcm","clk":"997947834","pt":1580584058493,"mc":[{"id":"1.168081860","rc":[{"trd":[[1.02,1.91]],"batb":[[0,1.02,7.69]],"ltp":1.02,"tv":1.9,"id":7698577,"hc":14.5}],"tv":3.83}]}
{"op":"mcm","clk":"997949939","pt":1580584071709,"mc":[{"id":"1.168081860","rc":[{"trd":[[1.02,1.94]],"batb":[[0,1.02,7.67]],"ltp":1.02,"tv":1.93,"id":7698577,"hc":13.5}],"tv":3.84}]}
{"op":"mcm","clk":"997950426","pt":1580584074538,"mc":[{"id":"1.168081860","rc":[{"batl":[[0,1000,0.02]],"ltp":1.02,"tv":1.9,"id":7698577,"hc":14.5}]}]}
{"op":"mcm","clk":"997950483","pt":1580584074921,"mc":[{"id":"1.168081860","rc":[{"trd":[[1.02,1.92]],"batb":[[0,1.02,7.68]],"batl":[[0,990,0.01]],"ltp":1.02,"tv":1.92,"id":7698577,"hc":14.5}],"tv":3.86}]}
{"op":"mcm","clk":"997952520","pt":1580584087672,"mc":[{"id":"1.168081860","rc":[{"batl":[[0,1000,2.37]],"ltp":1.02,"tv":1.93,"id":7698577,"hc":13.5}]}]}
{"op":"mcm","clk":"997952588","pt":1580584088042,"mc":[{"id":"1.168081860","rc":[{"trd":[[1.02,1.95]],"batb":[[0,1.02,7.66]],"batl":[[0,990,0.01]],"ltp":1.02,"tv":1.95,"id":7698577,"hc":13.5}],"tv":3.87}]}
{"op":"mcm","clk":"997953187","pt":1580584091653,"mc":[{"id":"1.168081860","rc":[{"trd":[[1.02,1.94]],"batb":[[0,1.02,7.67]],"ltp":1.02,"tv":1.93,"id":7698577,"hc":14.5}],"tv":3.89}]}
{"op":"mcm","clk":"997955140","pt":1580584104651,"mc":[{"id":"1.168081860","rc":[{"batl":[[0,1000,0.02]],"ltp":1.02,"tv":1.95,"id":7698577,"hc":13.5}]}]}
{"op":"mcm","clk":"997955205","pt":1580584105079,"mc":[{"id":"1.168081860","rc":[{"trd":[[1.02,1.97]],"batb":[[0,1.02,7.65]],"batl":[[0,990,0.01]],"ltp":1.02,"tv":1.96,"id":7698577,"hc":13.5}],"tv":3.9}]}
{"op":"mcm","clk":"997955633","pt":1580584107788,"mc":[{"id":"1.168081860","rc":[{"trd":[[1.02,1.95]],"batb":[[0,1.02,7.66]],"ltp":1.02,"tv":1.95,"id":7698577,"hc":14.5}],"tv":3.92}]}
{"op":"mcm","clk":"997957790","pt":1580584121503,"mc":[{"id":"1.168081860","rc":[{"trd":[[1.02,1.98]],"batb":[[0,1.02,7.64]],"ltp":1.02,"tv":1.98,"id":7698577,"hc":13.5}],"tv":3.93}]}
{"op":"mcm","clk":"997958126","pt":1580584123593,"mc":[{"id":"1.168081860","rc":[{"batl":[[0,1000,2.37]],"ltp":1.02,"tv":1.95,"id":7698577,"hc":14.5}]}]}
{"op":"mcm","clk":"997958241","pt":1580584124291,"mc":[{"id":"1.168081860","rc":[{"trd":[[1.02,1.97]],"batb":[[0,1.02,7.65]],"batl":[[0,990,0.01]],"ltp":1.02,"tv":1.96,"id":7698577,"hc":14.5}],"tv":3.95}]}
{"op":"mcm","clk":"997960345","pt":1580584137502,"mc":[{"id":"1.168081860","rc":[{"batl":[[0,1000,0.02]],"ltp":1.02,"tv":1.98,"id":7698577,"hc":13.5}]}]}
{"op":"mcm","clk":"997960417","pt":1580584137965,"mc":[{"id":"1.168081860","rc":[{"trd":[[1.02,2]],"batb":[[0,1.02,7.63]],"batl":[[0,990,0.01]],"ltp":1.02,"tv":2.0,"id":7698577,"hc":13.5}],"tv":3.96}]}
{"op":"mcm","clk":"997960871","pt":1580584140686,"mc":[{"id":"1.168081860","rc":[{"trd":[[1.02,1.98]],"batb":[[0,1.02,7.64]],"ltp":1.02,"tv":1.98,"id":7698577,"hc":14.5}],"tv":3.98}]}
{"op":"mcm","clk":"997963027","pt":1580584153632,"mc":[{"id":"1.168081860","rc":[{"batl":[[0,1000,2.37]],"ltp":1.02,"tv":2.0,"id":7698577,"hc":13.5}]}]}
{"op":"mcm","clk":"997963167","pt":1580584154430,"mc":[{"id":"1.168081860","rc":[{"trd":[[1.02,2.02]],"batb":[[0,1.02,7.62]],"batl":[[0,990,0.01]],"ltp":1.02,"tv":2.01,"id":7698577,"hc":13.5}],"tv":4.0}]}
{"op":"mcm","clk":"997963536","pt":1580584156556,"mc":[{"id":"1.168081860","rc":[{"batl":[[0,1000,0.02]],"ltp":1.02,"tv":1.98,"id":7698577,"hc":14.5}]}]}
{"op":"mcm","clk":"997963609","pt":1580584156933,"mc":[{"id":"1.168081860","rc":[{"trd":[[1.02,2]],"batb":[[0,1.02,7.63]],"batl":[[0,990,0.01]],"ltp":1.02,"tv":2.0,"id":7698577,"hc":14.5}],"tv":4.01}]}
{"op":"mcm","clk":"997965970","pt":1580584170444,"mc":[{"id":"1.168081860","rc":[{"trd":[[1.02,2.03]],"batb":[[0,1.02,7.61]],"ltp":1.02,"tv":2.03,"id":7698577,"hc":13.5}],"tv":4.03}]}
{"op":"mcm","clk":"997966543","pt":1580584173814,"mc":[{"id":"1.168081860","rc":[{"trd":[[1.02,2.02]],"batb":[[0,1.02,7.62]],"ltp":1.02,"tv":2.01,"id":7698577,"hc":14.5}],"tv":4.04}]}
{"op":"mcm","clk":"997968590","pt":1580584186424,"mc":[{"id":"1.168081860","rc":[{"trd":[[1.02,2.05]],"batb":[[0,1.02,7.6]],"ltp":1.02,"tv":2.04,"id":7698577,"hc":13.5}],"tv":4.06}]}
{"op":"mcm","clk":"997969276","pt":1580584190643,"mc":[{"id":"1.168081860","rc":[{"batl":[[0,1000,0.02]],"ltp":1.02,"tv":2.01,"id":7698577,"hc":14.5}]}]}
{"op":"mcm","clk":"997969323","pt":1580584190928,"mc":[{"id":"1.168081860","rc":[{"trd":[[1.02,2.03]],"batb":[[0,1.02,7.61]],"batl":[[0,990,0.01]],"ltp":1.02,"tv":2.03,"id":7698577,"hc":14.5}],"tv":4.07}]}
{"op":"mcm","clk":"997971261","pt":1580584202680,"mc":[{"id":"1.168081860","rc":[{"batl":[[0,1000,2.37]],"ltp":1.02,"tv":2.04,"id":7698577,"hc":13.5}]}]}
{"op":"mcm","clk":"997971342","pt":1580584203211,"mc":[{"id":"1.168081860","rc":[{"trd":[[1.02,2.06]],"batb":[[0,1.02,7.59]],"batl":[[0,990,0.01]],"ltp":1.02,"tv":2.06,"id":7698577,"hc":13.5}],"tv":4.09}]}
{"op":"mcm","clk":"997971889","pt":1580584206664,"mc":[{"id":"1.168081860","rc":[{"batl":[[0,1000,0.02]],"ltp":1.02,"tv":2.03,"id":7698577,"hc":14.5}]}]}
{"op":"mcm","clk":"997971968","pt":1580584207108,"mc":[{"id":"1.168081860","rc":[{"trd":[[1.02,2.05]],"batb":[[0,1.02,7.6]],"batl":[[0,990,0.01]],"ltp":1.02,"tv":2.04,"id":7698577,"hc":14.5}],"tv":4.1}]}
{"op":"mcm","clk":"997974019","pt":1580584219410,"mc":[{"id":"1.168081860","rc":[{"trd":[[1.02,2.08]],"batb":[[0,1.02,7.58]],"ltp":1.02,"tv":2.07,"id":7698577,"hc":13.5}],"tv":4.12}]}
{"op":"mcm","clk":"997974734","pt":1580584223344,"mc":[{"id":"1.168081860","rc":[{"trd":[[1.02,2.06]],"batb":[[0,1.02,7.59]],"ltp":1.02,"tv":2.06,"id":7698577,"hc":14.5}],"tv":4.14}]}
{"op":"mcm","clk":"997976634","pt":1580584235449,"mc":[{"id":"1.168081860","rc":[{"batl":[[0,1000,0.02]],"ltp":1.02,"tv":2.07,"id":7698577,"hc":13.5}]}]}
{"op":"mcm","clk":"997976713","pt":1580584235982,"mc":[{"id":"1.168081860","rc":[{"trd":[[1.02,2.09]],"batb":[[0,1.02,7.57]],"batl":[[0,990,0.01]],"ltp":1.02,"tv":2.09,"id":7698577,"hc":13.5}],"tv":4.15}]}
{"op":"mcm","clk":"997977423","pt":1580584240445,"mc":[{"id":"1.168081860","rc":[{"trd":[[1.02,2.08]],"batb":[[0,1.02,7.58]],"ltp":1.02,"tv":2.07,"id":7698577,"hc":14.5}],"tv":4.17}]}
{"op":"mcm","clk":"997979317","pt":1580584252694,"mc":[{"id":"1.168081860","rc":[{"trd":[[1.02,2.11]],"batb":[[0,1.02,7.56]],"ltp":1.02,"tv":2.1,"id":7698577,"hc":13.5}],"tv":4.18}]}
{"op":"mcm","clk":"997979969","pt":1580584256611,"mc":[{"id":"1.168081860","rc":[{"trd":[[1.02,2.09]],"batb":[[0,1.02,7.57]],"ltp":1.02,"tv":2.09,"id":7698577,"hc":14.5}],"tv":4.2}]}
{"op":"mcm","clk":"997982030","pt":1580584268644,"mc":[{"id":"1.168081860","rc":[{"trd":[[1.02,2.12]],"batb":[[0,1.02,7.55]],"ltp":1.02,"tv":2.12,"id":7698577,"hc":13.5}],"tv":4.21}]}
{"op":"mcm","clk":"997982859","pt":1580584273772,"mc":[{"id":"1.168081860","rc":[{"trd":[[1.02,2.11]],"batb":[[0,1.02,7.56]],"ltp":1.02,"tv":2.1,"id":7698577,"hc":14.5}],"tv":4.23}]}
{"op":"mcm","clk":"997984957","pt":1580584285590,"mc":[{"id":"1.168081860","rc":[{"trd":[[1.02,2.14]],"batb":[[0,1.02,7.54]],"ltp":1.02,"tv":2.14,"id":7698577,"hc":13.5}],"tv":4.24}]}
{"op":"mcm","clk":"997985765","pt":1580584290504,"mc":[{"id":"1.168081860","rc":[{"trd":[[1.02,2.12]],"batb":[[0,1.02,7.55]],"ltp":1.02,"tv":2.12,"id":7698577,"hc":14.5}],"tv":4.26}]}
{"op":"mcm","clk":"997987715","pt":1580584301702,"mc":[{"id":"1.168081860","rc":[{"batl":[[0,1000,2.37]],"ltp":1.02,"tv":2.14,"id":7698577,"hc":13.5}]}]}
{"op":"mcm","clk":"997987828","pt":1580584302300,"mc":[{"id":"1.168081860","rc":[{"trd":[[1.02,2.16]],"batb":[[0,1.02,7.53]],"batl":[[0,990,0.01]],"ltp":1.02,"tv":2.15,"id":7698577,"hc":13.5}],"tv":4.28}]}
{"op":"mcm","clk":"997988578","pt":1580584306614,"mc":[{"id":"1.168081860","rc":[{"batl":[[0,1000,2.37]],"ltp":1.02,"tv":2.12,"id":7698577,"hc":14.5}]}]}
{"op":"mcm","clk":"997988698","pt":1580584307315,"mc":[{"id":"1.168081860","rc":[{"trd":[[1.02,2.14]],"batb":[[0,1.02,7.54]],"batl":[[0,990,0.01]],"ltp":1.02,"tv":2.14,"id":7698577,"hc":14.5}],"tv":4.29}]}
{"op":"mcm","clk":"997990667","pt":1580584318552,"mc":[{"id":"1.168081860","rc":[{"batl":[[0,1000,0.02]],"ltp":1.02,"tv":2.15,"id":7698577,"hc":13.5}]}]}
{"op":"mcm","clk":"997990720","pt":1580584318834,"mc":[{"id":"1.168081860","rc":[{"trd":[[1.02,2.17]],"batb":[[0,1.02,7.52]],"batl":[[0,990,0.01]],"ltp":1.02,"tv":2.17,"id":7698577,"hc":13.5}],"tv":4.31}]}
{"op":"mcm","clk":"997991599","pt":1580584323666,"mc":[{"id":"1.168081860","rc":[{"trd":[[1.02,2.16]],"batb":[[0,1.02,7.53]],"ltp":1.02,"tv":2.15,"id":7698577,"hc":14.5}],"tv":4.32}]}
{"op":"mcm","clk":"997993699","pt":1580584335528,"mc":[{"id":"1.168081860","rc":[{"trd":[[1.02,2.19]],"batb":[[0,1.02,7.51]],"ltp":1.02,"tv":2.18,"id":7698577,"hc":13.5}],"tv":4.34}]}
{"op":"mcm","clk":"997994589","pt":1580584340604,"mc":[{"id":"1.168081860","rc":[{"trd":[[1.02,2.17]],"batb":[[0,1.02,7.52]],"ltp":1.02,"tv":2.17,"id":7698577,"hc":14.5}],"tv":4.35}]}
{"op":"mcm","clk":"997996403","pt":1580584351681,"mc":[{"id":"1.168081860","rc":[{"batl":[[0,1000,2.37]],"ltp":1.02,"tv":2.18,"id":7698577,"hc":13.5}]}]}
{"op":"mcm","clk":"997996508","pt":1580584352275,"mc":[{"id":"1.168081860","rc":[{"trd":[[1.02,2.2]],"batb":[[0,1.02,7.5]],"batl":[[0,990,0.01]],"ltp":1.02,"tv":2.2,"id":7698577,"hc":13.5}],"tv":4.37}]}
{"op":"mcm","clk":"997997218","pt":1580584356513,"mc":[{"id":"1.168081860","rc":[{"batl":[[0,1000,0.02]],"ltp":1.02,"tv":2.17,"id":7698577,"hc":14.5}]}]}
{"op":"mcm","clk":"997997309","pt":1580584356999,"mc":[{"id":"1.168081860","rc":[{"trd":[[1.02,2.19]],"batb":[[0,1.02,7.51]],"batl":[[0,990,0.01]],"ltp":1.02,"tv":2.18,"id":7698577,"hc":14.5}],"tv":4.38}]}
{"op":"mcm","clk":"997999370","pt":1580584368493,"mc":[{"id":"1.168081860","rc":[{"trd":[[1.02,2.22]],"batb":[[0,1.02,7.49]],"ltp":1.02,"tv":2.21,"id":7698577,"hc":13.5}],"tv":4.4}]}
{"op":"mcm","clk":"998000048","pt":1580584372634,"mc":[{"id":"1.168081860","rc":[{"batl":[[0,1000,0.02]],"ltp":1.02,"tv":2.18,"id":7698577,"hc":14.5}]}]}
{"op":"mcm","clk":"998000088","pt":1580584372902,"mc":[{"id":"1.168081860","rc":[{"trd":[[1.02,2.2]],"batb":[[0,1.02,7.5]],"batl":[[0,990,0.01]],"ltp":1.02,"tv":2.2,"id":7698577,"hc":14.5}],"tv":4.41}]}
{"op":"mcm","clk":"998002343","pt":1580584385727,"mc":[{"id":"1.168081860","rc":[{"trd":[[1.02,2.23]],"batb":[[0,1.02,7.48]],"ltp":1.02,"tv":2.23,"id":7698577,"hc":13.5}],"tv":4.43}]}
{"op":"mcm","clk":"998003088","pt":1580584389657,"mc":[{"id":"1.168081860","rc":[{"batl":[[0,1000,2.37]],"ltp":1.02,"tv":2.2,"id":7698577,"hc":14.5}]}]}
{"op":"mcm","clk":"998003205","pt":1580584390254,"mc":[{"id":"1.168081860","rc":[{"trd":[[1.02,2.22]],"batb":[[0,1.02,7.49]],"batl":[[0,990,0.01]],"ltp":1.02,"tv":2.21,"id":7698577,"hc":14.5}],"tv":4.45}]}
{"op":"mcm","clk":"998005456","pt":1580584402689,"mc":[{"id":"1.168081860","rc":[{"trd":[[1.02,2.25]],"batb":[[0,1.02,7.47]],"ltp":1.02,"tv":2.24,"id":7698577,"hc":13.5}],"tv":4.46}]}
{"op":"mcm","clk":"998006137","pt":1580584406566,"mc":[{"id":"1.168081860","rc":[{"trd":[[1.02,2.23]],"batb":[[0,1.02,7.48]],"ltp":1.02,"tv":2.23,"id":7698577,"hc":14.5}],"tv":4.48}]}
{"op":"mcm","clk":"998008294","pt":1580584418594,"mc":[{"id":"1.168081860","rc":[{"batl":[[0,1000,0.02]],"ltp":1.02,"tv":2.24,"id":7698577,"hc":13.5}]}]}
{"op":"mcm","clk":"998008367","pt":1580584419033,"mc":[{"id":"1.168081860","rc":[{"trd":[[1.02,2.26]],"batb":[[0,1.02,7.46]],"batl":[[0,990,0.01]],"ltp":1.02,"tv":2.26,"id":7698577,"hc":13.5}],"tv":4.49}]}
{"op":"mcm","clk":"998009016","pt":1580584422700,"mc":[{"id":"1.168081860","rc":[{"trd":[[1.02,2.25]],"batb":[[0,1.02,7.47]],"ltp":1.02,"tv":2.24,"id":7698577,"hc":14.5}],"tv":4.51}]}
{"op":"mcm","clk":"998011437","pt":1580584435623,"mc":[{"id":"1.168081860","rc":[{"batl":[[0,1000,0.02]],"ltp":1.02,"tv":2.26,"id":7698577,"hc":13.5}]}]}
{"op":"mcm","clk":"998011494","pt":1580584435941,"mc":[{"id":"1.168081860","rc":[{"trd":[[1.02,2.28]],"batb":[[0,1.02,7.45]],"batl":[[0,990,0.01]],"ltp":1.02,"tv":2.27,"id":7698577,"hc":13.5}],"tv":4.52}]}
{"op":"mcm","clk":"998012321","pt":1580584440364,"mc":[{"id":"1.168081860","rc":[{"trd":[[1.02,2.26]],"batb":[[0,1.02,7.46]],"ltp":1.02,"tv":2.26,"id":7698577,"hc":14.5}],"tv":4.54}]}
{"op":"mcm","clk":"998014464","pt":1580584452603,"mc":[{"id":"1.168081860","rc":[{"batl":[[0,1000,0.02]],"ltp":1.02,"tv":2.27,"id":7698577,"hc":13.5}]}]}
{"op":"mcm","clk":"998014513","pt":1580584452884,"mc":[{"id":"1.168081860","rc":[{"trd":[[1.02,2.3]],"batb":[[0,1.02,7.44]],"batl":[[0,990,0.01]],"ltp":1.02,"tv":2.29,"id":7698577,"hc":13.5}],"tv":4.55}]}
{"op":"mcm","clk":"998015108","pt":1580584456280,"mc":[{"id":"1.168081860","rc":[{"trd":[[1.02,2.28]],"batb":[[0,1.02,7.45]],"ltp":1.02,"tv":2.27,"id":7698577,"hc":14.5}],"tv":4.57}]}
{"op":"mcm","clk":"998017493","pt":1580584469528,"mc":[{"id":"1.168081860","rc":[{"trd":[[1.02,2.31]],"batb":[[0,1.02,7.43]],"ltp":1.02,"tv":2.31,"id":7698577,"hc":13.5}],"tv":4.59}]}
{"op":"mcm","clk":"998018044","pt":1580584472404,"mc":[{"id":"1.168081860","rc":[{"batl":[[0,1000,2.37]],"ltp":1.02,"tv":2.27,"id":7698577,"hc":14.5}]}]}
{"op":"mcm","clk":"998018194","pt":1580584473125,"mc":[{"id":"1.168081860","rc":[{"trd":[[1.02,2.3]],"batb":[[0,1.02,7.44]],"batl":[[0,990,0.01]],"ltp":1.02,"tv":2.29,"id":7698577,"hc":14.5}],"tv":4.6}]}
{"op":"mcm","clk":"998020501","pt":1580584485565,"mc":[{"id":"1.168081860","rc":[{"batl":[[0,1000,0.02]],"ltp":1.02,"tv":2.31,"id":7698577,"hc":13.5}]}]}
{"op":"mcm","clk":"998020587","pt":1580584486008,"mc":[{"id":"1.168081860","rc":[{"trd":[[1.02,2.33]],"batb":[[0,1.02,7.42]],"batl":[[0,990,0.01]],"ltp":1.02,"tv":2.32,"id":7698577,"hc":13.5}],"tv":4.62}]}
{"op":"mcm","clk":"998021271","pt":1580584489577,"mc":[{"id":"1.168081860","rc":[{"trd":[[1.02,2.31]],"batb":[[0,1.02,7.43]],"ltp":1.02,"tv":2.31,"id":7698577,"hc":14.5}],"tv":4.63}]}
{"op":"mcm","clk":"998023612","pt":1580584502503,"mc":[{"id":"1.168081860","rc":[{"trd":[[1.02,2.34]],"batb":[[0,1.02,7.41]],"ltp":1.02,"tv":2.34,"id":7698577,"hc":13.5}],"tv":4.65}]}
{"op":"mcm","clk":"998024415","pt":1580584506595,"mc":[{"id":"1.168081860","rc":[{"trd":[[1.02,2.33]],"batb":[[0,1.02,7.42]],"ltp":1.02,"tv":2.32,"id":7698577,"hc":14.5}],"tv":4.66}]}
{"op":"mcm","clk":"998026674","pt":1580584518701,"mc":[{"id":"1.168081860","rc":[{"batl":[[0,1000,2.37]],"ltp":1.02,"tv":2.34,"id":7698577,"hc":13.5}]}]}
{"op":"mcm","clk":"998026865","pt":1580584519699,"mc":[{"id":"1.168081860","rc":[{"trd":[[1.02,2.36]],"batb":[[0,1.02,7.4]],"batl":[[0,990,0.01]],"ltp":1.02,"tv":2.35,"id":7698577,"hc":13.5}],"tv":4.68}]}
{"op":"mcm","clk":"998027396","pt":1580584522425,"mc":[{"id":"1.168081860","rc":[{"batl":[[0,1000,2.37]],"ltp":1.02,"tv":2.32,"id":7698577,"hc":14.5}]}]}
{"op":"mcm","clk":"998027523","pt":1580584523116,"mc":[{"id":"1.168081860","rc":[{"trd":[[1.02,2.34]],"batb":[[0,1.02,7.41]],"batl":[[0,990,0.01]],"ltp":1.02,"tv":2.34,"id":7698577,"hc":14.5}],"tv":4.69}]}
{"op":"mcm","clk":"998030031","pt":1580584536760,"mc":[{"id":"1.168081860","rc":[{"trd":[[1.02,2.37]],"batb":[[0,1.02,7.39]],"ltp":1.02,"tv":2.37,"id":7698577,"hc":13.5}],"tv":4.71}]}
{"op":"mcm","clk":"998030588","pt":1580584539562,"mc":[{"id":"1.168081860","rc":[{"batl":[[0,1000,0.02]],"ltp":1.02,"tv":2.34,"id":7698577,"hc":14.5}]}]}
{"op":"mcm","clk":"998030668","pt":1580584539969,"mc":[{"id":"1.168081860","rc":[{"trd":[[1.02,2.36]],"batb":[[0,1.02,7.4]],"batl":[[0,990,0.01]],"ltp":1.02,"tv":2.35,"id":7698577,"hc":14.5}],"tv":4.72}]}
{"op":"mcm","clk":"998033331","pt":1580584553787,"mc":[{"id":"1.168081860","rc":[{"trd":[[1.02,2.39]],"batb":[[0,1.02,7.38]],"ltp":1.02,"tv":2.38,"id":7698577,"hc":13.5}],"tv":4.74}]}
{"op":"mcm","clk":"998033831","pt":1580584556487,"mc":[{"id":"1.168081860","rc":[{"trd":[[1.02,2.37]],"batb":[[0,1.02,7.39]],"ltp":1.02,"tv":2.37,"id":7698577,"hc":14.5}],"tv":4.76}]}
{"op":"mcm","clk":"998036425","pt":1580584569517,"mc":[{"id":"1.168081860","rc":[{"batl":[[0,1000,2.37]],"ltp":1.02,"tv":2.38,"id":7698577,"hc":13.5}]}]}
{"op":"mcm","clk":"998036598","pt":1580584570323,"mc":[{"id":"1.168081860","rc":[{"trd":[[1.02,2.4]],"batb":[[0,1.02,7.37]],"batl":[[0,990,0.01]],"ltp":1.02,"tv":2.4,"id":7698577,"hc":13.5}],"tv":4.77}]}
{"op":"mcm","clk":"998036980","pt":1580584572341,"mc":[{"id":"1.168081860","rc":[{"trd":[[1.02,2.39]],"batb":[[0,1.02,7.38]],"ltp":1.02,"tv":2.38,"id":7698577,"hc":14.5}],"tv":4.79}]}
{"op":"mcm","clk":"998039927","pt":1580584587658,"mc":[{"id":"1.168081860","rc":[{"trd":[[1.02,2.42]],"batb":[[0,1.02,7.36]],"ltp":1.02,"tv":2.41,"id":7698577,"hc":13.5},{"batl":[[0,1000,2.37]],"ltp":1.02,"tv":2.38,"id":7698577,"hc":14.5}],"tv":4.8}]}
{"op":"mcm","clk":"998040055","pt":1580584588334,"mc":[{"id":"1.168081860","rc":[{"trd":[[1.02,2.4]],"batb":[[0,1.02,7.37]],"batl":[[0,990,0.01]],"ltp":1.02,"tv":2.4,"id":7698577,"hc":14.5}],"tv":4.82}]}
{"op":"mcm","clk":"998042718","pt":1580584602501,"mc":[{"id":"1.168081860","rc":[{"trd":[[1.02,2.43]],"batb":[[0,1.02,7.35]],"ltp":1.02,"tv":2.43,"id":7698577,"hc":13.5}],"tv":4.83}]}
{"op":"mcm","clk":"998042954","pt":1580584603698,"mc":[{"id":"1.168081860","rc":[{"batl":[[0,1000,2.37]],"ltp":1.02,"tv":2.4,"id":7698577,"hc":14.5}]}]}
{"op":"mcm","clk":"998043089","pt":1580584604429,"mc":[{"id":"1.168081860","rc":[{"trd":[[1.02,2.42]],"batb":[[0,1.02,7.36]],"batl":[[0,990,0.01]],"ltp":1.02,"tv":2.41,"id":7698577,"hc":14.5}],"tv":4.85}]}
{"op":"mcm","clk":"998045792","pt":1580584618694,"mc":[{"id":"1.168081860","rc":[{"batl":[[0,1000,2.37]],"ltp":1.02,"tv":2.43,"id":7698577,"hc":13.5}]}]}
{"op":"mcm","clk":"998045923","pt":1580584619274,"mc":[{"id":"1.168081860","rc":[{"trd":[[1.02,2.45]],"batb":[[0,1.02,7.34]],"batl":[[0,990,0.01]],"ltp":1.02,"tv":2.45,"id":7698577,"hc":13.5}],"tv":4.86}]}
{"op":"mcm","clk":"998046160","pt":1580584620479,"mc":[{"id":"1.168081860","rc":[{"batl":[[0,1000,0.02]],"ltp":1.02,"tv":2.41,"id":7698577,"hc":14.5}]}]}
{"op":"mcm","clk":"998046255","pt":1580584620885,"mc":[{"id":"1.168081860","rc":[{"trd":[[1.02,2.43]],"batb":[[0,1.02,7.35]],"batl":[[0,990,0.01]],"ltp":1.02,"tv":2.43,"id":7698577,"hc":14.5}],"tv":4.88}]}
{"op":"mcm","clk":"998049356","pt":1580584636591,"mc":[{"id":"1.168081860","rc":[{"trd":[[1.02,2.47]],"batb":[[0,1.02,7.33]],"ltp":1.02,"tv":2.46,"id":7698577,"hc":13.5}],"tv":4.9}]}
{"op":"mcm","clk":"998049536","pt":1580584637494,"mc":[{"id":"1.168081860","rc":[{"batl":[[0,1000,2.37]],"ltp":1.02,"tv":2.43,"id":7698577,"hc":14.5}]}]}
{"op":"mcm","clk":"998049691","pt":1580584638210,"mc":[{"id":"1.168081860","rc":[{"trd":[[1.02,2.45]],"batb":[[0,1.02,7.34]],"batl":[[0,990,0.01]],"ltp":1.02,"tv":2.45,"id":7698577,"hc":14.5}],"tv":4.91}]}
{"op":"mcm","clk":"998052679","pt":1580584653651,"mc":[{"id":"1.168081860","rc":[{"trd":[[1.02,2.48]],"batb":[[0,1.02,7.32]],"ltp":1.02,"tv":2.48,"id":7698577,"hc":13.5},{"batl":[[0,1000,0.02]],"ltp":1.02,"tv":2.45,"id":7698577,"hc":14.5}],"tv":4.93}]}
{"op":"mcm","clk":"998052745","pt":1580584654025,"mc":[{"id":"1.168081860","rc":[{"trd":[[1.02,2.47]],"batb":[[0,1.02,7.33]],"batl":[[0,990,0.01]],"ltp":1.02,"tv":2.46,"id":7698577,"hc":14.5}],"tv":4.94}]}
{"op":"mcm","clk":"998055950","pt":1580584669596,"mc":[{"id":"1.168081860","rc":[{"batl":[[0,1000,2.37]],"ltp":1.02,"tv":2.48,"id":7698577,"hc":13.5},{"batl":[[0,1000,0.02]],"ltp":1.02,"tv":2.46,"id":7698577,"hc":14.5}]}]}
{"op":"mcm","clk":"998056049","pt":1580584670096,"mc":[{"id":"1.168081860","rc":[{"trd":[[1.02,2.5]],"batb":[[0,1.02,7.31]],"batl":[[0,990,0.01]],"ltp":1.02,"tv":2.49,"id":7698577,"hc":13.5},{"trd":[[1.02,2.48]],"batb":[[0,1.02,7.32]],"batl":[[0,990,0.01]],"ltp":1.02,"tv":2.48,"id":7698577,"hc":14.5}],"tv":4.97}]}
{"op":"mcm","clk":"998059086","pt":1580584686523,"mc":[{"id":"1.168081860","rc":[{"batl":[[0,1000,0.02]],"ltp":1.02,"tv":2.49,"id":7698577,"hc":13.5},{"trd":[[1.02,2.5]],"batb":[[0,1.02,7.31]],"ltp":1.02,"tv":2.49,"id":7698577,"hc":14.5}],"tv":4.99}]}
{"op":"mcm","clk":"998059142","pt":1580584686814,"mc":[{"id":"1.168081860","rc":[{"trd":[[1.02,2.51]],"batb":[[0,1.02,7.3]],"batl":[[0,990,0.01]],"ltp":1.02,"tv":2.51,"id":7698577,"hc":13.5}],"tv":5.0}]}
{"op":"mcm","clk":"998061952","pt":1580584702581,"mc":[{"id":"1.168081860","rc":[{"batl":[[0,1000,2.37]],"ltp":1.02,"tv":2.51,"id":7698577,"hc":13.5},{"batl":[[0,1000,2.37]],"ltp":1.02,"tv":2.49,"id":7698577,"hc":14.5}]}]}
{"op":"mcm","clk":"998062059","pt":1580584703184,"mc":[{"id":"1.168081860","rc":[{"trd":[[1.02,2.53]],"batb":[[0,1.02,7.29]],"batl":[[0,990,0.01]],"ltp":1.02,"tv":2.52,"id":7698577,"hc":13.5},{"trd":[[1.02,2.51]],"batb":[[0,1.02,7.3]],"batl":[[0,990,0.01]],"ltp":1.02,"tv":2.51,"id":7698577,"hc":14.5}],"tv":5.04}]}
{"op":"mcm","clk":"998064948","pt":1580584718578,"mc":[{"id":"1.168081860","rc":[{"batl":[[0,1000,0.02]],"ltp":1.02,"tv":2.51,"id":7698577,"hc":14.5}]}]}
{"op":"mcm","clk":"998065105","pt":1580584719495,"mc":[{"id":"1.168081860","rc":[{"batl":[[0,1000,0.02]],"ltp":1.02,"tv":2.52,"id":7698577,"hc":13.5},{"trd":[[1.02,2.53]],"batb":[[0,1.02,7.29]],"batl":[[0,990,0.01]],"ltp":1.02,"tv":2.52,"id":7698577,"hc":14.5}],"tv":5.05}]}
{"op":"mcm","clk":"998065182","pt":1580584719878,"mc":[{"id":"1.168081860","rc":[{"trd":[[1.02,2.54]],"batb":[[0,1.02,7.28]],"batl":[[0,990,0.01]],"ltp":1.02,"tv":2.54,"id":7698577,"hc":13.5}],"tv":5.07}]}
{"op":"mcm","clk":"998068210","pt":1580584735697,"mc":[{"id":"1.168081860","rc":[{"batl":[[0,1000,2.37]],"ltp":1.02,"tv":2.52,"id":7698577,"hc":14.5}]}]}
{"op":"mcm","clk":"998068389","pt":1580584736691,"mc":[{"id":"1.168081860","rc":[{"batl":[[0,1000,0.02]],"ltp":1.02,"tv":2.54,"id":7698577,"hc":13.5},{"trd":[[1.02,2.54]],"batb":[[0,1.02,7.28]],"batl":[[0,990,0.01]],"ltp":1.02,"tv":2.54,"id":7698577,"hc":14.5}],"tv":5.08}]}
{"op":"mcm","clk":"998068452","pt":1580584737008,"mc":[{"id":"1.168081860","rc":[{"trd":[[1.02,2.56]],"batb":[[0,1.02,7.27]],"batl":[[0,990,0.01]],"ltp":1.02,"tv":2.55,"id":7698577,"hc":13.5}],"tv":5.1}]}
{"op":"mcm","clk":"998071134","pt":1580584752628,"mc":[{"id":"1.168081860","rc":[{"batl":[[0,1000,2.37]],"ltp":1.02,"tv":2.55,"id":7698577,"hc":13.5},{"batl":[[0,1000,0.02]],"ltp":1.02,"tv":2.54,"id":7698577,"hc":14.5}]}]}
{"op":"mcm","clk":"998071309","pt":1580584753439,"mc":[{"id":"1.168081860","rc":[{"trd":[[1.02,2.57]],"batb":[[0,1.02,7.26]],"batl":[[0,990,0.01]],"ltp":1.02,"tv":2.57,"id":7698577,"hc":13.5},{"trd":[[1.02,2.56]],"batb":[[0,1.02,7.27]],"batl":[[0,990,0.01]],"ltp":1.02,"tv":2.55,"id":7698577,"hc":14.5}],"tv":5.13}]}
{"op":"mcm","clk":"998074236","pt":1580584769629,"mc":[{"id":"1.168081860","rc":[{"trd":[[1.02,2.59]],"batb":[[0,1.02,7.25]],"ltp":1.02,"tv":2.58,"id":7698577,"hc":13.5},{"batl":[[0,1000,2.37]],"ltp":1.02,"tv":2.55,"id":7698577,"hc":14.5}],"tv":5.14}]}
{"op":"mcm","clk":"998074356","pt":1580584770280,"mc":[{"id":"1.168081860","rc":[{"trd":[[1.02,2.57]],"batb":[[0,1.02,7.26]],"batl":[[0,990,0.01]],"ltp":1.02,"tv":2.57,"id":7698577,"hc":14.5}],"tv":5.16}]}
{"op":"mcm","clk":"998077031","pt":1580584786677,"mc":[{"id":"1.168081860","rc":[{"trd":[[1.02,2.61]],"batb":[[0,1.02,7.24]],"ltp":1.02,"tv":2.6,"id":7698577,"hc":13.5},{"batl":[[0,1000,2.37]],"ltp":1.02,"tv":2.57,"id":7698577,"hc":14.5}],"tv":5.17}]}
{"op":"mcm","clk":"998077169","pt":1580584787378,"mc":[{"id":"1.168081860","rc":[{"trd":[[1.02,2.59]],"batb":[[0,1.02,7.25]],"batl":[[0,990,0.01]],"ltp":1.02,"tv":2.58,"id":7698577,"hc":14.5}],"tv":5.19}]}
{"op":"mcm","clk":"998080043","pt":1580584804606,"mc":[{"id":"1.168081860","rc":[{"trd":[[1.02,2.62]],"batb":[[0,1.02,7.23]],"ltp":1.02,"tv":2.62,"id":7698577,"hc":13.5},{"trd":[[1.02,2.61]],"batb":[[0,1.02,7.24]],"ltp":1.02,"tv":2.6,"id":7698577,"hc":14.5}],"tv":5.22}]}
{"op":"mcm","clk":"998082633","pt":1580584820673,"mc":[{"id":"1.168081860","rc":[{"batl":[[0,1000,0.02]],"ltp":1.02,"tv":2.62,"id":7698577,"hc":13.5}]}]}
{"op":"mcm","clk":"998082801","pt":1580584821684,"mc":[{"id":"1.168081860","rc":[{"trd":[[1.02,2.64]],"batb":[[0,1.02,7.22]],"batl":[[0,990,0.01]],"ltp":1.02,"tv":2.63,"id":7698577,"hc":13.5},{"trd":[[1.02,2.62]],"batb":[[0,1.02,7.23]],"ltp":1.02,"tv":2.62,"id":7698577,"hc":14.5}],"tv":5.25}]}
{"op":"mcm","clk":"998085397","pt":1580584837616,"mc":[{"id":"1.168081860","rc":[{"batl":[[0,1000,0.02]],"ltp":1.02,"tv":2.63,"id":7698577,"hc":13.5}]}]}
{"op":"mcm","clk":"998085625","pt":1580584838699,"mc":[{"id":"1.168081860","rc":[{"trd":[[1.02,2.65]],"batb":[[0,1.02,7.21]],"batl":[[0,990,0.01]],"ltp":1.02,"tv":2.65,"id":7698577,"hc":13.5},{"batl":[[0,1000,0.02]],"ltp":1.02,"tv":2.62,"id":7698577,"hc":14.5}],"tv":5.27}]}
{"op":"mcm","clk":"998085692","pt":1580584839025,"mc":[{"id":"1.168081860","rc":[{"trd":[[1.02,2.64]],"batb":[[0,1.02,7.22]],"batl":[[0,990,0.01]],"ltp":1.02,"tv":2.63,"id":7698577,"hc":14.5}],"tv":5.28}]}
{"op":"mcm","clk":"998088351","pt":1580584854555,"mc":[{"id":"1.168081860","rc":[{"trd":[[1.02,2.67]],"batb":[[0,1.02,7.2]],"ltp":1.02,"tv":2.66,"id":7698577,"hc":13.5}],"tv":5.3}]}
{"op":"mcm","clk":"998088537","pt":1580584855480,"mc":[{"id":"1.168081860","rc":[{"batl":[[0,1000,0.02]],"ltp":1.02,"tv":2.63,"id":7698577,"hc":14.5}]}]}
{"op":"mcm","clk":"998088615","pt":1580584855868,"mc":[{"id":"1.168081860","rc":[{"trd":[[1.02,2.65]],"batb":[[0,1.02,7.21]],"batl":[[0,990,0.01]],"ltp":1.02,"tv":2.65,"id":7698577,"hc":14.5}],"tv":5.31}]}
{"op":"mcm","clk":"998091160","pt":1580584870602,"mc":[{"id":"1.168081860","rc":[{"batl":[[0,1000,2.37]],"ltp":1.02,"tv":2.66,"id":7698577,"hc":13.5}]}]}
{"op":"mcm","clk":"998091309","pt":1580584871273,"mc":[{"id":"1.168081860","rc":[{"trd":[[1.02,2.68]],"batb":[[0,1.02,7.19]],"batl":[[0,990,0.01]],"ltp":1.02,"tv":2.68,"id":7698577,"hc":13.5}],"tv":5.33}]}
{"op":"mcm","clk":"998091573","pt":1580584872693,"mc":[{"id":"1.168081860","rc":[{"batl":[[0,1000,0.02]],"ltp":1.02,"tv":2.65,"id":7698577,"hc":14.5}]}]}
{"op":"mcm","clk":"998091641","pt":1580584873112,"mc":[{"id":"1.168081860","rc":[{"trd":[[1.02,2.67]],"batb":[[0,1.02,7.2]],"batl":[[0,990,0.01]],"ltp":1.02,"tv":2.66,"id":7698577,"hc":14.5}],"tv":5.35}]}
{"op":"mcm","clk":"998094298","pt":1580584888285,"mc":[{"id":"1.168081860","rc":[{"trd":[[1.02,2.7]],"batb":[[0,1.02,7.18]],"ltp":1.02,"tv":2.69,"id":7698577,"hc":13.5}],"tv":5.36}]}
{"op":"mcm","clk":"998094495","pt":1580584889422,"mc":[{"id":"1.168081860","rc":[{"trd":[[1.02,2.68]],"batb":[[0,1.02,7.19]],"ltp":1.02,"tv":2.68,"id":7698577,"hc":14.5}],"tv":5.38}]}
{"op":"mcm","clk":"998097183","pt":1580584905576,"mc":[{"id":"1.168081860","rc":[{"trd":[[1.02,2.71]],"batb":[[0,1.02,7.17]],"ltp":1.02,"tv":2.71,"id":7698577,"hc":13.5}],"tv":5.39}]}
{"op":"mcm","clk":"998097214","pt":1580584905766,"mc":[{"id":"1.168081860","rc":[{"trd":[[1.02,2.7]],"batb":[[0,1.02,7.18]],"ltp":1.02,"tv":2.69,"id":7698577,"hc":14.5}],"tv":5.41}]}
{"op":"mcm","clk":"998099879","pt":1580584921669,"mc":[{"id":"1.168081860","rc":[{"batl":[[0,1000,0.02]],"ltp":1.02,"tv":2.69,"id":7698577,"hc":14.5}]}]}
{"op":"mcm","clk":"998099995","pt":1580584922362,"mc":[{"id":"1.168081860","rc":[{"trd":[[1.02,2.73]],"batb":[[0,1.02,7.16]],"ltp":1.02,"tv":2.72,"id":7698577,"hc":13.5},{"trd":[[1.02,2.71]],"batb":[[0,1.02,7.17]],"batl":[[0,990,0.01]],"ltp":1.02,"tv":2.71,"id":7698577,"hc":14.5}],"tv":5.44}]}
{"op":"mcm","clk":"998102625","pt":1580584938609,"mc":[{"id":"1.168081860","rc":[{"batl":[[0,1000,0.02]],"ltp":1.02,"tv":2.72,"id":7698577,"hc":13.5}]}]}
{"op":"mcm","clk":"998102816","pt":1580584939682,"mc":[{"id":"1.168081860","rc":[{"trd":[[1.02,2.74]],"batb":[[0,1.02,7.15]],"batl":[[0,990,0.01]],"ltp":1.02,"tv":2.74,"id":7698577,"hc":13.5},{"trd":[[1.02,2.73]],"batb":[[0,1.02,7.16]],"ltp":1.02,"tv":2.72,"id":7698577,"hc":14.5}],"tv":5.47}]}
{"op":"mcm","clk":"998105596","pt":1580584956590,"mc":[{"id":"1.168081860","rc":[{"trd":[[1.02,2.76]],"batb":[[0,1.02,7.14]],"ltp":1.02,"tv":2.76,"id":7698577,"hc":13.5},{"trd":[[1.02,2.74]],"batb":[[0,1.02,7.15]],"ltp":1.02,"tv":2.74,"id":7698577,"hc":14.5}],"tv":5.5}]}
{"op":"mcm","clk":"998108138","pt":1580584973613,"mc":[{"id":"1.168081860","rc":[{"trd":[[1.02,2.78]],"batb":[[0,1.02,7.13]],"ltp":1.02,"tv":2.77,"id":7698577,"hc":13.5}],"tv":5.52}]}
{"op":"mcm","clk":"998108154","pt":1580584973720,"mc":[{"id":"1.168081860","rc":[{"trd":[[1.02,2.76]],"batb":[[0,1.02,7.14]],"ltp":1.02,"tv":2.76,"id":7698577,"hc":14.5}],"tv":5.53}]}
{"op":"mcm","clk":"998110633","pt":1580584989583,"mc":[{"id":"1.168081860","rc":[{"batl":[[0,1000,2.37]],"ltp":1.02,"tv":2.77,"id":7698577,"hc":13.5},{"batl":[[0,1000,2.37]],"ltp":1.02,"tv":2.76,"id":7698577,"hc":14.5}]}]}
{"op":"mcm","clk":"998110761","pt":1580584990274,"mc":[{"id":"1.168081860","rc":[{"trd":[[1.02,2.79]],"batb":[[0,1.02,7.12]],"batl":[[0,990,0.01]],"ltp":1.02,"tv":2.79,"id":7698577,"hc":13.5},{"trd":[[1.02,2.78]],"batb":[[0,1.02,7.13]],"batl":[[0,990,0.01]],"ltp":1.02,"tv":2.77,"id":7698577,"hc":14.5}],"tv":5.56}]}
{"op":"mcm","clk":"998113233","pt":1580585006638,"mc":[{"id":"1.168081860","rc":[{"batl":[[0,1000,2.37]],"ltp":1.02,"tv":2.79,"id":7698577,"hc":13.5}]}]}
{"op":"mcm","clk":"998113293","pt":1580585007038,"mc":[{"id":"1.168081860","rc":[{"trd":[[1.02,2.81]],"batb":[[0,1.02,7.11]],"batl":[[0,990,0.01]],"ltp":1.02,"tv":2.8,"id":7698577,"hc":13.5},{"trd":[[1.02,2.79]],"batb":[[0,1.02,7.12]],"ltp":1.02,"tv":2.79,"id":7698577,"hc":14.5}],"tv":5.59}]}
{"op":"mcm","clk":"998115752","pt":1580585023643,"mc":[{"id":"1.168081860","rc":[{"batl":[[0,1000,0.02]],"ltp":1.02,"tv":2.8,"id":7698577,"hc":13.5},{"batl":[[0,1000,2.37]],"ltp":1.02,"tv":2.79,"id":7698577,"hc":14.5}]}]}
{"op":"mcm","clk":"998115851","pt":1580585024234,"mc":[{"id":"1.168081860","rc":[{"trd":[[1.02,2.82]],"batb":[[0,1.02,7.1]],"batl":[[0,990,0.01]],"ltp":1.02,"tv":2.82,"id":7698577,"hc":13.5},{"trd":[[1.02,2.81]],"batb":[[0,1.02,7.11]],"batl":[[0,990,0.01]],"ltp":1.02,"tv":2.8,"id":7698577,"hc":14.5}],"tv":5.62}]}
{"op":"mcm","clk":"998118218","pt":1580585040589,"mc":[{"id":"1.168081860","rc":[{"trd":[[1.02,2.84]],"batb":[[0,1.02,7.09]],"ltp":1.02,"tv":2.83,"id":7698577,"hc":13.5},{"batl":[[0,1000,2.37]],"ltp":1.02,"tv":2.8,"id":7698577,"hc":14.5}],"tv":5.64}]}
{"op":"mcm","clk":"998118299","pt":1580585041091,"mc":[{"id":"1.168081860","rc":[{"trd":[[1.02,2.82]],"batb":[[0,1.02,7.1]],"batl":[[0,990,0.01]],"ltp":1.02,"tv":2.82,"id":7698577,"hc":14.5}],"tv":5.66}]}
{"op":"mcm","clk":"998120631","pt":1580585056399,"mc":[{"id":"1.168081860","rc":[{"batl":[[0,1000,2.37]],"ltp":1.02,"tv":2.83,"id":7698577,"hc":13.5}]}]}
{"op":"mcm","clk":"998120848","pt":1580585057672,"mc":[{"id":"1.168081860","rc":[{"trd":[[1.02,2.85]],"batb":[[0,1.02,7.08]],"batl":[[0,990,0.01]],"ltp":1.02,"tv":2.85,"id":7698577,"hc":13.5},{"batl":[[0,1000,2.37]],"ltp":1.02,"tv":2.82,"id":7698577,"hc":14.5}],"tv":5.67}]}
{"op":"mcm","clk":"998120950","pt":1580585058370,"mc":[{"id":"1.168081860","rc":[{"trd":[[1.02,2.84]],"batb":[[0,1.02,7.09]],"batl":[[0,990,0.01]],"ltp":1.02,"tv":2.83,"id":7698577,"hc":14.5}],"tv":5.69}]}
{"op":"mcm","clk":"998123169","pt":1580585073481,"mc":[{"id":"1.168081860","rc":[{"batl":[[0,1000,2.37]],"ltp":1.02,"tv":2.85,"id":7698577,"hc":13.5}]}]}
{"op":"mcm","clk":"998123291","pt":1580585074226,"mc":[{"id":"1.168081860","rc":[{"trd":[[1.02,2.87]],"batb":[[0,1.02,7.07]],"batl":[[0,990,0.01]],"ltp":1.02,"tv":2.86,"id":7698577,"hc":13.5}],"tv":5.7}]}
{"op":"mcm","clk":"998123461","pt":1580585075254,"mc":[{"id":"1.168081860","rc":[{"trd":[[1.02,2.85]],"batb":[[0,1.02,7.08]],"ltp":1.02,"tv":2.85,"id":7698577,"hc":14.5}],"tv":5.72}]}
{"op":"mcm","clk":"998125732","pt":1580585090500,"mc":[{"id":"1.168081860","rc":[{"batl":[[0,1000,2.37]],"ltp":1.02,"tv":2.86,"id":7698577,"hc":13.5}]}]}
{"op":"mcm","clk":"998125870","pt":1580585091264,"mc":[{"id":"1.168081860","rc":[{"trd":[[1.02,2.88]],"batb":[[0,1.02,7.06]],"batl":[[0,990,0.01]],"ltp":1.02,"tv":2.88,"id":7698577,"hc":13.5}],"tv":5.73}]}
{"op":"mcm","clk":"998126087","pt":1580585092606,"mc":[{"id":"1.168081860","rc":[{"trd":[[1.02,2.87]],"batb":[[0,1.02,7.07]],"ltp":1.02,"tv":2.86,"id":7698577,"hc":14.5}],"tv":5.75}]}
{"op":"mcm","clk":"998128476","pt":1580585107436,"mc":[{"id":"1.168081860","rc":[{"batl":[[0,1000,0.02]],"ltp":1.02,"tv":2.88,"id":7698577,"hc":13.5}]}]}
{"op":"mcm","clk":"998128539","pt":1580585107819,"mc":[{"id":"1.168081860","rc":[{"trd":[[1.02,2.9]],"batb":[[0,1.02,7.05]],"batl":[[0,990,0.01]],"ltp":1.02,"tv":2.89,"id":7698577,"hc":13.5}],"tv":5.76}]}
{"op":"mcm","clk":"998128782","pt":1580585109438,"mc":[{"id":"1.168081860","rc":[{"batl":[[0,1000,2.37]],"ltp":1.02,"tv":2.86,"id":7698577,"hc":14.5}]}]}
{"op":"mcm","clk":"998128889","pt":1580585110101,"mc":[{"id":"1.168081860","rc":[{"trd":[[1.02,2.88]],"batb":[[0,1.02,7.06]],"batl":[[0,990,0.01]],"ltp":1.02,"tv":2.88,"id":7698577,"hc":14.5}],"tv":5.78}]}
{"op":"mcm","clk":"998130838","pt":1580585123576,"mc":[{"id":"1.168081860","rc":[{"batl":[[0,1000,0.02]],"ltp":1.02,"tv":2.89,"id":7698577,"hc":13.5}]}]}
{"op":"mcm","clk":"998130888","pt":1580585124003,"mc":[{"id":"1.168081860","rc":[{"trd":[[1.02,2.92]],"batb":[[0,1.02,7.04]],"batl":[[0,990,0.01]],"ltp":1.02,"tv":2.91,"id":7698577,"hc":13.5}],"tv":5.79}]}
{"op":"mcm","clk":"998131135","pt":1580585125591,"mc":[{"id":"1.168081860","rc":[{"batl":[[0,1000,2.37]],"ltp":1.02,"tv":2.88,"id":7698577,"hc":14.5}]}]}
{"op":"mcm","clk":"998131264","pt":1580585126506,"mc":[{"id":"1.168081860","rc":[{"trd":[[1.02,2.9]],"batb":[[0,1.02,7.05]],"batl":[[0,990,0.01]],"ltp":1.02,"tv":2.89,"id":7698577,"hc":14.5}],"tv":5.81}]}
{"op":"mcm","clk":"998133518","pt":1580585141620,"mc":[{"id":"1.168081860","rc":[{"batl":[[0,1000,0.02]],"ltp":1.02,"tv":2.91,"id":7698577,"hc":13.5}]}]}
{"op":"mcm","clk":"998133675","pt":1580585142632,"mc":[{"id":"1.168081860","rc":[{"trd":[[1.02,2.93]],"batb":[[0,1.02,7.03]],"batl":[[0,990,0.01]],"ltp":1.02,"tv":2.93,"id":7698577,"hc":13.5},{"trd":[[1.02,2.92]],"batb":[[0,1.02,7.04]],"ltp":1.02,"tv":2.91,"id":7698577,"hc":14.5}],"tv":5.84}]}
{"op":"mcm","clk":"998136062","pt":1580585158550,"mc":[{"id":"1.168081860","rc":[{"trd":[[1.02,2.93]],"batb":[[0,1.02,7.03]],"ltp":1.02,"tv":2.93,"id":7698577,"hc":14.5}],"tv":5.86}]}
{"op":"mcm","clk":"998136212","pt":1580585159464,"mc":[{"id":"1.168081860","rc":[{"trd":[[1.02,2.95]],"batb":[[0,1.02,7.02]],"ltp":1.02,"tv":2.94,"id":7698577,"hc":13.5}],"tv":5.87}]}
{"op":"mcm","clk":"998138514","pt":1580585174395,"mc":[{"id":"1.168081860","rc":[{"batl":[[0,1000,0.02]],"ltp":1.02,"tv":2.93,"id":7698577,"hc":14.5}]}]}
{"op":"mcm","clk":"998138677","pt":1580585175526,"mc":[{"id":"1.168081860","rc":[{"batl":[[0,1000,2.37]],"ltp":1.02,"tv":2.94,"id":7698577,"hc":13.5},{"trd":[[1.02,2.95]],"batb":[[0,1.02,7.02]],"batl":[[0,990,0.01]],"ltp":1.02,"tv":2.94,"id":7698577,"hc":14.5}],"tv":5.89}]}
{"op":"mcm","clk":"998138760","pt":1580585176023,"mc":[{"id":"1.168081860","rc":[{"trd":[[1.02,2.96]],"batb":[[0,1.02,7.01]],"batl":[[0,990,0.01]],"ltp":1.02,"tv":2.96,"id":7698577,"hc":13.5}],"tv":5.9}]}
{"op":"mcm","clk":"998141044","pt":1580585190452,"mc":[{"id":"1.168081860","rc":[{"batl":[[0,1000,0.02]],"ltp":1.02,"tv":2.94,"id":7698577,"hc":14.5}]}]}
{"op":"mcm","clk":"998141231","pt":1580585191700,"mc":[{"id":"1.168081860","rc":[{"batl":[[0,1000,0.02]],"ltp":1.02,"tv":2.96,"id":7698577,"hc":13.5},{"trd":[[1.02,2.96]],"batb":[[0,1.02,7.01]],"batl":[[0,990,0.01]],"ltp":1.02,"tv":2.96,"id":7698577,"hc":14.5}],"tv":5.92}]}
{"op":"mcm","clk":"998141299","pt":1580585192071,"mc":[{"id":"1.168081860","rc":[{"trd":[[1.02,2.98]],"batb":[[0,1.02,7]],"batl":[[0,990,0.01]],"ltp":1.02,"tv":2.97,"id":7698577,"hc":13.5}],"tv":5.93}]}
{"op":"mcm","clk":"998143560","pt":1580585206697,"mc":[{"id":"1.168081860","rc":[{"batl":[[0,1000,0.02]],"ltp":1.02,"tv":2.96,"id":7698577,"hc":14.5}]}]}
{"op":"mcm","clk":"998143612","pt":1580585206971,"mc":[{"id":"1.168081860","rc":[{"trd":[[1.02,2.98]],"batb":[[0,1.02,7]],"batl":[[0,990,0.01]],"ltp":1.02,"tv":2.97,"id":7698577,"hc":14.5}],"tv":5.95}]}
{"op":"mcm","clk":"998143892","pt":1580585208763,"mc":[{"id":"1.168081860","rc":[{"trd":[[1.02,2.99]],"batb":[[0,1.02,6.99]],"ltp":1.02,"tv":2.99,"id":7698577,"hc":13.5}],"tv":5.97}]}
{"op":"mcm","clk":"998146150","pt":1580585223445,"mc":[{"id":"1.168081860","rc":[{"batl":[[0,1000,0.02]],"ltp":1.02,"tv":2.97,"id":7698577,"hc":14.5}]}]}
{"op":"mcm","clk":"998146208","pt":1580585223817,"mc":[{"id":"1.168081860","rc":[{"trd":[[1.02,2.99]],"batb":[[0,1.02,6.99]],"batl":[[0,990,0.01]],"ltp":1.02,"tv":2.99,"id":7698577,"hc":14.5}],"tv":5.98}]}
{"op":"mcm","clk":"998146495","pt":1580585225487,"mc":[{"id":"1.168081860","rc":[{"trd":[[1.02,3.01]],"batb":[[0,1.02,6.98]],"ltp":1.02,"tv":3.0,"id":7698577,"hc":13.5}],"tv":6.0}]}
{"op":"mcm","clk":"998148961","pt":1580585240388,"mc":[{"id":"1.168081860","rc":[{"batl":[[0,1000,0.02]],"ltp":1.02,"tv":2.99,"id":7698577,"hc":14.5}]}]}
{"op":"mcm","clk":"998149188","pt":1580585241687,"mc":[{"id":"1.168081860","rc":[{"trd":[[1.02,3.01]],"batb":[[0,1.02,6.98]],"batl":[[0,990,0.01]],"ltp":1.02,"tv":3.0,"id":7698577,"hc":14.5}],"tv":6.01}]}
{"op":"mcm","clk":"998149211","pt":1580585241782,"mc":[{"id":"1.168081860","rc":[{"trd":[[1.02,3.02]],"batb":[[0,1.02,6.97]],"ltp":1.02,"tv":3.02,"id":7698577,"hc":13.5}],"tv":6.03}]}
{"op":"mcm","clk":"998151816","pt":1580585257634,"mc":[{"id":"1.168081860","rc":[{"trd":[[1.02,3.02]],"batb":[[0,1.02,6.97]],"ltp":1.02,"tv":3.02,"id":7698577,"hc":14.5}],"tv":6.04}]}
{"op":"mcm","clk":"998152013","pt":1580585258615,"mc":[{"id":"1.168081860","rc":[{"trd":[[1.02,3.04]],"batb":[[0,1.02,6.96]],"ltp":1.02,"tv":3.03,"id":7698577,"hc":13.5}],"tv":6.06}]}
{"op":"mcm","clk":"998154828","pt":1580585274479,"mc":[{"id":"1.168081860","rc":[{"batl":[[0,1000,0.02]],"ltp":1.02,"tv":3.03,"id":7698577,"hc":13.5},{"batl":[[0,1000,0.02]],"ltp":1.02,"tv":3.02,"id":7698577,"hc":14.5}]}]}
{"op":"mcm","clk":"998154918","pt":1580585274897,"mc":[{"id":"1.168081860","rc":[{"trd":[[1.02,3.06]],"batb":[[0,1.02,6.95]],"batl":[[0,990,0.01]],"ltp":1.02,"tv":3.05,"id":7698577,"hc":13.5},{"trd":[[1.02,3.04]],"batb":[[0,1.02,6.96]],"batl":[[0,990,0.01]],"ltp":1.02,"tv":3.03,"id":7698577,"hc":14.5}],"tv":6.09}]}
{"op":"mcm","clk":"998157810","pt":1580585291489,"mc":[{"id":"1.168081860","rc":[{"batl":[[0,1000,0.02]],"ltp":1.02,"tv":3.05,"id":7698577,"hc":13.5}]}]}
{"op":"mcm","clk":"998158028","pt":1580585292614,"mc":[{"id":"1.168081860","rc":[{"trd":[[1.02,3.07]],"batb":[[0,1.02,6.94]],"batl":[[0,990,0.01]],"ltp":1.02,"tv":3.07,"id":7698577,"hc":13.5},{"trd":[[1.02,3.06]],"batb":[[0,1.02,6.95]],"ltp":1.02,"tv":3.05,"id":7698577,"hc":14.5}],"tv":6.12}]}
{"op":"mcm","clk":"998161003","pt":1580585308687,"mc":[{"id":"1.168081860","rc":[{"batl":[[0,1000,0.02]],"ltp":1.02,"tv":3.07,"id":7698577,"hc":13.5}]}]}
{"op":"mcm","clk":"998161124","pt":1580585309511,"mc":[{"id":"1.168081860","rc":[{"trd":[[1.02,3.09]],"batb":[[0,1.02,6.93]],"batl":[[0,990,0.01]],"ltp":1.02,"tv":3.08,"id":7698577,"hc":13.5},{"batl":[[0,1000,2.37]],"ltp":1.02,"tv":3.05,"id":7698577,"hc":14.5}],"tv":6.14}]}
{"op":"mcm","clk":"998161223","pt":1580585310099,"mc":[{"id":"1.168081860","rc":[{"trd":[[1.02,3.07]],"batb":[[0,1.02,6.94]],"batl":[[0,990,0.01]],"ltp":1.02,"tv":3.07,"id":7698577,"hc":14.5}],"tv":6.15}]}
{"op":"mcm","clk":"998163807","pt":1580585326542,"mc":[{"id":"1.168081860","rc":[{"trd":[[1.02,3.1]],"batb":[[0,1.02,6.92]],"ltp":1.02,"tv":3.1,"id":7698577,"hc":13.5}],"tv":6.17}]}
{"op":"mcm","clk":"998164009","pt":1580585327715,"mc":[{"id":"1.168081860","rc":[{"trd":[[1.02,3.09]],"batb":[[0,1.02,6.93]],"ltp":1.02,"tv":3.08,"id":7698577,"hc":14.5}],"tv":6.18}]}
{"op":"mcm","clk":"998166511","pt":1580585343683,"mc":[{"id":"1.168081860","rc":[{"batl":[[0,1000,0.02]],"ltp":1.02,"tv":3.1,"id":7698577,"hc":13.5}]}]}
{"op":"mcm","clk":"998166652","pt":1580585344601,"mc":[{"id":"1.168081860","rc":[{"trd":[[1.02,3.12]],"batb":[[0,1.02,6.91]],"batl":[[0,990,0.01]],"ltp":1.02,"tv":3.11,"id":7698577,"hc":13.5},{"batl":[[0,1000,0.02]],"ltp":1.02,"tv":3.08,"id":7698577,"hc":14.5}],"tv":6.2}]}
{"op":"mcm","clk":"998166701","pt":1580585344875,"mc":[{"id":"1.168081860","rc":[{"trd":[[1.02,3.1]],"batb":[[0,1.02,6.92]],"batl":[[0,990,0.01]],"ltp":1.02,"tv":3.1,"id":7698577,"hc":14.5}],"tv":6.21}]}
{"op":"mcm","clk":"998169119","pt":1580585360614,"mc":[{"id":"1.168081860","rc":[{"batl":[[0,1000,2.37]],"ltp":1.02,"tv":3.1,"id":7698577,"hc":14.5}]}]}
{"op":"mcm","clk":"998169263","pt":1580585361522,"mc":[{"id":"1.168081860","rc":[{"trd":[[1.02,3.12]],"batb":[[0,1.02,6.91]],"batl":[[0,990,0.01]],"ltp":1.02,"tv":3.11,"id":7698577,"hc":14.5}],"tv":6.23}]}
{"op":"mcm","clk":"998169427","pt":1580585362490,"mc":[{"id":"1.168081860","rc":[{"trd":[[1.02,3.13]],"batb":[[0,1.02,6.9]],"ltp":1.02,"tv":3.13,"id":7698577,"hc":13.5}],"tv":6.24}]}
{"op":"mcm","clk":"998172102","pt":1580585378654,"mc":[{"id":"1.168081860","rc":[{"trd":[[1.02,3.13]],"batb":[[0,1.02,6.9]],"ltp":1.02,"tv":3.13,"id":7698577,"hc":14.5}],"tv":6.26}]}
{"op":"mcm","clk":"998172118","pt":1580585378729,"mc":[{"id":"1.168081860","rc":[{"trd":[[1.02,3.15]],"batb":[[0,1.02,6.89]],"ltp":1.02,"tv":3.14,"id":7698577,"hc":13.5}],"tv":6.28}]}
{"op":"mcm","clk":"998174526","pt":1580585393654,"mc":[{"id":"1.168081860","rc":[{"batl":[[0,1000,0.02]],"ltp":1.02,"tv":3.13,"id":7698577,"hc":14.5}]}]}
{"op":"mcm","clk":"998174686","pt":1580585394636,"mc":[{"id":"1.168081860","rc":[{"batl":[[0,1000,2.37]],"ltp":1.02,"tv":3.14,"id":7698577,"hc":13.5},{"trd":[[1.02,3.15]],"batb":[[0,1.02,6.89]],"batl":[[0,990,0.01]],"ltp":1.02,"tv":3.14,"id":7698577,"hc":14.5}],"tv":6.29}]}
{"op":"mcm","clk":"998174796","pt":1580585395383,"mc":[{"id":"1.168081860","rc":[{"trd":[[1.02,3.16]],"batb":[[0,1.02,6.88]],"batl":[[0,990,0.01]],"ltp":1.02,"tv":3.16,"id":7698577,"hc":13.5}],"tv":6.31}]}
{"op":"mcm","clk":"998177552","pt":1580585410484,"mc":[{"id":"1.168081860","rc":[{"batl":[[0,1000,0.02]],"ltp":1.02,"tv":3.14,"id":7698577,"hc":14.5}]}]}
{"op":"mcm","clk":"998177733","pt":1580585411463,"mc":[{"id":"1.168081860","rc":[{"batl":[[0,1000,0.02]],"ltp":1.02,"tv":3.16,"id":7698577,"hc":13.5},{"trd":[[1.02,3.16]],"batb":[[0,1.02,6.88]],"batl":[[0,990,0.01]],"ltp":1.02,"tv":3.16,"id":7698577,"hc":14.5}],"tv":6.32}]}
{"op":"mcm","clk":"998177966","pt":1580585412860,"mc":[{"id":"1.168081860","rc":[{"trd":[[1.02,3.18]],"batb":[[0,1.02,6.87]],"batl":[[0,990,0.01]],"ltp":1.02,"tv":3.17,"id":7698577,"hc":13.5}],"tv":6.34}]}
{"op":"mcm","clk":"998180481","pt":1580585427502,"mc":[{"id":"1.168081860","rc":[{"trd":[[1.02,3.18]],"batb":[[0,1.02,6.87]],"ltp":1.02,"tv":3.17,"id":7698577,"hc":14.5}],"tv":6.35}]}
{"op":"mcm","clk":"998180685","pt":1580585428573,"mc":[{"id":"1.168081860","rc":[{"batl":[[0,1000,2.37]],"ltp":1.02,"tv":3.17,"id":7698577,"hc":13.5}]}]}
{"op":"mcm","clk":"998180783","pt":1580585429162,"mc":[{"id":"1.168081860","rc":[{"trd":[[1.02,3.19]],"batb":[[0,1.02,6.86]],"batl":[[0,990,0.01]],"ltp":1.02,"tv":3.19,"id":7698577,"hc":13.5}],"tv":6.37}]}
{"op":"mcm","clk":"998183700","pt":1580585445437,"mc":[{"id":"1.168081860","rc":[{"trd":[[1.02,3.19]],"batb":[[0,1.02,6.86]],"ltp":1.02,"tv":3.19,"id":7698577,"hc":14.5}],"tv":6.38}]}
{"op":"mcm","clk":"998183927","pt":1580585446636,"mc":[{"id":"1.168081860","rc":[{"trd":[[1.02,3.21]],"batb":[[0,1.02,6.85]],"ltp":1.02,"tv":3.21,"id":7698577,"hc":13.5}],"tv":6.4}]}
{"op":"mcm","clk":"998186597","pt":1580585461502,"mc":[{"id":"1.168081860","rc":[{"batl":[[0,1000,0.02]],"ltp":1.02,"tv":3.19,"id":7698577,"hc":14.5}]}]}
{"op":"mcm","clk":"998186790","pt":1580585462602,"mc":[{"id":"1.168081860","rc":[{"trd":[[1.02,3.23]],"batb":[[0,1.02,6.84]],"ltp":1.02,"tv":3.22,"id":7698577,"hc":13.5},{"trd":[[1.02,3.21]],"batb":[[0,1.02,6.85]],"batl":[[0,990,0.01]],"ltp":1.02,"tv":3.21,"id":7698577,"hc":14.5}],"tv":6.43}]}
{"op":"mcm","clk":"998189974","pt":1580585479493,"mc":[{"id":"1.168081860","rc":[{"batl":[[0,1000,0.02]],"ltp":1.02,"tv":3.22,"id":7698577,"hc":13.5},{"trd":[[1.02,3.23]],"batb":[[0,1.02,6.84]],"ltp":1.02,"tv":3.22,"id":7698577,"hc":14.5}],"tv":6.45}]}
{"op":"mcm","clk":"998190054","pt":1580585479919,"mc":[{"id":"1.168081860","rc":[{"trd":[[1.02,3.24]],"batb":[[0,1.02,6.83]],"batl":[[0,990,0.01]],"ltp":1.02,"tv":3.24,"id":7698577,"hc":13.5}],"tv":6.46}]}
{"op":"mcm","clk":"998192852","pt":1580585495393,"mc":[{"id":"1.168081860","rc":[{"trd":[[1.02,3.24]],"batb":[[0,1.02,6.83]],"ltp":1.02,"tv":3.24,"id":7698577,"hc":14.5}],"tv":6.48}]}
{"op":"mcm","clk":"998193110","pt":1580585496500,"mc":[{"id":"1.168081860","rc":[{"batl":[[0,1000,0.02]],"ltp":1.02,"tv":3.24,"id":7698577,"hc":13.5}]}]}
{"op":"mcm","clk":"998193178","pt":1580585496798,"mc":[{"id":"1.168081860","rc":[{"trd":[[1.02,3.26]],"batb":[[0,1.02,6.82]],"batl":[[0,990,0.01]],"ltp":1.02,"tv":3.25,"id":7698577,"hc":13.5}],"tv":6.49}]}
{"op":"mcm","clk":"998196236","pt":1580585513630,"mc":[{"id":"1.168081860","rc":[{"trd":[[1.02,3.26]],"batb":[[0,1.02,6.82]],"ltp":1.02,"tv":3.25,"id":7698577,"hc":14.5}],"tv":6.51}]}
{"op":"mcm","clk":"998196254","pt":1580585513730,"mc":[{"id":"1.168081860","rc":[{"trd":[[1.02,3.27]],"batb":[[0,1.02,6.81]],"ltp":1.02,"tv":3.27,"id":7698577,"hc":13.5}],"tv":6.52}]}
{"op":"mcm","clk":"998199350","pt":1580585529489,"mc":[{"id":"1.168081860","rc":[{"batl":[[0,1000,0.02]],"ltp":1.02,"tv":3.25,"id":7698577,"hc":14.5}]}]}
{"op":"mcm","clk":"998199420","pt":1580585529873,"mc":[{"id":"1.168081860","rc":[{"trd":[[1.02,3.27]],"batb":[[0,1.02,6.81]],"batl":[[0,990,0.01]],"ltp":1.02,"tv":3.27,"id":7698577,"hc":14.5}],"tv":6.54}]}
{"op":"mcm","clk":"998199759","pt":1580585531675,"mc":[{"id":"1.168081860","rc":[{"trd":[[1.02,3.29]],"batb":[[0,1.02,6.8]],"ltp":1.02,"tv":3.28,"id":7698577,"hc":13.5}],"tv":6.55}]}
{"op":"mcm","clk":"998202308","pt":1580585545665,"mc":[{"id":"1.168081860","rc":[{"batl":[[0,1000,0.02]],"ltp":1.02,"tv":3.27,"id":7698577,"hc":14.5}]}]}
{"op":"mcm","clk":"998202373","pt":1580585546017,"mc":[{"id":"1.168081860","rc":[{"trd":[[1.02,3.29]],"batb":[[0,1.02,6.8]],"batl":[[0,990,0.01]],"ltp":1.02,"tv":3.28,"id":7698577,"hc":14.5}],"tv":6.57}]}
{"op":"mcm","clk":"998202667","pt":1580585547590,"mc":[{"id":"1.168081860","rc":[{"batl":[[0,1000,2.37]],"ltp":1.02,"tv":3.28,"id":7698577,"hc":13.5}]}]}
{"op":"mcm","clk":"998202781","pt":1580585548223,"mc":[{"id":"1.168081860","rc":[{"trd":[[1.02,3.3]],"batb":[[0,1.02,6.79]],"batl":[[0,990,0.01]],"ltp":1.02,"tv":3.3,"id":7698577,"hc":13.5}],"tv":6.59}]}
{"op":"mcm","clk":"998205728","pt":1580585563668,"mc":[{"id":"1.168081860","rc":[{"trd":[[1.02,3.3]],"batb":[[0,1.02,6.79]],"ltp":1.02,"tv":3.3,"id":7698577,"hc":14.5}],"tv":6.6}]}
{"op":"mcm","clk":"998205883","pt":1580585564486,"mc":[{"id":"1.168081860","rc":[{"trd":[[1.02,3.32]],"batb":[[0,1.02,6.78]],"ltp":1.02,"tv":3.31,"id":7698577,"hc":13.5}],"tv":6.62}]}
{"op":"mcm","clk":"998208735","pt":1580585580637,"mc":[{"id":"1.168081860","rc":[{"batl":[[0,1000,0.02]],"ltp":1.02,"tv":3.3,"id":7698577,"hc":14.5}]}]}
{"op":"mcm","clk":"998208939","pt":1580585581668,"mc":[{"id":"1.168081860","rc":[{"trd":[[1.02,3.33]],"batb":[[0,1.02,6.77]],"ltp":1.02,"tv":3.33,"id":7698577,"hc":13.5},{"trd":[[1.02,3.32]],"batb":[[0,1.02,6.78]],"batl":[[0,990,0.01]],"ltp":1.02,"tv":3.31,"id":7698577,"hc":14.5}],"tv":6.65}]}
{"op":"mcm","clk":"998211908","pt":1580585597666,"mc":[{"id":"1.168081860","rc":[{"trd":[[1.02,3.35]],"batb":[[0,1.02,6.76]],"ltp":1.02,"tv":3.34,"id":7698577,"hc":13.5},{"batl":[[0,1000,0.02]],"ltp":1.02,"tv":3.31,"id":7698577,"hc":14.5}],"tv":6.66}]}
{"op":"mcm","clk":"998212010","pt":1580585598158,"mc":[{"id":"1.168081860","rc":[{"trd":[[1.02,3.33]],"batb":[[0,1.02,6.77]],"batl":[[0,990,0.01]],"ltp":1.02,"tv":3.33,"id":7698577,"hc":14.5}],"tv":6.68}]}
{"op":"mcm","clk":"998215077","pt":1580585614637,"mc":[{"id":"1.168081860","rc":[{"batl":[[0,1000,0.02]],"ltp":1.02,"tv":3.34,"id":7698577,"hc":13.5}]}]}
{"op":"mcm","clk":"998215167","pt":1580585615037,"mc":[{"id":"1.168081860","rc":[{"trd":[[1.02,3.37]],"batb":[[0,1.02,6.75]],"batl":[[0,990,0.01]],"ltp":1.02,"tv":3.36,"id":7698577,"hc":13.5},{"trd":[[1.02,3.35]],"batb":[[0,1.02,6.76]],"ltp":1.02,"tv":3.34,"id":7698577,"hc":14.5}],"tv":6.71}]}
{"op":"mcm","clk":"998218518","pt":1580585632646,"mc":[{"id":"1.168081860","rc":[{"batl":[[0,1000,2.37]],"ltp":1.02,"tv":3.36,"id":7698577,"hc":13.5},{"trd":[[1.02,3.37]],"batb":[[0,1.02,6.75]],"ltp":1.02,"tv":3.36,"id":7698577,"hc":14.5}],"tv":6.73}]}
{"op":"mcm","clk":"998218593","pt":1580585633055,"mc":[{"id":"1.168081860","rc":[{"trd":[[1.02,3.38]],"batb":[[0,1.02,6.74]],"batl":[[0,990,0.01]],"ltp":1.02,"tv":3.38,"id":7698577,"hc":13.5}],"tv":6.74}]}
{"op":"mcm","clk":"998221568","pt":1580585649481,"mc":[{"id":"1.168081860","rc":[{"trd":[[1.02,3.4]],"batb":[[0,1.02,6.73]],"ltp":1.02,"tv":3.39,"id":7698577,"hc":13.5}],"tv":6.76}]}
{"op":"mcm","clk":"998221746","pt":1580585650500,"mc":[{"id":"1.168081860","rc":[{"batl":[[0,1000,0.02]],"ltp":1.02,"tv":3.36,"id":7698577,"hc":14.5}]}]}
{"op":"mcm","clk":"998221835","pt":1580585650980,"mc":[{"id":"1.168081860","rc":[{"trd":[[1.02,3.38]],"batb":[[0,1.02,6.74]],"batl":[[0,990,0.01]],"ltp":1.02,"tv":3.38,"id":7698577,"hc":14.5}],"tv":6.77}]}
{"op":"mcm","clk":"998224670","pt":1580585666608,"mc":[{"id":"1.168081860","rc":[{"trd":[[1.02,3.41]],"batb":[[0,1.02,6.72]],"ltp":1.02,"tv":3.41,"id":7698577,"hc":13.5},{"batl":[[0,1000,2.37]],"ltp":1.02,"tv":3.38,"id":7698577,"hc":14.5}],"tv":6.79}]}
{"op":"mcm","clk":"998224757","pt":1580585667133,"mc":[{"id":"1.168081860","rc":[{"trd":[[1.02,3.4]],"batb":[[0,1.02,6.73]],"batl":[[0,990,0.01]],"ltp":1.02,"tv":3.39,"id":7698577,"hc":14.5}],"tv":6.8}]}
{"op":"mcm","clk":"998227605","pt":1580585683385,"mc":[{"id":"1.168081860","rc":[{"trd":[[1.02,3.43]],"batb":[[0,1.02,6.71]],"ltp":1.02,"tv":3.42,"id":7698577,"hc":13.5}],"tv":6.82}]}
{"op":"mcm","clk":"998227855","pt":1580585684689,"mc":[{"id":"1.168081860","rc":[{"batl":[[0,1000,0.02]],"ltp":1.02,"tv":3.39,"id":7698577,"hc":14.5}]}]}
{"op":"mcm","clk":"998227930","pt":1580585685066,"mc":[{"id":"1.168081860","rc":[{"trd":[[1.02,3.41]],"batb":[[0,1.02,6.72]],"batl":[[0,990,0.01]],"ltp":1.02,"tv":3.41,"id":7698577,"hc":14.5}],"tv":6.83}]}
{"op":"mcm","clk":"998230472","pt":1580585699477,"mc":[{"id":"1.168081860","rc":[{"trd":[[1.02,3.44]],"batb":[[0,1.02,6.7]],"ltp":1.02,"tv":3.44,"id":7698577,"hc":13.5}],"tv":6.85}]}
{"op":"mcm","clk":"998230658","pt":1580585700495,"mc":[{"id":"1.168081860","rc":[{"batl":[[0,1000,2.37]],"ltp":1.02,"tv":3.41,"id":7698577,"hc":14.5}]}]}
{"op":"mcm","clk":"998230772","pt":1580585701097,"mc":[{"id":"1.168081860","rc":[{"trd":[[1.02,3.43]],"batb":[[0,1.02,6.71]],"batl":[[0,990,0.01]],"ltp":1.02,"tv":3.42,"id":7698577,"hc":14.5}],"tv":6.86}]}
{"op":"mcm","clk":"998233297","pt":1580585715579,"mc":[{"id":"1.168081860","rc":[{"batl":[[0,1000,2.37]],"ltp":1.02,"tv":3.44,"id":7698577,"hc":13.5}]}]}
{"op":"mcm","clk":"998233416","pt":1580585716180,"mc":[{"id":"1.168081860","rc":[{"trd":[[1.02,3.46]],"batb":[[0,1.02,6.69]],"batl":[[0,990,0.01]],"ltp":1.02,"tv":3.45,"id":7698577,"hc":13.5}],"tv":6.88}]}
{"op":"mcm","clk":"998233683","pt":1580585717592,"mc":[{"id":"1.168081860","rc":[{"batl":[[0,1000,0.02]],"ltp":1.02,"tv":3.42,"id":7698577,"hc":14.5}]}]}
{"op":"mcm","clk":"998233752","pt":1580585718007,"mc":[{"id":"1.168081860","rc":[{"trd":[[1.02,3.44]],"batb":[[0,1.02,6.7]],"batl":[[0,990,0.01]],"ltp":1.02,"tv":3.44,"id":7698577,"hc":14.5}],"tv":6.9}]}
{"op":"mcm","clk":"998236258","pt":1580585732634,"mc":[{"id":"1.168081860","rc":[{"batl":[[0,1000,2.37]],"ltp":1.02,"tv":3.45,"id":7698577,"hc":13.5}]}]}
{"op":"mcm","clk":"998236401","pt":1580585733333,"mc":[{"id":"1.168081860","rc":[{"trd":[[1.02,3.47]],"batb":[[0,1.02,6.68]],"batl":[[0,990,0.01]],"ltp":1.02,"tv":3.47,"id":7698577,"hc":13.5}],"tv":6.91}]}
{"op":"mcm","clk":"998236846","pt":1580585735610,"mc":[{"id":"1.168081860","rc":[{"batl":[[0,1000,0.02]],"ltp":1.02,"tv":3.44,"id":7698577,"hc":14.5}]}]}
{"op":"mcm","clk":"998236928","pt":1580585736053,"mc":[{"id":"1.168081860","rc":[{"trd":[[1.02,3.46]],"batb":[[0,1.02,6.69]],"batl":[[0,990,0.01]],"ltp":1.02,"tv":3.45,"id":7698577,"hc":14.5}],"tv":6.93}]}
{"op":"mcm","clk":"998239532","pt":1580585750569,"mc":[{"id":"1.168081860","rc":[{"batl":[[0,1000,0.02]],"ltp":1.02,"tv":3.47,"id":7698577,"hc":13.5}]}]}
{"op":"mcm","clk":"998239606","pt":1580585750955,"mc":[{"id":"1.168081860","rc":[{"trd":[[1.02,3.49]],"batb":[[0,1.02,6.67]],"batl":[[0,990,0.01]],"ltp":1.02,"tv":3.48,"id":7698577,"hc":13.5}],"tv":6.94}]}
{"op":"mcm","clk":"998240131","pt":1580585753666,"mc":[{"id":"1.168081860","rc":[{"batl":[[0,1000,2.37]],"ltp":1.02,"tv":3.45,"id":7698577,"hc":14.5}]}]}
{"op":"mcm","clk":"998240231","pt":1580585754262,"mc":[{"id":"1.168081860","rc":[{"trd":[[1.02,3.47]],"batb":[[0,1.02,6.68]],"batl":[[0,990,0.01]],"ltp":1.02,"tv":3.47,"id":7698577,"hc":14.5}],"tv":6.96}]}
{"op":"mcm","clk":"998242585","pt":1580585768243,"mc":[{"id":"1.168081860","rc":[{"trd":[[1.02,3.5]],"batb":[[0,1.02,6.66]],"ltp":1.02,"tv":3.5,"id":7698577,"hc":13.5}],"tv":6.97}]}
{"op":"mcm","clk":"998243012","pt":1580585770661,"mc":[{"id":"1.168081860","rc":[{"batl":[[0,1000,0.02]],"ltp":1.02,"tv":3.47,"id":7698577,"hc":14.5}]}]}
{"op":"mcm","clk":"998243117","pt":1580585771247,"mc":[{"id":"1.168081860","rc":[{"trd":[[1.02,3.49]],"batb":[[0,1.02,6.67]],"batl":[[0,990,0.01]],"ltp":1.02,"tv":3.48,"id":7698577,"hc":14.5}],"tv":6.99}]}
{"op":"mcm","clk":"998245481","pt":1580585785366,"mc":[{"id":"1.168081860","rc":[{"trd":[[1.02,3.52]],"batb":[[0,1.02,6.65]],"ltp":1.02,"tv":3.52,"id":7698577,"hc":13.5}],"tv":7.0}]}
{"op":"mcm","clk":"998246016","pt":1580585788489,"mc":[{"id":"1.168081860","rc":[{"trd":[[1.02,3.5]],"batb":[[0,1.02,6.66]],"ltp":1.02,"tv":3.5,"id":7698577,"hc":14.5}],"tv":7.02}]}
{"op":"mcm","clk":"998248420","pt":1580585802418,"mc":[{"id":"1.168081860","rc":[{"trd":[[1.02,3.54]],"batb":[[0,1.02,6.64]],"ltp":1.02,"tv":3.53,"id":7698577,"hc":13.5}],"tv":7.04}]}
{"op":"mcm","clk":"998248789","pt":1580585804624,"mc":[{"id":"1.168081860","rc":[{"batl":[[0,1000,2.37]],"ltp":1.02,"tv":3.5,"id":7698577,"hc":14.5}]}]}
{"op":"mcm","clk":"998248898","pt":1580585805221,"mc":[{"id":"1.168081860","rc":[{"trd":[[1.02,3.52]],"batb":[[0,1.02,6.65]],"batl":[[0,990,0.01]],"ltp":1.02,"tv":3.52,"id":7698577,"hc":14.5}],"tv":7.05}]}
{"op":"mcm","clk":"998251294","pt":1580585818733,"mc":[{"id":"1.168081860","rc":[{"trd":[[1.02,3.55]],"batb":[[0,1.02,6.63]],"ltp":1.02,"tv":3.55,"id":7698577,"hc":13.5}],"tv":7.07}]}
{"op":"mcm","clk":"998251794","pt":1580585821747,"mc":[{"id":"1.168081860","rc":[{"trd":[[1.02,3.54]],"batb":[[0,1.02,6.64]],"ltp":1.02,"tv":3.53,"id":7698577,"hc":14.5}],"tv":7.08}]}
{"op":"mcm","clk":"998254321","pt":1580585836729,"mc":[{"id":"1.168081860","rc":[{"trd":[[1.02,3.57]],"batb":[[0,1.02,6.62]],"ltp":1.02,"tv":3.56,"id":7698577,"hc":13.5}],"tv":7.1}]}
{"op":"mcm","clk":"998254639","pt":1580585838390,"mc":[{"id":"1.168081860","rc":[{"batl":[[0,1000,0.02]],"ltp":1.02,"tv":3.53,"id":7698577,"hc":14.5}]}]}
{"op":"mcm","clk":"998254710","pt":1580585838815,"mc":[{"id":"1.168081860","rc":[{"trd":[[1.02,3.55]],"batb":[[0,1.02,6.63]],"batl":[[0,990,0.01]],"ltp":1.02,"tv":3.55,"id":7698577,"hc":14.5}],"tv":7.11}]}
{"op":"mcm","clk":"998257296","pt":1580585854556,"mc":[{"id":"1.168081860","rc":[{"trd":[[1.02,3.58]],"batb":[[0,1.02,6.61]],"ltp":1.02,"tv":3.58,"id":7698577,"hc":13.5}],"tv":7.13}]}
{"op":"mcm","clk":"998257475","pt":1580585855531,"mc":[{"id":"1.168081860","rc":[{"batl":[[0,1000,0.02]],"ltp":1.02,"tv":3.55,"id":7698577,"hc":14.5}]}]}
{"op":"mcm","clk":"998257549","pt":1580585855945,"mc":[{"id":"1.168081860","rc":[{"trd":[[1.02,3.57]],"batb":[[0,1.02,6.62]],"batl":[[0,990,0.01]],"ltp":1.02,"tv":3.56,"id":7698577,"hc":14.5}],"tv":7.14}]}
{"op":"mcm","clk":"998260294","pt":1580585871461,"mc":[{"id":"1.168081860","rc":[{"batl":[[0,1000,0.02]],"ltp":1.02,"tv":3.58,"id":7698577,"hc":13.5}]}]}
{"op":"mcm","clk":"998260516","pt":1580585872647,"mc":[{"id":"1.168081860","rc":[{"trd":[[1.02,3.6]],"batb":[[0,1.02,6.6]],"batl":[[0,990,0.01]],"ltp":1.02,"tv":3.59,"id":7698577,"hc":13.5},{"batl":[[0,1000,0.02]],"ltp":1.02,"tv":3.56,"id":7698577,"hc":14.5}],"tv":7.16}]}
{"op":"mcm","clk":"998260621","pt":1580585873300,"mc":[{"id":"1.168081860","rc":[{"trd":[[1.02,3.58]],"batb":[[0,1.02,6.61]],"batl":[[0,990,0.01]],"ltp":1.02,"tv":3.58,"id":7698577,"hc":14.5}],"tv":7.18}]}
{"op":"mcm","clk":"998263358","pt":1580585888394,"mc":[{"id":"1.168081860","rc":[{"batl":[[0,1000,0.02]],"ltp":1.02,"tv":3.59,"id":7698577,"hc":13.5}]}]}
{"op":"mcm","clk":"998263440","pt":1580585888771,"mc":[{"id":"1.168081860","rc":[{"trd":[[1.02,3.61]],"batb":[[0,1.02,6.59]],"batl":[[0,990,0.01]],"ltp":1.02,"tv":3.61,"id":7698577,"hc":13.5}],"tv":7.19}]}
{"op":"mcm","clk":"998263757","pt":1580585890386,"mc":[{"id":"1.168081860","rc":[{"trd":[[1.02,3.6]],"batb":[[0,1.02,6.6]],"ltp":1.02,"tv":3.59,"id":7698577,"hc":14.5}],"tv":7.21}]}
{"op":"mcm","clk":"998266152","pt":1580585905463,"mc":[{"id":"1.168081860","rc":[{"batl":[[0,1000,0.02]],"ltp":1.02,"tv":3.61,"id":7698577,"hc":13.5}]}]}
{"op":"mcm","clk":"998266231","pt":1580585905886,"mc":[{"id":"1.168081860","rc":[{"trd":[[1.02,3.63]],"batb":[[0,1.02,6.58]],"batl":[[0,990,0.01]],"ltp":1.02,"tv":3.62,"id":7698577,"hc":13.5}],"tv":7.22}]}
{"op":"mcm","clk":"998266534","pt":1580585907654,"mc":[{"id":"1.168081860","rc":[{"trd":[[1.02,3.61]],"batb":[[0,1.02,6.59]],"ltp":1.02,"tv":3.61,"id":7698577,"hc":14.5}],"tv":7.24}]}
{"op":"mcm","clk":"998269044","pt":1580585923399,"mc":[{"id":"1.168081860","rc":[{"trd":[[1.02,3.64]],"batb":[[0,1.02,6.57]],"ltp":1.02,"tv":3.64,"id":7698577,"hc":13.5}],"tv":7.25}]}
{"op":"mcm","clk":"998269384","pt":1580585925507,"mc":[{"id":"1.168081860","rc":[{"trd":[[1.02,3.63]],"batb":[[0,1.02,6.58]],"ltp":1.02,"tv":3.62,"id":7698577,"hc":14.5}],"tv":7.27}]}
{"op":"mcm","clk":"998271754","pt":1580585940479,"mc":[{"id":"1.168081860","rc":[{"trd":[[1.02,3.66]],"batb":[[0,1.02,6.56]],"ltp":1.02,"tv":3.65,"id":7698577,"hc":13.5}],"tv":7.28}]}
{"op":"mcm","clk":"998271972","pt":1580585941667,"mc":[{"id":"1.168081860","rc":[{"batl":[[0,1000,2.37]],"ltp":1.02,"tv":3.62,"id":7698577,"hc":14.5}]}]}
{"op":"mcm","clk":"998272045","pt":1580585942051,"mc":[{"id":"1.168081860","rc":[{"trd":[[1.02,3.64]],"batb":[[0,1.02,6.57]],"batl":[[0,990,0.01]],"ltp":1.02,"tv":3.64,"id":7698577,"hc":14.5}],"tv":7.3}]}
{"op":"mcm","clk":"998274797","pt":1580585957779,"mc":[{"id":"1.168081860","rc":[{"trd":[[1.02,3.68]],"batb":[[0,1.02,6.55]],"ltp":1.02,"tv":3.67,"id":7698577,"hc":13.5}],"tv":7.31}]}
{"op":"mcm","clk":"998275165","pt":1580585959665,"mc":[{"id":"1.168081860","rc":[{"batl":[[0,1000,0.02]],"ltp":1.02,"tv":3.64,"id":7698577,"hc":14.5}]}]}
{"op":"mcm","clk":"998275257","pt":1580585960209,"mc":[{"id":"1.168081860","rc":[{"trd":[[1.02,3.66]],"batb":[[0,1.02,6.56]],"batl":[[0,990,0.01]],"ltp":1.02,"tv":3.65,"id":7698577,"hc":14.5}],"tv":7.33}]}
{"op":"mcm","clk":"998277531","pt":1580585973661,"mc":[{"id":"1.168081860","rc":[{"batl":[[0,1000,0.02]],"ltp":1.02,"tv":3.67,"id":7698577,"hc":13.5}]}]}
{"op":"mcm","clk":"998277603","pt":1580585974079,"mc":[{"id":"1.168081860","rc":[{"trd":[[1.02,3.69]],"batb":[[0,1.02,6.54]],"batl":[[0,990,0.01]],"ltp":1.02,"tv":3.69,"id":7698577,"hc":13.5}],"tv":7.35}]}
{"op":"mcm","clk":"998278239","pt":1580585977904,"mc":[{"id":"1.168081860","rc":[{"trd":[[1.02,3.68]],"batb":[[0,1.02,6.55]],"ltp":1.02,"tv":3.67,"id":7698577,"hc":14.5}],"tv":7.36}]}
{"op":"mcm","clk":"998280494","pt":1580585991424,"mc":[{"id":"1.168081860","rc":[{"trd":[[1.02,3.71]],"batb":[[0,1.02,6.53]],"ltp":1.02,"tv":3.7,"id":7698577,"hc":13.5}],"tv":7.38}]}
{"op":"mcm","clk":"998281075","pt":1580585994607,"mc":[{"id":"1.168081860","rc":[{"batl":[[0,1000,2.37]],"ltp":1.02,"tv":3.67,"id":7698577,"hc":14.5}]}]}
{"op":"mcm","clk":"998281240","pt":1580585995525,"mc":[{"id":"1.168081860","rc":[{"trd":[[1.02,3.69]],"batb":[[0,1.02,6.54]],"batl":[[0,990,0.01]],"ltp":1.02,"tv":3.69,"id":7698577,"hc":14.5}],"tv":7.39}]}
{"op":"mcm","clk":"998283286","pt":1580586007560,"mc":[{"id":"1.168081860","rc":[{"batl":[[0,1000,2.37]],"ltp":1.02,"tv":3.7,"id":7698577,"hc":13.5}]}]}
{"op":"mcm","clk":"998283383","pt":1580586008152,"mc":[{"id":"1.168081860","rc":[{"trd":[[1.02,3.72]],"batb":[[0,1.02,6.52]],"batl":[[0,990,0.01]],"ltp":1.02,"tv":3.72,"id":7698577,"hc":13.5}],"tv":7.41}]}
{"op":"mcm","clk":"998284152","pt":1580586012638,"mc":[{"id":"1.168081860","rc":[{"batl":[[0,1000,2.37]],"ltp":1.02,"tv":3.69,"id":7698577,"hc":14.5}]}]}
{"op":"mcm","clk":"998284278","pt":1580586013335,"mc":[{"id":"1.168081860","rc":[{"trd":[[1.02,3.71]],"batb":[[0,1.02,6.53]],"batl":[[0,990,0.01]],"ltp":1.02,"tv":3.7,"id":7698577,"hc":14.5}],"tv":7.42}]}
{"op":"mcm","clk":"998286202","pt":1580586024464,"mc":[{"id":"1.168081860","rc":[{"batl":[[0,1000,0.02]],"ltp":1.02,"tv":3.72,"id":7698577,"hc":13.5}]}]}
{"op":"mcm","clk":"998286291","pt":1580586025010,"mc":[{"id":"1.168081860","rc":[{"trd":[[1.02,3.74]],"batb":[[0,1.02,6.51]],"batl":[[0,990,0.01]],"ltp":1.02,"tv":3.73,"id":7698577,"hc":13.5}],"tv":7.44}]}
{"op":"mcm","clk":"998287269","pt":1580586030693,"mc":[{"id":"1.168081860","rc":[{"trd":[[1.02,3.72]],"batb":[[0,1.02,6.52]],"ltp":1.02,"tv":3.72,"id":7698577,"hc":14.5}],"tv":7.45}]}
{"op":"mcm","clk":"998289520","pt":1580586043647,"mc":[{"id":"1.168081860","rc":[{"trd":[[1.02,3.75]],"batb":[[0,1.02,6.5]],"ltp":1.02,"tv":3.75,"id":7698577,"hc":13.5}],"tv":7.47}]}
{"op":"mcm","clk":"998290508","pt":1580586049665,"mc":[{"id":"1.168081860","rc":[{"trd":[[1.02,3.74]],"batb":[[0,1.02,6.51]],"ltp":1.02,"tv":3.73,"id":7698577,"hc":14.5}],"tv":7.49}]}
{"op":"mcm","clk":"998292369","pt":1580586060786,"mc":[{"id":"1.168081860","rc":[{"trd":[[1.02,3.77]],"batb":[[0,1.02,6.49]],"ltp":1.02,"tv":3.76,"id":7698577,"hc":13.5}],"tv":7.5}]}
{"op":"mcm","clk":"998293388","pt":1580586066635,"mc":[{"id":"1.168081860","rc":[{"trd":[[1.02,3.75]],"batb":[[0,1.02,6.5]],"ltp":1.02,"tv":3.75,"id":7698577,"hc":14.5}],"tv":7.52}]}
{"op":"mcm","clk":"998295368","pt":1580586078573,"mc":[{"id":"1.168081860","rc":[{"trd":[[1.02,3.78]],"batb":[[0,1.02,6.48]],"ltp":1.02,"tv":3.78,"id":7698577,"hc":13.5}],"tv":7.53}]}
{"op":"mcm","clk":"998296409","pt":1580586084750,"mc":[{"id":"1.168081860","rc":[{"trd":[[1.02,3.77]],"batb":[[0,1.02,6.49]],"ltp":1.02,"tv":3.76,"id":7698577,"hc":14.5}],"tv":7.55}]}
{"op":"mcm","clk":"998298073","pt":1580586094605,"mc":[{"id":"1.168081860","rc":[{"trd":[[1.02,3.8]],"batb":[[0,1.02,6.47]],"ltp":1.02,"tv":3.79,"id":7698577,"hc":13.5}],"tv":7.56}]}
{"op":"mcm","clk":"998299395","pt":1580586102642,"mc":[{"id":"1.168081860","rc":[{"batl":[[0,1000,0.02]],"ltp":1.02,"tv":3.76,"id":7698577,"hc":14.5}]}]}
{"op":"mcm","clk":"998299457","pt":1580586103023,"mc":[{"id":"1.168081860","rc":[{"trd":[[1.02,3.78]],"batb":[[0,1.02,6.48]],"batl":[[0,990,0.01]],"ltp":1.02,"tv":3.78,"id":7698577,"hc":14.5}],"tv":7.58}]}
{"op":"mcm","clk":"998300963","pt":1580586112570,"mc":[{"id":"1.168081860","rc":[{"trd":[[1.02,3.81]],"batb":[[0,1.02,6.46]],"ltp":1.02,"tv":3.81,"id":7698577,"hc":13.5}],"tv":7.59}]}
{"op":"mcm","clk":"998302262","pt":1580586120237,"mc":[{"id":"1.168081860","rc":[{"trd":[[1.02,3.8]],"batb":[[0,1.02,6.47]],"ltp":1.02,"tv":3.79,"id":7698577,"hc":14.5}],"tv":7.61}]}
{"op":"mcm","clk":"998303879","pt":1580586129480,"mc":[{"id":"1.168081860","rc":[{"trd":[[1.02,3.83]],"batb":[[0,1.02,6.45]],"ltp":1.02,"tv":3.83,"id":7698577,"hc":13.5}],"tv":7.62}]}
{"op":"mcm","clk":"998305456","pt":1580586138699,"mc":[{"id":"1.168081860","rc":[{"batl":[[0,1000,0.02]],"ltp":1.02,"tv":3.79,"id":7698577,"hc":14.5}]}]}
{"op":"mcm","clk":"998305513","pt":1580586138985,"mc":[{"id":"1.168081860","rc":[{"trd":[[1.02,3.81]],"batb":[[0,1.02,6.46]],"batl":[[0,990,0.01]],"ltp":1.02,"tv":3.81,"id":7698577,"hc":14.5}],"tv":7.64}]}
{"op":"mcm","clk":"998306776","pt":1580586146492,"mc":[{"id":"1.168081860","rc":[{"batl":[[0,1000,0.02]],"ltp":1.02,"tv":3.83,"id":7698577,"hc":13.5}]}]}
{"op":"mcm","clk":"998306839","pt":1580586146814,"mc":[{"id":"1.168081860","rc":[{"trd":[[1.02,3.85]],"batb":[[0,1.02,6.44]],"batl":[[0,990,0.01]],"ltp":1.02,"tv":3.84,"id":7698577,"hc":13.5}],"tv":7.66}]}
{"op":"mcm","clk":"998308504","pt":1580586156576,"mc":[{"id":"1.168081860","rc":[{"trd":[[1.02,3.83]],"batb":[[0,1.02,6.45]],"ltp":1.02,"tv":3.83,"id":7698577,"hc":14.5}],"tv":7.67}]}
{"op":"mcm","clk":"998309753","pt":1580586164508,"mc":[{"id":"1.168081860","rc":[{"batl":[[0,1000,2.37]],"ltp":1.02,"tv":3.84,"id":7698577,"hc":13.5}]}]}
{"op":"mcm","clk":"998309851","pt":1580586165119,"mc":[{"id":"1.168081860","rc":[{"trd":[[1.02,3.86]],"batb":[[0,1.02,6.43]],"batl":[[0,990,0.01]],"ltp":1.02,"tv":3.86,"id":7698577,"hc":13.5}],"tv":7.69}]}
{"op":"mcm","clk":"998311121","pt":1580586172542,"mc":[{"id":"1.168081860","rc":[{"batl":[[0,1000,0.02]],"ltp":1.02,"tv":3.83,"id":7698577,"hc":14.5}]}]}
{"op":"mcm","clk":"998311241","pt":1580586173120,"mc":[{"id":"1.168081860","rc":[{"trd":[[1.02,3.85]],"batb":[[0,1.02,6.44]],"batl":[[0,990,0.01]],"ltp":1.02,"tv":3.84,"id":7698577,"hc":14.5}],"tv":7.7}]}
{"op":"mcm","clk":"998312631","pt":1580586181464,"mc":[{"id":"1.168081860","rc":[{"trd":[[1.02,3.88]],"batb":[[0,1.02,6.42]],"ltp":1.02,"tv":3.87,"id":7698577,"hc":13.5}],"tv":7.72}]}
{"op":"mcm","clk":"998314392","pt":1580586190582,"mc":[{"id":"1.168081860","rc":[{"trd":[[1.02,3.86]],"batb":[[0,1.02,6.43]],"ltp":1.02,"tv":3.86,"id":7698577,"hc":14.5}],"tv":7.73}]}
{"op":"mcm","clk":"998315828","pt":1580586198777,"mc":[{"id":"1.168081860","rc":[{"trd":[[1.02,3.89]],"batb":[[0,1.02,6.41]],"ltp":1.02,"tv":3.89,"id":7698577,"hc":13.5}],"tv":7.75}]}
{"op":"mcm","clk":"998317307","pt":1580586206694,"mc":[{"id":"1.168081860","rc":[{"batl":[[0,1000,2.37]],"ltp":1.02,"tv":3.86,"id":7698577,"hc":14.5}]}]}
{"op":"mcm","clk":"998317436","pt":1580586207504,"mc":[{"id":"1.168081860","rc":[{"trd":[[1.02,3.88]],"batb":[[0,1.02,6.42]],"batl":[[0,990,0.01]],"ltp":1.02,"tv":3.87,"id":7698577,"hc":14.5}],"tv":7.76}]}
{"op":"mcm","clk":"998318817","pt":1580586215660,"mc":[{"id":"1.168081860","rc":[{"batl":[[0,1000,2.37]],"ltp":1.02,"tv":3.89,"id":7698577,"hc":13.5}]}]}
{"op":"mcm","clk":"998318955","pt":1580586216420,"mc":[{"id":"1.168081860","rc":[{"trd":[[1.02,3.91]],"batb":[[0,1.02,6.4]],"batl":[[0,990,0.01]],"ltp":1.02,"tv":3.9,"id":7698577,"hc":13.5}],"tv":7.78}]}
{"op":"mcm","clk":"998320316","pt":1580586224675,"mc":[{"id":"1.168081860","rc":[{"trd":[[1.02,3.89]],"batb":[[0,1.02,6.41]],"ltp":1.02,"tv":3.89,"id":7698577,"hc":14.5}],"tv":7.8}]}
{"op":"mcm","clk":"998321787","pt":1580586233671,"mc":[{"id":"1.168081860","rc":[{"batl":[[0,1000,0.02]],"ltp":1.02,"tv":3.9,"id":7698577,"hc":13.5}]}]}
{"op":"mcm","clk":"998321977","pt":1580586234692,"mc":[{"id":"1.168081860","rc":[{"trd":[[1.02,3.92]],"batb":[[0,1.02,6.39]],"batl":[[0,990,0.01]],"ltp":1.02,"tv":3.92,"id":7698577,"hc":13.5}],"tv":7.81}]}
{"op":"mcm","clk":"998323363","pt":1580586242629,"mc":[{"id":"1.168081860","rc":[{"batl":[[0,1000,2.37]],"ltp":1.02,"tv":3.89,"id":7698577,"hc":14.5}]}]}
{"op":"mcm","clk":"998323491","pt":1580586243329,"mc":[{"id":"1.168081860","rc":[{"trd":[[1.02,3.91]],"batb":[[0,1.02,6.4]],"batl":[[0,990,0.01]],"ltp":1.02,"tv":3.9,"id":7698577,"hc":14.5}],"tv":7.83}]}
{"op":"mcm","clk":"998324805","pt":1580586251457,"mc":[{"id":"1.168081860","rc":[{"trd":[[1.02,3.94]],"batb":[[0,1.02,6.38]],"ltp":1.02,"tv":3.93,"id":7698577,"hc":13.5}],"tv":7.84}]}
{"op":"mcm","clk":"998326578","pt":1580586261564,"mc":[{"id":"1.168081860","rc":[{"trd":[[1.02,3.92]],"batb":[[0,1.02,6.39]],"ltp":1.02,"tv":3.92,"id":7698577,"hc":14.5}],"tv":7.86}]}
{"op":"mcm","clk":"998327921","pt":1580586269680,"mc":[{"id":"1.168081860","rc":[{"batl":[[0,1000,2.37]],"ltp":1.02,"tv":3.93,"id":7698577,"hc":13.5}]}]}
{"op":"mcm","clk":"998328005","pt":1580586270264,"mc":[{"id":"1.168081860","rc":[{"trd":[[1.02,3.95]],"batb":[[0,1.02,6.37]],"batl":[[0,990,0.01]],"ltp":1.02,"tv":3.95,"id":7698577,"hc":13.5}],"tv":7.87}]}
{"op":"mcm","clk":"998329446","pt":1580586278626,"mc":[{"id":"1.168081860","rc":[{"batl":[[0,1000,0.02]],"ltp":1.02,"tv":3.92,"id":7698577,"hc":14.5}]}]}
{"op":"mcm","clk":"998329556","pt":1580586279228,"mc":[{"id":"1.168081860","rc":[{"trd":[[1.02,3.94]],"batb":[[0,1.02,6.38]],"batl":[[0,990,0.01]],"ltp":1.02,"tv":3.93,"id":7698577,"hc":14.5}],"tv":7.89}]}
{"op":"mcm","clk":"998330826","pt":1580586287543,"mc":[{"id":"1.168081860","rc":[{"batl":[[0,1000,2.37]],"ltp":1.02,"tv":3.95,"id":7698577,"hc":13.5}]}]}
{"op":"mcm","clk":"998330919","pt":1580586288139,"mc":[{"id":"1.168081860","rc":[{"trd":[[1.02,3.97]],"batb":[[0,1.02,6.36]],"batl":[[0,990,0.01]],"ltp":1.02,"tv":3.96,"id":7698577,"hc":13.5}],"tv":7.9}]}
{"op":"mcm","clk":"998332156","pt":1580586295689,"mc":[{"id":"1.168081860","rc":[{"batl":[[0,1000,2.37]],"ltp":1.02,"tv":3.93,"id":7698577,"hc":14.5}]}]}
{"op":"mcm","clk":"998332258","pt":1580586296282,"mc":[{"id":"1.168081860","rc":[{"trd":[[1.02,3.95]],"batb":[[0,1.02,6.37]],"batl":[[0,990,0.01]],"ltp":1.02,"tv":3.95,"id":7698577,"hc":14.5}],"tv":7.92}]}
{"op":"mcm","clk":"998333545","pt":1580586304406,"mc":[{"id":"1.168081860","rc":[{"trd":[[1.02,3.99]],"batb":[[0,1.02,6.35]],"ltp":1.02,"tv":3.98,"id":7698577,"hc":13.5}],"tv":7.93}]}
{"op":"mcm","clk":"998334911","pt":1580586312694,"mc":[{"id":"1.168081860","rc":[{"batl":[[0,1000,2.37]],"ltp":1.02,"tv":3.95,"id":7698577,"hc":14.5}]}]}
{"op":"mcm","clk":"998335066","pt":1580586313572,"mc":[{"id":"1.168081860","rc":[{"trd":[[1.02,3.97]],"batb":[[0,1.02,6.36]],"batl":[[0,990,0.01]],"ltp":1.02,"tv":3.96,"id":7698577,"hc":14.5}],"tv":7.95}]}
{"op":"mcm","clk":"998336410","pt":1580586321592,"mc":[{"id":"1.168081860","rc":[{"trd":[[1.02,4]],"batb":[[0,1.02,6.34]],"ltp":1.02,"tv":4.0,"id":7698577,"hc":13.5}],"tv":7.97}]}
{"op":"mcm","clk":"998337898","pt":1580586330573,"mc":[{"id":"1.168081860","rc":[{"batl":[[0,1000,0.02]],"ltp":1.02,"tv":3.96,"id":7698577,"hc":14.5}]}]}
{"op":"mcm","clk":"998337997","pt":1580586331158,"mc":[{"id":"1.168081860","rc":[{"trd":[[1.02,3.99]],"batb":[[0,1.02,6.35]],"batl":[[0,990,0.01]],"ltp":1.02,"tv":3.98,"id":7698577,"hc":14.5}],"tv":7.98}]}
{"op":"mcm","clk":"998339356","pt":1580586339493,"mc":[{"id":"1.168081860","rc":[{"batl":[[0,1000,0.02]],"ltp":1.02,"tv":4.0,"id":7698577,"hc":13.5}]}]}
{"op":"mcm","clk":"998339424","pt":1580586339895,"mc":[{"id":"1.168081860","rc":[{"trd":[[1.02,4.02]],"batb":[[0,1.02,6.33]],"batl":[[0,990,0.01]],"ltp":1.02,"tv":4.01,"id":7698577,"hc":13.5}],"tv":8.0}]}
{"op":"mcm","clk":"998340675","pt":1580586347574,"mc":[{"id":"1.168081860","rc":[{"trd":[[1.02,4]],"batb":[[0,1.02,6.34]],"ltp":1.02,"tv":4.0,"id":7698577,"hc":14.5}],"tv":8.01}]}
{"op":"mcm","clk":"998342066","pt":1580586356552,"mc":[{"id":"1.168081860","rc":[{"trd":[[1.02,4.03]],"batb":[[0,1.02,6.32]],"ltp":1.02,"tv":4.03,"id":7698577,"hc":13.5}],"tv":8.03}]}
{"op":"mcm","clk":"998343417","pt":1580586364549,"mc":[{"id":"1.168081860","rc":[{"batl":[[0,1000,0.02]],"ltp":1.02,"tv":4.0,"id":7698577,"hc":14.5}]}]}
{"op":"mcm","clk":"998343482","pt":1580586364928,"mc":[{"id":"1.168081860","rc":[{"trd":[[1.02,4.02]],"batb":[[0,1.02,6.33]],"batl":[[0,990,0.01]],"ltp":1.02,"tv":4.01,"id":7698577,"hc":14.5}],"tv":8.04}]}
{"op":"mcm","clk":"998344913","pt":1580586373991,"mc":[{"id":"1.168081860","rc":[{"trd":[[1.02,4.05]],"batb":[[0,1.02,6.31]],"ltp":1.02,"tv":4.04,"id":7698577,"hc":13.5}],"tv":8.06}]}
{"op":"mcm","clk":"998346093","pt":1580586381570,"mc":[{"id":"1.168081860","rc":[{"trd":[[1.02,4.03]],"batb":[[0,1.02,6.32]],"ltp":1.02,"tv":4.03,"id":7698577,"hc":14.5}],"tv":8.07}]}
{"op":"mcm","clk":"998347557","pt":1580586391369,"mc":[{"id":"1.168081860","rc":[{"trd":[[1.02,4.06]],"batb":[[0,1.02,6.3]],"ltp":1.02,"tv":4.06,"id":7698577,"hc":13.5}],"tv":8.09}]}
{"op":"mcm","clk":"998348693","pt":1580586398636,"mc":[{"id":"1.168081860","rc":[{"batl":[[0,1000,2.37]],"ltp":1.02,"tv":4.03,"id":7698577,"hc":14.5}]}]}
{"op":"mcm","clk":"998348807","pt":1580586399318,"mc":[{"id":"1.168081860","rc":[{"trd":[[1.02,4.05]],"batb":[[0,1.02,6.31]],"batl":[[0,990,0.01]],"ltp":1.02,"tv":4.04,"id":7698577,"hc":14.5}],"tv":8.11}]}
{"op":"mcm","clk":"998349819","pt":1580586406625,"mc":[{"id":"1.168081860","rc":[{"batl":[[0,1000,2.37]],"ltp":1.02,"tv":4.06,"id":7698577,"hc":13.5}]}]}
{"op":"mcm","clk":"998349959","pt":1580586407422,"mc":[{"id":"1.168081860","rc":[{"trd":[[1.02,4.08]],"batb":[[0,1.02,6.29]],"batl":[[0,990,0.01]],"ltp":1.02,"tv":4.07,"id":7698577,"hc":13.5}],"tv":8.12}]}
{"op":"mcm","clk":"998351507","pt":1580586417331,"mc":[{"id":"1.168081860","rc":[{"trd":[[1.02,4.06]],"batb":[[0,1.02,6.3]],"ltp":1.02,"tv":4.06,"id":7698577,"hc":14.5}],"tv":8.14}]}
{"op":"mcm","clk":"998352590","pt":1580586424663,"mc":[{"id":"1.168081860","rc":[{"batl":[[0,1000,2.37]],"ltp":1.02,"tv":4.07,"id":7698577,"hc":13.5}]}]}
{"op":"mcm","clk":"998352699","pt":1580586425361,"mc":[{"id":"1.168081860","rc":[{"trd":[[1.02,4.09]],"batb":[[0,1.02,6.28]],"batl":[[0,990,0.01]],"ltp":1.02,"tv":4.09,"id":7698577,"hc":13.5}],"tv":8.15}]}
{"op":"mcm","clk":"998354342","pt":1580586435685,"mc":[{"id":"1.168081860","rc":[{"batl":[[0,1000,0.02]],"ltp":1.02,"tv":4.06,"id":7698577,"hc":14.5}]}]}
{"op":"mcm","clk":"998354423","pt":1580586436060,"mc":[{"id":"1.168081860","rc":[{"trd":[[1.02,4.08]],"batb":[[0,1.02,6.29]],"batl":[[0,990,0.01]],"ltp":1.02,"tv":4.07,"id":7698577,"hc":14.5}],"tv":8.17}]}
{"op":"mcm","clk":"998355570","pt":1580586443650,"mc":[{"id":"1.168081860","rc":[{"batl":[[0,1000,2.37]],"ltp":1.02,"tv":4.09,"id":7698577,"hc":13.5}]}]}
{"op":"mcm","clk":"998355681","pt":1580586444246,"mc":[{"id":"1.168081860","rc":[{"trd":[[1.02,4.11]],"batb":[[0,1.02,6.27]],"batl":[[0,990,0.01]],"ltp":1.02,"tv":4.1,"id":7698577,"hc":13.5}],"tv":8.18}]}
{"op":"mcm","clk":"998357271","pt":1580586454563,"mc":[{"id":"1.168081860","rc":[{"trd":[[1.02,4.09]],"batb":[[0,1.02,6.28]],"ltp":1.02,"tv":4.09,"id":7698577,"hc":14.5}],"tv":8.2}]}
{"op":"mcm","clk":"998358426","pt":1580586462594,"mc":[{"id":"1.168081860","rc":[{"trd":[[1.02,4.13]],"batb":[[0,1.02,6.26]],"ltp":1.02,"tv":4.12,"id":7698577,"hc":13.5}],"tv":8.21}]}
{"op":"mcm","clk":"998360008","pt":1580586472643,"mc":[{"id":"1.168081860","rc":[{"batl":[[0,1000,0.02]],"ltp":1.02,"tv":4.09,"id":7698577,"hc":14.5}]}]}
{"op":"mcm","clk":"998360078","pt":1580586473067,"mc":[{"id":"1.168081860","rc":[{"trd":[[1.02,4.11]],"batb":[[0,1.02,6.27]],"batl":[[0,990,0.01]],"ltp":1.02,"tv":4.1,"id":7698577,"hc":14.5}],"tv":8.23}]}
{"op":"mcm","clk":"998361135","pt":1580586479676,"mc":[{"id":"1.168081860","rc":[{"batl":[[0,1000,2.37]],"ltp":1.02,"tv":4.12,"id":7698577,"hc":13.5}]}]}
{"op":"mcm","clk":"998361242","pt":1580586480263,"mc":[{"id":"1.168081860","rc":[{"trd":[[1.02,4.14]],"batb":[[0,1.02,6.25]],"batl":[[0,990,0.01]],"ltp":1.02,"tv":4.14,"id":7698577,"hc":13.5}],"tv":8.25}]}
{"op":"mcm","clk":"998362747","pt":1580586489656,"mc":[{"id":"1.168081860","rc":[{"trd":[[1.02,4.13]],"batb":[[0,1.02,6.26]],"ltp":1.02,"tv":4.12,"id":7698577,"hc":14.5}],"tv":8.26}]}
{"op":"mcm","clk":"998363930","pt":1580586497611,"mc":[{"id":"1.168081860","rc":[{"batl":[[0,1000,2.37]],"ltp":1.02,"tv":4.14,"id":7698577,"hc":13.5}]}]}
{"op":"mcm","clk":"998364060","pt":1580586498202,"mc":[{"id":"1.168081860","rc":[{"trd":[[1.02,4.16]],"batb":[[0,1.02,6.24]],"batl":[[0,990,0.01]],"ltp":1.02,"tv":4.15,"id":7698577,"hc":13.5}],"tv":8.28}]}
{"op":"mcm","clk":"998365574","pt":1580586507432,"mc":[{"id":"1.168081860","rc":[{"trd":[[1.02,4.14]],"batb":[[0,1.02,6.25]],"ltp":1.02,"tv":4.14,"id":7698577,"hc":14.5}],"tv":8.29}]}
{"op":"mcm","clk":"998366835","pt":1580586515721,"mc":[{"id":"1.168081860","rc":[{"trd":[[1.02,4.17]],"batb":[[0,1.02,6.23]],"ltp":1.02,"tv":4.17,"id":7698577,"hc":13.5}],"tv":8.31}]}
{"op":"mcm","clk":"998368121","pt":1580586523630,"mc":[{"id":"1.168081860","rc":[{"trd":[[1.02,4.16]],"batb":[[0,1.02,6.24]],"ltp":1.02,"tv":4.15,"id":7698577,"hc":14.5}],"tv":8.32}]}
{"op":"mcm","clk":"998369296","pt":1580586531651,"mc":[{"id":"1.168081860","rc":[{"batl":[[0,1000,0.02]],"ltp":1.02,"tv":4.17,"id":7698577,"hc":13.5}]}]}
{"op":"mcm","clk":"998369353","pt":1580586532076,"mc":[{"id":"1.168081860","rc":[{"trd":[[1.02,4.19]],"batb":[[0,1.02,6.22]],"batl":[[0,990,0.01]],"ltp":1.02,"tv":4.18,"id":7698577,"hc":13.5}],"tv":8.34}]}
{"op":"mcm","clk":"998370967","pt":1580586542685,"mc":[{"id":"1.168081860","rc":[{"batl":[[0,1000,2.37]],"ltp":1.02,"tv":4.15,"id":7698577,"hc":14.5}]}]}
{"op":"mcm","clk":"998371083","pt":1580586543377,"mc":[{"id":"1.168081860","rc":[{"trd":[[1.02,4.17]],"batb":[[0,1.02,6.23]],"batl":[[0,990,0.01]],"ltp":1.02,"tv":4.17,"id":7698577,"hc":14.5}],"tv":8.35}]}
{"op":"mcm","clk":"998372017","pt":1580586548663,"mc":[{"id":"1.168081860","rc":[{"batl":[[0,1000,0.02]],"ltp":1.02,"tv":4.18,"id":7698577,"hc":13.5}]}]}
{"op":"mcm","clk":"998372075","pt":1580586549088,"mc":[{"id":"1.168081860","rc":[{"trd":[[1.02,4.2]],"batb":[[0,1.02,6.21]],"batl":[[0,990,0.01]],"ltp":1.02,"tv":4.2,"id":7698577,"hc":13.5}],"tv":8.37}]}
{"op":"mcm","clk":"998374055","pt":1580586561603,"mc":[{"id":"1.168081860","rc":[{"batl":[[0,1000,2.37]],"ltp":1.02,"tv":4.17,"id":7698577,"hc":14.5}]}]}
{"op":"mcm","clk":"998374127","pt":1580586562081,"mc":[{"id":"1.168081860","rc":[{"trd":[[1.02,4.19]],"batb":[[0,1.02,6.22]],"batl":[[0,990,0.01]],"ltp":1.02,"tv":4.18,"id":7698577,"hc":14.5}],"tv":8.38}]}
{"op":"mcm","clk":"998374870","pt":1580586567792,"mc":[{"id":"1.168081860","rc":[{"trd":[[1.02,4.22]],"batb":[[0,1.02,6.2]],"ltp":1.02,"tv":4.21,"id":7698577,"hc":13.5}],"tv":8.4}]}
{"op":"mcm","clk":"998376413","pt":1580586579512,"mc":[{"id":"1.168081860","rc":[{"batl":[[0,1000,0.02]],"ltp":1.02,"tv":4.18,"id":7698577,"hc":14.5}]}]}
{"op":"mcm","clk":"998376477","pt":1580586579935,"mc":[{"id":"1.168081860","rc":[{"trd":[[1.02,4.2]],"batb":[[0,1.02,6.21]],"batl":[[0,990,0.01]],"ltp":1.02,"tv":4.2,"id":7698577,"hc":14.5}],"tv":8.42}]}
{"op":"mcm","clk":"998377100","pt":1580586584701,"mc":[{"id":"1.168081860","rc":[{"trd":[[1.02,4.23]],"batb":[[0,1.02,6.19]],"ltp":1.02,"tv":4.23,"id":7698577,"hc":13.5}],"tv":8.43}]}
{"op":"mcm","clk":"998378642","pt":1580586596427,"mc":[{"id":"1.168081860","rc":[{"trd":[[1.02,4.22]],"batb":[[0,1.02,6.2]],"ltp":1.02,"tv":4.21,"id":7698577,"hc":14.5}],"tv":8.45}]}
{"op":"mcm","clk":"998379532","pt":1580586602668,"mc":[{"id":"1.168081860","rc":[{"trd":[[1.02,4.25]],"batb":[[0,1.02,6.18]],"ltp":1.02,"tv":4.24,"id":7698577,"hc":13.5}],"tv":8.46}]}
{"op":"mcm","clk":"998381183","pt":1580586613492,"mc":[{"id":"1.168081860","rc":[{"batl":[[0,1000,2.37]],"ltp":1.02,"tv":4.21,"id":7698577,"hc":14.5}]}]}
{"op":"mcm","clk":"998381298","pt":1580586614291,"mc":[{"id":"1.168081860","rc":[{"trd":[[1.02,4.23]],"batb":[[0,1.02,6.19]],"batl":[[0,990,0.01]],"ltp":1.02,"tv":4.23,"id":7698577,"hc":14.5}],"tv":8.48}]}
{"op":"mcm","clk":"998382251","pt":1580586620804,"mc":[{"id":"1.168081860","rc":[{"trd":[[1.02,4.26]],"batb":[[0,1.02,6.17]],"ltp":1.02,"tv":4.26,"id":7698577,"hc":13.5}],"tv":8.49}]}
{"op":"mcm","clk":"998383716","pt":1580586630613,"mc":[{"id":"1.168081860","rc":[{"trd":[[1.02,4.25]],"batb":[[0,1.02,6.18]],"ltp":1.02,"tv":4.24,"id":7698577,"hc":14.5}],"tv":8.51}]}
{"op":"mcm","clk":"998384838","pt":1580586638642,"mc":[{"id":"1.168081860","rc":[{"batl":[[0,1000,2.37]],"ltp":1.02,"tv":4.26,"id":7698577,"hc":13.5}]}]}
{"op":"mcm","clk":"998384969","pt":1580586639433,"mc":[{"id":"1.168081860","rc":[{"trd":[[1.02,4.28]],"batb":[[0,1.02,6.16]],"batl":[[0,990,0.01]],"ltp":1.02,"tv":4.28,"id":7698577,"hc":13.5}],"tv":8.52}]}
{"op":"mcm","clk":"998386076","pt":1580586646656,"mc":[{"id":"1.168081860","rc":[{"batl":[[0,1000,2.37]],"ltp":1.02,"tv":4.24,"id":7698577,"hc":14.5}]}]}
{"op":"mcm","clk":"998386209","pt":1580586647517,"mc":[{"id":"1.168081860","rc":[{"trd":[[1.02,4.26]],"batb":[[0,1.02,6.17]],"batl":[[0,990,0.01]],"ltp":1.02,"tv":4.26,"id":7698577,"hc":14.5}],"tv":8.54}]}
{"op":"mcm","clk":"998387237","pt":1580586654657,"mc":[{"id":"1.168081860","rc":[{"batl":[[0,1000,2.37]],"ltp":1.02,"tv":4.28,"id":7698577,"hc":13.5}]}]}
{"op":"mcm","clk":"998387361","pt":1580586655455,"mc":[{"id":"1.168081860","rc":[{"trd":[[1.02,4.3]],"batb":[[0,1.02,6.15]],"batl":[[0,990,0.01]],"ltp":1.02,"tv":4.29,"id":7698577,"hc":13.5}],"tv":8.56}]}
{"op":"mcm","clk":"998389166","pt":1580586667464,"mc":[{"id":"1.168081860","rc":[{"trd":[[1.02,4.28]],"batb":[[0,1.02,6.16]],"ltp":1.02,"tv":4.28,"id":7698577,"hc":14.5}],"tv":8.57}]}
{"op":"mcm","clk":"998390049","pt":1580586673502,"mc":[{"id":"1.168081860","rc":[{"batl":[[0,1000,0.02]],"ltp":1.02,"tv":4.29,"id":7698577,"hc":13.5}]}]}
{"op":"mcm","clk":"998390110","pt":1580586673875,"mc":[{"id":"1.168081860","rc":[{"trd":[[1.02,4.31]],"batb":[[0,1.02,6.14]],"batl":[[0,990,0.01]],"ltp":1.02,"tv":4.31,"id":7698577,"hc":13.5}],"tv":8.59}]}
{"op":"mcm","clk":"998391677","pt":1580586684781,"mc":[{"id":"1.168081860","rc":[{"trd":[[1.02,4.3]],"batb":[[0,1.02,6.15]],"ltp":1.02,"tv":4.29,"id":7698577,"hc":14.5}],"tv":8.6}]}
{"op":"mcm","clk":"998392539","pt":1580586690605,"mc":[{"id":"1.168081860","rc":[{"batl":[[0,1000,2.37]],"ltp":1.02,"tv":4.31,"id":7698577,"hc":13.5}]}]}
{"op":"mcm","clk":"998392635","pt":1580586691191,"mc":[{"id":"1.168081860","rc":[{"trd":[[1.02,4.33]],"batb":[[0,1.02,6.13]],"batl":[[0,990,0.01]],"ltp":1.02,"tv":4.32,"id":7698577,"hc":13.5}],"tv":8.62}]}
{"op":"mcm","clk":"998394215","pt":1580586701655,"mc":[{"id":"1.168081860","rc":[{"batl":[[0,1000,2.37]],"ltp":1.02,"tv":4.29,"id":7698577,"hc":14.5}]}]}
{"op":"mcm","clk":"998394336","pt":1580586702355,"mc":[{"id":"1.168081860","rc":[{"trd":[[1.02,4.31]],"batb":[[0,1.02,6.14]],"batl":[[0,990,0.01]],"ltp":1.02,"tv":4.31,"id":7698577,"hc":14.5}],"tv":8.63}]}
{"op":"mcm","clk":"998395291","pt":1580586708671,"mc":[{"id":"1.168081860","rc":[{"trd":[[1.02,4.34]],"batb":[[0,1.02,6.12]],"ltp":1.02,"tv":4.34,"id":7698577,"hc":13.5}],"tv":8.65}]}
{"op":"mcm","clk":"998396787","pt":1580586718572,"mc":[{"id":"1.168081860","rc":[{"batl":[[0,1000,2.37]],"ltp":1.02,"tv":4.31,"id":7698577,"hc":14.5}]}]}
{"op":"mcm","clk":"998396891","pt":1580586719295,"mc":[{"id":"1.168081860","rc":[{"trd":[[1.02,4.33]],"batb":[[0,1.02,6.13]],"batl":[[0,990,0.01]],"ltp":1.02,"tv":4.32,"id":7698577,"hc":14.5}],"tv":8.66}]}
{"op":"mcm","clk":"998397692","pt":1580586724681,"mc":[{"id":"1.168081860","rc":[{"batl":[[0,1000,2.37]],"ltp":1.02,"tv":4.34,"id":7698577,"hc":13.5}]}]}
{"op":"mcm","clk":"998397791","pt":1580586725399,"mc":[{"id":"1.168081860","rc":[{"trd":[[1.02,4.36]],"batb":[[0,1.02,6.11]],"batl":[[0,990,0.01]],"ltp":1.02,"tv":4.35,"id":7698577,"hc":13.5}],"tv":8.68}]}
{"op":"mcm","clk":"998399132","pt":1580586735622,"mc":[{"id":"1.168081860","rc":[{"batl":[[0,1000,2.37]],"ltp":1.02,"tv":4.32,"id":7698577,"hc":14.5}]}]}
{"op":"mcm","clk":"998399215","pt":1580586736304,"mc":[{"id":"1.168081860","rc":[{"trd":[[1.02,4.34]],"batb":[[0,1.02,6.12]],"batl":[[0,990,0.01]],"ltp":1.02,"tv":4.34,"id":7698577,"hc":14.5}],"tv":8.69}]}
{"op":"mcm","clk":"998400360","pt":1580586746547,"mc":[{"id":"1.168081860","rc":[{"trd":[[1.02,4.37]],"batb":[[0,1.02,6.1]],"ltp":1.02,"tv":4.37,"id":7698577,"hc":13.5}],"tv":8.71}]}
{"op":"mcm","clk":"998400926","pt":1580586751654,"mc":[{"id":"1.168081860","rc":[{"batl":[[0,1000,0.02]],"ltp":1.02,"tv":4.34,"id":7698577,"hc":14.5}]}]}
{"op":"mcm","clk":"998400991","pt":1580586752265,"mc":[{"id":"1.168081860","rc":[{"trd":[[1.02,4.36]],"batb":[[0,1.02,6.11]],"batl":[[0,990,0.01]],"ltp":1.02,"tv":4.35,"id":7698577,"hc":14.5}],"tv":8.73}]}
{"op":"mcm","clk":"998402759","pt":1580586768550,"mc":[{"id":"1.168081860","rc":[{"batl":[[0,1000,2.37]],"ltp":1.02,"tv":4.37,"id":7698577,"hc":13.5},{"batl":[[0,1000,0.02]],"ltp":1.02,"tv":4.35,"id":7698577,"hc":14.5}]}]}
{"op":"mcm","clk":"998402860","pt":1580586769351,"mc":[{"id":"1.168081860","rc":[{"trd":[[1.02,4.39]],"batb":[[0,1.02,6.09]],"batl":[[0,990,0.01]],"ltp":1.02,"tv":4.38,"id":7698577,"hc":13.5},{"trd":[[1.02,4.37]],"batb":[[0,1.02,6.1]],"batl":[[0,990,0.01]],"ltp":1.02,"tv":4.37,"id":7698577,"hc":14.5}],"tv":8.76}]}
{"op":"mcm","clk":"998404762","pt":1580586785871,"mc":[{"id":"1.168081860","rc":[{"trd":[[1.02,4.4]],"batb":[[0,1.02,6.08]],"ltp":1.02,"tv":4.4,"id":7698577,"hc":13.5}],"tv":8.77}]}
{"op":"mcm","clk":"998404964","pt":1580586787457,"mc":[{"id":"1.168081860","rc":[{"batl":[[0,1000,0.02]],"ltp":1.02,"tv":4.37,"id":7698577,"hc":14.5}]}]}
{"op":"mcm","clk":"998405028","pt":1580586788092,"mc":[{"id":"1.168081860","rc":[{"trd":[[1.02,4.39]],"batb":[[0,1.02,6.09]],"batl":[[0,990,0.01]],"ltp":1.02,"tv":4.38,"id":7698577,"hc":14.5}],"tv":8.79}]}
{"op":"mcm","clk":"998406982","pt":1580586803507,"mc":[{"id":"1.168081860","rc":[{"batl":[[0,1000,2.37]],"ltp":1.02,"tv":4.4,"id":7698577,"hc":13.5}]}]}
{"op":"mcm","clk":"998407103","pt":1580586804392,"mc":[{"id":"1.168081860","rc":[{"trd":[[1.02,4.42]],"batb":[[0,1.02,6.07]],"batl":[[0,990,0.01]],"ltp":1.02,"tv":4.41,"id":7698577,"hc":13.5}],"tv":8.8}]}
{"op":"mcm","clk":"998407275","pt":1580586805614,"mc":[{"id":"1.168081860","rc":[{"batl":[[0,1000,2.37]],"ltp":1.02,"tv":4.38,"id":7698577,"hc":14.5}]}]}
{"op":"mcm","clk":"998407362","pt":1580586806291,"mc":[{"id":"1.168081860","rc":[{"trd":[[1.02,4.4]],"batb":[[0,1.02,6.08]],"batl":[[0,990,0.01]],"ltp":1.02,"tv":4.4,"id":7698577,"hc":14.5}],"tv":8.82}]}
{"op":"mcm","clk":"998409313","pt":1580586820673,"mc":[{"id":"1.168081860","rc":[{"trd":[[1.02,4.44]],"batb":[[0,1.02,6.06]],"ltp":1.02,"tv":4.43,"id":7698577,"hc":13.5}],"tv":8.83}]}
{"op":"mcm","clk":"998409555","pt":1580586822682,"mc":[{"id":"1.168081860","rc":[{"trd":[[1.02,4.42]],"batb":[[0,1.02,6.07]],"ltp":1.02,"tv":4.41,"id":7698577,"hc":14.5}],"tv":8.85}]}
{"op":"mcm","clk":"998411463","pt":1580586838618,"mc":[{"id":"1.168081860","rc":[{"trd":[[1.02,4.45]],"batb":[[0,1.02,6.05]],"ltp":1.02,"tv":4.45,"id":7698577,"hc":13.5}],"tv":8.87}]}
{"op":"mcm","clk":"998411819","pt":1580586841683,"mc":[{"id":"1.168081860","rc":[{"trd":[[1.02,4.44]],"batb":[[0,1.02,6.06]],"ltp":1.02,"tv":4.43,"id":7698577,"hc":14.5}],"tv":8.88}]}
{"op":"mcm","clk":"998413678","pt":1580586856435,"mc":[{"id":"1.168081860","rc":[{"batl":[[0,1000,0.02]],"ltp":1.02,"tv":4.45,"id":7698577,"hc":13.5}]}]}
{"op":"mcm","clk":"998413778","pt":1580586857082,"mc":[{"id":"1.168081860","rc":[{"trd":[[1.02,4.47]],"batb":[[0,1.02,6.04]],"batl":[[0,990,0.01]],"ltp":1.02,"tv":4.46,"id":7698577,"hc":13.5}],"tv":8.9}]}
{"op":"mcm","clk":"998414433","pt":1580586862522,"mc":[{"id":"1.168081860","rc":[{"batl":[[0,1000,2.37]],"ltp":1.02,"tv":4.43,"id":7698577,"hc":14.5}]}]}
{"op":"mcm","clk":"998414522","pt":1580586863313,"mc":[{"id":"1.168081860","rc":[{"trd":[[1.02,4.45]],"batb":[[0,1.02,6.05]],"batl":[[0,990,0.01]],"ltp":1.02,"tv":4.45,"id":7698577,"hc":14.5}],"tv":8.91}]}
{"op":"mcm","clk":"998415518","pt":1580586873624,"mc":[{"id":"1.168081860","rc":[{"batl":[[0,1000,2.37]],"ltp":1.02,"tv":4.46,"id":7698577,"hc":13.5}]}]}
{"op":"mcm","clk":"998415598","pt":1580586874517,"mc":[{"id":"1.168081860","rc":[{"trd":[[1.02,4.48]],"batb":[[0,1.02,6.03]],"batl":[[0,990,0.01]],"ltp":1.02,"tv":4.48,"id":7698577,"hc":13.5}],"tv":8.93}]}
{"op":"mcm","clk":"998416507","pt":1580586882632,"mc":[{"id":"1.168081860","rc":[{"trd":[[1.02,4.47]],"batb":[[0,1.02,6.04]],"ltp":1.02,"tv":4.46,"id":7698577,"hc":14.5}],"tv":8.94}]}
{"op":"mcm","clk":"998417492","pt":1580586891957,"mc":[{"id":"1.168081860","rc":[{"trd":[[1.02,4.5]],"batb":[[0,1.02,6.02]],"ltp":1.02,"tv":4.49,"id":7698577,"hc":13.5}],"tv":8.96}]}
{"op":"mcm","clk":"998418256","pt":1580586899119,"mc":[{"id":"1.168081860","rc":[{"trd":[[1.02,4.48]],"batb":[[0,1.02,6.03]],"ltp":1.02,"tv":4.48,"id":7698577,"hc":14.5}],"tv":8.97}]}
{"op":"mcm","clk":"998419548","pt":1580586910540,"mc":[{"id":"1.168081860","rc":[{"trd":[[1.02,4.51]],"batb":[[0,1.02,6.01]],"ltp":1.02,"tv":4.51,"id":7698577,"hc":13.5}],"tv":8.99}]}
{"op":"mcm","clk":"998420162","pt":1580586915667,"mc":[{"id":"1.168081860","rc":[{"trd":[[1.02,4.5]],"batb":[[0,1.02,6.02]],"ltp":1.02,"tv":4.49,"id":7698577,"hc":14.5}],"tv":9.0}]}
{"op":"mcm","clk":"998421539","pt":1580586928747,"mc":[{"id":"1.168081860","rc":[{"trd":[[1.02,4.53]],"batb":[[0,1.02,6]],"ltp":1.02,"tv":4.52,"id":7698577,"hc":13.5}],"tv":9.02}]}
{"op":"mcm","clk":"998421946","pt":1580586931660,"mc":[{"id":"1.168081860","rc":[{"batl":[[0,1000,0.02]],"ltp":1.02,"tv":4.49,"id":7698577,"hc":14.5}]}]}
{"op":"mcm","clk":"998421991","pt":1580586932030,"mc":[{"id":"1.168081860","rc":[{"trd":[[1.02,4.51]],"batb":[[0,1.02,6.01]],"batl":[[0,990,0.01]],"ltp":1.02,"tv":4.51,"id":7698577,"hc":14.5}],"tv":9.04}]}
{"op":"mcm","clk":"998423667","pt":1580586947677,"mc":[{"id":"1.168081860","rc":[{"batl":[[0,1000,0.02]],"ltp":1.02,"tv":4.52,"id":7698577,"hc":13.5}]}]}
{"op":"mcm","clk":"998423705","pt":1580586948050,"mc":[{"id":"1.168081860","rc":[{"trd":[[1.02,4.54]],"batb":[[0,1.02,5.99]],"batl":[[0,990,0.01]],"ltp":1.02,"tv":4.54,"id":7698577,"hc":13.5}],"tv":9.05}]}
{"op":"mcm","clk":"998424071","pt":1580586951606,"mc":[{"id":"1.168081860","rc":[{"batl":[[0,1000,0.02]],"ltp":1.02,"tv":4.51,"id":7698577,"hc":14.5}]}]}
{"op":"mcm","clk":"998424119","pt":1580586951984,"mc":[{"id":"1.168081860","rc":[{"trd":[[1.02,4.53]],"batb":[[0,1.02,6]],"batl":[[0,990,0.01]],"ltp":1.02,"tv":4.52,"id":7698577,"hc":14.5}],"tv":9.07}]}
{"op":"mcm","clk":"998425751","pt":1580586967629,"mc":[{"id":"1.168081860","rc":[{"batl":[[0,1000,0.02]],"ltp":1.02,"tv":4.54,"id":7698577,"hc":13.5}]}]}
{"op":"mcm","clk":"998425866","pt":1580586968649,"mc":[{"id":"1.168081860","rc":[{"trd":[[1.02,4.56]],"batb":[[0,1.02,5.98]],"batl":[[0,990,0.01]],"ltp":1.02,"tv":4.55,"id":7698577,"hc":13.5},{"batl":[[0,1000,0.02]],"ltp":1.02,"tv":4.52,"id":7698577,"hc":14.5}],"tv":9.08}]}
{"op":"mcm","clk":"998425910","pt":1580586969058,"mc":[{"id":"1.168081860","rc":[{"trd":[[1.02,4.54]],"batb":[[0,1.02,5.99]],"batl":[[0,990,0.01]],"ltp":1.02,"tv":4.54,"id":7698577,"hc":14.5}],"tv":9.1}]}
{"op":"mcm","clk":"998427689","pt":1580586985696,"mc":[{"id":"1.168081860","rc":[{"trd":[[1.02,4.57]],"batb":[[0,1.02,5.97]],"ltp":1.02,"tv":4.57,"id":7698577,"hc":13.5}],"tv":9.11}]}
{"op":"mcm","clk":"998428105","pt":1580586989505,"mc":[{"id":"1.168081860","rc":[{"trd":[[1.02,4.56]],"batb":[[0,1.02,5.98]],"ltp":1.02,"tv":4.55,"id":7698577,"hc":14.5}],"tv":9.13}]}
{"op":"mcm","clk":"998429482","pt":1580587001648,"mc":[{"id":"1.168081860","rc":[{"trd":[[1.02,4.59]],"batb":[[0,1.02,5.96]],"ltp":1.02,"tv":4.59,"id":7698577,"hc":13.5}],"tv":9.14}]}
{"op":"mcm","clk":"998430006","pt":1580587006639,"mc":[{"id":"1.168081860","rc":[{"batl":[[0,1000,0.02]],"ltp":1.02,"tv":4.55,"id":7698577,"hc":14.5}]}]}
{"op":"mcm","clk":"998430069","pt":1580587007113,"mc":[{"id":"1.168081860","rc":[{"trd":[[1.02,4.57]],"batb":[[0,1.02,5.97]],"batl":[[0,990,0.01]],"ltp":1.02,"tv":4.57,"id":7698577,"hc":14.5}],"tv":9.16}]}
{"op":"mcm","clk":"998431456","pt":1580587018674,"mc":[{"id":"1.168081860","rc":[{"trd":[[1.02,4.61]],"batb":[[0,1.02,5.95]],"ltp":1.02,"tv":4.6,"id":7698577,"hc":13.5}],"tv":9.18}]}
{"op":"mcm","clk":"998432264","pt":1580587025473,"mc":[{"id":"1.168081860","rc":[{"batl":[[0,1000,0.02]],"ltp":1.02,"tv":4.57,"id":7698577,"hc":14.5}]}]}
{"op":"mcm","clk":"998432313","pt":1580587025858,"mc":[{"id":"1.168081860","rc":[{"trd":[[1.02,4.59]],"batb":[[0,1.02,5.96]],"batl":[[0,990,0.01]],"ltp":1.02,"tv":4.59,"id":7698577,"hc":14.5}],"tv":9.19}]}
{"op":"mcm","clk":"998433482","pt":1580587035688,"mc":[{"id":"1.168081860","rc":[{"trd":[[1.02,4.62]],"batb":[[0,1.02,5.94]],"ltp":1.02,"tv":4.62,"id":7698577,"hc":13.5}],"tv":9.21}]}
{"op":"mcm","clk":"998434810","pt":1580587046488,"mc":[{"id":"1.168081860","rc":[{"trd":[[1.02,4.61]],"batb":[[0,1.02,5.95]],"ltp":1.02,"tv":4.6,"id":7698577,"hc":14.5}],"tv":9.22}]}
{"op":"mcm","clk":"998435470","pt":1580587052411,"mc":[{"id":"1.168081860","rc":[{"trd":[[1.02,4.64]],"batb":[[0,1.02,5.93]],"ltp":1.02,"tv":4.63,"id":7698577,"hc":13.5}],"tv":9.24}]}
{"op":"mcm","clk":"998436905","pt":1580587064622,"mc":[{"id":"1.168081860","rc":[{"batl":[[0,1000,2.37]],"ltp":1.02,"tv":4.6,"id":7698577,"hc":14.5}]}]}
{"op":"mcm","clk":"998436977","pt":1580587065110,"mc":[{"id":"1.168081860","rc":[{"trd":[[1.02,4.62]],"batb":[[0,1.02,5.94]],"batl":[[0,990,0.01]],"ltp":1.02,"tv":4.62,"id":7698577,"hc":14.5}],"tv":9.25}]}
{"op":"mcm","clk":"998437468","pt":1580587069527,"mc":[{"id":"1.168081860","rc":[{"batl":[[0,1000,2.37]],"ltp":1.02,"tv":4.63,"id":7698577,"hc":13.5}]}]}
{"op":"mcm","clk":"998437608","pt":1580587070520,"mc":[{"id":"1.168081860","rc":[{"trd":[[1.02,4.65]],"batb":[[0,1.02,5.92]],"batl":[[0,990,0.01]],"ltp":1.02,"tv":4.65,"id":7698577,"hc":13.5}],"tv":9.27}]}
{"op":"mcm","clk":"998439091","pt":1580587082699,"mc":[{"id":"1.168081860","rc":[{"batl":[[0,1000,0.02]],"ltp":1.02,"tv":4.62,"id":7698577,"hc":14.5}]}]}
{"op":"mcm","clk":"998439163","pt":1580587083180,"mc":[{"id":"1.168081860","rc":[{"trd":[[1.02,4.64]],"batb":[[0,1.02,5.93]],"batl":[[0,990,0.01]],"ltp":1.02,"tv":4.63,"id":7698577,"hc":14.5}],"tv":9.28}]}
{"op":"mcm","clk":"998439983","pt":1580587089479,"mc":[{"id":"1.168081860","rc":[{"batl":[[0,1000,0.02]],"ltp":1.02,"tv":4.65,"id":7698577,"hc":13.5}]}]}
{"op":"mcm","clk":"998440037","pt":1580587089897,"mc":[{"id":"1.168081860","rc":[{"trd":[[1.02,4.67]],"batb":[[0,1.02,5.91]],"batl":[[0,990,0.01]],"ltp":1.02,"tv":4.66,"id":7698577,"hc":13.5}],"tv":9.3}]}
{"op":"mcm","clk":"998441373","pt":1580587100570,"mc":[{"id":"1.168081860","rc":[{"trd":[[1.02,4.65]],"batb":[[0,1.02,5.92]],"ltp":1.02,"tv":4.65,"id":7698577,"hc":14.5}],"tv":9.32}]}
{"op":"mcm","clk":"998442046","pt":1580587106594,"mc":[{"id":"1.168081860","rc":[{"batl":[[0,1000,0.02]],"ltp":1.02,"tv":4.66,"id":7698577,"hc":13.5}]}]}
{"op":"mcm","clk":"998442117","pt":1580587107071,"mc":[{"id":"1.168081860","rc":[{"trd":[[1.02,4.68]],"batb":[[0,1.02,5.9]],"batl":[[0,990,0.01]],"ltp":1.02,"tv":4.68,"id":7698577,"hc":13.5}],"tv":9.33}]}
{"op":"mcm","clk":"998443526","pt":1580587118697,"mc":[{"id":"1.168081860","rc":[{"batl":[[0,1000,0.02]],"ltp":1.02,"tv":4.65,"id":7698577,"hc":14.5}]}]}
{"op":"mcm","clk":"998443596","pt":1580587119158,"mc":[{"id":"1.168081860","rc":[{"trd":[[1.02,4.67]],"batb":[[0,1.02,5.91]],"batl":[[0,990,0.01]],"ltp":1.02,"tv":4.66,"id":7698577,"hc":14.5}],"tv":9.35}]}
{"op":"mcm","clk":"998444149","pt":1580587123593,"mc":[{"id":"1.168081860","rc":[{"trd":[[1.02,4.7]],"batb":[[0,1.02,5.89]],"ltp":1.02,"tv":4.69,"id":7698577,"hc":13.5}],"tv":9.36}]}
{"op":"mcm","clk":"998445786","pt":1580587136627,"mc":[{"id":"1.168081860","rc":[{"batl":[[0,1000,0.02]],"ltp":1.02,"tv":4.66,"id":7698577,"hc":14.5}]}]}
{"op":"mcm","clk":"998445837","pt":1580587137006,"mc":[{"id":"1.168081860","rc":[{"trd":[[1.02,4.68]],"batb":[[0,1.02,5.9]],"batl":[[0,990,0.01]],"ltp":1.02,"tv":4.68,"id":7698577,"hc":14.5}],"tv":9.38}]}
{"op":"mcm","clk":"998446135","pt":1580587139612,"mc":[{"id":"1.168081860","rc":[{"trd":[[1.02,4.71]],"batb":[[0,1.02,5.88]],"ltp":1.02,"tv":4.71,"id":7698577,"hc":13.5}],"tv":9.39}]}
{"op":"mcm","clk":"998447868","pt":1580587153725,"mc":[{"id":"1.168081860","rc":[{"trd":[[1.02,4.7]],"batb":[[0,1.02,5.89]],"ltp":1.02,"tv":4.69,"id":7698577,"hc":14.5}],"tv":9.41}]}
{"op":"mcm","clk":"998448467","pt":1580587158458,"mc":[{"id":"1.168081860","rc":[{"trd":[[1.02,4.73]],"batb":[[0,1.02,5.87]],"ltp":1.02,"tv":4.72,"id":7698577,"hc":13.5}],"tv":9.42}]}
{"op":"mcm","clk":"998449877","pt":1580587171549,"mc":[{"id":"1.168081860","rc":[{"batl":[[0,1000,0.02]],"ltp":1.02,"tv":4.69,"id":7698577,"hc":14.5}]}]}
{"op":"mcm","clk":"998449939","pt":1580587172047,"mc":[{"id":"1.168081860","rc":[{"trd":[[1.02,4.71]],"batb":[[0,1.02,5.88]],"batl":[[0,990,0.01]],"ltp":1.02,"tv":4.71,"id":7698577,"hc":14.5}],"tv":9.44}]}
{"op":"mcm","clk":"998450457","pt":1580587176551,"mc":[{"id":"1.168081860","rc":[{"batl":[[0,1000,2.37]],"ltp":1.02,"tv":4.72,"id":7698577,"hc":13.5}]}]}
{"op":"mcm","clk":"998450559","pt":1580587177550,"mc":[{"id":"1.168081860","rc":[{"trd":[[1.02,4.75]],"batb":[[0,1.02,5.86]],"batl":[[0,990,0.01]],"ltp":1.02,"tv":4.74,"id":7698577,"hc":13.5}],"tv":9.45}]}
{"op":"mcm","clk":"998451835","pt":1580587190670,"mc":[{"id":"1.168081860","rc":[{"batl":[[0,1000,2.37]],"ltp":1.02,"tv":4.71,"id":7698577,"hc":14.5}]}]}
{"op":"mcm","clk":"998451925","pt":1580587191364,"mc":[{"id":"1.168081860","rc":[{"trd":[[1.02,4.73]],"batb":[[0,1.02,5.87]],"batl":[[0,990,0.01]],"ltp":1.02,"tv":4.72,"id":7698577,"hc":14.5}],"tv":9.47}]}
{"op":"mcm","clk":"998452412","pt":1580587195663,"mc":[{"id":"1.168081860","rc":[{"batl":[[0,1000,0.02]],"ltp":1.02,"tv":4.74,"id":7698577,"hc":13.5}]}]}
{"op":"mcm","clk":"998452537","pt":1580587196652,"mc":[{"id":"1.168081860","rc":[{"trd":[[1.02,4.76]],"batb":[[0,1.02,5.85]],"batl":[[0,990,0.01]],"ltp":1.02,"tv":4.76,"id":7698577,"hc":13.5}],"tv":9.49}]}
{"op":"mcm","clk":"998454456","pt":1580587210553,"mc":[{"id":"1.168081860","rc":[{"trd":[[1.02,4.75]],"batb":[[0,1.02,5.86]],"ltp":1.02,"tv":4.74,"id":7698577,"hc":14.5}],"tv":9.5}]}
{"op":"mcm","clk":"998454877","pt":1580587212500,"mc":[{"id":"1.168081860","rc":[{"batl":[[0,1000,0.02]],"ltp":1.02,"tv":4.76,"id":7698577,"hc":13.5}]}]}
{"op":"mcm","clk":"998454972","pt":1580587213190,"mc":[{"id":"1.168081860","rc":[{"trd":[[1.02,4.78]],"batb":[[0,1.02,5.84]],"batl":[[0,990,0.01]],"ltp":1.02,"tv":4.77,"id":7698577,"hc":13.5}],"tv":9.52}]}
{"op":"mcm","clk":"998456923","pt":1580587228116,"mc":[{"id":"1.168081860","rc":[{"trd":[[1.02,4.76]],"batb":[[0,1.02,5.85]],"ltp":1.02,"tv":4.76,"id":7698577,"hc":14.5}],"tv":9.53}]}
{"op":"mcm","clk":"998457248","pt":1580587230697,"mc":[{"id":"1.168081860","rc":[{"batl":[[0,1000,2.37]],"ltp":1.02,"tv":4.77,"id":7698577,"hc":13.5}]}]}
{"op":"mcm","clk":"998457323","pt":1580587231278,"mc":[{"id":"1.168081860","rc":[{"trd":[[1.02,4.79]],"batb":[[0,1.02,5.83]],"batl":[[0,990,0.01]],"ltp":1.02,"tv":4.79,"id":7698577,"hc":13.5}],"tv":9.55}]}
{"op":"mcm","clk":"998458988","pt":1580587244648,"mc":[{"id":"1.168081860","rc":[{"batl":[[0,1000,2.37]],"ltp":1.02,"tv":4.76,"id":7698577,"hc":14.5}]}]}
{"op":"mcm","clk":"998459104","pt":1580587245351,"mc":[{"id":"1.168081860","rc":[{"trd":[[1.02,4.78]],"batb":[[0,1.02,5.84]],"batl":[[0,990,0.01]],"ltp":1.02,"tv":4.77,"id":7698577,"hc":14.5}],"tv":9.56}]}
{"op":"mcm","clk":"998459833","pt":1580587250650,"mc":[{"id":"1.168081860","rc":[{"trd":[[1.02,4.81]],"batb":[[0,1.02,5.82]],"ltp":1.02,"tv":4.8,"id":7698577,"hc":13.5}],"tv":9.58}]}
{"op":"mcm","clk":"998461641","pt":1580587264564,"mc":[{"id":"1.168081860","rc":[{"batl":[[0,1000,2.37]],"ltp":1.02,"tv":4.77,"id":7698577,"hc":14.5}]}]}
{"op":"mcm","clk":"998461790","pt":1580587265563,"mc":[{"id":"1.168081860","rc":[{"trd":[[1.02,4.79]],"batb":[[0,1.02,5.83]],"batl":[[0,990,0.01]],"ltp":1.02,"tv":4.79,"id":7698577,"hc":14.5}],"tv":9.59}]}
{"op":"mcm","clk":"998461937","pt":1580587266578,"mc":[{"id":"1.168081860","rc":[{"batl":[[0,1000,2.37]],"ltp":1.02,"tv":4.8,"id":7698577,"hc":13.5}]}]}
{"op":"mcm","clk":"998462029","pt":1580587267166,"mc":[{"id":"1.168081860","rc":[{"trd":[[1.02,4.82]],"batb":[[0,1.02,5.81]],"batl":[[0,990,0.01]],"ltp":1.02,"tv":4.82,"id":7698577,"hc":13.5}],"tv":9.61}]}
{"op":"mcm","clk":"998464204","pt":1580587283524,"mc":[{"id":"1.168081860","rc":[{"trd":[[1.02,4.84]],"batb":[[0,1.02,5.8]],"ltp":1.02,"tv":4.83,"id":7698577,"hc":13.5}],"tv":9.63}]}
{"op":"mcm","clk":"998464360","pt":1580587284543,"mc":[{"id":"1.168081860","rc":[{"batl":[[0,1000,0.02]],"ltp":1.02,"tv":4.79,"id":7698577,"hc":14.5}]}]}
{"op":"mcm","clk":"998464461","pt":1580587285231,"mc":[{"id":"1.168081860","rc":[{"trd":[[1.02,4.81]],"batb":[[0,1.02,5.82]],"batl":[[0,990,0.01]],"ltp":1.02,"tv":4.8,"id":7698577,"hc":14.5}],"tv":9.64}]}
{"op":"mcm","clk":"998467059","pt":1580587302654,"mc":[{"id":"1.168081860","rc":[{"trd":[[1.02,4.85]],"batb":[[0,1.02,5.79]],"ltp":1.02,"tv":4.85,"id":7698577,"hc":13.5},{"trd":[[1.02,4.82]],"batb":[[0,1.02,5.81]],"ltp":1.02,"tv":4.82,"id":7698577,"hc":14.5}],"tv":9.67}]}
{"op":"mcm","clk":"998469616","pt":1580587321052,"mc":[{"id":"1.168081860","rc":[{"trd":[[1.02,4.84]],"batb":[[0,1.02,5.8]],"ltp":1.02,"tv":4.83,"id":7698577,"hc":14.5}],"tv":9.69}]}
{"op":"mcm","clk":"998470131","pt":1580587323862,"mc":[{"id":"1.168081860","rc":[{"trd":[[1.02,4.87]],"batb":[[0,1.02,5.78]],"ltp":1.02,"tv":4.86,"id":7698577,"hc":13.5}],"tv":9.7}]}
{"op":"mcm","clk":"998472266","pt":1580587337601,"mc":[{"id":"1.168081860","rc":[{"batl":[[0,1000,0.02]],"ltp":1.02,"tv":4.83,"id":7698577,"hc":14.5}]}]}
{"op":"mcm","clk":"998472431","pt":1580587338569,"mc":[{"id":"1.168081860","rc":[{"trd":[[1.02,4.85]],"batb":[[0,1.02,5.79]],"batl":[[0,990,0.01]],"ltp":1.02,"tv":4.85,"id":7698577,"hc":14.5}],"tv":9.72}]}
{"op":"mcm","clk":"998472908","pt":1580587341500,"mc":[{"id":"1.168081860","rc":[{"trd":[[1.02,4.88]],"batb":[[0,1.02,5.77]],"ltp":1.02,"tv":4.88,"id":7698577,"hc":13.5}],"tv":9.73}]}
{"op":"mcm","clk":"998475270","pt":1580587357419,"mc":[{"id":"1.168081860","rc":[{"trd":[[1.02,4.87]],"batb":[[0,1.02,5.78]],"ltp":1.02,"tv":4.86,"id":7698577,"hc":14.5}],"tv":9.75}]}
{"op":"mcm","clk":"998475565","pt":1580587359633,"mc":[{"id":"1.168081860","rc":[{"batl":[[0,1000,2.37]],"ltp":1.02,"tv":4.88,"id":7698577,"hc":13.5}]}]}
{"op":"mcm","clk":"998475633","pt":1580587360017,"mc":[{"id":"1.168081860","rc":[{"trd":[[1.02,4.9]],"batb":[[0,1.02,5.76]],"batl":[[0,990,0.01]],"ltp":1.02,"tv":4.9,"id":7698577,"hc":13.5}],"tv":9.76}]}
{"op":"mcm","clk":"998477681","pt":1580587374429,"mc":[{"id":"1.168081860","rc":[{"batl":[[0,1000,0.02]],"ltp":1.02,"tv":4.86,"id":7698577,"hc":14.5}]}]}
{"op":"mcm","clk":"998477843","pt":1580587375663,"mc":[{"id":"1.168081860","rc":[{"trd":[[1.02,4.88]],"batb":[[0,1.02,5.77]],"batl":[[0,990,0.01]],"ltp":1.02,"tv":4.88,"id":7698577,"hc":14.5}],"tv":9.78}]}
{"op":"mcm","clk":"998478465","pt":1580587379669,"mc":[{"id":"1.168081860","rc":[{"batl":[[0,1000,0.02]],"ltp":1.02,"tv":4.9,"id":7698577,"hc":13.5}]}]}
{"op":"mcm","clk":"998478506","pt":1580587379939,"mc":[{"id":"1.168081860","rc":[{"trd":[[1.02,4.92]],"batb":[[0,1.02,5.75]],"batl":[[0,990,0.01]],"ltp":1.02,"tv":4.91,"id":7698577,"hc":13.5}],"tv":9.8}]}
{"op":"mcm","clk":"998480359","pt":1580587392446,"mc":[{"id":"1.168081860","rc":[{"batl":[[0,1000,2.37]],"ltp":1.02,"tv":4.88,"id":7698577,"hc":14.5}]}]}
{"op":"mcm","clk":"998480472","pt":1580587393142,"mc":[{"id":"1.168081860","rc":[{"trd":[[1.02,4.9]],"batb":[[0,1.02,5.76]],"batl":[[0,990,0.01]],"ltp":1.02,"tv":4.9,"id":7698577,"hc":14.5}],"tv":9.81}]}
{"op":"mcm","clk":"998481023","pt":1580587396793,"mc":[{"id":"1.168081860","rc":[{"trd":[[1.02,4.93]],"batb":[[0,1.02,5.74]],"ltp":1.02,"tv":4.93,"id":7698577,"hc":13.5}],"tv":9.83}]}
{"op":"mcm","clk":"998483281","pt":1580587411352,"mc":[{"id":"1.168081860","rc":[{"trd":[[1.02,4.92]],"batb":[[0,1.02,5.75]],"ltp":1.02,"tv":4.91,"id":7698577,"hc":14.5}],"tv":9.84}]}
{"op":"mcm","clk":"998483461","pt":1580587412518,"mc":[{"id":"1.168081860","rc":[{"batl":[[0,1000,2.37]],"ltp":1.02,"tv":4.93,"id":7698577,"hc":13.5}]}]}
{"op":"mcm","clk":"998483646","pt":1580587413633,"mc":[{"id":"1.168081860","rc":[{"trd":[[1.02,4.95]],"batb":[[0,1.02,5.73]],"batl":[[0,990,0.01]],"ltp":1.02,"tv":4.94,"id":7698577,"hc":13.5}],"tv":9.86}]}
{"op":"mcm","clk":"998485914","pt":1580587428669,"mc":[{"id":"1.168081860","rc":[{"trd":[[1.02,4.93]],"batb":[[0,1.02,5.74]],"ltp":1.02,"tv":4.93,"id":7698577,"hc":14.5}],"tv":9.87}]}
{"op":"mcm","clk":"998486360","pt":1580587431691,"mc":[{"id":"1.168081860","rc":[{"trd":[[1.02,4.96]],"batb":[[0,1.02,5.72]],"ltp":1.02,"tv":4.96,"id":7698577,"hc":13.5}],"tv":9.89}]}
{"op":"mcm","clk":"998488712","pt":1580587446699,"mc":[{"id":"1.168081860","rc":[{"batl":[[0,1000,2.37]],"ltp":1.02,"tv":4.96,"id":7698577,"hc":13.5},{"trd":[[1.02,4.95]],"batb":[[0,1.02,5.73]],"ltp":1.02,"tv":4.94,"id":7698577,"hc":14.5}],"tv":9.9}]}
{"op":"mcm","clk":"998488829","pt":1580587447408,"mc":[{"id":"1.168081860","rc":[{"trd":[[1.02,4.98]],"batb":[[0,1.02,5.71]],"batl":[[0,990,0.01]],"ltp":1.02,"tv":4.97,"id":7698577,"hc":13.5}],"tv":9.92}]}
{"op":"mcm","clk":"998491411","pt":1580587463602,"mc":[{"id":"1.168081860","rc":[{"batl":[[0,1000,0.02]],"ltp":1.02,"tv":4.97,"id":7698577,"hc":13.5}]}]}
{"op":"mcm","clk":"998491460","pt":1580587463855,"mc":[{"id":"1.168081860","rc":[{"trd":[[1.02,4.99]],"batb":[[0,1.02,5.7]],"batl":[[0,990,0.01]],"ltp":1.02,"tv":4.99,"id":7698577,"hc":13.5}],"tv":9.94}]}
{"op":"mcm","clk":"998492168","pt":1580587468543,"mc":[{"id":"1.168081860","rc":[{"batl":[[0,1000,0.02]],"ltp":1.02,"tv":4.94,"id":7698577,"hc":14.5}]}]}
{"op":"mcm","clk":"998492267","pt":1580587469143,"mc":[{"id":"1.168081860","rc":[{"trd":[[1.02,4.96]],"batb":[[0,1.02,5.72]],"batl":[[0,990,0.01]],"ltp":1.02,"tv":4.96,"id":7698577,"hc":14.5}],"tv":9.95}]}
{"op":"mcm","clk":"998494080","pt":1580587480633,"mc":[{"id":"1.168081860","rc":[{"batl":[[0,1000,0.02]],"ltp":1.02,"tv":4.99,"id":7698577,"hc":13.5}]}]}
{"op":"mcm","clk":"998494131","pt":1580587480918,"mc":[{"id":"1.168081860","rc":[{"trd":[[1.02,5.01]],"batb":[[0,1.02,5.69]],"batl":[[0,990,0.01]],"ltp":1.02,"tv":5.0,"id":7698577,"hc":13.5}],"tv":9.97}]}
{"op":"mcm","clk":"998495109","pt":1580587487433,"mc":[{"id":"1.168081860","rc":[{"batl":[[0,1000,0.02]],"ltp":1.02,"tv":4.96,"id":7698577,"hc":14.5}]}]}
{"op":"mcm","clk":"998495241","pt":1580587488134,"mc":[{"id":"1.168081860","rc":[{"trd":[[1.02,4.98]],"batb":[[0,1.02,5.71]],"batl":[[0,990,0.01]],"ltp":1.02,"tv":4.97,"id":7698577,"hc":14.5}],"tv":9.98}]}
{"op":"mcm","clk":"998496804","pt":1580587498574,"mc":[{"id":"1.168081860","rc":[{"batl":[[0,1000,0.02]],"ltp":1.02,"tv":5.0,"id":7698577,"hc":13.5}]}]}
{"op":"mcm","clk":"998496852","pt":1580587498838,"mc":[{"id":"1.168081860","rc":[{"trd":[[1.02,5.02]],"batb":[[0,1.02,5.68]],"batl":[[0,990,0.01]],"ltp":1.02,"tv":5.02,"id":7698577,"hc":13.5}],"tv":10.0}]}
{"op":"mcm","clk":"998497931","pt":1580587505605,"mc":[{"id":"1.168081860","rc":[{"trd":[[1.02,4.99]],"batb":[[0,1.02,5.7]],"ltp":1.02,"tv":4.99,"id":7698577,"hc":14.5}],"tv":10.01}]}
{"op":"mcm","clk":"998499867","pt":1580587517540,"mc":[{"id":"1.168081860","rc":[{"batl":[[0,1000,0.02]],"ltp":1.02,"tv":5.02,"id":7698577,"hc":13.5}]}]}
{"op":"mcm","clk":"998500047","pt":1580587518629,"mc":[{"id":"1.168081860","rc":[{"trd":[[1.02,5.04]],"batb":[[0,1.02,5.67]],"batl":[[0,990,0.01]],"ltp":1.02,"tv":5.04,"id":7698577,"hc":13.5}],"tv":10.03}]}
{"op":"mcm","clk":"998500645","pt":1580587522642,"mc":[{"id":"1.168081860","rc":[{"batl":[[0,1000,0.02]],"ltp":1.02,"tv":4.99,"id":7698577,"hc":14.5}]}]}
{"op":"mcm","clk":"998500833","pt":1580587523644,"mc":[{"id":"1.168081860","rc":[{"trd":[[1.02,5.01]],"batb":[[0,1.02,5.69]],"batl":[[0,990,0.01]],"ltp":1.02,"tv":5.0,"id":7698577,"hc":14.5}],"tv":10.04}]}
{"op":"mcm","clk":"998502537","pt":1580587534451,"mc":[{"id":"1.168081860","rc":[{"batl":[[0,1000,0.02]],"ltp":1.02,"tv":5.04,"id":7698577,"hc":13.5}]}]}
{"op":"mcm","clk":"998502610","pt":1580587534859,"mc":[{"id":"1.168081860","rc":[{"trd":[[1.02,5.06]],"batb":[[0,1.02,5.66]],"batl":[[0,990,0.01]],"ltp":1.02,"tv":5.05,"id":7698577,"hc":13.5}],"tv":10.06}]}
{"op":"mcm","clk":"998504099","pt":1580587543682,"mc":[{"id":"1.168081860","rc":[{"trd":[[1.02,5.02]],"batb":[[0,1.02,5.68]],"ltp":1.02,"tv":5.02,"id":7698577,"hc":14.5}],"tv":10.08}]}
{"op":"mcm","clk":"998505729","pt":1580587553612,"mc":[{"id":"1.168081860","rc":[{"batl":[[0,1000,0.02]],"ltp":1.02,"tv":5.05,"id":7698577,"hc":13.5}]}]}
{"op":"mcm","clk":"998505796","pt":1580587553997,"mc":[{"id":"1.168081860","rc":[{"trd":[[1.02,5.07]],"batb":[[0,1.02,5.65]],"batl":[[0,990,0.01]],"ltp":1.02,"tv":5.07,"id":7698577,"hc":13.5}],"tv":10.09}]}
{"op":"mcm","clk":"998506720","pt":1580587559387,"mc":[{"id":"1.168081860","rc":[{"trd":[[1.02,5.04]],"batb":[[0,1.02,5.67]],"ltp":1.02,"tv":5.04,"id":7698577,"hc":14.5}],"tv":10.11}]}
{"op":"mcm","clk":"998509556","pt":1580587576081,"mc":[{"id":"1.168081860","rc":[{"trd":[[1.02,5.09]],"batb":[[0,1.02,5.64]],"ltp":1.02,"tv":5.08,"id":7698577,"hc":13.5}],"tv":10.12}]}
{"op":"mcm","clk":"998509951","pt":1580587578637,"mc":[{"id":"1.168081860","rc":[{"batl":[[0,1000,2.37]],"ltp":1.02,"tv":5.04,"id":7698577,"hc":14.5}]}]}
{"op":"mcm","clk":"998510057","pt":1580587579342,"mc":[{"id":"1.168081860","rc":[{"trd":[[1.02,5.06]],"batb":[[0,1.02,5.66]],"batl":[[0,990,0.01]],"ltp":1.02,"tv":5.05,"id":7698577,"hc":14.5}],"tv":10.14}]}
{"op":"mcm","clk":"998511992","pt":1580587592655,"mc":[{"id":"1.168081860","rc":[{"trd":[[1.02,5.1]],"batb":[[0,1.02,5.63]],"ltp":1.02,"tv":5.1,"id":7698577,"hc":13.5}],"tv":10.15}]}
{"op":"mcm","clk":"998512539","pt":1580587596528,"mc":[{"id":"1.168081860","rc":[{"batl":[[0,1000,2.37]],"ltp":1.02,"tv":5.05,"id":7698577,"hc":14.5}]}]}
{"op":"mcm","clk":"998512689","pt":1580587597368,"mc":[{"id":"1.168081860","rc":[{"trd":[[1.02,5.07]],"batb":[[0,1.02,5.65]],"batl":[[0,990,0.01]],"ltp":1.02,"tv":5.07,"id":7698577,"hc":14.5}],"tv":10.17}]}
{"op":"mcm","clk":"998514236","pt":1580587608592,"mc":[{"id":"1.168081860","rc":[{"batl":[[0,1000,2.37]],"ltp":1.02,"tv":5.1,"id":7698577,"hc":13.5}]}]}
{"op":"mcm","clk":"998514347","pt":1580587609308,"mc":[{"id":"1.168081860","rc":[{"trd":[[1.02,5.12]],"batb":[[0,1.02,5.62]],"batl":[[0,990,0.01]],"ltp":1.02,"tv":5.11,"id":7698577,"hc":13.5}],"tv":10.18}]}
{"op":"mcm","clk":"998515131","pt":1580587614692,"mc":[{"id":"1.168081860","rc":[{"trd":[[1.02,5.09]],"batb":[[0,1.02,5.64]],"ltp":1.02,"tv":5.08,"id":7698577,"hc":14.5}],"tv":10.2}]}
{"op":"mcm","clk":"998517328","pt":1580587629528,"mc":[{"id":"1.168081860","rc":[{"batl":[[0,1000,2.37]],"ltp":1.02,"tv":5.11,"id":7698577,"hc":13.5}]}]}
{"op":"mcm","clk":"998517438","pt":1580587630256,"mc":[{"id":"1.168081860","rc":[{"trd":[[1.02,5.13]],"batb":[[0,1.02,5.61]],"batl":[[0,990,0.01]],"ltp":1.02,"tv":5.13,"id":7698577,"hc":13.5}],"tv":10.21}]}
{"op":"mcm","clk":"998517649","pt":1580587631657,"mc":[{"id":"1.168081860","rc":[{"batl":[[0,1000,0.02]],"ltp":1.02,"tv":5.08,"id":7698577,"hc":14.5}]}]}
{"op":"mcm","clk":"998517726","pt":1580587632168,"mc":[{"id":"1.168081860","rc":[{"trd":[[1.02,5.1]],"batb":[[0,1.02,5.63]],"batl":[[0,990,0.01]],"ltp":1.02,"tv":5.1,"id":7698577,"hc":14.5}],"tv":10.23}]}
{"op":"mcm","clk":"998519996","pt":1580587647604,"mc":[{"id":"1.168081860","rc":[{"batl":[[0,1000,2.37]],"ltp":1.02,"tv":5.13,"id":7698577,"hc":13.5}]}]}
{"op":"mcm","clk":"998520091","pt":1580587648135,"mc":[{"id":"1.168081860","rc":[{"trd":[[1.02,5.15]],"batb":[[0,1.02,5.6]],"batl":[[0,990,0.01]],"ltp":1.02,"tv":5.14,"id":7698577,"hc":13.5}],"tv":10.25}]}
{"op":"mcm","clk":"998520347","pt":1580587649644,"mc":[{"id":"1.168081860","rc":[{"batl":[[0,1000,0.02]],"ltp":1.02,"tv":5.1,"id":7698577,"hc":14.5}]}]}
{"op":"mcm","clk":"998520400","pt":1580587649978,"mc":[{"id":"1.168081860","rc":[{"trd":[[1.02,5.12]],"batb":[[0,1.02,5.62]],"batl":[[0,990,0.01]],"ltp":1.02,"tv":5.11,"id":7698577,"hc":14.5}],"tv":10.26}]}
{"op":"mcm","clk":"998523092","pt":1580587668290,"mc":[{"id":"1.168081860","rc":[{"trd":[[1.02,5.16]],"batb":[[0,1.02,5.59]],"ltp":1.02,"tv":5.16,"id":7698577,"hc":13.5}],"tv":10.28}]}
{"op":"mcm","clk":"998523332","pt":1580587669720,"mc":[{"id":"1.168081860","rc":[{"trd":[[1.02,5.13]],"batb":[[0,1.02,5.61]],"ltp":1.02,"tv":5.13,"id":7698577,"hc":14.5}],"tv":10.29}]}
{"op":"mcm","clk":"998526228","pt":1580587687565,"mc":[{"id":"1.168081860","rc":[{"trd":[[1.02,5.18]],"batb":[[0,1.02,5.58]],"ltp":1.02,"tv":5.17,"id":7698577,"hc":13.5}],"tv":10.31}]}
{"op":"mcm","clk":"998526380","pt":1580587688557,"mc":[{"id":"1.168081860","rc":[{"batl":[[0,1000,2.37]],"ltp":1.02,"tv":5.13,"id":7698577,"hc":14.5}]}]}
{"op":"mcm","clk":"998526550","pt":1580587689693,"mc":[{"id":"1.168081860","rc":[{"trd":[[1.02,5.15]],"batb":[[0,1.02,5.6]],"batl":[[0,990,0.01]],"ltp":1.02,"tv":5.14,"id":7698577,"hc":14.5}],"tv":10.32}]}
{"op":"mcm","clk":"998528926","pt":1580587704503,"mc":[{"id":"1.168081860","rc":[{"trd":[[1.02,5.2]],"batb":[[0,1.02,5.57]],"ltp":1.02,"tv":5.19,"id":7698577,"hc":13.5}],"tv":10.34}]}
{"op":"mcm","clk":"998529126","pt":1580587705516,"mc":[{"id":"1.168081860","rc":[{"batl":[[0,1000,2.37]],"ltp":1.02,"tv":5.14,"id":7698577,"hc":14.5}]}]}
{"op":"mcm","clk":"998529244","pt":1580587706323,"mc":[{"id":"1.168081860","rc":[{"trd":[[1.02,5.16]],"batb":[[0,1.02,5.59]],"batl":[[0,990,0.01]],"ltp":1.02,"tv":5.16,"id":7698577,"hc":14.5}],"tv":10.35}]}
{"op":"mcm","clk":"998531947","pt":1580587724595,"mc":[{"id":"1.168081860","rc":[{"batl":[[0,1000,2.37]],"ltp":1.02,"tv":5.16,"id":7698577,"hc":14.5}]}]}
{"op":"mcm","clk":"998532050","pt":1580587725280,"mc":[{"id":"1.168081860","rc":[{"trd":[[1.02,5.18]],"batb":[[0,1.02,5.58]],"batl":[[0,990,0.01]],"ltp":1.02,"tv":5.17,"id":7698577,"hc":14.5}],"tv":10.37}]}
{"op":"mcm","clk":"998532636","pt":1580587729433,"mc":[{"id":"1.168081860","rc":[{"batl":[[0,1000,0.02]],"ltp":1.02,"tv":5.19,"id":7698577,"hc":13.5}]}]}
{"op":"mcm","clk":"998532699","pt":1580587729806,"mc":[{"id":"1.168081860","rc":[{"trd":[[1.02,5.21]],"batb":[[0,1.02,5.56]],"batl":[[0,990,0.01]],"ltp":1.02,"tv":5.21,"id":7698577,"hc":13.5}],"tv":10.39}]}
{"op":"mcm","clk":"998534505","pt":1580587742423,"mc":[{"id":"1.168081860","rc":[{"trd":[[1.02,5.2]],"batb":[[0,1.02,5.57]],"ltp":1.02,"tv":5.19,"id":7698577,"hc":14.5}],"tv":10.4}]}
{"op":"mcm","clk":"998535137","pt":1580587746747,"mc":[{"id":"1.168081860","rc":[{"trd":[[1.02,5.23]],"batb":[[0,1.02,5.55]],"ltp":1.02,"tv":5.22,"id":7698577,"hc":13.5}],"tv":10.42}]}
{"op":"mcm","clk":"998536955","pt":1580587758642,"mc":[{"id":"1.168081860","rc":[{"batl":[[0,1000,2.37]],"ltp":1.02,"tv":5.19,"id":7698577,"hc":14.5}]}]}
{"op":"mcm","clk":"998537029","pt":1580587759059,"mc":[{"id":"1.168081860","rc":[{"trd":[[1.02,5.21]],"batb":[[0,1.02,5.56]],"batl":[[0,990,0.01]],"ltp":1.02,"tv":5.21,"id":7698577,"hc":14.5}],"tv":10.43}]}
{"op":"mcm","clk":"998537840","pt":1580587764471,"mc":[{"id":"1.168081860","rc":[{"batl":[[0,1000,2.37]],"ltp":1.02,"tv":5.22,"id":7698577,"hc":13.5}]}]}
{"op":"mcm","clk":"998537962","pt":1580587765285,"mc":[{"id":"1.168081860","rc":[{"trd":[[1.02,5.24]],"batb":[[0,1.02,5.54]],"batl":[[0,990,0.01]],"ltp":1.02,"tv":5.24,"id":7698577,"hc":13.5}],"tv":10.45}]}
{"op":"mcm","clk":"998540156","pt":1580587778695,"mc":[{"id":"1.168081860","rc":[{"batl":[[0,1000,0.02]],"ltp":1.02,"tv":5.21,"id":7698577,"hc":14.5}]}]}
{"op":"mcm","clk":"998540228","pt":1580587779104,"mc":[{"id":"1.168081860","rc":[{"trd":[[1.02,5.23]],"batb":[[0,1.02,5.55]],"batl":[[0,990,0.01]],"ltp":1.02,"tv":5.22,"id":7698577,"hc":14.5}],"tv":10.46}]}
{"op":"mcm","clk":"998541473","pt":1580587785701,"mc":[{"id":"1.168081860","rc":[{"trd":[[1.02,5.26]],"batb":[[0,1.02,5.53]],"ltp":1.02,"tv":5.25,"id":7698577,"hc":13.5}],"tv":10.48}]}
{"op":"mcm","clk":"998543094","pt":1580587795614,"mc":[{"id":"1.168081860","rc":[{"batl":[[0,1000,0.02]],"ltp":1.02,"tv":5.22,"id":7698577,"hc":14.5}]}]}
{"op":"mcm","clk":"998543236","pt":1580587796435,"mc":[{"id":"1.168081860","rc":[{"trd":[[1.02,5.24]],"batb":[[0,1.02,5.54]],"batl":[[0,990,0.01]],"ltp":1.02,"tv":5.24,"id":7698577,"hc":14.5}],"tv":10.49}]}
{"op":"mcm","clk":"998544514","pt":1580587803619,"mc":[{"id":"1.168081860","rc":[{"batl":[[0,1000,0.02]],"ltp":1.02,"tv":5.25,"id":7698577,"hc":13.5}]}]}
{"op":"mcm","clk":"998544565","pt":1580587803940,"mc":[{"id":"1.168081860","rc":[{"trd":[[1.02,5.27]],"batb":[[0,1.02,5.52]],"batl":[[0,990,0.01]],"ltp":1.02,"tv":5.27,"id":7698577,"hc":13.5}],"tv":10.51}]}
{"op":"mcm","clk":"998546603","pt":1580587816267,"mc":[{"id":"1.168081860","rc":[{"trd":[[1.02,5.26]],"batb":[[0,1.02,5.53]],"ltp":1.02,"tv":5.25,"id":7698577,"hc":14.5}],"tv":10.52}]}
{"op":"mcm","clk":"998547311","pt":1580587820526,"mc":[{"id":"1.168081860","rc":[{"trd":[[1.02,5.29]],"batb":[[0,1.02,5.51]],"ltp":1.02,"tv":5.28,"id":7698577,"hc":13.5}],"tv":10.54}]}
{"op":"mcm","clk":"998549707","pt":1580587835677,"mc":[{"id":"1.168081860","rc":[{"trd":[[1.02,5.27]],"batb":[[0,1.02,5.52]],"ltp":1.02,"tv":5.27,"id":7698577,"hc":14.5}],"tv":10.56}]}
{"op":"mcm","clk":"998550752","pt":1580587841576,"mc":[{"id":"1.168081860","rc":[{"trd":[[1.02,5.3]],"batb":[[0,1.02,5.5]],"ltp":1.02,"tv":5.3,"id":7698577,"hc":13.5}],"tv":10.57}]}
{"op":"mcm","clk":"998552693","pt":1580587853807,"mc":[{"id":"1.168081860","rc":[{"trd":[[1.02,5.29]],"batb":[[0,1.02,5.51]],"ltp":1.02,"tv":5.28,"id":7698577,"hc":14.5}],"tv":10.59}]}
{"op":"mcm","clk":"998553810","pt":1580587860776,"mc":[{"id":"1.168081860","rc":[{"trd":[[1.02,5.32]],"batb":[[0,1.02,5.49]],"ltp":1.02,"tv":5.31,"id":7698577,"hc":13.5}],"tv":10.6}]}
{"op":"mcm","clk":"998555395","pt":1580587871467,"mc":[{"id":"1.168081860","rc":[{"trd":[[1.02,5.3]],"batb":[[0,1.02,5.5]],"ltp":1.02,"tv":5.3,"id":7698577,"hc":14.5}],"tv":10.62}]}
{"op":"mcm","clk":"998556425","pt":1580587878676,"mc":[{"id":"1.168081860","rc":[{"batl":[[0,1000,0.02]],"ltp":1.02,"tv":5.31,"id":7698577,"hc":13.5}]}]}
{"op":"mcm","clk":"998556478","pt":1580587879105,"mc":[{"id":"1.168081860","rc":[{"trd":[[1.02,5.33]],"batb":[[0,1.02,5.48]],"batl":[[0,990,0.01]],"ltp":1.02,"tv":5.33,"id":7698577,"hc":13.5}],"tv":10.63}]}
{"op":"mcm","clk":"998557742","pt":1580587888534,"mc":[{"id":"1.168081860","rc":[{"batl":[[0,1000,2.37]],"ltp":1.02,"tv":5.3,"id":7698577,"hc":14.5}]}]}
{"op":"mcm","clk":"998557863","pt":1580587889320,"mc":[{"id":"1.168081860","rc":[{"trd":[[1.02,5.32]],"batb":[[0,1.02,5.49]],"batl":[[0,990,0.01]],"ltp":1.02,"tv":5.31,"id":7698577,"hc":14.5}],"tv":10.65}]}
{"op":"mcm","clk":"998558735","pt":1580587895645,"mc":[{"id":"1.168081860","rc":[{"batl":[[0,1000,0.02]],"ltp":1.02,"tv":5.33,"id":7698577,"hc":13.5}]}]}
{"op":"mcm","clk":"998558809","pt":1580587896159,"mc":[{"id":"1.168081860","rc":[{"trd":[[1.02,5.35]],"batb":[[0,1.02,5.47]],"batl":[[0,990,0.01]],"ltp":1.02,"tv":5.35,"id":7698577,"hc":13.5}],"tv":10.66}]}
{"op":"mcm","clk":"998561324","pt":1580587913519,"mc":[{"id":"1.168081860","rc":[{"batl":[[0,1000,0.02]],"ltp":1.02,"tv":5.31,"id":7698577,"hc":14.5}]}]}
{"op":"mcm","clk":"998561387","pt":1580587913927,"mc":[{"id":"1.168081860","rc":[{"trd":[[1.02,5.33]],"batb":[[0,1.02,5.48]],"batl":[[0,990,0.01]],"ltp":1.02,"tv":5.33,"id":7698577,"hc":14.5}],"tv":10.68}]}
{"op":"mcm","clk":"998561610","pt":1580587915544,"mc":[{"id":"1.168081860","rc":[{"batl":[[0,1000,0.02]],"ltp":1.02,"tv":5.35,"id":7698577,"hc":13.5}]}]}
{"op":"mcm","clk":"998561670","pt":1580587915933,"mc":[{"id":"1.168081860","rc":[{"trd":[[1.02,5.37]],"batb":[[0,1.02,5.46]],"batl":[[0,990,0.01]],"ltp":1.02,"tv":5.36,"id":7698577,"hc":13.5}],"tv":10.7}]}
{"op":"mcm","clk":"998563918","pt":1580587931673,"mc":[{"id":"1.168081860","rc":[{"trd":[[1.02,5.35]],"batb":[[0,1.02,5.47]],"ltp":1.02,"tv":5.35,"id":7698577,"hc":14.5}],"tv":10.71}]}
{"op":"mcm","clk":"998564198","pt":1580587933494,"mc":[{"id":"1.168081860","rc":[{"trd":[[1.02,5.38]],"batb":[[0,1.02,5.45]],"ltp":1.02,"tv":5.38,"id":7698577,"hc":13.5}],"tv":10.73}]}
{"op":"mcm","clk":"998566405","pt":1580587949591,"mc":[{"id":"1.168081860","rc":[{"trd":[[1.02,5.37]],"batb":[[0,1.02,5.46]],"ltp":1.02,"tv":5.36,"id":7698577,"hc":14.5}],"tv":10.74}]}
{"op":"mcm","clk":"998566688","pt":1580587951639,"mc":[{"id":"1.168081860","rc":[{"batl":[[0,1000,2.37]],"ltp":1.02,"tv":5.38,"id":7698577,"hc":13.5}]}]}
{"op":"mcm","clk":"998566807","pt":1580587952433,"mc":[{"id":"1.168081860","rc":[{"trd":[[1.02,5.4]],"batb":[[0,1.02,5.44]],"batl":[[0,990,0.01]],"ltp":1.02,"tv":5.39,"id":7698577,"hc":13.5}],"tv":10.76}]}
{"op":"mcm","clk":"998569085","pt":1580587967943,"mc":[{"id":"1.168081860","rc":[{"trd":[[1.02,5.38]],"batb":[[0,1.02,5.45]],"ltp":1.02,"tv":5.38,"id":7698577,"hc":14.5}],"tv":10.77}]}
{"op":"mcm","clk":"998569457","pt":1580587970573,"mc":[{"id":"1.168081860","rc":[{"batl":[[0,1000,2.37]],"ltp":1.02,"tv":5.39,"id":7698577,"hc":13.5}]}]}
{"op":"mcm","clk":"998569600","pt":1580587971372,"mc":[{"id":"1.168081860","rc":[{"trd":[[1.02,5.41]],"batb":[[0,1.02,5.43]],"batl":[[0,990,0.01]],"ltp":1.02,"tv":5.41,"id":7698577,"hc":13.5}],"tv":10.79}]}
{"op":"mcm","clk":"998571674","pt":1580587985617,"mc":[{"id":"1.168081860","rc":[{"trd":[[1.02,5.4]],"batb":[[0,1.02,5.44]],"ltp":1.02,"tv":5.39,"id":7698577,"hc":14.5}],"tv":10.8}]}
{"op":"mcm","clk":"998572309","pt":1580587989643,"mc":[{"id":"1.168081860","rc":[{"batl":[[0,1000,0.02]],"ltp":1.02,"tv":5.41,"id":7698577,"hc":13.5}]}]}
{"op":"mcm","clk":"998572381","pt":1580587990026,"mc":[{"id":"1.168081860","rc":[{"trd":[[1.02,5.43]],"batb":[[0,1.02,5.42]],"batl":[[0,990,0.01]],"ltp":1.02,"tv":5.42,"id":7698577,"hc":13.5}],"tv":10.82}]}
{"op":"mcm","clk":"998574602","pt":1580588003607,"mc":[{"id":"1.168081860","rc":[{"batl":[[0,1000,2.37]],"ltp":1.02,"tv":5.39,"id":7698577,"hc":14.5}]}]}
{"op":"mcm","clk":"998574699","pt":1580588004208,"mc":[{"id":"1.168081860","rc":[{"trd":[[1.02,5.41]],"batb":[[0,1.02,5.43]],"batl":[[0,990,0.01]],"ltp":1.02,"tv":5.41,"id":7698577,"hc":14.5}],"tv":10.83}]}
{"op":"mcm","clk":"998575250","pt":1580588007642,"mc":[{"id":"1.168081860","rc":[{"batl":[[0,1000,0.02]],"ltp":1.02,"tv":5.42,"id":7698577,"hc":13.5}]}]}
{"op":"mcm","clk":"998575314","pt":1580588008017,"mc":[{"id":"1.168081860","rc":[{"trd":[[1.02,5.44]],"batb":[[0,1.02,5.41]],"batl":[[0,990,0.01]],"ltp":1.02,"tv":5.44,"id":7698577,"hc":13.5}],"tv":10.85}]}
{"op":"mcm","clk":"998577810","pt":1580588023651,"mc":[{"id":"1.168081860","rc":[{"batl":[[0,1000,2.37]],"ltp":1.02,"tv":5.41,"id":7698577,"hc":14.5}]}]}
{"op":"mcm","clk":"998577922","pt":1580588024308,"mc":[{"id":"1.168081860","rc":[{"trd":[[1.02,5.43]],"batb":[[0,1.02,5.42]],"batl":[[0,990,0.01]],"ltp":1.02,"tv":5.42,"id":7698577,"hc":14.5}],"tv":10.87}]}
{"op":"mcm","clk":"998578121","pt":1580588025651,"mc":[{"id":"1.168081860","rc":[{"batl":[[0,1000,2.37]],"ltp":1.02,"tv":5.44,"id":7698577,"hc":13.5}]}]}
{"op":"mcm","clk":"998578230","pt":1580588026245,"mc":[{"id":"1.168081860","rc":[{"trd":[[1.02,5.46]],"batb":[[0,1.02,5.4]],"batl":[[0,990,0.01]],"ltp":1.02,"tv":5.45,"id":7698577,"hc":13.5}],"tv":10.88}]}
