{"op":"mcm","clk":"978248081","pt":1580359801373,"mc":[{"id":"1.168081820","marketDefinition":{"bspMarket":false,"turnInPlayEnabled":true,"persistenceEnabled":true,"marketBaseRate":5.0,"eventId":"29676917","eventTypeId":"2","numberOfWinners":1,"bettingType":"ODDS","marketType":"SET_WINNER","marketTime":"2020-02-02T05:00:00.000Z","suspendTime":"2020-02-02T05:00:00.000Z","bspReconciled":false,"complete":true,"inPlay":false,"crossMatching":false,"runnersVoidable":false,"numberOfActiveRunners":2,"betDelay":0,"status":"OPEN","runners":[{"status":"ACTIVE","sortPriority":1,"id":22229228,"name":"Ram/Salisbury"},{"status":"ACTIVE","sortPriority":2,"id":15256065,"name":"Purcell/Saville"}],"regulators":["MR_INT"],"countryCode":"AU","discountAllowed":false,"timezone":"GMT","openDate":"2020-02-02T05:00:00.000Z","version":3141663677,"name":"Set 1 Winner","eventName":"Ram/Salisbury v Purcell/Saville"},"rc":[{"batb":[[0,1.01,20]],"ltp":0.0,"tv":0.0,"id":15256065},{"batb":[[0,1.01,20]],"ltp":0.0,"tv":0.0,"id":22229228}]}]}
{"op":"mcm","clk":"978248109","pt":1580359802704,"mc":[{"id":"1.168081820","marketDefinition":{"bspMarket":false,"turnInPlayEnabled":true,"persistenceEnabled":true,"marketBaseRate":5.0,"eventId":"29676917","eventTypeId":"2","numberOfWinners":1,"bettingType":"ODDS","marketType":"SET_WINNER","marketTime":"2020-02-02T05:00:00.000Z","suspendTime":"2020-02-02T05:00:00.000Z","bspReconciled":false,"complete":true,"inPlay":false,"crossMatching":false,"runnersVoidable":false,"numberOfActiveRunners":2,"betDelay":0,"status":"OPEN","runners":[{"status":"ACTIVE","sortPriority":1,"id":22229228,"name":"Ram/Salisbury"},{"status":"ACTIVE","sortPriority":2,"id":15256065,"name":"Purcell/Saville"}],"regulators":["MR_INT"],"countryCode":"AU","discountAllowed":true,"timezone":"GMT","openDate":"2020-02-02T05:00:00.000Z","version":3141663677,"name":"Set 1 Winner","eventName":"Ram/Salisbury v Purcell/Saville"}}]}
{"op":"mcm","clk":"978263627","pt":1580360419967,"mc":[{"id":"1.168081820","rc":[{"batb":[[0,1.01,10]],"ltp":0.0,"tv":0.0,"id":15256065},{"batb":[[0,1.01,10]],"ltp":0.0,"tv":0.0,"id":22229228}]}]}
{"op":"mcm","clk":"982616311","pt":1580444599088,"mc":[{"id":"1.168081820","rc":[{"batb":[[0,2.24,19.99],[1,1.01,10]],"ltp":0.0,"tv":0.0,"id":15256065},{"batb":[[0,1.57,43.5],[1,1.01,10]],"ltp":0.0,"tv":0.0,"id":22229228}]}]}
{"op":"mcm","clk":"982616506","pt":1580444606100,"mc":[{"id":"1.168081820","marketDefinition":{"bspMarket":false,"turnInPlayEnabled":true,"persistenceEnabled":true,"marketBaseRate":5.0,"eventId":"29676917","eventTypeId":"2","numberOfWinners":1,"bettingType":"ODDS","marketType":"SET_WINNER","marketTime":"2020-02-02T05:00:00.000Z","suspendTime":"2020-02-02T05:00:00.000Z","bspReconciled":false,"complete":true,"inPlay":false,"crossMatching":true,"runnersVoidable":false,"numberOfActiveRunners":2,"betDelay":0,"status":"OPEN","runners":[{"status":"ACTIVE","sortPriority":1,"id":22229228,"name":"Ram/Salisbury"},{"status":"ACTIVE","sortPriority":2,"id":15256065,"name":"Purcell/Saville"}],"regulators":["MR_INT"],"countryCode":"AU","discountAllowed":true,"timezone":"GMT","openDate":"2020-02-02T05:00:00.000Z","version":3141663677,"name":"Set 1 Winner","eventName":"Ram/Salisbury v Purcell/Saville"}}]}
{"op":"mcm","clk":"985103953","pt":1580474923166,"mc":[{"id":"1.168081820","rc":[{"batb":[[0,1.01,10],[1,1.01,0]],"ltp":0.0,"tv":0.0,"id":15256065},{"batb":[[0,1.01,10],[1,1.01,0]],"ltp":0.0,"tv":0.0,"id":22229228}]}]}
{"op":"mcm","clk":"985196151","pt":1580475589498,"mc":[{"id":"1.168081820","rc":[{"batb":[[0,2.24,19.99],[1,1.01,10]],"ltp":0.0,"tv":0.0,"id":15256065},{"batb":[[0,1.57,43.5],[1,1.01,10]],"ltp":0.0,"tv":0.0,"id":22229228}]}]}
{"op":"mcm","clk":"987037939","pt":1580493584530,"mc":[{"id":"1.168081820","rc":[{"batb":[[0,2.24,21.91]],"ltp":0.0,"tv":0.0,"id":15256065},{"batb":[[0,1.57,47.68]],"ltp":0.0,"tv":0.0,"id":22229228}]}]}
{"op":"mcm","clk":"988916539","pt":1580511681628,"mc":[{"id":"1.168081820","rc":[{"batb":[[1,1.01,12.53]],"ltp":0.0,"tv":0.0,"id":15256065},{"batb":[[1,1.01,12.53]],"ltp":0.0,"tv":0.0,"id":22229228}]}]}
{"op":"mcm","clk":"988916594","pt":1580511682450,"mc":[{"id":"1.168081820","rc":[{"batb":[[1,1.01,10.51]],"ltp":0.0,"tv":0.0,"id":15256065},{"batb":[[1,1.01,10.51]],"ltp":0.0,"tv":0.0,"id":22229228}]}]}
{"op":"mcm","clk":"988940322","pt":1580511947643,"mc":[{"id":"1.168081820","rc":[{"batb":[[1,1.01,11.01]],"ltp":0.0,"tv":0.0,"id":15256065},{"batb":[[1,1.01,11.01]],"ltp":0.0,"tv":0.0,"id":22229228}]}]}
{"op":"mcm","clk":"995031172","pt":1580568860094,"mc":[{"id":"1.168081820","rc":[{"batb":[[0,2.2,22.64]],"ltp":0.0,"tv":0.0,"id":15256065},{"batb":[[0,1.62,43.83]],"ltp":0.0,"tv":0.0,"id":22229228}]}]}
{"op":"mcm","clk":"997278919","pt":1580579986749,"mc":[{"id":"1.168081820","rc":[{"batb":[[0,2.2,24.6]],"ltp":0.0,"tv":0.0,"id":15256065},{"batb":[[0,1.62,47.62]],"ltp":0.0,"tv":0.0,"id":22229228}]}]}
{"op":"mcm","clk":"998273033","pt":1580585947672,"mc":[{"id":"1.168081820","rc":[{"batb":[[0,2.24,23.81],[1,2.2,24.6],[2,1.01,11.01]],"ltp":0.0,"tv":0.0,"id":15256065},{"batb":[[1,1.57,51.79],[2,1.01,11.01]],"ltp":0.0,"tv":0.0,"id":22229228}]}]}
{"op":"mcm","clk":"998273056","pt":1580585947791,"mc":[{"id":"1.168081820","rc":[{"batb":[[1,1.01,11.01],[2,1.01,0]],"ltp":0.0,"tv":0.0,"id":15256065},{"batb":[[0,1.57,51.79],[1,1.01,11.01],[2,1.01,0]],"ltp":0.0,"tv":0.0,"id":22229228}]}]}
{"op":"mcm","clk":"998354931","pt":1580586439673,"mc":[{"id":"1.168081820","rc":[{"trd":[[2.24,40]],"batb":[[0,2.24,3.81]],"ltp":2.24,"tv":40.0,"id":15256065}],"tv":40.0}]}
{"op":"mcm","clk":"998355061","pt":1580586440474,"mc":[{"id":"1.168081820","rc":[{"batb":[[0,2.06,27.85]],"ltp":2.24,"tv":40.0,"id":15256065}]}]}
{"op":"mcm","clk":"998506720","pt":1580587559387,"mc":[{"id":"1.168081820","rc":[{"batb":[[0,2.38,21.39]],"ltp":2.24,"tv":40.0,"id":15256065},{"batb":[[0,1.53,55.7]],"ltp":0.0,"tv":0.0,"id":22229228}]}]}
{"op":"mcm","clk":"998660090","pt":1580588552615,"mc":[{"id":"1.168081820","rc":[{"trd":[[2.38,6.85]],"ltp":2.38,"tv":46.85,"id":15256065},{"trd":[[1.73,9.42]],"ltp":1.73,"tv":9.42,"id":22229228}],"tv":56.27}]}
{"op":"mcm","clk":"999128820","pt":1580592310886,"mc":[{"id":"1.168081820","rc":[{"batl":[[0,2.88,3.79]],"ltp":2.38,"tv":46.85,"id":15256065},{"batl":[[0,1.72,7.57]],"ltp":1.73,"tv":9.42,"id":22229228}]}]}
{"op":"mcm","clk":"999412302","pt":1580595018606,"mc":[{"id":"1.168081820","rc":[{"batb":[[1,2.24,23.81],[2,1.01,11.01]],"ltp":2.38,"tv":46.85,"id":15256065},{"batb":[[0,1.57,51.79],[1,1.53,55.7],[2,1.01,11.01]],"ltp":1.73,"tv":9.42,"id":22229228}]}]}
{"op":"mcm","clk":"999412315","pt":1580595018713,"mc":[{"id":"1.168081820","rc":[{"batb":[[0,2.24,23.81],[1,1.01,11.01],[2,1.01,0]],"ltp":2.38,"tv":46.85,"id":15256065},{"batb":[[1,1.01,11.01],[2,1.01,0]],"ltp":1.73,"tv":9.42,"id":22229228}]}]}
{"op":"mcm","clk":"999570876","pt":1580597131121,"mc":[{"id":"1.168081820","rc":[{"trd":[[2.38,12.32]],"batl":[[0,2.38,14.53],[1,2.88,3.79]],"ltp":2.38,"tv":52.32,"id":15256065},{"trd":[[1.72,7.57]],"ltp":1.72,"tv":16.99,"id":22229228}],"tv":69.31}]}
{"op":"mcm","clk":"999624566","pt":1580598003561,"mc":[{"id":"1.168081820","rc":[{"batb":[[0,2.24,35.71]],"ltp":2.38,"tv":52.32,"id":15256065},{"batb":[[0,1.57,77.69]],"ltp":1.72,"tv":16.99,"id":22229228}]}]}
{"op":"mcm","clk":"999890636","pt":1580602236800,"mc":[{"id":"1.168081820","rc":[{"trd":[[2.38,41.38]],"batb":[[0,2.38,5.47],[1,2.24,35.71],[2,1.01,11.01]],"batl":[[0,2.88,3.79],[1,2.88,0]],"ltp":2.38,"tv":81.38,"id":15256065}],"tv":98.37}]}
{"op":"mcm","clk":"1000055812","pt":1580605543659,"mc":[{"id":"1.168081820","rc":[{"batb":[[2,1.01,13.01]],"ltp":2.38,"tv":81.38,"id":15256065},{"batb":[[1,1.01,13.01]],"ltp":1.72,"tv":16.99,"id":22229228}]}]}
{"op":"mcm","clk":"1000055831","pt":1580605544072,"mc":[{"id":"1.168081820","rc":[{"batb":[[2,1.01,11.02]],"ltp":2.38,"tv":81.38,"id":15256065},{"batb":[[1,1.01,11.02]],"ltp":1.72,"tv":16.99,"id":22229228}]}]}
{"op":"mcm","clk":"1000324261","pt":1580612402513,"mc":[{"id":"1.168081820","rc":[{"batb":[[1,2.24,47.62]],"ltp":2.38,"tv":81.38,"id":15256065},{"batb":[[0,1.57,103.59]],"ltp":1.72,"tv":16.99,"id":22229228}]}]}
{"op":"mcm","clk":"1000351189","pt":1580612888969,"mc":[{"id":"1.168081820","marketDefinition":{"bspMarket":false,"turnInPlayEnabled":true,"persistenceEnabled":true,"marketBaseRate":5.0,"eventId":"29676917","eventTypeId":"2","numberOfWinners":1,"bettingType":"ODDS","marketType":"SET_WINNER","marketTime":"2020-02-02T04:00:00.000Z","suspendTime":"2020-02-02T04:00:00.000Z","bspReconciled":false,"complete":true,"inPlay":false,"crossMatching":true,"runnersVoidable":false,"numberOfActiveRunners":2,"betDelay":0,"status":"OPEN","runners":[{"status":"ACTIVE","sortPriority":1,"id":22229228,"name":"Ram/Salisbury"},{"status":"ACTIVE","sortPriority":2,"id":15256065,"name":"Purcell/Saville"}],"regulators":["MR_INT"],"countryCode":"AU","discountAllowed":true,"timezone":"GMT","openDate":"2020-02-02T05:00:00.000Z","version":3148089682,"name":"Set 1 Winner","eventName":"Ram/Salisbury v Purcell/Saville"}}]}
{"op":"mcm","clk":"1000351354","pt":1580612891105,"mc":[{"id":"1.168081820","marketDefinition":{"bspMarket":false,"turnInPlayEnabled":true,"persistenceEnabled":true,"marketBaseRate":5.0,"eventId":"29676917","eventTypeId":"2","numberOfWinners":1,"bettingType":"ODDS","marketType":"SET_WINNER","marketTime":"2020-02-02T04:00:00.000Z","suspendTime":"2020-02-02T04:00:00.000Z","bspReconciled":false,"complete":true,"inPlay":false,"crossMatching":true,"runnersVoidable":false,"numberOfActiveRunners":2,"betDelay":0,"status":"OPEN","runners":[{"status":"ACTIVE","sortPriority":1,"id":22229228,"name":"Ram/Salisbury"},{"status":"ACTIVE","sortPriority":2,"id":15256065,"name":"Purcell/Saville"}],"regulators":["MR_INT"],"countryCode":"AU","discountAllowed":true,"timezone":"GMT","openDate":"2020-02-02T04:00:00.000Z","version":3148089682,"name":"Set 1 Winner","eventName":"Ram/Salisbury v Purcell/Saville"}}]}
{"op":"mcm","clk":"1000367381","pt":1580613148630,"mc":[{"id":"1.168081820","rc":[{"batb":[[2,1.01,12.7]],"ltp":2.38,"tv":81.38,"id":15256065},{"batb":[[1,1.01,12.7]],"ltp":1.72,"tv":16.99,"id":22229228}]}]}
{"op":"mcm","clk":"1000367431","pt":1580613149353,"mc":[{"id":"1.168081820","rc":[{"batb":[[0,2.4,1.05],[1,2.38,5.47],[2,2.24,47.62]],"ltp":2.38,"tv":81.38,"id":15256065},{"batb":[[0,1.58,1.6],[1,1.57,103.59],[2,1.01,11.02]],"ltp":1.72,"tv":16.99,"id":22229228}]}]}
{"op":"mcm","clk":"1000513632","pt":1580615891879,"mc":[{"id":"1.168081820","rc":[{"batl":[[0,1.65,4.56]],"ltp":1.72,"tv":16.99,"id":22229228}]}]}
{"op":"mcm","clk":"1000523359","pt":1580616080267,"mc":[{"id":"1.168081820","rc":[{"batb":[[0,2.54,2],[1,2.4,1.05],[2,2.38,5.47]],"ltp":2.38,"tv":81.38,"id":15256065},{"batb":[[0,1.58,3.6]],"ltp":1.72,"tv":16.99,"id":22229228}]}]}
{"op":"mcm","clk":"1000550747","pt":1580616679599,"mc":[{"id":"1.168081820","rc":[{"batb":[[0,1.58,1.6]],"ltp":1.72,"tv":16.99,"id":22229228}]}]}
{"op":"mcm","clk":"1000550784","pt":1580616680320,"mc":[{"id":"1.168081820","rc":[{"batb":[[0,2.4,1.05],[1,2.38,5.47],[2,2.24,47.62]],"ltp":2.38,"tv":81.38,"id":15256065}]}]}
{"op":"mcm","clk":"1000551384","pt":1580616691531,"mc":[{"id":"1.168081820","rc":[{"batb":[[0,2.4,3.05]],"ltp":2.38,"tv":81.38,"id":15256065},{"batb":[[0,1.58,3.6]],"ltp":1.72,"tv":16.99,"id":22229228}]}]}
{"op":"mcm","clk":"1000559953","pt":1580616820692,"mc":[{"id":"1.168081820","marketDefinition":{"bspMarket":false,"turnInPlayEnabled":true,"persistenceEnabled":true,"marketBaseRate":5.0,"eventId":"29676917","eventTypeId":"2","numberOfWinners":1,"bettingType":"ODDS","marketType":"SET_WINNER","marketTime":"2020-02-02T04:00:00.000Z","suspendTime":"2020-02-02T04:00:00.000Z","bspReconciled":false,"complete":true,"inPlay":true,"crossMatching":true,"runnersVoidable":false,"numberOfActiveRunners":2,"betDelay":3,"status":"OPEN","runners":[{"status":"ACTIVE","sortPriority":1,"id":22229228,"name":"Ram/Salisbury"},{"status":"ACTIVE","sortPriority":2,"id":15256065,"name":"Purcell/Saville"}],"regulators":["MR_INT"],"countryCode":"AU","discountAllowed":true,"timezone":"GMT","openDate":"2020-02-02T04:00:00.000Z","version":3148152294,"name":"Set 1 Winner","eventName":"Ram/Salisbury v Purcell/Saville"},"rc":[{"batb":[[0,1.01,10.52],[1,2.38,0],[2,2.24,0]],"ltp":2.38,"tv":81.38,"id":15256065},{"batb":[[0,1.01,10.52],[1,1.57,0],[2,1.01,0]],"ltp":1.72,"tv":16.99,"id":22229228}]}]}
{"op":"mcm","clk":"1000579733","pt":1580617090096,"mc":[{"id":"1.168081820","rc":[{"batb":[[0,2.04,394.09],[1,1.01,10.52]],"ltp":2.38,"tv":81.38,"id":15256065},{"batb":[[0,1.34,465.44],[1,1.01,10.51]],"ltp":1.72,"tv":16.99,"id":22229228}]}]}
{"op":"mcm","clk":"1000581320","pt":1580617112300,"mc":[{"id":"1.168081820","rc":[{"batb":[[0,1.01,10.52],[1,1.01,0]],"ltp":2.38,"tv":81.38,"id":15256065},{"batb":[[0,1.01,10.52],[1,1.01,0]],"ltp":1.72,"tv":16.99,"id":22229228}]}]}
{"op":"mcm","clk":"1000581620","pt":1580617116579,"mc":[{"id":"1.168081820","rc":[{"batb":[[0,2.38,382.3],[1,1.01,10.52]],"ltp":2.38,"tv":81.38,"id":15256065},{"batb":[[0,1.23,516.49],[1,1.01,10.51]],"ltp":1.72,"tv":16.99,"id":22229228}]}]}
{"op":"mcm","clk":"1000585171","pt":1580617162406,"mc":[{"id":"1.168081820","rc":[{"batb":[[0,1.01,10.52],[1,1.01,0]],"ltp":1.72,"tv":16.99,"id":22229228}]}]}
{"op":"mcm","clk":"1000585501","pt":1580617166617,"mc":[{"id":"1.168081820","rc":[{"batb":[[0,1.31,477.52],[1,1.01,10.51]],"ltp":1.72,"tv":16.99,"id":22229228}]}]}
{"op":"mcm","clk":"1000587646","pt":1580617194485,"mc":[{"id":"1.168081820","rc":[{"batb":[[0,1.01,10.52],[1,1.01,0]],"ltp":2.38,"tv":81.38,"id":15256065},{"batb":[[0,1.01,10.52],[1,1.01,0]],"ltp":1.72,"tv":16.99,"id":22229228}]}]}
{"op":"mcm","clk":"1000587874","pt":1580617198000,"mc":[{"id":"1.168081820","rc":[{"batb":[[0,2.52,381.46],[1,1.01,10.52]],"ltp":2.38,"tv":81.38,"id":15256065},{"batb":[[0,1.2,530.87],[1,1.01,10.51]],"ltp":1.72,"tv":16.99,"id":22229228}]}]}
{"op":"mcm","clk":"1000589439","pt":1580617220571,"mc":[{"id":"1.168081820","rc":[{"batb":[[0,1.01,10.52],[1,1.01,0]],"ltp":2.38,"tv":81.38,"id":15256065},{"batb":[[0,1.01,10.52],[1,1.01,0]],"ltp":1.72,"tv":16.99,"id":22229228}]}]}
{"op":"mcm","clk":"1000590832","pt":1580617241270,"mc":[{"id":"1.168081820","rc":[{"batb":[[0,2.62,379.26],[1,1.01,10.52]],"ltp":2.38,"tv":81.38,"id":15256065},{"batb":[[0,1.18,549.73],[1,1.01,10.51]],"ltp":1.72,"tv":16.99,"id":22229228}]}]}
{"op":"mcm","clk":"1000591444","pt":1580617251606,"mc":[{"id":"1.168081820","rc":[{"batb":[[0,1.01,10.52],[1,1.01,0]],"ltp":1.72,"tv":16.99,"id":22229228}]}]}
{"op":"mcm","clk":"1000591693","pt":1580617255321,"mc":[{"id":"1.168081820","rc":[{"batb":[[0,1.25,505.1],[1,1.01,10.51]],"ltp":1.72,"tv":16.99,"id":22229228}]}]}
{"op":"mcm","clk":"1000593356","pt":1580617278764,"mc":[{"id":"1.168081820","rc":[{"batb":[[0,1.01,10.52],[1,1.01,0]],"ltp":2.38,"tv":81.38,"id":15256065},{"batb":[[0,1.01,10.52],[1,1.01,0]],"ltp":1.72,"tv":16.99,"id":22229228}]}]}
{"op":"mcm","clk":"1000593931","pt":1580617286551,"mc":[{"id":"1.168081820","rc":[{"batb":[[0,1.97,394.86],[1,1.01,10.52]],"ltp":2.38,"tv":81.38,"id":15256065},{"batb":[[0,1.38,448.46],[1,1.01,10.51]],"ltp":1.72,"tv":16.99,"id":22229228}]}]}
{"op":"mcm","clk":"1000596875","pt":1580617325903,"mc":[{"id":"1.168081820","rc":[{"batb":[[0,1.01,10.52],[1,1.01,0]],"ltp":2.38,"tv":81.38,"id":15256065},{"batb":[[0,1.01,10.52],[1,1.01,0]],"ltp":1.72,"tv":16.99,"id":22229228}]}]}
{"op":"mcm","clk":"1000597220","pt":1580617330339,"mc":[{"id":"1.168081820","rc":[{"batb":[[0,2.3,385.09],[1,1.01,10.52]],"ltp":2.38,"tv":81.38,"id":15256065},{"batb":[[0,1.25,505.1],[1,1.01,10.51]],"ltp":1.72,"tv":16.99,"id":22229228}]}]}
{"op":"mcm","clk":"1000598603","pt":1580617349989,"mc":[{"id":"1.168081820","rc":[{"batb":[[0,1.01,10.52],[1,1.01,0]],"ltp":2.38,"tv":81.38,"id":15256065},{"batb":[[0,1.01,10.52],[1,1.01,0]],"ltp":1.72,"tv":16.99,"id":22229228}]}]}
{"op":"mcm","clk":"1000599191","pt":1580617358372,"mc":[{"id":"1.168081820","rc":[{"batb":[[0,1.97,394.86],[1,1.01,10.52]],"ltp":2.38,"tv":81.38,"id":15256065},{"batb":[[0,1.38,448.46],[1,1.01,10.51]],"ltp":1.72,"tv":16.99,"id":22229228}]}]}
{"op":"mcm","clk":"1000600314","pt":1580617375405,"mc":[{"id":"1.168081820","rc":[{"batb":[[0,2,83.3],[1,1.97,394.86],[2,1.01,10.52]],"ltp":2.38,"tv":81.38,"id":15256065}]}]}
{"op":"mcm","clk":"1000601947","pt":1580617400035,"mc":[{"id":"1.168081820","rc":[{"batb":[[1,1.01,10.52],[2,1.01,0]],"ltp":2.38,"tv":81.38,"id":15256065},{"batb":[[0,1.01,10.52],[1,1.01,0]],"ltp":1.72,"tv":16.99,"id":22229228}]}]}
{"op":"mcm","clk":"1000602209","pt":1580617403761,"mc":[{"id":"1.168081820","rc":[{"batb":[[0,2.3,385.09],[1,2,83.3],[2,1.01,10.52]],"ltp":2.38,"tv":81.38,"id":15256065},{"batb":[[0,1.25,505.1],[1,1.01,10.51]],"ltp":1.72,"tv":16.99,"id":22229228}]}]}
{"op":"mcm","clk":"1000602670","pt":1580617410588,"mc":[{"id":"1.168081820","rc":[{"batb":[[1,1.01,10.52],[2,1.01,0]],"ltp":2.38,"tv":81.38,"id":15256065}]}]}
{"op":"mcm","clk":"1000602907","pt":1580617413694,"mc":[{"id":"1.168081820","rc":[{"batb":[[0,2.32,83.3],[1,2.3,385.09],[2,1.01,10.52]],"ltp":2.38,"tv":81.38,"id":15256065}]}]}
{"op":"mcm","clk":"1000603996","pt":1580617428140,"mc":[{"id":"1.168081820","rc":[{"batb":[[1,1.01,10.52],[2,1.01,0]],"ltp":2.38,"tv":81.38,"id":15256065},{"batb":[[0,1.01,10.52],[1,1.01,0]],"ltp":1.72,"tv":16.99,"id":22229228}]}]}
{"op":"mcm","clk":"1000604602","pt":1580617435957,"mc":[{"id":"1.168081820","rc":[{"batb":[[1,1.97,394.86],[2,1.01,10.52]],"ltp":2.38,"tv":81.38,"id":15256065},{"batb":[[0,1.38,448.46],[1,1.01,10.51]],"ltp":1.72,"tv":16.99,"id":22229228}]}]}
{"op":"mcm","clk":"1000604845","pt":1580617439222,"mc":[{"id":"1.168081820","rc":[{"batb":[[0,1.97,394.86],[1,1.01,10.52],[2,1.01,0]],"ltp":2.38,"tv":81.38,"id":15256065}]}]}
{"op":"mcm","clk":"1000605087","pt":1580617442329,"mc":[{"id":"1.168081820","rc":[{"batb":[[0,2,83.3],[1,1.97,394.86],[2,1.01,10.52]],"ltp":2.38,"tv":81.38,"id":15256065}]}]}
{"op":"mcm","clk":"1000607139","pt":1580617470308,"mc":[{"id":"1.168081820","rc":[{"batb":[[1,1.01,10.52],[2,1.01,0]],"ltp":2.38,"tv":81.38,"id":15256065},{"batb":[[0,1.01,10.52],[1,1.01,0]],"ltp":1.72,"tv":16.99,"id":22229228}]}]}
{"op":"mcm","clk":"1000607475","pt":1580617474278,"mc":[{"id":"1.168081820","rc":[{"batb":[[0,2.3,385.09],[1,2,83.3],[2,1.01,10.52]],"ltp":2.38,"tv":81.38,"id":15256065},{"batb":[[0,1.25,505.1],[1,1.01,10.51]],"ltp":1.72,"tv":16.99,"id":22229228}]}]}
{"op":"mcm","clk":"1000608968","pt":1580617494273,"mc":[{"id":"1.168081820","rc":[{"batb":[[0,2,83.3],[1,1.01,10.52],[2,1.01,0]],"ltp":2.38,"tv":81.38,"id":15256065},{"batb":[[0,1.01,10.52],[1,1.01,0]],"ltp":1.72,"tv":16.99,"id":22229228}]}]}
{"op":"mcm","clk":"1000610519","pt":1580617512615,"mc":[{"id":"1.168081820","rc":[{"batb":[[1,1.97,394.86],[2,1.01,10.52]],"ltp":2.38,"tv":81.38,"id":15256065},{"batb":[[0,1.38,448.46],[1,1.01,10.51]],"ltp":1.72,"tv":16.99,"id":22229228}]}]}
{"op":"mcm","clk":"1000613765","pt":1580617553364,"mc":[{"id":"1.168081820","rc":[{"batb":[[0,1.01,10.52],[1,1.01,0]],"ltp":1.72,"tv":16.99,"id":22229228}]}]}
{"op":"mcm","clk":"1000614025","pt":1580617556881,"mc":[{"id":"1.168081820","rc":[{"batb":[[0,1.46,435.71],[1,1.01,10.51]],"ltp":1.72,"tv":16.99,"id":22229228}]}]}
{"op":"mcm","clk":"1000615612","pt":1580617577260,"mc":[{"id":"1.168081820","rc":[{"batb":[[0,1.97,394.86],[1,1.01,10.52],[2,1.01,0]],"ltp":2.38,"tv":81.38,"id":15256065}]}]}
{"op":"mcm","clk":"1000615794","pt":1580617580218,"mc":[{"id":"1.168081820","rc":[{"batb":[[1,1.9,83.3],[2,1.01,10.52]],"ltp":2.38,"tv":81.38,"id":15256065}]}]}
{"op":"mcm","clk":"1000616191","pt":1580617583484,"mc":[{"id":"1.168081820","rc":[{"batb":[[0,1.9,83.3],[1,1.01,10.52],[2,1.01,0]],"ltp":2.38,"tv":81.38,"id":15256065},{"batb":[[0,1.01,10.52],[1,1.01,0]],"ltp":1.72,"tv":16.99,"id":22229228}]}]}
{"op":"mcm","clk":"1000616529","pt":1580617587220,"mc":[{"id":"1.168081820","rc":[{"batb":[[1,1.77,402.27],[2,1.01,10.52]],"ltp":2.38,"tv":81.38,"id":15256065},{"batb":[[0,1.5,426.9],[1,1.01,10.52]],"ltp":1.72,"tv":16.99,"id":22229228}]}]}
{"op":"mcm","clk":"1000617522","pt":1580617597468,"mc":[{"id":"1.168081820","rc":[{"batb":[[0,1.77,402.27],[1,1.01,10.52],[2,1.01,0]],"ltp":2.38,"tv":81.38,"id":15256065}]}]}
{"op":"mcm","clk":"1000617736","pt":1580617600620,"mc":[{"id":"1.168081820","rc":[{"batb":[[0,1.8,83.3],[1,1.77,402.27],[2,1.01,10.52]],"ltp":2.38,"tv":81.38,"id":15256065}]}]}
{"op":"mcm","clk":"1000624044","pt":1580617695660,"mc":[{"id":"1.168081820","rc":[{"batb":[[0,1.01,10.52],[1,1.01,0]],"ltp":1.72,"tv":16.99,"id":22229228}]}]}
{"op":"mcm","clk":"1000624325","pt":1580617699835,"mc":[{"id":"1.168081820","rc":[{"batb":[[0,1.58,416.47],[1,1.01,10.52]],"ltp":1.72,"tv":16.99,"id":22229228}]}]}
{"op":"mcm","clk":"1000625264","pt":1580617715067,"mc":[{"id":"1.168081820","rc":[{"batb":[[0,1.77,402.27],[1,1.01,10.52],[2,1.01,0]],"ltp":2.38,"tv":81.38,"id":15256065}]}]}
{"op":"mcm","clk":"1000627068","pt":1580617744314,"mc":[{"id":"1.168081820","rc":[{"batb":[[0,1.01,10.52],[1,1.01,0]],"ltp":1.72,"tv":16.99,"id":22229228}]}]}
{"op":"mcm","clk":"1000627310","pt":1580617748027,"mc":[{"id":"1.168081820","rc":[{"batb":[[0,1.46,435.71],[1,1.01,10.51]],"ltp":1.72,"tv":16.99,"id":22229228}]}]}
{"op":"mcm","clk":"1000628370","pt":1580617762546,"mc":[{"id":"1.168081820","rc":[{"batb":[[0,1.8,83.3],[1,1.77,402.27],[2,1.01,10.52]],"ltp":2.38,"tv":81.38,"id":15256065}]}]}
{"op":"mcm","clk":"1000628616","pt":1580617766882,"mc":[{"id":"1.168081820","rc":[{"batb":[[1,1.01,10.52],[2,1.01,0]],"ltp":2.38,"tv":81.38,"id":15256065}]}]}
{"op":"mcm","clk":"1000628881","pt":1580617771052,"mc":[{"id":"1.168081820","rc":[{"batb":[[0,1.86,398.62],[1,1.8,83.3],[2,1.01,10.52]],"ltp":2.38,"tv":81.38,"id":15256065}]}]}
{"op":"mcm","clk":"1000629313","pt":1580617778256,"mc":[{"id":"1.168081820","rc":[{"batb":[[1,1.01,10.52],[2,1.01,0]],"ltp":2.38,"tv":81.38,"id":15256065}]}]}
{"op":"mcm","clk":"1000629493","pt":1580617781395,"mc":[{"id":"1.168081820","rc":[{"batb":[[0,1.87,83.3],[1,1.86,398.62],[2,1.01,10.52]],"ltp":2.38,"tv":81.38,"id":15256065}]}]}
{"op":"mcm","clk":"1000631060","pt":1580617807134,"mc":[{"id":"1.168081820","rc":[{"trd":[[1.46,92.56],[1.48,0.02]],"batb":[[0,1.46,389.41]],"ltp":1.46,"tv":109.57,"id":22229228}],"tv":190.95}]}
{"op":"mcm","clk":"1000634640","pt":1580617872150,"mc":[{"id":"1.168081820","rc":[{"batb":[[1,1.01,10.52],[2,1.01,0]],"ltp":2.38,"tv":81.38,"id":15256065},{"batb":[[0,1.01,10.51],[1,1.01,0]],"ltp":1.46,"tv":109.57,"id":22229228}]}]}
{"op":"mcm","clk":"1000635300","pt":1580617884416,"mc":[{"id":"1.168081820","rc":[{"batb":[[0,1.01,10.52],[1,1.01,0]],"ltp":2.38,"tv":81.38,"id":15256065}]}]}
{"op":"mcm","clk":"1000635407","pt":1580617885964,"mc":[{"id":"1.168081820","rc":[{"batb":[[0,1.77,440.45],[1,1.01,10.52]],"ltp":2.38,"tv":81.38,"id":15256065},{"batb":[[0,1.5,381.78],[1,1.01,10.51]],"ltp":1.46,"tv":109.57,"id":22229228}]}]}
{"op":"mcm","clk":"1000635495","pt":1580617887517,"mc":[{"id":"1.168081820","rc":[{"batb":[[1,1.74,83.3],[2,1.01,10.52]],"ltp":2.38,"tv":81.38,"id":15256065}]}]}
{"op":"mcm","clk":"1000635802","pt":1580617892665,"mc":[{"id":"1.168081820","rc":[{"batb":[[1,1.01,10.52],[2,1.01,0]],"ltp":2.38,"tv":81.38,"id":15256065}]}]}
{"op":"mcm","clk":"1000635994","pt":1580617895754,"mc":[{"id":"1.168081820","rc":[{"batb":[[0,2,83.3],[1,1.77,440.45],[2,1.01,10.52]],"ltp":2.38,"tv":81.38,"id":15256065}]}]}
{"op":"mcm","clk":"1000637673","pt":1580617924166,"mc":[{"id":"1.168081820","rc":[{"batb":[[1,1.01,10.52],[2,1.01,0]],"ltp":2.38,"tv":81.38,"id":15256065},{"batb":[[0,1.01,10.51],[1,1.01,0]],"ltp":1.46,"tv":109.57,"id":22229228}]}]}
{"op":"mcm","clk":"1000637879","pt":1580617927774,"mc":[{"id":"1.168081820","rc":[{"batb":[[1,1.97,429.21],[2,1.01,10.52]],"ltp":2.38,"tv":81.38,"id":15256065},{"batb":[[0,1.38,399.16],[1,1.01,10.51]],"ltp":1.46,"tv":109.57,"id":22229228}]}]}
{"op":"mcm","clk":"1000639676","pt":1580617961329,"mc":[{"id":"1.168081820","rc":[{"batb":[[1,1.01,10.52],[2,1.01,0]],"ltp":2.38,"tv":81.38,"id":15256065},{"batb":[[0,1.01,10.51],[1,1.01,0]],"ltp":1.46,"tv":109.57,"id":22229228}]}]}
{"op":"mcm","clk":"1000639873","pt":1580617964931,"mc":[{"id":"1.168081820","rc":[{"batb":[[0,2.38,410.59],[1,2,83.3],[2,1.01,10.52]],"ltp":2.38,"tv":81.38,"id":15256065},{"batb":[[0,1.23,459.68],[1,1.01,10.51]],"ltp":1.46,"tv":109.57,"id":22229228}]}]}
{"op":"mcm","clk":"1000640406","pt":1580617973342,"mc":[{"id":"1.168081820","rc":[{"batb":[[1,1.01,10.52],[2,1.01,0]],"ltp":2.38,"tv":81.38,"id":15256065}]}]}
{"op":"mcm","clk":"1000640597","pt":1580617976440,"mc":[{"id":"1.168081820","rc":[{"batb":[[0,2.44,83.3],[1,2.38,410.59],[2,1.01,10.52]],"ltp":2.38,"tv":81.38,"id":15256065}]}]}
{"op":"mcm","clk":"1000641045","pt":1580617984473,"mc":[{"id":"1.168081820","rc":[{"batb":[[1,1.01,10.52],[2,1.01,0]],"ltp":2.38,"tv":81.38,"id":15256065},{"batb":[[0,1.01,10.51],[1,1.01,0]],"ltp":1.46,"tv":109.57,"id":22229228}]}]}
{"op":"mcm","clk":"1000641374","pt":1580617989941,"mc":[{"id":"1.168081820","rc":[{"batb":[[0,2.52,408.21],[1,2.44,83.3],[2,1.01,10.52]],"ltp":2.38,"tv":81.38,"id":15256065},{"batb":[[0,1.2,473.58],[1,1.01,10.51]],"ltp":1.46,"tv":109.57,"id":22229228}]}]}
{"op":"mcm","clk":"1000641736","pt":1580617996412,"mc":[{"id":"1.168081820","rc":[{"batb":[[0,2.44,83.3],[1,1.01,10.52],[2,1.01,0]],"ltp":2.38,"tv":81.38,"id":15256065},{"batb":[[0,1.01,10.51],[1,1.01,0]],"ltp":1.46,"tv":109.57,"id":22229228}]}]}
{"op":"mcm","clk":"1000641849","pt":1580617998121,"mc":[{"id":"1.168081820","rc":[{"batb":[[0,1.01,10.52],[1,1.01,0]],"ltp":2.38,"tv":81.38,"id":15256065}]}]}
{"op":"mcm","clk":"1000642022","pt":1580618001219,"mc":[{"id":"1.168081820","rc":[{"batb":[[0,2.6,83.3],[1,1.01,10.52]],"ltp":2.38,"tv":81.38,"id":15256065}]}]}
{"op":"mcm","clk":"1000642109","pt":1580618003020,"mc":[{"id":"1.168081820","rc":[{"batb":[[1,1.97,429.21],[2,1.01,10.52]],"ltp":2.38,"tv":81.38,"id":15256065},{"batb":[[0,1.38,399.16],[1,1.01,10.51]],"ltp":1.46,"tv":109.57,"id":22229228}]}]}
{"op":"mcm","clk":"1000642154","pt":1580618003946,"mc":[{"id":"1.168081820","rc":[{"batb":[[0,1.97,429.21],[1,1.01,10.52],[2,1.01,0]],"ltp":2.38,"tv":81.38,"id":15256065}]}]}
{"op":"mcm","clk":"1000643072","pt":1580618020926,"mc":[{"id":"1.168081820","rc":[{"batb":[[0,2,83.3],[1,1.97,429.21],[2,1.01,10.52]],"ltp":2.38,"tv":81.38,"id":15256065}]}]}
{"op":"mcm","clk":"1000643586","pt":1580618031574,"mc":[{"id":"1.168081820","rc":[{"batb":[[0,1.01,10.51],[1,1.01,0]],"ltp":1.46,"tv":109.57,"id":22229228}]}]}
{"op":"mcm","clk":"1000643746","pt":1580618035048,"mc":[{"id":"1.168081820","rc":[{"batb":[[0,1.46,389.02],[1,1.01,10.51]],"ltp":1.46,"tv":109.57,"id":22229228}]}]}
{"op":"mcm","clk":"1000644364","pt":1580618047200,"mc":[{"id":"1.168081820","rc":[{"batb":[[0,1.97,429.21],[1,1.01,10.52],[2,1.01,0]],"ltp":2.38,"tv":81.38,"id":15256065}]}]}
{"op":"mcm","clk":"1000644911","pt":1580618058587,"mc":[{"id":"1.168081820","rc":[{"batb":[[0,1.01,10.51],[1,1.01,0]],"ltp":1.46,"tv":109.57,"id":22229228}]}]}
{"op":"mcm","clk":"1000645089","pt":1580618062218,"mc":[{"id":"1.168081820","rc":[{"batb":[[0,1.38,399.16],[1,1.01,10.51]],"ltp":1.46,"tv":109.57,"id":22229228}]}]}
{"op":"mcm","clk":"1000645656","pt":1580618073606,"mc":[{"id":"1.168081820","rc":[{"batl":[[0,1.46,3.79]],"ltp":1.46,"tv":109.57,"id":22229228}]}]}
{"op":"mcm","clk":"1000647048","pt":1580618098771,"mc":[{"id":"1.168081820","rc":[{"batb":[[0,1.01,10.51],[1,1.01,0]],"ltp":1.46,"tv":109.57,"id":22229228}]}]}
{"op":"mcm","clk":"1000647257","pt":1580618102549,"mc":[{"id":"1.168081820","rc":[{"trd":[[1.46,100.14]],"ltp":1.46,"tv":117.14,"id":22229228}],"tv":198.52}]}
{"op":"mcm","clk":"1000648589","pt":1580618125717,"mc":[{"id":"1.168081820","rc":[{"batb":[[0,1.44,385.21],[1,1.01,10.51]],"ltp":1.46,"tv":117.14,"id":22229228}]}]}
{"op":"mcm","clk":"1000649148","pt":1580618134813,"mc":[{"id":"1.168081820","rc":[{"batb":[[0,1.01,10.52],[1,1.01,0]],"ltp":2.38,"tv":81.38,"id":15256065},{"batb":[[0,1.01,10.51],[1,1.01,0]],"ltp":1.46,"tv":117.14,"id":22229228}]}]}
{"op":"mcm","clk":"1000649444","pt":1580618139133,"mc":[{"id":"1.168081820","rc":[{"batb":[[0,1.77,443.57],[1,1.01,10.52]],"ltp":2.38,"tv":81.38,"id":15256065},{"batb":[[0,1.5,378.09],[1,1.01,10.51]],"ltp":1.46,"tv":117.14,"id":22229228}]}]}
{"op":"mcm","clk":"1000650361","pt":1580618155737,"mc":[{"id":"1.168081820","rc":[{"batb":[[0,1.8,83.3],[1,1.77,443.57],[2,1.01,10.52]],"ltp":2.38,"tv":81.38,"id":15256065}]}]}
{"op":"mcm","clk":"1000656948","pt":1580618277594,"mc":[{"id":"1.168081820","rc":[{"batb":[[1,1.01,10.52],[2,1.01,0]],"ltp":2.38,"tv":81.38,"id":15256065}]}]}
{"op":"mcm","clk":"1000657124","pt":1580618280892,"mc":[{"id":"1.168081820","rc":[{"batb":[[0,1.86,437.97],[1,1.8,83.3],[2,1.01,10.52]],"ltp":2.38,"tv":81.38,"id":15256065}]}]}
{"op":"mcm","clk":"1000657361","pt":1580618285520,"mc":[{"id":"1.168081820","rc":[{"batb":[[1,1.01,10.52],[2,1.01,0]],"ltp":2.38,"tv":81.38,"id":15256065}]}]}
{"op":"mcm","clk":"1000657515","pt":1580618288612,"mc":[{"id":"1.168081820","rc":[{"batb":[[0,1.87,83.3],[1,1.86,437.97],[2,1.01,10.52]],"ltp":2.38,"tv":81.38,"id":15256065}]}]}
{"op":"mcm","clk":"1000658294","pt":1580618303544,"mc":[{"id":"1.168081820","rc":[{"batb":[[0,1.86,437.97],[1,1.01,10.52],[2,1.01,0]],"ltp":2.38,"tv":81.38,"id":15256065}]}]}
{"op":"mcm","clk":"1000658450","pt":1580618306654,"mc":[{"id":"1.168081820","rc":[{"batb":[[0,1.9,83.3],[1,1.86,437.97],[2,1.01,10.52]],"ltp":2.38,"tv":81.38,"id":15256065}]}]}
{"op":"mcm","clk":"1000659483","pt":1580618326280,"mc":[{"id":"1.168081820","rc":[{"batb":[[0,1.01,10.51],[1,1.01,0]],"ltp":1.46,"tv":117.14,"id":22229228}]}]}
{"op":"mcm","clk":"1000659715","pt":1580618330281,"mc":[{"id":"1.168081820","rc":[{"batb":[[0,1.4,397.77],[1,1.01,10.51]],"ltp":1.46,"tv":117.14,"id":22229228}]}]}
{"op":"mcm","clk":"1000659939","pt":1580618334092,"mc":[{"id":"1.168081820","rc":[{"trd":[[1.9,11.84]],"batb":[[0,1.9,71.45]],"ltp":1.9,"tv":93.22,"id":15256065},{"trd":[[2.12,10.61]],"ltp":2.12,"tv":127.75,"id":22229228}],"tv":220.97}]}
{"op":"mcm","clk":"1000662932","pt":1580618395526,"mc":[{"id":"1.168081820","rc":[{"batb":[[0,1.01,10.52],[1,1.86,0],[2,1.01,0]],"ltp":1.9,"tv":93.22,"id":15256065}]}]}
{"op":"mcm","clk":"1000663104","pt":1580618398663,"mc":[{"id":"1.168081820","rc":[{"batb":[[0,2,71.45],[1,1.01,10.52]],"ltp":1.9,"tv":93.22,"id":15256065}]}]}
{"op":"mcm","clk":"1000663155","pt":1580618399537,"mc":[{"id":"1.168081820","rc":[{"batb":[[1,1.97,432.03],[2,1.01,10.52]],"ltp":1.9,"tv":93.22,"id":15256065}]}]}
{"op":"mcm","clk":"1000663419","pt":1580618404442,"mc":[{"id":"1.168081820","rc":[{"batb":[[1,1.01,10.52],[2,1.01,0]],"ltp":1.9,"tv":93.22,"id":15256065},{"batb":[[0,1.01,10.51],[1,1.01,0]],"ltp":2.12,"tv":127.75,"id":22229228}]}]}
{"op":"mcm","clk":"1000663614","pt":1580618408255,"mc":[{"id":"1.168081820","rc":[{"batb":[[0,2.12,423.08],[1,2,71.45],[2,1.01,10.52]],"ltp":1.9,"tv":93.22,"id":15256065},{"batb":[[0,1.31,420.15],[1,1.01,10.51]],"ltp":2.12,"tv":127.75,"id":22229228}]}]}
{"op":"mcm","clk":"1000664139","pt":1580618418957,"mc":[{"id":"1.168081820","rc":[{"batb":[[1,1.01,10.52],[2,1.01,0]],"ltp":1.9,"tv":93.22,"id":15256065}]}]}
{"op":"mcm","clk":"1000664296","pt":1580618422099,"mc":[{"id":"1.168081820","rc":[{"batb":[[0,2.14,71.45],[1,2.12,423.08],[2,1.01,10.52]],"ltp":1.9,"tv":93.22,"id":15256065}]}]}
{"op":"mcm","clk":"1000665262","pt":1580618441510,"mc":[{"id":"1.168081820","rc":[{"batb":[[1,1.01,10.52],[2,1.01,0]],"ltp":1.9,"tv":93.22,"id":15256065},{"batb":[[0,1.01,10.51],[1,1.01,0]],"ltp":2.12,"tv":127.75,"id":22229228}]}]}
{"op":"mcm","clk":"1000665452","pt":1580618445115,"mc":[{"id":"1.168081820","rc":[{"batb":[[0,2.52,410.4],[1,2.14,71.45],[2,1.01,10.52]],"ltp":1.9,"tv":93.22,"id":15256065},{"batb":[[0,1.2,468.89],[1,1.01,10.51]],"ltp":2.12,"tv":127.75,"id":22229228}]}]}
{"op":"mcm","clk":"1000665737","pt":1580618450521,"mc":[{"id":"1.168081820","rc":[{"batb":[[1,1.01,10.52],[2,1.01,0]],"ltp":1.9,"tv":93.22,"id":15256065}]}]}
{"op":"mcm","clk":"1000665880","pt":1580618453605,"mc":[{"id":"1.168081820","rc":[{"batb":[[0,2.54,71.45],[1,2.52,410.4],[2,1.01,10.52]],"ltp":1.9,"tv":93.22,"id":15256065}]}]}
{"op":"mcm","clk":"1000666517","pt":1580618464649,"mc":[{"id":"1.168081820","rc":[{"batb":[[1,1.01,10.52],[2,1.01,0]],"ltp":1.9,"tv":93.22,"id":15256065},{"batb":[[0,1.01,10.51],[1,1.01,0]],"ltp":2.12,"tv":127.75,"id":22229228}]}]}
{"op":"mcm","clk":"1000667300","pt":1580618474265,"mc":[{"id":"1.168081820","rc":[{"batb":[[0,3,405.22],[1,2.54,71.45],[2,1.01,10.52]],"ltp":1.9,"tv":93.22,"id":15256065},{"batb":[[0,1.11,614.87],[1,1.01,10.51]],"ltp":2.12,"tv":127.75,"id":22229228}]}]}
{"op":"mcm","clk":"1000667840","pt":1580618480335,"mc":[{"id":"1.168081820","rc":[{"batb":[[1,1.01,10.52],[2,1.01,0]],"ltp":1.9,"tv":93.22,"id":15256065}]}]}
{"op":"mcm","clk":"1000668004","pt":1580618483467,"mc":[{"id":"1.168081820","rc":[{"batb":[[0,3.1,71.45],[1,3,405.22],[2,1.01,10.52]],"ltp":1.9,"tv":93.22,"id":15256065}]}]}
{"op":"mcm","clk":"1000668752","pt":1580618496686,"mc":[{"id":"1.168081820","rc":[{"batb":[[1,1.01,10.52],[2,1.01,0]],"ltp":1.9,"tv":93.22,"id":15256065},{"batb":[[0,1.01,10.51],[1,1.01,0]],"ltp":2.12,"tv":127.75,"id":22229228}]}]}
{"op":"mcm","clk":"1000669078","pt":1580618502459,"mc":[{"id":"1.168081820","rc":[{"batb":[[1,2.8,401.29],[2,1.01,10.52]],"ltp":1.9,"tv":93.22,"id":15256065},{"batb":[[0,1.14,558.81],[1,1.01,10.51]],"ltp":2.12,"tv":127.75,"id":22229228}]}]}
{"op":"mcm","clk":"1000670169","pt":1580618523841,"mc":[{"id":"1.168081820","rc":[{"batb":[[1,1.01,10.52],[2,1.01,0]],"ltp":1.9,"tv":93.22,"id":15256065},{"batb":[[0,1.01,10.51],[1,1.01,0]],"ltp":2.12,"tv":127.75,"id":22229228}]}]}
{"op":"mcm","clk":"1000670510","pt":1580618529645,"mc":[{"id":"1.168081820","rc":[{"batb":[[0,3.7,394.02],[1,3.1,71.45],[2,1.01,10.52]],"ltp":1.9,"tv":93.22,"id":15256065},{"batb":[[0,1.04,1182.33],[1,1.01,10.51]],"ltp":2.12,"tv":127.75,"id":22229228}]}]}
{"op":"mcm","clk":"1000670945","pt":1580618537834,"mc":[{"id":"1.168081820","rc":[{"batb":[[1,3.1,43.92]],"ltp":1.9,"tv":93.22,"id":15256065}]}]}
{"op":"mcm","clk":"1000671262","pt":1580618544041,"mc":[{"id":"1.168081820","rc":[{"batb":[[1,1.01,10.52],[2,1.01,0]],"ltp":1.9,"tv":93.22,"id":15256065}]}]}
{"op":"mcm","clk":"1000671413","pt":1580618547173,"mc":[{"id":"1.168081820","rc":[{"batb":[[0,4.5,43.92],[1,3.7,394.02],[2,1.01,10.52]],"ltp":1.9,"tv":93.22,"id":15256065}]}]}
{"op":"mcm","clk":"1000673565","pt":1580618589305,"mc":[{"id":"1.168081820","rc":[{"batl":[[0,1.09,1.69]],"ltp":2.12,"tv":127.75,"id":22229228}]}]}
{"op":"mcm","clk":"1000675545","pt":1580618631021,"mc":[{"id":"1.168081820","rc":[{"batb":[[0,1.01,10.51],[1,1.01,0]],"ltp":2.12,"tv":127.75,"id":22229228}]}]}
{"op":"mcm","clk":"1000675731","pt":1580618634630,"mc":[{"id":"1.168081820","rc":[{"batb":[[0,1.02,2089.27],[1,1.01,10.51]],"ltp":2.12,"tv":127.75,"id":22229228}]}]}
{"op":"mcm","clk":"1000676703","pt":1580618651366,"mc":[{"id":"1.168081820","rc":[{"batb":[[0,1.01,10.51],[1,1.01,0]],"ltp":2.12,"tv":127.75,"id":22229228}]}]}
{"op":"mcm","clk":"1000676918","pt":1580618654776,"mc":[{"id":"1.168081820","rc":[{"batb":[[0,1.01,3947.74]],"ltp":2.12,"tv":127.75,"id":22229228}]}]}
{"op":"mcm","clk":"1000677941","pt":1580618670856,"mc":[{"id":"1.168081820","rc":[{"batb":[[0,3.7,394.02],[1,1.01,10.52],[2,1.01,0]],"ltp":1.9,"tv":93.22,"id":15256065}]}]}
{"op":"mcm","clk":"1000678176","pt":1580618674568,"mc":[{"id":"1.168081820","rc":[{"batb":[[0,4.8,43.92],[1,3.7,394.02],[2,1.01,10.52]],"ltp":1.9,"tv":93.22,"id":15256065}]}]}
{"op":"mcm","clk":"1000678217","pt":1580618675292,"mc":[{"id":"1.168081820","rc":[{"batb":[[0,1.01,10.51]],"ltp":2.12,"tv":127.75,"id":22229228}]}]}
{"op":"mcm","clk":"1000678434","pt":1580618678998,"mc":[{"id":"1.168081820","rc":[{"batb":[[0,1.02,2089.27],[1,1.01,10.51]],"ltp":2.12,"tv":127.75,"id":22229228}]}]}
{"op":"mcm","clk":"1000679743","pt":1580618701116,"mc":[{"id":"1.168081820","rc":[{"batb":[[0,1.01,10.51],[1,1.01,0]],"ltp":2.12,"tv":127.75,"id":22229228}]}]}
{"op":"mcm","clk":"1000680003","pt":1580618705195,"mc":[{"id":"1.168081820","rc":[{"batb":[[0,1.03,1485.92],[1,1.01,10.51]],"ltp":2.12,"tv":127.75,"id":22229228}]}]}
{"op":"mcm","clk":"1000680417","pt":1580618712313,"mc":[{"id":"1.168081820","rc":[{"batb":[[0,1.01,10.51],[1,1.01,0]],"ltp":2.12,"tv":127.75,"id":22229228}]}]}
{"op":"mcm","clk":"1000680646","pt":1580618716231,"mc":[{"id":"1.168081820","rc":[{"batb":[[0,1.01,3947.74]],"ltp":2.12,"tv":127.75,"id":22229228}]}]}
{"op":"mcm","clk":"1000682457","pt":1580618746364,"mc":[{"id":"1.168081820","rc":[{"batb":[[0,1.01,10.51]],"ltp":2.12,"tv":127.75,"id":22229228}]}]}
{"op":"mcm","clk":"1000682712","pt":1580618750672,"mc":[{"id":"1.168081820","rc":[{"batb":[[0,1.02,2089.27],[1,1.01,10.51]],"ltp":2.12,"tv":127.75,"id":22229228}]}]}
{"op":"mcm","clk":"1000683857","pt":1580618770351,"mc":[{"id":"1.168081820","rc":[{"batb":[[0,1.01,10.51],[1,1.01,0]],"ltp":2.12,"tv":127.75,"id":22229228}]}]}
{"op":"mcm","clk":"1000684058","pt":1580618773694,"mc":[{"id":"1.168081820","rc":[{"batb":[[0,1.03,1485.92],[1,1.01,10.51]],"ltp":2.12,"tv":127.75,"id":22229228}]}]}
{"op":"mcm","clk":"1000684339","pt":1580618778378,"mc":[{"id":"1.168081820","rc":[{"batb":[[1,1.01,10.52],[2,1.01,0]],"ltp":1.9,"tv":93.22,"id":15256065},{"batb":[[0,1.01,10.51],[1,1.01,0]],"ltp":2.12,"tv":127.75,"id":22229228}]}]}
{"op":"mcm","clk":"1000684653","pt":1580618784750,"mc":[{"id":"1.168081820","rc":[{"batb":[[1,4.2,390.28],[2,1.01,10.52]],"ltp":1.9,"tv":93.22,"id":15256065},{"batb":[[0,1.01,3797.09]],"ltp":2.12,"tv":127.75,"id":22229228}]}]}
{"op":"mcm","clk":"1000686658","pt":1580618821535,"mc":[{"id":"1.168081820","rc":[{"batb":[[0,1.01,10.51]],"ltp":2.12,"tv":127.75,"id":22229228}]}]}
{"op":"mcm","clk":"1000686889","pt":1580618825139,"mc":[{"id":"1.168081820","rc":[{"batl":[[0,160,36.53]],"ltp":1.9,"tv":93.22,"id":15256065}]}]}
{"op":"mcm","clk":"1000692969","pt":1580618928795,"mc":[{"id":"1.168081820","rc":[{"batb":[[0,1.01,3797.09]],"ltp":2.12,"tv":127.75,"id":22229228}]}]}
{"op":"mcm","clk":"1000694561","pt":1580618957192,"mc":[{"id":"1.168081820","rc":[{"batb":[[0,1.01,10.51]],"ltp":2.12,"tv":127.75,"id":22229228}]}]}
{"op":"mcm","clk":"1000694726","pt":1580618960132,"mc":[{"id":"1.168081820","rc":[{"batl":[[0,160,36.53]],"ltp":1.9,"tv":93.22,"id":15256065}]}]}
{"op":"mcm","clk":"1000696216","pt":1580618988637,"mc":[{"id":"1.168081820","rc":[{"batb":[[1,1.01,10.52],[2,1.01,0]],"ltp":1.9,"tv":93.22,"id":15256065}]}]}
{"op":"mcm","clk":"1000696494","pt":1580618994129,"mc":[{"id":"1.168081820","rc":[{"batb":[[1,4.4,392.02],[2,1.01,10.52]],"ltp":1.9,"tv":93.22,"id":15256065}]}]}
{"op":"mcm","clk":"1000697426","pt":1580619013938,"mc":[{"id":"1.168081820","rc":[{"batb":[[1,1.01,10.52],[2,1.01,0]],"ltp":1.9,"tv":93.22,"id":15256065}]}]}
{"op":"mcm","clk":"1000697759","pt":1580619021055,"mc":[{"id":"1.168081820","rc":[{"batb":[[1,4.3,388.08],[2,1.01,10.52]],"batl":[[0,160,36.53]],"ltp":1.9,"tv":93.22,"id":15256065}]}]}
{"op":"mcm","clk":"1000699263","pt":1580619048993,"mc":[{"id":"1.168081820","rc":[{"batb":[[1,1.01,10.52],[2,1.01,0]],"ltp":1.9,"tv":93.22,"id":15256065}]}]}
{"op":"mcm","clk":"1000699758","pt":1580619057428,"mc":[{"id":"1.168081820","rc":[{"batb":[[1,4.4,392.02],[2,1.01,10.52]],"ltp":1.9,"tv":93.22,"id":15256065}]}]}
{"op":"mcm","clk":"1000699857","pt":1580619059220,"mc":[{"id":"1.168081820","rc":[{"batb":[[0,4.4,392.02],[1,1.01,10.52],[2,1.01,0]],"ltp":1.9,"tv":93.22,"id":15256065}]}]}
{"op":"mcm","clk":"1000700056","pt":1580619062352,"mc":[{"id":"1.168081820","rc":[{"batb":[[0,5.8,43.92],[1,4.4,392.02],[2,1.01,10.52]],"ltp":1.9,"tv":93.22,"id":15256065}]}]}
{"op":"mcm","clk":"1000700779","pt":1580619074247,"mc":[{"id":"1.168081820","rc":[{"batb":[[1,1.01,10.52],[2,1.01,0]],"ltp":1.9,"tv":93.22,"id":15256065}]}]}
{"op":"mcm","clk":"1000701164","pt":1580619080273,"mc":[{"id":"1.168081820","rc":[{"batb":[[1,4.3,388.08],[2,1.01,10.52]],"batl":[[0,160,36.53]],"ltp":1.9,"tv":93.22,"id":15256065}]}]}
{"op":"mcm","clk":"1000702855","pt":1580619106286,"mc":[{"id":"1.168081820","rc":[{"batb":[[0,1.01,3797.09]],"ltp":2.12,"tv":127.75,"id":22229228}]}]}
{"op":"mcm","clk":"1000709494","pt":1580619219403,"mc":[{"id":"1.168081820","rc":[{"batb":[[1,1.01,10.52],[2,1.01,0]],"ltp":1.9,"tv":93.22,"id":15256065},{"batb":[[0,1.01,10.51]],"ltp":2.12,"tv":127.75,"id":22229228}]}]}
{"op":"mcm","clk":"1000709995","pt":1580619228236,"mc":[{"id":"1.168081820","rc":[{"batb":[[1,4.1,391.89],[2,1.01,10.52]],"ltp":1.9,"tv":93.22,"id":15256065},{"batb":[[0,1.01,3947.74]],"ltp":2.12,"tv":127.75,"id":22229228}]}]}
{"op":"mcm","clk":"1000710254","pt":1580619232337,"mc":[{"id":"1.168081820","rc":[{"batb":[[1,1.01,10.52],[2,1.01,0]],"ltp":1.9,"tv":93.22,"id":15256065},{"batb":[[0,1.01,10.51]],"ltp":2.12,"tv":127.75,"id":22229228}]}]}
{"op":"mcm","clk":"1000710522","pt":1580619237330,"mc":[{"id":"1.168081820","rc":[{"batb":[[1,3.6,394.45],[2,1.01,10.52]],"ltp":1.9,"tv":93.22,"id":15256065},{"batb":[[0,1.05,993.83],[1,1.01,10.51]],"ltp":2.12,"tv":127.75,"id":22229228}]}]}
{"op":"mcm","clk":"1000710588","pt":1580619238410,"mc":[{"id":"1.168081820","rc":[{"batb":[[0,3.6,394.45],[1,1.01,10.52],[2,1.01,0]],"ltp":1.9,"tv":93.22,"id":15256065}]}]}
{"op":"mcm","clk":"1000710757","pt":1580619241507,"mc":[{"id":"1.168081820","rc":[{"batb":[[0,5.1,43.92],[1,3.6,394.45],[2,1.01,10.52]],"ltp":1.9,"tv":93.22,"id":15256065}]}]}
{"op":"mcm","clk":"1000711660","pt":1580619257425,"mc":[{"id":"1.168081820","rc":[{"batb":[[1,1.01,10.52],[2,1.01,0]],"ltp":1.9,"tv":93.22,"id":15256065},{"batb":[[0,1.01,10.51],[1,1.01,0]],"ltp":2.12,"tv":127.75,"id":22229228}]}]}
{"op":"mcm","clk":"1000711840","pt":1580619260661,"mc":[{"id":"1.168081820","rc":[{"batb":[[0,1.01,10.52],[1,1.01,0]],"ltp":1.9,"tv":93.22,"id":15256065}]}]}
{"op":"mcm","clk":"1000711938","pt":1580619262560,"mc":[{"id":"1.168081820","rc":[{"batb":[[0,3.5,391.83],[1,1.01,10.52]],"ltp":1.9,"tv":93.22,"id":15256065},{"batb":[[0,1.06,880.57],[1,1.01,10.51]],"ltp":2.12,"tv":127.75,"id":22229228}]}]}
{"op":"mcm","clk":"1000712013","pt":1580619263740,"mc":[{"id":"1.168081820","rc":[{"batb":[[0,4.3,43.92],[1,3.5,391.83],[2,1.01,10.52]],"ltp":1.9,"tv":93.22,"id":15256065}]}]}
{"op":"mcm","clk":"1000712573","pt":1580619273570,"mc":[{"id":"1.168081820","rc":[{"batb":[[1,1.01,10.52],[2,1.01,0]],"ltp":1.9,"tv":93.22,"id":15256065},{"batb":[[0,1.01,10.51],[1,1.01,0]],"ltp":2.12,"tv":127.75,"id":22229228}]}]}
{"op":"mcm","clk":"1000712602","pt":1580619274031,"mc":[{"id":"1.168081820","rc":[{"batb":[[0,1.01,10.52],[1,1.01,0]],"ltp":1.9,"tv":93.22,"id":15256065}]}]}
{"op":"mcm","clk":"1000712804","pt":1580619277637,"mc":[{"id":"1.168081820","rc":[{"batb":[[0,4,388.09],[1,1.01,10.52]],"ltp":1.9,"tv":93.22,"id":15256065},{"batb":[[0,1.02,2089.27],[1,1.01,10.51]],"ltp":2.12,"tv":127.75,"id":22229228}]}]}
{"op":"mcm","clk":"1000713480","pt":1580619289493,"mc":[{"id":"1.168081820","rc":[{"batb":[[0,4.5,41.65],[1,4,388.09],[2,1.01,10.52]],"ltp":1.9,"tv":93.22,"id":15256065}]}]}
{"op":"mcm","clk":"1000713670","pt":1580619292595,"mc":[{"id":"1.168081820","rc":[{"batb":[[1,1.01,10.52],[2,1.01,0]],"ltp":1.9,"tv":93.22,"id":15256065},{"batb":[[0,1.01,10.51],[1,1.01,0]],"ltp":2.12,"tv":127.75,"id":22229228}]}]}
{"op":"mcm","clk":"1000714164","pt":1580619300799,"mc":[{"id":"1.168081820","rc":[{"batb":[[1,4.4,392.02],[2,1.01,10.52]],"ltp":1.9,"tv":93.22,"id":15256065}]}]}
{"op":"mcm","clk":"1000714608","pt":1580619308832,"mc":[{"id":"1.168081820","rc":[{"batb":[[0,6,17.48],[1,4.5,41.65],[2,4.4,392.02]],"ltp":1.9,"tv":93.22,"id":15256065}]}]}
{"op":"mcm","clk":"1000714898","pt":1580619314443,"mc":[{"id":"1.168081820","rc":[{"batb":[[1,4.4,392.02],[2,1.01,10.52]],"ltp":1.9,"tv":93.22,"id":15256065}]}]}
{"op":"mcm","clk":"1000714960","pt":1580619315626,"mc":[{"id":"1.168081820","rc":[{"batb":[[1,1.01,10.52],[2,1.01,0]],"ltp":1.9,"tv":93.22,"id":15256065}]}]}
{"op":"mcm","clk":"1000715054","pt":1580619317526,"mc":[{"id":"1.168081820","rc":[{"batb":[[0,6.2,41.65],[1,6,17.48],[2,1.01,10.52]],"ltp":1.9,"tv":93.22,"id":15256065}]}]}
{"op":"mcm","clk":"1000715268","pt":1580619321949,"mc":[{"id":"1.168081820","rc":[{"batb":[[2,4.7,389.7]],"ltp":1.9,"tv":93.22,"id":15256065}]}]}
{"op":"mcm","clk":"1000716036","pt":1580619336640,"mc":[{"id":"1.168081820","rc":[{"batb":[[2,1.01,10.52]],"ltp":1.9,"tv":93.22,"id":15256065}]}]}
{"op":"mcm","clk":"1000716585","pt":1580619346667,"mc":[{"id":"1.168081820","marketDefinition":{"bspMarket":false,"turnInPlayEnabled":true,"persistenceEnabled":true,"marketBaseRate":5.0,"eventId":"29676917","eventTypeId":"2","numberOfWinners":1,"bettingType":"ODDS","marketType":"SET_WINNER","marketTime":"2020-02-02T04:00:00.000Z","suspendTime":"2020-02-02T04:00:00.000Z","bspReconciled":false,"complete":true,"inPlay":true,"crossMatching":true,"runnersVoidable":false,"numberOfActiveRunners":2,"betDelay":3,"status":"SUSPENDED","runners":[{"status":"ACTIVE","sortPriority":1,"id":22229228,"name":"Ram/Salisbury"},{"status":"ACTIVE","sortPriority":2,"id":15256065,"name":"Purcell/Saville"}],"regulators":["MR_INT"],"countryCode":"AU","discountAllowed":true,"timezone":"GMT","openDate":"2020-02-02T04:00:00.000Z","version":3148170014,"name":"Set 1 Winner","eventName":"Ram/Salisbury v Purcell/Saville"}}]}
{"op":"mcm","clk":"1000716805","pt":1580619350863,"mc":[{"id":"1.168081820","rc":[{"batb":[[1,1.01,10.52],[2,1.01,0]],"ltp":1.9,"tv":93.22,"id":15256065}]}]}
{"op":"mcm","clk":"1000717083","pt":1580619355964,"mc":[{"id":"1.168081820","rc":[{"batb":[[0,1.01,10.52],[1,1.01,0]],"ltp":1.9,"tv":93.22,"id":15256065}]}]}
{"op":"mcm","clk":"1000718856","pt":1580619383617,"mc":[{"id":"1.168081820","tv":0.0}]}
{"op":"mcm","clk":"1000718921","pt":1580619384739,"mc":[{"id":"1.168081820","marketDefinition":{"bspMarket":false,"turnInPlayEnabled":true,"persistenceEnabled":true,"marketBaseRate":5.0,"eventId":"29676917","eventTypeId":"2","numberOfWinners":1,"bettingType":"ODDS","marketType":"SET_WINNER","marketTime":"2020-02-02T04:00:00.000Z","suspendTime":"2020-02-02T04:00:00.000Z","bspReconciled":false,"complete":true,"inPlay":true,"crossMatching":false,"runnersVoidable":false,"numberOfActiveRunners":0,"betDelay":3,"status":"CLOSED","settledTime":"2020-02-02T04:56:22.000Z","runners":[{"status":"WINNER","sortPriority":1,"id":22229228,"name":"Ram/Salisbury"},{"status":"LOSER","sortPriority":2,"id":15256065,"name":"Purcell/Saville"}],"regulators":["MR_INT"],"countryCode":"AU","discountAllowed":true,"timezone":"GMT","openDate":"2020-02-02T04:00:00.000Z","version":3148170044,"name":"Set 1 Winner","eventName":"Ram/Salisbury v Purcell/Saville"}}]}
