{"op":"mcm","clk":"978248081","pt":1580359801373,"mc":[{"id":"1.168081831","marketDefinition":{"bspMarket":false,"turnInPlayEnabled":true,"persistenceEnabled":true,"marketBaseRate":5.0,"eventId":"29676917","eventTypeId":"2","numberOfWinners":1,"bettingType":"ODDS","marketType":"SET_CORRECT_SCORE","marketTime":"2020-02-02T05:00:00.000Z","suspendTime":"2020-02-02T05:00:00.000Z","bspReconciled":false,"complete":true,"inPlay":false,"crossMatching":false,"runnersVoidable":false,"numberOfActiveRunners":14,"betDelay":0,"status":"OPEN","runners":[{"status":"ACTIVE","sortPriority":1,"id":27702977,"name":"Ram/Salisbury 6 - 0"},{"status":"ACTIVE","sortPriority":2,"id":27702978,"name":"Ram/Salisbury 6 - 1"},{"status":"ACTIVE","sortPriority":3,"id":27702979,"name":"Ram/Salisbury 6 - 2"},{"status":"ACTIVE","sortPriority":4,"id":27702980,"name":"Ram/Salisbury 6 - 3"},{"status":"ACTIVE","sortPriority":5,"id":27702981,"name":"Ram/Salisbury 6 - 4"},{"status":"ACTIVE","sortPriority":6,"id":27702982,"name":"Ram/Salisbury 7 - 5"},{"status":"ACTIVE","sortPriority":7,"id":27702983,"name":"Ram/Salisbury 7 - 6"},{"status":"ACTIVE","sortPriority":8,"id":27702984,"name":"Purcell/Saville 6 - 0"},{"status":"ACTIVE","sortPriority":9,"id":27702985,"name":"Purcell/Saville 6 - 1"},{"status":"ACTIVE","sortPriority":10,"id":27702986,"name":"Purcell/Saville 6 - 2"},{"status":"ACTIVE","sortPriority":11,"id":27702987,"name":"Purcell/Saville 6 - 3"},{"status":"ACTIVE","sortPriority":12,"id":27702988,"name":"Purcell/Saville 6 - 4"},{"status":"ACTIVE","sortPriority":13,"id":27702989,"name":"Purcell/Saville 7 - 5"},{"status":"ACTIVE","sortPriority":14,"id":27702990,"name":"Purcell/Saville 7 - 6"}],"regulators":["MR_INT"],"countryCode":"AU","discountAllowed":false,"timezone":"GMT","openDate":"2020-02-02T05:00:00.000Z","version":3141663671,"name":"Set 1 - Correct Score","eventName":"Ram/Salisbury v Purcell/Saville"}}]}
{"op":"mcm","clk":"978248109","pt":1580359802704,"mc":[{"id":"1.168081831","marketDefinition":{"bspMarket":false,"turnInPlayEnabled":true,"persistenceEnabled":true,"marketBaseRate":5.0,"eventId":"29676917","eventTypeId":"2","numberOfWinners":1,"bettingType":"ODDS","marketType":"SET_CORRECT_SCORE","marketTime":"2020-02-02T05:00:00.000Z","suspendTime":"2020-02-02T05:00:00.000Z","bspReconciled":false,"complete":true,"inPlay":false,"crossMatching":false,"runnersVoidable":false,"numberOfActiveRunners":14,"betDelay":0,"status":"OPEN","runners":[{"status":"ACTIVE","sortPriority":1,"id":27702977,"name":"Ram/Salisbury 6 - 0"},{"status":"ACTIVE","sortPriority":2,"id":27702978,"name":"Ram/Salisbury 6 - 1"},{"status":"ACTIVE","sortPriority":3,"id":27702979,"name":"Ram/Salisbury 6 - 2"},{"status":"ACTIVE","sortPriority":4,"id":27702980,"name":"Ram/Salisbury 6 - 3"},{"status":"ACTIVE","sortPriority":5,"id":27702981,"name":"Ram/Salisbury 6 - 4"},{"status":"ACTIVE","sortPriority":6,"id":27702982,"name":"Ram/Salisbury 7 - 5"},{"status":"ACTIVE","sortPriority":7,"id":27702983,"name":"Ram/Salisbury 7 - 6"},{"status":"ACTIVE","sortPriority":8,"id":27702984,"name":"Purcell/Saville 6 - 0"},{"status":"ACTIVE","sortPriority":9,"id":27702985,"name":"Purcell/Saville 6 - 1"},{"status":"ACTIVE","sortPriority":10,"id":27702986,"name":"Purcell/Saville 6 - 2"},{"status":"ACTIVE","sortPriority":11,"id":27702987,"name":"Purcell/Saville 6 - 3"},{"status":"ACTIVE","sortPriority":12,"id":27702988,"name":"Purcell/Saville 6 - 4"},{"status":"ACTIVE","sortPriority":13,"id":27702989,"name":"Purcell/Saville 7 - 5"},{"status":"ACTIVE","sortPriority":14,"id":27702990,"name":"Purcell/Saville 7 - 6"}],"regulators":["MR_INT"],"countryCode":"AU","discountAllowed":true,"timezone":"GMT","openDate":"2020-02-02T05:00:00.000Z","version":3141663671,"name":"Set 1 - Correct Score","eventName":"Ram/Salisbury v Purcell/Saville"}}]}
{"op":"mcm","clk":"979671939","pt":1580391166834,"mc":[{"id":"1.168081831","rc":[{"batb":[[0,2,171.94]],"ltp":0.0,"tv":0.0,"id":27702990},{"batb":[[0,3,171.94]],"ltp":0.0,"tv":0.0,"id":27702989},{"batb":[[0,3,171.94]],"ltp":0.0,"tv":0.0,"id":27702988},{"batb":[[0,3,171.94]],"ltp":0.0,"tv":0.0,"id":27702987},{"batb":[[0,3,171.94]],"ltp":0.0,"tv":0.0,"id":27702986},{"batb":[[0,3,171.94]],"ltp":0.0,"tv":0.0,"id":27702985},{"batb":[[0,3,171.94]],"ltp":0.0,"tv":0.0,"id":27702984},{"batb":[[0,2,171.94]],"ltp":0.0,"tv":0.0,"id":27702983},{"batb":[[0,3,171.94]],"ltp":0.0,"tv":0.0,"id":27702982},{"batb":[[0,3,171.94]],"ltp":0.0,"tv":0.0,"id":27702981},{"batb":[[0,3,171.94]],"ltp":0.0,"tv":0.0,"id":27702980},{"batb":[[0,3,171.94]],"ltp":0.0,"tv":0.0,"id":27702979},{"batb":[[0,3,171.94]],"ltp":0.0,"tv":0.0,"id":27702978},{"batb":[[0,3,171.94]],"ltp":0.0,"tv":0.0,"id":27702977}]}]}
{"op":"mcm","clk":"979674453","pt":1580391203265,"mc":[{"id":"1.168081831","rc":[{"batb":[[0,3,109.46]],"ltp":0.0,"tv":0.0,"id":27702987},{"batb":[[0,3,97.07]],"ltp":0.0,"tv":0.0,"id":27702980}]}]}
{"op":"mcm","clk":"979815299","pt":1580392951883,"mc":[{"id":"1.168081831","rc":[{"batb":[[0,2,170.86]],"ltp":0.0,"tv":0.0,"id":27702990},{"batb":[[0,3,170.86]],"ltp":0.0,"tv":0.0,"id":27702989},{"batb":[[0,3,170.86]],"ltp":0.0,"tv":0.0,"id":27702988},{"batb":[[0,3,108.77]],"ltp":0.0,"tv":0.0,"id":27702987},{"batb":[[0,3,170.86]],"ltp":0.0,"tv":0.0,"id":27702986},{"batb":[[0,3,170.86]],"ltp":0.0,"tv":0.0,"id":27702985},{"batb":[[0,3,170.86]],"ltp":0.0,"tv":0.0,"id":27702984},{"batb":[[0,2,170.86]],"ltp":0.0,"tv":0.0,"id":27702983},{"batb":[[0,3,170.86]],"ltp":0.0,"tv":0.0,"id":27702982},{"batb":[[0,3,170.86]],"ltp":0.0,"tv":0.0,"id":27702981},{"batb":[[0,3,96.46]],"ltp":0.0,"tv":0.0,"id":27702980},{"batb":[[0,3,170.86]],"ltp":0.0,"tv":0.0,"id":27702979},{"batb":[[0,3,170.86]],"ltp":0.0,"tv":0.0,"id":27702978},{"batb":[[0,3,170.86]],"ltp":0.0,"tv":0.0,"id":27702977}]}]}
{"op":"mcm","clk":"980193878","pt":1580400151879,"mc":[{"id":"1.168081831","rc":[{"batb":[[0,2,170.43]],"ltp":0.0,"tv":0.0,"id":27702990},{"batb":[[0,3,170.43]],"ltp":0.0,"tv":0.0,"id":27702989},{"batb":[[0,3,170.43]],"ltp":0.0,"tv":0.0,"id":27702988},{"batb":[[0,3,108.5]],"ltp":0.0,"tv":0.0,"id":27702987},{"batb":[[0,3,170.43]],"ltp":0.0,"tv":0.0,"id":27702986},{"batb":[[0,3,170.43]],"ltp":0.0,"tv":0.0,"id":27702985},{"batb":[[0,3,170.43]],"ltp":0.0,"tv":0.0,"id":27702984},{"batb":[[0,2,170.43]],"ltp":0.0,"tv":0.0,"id":27702983},{"batb":[[0,3,170.43]],"ltp":0.0,"tv":0.0,"id":27702982},{"batb":[[0,3,170.43]],"ltp":0.0,"tv":0.0,"id":27702981},{"batb":[[0,3,96.22]],"ltp":0.0,"tv":0.0,"id":27702980},{"batb":[[0,3,170.43]],"ltp":0.0,"tv":0.0,"id":27702979},{"batb":[[0,3,170.43]],"ltp":0.0,"tv":0.0,"id":27702978},{"batb":[[0,3,170.43]],"ltp":0.0,"tv":0.0,"id":27702977}]}]}
{"op":"mcm","clk":"980489115","pt":1580407351884,"mc":[{"id":"1.168081831","rc":[{"batb":[[0,2,170.53]],"ltp":0.0,"tv":0.0,"id":27702990},{"batb":[[0,3,170.53]],"ltp":0.0,"tv":0.0,"id":27702989},{"batb":[[0,3,170.53]],"ltp":0.0,"tv":0.0,"id":27702988},{"batb":[[0,3,108.57]],"ltp":0.0,"tv":0.0,"id":27702987},{"batb":[[0,3,170.53]],"ltp":0.0,"tv":0.0,"id":27702986},{"batb":[[0,3,170.53]],"ltp":0.0,"tv":0.0,"id":27702985},{"batb":[[0,3,170.53]],"ltp":0.0,"tv":0.0,"id":27702984},{"batb":[[0,2,170.53]],"ltp":0.0,"tv":0.0,"id":27702983},{"batb":[[0,3,170.53]],"ltp":0.0,"tv":0.0,"id":27702982},{"batb":[[0,3,170.53]],"ltp":0.0,"tv":0.0,"id":27702981},{"batb":[[0,3,96.28]],"ltp":0.0,"tv":0.0,"id":27702980},{"batb":[[0,3,170.53]],"ltp":0.0,"tv":0.0,"id":27702979},{"batb":[[0,3,170.53]],"ltp":0.0,"tv":0.0,"id":27702978},{"batb":[[0,3,170.53]],"ltp":0.0,"tv":0.0,"id":27702977}]}]}
{"op":"mcm","clk":"980906850","pt":1580414551883,"mc":[{"id":"1.168081831","rc":[{"batb":[[0,2,170.85]],"ltp":0.0,"tv":0.0,"id":27702990},{"batb":[[0,3,170.85]],"ltp":0.0,"tv":0.0,"id":27702989},{"batb":[[0,3,170.85]],"ltp":0.0,"tv":0.0,"id":27702988},{"batb":[[0,3,108.77]],"ltp":0.0,"tv":0.0,"id":27702987},{"batb":[[0,3,170.85]],"ltp":0.0,"tv":0.0,"id":27702986},{"batb":[[0,3,170.85]],"ltp":0.0,"tv":0.0,"id":27702985},{"batb":[[0,3,170.85]],"ltp":0.0,"tv":0.0,"id":27702984},{"batb":[[0,2,170.85]],"ltp":0.0,"tv":0.0,"id":27702983},{"batb":[[0,3,170.85]],"ltp":0.0,"tv":0.0,"id":27702982},{"batb":[[0,3,170.85]],"ltp":0.0,"tv":0.0,"id":27702981},{"batb":[[0,3,96.45]],"ltp":0.0,"tv":0.0,"id":27702980},{"batb":[[0,3,170.85]],"ltp":0.0,"tv":0.0,"id":27702979},{"batb":[[0,3,170.85]],"ltp":0.0,"tv":0.0,"id":27702978},{"batb":[[0,3,170.85]],"ltp":0.0,"tv":0.0,"id":27702977}]}]}
{"op":"mcm","clk":"981330261","pt":1580421751925,"mc":[{"id":"1.168081831","rc":[{"batb":[[0,2,170.96]],"ltp":0.0,"tv":0.0,"id":27702990},{"batb":[[0,3,170.96]],"ltp":0.0,"tv":0.0,"id":27702989},{"batb":[[0,3,170.96]],"ltp":0.0,"tv":0.0,"id":27702988},{"batb":[[0,3,108.84]],"ltp":0.0,"tv":0.0,"id":27702987},{"batb":[[0,3,170.96]],"ltp":0.0,"tv":0.0,"id":27702986},{"batb":[[0,3,170.96]],"ltp":0.0,"tv":0.0,"id":27702985},{"batb":[[0,3,170.96]],"ltp":0.0,"tv":0.0,"id":27702984},{"batb":[[0,2,170.96]],"ltp":0.0,"tv":0.0,"id":27702983},{"batb":[[0,3,170.96]],"ltp":0.0,"tv":0.0,"id":27702982},{"batb":[[0,3,170.96]],"ltp":0.0,"tv":0.0,"id":27702981},{"batb":[[0,3,96.52]],"ltp":0.0,"tv":0.0,"id":27702980},{"batb":[[0,3,170.96]],"ltp":0.0,"tv":0.0,"id":27702979},{"batb":[[0,3,170.96]],"ltp":0.0,"tv":0.0,"id":27702978},{"batb":[[0,3,170.96]],"ltp":0.0,"tv":0.0,"id":27702977}]}]}
{"op":"mcm","clk":"981763507","pt":1580428951899,"mc":[{"id":"1.168081831","rc":[{"batb":[[0,2,170.69]],"ltp":0.0,"tv":0.0,"id":27702990},{"batb":[[0,3,170.69]],"ltp":0.0,"tv":0.0,"id":27702989},{"batb":[[0,3,170.69]],"ltp":0.0,"tv":0.0,"id":27702988},{"batb":[[0,3,108.67]],"ltp":0.0,"tv":0.0,"id":27702987},{"batb":[[0,3,170.69]],"ltp":0.0,"tv":0.0,"id":27702986},{"batb":[[0,3,170.69]],"ltp":0.0,"tv":0.0,"id":27702985},{"batb":[[0,3,170.69]],"ltp":0.0,"tv":0.0,"id":27702984},{"batb":[[0,2,170.69]],"ltp":0.0,"tv":0.0,"id":27702983},{"batb":[[0,3,170.69]],"ltp":0.0,"tv":0.0,"id":27702982},{"batb":[[0,3,170.69]],"ltp":0.0,"tv":0.0,"id":27702981},{"batb":[[0,3,96.37]],"ltp":0.0,"tv":0.0,"id":27702980},{"batb":[[0,3,170.69]],"ltp":0.0,"tv":0.0,"id":27702979},{"batb":[[0,3,170.69]],"ltp":0.0,"tv":0.0,"id":27702978},{"batb":[[0,3,170.69]],"ltp":0.0,"tv":0.0,"id":27702977}]}]}
{"op":"mcm","clk":"982219421","pt":1580436151918,"mc":[{"id":"1.168081831","rc":[{"batb":[[0,2,170.73]],"ltp":0.0,"tv":0.0,"id":27702990},{"batb":[[0,3,170.73]],"ltp":0.0,"tv":0.0,"id":27702989},{"batb":[[0,3,170.73]],"ltp":0.0,"tv":0.0,"id":27702988},{"batb":[[0,3,108.7]],"ltp":0.0,"tv":0.0,"id":27702987},{"batb":[[0,3,170.73]],"ltp":0.0,"tv":0.0,"id":27702986},{"batb":[[0,3,170.73]],"ltp":0.0,"tv":0.0,"id":27702985},{"batb":[[0,3,170.73]],"ltp":0.0,"tv":0.0,"id":27702984},{"batb":[[0,2,170.73]],"ltp":0.0,"tv":0.0,"id":27702983},{"batb":[[0,3,170.73]],"ltp":0.0,"tv":0.0,"id":27702982},{"batb":[[0,3,170.73]],"ltp":0.0,"tv":0.0,"id":27702981},{"batb":[[0,3,96.39]],"ltp":0.0,"tv":0.0,"id":27702980},{"batb":[[0,3,170.73]],"ltp":0.0,"tv":0.0,"id":27702979},{"batb":[[0,3,170.73]],"ltp":0.0,"tv":0.0,"id":27702978},{"batb":[[0,3,170.73]],"ltp":0.0,"tv":0.0,"id":27702977}]}]}
{"op":"mcm","clk":"982562468","pt":1580443351901,"mc":[{"id":"1.168081831","rc":[{"batb":[[0,2,170.71]],"ltp":0.0,"tv":0.0,"id":27702990},{"batb":[[0,3,170.71]],"ltp":0.0,"tv":0.0,"id":27702989},{"batb":[[0,3,170.71]],"ltp":0.0,"tv":0.0,"id":27702988},{"batb":[[0,3,108.68]],"ltp":0.0,"tv":0.0,"id":27702987},{"batb":[[0,3,170.71]],"ltp":0.0,"tv":0.0,"id":27702986},{"batb":[[0,3,170.71]],"ltp":0.0,"tv":0.0,"id":27702985},{"batb":[[0,3,170.71]],"ltp":0.0,"tv":0.0,"id":27702984},{"batb":[[0,2,170.71]],"ltp":0.0,"tv":0.0,"id":27702983},{"batb":[[0,3,170.71]],"ltp":0.0,"tv":0.0,"id":27702982},{"batb":[[0,3,170.71]],"ltp":0.0,"tv":0.0,"id":27702981},{"batb":[[0,3,96.38]],"ltp":0.0,"tv":0.0,"id":27702980},{"batb":[[0,3,170.71]],"ltp":0.0,"tv":0.0,"id":27702979},{"batb":[[0,3,170.71]],"ltp":0.0,"tv":0.0,"id":27702978},{"batb":[[0,3,170.71]],"ltp":0.0,"tv":0.0,"id":27702977}]}]}
{"op":"mcm","clk":"982840736","pt":1580450551921,"mc":[{"id":"1.168081831","rc":[{"batb":[[0,2,170.88]],"ltp":0.0,"tv":0.0,"id":27702990},{"batb":[[0,3,170.88]],"ltp":0.0,"tv":0.0,"id":27702989},{"batb":[[0,3,170.88]],"ltp":0.0,"tv":0.0,"id":27702988},{"batb":[[0,3,108.79]],"ltp":0.0,"tv":0.0,"id":27702987},{"batb":[[0,3,170.88]],"ltp":0.0,"tv":0.0,"id":27702986},{"batb":[[0,3,170.88]],"ltp":0.0,"tv":0.0,"id":27702985},{"batb":[[0,3,170.88]],"ltp":0.0,"tv":0.0,"id":27702984},{"batb":[[0,2,170.88]],"ltp":0.0,"tv":0.0,"id":27702983},{"batb":[[0,3,170.88]],"ltp":0.0,"tv":0.0,"id":27702982},{"batb":[[0,3,170.88]],"ltp":0.0,"tv":0.0,"id":27702981},{"batb":[[0,3,96.47]],"ltp":0.0,"tv":0.0,"id":27702980},{"batb":[[0,3,170.88]],"ltp":0.0,"tv":0.0,"id":27702979},{"batb":[[0,3,170.88]],"ltp":0.0,"tv":0.0,"id":27702978},{"batb":[[0,3,170.88]],"ltp":0.0,"tv":0.0,"id":27702977}]}]}
{"op":"mcm","clk":"983196589","pt":1580457751914,"mc":[{"id":"1.168081831","rc":[{"batb":[[0,2,170.22]],"ltp":0.0,"tv":0.0,"id":27702990},{"batb":[[0,3,170.22]],"ltp":0.0,"tv":0.0,"id":27702989},{"batb":[[0,3,170.22]],"ltp":0.0,"tv":0.0,"id":27702988},{"batb":[[0,3,108.37]],"ltp":0.0,"tv":0.0,"id":27702987},{"batb":[[0,3,170.22]],"ltp":0.0,"tv":0.0,"id":27702986},{"batb":[[0,3,170.22]],"ltp":0.0,"tv":0.0,"id":27702985},{"batb":[[0,3,170.22]],"ltp":0.0,"tv":0.0,"id":27702984},{"batb":[[0,2,170.22]],"ltp":0.0,"tv":0.0,"id":27702983},{"batb":[[0,3,170.22]],"ltp":0.0,"tv":0.0,"id":27702982},{"batb":[[0,3,170.22]],"ltp":0.0,"tv":0.0,"id":27702981},{"batb":[[0,3,96.1]],"ltp":0.0,"tv":0.0,"id":27702980},{"batb":[[0,3,170.22]],"ltp":0.0,"tv":0.0,"id":27702979},{"batb":[[0,3,170.22]],"ltp":0.0,"tv":0.0,"id":27702978},{"batb":[[0,3,170.22]],"ltp":0.0,"tv":0.0,"id":27702977}]}]}
{"op":"mcm","clk":"983817390","pt":1580464951885,"mc":[{"id":"1.168081831","rc":[{"batb":[[0,2,169.77]],"ltp":0.0,"tv":0.0,"id":27702990},{"batb":[[0,3,169.77]],"ltp":0.0,"tv":0.0,"id":27702989},{"batb":[[0,3,169.77]],"ltp":0.0,"tv":0.0,"id":27702988},{"batb":[[0,3,108.08]],"ltp":0.0,"tv":0.0,"id":27702987},{"batb":[[0,3,169.77]],"ltp":0.0,"tv":0.0,"id":27702986},{"batb":[[0,3,169.77]],"ltp":0.0,"tv":0.0,"id":27702985},{"batb":[[0,3,169.77]],"ltp":0.0,"tv":0.0,"id":27702984},{"batb":[[0,2,169.77]],"ltp":0.0,"tv":0.0,"id":27702983},{"batb":[[0,3,169.77]],"ltp":0.0,"tv":0.0,"id":27702982},{"batb":[[0,3,169.77]],"ltp":0.0,"tv":0.0,"id":27702981},{"batb":[[0,3,95.85]],"ltp":0.0,"tv":0.0,"id":27702980},{"batb":[[0,3,169.77]],"ltp":0.0,"tv":0.0,"id":27702979},{"batb":[[0,3,169.77]],"ltp":0.0,"tv":0.0,"id":27702978},{"batb":[[0,3,169.77]],"ltp":0.0,"tv":0.0,"id":27702977}]}]}
{"op":"mcm","clk":"984674416","pt":1580472151902,"mc":[{"id":"1.168081831","rc":[{"batb":[[0,2,169.78]],"ltp":0.0,"tv":0.0,"id":27702990},{"batb":[[0,3,169.78]],"ltp":0.0,"tv":0.0,"id":27702989},{"batb":[[0,3,169.78]],"ltp":0.0,"tv":0.0,"id":27702988},{"batb":[[0,3,108.09]],"ltp":0.0,"tv":0.0,"id":27702987},{"batb":[[0,3,169.78]],"ltp":0.0,"tv":0.0,"id":27702986},{"batb":[[0,3,169.78]],"ltp":0.0,"tv":0.0,"id":27702985},{"batb":[[0,3,169.78]],"ltp":0.0,"tv":0.0,"id":27702984},{"batb":[[0,2,169.78]],"ltp":0.0,"tv":0.0,"id":27702983},{"batb":[[0,3,169.78]],"ltp":0.0,"tv":0.0,"id":27702982},{"batb":[[0,3,169.78]],"ltp":0.0,"tv":0.0,"id":27702981},{"batb":[[0,3,95.85]],"ltp":0.0,"tv":0.0,"id":27702980},{"batb":[[0,3,169.78]],"ltp":0.0,"tv":0.0,"id":27702979},{"batb":[[0,3,169.78]],"ltp":0.0,"tv":0.0,"id":27702978},{"batb":[[0,3,169.78]],"ltp":0.0,"tv":0.0,"id":27702977}]}]}
{"op":"mcm","clk":"985712801","pt":1580479351896,"mc":[{"id":"1.168081831","rc":[{"batb":[[0,2,169.82]],"ltp":0.0,"tv":0.0,"id":27702990},{"batb":[[0,3,169.82]],"ltp":0.0,"tv":0.0,"id":27702989},{"batb":[[0,3,169.82]],"ltp":0.0,"tv":0.0,"id":27702988},{"batb":[[0,3,108.11]],"ltp":0.0,"tv":0.0,"id":27702987},{"batb":[[0,3,169.82]],"ltp":0.0,"tv":0.0,"id":27702986},{"batb":[[0,3,169.82]],"ltp":0.0,"tv":0.0,"id":27702985},{"batb":[[0,3,169.82]],"ltp":0.0,"tv":0.0,"id":27702984},{"batb":[[0,2,169.82]],"ltp":0.0,"tv":0.0,"id":27702983},{"batb":[[0,3,169.82]],"ltp":0.0,"tv":0.0,"id":27702982},{"batb":[[0,3,169.82]],"ltp":0.0,"tv":0.0,"id":27702981},{"batb":[[0,3,95.87]],"ltp":0.0,"tv":0.0,"id":27702980},{"batb":[[0,3,169.82]],"ltp":0.0,"tv":0.0,"id":27702979},{"batb":[[0,3,169.82]],"ltp":0.0,"tv":0.0,"id":27702978},{"batb":[[0,3,169.82]],"ltp":0.0,"tv":0.0,"id":27702977}]}]}
{"op":"mcm","clk":"986471952","pt":1580486551903,"mc":[{"id":"1.168081831","rc":[{"batb":[[0,2,169.16]],"ltp":0.0,"tv":0.0,"id":27702990},{"batb":[[0,3,169.16]],"ltp":0.0,"tv":0.0,"id":27702989},{"batb":[[0,3,169.16]],"ltp":0.0,"tv":0.0,"id":27702988},{"batb":[[0,3,107.69]],"ltp":0.0,"tv":0.0,"id":27702987},{"batb":[[0,3,169.16]],"ltp":0.0,"tv":0.0,"id":27702986},{"batb":[[0,3,169.16]],"ltp":0.0,"tv":0.0,"id":27702985},{"batb":[[0,3,169.16]],"ltp":0.0,"tv":0.0,"id":27702984},{"batb":[[0,2,169.16]],"ltp":0.0,"tv":0.0,"id":27702983},{"batb":[[0,3,169.16]],"ltp":0.0,"tv":0.0,"id":27702982},{"batb":[[0,3,169.16]],"ltp":0.0,"tv":0.0,"id":27702981},{"batb":[[0,3,95.5]],"ltp":0.0,"tv":0.0,"id":27702980},{"batb":[[0,3,169.16]],"ltp":0.0,"tv":0.0,"id":27702979},{"batb":[[0,3,169.16]],"ltp":0.0,"tv":0.0,"id":27702978},{"batb":[[0,3,169.16]],"ltp":0.0,"tv":0.0,"id":27702977}]}]}
{"op":"mcm","clk":"987055242","pt":1580493751895,"mc":[{"id":"1.168081831","rc":[{"batb":[[0,2,168.99]],"ltp":0.0,"tv":0.0,"id":27702990},{"batb":[[0,3,168.99]],"ltp":0.0,"tv":0.0,"id":27702989},{"batb":[[0,3,168.99]],"ltp":0.0,"tv":0.0,"id":27702988},{"batb":[[0,3,107.59]],"ltp":0.0,"tv":0.0,"id":27702987},{"batb":[[0,3,168.99]],"ltp":0.0,"tv":0.0,"id":27702986},{"batb":[[0,3,168.99]],"ltp":0.0,"tv":0.0,"id":27702985},{"batb":[[0,3,168.99]],"ltp":0.0,"tv":0.0,"id":27702984},{"batb":[[0,2,168.99]],"ltp":0.0,"tv":0.0,"id":27702983},{"batb":[[0,3,168.99]],"ltp":0.0,"tv":0.0,"id":27702982},{"batb":[[0,3,168.99]],"ltp":0.0,"tv":0.0,"id":27702981},{"batb":[[0,3,95.41]],"ltp":0.0,"tv":0.0,"id":27702980},{"batb":[[0,3,168.99]],"ltp":0.0,"tv":0.0,"id":27702979},{"batb":[[0,3,168.99]],"ltp":0.0,"tv":0.0,"id":27702978},{"batb":[[0,3,168.99]],"ltp":0.0,"tv":0.0,"id":27702977}]}]}
{"op":"mcm","clk":"987924238","pt":1580500951900,"mc":[{"id":"1.168081831","rc":[{"batb":[[0,2,168.91]],"ltp":0.0,"tv":0.0,"id":27702990},{"batb":[[0,3,168.91]],"ltp":0.0,"tv":0.0,"id":27702989},{"batb":[[0,3,168.91]],"ltp":0.0,"tv":0.0,"id":27702988},{"batb":[[0,3,107.53]],"ltp":0.0,"tv":0.0,"id":27702987},{"batb":[[0,3,168.91]],"ltp":0.0,"tv":0.0,"id":27702986},{"batb":[[0,3,168.91]],"ltp":0.0,"tv":0.0,"id":27702985},{"batb":[[0,3,168.91]],"ltp":0.0,"tv":0.0,"id":27702984},{"batb":[[0,2,168.91]],"ltp":0.0,"tv":0.0,"id":27702983},{"batb":[[0,3,168.91]],"ltp":0.0,"tv":0.0,"id":27702982},{"batb":[[0,3,168.91]],"ltp":0.0,"tv":0.0,"id":27702981},{"batb":[[0,3,95.36]],"ltp":0.0,"tv":0.0,"id":27702980},{"batb":[[0,3,168.91]],"ltp":0.0,"tv":0.0,"id":27702979},{"batb":[[0,3,168.91]],"ltp":0.0,"tv":0.0,"id":27702978},{"batb":[[0,3,168.91]],"ltp":0.0,"tv":0.0,"id":27702977}]}]}
{"op":"mcm","clk":"988687952","pt":1580508151902,"mc":[{"id":"1.168081831","rc":[{"batb":[[0,2,168.67]],"ltp":0.0,"tv":0.0,"id":27702990},{"batb":[[0,3,168.67]],"ltp":0.0,"tv":0.0,"id":27702989},{"batb":[[0,3,168.67]],"ltp":0.0,"tv":0.0,"id":27702988},{"batb":[[0,3,107.38]],"ltp":0.0,"tv":0.0,"id":27702987},{"batb":[[0,3,168.67]],"ltp":0.0,"tv":0.0,"id":27702986},{"batb":[[0,3,168.67]],"ltp":0.0,"tv":0.0,"id":27702985},{"batb":[[0,3,168.67]],"ltp":0.0,"tv":0.0,"id":27702984},{"batb":[[0,2,168.67]],"ltp":0.0,"tv":0.0,"id":27702983},{"batb":[[0,3,168.67]],"ltp":0.0,"tv":0.0,"id":27702982},{"batb":[[0,3,168.67]],"ltp":0.0,"tv":0.0,"id":27702981},{"batb":[[0,3,95.22]],"ltp":0.0,"tv":0.0,"id":27702980},{"batb":[[0,3,168.67]],"ltp":0.0,"tv":0.0,"id":27702979},{"batb":[[0,3,168.67]],"ltp":0.0,"tv":0.0,"id":27702978},{"batb":[[0,3,168.67]],"ltp":0.0,"tv":0.0,"id":27702977}]}]}
{"op":"mcm","clk":"988916539","pt":1580511681628,"mc":[{"id":"1.168081831","rc":[{"batb":[[1,1.01,2.53]],"ltp":0.0,"tv":0.0,"id":27702990},{"batb":[[1,1.01,2.53]],"ltp":0.0,"tv":0.0,"id":27702989},{"batb":[[1,1.01,2.53]],"ltp":0.0,"tv":0.0,"id":27702988},{"batb":[[1,1.01,2.53]],"ltp":0.0,"tv":0.0,"id":27702987},{"batb":[[1,1.01,2.53]],"ltp":0.0,"tv":0.0,"id":27702986},{"batb":[[1,1.01,2.53]],"ltp":0.0,"tv":0.0,"id":27702985},{"batb":[[1,1.01,2.53]],"ltp":0.0,"tv":0.0,"id":27702984},{"batb":[[1,1.01,2.53]],"ltp":0.0,"tv":0.0,"id":27702983},{"batb":[[1,1.01,2.53]],"ltp":0.0,"tv":0.0,"id":27702982},{"batb":[[1,1.01,2.53]],"ltp":0.0,"tv":0.0,"id":27702981},{"batb":[[1,1.01,2.53]],"ltp":0.0,"tv":0.0,"id":27702980},{"batb":[[1,1.01,2.53]],"ltp":0.0,"tv":0.0,"id":27702979},{"batb":[[1,1.01,2.53]],"ltp":0.0,"tv":0.0,"id":27702978},{"batb":[[1,1.01,2.53]],"ltp":0.0,"tv":0.0,"id":27702977}]}]}
{"op":"mcm","clk":"988916594","pt":1580511682450,"mc":[{"id":"1.168081831","rc":[{"batb":[[1,1.01,0.51]],"ltp":0.0,"tv":0.0,"id":27702990},{"batb":[[1,1.01,0.51]],"ltp":0.0,"tv":0.0,"id":27702989},{"batb":[[1,1.01,0.51]],"ltp":0.0,"tv":0.0,"id":27702988},{"batb":[[1,1.01,0.51]],"ltp":0.0,"tv":0.0,"id":27702987},{"batb":[[1,1.01,0.51]],"ltp":0.0,"tv":0.0,"id":27702986},{"batb":[[1,1.01,0.51]],"ltp":0.0,"tv":0.0,"id":27702985},{"batb":[[1,1.01,0.51]],"ltp":0.0,"tv":0.0,"id":27702984},{"batb":[[1,1.01,0.51]],"ltp":0.0,"tv":0.0,"id":27702983},{"batb":[[1,1.01,0.51]],"ltp":0.0,"tv":0.0,"id":27702982},{"batb":[[1,1.01,0.51]],"ltp":0.0,"tv":0.0,"id":27702981},{"batb":[[1,1.01,0.51]],"ltp":0.0,"tv":0.0,"id":27702980},{"batb":[[1,1.01,0.51]],"ltp":0.0,"tv":0.0,"id":27702979},{"batb":[[1,1.01,0.51]],"ltp":0.0,"tv":0.0,"id":27702978},{"batb":[[1,1.01,0.51]],"ltp":0.0,"tv":0.0,"id":27702977}]}]}
{"op":"mcm","clk":"988940322","pt":1580511947643,"mc":[{"id":"1.168081831","rc":[{"batb":[[1,1.01,1.01]],"ltp":0.0,"tv":0.0,"id":27702990},{"batb":[[1,1.01,1.01]],"ltp":0.0,"tv":0.0,"id":27702989},{"batb":[[1,1.01,1.01]],"ltp":0.0,"tv":0.0,"id":27702988},{"batb":[[1,1.01,1.01]],"ltp":0.0,"tv":0.0,"id":27702987},{"batb":[[1,1.01,1.01]],"ltp":0.0,"tv":0.0,"id":27702986},{"batb":[[1,1.01,1.01]],"ltp":0.0,"tv":0.0,"id":27702985},{"batb":[[1,1.01,1.01]],"ltp":0.0,"tv":0.0,"id":27702984},{"batb":[[1,1.01,1.01]],"ltp":0.0,"tv":0.0,"id":27702983},{"batb":[[1,1.01,1.01]],"ltp":0.0,"tv":0.0,"id":27702982},{"batb":[[1,1.01,1.01]],"ltp":0.0,"tv":0.0,"id":27702981},{"batb":[[1,1.01,1.01]],"ltp":0.0,"tv":0.0,"id":27702980},{"batb":[[1,1.01,1.01]],"ltp":0.0,"tv":0.0,"id":27702979},{"batb":[[1,1.01,1.01]],"ltp":0.0,"tv":0.0,"id":27702978},{"batb":[[1,1.01,1.01]],"ltp":0.0,"tv":0.0,"id":27702977}]}]}
{"op":"mcm","clk":"1000053370","pt":1580605454532,"mc":[{"id":"1.168081831","rc":[{"batb":[[0,1.01,1.01],[1,1.01,0]],"ltp":0.0,"tv":0.0,"id":27702990},{"batb":[[0,1.01,1.01],[1,1.01,0]],"ltp":0.0,"tv":0.0,"id":27702989},{"batb":[[0,1.01,1.01],[1,1.01,0]],"ltp":0.0,"tv":0.0,"id":27702988},{"batb":[[0,1.01,1.01],[1,1.01,0]],"ltp":0.0,"tv":0.0,"id":27702987},{"batb":[[0,1.01,1.01],[1,1.01,0]],"ltp":0.0,"tv":0.0,"id":27702986},{"batb":[[0,1.01,1.01],[1,1.01,0]],"ltp":0.0,"tv":0.0,"id":27702985},{"batb":[[0,1.01,1.01],[1,1.01,0]],"ltp":0.0,"tv":0.0,"id":27702984},{"batb":[[0,1.01,1.01],[1,1.01,0]],"ltp":0.0,"tv":0.0,"id":27702983},{"batb":[[0,1.01,1.01],[1,1.01,0]],"ltp":0.0,"tv":0.0,"id":27702982},{"batb":[[0,1.01,1.01],[1,1.01,0]],"ltp":0.0,"tv":0.0,"id":27702981},{"batb":[[0,1.01,1.01],[1,1.01,0]],"ltp":0.0,"tv":0.0,"id":27702980},{"batb":[[0,1.01,1.01],[1,1.01,0]],"ltp":0.0,"tv":0.0,"id":27702979},{"batb":[[0,1.01,1.01],[1,1.01,0]],"ltp":0.0,"tv":0.0,"id":27702978},{"batb":[[0,1.01,1.01],[1,1.01,0]],"ltp":0.0,"tv":0.0,"id":27702977}]}]}
{"op":"mcm","clk":"1000351189","pt":1580612888969,"mc":[{"id":"1.168081831","marketDefinition":{"bspMarket":false,"turnInPlayEnabled":true,"persistenceEnabled":true,"marketBaseRate":5.0,"eventId":"29676917","eventTypeId":"2","numberOfWinners":1,"bettingType":"ODDS","marketType":"SET_CORRECT_SCORE","marketTime":"2020-02-02T04:00:00.000Z","suspendTime":"2020-02-02T04:00:00.000Z","bspReconciled":false,"complete":true,"inPlay":false,"crossMatching":false,"runnersVoidable":false,"numberOfActiveRunners":14,"betDelay":0,"status":"OPEN","runners":[{"status":"ACTIVE","sortPriority":1,"id":27702977,"name":"Ram/Salisbury 6 - 0"},{"status":"ACTIVE","sortPriority":2,"id":27702978,"name":"Ram/Salisbury 6 - 1"},{"status":"ACTIVE","sortPriority":3,"id":27702979,"name":"Ram/Salisbury 6 - 2"},{"status":"ACTIVE","sortPriority":4,"id":27702980,"name":"Ram/Salisbury 6 - 3"},{"status":"ACTIVE","sortPriority":5,"id":27702981,"name":"Ram/Salisbury 6 - 4"},{"status":"ACTIVE","sortPriority":6,"id":27702982,"name":"Ram/Salisbury 7 - 5"},{"status":"ACTIVE","sortPriority":7,"id":27702983,"name":"Ram/Salisbury 7 - 6"},{"status":"ACTIVE","sortPriority":8,"id":27702984,"name":"Purcell/Saville 6 - 0"},{"status":"ACTIVE","sortPriority":9,"id":27702985,"name":"Purcell/Saville 6 - 1"},{"status":"ACTIVE","sortPriority":10,"id":27702986,"name":"Purcell/Saville 6 - 2"},{"status":"ACTIVE","sortPriority":11,"id":27702987,"name":"Purcell/Saville 6 - 3"},{"status":"ACTIVE","sortPriority":12,"id":27702988,"name":"Purcell/Saville 6 - 4"},{"status":"ACTIVE","sortPriority":13,"id":27702989,"name":"Purcell/Saville 7 - 5"},{"status":"ACTIVE","sortPriority":14,"id":27702990,"name":"Purcell/Saville 7 - 6"}],"regulators":["MR_INT"],"countryCode":"AU","discountAllowed":true,"timezone":"GMT","openDate":"2020-02-02T05:00:00.000Z","version":3148089686,"name":"Set 1 - Correct Score","eventName":"Ram/Salisbury v Purcell/Saville"}}]}
{"op":"mcm","clk":"1000351354","pt":1580612891105,"mc":[{"id":"1.168081831","marketDefinition":{"bspMarket":false,"turnInPlayEnabled":true,"persistenceEnabled":true,"marketBaseRate":5.0,"eventId":"29676917","eventTypeId":"2","numberOfWinners":1,"bettingType":"ODDS","marketType":"SET_CORRECT_SCORE","marketTime":"2020-02-02T04:00:00.000Z","suspendTime":"2020-02-02T04:00:00.000Z","bspReconciled":false,"complete":true,"inPlay":false,"crossMatching":false,"runnersVoidable":false,"numberOfActiveRunners":14,"betDelay":0,"status":"OPEN","runners":[{"status":"ACTIVE","sortPriority":1,"id":27702977,"name":"Ram/Salisbury 6 - 0"},{"status":"ACTIVE","sortPriority":2,"id":27702978,"name":"Ram/Salisbury 6 - 1"},{"status":"ACTIVE","sortPriority":3,"id":27702979,"name":"Ram/Salisbury 6 - 2"},{"status":"ACTIVE","sortPriority":4,"id":27702980,"name":"Ram/Salisbury 6 - 3"},{"status":"ACTIVE","sortPriority":5,"id":27702981,"name":"Ram/Salisbury 6 - 4"},{"status":"ACTIVE","sortPriority":6,"id":27702982,"name":"Ram/Salisbury 7 - 5"},{"status":"ACTIVE","sortPriority":7,"id":27702983,"name":"Ram/Salisbury 7 - 6"},{"status":"ACTIVE","sortPriority":8,"id":27702984,"name":"Purcell/Saville 6 - 0"},{"status":"ACTIVE","sortPriority":9,"id":27702985,"name":"Purcell/Saville 6 - 1"},{"status":"ACTIVE","sortPriority":10,"id":27702986,"name":"Purcell/Saville 6 - 2"},{"status":"ACTIVE","sortPriority":11,"id":27702987,"name":"Purcell/Saville 6 - 3"},{"status":"ACTIVE","sortPriority":12,"id":27702988,"name":"Purcell/Saville 6 - 4"},{"status":"ACTIVE","sortPriority":13,"id":27702989,"name":"Purcell/Saville 7 - 5"},{"status":"ACTIVE","sortPriority":14,"id":27702990,"name":"Purcell/Saville 7 - 6"}],"regulators":["MR_INT"],"countryCode":"AU","discountAllowed":true,"timezone":"GMT","openDate":"2020-02-02T04:00:00.000Z","version":3148089686,"name":"Set 1 - Correct Score","eventName":"Ram/Salisbury v Purcell/Saville"}}]}
{"op":"mcm","clk":"1000559953","pt":1580616820692,"mc":[{"id":"1.168081831","marketDefinition":{"bspMarket":false,"turnInPlayEnabled":true,"persistenceEnabled":true,"marketBaseRate":5.0,"eventId":"29676917","eventTypeId":"2","numberOfWinners":1,"bettingType":"ODDS","marketType":"SET_CORRECT_SCORE","marketTime":"2020-02-02T04:00:00.000Z","suspendTime":"2020-02-02T04:00:00.000Z","bspReconciled":false,"complete":true,"inPlay":true,"crossMatching":false,"runnersVoidable":false,"numberOfActiveRunners":14,"betDelay":3,"status":"OPEN","runners":[{"status":"ACTIVE","sortPriority":1,"id":27702977,"name":"Ram/Salisbury 6 - 0"},{"status":"ACTIVE","sortPriority":2,"id":27702978,"name":"Ram/Salisbury 6 - 1"},{"status":"ACTIVE","sortPriority":3,"id":27702979,"name":"Ram/Salisbury 6 - 2"},{"status":"ACTIVE","sortPriority":4,"id":27702980,"name":"Ram/Salisbury 6 - 3"},{"status":"ACTIVE","sortPriority":5,"id":27702981,"name":"Ram/Salisbury 6 - 4"},{"status":"ACTIVE","sortPriority":6,"id":27702982,"name":"Ram/Salisbury 7 - 5"},{"status":"ACTIVE","sortPriority":7,"id":27702983,"name":"Ram/Salisbury 7 - 6"},{"status":"ACTIVE","sortPriority":8,"id":27702984,"name":"Purcell/Saville 6 - 0"},{"status":"ACTIVE","sortPriority":9,"id":27702985,"name":"Purcell/Saville 6 - 1"},{"status":"ACTIVE","sortPriority":10,"id":27702986,"name":"Purcell/Saville 6 - 2"},{"status":"ACTIVE","sortPriority":11,"id":27702987,"name":"Purcell/Saville 6 - 3"},{"status":"ACTIVE","sortPriority":12,"id":27702988,"name":"Purcell/Saville 6 - 4"},{"status":"ACTIVE","sortPriority":13,"id":27702989,"name":"Purcell/Saville 7 - 5"},{"status":"ACTIVE","sortPriority":14,"id":27702990,"name":"Purcell/Saville 7 - 6"}],"regulators":["MR_INT"],"countryCode":"AU","discountAllowed":true,"timezone":"GMT","openDate":"2020-02-02T04:00:00.000Z","version":3148152327,"name":"Set 1 - Correct Score","eventName":"Ram/Salisbury v Purcell/Saville"}}]}
{"op":"mcm","clk":"1000716585","pt":1580619346667,"mc":[{"id":"1.168081831","marketDefinition":{"bspMarket":false,"turnInPlayEnabled":true,"persistenceEnabled":true,"marketBaseRate":5.0,"eventId":"29676917","eventTypeId":"2","numberOfWinners":1,"bettingType":"ODDS","marketType":"SET_CORRECT_SCORE","marketTime":"2020-02-02T04:00:00.000Z","suspendTime":"2020-02-02T04:00:00.000Z","bspReconciled":false,"complete":true,"inPlay":true,"crossMatching":false,"runnersVoidable":false,"numberOfActiveRunners":14,"betDelay":3,"status":"SUSPENDED","runners":[{"status":"ACTIVE","sortPriority":1,"id":27702977,"name":"Ram/Salisbury 6 - 0"},{"status":"ACTIVE","sortPriority":2,"id":27702978,"name":"Ram/Salisbury 6 - 1"},{"status":"ACTIVE","sortPriority":3,"id":27702979,"name":"Ram/Salisbury 6 - 2"},{"status":"ACTIVE","sortPriority":4,"id":27702980,"name":"Ram/Salisbury 6 - 3"},{"status":"ACTIVE","sortPriority":5,"id":27702981,"name":"Ram/Salisbury 6 - 4"},{"status":"ACTIVE","sortPriority":6,"id":27702982,"name":"Ram/Salisbury 7 - 5"},{"status":"ACTIVE","sortPriority":7,"id":27702983,"name":"Ram/Salisbury 7 - 6"},{"status":"ACTIVE","sortPriority":8,"id":27702984,"name":"Purcell/Saville 6 - 0"},{"status":"ACTIVE","sortPriority":9,"id":27702985,"name":"Purcell/Saville 6 - 1"},{"status":"ACTIVE","sortPriority":10,"id":27702986,"name":"Purcell/Saville 6 - 2"},{"status":"ACTIVE","sortPriority":11,"id":27702987,"name":"Purcell/Saville 6 - 3"},{"status":"ACTIVE","sortPriority":12,"id":27702988,"name":"Purcell/Saville 6 - 4"},{"status":"ACTIVE","sortPriority":13,"id":27702989,"name":"Purcell/Saville 7 - 5"},{"status":"ACTIVE","sortPriority":14,"id":27702990,"name":"Purcell/Saville 7 - 6"}],"regulators":["MR_INT"],"countryCode":"AU","discountAllowed":true,"timezone":"GMT","openDate":"2020-02-02T04:00:00.000Z","version":3148170012,"name":"Set 1 - Correct Score","eventName":"Ram/Salisbury v Purcell/Saville"}}]}
{"op":"mcm","clk":"1000718921","pt":1580619384739,"mc":[{"id":"1.168081831","marketDefinition":{"bspMarket":false,"turnInPlayEnabled":true,"persistenceEnabled":true,"marketBaseRate":5.0,"eventId":"29676917","eventTypeId":"2","numberOfWinners":1,"bettingType":"ODDS","marketType":"SET_CORRECT_SCORE","marketTime":"2020-02-02T04:00:00.000Z","suspendTime":"2020-02-02T04:00:00.000Z","bspReconciled":false,"complete":true,"inPlay":true,"crossMatching":false,"runnersVoidable":false,"numberOfActiveRunners":0,"betDelay":3,"status":"CLOSED","settledTime":"2020-02-02T04:56:23.000Z","runners":[{"status":"LOSER","sortPriority":1,"id":27702977,"name":"Ram/Salisbury 6 - 0"},{"status":"LOSER","sortPriority":2,"id":27702978,"name":"Ram/Salisbury 6 - 1"},{"status":"LOSER","sortPriority":3,"id":27702979,"name":"Ram/Salisbury 6 - 2"},{"status":"LOSER","sortPriority":4,"id":27702980,"name":"Ram/Salisbury 6 - 3"},{"status":"WINNER","sortPriority":5,"id":27702981,"name":"Ram/Salisbury 6 - 4"},{"status":"LOSER","sortPriority":6,"id":27702982,"name":"Ram/Salisbury 7 - 5"},{"status":"LOSER","sortPriority":7,"id":27702983,"name":"Ram/Salisbury 7 - 6"},{"status":"LOSER","sortPriority":8,"id":27702984,"name":"Purcell/Saville 6 - 0"},{"status":"LOSER","sortPriority":9,"id":27702985,"name":"Purcell/Saville 6 - 1"},{"status":"LOSER","sortPriority":10,"id":27702986,"name":"Purcell/Saville 6 - 2"},{"status":"LOSER","sortPriority":11,"id":27702987,"name":"Purcell/Saville 6 - 3"},{"status":"LOSER","sortPriority":12,"id":27702988,"name":"Purcell/Saville 6 - 4"},{"status":"LOSER","sortPriority":13,"id":27702989,"name":"Purcell/Saville 7 - 5"},{"status":"LOSER","sortPriority":14,"id":27702990,"name":"Purcell/Saville 7 - 6"}],"regulators":["MR_INT"],"countryCode":"AU","discountAllowed":true,"timezone":"GMT","openDate":"2020-02-02T04:00:00.000Z","version":3148170052,"name":"Set 1 - Correct Score","eventName":"Ram/Salisbury v Purcell/Saville"}}]}
