{"op":"mcm","clk":"978248081","pt":1580359801373,"mc":[{"id":"1.168081817","marketDefinition":{"bspMarket":false,"turnInPlayEnabled":true,"persistenceEnabled":true,"marketBaseRate":5.0,"eventId":"29676917","eventTypeId":"2","numberOfWinners":1,"bettingType":"ODDS","marketType":"MATCH_ODDS","marketTime":"2020-02-02T05:00:00.000Z","suspendTime":"2020-02-02T05:00:00.000Z","bspReconciled":false,"complete":true,"inPlay":false,"crossMatching":false,"runnersVoidable":false,"numberOfActiveRunners":2,"betDelay":0,"status":"OPEN","runners":[{"status":"ACTIVE","sortPriority":1,"id":22229228,"name":"Ram/Salisbury"},{"status":"ACTIVE","sortPriority":2,"id":15256065,"name":"Purcell/Saville"}],"regulators":["MR_INT"],"countryCode":"AU","discountAllowed":false,"timezone":"GMT","openDate":"2020-02-02T05:00:00.000Z","version":3141663672,"name":"Match Odds","eventName":"Ram/Salisbury v Purcell/Saville"},"rc":[{"batb":[[0,1.01,30]],"ltp":0.0,"tv":0.0,"id":15256065},{"batb":[[0,1.01,30]],"ltp":0.0,"tv":0.0,"id":22229228}]}]}
{"op":"mcm","clk":"978248109","pt":1580359802704,"mc":[{"id":"1.168081817","marketDefinition":{"bspMarket":false,"turnInPlayEnabled":true,"persistenceEnabled":true,"marketBaseRate":5.0,"eventId":"29676917","eventTypeId":"2","numberOfWinners":1,"bettingType":"ODDS","marketType":"MATCH_ODDS","marketTime":"2020-02-02T05:00:00.000Z","suspendTime":"2020-02-02T05:00:00.000Z","bspReconciled":false,"complete":true,"inPlay":false,"crossMatching":false,"runnersVoidable":false,"numberOfActiveRunners":2,"betDelay":0,"status":"OPEN","runners":[{"status":"ACTIVE","sortPriority":1,"id":22229228,"name":"Ram/Salisbury"},{"status":"ACTIVE","sortPriority":2,"id":15256065,"name":"Purcell/Saville"}],"regulators":["MR_INT"],"countryCode":"AU","discountAllowed":true,"timezone":"GMT","openDate":"2020-02-02T05:00:00.000Z","version":3141663672,"name":"Match Odds","eventName":"Ram/Salisbury v Purcell/Saville"}}]}
{"op":"mcm","clk":"978248823","pt":1580359831539,"mc":[{"id":"1.168081817","rc":[{"batb":[[0,1.01,330]],"ltp":0.0,"tv":0.0,"id":22229228}]}]}
{"op":"mcm","clk":"978248843","pt":1580359832720,"mc":[{"id":"1.168081817","rc":[{"batb":[[0,1.01,330]],"ltp":0.0,"tv":0.0,"id":15256065}]}]}
{"op":"mcm","clk":"978263622","pt":1580360419556,"mc":[{"id":"1.168081817","rc":[{"batb":[[0,1.01,310]],"ltp":0.0,"tv":0.0,"id":15256065},{"batb":[[0,1.01,310]],"ltp":0.0,"tv":0.0,"id":22229228}]}]}
{"op":"mcm","clk":"978271880","pt":1580360556610,"mc":[{"id":"1.168081817","rc":[{"batl":[[0,990,1.54]],"ltp":0.0,"tv":0.0,"id":15256065},{"batl":[[0,990,1.54]],"ltp":0.0,"tv":0.0,"id":22229228}]}]}
{"op":"mcm","clk":"978276081","pt":1580360710592,"mc":[{"id":"1.168081817","rc":[{"batb":[[0,1.02,153.67],[1,1.01,310]],"ltp":0.0,"tv":0.0,"id":15256065},{"batb":[[0,1.02,153.67],[1,1.01,310]],"ltp":0.0,"tv":0.0,"id":22229228}]}]}
{"op":"mcm","clk":"978288407","pt":1580361134624,"mc":[{"id":"1.168081817","rc":[{"batb":[[1,1.01,310.2]],"ltp":0.0,"tv":0.0,"id":15256065},{"batb":[[1,1.01,310.2]],"ltp":0.0,"tv":0.0,"id":22229228}]}]}
{"op":"mcm","clk":"978288421","pt":1580361134931,"mc":[{"id":"1.168081817","rc":[{"batb":[[0,1.02,153.87],[1,1.01,310]],"ltp":0.0,"tv":0.0,"id":15256065},{"batb":[[0,1.02,153.87],[1,1.01,310]],"ltp":0.0,"tv":0.0,"id":22229228}]}]}
{"op":"mcm","clk":"978288518","pt":1580361138214,"mc":[{"id":"1.168081817","rc":[{"batl":[[0,990,3.74]],"ltp":0.0,"tv":0.0,"id":15256065},{"batl":[[0,990,3.74]],"ltp":0.0,"tv":0.0,"id":22229228}]}]}
{"op":"mcm","clk":"978288556","pt":1580361139450,"mc":[{"id":"1.168081817","rc":[{"batb":[[0,1.02,154.47],[1,1.01,312]],"batl":[[1,1000,0.02]],"ltp":0.0,"tv":0.0,"id":15256065},{"batb":[[0,1.02,154.47],[1,1.01,312]],"batl":[[1,1000,0.02]],"ltp":0.0,"tv":0.0,"id":22229228}]}]}
{"op":"mcm","clk":"978289212","pt":1580361169064,"mc":[{"id":"1.168081817","marketDefinition":{"bspMarket":false,"turnInPlayEnabled":true,"persistenceEnabled":true,"marketBaseRate":5.0,"eventId":"29676917","eventTypeId":"2","numberOfWinners":1,"bettingType":"ODDS","marketType":"MATCH_ODDS","marketTime":"2020-02-02T05:00:00.000Z","suspendTime":"2020-02-02T05:00:00.000Z","bspReconciled":false,"complete":true,"inPlay":false,"crossMatching":true,"runnersVoidable":false,"numberOfActiveRunners":2,"betDelay":0,"status":"OPEN","runners":[{"status":"ACTIVE","sortPriority":1,"id":22229228,"name":"Ram/Salisbury"},{"status":"ACTIVE","sortPriority":2,"id":15256065,"name":"Purcell/Saville"}],"regulators":["MR_INT"],"countryCode":"AU","discountAllowed":true,"timezone":"GMT","openDate":"2020-02-02T05:00:00.000Z","version":3141663672,"name":"Match Odds","eventName":"Ram/Salisbury v Purcell/Saville"}}]}
{"op":"mcm","clk":"978417335","pt":1580365987461,"mc":[{"id":"1.168081817","rc":[{"batb":[[0,1.13,76.93],[1,1.02,154.37],[2,1.01,312]],"ltp":0.0,"tv":0.0,"id":15256065},{"batb":[[0,1.13,76.93],[1,1.02,154.37],[2,1.01,312]],"ltp":0.0,"tv":0.0,"id":22229228}]}]}
{"op":"mcm","clk":"978451854","pt":1580367751845,"mc":[{"id":"1.168081817","rc":[{"batb":[[0,1.13,76.95],[1,1.02,154.4]],"ltp":0.0,"tv":0.0,"id":15256065},{"batb":[[0,1.13,76.95],[1,1.02,154.4]],"ltp":0.0,"tv":0.0,"id":22229228}]}]}
{"op":"mcm","clk":"978515863","pt":1580369624416,"mc":[{"id":"1.168081817","rc":[{"batb":[[2,1.01,318.15]],"ltp":0.0,"tv":0.0,"id":22229228}]}]}
{"op":"mcm","clk":"978568020","pt":1580371351845,"mc":[{"id":"1.168081817","rc":[{"batb":[[0,1.13,77.03],[1,1.02,154.56]],"batl":[[0,990,3.74]],"ltp":0.0,"tv":0.0,"id":15256065},{"batb":[[0,1.13,77.03],[1,1.02,154.56],[2,1.01,318.15]],"batl":[[0,990,3.74]],"ltp":0.0,"tv":0.0,"id":22229228}]}]}
{"op":"mcm","clk":"978756415","pt":1580376145184,"mc":[{"id":"1.168081817","rc":[{"batb":[[0,2.32,28.64],[1,1.13,77.03],[2,1.02,154.56]],"ltp":0.0,"tv":0.0,"id":15256065},{"batb":[[0,1.42,51.94],[1,1.13,77.03],[2,1.02,154.56]],"ltp":0.0,"tv":0.0,"id":22229228}]}]}
{"op":"mcm","clk":"978762123","pt":1580376310644,"mc":[{"id":"1.168081817","rc":[{"batb":[[0,2.34,30.77],[1,2.32,28.64],[2,1.13,77.03]],"ltp":0.0,"tv":0.0,"id":15256065},{"batb":[[0,1.47,50.18],[1,1.43,30.76],[2,1.13,77.03]],"ltp":0.0,"tv":0.0,"id":22229228}]}]}
{"op":"mcm","clk":"978762133","pt":1580376310901,"mc":[{"id":"1.168081817","rc":[{"batb":[[0,2.36,28.18],[1,2.34,30.77]],"ltp":0.0,"tv":0.0,"id":15256065}]}]}
{"op":"mcm","clk":"978765358","pt":1580376432691,"mc":[{"id":"1.168081817","rc":[{"batb":[[0,1.48,30.77],[1,1.13,77.03],[2,1.02,154.56]],"ltp":0.0,"tv":0.0,"id":22229228}]}]}
{"op":"mcm","clk":"978765375","pt":1580376433305,"mc":[{"id":"1.168081817","rc":[{"batb":[[0,2.4,27.56],[1,2.38,30.77]],"ltp":0.0,"tv":0.0,"id":15256065},{"batb":[[0,1.48,80.53]],"ltp":0.0,"tv":0.0,"id":22229228}]}]}
{"op":"mcm","clk":"978768429","pt":1580376554654,"mc":[{"id":"1.168081817","rc":[{"batb":[[0,2.56,25.83],[1,2.42,30.77]],"ltp":0.0,"tv":0.0,"id":15256065},{"batb":[[0,1.48,49.76]],"ltp":0.0,"tv":0.0,"id":22229228}]}]}
{"op":"mcm","clk":"978770124","pt":1580376612281,"mc":[{"id":"1.168081817","rc":[{"batb":[[0,2.42,30.77],[1,1.13,77.03],[2,1.02,154.56]],"ltp":0.0,"tv":0.0,"id":15256065},{"batb":[[0,1.13,77.03],[1,1.02,154.56],[2,1.01,318.15]],"ltp":0.0,"tv":0.0,"id":22229228}]}]}
{"op":"mcm","clk":"978770818","pt":1580376628586,"mc":[{"id":"1.168081817","rc":[{"batb":[[0,2.52,26.24],[1,2.42,30.77],[2,1.13,77.03]],"ltp":0.0,"tv":0.0,"id":15256065},{"batb":[[0,1.38,53.46],[1,1.13,77.03],[2,1.02,154.56]],"ltp":0.0,"tv":0.0,"id":22229228}]}]}
{"op":"mcm","clk":"978772385","pt":1580376675444,"mc":[{"id":"1.168081817","rc":[{"batb":[[0,1.4,52.66],[1,1.39,30.77],[2,1.13,77.03]],"ltp":0.0,"tv":0.0,"id":22229228}]}]}
{"op":"mcm","clk":"978772410","pt":1580376676168,"mc":[{"id":"1.168081817","rc":[{"batb":[[0,2.56,25.83],[1,2.54,30.77]],"ltp":0.0,"tv":0.0,"id":15256065}]}]}
{"op":"mcm","clk":"978773802","pt":1580376715523,"mc":[{"id":"1.168081817","rc":[{"batb":[[0,2.54,30.77],[1,1.13,77.03],[2,1.02,154.56]],"ltp":0.0,"tv":0.0,"id":15256065},{"batb":[[0,1.39,30.77],[1,1.13,77.03],[2,1.02,154.56]],"ltp":0.0,"tv":0.0,"id":22229228}]}]}
{"op":"mcm","clk":"978774381","pt":1580376734618,"mc":[{"id":"1.168081817","rc":[{"batb":[[0,2.56,25.83],[1,2.54,30.77],[2,1.13,77.03]],"ltp":0.0,"tv":0.0,"id":15256065},{"batb":[[0,1.4,52.66],[1,1.39,30.77],[2,1.13,77.03]],"ltp":0.0,"tv":0.0,"id":22229228}]}]}
{"op":"mcm","clk":"978781613","pt":1580376797701,"mc":[{"id":"1.168081817","rc":[{"batb":[[0,2.58,30.77],[1,1.13,77.03],[2,1.02,154.56]],"ltp":0.0,"tv":0.0,"id":15256065},{"batb":[[0,1.45,50.81],[1,1.41,30.77]],"ltp":0.0,"tv":0.0,"id":22229228}]}]}
{"op":"mcm","clk":"978781635","pt":1580376798627,"mc":[{"id":"1.168081817","rc":[{"batb":[[0,2.6,25.39],[1,2.58,30.77],[2,2.46,84.62]],"ltp":0.0,"tv":0.0,"id":15256065},{"batb":[[1,1.43,88.47],[2,1.41,30.77]],"ltp":0.0,"tv":0.0,"id":22229228}]}]}
{"op":"mcm","clk":"978784623","pt":1580376918659,"mc":[{"id":"1.168081817","rc":[{"batb":[[0,1.46,30.77],[1,1.45,50.81],[2,1.43,88.47]],"ltp":0.0,"tv":0.0,"id":22229228}]}]}
{"op":"mcm","clk":"978784660","pt":1580376919685,"mc":[{"id":"1.168081817","rc":[{"batb":[[0,2.62,56.1],[1,2.46,84.62],[2,1.13,77.03]],"ltp":0.0,"tv":0.0,"id":15256065},{"batb":[[0,1.47,50.18],[1,1.46,30.77]],"ltp":0.0,"tv":0.0,"id":22229228}]}]}
{"op":"mcm","clk":"978787772","pt":1580377040674,"mc":[{"id":"1.168081817","rc":[{"batb":[[0,1.48,80.53],[1,1.43,88.47],[2,1.13,77.03]],"ltp":0.0,"tv":0.0,"id":22229228}]}]}
{"op":"mcm","clk":"978787779","pt":1580377040882,"mc":[{"id":"1.168081817","rc":[{"batb":[[0,2.62,25.33]],"ltp":0.0,"tv":0.0,"id":15256065}]}]}
{"op":"mcm","clk":"978791400","pt":1580377161807,"mc":[{"id":"1.168081817","rc":[{"batb":[[0,1.48,49.76]],"ltp":0.0,"tv":0.0,"id":22229228}]}]}
{"op":"mcm","clk":"978840426","pt":1580378217548,"mc":[{"id":"1.168081817","rc":[{"batl":[[0,3,2.5],[1,990,3.74],[2,1000,0.02]],"ltp":0.0,"tv":0.0,"id":15256065},{"batb":[[0,1.43,88.47],[1,1.13,77.03],[2,1.02,154.56]],"ltp":0.0,"tv":0.0,"id":22229228}]}]}
{"op":"mcm","clk":"978841853","pt":1580378256917,"mc":[{"id":"1.168081817","rc":[{"batb":[[0,1.44,30.77],[1,1.43,88.47],[2,1.13,77.03]],"ltp":0.0,"tv":0.0,"id":22229228}]}]}
{"op":"mcm","clk":"978854339","pt":1580378551846,"mc":[{"id":"1.168081817","rc":[{"batb":[[1,2.46,84.51],[2,1.13,76.93]],"batl":[[1,990,3.74]],"ltp":0.0,"tv":0.0,"id":15256065},{"batb":[[0,1.44,30.73],[1,1.43,88.35],[2,1.13,76.93]],"batl":[[0,990,3.74]],"ltp":0.0,"tv":0.0,"id":22229228}]}]}
{"op":"mcm","clk":"978932996","pt":1580380028539,"mc":[{"id":"1.168081817","rc":[{"batb":[[0,2.62,50.83]],"ltp":0.0,"tv":0.0,"id":15256065}]}]}
{"op":"mcm","clk":"978943581","pt":1580380335235,"mc":[{"id":"1.168081817","rc":[{"batb":[[0,2.6,51.04]],"ltp":0.0,"tv":0.0,"id":15256065}]}]}
{"op":"mcm","clk":"978953606","pt":1580380448439,"mc":[{"id":"1.168081817","rc":[{"batb":[[0,2.62,81.56]],"ltp":0.0,"tv":0.0,"id":15256065}]}]}
{"op":"mcm","clk":"978958971","pt":1580380569990,"mc":[{"id":"1.168081817","rc":[{"batb":[[0,2.62,50.83]],"ltp":0.0,"tv":0.0,"id":15256065}]}]}
{"op":"mcm","clk":"978977030","pt":1580380994431,"mc":[{"id":"1.168081817","rc":[{"batb":[[0,2.52,51.74]],"batl":[[0,3,50.66]],"ltp":0.0,"tv":0.0,"id":15256065}]}]}
{"op":"mcm","clk":"978977056","pt":1580380995152,"mc":[{"id":"1.168081817","rc":[{"batl":[[0,3,2.5]],"ltp":0.0,"tv":0.0,"id":15256065},{"batb":[[0,1.51,7.12],[1,1.44,30.73],[2,1.43,88.35]],"ltp":0.0,"tv":0.0,"id":22229228}]}]}
{"op":"mcm","clk":"978977090","pt":1580380996030,"mc":[{"id":"1.168081817","rc":[{"batb":[[1,1.13,76.93],[2,1.02,154.36]],"ltp":0.0,"tv":0.0,"id":15256065}]}]}
{"op":"mcm","clk":"978979579","pt":1580381056566,"mc":[{"id":"1.168081817","rc":[{"batb":[[0,2.54,30.73],[1,2.52,51.74],[2,1.13,76.93]],"ltp":0.0,"tv":0.0,"id":15256065}]}]}
{"op":"mcm","clk":"978979592","pt":1580381056865,"mc":[{"id":"1.168081817","rc":[{"batb":[[0,2.56,51.08],[1,2.54,30.73]],"ltp":0.0,"tv":0.0,"id":15256065}]}]}
{"op":"mcm","clk":"978980751","pt":1580381081992,"mc":[{"id":"1.168081817","rc":[{"batb":[[2,1.43,145.21]],"ltp":0.0,"tv":0.0,"id":22229228}]}]}
{"op":"mcm","clk":"978985370","pt":1580381178151,"mc":[{"id":"1.168081817","rc":[{"batb":[[1,1.13,76.93],[2,1.02,154.36]],"ltp":0.0,"tv":0.0,"id":15256065}]}]}
{"op":"mcm","clk":"979008648","pt":1580381599675,"mc":[{"id":"1.168081817","rc":[{"batl":[[0,2.84,50.98],[1,3,2.5],[2,990,3.74]],"ltp":0.0,"tv":0.0,"id":15256065}]}]}
{"op":"mcm","clk":"979011414","pt":1580381664972,"mc":[{"id":"1.168081817","rc":[{"batb":[[1,1.43,145.21],[2,1.13,76.93]],"ltp":0.0,"tv":0.0,"id":22229228}]}]}
{"op":"mcm","clk":"979029654","pt":1580382047393,"mc":[{"id":"1.168081817","rc":[{"batb":[[1,2.54,81.44],[2,1.13,76.93]],"ltp":0.0,"tv":0.0,"id":15256065},{"batb":[[1,1.49,145.21]],"ltp":0.0,"tv":0.0,"id":22229228}]}]}
{"op":"mcm","clk":"979033126","pt":1580382101869,"mc":[{"id":"1.168081817","rc":[{"batl":[[0,2.78,5.66],[1,2.84,50.98],[2,3,2.5]],"ltp":0.0,"tv":0.0,"id":15256065}]}]}
{"op":"mcm","clk":"979033520","pt":1580382108040,"mc":[{"id":"1.168081817","rc":[{"batl":[[0,2.76,5.66]],"ltp":0.0,"tv":0.0,"id":15256065}]}]}
{"op":"mcm","clk":"979033882","pt":1580382114587,"mc":[{"id":"1.168081817","rc":[{"batl":[[0,2.84,50.98],[1,3,2.5],[2,990,3.74]],"ltp":0.0,"tv":0.0,"id":15256065}]}]}
{"op":"mcm","clk":"979035362","pt":1580382141993,"mc":[{"id":"1.168081817","rc":[{"batb":[[0,2.54,81.44],[1,1.13,76.93],[2,1.02,154.36]],"batl":[[0,2.84,99.22]],"ltp":0.0,"tv":0.0,"id":15256065}]}]}
{"op":"mcm","clk":"979035535","pt":1580382144627,"mc":[{"id":"1.168081817","rc":[{"batb":[[0,2.16,57.28]],"ltp":0.0,"tv":0.0,"id":15256065}]}]}
{"op":"mcm","clk":"979035959","pt":1580382151622,"mc":[{"id":"1.168081817","rc":[{"batb":[[0,2.42,51.13],[1,2.4,86.05],[2,2.24,30.73]],"ltp":0.0,"tv":0.0,"id":15256065},{"batb":[[0,1.51,152.33],[1,1.13,76.93],[2,1.02,154.36]],"ltp":0.0,"tv":0.0,"id":22229228}]}]}
{"op":"mcm","clk":"979049006","pt":1580382273656,"mc":[{"id":"1.168081817","rc":[{"batb":[[0,2.44,30.73],[2,1.13,76.93]],"ltp":0.0,"tv":0.0,"id":15256065}]}]}
{"op":"mcm","clk":"979049013","pt":1580382273760,"mc":[{"id":"1.168081817","rc":[{"batb":[[0,2.44,81.4]],"ltp":0.0,"tv":0.0,"id":15256065}]}]}
{"op":"mcm","clk":"979057563","pt":1580382394957,"mc":[{"id":"1.168081817","rc":[{"batb":[[0,2.44,50.67]],"ltp":0.0,"tv":0.0,"id":15256065}]}]}
{"op":"mcm","clk":"979068901","pt":1580382536622,"mc":[{"id":"1.168081817","rc":[{"batl":[[0,2.8,50.98],[1,2.84,48.24],[2,3,2.5]],"ltp":0.0,"tv":0.0,"id":15256065}]}]}
{"op":"mcm","clk":"979068920","pt":1580382536827,"mc":[{"id":"1.168081817","rc":[{"batl":[[1,3,2.5],[2,990,3.74]],"ltp":0.0,"tv":0.0,"id":15256065}]}]}
{"op":"mcm","clk":"979086854","pt":1580382812561,"mc":[{"id":"1.168081817","rc":[{"batb":[[0,1.56,7.12],[1,1.51,145.21],[2,1.13,76.93]],"ltp":0.0,"tv":0.0,"id":22229228}]}]}
{"op":"mcm","clk":"979094043","pt":1580382950226,"mc":[{"id":"1.168081817","rc":[{"batb":[[0,1.57,6],[1,1.56,7.12],[2,1.51,145.21]],"ltp":0.0,"tv":0.0,"id":22229228}]}]}
{"op":"mcm","clk":"979095972","pt":1580382984681,"mc":[{"id":"1.168081817","rc":[{"batl":[[0,1.65,20.74],[1,990,3.74],[2,1000,0.02]],"ltp":0.0,"tv":0.0,"id":22229228}]}]}
{"op":"mcm","clk":"979095991","pt":1580382984990,"mc":[{"id":"1.168081817","rc":[{"batb":[[0,2.4,86.05],[1,1.13,76.93],[2,1.02,154.36]],"ltp":0.0,"tv":0.0,"id":15256065}]}]}
{"op":"mcm","clk":"979097001","pt":1580383003312,"mc":[{"id":"1.168081817","rc":[{"batb":[[0,2.42,30.73],[1,2.4,86.05],[2,1.13,76.93]],"ltp":0.0,"tv":0.0,"id":15256065}]}]}
{"op":"mcm","clk":"979099214","pt":1580383043349,"mc":[{"id":"1.168081817","rc":[{"batl":[[1,900,2.1],[2,990,3.74]],"ltp":0.0,"tv":0.0,"id":22229228}]}]}
{"op":"mcm","clk":"979099459","pt":1580383047854,"mc":[{"id":"1.168081817","rc":[{"batl":[[1,990,3.74],[2,1000,0.02]],"ltp":0.0,"tv":0.0,"id":22229228}]}]}
{"op":"mcm","clk":"979105662","pt":1580383055066,"mc":[{"id":"1.168081817","rc":[{"batl":[[1,900,2.1],[2,990,3.74]],"ltp":0.0,"tv":0.0,"id":22229228}]}]}
{"op":"mcm","clk":"979105903","pt":1580383059886,"mc":[{"id":"1.168081817","rc":[{"batl":[[1,990,3.74],[2,1000,0.02]],"ltp":0.0,"tv":0.0,"id":22229228}]}]}
{"op":"mcm","clk":"979106212","pt":1580383065987,"mc":[{"id":"1.168081817","rc":[{"batl":[[1,900,2.1],[2,990,3.74]],"ltp":0.0,"tv":0.0,"id":22229228}]}]}
{"op":"mcm","clk":"979106581","pt":1580383073095,"mc":[{"id":"1.168081817","rc":[{"batl":[[1,990,3.74],[2,1000,0.02]],"ltp":0.0,"tv":0.0,"id":22229228}]}]}
{"op":"mcm","clk":"979106862","pt":1580383078581,"mc":[{"id":"1.168081817","rc":[{"batl":[[1,900,2.1],[2,990,3.74]],"ltp":0.0,"tv":0.0,"id":22229228}]}]}
{"op":"mcm","clk":"979107033","pt":1580383081677,"mc":[{"id":"1.168081817","rc":[{"batl":[[1,990,3.74],[2,1000,0.02]],"ltp":0.0,"tv":0.0,"id":22229228}]}]}
{"op":"mcm","clk":"979107038","pt":1580383081782,"mc":[{"id":"1.168081817","rc":[{"batl":[[1,890,2.1],[2,990,3.74]],"ltp":0.0,"tv":0.0,"id":22229228}]}]}
{"op":"mcm","clk":"979107193","pt":1580383084518,"mc":[{"id":"1.168081817","rc":[{"batl":[[1,990,3.74],[2,1000,0.02]],"ltp":0.0,"tv":0.0,"id":22229228}]}]}
{"op":"mcm","clk":"979133843","pt":1580383567538,"mc":[{"id":"1.168081817","rc":[{"batl":[[1,900,2.1],[2,990,3.74]],"ltp":0.0,"tv":0.0,"id":22229228}]}]}
{"op":"mcm","clk":"979134048","pt":1580383571055,"mc":[{"id":"1.168081817","rc":[{"batl":[[1,990,3.74],[2,1000,0.02]],"ltp":0.0,"tv":0.0,"id":22229228}]}]}
{"op":"mcm","clk":"979134250","pt":1580383575674,"mc":[{"id":"1.168081817","rc":[{"batl":[[1,900,2.1],[2,990,3.74]],"ltp":0.0,"tv":0.0,"id":22229228}]}]}
{"op":"mcm","clk":"979134386","pt":1580383578549,"mc":[{"id":"1.168081817","rc":[{"batl":[[1,990,3.74],[2,1000,0.02]],"ltp":0.0,"tv":0.0,"id":22229228}]}]}
{"op":"mcm","clk":"979134639","pt":1580383583690,"mc":[{"id":"1.168081817","rc":[{"batl":[[1,900,2.1],[2,990,3.74]],"ltp":0.0,"tv":0.0,"id":22229228}]}]}
{"op":"mcm","clk":"979134900","pt":1580383589403,"mc":[{"id":"1.168081817","rc":[{"batl":[[1,990,3.74],[2,1000,0.02]],"ltp":0.0,"tv":0.0,"id":22229228}]}]}
{"op":"mcm","clk":"979135120","pt":1580383593987,"mc":[{"id":"1.168081817","rc":[{"batl":[[1,900,2.1],[2,990,3.74]],"ltp":0.0,"tv":0.0,"id":22229228}]}]}
{"op":"mcm","clk":"979135316","pt":1580383597697,"mc":[{"id":"1.168081817","rc":[{"batl":[[1,890,2.1]],"ltp":0.0,"tv":0.0,"id":22229228}]}]}
{"op":"mcm","clk":"979135419","pt":1580383599907,"mc":[{"id":"1.168081817","rc":[{"batl":[[1,990,3.74],[2,1000,0.02]],"ltp":0.0,"tv":0.0,"id":22229228}]}]}
{"op":"mcm","clk":"979140605","pt":1580383701508,"mc":[{"id":"1.168081817","rc":[{"batl":[[0,2.76,2.5],[1,2.8,50.98],[2,3,2.5]],"ltp":0.0,"tv":0.0,"id":15256065}]}]}
{"op":"mcm","clk":"979151561","pt":1580383922065,"mc":[{"id":"1.168081817","rc":[{"batb":[[2,1.05,77.13]],"ltp":0.0,"tv":0.0,"id":15256065}]}]}
{"op":"mcm","clk":"979152324","pt":1580383934989,"mc":[{"id":"1.168081817","rc":[{"batl":[[1,2.2,3.07],[2,990,3.74]],"ltp":0.0,"tv":0.0,"id":22229228}]}]}
{"op":"mcm","clk":"979174089","pt":1580384192203,"mc":[{"id":"1.168081817","rc":[{"batl":[[0,2.8,50.98],[1,3,2.5],[2,990,3.74]],"ltp":0.0,"tv":0.0,"id":15256065}]}]}
{"op":"mcm","clk":"979199622","pt":1580384610104,"mc":[{"id":"1.168081817","rc":[{"batb":[[1,1.51,145.21],[2,1.25,12.29]],"ltp":0.0,"tv":0.0,"id":22229228}]}]}
{"op":"mcm","clk":"979216872","pt":1580384879174,"mc":[{"id":"1.168081817","rc":[{"batb":[[0,1.58,116.87],[1,1.57,6],[2,1.51,145.21]],"ltp":0.0,"tv":0.0,"id":22229228}]}]}
{"op":"mcm","clk":"979216949","pt":1580384880589,"mc":[{"id":"1.168081817","rc":[{"batb":[[1,1.05,77.13],[2,1.02,154.16]],"ltp":0.0,"tv":0.0,"id":15256065}]}]}
{"op":"mcm","clk":"979220285","pt":1580384950504,"mc":[{"id":"1.168081817","rc":[{"batb":[[0,2.06,30.73]],"ltp":0.0,"tv":0.0,"id":15256065}]}]}
{"op":"mcm","clk":"979240830","pt":1580385305025,"mc":[{"id":"1.168081817","rc":[{"batb":[[0,2.42,390.84],[1,2.06,30.73],[2,1.05,77.13]],"ltp":0.0,"tv":0.0,"id":15256065},{"batb":[[2,1.51,1233.44]],"ltp":0.0,"tv":0.0,"id":22229228}]}]}
{"op":"mcm","clk":"979241454","pt":1580385315231,"mc":[{"id":"1.168081817","rc":[{"batb":[[1,1.05,77.13],[2,1.02,154.16]],"ltp":0.0,"tv":0.0,"id":15256065}]}]}
{"op":"mcm","clk":"979260090","pt":1580385702441,"mc":[{"id":"1.168081817","rc":[{"batb":[[1,1.05,77.05],[2,1.02,154.21]],"batl":[[0,2.8,50.95],[1,3,2.5],[2,990,3.74]],"ltp":0.0,"tv":0.0,"id":15256065},{"batb":[[2,1.51,1233.29]],"batl":[[0,1.65,20.72],[1,2.2,3.07],[2,990,3.74]],"ltp":0.0,"tv":0.0,"id":22229228}]}]}
{"op":"mcm","clk":"979269346","pt":1580385768575,"mc":[{"id":"1.168081817","rc":[{"batb":[[1,2.32,89.03],[2,1.05,77.05]],"ltp":0.0,"tv":0.0,"id":15256065}]}]}
{"op":"mcm","clk":"979314394","pt":1580386493632,"mc":[{"id":"1.168081817","rc":[{"batl":[[2,4,3.07]],"ltp":0.0,"tv":0.0,"id":22229228}]}]}
{"op":"mcm","clk":"979314628","pt":1580386499725,"mc":[{"id":"1.168081817","rc":[{"batl":[[2,4,3.45]],"ltp":0.0,"tv":0.0,"id":22229228}]}]}
{"op":"mcm","clk":"979315205","pt":1580386512861,"mc":[{"id":"1.168081817","rc":[{"batl":[[0,1.65,21.11],[2,990,3.74]],"ltp":0.0,"tv":0.0,"id":22229228}]}]}
{"op":"mcm","clk":"979345232","pt":1580386981548,"mc":[{"id":"1.168081817","rc":[{"batb":[[0,1.58,156.56]],"ltp":0.0,"tv":0.0,"id":22229228}]}]}
{"op":"mcm","clk":"979445711","pt":1580388479846,"mc":[{"id":"1.168081817","rc":[{"batb":[[0,1.57,6],[1,1.51,1233.29],[2,1.25,12.28]],"ltp":0.0,"tv":0.0,"id":22229228}]}]}
{"op":"mcm","clk":"979454442","pt":1580388600386,"mc":[{"id":"1.168081817","rc":[{"batb":[[1,1.56,30.7],[2,1.51,1233.29]],"ltp":0.0,"tv":0.0,"id":22229228}]}]}
{"op":"mcm","clk":"979454475","pt":1580388600796,"mc":[{"id":"1.168081817","rc":[{"batb":[[0,1.58,157.37],[1,1.57,6],[2,1.56,30.7]],"ltp":0.0,"tv":0.0,"id":22229228}]}]}
{"op":"mcm","clk":"979464650","pt":1580388722111,"mc":[{"id":"1.168081817","rc":[{"batb":[[2,1.51,1233.29]],"ltp":0.0,"tv":0.0,"id":22229228}]}]}
{"op":"mcm","clk":"979504144","pt":1580389255975,"mc":[{"id":"1.168081817","rc":[{"batb":[[1,2.34,89.03]],"ltp":0.0,"tv":0.0,"id":15256065}]}]}
{"op":"mcm","clk":"979636382","pt":1580390783983,"mc":[{"id":"1.168081817","rc":[{"batb":[[0,1.58,198.37]],"ltp":0.0,"tv":0.0,"id":22229228}]}]}
{"op":"mcm","clk":"979658408","pt":1580391062854,"mc":[{"id":"1.168081817","rc":[{"batb":[[0,1.57,6],[1,1.51,1233.29],[2,1.25,12.28]],"ltp":0.0,"tv":0.0,"id":22229228}]}]}
{"op":"mcm","clk":"979658626","pt":1580391066661,"mc":[{"id":"1.168081817","rc":[{"batb":[[1,2.26,89.03]],"ltp":0.0,"tv":0.0,"id":15256065},{"batb":[[1,1.51,1088.23]],"ltp":0.0,"tv":0.0,"id":22229228}]}]}
{"op":"mcm","clk":"979659167","pt":1580391074256,"mc":[{"id":"1.168081817","rc":[{"batb":[[1,2.38,89.03]],"ltp":0.0,"tv":0.0,"id":15256065},{"batb":[[1,1.51,1225.62]],"ltp":0.0,"tv":0.0,"id":22229228}]}]}
{"op":"mcm","clk":"979671135","pt":1580391155726,"mc":[{"id":"1.168081817","rc":[{"batb":[[1,1.56,30.7],[2,1.51,1225.62]],"ltp":0.0,"tv":0.0,"id":22229228}]}]}
{"op":"mcm","clk":"979680079","pt":1580391285400,"mc":[{"id":"1.168081817","rc":[{"trd":[[1.64,0.76],[1.65,17.82]],"batl":[[0,1.65,11.79]],"ltp":1.65,"tv":18.58,"id":22229228}],"tv":18.58}]}
{"op":"mcm","clk":"979728671","pt":1580391909839,"mc":[{"id":"1.168081817","rc":[{"batb":[[2,1.37,4]],"ltp":0.0,"tv":0.0,"id":15256065}]}]}
{"op":"mcm","clk":"979783689","pt":1580392564890,"mc":[{"id":"1.168081817","rc":[{"batb":[[1,1.37,4],[2,1.05,77.05]],"ltp":0.0,"tv":0.0,"id":15256065},{"batb":[[2,1.51,1088.23]],"ltp":1.65,"tv":18.58,"id":22229228}]}]}
{"op":"mcm","clk":"979790104","pt":1580392638568,"mc":[{"id":"1.168081817","rc":[{"batb":[[1,2.22,41.45],[2,1.37,4]],"ltp":0.0,"tv":0.0,"id":15256065}]}]}
{"op":"mcm","clk":"979791063","pt":1580392650156,"mc":[{"id":"1.168081817","rc":[{"batb":[[1,2.32,41.45]],"ltp":0.0,"tv":0.0,"id":15256065}]}]}
{"op":"mcm","clk":"979815299","pt":1580392951883,"mc":[{"id":"1.168081817","rc":[{"batb":[[1,2.32,41.24]],"batl":[[0,2.8,50.7],[1,3,2.48],[2,990,3.73]],"ltp":0.0,"tv":0.0,"id":15256065},{"trd":[[1.64,0.76],[1.65,17.78]],"batb":[[1,1.56,30.55]],"batl":[[0,1.65,11.73],[1,2.2,3.05],[2,990,3.73]],"ltp":1.65,"tv":18.54,"id":22229228}],"tv":18.54}]}
{"op":"mcm","clk":"979837267","pt":1580393223047,"mc":[{"id":"1.168081817","rc":[{"batb":[[1,2.38,41.24]],"ltp":0.0,"tv":0.0,"id":15256065},{"batb":[[2,1.51,1149.33]],"ltp":1.65,"tv":18.54,"id":22229228}]}]}
{"op":"mcm","clk":"979847635","pt":1580393373558,"mc":[{"id":"1.168081817","rc":[{"batb":[[1,2.38,86.3]],"ltp":0.0,"tv":0.0,"id":15256065}]}]}
{"op":"mcm","clk":"979847669","pt":1580393373972,"mc":[{"id":"1.168081817","rc":[{"batb":[[2,1.51,1224.93]],"ltp":1.65,"tv":18.54,"id":22229228}]}]}
{"op":"mcm","clk":"979890397","pt":1580393960068,"mc":[{"id":"1.168081817","rc":[{"batl":[[0,2.78,4.09],[1,2.8,50.7],[2,3,2.48]],"ltp":0.0,"tv":0.0,"id":15256065}]}]}
{"op":"mcm","clk":"979893865","pt":1580394030779,"mc":[{"id":"1.168081817","rc":[{"batl":[[0,2.74,11.27],[1,2.78,4.09],[2,2.8,50.7]],"ltp":0.0,"tv":0.0,"id":15256065}]}]}
{"op":"mcm","clk":"979896313","pt":1580394076042,"mc":[{"id":"1.168081817","rc":[{"batb":[[1,1.51,1224.93],[2,1.37,4]],"ltp":1.65,"tv":18.54,"id":22229228}]}]}
{"op":"mcm","clk":"979956353","pt":1580395078598,"mc":[{"id":"1.168081817","rc":[{"batb":[[1,2.26,86.3]],"ltp":0.0,"tv":0.0,"id":15256065}]}]}
{"op":"mcm","clk":"979966398","pt":1580395273269,"mc":[{"id":"1.168081817","rc":[{"batb":[[1,2.38,86.3]],"ltp":0.0,"tv":0.0,"id":15256065}]}]}
{"op":"mcm","clk":"980189045","pt":1580400047522,"mc":[{"id":"1.168081817","rc":[{"batb":[[1,2.26,86.25]],"batl":[[0,2.74,11.27],[1,2.78,4.08],[2,2.8,50.72]],"ltp":0.0,"tv":0.0,"id":15256065},{"trd":[[1.65,17.77]],"batb":[[1,1.51,1224.85]],"batl":[[0,1.65,11.72],[1,2.2,3.05]],"ltp":1.65,"tv":18.53,"id":22229228}],"tv":18.53}]}
{"op":"mcm","clk":"980190114","pt":1580400071433,"mc":[{"id":"1.168081817","rc":[{"batb":[[1,2.38,86.25]],"ltp":0.0,"tv":0.0,"id":15256065}]}]}
{"op":"mcm","clk":"980374222","pt":1580403909074,"mc":[{"id":"1.168081817","rc":[{"batl":[[2,990,2.2]],"ltp":1.65,"tv":18.53,"id":22229228}]}]}
{"op":"mcm","clk":"980400783","pt":1580404659473,"mc":[{"id":"1.168081817","rc":[{"batb":[[1,2.26,86.25]],"ltp":0.0,"tv":0.0,"id":15256065}]}]}
{"op":"mcm","clk":"980405858","pt":1580404854049,"mc":[{"id":"1.168081817","rc":[{"batb":[[1,2.38,86.25]],"ltp":0.0,"tv":0.0,"id":15256065}]}]}
{"op":"mcm","clk":"980489115","pt":1580407351884,"mc":[{"id":"1.168081817","rc":[{"batb":[[1,2.38,86.29]],"batl":[[0,2.74,11.28],[1,2.78,4.09],[2,2.8,50.76]],"ltp":0.0,"tv":0.0,"id":15256065},{"trd":[[1.65,17.78]],"batb":[[1,1.51,1224.92]],"batl":[[0,1.65,11.73],[1,2.2,3.05]],"ltp":1.65,"tv":18.54,"id":22229228}],"tv":18.54}]}
{"op":"mcm","clk":"980575319","pt":1580409132360,"mc":[{"id":"1.168081817","rc":[{"batb":[[1,2.36,86.29]],"ltp":0.0,"tv":0.0,"id":15256065},{"batb":[[1,1.51,1088.23]],"ltp":1.65,"tv":18.54,"id":22229228}]}]}
{"op":"mcm","clk":"980575724","pt":1580409141572,"mc":[{"id":"1.168081817","rc":[{"batb":[[0,2.48,86.29],[1,2.42,390.84]],"ltp":0.0,"tv":0.0,"id":15256065}]}]}
{"op":"mcm","clk":"980575731","pt":1580409141728,"mc":[{"id":"1.168081817","rc":[{"batb":[[1,1.51,1224.92]],"ltp":1.65,"tv":18.54,"id":22229228}]}]}
{"op":"mcm","clk":"980587854","pt":1580409239363,"mc":[{"id":"1.168081817","rc":[{"batb":[[0,2.5,30.55],[1,2.48,86.29],[2,2.42,390.84]],"ltp":0.0,"tv":0.0,"id":15256065}]}]}
{"op":"mcm","clk":"980597119","pt":1580409452155,"mc":[{"id":"1.168081817","rc":[{"batb":[[1,2.42,390.84],[2,2.36,86.29]],"ltp":0.0,"tv":0.0,"id":15256065},{"batb":[[1,1.51,1088.23],[2,1.47,136.69]],"ltp":1.65,"tv":18.54,"id":22229228}]}]}
{"op":"mcm","clk":"980598472","pt":1580409482687,"mc":[{"id":"1.168081817","rc":[{"batb":[[0,2.44,30.55]],"ltp":0.0,"tv":0.0,"id":15256065}]}]}
{"op":"mcm","clk":"980605865","pt":1580409652168,"mc":[{"id":"1.168081817","rc":[{"batb":[[0,2.48,86.29],[1,2.44,30.55],[2,2.42,390.84]],"ltp":0.0,"tv":0.0,"id":15256065},{"batb":[[1,1.51,1224.92],[2,1.37,4]],"ltp":1.65,"tv":18.54,"id":22229228}]}]}
{"op":"mcm","clk":"980609471","pt":1580409727046,"mc":[{"id":"1.168081817","rc":[{"batb":[[0,2.5,30.55],[1,2.48,86.29]],"ltp":0.0,"tv":0.0,"id":15256065}]}]}
{"op":"mcm","clk":"980889493","pt":1580414265002,"mc":[{"id":"1.168081817","rc":[{"batb":[[1,2.42,390.84],[2,2.36,86.29]],"ltp":0.0,"tv":0.0,"id":15256065},{"batb":[[1,1.51,1088.23],[2,1.47,136.69]],"ltp":1.65,"tv":18.54,"id":22229228}]}]}
{"op":"mcm","clk":"980893931","pt":1580414352597,"mc":[{"id":"1.168081817","rc":[{"batb":[[0,2.42,390.84],[1,2.36,86.29],[2,1.37,4]],"ltp":0.0,"tv":0.0,"id":15256065}]}]}
{"op":"mcm","clk":"980893939","pt":1580414352706,"mc":[{"id":"1.168081817","rc":[{"batb":[[0,2.44,30.55],[1,2.42,390.84],[2,2.36,86.29]],"ltp":0.0,"tv":0.0,"id":15256065}]}]}
{"op":"mcm","clk":"980900839","pt":1580414466840,"mc":[{"id":"1.168081817","rc":[{"batb":[[0,2.48,86.37],[1,2.44,30.57],[2,2.42,390.84]],"batl":[[0,2.74,11.28],[1,2.78,4.09],[2,2.8,50.77]],"ltp":0.0,"tv":0.0,"id":15256065},{"trd":[[1.65,17.79]],"batb":[[1,1.51,1225.04],[2,1.37,4]],"batl":[[0,1.65,11.74],[1,2.2,3.06]],"ltp":1.65,"tv":18.54,"id":22229228}],"tv":18.54}]}
{"op":"mcm","clk":"980901307","pt":1580414474351,"mc":[{"id":"1.168081817","rc":[{"batb":[[0,2.5,30.57],[1,2.48,86.37]],"ltp":0.0,"tv":0.0,"id":15256065}]}]}
{"op":"mcm","clk":"981130630","pt":1580418056292,"mc":[{"id":"1.168081817","rc":[{"batb":[[1,2.42,390.84],[2,2.32,86.37]],"ltp":0.0,"tv":0.0,"id":15256065},{"batb":[[1,1.51,1088.23],[2,1.48,136.81]],"ltp":1.65,"tv":18.54,"id":22229228}]}]}
{"op":"mcm","clk":"981131222","pt":1580418067244,"mc":[{"id":"1.168081817","rc":[{"batb":[[1,2.44,86.37],[2,2.42,390.84]],"ltp":0.0,"tv":0.0,"id":15256065},{"batb":[[1,1.51,1225.04],[2,1.37,4]],"ltp":1.65,"tv":18.54,"id":22229228}]}]}
{"op":"mcm","clk":"981134139","pt":1580418125682,"mc":[{"id":"1.168081817","rc":[{"batb":[[0,2.44,86.37],[1,2.42,390.84],[2,1.37,4]],"ltp":0.0,"tv":0.0,"id":15256065}]}]}
{"op":"mcm","clk":"981134149","pt":1580418125785,"mc":[{"id":"1.168081817","rc":[{"batb":[[0,2.46,30.57],[1,2.44,86.37],[2,2.42,390.84]],"ltp":0.0,"tv":0.0,"id":15256065}]}]}
{"op":"mcm","clk":"981184473","pt":1580418951293,"mc":[{"id":"1.168081817","rc":[{"batl":[[0,2.7,7.5],[1,2.74,11.28],[2,2.78,4.09]],"ltp":0.0,"tv":0.0,"id":15256065}]}]}
{"op":"mcm","clk":"981254757","pt":1580420104336,"mc":[{"id":"1.168081817","rc":[{"batb":[[0,2.54,26.84],[1,2.46,30.57],[2,2.44,86.37]],"ltp":0.0,"tv":0.0,"id":15256065},{"batb":[[0,1.57,31.9]],"ltp":1.65,"tv":18.54,"id":22229228}]}]}
{"op":"mcm","clk":"981258138","pt":1580420195216,"mc":[{"id":"1.168081817","rc":[{"batb":[[1,2.44,86.37],[2,2.42,390.84]],"ltp":0.0,"tv":0.0,"id":15256065}]}]}
{"op":"mcm","clk":"981317971","pt":1580421465345,"mc":[{"id":"1.168081817","rc":[{"batl":[[0,2.64,7.5]],"ltp":0.0,"tv":0.0,"id":15256065}]}]}
{"op":"mcm","clk":"981318092","pt":1580421468266,"mc":[{"id":"1.168081817","rc":[{"trd":[[2.64,12.09]],"batb":[[0,2.54,20.7]],"batl":[[0,2.64,1.46]],"ltp":2.64,"tv":12.08,"id":15256065},{"batb":[[0,1.58,10.06],[1,1.57,31.9],[2,1.51,1225.04]],"ltp":1.65,"tv":18.54,"id":22229228}],"tv":30.63}]}
{"op":"mcm","clk":"981324113","pt":1580421608041,"mc":[{"id":"1.168081817","rc":[{"trd":[[2.64,12.08]],"batb":[[0,2.54,20.68],[1,2.42,390.84],[2,2.3,86.32]],"batl":[[1,2.74,11.28],[2,2.78,4.09]],"ltp":2.64,"tv":12.08,"id":15256065},{"trd":[[1.65,17.78]],"batb":[[0,1.58,10.05],[1,1.57,31.88],[2,1.51,1088.23]],"batl":[[0,1.65,11.73],[1,2.2,3.06]],"ltp":1.65,"tv":18.54,"id":22229228}],"tv":30.62}]}
{"op":"mcm","clk":"981324298","pt":1580421611642,"mc":[{"id":"1.168081817","rc":[{"batb":[[1,2.42,477.16],[2,1.37,4]],"ltp":2.64,"tv":12.08,"id":15256065},{"batb":[[2,1.51,1224.97]],"ltp":1.65,"tv":18.54,"id":22229228}]}]}
{"op":"mcm","clk":"981358528","pt":1580422313419,"mc":[{"id":"1.168081817","rc":[{"batb":[[1,2.42,390.84]],"ltp":2.64,"tv":12.08,"id":15256065}]}]}
{"op":"mcm","clk":"981358555","pt":1580422313934,"mc":[{"id":"1.168081817","rc":[{"batb":[[2,1.51,1088.23]],"ltp":1.65,"tv":18.54,"id":22229228}]}]}
{"op":"mcm","clk":"981358609","pt":1580422315069,"mc":[{"id":"1.168081817","rc":[{"batb":[[2,2.38,86.32]],"ltp":2.64,"tv":12.08,"id":15256065},{"batb":[[2,1.51,1224.97]],"ltp":1.65,"tv":18.54,"id":22229228}]}]}
{"op":"mcm","clk":"981402119","pt":1580423020658,"mc":[{"id":"1.168081817","rc":[{"trd":[[2.64,13.54]],"batl":[[0,2.74,11.28],[1,2.78,4.09],[2,2.8,50.74]],"ltp":2.64,"tv":13.54,"id":15256065},{"trd":[[1.6,2.41]],"ltp":1.6,"tv":20.95,"id":22229228}],"tv":34.49}]}
{"op":"mcm","clk":"981402279","pt":1580423023337,"mc":[{"id":"1.168081817","rc":[{"batb":[[2,2.34,86.32]],"ltp":2.64,"tv":13.54,"id":15256065},{"batb":[[2,1.51,1088.23]],"ltp":1.6,"tv":20.95,"id":22229228}]}]}
{"op":"mcm","clk":"981402361","pt":1580423024477,"mc":[{"id":"1.168081817","rc":[{"batb":[[1,2.46,86.32],[2,2.42,390.84]],"ltp":2.64,"tv":13.54,"id":15256065},{"batb":[[2,1.51,1224.97]],"ltp":1.6,"tv":20.95,"id":22229228}]}]}
{"op":"mcm","clk":"981459993","pt":1580423863938,"mc":[{"id":"1.168081817","rc":[{"batb":[[1,2.42,390.84],[2,2.34,86.32]],"ltp":2.64,"tv":13.54,"id":15256065},{"batb":[[2,1.51,1088.23]],"ltp":1.6,"tv":20.95,"id":22229228}]}]}
{"op":"mcm","clk":"981473484","pt":1580424066849,"mc":[{"id":"1.168081817","rc":[{"batb":[[1,2.46,86.32],[2,2.42,390.84]],"ltp":2.64,"tv":13.54,"id":15256065},{"batb":[[2,1.51,1224.97]],"ltp":1.6,"tv":20.95,"id":22229228}]}]}
{"op":"mcm","clk":"981480327","pt":1580424182165,"mc":[{"id":"1.168081817","rc":[{"batb":[[0,2.62,24.96],[1,2.54,20.68],[2,2.46,86.32]],"ltp":2.64,"tv":13.54,"id":15256065}]}]}
{"op":"mcm","clk":"981584564","pt":1580425912012,"mc":[{"id":"1.168081817","rc":[{"trd":[[2.62,3.71]],"batb":[[0,2.62,21.25]],"ltp":2.62,"tv":17.25,"id":15256065},{"trd":[[1.62,6]],"batb":[[1,1.57,25.88]],"ltp":1.62,"tv":26.95,"id":22229228}],"tv":44.2}]}
{"op":"mcm","clk":"981763507","pt":1580428951899,"mc":[{"id":"1.168081817","rc":[{"trd":[[2.62,3.71],[2.64,13.54]],"batb":[[0,2.62,21.23],[1,2.54,20.69],[2,2.46,86.36]],"batl":[[0,2.74,11.28],[1,2.78,4.09],[2,2.8,50.76]],"ltp":2.62,"tv":17.24,"id":15256065},{"trd":[[1.65,17.79]],"batb":[[0,1.58,10.05],[1,1.57,25.89],[2,1.51,1225.03]],"batl":[[0,1.65,11.74],[1,2.2,3.06]],"ltp":1.62,"tv":26.95,"id":22229228}],"tv":44.2}]}
{"op":"mcm","clk":"982206113","pt":1580435922900,"mc":[{"id":"1.168081817","rc":[{"batb":[[0,2.62,143.27]],"ltp":2.62,"tv":17.24,"id":15256065}]}]}
{"op":"mcm","clk":"982206189","pt":1580435924698,"mc":[{"id":"1.168081817","rc":[{"batb":[[2,1.51,1088.23]],"ltp":1.62,"tv":26.95,"id":22229228}]}]}
{"op":"mcm","clk":"982206322","pt":1580435927694,"mc":[{"id":"1.168081817","rc":[{"batb":[[1,2.58,86.36],[2,2.54,20.69]],"ltp":2.62,"tv":17.24,"id":15256065}]}]}
{"op":"mcm","clk":"982209779","pt":1580435994390,"mc":[{"id":"1.168081817","rc":[{"batb":[[0,2.64,11.36],[1,2.62,143.27],[2,2.58,86.36]],"ltp":2.62,"tv":17.24,"id":15256065},{"batb":[[0,1.56,26.54],[1,1.51,1088.23],[2,1.47,140.62]],"ltp":1.62,"tv":26.95,"id":22229228}]}]}
{"op":"mcm","clk":"982209834","pt":1580435995293,"mc":[{"id":"1.168081817","rc":[{"batb":[[1,2.62,21.23]],"ltp":2.62,"tv":17.24,"id":15256065}]}]}
{"op":"mcm","clk":"982219421","pt":1580436151918,"mc":[{"id":"1.168081817","rc":[{"trd":[[2.62,3.71],[2.64,13.54]],"batb":[[0,2.64,11.35],[1,2.62,21.24],[2,2.58,86.27]],"batl":[[0,2.74,11.27],[1,2.78,4.08],[2,2.8,50.71]],"ltp":2.62,"tv":17.24,"id":15256065},{"trd":[[1.6,2.41],[1.65,17.78]],"batb":[[0,1.56,26.52],[2,1.47,140.48]],"batl":[[0,1.65,11.73],[1,2.2,3.05]],"ltp":1.62,"tv":26.94,"id":22229228}],"tv":44.19}]}
{"op":"mcm","clk":"982350279","pt":1580438290198,"mc":[{"id":"1.168081817","rc":[{"batb":[[2,2.46,86.27]],"ltp":2.62,"tv":17.24,"id":15256065},{"batb":[[2,1.44,140.48]],"ltp":1.62,"tv":26.94,"id":22229228}]}]}
{"op":"mcm","clk":"982357744","pt":1580438495556,"mc":[{"id":"1.168081817","rc":[{"batb":[[2,2.58,86.27]],"ltp":2.62,"tv":17.24,"id":15256065},{"batb":[[2,1.47,140.48]],"ltp":1.62,"tv":26.94,"id":22229228}]}]}
{"op":"mcm","clk":"982360107","pt":1580438558590,"mc":[{"id":"1.168081817","rc":[{"trd":[[2.74,1.47]],"batl":[[0,2.74,9.8]],"ltp":2.74,"tv":18.71,"id":15256065},{"trd":[[1.57,2.56]],"ltp":1.57,"tv":29.51,"id":22229228}],"tv":48.22}]}
{"op":"mcm","clk":"982385761","pt":1580438977367,"mc":[{"id":"1.168081817","rc":[{"trd":[[2.64,15.06]],"batb":[[0,2.64,9.83]],"ltp":2.64,"tv":20.23,"id":15256065},{"trd":[[1.61,2.5]],"ltp":1.61,"tv":32.0,"id":22229228}],"tv":52.24}]}
{"op":"mcm","clk":"982385785","pt":1580438977878,"mc":[{"id":"1.168081817","rc":[{"batb":[[0,1.56,29.08]],"ltp":1.61,"tv":32.0,"id":22229228}]}]}
{"op":"mcm","clk":"982552169","pt":1580443063659,"mc":[{"id":"1.168081817","rc":[{"batb":[[2,2.46,86.27]],"ltp":2.64,"tv":20.23,"id":15256065},{"batb":[[2,1.44,140.48]],"ltp":1.61,"tv":32.0,"id":22229228}]}]}
{"op":"mcm","clk":"982558073","pt":1580443261639,"mc":[{"id":"1.168081817","rc":[{"trd":[[2.64,15.06]],"batb":[[0,2.64,9.82],[1,2.62,21.24],[2,2.42,390.84]],"batl":[[0,2.74,9.8],[2,2.8,50.7]],"ltp":2.64,"tv":20.23,"id":15256065},{"trd":[[1.65,17.78]],"batb":[[0,1.56,29.07],[2,1.37,4]],"batl":[[0,1.65,11.73],[1,2.2,3.06]],"ltp":1.61,"tv":32.0,"id":22229228}]}]}
{"op":"mcm","clk":"982558076","pt":1580443261741,"mc":[{"id":"1.168081817","rc":[{"batb":[[2,2.58,86.31]],"ltp":2.64,"tv":20.23,"id":15256065},{"batb":[[2,1.47,140.53]],"ltp":1.61,"tv":32.0,"id":22229228}]}]}
{"op":"mcm","clk":"982616035","pt":1580444588951,"mc":[{"id":"1.168081817","rc":[{"batb":[[1,2.62,41.21]],"ltp":2.64,"tv":20.23,"id":15256065},{"batb":[[2,1.5,64.72]],"ltp":1.61,"tv":32.0,"id":22229228}]}]}
{"op":"mcm","clk":"982693616","pt":1580446627094,"mc":[{"id":"1.168081817","rc":[{"batl":[[1,2.8,50.7],[2,990,2.2]],"ltp":2.64,"tv":20.23,"id":15256065}]}]}
{"op":"mcm","clk":"982742226","pt":1580447887280,"mc":[{"id":"1.168081817","rc":[{"batb":[[2,2.46,86.31]],"ltp":2.64,"tv":20.23,"id":15256065}]}]}
{"op":"mcm","clk":"982750075","pt":1580448087827,"mc":[{"id":"1.168081817","rc":[{"batb":[[2,2.58,86.31]],"ltp":2.64,"tv":20.23,"id":15256065}]}]}
{"op":"mcm","clk":"982840736","pt":1580450551921,"mc":[{"id":"1.168081817","rc":[{"trd":[[2.64,15.06]],"batb":[[0,2.64,9.82],[1,2.62,41.21],[2,2.58,86.29]],"batl":[[0,2.74,9.79],[1,2.8,50.68]],"ltp":2.64,"tv":20.23,"id":15256065},{"trd":[[1.57,2.57],[1.61,2.5],[1.65,17.78]],"batb":[[0,1.56,29.06]],"batl":[[0,1.65,11.73]],"ltp":1.61,"tv":32.01,"id":22229228}]}]}
{"op":"mcm","clk":"982860900","pt":1580451016922,"mc":[{"id":"1.168081817","rc":[{"batl":[[1,2.1,3.05]],"ltp":1.61,"tv":32.01,"id":22229228}]}]}
{"op":"mcm","clk":"982936074","pt":1580452704645,"mc":[{"id":"1.168081817","rc":[{"batb":[[2,2.42,390.84]],"ltp":2.64,"tv":20.23,"id":15256065}]}]}
{"op":"mcm","clk":"982936078","pt":1580452704747,"mc":[{"id":"1.168081817","rc":[{"batb":[[2,2.46,86.29]],"ltp":2.64,"tv":20.23,"id":15256065}]}]}
{"op":"mcm","clk":"982942055","pt":1580452868020,"mc":[{"id":"1.168081817","rc":[{"batb":[[2,2.42,390.84]],"ltp":2.64,"tv":20.23,"id":15256065}]}]}
{"op":"mcm","clk":"982944800","pt":1580452968207,"mc":[{"id":"1.168081817","rc":[{"batb":[[2,2.58,79.42]],"ltp":2.64,"tv":20.23,"id":15256065}]}]}
{"op":"mcm","clk":"983039911","pt":1580454994714,"mc":[{"id":"1.168081817","rc":[{"trd":[[2.74,2.98]],"batl":[[0,2.74,8.28]],"ltp":2.74,"tv":21.74,"id":15256065},{"trd":[[1.57,5.21]],"batb":[[1,1.55,2.67],[2,1.51,1088.23]],"ltp":1.57,"tv":34.65,"id":22229228}],"tv":56.4}]}
{"op":"mcm","clk":"983196589","pt":1580457751914,"mc":[{"id":"1.168081817","rc":[{"trd":[[2.62,3.69],[2.64,15.04],[2.74,2.98]],"batb":[[0,2.64,9.8],[1,2.62,41.12],[2,2.58,79.22]],"batl":[[0,2.74,8.26],[1,2.8,50.58]],"ltp":2.74,"tv":21.71,"id":15256065},{"trd":[[1.57,5.19],[1.6,2.4],[1.61,2.49],[1.65,17.76]],"batb":[[0,1.56,29.01],[1,1.55,2.66]],"batl":[[0,1.65,11.7],[1,2.1,3.05]],"ltp":1.57,"tv":34.59,"id":22229228}],"tv":56.3}]}
{"op":"mcm","clk":"983452746","pt":1580460873500,"mc":[{"id":"1.168081817","rc":[{"trd":[[2.74,4.12]],"batl":[[0,2.74,7.12]],"ltp":2.74,"tv":22.85,"id":15256065},{"trd":[[1.57,7.19]],"ltp":1.57,"tv":36.59,"id":22229228}],"tv":59.45}]}
{"op":"mcm","clk":"983507358","pt":1580461496232,"mc":[{"id":"1.168081817","rc":[{"batl":[[0,1.65,92.44]],"ltp":1.57,"tv":36.59,"id":22229228}]}]}
{"op":"mcm","clk":"983643111","pt":1580463099229,"mc":[{"id":"1.168081817","rc":[{"batl":[[0,2.72,50.58],[1,2.74,7.12]],"ltp":2.74,"tv":22.85,"id":15256065}]}]}
{"op":"mcm","clk":"983661473","pt":1580463219017,"mc":[{"id":"1.168081817","rc":[{"batb":[[0,1.55,2.66],[1,1.54,48.97]],"ltp":1.57,"tv":36.59,"id":22229228}]}]}
{"op":"mcm","clk":"983817390","pt":1580464951885,"mc":[{"id":"1.168081817","rc":[{"trd":[[2.62,3.68],[2.64,15.05],[2.74,4.13]],"batb":[[0,2.64,9.81],[1,2.62,41.07],[2,2.58,79.28]],"batl":[[0,2.72,50.62],[1,2.74,7.12]],"ltp":2.74,"tv":22.85,"id":15256065},{"trd":[[1.57,7.17],[1.6,2.4],[1.61,2.48],[1.65,17.76]],"batb":[[0,1.55,2.65],[1,1.54,49]],"batl":[[0,1.65,92.51],[1,2.1,3.05]],"ltp":1.57,"tv":36.58,"id":22229228}],"tv":59.44}]}
{"op":"mcm","clk":"984638838","pt":1580471881332,"mc":[{"id":"1.168081817","rc":[{"batb":[[2,2.46,79.28]],"ltp":2.74,"tv":22.85,"id":15256065}]}]}
{"op":"mcm","clk":"984662813","pt":1580472079469,"mc":[{"id":"1.168081817","rc":[{"trd":[[2.62,3.68],[2.64,15.05],[2.74,4.13]],"batb":[[0,2.64,9.81],[1,2.62,41.07],[2,2.58,79.23]],"batl":[[0,2.72,50.64],[1,2.74,7.13]],"ltp":2.74,"tv":22.86,"id":15256065},{"trd":[[1.65,17.76]],"batb":[[1,1.54,49.02]],"batl":[[0,1.65,92.46],[1,2.1,3.05]],"ltp":1.57,"tv":36.58,"id":22229228}]}]}
{"op":"mcm","clk":"985103953","pt":1580474923166,"mc":[{"id":"1.168081817","rc":[{"batb":[[1,2.62,21.1]],"ltp":2.74,"tv":22.86,"id":15256065}]}]}
{"op":"mcm","clk":"985158088","pt":1580475307454,"mc":[{"id":"1.168081817","rc":[{"batb":[[0,2.64,130.88]],"ltp":2.74,"tv":22.86,"id":15256065}]}]}
{"op":"mcm","clk":"985165739","pt":1580475363412,"mc":[{"id":"1.168081817","rc":[{"batb":[[0,2.64,9.81]],"ltp":2.74,"tv":22.86,"id":15256065}]}]}
{"op":"mcm","clk":"985166318","pt":1580475367806,"mc":[{"id":"1.168081817","rc":[{"batb":[[2,2.42,390.84]],"ltp":2.74,"tv":22.86,"id":15256065}]}]}
{"op":"mcm","clk":"985196151","pt":1580475589498,"mc":[{"id":"1.168081817","rc":[{"batb":[[2,2.54,21.01]],"ltp":2.74,"tv":22.86,"id":15256065},{"batb":[[2,1.53,61.06]],"ltp":1.57,"tv":36.58,"id":22229228}]}]}
{"op":"mcm","clk":"985305335","pt":1580476312558,"mc":[{"id":"1.168081817","rc":[{"batb":[[1,2.62,41.07],[2,2.48,83.04]],"ltp":2.74,"tv":22.86,"id":15256065},{"batb":[[2,1.51,1228.41]],"ltp":1.57,"tv":36.58,"id":22229228}]}]}
{"op":"mcm","clk":"985328673","pt":1580476498188,"mc":[{"id":"1.168081817","rc":[{"batb":[[1,2.62,21.1],[2,2.54,21.01]],"ltp":2.74,"tv":22.86,"id":15256065},{"batb":[[2,1.53,61.06]],"ltp":1.57,"tv":36.58,"id":22229228}]}]}
{"op":"mcm","clk":"985712801","pt":1580479351896,"mc":[{"id":"1.168081817","rc":[{"trd":[[2.62,3.68],[2.64,15.05]],"batb":[[0,2.64,9.81],[1,2.62,21.07]],"batl":[[0,2.72,50.64],[1,2.74,7.13]],"ltp":2.74,"tv":22.85,"id":15256065},{"trd":[[1.57,7.18],[1.65,17.75]],"batb":[[1,1.54,49.02]],"batl":[[0,1.65,92.33],[1,2.1,3.04]],"ltp":1.57,"tv":36.57,"id":22229228}],"tv":59.42}]}
{"op":"mcm","clk":"986165582","pt":1580483592660,"mc":[{"id":"1.168081817","rc":[{"trd":[[2.72,50.64]],"batl":[[0,2.74,7.13],[1,990,2.2],[2,1000,0.02]],"ltp":2.72,"tv":73.5,"id":15256065},{"trd":[[1.58,87.18]],"ltp":1.58,"tv":123.75,"id":22229228}],"tv":197.25}]}
{"op":"mcm","clk":"986166864","pt":1580483604372,"mc":[{"id":"1.168081817","rc":[{"trd":[[2.74,11.25]],"batl":[[0,990,2.2],[1,1000,0.02],[2,1000,0]],"ltp":2.74,"tv":80.62,"id":15256065},{"trd":[[1.57,19.62]],"ltp":1.57,"tv":136.19,"id":22229228}],"tv":216.82}]}
{"op":"mcm","clk":"986457407","pt":1580486424452,"mc":[{"id":"1.168081817","rc":[{"trd":[[2.62,3.67],[2.64,15.05],[2.72,50.64],[2.74,11.25]],"batb":[[0,2.64,9.81],[1,2.62,21.03]],"ltp":2.74,"tv":80.61,"id":15256065},{"trd":[[1.57,19.59],[1.58,87.17],[1.61,2.47],[1.64,0.76],[1.65,17.72]],"batb":[[0,1.55,2.64],[1,1.54,49.02]],"batl":[[0,1.65,92.08],[1,2.1,3.03]],"ltp":1.57,"tv":136.12,"id":22229228}],"tv":216.73}]}
{"op":"mcm","clk":"986605151","pt":1580487729052,"mc":[{"id":"1.168081817","rc":[{"batl":[[0,2.74,83.24],[1,990,2.2],[2,1000,0.02]],"ltp":2.74,"tv":80.61,"id":15256065}]}]}
{"op":"mcm","clk":"986606072","pt":1580487743057,"mc":[{"id":"1.168081817","rc":[{"batl":[[1,2.78,97.45],[2,990,2.2]],"ltp":2.74,"tv":80.61,"id":15256065}]}]}
{"op":"mcm","clk":"986607193","pt":1580487760350,"mc":[{"id":"1.168081817","rc":[{"batl":[[2,2.8,75.8]],"ltp":2.74,"tv":80.61,"id":15256065}]}]}
{"op":"mcm","clk":"986608097","pt":1580487774021,"mc":[{"id":"1.168081817","rc":[{"batl":[[0,2.72,36.55],[1,2.74,83.24],[2,2.78,97.45]],"ltp":2.74,"tv":80.61,"id":15256065}]}]}
{"op":"mcm","clk":"986615062","pt":1580487874660,"mc":[{"id":"1.168081817","rc":[{"batb":[[1,1.53,61.06],[2,1.51,1227.84]],"ltp":1.57,"tv":136.12,"id":22229228}]}]}
{"op":"mcm","clk":"986615074","pt":1580487874766,"mc":[{"id":"1.168081817","rc":[{"batb":[[0,1.57,19.44],[1,1.55,2.64],[2,1.53,61.06]],"ltp":1.57,"tv":136.12,"id":22229228}]}]}
{"op":"mcm","clk":"986681348","pt":1580488846631,"mc":[{"id":"1.168081817","rc":[{"batl":[[0,2.7,56.26],[1,2.72,36.55],[2,2.74,83.24]],"ltp":2.74,"tv":80.61,"id":15256065}]}]}
{"op":"mcm","clk":"986686081","pt":1580488937285,"mc":[{"id":"1.168081817","rc":[{"batl":[[0,2.68,56.26],[1,2.7,56.26],[2,2.72,36.55]],"ltp":2.74,"tv":80.61,"id":15256065}]}]}
{"op":"mcm","clk":"986713101","pt":1580489261597,"mc":[{"id":"1.168081817","rc":[{"trd":[[2.68,1.19]],"batl":[[0,2.68,55.08]],"ltp":2.68,"tv":81.79,"id":15256065},{"trd":[[1.59,2]],"ltp":1.59,"tv":138.12,"id":22229228}],"tv":219.91}]}
{"op":"mcm","clk":"986726310","pt":1580489500039,"mc":[{"id":"1.168081817","rc":[{"trd":[[2.68,12.44]],"batl":[[0,2.68,43.82]],"ltp":2.68,"tv":93.05,"id":15256065},{"trd":[[1.59,20.97]],"ltp":1.59,"tv":157.08,"id":22229228}],"tv":250.14}]}
{"op":"mcm","clk":"986755259","pt":1580489962612,"mc":[{"id":"1.168081817","rc":[{"trd":[[2.64,24.86]],"batb":[[0,2.62,21.03],[1,2.56,16.36]],"ltp":2.64,"tv":102.86,"id":15256065},{"trd":[[1.61,18.56]],"batb":[[0,1.61,3.53],[1,1.59,17.26],[2,1.55,2.64]],"ltp":1.61,"tv":173.17,"id":22229228}],"tv":276.04}]}
{"op":"mcm","clk":"986755389","pt":1580489964711,"mc":[{"id":"1.168081817","rc":[{"batb":[[0,1.59,17.26],[1,1.55,2.64],[2,1.53,61.06]],"ltp":1.61,"tv":173.17,"id":22229228}]}]}
{"op":"mcm","clk":"986756091","pt":1580489976524,"mc":[{"id":"1.168081817","rc":[{"trd":[[2.62,15.8]],"batb":[[0,2.62,8.9]],"ltp":2.62,"tv":114.99,"id":15256065},{"trd":[[1.62,25.62]],"ltp":1.62,"tv":192.79,"id":22229228}],"tv":307.79}]}
{"op":"mcm","clk":"987055242","pt":1580493751895,"mc":[{"id":"1.168081817","rc":[{"trd":[[2.62,15.8],[2.64,24.84],[2.68,12.42],[2.72,50.57],[2.74,11.24]],"batb":[[0,2.62,8.9],[1,2.56,16.34]],"batl":[[0,2.68,43.77],[1,2.7,56.19],[2,2.72,36.5]],"ltp":2.62,"tv":114.88,"id":15256065},{"trd":[[1.57,19.57],[1.58,87.06],[1.59,20.95],[1.6,2.4],[1.61,18.56],[1.65,17.71]],"batb":[[0,1.59,17.24],[1,1.55,2.64]],"batl":[[0,1.65,91.97],[1,2.1,3.03]],"ltp":1.62,"tv":192.62,"id":22229228}],"tv":307.5}]}
{"op":"mcm","clk":"987877152","pt":1580500477586,"mc":[{"id":"1.168081817","rc":[{"batb":[[0,1.6,2],[1,1.59,17.24],[2,1.55,2.64]],"ltp":1.62,"tv":192.62,"id":22229228}]}]}
{"op":"mcm","clk":"987877399","pt":1580500480168,"mc":[{"id":"1.168081817","rc":[{"batb":[[0,1.6,3]],"ltp":1.62,"tv":192.62,"id":22229228}]}]}
{"op":"mcm","clk":"987877729","pt":1580500483986,"mc":[{"id":"1.168081817","rc":[{"batb":[[0,1.6,1]],"ltp":1.62,"tv":192.62,"id":22229228}]}]}
{"op":"mcm","clk":"987924238","pt":1580500951900,"mc":[{"id":"1.168081817","rc":[{"trd":[[2.62,15.83],[2.64,24.84],[2.68,12.43],[2.72,50.58],[2.74,11.24]],"batb":[[0,2.62,8.91],[1,2.56,16.34]],"batl":[[0,2.68,43.77],[1,2.7,56.2],[2,2.72,36.47]],"ltp":2.62,"tv":114.91,"id":15256065},{"trd":[[1.57,19.57],[1.58,87.07],[1.59,20.93],[1.61,18.56],[1.65,17.71]],"batb":[[1,1.59,17.24],[2,1.55,2.64]],"batl":[[0,1.65,91.91],[1,2.1,3.03]],"ltp":1.62,"tv":192.61,"id":22229228}],"tv":307.53}]}
{"op":"mcm","clk":"988178192","pt":1580502531443,"mc":[{"id":"1.168081817","rc":[{"batb":[[0,2.64,28],[1,2.62,8.91],[2,2.56,16.34]],"ltp":2.62,"tv":114.91,"id":15256065}]}]}
{"op":"mcm","clk":"988200614","pt":1580502716013,"mc":[{"id":"1.168081817","rc":[{"batb":[[2,2.54,20.67]],"ltp":2.62,"tv":114.91,"id":15256065}]}]}
{"op":"mcm","clk":"988279227","pt":1580503224279,"mc":[{"id":"1.168081817","rc":[{"trd":[[1.59,22.93],[1.6,4.4]],"batb":[[0,1.59,16.24],[1,1.55,2.64],[2,1.51,1227.58]],"ltp":1.59,"tv":196.61,"id":22229228}],"tv":311.53}]}
{"op":"mcm","clk":"988463625","pt":1580505077387,"mc":[{"id":"1.168081817","rc":[{"batl":[[2,2.74,83.07]],"ltp":2.62,"tv":114.91,"id":15256065}]}]}
{"op":"mcm","clk":"988463769","pt":1580505079180,"mc":[{"id":"1.168081817","rc":[{"batl":[[2,2.78,97.25]],"ltp":2.62,"tv":114.91,"id":15256065}]}]}
{"op":"mcm","clk":"988463956","pt":1580505081189,"mc":[{"id":"1.168081817","rc":[{"batl":[[2,990,2.2]],"ltp":2.62,"tv":114.91,"id":15256065}]}]}
{"op":"mcm","clk":"988493504","pt":1580505436450,"mc":[{"id":"1.168081817","rc":[{"batb":[[2,1.51,1088.23]],"ltp":1.59,"tv":196.61,"id":22229228}]}]}
{"op":"mcm","clk":"988687952","pt":1580508151902,"mc":[{"id":"1.168081817","rc":[{"trd":[[2.62,15.8],[2.64,24.85],[2.68,12.43],[2.72,50.6],[2.74,11.24]],"batb":[[1,2.62,8.89],[2,2.54,20.68]],"batl":[[0,2.68,43.79],[1,2.7,56.22]],"ltp":2.62,"tv":114.92,"id":15256065},{"trd":[[1.57,19.57],[1.58,87.09],[1.59,22.93],[1.61,18.56],[1.65,17.7]],"batb":[[0,1.59,16.25],[1,1.55,2.63]],"batl":[[0,1.65,91.9]],"ltp":1.59,"tv":196.63,"id":22229228}],"tv":311.55}]}
{"op":"mcm","clk":"988704941","pt":1580508326315,"mc":[{"id":"1.168081817","rc":[{"trd":[[2.64,27.01]],"batb":[[0,2.64,25.84]],"ltp":2.64,"tv":117.08,"id":15256065},{"trd":[[1.61,22.1]],"ltp":1.61,"tv":200.17,"id":22229228}],"tv":317.25}]}
{"op":"mcm","clk":"988785634","pt":1580509695565,"mc":[{"id":"1.168081817","rc":[{"trd":[[2.68,32.43]],"batl":[[0,2.68,33.79]],"ltp":2.68,"tv":137.08,"id":15256065}],"tv":337.25}]}
{"op":"mcm","clk":"989282494","pt":1580516947816,"mc":[{"id":"1.168081817","rc":[{"trd":[[2.64,78.69]],"batb":[[0,2.62,8.89],[1,2.54,20.68],[2,2.5,82.54]],"batl":[[0,2.64,2.27],[1,2.68,33.79],[2,2.7,56.22]],"ltp":2.64,"tv":188.76,"id":15256065}],"tv":388.93}]}
{"op":"mcm","clk":"989282800","pt":1580516951944,"mc":[{"id":"1.168081817","rc":[{"batb":[[1,2.54,41.68]],"ltp":2.64,"tv":188.76,"id":15256065},{"batb":[[2,1.53,61.04]],"ltp":1.61,"tv":200.17,"id":22229228}]}]}
{"op":"mcm","clk":"989284607","pt":1580516978868,"mc":[{"id":"1.168081817","rc":[{"batl":[[2,7,8.66]],"ltp":1.61,"tv":200.17,"id":22229228}]}]}
{"op":"mcm","clk":"989318678","pt":1580517321788,"mc":[{"id":"1.168081817","rc":[{"trd":[[2.62,24.69]],"batb":[[0,2.54,41.68],[1,2.5,82.54],[2,2.42,390.84]],"ltp":2.62,"tv":197.65,"id":15256065},{"trd":[[1.62,40]],"batb":[[0,1.62,33.43],[1,1.59,16.25],[2,1.55,2.63]],"ltp":1.62,"tv":214.55,"id":22229228}],"tv":412.21}]}
{"op":"mcm","clk":"989320566","pt":1580517351651,"mc":[{"id":"1.168081817","rc":[{"batb":[[0,2.54,36.21]],"ltp":2.62,"tv":197.65,"id":15256065},{"trd":[[1.62,59.4]],"batb":[[0,1.62,23.73]],"ltp":1.62,"tv":233.95,"id":22229228}],"tv":431.6}]}
{"op":"mcm","clk":"989320573","pt":1580517351753,"mc":[{"id":"1.168081817","rc":[{"batb":[[1,1.6,9.81],[2,1.59,16.25]],"ltp":1.62,"tv":233.95,"id":22229228}]}]}
{"op":"mcm","clk":"989583076","pt":1580520922486,"mc":[{"id":"1.168081817","rc":[{"batb":[[0,2.54,157.57]],"ltp":2.62,"tv":197.65,"id":15256065}]}]}
{"op":"mcm","clk":"989853723","pt":1580524522504,"mc":[{"id":"1.168081817","rc":[{"batb":[[0,2.54,36.21]],"ltp":2.62,"tv":197.65,"id":15256065}]}]}
{"op":"mcm","clk":"990056241","pt":1580528123565,"mc":[{"id":"1.168081817","rc":[{"batb":[[0,2.54,157.57]],"ltp":2.62,"tv":197.65,"id":15256065}]}]}
{"op":"mcm","clk":"990115964","pt":1580529621896,"mc":[{"id":"1.168081817","rc":[{"batb":[[0,2.54,246.2]],"ltp":2.62,"tv":197.65,"id":15256065}]}]}
{"op":"mcm","clk":"990134989","pt":1580529890246,"mc":[{"id":"1.168081817","rc":[{"trd":[[2.54,5.07]],"batb":[[0,2.54,243.66]],"ltp":2.54,"tv":202.72,"id":15256065}],"tv":436.67}]}
{"op":"mcm","clk":"990135007","pt":1580529890761,"mc":[{"id":"1.168081817","rc":[{"batb":[[1,1.6,13.83]],"ltp":1.62,"tv":233.95,"id":22229228}]}]}
{"op":"mcm","clk":"990218443","pt":1580531355316,"mc":[{"id":"1.168081817","rc":[{"batb":[[0,2.56,3.94],[1,2.54,243.66],[2,2.5,82.54]],"ltp":2.54,"tv":202.72,"id":15256065},{"batb":[[1,1.6,7.56]],"ltp":1.62,"tv":233.95,"id":22229228}]}]}
{"op":"mcm","clk":"990246023","pt":1580531724538,"mc":[{"id":"1.168081817","rc":[{"batb":[[1,2.54,33.67]],"ltp":2.54,"tv":202.72,"id":15256065}]}]}
{"op":"mcm","clk":"990246038","pt":1580531724853,"mc":[{"id":"1.168081817","rc":[{"batb":[[0,2.56,215.52]],"ltp":2.54,"tv":202.72,"id":15256065}]}]}
{"op":"mcm","clk":"990246142","pt":1580531727221,"mc":[{"id":"1.168081817","rc":[{"batb":[[1,2.54,12.67]],"ltp":2.54,"tv":202.72,"id":15256065}]}]}
{"op":"mcm","clk":"990252786","pt":1580531899934,"mc":[{"id":"1.168081817","rc":[{"batb":[[0,2.58,8.09],[1,2.56,215.52]],"ltp":2.54,"tv":202.72,"id":15256065}]}]}
{"op":"mcm","clk":"990329632","pt":1580533222264,"mc":[{"id":"1.168081817","rc":[{"batb":[[1,2.56,3.94]],"ltp":2.54,"tv":202.72,"id":15256065}]}]}
{"op":"mcm","clk":"990334658","pt":1580533321470,"mc":[{"id":"1.168081817","rc":[{"batb":[[2,2.54,30.29]],"ltp":2.54,"tv":202.72,"id":15256065}]}]}
{"op":"mcm","clk":"990335425","pt":1580533336981,"mc":[{"id":"1.168081817","rc":[{"batb":[[0,2.56,12.3],[1,2.54,30.29],[2,2.5,82.54]],"ltp":2.54,"tv":202.72,"id":15256065}]}]}
{"op":"mcm","clk":"990468765","pt":1580535313544,"mc":[{"id":"1.168081817","rc":[{"batb":[[0,1.63,5.37],[1,1.62,23.73],[2,1.6,7.56]],"ltp":1.62,"tv":233.95,"id":22229228}]}]}
{"op":"mcm","clk":"990468782","pt":1580535313759,"mc":[{"id":"1.168081817","rc":[{"trd":[[1.63,10.61]],"batb":[[0,1.62,23.8],[1,1.6,7.56],[2,1.59,16.25]],"ltp":1.63,"tv":244.56,"id":22229228}],"tv":447.29}]}
{"op":"mcm","clk":"990494997","pt":1580535758678,"mc":[{"id":"1.168081817","rc":[{"batb":[[0,2.56,223.88]],"ltp":2.54,"tv":202.72,"id":15256065}]}]}
{"op":"mcm","clk":"990501758","pt":1580535878033,"mc":[{"id":"1.168081817","rc":[{"batb":[[1,2.5,82.54],[2,2.42,390.84]],"ltp":2.54,"tv":202.72,"id":15256065}]}]}
{"op":"mcm","clk":"990533788","pt":1580536287903,"mc":[{"id":"1.168081817","rc":[{"batb":[[0,2.56,12.3]],"ltp":2.54,"tv":202.72,"id":15256065},{"trd":[[1.62,106.76],[1.63,10.75]],"batb":[[0,1.6,7.61],[1,1.59,16.25],[2,1.55,2.63]],"ltp":1.62,"tv":292.06,"id":22229228}],"tv":494.78}]}
{"op":"mcm","clk":"990533848","pt":1580536288886,"mc":[{"id":"1.168081817","rc":[{"trd":[[2.62,24.72],[2.64,82.77]],"batl":[[0,2.68,34.02],[1,2.7,56.22],[2,990,2.2]],"ltp":2.64,"tv":206.83,"id":15256065},{"trd":[[1.62,106.81]],"batb":[[0,1.6,7.56]],"ltp":1.62,"tv":292.11,"id":22229228}],"tv":498.94}]}
{"op":"mcm","clk":"990533968","pt":1580536291410,"mc":[{"id":"1.168081817","rc":[{"batb":[[1,2.54,21],[2,2.5,82.54]],"ltp":2.64,"tv":206.83,"id":15256065}]}]}
{"op":"mcm","clk":"990533990","pt":1580536291873,"mc":[{"id":"1.168081817","rc":[{"batb":[[1,2.54,103.54],[2,2.42,390.84]],"ltp":2.64,"tv":206.83,"id":15256065}]}]}
{"op":"mcm","clk":"990536906","pt":1580536364640,"mc":[{"id":"1.168081817","rc":[{"batb":[[0,2.56,42.59]],"ltp":2.64,"tv":206.83,"id":15256065}]}]}
{"op":"mcm","clk":"990536923","pt":1580536364954,"mc":[{"id":"1.168081817","rc":[{"batb":[[0,2.58,213.06],[1,2.56,42.59],[2,2.54,103.54]],"ltp":2.64,"tv":206.83,"id":15256065}]}]}
{"op":"mcm","clk":"990537853","pt":1580536391676,"mc":[{"id":"1.168081817","rc":[{"batb":[[2,2.54,82.54]],"ltp":2.64,"tv":206.83,"id":15256065}]}]}
{"op":"mcm","clk":"990537891","pt":1580536392395,"mc":[{"id":"1.168081817","rc":[{"trd":[[2.62,37.18]],"batb":[[0,2.62,13.74],[1,2.58,213.06],[2,2.56,42.59]],"ltp":2.62,"tv":219.29,"id":15256065}],"tv":511.4}]}
{"op":"mcm","clk":"990538023","pt":1580536396670,"mc":[{"id":"1.168081817","rc":[{"batb":[[0,2.62,19.97]],"ltp":2.62,"tv":219.29,"id":15256065}]}]}
{"op":"mcm","clk":"990539250","pt":1580536423044,"mc":[{"id":"1.168081817","rc":[{"batb":[[1,2.6,11.81],[2,2.58,213.06]],"ltp":2.62,"tv":219.29,"id":15256065},{"batb":[[0,1.55,51.6],[1,1.51,1088.23],[2,1.5,64.7]],"ltp":1.62,"tv":292.11,"id":22229228}]}]}
{"op":"mcm","clk":"990560204","pt":1580536848097,"mc":[{"id":"1.168081817","rc":[{"batb":[[2,2.54,82.54]],"ltp":2.62,"tv":219.29,"id":15256065}]}]}
{"op":"mcm","clk":"990575926","pt":1580536972265,"mc":[{"id":"1.168081817","rc":[{"batb":[[1,2.56,20.18]],"ltp":2.62,"tv":219.29,"id":15256065}]}]}
{"op":"mcm","clk":"990967662","pt":1580544008949,"mc":[{"id":"1.168081817","rc":[{"batb":[[2,2.42,390.84]],"ltp":2.62,"tv":219.29,"id":15256065}]}]}
{"op":"mcm","clk":"990968096","pt":1580544020387,"mc":[{"id":"1.168081817","rc":[{"batb":[[2,2.54,37.86]],"ltp":2.62,"tv":219.29,"id":15256065}]}]}
{"op":"mcm","clk":"990971942","pt":1580544092654,"mc":[{"id":"1.168081817","rc":[{"batb":[[2,2.54,80.27]],"ltp":2.62,"tv":219.29,"id":15256065}]}]}
{"op":"mcm","clk":"991015182","pt":1580544966608,"mc":[{"id":"1.168081817","rc":[{"trd":[[2.64,83],[2.68,66.22]],"batl":[[0,2.7,56.22],[1,990,2.2],[2,1000,0.02]],"ltp":2.68,"tv":253.31,"id":15256065},{"trd":[[1.59,136.04],[1.6,4.78]],"batl":[[0,1.59,25.59],[1,1.65,91.9],[2,2.1,3.03]],"ltp":1.59,"tv":405.6,"id":22229228}],"tv":658.91}]}
{"op":"mcm","clk":"991030636","pt":1580545066394,"mc":[{"id":"1.168081817","rc":[{"trd":[[1.59,158.06]],"batl":[[0,1.59,14.58]],"ltp":1.59,"tv":427.61,"id":22229228}],"tv":680.93}]}
{"op":"mcm","clk":"991030664","pt":1580545067016,"mc":[{"id":"1.168081817","rc":[{"batb":[[0,2.64,10.42],[1,2.62,19.97]],"ltp":2.68,"tv":253.31,"id":15256065},{"batb":[[0,1.55,2.63],[1,1.53,58.36],[2,1.51,1088.23]],"ltp":1.59,"tv":427.61,"id":22229228}]}]}
{"op":"mcm","clk":"991119836","pt":1580546554071,"mc":[{"id":"1.168081817","rc":[{"batl":[[1,1.6,200],[2,1.65,91.9]],"ltp":1.59,"tv":427.61,"id":22229228}]}]}
{"op":"mcm","clk":"991157439","pt":1580546997093,"mc":[{"id":"1.168081817","rc":[{"trd":[[2.68,74.86]],"batl":[[0,2.68,1.49],[1,2.7,56.22],[2,990,2.2]],"ltp":2.68,"tv":261.95,"id":15256065},{"trd":[[1.59,172.64]],"batl":[[0,1.6,200],[1,1.65,91.9],[2,2.1,3.03]],"ltp":1.59,"tv":442.19,"id":22229228}],"tv":704.15}]}
{"op":"mcm","clk":"991158642","pt":1580547013620,"mc":[{"id":"1.168081817","rc":[{"batl":[[0,2.68,26.81]],"ltp":2.68,"tv":261.95,"id":15256065}]}]}
{"op":"mcm","clk":"991168696","pt":1580547152311,"mc":[{"id":"1.168081817","rc":[{"batl":[[0,2.68,52.14]],"ltp":2.68,"tv":261.95,"id":15256065}]}]}
{"op":"mcm","clk":"991248652","pt":1580548152016,"mc":[{"id":"1.168081817","rc":[{"trd":[[2.68,127]],"batl":[[0,2.7,56.22],[1,990,2.2],[2,1000,0.02]],"ltp":2.68,"tv":314.09,"id":15256065},{"trd":[[1.59,260.61]],"batl":[[0,1.59,23.03],[1,1.6,200],[2,1.65,91.9]],"ltp":1.59,"tv":530.16,"id":22229228}],"tv":844.26}]}
{"op":"mcm","clk":"991456215","pt":1580550629567,"mc":[{"id":"1.168081817","rc":[{"batl":[[1,95,15.9],[2,990,2.2]],"ltp":2.68,"tv":314.09,"id":15256065}]}]}
{"op":"mcm","clk":"991465474","pt":1580550768745,"mc":[{"id":"1.168081817","rc":[{"trd":[[2.7,56.22]],"batl":[[0,95,15.9],[1,990,2.2],[2,1000,0.02]],"ltp":2.7,"tv":370.31,"id":15256065},{"trd":[[1.58,183.06]],"batl":[[0,1.58,410.54],[1,1.59,23.03],[2,1.6,200]],"ltp":1.58,"tv":626.13,"id":22229228}],"tv":996.45}]}
{"op":"mcm","clk":"991471045","pt":1580550851257,"mc":[{"id":"1.168081817","rc":[{"batb":[[0,1.55,5.63]],"ltp":1.58,"tv":626.13,"id":22229228}]}]}
{"op":"mcm","clk":"991472413","pt":1580550875429,"mc":[{"id":"1.168081817","rc":[{"batl":[[0,2.96,8.4],[1,95,15.9],[2,990,2.2]],"ltp":2.7,"tv":370.31,"id":15256065},{"batb":[[2,1.52,15.03]],"batl":[[0,1.57,8.4],[1,1.58,410.54],[2,1.59,23.03]],"ltp":1.58,"tv":626.13,"id":22229228}]}]}
{"op":"mcm","clk":"991474202","pt":1580550906682,"mc":[{"id":"1.168081817","rc":[{"batb":[[0,2.68,7.65]],"ltp":2.7,"tv":370.31,"id":15256065},{"trd":[[1.57,36.37]],"batb":[[1,1.53,49.89]],"batl":[[0,1.58,410.54],[1,1.59,23.03],[2,1.6,200]],"ltp":1.57,"tv":642.93,"id":22229228}],"tv":1013.25}]}
{"op":"mcm","clk":"991514754","pt":1580551355713,"mc":[{"id":"1.168081817","rc":[{"batb":[[2,1.52,29.49]],"ltp":1.57,"tv":642.93,"id":22229228}]}]}
{"op":"mcm","clk":"991566979","pt":1580551807679,"mc":[{"id":"1.168081817","rc":[{"trd":[[1.58,382.96]],"batl":[[0,1.58,310.64]],"ltp":1.58,"tv":842.83,"id":22229228}],"tv":1213.15}]}
{"op":"mcm","clk":"991780985","pt":1580553298925,"mc":[{"id":"1.168081817","rc":[{"trd":[[1.58,422.68]],"batl":[[0,1.58,290.79]],"ltp":1.58,"tv":882.55,"id":22229228}],"tv":1252.87}]}
{"op":"mcm","clk":"991844585","pt":1580553791164,"mc":[{"id":"1.168081817","rc":[{"batb":[[0,1.56,171],[1,1.55,5.63],[2,1.53,49.89]],"ltp":1.58,"tv":882.55,"id":22229228}]}]}
{"op":"mcm","clk":"991844847","pt":1580553793070,"mc":[{"id":"1.168081817","rc":[{"batl":[[0,95,15.9],[1,990,2.2],[2,1000,0.02]],"ltp":2.7,"tv":370.31,"id":15256065},{"batb":[[0,1.57,8.4],[1,1.56,171],[2,1.55,5.63]],"ltp":1.58,"tv":882.55,"id":22229228}]}]}
{"op":"mcm","clk":"991914494","pt":1580554273125,"mc":[{"id":"1.168081817","rc":[{"batl":[[0,2.74,56.22],[1,95,15.9],[2,990,2.2]],"ltp":2.7,"tv":370.31,"id":15256065}]}]}
{"op":"mcm","clk":"991915771","pt":1580554284819,"mc":[{"id":"1.168081817","rc":[{"trd":[[2.72,106.82]],"ltp":2.72,"tv":426.53,"id":15256065},{"trd":[[1.58,519.36]],"batl":[[0,1.58,194.11]],"ltp":1.58,"tv":979.23,"id":22229228}],"tv":1405.77}]}
{"op":"mcm","clk":"992085428","pt":1580555397593,"mc":[{"id":"1.168081817","rc":[{"trd":[[1.58,719.26]],"batl":[[0,1.58,94.22]],"ltp":1.58,"tv":1179.13,"id":22229228}],"tv":1605.66}]}
{"op":"mcm","clk":"992145235","pt":1580555707794,"mc":[{"id":"1.168081817","rc":[{"trd":[[1.58,759.24]],"batl":[[0,1.58,74.23]],"ltp":1.58,"tv":1219.11,"id":22229228}],"tv":1645.65}]}
{"op":"mcm","clk":"992194226","pt":1580555917478,"mc":[{"id":"1.168081817","rc":[{"batl":[[0,1.58,84.23]],"ltp":1.58,"tv":1219.11,"id":22229228}]}]}
{"op":"mcm","clk":"992526088","pt":1580557792914,"mc":[{"id":"1.168081817","rc":[{"trd":[[1.58,792.83]],"batl":[[0,1.58,67.45]],"ltp":1.58,"tv":1252.7,"id":22229228}],"tv":1679.24}]}
{"op":"mcm","clk":"992935692","pt":1580559890526,"mc":[{"id":"1.168081817","rc":[{"trd":[[2.72,118.06]],"ltp":2.72,"tv":437.78,"id":15256065},{"trd":[[1.58,812.16]],"batl":[[0,1.58,48.11]],"ltp":1.58,"tv":1272.03,"id":22229228}],"tv":1709.81}]}
{"op":"mcm","clk":"993268298","pt":1580561526556,"mc":[{"id":"1.168081817","rc":[{"trd":[[1.57,40.37]],"batb":[[0,1.57,6.4]],"ltp":1.57,"tv":1276.03,"id":22229228}],"tv":1713.81}]}
{"op":"mcm","clk":"993608826","pt":1580563092183,"mc":[{"id":"1.168081817","rc":[{"batl":[[2,1.65,91.9]],"ltp":1.57,"tv":1276.03,"id":22229228}]}]}
{"op":"mcm","clk":"993609108","pt":1580563093382,"mc":[{"id":"1.168081817","rc":[{"batb":[[0,2.64,15.35]],"ltp":2.72,"tv":437.78,"id":15256065}]}]}
{"op":"mcm","clk":"993678768","pt":1580563406324,"mc":[{"id":"1.168081817","rc":[{"trd":[[1.58,908.43]],"batb":[[0,1.58,122.85],[1,1.57,6.4]],"batl":[[0,1.59,23.03],[1,1.65,91.9],[2,2.1,3.03]],"ltp":1.58,"tv":1372.3,"id":22229228}],"tv":1810.08}]}
{"op":"mcm","clk":"993844749","pt":1580564135668,"mc":[{"id":"1.168081817","rc":[{"batl":[[0,2.72,8.4],[1,2.74,56.22],[2,95,15.9]],"ltp":2.72,"tv":437.78,"id":15256065},{"trd":[[1.59,279.66]],"batl":[[0,1.59,13.5]],"ltp":1.59,"tv":1391.36,"id":22229228}],"tv":1829.14}]}
{"op":"mcm","clk":"993845201","pt":1580564137863,"mc":[{"id":"1.168081817","rc":[{"batb":[[1,1.55,5.63],[2,1.53,49.89]],"ltp":1.59,"tv":1391.36,"id":22229228}]}]}
{"op":"mcm","clk":"993956593","pt":1580564616866,"mc":[{"id":"1.168081817","rc":[{"batl":[[1,1.6,20],[2,1.65,91.9]],"ltp":1.59,"tv":1391.36,"id":22229228}]}]}
{"op":"mcm","clk":"993957103","pt":1580564619287,"mc":[{"id":"1.168081817","rc":[{"batl":[[2,1.61,3.17]],"ltp":1.59,"tv":1391.36,"id":22229228}]}]}
{"op":"mcm","clk":"993964118","pt":1580564650207,"mc":[{"id":"1.168081817","rc":[{"trd":[[1.59,306.67]],"batb":[[0,1.59,3.19],[1,1.58,122.85],[2,1.55,5.63]],"batl":[[0,1.6,20],[1,1.61,3.17],[2,1.65,91.9]],"ltp":1.59,"tv":1418.36,"id":22229228}],"tv":1856.14}]}
{"op":"mcm","clk":"993964381","pt":1580564651465,"mc":[{"id":"1.168081817","rc":[{"batl":[[1,1.65,91.9],[2,2.1,3.03]],"ltp":1.59,"tv":1418.36,"id":22229228}]}]}
{"op":"mcm","clk":"993969347","pt":1580564674748,"mc":[{"id":"1.168081817","rc":[{"batb":[[0,1.59,3.18]],"ltp":1.59,"tv":1418.36,"id":22229228}]}]}
{"op":"mcm","clk":"993972064","pt":1580564687488,"mc":[{"id":"1.168081817","rc":[{"batb":[[0,1.59,3.17]],"ltp":1.59,"tv":1418.36,"id":22229228}]}]}
{"op":"mcm","clk":"993972919","pt":1580564691344,"mc":[{"id":"1.168081817","rc":[{"batb":[[0,2.64,13.47]],"ltp":2.72,"tv":437.78,"id":15256065},{"trd":[[1.59,313]],"batb":[[0,1.58,122.85],[1,1.55,5.63],[2,1.53,53.13]],"ltp":1.59,"tv":1424.69,"id":22229228}],"tv":1862.47}]}
{"op":"mcm","clk":"993989479","pt":1580564761606,"mc":[{"id":"1.168081817","rc":[{"batb":[[0,1.58,122.88]],"ltp":1.59,"tv":1424.69,"id":22229228}]}]}
{"op":"mcm","clk":"993992023","pt":1580564772239,"mc":[{"id":"1.168081817","rc":[{"trd":[[1.6,4.84]],"batb":[[0,1.58,122.85]],"batl":[[0,1.6,19.97]],"ltp":1.6,"tv":1424.75,"id":22229228}],"tv":1862.53}]}
{"op":"mcm","clk":"994673115","pt":1580567472644,"mc":[{"id":"1.168081817","rc":[{"trd":[[1.6,27.68]],"batl":[[0,1.6,8.55]],"ltp":1.6,"tv":1447.59,"id":22229228}],"tv":1885.37}]}
{"op":"mcm","clk":"994773166","pt":1580567834128,"mc":[{"id":"1.168081817","rc":[{"batl":[[0,1.6,230.55]],"ltp":1.6,"tv":1447.59,"id":22229228}]}]}
{"op":"mcm","clk":"994773457","pt":1580567835120,"mc":[{"id":"1.168081817","rc":[{"batl":[[0,1.59,3.21],[1,1.6,230.55],[2,1.65,91.9]],"ltp":1.6,"tv":1447.59,"id":22229228}]}]}
{"op":"mcm","clk":"995030986","pt":1580568859182,"mc":[{"id":"1.168081817","rc":[{"batb":[[1,2.54,80.27],[2,2.5,21.56]],"ltp":2.72,"tv":437.78,"id":15256065},{"batb":[[1,1.55,64.45]],"ltp":1.6,"tv":1447.59,"id":22229228}]}]}
{"op":"mcm","clk":"995106535","pt":1580569201136,"mc":[{"id":"1.168081817","rc":[{"batb":[[0,2.56,29.97]],"ltp":2.72,"tv":437.78,"id":15256065},{"batb":[[1,1.56,22.81],[2,1.55,64.45]],"ltp":1.6,"tv":1447.59,"id":22229228}]}]}
{"op":"mcm","clk":"995404710","pt":1580570344868,"mc":[{"id":"1.168081817","rc":[{"trd":[[2.72,134.86]],"batb":[[0,2.72,37.56],[1,2.56,29.97],[2,2.54,80.27]],"batl":[[0,2.74,56.22],[1,95,15.9],[2,990,2.2]],"ltp":2.72,"tv":454.58,"id":15256065}],"tv":1902.17}]}
{"op":"mcm","clk":"995405387","pt":1580570347716,"mc":[{"id":"1.168081817","rc":[{"batb":[[1,2.68,8.53],[2,2.56,29.97]],"ltp":2.72,"tv":454.58,"id":15256065}]}]}
{"op":"mcm","clk":"995405718","pt":1580570349002,"mc":[{"id":"1.168081817","rc":[{"batb":[[2,1.55,5.63]],"ltp":1.6,"tv":1447.59,"id":22229228}]}]}
{"op":"mcm","clk":"995411035","pt":1580570370452,"mc":[{"id":"1.168081817","rc":[{"batb":[[0,2.68,8.53],[1,2.56,29.97],[2,2.54,80.27]],"ltp":2.72,"tv":454.58,"id":15256065}]}]}
{"op":"mcm","clk":"995411854","pt":1580570373964,"mc":[{"id":"1.168081817","rc":[{"batb":[[2,1.55,64.45]],"ltp":1.6,"tv":1447.59,"id":22229228}]}]}
{"op":"mcm","clk":"995415234","pt":1580570387557,"mc":[{"id":"1.168081817","rc":[{"trd":[[2.68,144.04]],"batb":[[0,2.56,29.98],[1,2.54,80.27],[2,2.5,21.56]],"ltp":2.68,"tv":471.62,"id":15256065}],"tv":1919.21}]}
{"op":"mcm","clk":"995415435","pt":1580570388369,"mc":[{"id":"1.168081817","rc":[{"batb":[[0,2.56,29.97]],"ltp":2.68,"tv":471.62,"id":15256065}]}]}
{"op":"mcm","clk":"995418967","pt":1580570402301,"mc":[{"id":"1.168081817","rc":[{"trd":[[2.74,102.49]],"batl":[[0,2.74,10.6]],"ltp":2.74,"tv":562.86,"id":15256065}],"tv":2010.45}]}
{"op":"mcm","clk":"995777555","pt":1580571823359,"mc":[{"id":"1.168081817","rc":[{"batl":[[0,1.59,13.21]],"ltp":1.6,"tv":1447.59,"id":22229228}]}]}
{"op":"mcm","clk":"995992550","pt":1580572939936,"mc":[{"id":"1.168081817","rc":[{"trd":[[1.59,339.42]],"batb":[[0,1.59,6.66],[1,1.58,122.85],[2,1.56,22.81]],"batl":[[0,1.6,230.55],[1,1.65,91.9],[2,2.1,3.03]],"ltp":1.59,"tv":1474.01,"id":22229228}],"tv":2036.87}]}
{"op":"mcm","clk":"995996143","pt":1580572960873,"mc":[{"id":"1.168081817","rc":[{"batb":[[0,1.58,122.85],[1,1.56,22.81],[2,1.55,64.45]],"ltp":1.59,"tv":1474.01,"id":22229228}]}]}
{"op":"mcm","clk":"996016552","pt":1580573078894,"mc":[{"id":"1.168081817","rc":[{"trd":[[1.6,41.02]],"batl":[[0,1.6,223.88]],"ltp":1.6,"tv":1487.35,"id":22229228}],"tv":2050.21}]}
{"op":"mcm","clk":"996125225","pt":1580573567516,"mc":[{"id":"1.168081817","rc":[{"batl":[[0,1.59,20],[1,1.6,223.88],[2,1.65,91.9]],"ltp":1.6,"tv":1487.35,"id":22229228}]}]}
{"op":"mcm","clk":"996433840","pt":1580574843257,"mc":[{"id":"1.168081817","rc":[{"trd":[[2.68,155.9]],"ltp":2.68,"tv":574.72,"id":15256065},{"trd":[[1.59,359.42]],"batl":[[0,1.6,223.88],[1,1.65,91.9],[2,2.1,3.03]],"ltp":1.59,"tv":1507.35,"id":22229228}],"tv":2082.08}]}
{"op":"mcm","clk":"996434344","pt":1580574845530,"mc":[{"id":"1.168081817","rc":[{"batl":[[0,2.74,11.3]],"ltp":2.68,"tv":574.72,"id":15256065}]}]}
{"op":"mcm","clk":"996505894","pt":1580575170990,"mc":[{"id":"1.168081817","rc":[{"batl":[[0,1.6,273.88]],"ltp":1.59,"tv":1507.35,"id":22229228}]}]}
{"op":"mcm","clk":"996512749","pt":1580575201694,"mc":[{"id":"1.168081817","rc":[{"trd":[[2.66,9.76]],"ltp":2.66,"tv":584.48,"id":15256065},{"trd":[[1.6,57.25]],"batl":[[0,1.6,257.65]],"ltp":1.6,"tv":1523.58,"id":22229228}],"tv":2108.07}]}
{"op":"mcm","clk":"996615527","pt":1580575668853,"mc":[{"id":"1.168081817","rc":[{"trd":[[1.6,250.93]],"batl":[[0,1.6,160.81]],"ltp":1.6,"tv":1717.26,"id":22229228}],"tv":2301.75}]}
{"op":"mcm","clk":"996627517","pt":1580575732674,"mc":[{"id":"1.168081817","rc":[{"trd":[[2.68,156.6]],"batl":[[0,2.74,10.6]],"ltp":2.68,"tv":585.18,"id":15256065},{"trd":[[1.59,360.6]],"batl":[[0,1.59,18.82],[1,1.6,160.81],[2,1.65,91.9]],"ltp":1.59,"tv":1718.44,"id":22229228}],"tv":2303.63}]}
{"op":"mcm","clk":"996662238","pt":1580575924101,"mc":[{"id":"1.168081817","rc":[{"trd":[[1.59,398.24]],"batb":[[0,1.58,123.65]],"batl":[[0,1.6,160.81],[1,1.65,91.9],[2,2.1,3.03]],"ltp":1.59,"tv":1756.08,"id":22229228}],"tv":2341.27}]}
{"op":"mcm","clk":"996668036","pt":1580575956900,"mc":[{"id":"1.168081817","rc":[{"trd":[[1.6,252.53]],"batb":[[0,1.58,122.85]],"batl":[[0,1.6,160.01]],"ltp":1.6,"tv":1757.68,"id":22229228}],"tv":2342.87}]}
{"op":"mcm","clk":"996764301","pt":1580576614245,"mc":[{"id":"1.168081817","rc":[{"trd":[[1.6,291.75]],"batl":[[0,1.6,140.4]],"ltp":1.6,"tv":1796.9,"id":22229228}],"tv":2382.09}]}
{"op":"mcm","clk":"996854526","pt":1580577185816,"mc":[{"id":"1.168081817","rc":[{"trd":[[1.6,483.01]],"batl":[[0,1.6,44.77]],"ltp":1.6,"tv":1988.16,"id":22229228}],"tv":2573.35}]}
{"op":"mcm","clk":"996854772","pt":1580577187418,"mc":[{"id":"1.168081817","rc":[{"batb":[[0,1.59,9.59],[1,1.58,122.85],[2,1.56,22.81]],"ltp":1.6,"tv":1988.16,"id":22229228}]}]}
{"op":"mcm","clk":"996949766","pt":1580577831534,"mc":[{"id":"1.168081817","rc":[{"batb":[[0,2.58,302.37],[1,2.56,29.97],[2,2.54,80.27]],"ltp":2.68,"tv":585.18,"id":15256065},{"trd":[[1.6,572.55]],"batb":[[0,1.6,78.08],[1,1.59,9.59]],"batl":[[0,1.65,91.9],[1,2.1,3.03],[2,7,8.66]],"ltp":1.6,"tv":2077.7,"id":22229228}],"tv":2662.89}]}
{"op":"mcm","clk":"996949874","pt":1580577832353,"mc":[{"id":"1.168081817","rc":[{"batb":[[1,1.56,22.81],[2,1.55,64.45]],"batl":[[0,1.64,10.68],[1,1.65,91.9],[2,2.1,3.03]],"ltp":1.6,"tv":2077.7,"id":22229228}]}]}
{"op":"mcm","clk":"996953498","pt":1580577857614,"mc":[{"id":"1.168081817","rc":[{"trd":[[1.6,600.24]],"batb":[[0,1.6,64.23]],"ltp":1.6,"tv":2105.39,"id":22229228}],"tv":2690.58}]}
{"op":"mcm","clk":"996953553","pt":1580577858039,"mc":[{"id":"1.168081817","rc":[{"batb":[[0,2.6,13.14],[1,2.58,302.37]],"ltp":2.68,"tv":585.18,"id":15256065},{"batb":[[1,1.56,36.88]],"ltp":1.6,"tv":2105.39,"id":22229228}]}]}
{"op":"mcm","clk":"996953761","pt":1580577859432,"mc":[{"id":"1.168081817","rc":[{"batb":[[0,2.6,312.98],[1,2.54,80.27],[2,2.42,390.84]],"ltp":2.68,"tv":585.18,"id":15256065},{"batb":[[2,1.55,5.63]],"ltp":1.6,"tv":2105.39,"id":22229228}]}]}
{"op":"mcm","clk":"996954003","pt":1580577861254,"mc":[{"id":"1.168081817","rc":[{"batl":[[0,1.62,10.63]],"ltp":1.6,"tv":2105.39,"id":22229228}]}]}
{"op":"mcm","clk":"996959646","pt":1580577897495,"mc":[{"id":"1.168081817","rc":[{"batb":[[0,2.6,13.14]],"ltp":2.68,"tv":585.18,"id":15256065},{"trd":[[1.6,728.64]],"batb":[[0,1.56,36.88],[1,1.55,5.63],[2,1.51,1088.23]],"batl":[[0,1.6,37.14],[1,1.62,10.63],[2,1.65,91.9]],"ltp":1.6,"tv":2233.79,"id":22229228}],"tv":2818.98}]}
{"op":"mcm","clk":"996960006","pt":1580577899694,"mc":[{"id":"1.168081817","rc":[{"batb":[[2,2.5,21.56]],"ltp":2.68,"tv":585.18,"id":15256065},{"batb":[[1,1.55,64.45]],"batl":[[0,1.65,91.9],[1,2.1,3.03],[2,7,8.66]],"ltp":1.6,"tv":2233.79,"id":22229228}]}]}
{"op":"mcm","clk":"996960069","pt":1580577900065,"mc":[{"id":"1.168081817","rc":[{"batb":[[0,2.6,312.98]],"ltp":2.68,"tv":585.18,"id":15256065}]}]}
{"op":"mcm","clk":"996960832","pt":1580577904703,"mc":[{"id":"1.168081817","rc":[{"batb":[[2,2.5,10]],"ltp":2.68,"tv":585.18,"id":15256065}]}]}
{"op":"mcm","clk":"996971989","pt":1580577977682,"mc":[{"id":"1.168081817","rc":[{"batl":[[0,1.62,10.44],[1,1.65,91.9],[2,2.1,3.03]],"ltp":1.6,"tv":2233.79,"id":22229228}]}]}
{"op":"mcm","clk":"997070766","pt":1580578623797,"mc":[{"id":"1.168081817","rc":[{"batb":[[0,2.6,13.14]],"ltp":2.68,"tv":585.18,"id":15256065}]}]}
{"op":"mcm","clk":"997071054","pt":1580578625610,"mc":[{"id":"1.168081817","rc":[{"batl":[[0,1.64,9.17]],"ltp":1.6,"tv":2233.79,"id":22229228}]}]}
{"op":"mcm","clk":"997071334","pt":1580578627521,"mc":[{"id":"1.168081817","rc":[{"batb":[[2,2.5,21.56]],"ltp":2.68,"tv":585.18,"id":15256065}]}]}
{"op":"mcm","clk":"997073012","pt":1580578638444,"mc":[{"id":"1.168081817","rc":[{"batb":[[0,2.58,17.28]],"ltp":2.68,"tv":585.18,"id":15256065}]}]}
{"op":"mcm","clk":"997457880","pt":1580581007687,"mc":[{"id":"1.168081817","rc":[{"batl":[[0,95,15.9],[1,990,2.2],[2,1000,0.02]],"ltp":2.68,"tv":585.18,"id":15256065}]}]}
{"op":"mcm","clk":"997457989","pt":1580581008342,"mc":[{"id":"1.168081817","rc":[{"batb":[[0,2.6,299.84],[1,2.58,17.28],[2,2.54,80.27]],"ltp":2.68,"tv":585.18,"id":15256065}]}]}
{"op":"mcm","clk":"997458398","pt":1580581010615,"mc":[{"id":"1.168081817","rc":[{"batl":[[0,1.65,91.9],[1,2.1,3.03],[2,7,8.66]],"ltp":1.6,"tv":2233.79,"id":22229228}]}]}
{"op":"mcm","clk":"997458425","pt":1580581010789,"mc":[{"id":"1.168081817","rc":[{"batl":[[0,1.62,11.12],[1,1.65,91.9],[2,2.1,3.03]],"ltp":1.6,"tv":2233.79,"id":22229228}]}]}
{"op":"mcm","clk":"997458634","pt":1580581012015,"mc":[{"id":"1.168081817","rc":[{"batb":[[0,2.58,17.28],[1,2.54,80.27],[2,2.42,390.84]],"ltp":2.68,"tv":585.18,"id":15256065}]}]}
{"op":"mcm","clk":"997458899","pt":1580581013627,"mc":[{"id":"1.168081817","rc":[{"batl":[[0,1.64,8.45]],"ltp":1.6,"tv":2233.79,"id":22229228}]}]}
{"op":"mcm","clk":"997458965","pt":1580581014008,"mc":[{"id":"1.168081817","rc":[{"batb":[[0,2.6,299.84],[1,2.58,17.28],[2,2.54,80.27]],"ltp":2.68,"tv":585.18,"id":15256065}]}]}
{"op":"mcm","clk":"997459226","pt":1580581015794,"mc":[{"id":"1.168081817","rc":[{"batl":[[0,1.65,91.9],[1,2.1,3.03],[2,7,8.66]],"ltp":1.6,"tv":2233.79,"id":22229228}]}]}
{"op":"mcm","clk":"997473058","pt":1580581094560,"mc":[{"id":"1.168081817","rc":[{"batl":[[0,1.62,11.17],[1,1.65,91.9],[2,2.1,3.03]],"ltp":1.6,"tv":2233.79,"id":22229228}]}]}
{"op":"mcm","clk":"997473162","pt":1580581095134,"mc":[{"id":"1.168081817","rc":[{"batb":[[0,2.58,17.28],[1,2.54,80.27],[2,2.42,390.84]],"ltp":2.68,"tv":585.18,"id":15256065}]}]}
{"op":"mcm","clk":"997473554","pt":1580581097556,"mc":[{"id":"1.168081817","rc":[{"batl":[[0,1.64,10.5]],"ltp":1.6,"tv":2233.79,"id":22229228}]}]}
{"op":"mcm","clk":"997473687","pt":1580581098261,"mc":[{"id":"1.168081817","rc":[{"batb":[[0,2.6,299.84],[1,2.58,17.28],[2,2.54,80.27]],"ltp":2.68,"tv":585.18,"id":15256065}]}]}
{"op":"mcm","clk":"997473953","pt":1580581099746,"mc":[{"id":"1.168081817","rc":[{"batl":[[0,1.65,91.9],[1,2.1,3.03],[2,7,8.66]],"ltp":1.6,"tv":2233.79,"id":22229228}]}]}
{"op":"mcm","clk":"997477072","pt":1580581116820,"mc":[{"id":"1.168081817","rc":[{"batb":[[0,2.62,9.1],[1,2.6,299.84]],"ltp":2.68,"tv":585.18,"id":15256065}]}]}
{"op":"mcm","clk":"997477532","pt":1580581119345,"mc":[{"id":"1.168081817","rc":[{"batb":[[1,2.54,80.27],[2,2.5,10]],"ltp":2.68,"tv":585.18,"id":15256065}]}]}
{"op":"mcm","clk":"997478419","pt":1580581124244,"mc":[{"id":"1.168081817","rc":[{"batb":[[2,2.5,21.56]],"ltp":2.68,"tv":585.18,"id":15256065}]}]}
{"op":"mcm","clk":"997481938","pt":1580581142353,"mc":[{"id":"1.168081817","rc":[{"batb":[[1,2.56,30.29],[2,2.54,80.27]],"ltp":2.68,"tv":585.18,"id":15256065}]}]}
{"op":"mcm","clk":"997488868","pt":1580581178373,"mc":[{"id":"1.168081817","rc":[{"batl":[[0,1.64,8.9],[1,1.65,91.9],[2,2.1,3.03]],"ltp":1.6,"tv":2233.79,"id":22229228}]}]}
{"op":"mcm","clk":"997508125","pt":1580581276200,"mc":[{"id":"1.168081817","rc":[{"batb":[[0,2.58,17.28]],"ltp":2.68,"tv":585.18,"id":15256065}]}]}
{"op":"mcm","clk":"997508386","pt":1580581277220,"mc":[{"id":"1.168081817","rc":[{"batl":[[0,1.63,478.5],[1,1.64,8.9],[2,1.65,91.9]],"ltp":1.6,"tv":2233.79,"id":22229228}]}]}
{"op":"mcm","clk":"997508613","pt":1580581278320,"mc":[{"id":"1.168081817","rc":[{"batl":[[0,1.62,10.96],[1,1.63,478.5]],"ltp":1.6,"tv":2233.79,"id":22229228}]}]}
{"op":"mcm","clk":"997529868","pt":1580581387409,"mc":[{"id":"1.168081817","rc":[{"batb":[[1,2.54,80.27],[2,2.5,21.56]],"ltp":2.68,"tv":585.18,"id":15256065},{"batl":[[1,1.65,91.9],[2,2.1,3.03]],"ltp":1.6,"tv":2233.79,"id":22229228}]}]}
{"op":"mcm","clk":"997530256","pt":1580581389447,"mc":[{"id":"1.168081817","rc":[{"batl":[[0,1.64,9.44]],"ltp":1.6,"tv":2233.79,"id":22229228}]}]}
{"op":"mcm","clk":"997635038","pt":1580581984523,"mc":[{"id":"1.168081817","rc":[{"trd":[[2.58,17.28]],"batb":[[0,2.54,80.27],[1,2.5,21.56],[2,2.42,390.84]],"ltp":2.58,"tv":602.47,"id":15256065},{"trd":[[1.64,46.83]],"batb":[[0,1.64,58.68],[1,1.56,36.88],[2,1.55,64.45]],"batl":[[0,1.65,91.9],[1,2.1,3.03],[2,7,8.66]],"ltp":1.64,"tv":2279.86,"id":22229228}],"tv":2882.33}]}
{"op":"mcm","clk":"997635156","pt":1580581985192,"mc":[{"id":"1.168081817","rc":[{"trd":[[1.64,164.19]],"batb":[[0,1.56,46.81],[1,1.55,64.45],[2,1.51,1088.23]],"ltp":1.64,"tv":2397.22,"id":22229228}],"tv":2999.69}]}
{"op":"mcm","clk":"997635244","pt":1580581985723,"mc":[{"id":"1.168081817","rc":[{"batb":[[0,2.56,20.14],[1,2.54,80.27],[2,2.5,21.56]],"ltp":2.58,"tv":602.47,"id":15256065},{"batb":[[0,1.56,49.09]],"ltp":1.64,"tv":2397.22,"id":22229228}]}]}
{"op":"mcm","clk":"997637506","pt":1580581998632,"mc":[{"id":"1.168081817","rc":[{"batb":[[0,2.58,332.66],[1,2.56,20.14],[2,2.54,80.27]],"ltp":2.58,"tv":602.47,"id":15256065}]}]}
{"op":"mcm","clk":"997650491","pt":1580582076619,"mc":[{"id":"1.168081817","rc":[{"batb":[[0,2.6,11.77],[1,2.58,332.66]],"ltp":2.58,"tv":602.47,"id":15256065}]}]}
{"op":"mcm","clk":"997657571","pt":1580582121282,"mc":[{"id":"1.168081817","rc":[{"batb":[[0,2.6,311.61],[1,2.54,80.27],[2,2.42,390.84]],"ltp":2.58,"tv":602.47,"id":15256065}]}]}
{"op":"mcm","clk":"997657723","pt":1580582122202,"mc":[{"id":"1.168081817","rc":[{"batb":[[2,2.5,10]],"ltp":2.58,"tv":602.47,"id":15256065}]}]}
{"op":"mcm","clk":"997707286","pt":1580582402672,"mc":[{"id":"1.168081817","rc":[{"trd":[[2.62,56.68]],"batb":[[0,2.6,11.77]],"ltp":2.62,"tv":621.97,"id":15256065}],"tv":3019.19}]}
{"op":"mcm","clk":"997707441","pt":1580582403474,"mc":[{"id":"1.168081817","rc":[{"batb":[[2,2.5,21.56]],"ltp":2.62,"tv":621.97,"id":15256065}]}]}
{"op":"mcm","clk":"997708409","pt":1580582408589,"mc":[{"id":"1.168081817","rc":[{"batb":[[0,2.56,20.14]],"ltp":2.62,"tv":621.97,"id":15256065}]}]}
{"op":"mcm","clk":"997710019","pt":1580582417975,"mc":[{"id":"1.168081817","rc":[{"batb":[[0,2.58,302.37],[1,2.56,20.14],[2,2.54,80.27]],"ltp":2.62,"tv":621.97,"id":15256065}]}]}
{"op":"mcm","clk":"997736351","pt":1580582572187,"mc":[{"id":"1.168081817","rc":[{"batb":[[0,2.6,11.77],[1,2.58,302.37]],"ltp":2.62,"tv":621.97,"id":15256065}]}]}
{"op":"mcm","clk":"997736641","pt":1580582573656,"mc":[{"id":"1.168081817","rc":[{"batb":[[1,2.54,80.27],[2,2.5,10]],"ltp":2.62,"tv":621.97,"id":15256065}]}]}
{"op":"mcm","clk":"997736688","pt":1580582573883,"mc":[{"id":"1.168081817","rc":[{"batb":[[0,2.6,311.61]],"ltp":2.62,"tv":621.97,"id":15256065}]}]}
{"op":"mcm","clk":"997773535","pt":1580582793713,"mc":[{"id":"1.168081817","rc":[{"batb":[[0,1.57,20],[1,1.56,49.09],[2,1.55,64.45]],"ltp":1.64,"tv":2397.22,"id":22229228}]}]}
{"op":"mcm","clk":"997918103","pt":1580583875627,"mc":[{"id":"1.168081817","rc":[{"batb":[[0,2.6,459.66]],"ltp":2.62,"tv":621.97,"id":15256065}]}]}
{"op":"mcm","clk":"997918306","pt":1580583877003,"mc":[{"id":"1.168081817","rc":[{"batb":[[2,2.42,390.84]],"ltp":2.62,"tv":621.97,"id":15256065}]}]}
{"op":"mcm","clk":"998103313","pt":1580584942585,"mc":[{"id":"1.168081817","rc":[{"trd":[[1.57,80.37]],"batb":[[0,1.56,49.09],[1,1.55,64.45],[2,1.51,1088.23]],"ltp":1.57,"tv":2437.22,"id":22229228}],"tv":3059.19}]}
{"op":"mcm","clk":"998134366","pt":1580585147234,"mc":[{"id":"1.168081817","rc":[{"batb":[[0,2.62,11.5],[1,2.6,11.77],[2,2.54,80.27]],"ltp":2.62,"tv":621.97,"id":15256065}]}]}
{"op":"mcm","clk":"998146683","pt":1580585226600,"mc":[{"id":"1.168081817","rc":[{"batb":[[1,2.54,80.27],[2,2.5,21.56]],"ltp":2.62,"tv":621.97,"id":15256065}]}]}
{"op":"mcm","clk":"998146709","pt":1580585226989,"mc":[{"id":"1.168081817","rc":[{"batb":[[1,2.56,20.14],[2,2.54,80.27]],"ltp":2.62,"tv":621.97,"id":15256065}]}]}
{"op":"mcm","clk":"998157268","pt":1580585288545,"mc":[{"id":"1.168081817","rc":[{"batb":[[1,2.58,30.29],[2,2.56,20.14]],"ltp":2.62,"tv":621.97,"id":15256065}]}]}
{"op":"mcm","clk":"998170582","pt":1580585369547,"mc":[{"id":"1.168081817","rc":[{"batb":[[1,2.6,11.77],[2,2.58,30.29]],"ltp":2.62,"tv":621.97,"id":15256065}]}]}
{"op":"mcm","clk":"998177552","pt":1580585410484,"mc":[{"id":"1.168081817","rc":[{"batb":[[2,2.54,80.27]],"ltp":2.62,"tv":621.97,"id":15256065}]}]}
{"op":"mcm","clk":"998194463","pt":1580585504210,"mc":[{"id":"1.168081817","rc":[{"batb":[[1,2.56,20.14]],"ltp":2.62,"tv":621.97,"id":15256065}]}]}
{"op":"mcm","clk":"998199794","pt":1580585531895,"mc":[{"id":"1.168081817","rc":[{"batb":[[1,2.58,30.29],[2,2.56,20.14]],"ltp":2.62,"tv":621.97,"id":15256065}]}]}
{"op":"mcm","clk":"998205728","pt":1580585563668,"mc":[{"id":"1.168081817","rc":[{"batl":[[0,1.62,333],[1,1.65,91.9],[2,2.1,3.03]],"ltp":1.57,"tv":2437.22,"id":22229228}]}]}
{"op":"mcm","clk":"998219150","pt":1580585636053,"mc":[{"id":"1.168081817","rc":[{"batl":[[2,1.76,16.8]],"ltp":1.57,"tv":2437.22,"id":22229228}]}]}
{"op":"mcm","clk":"998220105","pt":1580585641299,"mc":[{"id":"1.168081817","rc":[{"batb":[[0,2.62,19.23],[2,2.54,80.27]],"ltp":2.62,"tv":621.97,"id":15256065}]}]}
{"op":"mcm","clk":"998222312","pt":1580585653486,"mc":[{"id":"1.168081817","rc":[{"batb":[[1,2.54,80.27],[2,2.5,21.56]],"ltp":2.62,"tv":621.97,"id":15256065}]}]}
{"op":"mcm","clk":"998234414","pt":1580585721615,"mc":[{"id":"1.168081817","rc":[{"trd":[[2.62,63.01]],"batb":[[0,2.62,16.07]],"ltp":2.62,"tv":628.29,"id":15256065}],"tv":3065.52}]}
{"op":"mcm","clk":"998236401","pt":1580585733333,"mc":[{"id":"1.168081817","rc":[{"batb":[[0,2.62,469.4]],"ltp":2.62,"tv":628.29,"id":15256065}]}]}
{"op":"mcm","clk":"998236846","pt":1580585735610,"mc":[{"id":"1.168081817","rc":[{"batb":[[1,2.58,80.27]],"ltp":2.62,"tv":628.29,"id":15256065}]}]}
{"op":"mcm","clk":"998237093","pt":1580585737024,"mc":[{"id":"1.168081817","rc":[{"batb":[[2,2.42,390.84]],"ltp":2.62,"tv":628.29,"id":15256065}]}]}
{"op":"mcm","clk":"998265588","pt":1580585902193,"mc":[{"id":"1.168081817","rc":[{"batb":[[0,2.64,7.6],[1,2.62,469.4],[2,2.58,80.27]],"ltp":2.62,"tv":628.29,"id":15256065},{"batb":[[0,1.56,36.34]],"ltp":1.57,"tv":2437.22,"id":22229228}]}]}
{"op":"mcm","clk":"998273033","pt":1580585947672,"mc":[{"id":"1.168081817","rc":[{"batb":[[1,1.55,5.63]],"ltp":1.57,"tv":2437.22,"id":22229228}]}]}
{"op":"mcm","clk":"998273315","pt":1580585949289,"mc":[{"id":"1.168081817","rc":[{"batb":[[0,1.56,26.41]],"ltp":1.57,"tv":2437.22,"id":22229228}]}]}
{"op":"mcm","clk":"998278179","pt":1580585977476,"mc":[{"id":"1.168081817","rc":[{"batl":[[0,1.6,50],[1,1.62,333],[2,1.65,91.9]],"ltp":1.57,"tv":2437.22,"id":22229228}]}]}
{"op":"mcm","clk":"998278239","pt":1580585977904,"mc":[{"id":"1.168081817","rc":[{"batb":[[1,2.62,16.07]],"ltp":2.62,"tv":628.29,"id":15256065}]}]}
{"op":"mcm","clk":"998279019","pt":1580585982601,"mc":[{"id":"1.168081817","rc":[{"batb":[[1,2.62,36.04]],"ltp":2.62,"tv":628.29,"id":15256065}]}]}
{"op":"mcm","clk":"998452412","pt":1580587195663,"mc":[{"id":"1.168081817","rc":[{"batl":[[0,1.57,3.79],[1,1.6,50],[2,1.62,333]],"ltp":1.57,"tv":2437.22,"id":22229228}]}]}
{"op":"mcm","clk":"998454162","pt":1580587207692,"mc":[{"id":"1.168081817","rc":[{"trd":[[1.57,87.95]],"batb":[[0,1.55,5.63],[1,1.51,1088.23],[2,1.5,64.7]],"batl":[[0,1.6,50],[1,1.62,333],[2,1.65,91.9]],"ltp":1.57,"tv":2444.8,"id":22229228}],"tv":3073.09}]}
{"op":"mcm","clk":"998454207","pt":1580587208084,"mc":[{"id":"1.168081817","rc":[{"batb":[[0,2.64,9.83]],"ltp":2.62,"tv":628.29,"id":15256065},{"batb":[[1,1.53,52.94],[2,1.51,1088.23]],"ltp":1.57,"tv":2444.8,"id":22229228}]}]}
{"op":"mcm","clk":"998454281","pt":1580587209474,"mc":[{"id":"1.168081817","rc":[{"batl":[[0,2.96,8.4],[1,95,15.9],[2,990,2.2]],"ltp":2.62,"tv":628.29,"id":15256065},{"batb":[[2,1.52,24.86]],"ltp":1.57,"tv":2444.8,"id":22229228}]}]}
{"op":"mcm","clk":"998487942","pt":1580587442401,"mc":[{"id":"1.168081817","rc":[{"trd":[[1.52,49.72],[1.53,105.88],[1.55,11.27]],"batb":[[0,1.51,1088.23],[1,1.5,53.65],[2,1.47,139.33]],"ltp":1.52,"tv":2611.67,"id":22229228}],"tv":3239.97}]}
{"op":"mcm","clk":"998488136","pt":1580587443693,"mc":[{"id":"1.168081817","rc":[{"batb":[[0,2.7,31.67],[1,2.62,28.31]],"ltp":2.62,"tv":628.29,"id":15256065},{"trd":[[1.52,71.65]],"ltp":1.52,"tv":2633.6,"id":22229228}],"tv":3261.9}]}
{"op":"mcm","clk":"998488292","pt":1580587444278,"mc":[{"id":"1.168081817","rc":[{"batb":[[0,2.74,30.18],[1,2.72,454.34],[2,2.62,28.31]],"ltp":2.62,"tv":628.29,"id":15256065},{"batb":[[2,1.48,45.17]],"batl":[[0,1.59,14.02],[1,1.6,50],[2,1.62,333]],"ltp":1.52,"tv":2633.6,"id":22229228}]}]}
{"op":"mcm","clk":"998488495","pt":1580587445513,"mc":[{"id":"1.168081817","rc":[{"batb":[[0,2.74,481.2],[1,2.62,28.31],[2,2.58,80.27]],"ltp":2.62,"tv":628.29,"id":15256065},{"batl":[[0,1.58,12.46],[1,1.59,14.02],[2,1.6,50]],"ltp":1.52,"tv":2633.6,"id":22229228}]}]}
{"op":"mcm","clk":"998488712","pt":1580587446699,"mc":[{"id":"1.168081817","rc":[{"batb":[[1,2.62,8.34]],"ltp":2.62,"tv":628.29,"id":15256065},{"batb":[[1,1.5,64.7]],"batl":[[1,1.6,50],[2,1.62,333]],"ltp":1.52,"tv":2633.6,"id":22229228}]}]}
{"op":"mcm","clk":"998488829","pt":1580587447408,"mc":[{"id":"1.168081817","rc":[{"batb":[[1,2.64,80.27],[2,2.62,8.34]],"ltp":2.62,"tv":628.29,"id":15256065},{"batl":[[0,1.57,10.54],[1,1.58,12.46],[2,1.6,50]],"ltp":1.52,"tv":2633.6,"id":22229228}]}]}
{"op":"mcm","clk":"998490024","pt":1580587454631,"mc":[{"id":"1.168081817","rc":[{"batb":[[0,2.74,30.18]],"ltp":2.62,"tv":628.29,"id":15256065}]}]}
{"op":"mcm","clk":"998490143","pt":1580587455448,"mc":[{"id":"1.168081817","rc":[{"batl":[[0,1.6,50],[1,1.62,333],[2,1.65,91.9]],"ltp":1.52,"tv":2633.6,"id":22229228}]}]}
{"op":"mcm","clk":"998490350","pt":1580587456662,"mc":[{"id":"1.168081817","rc":[{"batb":[[0,2.74,481.2],[2,2.62,28.31]],"ltp":2.62,"tv":628.29,"id":15256065}]}]}
{"op":"mcm","clk":"998491079","pt":1580587461346,"mc":[{"id":"1.168081817","rc":[{"batb":[[2,2.62,8.34]],"ltp":2.62,"tv":628.29,"id":15256065}]}]}
{"op":"mcm","clk":"998491411","pt":1580587463602,"mc":[{"id":"1.168081817","rc":[{"batl":[[0,1.57,14.2],[1,1.6,50],[2,1.62,333]],"ltp":1.52,"tv":2633.6,"id":22229228}]}]}
{"op":"mcm","clk":"998491645","pt":1580587465246,"mc":[{"id":"1.168081817","rc":[{"batb":[[0,2.74,30.18]],"ltp":2.62,"tv":628.29,"id":15256065},{"batl":[[0,1.57,17.2]],"ltp":1.52,"tv":2633.6,"id":22229228}]}]}
{"op":"mcm","clk":"998491873","pt":1580587466682,"mc":[{"id":"1.168081817","rc":[{"batb":[[2,2.62,28.31]],"ltp":2.62,"tv":628.29,"id":15256065},{"batl":[[0,1.57,3]],"ltp":1.52,"tv":2633.6,"id":22229228}]}]}
{"op":"mcm","clk":"998502867","pt":1580587536362,"mc":[{"id":"1.168081817","rc":[{"batl":[[1,1.59,14.02],[2,1.6,50]],"ltp":1.52,"tv":2633.6,"id":22229228}]}]}
{"op":"mcm","clk":"998506227","pt":1580587556597,"mc":[{"id":"1.168081817","rc":[{"batb":[[0,2.8,17.97],[1,2.74,30.18],[2,2.64,80.27]],"ltp":2.62,"tv":628.29,"id":15256065},{"batb":[[1,1.48,45.17],[2,1.44,141.6]],"ltp":1.52,"tv":2633.6,"id":22229228}]}]}
{"op":"mcm","clk":"998506567","pt":1580587558645,"mc":[{"id":"1.168081817","rc":[{"batl":[[0,1.57,17.2],[1,1.6,50],[2,1.62,333]],"ltp":1.52,"tv":2633.6,"id":22229228}]}]}
{"op":"mcm","clk":"998507076","pt":1580587561496,"mc":[{"id":"1.168081817","rc":[{"trd":[[1.51,193.24]],"batb":[[0,1.51,991.61]],"ltp":1.51,"tv":2826.84,"id":22229228}],"tv":3455.14}]}
{"op":"mcm","clk":"998507975","pt":1580587566475,"mc":[{"id":"1.168081817","rc":[{"batb":[[2,1.44,215.12]],"ltp":1.51,"tv":2826.84,"id":22229228}]}]}
{"op":"mcm","clk":"998515982","pt":1580587620518,"mc":[{"id":"1.168081817","rc":[{"batb":[[1,2.64,80.27],[2,2.62,8.34]],"ltp":2.62,"tv":628.29,"id":15256065},{"batb":[[1,1.44,215.12],[2,1.37,4]],"ltp":1.51,"tv":2826.84,"id":22229228}]}]}
{"op":"mcm","clk":"998516161","pt":1580587621690,"mc":[{"id":"1.168081817","rc":[{"batb":[[0,2.82,16.26],[1,2.8,17.97],[2,2.64,80.27]],"ltp":2.62,"tv":628.29,"id":15256065},{"batb":[[1,1.47,57.33],[2,1.44,285.77]],"ltp":1.51,"tv":2826.84,"id":22229228}]}]}
{"op":"mcm","clk":"998516174","pt":1580587621830,"mc":[{"id":"1.168081817","rc":[{"batb":[[2,1.44,212.25]],"ltp":1.51,"tv":2826.84,"id":22229228}]}]}
{"op":"mcm","clk":"998516431","pt":1580587623548,"mc":[{"id":"1.168081817","rc":[{"batl":[[0,1.57,3]],"ltp":1.51,"tv":2826.84,"id":22229228}]}]}
{"op":"mcm","clk":"998518134","pt":1580587634860,"mc":[{"id":"1.168081817","rc":[{"batb":[[2,2.68,80.27]],"ltp":2.62,"tv":628.29,"id":15256065}]}]}
{"op":"mcm","clk":"998545932","pt":1580587812068,"mc":[{"id":"1.168081817","rc":[{"trd":[[1.51,428.5]],"batb":[[0,1.51,873.98],[2,1.44,215.12]],"ltp":1.51,"tv":3062.1,"id":22229228}],"tv":3690.4}]}
{"op":"mcm","clk":"998549707","pt":1580587835677,"mc":[{"id":"1.168081817","rc":[{"trd":[[1.51,764.58]],"batb":[[0,1.51,705.94]],"ltp":1.51,"tv":3398.18,"id":22229228}],"tv":4026.48}]}
{"op":"mcm","clk":"998551952","pt":1580587849155,"mc":[{"id":"1.168081817","rc":[{"trd":[[1.51,932.62]],"batb":[[0,1.51,621.92]],"ltp":1.51,"tv":3566.22,"id":22229228}],"tv":4194.52}]}
{"op":"mcm","clk":"998584585","pt":1580588067398,"mc":[{"id":"1.168081817","rc":[{"batl":[[0,1.54,7.57],[1,1.57,3],[2,1.6,50]],"ltp":1.51,"tv":3566.22,"id":22229228}]}]}
{"op":"mcm","clk":"998593606","pt":1580588121979,"mc":[{"id":"1.168081817","rc":[{"batl":[[0,1.53,7.57],[1,1.54,7.57],[2,1.57,3]],"ltp":1.51,"tv":3566.22,"id":22229228}]}]}
{"op":"mcm","clk":"998614178","pt":1580588254192,"mc":[{"id":"1.168081817","rc":[{"trd":[[1.53,121.02],[1.54,5]],"batl":[[0,1.54,5.07],[1,1.57,3],[2,1.6,50]],"ltp":1.54,"tv":3586.36,"id":22229228}],"tv":4214.66}]}
{"op":"mcm","clk":"998634862","pt":1580588390391,"mc":[{"id":"1.168081817","rc":[{"batl":[[0,1.54,12.65]],"ltp":1.54,"tv":3586.36,"id":22229228}]}]}
{"op":"mcm","clk":"998666916","pt":1580588599316,"mc":[{"id":"1.168081817","rc":[{"trd":[[1.54,30.28]],"batb":[[0,1.54,35.36],[1,1.51,621.92],[2,1.47,57.33]],"batl":[[0,1.57,3],[1,1.6,50],[2,1.62,333]],"ltp":1.54,"tv":3611.65,"id":22229228}],"tv":4239.94}]}
{"op":"mcm","clk":"998667098","pt":1580588600621,"mc":[{"id":"1.168081817","rc":[{"batl":[[0,95,15.9],[1,990,2.2],[2,1000,0.02]],"ltp":2.62,"tv":628.29,"id":15256065}]}]}
{"op":"mcm","clk":"998667538","pt":1580588603793,"mc":[{"id":"1.168081817","rc":[{"batb":[[1,2.68,80.27],[2,2.62,8.34]],"ltp":2.62,"tv":628.29,"id":15256065}]}]}
{"op":"mcm","clk":"998668092","pt":1580588607511,"mc":[{"id":"1.168081817","rc":[{"batb":[[0,2.7,26.34]],"ltp":2.62,"tv":628.29,"id":15256065},{"trd":[[1.54,71.17]],"batb":[[0,1.54,14.92],[1,1.52,20.67],[2,1.51,621.92]],"ltp":1.54,"tv":3652.53,"id":22229228}],"tv":4280.82}]}
{"op":"mcm","clk":"998668139","pt":1580588607803,"mc":[{"id":"1.168081817","rc":[{"batl":[[0,2.96,8.4],[1,95,15.9],[2,990,2.2]],"ltp":2.62,"tv":628.29,"id":15256065}]}]}
{"op":"mcm","clk":"998668342","pt":1580588609090,"mc":[{"id":"1.168081817","rc":[{"batb":[[0,2.8,17.97],[1,2.7,26.34],[2,2.68,80.27]],"ltp":2.62,"tv":628.29,"id":15256065},{"batl":[[1,1.59,23.42],[2,1.6,50]],"ltp":1.54,"tv":3652.53,"id":22229228}]}]}
{"op":"mcm","clk":"998668568","pt":1580588610590,"mc":[{"id":"1.168081817","rc":[{"batl":[[1,1.59,14.02]],"ltp":1.54,"tv":3652.53,"id":22229228}]}]}
{"op":"mcm","clk":"998674301","pt":1580588649017,"mc":[{"id":"1.168081817","rc":[{"batl":[[0,1.55,7.57],[1,1.57,3],[2,1.59,14.02]],"ltp":1.54,"tv":3652.53,"id":22229228}]}]}
{"op":"mcm","clk":"998697480","pt":1580588819092,"mc":[{"id":"1.168081817","rc":[{"trd":[[2.8,39.97]],"batb":[[0,2.7,26.34],[1,2.68,80.27],[2,2.62,8.34]],"ltp":2.8,"tv":668.26,"id":15256065},{"trd":[[1.55,18.55]],"batl":[[0,1.57,3.3],[1,1.59,14.02],[2,1.6,50]],"ltp":1.55,"tv":3659.81,"id":22229228}],"tv":4328.07}]}
{"op":"mcm","clk":"998697659","pt":1580588820432,"mc":[{"id":"1.168081817","rc":[{"batl":[[1,1.59,23.82]],"ltp":1.55,"tv":3659.81,"id":22229228}]}]}
{"op":"mcm","clk":"998698176","pt":1580588824640,"mc":[{"id":"1.168081817","rc":[{"batb":[[2,2.64,19.72]],"ltp":2.8,"tv":668.26,"id":15256065}]}]}
{"op":"mcm","clk":"998711551","pt":1580588941681,"mc":[{"id":"1.168081817","rc":[{"batb":[[0,2.72,30.29],[1,2.7,26.34],[2,2.68,80.27]],"ltp":2.8,"tv":668.26,"id":15256065}]}]}
{"op":"mcm","clk":"998717234","pt":1580588985945,"mc":[{"id":"1.168081817","rc":[{"batl":[[0,1.57,7.08]],"ltp":1.55,"tv":3659.81,"id":22229228}]}]}
{"op":"mcm","clk":"998723700","pt":1580589033608,"mc":[{"id":"1.168081817","rc":[{"batb":[[1,2.68,80.27],[2,2.64,19.72]],"ltp":2.8,"tv":668.26,"id":15256065}]}]}
{"op":"mcm","clk":"998723726","pt":1580589033819,"mc":[{"id":"1.168081817","rc":[{"batb":[[0,2.76,15.43],[1,2.72,30.29],[2,2.68,80.27]],"ltp":2.8,"tv":668.26,"id":15256065}]}]}
{"op":"mcm","clk":"998727993","pt":1580589063385,"mc":[{"id":"1.168081817","rc":[{"batb":[[1,2.68,80.27],[2,2.64,19.72]],"ltp":2.8,"tv":668.26,"id":15256065}]}]}
{"op":"mcm","clk":"998728133","pt":1580589064399,"mc":[{"id":"1.168081817","rc":[{"batl":[[1,1.59,14.02]],"ltp":1.55,"tv":3659.81,"id":22229228}]}]}
{"op":"mcm","clk":"998750233","pt":1580589234044,"mc":[{"id":"1.168081817","rc":[{"trd":[[1.54,99.73]],"batb":[[0,1.52,21.31],[1,1.51,621.92],[2,1.45,141.6]],"ltp":1.54,"tv":3688.37,"id":22229228}],"tv":4356.64}]}
{"op":"mcm","clk":"998777073","pt":1580589438159,"mc":[{"id":"1.168081817","rc":[{"batb":[[1,1.51,701.38]],"ltp":1.54,"tv":3688.37,"id":22229228}]}]}
{"op":"mcm","clk":"998778772","pt":1580589450554,"mc":[{"id":"1.168081817","rc":[{"trd":[[2.76,3.68],[2.8,40.13]],"batb":[[0,2.76,13.59]],"ltp":2.76,"tv":672.1,"id":15256065},{"trd":[[1.55,18.84]],"batl":[[0,1.57,6.79]],"ltp":1.55,"tv":3688.66,"id":22229228}],"tv":4360.77}]}
{"op":"mcm","clk":"998778854","pt":1580589451148,"mc":[{"id":"1.168081817","rc":[{"batb":[[0,1.52,24.63]],"ltp":1.55,"tv":3688.66,"id":22229228}]}]}
{"op":"mcm","clk":"998872412","pt":1580590159976,"mc":[{"id":"1.168081817","rc":[{"batl":[[0,1.56,5.07],[1,1.57,6.79],[2,1.59,14.02]],"ltp":1.55,"tv":3688.66,"id":22229228}]}]}
{"op":"mcm","clk":"998907394","pt":1580590431034,"mc":[{"id":"1.168081817","rc":[{"trd":[[1.56,10.14]],"batb":[[0,1.56,14.55],[1,1.52,24.63],[2,1.51,701.38]],"batl":[[0,1.57,6.79],[1,1.59,14.02],[2,1.6,50]],"ltp":1.56,"tv":3698.8,"id":22229228}],"tv":4370.91}]}
{"op":"mcm","clk":"998907567","pt":1580590432541,"mc":[{"id":"1.168081817","rc":[{"batl":[[0,95,15.9],[1,990,2.2],[2,1000,0.02]],"ltp":2.76,"tv":672.1,"id":15256065}]}]}
{"op":"mcm","clk":"998907593","pt":1580590432749,"mc":[{"id":"1.168081817","rc":[{"batb":[[2,2.62,8.34]],"ltp":2.76,"tv":672.1,"id":15256065}]}]}
{"op":"mcm","clk":"998920856","pt":1580590549568,"mc":[{"id":"1.168081817","rc":[{"batl":[[0,2.96,8.4],[1,95,15.9],[2,990,2.2]],"ltp":2.76,"tv":672.1,"id":15256065},{"trd":[[1.56,16.19]],"batb":[[0,1.56,11.52]],"ltp":1.56,"tv":3704.86,"id":22229228}],"tv":4376.96}]}
{"op":"mcm","clk":"998921555","pt":1580590555698,"mc":[{"id":"1.168081817","rc":[{"batb":[[0,2.68,80.27],[1,2.62,8.34],[2,2.42,390.84]],"ltp":2.76,"tv":672.1,"id":15256065},{"trd":[[1.56,39.23]],"batb":[[0,1.52,24.63],[1,1.51,701.38],[2,1.45,141.6]],"ltp":1.56,"tv":3727.9,"id":22229228}],"tv":4400.0}]}
{"op":"mcm","clk":"998921571","pt":1580590555799,"mc":[{"id":"1.168081817","rc":[{"batb":[[0,2.7,18],[1,2.68,80.27],[2,2.62,8.34]],"ltp":2.76,"tv":672.1,"id":15256065},{"batb":[[0,1.52,36.34]],"ltp":1.56,"tv":3727.9,"id":22229228}]}]}
{"op":"mcm","clk":"998921740","pt":1580590556709,"mc":[{"id":"1.168081817","rc":[{"batl":[[1,1.59,23.54]],"ltp":1.56,"tv":3727.9,"id":22229228}]}]}
{"op":"mcm","clk":"998921946","pt":1580590558504,"mc":[{"id":"1.168081817","rc":[{"batb":[[2,2.64,19.72]],"ltp":2.76,"tv":672.1,"id":15256065}]}]}
{"op":"mcm","clk":"998931985","pt":1580590645545,"mc":[{"id":"1.168081817","rc":[{"batb":[[0,2.72,30.29],[1,2.7,18],[2,2.68,80.27]],"ltp":2.76,"tv":672.1,"id":15256065}]}]}
{"op":"mcm","clk":"998937996","pt":1580590695695,"mc":[{"id":"1.168081817","rc":[{"batb":[[1,2.68,80.27],[2,2.64,19.72]],"ltp":2.76,"tv":672.1,"id":15256065}]}]}
{"op":"mcm","clk":"998938009","pt":1580590695792,"mc":[{"id":"1.168081817","rc":[{"batb":[[0,2.74,10.7],[1,2.72,30.29],[2,2.68,80.27]],"ltp":2.76,"tv":672.1,"id":15256065}]}]}
{"op":"mcm","clk":"998945225","pt":1580590767436,"mc":[{"id":"1.168081817","rc":[{"batb":[[1,2.68,80.27],[2,2.64,19.72]],"ltp":2.76,"tv":672.1,"id":15256065}]}]}
{"op":"mcm","clk":"998945267","pt":1580590767951,"mc":[{"id":"1.168081817","rc":[{"batb":[[1,2.7,30.28],[2,2.68,80.27]],"ltp":2.76,"tv":672.1,"id":15256065}]}]}
{"op":"mcm","clk":"998950110","pt":1580590814654,"mc":[{"id":"1.168081817","rc":[{"batb":[[0,2.72,19.78]],"ltp":2.76,"tv":672.1,"id":15256065},{"trd":[[1.52,91.57],[1.54,101.01]],"batb":[[0,1.52,25.74]],"ltp":1.52,"tv":3749.1,"id":22229228}],"tv":4421.2}]}
{"op":"mcm","clk":"998957987","pt":1580590889123,"mc":[{"id":"1.168081817","rc":[{"batb":[[1,2.68,80.27],[2,2.64,19.72]],"ltp":2.76,"tv":672.1,"id":15256065}]}]}
{"op":"mcm","clk":"998967868","pt":1580590981150,"mc":[{"id":"1.168081817","rc":[{"batb":[[0,2.7,23.48]],"ltp":2.76,"tv":672.1,"id":15256065}]}]}
{"op":"mcm","clk":"998971261","pt":1580591010556,"mc":[{"id":"1.168081817","rc":[{"batb":[[0,2.72,30.29],[1,2.7,23.48],[2,2.68,80.27]],"ltp":2.76,"tv":672.1,"id":15256065}]}]}
{"op":"mcm","clk":"998983272","pt":1580591123656,"mc":[{"id":"1.168081817","rc":[{"batb":[[0,2.74,16.15],[1,2.72,30.29]],"ltp":2.76,"tv":672.1,"id":15256065}]}]}
{"op":"mcm","clk":"998984354","pt":1580591132196,"mc":[{"id":"1.168081817","rc":[{"batb":[[1,2.68,80.27],[2,2.64,19.72]],"ltp":2.76,"tv":672.1,"id":15256065}]}]}
{"op":"mcm","clk":"998998593","pt":1580591262594,"mc":[{"id":"1.168081817","rc":[{"batb":[[0,2.7,23.48]],"ltp":2.76,"tv":672.1,"id":15256065}]}]}
{"op":"mcm","clk":"999012036","pt":1580591375607,"mc":[{"id":"1.168081817","rc":[{"batb":[[0,2.72,30.29],[1,2.7,23.48],[2,2.68,80.27]],"ltp":2.76,"tv":672.1,"id":15256065}]}]}
{"op":"mcm","clk":"999015144","pt":1580591401668,"mc":[{"id":"1.168081817","rc":[{"trd":[[2.72,146.18]],"batb":[[0,2.74,452.52],[1,2.72,18.98],[2,2.7,23.48]],"ltp":2.72,"tv":683.41,"id":15256065},{"trd":[[1.57,101.52],[1.59,464.67]],"batl":[[0,1.6,50],[1,1.62,333],[2,1.65,91.9]],"ltp":1.59,"tv":3829.1,"id":22229228}],"tv":4512.52}]}
{"op":"mcm","clk":"999015277","pt":1580591402879,"mc":[{"id":"1.168081817","rc":[{"batb":[[0,1.52,46.5]],"ltp":1.59,"tv":3829.1,"id":22229228}]}]}
{"op":"mcm","clk":"999015567","pt":1580591405578,"mc":[{"id":"1.168081817","rc":[{"batb":[[0,2.76,12.6],[2,2.68,80.27]],"ltp":2.72,"tv":683.41,"id":15256065}]}]}
{"op":"mcm","clk":"999026523","pt":1580591497298,"mc":[{"id":"1.168081817","rc":[{"batb":[[0,1.53,20.11],[1,1.52,46.5],[2,1.51,701.38]],"ltp":1.59,"tv":3829.1,"id":22229228}]}]}
{"op":"mcm","clk":"999026667","pt":1580591498356,"mc":[{"id":"1.168081817","rc":[{"batb":[[1,2.7,30.28]],"ltp":2.72,"tv":683.41,"id":15256065}]}]}
{"op":"mcm","clk":"999032929","pt":1580591547513,"mc":[{"id":"1.168081817","rc":[{"batb":[[0,2.72,19.78]],"ltp":2.72,"tv":683.41,"id":15256065}]}]}
{"op":"mcm","clk":"999032969","pt":1580591547832,"mc":[{"id":"1.168081817","rc":[{"batb":[[0,2.72,475.62]],"ltp":2.72,"tv":683.41,"id":15256065}]}]}
{"op":"mcm","clk":"999042237","pt":1580591619535,"mc":[{"id":"1.168081817","rc":[{"batb":[[1,2.68,80.27],[2,2.62,8.34]],"ltp":2.72,"tv":683.41,"id":15256065}]}]}
{"op":"mcm","clk":"999053740","pt":1580591707514,"mc":[{"id":"1.168081817","rc":[{"trd":[[2.72,156.18]],"batb":[[0,2.72,470.62]],"ltp":2.72,"tv":693.41,"id":15256065},{"batb":[[0,1.53,29.07]],"ltp":1.59,"tv":3829.1,"id":22229228}],"tv":4522.52}]}
{"op":"mcm","clk":"999057934","pt":1580591740622,"mc":[{"id":"1.168081817","rc":[{"batb":[[0,1.53,8.96]],"ltp":1.59,"tv":3829.1,"id":22229228}]}]}
{"op":"mcm","clk":"999057999","pt":1580591741143,"mc":[{"id":"1.168081817","rc":[{"batb":[[0,1.54,19.98],[1,1.53,8.96],[2,1.52,46.5]],"ltp":1.59,"tv":3829.1,"id":22229228}]}]}
{"op":"mcm","clk":"999058181","pt":1580591742533,"mc":[{"id":"1.168081817","rc":[{"batl":[[0,95,15.9],[1,990,2.2],[2,1000,0.02]],"ltp":2.72,"tv":693.41,"id":15256065}]}]}
{"op":"mcm","clk":"999130635","pt":1580592326300,"mc":[{"id":"1.168081817","rc":[{"batl":[[0,1.58,20],[1,1.6,50],[2,1.62,333]],"ltp":1.59,"tv":3829.1,"id":22229228}]}]}
{"op":"mcm","clk":"999181650","pt":1580592740661,"mc":[{"id":"1.168081817","rc":[{"batb":[[0,2.72,14.78]],"ltp":2.72,"tv":693.41,"id":15256065},{"batl":[[0,1.58,804.99]],"ltp":1.59,"tv":3829.1,"id":22229228}]}]}
{"op":"mcm","clk":"999181902","pt":1580592742567,"mc":[{"id":"1.168081817","rc":[{"batb":[[2,2.64,19.72]],"ltp":2.72,"tv":693.41,"id":15256065}]}]}
{"op":"mcm","clk":"999203932","pt":1580592932039,"mc":[{"id":"1.168081817","rc":[{"batl":[[2,1.62,351.93]],"ltp":1.59,"tv":3829.1,"id":22229228}]}]}
{"op":"mcm","clk":"999227546","pt":1580593149354,"mc":[{"id":"1.168081817","rc":[{"trd":[[1.58,938.43]],"batl":[[0,1.58,789.99]],"ltp":1.58,"tv":3859.1,"id":22229228}],"tv":4552.52}]}
{"op":"mcm","clk":"999262486","pt":1580593453369,"mc":[{"id":"1.168081817","rc":[{"batl":[[2,1.62,333]],"ltp":1.58,"tv":3859.1,"id":22229228}]}]}
{"op":"mcm","clk":"999262730","pt":1580593455587,"mc":[{"id":"1.168081817","rc":[{"trd":[[1.58,1134.59]],"batl":[[0,1.58,784.99]],"ltp":1.58,"tv":4055.26,"id":22229228}],"tv":4748.68}]}
{"op":"mcm","clk":"999264831","pt":1580593476685,"mc":[{"id":"1.168081817","rc":[{"batl":[[1,1.6,257.59]],"ltp":1.58,"tv":4055.26,"id":22229228}]}]}
{"op":"mcm","clk":"999288825","pt":1580593699185,"mc":[{"id":"1.168081817","rc":[{"trd":[[1.58,1330.75]],"batl":[[0,1.6,257.59],[1,1.62,333],[2,1.65,91.9]],"ltp":1.58,"tv":4251.42,"id":22229228}],"tv":4944.84}]}
{"op":"mcm","clk":"999288906","pt":1580593699960,"mc":[{"id":"1.168081817","rc":[{"batl":[[0,1.58,784.99],[1,1.6,257.59],[2,1.62,333]],"ltp":1.58,"tv":4251.42,"id":22229228}]}]}
{"op":"mcm","clk":"999311207","pt":1580593934611,"mc":[{"id":"1.168081817","rc":[{"trd":[[1.58,1526.91]],"ltp":1.58,"tv":4447.58,"id":22229228}],"tv":5141.0}]}
{"op":"mcm","clk":"999356002","pt":1580594357312,"mc":[{"id":"1.168081817","rc":[{"trd":[[1.58,1723.07]],"batl":[[0,1.6,257.59],[1,1.62,333],[2,1.65,91.9]],"ltp":1.58,"tv":4643.74,"id":22229228}],"tv":5337.16}]}
{"op":"mcm","clk":"999356181","pt":1580594358622,"mc":[{"id":"1.168081817","rc":[{"batb":[[1,2.7,30.28],[2,2.68,80.27]],"ltp":2.72,"tv":693.41,"id":15256065},{"batl":[[0,1.58,784.99],[1,1.6,257.59],[2,1.62,333]],"ltp":1.58,"tv":4643.74,"id":22229228}]}]}
{"op":"mcm","clk":"999362182","pt":1580594419518,"mc":[{"id":"1.168081817","rc":[{"batb":[[1,2.68,80.27],[2,2.64,19.72]],"ltp":2.72,"tv":693.41,"id":15256065}]}]}
{"op":"mcm","clk":"999371004","pt":1580594516576,"mc":[{"id":"1.168081817","rc":[{"trd":[[1.58,1874.51]],"batl":[[0,1.6,257.59],[1,1.62,333],[2,1.65,91.9]],"ltp":1.58,"tv":4795.19,"id":22229228}],"tv":5488.6}]}
{"op":"mcm","clk":"999371049","pt":1580594517054,"mc":[{"id":"1.168081817","rc":[{"batl":[[0,1.58,784.99],[1,1.6,257.59],[2,1.62,333]],"ltp":1.58,"tv":4795.19,"id":22229228}]}]}
{"op":"mcm","clk":"999373191","pt":1580594544685,"mc":[{"id":"1.168081817","rc":[{"batl":[[1,1.6,590.59],[2,1.65,91.9]],"ltp":1.58,"tv":4795.19,"id":22229228}]}]}
{"op":"mcm","clk":"999373566","pt":1580594549613,"mc":[{"id":"1.168081817","rc":[{"batl":[[0,1.6,590.59],[1,1.65,91.9],[2,1.76,16.8]],"ltp":1.58,"tv":4795.19,"id":22229228}]}]}
{"op":"mcm","clk":"999373585","pt":1580594549772,"mc":[{"id":"1.168081817","rc":[{"batl":[[0,1.58,1041.75],[1,1.6,590.59],[2,1.65,91.9]],"ltp":1.58,"tv":4795.19,"id":22229228}]}]}
{"op":"mcm","clk":"999378224","pt":1580594613203,"mc":[{"id":"1.168081817","rc":[{"batb":[[0,2.74,32.14],[1,2.72,14.78],[2,2.68,80.27]],"ltp":2.72,"tv":693.41,"id":15256065},{"batl":[[0,1.57,56.09],[1,1.58,1041.75],[2,1.6,590.59]],"ltp":1.58,"tv":4795.19,"id":22229228}]}]}
{"op":"mcm","clk":"999388149","pt":1580594740507,"mc":[{"id":"1.168081817","rc":[{"batb":[[0,2.76,7.73],[1,2.74,32.14],[2,2.7,32.61]],"ltp":2.72,"tv":693.41,"id":15256065},{"batl":[[0,1.59,55.38],[1,1.6,590.59],[2,1.65,91.9]],"ltp":1.58,"tv":4795.19,"id":22229228}]}]}
{"op":"mcm","clk":"999399117","pt":1580594865611,"mc":[{"id":"1.168081817","rc":[{"trd":[[2.74,134.63],[2.76,11.41]],"batb":[[0,2.68,80.27],[1,2.64,19.72],[2,2.62,8.34]],"ltp":2.74,"tv":733.28,"id":15256065},{"trd":[[1.57,2182.17],[1.58,1935.91]],"batb":[[0,1.58,62.94],[1,1.57,2.88],[2,1.54,19.98]],"batl":[[0,1.6,590.59],[1,1.65,91.9],[2,1.76,16.8]],"ltp":1.57,"tv":6937.24,"id":22229228}],"tv":7670.52}]}
{"op":"mcm","clk":"999399188","pt":1580594866395,"mc":[{"id":"1.168081817","rc":[{"batb":[[0,2.7,43.97],[1,2.66,80.27],[2,2.64,19.72]],"ltp":2.74,"tv":733.28,"id":15256065},{"trd":[[1.57,2187.93]],"batb":[[0,1.56,1.5],[1,1.54,19.98],[2,1.53,22.8]],"batl":[[0,1.59,56.38],[1,1.6,590.59],[2,1.65,91.9]],"ltp":1.57,"tv":6942.99,"id":22229228}],"tv":7676.28}]}
{"op":"mcm","clk":"999399356","pt":1580594868545,"mc":[{"id":"1.168081817","rc":[{"trd":[[1.59,470.4]],"batl":[[0,1.59,53.52]],"ltp":1.59,"tv":6948.72,"id":22229228}],"tv":7682.0}]}
{"op":"mcm","clk":"999399436","pt":1580594869417,"mc":[{"id":"1.168081817","rc":[{"batb":[[1,2.64,19.72],[2,2.62,8.34]],"ltp":2.74,"tv":733.28,"id":15256065}]}]}
{"op":"mcm","clk":"999400027","pt":1580594875451,"mc":[{"id":"1.168081817","rc":[{"batb":[[1,2.64,97.71]],"ltp":2.74,"tv":733.28,"id":15256065}]}]}
{"op":"mcm","clk":"999402687","pt":1580594906241,"mc":[{"id":"1.168081817","rc":[{"batb":[[0,2.72,30.29],[1,2.7,43.97],[2,2.64,97.71]],"ltp":2.74,"tv":733.28,"id":15256065}]}]}
{"op":"mcm","clk":"999407966","pt":1580594967833,"mc":[{"id":"1.168081817","rc":[{"batb":[[0,2.7,43.97],[1,2.64,97.71],[2,2.62,8.34]],"ltp":2.74,"tv":733.28,"id":15256065}]}]}
{"op":"mcm","clk":"999408103","pt":1580594969446,"mc":[{"id":"1.168081817","rc":[{"batl":[[0,1.57,14],[1,1.59,53.52],[2,1.6,590.59]],"ltp":1.59,"tv":6948.72,"id":22229228}]}]}
{"op":"mcm","clk":"999412214","pt":1580595017402,"mc":[{"id":"1.168081817","rc":[{"batb":[[0,2.7,63],[1,2.64,77.99]],"ltp":2.74,"tv":733.28,"id":15256065}]}]}
{"op":"mcm","clk":"999451898","pt":1580595494461,"mc":[{"id":"1.168081817","rc":[{"trd":[[1.54,102.01],[1.56,42.24]],"batb":[[0,1.54,19.48],[1,1.53,22.8],[2,1.52,46.5]],"ltp":1.54,"tv":6952.72,"id":22229228}],"tv":7686.01}]}
{"op":"mcm","clk":"999451950","pt":1580595495195,"mc":[{"id":"1.168081817","rc":[{"batl":[[0,1.57,15.5]],"ltp":1.54,"tv":6952.72,"id":22229228}]}]}
{"op":"mcm","clk":"999454842","pt":1580595535474,"mc":[{"id":"1.168081817","rc":[{"trd":[[1.57,2218.93]],"batb":[[0,1.57,4.63],[1,1.54,19.48],[2,1.53,22.8]],"batl":[[0,1.59,53.52],[1,1.6,590.59],[2,1.65,91.9]],"ltp":1.57,"tv":6983.72,"id":22229228}],"tv":7717.0}]}
{"op":"mcm","clk":"999454934","pt":1580595536683,"mc":[{"id":"1.168081817","rc":[{"batb":[[1,1.56,1.5],[2,1.54,19.48]],"ltp":1.57,"tv":6983.72,"id":22229228}]}]}
{"op":"mcm","clk":"999475671","pt":1580595820887,"mc":[{"id":"1.168081817","rc":[{"trd":[[2.76,14.04]],"batb":[[0,2.76,42.37],[1,2.7,63],[2,2.64,77.99]],"ltp":2.76,"tv":735.91,"id":15256065},{"trd":[[1.57,2223.56]],"batb":[[0,1.56,1.5],[1,1.54,19.48],[2,1.53,22.8]],"ltp":1.57,"tv":6988.35,"id":22229228}],"tv":7724.26}]}
{"op":"mcm","clk":"999476405","pt":1580595830130,"mc":[{"id":"1.168081817","rc":[{"batb":[[0,2.76,74.89]],"ltp":2.76,"tv":735.91,"id":15256065},{"batl":[[0,1.57,75.98],[1,1.59,53.52],[2,1.6,590.59]],"ltp":1.57,"tv":6988.35,"id":22229228}]}]}
{"op":"mcm","clk":"999481256","pt":1580595896519,"mc":[{"id":"1.168081817","rc":[{"trd":[[1.52,156.05],[1.53,166.6],[1.54,140.96],[1.56,45.25]],"batb":[[0,1.52,14.25],[1,1.51,701.38],[2,1.48,67.4]],"batl":[[0,1.59,53.52],[1,1.6,590.59],[2,1.65,91.9]],"ltp":1.52,"tv":7140.37,"id":22229228}],"tv":7876.28}]}
{"op":"mcm","clk":"999481368","pt":1580595897614,"mc":[{"id":"1.168081817","rc":[{"batb":[[0,2.78,51.47],[1,2.76,74.89],[2,2.7,52.23]],"ltp":2.76,"tv":735.91,"id":15256065},{"batb":[[0,1.53,1.94],[1,1.52,67.57],[2,1.51,701.38]],"ltp":1.52,"tv":7140.37,"id":22229228}]}]}
{"op":"mcm","clk":"999481406","pt":1580595898080,"mc":[{"id":"1.168081817","rc":[{"batl":[[0,2.96,37.91],[1,95,15.9],[2,990,2.2]],"ltp":2.76,"tv":735.91,"id":15256065},{"batl":[[0,1.57,54.45],[1,1.58,1.5],[2,1.59,53.52]],"ltp":1.52,"tv":7140.37,"id":22229228}]}]}
{"op":"mcm","clk":"999501765","pt":1580596154391,"mc":[{"id":"1.168081817","rc":[{"batb":[[0,1.53,26.77]],"ltp":1.52,"tv":7140.37,"id":22229228}]}]}
{"op":"mcm","clk":"999508254","pt":1580596237968,"mc":[{"id":"1.168081817","rc":[{"batl":[[0,2.86,2.39],[1,2.96,37.91],[2,95,15.9]],"ltp":2.76,"tv":735.91,"id":15256065}]}]}
{"op":"mcm","clk":"999515491","pt":1580596349616,"mc":[{"id":"1.168081817","rc":[{"batb":[[0,1.55,510],[1,1.53,26.77],[2,1.52,67.57]],"ltp":1.52,"tv":7140.37,"id":22229228}]}]}
{"op":"mcm","clk":"999515537","pt":1580596350135,"mc":[{"id":"1.168081817","rc":[{"batb":[[0,2.78,20.72],[1,2.76,42.37],[2,2.7,33.2]],"batl":[[0,2.84,36.99],[1,2.86,2.39],[2,2.96,37.91]],"ltp":2.76,"tv":735.91,"id":15256065},{"batb":[[0,1.56,67.35],[1,1.55,510],[2,1.53,26.77]],"batl":[[0,1.58,56.73],[1,1.59,53.52],[2,1.6,590.59]],"ltp":1.52,"tv":7140.37,"id":22229228}]}]}
{"op":"mcm","clk":"999515682","pt":1580596352156,"mc":[{"id":"1.168081817","rc":[{"trd":[[2.8,50.05]],"batl":[[0,2.8,39.59],[1,2.84,36.99],[2,2.86,2.39]],"ltp":2.8,"tv":745.83,"id":15256065},{"batb":[[0,1.56,70.71]],"ltp":1.52,"tv":7140.37,"id":22229228}],"tv":7886.2}]}
{"op":"mcm","clk":"999515908","pt":1580596355636,"mc":[{"id":"1.168081817","rc":[{"batb":[[0,2.76,42.37],[1,2.74,8.13]],"ltp":2.8,"tv":745.83,"id":15256065},{"trd":[[1.56,115.72]],"batb":[[0,1.56,35.47],[2,1.54,19.4]],"ltp":1.56,"tv":7210.84,"id":22229228}],"tv":7956.68}]}
{"op":"mcm","clk":"999515977","pt":1580596356426,"mc":[{"id":"1.168081817","rc":[{"batb":[[0,1.56,52.78]],"ltp":1.56,"tv":7210.84,"id":22229228}]}]}
{"op":"mcm","clk":"999520126","pt":1580596417770,"mc":[{"id":"1.168081817","rc":[{"batb":[[1,1.55,503.29]],"ltp":1.56,"tv":7210.84,"id":22229228}]}]}
{"op":"mcm","clk":"999520483","pt":1580596422510,"mc":[{"id":"1.168081817","rc":[{"trd":[[2.76,81.63]],"batb":[[0,2.74,8.13],[1,2.7,33.2],[2,2.64,77.99]],"batl":[[0,2.8,3.44]],"ltp":2.76,"tv":813.42,"id":15256065},{"trd":[[1.57,2342.38]],"batb":[[0,1.57,384.47],[1,1.56,20.67]],"batl":[[0,1.58,1.5]],"ltp":1.57,"tv":7329.66,"id":22229228}],"tv":8143.09}]}
{"op":"mcm","clk":"999520529","pt":1580596422985,"mc":[{"id":"1.168081817","rc":[{"batl":[[0,2.84,36.99],[1,2.86,2.39],[2,2.96,29.51]],"ltp":2.76,"tv":813.42,"id":15256065},{"batb":[[1,1.56,3.36]],"ltp":1.57,"tv":7329.66,"id":22229228}]}]}
{"op":"mcm","clk":"999520619","pt":1580596424189,"mc":[{"id":"1.168081817","rc":[{"batb":[[2,2.68,5.18]],"ltp":2.76,"tv":813.42,"id":15256065}]}]}
{"op":"mcm","clk":"999525679","pt":1580596489628,"mc":[{"id":"1.168081817","rc":[{"batb":[[0,2.7,33.2],[1,2.68,5.18],[2,2.64,77.99]],"ltp":2.76,"tv":813.42,"id":15256065},{"trd":[[1.57,2362]],"batb":[[0,1.57,374.66]],"ltp":1.57,"tv":7349.29,"id":22229228}],"tv":8162.71}]}
{"op":"mcm","clk":"999525731","pt":1580596490537,"mc":[{"id":"1.168081817","rc":[{"batb":[[0,2.7,42.97]],"ltp":2.76,"tv":813.42,"id":15256065},{"trd":[[1.58,1938.9]],"batb":[[0,1.58,1.82],[1,1.57,374.66],[2,1.55,9.93]],"batl":[[0,1.59,53.52],[1,1.6,590.59],[2,1.65,91.9]],"ltp":1.58,"tv":7352.28,"id":22229228}],"tv":8165.7}]}
{"op":"mcm","clk":"999525768","pt":1580596491112,"mc":[{"id":"1.168081817","rc":[{"batb":[[2,1.56,1.5]],"ltp":1.58,"tv":7352.28,"id":22229228}]}]}
{"op":"mcm","clk":"999533954","pt":1580596611197,"mc":[{"id":"1.168081817","rc":[{"trd":[[1.57,2363.29],[1.58,1942.55]],"batb":[[0,1.57,374.01],[1,1.56,1.5],[2,1.55,9.93]],"ltp":1.57,"tv":7357.22,"id":22229228}],"tv":8170.65}]}
{"op":"mcm","clk":"999540345","pt":1580596705489,"mc":[{"id":"1.168081817","rc":[{"batb":[[0,2.7,62]],"ltp":2.76,"tv":813.42,"id":15256065},{"trd":[[1.58,2690.57]],"batb":[[0,1.56,1.5],[1,1.55,9.93],[2,1.54,19.4]],"ltp":1.58,"tv":8105.24,"id":22229228}],"tv":8918.67}]}
{"op":"mcm","clk":"999540473","pt":1580596707260,"mc":[{"id":"1.168081817","rc":[{"batl":[[0,1.58,14.22],[1,1.59,53.52],[2,1.6,590.59]],"ltp":1.58,"tv":8105.24,"id":22229228}]}]}
{"op":"mcm","clk":"999540827","pt":1580596712670,"mc":[{"id":"1.168081817","rc":[{"batb":[[2,2.62,86.33]],"ltp":2.76,"tv":813.42,"id":15256065}]}]}
{"op":"mcm","clk":"999575235","pt":1580597195393,"mc":[{"id":"1.168081817","rc":[{"batl":[[0,1.58,28.45]],"ltp":1.58,"tv":8105.24,"id":22229228}]}]}
{"op":"mcm","clk":"999600633","pt":1580597609232,"mc":[{"id":"1.168081817","rc":[{"trd":[[1.56,118.73]],"batb":[[0,1.55,9.93],[1,1.54,19.4],[2,1.53,26.77]],"batl":[[0,1.56,1.66],[1,1.58,28.45],[2,1.59,53.52]],"ltp":1.56,"tv":8108.25,"id":22229228}],"tv":8921.67}]}
{"op":"mcm","clk":"999600758","pt":1580597611571,"mc":[{"id":"1.168081817","rc":[{"batl":[[1,1.57,1.5],[2,1.58,28.45]],"ltp":1.56,"tv":8108.25,"id":22229228}]}]}
{"op":"mcm","clk":"999622529","pt":1580597972628,"mc":[{"id":"1.168081817","rc":[{"trd":[[1.55,22.17]],"batb":[[0,1.55,8.27]],"batl":[[0,1.57,1.5],[1,1.58,28.45],[2,1.59,53.52]],"ltp":1.55,"tv":8111.58,"id":22229228}],"tv":8925.0}]}
{"op":"mcm","clk":"999622600","pt":1580597974227,"mc":[{"id":"1.168081817","rc":[{"batb":[[0,1.55,16.86]],"ltp":1.55,"tv":8111.58,"id":22229228}]}]}
{"op":"mcm","clk":"999622842","pt":1580597978119,"mc":[{"id":"1.168081817","rc":[{"batb":[[0,1.55,8.27]],"ltp":1.55,"tv":8111.58,"id":22229228}]}]}
{"op":"mcm","clk":"999623854","pt":1580597994741,"mc":[{"id":"1.168081817","rc":[{"batb":[[0,1.55,16.86]],"ltp":1.55,"tv":8111.58,"id":22229228}]}]}
{"op":"mcm","clk":"999623997","pt":1580597996763,"mc":[{"id":"1.168081817","rc":[{"batb":[[0,1.55,8.27]],"ltp":1.55,"tv":8111.58,"id":22229228}]}]}
{"op":"mcm","clk":"999624443","pt":1580598002174,"mc":[{"id":"1.168081817","rc":[{"batb":[[0,1.55,16.86]],"ltp":1.55,"tv":8111.58,"id":22229228}]}]}
{"op":"mcm","clk":"999624566","pt":1580598003561,"mc":[{"id":"1.168081817","rc":[{"batb":[[0,2.7,71.51]],"ltp":2.76,"tv":813.42,"id":15256065},{"batb":[[0,1.55,8.27]],"ltp":1.55,"tv":8111.58,"id":22229228}]}]}
{"op":"mcm","clk":"999624610","pt":1580598004077,"mc":[{"id":"1.168081817","rc":[{"batb":[[0,2.74,26.18],[1,2.72,35.37],[2,2.7,71.51]],"ltp":2.76,"tv":813.42,"id":15256065}]}]}
{"op":"mcm","clk":"999625089","pt":1580598012398,"mc":[{"id":"1.168081817","rc":[{"batb":[[0,1.55,16.86]],"ltp":1.55,"tv":8111.58,"id":22229228}]}]}
{"op":"mcm","clk":"999625195","pt":1580598014523,"mc":[{"id":"1.168081817","rc":[{"batb":[[0,1.55,8.27]],"ltp":1.55,"tv":8111.58,"id":22229228}]}]}
{"op":"mcm","clk":"999628051","pt":1580598060563,"mc":[{"id":"1.168081817","rc":[{"batb":[[0,1.55,16.86]],"ltp":1.55,"tv":8111.58,"id":22229228}]}]}
{"op":"mcm","clk":"999628134","pt":1580598062016,"mc":[{"id":"1.168081817","rc":[{"batb":[[0,1.55,8.27]],"ltp":1.55,"tv":8111.58,"id":22229228}]}]}
{"op":"mcm","clk":"999628902","pt":1580598072948,"mc":[{"id":"1.168081817","rc":[{"batb":[[0,1.55,16.86]],"ltp":1.55,"tv":8111.58,"id":22229228}]}]}
{"op":"mcm","clk":"999629009","pt":1580598074295,"mc":[{"id":"1.168081817","rc":[{"batb":[[0,1.55,8.27]],"ltp":1.55,"tv":8111.58,"id":22229228}]}]}
{"op":"mcm","clk":"999631835","pt":1580598121088,"mc":[{"id":"1.168081817","rc":[{"batb":[[0,1.55,16.86]],"ltp":1.55,"tv":8111.58,"id":22229228}]}]}
{"op":"mcm","clk":"999631917","pt":1580598122440,"mc":[{"id":"1.168081817","rc":[{"batb":[[0,1.55,8.27]],"ltp":1.55,"tv":8111.58,"id":22229228}]}]}
{"op":"mcm","clk":"999634115","pt":1580598155565,"mc":[{"id":"1.168081817","rc":[{"batb":[[0,1.55,16.86]],"ltp":1.55,"tv":8111.58,"id":22229228}]}]}
{"op":"mcm","clk":"999634230","pt":1580598157497,"mc":[{"id":"1.168081817","rc":[{"batb":[[0,1.55,8.27]],"ltp":1.55,"tv":8111.58,"id":22229228}]}]}
{"op":"mcm","clk":"999635251","pt":1580598171515,"mc":[{"id":"1.168081817","rc":[{"batl":[[0,2.86,2.39],[1,2.96,29.51],[2,95,15.9]],"ltp":2.76,"tv":813.42,"id":15256065},{"batl":[[0,1.56,84.02],[1,1.57,1.5],[2,1.58,28.45]],"ltp":1.55,"tv":8111.58,"id":22229228}]}]}
{"op":"mcm","clk":"999635329","pt":1580598172597,"mc":[{"id":"1.168081817","rc":[{"batl":[[2,1.59,53.52]],"ltp":1.55,"tv":8111.58,"id":22229228}]}]}
{"op":"mcm","clk":"999635575","pt":1580598176586,"mc":[{"id":"1.168081817","rc":[{"trd":[[1.55,57.48]],"batb":[[0,1.54,19.4],[1,1.53,26.77],[2,1.51,701.38]],"batl":[[0,1.55,66.37],[1,1.56,84.02],[2,1.57,1.5]],"ltp":1.55,"tv":8146.88,"id":22229228}],"tv":8960.31}]}
{"op":"mcm","clk":"999635659","pt":1580598177520,"mc":[{"id":"1.168081817","rc":[{"batb":[[0,2.8,35.87],[1,2.78,31.12],[2,2.76,9.84]],"ltp":2.76,"tv":813.42,"id":15256065},{"batb":[[0,1.53,26.77],[1,1.52,30.87]],"ltp":1.55,"tv":8146.88,"id":22229228}]}]}
{"op":"mcm","clk":"999635712","pt":1580598177785,"mc":[{"id":"1.168081817","rc":[{"batl":[[1,2.96,37.91]],"ltp":2.76,"tv":813.42,"id":15256065},{"batb":[[1,1.52,39.67]],"ltp":1.55,"tv":8146.88,"id":22229228}]}]}
{"op":"mcm","clk":"999635940","pt":1580598179289,"mc":[{"id":"1.168081817","rc":[{"batb":[[0,1.53,66.95],[1,1.52,49.46]],"batl":[[0,1.55,92.98]],"ltp":1.55,"tv":8146.88,"id":22229228}]}]}
{"op":"mcm","clk":"999636770","pt":1580598189340,"mc":[{"id":"1.168081817","rc":[{"trd":[[2.86,2.39]],"batl":[[0,2.96,37.91],[1,95,15.9],[2,990,2.2]],"ltp":2.86,"tv":815.81,"id":15256065},{"trd":[[1.53,304.97]],"batb":[[0,1.52,49.46],[1,1.51,703.84],[2,1.48,101.1]],"batl":[[0,1.54,1.93],[1,1.55,92.98],[2,1.56,84.02]],"ltp":1.53,"tv":8285.25,"id":22229228}],"tv":9101.07}]}
{"op":"mcm","clk":"999637199","pt":1580598195813,"mc":[{"id":"1.168081817","rc":[{"batl":[[2,1.57,1.5]],"ltp":1.53,"tv":8285.25,"id":22229228}]}]}
{"op":"mcm","clk":"999638285","pt":1580598210054,"mc":[{"id":"1.168081817","rc":[{"batl":[[1,1.55,177]],"ltp":1.53,"tv":8285.25,"id":22229228}]}]}
{"op":"mcm","clk":"999639913","pt":1580598231852,"mc":[{"id":"1.168081817","rc":[{"trd":[[1.54,144.81]],"batb":[[0,1.52,47.53]],"batl":[[0,1.55,177.01],[1,1.57,1.5],[2,1.59,53.52]],"ltp":1.54,"tv":8289.1,"id":22229228}],"tv":9104.92}]}
{"op":"mcm","clk":"999644999","pt":1580598297817,"mc":[{"id":"1.168081817","rc":[{"batb":[[0,2.82,2.5],[1,2.8,38.39],[2,2.78,31.12]],"batl":[[0,2.94,2.4],[1,2.96,40.3],[2,95,15.9]],"ltp":2.86,"tv":815.81,"id":15256065},{"batb":[[0,1.53,5.49],[1,1.52,53.06],[2,1.51,703.84]],"batl":[[0,1.54,5.46],[1,1.55,182.42],[2,1.57,1.5]],"ltp":1.54,"tv":8289.1,"id":22229228}]}]}
{"op":"mcm","clk":"999649756","pt":1580598367674,"mc":[{"id":"1.168081817","rc":[{"trd":[[1.54,155.73]],"batl":[[0,1.55,182.42],[1,1.57,1.5],[2,1.59,53.52]],"ltp":1.54,"tv":8300.02,"id":22229228}],"tv":9115.84}]}
{"op":"mcm","clk":"999649799","pt":1580598368291,"mc":[{"id":"1.168081817","rc":[{"batb":[[1,2.8,45.43]],"batl":[[0,2.9,2.44],[1,2.92,29.83],[2,2.94,24.17]],"ltp":2.86,"tv":815.81,"id":15256065},{"batb":[[0,1.53,62.69],[1,1.52,47.57]],"batl":[[1,1.56,5.39],[2,1.57,1.5]],"ltp":1.54,"tv":8300.02,"id":22229228}]}]}
{"op":"mcm","clk":"999654098","pt":1580598421708,"mc":[{"id":"1.168081817","rc":[{"batl":[[0,1.55,32.04]],"ltp":1.54,"tv":8300.02,"id":22229228}]}]}
{"op":"mcm","clk":"999654228","pt":1580598423260,"mc":[{"id":"1.168081817","rc":[{"batl":[[0,1.55,5.42]],"ltp":1.54,"tv":8300.02,"id":22229228}]}]}
{"op":"mcm","clk":"999654321","pt":1580598424513,"mc":[{"id":"1.168081817","rc":[{"batb":[[1,2.8,40.46]],"ltp":2.86,"tv":815.81,"id":15256065}]}]}
{"op":"mcm","clk":"999689191","pt":1580598858907,"mc":[{"id":"1.168081817","rc":[{"trd":[[2.8,55.05],[2.82,5]],"batb":[[0,2.8,37.96],[1,2.78,31.12],[2,2.76,5.03]],"ltp":2.8,"tv":825.82,"id":15256065}],"tv":9125.84}]}
{"op":"mcm","clk":"999689276","pt":1580598859904,"mc":[{"id":"1.168081817","rc":[{"batb":[[1,2.78,33.67]],"ltp":2.8,"tv":825.82,"id":15256065},{"batb":[[0,1.54,4.6],[1,1.53,62.69],[2,1.52,47.57]],"batl":[[0,1.56,5.39],[1,1.57,6.01],[2,1.59,53.52]],"ltp":1.54,"tv":8300.02,"id":22229228}]}]}
{"op":"mcm","clk":"999693441","pt":1580598915559,"mc":[{"id":"1.168081817","rc":[{"batb":[[0,2.82,2.51],[1,2.8,37.96],[2,2.78,33.67]],"ltp":2.8,"tv":825.82,"id":15256065}]}]}
{"op":"mcm","clk":"999707471","pt":1580599097689,"mc":[{"id":"1.168081817","rc":[{"trd":[[2.78,70.36],[2.8,130.97],[2.82,10.03]],"batb":[[0,2.76,5.03],[1,2.74,26.18],[2,2.72,30.26]],"ltp":2.78,"tv":977.12,"id":15256065},{"trd":[[1.56,124.12]],"batl":[[0,1.57,6.01],[1,1.59,53.52],[2,1.6,590.59]],"ltp":1.56,"tv":8305.4,"id":22229228}],"tv":9282.53}]}
{"op":"mcm","clk":"999707525","pt":1580599098255,"mc":[{"id":"1.168081817","rc":[{"batb":[[0,2.76,11.88],[1,2.74,28.77],[2,2.72,32.86]],"ltp":2.78,"tv":977.12,"id":15256065},{"batb":[[0,1.54,20],[2,1.52,24.12]],"batl":[[0,1.57,1.5],[1,1.58,4.49],[2,1.59,57.98]],"ltp":1.56,"tv":8305.4,"id":22229228}]}]}
{"op":"mcm","clk":"999707631","pt":1580599099468,"mc":[{"id":"1.168081817","rc":[{"batb":[[0,2.76,6.85],[2,2.72,37.97]],"ltp":2.78,"tv":977.12,"id":15256065},{"batl":[[1,1.58,19.11]],"ltp":1.56,"tv":8305.4,"id":22229228}]}]}
{"op":"mcm","clk":"999707665","pt":1580599099987,"mc":[{"id":"1.168081817","rc":[{"batl":[[1,1.58,33.74]],"ltp":1.56,"tv":8305.4,"id":22229228}]}]}
{"op":"mcm","clk":"999708231","pt":1580599107870,"mc":[{"id":"1.168081817","rc":[{"batl":[[0,1.57,6.02]],"ltp":1.56,"tv":8305.4,"id":22229228}]}]}
{"op":"mcm","clk":"999708850","pt":1580599116594,"mc":[{"id":"1.168081817","rc":[{"batb":[[0,1.55,4.58],[1,1.54,20],[2,1.53,62.69]],"ltp":1.56,"tv":8305.4,"id":22229228}]}]}
{"op":"mcm","clk":"999709018","pt":1580599118808,"mc":[{"id":"1.168081817","rc":[{"batb":[[0,2.76,9.42]],"ltp":2.78,"tv":977.12,"id":15256065}]}]}
{"op":"mcm","clk":"999712093","pt":1580599160127,"mc":[{"id":"1.168081817","rc":[{"batl":[[0,1.57,18.02]],"ltp":1.56,"tv":8305.4,"id":22229228}]}]}
{"op":"mcm","clk":"999737043","pt":1580599498659,"mc":[{"id":"1.168081817","rc":[{"trd":[[2.76,100.47]],"batb":[[0,2.74,28.77],[1,2.72,37.97],[2,2.62,38.29]],"batl":[[0,2.76,10.58],[1,2.9,2.44],[2,2.92,29.83]],"ltp":2.76,"tv":995.96,"id":15256065}],"tv":9301.37}]}
{"op":"mcm","clk":"999737126","pt":1580599499672,"mc":[{"id":"1.168081817","rc":[{"trd":[[2.76,121.63]],"batb":[[0,2.74,26.18],[2,2.7,10.75]],"batl":[[0,2.9,2.44],[1,2.92,29.83],[2,2.94,24.17]],"ltp":2.76,"tv":1017.12,"id":15256065},{"batb":[[1,1.54,32.19]],"batl":[[0,1.57,13.5]],"ltp":1.56,"tv":8305.4,"id":22229228}],"tv":9322.53}]}
{"op":"mcm","clk":"999737135","pt":1580599499755,"mc":[{"id":"1.168081817","rc":[{"batb":[[2,2.7,13.38]],"ltp":2.76,"tv":1017.12,"id":15256065}]}]}
{"op":"mcm","clk":"999743485","pt":1580599594327,"mc":[{"id":"1.168081817","rc":[{"batb":[[0,2.74,28.78]],"ltp":2.76,"tv":1017.12,"id":15256065}]}]}
{"op":"mcm","clk":"999743612","pt":1580599596328,"mc":[{"id":"1.168081817","rc":[{"batl":[[0,1.57,18.02]],"ltp":1.56,"tv":8305.4,"id":22229228}]}]}
{"op":"mcm","clk":"999743664","pt":1580599597134,"mc":[{"id":"1.168081817","rc":[{"batb":[[0,2.76,2.58],[1,2.74,28.78],[2,2.72,37.97]],"ltp":2.76,"tv":1017.12,"id":15256065}]}]}
{"op":"mcm","clk":"999755166","pt":1580599794114,"mc":[{"id":"1.168081817","rc":[{"batb":[[0,2.76,25.59]],"ltp":2.76,"tv":1017.12,"id":15256065},{"trd":[[1.55,66.63]],"batb":[[0,1.54,32.19],[1,1.53,62.69],[2,1.52,5.53]],"batl":[[0,1.55,54.53],[1,1.57,18.02],[2,1.58,33.74]],"ltp":1.55,"tv":8314.56,"id":22229228}],"tv":9331.69}]}
{"op":"mcm","clk":"999755277","pt":1580599795593,"mc":[{"id":"1.168081817","rc":[{"batb":[[0,2.78,2.56],[1,2.76,25.59],[2,2.74,28.78]],"ltp":2.76,"tv":1017.12,"id":15256065},{"batl":[[1,1.56,4.56],[2,1.57,18.02]],"ltp":1.55,"tv":8314.56,"id":22229228}]}]}
{"op":"mcm","clk":"999755290","pt":1580599795800,"mc":[{"id":"1.168081817","rc":[{"batb":[[1,2.76,30.62]],"ltp":2.76,"tv":1017.12,"id":15256065}]}]}
{"op":"mcm","clk":"999755945","pt":1580599805635,"mc":[{"id":"1.168081817","rc":[{"trd":[[1.54,262.52]],"batb":[[0,1.53,62.69],[1,1.52,5.53],[2,1.51,703.84]],"batl":[[0,1.54,1.13]],"ltp":1.54,"tv":8421.35,"id":22229228}],"tv":9438.48}]}
{"op":"mcm","clk":"999755964","pt":1580599805902,"mc":[{"id":"1.168081817","rc":[{"batb":[[0,2.78,14.38]],"ltp":2.76,"tv":1017.12,"id":15256065},{"batb":[[1,1.52,26.45]],"ltp":1.54,"tv":8421.35,"id":22229228}]}]}
{"op":"mcm","clk":"999756078","pt":1580599807421,"mc":[{"id":"1.168081817","rc":[{"batb":[[0,2.8,2.55],[1,2.78,14.38],[2,2.76,25.59]],"ltp":2.76,"tv":1017.12,"id":15256065},{"batl":[[1,1.56,23.13]],"ltp":1.54,"tv":8421.35,"id":22229228}]}]}
{"op":"mcm","clk":"999756220","pt":1580599809403,"mc":[{"id":"1.168081817","rc":[{"batl":[[1,1.56,4.56]],"ltp":1.54,"tv":8421.35,"id":22229228}]}]}
{"op":"mcm","clk":"999757443","pt":1580599828563,"mc":[{"id":"1.168081817","rc":[{"trd":[[1.54,264.78]],"batb":[[0,1.54,3.5],[1,1.53,62.69],[2,1.52,26.45]],"batl":[[0,1.56,4.56],[1,1.57,18.02],[2,1.58,4.49]],"ltp":1.54,"tv":8423.61,"id":22229228}],"tv":9440.74}]}
{"op":"mcm","clk":"999759468","pt":1580599860390,"mc":[{"id":"1.168081817","rc":[{"batb":[[2,2.76,30.62]],"ltp":2.76,"tv":1017.12,"id":15256065}]}]}
{"op":"mcm","clk":"999759693","pt":1580599864191,"mc":[{"id":"1.168081817","rc":[{"batl":[[0,1.56,13.33]],"ltp":1.54,"tv":8423.61,"id":22229228}]}]}
{"op":"mcm","clk":"999760252","pt":1580599873125,"mc":[{"id":"1.168081817","rc":[{"batl":[[0,1.56,22.11]],"ltp":1.54,"tv":8423.61,"id":22229228}]}]}
{"op":"mcm","clk":"999775370","pt":1580600124852,"mc":[{"id":"1.168081817","rc":[{"trd":[[2.86,4.28],[2.9,21.59]],"batl":[[0,2.92,29.83],[1,2.94,24.17],[2,2.96,2.39]],"ltp":2.9,"tv":1040.6,"id":15256065},{"trd":[[1.53,336.65],[1.54,268.28]],"batb":[[0,1.53,31.01],[1,1.52,26.45],[2,1.51,703.84]],"ltp":1.53,"tv":8458.79,"id":22229228}],"tv":9499.39}]}
{"op":"mcm","clk":"999775443","pt":1580600125999,"mc":[{"id":"1.168081817","rc":[{"batl":[[0,2.9,2.46],[1,2.92,29.83],[2,2.94,24.17]],"ltp":2.9,"tv":1040.6,"id":15256065},{"batb":[[2,1.51,708.57]],"batl":[[0,1.55,4.6],[1,1.56,22.11],[2,1.57,18.02]],"ltp":1.53,"tv":8458.79,"id":22229228}]}]}
{"op":"mcm","clk":"999778568","pt":1580600176112,"mc":[{"id":"1.168081817","rc":[{"batb":[[0,1.53,35.67]],"ltp":1.53,"tv":8458.79,"id":22229228}]}]}
{"op":"mcm","clk":"999779612","pt":1580600195325,"mc":[{"id":"1.168081817","rc":[{"trd":[[2.8,135.51]],"batb":[[0,2.78,14.66],[1,2.76,30.62],[2,2.74,28.78]],"ltp":2.8,"tv":1045.14,"id":15256065}],"tv":9503.93}]}
{"op":"mcm","clk":"999779681","pt":1580600196569,"mc":[{"id":"1.168081817","rc":[{"batb":[[0,1.54,4.64],[1,1.53,35.67],[2,1.52,26.45]],"batl":[[0,1.56,22.11],[1,1.57,18.02],[2,1.58,4.49]],"ltp":1.53,"tv":8458.79,"id":22229228}]}]}
{"op":"mcm","clk":"999779838","pt":1580600199406,"mc":[{"id":"1.168081817","rc":[{"batb":[[0,2.78,14.38]],"ltp":2.8,"tv":1045.14,"id":15256065}]}]}
{"op":"mcm","clk":"999785872","pt":1580600308901,"mc":[{"id":"1.168081817","rc":[{"batb":[[0,2.8,2.55],[1,2.78,14.38],[2,2.76,30.62]],"ltp":2.8,"tv":1045.14,"id":15256065}]}]}
{"op":"mcm","clk":"999793742","pt":1580600452699,"mc":[{"id":"1.168081817","rc":[{"batb":[[0,2.78,11.82],[1,2.76,30.62],[2,2.74,28.78]],"ltp":2.8,"tv":1045.14,"id":15256065},{"trd":[[1.56,143.36]],"batl":[[0,1.56,12.49]],"ltp":1.56,"tv":8478.03,"id":22229228}],"tv":9523.17}]}
{"op":"mcm","clk":"999793801","pt":1580600453520,"mc":[{"id":"1.168081817","rc":[{"batb":[[1,2.76,25.59],[2,2.74,33.85]],"ltp":2.8,"tv":1045.14,"id":15256065},{"batl":[[0,1.57,18.02],[1,1.58,4.49],[2,1.6,590.59]],"ltp":1.56,"tv":8478.03,"id":22229228}]}]}
{"op":"mcm","clk":"999793864","pt":1580600454714,"mc":[{"id":"1.168081817","rc":[{"batb":[[1,1.53,40.83]],"ltp":1.56,"tv":8478.03,"id":22229228}]}]}
{"op":"mcm","clk":"999795946","pt":1580600488661,"mc":[{"id":"1.168081817","rc":[{"batb":[[0,2.8,2.55],[1,2.78,14.39],[2,2.76,25.59]],"ltp":2.8,"tv":1045.14,"id":15256065},{"batl":[[0,1.56,4.58],[1,1.57,18.02],[2,1.58,4.49]],"ltp":1.56,"tv":8478.03,"id":22229228}]}]}
{"op":"mcm","clk":"999835697","pt":1580601156102,"mc":[{"id":"1.168081817","rc":[{"trd":[[2.8,138.06]],"batb":[[0,2.78,14.39],[1,2.76,25.59],[2,2.74,33.85]],"ltp":2.8,"tv":1047.69,"id":15256065},{"trd":[[1.56,157.1]],"batb":[[0,1.56,38.6],[1,1.54,4.64],[2,1.53,40.83]],"batl":[[0,1.57,18.02],[1,1.58,4.49],[2,1.6,590.59]],"ltp":1.56,"tv":8491.77,"id":22229228}],"tv":9539.46}]}
{"op":"mcm","clk":"999835764","pt":1580601157391,"mc":[{"id":"1.168081817","rc":[{"batb":[[0,2.78,11.82],[1,2.76,23.01]],"ltp":2.8,"tv":1047.69,"id":15256065},{"batl":[[0,1.57,18.07],[2,1.59,4.51]],"ltp":1.56,"tv":8491.77,"id":22229228}]}]}
{"op":"mcm","clk":"999835926","pt":1580601160092,"mc":[{"id":"1.168081817","rc":[{"batb":[[1,1.55,4.63],[2,1.54,4.64]],"ltp":1.56,"tv":8491.77,"id":22229228}]}]}
{"op":"mcm","clk":"999836240","pt":1580601165314,"mc":[{"id":"1.168081817","rc":[{"batl":[[0,1.57,13.5]],"ltp":1.56,"tv":8491.77,"id":22229228}]}]}
{"op":"mcm","clk":"999836643","pt":1580601171449,"mc":[{"id":"1.168081817","rc":[{"batb":[[1,2.76,25.61]],"ltp":2.8,"tv":1047.69,"id":15256065},{"batb":[[0,1.55,4.63],[1,1.54,4.64],[2,1.53,40.83]],"batl":[[0,1.57,18.07]],"ltp":1.56,"tv":8491.77,"id":22229228}]}]}
{"op":"mcm","clk":"999837498","pt":1580601184526,"mc":[{"id":"1.168081817","rc":[{"batb":[[0,2.78,9.27]],"ltp":2.8,"tv":1047.69,"id":15256065},{"trd":[[1.55,75.89]],"batb":[[0,1.54,4.64],[1,1.53,45.51],[2,1.52,26.45]],"ltp":1.55,"tv":8501.03,"id":22229228}],"tv":9548.72}]}
{"op":"mcm","clk":"999837530","pt":1580601184939,"mc":[{"id":"1.168081817","rc":[{"batb":[[0,2.8,2.56],[1,2.78,11.85],[2,2.76,25.61]],"ltp":2.8,"tv":1047.69,"id":15256065},{"batl":[[0,1.56,4.6],[1,1.57,18.07],[2,1.58,4.49]],"ltp":1.55,"tv":8501.03,"id":22229228}]}]}
{"op":"mcm","clk":"999838653","pt":1580601203341,"mc":[{"id":"1.168081817","rc":[{"trd":[[2.8,140.52]],"batb":[[0,2.78,9.27],[1,2.76,25.61],[2,2.74,33.85]],"ltp":2.8,"tv":1050.14,"id":15256065},{"trd":[[1.56,170.69]],"batl":[[0,1.57,18.07],[1,1.58,4.49],[2,1.59,4.51]],"ltp":1.56,"tv":8514.62,"id":22229228}],"tv":9564.77}]}
{"op":"mcm","clk":"999841122","pt":1580601248625,"mc":[{"id":"1.168081817","rc":[{"trd":[[1.54,276.28]],"batb":[[0,1.53,46.15],[1,1.52,26.45],[2,1.51,703.84]],"ltp":1.54,"tv":8522.62,"id":22229228}],"tv":9572.77}]}
{"op":"mcm","clk":"999841154","pt":1580601249247,"mc":[{"id":"1.168081817","rc":[{"batb":[[0,2.78,11.85]],"ltp":2.8,"tv":1050.14,"id":15256065},{"batl":[[0,1.56,4.6],[1,1.57,18.07],[2,1.58,4.49]],"ltp":1.54,"tv":8522.62,"id":22229228}]}]}
{"op":"mcm","clk":"999844933","pt":1580601314703,"mc":[{"id":"1.168081817","rc":[{"trd":[[1.56,178.69]],"batl":[[0,1.57,18.67],[1,1.58,4.49],[2,1.59,4.51]],"ltp":1.56,"tv":8530.62,"id":22229228}],"tv":9580.77}]}
{"op":"mcm","clk":"999844974","pt":1580601315690,"mc":[{"id":"1.168081817","rc":[{"batb":[[0,2.78,9.27]],"ltp":2.8,"tv":1050.14,"id":15256065},{"batl":[[0,1.57,18.07]],"ltp":1.56,"tv":8530.62,"id":22229228}]}]}
{"op":"mcm","clk":"999845252","pt":1580601322100,"mc":[{"id":"1.168081817","rc":[{"batl":[[0,1.56,2.5],[1,1.57,18.07],[2,1.58,4.49]],"ltp":1.56,"tv":8530.62,"id":22229228}]}]}
{"op":"mcm","clk":"999845421","pt":1580601324839,"mc":[{"id":"1.168081817","rc":[{"batl":[[0,1.55,2.5]],"ltp":1.56,"tv":8530.62,"id":22229228}]}]}
{"op":"mcm","clk":"999845526","pt":1580601327319,"mc":[{"id":"1.168081817","rc":[{"trd":[[1.54,277.56]],"batb":[[0,1.53,45.51]],"batl":[[0,1.54,1.86]],"ltp":1.54,"tv":8531.9,"id":22229228}],"tv":9582.05}]}
{"op":"mcm","clk":"999845544","pt":1580601328043,"mc":[{"id":"1.168081817","rc":[{"batb":[[0,2.8,2.56],[1,2.78,11.85],[2,2.76,25.61]],"ltp":2.8,"tv":1050.14,"id":15256065},{"batl":[[1,1.55,4.63],[2,1.56,4.6]],"ltp":1.54,"tv":8531.9,"id":22229228}]}]}
{"op":"mcm","clk":"999845631","pt":1580601330423,"mc":[{"id":"1.168081817","rc":[{"trd":[[1.53,340.37]],"batb":[[0,1.53,43.65]],"batl":[[0,1.55,4.63],[1,1.56,4.6],[2,1.57,18.07]],"ltp":1.53,"tv":8535.62,"id":22229228}],"tv":9585.77}]}
{"op":"mcm","clk":"999845664","pt":1580601331098,"mc":[{"id":"1.168081817","rc":[{"batb":[[0,1.54,4.66],[1,1.53,43.65],[2,1.52,26.45]],"batl":[[0,1.56,4.6],[1,1.57,18.07],[2,1.58,4.49]],"ltp":1.53,"tv":8535.62,"id":22229228}]}]}
{"op":"mcm","clk":"999845692","pt":1580601331824,"mc":[{"id":"1.168081817","rc":[{"batb":[[0,2.78,11.85],[1,2.76,25.61],[2,2.74,33.85]],"ltp":2.8,"tv":1050.14,"id":15256065}]}]}
{"op":"mcm","clk":"999846517","pt":1580601351260,"mc":[{"id":"1.168081817","rc":[{"trd":[[1.56,186.69]],"batl":[[0,1.57,18.67],[1,1.58,4.49],[2,1.6,383]],"ltp":1.56,"tv":8543.62,"id":22229228}],"tv":9593.77}]}
{"op":"mcm","clk":"999846551","pt":1580601352241,"mc":[{"id":"1.168081817","rc":[{"batb":[[0,2.78,9.27],[1,2.76,23.01]],"ltp":2.8,"tv":1050.14,"id":15256065},{"batl":[[0,1.57,18.07]],"ltp":1.56,"tv":8543.62,"id":22229228}]}]}
{"op":"mcm","clk":"999846605","pt":1580601353123,"mc":[{"id":"1.168081817","rc":[{"batb":[[1,2.76,25.61]],"ltp":2.8,"tv":1050.14,"id":15256065},{"trd":[[1.54,285.26]],"batb":[[0,1.53,44.47],[1,1.52,26.45],[2,1.51,703.84]],"ltp":1.54,"tv":8551.32,"id":22229228}],"tv":9601.47}]}
{"op":"mcm","clk":"999846653","pt":1580601354055,"mc":[{"id":"1.168081817","rc":[{"batb":[[0,2.8,2.56],[1,2.78,11.85],[2,2.76,25.61]],"ltp":2.8,"tv":1050.14,"id":15256065},{"batb":[[0,1.53,43.65]],"batl":[[0,1.56,4.6],[1,1.57,18.07],[2,1.58,4.49]],"ltp":1.54,"tv":8551.32,"id":22229228}]}]}
{"op":"mcm","clk":"999846752","pt":1580601356276,"mc":[{"id":"1.168081817","rc":[{"batb":[[0,1.54,4.66],[1,1.53,43.65],[2,1.52,26.45]],"ltp":1.54,"tv":8551.32,"id":22229228}]}]}
{"op":"mcm","clk":"999848432","pt":1580601382980,"mc":[{"id":"1.168081817","rc":[{"batb":[[0,2.78,11.85],[1,2.76,25.61],[2,2.74,33.85]],"ltp":2.8,"tv":1050.14,"id":15256065}]}]}
{"op":"mcm","clk":"999849133","pt":1580601398514,"mc":[{"id":"1.168081817","rc":[{"batb":[[0,2.78,9.27],[1,2.76,23.01]],"ltp":2.8,"tv":1050.14,"id":15256065},{"trd":[[1.56,194.69]],"batl":[[0,1.57,18.07],[1,1.58,4.49],[2,1.6,383]],"ltp":1.56,"tv":8559.32,"id":22229228}],"tv":9609.47}]}
{"op":"mcm","clk":"999849228","pt":1580601400623,"mc":[{"id":"1.168081817","rc":[{"batb":[[1,2.76,25.61]],"ltp":2.8,"tv":1050.14,"id":15256065}]}]}
{"op":"mcm","clk":"999849258","pt":1580601401404,"mc":[{"id":"1.168081817","rc":[{"batb":[[1,2.76,23.01]],"ltp":2.8,"tv":1050.14,"id":15256065}]}]}
{"op":"mcm","clk":"999849297","pt":1580601402129,"mc":[{"id":"1.168081817","rc":[{"batb":[[1,2.76,25.61]],"ltp":2.8,"tv":1050.14,"id":15256065}]}]}
{"op":"mcm","clk":"999850278","pt":1580601421675,"mc":[{"id":"1.168081817","rc":[{"batb":[[0,2.78,11.86]],"ltp":2.8,"tv":1050.14,"id":15256065},{"batl":[[0,1.56,4.6],[1,1.57,18.07],[2,1.58,4.49]],"ltp":1.56,"tv":8559.32,"id":22229228}]}]}
{"op":"mcm","clk":"999850814","pt":1580601431783,"mc":[{"id":"1.168081817","rc":[{"trd":[[1.56,202.69]],"batl":[[0,1.57,18.67],[1,1.58,4.49],[2,1.6,383]],"ltp":1.56,"tv":8567.32,"id":22229228}],"tv":9617.47}]}
{"op":"mcm","clk":"999850872","pt":1580601432966,"mc":[{"id":"1.168081817","rc":[{"batb":[[0,2.78,9.27],[1,2.76,23.01]],"ltp":2.8,"tv":1050.14,"id":15256065},{"batl":[[0,1.57,18.07]],"ltp":1.56,"tv":8567.32,"id":22229228}]}]}
{"op":"mcm","clk":"999853028","pt":1580601476640,"mc":[{"id":"1.168081817","rc":[{"batb":[[1,2.76,25.61]],"ltp":2.8,"tv":1050.14,"id":15256065}]}]}
{"op":"mcm","clk":"999853077","pt":1580601477564,"mc":[{"id":"1.168081817","rc":[{"batb":[[1,2.76,23.01]],"ltp":2.8,"tv":1050.14,"id":15256065}]}]}
{"op":"mcm","clk":"999853109","pt":1580601478233,"mc":[{"id":"1.168081817","rc":[{"batb":[[1,2.76,25.61]],"ltp":2.8,"tv":1050.14,"id":15256065}]}]}
{"op":"mcm","clk":"999853406","pt":1580601485228,"mc":[{"id":"1.168081817","rc":[{"batb":[[0,2.78,11.86]],"ltp":2.8,"tv":1050.14,"id":15256065}]}]}
{"op":"mcm","clk":"999853446","pt":1580601486357,"mc":[{"id":"1.168081817","rc":[{"batl":[[0,1.56,4.6],[1,1.57,18.07],[2,1.58,4.49]],"ltp":1.56,"tv":8567.32,"id":22229228}]}]}
{"op":"mcm","clk":"999854918","pt":1580601511702,"mc":[{"id":"1.168081817","rc":[{"batb":[[0,2.78,9.27],[1,2.76,23.01]],"ltp":2.8,"tv":1050.14,"id":15256065},{"trd":[[1.56,210.69]],"batl":[[0,1.57,18.07],[1,1.58,4.49],[2,1.6,383]],"ltp":1.56,"tv":8575.31,"id":22229228}],"tv":9625.46}]}
{"op":"mcm","clk":"999856042","pt":1580601535310,"mc":[{"id":"1.168081817","rc":[{"batb":[[1,2.76,25.61]],"ltp":2.8,"tv":1050.14,"id":15256065}]}]}
{"op":"mcm","clk":"999856080","pt":1580601536228,"mc":[{"id":"1.168081817","rc":[{"batb":[[1,2.76,23.01]],"ltp":2.8,"tv":1050.14,"id":15256065}]}]}
{"op":"mcm","clk":"999856110","pt":1580601536944,"mc":[{"id":"1.168081817","rc":[{"batb":[[1,2.76,25.61]],"ltp":2.8,"tv":1050.14,"id":15256065}]}]}
{"op":"mcm","clk":"999856363","pt":1580601543019,"mc":[{"id":"1.168081817","rc":[{"batb":[[0,2.78,11.86]],"ltp":2.8,"tv":1050.14,"id":15256065},{"batl":[[0,1.56,4.6],[1,1.57,18.07],[2,1.58,4.49]],"ltp":1.56,"tv":8575.31,"id":22229228}]}]}
{"op":"mcm","clk":"999857198","pt":1580601559380,"mc":[{"id":"1.168081817","rc":[{"trd":[[1.56,218.69]],"batl":[[0,1.57,18.67],[1,1.58,4.49],[2,1.6,383]],"ltp":1.56,"tv":8583.31,"id":22229228}],"tv":9633.46}]}
{"op":"mcm","clk":"999857256","pt":1580601560573,"mc":[{"id":"1.168081817","rc":[{"batb":[[0,2.78,9.27],[1,2.76,23.01]],"ltp":2.8,"tv":1050.14,"id":15256065},{"batl":[[0,1.57,18.07]],"ltp":1.56,"tv":8583.31,"id":22229228}]}]}
{"op":"mcm","clk":"999861135","pt":1580601644917,"mc":[{"id":"1.168081817","rc":[{"batb":[[1,2.76,25.61]],"ltp":2.8,"tv":1050.14,"id":15256065}]}]}
{"op":"mcm","clk":"999861638","pt":1580601657217,"mc":[{"id":"1.168081817","rc":[{"batb":[[0,2.78,11.86]],"ltp":2.8,"tv":1050.14,"id":15256065}]}]}
{"op":"mcm","clk":"999861669","pt":1580601658005,"mc":[{"id":"1.168081817","rc":[{"batl":[[0,1.56,4.61],[1,1.57,18.07],[2,1.58,4.49]],"ltp":1.56,"tv":8583.31,"id":22229228}]}]}
{"op":"mcm","clk":"999862376","pt":1580601677517,"mc":[{"id":"1.168081817","rc":[{"batb":[[0,2.78,9.27],[1,2.76,23.01]],"ltp":2.8,"tv":1050.14,"id":15256065},{"trd":[[1.56,226.69]],"batl":[[0,1.57,18.07],[1,1.58,4.49],[2,1.6,383]],"ltp":1.56,"tv":8591.31,"id":22229228}],"tv":9641.46}]}
{"op":"mcm","clk":"999864102","pt":1580601719292,"mc":[{"id":"1.168081817","rc":[{"batb":[[1,2.76,25.61]],"ltp":2.8,"tv":1050.14,"id":15256065}]}]}
{"op":"mcm","clk":"999864203","pt":1580601721205,"mc":[{"id":"1.168081817","rc":[{"batb":[[0,2.78,11.86]],"ltp":2.8,"tv":1050.14,"id":15256065}]}]}
{"op":"mcm","clk":"999864229","pt":1580601721985,"mc":[{"id":"1.168081817","rc":[{"batl":[[0,1.56,4.61],[1,1.57,18.07],[2,1.58,4.49]],"ltp":1.56,"tv":8591.31,"id":22229228}]}]}
{"op":"mcm","clk":"999865620","pt":1580601755603,"mc":[{"id":"1.168081817","rc":[{"trd":[[1.56,231.19]],"batl":[[0,1.56,2.36]],"ltp":1.56,"tv":8595.82,"id":22229228}],"tv":9645.96}]}
{"op":"mcm","clk":"999865648","pt":1580601756330,"mc":[{"id":"1.168081817","rc":[{"batb":[[0,2.78,9.27],[1,2.76,23.01]],"ltp":2.8,"tv":1050.14,"id":15256065},{"batl":[[0,1.57,18.07],[1,1.58,4.49],[2,1.6,383]],"ltp":1.56,"tv":8595.82,"id":22229228}]}]}
{"op":"mcm","clk":"999866624","pt":1580601780879,"mc":[{"id":"1.168081817","rc":[{"batb":[[1,2.76,25.61]],"ltp":2.8,"tv":1050.14,"id":15256065}]}]}
{"op":"mcm","clk":"999870370","pt":1580601859637,"mc":[{"id":"1.168081817","rc":[{"trd":[[2.76,147.24],[2.78,79.62]],"batb":[[0,2.74,33.85],[1,2.72,32.9],[2,2.62,38.29]],"ltp":2.76,"tv":1085.03,"id":15256065},{"trd":[[1.57,2495.4]],"batl":[[0,1.58,4.49],[1,1.6,383],[2,1.65,91.9]],"ltp":1.57,"tv":8727.92,"id":22229228}],"tv":9812.95}]}
{"op":"mcm","clk":"999870409","pt":1580601860510,"mc":[{"id":"1.168081817","rc":[{"batb":[[0,2.74,26.18],[2,2.7,2.67]],"ltp":2.76,"tv":1085.03,"id":15256065},{"batb":[[0,1.56,1.5],[1,1.54,30.82],[2,1.53,43.65]],"batl":[[0,1.59,4.67],[1,1.6,387.65]],"ltp":1.57,"tv":8727.92,"id":22229228}]}]}
{"op":"mcm","clk":"999870428","pt":1580601860927,"mc":[{"id":"1.168081817","rc":[{"batb":[[1,1.55,5.03],[2,1.54,30.82]],"ltp":1.57,"tv":8727.92,"id":22229228}]}]}
{"op":"mcm","clk":"999870572","pt":1580601864134,"mc":[{"id":"1.168081817","rc":[{"batb":[[0,2.72,32.9],[1,2.7,2.67],[2,2.68,15.33]],"ltp":2.76,"tv":1085.03,"id":15256065},{"batb":[[0,1.57,19.35],[1,1.56,1.5],[2,1.55,5.03]],"ltp":1.57,"tv":8727.92,"id":22229228}]}]}
{"op":"mcm","clk":"999870638","pt":1580601865326,"mc":[{"id":"1.168081817","rc":[{"batb":[[0,2.72,30.26],[2,2.68,23.2]],"ltp":2.76,"tv":1085.03,"id":15256065},{"batl":[[0,1.59,13.91]],"ltp":1.57,"tv":8727.92,"id":22229228}]}]}
{"op":"mcm","clk":"999872179","pt":1580601905762,"mc":[{"id":"1.168081817","rc":[{"batb":[[0,1.56,1.5],[1,1.55,5.03],[2,1.54,30.82]],"ltp":1.57,"tv":8727.92,"id":22229228}]}]}
{"op":"mcm","clk":"999873070","pt":1580601924790,"mc":[{"id":"1.168081817","rc":[{"trd":[[2.72,159.23]],"batb":[[0,2.72,27.21]],"ltp":2.72,"tv":1088.08,"id":15256065},{"trd":[[1.59,503.41]],"batl":[[0,1.6,387.65],[1,1.65,91.9],[2,1.76,16.8]],"ltp":1.59,"tv":8760.93,"id":22229228}],"tv":9849.01}]}
{"op":"mcm","clk":"999873132","pt":1580601926289,"mc":[{"id":"1.168081817","rc":[{"batb":[[0,2.68,23.2],[1,2.66,2.71],[2,2.62,38.29]],"ltp":2.72,"tv":1088.08,"id":15256065},{"batl":[[1,1.61,4.48],[2,1.65,91.9]],"ltp":1.59,"tv":8760.93,"id":22229228}]}]}
{"op":"mcm","clk":"999873163","pt":1580601926910,"mc":[{"id":"1.168081817","rc":[{"batb":[[0,2.68,20.51],[2,2.64,2.73]],"ltp":2.72,"tv":1088.08,"id":15256065}]}]}
{"op":"mcm","clk":"999873505","pt":1580601934688,"mc":[{"id":"1.168081817","rc":[{"batb":[[0,1.59,19.11],[1,1.56,1.5],[2,1.55,5.03]],"ltp":1.59,"tv":8760.93,"id":22229228}]}]}
{"op":"mcm","clk":"999873553","pt":1580601935817,"mc":[{"id":"1.168081817","rc":[{"batb":[[1,1.56,6.13]],"batl":[[0,1.6,383],[2,1.62,4.45]],"ltp":1.59,"tv":8760.93,"id":22229228}]}]}
{"op":"mcm","clk":"999873635","pt":1580601938403,"mc":[{"id":"1.168081817","rc":[{"batb":[[1,1.57,4.6],[2,1.56,6.13]],"ltp":1.59,"tv":8760.93,"id":22229228}]}]}
{"op":"mcm","clk":"999874634","pt":1580601965880,"mc":[{"id":"1.168081817","rc":[{"trd":[[1.59,541.19]],"batb":[[0,1.57,4.82],[1,1.56,6.13],[2,1.55,5.03]],"ltp":1.59,"tv":8798.71,"id":22229228}],"tv":9886.79}]}
{"op":"mcm","clk":"999874669","pt":1580601966866,"mc":[{"id":"1.168081817","rc":[{"batb":[[0,2.68,23.21]],"ltp":2.72,"tv":1088.08,"id":15256065},{"trd":[[1.59,541.63]],"batb":[[0,1.57,4.6]],"batl":[[0,1.59,4.32],[1,1.6,387.51],[2,1.61,4.48]],"ltp":1.59,"tv":8799.15,"id":22229228}],"tv":9887.23}]}
{"op":"mcm","clk":"999876894","pt":1580602011501,"mc":[{"id":"1.168081817","rc":[{"batb":[[0,2.68,20.51]],"ltp":2.72,"tv":1088.08,"id":15256065},{"batb":[[0,1.58,82.37],[1,1.57,4.6],[2,1.56,6.13]],"batl":[[0,1.6,387.51],[1,1.61,4.48],[2,1.62,4.45]],"ltp":1.59,"tv":8799.15,"id":22229228}]}]}
{"op":"mcm","clk":"999876948","pt":1580602012527,"mc":[{"id":"1.168081817","rc":[{"batb":[[1,1.57,18.97]],"ltp":1.59,"tv":8799.15,"id":22229228}]}]}
{"op":"mcm","clk":"999880266","pt":1580602074557,"mc":[{"id":"1.168081817","rc":[{"batb":[[1,2.64,2.73],[2,2.62,11.1]],"ltp":2.72,"tv":1088.08,"id":15256065},{"batb":[[0,1.59,95],[1,1.58,86.94],[2,1.57,18.97]],"batl":[[0,1.6,383]],"ltp":1.59,"tv":8799.15,"id":22229228}]}]}
{"op":"mcm","clk":"999880330","pt":1580602075589,"mc":[{"id":"1.168081817","rc":[{"batb":[[0,1.59,99.97],[2,1.57,13.95]],"ltp":1.59,"tv":8799.15,"id":22229228}]}]}
{"op":"mcm","clk":"999880368","pt":1580602076168,"mc":[{"id":"1.168081817","rc":[{"batb":[[0,1.59,109.2],[2,1.57,4.6]],"ltp":1.59,"tv":8799.15,"id":22229228}]}]}
{"op":"mcm","clk":"999881343","pt":1580602091617,"mc":[{"id":"1.168081817","rc":[{"trd":[[1.59,584.07]],"batb":[[0,1.59,87.98]],"ltp":1.59,"tv":8841.59,"id":22229228}],"tv":9929.68}]}
{"op":"mcm","clk":"999881389","pt":1580602092189,"mc":[{"id":"1.168081817","rc":[{"batb":[[0,2.68,5.18]],"ltp":2.72,"tv":1088.08,"id":15256065}]}]}
{"op":"mcm","clk":"999881622","pt":1580602095718,"mc":[{"id":"1.168081817","rc":[{"batb":[[2,2.62,41.05]],"ltp":2.72,"tv":1088.08,"id":15256065}]}]}
{"op":"mcm","clk":"999884390","pt":1580602141582,"mc":[{"id":"1.168081817","rc":[{"trd":[[2.66,55.23],[2.68,166.96]],"batb":[[0,2.64,2.73],[1,2.62,41.05],[2,2.58,22.7]],"ltp":2.66,"tv":1143.91,"id":15256065},{"trd":[[1.6,804.32]],"batl":[[0,1.6,307.32]],"ltp":1.6,"tv":8917.27,"id":22229228}],"tv":10061.19}]}
{"op":"mcm","clk":"999884448","pt":1580602142363,"mc":[{"id":"1.168081817","rc":[{"trd":[[1.59,759.85]],"batb":[[0,1.58,87.04],[1,1.57,4.6],[2,1.56,6.13]],"ltp":1.59,"tv":9093.05,"id":22229228}],"tv":10236.97}]}
{"op":"mcm","clk":"999884509","pt":1580602143507,"mc":[{"id":"1.168081817","rc":[{"batb":[[0,1.58,86.94]],"batl":[[0,1.6,311.85]],"ltp":1.59,"tv":9093.05,"id":22229228}]}]}
{"op":"mcm","clk":"999889417","pt":1580602217980,"mc":[{"id":"1.168081817","rc":[{"batb":[[0,2.64,13.24],[2,2.56,78.75]],"ltp":2.66,"tv":1143.91,"id":15256065}]}]}
{"op":"mcm","clk":"999889500","pt":1580602219070,"mc":[{"id":"1.168081817","rc":[{"batb":[[0,2.66,2.72],[1,2.64,13.24],[2,2.62,41.05]],"ltp":2.66,"tv":1143.91,"id":15256065}]}]}
{"op":"mcm","clk":"999893229","pt":1580602276295,"mc":[{"id":"1.168081817","rc":[{"trd":[[1.6,1004.32]],"batl":[[0,1.6,211.85]],"ltp":1.6,"tv":9293.05,"id":22229228}],"tv":10436.97}]}
{"op":"mcm","clk":"999900710","pt":1580602385225,"mc":[{"id":"1.168081817","rc":[{"trd":[[1.58,2722.38]],"batb":[[0,1.58,71.04]],"ltp":1.58,"tv":9324.86,"id":22229228}],"tv":10468.77}]}
{"op":"mcm","clk":"999900822","pt":1580602386422,"mc":[{"id":"1.168081817","rc":[{"batl":[[0,1.59,24.33],[1,1.6,207.32],[2,1.61,4.48]],"ltp":1.58,"tv":9324.86,"id":22229228}]}]}
{"op":"mcm","clk":"999900857","pt":1580602386795,"mc":[{"id":"1.168081817","rc":[{"batl":[[1,1.6,211.87]],"ltp":1.58,"tv":9324.86,"id":22229228}]}]}
{"op":"mcm","clk":"999910359","pt":1580602518973,"mc":[{"id":"1.168081817","rc":[{"trd":[[1.59,808.51]],"batb":[[0,1.59,70.67],[1,1.58,71.04],[2,1.57,4.6]],"batl":[[0,1.6,211.87],[1,1.61,4.48],[2,1.62,4.45]],"ltp":1.59,"tv":9373.52,"id":22229228}],"tv":10517.44}]}
{"op":"mcm","clk":"999910465","pt":1580602520589,"mc":[{"id":"1.168081817","rc":[{"batb":[[0,2.64,13.24],[1,2.62,41.05],[2,2.56,78.75]],"ltp":2.66,"tv":1143.91,"id":15256065},{"batb":[[0,1.59,95.09]],"batl":[[0,1.6,207.32]],"ltp":1.59,"tv":9373.52,"id":22229228}]}]}
{"op":"mcm","clk":"999910534","pt":1580602521523,"mc":[{"id":"1.168081817","rc":[{"batb":[[1,2.62,11.1]],"ltp":2.66,"tv":1143.91,"id":15256065}]}]}
{"op":"mcm","clk":"999910582","pt":1580602522098,"mc":[{"id":"1.168081817","rc":[{"batb":[[0,1.59,99.67]],"ltp":1.59,"tv":9373.52,"id":22229228}]}]}
{"op":"mcm","clk":"999911499","pt":1580602535017,"mc":[{"id":"1.168081817","rc":[{"batb":[[0,1.59,194.67]],"ltp":1.59,"tv":9373.52,"id":22229228}]}]}
{"op":"mcm","clk":"999917665","pt":1580602624406,"mc":[{"id":"1.168081817","rc":[{"batb":[[0,2.64,2.73],[2,2.58,22.7]],"ltp":2.66,"tv":1143.91,"id":15256065}]}]}
{"op":"mcm","clk":"999917824","pt":1580602626710,"mc":[{"id":"1.168081817","rc":[{"batb":[[1,2.62,41.05]],"ltp":2.66,"tv":1143.91,"id":15256065}]}]}
{"op":"mcm","clk":"999923329","pt":1580602706424,"mc":[{"id":"1.168081817","rc":[{"trd":[[1.6,1043.02]],"batl":[[0,1.6,187.97]],"ltp":1.6,"tv":9412.22,"id":22229228}],"tv":10556.14}]}
{"op":"mcm","clk":"999926909","pt":1580602757868,"mc":[{"id":"1.168081817","rc":[{"batb":[[0,2.64,13.24],[2,2.56,78.75]],"ltp":2.66,"tv":1143.91,"id":15256065}]}]}
{"op":"mcm","clk":"999927214","pt":1580602762022,"mc":[{"id":"1.168081817","rc":[{"trd":[[2.7,61.13]],"batb":[[1,2.62,11.1]],"ltp":2.7,"tv":1148.82,"id":15256065},{"trd":[[1.59,816.85]],"batb":[[0,1.59,186.33]],"ltp":1.59,"tv":9420.56,"id":22229228}],"tv":10569.39}]}
{"op":"mcm","clk":"999935712","pt":1580602891625,"mc":[{"id":"1.168081817","rc":[{"batb":[[0,2.64,2.73],[2,2.58,22.7]],"ltp":2.7,"tv":1148.82,"id":15256065}]}]}
{"op":"mcm","clk":"999935742","pt":1580602892239,"mc":[{"id":"1.168081817","rc":[{"batb":[[1,2.62,41.05]],"ltp":2.7,"tv":1148.82,"id":15256065}]}]}
{"op":"mcm","clk":"999937121","pt":1580602916071,"mc":[{"id":"1.168081817","rc":[{"batb":[[0,2.68,14.29],[1,2.64,2.73],[2,2.62,41.05]],"ltp":2.7,"tv":1148.82,"id":15256065}]}]}
{"op":"mcm","clk":"999937208","pt":1580602917641,"mc":[{"id":"1.168081817","rc":[{"batb":[[2,2.62,11.1]],"ltp":2.7,"tv":1148.82,"id":15256065}]}]}
{"op":"mcm","clk":"999948713","pt":1580603118024,"mc":[{"id":"1.168081817","rc":[{"batb":[[0,2.64,2.73],[1,2.62,11.1],[2,2.58,22.7]],"ltp":2.7,"tv":1148.82,"id":15256065}]}]}
{"op":"mcm","clk":"999948977","pt":1580603122942,"mc":[{"id":"1.168081817","rc":[{"batb":[[1,2.62,41.05]],"ltp":2.7,"tv":1148.82,"id":15256065}]}]}
{"op":"mcm","clk":"999949585","pt":1580603133001,"mc":[{"id":"1.168081817","rc":[{"trd":[[1.59,866.39]],"batb":[[0,1.59,161.56]],"ltp":1.59,"tv":9470.1,"id":22229228}],"tv":10618.92}]}
{"op":"mcm","clk":"999951666","pt":1580603166138,"mc":[{"id":"1.168081817","rc":[{"batb":[[0,2.64,13.24],[2,2.56,78.75]],"ltp":2.7,"tv":1148.82,"id":15256065}]}]}
{"op":"mcm","clk":"999951761","pt":1580603168052,"mc":[{"id":"1.168081817","rc":[{"batb":[[1,2.62,11.1]],"ltp":2.7,"tv":1148.82,"id":15256065}]}]}
{"op":"mcm","clk":"999959429","pt":1580603298958,"mc":[{"id":"1.168081817","rc":[{"batb":[[0,2.64,2.73],[2,2.58,22.7]],"ltp":2.7,"tv":1148.82,"id":15256065}]}]}
{"op":"mcm","clk":"999959777","pt":1580603303268,"mc":[{"id":"1.168081817","rc":[{"batb":[[1,2.62,41.05]],"ltp":2.7,"tv":1148.82,"id":15256065}]}]}
{"op":"mcm","clk":"999965825","pt":1580603419695,"mc":[{"id":"1.168081817","rc":[{"trd":[[2.66,56.91]],"ltp":2.66,"tv":1150.5,"id":15256065},{"trd":[[1.6,1045.81]],"batl":[[0,1.6,185.18]],"ltp":1.6,"tv":9472.89,"id":22229228}],"tv":10623.39}]}
{"op":"mcm","clk":"999966553","pt":1580603433639,"mc":[{"id":"1.168081817","rc":[{"batb":[[0,2.64,13.24],[1,2.62,11.1],[2,2.56,78.75]],"ltp":2.66,"tv":1150.5,"id":15256065}]}]}
{"op":"mcm","clk":"999970903","pt":1580603505887,"mc":[{"id":"1.168081817","rc":[{"trd":[[1.6,1049.17]],"batl":[[0,1.6,183.5]],"ltp":1.6,"tv":9476.25,"id":22229228}],"tv":10626.75}]}
{"op":"mcm","clk":"999974940","pt":1580603567666,"mc":[{"id":"1.168081817","rc":[{"batb":[[0,2.64,2.73]],"ltp":2.66,"tv":1150.5,"id":15256065}]}]}
{"op":"mcm","clk":"999974999","pt":1580603568699,"mc":[{"id":"1.168081817","rc":[{"batb":[[1,2.62,41.05],[2,2.58,22.7]],"ltp":2.66,"tv":1150.5,"id":15256065}]}]}
{"op":"mcm","clk":"999976225","pt":1580603588823,"mc":[{"id":"1.168081817","rc":[{"batl":[[0,1.6,233.5]],"ltp":1.6,"tv":9476.25,"id":22229228}]}]}
{"op":"mcm","clk":"999982314","pt":1580603706553,"mc":[{"id":"1.168081817","rc":[{"batb":[[0,2.64,13.24],[2,2.56,78.75]],"ltp":2.66,"tv":1150.5,"id":15256065}]}]}
{"op":"mcm","clk":"999982435","pt":1580603709141,"mc":[{"id":"1.168081817","rc":[{"batb":[[1,2.62,11.1]],"ltp":2.66,"tv":1150.5,"id":15256065}]}]}
{"op":"mcm","clk":"999986696","pt":1580603800582,"mc":[{"id":"1.168081817","rc":[{"trd":[[2.7,66.21]],"ltp":2.7,"tv":1155.58,"id":15256065},{"trd":[[1.59,875.02]],"batb":[[0,1.59,152.93]],"ltp":1.59,"tv":9484.88,"id":22229228}],"tv":10640.46}]}
{"op":"mcm","clk":"999988341","pt":1580603839849,"mc":[{"id":"1.168081817","rc":[{"batb":[[0,2.64,2.73],[2,2.58,22.7]],"ltp":2.7,"tv":1155.58,"id":15256065}]}]}
{"op":"mcm","clk":"999988531","pt":1580603844285,"mc":[{"id":"1.168081817","rc":[{"batb":[[1,2.62,41.05]],"ltp":2.7,"tv":1155.58,"id":15256065}]}]}
{"op":"mcm","clk":"999990775","pt":1580603895941,"mc":[{"id":"1.168081817","rc":[{"trd":[[1.6,1053.93]],"batl":[[0,1.6,231.12]],"ltp":1.6,"tv":9489.64,"id":22229228}],"tv":10645.22}]}
{"op":"mcm","clk":"999994704","pt":1580603975015,"mc":[{"id":"1.168081817","rc":[{"batb":[[0,2.64,13.24],[2,2.56,78.75]],"ltp":2.7,"tv":1155.58,"id":15256065}]}]}
{"op":"mcm","clk":"999994915","pt":1580603979642,"mc":[{"id":"1.168081817","rc":[{"batb":[[1,2.62,11.1]],"ltp":2.7,"tv":1155.58,"id":15256065}]}]}
{"op":"mcm","clk":"1000001349","pt":1580604111165,"mc":[{"id":"1.168081817","rc":[{"batb":[[0,2.64,2.73],[2,2.58,22.7]],"ltp":2.7,"tv":1155.58,"id":15256065}]}]}
{"op":"mcm","clk":"1000001500","pt":1580604114764,"mc":[{"id":"1.168081817","rc":[{"batb":[[1,2.62,41.05]],"ltp":2.7,"tv":1155.58,"id":15256065}]}]}
{"op":"mcm","clk":"1000003561","pt":1580604165256,"mc":[{"id":"1.168081817","rc":[{"batb":[[1,2.62,32.71]],"ltp":2.7,"tv":1155.58,"id":15256065},{"trd":[[1.59,904.1]],"batb":[[0,1.59,138.39]],"ltp":1.59,"tv":9518.72,"id":22229228}],"tv":10674.3}]}
{"op":"mcm","clk":"1000006868","pt":1580604244681,"mc":[{"id":"1.168081817","rc":[{"batb":[[2,2.56,78.75]],"ltp":2.7,"tv":1155.58,"id":15256065}]}]}
{"op":"mcm","clk":"1000006883","pt":1580604245041,"mc":[{"id":"1.168081817","rc":[{"batb":[[0,2.64,13.24],[1,2.62,2.76]],"ltp":2.7,"tv":1155.58,"id":15256065}]}]}
{"op":"mcm","clk":"1000011720","pt":1580604359427,"mc":[{"id":"1.168081817","rc":[{"trd":[[2.7,90.25]],"ltp":2.7,"tv":1179.62,"id":15256065},{"trd":[[1.59,944.92]],"batb":[[0,1.59,97.57]],"ltp":1.59,"tv":9559.54,"id":22229228}],"tv":10739.17}]}
{"op":"mcm","clk":"1000012735","pt":1580604382861,"mc":[{"id":"1.168081817","rc":[{"batb":[[0,2.64,2.73],[2,2.58,22.7]],"ltp":2.7,"tv":1179.62,"id":15256065}]}]}
{"op":"mcm","clk":"1000012838","pt":1580604385228,"mc":[{"id":"1.168081817","rc":[{"batb":[[1,2.62,32.71]],"ltp":2.7,"tv":1179.62,"id":15256065}]}]}
{"op":"mcm","clk":"1000018641","pt":1580604518012,"mc":[{"id":"1.168081817","rc":[{"batb":[[0,2.64,13.24],[2,2.56,78.75]],"ltp":2.7,"tv":1179.62,"id":15256065}]}]}
{"op":"mcm","clk":"1000018758","pt":1580604520606,"mc":[{"id":"1.168081817","rc":[{"batb":[[1,2.62,2.76]],"ltp":2.7,"tv":1179.62,"id":15256065}]}]}
{"op":"mcm","clk":"1000024387","pt":1580604651408,"mc":[{"id":"1.168081817","rc":[{"batb":[[0,2.64,2.73],[2,2.58,22.7]],"ltp":2.7,"tv":1179.62,"id":15256065}]}]}
{"op":"mcm","clk":"1000024543","pt":1580604655734,"mc":[{"id":"1.168081817","rc":[{"batb":[[1,2.62,32.71]],"ltp":2.7,"tv":1179.62,"id":15256065}]}]}
{"op":"mcm","clk":"1000030892","pt":1580604784507,"mc":[{"id":"1.168081817","rc":[{"batb":[[2,2.56,78.75]],"ltp":2.7,"tv":1179.62,"id":15256065}]}]}
{"op":"mcm","clk":"1000030899","pt":1580604784712,"mc":[{"id":"1.168081817","rc":[{"batb":[[0,2.64,13.24]],"ltp":2.7,"tv":1179.62,"id":15256065}]}]}
{"op":"mcm","clk":"1000030960","pt":1580604786104,"mc":[{"id":"1.168081817","rc":[{"batb":[[1,2.62,2.76]],"ltp":2.7,"tv":1179.62,"id":15256065}]}]}
{"op":"mcm","clk":"1000036379","pt":1580604918237,"mc":[{"id":"1.168081817","rc":[{"batb":[[0,2.64,2.73],[2,2.58,22.7]],"ltp":2.7,"tv":1179.62,"id":15256065}]}]}
{"op":"mcm","clk":"1000036502","pt":1580604921257,"mc":[{"id":"1.168081817","rc":[{"batb":[[1,2.62,32.71]],"ltp":2.7,"tv":1179.62,"id":15256065}]}]}
{"op":"mcm","clk":"1000038330","pt":1580604971506,"mc":[{"id":"1.168081817","rc":[{"trd":[[1.59,1140.06]],"batb":[[0,1.58,71.04],[1,1.57,4.6],[2,1.56,6.13]],"batl":[[0,1.59,2.43],[1,1.6,231.12],[2,1.61,4.48]],"ltp":1.59,"tv":9754.68,"id":22229228}],"tv":10934.31}]}
{"op":"mcm","clk":"1000038358","pt":1580604972633,"mc":[{"id":"1.168081817","rc":[{"batl":[[0,1.59,23.32],[1,1.6,235.74]],"ltp":1.59,"tv":9754.68,"id":22229228}]}]}
{"op":"mcm","clk":"1000040877","pt":1580605054919,"mc":[{"id":"1.168081817","rc":[{"batb":[[0,2.64,13.24],[2,2.56,78.75]],"ltp":2.7,"tv":1179.62,"id":15256065}]}]}
{"op":"mcm","clk":"1000040916","pt":1580605056042,"mc":[{"id":"1.168081817","rc":[{"batb":[[0,2.66,2.78],[1,2.64,13.24],[2,2.62,32.71]],"ltp":2.7,"tv":1179.62,"id":15256065}]}]}
{"op":"mcm","clk":"1000041296","pt":1580605067949,"mc":[{"id":"1.168081817","rc":[{"trd":[[1.59,1178.28]],"batl":[[0,1.59,4.21]],"ltp":1.59,"tv":9792.9,"id":22229228}],"tv":10972.53}]}
{"op":"mcm","clk":"1000061176","pt":1580605739464,"mc":[{"id":"1.168081817","rc":[{"trd":[[2.66,64.8],[2.68,169.46]],"batb":[[0,2.64,13.24],[1,2.62,32.71],[2,2.56,78.75]],"ltp":2.66,"tv":1190.0,"id":15256065},{"trd":[[1.59,1182.49],[1.6,1057.79]],"batl":[[0,1.6,231.88],[1,1.61,4.48],[2,1.62,4.45]],"ltp":1.6,"tv":9800.97,"id":22229228}],"tv":10990.97}]}
{"op":"mcm","clk":"1000061213","pt":1580605740339,"mc":[{"id":"1.168081817","rc":[{"batl":[[0,1.6,227.26]],"ltp":1.6,"tv":9800.97,"id":22229228}]}]}
{"op":"mcm","clk":"1000061425","pt":1580605747285,"mc":[{"id":"1.168081817","rc":[{"trd":[[1.59,1191.36]],"batb":[[0,1.58,71.27]],"ltp":1.59,"tv":9809.84,"id":22229228}],"tv":10999.85}]}
{"op":"mcm","clk":"1000061801","pt":1580605758492,"mc":[{"id":"1.168081817","rc":[{"trd":[[1.59,1191.84]],"batb":[[0,1.58,71.04]],"batl":[[0,1.59,1.76],[1,1.6,227.26],[2,1.61,4.48]],"ltp":1.59,"tv":9810.31,"id":22229228}],"tv":11000.32}]}
{"op":"mcm","clk":"1000061837","pt":1580605759475,"mc":[{"id":"1.168081817","rc":[{"trd":[[1.59,1195.35]],"batb":[[0,1.59,2.92],[1,1.58,71.04],[2,1.57,4.6]],"batl":[[0,1.6,227.26],[1,1.61,4.48],[2,1.62,4.45]],"ltp":1.59,"tv":9813.83,"id":22229228}],"tv":11003.84}]}
{"op":"mcm","clk":"1000061882","pt":1580605760660,"mc":[{"id":"1.168081817","rc":[{"batb":[[2,1.57,15.45]],"ltp":1.59,"tv":9813.83,"id":22229228}]}]}
{"op":"mcm","clk":"1000061906","pt":1580605761275,"mc":[{"id":"1.168081817","rc":[{"batb":[[0,2.66,2.79],[1,2.64,13.24],[2,2.62,32.71]],"ltp":2.66,"tv":1190.0,"id":15256065},{"batb":[[0,1.58,71.04],[1,1.57,25.74],[2,1.56,6.13]],"ltp":1.59,"tv":9813.83,"id":22229228}]}]}
{"op":"mcm","clk":"1000061923","pt":1580605761894,"mc":[{"id":"1.168081817","rc":[{"batl":[[0,1.6,231.91]],"ltp":1.59,"tv":9813.83,"id":22229228}]}]}
{"op":"mcm","clk":"1000085521","pt":1580606539584,"mc":[{"id":"1.168081817","rc":[{"trd":[[2.66,70.74]],"batb":[[0,2.64,13.24],[1,2.62,32.71],[2,2.56,78.75]],"ltp":2.66,"tv":1195.95,"id":15256065},{"trd":[[1.6,1058.4]],"batl":[[0,1.6,226.65]],"ltp":1.6,"tv":9814.44,"id":22229228}],"tv":11010.4}]}
{"op":"mcm","clk":"1000085977","pt":1580606552693,"mc":[{"id":"1.168081817","rc":[{"trd":[[1.58,2739.18]],"batb":[[0,1.58,62.64]],"ltp":1.58,"tv":9831.24,"id":22229228}],"tv":11027.2}]}
{"op":"mcm","clk":"1000085993","pt":1580606553107,"mc":[{"id":"1.168081817","rc":[{"batb":[[0,1.59,4.7],[1,1.58,62.64],[2,1.57,25.74]],"ltp":1.58,"tv":9831.24,"id":22229228}]}]}
{"op":"mcm","clk":"1000086052","pt":1580606554603,"mc":[{"id":"1.168081817","rc":[{"batb":[[2,1.57,4.6]],"ltp":1.58,"tv":9831.24,"id":22229228}]}]}
{"op":"mcm","clk":"1000087226","pt":1580606590451,"mc":[{"id":"1.168081817","rc":[{"batb":[[0,2.66,2.81],[1,2.64,13.24],[2,2.62,32.71]],"ltp":2.66,"tv":1195.95,"id":15256065},{"batb":[[0,1.58,62.64],[1,1.57,4.6],[2,1.56,6.13]],"batl":[[0,1.6,231.31]],"ltp":1.58,"tv":9831.24,"id":22229228}]}]}
{"op":"mcm","clk":"1000095760","pt":1580606846749,"mc":[{"id":"1.168081817","rc":[{"batl":[[0,1.59,7.57],[1,1.6,231.31],[2,1.61,4.48]],"ltp":1.58,"tv":9831.24,"id":22229228}]}]}
{"op":"mcm","clk":"1000099279","pt":1580606939452,"mc":[{"id":"1.168081817","rc":[{"trd":[[1.58,2863.18]],"batb":[[0,1.57,5.23],[1,1.56,6.13],[2,1.54,47.8]],"ltp":1.58,"tv":9955.24,"id":22229228}],"tv":11151.2}]}
{"op":"mcm","clk":"1000099299","pt":1580606940226,"mc":[{"id":"1.168081817","rc":[{"batb":[[0,1.57,4.6]],"batl":[[0,1.59,12.29]],"ltp":1.58,"tv":9955.24,"id":22229228}]}]}
{"op":"mcm","clk":"1000100476","pt":1580606973110,"mc":[{"id":"1.168081817","rc":[{"batl":[[0,1.58,7.57],[1,1.59,4.71],[2,1.6,231.31]],"ltp":1.58,"tv":9955.24,"id":22229228}]}]}
{"op":"mcm","clk":"1000101885","pt":1580607010336,"mc":[{"id":"1.168081817","rc":[{"trd":[[2.72,161.23]],"ltp":2.72,"tv":1197.95,"id":15256065},{"trd":[[1.58,2866.62]],"batl":[[0,1.58,4.13]],"ltp":1.58,"tv":9958.69,"id":22229228}],"tv":11156.64}]}
{"op":"mcm","clk":"1000104012","pt":1580607068314,"mc":[{"id":"1.168081817","rc":[{"trd":[[1.58,2874.87]],"batl":[[0,1.59,4.71],[1,1.6,231.31],[2,1.61,4.48]],"ltp":1.58,"tv":9966.94,"id":22229228}],"tv":11164.9}]}
{"op":"mcm","clk":"1000104043","pt":1580607068936,"mc":[{"id":"1.168081817","rc":[{"batb":[[1,2.64,15.68]],"ltp":2.72,"tv":1197.95,"id":15256065},{"batb":[[2,1.53,55.97]],"batl":[[0,1.6,231.31],[1,1.61,4.48],[2,1.62,4.45]],"ltp":1.58,"tv":9966.94,"id":22229228}]}]}
{"op":"mcm","clk":"1000105322","pt":1580607100305,"mc":[{"id":"1.168081817","rc":[{"trd":[[2.66,78.65]],"batb":[[0,2.64,15.68],[1,2.62,32.71],[2,2.56,78.75]],"ltp":2.66,"tv":1205.86,"id":15256065},{"trd":[[1.6,1062.21]],"batl":[[0,1.6,227.5]],"ltp":1.6,"tv":9970.75,"id":22229228}],"tv":11176.61}]}
{"op":"mcm","clk":"1000105363","pt":1580607100978,"mc":[{"id":"1.168081817","rc":[{"batl":[[0,1.6,222.84]],"ltp":1.6,"tv":9970.75,"id":22229228}]}]}
{"op":"mcm","clk":"1000109267","pt":1580607194043,"mc":[{"id":"1.168081817","rc":[{"trd":[[2.66,80.65]],"ltp":2.66,"tv":1207.86,"id":15256065},{"trd":[[1.6,1065.54]],"batl":[[0,1.6,219.51]],"ltp":1.6,"tv":9974.08,"id":22229228}],"tv":11181.94}]}
{"op":"mcm","clk":"1000110806","pt":1580607230887,"mc":[{"id":"1.168081817","rc":[{"batb":[[0,2.66,2.82],[1,2.64,15.68],[2,2.62,32.71]],"ltp":2.66,"tv":1207.86,"id":15256065},{"batl":[[0,1.6,224.2]],"ltp":1.6,"tv":9974.08,"id":22229228}]}]}
{"op":"mcm","clk":"1000134540","pt":1580607823130,"mc":[{"id":"1.168081817","rc":[{"trd":[[2.76,149.86]],"batb":[[0,2.76,38.72],[1,2.66,2.82],[2,2.64,15.68]],"ltp":2.76,"tv":1210.47,"id":15256065},{"trd":[[1.57,2499.99]],"batb":[[0,1.56,6.13],[1,1.53,55.97],[2,1.51,703.84]],"ltp":1.57,"tv":9978.68,"id":22229228}],"tv":11189.15}]}
{"op":"mcm","clk":"1000134572","pt":1580607824159,"mc":[{"id":"1.168081817","rc":[{"batb":[[1,2.72,2.77],[2,2.7,2.79]],"ltp":2.76,"tv":1210.47,"id":15256065},{"batb":[[1,1.55,4.86],[2,1.53,77.67]],"batl":[[0,1.59,4.74],[1,1.6,224.2],[2,1.61,4.48]],"ltp":1.57,"tv":9978.68,"id":22229228}]}]}
{"op":"mcm","clk":"1000135812","pt":1580607859065,"mc":[{"id":"1.168081817","rc":[{"batb":[[1,2.74,2.75],[2,2.72,2.77]],"ltp":2.76,"tv":1210.47,"id":15256065}]}]}
{"op":"mcm","clk":"1000138284","pt":1580607921337,"mc":[{"id":"1.168081817","rc":[{"trd":[[2.76,167.87]],"batb":[[0,2.76,29.71]],"ltp":2.76,"tv":1228.48,"id":15256065},{"batb":[[2,1.53,61.66]],"ltp":1.57,"tv":9978.68,"id":22229228}],"tv":11207.16}]}
{"op":"mcm","clk":"1000145640","pt":1580608111588,"mc":[{"id":"1.168081817","rc":[{"trd":[[1.56,243.43]],"batb":[[0,1.55,4.86],[1,1.53,61.66],[2,1.51,703.84]],"batl":[[0,1.56,15.88],[1,1.59,4.74],[2,1.6,224.2]],"ltp":1.56,"tv":9990.92,"id":22229228}],"tv":11219.41}]}
{"op":"mcm","clk":"1000145679","pt":1580608112615,"mc":[{"id":"1.168081817","rc":[{"batb":[[0,2.76,32.45]],"ltp":2.76,"tv":1228.48,"id":15256065},{"batb":[[1,1.54,4.91],[2,1.53,61.66]],"batl":[[1,1.57,4.81],[2,1.58,4.78]],"ltp":1.56,"tv":9990.92,"id":22229228}]}]}
{"op":"mcm","clk":"1000145708","pt":1580608113389,"mc":[{"id":"1.168081817","rc":[{"batl":[[1,1.57,6.3]],"ltp":1.56,"tv":9990.92,"id":22229228}]}]}
{"op":"mcm","clk":"1000147768","pt":1580608165575,"mc":[{"id":"1.168081817","rc":[{"trd":[[1.56,259.13]],"batb":[[2,1.53,53.75]],"batl":[[0,1.56,8.03]],"ltp":1.56,"tv":10006.62,"id":22229228}],"tv":11235.1}]}
{"op":"mcm","clk":"1000173800","pt":1580608826332,"mc":[{"id":"1.168081817","rc":[{"batb":[[0,2.76,29.71]],"ltp":2.76,"tv":1228.48,"id":15256065},{"trd":[[1.56,275.19]],"batb":[[0,1.56,11.45],[1,1.55,4.86],[2,1.54,4.91]],"batl":[[0,1.57,1.5],[1,1.58,4.78],[2,1.59,104.74]],"ltp":1.56,"tv":10022.68,"id":22229228}],"tv":11251.16}]}
{"op":"mcm","clk":"1000175295","pt":1580608864388,"mc":[{"id":"1.168081817","rc":[{"batb":[[1,2.74,13.84]],"batl":[[0,2.88,10.55],[1,2.9,2.46],[2,2.92,29.83]],"ltp":2.76,"tv":1228.48,"id":15256065},{"batb":[[2,1.54,24.64]],"batl":[[1,1.58,24.01]],"ltp":1.56,"tv":10022.68,"id":22229228}]}]}
{"op":"mcm","clk":"1000175336","pt":1580608865167,"mc":[{"id":"1.168081817","rc":[{"batl":[[0,2.86,2.66],[1,2.88,13.19],[2,2.9,2.46]],"ltp":2.76,"tv":1228.48,"id":15256065},{"batb":[[0,1.56,16.31]],"ltp":1.56,"tv":10022.68,"id":22229228}]}]}
{"op":"mcm","clk":"1000176916","pt":1580608901872,"mc":[{"id":"1.168081817","rc":[{"batb":[[1,2.74,21.75]],"ltp":2.76,"tv":1228.48,"id":15256065}]}]}
{"op":"mcm","clk":"1000177519","pt":1580608917693,"mc":[{"id":"1.168081817","rc":[{"batb":[[2,2.72,4.86]],"batl":[[0,2.84,2.03],[1,2.86,4.91],[2,2.88,13.19]],"ltp":2.76,"tv":1228.48,"id":15256065},{"batb":[[2,1.54,26.66]],"ltp":1.56,"tv":10022.68,"id":22229228}]}]}
{"op":"mcm","clk":"1000177552","pt":1580608918621,"mc":[{"id":"1.168081817","rc":[{"batl":[[0,2.84,4.7]],"ltp":2.76,"tv":1228.48,"id":15256065},{"batl":[[1,1.58,4.78]],"ltp":1.56,"tv":10022.68,"id":22229228}]}]}
{"op":"mcm","clk":"1000178272","pt":1580608938419,"mc":[{"id":"1.168081817","rc":[{"batl":[[1,2.86,4.69]],"ltp":2.76,"tv":1228.48,"id":15256065}]}]}
{"op":"mcm","clk":"1000181364","pt":1580609023597,"mc":[{"id":"1.168081817","rc":[{"batb":[[1,2.74,13.84]],"batl":[[1,2.86,2.66]],"ltp":2.76,"tv":1228.48,"id":15256065}]}]}
{"op":"mcm","clk":"1000181380","pt":1580609023907,"mc":[{"id":"1.168081817","rc":[{"batl":[[1,2.86,6.94]],"ltp":2.76,"tv":1228.48,"id":15256065}]}]}
{"op":"mcm","clk":"1000186502","pt":1580609153444,"mc":[{"id":"1.168081817","rc":[{"batb":[[0,2.76,32.71],[1,2.74,16.84]],"batl":[[0,2.82,3],[1,2.84,4.7],[2,2.86,4.69]],"ltp":2.76,"tv":1228.48,"id":15256065},{"batb":[[1,1.55,10.86],[2,1.54,32.66]],"batl":[[0,1.57,5.5],[1,1.58,8.78],[2,1.59,110.8]],"ltp":1.56,"tv":10022.68,"id":22229228}]}]}
{"op":"mcm","clk":"1000186523","pt":1580609153958,"mc":[{"id":"1.168081817","rc":[{"batl":[[0,2.82,5.7]],"ltp":2.76,"tv":1228.48,"id":15256065}]}]}
{"op":"mcm","clk":"1000198184","pt":1580609465486,"mc":[{"id":"1.168081817","rc":[{"batl":[[2,2.86,4.91]],"ltp":2.76,"tv":1228.48,"id":15256065}]}]}
{"op":"mcm","clk":"1000203367","pt":1580609590611,"mc":[{"id":"1.168081817","rc":[{"batb":[[0,2.78,10.16],[1,2.76,32.71],[2,2.74,16.84]],"batl":[[0,2.82,2.7],[1,2.84,5.67],[2,2.86,4.69]],"ltp":2.76,"tv":1228.48,"id":15256065},{"trd":[[1.56,307.8]],"batb":[[0,1.55,4.86],[1,1.54,30.64],[2,1.53,62.75]],"batl":[[0,1.56,27.69],[1,1.57,5.5],[2,1.58,11.03]],"ltp":1.56,"tv":10055.29,"id":22229228}],"tv":11283.77}]}
{"op":"mcm","clk":"1000203378","pt":1580609590818,"mc":[{"id":"1.168081817","rc":[{"batb":[[1,2.76,35.48]],"ltp":2.76,"tv":1228.48,"id":15256065},{"batl":[[1,1.57,10.36]],"ltp":1.56,"tv":10055.29,"id":22229228}]}]}
{"op":"mcm","clk":"1000204015","pt":1580609604568,"mc":[{"id":"1.168081817","rc":[{"batb":[[0,2.78,10.04]],"ltp":2.76,"tv":1228.48,"id":15256065},{"batl":[[1,1.57,29.72]],"ltp":1.56,"tv":10055.29,"id":22229228}]}]}
{"op":"mcm","clk":"1000204200","pt":1580609608658,"mc":[{"id":"1.168081817","rc":[{"batb":[[0,2.78,10.01],[2,2.74,5.75]],"ltp":2.76,"tv":1228.48,"id":15256065}]}]}
{"op":"mcm","clk":"1000206695","pt":1580609663594,"mc":[{"id":"1.168081817","rc":[{"trd":[[2.78,114.96]],"batb":[[0,2.78,4],[2,2.74,7.77]],"batl":[[1,2.84,7.67]],"ltp":2.78,"tv":1263.82,"id":15256065},{"trd":[[1.56,335.12]],"batb":[[1,1.54,34.64]],"batl":[[0,1.56,6]],"ltp":1.56,"tv":10082.61,"id":22229228}],"tv":11346.43}]}
{"op":"mcm","clk":"1000207150","pt":1580609673501,"mc":[{"id":"1.168081817","rc":[{"trd":[[2.78,125.91]],"batb":[[2,2.74,5.75]],"ltp":2.78,"tv":1274.77,"id":15256065},{"trd":[[1.56,340.4]],"batb":[[2,1.53,67.75]],"batl":[[0,1.56,5],[2,1.58,8.78]],"ltp":1.56,"tv":10087.89,"id":22229228}],"tv":11362.67}]}
{"op":"mcm","clk":"1000207174","pt":1580609673910,"mc":[{"id":"1.168081817","rc":[{"batb":[[2,2.74,7.75]],"ltp":2.78,"tv":1274.77,"id":15256065},{"batl":[[2,1.58,10.91]],"ltp":1.56,"tv":10087.89,"id":22229228}]}]}
{"op":"mcm","clk":"1000207256","pt":1580609675503,"mc":[{"id":"1.168081817","rc":[{"batl":[[1,1.57,10.36]],"ltp":1.56,"tv":10087.89,"id":22229228}]}]}
{"op":"mcm","clk":"1000207289","pt":1580609676325,"mc":[{"id":"1.168081817","rc":[{"batb":[[1,1.54,43.4]],"ltp":1.56,"tv":10087.89,"id":22229228}]}]}
{"op":"mcm","clk":"1000207305","pt":1580609676746,"mc":[{"id":"1.168081817","rc":[{"batb":[[1,1.54,52.22]],"ltp":1.56,"tv":10087.89,"id":22229228}]}]}
{"op":"mcm","clk":"1000207352","pt":1580609677825,"mc":[{"id":"1.168081817","rc":[{"batb":[[2,1.53,56.61]],"ltp":1.56,"tv":10087.89,"id":22229228}]}]}
{"op":"mcm","clk":"1000209327","pt":1580609718218,"mc":[{"id":"1.168081817","rc":[{"batb":[[1,1.54,60.98]],"ltp":1.56,"tv":10087.89,"id":22229228}]}]}
{"op":"mcm","clk":"1000252696","pt":1580610704668,"mc":[{"id":"1.168081817","rc":[{"trd":[[1.54,336.09],[1.55,85.62]],"batb":[[0,1.54,35.58],[1,1.53,54.61],[2,1.52,2]],"ltp":1.54,"tv":10148.44,"id":22229228}],"tv":11423.22}]}
{"op":"mcm","clk":"1000252753","pt":1580610705456,"mc":[{"id":"1.168081817","rc":[{"batb":[[0,2.78,6.77]],"batl":[[0,2.84,2.67],[1,2.86,8.66],[2,2.88,4.68]],"ltp":2.78,"tv":1274.77,"id":15256065},{"batb":[[0,1.54,31.82],[1,1.53,59.65]],"batl":[[0,1.56,9.95]],"ltp":1.54,"tv":10148.44,"id":22229228}]}]}
{"op":"mcm","clk":"1000252820","pt":1580610706657,"mc":[{"id":"1.168081817","rc":[{"batb":[[0,1.54,23.01]],"batl":[[0,1.56,29.43]],"ltp":1.54,"tv":10148.44,"id":22229228}]}]}
{"op":"mcm","clk":"1000252878","pt":1580610707649,"mc":[{"id":"1.168081817","rc":[{"batb":[[0,2.8,4.25],[1,2.78,6.77],[2,2.76,37.63]],"ltp":2.78,"tv":1274.77,"id":15256065}]}]}
{"op":"mcm","clk":"1000253144","pt":1580610712657,"mc":[{"id":"1.168081817","rc":[{"batb":[[1,2.78,17.7]],"ltp":2.78,"tv":1274.77,"id":15256065}]}]}
{"op":"mcm","clk":"1000256091","pt":1580610775537,"mc":[{"id":"1.168081817","rc":[{"batl":[[0,1.56,24.48]],"ltp":1.54,"tv":10148.44,"id":22229228}]}]}
{"op":"mcm","clk":"1000258673","pt":1580610831599,"mc":[{"id":"1.168081817","rc":[{"batb":[[0,1.54,33.8]],"ltp":1.54,"tv":10148.44,"id":22229228}]}]}
{"op":"mcm","clk":"1000268422","pt":1580611040701,"mc":[{"id":"1.168081817","rc":[{"trd":[[1.54,403.29]],"batb":[[0,1.53,59.86],[1,1.52,11.28],[2,1.51,703.84]],"ltp":1.54,"tv":10215.65,"id":22229228}],"tv":11490.42}]}
{"op":"mcm","clk":"1000268457","pt":1580611041628,"mc":[{"id":"1.168081817","rc":[{"batb":[[0,2.8,7.01]],"batl":[[0,2.86,8.66],[1,2.88,2.64],[2,2.9,2.05]],"ltp":2.78,"tv":1274.77,"id":15256065},{"batb":[[0,1.54,58.57],[1,1.53,59.65],[2,1.52,13.42]],"batl":[[0,1.56,29.45]],"ltp":1.54,"tv":10215.65,"id":22229228}]}]}
{"op":"mcm","clk":"1000271820","pt":1580611134578,"mc":[{"id":"1.168081817","rc":[{"batb":[[0,2.8,4.25]],"ltp":2.78,"tv":1274.77,"id":15256065}]}]}
{"op":"mcm","clk":"1000272152","pt":1580611142689,"mc":[{"id":"1.168081817","rc":[{"trd":[[1.56,350.58]],"batl":[[0,1.56,24.35]],"ltp":1.56,"tv":10225.83,"id":22229228}],"tv":11500.6}]}
{"op":"mcm","clk":"1000272178","pt":1580611143202,"mc":[{"id":"1.168081817","rc":[{"batb":[[2,2.76,39.63]],"ltp":2.78,"tv":1274.77,"id":15256065},{"batl":[[0,1.56,30.35]],"ltp":1.56,"tv":10225.83,"id":22229228}]}]}
{"op":"mcm","clk":"1000273880","pt":1580611188468,"mc":[{"id":"1.168081817","rc":[{"batl":[[0,1.56,30.45]],"ltp":1.56,"tv":10225.83,"id":22229228}]}]}
{"op":"mcm","clk":"1000351189","pt":1580612888969,"mc":[{"id":"1.168081817","marketDefinition":{"bspMarket":false,"turnInPlayEnabled":true,"persistenceEnabled":true,"marketBaseRate":5.0,"eventId":"29676917","eventTypeId":"2","numberOfWinners":1,"bettingType":"ODDS","marketType":"MATCH_ODDS","marketTime":"2020-02-02T04:00:00.000Z","suspendTime":"2020-02-02T04:00:00.000Z","bspReconciled":false,"complete":true,"inPlay":false,"crossMatching":true,"runnersVoidable":false,"numberOfActiveRunners":2,"betDelay":0,"status":"OPEN","runners":[{"status":"ACTIVE","sortPriority":1,"id":22229228,"name":"Ram/Salisbury"},{"status":"ACTIVE","sortPriority":2,"id":15256065,"name":"Purcell/Saville"}],"regulators":["MR_INT"],"countryCode":"AU","discountAllowed":true,"timezone":"GMT","openDate":"2020-02-02T05:00:00.000Z","version":3148089676,"name":"Match Odds","eventName":"Ram/Salisbury v Purcell/Saville"}}]}
{"op":"mcm","clk":"1000351354","pt":1580612891105,"mc":[{"id":"1.168081817","marketDefinition":{"bspMarket":false,"turnInPlayEnabled":true,"persistenceEnabled":true,"marketBaseRate":5.0,"eventId":"29676917","eventTypeId":"2","numberOfWinners":1,"bettingType":"ODDS","marketType":"MATCH_ODDS","marketTime":"2020-02-02T04:00:00.000Z","suspendTime":"2020-02-02T04:00:00.000Z","bspReconciled":false,"complete":true,"inPlay":false,"crossMatching":true,"runnersVoidable":false,"numberOfActiveRunners":2,"betDelay":0,"status":"OPEN","runners":[{"status":"ACTIVE","sortPriority":1,"id":22229228,"name":"Ram/Salisbury"},{"status":"ACTIVE","sortPriority":2,"id":15256065,"name":"Purcell/Saville"}],"regulators":["MR_INT"],"countryCode":"AU","discountAllowed":true,"timezone":"GMT","openDate":"2020-02-02T04:00:00.000Z","version":3148089676,"name":"Match Odds","eventName":"Ram/Salisbury v Purcell/Saville"},"rc":[{"batb":[[1,1.53,57.71]],"batl":[[1,1.57,8.86]],"ltp":1.56,"tv":10225.83,"id":22229228}]}]}
{"op":"mcm","clk":"1000352544","pt":1580612911512,"mc":[{"id":"1.168081817","rc":[{"batb":[[0,2.78,13.7],[1,2.76,32.48],[2,2.74,4.77]],"ltp":2.78,"tv":1274.77,"id":15256065},{"batl":[[0,1.55,1.5],[1,1.56,24.45],[2,1.57,4.86]],"ltp":1.56,"tv":10225.83,"id":22229228}]}]}
{"op":"mcm","clk":"1000352602","pt":1580612912639,"mc":[{"id":"1.168081817","rc":[{"batb":[[0,2.78,18.7],[1,2.76,37.48]],"ltp":2.78,"tv":1274.77,"id":15256065},{"trd":[[1.55,88.61]],"batb":[[0,1.55,3.6],[1,1.54,58.57],[2,1.53,59.87]],"batl":[[0,1.56,26.48],[1,1.57,11.86],[2,1.58,13.91]],"ltp":1.55,"tv":10228.82,"id":22229228}],"tv":11503.6}]}
{"op":"mcm","clk":"1000377526","pt":1580613346456,"mc":[{"id":"1.168081817","rc":[{"trd":[[1.56,389.52]],"batl":[[0,1.56,7.02]],"ltp":1.56,"tv":10267.76,"id":22229228}],"tv":11542.54}]}
{"op":"mcm","clk":"1000377553","pt":1580613347031,"mc":[{"id":"1.168081817","rc":[{"batb":[[0,2.78,15.93]],"ltp":2.78,"tv":1274.77,"id":15256065}]}]}
{"op":"mcm","clk":"1000377653","pt":1580613349043,"mc":[{"id":"1.168081817","rc":[{"batb":[[0,2.78,5]],"ltp":2.78,"tv":1274.77,"id":15256065},{"batl":[[0,1.56,7]],"ltp":1.56,"tv":10267.76,"id":22229228}]}]}
{"op":"mcm","clk":"1000379185","pt":1580613382272,"mc":[{"id":"1.168081817","rc":[{"batl":[[0,1.56,17.38]],"ltp":1.56,"tv":10267.76,"id":22229228}]}]}
{"op":"mcm","clk":"1000407185","pt":1580613934699,"mc":[{"id":"1.168081817","rc":[{"trd":[[2.74,172.69],[2.76,242.84],[2.78,145.67]],"batb":[[0,2.7,15.18],[1,2.68,3.2],[2,2.66,7.23]],"batl":[[0,2.74,931.46],[1,2.76,9.18],[2,2.78,11.2]],"ltp":2.74,"tv":1407.56,"id":15256065},{"trd":[[1.56,406.9],[1.57,2521.86]],"batb":[[0,1.58,17.18],[1,1.57,17],[2,1.56,17]],"batl":[[0,1.59,100],[1,1.6,230.89],[2,1.61,7.48]],"ltp":1.57,"tv":10307.0,"id":22229228}],"tv":11714.57}]}
{"op":"mcm","clk":"1000407235","pt":1580613935627,"mc":[{"id":"1.168081817","rc":[{"batb":[[1,2.66,7.23],[2,2.64,3.25]],"ltp":2.74,"tv":1407.56,"id":15256065},{"batb":[[0,1.58,19.42],[1,1.57,27.29],[2,1.56,19.08]],"batl":[[1,1.6,228.88]],"ltp":1.57,"tv":10307.0,"id":22229228}]}]}
{"op":"mcm","clk":"1000407252","pt":1580613935933,"mc":[{"id":"1.168081817","rc":[{"batl":[[0,2.72,9.19],[1,2.74,931.46],[2,2.76,11.2]],"ltp":2.74,"tv":1407.56,"id":15256065},{"batb":[[0,1.58,60.83]],"batl":[[2,1.61,11.48]],"ltp":1.57,"tv":10307.0,"id":22229228}]}]}
{"op":"mcm","clk":"1000407454","pt":1580613940615,"mc":[{"id":"1.168081817","rc":[{"batb":[[2,1.56,24.59]],"ltp":1.57,"tv":10307.0,"id":22229228}]}]}
{"op":"mcm","clk":"1000407672","pt":1580613945519,"mc":[{"id":"1.168081817","rc":[{"trd":[[2.66,213.37],[2.68,228.79],[2.7,120.61]],"batb":[[0,2.66,3],[1,2.64,3.25],[2,2.52,78.75]],"batl":[[0,2.72,15],[1,2.74,937.46],[2,2.76,17.02]],"ltp":2.66,"tv":1629.97,"id":15256065},{"trd":[[1.59,1295.35],[1.6,1262.15]],"batb":[[0,1.58,72.65],[1,1.57,40.29],[2,1.56,37.59]],"batl":[[0,1.6,28.27],[1,1.61,15.34],[2,1.62,2.25]],"ltp":1.6,"tv":10603.61,"id":22229228}],"tv":12233.58}]}
{"op":"mcm","clk":"1000407737","pt":1580613946502,"mc":[{"id":"1.168081817","rc":[{"batb":[[0,2.64,8.25],[1,2.62,3.29],[2,2.6,3.32]],"ltp":2.66,"tv":1629.97,"id":15256065},{"batb":[[0,1.58,79.94]],"batl":[[0,1.6,22.9],[2,1.62,7.58]],"ltp":1.6,"tv":10603.61,"id":22229228}]}]}
{"op":"mcm","clk":"1000407863","pt":1580613948615,"mc":[{"id":"1.168081817","rc":[{"batb":[[0,2.64,3.27],[1,2.62,11.29]],"batl":[[0,2.7,15.26],[1,2.72,15],[2,2.74,939.63]],"ltp":2.66,"tv":1629.97,"id":15256065},{"batb":[[0,1.59,39.43],[1,1.58,79.94],[2,1.57,37.55]],"batl":[[1,1.61,15.36],[2,1.62,17.58]],"ltp":1.6,"tv":10603.61,"id":22229228}]}]}
{"op":"mcm","clk":"1000407931","pt":1580613949694,"mc":[{"id":"1.168081817","rc":[{"batb":[[0,2.62,51.22],[1,2.6,3.32],[2,2.54,32.33]],"ltp":2.66,"tv":1629.97,"id":15256065}]}]}
{"op":"mcm","clk":"1000407974","pt":1580613950519,"mc":[{"id":"1.168081817","rc":[{"batb":[[0,2.64,3.27],[1,2.62,51.22],[2,2.6,15.32]],"ltp":2.66,"tv":1629.97,"id":15256065},{"batl":[[1,1.61,19.36],[2,1.62,21.58]],"ltp":1.6,"tv":10603.61,"id":22229228}]}]}
{"op":"mcm","clk":"1000408043","pt":1580613951604,"mc":[{"id":"1.168081817","rc":[{"batl":[[2,2.74,942.78]],"ltp":2.66,"tv":1629.97,"id":15256065}]}]}
{"op":"mcm","clk":"1000408194","pt":1580613954534,"mc":[{"id":"1.168081817","rc":[{"batb":[[0,2.64,16.56],[1,2.62,56.22]],"batl":[[2,2.74,20.32]],"ltp":2.66,"tv":1629.97,"id":15256065}]}]}
{"op":"mcm","clk":"1000408341","pt":1580613957421,"mc":[{"id":"1.168081817","rc":[{"batb":[[1,1.58,85.4]],"ltp":1.6,"tv":10603.61,"id":22229228}]}]}
{"op":"mcm","clk":"1000408431","pt":1580613959222,"mc":[{"id":"1.168081817","rc":[{"batb":[[1,2.62,16.29]],"ltp":2.66,"tv":1629.97,"id":15256065}]}]}
{"op":"mcm","clk":"1000408516","pt":1580613960662,"mc":[{"id":"1.168081817","rc":[{"batl":[[1,2.72,18.18]],"ltp":2.66,"tv":1629.97,"id":15256065}]}]}
{"op":"mcm","clk":"1000408573","pt":1580613961643,"mc":[{"id":"1.168081817","rc":[{"trd":[[2.64,113.46],[2.66,227.14]],"batb":[[0,2.62,16.29],[1,2.6,15.32],[2,2.56,11.87]],"batl":[[0,2.7,23],[1,2.72,25.18],[2,2.74,27.32]],"ltp":2.64,"tv":1674.19,"id":15256065},{"trd":[[1.6,1285.05]],"batb":[[0,1.59,54.17],[1,1.58,100.4],[2,1.57,52.55]],"batl":[[0,1.61,5.36],[1,1.62,19.33],[2,1.63,24.33]],"ltp":1.6,"tv":10626.51,"id":22229228}],"tv":12300.71}]}
{"op":"mcm","clk":"1000408594","pt":1580613961960,"mc":[{"id":"1.168081817","rc":[{"batb":[[0,2.62,13],[2,2.58,3.34]],"ltp":2.64,"tv":1674.19,"id":15256065},{"batl":[[0,1.62,19.33],[1,1.63,22.29],[2,1.64,10.84]],"ltp":1.6,"tv":10626.51,"id":22229228}]}]}
{"op":"mcm","clk":"1000408664","pt":1580613963238,"mc":[{"id":"1.168081817","rc":[{"batl":[[0,1.62,14],[2,1.64,16.1]],"ltp":1.6,"tv":10626.51,"id":22229228}]}]}
{"op":"mcm","clk":"1000408708","pt":1580613964114,"mc":[{"id":"1.168081817","rc":[{"batb":[[0,2.62,52.93]],"ltp":2.64,"tv":1674.19,"id":15256065}]}]}
{"op":"mcm","clk":"1000409447","pt":1580613978440,"mc":[{"id":"1.168081817","rc":[{"batl":[[0,2.7,26.2]],"ltp":2.64,"tv":1674.19,"id":15256065},{"batl":[[0,1.62,19.34]],"ltp":1.6,"tv":10626.51,"id":22229228}]}]}
{"op":"mcm","clk":"1000409471","pt":1580613978953,"mc":[{"id":"1.168081817","rc":[{"batl":[[0,1.62,14]],"ltp":1.6,"tv":10626.51,"id":22229228}]}]}
{"op":"mcm","clk":"1000409538","pt":1580613980248,"mc":[{"id":"1.168081817","rc":[{"batb":[[0,1.59,59.6]],"batl":[[0,1.62,19.34]],"ltp":1.6,"tv":10626.51,"id":22229228}]}]}
{"op":"mcm","clk":"1000410318","pt":1580613996090,"mc":[{"id":"1.168081817","rc":[{"batb":[[0,2.62,56.23]],"ltp":2.64,"tv":1674.19,"id":15256065}]}]}
{"op":"mcm","clk":"1000410384","pt":1580613997380,"mc":[{"id":"1.168081817","rc":[{"batl":[[2,1.64,7.45]],"ltp":1.6,"tv":10626.51,"id":22229228}]}]}
{"op":"mcm","clk":"1000410765","pt":1580614004694,"mc":[{"id":"1.168081817","rc":[{"batl":[[0,1.61,16.2],[1,1.62,19.34],[2,1.63,24.33]],"ltp":1.6,"tv":10626.51,"id":22229228}]}]}
{"op":"mcm","clk":"1000410876","pt":1580614006396,"mc":[{"id":"1.168081817","rc":[{"batb":[[0,2.64,12.25],[1,2.62,56.23],[2,2.6,15.32]],"ltp":2.64,"tv":1674.19,"id":15256065},{"batb":[[0,1.59,79.21]],"ltp":1.6,"tv":10626.51,"id":22229228}]}]}
{"op":"mcm","clk":"1000410941","pt":1580614007690,"mc":[{"id":"1.168081817","rc":[{"batl":[[0,2.68,3.23],[1,2.7,26.2],[2,2.72,27.19]],"ltp":2.64,"tv":1674.19,"id":15256065},{"batb":[[0,1.6,5.4],[1,1.59,79.21],[2,1.58,102.46]],"ltp":1.6,"tv":10626.51,"id":22229228}]}]}
{"op":"mcm","clk":"1000410985","pt":1580614008616,"mc":[{"id":"1.168081817","rc":[{"batb":[[0,2.62,56.23],[1,2.6,15.32],[2,2.58,3.34]],"batl":[[0,2.68,24.49]],"ltp":2.64,"tv":1674.19,"id":15256065},{"batb":[[0,1.59,79.21],[1,1.58,100.4],[2,1.57,52.51]],"batl":[[0,1.62,19.34],[1,1.63,22.29],[2,1.64,22.45]],"ltp":1.6,"tv":10626.51,"id":22229228}]}]}
{"op":"mcm","clk":"1000411050","pt":1580614009703,"mc":[{"id":"1.168081817","rc":[{"trd":[[2.68,251.51]],"batb":[[0,2.64,12.27],[1,2.62,52.93],[2,2.6,15.32]],"batl":[[0,2.7,3.2],[1,2.72,3.18],[2,2.74,5.4]],"ltp":2.68,"tv":1696.91,"id":15256065},{"batb":[[0,1.6,2.22],[1,1.59,79.21],[2,1.58,100.16]],"batl":[[0,1.61,16.27],[1,1.62,19.34],[2,1.63,24.33]],"ltp":1.6,"tv":10626.51,"id":22229228}],"tv":12323.43}]}
{"op":"mcm","clk":"1000411092","pt":1580614010626,"mc":[{"id":"1.168081817","rc":[{"batb":[[0,2.64,15.55],[1,2.62,56.23]],"batl":[[0,2.7,22.2]],"ltp":2.68,"tv":1696.91,"id":15256065},{"batb":[[0,1.59,81.44],[1,1.58,98.16],[2,1.57,52.51]],"batl":[[0,1.61,21.64]],"ltp":1.6,"tv":10626.51,"id":22229228}]}]}
{"op":"mcm","clk":"1000411156","pt":1580614011703,"mc":[{"id":"1.168081817","rc":[{"batl":[[0,2.68,3.23],[1,2.7,22.2],[2,2.72,24.62]],"ltp":2.68,"tv":1696.91,"id":15256065},{"batl":[[0,1.61,40.52]],"ltp":1.6,"tv":10626.51,"id":22229228}]}]}
{"op":"mcm","clk":"1000411176","pt":1580614012013,"mc":[{"id":"1.168081817","rc":[{"trd":[[2.68,257.73]],"batl":[[0,2.7,22.32],[1,2.72,22.46],[2,2.74,5.4]],"ltp":2.68,"tv":1703.13,"id":15256065}],"tv":12329.65}]}
{"op":"mcm","clk":"1000411325","pt":1580614014495,"mc":[{"id":"1.168081817","rc":[{"batb":[[0,2.64,3.28],[1,2.62,16.3]],"ltp":2.68,"tv":1703.13,"id":15256065},{"batl":[[0,1.61,24.25]],"ltp":1.6,"tv":10626.51,"id":22229228}]}]}
{"op":"mcm","clk":"1000411358","pt":1580614015014,"mc":[{"id":"1.168081817","rc":[{"batb":[[0,2.64,14.77]],"ltp":2.68,"tv":1703.13,"id":15256065},{"batb":[[1,1.58,90.87],[2,1.57,69.12]],"ltp":1.6,"tv":10626.51,"id":22229228}]}]}
{"op":"mcm","clk":"1000411486","pt":1580614017638,"mc":[{"id":"1.168081817","rc":[{"batb":[[1,2.62,28.17]],"ltp":2.68,"tv":1703.13,"id":15256065}]}]}
{"op":"mcm","clk":"1000411508","pt":1580614018000,"mc":[{"id":"1.168081817","rc":[{"batl":[[0,1.61,38.25]],"ltp":1.6,"tv":10626.51,"id":22229228}]}]}
{"op":"mcm","clk":"1000413221","pt":1580614050618,"mc":[{"id":"1.168081817","rc":[{"trd":[[2.64,141.46]],"batb":[[0,2.62,24.87],[1,2.6,15.32],[2,2.58,3.34]],"ltp":2.64,"tv":1731.13,"id":15256065},{"batl":[[0,1.61,18.88]],"ltp":1.6,"tv":10626.51,"id":22229228}],"tv":12357.64}]}
{"op":"mcm","clk":"1000413275","pt":1580614051505,"mc":[{"id":"1.168081817","rc":[{"batb":[[1,2.6,24.11]],"batl":[[0,2.68,18.29],[1,2.7,22.2],[2,2.72,22.46]],"ltp":2.64,"tv":1731.13,"id":15256065},{"batb":[[0,1.59,97.41],[2,1.57,41.51]],"batl":[[0,1.62,19.34],[1,1.63,17.29],[2,1.64,22.28]],"ltp":1.6,"tv":10626.51,"id":22229228}]}]}
{"op":"mcm","clk":"1000413314","pt":1580614052078,"mc":[{"id":"1.168081817","rc":[{"batl":[[2,2.72,24.62]],"ltp":2.64,"tv":1731.13,"id":15256065},{"batl":[[0,1.62,14]],"ltp":1.6,"tv":10626.51,"id":22229228}]}]}
{"op":"mcm","clk":"1000413441","pt":1580614054293,"mc":[{"id":"1.168081817","rc":[{"batb":[[0,2.62,39.93],[1,2.6,35.98]],"ltp":2.64,"tv":1731.13,"id":15256065}]}]}
{"op":"mcm","clk":"1000413524","pt":1580614055691,"mc":[{"id":"1.168081817","rc":[{"batb":[[0,2.62,48.93]],"ltp":2.64,"tv":1731.13,"id":15256065},{"batb":[[0,1.6,5.42],[1,1.59,86.41],[2,1.58,81.93]],"batl":[[0,1.62,19.35]],"ltp":1.6,"tv":10626.51,"id":22229228}]}]}
{"op":"mcm","clk":"1000413727","pt":1580614059624,"mc":[{"id":"1.168081817","rc":[{"batl":[[0,2.7,22.32],[1,2.72,24.62],[2,2.74,3.15]],"ltp":2.64,"tv":1731.13,"id":15256065},{"batb":[[1,1.59,66.8]],"batl":[[0,1.61,12.21],[1,1.62,19.35],[2,1.63,17.29]],"ltp":1.6,"tv":10626.51,"id":22229228}]}]}
{"op":"mcm","clk":"1000413792","pt":1580614060600,"mc":[{"id":"1.168081817","rc":[{"batl":[[0,2.68,18.12],[1,2.7,24.25],[2,2.72,24.51]],"ltp":2.64,"tv":1731.13,"id":15256065},{"batl":[[0,1.62,19.35],[1,1.63,17.29],[2,1.64,22.28]],"ltp":1.6,"tv":10626.51,"id":22229228}]}]}
{"op":"mcm","clk":"1000413849","pt":1580614061605,"mc":[{"id":"1.168081817","rc":[{"batb":[[0,2.62,52.24]],"batl":[[0,2.66,3.26],[1,2.68,18.12],[2,2.7,24.21]],"ltp":2.64,"tv":1731.13,"id":15256065},{"batl":[[0,1.61,12.22],[1,1.62,19.35],[2,1.63,17.29]],"ltp":1.6,"tv":10626.51,"id":22229228}]}]}
{"op":"mcm","clk":"1000413904","pt":1580614062689,"mc":[{"id":"1.168081817","rc":[{"batb":[[0,2.62,48.93]],"batl":[[0,2.68,18.12],[1,2.7,24.21],[2,2.72,24.62]],"ltp":2.64,"tv":1731.13,"id":15256065},{"batl":[[0,1.62,19.35],[1,1.63,17.29],[2,1.64,22.31]],"ltp":1.6,"tv":10626.51,"id":22229228}]}]}
{"op":"mcm","clk":"1000413954","pt":1580614063628,"mc":[{"id":"1.168081817","rc":[{"batb":[[0,2.62,52.24],[2,2.58,13.34]],"batl":[[0,2.7,702.32],[1,2.72,24.51],[2,2.74,2.25]],"ltp":2.64,"tv":1731.13,"id":15256065},{"batb":[[0,1.61,20.23],[1,1.6,38.65],[2,1.59,66.8]],"ltp":1.6,"tv":10626.51,"id":22229228}]}]}
{"op":"mcm","clk":"1000414015","pt":1580614064698,"mc":[{"id":"1.168081817","rc":[{"batb":[[0,2.6,32.98],[1,2.58,13.34],[2,2.56,10]],"batl":[[0,2.66,21.49],[1,2.68,19.26],[2,2.7,704.25]],"ltp":2.64,"tv":1731.13,"id":15256065},{"batb":[[0,1.6,38.65],[1,1.59,66.8],[2,1.58,81.93]],"batl":[[0,1.63,17.29],[1,1.64,20.27],[2,1.65,94]],"ltp":1.6,"tv":10626.51,"id":22229228}]}]}
{"op":"mcm","clk":"1000414053","pt":1580614065323,"mc":[{"id":"1.168081817","rc":[{"batb":[[0,2.6,20.66],[2,2.56,13.39]],"batl":[[1,2.68,17.12]],"ltp":2.64,"tv":1731.13,"id":15256065},{"batl":[[0,1.63,5.29]],"ltp":1.6,"tv":10626.51,"id":22229228}]}]}
{"op":"mcm","clk":"1000414197","pt":1580614068617,"mc":[{"id":"1.168081817","rc":[{"batb":[[0,2.6,8.79],[1,2.58,3.34]],"ltp":2.64,"tv":1731.13,"id":15256065}]}]}
{"op":"mcm","clk":"1000414241","pt":1580614069599,"mc":[{"id":"1.168081817","rc":[{"batb":[[0,2.62,39.93],[1,2.6,8.79],[2,2.58,13.61]],"ltp":2.64,"tv":1731.13,"id":15256065},{"batl":[[0,1.63,17.29],[1,1.64,22.31]],"ltp":1.6,"tv":10626.51,"id":22229228}]}]}
{"op":"mcm","clk":"1000414271","pt":1580614070325,"mc":[{"id":"1.168081817","rc":[{"batb":[[1,2.6,12.12]],"ltp":2.64,"tv":1731.13,"id":15256065}]}]}
{"op":"mcm","clk":"1000414462","pt":1580614074611,"mc":[{"id":"1.168081817","rc":[{"batb":[[0,2.6,12.12],[1,2.58,3.34],[2,2.56,13.39]],"ltp":2.64,"tv":1731.13,"id":15256065},{"batl":[[0,1.63,5.29]],"ltp":1.6,"tv":10626.51,"id":22229228}]}]}
{"op":"mcm","clk":"1000414505","pt":1580614075435,"mc":[{"id":"1.168081817","rc":[{"batb":[[0,2.6,8.79]],"ltp":2.64,"tv":1731.13,"id":15256065},{"batl":[[1,1.64,20.27]],"ltp":1.6,"tv":10626.51,"id":22229228}]}]}
{"op":"mcm","clk":"1000414689","pt":1580614079612,"mc":[{"id":"1.168081817","rc":[{"batb":[[0,2.62,39.93],[1,2.6,8.79],[2,2.58,13.66]],"ltp":2.64,"tv":1731.13,"id":15256065},{"batl":[[0,1.63,17.29],[1,1.64,40.98]],"ltp":1.6,"tv":10626.51,"id":22229228}]}]}
{"op":"mcm","clk":"1000414741","pt":1580614080540,"mc":[{"id":"1.168081817","rc":[{"batb":[[1,2.6,12.12]],"ltp":2.64,"tv":1731.13,"id":15256065}]}]}
{"op":"mcm","clk":"1000414907","pt":1580614084519,"mc":[{"id":"1.168081817","rc":[{"batb":[[0,2.6,12.12],[1,2.58,13.66],[2,2.56,13.39]],"ltp":2.64,"tv":1731.13,"id":15256065}]}]}
{"op":"mcm","clk":"1000414937","pt":1580614085336,"mc":[{"id":"1.168081817","rc":[{"batb":[[0,2.6,8.79],[1,2.58,3.34]],"ltp":2.64,"tv":1731.13,"id":15256065},{"batl":[[0,1.63,5.29],[1,1.64,38.8]],"ltp":1.6,"tv":10626.51,"id":22229228}]}]}
{"op":"mcm","clk":"1000415089","pt":1580614089656,"mc":[{"id":"1.168081817","rc":[{"batb":[[0,2.62,39.93],[1,2.6,8.79],[2,2.58,14.39]],"ltp":2.64,"tv":1731.13,"id":15256065},{"batl":[[0,1.63,18.29]],"ltp":1.6,"tv":10626.51,"id":22229228}]}]}
{"op":"mcm","clk":"1000415125","pt":1580614090477,"mc":[{"id":"1.168081817","rc":[{"batb":[[1,2.6,12.12]],"ltp":2.64,"tv":1731.13,"id":15256065},{"batl":[[1,1.64,40.98]],"ltp":1.6,"tv":10626.51,"id":22229228}]}]}
{"op":"mcm","clk":"1000415286","pt":1580614094556,"mc":[{"id":"1.168081817","rc":[{"batb":[[0,2.6,12.12],[1,2.58,14.39],[2,2.56,13.39]],"ltp":2.64,"tv":1731.13,"id":15256065}]}]}
{"op":"mcm","clk":"1000415327","pt":1580614095635,"mc":[{"id":"1.168081817","rc":[{"batb":[[0,2.6,8.79]],"ltp":2.64,"tv":1731.13,"id":15256065},{"batb":[[0,1.61,5.39],[1,1.6,38.65],[2,1.59,66.8]],"batl":[[0,1.63,5.29],[1,1.64,38.8]],"ltp":1.6,"tv":10626.51,"id":22229228}]}]}
{"op":"mcm","clk":"1000415373","pt":1580614096671,"mc":[{"id":"1.168081817","rc":[{"batb":[[0,2.6,19.79]],"batl":[[1,2.68,19.26]],"ltp":2.64,"tv":1731.13,"id":15256065},{"batb":[[0,1.6,38.65],[1,1.59,68.82],[2,1.58,81.93]],"batl":[[0,1.63,19.29]],"ltp":1.6,"tv":10626.51,"id":22229228}]}]}
{"op":"mcm","clk":"1000415408","pt":1580614097344,"mc":[{"id":"1.168081817","rc":[{"batb":[[0,1.61,5.39],[1,1.6,38.65],[2,1.59,68.91]],"ltp":1.6,"tv":10626.51,"id":22229228}]}]}
{"op":"mcm","clk":"1000415480","pt":1580614098685,"mc":[{"id":"1.168081817","rc":[{"batb":[[0,2.6,8.79]],"batl":[[1,2.68,17.12]],"ltp":2.64,"tv":1731.13,"id":15256065},{"trd":[[1.61,32.74]],"batb":[[0,1.6,38.65],[1,1.59,66.8],[2,1.58,81.93]],"batl":[[0,1.63,5.29]],"ltp":1.61,"tv":10637.15,"id":22229228}],"tv":12368.28}]}
{"op":"mcm","clk":"1000415527","pt":1580614099668,"mc":[{"id":"1.168081817","rc":[{"batb":[[0,2.6,24.12]],"batl":[[0,2.64,3.29],[1,2.66,21.49],[2,2.68,19.13]],"ltp":2.64,"tv":1731.13,"id":15256065},{"batb":[[0,1.61,5.39],[1,1.6,38.65],[2,1.59,58.74]],"batl":[[0,1.63,19.29]],"ltp":1.61,"tv":10637.15,"id":22229228}]}]}
{"op":"mcm","clk":"1000415576","pt":1580614100646,"mc":[{"id":"1.168081817","rc":[{"batb":[[0,2.6,20.79]],"ltp":2.64,"tv":1731.13,"id":15256065},{"batb":[[0,1.61,17.64],[1,1.6,42.42],[2,1.59,60.52]],"batl":[[2,1.65,108]],"ltp":1.61,"tv":10637.15,"id":22229228}]}]}
{"op":"mcm","clk":"1000415605","pt":1580614101473,"mc":[{"id":"1.168081817","rc":[{"batb":[[0,2.6,24.12]],"ltp":2.64,"tv":1731.13,"id":15256065}]}]}
{"op":"mcm","clk":"1000415648","pt":1580614102665,"mc":[{"id":"1.168081817","rc":[{"trd":[[1.61,62.2]],"batb":[[0,1.61,7.6]],"ltp":1.61,"tv":10666.62,"id":22229228}],"tv":12397.75}]}
{"op":"mcm","clk":"1000416377","pt":1580614119603,"mc":[{"id":"1.168081817","rc":[{"batb":[[1,1.6,61.41]],"ltp":1.61,"tv":10666.62,"id":22229228}]}]}
{"op":"mcm","clk":"1000416536","pt":1580614123417,"mc":[{"id":"1.168081817","rc":[{"batb":[[0,2.6,20.79]],"ltp":2.64,"tv":1731.13,"id":15256065}]}]}
{"op":"mcm","clk":"1000416575","pt":1580614124348,"mc":[{"id":"1.168081817","rc":[{"batb":[[0,2.6,24.13]],"ltp":2.64,"tv":1731.13,"id":15256065}]}]}
{"op":"mcm","clk":"1000416601","pt":1580614124915,"mc":[{"id":"1.168081817","rc":[{"batb":[[0,2.6,20.79]],"ltp":2.64,"tv":1731.13,"id":15256065}]}]}
{"op":"mcm","clk":"1000416922","pt":1580614133532,"mc":[{"id":"1.168081817","rc":[{"batb":[[1,2.58,26.27]],"ltp":2.64,"tv":1731.13,"id":15256065}]}]}
{"op":"mcm","clk":"1000434262","pt":1580614464571,"mc":[{"id":"1.168081817","rc":[{"trd":[[2.6,41.58]],"batb":[[0,2.58,26.27],[1,2.56,13.39],[2,2.52,78.75]],"batl":[[0,2.6,17.67],[1,2.64,3.29],[2,2.66,21.49]],"ltp":2.6,"tv":1772.7,"id":15256065}],"tv":12439.33}]}
{"op":"mcm","clk":"1000434316","pt":1580614465652,"mc":[{"id":"1.168081817","rc":[{"trd":[[2.6,76.92]],"batb":[[0,2.62,39.93],[1,2.6,3.77],[2,2.58,19.22]],"batl":[[0,2.64,3.29],[1,2.66,14.26],[2,2.68,13.13]],"ltp":2.6,"tv":1808.04,"id":15256065},{"batb":[[1,1.6,44.41],[2,1.59,44.52]],"batl":[[0,1.63,10.4],[1,1.64,28.8],[2,1.65,104.34]],"ltp":1.61,"tv":10666.62,"id":22229228}],"tv":12474.67}]}
{"op":"mcm","clk":"1000434347","pt":1580614466269,"mc":[{"id":"1.168081817","rc":[{"batb":[[1,2.6,7.16]],"ltp":2.6,"tv":1808.04,"id":15256065},{"batb":[[0,1.61,5.39],[1,1.6,46.63]],"batl":[[0,1.62,5],[1,1.63,10.4],[2,1.64,30.84]],"ltp":1.61,"tv":10666.62,"id":22229228}]}]}
{"op":"mcm","clk":"1000434393","pt":1580614466939,"mc":[{"id":"1.168081817","rc":[{"batb":[[1,2.6,15.1]],"ltp":2.6,"tv":1808.04,"id":15256065}]}]}
{"op":"mcm","clk":"1000434475","pt":1580614468485,"mc":[{"id":"1.168081817","rc":[{"batb":[[2,2.58,7.34]],"ltp":2.6,"tv":1808.04,"id":15256065},{"batl":[[0,1.62,23.53],[2,1.64,12.31]],"ltp":1.61,"tv":10666.62,"id":22229228}]}]}
{"op":"mcm","clk":"1000434593","pt":1580614470645,"mc":[{"id":"1.168081817","rc":[{"batb":[[0,2.6,15.1],[1,2.58,7.34],[2,2.56,7.39]],"ltp":2.6,"tv":1808.04,"id":15256065}]}]}
{"op":"mcm","clk":"1000434660","pt":1580614471673,"mc":[{"id":"1.168081817","rc":[{"batb":[[0,2.6,11.71]],"ltp":2.6,"tv":1808.04,"id":15256065},{"trd":[[1.62,142.01]],"batl":[[0,1.63,11.34],[1,1.64,10.27],[2,1.65,104.34]],"ltp":1.62,"tv":10701.82,"id":22229228}],"tv":12509.87}]}
{"op":"mcm","clk":"1000434764","pt":1580614473677,"mc":[{"id":"1.168081817","rc":[{"batb":[[0,2.6,7.94]],"batl":[[0,2.62,3.37],[1,2.64,14.29],[2,2.66,14.26]],"ltp":2.6,"tv":1808.04,"id":15256065},{"batb":[[0,1.61,25.39],[1,1.6,45.45],[2,1.59,23.52]],"ltp":1.62,"tv":10701.82,"id":22229228}]}]}
{"op":"mcm","clk":"1000434801","pt":1580614474244,"mc":[{"id":"1.168081817","rc":[{"trd":[[2.62,69.24]],"batl":[[0,2.64,14.29],[1,2.66,14.26],[2,2.68,13.13]],"ltp":2.62,"tv":1814.28,"id":15256065}],"tv":12516.11}]}
{"op":"mcm","clk":"1000434831","pt":1580614475167,"mc":[{"id":"1.168081817","rc":[{"batl":[[2,2.68,24.47]],"ltp":2.62,"tv":1814.28,"id":15256065}]}]}
{"op":"mcm","clk":"1000435239","pt":1580614482679,"mc":[{"id":"1.168081817","rc":[{"batl":[[0,2.62,3.37],[1,2.64,14.29],[2,2.66,16.42]],"ltp":2.62,"tv":1814.28,"id":15256065},{"batl":[[0,1.63,10.4],[1,1.64,11.21]],"ltp":1.62,"tv":10701.82,"id":22229228}]}]}
{"op":"mcm","clk":"1000435290","pt":1580614483658,"mc":[{"id":"1.168081817","rc":[{"trd":[[2.62,75.48]],"batl":[[0,2.64,14.29],[1,2.66,14.26],[2,2.68,24.6]],"ltp":2.62,"tv":1820.52,"id":15256065}],"tv":12522.34}]}
{"op":"mcm","clk":"1000436096","pt":1580614498584,"mc":[{"id":"1.168081817","rc":[{"batl":[[0,2.62,3.37],[1,2.64,14.29],[2,2.66,16.33]],"ltp":2.62,"tv":1820.52,"id":15256065}]}]}
{"op":"mcm","clk":"1000436451","pt":1580614504519,"mc":[{"id":"1.168081817","rc":[{"trd":[[2.62,81.72]],"batl":[[0,2.64,14.54],[1,2.66,16.33],[2,2.68,22.46]],"ltp":2.62,"tv":1826.76,"id":15256065},{"batl":[[0,1.63,5.4],[1,1.64,6.21],[2,1.65,99.34]],"ltp":1.62,"tv":10701.82,"id":22229228}],"tv":12528.58}]}
{"op":"mcm","clk":"1000436489","pt":1580614505291,"mc":[{"id":"1.168081817","rc":[{"batb":[[0,2.6,11.33]],"batl":[[0,2.64,14.29],[1,2.66,14.26],[2,2.68,24.6]],"ltp":2.62,"tv":1826.76,"id":15256065}]}]}
{"op":"mcm","clk":"1000436572","pt":1580614506633,"mc":[{"id":"1.168081817","rc":[{"batb":[[0,2.6,7.94]],"ltp":2.62,"tv":1826.76,"id":15256065}]}]}
{"op":"mcm","clk":"1000436624","pt":1580614507514,"mc":[{"id":"1.168081817","rc":[{"trd":[[2.62,87.95]],"batl":[[0,2.64,14.54],[1,2.66,16.48]],"ltp":2.62,"tv":1832.99,"id":15256065}],"tv":12534.82}]}
{"op":"mcm","clk":"1000436673","pt":1580614508390,"mc":[{"id":"1.168081817","rc":[{"batb":[[0,2.6,11.33]],"batl":[[0,2.64,14.29],[1,2.66,14.26]],"ltp":2.62,"tv":1832.99,"id":15256065}]}]}
{"op":"mcm","clk":"1000436824","pt":1580614511127,"mc":[{"id":"1.168081817","rc":[{"batl":[[2,2.68,13.26]],"ltp":2.62,"tv":1832.99,"id":15256065}]}]}
{"op":"mcm","clk":"1000437033","pt":1580614515243,"mc":[{"id":"1.168081817","rc":[{"batb":[[0,1.61,43.2],[1,1.6,27.64]],"ltp":1.62,"tv":10701.82,"id":22229228}]}]}
{"op":"mcm","clk":"1000437150","pt":1580614517523,"mc":[{"id":"1.168081817","rc":[{"batb":[[0,2.6,7.94]],"batl":[[0,2.62,3.37],[1,2.64,14.29],[2,2.66,16.51]],"ltp":2.62,"tv":1832.99,"id":15256065}]}]}
{"op":"mcm","clk":"1000438222","pt":1580614536559,"mc":[{"id":"1.168081817","rc":[{"batb":[[0,1.61,43.09]],"ltp":1.62,"tv":10701.82,"id":22229228}]}]}
{"op":"mcm","clk":"1000438549","pt":1580614542484,"mc":[{"id":"1.168081817","rc":[{"trd":[[2.62,94.69]],"batb":[[0,2.6,4.57]],"batl":[[0,2.64,14.29],[1,2.66,14.26],[2,2.68,13.26]],"ltp":2.62,"tv":1839.73,"id":15256065}],"tv":12541.56}]}
{"op":"mcm","clk":"1000438571","pt":1580614542948,"mc":[{"id":"1.168081817","rc":[{"batb":[[0,2.6,3.4]],"ltp":2.62,"tv":1839.73,"id":15256065},{"batb":[[1,1.6,34.54]],"ltp":1.62,"tv":10701.82,"id":22229228}]}]}
{"op":"mcm","clk":"1000441838","pt":1580614600633,"mc":[{"id":"1.168081817","rc":[{"batb":[[0,2.58,7.34],[1,2.56,7.39],[2,2.54,28.95]],"batl":[[0,2.62,3.39],[1,2.64,14.29],[2,2.66,14.26]],"ltp":2.62,"tv":1839.73,"id":15256065}]}]}
{"op":"mcm","clk":"1000441929","pt":1580614601615,"mc":[{"id":"1.168081817","rc":[{"trd":[[2.62,101.35]],"batl":[[0,2.64,14.34],[1,2.66,16.51],[2,2.68,13.13]],"ltp":2.62,"tv":1846.39,"id":15256065}],"tv":12548.21}]}
{"op":"mcm","clk":"1000441974","pt":1580614602435,"mc":[{"id":"1.168081817","rc":[{"batl":[[0,2.64,14.29],[1,2.66,14.26]],"ltp":2.62,"tv":1846.39,"id":15256065}]}]}
{"op":"mcm","clk":"1000442203","pt":1580614606548,"mc":[{"id":"1.168081817","rc":[{"trd":[[2.62,152.89]],"batb":[[0,2.62,14.16],[1,2.6,6.66],[2,2.58,7.34]],"batl":[[0,2.64,3.29]],"ltp":2.62,"tv":1897.93,"id":15256065},{"batb":[[0,1.61,23.09],[2,1.59,40.52]],"batl":[[1,1.64,8.39]],"ltp":1.62,"tv":10701.82,"id":22229228}],"tv":12599.75}]}
{"op":"mcm","clk":"1000442439","pt":1580614610608,"mc":[{"id":"1.168081817","rc":[{"batb":[[0,1.61,5.39],[1,1.6,52.23]],"ltp":1.62,"tv":10701.82,"id":22229228}]}]}
{"op":"mcm","clk":"1000442480","pt":1580614611329,"mc":[{"id":"1.168081817","rc":[{"batb":[[0,2.6,3.41],[1,2.58,7.34],[2,2.56,7.39]],"batl":[[0,2.64,12.57]],"ltp":2.62,"tv":1897.93,"id":15256065},{"batb":[[0,1.61,21.79],[2,1.59,40.41]],"batl":[[1,1.64,6.21]],"ltp":1.62,"tv":10701.82,"id":22229228}]}]}
{"op":"mcm","clk":"1000444740","pt":1580614651613,"mc":[{"id":"1.168081817","rc":[{"batb":[[0,1.61,39.49],[1,1.6,34.54]],"ltp":1.62,"tv":10701.82,"id":22229228}]}]}
{"op":"mcm","clk":"1000445159","pt":1580614659693,"mc":[{"id":"1.168081817","rc":[{"trd":[[2.62,159.55]],"batb":[[0,2.58,7.34],[1,2.56,7.39],[2,2.54,28.95]],"batl":[[0,2.64,12.63]],"ltp":2.62,"tv":1904.59,"id":15256065}],"tv":12606.41}]}
{"op":"mcm","clk":"1000445195","pt":1580614660208,"mc":[{"id":"1.168081817","rc":[{"batl":[[0,2.64,12.57]],"ltp":2.62,"tv":1904.59,"id":15256065}]}]}
{"op":"mcm","clk":"1000451400","pt":1580614768622,"mc":[{"id":"1.168081817","rc":[{"batl":[[0,2.62,3.42],[1,2.64,12.57],[2,2.66,16.36]],"ltp":2.62,"tv":1904.59,"id":15256065}]}]}
{"op":"mcm","clk":"1000453479","pt":1580614801341,"mc":[{"id":"1.168081817","rc":[{"trd":[[2.62,166.2]],"batl":[[0,2.64,12.66],[1,2.66,14.26],[2,2.68,13.26]],"ltp":2.62,"tv":1911.24,"id":15256065},{"trd":[[1.63,15.07]],"batb":[[1,1.6,32.32]],"batl":[[0,1.63,3.24]],"ltp":1.63,"tv":10706.14,"id":22229228}],"tv":12617.39}]}
{"op":"mcm","clk":"1000456712","pt":1580614851026,"mc":[{"id":"1.168081817","rc":[{"batl":[[0,2.64,12.57]],"ltp":2.62,"tv":1911.24,"id":15256065}]}]}
{"op":"mcm","clk":"1000461774","pt":1580614923626,"mc":[{"id":"1.168081817","rc":[{"batl":[[0,2.62,3.44],[1,2.64,12.57],[2,2.66,16.36]],"ltp":2.62,"tv":1911.24,"id":15256065}]}]}
{"op":"mcm","clk":"1000461849","pt":1580614924634,"mc":[{"id":"1.168081817","rc":[{"batb":[[0,2.58,3.34],[2,2.54,31.95]],"ltp":2.62,"tv":1911.24,"id":15256065},{"batb":[[0,1.62,5.57],[1,1.61,39.49],[2,1.6,34.36]],"ltp":1.63,"tv":10706.14,"id":22229228}]}]}
{"op":"mcm","clk":"1000461906","pt":1580614925612,"mc":[{"id":"1.168081817","rc":[{"batl":[[0,1.64,6.21],[1,1.65,97.24],[2,1.66,2.25]],"ltp":1.63,"tv":10706.14,"id":22229228}]}]}
