{"op":"mcm","clk":"978248081","pt":1580359801373,"mc":[{"id":"1.168081821","marketDefinition":{"bspMarket":false,"turnInPlayEnabled":true,"persistenceEnabled":true,"marketBaseRate":5.0,"eventId":"29676917","eventTypeId":"2","numberOfWinners":1,"bettingType":"ODDS","marketType":"SET_WINNER","marketTime":"2020-02-02T05:00:00.000Z","suspendTime":"2020-02-02T05:00:00.000Z","bspReconciled":false,"complete":true,"inPlay":false,"crossMatching":false,"runnersVoidable":false,"numberOfActiveRunners":2,"betDelay":0,"status":"OPEN","runners":[{"status":"ACTIVE","sortPriority":1,"id":22229228,"name":"Ram/Salisbury"},{"status":"ACTIVE","sortPriority":2,"id":15256065,"name":"Purcell/Saville"}],"regulators":["MR_INT"],"countryCode":"AU","discountAllowed":false,"timezone":"GMT","openDate":"2020-02-02T05:00:00.000Z","version":3141663675,"name":"Set 2 Winner","eventName":"Ram/Salisbury v Purcell/Saville"},"rc":[{"batb":[[0,1.01,20]],"ltp":0.0,"tv":0.0,"id":15256065},{"batb":[[0,1.01,20]],"ltp":0.0,"tv":0.0,"id":22229228}]}]}
{"op":"mcm","clk":"978248109","pt":1580359802704,"mc":[{"id":"1.168081821","marketDefinition":{"bspMarket":false,"turnInPlayEnabled":true,"persistenceEnabled":true,"marketBaseRate":5.0,"eventId":"29676917","eventTypeId":"2","numberOfWinners":1,"bettingType":"ODDS","marketType":"SET_WINNER","marketTime":"2020-02-02T05:00:00.000Z","suspendTime":"2020-02-02T05:00:00.000Z","bspReconciled":false,"complete":true,"inPlay":false,"crossMatching":false,"runnersVoidable":false,"numberOfActiveRunners":2,"betDelay":0,"status":"OPEN","runners":[{"status":"ACTIVE","sortPriority":1,"id":22229228,"name":"Ram/Salisbury"},{"status":"ACTIVE","sortPriority":2,"id":15256065,"name":"Purcell/Saville"}],"regulators":["MR_INT"],"countryCode":"AU","discountAllowed":true,"timezone":"GMT","openDate":"2020-02-02T05:00:00.000Z","version":3141663675,"name":"Set 2 Winner","eventName":"Ram/Salisbury v Purcell/Saville"}}]}
{"op":"mcm","clk":"978263627","pt":1580360419967,"mc":[{"id":"1.168081821","rc":[{"batb":[[0,1.01,10]],"ltp":0.0,"tv":0.0,"id":15256065},{"batb":[[0,1.01,10]],"ltp":0.0,"tv":0.0,"id":22229228}]}]}
{"op":"mcm","clk":"988916594","pt":1580511682450,"mc":[{"id":"1.168081821","rc":[{"batb":[[0,1.01,12.53]],"ltp":0.0,"tv":0.0,"id":15256065},{"batb":[[0,1.01,12.53]],"ltp":0.0,"tv":0.0,"id":22229228}]}]}
{"op":"mcm","clk":"988916665","pt":1580511683640,"mc":[{"id":"1.168081821","rc":[{"batb":[[0,1.01,10.51]],"ltp":0.0,"tv":0.0,"id":15256065},{"batb":[[0,1.01,10.51]],"ltp":0.0,"tv":0.0,"id":22229228}]}]}
{"op":"mcm","clk":"988940382","pt":1580511948676,"mc":[{"id":"1.168081821","rc":[{"batb":[[0,1.01,11.01]],"ltp":0.0,"tv":0.0,"id":15256065},{"batb":[[0,1.01,11.01]],"ltp":0.0,"tv":0.0,"id":22229228}]}]}
{"op":"mcm","clk":"1000055783","pt":1580605542528,"mc":[{"id":"1.168081821","rc":[{"batb":[[0,1.01,13.01]],"ltp":0.0,"tv":0.0,"id":22229228}]}]}
{"op":"mcm","clk":"1000055812","pt":1580605543659,"mc":[{"id":"1.168081821","rc":[{"batb":[[0,1.01,11.02]],"ltp":0.0,"tv":0.0,"id":15256065},{"batb":[[0,1.01,11.02]],"ltp":0.0,"tv":0.0,"id":22229228}]}]}
{"op":"mcm","clk":"1000351189","pt":1580612888969,"mc":[{"id":"1.168081821","marketDefinition":{"bspMarket":false,"turnInPlayEnabled":true,"persistenceEnabled":true,"marketBaseRate":5.0,"eventId":"29676917","eventTypeId":"2","numberOfWinners":1,"bettingType":"ODDS","marketType":"SET_WINNER","marketTime":"2020-02-02T04:00:00.000Z","suspendTime":"2020-02-02T04:00:00.000Z","bspReconciled":false,"complete":true,"inPlay":false,"crossMatching":false,"runnersVoidable":false,"numberOfActiveRunners":2,"betDelay":0,"status":"OPEN","runners":[{"status":"ACTIVE","sortPriority":1,"id":22229228,"name":"Ram/Salisbury"},{"status":"ACTIVE","sortPriority":2,"id":15256065,"name":"Purcell/Saville"}],"regulators":["MR_INT"],"countryCode":"AU","discountAllowed":true,"timezone":"GMT","openDate":"2020-02-02T05:00:00.000Z","version":3148089684,"name":"Set 2 Winner","eventName":"Ram/Salisbury v Purcell/Saville"}}]}
{"op":"mcm","clk":"1000351354","pt":1580612891105,"mc":[{"id":"1.168081821","marketDefinition":{"bspMarket":false,"turnInPlayEnabled":true,"persistenceEnabled":true,"marketBaseRate":5.0,"eventId":"29676917","eventTypeId":"2","numberOfWinners":1,"bettingType":"ODDS","marketType":"SET_WINNER","marketTime":"2020-02-02T04:00:00.000Z","suspendTime":"2020-02-02T04:00:00.000Z","bspReconciled":false,"complete":true,"inPlay":false,"crossMatching":false,"runnersVoidable":false,"numberOfActiveRunners":2,"betDelay":0,"status":"OPEN","runners":[{"status":"ACTIVE","sortPriority":1,"id":22229228,"name":"Ram/Salisbury"},{"status":"ACTIVE","sortPriority":2,"id":15256065,"name":"Purcell/Saville"}],"regulators":["MR_INT"],"countryCode":"AU","discountAllowed":true,"timezone":"GMT","openDate":"2020-02-02T04:00:00.000Z","version":3148089684,"name":"Set 2 Winner","eventName":"Ram/Salisbury v Purcell/Saville"}}]}
{"op":"mcm","clk":"1000520971","pt":1580616033301,"mc":[{"id":"1.168081821","rc":[{"batb":[[0,1.04,126.04],[1,1.01,11.01]],"ltp":0.0,"tv":0.0,"id":15256065},{"batb":[[0,1.04,126.04],[1,1.01,11.01]],"ltp":0.0,"tv":0.0,"id":22229228}]}]}
{"op":"mcm","clk":"1000522484","pt":1580616059948,"mc":[{"id":"1.168081821","marketDefinition":{"bspMarket":false,"turnInPlayEnabled":true,"persistenceEnabled":true,"marketBaseRate":5.0,"eventId":"29676917","eventTypeId":"2","numberOfWinners":1,"bettingType":"ODDS","marketType":"SET_WINNER","marketTime":"2020-02-02T04:00:00.000Z","suspendTime":"2020-02-02T04:00:00.000Z","bspReconciled":false,"complete":true,"inPlay":false,"crossMatching":true,"runnersVoidable":false,"numberOfActiveRunners":2,"betDelay":0,"status":"OPEN","runners":[{"status":"ACTIVE","sortPriority":1,"id":22229228,"name":"Ram/Salisbury"},{"status":"ACTIVE","sortPriority":2,"id":15256065,"name":"Purcell/Saville"}],"regulators":["MR_INT"],"countryCode":"AU","discountAllowed":true,"timezone":"GMT","openDate":"2020-02-02T04:00:00.000Z","version":3148089684,"name":"Set 2 Winner","eventName":"Ram/Salisbury v Purcell/Saville"}}]}
{"op":"mcm","clk":"1000523385","pt":1580616080780,"mc":[{"id":"1.168081821","rc":[{"batb":[[0,1.05,2.01],[1,1.04,126.03],[2,1.01,11.01]],"ltp":0.0,"tv":0.0,"id":15256065},{"batb":[[0,1.05,2.01],[1,1.04,126.03],[2,1.01,11.01]],"ltp":0.0,"tv":0.0,"id":22229228}]}]}
{"op":"mcm","clk":"1000539732","pt":1580616464696,"mc":[{"id":"1.168081821","rc":[{"batb":[[1,1.01,11.01],[2,1.01,0]],"ltp":0.0,"tv":0.0,"id":15256065},{"batb":[[1,1.01,11.01],[2,1.01,0]],"ltp":0.0,"tv":0.0,"id":22229228}]}]}
{"op":"mcm","clk":"1000542816","pt":1580616531409,"mc":[{"id":"1.168081821","rc":[{"batb":[[1,1.04,126.03],[2,1.01,11.01]],"ltp":0.0,"tv":0.0,"id":15256065},{"batb":[[1,1.04,126.03],[2,1.01,11.01]],"ltp":0.0,"tv":0.0,"id":22229228}]}]}
{"op":"mcm","clk":"1000550784","pt":1580616680320,"mc":[{"id":"1.168081821","rc":[{"batb":[[0,1.04,126.04],[1,1.01,11.01],[2,1.01,0]],"ltp":0.0,"tv":0.0,"id":15256065},{"batb":[[0,1.04,126.04],[1,1.01,11.01],[2,1.01,0]],"ltp":0.0,"tv":0.0,"id":22229228}]}]}
{"op":"mcm","clk":"1000551410","pt":1580616692148,"mc":[{"id":"1.168081821","rc":[{"batb":[[0,1.05,2.01],[1,1.04,126.03],[2,1.01,11.01]],"ltp":0.0,"tv":0.0,"id":15256065},{"batb":[[0,1.05,2.01],[1,1.04,126.03],[2,1.01,11.01]],"ltp":0.0,"tv":0.0,"id":22229228}]}]}
{"op":"mcm","clk":"1000559953","pt":1580616820692,"mc":[{"id":"1.168081821","marketDefinition":{"bspMarket":false,"turnInPlayEnabled":true,"persistenceEnabled":true,"marketBaseRate":5.0,"eventId":"29676917","eventTypeId":"2","numberOfWinners":1,"bettingType":"ODDS","marketType":"SET_WINNER","marketTime":"2020-02-02T04:00:00.000Z","suspendTime":"2020-02-02T04:00:00.000Z","bspReconciled":false,"complete":true,"inPlay":true,"crossMatching":true,"runnersVoidable":false,"numberOfActiveRunners":2,"betDelay":3,"status":"OPEN","runners":[{"status":"ACTIVE","sortPriority":1,"id":22229228,"name":"Ram/Salisbury"},{"status":"ACTIVE","sortPriority":2,"id":15256065,"name":"Purcell/Saville"}],"regulators":["MR_INT"],"countryCode":"AU","discountAllowed":true,"timezone":"GMT","openDate":"2020-02-02T04:00:00.000Z","version":3148152299,"name":"Set 2 Winner","eventName":"Ram/Salisbury v Purcell/Saville"},"rc":[{"batb":[[0,1.04,126.04],[1,1.01,10.51],[2,1.01,0]],"ltp":0.0,"tv":0.0,"id":15256065},{"batb":[[0,1.04,126.04],[1,1.01,10.51],[2,1.01,0]],"ltp":0.0,"tv":0.0,"id":22229228}]}]}
{"op":"mcm","clk":"1000579302","pt":1580617084548,"mc":[{"id":"1.168081821","rc":[{"batl":[[0,3.3,191.92]],"ltp":0.0,"tv":0.0,"id":15256065},{"batl":[[0,2.16,342.82]],"ltp":0.0,"tv":0.0,"id":22229228}]}]}
{"op":"mcm","clk":"1000595430","pt":1580617306467,"mc":[{"id":"1.168081821","rc":[{"batb":[[0,1.01,10.52],[1,1.01,0]],"ltp":0.0,"tv":0.0,"id":15256065},{"batb":[[0,1.01,10.52],[1,1.01,0]],"ltp":0.0,"tv":0.0,"id":22229228}]}]}
{"op":"mcm","clk":"1000635407","pt":1580617885964,"mc":[{"id":"1.168081821","rc":[{"batl":[[0,3.45,161.81]],"ltp":0.0,"tv":0.0,"id":15256065},{"batl":[[0,2.1,397.41]],"ltp":0.0,"tv":0.0,"id":22229228}]}]}
{"op":"mcm","clk":"1000665452","pt":1580618445115,"mc":[{"id":"1.168081821","rc":[{"batl":[[0,3.9,141.49]],"ltp":0.0,"tv":0.0,"id":15256065},{"batl":[[0,1.95,443.08]],"ltp":0.0,"tv":0.0,"id":22229228}]}]}
{"op":"mcm","clk":"1000718765","pt":1580619382322,"mc":[{"id":"1.168081821","rc":[{"batb":[[0,2.1,83.3],[1,1.01,10.52]],"ltp":0.0,"tv":0.0,"id":15256065}]}]}
{"op":"mcm","clk":"1000724708","pt":1580619503666,"mc":[{"id":"1.168081821","rc":[{"batb":[[0,1.01,10.52],[1,1.01,0]],"ltp":0.0,"tv":0.0,"id":15256065}]}]}
{"op":"mcm","clk":"1000724813","pt":1580619506532,"mc":[{"id":"1.168081821","rc":[{"batb":[[0,2.06,83.3],[1,1.01,10.52]],"ltp":0.0,"tv":0.0,"id":15256065}]}]}
{"op":"mcm","clk":"1000724921","pt":1580619509655,"mc":[{"id":"1.168081821","rc":[{"batl":[[0,3.65,170.41]],"ltp":0.0,"tv":0.0,"id":15256065}]}]}
{"op":"mcm","clk":"1000725687","pt":1580619529556,"mc":[{"id":"1.168081821","rc":[{"batl":[[1,1000,0.02]],"ltp":0.0,"tv":0.0,"id":22229228}]}]}
{"op":"mcm","clk":"1000725702","pt":1580619529865,"mc":[{"id":"1.168081821","rc":[{"batl":[[1,1000,0]],"ltp":0.0,"tv":0.0,"id":22229228}]}]}
{"op":"mcm","clk":"1000725852","pt":1580619533658,"mc":[{"id":"1.168081821","rc":[{"trd":[[1.37,0.01],[1.48,0.02]],"batb":[[0,1.01,10.51]],"ltp":1.37,"tv":0.02,"id":22229228}],"tv":0.02}]}
{"op":"mcm","clk":"1000726077","pt":1580619539366,"mc":[{"id":"1.168081821","rc":[{"batb":[[0,1.01,10.52]],"ltp":1.37,"tv":0.02,"id":22229228}]}]}
{"op":"mcm","clk":"1000726093","pt":1580619539776,"mc":[{"id":"1.168081821","rc":[{"batb":[[0,1.01,10.51]],"ltp":1.37,"tv":0.02,"id":22229228}]}]}
{"op":"mcm","clk":"1000726226","pt":1580619542906,"mc":[{"id":"1.168081821","rc":[{"batb":[[0,1.01,10.52]],"ltp":1.37,"tv":0.02,"id":22229228}]}]}
{"op":"mcm","clk":"1000726459","pt":1580619548810,"mc":[{"id":"1.168081821","rc":[{"batl":[[0,1.8,22.72],[1,1.95,443.08]],"ltp":1.37,"tv":0.02,"id":22229228}]}]}
{"op":"mcm","clk":"1000727785","pt":1580619578227,"mc":[{"id":"1.168081821","rc":[{"batl":[[1,1.95,0]],"ltp":1.37,"tv":0.02,"id":22229228}]}]}
{"op":"mcm","clk":"1000727938","pt":1580619581615,"mc":[{"id":"1.168081821","rc":[{"batl":[[0,4.6,136.05]],"ltp":0.0,"tv":0.0,"id":15256065},{"batl":[[1,1.82,469.11]],"ltp":1.37,"tv":0.02,"id":22229228}]}]}
{"op":"mcm","clk":"1000728797","pt":1580619602254,"mc":[{"id":"1.168081821","rc":[{"batb":[[0,1.01,10.52],[1,1.01,0]],"ltp":0.0,"tv":0.0,"id":15256065}]}]}
{"op":"mcm","clk":"1000728991","pt":1580619605373,"mc":[{"id":"1.168081821","rc":[{"batb":[[0,2.26,83.3],[1,1.01,10.52]],"ltp":0.0,"tv":0.0,"id":15256065}]}]}
{"op":"mcm","clk":"1000729225","pt":1580619610135,"mc":[{"id":"1.168081821","rc":[{"batl":[[0,3.9,158.24]],"ltp":0.0,"tv":0.0,"id":15256065}]}]}
{"op":"mcm","clk":"1000729454","pt":1580619616864,"mc":[{"id":"1.168081821","rc":[{"batb":[[0,1.01,10.52],[1,1.01,0]],"ltp":0.0,"tv":0.0,"id":15256065}]}]}
{"op":"mcm","clk":"1000729589","pt":1580619620014,"mc":[{"id":"1.168081821","rc":[{"batb":[[0,2.1,83.3],[1,1.01,10.52]],"ltp":0.0,"tv":0.0,"id":15256065}]}]}
{"op":"mcm","clk":"1000730018","pt":1580619627204,"mc":[{"id":"1.168081821","rc":[{"batl":[[1,1.82,0]],"ltp":1.37,"tv":0.02,"id":22229228}]}]}
{"op":"mcm","clk":"1000730248","pt":1580619630906,"mc":[{"id":"1.168081821","rc":[{"batl":[[0,3.65,170.41]],"ltp":0.0,"tv":0.0,"id":15256065},{"batl":[[1,2.04,383.01]],"ltp":1.37,"tv":0.02,"id":22229228}]}]}
{"op":"mcm","clk":"1000730453","pt":1580619634695,"mc":[{"id":"1.168081821","rc":[{"batb":[[0,1.01,10.52],[1,1.01,0]],"ltp":0.0,"tv":0.0,"id":15256065}]}]}
{"op":"mcm","clk":"1000730564","pt":1580619637323,"mc":[{"id":"1.168081821","rc":[{"batb":[[0,2.02,83.3],[1,1.01,10.52]],"ltp":0.0,"tv":0.0,"id":15256065}]}]}
{"op":"mcm","clk":"1000734918","pt":1580619721391,"mc":[{"id":"1.168081821","rc":[{"batb":[[0,1.01,10.52],[1,1.01,0]],"ltp":0.0,"tv":0.0,"id":15256065}]}]}
{"op":"mcm","clk":"1000735084","pt":1580619724506,"mc":[{"id":"1.168081821","rc":[{"batb":[[0,2.26,83.3],[1,1.01,10.52]],"ltp":0.0,"tv":0.0,"id":15256065}]}]}
{"op":"mcm","clk":"1000736157","pt":1580619746470,"mc":[{"id":"1.168081821","rc":[{"batl":[[1,2.04,0]],"ltp":1.37,"tv":0.02,"id":22229228}]}]}
{"op":"mcm","clk":"1000736355","pt":1580619750488,"mc":[{"id":"1.168081821","rc":[{"batl":[[0,4.2,148.03]],"ltp":0.0,"tv":0.0,"id":15256065},{"batl":[[1,1.89,435.28]],"ltp":1.37,"tv":0.02,"id":22229228}]}]}
{"op":"mcm","clk":"1000740172","pt":1580619834277,"mc":[{"id":"1.168081821","rc":[{"batl":[[1,1.89,0]],"ltp":1.37,"tv":0.02,"id":22229228}]}]}
{"op":"mcm","clk":"1000740329","pt":1580619837173,"mc":[{"id":"1.168081821","rc":[{"batl":[[0,4.9,126.27]],"ltp":0.0,"tv":0.0,"id":15256065},{"batl":[[0,1.77,500.61],[1,1.8,22.72]],"ltp":1.37,"tv":0.02,"id":22229228}]}]}
{"op":"mcm","clk":"1000740647","pt":1580619844512,"mc":[{"id":"1.168081821","rc":[{"batb":[[0,1.01,10.52],[1,1.01,0]],"ltp":0.0,"tv":0.0,"id":15256065}]}]}
{"op":"mcm","clk":"1000740783","pt":1580619847605,"mc":[{"id":"1.168081821","rc":[{"batb":[[0,2.32,83.3],[1,1.01,10.52]],"ltp":0.0,"tv":0.0,"id":15256065}]}]}
{"op":"mcm","clk":"1000741780","pt":1580619868695,"mc":[{"id":"1.168081821","rc":[{"batl":[[0,1.8,22.72],[1,1.8,0]],"ltp":1.37,"tv":0.02,"id":22229228}]}]}
{"op":"mcm","clk":"1000741965","pt":1580619872620,"mc":[{"id":"1.168081821","rc":[{"batl":[[0,6.6,98.95]],"ltp":0.0,"tv":0.0,"id":15256065},{"batl":[[0,1.62,614.4],[1,1.8,22.72]],"ltp":1.37,"tv":0.02,"id":22229228}]}]}
{"op":"mcm","clk":"1000742321","pt":1580619879913,"mc":[{"id":"1.168081821","rc":[{"batb":[[0,1.01,10.52],[1,1.01,0]],"ltp":0.0,"tv":0.0,"id":15256065}]}]}
{"op":"mcm","clk":"1000742460","pt":1580619883018,"mc":[{"id":"1.168081821","rc":[{"batb":[[0,2.64,83.3],[1,1.01,10.52]],"ltp":0.0,"tv":0.0,"id":15256065}]}]}
{"op":"mcm","clk":"1000743243","pt":1580619899373,"mc":[{"id":"1.168081821","rc":[{"batl":[[0,1.8,22.72],[1,1.8,0]],"ltp":1.37,"tv":0.02,"id":22229228}]}]}
{"op":"mcm","clk":"1000743407","pt":1580619902437,"mc":[{"id":"1.168081821","rc":[{"batl":[[0,9.8,75.27]],"ltp":0.0,"tv":0.0,"id":15256065},{"batl":[[0,1.49,761.67],[1,1.8,22.72]],"ltp":1.37,"tv":0.02,"id":22229228}]}]}
{"op":"mcm","clk":"1000743787","pt":1580619910162,"mc":[{"id":"1.168081821","rc":[{"batb":[[0,1.01,10.52],[1,1.01,0]],"ltp":0.0,"tv":0.0,"id":15256065}]}]}
{"op":"mcm","clk":"1000743946","pt":1580619913260,"mc":[{"id":"1.168081821","rc":[{"batb":[[0,3.15,83.3],[1,1.01,10.52]],"ltp":0.0,"tv":0.0,"id":15256065}]}]}
{"op":"mcm","clk":"1000744745","pt":1580619928904,"mc":[{"id":"1.168081821","rc":[{"batl":[[0,11.5,70.11]],"ltp":0.0,"tv":0.0,"id":15256065}]}]}
{"op":"mcm","clk":"1000745217","pt":1580619936898,"mc":[{"id":"1.168081821","rc":[{"batl":[[0,1.8,22.72],[1,1.8,0]],"ltp":1.37,"tv":0.02,"id":22229228}]}]}
{"op":"mcm","clk":"1000745458","pt":1580619940873,"mc":[{"id":"1.168081821","rc":[{"batl":[[0,17,57.33]],"ltp":0.0,"tv":0.0,"id":15256065},{"trd":[[1.42,0.03]],"batb":[[0,1.01,10.51]],"ltp":1.42,"tv":0.05,"id":22229228}],"tv":0.05}]}
{"op":"mcm","clk":"1000746028","pt":1580619951132,"mc":[{"id":"1.168081821","rc":[{"batb":[[0,3.15,49.22]],"ltp":0.0,"tv":0.0,"id":15256065}]}]}
{"op":"mcm","clk":"1000746566","pt":1580619960920,"mc":[{"id":"1.168081821","rc":[{"batb":[[0,1.01,10.52],[1,1.01,0]],"ltp":0.0,"tv":0.0,"id":15256065}]}]}
{"op":"mcm","clk":"1000746739","pt":1580619964054,"mc":[{"id":"1.168081821","rc":[{"batb":[[0,4.3,49.22],[1,1.01,10.52]],"ltp":0.0,"tv":0.0,"id":15256065}]}]}
{"op":"mcm","clk":"1000751013","pt":1580620044854,"mc":[{"id":"1.168081821","rc":[{"batb":[[0,1.01,10.52],[1,1.01,0]],"ltp":0.0,"tv":0.0,"id":15256065}]}]}
{"op":"mcm","clk":"1000751182","pt":1580620048637,"mc":[{"id":"1.168081821","rc":[{"batb":[[0,3.7,49.22],[1,1.01,10.52]],"ltp":0.0,"tv":0.0,"id":15256065}]}]}
{"op":"mcm","clk":"1000751446","pt":1580620053044,"mc":[{"id":"1.168081821","rc":[{"batl":[[0,11.5,70.11]],"ltp":0.0,"tv":0.0,"id":15256065},{"batl":[[0,1.47,803.2],[1,1.8,22.72]],"ltp":1.42,"tv":0.05,"id":22229228}]}]}
{"op":"mcm","clk":"1000752304","pt":1580620071254,"mc":[{"id":"1.168081821","rc":[{"batb":[[0,1.01,10.52],[1,1.01,0]],"ltp":0.0,"tv":0.0,"id":15256065},{"batl":[[1,1.8,0]],"ltp":1.42,"tv":0.05,"id":22229228}]}]}
{"op":"mcm","clk":"1000752442","pt":1580620074150,"mc":[{"id":"1.168081821","rc":[{"batb":[[0,3.4,49.22],[1,1.01,10.52]],"ltp":0.0,"tv":0.0,"id":15256065}]}]}
{"op":"mcm","clk":"1000753067","pt":1580620086825,"mc":[{"id":"1.168081821","rc":[{"batl":[[0,14,62.58]],"ltp":0.0,"tv":0.0,"id":15256065}]}]}
{"op":"mcm","clk":"1000754031","pt":1580620107644,"mc":[{"id":"1.168081821","rc":[{"batl":[[0,21,53.48]],"ltp":0.0,"tv":0.0,"id":15256065},{"batl":[[0,1.38,972.95]],"ltp":1.42,"tv":0.05,"id":22229228}]}]}
{"op":"mcm","clk":"1000754817","pt":1580620125591,"mc":[{"id":"1.168081821","rc":[{"batb":[[0,1.01,10.52],[1,1.01,0]],"batl":[[0,17,57.33]],"ltp":0.0,"tv":0.0,"id":15256065}]}]}
{"op":"mcm","clk":"1000754964","pt":1580620128675,"mc":[{"id":"1.168081821","rc":[{"batb":[[0,3.8,49.22],[1,1.01,10.52]],"ltp":0.0,"tv":0.0,"id":15256065}]}]}
{"op":"mcm","clk":"1000755611","pt":1580620142297,"mc":[{"id":"1.168081821","rc":[{"batl":[[0,24,50.52]],"ltp":0.0,"tv":0.0,"id":15256065}]}]}
{"op":"mcm","clk":"1000755687","pt":1580620143689,"mc":[{"id":"1.168081821","rc":[{"batb":[[0,1.01,10.52],[1,1.01,0]],"ltp":0.0,"tv":0.0,"id":15256065}]}]}
{"op":"mcm","clk":"1000755813","pt":1580620146478,"mc":[{"id":"1.168081821","rc":[{"batb":[[0,4.3,49.22],[1,1.01,10.52]],"ltp":0.0,"tv":0.0,"id":15256065}]}]}
{"op":"mcm","clk":"1000761163","pt":1580620260642,"mc":[{"id":"1.168081821","rc":[{"batl":[[0,30,47.16]],"ltp":0.0,"tv":0.0,"id":15256065},{"batl":[[0,1.35,1057.17]],"ltp":1.42,"tv":0.05,"id":22229228}]}]}
{"op":"mcm","clk":"1000763328","pt":1580620294598,"mc":[{"id":"1.168081821","rc":[{"batl":[[0,42,43.68]],"ltp":0.0,"tv":0.0,"id":15256065}]}]}
{"op":"mcm","clk":"1000764673","pt":1580620320129,"mc":[{"id":"1.168081821","rc":[{"batl":[[0,95,38.77]],"ltp":0.0,"tv":0.0,"id":15256065}]}]}
{"op":"mcm","clk":"1000766069","pt":1580620350345,"mc":[{"id":"1.168081821","rc":[{"batl":[[0,1.27,1360.36]],"ltp":1.42,"tv":0.05,"id":22229228}]}]}
{"op":"mcm","clk":"1000767949","pt":1580620389003,"mc":[{"id":"1.168081821","rc":[{"batb":[[0,1.01,10.52],[1,1.01,0]],"ltp":0.0,"tv":0.0,"id":15256065}]}]}
{"op":"mcm","clk":"1000768123","pt":1580620392109,"mc":[{"id":"1.168081821","rc":[{"batb":[[0,4.8,49.22],[1,1.01,10.52]],"ltp":0.0,"tv":0.0,"id":15256065}]}]}
{"op":"mcm","clk":"1000773442","pt":1580620508079,"mc":[{"id":"1.168081821","rc":[{"trd":[[1.01,3.36]],"batb":[[0,1.01,8.83]],"ltp":1.01,"tv":3.41,"id":22229228}],"tv":3.41}]}
{"op":"mcm","clk":"1000773734","pt":1580620514352,"mc":[{"id":"1.168081821","rc":[{"batl":[[0,1.27,1396.98]],"ltp":1.01,"tv":3.41,"id":22229228}]}]}
{"op":"mcm","clk":"1000776016","pt":1580620565099,"mc":[{"id":"1.168081821","rc":[{"trd":[[1.01,6.72]],"batb":[[0,1.01,7.15]],"ltp":1.01,"tv":6.77,"id":22229228}],"tv":6.77}]}
{"op":"mcm","clk":"1000777415","pt":1580620596297,"mc":[{"id":"1.168081821","rc":[{"batb":[[0,1.01,10.52],[1,1.01,0]],"ltp":0.0,"tv":0.0,"id":15256065}]}]}
{"op":"mcm","clk":"1000777535","pt":1580620599421,"mc":[{"id":"1.168081821","rc":[{"batb":[[0,5.8,49.22],[1,1.01,10.52]],"ltp":0.0,"tv":0.0,"id":15256065}]}]}
{"op":"mcm","clk":"1000779442","pt":1580620643654,"mc":[{"id":"1.168081821","rc":[{"trd":[[1.01,20.72]],"batb":[[0,1.01,0.15]],"ltp":1.01,"tv":20.77,"id":22229228}],"tv":20.77}]}
{"op":"mcm","clk":"1000788064","pt":1580620832355,"mc":[{"id":"1.168081821","rc":[{"batb":[[0,1.01,10.52],[1,1.01,0]],"ltp":0.0,"tv":0.0,"id":15256065}]}]}
{"op":"mcm","clk":"1000788202","pt":1580620835490,"mc":[{"id":"1.168081821","rc":[{"batb":[[0,5.3,49.22],[1,1.01,10.52]],"ltp":0.0,"tv":0.0,"id":15256065}]}]}
{"op":"mcm","clk":"1000788921","pt":1580620849600,"mc":[{"id":"1.168081821","rc":[{"batl":[[0,1.27,1396.98]],"ltp":1.01,"tv":20.77,"id":22229228}]}]}
{"op":"mcm","clk":"1000793935","pt":1580620946233,"mc":[{"id":"1.168081821","rc":[{"batl":[[0,1.26,1406.2]],"ltp":1.01,"tv":20.77,"id":22229228}]}]}
{"op":"mcm","clk":"1000795401","pt":1580620974581,"mc":[{"id":"1.168081821","rc":[{"batl":[[0,1.27,1396.98]],"ltp":1.01,"tv":20.77,"id":22229228}]}]}
{"op":"mcm","clk":"1000796571","pt":1580620996779,"mc":[{"id":"1.168081821","rc":[{"batl":[[0,1.26,1406.2]],"ltp":1.01,"tv":20.77,"id":22229228}]}]}
{"op":"mcm","clk":"1000800438","pt":1580621069334,"mc":[{"id":"1.168081821","marketDefinition":{"bspMarket":false,"turnInPlayEnabled":true,"persistenceEnabled":true,"marketBaseRate":5.0,"eventId":"29676917","eventTypeId":"2","numberOfWinners":1,"bettingType":"ODDS","marketType":"SET_WINNER","marketTime":"2020-02-02T04:00:00.000Z","suspendTime":"2020-02-02T04:00:00.000Z","bspReconciled":false,"complete":true,"inPlay":true,"crossMatching":true,"runnersVoidable":false,"numberOfActiveRunners":2,"betDelay":3,"status":"SUSPENDED","runners":[{"status":"ACTIVE","sortPriority":1,"id":22229228,"name":"Ram/Salisbury"},{"status":"ACTIVE","sortPriority":2,"id":15256065,"name":"Purcell/Saville"}],"regulators":["MR_INT"],"countryCode":"AU","discountAllowed":true,"timezone":"GMT","openDate":"2020-02-02T04:00:00.000Z","version":3148198863,"name":"Set 2 Winner","eventName":"Ram/Salisbury v Purcell/Saville"}}]}
{"op":"mcm","clk":"1000801030","pt":1580621081636,"mc":[{"id":"1.168081821","rc":[{"batb":[[0,1.01,10.52],[1,1.01,0]],"ltp":0.0,"tv":0.0,"id":15256065}]}]}
{"op":"mcm","clk":"1000802489","pt":1580621112429,"mc":[{"id":"1.168081821","tv":0.0}]}
{"op":"mcm","clk":"1000802541","pt":1580621113432,"mc":[{"id":"1.168081821","marketDefinition":{"bspMarket":false,"turnInPlayEnabled":true,"persistenceEnabled":true,"marketBaseRate":5.0,"eventId":"29676917","eventTypeId":"2","numberOfWinners":1,"bettingType":"ODDS","marketType":"SET_WINNER","marketTime":"2020-02-02T04:00:00.000Z","suspendTime":"2020-02-02T04:00:00.000Z","bspReconciled":false,"complete":true,"inPlay":true,"crossMatching":false,"runnersVoidable":false,"numberOfActiveRunners":0,"betDelay":3,"status":"CLOSED","settledTime":"2020-02-02T05:25:11.000Z","runners":[{"status":"WINNER","sortPriority":1,"id":22229228,"name":"Ram/Salisbury"},{"status":"LOSER","sortPriority":2,"id":15256065,"name":"Purcell/Saville"}],"regulators":["MR_INT"],"countryCode":"AU","discountAllowed":true,"timezone":"GMT","openDate":"2020-02-02T04:00:00.000Z","version":3148199094,"name":"Set 2 Winner","eventName":"Ram/Salisbury v Purcell/Saville"}}]}
