{"op":"mcm","clk":"993864652","pt":1580564223743,"mc":[{"id":"1.168213440","marketDefinition":{"bspMarket":false,"turnInPlayEnabled":true,"persistenceEnabled":true,"marketBaseRate":5.0,"eventId":"29681204","eventTypeId":"2","numberOfWinners":1,"bettingType":"ODDS","marketType":"SET_WINNER","marketTime":"2020-02-02T09:00:00.000Z","suspendTime":"2020-02-02T09:00:00.000Z","bspReconciled":false,"complete":true,"inPlay":false,"crossMatching":false,"runnersVoidable":false,"numberOfActiveRunners":2,"betDelay":0,"status":"OPEN","runners":[{"status":"ACTIVE","sortPriority":1,"id":8444034,"name":"Golubev/Nedovyesov"},{"status":"ACTIVE","sortPriority":2,"id":10107989,"name":"Sabanov/Sabanov"}],"regulators":["MR_INT"],"countryCode":"FR","discountAllowed":false,"timezone":"UTC","openDate":"2020-02-02T09:00:00.000Z","version":3145282991,"name":"Set 2 Winner","eventName":"Golubev/Nedovyesov v Sabanov/Sabanov"}}]}
{"op":"mcm","clk":"993865048","pt":1580564225394,"mc":[{"id":"1.168213440","rc":[{"batb":[[0,1.01,20]],"ltp":0.0,"tv":0.0,"id":10107989},{"batb":[[0,1.01,20]],"ltp":0.0,"tv":0.0,"id":8444034}]}]}
{"op":"mcm","clk":"993865150","pt":1580564225779,"mc":[{"id":"1.168213440","marketDefinition":{"bspMarket":false,"turnInPlayEnabled":true,"persistenceEnabled":true,"marketBaseRate":5.0,"eventId":"29681204","eventTypeId":"2","numberOfWinners":1,"bettingType":"ODDS","marketType":"SET_WINNER","marketTime":"2020-02-02T09:00:00.000Z","suspendTime":"2020-02-02T09:00:00.000Z","bspReconciled":false,"complete":true,"inPlay":false,"crossMatching":false,"runnersVoidable":false,"numberOfActiveRunners":2,"betDelay":0,"status":"OPEN","runners":[{"status":"ACTIVE","sortPriority":1,"id":8444034,"name":"Golubev/Nedovyesov"},{"status":"ACTIVE","sortPriority":2,"id":10107989,"name":"Sabanov/Sabanov"}],"regulators":["MR_INT"],"countryCode":"FR","discountAllowed":false,"timezone":"UTC","openDate":"2020-02-02T09:00:00.000Z","version":3145282991,"name":"Set 2 Winner","eventName":"Golubev/Nedovyesov v Sabanov/Sabanov"}}]}
{"op":"mcm","clk":"993865438","pt":1580564226748,"mc":[{"id":"1.168213440","marketDefinition":{"bspMarket":false,"turnInPlayEnabled":true,"persistenceEnabled":true,"marketBaseRate":5.0,"eventId":"29681204","eventTypeId":"2","numberOfWinners":1,"bettingType":"ODDS","marketType":"SET_WINNER","marketTime":"2020-02-02T09:00:00.000Z","suspendTime":"2020-02-02T09:00:00.000Z","bspReconciled":false,"complete":true,"inPlay":false,"crossMatching":false,"runnersVoidable":false,"numberOfActiveRunners":2,"betDelay":0,"status":"OPEN","runners":[{"status":"ACTIVE","sortPriority":1,"id":8444034,"name":"Golubev/Nedovyesov"},{"status":"ACTIVE","sortPriority":2,"id":10107989,"name":"Sabanov/Sabanov"}],"regulators":["MR_INT"],"countryCode":"FR","discountAllowed":true,"timezone":"UTC","openDate":"2020-02-02T09:00:00.000Z","version":3145282991,"name":"Set 2 Winner","eventName":"Golubev/Nedovyesov v Sabanov/Sabanov"}}]}
{"op":"mcm","clk":"993978347","pt":1580564712787,"mc":[{"id":"1.168213440","rc":[{"batb":[[0,1.01,15]],"ltp":0.0,"tv":0.0,"id":10107989},{"batb":[[0,1.01,15]],"ltp":0.0,"tv":0.0,"id":8444034}]}]}
{"op":"mcm","clk":"996243237","pt":1580574046235,"mc":[{"id":"1.168213440","marketDefinition":{"bspMarket":false,"turnInPlayEnabled":true,"persistenceEnabled":true,"marketBaseRate":5.0,"eventId":"29681204","eventTypeId":"2","numberOfWinners":1,"bettingType":"ODDS","marketType":"SET_WINNER","marketTime":"2020-02-02T13:00:00.000Z","suspendTime":"2020-02-02T13:00:00.000Z","bspReconciled":false,"complete":true,"inPlay":false,"crossMatching":false,"runnersVoidable":false,"numberOfActiveRunners":2,"betDelay":0,"status":"OPEN","runners":[{"status":"ACTIVE","sortPriority":1,"id":8444034,"name":"Golubev/Nedovyesov"},{"status":"ACTIVE","sortPriority":2,"id":10107989,"name":"Sabanov/Sabanov"}],"regulators":["MR_INT"],"countryCode":"FR","discountAllowed":true,"timezone":"UTC","openDate":"2020-02-02T09:00:00.000Z","version":3146180830,"name":"Set 2 Winner","eventName":"Golubev/Nedovyesov v Sabanov/Sabanov"}}]}
{"op":"mcm","clk":"996243943","pt":1580574049267,"mc":[{"id":"1.168213440","marketDefinition":{"bspMarket":false,"turnInPlayEnabled":true,"persistenceEnabled":true,"marketBaseRate":5.0,"eventId":"29681204","eventTypeId":"2","numberOfWinners":1,"bettingType":"ODDS","marketType":"SET_WINNER","marketTime":"2020-02-02T13:00:00.000Z","suspendTime":"2020-02-02T13:00:00.000Z","bspReconciled":false,"complete":true,"inPlay":false,"crossMatching":false,"runnersVoidable":false,"numberOfActiveRunners":2,"betDelay":0,"status":"OPEN","runners":[{"status":"ACTIVE","sortPriority":1,"id":8444034,"name":"Golubev/Nedovyesov"},{"status":"ACTIVE","sortPriority":2,"id":10107989,"name":"Sabanov/Sabanov"}],"regulators":["MR_INT"],"countryCode":"FR","discountAllowed":true,"timezone":"UTC","openDate":"2020-02-02T13:00:00.000Z","version":3146180830,"name":"Set 2 Winner","eventName":"Golubev/Nedovyesov v Sabanov/Sabanov"}}]}
{"op":"mcm","clk":"999914821","pt":1580602583679,"mc":[{"id":"1.168213440","rc":[{"batb":[[0,1.01,15.51]],"ltp":0.0,"tv":0.0,"id":10107989},{"batb":[[0,1.01,15.51]],"ltp":0.0,"tv":0.0,"id":8444034}]}]}
{"op":"mcm","clk":"999962496","pt":1580603349598,"mc":[{"id":"1.168213440","rc":[{"batb":[[0,1.01,16.01]],"ltp":0.0,"tv":0.0,"id":10107989},{"batb":[[0,1.01,16.01]],"ltp":0.0,"tv":0.0,"id":8444034}]}]}
{"op":"mcm","clk":"1003032753","pt":1580647775584,"mc":[{"id":"1.168213440","rc":[{"batb":[[0,2.38,17.07],[1,1.01,16.01]],"ltp":0.0,"tv":0.0,"id":10107989},{"batb":[[0,1.63,27.38],[1,1.01,16.01]],"ltp":0.0,"tv":0.0,"id":8444034}]}]}
{"op":"mcm","clk":"1003034239","pt":1580647783704,"mc":[{"id":"1.168213440","rc":[{"batb":[[0,2.36,17.23]],"ltp":0.0,"tv":0.0,"id":10107989},{"batb":[[0,1.64,27.07]],"ltp":0.0,"tv":0.0,"id":8444034}]}]}
{"op":"mcm","clk":"1003036088","pt":1580647793633,"mc":[{"id":"1.168213440","rc":[{"batb":[[0,1.64,26.75]],"ltp":0.0,"tv":0.0,"id":8444034}]}]}
{"op":"mcm","clk":"1003056996","pt":1580647911731,"mc":[{"id":"1.168213440","marketDefinition":{"bspMarket":false,"turnInPlayEnabled":true,"persistenceEnabled":true,"marketBaseRate":5.0,"eventId":"29681204","eventTypeId":"2","numberOfWinners":1,"bettingType":"ODDS","marketType":"SET_WINNER","marketTime":"2020-02-02T12:47:00.000Z","suspendTime":"2020-02-02T12:47:00.000Z","bspReconciled":false,"complete":true,"inPlay":false,"crossMatching":false,"runnersVoidable":false,"numberOfActiveRunners":2,"betDelay":0,"status":"OPEN","runners":[{"status":"ACTIVE","sortPriority":1,"id":8444034,"name":"Golubev/Nedovyesov"},{"status":"ACTIVE","sortPriority":2,"id":10107989,"name":"Sabanov/Sabanov"}],"regulators":["MR_INT"],"countryCode":"FR","discountAllowed":true,"timezone":"UTC","openDate":"2020-02-02T13:00:00.000Z","version":3148783609,"name":"Set 2 Winner","eventName":"Golubev/Nedovyesov v Sabanov/Sabanov"}}]}
{"op":"mcm","clk":"1003057552","pt":1580647914747,"mc":[{"id":"1.168213440","marketDefinition":{"bspMarket":false,"turnInPlayEnabled":true,"persistenceEnabled":true,"marketBaseRate":5.0,"eventId":"29681204","eventTypeId":"2","numberOfWinners":1,"bettingType":"ODDS","marketType":"SET_WINNER","marketTime":"2020-02-02T12:47:00.000Z","suspendTime":"2020-02-02T12:47:00.000Z","bspReconciled":false,"complete":true,"inPlay":false,"crossMatching":false,"runnersVoidable":false,"numberOfActiveRunners":2,"betDelay":0,"status":"OPEN","runners":[{"status":"ACTIVE","sortPriority":1,"id":8444034,"name":"Golubev/Nedovyesov"},{"status":"ACTIVE","sortPriority":2,"id":10107989,"name":"Sabanov/Sabanov"}],"regulators":["MR_INT"],"countryCode":"FR","discountAllowed":true,"timezone":"UTC","openDate":"2020-02-02T12:47:00.000Z","version":3148783609,"name":"Set 2 Winner","eventName":"Golubev/Nedovyesov v Sabanov/Sabanov"}}]}
{"op":"mcm","clk":"1003168208","pt":1580648568602,"mc":[{"id":"1.168213440","rc":[{"batb":[[0,1.01,16.01],[1,1.01,0]],"ltp":0.0,"tv":0.0,"id":10107989},{"batb":[[0,1.01,16.01],[1,1.01,0]],"ltp":0.0,"tv":0.0,"id":8444034}]}]}
{"op":"mcm","clk":"1003168303","pt":1580648569134,"mc":[{"id":"1.168213440","marketDefinition":{"bspMarket":false,"turnInPlayEnabled":true,"persistenceEnabled":true,"marketBaseRate":5.0,"eventId":"29681204","eventTypeId":"2","numberOfWinners":1,"bettingType":"ODDS","marketType":"SET_WINNER","marketTime":"2020-02-02T12:47:00.000Z","suspendTime":"2020-02-02T12:47:00.000Z","bspReconciled":false,"complete":true,"inPlay":true,"crossMatching":false,"runnersVoidable":false,"numberOfActiveRunners":2,"betDelay":3,"status":"OPEN","runners":[{"status":"ACTIVE","sortPriority":1,"id":8444034,"name":"Golubev/Nedovyesov"},{"status":"ACTIVE","sortPriority":2,"id":10107989,"name":"Sabanov/Sabanov"}],"regulators":["MR_INT"],"countryCode":"FR","discountAllowed":true,"timezone":"UTC","openDate":"2020-02-02T12:47:00.000Z","version":3148851633,"name":"Set 2 Winner","eventName":"Golubev/Nedovyesov v Sabanov/Sabanov"},"rc":[{"batb":[[0,1.01,15.51]],"ltp":0.0,"tv":0.0,"id":10107989},{"batb":[[0,1.01,15.51]],"ltp":0.0,"tv":0.0,"id":8444034}]}]}
{"op":"mcm","clk":"1003171573","pt":1580648586356,"mc":[{"id":"1.168213440","rc":[{"batb":[[0,2.3,18.57],[1,2.28,19.28],[2,1.01,15.51]],"ltp":0.0,"tv":0.0,"id":10107989},{"batb":[[0,1.67,25.41],[1,1.63,27.77],[2,1.01,15.51]],"ltp":0.0,"tv":0.0,"id":8444034}]}]}
{"op":"mcm","clk":"1003172797","pt":1580648592505,"mc":[{"id":"1.168213440","rc":[{"batb":[[0,2.28,19.28],[1,1.01,15.51],[2,1.01,0]],"ltp":0.0,"tv":0.0,"id":10107989},{"batb":[[0,1.63,27.77],[1,1.01,15.51],[2,1.01,0]],"ltp":0.0,"tv":0.0,"id":8444034}]}]}
{"op":"mcm","clk":"1003176203","pt":1580648610517,"mc":[{"id":"1.168213440","rc":[{"batb":[[0,2.4,16.76],[1,2.34,17.86],[2,1.01,15.51]],"ltp":0.0,"tv":0.0,"id":10107989},{"batb":[[1,1.59,30.21],[2,1.01,15.51]],"ltp":0.0,"tv":0.0,"id":8444034}]}]}
{"op":"mcm","clk":"1003179288","pt":1580648626271,"mc":[{"id":"1.168213440","rc":[{"batb":[[0,2.34,17.86],[1,1.01,15.51],[2,1.01,0]],"ltp":0.0,"tv":0.0,"id":10107989},{"batb":[[0,1.59,30.21],[1,1.01,15.51],[2,1.01,0]],"ltp":0.0,"tv":0.0,"id":8444034}]}]}
{"op":"mcm","clk":"1003181777","pt":1580648638658,"mc":[{"id":"1.168213440","rc":[{"batb":[[1,2.28,19.04],[2,1.01,15.51]],"ltp":0.0,"tv":0.0,"id":10107989},{"batb":[[0,1.65,26.28],[1,1.61,28.48],[2,1.01,15.51]],"ltp":0.0,"tv":0.0,"id":8444034}]}]}
{"op":"mcm","clk":"1003184819","pt":1580648655212,"mc":[{"id":"1.168213440","rc":[{"batb":[[0,2.28,19.04],[1,1.01,15.51],[2,1.01,0]],"ltp":0.0,"tv":0.0,"id":10107989},{"batb":[[0,1.61,28.48],[1,1.01,15.51],[2,1.01,0]],"ltp":0.0,"tv":0.0,"id":8444034}]}]}
{"op":"mcm","clk":"1003187289","pt":1580648669648,"mc":[{"id":"1.168213440","rc":[{"batb":[[1,2.24,20.06],[2,1.01,15.51]],"ltp":0.0,"tv":0.0,"id":10107989},{"batb":[[0,1.68,24.78],[1,1.64,26.67],[2,1.01,15.51]],"ltp":0.0,"tv":0.0,"id":8444034}]}]}
{"op":"mcm","clk":"1003190308","pt":1580648686041,"mc":[{"id":"1.168213440","rc":[{"batb":[[0,2.24,20.06],[1,1.01,15.51],[2,1.01,0]],"ltp":0.0,"tv":0.0,"id":10107989},{"batb":[[0,1.64,26.67],[1,1.01,15.51],[2,1.01,0]],"ltp":0.0,"tv":0.0,"id":8444034}]}]}
{"op":"mcm","clk":"1003190926","pt":1580648689427,"mc":[{"id":"1.168213440","rc":[{"batb":[[1,2.22,20.69],[2,1.01,15.51]],"ltp":0.0,"tv":0.0,"id":10107989},{"batb":[[0,1.66,25.97]],"ltp":0.0,"tv":0.0,"id":8444034}]}]}
{"op":"mcm","clk":"1003191491","pt":1580648692435,"mc":[{"id":"1.168213440","rc":[{"batb":[[0,2.22,20.69],[1,1.01,15.51],[2,1.01,0]],"ltp":0.0,"tv":0.0,"id":10107989}]}]}
{"op":"mcm","clk":"1003192018","pt":1580648695411,"mc":[{"id":"1.168213440","rc":[{"batb":[[1,2.16,22.58],[2,1.01,15.51]],"ltp":0.0,"tv":0.0,"id":10107989},{"batb":[[0,1.71,23.05],[1,1.69,24.16],[2,1.01,15.51]],"ltp":0.0,"tv":0.0,"id":8444034}]}]}
{"op":"mcm","clk":"1003193585","pt":1580648703681,"mc":[{"id":"1.168213440","rc":[{"batb":[[0,2.2,21.01],[1,2.14,22.98]],"ltp":0.0,"tv":0.0,"id":10107989},{"batb":[[0,1.72,22.74],[1,1.7,23.84]],"ltp":0.0,"tv":0.0,"id":8444034}]}]}
{"op":"mcm","clk":"1003195003","pt":1580648711364,"mc":[{"id":"1.168213440","rc":[{"batb":[[1,2.12,23.29]],"ltp":0.0,"tv":0.0,"id":10107989},{"batb":[[0,1.73,22.42],[1,1.7,23.53]],"ltp":0.0,"tv":0.0,"id":8444034}]}]}
{"op":"mcm","clk":"1003200910","pt":1580648744438,"mc":[{"id":"1.168213440","rc":[{"batb":[[0,2.12,23.29],[1,1.01,15.51],[2,1.01,0]],"ltp":0.0,"tv":0.0,"id":10107989},{"batb":[[0,1.7,23.53],[1,1.01,15.51],[2,1.01,0]],"ltp":0.0,"tv":0.0,"id":8444034}]}]}
{"op":"mcm","clk":"1003201488","pt":1580648747627,"mc":[{"id":"1.168213440","rc":[{"batb":[[0,2.14,23.21]],"ltp":0.0,"tv":0.0,"id":10107989}]}]}
{"op":"mcm","clk":"1003202418","pt":1580648752659,"mc":[{"id":"1.168213440","rc":[{"batb":[[0,2.24,20.14],[1,2.16,22.27],[2,2.14,23.21]],"ltp":0.0,"tv":0.0,"id":10107989},{"batb":[[1,1.68,24.78],[2,1.01,15.51]],"ltp":0.0,"tv":0.0,"id":8444034}]}]}
{"op":"mcm","clk":"1003202472","pt":1580648752923,"mc":[{"id":"1.168213440","rc":[{"batb":[[2,1.01,15.51]],"ltp":0.0,"tv":0.0,"id":10107989}]}]}
{"op":"mcm","clk":"1003205264","pt":1580648768679,"mc":[{"id":"1.168213440","rc":[{"batb":[[0,2.16,22.27],[1,1.01,15.51],[2,1.01,0]],"ltp":0.0,"tv":0.0,"id":10107989},{"batb":[[0,1.68,24.78],[1,1.01,15.51],[2,1.01,0]],"ltp":0.0,"tv":0.0,"id":8444034}]}]}
{"op":"mcm","clk":"1003205280","pt":1580648768763,"mc":[{"id":"1.168213440","rc":[{"batb":[[0,1.68,24.55]],"ltp":0.0,"tv":0.0,"id":8444034}]}]}
{"op":"mcm","clk":"1003208487","pt":1580648785651,"mc":[{"id":"1.168213440","rc":[{"batb":[[0,2.28,19.28],[1,2.2,21.09],[2,1.01,15.51]],"ltp":0.0,"tv":0.0,"id":10107989},{"batb":[[1,1.66,25.65],[2,1.01,15.51]],"ltp":0.0,"tv":0.0,"id":8444034}]}]}
{"op":"mcm","clk":"1003211497","pt":1580648801183,"mc":[{"id":"1.168213440","rc":[{"batb":[[0,2.2,21.09],[1,1.01,15.51],[2,1.01,0]],"ltp":0.0,"tv":0.0,"id":10107989},{"batb":[[0,1.66,25.65],[1,1.01,15.51],[2,1.01,0]],"ltp":0.0,"tv":0.0,"id":8444034}]}]}
{"op":"mcm","clk":"1003213122","pt":1580648809629,"mc":[{"id":"1.168213440","rc":[{"batb":[[0,2.32,18.33],[1,2.24,19.91],[2,2.2,21.09]],"ltp":0.0,"tv":0.0,"id":10107989},{"batb":[[1,1.64,26.67],[2,1.01,15.51]],"ltp":0.0,"tv":0.0,"id":8444034}]}]}
{"op":"mcm","clk":"1003213167","pt":1580648809945,"mc":[{"id":"1.168213440","rc":[{"batb":[[2,1.01,15.51]],"ltp":0.0,"tv":0.0,"id":10107989}]}]}
{"op":"mcm","clk":"1003214941","pt":1580648819355,"mc":[{"id":"1.168213440","rc":[{"batb":[[0,2.24,19.91],[1,1.01,15.51],[2,1.01,0]],"ltp":0.0,"tv":0.0,"id":10107989},{"batb":[[0,1.64,26.67],[1,1.01,15.51],[2,1.01,0]],"ltp":0.0,"tv":0.0,"id":8444034}]}]}
{"op":"mcm","clk":"1003216510","pt":1580648827441,"mc":[{"id":"1.168213440","rc":[{"batb":[[0,2.36,17.47],[1,2.32,18.41],[2,1.01,15.51]],"ltp":0.0,"tv":0.0,"id":10107989},{"batb":[[1,1.6,29.19],[2,1.01,15.51]],"ltp":0.0,"tv":0.0,"id":8444034}]}]}
{"op":"mcm","clk":"1003221404","pt":1580648854690,"mc":[{"id":"1.168213440","rc":[{"batb":[[0,2.32,18.41],[1,1.01,15.51],[2,1.01,0]],"ltp":0.0,"tv":0.0,"id":10107989},{"batb":[[0,1.6,29.19],[1,1.01,15.51],[2,1.01,0]],"ltp":0.0,"tv":0.0,"id":8444034}]}]}
{"op":"mcm","clk":"1003225439","pt":1580648876716,"mc":[{"id":"1.168213440","rc":[{"batb":[[0,2.44,15.82],[1,2.38,16.92],[2,1.01,15.51]],"ltp":0.0,"tv":0.0,"id":10107989},{"batb":[[1,1.56,32.26],[2,1.01,15.51]],"ltp":0.0,"tv":0.0,"id":8444034}]}]}
{"op":"mcm","clk":"1003228116","pt":1580648890648,"mc":[{"id":"1.168213440","rc":[{"batb":[[0,2.38,16.92],[1,1.01,15.51],[2,1.01,0]],"ltp":0.0,"tv":0.0,"id":10107989},{"batb":[[0,1.56,32.26],[1,1.01,15.51],[2,1.01,0]],"ltp":0.0,"tv":0.0,"id":8444034}]}]}
{"op":"mcm","clk":"1003231689","pt":1580648909549,"mc":[{"id":"1.168213440","rc":[{"batb":[[0,2.56,14.08],[1,2.48,15.11],[2,2.38,16.92]],"ltp":0.0,"tv":0.0,"id":10107989},{"batb":[[1,1.52,35.64],[2,1.01,15.51]],"ltp":0.0,"tv":0.0,"id":8444034}]}]}
{"op":"mcm","clk":"1003231737","pt":1580648909868,"mc":[{"id":"1.168213440","rc":[{"batb":[[2,1.01,15.51]],"ltp":0.0,"tv":0.0,"id":10107989}]}]}
{"op":"mcm","clk":"1003234253","pt":1580648923909,"mc":[{"id":"1.168213440","rc":[{"batb":[[0,2.48,15.11],[1,1.01,15.51],[2,1.01,0]],"ltp":0.0,"tv":0.0,"id":10107989},{"batb":[[0,1.52,35.64],[1,1.01,15.51],[2,1.01,0]],"ltp":0.0,"tv":0.0,"id":8444034}]}]}
{"op":"mcm","clk":"1003240916","pt":1580648960044,"mc":[{"id":"1.168213440","rc":[{"batb":[[1,2.42,16.37],[2,1.01,15.51]],"ltp":0.0,"tv":0.0,"id":10107989},{"batb":[[0,1.58,30.45],[1,1.54,33.6],[2,1.01,15.51]],"ltp":0.0,"tv":0.0,"id":8444034}]}]}
{"op":"mcm","clk":"1003243457","pt":1580648973969,"mc":[{"id":"1.168213440","rc":[{"batb":[[0,2.42,16.37],[1,1.01,15.51],[2,1.01,0]],"ltp":0.0,"tv":0.0,"id":10107989},{"batb":[[0,1.54,33.6],[1,1.01,15.51],[2,1.01,0]],"ltp":0.0,"tv":0.0,"id":8444034}]}]}
{"op":"mcm","clk":"1003245168","pt":1580648983495,"mc":[{"id":"1.168213440","rc":[{"batb":[[0,2.6,13.45],[1,2.54,14.4],[2,2.42,16.37]],"ltp":0.0,"tv":0.0,"id":10107989},{"batb":[[1,1.5,37.69],[2,1.01,15.51]],"ltp":0.0,"tv":0.0,"id":8444034}]}]}
{"op":"mcm","clk":"1003245228","pt":1580648983757,"mc":[{"id":"1.168213440","rc":[{"batb":[[2,1.01,15.51]],"ltp":0.0,"tv":0.0,"id":10107989}]}]}
{"op":"mcm","clk":"1003248005","pt":1580648999756,"mc":[{"id":"1.168213440","rc":[{"batb":[[0,2.54,14.4],[1,1.01,15.51],[2,1.01,0]],"ltp":0.0,"tv":0.0,"id":10107989},{"batb":[[0,1.5,37.69],[1,1.01,15.51],[2,1.01,0]],"ltp":0.0,"tv":0.0,"id":8444034}]}]}
{"op":"mcm","clk":"1003249678","pt":1580649008385,"mc":[{"id":"1.168213440","rc":[{"batb":[[1,2.44,15.74],[2,1.01,15.51]],"ltp":0.0,"tv":0.0,"id":10107989},{"batb":[[0,1.57,31.71],[1,1.51,36.27],[2,1.01,15.51]],"ltp":0.0,"tv":0.0,"id":8444034}]}]}
{"op":"mcm","clk":"1003251754","pt":1580649018906,"mc":[{"id":"1.168213440","rc":[{"batb":[[0,2.44,15.74],[1,1.01,15.51],[2,1.01,0]],"ltp":0.0,"tv":0.0,"id":10107989},{"batb":[[0,1.51,36.27],[1,1.01,15.51],[2,1.01,0]],"ltp":0.0,"tv":0.0,"id":8444034}]}]}
{"op":"mcm","clk":"1003253430","pt":1580649027464,"mc":[{"id":"1.168213440","rc":[{"batb":[[1,2.34,17.62],[2,1.01,15.51]],"ltp":0.0,"tv":0.0,"id":10107989},{"batb":[[0,1.6,29.35],[1,1.53,34.62],[2,1.01,15.51]],"ltp":0.0,"tv":0.0,"id":8444034}]}]}
{"op":"mcm","clk":"1003255792","pt":1580649039786,"mc":[{"id":"1.168213440","rc":[{"batb":[[0,2.34,17.62],[1,1.01,15.51],[2,1.01,0]],"ltp":0.0,"tv":0.0,"id":10107989},{"batb":[[0,1.53,34.62],[1,1.01,15.51],[2,1.01,0]],"ltp":0.0,"tv":0.0,"id":8444034}]}]}
{"op":"mcm","clk":"1003257543","pt":1580649048555,"mc":[{"id":"1.168213440","rc":[{"batb":[[0,2.64,12.98],[1,2.52,14.56],[2,1.01,15.51]],"ltp":0.0,"tv":0.0,"id":10107989},{"batb":[[1,1.52,36.12],[2,1.01,15.51]],"ltp":0.0,"tv":0.0,"id":8444034}]}]}
{"op":"mcm","clk":"1003273727","pt":1580649130936,"mc":[{"id":"1.168213440","rc":[{"batb":[[0,2.52,14.56],[1,1.01,15.51],[2,1.01,0]],"ltp":0.0,"tv":0.0,"id":10107989},{"batb":[[0,1.52,36.12],[1,1.01,15.51],[2,1.01,0]],"ltp":0.0,"tv":0.0,"id":8444034}]}]}
{"op":"mcm","clk":"1003277975","pt":1580649152320,"mc":[{"id":"1.168213440","rc":[{"batb":[[1,2.42,16.44],[2,1.01,15.51]],"ltp":0.0,"tv":0.0,"id":10107989},{"batb":[[0,1.57,31.39],[1,1.54,33.52],[2,1.01,15.51]],"ltp":0.0,"tv":0.0,"id":8444034}]}]}
{"op":"mcm","clk":"1003281455","pt":1580649170899,"mc":[{"id":"1.168213440","rc":[{"batb":[[0,2.42,16.44],[1,1.01,15.51],[2,1.01,0]],"ltp":0.0,"tv":0.0,"id":10107989},{"batb":[[0,1.54,33.52],[1,1.01,15.51],[2,1.01,0]],"ltp":0.0,"tv":0.0,"id":8444034}]}]}
{"op":"mcm","clk":"1003283045","pt":1580649179717,"mc":[{"id":"1.168213440","rc":[{"batb":[[0,2.6,13.45],[1,2.48,15.34],[2,1.01,15.51]],"ltp":0.0,"tv":0.0,"id":10107989},{"batb":[[1,1.53,34.93],[2,1.01,15.51]],"ltp":0.0,"tv":0.0,"id":8444034}]}]}
{"op":"mcm","clk":"1003285817","pt":1580649194631,"mc":[{"id":"1.168213440","rc":[{"batb":[[0,2.48,15.34],[1,1.01,15.51],[2,1.01,0]],"ltp":0.0,"tv":0.0,"id":10107989},{"batb":[[0,1.53,34.93],[1,1.01,15.51],[2,1.01,0]],"ltp":0.0,"tv":0.0,"id":8444034}]}]}
{"op":"mcm","clk":"1003288065","pt":1580649207670,"mc":[{"id":"1.168213440","rc":[{"batb":[[1,2.36,17.47],[2,1.01,15.51]],"ltp":0.0,"tv":0.0,"id":10107989},{"batb":[[0,1.59,29.98],[1,1.56,31.94],[2,1.53,34.93]],"ltp":0.0,"tv":0.0,"id":8444034}]}]}
{"op":"mcm","clk":"1003288099","pt":1580649207869,"mc":[{"id":"1.168213440","rc":[{"batb":[[2,1.01,15.51]],"ltp":0.0,"tv":0.0,"id":8444034}]}]}
{"op":"mcm","clk":"1003291268","pt":1580649225213,"mc":[{"id":"1.168213440","rc":[{"batb":[[0,2.36,17.47],[1,1.01,15.51],[2,1.01,0]],"ltp":0.0,"tv":0.0,"id":10107989},{"batb":[[0,1.56,31.94],[1,1.01,15.51],[2,1.01,0]],"ltp":0.0,"tv":0.0,"id":8444034}]}]}
{"op":"mcm","clk":"1003293656","pt":1580649238198,"mc":[{"id":"1.168213440","rc":[{"batb":[[0,2.54,14.24],[1,2.4,16.6],[2,1.01,15.51]],"ltp":0.0,"tv":0.0,"id":10107989},{"batb":[[1,1.54,33.83],[2,1.01,15.51]],"ltp":0.0,"tv":0.0,"id":8444034}]}]}
{"op":"mcm","clk":"1003294327","pt":1580649242047,"mc":[{"id":"1.168213440","rc":[{"batb":[[0,2.4,16.6],[1,1.01,15.51],[2,1.01,0]],"ltp":0.0,"tv":0.0,"id":10107989},{"batb":[[0,1.54,33.83],[1,1.01,15.51],[2,1.01,0]],"ltp":0.0,"tv":0.0,"id":8444034}]}]}
{"op":"mcm","clk":"1003299780","pt":1580649271696,"mc":[{"id":"1.168213440","rc":[{"batb":[[0,2.6,13.38],[1,2.48,15.19],[2,1.01,15.51]],"ltp":0.0,"tv":0.0,"id":10107989},{"batb":[[1,1.52,35.64],[2,1.01,15.51]],"ltp":0.0,"tv":0.0,"id":8444034}]}]}
{"op":"mcm","clk":"1003303776","pt":1580649293064,"mc":[{"id":"1.168213440","rc":[{"batb":[[0,2.48,15.19],[1,1.01,15.51],[2,1.01,0]],"ltp":0.0,"tv":0.0,"id":10107989},{"batb":[[0,1.52,35.64],[1,1.01,15.51],[2,1.01,0]],"ltp":0.0,"tv":0.0,"id":8444034}]}]}
{"op":"mcm","clk":"1003308364","pt":1580649317546,"mc":[{"id":"1.168213440","rc":[{"batb":[[0,2.66,12.51],[1,2.62,13.22],[2,1.01,15.51]],"ltp":0.0,"tv":0.0,"id":10107989},{"batb":[[1,1.49,38.87],[2,1.01,15.51]],"ltp":0.0,"tv":0.0,"id":8444034}]}]}
{"op":"mcm","clk":"1003313716","pt":1580649350292,"mc":[{"id":"1.168213440","rc":[{"batb":[[0,2.62,13.22],[1,1.01,15.51],[2,1.01,0]],"ltp":0.0,"tv":0.0,"id":10107989},{"batb":[[0,1.49,38.87],[1,1.01,15.51],[2,1.01,0]],"ltp":0.0,"tv":0.0,"id":8444034}]}]}
{"op":"mcm","clk":"1003315623","pt":1580649361409,"mc":[{"id":"1.168213440","rc":[{"batb":[[1,2.56,14.08],[2,1.01,15.51]],"ltp":0.0,"tv":0.0,"id":10107989},{"batb":[[0,1.54,33.99],[1,1.51,36.82],[2,1.01,15.51]],"ltp":0.0,"tv":0.0,"id":8444034}]}]}
{"op":"mcm","clk":"1003318642","pt":1580649377847,"mc":[{"id":"1.168213440","rc":[{"batb":[[0,2.56,14.08],[1,1.01,15.51],[2,1.01,0]],"ltp":0.0,"tv":0.0,"id":10107989},{"batb":[[0,1.51,36.82],[1,1.01,15.51],[2,1.01,0]],"ltp":0.0,"tv":0.0,"id":8444034}]}]}
{"op":"mcm","clk":"1003320758","pt":1580649389326,"mc":[{"id":"1.168213440","rc":[{"batb":[[1,2.5,14.95],[2,1.01,15.51]],"ltp":0.0,"tv":0.0,"id":10107989},{"batb":[[0,1.56,32.26],[1,1.53,35.09],[2,1.01,15.51]],"ltp":0.0,"tv":0.0,"id":8444034}]}]}
{"op":"mcm","clk":"1003323656","pt":1580649404506,"mc":[{"id":"1.168213440","rc":[{"batb":[[0,2.5,14.95],[1,1.01,15.51],[2,1.01,0]],"ltp":0.0,"tv":0.0,"id":10107989},{"batb":[[0,1.53,35.09],[1,1.01,15.51],[2,1.01,0]],"ltp":0.0,"tv":0.0,"id":8444034}]}]}
{"op":"mcm","clk":"1003327321","pt":1580649424636,"mc":[{"id":"1.168213440","rc":[{"batb":[[0,2.64,12.75],[1,2.58,13.69],[2,1.01,15.51]],"ltp":0.0,"tv":0.0,"id":10107989},{"batb":[[1,1.49,38.48],[2,1.01,15.51]],"ltp":0.0,"tv":0.0,"id":8444034}]}]}
{"op":"mcm","clk":"1003331256","pt":1580649446309,"mc":[{"id":"1.168213440","rc":[{"batb":[[0,2.58,13.69],[1,1.01,15.51],[2,1.01,0]],"ltp":0.0,"tv":0.0,"id":10107989},{"batb":[[0,1.49,38.48],[1,1.01,15.51],[2,1.01,0]],"ltp":0.0,"tv":0.0,"id":8444034}]}]}
{"op":"mcm","clk":"1003333457","pt":1580649459697,"mc":[{"id":"1.168213440","rc":[{"batb":[[0,2.76,11.41],[1,2.68,12.51],[2,2.58,13.69]],"ltp":0.0,"tv":0.0,"id":10107989},{"batb":[[1,1.46,42.09],[2,1.01,15.51]],"ltp":0.0,"tv":0.0,"id":8444034}]}]}
{"op":"mcm","clk":"1003333486","pt":1580649459909,"mc":[{"id":"1.168213440","rc":[{"batb":[[2,1.01,15.51]],"ltp":0.0,"tv":0.0,"id":10107989}]}]}
{"op":"mcm","clk":"1003337769","pt":1580649483870,"mc":[{"id":"1.168213440","rc":[{"batb":[[0,2.68,12.51],[1,1.01,15.51],[2,1.01,0]],"ltp":0.0,"tv":0.0,"id":10107989},{"batb":[[0,1.46,42.09],[1,1.01,15.51],[2,1.01,0]],"ltp":0.0,"tv":0.0,"id":8444034}]}]}
{"op":"mcm","clk":"1003339600","pt":1580649493677,"mc":[{"id":"1.168213440","rc":[{"batb":[[1,2.6,13.45],[2,1.01,15.51]],"ltp":0.0,"tv":0.0,"id":10107989},{"batb":[[0,1.52,35.8],[1,1.48,39.1],[2,1.46,42.09]],"ltp":0.0,"tv":0.0,"id":8444034}]}]}
{"op":"mcm","clk":"1003339674","pt":1580649494076,"mc":[{"id":"1.168213440","rc":[{"batb":[[2,1.01,15.51]],"ltp":0.0,"tv":0.0,"id":8444034}]}]}
{"op":"mcm","clk":"1003342391","pt":1580649509975,"mc":[{"id":"1.168213440","rc":[{"batb":[[0,2.6,13.45],[1,1.01,15.51],[2,1.01,0]],"ltp":0.0,"tv":0.0,"id":10107989},{"batb":[[0,1.48,39.1],[1,1.01,15.51],[2,1.01,0]],"ltp":0.0,"tv":0.0,"id":8444034}]}]}
{"op":"mcm","clk":"1003344252","pt":1580649520128,"mc":[{"id":"1.168213440","rc":[{"batb":[[1,2.5,15.03],[2,1.01,15.51]],"ltp":0.0,"tv":0.0,"id":10107989},{"batb":[[0,1.54,33.68],[1,1.52,35.49],[2,1.01,15.51]],"ltp":0.0,"tv":0.0,"id":8444034}]}]}
{"op":"mcm","clk":"1003359171","pt":1580649614406,"mc":[{"id":"1.168213440","rc":[{"batb":[[0,2.5,15.03],[1,1.01,15.51],[2,1.01,0]],"ltp":0.0,"tv":0.0,"id":10107989},{"batb":[[0,1.52,35.49],[1,1.01,15.51],[2,1.01,0]],"ltp":0.0,"tv":0.0,"id":8444034}]}]}
{"op":"mcm","clk":"1003362270","pt":1580649633724,"mc":[{"id":"1.168213440","rc":[{"batb":[[0,2.66,12.59],[1,2.54,14.16],[2,1.01,15.51]],"ltp":0.0,"tv":0.0,"id":10107989},{"batb":[[1,1.5,37.53],[2,1.01,15.51]],"ltp":0.0,"tv":0.0,"id":8444034}]}]}
{"op":"mcm","clk":"1003364692","pt":1580649649045,"mc":[{"id":"1.168213440","rc":[{"batb":[[0,2.54,14.16],[1,1.01,15.51],[2,1.01,0]],"ltp":0.0,"tv":0.0,"id":10107989},{"batb":[[0,1.5,37.53],[1,1.01,15.51],[2,1.01,0]],"ltp":0.0,"tv":0.0,"id":8444034}]}]}
{"op":"mcm","clk":"1003365800","pt":1580649656051,"mc":[{"id":"1.168213440","rc":[{"batb":[[0,2.74,11.8],[1,2.6,13.3],[2,1.01,15.51]],"ltp":0.0,"tv":0.0,"id":10107989},{"batb":[[1,1.49,39.1],[2,1.01,15.51]],"ltp":0.0,"tv":0.0,"id":8444034}]}]}
{"op":"mcm","clk":"1003367767","pt":1580649669032,"mc":[{"id":"1.168213440","rc":[{"batb":[[0,2.6,13.3],[1,1.01,15.51],[2,1.01,0]],"ltp":0.0,"tv":0.0,"id":10107989},{"batb":[[0,1.49,39.1],[1,1.01,15.51],[2,1.01,0]],"ltp":0.0,"tv":0.0,"id":8444034}]}]}
{"op":"mcm","clk":"1003370378","pt":1580649686606,"mc":[{"id":"1.168213440","rc":[{"batb":[[0,1.01,15.51],[1,1.01,0]],"ltp":0.0,"tv":0.0,"id":8444034}]}]}
{"op":"mcm","clk":"1003370907","pt":1580649689502,"mc":[{"id":"1.168213440","rc":[{"batb":[[0,2.8,11.09],[1,2.68,12.43],[2,2.6,13.3]],"ltp":0.0,"tv":0.0,"id":10107989},{"batb":[[0,1.48,39.42],[1,1.47,41.15],[2,1.01,15.51]],"ltp":0.0,"tv":0.0,"id":8444034}]}]}
{"op":"mcm","clk":"1003370997","pt":1580649690090,"mc":[{"id":"1.168213440","rc":[{"batb":[[2,1.01,15.51]],"ltp":0.0,"tv":0.0,"id":10107989}]}]}
{"op":"mcm","clk":"1003373316","pt":1580649705319,"mc":[{"id":"1.168213440","rc":[{"batb":[[0,2.68,12.43],[1,1.01,15.51],[2,1.01,0]],"ltp":0.0,"tv":0.0,"id":10107989},{"batb":[[0,1.47,41.15],[1,1.01,15.51],[2,1.01,0]],"ltp":0.0,"tv":0.0,"id":8444034}]}]}
{"op":"mcm","clk":"1003374507","pt":1580649713439,"mc":[{"id":"1.168213440","rc":[{"batb":[[0,2.86,10.54],[1,2.78,11.25],[2,2.68,12.43]],"ltp":0.0,"tv":0.0,"id":10107989},{"batb":[[1,1.44,44.69],[2,1.01,15.51]],"ltp":0.0,"tv":0.0,"id":8444034}]}]}
{"op":"mcm","clk":"1003374557","pt":1580649713758,"mc":[{"id":"1.168213440","rc":[{"batb":[[2,1.01,15.51]],"ltp":0.0,"tv":0.0,"id":10107989}]}]}
{"op":"mcm","clk":"1003375923","pt":1580649722863,"mc":[{"id":"1.168213440","rc":[{"trd":[[2.86,10]],"batb":[[0,2.86,5.54]],"ltp":2.86,"tv":10.0,"id":10107989}],"tv":10.0}]}
{"op":"mcm","clk":"1003376124","pt":1580649724048,"mc":[{"id":"1.168213440","rc":[{"trd":[[2.86,14]],"batb":[[0,2.86,3.54]],"ltp":2.86,"tv":14.0,"id":10107989}],"tv":14.0}]}
{"op":"mcm","clk":"1003376366","pt":1580649725644,"mc":[{"id":"1.168213440","rc":[{"trd":[[2.86,21.08]],"batb":[[0,2.78,11.25],[1,1.01,15.51],[2,1.01,0]],"ltp":2.86,"tv":21.08,"id":10107989}],"tv":21.08}]}
{"op":"mcm","clk":"1003378976","pt":1580649741636,"mc":[{"id":"1.168213440","rc":[{"batb":[[0,1.44,44.69],[1,1.01,15.51],[2,1.01,0]],"ltp":0.0,"tv":0.0,"id":8444034}]}]}
{"op":"mcm","clk":"1003379482","pt":1580649744742,"mc":[{"id":"1.168213440","rc":[{"batb":[[1,2.76,11.49],[2,1.01,15.51]],"ltp":2.86,"tv":21.08,"id":10107989},{"batb":[[0,1.45,44.14],[1,1.44,44.69],[2,1.01,15.51]],"ltp":0.0,"tv":0.0,"id":8444034}]}]}
{"op":"mcm","clk":"1003379528","pt":1580649745019,"mc":[{"id":"1.168213440","rc":[{"batb":[[0,2.76,11.49],[1,1.01,15.51],[2,1.01,0]],"ltp":2.86,"tv":21.08,"id":10107989},{"batb":[[1,1.01,15.51],[2,1.01,0]],"ltp":0.0,"tv":0.0,"id":8444034}]}]}
{"op":"mcm","clk":"1003381282","pt":1580649756436,"mc":[{"id":"1.168213440","rc":[{"batb":[[1,2.7,12.12],[2,1.01,15.51]],"ltp":2.86,"tv":21.08,"id":10107989},{"batb":[[0,1.5,38.32],[1,1.47,41.54],[2,1.01,15.51]],"ltp":0.0,"tv":0.0,"id":8444034}]}]}
{"op":"mcm","clk":"1003383239","pt":1580649769109,"mc":[{"id":"1.168213440","rc":[{"batb":[[0,2.7,12.12],[1,1.01,15.51],[2,1.01,0]],"ltp":2.86,"tv":21.08,"id":10107989},{"batb":[[0,1.47,41.54],[1,1.01,15.51],[2,1.01,0]],"ltp":0.0,"tv":0.0,"id":8444034}]}]}
{"op":"mcm","clk":"1003386474","pt":1580649789227,"mc":[{"id":"1.168213440","rc":[{"batb":[[1,2.64,12.98],[2,1.01,15.51]],"ltp":2.86,"tv":21.08,"id":10107989},{"batb":[[0,1.52,36.51],[1,1.49,39.89],[2,1.01,15.51]],"ltp":0.0,"tv":0.0,"id":8444034}]}]}
{"op":"mcm","clk":"1003389178","pt":1580649805661,"mc":[{"id":"1.168213440","rc":[{"batb":[[0,2.64,12.98],[1,1.01,15.51],[2,1.01,0]],"ltp":2.86,"tv":21.08,"id":10107989},{"batb":[[0,1.49,39.89],[1,1.01,15.51],[2,1.01,0]],"ltp":0.0,"tv":0.0,"id":8444034}]}]}
{"op":"mcm","clk":"1003390381","pt":1580649813162,"mc":[{"id":"1.168213440","rc":[{"batb":[[1,2.58,13.77],[2,1.01,15.51]],"ltp":2.86,"tv":21.08,"id":10107989},{"batb":[[0,1.54,34.62],[1,1.51,37.61],[2,1.01,15.51]],"ltp":0.0,"tv":0.0,"id":8444034}]}]}
{"op":"mcm","clk":"1003392112","pt":1580649823621,"mc":[{"id":"1.168213440","rc":[{"batb":[[0,2.58,13.77],[1,1.01,15.51],[2,1.01,0]],"ltp":2.86,"tv":21.08,"id":10107989},{"batb":[[0,1.51,37.61],[1,1.01,15.51],[2,1.01,0]],"ltp":0.0,"tv":0.0,"id":8444034}]}]}
{"op":"mcm","clk":"1003395443","pt":1580649843723,"mc":[{"id":"1.168213440","rc":[{"batb":[[1,2.44,15.82],[2,1.01,15.51]],"ltp":2.86,"tv":21.08,"id":10107989},{"batb":[[0,1.56,32.97],[1,1.54,34.62],[2,1.51,37.61]],"ltp":0.0,"tv":0.0,"id":8444034}]}]}
{"op":"mcm","clk":"1003395495","pt":1580649844041,"mc":[{"id":"1.168213440","rc":[{"batb":[[2,1.01,15.51]],"ltp":0.0,"tv":0.0,"id":8444034}]}]}
{"op":"mcm","clk":"1003408821","pt":1580649923207,"mc":[{"id":"1.168213440","rc":[{"batb":[[0,2.44,15.82],[1,1.01,15.51],[2,1.01,0]],"ltp":2.86,"tv":21.08,"id":10107989},{"batb":[[0,1.54,34.62],[1,1.01,15.51],[2,1.01,0]],"ltp":0.0,"tv":0.0,"id":8444034}]}]}
{"op":"mcm","clk":"1003410963","pt":1580649935718,"mc":[{"id":"1.168213440","rc":[{"batb":[[1,2.32,18.18],[2,1.01,15.51]],"ltp":2.86,"tv":21.08,"id":10107989},{"batb":[[0,1.62,29.35],[1,1.59,31.24],[2,1.54,34.62]],"ltp":0.0,"tv":0.0,"id":8444034}]}]}
{"op":"mcm","clk":"1003411001","pt":1580649935928,"mc":[{"id":"1.168213440","rc":[{"batb":[[2,1.01,15.51]],"ltp":0.0,"tv":0.0,"id":8444034}]}]}
{"op":"mcm","clk":"1003413460","pt":1580649950569,"mc":[{"id":"1.168213440","rc":[{"batb":[[0,2.32,18.18],[1,1.01,15.51],[2,1.01,0]],"ltp":2.86,"tv":21.08,"id":10107989},{"batb":[[0,1.59,31.24],[1,1.01,15.51],[2,1.01,0]],"ltp":0.0,"tv":0.0,"id":8444034}]}]}
{"op":"mcm","clk":"1003415037","pt":1580649962048,"mc":[{"id":"1.168213440","rc":[{"batb":[[1,2.22,20.93],[2,1.01,15.51]],"ltp":2.86,"tv":21.08,"id":10107989},{"batb":[[0,1.68,25.89],[1,1.64,27.7],[2,1.01,15.51]],"ltp":0.0,"tv":0.0,"id":8444034}]}]}
{"op":"mcm","clk":"1003417795","pt":1580649980361,"mc":[{"id":"1.168213440","rc":[{"batb":[[0,2.22,20.93],[1,1.01,15.51],[2,1.01,0]],"ltp":2.86,"tv":21.08,"id":10107989},{"batb":[[0,1.64,27.7],[1,1.01,15.51],[2,1.01,0]],"ltp":0.0,"tv":0.0,"id":8444034}]}]}
{"op":"mcm","clk":"1003419330","pt":1580649989630,"mc":[{"id":"1.168213440","rc":[{"batb":[[0,2.4,16.76],[1,2.26,19.83],[2,2.22,20.93]],"ltp":2.86,"tv":21.08,"id":10107989},{"batb":[[1,1.61,29.66],[2,1.01,15.51]],"ltp":0.0,"tv":0.0,"id":8444034}]}]}
{"op":"mcm","clk":"1003419367","pt":1580649989908,"mc":[{"id":"1.168213440","rc":[{"batb":[[2,1.01,15.51]],"ltp":2.86,"tv":21.08,"id":10107989}]}]}
{"op":"mcm","clk":"1003422017","pt":1580650007172,"mc":[{"id":"1.168213440","rc":[{"batb":[[0,2.26,19.83],[1,1.01,15.51],[2,1.01,0]],"ltp":2.86,"tv":21.08,"id":10107989},{"batb":[[0,1.61,29.66],[1,1.01,15.51],[2,1.01,0]],"ltp":0.0,"tv":0.0,"id":8444034}]}]}
{"op":"mcm","clk":"1003425094","pt":1580650027347,"mc":[{"id":"1.168213440","rc":[{"batb":[[0,2.46,15.58],[1,2.32,18.41],[2,1.01,15.51]],"ltp":2.86,"tv":21.08,"id":10107989},{"batb":[[1,1.58,31.71],[2,1.01,15.51]],"ltp":0.0,"tv":0.0,"id":8444034}]}]}
{"op":"mcm","clk":"1003427776","pt":1580650045358,"mc":[{"id":"1.168213440","rc":[{"batb":[[0,2.32,18.41],[1,1.01,15.51],[2,1.01,0]],"ltp":2.86,"tv":21.08,"id":10107989},{"batb":[[0,1.58,31.71],[1,1.01,15.51],[2,1.01,0]],"ltp":0.0,"tv":0.0,"id":8444034}]}]}
{"op":"mcm","clk":"1003431757","pt":1580650072544,"mc":[{"id":"1.168213440","rc":[{"batb":[[0,2.54,14.4],[1,2.4,16.76],[2,1.01,15.51]],"ltp":2.86,"tv":21.08,"id":10107989},{"batb":[[1,1.55,33.83],[2,1.01,15.51]],"ltp":0.0,"tv":0.0,"id":8444034}]}]}
{"op":"mcm","clk":"1003434261","pt":1580650088903,"mc":[{"id":"1.168213440","rc":[{"batb":[[0,2.4,16.76],[1,1.01,15.51],[2,1.01,0]],"ltp":2.86,"tv":21.08,"id":10107989},{"batb":[[0,1.55,33.83],[1,1.01,15.51],[2,1.01,0]],"ltp":0.0,"tv":0.0,"id":8444034}]}]}
{"op":"mcm","clk":"1003435993","pt":1580650099560,"mc":[{"id":"1.168213440","rc":[{"batb":[[1,2.2,21.09],[2,1.01,15.51]],"ltp":2.86,"tv":21.08,"id":10107989},{"batb":[[0,1.64,27.77],[1,1.59,30.92],[2,1.55,33.83]],"ltp":0.0,"tv":0.0,"id":8444034}]}]}
{"op":"mcm","clk":"1003436079","pt":1580650100139,"mc":[{"id":"1.168213440","rc":[{"batb":[[2,1.01,15.51]],"ltp":0.0,"tv":0.0,"id":8444034}]}]}
{"op":"mcm","clk":"1003439675","pt":1580650123588,"mc":[{"id":"1.168213440","rc":[{"batb":[[0,2.2,21.09],[1,1.01,15.51],[2,1.01,0]],"ltp":2.86,"tv":21.08,"id":10107989},{"batb":[[0,1.59,30.92],[1,1.01,15.51],[2,1.01,0]],"ltp":0.0,"tv":0.0,"id":8444034}]}]}
{"op":"mcm","clk":"1003442828","pt":1580650144320,"mc":[{"id":"1.168213440","rc":[{"batb":[[0,2.5,14.87],[1,2.44,15.82],[2,1.01,15.51]],"ltp":2.86,"tv":21.08,"id":10107989},{"batb":[[1,1.55,34.07],[2,1.01,15.51]],"ltp":0.0,"tv":0.0,"id":8444034}]}]}
{"op":"mcm","clk":"1003447220","pt":1580650172616,"mc":[{"id":"1.168213440","rc":[{"batb":[[0,2.44,15.82],[1,1.01,15.51],[2,1.01,0]],"ltp":2.86,"tv":21.08,"id":10107989},{"batb":[[0,1.55,34.07],[1,1.01,15.51],[2,1.01,0]],"ltp":0.0,"tv":0.0,"id":8444034}]}]}
{"op":"mcm","clk":"1003448472","pt":1580650180602,"mc":[{"id":"1.168213440","rc":[{"batb":[[0,2.62,13.22],[1,2.54,14.16],[2,2.44,15.82]],"ltp":2.86,"tv":21.08,"id":10107989},{"batb":[[1,1.52,37.22],[2,1.01,15.51]],"ltp":0.0,"tv":0.0,"id":8444034}]}]}
{"op":"mcm","clk":"1003448513","pt":1580650180871,"mc":[{"id":"1.168213440","rc":[{"batb":[[2,1.01,15.51]],"ltp":2.86,"tv":21.08,"id":10107989}]}]}
{"op":"mcm","clk":"1003450750","pt":1580650195631,"mc":[{"id":"1.168213440","rc":[{"batb":[[0,2.54,14.16],[1,1.01,15.51],[2,1.01,0]],"ltp":2.86,"tv":21.08,"id":10107989},{"batb":[[0,1.52,37.22],[1,1.01,15.51],[2,1.01,0]],"ltp":0.0,"tv":0.0,"id":8444034}]}]}
{"op":"mcm","clk":"1003452352","pt":1580650204551,"mc":[{"id":"1.168213440","rc":[{"batb":[[0,2.72,11.88],[1,2.66,12.59],[2,1.01,15.51]],"ltp":2.86,"tv":21.08,"id":10107989},{"batb":[[1,1.47,41.62],[2,1.01,15.51]],"ltp":0.0,"tv":0.0,"id":8444034}]}]}
{"op":"mcm","clk":"1003455372","pt":1580650222831,"mc":[{"id":"1.168213440","rc":[{"batb":[[0,2.66,12.59],[1,1.01,15.51],[2,1.01,0]],"ltp":2.86,"tv":21.08,"id":10107989},{"batb":[[0,1.47,41.62],[1,1.01,15.51],[2,1.01,0]],"ltp":0.0,"tv":0.0,"id":8444034}]}]}
{"op":"mcm","clk":"1003457314","pt":1580650235643,"mc":[{"id":"1.168213440","rc":[{"batb":[[1,2.58,13.69],[2,1.01,15.51]],"ltp":2.86,"tv":21.08,"id":10107989},{"batb":[[0,1.53,35.49],[1,1.49,39.34],[2,1.01,15.51]],"ltp":0.0,"tv":0.0,"id":8444034}]}]}
{"op":"mcm","clk":"1003459434","pt":1580650249940,"mc":[{"id":"1.168213440","rc":[{"batb":[[0,2.58,13.69],[1,1.01,15.51],[2,1.01,0]],"ltp":2.86,"tv":21.08,"id":10107989},{"batb":[[0,1.49,39.34],[1,1.01,15.51],[2,1.01,0]],"ltp":0.0,"tv":0.0,"id":8444034}]}]}
{"op":"mcm","clk":"1003460744","pt":1580650258578,"mc":[{"id":"1.168213440","rc":[{"batb":[[1,2.52,14.56],[2,1.01,15.51]],"ltp":2.86,"tv":21.08,"id":10107989},{"batb":[[0,1.56,33.05],[1,1.52,36.9],[2,1.01,15.51]],"ltp":0.0,"tv":0.0,"id":8444034}]}]}
{"op":"mcm","clk":"1003462738","pt":1580650271611,"mc":[{"id":"1.168213440","rc":[{"batb":[[0,2.52,14.56],[1,1.01,15.51],[2,1.01,0]],"ltp":2.86,"tv":21.08,"id":10107989},{"batb":[[0,1.52,36.9],[1,1.01,15.51],[2,1.01,0]],"ltp":0.0,"tv":0.0,"id":8444034}]}]}
{"op":"mcm","clk":"1003464254","pt":1580650280693,"mc":[{"id":"1.168213440","rc":[{"batb":[[1,2.46,15.66],[2,1.01,15.51]],"ltp":2.86,"tv":21.08,"id":10107989},{"batb":[[0,1.59,31.39],[1,1.54,34.78],[2,1.52,36.9]],"ltp":0.0,"tv":0.0,"id":8444034}]}]}
{"op":"mcm","clk":"1003464306","pt":1580650281016,"mc":[{"id":"1.168213440","rc":[{"batb":[[2,1.01,15.51]],"ltp":0.0,"tv":0.0,"id":8444034}]}]}
{"op":"mcm","clk":"1003466694","pt":1580650295411,"mc":[{"id":"1.168213440","rc":[{"batb":[[0,2.46,15.66],[1,1.01,15.51],[2,1.01,0]],"ltp":2.86,"tv":21.08,"id":10107989},{"batb":[[0,1.54,34.78],[1,1.01,15.51],[2,1.01,0]],"ltp":0.0,"tv":0.0,"id":8444034}]}]}
{"op":"mcm","clk":"1003468183","pt":1580650305140,"mc":[{"id":"1.168213440","rc":[{"batb":[[1,2.32,18.1],[2,1.01,15.51]],"ltp":2.86,"tv":21.08,"id":10107989},{"batb":[[0,1.61,29.51],[1,1.58,31.55],[2,1.01,15.51]],"ltp":0.0,"tv":0.0,"id":8444034}]}]}
{"op":"mcm","clk":"1003471760","pt":1580650327696,"mc":[{"id":"1.168213440","rc":[{"batb":[[1,2.34,17.94],[2,2.32,18.1]],"ltp":2.86,"tv":21.08,"id":10107989}]}]}
{"op":"mcm","clk":"1003471903","pt":1580650328560,"mc":[{"id":"1.168213440","rc":[{"batb":[[2,1.01,15.51]],"ltp":2.86,"tv":21.08,"id":10107989}]}]}
{"op":"mcm","clk":"1003472697","pt":1580650333697,"mc":[{"id":"1.168213440","rc":[{"batb":[[0,2.46,15.42],[1,2.34,17.62]],"ltp":2.86,"tv":21.08,"id":10107989}]}]}
{"op":"mcm","clk":"1003476582","pt":1580650358540,"mc":[{"id":"1.168213440","rc":[{"batb":[[0,2.48,15.26],[1,2.36,17.39]],"ltp":2.86,"tv":21.08,"id":10107989},{"batb":[[0,1.6,30.21]],"ltp":0.0,"tv":0.0,"id":8444034}]}]}
{"op":"mcm","clk":"1003481590","pt":1580650390191,"mc":[{"id":"1.168213440","rc":[{"batb":[[0,2.36,17.39],[1,1.01,15.51],[2,1.01,0]],"ltp":2.86,"tv":21.08,"id":10107989},{"batb":[[0,1.58,31.55],[1,1.01,15.51],[2,1.01,0]],"ltp":0.0,"tv":0.0,"id":8444034}]}]}
{"op":"mcm","clk":"1003482125","pt":1580650393381,"mc":[{"id":"1.168213440","rc":[{"batb":[[0,2.38,17.07]],"ltp":2.86,"tv":21.08,"id":10107989},{"batb":[[0,1.57,32.26]],"ltp":0.0,"tv":0.0,"id":8444034}]}]}
{"op":"mcm","clk":"1003484231","pt":1580650406286,"mc":[{"id":"1.168213440","rc":[{"batb":[[0,2.54,14.16],[1,2.42,16.21],[2,1.01,15.51]],"ltp":2.86,"tv":21.08,"id":10107989},{"batb":[[1,1.56,33.52],[2,1.01,15.51]],"ltp":0.0,"tv":0.0,"id":8444034}]}]}
{"op":"mcm","clk":"1003486803","pt":1580650420628,"mc":[{"id":"1.168213440","rc":[{"batb":[[0,2.42,16.21],[1,1.01,15.51],[2,1.01,0]],"ltp":2.86,"tv":21.08,"id":10107989},{"batb":[[0,1.56,33.52],[1,1.01,15.51],[2,1.01,0]],"ltp":0.0,"tv":0.0,"id":8444034}]}]}
{"op":"mcm","clk":"1003488131","pt":1580650427622,"mc":[{"id":"1.168213440","rc":[{"batb":[[0,2.6,13.53],[1,2.48,15.19],[2,1.01,15.51]],"ltp":2.86,"tv":21.08,"id":10107989},{"batb":[[1,1.54,35.17],[2,1.01,15.51]],"ltp":0.0,"tv":0.0,"id":8444034}]}]}
{"op":"mcm","clk":"1003490495","pt":1580650440327,"mc":[{"id":"1.168213440","rc":[{"batb":[[0,2.48,15.19],[1,1.01,15.51],[2,1.01,0]],"ltp":2.86,"tv":21.08,"id":10107989},{"batb":[[0,1.54,35.17],[1,1.01,15.51],[2,1.01,0]],"ltp":0.0,"tv":0.0,"id":8444034}]}]}
{"op":"mcm","clk":"1003492443","pt":1580650451552,"mc":[{"id":"1.168213440","rc":[{"batb":[[0,2.66,12.75],[1,2.52,14.56],[2,1.01,15.51]],"ltp":2.86,"tv":21.08,"id":10107989},{"batb":[[1,1.52,36.67],[2,1.01,15.51]],"ltp":0.0,"tv":0.0,"id":8444034}]}]}
{"op":"mcm","clk":"1003495235","pt":1580650467450,"mc":[{"id":"1.168213440","rc":[{"batb":[[0,2.52,14.56],[1,1.01,15.51],[2,1.01,0]],"ltp":2.86,"tv":21.08,"id":10107989},{"batb":[[0,1.52,36.67],[1,1.01,15.51],[2,1.01,0]],"ltp":0.0,"tv":0.0,"id":8444034}]}]}
{"op":"mcm","clk":"1003499271","pt":1580650489610,"mc":[{"id":"1.168213440","rc":[{"batb":[[1,2.42,16.37],[2,1.01,15.51]],"ltp":2.86,"tv":21.08,"id":10107989},{"batb":[[0,1.59,31.39],[1,1.56,33.13],[2,1.01,15.51]],"ltp":0.0,"tv":0.0,"id":8444034}]}]}
{"op":"mcm","clk":"1003502668","pt":1580650507424,"mc":[{"id":"1.168213440","rc":[{"batb":[[0,2.42,16.37],[1,1.01,15.51],[2,1.01,0]],"ltp":2.86,"tv":21.08,"id":10107989},{"batb":[[0,1.56,33.13],[1,1.01,15.51],[2,1.01,0]],"ltp":0.0,"tv":0.0,"id":8444034}]}]}
{"op":"mcm","clk":"1003505401","pt":1580650520684,"mc":[{"id":"1.168213440","rc":[{"batb":[[0,2.58,13.69],[1,2.42,16.37],[2,2.4,16.84]],"ltp":2.86,"tv":21.08,"id":10107989},{"batb":[[1,1.44,45.48],[2,1.01,15.51]],"ltp":0.0,"tv":0.0,"id":8444034}]}]}
{"op":"mcm","clk":"1003505444","pt":1580650520898,"mc":[{"id":"1.168213440","rc":[{"batb":[[1,2.4,16.84],[2,1.01,15.51]],"ltp":2.86,"tv":21.08,"id":10107989}]}]}
{"op":"mcm","clk":"1003505778","pt":1580650522482,"mc":[{"id":"1.168213440","rc":[{"batl":[[0,3.3,191.92]],"ltp":2.86,"tv":21.08,"id":10107989},{"batl":[[0,2.16,342.82]],"ltp":0.0,"tv":0.0,"id":8444034}]}]}
{"op":"mcm","clk":"1003510218","pt":1580650544712,"mc":[{"id":"1.168213440","marketDefinition":{"bspMarket":false,"turnInPlayEnabled":true,"persistenceEnabled":true,"marketBaseRate":5.0,"eventId":"29681204","eventTypeId":"2","numberOfWinners":1,"bettingType":"ODDS","marketType":"SET_WINNER","marketTime":"2020-02-02T12:47:00.000Z","suspendTime":"2020-02-02T12:47:00.000Z","bspReconciled":false,"complete":true,"inPlay":true,"crossMatching":true,"runnersVoidable":false,"numberOfActiveRunners":2,"betDelay":3,"status":"OPEN","runners":[{"status":"ACTIVE","sortPriority":1,"id":8444034,"name":"Golubev/Nedovyesov"},{"status":"ACTIVE","sortPriority":2,"id":10107989,"name":"Sabanov/Sabanov"}],"regulators":["MR_INT"],"countryCode":"FR","discountAllowed":true,"timezone":"UTC","openDate":"2020-02-02T12:47:00.000Z","version":3148851633,"name":"Set 2 Winner","eventName":"Golubev/Nedovyesov v Sabanov/Sabanov"}}]}
{"op":"mcm","clk":"1003511169","pt":1580650549740,"mc":[{"id":"1.168213440","rc":[{"batb":[[1,2.38,16.92]],"ltp":2.86,"tv":21.08,"id":10107989},{"batb":[[0,1.57,32.97],[1,1.44,45.24]],"ltp":0.0,"tv":0.0,"id":8444034}]}]}
{"op":"mcm","clk":"1003515393","pt":1580650571464,"mc":[{"id":"1.168213440","rc":[{"batb":[[0,2.56,13.85]],"ltp":2.86,"tv":21.08,"id":10107989},{"batb":[[0,1.57,32.73],[1,1.44,45.01]],"ltp":0.0,"tv":0.0,"id":8444034}]}]}
{"op":"mcm","clk":"1003523274","pt":1580650614513,"mc":[{"id":"1.168213440","rc":[{"batb":[[0,2.38,16.92],[1,1.01,15.51],[2,1.01,0]],"ltp":2.86,"tv":21.08,"id":10107989},{"batb":[[0,1.44,45.01],[1,1.01,15.51],[2,1.01,0]],"ltp":0.0,"tv":0.0,"id":8444034}]}]}
{"op":"mcm","clk":"1003524706","pt":1580650622213,"mc":[{"id":"1.168213440","rc":[{"batb":[[1,2.24,19.91],[2,1.01,15.51]],"ltp":2.86,"tv":21.08,"id":10107989},{"batb":[[0,1.65,27.46],[1,1.53,36.04],[2,1.01,15.51]],"ltp":0.0,"tv":0.0,"id":8444034}]}]}
{"op":"mcm","clk":"1003526604","pt":1580650632151,"mc":[{"id":"1.168213440","rc":[{"batb":[[0,2.24,19.91],[1,1.01,15.51],[2,1.01,0]],"ltp":2.86,"tv":21.08,"id":10107989},{"batb":[[0,1.53,36.04],[1,1.01,15.51],[2,1.01,0]],"ltp":0.0,"tv":0.0,"id":8444034}]}]}
{"op":"mcm","clk":"1003528707","pt":1580650643512,"mc":[{"id":"1.168213440","rc":[{"batb":[[1,2.16,22.5],[2,1.01,15.51]],"ltp":2.86,"tv":21.08,"id":10107989},{"batb":[[0,1.72,23.84],[1,1.62,29.11],[2,1.01,15.51]],"ltp":0.0,"tv":0.0,"id":8444034}]}]}
{"op":"mcm","clk":"1003529079","pt":1580650645612,"mc":[{"id":"1.168213440","rc":[{"batl":[[0,3,213.45]],"ltp":2.86,"tv":21.08,"id":10107989}]}]}
{"op":"mcm","clk":"1003531258","pt":1580650657724,"mc":[{"id":"1.168213440","rc":[{"batb":[[0,2.16,22.5],[1,1.01,15.51],[2,1.01,0]],"ltp":2.86,"tv":21.08,"id":10107989},{"batb":[[0,1.62,29.11],[1,1.01,15.51],[2,1.01,0]],"ltp":0.0,"tv":0.0,"id":8444034}]}]}
{"op":"mcm","clk":"1003532614","pt":1580650665256,"mc":[{"id":"1.168213440","rc":[{"batb":[[1,2.1,24.55],[2,1.01,15.51]],"ltp":2.86,"tv":21.08,"id":10107989},{"batb":[[0,1.78,21.32],[1,1.71,24.47],[2,1.01,15.51]],"ltp":0.0,"tv":0.0,"id":8444034}]}]}
{"op":"mcm","clk":"1003534466","pt":1580650675524,"mc":[{"id":"1.168213440","rc":[{"batb":[[0,2.1,24.55],[1,1.01,15.51],[2,1.01,0]],"ltp":2.86,"tv":21.08,"id":10107989},{"batb":[[0,1.71,24.47],[1,1.01,15.51],[2,1.01,0]],"ltp":0.0,"tv":0.0,"id":8444034}]}]}
{"op":"mcm","clk":"1003538398","pt":1580650697670,"mc":[{"id":"1.168213440","rc":[{"batb":[[0,2.28,19.36],[1,2.16,22.03],[2,1.01,15.51]],"ltp":2.86,"tv":21.08,"id":10107989},{"batb":[[1,1.6,30.37],[2,1.01,15.51]],"ltp":0.0,"tv":0.0,"id":8444034}]}]}
{"op":"mcm","clk":"1003541464","pt":1580650714879,"mc":[{"id":"1.168213440","rc":[{"batb":[[0,2.16,22.03],[1,1.01,15.51],[2,1.01,0]],"ltp":2.86,"tv":21.08,"id":10107989},{"batb":[[0,1.6,30.37],[1,1.01,15.51],[2,1.01,0]],"ltp":0.0,"tv":0.0,"id":8444034}]}]}
{"op":"mcm","clk":"1003544424","pt":1580650731513,"mc":[{"id":"1.168213440","rc":[{"batb":[[1,1.93,15.66],[2,1.01,15.51]],"ltp":2.86,"tv":21.08,"id":10107989},{"batb":[[0,1.77,21.72],[1,1.69,25.18],[2,1.6,30.37]],"ltp":0.0,"tv":0.0,"id":8444034}]}]}
{"op":"mcm","clk":"1003544473","pt":1580650731801,"mc":[{"id":"1.168213440","rc":[{"batb":[[2,1.01,15.51]],"ltp":0.0,"tv":0.0,"id":8444034}]}]}
{"op":"mcm","clk":"1003552334","pt":1580650774743,"mc":[{"id":"1.168213440","rc":[{"batb":[[0,1.93,15.66],[1,1.01,15.51],[2,1.01,0]],"ltp":2.86,"tv":21.08,"id":10107989},{"batb":[[0,1.69,25.18],[1,1.01,15.51],[2,1.01,0]],"ltp":0.0,"tv":0.0,"id":8444034}]}]}
{"op":"mcm","clk":"1003554087","pt":1580650785362,"mc":[{"id":"1.168213440","rc":[{"batb":[[1,1.67,25.49],[2,1.01,15.51]],"ltp":2.86,"tv":21.08,"id":10107989},{"batb":[[0,1.97,15.5],[1,1.84,19.36],[2,1.01,15.51]],"ltp":0.0,"tv":0.0,"id":8444034}]}]}
{"op":"mcm","clk":"1003554385","pt":1580650787280,"mc":[{"id":"1.168213440","rc":[{"batl":[[0,2.6,257.57]],"ltp":2.86,"tv":21.08,"id":10107989},{"batl":[[0,2.6,257.57]],"ltp":0.0,"tv":0.0,"id":8444034}]}]}
{"op":"mcm","clk":"1003557415","pt":1580650805091,"mc":[{"id":"1.168213440","rc":[{"batb":[[0,1.67,25.49],[1,1.01,15.51],[2,1.01,0]],"ltp":2.86,"tv":21.08,"id":10107989},{"batb":[[0,1.84,19.36],[1,1.01,15.51],[2,1.01,0]],"ltp":0.0,"tv":0.0,"id":8444034}]}]}
{"op":"mcm","clk":"1003558963","pt":1580650813507,"mc":[{"id":"1.168213440","rc":[{"batl":[[0,2.42,286.52]],"ltp":2.86,"tv":21.08,"id":10107989}]}]}
{"op":"mcm","clk":"1003561751","pt":1580650828543,"mc":[{"id":"1.168213440","rc":[{"batb":[[1,1.44,43.98],[2,1.01,15.51]],"ltp":2.86,"tv":21.08,"id":10107989},{"batb":[[0,2.34,18.57],[1,2.1,24.94],[2,1.01,15.51]],"ltp":0.0,"tv":0.0,"id":8444034}]}]}
{"op":"mcm","clk":"1003561949","pt":1580650829651,"mc":[{"id":"1.168213440","rc":[{"batl":[[0,2.22,329.01]],"ltp":2.86,"tv":21.08,"id":10107989},{"batl":[[0,3.15,200.42]],"ltp":0.0,"tv":0.0,"id":8444034}]}]}
{"op":"mcm","clk":"1003565773","pt":1580650850910,"mc":[{"id":"1.168213440","rc":[{"batb":[[0,1.44,43.98],[1,1.01,15.51],[2,1.01,0]],"ltp":2.86,"tv":21.08,"id":10107989},{"batb":[[0,2.1,24.94],[1,1.01,15.51],[2,1.01,0]],"ltp":0.0,"tv":0.0,"id":8444034}]}]}
{"op":"mcm","clk":"1003567220","pt":1580650859519,"mc":[{"id":"1.168213440","rc":[{"batb":[[0,1.81,19.36],[1,1.52,35.41],[2,1.44,43.98]],"ltp":2.86,"tv":21.08,"id":10107989},{"batb":[[1,1.92,16.92],[2,1.01,15.51]],"ltp":0.0,"tv":0.0,"id":8444034}]}]}
{"op":"mcm","clk":"1003567278","pt":1580650859864,"mc":[{"id":"1.168213440","rc":[{"batb":[[2,1.01,15.51]],"ltp":2.86,"tv":21.08,"id":10107989}]}]}
{"op":"mcm","clk":"1003567635","pt":1580650861846,"mc":[{"id":"1.168213440","rc":[{"batl":[[0,2.82,231.28]],"ltp":0.0,"tv":0.0,"id":8444034}]}]}
{"op":"mcm","clk":"1003568582","pt":1580650866952,"mc":[{"id":"1.168213440","rc":[{"trd":[[2.1,3.54]],"batb":[[0,2.1,23.17]],"ltp":2.1,"tv":3.53,"id":8444034}],"tv":24.62}]}
{"op":"mcm","clk":"1003570756","pt":1580650878639,"mc":[{"id":"1.168213440","rc":[{"batb":[[0,1.52,35.41],[1,1.01,15.51],[2,1.01,0]],"ltp":2.86,"tv":21.08,"id":10107989},{"batb":[[0,1.92,16.92],[1,1.01,15.51],[2,1.01,0]],"ltp":2.1,"tv":3.53,"id":8444034}]}]}
{"op":"mcm","clk":"1003571285","pt":1580650881612,"mc":[{"id":"1.168213440","rc":[{"batb":[[1,1.91,16.92],[2,1.01,15.51]],"ltp":2.1,"tv":3.53,"id":8444034}]}]}
{"op":"mcm","clk":"1003571341","pt":1580650881899,"mc":[{"id":"1.168213440","rc":[{"batb":[[0,1.91,16.92],[1,1.01,15.51],[2,1.01,0]],"ltp":2.1,"tv":3.53,"id":8444034}]}]}
{"op":"mcm","clk":"1003572841","pt":1580650889685,"mc":[{"id":"1.168213440","rc":[{"batb":[[1,1.32,65.54],[2,1.01,15.51]],"ltp":2.86,"tv":21.08,"id":10107989},{"batb":[[0,2.7,12.67],[1,2.38,17.78],[2,1.01,15.51]],"ltp":2.1,"tv":3.53,"id":8444034}]}]}
{"op":"mcm","clk":"1003573128","pt":1580650891182,"mc":[{"id":"1.168213440","rc":[{"batl":[[0,1.95,409.86]],"ltp":2.86,"tv":21.08,"id":10107989},{"batl":[[0,3.9,158.24]],"ltp":2.1,"tv":3.53,"id":8444034}]}]}
{"op":"mcm","clk":"1003576817","pt":1580650912514,"mc":[{"id":"1.168213440","rc":[{"batb":[[0,1.32,65.54],[1,1.01,15.51],[2,1.01,0]],"ltp":2.86,"tv":21.08,"id":10107989},{"batb":[[0,2.38,17.78],[1,1.01,15.51],[2,1.01,0]],"ltp":2.1,"tv":3.53,"id":8444034}]}]}
{"op":"mcm","clk":"1003581018","pt":1580650933548,"mc":[{"id":"1.168213440","rc":[{"batb":[[1,1.27,81.83],[2,1.01,15.51]],"ltp":2.86,"tv":21.08,"id":10107989},{"batb":[[0,3.65,14.48],[1,2.98,24.16],[2,1.01,15.51]],"ltp":2.1,"tv":3.53,"id":8444034}]}]}
{"op":"mcm","clk":"1003581398","pt":1580650935553,"mc":[{"id":"1.168213440","rc":[{"batl":[[0,1.71,542.06]],"ltp":2.86,"tv":21.08,"id":10107989},{"batl":[[0,5.5,115.06]],"ltp":2.1,"tv":3.53,"id":8444034}]}]}
{"op":"mcm","clk":"1003586584","pt":1580650961464,"mc":[{"id":"1.168213440","rc":[{"batb":[[0,1.27,80.96],[1,1.01,15.51],[2,1.01,0]],"ltp":2.86,"tv":21.08,"id":10107989},{"batb":[[0,2.98,24.16],[1,1.01,15.51],[2,1.01,0]],"ltp":2.1,"tv":3.53,"id":8444034}]}]}
{"op":"mcm","clk":"1003588184","pt":1580650969441,"mc":[{"id":"1.168213440","rc":[{"batb":[[0,1.44,43.98],[1,1.36,58.15],[2,1.01,15.51]],"ltp":2.86,"tv":21.08,"id":10107989},{"batb":[[1,2.42,17.07],[2,1.01,15.51]],"ltp":2.1,"tv":3.53,"id":8444034}]}]}
{"op":"mcm","clk":"1003588630","pt":1580650971839,"mc":[{"id":"1.168213440","rc":[{"batl":[[0,4.6,136.05]],"ltp":2.1,"tv":3.53,"id":8444034}]}]}
{"op":"mcm","clk":"1003591649","pt":1580650987639,"mc":[{"id":"1.168213440","rc":[{"batb":[[0,1.36,58.15],[1,1.01,15.51],[2,1.01,0]],"ltp":2.86,"tv":21.08,"id":10107989},{"batb":[[0,2.42,17.07],[1,1.01,15.51],[2,1.01,0]],"ltp":2.1,"tv":3.53,"id":8444034}]}]}
{"op":"mcm","clk":"1003594605","pt":1580651002414,"mc":[{"id":"1.168213440","rc":[{"batb":[[0,1.63,27.38],[1,1.51,36.74],[2,1.01,15.51]],"ltp":2.86,"tv":21.08,"id":10107989},{"batb":[[1,2,28.88],[2,1.01,15.51]],"ltp":2.1,"tv":3.53,"id":8444034}]}]}
{"op":"mcm","clk":"1003594967","pt":1580651004216,"mc":[{"id":"1.168213440","rc":[{"batl":[[0,2.1,363.31]],"ltp":2.86,"tv":21.08,"id":10107989},{"batl":[[0,3.45,180.4]],"ltp":2.1,"tv":3.53,"id":8444034}]}]}
{"op":"mcm","clk":"1003598084","pt":1580651019844,"mc":[{"id":"1.168213440","rc":[{"batb":[[0,1.51,36.74],[1,1.01,15.51],[2,1.01,0]],"ltp":2.86,"tv":21.08,"id":10107989},{"batb":[[0,2,28.88],[1,1.01,15.51],[2,1.01,0]],"ltp":2.1,"tv":3.53,"id":8444034}]}]}
{"op":"mcm","clk":"1003600092","pt":1580651030356,"mc":[{"id":"1.168213440","rc":[{"batl":[[0,3.15,200.42]],"ltp":2.1,"tv":3.53,"id":8444034}]}]}
{"op":"mcm","clk":"1003604185","pt":1580651050616,"mc":[{"id":"1.168213440","rc":[{"batb":[[0,1.89,16.84],[1,1.77,20.85],[2,1.01,15.51]],"ltp":2.86,"tv":21.08,"id":10107989},{"batb":[[1,1.8,20.38],[2,1.01,15.51]],"ltp":2.1,"tv":3.53,"id":8444034}]}]}
{"op":"mcm","clk":"1003604562","pt":1580651052615,"mc":[{"id":"1.168213440","rc":[{"batl":[[0,2.5,274.54]],"ltp":2.86,"tv":21.08,"id":10107989},{"batl":[[0,2.72,241.55]],"ltp":2.1,"tv":3.53,"id":8444034}]}]}
{"op":"mcm","clk":"1003607460","pt":1580651067334,"mc":[{"id":"1.168213440","rc":[{"batb":[[0,1.77,20.85],[1,1.01,15.51],[2,1.01,0]],"ltp":2.86,"tv":21.08,"id":10107989},{"batb":[[0,1.8,20.38],[1,1.01,15.51],[2,1.01,0]],"ltp":2.1,"tv":3.53,"id":8444034}]}]}
{"op":"mcm","clk":"1003609967","pt":1580651080347,"mc":[{"id":"1.168213440","rc":[{"batb":[[1,1.62,28.4],[2,1.01,15.51]],"ltp":2.86,"tv":21.08,"id":10107989},{"batb":[[0,2.16,23.05],[1,1.83,19.36],[2,1.01,15.51]],"ltp":2.1,"tv":3.53,"id":8444034}]}]}
{"op":"mcm","clk":"1003610225","pt":1580651081749,"mc":[{"id":"1.168213440","rc":[{"batl":[[0,2.36,299.17]],"ltp":2.86,"tv":21.08,"id":10107989}]}]}
{"op":"mcm","clk":"1003613307","pt":1580651097461,"mc":[{"id":"1.168213440","rc":[{"batb":[[0,1.62,28.4],[1,1.01,15.51],[2,1.01,0]],"ltp":2.86,"tv":21.08,"id":10107989},{"batb":[[0,1.83,19.36],[1,1.01,15.51],[2,1.01,0]],"ltp":2.1,"tv":3.53,"id":8444034}]}]}
{"op":"mcm","clk":"1003613761","pt":1580651099670,"mc":[{"id":"1.168213440","rc":[{"batb":[[0,1.87,2.27],[1,1.62,28.4],[2,1.01,15.51]],"ltp":2.86,"tv":21.08,"id":10107989}]}]}
{"op":"mcm","clk":"1003615016","pt":1580651105465,"mc":[{"id":"1.168213440","rc":[{"batb":[[0,1.62,28.4],[1,1.01,15.51],[2,1.01,0]],"ltp":2.86,"tv":21.08,"id":10107989}]}]}
{"op":"mcm","clk":"1003615623","pt":1580651108165,"mc":[{"id":"1.168213440","rc":[{"batb":[[0,2.08,24.86],[1,1.84,18.18],[2,1.01,15.51]],"ltp":2.86,"tv":21.08,"id":10107989},{"batb":[[1,1.72,23.68],[2,1.01,15.51]],"ltp":2.1,"tv":3.53,"id":8444034}]}]}
{"op":"mcm","clk":"1003616130","pt":1580651110478,"mc":[{"id":"1.168213440","rc":[{"batl":[[0,2.82,231.28]],"ltp":2.86,"tv":21.08,"id":10107989},{"batl":[[0,2.42,286.52]],"ltp":2.1,"tv":3.53,"id":8444034}]}]}
{"op":"mcm","clk":"1003632701","pt":1580651195732,"mc":[{"id":"1.168213440","rc":[{"batb":[[0,1.84,18.18],[1,1.01,15.51],[2,1.01,0]],"ltp":2.86,"tv":21.08,"id":10107989},{"batb":[[0,1.72,23.68],[1,1.01,15.51],[2,1.01,0]],"ltp":2.1,"tv":3.53,"id":8444034}]}]}
{"op":"mcm","clk":"1003634160","pt":1580651202545,"mc":[{"id":"1.168213440","rc":[{"batb":[[0,2.24,20.06],[1,2,28.17],[2,1.84,18.18]],"ltp":2.86,"tv":21.08,"id":10107989},{"batb":[[1,1.64,27.62],[2,1.01,15.51]],"ltp":2.1,"tv":3.53,"id":8444034}]}]}
{"op":"mcm","clk":"1003634345","pt":1580651203555,"mc":[{"id":"1.168213440","rc":[{"batb":[[2,1.01,15.51]],"ltp":2.86,"tv":21.08,"id":10107989}]}]}
{"op":"mcm","clk":"1003634406","pt":1580651203826,"mc":[{"id":"1.168213440","rc":[{"batl":[[0,2.3,309.75]],"ltp":2.1,"tv":3.53,"id":8444034}]}]}
{"op":"mcm","clk":"1003636931","pt":1580651217135,"mc":[{"id":"1.168213440","rc":[{"batb":[[0,2,28.17],[1,1.01,15.51],[2,1.01,0]],"ltp":2.86,"tv":21.08,"id":10107989},{"batb":[[0,1.64,27.62],[1,1.01,15.51],[2,1.01,0]],"ltp":2.1,"tv":3.53,"id":8444034}]}]}
{"op":"mcm","clk":"1003638815","pt":1580651226455,"mc":[{"id":"1.168213440","rc":[{"batb":[[0,2.38,16.92],[1,2.18,21.72],[2,2,28.17]],"ltp":2.86,"tv":21.08,"id":10107989},{"batb":[[1,1.59,31.08],[2,1.01,15.51]],"ltp":2.1,"tv":3.53,"id":8444034}]}]}
{"op":"mcm","clk":"1003638875","pt":1580651226753,"mc":[{"id":"1.168213440","rc":[{"batb":[[2,1.01,15.51]],"ltp":2.86,"tv":21.08,"id":10107989}]}]}
{"op":"mcm","clk":"1003641605","pt":1580651240773,"mc":[{"id":"1.168213440","rc":[{"batb":[[0,2.18,21.72],[1,1.01,15.51],[2,1.01,0]],"ltp":2.86,"tv":21.08,"id":10107989},{"batb":[[0,1.59,31.08],[1,1.01,15.51],[2,1.01,0]],"ltp":2.1,"tv":3.53,"id":8444034}]}]}
{"op":"mcm","clk":"1003643324","pt":1580651249497,"mc":[{"id":"1.168213440","rc":[{"batb":[[0,2.5,14.71],[1,2.36,17.39],[2,1.01,15.51]],"ltp":2.86,"tv":21.08,"id":10107989},{"batb":[[1,1.55,33.68],[2,1.01,15.51]],"ltp":2.1,"tv":3.53,"id":8444034}]}]}
{"op":"mcm","clk":"1003643437","pt":1580651250155,"mc":[{"id":"1.168213440","rc":[{"batl":[[0,3.15,200.42]],"ltp":2.86,"tv":21.08,"id":10107989}]}]}
{"op":"mcm","clk":"1003645643","pt":1580651262711,"mc":[{"id":"1.168213440","rc":[{"batb":[[0,2.36,17.39],[1,1.01,15.51],[2,1.01,0]],"ltp":2.86,"tv":21.08,"id":10107989},{"batb":[[0,1.55,33.68],[1,1.01,15.51],[2,1.01,0]],"ltp":2.1,"tv":3.53,"id":8444034}]}]}
{"op":"mcm","clk":"1003647620","pt":1580651273718,"mc":[{"id":"1.168213440","rc":[{"batb":[[0,2.6,13.45],[1,2.36,17.39],[2,1.01,15.51]],"ltp":2.86,"tv":21.08,"id":10107989},{"batb":[[1,1.42,47.92],[2,1.01,15.51]],"ltp":2.1,"tv":3.53,"id":8444034}]}]}
{"op":"mcm","clk":"1003651042","pt":1580651293253,"mc":[{"id":"1.168213440","rc":[{"batb":[[0,2.36,17.39],[1,1.01,15.51],[2,1.01,0]],"ltp":2.86,"tv":21.08,"id":10107989},{"batb":[[0,1.42,47.92],[1,1.01,15.51],[2,1.01,0]],"ltp":2.1,"tv":3.53,"id":8444034}]}]}
{"op":"mcm","clk":"1003652456","pt":1580651301175,"mc":[{"id":"1.168213440","rc":[{"batb":[[1,2.2,21.32],[2,1.01,15.51]],"ltp":2.86,"tv":21.08,"id":10107989},{"batb":[[0,1.66,26.91],[1,1.52,36.27],[2,1.01,15.51]],"ltp":2.1,"tv":3.53,"id":8444034}]}]}
{"op":"mcm","clk":"1003652921","pt":1580651303668,"mc":[{"id":"1.168213440","rc":[{"batl":[[0,2.92,221.26]],"ltp":2.86,"tv":21.08,"id":10107989}]}]}
{"op":"mcm","clk":"1003654380","pt":1580651311689,"mc":[{"id":"1.168213440","rc":[{"batb":[[0,2.2,21.32],[1,1.01,15.51],[2,1.01,0]],"ltp":2.86,"tv":21.08,"id":10107989},{"batb":[[0,1.52,36.27],[1,1.01,15.51],[2,1.01,0]],"ltp":2.1,"tv":3.53,"id":8444034}]}]}
{"op":"mcm","clk":"1003659112","pt":1580651335748,"mc":[{"id":"1.168213440","rc":[{"trd":[[1.52,40]],"batb":[[0,1.52,16.27]],"ltp":1.52,"tv":43.53,"id":8444034}],"tv":64.62}]}
{"op":"mcm","clk":"1003659686","pt":1580651338537,"mc":[{"id":"1.168213440","rc":[{"batb":[[1,2.08,25.02],[2,1.01,15.51]],"ltp":2.86,"tv":21.08,"id":10107989},{"batb":[[0,1.75,22.35],[1,1.64,27.93],[2,1.01,15.51]],"ltp":1.52,"tv":43.53,"id":8444034}]}]}
{"op":"mcm","clk":"1003662649","pt":1580651353024,"mc":[{"id":"1.168213440","rc":[{"batb":[[0,2.08,25.02],[1,1.01,15.51],[2,1.01,0]],"ltp":2.86,"tv":21.08,"id":10107989},{"batb":[[0,1.64,27.93],[1,1.01,15.51],[2,1.01,0]],"ltp":1.52,"tv":43.53,"id":8444034}]}]}
{"op":"mcm","clk":"1003663267","pt":1580651356239,"mc":[{"id":"1.168213440","rc":[{"batb":[[0,2.1,24.63]],"ltp":2.86,"tv":21.08,"id":10107989},{"batb":[[0,1.62,28.33]],"ltp":1.52,"tv":43.53,"id":8444034}]}]}
{"op":"mcm","clk":"1003664232","pt":1580651361054,"mc":[{"id":"1.168213440","rc":[{"batb":[[0,2.42,16.44],[1,2.2,21.17],[2,1.01,15.51]],"ltp":2.86,"tv":21.08,"id":10107989},{"batb":[[1,1.47,41.15],[2,1.01,15.51]],"ltp":1.52,"tv":43.53,"id":8444034}]}]}
{"op":"mcm","clk":"1003666411","pt":1580651372652,"mc":[{"id":"1.168213440","rc":[{"batb":[[0,2.2,21.17],[1,1.01,15.51],[2,1.01,0]],"ltp":2.86,"tv":21.08,"id":10107989},{"batb":[[0,1.47,41.15],[1,1.01,15.51],[2,1.01,0]],"ltp":1.52,"tv":43.53,"id":8444034}]}]}
{"op":"mcm","clk":"1003666760","pt":1580651374447,"mc":[{"id":"1.168213440","rc":[{"batl":[[1,1000,3.04]],"ltp":1.52,"tv":43.53,"id":8444034}]}]}
{"op":"mcm","clk":"1003666951","pt":1580651375480,"mc":[{"id":"1.168213440","rc":[{"batl":[[1,1000,0]],"ltp":1.52,"tv":43.53,"id":8444034}]}]}
{"op":"mcm","clk":"1003667537","pt":1580651378587,"mc":[{"id":"1.168213440","rc":[{"batl":[[0,2.3,309.76]],"ltp":1.52,"tv":43.53,"id":8444034}]}]}
{"op":"mcm","clk":"1003668297","pt":1580651382573,"mc":[{"id":"1.168213440","rc":[{"batl":[[0,1.62,0.02]],"ltp":1.52,"tv":43.53,"id":8444034}]}]}
{"op":"mcm","clk":"1003668463","pt":1580651383534,"mc":[{"id":"1.168213440","rc":[{"batb":[[0,2.86,10.54],[1,2.42,16.37],[2,1.01,15.51]],"ltp":2.86,"tv":21.08,"id":10107989},{"batb":[[1,1.29,74.98],[2,1.01,15.51]],"ltp":1.52,"tv":43.53,"id":8444034}]}]}
{"op":"mcm","clk":"1003669042","pt":1580651386471,"mc":[{"id":"1.168213440","rc":[{"batl":[[0,3.45,180.4]],"ltp":2.86,"tv":21.08,"id":10107989},{"batl":[[0,2.1,363.32]],"ltp":1.52,"tv":43.53,"id":8444034}]}]}
{"op":"mcm","clk":"1003671928","pt":1580651401478,"mc":[{"id":"1.168213440","rc":[{"batb":[[0,2.42,16.37],[1,1.01,15.51],[2,1.01,0]],"ltp":2.86,"tv":21.08,"id":10107989},{"batb":[[0,1.29,74.98],[1,1.01,15.51],[2,1.01,0]],"ltp":1.52,"tv":43.53,"id":8444034}]}]}
{"op":"mcm","clk":"1003672430","pt":1580651403827,"mc":[{"id":"1.168213440","rc":[{"batl":[[0,2.86,10],[1,3.45,180.4]],"ltp":2.86,"tv":21.08,"id":10107989}]}]}
{"op":"mcm","clk":"1003673376","pt":1580651408275,"mc":[{"id":"1.168213440","rc":[{"batl":[[1,3.45,0]],"ltp":2.86,"tv":21.08,"id":10107989},{"batl":[[0,1.62,0.02]],"ltp":1.52,"tv":43.53,"id":8444034}]}]}
{"op":"mcm","clk":"1003673741","pt":1580651409946,"mc":[{"id":"1.168213440","rc":[{"batb":[[1,2.14,22.82],[2,1.01,15.51]],"ltp":2.86,"tv":21.08,"id":10107989},{"trd":[[1.62,0.03]],"batb":[[0,1.62,28.39],[1,1.43,46.26],[2,1.01,15.51]],"ltp":1.62,"tv":43.56,"id":8444034}],"tv":64.65}]}
{"op":"mcm","clk":"1003674244","pt":1580651412565,"mc":[{"id":"1.168213440","rc":[{"batl":[[0,3,213.45]],"ltp":2.86,"tv":21.08,"id":10107989},{"batl":[[0,2.3,309.75]],"ltp":1.62,"tv":43.56,"id":8444034}]}]}
{"op":"mcm","clk":"1003675196","pt":1580651417175,"mc":[{"id":"1.168213440","rc":[{"trd":[[2.42,20]],"batb":[[0,2.42,6.37]],"ltp":2.42,"tv":41.08,"id":10107989}],"tv":84.65}]}
{"op":"mcm","clk":"1003676426","pt":1580651423369,"mc":[{"id":"1.168213440","rc":[{"batb":[[0,2.14,22.82],[1,1.01,15.51],[2,1.01,0]],"ltp":2.42,"tv":41.08,"id":10107989},{"batb":[[0,1.43,46.26],[1,1.01,15.51],[2,1.01,0]],"ltp":1.62,"tv":43.56,"id":8444034}]}]}
{"op":"mcm","clk":"1003677036","pt":1580651426491,"mc":[{"id":"1.168213440","rc":[{"batb":[[0,1.44,45.79]],"ltp":1.62,"tv":43.56,"id":8444034}]}]}
{"op":"mcm","clk":"1003677869","pt":1580651430710,"mc":[{"id":"1.168213440","rc":[{"batb":[[1,1.01,15.52]],"batl":[[0,2.16,342.82]],"ltp":1.62,"tv":43.56,"id":8444034}]}]}
{"op":"mcm","clk":"1003677891","pt":1580651430778,"mc":[{"id":"1.168213440","rc":[{"batb":[[1,1.01,15.51]],"ltp":1.62,"tv":43.56,"id":8444034}]}]}
{"op":"mcm","clk":"1003678503","pt":1580651433900,"mc":[{"id":"1.168213440","rc":[{"batb":[[0,1.44,45.81]],"ltp":1.62,"tv":43.56,"id":8444034}]}]}
{"op":"mcm","clk":"1003680305","pt":1580651442599,"mc":[{"id":"1.168213440","rc":[{"trd":[[2.62,0.01]],"batb":[[0,3,23.28],[1,2.2,21.09],[2,2.14,22.82]],"ltp":2.62,"tv":41.09,"id":10107989},{"trd":[[1.62,0.05]],"batb":[[0,1.44,45.79],[1,1.14,175.07],[2,1.01,15.51]],"ltp":1.62,"tv":43.58,"id":8444034}],"tv":84.67}]}
{"op":"mcm","clk":"1003680434","pt":1580651443253,"mc":[{"id":"1.168213440","rc":[{"batb":[[2,1.01,15.51]],"ltp":2.62,"tv":41.09,"id":10107989}]}]}
{"op":"mcm","clk":"1003680872","pt":1580651445473,"mc":[{"id":"1.168213440","rc":[{"batl":[[0,3.65,170.41]],"ltp":2.62,"tv":41.09,"id":10107989},{"batl":[[0,2.04,383.01]],"ltp":1.62,"tv":43.58,"id":8444034}]}]}
{"op":"mcm","clk":"1003684123","pt":1580651462507,"mc":[{"id":"1.168213440","rc":[{"batb":[[0,2.2,21.09],[1,1.01,15.51],[2,1.01,0]],"ltp":2.62,"tv":41.09,"id":10107989},{"batb":[[0,1.14,175.07],[1,1.01,15.51],[2,1.01,0]],"ltp":1.62,"tv":43.58,"id":8444034}]}]}
{"op":"mcm","clk":"1003686797","pt":1580651476730,"mc":[{"id":"1.168213440","rc":[{"batb":[[0,6.6,13.61],[1,4.9,13.69],[2,1.01,15.51]],"ltp":2.62,"tv":41.09,"id":10107989},{"batb":[[1,1.1,228.73],[2,1.01,15.51]],"ltp":1.62,"tv":43.58,"id":8444034}]}]}
{"op":"mcm","clk":"1003687146","pt":1580651478527,"mc":[{"id":"1.168213440","rc":[{"batl":[[0,10.5,72.32]],"ltp":2.62,"tv":41.09,"id":10107989},{"batl":[[0,1.48,784.94]],"ltp":1.62,"tv":43.58,"id":8444034}]}]}
{"op":"mcm","clk":"1003688277","pt":1580651484965,"mc":[{"id":"1.168213440","rc":[{"batb":[[0,1.13,176.09]],"ltp":1.62,"tv":43.58,"id":8444034}]}]}
{"op":"mcm","clk":"1003694286","pt":1580651518497,"mc":[{"id":"1.168213440","rc":[{"trd":[[6.6,0.68]],"batb":[[0,6.6,12.94]],"ltp":6.6,"tv":41.76,"id":10107989},{"trd":[[1.18,3.79]],"batb":[[0,1.13,175.7]],"ltp":1.18,"tv":47.36,"id":8444034}],"tv":89.13}]}
{"op":"mcm","clk":"1003695795","pt":1580651526760,"mc":[{"id":"1.168213440","rc":[{"batb":[[0,1.13,175.46]],"ltp":1.18,"tv":47.36,"id":8444034}]}]}
{"op":"mcm","clk":"1003697881","pt":1580651537684,"mc":[{"id":"1.168213440","rc":[{"batb":[[0,1.14,175.46],[1,1.13,175.46],[2,1.1,228.73]],"ltp":1.18,"tv":47.36,"id":8444034}]}]}
{"op":"mcm","clk":"1003698026","pt":1580651538480,"mc":[{"id":"1.168213440","rc":[{"batb":[[1,1.1,228.73],[2,1.01,15.51]],"ltp":1.18,"tv":47.36,"id":8444034}]}]}
{"op":"mcm","clk":"1003699787","pt":1580651548200,"mc":[{"id":"1.168213440","rc":[{"batb":[[0,4.9,13.69],[1,1.01,15.51],[2,1.01,0]],"ltp":6.6,"tv":41.76,"id":10107989},{"batb":[[0,1.1,228.73],[1,1.01,15.51],[2,1.01,0]],"ltp":1.18,"tv":47.36,"id":8444034}]}]}
{"op":"mcm","clk":"1003701509","pt":1580651558724,"mc":[{"id":"1.168213440","rc":[{"batb":[[0,8,8.73],[1,6,17.39],[2,4.9,13.69]],"ltp":6.6,"tv":41.76,"id":10107989},{"batb":[[1,1.08,294.51],[2,1.01,15.51]],"ltp":1.18,"tv":47.36,"id":8444034}]}]}
{"op":"mcm","clk":"1003701548","pt":1580651558901,"mc":[{"id":"1.168213440","rc":[{"batb":[[2,1.01,15.51]],"ltp":6.6,"tv":41.76,"id":10107989}]}]}
{"op":"mcm","clk":"1003701864","pt":1580651560701,"mc":[{"id":"1.168213440","rc":[{"batl":[[0,13.5,64.07]],"ltp":6.6,"tv":41.76,"id":10107989}]}]}
{"op":"mcm","clk":"1003704311","pt":1580651575036,"mc":[{"id":"1.168213440","rc":[{"batb":[[0,6,17.39],[1,1.01,15.51],[2,1.01,0]],"ltp":6.6,"tv":41.76,"id":10107989},{"batb":[[0,1.08,294.51],[1,1.01,15.51],[2,1.01,0]],"ltp":1.18,"tv":47.36,"id":8444034}]}]}
{"op":"mcm","clk":"1003706290","pt":1580651585455,"mc":[{"id":"1.168213440","rc":[{"batb":[[0,9.6,14.87],[1,7.6,9.99],[2,1.01,15.51]],"ltp":6.6,"tv":41.76,"id":10107989},{"batb":[[1,1.06,356.51],[2,1.01,15.51]],"ltp":1.18,"tv":47.36,"id":8444034}]}]}
{"op":"mcm","clk":"1003706726","pt":1580651587763,"mc":[{"id":"1.168213440","rc":[{"batl":[[0,15.5,59.64]],"ltp":6.6,"tv":41.76,"id":10107989},{"batl":[[0,1.41,902.65]],"ltp":1.18,"tv":47.36,"id":8444034}]}]}
{"op":"mcm","clk":"1003709180","pt":1580651601486,"mc":[{"id":"1.168213440","rc":[{"batb":[[0,7.6,9.99],[1,1.01,15.51],[2,1.01,0]],"ltp":6.6,"tv":41.76,"id":10107989},{"batb":[[0,1.06,356.51],[1,1.01,15.51],[2,1.01,0]],"ltp":1.18,"tv":47.36,"id":8444034}]}]}
{"op":"mcm","clk":"1003709506","pt":1580651603194,"mc":[{"id":"1.168213440","rc":[{"batl":[[0,1.08,43.94],[1,1.41,902.65]],"ltp":1.18,"tv":47.36,"id":8444034}]}]}
{"op":"mcm","clk":"1003711750","pt":1580651615522,"mc":[{"id":"1.168213440","rc":[{"batb":[[1,5.4,11.02],[2,1.01,15.51]],"ltp":6.6,"tv":41.76,"id":10107989},{"trd":[[1.08,87.9]],"batb":[[0,1.11,211.5],[1,1.08,240.95],[2,1.06,356.51]],"batl":[[0,1.41,902.65],[1,1.41,0]],"ltp":1.08,"tv":135.26,"id":8444034}],"tv":177.03}]}
{"op":"mcm","clk":"1003711782","pt":1580651615745,"mc":[{"id":"1.168213440","rc":[{"batb":[[2,1.01,15.51]],"ltp":1.08,"tv":135.26,"id":8444034}]}]}
{"op":"mcm","clk":"1003712203","pt":1580651617941,"mc":[{"id":"1.168213440","rc":[{"batl":[[0,13.5,64.07]],"ltp":6.6,"tv":41.76,"id":10107989}]}]}
{"op":"mcm","clk":"1003715721","pt":1580651637661,"mc":[{"id":"1.168213440","rc":[{"batb":[[0,5.4,11.02],[1,1.01,15.51],[2,1.01,0]],"ltp":6.6,"tv":41.76,"id":10107989},{"batb":[[0,1.08,240.95],[1,1.01,15.51],[2,1.01,0]],"ltp":1.08,"tv":135.26,"id":8444034}]}]}
{"op":"mcm","clk":"1003716234","pt":1580651640639,"mc":[{"id":"1.168213440","rc":[{"batb":[[0,5.5,10.7],[1,5.4,11.02],[2,1.01,15.51]],"ltp":6.6,"tv":41.76,"id":10107989}]}]}
{"op":"mcm","clk":"1003716305","pt":1580651641059,"mc":[{"id":"1.168213440","rc":[{"batb":[[1,1.01,15.51],[2,1.01,0]],"ltp":6.6,"tv":41.76,"id":10107989}]}]}
{"op":"mcm","clk":"1003717108","pt":1580651645655,"mc":[{"id":"1.168213440","rc":[{"batb":[[1,3.65,14.48],[2,1.01,15.51]],"ltp":6.6,"tv":41.76,"id":10107989},{"batb":[[0,1.18,130.14],[1,1.12,205.44],[2,1.01,15.51]],"ltp":1.08,"tv":135.26,"id":8444034}]}]}
{"op":"mcm","clk":"1003717556","pt":1580651647971,"mc":[{"id":"1.168213440","rc":[{"batl":[[0,8.2,85.46]],"ltp":6.6,"tv":41.76,"id":10107989}]}]}
{"op":"mcm","clk":"1003720391","pt":1580651663895,"mc":[{"id":"1.168213440","rc":[{"batb":[[0,3.65,14.48],[1,1.01,15.51],[2,1.01,0]],"ltp":6.6,"tv":41.76,"id":10107989},{"batb":[[0,1.12,205.44],[1,1.01,15.51],[2,1.01,0]],"ltp":1.08,"tv":135.26,"id":8444034}]}]}
{"op":"mcm","clk":"1003724360","pt":1580651685561,"mc":[{"id":"1.168213440","rc":[{"batb":[[0,7.4,10.54],[1,4.8,14.63],[2,3.65,14.48]],"ltp":6.6,"tv":41.76,"id":10107989},{"batb":[[1,1.07,321.18],[2,1.01,15.51]],"ltp":1.08,"tv":135.26,"id":8444034}]}]}
{"op":"mcm","clk":"1003724389","pt":1580651685848,"mc":[{"id":"1.168213440","rc":[{"batb":[[2,1.01,15.51]],"ltp":6.6,"tv":41.76,"id":10107989}]}]}
{"op":"mcm","clk":"1003724832","pt":1580651688152,"mc":[{"id":"1.168213440","rc":[{"batl":[[0,12,67.78]],"ltp":6.6,"tv":41.76,"id":10107989}]}]}
{"op":"mcm","clk":"1003727378","pt":1580651702351,"mc":[{"id":"1.168213440","rc":[{"trd":[[7.4,0.59]],"batb":[[0,7.4,9.95]],"ltp":7.4,"tv":42.36,"id":10107989},{"trd":[[1.16,3.79]],"ltp":1.16,"tv":139.05,"id":8444034}],"tv":181.41}]}
{"op":"mcm","clk":"1003728444","pt":1580651707669,"mc":[{"id":"1.168213440","rc":[{"batb":[[0,4.8,14.63],[1,1.01,15.51],[2,1.01,0]],"ltp":7.4,"tv":42.36,"id":10107989},{"batb":[[0,1.07,321.18],[1,1.01,15.51],[2,1.01,0]],"ltp":1.16,"tv":139.05,"id":8444034}]}]}
{"op":"mcm","clk":"1003728512","pt":1580651707944,"mc":[{"id":"1.168213440","rc":[{"batb":[[0,1.07,320.63]],"ltp":1.16,"tv":139.05,"id":8444034}]}]}
{"op":"mcm","clk":"1003730337","pt":1580651717277,"mc":[{"id":"1.168213440","rc":[{"batl":[[0,9.4,78.04]],"ltp":7.4,"tv":42.36,"id":10107989}]}]}
{"op":"mcm","clk":"1003736495","pt":1580651750414,"mc":[{"id":"1.168213440","rc":[{"batb":[[0,10,12.83],[1,9,7],[2,1.01,15.51]],"ltp":7.4,"tv":42.36,"id":10107989},{"batb":[[1,1.05,441.96],[2,1.01,15.51]],"ltp":1.16,"tv":139.05,"id":8444034}]}]}
{"op":"mcm","clk":"1003736706","pt":1580651751482,"mc":[{"id":"1.168213440","rc":[{"batl":[[0,21,53.48]],"ltp":7.4,"tv":42.36,"id":10107989},{"batl":[[0,1.38,972.95]],"ltp":1.16,"tv":139.05,"id":8444034}]}]}
{"op":"mcm","clk":"1003742840","pt":1580651785558,"mc":[{"id":"1.168213440","rc":[{"batb":[[0,9,7],[1,1.01,15.51],[2,1.01,0]],"ltp":7.4,"tv":42.36,"id":10107989},{"batb":[[0,1.05,441.96],[1,1.01,15.51],[2,1.01,0]],"ltp":1.16,"tv":139.05,"id":8444034}]}]}
{"op":"mcm","clk":"1003744501","pt":1580651794628,"mc":[{"id":"1.168213440","rc":[{"batb":[[0,13,7.4],[1,10.5,11.41],[2,1.01,15.51]],"ltp":7.4,"tv":42.36,"id":10107989},{"batb":[[1,1.03,732.61],[2,1.01,15.51]],"ltp":1.16,"tv":139.05,"id":8444034}]}]}
{"op":"mcm","clk":"1003744871","pt":1580651796598,"mc":[{"id":"1.168213440","rc":[{"batl":[[0,26,49.38]],"ltp":7.4,"tv":42.36,"id":10107989}]}]}
{"op":"mcm","clk":"1003747715","pt":1580651811488,"mc":[{"id":"1.168213440","rc":[{"batb":[[0,10.5,11.41],[1,1.01,15.51],[2,1.01,0]],"ltp":7.4,"tv":42.36,"id":10107989},{"batb":[[0,1.03,732.61],[1,1.01,15.51],[2,1.01,0]],"ltp":1.16,"tv":139.05,"id":8444034}]}]}
{"op":"mcm","clk":"1003749487","pt":1580651821269,"mc":[{"id":"1.168213440","rc":[{"batb":[[1,9,16.92],[2,1.01,15.51]],"ltp":7.4,"tv":42.36,"id":10107989},{"batb":[[0,1.07,343.05],[1,1.04,514.82],[2,1.01,15.51]],"ltp":1.16,"tv":139.05,"id":8444034}]}]}
{"op":"mcm","clk":"1003749764","pt":1580651822703,"mc":[{"id":"1.168213440","rc":[{"batl":[[0,21,53.48]],"ltp":7.4,"tv":42.36,"id":10107989}]}]}
{"op":"mcm","clk":"1003752528","pt":1580651837763,"mc":[{"id":"1.168213440","rc":[{"batb":[[0,9,16.92],[1,1.01,15.51],[2,1.01,0]],"ltp":7.4,"tv":42.36,"id":10107989},{"batb":[[0,1.04,514.82],[1,1.01,15.51],[2,1.01,0]],"ltp":1.16,"tv":139.05,"id":8444034}]}]}
{"op":"mcm","clk":"1003755042","pt":1580651851586,"mc":[{"id":"1.168213440","rc":[{"batb":[[1,8,8.89],[2,1.01,15.51]],"ltp":7.4,"tv":42.36,"id":10107989},{"batb":[[0,1.09,273.03],[1,1.06,366.34],[2,1.04,514.82]],"ltp":1.16,"tv":139.05,"id":8444034}]}]}
{"op":"mcm","clk":"1003755076","pt":1580651851784,"mc":[{"id":"1.168213440","rc":[{"batb":[[2,1.01,15.51]],"ltp":1.16,"tv":139.05,"id":8444034}]}]}
{"op":"mcm","clk":"1003755260","pt":1580651852800,"mc":[{"id":"1.168213440","rc":[{"batl":[[0,18,56.21]],"ltp":7.4,"tv":42.36,"id":10107989}]}]}
{"op":"mcm","clk":"1003758340","pt":1580651869541,"mc":[{"id":"1.168213440","rc":[{"batb":[[0,8,8.89],[1,1.01,15.51],[2,1.01,0]],"ltp":7.4,"tv":42.36,"id":10107989},{"batb":[[0,1.06,366.34],[1,1.01,15.51],[2,1.01,0]],"ltp":1.16,"tv":139.05,"id":8444034}]}]}
{"op":"mcm","clk":"1003760247","pt":1580651879644,"mc":[{"id":"1.168213440","rc":[{"batl":[[0,21,53.48]],"ltp":7.4,"tv":42.36,"id":10107989}]}]}
{"op":"mcm","clk":"1003762938","pt":1580651892952,"mc":[{"id":"1.168213440","rc":[{"batb":[[0,11,10.23],[1,9,6.92],[2,1.01,15.51]],"ltp":7.4,"tv":42.36,"id":10107989},{"batb":[[1,1.03,681.23],[2,1.01,15.51]],"ltp":1.16,"tv":139.05,"id":8444034}]}]}
{"op":"mcm","clk":"1003767297","pt":1580651914522,"mc":[{"id":"1.168213440","rc":[{"batb":[[0,9,6.92],[1,1.01,15.51],[2,1.01,0]],"ltp":7.4,"tv":42.36,"id":10107989},{"batb":[[0,1.03,681.23],[1,1.01,15.51],[2,1.01,0]],"ltp":1.16,"tv":139.05,"id":8444034}]}]}
{"op":"mcm","clk":"1003770638","pt":1580651931413,"mc":[{"id":"1.168213440","rc":[{"batb":[[1,7.8,9.76],[2,1.01,15.51]],"ltp":7.4,"tv":42.36,"id":10107989},{"batb":[[0,1.09,269.49],[1,1.06,404.58],[2,1.01,15.51]],"ltp":1.16,"tv":139.05,"id":8444034}]}]}
{"op":"mcm","clk":"1003771107","pt":1580651934081,"mc":[{"id":"1.168213440","rc":[{"batl":[[0,18,56.21]],"ltp":7.4,"tv":42.36,"id":10107989}]}]}
{"op":"mcm","clk":"1003774223","pt":1580651949641,"mc":[{"id":"1.168213440","rc":[{"batb":[[0,7.8,9.76],[1,1.01,15.51],[2,1.01,0]],"ltp":7.4,"tv":42.36,"id":10107989},{"batb":[[0,1.06,404.58],[1,1.01,15.51],[2,1.01,0]],"ltp":1.16,"tv":139.05,"id":8444034}]}]}
{"op":"mcm","clk":"1003779865","pt":1580651978312,"mc":[{"id":"1.168213440","rc":[{"batb":[[0,12,8.58],[1,8,8.89],[2,1.01,15.51]],"ltp":7.4,"tv":42.36,"id":10107989}]}]}
{"op":"mcm","clk":"1003780421","pt":1580651981244,"mc":[{"id":"1.168213440","rc":[{"batl":[[0,26,49.38]],"ltp":7.4,"tv":42.36,"id":10107989}]}]}
{"op":"mcm","clk":"1003785734","pt":1580652006485,"mc":[{"id":"1.168213440","rc":[{"batb":[[0,8,8.89],[1,1.01,15.51],[2,1.01,0]],"ltp":7.4,"tv":42.36,"id":10107989},{"batb":[[0,1.01,15.51],[1,1.01,0]],"ltp":1.16,"tv":139.05,"id":8444034}]}]}
{"op":"mcm","clk":"1003787234","pt":1580652012689,"mc":[{"id":"1.168213440","rc":[{"batb":[[0,1.01,15.51],[1,1.01,0]],"ltp":7.4,"tv":42.36,"id":10107989}]}]}
{"op":"mcm","clk":"1003788197","pt":1580652017400,"mc":[{"id":"1.168213440","rc":[{"batl":[[0,1.27,1374.85]],"ltp":1.16,"tv":139.05,"id":8444034}]}]}
{"op":"mcm","clk":"1003791059","pt":1580652031215,"mc":[{"id":"1.168213440","rc":[{"trd":[[1.01,20.16]],"batb":[[0,1.01,5.43]],"ltp":1.01,"tv":159.21,"id":8444034}],"tv":201.57}]}
{"op":"mcm","clk":"1003814281","pt":1580652142217,"mc":[{"id":"1.168213440","rc":[{"batb":[[0,21,4.41],[1,1.01,15.51]],"ltp":7.4,"tv":42.36,"id":10107989},{"batl":[[0,1.28,1309.11]],"ltp":1.01,"tv":159.21,"id":8444034}]}]}
{"op":"mcm","clk":"1003819397","pt":1580652165706,"mc":[{"id":"1.168213440","rc":[{"batb":[[0,26,3.52],[1,21,4.41],[2,1.01,15.51]],"ltp":7.4,"tv":42.36,"id":10107989}]}]}
{"op":"mcm","clk":"1003819456","pt":1580652165991,"mc":[{"id":"1.168213440","rc":[{"batb":[[1,1.01,15.51],[2,1.01,0]],"ltp":7.4,"tv":42.36,"id":10107989}]}]}
{"op":"mcm","clk":"1003825727","pt":1580652193551,"mc":[{"id":"1.168213440","rc":[{"batb":[[0,30,2.44],[1,26,3.52],[2,1.01,15.51]],"ltp":7.4,"tv":42.36,"id":10107989}]}]}
{"op":"mcm","clk":"1003825937","pt":1580652194587,"mc":[{"id":"1.168213440","rc":[{"batb":[[1,1.01,15.51],[2,1.01,0]],"ltp":7.4,"tv":42.36,"id":10107989},{"batl":[[0,1.27,1374.85]],"ltp":1.01,"tv":159.21,"id":8444034}]}]}
{"op":"mcm","clk":"1003831027","pt":1580652216536,"mc":[{"id":"1.168213440","rc":[{"batb":[[1,21,4.19],[2,1.01,15.51]],"ltp":7.4,"tv":42.36,"id":10107989}]}]}
{"op":"mcm","clk":"1003831307","pt":1580652217733,"mc":[{"id":"1.168213440","rc":[{"batl":[[0,1.28,1309.11]],"ltp":1.01,"tv":159.21,"id":8444034}]}]}
{"op":"mcm","clk":"1003836014","pt":1580652237480,"mc":[{"id":"1.168213440","rc":[{"batb":[[0,21,4.19],[1,1.01,15.51],[2,1.01,0]],"ltp":7.4,"tv":42.36,"id":10107989}]}]}
{"op":"mcm","clk":"1003837716","pt":1580652245048,"mc":[{"id":"1.168213440","rc":[{"batl":[[0,340,35.88]],"ltp":7.4,"tv":42.36,"id":10107989},{"batl":[[0,1.3,1248.63]],"ltp":1.01,"tv":159.21,"id":8444034}]}]}
{"op":"mcm","clk":"1003840830","pt":1580652257624,"mc":[{"id":"1.168213440","rc":[{"batb":[[0,1.01,15.51],[1,1.01,0]],"ltp":7.4,"tv":42.36,"id":10107989}]}]}
{"op":"mcm","clk":"1003841900","pt":1580652262145,"mc":[{"id":"1.168213440","rc":[{"batl":[[0,1.27,1374.85]],"ltp":1.01,"tv":159.21,"id":8444034}]}]}
{"op":"mcm","clk":"1003848343","pt":1580652290045,"mc":[{"id":"1.168213440","marketDefinition":{"bspMarket":false,"turnInPlayEnabled":true,"persistenceEnabled":true,"marketBaseRate":5.0,"eventId":"29681204","eventTypeId":"2","numberOfWinners":1,"bettingType":"ODDS","marketType":"SET_WINNER","marketTime":"2020-02-02T12:47:00.000Z","suspendTime":"2020-02-02T12:47:00.000Z","bspReconciled":false,"complete":true,"inPlay":true,"crossMatching":true,"runnersVoidable":false,"numberOfActiveRunners":2,"betDelay":3,"status":"SUSPENDED","runners":[{"status":"ACTIVE","sortPriority":1,"id":8444034,"name":"Golubev/Nedovyesov"},{"status":"ACTIVE","sortPriority":2,"id":10107989,"name":"Sabanov/Sabanov"}],"regulators":["MR_INT"],"countryCode":"FR","discountAllowed":true,"timezone":"UTC","openDate":"2020-02-02T12:47:00.000Z","version":3149102925,"name":"Set 2 Winner","eventName":"Golubev/Nedovyesov v Sabanov/Sabanov"}}]}
{"op":"mcm","clk":"1003856377","pt":1580652321801,"mc":[{"id":"1.168213440","tv":0.0}]}
{"op":"mcm","clk":"1003856759","pt":1580652323208,"mc":[{"id":"1.168213440","marketDefinition":{"bspMarket":false,"turnInPlayEnabled":true,"persistenceEnabled":true,"marketBaseRate":5.0,"eventId":"29681204","eventTypeId":"2","numberOfWinners":1,"bettingType":"ODDS","marketType":"SET_WINNER","marketTime":"2020-02-02T12:47:00.000Z","suspendTime":"2020-02-02T12:47:00.000Z","bspReconciled":false,"complete":true,"inPlay":true,"crossMatching":false,"runnersVoidable":false,"numberOfActiveRunners":0,"betDelay":3,"status":"CLOSED","settledTime":"2020-02-02T14:05:20.000Z","runners":[{"status":"WINNER","sortPriority":1,"id":8444034,"name":"Golubev/Nedovyesov"},{"status":"LOSER","sortPriority":2,"id":10107989,"name":"Sabanov/Sabanov"}],"regulators":["MR_INT"],"countryCode":"FR","discountAllowed":true,"timezone":"UTC","openDate":"2020-02-02T12:47:00.000Z","version":3149107862,"name":"Set 2 Winner","eventName":"Golubev/Nedovyesov v Sabanov/Sabanov"}}]}
