{"op":"mcm","clk":"993864652","pt":1580564223743,"mc":[{"id":"1.168213437","marketDefinition":{"bspMarket":false,"turnInPlayEnabled":true,"persistenceEnabled":true,"marketBaseRate":5.0,"eventId":"29681204","eventTypeId":"2","numberOfWinners":1,"bettingType":"ODDS","marketType":"MATCH_ODDS","marketTime":"2020-02-02T09:00:00.000Z","suspendTime":"2020-02-02T09:00:00.000Z","bspReconciled":false,"complete":true,"inPlay":false,"crossMatching":false,"runnersVoidable":false,"numberOfActiveRunners":2,"betDelay":0,"status":"OPEN","runners":[{"status":"ACTIVE","sortPriority":1,"id":8444034,"name":"Golubev/Nedovyesov"},{"status":"ACTIVE","sortPriority":2,"id":10107989,"name":"Sabanov/Sabanov"}],"regulators":["MR_INT"],"countryCode":"FR","discountAllowed":false,"timezone":"UTC","openDate":"2020-02-02T09:00:00.000Z","version":3145282985,"name":"Match Odds","eventName":"Golubev/Nedovyesov v Sabanov/Sabanov"}}]}
{"op":"mcm","clk":"993865048","pt":1580564225394,"mc":[{"id":"1.168213437","rc":[{"batb":[[0,1.01,30]],"ltp":0.0,"tv":0.0,"id":10107989},{"batb":[[0,1.01,30]],"ltp":0.0,"tv":0.0,"id":8444034}]}]}
{"op":"mcm","clk":"993865150","pt":1580564225779,"mc":[{"id":"1.168213437","marketDefinition":{"bspMarket":false,"turnInPlayEnabled":true,"persistenceEnabled":true,"marketBaseRate":5.0,"eventId":"29681204","eventTypeId":"2","numberOfWinners":1,"bettingType":"ODDS","marketType":"MATCH_ODDS","marketTime":"2020-02-02T09:00:00.000Z","suspendTime":"2020-02-02T09:00:00.000Z","bspReconciled":false,"complete":true,"inPlay":false,"crossMatching":false,"runnersVoidable":false,"numberOfActiveRunners":2,"betDelay":0,"status":"OPEN","runners":[{"status":"ACTIVE","sortPriority":1,"id":8444034,"name":"Golubev/Nedovyesov"},{"status":"ACTIVE","sortPriority":2,"id":10107989,"name":"Sabanov/Sabanov"}],"regulators":["MR_INT"],"countryCode":"FR","discountAllowed":false,"timezone":"UTC","openDate":"2020-02-02T09:00:00.000Z","version":3145282985,"name":"Match Odds","eventName":"Golubev/Nedovyesov v Sabanov/Sabanov"}}]}
{"op":"mcm","clk":"993865438","pt":1580564226748,"mc":[{"id":"1.168213437","marketDefinition":{"bspMarket":false,"turnInPlayEnabled":true,"persistenceEnabled":true,"marketBaseRate":5.0,"eventId":"29681204","eventTypeId":"2","numberOfWinners":1,"bettingType":"ODDS","marketType":"MATCH_ODDS","marketTime":"2020-02-02T09:00:00.000Z","suspendTime":"2020-02-02T09:00:00.000Z","bspReconciled":false,"complete":true,"inPlay":false,"crossMatching":false,"runnersVoidable":false,"numberOfActiveRunners":2,"betDelay":0,"status":"OPEN","runners":[{"status":"ACTIVE","sortPriority":1,"id":8444034,"name":"Golubev/Nedovyesov"},{"status":"ACTIVE","sortPriority":2,"id":10107989,"name":"Sabanov/Sabanov"}],"regulators":["MR_INT"],"countryCode":"FR","discountAllowed":true,"timezone":"UTC","openDate":"2020-02-02T09:00:00.000Z","version":3145282985,"name":"Match Odds","eventName":"Golubev/Nedovyesov v Sabanov/Sabanov"}}]}
{"op":"mcm","clk":"993872064","pt":1580564253982,"mc":[{"id":"1.168213437","rc":[{"batb":[[0,1.01,330]],"ltp":0.0,"tv":0.0,"id":8444034}]}]}
{"op":"mcm","clk":"993872422","pt":1580564255376,"mc":[{"id":"1.168213437","rc":[{"batb":[[0,1.01,330]],"ltp":0.0,"tv":0.0,"id":10107989}]}]}
{"op":"mcm","clk":"993964428","pt":1580564651628,"mc":[{"id":"1.168213437","rc":[{"batb":[[0,1.02,151.45],[1,1.01,330]],"batl":[[0,990,1.51]],"ltp":0.0,"tv":0.0,"id":8444034}]}]}
{"op":"mcm","clk":"993964528","pt":1580564652117,"mc":[{"id":"1.168213437","rc":[{"batb":[[0,1.02,151.45],[1,1.01,330]],"batl":[[0,990,1.51]],"ltp":0.0,"tv":0.0,"id":10107989}]}]}
{"op":"mcm","clk":"993978302","pt":1580564712602,"mc":[{"id":"1.168213437","rc":[{"batb":[[1,1.01,320]],"ltp":0.0,"tv":0.0,"id":10107989},{"batb":[[1,1.01,320]],"ltp":0.0,"tv":0.0,"id":8444034}]}]}
{"op":"mcm","clk":"993984441","pt":1580564740532,"mc":[{"id":"1.168213437","rc":[{"batb":[[0,1.02,176.65]],"ltp":0.0,"tv":0.0,"id":10107989},{"batb":[[0,1.03,8.4],[1,1.02,176.65],[2,1.01,320]],"ltp":0.0,"tv":0.0,"id":8444034}]}]}
{"op":"mcm","clk":"993984513","pt":1580564740836,"mc":[{"id":"1.168213437","rc":[{"batb":[[0,1.03,8.4],[1,1.02,176.65],[2,1.01,320]],"ltp":0.0,"tv":0.0,"id":10107989}]}]}
{"op":"mcm","clk":"993993082","pt":1580564776774,"mc":[{"id":"1.168213437","marketDefinition":{"bspMarket":false,"turnInPlayEnabled":true,"persistenceEnabled":true,"marketBaseRate":5.0,"eventId":"29681204","eventTypeId":"2","numberOfWinners":1,"bettingType":"ODDS","marketType":"MATCH_ODDS","marketTime":"2020-02-02T09:00:00.000Z","suspendTime":"2020-02-02T09:00:00.000Z","bspReconciled":false,"complete":true,"inPlay":false,"crossMatching":true,"runnersVoidable":false,"numberOfActiveRunners":2,"betDelay":0,"status":"OPEN","runners":[{"status":"ACTIVE","sortPriority":1,"id":8444034,"name":"Golubev/Nedovyesov"},{"status":"ACTIVE","sortPriority":2,"id":10107989,"name":"Sabanov/Sabanov"}],"regulators":["MR_INT"],"countryCode":"FR","discountAllowed":true,"timezone":"UTC","openDate":"2020-02-02T09:00:00.000Z","version":3145282985,"name":"Match Odds","eventName":"Golubev/Nedovyesov v Sabanov/Sabanov"}}]}
{"op":"mcm","clk":"994051665","pt":1580564998581,"mc":[{"id":"1.168213437","rc":[{"batb":[[0,1.13,75.72],[1,1.03,8.4],[2,1.02,176.65]],"ltp":0.0,"tv":0.0,"id":10107989},{"batb":[[0,1.13,75.72],[1,1.03,8.4],[2,1.02,176.65]],"ltp":0.0,"tv":0.0,"id":8444034}]}]}
{"op":"mcm","clk":"994053261","pt":1580565006873,"mc":[{"id":"1.168213437","rc":[{"batb":[[1,1.04,75.72],[2,1.03,8.4]],"ltp":0.0,"tv":0.0,"id":10107989},{"batb":[[1,1.04,75.72],[2,1.03,8.4]],"ltp":0.0,"tv":0.0,"id":8444034}]}]}
{"op":"mcm","clk":"994367130","pt":1580566357161,"mc":[{"id":"1.168213437","rc":[{"batl":[[0,990,3.71]],"ltp":0.0,"tv":0.0,"id":10107989},{"batl":[[0,990,3.71]],"ltp":0.0,"tv":0.0,"id":8444034}]}]}
{"op":"mcm","clk":"996243237","pt":1580574046235,"mc":[{"id":"1.168213437","marketDefinition":{"bspMarket":false,"turnInPlayEnabled":true,"persistenceEnabled":true,"marketBaseRate":5.0,"eventId":"29681204","eventTypeId":"2","numberOfWinners":1,"bettingType":"ODDS","marketType":"MATCH_ODDS","marketTime":"2020-02-02T13:00:00.000Z","suspendTime":"2020-02-02T13:00:00.000Z","bspReconciled":false,"complete":true,"inPlay":false,"crossMatching":true,"runnersVoidable":false,"numberOfActiveRunners":2,"betDelay":0,"status":"OPEN","runners":[{"status":"ACTIVE","sortPriority":1,"id":8444034,"name":"Golubev/Nedovyesov"},{"status":"ACTIVE","sortPriority":2,"id":10107989,"name":"Sabanov/Sabanov"}],"regulators":["MR_INT"],"countryCode":"FR","discountAllowed":true,"timezone":"UTC","openDate":"2020-02-02T09:00:00.000Z","version":3146180824,"name":"Match Odds","eventName":"Golubev/Nedovyesov v Sabanov/Sabanov"}}]}
{"op":"mcm","clk":"996243943","pt":1580574049267,"mc":[{"id":"1.168213437","marketDefinition":{"bspMarket":false,"turnInPlayEnabled":true,"persistenceEnabled":true,"marketBaseRate":5.0,"eventId":"29681204","eventTypeId":"2","numberOfWinners":1,"bettingType":"ODDS","marketType":"MATCH_ODDS","marketTime":"2020-02-02T13:00:00.000Z","suspendTime":"2020-02-02T13:00:00.000Z","bspReconciled":false,"complete":true,"inPlay":false,"crossMatching":true,"runnersVoidable":false,"numberOfActiveRunners":2,"betDelay":0,"status":"OPEN","runners":[{"status":"ACTIVE","sortPriority":1,"id":8444034,"name":"Golubev/Nedovyesov"},{"status":"ACTIVE","sortPriority":2,"id":10107989,"name":"Sabanov/Sabanov"}],"regulators":["MR_INT"],"countryCode":"FR","discountAllowed":true,"timezone":"UTC","openDate":"2020-02-02T13:00:00.000Z","version":3146180824,"name":"Match Odds","eventName":"Golubev/Nedovyesov v Sabanov/Sabanov"}}]}
{"op":"mcm","clk":"998274925","pt":1580585958471,"mc":[{"id":"1.168213437","rc":[{"batl":[[0,48,31.05],[1,990,3.71]],"ltp":0.0,"tv":0.0,"id":10107989},{"batl":[[0,48,31.05],[1,990,3.71]],"ltp":0.0,"tv":0.0,"id":8444034}]}]}
{"op":"mcm","clk":"999026861","pt":1580591499993,"mc":[{"id":"1.168213437","rc":[{"batb":[[0,2.04,31.1],[1,1.13,75.72],[2,1.04,75.72]],"ltp":0.0,"tv":0.0,"id":10107989},{"batb":[[0,1.67,48.28],[1,1.13,75.72],[2,1.04,75.72]],"ltp":0.0,"tv":0.0,"id":8444034}]}]}
{"op":"mcm","clk":"999028108","pt":1580591510682,"mc":[{"id":"1.168213437","rc":[{"batb":[[1,1.66,20.49],[2,1.13,75.72]],"ltp":0.0,"tv":0.0,"id":10107989},{"batb":[[1,1.44,30.17],[2,1.13,75.72]],"ltp":0.0,"tv":0.0,"id":8444034}]}]}
{"op":"mcm","clk":"999201835","pt":1580592913407,"mc":[{"id":"1.168213437","rc":[{"batb":[[1,1.84,15.14]],"ltp":0.0,"tv":0.0,"id":10107989},{"batb":[[1,1.51,18.17]],"ltp":0.0,"tv":0.0,"id":8444034}]}]}
{"op":"mcm","clk":"999361449","pt":1580594411711,"mc":[{"id":"1.168213437","rc":[{"batb":[[1,1.5,18.17]],"ltp":0.0,"tv":0.0,"id":8444034}]}]}
{"op":"mcm","clk":"999403386","pt":1580594913475,"mc":[{"id":"1.168213437","rc":[{"batb":[[1,1.51,18.17]],"ltp":0.0,"tv":0.0,"id":8444034}]}]}
{"op":"mcm","clk":"999405011","pt":1580594933319,"mc":[{"id":"1.168213437","rc":[{"batb":[[2,1.21,37.86]],"ltp":0.0,"tv":0.0,"id":8444034}]}]}
{"op":"mcm","clk":"999405113","pt":1580594934680,"mc":[{"id":"1.168213437","rc":[{"batb":[[2,1.31,37.86]],"ltp":0.0,"tv":0.0,"id":10107989},{"batb":[[1,1.51,56.04],[2,1.41,37.86]],"ltp":0.0,"tv":0.0,"id":8444034}]}]}
{"op":"mcm","clk":"999405192","pt":1580594935608,"mc":[{"id":"1.168213437","rc":[{"batb":[[2,1.81,37.86]],"ltp":0.0,"tv":0.0,"id":10107989}]}]}
{"op":"mcm","clk":"999435187","pt":1580595274852,"mc":[{"id":"1.168213437","rc":[{"batb":[[1,1.85,15.14]],"ltp":0.0,"tv":0.0,"id":10107989},{"batb":[[1,1.51,37.86],[2,1.5,18.17]],"ltp":0.0,"tv":0.0,"id":8444034}]}]}
{"op":"mcm","clk":"999443869","pt":1580595387112,"mc":[{"id":"1.168213437","rc":[{"batb":[[1,1.84,15.14]],"ltp":0.0,"tv":0.0,"id":10107989},{"batb":[[1,1.51,56.04],[2,1.41,37.86]],"ltp":0.0,"tv":0.0,"id":8444034}]}]}
{"op":"mcm","clk":"999447209","pt":1580595430343,"mc":[{"id":"1.168213437","rc":[{"batb":[[1,1.85,15.14]],"ltp":0.0,"tv":0.0,"id":10107989},{"batb":[[1,1.51,37.86],[2,1.5,18.17]],"ltp":0.0,"tv":0.0,"id":8444034}]}]}
{"op":"mcm","clk":"999450321","pt":1580595473147,"mc":[{"id":"1.168213437","rc":[{"batb":[[1,1.84,15.14]],"ltp":0.0,"tv":0.0,"id":10107989},{"batb":[[1,1.51,56.04],[2,1.41,37.86]],"ltp":0.0,"tv":0.0,"id":8444034}]}]}
{"op":"mcm","clk":"999464819","pt":1580595669653,"mc":[{"id":"1.168213437","rc":[{"batb":[[1,1.85,15.14]],"ltp":0.0,"tv":0.0,"id":10107989},{"batb":[[1,1.51,37.86],[2,1.5,18.17]],"ltp":0.0,"tv":0.0,"id":8444034}]}]}
{"op":"mcm","clk":"999473111","pt":1580595788155,"mc":[{"id":"1.168213437","rc":[{"batb":[[1,1.84,15.14]],"ltp":0.0,"tv":0.0,"id":10107989},{"batb":[[1,1.51,56.04],[2,1.41,37.86]],"ltp":0.0,"tv":0.0,"id":8444034}]}]}
{"op":"mcm","clk":"999513233","pt":1580596320442,"mc":[{"id":"1.168213437","rc":[{"batb":[[1,1.85,15.14]],"ltp":0.0,"tv":0.0,"id":10107989},{"batb":[[1,1.51,37.86],[2,1.5,18.17]],"ltp":0.0,"tv":0.0,"id":8444034}]}]}
{"op":"mcm","clk":"999663985","pt":1580598544593,"mc":[{"id":"1.168213437","rc":[{"batb":[[2,1.49,18.17]],"ltp":0.0,"tv":0.0,"id":8444034}]}]}
{"op":"mcm","clk":"999857475","pt":1580601564666,"mc":[{"id":"1.168213437","rc":[{"batl":[[2,1000,0.02]],"ltp":0.0,"tv":0.0,"id":10107989},{"batl":[[2,1000,0.02]],"ltp":0.0,"tv":0.0,"id":8444034}]}]}
{"op":"mcm","clk":"999978443","pt":1580603629559,"mc":[{"id":"1.168213437","rc":[{"batb":[[0,2.06,30.29],[1,2.04,31.1],[2,1.85,15.14]],"ltp":0.0,"tv":0.0,"id":10107989}]}]}
{"op":"mcm","clk":"1000021122","pt":1580604576093,"mc":[{"id":"1.168213437","rc":[{"batb":[[2,1.87,15.14]],"ltp":0.0,"tv":0.0,"id":10107989},{"batb":[[1,1.51,56.04],[2,1.41,37.86]],"ltp":0.0,"tv":0.0,"id":8444034}]}]}
{"op":"mcm","clk":"1000024156","pt":1580604645699,"mc":[{"id":"1.168213437","rc":[{"batb":[[1,1.51,37.86]],"ltp":0.0,"tv":0.0,"id":8444034}]}]}
{"op":"mcm","clk":"1000024183","pt":1580604646415,"mc":[{"id":"1.168213437","rc":[{"batb":[[2,1.87,19.69]],"ltp":0.0,"tv":0.0,"id":10107989},{"batb":[[1,1.51,62.09]],"ltp":0.0,"tv":0.0,"id":8444034}]}]}
{"op":"mcm","clk":"1000036905","pt":1580604931383,"mc":[{"id":"1.168213437","rc":[{"batb":[[2,1.88,19.69]],"ltp":0.0,"tv":0.0,"id":10107989}]}]}
{"op":"mcm","clk":"1000046675","pt":1580605251177,"mc":[{"id":"1.168213437","rc":[{"batb":[[2,1.87,19.69]],"ltp":0.0,"tv":0.0,"id":10107989}]}]}
{"op":"mcm","clk":"1000052246","pt":1580605414550,"mc":[{"id":"1.168213437","rc":[{"batb":[[2,1.88,19.69]],"ltp":0.0,"tv":0.0,"id":10107989}]}]}
{"op":"mcm","clk":"1000136153","pt":1580607867599,"mc":[{"id":"1.168213437","rc":[{"batl":[[1,990,2.2]],"ltp":0.0,"tv":0.0,"id":8444034}]}]}
{"op":"mcm","clk":"1000142793","pt":1580608035296,"mc":[{"id":"1.168213437","rc":[{"batl":[[1,990,2.2]],"ltp":0.0,"tv":0.0,"id":10107989}]}]}
{"op":"mcm","clk":"1000272606","pt":1580611153902,"mc":[{"id":"1.168213437","rc":[{"batb":[[1,1.51,37.86],[2,1.5,24.23]],"ltp":0.0,"tv":0.0,"id":8444034}]}]}
{"op":"mcm","clk":"1000280436","pt":1580611357661,"mc":[{"id":"1.168213437","rc":[{"batb":[[2,1.41,37.86]],"ltp":0.0,"tv":0.0,"id":8444034}]}]}
{"op":"mcm","clk":"1000280440","pt":1580611357763,"mc":[{"id":"1.168213437","rc":[{"batb":[[1,1.51,62.09]],"ltp":0.0,"tv":0.0,"id":8444034}]}]}
{"op":"mcm","clk":"1000326374","pt":1580612438488,"mc":[{"id":"1.168213437","rc":[{"batb":[[1,1.52,24.23],[2,1.51,37.86]],"ltp":0.0,"tv":0.0,"id":8444034}]}]}
{"op":"mcm","clk":"1000473038","pt":1580615093192,"mc":[{"id":"1.168213437","rc":[{"batl":[[0,990,2.2],[1,1000,0.02],[2,1000,0]],"ltp":0.0,"tv":0.0,"id":10107989},{"batl":[[0,990,2.2],[1,1000,0.02],[2,1000,0]],"ltp":0.0,"tv":0.0,"id":8444034}]}]}
{"op":"mcm","clk":"1000553696","pt":1580616728915,"mc":[{"id":"1.168213437","rc":[{"batl":[[0,95,2.27],[1,990,2.2],[2,1000,0.02]],"ltp":0.0,"tv":0.0,"id":10107989},{"batl":[[0,95,2.27],[1,990,2.2],[2,1000,0.02]],"ltp":0.0,"tv":0.0,"id":8444034}]}]}
{"op":"mcm","clk":"1000619113","pt":1580617620013,"mc":[{"id":"1.168213437","rc":[{"batb":[[2,1.88,9.09]],"ltp":0.0,"tv":0.0,"id":10107989},{"batb":[[1,1.52,10.6]],"ltp":0.0,"tv":0.0,"id":8444034}]}]}
{"op":"mcm","clk":"1000630681","pt":1580617801529,"mc":[{"id":"1.168213437","rc":[{"batb":[[2,1.88,19.69]],"ltp":0.0,"tv":0.0,"id":10107989},{"batb":[[1,1.52,24.23]],"ltp":0.0,"tv":0.0,"id":8444034}]}]}
{"op":"mcm","clk":"1000729420","pt":1580619615988,"mc":[{"id":"1.168213437","rc":[{"batb":[[0,2.1,29.4],[1,2.06,30.29]],"ltp":0.0,"tv":0.0,"id":10107989}]}]}
{"op":"mcm","clk":"1000733535","pt":1580619694868,"mc":[{"id":"1.168213437","rc":[{"batb":[[0,2.12,30.29],[1,2.1,29.4]],"ltp":0.0,"tv":0.0,"id":10107989}]}]}
{"op":"mcm","clk":"1000735647","pt":1580619736055,"mc":[{"id":"1.168213437","rc":[{"batl":[[0,2.4,15.14],[1,95,2.27],[2,990,2.2]],"ltp":0.0,"tv":0.0,"id":8444034}]}]}
{"op":"mcm","clk":"1000985225","pt":1580625579653,"mc":[{"id":"1.168213437","rc":[{"batb":[[1,1.51,37.86],[2,1.41,37.86]],"ltp":0.0,"tv":0.0,"id":8444034}]}]}
{"op":"mcm","clk":"1000985227","pt":1580625579755,"mc":[{"id":"1.168213437","rc":[{"batb":[[1,1.51,62.09]],"ltp":0.0,"tv":0.0,"id":8444034}]}]}
{"op":"mcm","clk":"1000993376","pt":1580625782218,"mc":[{"id":"1.168213437","rc":[{"batb":[[1,1.52,24.23],[2,1.51,37.86]],"ltp":0.0,"tv":0.0,"id":8444034}]}]}
{"op":"mcm","clk":"1001027143","pt":1580626804624,"mc":[{"id":"1.168213437","rc":[{"batb":[[1,2.1,44.11]],"ltp":0.0,"tv":0.0,"id":10107989},{"batb":[[0,1.67,72.42]],"ltp":0.0,"tv":0.0,"id":8444034}]}]}
{"op":"mcm","clk":"1001048653","pt":1580627317809,"mc":[{"id":"1.168213437","rc":[{"batl":[[0,2.48,3.79],[1,95,2.27],[2,990,2.2]],"ltp":0.0,"tv":0.0,"id":10107989},{"batl":[[0,1.89,7.57],[1,2.4,15.14],[2,95,2.27]],"ltp":0.0,"tv":0.0,"id":8444034}]}]}
{"op":"mcm","clk":"1001087157","pt":1580628202274,"mc":[{"id":"1.168213437","rc":[{"batb":[[0,2.2,40.43],[1,2.12,30.29]],"ltp":0.0,"tv":0.0,"id":10107989},{"batb":[[0,1.62,78.26]],"ltp":0.0,"tv":0.0,"id":8444034}]}]}
{"op":"mcm","clk":"1001087199","pt":1580628203046,"mc":[{"id":"1.168213437","rc":[{"batb":[[2,2,37.86]],"ltp":0.0,"tv":0.0,"id":10107989}]}]}
{"op":"mcm","clk":"1001087770","pt":1580628215081,"mc":[{"id":"1.168213437","rc":[{"batb":[[1,2,37.86],[2,1.88,19.69]],"ltp":0.0,"tv":0.0,"id":10107989}]}]}
{"op":"mcm","clk":"1001099797","pt":1580628468307,"mc":[{"id":"1.168213437","rc":[{"batb":[[1,1.51,62.09],[2,1.41,37.86]],"ltp":0.0,"tv":0.0,"id":8444034}]}]}
{"op":"mcm","clk":"1001116191","pt":1580628818626,"mc":[{"id":"1.168213437","rc":[{"batb":[[2,1.88,9.09]],"ltp":0.0,"tv":0.0,"id":10107989},{"batb":[[1,1.51,48.46]],"ltp":0.0,"tv":0.0,"id":8444034}]}]}
{"op":"mcm","clk":"1001124154","pt":1580629008660,"mc":[{"id":"1.168213437","rc":[{"batb":[[2,1.81,37.86]],"ltp":0.0,"tv":0.0,"id":10107989},{"batb":[[1,1.51,62.09]],"ltp":0.0,"tv":0.0,"id":8444034}]}]}
{"op":"mcm","clk":"1001124166","pt":1580629008868,"mc":[{"id":"1.168213437","rc":[{"batb":[[2,1.88,19.69]],"ltp":0.0,"tv":0.0,"id":10107989}]}]}
{"op":"mcm","clk":"1001142757","pt":1580629379443,"mc":[{"id":"1.168213437","rc":[{"batb":[[0,2.24,39.13]],"ltp":0.0,"tv":0.0,"id":10107989},{"batb":[[0,1.57,85.13]],"ltp":0.0,"tv":0.0,"id":8444034}]}]}
{"op":"mcm","clk":"1001144765","pt":1580629421648,"mc":[{"id":"1.168213437","rc":[{"batb":[[2,1.99,19.69]],"ltp":0.0,"tv":0.0,"id":10107989},{"batb":[[1,1.51,37.86],[2,1.42,24.23]],"ltp":0.0,"tv":0.0,"id":8444034}]}]}
{"op":"mcm","clk":"1001145289","pt":1580629431715,"mc":[{"id":"1.168213437","rc":[{"batb":[[0,1.58,30.29],[1,1.57,85.13],[2,1.51,37.86]],"ltp":0.0,"tv":0.0,"id":8444034}]}]}
{"op":"mcm","clk":"1001150300","pt":1580629553121,"mc":[{"id":"1.168213437","rc":[{"batb":[[1,2,57.55],[2,1.81,37.86]],"ltp":0.0,"tv":0.0,"id":10107989}]}]}
{"op":"mcm","clk":"1001155133","pt":1580629670087,"mc":[{"id":"1.168213437","rc":[{"batb":[[1,2.02,19.69],[2,2,37.86]],"ltp":0.0,"tv":0.0,"id":10107989}]}]}
{"op":"mcm","clk":"1001171201","pt":1580630068501,"mc":[{"id":"1.168213437","rc":[{"batb":[[1,2.04,19.69]],"ltp":0.0,"tv":0.0,"id":10107989}]}]}
{"op":"mcm","clk":"1001187914","pt":1580630462404,"mc":[{"id":"1.168213437","rc":[{"batb":[[1,2.02,19.69]],"ltp":0.0,"tv":0.0,"id":10107989}]}]}
{"op":"mcm","clk":"1001192689","pt":1580630551092,"mc":[{"id":"1.168213437","rc":[{"batb":[[1,2.04,19.69]],"ltp":0.0,"tv":0.0,"id":10107989}]}]}
{"op":"mcm","clk":"1001194911","pt":1580630591029,"mc":[{"id":"1.168213437","rc":[{"batb":[[1,2.06,19.69]],"ltp":0.0,"tv":0.0,"id":10107989}]}]}
{"op":"mcm","clk":"1001225120","pt":1580631157313,"mc":[{"id":"1.168213437","rc":[{"trd":[[2.48,3.79]],"batl":[[0,95,2.27],[1,990,2.2],[2,1000,0.02]],"ltp":2.48,"tv":3.78,"id":10107989},{"trd":[[1.67,5.62]],"ltp":1.67,"tv":5.62,"id":8444034}],"tv":9.4}]}
{"op":"mcm","clk":"1001276454","pt":1580632394545,"mc":[{"id":"1.168213437","rc":[{"trd":[[2.24,4]],"batb":[[0,2.24,37.13]],"ltp":2.24,"tv":7.78,"id":10107989}],"tv":13.4}]}
{"op":"mcm","clk":"1001276478","pt":1580632395263,"mc":[{"id":"1.168213437","rc":[{"batb":[[0,2.24,39.13]],"ltp":2.24,"tv":7.78,"id":10107989}]}]}
{"op":"mcm","clk":"1001290695","pt":1580632762073,"mc":[{"id":"1.168213437","rc":[{"batl":[[0,1.8,7.57]],"ltp":1.67,"tv":5.62,"id":8444034}]}]}
{"op":"mcm","clk":"1001291326","pt":1580632777316,"mc":[{"id":"1.168213437","rc":[{"batl":[[0,1.7,78.68],[1,1.8,7.57],[2,2.4,15.14]],"ltp":1.67,"tv":5.62,"id":8444034}]}]}
{"op":"mcm","clk":"1001291666","pt":1580632785934,"mc":[{"id":"1.168213437","rc":[{"batl":[[0,1.8,7.57],[1,2.4,15.14],[2,95,2.27]],"ltp":1.67,"tv":5.62,"id":8444034}]}]}
{"op":"mcm","clk":"1001295625","pt":1580632875046,"mc":[{"id":"1.168213437","rc":[{"trd":[[1.58,10.14]],"batb":[[0,1.58,25.22]],"ltp":1.58,"tv":15.75,"id":8444034}],"tv":23.54}]}
{"op":"mcm","clk":"1001300190","pt":1580632962370,"mc":[{"id":"1.168213437","rc":[{"batb":[[0,1.58,30.29]],"ltp":1.58,"tv":15.75,"id":8444034}]}]}
{"op":"mcm","clk":"1001300220","pt":1580632962886,"mc":[{"id":"1.168213437","rc":[{"batb":[[0,2.26,3.55],[1,2.24,39.13],[2,2.06,19.69]],"ltp":2.24,"tv":7.78,"id":10107989}]}]}
{"op":"mcm","clk":"1001348155","pt":1580634059660,"mc":[{"id":"1.168213437","rc":[{"batb":[[2,2,37.86]],"ltp":2.24,"tv":7.78,"id":10107989}]}]}
{"op":"mcm","clk":"1001348160","pt":1580634059764,"mc":[{"id":"1.168213437","rc":[{"batb":[[2,2,57.55]],"ltp":2.24,"tv":7.78,"id":10107989}]}]}
{"op":"mcm","clk":"1001458733","pt":1580636298536,"mc":[{"id":"1.168213437","rc":[{"batl":[[2,2.6,74.21]],"ltp":1.58,"tv":15.75,"id":8444034}]}]}
{"op":"mcm","clk":"1001486976","pt":1580636856177,"mc":[{"id":"1.168213437","rc":[{"batl":[[0,4.1,77.99],[1,95,2.27],[2,990,2.2]],"ltp":2.24,"tv":7.78,"id":10107989}]}]}
{"op":"mcm","clk":"1001520451","pt":1580637442605,"mc":[{"id":"1.168213437","rc":[{"trd":[[1.58,52.15]],"batb":[[0,1.58,9.28]],"ltp":1.58,"tv":57.76,"id":8444034}],"tv":65.55}]}
{"op":"mcm","clk":"1001522226","pt":1580637467309,"mc":[{"id":"1.168213437","rc":[{"batb":[[0,1.58,30.29]],"ltp":1.58,"tv":57.76,"id":8444034}]}]}
{"op":"mcm","clk":"1001522263","pt":1580637467820,"mc":[{"id":"1.168213437","rc":[{"batb":[[0,2.26,18.23]],"ltp":2.24,"tv":7.78,"id":10107989}]}]}
{"op":"mcm","clk":"1001559442","pt":1580637942819,"mc":[{"id":"1.168213437","rc":[{"batb":[[0,2.26,22.44]],"batl":[[0,2.74,4.2],[1,4.1,77.99],[2,95,2.27]],"ltp":2.24,"tv":7.78,"id":10107989},{"batb":[[0,1.58,34.49]],"batl":[[0,1.8,11.77]],"ltp":1.58,"tv":57.76,"id":8444034}]}]}
{"op":"mcm","clk":"1001738902","pt":1580639713714,"mc":[{"id":"1.168213437","rc":[{"batl":[[1,2.3,15.14]],"ltp":1.58,"tv":57.76,"id":8444034}]}]}
{"op":"mcm","clk":"1001910529","pt":1580641202913,"mc":[{"id":"1.168213437","rc":[{"batb":[[1,2.24,52.17]],"ltp":2.24,"tv":7.78,"id":10107989},{"batb":[[1,1.57,113.5]],"ltp":1.58,"tv":57.76,"id":8444034}]}]}
{"op":"mcm","clk":"1001913881","pt":1580641222874,"mc":[{"id":"1.168213437","rc":[{"batb":[[0,2.3,49.76],[1,2.26,22.44]],"ltp":2.24,"tv":7.78,"id":10107989},{"batb":[[1,1.53,122.07]],"ltp":1.58,"tv":57.76,"id":8444034}]}]}
{"op":"mcm","clk":"1001916445","pt":1580641240721,"mc":[{"id":"1.168213437","rc":[{"batb":[[0,1.58,4.2],[1,1.54,30.29],[2,1.53,122.07]],"ltp":1.58,"tv":57.76,"id":8444034}]}]}
{"op":"mcm","clk":"1001916588","pt":1580641241729,"mc":[{"id":"1.168213437","rc":[{"batb":[[0,2.32,17.76],[1,2.3,49.76],[2,2.26,4.2]],"ltp":2.24,"tv":7.78,"id":10107989}]}]}
{"op":"mcm","clk":"1002053447","pt":1580642014590,"mc":[{"id":"1.168213437","rc":[{"batb":[[1,2.26,4.2],[2,2.2,53.91]],"ltp":2.24,"tv":7.78,"id":10107989},{"batb":[[1,1.57,113.5],[2,1.54,30.29]],"ltp":1.58,"tv":57.76,"id":8444034}]}]}
{"op":"mcm","clk":"1002061186","pt":1580642058615,"mc":[{"id":"1.168213437","rc":[{"batb":[[0,1.58,34.49],[2,1.51,37.86]],"ltp":1.58,"tv":57.76,"id":8444034}]}]}
{"op":"mcm","clk":"1002061375","pt":1580642059599,"mc":[{"id":"1.168213437","rc":[{"batb":[[0,2.26,22.44],[1,2.2,53.91],[2,2,57.55]],"ltp":2.24,"tv":7.78,"id":10107989}]}]}
{"op":"mcm","clk":"1002141873","pt":1580642506304,"mc":[{"id":"1.168213437","rc":[{"batl":[[0,1.76,106.37],[1,1.8,11.77],[2,2.3,15.14]],"ltp":1.58,"tv":57.76,"id":8444034}]}]}
{"op":"mcm","clk":"1002148452","pt":1580642545678,"mc":[{"id":"1.168213437","rc":[{"batb":[[0,2.32,17.76],[1,2.26,4.2],[2,2.2,53.91]],"ltp":2.24,"tv":7.78,"id":10107989}]}]}
{"op":"mcm","clk":"1002518399","pt":1580644804217,"mc":[{"id":"1.168213437","rc":[{"batb":[[0,1.58,43.11]],"ltp":1.58,"tv":57.76,"id":8444034}]}]}
{"op":"mcm","clk":"1002518722","pt":1580644805820,"mc":[{"id":"1.168213437","rc":[{"batb":[[0,2.32,36.86],[1,2.3,19.39],[2,2.26,4.2]],"ltp":2.24,"tv":7.78,"id":10107989},{"batb":[[0,1.58,86.57],[1,1.57,157.72]],"ltp":1.58,"tv":57.76,"id":8444034}]}]}
{"op":"mcm","clk":"1002518885","pt":1580644806824,"mc":[{"id":"1.168213437","rc":[{"batb":[[0,2.32,17.76]],"ltp":2.24,"tv":7.78,"id":10107989},{"batb":[[0,1.58,43.11]],"ltp":1.58,"tv":57.76,"id":8444034}]}]}
{"op":"mcm","clk":"1002519063","pt":1580644807822,"mc":[{"id":"1.168213437","rc":[{"batb":[[0,2.32,36.86]],"ltp":2.24,"tv":7.78,"id":10107989},{"batb":[[0,1.58,86.57]],"ltp":1.58,"tv":57.76,"id":8444034}]}]}
{"op":"mcm","clk":"1002519192","pt":1580644808841,"mc":[{"id":"1.168213437","rc":[{"batb":[[0,2.32,17.76]],"ltp":2.24,"tv":7.78,"id":10107989},{"batb":[[0,1.58,43.11]],"ltp":1.58,"tv":57.76,"id":8444034}]}]}
{"op":"mcm","clk":"1002519393","pt":1580644809805,"mc":[{"id":"1.168213437","rc":[{"batb":[[0,2.32,36.86]],"ltp":2.24,"tv":7.78,"id":10107989},{"batb":[[0,1.58,86.57]],"ltp":1.58,"tv":57.76,"id":8444034}]}]}
{"op":"mcm","clk":"1002519517","pt":1580644810805,"mc":[{"id":"1.168213437","rc":[{"batb":[[0,2.32,17.76]],"ltp":2.24,"tv":7.78,"id":10107989}]}]}
{"op":"mcm","clk":"1002519642","pt":1580644811800,"mc":[{"id":"1.168213437","rc":[{"batb":[[0,2.32,36.86]],"ltp":2.24,"tv":7.78,"id":10107989}]}]}
{"op":"mcm","clk":"1002519749","pt":1580644812798,"mc":[{"id":"1.168213437","rc":[{"batb":[[0,2.32,17.76]],"ltp":2.24,"tv":7.78,"id":10107989}]}]}
{"op":"mcm","clk":"1002519859","pt":1580644813817,"mc":[{"id":"1.168213437","rc":[{"batb":[[0,2.32,36.86]],"ltp":2.24,"tv":7.78,"id":10107989}]}]}
{"op":"mcm","clk":"1002520011","pt":1580644814908,"mc":[{"id":"1.168213437","rc":[{"batb":[[0,2.32,17.76]],"ltp":2.24,"tv":7.78,"id":10107989}]}]}
{"op":"mcm","clk":"1002520118","pt":1580644815842,"mc":[{"id":"1.168213437","rc":[{"batb":[[0,2.32,36.86]],"ltp":2.24,"tv":7.78,"id":10107989}]}]}
{"op":"mcm","clk":"1002520231","pt":1580644816840,"mc":[{"id":"1.168213437","rc":[{"batb":[[0,2.32,17.76]],"ltp":2.24,"tv":7.78,"id":10107989}]}]}
{"op":"mcm","clk":"1002520338","pt":1580644817844,"mc":[{"id":"1.168213437","rc":[{"batb":[[0,2.32,36.86]],"ltp":2.24,"tv":7.78,"id":10107989}]}]}
{"op":"mcm","clk":"1002520458","pt":1580644818945,"mc":[{"id":"1.168213437","rc":[{"batb":[[0,2.32,17.76]],"ltp":2.24,"tv":7.78,"id":10107989}]}]}
{"op":"mcm","clk":"1002520574","pt":1580644819845,"mc":[{"id":"1.168213437","rc":[{"batb":[[0,2.32,36.86]],"ltp":2.24,"tv":7.78,"id":10107989}]}]}
{"op":"mcm","clk":"1002520703","pt":1580644820945,"mc":[{"id":"1.168213437","rc":[{"batb":[[0,2.32,17.76]],"ltp":2.24,"tv":7.78,"id":10107989}]}]}
{"op":"mcm","clk":"1002520804","pt":1580644821841,"mc":[{"id":"1.168213437","rc":[{"batb":[[0,2.32,36.86]],"ltp":2.24,"tv":7.78,"id":10107989}]}]}
{"op":"mcm","clk":"1002520941","pt":1580644822842,"mc":[{"id":"1.168213437","rc":[{"batb":[[0,2.32,17.76]],"ltp":2.24,"tv":7.78,"id":10107989}]}]}
{"op":"mcm","clk":"1002521064","pt":1580644823832,"mc":[{"id":"1.168213437","rc":[{"batb":[[0,2.32,36.86]],"ltp":2.24,"tv":7.78,"id":10107989}]}]}
{"op":"mcm","clk":"1002521179","pt":1580644824849,"mc":[{"id":"1.168213437","rc":[{"batb":[[0,2.32,17.76]],"ltp":2.24,"tv":7.78,"id":10107989}]}]}
{"op":"mcm","clk":"1002521313","pt":1580644825851,"mc":[{"id":"1.168213437","rc":[{"batb":[[0,2.32,36.86]],"ltp":2.24,"tv":7.78,"id":10107989}]}]}
{"op":"mcm","clk":"1002521429","pt":1580644826839,"mc":[{"id":"1.168213437","rc":[{"batb":[[0,2.32,17.76]],"ltp":2.24,"tv":7.78,"id":10107989}]}]}
{"op":"mcm","clk":"1002521544","pt":1580644827831,"mc":[{"id":"1.168213437","rc":[{"batb":[[0,2.32,36.86]],"ltp":2.24,"tv":7.78,"id":10107989}]}]}
{"op":"mcm","clk":"1002521661","pt":1580644828840,"mc":[{"id":"1.168213437","rc":[{"batb":[[0,2.32,17.76]],"ltp":2.24,"tv":7.78,"id":10107989}]}]}
{"op":"mcm","clk":"1002521767","pt":1580644829790,"mc":[{"id":"1.168213437","rc":[{"batb":[[0,2.32,36.86]],"ltp":2.24,"tv":7.78,"id":10107989}]}]}
{"op":"mcm","clk":"1002521890","pt":1580644830861,"mc":[{"id":"1.168213437","rc":[{"batb":[[0,2.32,17.76]],"ltp":2.24,"tv":7.78,"id":10107989}]}]}
{"op":"mcm","clk":"1002522020","pt":1580644831850,"mc":[{"id":"1.168213437","rc":[{"batb":[[0,2.32,36.86]],"ltp":2.24,"tv":7.78,"id":10107989}]}]}
{"op":"mcm","clk":"1002522133","pt":1580644832855,"mc":[{"id":"1.168213437","rc":[{"batb":[[0,2.32,17.76]],"ltp":2.24,"tv":7.78,"id":10107989}]}]}
{"op":"mcm","clk":"1002522234","pt":1580644833841,"mc":[{"id":"1.168213437","rc":[{"batb":[[0,2.32,36.86]],"ltp":2.24,"tv":7.78,"id":10107989}]}]}
{"op":"mcm","clk":"1002522354","pt":1580644834854,"mc":[{"id":"1.168213437","rc":[{"batb":[[0,2.32,17.76]],"ltp":2.24,"tv":7.78,"id":10107989}]}]}
{"op":"mcm","clk":"1002522460","pt":1580644835748,"mc":[{"id":"1.168213437","rc":[{"batb":[[0,2.32,36.86]],"ltp":2.24,"tv":7.78,"id":10107989}]}]}
{"op":"mcm","clk":"1002522596","pt":1580644836852,"mc":[{"id":"1.168213437","rc":[{"batb":[[0,2.32,17.76]],"ltp":2.24,"tv":7.78,"id":10107989}]}]}
{"op":"mcm","clk":"1002522874","pt":1580644838862,"mc":[{"id":"1.168213437","rc":[{"batb":[[0,2.32,36.86]],"ltp":2.24,"tv":7.78,"id":10107989}]}]}
{"op":"mcm","clk":"1002522988","pt":1580644839860,"mc":[{"id":"1.168213437","rc":[{"batb":[[0,2.32,17.76]],"ltp":2.24,"tv":7.78,"id":10107989}]}]}
{"op":"mcm","clk":"1002523092","pt":1580644840808,"mc":[{"id":"1.168213437","rc":[{"batb":[[0,2.32,36.86]],"ltp":2.24,"tv":7.78,"id":10107989}]}]}
{"op":"mcm","clk":"1002523242","pt":1580644841867,"mc":[{"id":"1.168213437","rc":[{"batb":[[0,2.32,17.76]],"ltp":2.24,"tv":7.78,"id":10107989}]}]}
{"op":"mcm","clk":"1002523360","pt":1580644842757,"mc":[{"id":"1.168213437","rc":[{"batb":[[0,2.32,36.86]],"ltp":2.24,"tv":7.78,"id":10107989}]}]}
{"op":"mcm","clk":"1002523508","pt":1580644843751,"mc":[{"id":"1.168213437","rc":[{"batb":[[0,2.32,17.76]],"ltp":2.24,"tv":7.78,"id":10107989}]}]}
{"op":"mcm","clk":"1002523616","pt":1580644844763,"mc":[{"id":"1.168213437","rc":[{"batb":[[0,2.32,36.86]],"ltp":2.24,"tv":7.78,"id":10107989}]}]}
{"op":"mcm","clk":"1002523743","pt":1580644845870,"mc":[{"id":"1.168213437","rc":[{"batb":[[0,2.32,17.76]],"ltp":2.24,"tv":7.78,"id":10107989}]}]}
{"op":"mcm","clk":"1002523838","pt":1580644846781,"mc":[{"id":"1.168213437","rc":[{"batb":[[0,2.32,36.86]],"ltp":2.24,"tv":7.78,"id":10107989}]}]}
{"op":"mcm","clk":"1002523957","pt":1580644847770,"mc":[{"id":"1.168213437","rc":[{"batb":[[0,2.32,17.76]],"ltp":2.24,"tv":7.78,"id":10107989}]}]}
{"op":"mcm","clk":"1002524070","pt":1580644848770,"mc":[{"id":"1.168213437","rc":[{"batb":[[0,2.32,36.86]],"ltp":2.24,"tv":7.78,"id":10107989}]}]}
{"op":"mcm","clk":"1002524217","pt":1580644849836,"mc":[{"id":"1.168213437","rc":[{"batb":[[0,2.32,17.76]],"ltp":2.24,"tv":7.78,"id":10107989}]}]}
{"op":"mcm","clk":"1002524335","pt":1580644850801,"mc":[{"id":"1.168213437","rc":[{"batb":[[0,2.32,36.86]],"ltp":2.24,"tv":7.78,"id":10107989}]}]}
{"op":"mcm","clk":"1002524471","pt":1580644851794,"mc":[{"id":"1.168213437","rc":[{"batb":[[0,2.32,17.76]],"ltp":2.24,"tv":7.78,"id":10107989}]}]}
{"op":"mcm","clk":"1002524623","pt":1580644852765,"mc":[{"id":"1.168213437","rc":[{"batb":[[0,2.32,36.86]],"ltp":2.24,"tv":7.78,"id":10107989}]}]}
{"op":"mcm","clk":"1002524749","pt":1580644853873,"mc":[{"id":"1.168213437","rc":[{"batb":[[0,2.32,17.76]],"ltp":2.24,"tv":7.78,"id":10107989}]}]}
{"op":"mcm","clk":"1002524842","pt":1580644854780,"mc":[{"id":"1.168213437","rc":[{"batb":[[0,2.32,36.86]],"ltp":2.24,"tv":7.78,"id":10107989}]}]}
{"op":"mcm","clk":"1002524968","pt":1580644855934,"mc":[{"id":"1.168213437","rc":[{"batb":[[0,2.32,17.76]],"ltp":2.24,"tv":7.78,"id":10107989}]}]}
{"op":"mcm","clk":"1002525134","pt":1580644857214,"mc":[{"id":"1.168213437","rc":[{"batb":[[0,2.32,36.86]],"ltp":2.24,"tv":7.78,"id":10107989},{"batb":[[0,1.59,30.29],[1,1.58,56.28],[2,1.57,157.72]],"ltp":1.58,"tv":57.76,"id":8444034}]}]}
{"op":"mcm","clk":"1002525223","pt":1580644857807,"mc":[{"id":"1.168213437","rc":[{"batb":[[0,2.32,17.76]],"ltp":2.24,"tv":7.78,"id":10107989}]}]}
{"op":"mcm","clk":"1002525396","pt":1580644858817,"mc":[{"id":"1.168213437","rc":[{"batb":[[0,2.32,36.86]],"ltp":2.24,"tv":7.78,"id":10107989}]}]}
{"op":"mcm","clk":"1002525563","pt":1580644859880,"mc":[{"id":"1.168213437","rc":[{"batb":[[0,2.32,17.76]],"ltp":2.24,"tv":7.78,"id":10107989}]}]}
{"op":"mcm","clk":"1002525676","pt":1580644860784,"mc":[{"id":"1.168213437","rc":[{"batb":[[0,2.32,36.86]],"ltp":2.24,"tv":7.78,"id":10107989}]}]}
{"op":"mcm","clk":"1002525832","pt":1580644861791,"mc":[{"id":"1.168213437","rc":[{"batb":[[0,2.32,17.76]],"ltp":2.24,"tv":7.78,"id":10107989}]}]}
{"op":"mcm","clk":"1002525973","pt":1580644862812,"mc":[{"id":"1.168213437","rc":[{"batb":[[0,2.32,36.86]],"ltp":2.24,"tv":7.78,"id":10107989}]}]}
{"op":"mcm","clk":"1002526106","pt":1580644863815,"mc":[{"id":"1.168213437","rc":[{"batb":[[0,2.32,17.76]],"ltp":2.24,"tv":7.78,"id":10107989}]}]}
{"op":"mcm","clk":"1002526252","pt":1580644864824,"mc":[{"id":"1.168213437","rc":[{"batb":[[0,2.32,36.86]],"ltp":2.24,"tv":7.78,"id":10107989}]}]}
{"op":"mcm","clk":"1002526401","pt":1580644865772,"mc":[{"id":"1.168213437","rc":[{"batb":[[0,2.32,17.76]],"ltp":2.24,"tv":7.78,"id":10107989}]}]}
{"op":"mcm","clk":"1002526535","pt":1580644866828,"mc":[{"id":"1.168213437","rc":[{"batb":[[0,2.32,36.86]],"ltp":2.24,"tv":7.78,"id":10107989}]}]}
{"op":"mcm","clk":"1002533314","pt":1580644918408,"mc":[{"id":"1.168213437","rc":[{"batb":[[0,2.34,17.61],[1,2.32,19.1],[2,2.3,19.39]],"ltp":2.24,"tv":7.78,"id":10107989}]}]}
{"op":"mcm","clk":"1002533375","pt":1580644918840,"mc":[{"id":"1.168213437","rc":[{"batb":[[0,2.34,36.43]],"ltp":2.24,"tv":7.78,"id":10107989}]}]}
{"op":"mcm","clk":"1002542616","pt":1580644978728,"mc":[{"id":"1.168213437","rc":[{"batb":[[0,2.34,18.81]],"ltp":2.24,"tv":7.78,"id":10107989}]}]}
{"op":"mcm","clk":"1002542700","pt":1580644979215,"mc":[{"id":"1.168213437","rc":[{"batb":[[0,2.36,17.46],[1,2.34,18.81],[2,2.32,19.1]],"ltp":2.24,"tv":7.78,"id":10107989}]}]}
{"op":"mcm","clk":"1002543029","pt":1580644980840,"mc":[{"id":"1.168213437","rc":[{"batb":[[0,2.36,36]],"ltp":2.24,"tv":7.78,"id":10107989}]}]}
{"op":"mcm","clk":"1002553012","pt":1580645039613,"mc":[{"id":"1.168213437","rc":[{"batb":[[0,2.36,18.53]],"ltp":2.24,"tv":7.78,"id":10107989}]}]}
{"op":"mcm","clk":"1002553135","pt":1580645040157,"mc":[{"id":"1.168213437","rc":[{"batb":[[0,2.38,17.32],[1,2.36,18.53],[2,2.34,18.81]],"ltp":2.24,"tv":7.78,"id":10107989}]}]}
{"op":"mcm","clk":"1002553496","pt":1580645041938,"mc":[{"id":"1.168213437","rc":[{"batb":[[0,2.38,35.58]],"ltp":2.24,"tv":7.78,"id":10107989}]}]}
{"op":"mcm","clk":"1002562294","pt":1580645100385,"mc":[{"id":"1.168213437","rc":[{"batb":[[0,2.38,18.27]],"ltp":2.24,"tv":7.78,"id":10107989}]}]}
{"op":"mcm","clk":"1002562367","pt":1580645100862,"mc":[{"id":"1.168213437","rc":[{"batb":[[0,2.4,17.17],[1,2.3,19.39],[2,2.26,4.2]],"ltp":2.24,"tv":7.78,"id":10107989}]}]}
{"op":"mcm","clk":"1002562517","pt":1580645101871,"mc":[{"id":"1.168213437","rc":[{"batb":[[0,2.4,35.18]],"ltp":2.24,"tv":7.78,"id":10107989}]}]}
{"op":"mcm","clk":"1002571661","pt":1580645161240,"mc":[{"id":"1.168213437","rc":[{"batb":[[0,2.4,18.01]],"ltp":2.24,"tv":7.78,"id":10107989}]}]}
{"op":"mcm","clk":"1002571761","pt":1580645161919,"mc":[{"id":"1.168213437","rc":[{"batb":[[0,2.42,17.03]],"ltp":2.24,"tv":7.78,"id":10107989}]}]}
{"op":"mcm","clk":"1002571945","pt":1580645162958,"mc":[{"id":"1.168213437","rc":[{"batb":[[0,2.42,34.78]],"ltp":2.24,"tv":7.78,"id":10107989}]}]}
{"op":"mcm","clk":"1002581621","pt":1580645222539,"mc":[{"id":"1.168213437","rc":[{"batb":[[0,2.44,16.89],[1,2.42,17.75],[2,2.3,19.39]],"ltp":2.24,"tv":7.78,"id":10107989}]}]}
{"op":"mcm","clk":"1002581685","pt":1580645222945,"mc":[{"id":"1.168213437","rc":[{"batb":[[0,2.44,34.39]],"ltp":2.24,"tv":7.78,"id":10107989}]}]}
{"op":"mcm","clk":"1002591345","pt":1580645283302,"mc":[{"id":"1.168213437","rc":[{"batb":[[0,2.46,16.75],[1,2.44,17.5],[2,2.42,17.75]],"ltp":2.24,"tv":7.78,"id":10107989}]}]}
{"op":"mcm","clk":"1002591460","pt":1580645283981,"mc":[{"id":"1.168213437","rc":[{"batb":[[1,1.58,12.82]],"ltp":1.58,"tv":57.76,"id":8444034}]}]}
{"op":"mcm","clk":"1002601010","pt":1580645343881,"mc":[{"id":"1.168213437","rc":[{"batb":[[0,1.58,43.11],[1,1.57,157.72],[2,1.51,37.86]],"ltp":1.58,"tv":57.76,"id":8444034}]}]}
{"op":"mcm","clk":"1002631567","pt":1580645539647,"mc":[{"id":"1.168213437","rc":[{"batb":[[0,1.59,1.59],[1,1.58,43.11],[2,1.57,157.72]],"ltp":1.58,"tv":57.76,"id":8444034}]}]}
{"op":"mcm","clk":"1002631675","pt":1580645540231,"mc":[{"id":"1.168213437","rc":[{"batb":[[0,2.48,1.02],[1,2.46,16.75],[2,2.44,17.5]],"ltp":2.24,"tv":7.78,"id":10107989}]}]}
{"op":"mcm","clk":"1002643959","pt":1580645615466,"mc":[{"id":"1.168213437","rc":[{"batl":[[0,1.68,7.5],[1,1.76,106.37],[2,1.8,11.77]],"ltp":1.58,"tv":57.76,"id":8444034}]}]}
{"op":"mcm","clk":"1002644396","pt":1580645618269,"mc":[{"id":"1.168213437","rc":[{"batl":[[0,1.67,7.5]],"ltp":1.58,"tv":57.76,"id":8444034}]}]}
{"op":"mcm","clk":"1002644744","pt":1580645620707,"mc":[{"id":"1.168213437","rc":[{"batl":[[0,1.66,7.5]],"ltp":1.58,"tv":57.76,"id":8444034}]}]}
{"op":"mcm","clk":"1002645219","pt":1580645623175,"mc":[{"id":"1.168213437","rc":[{"batl":[[0,1.65,7.5]],"ltp":1.58,"tv":57.76,"id":8444034}]}]}
{"op":"mcm","clk":"1002645650","pt":1580645625589,"mc":[{"id":"1.168213437","rc":[{"batl":[[0,1.64,7.5]],"ltp":1.58,"tv":57.76,"id":8444034}]}]}
{"op":"mcm","clk":"1002646167","pt":1580645628467,"mc":[{"id":"1.168213437","rc":[{"trd":[[1.63,15]],"batl":[[0,1.76,106.37],[1,1.8,11.77],[2,2.3,15.14]],"ltp":1.63,"tv":72.76,"id":8444034}],"tv":80.55}]}
{"op":"mcm","clk":"1002773349","pt":1580646439266,"mc":[{"id":"1.168213437","rc":[{"batb":[[1,2.46,34.02]],"ltp":2.24,"tv":7.78,"id":10107989},{"batb":[[1,1.58,12.82]],"ltp":1.63,"tv":72.76,"id":8444034}]}]}
{"op":"mcm","clk":"1002782943","pt":1580646499604,"mc":[{"id":"1.168213437","rc":[{"batb":[[1,2.46,17.27]],"ltp":2.24,"tv":7.78,"id":10107989}]}]}
{"op":"mcm","clk":"1002783062","pt":1580646500330,"mc":[{"id":"1.168213437","rc":[{"batb":[[0,2.48,17.63],[1,2.3,19.39],[2,2.26,4.2]],"ltp":2.24,"tv":7.78,"id":10107989}]}]}
{"op":"mcm","clk":"1002783273","pt":1580646501287,"mc":[{"id":"1.168213437","rc":[{"batb":[[0,2.48,34.66]],"ltp":2.24,"tv":7.78,"id":10107989},{"batb":[[2,1.57,113.5]],"ltp":1.63,"tv":72.76,"id":8444034}]}]}
{"op":"mcm","clk":"1002793235","pt":1580646560573,"mc":[{"id":"1.168213437","rc":[{"batb":[[0,2.48,18.05]],"ltp":2.24,"tv":7.78,"id":10107989}]}]}
{"op":"mcm","clk":"1002793320","pt":1580646561098,"mc":[{"id":"1.168213437","rc":[{"batb":[[0,2.5,16.48],[1,2.48,18.05],[2,2.3,19.39]],"ltp":2.24,"tv":7.78,"id":10107989}]}]}
{"op":"mcm","clk":"1002799986","pt":1580646603106,"mc":[{"id":"1.168213437","rc":[{"batb":[[2,2.3,20.13]],"ltp":2.24,"tv":7.78,"id":10107989}]}]}
{"op":"mcm","clk":"1002803233","pt":1580646621284,"mc":[{"id":"1.168213437","rc":[{"batb":[[0,2.52,2],[1,2.5,16.48],[2,2.48,18.05]],"ltp":2.24,"tv":7.78,"id":10107989},{"batb":[[0,1.59,3.59]],"ltp":1.63,"tv":72.76,"id":8444034}]}]}
{"op":"mcm","clk":"1002850136","pt":1580646870982,"mc":[{"id":"1.168213437","rc":[{"trd":[[1.57,93.18],[1.58,77.79],[1.59,7.18]],"batb":[[0,1.57,66.91],[1,1.56,45.01],[2,1.52,1.92]],"ltp":1.57,"tv":198.76,"id":8444034}],"tv":206.55}]}
{"op":"mcm","clk":"1002850982","pt":1580646875293,"mc":[{"id":"1.168213437","rc":[{"batb":[[0,1.57,113.5]],"ltp":1.57,"tv":198.76,"id":8444034}]}]}
{"op":"mcm","clk":"1002854664","pt":1580646893596,"mc":[{"id":"1.168213437","rc":[{"batb":[[0,2.52,2.99],[2,2.48,17.03]],"ltp":2.24,"tv":7.78,"id":10107989}]}]}
{"op":"mcm","clk":"1002921079","pt":1580647220516,"mc":[{"id":"1.168213437","rc":[{"batb":[[0,2.5,17.48],[1,2.48,17.03],[2,2.3,20.13]],"ltp":2.24,"tv":7.78,"id":10107989}]}]}
{"op":"mcm","clk":"1002924415","pt":1580647235912,"mc":[{"id":"1.168213437","rc":[{"batb":[[0,2.52,2.99],[1,2.5,16.48],[2,2.48,17.03]],"ltp":2.24,"tv":7.78,"id":10107989}]}]}
{"op":"mcm","clk":"1002983749","pt":1580647523550,"mc":[{"id":"1.168213437","rc":[{"batb":[[0,1.58,1.6],[1,1.57,113.5],[2,1.56,45.01]],"ltp":1.57,"tv":198.76,"id":8444034}]}]}
{"op":"mcm","clk":"1002986100","pt":1580647535584,"mc":[{"id":"1.168213437","rc":[{"trd":[[2.74,9.33],[2.76,9.59]],"batb":[[1,2.3,20.13],[2,2.26,4.2]],"batl":[[0,4.1,77.99],[1,95,2.27],[2,990,2.2]],"ltp":2.76,"tv":26.7,"id":10107989},{"trd":[[1.57,110.05],[1.58,79.39]],"batb":[[0,1.57,140.85],[1,1.56,45.01],[2,1.52,1.92]],"ltp":1.57,"tv":217.23,"id":8444034}],"tv":243.94}]}
{"op":"mcm","clk":"1002986291","pt":1580647536552,"mc":[{"id":"1.168213437","rc":[{"batb":[[0,1.57,157.72]],"ltp":1.57,"tv":217.23,"id":8444034}]}]}
{"op":"mcm","clk":"1003032753","pt":1580647775584,"mc":[{"id":"1.168213437","rc":[{"batb":[[1,2.48,61.53],[2,2.44,17.5]],"ltp":2.76,"tv":26.7,"id":10107989},{"batb":[[0,1.6,119.83],[1,1.58,43.45],[2,1.57,157.72]],"ltp":1.57,"tv":217.23,"id":8444034}]}]}
{"op":"mcm","clk":"1003033089","pt":1580647777379,"mc":[{"id":"1.168213437","rc":[{"trd":[[1.6,60]],"batb":[[0,1.6,89.83]],"ltp":1.6,"tv":277.23,"id":8444034}],"tv":303.94}]}
{"op":"mcm","clk":"1003034239","pt":1580647783704,"mc":[{"id":"1.168213437","rc":[{"batb":[[1,2.5,62.08],[2,2.46,17.27]],"ltp":2.76,"tv":26.7,"id":10107989},{"batb":[[1,1.57,157.72],[2,1.56,45.01]],"ltp":1.6,"tv":277.23,"id":8444034}]}]}
{"op":"mcm","clk":"1003036088","pt":1580647793633,"mc":[{"id":"1.168213437","rc":[{"batb":[[1,2.48,63.02],[2,2.44,17.5]],"ltp":2.76,"tv":26.7,"id":10107989},{"batb":[[0,1.61,117.47],[1,1.58,43.45],[2,1.57,157.72]],"ltp":1.6,"tv":277.23,"id":8444034}]}]}
{"op":"mcm","clk":"1003043657","pt":1580647835280,"mc":[{"id":"1.168213437","rc":[{"batb":[[0,2.48,64.02],[1,2.44,17.5],[2,2.3,20.13]],"ltp":2.76,"tv":26.7,"id":10107989}]}]}
{"op":"mcm","clk":"1003052636","pt":1580647886664,"mc":[{"id":"1.168213437","rc":[{"trd":[[1.61,0.03]],"batb":[[0,1.61,117.46]],"ltp":1.61,"tv":277.26,"id":8444034}],"tv":303.97}]}
{"op":"mcm","clk":"1003056996","pt":1580647911731,"mc":[{"id":"1.168213437","marketDefinition":{"bspMarket":false,"turnInPlayEnabled":true,"persistenceEnabled":true,"marketBaseRate":5.0,"eventId":"29681204","eventTypeId":"2","numberOfWinners":1,"bettingType":"ODDS","marketType":"MATCH_ODDS","marketTime":"2020-02-02T12:47:00.000Z","suspendTime":"2020-02-02T12:47:00.000Z","bspReconciled":false,"complete":true,"inPlay":false,"crossMatching":true,"runnersVoidable":false,"numberOfActiveRunners":2,"betDelay":0,"status":"OPEN","runners":[{"status":"ACTIVE","sortPriority":1,"id":8444034,"name":"Golubev/Nedovyesov"},{"status":"ACTIVE","sortPriority":2,"id":10107989,"name":"Sabanov/Sabanov"}],"regulators":["MR_INT"],"countryCode":"FR","discountAllowed":true,"timezone":"UTC","openDate":"2020-02-02T13:00:00.000Z","version":3148783603,"name":"Match Odds","eventName":"Golubev/Nedovyesov v Sabanov/Sabanov"}}]}
{"op":"mcm","clk":"1003057552","pt":1580647914747,"mc":[{"id":"1.168213437","marketDefinition":{"bspMarket":false,"turnInPlayEnabled":true,"persistenceEnabled":true,"marketBaseRate":5.0,"eventId":"29681204","eventTypeId":"2","numberOfWinners":1,"bettingType":"ODDS","marketType":"MATCH_ODDS","marketTime":"2020-02-02T12:47:00.000Z","suspendTime":"2020-02-02T12:47:00.000Z","bspReconciled":false,"complete":true,"inPlay":false,"crossMatching":true,"runnersVoidable":false,"numberOfActiveRunners":2,"betDelay":0,"status":"OPEN","runners":[{"status":"ACTIVE","sortPriority":1,"id":8444034,"name":"Golubev/Nedovyesov"},{"status":"ACTIVE","sortPriority":2,"id":10107989,"name":"Sabanov/Sabanov"}],"regulators":["MR_INT"],"countryCode":"FR","discountAllowed":true,"timezone":"UTC","openDate":"2020-02-02T12:47:00.000Z","version":3148783603,"name":"Match Odds","eventName":"Golubev/Nedovyesov v Sabanov/Sabanov"}}]}
{"op":"mcm","clk":"1003058580","pt":1580647920611,"mc":[{"id":"1.168213437","rc":[{"batl":[[0,1.65,30],[1,1.76,106.37],[2,1.8,11.77]],"ltp":1.61,"tv":277.26,"id":8444034}]}]}
{"op":"mcm","clk":"1003058764","pt":1580647921626,"mc":[{"id":"1.168213437","rc":[{"batb":[[1,2.46,17.27],[2,2.44,17.5]],"ltp":2.76,"tv":26.7,"id":10107989},{"batb":[[1,1.57,157.72],[2,1.56,45.01]],"ltp":1.61,"tv":277.26,"id":8444034}]}]}
{"op":"mcm","clk":"1003065611","pt":1580647963463,"mc":[{"id":"1.168213437","rc":[{"batb":[[0,1.61,117.47]],"ltp":1.61,"tv":277.26,"id":8444034}]}]}
{"op":"mcm","clk":"1003074870","pt":1580648020560,"mc":[{"id":"1.168213437","rc":[{"batl":[[1,1.72,15],[2,1.76,106.37]],"ltp":1.61,"tv":277.26,"id":8444034}]}]}
{"op":"mcm","clk":"1003081157","pt":1580648060875,"mc":[{"id":"1.168213437","rc":[{"trd":[[1.61,6.11]],"batb":[[0,1.61,114.43]],"ltp":1.61,"tv":283.34,"id":8444034}],"tv":310.05}]}
{"op":"mcm","clk":"1003086654","pt":1580648095288,"mc":[{"id":"1.168213437","rc":[{"trd":[[1.61,8.78]],"batb":[[0,1.61,113.1]],"ltp":1.61,"tv":286.01,"id":8444034}],"tv":312.72}]}
{"op":"mcm","clk":"1003088468","pt":1580648105485,"mc":[{"id":"1.168213437","rc":[{"trd":[[1.61,8.8]],"batb":[[0,1.61,113.08]],"ltp":1.61,"tv":286.03,"id":8444034}],"tv":312.74}]}
{"op":"mcm","clk":"1003122031","pt":1580648299738,"mc":[{"id":"1.168213437","rc":[{"batb":[[0,2.5,63.23],[1,2.48,63.02],[2,2.46,17.27]],"ltp":2.76,"tv":26.7,"id":10107989},{"trd":[[1.61,112.62]],"batb":[[0,1.61,61.17],[1,1.6,118.65],[2,1.57,157.72]],"ltp":1.61,"tv":389.86,"id":8444034}],"tv":416.56}]}
{"op":"mcm","clk":"1003122077","pt":1580648300051,"mc":[{"id":"1.168213437","rc":[{"batb":[[1,2.46,17.27],[2,2.44,17.5]],"ltp":2.76,"tv":26.7,"id":10107989},{"batb":[[0,1.6,118.67],[1,1.57,157.72],[2,1.56,45.01]],"ltp":1.61,"tv":389.86,"id":8444034}]}]}
{"op":"mcm","clk":"1003168208","pt":1580648568602,"mc":[{"id":"1.168213437","rc":[{"batb":[[0,2.46,18.26],[1,2.44,17.5],[2,2.3,20.13]],"ltp":2.76,"tv":26.7,"id":10107989},{"batb":[[0,1.57,157.73],[1,1.56,45.01],[2,1.52,1.92]],"ltp":1.61,"tv":389.86,"id":8444034}]}]}
{"op":"mcm","clk":"1003168303","pt":1580648569134,"mc":[{"id":"1.168213437","marketDefinition":{"bspMarket":false,"turnInPlayEnabled":true,"persistenceEnabled":true,"marketBaseRate":5.0,"eventId":"29681204","eventTypeId":"2","numberOfWinners":1,"bettingType":"ODDS","marketType":"MATCH_ODDS","marketTime":"2020-02-02T12:47:00.000Z","suspendTime":"2020-02-02T12:47:00.000Z","bspReconciled":false,"complete":true,"inPlay":true,"crossMatching":true,"runnersVoidable":false,"numberOfActiveRunners":2,"betDelay":3,"status":"OPEN","runners":[{"status":"ACTIVE","sortPriority":1,"id":8444034,"name":"Golubev/Nedovyesov"},{"status":"ACTIVE","sortPriority":2,"id":10107989,"name":"Sabanov/Sabanov"}],"regulators":["MR_INT"],"countryCode":"FR","discountAllowed":true,"timezone":"UTC","openDate":"2020-02-02T12:47:00.000Z","version":3148851643,"name":"Match Odds","eventName":"Golubev/Nedovyesov v Sabanov/Sabanov"},"rc":[{"batb":[[0,1.11,37.97],[1,1.03,9],[2,1.02,25.41]],"batl":[[0,1000,0.02],[1,95,0],[2,990,0]],"ltp":2.76,"tv":26.7,"id":10107989},{"batb":[[0,1.11,37.99],[1,1.03,9],[2,1.02,25.41]],"batl":[[0,1000,0.02],[1,1.72,0],[2,1.76,0]],"ltp":1.61,"tv":389.86,"id":8444034}]}]}
{"op":"mcm","clk":"1003171573","pt":1580648586356,"mc":[{"id":"1.168213437","rc":[{"batb":[[0,2.4,70.74],[1,2.3,78.76],[2,1.11,37.97]],"ltp":2.76,"tv":26.7,"id":10107989},{"batb":[[0,1.65,106.14],[1,1.57,126.77],[2,1.11,37.97]],"ltp":1.61,"tv":389.86,"id":8444034}]}]}
{"op":"mcm","clk":"1003172797","pt":1580648592505,"mc":[{"id":"1.168213437","rc":[{"batb":[[0,2.3,78.76],[1,1.11,37.97],[2,1.03,9]],"ltp":2.76,"tv":26.7,"id":10107989},{"batb":[[0,1.57,126.77],[1,1.11,37.97],[2,1.03,9]],"ltp":1.61,"tv":389.86,"id":8444034}]}]}
{"op":"mcm","clk":"1003176203","pt":1580648610517,"mc":[{"id":"1.168213437","rc":[{"batb":[[0,2.6,57.67],[1,2.44,67.43],[2,1.11,37.97]],"ltp":2.76,"tv":26.7,"id":10107989},{"batb":[[1,1.49,158.23],[2,1.11,37.97]],"ltp":1.61,"tv":389.86,"id":8444034}]}]}
{"op":"mcm","clk":"1003179033","pt":1580648625068,"mc":[{"id":"1.168213437","rc":[{"batb":[[0,1.58,4.52],[1,1.57,126.76],[2,1.49,158.23]],"ltp":1.61,"tv":389.86,"id":8444034}]}]}
{"op":"mcm","clk":"1003179288","pt":1580648626271,"mc":[{"id":"1.168213437","rc":[{"batb":[[0,2.44,67.43],[1,1.11,37.97],[2,1.03,9]],"ltp":2.76,"tv":26.7,"id":10107989},{"batb":[[1,1.49,158.23],[2,1.11,37.97]],"ltp":1.61,"tv":389.86,"id":8444034}]}]}
{"op":"mcm","clk":"1003179708","pt":1580648628252,"mc":[{"id":"1.168213437","rc":[{"batl":[[0,1.62,3],[1,1000,0.02]],"ltp":1.61,"tv":389.86,"id":8444034}]}]}
{"op":"mcm","clk":"1003181577","pt":1580648637732,"mc":[{"id":"1.168213437","rc":[{"trd":[[2.6,1.87]],"ltp":2.6,"tv":28.57,"id":10107989},{"trd":[[1.62,3]],"batl":[[0,1000,0.02],[1,1000,0]],"ltp":1.62,"tv":392.86,"id":8444034}],"tv":421.43}]}
{"op":"mcm","clk":"1003181777","pt":1580648638658,"mc":[{"id":"1.168213437","rc":[{"batb":[[1,2.32,77.66],[2,1.11,37.97]],"ltp":2.6,"tv":28.57,"id":10107989},{"batb":[[0,1.63,110.71],[1,1.58,4.52],[2,1.55,133.92]],"ltp":1.62,"tv":392.86,"id":8444034}]}]}
{"op":"mcm","clk":"1003184819","pt":1580648655212,"mc":[{"id":"1.168213437","rc":[{"batb":[[0,2.32,77.66],[1,1.11,37.97],[2,1.03,9]],"ltp":2.6,"tv":28.57,"id":10107989},{"batb":[[0,1.58,4.52],[1,1.55,133.92],[2,1.11,37.97]],"ltp":1.62,"tv":392.86,"id":8444034}]}]}
{"op":"mcm","clk":"1003187131","pt":1580648668626,"mc":[{"id":"1.168213437","rc":[{"trd":[[2.32,155.31]],"batb":[[0,1.11,37.97],[1,1.03,9],[2,1.02,25.41]],"batl":[[0,2.2,67.79],[1,2.66,5.49],[2,1000,0.02]],"ltp":2.32,"tv":183.88,"id":10107989},{"batl":[[0,1.92,12.84],[1,1.96,157.55],[2,1000,0.02]],"ltp":1.62,"tv":392.86,"id":8444034}],"tv":576.74}]}
{"op":"mcm","clk":"1003187289","pt":1580648669648,"mc":[{"id":"1.168213437","rc":[{"trd":[[2.2,135.58]],"batb":[[0,2.24,17.1],[1,1.11,37.97],[2,1.03,9]],"batl":[[0,1000,0.02],[1,2.66,0],[2,1000,0]],"ltp":2.2,"tv":319.47,"id":10107989},{"batb":[[0,1.69,97.57],[1,1.62,112.59],[2,1.58,4.52]],"ltp":1.62,"tv":392.86,"id":8444034}],"tv":712.33}]}
{"op":"mcm","clk":"1003189023","pt":1580648678730,"mc":[{"id":"1.168213437","rc":[{"batb":[[1,1.3,756.19],[2,1.11,37.96]],"ltp":2.2,"tv":319.47,"id":10107989},{"batl":[[0,1.96,157.55],[1,1000,0.02],[2,1000,0]],"ltp":1.62,"tv":392.86,"id":8444034}]}]}
{"op":"mcm","clk":"1003189702","pt":1580648682515,"mc":[{"id":"1.168213437","rc":[{"trd":[[2.24,27.86]],"batb":[[0,2.24,5.17]],"ltp":2.24,"tv":343.33,"id":10107989},{"batl":[[0,1.89,15.23],[1,1.96,157.55],[2,1000,0.02]],"ltp":1.62,"tv":392.86,"id":8444034}],"tv":736.19}]}
{"op":"mcm","clk":"1003190261","pt":1580648685719,"mc":[{"id":"1.168213437","rc":[{"batl":[[0,1000,0.02],[1,1.96,0],[2,1000,0]],"ltp":1.62,"tv":392.86,"id":8444034}]}]}
{"op":"mcm","clk":"1003190308","pt":1580648686041,"mc":[{"id":"1.168213437","rc":[{"batb":[[0,1.62,112.59],[1,1.58,4.52],[2,1.2,756.29]],"ltp":1.62,"tv":392.86,"id":8444034}]}]}
{"op":"mcm","clk":"1003190926","pt":1580648689427,"mc":[{"id":"1.168213437","rc":[{"batb":[[0,2.18,89.07]],"ltp":2.24,"tv":343.33,"id":10107989},{"batb":[[0,1.67,107.87]],"ltp":1.62,"tv":392.86,"id":8444034}]}]}
{"op":"mcm","clk":"1003191491","pt":1580648692435,"mc":[{"id":"1.168213437","rc":[{"batb":[[2,1.2,189.41]],"ltp":2.24,"tv":343.33,"id":10107989},{"batb":[[2,1.2,945.59]],"ltp":1.62,"tv":392.86,"id":8444034}]}]}
{"op":"mcm","clk":"1003191804","pt":1580648694236,"mc":[{"id":"1.168213437","rc":[{"trd":[[2.18,178.13]],"batb":[[0,1.3,756.19],[1,1.2,189.41],[2,1.11,37.86]],"batl":[[0,2.16,88.48],[1,1000,0.02]],"ltp":2.18,"tv":521.45,"id":10107989},{"batl":[[0,1.98,120.02],[1,1000,0.02]],"ltp":1.62,"tv":392.86,"id":8444034}],"tv":914.31}]}
{"op":"mcm","clk":"1003192018","pt":1580648695411,"mc":[{"id":"1.168213437","rc":[{"batb":[[0,2.02,110.71],[1,1.3,756.19],[2,1.2,189.41]],"ltp":2.18,"tv":521.45,"id":10107989},{"batb":[[0,1.79,86.08],[1,1.73,95.83],[2,1.58,4.52]],"ltp":1.62,"tv":392.86,"id":8444034}]}]}
{"op":"mcm","clk":"1003192349","pt":1580648697222,"mc":[{"id":"1.168213437","rc":[{"batl":[[0,2.16,105.79]],"ltp":2.18,"tv":521.45,"id":10107989},{"batl":[[0,1.92,8.92],[1,1.98,120.02],[2,1000,0.02]],"ltp":1.62,"tv":392.86,"id":8444034}]}]}
{"op":"mcm","clk":"1003192699","pt":1580648698930,"mc":[{"id":"1.168213437","rc":[{"trd":[[2.16,28.56]],"batl":[[0,2.16,91.51]],"ltp":2.16,"tv":550.01,"id":10107989}],"tv":942.87}]}
{"op":"mcm","clk":"1003193313","pt":1580648702123,"mc":[{"id":"1.168213437","rc":[{"trd":[[2.16,57.12]],"batl":[[0,2.16,77.23]],"ltp":2.16,"tv":578.57,"id":10107989}],"tv":971.43}]}
{"op":"mcm","clk":"1003193585","pt":1580648703681,"mc":[{"id":"1.168213437","rc":[{"trd":[[2.16,209.86]],"batb":[[0,2.16,15.91],[1,2,113.54],[2,1.3,756.19]],"batl":[[0,1000,0.02],[1,1000,0]],"ltp":2.16,"tv":731.32,"id":10107989},{"trd":[[1.86,2]],"batb":[[0,1.8,84.03],[1,1.74,93.63]],"batl":[[0,1.86,2],[1,1.92,8.92],[2,1.98,120.02]],"ltp":1.86,"tv":394.86,"id":8444034}],"tv":1126.18}]}
{"op":"mcm","clk":"1003193759","pt":1580648704676,"mc":[{"id":"1.168213437","rc":[{"batl":[[0,1.86,6],[1,1.98,120.02],[2,1000,0.02]],"ltp":1.86,"tv":394.86,"id":8444034}]}]}
{"op":"mcm","clk":"1003193936","pt":1580648705584,"mc":[{"id":"1.168213437","rc":[{"batl":[[0,1.86,2]],"ltp":1.86,"tv":394.86,"id":8444034}]}]}
{"op":"mcm","clk":"1003194115","pt":1580648706462,"mc":[{"id":"1.168213437","rc":[{"batb":[[2,1.4,75.73]],"ltp":2.16,"tv":731.32,"id":10107989},{"batl":[[0,1.98,120.02],[1,1000,0.02],[2,1000,0]],"ltp":1.86,"tv":394.86,"id":8444034}]}]}
{"op":"mcm","clk":"1003194256","pt":1580648707169,"mc":[{"id":"1.168213437","rc":[{"batl":[[0,2.24,8.18],[1,1000,0.02]],"ltp":2.16,"tv":731.32,"id":10107989},{"batl":[[0,1.86,19.2],[1,1.98,120.02],[2,1000,0.02]],"ltp":1.86,"tv":394.86,"id":8444034}]}]}
{"op":"mcm","clk":"1003194713","pt":1580648709772,"mc":[{"id":"1.168213437","rc":[{"batb":[[2,1.5,75.72]],"ltp":2.16,"tv":731.32,"id":10107989}]}]}
{"op":"mcm","clk":"1003195003","pt":1580648711364,"mc":[{"id":"1.168213437","rc":[{"batb":[[0,2.14,93.32],[1,1.99,115.9]],"ltp":2.16,"tv":731.32,"id":10107989},{"batb":[[0,1.81,82.38],[1,1.75,91.82]],"ltp":1.86,"tv":394.86,"id":8444034}]}]}
{"op":"mcm","clk":"1003195393","pt":1580648713585,"mc":[{"id":"1.168213437","rc":[{"batl":[[0,1000,0.02],[1,1000,0]],"ltp":2.16,"tv":731.32,"id":10107989},{"batl":[[0,1.98,120.02],[1,1000,0.02],[2,1000,0]],"ltp":1.86,"tv":394.86,"id":8444034}]}]}
{"op":"mcm","clk":"1003195494","pt":1580648714107,"mc":[{"id":"1.168213437","rc":[{"batl":[[0,1.86,13.78],[1,1.98,120.02],[2,1000,0.02]],"ltp":1.86,"tv":394.86,"id":8444034}]}]}
{"op":"mcm","clk":"1003195891","pt":1580648716271,"mc":[{"id":"1.168213437","rc":[{"batl":[[0,2.24,8.18],[1,1000,0.02]],"ltp":2.16,"tv":731.32,"id":10107989},{"batl":[[0,1.86,32.98]],"ltp":1.86,"tv":394.86,"id":8444034}]}]}
{"op":"mcm","clk":"1003197357","pt":1580648724284,"mc":[{"id":"1.168213437","rc":[{"batl":[[0,1.86,19.2]],"ltp":1.86,"tv":394.86,"id":8444034}]}]}
{"op":"mcm","clk":"1003197913","pt":1580648727420,"mc":[{"id":"1.168213437","rc":[{"batl":[[1,1.87,13.78],[2,1.98,120.02]],"ltp":1.86,"tv":394.86,"id":8444034}]}]}
{"op":"mcm","clk":"1003198612","pt":1580648731495,"mc":[{"id":"1.168213437","rc":[{"batb":[[0,2.16,3.21],[1,2.14,93.32],[2,1.99,115.9]],"ltp":2.16,"tv":731.32,"id":10107989}]}]}
{"op":"mcm","clk":"1003199170","pt":1580648734457,"mc":[{"id":"1.168213437","rc":[{"trd":[[1.86,40.4]],"batb":[[0,1.86,56.52],[1,1.81,82.38],[2,1.75,91.82]],"batl":[[0,1.87,13.78],[1,1.98,120.02],[2,1000,0.02]],"ltp":1.86,"tv":433.26,"id":8444034}],"tv":1164.58}]}
{"op":"mcm","clk":"1003199320","pt":1580648735311,"mc":[{"id":"1.168213437","rc":[{"trd":[[1.86,46.82]],"batb":[[0,1.81,82.38],[1,1.75,91.82],[2,1.58,4.52]],"ltp":1.86,"tv":439.68,"id":8444034}],"tv":1171.0}]}
{"op":"mcm","clk":"1003199889","pt":1580648738449,"mc":[{"id":"1.168213437","rc":[{"batb":[[0,1.82,3.28],[1,1.81,82.38],[2,1.75,91.82]],"ltp":1.86,"tv":439.68,"id":8444034}]}]}
{"op":"mcm","clk":"1003200192","pt":1580648740317,"mc":[{"id":"1.168213437","rc":[{"batb":[[0,1.81,82.38],[1,1.75,91.82],[2,1.58,4.52]],"ltp":1.86,"tv":439.68,"id":8444034}]}]}
{"op":"mcm","clk":"1003200735","pt":1580648743434,"mc":[{"id":"1.168213437","rc":[{"batb":[[1,1.75,95.1]],"ltp":1.86,"tv":439.68,"id":8444034}]}]}
{"op":"mcm","clk":"1003200910","pt":1580648744438,"mc":[{"id":"1.168213437","rc":[{"batb":[[1,1.99,115.9],[2,1.5,75.72]],"batl":[[0,1000,0.02],[1,1000,0]],"ltp":2.16,"tv":731.32,"id":10107989},{"batb":[[0,1.75,95.1],[1,1.58,4.52],[2,1.4,75.73]],"batl":[[1,1000,0.02],[2,1000,0]],"ltp":1.86,"tv":439.68,"id":8444034}]}]}
{"op":"mcm","clk":"1003201488","pt":1580648747627,"mc":[{"id":"1.168213437","rc":[{"batb":[[1,2,114.88]],"ltp":2.16,"tv":731.32,"id":10107989}]}]}
{"op":"mcm","clk":"1003201533","pt":1580648747852,"mc":[{"id":"1.168213437","rc":[{"batb":[[0,1.75,91.82]],"ltp":1.86,"tv":439.68,"id":8444034}]}]}
{"op":"mcm","clk":"1003202238","pt":1580648751648,"mc":[{"id":"1.168213437","rc":[{"batb":[[1,1.62,3.28],[2,1.58,4.52]],"batl":[[0,1.84,7.87],[1,1.87,13.78],[2,1000,0.02]],"ltp":1.86,"tv":439.68,"id":8444034}]}]}
{"op":"mcm","clk":"1003202418","pt":1580648752659,"mc":[{"id":"1.168213437","rc":[{"batb":[[0,2.24,82.3],[1,2.16,3.21],[2,2.08,100.63]],"ltp":2.16,"tv":731.32,"id":10107989},{"batb":[[0,1.76,159.08],[1,1.75,91.82],[2,1.7,102.37]],"batl":[[0,1.8,7.9],[1,1.86,178.66],[2,1.87,13.78]],"ltp":1.86,"tv":439.68,"id":8444034}]}]}
{"op":"mcm","clk":"1003203054","pt":1580648756136,"mc":[{"id":"1.168213437","rc":[{"batl":[[2,1000,0.02]],"ltp":1.86,"tv":439.68,"id":8444034}]}]}
{"op":"mcm","clk":"1003203328","pt":1580648757732,"mc":[{"id":"1.168213437","rc":[{"batl":[[1,1.86,156.25]],"ltp":1.86,"tv":439.68,"id":8444034}]}]}
{"op":"mcm","clk":"1003203380","pt":1580648758043,"mc":[{"id":"1.168213437","rc":[{"trd":[[1.76,47.38]],"batb":[[0,1.76,135.39]],"ltp":1.76,"tv":487.06,"id":8444034}],"tv":1218.38}]}
{"op":"mcm","clk":"1003203605","pt":1580648759318,"mc":[{"id":"1.168213437","rc":[{"batl":[[2,1.88,13.78]],"ltp":1.76,"tv":487.06,"id":8444034}]}]}
{"op":"mcm","clk":"1003205264","pt":1580648768679,"mc":[{"id":"1.168213437","rc":[{"batb":[[0,2.16,3.21],[1,2.08,100.63],[2,1.6,75.72]],"ltp":2.16,"tv":731.32,"id":10107989},{"batb":[[0,1.7,102.37],[1,1.62,3.28],[2,1.58,4.52]],"batl":[[0,1.88,13.78],[1,1000,0.02],[2,1.88,0]],"ltp":1.76,"tv":487.06,"id":8444034}]}]}
{"op":"mcm","clk":"1003205280","pt":1580648768763,"mc":[{"id":"1.168213437","rc":[{"batb":[[0,1.7,101.89]],"ltp":1.76,"tv":487.06,"id":8444034}]}]}
{"op":"mcm","clk":"1003208265","pt":1580648784557,"mc":[{"id":"1.168213437","rc":[{"batl":[[0,2.42,96.72],[1,2.46,9.05],[2,1000,0.02]],"ltp":2.16,"tv":731.32,"id":10107989},{"batl":[[0,1.72,11.65],[1,1.8,193.14],[2,1.83,7.93]],"ltp":1.76,"tv":487.06,"id":8444034}]}]}
{"op":"mcm","clk":"1003208487","pt":1580648785651,"mc":[{"id":"1.168213437","rc":[{"batb":[[0,2.32,74.04],[1,2.18,87.34],[2,2.16,3.21]],"ltp":2.16,"tv":731.32,"id":10107989},{"batb":[[1,1.66,109.92],[2,1.62,3.28]],"batl":[[2,1.88,13.78]],"ltp":1.76,"tv":487.06,"id":8444034}]}]}
{"op":"mcm","clk":"1003208767","pt":1580648787071,"mc":[{"id":"1.168213437","rc":[{"batl":[[2,2.16,342.82]],"ltp":1.76,"tv":487.06,"id":8444034}]}]}
{"op":"mcm","clk":"1003209392","pt":1580648790275,"mc":[{"id":"1.168213437","rc":[{"batl":[[2,1.86,13.78]],"ltp":1.76,"tv":487.06,"id":8444034}]}]}
{"op":"mcm","clk":"1003211402","pt":1580648800696,"mc":[{"id":"1.168213437","rc":[{"batl":[[0,1000,0.02],[1,2.46,0],[2,1000,0]],"ltp":2.16,"tv":731.32,"id":10107989},{"batl":[[0,1.86,13.78],[1,2.16,342.82],[2,1000,0.02]],"ltp":1.76,"tv":487.06,"id":8444034}]}]}
{"op":"mcm","clk":"1003211497","pt":1580648801183,"mc":[{"id":"1.168213437","rc":[{"batb":[[0,2.18,87.34],[1,2.16,3.21],[2,1.7,75.72]],"ltp":2.16,"tv":731.32,"id":10107989},{"batb":[[0,1.66,109.92],[1,1.62,3.28],[2,1.58,4.52]],"ltp":1.76,"tv":487.06,"id":8444034}]}]}
{"op":"mcm","clk":"1003213122","pt":1580648809629,"mc":[{"id":"1.168213437","rc":[{"batb":[[0,2.4,67.9],[1,2.28,77.5],[2,2.18,87.34]],"batl":[[0,2.56,10.75],[1,1000,0.02]],"ltp":2.16,"tv":731.32,"id":10107989},{"batb":[[0,1.66,277.04],[1,1.63,116.69],[2,1.62,3.28]],"batl":[[0,1.68,13.46],[1,1.74,133.88],[2,1.86,13.78]],"ltp":1.76,"tv":487.06,"id":8444034}]}]}
{"op":"mcm","clk":"1003213167","pt":1580648809945,"mc":[{"id":"1.168213437","rc":[{"batb":[[2,2.16,3.21]],"ltp":2.16,"tv":731.32,"id":10107989}]}]}
{"op":"mcm","clk":"1003214941","pt":1580648819355,"mc":[{"id":"1.168213437","rc":[{"batb":[[0,2.28,77.5],[1,2.16,3.21],[2,1.7,75.72]],"batl":[[0,1000,0.02],[1,1000,0]],"ltp":2.16,"tv":731.32,"id":10107989},{"trd":[[1.66,88]],"batb":[[0,1.63,116.69],[1,1.62,3.28],[2,1.58,4.52]],"batl":[[0,1.86,13.78],[1,2.16,342.82],[2,1000,0.02]],"ltp":1.66,"tv":575.06,"id":8444034}],"tv":1306.38}]}
{"op":"mcm","clk":"1003216310","pt":1580648826426,"mc":[{"id":"1.168213437","rc":[{"batl":[[0,2.6,102.8],[1,2.66,12.28],[2,1000,0.02]],"ltp":2.16,"tv":731.32,"id":10107989},{"batl":[[0,1.64,11.54],[1,1.7,140.9],[2,1.86,13.78]],"ltp":1.66,"tv":575.06,"id":8444034}]}]}
{"op":"mcm","clk":"1003216510","pt":1580648827441,"mc":[{"id":"1.168213437","rc":[{"batb":[[0,2.46,62.87],[1,2.34,71.92],[2,2.16,3.21]],"ltp":2.16,"tv":731.32,"id":10107989}]}]}
{"op":"mcm","clk":"1003217493","pt":1580648833226,"mc":[{"id":"1.168213437","rc":[{"batb":[[1,1.58,4.52],[2,1.54,143.99]],"ltp":1.66,"tv":575.06,"id":8444034}]}]}
{"op":"mcm","clk":"1003218061","pt":1580648836367,"mc":[{"id":"1.168213437","rc":[{"trd":[[1.64,6.56]],"batl":[[0,1.64,8.26]],"ltp":1.64,"tv":581.62,"id":8444034}],"tv":1312.94}]}
{"op":"mcm","clk":"1003219896","pt":1580648846532,"mc":[{"id":"1.168213437","rc":[{"batl":[[1,1000,0.02],[2,1000,0]],"ltp":2.16,"tv":731.32,"id":10107989},{"batl":[[0,1.7,140.9],[1,1.86,13.78],[2,2.16,342.82]],"ltp":1.64,"tv":581.62,"id":8444034}]}]}
{"op":"mcm","clk":"1003220438","pt":1580648849483,"mc":[{"id":"1.168213437","rc":[{"batb":[[0,2.56,5.82],[1,2.46,62.87],[2,2.34,71.92]],"batl":[[1,2.66,14.31],[2,1000,0.02]],"ltp":2.16,"tv":731.32,"id":10107989}]}]}
{"op":"mcm","clk":"1003221404","pt":1580648854690,"mc":[{"id":"1.168213437","rc":[{"batb":[[0,2.34,71.92],[1,2.16,3.21],[2,1.8,75.72]],"batl":[[0,1000,0.02],[1,2.66,0],[2,1000,0]],"ltp":2.16,"tv":731.32,"id":10107989},{"batb":[[0,1.58,4.52],[1,1.54,143.99],[2,1.44,436.19]],"batl":[[0,1.86,13.78],[1,2.16,342.82],[2,1000,0.02]],"ltp":1.64,"tv":581.62,"id":8444034}]}]}
{"op":"mcm","clk":"1003225076","pt":1580648874828,"mc":[{"id":"1.168213437","rc":[{"batb":[[2,1.3,75.73]],"batl":[[1,1000,0.02],[2,1000,0]],"ltp":1.64,"tv":581.62,"id":8444034}]}]}
{"op":"mcm","clk":"1003225439","pt":1580648876716,"mc":[{"id":"1.168213437","rc":[{"batb":[[0,2.7,49.49],[1,2.52,59.09],[2,2.34,71.92]],"batl":[[0,2.92,152.74],[1,1000,0.02]],"ltp":2.16,"tv":731.32,"id":10107989},{"trd":[[1.58,88.39],[1.61,112.66]],"batb":[[0,1.54,143.99],[1,1.45,185.38],[2,1.25,378.62]],"batl":[[0,1.56,15.23],[1,1.66,507.67],[2,1.86,13.78]],"ltp":1.58,"tv":590.65,"id":8444034}],"tv":1321.97}]}
{"op":"mcm","clk":"1003225478","pt":1580648876931,"mc":[{"id":"1.168213437","rc":[{"batb":[[2,2.16,3.21]],"ltp":2.16,"tv":731.32,"id":10107989}]}]}
{"op":"mcm","clk":"1003225908","pt":1580648879201,"mc":[{"id":"1.168213437","rc":[{"batb":[[2,1.38,448.45]],"batl":[[2,2.04,383.01]],"ltp":1.58,"tv":590.65,"id":8444034}]}]}
{"op":"mcm","clk":"1003227191","pt":1580648886045,"mc":[{"id":"1.168213437","rc":[{"batl":[[0,2.92,142.07]],"ltp":2.16,"tv":731.32,"id":10107989},{"batl":[[0,1.66,507.67],[1,2.04,383.01],[2,1000,0.02]],"ltp":1.58,"tv":590.65,"id":8444034}]}]}
{"op":"mcm","clk":"1003227802","pt":1580648889052,"mc":[{"id":"1.168213437","rc":[{"batl":[[0,2.88,7],[1,2.92,142.07],[2,1000,0.02]],"ltp":2.16,"tv":731.32,"id":10107989},{"trd":[[1.54,6.08]],"batb":[[0,1.54,140.95]],"batl":[[0,1.56,15.17],[1,1.66,507.67],[2,2.04,383.01]],"ltp":1.54,"tv":596.73,"id":8444034}],"tv":1328.05}]}
{"op":"mcm","clk":"1003228116","pt":1580648890648,"mc":[{"id":"1.168213437","rc":[{"batb":[[0,2.52,59.09],[1,2.16,3.21],[2,1.8,75.72]],"batl":[[0,1000,0.02],[1,2.92,0],[2,1000,0]],"ltp":2.16,"tv":731.32,"id":10107989},{"batb":[[0,1.45,185.38],[1,1.38,448.45],[2,1.25,378.62]],"batl":[[0,2.04,383.01],[1,1000,0.02],[2,2.04,0]],"ltp":1.54,"tv":596.73,"id":8444034}]}]}
{"op":"mcm","clk":"1003228652","pt":1580648893328,"mc":[{"id":"1.168213437","rc":[{"batl":[[0,2.78,2],[1,1000,0.02]],"ltp":2.16,"tv":731.32,"id":10107989}]}]}
{"op":"mcm","clk":"1003228817","pt":1580648894144,"mc":[{"id":"1.168213437","rc":[{"batl":[[0,1000,0.02],[1,1000,0]],"ltp":2.16,"tv":731.32,"id":10107989}]}]}
{"op":"mcm","clk":"1003230967","pt":1580648905667,"mc":[{"id":"1.168213437","rc":[{"trd":[[3.1,0.01],[3.25,0.11]],"ltp":3.25,"tv":731.44,"id":10107989},{"trd":[[1.45,0.24],[1.48,0.01]],"batb":[[0,1.45,185.13]],"ltp":1.45,"tv":596.99,"id":8444034}],"tv":1328.43}]}
{"op":"mcm","clk":"1003231266","pt":1580648907264,"mc":[{"id":"1.168213437","rc":[{"batb":[[1,1.25,378.62],[2,1.2,945.58]],"batl":[[0,1000,0.02],[1,1000,0]],"ltp":1.45,"tv":596.99,"id":8444034}]}]}
{"op":"mcm","clk":"1003231528","pt":1580648908654,"mc":[{"id":"1.168213437","rc":[{"batl":[[0,1.49,2162.8],[1,1.57,9.76],[2,1000,0.02]],"ltp":1.45,"tv":596.99,"id":8444034}]}]}
{"op":"mcm","clk":"1003231689","pt":1580648909549,"mc":[{"id":"1.168213437","rc":[{"batb":[[0,3.15,7.45],[1,3,91.51],[2,2.96,2.65]],"batl":[[0,3.25,4.75],[1,3.3,109.42],[2,1000,0.02]],"ltp":3.25,"tv":731.44,"id":10107989},{"batb":[[0,1.45,187.78],[1,1.36,241.87]],"batl":[[0,1.58,761.33],[1,1000,0.02],[2,1000,0]],"ltp":1.45,"tv":596.99,"id":8444034}]}]}
{"op":"mcm","clk":"1003232003","pt":1580648911394,"mc":[{"id":"1.168213437","rc":[{"batb":[[2,1.31,477.51]],"batl":[[1,1.89,435.28],[2,1000,0.02]],"ltp":1.45,"tv":596.99,"id":8444034}]}]}
{"op":"mcm","clk":"1003234157","pt":1580648923377,"mc":[{"id":"1.168213437","rc":[{"batb":[[0,3,91.51],[1,2.96,2.65],[2,2.82,43.98]],"batl":[[0,1000,0.02],[1,3.3,0],[2,1000,0]],"ltp":3.25,"tv":731.44,"id":10107989},{"batl":[[0,1.89,435.28],[1,1000,0.02],[2,1000,0]],"ltp":1.45,"tv":596.99,"id":8444034}]}]}
{"op":"mcm","clk":"1003234253","pt":1580648923909,"mc":[{"id":"1.168213437","rc":[{"batb":[[0,2.96,2.65],[1,2.82,43.98],[2,2.16,3.21]],"ltp":3.25,"tv":731.44,"id":10107989},{"batb":[[0,1.45,2.65]],"ltp":1.45,"tv":596.99,"id":8444034}]}]}
{"op":"mcm","clk":"1003234875","pt":1580648926925,"mc":[{"id":"1.168213437","rc":[{"trd":[[1.45,5.55]],"batb":[[0,1.36,241.87],[1,1.31,477.51],[2,1.2,945.58]],"batl":[[0,1.45,1.55],[1,1.89,435.28],[2,1000,0.02]],"ltp":1.45,"tv":602.29,"id":8444034}],"tv":1333.73}]}
{"op":"mcm","clk":"1003236714","pt":1580648936996,"mc":[{"id":"1.168213437","rc":[{"batb":[[0,2.82,43.98],[1,2.16,3.21],[2,1.8,75.72]],"ltp":3.25,"tv":731.44,"id":10107989}]}]}
{"op":"mcm","clk":"1003238594","pt":1580648947152,"mc":[{"id":"1.168213437","rc":[{"batl":[[0,1.89,435.28],[1,1000,0.02],[2,1000,0]],"ltp":1.45,"tv":602.29,"id":8444034}]}]}
{"op":"mcm","clk":"1003240494","pt":1580648957739,"mc":[{"id":"1.168213437","rc":[{"batb":[[1,1.2,945.58],[2,1.15,378.62]],"ltp":1.45,"tv":602.29,"id":8444034}]}]}
{"op":"mcm","clk":"1003240864","pt":1580648959741,"mc":[{"id":"1.168213437","rc":[{"batb":[[1,2.72,2.57],[2,2.16,3.21]],"batl":[[0,3,48.66],[1,1000,0.02]],"ltp":3.25,"tv":731.44,"id":10107989},{"batb":[[0,1.5,85.94],[1,1.36,241.87],[2,1.2,945.58]],"batl":[[0,1.52,10.82],[1,1.58,266.67],[2,1.89,435.28]],"ltp":1.45,"tv":602.29,"id":8444034}]}]}
{"op":"mcm","clk":"1003240916","pt":1580648960044,"mc":[{"id":"1.168213437","rc":[{"batb":[[2,2.6,54.76]],"ltp":3.25,"tv":731.44,"id":10107989},{"batb":[[0,1.5,244.72],[1,1.4,213.15]],"ltp":1.45,"tv":602.29,"id":8444034}]}]}
{"op":"mcm","clk":"1003241354","pt":1580648962454,"mc":[{"id":"1.168213437","rc":[{"batb":[[2,1.34,465.43]],"ltp":1.45,"tv":602.29,"id":8444034}]}]}
{"op":"mcm","clk":"1003243395","pt":1580648973648,"mc":[{"id":"1.168213437","rc":[{"batl":[[0,1000,0.02],[1,1000,0]],"ltp":3.25,"tv":731.44,"id":10107989},{"batb":[[0,1.5,158.78]],"batl":[[0,1.89,435.28],[1,1000,0.02],[2,1.89,0]],"ltp":1.45,"tv":602.29,"id":8444034}]}]}
{"op":"mcm","clk":"1003243457","pt":1580648973969,"mc":[{"id":"1.168213437","rc":[{"batb":[[0,2.72,2.57],[1,2.6,54.76],[2,2.16,3.21]],"ltp":3.25,"tv":731.44,"id":10107989},{"batb":[[0,1.4,213.15],[1,1.34,465.43],[2,1.2,945.58]],"ltp":1.45,"tv":602.29,"id":8444034}]}]}
{"op":"mcm","clk":"1003245021","pt":1580648982690,"mc":[{"id":"1.168213437","rc":[{"batb":[[0,3.4,4.81],[1,3.15,115.28],[2,2.72,2.57]],"batl":[[0,3.5,5.36],[1,3.55,98.47],[2,1000,0.02]],"ltp":3.25,"tv":731.44,"id":10107989},{"batb":[[1,1.2,945.58],[2,1.15,378.62]],"batl":[[0,1.42,2352.6],[1,1.48,10.71],[2,1.89,435.28]],"ltp":1.45,"tv":602.29,"id":8444034}]}]}
{"op":"mcm","clk":"1003245168","pt":1580648983495,"mc":[{"id":"1.168213437","rc":[{"batb":[[1,3.25,76.4],[2,3.15,115.28]],"ltp":3.25,"tv":731.44,"id":10107989},{"batb":[[1,1.32,283.33],[2,1.2,756.28]],"batl":[[0,1.89,435.28],[1,1000,0.02],[2,1.89,0]],"ltp":1.45,"tv":602.29,"id":8444034}]}]}
{"op":"mcm","clk":"1003245741","pt":1580648986573,"mc":[{"id":"1.168213437","rc":[{"batb":[[2,1.28,485.89]],"ltp":1.45,"tv":602.29,"id":8444034}]}]}
{"op":"mcm","clk":"1003247935","pt":1580648999339,"mc":[{"id":"1.168213437","rc":[{"batb":[[0,3.25,76.4],[1,3,94.65],[2,2.6,54.76]],"batl":[[0,1000,0.02],[1,3.55,0],[2,1000,0]],"ltp":3.25,"tv":731.44,"id":10107989}]}]}
{"op":"mcm","clk":"1003248005","pt":1580648999756,"mc":[{"id":"1.168213437","rc":[{"batb":[[0,3,94.65],[1,2.16,3.21],[2,2,75.72]],"ltp":3.25,"tv":731.44,"id":10107989},{"batb":[[0,1.32,283.33],[1,1.28,485.89],[2,1.2,756.28]],"ltp":1.45,"tv":602.29,"id":8444034}]}]}
{"op":"mcm","clk":"1003248245","pt":1580649001037,"mc":[{"id":"1.168213437","rc":[{"batl":[[0,1.4,6.06],[1,1.89,435.28],[2,1000,0.02]],"ltp":1.45,"tv":602.29,"id":8444034}]}]}
{"op":"mcm","clk":"1003249175","pt":1580649005889,"mc":[{"id":"1.168213437","rc":[{"batb":[[1,1.2,756.28],[2,1.15,378.62]],"ltp":1.45,"tv":602.29,"id":8444034}]}]}
{"op":"mcm","clk":"1003249540","pt":1580649007675,"mc":[{"id":"1.168213437","rc":[{"trd":[[3.5,2.42]],"batb":[[0,3.1,7.33],[1,3,94.65],[2,2.16,3.21]],"batl":[[0,3.2,5.33],[1,1000,0.02]],"ltp":3.5,"tv":733.86,"id":10107989},{"trd":[[1.4,6.06]],"batb":[[0,1.45,224.43],[1,1.32,283.33],[2,1.2,756.28]],"batl":[[0,1.52,210.79]],"ltp":1.4,"tv":608.35,"id":8444034}],"tv":1342.21}]}
{"op":"mcm","clk":"1003249678","pt":1580649008385,"mc":[{"id":"1.168213437","rc":[{"batb":[[2,2.72,2.53]],"ltp":3.5,"tv":733.86,"id":10107989},{"batb":[[0,1.46,180.65],[1,1.45,224.43],[2,1.33,272]],"ltp":1.4,"tv":608.35,"id":8444034}]}]}
{"op":"mcm","clk":"1003251629","pt":1580649018404,"mc":[{"id":"1.168213437","rc":[{"batb":[[0,3,94.65],[1,2.72,2.53],[2,2.7,49.65]],"batl":[[0,1000,0.02],[1,1000,0]],"ltp":3.5,"tv":733.86,"id":10107989},{"batb":[[1,1.33,272],[2,1.31,477.51]],"batl":[[0,1.89,435.28],[1,1000,0.02],[2,1000,0]],"ltp":1.4,"tv":608.35,"id":8444034}]}]}
{"op":"mcm","clk":"1003251754","pt":1580649018906,"mc":[{"id":"1.168213437","rc":[{"batb":[[0,2.72,2.53],[1,2.7,49.65],[2,2.16,3.21]],"ltp":3.5,"tv":733.86,"id":10107989},{"batb":[[0,1.33,272],[1,1.31,477.51],[2,1.2,756.28]],"ltp":1.4,"tv":608.35,"id":8444034}]}]}
{"op":"mcm","clk":"1003252984","pt":1580649025057,"mc":[{"id":"1.168213437","rc":[{"batb":[[0,2.7,49.65],[1,2.16,3.21],[2,2,75.72]],"ltp":3.5,"tv":733.86,"id":10107989},{"batb":[[1,1.2,756.28],[2,1.15,378.62]],"ltp":1.4,"tv":608.35,"id":8444034}]}]}
{"op":"mcm","clk":"1003253186","pt":1580649026162,"mc":[{"id":"1.168213437","rc":[{"batb":[[1,2.6,126.2],[2,2.16,3.21]],"batl":[[0,2.84,6.04],[1,2.88,132.07],[2,1000,0.02]],"ltp":3.5,"tv":733.86,"id":10107989},{"batl":[[0,1.58,24.08],[1,1.89,435.28],[2,1000,0.02]],"ltp":1.4,"tv":608.35,"id":8444034}]}]}
{"op":"mcm","clk":"1003253430","pt":1580649027464,"mc":[{"id":"1.168213437","rc":[{"batb":[[2,2.32,74.2]],"ltp":3.5,"tv":733.86,"id":10107989},{"batb":[[0,1.54,143.75],[1,1.34,259.02],[2,1.2,756.28]],"ltp":1.4,"tv":608.35,"id":8444034}]}]}
{"op":"mcm","clk":"1003253591","pt":1580649028384,"mc":[{"id":"1.168213437","rc":[{"batb":[[1,1.38,448.45],[2,1.34,259.02]],"ltp":1.4,"tv":608.35,"id":8444034}]}]}
{"op":"mcm","clk":"1003255734","pt":1580649039506,"mc":[{"id":"1.168213437","rc":[{"batb":[[1,2.32,74.2],[2,2.16,3.21]],"batl":[[0,1000,0.02],[1,2.88,0],[2,1000,0]],"ltp":3.5,"tv":733.86,"id":10107989},{"batl":[[0,1.89,435.28],[1,1000,0.02],[2,1000,0]],"ltp":1.4,"tv":608.35,"id":8444034}]}]}
{"op":"mcm","clk":"1003255792","pt":1580649039786,"mc":[{"id":"1.168213437","rc":[{"batb":[[0,2.32,74.2],[1,2.16,3.21],[2,1.81,75.62]],"ltp":3.5,"tv":733.86,"id":10107989},{"batb":[[0,1.38,448.45],[1,1.34,259.02],[2,1.25,378.62]],"ltp":1.4,"tv":608.35,"id":8444034}]}]}
{"op":"mcm","clk":"1003257370","pt":1580649047544,"mc":[{"id":"1.168213437","rc":[{"trd":[[3.85,7.15]],"batb":[[0,3.35,138.65],[1,2.32,74.2],[2,2.16,3.21]],"batl":[[0,4,130.95],[1,1000,0.02]],"ltp":3.85,"tv":741.01,"id":10107989},{"trd":[[1.35,20.39]],"batb":[[0,1.34,259.02],[1,1.25,378.62],[2,1.2,945.58]],"batl":[[0,1.35,2551.41],[1,1.37,13.4],[2,1.39,11.93]],"ltp":1.35,"tv":628.74,"id":8444034}],"tv":1369.75}]}
{"op":"mcm","clk":"1003257543","pt":1580649048555,"mc":[{"id":"1.168213437","rc":[{"batb":[[0,3.6,58.78],[1,3.35,138.65],[2,3.2,78.45]],"ltp":3.85,"tv":741.01,"id":10107989},{"batb":[[1,1.31,290.02],[2,1.2,756.28]],"batl":[[0,1.37,13.4],[1,1000,0.02],[2,1.39,0]],"ltp":1.35,"tv":628.74,"id":8444034}]}]}
{"op":"mcm","clk":"1003257769","pt":1580649049738,"mc":[{"id":"1.168213437","rc":[{"batb":[[0,3.6,61.45]],"ltp":3.85,"tv":741.01,"id":10107989}]}]}
{"op":"mcm","clk":"1003257929","pt":1580649050562,"mc":[{"id":"1.168213437","rc":[{"batb":[[2,1.23,516.48]],"ltp":1.35,"tv":628.74,"id":8444034}]}]}
{"op":"mcm","clk":"1003258112","pt":1580649051517,"mc":[{"id":"1.168213437","rc":[{"batl":[[1,1.73,527.57],[2,1000,0.02]],"ltp":1.35,"tv":628.74,"id":8444034}]}]}
{"op":"mcm","clk":"1003258377","pt":1580649053535,"mc":[{"id":"1.168213437","rc":[{"batl":[[1,1.54,84.02],[2,1.73,527.57]],"ltp":1.35,"tv":628.74,"id":8444034}]}]}
{"op":"mcm","clk":"1003259102","pt":1580649056750,"mc":[{"id":"1.168213437","rc":[{"batl":[[1,1.73,527.57],[2,1000,0.02]],"ltp":1.35,"tv":628.74,"id":8444034}]}]}
{"op":"mcm","clk":"1003259299","pt":1580649057768,"mc":[{"id":"1.168213437","rc":[{"batl":[[0,1.73,527.57],[1,1000,0.02],[2,1000,0]],"ltp":1.35,"tv":628.74,"id":8444034}]}]}
{"op":"mcm","clk":"1003259887","pt":1580649060681,"mc":[{"id":"1.168213437","rc":[{"batb":[[0,1.34,279.75]],"batl":[[0,1.36,16.41],[1,1.73,527.57],[2,1000,0.02]],"ltp":1.35,"tv":628.74,"id":8444034}]}]}
{"op":"mcm","clk":"1003262148","pt":1580649072187,"mc":[{"id":"1.168213437","rc":[{"batb":[[0,1.35,3.21],[1,1.34,279.75],[2,1.31,290.02]],"ltp":1.35,"tv":628.74,"id":8444034}]}]}
{"op":"mcm","clk":"1003263128","pt":1580649077177,"mc":[{"id":"1.168213437","rc":[{"batb":[[0,3.6,58.78]],"ltp":3.85,"tv":741.01,"id":10107989}]}]}
{"op":"mcm","clk":"1003263245","pt":1580649077782,"mc":[{"id":"1.168213437","rc":[{"trd":[[3.75,1.07]],"ltp":3.75,"tv":742.07,"id":10107989},{"trd":[[1.36,2.94]],"batl":[[0,1.36,13.47]],"ltp":1.36,"tv":631.68,"id":8444034}],"tv":1373.76}]}
{"op":"mcm","clk":"1003265253","pt":1580649088104,"mc":[{"id":"1.168213437","rc":[{"batb":[[1,1.34,259.02]],"batl":[[0,1.73,527.57],[1,1000,0.02],[2,1000,0]],"ltp":1.36,"tv":631.68,"id":8444034}]}]}
{"op":"mcm","clk":"1003265805","pt":1580649090940,"mc":[{"id":"1.168213437","rc":[{"batl":[[0,3.9,4.95],[1,4,130.95],[2,1000,0.02]],"ltp":3.75,"tv":742.07,"id":10107989},{"batl":[[0,1.36,13.47],[1,1.73,527.57],[2,1000,0.02]],"ltp":1.36,"tv":631.68,"id":8444034}]}]}
{"op":"mcm","clk":"1003271957","pt":1580649122687,"mc":[{"id":"1.168213437","rc":[{"trd":[[1.35,20.61]],"batb":[[0,1.35,3.1]],"ltp":1.35,"tv":631.9,"id":8444034}],"tv":1373.97}]}
{"op":"mcm","clk":"1003272196","pt":1580649123840,"mc":[{"id":"1.168213437","rc":[{"trd":[[1.36,29.88]],"batb":[[0,1.36,208.53],[1,1.35,3.1],[2,1.34,259.02]],"batl":[[0,1.73,527.57],[1,1000,0.02],[2,1000,0]],"ltp":1.36,"tv":658.84,"id":8444034}],"tv":1400.91}]}
{"op":"mcm","clk":"1003273432","pt":1580649129593,"mc":[{"id":"1.168213437","rc":[{"batl":[[0,1.73,527.68]],"ltp":1.36,"tv":658.84,"id":8444034}]}]}
{"op":"mcm","clk":"1003273597","pt":1580649130295,"mc":[{"id":"1.168213437","rc":[{"batb":[[1,3.2,78.45],[2,2.2,75.72]],"batl":[[0,1000,0.02],[1,4,0],[2,1000,0]],"ltp":3.75,"tv":742.07,"id":10107989}]}]}
{"op":"mcm","clk":"1003273727","pt":1580649130936,"mc":[{"id":"1.168213437","rc":[{"batb":[[0,3.2,78.45],[1,2.2,75.72],[2,2.16,3.21]],"ltp":3.75,"tv":742.07,"id":10107989},{"batb":[[2,1.31,290.02]],"ltp":1.36,"tv":658.84,"id":8444034}]}]}
{"op":"mcm","clk":"1003274572","pt":1580649134505,"mc":[{"id":"1.168213437","rc":[{"trd":[[1.39,0.22]],"batb":[[0,1.42,1.89],[1,1.36,208.53],[2,1.35,3.1]],"batl":[[0,1.73,527.57]],"ltp":1.39,"tv":659.05,"id":8444034}],"tv":1401.13}]}
{"op":"mcm","clk":"1003274656","pt":1580649134889,"mc":[{"id":"1.168213437","rc":[{"batb":[[1,2.16,3.21],[2,2,75.72]],"ltp":3.75,"tv":742.07,"id":10107989}]}]}
{"op":"mcm","clk":"1003275714","pt":1580649140573,"mc":[{"id":"1.168213437","rc":[{"batb":[[0,1.36,208.53],[1,1.35,3.1],[2,1.31,290.02]],"ltp":1.39,"tv":659.05,"id":8444034}]}]}
{"op":"mcm","clk":"1003276245","pt":1580649143380,"mc":[{"id":"1.168213437","rc":[{"trd":[[3.2,0.86]],"batb":[[0,3.2,77.58]],"ltp":3.2,"tv":742.94,"id":10107989},{"trd":[[1.46,1.89]],"ltp":1.46,"tv":660.94,"id":8444034}],"tv":1403.89}]}
{"op":"mcm","clk":"1003277500","pt":1580649149765,"mc":[{"id":"1.168213437","rc":[{"batb":[[2,2.02,75.62]],"ltp":3.2,"tv":742.94,"id":10107989}]}]}
{"op":"mcm","clk":"1003277831","pt":1580649151517,"mc":[{"id":"1.168213437","rc":[{"batb":[[0,3.3,5.8],[1,3.2,77.58],[2,2.16,3.21]],"batl":[[0,3.4,5.15],[1,1000,0.02]],"ltp":3.2,"tv":742.94,"id":10107989},{"batb":[[0,1.41,278.17],[1,1.37,17.77],[2,1.36,208.53]],"batl":[[0,1.48,203.63],[1,1.73,527.57],[2,1000,0.02]],"ltp":1.46,"tv":660.94,"id":8444034}]}]}
{"op":"mcm","clk":"1003277975","pt":1580649152320,"mc":[{"id":"1.168213437","rc":[{"batb":[[1,3.2,80.21],[2,2.84,43.28]],"ltp":3.2,"tv":742.94,"id":10107989},{"batb":[[0,1.41,487.07],[1,1.36,450.95],[2,1.35,3.1]],"ltp":1.46,"tv":660.94,"id":8444034}]}]}
{"op":"mcm","clk":"1003280694","pt":1580649166891,"mc":[{"id":"1.168213437","rc":[{"trd":[[1.41,88.43]],"batb":[[0,1.41,442.84]],"ltp":1.41,"tv":749.37,"id":8444034}],"tv":1492.32}]}
{"op":"mcm","clk":"1003281344","pt":1580649170296,"mc":[{"id":"1.168213437","rc":[{"batb":[[0,3.2,80.21],[1,2.84,43.28],[2,2.16,3.21]],"batl":[[0,1000,0.02],[1,1000,0]],"ltp":3.2,"tv":742.94,"id":10107989},{"batb":[[0,1.41,208.9]],"batl":[[0,1.73,527.57],[1,1000,0.02],[2,1000,0]],"ltp":1.41,"tv":749.37,"id":8444034}]}]}
{"op":"mcm","clk":"1003281455","pt":1580649170899,"mc":[{"id":"1.168213437","rc":[{"batb":[[0,3.2,2.62]],"ltp":3.2,"tv":742.94,"id":10107989},{"batb":[[0,1.36,450.95],[1,1.35,3.1],[2,1.25,507.36]],"ltp":1.41,"tv":749.37,"id":8444034}]}]}
{"op":"mcm","clk":"1003282548","pt":1580649176932,"mc":[{"id":"1.168213437","rc":[{"batl":[[0,3.3,32],[1,1000,0.02]],"ltp":3.2,"tv":742.94,"id":10107989}]}]}
{"op":"mcm","clk":"1003282833","pt":1580649178518,"mc":[{"id":"1.168213437","rc":[{"trd":[[3.3,32]],"batb":[[0,3.6,4.77],[1,3.2,2.62],[2,2.84,43.28]],"batl":[[0,3.75,93.67]],"ltp":3.3,"tv":774.94,"id":10107989},{"trd":[[1.43,73.85]],"batb":[[0,1.37,11.9],[1,1.36,450.95],[2,1.35,3.1]],"batl":[[0,1.42,131.81],[1,1.73,527.57],[2,1000,0.02]],"ltp":1.43,"tv":823.22,"id":8444034}],"tv":1598.17}]}
{"op":"mcm","clk":"1003283045","pt":1580649179717,"mc":[{"id":"1.168213437","rc":[{"batb":[[1,3.5,64.36],[2,3.25,51.41]],"ltp":3.3,"tv":774.94,"id":10107989}]}]}
{"op":"mcm","clk":"1003283210","pt":1580649180525,"mc":[{"id":"1.168213437","rc":[{"batb":[[2,3,90.96]],"ltp":3.3,"tv":774.94,"id":10107989}]}]}
{"op":"mcm","clk":"1003284971","pt":1580649190034,"mc":[{"id":"1.168213437","rc":[{"trd":[[3.6,0.74]],"batb":[[0,3.6,4.03]],"ltp":3.6,"tv":775.68,"id":10107989},{"trd":[[1.39,2.15]],"ltp":1.39,"tv":825.15,"id":8444034}],"tv":1600.83}]}
{"op":"mcm","clk":"1003285817","pt":1580649194631,"mc":[{"id":"1.168213437","rc":[{"batb":[[0,3,90.96],[1,2.16,3.21],[2,2.02,75.62]],"batl":[[0,1000,0.02],[1,1000,0]],"ltp":3.6,"tv":775.68,"id":10107989},{"batb":[[0,1.36,208.53],[1,1.35,3.1],[2,1.33,275.39]],"batl":[[0,1.73,527.57],[1,1000,0.02],[2,1000,0]],"ltp":1.39,"tv":825.15,"id":8444034}]}]}
{"op":"mcm","clk":"1003286929","pt":1580649201030,"mc":[{"id":"1.168213437","rc":[{"batl":[[0,1.37,22],[1,1.73,527.57],[2,1000,0.02]],"ltp":1.39,"tv":825.15,"id":8444034}]}]}
{"op":"mcm","clk":"1003287881","pt":1580649206555,"mc":[{"id":"1.168213437","rc":[{"batl":[[0,3.75,500.42],[1,1000,0.02]],"ltp":3.6,"tv":775.68,"id":10107989},{"trd":[[1.37,23.1]],"batl":[[0,1.37,10.45],[1,1.47,14.58],[2,1.52,198.14]],"ltp":1.37,"tv":848.25,"id":8444034}],"tv":1623.93}]}
{"op":"mcm","clk":"1003288065","pt":1580649207670,"mc":[{"id":"1.168213437","rc":[{"batb":[[1,2.8,2.63],[2,2.64,52.64]],"ltp":3.6,"tv":775.68,"id":10107989},{"trd":[[1.37,44]],"batb":[[0,1.45,186.4],[1,1.39,212.53],[2,1.37,21.77]],"batl":[[0,1.47,14.58],[1,1.52,198.14],[2,1.73,527.57]],"ltp":1.37,"tv":869.15,"id":8444034}],"tv":1644.83}]}
{"op":"mcm","clk":"1003288099","pt":1580649207869,"mc":[{"id":"1.168213437","rc":[{"batb":[[2,1.36,208.53]],"ltp":1.37,"tv":869.15,"id":8444034}]}]}
{"op":"mcm","clk":"1003289753","pt":1580649216797,"mc":[{"id":"1.168213437","rc":[{"batl":[[0,1.52,198.14],[1,1.73,527.57],[2,1000,0.02]],"ltp":1.37,"tv":869.15,"id":8444034}]}]}
{"op":"mcm","clk":"1003290279","pt":1580649219695,"mc":[{"id":"1.168213437","rc":[{"batb":[[1,1.44,13.62],[2,1.39,212.53]],"batl":[[0,1.46,12.88],[1,1.52,198.14],[2,1.73,527.57]],"ltp":1.37,"tv":869.15,"id":8444034}]}]}
{"op":"mcm","clk":"1003291170","pt":1580649224698,"mc":[{"id":"1.168213437","rc":[{"batl":[[0,1000,0.02],[1,1000,0]],"ltp":3.6,"tv":775.68,"id":10107989},{"batl":[[1,1.73,527.57],[2,1000,0.02]],"ltp":1.37,"tv":869.15,"id":8444034}]}]}
{"op":"mcm","clk":"1003291268","pt":1580649225213,"mc":[{"id":"1.168213437","rc":[{"batb":[[0,2.8,2.63],[1,2.64,52.64],[2,2.16,3.21]],"ltp":3.6,"tv":775.68,"id":10107989},{"batb":[[0,1.39,212.53],[1,1.36,208.53],[2,1.35,3.1]],"batl":[[0,1.73,527.57],[1,1000,0.02],[2,1000,0]],"ltp":1.37,"tv":869.15,"id":8444034}]}]}
{"op":"mcm","clk":"1003293063","pt":1580649234985,"mc":[{"id":"1.168213437","rc":[{"batb":[[0,2.64,52.64],[1,2.16,3.21],[2,2.02,75.62]],"ltp":3.6,"tv":775.68,"id":10107989}]}]}
{"op":"mcm","clk":"1003293534","pt":1580649237539,"mc":[{"id":"1.168213437","rc":[{"batb":[[0,1.39,436.47],[1,1.38,18],[2,1.36,208.53]],"batl":[[0,1.4,7.06],[1,1.45,205.69],[2,1.73,527.57]],"ltp":1.37,"tv":869.15,"id":8444034}]}]}
{"op":"mcm","clk":"1003293656","pt":1580649238198,"mc":[{"id":"1.168213437","rc":[{"batb":[[0,3.35,71.84],[1,3.15,2.63],[2,2.82,44.06]],"ltp":3.6,"tv":775.68,"id":10107989}]}]}
{"op":"mcm","clk":"1003294237","pt":1580649241547,"mc":[{"id":"1.168213437","rc":[{"batb":[[0,1.39,212.53],[1,1.36,208.53],[2,1.35,3.1]],"batl":[[0,1.73,527.57],[1,1000,0.02],[2,1.73,0]],"ltp":1.37,"tv":869.15,"id":8444034}]}]}
{"op":"mcm","clk":"1003294327","pt":1580649242047,"mc":[{"id":"1.168213437","rc":[{"batb":[[0,3.15,2.63],[1,2.82,44.06],[2,2.16,3.21]],"ltp":3.6,"tv":775.68,"id":10107989},{"batb":[[0,1.36,208.53],[1,1.35,3.1],[2,1.34,266.18]],"ltp":1.37,"tv":869.15,"id":8444034}]}]}
{"op":"mcm","clk":"1003298670","pt":1580649265644,"mc":[{"id":"1.168213437","rc":[{"batb":[[0,2.82,44.06],[1,2.16,3.21],[2,2.02,75.62]],"ltp":3.6,"tv":775.68,"id":10107989}]}]}
{"op":"mcm","clk":"1003299575","pt":1580649270668,"mc":[{"id":"1.168213437","rc":[{"trd":[[3.8,6.43]],"batl":[[0,4,80.95],[1,4.1,8.26],[2,1000,0.02]],"ltp":3.8,"tv":782.11,"id":10107989},{"trd":[[1.36,47.86]],"batb":[[0,1.36,190.55]],"batl":[[0,1.39,260.36],[1,1.73,527.57],[2,1000,0.02]],"ltp":1.36,"tv":887.13,"id":8444034}],"tv":1669.24}]}
{"op":"mcm","clk":"1003299780","pt":1580649271696,"mc":[{"id":"1.168213437","rc":[{"batb":[[0,3.65,56.65],[1,3.35,2.7],[2,3.15,83.4]],"ltp":3.8,"tv":782.11,"id":10107989}]}]}
{"op":"mcm","clk":"1003301470","pt":1580649280925,"mc":[{"id":"1.168213437","rc":[{"batl":[[1,1000,0.02],[2,1000,0]],"ltp":3.8,"tv":782.11,"id":10107989}]}]}
{"op":"mcm","clk":"1003302000","pt":1580649283778,"mc":[{"id":"1.168213437","rc":[{"batl":[[0,4,88.31]],"ltp":3.8,"tv":782.11,"id":10107989},{"trd":[[1.36,101.86]],"batb":[[0,1.36,163.55]],"ltp":1.36,"tv":941.13,"id":8444034}],"tv":1723.24}]}
{"op":"mcm","clk":"1003303707","pt":1580649292646,"mc":[{"id":"1.168213437","rc":[{"batl":[[0,1000,0.02],[1,1000,0]],"ltp":3.8,"tv":782.11,"id":10107989},{"batl":[[0,1.73,527.57],[1,1000,0.02],[2,1000,0]],"ltp":1.36,"tv":941.13,"id":8444034}]}]}
{"op":"mcm","clk":"1003303776","pt":1580649293064,"mc":[{"id":"1.168213437","rc":[{"batb":[[0,3.35,2.7],[1,3.15,83.4],[2,2.16,3.21]],"ltp":3.8,"tv":782.11,"id":10107989},{"batb":[[2,1.3,306.78]],"ltp":1.36,"tv":941.13,"id":8444034}]}]}
{"op":"mcm","clk":"1003304881","pt":1580649298755,"mc":[{"id":"1.168213437","rc":[{"batb":[[0,3.15,83.4],[1,2.16,3.21],[2,2.02,75.62]],"ltp":3.8,"tv":782.11,"id":10107989}]}]}
{"op":"mcm","clk":"1003307945","pt":1580649315360,"mc":[{"id":"1.168213437","rc":[{"batl":[[0,1000,0.02],[1,1000,0]],"ltp":1.36,"tv":941.13,"id":8444034}]}]}
{"op":"mcm","clk":"1003308184","pt":1580649316670,"mc":[{"id":"1.168213437","rc":[{"batl":[[0,4.3,6.03],[1,1000,0.02]],"ltp":3.8,"tv":782.11,"id":10107989},{"trd":[[1.35,26.81],[1.36,428.96]],"batb":[[0,1.3,306.78],[1,1.29,239],[2,1.25,2.27]],"batl":[[0,1.32,15.36],[1,1.34,129.92],[2,1000,0.02]],"ltp":1.35,"tv":1274.43,"id":8444034}],"tv":2056.55}]}
{"op":"mcm","clk":"1003308364","pt":1580649317546,"mc":[{"id":"1.168213437","rc":[{"batb":[[0,4.1,2.6],[1,3.95,94.18],[2,3.8,52.64]],"ltp":3.8,"tv":782.11,"id":10107989},{"batb":[[2,1.26,353.05]],"ltp":1.35,"tv":1274.43,"id":8444034}]}]}
{"op":"mcm","clk":"1003308691","pt":1580649319474,"mc":[{"id":"1.168213437","rc":[{"batl":[[2,1.39,3.01]],"ltp":1.35,"tv":1274.43,"id":8444034}]}]}
{"op":"mcm","clk":"1003312788","pt":1580649344706,"mc":[{"id":"1.168213437","rc":[{"batb":[[0,3.95,94.18],[1,3.8,52.64],[2,2.2,75.72]],"ltp":3.8,"tv":782.11,"id":10107989}]}]}
{"op":"mcm","clk":"1003313568","pt":1580649349379,"mc":[{"id":"1.168213437","rc":[{"batl":[[0,1000,0.02],[1,1000,0]],"ltp":3.8,"tv":782.11,"id":10107989},{"batb":[[1,1.26,353.05],[2,1.25,2.27]],"batl":[[0,1.39,3.01],[1,1.66,579.81],[2,1000,0.02]],"ltp":1.35,"tv":1274.43,"id":8444034}]}]}
{"op":"mcm","clk":"1003313716","pt":1580649350292,"mc":[{"id":"1.168213437","rc":[{"batb":[[0,3.8,52.64],[1,2.2,75.72],[2,2.16,3.21]],"ltp":3.8,"tv":782.11,"id":10107989},{"batb":[[0,1.26,352.81],[1,1.25,2.27],[2,1.23,2]],"ltp":1.35,"tv":1274.43,"id":8444034}]}]}
{"op":"mcm","clk":"1003315424","pt":1580649360409,"mc":[{"id":"1.168213437","rc":[{"batb":[[0,3.9,5],[1,3.8,52.64],[2,2.2,75.72]],"batl":[[0,4.1,86.49],[1,1000,0.02]],"ltp":3.8,"tv":782.11,"id":10107989},{"batb":[[0,1.33,13.29],[1,1.26,352.81],[2,1.25,2.27]],"batl":[[0,1.37,198.88],[1,1.39,3.01],[2,1.66,579.81]],"ltp":1.35,"tv":1274.43,"id":8444034}]}]}
{"op":"mcm","clk":"1003315623","pt":1580649361409,"mc":[{"id":"1.168213437","rc":[{"batb":[[1,3.85,2.59],[2,3.8,52.64]],"ltp":3.8,"tv":782.11,"id":10107989},{"batb":[[1,1.32,283.33],[2,1.29,318.11]],"ltp":1.35,"tv":1274.43,"id":8444034}]}]}
{"op":"mcm","clk":"1003318531","pt":1580649377263,"mc":[{"id":"1.168213437","rc":[{"batb":[[0,3.85,2.59],[1,3.8,52.64],[2,3.65,58.07]],"batl":[[0,1000,0.02],[1,1000,0]],"ltp":3.8,"tv":782.11,"id":10107989},{"batb":[[0,1.32,283.33],[1,1.29,318.11],[2,1.25,2.27]],"batl":[[0,1.39,3.01],[1,1.66,579.81],[2,1000,0.02]],"ltp":1.35,"tv":1274.43,"id":8444034}]}]}
{"op":"mcm","clk":"1003318642","pt":1580649377847,"mc":[{"id":"1.168213437","rc":[{"batb":[[1,3.65,58.07],[2,2.2,75.72]],"ltp":3.8,"tv":782.11,"id":10107989},{"batb":[[0,1.29,318.11],[1,1.25,2.27],[2,1.23,2]],"ltp":1.35,"tv":1274.43,"id":8444034}]}]}
{"op":"mcm","clk":"1003318875","pt":1580649379058,"mc":[{"id":"1.168213437","rc":[{"batl":[[0,4,2.53],[1,1000,0.02]],"ltp":3.8,"tv":782.11,"id":10107989}]}]}
{"op":"mcm","clk":"1003320297","pt":1580649386669,"mc":[{"id":"1.168213437","rc":[{"batb":[[0,3.65,58.07],[1,2.2,75.72],[2,2.16,3.21]],"ltp":3.8,"tv":782.11,"id":10107989}]}]}
{"op":"mcm","clk":"1003320600","pt":1580649388363,"mc":[{"id":"1.168213437","rc":[{"batb":[[1,3.5,51.3],[2,2.2,75.72]],"batl":[[0,3.85,66.55],[1,4,2.53],[2,1000,0.02]],"ltp":3.8,"tv":782.11,"id":10107989},{"batl":[[0,1.37,16.72],[1,1.39,3.01],[2,1.4,128.26]],"ltp":1.35,"tv":1274.43,"id":8444034}]}]}
{"op":"mcm","clk":"1003320758","pt":1580649389326,"mc":[{"id":"1.168213437","rc":[{"batb":[[1,3.5,114.4]],"ltp":3.8,"tv":782.11,"id":10107989},{"batb":[[0,1.34,261.38],[1,1.31,291.91],[2,1.25,2.27]],"ltp":1.35,"tv":1274.43,"id":8444034}]}]}
{"op":"mcm","clk":"1003321286","pt":1580649392093,"mc":[{"id":"1.168213437","rc":[{"trd":[[3.85,21.95]],"batl":[[0,3.85,51.75]],"ltp":3.85,"tv":796.91,"id":10107989},{"trd":[[1.35,69.03]],"ltp":1.35,"tv":1316.65,"id":8444034}],"tv":2113.56}]}
{"op":"mcm","clk":"1003323255","pt":1580649402324,"mc":[{"id":"1.168213437","rc":[{"batl":[[0,1.39,3.01],[1,1.4,128.26],[2,1.66,579.81]],"ltp":1.35,"tv":1316.65,"id":8444034}]}]}
{"op":"mcm","clk":"1003323656","pt":1580649404506,"mc":[{"id":"1.168213437","rc":[{"batb":[[0,3.5,63.1],[1,2.2,75.72],[2,2.16,3.21]],"batl":[[0,4,2.53],[1,1000,0.02],[2,1000,0]],"ltp":3.85,"tv":796.91,"id":10107989},{"batb":[[0,1.31,291.91],[1,1.25,2.27],[2,1.23,2]],"batl":[[1,1.66,579.81],[2,1000,0.02]],"ltp":1.35,"tv":1316.65,"id":8444034}]}]}
{"op":"mcm","clk":"1003327062","pt":1580649423245,"mc":[{"id":"1.168213437","rc":[{"trd":[[4,2.53]],"batb":[[0,3.75,79.89],[1,3.5,63.1],[2,2.2,75.72]],"batl":[[0,4.2,106.79]],"ltp":4.0,"tv":799.44,"id":10107989},{"trd":[[1.33,7.62]],"batl":[[0,1.33,6.46],[1,1.39,3.01],[2,1.66,579.81]],"ltp":1.33,"tv":1324.27,"id":8444034}],"tv":2123.72}]}
{"op":"mcm","clk":"1003327321","pt":1580649424636,"mc":[{"id":"1.168213437","rc":[{"batb":[[0,3.9,2.68],[1,3.85,101.03],[2,3.75,79.89]],"ltp":4.0,"tv":799.44,"id":10107989},{"batb":[[1,1.27,338.02],[2,1.25,2.27]],"ltp":1.33,"tv":1324.27,"id":8444034}]}]}
{"op":"mcm","clk":"1003329014","pt":1580649433501,"mc":[{"id":"1.168213437","rc":[{"batl":[[0,4.2,100.11]],"ltp":4.0,"tv":799.44,"id":10107989},{"batl":[[0,1.39,3.01],[1,1.66,579.81],[2,1000,0.02]],"ltp":1.33,"tv":1324.27,"id":8444034}]}]}
{"op":"mcm","clk":"1003329531","pt":1580649436387,"mc":[{"id":"1.168213437","rc":[{"batb":[[0,4,4.27],[1,3.9,2.68],[2,3.85,101.03]],"ltp":4.0,"tv":799.44,"id":10107989},{"batb":[[0,1.32,13.4],[1,1.31,291.91],[2,1.27,338.02]],"ltp":1.33,"tv":1324.27,"id":8444034}]}]}
{"op":"mcm","clk":"1003331256","pt":1580649446309,"mc":[{"id":"1.168213437","rc":[{"batb":[[0,3.9,2.68],[1,3.65,56.57],[2,2.2,75.72]],"batl":[[0,1000,0.02],[1,1000,0]],"ltp":4.0,"tv":799.44,"id":10107989},{"batb":[[0,1.27,338.02],[1,1.25,2.27],[2,1.23,2]],"ltp":1.33,"tv":1324.27,"id":8444034}]}]}
{"op":"mcm","clk":"1003332087","pt":1580649451488,"mc":[{"id":"1.168213437","rc":[{"batb":[[0,3.65,56.57],[1,2.2,75.72],[2,2.16,3.21]],"ltp":4.0,"tv":799.44,"id":10107989}]}]}
{"op":"mcm","clk":"1003333457","pt":1580649459697,"mc":[{"id":"1.168213437","rc":[{"batb":[[0,4.2,81.91],[1,3.9,98.12],[2,3.65,56.57]],"batl":[[0,4.5,3.66],[1,1000,0.02]],"ltp":4.0,"tv":799.44,"id":10107989},{"batb":[[0,1.28,283.39],[1,1.27,338.02],[2,1.25,2.27]],"batl":[[0,1.3,19.25],[1,1.34,450.01],[2,1.39,3.01]],"ltp":1.33,"tv":1324.27,"id":8444034}]}]}
{"op":"mcm","clk":"1003333486","pt":1580649459909,"mc":[{"id":"1.168213437","rc":[{"batb":[[2,2.2,75.72]],"ltp":4.0,"tv":799.44,"id":10107989}]}]}
{"op":"mcm","clk":"1003333730","pt":1580649461319,"mc":[{"id":"1.168213437","rc":[{"trd":[[4.5,5.4]],"batl":[[0,1000,0.98],[1,1000,0]],"ltp":4.5,"tv":804.84,"id":10107989}],"tv":2129.12}]}
{"op":"mcm","clk":"1003335539","pt":1580649471532,"mc":[{"id":"1.168213437","rc":[{"batl":[[0,1000,0.02]],"ltp":4.5,"tv":804.84,"id":10107989},{"batl":[[0,1.34,450.01],[1,1.39,3.01],[2,1.66,579.81]],"ltp":1.33,"tv":1324.27,"id":8444034}]}]}
{"op":"mcm","clk":"1003336039","pt":1580649474550,"mc":[{"id":"1.168213437","rc":[{"batb":[[0,4.4,4.65],[1,4.2,81.91],[2,3.9,98.12]],"ltp":4.5,"tv":804.84,"id":10107989},{"batb":[[0,1.28,300.46]],"ltp":1.33,"tv":1324.27,"id":8444034}]}]}
{"op":"mcm","clk":"1003337685","pt":1580649483360,"mc":[{"id":"1.168213437","rc":[{"batb":[[0,4.2,81.91],[1,3.9,98.12],[2,2.2,75.72]],"ltp":4.5,"tv":804.84,"id":10107989},{"batb":[[0,1.27,338.02],[1,1.25,2.27],[2,1.23,412.48]],"batl":[[0,1.39,3.01],[1,1.66,579.81],[2,1000,0.02]],"ltp":1.33,"tv":1324.27,"id":8444034}]}]}
{"op":"mcm","clk":"1003337769","pt":1580649483870,"mc":[{"id":"1.168213437","rc":[{"batb":[[0,3.9,98.12],[1,2.2,75.72],[2,2.16,3.21]],"ltp":4.5,"tv":804.84,"id":10107989},{"batb":[[0,1.25,2.27],[1,1.23,412.48],[2,1.22,523]],"ltp":1.33,"tv":1324.27,"id":8444034}]}]}
{"op":"mcm","clk":"1003339381","pt":1580649492674,"mc":[{"id":"1.168213437","rc":[{"batl":[[0,4.2,4.44],[1,4.3,821.8],[2,4.7,306.24]],"ltp":4.5,"tv":804.84,"id":10107989},{"batl":[[0,1.33,21.02],[1,1.36,204.27],[2,1.39,3.01]],"ltp":1.33,"tv":1324.27,"id":8444034}]}]}
{"op":"mcm","clk":"1003339600","pt":1580649493677,"mc":[{"id":"1.168213437","rc":[{"batb":[[1,3.7,56.34],[2,2.2,75.72]],"batl":[[1,4.7,306.24],[2,1000,0.02]],"ltp":4.5,"tv":804.84,"id":10107989},{"batb":[[0,1.3,298.05],[1,1.26,351.87],[2,1.25,2.27]],"ltp":1.33,"tv":1324.27,"id":8444034}]}]}
{"op":"mcm","clk":"1003342323","pt":1580649509557,"mc":[{"id":"1.168213437","rc":[{"batl":[[0,1000,0.02],[1,4.7,0],[2,1000,0]],"ltp":4.5,"tv":804.84,"id":10107989},{"batl":[[0,1.39,3.01],[1,1.66,579.81],[2,1000,0.02]],"ltp":1.33,"tv":1324.27,"id":8444034}]}]}
{"op":"mcm","clk":"1003342391","pt":1580649509975,"mc":[{"id":"1.168213437","rc":[{"batb":[[0,3.7,56.34],[1,2.2,75.72],[2,2.16,3.21]],"ltp":4.5,"tv":804.84,"id":10107989},{"batb":[[0,1.26,351.87],[1,1.25,2.27],[2,1.23,2]],"ltp":1.33,"tv":1324.27,"id":8444034}]}]}
{"op":"mcm","clk":"1003344068","pt":1580649519111,"mc":[{"id":"1.168213437","rc":[{"batb":[[0,3.75,4.36],[1,3.7,56.34],[2,2.2,75.72]],"batl":[[0,3.85,80.32],[1,1000,0.02]],"ltp":4.5,"tv":804.84,"id":10107989},{"batb":[[0,1.35,12.11],[1,1.26,351.87],[2,1.25,2.27]],"batl":[[1,1.41,291.64],[2,1.66,579.81]],"ltp":1.33,"tv":1324.27,"id":8444034}]}]}
{"op":"mcm","clk":"1003344252","pt":1580649520128,"mc":[{"id":"1.168213437","rc":[{"batb":[[2,3.25,77.34]],"ltp":4.5,"tv":804.84,"id":10107989},{"batb":[[1,1.33,267.13],[2,1.3,301.27]],"ltp":1.33,"tv":1324.27,"id":8444034}]}]}
{"op":"mcm","clk":"1003345846","pt":1580649529718,"mc":[{"id":"1.168213437","rc":[{"trd":[[3.85,86.35]],"batl":[[0,3.85,15.92]],"ltp":3.85,"tv":869.24,"id":10107989},{"trd":[[1.35,276.9]],"batb":[[0,1.33,267.13],[1,1.3,301.27],[2,1.25,2.27]],"ltp":1.35,"tv":1532.15,"id":8444034}],"tv":2401.39}]}
{"op":"mcm","clk":"1003346627","pt":1580649534691,"mc":[{"id":"1.168213437","rc":[{"trd":[[3.75,7.07]],"batb":[[0,3.75,1.36]],"ltp":3.75,"tv":875.24,"id":10107989}],"tv":2407.39}]}
{"op":"mcm","clk":"1003347456","pt":1580649539936,"mc":[{"id":"1.168213437","rc":[{"batb":[[0,3.7,56.34],[1,3.25,77.34],[2,2.2,75.72]],"ltp":3.75,"tv":875.24,"id":10107989}]}]}
{"op":"mcm","clk":"1003347915","pt":1580649542638,"mc":[{"id":"1.168213437","rc":[{"trd":[[3.85,92.55]],"batl":[[0,3.85,9.72]],"ltp":3.85,"tv":881.44,"id":10107989},{"trd":[[1.35,294.58]],"ltp":1.35,"tv":1549.83,"id":8444034}],"tv":2431.27}]}
{"op":"mcm","clk":"1003347952","pt":1580649542851,"mc":[{"id":"1.168213437","rc":[{"batb":[[0,3.75,5.72],[1,3.7,56.34],[2,3.25,77.34]],"batl":[[1,3.9,6.19],[2,1000,0.02]],"ltp":3.85,"tv":881.44,"id":10107989}]}]}
{"op":"mcm","clk":"1003348290","pt":1580649544931,"mc":[{"id":"1.168213437","rc":[{"batb":[[0,3.7,56.34],[1,3.25,77.34],[2,2.2,75.72]],"batl":[[1,1000,0.02],[2,1000,0]],"ltp":3.85,"tv":881.44,"id":10107989}]}]}
{"op":"mcm","clk":"1003348794","pt":1580649547874,"mc":[{"id":"1.168213437","rc":[{"batb":[[0,3.75,5.72],[1,3.7,56.34],[2,3.25,77.34]],"batl":[[1,3.9,6.19],[2,1000,0.02]],"ltp":3.85,"tv":881.44,"id":10107989}]}]}
{"op":"mcm","clk":"1003348974","pt":1580649549044,"mc":[{"id":"1.168213437","rc":[{"trd":[[3.85,97.81]],"batl":[[0,3.85,7.09]],"ltp":3.85,"tv":886.7,"id":10107989}],"tv":2436.53}]}
{"op":"mcm","clk":"1003359171","pt":1580649614406,"mc":[{"id":"1.168213437","rc":[{"batb":[[0,3.25,77.34],[1,2.2,75.72],[2,2.16,3.21]],"batl":[[0,1000,0.02],[1,3.9,0],[2,1000,0]],"ltp":3.85,"tv":886.7,"id":10107989},{"batb":[[0,1.3,301.27],[1,1.25,2.27],[2,1.23,2]],"batl":[[1,1.66,579.81],[2,1000,0.02]],"ltp":1.35,"tv":1549.83,"id":8444034}]}]}
{"op":"mcm","clk":"1003362055","pt":1580649632416,"mc":[{"id":"1.168213437","rc":[{"batl":[[0,4.3,66.05],[1,1000,0.02]],"ltp":3.85,"tv":886.7,"id":10107989},{"batb":[[0,1.31,15.77],[1,1.3,301.27],[2,1.25,2.27]],"batl":[[0,1.33,24.76],[1,1.35,265.92],[2,1.39,3.01]],"ltp":1.35,"tv":1549.83,"id":8444034}]}]}
{"op":"mcm","clk":"1003362270","pt":1580649633724,"mc":[{"id":"1.168213437","rc":[{"batb":[[0,3.9,96.62],[1,3.5,63.34],[2,2.2,75.72]],"ltp":3.85,"tv":886.7,"id":10107989},{"batb":[[2,1.27,336.29]],"ltp":1.35,"tv":1549.83,"id":8444034}]}]}
{"op":"mcm","clk":"1003364640","pt":1580649648720,"mc":[{"id":"1.168213437","rc":[{"batl":[[0,1000,0.02],[1,1000,0]],"ltp":3.85,"tv":886.7,"id":10107989},{"batb":[[0,1.3,301.27],[1,1.27,336.29],[2,1.25,2.27]],"batl":[[0,1.39,3.01],[1,1.66,579.81],[2,1000,0.02]],"ltp":1.35,"tv":1549.83,"id":8444034}]}]}
{"op":"mcm","clk":"1003364692","pt":1580649649045,"mc":[{"id":"1.168213437","rc":[{"batb":[[0,3.5,63.34],[1,2.2,75.72],[2,2.16,3.21]],"ltp":3.85,"tv":886.7,"id":10107989},{"batb":[[0,1.27,336.29],[1,1.25,2.27],[2,1.23,2]],"ltp":1.35,"tv":1549.83,"id":8444034}]}]}
{"op":"mcm","clk":"1003365702","pt":1580649655465,"mc":[{"id":"1.168213437","rc":[{"batl":[[0,4.7,92.06],[1,1000,0.02]],"ltp":3.85,"tv":886.7,"id":10107989},{"batb":[[0,1.28,20.67],[1,1.27,336.29],[2,1.25,2.27]],"batl":[[0,1.3,25.31],[1,1.32,306.2],[2,1.39,3.01]],"ltp":1.35,"tv":1549.83,"id":8444034}]}]}
{"op":"mcm","clk":"1003365800","pt":1580649656051,"mc":[{"id":"1.168213437","rc":[{"batb":[[0,4.2,82.54],[1,3.8,52.4],[2,2.2,75.72]],"ltp":3.85,"tv":886.7,"id":10107989},{"batb":[[2,1.26,362.64]],"ltp":1.35,"tv":1549.83,"id":8444034}]}]}
{"op":"mcm","clk":"1003366198","pt":1580649658645,"mc":[{"id":"1.168213437","rc":[{"batl":[[2,1.38,127.54]],"ltp":1.35,"tv":1549.83,"id":8444034}]}]}
{"op":"mcm","clk":"1003366244","pt":1580649658855,"mc":[{"id":"1.168213437","rc":[{"batl":[[2,1.39,3.01]],"ltp":1.35,"tv":1549.83,"id":8444034}]}]}
{"op":"mcm","clk":"1003367678","pt":1580649668442,"mc":[{"id":"1.168213437","rc":[{"batl":[[0,1000,0.02],[1,1000,0]],"ltp":3.85,"tv":886.7,"id":10107989},{"batb":[[0,1.27,336.29],[1,1.26,362.64],[2,1.25,2.27]],"batl":[[0,1.39,3.01],[1,1.66,579.81],[2,1000,0.02]],"ltp":1.35,"tv":1549.83,"id":8444034}]}]}
{"op":"mcm","clk":"1003367767","pt":1580649669032,"mc":[{"id":"1.168213437","rc":[{"batb":[[0,3.8,52.4],[1,2.2,75.72],[2,2.16,3.21]],"ltp":3.85,"tv":886.7,"id":10107989},{"batb":[[0,1.26,362.64],[1,1.25,2.27],[2,1.23,2]],"ltp":1.35,"tv":1549.83,"id":8444034}]}]}
{"op":"mcm","clk":"1003370378","pt":1580649686606,"mc":[{"id":"1.168213437","rc":[{"trd":[[4.9,30]],"ltp":4.9,"tv":916.7,"id":10107989},{"trd":[[1.26,116.67]],"batb":[[0,1.25,2.27],[1,1.23,2],[2,1.22,523]],"ltp":1.26,"tv":1666.5,"id":8444034}],"tv":2583.21}]}
{"op":"mcm","clk":"1003370552","pt":1580649687406,"mc":[{"id":"1.168213437","rc":[{"batb":[[2,1.16,756.28]],"ltp":1.26,"tv":1666.5,"id":8444034}]}]}
{"op":"mcm","clk":"1003370907","pt":1580649689502,"mc":[{"id":"1.168213437","rc":[{"batb":[[0,4.4,147.02],[1,4.1,86.86],[2,3.8,52.4]],"batl":[[0,4.8,3.72],[1,5,49.03],[2,1000,0.02]],"ltp":4.9,"tv":916.7,"id":10107989},{"batb":[[0,1.25,566.46],[1,1.24,390.89],[2,1.23,2]],"batl":[[0,1.28,27.66],[1,1.39,3.01],[2,1.66,579.81]],"ltp":1.26,"tv":1666.5,"id":8444034}]}]}
{"op":"mcm","clk":"1003370997","pt":1580649690090,"mc":[{"id":"1.168213437","rc":[{"batb":[[2,2.2,75.72]],"ltp":4.9,"tv":916.7,"id":10107989}]}]}
{"op":"mcm","clk":"1003371330","pt":1580649692081,"mc":[{"id":"1.168213437","rc":[{"batb":[[2,2.6,75.72]],"ltp":4.9,"tv":916.7,"id":10107989}]}]}
{"op":"mcm","clk":"1003373220","pt":1580649704716,"mc":[{"id":"1.168213437","rc":[{"batb":[[0,4.4,72.39]],"batl":[[0,1000,0.02],[1,5,0],[2,1000,0]],"ltp":4.9,"tv":916.7,"id":10107989},{"batb":[[0,1.25,370.35]],"batl":[[0,1.39,3.01],[1,1.66,579.81],[2,1000,0.02]],"ltp":1.26,"tv":1666.5,"id":8444034}]}]}
{"op":"mcm","clk":"1003373316","pt":1580649705319,"mc":[{"id":"1.168213437","rc":[{"batb":[[0,4.1,86.71],[1,2.6,75.72],[2,2.2,75.72]],"ltp":4.9,"tv":916.7,"id":10107989},{"batb":[[0,1.25,2.27],[1,1.24,390.73]],"ltp":1.26,"tv":1666.5,"id":8444034}]}]}
{"op":"mcm","clk":"1003374378","pt":1580649712539,"mc":[{"id":"1.168213437","rc":[{"batl":[[0,5.1,64.04],[1,1000,0.02]],"ltp":4.9,"tv":916.7,"id":10107989},{"batl":[[0,1.26,14],[1,1.28,285.11],[2,1.39,3.01]],"ltp":1.26,"tv":1666.5,"id":8444034}]}]}
{"op":"mcm","clk":"1003374507","pt":1580649713439,"mc":[{"id":"1.168213437","rc":[{"batb":[[0,4.6,66.25],[1,4.4,74.43],[2,4.1,86.71]],"ltp":4.9,"tv":916.7,"id":10107989}]}]}
{"op":"mcm","clk":"1003374557","pt":1580649713758,"mc":[{"id":"1.168213437","rc":[{"batb":[[2,2.6,75.72]],"ltp":4.9,"tv":916.7,"id":10107989}]}]}
{"op":"mcm","clk":"1003376599","pt":1580649727151,"mc":[{"id":"1.168213437","rc":[{"batb":[[0,1.24,390.73],[1,1.23,2],[2,1.21,446.99]],"ltp":1.26,"tv":1666.5,"id":8444034}]}]}
{"op":"mcm","clk":"1003378976","pt":1580649741636,"mc":[{"id":"1.168213437","rc":[{"batb":[[0,4.4,74.43],[1,2.6,75.72],[2,2.2,75.72]],"batl":[[0,1000,0.02],[1,1000,0]],"ltp":4.9,"tv":916.7,"id":10107989},{"batb":[[0,1.23,2],[1,1.21,446.99],[2,1.18,549.82]],"batl":[[0,1.39,3.01],[1,1.66,579.81],[2,1000,0.02]],"ltp":1.26,"tv":1666.5,"id":8444034}]}]}
{"op":"mcm","clk":"1003379482","pt":1580649744742,"mc":[{"id":"1.168213437","rc":[{"batb":[[1,4.3,75.46],[2,2.6,75.72]],"ltp":4.9,"tv":916.7,"id":10107989}]}]}
{"op":"mcm","clk":"1003379528","pt":1580649745019,"mc":[{"id":"1.168213437","rc":[{"batb":[[0,4.3,75.46],[1,2.6,75.72],[2,2.2,75.72]],"ltp":4.9,"tv":916.7,"id":10107989},{"batb":[[1,1.21,443.06]],"ltp":1.26,"tv":1666.5,"id":8444034}]}]}
{"op":"mcm","clk":"1003379636","pt":1580649745765,"mc":[{"id":"1.168213437","rc":[{"batb":[[0,1.25,2.27],[1,1.23,2],[2,1.21,443.06]],"ltp":1.26,"tv":1666.5,"id":8444034}]}]}
{"op":"mcm","clk":"1003381096","pt":1580649755266,"mc":[{"id":"1.168213437","rc":[{"batl":[[0,4.8,6.69],[1,1000,0.02]],"ltp":4.9,"tv":916.7,"id":10107989},{"batb":[[0,1.26,255.81],[1,1.25,2.27],[2,1.23,2]],"batl":[[0,1.28,16.89],[1,1.3,273.66],[2,1.39,3.01]],"ltp":1.26,"tv":1666.5,"id":8444034}]}]}
{"op":"mcm","clk":"1003381282","pt":1580649756436,"mc":[{"id":"1.168213437","rc":[{"batb":[[1,4.2,83.17],[2,2.6,75.72]],"ltp":4.9,"tv":916.7,"id":10107989},{"batb":[[0,1.26,613.66],[2,1.23,404.38]],"ltp":1.26,"tv":1666.5,"id":8444034}]}]}
{"op":"mcm","clk":"1003382098","pt":1580649761950,"mc":[{"id":"1.168213437","rc":[{"trd":[[1.28,33.77],[1.3,2.96]],"batl":[[0,1.3,272.18],[1,1.39,3.01],[2,1.66,579.81]],"ltp":1.3,"tv":1703.23,"id":8444034}],"tv":2619.94}]}
{"op":"mcm","clk":"1003383174","pt":1580649768688,"mc":[{"id":"1.168213437","rc":[{"batl":[[0,1000,0.02],[1,1000,0]],"ltp":4.9,"tv":916.7,"id":10107989},{"batb":[[0,1.26,357.85]],"batl":[[0,1.39,3.01],[1,1.66,579.81],[2,1000,0.02]],"ltp":1.3,"tv":1703.23,"id":8444034}]}]}
{"op":"mcm","clk":"1003383239","pt":1580649769109,"mc":[{"id":"1.168213437","rc":[{"batb":[[0,4.2,83.17],[1,2.6,75.72],[2,2.2,75.72]],"ltp":4.9,"tv":916.7,"id":10107989},{"batb":[[0,1.25,2.27],[1,1.23,404.22],[2,1.18,549.82]],"ltp":1.3,"tv":1703.23,"id":8444034}]}]}
{"op":"mcm","clk":"1003384035","pt":1580649774102,"mc":[{"id":"1.168213437","rc":[{"trd":[[4.2,0.08]],"batb":[[0,4.2,83.09]],"ltp":4.2,"tv":916.78,"id":10107989},{"trd":[[1.32,0.24]],"ltp":1.32,"tv":1703.48,"id":8444034}],"tv":2620.26}]}
{"op":"mcm","clk":"1003386352","pt":1580649788542,"mc":[{"id":"1.168213437","rc":[{"batl":[[0,4.7,105.27],[1,1000,0.02]],"ltp":4.2,"tv":916.78,"id":10107989},{"batb":[[0,1.29,17.09],[1,1.25,2.27],[2,1.23,404.22]],"batl":[[0,1.31,26.3],[1,1.32,292.68],[2,1.39,3.01]],"ltp":1.32,"tv":1703.48,"id":8444034}]}]}
{"op":"mcm","clk":"1003386474","pt":1580649789227,"mc":[{"id":"1.168213437","rc":[{"batb":[[1,4,89.78],[2,2.6,75.72]],"ltp":4.2,"tv":916.78,"id":10107989},{"batb":[[1,1.27,334.48],[2,1.25,374.91]],"ltp":1.32,"tv":1703.48,"id":8444034}]}]}
{"op":"mcm","clk":"1003389178","pt":1580649805661,"mc":[{"id":"1.168213437","rc":[{"batb":[[0,4,89.78],[1,2.6,75.72],[2,2.2,75.72]],"batl":[[0,1000,0.02],[1,1000,0]],"ltp":4.2,"tv":916.78,"id":10107989},{"batb":[[0,1.25,374.91],[1,1.23,2],[2,1.18,549.82]],"batl":[[0,1.39,3.01],[1,1.66,579.81],[2,1000,0.02]],"ltp":1.32,"tv":1703.48,"id":8444034}]}]}
{"op":"mcm","clk":"1003389919","pt":1580649810384,"mc":[{"id":"1.168213437","rc":[{"batb":[[2,1.1,756.38]],"ltp":1.32,"tv":1703.48,"id":8444034}]}]}
{"op":"mcm","clk":"1003390222","pt":1580649812158,"mc":[{"id":"1.168213437","rc":[{"batl":[[0,4.3,6.25],[1,4.4,55.48],[2,1000,0.02]],"ltp":4.2,"tv":916.78,"id":10107989},{"batl":[[0,1.32,14.8],[1,1.33,197.05],[2,1.39,3.01]],"ltp":1.32,"tv":1703.48,"id":8444034}]}]}
{"op":"mcm","clk":"1003390381","pt":1580649813162,"mc":[{"id":"1.168213437","rc":[{"batb":[[1,3.9,96.62],[2,2.6,75.72]],"ltp":4.2,"tv":916.78,"id":10107989},{"batb":[[0,1.29,317.17],[1,1.27,342.58],[2,1.25,2.27]],"ltp":1.32,"tv":1703.48,"id":8444034}]}]}
{"op":"mcm","clk":"1003392112","pt":1580649823621,"mc":[{"id":"1.168213437","rc":[{"batb":[[0,3.9,96.62],[1,2.6,75.72],[2,2.2,75.72]],"batl":[[0,1000,0.02],[1,4.4,0],[2,1000,0]],"ltp":4.2,"tv":916.78,"id":10107989},{"batb":[[0,1.27,342.58],[1,1.25,2.27],[2,1.23,2]],"batl":[[0,1.39,3.01],[1,1.66,579.81],[2,1000,0.02]],"ltp":1.32,"tv":1703.48,"id":8444034}]}]}
{"op":"mcm","clk":"1003395443","pt":1580649843723,"mc":[{"id":"1.168213437","rc":[{"batb":[[1,3.35,69.32],[2,2.6,75.72]],"batl":[[0,4.1,6.12],[1,1000,0.02]],"ltp":4.2,"tv":916.78,"id":10107989},{"batb":[[0,1.31,226.71],[1,1.3,301.27],[2,1.27,342.58]],"batl":[[0,1.34,14.66],[1,1.35,182.34],[2,1.39,3.01]],"ltp":1.32,"tv":1703.48,"id":8444034}]}]}
{"op":"mcm","clk":"1003395495","pt":1580649844041,"mc":[{"id":"1.168213437","rc":[{"batb":[[2,1.27,342.27]],"ltp":1.32,"tv":1703.48,"id":8444034}]}]}
{"op":"mcm","clk":"1003398985","pt":1580649864266,"mc":[{"id":"1.168213437","rc":[{"trd":[[4.1,6.12]],"batl":[[0,1000,0.02],[1,1000,0]],"ltp":4.1,"tv":922.9,"id":10107989},{"trd":[[1.32,19.25]],"batl":[[0,1.32,80.99],[1,1.34,14.66],[2,1.35,182.34]],"ltp":1.32,"tv":1722.49,"id":8444034}],"tv":2645.39}]}
{"op":"mcm","clk":"1003400144","pt":1580649871052,"mc":[{"id":"1.168213437","rc":[{"batl":[[0,1.34,14.66],[1,1.35,182.34],[2,1.39,3.01]],"ltp":1.32,"tv":1722.49,"id":8444034}]}]}
{"op":"mcm","clk":"1003400713","pt":1580649874485,"mc":[{"id":"1.168213437","rc":[{"batl":[[0,1.35,182.34],[1,1.39,3.01],[2,1.66,579.81]],"ltp":1.32,"tv":1722.49,"id":8444034}]}]}
{"op":"mcm","clk":"1003401212","pt":1580649877383,"mc":[{"id":"1.168213437","rc":[{"batl":[[0,4.2,6.56],[1,1000,0.02]],"ltp":4.1,"tv":922.9,"id":10107989},{"batl":[[0,1.33,14.66],[1,1.35,182.34],[2,1.39,3.01]],"ltp":1.32,"tv":1722.49,"id":8444034}]}]}
{"op":"mcm","clk":"1003401608","pt":1580649879784,"mc":[{"id":"1.168213437","rc":[{"trd":[[1.31,160]],"batb":[[0,1.31,146.71]],"ltp":1.31,"tv":1882.49,"id":8444034}],"tv":2805.39}]}
{"op":"mcm","clk":"1003408715","pt":1580649922489,"mc":[{"id":"1.168213437","rc":[{"batl":[[0,1000,0.02],[1,1000,0]],"ltp":4.1,"tv":922.9,"id":10107989},{"batb":[[0,1.3,301.27],[1,1.27,342.27],[2,1.25,2.27]],"batl":[[0,1.39,3.01],[1,1.66,579.81],[2,1000,0.02]],"ltp":1.31,"tv":1882.49,"id":8444034}]}]}
{"op":"mcm","clk":"1003408821","pt":1580649923207,"mc":[{"id":"1.168213437","rc":[{"batb":[[0,3.35,69.32],[1,2.6,75.72],[2,2.2,75.72]],"ltp":4.1,"tv":922.9,"id":10107989},{"batb":[[0,1.27,342.27],[1,1.25,2.27],[2,1.23,2]],"ltp":1.31,"tv":1882.49,"id":8444034}]}]}
{"op":"mcm","clk":"1003410963","pt":1580649935718,"mc":[{"id":"1.168213437","rc":[{"batb":[[1,2.86,42.49],[2,2.16,3.21]],"batl":[[0,3.6,5.55],[1,1000,0.02]],"ltp":4.1,"tv":922.9,"id":10107989},{"batb":[[0,1.38,229.2],[1,1.32,274.29],[2,1.31,1248.88]],"batl":[[1,1.41,24.52],[2,1.43,228.41]],"ltp":1.31,"tv":1882.49,"id":8444034}]}]}
{"op":"mcm","clk":"1003413460","pt":1580649950569,"mc":[{"id":"1.168213437","rc":[{"batb":[[0,2.86,42.49],[1,2.16,3.21],[2,2.02,75.62]],"batl":[[0,1000,0.02],[1,1000,0]],"ltp":4.1,"tv":922.9,"id":10107989},{"batb":[[0,1.32,274.29],[1,1.25,2.27],[2,1.23,2]],"batl":[[1,1.66,579.81],[2,1000,0.02]],"ltp":1.31,"tv":1882.49,"id":8444034}]}]}
{"op":"mcm","clk":"1003414632","pt":1580649959103,"mc":[{"id":"1.168213437","rc":[{"batl":[[1,1000,0.02],[2,1000,0]],"ltp":1.31,"tv":1882.49,"id":8444034}]}]}
{"op":"mcm","clk":"1003414941","pt":1580649961251,"mc":[{"id":"1.168213437","rc":[{"trd":[[3.55,1.18]],"batb":[[0,2.96,5.96],[1,2.86,42.49],[2,2.16,3.21]],"batl":[[0,3.05,5.58],[1,3.15,104.97],[2,1000,0.02]],"ltp":3.55,"tv":924.08,"id":10107989},{"trd":[[1.39,5.16]],"batl":[[0,1.56,312.59]],"ltp":1.39,"tv":1885.5,"id":8444034}],"tv":2809.58}]}
{"op":"mcm","clk":"1003415037","pt":1580649962048,"mc":[{"id":"1.168213437","rc":[{"batb":[[2,2.4,66.88]],"ltp":3.55,"tv":924.08,"id":10107989},{"batb":[[0,1.49,163.11],[1,1.42,197.41],[2,1.25,2.27]],"ltp":1.39,"tv":1885.5,"id":8444034}]}]}
{"op":"mcm","clk":"1003415163","pt":1580649962961,"mc":[{"id":"1.168213437","rc":[{"batb":[[2,1.28,485.89]],"batl":[[1,1.82,469.11],[2,1000,0.02]],"ltp":1.39,"tv":1885.5,"id":8444034}]}]}
{"op":"mcm","clk":"1003416069","pt":1580649969166,"mc":[{"id":"1.168213437","rc":[{"trd":[[1.49,4]],"batb":[[0,1.49,161.11]],"ltp":1.49,"tv":1889.5,"id":8444034}],"tv":2813.58}]}
{"op":"mcm","clk":"1003416417","pt":1580649971389,"mc":[{"id":"1.168213437","rc":[{"batb":[[0,2.86,42.49],[1,2.4,66.88],[2,2.16,3.21]],"batl":[[0,3.15,104.97],[1,1000,0.02],[2,1000,0]],"ltp":3.55,"tv":924.08,"id":10107989},{"trd":[[1.49,24]],"batb":[[0,1.49,151.11]],"ltp":1.49,"tv":1909.5,"id":8444034}],"tv":2833.58}]}
{"op":"mcm","clk":"1003416539","pt":1580649972163,"mc":[{"id":"1.168213437","rc":[{"trd":[[1.49,38]],"batb":[[0,1.49,144.11]],"ltp":1.49,"tv":1923.5,"id":8444034}],"tv":2847.58}]}
{"op":"mcm","clk":"1003416628","pt":1580649972746,"mc":[{"id":"1.168213437","rc":[{"batl":[[0,1.5,4.2],[1,1.56,312.59],[2,1.82,469.11]],"ltp":1.49,"tv":1923.5,"id":8444034}]}]}
{"op":"mcm","clk":"1003416807","pt":1580649973877,"mc":[{"id":"1.168213437","rc":[{"batb":[[0,2.96,7.36],[1,2.86,42.49],[2,2.4,66.88]],"batl":[[0,3.05,5.39],[1,3.15,104.97],[2,1000,0.02]],"ltp":3.55,"tv":924.08,"id":10107989}]}]}
{"op":"mcm","clk":"1003417680","pt":1580649979662,"mc":[{"id":"1.168213437","rc":[{"batb":[[0,2.86,42.49],[1,2.4,66.88],[2,2.16,3.21]],"batl":[[0,1000,0.02],[1,3.15,0],[2,1000,0]],"ltp":3.55,"tv":924.08,"id":10107989},{"batl":[[1,1.82,469.11],[2,1000,0.02]],"ltp":1.49,"tv":1923.5,"id":8444034}]}]}
{"op":"mcm","clk":"1003417795","pt":1580649980361,"mc":[{"id":"1.168213437","rc":[{"batb":[[0,2.4,66.88],[1,2.16,3.21],[2,2.02,75.62]],"ltp":3.55,"tv":924.08,"id":10107989},{"batb":[[0,1.42,197.41],[1,1.28,485.89],[2,1.25,2.27]],"ltp":1.49,"tv":1923.5,"id":8444034}]}]}
{"op":"mcm","clk":"1003418332","pt":1580649983285,"mc":[{"id":"1.168213437","rc":[{"batb":[[0,2.42,66.64]],"ltp":3.55,"tv":924.08,"id":10107989}]}]}
{"op":"mcm","clk":"1003419330","pt":1580649989630,"mc":[{"id":"1.168213437","rc":[{"batb":[[0,3.1,84.11],[1,2.56,56.26],[2,2.42,66.64]],"batl":[[0,3.5,60.77],[1,1000,0.02]],"ltp":3.55,"tv":924.08,"id":10107989},{"batb":[[0,1.42,212.02],[1,1.4,151.93],[2,1.35,247.22]],"batl":[[0,1.44,13.27],[1,1.5,4.2],[2,1.52,672.94]],"ltp":1.49,"tv":1923.5,"id":8444034}]}]}
{"op":"mcm","clk":"1003419367","pt":1580649989908,"mc":[{"id":"1.168213437","rc":[{"batb":[[2,2.16,3.21]],"ltp":3.55,"tv":924.08,"id":10107989}]}]}
{"op":"mcm","clk":"1003421264","pt":1580650002132,"mc":[{"id":"1.168213437","rc":[{"trd":[[1.42,3.86]],"batb":[[0,1.42,210.09]],"ltp":1.42,"tv":1927.35,"id":8444034}],"tv":2851.43}]}
{"op":"mcm","clk":"1003422017","pt":1580650007172,"mc":[{"id":"1.168213437","rc":[{"batb":[[0,2.56,56.26],[1,2.16,3.21],[2,2.02,75.62]],"batl":[[0,1000,0.02],[1,1000,0]],"ltp":3.55,"tv":924.08,"id":10107989},{"batb":[[0,1.35,247.22],[1,1.28,485.89],[2,1.25,2.27]],"batl":[[0,1.5,4.2],[1,1.82,469.11],[2,1000,0.02]],"ltp":1.42,"tv":1927.35,"id":8444034}]}]}
{"op":"mcm","clk":"1003424760","pt":1580650025342,"mc":[{"id":"1.168213437","rc":[{"batb":[[1,1.25,2.27],[2,1.23,2]],"batl":[[1,1000,0.02],[2,1000,0]],"ltp":1.42,"tv":1927.35,"id":8444034}]}]}
{"op":"mcm","clk":"1003424910","pt":1580650026273,"mc":[{"id":"1.168213437","rc":[{"batb":[[0,3.5,53.47],[1,2.56,56.26],[2,2.16,3.21]],"batl":[[0,3.85,7.32],[1,1000,0.02]],"ltp":3.55,"tv":924.08,"id":10107989},{"batb":[[1,1.34,254.64],[2,1.25,2.27]],"batl":[[0,1.37,12.86],[1,1.4,133.67],[2,1.5,4.2]],"ltp":1.42,"tv":1927.35,"id":8444034}]}]}
{"op":"mcm","clk":"1003425094","pt":1580650027347,"mc":[{"id":"1.168213437","rc":[{"batb":[[0,3.5,116.1],[1,2.84,43.59]],"ltp":3.55,"tv":924.08,"id":10107989},{"batb":[[2,1.3,305.13]],"ltp":1.42,"tv":1927.35,"id":8444034}]}]}
{"op":"mcm","clk":"1003425760","pt":1580650031739,"mc":[{"id":"1.168213437","rc":[{"batl":[[2,1.49,113.99]],"ltp":1.42,"tv":1927.35,"id":8444034}]}]}
{"op":"mcm","clk":"1003425798","pt":1580650031952,"mc":[{"id":"1.168213437","rc":[{"batl":[[2,1.5,4.2]],"ltp":1.42,"tv":1927.35,"id":8444034}]}]}
{"op":"mcm","clk":"1003427776","pt":1580650045358,"mc":[{"id":"1.168213437","rc":[{"batb":[[0,2.84,43.59],[1,2.16,3.21],[2,2.02,75.62]],"batl":[[0,1000,0.02],[1,1000,0]],"ltp":3.55,"tv":924.08,"id":10107989},{"batb":[[0,1.3,305.13],[1,1.25,2.27],[2,1.23,2]],"batl":[[0,1.5,4.2],[1,1.71,542.06],[2,1000,0.02]],"ltp":1.42,"tv":1927.35,"id":8444034}]}]}
{"op":"mcm","clk":"1003428282","pt":1580650048614,"mc":[{"id":"1.168213437","rc":[{"batb":[[0,2.82,43.75]],"ltp":3.55,"tv":924.08,"id":10107989},{"batb":[[0,1.3,304.66]],"ltp":1.42,"tv":1927.35,"id":8444034}]}]}
{"op":"mcm","clk":"1003431626","pt":1580650071737,"mc":[{"id":"1.168213437","rc":[{"batl":[[0,4.4,4.14],[1,1000,0.02]],"ltp":3.55,"tv":924.08,"id":10107989},{"batb":[[1,1.28,290.99],[2,1.25,2.27]],"batl":[[0,1.31,20.7],[1,1.33,247.44],[2,1.5,4.2]],"ltp":1.42,"tv":1927.35,"id":8444034}]}]}
{"op":"mcm","clk":"1003431757","pt":1580650072544,"mc":[{"id":"1.168213437","rc":[{"batb":[[0,3.95,95.13],[1,3.25,76.71],[2,2.16,3.21]],"ltp":3.55,"tv":924.08,"id":10107989},{"batb":[[2,1.25,372.23]],"ltp":1.42,"tv":1927.35,"id":8444034}]}]}
{"op":"mcm","clk":"1003432068","pt":1580650074623,"mc":[{"id":"1.168213437","rc":[{"batb":[[2,2.2,75.72]],"ltp":3.55,"tv":924.08,"id":10107989}]}]}
{"op":"mcm","clk":"1003432659","pt":1580650078462,"mc":[{"id":"1.168213437","rc":[{"batb":[[0,1.3,326.66]],"ltp":1.42,"tv":1927.35,"id":8444034}]}]}
{"op":"mcm","clk":"1003433611","pt":1580650084768,"mc":[{"id":"1.168213437","rc":[{"batb":[[0,1.3,304.66]],"ltp":1.42,"tv":1927.35,"id":8444034}]}]}
{"op":"mcm","clk":"1003434190","pt":1580650088470,"mc":[{"id":"1.168213437","rc":[{"batl":[[0,1000,0.02],[1,1000,0]],"ltp":3.55,"tv":924.08,"id":10107989},{"trd":[[1.31,201.4]],"batb":[[0,1.31,1.3],[1,1.3,304.66]],"batl":[[0,1.5,4.2],[1,1.71,542.06],[2,1000,0.02]],"ltp":1.31,"tv":1968.75,"id":8444034}],"tv":2892.83}]}
{"op":"mcm","clk":"1003434261","pt":1580650088903,"mc":[{"id":"1.168213437","rc":[{"batb":[[0,3.25,76.71],[1,2.2,75.72],[2,2.16,3.21]],"ltp":3.55,"tv":924.08,"id":10107989},{"batb":[[1,1.25,371.84],[2,1.23,2]],"ltp":1.31,"tv":1968.75,"id":8444034}]}]}
{"op":"mcm","clk":"1003435844","pt":1580650098554,"mc":[{"id":"1.168213437","rc":[{"batb":[[0,3.4,6.68],[1,3.3,104.8],[2,3.25,76.71]],"batl":[[0,3.55,8.07],[1,4.4,465.5],[2,1000,0.02]],"ltp":3.55,"tv":924.08,"id":10107989}]}]}
{"op":"mcm","clk":"1003435993","pt":1580650099560,"mc":[{"id":"1.168213437","rc":[{"batb":[[0,3.3,104.8],[1,3.25,76.71],[2,2.24,81.04]],"batl":[[0,4.4,465.5],[1,1000,0.02],[2,1000,0]],"ltp":3.55,"tv":924.08,"id":10107989},{"batb":[[0,1.4,212.13],[1,1.31,1.3],[2,1.27,334.87]],"ltp":1.31,"tv":1968.75,"id":8444034}]}]}
{"op":"mcm","clk":"1003436348","pt":1580650101697,"mc":[{"id":"1.168213437","rc":[{"batb":[[0,3.4,6.68],[1,3.3,104.8],[2,3.25,76.71]],"batl":[[0,3.55,8.07],[1,4.4,465.5],[2,1000,0.02]],"ltp":3.55,"tv":924.08,"id":10107989}]}]}
{"op":"mcm","clk":"1003437231","pt":1580650107568,"mc":[{"id":"1.168213437","rc":[{"batb":[[1,1.27,334.87],[2,1.25,2.27]],"ltp":1.31,"tv":1968.75,"id":8444034}]}]}
{"op":"mcm","clk":"1003437701","pt":1580650110698,"mc":[{"id":"1.168213437","rc":[{"trd":[[3.4,0.87]],"batb":[[0,3.4,5.81]],"ltp":3.4,"tv":924.95,"id":10107989},{"trd":[[1.42,5.95]],"ltp":1.42,"tv":1970.84,"id":8444034}],"tv":2895.79}]}
{"op":"mcm","clk":"1003438580","pt":1580650116315,"mc":[{"id":"1.168213437","rc":[{"trd":[[3.4,0.89]],"batb":[[0,3.4,5.79]],"ltp":3.4,"tv":924.97,"id":10107989},{"trd":[[1.42,5.99]],"ltp":1.42,"tv":1970.88,"id":8444034}],"tv":2895.85}]}
{"op":"mcm","clk":"1003439293","pt":1580650120911,"mc":[{"id":"1.168213437","rc":[{"batb":[[0,3.3,104.8],[1,3.25,76.71],[2,2.24,81.04]],"batl":[[0,4.4,465.5],[1,1000,0.02],[2,1000,0]],"ltp":3.4,"tv":924.97,"id":10107989}]}]}
{"op":"mcm","clk":"1003439675","pt":1580650123588,"mc":[{"id":"1.168213437","rc":[{"batb":[[0,2.24,81.04],[1,2.16,3.21],[2,2.02,75.62]],"batl":[[0,1000,0.02],[1,1000,0]],"ltp":3.4,"tv":924.97,"id":10107989},{"batb":[[0,1.27,334.87],[1,1.25,2.27],[2,1.23,2]],"ltp":1.42,"tv":1970.88,"id":8444034}]}]}
{"op":"mcm","clk":"1003441445","pt":1580650135378,"mc":[{"id":"1.168213437","rc":[{"batb":[[1,1.25,507.36]],"ltp":1.42,"tv":1970.88,"id":8444034}]}]}
{"op":"mcm","clk":"1003442699","pt":1580650143501,"mc":[{"id":"1.168213437","rc":[{"batb":[[0,4.5,5.56],[1,2.24,81.04],[2,2.16,3.21]],"batl":[[0,4.7,4.73],[1,1000,0.02]],"ltp":3.4,"tv":924.97,"id":10107989},{"batb":[[1,1.25,2.27],[2,1.24,433.9]],"batl":[[0,1.31,439.43],[1,1.5,4.2]],"ltp":1.42,"tv":1970.88,"id":8444034}]}]}
{"op":"mcm","clk":"1003442828","pt":1580650144320,"mc":[{"id":"1.168213437","rc":[{"batb":[[1,4.2,83.09],[2,4,91.35]],"ltp":3.4,"tv":924.97,"id":10107989},{"batb":[[2,1.24,815.51]],"ltp":1.42,"tv":1970.88,"id":8444034}]}]}
{"op":"mcm","clk":"1003443196","pt":1580650146506,"mc":[{"id":"1.168213437","rc":[{"batl":[[2,1.62,614.4]],"ltp":1.42,"tv":1970.88,"id":8444034}]}]}
{"op":"mcm","clk":"1003447220","pt":1580650172616,"mc":[{"id":"1.168213437","rc":[{"batb":[[0,4,91.35],[1,2.2,75.72],[2,2.16,3.21]],"batl":[[0,1000,0.02],[1,1000,0]],"ltp":3.4,"tv":924.97,"id":10107989},{"batb":[[0,1.25,2.27],[1,1.24,381.61],[2,1.23,2]],"batl":[[0,1.5,4.2],[1,1.62,614.4],[2,1000,0.02]],"ltp":1.42,"tv":1970.88,"id":8444034}]}]}
{"op":"mcm","clk":"1003447870","pt":1580650176387,"mc":[{"id":"1.168213437","rc":[{"batb":[[0,1.24,381.61],[1,1.23,2],[2,1.18,549.82]],"ltp":1.42,"tv":1970.88,"id":8444034}]}]}
{"op":"mcm","clk":"1003448335","pt":1580650179677,"mc":[{"id":"1.168213437","rc":[{"batl":[[0,5.1,6.67],[1,5.3,55.02],[2,1000,0.02]],"ltp":3.4,"tv":924.97,"id":10107989},{"batl":[[0,1.26,16.42],[1,1.27,317.29],[2,1.5,4.2]],"ltp":1.42,"tv":1970.88,"id":8444034}]}]}
{"op":"mcm","clk":"1003448472","pt":1580650180602,"mc":[{"id":"1.168213437","rc":[{"batb":[[0,4.5,68.61],[1,4.3,77.19],[2,4.1,5.14]],"ltp":3.4,"tv":924.97,"id":10107989},{"batb":[[2,1.22,437]],"ltp":1.42,"tv":1970.88,"id":8444034}]}]}
{"op":"mcm","clk":"1003448513","pt":1580650180871,"mc":[{"id":"1.168213437","rc":[{"batb":[[2,2.2,75.72]],"ltp":3.4,"tv":924.97,"id":10107989}]}]}
{"op":"mcm","clk":"1003448811","pt":1580650183001,"mc":[{"id":"1.168213437","rc":[{"batb":[[2,2.6,75.72]],"ltp":3.4,"tv":924.97,"id":10107989}]}]}
{"op":"mcm","clk":"1003450750","pt":1580650195631,"mc":[{"id":"1.168213437","rc":[{"batb":[[0,4.3,77.19],[1,2.6,75.72],[2,2.2,75.72]],"batl":[[0,1000,0.02],[1,5.3,0],[2,1000,0]],"ltp":3.4,"tv":924.97,"id":10107989},{"batb":[[0,1.23,2],[1,1.22,437],[2,1.18,549.82]],"batl":[[0,1.5,4.2],[1,1.62,614.4],[2,1000,0.02]],"ltp":1.42,"tv":1970.88,"id":8444034}]}]}
{"op":"mcm","clk":"1003451840","pt":1580650202167,"mc":[{"id":"1.168213437","rc":[{"batb":[[2,1.05,378.82]],"batl":[[1,1000,0.02],[2,1000,0]],"ltp":1.42,"tv":1970.88,"id":8444034}]}]}
{"op":"mcm","clk":"1003452128","pt":1580650203545,"mc":[{"id":"1.168213437","rc":[{"batl":[[0,5.5,4.46],[1,6,52.76],[2,1000,0.02]],"ltp":3.4,"tv":924.97,"id":10107989},{"batb":[[2,1.2,263.88]],"batl":[[0,1.24,269.63],[1,1.5,4.2],[2,1000,0.02]],"ltp":1.42,"tv":1970.88,"id":8444034}]}]}
{"op":"mcm","clk":"1003452352","pt":1580650204551,"mc":[{"id":"1.168213437","rc":[{"batb":[[0,4.9,56.02],[1,4.7,63.1],[2,2.6,75.72]],"ltp":3.4,"tv":924.97,"id":10107989}]}]}
{"op":"mcm","clk":"1003452699","pt":1580650206200,"mc":[{"id":"1.168213437","rc":[{"batl":[[2,1.55,690.76]],"ltp":1.42,"tv":1970.88,"id":8444034}]}]}
{"op":"mcm","clk":"1003452910","pt":1580650207284,"mc":[{"id":"1.168213437","rc":[{"batb":[[2,3,75.72]],"ltp":3.4,"tv":924.97,"id":10107989}]}]}
{"op":"mcm","clk":"1003455320","pt":1580650222445,"mc":[{"id":"1.168213437","rc":[{"batl":[[0,1000,0.02],[1,6,0],[2,1000,0]],"ltp":3.4,"tv":924.97,"id":10107989},{"batb":[[2,1.19,516.73]],"batl":[[0,1.5,4.2],[1,1.55,690.76],[2,1000,0.02]],"ltp":1.42,"tv":1970.88,"id":8444034}]}]}
{"op":"mcm","clk":"1003455372","pt":1580650222831,"mc":[{"id":"1.168213437","rc":[{"batb":[[0,4.7,63.1],[1,3,75.72],[2,2.6,75.72]],"ltp":3.4,"tv":924.97,"id":10107989},{"batb":[[1,1.19,516.73],[2,1.14,610.45]],"ltp":1.42,"tv":1970.88,"id":8444034}]}]}
{"op":"mcm","clk":"1003456939","pt":1580650233336,"mc":[{"id":"1.168213437","rc":[{"batb":[[2,1.05,378.72]],"ltp":1.42,"tv":1970.88,"id":8444034}]}]}
{"op":"mcm","clk":"1003457157","pt":1580650234630,"mc":[{"id":"1.168213437","rc":[{"batl":[[0,5.3,8.41],[1,5.5,68.67],[2,1000,0.02]],"ltp":3.4,"tv":924.97,"id":10107989},{"batl":[[0,1.25,7.06],[1,1.26,316.87],[2,1.5,4.2]],"ltp":1.42,"tv":1970.88,"id":8444034}]}]}
{"op":"mcm","clk":"1003457314","pt":1580650235643,"mc":[{"id":"1.168213437","rc":[{"batb":[[1,4.4,73.57],[2,3,75.72]],"ltp":3.4,"tv":924.97,"id":10107989},{"batb":[[0,1.23,405.8],[1,1.2,480.85]],"ltp":1.42,"tv":1970.88,"id":8444034}]}]}
{"op":"mcm","clk":"1003457532","pt":1580650237142,"mc":[{"id":"1.168213437","rc":[{"batb":[[2,1.16,576.13]],"ltp":1.42,"tv":1970.88,"id":8444034}]}]}
{"op":"mcm","clk":"1003459368","pt":1580650249551,"mc":[{"id":"1.168213437","rc":[{"batl":[[0,1000,0.02],[1,5.5,0],[2,1000,0]],"ltp":3.4,"tv":924.97,"id":10107989},{"batl":[[0,1.5,4.2],[1,1.55,690.76],[2,1000,0.02]],"ltp":1.42,"tv":1970.88,"id":8444034}]}]}
{"op":"mcm","clk":"1003459434","pt":1580650249940,"mc":[{"id":"1.168213437","rc":[{"batb":[[0,4.4,73.57],[1,3,75.72],[2,2.6,75.72]],"ltp":3.4,"tv":924.97,"id":10107989},{"batb":[[0,1.23,2]],"ltp":1.42,"tv":1970.88,"id":8444034}]}]}
{"op":"mcm","clk":"1003460599","pt":1580650257652,"mc":[{"id":"1.168213437","rc":[{"batb":[[1,2.6,75.72],[2,2.2,75.72]],"batl":[[0,5,4.8],[1,1000,0.02]],"ltp":3.4,"tv":924.97,"id":10107989},{"batb":[[0,1.25,19.18],[1,1.24,298.41],[2,1.23,2]],"batl":[[0,1.27,14.37],[1,1.28,298.86],[2,1.5,4.2]],"ltp":1.42,"tv":1970.88,"id":8444034}]}]}
{"op":"mcm","clk":"1003460744","pt":1580650258578,"mc":[{"id":"1.168213437","rc":[{"batb":[[1,4.2,83.17],[2,2.6,75.72]],"ltp":3.4,"tv":924.97,"id":10107989},{"batb":[[0,1.25,383.08]],"ltp":1.42,"tv":1970.88,"id":8444034}]}]}
{"op":"mcm","clk":"1003462738","pt":1580650271611,"mc":[{"id":"1.168213437","rc":[{"batb":[[0,4.2,83.17],[1,2.6,75.72],[2,2.2,75.72]],"batl":[[0,1000,0.02],[1,1000,0]],"ltp":3.4,"tv":924.97,"id":10107989},{"batb":[[0,1.23,2],[1,1.22,435.27],[2,1.16,576.23]],"batl":[[0,1.5,4.2],[1,1.55,690.76],[2,1000,0.02]],"ltp":1.42,"tv":1970.88,"id":8444034}]}]}
{"op":"mcm","clk":"1003464254","pt":1580650280693,"mc":[{"id":"1.168213437","rc":[{"batb":[[0,4.4,5.71],[1,4.2,83.17],[2,3.95,94.02]],"ltp":3.4,"tv":924.97,"id":10107989},{"batb":[[0,1.28,12.98],[1,1.27,334.56],[2,1.26,278.96]],"batl":[[0,1.3,250.27],[1,1.5,4.2],[2,1.55,690.76]],"ltp":1.42,"tv":1970.88,"id":8444034}]}]}
{"op":"mcm","clk":"1003464306","pt":1580650281016,"mc":[{"id":"1.168213437","rc":[{"batl":[[0,1.29,17.68],[1,1.3,250.27],[2,1.5,4.2]],"ltp":1.42,"tv":1970.88,"id":8444034}]}]}
{"op":"mcm","clk":"1003466694","pt":1580650295411,"mc":[{"id":"1.168213437","rc":[{"batb":[[0,3.95,94.02],[1,2.6,75.72],[2,2.2,75.72]],"ltp":3.4,"tv":924.97,"id":10107989},{"batb":[[0,1.24,387.27],[1,1.23,2],[2,1.16,576.23]],"batl":[[1,1.5,4.2],[2,1.55,690.76]],"ltp":1.42,"tv":1970.88,"id":8444034}]}]}
{"op":"mcm","clk":"1003467944","pt":1580650303538,"mc":[{"id":"1.168213437","rc":[{"batb":[[2,1.05,378.82]],"batl":[[0,1.5,4.2],[1,1.55,690.76],[2,1000,0.02]],"ltp":1.42,"tv":1970.88,"id":8444034}]}]}
{"op":"mcm","clk":"1003468103","pt":1580650304650,"mc":[{"id":"1.168213437","rc":[{"batb":[[0,4.1,4.95],[1,3.95,94.02],[2,2.6,75.72]],"batl":[[0,4.3,7.68],[1,4.5,82.22],[2,1000,0.02]],"ltp":3.4,"tv":924.97,"id":10107989},{"batl":[[0,1.33,223.28],[1,1.5,4.2],[2,1.55,690.76]],"ltp":1.42,"tv":1970.88,"id":8444034}]}]}
{"op":"mcm","clk":"1003468183","pt":1580650305140,"mc":[{"id":"1.168213437","rc":[{"batb":[[2,3.35,71.36]],"ltp":3.4,"tv":924.97,"id":10107989},{"batb":[[0,1.29,307.17],[1,1.25,363.98],[2,1.23,2]],"ltp":1.42,"tv":1970.88,"id":8444034}]}]}
{"op":"mcm","clk":"1003468402","pt":1580650306616,"mc":[{"id":"1.168213437","rc":[{"trd":[[4.3,5.35]],"batl":[[0,4.3,2.33]],"ltp":4.3,"tv":930.32,"id":10107989},{"trd":[[1.3,20.64]],"ltp":1.3,"tv":1988.56,"id":8444034}],"tv":2918.88}]}
{"op":"mcm","clk":"1003469855","pt":1580650315737,"mc":[{"id":"1.168213437","rc":[{"trd":[[4.3,7.68]],"batl":[[0,4.5,82.22],[1,1000,0.02],[2,1000,0]],"ltp":4.3,"tv":932.65,"id":10107989},{"trd":[[1.3,28.34]],"batl":[[0,1.3,75.47],[1,1.33,223.28],[2,1.5,4.2]],"ltp":1.3,"tv":1996.27,"id":8444034}],"tv":2928.92}]}
{"op":"mcm","clk":"1003470001","pt":1580650316753,"mc":[{"id":"1.168213437","rc":[{"batb":[[0,3.95,94.02],[1,3.35,71.36],[2,2.6,75.72]],"ltp":4.3,"tv":932.65,"id":10107989}]}]}
{"op":"mcm","clk":"1003470441","pt":1580650319265,"mc":[{"id":"1.168213437","rc":[{"trd":[[1.3,34.76]],"batl":[[0,1.3,72.27]],"ltp":1.3,"tv":2002.69,"id":8444034}],"tv":2935.34}]}
{"op":"mcm","clk":"1003470519","pt":1580650319747,"mc":[{"id":"1.168213437","rc":[{"batl":[[0,4.4,5.92],[1,4.5,82.22],[2,1000,0.02]],"ltp":4.3,"tv":932.65,"id":10107989},{"batl":[[1,1.31,14.96],[2,1.33,223.28]],"ltp":1.3,"tv":2002.69,"id":8444034}]}]}
{"op":"mcm","clk":"1003470706","pt":1580650321044,"mc":[{"id":"1.168213437","rc":[{"batl":[[0,1.31,14.96],[1,1.33,223.28],[2,1.5,4.2]],"ltp":1.3,"tv":2002.69,"id":8444034}]}]}
{"op":"mcm","clk":"1003470931","pt":1580650322540,"mc":[{"id":"1.168213437","rc":[{"batl":[[2,1.34,3.12]],"ltp":1.3,"tv":2002.69,"id":8444034}]}]}
{"op":"mcm","clk":"1003471217","pt":1580650324151,"mc":[{"id":"1.168213437","rc":[{"trd":[[1.29,144.53]],"batb":[[0,1.29,234.9]],"ltp":1.29,"tv":2147.22,"id":8444034}],"tv":3079.87}]}
{"op":"mcm","clk":"1003471417","pt":1580650325452,"mc":[{"id":"1.168213437","rc":[{"batl":[[2,1.5,4.2]],"ltp":1.29,"tv":2147.22,"id":8444034}]}]}
{"op":"mcm","clk":"1003471493","pt":1580650325992,"mc":[{"id":"1.168213437","rc":[{"batl":[[0,4.5,82.22],[1,1000,0.02],[2,1000,0]],"ltp":4.3,"tv":932.65,"id":10107989},{"batl":[[0,1.33,223.28],[1,1.5,4.2],[2,1.55,690.76]],"ltp":1.29,"tv":2147.22,"id":8444034}]}]}
{"op":"mcm","clk":"1003471760","pt":1580650327696,"mc":[{"id":"1.168213437","rc":[{"batb":[[0,4,92.77],[1,3.95,94.02],[2,3.35,71.36]],"ltp":4.3,"tv":932.65,"id":10107989}]}]}
{"op":"mcm","clk":"1003471903","pt":1580650328560,"mc":[{"id":"1.168213437","rc":[{"batb":[[1,3.35,70.5],[2,2.6,75.72]],"ltp":4.3,"tv":932.65,"id":10107989},{"batl":[[1,1.41,3.12],[2,1.5,4.2]],"ltp":1.29,"tv":2147.22,"id":8444034}]}]}
{"op":"mcm","clk":"1003471954","pt":1580650328870,"mc":[{"id":"1.168213437","rc":[{"batl":[[0,4.4,5.92],[1,4.5,82.22],[2,1000,0.02]],"ltp":4.3,"tv":932.65,"id":10107989},{"batl":[[0,1.31,14.96],[1,1.33,223.28],[2,1.41,3.12]],"ltp":1.29,"tv":2147.22,"id":8444034}]}]}
{"op":"mcm","clk":"1003472819","pt":1580650334510,"mc":[{"id":"1.168213437","rc":[{"batl":[[2,1.5,4.2]],"ltp":1.29,"tv":2147.22,"id":8444034}]}]}
{"op":"mcm","clk":"1003473185","pt":1580650336663,"mc":[{"id":"1.168213437","rc":[{"batb":[[1,3.45,65.78],[2,3.35,70.5]],"ltp":4.3,"tv":932.65,"id":10107989},{"batb":[[1,1.28,320.24],[2,1.25,363.98]],"ltp":1.29,"tv":2147.22,"id":8444034}]}]}
{"op":"mcm","clk":"1003473336","pt":1580650337582,"mc":[{"id":"1.168213437","rc":[{"batb":[[0,4,88.6],[2,2.6,75.72]],"ltp":4.3,"tv":932.65,"id":10107989},{"batb":[[0,1.28,320.24],[1,1.25,363.98],[2,1.23,2]],"batl":[[2,1.49,3.12]],"ltp":1.29,"tv":2147.22,"id":8444034}]}]}
{"op":"mcm","clk":"1003476582","pt":1580650358540,"mc":[{"id":"1.168213437","rc":[{"batb":[[0,4.1,84.43],[1,3.55,61.06]],"ltp":4.3,"tv":932.65,"id":10107989},{"batb":[[0,1.27,331.17],[1,1.24,382.55]],"ltp":1.29,"tv":2147.22,"id":8444034}]}]}
{"op":"mcm","clk":"1003479166","pt":1580650375268,"mc":[{"id":"1.168213437","rc":[{"trd":[[1.31,205.26]],"batl":[[0,1.31,13.03]],"ltp":1.31,"tv":2151.08,"id":8444034}],"tv":3083.73}]}
{"op":"mcm","clk":"1003480801","pt":1580650385466,"mc":[{"id":"1.168213437","rc":[{"batl":[[0,4.5,82.22],[1,1000,0.02],[2,1000,0]],"ltp":4.3,"tv":932.65,"id":10107989},{"trd":[[1.31,226.48]],"batl":[[0,1.33,223.28],[1,1.49,3.12],[2,1.5,4.2]],"ltp":1.31,"tv":2172.3,"id":8444034}],"tv":3104.95}]}
{"op":"mcm","clk":"1003481320","pt":1580650388560,"mc":[{"id":"1.168213437","rc":[{"batl":[[0,4.3,3.82],[1,4.5,82.22],[2,1000,0.02]],"ltp":4.3,"tv":932.65,"id":10107989},{"batl":[[0,1.32,22.81],[1,1.33,223.28],[2,1.49,3.12]],"ltp":1.31,"tv":2172.3,"id":8444034}]}]}
{"op":"mcm","clk":"1003481489","pt":1580650389548,"mc":[{"id":"1.168213437","rc":[{"batl":[[0,1000,0.02],[1,4.5,0],[2,1000,0]],"ltp":4.3,"tv":932.65,"id":10107989},{"batl":[[0,1.49,3.12],[1,1.5,4.2],[2,1.55,690.76]],"ltp":1.31,"tv":2172.3,"id":8444034}]}]}
{"op":"mcm","clk":"1003481590","pt":1580650390191,"mc":[{"id":"1.168213437","rc":[{"batb":[[0,3.55,61.06],[1,2.6,75.72],[2,2.2,75.72]],"ltp":4.3,"tv":932.65,"id":10107989},{"batb":[[0,1.24,382.55],[1,1.23,2],[2,1.18,549.82]],"ltp":1.31,"tv":2172.3,"id":8444034}]}]}
{"op":"mcm","clk":"1003482125","pt":1580650393381,"mc":[{"id":"1.168213437","rc":[{"batb":[[0,3.65,56.49]],"ltp":4.3,"tv":932.65,"id":10107989}]}]}
{"op":"mcm","clk":"1003483959","pt":1580650404699,"mc":[{"id":"1.168213437","rc":[{"batl":[[0,5.1,85.84],[1,1000,0.02]],"ltp":4.3,"tv":932.65,"id":10107989},{"batb":[[0,1.26,18.98],[1,1.24,382.55],[2,1.23,2]],"batl":[[0,1.28,30.85],[1,1.29,3137.93],[2,1.32,13.42]],"ltp":1.31,"tv":2172.3,"id":8444034}]}]}
{"op":"mcm","clk":"1003483993","pt":1580650404928,"mc":[{"id":"1.168213437","rc":[{"batl":[[1,1.29,289.33],[2,1.49,3.12]],"ltp":1.31,"tv":2172.3,"id":8444034}]}]}
{"op":"mcm","clk":"1003484231","pt":1580650406286,"mc":[{"id":"1.168213437","rc":[{"batb":[[0,4.6,66.33],[1,4,91.19],[2,2.6,75.72]],"ltp":4.3,"tv":932.65,"id":10107989}]}]}
{"op":"mcm","clk":"1003486803","pt":1580650420628,"mc":[{"id":"1.168213437","rc":[{"batb":[[0,4,91.19],[1,2.6,75.72],[2,2.2,75.72]],"batl":[[0,1000,0.02],[1,1000,0]],"ltp":4.3,"tv":932.65,"id":10107989},{"batb":[[0,1.23,2],[1,1.22,430.23],[2,1.18,549.82]],"batl":[[0,1.49,3.12],[1,1.5,4.2],[2,1.55,690.76]],"ltp":1.31,"tv":2172.3,"id":8444034}]}]}
{"op":"mcm","clk":"1003487700","pt":1580650425342,"mc":[{"id":"1.168213437","rc":[{"batb":[[2,1.1,378.82]],"ltp":1.31,"tv":2172.3,"id":8444034}]}]}
{"op":"mcm","clk":"1003487945","pt":1580650426686,"mc":[{"id":"1.168213437","rc":[{"trd":[[5.1,0.37]],"batb":[[0,5.1,5.06],[1,4,91.19],[2,2.6,75.72]],"batl":[[0,5.7,95.24],[1,1000,0.02]],"ltp":5.1,"tv":933.02,"id":10107989},{"trd":[[1.25,1.52]],"batb":[[0,1.23,20.54]],"batl":[[0,1.26,384.41],[1,1.49,3.12],[2,1.5,4.2]],"ltp":1.25,"tv":2173.82,"id":8444034}],"tv":3106.84}]}
{"op":"mcm","clk":"1003488131","pt":1580650427622,"mc":[{"id":"1.168213437","rc":[{"batb":[[1,4.9,57.36],[2,4.4,73.65]],"ltp":5.1,"tv":933.02,"id":10107989},{"batb":[[2,1.2,464.24]],"ltp":1.25,"tv":2173.82,"id":8444034}]}]}
{"op":"mcm","clk":"1003489886","pt":1580650436918,"mc":[{"id":"1.168213437","rc":[{"batb":[[0,4.9,57.36],[1,4.4,73.65],[2,3,75.72]],"ltp":5.1,"tv":933.02,"id":10107989},{"batb":[[0,1.23,2]],"ltp":1.25,"tv":2173.82,"id":8444034}]}]}
{"op":"mcm","clk":"1003490495","pt":1580650440327,"mc":[{"id":"1.168213437","rc":[{"batb":[[0,4.4,73.65],[1,3,75.72],[2,2.6,75.72]],"batl":[[0,1000,0.02],[1,1000,0]],"ltp":5.1,"tv":933.02,"id":10107989},{"batb":[[1,1.2,464.24],[2,1.14,610.45]],"batl":[[0,1.49,3.12],[1,1.5,4.2],[2,1.55,690.76]],"ltp":1.25,"tv":2173.82,"id":8444034}]}]}
{"op":"mcm","clk":"1003492269","pt":1580650450578,"mc":[{"id":"1.168213437","rc":[{"trd":[[5.4,0.46]],"batb":[[0,5.5,3.69],[1,5.1,132.84],[2,4.4,73.65]],"batl":[[0,6,29.37],[1,1000,0.02]],"ltp":5.4,"tv":933.48,"id":10107989},{"trd":[[1.23,2]],"batb":[[0,1.21,21.53],[1,1.2,611.1]],"ltp":1.23,"tv":2175.82,"id":8444034}],"tv":3109.3}]}
{"op":"mcm","clk":"1003492443","pt":1580650451552,"mc":[{"id":"1.168213437","rc":[{"batb":[[1,5.1,183.98],[2,4.7,62.16]],"ltp":5.4,"tv":933.48,"id":10107989}]}]}
{"op":"mcm","clk":"1003494091","pt":1580650460884,"mc":[{"id":"1.168213437","rc":[{"batb":[[0,5.1,183.98],[1,4.7,62.16],[2,3,75.72]],"ltp":5.4,"tv":933.48,"id":10107989},{"batb":[[0,1.2,611.1],[1,1.14,610.45],[2,1.05,378.72]],"ltp":1.23,"tv":2175.82,"id":8444034}]}]}
{"op":"mcm","clk":"1003494591","pt":1580650463716,"mc":[{"id":"1.168213437","rc":[{"batb":[[0,5.5,3.69],[1,5.1,183.98],[2,4.7,62.16]],"ltp":5.4,"tv":933.48,"id":10107989},{"batb":[[0,1.21,23.59],[1,1.2,611.1],[2,1.14,610.45]],"ltp":1.23,"tv":2175.82,"id":8444034}]}]}
{"op":"mcm","clk":"1003495023","pt":1580650466267,"mc":[{"id":"1.168213437","rc":[{"batb":[[0,5.1,51.14],[1,4.7,62.16],[2,3,75.72]],"batl":[[0,1000,0.02],[1,1000,0]],"ltp":5.4,"tv":933.48,"id":10107989},{"batb":[[0,1.2,464.24],[1,1.14,610.45],[2,1.05,378.72]],"ltp":1.23,"tv":2175.82,"id":8444034}]}]}
{"op":"mcm","clk":"1003495235","pt":1580650467450,"mc":[{"id":"1.168213437","rc":[{"batb":[[0,4.7,62.16],[1,3,75.72],[2,2.6,75.72]],"ltp":5.4,"tv":933.48,"id":10107989}]}]}
{"op":"mcm","clk":"1003497758","pt":1580650481464,"mc":[{"id":"1.168213437","rc":[{"batb":[[0,1.21,69.07],[1,1.2,464.24],[2,1.14,610.45]],"ltp":1.23,"tv":2175.82,"id":8444034}]}]}
{"op":"mcm","clk":"1003498888","pt":1580650487584,"mc":[{"id":"1.168213437","rc":[{"batb":[[2,1.05,378.72]],"ltp":1.23,"tv":2175.82,"id":8444034}]}]}
{"op":"mcm","clk":"1003499051","pt":1580650488458,"mc":[{"id":"1.168213437","rc":[{"batb":[[0,5.1,3.75],[1,4.7,62.16],[2,3,75.72]],"batl":[[0,5.3,4.13],[1,1000,0.02]],"ltp":5.4,"tv":933.48,"id":10107989},{"batb":[[0,1.21,649.34]],"batl":[[0,1.26,371.39],[1,1.49,3.12],[2,1.5,4.2]],"ltp":1.23,"tv":2175.82,"id":8444034}]}]}
{"op":"mcm","clk":"1003499271","pt":1580650489610,"mc":[{"id":"1.168213437","rc":[{"batb":[[2,4.2,80.18]],"ltp":5.4,"tv":933.48,"id":10107989},{"batb":[[0,1.23,408.04],[1,1.21,1094.84],[2,1.05,378.82]],"ltp":1.23,"tv":2175.82,"id":8444034}]}]}
{"op":"mcm","clk":"1003499548","pt":1580650491091,"mc":[{"id":"1.168213437","rc":[{"batb":[[2,1.16,576.23]],"ltp":1.23,"tv":2175.82,"id":8444034}]}]}
{"op":"mcm","clk":"1003500875","pt":1580650498127,"mc":[{"id":"1.168213437","rc":[{"batb":[[1,1.21,1025.77]],"ltp":1.23,"tv":2175.82,"id":8444034}]}]}
{"op":"mcm","clk":"1003502668","pt":1580650507424,"mc":[{"id":"1.168213437","rc":[{"batb":[[0,4.2,80.18],[1,3,75.72],[2,2.6,75.72]],"batl":[[0,1000,0.02],[1,1000,0]],"ltp":5.4,"tv":933.48,"id":10107989},{"batb":[[0,1.21,445.5],[1,1.16,576.23],[2,1.05,378.72]],"batl":[[0,1.49,3.12],[1,1.5,4.2],[2,1.55,690.76]],"ltp":1.23,"tv":2175.82,"id":8444034}]}]}
{"op":"mcm","clk":"1003504954","pt":1580650518717,"mc":[{"id":"1.168213437","rc":[{"batb":[[1,1.05,378.82],[2,1.03,387.52]],"ltp":1.23,"tv":2175.82,"id":8444034}]}]}
{"op":"mcm","clk":"1003505401","pt":1580650520684,"mc":[{"id":"1.168213437","rc":[{"batb":[[0,5.5,3.68],[1,5.3,64.61],[2,5,54.45]],"batl":[[0,6,29.19],[1,1000,0.02]],"ltp":5.4,"tv":933.48,"id":10107989},{"batb":[[0,1.21,469.17],[1,1.2,146.04],[2,1.17,561.63]],"ltp":1.23,"tv":2175.82,"id":8444034}]}]}
{"op":"mcm","clk":"1003508387","pt":1580650535649,"mc":[{"id":"1.168213437","rc":[{"trd":[[5.3,98.82],[5.5,7.36]],"batb":[[0,5.3,15.2],[1,5,54.45],[2,4.6,65.07]],"ltp":5.3,"tv":1039.66,"id":10107989},{"batb":[[1,1.2,215.69]],"ltp":1.23,"tv":2175.82,"id":8444034}],"tv":3215.48}]}
{"op":"mcm","clk":"1003510376","pt":1580650545593,"mc":[{"id":"1.168213437","rc":[{"trd":[[5,33.5],[5.3,129.22]],"batb":[[0,5,37.7],[1,4.6,65.07],[2,3,75.72]],"ltp":5.0,"tv":1103.56,"id":10107989}],"tv":3279.38}]}
{"op":"mcm","clk":"1003510421","pt":1580650546259,"mc":[{"id":"1.168213437","rc":[{"batb":[[0,1.21,445.5]],"ltp":1.23,"tv":2175.82,"id":8444034}]}]}
{"op":"mcm","clk":"1003510562","pt":1580650546799,"mc":[{"id":"1.168213437","rc":[{"batb":[[0,1.21,441.8],[2,1.17,556.99]],"ltp":1.23,"tv":2175.82,"id":8444034}]}]}
{"op":"mcm","clk":"1003510978","pt":1580650548714,"mc":[{"id":"1.168213437","rc":[{"batl":[[0,5.7,6.57],[1,6,29.19],[2,1000,0.02]],"ltp":5.0,"tv":1103.56,"id":10107989},{"batl":[[0,1.23,23.44],[1,1.49,3.12],[2,1.5,4.2]],"ltp":1.23,"tv":2175.82,"id":8444034}]}]}
{"op":"mcm","clk":"1003512095","pt":1580650554330,"mc":[{"id":"1.168213437","rc":[{"trd":[[5.7,5.96]],"batl":[[0,5.7,3.59]],"ltp":5.7,"tv":1109.52,"id":10107989}],"tv":3285.34}]}
{"op":"mcm","clk":"1003514075","pt":1580650564459,"mc":[{"id":"1.168213437","rc":[{"batl":[[0,6,29.19],[1,1000,0.02],[2,1000,0]],"ltp":5.7,"tv":1109.52,"id":10107989},{"batl":[[0,1.49,3.12],[1,1.5,4.2],[2,1.55,690.76]],"ltp":1.23,"tv":2175.82,"id":8444034}]}]}
{"op":"mcm","clk":"1003514642","pt":1580650567461,"mc":[{"id":"1.168213437","rc":[{"trd":[[5,73.5]],"batb":[[0,5,17.7]],"batl":[[0,5.7,3.59],[1,6,29.19],[2,1000,0.02]],"ltp":5.0,"tv":1149.52,"id":10107989},{"trd":[[1.23,42]],"batl":[[0,1.23,17.25],[1,1.49,3.12],[2,1.5,4.2]],"ltp":1.23,"tv":2215.82,"id":8444034}],"tv":3365.34}]}
{"op":"mcm","clk":"1003515393","pt":1580650571464,"mc":[{"id":"1.168213437","rc":[{"batb":[[0,4.9,55.94]],"ltp":5.0,"tv":1149.52,"id":10107989},{"batb":[[0,1.22,437.39],[2,1.18,551.56]],"ltp":1.23,"tv":2215.82,"id":8444034}]}]}
{"op":"mcm","clk":"1003516558","pt":1580650577775,"mc":[{"id":"1.168213437","rc":[{"batl":[[0,6,29.19],[1,1000,0.02],[2,1000,0]],"ltp":5.0,"tv":1149.52,"id":10107989},{"batl":[[0,1.49,3.12],[1,1.5,4.2],[2,1.55,690.76]],"ltp":1.23,"tv":2215.82,"id":8444034}]}]}
{"op":"mcm","clk":"1003517065","pt":1580650580747,"mc":[{"id":"1.168213437","rc":[{"batl":[[0,5.7,7.91],[1,6,29.19],[2,1000,0.02]],"ltp":5.0,"tv":1149.52,"id":10107989},{"batl":[[0,1.23,17.25],[1,1.49,3.12],[2,1.5,4.2]],"ltp":1.23,"tv":2215.82,"id":8444034}]}]}
{"op":"mcm","clk":"1003517892","pt":1580650584992,"mc":[{"id":"1.168213437","rc":[{"trd":[[5.3,133.23]],"batl":[[0,5.3,3.57],[1,5.7,7.91],[2,6,29.19]],"ltp":5.3,"tv":1153.53,"id":10107989},{"trd":[[1.23,59.25]],"batl":[[0,1.49,3.12],[1,1.5,4.2],[2,1.55,690.76]],"ltp":1.23,"tv":2233.07,"id":8444034}],"tv":3386.6}]}
{"op":"mcm","clk":"1003518513","pt":1580650588691,"mc":[{"id":"1.168213437","rc":[{"batl":[[0,5.3,5.33]],"ltp":5.3,"tv":1153.53,"id":10107989}]}]}
{"op":"mcm","clk":"1003519113","pt":1580650592111,"mc":[{"id":"1.168213437","rc":[{"batl":[[0,5.3,3.57]],"ltp":5.3,"tv":1153.53,"id":10107989}]}]}
{"op":"mcm","clk":"1003519648","pt":1580650595208,"mc":[{"id":"1.168213437","rc":[{"batl":[[1,6,29.19],[2,1000,0.02]],"ltp":5.3,"tv":1153.53,"id":10107989}]}]}
{"op":"mcm","clk":"1003520178","pt":1580650598112,"mc":[{"id":"1.168213437","rc":[{"batl":[[1,5.5,5.26],[2,6,29.19]],"ltp":5.3,"tv":1153.53,"id":10107989},{"batl":[[0,1.24,28.13],[1,1.49,3.12],[2,1.5,4.2]],"ltp":1.23,"tv":2233.07,"id":8444034}]}]}
{"op":"mcm","clk":"1003522451","pt":1580650609941,"mc":[{"id":"1.168213437","rc":[{"trd":[[5.3,133.7]],"batl":[[0,5.3,3.1]],"ltp":5.3,"tv":1153.99,"id":10107989},{"trd":[[1.23,61.26]],"ltp":1.23,"tv":2235.08,"id":8444034}],"tv":3389.08}]}
{"op":"mcm","clk":"1003523274","pt":1580650614513,"mc":[{"id":"1.168213437","rc":[{"batb":[[0,4.6,65.07],[1,3,75.72],[2,2.6,75.72]],"batl":[[1,1000,0.02],[2,6,0]],"ltp":5.3,"tv":1153.99,"id":10107989},{"batb":[[0,1.2,69.75],[1,1.18,551.56],[2,1.14,610.45]],"batl":[[0,1.49,3.12],[1,1.5,4.2],[2,1.55,690.76]],"ltp":1.23,"tv":2235.08,"id":8444034}]}]}
{"op":"mcm","clk":"1003523681","pt":1580650616711,"mc":[{"id":"1.168213437","rc":[{"batb":[[1,2.6,75.72],[2,2.22,75.62]],"batl":[[0,5.1,3.54],[1,5.3,3.1],[2,1000,0.02]],"ltp":5.3,"tv":1153.99,"id":10107989}]}]}
{"op":"mcm","clk":"1003524053","pt":1580650618713,"mc":[{"id":"1.168213437","rc":[{"batl":[[0,5.3,3.1],[1,1000,0.02],[2,1000,0]],"ltp":5.3,"tv":1153.99,"id":10107989}]}]}
{"op":"mcm","clk":"1003524364","pt":1580650620315,"mc":[{"id":"1.168213437","rc":[{"batb":[[2,1.05,378.72]],"ltp":1.23,"tv":2235.08,"id":8444034}]}]}
{"op":"mcm","clk":"1003524482","pt":1580650621025,"mc":[{"id":"1.168213437","rc":[{"trd":[[5.3,136.79]],"batb":[[0,4.8,54.7],[1,4.6,65.07],[2,2.6,75.72]],"batl":[[0,5.1,4.69]],"ltp":5.3,"tv":1157.09,"id":10107989},{"trd":[[1.23,468.02]],"batb":[[0,1.23,58.91],[1,1.2,69.75],[2,1.18,551.56]],"batl":[[0,1.26,23.03],[1,1.49,3.12],[2,1.5,4.2]],"ltp":1.23,"tv":2641.84,"id":8444034}],"tv":3798.93}]}
{"op":"mcm","clk":"1003524706","pt":1580650622213,"mc":[{"id":"1.168213437","rc":[{"batb":[[2,4.3,77.11]],"ltp":5.3,"tv":1157.09,"id":10107989},{"batb":[[0,1.24,388.14],[1,1.23,58.91],[2,1.2,542.39]],"ltp":1.23,"tv":2641.84,"id":8444034}]}]}
{"op":"mcm","clk":"1003525896","pt":1580650628410,"mc":[{"id":"1.168213437","rc":[{"trd":[[4.8,7.08]],"batb":[[0,4.8,51.16]],"ltp":4.8,"tv":1164.17,"id":10107989}],"tv":3806.01}]}
{"op":"mcm","clk":"1003526500","pt":1580650631596,"mc":[{"id":"1.168213437","rc":[{"batb":[[0,4.6,65.07],[1,4.3,77.11],[2,2.6,75.72]],"batl":[[0,1000,0.02],[1,1000,0]],"ltp":4.8,"tv":1164.17,"id":10107989},{"batb":[[1,1.2,542.39],[2,1.16,576.13]],"batl":[[0,1.49,3.12],[1,1.5,4.2],[2,1.55,690.76]],"ltp":1.23,"tv":2641.84,"id":8444034}]}]}
{"op":"mcm","clk":"1003526604","pt":1580650632151,"mc":[{"id":"1.168213437","rc":[{"batb":[[0,4.3,77.11],[1,2.6,75.72],[2,2.22,75.62]],"ltp":4.8,"tv":1164.17,"id":10107989},{"batb":[[0,1.2,542.39],[1,1.16,576.13],[2,1.05,378.72]],"ltp":1.23,"tv":2641.84,"id":8444034}]}]}
{"op":"mcm","clk":"1003528475","pt":1580650642210,"mc":[{"id":"1.168213437","rc":[{"batl":[[0,4.8,6.83],[1,5.1,58.12],[2,1000,0.02]],"ltp":4.8,"tv":1164.17,"id":10107989},{"batl":[[0,1.28,265.33],[1,1.49,3.12],[2,1.5,4.2]],"ltp":1.23,"tv":2641.84,"id":8444034}]}]}
{"op":"mcm","clk":"1003528707","pt":1580650643512,"mc":[{"id":"1.168213437","rc":[{"batb":[[1,4.1,86.47],[2,2.6,75.72]],"ltp":4.8,"tv":1164.17,"id":10107989},{"batb":[[0,1.26,352.42],[1,1.23,407.81],[2,1.2,69.75]],"ltp":1.23,"tv":2641.84,"id":8444034}]}]}
{"op":"mcm","clk":"1003531258","pt":1580650657724,"mc":[{"id":"1.168213437","rc":[{"batb":[[0,4.1,86.47],[1,2.6,75.72],[2,2.22,75.62]],"batl":[[0,1000,0.02],[1,5.1,0],[2,1000,0]],"ltp":4.8,"tv":1164.17,"id":10107989},{"batb":[[0,1.23,407.81],[1,1.2,69.75],[2,1.16,576.13]],"batl":[[0,1.49,3.12],[1,1.5,4.2],[2,1.55,690.76]],"ltp":1.23,"tv":2641.84,"id":8444034}]}]}
{"op":"mcm","clk":"1003532330","pt":1580650663570,"mc":[{"id":"1.168213437","rc":[{"batb":[[2,1.05,378.72]],"ltp":1.23,"tv":2641.84,"id":8444034}]}]}
{"op":"mcm","clk":"1003532505","pt":1580650664669,"mc":[{"id":"1.168213437","rc":[{"batl":[[0,4.5,3.75],[1,1000,0.02]],"ltp":4.8,"tv":1164.17,"id":10107989},{"batb":[[0,1.26,244.56],[1,1.23,407.81],[2,1.2,69.75]],"batl":[[0,1.3,305.93],[1,1.49,3.12],[2,1.5,4.2]],"ltp":1.23,"tv":2641.84,"id":8444034}]}]}
{"op":"mcm","clk":"1003532614","pt":1580650665256,"mc":[{"id":"1.168213437","rc":[{"batb":[[1,3.95,95.05],[2,2.6,75.72]],"ltp":4.8,"tv":1164.17,"id":10107989},{"batb":[[0,1.28,325.74],[1,1.26,606.18]],"ltp":1.23,"tv":2641.84,"id":8444034}]}]}
{"op":"mcm","clk":"1003534466","pt":1580650675524,"mc":[{"id":"1.168213437","rc":[{"batb":[[0,3.95,95.05],[1,2.6,75.72],[2,2.22,75.62]],"batl":[[0,1000,0.02],[1,1000,0]],"ltp":4.8,"tv":1164.17,"id":10107989},{"batb":[[0,1.26,361.62],[1,1.2,69.75],[2,1.18,549.72]],"batl":[[0,1.49,3.12],[1,1.5,4.2],[2,1.55,690.76]],"ltp":1.23,"tv":2641.84,"id":8444034}]}]}
{"op":"mcm","clk":"1003538398","pt":1580650697670,"mc":[{"id":"1.168213437","rc":[{"batb":[[0,4.4,74.28],[1,4.1,83.48],[2,4,5.95]],"batl":[[0,4.8,5.77],[1,1000,0.02]],"ltp":4.8,"tv":1164.17,"id":10107989},{"batb":[[1,1.24,306.57],[2,1.22,424.73]],"batl":[[0,1.28,308.52],[1,1.49,3.12],[2,1.5,4.2]],"ltp":1.23,"tv":2641.84,"id":8444034}]}]}
{"op":"mcm","clk":"1003539165","pt":1580650702188,"mc":[{"id":"1.168213437","rc":[{"batb":[[2,2.6,75.72]],"ltp":4.8,"tv":1164.17,"id":10107989}]}]}
{"op":"mcm","clk":"1003541364","pt":1580650714393,"mc":[{"id":"1.168213437","rc":[{"batl":[[0,1000,0.02],[1,1000,0]],"ltp":4.8,"tv":1164.17,"id":10107989},{"batb":[[1,1.22,424.73],[2,1.2,69.75]],"batl":[[0,1.49,3.12],[1,1.5,4.2],[2,1.55,690.76]],"ltp":1.23,"tv":2641.84,"id":8444034}]}]}
{"op":"mcm","clk":"1003541464","pt":1580650714879,"mc":[{"id":"1.168213437","rc":[{"batb":[[0,4.1,83.48],[1,2.6,75.72],[2,2.22,75.62]],"ltp":4.8,"tv":1164.17,"id":10107989},{"batb":[[0,1.22,424.73],[1,1.2,69.75],[2,1.18,549.72]],"ltp":1.23,"tv":2641.84,"id":8444034}]}]}
{"op":"mcm","clk":"1003544424","pt":1580650731513,"mc":[{"id":"1.168213437","rc":[{"batb":[[0,4.3,76.08],[1,4.1,83.48],[2,3.7,55.39]],"batl":[[0,4.8,69.81],[1,1000,0.02]],"ltp":4.8,"tv":1164.17,"id":10107989},{"batb":[[0,1.29,14.8],[1,1.28,333.61],[2,1.25,370.04]],"ltp":1.23,"tv":2641.84,"id":8444034}]}]}
{"op":"mcm","clk":"1003549043","pt":1580650755810,"mc":[{"id":"1.168213437","rc":[{"trd":[[1.29,174.13]],"batb":[[0,1.28,333.61],[1,1.25,370.04],[2,1.2,69.75]],"batl":[[0,1.29,10.41],[1,1.49,3.12],[2,1.5,4.2]],"ltp":1.29,"tv":2671.43,"id":8444034}],"tv":3835.6}]}
{"op":"mcm","clk":"1003550487","pt":1580650763531,"mc":[{"id":"1.168213437","rc":[{"batl":[[0,1.49,3.12],[1,1.5,4.2],[2,1.55,690.76]],"ltp":1.29,"tv":2671.43,"id":8444034}]}]}
{"op":"mcm","clk":"1003550994","pt":1580650766644,"mc":[{"id":"1.168213437","rc":[{"batb":[[0,4.3,72.04]],"ltp":4.8,"tv":1164.17,"id":10107989},{"trd":[[1.28,54.59]],"batb":[[0,1.28,323.2]],"ltp":1.28,"tv":2692.25,"id":8444034}],"tv":3856.42}]}
{"op":"mcm","clk":"1003551390","pt":1580650768916,"mc":[{"id":"1.168213437","rc":[{"batb":[[0,1.28,346.42]],"batl":[[0,1.3,21.68],[1,1.49,3.12],[2,1.5,4.2]],"ltp":1.28,"tv":2692.25,"id":8444034}]}]}
{"op":"mcm","clk":"1003552239","pt":1580650774157,"mc":[{"id":"1.168213437","rc":[{"batb":[[0,4.1,83.48],[1,3.7,55.39],[2,2.6,75.72]],"batl":[[0,1000,0.02],[1,1000,0]],"ltp":4.8,"tv":1164.17,"id":10107989},{"batb":[[0,1.28,323.2]],"batl":[[0,1.49,3.12],[1,1.5,4.2],[2,1.55,690.76]],"ltp":1.28,"tv":2692.25,"id":8444034}]}]}
{"op":"mcm","clk":"1003552334","pt":1580650774743,"mc":[{"id":"1.168213437","rc":[{"batb":[[0,3.7,55.23],[1,2.6,75.72],[2,2.22,75.62]],"ltp":4.8,"tv":1164.17,"id":10107989},{"batb":[[0,1.25,370.04],[1,1.2,69.75],[2,1.18,549.72]],"ltp":1.28,"tv":2692.25,"id":8444034}]}]}
{"op":"mcm","clk":"1003553711","pt":1580650783049,"mc":[{"id":"1.168213437","rc":[{"batb":[[2,1.05,378.72]],"ltp":1.28,"tv":2692.25,"id":8444034}]}]}
{"op":"mcm","clk":"1003553935","pt":1580650784445,"mc":[{"id":"1.168213437","rc":[{"batb":[[1,2.22,75.62],[2,2.2,75.72]],"batl":[[0,4,4.86],[1,1000,0.02]],"ltp":4.8,"tv":1164.17,"id":10107989},{"batb":[[0,1.28,821.37],[1,1.25,370.04],[2,1.2,69.75]],"batl":[[0,1.35,15.82],[1,1.36,252],[2,1.49,3.12]],"ltp":1.28,"tv":2692.25,"id":8444034}]}]}
{"op":"mcm","clk":"1003554087","pt":1580650785362,"mc":[{"id":"1.168213437","rc":[{"batb":[[1,3.2,80.18],[2,2.22,75.62]],"ltp":4.8,"tv":1164.17,"id":10107989},{"batb":[[0,1.33,270.9],[1,1.29,310.01],[2,1.28,821.37]],"ltp":1.28,"tv":2692.25,"id":8444034}]}]}
{"op":"mcm","clk":"1003554616","pt":1580650788661,"mc":[{"id":"1.168213437","rc":[{"trd":[[1.33,27.62]],"batb":[[0,1.33,260.9]],"ltp":1.33,"tv":2712.25,"id":8444034}],"tv":3876.42}]}
{"op":"mcm","clk":"1003557282","pt":1580650804391,"mc":[{"id":"1.168213437","rc":[{"batl":[[0,1000,0.02],[1,1000,0]],"ltp":4.8,"tv":1164.17,"id":10107989},{"batb":[[2,1.2,600.61]],"batl":[[0,1.49,3.12],[1,1.5,4.2],[2,1.55,690.76]],"ltp":1.33,"tv":2712.25,"id":8444034}]}]}
{"op":"mcm","clk":"1003557415","pt":1580650805091,"mc":[{"id":"1.168213437","rc":[{"batb":[[0,3.2,80.02],[1,2.22,75.62],[2,2.2,75.72]],"ltp":4.8,"tv":1164.17,"id":10107989},{"batb":[[0,1.29,310.01],[1,1.2,600.61],[2,1.15,378.62]],"ltp":1.33,"tv":2712.25,"id":8444034}]}]}
{"op":"mcm","clk":"1003558363","pt":1580650810201,"mc":[{"id":"1.168213437","rc":[{"batb":[[1,1.2,69.75]],"batl":[[2,1000,0.02]],"ltp":1.33,"tv":2712.25,"id":8444034}]}]}
{"op":"mcm","clk":"1003559107","pt":1580650814307,"mc":[{"id":"1.168213437","rc":[{"batb":[[1,1.22,523],[2,1.2,69.75]],"batl":[[2,1.71,542.06]],"ltp":1.33,"tv":2712.25,"id":8444034}]}]}
{"op":"mcm","clk":"1003561320","pt":1580650826232,"mc":[{"id":"1.168213437","rc":[{"batb":[[1,1.2,69.75],[2,1.15,378.62]],"ltp":1.33,"tv":2712.25,"id":8444034}]}]}
{"op":"mcm","clk":"1003561562","pt":1580650827532,"mc":[{"id":"1.168213437","rc":[{"batb":[[0,3.35,6.84],[1,3.2,80.02],[2,2.22,75.62]],"batl":[[0,3.5,4.12],[1,3.7,104.02],[2,1000,0.02]],"ltp":4.8,"tv":1164.17,"id":10107989},{"batb":[[0,1.4,10.29],[1,1.29,310.01],[2,1.2,69.75]],"batl":[[0,1.44,264.09],[1,1.49,3.12],[2,1.5,4.2]],"ltp":1.33,"tv":2712.25,"id":8444034}]}]}
{"op":"mcm","clk":"1003561751","pt":1580650828543,"mc":[{"id":"1.168213437","rc":[{"batb":[[2,2.76,46.34]],"ltp":4.8,"tv":1164.17,"id":10107989},{"batb":[[0,1.41,205.75],[1,1.4,10.29],[2,1.37,238.01]],"ltp":1.33,"tv":2712.25,"id":8444034}]}]}
{"op":"mcm","clk":"1003563811","pt":1580650839955,"mc":[{"id":"1.168213437","rc":[{"trd":[[3.35,6.84]],"batb":[[0,3.2,80.02],[1,2.76,46.34],[2,2.22,75.62]],"ltp":3.35,"tv":1171.01,"id":10107989},{"trd":[[1.43,89.87],[1.44,55.96]],"batl":[[0,1.44,236.11]],"ltp":1.44,"tv":2784.23,"id":8444034}],"tv":3955.24}]}
{"op":"mcm","clk":"1003565635","pt":1580650850166,"mc":[{"id":"1.168213437","rc":[{"batl":[[0,3.7,104.02],[1,1000,0.02],[2,1000,0]],"ltp":3.35,"tv":1171.01,"id":10107989},{"batb":[[1,1.37,238.01],[2,1.25,505.09]],"ltp":1.44,"tv":2784.23,"id":8444034}]}]}
{"op":"mcm","clk":"1003565773","pt":1580650850910,"mc":[{"id":"1.168213437","rc":[{"batb":[[0,2.76,46.34],[1,2.22,75.62],[2,2.2,75.72]],"batl":[[0,1000,0.02],[1,1000,0]],"ltp":3.35,"tv":1171.01,"id":10107989},{"batb":[[0,1.37,238.01],[1,1.25,505.09],[2,1.2,69.75]],"batl":[[0,1.49,3.12],[1,1.5,4.2],[2,1.71,542.06]],"ltp":1.44,"tv":2784.23,"id":8444034}]}]}
{"op":"mcm","clk":"1003567010","pt":1580650858234,"mc":[{"id":"1.168213437","rc":[{"batb":[[1,1.2,69.75],[2,1.15,378.62]],"ltp":1.44,"tv":2784.23,"id":8444034}]}]}
{"op":"mcm","clk":"1003567220","pt":1580650859519,"mc":[{"id":"1.168213437","rc":[{"batb":[[0,3.45,65.94],[1,2.92,100.63],[2,2.76,46.34]],"batl":[[0,3.7,4.98],[1,4,95.79],[2,1000,0.02]],"ltp":3.35,"tv":1171.01,"id":10107989},{"batb":[[1,1.32,283.33],[2,1.2,69.75]],"batl":[[0,1.39,17.4],[1,1.44,813.38],[2,1.49,3.12]],"ltp":1.44,"tv":2784.23,"id":8444034}]}]}
{"op":"mcm","clk":"1003567278","pt":1580650859864,"mc":[{"id":"1.168213437","rc":[{"batb":[[2,2.22,75.62]],"ltp":3.35,"tv":1171.01,"id":10107989}]}]}
{"op":"mcm","clk":"1003567635","pt":1580650861846,"mc":[{"id":"1.168213437","rc":[{"batb":[[2,1.22,523]],"ltp":1.44,"tv":2784.23,"id":8444034}]}]}
{"op":"mcm","clk":"1003570064","pt":1580650875073,"mc":[{"id":"1.168213437","rc":[{"trd":[[1.37,54]],"batb":[[0,1.37,233.01]],"ltp":1.37,"tv":2794.23,"id":8444034}],"tv":3965.24}]}
{"op":"mcm","clk":"1003570756","pt":1580650878639,"mc":[{"id":"1.168213437","rc":[{"batb":[[0,2.92,100.48],[1,2.22,75.62],[2,2.2,75.72]],"batl":[[0,1000,0.02],[1,4,0],[2,1000,0]],"ltp":3.35,"tv":1171.01,"id":10107989},{"batb":[[0,1.32,283.33],[1,1.22,523],[2,1.2,69.75]],"batl":[[0,1.49,3.12],[1,1.5,4.2],[2,1.71,542.06]],"ltp":1.37,"tv":2794.23,"id":8444034}]}]}
{"op":"mcm","clk":"1003572387","pt":1580650887308,"mc":[{"id":"1.168213437","rc":[{"batb":[[1,1.2,69.75],[2,1.15,378.62]],"ltp":1.37,"tv":2794.23,"id":8444034}]}]}
{"op":"mcm","clk":"1003572574","pt":1580650888378,"mc":[{"id":"1.168213437","rc":[{"batb":[[0,3.05,6.27],[1,3,70.58],[2,2.92,100.48]],"batl":[[0,3.15,6.4],[1,3.4,109.77],[2,1000,0.02]],"ltp":3.35,"tv":1171.01,"id":10107989},{"batl":[[1,1.5,145.36]],"ltp":1.37,"tv":2794.23,"id":8444034}]}]}
{"op":"mcm","clk":"1003572841","pt":1580650889685,"mc":[{"id":"1.168213437","rc":[{"batb":[[0,1.47,172.39],[1,1.42,201.74],[2,1.32,283.33]],"ltp":1.37,"tv":2794.23,"id":8444034}]}]}
{"op":"mcm","clk":"1003572859","pt":1580650889798,"mc":[{"id":"1.168213437","rc":[{"batb":[[2,1.2,69.75]],"ltp":1.37,"tv":2794.23,"id":8444034}]}]}
{"op":"mcm","clk":"1003573128","pt":1580650891182,"mc":[{"id":"1.168213437","rc":[{"batb":[[2,1.28,485.89]],"ltp":1.37,"tv":2794.23,"id":8444034}]}]}
{"op":"mcm","clk":"1003574061","pt":1580650896505,"mc":[{"id":"1.168213437","rc":[{"trd":[[1.47,24.85]],"batb":[[0,1.47,159.97]],"ltp":1.47,"tv":2819.09,"id":8444034}],"tv":3990.1}]}
{"op":"mcm","clk":"1003575275","pt":1580650903488,"mc":[{"id":"1.168213437","rc":[{"trd":[[1.49,38.15]],"batl":[[0,1.49,3.04]],"ltp":1.49,"tv":2819.24,"id":8444034}],"tv":3990.25}]}
{"op":"mcm","clk":"1003575418","pt":1580650904314,"mc":[{"id":"1.168213437","rc":[{"trd":[[1.47,27.75]],"batb":[[0,1.47,158.52]],"ltp":1.47,"tv":2822.13,"id":8444034}],"tv":3993.14}]}
{"op":"mcm","clk":"1003576231","pt":1580650909138,"mc":[{"id":"1.168213437","rc":[{"trd":[[1.47,31.75]],"batb":[[0,1.47,156.52]],"ltp":1.47,"tv":2826.13,"id":8444034}],"tv":3997.14}]}
{"op":"mcm","clk":"1003576817","pt":1580650912514,"mc":[{"id":"1.168213437","rc":[{"batb":[[0,2.52,58.62],[1,2.22,75.62],[2,2.2,75.72]],"batl":[[0,1000,0.02],[1,3.4,0],[2,1000,0]],"ltp":3.35,"tv":1171.01,"id":10107989},{"batb":[[0,1.42,201.74],[1,1.28,485.89],[2,1.2,69.75]],"batl":[[1,1.5,4.2]],"ltp":1.47,"tv":2826.13,"id":8444034}]}]}
{"op":"mcm","clk":"1003577705","pt":1580650917507,"mc":[{"id":"1.168213437","rc":[{"batb":[[1,1.2,69.75],[2,1.15,378.62]],"batl":[[2,1000,0.02]],"ltp":1.47,"tv":2826.13,"id":8444034}]}]}
{"op":"mcm","clk":"1003578388","pt":1580650921218,"mc":[{"id":"1.168213437","rc":[{"batb":[[1,1.31,477.51],[2,1.2,69.75]],"batl":[[2,1.89,435.28]],"ltp":1.47,"tv":2826.13,"id":8444034}]}]}
{"op":"mcm","clk":"1003580598","pt":1580650931536,"mc":[{"id":"1.168213437","rc":[{"batb":[[1,1.2,69.75],[2,1.15,378.62]],"ltp":1.47,"tv":2826.13,"id":8444034}]}]}
{"op":"mcm","clk":"1003580804","pt":1580650932439,"mc":[{"id":"1.168213437","rc":[{"trd":[[3,3.61]],"batl":[[0,2.78,1.87],[1,3,67.47],[2,1000,0.02]],"ltp":3.0,"tv":1174.62,"id":10107989},{"trd":[[1.49,41.19],[1.5,4.2]],"batb":[[0,1.5,134.94],[1,1.42,201.74],[2,1.2,69.75]],"batl":[[0,1.6,302.98],[1,1.89,435.28],[2,1000,0.02]],"ltp":1.5,"tv":2833.37,"id":8444034}],"tv":4008.0}]}
{"op":"mcm","clk":"1003581018","pt":1580650933548,"mc":[{"id":"1.168213437","rc":[{"batb":[[1,2.42,65.94],[2,2.22,75.62]],"ltp":3.0,"tv":1174.62,"id":10107989},{"trd":[[1.6,309.89]],"batb":[[0,1.51,154.85],[1,1.5,134.94]],"batl":[[0,1.6,178.04]],"ltp":1.6,"tv":3083.26,"id":8444034}],"tv":4257.88}]}
{"op":"mcm","clk":"1003581398","pt":1580650935553,"mc":[{"id":"1.168213437","rc":[{"trd":[[2.66,3.36]],"ltp":2.66,"tv":1177.98,"id":10107989},{"trd":[[1.6,315.48]],"batb":[[2,1.34,465.43]],"batl":[[0,1.6,172.45]],"ltp":1.6,"tv":3088.85,"id":8444034}],"tv":4266.84}]}
{"op":"mcm","clk":"1003582898","pt":1580650942678,"mc":[{"id":"1.168213437","rc":[{"batl":[[0,3,67.47],[1,1000,0.02],[2,1000,0]],"ltp":2.66,"tv":1177.98,"id":10107989}]}]}
{"op":"mcm","clk":"1003583139","pt":1580650943747,"mc":[{"id":"1.168213437","rc":[{"trd":[[1.6,419.96]],"batl":[[0,1.6,120.21]],"ltp":1.6,"tv":3193.33,"id":8444034}],"tv":4371.32}]}
{"op":"mcm","clk":"1003583492","pt":1580650945570,"mc":[{"id":"1.168213437","rc":[{"batb":[[0,2.66,5.3],[1,2.52,58.62],[2,2.42,65.94]],"batl":[[0,2.72,5.48],[1,3,67.47],[2,1000,0.02]],"ltp":2.66,"tv":1177.98,"id":10107989}]}]}
{"op":"mcm","clk":"1003583637","pt":1580650946363,"mc":[{"id":"1.168213437","rc":[{"batb":[[0,2.52,58.62],[1,2.42,65.94],[2,2.22,75.62]],"batl":[[0,3,67.47],[1,1000,0.02],[2,1000,0]],"ltp":2.66,"tv":1177.98,"id":10107989},{"batb":[[0,1.52,51.49],[1,1.51,154.85],[2,1.5,134.94]],"ltp":1.6,"tv":3193.33,"id":8444034}]}]}
{"op":"mcm","clk":"1003584077","pt":1580650948683,"mc":[{"id":"1.168213437","rc":[{"batb":[[0,2.66,5.3],[1,2.52,58.62],[2,2.42,65.94]],"batl":[[0,2.72,5.48],[1,3,67.47],[2,1000,0.02]],"ltp":2.66,"tv":1177.98,"id":10107989}]}]}
{"op":"mcm","clk":"1003584627","pt":1580650951481,"mc":[{"id":"1.168213437","rc":[{"trd":[[2.72,0.3]],"batl":[[0,2.72,5.33]],"ltp":2.72,"tv":1178.28,"id":10107989},{"batb":[[0,1.51,154.85],[1,1.5,134.94],[2,1.34,465.43]],"ltp":1.6,"tv":3193.33,"id":8444034}],"tv":4371.62}]}
{"op":"mcm","clk":"1003586584","pt":1580650961464,"mc":[{"id":"1.168213437","rc":[{"batb":[[0,2.42,65.94],[1,2.22,75.62],[2,2.16,3.21]],"batl":[[0,1000,0.02],[1,3,0],[2,1000,0]],"ltp":2.72,"tv":1178.28,"id":10107989},{"batb":[[1,1.34,465.43],[2,1.25,378.62]],"batl":[[0,1.89,435.28],[1,1000,0.02],[2,1000,0]],"ltp":1.6,"tv":3193.33,"id":8444034}]}]}
{"op":"mcm","clk":"1003586724","pt":1580650962176,"mc":[{"id":"1.168213437","rc":[{"batl":[[0,1.58,17.68],[1,1.89,435.28],[2,1000,0.02]],"ltp":1.6,"tv":3193.33,"id":8444034}]}]}
{"op":"mcm","clk":"1003587222","pt":1580650964732,"mc":[{"id":"1.168213437","rc":[{"batb":[[0,2.44,64.2],[1,2.42,65.94],[2,2.22,75.62]],"ltp":2.72,"tv":1178.28,"id":10107989},{"batb":[[1,1.5,158.31],[2,1.34,465.43]],"ltp":1.6,"tv":3193.33,"id":8444034}]}]}
{"op":"mcm","clk":"1003587288","pt":1580650965015,"mc":[{"id":"1.168213437","rc":[{"batb":[[1,2.22,75.62],[2,2.16,3.21]],"ltp":2.72,"tv":1178.28,"id":10107989},{"batb":[[0,1.5,158.31],[1,1.34,465.43],[2,1.25,378.62]],"ltp":1.6,"tv":3193.33,"id":8444034}]}]}
{"op":"mcm","clk":"1003588044","pt":1580650968721,"mc":[{"id":"1.168213437","rc":[{"batb":[[0,2.88,130.27],[1,2.44,64.2],[2,2.22,75.62]],"batl":[[0,3,3.89],[1,1000,0.02]],"ltp":2.72,"tv":1178.28,"id":10107989},{"batb":[[0,1.5,166.1],[1,1.46,188.42],[2,1.34,465.43]],"batl":[[0,1.57,14.08],[1,1.58,17.68],[2,1.89,435.28]],"ltp":1.6,"tv":3193.33,"id":8444034}]}]}
{"op":"mcm","clk":"1003588184","pt":1580650969441,"mc":[{"id":"1.168213437","rc":[{"batb":[[1,2.82,44.14],[2,2.64,52.56]],"ltp":2.72,"tv":1178.28,"id":10107989},{"batb":[[2,1.4,206.54]],"batl":[[0,1.58,17.68],[1,1.89,435.28],[2,1000,0.02]],"ltp":1.6,"tv":3193.33,"id":8444034}]}]}
{"op":"mcm","clk":"1003591649","pt":1580650987639,"mc":[{"id":"1.168213437","rc":[{"batb":[[0,2.64,52.56],[1,2.16,3.21],[2,2.02,75.62]],"batl":[[0,1000,0.02],[1,1000,0]],"ltp":2.72,"tv":1178.28,"id":10107989},{"batb":[[0,1.4,206.54],[1,1.34,465.43],[2,1.25,378.62]],"ltp":1.6,"tv":3193.33,"id":8444034}]}]}
{"op":"mcm","clk":"1003594275","pt":1580651000690,"mc":[{"id":"1.168213437","rc":[{"batb":[[1,1.25,378.62],[2,1.2,189.41]],"batl":[[1,1000,0.02],[2,1000,0]],"ltp":1.6,"tv":3193.33,"id":8444034}]}]}
{"op":"mcm","clk":"1003594446","pt":1580651001508,"mc":[{"id":"1.168213437","rc":[{"batb":[[0,3.25,91.11],[1,2.64,52.56],[2,2.16,3.21]],"ltp":2.72,"tv":1178.28,"id":10107989},{"batb":[[0,1.42,15.76],[1,1.4,206.54],[2,1.38,262.25]],"batl":[[0,1.44,10.9]],"ltp":1.6,"tv":3193.33,"id":8444034}]}]}
{"op":"mcm","clk":"1003594605","pt":1580651002414,"mc":[{"id":"1.168213437","rc":[{"batb":[[1,3.2,79.63],[2,2.94,98.35]],"ltp":2.72,"tv":1178.28,"id":10107989}]}]}
{"op":"mcm","clk":"1003594967","pt":1580651004216,"mc":[{"id":"1.168213437","rc":[{"batl":[[1,1.77,500.61],[2,1000,0.02]],"ltp":1.6,"tv":3193.33,"id":8444034}]}]}
{"op":"mcm","clk":"1003597977","pt":1580651019397,"mc":[{"id":"1.168213437","rc":[{"batb":[[0,3.2,79.63],[1,2.94,98.35],[2,2.16,3.21]],"ltp":2.72,"tv":1178.28,"id":10107989},{"batb":[[0,1.4,206.54],[1,1.32,270.43],[2,1.25,505.09]],"batl":[[0,1.77,500.61],[1,1000,0.02],[2,1000,0]],"ltp":1.6,"tv":3193.33,"id":8444034}]}]}
{"op":"mcm","clk":"1003598084","pt":1580651019844,"mc":[{"id":"1.168213437","rc":[{"batb":[[0,2.94,98.35],[1,2.16,3.21],[2,2.02,75.62]],"ltp":2.72,"tv":1178.28,"id":10107989},{"batb":[[0,1.32,270.43],[1,1.25,505.09],[2,1.2,189.41]],"ltp":1.6,"tv":3193.33,"id":8444034}]}]}
{"op":"mcm","clk":"1003603989","pt":1580651049640,"mc":[{"id":"1.168213437","rc":[{"batl":[[0,3.85,4.19],[1,4.2,97.49],[2,1000,0.02]],"ltp":2.72,"tv":1178.28,"id":10107989},{"batb":[[1,1.15,378.72],[2,1.1,378.72]],"batl":[[0,1.37,248.08],[1,1.77,500.61],[2,1000,0.02]],"ltp":1.6,"tv":3193.33,"id":8444034}]}]}
{"op":"mcm","clk":"1003604185","pt":1580651050616,"mc":[{"id":"1.168213437","rc":[{"batb":[[0,3.7,55.39],[1,3.45,65.94],[2,2.16,3.21]],"ltp":2.72,"tv":1178.28,"id":10107989},{"batb":[[1,1.27,335.5],[2,1.15,378.72]],"ltp":1.6,"tv":3193.33,"id":8444034}]}]}
{"op":"mcm","clk":"1003604562","pt":1580651052615,"mc":[{"id":"1.168213437","rc":[{"batb":[[2,1.22,523]],"ltp":1.6,"tv":3193.33,"id":8444034}]}]}
{"op":"mcm","clk":"1003607460","pt":1580651067334,"mc":[{"id":"1.168213437","rc":[{"batb":[[0,3.45,65.94],[1,2.16,3.21],[2,2.02,75.62]],"batl":[[0,1000,0.02],[1,4.2,0],[2,1000,0]],"ltp":2.72,"tv":1178.28,"id":10107989},{"batb":[[0,1.27,335.5],[1,1.22,523],[2,1.15,378.72]],"batl":[[0,1.77,500.61],[1,1000,0.02],[2,1000,0]],"ltp":1.6,"tv":3193.33,"id":8444034}]}]}
{"op":"mcm","clk":"1003609782","pt":1580651079454,"mc":[{"id":"1.168213437","rc":[{"batb":[[0,3.5,43.8],[1,3.45,65.94],[2,2.16,3.21]],"batl":[[0,3.85,69.58],[1,1000,0.02]],"ltp":2.72,"tv":1178.28,"id":10107989},{"batb":[[0,1.38,16.34],[1,1.27,335.5],[2,1.22,523]],"batl":[[0,1.4,116.44],[1,1.77,500.61],[2,1000,0.02]],"ltp":1.6,"tv":3193.33,"id":8444034}]}]}
{"op":"mcm","clk":"1003609967","pt":1580651080347,"mc":[{"id":"1.168213437","rc":[{"batb":[[2,3.15,82.54]],"ltp":2.72,"tv":1178.28,"id":10107989},{"batb":[[1,1.36,238.09],[2,1.28,320.55]],"ltp":1.6,"tv":3193.33,"id":8444034}]}]}
{"op":"mcm","clk":"1003612268","pt":1580651092170,"mc":[{"id":"1.168213437","rc":[{"trd":[[1.4,22.86]],"batl":[[0,1.4,108.04]],"ltp":1.4,"tv":3210.13,"id":8444034}],"tv":4388.42}]}
{"op":"mcm","clk":"1003612670","pt":1580651094265,"mc":[{"id":"1.168213437","rc":[{"batl":[[0,1.4,120.91]],"ltp":1.4,"tv":3210.13,"id":8444034}]}]}
{"op":"mcm","clk":"1003613307","pt":1580651097461,"mc":[{"id":"1.168213437","rc":[{"batb":[[0,3.15,82.54],[1,2.16,3.21],[2,2.02,75.62]],"batl":[[0,1000,0.02],[1,1000,0]],"ltp":2.72,"tv":1178.28,"id":10107989},{"batb":[[0,1.28,320.55],[1,1.22,523],[2,1.15,378.72]],"batl":[[0,1.4,12.87]],"ltp":1.4,"tv":3210.13,"id":8444034}]}]}
{"op":"mcm","clk":"1003614658","pt":1580651103973,"mc":[{"id":"1.168213437","rc":[{"batl":[[0,1.77,500.61],[1,1000,0.02],[2,1000,0]],"ltp":1.4,"tv":3210.13,"id":8444034}]}]}
{"op":"mcm","clk":"1003615170","pt":1580651106173,"mc":[{"id":"1.168213437","rc":[{"batb":[[1,1.15,378.72],[2,1.1,378.72]],"batl":[[0,1000,0.02],[1,1000,0]],"ltp":1.4,"tv":3210.13,"id":8444034}]}]}
{"op":"mcm","clk":"1003615521","pt":1580651107674,"mc":[{"id":"1.168213437","rc":[{"batb":[[0,4,4.24],[1,3.15,82.54],[2,2.16,3.21]],"batl":[[0,4.5,90.74],[1,1000,0.02]],"ltp":2.72,"tv":1178.28,"id":10107989},{"batb":[[0,1.32,12.46],[1,1.28,320.55],[2,1.15,378.72]],"batl":[[0,1.34,262.92],[1,1.38,12.87],[2,1000,0.02]],"ltp":1.4,"tv":3210.13,"id":8444034}]}]}
{"op":"mcm","clk":"1003615623","pt":1580651108165,"mc":[{"id":"1.168213437","rc":[{"batb":[[0,4,92.68],[1,3.6,59.96]],"ltp":2.72,"tv":1178.28,"id":10107989},{"batb":[[2,1.25,362.8]],"ltp":1.4,"tv":3210.13,"id":8444034}]}]}
{"op":"mcm","clk":"1003616130","pt":1580651110478,"mc":[{"id":"1.168213437","rc":[{"batb":[[2,2.2,75.72]],"ltp":2.72,"tv":1178.28,"id":10107989},{"batl":[[2,1.62,614.4]],"ltp":1.4,"tv":3210.13,"id":8444034}]}]}
{"op":"mcm","clk":"1003618345","pt":1580651121631,"mc":[{"id":"1.168213437","rc":[{"batl":[[2,1.5,2.52]],"ltp":1.4,"tv":3210.13,"id":8444034}]}]}
{"op":"mcm","clk":"1003618687","pt":1580651123463,"mc":[{"id":"1.168213437","rc":[{"trd":[[4,14.33]],"batb":[[0,4,86.78]],"ltp":4.0,"tv":1190.08,"id":10107989}],"tv":4400.21}]}
{"op":"mcm","clk":"1003618881","pt":1580651124582,"mc":[{"id":"1.168213437","rc":[{"batb":[[1,1.28,320.31],[2,1.25,362.57]],"batl":[[1,1.5,2.52],[2,1.62,614.4]],"ltp":1.4,"tv":3210.13,"id":8444034}]}]}
{"op":"mcm","clk":"1003619464","pt":1580651127656,"mc":[{"id":"1.168213437","rc":[{"trd":[[1.32,44.17]],"batb":[[0,1.28,320.31],[1,1.25,362.57],[2,1.18,549.82]],"batl":[[0,1.34,263.34]],"ltp":1.32,"tv":3235.05,"id":8444034}],"tv":4425.13}]}
{"op":"mcm","clk":"1003620066","pt":1580651131082,"mc":[{"id":"1.168213437","rc":[{"trd":[[1.32,45],[1.34,3.02]],"batl":[[0,1.34,261.41]],"ltp":1.34,"tv":3238.9,"id":8444034}],"tv":4428.99}]}
{"op":"mcm","clk":"1003621037","pt":1580651136576,"mc":[{"id":"1.168213437","rc":[{"batb":[[0,4,90.89]],"ltp":4.0,"tv":1190.08,"id":10107989},{"batb":[[0,1.32,12.85],[1,1.28,320.31],[2,1.25,362.57]],"ltp":1.34,"tv":3238.9,"id":8444034}]}]}
{"op":"mcm","clk":"1003621258","pt":1580651137806,"mc":[{"id":"1.168213437","rc":[{"batb":[[0,4,86.78]],"ltp":4.0,"tv":1190.08,"id":10107989},{"batb":[[0,1.28,320.31],[1,1.25,362.57],[2,1.18,549.82]],"ltp":1.34,"tv":3238.9,"id":8444034}]}]}
{"op":"mcm","clk":"1003621811","pt":1580651140836,"mc":[{"id":"1.168213437","rc":[{"batb":[[0,4,90.89]],"ltp":4.0,"tv":1190.08,"id":10107989},{"batb":[[0,1.32,12.85],[1,1.28,320.31],[2,1.25,362.57]],"ltp":1.34,"tv":3238.9,"id":8444034}]}]}
{"op":"mcm","clk":"1003631506","pt":1580651189609,"mc":[{"id":"1.168213437","rc":[{"batl":[[1,1.62,614.4],[2,1000,0.02]],"ltp":1.34,"tv":3238.9,"id":8444034}]}]}
{"op":"mcm","clk":"1003632251","pt":1580651193432,"mc":[{"id":"1.168213437","rc":[{"trd":[[1.32,54.79]],"batb":[[0,1.32,7.96]],"ltp":1.32,"tv":3248.69,"id":8444034}],"tv":4438.77}]}
{"op":"mcm","clk":"1003632701","pt":1580651195732,"mc":[{"id":"1.168213437","rc":[{"batb":[[0,3.6,59.96],[1,2.2,75.72],[2,2.16,3.21]],"batl":[[0,1000,0.02],[1,1000,0]],"ltp":4.0,"tv":1190.08,"id":10107989},{"batb":[[0,1.25,362.57],[1,1.18,549.82],[2,1.15,378.62]],"batl":[[0,1.62,614.4],[1,1000,0.02],[2,1000,0]],"ltp":1.32,"tv":3248.69,"id":8444034}]}]}
{"op":"mcm","clk":"1003633980","pt":1580651201627,"mc":[{"id":"1.168213437","rc":[{"batb":[[0,4.3,73.58],[1,3.6,59.96],[2,2.2,75.72]],"batl":[[0,4.5,3.95],[1,4.8,60.51],[2,1000,0.02]],"ltp":4.0,"tv":1190.08,"id":10107989},{"batl":[[0,1.3,17.1],[1,1.62,614.4],[2,1000,0.02]],"ltp":1.32,"tv":3248.69,"id":8444034}]}]}
{"op":"mcm","clk":"1003634160","pt":1580651202545,"mc":[{"id":"1.168213437","rc":[{"batb":[[0,4.4,73.96],[1,4.3,73.58],[2,3.85,99.38]],"ltp":4.0,"tv":1190.08,"id":10107989},{"batb":[[1,1.23,407.81],[2,1.18,549.82]],"ltp":1.32,"tv":3248.69,"id":8444034}]}]}
{"op":"mcm","clk":"1003634345","pt":1580651203555,"mc":[{"id":"1.168213437","rc":[{"batl":[[0,4.8,60.51],[1,1000,0.02],[2,1000,0]],"ltp":4.0,"tv":1190.08,"id":10107989},{"batl":[[0,1.62,614.4],[1,1000,0.02],[2,1000,0]],"ltp":1.32,"tv":3248.69,"id":8444034}]}]}
{"op":"mcm","clk":"1003634901","pt":1580651206513,"mc":[{"id":"1.168213437","rc":[{"batl":[[0,4.5,3.95],[1,4.8,60.51],[2,1000,0.02]],"ltp":4.0,"tv":1190.08,"id":10107989},{"batl":[[0,1.3,17.1],[1,1.62,614.4],[2,1000,0.02]],"ltp":1.32,"tv":3248.69,"id":8444034}]}]}
{"op":"mcm","clk":"1003636790","pt":1580651216378,"mc":[{"id":"1.168213437","rc":[{"batb":[[1,3.85,99.38],[2,2.2,75.72]],"batl":[[0,1000,0.02],[1,4.8,0],[2,1000,0]],"ltp":4.0,"tv":1190.08,"id":10107989},{"batl":[[0,1.62,614.4],[1,1000,0.02],[2,1000,0]],"ltp":1.32,"tv":3248.69,"id":8444034}]}]}
{"op":"mcm","clk":"1003636931","pt":1580651217135,"mc":[{"id":"1.168213437","rc":[{"batb":[[0,3.85,99.38],[1,2.2,75.72],[2,2.16,3.21]],"ltp":4.0,"tv":1190.08,"id":10107989},{"batb":[[0,1.23,407.81],[1,1.18,549.82],[2,1.1,378.72]],"ltp":1.32,"tv":3248.69,"id":8444034}]}]}
{"op":"mcm","clk":"1003638815","pt":1580651226455,"mc":[{"id":"1.168213437","rc":[{"batb":[[0,4.7,62.16],[1,4.2,79.47],[2,3.85,99.38]],"ltp":4.0,"tv":1190.08,"id":10107989},{"batb":[[0,1.26,16.62],[1,1.24,247.61],[2,1.23,407.81]],"batl":[[0,1.28,343.24],[1,1.62,614.4],[2,1000,0.02]],"ltp":1.32,"tv":3248.69,"id":8444034}]}]}
{"op":"mcm","clk":"1003638875","pt":1580651226753,"mc":[{"id":"1.168213437","rc":[{"batb":[[2,2.2,75.72]],"ltp":4.0,"tv":1190.08,"id":10107989}]}]}
{"op":"mcm","clk":"1003639299","pt":1580651229054,"mc":[{"id":"1.168213437","rc":[{"batb":[[2,2.6,75.72]],"ltp":4.0,"tv":1190.08,"id":10107989}]}]}
{"op":"mcm","clk":"1003641079","pt":1580651237876,"mc":[{"id":"1.168213437","rc":[{"batb":[[1,1.24,255.17]],"ltp":1.32,"tv":3248.69,"id":8444034}]}]}
{"op":"mcm","clk":"1003641517","pt":1580651240266,"mc":[{"id":"1.168213437","rc":[{"batb":[[0,1.24,7.56],[1,1.23,407.81],[2,1.21,443.53]],"batl":[[0,1.62,614.4],[1,1000,0.02],[2,1000,0]],"ltp":1.32,"tv":3248.69,"id":8444034}]}]}
{"op":"mcm","clk":"1003641605","pt":1580651240773,"mc":[{"id":"1.168213437","rc":[{"batb":[[0,4.2,79.47],[1,2.6,75.72],[2,2.2,75.72]],"ltp":4.0,"tv":1190.08,"id":10107989},{"batb":[[1,1.21,443.53],[2,1.18,549.82]],"ltp":1.32,"tv":3248.69,"id":8444034}]}]}
{"op":"mcm","clk":"1003642111","pt":1580651243068,"mc":[{"id":"1.168213437","rc":[{"batb":[[0,1.21,443.53],[1,1.18,549.82],[2,1.1,378.72]],"ltp":1.32,"tv":3248.69,"id":8444034}]}]}
{"op":"mcm","clk":"1003642707","pt":1580651246172,"mc":[{"id":"1.168213437","rc":[{"batb":[[0,1.27,7.56],[1,1.21,443.53],[2,1.18,549.82]],"ltp":1.32,"tv":3248.69,"id":8444034}]}]}
{"op":"mcm","clk":"1003643144","pt":1580651248484,"mc":[{"id":"1.168213437","rc":[{"batl":[[0,5.1,3.68],[1,5.5,71.81],[2,1000,0.02]],"ltp":4.0,"tv":1190.08,"id":10107989},{"trd":[[1.27,15.12]],"batb":[[0,1.21,443.53],[1,1.18,549.82],[2,1.05,378.72]],"batl":[[0,1.26,303.7],[1,1.62,614.4],[2,1000,0.02]],"ltp":1.27,"tv":3263.81,"id":8444034}],"tv":4453.89}]}
{"op":"mcm","clk":"1003643324","pt":1580651249497,"mc":[{"id":"1.168213437","rc":[{"batb":[[0,5,54.84],[1,4.6,65.94],[2,2.6,75.72]],"ltp":4.0,"tv":1190.08,"id":10107989},{"batb":[[1,1.2,474.08],[2,1.18,549.72]],"ltp":1.27,"tv":3263.81,"id":8444034}]}]}
{"op":"mcm","clk":"1003643841","pt":1580651252577,"mc":[{"id":"1.168213437","rc":[{"batb":[[2,3,75.72]],"ltp":4.0,"tv":1190.08,"id":10107989}]}]}
{"op":"mcm","clk":"1003644794","pt":1580651258217,"mc":[{"id":"1.168213437","rc":[{"batl":[[0,5.5,71.81],[1,1000,0.02],[2,1000,0]],"ltp":4.0,"tv":1190.08,"id":10107989},{"batl":[[0,1.26,284.69]],"ltp":1.27,"tv":3263.81,"id":8444034}]}]}
{"op":"mcm","clk":"1003645434","pt":1580651261526,"mc":[{"id":"1.168213437","rc":[{"batb":[[2,2.6,75.72]],"batl":[[0,5.1,5.56],[1,5.5,71.81],[2,1000,0.02]],"ltp":4.0,"tv":1190.08,"id":10107989},{"batl":[[0,1.26,303.64]],"ltp":1.27,"tv":3263.81,"id":8444034}]}]}
{"op":"mcm","clk":"1003645643","pt":1580651262711,"mc":[{"id":"1.168213437","rc":[{"batb":[[0,4.6,65.94],[1,2.6,75.72],[2,2.2,75.72]],"batl":[[0,1000,0.02],[1,5.5,0],[2,1000,0]],"ltp":4.0,"tv":1190.08,"id":10107989},{"batb":[[0,1.2,474.08],[1,1.18,549.72],[2,1.05,378.72]],"batl":[[0,1.62,614.4],[1,1000,0.02],[2,1000,0]],"ltp":1.27,"tv":3263.81,"id":8444034}]}]}
{"op":"mcm","clk":"1003646090","pt":1580651265200,"mc":[{"id":"1.168213437","rc":[{"batb":[[1,3,75.72],[2,2.6,75.72]],"ltp":4.0,"tv":1190.08,"id":10107989}]}]}
{"op":"mcm","clk":"1003647409","pt":1580651272442,"mc":[{"id":"1.168213437","rc":[{"batb":[[0,5.1,71.54],[1,4.6,65.94],[2,3,75.72]],"ltp":4.0,"tv":1190.08,"id":10107989},{"batb":[[0,1.21,296.63],[1,1.2,474.08],[2,1.18,549.72]],"ltp":1.27,"tv":3263.81,"id":8444034}]}]}
{"op":"mcm","clk":"1003647620","pt":1580651273718,"mc":[{"id":"1.168213437","rc":[{"batb":[[0,5.2,49.57],[1,5.1,71.54],[2,4.7,62.55]],"ltp":4.0,"tv":1190.08,"id":10107989}]}]}
{"op":"mcm","clk":"1003649155","pt":1580651282348,"mc":[{"id":"1.168213437","rc":[{"trd":[[5.2,2.38]],"batb":[[0,5.2,47.18]],"ltp":5.2,"tv":1192.46,"id":10107989},{"trd":[[1.24,10]],"ltp":1.24,"tv":3273.81,"id":8444034}],"tv":4466.27}]}
{"op":"mcm","clk":"1003651042","pt":1580651293253,"mc":[{"id":"1.168213437","rc":[{"batb":[[0,4.7,62.55],[1,3,75.72],[2,2.6,75.72]],"ltp":5.2,"tv":1192.46,"id":10107989},{"batb":[[0,1.18,549.82],[1,1.16,611.2],[2,1.05,378.72]],"ltp":1.24,"tv":3273.81,"id":8444034}]}]}
{"op":"mcm","clk":"1003651668","pt":1580651296677,"mc":[{"id":"1.168213437","rc":[{"batb":[[0,1.24,12.87],[1,1.18,549.82],[2,1.16,611.2]],"ltp":1.24,"tv":3273.81,"id":8444034}]}]}
{"op":"mcm","clk":"1003651717","pt":1580651296956,"mc":[{"id":"1.168213437","rc":[{"batb":[[1,2.6,75.72],[2,2.2,75.72]],"ltp":5.2,"tv":1192.46,"id":10107989}]}]}
{"op":"mcm","clk":"1003652065","pt":1580651298950,"mc":[{"id":"1.168213437","rc":[{"trd":[[4.7,0.16]],"batb":[[0,4.7,62.39]],"ltp":4.7,"tv":1192.63,"id":10107989},{"trd":[[1.28,55.19]],"ltp":1.28,"tv":3274.41,"id":8444034}],"tv":4467.04}]}
{"op":"mcm","clk":"1003652296","pt":1580651300273,"mc":[{"id":"1.168213437","rc":[{"batl":[[0,4.8,3.93],[1,5.3,95.04],[2,1000,0.02]],"ltp":4.7,"tv":1192.63,"id":10107989},{"batl":[[0,1.28,334.08],[1,1.62,614.4],[2,1000,0.02]],"ltp":1.28,"tv":3274.41,"id":8444034}]}]}
{"op":"mcm","clk":"1003652456","pt":1580651301175,"mc":[{"id":"1.168213437","rc":[{"batb":[[1,4.3,74.98],[2,2.6,75.72]],"ltp":4.7,"tv":1192.63,"id":10107989},{"batb":[[1,1.23,405.61],[2,1.19,506.73]],"ltp":1.28,"tv":3274.41,"id":8444034}]}]}
{"op":"mcm","clk":"1003653026","pt":1580651304277,"mc":[{"id":"1.168213437","rc":[{"trd":[[1.28,55.35]],"batl":[[0,1.28,334]],"ltp":1.28,"tv":3274.57,"id":8444034}],"tv":4467.2}]}
{"op":"mcm","clk":"1003653183","pt":1580651305182,"mc":[{"id":"1.168213437","rc":[{"batb":[[0,1.23,405.61],[1,1.19,506.73],[2,1.18,549.72]],"ltp":1.28,"tv":3274.57,"id":8444034}]}]}
{"op":"mcm","clk":"1003653352","pt":1580651306049,"mc":[{"id":"1.168213437","rc":[{"trd":[[4.7,3.03]],"batb":[[0,4.7,60.96]],"ltp":4.7,"tv":1195.49,"id":10107989}],"tv":4470.06}]}
{"op":"mcm","clk":"1003653828","pt":1580651308676,"mc":[{"id":"1.168213437","rc":[{"trd":[[4.7,10.57]],"batb":[[0,4.7,57.19]],"ltp":4.7,"tv":1203.03,"id":10107989},{"trd":[[1.28,55.39]],"batl":[[0,1.28,333.98]],"ltp":1.28,"tv":3274.61,"id":8444034}],"tv":4477.64}]}
{"op":"mcm","clk":"1003654380","pt":1580651311689,"mc":[{"id":"1.168213437","rc":[{"batl":[[0,1000,0.02],[1,5.3,0],[2,1000,0]],"ltp":4.7,"tv":1203.03,"id":10107989},{"batl":[[0,1.62,614.4],[1,1000,0.02],[2,1000,0]],"ltp":1.28,"tv":3274.61,"id":8444034}]}]}
{"op":"mcm","clk":"1003654430","pt":1580651311870,"mc":[{"id":"1.168213437","rc":[{"batb":[[0,4.3,74.98],[1,2.6,75.72],[2,2.2,75.72]],"ltp":4.7,"tv":1203.03,"id":10107989},{"batb":[[0,1.19,505.47],[1,1.18,549.72],[2,1.05,378.72]],"ltp":1.28,"tv":3274.61,"id":8444034}]}]}
{"op":"mcm","clk":"1003657809","pt":1580651328952,"mc":[{"id":"1.168213437","rc":[{"trd":[[6,0.02],[6.4,0.02]],"ltp":6.4,"tv":1203.07,"id":10107989},{"trd":[[1.19,0.08],[1.2,0.1]],"batb":[[0,1.19,505.29]],"ltp":1.19,"tv":3274.79,"id":8444034}],"tv":4477.86}]}
{"op":"mcm","clk":"1003658182","pt":1580651330921,"mc":[{"id":"1.168213437","rc":[{"trd":[[1.19,1.32]],"batb":[[0,1.19,504.67]],"ltp":1.19,"tv":3276.03,"id":8444034}],"tv":4479.1}]}
{"op":"mcm","clk":"1003659516","pt":1580651337737,"mc":[{"id":"1.168213437","rc":[{"batb":[[0,4.3,135.14]],"batl":[[0,4.8,74.7],[1,1000,0.02]],"ltp":6.4,"tv":1203.07,"id":10107989},{"batb":[[0,1.29,17.46],[1,1.19,504.67],[2,1.18,549.72]],"batl":[[0,1.31,24.22],[1,1.62,614.4],[2,1000,0.02]],"ltp":1.19,"tv":3276.03,"id":8444034}]}]}
{"op":"mcm","clk":"1003659686","pt":1580651338537,"mc":[{"id":"1.168213437","rc":[{"batb":[[1,4.1,86.47],[2,2.6,75.72]],"ltp":6.4,"tv":1203.07,"id":10107989},{"batb":[[1,1.26,358.4],[2,1.22,419.45]],"ltp":1.19,"tv":3276.03,"id":8444034}]}]}
{"op":"mcm","clk":"1003662548","pt":1580651352530,"mc":[{"id":"1.168213437","rc":[{"batb":[[0,4.3,74.98]],"batl":[[0,1000,0.02],[1,1000,0]],"ltp":6.4,"tv":1203.07,"id":10107989},{"batb":[[0,1.26,358.4],[1,1.22,419.45],[2,1.18,549.72]],"batl":[[0,1.62,614.4],[1,1000,0.02],[2,1000,0]],"ltp":1.19,"tv":3276.03,"id":8444034}]}]}
{"op":"mcm","clk":"1003662649","pt":1580651353024,"mc":[{"id":"1.168213437","rc":[{"batb":[[0,4.1,85.37],[1,2.6,75.72],[2,2.2,75.72]],"ltp":6.4,"tv":1203.07,"id":10107989},{"batb":[[0,1.22,419.45],[1,1.18,549.72],[2,1.05,378.72]],"ltp":1.19,"tv":3276.03,"id":8444034}]}]}
{"op":"mcm","clk":"1003663050","pt":1580651355044,"mc":[{"id":"1.168213437","rc":[{"batb":[[0,1.31,5.36],[1,1.22,419.45],[2,1.18,549.72]],"ltp":1.19,"tv":3276.03,"id":8444034}]}]}
{"op":"mcm","clk":"1003663447","pt":1580651357137,"mc":[{"id":"1.168213437","rc":[{"batb":[[0,1.31,205.36]],"ltp":1.19,"tv":3276.03,"id":8444034}]}]}
{"op":"mcm","clk":"1003664103","pt":1580651360430,"mc":[{"id":"1.168213437","rc":[{"batl":[[0,5,4.86],[1,5.3,73.48],[2,1000,0.02]],"ltp":6.4,"tv":1203.07,"id":10107989},{"trd":[[1.31,637.2]],"batb":[[0,1.25,19.44]],"batl":[[0,1.28,224.25],[1,1.62,614.4],[2,1000,0.02]],"ltp":1.31,"tv":3686.75,"id":8444034}],"tv":4889.82}]}
{"op":"mcm","clk":"1003664232","pt":1580651361054,"mc":[{"id":"1.168213437","rc":[{"batb":[[0,4.8,58.78],[1,4.4,73.1],[2,2.6,75.72]],"ltp":6.4,"tv":1203.07,"id":10107989}]}]}
{"op":"mcm","clk":"1003666411","pt":1580651372652,"mc":[{"id":"1.168213437","rc":[{"batb":[[0,4.4,73.1],[1,2.6,75.72],[2,2.2,75.72]],"batl":[[0,1000,0.02],[1,5.3,0],[2,1000,0]],"ltp":6.4,"tv":1203.07,"id":10107989},{"batb":[[0,1.18,549.72],[1,1.17,553.53],[2,1.1,378.72]],"batl":[[0,1.62,614.4],[1,1000,0.02],[2,1000,0]],"ltp":1.31,"tv":3686.75,"id":8444034}]}]}
{"op":"mcm","clk":"1003668297","pt":1580651382573,"mc":[{"id":"1.168213437","rc":[{"batb":[[0,5.5,3.81],[1,4.4,73.1],[2,2.6,75.72]],"batl":[[0,6.2,82.37],[1,1000,0.02]],"ltp":6.4,"tv":1203.07,"id":10107989},{"batb":[[0,1.21,20.89]],"batl":[[0,1.24,405.55]],"ltp":1.31,"tv":3686.75,"id":8444034}]}]}
{"op":"mcm","clk":"1003668463","pt":1580651383534,"mc":[{"id":"1.168213437","rc":[{"batb":[[0,5.7,79.39],[1,5.5,3.81],[2,4.9,57.6]],"ltp":6.4,"tv":1203.07,"id":10107989},{"batb":[[2,1.11,866.6]],"ltp":1.31,"tv":3686.75,"id":8444034}]}]}
{"op":"mcm","clk":"1003669042","pt":1580651386471,"mc":[{"id":"1.168213437","rc":[{"batb":[[2,1.14,610.45]],"batl":[[1,1.55,690.76],[2,1000,0.02]],"ltp":1.31,"tv":3686.75,"id":8444034}]}]}
{"op":"mcm","clk":"1003671780","pt":1580651400713,"mc":[{"id":"1.168213437","rc":[{"batb":[[1,4.9,57.6],[2,3,75.72]],"batl":[[0,1000,0.02],[1,1000,0]],"ltp":6.4,"tv":1203.07,"id":10107989},{"batb":[[0,1.17,553.53],[1,1.14,610.45],[2,1.11,866.6]],"batl":[[0,1.55,690.76],[1,1000,0.02],[2,1000,0]],"ltp":1.31,"tv":3686.75,"id":8444034}]}]}
{"op":"mcm","clk":"1003671928","pt":1580651401478,"mc":[{"id":"1.168213437","rc":[{"batb":[[0,4.9,57.6],[1,3,75.72],[2,2.6,75.72]],"ltp":6.4,"tv":1203.07,"id":10107989},{"batb":[[0,1.14,610.45],[1,1.11,866.6],[2,1.05,378.72]],"ltp":1.31,"tv":3686.75,"id":8444034}]}]}
{"op":"mcm","clk":"1003672707","pt":1580651405004,"mc":[{"id":"1.168213437","rc":[{"batb":[[0,1.22,5.36],[1,1.14,610.45],[2,1.11,866.6]],"ltp":1.31,"tv":3686.75,"id":8444034}]}]}
{"op":"mcm","clk":"1003673376","pt":1580651408275,"mc":[{"id":"1.168213437","rc":[{"batb":[[1,1.11,866.6],[2,1.05,378.72]],"ltp":1.31,"tv":3686.75,"id":8444034}]}]}
{"op":"mcm","clk":"1003673570","pt":1580651409167,"mc":[{"id":"1.168213437","rc":[{"trd":[[4.9,33.68]],"batb":[[0,4.9,53.92],[1,4.5,69.6]],"ltp":4.9,"tv":1206.75,"id":10107989},{"trd":[[1.26,130.98]],"batb":[[0,1.24,326.23],[1,1.22,5.36],[2,1.11,866.6]],"batl":[[0,1.28,32.76],[1,1.55,690.76],[2,1000,0.02]],"ltp":1.26,"tv":3701.06,"id":8444034}],"tv":4907.81}]}
{"op":"mcm","clk":"1003673741","pt":1580651409946,"mc":[{"id":"1.168213437","rc":[{"batb":[[2,4.3,75.46]],"ltp":4.9,"tv":1206.75,"id":10107989},{"batb":[[1,1.22,434.49],[2,1.16,609.16]],"ltp":1.26,"tv":3701.06,"id":8444034}]}]}
{"op":"mcm","clk":"1003674244","pt":1580651412565,"mc":[{"id":"1.168213437","rc":[{"batb":[[2,1.16,1185.29]],"ltp":1.26,"tv":3701.06,"id":8444034}]}]}
{"op":"mcm","clk":"1003675560","pt":1580651418967,"mc":[{"id":"1.168213437","rc":[{"batl":[[0,1.55,690.76],[1,1000,0.02],[2,1000,0]],"ltp":1.26,"tv":3701.06,"id":8444034}]}]}
{"op":"mcm","clk":"1003676012","pt":1580651421274,"mc":[{"id":"1.168213437","rc":[{"batb":[[1,1.22,429.13]],"ltp":1.26,"tv":3701.06,"id":8444034}]}]}
{"op":"mcm","clk":"1003676272","pt":1580651422563,"mc":[{"id":"1.168213437","rc":[{"batb":[[1,4.3,75.46],[2,2.6,75.72]],"ltp":4.9,"tv":1206.75,"id":10107989},{"batb":[[0,1.22,429.13],[1,1.16,1185.29],[2,1.05,378.72]],"ltp":1.26,"tv":3701.06,"id":8444034}]}]}
{"op":"mcm","clk":"1003676426","pt":1580651423369,"mc":[{"id":"1.168213437","rc":[{"batb":[[0,4.3,75.46],[1,2.6,75.72],[2,2.2,75.72]],"ltp":4.9,"tv":1206.75,"id":10107989},{"batb":[[0,1.16,1179.62],[1,1.05,378.72],[2,1.03,387.52]],"ltp":1.26,"tv":3701.06,"id":8444034}]}]}
{"op":"mcm","clk":"1003676637","pt":1580651424486,"mc":[{"id":"1.168213437","rc":[{"batb":[[0,1.26,5.36],[1,1.16,1179.62],[2,1.05,378.72]],"ltp":1.26,"tv":3701.06,"id":8444034}]}]}
{"op":"mcm","clk":"1003677185","pt":1580651427295,"mc":[{"id":"1.168213437","rc":[{"batb":[[1,1.16,603.49]],"ltp":1.26,"tv":3701.06,"id":8444034}]}]}
{"op":"mcm","clk":"1003677869","pt":1580651430710,"mc":[{"id":"1.168213437","rc":[{"batb":[[2,1.14,610.45]],"ltp":1.26,"tv":3701.06,"id":8444034}]}]}
{"op":"mcm","clk":"1003680019","pt":1580651441302,"mc":[{"id":"1.168213437","rc":[{"batb":[[2,1.05,378.72]],"ltp":1.26,"tv":3701.06,"id":8444034}]}]}
{"op":"mcm","clk":"1003680305","pt":1580651442599,"mc":[{"id":"1.168213437","rc":[{"batb":[[0,6,69.24],[1,4.5,68.22],[2,4.3,75.46]],"batl":[[0,6.2,4.34],[1,1000,0.02]],"ltp":4.9,"tv":1206.75,"id":10107989},{"trd":[[1.26,141.7]],"batb":[[0,1.18,403.81],[2,1.06,1717.25]],"batl":[[0,1.21,32.15],[1,1.28,1372.49],[2,1.55,690.76]],"ltp":1.26,"tv":3711.78,"id":8444034}],"tv":4918.53}]}
{"op":"mcm","clk":"1003680434","pt":1580651443253,"mc":[{"id":"1.168213437","rc":[{"batb":[[2,2.6,75.72]],"ltp":4.9,"tv":1206.75,"id":10107989}]}]}
{"op":"mcm","clk":"1003680872","pt":1580651445473,"mc":[{"id":"1.168213437","rc":[{"batb":[[2,3,75.72]],"ltp":4.9,"tv":1206.75,"id":10107989},{"batb":[[2,1.12,650.34]],"ltp":1.26,"tv":3711.78,"id":8444034}]}]}
{"op":"mcm","clk":"1003681471","pt":1580651448622,"mc":[{"id":"1.168213437","rc":[{"batb":[[2,3.5,37.86]],"ltp":4.9,"tv":1206.75,"id":10107989}]}]}
{"op":"mcm","clk":"1003682142","pt":1580651452018,"mc":[{"id":"1.168213437","rc":[{"batl":[[0,1000,0.02],[1,1000,0]],"ltp":4.9,"tv":1206.75,"id":10107989},{"batl":[[0,1.28,1372.49],[1,1.55,690.76],[2,1000,0.02]],"ltp":1.26,"tv":3711.78,"id":8444034}]}]}
{"op":"mcm","clk":"1003682760","pt":1580651455282,"mc":[{"id":"1.168213437","rc":[{"batl":[[0,6.2,5.43],[1,1000,0.02]],"ltp":4.9,"tv":1206.75,"id":10107989},{"batl":[[0,1.21,31.94],[1,1.28,1372.49],[2,1.55,690.76]],"ltp":1.26,"tv":3711.78,"id":8444034}]}]}
{"op":"mcm","clk":"1003683294","pt":1580651458286,"mc":[{"id":"1.168213437","rc":[{"trd":[[6.2,5.43]],"batb":[[2,3,75.72]],"batl":[[0,1000,0.02],[1,1000,0]],"ltp":6.2,"tv":1212.18,"id":10107989},{"trd":[[1.19,29.61]],"batl":[[0,1.19,121.71],[1,1.21,31.94],[2,1.28,1372.49]],"ltp":1.19,"tv":3740.07,"id":8444034}],"tv":4952.25}]}
{"op":"mcm","clk":"1003683946","pt":1580651461598,"mc":[{"id":"1.168213437","rc":[{"batb":[[2,3.5,37.86]],"ltp":6.2,"tv":1212.18,"id":10107989}]}]}
{"op":"mcm","clk":"1003684123","pt":1580651462507,"mc":[{"id":"1.168213437","rc":[{"batb":[[0,4.5,68.22],[1,3.5,37.86],[2,3,75.72]],"ltp":6.2,"tv":1212.18,"id":10107989},{"batb":[[0,1.12,650.34],[1,1.06,1717.25],[2,1.05,378.62]],"batl":[[1,1.55,690.76],[2,1000,0.02]],"ltp":1.19,"tv":3740.07,"id":8444034}]}]}
{"op":"mcm","clk":"1003684260","pt":1580651463313,"mc":[{"id":"1.168213437","rc":[{"batb":[[0,1.06,1717.25],[1,1.05,378.62],[2,1.03,387.52]],"batl":[[1,1000,0.02],[2,1000,0]],"ltp":1.19,"tv":3740.07,"id":8444034}]}]}
{"op":"mcm","clk":"1003684629","pt":1580651465225,"mc":[{"id":"1.168213437","rc":[{"batl":[[0,1000,0.02],[1,1000,0]],"ltp":1.19,"tv":3740.07,"id":8444034}]}]}
{"op":"mcm","clk":"1003686797","pt":1580651476730,"mc":[{"id":"1.168213437","rc":[{"batb":[[0,13,31.08],[1,9.6,62.39],[2,3.5,37.86]],"batl":[[0,17.5,110.01],[1,1000,0.02]],"ltp":6.2,"tv":1212.18,"id":10107989},{"trd":[[1.1,0.2]],"batb":[[0,1.06,1717.15],[1,1.04,2199.11],[2,1.03,8.4]],"batl":[[0,1.09,60.69],[1,1.11,767.34],[2,1000,0.02]],"ltp":1.1,"tv":3740.27,"id":8444034}],"tv":4952.45}]}
{"op":"mcm","clk":"1003687146","pt":1580651478527,"mc":[{"id":"1.168213437","rc":[{"trd":[[1.06,244.01]],"batb":[[0,1.06,1595.15],[1,1.04,3433.66]],"batl":[[2,1.36,1025.96]],"ltp":1.06,"tv":3984.28,"id":8444034}],"tv":5196.46}]}
{"op":"mcm","clk":"1003687343","pt":1580651479559,"mc":[{"id":"1.168213437","rc":[{"batb":[[2,4,37.86]],"ltp":6.2,"tv":1212.18,"id":10107989}]}]}
{"op":"mcm","clk":"1003687830","pt":1580651482341,"mc":[{"id":"1.168213437","rc":[{"batb":[[2,5,37.86]],"ltp":6.2,"tv":1212.18,"id":10107989}]}]}
{"op":"mcm","clk":"1003688277","pt":1580651484965,"mc":[{"id":"1.168213437","rc":[{"batb":[[0,13,30.45],[1,9.6,61.21]],"ltp":6.2,"tv":1212.18,"id":10107989},{"batb":[[0,1.05,1736.59]],"ltp":1.06,"tv":3984.28,"id":8444034}]}]}
{"op":"mcm","clk":"1003688455","pt":1580651485936,"mc":[{"id":"1.168213437","rc":[{"batl":[[0,1.11,767.34],[1,1.36,1025.96],[2,1000,0.02]],"ltp":1.06,"tv":3984.28,"id":8444034}]}]}
{"op":"mcm","clk":"1003688952","pt":1580651488858,"mc":[{"id":"1.168213437","rc":[{"batl":[[0,1.09,60.69],[1,1.11,767.34],[2,1.36,1025.96]],"ltp":1.06,"tv":3984.28,"id":8444034}]}]}
{"op":"mcm","clk":"1003689722","pt":1580651493183,"mc":[{"id":"1.168213437","rc":[{"trd":[[1.09,114.39]],"batl":[[0,1.09,3.48]],"ltp":1.09,"tv":4098.66,"id":8444034}],"tv":5310.85}]}
{"op":"mcm","clk":"1003690393","pt":1580651496640,"mc":[{"id":"1.168213437","rc":[{"trd":[[13,0.16]],"batb":[[0,13,30.29]],"ltp":13.0,"tv":1212.34,"id":10107989},{"trd":[[1.09,123.22]],"batb":[[0,1.05,1736.27]],"batl":[[0,1.11,767.34],[1,1.36,1025.96],[2,1000,0.02]],"ltp":1.09,"tv":4107.5,"id":8444034}],"tv":5319.84}]}
{"op":"mcm","clk":"1003691819","pt":1580651504813,"mc":[{"id":"1.168213437","rc":[{"batb":[[0,1.05,1735.33]],"ltp":1.09,"tv":4107.5,"id":8444034}]}]}
{"op":"mcm","clk":"1003692651","pt":1580651509396,"mc":[{"id":"1.168213437","rc":[{"batb":[[1,11,3.65],[2,9.6,61.21]],"batl":[[0,13.5,3.65],[1,17.5,110.01],[2,1000,0.02]],"ltp":13.0,"tv":1212.34,"id":10107989},{"batb":[[0,1.08,45.59],[1,1.05,1735.33],[2,1.04,3433.66]],"batl":[[0,1.1,36.47],[1,1.11,767.34],[2,1.36,1025.96]],"ltp":1.09,"tv":4107.5,"id":8444034}]}]}
{"op":"mcm","clk":"1003694286","pt":1580651518497,"mc":[{"id":"1.168213437","rc":[{"batb":[[1,1.05,1732.65]],"ltp":1.09,"tv":4107.5,"id":8444034}]}]}
{"op":"mcm","clk":"1003695524","pt":1580651525322,"mc":[{"id":"1.168213437","rc":[{"trd":[[13.5,1.94]],"batl":[[0,13.5,2.68]],"ltp":13.5,"tv":1214.27,"id":10107989}],"tv":5321.78}]}
{"op":"mcm","clk":"1003695691","pt":1580651526231,"mc":[{"id":"1.168213437","rc":[{"trd":[[13,3.69]],"batb":[[0,13,28.52]],"ltp":13.0,"tv":1217.81,"id":10107989}],"tv":5325.32}]}
{"op":"mcm","clk":"1003695795","pt":1580651526760,"mc":[{"id":"1.168213437","rc":[{"batb":[[1,1.05,1728.88]],"ltp":1.09,"tv":4107.5,"id":8444034}]}]}
{"op":"mcm","clk":"1003696384","pt":1580651529739,"mc":[{"id":"1.168213437","rc":[{"trd":[[1.08,5.07]],"batb":[[0,1.08,43.05]],"ltp":1.08,"tv":4112.57,"id":8444034}],"tv":5330.39}]}
{"op":"mcm","clk":"1003696553","pt":1580651530552,"mc":[{"id":"1.168213437","rc":[{"trd":[[13,3.86]],"batb":[[0,13,28.36]],"ltp":13.0,"tv":1217.98,"id":10107989},{"trd":[[1.09,125.22]],"ltp":1.09,"tv":4114.57,"id":8444034}],"tv":5332.56}]}
{"op":"mcm","clk":"1003696809","pt":1580651531825,"mc":[{"id":"1.168213437","rc":[{"trd":[[13.5,2.38]],"batl":[[0,13.5,2.46]],"ltp":13.5,"tv":1218.42,"id":10107989}],"tv":5333.0}]}
{"op":"mcm","clk":"1003697491","pt":1580651535492,"mc":[{"id":"1.168213437","rc":[{"batb":[[1,9.6,61.21],[2,5,37.86]],"batl":[[0,17.5,110.01],[1,1000,0.02],[2,1000,0]],"ltp":13.5,"tv":1218.42,"id":10107989},{"batb":[[0,1.05,1728.56],[1,1.04,3433.66],[2,1.03,8.4]],"batl":[[0,1.11,767.34],[1,1.36,1025.96],[2,1000,0.02]],"ltp":1.09,"tv":4114.57,"id":8444034}]}]}
{"op":"mcm","clk":"1003698026","pt":1580651538480,"mc":[{"id":"1.168213437","rc":[{"batl":[[0,13.5,5.9],[1,17.5,110.01],[2,1000,0.02]],"ltp":13.5,"tv":1218.42,"id":10107989}]}]}
{"op":"mcm","clk":"1003698275","pt":1580651539862,"mc":[{"id":"1.168213437","rc":[{"batl":[[0,17.5,110.01],[1,1000,0.02],[2,1000,0]],"ltp":13.5,"tv":1218.42,"id":10107989}]}]}
{"op":"mcm","clk":"1003699137","pt":1580651544803,"mc":[{"id":"1.168213437","rc":[{"trd":[[17.5,6.06]],"batl":[[0,17.5,103.95]],"ltp":17.5,"tv":1224.48,"id":10107989},{"trd":[[1.06,344.01]],"ltp":1.06,"tv":4214.57,"id":8444034}],"tv":5439.06}]}
{"op":"mcm","clk":"1003699338","pt":1580651545892,"mc":[{"id":"1.168213437","rc":[{"batl":[[0,13.5,5.9],[1,17.5,103.95],[2,1000,0.02]],"ltp":17.5,"tv":1224.48,"id":10107989}]}]}
{"op":"mcm","clk":"1003699696","pt":1580651547710,"mc":[{"id":"1.168213437","rc":[{"batl":[[0,1000,0.02],[1,17.5,0],[2,1000,0]],"ltp":17.5,"tv":1224.48,"id":10107989},{"batl":[[0,1.36,1025.96],[1,1000,0.02],[2,1000,0]],"ltp":1.06,"tv":4214.57,"id":8444034}]}]}
{"op":"mcm","clk":"1003699787","pt":1580651548200,"mc":[{"id":"1.168213437","rc":[{"batb":[[0,9.6,61.21],[1,5,37.86],[2,4,37.86]],"ltp":17.5,"tv":1224.48,"id":10107989},{"batb":[[0,1.04,3433.66],[1,1.03,8.4],[2,1.02,25.41]],"ltp":1.06,"tv":4214.57,"id":8444034}]}]}
{"op":"mcm","clk":"1003701182","pt":1580651556628,"mc":[{"id":"1.168213437","rc":[{"batb":[[0,1.04,2199.11]],"ltp":1.06,"tv":4214.57,"id":8444034}]}]}
{"op":"mcm","clk":"1003701509","pt":1580651558724,"mc":[{"id":"1.168213437","rc":[{"batb":[[0,15.5,20.06],[1,13.5,31.2],[2,11.5,39.1]],"batl":[[0,17.5,7.08],[1,1000,0.02]],"ltp":17.5,"tv":1224.48,"id":10107989},{"batb":[[0,1.06,508.84],[1,1.04,2199.11],[2,1.03,2821.99]],"batl":[[0,1.08,390.02],[1,1.36,1025.96],[2,1000,0.02]],"ltp":1.06,"tv":4214.57,"id":8444034}]}]}
{"op":"mcm","clk":"1003701864","pt":1580651560701,"mc":[{"id":"1.168213437","rc":[{"batb":[[2,1.03,4357.83]],"ltp":1.06,"tv":4214.57,"id":8444034}]}]}
{"op":"mcm","clk":"1003703203","pt":1580651568510,"mc":[{"id":"1.168213437","rc":[{"batb":[[1,13.5,33.2],[2,12,2]],"batl":[[1,26,2],[2,1000,0.02]],"ltp":17.5,"tv":1224.48,"id":10107989},{"batb":[[1,1.04,2684.23]],"batl":[[0,1.08,583.21],[1,1.09,199.5],[2,1.1,177.95]],"ltp":1.06,"tv":4214.57,"id":8444034}]}]}
{"op":"mcm","clk":"1003703271","pt":1580651568843,"mc":[{"id":"1.168213437","rc":[{"batb":[[1,13.5,31.2],[2,11.5,39.1]],"ltp":17.5,"tv":1224.48,"id":10107989},{"batb":[[1,1.04,2199.11]],"ltp":1.06,"tv":4214.57,"id":8444034}]}]}
{"op":"mcm","clk":"1003703965","pt":1580651573051,"mc":[{"id":"1.168213437","rc":[{"trd":[[17.5,6.16]],"batl":[[0,17.5,7.03]],"ltp":17.5,"tv":1224.58,"id":10107989}],"tv":5439.16}]}
{"op":"mcm","clk":"1003704178","pt":1580651574235,"mc":[{"id":"1.168213437","rc":[{"batb":[[1,11.5,39.1],[2,6,37.86]],"batl":[[0,26,2],[1,1000,0.02],[2,1000,0]],"ltp":17.5,"tv":1224.58,"id":10107989},{"batb":[[0,1.04,2199.11],[1,1.03,4357.83],[2,1.02,25.41]],"batl":[[0,1.08,193.19]],"ltp":1.06,"tv":4214.57,"id":8444034}]}]}
{"op":"mcm","clk":"1003704311","pt":1580651575036,"mc":[{"id":"1.168213437","rc":[{"batb":[[0,11.5,39.1],[1,6,37.86],[2,5,37.86]],"ltp":17.5,"tv":1224.58,"id":10107989},{"batb":[[0,1.03,4358.33],[1,1.02,25.41],[2,1.01,22.51]],"batl":[[0,1.09,199.5],[1,1.1,177.95],[2,1.36,1025.96]],"ltp":1.06,"tv":4214.57,"id":8444034}]}]}
{"op":"mcm","clk":"1003704471","pt":1580651575930,"mc":[{"id":"1.168213437","rc":[{"batb":[[0,12,2],[1,11.5,39.1],[2,6,37.86]],"ltp":17.5,"tv":1224.58,"id":10107989},{"batb":[[0,1.04,502.37],[1,1.03,4357.83],[2,1.02,25.41]],"ltp":1.06,"tv":4214.57,"id":8444034}]}]}
{"op":"mcm","clk":"1003704979","pt":1580651578683,"mc":[{"id":"1.168213437","rc":[{"batl":[[2,1.19,756.18]],"ltp":1.06,"tv":4214.57,"id":8444034}]}]}
{"op":"mcm","clk":"1003705324","pt":1580651580558,"mc":[{"id":"1.168213437","rc":[{"batl":[[0,26,2.11]],"ltp":17.5,"tv":1224.58,"id":10107989}]}]}
{"op":"mcm","clk":"1003705709","pt":1580651582558,"mc":[{"id":"1.168213437","rc":[{"batb":[[0,13.5,2],[1,12,2],[2,11.5,39.1]],"ltp":17.5,"tv":1224.58,"id":10107989}]}]}
{"op":"mcm","clk":"1003705927","pt":1580651583646,"mc":[{"id":"1.168213437","rc":[{"batb":[[0,12,2],[1,11.5,39.1],[2,6,37.86]],"ltp":17.5,"tv":1224.58,"id":10107989},{"batb":[[1,1.03,2821.99]],"ltp":1.06,"tv":4214.57,"id":8444034}]}]}
{"op":"mcm","clk":"1003706141","pt":1580651584668,"mc":[{"id":"1.168213437","rc":[{"trd":[[14.5,0.11]],"batb":[[0,13.5,58.9],[1,12,2],[2,11.5,39.1]],"batl":[[0,26,41.83]],"ltp":14.5,"tv":1224.69,"id":10107989},{"trd":[[1.07,1.49]],"batb":[[0,1.04,1498.1]],"batl":[[0,1.08,736.24],[1,1.09,199.5],[2,1.1,177.95]],"ltp":1.07,"tv":4216.06,"id":8444034}],"tv":5440.76}]}
{"op":"mcm","clk":"1003706290","pt":1580651585455,"mc":[{"id":"1.168213437","rc":[{"batb":[[0,18.5,27.3],[1,14.5,23.13],[2,13.5,58.9]],"ltp":14.5,"tv":1224.69,"id":10107989},{"batb":[[2,1.02,3461.76]],"ltp":1.07,"tv":4216.06,"id":8444034}]}]}
{"op":"mcm","clk":"1003706704","pt":1580651587649,"mc":[{"id":"1.168213437","rc":[{"batl":[[0,21,4.82],[1,26,41.83],[2,1000,0.02]],"ltp":14.5,"tv":1224.69,"id":10107989},{"batb":[[2,1.02,5609.72]],"batl":[[0,1.06,47.79],[1,1.08,736.24],[2,1.09,199.5]],"ltp":1.07,"tv":4216.06,"id":8444034}]}]}
{"op":"mcm","clk":"1003708070","pt":1580651594984,"mc":[{"id":"1.168213437","rc":[{"batb":[[1,15,2],[2,14.5,23.13]],"batl":[[2,36,2]],"ltp":14.5,"tv":1224.69,"id":10107989},{"batb":[[1,1.03,3508.82],[2,1.02,6639.36]],"batl":[[1,1.07,250.5],[2,1.08,961.43]],"ltp":1.07,"tv":4216.06,"id":8444034}]}]}
{"op":"mcm","clk":"1003708618","pt":1580651598088,"mc":[{"id":"1.168213437","rc":[{"trd":[[21,0.53]],"batl":[[0,21,4.29]],"ltp":21.0,"tv":1225.22,"id":10107989},{"trd":[[1.05,10.56]],"ltp":1.05,"tv":4226.62,"id":8444034}],"tv":5451.84}]}
{"op":"mcm","clk":"1003709053","pt":1580651600688,"mc":[{"id":"1.168213437","rc":[{"batl":[[0,26,41.83],[1,36,2],[2,1000,0.02]],"ltp":21.0,"tv":1225.22,"id":10107989},{"batl":[[0,1.07,250.5],[1,1.08,961.43],[2,1.09,199.5]],"ltp":1.05,"tv":4226.62,"id":8444034}]}]}
{"op":"mcm","clk":"1003709180","pt":1580651601486,"mc":[{"id":"1.168213437","rc":[{"batb":[[0,14.5,23.13],[1,13.5,2],[2,12,2]],"batl":[[0,36,2],[1,1000,0.02],[2,1000,0]],"ltp":21.0,"tv":1225.22,"id":10107989},{"batb":[[0,1.03,695.73],[1,1.02,6639.36],[2,1.01,22.51]],"batl":[[0,1.08,225.19],[1,1.09,199.5],[2,1.1,177.95]],"ltp":1.05,"tv":4226.62,"id":8444034}]}]}
{"op":"mcm","clk":"1003709799","pt":1580651604691,"mc":[{"id":"1.168213437","rc":[{"batb":[[0,15,2],[1,14.5,23.13],[2,13.5,2]],"ltp":21.0,"tv":1225.22,"id":10107989},{"batl":[[0,1.07,262.5],[1,1.08,225.19],[2,1.09,199.5]],"ltp":1.05,"tv":4226.62,"id":8444034}]}]}
{"op":"mcm","clk":"1003709834","pt":1580651604898,"mc":[{"id":"1.168213437","rc":[{"batb":[[0,14.5,23.13],[1,13.5,2],[2,12,2]],"ltp":21.0,"tv":1225.22,"id":10107989},{"batl":[[0,1.08,225.19],[1,1.09,199.5],[2,1.1,177.95]],"ltp":1.05,"tv":4226.62,"id":8444034}]}]}
{"op":"mcm","clk":"1003710296","pt":1580651607677,"mc":[{"id":"1.168213437","rc":[{"batl":[[0,26,2],[1,36,2],[2,1000,0.02]],"ltp":21.0,"tv":1225.22,"id":10107989},{"batb":[[0,1.04,486.12],[1,1.03,695.23],[2,1.02,6639.36]],"ltp":1.05,"tv":4226.62,"id":8444034}]}]}
{"op":"mcm","clk":"1003710423","pt":1580651608371,"mc":[{"id":"1.168213437","rc":[{"batl":[[0,36,2],[1,1000,0.02],[2,1000,0]],"ltp":21.0,"tv":1225.22,"id":10107989},{"batb":[[0,1.03,695.73],[1,1.02,6639.36],[2,1.01,22.51]],"ltp":1.05,"tv":4226.62,"id":8444034}]}]}
{"op":"mcm","clk":"1003711038","pt":1580651611599,"mc":[{"id":"1.168213437","rc":[{"batb":[[0,15,2],[1,14.5,23.13],[2,13.5,2]],"ltp":21.0,"tv":1225.22,"id":10107989},{"batl":[[0,1.07,268.5],[1,1.08,225.19],[2,1.09,199.5]],"ltp":1.05,"tv":4226.62,"id":8444034}]}]}
{"op":"mcm","clk":"1003711083","pt":1580651611815,"mc":[{"id":"1.168213437","rc":[{"batb":[[0,14.5,23.13],[1,13.5,2],[2,12,2]],"ltp":21.0,"tv":1225.22,"id":10107989},{"batl":[[0,1.08,225.19],[1,1.09,199.5],[2,1.1,177.95]],"ltp":1.05,"tv":4226.62,"id":8444034}]}]}
{"op":"mcm","clk":"1003711411","pt":1580651613710,"mc":[{"id":"1.168213437","rc":[{"batb":[[1,1.02,4491.4]],"ltp":1.05,"tv":4226.62,"id":8444034}]}]}
{"op":"mcm","clk":"1003711594","pt":1580651614732,"mc":[{"id":"1.168213437","rc":[{"batb":[[1,13.5,20.31]],"batl":[[0,17.5,367.24],[1,21,56.53],[2,36,2]],"ltp":21.0,"tv":1225.22,"id":10107989},{"batb":[[0,1.05,1130.64],[1,1.03,695.73],[2,1.02,4491.4]],"batl":[[0,1.08,494.17]],"ltp":1.05,"tv":4226.62,"id":8444034}]}]}
{"op":"mcm","clk":"1003711750","pt":1580651615522,"mc":[{"id":"1.168213437","rc":[{"batl":[[0,17.5,8.44],[2,26,2]],"ltp":21.0,"tv":1225.22,"id":10107989},{"batb":[[0,1.05,3168.97],[1,1.04,437.12],[2,1.03,3403.15]],"ltp":1.05,"tv":4226.62,"id":8444034}]}]}
{"op":"mcm","clk":"1003712167","pt":1580651617728,"mc":[{"id":"1.168213437","rc":[{"batb":[[2,1.03,4938.99]],"ltp":1.05,"tv":4226.62,"id":8444034}]}]}
{"op":"mcm","clk":"1003713154","pt":1580651623329,"mc":[{"id":"1.168213437","rc":[{"batl":[[1,21,58.53]],"ltp":21.0,"tv":1225.22,"id":10107989},{"batb":[[0,1.05,3497.26]],"ltp":1.05,"tv":4226.62,"id":8444034}]}]}
{"op":"mcm","clk":"1003715006","pt":1580651633756,"mc":[{"id":"1.168213437","rc":[{"trd":[[17.5,14.6]],"batl":[[0,21,58.53],[1,26,2],[2,36,2]],"ltp":17.5,"tv":1233.66,"id":10107989},{"trd":[[1.06,483.35]],"batl":[[0,1.06,833.66],[1,1.08,494.17],[2,1.09,199.5]],"ltp":1.06,"tv":4365.96,"id":8444034}],"tv":5599.62}]}
{"op":"mcm","clk":"1003715721","pt":1580651637661,"mc":[{"id":"1.168213437","rc":[{"batb":[[0,12,2],[1,10.5,49.49],[2,10,2]],"batl":[[0,36,2],[1,1000,0.02],[2,36,0]],"ltp":17.5,"tv":1233.66,"id":10107989},{"batb":[[0,1.03,4939.49],[1,1.02,1065.92],[2,1.01,22.51]],"batl":[[1,1.09,199.5],[2,1.1,177.95]],"ltp":1.06,"tv":4365.96,"id":8444034}]}]}
{"op":"mcm","clk":"1003716234","pt":1580651640639,"mc":[{"id":"1.168213437","rc":[{"batb":[[1,11,2],[2,10.5,49.49]],"ltp":17.5,"tv":1233.66,"id":10107989}]}]}
{"op":"mcm","clk":"1003716617","pt":1580651642936,"mc":[{"id":"1.168213437","rc":[{"batb":[[0,11,2],[1,10.5,49.49],[2,6,37.86]],"ltp":17.5,"tv":1233.66,"id":10107989},{"batl":[[1,1.1,177.95],[2,1.19,756.18]],"ltp":1.06,"tv":4365.96,"id":8444034}]}]}
{"op":"mcm","clk":"1003716954","pt":1580651644742,"mc":[{"id":"1.168213437","rc":[{"trd":[[17.5,65.1]],"batl":[[0,12.5,21.81],[1,13.5,6.49],[2,21,149.16]],"ltp":17.5,"tv":1284.16,"id":10107989},{"trd":[[1.06,1317.01]],"batb":[[0,1.05,2983.11],[1,1.04,423.87],[2,1.03,3403.15]],"batl":[[0,1.1,177.95],[1,1.12,648.04]],"ltp":1.06,"tv":5199.62,"id":8444034}],"tv":6483.78}]}
{"op":"mcm","clk":"1003717108","pt":1580651645655,"mc":[{"id":"1.168213437","rc":[{"batb":[[2,7,48.47]],"batl":[[0,21,149.16],[1,26,2],[2,36,2]],"ltp":17.5,"tv":1284.16,"id":10107989},{"batb":[[0,1.07,1310.76],[1,1.05,4942.76],[2,1.04,423.87]],"ltp":1.06,"tv":5199.62,"id":8444034}]}]}
{"op":"mcm","clk":"1003717501","pt":1580651647649,"mc":[{"id":"1.168213437","rc":[{"batl":[[0,13.5,6.49],[1,21,149.16],[2,26,2]],"ltp":17.5,"tv":1284.16,"id":10107989}]}]}
{"op":"mcm","clk":"1003717556","pt":1580651647971,"mc":[{"id":"1.168213437","rc":[{"batb":[[1,1.05,6012.35]],"ltp":1.06,"tv":5199.62,"id":8444034}]}]}
{"op":"mcm","clk":"1003718213","pt":1580651651576,"mc":[{"id":"1.168213437","rc":[{"batl":[[2,1.36,1025.96]],"ltp":1.06,"tv":5199.62,"id":8444034}]}]}
{"op":"mcm","clk":"1003718270","pt":1580651652008,"mc":[{"id":"1.168213437","rc":[{"batl":[[1,21,151.16]],"ltp":17.5,"tv":1284.16,"id":10107989},{"batb":[[1,1.05,6392.24]],"ltp":1.06,"tv":5199.62,"id":8444034}]}]}
{"op":"mcm","clk":"1003720299","pt":1580651663438,"mc":[{"id":"1.168213437","rc":[{"batl":[[0,21,2],[1,26,2],[2,36,2]],"ltp":17.5,"tv":1284.16,"id":10107989},{"batb":[[1,1.05,3409.13]],"batl":[[1,1.36,1025.96],[2,1.48,38.24]],"ltp":1.06,"tv":5199.62,"id":8444034}]}]}
{"op":"mcm","clk":"1003720391","pt":1580651663895,"mc":[{"id":"1.168213437","rc":[{"batb":[[0,7,48.47],[1,5,37.86],[2,4,37.86]],"ltp":17.5,"tv":1284.16,"id":10107989},{"batb":[[0,1.05,3409.13],[1,1.04,423.87],[2,1.03,695.23]],"batl":[[0,1.36,1025.96],[1,1.51,39.5],[2,1.52,34.26]],"ltp":1.06,"tv":5199.62,"id":8444034}]}]}
{"op":"mcm","clk":"1003723796","pt":1580651682446,"mc":[{"id":"1.168213437","rc":[{"batl":[[0,26,2],[1,36,2],[2,1000,0.02]],"ltp":17.5,"tv":1284.16,"id":10107989},{"batb":[[0,1.05,3029.24]],"ltp":1.06,"tv":5199.62,"id":8444034}]}]}
{"op":"mcm","clk":"1003724041","pt":1580651683975,"mc":[{"id":"1.168213437","rc":[{"batb":[[0,1.05,1959.65]],"ltp":1.06,"tv":5199.62,"id":8444034}]}]}
