{"op":"mcm","clk":"993864652","pt":1580564223743,"mc":[{"id":"1.168213439","marketDefinition":{"bspMarket":false,"turnInPlayEnabled":true,"persistenceEnabled":true,"marketBaseRate":5.0,"eventId":"29681204","eventTypeId":"2","numberOfWinners":1,"bettingType":"ODDS","marketType":"SET_WINNER","marketTime":"2020-02-02T09:00:00.000Z","suspendTime":"2020-02-02T09:00:00.000Z","bspReconciled":false,"complete":true,"inPlay":false,"crossMatching":false,"runnersVoidable":false,"numberOfActiveRunners":2,"betDelay":0,"status":"OPEN","runners":[{"status":"ACTIVE","sortPriority":1,"id":8444034,"name":"Golubev/Nedovyesov"},{"status":"ACTIVE","sortPriority":2,"id":10107989,"name":"Sabanov/Sabanov"}],"regulators":["MR_INT"],"countryCode":"FR","discountAllowed":false,"timezone":"UTC","openDate":"2020-02-02T09:00:00.000Z","version":3145282989,"name":"Set 1 Winner","eventName":"Golubev/Nedovyesov v Sabanov/Sabanov"}}]}
{"op":"mcm","clk":"993865048","pt":1580564225394,"mc":[{"id":"1.168213439","rc":[{"batb":[[0,1.01,20]],"ltp":0.0,"tv":0.0,"id":10107989},{"batb":[[0,1.01,20]],"ltp":0.0,"tv":0.0,"id":8444034}]}]}
{"op":"mcm","clk":"993865150","pt":1580564225779,"mc":[{"id":"1.168213439","marketDefinition":{"bspMarket":false,"turnInPlayEnabled":true,"persistenceEnabled":true,"marketBaseRate":5.0,"eventId":"29681204","eventTypeId":"2","numberOfWinners":1,"bettingType":"ODDS","marketType":"SET_WINNER","marketTime":"2020-02-02T09:00:00.000Z","suspendTime":"2020-02-02T09:00:00.000Z","bspReconciled":false,"complete":true,"inPlay":false,"crossMatching":false,"runnersVoidable":false,"numberOfActiveRunners":2,"betDelay":0,"status":"OPEN","runners":[{"status":"ACTIVE","sortPriority":1,"id":8444034,"name":"Golubev/Nedovyesov"},{"status":"ACTIVE","sortPriority":2,"id":10107989,"name":"Sabanov/Sabanov"}],"regulators":["MR_INT"],"countryCode":"FR","discountAllowed":false,"timezone":"UTC","openDate":"2020-02-02T09:00:00.000Z","version":3145282989,"name":"Set 1 Winner","eventName":"Golubev/Nedovyesov v Sabanov/Sabanov"}}]}
{"op":"mcm","clk":"993865438","pt":1580564226748,"mc":[{"id":"1.168213439","marketDefinition":{"bspMarket":false,"turnInPlayEnabled":true,"persistenceEnabled":true,"marketBaseRate":5.0,"eventId":"29681204","eventTypeId":"2","numberOfWinners":1,"bettingType":"ODDS","marketType":"SET_WINNER","marketTime":"2020-02-02T09:00:00.000Z","suspendTime":"2020-02-02T09:00:00.000Z","bspReconciled":false,"complete":true,"inPlay":false,"crossMatching":false,"runnersVoidable":false,"numberOfActiveRunners":2,"betDelay":0,"status":"OPEN","runners":[{"status":"ACTIVE","sortPriority":1,"id":8444034,"name":"Golubev/Nedovyesov"},{"status":"ACTIVE","sortPriority":2,"id":10107989,"name":"Sabanov/Sabanov"}],"regulators":["MR_INT"],"countryCode":"FR","discountAllowed":true,"timezone":"UTC","openDate":"2020-02-02T09:00:00.000Z","version":3145282989,"name":"Set 1 Winner","eventName":"Golubev/Nedovyesov v Sabanov/Sabanov"}}]}
{"op":"mcm","clk":"993978302","pt":1580564712602,"mc":[{"id":"1.168213439","rc":[{"batb":[[0,1.01,15]],"ltp":0.0,"tv":0.0,"id":10107989},{"batb":[[0,1.01,15]],"ltp":0.0,"tv":0.0,"id":8444034}]}]}
{"op":"mcm","clk":"996243237","pt":1580574046235,"mc":[{"id":"1.168213439","marketDefinition":{"bspMarket":false,"turnInPlayEnabled":true,"persistenceEnabled":true,"marketBaseRate":5.0,"eventId":"29681204","eventTypeId":"2","numberOfWinners":1,"bettingType":"ODDS","marketType":"SET_WINNER","marketTime":"2020-02-02T13:00:00.000Z","suspendTime":"2020-02-02T13:00:00.000Z","bspReconciled":false,"complete":true,"inPlay":false,"crossMatching":false,"runnersVoidable":false,"numberOfActiveRunners":2,"betDelay":0,"status":"OPEN","runners":[{"status":"ACTIVE","sortPriority":1,"id":8444034,"name":"Golubev/Nedovyesov"},{"status":"ACTIVE","sortPriority":2,"id":10107989,"name":"Sabanov/Sabanov"}],"regulators":["MR_INT"],"countryCode":"FR","discountAllowed":true,"timezone":"UTC","openDate":"2020-02-02T09:00:00.000Z","version":3146180828,"name":"Set 1 Winner","eventName":"Golubev/Nedovyesov v Sabanov/Sabanov"}}]}
{"op":"mcm","clk":"996243943","pt":1580574049267,"mc":[{"id":"1.168213439","marketDefinition":{"bspMarket":false,"turnInPlayEnabled":true,"persistenceEnabled":true,"marketBaseRate":5.0,"eventId":"29681204","eventTypeId":"2","numberOfWinners":1,"bettingType":"ODDS","marketType":"SET_WINNER","marketTime":"2020-02-02T13:00:00.000Z","suspendTime":"2020-02-02T13:00:00.000Z","bspReconciled":false,"complete":true,"inPlay":false,"crossMatching":false,"runnersVoidable":false,"numberOfActiveRunners":2,"betDelay":0,"status":"OPEN","runners":[{"status":"ACTIVE","sortPriority":1,"id":8444034,"name":"Golubev/Nedovyesov"},{"status":"ACTIVE","sortPriority":2,"id":10107989,"name":"Sabanov/Sabanov"}],"regulators":["MR_INT"],"countryCode":"FR","discountAllowed":true,"timezone":"UTC","openDate":"2020-02-02T13:00:00.000Z","version":3146180828,"name":"Set 1 Winner","eventName":"Golubev/Nedovyesov v Sabanov/Sabanov"}}]}
{"op":"mcm","clk":"999037484","pt":1580591581985,"mc":[{"id":"1.168213439","rc":[{"batb":[[0,2.1,26.84],[1,1.01,15]],"ltp":0.0,"tv":0.0,"id":10107989},{"batb":[[0,1.67,44.06],[1,1.01,15]],"ltp":0.0,"tv":0.0,"id":8444034}]}]}
{"op":"mcm","clk":"999041446","pt":1580591613033,"mc":[{"id":"1.168213439","marketDefinition":{"bspMarket":false,"turnInPlayEnabled":true,"persistenceEnabled":true,"marketBaseRate":5.0,"eventId":"29681204","eventTypeId":"2","numberOfWinners":1,"bettingType":"ODDS","marketType":"SET_WINNER","marketTime":"2020-02-02T13:00:00.000Z","suspendTime":"2020-02-02T13:00:00.000Z","bspReconciled":false,"complete":true,"inPlay":false,"crossMatching":true,"runnersVoidable":false,"numberOfActiveRunners":2,"betDelay":0,"status":"OPEN","runners":[{"status":"ACTIVE","sortPriority":1,"id":8444034,"name":"Golubev/Nedovyesov"},{"status":"ACTIVE","sortPriority":2,"id":10107989,"name":"Sabanov/Sabanov"}],"regulators":["MR_INT"],"countryCode":"FR","discountAllowed":true,"timezone":"UTC","openDate":"2020-02-02T13:00:00.000Z","version":3146180828,"name":"Set 1 Winner","eventName":"Golubev/Nedovyesov v Sabanov/Sabanov"}}]}
{"op":"mcm","clk":"999914871","pt":1580602584406,"mc":[{"id":"1.168213439","rc":[{"batb":[[1,1.01,15.51]],"ltp":0.0,"tv":0.0,"id":10107989},{"batb":[[1,1.01,15.51]],"ltp":0.0,"tv":0.0,"id":8444034}]}]}
{"op":"mcm","clk":"999962543","pt":1580603350739,"mc":[{"id":"1.168213439","rc":[{"batb":[[1,1.01,16.01]],"ltp":0.0,"tv":0.0,"id":10107989},{"batb":[[1,1.01,16.01]],"ltp":0.0,"tv":0.0,"id":8444034}]}]}
{"op":"mcm","clk":"1001027143","pt":1580626804624,"mc":[{"id":"1.168213439","rc":[{"batb":[[0,2.1,40.26]],"ltp":0.0,"tv":0.0,"id":10107989},{"batb":[[0,1.67,66.1]],"ltp":0.0,"tv":0.0,"id":8444034}]}]}
{"op":"mcm","clk":"1001142548","pt":1580629375699,"mc":[{"id":"1.168213439","rc":[{"batb":[[0,2.2,36.9]],"ltp":0.0,"tv":0.0,"id":10107989},{"batb":[[0,1.62,71.43]],"ltp":0.0,"tv":0.0,"id":8444034}]}]}
{"op":"mcm","clk":"1001172120","pt":1580630097364,"mc":[{"id":"1.168213439","rc":[{"batb":[[0,1.57,77.69]],"ltp":0.0,"tv":0.0,"id":8444034}]}]}
{"op":"mcm","clk":"1001328238","pt":1580633556851,"mc":[{"id":"1.168213439","rc":[{"batb":[[0,1.62,71.43]],"ltp":0.0,"tv":0.0,"id":8444034}]}]}
{"op":"mcm","clk":"1001910700","pt":1580641203875,"mc":[{"id":"1.168213439","rc":[{"batb":[[0,2.2,49.2]],"ltp":0.0,"tv":0.0,"id":10107989},{"batb":[[0,1.62,95.24]],"ltp":0.0,"tv":0.0,"id":8444034}]}]}
{"op":"mcm","clk":"1002052886","pt":1580642011189,"mc":[{"id":"1.168213439","rc":[{"batb":[[0,2.1,53.68]],"ltp":0.0,"tv":0.0,"id":10107989},{"batb":[[0,1.67,88.13]],"ltp":0.0,"tv":0.0,"id":8444034}]}]}
{"op":"mcm","clk":"1002631567","pt":1580645539647,"mc":[{"id":"1.168213439","rc":[{"batb":[[1,1.01,17.69]],"ltp":0.0,"tv":0.0,"id":10107989},{"batb":[[0,1.68,1.5],[1,1.67,88.13],[2,1.01,16.01]],"ltp":0.0,"tv":0.0,"id":8444034}]}]}
{"op":"mcm","clk":"1002631675","pt":1580645540231,"mc":[{"id":"1.168213439","rc":[{"batb":[[0,2.12,1.19],[1,2.1,53.68],[2,1.01,16.01]],"ltp":0.0,"tv":0.0,"id":10107989}]}]}
{"op":"mcm","clk":"1002680268","pt":1580645839176,"mc":[{"id":"1.168213439","rc":[{"batl":[[0,1.9,7.57]],"ltp":0.0,"tv":0.0,"id":8444034}]}]}
{"op":"mcm","clk":"1002803317","pt":1580646621757,"mc":[{"id":"1.168213439","rc":[{"batb":[[0,1.68,3.5]],"ltp":0.0,"tv":0.0,"id":8444034}]}]}
{"op":"mcm","clk":"1002921181","pt":1580647221008,"mc":[{"id":"1.168213439","rc":[{"batb":[[0,1.68,1.5]],"ltp":0.0,"tv":0.0,"id":8444034}]}]}
{"op":"mcm","clk":"1003032753","pt":1580647775584,"mc":[{"id":"1.168213439","rc":[{"batb":[[0,2.36,17.62],[1,2.12,1.19],[2,2.1,53.68]],"ltp":0.0,"tv":0.0,"id":10107989},{"batb":[[2,1.65,26.59]],"ltp":0.0,"tv":0.0,"id":8444034}]}]}
{"op":"mcm","clk":"1003034239","pt":1580647783704,"mc":[{"id":"1.168213439","rc":[{"batb":[[0,2.34,17.86]],"ltp":0.0,"tv":0.0,"id":10107989},{"batb":[[2,1.65,26.36]],"ltp":0.0,"tv":0.0,"id":8444034}]}]}
{"op":"mcm","clk":"1003036088","pt":1580647793633,"mc":[{"id":"1.168213439","rc":[{"batb":[[0,2.32,18.1]],"ltp":0.0,"tv":0.0,"id":10107989},{"batb":[[2,1.66,25.97]],"ltp":0.0,"tv":0.0,"id":8444034}]}]}
{"op":"mcm","clk":"1003056996","pt":1580647911731,"mc":[{"id":"1.168213439","marketDefinition":{"bspMarket":false,"turnInPlayEnabled":true,"persistenceEnabled":true,"marketBaseRate":5.0,"eventId":"29681204","eventTypeId":"2","numberOfWinners":1,"bettingType":"ODDS","marketType":"SET_WINNER","marketTime":"2020-02-02T12:47:00.000Z","suspendTime":"2020-02-02T12:47:00.000Z","bspReconciled":false,"complete":true,"inPlay":false,"crossMatching":true,"runnersVoidable":false,"numberOfActiveRunners":2,"betDelay":0,"status":"OPEN","runners":[{"status":"ACTIVE","sortPriority":1,"id":8444034,"name":"Golubev/Nedovyesov"},{"status":"ACTIVE","sortPriority":2,"id":10107989,"name":"Sabanov/Sabanov"}],"regulators":["MR_INT"],"countryCode":"FR","discountAllowed":true,"timezone":"UTC","openDate":"2020-02-02T13:00:00.000Z","version":3148783607,"name":"Set 1 Winner","eventName":"Golubev/Nedovyesov v Sabanov/Sabanov"}}]}
{"op":"mcm","clk":"1003057552","pt":1580647914747,"mc":[{"id":"1.168213439","marketDefinition":{"bspMarket":false,"turnInPlayEnabled":true,"persistenceEnabled":true,"marketBaseRate":5.0,"eventId":"29681204","eventTypeId":"2","numberOfWinners":1,"bettingType":"ODDS","marketType":"SET_WINNER","marketTime":"2020-02-02T12:47:00.000Z","suspendTime":"2020-02-02T12:47:00.000Z","bspReconciled":false,"complete":true,"inPlay":false,"crossMatching":true,"runnersVoidable":false,"numberOfActiveRunners":2,"betDelay":0,"status":"OPEN","runners":[{"status":"ACTIVE","sortPriority":1,"id":8444034,"name":"Golubev/Nedovyesov"},{"status":"ACTIVE","sortPriority":2,"id":10107989,"name":"Sabanov/Sabanov"}],"regulators":["MR_INT"],"countryCode":"FR","discountAllowed":true,"timezone":"UTC","openDate":"2020-02-02T12:47:00.000Z","version":3148783607,"name":"Set 1 Winner","eventName":"Golubev/Nedovyesov v Sabanov/Sabanov"}}]}
{"op":"mcm","clk":"1003122031","pt":1580648299738,"mc":[{"id":"1.168213439","rc":[{"batb":[[0,2.34,18.02],[1,2.32,18.1],[2,2.12,1.19]],"ltp":0.0,"tv":0.0,"id":10107989}]}]}
{"op":"mcm","clk":"1003122077","pt":1580648300051,"mc":[{"id":"1.168213439","rc":[{"batb":[[1,2.12,1.19],[2,2.1,53.68]],"ltp":0.0,"tv":0.0,"id":10107989},{"batb":[[2,1.65,26.12]],"ltp":0.0,"tv":0.0,"id":8444034}]}]}
{"op":"mcm","clk":"1003168208","pt":1580648568602,"mc":[{"id":"1.168213439","rc":[{"batb":[[0,2.12,1.19],[1,2.1,53.68],[2,1.01,16.01]],"ltp":0.0,"tv":0.0,"id":10107989},{"batb":[[2,1.01,16.01]],"ltp":0.0,"tv":0.0,"id":8444034}]}]}
{"op":"mcm","clk":"1003168303","pt":1580648569134,"mc":[{"id":"1.168213439","marketDefinition":{"bspMarket":false,"turnInPlayEnabled":true,"persistenceEnabled":true,"marketBaseRate":5.0,"eventId":"29681204","eventTypeId":"2","numberOfWinners":1,"bettingType":"ODDS","marketType":"SET_WINNER","marketTime":"2020-02-02T12:47:00.000Z","suspendTime":"2020-02-02T12:47:00.000Z","bspReconciled":false,"complete":true,"inPlay":true,"crossMatching":true,"runnersVoidable":false,"numberOfActiveRunners":2,"betDelay":3,"status":"OPEN","runners":[{"status":"ACTIVE","sortPriority":1,"id":8444034,"name":"Golubev/Nedovyesov"},{"status":"ACTIVE","sortPriority":2,"id":10107989,"name":"Sabanov/Sabanov"}],"regulators":["MR_INT"],"countryCode":"FR","discountAllowed":true,"timezone":"UTC","openDate":"2020-02-02T12:47:00.000Z","version":3148851637,"name":"Set 1 Winner","eventName":"Golubev/Nedovyesov v Sabanov/Sabanov"},"rc":[{"batb":[[0,1.01,15.51],[1,2.1,0],[2,1.01,0]],"ltp":0.0,"tv":0.0,"id":10107989},{"batb":[[0,1.01,15.51],[1,1.67,0],[2,1.01,0]],"ltp":0.0,"tv":0.0,"id":8444034}]}]}
{"op":"mcm","clk":"1003171573","pt":1580648586356,"mc":[{"id":"1.168213439","rc":[{"batb":[[0,2.18,21.95],[1,2.04,26.12],[2,1.01,15.51]],"ltp":0.0,"tv":0.0,"id":10107989},{"batb":[[0,1.74,21.79],[1,1.61,28.64],[2,1.01,15.51]],"ltp":0.0,"tv":0.0,"id":8444034}]}]}
{"op":"mcm","clk":"1003172797","pt":1580648592505,"mc":[{"id":"1.168213439","rc":[{"batb":[[0,2.04,26.12],[1,1.01,15.51],[2,1.01,0]],"ltp":0.0,"tv":0.0,"id":10107989},{"batb":[[0,1.61,28.64],[1,1.01,15.51],[2,1.01,0]],"ltp":0.0,"tv":0.0,"id":8444034}]}]}
{"op":"mcm","clk":"1003176203","pt":1580648610517,"mc":[{"id":"1.168213439","rc":[{"batb":[[0,2.42,16.21],[1,2.2,20.93],[2,1.01,15.51]],"ltp":0.0,"tv":0.0,"id":10107989},{"batb":[[1,1.46,41.94],[2,1.01,15.51]],"ltp":0.0,"tv":0.0,"id":8444034}]}]}
{"op":"mcm","clk":"1003179288","pt":1580648626271,"mc":[{"id":"1.168213439","rc":[{"batb":[[0,2.2,20.93],[1,1.01,15.51],[2,1.01,0]],"ltp":0.0,"tv":0.0,"id":10107989},{"batb":[[0,1.46,41.94],[1,1.01,15.51],[2,1.01,0]],"ltp":0.0,"tv":0.0,"id":8444034}]}]}
{"op":"mcm","clk":"1003181777","pt":1580648638658,"mc":[{"id":"1.168213439","rc":[{"batb":[[1,2.04,26.04],[2,1.01,15.51]],"ltp":0.0,"tv":0.0,"id":10107989},{"batb":[[0,1.72,22.74],[1,1.57,31.32],[2,1.01,15.51]],"ltp":0.0,"tv":0.0,"id":8444034}]}]}
{"op":"mcm","clk":"1003184819","pt":1580648655212,"mc":[{"id":"1.168213439","rc":[{"batb":[[0,2.04,26.04],[1,1.01,15.51],[2,1.01,0]],"ltp":0.0,"tv":0.0,"id":10107989},{"batb":[[0,1.57,31.32],[1,1.01,15.51],[2,1.01,0]],"ltp":0.0,"tv":0.0,"id":8444034}]}]}
{"op":"mcm","clk":"1003187289","pt":1580648669648,"mc":[{"id":"1.168213439","rc":[{"batb":[[1,1.97,29.51],[2,1.01,15.51]],"ltp":0.0,"tv":0.0,"id":10107989},{"batb":[[0,1.83,18.57],[1,1.71,23.13],[2,1.01,15.51]],"ltp":0.0,"tv":0.0,"id":8444034}]}]}
{"op":"mcm","clk":"1003190308","pt":1580648686041,"mc":[{"id":"1.168213439","rc":[{"batb":[[0,1.97,29.51],[1,1.01,15.51],[2,1.01,0]],"ltp":0.0,"tv":0.0,"id":10107989},{"batb":[[0,1.71,23.13],[1,1.01,15.51],[2,1.01,0]],"ltp":0.0,"tv":0.0,"id":8444034}]}]}
{"op":"mcm","clk":"1003190926","pt":1580648689427,"mc":[{"id":"1.168213439","rc":[{"batb":[[0,1.95,30.29]],"ltp":0.0,"tv":0.0,"id":10107989},{"batb":[[0,1.73,22.5]],"ltp":0.0,"tv":0.0,"id":8444034}]}]}
{"op":"mcm","clk":"1003192018","pt":1580648695411,"mc":[{"id":"1.168213439","rc":[{"batb":[[1,1.76,21.32],[2,1.01,15.51]],"ltp":0.0,"tv":0.0,"id":10107989},{"batb":[[0,1.92,16.05],[1,1.82,19.12],[2,1.01,15.51]],"ltp":0.0,"tv":0.0,"id":8444034}]}]}
{"op":"mcm","clk":"1003193585","pt":1580648703681,"mc":[{"id":"1.168213439","rc":[{"batb":[[0,1.94,30.76],[1,1.75,21.64]],"ltp":0.0,"tv":0.0,"id":10107989},{"batb":[[0,1.93,15.82],[1,1.82,18.8]],"ltp":0.0,"tv":0.0,"id":8444034}]}]}
{"op":"mcm","clk":"1003195003","pt":1580648711364,"mc":[{"id":"1.168213439","rc":[{"batb":[[0,1.94,15.58],[1,1.74,21.87]],"ltp":0.0,"tv":0.0,"id":10107989},{"batb":[[0,1.94,15.58],[1,1.83,18.65]],"ltp":0.0,"tv":0.0,"id":8444034}]}]}
{"op":"mcm","clk":"1003195393","pt":1580648713585,"mc":[{"id":"1.168213439","rc":[{"trd":[[1.94,31.16]],"batb":[[0,1.83,18.65],[1,1.01,15.51],[2,1.01,0]],"batl":[[0,1.93,3.35]],"ltp":1.94,"tv":31.15,"id":8444034}],"tv":31.15}]}
{"op":"mcm","clk":"1003200910","pt":1580648744438,"mc":[{"id":"1.168213439","rc":[{"batb":[[0,1.74,21.87],[1,1.01,15.51],[2,1.01,0]],"ltp":0.0,"tv":0.0,"id":10107989}]}]}
{"op":"mcm","clk":"1003201488","pt":1580648747627,"mc":[{"id":"1.168213439","rc":[{"batb":[[0,1.78,21.56]],"ltp":0.0,"tv":0.0,"id":10107989},{"batb":[[0,1.82,18.88]],"ltp":1.94,"tv":31.15,"id":8444034}]}]}
{"op":"mcm","clk":"1003202418","pt":1580648752659,"mc":[{"id":"1.168213439","rc":[{"batb":[[0,2.08,25.57],[1,1.91,17.07],[2,1.78,21.56]],"ltp":0.0,"tv":0.0,"id":10107989},{"batb":[[1,1.74,22.11],[2,1.01,15.51]],"ltp":1.94,"tv":31.15,"id":8444034}]}]}
{"op":"mcm","clk":"1003202472","pt":1580648752923,"mc":[{"id":"1.168213439","rc":[{"batb":[[2,1.01,15.51]],"ltp":0.0,"tv":0.0,"id":10107989}]}]}
{"op":"mcm","clk":"1003205264","pt":1580648768679,"mc":[{"id":"1.168213439","rc":[{"batb":[[0,1.91,17.07],[1,1.01,15.51],[2,1.01,0]],"ltp":0.0,"tv":0.0,"id":10107989},{"batb":[[0,1.74,21.87],[1,1.01,15.51],[2,1.01,0]],"ltp":1.94,"tv":31.15,"id":8444034}]}]}
{"op":"mcm","clk":"1003206501","pt":1580648774784,"mc":[{"id":"1.168213439","rc":[{"batb":[[1,1.74,404.28],[2,1.01,15.51]],"ltp":0.0,"tv":0.0,"id":10107989},{"batb":[[1,1.52,425.49],[2,1.01,15.51]],"ltp":1.94,"tv":31.15,"id":8444034}]}]}
{"op":"mcm","clk":"1003208044","pt":1580648783432,"mc":[{"id":"1.168213439","rc":[{"batb":[[1,1.01,15.51],[2,1.01,0]],"ltp":0.0,"tv":0.0,"id":10107989}]}]}
{"op":"mcm","clk":"1003208487","pt":1580648785651,"mc":[{"id":"1.168213439","rc":[{"batb":[[0,2.2,21.87],[1,2.04,27.3],[2,1.01,15.51]],"ltp":0.0,"tv":0.0,"id":10107989},{"batb":[[1,1.69,24.39],[2,1.52,425.49]],"ltp":1.94,"tv":31.15,"id":8444034}]}]}
{"op":"mcm","clk":"1003208767","pt":1580648787071,"mc":[{"id":"1.168213439","rc":[{"batb":[[2,1.82,401.24]],"ltp":0.0,"tv":0.0,"id":10107989}]}]}
{"op":"mcm","clk":"1003211497","pt":1580648801183,"mc":[{"id":"1.168213439","rc":[{"batb":[[0,2.04,27.3],[1,1.82,401.24],[2,1.01,15.51]],"ltp":0.0,"tv":0.0,"id":10107989},{"batb":[[0,1.69,24.39],[1,1.52,425.49],[2,1.01,15.51]],"ltp":1.94,"tv":31.15,"id":8444034}]}]}
{"op":"mcm","clk":"1003213122","pt":1580648809629,"mc":[{"id":"1.168213439","rc":[{"batb":[[0,2.3,19.43],[1,2.18,22.9],[2,2.04,27.3]],"ltp":0.0,"tv":0.0,"id":10107989},{"batb":[[1,1.65,26.36],[2,1.52,425.49]],"ltp":1.94,"tv":31.15,"id":8444034}]}]}
{"op":"mcm","clk":"1003213167","pt":1580648809945,"mc":[{"id":"1.168213439","rc":[{"batb":[[2,1.82,401.24]],"ltp":0.0,"tv":0.0,"id":10107989}]}]}
{"op":"mcm","clk":"1003214941","pt":1580648819355,"mc":[{"id":"1.168213439","rc":[{"batb":[[0,2.18,22.9],[1,1.82,401.24],[2,1.01,15.51]],"ltp":0.0,"tv":0.0,"id":10107989},{"batb":[[0,1.65,26.36],[1,1.52,425.49],[2,1.01,15.51]],"ltp":1.94,"tv":31.15,"id":8444034}]}]}
{"op":"mcm","clk":"1003215933","pt":1580648824439,"mc":[{"id":"1.168213439","rc":[{"batb":[[1,1.01,15.51],[2,1.01,0]],"ltp":1.94,"tv":31.15,"id":8444034}]}]}
{"op":"mcm","clk":"1003216510","pt":1580648827441,"mc":[{"id":"1.168213439","rc":[{"batb":[[0,2.38,17.7],[1,2.2,22.03],[2,1.82,401.24]],"ltp":0.0,"tv":0.0,"id":10107989},{"batb":[[1,1.5,37.14],[2,1.01,15.51]],"ltp":1.94,"tv":31.15,"id":8444034}]}]}
{"op":"mcm","clk":"1003216692","pt":1580648828462,"mc":[{"id":"1.168213439","rc":[{"batb":[[2,1.44,436.18]],"ltp":1.94,"tv":31.15,"id":8444034}]}]}
{"op":"mcm","clk":"1003221404","pt":1580648854690,"mc":[{"id":"1.168213439","rc":[{"batb":[[0,2.2,22.03],[1,1.82,401.24],[2,1.01,15.51]],"ltp":0.0,"tv":0.0,"id":10107989},{"batb":[[0,1.5,37.14],[1,1.44,436.18],[2,1.01,15.51]],"ltp":1.94,"tv":31.15,"id":8444034}]}]}
{"op":"mcm","clk":"1003222554","pt":1580648860813,"mc":[{"id":"1.168213439","rc":[{"batb":[[1,1.01,15.51],[2,1.01,0]],"ltp":0.0,"tv":0.0,"id":10107989}]}]}
{"op":"mcm","clk":"1003223296","pt":1580648864903,"mc":[{"id":"1.168213439","rc":[{"batb":[[1,1.92,394.91],[2,1.01,15.51]],"ltp":0.0,"tv":0.0,"id":10107989}]}]}
{"op":"mcm","clk":"1003225076","pt":1580648874828,"mc":[{"id":"1.168213439","rc":[{"batb":[[1,1.01,15.51],[2,1.01,0]],"ltp":0.0,"tv":0.0,"id":10107989},{"batb":[[1,1.01,15.51],[2,1.01,0]],"ltp":1.94,"tv":31.15,"id":8444034}]}]}
{"op":"mcm","clk":"1003225439","pt":1580648876716,"mc":[{"id":"1.168213439","rc":[{"batb":[[0,2.78,11.88],[1,2.48,16.13],[2,1.01,15.51]],"ltp":0.0,"tv":0.0,"id":10107989},{"batb":[[1,1.36,57.6],[2,1.01,15.51]],"ltp":1.94,"tv":31.15,"id":8444034}]}]}
{"op":"mcm","clk":"1003225908","pt":1580648879201,"mc":[{"id":"1.168213439","rc":[{"batb":[[2,2.04,394.09]],"ltp":0.0,"tv":0.0,"id":10107989},{"batb":[[2,1.34,465.43]],"ltp":1.94,"tv":31.15,"id":8444034}]}]}
{"op":"mcm","clk":"1003228116","pt":1580648890648,"mc":[{"id":"1.168213439","rc":[{"batb":[[0,2.48,16.13],[1,2.04,394.09],[2,1.01,15.51]],"ltp":0.0,"tv":0.0,"id":10107989},{"batb":[[0,1.36,57.6],[1,1.34,465.43],[2,1.01,15.51]],"ltp":1.94,"tv":31.15,"id":8444034}]}]}
{"op":"mcm","clk":"1003231266","pt":1580648907264,"mc":[{"id":"1.168213439","rc":[{"batb":[[1,1.01,15.51],[2,1.01,0]],"ltp":0.0,"tv":0.0,"id":10107989},{"batb":[[1,1.01,15.51],[2,1.01,0]],"ltp":1.94,"tv":31.15,"id":8444034}]}]}
{"op":"mcm","clk":"1003231689","pt":1580648909549,"mc":[{"id":"1.168213439","rc":[{"batb":[[0,3.4,17.23],[1,2.96,24.71],[2,2.48,16.13]],"ltp":0.0,"tv":0.0,"id":10107989},{"batb":[[1,1.24,93.47],[2,1.01,15.51]],"ltp":1.94,"tv":31.15,"id":8444034}]}]}
{"op":"mcm","clk":"1003231737","pt":1580648909868,"mc":[{"id":"1.168213439","rc":[{"batb":[[2,1.01,15.51]],"ltp":0.0,"tv":0.0,"id":10107989}]}]}
{"op":"mcm","clk":"1003232003","pt":1580648911394,"mc":[{"id":"1.168213439","rc":[{"batb":[[2,2.3,385.09]],"ltp":0.0,"tv":0.0,"id":10107989},{"batb":[[1,1.25,505.09],[2,1.24,93.47]],"ltp":1.94,"tv":31.15,"id":8444034}]}]}
{"op":"mcm","clk":"1003234253","pt":1580648923909,"mc":[{"id":"1.168213439","rc":[{"batb":[[0,2.96,24.71],[1,2.3,385.09],[2,1.01,15.51]],"ltp":0.0,"tv":0.0,"id":10107989},{"batb":[[0,1.25,505.09],[1,1.24,93.47],[2,1.01,15.51]],"ltp":1.94,"tv":31.15,"id":8444034}]}]}
{"op":"mcm","clk":"1003237766","pt":1580648942670,"mc":[{"id":"1.168213439","rc":[{"batb":[[0,1.24,93.47],[1,1.01,15.51],[2,1.01,0]],"ltp":1.94,"tv":31.15,"id":8444034}]}]}
{"op":"mcm","clk":"1003238594","pt":1580648947152,"mc":[{"id":"1.168213439","rc":[{"batb":[[1,1.22,523],[2,1.01,15.51]],"ltp":1.94,"tv":31.15,"id":8444034}]}]}
{"op":"mcm","clk":"1003240494","pt":1580648957739,"mc":[{"id":"1.168213439","rc":[{"batb":[[1,1.01,15.51],[2,1.01,0]],"ltp":1.94,"tv":31.15,"id":8444034}]}]}
{"op":"mcm","clk":"1003240916","pt":1580648960044,"mc":[{"id":"1.168213439","rc":[{"batb":[[1,2.6,14.08],[2,2.3,385.09]],"ltp":0.0,"tv":0.0,"id":10107989},{"batb":[[0,1.45,43.75],[1,1.28,76.01],[2,1.01,15.51]],"ltp":1.94,"tv":31.15,"id":8444034}]}]}
{"op":"mcm","clk":"1003241354","pt":1580648962454,"mc":[{"id":"1.168213439","rc":[{"batb":[[1,1.31,477.51],[2,1.28,76.01]],"ltp":1.94,"tv":31.15,"id":8444034}]}]}
{"op":"mcm","clk":"1003243457","pt":1580648973969,"mc":[{"id":"1.168213439","rc":[{"batb":[[0,2.6,14.08],[1,2.3,385.09],[2,1.01,15.51]],"ltp":0.0,"tv":0.0,"id":10107989},{"batb":[[0,1.31,477.51],[1,1.28,76.01],[2,1.01,15.51]],"ltp":1.94,"tv":31.15,"id":8444034}]}]}
{"op":"mcm","clk":"1003245021","pt":1580648982690,"mc":[{"id":"1.168213439","rc":[{"batb":[[1,1.01,15.51],[2,1.01,0]],"ltp":0.0,"tv":0.0,"id":10107989},{"batb":[[0,1.28,76.01],[1,1.01,15.51],[2,1.01,0]],"ltp":1.94,"tv":31.15,"id":8444034}]}]}
{"op":"mcm","clk":"1003245168","pt":1580648983495,"mc":[{"id":"1.168213439","rc":[{"batb":[[0,3.95,23.84],[1,3.35,17.86],[2,2.6,14.08]],"ltp":0.0,"tv":0.0,"id":10107989},{"batb":[[1,1.17,132.82],[2,1.01,15.51]],"ltp":1.94,"tv":31.15,"id":8444034}]}]}
{"op":"mcm","clk":"1003245228","pt":1580648983757,"mc":[{"id":"1.168213439","rc":[{"batb":[[2,1.01,15.51]],"ltp":0.0,"tv":0.0,"id":10107989}]}]}
{"op":"mcm","clk":"1003245741","pt":1580648986573,"mc":[{"id":"1.168213439","rc":[{"batb":[[2,2.52,381.46]],"ltp":0.0,"tv":0.0,"id":10107989},{"batb":[[1,1.2,530.86],[2,1.17,132.82]],"ltp":1.94,"tv":31.15,"id":8444034}]}]}
{"op":"mcm","clk":"1003248005","pt":1580648999756,"mc":[{"id":"1.168213439","rc":[{"batb":[[0,3.35,17.86],[1,2.52,381.46],[2,1.01,15.51]],"ltp":0.0,"tv":0.0,"id":10107989},{"batb":[[0,1.2,530.86],[1,1.17,132.82],[2,1.01,15.51]],"ltp":1.94,"tv":31.15,"id":8444034}]}]}
{"op":"mcm","clk":"1003249175","pt":1580649005889,"mc":[{"id":"1.168213439","rc":[{"batb":[[0,1.17,132.82],[1,1.01,15.51],[2,1.01,0]],"ltp":1.94,"tv":31.15,"id":8444034}]}]}
{"op":"mcm","clk":"1003249678","pt":1580649008385,"mc":[{"id":"1.168213439","rc":[{"batb":[[1,2.76,12.2],[2,2.52,381.46]],"ltp":0.0,"tv":0.0,"id":10107989},{"batb":[[0,1.37,56.1],[1,1.18,127.62],[2,1.01,15.51]],"ltp":1.94,"tv":31.15,"id":8444034}]}]}
{"op":"mcm","clk":"1003249854","pt":1580649009351,"mc":[{"id":"1.168213439","rc":[{"batb":[[1,1.25,505.09],[2,1.18,127.62]],"ltp":1.94,"tv":31.15,"id":8444034}]}]}
{"op":"mcm","clk":"1003251754","pt":1580649018906,"mc":[{"id":"1.168213439","rc":[{"batb":[[0,2.76,12.2],[1,2.52,381.46],[2,1.01,15.51]],"ltp":0.0,"tv":0.0,"id":10107989},{"batb":[[0,1.25,505.09],[1,1.18,127.62],[2,1.01,15.51]],"ltp":1.94,"tv":31.15,"id":8444034}]}]}
{"op":"mcm","clk":"1003251983","pt":1580649019914,"mc":[{"id":"1.168213439","rc":[{"batb":[[1,1.01,15.51],[2,1.01,0]],"ltp":0.0,"tv":0.0,"id":10107989},{"batb":[[0,1.18,127.62],[1,1.01,15.51],[2,1.01,0]],"ltp":1.94,"tv":31.15,"id":8444034}]}]}
{"op":"mcm","clk":"1003253430","pt":1580649027464,"mc":[{"id":"1.168213439","rc":[{"batb":[[1,2.1,25.26],[2,2.04,394.09]],"ltp":0.0,"tv":0.0,"id":10107989},{"batb":[[0,1.51,36.43],[1,1.34,465.43],[2,1.19,122.59]],"ltp":1.94,"tv":31.15,"id":8444034}]}]}
{"op":"mcm","clk":"1003255792","pt":1580649039786,"mc":[{"id":"1.168213439","rc":[{"batb":[[0,2.1,25.26],[1,2.04,394.09],[2,1.01,15.51]],"ltp":0.0,"tv":0.0,"id":10107989},{"batb":[[0,1.34,465.43],[1,1.19,122.59],[2,1.01,15.51]],"ltp":1.94,"tv":31.15,"id":8444034}]}]}
{"op":"mcm","clk":"1003256048","pt":1580649041088,"mc":[{"id":"1.168213439","rc":[{"batb":[[1,1.01,15.51],[2,1.01,0]],"ltp":0.0,"tv":0.0,"id":10107989},{"batb":[[0,1.19,122.59],[1,1.01,15.51],[2,1.01,0]],"ltp":1.94,"tv":31.15,"id":8444034}]}]}
{"op":"mcm","clk":"1003257543","pt":1580649048555,"mc":[{"id":"1.168213439","rc":[{"batb":[[0,5.4,11.72],[1,4.1,21.4],[2,1.01,15.51]],"ltp":0.0,"tv":0.0,"id":10107989},{"batb":[[1,1.15,153.59],[2,1.01,15.51]],"ltp":1.94,"tv":31.15,"id":8444034}]}]}
{"op":"mcm","clk":"1003257929","pt":1580649050562,"mc":[{"id":"1.168213439","rc":[{"batb":[[2,2.98,374.28]],"ltp":0.0,"tv":0.0,"id":10107989},{"batb":[[2,1.12,650.34]],"ltp":1.94,"tv":31.15,"id":8444034}]}]}
{"op":"mcm","clk":"1003273727","pt":1580649130936,"mc":[{"id":"1.168213439","rc":[{"batb":[[0,4.1,21.4],[1,2.98,374.28],[2,1.01,15.51]],"ltp":0.0,"tv":0.0,"id":10107989},{"batb":[[0,1.15,153.59],[1,1.12,650.34],[2,1.01,15.51]],"ltp":1.94,"tv":31.15,"id":8444034}]}]}
{"op":"mcm","clk":"1003274988","pt":1580649136530,"mc":[{"id":"1.168213439","rc":[{"batb":[[1,1.01,15.51],[2,1.01,0]],"ltp":1.94,"tv":31.15,"id":8444034}]}]}
{"op":"mcm","clk":"1003275714","pt":1580649140573,"mc":[{"id":"1.168213439","rc":[{"batb":[[1,1.14,610.45],[2,1.01,15.51]],"ltp":1.94,"tv":31.15,"id":8444034}]}]}
{"op":"mcm","clk":"1003277457","pt":1580649149562,"mc":[{"id":"1.168213439","rc":[{"batb":[[1,1.01,15.51],[2,1.01,0]],"ltp":1.94,"tv":31.15,"id":8444034}]}]}
{"op":"mcm","clk":"1003277975","pt":1580649152320,"mc":[{"id":"1.168213439","rc":[{"batb":[[1,3.15,20.61],[2,2.98,374.28]],"ltp":0.0,"tv":0.0,"id":10107989},{"batb":[[0,1.27,81.91],[1,1.21,108.11],[2,1.01,15.51]],"ltp":1.94,"tv":31.15,"id":8444034}]}]}
{"op":"mcm","clk":"1003278236","pt":1580649153722,"mc":[{"id":"1.168213439","rc":[{"batb":[[2,1.16,576.13]],"ltp":1.94,"tv":31.15,"id":8444034}]}]}
{"op":"mcm","clk":"1003281455","pt":1580649170899,"mc":[{"id":"1.168213439","rc":[{"batb":[[0,3.15,20.61],[1,2.98,374.28],[2,1.01,15.51]],"ltp":0.0,"tv":0.0,"id":10107989},{"batb":[[0,1.21,108.11],[1,1.16,576.13],[2,1.01,15.51]],"ltp":1.94,"tv":31.15,"id":8444034}]}]}
{"op":"mcm","clk":"1003282496","pt":1580649176595,"mc":[{"id":"1.168213439","rc":[{"batb":[[1,1.01,15.51],[2,1.01,0]],"ltp":1.94,"tv":31.15,"id":8444034}]}]}
{"op":"mcm","clk":"1003283045","pt":1580649179717,"mc":[{"id":"1.168213439","rc":[{"batb":[[0,4.9,14.24],[1,3.7,14.24],[2,2.98,374.28]],"ltp":0.0,"tv":0.0,"id":10107989},{"batb":[[1,1.16,141.94],[2,1.01,15.51]],"ltp":1.94,"tv":31.15,"id":8444034}]}]}
{"op":"mcm","clk":"1003283210","pt":1580649180525,"mc":[{"id":"1.168213439","rc":[{"batb":[[2,1.14,610.45]],"ltp":1.94,"tv":31.15,"id":8444034}]}]}
{"op":"mcm","clk":"1003285817","pt":1580649194631,"mc":[{"id":"1.168213439","rc":[{"batb":[[0,3.7,14.24],[1,2.98,374.28],[2,1.01,15.51]],"ltp":0.0,"tv":0.0,"id":10107989},{"batb":[[0,1.16,141.94],[1,1.14,610.45],[2,1.01,15.51]],"ltp":1.94,"tv":31.15,"id":8444034}]}]}
{"op":"mcm","clk":"1003287621","pt":1580649204881,"mc":[{"id":"1.168213439","rc":[{"batb":[[1,1.01,15.51],[2,1.01,0]],"ltp":0.0,"tv":0.0,"id":10107989},{"batb":[[1,1.01,15.51],[2,1.01,0]],"ltp":1.94,"tv":31.15,"id":8444034}]}]}
{"op":"mcm","clk":"1003288065","pt":1580649207670,"mc":[{"id":"1.168213439","rc":[{"batb":[[1,2.8,11.8],[2,1.01,15.51]],"ltp":0.0,"tv":0.0,"id":10107989},{"batb":[[0,1.32,66.33],[1,1.24,93.4],[2,1.16,141.94]],"ltp":1.94,"tv":31.15,"id":8444034}]}]}
{"op":"mcm","clk":"1003288099","pt":1580649207869,"mc":[{"id":"1.168213439","rc":[{"batb":[[2,1.01,15.51]],"ltp":1.94,"tv":31.15,"id":8444034}]}]}
{"op":"mcm","clk":"1003288337","pt":1580649209249,"mc":[{"id":"1.168213439","rc":[{"batb":[[2,2.52,381.46]],"ltp":0.0,"tv":0.0,"id":10107989},{"batb":[[2,1.2,530.86]],"ltp":1.94,"tv":31.15,"id":8444034}]}]}
{"op":"mcm","clk":"1003291268","pt":1580649225213,"mc":[{"id":"1.168213439","rc":[{"batb":[[0,2.8,11.8],[1,2.52,381.46],[2,1.01,15.51]],"ltp":0.0,"tv":0.0,"id":10107989},{"batb":[[0,1.24,93.4],[1,1.2,530.86],[2,1.01,15.51]],"ltp":1.94,"tv":31.15,"id":8444034}]}]}
{"op":"mcm","clk":"1003293292","pt":1580649236021,"mc":[{"id":"1.168213439","rc":[{"batb":[[1,1.01,15.51],[2,1.01,0]],"ltp":0.0,"tv":0.0,"id":10107989},{"batb":[[1,1.01,15.51],[2,1.01,0]],"ltp":1.94,"tv":31.15,"id":8444034}]}]}
{"op":"mcm","clk":"1003293656","pt":1580649238198,"mc":[{"id":"1.168213439","rc":[{"batb":[[0,4.5,17.7],[1,3.15,20.93],[2,1.01,15.51]],"ltp":0.0,"tv":0.0,"id":10107989},{"batb":[[1,1.17,136.36],[2,1.01,15.51]],"ltp":1.94,"tv":31.15,"id":8444034}]}]}
{"op":"mcm","clk":"1003293876","pt":1580649239550,"mc":[{"id":"1.168213439","rc":[{"batb":[[2,2.84,375.42]],"ltp":0.0,"tv":0.0,"id":10107989},{"batb":[[2,1.14,610.45]],"ltp":1.94,"tv":31.15,"id":8444034}]}]}
{"op":"mcm","clk":"1003294327","pt":1580649242047,"mc":[{"id":"1.168213439","rc":[{"batb":[[0,3.15,20.93],[1,2.84,375.42],[2,1.01,15.51]],"ltp":0.0,"tv":0.0,"id":10107989},{"batb":[[0,1.17,136.36],[1,1.14,610.45],[2,1.01,15.51]],"ltp":1.94,"tv":31.15,"id":8444034}]}]}
{"op":"mcm","clk":"1003299267","pt":1580649269059,"mc":[{"id":"1.168213439","rc":[{"batb":[[1,1.01,15.51],[2,1.01,0]],"ltp":0.0,"tv":0.0,"id":10107989},{"batb":[[1,1.01,15.51],[2,1.01,0]],"ltp":1.94,"tv":31.15,"id":8444034}]}]}
{"op":"mcm","clk":"1003299780","pt":1580649271696,"mc":[{"id":"1.168213439","rc":[{"batb":[[0,5.7,20.3],[1,4,23.29],[2,1.01,15.51]],"ltp":0.0,"tv":0.0,"id":10107989},{"batb":[[1,1.12,191.51],[2,1.01,15.51]],"ltp":1.94,"tv":31.15,"id":8444034}]}]}
{"op":"mcm","clk":"1003299990","pt":1580649272790,"mc":[{"id":"1.168213439","rc":[{"batb":[[2,3.1,373.78]],"ltp":0.0,"tv":0.0,"id":10107989},{"batb":[[2,1.1,723.21]],"ltp":1.94,"tv":31.15,"id":8444034}]}]}
{"op":"mcm","clk":"1003303776","pt":1580649293064,"mc":[{"id":"1.168213439","rc":[{"batb":[[0,4,23.29],[1,3.1,373.78],[2,1.01,15.51]],"ltp":0.0,"tv":0.0,"id":10107989},{"batb":[[0,1.12,191.51],[1,1.1,723.21],[2,1.01,15.51]],"ltp":1.94,"tv":31.15,"id":8444034}]}]}
{"op":"mcm","clk":"1003306047","pt":1580649304403,"mc":[{"id":"1.168213439","rc":[{"batb":[[1,1.01,15.51],[2,1.01,0]],"ltp":1.94,"tv":31.15,"id":8444034}]}]}
{"op":"mcm","clk":"1003306689","pt":1580649308049,"mc":[{"id":"1.168213439","rc":[{"batb":[[0,1.14,610.45],[1,1.12,191.51],[2,1.01,15.51]],"ltp":1.94,"tv":31.15,"id":8444034}]}]}
{"op":"mcm","clk":"1003307945","pt":1580649315360,"mc":[{"id":"1.168213439","rc":[{"batb":[[0,1.12,191.51],[1,1.01,15.51],[2,1.01,0]],"ltp":1.94,"tv":31.15,"id":8444034}]}]}
{"op":"mcm","clk":"1003308364","pt":1580649317546,"mc":[{"id":"1.168213439","rc":[{"batb":[[0,7.2,11.8],[1,6.4,15.26],[2,3.1,373.78]],"ltp":0.0,"tv":0.0,"id":10107989},{"batb":[[1,1.09,255.24],[2,1.01,15.51]],"ltp":1.94,"tv":31.15,"id":8444034}]}]}
{"op":"mcm","clk":"1003308691","pt":1580649319474,"mc":[{"id":"1.168213439","rc":[{"batb":[[2,1.08,800.96]],"ltp":1.94,"tv":31.15,"id":8444034}]}]}
{"op":"mcm","clk":"1003312788","pt":1580649344706,"mc":[{"id":"1.168213439","rc":[{"trd":[[7.2,0.62]],"batb":[[0,7.2,11.19]],"ltp":7.2,"tv":0.61,"id":10107989},{"trd":[[1.17,3.79]],"ltp":1.17,"tv":34.94,"id":8444034}],"tv":35.55}]}
{"op":"mcm","clk":"1003313716","pt":1580649350292,"mc":[{"id":"1.168213439","rc":[{"batb":[[0,6.4,15.26],[1,3.1,373.78],[2,1.01,15.51]],"ltp":7.2,"tv":0.61,"id":10107989},{"batb":[[0,1.09,254.85],[1,1.08,800.96],[2,1.01,15.51]],"ltp":1.17,"tv":34.94,"id":8444034}]}]}
{"op":"mcm","clk":"1003315623","pt":1580649361409,"mc":[{"id":"1.168213439","rc":[{"batb":[[1,5.9,18.49],[2,3.1,373.78]],"ltp":7.2,"tv":0.61,"id":10107989},{"batb":[[0,1.14,162.87],[1,1.11,204.65],[2,1.08,800.96]],"ltp":1.17,"tv":34.94,"id":8444034}]}]}
{"op":"mcm","clk":"1003318642","pt":1580649377847,"mc":[{"id":"1.168213439","rc":[{"batb":[[0,5.9,18.49],[1,3.1,373.78],[2,1.01,15.51]],"ltp":7.2,"tv":0.61,"id":10107989},{"batb":[[0,1.11,204.65],[1,1.08,800.96],[2,1.01,15.51]],"ltp":1.17,"tv":34.94,"id":8444034}]}]}
{"op":"mcm","clk":"1003320297","pt":1580649386669,"mc":[{"id":"1.168213439","rc":[{"batb":[[1,1.01,15.51],[2,1.01,0]],"ltp":1.17,"tv":34.94,"id":8444034}]}]}
{"op":"mcm","clk":"1003320758","pt":1580649389326,"mc":[{"id":"1.168213439","rc":[{"batb":[[1,5.6,10.54],[2,3.1,373.78]],"ltp":7.2,"tv":0.61,"id":10107989},{"batb":[[0,1.16,144.85],[1,1.14,170.11],[2,1.01,15.51]],"ltp":1.17,"tv":34.94,"id":8444034}]}]}
{"op":"mcm","clk":"1003321031","pt":1580649390759,"mc":[{"id":"1.168213439","rc":[{"batb":[[2,1.09,753.06]],"ltp":1.17,"tv":34.94,"id":8444034}]}]}
{"op":"mcm","clk":"1003323656","pt":1580649404506,"mc":[{"id":"1.168213439","rc":[{"batb":[[0,5.6,10.54],[1,3.1,373.78],[2,1.01,15.51]],"ltp":7.2,"tv":0.61,"id":10107989},{"batb":[[0,1.14,170.11],[1,1.09,753.06],[2,1.01,15.51]],"ltp":1.17,"tv":34.94,"id":8444034}]}]}
{"op":"mcm","clk":"1003327321","pt":1580649424636,"mc":[{"id":"1.168213439","rc":[{"batb":[[0,6.6,14.32],[1,5.9,18.57],[2,3.1,373.78]],"ltp":7.2,"tv":0.61,"id":10107989},{"batb":[[1,1.11,222.51],[2,1.09,753.06]],"ltp":1.17,"tv":34.94,"id":8444034}]}]}
{"op":"mcm","clk":"1003331256","pt":1580649446309,"mc":[{"id":"1.168213439","rc":[{"batb":[[0,5.9,18.57],[1,3.1,373.78],[2,1.01,15.51]],"ltp":7.2,"tv":0.61,"id":10107989},{"batb":[[0,1.11,222.51],[1,1.09,753.06],[2,1.01,15.51]],"ltp":1.17,"tv":34.94,"id":8444034}]}]}
{"op":"mcm","clk":"1003333203","pt":1580649458309,"mc":[{"id":"1.168213439","rc":[{"batb":[[1,1.01,15.51],[2,1.01,0]],"ltp":7.2,"tv":0.61,"id":10107989},{"batb":[[1,1.01,15.51],[2,1.01,0]],"ltp":1.17,"tv":34.94,"id":8444034}]}]}
{"op":"mcm","clk":"1003333457","pt":1580649459697,"mc":[{"id":"1.168213439","rc":[{"batb":[[0,8,9.21],[1,6.6,14.16],[2,5.9,18.57]],"ltp":7.2,"tv":0.61,"id":10107989},{"batb":[[1,1.06,377.52],[2,1.01,15.51]],"ltp":1.17,"tv":34.94,"id":8444034}]}]}
{"op":"mcm","clk":"1003333486","pt":1580649459909,"mc":[{"id":"1.168213439","rc":[{"batb":[[2,1.01,15.51]],"ltp":7.2,"tv":0.61,"id":10107989}]}]}
{"op":"mcm","clk":"1003333944","pt":1580649462632,"mc":[{"id":"1.168213439","rc":[{"batb":[[2,3.4,376.1]],"ltp":7.2,"tv":0.61,"id":10107989},{"batb":[[1,1.06,1371.42]],"ltp":1.17,"tv":34.94,"id":8444034}]}]}
{"op":"mcm","clk":"1003337769","pt":1580649483870,"mc":[{"id":"1.168213439","rc":[{"batb":[[0,6.6,14.16],[1,3.4,376.1],[2,1.01,15.51]],"ltp":7.2,"tv":0.61,"id":10107989},{"batb":[[0,1.06,1371.42],[1,1.01,15.51],[2,1.01,0]],"ltp":1.17,"tv":34.94,"id":8444034}]}]}
{"op":"mcm","clk":"1003339191","pt":1580649491719,"mc":[{"id":"1.168213439","rc":[{"batb":[[0,1.06,377.52]],"ltp":1.17,"tv":34.94,"id":8444034}]}]}
{"op":"mcm","clk":"1003339600","pt":1580649493677,"mc":[{"id":"1.168213439","rc":[{"batb":[[1,5.8,19.51],[2,3.4,376.1]],"ltp":7.2,"tv":0.61,"id":10107989},{"batb":[[0,1.14,171.05],[1,1.09,247.53],[2,1.06,377.52]],"ltp":1.17,"tv":34.94,"id":8444034}]}]}
{"op":"mcm","clk":"1003339674","pt":1580649494076,"mc":[{"id":"1.168213439","rc":[{"batb":[[2,1.01,15.51]],"ltp":1.17,"tv":34.94,"id":8444034}]}]}
{"op":"mcm","clk":"1003340016","pt":1580649496043,"mc":[{"id":"1.168213439","rc":[{"batb":[[2,1.08,800.96]],"ltp":1.17,"tv":34.94,"id":8444034}]}]}
{"op":"mcm","clk":"1003342391","pt":1580649509975,"mc":[{"id":"1.168213439","rc":[{"batb":[[0,5.8,19.51],[1,3.4,376.1],[2,1.01,15.51]],"ltp":7.2,"tv":0.61,"id":10107989},{"batb":[[0,1.09,247.53],[1,1.08,800.96],[2,1.01,15.51]],"ltp":1.17,"tv":34.94,"id":8444034}]}]}
{"op":"mcm","clk":"1003343952","pt":1580649518516,"mc":[{"id":"1.168213439","rc":[{"batb":[[1,1.01,15.51],[2,1.01,0]],"ltp":1.17,"tv":34.94,"id":8444034}]}]}
{"op":"mcm","clk":"1003344252","pt":1580649520128,"mc":[{"id":"1.168213439","rc":[{"batb":[[1,4.3,19.28],[2,3.4,376.1]],"ltp":7.2,"tv":0.61,"id":10107989},{"batb":[[0,1.17,139.9],[1,1.13,185.37],[2,1.01,15.51]],"ltp":1.17,"tv":34.94,"id":8444034}]}]}
{"op":"mcm","clk":"1003344543","pt":1580649521894,"mc":[{"id":"1.168213439","rc":[{"batb":[[2,1.09,753.06]],"ltp":1.17,"tv":34.94,"id":8444034}]}]}
{"op":"mcm","clk":"1003359171","pt":1580649614406,"mc":[{"id":"1.168213439","rc":[{"batb":[[0,4.3,19.28],[1,3.4,376.1],[2,1.01,15.51]],"ltp":7.2,"tv":0.61,"id":10107989},{"batb":[[0,1.13,185.37],[1,1.09,753.06],[2,1.01,15.51]],"ltp":1.17,"tv":34.94,"id":8444034}]}]}
{"op":"mcm","clk":"1003360092","pt":1580649620098,"mc":[{"id":"1.168213439","rc":[{"batb":[[1,1.01,15.51],[2,1.01,0]],"ltp":1.17,"tv":34.94,"id":8444034}]}]}
{"op":"mcm","clk":"1003360708","pt":1580649623810,"mc":[{"id":"1.168213439","rc":[{"batb":[[1,1.1,723.21],[2,1.01,15.51]],"ltp":1.17,"tv":34.94,"id":8444034}]}]}
{"op":"mcm","clk":"1003361860","pt":1580649631111,"mc":[{"id":"1.168213439","rc":[{"batb":[[1,1.01,15.51],[2,1.01,0]],"ltp":1.17,"tv":34.94,"id":8444034}]}]}
{"op":"mcm","clk":"1003362270","pt":1580649633724,"mc":[{"id":"1.168213439","rc":[{"batb":[[0,7,12.43],[1,5.3,12.12],[2,3.4,376.1]],"ltp":7.2,"tv":0.61,"id":10107989},{"batb":[[1,1.1,232.74],[2,1.01,15.51]],"ltp":1.17,"tv":34.94,"id":8444034}]}]}
{"op":"mcm","clk":"1003362455","pt":1580649634913,"mc":[{"id":"1.168213439","rc":[{"batb":[[2,1.06,993.9]],"ltp":1.17,"tv":34.94,"id":8444034}]}]}
{"op":"mcm","clk":"1003364692","pt":1580649649045,"mc":[{"id":"1.168213439","rc":[{"batb":[[0,5.3,12.12],[1,3.4,376.1],[2,1.01,15.51]],"ltp":7.2,"tv":0.61,"id":10107989},{"batb":[[0,1.1,232.74],[1,1.06,993.9],[2,1.01,15.51]],"ltp":1.17,"tv":34.94,"id":8444034}]}]}
{"op":"mcm","clk":"1003365362","pt":1580649653239,"mc":[{"id":"1.168213439","rc":[{"batb":[[1,1.01,15.51],[2,1.01,0]],"ltp":1.17,"tv":34.94,"id":8444034}]}]}
{"op":"mcm","clk":"1003365800","pt":1580649656051,"mc":[{"id":"1.168213439","rc":[{"batb":[[0,8.4,8.58],[1,6.6,14.56],[2,3.4,376.1]],"ltp":7.2,"tv":0.61,"id":10107989},{"batb":[[1,1.08,278.22],[2,1.01,15.51]],"ltp":1.17,"tv":34.94,"id":8444034}]}]}
{"op":"mcm","clk":"1003365952","pt":1580649657143,"mc":[{"id":"1.168213439","rc":[{"batb":[[2,1.06,936.8]],"ltp":1.17,"tv":34.94,"id":8444034}]}]}
{"op":"mcm","clk":"1003367767","pt":1580649669032,"mc":[{"id":"1.168213439","rc":[{"batb":[[0,6.6,14.56],[1,3.4,376.1],[2,1.01,15.51]],"ltp":7.2,"tv":0.61,"id":10107989},{"batb":[[0,1.08,278.22],[1,1.06,936.8],[2,1.01,15.51]],"ltp":1.17,"tv":34.94,"id":8444034}]}]}
{"op":"mcm","clk":"1003368393","pt":1580649673240,"mc":[{"id":"1.168213439","rc":[{"batb":[[1,1.01,15.51],[2,1.01,0]],"ltp":1.17,"tv":34.94,"id":8444034}]}]}
{"op":"mcm","clk":"1003368938","pt":1580649677277,"mc":[{"id":"1.168213439","rc":[{"batb":[[1,1.06,993.9],[2,1.01,15.51]],"ltp":1.17,"tv":34.94,"id":8444034}]}]}
{"op":"mcm","clk":"1003370552","pt":1580649687406,"mc":[{"id":"1.168213439","rc":[{"batb":[[1,1.01,15.51],[2,1.01,0]],"ltp":1.17,"tv":34.94,"id":8444034}]}]}
{"op":"mcm","clk":"1003370997","pt":1580649690090,"mc":[{"id":"1.168213439","rc":[{"batb":[[0,9.4,16.13],[1,8.2,8.97],[2,3.4,376.1]],"ltp":7.2,"tv":0.61,"id":10107989},{"batb":[[1,1.07,316.38],[2,1.01,15.51]],"ltp":1.17,"tv":34.94,"id":8444034}]}]}
{"op":"mcm","clk":"1003371204","pt":1580649691389,"mc":[{"id":"1.168213439","rc":[{"batb":[[2,1.05,1069.58]],"ltp":1.17,"tv":34.94,"id":8444034}]}]}
{"op":"mcm","clk":"1003373316","pt":1580649705319,"mc":[{"id":"1.168213439","rc":[{"batb":[[0,8.2,8.97],[1,3.4,376.1],[2,1.01,15.51]],"ltp":7.2,"tv":0.61,"id":10107989},{"batb":[[0,1.07,316.14],[1,1.05,1069.58],[2,1.01,15.51]],"ltp":1.17,"tv":34.94,"id":8444034}]}]}
{"op":"mcm","clk":"1003374507","pt":1580649713439,"mc":[{"id":"1.168213439","rc":[{"batb":[[0,10,13.14],[1,9.2,6.92],[2,8.2,8.97]],"ltp":7.2,"tv":0.61,"id":10107989},{"batb":[[1,1.05,1497.93]],"ltp":1.17,"tv":34.94,"id":8444034}]}]}
{"op":"mcm","clk":"1003374557","pt":1580649713758,"mc":[{"id":"1.168213439","rc":[{"batb":[[2,3.4,376.1]],"ltp":7.2,"tv":0.61,"id":10107989}]}]}
{"op":"mcm","clk":"1003378976","pt":1580649741636,"mc":[{"id":"1.168213439","rc":[{"batb":[[0,9.2,6.92],[1,3.4,376.1],[2,1.01,15.51]],"ltp":7.2,"tv":0.61,"id":10107989},{"batb":[[0,1.05,1496.91],[1,1.01,15.51],[2,1.01,0]],"ltp":1.17,"tv":34.94,"id":8444034}]}]}
{"op":"mcm","clk":"1003380947","pt":1580649754359,"mc":[{"id":"1.168213439","rc":[{"trd":[[9.2,0.47]],"batb":[[0,9.2,6.46]],"ltp":9.2,"tv":1.08,"id":10107989},{"trd":[[1.13,3.79]],"ltp":1.13,"tv":38.72,"id":8444034}],"tv":39.8}]}
{"op":"mcm","clk":"1003381096","pt":1580649755266,"mc":[{"id":"1.168213439","rc":[{"batb":[[0,1.05,427.32]],"ltp":1.13,"tv":38.72,"id":8444034}]}]}
{"op":"mcm","clk":"1003381282","pt":1580649756436,"mc":[{"id":"1.168213439","rc":[{"batb":[[1,8.4,8.26],[2,3.4,376.1]],"ltp":9.2,"tv":1.08,"id":10107989},{"batb":[[0,1.09,269.09],[1,1.07,334.32],[2,1.01,15.51]],"ltp":1.13,"tv":38.72,"id":8444034}]}]}
{"op":"mcm","clk":"1003381649","pt":1580649759050,"mc":[{"id":"1.168213439","rc":[{"batb":[[2,1.06,936.8]],"ltp":1.13,"tv":38.72,"id":8444034}]}]}
{"op":"mcm","clk":"1003383239","pt":1580649769109,"mc":[{"id":"1.168213439","rc":[{"batb":[[0,8.4,8.26],[1,3.4,376.1],[2,1.01,15.51]],"ltp":9.2,"tv":1.08,"id":10107989},{"batb":[[0,1.07,333.77],[1,1.06,936.8],[2,1.01,15.51]],"ltp":1.13,"tv":38.72,"id":8444034}]}]}
{"op":"mcm","clk":"1003384035","pt":1580649774102,"mc":[{"id":"1.168213439","rc":[{"batb":[[1,1.01,15.51],[2,1.01,0]],"ltp":1.13,"tv":38.72,"id":8444034}]}]}
{"op":"mcm","clk":"1003384664","pt":1580649778207,"mc":[{"id":"1.168213439","rc":[{"batb":[[1,1.05,1069.58],[2,1.01,15.51]],"ltp":1.13,"tv":38.72,"id":8444034}]}]}
{"op":"mcm","clk":"1003386115","pt":1580649787228,"mc":[{"id":"1.168213439","rc":[{"batb":[[1,1.01,15.51],[2,1.01,0]],"ltp":1.13,"tv":38.72,"id":8444034}]}]}
{"op":"mcm","clk":"1003386474","pt":1580649789227,"mc":[{"id":"1.168213439","rc":[{"batb":[[1,8,9.36],[2,3.4,376.1]],"ltp":9.2,"tv":1.08,"id":10107989},{"batb":[[0,1.1,237.3],[1,1.08,277.9],[2,1.01,15.51]],"ltp":1.13,"tv":38.72,"id":8444034}]}]}
{"op":"mcm","clk":"1003386819","pt":1580649791341,"mc":[{"id":"1.168213439","rc":[{"batb":[[2,1.06,936.8]],"ltp":1.13,"tv":38.72,"id":8444034}]}]}
{"op":"mcm","clk":"1003389178","pt":1580649805661,"mc":[{"id":"1.168213439","rc":[{"batb":[[0,8,9.36],[1,3.4,376.1],[2,1.01,15.51]],"ltp":9.2,"tv":1.08,"id":10107989},{"batb":[[0,1.08,277.9],[1,1.06,936.8],[2,1.01,15.51]],"ltp":1.13,"tv":38.72,"id":8444034}]}]}
{"op":"mcm","clk":"1003389919","pt":1580649810384,"mc":[{"id":"1.168213439","rc":[{"batb":[[1,1.01,15.51],[2,1.01,0]],"ltp":1.13,"tv":38.72,"id":8444034}]}]}
{"op":"mcm","clk":"1003390381","pt":1580649813162,"mc":[{"id":"1.168213439","rc":[{"batb":[[1,7.8,10.15],[2,3.4,376.1]],"ltp":9.2,"tv":1.08,"id":10107989},{"batb":[[0,1.1,239.11]],"ltp":1.13,"tv":38.72,"id":8444034}]}]}
{"op":"mcm","clk":"1003390606","pt":1580649814584,"mc":[{"id":"1.168213439","rc":[{"batb":[[1,1.06,993.9],[2,1.01,15.51]],"ltp":1.13,"tv":38.72,"id":8444034}]}]}
{"op":"mcm","clk":"1003392112","pt":1580649823621,"mc":[{"id":"1.168213439","rc":[{"batb":[[0,7.8,10.15],[1,3.4,376.1],[2,1.01,15.51]],"ltp":9.2,"tv":1.08,"id":10107989}]}]}
{"op":"mcm","clk":"1003395443","pt":1580649843723,"mc":[{"id":"1.168213439","rc":[{"batb":[[1,5.2,12.83],[2,3.4,376.1]],"ltp":9.2,"tv":1.08,"id":10107989},{"batb":[[0,1.11,209.69],[1,1.1,239.11],[2,1.08,299.15]],"ltp":1.13,"tv":38.72,"id":8444034}]}]}
{"op":"mcm","clk":"1003395495","pt":1580649844041,"mc":[{"id":"1.168213439","rc":[{"batb":[[1,1.08,299.15],[2,1.06,993.9]],"ltp":1.13,"tv":38.72,"id":8444034}]}]}
{"op":"mcm","clk":"1003408821","pt":1580649923207,"mc":[{"id":"1.168213439","rc":[{"batb":[[0,5.2,12.83],[1,3.4,376.1],[2,1.01,15.51]],"ltp":9.2,"tv":1.08,"id":10107989},{"batb":[[0,1.08,299.15],[1,1.06,993.9],[2,1.01,15.51]],"ltp":1.13,"tv":38.72,"id":8444034}]}]}
{"op":"mcm","clk":"1003410609","pt":1580649933943,"mc":[{"id":"1.168213439","rc":[{"batb":[[1,1.01,15.51],[2,1.01,0]],"ltp":1.13,"tv":38.72,"id":8444034}]}]}
{"op":"mcm","clk":"1003410963","pt":1580649935718,"mc":[{"id":"1.168213439","rc":[{"batb":[[1,3.45,16.76],[2,3.4,376.1]],"ltp":9.2,"tv":1.08,"id":10107989},{"batb":[[0,1.2,115.58],[1,1.14,173.34],[2,1.08,299.15]],"ltp":1.13,"tv":38.72,"id":8444034}]}]}
{"op":"mcm","clk":"1003411001","pt":1580649935928,"mc":[{"id":"1.168213439","rc":[{"batb":[[2,1.01,15.51]],"ltp":1.13,"tv":38.72,"id":8444034}]}]}
{"op":"mcm","clk":"1003411329","pt":1580649937634,"mc":[{"id":"1.168213439","rc":[{"batb":[[2,1.12,650.34]],"ltp":1.13,"tv":38.72,"id":8444034}]}]}
{"op":"mcm","clk":"1003413460","pt":1580649950569,"mc":[{"id":"1.168213439","rc":[{"batb":[[0,3.45,16.76],[1,3.4,376.1],[2,1.01,15.51]],"ltp":9.2,"tv":1.08,"id":10107989},{"batb":[[0,1.14,173.34],[1,1.12,650.34],[2,1.01,15.51]],"ltp":1.13,"tv":38.72,"id":8444034}]}]}
{"op":"mcm","clk":"1003414632","pt":1580649959103,"mc":[{"id":"1.168213439","rc":[{"batb":[[1,1.01,15.51],[2,1.01,0]],"ltp":9.2,"tv":1.08,"id":10107989},{"batb":[[1,1.01,15.51],[2,1.01,0]],"ltp":1.13,"tv":38.72,"id":8444034}]}]}
{"op":"mcm","clk":"1003415037","pt":1580649962048,"mc":[{"id":"1.168213439","rc":[{"batb":[[1,2.5,15.5],[2,1.01,15.51]],"ltp":9.2,"tv":1.08,"id":10107989},{"batb":[[0,1.35,58.7],[1,1.26,85.61],[2,1.01,15.51]],"ltp":1.13,"tv":38.72,"id":8444034}]}]}
{"op":"mcm","clk":"1003415163","pt":1580649962961,"mc":[{"id":"1.168213439","rc":[{"batb":[[1,2.52,381.46],[2,2.5,15.5]],"ltp":9.2,"tv":1.08,"id":10107989},{"batb":[[2,1.2,530.86]],"ltp":1.13,"tv":38.72,"id":8444034}]}]}
{"op":"mcm","clk":"1003417795","pt":1580649980361,"mc":[{"id":"1.168213439","rc":[{"batb":[[0,2.52,381.46],[1,2.5,15.5],[2,1.01,15.51]],"ltp":9.2,"tv":1.08,"id":10107989},{"batb":[[0,1.26,85.61],[1,1.2,530.86],[2,1.01,15.51]],"ltp":1.13,"tv":38.72,"id":8444034}]}]}
{"op":"mcm","clk":"1003418965","pt":1580649987110,"mc":[{"id":"1.168213439","rc":[{"batb":[[0,2.5,15.5],[1,1.01,15.51],[2,1.01,0]],"ltp":9.2,"tv":1.08,"id":10107989},{"batb":[[1,1.01,15.51],[2,1.01,0]],"ltp":1.13,"tv":38.72,"id":8444034}]}]}
{"op":"mcm","clk":"1003419330","pt":1580649989630,"mc":[{"id":"1.168213439","rc":[{"batb":[[0,4.2,20.06],[1,2.82,11.33],[2,2.5,15.5]],"ltp":9.2,"tv":1.08,"id":10107989},{"batb":[[1,1.17,138.95],[2,1.01,15.51]],"ltp":1.13,"tv":38.72,"id":8444034}]}]}
{"op":"mcm","clk":"1003419367","pt":1580649989908,"mc":[{"id":"1.168213439","rc":[{"batb":[[2,1.01,15.51]],"ltp":9.2,"tv":1.08,"id":10107989}]}]}
{"op":"mcm","clk":"1003419551","pt":1580649991225,"mc":[{"id":"1.168213439","rc":[{"batb":[[2,2.72,378.25]],"ltp":9.2,"tv":1.08,"id":10107989},{"batb":[[2,1.16,576.13]],"ltp":1.13,"tv":38.72,"id":8444034}]}]}
{"op":"mcm","clk":"1003422017","pt":1580650007172,"mc":[{"id":"1.168213439","rc":[{"batb":[[0,2.82,11.33],[1,2.72,378.25],[2,1.01,15.51]],"ltp":9.2,"tv":1.08,"id":10107989},{"batb":[[0,1.17,138.95],[1,1.16,576.13],[2,1.01,15.51]],"ltp":1.13,"tv":38.72,"id":8444034}]}]}
{"op":"mcm","clk":"1003422789","pt":1580650012566,"mc":[{"id":"1.168213439","rc":[{"batb":[[1,1.01,15.51],[2,1.01,0]],"ltp":1.13,"tv":38.72,"id":8444034}]}]}
{"op":"mcm","clk":"1003423323","pt":1580650016361,"mc":[{"id":"1.168213439","rc":[{"batb":[[0,1.2,530.86],[1,1.17,138.95],[2,1.01,15.51]],"ltp":1.13,"tv":38.72,"id":8444034}]}]}
{"op":"mcm","clk":"1003424760","pt":1580650025342,"mc":[{"id":"1.168213439","rc":[{"batb":[[1,1.01,15.51],[2,1.01,0]],"ltp":9.2,"tv":1.08,"id":10107989},{"batb":[[0,1.17,138.95],[1,1.01,15.51],[2,1.01,0]],"ltp":1.13,"tv":38.72,"id":8444034}]}]}
{"op":"mcm","clk":"1003425094","pt":1580650027347,"mc":[{"id":"1.168213439","rc":[{"batb":[[0,5.8,19.75],[1,3.35,17.62],[2,1.01,15.51]],"ltp":9.2,"tv":1.08,"id":10107989},{"batb":[[1,1.09,254.14],[2,1.01,15.51]],"ltp":1.13,"tv":38.72,"id":8444034}]}]}
{"op":"mcm","clk":"1003425425","pt":1580650029469,"mc":[{"id":"1.168213439","rc":[{"batb":[[2,3.1,373.78]],"ltp":9.2,"tv":1.08,"id":10107989},{"batb":[[1,1.1,723.21],[2,1.09,254.14]],"ltp":1.13,"tv":38.72,"id":8444034}]}]}
{"op":"mcm","clk":"1003427226","pt":1580650041382,"mc":[{"id":"1.168213439","rc":[{"trd":[[5.8,4.54]],"batb":[[0,5.8,17.48]],"ltp":5.8,"tv":5.62,"id":10107989}],"tv":44.35}]}
{"op":"mcm","clk":"1003427776","pt":1580650045358,"mc":[{"id":"1.168213439","rc":[{"batb":[[0,3.35,17.62],[1,3.1,373.78],[2,1.01,15.51]],"ltp":5.8,"tv":5.62,"id":10107989},{"batb":[[0,1.1,723.21],[1,1.09,252.88],[2,1.01,15.51]],"ltp":1.13,"tv":38.72,"id":8444034}]}]}
{"op":"mcm","clk":"1003427939","pt":1580650046492,"mc":[{"id":"1.168213439","rc":[{"batb":[[1,1.01,15.51],[2,1.01,0]],"ltp":5.8,"tv":5.62,"id":10107989},{"batb":[[0,1.09,252.88],[1,1.01,15.51],[2,1.01,0]],"ltp":1.13,"tv":38.72,"id":8444034}]}]}
{"op":"mcm","clk":"1003429155","pt":1580650054699,"mc":[{"id":"1.168213439","rc":[{"batb":[[1,2.84,375.42],[2,1.01,15.51]],"ltp":5.8,"tv":5.62,"id":10107989},{"batb":[[0,1.14,610.45],[1,1.09,252.88],[2,1.01,15.51]],"ltp":1.13,"tv":38.72,"id":8444034}]}]}
{"op":"mcm","clk":"1003431458","pt":1580650070520,"mc":[{"id":"1.168213439","rc":[{"batb":[[1,1.01,15.51],[2,1.01,0]],"ltp":5.8,"tv":5.62,"id":10107989},{"batb":[[0,1.09,252.88],[1,1.01,15.51],[2,1.01,0]],"ltp":1.13,"tv":38.72,"id":8444034}]}]}
{"op":"mcm","clk":"1003431757","pt":1580650072544,"mc":[{"id":"1.168213439","rc":[{"batb":[[0,8.8,7.47],[1,4.8,15.03],[2,1.01,15.51]],"ltp":5.8,"tv":5.62,"id":10107989},{"batb":[[1,1.04,497.98],[2,1.01,15.51]],"ltp":1.13,"tv":38.72,"id":8444034}]}]}
{"op":"mcm","clk":"1003432068","pt":1580650074623,"mc":[{"id":"1.168213439","rc":[{"batb":[[2,3.6,374.21]],"ltp":5.8,"tv":5.62,"id":10107989},{"batb":[[1,1.05,1069.58],[2,1.04,497.98]],"ltp":1.13,"tv":38.72,"id":8444034}]}]}
{"op":"mcm","clk":"1003434261","pt":1580650088903,"mc":[{"id":"1.168213439","rc":[{"batb":[[0,4.8,15.03],[1,3.6,374.21],[2,1.01,15.51]],"ltp":5.8,"tv":5.62,"id":10107989},{"batb":[[0,1.05,1069.58],[1,1.04,497.66],[2,1.01,15.51]],"ltp":1.13,"tv":38.72,"id":8444034}]}]}
{"op":"mcm","clk":"1003434559","pt":1580650090662,"mc":[{"id":"1.168213439","rc":[{"batb":[[1,1.01,15.51],[2,1.01,0]],"ltp":5.8,"tv":5.62,"id":10107989},{"batb":[[0,1.04,497.66],[1,1.01,15.51],[2,1.01,0]],"ltp":1.13,"tv":38.72,"id":8444034}]}]}
{"op":"mcm","clk":"1003435993","pt":1580650099560,"mc":[{"id":"1.168213439","rc":[{"batb":[[1,2.12,24.08],[2,1.01,15.51]],"ltp":5.8,"tv":5.62,"id":10107989},{"batb":[[0,1.22,104.1],[1,1.05,442.66],[2,1.04,497.66]],"ltp":1.13,"tv":38.72,"id":8444034}]}]}
{"op":"mcm","clk":"1003436079","pt":1580650100139,"mc":[{"id":"1.168213439","rc":[{"batb":[[1,2.84,375.42],[2,2.12,24.08]],"ltp":5.8,"tv":5.62,"id":10107989},{"batb":[[1,1.14,610.45],[2,1.05,442.66]],"ltp":1.13,"tv":38.72,"id":8444034}]}]}
{"op":"mcm","clk":"1003439675","pt":1580650123588,"mc":[{"id":"1.168213439","rc":[{"batb":[[0,2.84,375.42],[1,2.12,24.08],[2,1.01,15.51]],"ltp":5.8,"tv":5.62,"id":10107989},{"batb":[[0,1.14,610.45],[1,1.05,442.66],[2,1.01,15.51]],"ltp":1.13,"tv":38.72,"id":8444034}]}]}
{"op":"mcm","clk":"1003439869","pt":1580650124800,"mc":[{"id":"1.168213439","rc":[{"batb":[[0,2.12,24.08],[1,1.01,15.51],[2,1.01,0]],"ltp":5.8,"tv":5.62,"id":10107989},{"batb":[[0,1.05,442.66],[1,1.01,15.51],[2,1.01,0]],"ltp":1.13,"tv":38.72,"id":8444034}]}]}
{"op":"mcm","clk":"1003441310","pt":1580650134386,"mc":[{"id":"1.168213439","rc":[{"batb":[[0,2.62,379.26],[1,2.12,24.08],[2,1.01,15.51]],"ltp":5.8,"tv":5.62,"id":10107989},{"batb":[[0,1.18,549.72],[1,1.05,442.66],[2,1.01,15.51]],"ltp":1.13,"tv":38.72,"id":8444034}]}]}
{"op":"mcm","clk":"1003441648","pt":1580650136887,"mc":[{"id":"1.168213439","rc":[{"batb":[[0,2.12,24.08],[1,1.01,15.51],[2,1.01,0]],"ltp":5.8,"tv":5.62,"id":10107989},{"batb":[[0,1.05,442.66],[1,1.01,15.51],[2,1.01,0]],"ltp":1.13,"tv":38.72,"id":8444034}]}]}
{"op":"mcm","clk":"1003442828","pt":1580650144320,"mc":[{"id":"1.168213439","rc":[{"batb":[[0,13,7.4],[1,11.5,9.68],[2,1.01,15.51]],"ltp":5.8,"tv":5.62,"id":10107989},{"batb":[[1,1.03,599.79],[2,1.01,15.51]],"ltp":1.13,"tv":38.72,"id":8444034}]}]}
{"op":"mcm","clk":"1003443031","pt":1580650145485,"mc":[{"id":"1.168213439","rc":[{"batb":[[2,4,373.79]],"ltp":5.8,"tv":5.62,"id":10107989},{"batb":[[2,1.02,2147.96]],"ltp":1.13,"tv":38.72,"id":8444034}]}]}
{"op":"mcm","clk":"1003447220","pt":1580650172616,"mc":[{"id":"1.168213439","rc":[{"batb":[[0,11.5,9.68],[1,4,373.79],[2,1.01,15.51]],"ltp":5.8,"tv":5.62,"id":10107989},{"batb":[[0,1.03,599.79],[1,1.02,2147.96],[2,1.01,15.51]],"ltp":1.13,"tv":38.72,"id":8444034}]}]}
{"op":"mcm","clk":"1003448110","pt":1580650178084,"mc":[{"id":"1.168213439","rc":[{"batb":[[1,1.01,15.51],[2,1.01,0]],"ltp":1.13,"tv":38.72,"id":8444034}]}]}
{"op":"mcm","clk":"1003448472","pt":1580650180602,"mc":[{"id":"1.168213439","rc":[{"batb":[[0,16.5,4.41],[1,14,6.61],[2,11.5,9.68]],"ltp":5.8,"tv":5.62,"id":10107989}]}]}
{"op":"mcm","clk":"1003448513","pt":1580650180871,"mc":[{"id":"1.168213439","rc":[{"batb":[[2,4,373.79]],"ltp":5.8,"tv":5.62,"id":10107989}]}]}
{"op":"mcm","clk":"1003448631","pt":1580650181778,"mc":[{"id":"1.168213439","rc":[{"batb":[[1,1.01,4112.75]],"ltp":1.13,"tv":38.72,"id":8444034}]}]}
{"op":"mcm","clk":"1003450750","pt":1580650195631,"mc":[{"id":"1.168213439","rc":[{"batb":[[0,14,6.61],[1,4,373.79],[2,1.01,15.51]],"ltp":5.8,"tv":5.62,"id":10107989},{"batb":[[0,1.01,4112.75],[1,1.01,0]],"ltp":1.13,"tv":38.72,"id":8444034}]}]}
{"op":"mcm","clk":"1003451840","pt":1580650202167,"mc":[{"id":"1.168213439","rc":[{"batb":[[0,1.01,15.51]],"ltp":1.13,"tv":38.72,"id":8444034}]}]}
{"op":"mcm","clk":"1003452352","pt":1580650204551,"mc":[{"id":"1.168213439","rc":[{"batb":[[0,24,5.67],[1,18.5,6.45],[2,4,373.79]],"ltp":5.8,"tv":5.62,"id":10107989}]}]}
{"op":"mcm","clk":"1003452699","pt":1580650206200,"mc":[{"id":"1.168213439","rc":[{"batl":[[0,340,35.88]],"ltp":5.8,"tv":5.62,"id":10107989}]}]}
{"op":"mcm","clk":"1003455372","pt":1580650222831,"mc":[{"id":"1.168213439","rc":[{"batb":[[0,18.5,6.45],[1,4,373.79],[2,1.01,15.51]],"ltp":5.8,"tv":5.62,"id":10107989}]}]}
{"op":"mcm","clk":"1003455603","pt":1580650224373,"mc":[{"id":"1.168213439","rc":[{"batb":[[1,1.01,15.51],[2,1.01,0]],"ltp":5.8,"tv":5.62,"id":10107989}]}]}
{"op":"mcm","clk":"1003457314","pt":1580650235643,"mc":[{"id":"1.168213439","rc":[{"batb":[[1,15,5.51],[2,1.01,15.51]],"ltp":5.8,"tv":5.62,"id":10107989},{"batb":[[0,1.03,724.82],[1,1.01,15.51]],"ltp":1.13,"tv":38.72,"id":8444034}]}]}
{"op":"mcm","clk":"1003457413","pt":1580650236339,"mc":[{"id":"1.168213439","rc":[{"batb":[[2,4.2,370.95]],"ltp":5.8,"tv":5.62,"id":10107989},{"batb":[[1,1.01,3928.19]],"ltp":1.13,"tv":38.72,"id":8444034}]}]}
{"op":"mcm","clk":"1003459434","pt":1580650249940,"mc":[{"id":"1.168213439","rc":[{"batb":[[0,15,5.51],[1,4.2,370.95],[2,1.01,15.51]],"ltp":5.8,"tv":5.62,"id":10107989},{"batb":[[0,1.01,3928.19],[1,1.01,0]],"ltp":1.13,"tv":38.72,"id":8444034}]}]}
{"op":"mcm","clk":"1003459654","pt":1580650251462,"mc":[{"id":"1.168213439","rc":[{"batb":[[1,1.01,15.51],[2,1.01,0]],"ltp":5.8,"tv":5.62,"id":10107989},{"batb":[[0,1.01,15.51]],"ltp":1.13,"tv":38.72,"id":8444034}]}]}
{"op":"mcm","clk":"1003460744","pt":1580650258578,"mc":[{"id":"1.168213439","rc":[{"batb":[[1,12,8.97],[2,1.01,15.51]],"ltp":5.8,"tv":5.62,"id":10107989},{"batb":[[0,1.04,523],[1,1.01,15.51]],"ltp":1.13,"tv":38.72,"id":8444034}]}]}
{"op":"mcm","clk":"1003460893","pt":1580650259582,"mc":[{"id":"1.168213439","rc":[{"batb":[[2,4.1,372.42]],"ltp":5.8,"tv":5.62,"id":10107989},{"batb":[[1,1.01,4112.75]],"ltp":1.13,"tv":38.72,"id":8444034}]}]}
{"op":"mcm","clk":"1003462738","pt":1580650271611,"mc":[{"id":"1.168213439","rc":[{"batb":[[0,12,8.97],[1,4.1,372.42],[2,1.01,15.51]],"ltp":5.8,"tv":5.62,"id":10107989},{"batb":[[0,1.01,4112.75],[1,1.01,0]],"ltp":1.13,"tv":38.72,"id":8444034}]}]}
{"op":"mcm","clk":"1003462960","pt":1580650273228,"mc":[{"id":"1.168213439","rc":[{"batb":[[1,1.01,15.51],[2,1.01,0]],"ltp":5.8,"tv":5.62,"id":10107989},{"batb":[[0,1.01,15.51]],"ltp":1.13,"tv":38.72,"id":8444034}]}]}
{"op":"mcm","clk":"1003464254","pt":1580650280693,"mc":[{"id":"1.168213439","rc":[{"batb":[[1,10.5,12.51],[2,1.01,15.51]],"ltp":5.8,"tv":5.62,"id":10107989},{"batb":[[0,1.06,394.12],[1,1.04,587.83],[2,1.01,15.51]],"ltp":1.13,"tv":38.72,"id":8444034}]}]}
{"op":"mcm","clk":"1003464478","pt":1580650281890,"mc":[{"id":"1.168213439","rc":[{"batb":[[2,4,373.79]],"ltp":5.8,"tv":5.62,"id":10107989},{"batb":[[2,1.02,2147.96]],"ltp":1.13,"tv":38.72,"id":8444034}]}]}
{"op":"mcm","clk":"1003466694","pt":1580650295411,"mc":[{"id":"1.168213439","rc":[{"batb":[[0,10.5,12.51],[1,4,373.79],[2,1.01,15.51]],"ltp":5.8,"tv":5.62,"id":10107989},{"batb":[[0,1.04,587.83],[1,1.02,2147.96],[2,1.01,15.51]],"ltp":1.13,"tv":38.72,"id":8444034}]}]}
{"op":"mcm","clk":"1003468183","pt":1580650305140,"mc":[{"id":"1.168213439","rc":[{"batb":[[1,5.8,19.36],[2,4,373.79]],"ltp":5.8,"tv":5.62,"id":10107989},{"batb":[[0,1.07,325.04],[1,1.03,656.6],[2,1.02,2147.96]],"ltp":1.13,"tv":38.72,"id":8444034}]}]}
{"op":"mcm","clk":"1003468861","pt":1580650309451,"mc":[{"id":"1.168213439","rc":[{"trd":[[10.5,0.4]],"batb":[[0,10.5,12.11]],"ltp":10.5,"tv":6.02,"id":10107989},{"trd":[[1.11,3.79]],"ltp":1.11,"tv":42.51,"id":8444034}],"tv":48.53}]}
{"op":"mcm","clk":"1003468982","pt":1580650310143,"mc":[{"id":"1.168213439","rc":[{"batb":[[0,1.07,324.56],[1,1.03,655.5]],"ltp":1.11,"tv":42.51,"id":8444034}]}]}
{"op":"mcm","clk":"1003472697","pt":1580650333697,"mc":[{"id":"1.168213439","rc":[{"trd":[[1.07,649.1]],"batb":[[0,1.03,655.5],[1,1.02,2147.96],[2,1.01,15.51]],"batl":[[0,1.07,1114.2]],"ltp":1.07,"tv":691.61,"id":8444034}],"tv":697.64}]}
{"op":"mcm","clk":"1003473185","pt":1580650336663,"mc":[{"id":"1.168213439","rc":[{"batb":[[0,11.5,9.99],[1,10.5,12.11],[2,6.4,15.5]],"ltp":10.5,"tv":6.02,"id":10107989},{"batb":[[0,1.06,371.61],[1,1.03,655.5],[2,1.02,2900.63]],"ltp":1.07,"tv":691.61,"id":8444034}]}]}
{"op":"mcm","clk":"1003473336","pt":1580650337582,"mc":[{"id":"1.168213439","rc":[{"batb":[[1,6.4,15.5],[2,4,373.79]],"ltp":10.5,"tv":6.02,"id":10107989},{"batb":[[1,1.02,2900.63],[2,1.01,15.51]],"ltp":1.07,"tv":691.61,"id":8444034}]}]}
{"op":"mcm","clk":"1003475893","pt":1580650353898,"mc":[{"id":"1.168213439","rc":[{"trd":[[1.06,743.2]],"batb":[[0,1.02,2900.63],[1,1.01,15.51],[2,1.01,0]],"batl":[[0,1.06,742.61]],"ltp":1.06,"tv":1434.82,"id":8444034}],"tv":1440.84}]}
{"op":"mcm","clk":"1003476582","pt":1580650358540,"mc":[{"id":"1.168213439","rc":[{"batb":[[0,13,7.71],[1,7.2,12.12]],"ltp":10.5,"tv":6.02,"id":10107989},{"batb":[[0,1.05,431.02],[1,1.02,2900.63],[2,1.01,15.51]],"ltp":1.06,"tv":1434.82,"id":8444034}]}]}
{"op":"mcm","clk":"1003478496","pt":1580650371007,"mc":[{"id":"1.168213439","rc":[{"trd":[[1.06,750.78]],"batl":[[0,1.06,738.82]],"ltp":1.06,"tv":1442.39,"id":8444034}],"tv":1448.41}]}
{"op":"mcm","clk":"1003481320","pt":1580650388560,"mc":[{"id":"1.168213439","rc":[{"trd":[[1.05,862.01]],"batb":[[0,1.02,2900.63],[1,1.01,15.51],[2,1.01,0]],"batl":[[0,1.05,307.83]],"ltp":1.05,"tv":2304.4,"id":8444034}],"tv":2310.43}]}
{"op":"mcm","clk":"1003481590","pt":1580650390191,"mc":[{"id":"1.168213439","rc":[{"batb":[[0,7.2,12.12],[1,4,373.79],[2,1.01,15.51]],"ltp":10.5,"tv":6.02,"id":10107989}]}]}
{"op":"mcm","clk":"1003481914","pt":1580650392135,"mc":[{"id":"1.168213439","rc":[{"batb":[[1,1.01,15.51],[2,1.01,0]],"ltp":10.5,"tv":6.02,"id":10107989},{"batb":[[0,1.02,752.67]],"ltp":1.05,"tv":2304.4,"id":8444034}]}]}
{"op":"mcm","clk":"1003482125","pt":1580650393381,"mc":[{"id":"1.168213439","rc":[{"batb":[[0,8.2,9.13]],"ltp":10.5,"tv":6.02,"id":10107989},{"batb":[[0,1.01,15.51],[1,1.01,0]],"ltp":1.05,"tv":2304.4,"id":8444034}]}]}
{"op":"mcm","clk":"1003484231","pt":1580650406286,"mc":[{"id":"1.168213439","rc":[{"batb":[[0,24,2.9],[1,12,9.21],[2,1.01,15.51]],"ltp":10.5,"tv":6.02,"id":10107989}]}]}
{"op":"mcm","clk":"1003484375","pt":1580650407210,"mc":[{"id":"1.168213439","rc":[{"batb":[[2,4.3,371.86]],"batl":[[0,170,36.98]],"ltp":10.5,"tv":6.02,"id":10107989}]}]}
{"op":"mcm","clk":"1003486803","pt":1580650420628,"mc":[{"id":"1.168213439","rc":[{"batb":[[0,12,9.21],[1,4.3,371.86],[2,1.01,15.51]],"ltp":10.5,"tv":6.02,"id":10107989}]}]}
{"op":"mcm","clk":"1003487116","pt":1580650422225,"mc":[{"id":"1.168213439","rc":[{"batb":[[1,1.01,15.51],[2,1.01,0]],"ltp":10.5,"tv":6.02,"id":10107989}]}]}
{"op":"mcm","clk":"1003488131","pt":1580650427622,"mc":[{"id":"1.168213439","rc":[{"batb":[[0,22,4.18]],"ltp":10.5,"tv":6.02,"id":10107989}]}]}
{"op":"mcm","clk":"1003488292","pt":1580650428419,"mc":[{"id":"1.168213439","rc":[{"batb":[[1,4.6,370.62],[2,1.01,15.51]],"ltp":10.5,"tv":6.02,"id":10107989}]}]}
{"op":"mcm","clk":"1003490854","pt":1580650442453,"mc":[{"id":"1.168213439","rc":[{"batb":[[1,1.01,15.51],[2,1.01,0]],"ltp":10.5,"tv":6.02,"id":10107989}]}]}
{"op":"mcm","clk":"1003491871","pt":1580650448261,"mc":[{"id":"1.168213439","rc":[{"batb":[[0,1.01,15.51],[1,1.01,0]],"ltp":10.5,"tv":6.02,"id":10107989}]}]}
{"op":"mcm","clk":"1003492639","pt":1580650452670,"mc":[{"id":"1.168213439","rc":[{"batb":[[0,4.8,366.76],[1,1.01,15.51]],"ltp":10.5,"tv":6.02,"id":10107989}]}]}
{"op":"mcm","clk":"1003495235","pt":1580650467450,"mc":[{"id":"1.168213439","rc":[{"batb":[[0,1.01,15.51],[1,1.01,0]],"ltp":10.5,"tv":6.02,"id":10107989}]}]}
{"op":"mcm","clk":"1003496562","pt":1580650474873,"mc":[{"id":"1.168213439","rc":[{"batb":[[0,4.7,371.58],[1,1.01,15.51]],"ltp":10.5,"tv":6.02,"id":10107989}]}]}
{"op":"mcm","clk":"1003497758","pt":1580650481464,"mc":[{"id":"1.168213439","rc":[{"batb":[[0,1.01,15.51],[1,1.01,0]],"ltp":10.5,"tv":6.02,"id":10107989}]}]}
{"op":"mcm","clk":"1003499271","pt":1580650489610,"mc":[{"id":"1.168213439","rc":[{"batb":[[0,21,4.56],[1,1.01,15.51]],"ltp":10.5,"tv":6.02,"id":10107989}]}]}
{"op":"mcm","clk":"1003499548","pt":1580650491091,"mc":[{"id":"1.168213439","rc":[{"batb":[[1,4.6,374.41],[2,1.01,15.51]],"ltp":10.5,"tv":6.02,"id":10107989}]}]}
{"op":"mcm","clk":"1003502913","pt":1580650508619,"mc":[{"id":"1.168213439","rc":[{"batb":[[1,1.01,15.51],[2,1.01,0]],"ltp":10.5,"tv":6.02,"id":10107989}]}]}
{"op":"mcm","clk":"1003504723","pt":1580650517571,"mc":[{"id":"1.168213439","marketDefinition":{"bspMarket":false,"turnInPlayEnabled":true,"persistenceEnabled":true,"marketBaseRate":5.0,"eventId":"29681204","eventTypeId":"2","numberOfWinners":1,"bettingType":"ODDS","marketType":"SET_WINNER","marketTime":"2020-02-02T12:47:00.000Z","suspendTime":"2020-02-02T12:47:00.000Z","bspReconciled":false,"complete":true,"inPlay":true,"crossMatching":true,"runnersVoidable":false,"numberOfActiveRunners":2,"betDelay":3,"status":"SUSPENDED","runners":[{"status":"ACTIVE","sortPriority":1,"id":8444034,"name":"Golubev/Nedovyesov"},{"status":"ACTIVE","sortPriority":2,"id":10107989,"name":"Sabanov/Sabanov"}],"regulators":["MR_INT"],"countryCode":"FR","discountAllowed":true,"timezone":"UTC","openDate":"2020-02-02T12:47:00.000Z","version":3148953468,"name":"Set 1 Winner","eventName":"Golubev/Nedovyesov v Sabanov/Sabanov"}}]}
{"op":"mcm","clk":"1003504954","pt":1580650518717,"mc":[{"id":"1.168213439","rc":[{"batb":[[0,1.01,15.51],[1,1.01,0]],"ltp":10.5,"tv":6.02,"id":10107989}]}]}
{"op":"mcm","clk":"1003511169","pt":1580650549740,"mc":[{"id":"1.168213439","tv":0.0}]}
{"op":"mcm","clk":"1003511347","pt":1580650550676,"mc":[{"id":"1.168213439","marketDefinition":{"bspMarket":false,"turnInPlayEnabled":true,"persistenceEnabled":true,"marketBaseRate":5.0,"eventId":"29681204","eventTypeId":"2","numberOfWinners":1,"bettingType":"ODDS","marketType":"SET_WINNER","marketTime":"2020-02-02T12:47:00.000Z","suspendTime":"2020-02-02T12:47:00.000Z","bspReconciled":false,"complete":true,"inPlay":true,"crossMatching":false,"runnersVoidable":false,"numberOfActiveRunners":0,"betDelay":3,"status":"CLOSED","settledTime":"2020-02-02T13:35:48.000Z","runners":[{"status":"WINNER","sortPriority":1,"id":8444034,"name":"Golubev/Nedovyesov"},{"status":"LOSER","sortPriority":2,"id":10107989,"name":"Sabanov/Sabanov"}],"regulators":["MR_INT"],"countryCode":"FR","discountAllowed":true,"timezone":"UTC","openDate":"2020-02-02T12:47:00.000Z","version":3148957035,"name":"Set 1 Winner","eventName":"Golubev/Nedovyesov v Sabanov/Sabanov"}}]}
