{"op":"mcm","clk":"993864652","pt":1580564223743,"mc":[{"id":"1.168213438","marketDefinition":{"bspMarket":false,"turnInPlayEnabled":true,"persistenceEnabled":true,"marketBaseRate":5.0,"eventId":"29681204","eventTypeId":"2","numberOfWinners":1,"bettingType":"ODDS","marketType":"SET_BETTING","marketTime":"2020-02-02T09:00:00.000Z","suspendTime":"2020-02-02T09:00:00.000Z","bspReconciled":false,"complete":true,"inPlay":false,"crossMatching":false,"runnersVoidable":false,"numberOfActiveRunners":4,"betDelay":0,"status":"OPEN","runners":[{"status":"ACTIVE","sortPriority":1,"id":13114898,"name":"Golubev/Nedovyesov 2-0"},{"status":"ACTIVE","sortPriority":2,"id":13114902,"name":"Golubev/Nedovyesov 2-1"},{"status":"ACTIVE","sortPriority":3,"id":14819609,"name":"Sabanov/Sabanov 2-0"},{"status":"ACTIVE","sortPriority":4,"id":14819608,"name":"Sabanov/Sabanov 2-1"}],"regulators":["MR_INT"],"countryCode":"FR","discountAllowed":false,"timezone":"UTC","openDate":"2020-02-02T09:00:00.000Z","version":3145282987,"name":"Set Betting","eventName":"Golubev/Nedovyesov v Sabanov/Sabanov"}}]}
{"op":"mcm","clk":"993865150","pt":1580564225779,"mc":[{"id":"1.168213438","marketDefinition":{"bspMarket":false,"turnInPlayEnabled":true,"persistenceEnabled":true,"marketBaseRate":5.0,"eventId":"29681204","eventTypeId":"2","numberOfWinners":1,"bettingType":"ODDS","marketType":"SET_BETTING","marketTime":"2020-02-02T09:00:00.000Z","suspendTime":"2020-02-02T09:00:00.000Z","bspReconciled":false,"complete":true,"inPlay":false,"crossMatching":false,"runnersVoidable":false,"numberOfActiveRunners":4,"betDelay":0,"status":"OPEN","runners":[{"status":"ACTIVE","sortPriority":1,"id":13114898,"name":"Golubev/Nedovyesov 2-0"},{"status":"ACTIVE","sortPriority":2,"id":13114902,"name":"Golubev/Nedovyesov 2-1"},{"status":"ACTIVE","sortPriority":3,"id":14819609,"name":"Sabanov/Sabanov 2-0"},{"status":"ACTIVE","sortPriority":4,"id":14819608,"name":"Sabanov/Sabanov 2-1"}],"regulators":["MR_INT"],"countryCode":"FR","discountAllowed":false,"timezone":"UTC","openDate":"2020-02-02T09:00:00.000Z","version":3145282987,"name":"Set Betting","eventName":"Golubev/Nedovyesov v Sabanov/Sabanov"}}]}
{"op":"mcm","clk":"993865438","pt":1580564226748,"mc":[{"id":"1.168213438","marketDefinition":{"bspMarket":false,"turnInPlayEnabled":true,"persistenceEnabled":true,"marketBaseRate":5.0,"eventId":"29681204","eventTypeId":"2","numberOfWinners":1,"bettingType":"ODDS","marketType":"SET_BETTING","marketTime":"2020-02-02T09:00:00.000Z","suspendTime":"2020-02-02T09:00:00.000Z","bspReconciled":false,"complete":true,"inPlay":false,"crossMatching":false,"runnersVoidable":false,"numberOfActiveRunners":4,"betDelay":0,"status":"OPEN","runners":[{"status":"ACTIVE","sortPriority":1,"id":13114898,"name":"Golubev/Nedovyesov 2-0"},{"status":"ACTIVE","sortPriority":2,"id":13114902,"name":"Golubev/Nedovyesov 2-1"},{"status":"ACTIVE","sortPriority":3,"id":14819609,"name":"Sabanov/Sabanov 2-0"},{"status":"ACTIVE","sortPriority":4,"id":14819608,"name":"Sabanov/Sabanov 2-1"}],"regulators":["MR_INT"],"countryCode":"FR","discountAllowed":true,"timezone":"UTC","openDate":"2020-02-02T09:00:00.000Z","version":3145282987,"name":"Set Betting","eventName":"Golubev/Nedovyesov v Sabanov/Sabanov"}}]}
{"op":"mcm","clk":"994367130","pt":1580566357161,"mc":[{"id":"1.168213438","rc":[{"batb":[[0,1.02,2]],"ltp":0.0,"tv":0.0,"id":13114902},{"batb":[[0,1.02,2]],"ltp":0.0,"tv":0.0,"id":13114898},{"batb":[[0,1.02,2]],"ltp":0.0,"tv":0.0,"id":14819609},{"batb":[[0,1.02,2]],"ltp":0.0,"tv":0.0,"id":14819608}]}]}
{"op":"mcm","clk":"996243237","pt":1580574046235,"mc":[{"id":"1.168213438","marketDefinition":{"bspMarket":false,"turnInPlayEnabled":true,"persistenceEnabled":true,"marketBaseRate":5.0,"eventId":"29681204","eventTypeId":"2","numberOfWinners":1,"bettingType":"ODDS","marketType":"SET_BETTING","marketTime":"2020-02-02T13:00:00.000Z","suspendTime":"2020-02-02T13:00:00.000Z","bspReconciled":false,"complete":true,"inPlay":false,"crossMatching":false,"runnersVoidable":false,"numberOfActiveRunners":4,"betDelay":0,"status":"OPEN","runners":[{"status":"ACTIVE","sortPriority":1,"id":13114898,"name":"Golubev/Nedovyesov 2-0"},{"status":"ACTIVE","sortPriority":2,"id":13114902,"name":"Golubev/Nedovyesov 2-1"},{"status":"ACTIVE","sortPriority":3,"id":14819609,"name":"Sabanov/Sabanov 2-0"},{"status":"ACTIVE","sortPriority":4,"id":14819608,"name":"Sabanov/Sabanov 2-1"}],"regulators":["MR_INT"],"countryCode":"FR","discountAllowed":true,"timezone":"UTC","openDate":"2020-02-02T09:00:00.000Z","version":3146180826,"name":"Set Betting","eventName":"Golubev/Nedovyesov v Sabanov/Sabanov"}}]}
{"op":"mcm","clk":"996243943","pt":1580574049267,"mc":[{"id":"1.168213438","marketDefinition":{"bspMarket":false,"turnInPlayEnabled":true,"persistenceEnabled":true,"marketBaseRate":5.0,"eventId":"29681204","eventTypeId":"2","numberOfWinners":1,"bettingType":"ODDS","marketType":"SET_BETTING","marketTime":"2020-02-02T13:00:00.000Z","suspendTime":"2020-02-02T13:00:00.000Z","bspReconciled":false,"complete":true,"inPlay":false,"crossMatching":false,"runnersVoidable":false,"numberOfActiveRunners":4,"betDelay":0,"status":"OPEN","runners":[{"status":"ACTIVE","sortPriority":1,"id":13114898,"name":"Golubev/Nedovyesov 2-0"},{"status":"ACTIVE","sortPriority":2,"id":13114902,"name":"Golubev/Nedovyesov 2-1"},{"status":"ACTIVE","sortPriority":3,"id":14819609,"name":"Sabanov/Sabanov 2-0"},{"status":"ACTIVE","sortPriority":4,"id":14819608,"name":"Sabanov/Sabanov 2-1"}],"regulators":["MR_INT"],"countryCode":"FR","discountAllowed":true,"timezone":"UTC","openDate":"2020-02-02T13:00:00.000Z","version":3146180826,"name":"Set Betting","eventName":"Golubev/Nedovyesov v Sabanov/Sabanov"}}]}
{"op":"mcm","clk":"999037484","pt":1580591581985,"mc":[{"id":"1.168213438","rc":[{"batb":[[0,3.75,10.73],[1,1.02,2]],"ltp":0.0,"tv":0.0,"id":13114902},{"batb":[[0,2.7,17.36],[1,1.02,2]],"ltp":0.0,"tv":0.0,"id":13114898},{"batb":[[0,3.75,10.73],[1,1.02,2]],"ltp":0.0,"tv":0.0,"id":14819609},{"batb":[[0,4.3,10],[1,1.02,2]],"ltp":0.0,"tv":0.0,"id":14819608}]}]}
{"op":"mcm","clk":"999041446","pt":1580591613033,"mc":[{"id":"1.168213438","marketDefinition":{"bspMarket":false,"turnInPlayEnabled":true,"persistenceEnabled":true,"marketBaseRate":5.0,"eventId":"29681204","eventTypeId":"2","numberOfWinners":1,"bettingType":"ODDS","marketType":"SET_BETTING","marketTime":"2020-02-02T13:00:00.000Z","suspendTime":"2020-02-02T13:00:00.000Z","bspReconciled":false,"complete":true,"inPlay":false,"crossMatching":true,"runnersVoidable":false,"numberOfActiveRunners":4,"betDelay":0,"status":"OPEN","runners":[{"status":"ACTIVE","sortPriority":1,"id":13114898,"name":"Golubev/Nedovyesov 2-0"},{"status":"ACTIVE","sortPriority":2,"id":13114902,"name":"Golubev/Nedovyesov 2-1"},{"status":"ACTIVE","sortPriority":3,"id":14819609,"name":"Sabanov/Sabanov 2-0"},{"status":"ACTIVE","sortPriority":4,"id":14819608,"name":"Sabanov/Sabanov 2-1"}],"regulators":["MR_INT"],"countryCode":"FR","discountAllowed":true,"timezone":"UTC","openDate":"2020-02-02T13:00:00.000Z","version":3146180826,"name":"Set Betting","eventName":"Golubev/Nedovyesov v Sabanov/Sabanov"}}]}
{"op":"mcm","clk":"999914821","pt":1580602583679,"mc":[{"id":"1.168213438","rc":[{"batb":[[2,1.01,0.51]],"ltp":0.0,"tv":0.0,"id":13114902},{"batb":[[2,1.01,0.51]],"ltp":0.0,"tv":0.0,"id":13114898},{"batb":[[2,1.01,0.51]],"ltp":0.0,"tv":0.0,"id":14819609},{"batb":[[2,1.01,0.51]],"ltp":0.0,"tv":0.0,"id":14819608}]}]}
{"op":"mcm","clk":"999962496","pt":1580603349598,"mc":[{"id":"1.168213438","rc":[{"batb":[[2,1.01,3.04]],"ltp":0.0,"tv":0.0,"id":13114902},{"batb":[[2,1.01,3.04]],"ltp":0.0,"tv":0.0,"id":13114898},{"batb":[[2,1.01,3.04]],"ltp":0.0,"tv":0.0,"id":14819609},{"batb":[[2,1.01,3.04]],"ltp":0.0,"tv":0.0,"id":14819608}]}]}
{"op":"mcm","clk":"999962543","pt":1580603350739,"mc":[{"id":"1.168213438","rc":[{"batb":[[2,1.01,1.01]],"ltp":0.0,"tv":0.0,"id":13114902},{"batb":[[2,1.01,1.01]],"ltp":0.0,"tv":0.0,"id":13114898},{"batb":[[2,1.01,1.01]],"ltp":0.0,"tv":0.0,"id":14819609},{"batb":[[2,1.01,1.01]],"ltp":0.0,"tv":0.0,"id":14819608}]}]}
{"op":"mcm","clk":"1001027143","pt":1580626804624,"mc":[{"id":"1.168213438","rc":[{"batb":[[0,3.75,16.1]],"ltp":0.0,"tv":0.0,"id":13114902},{"batb":[[0,2.7,26.05]],"ltp":0.0,"tv":0.0,"id":13114898},{"batb":[[0,3.75,16.1]],"ltp":0.0,"tv":0.0,"id":14819609},{"batb":[[0,4.3,13.42]],"ltp":0.0,"tv":0.0,"id":14819608}]}]}
{"op":"mcm","clk":"1001142548","pt":1580629375699,"mc":[{"id":"1.168213438","rc":[{"batb":[[0,2.5,29.52]],"ltp":0.0,"tv":0.0,"id":13114898},{"batb":[[0,4,14.76]],"ltp":0.0,"tv":0.0,"id":14819609},{"batb":[[0,4.5,12.65]],"ltp":0.0,"tv":0.0,"id":14819608}]}]}
{"op":"mcm","clk":"1001145289","pt":1580629431715,"mc":[{"id":"1.168213438","rc":[{"batb":[[0,2.52,30.29],[1,2.5,29.52],[2,1.02,2]],"ltp":0.0,"tv":0.0,"id":13114898}]}]}
{"op":"mcm","clk":"1001172120","pt":1580630097364,"mc":[{"id":"1.168213438","rc":[{"batb":[[0,3.6,17.03]],"ltp":0.0,"tv":0.0,"id":13114902}]}]}
{"op":"mcm","clk":"1001328238","pt":1580633556851,"mc":[{"id":"1.168213438","rc":[{"batb":[[0,3.75,16.1]],"ltp":0.0,"tv":0.0,"id":13114902}]}]}
{"op":"mcm","clk":"1001910700","pt":1580641203875,"mc":[{"id":"1.168213438","rc":[{"batb":[[0,3.75,21.47]],"ltp":0.0,"tv":0.0,"id":13114902},{"batb":[[1,2.5,39.36]],"ltp":0.0,"tv":0.0,"id":13114898},{"batb":[[0,4,19.68]],"ltp":0.0,"tv":0.0,"id":14819609},{"batb":[[0,4.5,16.87]],"ltp":0.0,"tv":0.0,"id":14819608}]}]}
{"op":"mcm","clk":"1002053684","pt":1580642016063,"mc":[{"id":"1.168213438","rc":[{"batb":[[0,2.6,36.9],[1,2.52,30.29]],"ltp":0.0,"tv":0.0,"id":13114898},{"batb":[[0,3.75,21.47]],"ltp":0.0,"tv":0.0,"id":14819609}]}]}
{"op":"mcm","clk":"1002067339","pt":1580642092920,"mc":[{"id":"1.168213438","rc":[{"batb":[[1,1.02,2],[2,1.01,1.01]],"ltp":0.0,"tv":0.0,"id":13114898}]}]}
{"op":"mcm","clk":"1003032753","pt":1580647775584,"mc":[{"id":"1.168213438","rc":[{"batb":[[0,4.4,17.31],[1,3.75,21.47],[2,1.02,2]],"batl":[[0,5.2,16.52]],"ltp":0.0,"tv":0.0,"id":13114902},{"trd":[[2.6,33.2]],"batb":[[0,2.6,20.3],[1,2.38,16.92],[2,1.02,2]],"ltp":2.6,"tv":33.2,"id":13114898},{"batb":[[0,4.3,18.73],[1,3.75,21.47],[2,1.02,2]],"batl":[[0,5,17.86]],"ltp":0.0,"tv":0.0,"id":14819609},{"batb":[[0,5.3,11.33],[1,4.5,16.87],[2,1.02,2]],"batl":[[0,6.4,10.94]],"ltp":0.0,"tv":0.0,"id":14819608}],"tv":33.2}]}
{"op":"mcm","clk":"1003033475","pt":1580647779507,"mc":[{"id":"1.168213438","rc":[{"batb":[[0,2.6,36.9]],"ltp":2.6,"tv":33.2,"id":13114898}]}]}
{"op":"mcm","clk":"1003034239","pt":1580647783704,"mc":[{"id":"1.168213438","rc":[{"batb":[[0,4.5,17.62]],"batl":[[0,5.1,16.76]],"ltp":0.0,"tv":0.0,"id":13114902},{"trd":[[2.6,65.78]],"batb":[[0,2.6,20.61],[1,2.46,16.6]],"ltp":2.6,"tv":65.77,"id":13114898},{"batl":[[0,4.9,18.02]],"ltp":0.0,"tv":0.0,"id":14819609},{"batb":[[0,5.4,11.41]],"batl":[[0,6.2,11.02]],"ltp":0.0,"tv":0.0,"id":14819608}],"tv":65.77}]}
{"op":"mcm","clk":"1003034405","pt":1580647784515,"mc":[{"id":"1.168213438","rc":[{"batb":[[0,2.6,36.9]],"ltp":2.6,"tv":65.77,"id":13114898}]}]}
{"op":"mcm","clk":"1003036088","pt":1580647793633,"mc":[{"id":"1.168213438","rc":[{"batb":[[0,4.4,17.86]],"batl":[[0,5,17]],"ltp":0.0,"tv":0.0,"id":13114902},{"batb":[[1,2.48,16.29]],"batl":[[0,2.62,15.89]],"ltp":2.6,"tv":65.77,"id":13114898},{"batb":[[0,5.3,11.57]],"ltp":0.0,"tv":0.0,"id":14819608}]}]}
{"op":"mcm","clk":"1003056996","pt":1580647911731,"mc":[{"id":"1.168213438","marketDefinition":{"bspMarket":false,"turnInPlayEnabled":true,"persistenceEnabled":true,"marketBaseRate":5.0,"eventId":"29681204","eventTypeId":"2","numberOfWinners":1,"bettingType":"ODDS","marketType":"SET_BETTING","marketTime":"2020-02-02T12:47:00.000Z","suspendTime":"2020-02-02T12:47:00.000Z","bspReconciled":false,"complete":true,"inPlay":false,"crossMatching":true,"runnersVoidable":false,"numberOfActiveRunners":4,"betDelay":0,"status":"OPEN","runners":[{"status":"ACTIVE","sortPriority":1,"id":13114898,"name":"Golubev/Nedovyesov 2-0"},{"status":"ACTIVE","sortPriority":2,"id":13114902,"name":"Golubev/Nedovyesov 2-1"},{"status":"ACTIVE","sortPriority":3,"id":14819609,"name":"Sabanov/Sabanov 2-0"},{"status":"ACTIVE","sortPriority":4,"id":14819608,"name":"Sabanov/Sabanov 2-1"}],"regulators":["MR_INT"],"countryCode":"FR","discountAllowed":true,"timezone":"UTC","openDate":"2020-02-02T13:00:00.000Z","version":3148783605,"name":"Set Betting","eventName":"Golubev/Nedovyesov v Sabanov/Sabanov"}}]}
{"op":"mcm","clk":"1003057552","pt":1580647914747,"mc":[{"id":"1.168213438","marketDefinition":{"bspMarket":false,"turnInPlayEnabled":true,"persistenceEnabled":true,"marketBaseRate":5.0,"eventId":"29681204","eventTypeId":"2","numberOfWinners":1,"bettingType":"ODDS","marketType":"SET_BETTING","marketTime":"2020-02-02T12:47:00.000Z","suspendTime":"2020-02-02T12:47:00.000Z","bspReconciled":false,"complete":true,"inPlay":false,"crossMatching":true,"runnersVoidable":false,"numberOfActiveRunners":4,"betDelay":0,"status":"OPEN","runners":[{"status":"ACTIVE","sortPriority":1,"id":13114898,"name":"Golubev/Nedovyesov 2-0"},{"status":"ACTIVE","sortPriority":2,"id":13114902,"name":"Golubev/Nedovyesov 2-1"},{"status":"ACTIVE","sortPriority":3,"id":14819609,"name":"Sabanov/Sabanov 2-0"},{"status":"ACTIVE","sortPriority":4,"id":14819608,"name":"Sabanov/Sabanov 2-1"}],"regulators":["MR_INT"],"countryCode":"FR","discountAllowed":true,"timezone":"UTC","openDate":"2020-02-02T12:47:00.000Z","version":3148783605,"name":"Set Betting","eventName":"Golubev/Nedovyesov v Sabanov/Sabanov"}}]}
{"op":"mcm","clk":"1003082837","pt":1580648071590,"mc":[{"id":"1.168213438","rc":[{"trd":[[2.6,103.64]],"batb":[[0,2.6,17.97]],"ltp":2.6,"tv":103.63,"id":13114898}],"tv":103.63}]}
{"op":"mcm","clk":"1003083407","pt":1580648075144,"mc":[{"id":"1.168213438","rc":[{"batb":[[0,2.6,36.9]],"ltp":2.6,"tv":103.63,"id":13114898}]}]}
{"op":"mcm","clk":"1003122031","pt":1580648299738,"mc":[{"id":"1.168213438","rc":[{"batb":[[0,5.4,11.49],[1,5.3,11.57],[2,4.5,16.87]],"ltp":0.0,"tv":0.0,"id":14819608}]}]}
{"op":"mcm","clk":"1003122077","pt":1580648300051,"mc":[{"id":"1.168213438","rc":[{"batb":[[1,4.5,16.87],[2,1.02,2]],"ltp":0.0,"tv":0.0,"id":14819608}]}]}
{"op":"mcm","clk":"1003129552","pt":1580648347708,"mc":[{"id":"1.168213438","rc":[{"batb":[[0,4.5,2],[1,4.4,17.86],[2,3.75,21.47]],"ltp":0.0,"tv":0.0,"id":13114902},{"batb":[[0,4.4,2],[1,4.3,18.73],[2,3.75,21.47]],"ltp":0.0,"tv":0.0,"id":14819609},{"batb":[[0,5.5,2],[1,5.4,11.49],[2,4.5,16.87]],"ltp":0.0,"tv":0.0,"id":14819608}]}]}
{"op":"mcm","clk":"1003139585","pt":1580648407365,"mc":[{"id":"1.168213438","rc":[{"batb":[[0,4.4,17.86],[1,3.75,21.47],[2,1.02,2]],"ltp":0.0,"tv":0.0,"id":13114902},{"batb":[[0,4.3,18.73],[1,3.75,21.47],[2,1.02,2]],"ltp":0.0,"tv":0.0,"id":14819609},{"batb":[[0,5.4,11.49],[1,4.5,16.87],[2,1.02,2]],"ltp":0.0,"tv":0.0,"id":14819608}]}]}
{"op":"mcm","clk":"1003168208","pt":1580648568602,"mc":[{"id":"1.168213438","rc":[{"batb":[[0,3.75,21.47],[1,1.02,2],[2,1.01,1.01]],"ltp":0.0,"tv":0.0,"id":13114902},{"batb":[[1,1.02,2],[2,1.01,1.01]],"ltp":2.6,"tv":103.63,"id":13114898},{"batb":[[0,3.75,21.47],[1,1.02,2],[2,1.01,1.01]],"ltp":0.0,"tv":0.0,"id":14819609},{"batb":[[0,4.5,16.87],[1,1.02,2],[2,1.01,1.01]],"ltp":0.0,"tv":0.0,"id":14819608}]}]}
{"op":"mcm","clk":"1003168303","pt":1580648569134,"mc":[{"id":"1.168213438","marketDefinition":{"bspMarket":false,"turnInPlayEnabled":true,"persistenceEnabled":true,"marketBaseRate":5.0,"eventId":"29681204","eventTypeId":"2","numberOfWinners":1,"bettingType":"ODDS","marketType":"SET_BETTING","marketTime":"2020-02-02T12:47:00.000Z","suspendTime":"2020-02-02T12:47:00.000Z","bspReconciled":false,"complete":true,"inPlay":true,"crossMatching":true,"runnersVoidable":false,"numberOfActiveRunners":4,"betDelay":3,"status":"OPEN","runners":[{"status":"ACTIVE","sortPriority":1,"id":13114898,"name":"Golubev/Nedovyesov 2-0"},{"status":"ACTIVE","sortPriority":2,"id":13114902,"name":"Golubev/Nedovyesov 2-1"},{"status":"ACTIVE","sortPriority":3,"id":14819609,"name":"Sabanov/Sabanov 2-0"},{"status":"ACTIVE","sortPriority":4,"id":14819608,"name":"Sabanov/Sabanov 2-1"}],"regulators":["MR_INT"],"countryCode":"FR","discountAllowed":true,"timezone":"UTC","openDate":"2020-02-02T12:47:00.000Z","version":3148851635,"name":"Set Betting","eventName":"Golubev/Nedovyesov v Sabanov/Sabanov"},"rc":[{"batb":[[0,1.01,0.51],[1,1.02,0],[2,1.01,0]],"ltp":0.0,"tv":0.0,"id":13114902},{"batb":[[0,1.01,0.51],[1,1.02,0],[2,1.01,0]],"ltp":2.6,"tv":103.63,"id":13114898},{"batb":[[0,1.01,0.51],[1,1.02,0],[2,1.01,0]],"ltp":0.0,"tv":0.0,"id":14819609},{"batb":[[0,1.01,0.51],[1,1.02,0],[2,1.01,0]],"ltp":0.0,"tv":0.0,"id":14819608}]}]}
{"op":"mcm","clk":"1003171573","pt":1580648586356,"mc":[{"id":"1.168213438","rc":[{"batb":[[0,4.3,19.2],[1,1.01,0.51]],"batl":[[0,5,17.07]],"ltp":0.0,"tv":0.0,"id":13114902},{"batb":[[0,2.62,14.08],[1,2.4,17.7],[2,1.01,0.51]],"batl":[[0,2.78,13.77],[1,2.92,12.04]],"ltp":2.6,"tv":103.63,"id":13114898},{"batb":[[0,4,22.98],[1,3.8,13.14],[2,1.01,0.51]],"batl":[[0,4.5,21.72],[1,5.1,16.29]],"ltp":0.0,"tv":0.0,"id":14819609},{"batb":[[0,5.3,11.88],[1,1.01,0.51]],"batl":[[0,6.2,10.78]],"ltp":0.0,"tv":0.0,"id":14819608}]}]}
{"op":"mcm","clk":"1003172797","pt":1580648592505,"mc":[{"id":"1.168213438","rc":[{"batb":[[0,2.4,17.7],[1,1.01,0.51],[2,1.01,0]],"batl":[[0,2.92,12.04],[1,2.92,0]],"ltp":2.6,"tv":103.63,"id":13114898},{"batb":[[0,3.8,13.14],[1,1.01,0.51],[2,1.01,0]],"batl":[[0,5.1,16.29],[1,5.1,0]],"ltp":0.0,"tv":0.0,"id":14819609}]}]}
{"op":"mcm","clk":"1003176203","pt":1580648610517,"mc":[{"id":"1.168213438","rc":[{"batb":[[0,4.4,17.94],[1,4.3,18.8],[2,1.01,0.51]],"batl":[[1,5.2,15.66]],"ltp":0.0,"tv":0.0,"id":13114902},{"batb":[[1,2.16,23.6],[2,1.01,0.51]],"batl":[[0,2.54,17.31],[1,2.72,14.4]],"ltp":2.6,"tv":103.63,"id":13114898},{"batb":[[0,4.5,17.07],[1,4.1,21.4],[2,1.01,0.51]],"batl":[[1,6.2,11.09]],"ltp":0.0,"tv":0.0,"id":14819609},{"batb":[[0,5.4,11.49]],"batl":[[0,6.4,20.54]],"ltp":0.0,"tv":0.0,"id":14819608}]}]}
{"op":"mcm","clk":"1003179288","pt":1580648626271,"mc":[{"id":"1.168213438","rc":[{"batb":[[0,4.3,18.8],[1,1.01,0.51],[2,1.01,0]],"batl":[[0,5.2,15.66],[1,5.2,0]],"ltp":0.0,"tv":0.0,"id":13114902},{"batb":[[0,2.16,23.6],[1,1.01,0.51],[2,1.01,0]],"batl":[[0,2.72,14.4],[1,2.72,0]],"ltp":2.6,"tv":103.63,"id":13114898},{"batb":[[0,4.1,21.4],[1,1.01,0.51],[2,1.01,0]],"batl":[[0,6.2,11.09],[1,6.2,0]],"ltp":0.0,"tv":0.0,"id":14819609}]}]}
{"op":"mcm","clk":"1003181777","pt":1580648638658,"mc":[{"id":"1.168213438","rc":[{"batl":[[0,4.9,17.94],[1,5.1,16.76]],"ltp":0.0,"tv":0.0,"id":13114902},{"batb":[[0,2.58,14.71],[1,2.34,19.04],[2,1.01,0.51]],"batl":[[1,2.92,12.12]],"ltp":2.6,"tv":103.63,"id":13114898},{"batb":[[1,3.8,12.98],[2,1.01,0.51]],"batl":[[0,4.6,20.3],[1,5.3,14.87]],"ltp":0.0,"tv":0.0,"id":14819609},{"batb":[[0,5.3,11.72]],"batl":[[0,6.2,10.7]],"ltp":0.0,"tv":0.0,"id":14819608}]}]}
{"op":"mcm","clk":"1003184819","pt":1580648655212,"mc":[{"id":"1.168213438","rc":[{"batl":[[0,5.1,16.76],[1,5.1,0]],"ltp":0.0,"tv":0.0,"id":13114902},{"batb":[[0,2.34,19.04],[1,1.01,0.51],[2,1.01,0]],"batl":[[0,2.92,12.12],[1,2.92,0]],"ltp":2.6,"tv":103.63,"id":13114898},{"batb":[[0,3.8,12.98],[1,1.01,0.51],[2,1.01,0]],"batl":[[0,5.3,14.87],[1,5.3,0]],"ltp":0.0,"tv":0.0,"id":14819609}]}]}
{"op":"mcm","clk":"1003187289","pt":1580648669648,"mc":[{"id":"1.168213438","rc":[{"batb":[[0,4.2,19.75]],"batl":[[0,4.9,17.86]],"ltp":0.0,"tv":0.0,"id":13114902},{"batb":[[0,2.76,12.35],[1,2.56,15.03],[2,1.01,0.51]],"batl":[[1,3.05,10.86]],"ltp":2.6,"tv":103.63,"id":13114898},{"batb":[[1,3.65,14.4],[2,1.01,0.51]],"batl":[[0,4.3,24.55],[1,4.7,19.91]],"ltp":0.0,"tv":0.0,"id":14819609}]}]}
{"op":"mcm","clk":"1003190308","pt":1580648686041,"mc":[{"id":"1.168213438","rc":[{"batb":[[0,2.56,15.03],[1,1.01,0.51],[2,1.01,0]],"batl":[[0,3.05,10.86],[1,3.05,0]],"ltp":2.6,"tv":103.63,"id":13114898},{"batb":[[0,3.65,14.4],[1,1.01,0.51],[2,1.01,0]],"batl":[[0,4.7,19.91],[1,4.7,0]],"ltp":0.0,"tv":0.0,"id":14819609}]}]}
{"op":"mcm","clk":"1003190926","pt":1580648689427,"mc":[{"id":"1.168213438","rc":[{"batb":[[0,4.3,19.12]],"batl":[[0,5,17.31]],"ltp":0.0,"tv":0.0,"id":13114902},{"batb":[[0,2.58,14.56]],"batl":[[0,3.1,10.46]],"ltp":2.6,"tv":103.63,"id":13114898},{"batb":[[0,3.6,15.03]],"batl":[[0,4.6,20.77]],"ltp":0.0,"tv":0.0,"id":14819609},{"batb":[[0,5.2,12.35]],"ltp":0.0,"tv":0.0,"id":14819608}]}]}
{"op":"mcm","clk":"1003192018","pt":1580648695411,"mc":[{"id":"1.168213438","rc":[{"batb":[[0,4.2,20.3]],"batl":[[0,4.9,17.94]],"ltp":0.0,"tv":0.0,"id":13114902},{"batb":[[0,2.92,10.7],[1,2.76,12.35],[2,1.01,0.51]],"batl":[[1,3.55,18.96]],"ltp":2.6,"tv":103.63,"id":13114898},{"batb":[[1,3.2,19.83],[2,1.01,0.51]],"batl":[[0,3.95,14.56],[1,4.3,24.39]],"ltp":0.0,"tv":0.0,"id":14819609},{"batb":[[0,5.1,12.75]],"batl":[[0,5.9,11.8]],"ltp":0.0,"tv":0.0,"id":14819608}]}]}
{"op":"mcm","clk":"1003193585","pt":1580648703681,"mc":[{"id":"1.168213438","rc":[{"batb":[[0,4.3,18.8],[1,4.2,19.91],[2,1.01,0.51]],"batl":[[1,5,17.62]],"ltp":0.0,"tv":0.0,"id":13114902},{"batb":[[0,2.94,10.46],[1,2.78,12.12]],"batl":[[0,3.15,10.31],[1,3.6,18.65]],"ltp":2.6,"tv":103.63,"id":13114898},{"batb":[[0,3.55,15.34]],"batl":[[0,3.9,14.87],[1,4.2,24.94]],"ltp":0.0,"tv":0.0,"id":14819609}]}]}
{"op":"mcm","clk":"1003195003","pt":1580648711364,"mc":[{"id":"1.168213438","rc":[{"batb":[[1,1.01,0.51],[2,1.01,0]],"batl":[[0,4.9,17.7],[1,5,17.39]],"ltp":0.0,"tv":0.0,"id":13114902},{"batb":[[1,2.78,11.96]],"batl":[[0,3.15,25.02],[1,3.6,18.33]],"ltp":2.6,"tv":103.63,"id":13114898},{"batb":[[1,3.15,20.54]],"batl":[[0,3.85,15.11],[1,4.2,12.83]],"ltp":0.0,"tv":0.0,"id":14819609},{"batl":[[0,5.8,12.27]],"ltp":0.0,"tv":0.0,"id":14819608}]}]}
{"op":"mcm","clk":"1003200910","pt":1580648744438,"mc":[{"id":"1.168213438","rc":[{"batl":[[0,5,17.39],[1,5,0]],"ltp":0.0,"tv":0.0,"id":13114902},{"batb":[[0,2.78,11.96],[1,1.01,0.51],[2,1.01,0]],"batl":[[0,3.6,18.33],[1,3.6,0]],"ltp":2.6,"tv":103.63,"id":13114898},{"batb":[[0,3.15,20.54],[1,1.01,0.51],[2,1.01,0]],"batl":[[0,4.2,12.83],[1,4.2,0]],"ltp":0.0,"tv":0.0,"id":14819609}]}]}
{"op":"mcm","clk":"1003200962","pt":1580648744751,"mc":[{"id":"1.168213438","rc":[{"batb":[[0,3.15,20.38]],"ltp":0.0,"tv":0.0,"id":14819609}]}]}
{"op":"mcm","clk":"1003202418","pt":1580648752659,"mc":[{"id":"1.168213438","rc":[{"batb":[[1,2.64,13.85],[2,1.01,0.51]],"batl":[[0,2.94,11.88],[1,3.3,22.66],[2,3.6,18.33]],"ltp":2.6,"tv":103.63,"id":13114898},{"batb":[[0,3.8,13.06],[1,3.4,17.07],[2,3.15,20.38]],"batl":[[1,4.5,21.64]],"ltp":0.0,"tv":0.0,"id":14819609},{"batl":[[1,5.9,12.04]],"ltp":0.0,"tv":0.0,"id":14819608}]}]}
{"op":"mcm","clk":"1003202472","pt":1580648752923,"mc":[{"id":"1.168213438","rc":[{"batl":[[0,5,17]],"ltp":0.0,"tv":0.0,"id":13114902},{"batl":[[2,3.6,0]],"ltp":2.6,"tv":103.63,"id":13114898},{"batb":[[2,1.01,0.51]],"ltp":0.0,"tv":0.0,"id":14819609},{"batl":[[0,5.9,12.04],[1,5.9,0]],"ltp":0.0,"tv":0.0,"id":14819608}]}]}
{"op":"mcm","clk":"1003205264","pt":1580648768679,"mc":[{"id":"1.168213438","rc":[{"batb":[[0,2.64,13.85],[1,1.01,0.51],[2,1.01,0]],"batl":[[0,3.3,22.66],[1,3.3,0]],"ltp":2.6,"tv":103.63,"id":13114898},{"batb":[[0,3.4,17.07],[1,1.01,0.51],[2,1.01,0]],"batl":[[0,4.5,21.64],[1,4.5,0]],"ltp":0.0,"tv":0.0,"id":14819609}]}]}
{"op":"mcm","clk":"1003205823","pt":1580648771659,"mc":[{"id":"1.168213438","rc":[{"batl":[[1,3.35,22.27]],"ltp":2.6,"tv":103.63,"id":13114898}]}]}
{"op":"mcm","clk":"1003205879","pt":1580648771976,"mc":[{"id":"1.168213438","rc":[{"batb":[[0,2.64,13.69]],"batl":[[0,3.35,22.27],[1,3.35,0]],"ltp":2.6,"tv":103.63,"id":13114898},{"batl":[[0,5.9,11.88]],"ltp":0.0,"tv":0.0,"id":14819608}]}]}
{"op":"mcm","clk":"1003208487","pt":1580648785651,"mc":[{"id":"1.168213438","rc":[{"batb":[[0,4.4,18.41]],"ltp":0.0,"tv":0.0,"id":13114902},{"batb":[[1,2.56,15.11],[2,1.01,0.51]],"batl":[[0,2.8,13.45],[1,3.05,11.02]],"ltp":2.6,"tv":103.63,"id":13114898},{"batb":[[0,4,23.21],[1,3.7,14.08],[2,1.01,0.51]],"batl":[[1,4.7,19.51]],"ltp":0.0,"tv":0.0,"id":14819609},{"batl":[[1,6,11.8]],"ltp":0.0,"tv":0.0,"id":14819608}]}]}
{"op":"mcm","clk":"1003211497","pt":1580648801183,"mc":[{"id":"1.168213438","rc":[{"batb":[[0,2.56,15.11],[1,1.01,0.51],[2,1.01,0]],"batl":[[0,3.05,11.02],[1,3.05,0]],"ltp":2.6,"tv":103.63,"id":13114898},{"batb":[[0,3.7,14.08],[1,1.01,0.51],[2,1.01,0]],"batl":[[0,4.7,19.51],[1,4.7,0]],"ltp":0.0,"tv":0.0,"id":14819609},{"batl":[[0,6,11.8],[1,6,0]],"ltp":0.0,"tv":0.0,"id":14819608}]}]}
{"op":"mcm","clk":"1003213122","pt":1580648809629,"mc":[{"id":"1.168213438","rc":[{"batb":[[1,2.48,16.21],[2,1.01,0.51]],"batl":[[0,2.7,14.79],[1,2.86,12.75],[2,3.05,11.02]],"ltp":2.6,"tv":103.63,"id":13114898},{"batb":[[0,4.2,20.54],[1,3.9,24.31],[2,3.7,14.08]],"batl":[[1,4.9,17.7]],"ltp":0.0,"tv":0.0,"id":14819609}]}]}
{"op":"mcm","clk":"1003213167","pt":1580648809945,"mc":[{"id":"1.168213438","rc":[{"batb":[[0,4.4,18.1]],"ltp":0.0,"tv":0.0,"id":13114902},{"batl":[[2,3.05,0]],"ltp":2.6,"tv":103.63,"id":13114898},{"batb":[[2,1.01,0.51]],"ltp":0.0,"tv":0.0,"id":14819609},{"batl":[[0,6,11.64]],"ltp":0.0,"tv":0.0,"id":14819608}]}]}
{"op":"mcm","clk":"1003214941","pt":1580648819355,"mc":[{"id":"1.168213438","rc":[{"batb":[[0,2.48,16.21],[1,1.01,0.51],[2,1.01,0]],"batl":[[0,2.86,12.75],[1,2.86,0]],"ltp":2.6,"tv":103.63,"id":13114898},{"batb":[[0,3.9,24.31],[1,1.01,0.51],[2,1.01,0]],"batl":[[0,4.9,17.7],[1,4.9,0]],"ltp":0.0,"tv":0.0,"id":14819609}]}]}
{"op":"mcm","clk":"1003216510","pt":1580648827441,"mc":[{"id":"1.168213438","rc":[{"batl":[[0,5.2,15.74]],"ltp":0.0,"tv":0.0,"id":13114902},{"batb":[[1,2.24,21.32],[2,1.01,0.51]],"batl":[[0,2.62,15.97],[1,2.78,13.61]],"ltp":2.6,"tv":103.63,"id":13114898},{"batb":[[0,4.4,18.41],[1,4,22.42],[2,1.01,0.51]],"batl":[[0,5,17.55],[1,5.8,12.51]],"ltp":0.0,"tv":0.0,"id":14819609},{"batb":[[0,5.3,12.04],[1,5.2,12.27],[2,1.01,0.51]],"batl":[[0,6.2,11.09]],"ltp":0.0,"tv":0.0,"id":14819608}]}]}
{"op":"mcm","clk":"1003221404","pt":1580648854690,"mc":[{"id":"1.168213438","rc":[{"batb":[[0,2.24,21.32],[1,1.01,0.51],[2,1.01,0]],"batl":[[0,2.78,13.61],[1,2.78,0]],"ltp":2.6,"tv":103.63,"id":13114898},{"batb":[[0,4,22.42],[1,1.01,0.51],[2,1.01,0]],"batl":[[0,5.8,12.51],[1,5.8,0]],"ltp":0.0,"tv":0.0,"id":14819609},{"batb":[[0,5.2,12.27],[1,1.01,0.51],[2,1.01,0]],"ltp":0.0,"tv":0.0,"id":14819608}]}]}
{"op":"mcm","clk":"1003225439","pt":1580648876716,"mc":[{"id":"1.168213438","rc":[{"batb":[[0,4.6,16.52],[1,4.5,17.39],[2,4.4,18.1]],"batl":[[1,5.4,14.32]],"ltp":0.0,"tv":0.0,"id":13114902},{"batb":[[1,2.02,29.27],[2,1.01,0.51]],"batl":[[0,2.38,20.85],[1,2.54,17.15],[2,2.78,13.61]],"ltp":2.6,"tv":103.63,"id":13114898},{"batb":[[0,5.1,12.98],[1,4.5,16.92],[2,4,22.42]],"batl":[[1,7.4,14.95]],"ltp":0.0,"tv":0.0,"id":14819609},{"batb":[[0,5.4,11.49],[1,5.3,11.88],[2,5.2,12.27]],"batl":[[1,6.4,10.46]],"ltp":0.0,"tv":0.0,"id":14819608}]}]}
{"op":"mcm","clk":"1003225478","pt":1580648876931,"mc":[{"id":"1.168213438","rc":[{"batb":[[2,1.01,0.51]],"ltp":0.0,"tv":0.0,"id":13114902},{"batl":[[2,2.78,0]],"ltp":2.6,"tv":103.63,"id":13114898},{"batb":[[2,1.01,0.51]],"ltp":0.0,"tv":0.0,"id":14819609},{"batb":[[2,1.01,0.51]],"ltp":0.0,"tv":0.0,"id":14819608}]}]}
{"op":"mcm","clk":"1003228116","pt":1580648890648,"mc":[{"id":"1.168213438","rc":[{"batb":[[0,4.5,17.39],[1,1.01,0.51],[2,1.01,0]],"batl":[[0,5.4,14.32],[1,5.4,0]],"ltp":0.0,"tv":0.0,"id":13114902},{"batb":[[0,2.02,29.27],[1,1.01,0.51],[2,1.01,0]],"batl":[[0,2.54,17.15],[1,2.54,0]],"ltp":2.6,"tv":103.63,"id":13114898},{"batb":[[0,4.5,16.92],[1,1.01,0.51],[2,1.01,0]],"batl":[[0,7.4,14.95],[1,7.4,0]],"ltp":0.0,"tv":0.0,"id":14819609},{"batb":[[0,5.3,11.88],[1,1.01,0.51],[2,1.01,0]],"batl":[[0,6.4,10.46],[1,6.4,0]],"ltp":0.0,"tv":0.0,"id":14819608}]}]}
{"op":"mcm","clk":"1003231689","pt":1580648909549,"mc":[{"id":"1.168213438","rc":[{"batb":[[0,4.8,14.95],[1,4.6,15.97],[2,4.5,17.39]],"batl":[[1,5.7,12.98]],"ltp":0.0,"tv":0.0,"id":13114902},{"batb":[[1,1.83,19.67],[2,1.01,0.51]],"batl":[[0,2.12,28.4],[1,2.26,23.53],[2,2.54,17.15]],"ltp":2.6,"tv":103.63,"id":13114898},{"batb":[[0,6.2,15.97],[1,5.5,10.78],[2,4.5,16.92]],"batl":[[1,10.5,8.03]],"ltp":0.0,"tv":0.0,"id":14819609},{"batb":[[0,5.5,10.86],[1,5.4,11.33],[2,5.3,11.88]],"batl":[[1,6.6,19.28]],"ltp":0.0,"tv":0.0,"id":14819608}]}]}
{"op":"mcm","clk":"1003231737","pt":1580648909868,"mc":[{"id":"1.168213438","rc":[{"batb":[[2,1.01,0.51]],"ltp":0.0,"tv":0.0,"id":13114902},{"batl":[[2,2.54,0]],"ltp":2.6,"tv":103.63,"id":13114898},{"batb":[[2,1.01,0.51]],"ltp":0.0,"tv":0.0,"id":14819609},{"batb":[[2,1.01,0.51]],"ltp":0.0,"tv":0.0,"id":14819608}]}]}
{"op":"mcm","clk":"1003234253","pt":1580648923909,"mc":[{"id":"1.168213438","rc":[{"batb":[[0,4.6,15.97],[1,1.01,0.51],[2,1.01,0]],"batl":[[0,5.7,12.98],[1,5.7,0]],"ltp":0.0,"tv":0.0,"id":13114902},{"batb":[[0,1.83,19.67],[1,1.01,0.51],[2,1.01,0]],"batl":[[0,2.26,23.53],[1,2.26,0]],"ltp":2.6,"tv":103.63,"id":13114898},{"batb":[[0,5.5,10.78],[1,1.01,0.51],[2,1.01,0]],"batl":[[0,10.5,8.03],[1,10.5,0]],"ltp":0.0,"tv":0.0,"id":14819609},{"batb":[[0,5.4,11.33],[1,1.01,0.51],[2,1.01,0]],"batl":[[0,6.6,19.28],[1,6.6,0]],"ltp":0.0,"tv":0.0,"id":14819608}]}]}
{"op":"mcm","clk":"1003240916","pt":1580648960044,"mc":[{"id":"1.168213438","rc":[{"batb":[[1,4.5,17.07],[2,1.01,0.51]],"batl":[[0,5.3,15.26],[1,5.6,13.45]],"ltp":0.0,"tv":0.0,"id":13114902},{"batb":[[0,2.16,24.08],[1,1.91,17.15],[2,1.01,0.51]],"batl":[[1,2.48,18.65]],"ltp":2.6,"tv":103.63,"id":13114898},{"batb":[[1,4.8,14.95],[2,1.01,0.51]],"batl":[[0,6.4,10.39],[1,8.8,10.78]],"ltp":0.0,"tv":0.0,"id":14819609},{"batb":[[1,5.3,11.88],[2,1.01,0.51]],"batl":[[0,6.2,10.86],[1,6.4,10.31]],"ltp":0.0,"tv":0.0,"id":14819608}]}]}
{"op":"mcm","clk":"1003243457","pt":1580648973969,"mc":[{"id":"1.168213438","rc":[{"batb":[[0,4.5,17.07],[1,1.01,0.51],[2,1.01,0]],"batl":[[0,5.6,13.45],[1,5.6,0]],"ltp":0.0,"tv":0.0,"id":13114902},{"batb":[[0,1.91,17.15],[1,1.01,0.51],[2,1.01,0]],"batl":[[0,2.48,18.65],[1,2.48,0]],"ltp":2.6,"tv":103.63,"id":13114898},{"batb":[[0,4.8,14.95],[1,1.01,0.51],[2,1.01,0]],"batl":[[0,8.8,10.78],[1,8.8,0]],"ltp":0.0,"tv":0.0,"id":14819609},{"batb":[[0,5.3,11.88],[1,1.01,0.51],[2,1.01,0]],"batl":[[0,6.4,10.31],[1,6.4,0]],"ltp":0.0,"tv":0.0,"id":14819608}]}]}
{"op":"mcm","clk":"1003245168","pt":1580648983495,"mc":[{"id":"1.168213438","rc":[{"batb":[[0,4.9,14.01],[1,4.8,15.03],[2,4.5,17.07]],"batl":[[1,5.9,11.8]],"ltp":0.0,"tv":0.0,"id":13114902},{"batb":[[1,1.73,23.68],[2,1.01,0.51]],"batl":[[0,2,16.92],[1,2.14,27.62],[2,2.48,18.65]],"ltp":2.6,"tv":103.63,"id":13114898},{"batb":[[0,7.2,11.33],[1,6.2,16.44],[2,4.8,14.95]],"batl":[[1,13,12.35]],"ltp":0.0,"tv":0.0,"id":14819609},{"batb":[[0,5.5,10.7],[1,5.4,11.17],[2,5.3,11.88]],"batl":[[1,6.8,18.65]],"ltp":0.0,"tv":0.0,"id":14819608}]}]}
{"op":"mcm","clk":"1003245228","pt":1580648983757,"mc":[{"id":"1.168213438","rc":[{"batb":[[2,1.01,0.51]],"ltp":0.0,"tv":0.0,"id":13114902},{"batl":[[2,2.48,0]],"ltp":2.6,"tv":103.63,"id":13114898},{"batb":[[2,1.01,0.51]],"ltp":0.0,"tv":0.0,"id":14819609},{"batb":[[2,1.01,0.51]],"ltp":0.0,"tv":0.0,"id":14819608}]}]}
{"op":"mcm","clk":"1003248005","pt":1580648999756,"mc":[{"id":"1.168213438","rc":[{"batb":[[0,4.8,15.03],[1,1.01,0.51],[2,1.01,0]],"batl":[[0,5.9,11.8],[1,5.9,0]],"ltp":0.0,"tv":0.0,"id":13114902},{"batb":[[0,1.73,23.68],[1,1.01,0.51],[2,1.01,0]],"batl":[[0,2.14,27.62],[1,2.14,0]],"ltp":2.6,"tv":103.63,"id":13114898},{"batb":[[0,6.2,16.44],[1,1.01,0.51],[2,1.01,0]],"batl":[[0,13,12.35],[1,13,0]],"ltp":0.0,"tv":0.0,"id":14819609},{"batb":[[0,5.4,11.17],[1,1.01,0.51],[2,1.01,0]],"batl":[[0,6.8,18.65],[1,6.8,0]],"ltp":0.0,"tv":0.0,"id":14819608}]}]}
{"op":"mcm","clk":"1003249678","pt":1580649008385,"mc":[{"id":"1.168213438","rc":[{"batb":[[1,4.5,16.92],[2,1.01,0.51]],"batl":[[0,5.4,14.4],[1,5.9,11.8]],"ltp":0.0,"tv":0.0,"id":13114902},{"batb":[[0,2.04,28.4],[1,1.76,22.58],[2,1.01,0.51]],"batl":[[1,2.38,20.54]],"ltp":2.6,"tv":103.63,"id":13114898},{"batb":[[1,5.1,13.06],[2,1.01,0.51]],"batl":[[0,7.4,15.42],[1,12.5,13.22]],"ltp":0.0,"tv":0.0,"id":14819609},{"batb":[[1,5.3,11.49],[2,1.01,0.51]],"batl":[[0,6.6,19.43]],"ltp":0.0,"tv":0.0,"id":14819608}]}]}
{"op":"mcm","clk":"1003251754","pt":1580649018906,"mc":[{"id":"1.168213438","rc":[{"batb":[[0,4.5,16.92],[1,1.01,0.51],[2,1.01,0]],"batl":[[0,5.9,11.8],[1,5.9,0]],"ltp":0.0,"tv":0.0,"id":13114902},{"batb":[[0,1.76,22.58],[1,1.01,0.51],[2,1.01,0]],"batl":[[0,2.38,20.54],[1,2.38,0]],"ltp":2.6,"tv":103.63,"id":13114898},{"batb":[[0,5.1,13.06],[1,1.01,0.51],[2,1.01,0]],"batl":[[0,12.5,13.22],[1,12.5,0]],"ltp":0.0,"tv":0.0,"id":14819609},{"batb":[[0,5.3,11.49],[1,1.01,0.51],[2,1.01,0]],"ltp":0.0,"tv":0.0,"id":14819608}]}]}
{"op":"mcm","clk":"1003253430","pt":1580649027464,"mc":[{"id":"1.168213438","rc":[{"batb":[[1,4.3,19.51],[2,1.01,0.51]],"batl":[[0,5.1,16.13],[1,5.8,12.35]],"ltp":0.0,"tv":0.0,"id":13114902},{"batb":[[0,2.26,21.01],[1,1.78,21.4],[2,1.01,0.51]],"batl":[[1,2.86,12.75]],"ltp":2.6,"tv":103.63,"id":13114898},{"batb":[[1,3.95,23.53],[2,1.01,0.51]],"batl":[[0,5.8,12.51],[1,12,14.32]],"ltp":0.0,"tv":0.0,"id":14819609},{"batb":[[1,5.2,12.2],[2,1.01,0.51]],"batl":[[0,6.2,11.09],[1,6.4,10.39]],"ltp":0.0,"tv":0.0,"id":14819608}]}]}
{"op":"mcm","clk":"1003255792","pt":1580649039786,"mc":[{"id":"1.168213438","rc":[{"batb":[[0,4.3,19.51],[1,1.01,0.51],[2,1.01,0]],"batl":[[0,5.8,12.35],[1,5.8,0]],"ltp":0.0,"tv":0.0,"id":13114902},{"batb":[[0,1.78,21.4],[1,1.01,0.51],[2,1.01,0]],"batl":[[0,2.86,12.75],[1,2.86,0]],"ltp":2.6,"tv":103.63,"id":13114898},{"batb":[[0,3.95,23.53],[1,1.01,0.51],[2,1.01,0]],"batl":[[0,12,14.32],[1,12,0]],"ltp":0.0,"tv":0.0,"id":14819609},{"batb":[[0,5.2,12.2],[1,1.01,0.51],[2,1.01,0]],"batl":[[0,6.4,10.39],[1,6.4,0]],"ltp":0.0,"tv":0.0,"id":14819608}]}]}
{"op":"mcm","clk":"1003257543","pt":1580649048555,"mc":[{"id":"1.168213438","rc":[{"batb":[[0,5.1,12.83],[1,4.9,14.08],[2,1.01,0.51]],"batl":[[1,5.9,11.96]],"ltp":0.0,"tv":0.0,"id":13114902},{"batb":[[1,1.72,24],[2,1.01,0.51]],"batl":[[0,1.86,21.09],[1,2.02,16.52]],"ltp":2.6,"tv":103.63,"id":13114898},{"batb":[[0,9.4,15.82],[1,7.4,10.78],[2,1.01,0.51]],"batl":[[1,14.5,10.46]],"ltp":0.0,"tv":0.0,"id":14819609},{"batb":[[0,5.5,10.78],[1,5.3,11.49],[2,1.01,0.51]],"batl":[[1,6.6,19.51]],"ltp":0.0,"tv":0.0,"id":14819608}]}]}
{"op":"mcm","clk":"1003273727","pt":1580649130936,"mc":[{"id":"1.168213438","rc":[{"batb":[[0,4.9,14.08],[1,1.01,0.51],[2,1.01,0]],"batl":[[0,5.9,11.96],[1,5.9,0]],"ltp":0.0,"tv":0.0,"id":13114902},{"batb":[[0,1.72,24],[1,1.01,0.51],[2,1.01,0]],"batl":[[0,2.02,16.52],[1,2.02,0]],"ltp":2.6,"tv":103.63,"id":13114898},{"batb":[[0,7.4,10.78],[1,1.01,0.51],[2,1.01,0]],"batl":[[0,14.5,10.46],[1,14.5,0]],"ltp":0.0,"tv":0.0,"id":14819609},{"batb":[[0,5.3,11.49],[1,1.01,0.51],[2,1.01,0]],"batl":[[0,6.6,19.51],[1,6.6,0]],"ltp":0.0,"tv":0.0,"id":14819608}]}]}
{"op":"mcm","clk":"1003277975","pt":1580649152320,"mc":[{"id":"1.168213438","rc":[{"batb":[[1,4.7,15.5],[2,1.01,0.51]],"batl":[[0,5.6,13.45],[1,5.7,12.67]],"ltp":0.0,"tv":0.0,"id":13114902},{"batb":[[0,1.93,16.84],[1,1.83,19.91],[2,1.01,0.51]],"batl":[[1,2.24,24.16]],"ltp":2.6,"tv":103.63,"id":13114898},{"batb":[[1,5.7,20.22],[2,1.01,0.51]],"batl":[[0,9,10.23],[1,11,7.08]],"ltp":0.0,"tv":0.0,"id":14819609},{"batl":[[0,6.2,10.62]],"ltp":0.0,"tv":0.0,"id":14819608}]}]}
{"op":"mcm","clk":"1003281455","pt":1580649170899,"mc":[{"id":"1.168213438","rc":[{"batb":[[0,4.7,15.5],[1,1.01,0.51],[2,1.01,0]],"batl":[[0,5.7,12.67],[1,5.7,0]],"ltp":0.0,"tv":0.0,"id":13114902},{"batb":[[0,1.83,19.91],[1,1.01,0.51],[2,1.01,0]],"batl":[[0,2.24,24.16],[1,2.24,0]],"ltp":2.6,"tv":103.63,"id":13114898},{"batb":[[0,5.7,20.22],[1,1.01,0.51],[2,1.01,0]],"batl":[[0,11,7.08],[1,11,0]],"ltp":0.0,"tv":0.0,"id":14819609}]}]}
{"op":"mcm","clk":"1003283045","pt":1580649179717,"mc":[{"id":"1.168213438","rc":[{"batb":[[0,5,13.22],[1,4.8,14.71],[2,1.01,0.51]],"batl":[[1,5.8,12.27]],"ltp":0.0,"tv":0.0,"id":13114902},{"batb":[[1,1.75,22.66],[2,1.01,0.51]],"batl":[[0,1.9,19.59],[1,2.12,28.72]],"ltp":2.6,"tv":103.63,"id":13114898},{"batb":[[0,8.8,7.4],[1,6.6,14.24],[2,1.01,0.51]],"batl":[[1,13.5,11.57]],"ltp":0.0,"tv":0.0,"id":14819609},{"batb":[[0,5.4,11.02],[1,5.3,11.49],[2,1.01,0.51]],"batl":[[1,6.4,10.39]],"ltp":0.0,"tv":0.0,"id":14819608}]}]}
{"op":"mcm","clk":"1003285817","pt":1580649194631,"mc":[{"id":"1.168213438","rc":[{"batb":[[0,4.8,14.71],[1,1.01,0.51],[2,1.01,0]],"batl":[[0,5.8,12.27],[1,5.8,0]],"ltp":0.0,"tv":0.0,"id":13114902},{"batb":[[0,1.75,22.66],[1,1.01,0.51],[2,1.01,0]],"batl":[[0,2.12,28.72],[1,2.12,0]],"ltp":2.6,"tv":103.63,"id":13114898},{"batb":[[0,6.6,14.24],[1,1.01,0.51],[2,1.01,0]],"batl":[[0,13.5,11.57],[1,13.5,0]],"ltp":0.0,"tv":0.0,"id":14819609},{"batb":[[0,5.3,11.49],[1,1.01,0.51],[2,1.01,0]],"batl":[[0,6.4,10.39],[1,6.4,0]],"ltp":0.0,"tv":0.0,"id":14819608}]}]}
{"op":"mcm","clk":"1003288065","pt":1580649207670,"mc":[{"id":"1.168213438","rc":[{"batb":[[1,4.6,16.6],[2,1.01,0.51]],"batl":[[0,5.5,14.08],[1,5.6,13.38],[2,5.8,12.27]],"ltp":0.0,"tv":0.0,"id":13114902},{"batb":[[0,2,29.58],[1,1.89,17.94],[2,1.75,22.66]],"batl":[[1,2.42,19.59]],"ltp":2.6,"tv":103.63,"id":13114898},{"batb":[[1,5,13.53],[2,1.01,0.51]],"batl":[[0,7.8,13.38],[1,9.8,8.66],[2,13.5,11.57]],"ltp":0.0,"tv":0.0,"id":14819609},{"batb":[[1,5.2,12.27],[2,1.01,0.51]],"batl":[[0,6,11.33],[1,6.2,11.02],[2,6.4,10.39]],"ltp":0.0,"tv":0.0,"id":14819608}]}]}
{"op":"mcm","clk":"1003288099","pt":1580649207869,"mc":[{"id":"1.168213438","rc":[{"batl":[[2,5.8,0]],"ltp":0.0,"tv":0.0,"id":13114902},{"batb":[[2,1.01,0.51]],"ltp":2.6,"tv":103.63,"id":13114898},{"batl":[[2,13.5,0]],"ltp":0.0,"tv":0.0,"id":14819609},{"batl":[[2,6.4,0]],"ltp":0.0,"tv":0.0,"id":14819608}]}]}
{"op":"mcm","clk":"1003291268","pt":1580649225213,"mc":[{"id":"1.168213438","rc":[{"batb":[[0,4.6,16.6],[1,1.01,0.51],[2,1.01,0]],"batl":[[0,5.6,13.38],[1,5.6,0]],"ltp":0.0,"tv":0.0,"id":13114902},{"batb":[[0,1.89,17.94],[1,1.01,0.51],[2,1.01,0]],"batl":[[0,2.42,19.59],[1,2.42,0]],"ltp":2.6,"tv":103.63,"id":13114898},{"batb":[[0,5,13.53],[1,1.01,0.51],[2,1.01,0]],"batl":[[0,9.8,8.66],[1,9.8,0]],"ltp":0.0,"tv":0.0,"id":14819609},{"batb":[[0,5.2,12.27],[1,1.01,0.51],[2,1.01,0]],"batl":[[0,6.2,11.02],[1,6.2,0]],"ltp":0.0,"tv":0.0,"id":14819608}]}]}
{"op":"mcm","clk":"1003293656","pt":1580649238198,"mc":[{"id":"1.168213438","rc":[{"batb":[[0,4.9,13.93],[1,4.7,15.66],[2,1.01,0.51]],"batl":[[1,5.7,12.67]],"ltp":0.0,"tv":0.0,"id":13114902},{"batb":[[1,1.78,21.64],[2,1.01,0.51]],"batl":[[0,1.96,17.7],[1,2.26,23.68]],"ltp":2.6,"tv":103.63,"id":13114898},{"batb":[[0,8,9.05],[1,5.6,20.3],[2,1.01,0.51]],"batl":[[1,13,12.35]],"ltp":0.0,"tv":0.0,"id":14819609},{"batl":[[0,6.2,10.78]],"ltp":0.0,"tv":0.0,"id":14819608}]}]}
{"op":"mcm","clk":"1003294327","pt":1580649242047,"mc":[{"id":"1.168213438","rc":[{"batb":[[0,4.7,15.66],[1,1.01,0.51],[2,1.01,0]],"batl":[[0,5.7,12.67],[1,5.7,0]],"ltp":0.0,"tv":0.0,"id":13114902},{"batb":[[0,1.78,21.64],[1,1.01,0.51],[2,1.01,0]],"batl":[[0,2.26,23.68],[1,2.26,0]],"ltp":2.6,"tv":103.63,"id":13114898},{"batb":[[0,5.6,20.3],[1,1.01,0.51],[2,1.01,0]],"batl":[[0,13,12.35],[1,13,0]],"ltp":0.0,"tv":0.0,"id":14819609}]}]}
{"op":"mcm","clk":"1003299780","pt":1580649271696,"mc":[{"id":"1.168213438","rc":[{"batb":[[0,5,13.22],[1,4.8,14.4],[2,1.01,0.51]],"batl":[[1,5.9,11.88]],"ltp":0.0,"tv":0.0,"id":13114902},{"batb":[[1,1.7,25.26],[2,1.01,0.51]],"batl":[[0,1.85,21.24],[1,2.06,15.66]],"ltp":2.6,"tv":103.63,"id":13114898},{"batb":[[0,10,13.53],[1,7.2,11.64],[2,1.01,0.51]],"batl":[[1,17,7.63]],"ltp":0.0,"tv":0.0,"id":14819609},{"batb":[[0,5.4,11.17],[1,5.2,12.04],[2,1.01,0.51]],"batl":[[1,6.4,10.39]],"ltp":0.0,"tv":0.0,"id":14819608}]}]}
{"op":"mcm","clk":"1003303776","pt":1580649293064,"mc":[{"id":"1.168213438","rc":[{"batb":[[0,4.8,14.4],[1,1.01,0.51],[2,1.01,0]],"batl":[[0,5.9,11.88],[1,5.9,0]],"ltp":0.0,"tv":0.0,"id":13114902},{"batb":[[0,1.7,25.26],[1,1.01,0.51],[2,1.01,0]],"batl":[[0,2.06,15.66],[1,2.06,0]],"ltp":2.6,"tv":103.63,"id":13114898},{"batb":[[0,7.2,11.64],[1,1.01,0.51],[2,1.01,0]],"batl":[[0,17,7.63],[1,17,0]],"ltp":0.0,"tv":0.0,"id":14819609},{"batb":[[0,5.2,12.04],[1,1.01,0.51],[2,1.01,0]],"batl":[[0,6.4,10.39],[1,6.4,0]],"ltp":0.0,"tv":0.0,"id":14819608}]}]}
{"op":"mcm","clk":"1003308364","pt":1580649317546,"mc":[{"id":"1.168213438","rc":[{"batb":[[0,5.2,12.35],[1,5.1,12.9],[2,1.01,0.51]],"batl":[[1,6.2,11.09]],"ltp":0.0,"tv":0.0,"id":13114902},{"batb":[[1,1.63,29.35],[2,1.01,0.51]],"batl":[[0,1.77,24.78],[1,1.81,22.74]],"ltp":2.6,"tv":103.63,"id":13114898},{"batb":[[0,12.5,8.18],[1,11,10.54],[2,1.01,0.51]],"batl":[[1,22,4.72]],"ltp":0.0,"tv":0.0,"id":14819609},{"batb":[[0,5.5,10.78],[1,5.4,11.17],[2,1.01,0.51]],"batl":[[1,6.6,18.96]],"ltp":0.0,"tv":0.0,"id":14819608}]}]}
{"op":"mcm","clk":"1003313716","pt":1580649350292,"mc":[{"id":"1.168213438","rc":[{"batb":[[0,5.1,12.9],[1,1.01,0.51],[2,1.01,0]],"batl":[[0,6.2,11.09],[1,6.2,0]],"ltp":0.0,"tv":0.0,"id":13114902},{"batb":[[0,1.63,29.35],[1,1.01,0.51],[2,1.01,0]],"batl":[[0,1.81,22.74],[1,1.81,0]],"ltp":2.6,"tv":103.63,"id":13114898},{"batb":[[0,11,10.54],[1,1.01,0.51],[2,1.01,0]],"batl":[[0,22,4.72],[1,22,0]],"ltp":0.0,"tv":0.0,"id":14819609},{"batb":[[0,5.4,11.17],[1,1.01,0.51],[2,1.01,0]],"batl":[[0,6.6,18.96],[1,6.6,0]],"ltp":0.0,"tv":0.0,"id":14819608}]}]}
{"op":"mcm","clk":"1003315623","pt":1580649361409,"mc":[{"id":"1.168213438","rc":[{"batb":[[1,5,13.22],[2,1.01,0.51]],"batl":[[0,5.8,12.35],[1,6,11.41]],"ltp":0.0,"tv":0.0,"id":13114902},{"batb":[[0,1.74,23.13],[1,1.67,26.52],[2,1.01,0.51]],"batl":[[1,1.86,20.93]],"ltp":2.6,"tv":103.63,"id":13114898},{"batb":[[1,10,12.83],[2,1.01,0.51]],"batl":[[0,15,9.76],[1,18,6.85]],"ltp":0.0,"tv":0.0,"id":14819609},{"batb":[[1,5.3,11.88],[2,1.01,0.51]],"batl":[[0,6.2,10.78],[1,6.4,20.3]],"ltp":0.0,"tv":0.0,"id":14819608}]}]}
{"op":"mcm","clk":"1003318642","pt":1580649377847,"mc":[{"id":"1.168213438","rc":[{"batb":[[0,5,13.22],[1,1.01,0.51],[2,1.01,0]],"batl":[[0,6,11.41],[1,6,0]],"ltp":0.0,"tv":0.0,"id":13114902},{"batb":[[0,1.67,26.52],[1,1.01,0.51],[2,1.01,0]],"batl":[[0,1.86,20.93],[1,1.86,0]],"ltp":2.6,"tv":103.63,"id":13114898},{"batb":[[0,10,12.83],[1,1.01,0.51],[2,1.01,0]],"batl":[[0,18,6.85],[1,18,0]],"ltp":0.0,"tv":0.0,"id":14819609},{"batb":[[0,5.3,11.88],[1,1.01,0.51],[2,1.01,0]],"batl":[[0,6.4,20.3],[1,6.4,0]],"ltp":0.0,"tv":0.0,"id":14819608}]}]}
{"op":"mcm","clk":"1003320758","pt":1580649389326,"mc":[{"id":"1.168213438","rc":[{"batl":[[0,5.7,12.75],[1,5.9,12.12]],"ltp":0.0,"tv":0.0,"id":13114902},{"batb":[[0,1.79,21.24],[1,1.72,24],[2,1.01,0.51]],"batl":[[1,1.9,19.51]],"ltp":2.6,"tv":103.63,"id":13114898},{"batb":[[1,9.6,14.79],[2,1.01,0.51]],"batl":[[0,13.5,11.72],[1,15.5,8.97]],"ltp":0.0,"tv":0.0,"id":14819609},{"batb":[[1,5.2,12.35],[2,1.01,0.51]],"batl":[[0,6,11.41],[1,6.2,10.54]],"ltp":0.0,"tv":0.0,"id":14819608}]}]}
{"op":"mcm","clk":"1003323656","pt":1580649404506,"mc":[{"id":"1.168213438","rc":[{"batl":[[0,5.9,12.12],[1,5.9,0]],"ltp":0.0,"tv":0.0,"id":13114902},{"batb":[[0,1.72,24],[1,1.01,0.51],[2,1.01,0]],"batl":[[0,1.9,19.51],[1,1.9,0]],"ltp":2.6,"tv":103.63,"id":13114898},{"batb":[[0,9.6,14.79],[1,1.01,0.51],[2,1.01,0]],"batl":[[0,15.5,8.97],[1,15.5,0]],"ltp":0.0,"tv":0.0,"id":14819609},{"batb":[[0,5.2,12.35],[1,1.01,0.51],[2,1.01,0]],"batl":[[0,6.2,10.54],[1,6.2,0]],"ltp":0.0,"tv":0.0,"id":14819608}]}]}
{"op":"mcm","clk":"1003327321","pt":1580649424636,"mc":[{"id":"1.168213438","rc":[{"batb":[[0,5.1,12.59],[1,5,13.22],[2,1.01,0.51]],"batl":[[1,6,11.33]],"ltp":0.0,"tv":0.0,"id":13114902},{"batb":[[1,1.65,28.09],[2,1.01,0.51]],"batl":[[0,1.79,23.6],[1,1.85,21.32]],"ltp":2.6,"tv":103.63,"id":13114898},{"batb":[[0,11.5,9.68],[1,10,12.75],[2,1.01,0.51]],"batl":[[1,20,5.82]],"ltp":0.0,"tv":0.0,"id":14819609},{"batb":[[0,5.4,11.02],[1,5.3,11.49],[2,1.01,0.51]],"batl":[[0,6.6,19.12]],"ltp":0.0,"tv":0.0,"id":14819608}]}]}
{"op":"mcm","clk":"1003331256","pt":1580649446309,"mc":[{"id":"1.168213438","rc":[{"batb":[[0,5,13.22],[1,1.01,0.51],[2,1.01,0]],"batl":[[0,6,11.33],[1,6,0]],"ltp":0.0,"tv":0.0,"id":13114902},{"batb":[[0,1.65,28.09],[1,1.01,0.51],[2,1.01,0]],"batl":[[0,1.85,21.32],[1,1.85,0]],"ltp":2.6,"tv":103.63,"id":13114898},{"batb":[[0,10,12.75],[1,1.01,0.51],[2,1.01,0]],"batl":[[0,20,5.82],[1,20,0]],"ltp":0.0,"tv":0.0,"id":14819609},{"batb":[[0,5.3,11.49],[1,1.01,0.51],[2,1.01,0]],"ltp":0.0,"tv":0.0,"id":14819608}]}]}
{"op":"mcm","clk":"1003333457","pt":1580649459697,"mc":[{"id":"1.168213438","rc":[{"batb":[[0,5.3,11.72],[1,5.1,12.59],[2,5,13.22]],"batl":[[1,6.4,10.39]],"ltp":0.0,"tv":0.0,"id":13114902},{"batb":[[1,1.56,34.07],[2,1.01,0.51]],"batl":[[0,1.71,27.46],[1,1.78,24],[2,1.85,21.32]],"ltp":2.6,"tv":103.63,"id":13114898},{"batb":[[0,14,6.14],[1,11.5,9.44],[2,10,12.75]],"ltp":0.0,"tv":0.0,"id":14819609},{"batb":[[0,5.6,20.54],[1,5.5,10.7],[2,5.3,11.49]],"batl":[[1,6.8,17.78]],"ltp":0.0,"tv":0.0,"id":14819608}]}]}
{"op":"mcm","clk":"1003333486","pt":1580649459909,"mc":[{"id":"1.168213438","rc":[{"batb":[[2,1.01,0.51]],"ltp":0.0,"tv":0.0,"id":13114902},{"batl":[[2,1.85,0]],"ltp":2.6,"tv":103.63,"id":13114898},{"batb":[[2,1.01,0.51]],"ltp":0.0,"tv":0.0,"id":14819609},{"batb":[[2,1.01,0.51]],"ltp":0.0,"tv":0.0,"id":14819608}]}]}
{"op":"mcm","clk":"1003337769","pt":1580649483870,"mc":[{"id":"1.168213438","rc":[{"batb":[[0,5.1,12.59],[1,1.01,0.51],[2,1.01,0]],"batl":[[0,6.4,10.39],[1,6.4,0]],"ltp":0.0,"tv":0.0,"id":13114902},{"batb":[[0,1.56,34.07],[1,1.01,0.51],[2,1.01,0]],"batl":[[0,1.78,24],[1,1.78,0]],"ltp":2.6,"tv":103.63,"id":13114898},{"batb":[[0,11.5,9.44],[1,1.01,0.51],[2,1.01,0]],"ltp":0.0,"tv":0.0,"id":14819609},{"batb":[[0,5.5,10.7],[1,1.01,0.51],[2,1.01,0]],"batl":[[0,6.8,17.78],[1,6.8,0]],"ltp":0.0,"tv":0.0,"id":14819608}]}]}
{"op":"mcm","clk":"1003339674","pt":1580649494076,"mc":[{"id":"1.168213438","rc":[{"batb":[[1,5,13.14],[2,1.01,0.51]],"batl":[[0,5.9,12.12],[1,6.2,11.09]],"ltp":0.0,"tv":0.0,"id":13114902},{"batb":[[0,1.71,24.47],[1,1.63,29.27],[2,1.01,0.51]],"batl":[[1,1.85,21.4]],"ltp":2.6,"tv":103.63,"id":13114898},{"batb":[[1,10,13.14],[2,1.01,0.51]],"batl":[[0,16,8.73],[1,22,4.88]],"ltp":0.0,"tv":0.0,"id":14819609},{"batb":[[1,5.4,11.25],[2,1.01,0.51]],"batl":[[0,6.4,10.31],[1,6.6,18.88]],"ltp":0.0,"tv":0.0,"id":14819608}]}]}
{"op":"mcm","clk":"1003342391","pt":1580649509975,"mc":[{"id":"1.168213438","rc":[{"batb":[[0,5,13.14],[1,1.01,0.51],[2,1.01,0]],"batl":[[0,6.2,11.09],[1,6.2,0]],"ltp":0.0,"tv":0.0,"id":13114902},{"batb":[[0,1.63,29.27],[1,1.01,0.51],[2,1.01,0]],"batl":[[0,1.85,21.4],[1,1.85,0]],"ltp":2.6,"tv":103.63,"id":13114898},{"batb":[[0,10,13.14],[1,1.01,0.51],[2,1.01,0]],"batl":[[0,22,4.88],[1,22,0]],"ltp":0.0,"tv":0.0,"id":14819609},{"batb":[[0,5.4,11.25],[1,1.01,0.51],[2,1.01,0]],"batl":[[0,6.6,18.88],[1,6.6,0]],"ltp":0.0,"tv":0.0,"id":14819608}]}]}
{"op":"mcm","clk":"1003344252","pt":1580649520128,"mc":[{"id":"1.168213438","rc":[{"batb":[[1,4.9,14.24],[2,1.01,0.51]],"batl":[[0,5.8,12.59],[1,5.9,11.96]],"ltp":0.0,"tv":0.0,"id":13114902},{"batb":[[0,1.78,21.79],[1,1.71,24.78],[2,1.01,0.51]],"batl":[[1,2.02,16.6]],"ltp":2.6,"tv":103.63,"id":13114898},{"batb":[[1,7.6,9.91],[2,1.01,0.51]],"batl":[[0,13.5,11.96],[1,17,7.79]],"ltp":0.0,"tv":0.0,"id":14819609},{"batb":[[0,5.2,11.96]],"batl":[[0,6.2,10.62]],"ltp":0.0,"tv":0.0,"id":14819608}]}]}
{"op":"mcm","clk":"1003359171","pt":1580649614406,"mc":[{"id":"1.168213438","rc":[{"batb":[[0,4.9,14.24],[1,1.01,0.51],[2,1.01,0]],"batl":[[0,5.9,11.96],[1,5.9,0]],"ltp":0.0,"tv":0.0,"id":13114902},{"batb":[[0,1.71,24.78],[1,1.01,0.51],[2,1.01,0]],"batl":[[0,2.02,16.6],[1,2.02,0]],"ltp":2.6,"tv":103.63,"id":13114898},{"batb":[[0,7.6,9.91],[1,1.01,0.51],[2,1.01,0]],"batl":[[0,17,7.79],[1,17,0]],"ltp":0.0,"tv":0.0,"id":14819609}]}]}
{"op":"mcm","clk":"1003362270","pt":1580649633724,"mc":[{"id":"1.168213438","rc":[{"batb":[[0,5,13.69]],"batl":[[1,6,11.57]],"ltp":0.0,"tv":0.0,"id":13114902},{"batb":[[1,1.65,27.62],[2,1.01,0.51]],"batl":[[0,1.78,24.31],[1,1.91,19.43]],"ltp":2.6,"tv":103.63,"id":13114898},{"batb":[[0,12.5,8.34],[1,9.2,16.37],[2,1.01,0.51]],"batl":[[1,21,5.35]],"ltp":0.0,"tv":0.0,"id":14819609},{"batb":[[0,5.4,11.09],[1,5.3,11.8],[2,1.01,0.51]],"batl":[[1,6.4,20.22]],"ltp":0.0,"tv":0.0,"id":14819608}]}]}
{"op":"mcm","clk":"1003364692","pt":1580649649045,"mc":[{"id":"1.168213438","rc":[{"batl":[[0,6,11.57],[1,6,0]],"ltp":0.0,"tv":0.0,"id":13114902},{"batb":[[0,1.65,27.62],[1,1.01,0.51],[2,1.01,0]],"batl":[[0,1.91,19.43],[1,1.91,0]],"ltp":2.6,"tv":103.63,"id":13114898},{"batb":[[0,9.2,16.37],[1,1.01,0.51],[2,1.01,0]],"batl":[[0,21,5.35],[1,21,0]],"ltp":0.0,"tv":0.0,"id":14819609},{"batb":[[0,5.3,11.8],[1,1.01,0.51],[2,1.01,0]],"batl":[[0,6.4,20.22],[1,6.4,0]],"ltp":0.0,"tv":0.0,"id":14819608}]}]}
{"op":"mcm","clk":"1003365800","pt":1580649656051,"mc":[{"id":"1.168213438","rc":[{"batb":[[0,5.2,12.04],[1,5.1,12.98],[2,1.01,0.51]],"batl":[[1,6.2,11.17]],"ltp":0.0,"tv":0.0,"id":13114902},{"batb":[[1,1.62,29.9],[2,1.01,0.51]],"batl":[[0,1.72,27.07],[1,1.81,22.74]],"ltp":2.6,"tv":103.63,"id":13114898},{"batb":[[0,14.5,5.74],[1,11.5,9.84],[2,1.01,0.51]],"batl":[[1,25,8.03]],"ltp":0.0,"tv":0.0,"id":14819609},{"batb":[[0,5.3,11.49]],"batl":[[1,6.6,19.12]],"ltp":0.0,"tv":0.0,"id":14819608}]}]}
{"op":"mcm","clk":"1003367767","pt":1580649669032,"mc":[{"id":"1.168213438","rc":[{"batb":[[0,5.1,12.98],[1,1.01,0.51],[2,1.01,0]],"batl":[[0,6.2,11.17],[1,6.2,0]],"ltp":0.0,"tv":0.0,"id":13114902},{"batb":[[0,1.62,29.9],[1,1.01,0.51],[2,1.01,0]],"batl":[[0,1.81,22.74],[1,1.81,0]],"ltp":2.6,"tv":103.63,"id":13114898},{"batb":[[0,11.5,9.84],[1,1.01,0.51],[2,1.01,0]],"batl":[[0,25,8.03],[1,25,0]],"ltp":0.0,"tv":0.0,"id":14819609},{"batl":[[0,6.6,19.12],[1,6.6,0]],"ltp":0.0,"tv":0.0,"id":14819608}]}]}
{"op":"mcm","clk":"1003370378","pt":1580649686606,"mc":[{"id":"1.168213438","rc":[{"batb":[[0,1.01,0.51],[1,1.01,0]],"ltp":2.6,"tv":103.63,"id":13114898}]}]}
{"op":"mcm","clk":"1003370997","pt":1580649690090,"mc":[{"id":"1.168213438","rc":[{"batb":[[0,5.3,11.64],[1,5.2,12.43],[2,1.01,0.51]],"batl":[[0,6.2,10.78]],"ltp":0.0,"tv":0.0,"id":13114902},{"batb":[[0,1.61,30.21],[1,1.59,32.18],[2,1.01,0.51]],"batl":[[0,1.68,29.51],[1,1.74,25.97]],"ltp":2.6,"tv":103.63,"id":13114898},{"batb":[[0,16.5,4.25],[1,14,6.22],[2,1.01,0.51]],"batl":[[0,25,7.71],[1,28,6.29]],"ltp":0.0,"tv":0.0,"id":14819609},{"batb":[[0,5.6,20.14],[1,5.5,10.78],[2,1.01,0.51]],"batl":[[0,6.6,18.73],[1,6.8,17.94]],"ltp":0.0,"tv":0.0,"id":14819608}]}]}
{"op":"mcm","clk":"1003373316","pt":1580649705319,"mc":[{"id":"1.168213438","rc":[{"batb":[[0,5.2,12.43],[1,1.01,0.51],[2,1.01,0]],"ltp":0.0,"tv":0.0,"id":13114902},{"batb":[[0,1.59,32.18],[1,1.01,0.51],[2,1.01,0]],"batl":[[0,1.74,25.97],[1,1.74,0]],"ltp":2.6,"tv":103.63,"id":13114898},{"batb":[[0,14,6.22],[1,1.01,0.51],[2,1.01,0]],"batl":[[0,28,6.29],[1,28,0]],"ltp":0.0,"tv":0.0,"id":14819609},{"batb":[[0,5.5,10.78],[1,1.01,0.51],[2,1.01,0]],"batl":[[0,6.8,17.94],[1,6.8,0]],"ltp":0.0,"tv":0.0,"id":14819608}]}]}
{"op":"mcm","clk":"1003374507","pt":1580649713439,"mc":[{"id":"1.168213438","rc":[{"batb":[[0,5.4,11.25],[1,5.3,11.8],[2,5.2,12.43]],"batl":[[1,6.4,20.3]],"ltp":0.0,"tv":0.0,"id":13114902},{"batb":[[1,1.53,36.74],[2,1.01,0.51]],"batl":[[0,1.65,31.47],[1,1.69,28.88],[2,1.74,25.97]],"ltp":2.6,"tv":103.63,"id":13114898},{"batb":[[0,18,6.85],[1,16,4.41],[2,14,6.22]],"ltp":0.0,"tv":0.0,"id":14819609},{"batb":[[0,5.8,19.28],[1,5.6,20.46],[2,5.5,10.78]],"batl":[[1,7.2,16.29]],"ltp":0.0,"tv":0.0,"id":14819608}]}]}
{"op":"mcm","clk":"1003374557","pt":1580649713758,"mc":[{"id":"1.168213438","rc":[{"batb":[[2,1.01,0.51]],"ltp":0.0,"tv":0.0,"id":13114902},{"batl":[[2,1.74,0]],"ltp":2.6,"tv":103.63,"id":13114898},{"batb":[[2,1.01,0.51]],"ltp":0.0,"tv":0.0,"id":14819609},{"batb":[[2,1.01,0.51]],"ltp":0.0,"tv":0.0,"id":14819608}]}]}
{"op":"mcm","clk":"1003378976","pt":1580649741636,"mc":[{"id":"1.168213438","rc":[{"batb":[[0,5.3,11.8],[1,1.01,0.51],[2,1.01,0]],"batl":[[0,6.4,20.3],[1,6.4,0]],"ltp":0.0,"tv":0.0,"id":13114902},{"batb":[[0,1.53,36.74],[1,1.01,0.51],[2,1.01,0]],"batl":[[0,1.69,28.88],[1,1.69,0]],"ltp":2.6,"tv":103.63,"id":13114898},{"batb":[[0,16,4.41],[1,1.01,0.51],[2,1.01,0]],"ltp":0.0,"tv":0.0,"id":14819609},{"batb":[[0,5.6,20.46],[1,1.01,0.51],[2,1.01,0]],"batl":[[0,7.2,16.29],[1,7.2,0]],"ltp":0.0,"tv":0.0,"id":14819608}]}]}
{"op":"mcm","clk":"1003379482","pt":1580649744742,"mc":[{"id":"1.168213438","rc":[{"batb":[[1,5.2,11.96],[2,1.01,0.51]],"ltp":0.0,"tv":0.0,"id":13114902}]}]}
{"op":"mcm","clk":"1003379528","pt":1580649745019,"mc":[{"id":"1.168213438","rc":[{"batb":[[0,5.2,11.96],[1,1.01,0.51],[2,1.01,0]],"ltp":0.0,"tv":0.0,"id":13114902},{"batb":[[0,1.53,36.27]],"batl":[[0,1.69,28.56]],"ltp":2.6,"tv":103.63,"id":13114898},{"batb":[[0,5.6,10.31]],"ltp":0.0,"tv":0.0,"id":14819608}]}]}
{"op":"mcm","clk":"1003381282","pt":1580649756436,"mc":[{"id":"1.168213438","rc":[{"batb":[[1,5.1,12.51],[2,1.01,0.51]],"batl":[[0,6,11.49],[1,6.2,10.86]],"ltp":0.0,"tv":0.0,"id":13114902},{"batb":[[0,1.63,29.11],[1,1.58,32.81],[2,1.01,0.51]],"batl":[[1,1.73,26.52]],"ltp":2.6,"tv":103.63,"id":13114898},{"batb":[[1,14.5,5.51],[2,1.01,0.51]],"batl":[[0,24,4.25],[1,30,5.74]],"ltp":0.0,"tv":0.0,"id":14819609},{"batb":[[1,5.5,10.7],[2,1.01,0.51]],"batl":[[0,6.6,19.28],[1,7,17.55]],"ltp":0.0,"tv":0.0,"id":14819608}]}]}
{"op":"mcm","clk":"1003383239","pt":1580649769109,"mc":[{"id":"1.168213438","rc":[{"batb":[[0,5.1,12.51],[1,1.01,0.51],[2,1.01,0]],"batl":[[0,6.2,10.86],[1,6.2,0]],"ltp":0.0,"tv":0.0,"id":13114902},{"batb":[[0,1.58,32.81],[1,1.01,0.51],[2,1.01,0]],"batl":[[0,1.73,26.52],[1,1.73,0]],"ltp":2.6,"tv":103.63,"id":13114898},{"batb":[[0,14.5,5.51],[1,1.01,0.51],[2,1.01,0]],"batl":[[0,30,5.74],[1,30,0]],"ltp":0.0,"tv":0.0,"id":14819609},{"batb":[[0,5.5,10.7],[1,1.01,0.51],[2,1.01,0]],"batl":[[0,7,17.55],[1,7,0]],"ltp":0.0,"tv":0.0,"id":14819608}]}]}
{"op":"mcm","clk":"1003383751","pt":1580649772297,"mc":[{"id":"1.168213438","rc":[{"batl":[[0,6.8,17.55]],"ltp":0.0,"tv":0.0,"id":14819608}]}]}
{"op":"mcm","clk":"1003386474","pt":1580649789227,"mc":[{"id":"1.168213438","rc":[{"batb":[[1,5,13.14],[2,1.01,0.51]],"batl":[[0,5.9,12.04],[1,6,11.33]],"ltp":0.0,"tv":0.0,"id":13114902},{"batb":[[0,1.67,27.07],[1,1.61,30.37],[2,1.01,0.51]],"batl":[[1,1.77,24.78]],"ltp":2.6,"tv":103.63,"id":13114898},{"batb":[[1,14,6.37],[2,1.01,0.51]],"batl":[[0,21,5.19],[1,25,7.63]],"ltp":0.0,"tv":0.0,"id":14819609},{"batb":[[1,5.4,11.25],[2,1.01,0.51]],"batl":[[0,6.4,10.31],[1,6.8,17.55]],"ltp":0.0,"tv":0.0,"id":14819608}]}]}
{"op":"mcm","clk":"1003389178","pt":1580649805661,"mc":[{"id":"1.168213438","rc":[{"batb":[[0,5,13.14],[1,1.01,0.51],[2,1.01,0]],"batl":[[0,6,11.33],[1,6,0]],"ltp":0.0,"tv":0.0,"id":13114902},{"batb":[[0,1.61,30.37],[1,1.01,0.51],[2,1.01,0]],"batl":[[0,1.77,24.78],[1,1.77,0]],"ltp":2.6,"tv":103.63,"id":13114898},{"batb":[[0,14,6.37],[1,1.01,0.51],[2,1.01,0]],"batl":[[0,25,7.63],[1,25,0]],"ltp":0.0,"tv":0.0,"id":14819609},{"batb":[[0,5.4,11.25],[1,1.01,0.51],[2,1.01,0]],"batl":[[0,6.8,17.55],[1,6.8,0]],"ltp":0.0,"tv":0.0,"id":14819608}]}]}
{"op":"mcm","clk":"1003390381","pt":1580649813162,"mc":[{"id":"1.168213438","rc":[{"batl":[[0,5.8,12.59],[1,5.9,11.8]],"ltp":0.0,"tv":0.0,"id":13114902},{"batb":[[0,1.7,25.26],[1,1.65,27.77],[2,1.01,0.51]],"batl":[[1,1.8,23.45]],"ltp":2.6,"tv":103.63,"id":13114898},{"batb":[[1,13,7],[2,1.01,0.51]],"batl":[[0,19.5,5.98],[1,22,5.04]],"ltp":0.0,"tv":0.0,"id":14819609},{"batb":[[1,5.3,11.88],[2,1.01,0.51]],"batl":[[0,6.2,10.78],[1,6.6,19.67]],"ltp":0.0,"tv":0.0,"id":14819608}]}]}
{"op":"mcm","clk":"1003392112","pt":1580649823621,"mc":[{"id":"1.168213438","rc":[{"batl":[[0,5.9,11.8],[1,5.9,0]],"ltp":0.0,"tv":0.0,"id":13114902},{"batb":[[0,1.65,27.77],[1,1.01,0.51],[2,1.01,0]],"batl":[[0,1.8,23.45],[1,1.8,0]],"ltp":2.6,"tv":103.63,"id":13114898},{"batb":[[0,13,7],[1,1.01,0.51],[2,1.01,0]],"batl":[[0,22,5.04],[1,22,0]],"ltp":0.0,"tv":0.0,"id":14819609},{"batb":[[0,5.3,11.88],[1,1.01,0.51],[2,1.01,0]],"batl":[[0,6.6,19.67],[1,6.6,0]],"ltp":0.0,"tv":0.0,"id":14819608}]}]}
{"op":"mcm","clk":"1003395443","pt":1580649843723,"mc":[{"id":"1.168213438","rc":[{"batb":[[1,4.8,14.71],[2,1.01,0.51]],"batl":[[0,5.7,12.9],[1,5.8,12.43],[2,5.9,11.8]],"ltp":0.0,"tv":0.0,"id":13114902},{"batb":[[0,1.73,23.92],[1,1.66,27.07],[2,1.65,27.77]],"batl":[[1,1.97,17.62]],"ltp":2.6,"tv":103.63,"id":13114898},{"batb":[[1,9,7.08],[2,1.01,0.51]],"batl":[[0,18.5,6.61],[1,22,5.04],[2,26,7.32]],"ltp":0.0,"tv":0.0,"id":14819609},{"batb":[[1,5.1,12.83],[2,1.01,0.51]],"batl":[[0,6,11.41],[1,6.2,11.02],[2,6.6,19.67]],"ltp":0.0,"tv":0.0,"id":14819608}]}]}
{"op":"mcm","clk":"1003395495","pt":1580649844041,"mc":[{"id":"1.168213438","rc":[{"batl":[[2,5.9,0]],"ltp":0.0,"tv":0.0,"id":13114902},{"batb":[[2,1.01,0.51]],"ltp":2.6,"tv":103.63,"id":13114898},{"batl":[[1,26,7.32],[2,26,0]],"ltp":0.0,"tv":0.0,"id":14819609},{"batb":[[0,5.1,12.83],[1,1.01,0.51],[2,1.01,0]],"batl":[[2,6.6,0]],"ltp":0.0,"tv":0.0,"id":14819608}]}]}
{"op":"mcm","clk":"1003408821","pt":1580649923207,"mc":[{"id":"1.168213438","rc":[{"batb":[[0,4.8,14.71],[1,1.01,0.51],[2,1.01,0]],"batl":[[0,5.8,12.43],[1,5.8,0]],"ltp":0.0,"tv":0.0,"id":13114902},{"batb":[[0,1.66,27.07],[1,1.01,0.51],[2,1.01,0]],"batl":[[0,1.97,17.62],[1,1.97,0]],"ltp":2.6,"tv":103.63,"id":13114898},{"batb":[[0,9,7.08],[1,1.01,0.51],[2,1.01,0]],"batl":[[0,26,7.32],[1,26,0]],"ltp":0.0,"tv":0.0,"id":14819609},{"batl":[[0,6.2,11.02],[1,6.2,0]],"ltp":0.0,"tv":0.0,"id":14819608}]}]}
{"op":"mcm","clk":"1003410963","pt":1580649935718,"mc":[{"id":"1.168213438","rc":[{"batb":[[1,4.6,16.52],[2,1.01,0.51]],"batl":[[0,5.5,14.08],[1,5.6,13.45],[2,5.8,12.43]],"ltp":0.0,"tv":0.0,"id":13114902},{"batb":[[0,1.89,17.94],[1,1.78,21.56],[2,1.66,27.07]],"batl":[[1,2.26,23.68]],"ltp":2.6,"tv":103.63,"id":13114898},{"batb":[[1,6,17],[2,1.01,0.51]],"batl":[[0,11.5,15.97],[1,16,8.73],[2,26,7.32]],"ltp":0.0,"tv":0.0,"id":14819609},{"batb":[[1,5,13.45],[2,1.01,0.51]],"batl":[[0,5.8,12.35],[1,5.9,12.04],[2,6.2,11.02]],"ltp":0.0,"tv":0.0,"id":14819608}]}]}
{"op":"mcm","clk":"1003411001","pt":1580649935928,"mc":[{"id":"1.168213438","rc":[{"batl":[[2,5.8,0]],"ltp":0.0,"tv":0.0,"id":13114902},{"batb":[[2,1.01,0.51]],"ltp":2.6,"tv":103.63,"id":13114898},{"batl":[[2,26,0]],"ltp":0.0,"tv":0.0,"id":14819609},{"batb":[[0,5,13.45],[1,1.01,0.51],[2,1.01,0]],"batl":[[2,6.2,0]],"ltp":0.0,"tv":0.0,"id":14819608}]}]}
{"op":"mcm","clk":"1003413460","pt":1580649950569,"mc":[{"id":"1.168213438","rc":[{"batb":[[0,4.6,16.52],[1,1.01,0.51],[2,1.01,0]],"batl":[[0,5.6,13.45],[1,5.6,0]],"ltp":0.0,"tv":0.0,"id":13114902},{"batb":[[0,1.78,21.56],[1,1.01,0.51],[2,1.01,0]],"batl":[[0,2.26,23.68],[1,2.26,0]],"ltp":2.6,"tv":103.63,"id":13114898},{"batb":[[0,6,17],[1,1.01,0.51],[2,1.01,0]],"batl":[[0,16,8.73],[1,16,0]],"ltp":0.0,"tv":0.0,"id":14819609},{"batl":[[0,5.9,12.04],[1,5.9,0]],"ltp":0.0,"tv":0.0,"id":14819608}]}]}
{"op":"mcm","clk":"1003415037","pt":1580649962048,"mc":[{"id":"1.168213438","rc":[{"batb":[[1,4.4,18.02],[2,1.01,0.51]],"batl":[[0,5.2,15.82],[1,5.3,14.87]],"ltp":0.0,"tv":0.0,"id":13114902},{"batb":[[0,2.14,24.31],[1,1.99,30.45],[2,1.01,0.51]],"batl":[[1,2.7,14.87]],"ltp":2.6,"tv":103.63,"id":13114898},{"batb":[[1,4.4,18.1],[2,1.01,0.51]],"batl":[[0,7.2,15.89],[1,9.2,9.76]],"ltp":0.0,"tv":0.0,"id":14819609},{"batb":[[0,4.9,13.85]],"batl":[[0,5.7,12.83]],"ltp":0.0,"tv":0.0,"id":14819608}]}]}
{"op":"mcm","clk":"1003417795","pt":1580649980361,"mc":[{"id":"1.168213438","rc":[{"batb":[[0,4.4,18.02],[1,1.01,0.51],[2,1.01,0]],"batl":[[0,5.3,14.87],[1,5.3,0]],"ltp":0.0,"tv":0.0,"id":13114902},{"batb":[[0,1.99,30.45],[1,1.01,0.51],[2,1.01,0]],"batl":[[0,2.7,14.87],[1,2.7,0]],"ltp":2.6,"tv":103.63,"id":13114898},{"batb":[[0,4.4,18.1],[1,1.01,0.51],[2,1.01,0]],"batl":[[0,9.2,9.76],[1,9.2,0]],"ltp":0.0,"tv":0.0,"id":14819609}]}]}
{"op":"mcm","clk":"1003418332","pt":1580649983285,"mc":[{"id":"1.168213438","rc":[{"batb":[[0,5,13.77]],"ltp":0.0,"tv":0.0,"id":14819608}]}]}
{"op":"mcm","clk":"1003419330","pt":1580649989630,"mc":[{"id":"1.168213438","rc":[{"batb":[[0,4.7,15.58],[1,4.5,17.47],[2,4.4,18.02]],"batl":[[1,5.5,14.16]],"ltp":0.0,"tv":0.0,"id":13114902},{"batb":[[1,1.85,19.12],[2,1.01,0.51]],"batl":[[0,2.1,29.58],[1,2.5,17.94],[2,2.7,14.87]],"ltp":2.6,"tv":103.63,"id":13114898},{"batb":[[0,7.6,10.23],[1,5,13.61],[2,4.4,18.1]],"batl":[[1,13.5,12.04]],"ltp":0.0,"tv":0.0,"id":14819609},{"batl":[[1,5.8,12.51]],"ltp":0.0,"tv":0.0,"id":14819608}]}]}
{"op":"mcm","clk":"1003419367","pt":1580649989908,"mc":[{"id":"1.168213438","rc":[{"batb":[[2,1.01,0.51]],"ltp":0.0,"tv":0.0,"id":13114902},{"batl":[[2,2.7,0]],"ltp":2.6,"tv":103.63,"id":13114898},{"batb":[[2,1.01,0.51]],"ltp":0.0,"tv":0.0,"id":14819609}]}]}
{"op":"mcm","clk":"1003422017","pt":1580650007172,"mc":[{"id":"1.168213438","rc":[{"batb":[[0,4.5,17.47],[1,1.01,0.51],[2,1.01,0]],"batl":[[0,5.5,14.16],[1,5.5,0]],"ltp":0.0,"tv":0.0,"id":13114902},{"batb":[[0,1.85,19.12],[1,1.01,0.51],[2,1.01,0]],"batl":[[0,2.5,17.94],[1,2.5,0]],"ltp":2.6,"tv":103.63,"id":13114898},{"batb":[[0,5,13.61],[1,1.01,0.51],[2,1.01,0]],"batl":[[0,13.5,12.04],[1,13.5,0]],"ltp":0.0,"tv":0.0,"id":14819609},{"batl":[[0,5.8,12.51],[1,5.8,0]],"ltp":0.0,"tv":0.0,"id":14819608}]}]}
{"op":"mcm","clk":"1003425094","pt":1580650027347,"mc":[{"id":"1.168213438","rc":[{"batb":[[0,4.8,14.79],[1,4.5,16.92],[2,1.01,0.51]],"batl":[[1,5.7,12.98]],"ltp":0.0,"tv":0.0,"id":13114902},{"batb":[[1,1.72,24.08],[2,1.01,0.51]],"batl":[[0,1.92,18.8],[1,2.28,22.9]],"ltp":2.6,"tv":103.63,"id":13114898},{"batb":[[0,10,13.22],[1,6,17.62],[2,1.01,0.51]],"batl":[[1,22,4.88]],"ltp":0.0,"tv":0.0,"id":14819609},{"batb":[[0,5,13.53]],"ltp":0.0,"tv":0.0,"id":14819608}]}]}
{"op":"mcm","clk":"1003427776","pt":1580650045358,"mc":[{"id":"1.168213438","rc":[{"batb":[[0,4.5,16.92],[1,1.01,0.51],[2,1.01,0]],"batl":[[0,5.7,12.98],[1,5.7,0]],"ltp":0.0,"tv":0.0,"id":13114902},{"batb":[[0,1.72,24.08],[1,1.01,0.51],[2,1.01,0]],"batl":[[0,2.28,22.9],[1,2.28,0]],"ltp":2.6,"tv":103.63,"id":13114898},{"batb":[[0,6,17.62],[1,1.01,0.51],[2,1.01,0]],"batl":[[0,22,4.88],[1,22,0]],"ltp":0.0,"tv":0.0,"id":14819609}]}]}
{"op":"mcm","clk":"1003428282","pt":1580650048614,"mc":[{"id":"1.168213438","rc":[{"batl":[[0,2.3,22.82]],"ltp":2.6,"tv":103.63,"id":13114898}]}]}
{"op":"mcm","clk":"1003431757","pt":1580650072544,"mc":[{"id":"1.168213438","rc":[{"batb":[[0,5,13.61],[1,4.7,15.42],[2,1.01,0.51]],"batl":[[1,5.8,12.43]],"ltp":0.0,"tv":0.0,"id":13114902},{"batb":[[1,1.63,28.88],[2,1.01,0.51]],"batl":[[0,1.79,23.6],[1,2.04,16.05]],"ltp":2.6,"tv":103.63,"id":13114898},{"batb":[[0,15,5.19],[1,8.6,7.87],[2,1.01,0.51]],"ltp":0.0,"tv":0.0,"id":14819609},{"batb":[[0,5.1,12.9],[1,4.9,13.77],[2,1.01,0.51]],"batl":[[1,5.9,11.8]],"ltp":0.0,"tv":0.0,"id":14819608}]}]}
{"op":"mcm","clk":"1003434261","pt":1580650088903,"mc":[{"id":"1.168213438","rc":[{"batb":[[0,4.7,15.42],[1,1.01,0.51],[2,1.01,0]],"batl":[[0,5.8,12.43],[1,5.8,0]],"ltp":0.0,"tv":0.0,"id":13114902},{"batb":[[0,1.63,28.88],[1,1.01,0.51],[2,1.01,0]],"batl":[[0,2.04,16.05],[1,2.04,0]],"ltp":2.6,"tv":103.63,"id":13114898},{"batb":[[0,8.6,7.87],[1,1.01,0.51],[2,1.01,0]],"ltp":0.0,"tv":0.0,"id":14819609},{"batb":[[0,4.9,13.77],[1,1.01,0.51],[2,1.01,0]],"batl":[[0,5.9,11.8],[1,5.9,0]],"ltp":0.0,"tv":0.0,"id":14819608}]}]}
{"op":"mcm","clk":"1003435993","pt":1580650099560,"mc":[{"id":"1.168213438","rc":[{"batb":[[1,4.3,19.51],[2,1.01,0.51]],"batl":[[0,5.4,14.71],[1,5.7,12.9],[2,5.8,12.43]],"ltp":0.0,"tv":0.0,"id":13114902},{"batb":[[0,1.95,16.29],[1,1.68,26.12],[2,1.63,28.88]],"batl":[[1,2.98,11.57]],"ltp":2.6,"tv":103.63,"id":13114898},{"batb":[[1,3.85,25.1],[2,1.01,0.51]],"batl":[[0,10.5,7.55]],"ltp":0.0,"tv":0.0,"id":14819609},{"batl":[[0,5.7,12.75],[1,5.9,11.8]],"ltp":0.0,"tv":0.0,"id":14819608}]}]}
{"op":"mcm","clk":"1003436079","pt":1580650100139,"mc":[{"id":"1.168213438","rc":[{"batl":[[2,5.8,0]],"ltp":0.0,"tv":0.0,"id":13114902},{"batb":[[2,1.01,0.51]],"ltp":2.6,"tv":103.63,"id":13114898},{"batl":[[1,5.9,0]],"ltp":0.0,"tv":0.0,"id":14819608}]}]}
{"op":"mcm","clk":"1003439675","pt":1580650123588,"mc":[{"id":"1.168213438","rc":[{"batb":[[0,4.3,19.51],[1,1.01,0.51],[2,1.01,0]],"batl":[[0,5.7,12.9],[1,5.7,0]],"ltp":0.0,"tv":0.0,"id":13114902},{"batb":[[0,1.68,26.12],[1,1.01,0.51],[2,1.01,0]],"batl":[[0,2.98,11.57],[1,2.98,0]],"ltp":2.6,"tv":103.63,"id":13114898},{"batb":[[0,3.85,25.1],[1,1.01,0.51],[2,1.01,0]],"ltp":0.0,"tv":0.0,"id":14819609}]}]}
{"op":"mcm","clk":"1003442828","pt":1580650144320,"mc":[{"id":"1.168213438","rc":[{"batb":[[0,5,13.45],[1,4.9,14.16],[2,1.01,0.51]],"batl":[[1,5.8,12.27]],"ltp":0.0,"tv":0.0,"id":13114902},{"batb":[[1,1.62,29.74],[2,1.01,0.51]],"batl":[[0,1.75,25.57],[1,1.79,23.6]],"ltp":2.6,"tv":103.63,"id":13114898},{"batb":[[0,21,4.34],[1,19,5.9],[2,1.01,0.51]],"ltp":0.0,"tv":0.0,"id":14819609},{"batb":[[1,4.8,14.56],[2,1.01,0.51]],"batl":[[0,5.6,13.22],[1,5.9,11.88]],"ltp":0.0,"tv":0.0,"id":14819608}]}]}
{"op":"mcm","clk":"1003447220","pt":1580650172616,"mc":[{"id":"1.168213438","rc":[{"batb":[[0,4.9,14.16],[1,1.01,0.51],[2,1.01,0]],"batl":[[0,5.8,12.27],[1,5.8,0]],"ltp":0.0,"tv":0.0,"id":13114902},{"batb":[[0,1.62,29.74],[1,1.01,0.51],[2,1.01,0]],"batl":[[0,1.79,23.6],[1,1.79,0]],"ltp":2.6,"tv":103.63,"id":13114898},{"batb":[[0,19,5.9],[1,1.01,0.51],[2,1.01,0]],"ltp":0.0,"tv":0.0,"id":14819609},{"batb":[[0,4.8,14.56],[1,1.01,0.51],[2,1.01,0]],"batl":[[0,5.9,11.88],[1,5.9,0]],"ltp":0.0,"tv":0.0,"id":14819608}]}]}
{"op":"mcm","clk":"1003448472","pt":1580650180602,"mc":[{"id":"1.168213438","rc":[{"batb":[[0,5.1,12.75],[1,5,13.38],[2,4.9,14.16]],"batl":[[1,6,11.49]],"ltp":0.0,"tv":0.0,"id":13114902},{"batb":[[1,1.56,34.07],[2,1.01,0.51]],"batl":[[0,1.68,29.11],[1,1.73,26.75],[2,1.79,23.6]],"ltp":2.6,"tv":103.63,"id":13114898},{"batb":[[0,26,3.75],[1,22,3.54],[2,19,5.9]],"ltp":0.0,"tv":0.0,"id":14819609},{"batb":[[0,5.2,12.35],[1,5.1,13.06],[2,4.8,14.56]],"batl":[[1,6.2,10.86]],"ltp":0.0,"tv":0.0,"id":14819608}]}]}
{"op":"mcm","clk":"1003448513","pt":1580650180871,"mc":[{"id":"1.168213438","rc":[{"batb":[[2,1.01,0.51]],"ltp":0.0,"tv":0.0,"id":13114902},{"batl":[[2,1.79,0]],"ltp":2.6,"tv":103.63,"id":13114898},{"batb":[[2,1.01,0.51]],"ltp":0.0,"tv":0.0,"id":14819609},{"batb":[[2,1.01,0.51]],"ltp":0.0,"tv":0.0,"id":14819608}]}]}
{"op":"mcm","clk":"1003450750","pt":1580650195631,"mc":[{"id":"1.168213438","rc":[{"batb":[[0,5,13.38],[1,1.01,0.51],[2,1.01,0]],"batl":[[0,6,11.49],[1,6,0]],"ltp":0.0,"tv":0.0,"id":13114902},{"batb":[[0,1.56,34.07],[1,1.01,0.51],[2,1.01,0]],"batl":[[0,1.73,26.75],[1,1.73,0]],"ltp":2.6,"tv":103.63,"id":13114898},{"batb":[[0,22,3.54],[1,1.01,0.51],[2,1.01,0]],"ltp":0.0,"tv":0.0,"id":14819609},{"batb":[[0,5.1,13.06],[1,1.01,0.51],[2,1.01,0]],"batl":[[0,6.2,10.86],[1,6.2,0]],"ltp":0.0,"tv":0.0,"id":14819608}]}]}
{"op":"mcm","clk":"1003452352","pt":1580650204551,"mc":[{"id":"1.168213438","rc":[{"batb":[[0,5.2,12.35]],"batl":[[1,6.4,10.46]],"ltp":0.0,"tv":0.0,"id":13114902},{"batb":[[1,1.49,40.29],[2,1.01,0.51]],"batl":[[0,1.62,33.28],[1,1.66,30.84]],"ltp":2.6,"tv":103.63,"id":13114898},{"batb":[[0,30,2.64]],"ltp":0.0,"tv":0.0,"id":14819609},{"batb":[[0,5.4,11.25],[1,5.3,11.88],[2,1.01,0.51]],"batl":[[1,6.6,18.8]],"ltp":0.0,"tv":0.0,"id":14819608}]}]}
{"op":"mcm","clk":"1003455372","pt":1580650222831,"mc":[{"id":"1.168213438","rc":[{"batl":[[0,6.4,10.46],[1,6.4,0]],"ltp":0.0,"tv":0.0,"id":13114902},{"batb":[[0,1.49,40.29],[1,1.01,0.51],[2,1.01,0]],"batl":[[0,1.66,30.84],[1,1.66,0]],"ltp":2.6,"tv":103.63,"id":13114898},{"batb":[[0,1.01,0.51],[1,1.01,0]],"ltp":0.0,"tv":0.0,"id":14819609},{"batb":[[0,5.3,11.88],[1,1.01,0.51],[2,1.01,0]],"batl":[[0,6.6,18.8],[1,6.6,0]],"ltp":0.0,"tv":0.0,"id":14819608}]}]}
{"op":"mcm","clk":"1003457314","pt":1580650235643,"mc":[{"id":"1.168213438","rc":[{"batb":[[1,5,13.06],[2,1.01,0.51]],"batl":[[0,5.9,11.88],[1,6.2,11.09]],"ltp":0.0,"tv":0.0,"id":13114902},{"batb":[[0,1.59,31.55],[1,1.52,37.22],[2,1.01,0.51]],"batl":[[1,1.71,27.7]],"ltp":2.6,"tv":103.63,"id":13114898},{"batb":[[0,24,5.22],[1,1.01,0.51]],"ltp":0.0,"tv":0.0,"id":14819609},{"batb":[[1,5.1,12.9],[2,1.01,0.51]],"batl":[[0,6,11.41],[1,6.4,20.3]],"ltp":0.0,"tv":0.0,"id":14819608}]}]}
{"op":"mcm","clk":"1003459434","pt":1580650249940,"mc":[{"id":"1.168213438","rc":[{"batb":[[0,5,13.06],[1,1.01,0.51],[2,1.01,0]],"batl":[[0,6.2,11.09],[1,6.2,0]],"ltp":0.0,"tv":0.0,"id":13114902},{"batb":[[0,1.52,37.22],[1,1.01,0.51],[2,1.01,0]],"batl":[[0,1.71,27.7],[1,1.71,0]],"ltp":2.6,"tv":103.63,"id":13114898},{"batb":[[0,5.1,12.9],[1,1.01,0.51],[2,1.01,0]],"batl":[[0,6.4,20.3],[1,6.4,0]],"ltp":0.0,"tv":0.0,"id":14819608}]}]}
{"op":"mcm","clk":"1003460744","pt":1580650258578,"mc":[{"id":"1.168213438","rc":[{"batb":[[1,4.9,13.69],[2,1.01,0.51]],"batl":[[0,5.8,12.59],[1,6,11.64]],"ltp":0.0,"tv":0.0,"id":13114902},{"batb":[[0,1.64,28.33],[1,1.56,33.75],[2,1.01,0.51]],"batl":[[1,1.75,25.34]],"ltp":2.6,"tv":103.63,"id":13114898},{"batb":[[1,20,5.19],[2,1.01,0.51]],"ltp":0.0,"tv":0.0,"id":14819609},{"batb":[[1,5,13.38],[2,1.01,0.51]],"batl":[[0,5.8,12.35],[1,6.2,10.94]],"ltp":0.0,"tv":0.0,"id":14819608}]}]}
{"op":"mcm","clk":"1003462738","pt":1580650271611,"mc":[{"id":"1.168213438","rc":[{"batb":[[0,4.9,13.69],[1,1.01,0.51],[2,1.01,0]],"batl":[[0,6,11.64],[1,6,0]],"ltp":0.0,"tv":0.0,"id":13114902},{"batb":[[0,1.56,33.75],[1,1.01,0.51],[2,1.01,0]],"batl":[[0,1.75,25.34],[1,1.75,0]],"ltp":2.6,"tv":103.63,"id":13114898},{"batb":[[0,20,5.19],[1,1.01,0.51],[2,1.01,0]],"ltp":0.0,"tv":0.0,"id":14819609},{"batb":[[0,5,13.38],[1,1.01,0.51],[2,1.01,0]],"batl":[[0,6.2,10.94],[1,6.2,0]],"ltp":0.0,"tv":0.0,"id":14819608}]}]}
{"op":"mcm","clk":"1003464254","pt":1580650280693,"mc":[{"id":"1.168213438","rc":[{"batl":[[0,5.6,13.14],[1,5.8,12.2],[2,6,11.64]],"ltp":0.0,"tv":0.0,"id":13114902},{"batb":[[0,1.69,25.89],[1,1.61,30.21],[2,1.56,33.75]],"batl":[[1,1.8,23.21]],"ltp":2.6,"tv":103.63,"id":13114898},{"batb":[[1,17.5,7.32],[2,1.01,0.51]],"ltp":0.0,"tv":0.0,"id":14819609},{"batb":[[1,4.9,14.24],[2,1.01,0.51]],"batl":[[0,5.7,12.9],[1,6,11.57],[2,6.2,10.94]],"ltp":0.0,"tv":0.0,"id":14819608}]}]}
{"op":"mcm","clk":"1003464306","pt":1580650281016,"mc":[{"id":"1.168213438","rc":[{"batl":[[2,6,0]],"ltp":0.0,"tv":0.0,"id":13114902},{"batb":[[2,1.01,0.51]],"ltp":2.6,"tv":103.63,"id":13114898},{"batl":[[2,6.2,0]],"ltp":0.0,"tv":0.0,"id":14819608}]}]}
{"op":"mcm","clk":"1003466694","pt":1580650295411,"mc":[{"id":"1.168213438","rc":[{"batl":[[0,5.8,12.2],[1,5.8,0]],"ltp":0.0,"tv":0.0,"id":13114902},{"batb":[[0,1.61,30.21],[1,1.01,0.51],[2,1.01,0]],"batl":[[0,1.8,23.21],[1,1.8,0]],"ltp":2.6,"tv":103.63,"id":13114898},{"batb":[[0,17.5,7.32],[1,1.01,0.51],[2,1.01,0]],"ltp":0.0,"tv":0.0,"id":14819609},{"batb":[[0,4.9,14.24],[1,1.01,0.51],[2,1.01,0]],"batl":[[0,6,11.57],[1,6,0]],"ltp":0.0,"tv":0.0,"id":14819608}]}]}
{"op":"mcm","clk":"1003468183","pt":1580650305140,"mc":[{"id":"1.168213438","rc":[{"batb":[[1,4.7,15.58],[2,1.01,0.51]],"batl":[[0,5.5,13.69],[1,5.7,12.98]],"ltp":0.0,"tv":0.0,"id":13114902},{"batb":[[0,1.73,23.6],[1,1.65,27.85],[2,1.01,0.51]],"batl":[[1,2,16.84]],"ltp":2.6,"tv":103.63,"id":13114898},{"batb":[[1,10,13.69],[2,1.01,0.51]],"batl":[[0,27,6.69]],"ltp":0.0,"tv":0.0,"id":14819609},{"batb":[[1,4.7,15.26],[2,1.01,0.51]],"batl":[[0,5.5,13.61],[1,5.6,13.06]],"ltp":0.0,"tv":0.0,"id":14819608}]}]}
{"op":"mcm","clk":"1003471760","pt":1580650327696,"mc":[{"id":"1.168213438","rc":[{"batb":[[1,4.8,15.03],[2,4.7,15.26]],"batl":[[2,5.7,12.9]],"ltp":0.0,"tv":0.0,"id":14819608}]}]}
{"op":"mcm","clk":"1003471903","pt":1580650328560,"mc":[{"id":"1.168213438","rc":[{"batb":[[0,4.9,14.08],[2,1.01,0.51]],"batl":[[0,5.6,13.06],[1,5.7,12.9],[2,5.7,0]],"ltp":0.0,"tv":0.0,"id":14819608}]}]}
{"op":"mcm","clk":"1003473185","pt":1580650336663,"mc":[{"id":"1.168213438","rc":[{"batb":[[1,1.71,24.47],[2,1.65,27.85]],"batl":[[0,1.78,24],[1,1.8,23.21],[2,1.96,17.86]],"ltp":2.6,"tv":103.63,"id":13114898},{"batb":[[0,19,5.82],[1,17.5,7.32],[2,11,11.02]],"ltp":0.0,"tv":0.0,"id":14819609},{"batb":[[2,4.7,15.11]],"ltp":0.0,"tv":0.0,"id":14819608}]}]}
{"op":"mcm","clk":"1003473336","pt":1580650337582,"mc":[{"id":"1.168213438","rc":[{"batb":[[0,1.71,24.47],[1,1.64,28.48],[2,1.01,0.51]],"batl":[[1,1.96,17.86],[2,1.96,0]],"ltp":2.6,"tv":103.63,"id":13114898},{"batb":[[1,11,11.02],[2,1.01,0.51]],"ltp":0.0,"tv":0.0,"id":14819609},{"batb":[[1,4.7,15.11],[2,1.01,0.51]],"ltp":0.0,"tv":0.0,"id":14819608}]}]}
{"op":"mcm","clk":"1003476582","pt":1580650358540,"mc":[{"id":"1.168213438","rc":[{"batb":[[1,4.7,15.26]],"batl":[[0,5.6,13.53]],"ltp":0.0,"tv":0.0,"id":13114902},{"batb":[[0,1.7,25.26],[1,1.63,29.03]],"batl":[[0,1.77,24.78],[1,1.92,18.88]],"ltp":2.6,"tv":103.63,"id":13114898},{"batb":[[0,21,4.34],[1,12,8.73]],"ltp":0.0,"tv":0.0,"id":14819609}]}]}
{"op":"mcm","clk":"1003481590","pt":1580650390191,"mc":[{"id":"1.168213438","rc":[{"batb":[[0,4.7,15.26],[1,1.01,0.51],[2,1.01,0]],"batl":[[0,5.7,12.98],[1,5.7,0]],"ltp":0.0,"tv":0.0,"id":13114902},{"batb":[[0,1.63,29.03],[1,1.01,0.51],[2,1.01,0]],"batl":[[0,1.92,18.88],[1,1.92,0]],"ltp":2.6,"tv":103.63,"id":13114898},{"batb":[[0,12,8.73],[1,1.01,0.51],[2,1.01,0]],"ltp":0.0,"tv":0.0,"id":14819609},{"batb":[[0,4.7,15.11],[1,1.01,0.51],[2,1.01,0]],"batl":[[0,5.7,12.9],[1,5.7,0]],"ltp":0.0,"tv":0.0,"id":14819608}]}]}
{"op":"mcm","clk":"1003482125","pt":1580650393381,"mc":[{"id":"1.168213438","rc":[{"batb":[[0,4.7,15.11]],"ltp":0.0,"tv":0.0,"id":13114902},{"batb":[[0,1.62,29.58]],"batl":[[0,1.89,19.99]],"ltp":2.6,"tv":103.63,"id":13114898},{"batb":[[0,13.5,6.61]],"ltp":0.0,"tv":0.0,"id":14819609}]}]}
{"op":"mcm","clk":"1003484231","pt":1580650406286,"mc":[{"id":"1.168213438","rc":[{"batb":[[0,4.8,14.79]],"batl":[[1,5.8,12.59]],"ltp":0.0,"tv":0.0,"id":13114902},{"batb":[[1,1.58,32.26],[2,1.01,0.51]],"batl":[[0,1.69,28.95],[1,1.8,23.13]],"ltp":2.6,"tv":103.63,"id":13114898},{"batb":[[0,30,2.75],[1,20,5.43],[2,1.01,0.51]],"ltp":0.0,"tv":0.0,"id":14819609},{"batb":[[0,4.8,14.79]],"batl":[[1,5.8,12.51]],"ltp":0.0,"tv":0.0,"id":14819608}]}]}
{"op":"mcm","clk":"1003486803","pt":1580650420628,"mc":[{"id":"1.168213438","rc":[{"batl":[[0,5.8,12.59],[1,5.8,0]],"ltp":0.0,"tv":0.0,"id":13114902},{"batb":[[0,1.58,32.26],[1,1.01,0.51],[2,1.01,0]],"batl":[[0,1.8,23.13],[1,1.8,0]],"ltp":2.6,"tv":103.63,"id":13114898},{"batb":[[0,20,5.43],[1,1.01,0.51],[2,1.01,0]],"ltp":0.0,"tv":0.0,"id":14819609},{"batl":[[0,5.8,12.51],[1,5.8,0]],"ltp":0.0,"tv":0.0,"id":14819608}]}]}
{"op":"mcm","clk":"1003488131","pt":1580650427622,"mc":[{"id":"1.168213438","rc":[{"batb":[[0,5,13.06],[1,4.9,13.93],[2,1.01,0.51]],"batl":[[1,5.9,12.04]],"ltp":0.0,"tv":0.0,"id":13114902},{"batb":[[1,1.55,34.78],[2,1.01,0.51]],"batl":[[0,1.65,31.55],[1,1.72,26.91]],"ltp":2.6,"tv":103.63,"id":13114898},{"batb":[[0,1.01,0.51],[1,1.01,0]],"ltp":0.0,"tv":0.0,"id":14819609},{"batb":[[0,5,13.06],[1,4.8,14.63],[2,1.01,0.51]],"batl":[[1,5.9,11.96]],"ltp":0.0,"tv":0.0,"id":14819608}]}]}
{"op":"mcm","clk":"1003490495","pt":1580650440327,"mc":[{"id":"1.168213438","rc":[{"batb":[[0,4.9,13.93],[1,1.01,0.51],[2,1.01,0]],"batl":[[0,5.9,12.04],[1,5.9,0]],"ltp":0.0,"tv":0.0,"id":13114902},{"batb":[[0,1.55,34.78],[1,1.01,0.51],[2,1.01,0]],"batl":[[0,1.72,26.91],[1,1.72,0]],"ltp":2.6,"tv":103.63,"id":13114898},{"batb":[[0,4.8,14.63],[1,1.01,0.51],[2,1.01,0]],"batl":[[0,5.9,11.96],[1,5.9,0]],"ltp":0.0,"tv":0.0,"id":14819608}]}]}
{"op":"mcm","clk":"1003492443","pt":1580650451552,"mc":[{"id":"1.168213438","rc":[{"batb":[[0,5.1,12.59],[1,5,13.61],[2,1.01,0.51]],"batl":[[1,6,11.64]],"ltp":0.0,"tv":0.0,"id":13114902},{"batb":[[1,1.53,36.67],[2,1.01,0.51]],"batl":[[0,1.61,33.99],[1,1.67,29.74]],"ltp":2.6,"tv":103.63,"id":13114898},{"batb":[[0,5.1,12.51],[1,4.8,14.32],[2,1.01,0.51]],"batl":[[1,6,11.41]],"ltp":0.0,"tv":0.0,"id":14819608}]}]}
{"op":"mcm","clk":"1003495235","pt":1580650467450,"mc":[{"id":"1.168213438","rc":[{"batb":[[0,5,13.61],[1,1.01,0.51],[2,1.01,0]],"batl":[[0,6,11.64],[1,6,0]],"ltp":0.0,"tv":0.0,"id":13114902},{"batb":[[0,1.53,36.67],[1,1.01,0.51],[2,1.01,0]],"batl":[[0,1.67,29.74],[1,1.67,0]],"ltp":2.6,"tv":103.63,"id":13114898},{"batb":[[0,4.8,14.32],[1,1.01,0.51],[2,1.01,0]],"batl":[[0,6,11.41],[1,6,0]],"ltp":0.0,"tv":0.0,"id":14819608}]}]}
{"op":"mcm","clk":"1003499271","pt":1580650489610,"mc":[{"id":"1.168213438","rc":[{"batb":[[0,4.8,14.56]],"batl":[[0,5.6,13.06],[1,5.7,12.59]],"ltp":0.0,"tv":0.0,"id":13114902},{"batb":[[0,1.61,30.37],[1,1.57,33.13],[2,1.01,0.51]],"batl":[[1,1.76,25.18]],"ltp":2.6,"tv":103.63,"id":13114898},{"batb":[[1,4.6,15.97],[2,1.01,0.51]],"batl":[[0,5.5,13.77],[1,5.7,13.06]],"ltp":0.0,"tv":0.0,"id":14819608}]}]}
{"op":"mcm","clk":"1003502668","pt":1580650507424,"mc":[{"id":"1.168213438","rc":[{"batl":[[0,5.7,12.59],[1,5.7,0]],"ltp":0.0,"tv":0.0,"id":13114902},{"batb":[[0,1.57,33.13],[1,1.01,0.51],[2,1.01,0]],"batl":[[0,1.76,25.18],[1,1.76,0]],"ltp":2.6,"tv":103.63,"id":13114898},{"batb":[[0,4.6,15.97],[1,1.01,0.51],[2,1.01,0]],"batl":[[0,5.7,13.06],[1,5.7,0]],"ltp":0.0,"tv":0.0,"id":14819608}]}]}
{"op":"mcm","clk":"1003505401","pt":1580650520684,"mc":[{"id":"1.168213438","rc":[{"batb":[[0,5,13.14],[1,4.8,14.56],[2,4.7,15.58]],"batl":[[1,6.8,17.94]],"ltp":0.0,"tv":0.0,"id":13114902},{"batb":[[1,1.45,45.48],[2,1.01,0.51]],"batl":[[0,1.64,32.34],[1,1.72,27.15],[2,1.76,25.18]],"ltp":2.6,"tv":103.63,"id":13114898},{"batb":[[0,5,13.61],[1,4.6,15.97],[2,1.01,0.51]],"batl":[[1,6.8,18.1]],"ltp":0.0,"tv":0.0,"id":14819608}]}]}
{"op":"mcm","clk":"1003505444","pt":1580650520898,"mc":[{"id":"1.168213438","rc":[{"batb":[[1,4.7,15.58],[2,1.01,0.51]],"ltp":0.0,"tv":0.0,"id":13114902},{"batl":[[2,1.76,0]],"ltp":2.6,"tv":103.63,"id":13114898}]}]}
{"op":"mcm","clk":"1003511169","pt":1580650549740,"mc":[{"id":"1.168213438","rc":[{"batl":[[0,5.8,12.51]],"ltp":0.0,"tv":0.0,"id":13114902},{"batb":[[0,1.58,32.97],[1,1.45,45.24]],"batl":[[0,1.64,32.18]],"ltp":2.6,"tv":103.63,"id":13114898},{"batb":[[0,4.9,13.77]],"batl":[[0,5.6,13.22]],"ltp":0.0,"tv":0.0,"id":14819608}]}]}
{"op":"mcm","clk":"1003515393","pt":1580650571464,"mc":[{"id":"1.168213438","rc":[{"batb":[[0,5,12.98],[1,4.7,15.42]],"ltp":0.0,"tv":0.0,"id":13114902},{"batb":[[0,1.58,32.73],[1,1.45,45.01]],"batl":[[0,1.64,32.02],[1,1.72,26.91]],"ltp":2.6,"tv":103.63,"id":13114898},{"batb":[[1,4.5,16.76]],"ltp":0.0,"tv":0.0,"id":14819608}]}]}
{"op":"mcm","clk":"1003523274","pt":1580650614513,"mc":[{"id":"1.168213438","rc":[{"batb":[[0,4.7,15.42],[1,1.01,0.51],[2,1.01,0]],"batl":[[0,6.8,17.94],[1,6.8,0]],"ltp":0.0,"tv":0.0,"id":13114902},{"batb":[[0,1.45,45.01],[1,1.01,0.51],[2,1.01,0]],"batl":[[0,1.72,26.91],[1,1.72,0]],"ltp":2.6,"tv":103.63,"id":13114898},{"batb":[[0,4.5,16.76],[1,1.01,0.51],[2,1.01,0]],"batl":[[0,6.8,18.1],[1,6.8,0]],"ltp":0.0,"tv":0.0,"id":14819608}]}]}
{"op":"mcm","clk":"1003524706","pt":1580650622213,"mc":[{"id":"1.168213438","rc":[{"batb":[[1,4.5,17.47],[2,1.01,0.51]],"batl":[[0,5.3,14.79],[1,6,11.57]],"ltp":0.0,"tv":0.0,"id":13114902},{"batb":[[0,1.66,27.46],[1,1.54,36.04],[2,1.01,0.51]],"batl":[[1,1.8,23.37]],"ltp":2.6,"tv":103.63,"id":13114898},{"batb":[[1,4.3,19.28],[2,1.01,0.51]],"batl":[[0,5.2,15.97],[1,5.9,11.96]],"ltp":0.0,"tv":0.0,"id":14819608}]}]}
{"op":"mcm","clk":"1003526604","pt":1580650632151,"mc":[{"id":"1.168213438","rc":[{"batb":[[0,4.5,17.47],[1,1.01,0.51],[2,1.01,0]],"batl":[[0,6,11.57],[1,6,0]],"ltp":0.0,"tv":0.0,"id":13114902},{"batb":[[0,1.54,36.04],[1,1.01,0.51],[2,1.01,0]],"batl":[[0,1.8,23.37],[1,1.8,0]],"ltp":2.6,"tv":103.63,"id":13114898},{"batb":[[0,4.3,19.28],[1,1.01,0.51],[2,1.01,0]],"batl":[[0,5.9,11.96],[1,5.9,0]],"ltp":0.0,"tv":0.0,"id":14819608}]}]}
{"op":"mcm","clk":"1003528707","pt":1580650643512,"mc":[{"id":"1.168213438","rc":[{"batb":[[1,4.3,18.96],[2,1.01,0.51]],"batl":[[0,5.1,16.68],[1,5.4,14.16]],"ltp":0.0,"tv":0.0,"id":13114902},{"batb":[[0,1.73,23.84],[1,1.63,29.11],[2,1.01,0.51]],"batl":[[1,1.86,20.93]],"ltp":2.6,"tv":103.63,"id":13114898},{"batb":[[1,4.1,21.64],[2,1.01,0.51]],"batl":[[0,4.8,18.33],[1,5.3,14.87]],"ltp":0.0,"tv":0.0,"id":14819608}]}]}
{"op":"mcm","clk":"1003531258","pt":1580650657724,"mc":[{"id":"1.168213438","rc":[{"batb":[[0,4.3,18.96],[1,1.01,0.51],[2,1.01,0]],"batl":[[0,5.4,14.16],[1,5.4,0]],"ltp":0.0,"tv":0.0,"id":13114902},{"batb":[[0,1.63,29.11],[1,1.01,0.51],[2,1.01,0]],"batl":[[0,1.86,20.93],[1,1.86,0]],"ltp":2.6,"tv":103.63,"id":13114898},{"batb":[[0,4.1,21.64],[1,1.01,0.51],[2,1.01,0]],"batl":[[0,5.3,14.87],[1,5.3,0]],"ltp":0.0,"tv":0.0,"id":14819608}]}]}
{"op":"mcm","clk":"1003532614","pt":1580650665256,"mc":[{"id":"1.168213438","rc":[{"batb":[[1,4.2,19.99],[2,1.01,0.51]],"batl":[[0,4.9,18.1],[1,5.1,16.52]],"ltp":0.0,"tv":0.0,"id":13114902},{"batb":[[0,1.79,21.32],[1,1.71,24.47],[2,1.01,0.51]],"batl":[[1,1.91,19.28]],"ltp":2.6,"tv":103.63,"id":13114898},{"batb":[[1,3.95,23.76],[2,1.01,0.51]],"batl":[[0,4.6,20.54],[1,4.9,17.7]],"ltp":0.0,"tv":0.0,"id":14819608}]}]}
{"op":"mcm","clk":"1003534466","pt":1580650675524,"mc":[{"id":"1.168213438","rc":[{"batb":[[0,4.2,19.99],[1,1.01,0.51],[2,1.01,0]],"batl":[[0,5.1,16.52],[1,5.1,0]],"ltp":0.0,"tv":0.0,"id":13114902},{"batb":[[0,1.71,24.47],[1,1.01,0.51],[2,1.01,0]],"batl":[[0,1.91,19.28],[1,1.91,0]],"ltp":2.6,"tv":103.63,"id":13114898},{"batb":[[0,3.95,23.76],[1,1.01,0.51],[2,1.01,0]],"batl":[[0,4.9,17.7],[1,4.9,0]],"ltp":0.0,"tv":0.0,"id":14819608}]}]}
{"op":"mcm","clk":"1003538398","pt":1580650697670,"mc":[{"id":"1.168213438","rc":[{"batb":[[0,4.5,17.31],[1,4.3,19.12],[2,1.01,0.51]],"batl":[[1,5.5,13.85]],"ltp":0.0,"tv":0.0,"id":13114902},{"batb":[[1,1.61,30.37],[2,1.01,0.51]],"batl":[[0,1.78,24],[1,1.85,21.32]],"ltp":2.6,"tv":103.63,"id":13114898},{"batb":[[0,4.3,18.57],[1,4.1,20.85],[2,1.01,0.51]],"batl":[[1,5.5,14.01]],"ltp":0.0,"tv":0.0,"id":14819608}]}]}
{"op":"mcm","clk":"1003541464","pt":1580650714879,"mc":[{"id":"1.168213438","rc":[{"batb":[[0,4.3,19.12],[1,1.01,0.51],[2,1.01,0]],"batl":[[0,5.5,13.85],[1,5.5,0]],"ltp":0.0,"tv":0.0,"id":13114902},{"batb":[[0,1.61,30.37],[1,1.01,0.51],[2,1.01,0]],"batl":[[0,1.85,21.32],[1,1.85,0]],"ltp":2.6,"tv":103.63,"id":13114898},{"batb":[[0,4.1,20.85],[1,1.01,0.51],[2,1.01,0]],"batl":[[0,5.5,14.01],[1,5.5,0]],"ltp":0.0,"tv":0.0,"id":14819608}]}]}
{"op":"mcm","clk":"1003544424","pt":1580650731513,"mc":[{"id":"1.168213438","rc":[{"batb":[[1,3.85,25.26],[2,1.01,0.51]],"batl":[[0,4.9,18.18],[1,5.1,16.21],[2,5.5,13.85]],"ltp":0.0,"tv":0.0,"id":13114902},{"batb":[[0,1.78,21.72],[1,1.7,25.18],[2,1.61,30.37]],"batl":[[1,2.08,30.06]],"ltp":2.6,"tv":103.63,"id":13114898},{"batb":[[1,3.7,13.85],[2,1.01,0.51]],"batl":[[0,4.7,19.83],[1,5,17.07],[2,5.5,14.01]],"ltp":0.0,"tv":0.0,"id":14819608}]}]}
{"op":"mcm","clk":"1003544473","pt":1580650731801,"mc":[{"id":"1.168213438","rc":[{"batl":[[2,5.5,0]],"ltp":0.0,"tv":0.0,"id":13114902},{"batb":[[2,1.01,0.51]],"ltp":2.6,"tv":103.63,"id":13114898},{"batl":[[2,5.5,0]],"ltp":0.0,"tv":0.0,"id":14819608}]}]}
{"op":"mcm","clk":"1003552334","pt":1580650774743,"mc":[{"id":"1.168213438","rc":[{"batb":[[0,3.85,25.26],[1,1.01,0.51],[2,1.01,0]],"batl":[[0,5.1,16.21],[1,5.1,0]],"ltp":0.0,"tv":0.0,"id":13114902},{"batb":[[0,1.7,25.18],[1,1.01,0.51],[2,1.01,0]],"batl":[[0,2.08,30.06],[1,2.08,0]],"ltp":2.6,"tv":103.63,"id":13114898},{"batb":[[0,3.7,13.85],[1,1.01,0.51],[2,1.01,0]],"batl":[[0,5,17.07],[1,5,0]],"ltp":0.0,"tv":0.0,"id":14819608}]}]}
{"op":"mcm","clk":"1003554087","pt":1580650785362,"mc":[{"id":"1.168213438","rc":[{"batb":[[1,3.35,17.7],[2,1.01,0.51]],"batl":[[0,4.3,23.84],[1,4.7,19.91]],"ltp":0.0,"tv":0.0,"id":13114902},{"batb":[[0,1.98,15.5],[1,1.84,19.36],[2,1.01,0.51]],"batl":[[1,2.5,18.1]],"ltp":2.6,"tv":103.63,"id":13114898},{"batb":[[1,3.2,20.06],[2,1.01,0.51]],"batl":[[0,4.1,13.38],[1,4.5,21.95]],"ltp":0.0,"tv":0.0,"id":14819608}]}]}
{"op":"mcm","clk":"1003557415","pt":1580650805091,"mc":[{"id":"1.168213438","rc":[{"batb":[[0,3.35,17.7],[1,1.01,0.51],[2,1.01,0]],"batl":[[0,4.7,19.91],[1,4.7,0]],"ltp":0.0,"tv":0.0,"id":13114902},{"batb":[[0,1.84,19.36],[1,1.01,0.51],[2,1.01,0]],"batl":[[0,2.5,18.1],[1,2.5,0]],"ltp":2.6,"tv":103.63,"id":13114898},{"batb":[[0,3.2,20.06],[1,1.01,0.51],[2,1.01,0]],"batl":[[0,4.5,21.95],[1,4.5,0]],"ltp":0.0,"tv":0.0,"id":14819608}]}]}
{"op":"mcm","clk":"1003561751","pt":1580650828543,"mc":[{"id":"1.168213438","rc":[{"batb":[[1,2.92,25.02],[2,1.01,0.51]],"batl":[[0,3.65,17.15],[1,4,13.93]],"ltp":0.0,"tv":0.0,"id":13114902},{"batb":[[0,2.36,18.57],[1,2.12,24.94],[2,1.01,0.51]],"batl":[[1,3.25,23.53]],"ltp":2.6,"tv":103.63,"id":13114898},{"batb":[[1,2.76,11.57],[2,1.01,0.51]],"batl":[[0,3.5,19.28],[1,3.75,15.97]],"ltp":0.0,"tv":0.0,"id":14819608}]}]}
{"op":"mcm","clk":"1003565773","pt":1580650850910,"mc":[{"id":"1.168213438","rc":[{"batb":[[0,2.92,25.02],[1,1.01,0.51],[2,1.01,0]],"batl":[[0,4,13.93],[1,4,0]],"ltp":0.0,"tv":0.0,"id":13114902},{"batb":[[0,2.12,24.94],[1,1.01,0.51],[2,1.01,0]],"batl":[[0,3.25,23.53],[1,3.25,0]],"ltp":2.6,"tv":103.63,"id":13114898},{"batb":[[0,2.76,11.57],[1,1.01,0.51],[2,1.01,0]],"batl":[[0,3.75,15.97],[1,3.75,0]],"ltp":0.0,"tv":0.0,"id":14819608}]}]}
{"op":"mcm","clk":"1003567220","pt":1580650859519,"mc":[{"id":"1.168213438","rc":[{"batb":[[0,3.65,14.4],[1,3.05,22.19],[2,2.92,25.02]],"batl":[[1,4.5,21.95]],"ltp":0.0,"tv":0.0,"id":13114902},{"batb":[[1,1.92,16.92],[2,1.01,0.51]],"batl":[[0,2.24,24.31],[1,2.9,12.43],[2,3.25,23.53]],"ltp":2.6,"tv":103.63,"id":13114898},{"batb":[[0,3.45,16.52],[1,2.92,25.18],[2,2.76,11.57]],"batl":[[1,4.2,24.86]],"ltp":0.0,"tv":0.0,"id":14819608}]}]}
{"op":"mcm","clk":"1003567278","pt":1580650859864,"mc":[{"id":"1.168213438","rc":[{"batb":[[2,1.01,0.51]],"ltp":0.0,"tv":0.0,"id":13114902},{"batl":[[2,3.25,0]],"ltp":2.6,"tv":103.63,"id":13114898},{"batb":[[2,1.01,0.51]],"ltp":0.0,"tv":0.0,"id":14819608}]}]}
{"op":"mcm","clk":"1003570756","pt":1580650878639,"mc":[{"id":"1.168213438","rc":[{"batb":[[0,3.05,22.19],[1,1.01,0.51],[2,1.01,0]],"batl":[[0,4.5,21.95],[1,4.5,0]],"ltp":0.0,"tv":0.0,"id":13114902},{"batb":[[0,1.92,16.92],[1,1.01,0.51],[2,1.01,0]],"batl":[[0,2.9,12.43],[1,2.9,0]],"ltp":2.6,"tv":103.63,"id":13114898},{"batb":[[0,2.92,25.18],[1,1.01,0.51],[2,1.01,0]],"batl":[[0,4.2,24.86],[1,4.2,0]],"ltp":0.0,"tv":0.0,"id":14819608}]}]}
{"op":"mcm","clk":"1003572841","pt":1580650889685,"mc":[{"id":"1.168213438","rc":[{"batb":[[1,2.7,12.27],[2,1.01,0.51]],"batl":[[0,3.35,21.32],[1,3.6,17.55]],"ltp":0.0,"tv":0.0,"id":13114902},{"batb":[[0,2.72,12.67],[1,2.4,17.78],[2,1.01,0.51]],"batl":[[1,4.1,14.01]],"ltp":2.6,"tv":103.63,"id":13114898},{"batb":[[1,2.54,14.71],[2,1.01,0.51]],"batl":[[0,3.15,24.08],[1,3.45,19.75]],"ltp":0.0,"tv":0.0,"id":14819608}]}]}
{"op":"mcm","clk":"1003576478","pt":1580650910626,"mc":[{"id":"1.168213438","rc":[{"batb":[[0,8,15.96],[1,1.01,0.51]],"ltp":0.0,"tv":0.0,"id":14819609}]}]}
{"op":"mcm","clk":"1003576817","pt":1580650912514,"mc":[{"id":"1.168213438","rc":[{"batb":[[0,2.7,12.27],[1,1.01,0.51],[2,1.01,0]],"batl":[[0,3.6,17.55],[1,3.6,0]],"ltp":0.0,"tv":0.0,"id":13114902},{"batb":[[0,2.4,17.78],[1,1.01,0.51],[2,1.01,0]],"batl":[[0,4.1,14.01],[1,4.1,0]],"ltp":2.6,"tv":103.63,"id":13114898},{"batb":[[0,2.54,14.71],[1,1.01,0.51],[2,1.01,0]],"batl":[[0,3.45,19.75],[1,3.45,0]],"ltp":0.0,"tv":0.0,"id":14819608}]}]}
{"op":"mcm","clk":"1003581018","pt":1580650933548,"mc":[{"id":"1.168213438","rc":[{"batb":[[1,2.6,13.77],[2,1.01,0.51]],"batl":[[0,2.88,12.12],[1,3.15,24.94]],"ltp":0.0,"tv":0.0,"id":13114902},{"batb":[[0,3.7,14.48],[1,3,24.16],[2,1.01,0.51]],"batl":[[1,4.7,20.38]],"ltp":2.6,"tv":103.63,"id":13114898},{"batb":[[1,2.42,16.52],[2,1.01,0.51]],"batl":[[0,2.68,14.4],[1,2.96,11.17]],"ltp":0.0,"tv":0.0,"id":14819608}]}]}
{"op":"mcm","clk":"1003582473","pt":1580650940679,"mc":[{"id":"1.168213438","rc":[{"batb":[[0,1.01,0.51],[1,1.01,0]],"ltp":0.0,"tv":0.0,"id":14819609}]}]}
{"op":"mcm","clk":"1003586724","pt":1580650962176,"mc":[{"id":"1.168213438","rc":[{"batb":[[0,2.6,13.77],[1,1.01,0.51],[2,1.01,0]],"batl":[[0,3.15,24.94],[1,3.15,0]],"ltp":0.0,"tv":0.0,"id":13114902},{"batb":[[0,3,24.16],[1,1.01,0.51],[2,1.01,0]],"batl":[[0,4.7,20.38],[1,4.7,0]],"ltp":2.6,"tv":103.63,"id":13114898},{"batb":[[0,2.42,16.52],[1,1.01,0.51],[2,1.01,0]],"batl":[[0,2.96,11.17],[1,2.96,0]],"ltp":0.0,"tv":0.0,"id":14819608}]}]}
{"op":"mcm","clk":"1003587222","pt":1580650964732,"mc":[{"id":"1.168213438","rc":[{"batb":[[1,2.58,14.01],[2,1.01,0.51]],"batl":[[0,3.1,25.57],[1,3.15,24.94]],"ltp":0.0,"tv":0.0,"id":13114902},{"batb":[[0,2.46,16.05],[1,2.42,16.52],[2,1.01,0.51]],"batl":[[1,3,10.86]],"ltp":0.0,"tv":0.0,"id":14819608}]}]}
{"op":"mcm","clk":"1003587288","pt":1580650965015,"mc":[{"id":"1.168213438","rc":[{"batb":[[0,2.58,14.01],[1,1.01,0.51],[2,1.01,0]],"batl":[[1,3.15,0]],"ltp":0.0,"tv":0.0,"id":13114902},{"batb":[[1,1.01,0.51],[2,1.01,0]],"batl":[[0,3,10.86],[1,3,0]],"ltp":0.0,"tv":0.0,"id":14819608}]}]}
{"op":"mcm","clk":"1003588184","pt":1580650969441,"mc":[{"id":"1.168213438","rc":[{"batb":[[0,2.88,10.39],[1,2.72,12.12],[2,1.01,0.51]],"batl":[[1,3.5,19.04]],"ltp":0.0,"tv":0.0,"id":13114902},{"batb":[[1,2.44,17.07],[2,1.01,0.51]],"batl":[[0,3.25,23.53],[1,3.8,16.44]],"ltp":2.6,"tv":103.63,"id":13114898},{"batb":[[0,2.82,11.02],[1,2.64,13.14],[2,1.01,0.51]],"batl":[[1,3.5,19.2]],"ltp":0.0,"tv":0.0,"id":14819608}]}]}
{"op":"mcm","clk":"1003589526","pt":1580650976536,"mc":[{"id":"1.168213438","rc":[{"batb":[[0,12,15.96],[1,1.01,0.51]],"ltp":0.0,"tv":0.0,"id":14819609}]}]}
{"op":"mcm","clk":"1003591649","pt":1580650987639,"mc":[{"id":"1.168213438","rc":[{"batb":[[0,2.72,12.12],[1,1.01,0.51],[2,1.01,0]],"batl":[[0,3.5,19.04],[1,3.5,0]],"ltp":0.0,"tv":0.0,"id":13114902},{"batb":[[0,2.44,17.07],[1,1.01,0.51],[2,1.01,0]],"batl":[[0,3.8,16.44],[1,3.8,0]],"ltp":2.6,"tv":103.63,"id":13114898},{"batb":[[0,2.64,13.14],[1,1.01,0.51],[2,1.01,0]],"batl":[[0,3.5,19.2],[1,3.5,0]],"ltp":0.0,"tv":0.0,"id":14819608}]}]}
{"op":"mcm","clk":"1003594605","pt":1580651002414,"mc":[{"id":"1.168213438","rc":[{"batb":[[0,3.2,19.75],[1,2.98,23.84],[2,1.01,0.51]],"batl":[[1,4.1,13.45]],"ltp":0.0,"tv":0.0,"id":13114902},{"batb":[[1,2.02,28.88],[2,1.01,0.51]],"batl":[[0,2.58,16.68],[1,2.94,11.88]],"ltp":2.6,"tv":103.63,"id":13114898},{"batb":[[0,3.2,19.91],[1,2.94,24.63],[2,1.01,0.51]],"batl":[[1,4.1,13.45]],"ltp":0.0,"tv":0.0,"id":14819608}]}]}
{"op":"mcm","clk":"1003595609","pt":1580651007408,"mc":[{"id":"1.168213438","rc":[{"batb":[[0,1.01,0.51],[1,1.01,0]],"ltp":0.0,"tv":0.0,"id":14819609}]}]}
{"op":"mcm","clk":"1003598084","pt":1580651019844,"mc":[{"id":"1.168213438","rc":[{"batb":[[0,2.98,23.84],[1,1.01,0.51],[2,1.01,0]],"batl":[[0,4.1,13.45],[1,4.1,0]],"ltp":0.0,"tv":0.0,"id":13114902},{"batb":[[0,2.02,28.88],[1,1.01,0.51],[2,1.01,0]],"batl":[[0,2.94,11.88],[1,2.94,0]],"ltp":2.6,"tv":103.63,"id":13114898},{"batb":[[0,2.94,24.63],[1,1.01,0.51],[2,1.01,0]],"batl":[[0,4.1,13.45],[1,4.1,0]],"ltp":0.0,"tv":0.0,"id":14819608}]}]}
{"op":"mcm","clk":"1003603656","pt":1580651047934,"mc":[{"id":"1.168213438","rc":[{"batb":[[0,6,13.44],[1,1.01,0.51]],"ltp":0.0,"tv":0.0,"id":14819609}]}]}
{"op":"mcm","clk":"1003604185","pt":1580651050616,"mc":[{"id":"1.168213438","rc":[{"batb":[[0,3.7,13.85],[1,3.45,16.13],[2,1.01,0.51]],"batl":[[1,4.6,20.38]],"ltp":0.0,"tv":0.0,"id":13114902},{"batb":[[1,1.81,20.38],[2,1.01,0.51]],"batl":[[0,2.14,28.01],[1,2.3,22.42]],"ltp":2.6,"tv":103.63,"id":13114898},{"batb":[[0,3.7,13.85],[1,3.45,16.44],[2,1.01,0.51]],"batl":[[1,4.7,19.67]],"ltp":0.0,"tv":0.0,"id":14819608}]}]}
{"op":"mcm","clk":"1003607460","pt":1580651067334,"mc":[{"id":"1.168213438","rc":[{"batb":[[0,3.45,16.13],[1,1.01,0.51],[2,1.01,0]],"batl":[[0,4.6,20.38],[1,4.6,0]],"ltp":0.0,"tv":0.0,"id":13114902},{"batb":[[0,1.81,20.38],[1,1.01,0.51],[2,1.01,0]],"batl":[[0,2.3,22.42],[1,2.3,0]],"ltp":2.6,"tv":103.63,"id":13114898},{"batb":[[0,3.45,16.44],[1,1.01,0.51],[2,1.01,0]],"batl":[[0,4.7,19.67],[1,4.7,0]],"ltp":0.0,"tv":0.0,"id":14819608}]}]}
{"op":"mcm","clk":"1003609517","pt":1580651077995,"mc":[{"id":"1.168213438","rc":[{"batb":[[0,1.01,0.51],[1,1.01,0]],"ltp":0.0,"tv":0.0,"id":14819609}]}]}
{"op":"mcm","clk":"1003609967","pt":1580651080347,"mc":[{"id":"1.168213438","rc":[{"batb":[[1,3.2,20.06],[2,1.01,0.51]],"batl":[[0,3.8,15.66],[1,4.6,20.38]],"ltp":0.0,"tv":0.0,"id":13114902},{"batb":[[0,2.18,23.05],[1,1.84,19.36],[2,1.01,0.51]],"batl":[[1,2.62,16.05]],"ltp":2.6,"tv":103.63,"id":13114898},{"batb":[[1,3.15,20.61],[2,1.01,0.51]],"batl":[[0,3.75,15.97],[1,4.6,20.93]],"ltp":0.0,"tv":0.0,"id":14819608}]}]}
{"op":"mcm","clk":"1003613307","pt":1580651097461,"mc":[{"id":"1.168213438","rc":[{"batb":[[0,3.2,20.06],[1,1.01,0.51],[2,1.01,0]],"batl":[[0,4.6,20.38],[1,4.6,0]],"ltp":0.0,"tv":0.0,"id":13114902},{"batb":[[0,1.84,19.36],[1,1.01,0.51],[2,1.01,0]],"batl":[[0,2.62,16.05],[1,2.62,0]],"ltp":2.6,"tv":103.63,"id":13114898},{"batb":[[0,3.15,20.61],[1,1.01,0.51],[2,1.01,0]],"batl":[[0,4.6,20.93],[1,4.6,0]],"ltp":0.0,"tv":0.0,"id":14819608}]}]}
{"op":"mcm","clk":"1003615623","pt":1580651108165,"mc":[{"id":"1.168213438","rc":[{"batb":[[0,4,21.95],[1,3.65,14.4],[2,1.01,0.51]],"batl":[[1,4.9,17.62]],"ltp":0.0,"tv":0.0,"id":13114902},{"batb":[[1,1.73,23.68],[2,1.01,0.51]],"batl":[[0,1.92,19.04],[1,2.2,25.97]],"ltp":2.6,"tv":103.63,"id":13114898},{"batb":[[0,4,22.11],[1,3.6,14.95],[2,1.01,0.51]],"batl":[[1,4.9,17.62]],"ltp":0.0,"tv":0.0,"id":14819608}]}]}
{"op":"mcm","clk":"1003619464","pt":1580651127656,"mc":[{"id":"1.168213438","rc":[{"batb":[[1,3.55,15.03]],"ltp":0.0,"tv":0.0,"id":14819608}]}]}
{"op":"mcm","clk":"1003624176","pt":1580651153107,"mc":[{"id":"1.168213438","rc":[{"batb":[[0,10,12.6],[1,1.01,0.51]],"ltp":0.0,"tv":0.0,"id":14819609}]}]}
{"op":"mcm","clk":"1003632701","pt":1580651195732,"mc":[{"id":"1.168213438","rc":[{"batb":[[0,3.65,14.4],[1,1.01,0.51],[2,1.01,0]],"batl":[[0,4.9,17.62],[1,4.9,0]],"ltp":0.0,"tv":0.0,"id":13114902},{"batb":[[0,1.73,23.68],[1,1.01,0.51],[2,1.01,0]],"batl":[[0,2.2,25.97],[1,2.2,0]],"ltp":2.6,"tv":103.63,"id":13114898},{"batb":[[0,3.55,15.03],[1,1.01,0.51],[2,1.01,0]],"batl":[[0,4.9,17.62],[1,4.9,0]],"ltp":0.0,"tv":0.0,"id":14819608}]}]}
{"op":"mcm","clk":"1003634160","pt":1580651202545,"mc":[{"id":"1.168213438","rc":[{"batb":[[0,4.3,18.49],[1,3.95,23.84],[2,3.65,14.4]],"batl":[[1,5.2,15.74]],"ltp":0.0,"tv":0.0,"id":13114902},{"batb":[[1,1.66,27.62],[2,1.01,0.51]],"batl":[[0,1.8,23.21],[1,1.99,16.92],[2,2.2,25.97]],"ltp":2.6,"tv":103.63,"id":13114898},{"batb":[[0,4.3,18.49],[1,3.85,24.86],[2,3.55,15.03]],"batl":[[1,5.3,14.87]],"ltp":0.0,"tv":0.0,"id":14819608}]}]}
{"op":"mcm","clk":"1003634345","pt":1580651203555,"mc":[{"id":"1.168213438","rc":[{"batb":[[2,1.01,0.51]],"ltp":0.0,"tv":0.0,"id":13114902},{"batl":[[2,2.2,0]],"ltp":2.6,"tv":103.63,"id":13114898},{"batb":[[2,1.01,0.51]],"ltp":0.0,"tv":0.0,"id":14819608}]}]}
{"op":"mcm","clk":"1003636931","pt":1580651217135,"mc":[{"id":"1.168213438","rc":[{"batb":[[0,3.95,23.84],[1,1.01,0.51],[2,1.01,0]],"batl":[[0,5.2,15.74],[1,5.2,0]],"ltp":0.0,"tv":0.0,"id":13114902},{"batb":[[0,1.66,27.62],[1,1.01,0.51],[2,1.01,0]],"batl":[[0,1.99,16.92],[1,1.99,0]],"ltp":2.6,"tv":103.63,"id":13114898},{"batb":[[0,3.85,24.86],[1,1.01,0.51],[2,1.01,0]],"batl":[[0,5.3,14.87],[1,5.3,0]],"ltp":0.0,"tv":0.0,"id":14819608}]}]}
{"op":"mcm","clk":"1003638815","pt":1580651226455,"mc":[{"id":"1.168213438","rc":[{"batb":[[0,4.6,16.44],[1,4.2,19.59],[2,3.95,23.84]],"batl":[[1,5.5,14.16]],"ltp":0.0,"tv":0.0,"id":13114902},{"batb":[[1,1.6,31.08],[2,1.01,0.51]],"batl":[[0,1.72,27.07],[1,1.84,21.64],[2,1.99,16.92]],"ltp":2.6,"tv":103.63,"id":13114898},{"batb":[[0,4.7,15.58],[1,4.2,19.83],[2,3.85,24.86]],"batl":[[1,5.6,13.14]],"ltp":0.0,"tv":0.0,"id":14819608}]}]}
{"op":"mcm","clk":"1003638875","pt":1580651226753,"mc":[{"id":"1.168213438","rc":[{"batb":[[2,1.01,0.51]],"ltp":0.0,"tv":0.0,"id":13114902},{"batl":[[2,1.99,0]],"ltp":2.6,"tv":103.63,"id":13114898},{"batb":[[2,1.01,0.51]],"ltp":0.0,"tv":0.0,"id":14819608}]}]}
{"op":"mcm","clk":"1003641605","pt":1580651240773,"mc":[{"id":"1.168213438","rc":[{"batb":[[0,4.2,19.59],[1,1.01,0.51],[2,1.01,0]],"batl":[[0,5.5,14.16],[1,5.5,0]],"ltp":0.0,"tv":0.0,"id":13114902},{"batb":[[0,1.6,31.08],[1,1.01,0.51],[2,1.01,0]],"batl":[[0,1.84,21.64],[1,1.84,0]],"ltp":2.6,"tv":103.63,"id":13114898},{"batb":[[0,4.2,19.83],[1,1.01,0.51],[2,1.01,0]],"batl":[[0,5.6,13.14],[1,5.6,0]],"ltp":0.0,"tv":0.0,"id":14819608}]}]}
{"op":"mcm","clk":"1003643324","pt":1580651249497,"mc":[{"id":"1.168213438","rc":[{"batb":[[0,4.8,14.79],[1,4.6,16.21],[2,1.01,0.51]],"batl":[[1,5.6,13.3]],"ltp":0.0,"tv":0.0,"id":13114902},{"batb":[[1,1.57,33.68],[2,1.01,0.51]],"batl":[[0,1.66,30.37],[1,1.73,26.44]],"ltp":2.6,"tv":103.63,"id":13114898},{"batb":[[0,4.9,13.69],[1,4.6,16.52],[2,1.01,0.51]],"batl":[[1,5.9,11.88]],"ltp":0.0,"tv":0.0,"id":14819608}]}]}
{"op":"mcm","clk":"1003643934","pt":1580651253064,"mc":[{"id":"1.168213438","rc":[{"batb":[[0,1.01,0.51],[1,1.01,0]],"ltp":0.0,"tv":0.0,"id":14819609}]}]}
{"op":"mcm","clk":"1003645643","pt":1580651262711,"mc":[{"id":"1.168213438","rc":[{"batb":[[0,4.6,16.21],[1,1.01,0.51],[2,1.01,0]],"batl":[[0,5.6,13.3],[1,5.6,0]],"ltp":0.0,"tv":0.0,"id":13114902},{"batb":[[0,1.57,33.68],[1,1.01,0.51],[2,1.01,0]],"batl":[[0,1.73,26.44],[1,1.73,0]],"ltp":2.6,"tv":103.63,"id":13114898},{"batb":[[0,4.6,16.52],[1,1.01,0.51],[2,1.01,0]],"batl":[[0,5.9,11.88],[1,5.9,0]],"ltp":0.0,"tv":0.0,"id":14819608}]}]}
{"op":"mcm","clk":"1003647620","pt":1580651273718,"mc":[{"id":"1.168213438","rc":[{"batb":[[0,4.9,13.93],[1,4.5,17.15],[2,1.01,0.51]],"batl":[[1,6.8,18.1]],"ltp":0.0,"tv":0.0,"id":13114902},{"batb":[[1,1.43,47.92],[2,1.01,0.51]],"batl":[[0,1.63,32.89],[1,1.73,26.44]],"ltp":2.6,"tv":103.63,"id":13114898},{"batb":[[0,5.2,12.35],[1,4.7,15.66],[2,1.01,0.51]],"batl":[[1,7.2,15.89]],"ltp":0.0,"tv":0.0,"id":14819608}]}]}
{"op":"mcm","clk":"1003651042","pt":1580651293253,"mc":[{"id":"1.168213438","rc":[{"batb":[[0,4.5,17.15],[1,1.01,0.51],[2,1.01,0]],"batl":[[0,6.8,18.1],[1,6.8,0]],"ltp":0.0,"tv":0.0,"id":13114902},{"batb":[[0,1.43,47.92],[1,1.01,0.51],[2,1.01,0]],"batl":[[0,1.73,26.44],[1,1.73,0]],"ltp":2.6,"tv":103.63,"id":13114898},{"batb":[[0,4.7,15.66],[1,1.01,0.51],[2,1.01,0]],"batl":[[0,7.2,15.89],[1,7.2,0]],"ltp":0.0,"tv":0.0,"id":14819608}]}]}
{"op":"mcm","clk":"1003652456","pt":1580651301175,"mc":[{"id":"1.168213438","rc":[{"batb":[[1,4.2,20.14],[2,1.01,0.51]],"batl":[[0,5.1,16.37],[1,5.7,12.59]],"ltp":0.0,"tv":0.0,"id":13114902},{"batb":[[0,1.67,26.91],[1,1.53,36.27],[2,1.01,0.51]],"batl":[[1,1.83,21.95]],"ltp":2.6,"tv":103.63,"id":13114898},{"batb":[[1,4.3,18.73],[2,1.01,0.51]],"batl":[[0,5.3,14.95],[1,6.2,10.78]],"ltp":0.0,"tv":0.0,"id":14819608}]}]}
{"op":"mcm","clk":"1003654430","pt":1580651311870,"mc":[{"id":"1.168213438","rc":[{"batb":[[0,4.2,20.14],[1,1.01,0.51],[2,1.01,0]],"batl":[[0,5.7,12.59],[1,5.7,0]],"ltp":0.0,"tv":0.0,"id":13114902},{"batb":[[0,1.53,36.27],[1,1.01,0.51],[2,1.01,0]],"batl":[[0,1.83,21.95],[1,1.83,0]],"ltp":2.6,"tv":103.63,"id":13114898},{"batb":[[0,4.3,18.73],[1,1.01,0.51],[2,1.01,0]],"batl":[[0,6.2,10.78],[1,6.2,0]],"ltp":0.0,"tv":0.0,"id":14819608}]}]}
{"op":"mcm","clk":"1003659686","pt":1580651338537,"mc":[{"id":"1.168213438","rc":[{"batb":[[1,4,22.66],[2,1.01,0.51]],"batl":[[0,4.8,19.12],[1,5.1,15.97]],"ltp":0.0,"tv":0.0,"id":13114902},{"batb":[[0,1.76,22.35],[1,1.65,27.93],[2,1.01,0.51]],"batl":[[1,1.92,18.96]],"ltp":2.6,"tv":103.63,"id":13114898},{"batb":[[1,4.1,21.64],[2,1.01,0.51]],"batl":[[0,4.9,17.94],[1,5.4,14.24]],"ltp":0.0,"tv":0.0,"id":14819608}]}]}
{"op":"mcm","clk":"1003662649","pt":1580651353024,"mc":[{"id":"1.168213438","rc":[{"batb":[[0,4,22.66],[1,1.01,0.51],[2,1.01,0]],"batl":[[0,5.1,15.97],[1,5.1,0]],"ltp":0.0,"tv":0.0,"id":13114902},{"batb":[[0,1.65,27.93],[1,1.01,0.51],[2,1.01,0]],"batl":[[0,1.92,18.96],[1,1.92,0]],"ltp":2.6,"tv":103.63,"id":13114898},{"batb":[[0,4.1,21.64],[1,1.01,0.51],[2,1.01,0]],"batl":[[0,5.4,14.24],[1,5.4,0]],"ltp":0.0,"tv":0.0,"id":14819608}]}]}
{"op":"mcm","clk":"1003663267","pt":1580651356239,"mc":[{"id":"1.168213438","rc":[{"batb":[[0,4,22.42]],"batl":[[0,5.2,15.82]],"ltp":0.0,"tv":0.0,"id":13114902},{"batb":[[0,1.64,28.33]],"batl":[[0,1.91,19.28]],"ltp":2.6,"tv":103.63,"id":13114898},{"batb":[[0,4.1,21.32]],"batl":[[0,5.5,14.08]],"ltp":0.0,"tv":0.0,"id":14819608}]}]}
{"op":"mcm","clk":"1003664232","pt":1580651361054,"mc":[{"id":"1.168213438","rc":[{"batb":[[0,4.6,16.52],[1,4.2,20.38],[2,1.01,0.51]],"batl":[[1,6.2,11.09]],"ltp":0.0,"tv":0.0,"id":13114902},{"batb":[[1,1.48,41.15],[2,1.01,0.51]],"batl":[[0,1.71,27.7],[1,1.83,22.11]],"ltp":2.6,"tv":103.63,"id":13114898},{"batb":[[0,4.8,14.71],[1,4.4,18.25],[2,1.01,0.51]],"batl":[[1,6.8,18.49]],"ltp":0.0,"tv":0.0,"id":14819608}]}]}
{"op":"mcm","clk":"1003666411","pt":1580651372652,"mc":[{"id":"1.168213438","rc":[{"batb":[[0,4.2,20.38],[1,1.01,0.51],[2,1.01,0]],"batl":[[0,6.2,11.09],[1,6.2,0]],"ltp":0.0,"tv":0.0,"id":13114902},{"batb":[[0,1.48,41.15],[1,1.01,0.51],[2,1.01,0]],"batl":[[0,1.83,22.11],[1,1.83,0]],"ltp":2.6,"tv":103.63,"id":13114898},{"batb":[[0,4.4,18.25],[1,1.01,0.51],[2,1.01,0]],"batl":[[0,6.8,18.49],[1,6.8,0]],"ltp":0.0,"tv":0.0,"id":14819608}]}]}
{"op":"mcm","clk":"1003668463","pt":1580651383534,"mc":[{"id":"1.168213438","rc":[{"batb":[[0,5.3,11.49],[1,4.5,16.76],[2,1.01,0.51]],"batl":[[1,8.8,10.78]],"ltp":0.0,"tv":0.0,"id":13114902},{"batb":[[1,1.3,74.98],[2,1.01,0.51]],"batl":[[0,1.54,40.05],[1,1.71,27.85]],"ltp":2.6,"tv":103.63,"id":13114898},{"batb":[[0,5.7,19.83],[1,4.8,14.4],[2,1.01,0.51]],"batl":[[1,9.4,9.13]],"ltp":0.0,"tv":0.0,"id":14819608}]}]}
{"op":"mcm","clk":"1003669198","pt":1580651387291,"mc":[{"id":"1.168213438","rc":[{"batb":[[0,7,13.44],[1,1.01,0.51]],"ltp":0.0,"tv":0.0,"id":14819609}]}]}
{"op":"mcm","clk":"1003671928","pt":1580651401478,"mc":[{"id":"1.168213438","rc":[{"batb":[[0,4.5,16.76],[1,1.01,0.51],[2,1.01,0]],"batl":[[0,8.8,10.78],[1,8.8,0]],"ltp":0.0,"tv":0.0,"id":13114902},{"batb":[[0,1.3,74.98],[1,1.01,0.51],[2,1.01,0]],"batl":[[0,1.71,27.85],[1,1.71,0]],"ltp":2.6,"tv":103.63,"id":13114898},{"batb":[[0,4.8,14.4],[1,1.01,0.51],[2,1.01,0]],"batl":[[0,9.4,9.13],[1,9.4,0]],"ltp":0.0,"tv":0.0,"id":14819608}]}]}
{"op":"mcm","clk":"1003673741","pt":1580651409946,"mc":[{"id":"1.168213438","rc":[{"batb":[[1,4,22.35],[2,1.01,0.51]],"batl":[[0,5.2,15.97],[1,6.6,19.43]],"ltp":0.0,"tv":0.0,"id":13114902},{"batb":[[0,1.64,28.4],[1,1.44,46.26],[2,1.01,0.51]],"batl":[[1,1.87,20.61]],"ltp":2.6,"tv":103.63,"id":13114898},{"batb":[[1,4.3,18.88],[2,1.01,0.51]],"batl":[[0,5.5,13.77],[1,7.2,15.97]],"ltp":0.0,"tv":0.0,"id":14819608}]}]}
{"op":"mcm","clk":"1003674879","pt":1580651415674,"mc":[{"id":"1.168213438","rc":[{"batb":[[0,1.01,0.51],[1,1.01,0]],"ltp":0.0,"tv":0.0,"id":14819609}]}]}
{"op":"mcm","clk":"1003676426","pt":1580651423369,"mc":[{"id":"1.168213438","rc":[{"batb":[[0,4,22.35],[1,1.01,0.51],[2,1.01,0]],"batl":[[0,6.6,19.43],[1,6.6,0]],"ltp":0.0,"tv":0.0,"id":13114902},{"batb":[[0,1.44,46.26],[1,1.01,0.51],[2,1.01,0]],"batl":[[0,1.87,20.61],[1,1.87,0]],"ltp":2.6,"tv":103.63,"id":13114898},{"batb":[[0,4.3,18.88],[1,1.01,0.51],[2,1.01,0]],"batl":[[0,7.2,15.97],[1,7.2,0]],"ltp":0.0,"tv":0.0,"id":14819608}]}]}
{"op":"mcm","clk":"1003677036","pt":1580651426491,"mc":[{"id":"1.168213438","rc":[{"batb":[[0,1.45,45.79]],"batl":[[0,1.88,20.38]],"ltp":2.6,"tv":103.63,"id":13114898}]}]}
{"op":"mcm","clk":"1003680305","pt":1580651442599,"mc":[{"id":"1.168213438","rc":[{"batb":[[0,5.5,10.54],[1,4.1,21.64],[2,4,22.35]],"batl":[[1,17,7.55]],"ltp":0.0,"tv":0.0,"id":13114902},{"batb":[[1,1.14,175.07],[2,1.01,0.51]],"batl":[[0,1.5,44.46],[1,1.83,22.19],[2,1.88,20.38]],"ltp":2.6,"tv":103.63,"id":13114898},{"batb":[[0,6,17.31],[1,4.5,17.07],[2,4.3,18.88]],"batl":[[1,17.5,7.24]],"ltp":0.0,"tv":0.0,"id":14819608}]}]}
{"op":"mcm","clk":"1003680434","pt":1580651443253,"mc":[{"id":"1.168213438","rc":[{"batb":[[2,1.01,0.51]],"ltp":0.0,"tv":0.0,"id":13114902},{"batl":[[2,1.88,0]],"ltp":2.6,"tv":103.63,"id":13114898},{"batb":[[2,1.01,0.51]],"ltp":0.0,"tv":0.0,"id":14819608}]}]}
{"op":"mcm","clk":"1003684123","pt":1580651462507,"mc":[{"id":"1.168213438","rc":[{"batb":[[0,4.1,21.64],[1,1.01,0.51],[2,1.01,0]],"batl":[[0,17,7.55],[1,17,0]],"ltp":0.0,"tv":0.0,"id":13114902},{"batb":[[0,1.14,175.07],[1,1.01,0.51],[2,1.01,0]],"batl":[[0,1.83,22.19],[1,1.83,0]],"ltp":2.6,"tv":103.63,"id":13114898},{"batb":[[0,4.5,17.07],[1,1.01,0.51],[2,1.01,0]],"batl":[[0,17.5,7.24],[1,17.5,0]],"ltp":0.0,"tv":0.0,"id":14819608}]}]}
{"op":"mcm","clk":"1003686797","pt":1580651476730,"mc":[{"id":"1.168213438","rc":[{"batb":[[0,12.5,8.1],[1,9.2,16.05],[2,1.01,0.51]],"batl":[[1,21,5.04]],"ltp":0.0,"tv":0.0,"id":13114902},{"batb":[[1,1.11,228.73],[2,1.01,0.51]],"batl":[[0,1.18,144.22],[1,1.26,105.2]],"ltp":2.6,"tv":103.63,"id":13114898},{"batb":[[0,12.5,7.79],[1,9.4,15.58],[2,1.01,0.51]],"batl":[[1,22,4.8]],"ltp":0.0,"tv":0.0,"id":14819608}]}]}
{"op":"mcm","clk":"1003688277","pt":1580651484965,"mc":[{"id":"1.168213438","rc":[{"batb":[[1,1.1,229.99]],"ltp":2.6,"tv":103.63,"id":13114898},{"batb":[[0,12.5,7.63],[1,9.4,15.26]],"batl":[[0,17.5,7.08]],"ltp":0.0,"tv":0.0,"id":14819608}]}]}
{"op":"mcm","clk":"1003694286","pt":1580651518497,"mc":[{"id":"1.168213438","rc":[{"batb":[[1,1.1,229.52]],"ltp":2.6,"tv":103.63,"id":13114898}]}]}
{"op":"mcm","clk":"1003696384","pt":1580651529739,"mc":[{"id":"1.168213438","rc":[{"batb":[[1,1.11,229.28],[2,1.1,229.52]],"ltp":2.6,"tv":103.63,"id":13114898}]}]}
{"op":"mcm","clk":"1003696553","pt":1580651530552,"mc":[{"id":"1.168213438","rc":[{"batb":[[2,1.01,0.51]],"ltp":2.6,"tv":103.63,"id":13114898}]}]}
{"op":"mcm","clk":"1003699787","pt":1580651548200,"mc":[{"id":"1.168213438","rc":[{"batb":[[0,9.2,16.05],[1,1.01,0.51],[2,1.01,0]],"batl":[[0,21,5.04],[1,21,0]],"ltp":0.0,"tv":0.0,"id":13114902},{"batb":[[0,1.11,229.28],[1,1.01,0.51],[2,1.01,0]],"batl":[[0,1.26,105.2],[1,1.26,0]],"ltp":2.6,"tv":103.63,"id":13114898},{"batb":[[0,9.4,15.26],[1,1.01,0.51],[2,1.01,0]],"batl":[[0,22,4.8],[1,22,0]],"ltp":0.0,"tv":0.0,"id":14819608}]}]}
{"op":"mcm","clk":"1003701509","pt":1580651558724,"mc":[{"id":"1.168213438","rc":[{"batb":[[0,15,5.35],[1,11,10.31],[2,9.2,16.05]],"batl":[[1,27,6.61]],"ltp":0.0,"tv":0.0,"id":13114902},{"batb":[[1,1.08,294.51],[2,1.01,0.51]],"batl":[[0,1.15,149.81],[1,1.2,141.23],[2,1.26,105.2]],"ltp":2.6,"tv":103.63,"id":13114898},{"batb":[[0,15,5.04],[1,11.5,9.76],[2,9.4,15.26]],"batl":[[1,28,6.22]],"ltp":0.0,"tv":0.0,"id":14819608}]}]}
{"op":"mcm","clk":"1003701548","pt":1580651558901,"mc":[{"id":"1.168213438","rc":[{"batb":[[2,1.01,0.51]],"ltp":0.0,"tv":0.0,"id":13114902},{"batl":[[2,1.26,0]],"ltp":2.6,"tv":103.63,"id":13114898},{"batb":[[2,1.01,0.51]],"ltp":0.0,"tv":0.0,"id":14819608}]}]}
{"op":"mcm","clk":"1003704311","pt":1580651575036,"mc":[{"id":"1.168213438","rc":[{"batb":[[0,11,10.31],[1,1.01,0.51],[2,1.01,0]],"batl":[[0,27,6.61],[1,27,0]],"ltp":0.0,"tv":0.0,"id":13114902},{"batb":[[0,1.08,294.51],[1,1.01,0.51],[2,1.01,0]],"batl":[[0,1.2,141.23],[1,1.2,0]],"ltp":2.6,"tv":103.63,"id":13114898},{"batb":[[0,11.5,9.76],[1,1.01,0.51],[2,1.01,0]],"batl":[[0,28,6.22],[1,28,0]],"ltp":0.0,"tv":0.0,"id":14819608}]}]}
{"op":"mcm","clk":"1003706290","pt":1580651585455,"mc":[{"id":"1.168213438","rc":[{"batb":[[0,17.5,7.32],[1,14,5.98],[2,1.01,0.51]],"ltp":0.0,"tv":0.0,"id":13114902},{"batb":[[1,1.07,356.51],[2,1.01,0.51]],"batl":[[0,1.12,143.44],[1,1.16,150.05]],"ltp":2.6,"tv":103.63,"id":13114898},{"batb":[[0,18,6.85],[1,14.5,5.82],[2,1.01,0.51]],"ltp":0.0,"tv":0.0,"id":14819608}]}]}
{"op":"mcm","clk":"1003709180","pt":1580651601486,"mc":[{"id":"1.168213438","rc":[{"batb":[[0,14,5.98],[1,1.01,0.51],[2,1.01,0]],"ltp":0.0,"tv":0.0,"id":13114902},{"batb":[[0,1.07,356.51],[1,1.01,0.51],[2,1.01,0]],"batl":[[0,1.16,150.05],[1,1.16,0]],"ltp":2.6,"tv":103.63,"id":13114898},{"batb":[[0,14.5,5.82],[1,1.01,0.51],[2,1.01,0]],"ltp":0.0,"tv":0.0,"id":14819608}]}]}
{"op":"mcm","clk":"1003710423","pt":1580651608371,"mc":[{"id":"1.168213438","rc":[{"batb":[[0,8,15.12],[1,1.01,0.51]],"ltp":0.0,"tv":0.0,"id":14819609}]}]}
{"op":"mcm","clk":"1003711594","pt":1580651614732,"mc":[{"id":"1.168213438","rc":[{"batl":[[0,18,76.39]],"ltp":0.0,"tv":0.0,"id":14819608}]}]}
{"op":"mcm","clk":"1003711750","pt":1580651615522,"mc":[{"id":"1.168213438","rc":[{"batb":[[1,10,12.98],[2,1.01,0.51]],"batl":[[0,20,5.67],[1,27,6.92]],"ltp":0.0,"tv":0.0,"id":13114902},{"batb":[[0,1.11,211.5],[1,1.08,284.91],[2,1.07,356.51]],"batl":[[1,1.23,120.62]],"ltp":2.6,"tv":103.63,"id":13114898},{"batb":[[1,10,12.75],[2,1.01,0.51]],"batl":[[0,21,5.43],[1,27,6.61]],"ltp":0.0,"tv":0.0,"id":14819608}]}]}
{"op":"mcm","clk":"1003711782","pt":1580651615745,"mc":[{"id":"1.168213438","rc":[{"batb":[[2,1.01,0.51]],"ltp":2.6,"tv":103.63,"id":13114898}]}]}
{"op":"mcm","clk":"1003715721","pt":1580651637661,"mc":[{"id":"1.168213438","rc":[{"batb":[[0,10,12.98],[1,1.01,0.51],[2,1.01,0]],"batl":[[0,27,6.92],[1,27,0]],"ltp":0.0,"tv":0.0,"id":13114902},{"batb":[[0,1.08,284.91],[1,1.01,0.51],[2,1.01,0]],"batl":[[0,1.23,120.62],[1,1.23,0]],"ltp":2.6,"tv":103.63,"id":13114898},{"batb":[[0,1.01,0.51],[1,1.01,0]],"ltp":0.0,"tv":0.0,"id":14819609},{"batb":[[0,10,12.75],[1,1.01,0.51],[2,1.01,0]],"batl":[[0,27,6.61],[1,27,0]],"ltp":0.0,"tv":0.0,"id":14819608}]}]}
{"op":"mcm","clk":"1003716305","pt":1580651641059,"mc":[{"id":"1.168213438","rc":[{"batb":[[0,10,12.59]],"batl":[[0,27,6.77]],"ltp":0.0,"tv":0.0,"id":13114902},{"batb":[[0,10,12.35]],"batl":[[0,28,6.45]],"ltp":0.0,"tv":0.0,"id":14819608}]}]}
{"op":"mcm","clk":"1003717108","pt":1580651645655,"mc":[{"id":"1.168213438","rc":[{"batb":[[1,6.8,12.83],[2,1.01,0.51]],"batl":[[0,13.5,11.57],[1,19.5,5.82]],"ltp":0.0,"tv":0.0,"id":13114902},{"batb":[[0,1.18,130.14],[1,1.12,205.44],[2,1.01,0.51]],"batl":[[1,1.39,63.1]],"ltp":2.6,"tv":103.63,"id":13114898},{"batb":[[1,7,12.12],[2,1.01,0.51]],"batl":[[0,13.5,11.33],[1,19.5,5.82]],"ltp":0.0,"tv":0.0,"id":14819608}]}]}
{"op":"mcm","clk":"1003720391","pt":1580651663895,"mc":[{"id":"1.168213438","rc":[{"batb":[[0,6.8,12.83],[1,1.01,0.51],[2,1.01,0]],"batl":[[0,19.5,5.82],[1,19.5,0]],"ltp":0.0,"tv":0.0,"id":13114902},{"batb":[[0,1.12,205.44],[1,1.01,0.51],[2,1.01,0]],"batl":[[0,1.39,63.1],[1,1.39,0]],"ltp":2.6,"tv":103.63,"id":13114898},{"batb":[[0,7,12.12],[1,1.01,0.51],[2,1.01,0]],"batl":[[0,19.5,5.82],[1,19.5,0]],"ltp":0.0,"tv":0.0,"id":14819608}]}]}
{"op":"mcm","clk":"1003721939","pt":1580651672421,"mc":[{"id":"1.168213438","rc":[{"batb":[[0,6,12.6],[1,1.01,0.51]],"ltp":0.0,"tv":0.0,"id":14819609}]}]}
{"op":"mcm","clk":"1003724360","pt":1580651685561,"mc":[{"id":"1.168213438","rc":[{"batb":[[0,14,6.14],[1,9,17.07],[2,6.8,12.83]],"batl":[[1,30,5.67]],"ltp":0.0,"tv":0.0,"id":13114902},{"batb":[[1,1.07,321.18],[2,1.01,0.51]],"batl":[[0,1.16,146.03],[1,1.27,101.11],[2,1.39,63.1]],"ltp":2.6,"tv":103.63,"id":13114898},{"batb":[[0,14,6.22],[1,9.2,16.52],[2,7,12.12]],"batl":[[1,30,5.59]],"ltp":0.0,"tv":0.0,"id":14819608}]}]}
{"op":"mcm","clk":"1003724389","pt":1580651685848,"mc":[{"id":"1.168213438","rc":[{"batb":[[2,1.01,0.51]],"ltp":0.0,"tv":0.0,"id":13114902},{"batl":[[2,1.39,0]],"ltp":2.6,"tv":103.63,"id":13114898},{"batb":[[2,1.01,0.51]],"ltp":0.0,"tv":0.0,"id":14819608}]}]}
{"op":"mcm","clk":"1003727239","pt":1580651701683,"mc":[{"id":"1.168213438","rc":[{"batb":[[0,1.01,0.51],[1,1.01,0]],"ltp":0.0,"tv":0.0,"id":14819609}]}]}
{"op":"mcm","clk":"1003728444","pt":1580651707669,"mc":[{"id":"1.168213438","rc":[{"batb":[[0,9,17.07],[1,1.01,0.51],[2,1.01,0]],"batl":[[0,30,5.67],[1,30,0]],"ltp":0.0,"tv":0.0,"id":13114902},{"batb":[[0,1.07,321.18],[1,1.01,0.51],[2,1.01,0]],"batl":[[0,1.27,101.11],[1,1.27,0]],"ltp":2.6,"tv":103.63,"id":13114898},{"batb":[[0,9.2,16.52],[1,1.01,0.51],[2,1.01,0]],"batl":[[0,30,5.59],[1,30,0]],"ltp":0.0,"tv":0.0,"id":14819608}]}]}
{"op":"mcm","clk":"1003728512","pt":1580651707944,"mc":[{"id":"1.168213438","rc":[{"batb":[[0,9,6.85]],"ltp":0.0,"tv":0.0,"id":13114902},{"batb":[[0,1.07,320.63]],"batl":[[0,1.27,100.95]],"ltp":2.6,"tv":103.63,"id":13114898}]}]}
{"op":"mcm","clk":"1003734066","pt":1580651737684,"mc":[{"id":"1.168213438","rc":[{"batb":[[0,7,14.28],[1,1.01,0.51]],"ltp":0.0,"tv":0.0,"id":14819609}]}]}
{"op":"mcm","clk":"1003736495","pt":1580651750414,"mc":[{"id":"1.168213438","rc":[{"batb":[[0,18.5,6.14],[1,16.5,4.09],[2,1.01,0.51]],"ltp":0.0,"tv":0.0,"id":13114902},{"batb":[[1,1.05,441.96],[2,1.01,0.51]],"batl":[[0,1.12,154.92],[1,1.13,145.33]],"ltp":2.6,"tv":103.63,"id":13114898},{"batb":[[0,19,6.06],[1,16.5,4.17],[2,1.01,0.51]],"ltp":0.0,"tv":0.0,"id":14819608}]}]}
{"op":"mcm","clk":"1003740064","pt":1580651769547,"mc":[{"id":"1.168213438","rc":[{"batb":[[0,1.01,0.51],[1,1.01,0]],"ltp":0.0,"tv":0.0,"id":14819609}]}]}
{"op":"mcm","clk":"1003742840","pt":1580651785558,"mc":[{"id":"1.168213438","rc":[{"batb":[[0,16.5,4.09],[1,1.01,0.51],[2,1.01,0]],"ltp":0.0,"tv":0.0,"id":13114902},{"batb":[[0,1.05,441.96],[1,1.01,0.51],[2,1.01,0]],"batl":[[0,1.13,145.33],[1,1.13,0]],"ltp":2.6,"tv":103.63,"id":13114898},{"batb":[[0,16.5,4.17],[1,1.01,0.51],[2,1.01,0]],"ltp":0.0,"tv":0.0,"id":14819608}]}]}
{"op":"mcm","clk":"1003744501","pt":1580651794628,"mc":[{"id":"1.168213438","rc":[{"batb":[[0,22,3.4],[1,19.5,5.43],[2,1.01,0.51]],"ltp":0.0,"tv":0.0,"id":13114902},{"batb":[[1,1.03,732.61],[2,1.01,0.51]],"batl":[[0,1.09,141.08],[1,1.11,147.29]],"ltp":2.6,"tv":103.63,"id":13114898},{"batb":[[0,23,3.08],[1,19.5,5.51],[2,1.01,0.51]],"ltp":0.0,"tv":0.0,"id":14819608}]}]}
{"op":"mcm","clk":"1003746212","pt":1580651803905,"mc":[{"id":"1.168213438","rc":[{"batb":[[0,13,13.44],[1,1.01,0.51]],"ltp":0.0,"tv":0.0,"id":14819609}]}]}
{"op":"mcm","clk":"1003747715","pt":1580651811488,"mc":[{"id":"1.168213438","rc":[{"batb":[[0,19.5,5.43],[1,1.01,0.51],[2,1.01,0]],"ltp":0.0,"tv":0.0,"id":13114902},{"batb":[[0,1.03,732.61],[1,1.01,0.51],[2,1.01,0]],"batl":[[0,1.11,147.29],[1,1.11,0]],"ltp":2.6,"tv":103.63,"id":13114898},{"batb":[[0,19.5,5.51],[1,1.01,0.51],[2,1.01,0]],"ltp":0.0,"tv":0.0,"id":14819608}]}]}
{"op":"mcm","clk":"1003749487","pt":1580651821269,"mc":[{"id":"1.168213438","rc":[{"batb":[[1,16.5,7.95],[2,1.01,0.51]],"ltp":0.0,"tv":0.0,"id":13114902},{"batb":[[0,1.07,343.05],[1,1.04,514.82],[2,1.01,0.51]],"batl":[[1,1.13,147.92]],"ltp":2.6,"tv":103.63,"id":13114898},{"batb":[[1,16.5,8.03],[2,1.01,0.51]],"ltp":0.0,"tv":0.0,"id":14819608}]}]}
{"op":"mcm","clk":"1003752528","pt":1580651837763,"mc":[{"id":"1.168213438","rc":[{"batb":[[0,16.5,7.95],[1,1.01,0.51],[2,1.01,0]],"ltp":0.0,"tv":0.0,"id":13114902},{"batb":[[0,1.04,514.82],[1,1.01,0.51],[2,1.01,0]],"batl":[[0,1.13,147.92],[1,1.13,0]],"ltp":2.6,"tv":103.63,"id":13114898},{"batb":[[0,16.5,8.03],[1,1.01,0.51],[2,1.01,0]],"ltp":0.0,"tv":0.0,"id":14819608}]}]}
{"op":"mcm","clk":"1003755042","pt":1580651851586,"mc":[{"id":"1.168213438","rc":[{"batb":[[1,15,5.27],[2,1.01,0.51]],"batl":[[0,26,7.24]],"ltp":0.0,"tv":0.0,"id":13114902},{"batb":[[0,1.09,273.03],[1,1.06,366.34],[2,1.04,514.82]],"batl":[[1,1.15,149.02]],"ltp":2.6,"tv":103.63,"id":13114898},{"batb":[[1,15,5.19],[2,1.01,0.51]],"batl":[[0,26,7.24]],"ltp":0.0,"tv":0.0,"id":14819608}]}]}
{"op":"mcm","clk":"1003755076","pt":1580651851784,"mc":[{"id":"1.168213438","rc":[{"batb":[[2,1.01,0.51]],"ltp":2.6,"tv":103.63,"id":13114898}]}]}
{"op":"mcm","clk":"1003758340","pt":1580651869541,"mc":[{"id":"1.168213438","rc":[{"batb":[[0,15,5.27],[1,1.01,0.51],[2,1.01,0]],"ltp":0.0,"tv":0.0,"id":13114902},{"batb":[[0,1.06,366.34],[1,1.01,0.51],[2,1.01,0]],"batl":[[0,1.15,149.02],[1,1.15,0]],"ltp":2.6,"tv":103.63,"id":13114898},{"batb":[[0,15,5.19],[1,1.01,0.51],[2,1.01,0]],"ltp":0.0,"tv":0.0,"id":14819608}]}]}
{"op":"mcm","clk":"1003760825","pt":1580651882670,"mc":[{"id":"1.168213438","rc":[{"batb":[[0,1.01,0.51],[1,1.01,0]],"ltp":0.0,"tv":0.0,"id":14819609}]}]}
{"op":"mcm","clk":"1003762938","pt":1580651892952,"mc":[{"id":"1.168213438","rc":[{"batb":[[0,20,4.96],[1,16.5,4.17],[2,1.01,0.51]],"ltp":0.0,"tv":0.0,"id":13114902},{"batb":[[1,1.03,681.23],[2,1.01,0.51]],"batl":[[0,1.1,137.85],[1,1.13,146.11]],"ltp":2.6,"tv":103.63,"id":13114898},{"batb":[[0,20,4.8],[1,16.5,8.03],[2,1.01,0.51]],"ltp":0.0,"tv":0.0,"id":14819608}]}]}
{"op":"mcm","clk":"1003766682","pt":1580651911413,"mc":[{"id":"1.168213438","rc":[{"batb":[[0,12,15.96],[1,1.01,0.51]],"ltp":0.0,"tv":0.0,"id":14819609}]}]}
{"op":"mcm","clk":"1003767297","pt":1580651914522,"mc":[{"id":"1.168213438","rc":[{"batb":[[0,16.5,4.17],[1,1.01,0.51],[2,1.01,0]],"ltp":0.0,"tv":0.0,"id":13114902},{"batb":[[0,1.03,681.23],[1,1.01,0.51],[2,1.01,0]],"batl":[[0,1.13,146.11],[1,1.13,0]],"ltp":2.6,"tv":103.63,"id":13114898},{"batb":[[0,16.5,8.03],[1,1.01,0.51],[2,1.01,0]],"ltp":0.0,"tv":0.0,"id":14819608}]}]}
{"op":"mcm","clk":"1003770638","pt":1580651931413,"mc":[{"id":"1.168213438","rc":[{"batb":[[1,14,5.82],[2,1.01,0.51]],"batl":[[0,25,7.55]],"ltp":0.0,"tv":0.0,"id":13114902},{"batb":[[0,1.09,269.49],[1,1.06,404.58],[2,1.01,0.51]],"batl":[[1,1.16,152.49]],"ltp":2.6,"tv":103.63,"id":13114898},{"batb":[[1,14.5,5.67],[2,1.01,0.51]],"batl":[[0,26,7.32]],"ltp":0.0,"tv":0.0,"id":14819608}]}]}
{"op":"mcm","clk":"1003772298","pt":1580651940625,"mc":[{"id":"1.168213438","rc":[{"batb":[[0,1.01,0.51],[1,1.01,0]],"ltp":0.0,"tv":0.0,"id":14819609}]}]}
{"op":"mcm","clk":"1003774223","pt":1580651949641,"mc":[{"id":"1.168213438","rc":[{"batb":[[0,14,5.82],[1,1.01,0.51],[2,1.01,0]],"ltp":0.0,"tv":0.0,"id":13114902},{"batb":[[0,1.06,404.58],[1,1.01,0.51],[2,1.01,0]],"batl":[[0,1.16,152.49],[1,1.16,0]],"ltp":2.6,"tv":103.63,"id":13114898},{"batb":[[0,14.5,5.67],[1,1.01,0.51],[2,1.01,0]],"ltp":0.0,"tv":0.0,"id":14819608}]}]}
{"op":"mcm","clk":"1003779191","pt":1580651974999,"mc":[{"id":"1.168213438","rc":[{"batb":[[0,8,15.12],[1,1.01,0.51]],"ltp":0.0,"tv":0.0,"id":14819609}]}]}
{"op":"mcm","clk":"1003779865","pt":1580651978312,"mc":[{"id":"1.168213438","rc":[{"batb":[[0,21,4.04],[1,14.5,5.51],[2,1.01,0.51]],"ltp":0.0,"tv":0.0,"id":13114902},{"batl":[[0,1.1,150.6],[1,1.15,148.39]],"ltp":2.6,"tv":103.63,"id":13114898},{"batb":[[0,22,3.61],[1,15,5.04],[2,1.01,0.51]],"ltp":0.0,"tv":0.0,"id":14819608}]}]}
{"op":"mcm","clk":"1003784969","pt":1580652003719,"mc":[{"id":"1.168213438","rc":[{"batb":[[0,1.01,0.51],[1,1.01,0]],"ltp":0.0,"tv":0.0,"id":14819609}]}]}
{"op":"mcm","clk":"1003785734","pt":1580652006485,"mc":[{"id":"1.168213438","rc":[{"batb":[[0,14.5,5.51],[1,1.01,0.51],[2,1.01,0]],"ltp":0.0,"tv":0.0,"id":13114902},{"batb":[[0,1.01,0.51],[1,1.01,0]],"batl":[[0,1.15,148.39],[1,1.15,0]],"ltp":2.6,"tv":103.63,"id":13114898},{"batb":[[0,15,5.04],[1,1.01,0.51],[2,1.01,0]],"ltp":0.0,"tv":0.0,"id":14819608}]}]}
{"op":"mcm","clk":"1003787847","pt":1580652015694,"mc":[{"id":"1.168213438","rc":[{"batl":[[0,1.06,387.59],[1,1.15,148.39]],"ltp":2.6,"tv":103.63,"id":13114898}]}]}
{"op":"mcm","clk":"1003787884","pt":1580652015902,"mc":[{"id":"1.168213438","rc":[{"batb":[[0,1.01,0.51],[1,1.01,0]],"ltp":0.0,"tv":0.0,"id":13114902},{"batl":[[1,1.15,0]],"ltp":2.6,"tv":103.63,"id":13114898},{"batb":[[0,1.01,0.51],[1,1.01,0]],"ltp":0.0,"tv":0.0,"id":14819608}]}]}
{"op":"mcm","clk":"1003792546","pt":1580652038412,"mc":[{"id":"1.168213438","rc":[{"batb":[[0,18,15.12],[1,1.01,0.51]],"ltp":0.0,"tv":0.0,"id":14819609}]}]}
{"op":"mcm","clk":"1003814281","pt":1580652142217,"mc":[{"id":"1.168213438","rc":[{"batb":[[0,30,2.83],[1,1.01,0.51]],"ltp":0.0,"tv":0.0,"id":13114902},{"batl":[[0,1.06,134.86]],"ltp":2.6,"tv":103.63,"id":13114898}]}]}
{"op":"mcm","clk":"1003819397","pt":1580652165706,"mc":[{"id":"1.168213438","rc":[{"batl":[[0,1.06,387.59]],"ltp":2.6,"tv":103.63,"id":13114898}]}]}
{"op":"mcm","clk":"1003819456","pt":1580652165991,"mc":[{"id":"1.168213438","rc":[{"batb":[[0,1.01,0.51],[1,1.01,0]],"ltp":0.0,"tv":0.0,"id":13114902}]}]}
{"op":"mcm","clk":"1003831027","pt":1580652216536,"mc":[{"id":"1.168213438","rc":[{"batb":[[0,30,2.79],[1,1.01,0.51]],"ltp":0.0,"tv":0.0,"id":13114902},{"batb":[[0,30,2.87],[1,1.01,0.51]],"ltp":0.0,"tv":0.0,"id":14819608}]}]}
{"op":"mcm","clk":"1003831307","pt":1580652217733,"mc":[{"id":"1.168213438","rc":[{"batl":[[0,1.06,138.32]],"ltp":2.6,"tv":103.63,"id":13114898}]}]}
{"op":"mcm","clk":"1003841536","pt":1580652260649,"mc":[{"id":"1.168213438","rc":[{"batl":[[0,1.06,387.59]],"ltp":2.6,"tv":103.63,"id":13114898}]}]}
{"op":"mcm","clk":"1003841687","pt":1580652261260,"mc":[{"id":"1.168213438","rc":[{"batb":[[0,1.01,0.51],[1,1.01,0]],"ltp":0.0,"tv":0.0,"id":13114902},{"batb":[[0,1.01,0.51],[1,1.01,0]],"ltp":0.0,"tv":0.0,"id":14819608}]}]}
{"op":"mcm","clk":"1003848343","pt":1580652290045,"mc":[{"id":"1.168213438","marketDefinition":{"bspMarket":false,"turnInPlayEnabled":true,"persistenceEnabled":true,"marketBaseRate":5.0,"eventId":"29681204","eventTypeId":"2","numberOfWinners":1,"bettingType":"ODDS","marketType":"SET_BETTING","marketTime":"2020-02-02T12:47:00.000Z","suspendTime":"2020-02-02T12:47:00.000Z","bspReconciled":false,"complete":true,"inPlay":true,"crossMatching":true,"runnersVoidable":false,"numberOfActiveRunners":4,"betDelay":3,"status":"SUSPENDED","runners":[{"status":"ACTIVE","sortPriority":1,"id":13114898,"name":"Golubev/Nedovyesov 2-0"},{"status":"ACTIVE","sortPriority":2,"id":13114902,"name":"Golubev/Nedovyesov 2-1"},{"status":"ACTIVE","sortPriority":3,"id":14819609,"name":"Sabanov/Sabanov 2-0"},{"status":"ACTIVE","sortPriority":4,"id":14819608,"name":"Sabanov/Sabanov 2-1"}],"regulators":["MR_INT"],"countryCode":"FR","discountAllowed":true,"timezone":"UTC","openDate":"2020-02-02T12:47:00.000Z","version":3149102939,"name":"Set Betting","eventName":"Golubev/Nedovyesov v Sabanov/Sabanov"}}]}
{"op":"mcm","clk":"1003856377","pt":1580652321801,"mc":[{"id":"1.168213438","tv":0.0}]}
{"op":"mcm","clk":"1003856759","pt":1580652323208,"mc":[{"id":"1.168213438","marketDefinition":{"bspMarket":false,"turnInPlayEnabled":true,"persistenceEnabled":true,"marketBaseRate":5.0,"eventId":"29681204","eventTypeId":"2","numberOfWinners":1,"bettingType":"ODDS","marketType":"SET_BETTING","marketTime":"2020-02-02T12:47:00.000Z","suspendTime":"2020-02-02T12:47:00.000Z","bspReconciled":false,"complete":true,"inPlay":true,"crossMatching":false,"runnersVoidable":false,"numberOfActiveRunners":0,"betDelay":3,"status":"CLOSED","settledTime":"2020-02-02T14:05:20.000Z","runners":[{"status":"WINNER","sortPriority":1,"id":13114898,"name":"Golubev/Nedovyesov 2-0"},{"status":"LOSER","sortPriority":2,"id":13114902,"name":"Golubev/Nedovyesov 2-1"},{"status":"LOSER","sortPriority":3,"id":14819609,"name":"Sabanov/Sabanov 2-0"},{"status":"LOSER","sortPriority":4,"id":14819608,"name":"Sabanov/Sabanov 2-1"}],"regulators":["MR_INT"],"countryCode":"FR","discountAllowed":true,"timezone":"UTC","openDate":"2020-02-02T12:47:00.000Z","version":3149107866,"name":"Set Betting","eventName":"Golubev/Nedovyesov v Sabanov/Sabanov"}}]}
