{"op":"mcm","clk":"1001179394","pt":1580585281138,"mc":[{"id":"1.168224553","marketDefinition":{"bspMarket":false,"turnInPlayEnabled":true,"persistenceEnabled":true,"marketBaseRate":5.0,"eventId":"29681742","eventTypeId":"2","numberOfWinners":1,"bettingType":"ODDS","marketType":"SET_BETTING","marketTime":"2020-02-02T09:00:00.000Z","suspendTime":"2020-02-02T09:00:00.000Z","bspReconciled":false,"complete":true,"inPlay":false,"crossMatching":false,"runnersVoidable":false,"numberOfActiveRunners":4,"betDelay":0,"status":"OPEN","runners":[{"status":"ACTIVE","sortPriority":1,"id":12982356,"name":"Dzumhur 2-0"},{"status":"ACTIVE","sortPriority":2,"id":12982355,"name":"Dzumhur 2-1"},{"status":"ACTIVE","sortPriority":3,"id":13015345,"name":"Halys 2-0"},{"status":"ACTIVE","sortPriority":4,"id":13015344,"name":"Halys 2-1"}],"regulators":["MR_INT"],"countryCode":"FR","discountAllowed":false,"timezone":"UTC","openDate":"2020-02-02T09:00:00.000Z","version":3147098913,"name":"Set Betting","eventName":"Dzumhur v Halys"}}]}
{"op":"mcm","clk":"1001179667","pt":1580585282545,"mc":[{"id":"1.168224553","marketDefinition":{"bspMarket":false,"turnInPlayEnabled":true,"persistenceEnabled":true,"marketBaseRate":5.0,"eventId":"29681742","eventTypeId":"2","numberOfWinners":1,"bettingType":"ODDS","marketType":"SET_BETTING","marketTime":"2020-02-02T09:00:00.000Z","suspendTime":"2020-02-02T09:00:00.000Z","bspReconciled":false,"complete":true,"inPlay":false,"crossMatching":false,"runnersVoidable":false,"numberOfActiveRunners":4,"betDelay":0,"status":"OPEN","runners":[{"status":"ACTIVE","sortPriority":1,"id":12982356,"name":"Dzumhur 2-0"},{"status":"ACTIVE","sortPriority":2,"id":12982355,"name":"Dzumhur 2-1"},{"status":"ACTIVE","sortPriority":3,"id":13015345,"name":"Halys 2-0"},{"status":"ACTIVE","sortPriority":4,"id":13015344,"name":"Halys 2-1"}],"regulators":["MR_INT"],"countryCode":"FR","discountAllowed":false,"timezone":"UTC","openDate":"2020-02-02T09:00:00.000Z","version":3147098913,"name":"Set Betting","eventName":"Dzumhur v Halys"}}]}
{"op":"mcm","clk":"1001179866","pt":1580585283504,"mc":[{"id":"1.168224553","marketDefinition":{"bspMarket":false,"turnInPlayEnabled":true,"persistenceEnabled":true,"marketBaseRate":5.0,"eventId":"29681742","eventTypeId":"2","numberOfWinners":1,"bettingType":"ODDS","marketType":"SET_BETTING","marketTime":"2020-02-02T09:00:00.000Z","suspendTime":"2020-02-02T09:00:00.000Z","bspReconciled":false,"complete":true,"inPlay":false,"crossMatching":false,"runnersVoidable":false,"numberOfActiveRunners":4,"betDelay":0,"status":"OPEN","runners":[{"status":"ACTIVE","sortPriority":1,"id":12982356,"name":"Dzumhur 2-0"},{"status":"ACTIVE","sortPriority":2,"id":12982355,"name":"Dzumhur 2-1"},{"status":"ACTIVE","sortPriority":3,"id":13015345,"name":"Halys 2-0"},{"status":"ACTIVE","sortPriority":4,"id":13015344,"name":"Halys 2-1"}],"regulators":["MR_INT"],"countryCode":"FR","discountAllowed":true,"timezone":"UTC","openDate":"2020-02-02T09:00:00.000Z","version":3147098913,"name":"Set Betting","eventName":"Dzumhur v Halys"}}]}
{"op":"mcm","clk":"1001222203","pt":1580585513427,"mc":[{"id":"1.168224553","marketDefinition":{"bspMarket":false,"turnInPlayEnabled":true,"persistenceEnabled":true,"marketBaseRate":5.0,"eventId":"29681742","eventTypeId":"2","numberOfWinners":1,"bettingType":"ODDS","marketType":"SET_BETTING","marketTime":"2020-02-02T13:30:00.000Z","suspendTime":"2020-02-02T13:30:00.000Z","bspReconciled":false,"complete":true,"inPlay":false,"crossMatching":false,"runnersVoidable":false,"numberOfActiveRunners":4,"betDelay":0,"status":"OPEN","runners":[{"status":"ACTIVE","sortPriority":1,"id":12982356,"name":"Dzumhur 2-0"},{"status":"ACTIVE","sortPriority":2,"id":12982355,"name":"Dzumhur 2-1"},{"status":"ACTIVE","sortPriority":3,"id":13015345,"name":"Halys 2-0"},{"status":"ACTIVE","sortPriority":4,"id":13015344,"name":"Halys 2-1"}],"regulators":["MR_INT"],"countryCode":"FR","discountAllowed":true,"timezone":"UTC","openDate":"2020-02-02T09:00:00.000Z","version":3147124719,"name":"Set Betting","eventName":"Dzumhur v Halys"}}]}
{"op":"mcm","clk":"1001222802","pt":1580585516439,"mc":[{"id":"1.168224553","marketDefinition":{"bspMarket":false,"turnInPlayEnabled":true,"persistenceEnabled":true,"marketBaseRate":5.0,"eventId":"29681742","eventTypeId":"2","numberOfWinners":1,"bettingType":"ODDS","marketType":"SET_BETTING","marketTime":"2020-02-02T13:30:00.000Z","suspendTime":"2020-02-02T13:30:00.000Z","bspReconciled":false,"complete":true,"inPlay":false,"crossMatching":false,"runnersVoidable":false,"numberOfActiveRunners":4,"betDelay":0,"status":"OPEN","runners":[{"status":"ACTIVE","sortPriority":1,"id":12982356,"name":"Dzumhur 2-0"},{"status":"ACTIVE","sortPriority":2,"id":12982355,"name":"Dzumhur 2-1"},{"status":"ACTIVE","sortPriority":3,"id":13015345,"name":"Halys 2-0"},{"status":"ACTIVE","sortPriority":4,"id":13015344,"name":"Halys 2-1"}],"regulators":["MR_INT"],"countryCode":"FR","discountAllowed":true,"timezone":"UTC","openDate":"2020-02-02T13:30:00.000Z","version":3147124719,"name":"Set Betting","eventName":"Dzumhur v Halys"}}]}
{"op":"mcm","clk":"1001665704","pt":1580587947756,"mc":[{"id":"1.168224553","rc":[{"batb":[[0,1.02,2]],"ltp":0.0,"tv":0.0,"id":12982356},{"batb":[[0,1.02,2]],"ltp":0.0,"tv":0.0,"id":12982355},{"batb":[[0,1.02,2]],"ltp":0.0,"tv":0.0,"id":13015345},{"batb":[[0,1.02,2]],"ltp":0.0,"tv":0.0,"id":13015344}]}]}
{"op":"mcm","clk":"1003032822","pt":1580602188482,"mc":[{"id":"1.168224553","rc":[{"batb":[[1,1.01,0.51]],"ltp":0.0,"tv":0.0,"id":12982356},{"batb":[[1,1.01,0.51]],"ltp":0.0,"tv":0.0,"id":12982355},{"batb":[[1,1.01,0.51]],"ltp":0.0,"tv":0.0,"id":13015345},{"batb":[[1,1.01,0.51]],"ltp":0.0,"tv":0.0,"id":13015344}]}]}
{"op":"mcm","clk":"1003160539","pt":1580603728152,"mc":[{"id":"1.168224553","rc":[{"batb":[[1,1.01,1.01]],"ltp":0.0,"tv":0.0,"id":12982356},{"batb":[[1,1.01,1.01]],"ltp":0.0,"tv":0.0,"id":12982355},{"batb":[[1,1.01,1.01]],"ltp":0.0,"tv":0.0,"id":13015345},{"batb":[[1,1.01,1.01]],"ltp":0.0,"tv":0.0,"id":13015344}]}]}
{"op":"mcm","clk":"1004449766","pt":1580630119139,"mc":[{"id":"1.168224553","rc":[{"batb":[[0,1.98,30.29],[1,1.02,2],[2,1.01,1.01]],"ltp":0.0,"tv":0.0,"id":12982356}]}]}
{"op":"mcm","clk":"1004494894","pt":1580631092661,"mc":[{"id":"1.168224553","rc":[{"batb":[[0,1.92,30.29]],"ltp":0.0,"tv":0.0,"id":12982356}]}]}
{"op":"mcm","clk":"1004691847","pt":1580635314870,"mc":[{"id":"1.168224553","marketDefinition":{"bspMarket":false,"turnInPlayEnabled":true,"persistenceEnabled":true,"marketBaseRate":5.0,"eventId":"29681742","eventTypeId":"2","numberOfWinners":1,"bettingType":"ODDS","marketType":"SET_BETTING","marketTime":"2020-02-02T13:19:00.000Z","suspendTime":"2020-02-02T13:19:00.000Z","bspReconciled":false,"complete":true,"inPlay":false,"crossMatching":false,"runnersVoidable":false,"numberOfActiveRunners":4,"betDelay":0,"status":"OPEN","runners":[{"status":"ACTIVE","sortPriority":1,"id":12982356,"name":"Dzumhur 2-0"},{"status":"ACTIVE","sortPriority":2,"id":12982355,"name":"Dzumhur 2-1"},{"status":"ACTIVE","sortPriority":3,"id":13015345,"name":"Halys 2-0"},{"status":"ACTIVE","sortPriority":4,"id":13015344,"name":"Halys 2-1"}],"regulators":["MR_INT"],"countryCode":"FR","discountAllowed":true,"timezone":"UTC","openDate":"2020-02-02T13:30:00.000Z","version":3148342676,"name":"Set Betting","eventName":"Dzumhur v Halys"}}]}
{"op":"mcm","clk":"1004692024","pt":1580635317913,"mc":[{"id":"1.168224553","marketDefinition":{"bspMarket":false,"turnInPlayEnabled":true,"persistenceEnabled":true,"marketBaseRate":5.0,"eventId":"29681742","eventTypeId":"2","numberOfWinners":1,"bettingType":"ODDS","marketType":"SET_BETTING","marketTime":"2020-02-02T13:19:00.000Z","suspendTime":"2020-02-02T13:19:00.000Z","bspReconciled":false,"complete":true,"inPlay":false,"crossMatching":false,"runnersVoidable":false,"numberOfActiveRunners":4,"betDelay":0,"status":"OPEN","runners":[{"status":"ACTIVE","sortPriority":1,"id":12982356,"name":"Dzumhur 2-0"},{"status":"ACTIVE","sortPriority":2,"id":12982355,"name":"Dzumhur 2-1"},{"status":"ACTIVE","sortPriority":3,"id":13015345,"name":"Halys 2-0"},{"status":"ACTIVE","sortPriority":4,"id":13015344,"name":"Halys 2-1"}],"regulators":["MR_INT"],"countryCode":"FR","discountAllowed":true,"timezone":"UTC","openDate":"2020-02-02T13:19:00.000Z","version":3148342676,"name":"Set Betting","eventName":"Dzumhur v Halys"}}]}
{"op":"mcm","clk":"1005237073","pt":1580641614817,"mc":[{"id":"1.168224553","marketDefinition":{"bspMarket":false,"turnInPlayEnabled":true,"persistenceEnabled":true,"marketBaseRate":5.0,"eventId":"29681742","eventTypeId":"2","numberOfWinners":1,"bettingType":"ODDS","marketType":"SET_BETTING","marketTime":"2020-02-02T13:10:00.000Z","suspendTime":"2020-02-02T13:10:00.000Z","bspReconciled":false,"complete":true,"inPlay":false,"crossMatching":false,"runnersVoidable":false,"numberOfActiveRunners":4,"betDelay":0,"status":"OPEN","runners":[{"status":"ACTIVE","sortPriority":1,"id":12982356,"name":"Dzumhur 2-0"},{"status":"ACTIVE","sortPriority":2,"id":12982355,"name":"Dzumhur 2-1"},{"status":"ACTIVE","sortPriority":3,"id":13015345,"name":"Halys 2-0"},{"status":"ACTIVE","sortPriority":4,"id":13015344,"name":"Halys 2-1"}],"regulators":["MR_INT"],"countryCode":"FR","discountAllowed":true,"timezone":"UTC","openDate":"2020-02-02T13:19:00.000Z","version":3148499225,"name":"Set Betting","eventName":"Dzumhur v Halys"}}]}
{"op":"mcm","clk":"1005237509","pt":1580641616832,"mc":[{"id":"1.168224553","marketDefinition":{"bspMarket":false,"turnInPlayEnabled":true,"persistenceEnabled":true,"marketBaseRate":5.0,"eventId":"29681742","eventTypeId":"2","numberOfWinners":1,"bettingType":"ODDS","marketType":"SET_BETTING","marketTime":"2020-02-02T13:10:00.000Z","suspendTime":"2020-02-02T13:10:00.000Z","bspReconciled":false,"complete":true,"inPlay":false,"crossMatching":false,"runnersVoidable":false,"numberOfActiveRunners":4,"betDelay":0,"status":"OPEN","runners":[{"status":"ACTIVE","sortPriority":1,"id":12982356,"name":"Dzumhur 2-0"},{"status":"ACTIVE","sortPriority":2,"id":12982355,"name":"Dzumhur 2-1"},{"status":"ACTIVE","sortPriority":3,"id":13015345,"name":"Halys 2-0"},{"status":"ACTIVE","sortPriority":4,"id":13015344,"name":"Halys 2-1"}],"regulators":["MR_INT"],"countryCode":"FR","discountAllowed":true,"timezone":"UTC","openDate":"2020-02-02T13:10:00.000Z","version":3148499225,"name":"Set Betting","eventName":"Dzumhur v Halys"}}]}
{"op":"mcm","clk":"1005295374","pt":1580641914620,"mc":[{"id":"1.168224553","marketDefinition":{"bspMarket":false,"turnInPlayEnabled":true,"persistenceEnabled":true,"marketBaseRate":5.0,"eventId":"29681742","eventTypeId":"2","numberOfWinners":1,"bettingType":"ODDS","marketType":"SET_BETTING","marketTime":"2020-02-02T13:08:00.000Z","suspendTime":"2020-02-02T13:08:00.000Z","bspReconciled":false,"complete":true,"inPlay":false,"crossMatching":false,"runnersVoidable":false,"numberOfActiveRunners":4,"betDelay":0,"status":"OPEN","runners":[{"status":"ACTIVE","sortPriority":1,"id":12982356,"name":"Dzumhur 2-0"},{"status":"ACTIVE","sortPriority":2,"id":12982355,"name":"Dzumhur 2-1"},{"status":"ACTIVE","sortPriority":3,"id":13015345,"name":"Halys 2-0"},{"status":"ACTIVE","sortPriority":4,"id":13015344,"name":"Halys 2-1"}],"regulators":["MR_INT"],"countryCode":"FR","discountAllowed":true,"timezone":"UTC","openDate":"2020-02-02T13:10:00.000Z","version":3148508350,"name":"Set Betting","eventName":"Dzumhur v Halys"}}]}
{"op":"mcm","clk":"1005295947","pt":1580641917627,"mc":[{"id":"1.168224553","marketDefinition":{"bspMarket":false,"turnInPlayEnabled":true,"persistenceEnabled":true,"marketBaseRate":5.0,"eventId":"29681742","eventTypeId":"2","numberOfWinners":1,"bettingType":"ODDS","marketType":"SET_BETTING","marketTime":"2020-02-02T13:08:00.000Z","suspendTime":"2020-02-02T13:08:00.000Z","bspReconciled":false,"complete":true,"inPlay":false,"crossMatching":false,"runnersVoidable":false,"numberOfActiveRunners":4,"betDelay":0,"status":"OPEN","runners":[{"status":"ACTIVE","sortPriority":1,"id":12982356,"name":"Dzumhur 2-0"},{"status":"ACTIVE","sortPriority":2,"id":12982355,"name":"Dzumhur 2-1"},{"status":"ACTIVE","sortPriority":3,"id":13015345,"name":"Halys 2-0"},{"status":"ACTIVE","sortPriority":4,"id":13015344,"name":"Halys 2-1"}],"regulators":["MR_INT"],"countryCode":"FR","discountAllowed":true,"timezone":"UTC","openDate":"2020-02-02T13:08:00.000Z","version":3148508350,"name":"Set Betting","eventName":"Dzumhur v Halys"}}]}
{"op":"mcm","clk":"1005340679","pt":1580642171062,"mc":[{"id":"1.168224553","rc":[{"batb":[[0,1.02,2],[1,1.01,1.01],[2,1.01,0]],"ltp":0.0,"tv":0.0,"id":12982356}]}]}
{"op":"mcm","clk":"1006121905","pt":1580646610461,"mc":[{"id":"1.168224553","rc":[{"batb":[[0,2.38,16.92],[1,1.02,2],[2,1.01,1.01]],"batl":[[0,2.58,16.52]],"ltp":0.0,"tv":0.0,"id":12982356},{"batb":[[0,4.3,18.73],[1,1.02,2],[2,1.01,1.01]],"batl":[[0,5,17.78]],"ltp":0.0,"tv":0.0,"id":12982355},{"batb":[[0,4.3,19.2],[1,1.02,2],[2,1.01,1.01]],"batl":[[0,4.9,18.33]],"ltp":0.0,"tv":0.0,"id":13015345},{"batb":[[0,5.6,20.54],[1,1.02,2],[2,1.01,1.01]],"batl":[[0,6.8,19.04]],"ltp":0.0,"tv":0.0,"id":13015344}]}]}
{"op":"mcm","clk":"1006140282","pt":1580646714573,"mc":[{"id":"1.168224553","marketDefinition":{"bspMarket":false,"turnInPlayEnabled":true,"persistenceEnabled":true,"marketBaseRate":5.0,"eventId":"29681742","eventTypeId":"2","numberOfWinners":1,"bettingType":"ODDS","marketType":"SET_BETTING","marketTime":"2020-02-02T12:28:00.000Z","suspendTime":"2020-02-02T12:28:00.000Z","bspReconciled":false,"complete":true,"inPlay":false,"crossMatching":false,"runnersVoidable":false,"numberOfActiveRunners":4,"betDelay":0,"status":"OPEN","runners":[{"status":"ACTIVE","sortPriority":1,"id":12982356,"name":"Dzumhur 2-0"},{"status":"ACTIVE","sortPriority":2,"id":12982355,"name":"Dzumhur 2-1"},{"status":"ACTIVE","sortPriority":3,"id":13015345,"name":"Halys 2-0"},{"status":"ACTIVE","sortPriority":4,"id":13015344,"name":"Halys 2-1"}],"regulators":["MR_INT"],"countryCode":"FR","discountAllowed":true,"timezone":"UTC","openDate":"2020-02-02T13:08:00.000Z","version":3148727319,"name":"Set Betting","eventName":"Dzumhur v Halys"}}]}
{"op":"mcm","clk":"1006141082","pt":1580646718562,"mc":[{"id":"1.168224553","marketDefinition":{"bspMarket":false,"turnInPlayEnabled":true,"persistenceEnabled":true,"marketBaseRate":5.0,"eventId":"29681742","eventTypeId":"2","numberOfWinners":1,"bettingType":"ODDS","marketType":"SET_BETTING","marketTime":"2020-02-02T12:28:00.000Z","suspendTime":"2020-02-02T12:28:00.000Z","bspReconciled":false,"complete":true,"inPlay":false,"crossMatching":false,"runnersVoidable":false,"numberOfActiveRunners":4,"betDelay":0,"status":"OPEN","runners":[{"status":"ACTIVE","sortPriority":1,"id":12982356,"name":"Dzumhur 2-0"},{"status":"ACTIVE","sortPriority":2,"id":12982355,"name":"Dzumhur 2-1"},{"status":"ACTIVE","sortPriority":3,"id":13015345,"name":"Halys 2-0"},{"status":"ACTIVE","sortPriority":4,"id":13015344,"name":"Halys 2-1"}],"regulators":["MR_INT"],"countryCode":"FR","discountAllowed":true,"timezone":"UTC","openDate":"2020-02-02T12:28:00.000Z","version":3148727319,"name":"Set Betting","eventName":"Dzumhur v Halys"}}]}
{"op":"mcm","clk":"1006162335","pt":1580646839426,"mc":[{"id":"1.168224553","rc":[{"batl":[[1,5,18.18]],"ltp":0.0,"tv":0.0,"id":13015345}]}]}
{"op":"mcm","clk":"1006162371","pt":1580646839630,"mc":[{"id":"1.168224553","rc":[{"batl":[[0,5,18.18],[1,5,0]],"ltp":0.0,"tv":0.0,"id":13015345},{"batb":[[0,5.6,20.38]],"ltp":0.0,"tv":0.0,"id":13015344}]}]}
{"op":"mcm","clk":"1006185677","pt":1580646959872,"mc":[{"id":"1.168224553","rc":[{"batb":[[1,2.36,30.25],[2,1.02,2]],"batl":[[1,2.64,25.21]],"ltp":0.0,"tv":0.0,"id":12982356},{"batb":[[1,4,13.44],[2,1.02,2]],"batl":[[0,4.8,10.92],[1,5,17.78]],"ltp":0.0,"tv":0.0,"id":12982355},{"batb":[[0,4.5,11.76],[1,4.3,19.2],[2,1.02,2]],"batl":[[1,5.5,9.24]],"ltp":0.0,"tv":0.0,"id":13015345},{"batb":[[1,5.3,9.24],[2,1.02,2]],"batl":[[0,6.6,6.72],[1,6.8,19.04]],"ltp":0.0,"tv":0.0,"id":13015344}]}]}
{"op":"mcm","clk":"1006188182","pt":1580646973322,"mc":[{"id":"1.168224553","marketDefinition":{"bspMarket":false,"turnInPlayEnabled":true,"persistenceEnabled":true,"marketBaseRate":5.0,"eventId":"29681742","eventTypeId":"2","numberOfWinners":1,"bettingType":"ODDS","marketType":"SET_BETTING","marketTime":"2020-02-02T12:28:00.000Z","suspendTime":"2020-02-02T12:28:00.000Z","bspReconciled":false,"complete":true,"inPlay":false,"crossMatching":true,"runnersVoidable":false,"numberOfActiveRunners":4,"betDelay":0,"status":"OPEN","runners":[{"status":"ACTIVE","sortPriority":1,"id":12982356,"name":"Dzumhur 2-0"},{"status":"ACTIVE","sortPriority":2,"id":12982355,"name":"Dzumhur 2-1"},{"status":"ACTIVE","sortPriority":3,"id":13015345,"name":"Halys 2-0"},{"status":"ACTIVE","sortPriority":4,"id":13015344,"name":"Halys 2-1"}],"regulators":["MR_INT"],"countryCode":"FR","discountAllowed":true,"timezone":"UTC","openDate":"2020-02-02T12:28:00.000Z","version":3148727319,"name":"Set Betting","eventName":"Dzumhur v Halys"}}]}
{"op":"mcm","clk":"1006209388","pt":1580647080161,"mc":[{"id":"1.168224553","rc":[{"batb":[[1,4.3,18.96]],"batl":[[0,5,18.02]],"ltp":0.0,"tv":0.0,"id":13015345},{"batb":[[0,5.6,20.22]],"batl":[[1,6.8,18.8]],"ltp":0.0,"tv":0.0,"id":13015344}]}]}
{"op":"mcm","clk":"1006238006","pt":1580647222420,"mc":[{"id":"1.168224553","rc":[{"batb":[[0,2.36,30.25],[1,1.02,2],[2,1.01,1.01]],"batl":[[0,2.64,25.21],[1,2.64,0]],"ltp":0.0,"tv":0.0,"id":12982356},{"batb":[[0,4,13.44],[1,1.02,2],[2,1.01,1.01]],"batl":[[1,5,0]],"ltp":0.0,"tv":0.0,"id":12982355},{"batb":[[1,1.02,2],[2,1.01,1.01]],"batl":[[0,5.5,9.24],[1,5.5,0]],"ltp":0.0,"tv":0.0,"id":13015345},{"batb":[[0,5.3,9.24],[1,1.02,2],[2,1.01,1.01]],"batl":[[1,6.8,0]],"ltp":0.0,"tv":0.0,"id":13015344}]}]}
{"op":"mcm","clk":"1006238227","pt":1580647223354,"mc":[{"id":"1.168224553","marketDefinition":{"bspMarket":false,"turnInPlayEnabled":true,"persistenceEnabled":true,"marketBaseRate":5.0,"eventId":"29681742","eventTypeId":"2","numberOfWinners":1,"bettingType":"ODDS","marketType":"SET_BETTING","marketTime":"2020-02-02T12:28:00.000Z","suspendTime":"2020-02-02T12:28:00.000Z","bspReconciled":false,"complete":true,"inPlay":true,"crossMatching":true,"runnersVoidable":false,"numberOfActiveRunners":4,"betDelay":3,"status":"OPEN","runners":[{"status":"ACTIVE","sortPriority":1,"id":12982356,"name":"Dzumhur 2-0"},{"status":"ACTIVE","sortPriority":2,"id":12982355,"name":"Dzumhur 2-1"},{"status":"ACTIVE","sortPriority":3,"id":13015345,"name":"Halys 2-0"},{"status":"ACTIVE","sortPriority":4,"id":13015344,"name":"Halys 2-1"}],"regulators":["MR_INT"],"countryCode":"FR","discountAllowed":true,"timezone":"UTC","openDate":"2020-02-02T12:28:00.000Z","version":3148750635,"name":"Set Betting","eventName":"Dzumhur v Halys"},"rc":[{"batb":[[0,1.01,0.51],[1,1.02,0],[2,1.01,0]],"ltp":0.0,"tv":0.0,"id":12982356},{"batb":[[0,1.01,0.51],[1,1.02,0],[2,1.01,0]],"ltp":0.0,"tv":0.0,"id":12982355},{"batb":[[0,1.01,0.51],[1,1.02,0],[2,1.01,0]],"ltp":0.0,"tv":0.0,"id":13015345},{"batb":[[0,1.01,0.51],[1,1.02,0],[2,1.01,0]],"ltp":0.0,"tv":0.0,"id":13015344}]}]}
{"op":"mcm","clk":"1006238977","pt":1580647226945,"mc":[{"id":"1.168224553","rc":[{"batb":[[0,4.1,56.25],[1,1.01,0.51]],"ltp":0.0,"tv":0.0,"id":12982355},{"batb":[[0,5.8,22.49],[1,1.01,0.51]],"ltp":0.0,"tv":0.0,"id":13015344}]}]}
{"op":"mcm","clk":"1006239219","pt":1580647228230,"mc":[{"id":"1.168224553","rc":[{"batb":[[0,2.38,78.72],[1,2.34,83.92],[2,1.01,0.51]],"ltp":0.0,"tv":0.0,"id":12982356},{"batb":[[0,4.2,51.52],[1,4.1,56.25],[2,1.01,0.51]],"ltp":0.0,"tv":0.0,"id":12982355},{"batb":[[0,4.8,22.48],[1,4.7,37.09],[2,1.01,0.51]],"ltp":0.0,"tv":0.0,"id":13015345},{"batb":[[0,5.9,21.14],[1,5.8,22.49],[2,1.01,0.51]],"ltp":0.0,"tv":0.0,"id":13015344}]}]}
{"op":"mcm","clk":"1006239793","pt":1580647230838,"mc":[{"id":"1.168224553","rc":[{"batb":[[0,1.01,0.51],[1,2.34,0],[2,1.01,0]],"ltp":0.0,"tv":0.0,"id":12982356},{"batb":[[0,4.1,56.25],[1,1.01,0.51],[2,1.01,0]],"ltp":0.0,"tv":0.0,"id":12982355},{"batb":[[0,1.01,0.51],[1,4.7,0],[2,1.01,0]],"ltp":0.0,"tv":0.0,"id":13015345},{"batb":[[0,5.8,22.49],[1,1.01,0.51],[2,1.01,0]],"ltp":0.0,"tv":0.0,"id":13015344}]}]}
{"op":"mcm","clk":"1006240435","pt":1580647233944,"mc":[{"id":"1.168224553","rc":[{"batb":[[0,2.24,56.7],[1,2.22,49.15],[2,1.01,0.51]],"ltp":0.0,"tv":0.0,"id":12982356},{"batb":[[1,4,53.19],[2,1.01,0.51]],"ltp":0.0,"tv":0.0,"id":12982355},{"batb":[[0,4.3,35.24],[1,4.2,47.79],[2,1.01,0.51]],"ltp":0.0,"tv":0.0,"id":13015345},{"batb":[[1,5.7,24.03],[2,1.01,0.51]],"ltp":0.0,"tv":0.0,"id":13015344}]}]}
{"op":"mcm","clk":"1006241361","pt":1580647238431,"mc":[{"id":"1.168224553","rc":[{"batb":[[0,1.01,0.51],[1,4,0],[2,1.01,0]],"ltp":0.0,"tv":0.0,"id":12982355},{"batb":[[0,1.01,0.51],[1,4.2,0],[2,1.01,0]],"ltp":0.0,"tv":0.0,"id":13015345},{"batb":[[0,1.01,0.51],[1,5.7,0],[2,1.01,0]],"ltp":0.0,"tv":0.0,"id":13015344}]}]}
{"op":"mcm","clk":"1006241965","pt":1580647241472,"mc":[{"id":"1.168224553","rc":[{"batb":[[0,4.3,45.96],[1,4.2,47.61],[2,1.01,0.51]],"ltp":0.0,"tv":0.0,"id":12982355},{"batb":[[0,5.3,34.68],[1,5.2,29.32],[2,1.01,0.51]],"ltp":0.0,"tv":0.0,"id":13015345},{"batb":[[0,6,18.98],[1,5.9,22.31],[2,1.01,0.51]],"ltp":0.0,"tv":0.0,"id":13015344}]}]}
{"op":"mcm","clk":"1006242151","pt":1580647242255,"mc":[{"id":"1.168224553","rc":[{"batb":[[2,2.18,21.79]],"batl":[[0,2.36,21.24],[1,2.52,17.62]],"ltp":0.0,"tv":0.0,"id":12982356},{"batb":[[0,4.4,17.39],[1,4.3,64.21],[2,4.2,47.61]],"batl":[[0,5.2,16.6],[1,5.4,15.26]],"ltp":0.0,"tv":0.0,"id":12982355},{"batb":[[2,4.9,13.85]],"batl":[[0,5.7,13.3],[1,7,17.31]],"ltp":0.0,"tv":0.0,"id":13015345},{"batb":[[2,5.7,19.51]],"batl":[[0,7,17.62]],"ltp":0.0,"tv":0.0,"id":13015344}]}]}
{"op":"mcm","clk":"1006242283","pt":1580647242859,"mc":[{"id":"1.168224553","rc":[{"batb":[[2,2.2,34.45]],"ltp":0.0,"tv":0.0,"id":12982356},{"batl":[[0,4.9,10.08],[1,5.2,16.6],[2,5.4,15.26]],"ltp":0.0,"tv":0.0,"id":12982355},{"batb":[[2,5.1,10.08]],"batl":[[1,6.2,7.56],[2,7,17.31]],"ltp":0.0,"tv":0.0,"id":13015345},{"batl":[[0,6.6,6.72],[1,7,17.62]],"ltp":0.0,"tv":0.0,"id":13015344}]}]}
{"op":"mcm","clk":"1006242761","pt":1580647244950,"mc":[{"id":"1.168224553","rc":[{"batl":[[1,2.46,28.57],[2,2.52,17.62]],"ltp":0.0,"tv":0.0,"id":12982356}]}]}
{"op":"mcm","clk":"1006244583","pt":1580647254072,"mc":[{"id":"1.168224553","rc":[{"batb":[[0,2.2,34.45],[1,1.99,28.48],[2,1.01,0.51]],"batl":[[0,2.46,28.57],[1,2.52,17.62],[2,2.52,0]],"ltp":0.0,"tv":0.0,"id":12982356},{"batb":[[0,4.3,18.25],[1,4.2,47.61],[2,4.1,13.44]],"batl":[[1,5.4,15.26],[2,5.4,0]],"ltp":0.0,"tv":0.0,"id":12982355},{"batb":[[0,5.1,10.08],[1,4.4,18.02],[2,1.01,0.51]],"batl":[[0,6.2,7.56],[1,7,17.31],[2,7,0]],"ltp":0.0,"tv":0.0,"id":13015345},{"batb":[[0,5.9,22.31],[1,5.6,20.14],[2,5.4,9.24]],"ltp":0.0,"tv":0.0,"id":13015344}]}]}
{"op":"mcm","clk":"1006244898","pt":1580647255465,"mc":[{"id":"1.168224553","rc":[{"batb":[[0,1.99,28.48],[1,1.01,0.51],[2,1.01,0]],"batl":[[0,2.52,17.62],[1,2.52,0]],"ltp":0.0,"tv":0.0,"id":12982356},{"batb":[[2,1.01,0.51]],"batl":[[0,5.4,15.26],[1,5.4,0]],"ltp":0.0,"tv":0.0,"id":12982355},{"batb":[[0,4.4,18.02],[1,1.01,0.51],[2,1.01,0]],"batl":[[0,7,17.31],[1,7,0]],"ltp":0.0,"tv":0.0,"id":13015345},{"batb":[[2,1.01,0.51]],"batl":[[0,7,17.62],[1,7,0]],"ltp":0.0,"tv":0.0,"id":13015344}]}]}
{"op":"mcm","clk":"1006245219","pt":1580647256962,"mc":[{"id":"1.168224553","rc":[{"batb":[[0,2.04,83.41],[1,2.02,64.82],[2,1.99,28.48]],"ltp":0.0,"tv":0.0,"id":12982356},{"batb":[[2,4.1,50.34]],"ltp":0.0,"tv":0.0,"id":12982355},{"batb":[[0,4.7,54.15],[1,4.6,38.36],[2,4.4,18.02]],"ltp":0.0,"tv":0.0,"id":13015345},{"batb":[[1,5.8,23.13],[2,5.6,20.14]],"ltp":0.0,"tv":0.0,"id":13015344}]}]}
{"op":"mcm","clk":"1006246225","pt":1580647261857,"mc":[{"id":"1.168224553","rc":[{"batb":[[0,1.99,28.48],[1,1.01,0.51],[2,1.99,0]],"ltp":0.0,"tv":0.0,"id":12982356}]}]}
{"op":"mcm","clk":"1006246975","pt":1580647265477,"mc":[{"id":"1.168224553","rc":[{"batb":[[0,2.4,52.35],[1,2.36,82.14],[2,2.34,18.02]],"batl":[[1,2.72,14.48]],"ltp":0.0,"tv":0.0,"id":12982356},{"batb":[[1,4.2,67.28]],"batl":[[0,5.1,17.39],[1,5.2,16.05],[2,5.4,15.26]],"ltp":0.0,"tv":0.0,"id":12982355},{"batl":[[0,5.1,17.23],[1,6,11.96],[2,7,17.31]],"ltp":0.0,"tv":0.0,"id":13015345},{"batl":[[0,6.8,18.25],[1,7,17.62]],"ltp":0.0,"tv":0.0,"id":13015344}]}]}
{"op":"mcm","clk":"1006247008","pt":1580647265724,"mc":[{"id":"1.168224553","rc":[{"batl":[[2,5.4,0]],"ltp":0.0,"tv":0.0,"id":12982355},{"batl":[[2,7,0]],"ltp":0.0,"tv":0.0,"id":13015345},{"batl":[[1,7,0]],"ltp":0.0,"tv":0.0,"id":13015344}]}]}
{"op":"mcm","clk":"1006247191","pt":1580647266491,"mc":[{"id":"1.168224553","rc":[{"batl":[[1,2.6,26.05],[2,2.72,14.48]],"ltp":0.0,"tv":0.0,"id":12982356},{"batl":[[0,4.8,10.92],[1,5.1,17.39],[2,5.2,16.05]],"ltp":0.0,"tv":0.0,"id":12982355},{"batb":[[0,4.7,65.07]],"batl":[[1,5.8,8.4],[2,6,11.96]],"ltp":0.0,"tv":0.0,"id":13015345},{"batl":[[0,6.6,6.72],[1,6.8,18.25]],"ltp":0.0,"tv":0.0,"id":13015344}]}]}
{"op":"mcm","clk":"1006249257","pt":1580647276463,"mc":[{"id":"1.168224553","rc":[{"batb":[[0,2.3,31.93],[1,2.12,23.53],[2,1.01,0.51]],"batl":[[0,2.6,26.05],[1,2.72,14.48],[2,2.72,0]],"ltp":0.0,"tv":0.0,"id":12982356},{"batb":[[0,4.2,19.67],[1,4.1,50.34],[2,3.95,13.44]],"batl":[[1,5.2,16.05],[2,5.2,0]],"ltp":0.0,"tv":0.0,"id":12982355},{"batb":[[0,4.7,10.92],[1,4,22.66],[2,1.01,0.51]],"batl":[[0,5.8,8.4],[1,6,11.96],[2,6,0]],"ltp":0.0,"tv":0.0,"id":13015345},{"batb":[[0,5.8,23.13],[1,5.6,20.14],[2,5.4,9.24]],"ltp":0.0,"tv":0.0,"id":13015344}]}]}
{"op":"mcm","clk":"1006249476","pt":1580647277484,"mc":[{"id":"1.168224553","rc":[{"batb":[[0,2.12,23.53],[1,1.01,0.51],[2,1.01,0]],"batl":[[0,2.72,14.48],[1,2.72,0]],"ltp":0.0,"tv":0.0,"id":12982356},{"batb":[[2,1.01,0.51]],"batl":[[0,5.2,16.05],[1,5.2,0]],"ltp":0.0,"tv":0.0,"id":12982355},{"batb":[[0,4,22.66],[1,1.01,0.51],[2,1.01,0]],"batl":[[0,6,11.96],[1,6,0]],"ltp":0.0,"tv":0.0,"id":13015345},{"batb":[[2,1.01,0.51]],"batl":[[0,6.8,18.25],[1,6.8,0]],"ltp":0.0,"tv":0.0,"id":13015344}]}]}
{"op":"mcm","clk":"1006249829","pt":1580647279298,"mc":[{"id":"1.168224553","rc":[{"batb":[[0,2.18,58.23],[1,2.16,53.2],[2,2.12,23.53]],"ltp":0.0,"tv":0.0,"id":12982356},{"batb":[[2,4,53.21]],"ltp":0.0,"tv":0.0,"id":12982355},{"batb":[[0,4.3,46.45],[1,4.2,47.52],[2,4,22.66]],"ltp":0.0,"tv":0.0,"id":13015345},{"batb":[[1,5.7,23.98],[2,5.6,20.14]],"ltp":0.0,"tv":0.0,"id":13015344}]}]}
{"op":"mcm","clk":"1006250022","pt":1580647280204,"mc":[{"id":"1.168224553","rc":[{"batb":[[0,2.12,23.53],[1,1.01,0.51],[2,2.12,0]],"ltp":0.0,"tv":0.0,"id":12982356}]}]}
{"op":"mcm","clk":"1006250849","pt":1580647284409,"mc":[{"id":"1.168224553","rc":[{"batb":[[0,2.56,71.81],[1,2.52,68.6],[2,2.5,14.79]],"batl":[[1,2.76,23.53],[2,2.9,12.27]],"ltp":0.0,"tv":0.0,"id":12982356},{"batl":[[0,4.7,10.92],[1,4.9,18.65],[2,5,17.47]],"ltp":0.0,"tv":0.0,"id":12982355},{"batb":[[0,4.3,59.05]],"batl":[[0,4.6,21.4],[1,5.3,25.14]],"ltp":0.0,"tv":0.0,"id":13015345},{"batl":[[0,6.4,7.56],[1,6.8,18.25]],"ltp":0.0,"tv":0.0,"id":13015344}]}]}
{"op":"mcm","clk":"1006253134","pt":1580647295627,"mc":[{"id":"1.168224553","rc":[{"batb":[[0,2.28,18.96],[1,1.01,0.51],[2,2.5,0]],"batl":[[0,2.9,12.27],[1,2.76,0],[2,2.9,0]],"ltp":0.0,"tv":0.0,"id":12982356},{"batb":[[1,4,53.21],[2,1.01,0.51]],"batl":[[0,5,17.47],[1,4.9,0],[2,5,0]],"ltp":0.0,"tv":0.0,"id":12982355},{"batb":[[0,3.7,13.38],[1,1.01,0.51],[2,4,0]],"batl":[[0,5.3,15.89],[1,5.3,0]],"ltp":0.0,"tv":0.0,"id":13015345},{"batb":[[0,5.7,23.98],[1,5.5,10.39],[2,1.01,0.51]],"batl":[[0,6.8,18.25],[1,6.8,0]],"ltp":0.0,"tv":0.0,"id":13015344}]}]}
{"op":"mcm","clk":"1006254224","pt":1580647301206,"mc":[{"id":"1.168224553","rc":[{"batb":[[0,2.52,63.88],[1,2.48,71.68],[2,2.28,18.96]],"ltp":0.0,"tv":0.0,"id":12982356},{"batb":[[1,4.1,63.19],[2,4,53.21]],"ltp":0.0,"tv":0.0,"id":12982355},{"batb":[[0,4.4,45.71],[1,4.3,45],[2,3.7,13.38]],"ltp":0.0,"tv":0.0,"id":13015345},{"batb":[[0,5.8,31.13],[1,5.7,23.98],[2,5.5,10.39]],"ltp":0.0,"tv":0.0,"id":13015344}]}]}
{"op":"mcm","clk":"1006254732","pt":1580647304017,"mc":[{"id":"1.168224553","rc":[{"batb":[[0,2.28,18.96],[1,1.01,0.51],[2,2.28,0]],"ltp":0.0,"tv":0.0,"id":12982356},{"batb":[[1,4,53.21],[2,1.01,0.51]],"ltp":0.0,"tv":0.0,"id":12982355},{"batb":[[0,3.7,13.38],[1,1.01,0.51],[2,3.7,0]],"ltp":0.0,"tv":0.0,"id":13015345},{"batb":[[0,5.7,23.98],[1,5.5,10.39],[2,1.01,0.51]],"ltp":0.0,"tv":0.0,"id":13015344}]}]}
{"op":"mcm","clk":"1006255296","pt":1580647306895,"mc":[{"id":"1.168224553","rc":[{"batb":[[0,2.36,55.32],[1,2.32,86.11],[2,2.28,18.96]],"ltp":0.0,"tv":0.0,"id":12982356},{"batb":[[1,4,73.15],[2,3.95,27.57]],"ltp":0.0,"tv":0.0,"id":12982355},{"batb":[[0,4,50.43],[1,3.95,27.75],[2,3.7,13.38]],"ltp":0.0,"tv":0.0,"id":13015345},{"batb":[[0,5.7,34.18],[1,5.6,24.82],[2,5.5,10.39]],"ltp":0.0,"tv":0.0,"id":13015344}]}]}
{"op":"mcm","clk":"1006256256","pt":1580647311776,"mc":[{"id":"1.168224553","rc":[{"batb":[[0,2.28,18.96],[1,1.01,0.51],[2,2.28,0]],"ltp":0.0,"tv":0.0,"id":12982356}]}]}
{"op":"mcm","clk":"1006256974","pt":1580647315408,"mc":[{"id":"1.168224553","rc":[{"batb":[[0,2.74,39.1],[1,2.7,57.34],[2,2.66,12.51]],"batl":[[1,3.05,10.94]],"ltp":0.0,"tv":0.0,"id":12982356},{"batb":[[1,4.1,20.77],[2,4,73.15]],"batl":[[0,4.9,18.8],[1,5,17.47]],"ltp":0.0,"tv":0.0,"id":12982355},{"batl":[[0,4.2,12.98],[1,4.6,21.24],[2,5.3,15.89]],"ltp":0.0,"tv":0.0,"id":13015345}]}]}
{"op":"mcm","clk":"1006257175","pt":1580647316480,"mc":[{"id":"1.168224553","rc":[{"batl":[[0,2.9,34.12]],"ltp":0.0,"tv":0.0,"id":12982356},{"batb":[[0,4.1,20.77],[1,4,73.15],[2,3.95,27.57]],"batl":[[0,4.6,10.92],[1,4.9,18.8]],"ltp":0.0,"tv":0.0,"id":12982355},{"batb":[[0,4.1,13.44],[1,4,50.43],[2,3.95,27.75]],"batl":[[2,4.9,10.08]],"ltp":0.0,"tv":0.0,"id":13015345},{"batl":[[0,6.4,7.56],[1,6.8,18.25]],"ltp":0.0,"tv":0.0,"id":13015344}]}]}
{"op":"mcm","clk":"1006259182","pt":1580647326924,"mc":[{"id":"1.168224553","rc":[{"batb":[[0,2.54,26.89],[1,2.5,14.79],[2,1.01,0.51]],"batl":[[0,2.9,21.85]],"ltp":0.0,"tv":0.0,"id":12982356},{"batb":[[1,4,56.86]],"ltp":0.0,"tv":0.0,"id":12982355},{"batb":[[1,3.55,15.03],[2,1.01,0.51]],"batl":[[0,4.6,21.24],[1,4.9,10.08],[2,4.9,0]],"ltp":0.0,"tv":0.0,"id":13015345},{"batb":[[0,5.7,23.98]],"ltp":0.0,"tv":0.0,"id":13015344}]}]}
{"op":"mcm","clk":"1006259368","pt":1580647327824,"mc":[{"id":"1.168224553","rc":[{"batb":[[0,2.5,14.79],[1,1.01,0.51],[2,1.01,0]],"batl":[[0,3.05,10.94],[1,3.05,0]],"ltp":0.0,"tv":0.0,"id":12982356},{"batl":[[0,4.9,18.8],[1,4.9,0]],"ltp":0.0,"tv":0.0,"id":12982355},{"batb":[[0,3.55,15.03],[1,1.01,0.51],[2,1.01,0]],"batl":[[1,4.9,0]],"ltp":0.0,"tv":0.0,"id":13015345},{"batl":[[0,6.8,18.25],[1,6.8,0]],"ltp":0.0,"tv":0.0,"id":13015344}]}]}
{"op":"mcm","clk":"1006260475","pt":1580647333410,"mc":[{"id":"1.168224553","rc":[{"batb":[[0,2.7,51.46],[1,2.66,59.54],[2,2.5,14.79]],"ltp":0.0,"tv":0.0,"id":12982356},{"batb":[[1,4,78.24]],"ltp":0.0,"tv":0.0,"id":12982355},{"batb":[[0,4.1,25.04],[1,4,53.64],[2,3.55,15.03]],"ltp":0.0,"tv":0.0,"id":13015345},{"batb":[[0,5.7,38]],"ltp":0.0,"tv":0.0,"id":13015344}]}]}
{"op":"mcm","clk":"1006261033","pt":1580647336217,"mc":[{"id":"1.168224553","rc":[{"batb":[[0,2.5,14.79],[1,1.01,0.51],[2,2.5,0]],"ltp":0.0,"tv":0.0,"id":12982356},{"batb":[[1,4,56.86]],"ltp":0.0,"tv":0.0,"id":12982355},{"batb":[[0,3.55,15.03],[1,1.01,0.51],[2,3.55,0]],"ltp":0.0,"tv":0.0,"id":13015345},{"batb":[[0,5.7,23.98]],"ltp":0.0,"tv":0.0,"id":13015344}]}]}
{"op":"mcm","clk":"1006261507","pt":1580647338771,"mc":[{"id":"1.168224553","rc":[{"batb":[[2,1.01,0.51]],"ltp":0.0,"tv":0.0,"id":12982355},{"batb":[[1,5.5,10.39],[2,1.01,0.51]],"ltp":0.0,"tv":0.0,"id":13015344}]}]}
{"op":"mcm","clk":"1006261759","pt":1580647339927,"mc":[{"id":"1.168224553","rc":[{"batb":[[0,2.58,54.04],[1,2.54,67.27],[2,2.5,14.79]],"ltp":0.0,"tv":0.0,"id":12982356}]}]}
{"op":"mcm","clk":"1006262232","pt":1580647342431,"mc":[{"id":"1.168224553","rc":[{"batl":[[0,2.72,14.48],[1,2.78,23.53],[2,2.94,12.04]],"ltp":0.0,"tv":0.0,"id":12982356},{"batb":[[0,4.2,19.75],[1,4.1,65.07],[2,4,56.86]],"batl":[[0,4.7,10.92],[1,4.9,18.8],[2,5.1,17.39]],"ltp":0.0,"tv":0.0,"id":12982355},{"batb":[[0,4.4,11.76],[1,4.3,39.23],[2,4.2,47.64]],"batl":[[1,5.3,9.24],[2,5.4,15.26]],"ltp":0.0,"tv":0.0,"id":13015345},{"batb":[[0,5.8,28.93],[1,5.7,23.98],[2,5.6,20.3]],"batl":[[0,6.6,6.72],[1,6.8,18.25]],"ltp":0.0,"tv":0.0,"id":13015344}]}]}
{"op":"mcm","clk":"1006264929","pt":1580647356143,"mc":[{"id":"1.168224553","rc":[{"batb":[[0,2.44,28.57],[1,2.26,19.51],[2,1.01,0.51]],"batl":[[0,2.78,23.53],[1,2.94,12.04],[2,2.94,0]],"ltp":0.0,"tv":0.0,"id":12982356},{"batb":[[0,4.1,20.77],[1,4,56.86],[2,3.9,14.28]],"batl":[[1,5.1,17.39],[2,5.1,0]],"ltp":0.0,"tv":0.0,"id":12982355},{"batb":[[1,3.7,13.45],[2,1.01,0.51]],"batl":[[0,5.3,9.24],[1,5.4,15.26],[2,5.4,0]],"ltp":0.0,"tv":0.0,"id":13015345},{"batb":[[0,5.7,23.98],[1,5.5,10.39],[2,5.3,9.24]],"ltp":0.0,"tv":0.0,"id":13015344}]}]}
{"op":"mcm","clk":"1006265210","pt":1580647357578,"mc":[{"id":"1.168224553","rc":[{"batb":[[0,2.26,19.51],[1,1.01,0.51],[2,1.01,0]],"batl":[[0,2.94,12.04],[1,2.94,0]],"ltp":0.0,"tv":0.0,"id":12982356},{"batb":[[2,1.01,0.51]],"batl":[[0,5.1,17.39],[1,5.1,0]],"ltp":0.0,"tv":0.0,"id":12982355},{"batb":[[0,3.7,13.45],[1,1.01,0.51],[2,1.01,0]],"batl":[[0,5.4,15.26],[1,5.4,0]],"ltp":0.0,"tv":0.0,"id":13015345},{"batb":[[2,1.01,0.51]],"batl":[[0,6.8,18.25],[1,6.8,0]],"ltp":0.0,"tv":0.0,"id":13015344}]}]}
{"op":"mcm","clk":"1006265465","pt":1580647358964,"mc":[{"id":"1.168224553","rc":[{"batb":[[0,2.34,55.93],[1,2.3,88.21],[2,2.26,19.51]],"ltp":0.0,"tv":0.0,"id":12982356},{"batb":[[2,3.95,27.72]],"ltp":0.0,"tv":0.0,"id":12982355},{"batb":[[0,3.95,49.7],[1,3.9,28.61],[2,3.7,13.45]],"ltp":0.0,"tv":0.0,"id":13015345},{"batb":[[0,5.7,34.74],[1,5.6,24.81],[2,5.5,10.39]],"ltp":0.0,"tv":0.0,"id":13015344}]}]}
{"op":"mcm","clk":"1006266158","pt":1580647362462,"mc":[{"id":"1.168224553","rc":[{"batb":[[0,2.26,19.51],[1,1.01,0.51],[2,2.26,0]],"ltp":0.0,"tv":0.0,"id":12982356}]}]}
{"op":"mcm","clk":"1006266734","pt":1580647365477,"mc":[{"id":"1.168224553","rc":[{"batb":[[0,2.78,36.59],[1,2.74,55.21],[2,2.26,19.51]],"ltp":0.0,"tv":0.0,"id":12982356}]}]}
{"op":"mcm","clk":"1006266931","pt":1580647366353,"mc":[{"id":"1.168224553","rc":[{"batb":[[2,2.7,12.27]],"batl":[[1,3.35,22.27]],"ltp":0.0,"tv":0.0,"id":12982356},{"batb":[[1,4,78.97]],"batl":[[0,4.8,19.67],[1,4.9,18.88]],"ltp":0.0,"tv":0.0,"id":12982355},{"batl":[[0,4.2,13.06],[1,4.6,21.56]],"ltp":0.0,"tv":0.0,"id":13015345}]}]}
{"op":"mcm","clk":"1006266950","pt":1580647366493,"mc":[{"id":"1.168224553","rc":[{"batl":[[1,2.96,21],[2,3.35,22.27]],"ltp":0.0,"tv":0.0,"id":12982356},{"batl":[[0,4.6,10.92],[1,4.8,19.67],[2,4.9,18.88]],"ltp":0.0,"tv":0.0,"id":12982355},{"batb":[[0,4,13.44],[1,3.95,49.7],[2,3.9,28.61]],"batl":[[2,4.8,10.92]],"ltp":0.0,"tv":0.0,"id":13015345},{"batl":[[0,6.4,7.56],[1,6.8,18.25]],"ltp":0.0,"tv":0.0,"id":13015344}]}]}
{"op":"mcm","clk":"1006270141","pt":1580647382394,"mc":[{"id":"1.168224553","rc":[{"batl":[[0,2.92,12.04],[1,2.94,12.04],[2,2.96,21]],"ltp":0.0,"tv":0.0,"id":12982356}]}]}
{"op":"mcm","clk":"1006270161","pt":1580647382498,"mc":[{"id":"1.168224553","rc":[{"batb":[[2,2.68,12.27]],"batl":[[1,2.96,21],[2,3.35,22.27]],"ltp":0.0,"tv":0.0,"id":12982356}]}]}
{"op":"mcm","clk":"1006272703","pt":1580647395629,"mc":[{"id":"1.168224553","rc":[{"batb":[[0,2.68,12.27],[1,2.58,26.05],[2,2.52,14.56]],"ltp":0.0,"tv":0.0,"id":12982356},{"batb":[[1,4,65.95]],"ltp":0.0,"tv":0.0,"id":12982355},{"batb":[[1,3.95,28.01],[2,3.7,13.45]],"ltp":0.0,"tv":0.0,"id":13015345},{"batb":[[0,5.7,24.2],[1,5.5,10.39],[2,5.2,9.24]],"ltp":0.0,"tv":0.0,"id":13015344}]}]}
{"op":"mcm","clk":"1006273264","pt":1580647398505,"mc":[{"id":"1.168224553","rc":[{"batb":[[0,2.76,42.59],[1,2.72,56.08],[2,2.68,12.27]],"ltp":0.0,"tv":0.0,"id":12982356},{"batb":[[0,4,53.35]],"ltp":0.0,"tv":0.0,"id":13015345},{"batb":[[0,5.8,21.95],[1,5.7,24.2],[2,5.5,10.39]],"ltp":0.0,"tv":0.0,"id":13015344}]}]}
{"op":"mcm","clk":"1006274128","pt":1580647402745,"mc":[{"id":"1.168224553","rc":[{"batb":[[0,2.68,12.27],[1,2.58,26.05],[2,2.52,14.56]],"ltp":0.0,"tv":0.0,"id":12982356},{"batb":[[1,4,22.11],[2,3.9,14.28]],"ltp":0.0,"tv":0.0,"id":12982355},{"batb":[[0,4,13.44],[1,3.7,13.45],[2,3.3,17.78]],"ltp":0.0,"tv":0.0,"id":13015345},{"batb":[[0,5.7,23.98],[1,5.5,10.39],[2,5.2,9.24]],"ltp":0.0,"tv":0.0,"id":13015344}]}]}
{"op":"mcm","clk":"1006274727","pt":1580647405622,"mc":[{"id":"1.168224553","rc":[{"batb":[[1,2.6,43.07],[2,2.58,26.05]],"ltp":0.0,"tv":0.0,"id":12982356},{"batb":[[2,3.9,61.79]],"ltp":0.0,"tv":0.0,"id":12982355},{"batb":[[2,3.55,61.51]],"ltp":0.0,"tv":0.0,"id":13015345},{"batb":[[1,5.6,25.16],[2,5.5,10.39]],"ltp":0.0,"tv":0.0,"id":13015344}]}]}
{"op":"mcm","clk":"1006275128","pt":1580647407624,"mc":[{"id":"1.168224553","rc":[{"batb":[[0,2.6,43.07],[1,2.56,65.79],[2,2.52,14.56]],"batl":[[0,3.35,22.27],[1,2.96,0],[2,3.35,0]],"ltp":0.0,"tv":0.0,"id":12982356},{"batb":[[0,4,22.11],[1,3.9,47.51],[2,3.85,29.42]],"batl":[[0,4.9,18.88],[1,4.8,0],[2,4.9,0]],"ltp":0.0,"tv":0.0,"id":12982355},{"batb":[[0,3.55,61.51],[1,3.5,37.2],[2,3.3,17.78]],"batl":[[0,4.6,21.56],[1,4.6,0],[2,4.8,0]],"ltp":0.0,"tv":0.0,"id":13015345},{"batl":[[0,6.8,18.25],[1,6.8,0]],"ltp":0.0,"tv":0.0,"id":13015344}]}]}
{"op":"mcm","clk":"1006275707","pt":1580647410447,"mc":[{"id":"1.168224553","rc":[{"batb":[[0,2.52,14.56],[1,2.5,14.79],[2,1.01,0.51]],"batl":[[0,3.3,22.58],[1,3.35,22.27]],"ltp":0.0,"tv":0.0,"id":12982356},{"batb":[[1,1.01,0.51],[2,3.85,0]],"ltp":0.0,"tv":0.0,"id":12982355},{"batb":[[0,3.35,17.39],[1,3.3,17.78],[2,1.01,0.51]],"ltp":0.0,"tv":0.0,"id":13015345}]}]}
{"op":"mcm","clk":"1006275739","pt":1580647410663,"mc":[{"id":"1.168224553","rc":[{"batb":[[0,2.5,14.79],[1,1.01,0.51],[2,1.01,0]],"batl":[[1,3.35,0]],"ltp":0.0,"tv":0.0,"id":12982356},{"batb":[[1,1.01,0.51],[2,1.01,0]],"batl":[[0,4.6,21.09]],"ltp":0.0,"tv":0.0,"id":13015345}]}]}
{"op":"mcm","clk":"1006277031","pt":1580647417031,"mc":[{"id":"1.168224553","rc":[{"batb":[[0,2.6,43.07],[1,2.56,65.79],[2,2.5,14.79]],"ltp":0.0,"tv":0.0,"id":12982356},{"batb":[[1,3.9,47.51],[2,3.85,29.42]],"ltp":0.0,"tv":0.0,"id":12982355},{"batb":[[0,3.55,61.51],[1,3.5,37.2],[2,3.35,17.39]],"ltp":0.0,"tv":0.0,"id":13015345}]}]}
{"op":"mcm","clk":"1006277824","pt":1580647421035,"mc":[{"id":"1.168224553","rc":[{"batb":[[1,1.01,0.51],[2,3.85,0]],"ltp":0.0,"tv":0.0,"id":12982355},{"batb":[[0,3.35,17.39],[1,1.01,0.51],[2,3.35,0]],"ltp":0.0,"tv":0.0,"id":13015345},{"batb":[[1,5.5,10.39],[2,1.01,0.51]],"ltp":0.0,"tv":0.0,"id":13015344}]}]}
{"op":"mcm","clk":"1006278476","pt":1580647424441,"mc":[{"id":"1.168224553","rc":[{"batb":[[2,2.5,42.52]],"batl":[[0,2.72,14.48],[1,2.84,22.69],[2,3,11.41]],"ltp":0.0,"tv":0.0,"id":12982356},{"batb":[[0,4.1,21.32],[1,4,97.16],[2,3.95,27.45]],"batl":[[0,4.6,10.92],[1,4.8,19.2],[2,4.9,18.65]],"ltp":0.0,"tv":0.0,"id":12982355},{"batb":[[0,4.3,50.05],[1,4.2,47.96],[2,4,22.27]],"batl":[[1,4.9,18.25],[2,5.1,10.08]],"ltp":0.0,"tv":0.0,"id":13015345},{"batb":[[0,5.8,36.13],[1,5.7,23.98],[2,5.6,20.38]],"batl":[[0,6.4,7.56],[1,6.8,18.25]],"ltp":0.0,"tv":0.0,"id":13015344}]}]}
{"op":"mcm","clk":"1006278596","pt":1580647425053,"mc":[{"id":"1.168224553","rc":[{"batb":[[1,4,75.05]],"ltp":0.0,"tv":0.0,"id":12982355}]}]}
{"op":"mcm","clk":"1006280209","pt":1580647433879,"mc":[{"id":"1.168224553","rc":[{"batb":[[0,2.5,27.73],[1,2.4,16.68],[2,1.01,0.51]],"batl":[[0,2.84,22.69],[1,3,11.41],[2,3,0]],"ltp":0.0,"tv":0.0,"id":12982356},{"batb":[[1,4,33.57]],"batl":[[1,4.9,18.65],[2,4.9,0]],"ltp":0.0,"tv":0.0,"id":12982355},{"batb":[[0,4.3,12.6],[1,3.65,14.32],[2,1.01,0.51]],"batl":[[0,4.9,18.25],[1,5.1,10.08],[2,5.1,0]],"ltp":0.0,"tv":0.0,"id":13015345},{"batb":[[0,5.7,23.98],[1,5.6,20.38],[2,5.3,9.24]],"ltp":0.0,"tv":0.0,"id":13015344}]}]}
{"op":"mcm","clk":"1006280391","pt":1580647434887,"mc":[{"id":"1.168224553","rc":[{"batb":[[0,4.6,3.36],[1,4.3,12.6],[2,3.65,14.32]],"ltp":0.0,"tv":0.0,"id":13015345}]}]}
{"op":"mcm","clk":"1006280546","pt":1580647435684,"mc":[{"id":"1.168224553","rc":[{"batb":[[0,2.4,16.68],[1,1.01,0.51],[2,1.01,0]],"batl":[[0,3,11.41],[1,3,0]],"ltp":0.0,"tv":0.0,"id":12982356},{"batl":[[0,4.9,18.65],[1,4.9,0]],"ltp":0.0,"tv":0.0,"id":12982355},{"batb":[[1,3.65,14.32],[2,1.01,0.51]],"batl":[[1,5.1,0]],"ltp":0.0,"tv":0.0,"id":13015345},{"batb":[[2,1.01,0.51]],"batl":[[0,6.8,18.25],[1,6.8,0]],"ltp":0.0,"tv":0.0,"id":13015344}]}]}
{"op":"mcm","clk":"1006280800","pt":1580647437064,"mc":[{"id":"1.168224553","rc":[{"batb":[[0,5.7,24.06]],"ltp":0.0,"tv":0.0,"id":13015344}]}]}
{"op":"mcm","clk":"1006280900","pt":1580647437690,"mc":[{"id":"1.168224553","rc":[{"batb":[[0,3.65,14.32],[1,1.01,0.51],[2,1.01,0]],"ltp":0.0,"tv":0.0,"id":13015345}]}]}
{"op":"mcm","clk":"1006281145","pt":1580647438966,"mc":[{"id":"1.168224553","rc":[{"batb":[[0,2.64,47.42],[1,2.6,63.1],[2,2.4,16.68]],"ltp":0.0,"tv":0.0,"id":12982356},{"batb":[[1,4,66.74]],"ltp":0.0,"tv":0.0,"id":12982355},{"batb":[[0,4.2,44],[1,4.1,50.62],[2,3.65,14.32]],"ltp":0.0,"tv":0.0,"id":13015345},{"batb":[[0,5.8,31.66],[1,5.7,24.06],[2,5.6,20.38]],"ltp":0.0,"tv":0.0,"id":13015344}]}]}
{"op":"mcm","clk":"1006281909","pt":1580647443012,"mc":[{"id":"1.168224553","rc":[{"batb":[[0,2.4,16.68],[1,1.01,0.51],[2,2.4,0]],"ltp":0.0,"tv":0.0,"id":12982356},{"batb":[[1,4,33.57]],"ltp":0.0,"tv":0.0,"id":12982355},{"batb":[[0,3.65,14.32],[1,1.01,0.51],[2,3.65,0]],"ltp":0.0,"tv":0.0,"id":13015345},{"batb":[[0,5.7,24.06],[1,5.6,20.38],[2,1.01,0.51]],"ltp":0.0,"tv":0.0,"id":13015344}]}]}
{"op":"mcm","clk":"1006282526","pt":1580647445867,"mc":[{"id":"1.168224553","rc":[{"batb":[[0,2.48,51.74],[1,2.44,74.8],[2,2.4,16.68]],"ltp":0.0,"tv":0.0,"id":12982356},{"batb":[[0,3.9,35.76],[1,3.85,29.8],[2,3.65,14.32]],"ltp":0.0,"tv":0.0,"id":13015345},{"batb":[[0,5.7,38.3],[1,5.6,45.32]],"ltp":0.0,"tv":0.0,"id":13015344}]}]}
{"op":"mcm","clk":"1006283241","pt":1580647449686,"mc":[{"id":"1.168224553","rc":[{"batb":[[2,1.01,0.51]],"ltp":0.0,"tv":0.0,"id":12982355},{"batb":[[0,3.65,14.32],[1,1.01,0.51],[2,3.65,0]],"ltp":0.0,"tv":0.0,"id":13015345},{"batb":[[0,5.6,20.38],[1,1.01,0.51],[2,1.01,0]],"ltp":0.0,"tv":0.0,"id":13015344}]}]}
{"op":"mcm","clk":"1006283507","pt":1580647450874,"mc":[{"id":"1.168224553","rc":[{"trd":[[4.9,5.88]],"batl":[[0,4.9,15.31]],"ltp":4.9,"tv":5.88,"id":13015345}],"tv":5.88}]}
{"op":"mcm","clk":"1006283960","pt":1580647453271,"mc":[{"id":"1.168224553","rc":[{"batl":[[0,2.6,16.37],[1,2.78,13.69],[2,3,11.41]],"ltp":0.0,"tv":0.0,"id":12982356},{"batb":[[0,4.2,20.3],[1,4.1,66],[2,4,53.13]],"batl":[[1,5,18.18]],"ltp":0.0,"tv":0.0,"id":12982355},{"batb":[[0,4.6,25.21],[1,4.5,41.09],[2,4.3,19.2]],"batl":[[1,5.2,16.29]],"ltp":4.9,"tv":5.88,"id":13015345},{"batb":[[0,5.9,25.31],[1,5.8,23.24],[2,5.6,20.38]],"batl":[[1,7,18.02]],"ltp":0.0,"tv":0.0,"id":13015344}]}]}
{"op":"mcm","clk":"1006284186","pt":1580647454486,"mc":[{"id":"1.168224553","rc":[{"batb":[[2,2.42,29.41]],"batl":[[1,2.74,23.53],[2,2.78,13.69]],"ltp":0.0,"tv":0.0,"id":12982356},{"batb":[[1,4.1,44.68]],"batl":[[0,4.7,10.92],[1,4.9,18.65],[2,5,18.18]],"ltp":0.0,"tv":0.0,"id":12982355},{"batb":[[1,4.5,52.85]],"batl":[[2,5.4,9.24]],"ltp":4.9,"tv":5.88,"id":13015345},{"batl":[[0,6.6,6.72]],"ltp":0.0,"tv":0.0,"id":13015344}]}]}
{"op":"mcm","clk":"1006285576","pt":1580647462114,"mc":[{"id":"1.168224553","rc":[{"batb":[[0,2.42,29.41],[1,2.32,18.49],[2,1.01,0.51]],"batl":[[0,2.74,23.53],[1,2.78,13.69],[2,2.78,0]],"ltp":0.0,"tv":0.0,"id":12982356},{"batb":[[1,4,53.13],[2,3.95,13.44]],"batl":[[1,5,18.18],[2,5,0]],"ltp":0.0,"tv":0.0,"id":12982355},{"batb":[[0,4.5,11.76],[1,3.9,23.68],[2,1.01,0.51]],"batl":[[0,5.2,16.29],[1,5.4,9.24],[2,5.4,0]],"ltp":4.9,"tv":5.88,"id":13015345},{"batb":[[0,5.8,23.24],[1,5.6,20.38],[2,5.3,9.24]],"ltp":0.0,"tv":0.0,"id":13015344}]}]}
{"op":"mcm","clk":"1006285870","pt":1580647463615,"mc":[{"id":"1.168224553","rc":[{"batb":[[0,2.32,18.49],[1,1.01,0.51],[2,1.01,0]],"batl":[[0,2.78,13.69],[1,2.78,0]],"ltp":0.0,"tv":0.0,"id":12982356},{"batb":[[2,1.01,0.51]],"batl":[[0,5,18.18],[1,5,0]],"ltp":0.0,"tv":0.0,"id":12982355},{"batb":[[0,3.9,23.68],[1,1.01,0.51],[2,1.01,0]],"batl":[[1,5.4,0]],"ltp":4.9,"tv":5.88,"id":13015345},{"batb":[[2,1.01,0.51]],"batl":[[0,7,18.02],[1,7,0]],"ltp":0.0,"tv":0.0,"id":13015344}]}]}
{"op":"mcm","clk":"1006286169","pt":1580647465204,"mc":[{"id":"1.168224553","rc":[{"batl":[[0,2.76,13.77]],"ltp":0.0,"tv":0.0,"id":12982356},{"batb":[[1,4,53.22]],"ltp":0.0,"tv":0.0,"id":12982355},{"batb":[[0,3.95,23.45]],"batl":[[0,5.2,16.13]],"ltp":4.9,"tv":5.88,"id":13015345},{"batb":[[0,5.8,23.3]],"ltp":0.0,"tv":0.0,"id":13015344}]}]}
{"op":"mcm","clk":"1006286566","pt":1580647467311,"mc":[{"id":"1.168224553","rc":[{"batb":[[0,2.5,65.98],[1,2.46,73.08],[2,2.32,18.49]],"ltp":0.0,"tv":0.0,"id":12982356},{"batb":[[1,4.1,39.51],[2,4,53.22]],"ltp":0.0,"tv":0.0,"id":12982355},{"batb":[[0,4.5,36.94],[1,4.4,43.07],[2,3.95,23.45]],"ltp":4.9,"tv":5.88,"id":13015345},{"batb":[[0,5.9,21.32],[1,5.8,23.3],[2,5.6,20.38]],"ltp":0.0,"tv":0.0,"id":13015344}]}]}
{"op":"mcm","clk":"1006287129","pt":1580647469833,"mc":[{"id":"1.168224553","rc":[{"batb":[[0,2.32,18.49],[1,1.01,0.51],[2,2.32,0]],"ltp":0.0,"tv":0.0,"id":12982356},{"batb":[[1,4,53.22],[2,1.01,0.51]],"ltp":0.0,"tv":0.0,"id":12982355},{"batb":[[0,3.95,23.45],[1,1.01,0.51],[2,3.95,0]],"ltp":4.9,"tv":5.88,"id":13015345},{"batb":[[0,5.8,23.3],[1,5.6,20.38],[2,1.01,0.51]],"ltp":0.0,"tv":0.0,"id":13015344}]}]}
{"op":"mcm","clk":"1006287699","pt":1580647472716,"mc":[{"id":"1.168224553","rc":[{"batb":[[0,2.4,63.81],[1,2.36,81.9],[2,2.32,18.49]],"ltp":0.0,"tv":0.0,"id":12982356},{"batb":[[1,4,73.53],[2,3.95,27.46]],"ltp":0.0,"tv":0.0,"id":12982355},{"batb":[[0,4.2,56.36],[1,4.1,50.4],[2,3.95,23.45]],"ltp":4.9,"tv":5.88,"id":13015345},{"batb":[[0,5.8,29.35],[1,5.7,24.1],[2,5.6,20.38]],"ltp":0.0,"tv":0.0,"id":13015344}]}]}
{"op":"mcm","clk":"1006288382","pt":1580647476067,"mc":[{"id":"1.168224553","rc":[{"batb":[[1,4,53.13],[2,1.01,0.51]],"ltp":0.0,"tv":0.0,"id":12982355},{"batb":[[0,3.95,23.45],[1,1.01,0.51],[2,3.95,0]],"ltp":4.9,"tv":5.88,"id":13015345},{"batb":[[0,5.8,23.24],[1,5.6,20.38],[2,1.01,0.51]],"ltp":0.0,"tv":0.0,"id":13015344}]}]}
{"op":"mcm","clk":"1006289035","pt":1580647479450,"mc":[{"id":"1.168224553","rc":[{"batb":[[1,4.1,58.92],[2,4,53.13]],"ltp":0.0,"tv":0.0,"id":12982355},{"batb":[[0,4.8,29.42],[1,4.7,37.13],[2,3.95,23.45]],"ltp":4.9,"tv":5.88,"id":13015345},{"batb":[[0,5.9,36.36],[1,5.8,23.24],[2,5.6,20.38]],"ltp":0.0,"tv":0.0,"id":13015344}]}]}
{"op":"mcm","clk":"1006289225","pt":1580647480321,"mc":[{"id":"1.168224553","rc":[{"batl":[[0,2.48,18.1],[1,2.6,15.97]],"ltp":0.0,"tv":0.0,"id":12982356},{"batb":[[0,4.2,19.43]],"batl":[[0,4.9,18.1]],"ltp":0.0,"tv":0.0,"id":12982355},{"batb":[[2,4.5,16.92]],"batl":[[1,5.5,14.63]],"ltp":4.9,"tv":5.88,"id":13015345}]}]}
{"op":"mcm","clk":"1006289436","pt":1580647481434,"mc":[{"id":"1.168224553","rc":[{"batb":[[1,2.36,112.15]],"batl":[[2,2.66,25.21]],"ltp":0.0,"tv":0.0,"id":12982356},{"batl":[[0,4.7,10.92],[1,4.9,18.1]],"ltp":0.0,"tv":0.0,"id":12982355},{"batb":[[2,4.6,10.92]],"batl":[[2,5.6,8.4]],"ltp":4.9,"tv":5.88,"id":13015345},{"batl":[[0,6.6,6.72],[1,7,18.02]],"ltp":0.0,"tv":0.0,"id":13015344}]}]}
{"op":"mcm","clk":"1006291457","pt":1580647492082,"mc":[{"id":"1.168224553","rc":[{"batb":[[0,2.36,30.25],[1,2.26,19.59],[2,1.01,0.51]],"batl":[[0,2.6,15.97],[1,2.66,25.21],[2,2.66,0]],"ltp":0.0,"tv":0.0,"id":12982356},{"batb":[[1,3.95,13.44],[2,1.01,0.51]],"ltp":0.0,"tv":0.0,"id":12982355},{"batb":[[0,4.6,10.92],[1,4.2,19.67],[2,1.01,0.51]],"batl":[[0,5.5,14.63],[1,5.6,8.4],[2,5.6,0]],"ltp":4.9,"tv":5.88,"id":13015345},{"batb":[[0,5.6,20.38],[1,5.4,9.24],[2,1.01,0.51]],"ltp":0.0,"tv":0.0,"id":13015344}]}]}
{"op":"mcm","clk":"1006291755","pt":1580647493670,"mc":[{"id":"1.168224553","rc":[{"batb":[[0,2.26,19.59],[1,1.01,0.51],[2,1.01,0]],"batl":[[1,2.66,0]],"ltp":0.0,"tv":0.0,"id":12982356},{"batb":[[1,1.01,0.51],[2,1.01,0]],"batl":[[0,4.9,18.1],[1,4.9,0]],"ltp":0.0,"tv":0.0,"id":12982355},{"batb":[[0,4.2,19.67],[1,1.01,0.51],[2,1.01,0]],"batl":[[1,5.6,0]],"ltp":4.9,"tv":5.88,"id":13015345},{"batb":[[1,1.01,0.51],[2,1.01,0]],"batl":[[0,7,18.02],[1,7,0]],"ltp":0.0,"tv":0.0,"id":13015344}]}]}
{"op":"mcm","clk":"1006292163","pt":1580647495796,"mc":[{"id":"1.168224553","rc":[{"batb":[[0,2.36,58.59],[1,2.32,85.91],[2,2.26,19.59]],"ltp":0.0,"tv":0.0,"id":12982356},{"batb":[[1,4.1,48.59],[2,4,53.06]],"ltp":0.0,"tv":0.0,"id":12982355},{"batb":[[0,4.5,56.97],[1,4.4,42.73],[2,4.2,19.67]],"ltp":4.9,"tv":5.88,"id":13015345},{"batb":[[0,5.9,19.26],[1,5.8,23.32],[2,5.6,20.38]],"ltp":0.0,"tv":0.0,"id":13015344}]}]}
{"op":"mcm","clk":"1006293728","pt":1580647503462,"mc":[{"id":"1.168224553","rc":[{"batb":[[0,2.26,19.59],[1,1.01,0.51],[2,2.26,0]],"ltp":0.0,"tv":0.0,"id":12982356}]}]}
{"op":"mcm","clk":"1006294335","pt":1580647506382,"mc":[{"id":"1.168224553","rc":[{"batb":[[0,2.48,67.95],[1,2.44,74.72],[2,2.26,19.59]],"ltp":0.0,"tv":0.0,"id":12982356}]}]}
{"op":"mcm","clk":"1006294526","pt":1580647507412,"mc":[{"id":"1.168224553","rc":[{"batb":[[1,2.44,103.29],[2,2.42,16.29]],"batl":[[1,2.74,23.53],[2,2.8,13.38]],"ltp":0.0,"tv":0.0,"id":12982356},{"batl":[[0,4.7,10.92],[1,4.9,18.1]],"ltp":0.0,"tv":0.0,"id":12982355},{"batb":[[1,4.4,54.49]],"batl":[[0,4.9,18.73],[1,5.2,16.68],[2,5.3,9.24]],"ltp":4.9,"tv":5.88,"id":13015345},{"batb":[[2,5.6,10.31]],"batl":[[0,6.4,7.56],[1,6.8,18.25]],"ltp":0.0,"tv":0.0,"id":13015344}]}]}
{"op":"mcm","clk":"1006296748","pt":1580647519003,"mc":[{"id":"1.168224553","rc":[{"batb":[[0,2.44,28.57],[1,2.34,17.94],[2,1.01,0.51]],"batl":[[0,2.74,23.53],[1,2.8,13.38],[2,2.8,0]],"ltp":0.0,"tv":0.0,"id":12982356},{"batb":[[1,4.1,26.28]],"ltp":0.0,"tv":0.0,"id":12982355},{"batb":[[0,4.4,11.76],[1,3.9,24.31],[2,1.01,0.51]],"batl":[[0,5.2,16.68],[1,5.3,9.24],[2,5.3,0]],"ltp":4.9,"tv":5.88,"id":13015345},{"batb":[[0,5.8,23.32],[1,5.6,10.31],[2,5.2,9.24]],"ltp":0.0,"tv":0.0,"id":13015344}]}]}
{"op":"mcm","clk":"1006296899","pt":1580647519692,"mc":[{"id":"1.168224553","rc":[{"batb":[[0,2.34,17.94],[1,1.01,0.51],[2,1.01,0]],"batl":[[0,2.8,13.38],[1,2.8,0]],"ltp":0.0,"tv":0.0,"id":12982356},{"batl":[[0,4.9,18.1],[1,4.9,0]],"ltp":0.0,"tv":0.0,"id":12982355},{"batb":[[0,3.9,24.31],[1,1.01,0.51],[2,1.01,0]],"batl":[[1,5.3,0]],"ltp":4.9,"tv":5.88,"id":13015345},{"batb":[[2,1.01,0.51]],"batl":[[0,6.8,18.25],[1,6.8,0]],"ltp":0.0,"tv":0.0,"id":13015344}]}]}
{"op":"mcm","clk":"1006297285","pt":1580647521681,"mc":[{"id":"1.168224553","rc":[{"batb":[[0,2.42,46.25],[1,2.38,80.11],[2,2.34,17.94]],"ltp":0.0,"tv":0.0,"id":12982356},{"batb":[[0,4.2,52.58],[1,4.1,50.46],[2,3.9,24.31]],"ltp":4.9,"tv":5.88,"id":13015345},{"batb":[[1,5.7,24.17],[2,5.6,10.31]],"ltp":0.0,"tv":0.0,"id":13015344}]}]}
{"op":"mcm","clk":"1006298382","pt":1580647527332,"mc":[{"id":"1.168224553","rc":[{"batb":[[0,2.34,17.94],[1,1.01,0.51],[2,2.34,0]],"ltp":0.0,"tv":0.0,"id":12982356}]}]}
{"op":"mcm","clk":"1006298979","pt":1580647530390,"mc":[{"id":"1.168224553","rc":[{"batb":[[0,2.62,61.63],[1,2.58,64.33],[2,2.34,17.94]],"ltp":0.0,"tv":0.0,"id":12982356}]}]}
{"op":"mcm","clk":"1006299094","pt":1580647531136,"mc":[{"id":"1.168224553","rc":[{"batb":[[1,2.58,77.94],[2,2.52,26.89]],"batl":[[1,2.88,21.85],[2,3.2,24.39]],"ltp":0.0,"tv":0.0,"id":12982356},{"batb":[[0,4.1,26.28],[1,4,74.85],[2,3.95,13.44]],"batl":[[0,4.7,10.92],[1,4.8,19.28],[2,4.9,18.1]],"ltp":0.0,"tv":0.0,"id":12982355},{"batb":[[0,4.2,65.18]],"batl":[[0,4.5,22.98],[1,4.9,18.65],[2,5,10.08]],"ltp":4.9,"tv":5.88,"id":13015345},{"batb":[[2,5.5,10.46]],"batl":[[0,6.2,7.56],[1,6.8,18.25]],"ltp":0.0,"tv":0.0,"id":13015344}]}]}
{"op":"mcm","clk":"1006301070","pt":1580647542227,"mc":[{"id":"1.168224553","rc":[{"batb":[[0,2.52,26.89],[1,2.42,16.21],[2,1.01,0.51]],"batl":[[0,2.88,21.85],[1,3.2,24.39],[2,3.2,0]],"ltp":0.0,"tv":0.0,"id":12982356},{"batb":[[0,4,21.79],[1,3.95,13.44],[2,1.01,0.51]],"batl":[[1,4.9,18.1],[2,4.9,0]],"ltp":0.0,"tv":0.0,"id":12982355},{"batb":[[0,4.2,12.6],[1,3.45,16.37],[2,1.01,0.51]],"batl":[[0,4.9,18.65],[1,5,10.08],[2,5,0]],"ltp":4.9,"tv":5.88,"id":13015345},{"batb":[[0,5.7,24.17],[1,5.5,10.46],[2,5.1,10.08]],"ltp":0.0,"tv":0.0,"id":13015344}]}]}
{"op":"mcm","clk":"1006301350","pt":1580647543724,"mc":[{"id":"1.168224553","rc":[{"batb":[[0,2.42,16.21],[1,1.01,0.51],[2,1.01,0]],"batl":[[0,3.2,24.39],[1,3.2,0]],"ltp":0.0,"tv":0.0,"id":12982356},{"batb":[[1,1.01,0.51],[2,1.01,0]],"batl":[[0,4.9,18.1],[1,4.9,0]],"ltp":0.0,"tv":0.0,"id":12982355},{"batb":[[0,3.45,16.37],[1,1.01,0.51],[2,1.01,0]],"batl":[[1,5,0]],"ltp":4.9,"tv":5.88,"id":13015345},{"batb":[[2,1.01,0.51]],"batl":[[0,6.8,18.25],[1,6.8,0]],"ltp":0.0,"tv":0.0,"id":13015344}]}]}
{"op":"mcm","clk":"1006301654","pt":1580647545218,"mc":[{"id":"1.168224553","rc":[{"batb":[[1,3.95,27.5],[2,1.01,0.51]],"ltp":0.0,"tv":0.0,"id":12982355}]}]}
{"op":"mcm","clk":"1006302217","pt":1580647548254,"mc":[{"id":"1.168224553","rc":[{"batb":[[0,2.68,56.55],[1,2.64,60.56],[2,2.42,16.21]],"ltp":0.0,"tv":0.0,"id":12982356},{"batb":[[0,4,90.9]],"ltp":0.0,"tv":0.0,"id":12982355},{"batb":[[0,4.1,48.33],[1,4,53.54],[2,3.45,16.37]],"ltp":4.9,"tv":5.88,"id":13015345},{"batb":[[0,5.8,19.45],[1,5.7,24.17],[2,5.5,10.46]],"ltp":0.0,"tv":0.0,"id":13015344}]}]}
{"op":"mcm","clk":"1006302937","pt":1580647552151,"mc":[{"id":"1.168224553","rc":[{"batb":[[0,2.42,16.21],[1,1.01,0.51],[2,2.42,0]],"ltp":0.0,"tv":0.0,"id":12982356},{"batb":[[0,4,21.79]],"ltp":0.0,"tv":0.0,"id":12982355},{"batb":[[0,3.45,16.37],[1,1.01,0.51],[2,3.45,0]],"ltp":4.9,"tv":5.88,"id":13015345},{"batb":[[0,5.7,24.17],[1,5.5,10.46],[2,1.01,0.51]],"ltp":0.0,"tv":0.0,"id":13015344}]}]}
{"op":"mcm","clk":"1006303492","pt":1580647555160,"mc":[{"id":"1.168224553","rc":[{"batb":[[0,2.46,75.3],[1,2.42,92.59],[2,1.01,0.51]],"ltp":0.0,"tv":0.0,"id":12982356},{"batb":[[1,3.95,52.17],[2,3.9,28.49]],"ltp":0.0,"tv":0.0,"id":12982355},{"batb":[[0,3.7,59.34],[1,3.65,33.62],[2,3.45,16.37]],"ltp":4.9,"tv":5.88,"id":13015345},{"batb":[[1,5.6,25.13],[2,5.5,10.46]],"ltp":0.0,"tv":0.0,"id":13015344}]}]}
{"op":"mcm","clk":"1006304848","pt":1580647563363,"mc":[{"id":"1.168224553","rc":[{"batb":[[0,2.42,16.21],[1,1.01,0.51],[2,1.01,0]],"ltp":0.0,"tv":0.0,"id":12982356}]}]}
{"op":"mcm","clk":"1006305340","pt":1580647566242,"mc":[{"id":"1.168224553","rc":[{"batb":[[0,2.94,50.41],[1,2.9,47.5],[2,2.42,16.21]],"ltp":0.0,"tv":0.0,"id":12982356}]}]}
{"op":"mcm","clk":"1006305545","pt":1580647567360,"mc":[{"id":"1.168224553","rc":[{"batb":[[1,2.9,72.91],[2,2.78,23.53]],"batl":[[0,3.2,42.88],[1,3.9,15.26]],"ltp":0.0,"tv":0.0,"id":12982356},{"batb":[[2,3.9,52.57]],"batl":[[0,4.6,10.92],[1,4.7,20.69],[2,4.8,19.36]],"ltp":0.0,"tv":0.0,"id":12982355},{"batb":[[0,3.75,15.12],[1,3.7,59.34],[2,3.65,33.62]],"batl":[[0,3.85,15.82],[1,4.4,24.23],[2,4.5,11.76]],"ltp":4.9,"tv":5.88,"id":13015345},{"batl":[[0,6.2,7.56],[1,6.6,19.36]],"ltp":0.0,"tv":0.0,"id":13015344}]}]}
{"op":"mcm","clk":"1006307508","pt":1580647579461,"mc":[{"id":"1.168224553","rc":[{"batb":[[0,2.9,25.41],[1,2.78,23.53],[2,2.64,12.98]],"ltp":0.0,"tv":0.0,"id":12982356},{"batb":[[1,3.9,24.08],[2,3.85,14.28]],"ltp":0.0,"tv":0.0,"id":12982355},{"batb":[[1,3.45,16.37],[2,2.98,24]],"ltp":4.9,"tv":5.88,"id":13015345},{"batb":[[0,5.6,18.8],[1,5.5,10.46],[2,5,10.08]],"ltp":0.0,"tv":0.0,"id":13015344}]}]}
{"op":"mcm","clk":"1006307551","pt":1580647579784,"mc":[{"id":"1.168224553","rc":[{"batb":[[0,2.64,12.98],[1,1.01,0.51],[2,2.64,0]],"batl":[[0,3.9,15.26],[1,3.9,0]],"ltp":0.0,"tv":0.0,"id":12982356},{"batb":[[0,3.9,24.08],[1,1.01,0.51],[2,3.85,0]],"batl":[[0,4.8,19.36],[1,4.7,0],[2,4.8,0]],"ltp":0.0,"tv":0.0,"id":12982355},{"batb":[[0,2.98,24],[1,1.01,0.51],[2,2.98,0]],"batl":[[0,4.4,24.23],[1,4.4,0],[2,4.5,0]],"ltp":4.9,"tv":5.88,"id":13015345},{"batb":[[2,1.01,0.51]],"batl":[[0,6.6,19.36],[1,6.6,0]],"ltp":0.0,"tv":0.0,"id":13015344}]}]}
{"op":"mcm","clk":"1006308011","pt":1580647582477,"mc":[{"id":"1.168224553","rc":[{"batb":[[0,2.66,39.8],[1,2.64,12.98],[2,2.62,61.9]],"ltp":0.0,"tv":0.0,"id":12982356},{"batb":[[1,3.8,48.33],[2,3.75,31.32]],"ltp":0.0,"tv":0.0,"id":12982355},{"batb":[[0,3.15,63.83],[1,3.1,50.15],[2,2.98,24]],"batl":[[0,4.4,36]],"ltp":4.9,"tv":5.88,"id":13015345},{"batb":[[1,5.5,36.7]],"ltp":0.0,"tv":0.0,"id":13015344}]}]}
{"op":"mcm","clk":"1006308079","pt":1580647582880,"mc":[{"id":"1.168224553","rc":[{"batb":[[0,2.64,12.98],[1,1.01,0.51],[2,2.62,0]],"ltp":0.0,"tv":0.0,"id":12982356},{"batb":[[1,1.01,0.51],[2,3.75,0]],"ltp":0.0,"tv":0.0,"id":12982355},{"batb":[[0,2.98,24],[1,1.01,0.51],[2,2.98,0]],"batl":[[0,4.4,24.23]],"ltp":4.9,"tv":5.88,"id":13015345},{"batb":[[1,5.5,10.46]],"ltp":0.0,"tv":0.0,"id":13015344}]}]}
{"op":"mcm","clk":"1006308486","pt":1580647585489,"mc":[{"id":"1.168224553","rc":[{"batb":[[0,3.05,49.49],[1,3,54.29],[2,2.64,12.98]],"ltp":0.0,"tv":0.0,"id":12982356},{"batb":[[0,3.95,33.51],[1,3.9,52.74],[2,1.01,0.51]],"ltp":0.0,"tv":0.0,"id":12982355},{"batb":[[0,3.6,42.06],[1,3.55,36.11],[2,2.98,24]],"ltp":4.9,"tv":5.88,"id":13015345},{"batb":[[0,5.7,18.41],[1,5.6,25.22],[2,5.5,10.46]],"ltp":0.0,"tv":0.0,"id":13015344}]}]}
{"op":"mcm","clk":"1006308961","pt":1580647588257,"mc":[{"id":"1.168224553","rc":[{"batb":[[0,2.64,12.98],[1,1.01,0.51],[2,2.64,0]],"ltp":0.0,"tv":0.0,"id":12982356},{"batb":[[0,3.9,24.08],[1,1.01,0.51],[2,1.01,0]],"ltp":0.0,"tv":0.0,"id":12982355},{"batb":[[0,2.98,24],[1,1.01,0.51],[2,2.98,0]],"ltp":4.9,"tv":5.88,"id":13015345},{"batb":[[0,5.6,18.8],[1,5.5,10.46],[2,1.01,0.51]],"ltp":0.0,"tv":0.0,"id":13015344}]}]}
{"op":"mcm","clk":"1006309433","pt":1580647591191,"mc":[{"id":"1.168224553","rc":[{"batb":[[0,2.66,39.8],[1,2.64,12.98],[2,2.62,61.9]],"ltp":0.0,"tv":0.0,"id":12982356},{"batb":[[1,3.8,48.33],[2,3.75,31.32]],"ltp":0.0,"tv":0.0,"id":12982355},{"batb":[[0,3.15,63.83],[1,3.1,50.15],[2,2.98,24]],"ltp":4.9,"tv":5.88,"id":13015345},{"batb":[[1,5.5,36.7]],"ltp":0.0,"tv":0.0,"id":13015344}]}]}
{"op":"mcm","clk":"1006309588","pt":1580647592157,"mc":[{"id":"1.168224553","rc":[{"batb":[[1,1.01,0.51],[2,3.75,0]],"ltp":0.0,"tv":0.0,"id":12982355},{"batb":[[0,2.98,24],[1,1.01,0.51],[2,2.98,0]],"ltp":4.9,"tv":5.88,"id":13015345},{"batb":[[0,5.5,10.46],[1,1.01,0.51],[2,1.01,0]],"ltp":0.0,"tv":0.0,"id":13015344}]}]}
{"op":"mcm","clk":"1006310059","pt":1580647595089,"mc":[{"id":"1.168224553","rc":[{"batb":[[0,4.1,26.1],[1,4,53.45],[2,3.9,24.08]],"ltp":0.0,"tv":0.0,"id":12982355},{"batb":[[0,4.2,25.15],[1,4.1,50.93],[2,2.98,24]],"ltp":4.9,"tv":5.88,"id":13015345},{"batb":[[0,5.8,19.09],[1,5.7,24.24],[2,5.5,10.46]],"ltp":0.0,"tv":0.0,"id":13015344}]}]}
{"op":"mcm","clk":"1006310253","pt":1580647596215,"mc":[{"id":"1.168224553","rc":[{"batl":[[0,2.84,12.83],[1,3.25,23.84]],"ltp":0.0,"tv":0.0,"id":12982356},{"batb":[[1,4,75.17],[2,1.01,0.51]],"batl":[[1,4.9,18.65]],"ltp":0.0,"tv":0.0,"id":12982355},{"batb":[[2,3.8,25.65]],"batl":[[1,4.8,19.83]],"ltp":4.9,"tv":5.88,"id":13015345},{"batl":[[0,6.8,18.88]],"ltp":0.0,"tv":0.0,"id":13015344}]}]}
{"op":"mcm","clk":"1006310506","pt":1580647597476,"mc":[{"id":"1.168224553","rc":[{"batl":[[1,2.96,21],[2,3.25,23.84]],"ltp":0.0,"tv":0.0,"id":12982356},{"batb":[[2,3.95,13.44]],"batl":[[0,4.7,10.92],[1,4.8,19.36],[2,4.9,18.65]],"ltp":0.0,"tv":0.0,"id":12982355},{"batb":[[1,4.1,64.37]],"batl":[[2,4.9,10.08]],"ltp":4.9,"tv":5.88,"id":13015345},{"batl":[[0,6.2,7.56],[1,6.8,18.88]],"ltp":0.0,"tv":0.0,"id":13015344}]}]}
{"op":"mcm","clk":"1006312668","pt":1580647611222,"mc":[{"id":"1.168224553","rc":[{"batb":[[0,2.6,26.05],[1,2.46,15.58],[2,1.01,0.51]],"batl":[[0,2.96,21],[1,3.25,23.84],[2,3.25,0]],"ltp":0.0,"tv":0.0,"id":12982356},{"batb":[[0,4,21.72],[1,3.95,13.44],[2,1.01,0.51]],"batl":[[1,4.9,18.65],[2,4.9,0]],"ltp":0.0,"tv":0.0,"id":12982355},{"batb":[[0,4.1,13.44],[1,3.4,16.76],[2,1.01,0.51]],"batl":[[0,4.8,19.83],[1,4.9,10.08],[2,4.9,0]],"ltp":4.9,"tv":5.88,"id":13015345},{"batb":[[0,5.7,24.24],[1,5.5,10.46],[2,5.1,10.08]],"ltp":0.0,"tv":0.0,"id":13015344}]}]}
{"op":"mcm","clk":"1006312765","pt":1580647611817,"mc":[{"id":"1.168224553","rc":[{"batb":[[0,2.46,15.58],[1,1.01,0.51],[2,1.01,0]],"batl":[[0,3.25,23.84],[1,3.25,0]],"ltp":0.0,"tv":0.0,"id":12982356},{"batb":[[1,1.01,0.51],[2,1.01,0]],"batl":[[0,4.9,18.65],[1,4.9,0]],"ltp":0.0,"tv":0.0,"id":12982355},{"batb":[[0,3.4,16.76],[1,1.01,0.51],[2,1.01,0]],"batl":[[1,4.9,0]],"ltp":4.9,"tv":5.88,"id":13015345},{"batb":[[2,1.01,0.51]],"batl":[[0,6.8,18.88],[1,6.8,0]],"ltp":0.0,"tv":0.0,"id":13015344}]}]}
{"op":"mcm","clk":"1006313112","pt":1580647614212,"mc":[{"id":"1.168224553","rc":[{"batb":[[0,2.5,40.96],[1,2.46,88.82],[2,2.44,15.82]],"batl":[[0,3.2,24.23],[1,3.25,23.84]],"ltp":0.0,"tv":0.0,"id":12982356},{"batb":[[1,3.95,53.29],[2,3.9,28.49]],"ltp":0.0,"tv":0.0,"id":12982355},{"batb":[[0,3.7,28.26],[1,3.65,33.9],[2,3.45,16.44]],"ltp":4.9,"tv":5.88,"id":13015345},{"batb":[[1,5.6,35.5],[2,5.5,10.46]],"ltp":0.0,"tv":0.0,"id":13015344}]}]}
{"op":"mcm","clk":"1006313164","pt":1580647614533,"mc":[{"id":"1.168224553","rc":[{"batb":[[1,2.46,73.24]],"batl":[[1,3.25,0]],"ltp":0.0,"tv":0.0,"id":12982356},{"batl":[[0,4.8,19.43]],"ltp":4.9,"tv":5.88,"id":13015345},{"batb":[[2,1.01,0.51]],"batl":[[0,6.8,18.57]],"ltp":0.0,"tv":0.0,"id":13015344}]}]}
{"op":"mcm","clk":"1006313747","pt":1580647618099,"mc":[{"id":"1.168224553","rc":[{"batb":[[1,1.01,0.51],[2,3.9,0]],"ltp":0.0,"tv":0.0,"id":12982355},{"batb":[[0,3.45,16.44],[1,1.01,0.51],[2,3.45,0]],"ltp":4.9,"tv":5.88,"id":13015345},{"batb":[[1,5.6,10.31]],"ltp":0.0,"tv":0.0,"id":13015344}]}]}
{"op":"mcm","clk":"1006314224","pt":1580647621037,"mc":[{"id":"1.168224553","rc":[{"batb":[[0,4.1,58.49],[1,4,74.61],[2,1.01,0.51]],"ltp":0.0,"tv":0.0,"id":12982355},{"batb":[[0,4.5,50.71],[1,4.4,42.84],[2,3.45,16.44]],"ltp":4.9,"tv":5.88,"id":13015345},{"batb":[[0,5.8,32.79],[1,5.7,24.24],[2,5.6,10.31]],"ltp":0.0,"tv":0.0,"id":13015344}]}]}
{"op":"mcm","clk":"1006314485","pt":1580647623167,"mc":[{"id":"1.168224553","rc":[{"batb":[[1,2.46,101.81]],"batl":[[0,2.64,15.5],[1,2.8,22.69],[2,2.82,12.98]],"ltp":0.0,"tv":0.0,"id":12982356},{"batb":[[0,4.2,19.91],[1,4.1,79.26],[2,4,52.89]],"batl":[[0,4.7,10.92],[1,4.9,18.65],[2,5,17.55]],"ltp":0.0,"tv":0.0,"id":12982355},{"batb":[[1,4.4,54.6],[2,4.2,20.46]],"batl":[[1,5.3,9.24],[2,5.6,13.93]],"ltp":4.9,"tv":5.88,"id":13015345},{"batl":[[0,6.2,7.56],[1,6.8,18.1]],"ltp":0.0,"tv":0.0,"id":13015344}]}]}
{"op":"mcm","clk":"1006315101","pt":1580647626030,"mc":[{"id":"1.168224553","rc":[{"batb":[[0,2.46,28.57],[1,2.44,15.82],[2,2.22,20.61]],"ltp":0.0,"tv":0.0,"id":12982356}]}]}
{"op":"mcm","clk":"1006315475","pt":1580647628460,"mc":[{"id":"1.168224553","rc":[{"batb":[[0,2.48,75.91],[1,2.46,28.57],[2,2.44,90.48]],"ltp":0.0,"tv":0.0,"id":12982356}]}]}
{"op":"mcm","clk":"1006317516","pt":1580647640348,"mc":[{"id":"1.168224553","rc":[{"batb":[[0,2.46,28.57],[1,2.22,20.61],[2,1.01,0.51]],"batl":[[0,2.8,22.69],[1,2.82,12.98],[2,2.82,0]],"ltp":0.0,"tv":0.0,"id":12982356},{"batb":[[0,4.1,20.77],[1,4,52.89],[2,3.95,13.44]],"batl":[[1,5,17.55],[2,5,0]],"ltp":0.0,"tv":0.0,"id":12982355},{"batb":[[0,4.4,11.76],[1,3.85,24.94],[2,1.01,0.51]],"batl":[[0,5.3,9.24],[1,5.6,13.93],[2,5.6,0]],"ltp":4.9,"tv":5.88,"id":13015345},{"batb":[[0,5.7,24.24],[1,5.6,10.31],[2,5.2,9.24]],"ltp":0.0,"tv":0.0,"id":13015344}]}]}
{"op":"mcm","clk":"1006317760","pt":1580647641862,"mc":[{"id":"1.168224553","rc":[{"trd":[[2.46,57.14]],"batb":[[0,2.22,20.61],[1,1.01,0.51],[2,1.01,0]],"batl":[[0,2.44,24.4]],"ltp":2.46,"tv":57.13,"id":12982356},{"batb":[[2,1.01,0.51]],"batl":[[0,5,17.55],[1,5,0]],"ltp":0.0,"tv":0.0,"id":12982355},{"batb":[[0,3.85,24.94],[1,1.01,0.51],[2,1.01,0]],"batl":[[0,5.6,13.93],[1,5.6,0]],"ltp":4.9,"tv":5.88,"id":13015345},{"batb":[[2,1.01,0.51]],"batl":[[0,6.8,18.1],[1,6.8,0]],"ltp":0.0,"tv":0.0,"id":13015344}],"tv":63.01}]}
{"op":"mcm","clk":"1006317965","pt":1580647643174,"mc":[{"id":"1.168224553","rc":[{"batb":[[0,2.28,46.05],[1,2.26,46.69],[2,2.22,20.61]],"ltp":2.46,"tv":57.13,"id":12982356},{"batb":[[1,4,74.07],[2,3.95,27.44]],"ltp":0.0,"tv":0.0,"id":12982355},{"batb":[[0,4.2,26.88],[1,4.1,50.91],[2,3.85,24.94]],"ltp":4.9,"tv":5.88,"id":13015345},{"batb":[[0,5.7,40.61],[1,5.6,35.22]],"ltp":0.0,"tv":0.0,"id":13015344}]}]}
{"op":"mcm","clk":"1006318108","pt":1580647644172,"mc":[{"id":"1.168224553","rc":[{"batb":[[0,2.22,20.61],[1,1.01,0.51],[2,2.22,0]],"ltp":2.46,"tv":57.13,"id":12982356},{"batb":[[1,4,52.89],[2,1.01,0.51]],"ltp":0.0,"tv":0.0,"id":12982355},{"batb":[[0,3.85,24.94],[1,1.01,0.51],[2,3.85,0]],"ltp":4.9,"tv":5.88,"id":13015345},{"batb":[[0,5.7,24.24],[1,5.6,10.31]],"ltp":0.0,"tv":0.0,"id":13015344}]}]}
{"op":"mcm","clk":"1006318628","pt":1580647647459,"mc":[{"id":"1.168224553","rc":[{"trd":[[2.44,48.8]],"batb":[[0,2.44,40.46],[1,2.4,78.19],[2,2.22,20.61]],"batl":[[0,2.82,12.98],[1,2.82,0]],"ltp":2.44,"tv":105.93,"id":12982356},{"batb":[[0,4.1,90.06]],"ltp":0.0,"tv":0.0,"id":12982355},{"batb":[[0,4.6,59.36],[1,4.5,40.54],[2,3.85,24.94]],"ltp":4.9,"tv":5.88,"id":13015345},{"batb":[[0,5.8,38.95],[1,5.7,24.24],[2,5.6,10.31]],"ltp":0.0,"tv":0.0,"id":13015344}],"tv":111.81}]}
{"op":"mcm","clk":"1006318877","pt":1580647648976,"mc":[{"id":"1.168224553","rc":[{"batb":[[0,2.22,20.61],[1,1.01,0.51],[2,2.22,0]],"ltp":2.44,"tv":105.93,"id":12982356},{"batb":[[0,4.1,20.77]],"ltp":0.0,"tv":0.0,"id":12982355},{"batb":[[0,3.85,24.94],[1,1.01,0.51],[2,3.85,0]],"ltp":4.9,"tv":5.88,"id":13015345},{"batb":[[0,5.7,24.24],[1,5.6,10.31],[2,1.01,0.51]],"ltp":0.0,"tv":0.0,"id":13015344}]}]}
{"op":"mcm","clk":"1006319363","pt":1580647651970,"mc":[{"id":"1.168224553","rc":[{"batb":[[0,2.28,47.44],[1,2.26,46.7],[2,2.22,20.61]],"ltp":2.44,"tv":105.93,"id":12982356},{"batb":[[1,4,78.61],[2,3.95,27.44]],"ltp":0.0,"tv":0.0,"id":12982355},{"batb":[[0,4.1,75.15],[1,4,53.03],[2,3.85,24.94]],"ltp":4.9,"tv":5.88,"id":13015345},{"batb":[[0,5.7,38.4],[1,5.6,35.22]],"ltp":0.0,"tv":0.0,"id":13015344}]}]}
{"op":"mcm","clk":"1006319828","pt":1580647655160,"mc":[{"id":"1.168224553","rc":[{"batb":[[1,1.01,0.51],[2,3.95,0]],"ltp":0.0,"tv":0.0,"id":12982355},{"batb":[[0,3.85,24.94],[1,1.01,0.51],[2,3.85,0]],"ltp":4.9,"tv":5.88,"id":13015345},{"batb":[[0,5.6,10.31],[1,1.01,0.51],[2,1.01,0]],"ltp":0.0,"tv":0.0,"id":13015344}]}]}
{"op":"mcm","clk":"1006320302","pt":1580647658064,"mc":[{"id":"1.168224553","rc":[{"batb":[[0,4.2,68.19],[1,4.1,70.59],[2,1.01,0.51]],"ltp":0.0,"tv":0.0,"id":12982355},{"batb":[[0,5.2,38],[1,5.1,30.71],[2,3.85,24.94]],"ltp":4.9,"tv":5.88,"id":13015345},{"batb":[[0,5.9,34.44],[1,5.8,23.11],[2,5.6,10.31]],"ltp":0.0,"tv":0.0,"id":13015344}]}]}
{"op":"mcm","clk":"1006320501","pt":1580647659283,"mc":[{"id":"1.168224553","rc":[{"batb":[[2,2.24,33.61]],"batl":[[0,2.4,20.14],[1,2.48,27.73],[2,2.58,16.37]],"ltp":2.44,"tv":105.93,"id":12982356},{"batb":[[0,4.3,18.41],[1,4.2,87.86],[2,4.1,63.26]],"batl":[[0,4.8,10.92],[1,5,17.55],[2,5.2,15.97]],"ltp":0.0,"tv":0.0,"id":12982355},{"batb":[[1,5.1,40.79],[2,4.8,14.56]],"batl":[[1,6.2,7.56],[2,7,17.62]],"ltp":4.9,"tv":5.88,"id":13015345},{"batb":[[2,5.7,19.91]],"batl":[[0,6.4,7.56],[1,7,17.62]],"ltp":0.0,"tv":0.0,"id":13015344}]}]}
{"op":"mcm","clk":"1006323004","pt":1580647675298,"mc":[{"id":"1.168224553","rc":[{"batb":[[0,2.24,33.61],[1,2.22,20.61],[2,2.02,27.54]],"ltp":2.44,"tv":105.93,"id":12982356},{"batb":[[1,4.2,19.67],[2,4.1,13.44]],"ltp":0.0,"tv":0.0,"id":12982355},{"batb":[[0,5.1,10.08],[1,4.8,14.56],[2,4.3,19.04]],"ltp":4.9,"tv":5.88,"id":13015345},{"batb":[[0,5.7,19.91],[1,5.4,9.24],[2,1.01,0.51]],"ltp":0.0,"tv":0.0,"id":13015344}]}]}
{"op":"mcm","clk":"1006323089","pt":1580647675892,"mc":[{"id":"1.168224553","rc":[{"batb":[[0,2.02,27.54],[1,1.01,0.51],[2,2.02,0]],"batl":[[0,2.58,16.37],[1,2.48,0],[2,2.58,0]],"ltp":2.44,"tv":105.93,"id":12982356},{"batb":[[0,4.2,19.67],[1,1.01,0.51],[2,4.1,0]],"batl":[[0,5.2,15.97],[1,5,0],[2,5.2,0]],"ltp":0.0,"tv":0.0,"id":12982355},{"batb":[[0,4.3,19.04],[1,1.01,0.51],[2,4.3,0]],"batl":[[0,7,17.62],[1,6.2,0],[2,7,0]],"ltp":4.9,"tv":5.88,"id":13015345},{"batb":[[1,1.01,0.51],[2,1.01,0]],"batl":[[0,7,17.62],[1,7,0]],"ltp":0.0,"tv":0.0,"id":13015344}]}]}
{"op":"mcm","clk":"1006323643","pt":1580647679419,"mc":[{"id":"1.168224553","rc":[{"batb":[[0,2.06,54.32],[1,2.04,62.9],[2,2.02,27.54]],"ltp":2.44,"tv":105.93,"id":12982356},{"batb":[[1,4.1,69.23],[2,4,52.78]],"ltp":0.0,"tv":0.0,"id":12982355},{"batb":[[0,4.6,56.39],[1,4.5,40.57],[2,4.3,19.04]],"ltp":4.9,"tv":5.88,"id":13015345},{"batb":[[0,5.8,37.39],[1,5.7,43.88],[2,1.01,0.51]],"ltp":0.0,"tv":0.0,"id":13015344}]}]}
{"op":"mcm","clk":"1006325158","pt":1580647689023,"mc":[{"id":"1.168224553","rc":[{"batb":[[1,1.01,0.51],[2,4,0]],"ltp":0.0,"tv":0.0,"id":12982355},{"batb":[[0,4.3,19.04],[1,1.01,0.51],[2,4.3,0]],"ltp":4.9,"tv":5.88,"id":13015345},{"batb":[[0,5.7,19.91],[1,1.01,0.51],[2,1.01,0]],"ltp":0.0,"tv":0.0,"id":13015344}]}]}
{"op":"mcm","clk":"1006325655","pt":1580647692444,"mc":[{"id":"1.168224553","rc":[{"batb":[[0,4.4,48.44],[1,4.3,44.92],[2,4.2,19.67]],"ltp":0.0,"tv":0.0,"id":12982355},{"batb":[[0,6.4,26.44],[1,6.2,39.36],[2,4.3,19.04]],"ltp":4.9,"tv":5.88,"id":13015345},{"batb":[[0,6,42.92],[1,5.9,22.15],[2,5.7,19.91]],"ltp":0.0,"tv":0.0,"id":13015344}]}]}
{"op":"mcm","clk":"1006325821","pt":1580647693418,"mc":[{"id":"1.168224553","rc":[{"batb":[[0,2.06,93.81]],"batl":[[0,2.16,26.75],[1,2.32,21.95]],"ltp":2.44,"tv":105.93,"id":12982356},{"batb":[[0,4.5,16.68],[1,4.4,66.46],[2,4.3,44.92]],"batl":[[0,5,10.08],[1,5.2,15.97],[2,5.5,14.4]],"ltp":0.0,"tv":0.0,"id":12982355},{"batb":[[1,6.2,46.92],[2,5.8,18.88]],"batl":[[1,7.4,5.88],[2,9,10.31]],"ltp":4.9,"tv":5.88,"id":13015345},{"batb":[[2,5.8,18.88]],"batl":[[0,6.6,6.72],[1,7.2,16.76]],"ltp":0.0,"tv":0.0,"id":13015344}]}]}
{"op":"mcm","clk":"1006325987","pt":1580647694435,"mc":[{"id":"1.168224553","rc":[{"batl":[[1,2.24,33.61],[2,2.32,21.95]],"ltp":2.44,"tv":105.93,"id":12982356}]}]}
{"op":"mcm","clk":"1006328058","pt":1580647707847,"mc":[{"id":"1.168224553","rc":[{"batb":[[0,1.84,18.18],[1,1.01,0.51],[2,2.02,0]],"batl":[[0,2.32,21.95],[1,2.24,0],[2,2.32,0]],"ltp":2.44,"tv":105.93,"id":12982356},{"batb":[[0,4.4,18.02],[1,4.3,44.92],[2,1.01,0.51]],"batl":[[0,5.5,14.4],[1,5.2,0],[2,5.5,0]],"ltp":0.0,"tv":0.0,"id":12982355},{"batb":[[0,5.1,12.67],[1,1.01,0.51],[2,5.8,0]],"batl":[[0,9,10.31],[1,7.4,0],[2,9,0]],"ltp":4.9,"tv":5.88,"id":13015345},{"batb":[[0,6,19.99],[2,5.7,19.28]],"batl":[[0,7.2,16.76],[1,7.2,0]],"ltp":0.0,"tv":0.0,"id":13015344}]}]}
{"op":"mcm","clk":"1006328610","pt":1580647711434,"mc":[{"id":"1.168224553","rc":[{"batb":[[0,1.87,90.6],[1,1.85,85.25],[2,1.84,18.18]],"ltp":2.44,"tv":105.93,"id":12982356},{"batb":[[2,4.2,47.58]],"ltp":0.0,"tv":0.0,"id":12982355},{"batb":[[0,5.5,40.33],[1,5.4,26.98],[2,5.1,12.67]],"ltp":4.9,"tv":5.88,"id":13015345}]}]}
{"op":"mcm","clk":"1006328941","pt":1580647713739,"mc":[{"id":"1.168224553","rc":[{"batb":[[0,1.84,18.18],[1,1.01,0.51],[2,1.84,0]],"ltp":2.44,"tv":105.93,"id":12982356},{"batb":[[2,1.01,0.51]],"ltp":0.0,"tv":0.0,"id":12982355},{"batb":[[0,5.1,12.67],[1,1.01,0.51],[2,5.1,0]],"ltp":4.9,"tv":5.88,"id":13015345}]}]}
{"op":"mcm","clk":"1006329507","pt":1580647717473,"mc":[{"id":"1.168224553","rc":[{"batb":[[0,2.2,72.69],[1,2.18,51.71],[2,2.16,58.71]],"batl":[[1,2.38,30.25],[2,2.54,17.31]],"ltp":2.44,"tv":105.93,"id":12982356},{"batb":[[1,4.3,64.2],[2,4.2,47.58]],"batl":[[0,4.8,10.92],[1,5.1,17.15],[2,5.3,15.42]],"ltp":0.0,"tv":0.0,"id":12982355},{"batb":[[0,5.5,49.57],[1,5.4,26.98],[2,5.1,12.67]],"batl":[[0,6,12.2],[1,6.6,6.72],[2,8,13.61]],"ltp":4.9,"tv":5.88,"id":13015345},{"batl":[[0,6.4,7.56],[1,7,17.47],[2,7.2,16.76]],"ltp":0.0,"tv":0.0,"id":13015344}]}]}
{"op":"mcm","clk":"1006329634","pt":1580647718250,"mc":[{"id":"1.168224553","rc":[{"batl":[[2,7.2,0]],"ltp":0.0,"tv":0.0,"id":13015344}]}]}
{"op":"mcm","clk":"1006332201","pt":1580647735467,"mc":[{"id":"1.168224553","rc":[{"batb":[[0,2.16,36.13],[1,1.94,15.58],[2,1.01,0.51]],"batl":[[0,2.38,30.25],[1,2.54,17.31],[2,2.54,0]],"ltp":2.44,"tv":105.93,"id":12982356},{"batb":[[0,4.3,19.28],[1,4.2,25.11],[2,4.1,13.44]],"batl":[[1,5.3,15.42],[2,5.3,0]],"ltp":0.0,"tv":0.0,"id":12982355},{"batb":[[0,5.5,9.24],[1,4.4,17.7],[2,1.01,0.51]],"batl":[[0,6.6,6.72],[1,8,13.61],[2,8,0]],"ltp":4.9,"tv":5.88,"id":13015345},{"batb":[[0,5.9,22.15],[1,5.7,19.28],[2,5.4,9.24]],"ltp":0.0,"tv":0.0,"id":13015344}]}]}
{"op":"mcm","clk":"1006332252","pt":1580647735885,"mc":[{"id":"1.168224553","rc":[{"batb":[[0,1.94,15.58],[1,1.01,0.51],[2,1.01,0]],"batl":[[0,2.54,17.31],[1,2.54,0]],"ltp":2.44,"tv":105.93,"id":12982356},{"batb":[[2,1.01,0.51]],"batl":[[0,5.3,15.42],[1,5.3,0]],"ltp":0.0,"tv":0.0,"id":12982355},{"batb":[[0,4.4,17.7],[1,1.01,0.51],[2,1.01,0]],"batl":[[0,8,13.61],[1,8,0]],"ltp":4.9,"tv":5.88,"id":13015345},{"batb":[[2,1.01,0.51]],"batl":[[0,7,17.47],[1,7,0]],"ltp":0.0,"tv":0.0,"id":13015344}]}]}
{"op":"mcm","clk":"1006332624","pt":1580647738407,"mc":[{"id":"1.168224553","rc":[{"batb":[[0,1.96,70.71],[1,1.94,88.91],[2,1.01,0.51]],"ltp":2.44,"tv":105.93,"id":12982356},{"batb":[[2,4.1,50.56]],"ltp":0.0,"tv":0.0,"id":12982355},{"batb":[[0,4.8,25.43],[1,4.7,37.2],[2,4.4,17.7]],"ltp":4.9,"tv":5.88,"id":13015345},{"batb":[[1,5.8,23.32],[2,5.7,19.28]],"ltp":0.0,"tv":0.0,"id":13015344}]}]}
{"op":"mcm","clk":"1006332718","pt":1580647738995,"mc":[{"id":"1.168224553","rc":[{"batb":[[0,1.94,15.58],[1,1.01,0.51],[2,1.01,0]],"ltp":2.44,"tv":105.93,"id":12982356},{"batb":[[2,1.01,0.51]],"ltp":0.0,"tv":0.0,"id":12982355},{"batb":[[0,4.4,17.7],[1,1.01,0.51],[2,4.4,0]],"ltp":4.9,"tv":5.88,"id":13015345},{"batb":[[1,5.7,19.28],[2,1.01,0.51]],"ltp":0.0,"tv":0.0,"id":13015344}]}]}
{"op":"mcm","clk":"1006333218","pt":1580647742591,"mc":[{"id":"1.168224553","rc":[{"batb":[[0,2.14,92.68],[1,2.12,56.06],[2,1.94,15.58]],"ltp":2.44,"tv":105.93,"id":12982356},{"batb":[[0,4.3,77.93],[1,4.2,47.26]],"ltp":0.0,"tv":0.0,"id":12982355},{"batb":[[0,5.8,32.06],[1,5.7,24.02],[2,4.4,17.7]],"ltp":4.9,"tv":5.88,"id":13015345},{"batb":[[0,6,26.99],[1,5.9,22.15],[2,5.7,19.28]],"ltp":0.0,"tv":0.0,"id":13015344}]}]}
{"op":"mcm","clk":"1006333468","pt":1580647744179,"mc":[{"id":"1.168224553","rc":[{"batb":[[0,1.94,15.58],[1,1.01,0.51],[2,1.94,0]],"ltp":2.44,"tv":105.93,"id":12982356},{"batb":[[0,4.3,19.28],[1,4.2,25.11]],"ltp":0.0,"tv":0.0,"id":12982355},{"batb":[[0,4.4,17.7],[1,1.01,0.51],[2,4.4,0]],"ltp":4.9,"tv":5.88,"id":13015345},{"batb":[[0,5.9,22.15],[1,5.7,19.28],[2,1.01,0.51]],"ltp":0.0,"tv":0.0,"id":13015344}]}]}
{"op":"mcm","clk":"1006333944","pt":1580647747197,"mc":[{"id":"1.168224553","rc":[{"batb":[[0,1.96,70.71],[1,1.94,88.91],[2,1.01,0.51]],"ltp":2.44,"tv":105.93,"id":12982356},{"batb":[[2,4.1,50.56]],"ltp":0.0,"tv":0.0,"id":12982355},{"batb":[[0,4.8,25.43],[1,4.7,37.2],[2,4.4,17.7]],"ltp":4.9,"tv":5.88,"id":13015345},{"batb":[[1,5.8,23.32],[2,5.7,19.28]],"ltp":0.0,"tv":0.0,"id":13015344}]}]}
{"op":"mcm","clk":"1006338001","pt":1580647773653,"mc":[{"id":"1.168224553","rc":[{"batb":[[0,1.94,15.58],[1,1.01,0.51],[2,1.01,0]],"ltp":2.44,"tv":105.93,"id":12982356}]}]}
{"op":"mcm","clk":"1006338561","pt":1580647777440,"mc":[{"id":"1.168224553","rc":[{"batb":[[0,2.4,71.51],[1,2.36,99.57],[2,2.32,31.09]],"batl":[[1,2.8,13.3]],"ltp":2.44,"tv":105.93,"id":12982356},{"batb":[[2,4.1,71.33]],"batl":[[0,4.7,10.92],[1,4.9,18.33],[2,5.1,16.76]],"ltp":0.0,"tv":0.0,"id":12982355},{"batb":[[0,4.8,36.35]],"batl":[[0,5.1,16.84],[1,6.6,19.51]],"ltp":4.9,"tv":5.88,"id":13015345},{"batl":[[0,6.4,7.56],[1,7,17.47]],"ltp":0.0,"tv":0.0,"id":13015344}]}]}
{"op":"mcm","clk":"1006338723","pt":1580647778479,"mc":[{"id":"1.168224553","rc":[{"batl":[[1,2.56,26.89],[2,2.8,13.3]],"ltp":2.44,"tv":105.93,"id":12982356},{"batl":[[1,5.7,8.4],[2,6.6,19.51]],"ltp":4.9,"tv":5.88,"id":13015345}]}]}
{"op":"mcm","clk":"1006340142","pt":1580647787295,"mc":[{"id":"1.168224553","rc":[{"batb":[[1,4.1,71.33],[2,4,13.44]],"ltp":0.0,"tv":0.0,"id":12982355}]}]}
{"op":"mcm","clk":"1006340622","pt":1580647790404,"mc":[{"id":"1.168224553","rc":[{"batb":[[1,4.1,93.93],[2,4,66.09]],"ltp":0.0,"tv":0.0,"id":12982355}]}]}
{"op":"mcm","clk":"1006341568","pt":1580647796410,"mc":[{"id":"1.168224553","rc":[{"batb":[[0,2.36,17.7],[1,2.32,31.09],[2,2.06,25.41]],"ltp":2.44,"tv":105.93,"id":12982356},{"batb":[[1,4.1,20.77]],"ltp":0.0,"tv":0.0,"id":12982355},{"batb":[[0,4.8,10.92],[1,4.4,17.7],[2,3.9,24.23]],"ltp":4.9,"tv":5.88,"id":13015345},{"batb":[[0,5.8,23.32],[1,5.7,19.28],[2,5.6,20.38]],"ltp":0.0,"tv":0.0,"id":13015344}]}]}
{"op":"mcm","clk":"1006341588","pt":1580647796548,"mc":[{"id":"1.168224553","rc":[{"batb":[[0,2.32,31.09],[1,2.06,25.41],[2,1.01,0.51]],"batl":[[0,2.56,26.89],[1,2.8,13.3],[2,2.8,0]],"ltp":2.44,"tv":105.93,"id":12982356},{"batb":[[0,4.1,20.77],[1,4,66.09],[2,1.01,0.51]],"batl":[[1,5.1,16.76],[2,5.1,0]],"ltp":0.0,"tv":0.0,"id":12982355},{"batb":[[1,3.9,24.23],[2,1.01,0.51]],"batl":[[0,5.7,8.4],[1,6.6,19.51],[2,6.6,0]],"ltp":4.9,"tv":5.88,"id":13015345},{"batb":[[1,5.6,20.38],[2,5.4,9.24]],"ltp":0.0,"tv":0.0,"id":13015344}]}]}
{"op":"mcm","clk":"1006341862","pt":1580647798292,"mc":[{"id":"1.168224553","rc":[{"batb":[[0,2.06,25.41],[1,1.01,0.51],[2,1.01,0]],"batl":[[0,2.8,13.3],[1,2.8,0]],"ltp":2.44,"tv":105.93,"id":12982356},{"batb":[[1,4,52.65]],"batl":[[0,5.1,16.76],[1,5.1,0]],"ltp":0.0,"tv":0.0,"id":12982355},{"batb":[[0,3.9,24.23],[1,1.01,0.51],[2,1.01,0]],"batl":[[0,6.6,19.51],[1,6.6,0]],"ltp":4.9,"tv":5.88,"id":13015345},{"batb":[[2,1.01,0.51]],"batl":[[0,7,17.47],[1,7,0]],"ltp":0.0,"tv":0.0,"id":13015344}]}]}
{"op":"mcm","clk":"1006342031","pt":1580647799414,"mc":[{"id":"1.168224553","rc":[{"batb":[[0,2.1,76.31],[1,2.08,59.31],[2,2.06,25.41]],"ltp":2.44,"tv":105.93,"id":12982356},{"batb":[[1,4,61.52],[2,3.95,27.56]],"ltp":0.0,"tv":0.0,"id":12982355},{"batb":[[0,4.2,34.74],[1,4.1,50.87],[2,3.9,24.23]],"ltp":4.9,"tv":5.88,"id":13015345},{"batb":[[1,5.7,24.22],[2,5.6,20.38]],"ltp":0.0,"tv":0.0,"id":13015344}]}]}
{"op":"mcm","clk":"1006343120","pt":1580647805812,"mc":[{"id":"1.168224553","rc":[{"batb":[[0,2.06,25.41],[1,1.01,0.51],[2,2.06,0]],"ltp":2.44,"tv":105.93,"id":12982356}]}]}
{"op":"mcm","clk":"1006343720","pt":1580647809461,"mc":[{"id":"1.168224553","rc":[{"batb":[[0,2.66,44.65],[1,2.62,61.79],[2,2.6,13.53]],"batl":[[0,2.8,35.98],[1,3.05,10.7]],"ltp":2.44,"tv":105.93,"id":12982356},{"batb":[[1,4,83.55],[2,3.95,41]],"batl":[[0,4.6,10.92],[1,4.8,19.75],[2,4.9,18.41]],"ltp":0.0,"tv":0.0,"id":12982355},{"batb":[[0,4.3,12.6],[1,4.2,34.74],[2,4.1,50.87]],"batl":[[0,4.5,22.9],[1,5.1,10.08],[2,5.2,16.29]],"ltp":4.9,"tv":5.88,"id":13015345},{"batl":[[0,6.2,7.56],[1,6.8,18.57],[2,7,17.47]],"ltp":0.0,"tv":0.0,"id":13015344}]}]}
{"op":"mcm","clk":"1006343816","pt":1580647810152,"mc":[{"id":"1.168224553","rc":[{"batb":[[2,5.6,10.31]],"batl":[[2,7,0]],"ltp":0.0,"tv":0.0,"id":13015344}]}]}
{"op":"mcm","clk":"1006346246","pt":1580647825182,"mc":[{"id":"1.168224553","rc":[{"batb":[[0,2.5,27.73],[1,2.34,18.02],[2,1.01,0.51]],"batl":[[0,2.8,22.69]],"ltp":2.44,"tv":105.93,"id":12982356},{"batb":[[0,4,22.03],[1,3.95,41],[2,1.01,0.51]],"batl":[[1,4.9,18.41],[2,4.9,0]],"ltp":0.0,"tv":0.0,"id":12982355},{"batb":[[1,3.6,14.79],[2,1.01,0.51]],"batl":[[0,5.1,10.08],[1,5.2,16.29],[2,5.2,0]],"ltp":4.9,"tv":5.88,"id":13015345},{"batb":[[0,5.7,24.22],[1,5.6,10.31],[2,5.3,9.24]],"ltp":0.0,"tv":0.0,"id":13015344}]}]}
{"op":"mcm","clk":"1006346345","pt":1580647825933,"mc":[{"id":"1.168224553","rc":[{"batb":[[0,2.34,18.02],[1,1.01,0.51],[2,1.01,0]],"batl":[[0,3.05,10.7],[1,3.05,0]],"ltp":2.44,"tv":105.93,"id":12982356},{"batb":[[1,3.95,27.56]],"batl":[[0,4.9,18.41],[1,4.9,0]],"ltp":0.0,"tv":0.0,"id":12982355},{"batb":[[0,3.6,14.79],[1,1.01,0.51],[2,1.01,0]],"batl":[[0,5.2,16.29],[1,5.2,0]],"ltp":4.9,"tv":5.88,"id":13015345},{"batb":[[2,1.01,0.51]],"batl":[[0,6.8,18.57],[1,6.8,0]],"ltp":0.0,"tv":0.0,"id":13015344}]}]}
{"op":"mcm","clk":"1006346663","pt":1580647828113,"mc":[{"id":"1.168224553","rc":[{"batb":[[0,2.38,68.83],[1,2.34,101.62],[2,1.01,0.51]],"batl":[[0,3.1,10.54]],"ltp":2.44,"tv":105.93,"id":12982356},{"batb":[[0,4,21.79],[1,3.95,49.43],[2,3.9,28.56]],"batl":[[0,4.9,18.18]],"ltp":0.0,"tv":0.0,"id":12982355},{"batb":[[0,3.85,38.6],[1,3.8,30.73],[2,3.6,14.79]],"ltp":4.9,"tv":5.88,"id":13015345},{"batb":[[1,5.6,25.12],[2,5.5,10.54]],"ltp":0.0,"tv":0.0,"id":13015344}]}]}
{"op":"mcm","clk":"1006348233","pt":1580647839205,"mc":[{"id":"1.168224553","rc":[{"batb":[[1,1.01,0.51],[2,3.9,0]],"ltp":0.0,"tv":0.0,"id":12982355},{"batb":[[0,3.6,14.79],[1,1.01,0.51],[2,3.6,0]],"ltp":4.9,"tv":5.88,"id":13015345},{"batb":[[0,5.5,10.54],[1,1.01,0.51],[2,5.5,0]],"ltp":0.0,"tv":0.0,"id":13015344}]}]}
{"op":"mcm","clk":"1006348658","pt":1580647842410,"mc":[{"id":"1.168224553","rc":[{"batb":[[0,4.2,26.67],[1,4.1,50.53],[2,4,21.79]],"ltp":0.0,"tv":0.0,"id":12982355},{"batb":[[0,4.8,48.78],[1,4.7,36.85],[2,3.6,14.79]],"ltp":4.9,"tv":5.88,"id":13015345},{"batb":[[0,5.9,26.19],[1,5.8,23.24],[2,5.5,10.54]],"ltp":0.0,"tv":0.0,"id":13015344}]}]}
{"op":"mcm","clk":"1006348773","pt":1580647843307,"mc":[{"id":"1.168224553","rc":[{"batb":[[2,2.32,31.09]],"batl":[[0,2.52,17.39],[1,2.58,26.05],[2,2.8,13.38]],"ltp":2.44,"tv":105.93,"id":12982356},{"batb":[[0,4.3,19.12],[1,4.2,26.67],[2,4.1,71.38]],"batl":[[0,4.7,10.92],[1,4.9,18.18],[2,5.2,16.37]],"ltp":0.0,"tv":0.0,"id":12982355},{"batb":[[0,4.8,59.7],[2,4.5,17.39]],"batl":[[1,5.7,8.4],[2,6.8,19.04]],"ltp":4.9,"tv":5.88,"id":13015345},{"batb":[[2,5.6,20.46]],"batl":[[0,6.4,7.56],[1,6.8,18.18]],"ltp":0.0,"tv":0.0,"id":13015344}]}]}
{"op":"mcm","clk":"1006350705","pt":1580647856449,"mc":[{"id":"1.168224553","rc":[{"batb":[[1,2.34,83.84]],"batl":[[0,2.58,26.05],[1,2.8,13.38],[2,2.8,0]],"ltp":2.44,"tv":105.93,"id":12982356},{"batb":[[0,4.2,26.67],[1,4.1,71.38],[2,4,13.44]],"batl":[[1,5.2,16.37],[2,5.2,0]],"ltp":0.0,"tv":0.0,"id":12982355},{"batb":[[2,3.95,23.76]],"batl":[[0,5.7,8.4],[1,6.8,19.04],[2,6.8,0]],"ltp":4.9,"tv":5.88,"id":13015345}]}]}
{"op":"mcm","clk":"1006350751","pt":1580647856755,"mc":[{"id":"1.168224553","rc":[{"batb":[[0,2.32,31.09],[1,2.06,25.81],[2,1.01,0.51]],"ltp":2.44,"tv":105.93,"id":12982356},{"batb":[[0,4.1,20.85],[1,4,13.44],[2,1.01,0.51]],"ltp":0.0,"tv":0.0,"id":12982355},{"batb":[[0,4.8,10.92],[1,3.95,23.76],[2,1.01,0.51]],"ltp":4.9,"tv":5.88,"id":13015345},{"batb":[[0,5.8,23.24],[1,5.6,20.46],[2,5.4,9.24]],"ltp":0.0,"tv":0.0,"id":13015344}]}]}
{"op":"mcm","clk":"1006350936","pt":1580647857942,"mc":[{"id":"1.168224553","rc":[{"batb":[[0,2.06,25.81],[1,1.01,0.51],[2,1.01,0]],"batl":[[0,2.8,13.38],[1,2.8,0]],"ltp":2.44,"tv":105.93,"id":12982356},{"batb":[[1,1.01,0.51],[2,1.01,0]],"batl":[[0,5.2,16.37],[1,5.2,0]],"ltp":0.0,"tv":0.0,"id":12982355},{"batb":[[0,3.95,23.76],[1,1.01,0.51],[2,1.01,0]],"batl":[[0,6.8,19.04],[1,6.8,0]],"ltp":4.9,"tv":5.88,"id":13015345},{"batb":[[2,1.01,0.51]],"batl":[[0,6.8,18.18],[1,6.8,0]],"ltp":0.0,"tv":0.0,"id":13015344}]}]}
{"op":"mcm","clk":"1006351160","pt":1580647859562,"mc":[{"id":"1.168224553","rc":[{"batb":[[0,2.08,97.78],[1,2.06,86.85],[2,1.01,0.51]],"ltp":2.44,"tv":105.93,"id":12982356},{"batb":[[1,4,65.62],[2,3.95,27.56]],"ltp":0.0,"tv":0.0,"id":12982355},{"batb":[[0,4.2,53.14],[1,4.1,50.48],[2,3.95,23.76]],"ltp":4.9,"tv":5.88,"id":13015345},{"batb":[[1,5.7,24.14],[2,5.6,20.46]],"ltp":0.0,"tv":0.0,"id":13015344}]}]}
{"op":"mcm","clk":"1006351406","pt":1580647861239,"mc":[{"id":"1.168224553","rc":[{"batb":[[0,2.06,25.81],[1,1.01,0.51],[2,1.01,0]],"ltp":2.44,"tv":105.93,"id":12982356},{"batb":[[1,1.01,0.51],[2,3.95,0]],"ltp":0.0,"tv":0.0,"id":12982355},{"batb":[[0,3.95,23.76],[1,1.01,0.51],[2,3.95,0]],"ltp":4.9,"tv":5.88,"id":13015345},{"batb":[[1,5.6,20.46],[2,1.01,0.51]],"ltp":0.0,"tv":0.0,"id":13015344}]}]}
{"op":"mcm","clk":"1006351878","pt":1580647864263,"mc":[{"id":"1.168224553","rc":[{"batb":[[0,2.32,58.69],[1,2.3,44.41],[2,2.06,25.81]],"ltp":2.44,"tv":105.93,"id":12982356},{"batb":[[0,4.2,46.35],[1,4.1,71.05],[2,1.01,0.51]],"ltp":0.0,"tv":0.0,"id":12982355},{"batb":[[0,5,52.36],[1,4.9,33.45],[2,3.95,23.76]],"ltp":4.9,"tv":5.88,"id":13015345},{"batb":[[0,5.9,33.38],[1,5.8,23.24],[2,5.6,20.46]],"ltp":0.0,"tv":0.0,"id":13015344}]}]}
{"op":"mcm","clk":"1006352286","pt":1580647866934,"mc":[{"id":"1.168224553","rc":[{"batb":[[0,2.06,25.81],[1,1.01,0.51],[2,2.06,0]],"ltp":2.44,"tv":105.93,"id":12982356},{"batb":[[0,4.1,20.85],[1,1.01,0.51],[2,1.01,0]],"ltp":0.0,"tv":0.0,"id":12982355},{"batb":[[0,3.95,23.76],[1,1.01,0.51],[2,3.95,0]],"ltp":4.9,"tv":5.88,"id":13015345},{"batb":[[0,5.8,23.24],[1,5.6,20.46],[2,1.01,0.51]],"ltp":0.0,"tv":0.0,"id":13015344}]}]}
{"op":"mcm","clk":"1006352806","pt":1580647869986,"mc":[{"id":"1.168224553","rc":[{"batb":[[0,2.08,97.78],[1,2.06,86.85],[2,1.01,0.51]],"ltp":2.44,"tv":105.93,"id":12982356},{"batb":[[1,4,65.62],[2,3.95,27.56]],"ltp":0.0,"tv":0.0,"id":12982355},{"batb":[[0,4.2,53.14],[1,4.1,50.48],[2,3.95,23.76]],"ltp":4.9,"tv":5.88,"id":13015345},{"batb":[[1,5.7,24.14],[2,5.6,20.46]],"ltp":0.0,"tv":0.0,"id":13015344}]}]}
{"op":"mcm","clk":"1006352954","pt":1580647870869,"mc":[{"id":"1.168224553","rc":[{"batb":[[1,1.01,0.51],[2,3.95,0]],"ltp":0.0,"tv":0.0,"id":12982355},{"batb":[[0,3.95,23.76],[1,1.01,0.51],[2,3.95,0]],"ltp":4.9,"tv":5.88,"id":13015345},{"batb":[[0,5.6,20.46],[1,1.01,0.51],[2,5.6,0]],"ltp":0.0,"tv":0.0,"id":13015344}]}]}
{"op":"mcm","clk":"1006353516","pt":1580647874482,"mc":[{"id":"1.168224553","rc":[{"batb":[[2,1.78,20.3]],"batl":[[0,2.2,25.1],[1,2.5,17.86]],"ltp":2.44,"tv":105.93,"id":12982356},{"batb":[[0,4.5,17.15],[1,4.4,30.26],[2,4.3,45.22]],"batl":[[1,5.6,13.85]],"ltp":0.0,"tv":0.0,"id":12982355},{"batb":[[0,6.2,22.23],[1,6,42.46],[2,5.6,20.46]],"batl":[[1,10.5,7.63]],"ltp":4.9,"tv":5.88,"id":13015345},{"batb":[[0,6,39.18],[1,5.9,22.21],[2,5.7,19.75]],"batl":[[0,7,17.15]],"ltp":0.0,"tv":0.0,"id":13015344}]}]}
{"op":"mcm","clk":"1006353617","pt":1580647875171,"mc":[{"id":"1.168224553","rc":[{"batb":[[0,2.08,136.43]],"batl":[[1,2.28,32.77],[2,2.5,17.86]],"ltp":2.44,"tv":105.93,"id":12982356},{"batl":[[0,4.9,10.08],[1,5.2,16.37],[2,5.6,13.85]],"ltp":0.0,"tv":0.0,"id":12982355},{"batb":[[1,6,50.86]],"ltp":4.9,"tv":5.88,"id":13015345},{"batl":[[0,6.6,6.72],[1,7,17.15]],"ltp":0.0,"tv":0.0,"id":13015344}]}]}
{"op":"mcm","clk":"1006353784","pt":1580647876090,"mc":[{"id":"1.168224553","rc":[{"batl":[[1,7.4,5.88],[2,10.5,7.63]],"ltp":4.9,"tv":5.88,"id":13015345}]}]}
{"op":"mcm","clk":"1006355512","pt":1580647887907,"mc":[{"id":"1.168224553","rc":[{"batb":[[0,1.78,20.3],[1,1.01,0.51],[2,1.78,0]],"batl":[[0,2.5,17.86],[1,2.28,0],[2,2.5,0]],"ltp":2.44,"tv":105.93,"id":12982356},{"batb":[[0,4.2,19.51],[1,1.01,0.51],[2,4.3,0]],"batl":[[0,5.6,13.85],[1,5.2,0],[2,5.6,0]],"ltp":0.0,"tv":0.0,"id":12982355},{"batb":[[0,4.5,16.76],[1,1.01,0.51],[2,5.6,0]],"batl":[[0,10.5,7.63],[1,7.4,0],[2,10.5,0]],"ltp":4.9,"tv":5.88,"id":13015345},{"batb":[[0,5.9,22.21],[1,5.7,19.75],[2,1.01,0.51]],"batl":[[0,7,17.15],[1,7,0]],"ltp":0.0,"tv":0.0,"id":13015344}]}]}
{"op":"mcm","clk":"1006356035","pt":1580647891470,"mc":[{"id":"1.168224553","rc":[{"batb":[[0,4.2,48.39],[1,4.1,50.49],[2,1.01,0.51]],"ltp":0.0,"tv":0.0,"id":12982355},{"batb":[[0,4.9,32.26],[1,4.8,35.38],[2,4.5,16.76]],"ltp":4.9,"tv":5.88,"id":13015345},{"batb":[[0,5.9,31.67],[1,5.8,23.16],[2,5.7,19.75]],"ltp":0.0,"tv":0.0,"id":13015344}]}]}
{"op":"mcm","clk":"1006356620","pt":1580647895458,"mc":[{"id":"1.168224553","rc":[{"batb":[[0,2.36,73.32],[1,2.32,104.1],[2,2.28,32.77]],"batl":[[1,2.52,26.89],[2,2.76,13.77]],"ltp":2.44,"tv":105.93,"id":12982356},{"batb":[[1,4.1,71.1],[2,4,13.44]],"batl":[[0,4.7,10.92],[1,4.9,18.57],[2,5.2,16.05]],"ltp":0.0,"tv":0.0,"id":12982355},{"batb":[[0,4.9,42.34]],"batl":[[0,5.3,15.97],[1,5.9,8.4],[2,6.8,18.65]],"ltp":4.9,"tv":5.88,"id":13015345}]}]}
{"op":"mcm","clk":"1006356862","pt":1580647897296,"mc":[{"id":"1.168224553","rc":[{"batl":[[0,6.4,7.56],[1,7,17.15]],"ltp":0.0,"tv":0.0,"id":13015344}]}]}
{"op":"mcm","clk":"1006358540","pt":1580647909963,"mc":[{"id":"1.168224553","rc":[{"batb":[[0,2.04,26.67],[1,1.01,0.51],[2,2.28,0]],"batl":[[0,2.76,13.77],[1,2.52,0],[2,2.76,0]],"ltp":2.44,"tv":105.93,"id":12982356},{"batb":[[0,4.1,20.61],[1,1.01,0.51],[2,4,0]],"batl":[[0,5.2,16.05],[1,4.9,0],[2,5.2,0]],"ltp":0.0,"tv":0.0,"id":12982355},{"batb":[[0,4,23.05],[1,1.01,0.51],[2,4.5,0]],"batl":[[0,6.8,18.65],[1,5.9,0],[2,6.8,0]],"ltp":4.9,"tv":5.88,"id":13015345},{"batb":[[0,5.8,23.16],[1,5.6,20.54],[2,1.01,0.51]],"batl":[[0,7,17.15],[1,7,0]],"ltp":0.0,"tv":0.0,"id":13015344}]}]}
{"op":"mcm","clk":"1006358909","pt":1580647912562,"mc":[{"id":"1.168224553","rc":[{"batb":[[0,2.08,57.62],[1,2.06,61.09],[2,2.04,26.67]],"ltp":2.44,"tv":105.93,"id":12982356},{"batb":[[1,4,66.29],[2,3.95,27.55]],"ltp":0.0,"tv":0.0,"id":12982355},{"batb":[[0,4.3,24.56],[1,4.2,48.2],[2,4,23.05]],"ltp":4.9,"tv":5.88,"id":13015345},{"batb":[[0,5.8,30.46],[1,5.7,24.08],[2,5.6,20.54]],"ltp":0.0,"tv":0.0,"id":13015344}]}]}
{"op":"mcm","clk":"1006359131","pt":1580647913535,"mc":[{"id":"1.168224553","rc":[{"batb":[[0,2.04,26.67],[1,1.01,0.51],[2,2.04,0]],"ltp":2.44,"tv":105.93,"id":12982356},{"batb":[[1,1.01,0.51],[2,3.95,0]],"ltp":0.0,"tv":0.0,"id":12982355},{"batb":[[0,4,23.05],[1,1.01,0.51],[2,4,0]],"ltp":4.9,"tv":5.88,"id":13015345},{"batb":[[0,5.8,23.16],[1,5.6,20.54],[2,1.01,0.51]],"ltp":0.0,"tv":0.0,"id":13015344}]}]}
{"op":"mcm","clk":"1006359558","pt":1580647916441,"mc":[{"id":"1.168224553","rc":[{"batb":[[0,2.3,66.06],[1,2.28,45.49],[2,2.04,26.67]],"ltp":2.44,"tv":105.93,"id":12982356},{"batb":[[0,4.2,48.81],[1,4.1,70.76],[2,1.01,0.51]],"ltp":0.0,"tv":0.0,"id":12982355},{"batb":[[0,5.1,37.95],[1,5,32.17],[2,4,23.05]],"ltp":4.9,"tv":5.88,"id":13015345},{"batb":[[0,5.9,39.01],[1,5.8,23.16],[2,5.6,20.54]],"ltp":0.0,"tv":0.0,"id":13015344}]}]}
{"op":"mcm","clk":"1006359935","pt":1580647919369,"mc":[{"id":"1.168224553","rc":[{"batb":[[0,2.04,26.67],[1,1.01,0.51],[2,2.04,0]],"ltp":2.44,"tv":105.93,"id":12982356},{"batb":[[0,4.1,20.61],[1,1.01,0.51],[2,1.01,0]],"ltp":0.0,"tv":0.0,"id":12982355},{"batb":[[0,4,23.05],[1,1.01,0.51],[2,4,0]],"ltp":4.9,"tv":5.88,"id":13015345},{"batb":[[0,5.8,23.16],[1,5.6,20.54],[2,1.01,0.51]],"ltp":0.0,"tv":0.0,"id":13015344}]}]}
{"op":"mcm","clk":"1006360319","pt":1580647922382,"mc":[{"id":"1.168224553","rc":[{"batb":[[0,2.08,57.62],[1,2.06,61.09],[2,2.04,26.67]],"ltp":2.44,"tv":105.93,"id":12982356},{"batb":[[1,4,66.29],[2,3.95,27.55]],"ltp":0.0,"tv":0.0,"id":12982355},{"batb":[[0,4.3,24.56],[1,4.2,48.2],[2,4,23.05]],"ltp":4.9,"tv":5.88,"id":13015345},{"batb":[[0,5.8,30.46],[1,5.7,24.08],[2,5.6,20.54]],"ltp":0.0,"tv":0.0,"id":13015344}]}]}
{"op":"mcm","clk":"1006361062","pt":1580647927977,"mc":[{"id":"1.168224553","rc":[{"batb":[[0,2.04,26.67],[1,1.01,0.51],[2,2.04,0]],"ltp":2.44,"tv":105.93,"id":12982356},{"batb":[[1,1.01,0.51],[2,3.95,0]],"ltp":0.0,"tv":0.0,"id":12982355},{"batb":[[0,4,23.05],[1,1.01,0.51],[2,4,0]],"ltp":4.9,"tv":5.88,"id":13015345},{"batb":[[0,5.6,20.54],[1,1.01,0.51],[2,5.6,0]],"ltp":0.0,"tv":0.0,"id":13015344}]}]}
{"op":"mcm","clk":"1006361463","pt":1580647931092,"mc":[{"id":"1.168224553","rc":[{"batb":[[0,2.08,57.62],[1,2.06,100.58],[2,2.04,26.67]],"batl":[[0,2.26,32.77],[1,2.76,13.77]],"ltp":2.44,"tv":105.93,"id":12982356},{"batb":[[0,4.4,33.85],[1,4.3,45.16],[2,4.2,12.6]],"batl":[[0,4.9,10.08],[1,5.2,16.05]],"ltp":0.0,"tv":0.0,"id":12982355},{"batb":[[0,6.2,45.19],[1,6,42.03],[2,4,23.05]],"batl":[[1,7.4,5.88]],"ltp":4.9,"tv":5.88,"id":13015345},{"batb":[[0,6,45.52],[1,5.9,22.13],[2,5.6,28.94]],"batl":[[0,6.6,6.72],[1,7,17.15]],"ltp":0.0,"tv":0.0,"id":13015344}]}]}
{"op":"mcm","clk":"1006361560","pt":1580647931882,"mc":[{"id":"1.168224553","rc":[{"batl":[[0,2.18,25.97],[1,2.26,32.77],[2,2.48,18.25]],"ltp":2.44,"tv":105.93,"id":12982356},{"batb":[[0,4.5,16.84],[1,4.4,33.85],[2,4.3,64.28]],"batl":[[2,5.6,13.61]],"ltp":0.0,"tv":0.0,"id":12982355},{"batb":[[2,5.7,20.06]],"batl":[[2,11,7.55]],"ltp":4.9,"tv":5.88,"id":13015345},{"batb":[[2,5.8,18.96]],"batl":[[2,7.2,17]],"ltp":0.0,"tv":0.0,"id":13015344}]}]}
{"op":"mcm","clk":"1006363560","pt":1580647947438,"mc":[{"id":"1.168224553","rc":[{"batb":[[0,2.06,39.49],[1,1.77,20.61],[2,1.01,0.51]],"batl":[[0,2.26,32.77],[1,2.48,18.25],[2,2.48,0]],"ltp":2.44,"tv":105.93,"id":12982356},{"batb":[[0,4.3,19.12],[1,4.2,12.6],[2,1.01,0.51]],"batl":[[1,5.6,13.61],[2,5.6,0]],"ltp":0.0,"tv":0.0,"id":12982355},{"batb":[[0,6.2,7.56],[1,4.6,16.44],[2,1.01,0.51]],"batl":[[0,7.4,5.88],[1,11,7.55],[2,11,0]],"ltp":4.9,"tv":5.88,"id":13015345},{"batb":[[0,5.9,22.13],[1,5.7,19.75],[2,5.6,8.4]],"batl":[[1,7.2,17],[2,7.2,0]],"ltp":0.0,"tv":0.0,"id":13015344}]}]}
{"op":"mcm","clk":"1006363675","pt":1580647948108,"mc":[{"id":"1.168224553","rc":[{"batb":[[0,1.77,20.61],[1,1.01,0.51],[2,1.01,0]],"batl":[[0,2.48,18.25],[1,2.48,0]],"ltp":2.44,"tv":105.93,"id":12982356},{"batb":[[1,1.01,0.51],[2,1.01,0]],"batl":[[0,5.6,13.61],[1,5.6,0]],"ltp":0.0,"tv":0.0,"id":12982355},{"batb":[[0,4.6,16.44],[1,1.01,0.51],[2,1.01,0]],"batl":[[0,11,7.55],[1,11,0]],"ltp":4.9,"tv":5.88,"id":13015345},{"batb":[[2,1.01,0.51]],"batl":[[0,7.2,17],[1,7.2,0]],"ltp":0.0,"tv":0.0,"id":13015344}]}]}
{"op":"mcm","clk":"1006363976","pt":1580647950357,"mc":[{"id":"1.168224553","rc":[{"batb":[[0,1.78,76.41],[1,1.77,20.61],[2,1.76,100.27]],"batl":[[0,2.46,18.65],[1,2.48,18.25]],"ltp":2.44,"tv":105.93,"id":12982356},{"batb":[[1,4.2,50.27],[2,4.1,50.46]],"ltp":0.0,"tv":0.0,"id":12982355},{"batb":[[0,4.9,51.2],[1,4.8,35.09],[2,4.6,16.44]],"ltp":4.9,"tv":5.88,"id":13015345},{"batb":[[0,5.9,37.29],[1,5.8,23.09],[2,5.7,19.75]],"ltp":0.0,"tv":0.0,"id":13015344}]}]}
{"op":"mcm","clk":"1006364128","pt":1580647951342,"mc":[{"id":"1.168224553","rc":[{"batb":[[0,1.77,20.61],[1,1.01,0.51],[2,1.76,0]],"batl":[[1,2.48,0]],"ltp":2.44,"tv":105.93,"id":12982356},{"batb":[[0,4.2,19.43],[1,1.01,0.51],[2,4.1,0]],"ltp":0.0,"tv":0.0,"id":12982355},{"batb":[[0,4.6,15.89],[1,1.01,0.51],[2,4.6,0]],"batl":[[0,11,7.32]],"ltp":4.9,"tv":5.88,"id":13015345},{"batb":[[0,5.9,22.13],[1,1.01,0.51],[2,5.7,0]],"batl":[[0,7.2,16.44]],"ltp":0.0,"tv":0.0,"id":13015344}]}]}
{"op":"mcm","clk":"1006364523","pt":1580647954212,"mc":[{"id":"1.168224553","rc":[{"batb":[[0,2,101.7],[1,1.98,68.84],[2,1.77,20.61]],"ltp":2.44,"tv":105.93,"id":12982356},{"batb":[[0,4.4,61.48],[1,4.3,44.7],[2,4.2,19.43]],"ltp":0.0,"tv":0.0,"id":12982355},{"batb":[[0,6.8,19.67],[1,6.6,34.55],[2,4.6,15.89]],"ltp":4.9,"tv":5.88,"id":13015345},{"batb":[[0,6,54.93],[1,5.9,22.13],[2,1.01,0.51]],"ltp":0.0,"tv":0.0,"id":13015344}]}]}
{"op":"mcm","clk":"1006364805","pt":1580647956455,"mc":[{"id":"1.168224553","rc":[{"batb":[[0,1.77,20.61],[1,1.01,0.51],[2,1.77,0]],"ltp":2.44,"tv":105.93,"id":12982356},{"batb":[[0,4.2,19.43],[1,1.01,0.51],[2,4.2,0]],"ltp":0.0,"tv":0.0,"id":12982355},{"batb":[[0,4.6,15.89],[1,1.01,0.51],[2,4.6,0]],"ltp":4.9,"tv":5.88,"id":13015345},{"batb":[[0,5.9,22.13],[1,1.01,0.51],[2,1.01,0]],"ltp":0.0,"tv":0.0,"id":13015344}]}]}
{"op":"mcm","clk":"1006365181","pt":1580647959430,"mc":[{"id":"1.168224553","rc":[{"batb":[[0,1.78,76.41],[1,1.77,20.61],[2,1.76,100.27]],"ltp":2.44,"tv":105.93,"id":12982356},{"batb":[[0,4.2,50.27],[1,4.1,50.46],[2,1.01,0.51]],"ltp":0.0,"tv":0.0,"id":12982355},{"batb":[[0,4.9,51.2],[1,4.8,35.09],[2,4.6,15.89]],"ltp":4.9,"tv":5.88,"id":13015345},{"batb":[[0,5.9,37.29],[1,5.8,23.09],[2,1.01,0.51]],"ltp":0.0,"tv":0.0,"id":13015344}]}]}
{"op":"mcm","clk":"1006365706","pt":1580647963374,"mc":[{"id":"1.168224553","rc":[{"batb":[[0,4.2,19.43],[1,1.01,0.51],[2,1.01,0]],"ltp":0.0,"tv":0.0,"id":12982355},{"batb":[[0,4.6,15.89],[1,1.01,0.51],[2,4.6,0]],"ltp":4.9,"tv":5.88,"id":13015345},{"batb":[[0,1.01,0.51],[1,5.8,0],[2,1.01,0]],"ltp":0.0,"tv":0.0,"id":13015344}]}]}
{"op":"mcm","clk":"1006366077","pt":1580647966240,"mc":[{"id":"1.168224553","rc":[{"batb":[[0,4.7,47.75],[1,4.6,38.48],[2,4.2,19.43]],"ltp":0.0,"tv":0.0,"id":12982355},{"batb":[[0,10,26.12],[1,9.8,14.68],[2,4.6,15.89]],"ltp":4.9,"tv":5.88,"id":13015345},{"batb":[[0,6.2,48.22],[1,6,41.91],[2,1.01,0.51]],"ltp":0.0,"tv":0.0,"id":13015344}]}]}
{"op":"mcm","clk":"1006366216","pt":1580647967247,"mc":[{"id":"1.168224553","rc":[{"batl":[[0,1.85,42.01],[1,1.86,20.61],[2,2,16.52]],"ltp":2.44,"tv":105.93,"id":12982356},{"batb":[[0,4.8,14.4],[1,4.7,47.75],[2,4.6,54.22]],"batl":[[0,5.3,9.24],[1,5.6,13.61],[2,5.7,13.14]],"ltp":0.0,"tv":0.0,"id":12982355},{"batb":[[2,8.6,7.63]],"batl":[[1,13.5,12.2]],"ltp":4.9,"tv":5.88,"id":13015345},{"batb":[[2,5.9,8.4]],"batl":[[0,7.2,22.93]],"ltp":0.0,"tv":0.0,"id":13015344}]}]}
{"op":"mcm","clk":"1006366488","pt":1580647969363,"mc":[{"id":"1.168224553","rc":[{"trd":[[11,8.4]],"batl":[[0,11,3.12]],"ltp":11.0,"tv":14.28,"id":13015345}],"tv":120.22}]}
{"op":"mcm","clk":"1006367229","pt":1580647975050,"mc":[{"id":"1.168224553","rc":[{"batb":[[1,1.76,121.36],[2,1.72,57.97]],"batl":[[2,1.99,16.68]],"ltp":2.44,"tv":105.93,"id":12982356},{"batb":[[1,4.7,63.57],[2,4.6,38.48]],"ltp":0.0,"tv":0.0,"id":12982355},{"batb":[[2,9,7.4]],"batl":[[0,11,7.05],[1,13.5,11.8]],"ltp":11.0,"tv":14.28,"id":13015345}]}]}
{"op":"mcm","clk":"1006367645","pt":1580647978277,"mc":[{"id":"1.168224553","rc":[{"trd":[[11,16.8]],"batl":[[0,11,2.85]],"ltp":11.0,"tv":22.68,"id":13015345}],"tv":128.62}]}
{"op":"mcm","clk":"1006367853","pt":1580647979960,"mc":[{"id":"1.168224553","rc":[{"trd":[[1.78,42.08]],"batb":[[0,1.78,55.37]],"ltp":1.78,"tv":148.01,"id":12982356}],"tv":170.69}]}
{"op":"mcm","clk":"1006368278","pt":1580647982950,"mc":[{"id":"1.168224553","rc":[{"batl":[[0,1.85,62.94],[1,1.98,16.76],[2,1.99,0]],"ltp":1.78,"tv":148.01,"id":12982356},{"batb":[[0,4.9,14.56]],"ltp":0.0,"tv":0.0,"id":12982355},{"batb":[[2,9.2,7.16]],"batl":[[0,11.5,17.07],[1,14,11.41]],"ltp":11.0,"tv":22.68,"id":13015345},{"batb":[[2,5.9,27.05]],"ltp":0.0,"tv":0.0,"id":13015344}]}]}
{"op":"mcm","clk":"1006368814","pt":1580647986436,"mc":[{"id":"1.168224553","rc":[{"batb":[[0,11,4.2],[1,10,26.12],[2,9.8,14.68]],"ltp":11.0,"tv":22.68,"id":13015345}]}]}
{"op":"mcm","clk":"1006373525","pt":1580648018307,"mc":[{"id":"1.168224553","rc":[{"batb":[[0,1.76,21.09],[1,1.72,57.97],[2,1.69,24.31]],"ltp":1.78,"tv":148.01,"id":12982356}]}]}
{"op":"mcm","clk":"1006373984","pt":1580648021205,"mc":[{"id":"1.168224553","rc":[{"batb":[[0,1.77,106.86],[1,1.76,21.09],[2,1.75,102.53]],"ltp":1.78,"tv":148.01,"id":12982356},{"batb":[[1,10,30.73]],"ltp":11.0,"tv":22.68,"id":13015345},{"batb":[[0,6.2,55.95]],"ltp":0.0,"tv":0.0,"id":13015344}]}]}
{"op":"mcm","clk":"1006375160","pt":1580648029035,"mc":[{"id":"1.168224553","rc":[{"batb":[[0,6.2,40.05],[1,5.9,27.05],[2,1.01,0.51]],"ltp":0.0,"tv":0.0,"id":13015344}]}]}
{"op":"mcm","clk":"1006375678","pt":1580648032470,"mc":[{"id":"1.168224553","rc":[{"batb":[[0,6.4,16.56],[1,6.2,40.05],[2,5.9,27.05]],"ltp":0.0,"tv":0.0,"id":13015344}]}]}
{"op":"mcm","clk":"1006376384","pt":1580648037436,"mc":[{"id":"1.168224553","rc":[{"batb":[[0,1.77,80.72]],"ltp":1.78,"tv":148.01,"id":12982356},{"batb":[[1,4.7,56.05]],"ltp":0.0,"tv":0.0,"id":12982355}]}]}
{"op":"mcm","clk":"1006376813","pt":1580648040334,"mc":[{"id":"1.168224553","rc":[{"batb":[[1,10,37.92]],"ltp":11.0,"tv":22.68,"id":13015345},{"batb":[[0,6.4,27.36]],"ltp":0.0,"tv":0.0,"id":13015344}]}]}
{"op":"mcm","clk":"1006377307","pt":1580648043723,"mc":[{"id":"1.168224553","rc":[{"batb":[[0,1.76,21.09],[1,1.72,57.97],[2,1.69,24.31]],"ltp":1.78,"tv":148.01,"id":12982356},{"batb":[[1,4.7,47.94]],"ltp":0.0,"tv":0.0,"id":12982355},{"batb":[[2,9.2,7.16]],"ltp":11.0,"tv":22.68,"id":13015345}]}]}
{"op":"mcm","clk":"1006377722","pt":1580648046730,"mc":[{"id":"1.168224553","rc":[{"batb":[[0,1.76,113.66],[1,1.74,104.64],[2,1.72,57.97]],"ltp":1.78,"tv":148.01,"id":12982356},{"batb":[[1,10.5,12.52],[2,10,37.92]],"ltp":11.0,"tv":22.68,"id":13015345},{"batb":[[0,6.4,45.53]],"ltp":0.0,"tv":0.0,"id":13015344}]}]}
{"op":"mcm","clk":"1006378105","pt":1580648049450,"mc":[{"id":"1.168224553","rc":[{"batb":[[0,1.76,89.49]],"ltp":1.78,"tv":148.01,"id":12982356},{"batb":[[0,6.4,38.34],[1,5.9,27.05],[2,1.01,0.51]],"ltp":0.0,"tv":0.0,"id":13015344}]}]}
{"op":"mcm","clk":"1006378507","pt":1580648052458,"mc":[{"id":"1.168224553","rc":[{"batb":[[1,10.5,19.06]],"ltp":11.0,"tv":22.68,"id":13015345},{"batb":[[0,6.6,18.01],[1,6.4,38.34],[2,5.9,27.05]],"ltp":0.0,"tv":0.0,"id":13015344}]}]}
{"op":"mcm","clk":"1006380166","pt":1580648064261,"mc":[{"id":"1.168224553","rc":[{"batb":[[0,1.76,21.09],[1,1.72,57.97],[2,1.69,24.31]],"ltp":1.78,"tv":148.01,"id":12982356},{"batb":[[1,4.7,15.82],[2,4.5,11.76]],"ltp":0.0,"tv":0.0,"id":12982355},{"batb":[[1,9.2,7.16],[2,7.4,11.57]],"ltp":11.0,"tv":22.68,"id":13015345},{"batb":[[0,5.9,27.05],[1,1.01,0.51],[2,5.9,0]],"ltp":0.0,"tv":0.0,"id":13015344}]}]}
{"op":"mcm","clk":"1006380231","pt":1580648064780,"mc":[{"id":"1.168224553","rc":[{"batb":[[0,1.72,57.97],[1,1.69,24.31],[2,1.01,0.51]],"batl":[[0,1.85,42.01]],"ltp":1.78,"tv":148.01,"id":12982356},{"batb":[[0,4.7,15.82],[1,4.5,11.76],[2,1.01,0.51]],"batl":[[1,5.7,13.14],[2,5.7,0]],"ltp":0.0,"tv":0.0,"id":12982355},{"batb":[[1,7.4,11.57],[2,1.01,0.51]],"batl":[[0,14,11.41],[1,14,0]],"ltp":11.0,"tv":22.68,"id":13015345}]}]}
{"op":"mcm","clk":"1006380383","pt":1580648065990,"mc":[{"id":"1.168224553","rc":[{"batb":[[0,1.69,24.31],[1,1.01,0.51],[2,1.01,0]],"batl":[[0,1.98,16.76],[1,1.98,0]],"ltp":1.78,"tv":148.01,"id":12982356},{"batb":[[1,1.01,0.51],[2,1.01,0]],"batl":[[0,5.7,13.14],[1,5.7,0]],"ltp":0.0,"tv":0.0,"id":12982355},{"batb":[[0,7.4,11.57],[1,1.01,0.51],[2,1.01,0]],"ltp":11.0,"tv":22.68,"id":13015345},{"batb":[[0,5.9,18.65]],"batl":[[0,7.2,16.21]],"ltp":0.0,"tv":0.0,"id":13015344}]}]}
{"op":"mcm","clk":"1006380716","pt":1580648068388,"mc":[{"id":"1.168224553","rc":[{"batb":[[0,1.68,24.86]],"batl":[[0,1.96,17.23]],"ltp":1.78,"tv":148.01,"id":12982356},{"batb":[[0,4.6,16.21],[1,4.5,25.87],[2,1.01,0.51]],"ltp":0.0,"tv":0.0,"id":12982355},{"batb":[[0,7.6,11.09]],"batl":[[0,14.5,10.94]],"ltp":11.0,"tv":22.68,"id":13015345},{"batb":[[0,6.6,24.79],[1,6,17.78],[2,1.01,0.51]],"batl":[[0,7.4,15.42]],"ltp":0.0,"tv":0.0,"id":13015344}]}]}
{"op":"mcm","clk":"1006380973","pt":1580648070388,"mc":[{"id":"1.168224553","rc":[{"batb":[[0,1.76,89.89],[1,1.74,104.79],[2,1.68,24.86]],"ltp":1.78,"tv":148.01,"id":12982356},{"batb":[[0,4.6,51.73],[1,4.5,39.98]],"ltp":0.0,"tv":0.0,"id":12982355},{"batb":[[0,10,43.92],[1,9.8,15.37],[2,7.6,11.09]],"ltp":11.0,"tv":22.68,"id":13015345},{"batb":[[0,6.8,15.01],[1,6.6,36.94],[2,6,17.78]],"ltp":0.0,"tv":0.0,"id":13015344}]}]}
{"op":"mcm","clk":"1006381189","pt":1580648071798,"mc":[{"id":"1.168224553","rc":[{"batb":[[0,1.68,24.86],[1,1.01,0.51],[2,1.68,0]],"ltp":1.78,"tv":148.01,"id":12982356},{"batb":[[0,4.6,16.21],[1,4.5,25.87]],"ltp":0.0,"tv":0.0,"id":12982355},{"batb":[[0,7.6,11.09],[1,1.01,0.51],[2,7.6,0]],"ltp":11.0,"tv":22.68,"id":13015345},{"batb":[[0,6.6,24.79],[1,6,17.78],[2,1.01,0.51]],"ltp":0.0,"tv":0.0,"id":13015344}]}]}
{"op":"mcm","clk":"1006381502","pt":1580648074183,"mc":[{"id":"1.168224553","rc":[{"batb":[[1,1.01,0.51],[2,1.01,0]],"ltp":0.0,"tv":0.0,"id":12982355}]}]}
{"op":"mcm","clk":"1006381620","pt":1580648075178,"mc":[{"id":"1.168224553","rc":[{"batb":[[0,1.68,130.77],[1,1.67,60.83],[2,1.01,0.51]],"ltp":1.78,"tv":148.01,"id":12982356}]}]}
{"op":"mcm","clk":"1006381893","pt":1580648077088,"mc":[{"id":"1.168224553","rc":[{"batb":[[0,4.7,44.53],[1,4.6,54.04],[2,1.01,0.51]],"ltp":0.0,"tv":0.0,"id":12982355},{"batb":[[0,12.5,28.86],[1,12,24.78],[2,7.6,11.09]],"ltp":11.0,"tv":22.68,"id":13015345},{"batb":[[0,6.8,41.16],[1,6.6,36.27],[2,6,17.78]],"ltp":0.0,"tv":0.0,"id":13015344}]}]}
{"op":"mcm","clk":"1006382012","pt":1580648077887,"mc":[{"id":"1.168224553","rc":[{"batb":[[2,1.63,27.77]],"batl":[[0,1.76,24.39],[1,1.87,20.22]],"ltp":1.78,"tv":148.01,"id":12982356},{"batb":[[0,4.9,14.01],[1,4.7,59.79],[2,4.6,37.83]],"batl":[[1,5.8,12.9]],"ltp":0.0,"tv":0.0,"id":12982355},{"batb":[[2,11,11.88]],"batl":[[1,17,7.95]],"ltp":11.0,"tv":22.68,"id":13015345},{"batb":[[2,6.2,16.44]],"batl":[[1,7.6,14.63]],"ltp":0.0,"tv":0.0,"id":13015344}]}]}
{"op":"mcm","clk":"1006382162","pt":1580648078873,"mc":[{"id":"1.168224553","rc":[{"batb":[[1,1.67,123]],"batl":[[1,1.8,42.01],[2,1.87,20.22]],"ltp":1.78,"tv":148.01,"id":12982356},{"batb":[[2,4.6,48.75]],"batl":[[0,5.4,9.24],[1,5.7,13.14],[2,5.8,12.9]],"ltp":0.0,"tv":0.0,"id":12982355},{"batb":[[0,12.5,32.22]],"ltp":11.0,"tv":22.68,"id":13015345},{"batl":[[0,7.4,21.3]],"ltp":0.0,"tv":0.0,"id":13015344}]}]}
{"op":"mcm","clk":"1006383847","pt":1580648090308,"mc":[{"id":"1.168224553","rc":[{"batb":[[0,1.63,27.54],[1,1.01,0.51],[2,1.63,0]],"batl":[[0,1.87,20.22],[1,1.8,0],[2,1.87,0]],"ltp":1.78,"tv":148.01,"id":12982356},{"batb":[[0,4.7,15.26],[1,4.6,37.83],[2,1.01,0.51]],"batl":[[0,5.8,12.9],[1,5.7,0],[2,5.8,0]],"ltp":0.0,"tv":0.0,"id":12982355},{"batb":[[0,9,7.55],[1,1.01,0.51],[2,11,0]],"batl":[[0,17,7.95],[1,17,0]],"ltp":11.0,"tv":22.68,"id":13015345},{"batb":[[0,6.6,36.27],[1,6,17.07],[2,1.01,0.51]],"batl":[[0,7.6,14.63],[1,7.6,0]],"ltp":0.0,"tv":0.0,"id":13015344}]}]}
{"op":"mcm","clk":"1006384313","pt":1580648093397,"mc":[{"id":"1.168224553","rc":[{"batb":[[0,1.64,92.71],[1,1.63,93.86],[2,1.01,0.51]],"ltp":1.78,"tv":148.01,"id":12982356},{"batb":[[2,4.5,40.06]],"ltp":0.0,"tv":0.0,"id":12982355},{"batb":[[0,10,39.63],[1,9.8,15.43],[2,9,7.55]],"ltp":11.0,"tv":22.68,"id":13015345},{"batb":[[0,6.6,43.85],[1,6.4,38.72],[2,6,17.07]],"ltp":0.0,"tv":0.0,"id":13015344}]}]}
{"op":"mcm","clk":"1006384583","pt":1580648095102,"mc":[{"id":"1.168224553","rc":[{"batb":[[0,1.63,27.54],[1,1.01,0.51],[2,1.01,0]],"ltp":1.78,"tv":148.01,"id":12982356},{"batb":[[2,1.01,0.51]],"ltp":0.0,"tv":0.0,"id":12982355},{"batb":[[0,9,7.55],[1,1.01,0.51],[2,9,0]],"ltp":11.0,"tv":22.68,"id":13015345},{"batb":[[0,6.6,36.44],[1,6,17.07],[2,1.01,0.51]],"ltp":0.0,"tv":0.0,"id":13015344}]}]}
{"op":"mcm","clk":"1006385459","pt":1580648101137,"mc":[{"id":"1.168224553","rc":[{"batb":[[0,1.64,92.71],[1,1.63,93.86],[2,1.01,0.51]],"ltp":1.78,"tv":148.01,"id":12982356},{"batb":[[2,4.5,40.06]],"ltp":0.0,"tv":0.0,"id":12982355},{"batb":[[0,10,39.63],[1,9.8,15.43],[2,9,7.55]],"ltp":11.0,"tv":22.68,"id":13015345},{"batb":[[0,6.6,43.85],[1,6.4,38.72],[2,6,17.07]],"ltp":0.0,"tv":0.0,"id":13015344}]}]}
{"op":"mcm","clk":"1006385845","pt":1580648103706,"mc":[{"id":"1.168224553","rc":[{"batb":[[1,1.01,0.51],[2,4.5,0]],"ltp":0.0,"tv":0.0,"id":12982355},{"batb":[[0,9,7.55],[1,1.01,0.51],[2,9,0]],"ltp":11.0,"tv":22.68,"id":13015345},{"batb":[[0,6,17.07],[1,1.01,0.51],[2,6,0]],"ltp":0.0,"tv":0.0,"id":13015344}]}]}
{"op":"mcm","clk":"1006386292","pt":1580648106351,"mc":[{"id":"1.168224553","rc":[{"batb":[[0,4.8,36.85],[1,4.7,51.38],[2,1.01,0.51]],"ltp":0.0,"tv":0.0,"id":12982355},{"batb":[[0,14.5,22.56],[1,14,18.12],[2,9,7.55]],"ltp":11.0,"tv":22.68,"id":13015345},{"batb":[[0,7,23.34],[1,6.8,34.38],[2,6,17.07]],"ltp":0.0,"tv":0.0,"id":13015344}]}]}
{"op":"mcm","clk":"1006386428","pt":1580648107235,"mc":[{"id":"1.168224553","rc":[{"batb":[[1,1.63,160.23],[2,1.59,30.06]],"batl":[[0,1.71,26.99],[1,1.76,42.01],[2,1.78,23.53]],"ltp":1.78,"tv":148.01,"id":12982356},{"batb":[[0,5,13.45],[1,4.9,14.32],[2,4.8,36.85]],"batl":[[0,5.5,9.24],[1,5.8,12.9],[2,5.9,12.27]],"ltp":0.0,"tv":0.0,"id":12982355},{"batb":[[2,13.5,3.36]],"batl":[[1,19.5,6.22]],"ltp":11.0,"tv":22.68,"id":13015345},{"batb":[[2,6.2,23.46]],"batl":[[0,7.4,5.88],[1,7.6,14.63],[2,7.8,14.32]],"ltp":0.0,"tv":0.0,"id":13015344}]}]}
{"op":"mcm","clk":"1006388325","pt":1580648120231,"mc":[{"id":"1.168224553","rc":[{"batb":[[0,1.59,30.06],[1,1.01,0.51],[2,1.59,0]],"batl":[[0,1.78,23.53],[1,1.76,0],[2,1.78,0]],"ltp":1.78,"tv":148.01,"id":12982356},{"batb":[[0,4.9,14.32],[1,4.7,36.12],[2,1.01,0.51]],"batl":[[0,5.9,12.27],[1,5.8,0],[2,5.9,0]],"ltp":0.0,"tv":0.0,"id":12982355},{"batb":[[0,10.5,12.67],[1,1.01,0.51],[2,13.5,0]],"batl":[[0,19.5,6.22],[1,19.5,0]],"ltp":11.0,"tv":22.68,"id":13015345},{"batb":[[0,6.8,26.44],[1,6,16.92],[2,1.01,0.51]],"batl":[[0,7.8,14.32],[1,7.6,0],[2,7.8,0]],"ltp":0.0,"tv":0.0,"id":13015344}]}]}
{"op":"mcm","clk":"1006388697","pt":1580648122853,"mc":[{"id":"1.168224553","rc":[{"batb":[[0,1.61,100.59],[1,1.6,71.04],[2,1.59,30.06]],"ltp":1.78,"tv":148.01,"id":12982356},{"batb":[[2,4.6,37.99]],"ltp":0.0,"tv":0.0,"id":12982355},{"batb":[[0,12.5,13.12],[1,12,25.36],[2,10.5,12.67]],"ltp":11.0,"tv":22.68,"id":13015345},{"batb":[[1,6.6,36.61],[2,6,16.92]],"ltp":0.0,"tv":0.0,"id":13015344}]}]}
{"op":"mcm","clk":"1006389579","pt":1580648129187,"mc":[{"id":"1.168224553","rc":[{"batb":[[0,1.59,30.06],[1,1.01,0.51],[2,1.59,0]],"ltp":1.78,"tv":148.01,"id":12982356}]}]}
{"op":"mcm","clk":"1006390098","pt":1580648132486,"mc":[{"id":"1.168224553","rc":[{"batb":[[0,1.7,91.5],[1,1.68,118.21],[2,1.64,27.15]],"batl":[[1,1.91,18.88]],"ltp":1.78,"tv":148.01,"id":12982356},{"batb":[[1,4.7,51.86]],"batl":[[0,5.6,13.77],[1,5.8,12.9],[2,5.9,12.27]],"ltp":0.0,"tv":0.0,"id":12982355},{"batl":[[0,14,11.57],[1,16.5,8.1],[2,19.5,6.22]],"ltp":11.0,"tv":22.68,"id":13015345},{"batl":[[0,7.4,15.26],[1,7.8,14.32]],"ltp":0.0,"tv":0.0,"id":13015344}]}]}
{"op":"mcm","clk":"1006390228","pt":1580648133282,"mc":[{"id":"1.168224553","rc":[{"batb":[[1,1.68,179.54]],"batl":[[1,1.81,42.01],[2,1.91,18.88]],"ltp":1.78,"tv":148.01,"id":12982356},{"batb":[[2,4.6,48.91]],"batl":[[0,5.4,9.24],[1,5.6,13.77],[2,5.8,12.9]],"ltp":0.0,"tv":0.0,"id":12982355},{"batl":[[2,19.5,0]],"ltp":11.0,"tv":22.68,"id":13015345},{"batb":[[2,6,25.32]],"batl":[[0,7.2,6.72],[1,7.4,15.26]],"ltp":0.0,"tv":0.0,"id":13015344}]}]}
{"op":"mcm","clk":"1006390392","pt":1580648134360,"mc":[{"id":"1.168224553","rc":[{"batb":[[1,12,28.72]],"ltp":11.0,"tv":22.68,"id":13015345}]}]}
{"op":"mcm","clk":"1006391986","pt":1580648146993,"mc":[{"id":"1.168224553","rc":[{"batb":[[0,1.68,61.33],[1,1.64,27.15],[2,1.01,0.51]],"batl":[[0,1.81,42.01],[1,1.91,18.88],[2,1.91,0]],"ltp":1.78,"tv":148.01,"id":12982356},{"batb":[[0,4.7,15.74],[1,4.6,10.92],[2,1.01,0.51]],"batl":[[1,5.8,12.9],[2,5.8,0]],"ltp":0.0,"tv":0.0,"id":12982355},{"batb":[[0,12,3.36],[1,8.4,8.5],[2,1.01,0.51]],"batl":[[0,16.5,8.1],[1,16.5,0]],"ltp":11.0,"tv":22.68,"id":13015345},{"batb":[[0,6.6,28.97],[1,6,25.32],[2,1.01,0.51]],"ltp":0.0,"tv":0.0,"id":13015344}]}]}
{"op":"mcm","clk":"1006392129","pt":1580648148105,"mc":[{"id":"1.168224553","rc":[{"batb":[[0,1.64,27.15],[1,1.01,0.51],[2,1.01,0]],"batl":[[0,1.91,18.88],[1,1.91,0]],"ltp":1.78,"tv":148.01,"id":12982356},{"batb":[[1,1.01,0.51],[2,1.01,0]],"batl":[[0,5.8,12.9],[1,5.8,0]],"ltp":0.0,"tv":0.0,"id":12982355},{"batb":[[0,8.4,8.5],[1,1.01,0.51],[2,1.01,0]],"ltp":11.0,"tv":22.68,"id":13015345},{"batb":[[1,6,16.92]],"batl":[[0,7.4,15.26],[1,7.4,0]],"ltp":0.0,"tv":0.0,"id":13015344}]}]}
{"op":"mcm","clk":"1006392789","pt":1580648153083,"mc":[{"id":"1.168224553","rc":[{"batb":[[0,1.72,61.93],[1,1.7,113.4],[2,1.64,27.15]],"ltp":1.78,"tv":148.01,"id":12982356},{"batb":[[0,4.7,39.26],[1,4.6,38.2],[2,1.01,0.51]],"ltp":0.0,"tv":0.0,"id":12982355},{"batb":[[0,11.5,32.77],[1,11,27.2],[2,8.4,8.5]],"ltp":11.0,"tv":22.68,"id":13015345},{"batb":[[0,6.8,19.47],[1,6.6,36.78],[2,6,16.92]],"ltp":0.0,"tv":0.0,"id":13015344}]}]}
{"op":"mcm","clk":"1006393081","pt":1580648155804,"mc":[{"id":"1.168224553","rc":[{"batb":[[0,1.64,27.15],[1,1.01,0.51],[2,1.64,0]],"ltp":1.78,"tv":148.01,"id":12982356},{"batb":[[0,4.7,15.74],[1,1.01,0.51],[2,1.01,0]],"ltp":0.0,"tv":0.0,"id":12982355},{"batb":[[0,8.4,8.5],[1,1.01,0.51],[2,8.4,0]],"ltp":11.0,"tv":22.68,"id":13015345},{"batb":[[0,6.6,29.04],[1,6,16.92],[2,1.01,0.51]],"ltp":0.0,"tv":0.0,"id":13015344}]}]}
{"op":"mcm","clk":"1006393465","pt":1580648158690,"mc":[{"id":"1.168224553","rc":[{"batb":[[0,1.64,151.93],[1,1.63,66.41],[2,1.01,0.51]],"ltp":1.78,"tv":148.01,"id":12982356},{"batb":[[1,4.5,54.97],[2,4.4,41.8]],"ltp":0.0,"tv":0.0,"id":12982355},{"batb":[[0,9.8,11.49],[1,9.6,16.65],[2,8.4,8.5]],"ltp":11.0,"tv":22.68,"id":13015345},{"batb":[[1,6.4,39.09],[2,6,16.92]],"ltp":0.0,"tv":0.0,"id":13015344}]}]}
{"op":"mcm","clk":"1006395100","pt":1580648170828,"mc":[{"id":"1.168224553","rc":[{"batb":[[0,1.64,27.15],[1,1.01,0.51],[2,1.01,0]],"ltp":1.78,"tv":148.01,"id":12982356},{"batb":[[1,1.01,0.51],[2,4.4,0]],"ltp":0.0,"tv":0.0,"id":12982355},{"batb":[[0,8.4,8.5],[1,1.01,0.51],[2,8.4,0]],"ltp":11.0,"tv":22.68,"id":13015345},{"batb":[[1,6,16.92],[2,1.01,0.51]],"ltp":0.0,"tv":0.0,"id":13015344}]}]}
{"op":"mcm","clk":"1006395518","pt":1580648174350,"mc":[{"id":"1.168224553","rc":[{"batb":[[0,1.64,151.93],[1,1.63,66.41],[2,1.61,29.27]],"batl":[[0,1.72,26.59],[1,1.8,22.9],[2,1.91,18.88]],"ltp":1.78,"tv":148.01,"id":12982356},{"batb":[[0,5,13.53],[1,4.8,46.52],[2,4.7,51.94]],"ltp":0.0,"tv":0.0,"id":12982355},{"batb":[[0,15,6.78],[1,14.5,17.34],[2,12.5,8.73]],"batl":[[1,19.5,6.22]],"ltp":11.0,"tv":22.68,"id":13015345},{"batb":[[0,6.8,45.78],[1,6.6,36.12],[2,6.2,16.21]],"batl":[[1,7.6,14.71]],"ltp":0.0,"tv":0.0,"id":13015344}]}]}
{"op":"mcm","clk":"1006395645","pt":1580648175448,"mc":[{"id":"1.168224553","rc":[{"batb":[[0,1.64,217.46]],"batl":[[1,1.77,42.01],[2,1.8,22.9]],"ltp":1.78,"tv":148.01,"id":12982356},{"batb":[[2,4.7,47.12]],"batl":[[0,5.5,9.24],[1,5.8,12.67]],"ltp":0.0,"tv":0.0,"id":12982355},{"batl":[[0,7.4,21.15]],"ltp":0.0,"tv":0.0,"id":13015344}]}]}
{"op":"mcm","clk":"1006395711","pt":1580648175956,"mc":[{"id":"1.168224553","rc":[{"batb":[[0,1.64,157.54],[1,1.61,29.27],[2,1.01,0.51]],"ltp":1.78,"tv":148.01,"id":12982356},{"batb":[[0,14.5,13.02],[1,12.5,8.73],[2,10.5,12.75]],"ltp":11.0,"tv":22.68,"id":13015345},{"batb":[[0,6.8,19.67]],"ltp":0.0,"tv":0.0,"id":13015344}]}]}
{"op":"mcm","clk":"1006396092","pt":1580648178881,"mc":[{"id":"1.168224553","rc":[{"batb":[[0,1.65,116.02],[1,1.64,157.54],[2,1.61,29.27]],"ltp":1.78,"tv":148.01,"id":12982356},{"batb":[[1,4.8,56.12]],"ltp":0.0,"tv":0.0,"id":12982355},{"batb":[[1,14,18.07],[2,12.5,8.73]],"ltp":11.0,"tv":22.68,"id":13015345}]}]}
{"op":"mcm","clk":"1006396738","pt":1580648183477,"mc":[{"id":"1.168224553","rc":[{"batb":[[0,1.65,82.36]],"ltp":1.78,"tv":148.01,"id":12982356}]}]}
{"op":"mcm","clk":"1006396954","pt":1580648185395,"mc":[{"id":"1.168224553","rc":[{"batb":[[0,14.5,17.22]],"ltp":11.0,"tv":22.68,"id":13015345},{"batb":[[0,6.8,29.29]],"ltp":0.0,"tv":0.0,"id":13015344}]}]}
{"op":"mcm","clk":"1006397097","pt":1580648186511,"mc":[{"id":"1.168224553","rc":[{"batb":[[0,14.5,21.46]],"ltp":11.0,"tv":22.68,"id":13015345}]}]}
{"op":"mcm","clk":"1006397739","pt":1580648191307,"mc":[{"id":"1.168224553","rc":[{"batb":[[0,1.64,92.68],[1,1.61,29.27],[2,1.01,0.51]],"ltp":1.78,"tv":148.01,"id":12982356},{"batb":[[1,4.8,14.56]],"ltp":0.0,"tv":0.0,"id":12982355},{"batb":[[0,13.5,3.36],[1,12.5,8.73],[2,10.5,12.75]],"ltp":11.0,"tv":22.68,"id":13015345},{"batb":[[0,6.6,36.12],[1,6.2,16.21],[2,6,25.32]],"ltp":0.0,"tv":0.0,"id":13015344}]}]}
{"op":"mcm","clk":"1006397819","pt":1580648191986,"mc":[{"id":"1.168224553","rc":[{"batb":[[0,1.61,29.27],[1,1.01,0.51],[2,1.01,0]],"batl":[[0,1.8,22.9],[1,1.77,0],[2,1.8,0]],"ltp":1.78,"tv":148.01,"id":12982356},{"batb":[[0,4.8,14.56],[1,4.7,36.2],[2,1.01,0.51]],"batl":[[0,5.8,12.67],[1,5.8,0]],"ltp":0.0,"tv":0.0,"id":12982355},{"batb":[[0,10.5,12.75],[1,1.01,0.51],[2,10.5,0]],"batl":[[0,19.5,6.22],[1,19.5,0]],"ltp":11.0,"tv":22.68,"id":13015345},{"batb":[[1,6,16.92],[2,1.01,0.51]],"batl":[[0,7.6,14.71],[1,7.6,0]],"ltp":0.0,"tv":0.0,"id":13015344}]}]}
{"op":"mcm","clk":"1006398115","pt":1580648194189,"mc":[{"id":"1.168224553","rc":[{"batb":[[0,1.62,92.67],[1,1.61,98.69],[2,1.01,0.51]],"ltp":1.78,"tv":148.01,"id":12982356},{"batb":[[2,4.6,38.07]],"ltp":0.0,"tv":0.0,"id":12982355},{"batb":[[0,12.5,15.4],[1,12,25.16],[2,10.5,12.75]],"ltp":11.0,"tv":22.68,"id":13015345},{"batb":[[1,6.4,38.51],[2,6,16.92]],"ltp":0.0,"tv":0.0,"id":13015344}]}]}
{"op":"mcm","clk":"1006398654","pt":1580648198294,"mc":[{"id":"1.168224553","rc":[{"batb":[[0,1.61,29.27],[1,1.01,0.51],[2,1.01,0]],"ltp":1.78,"tv":148.01,"id":12982356}]}]}
{"op":"mcm","clk":"1006399067","pt":1580648201211,"mc":[{"id":"1.168224553","rc":[{"batb":[[0,1.7,106.61],[1,1.68,118.39],[2,1.61,29.27]],"ltp":1.78,"tv":148.01,"id":12982356}]}]}
{"op":"mcm","clk":"1006399179","pt":1580648202094,"mc":[{"id":"1.168224553","rc":[{"batb":[[0,1.71,23.37],[1,1.7,106.61],[2,1.68,118.39]],"batl":[[1,1.93,18.18]],"ltp":1.78,"tv":148.01,"id":12982356},{"batb":[[2,4.6,54.2]],"batl":[[0,5.6,14.01],[1,5.7,13.22]],"ltp":0.0,"tv":0.0,"id":12982355},{"batl":[[0,14,11.64],[1,17.5,7.55]],"ltp":11.0,"tv":22.68,"id":13015345},{"batb":[[2,5.9,18.18]],"batl":[[0,7.4,15.82]],"ltp":0.0,"tv":0.0,"id":13015344}]}]}
{"op":"mcm","clk":"1006399292","pt":1580648203010,"mc":[{"id":"1.168224553","rc":[{"batb":[[2,1.69,60.49]],"batl":[[1,1.83,42.01],[2,1.93,18.18]],"ltp":1.78,"tv":148.01,"id":12982356},{"batb":[[2,4.6,65.12]],"batl":[[0,5.4,9.24],[1,5.6,14.01],[2,5.7,13.22]],"ltp":0.0,"tv":0.0,"id":12982355},{"batb":[[0,12.5,18.76]],"ltp":11.0,"tv":22.68,"id":13015345},{"batb":[[2,5.9,26.58]],"batl":[[0,7,6.72],[1,7.4,15.82]],"ltp":0.0,"tv":0.0,"id":13015344}]}]}
{"op":"mcm","clk":"1006400757","pt":1580648213300,"mc":[{"id":"1.168224553","rc":[{"batb":[[0,1.69,60.49],[1,1.65,26.91],[2,1.01,0.51]],"batl":[[0,1.83,42.01],[1,1.93,18.18],[2,1.93,0]],"ltp":1.78,"tv":148.01,"id":12982356},{"batb":[[0,4.6,27.05],[1,1.01,0.51],[2,4.6,0]],"batl":[[1,5.7,13.22],[2,5.7,0]],"ltp":0.0,"tv":0.0,"id":12982355},{"batb":[[0,12.5,3.36],[1,8.2,9.21],[2,1.01,0.51]],"batl":[[0,17.5,7.55],[1,17.5,0]],"ltp":11.0,"tv":22.68,"id":13015345},{"batb":[[0,6.4,38.51],[1,5.9,26.58],[2,1.01,0.51]],"ltp":0.0,"tv":0.0,"id":13015344}]}]}
{"op":"mcm","clk":"1006400859","pt":1580648214121,"mc":[{"id":"1.168224553","rc":[{"batb":[[0,1.65,26.91],[1,1.01,0.51],[2,1.01,0]],"batl":[[0,1.93,18.18],[1,1.93,0]],"ltp":1.78,"tv":148.01,"id":12982356},{"batb":[[0,4.6,16.13]],"batl":[[0,5.7,13.22],[1,5.7,0]],"ltp":0.0,"tv":0.0,"id":12982355},{"batb":[[0,8.2,9.21],[1,1.01,0.51],[2,1.01,0]],"ltp":11.0,"tv":22.68,"id":13015345},{"batb":[[1,5.9,18.18]],"batl":[[0,7.4,15.82],[1,7.4,0]],"ltp":0.0,"tv":0.0,"id":13015344}]}]}
{"op":"mcm","clk":"1006401592","pt":1580648220329,"mc":[{"id":"1.168224553","rc":[{"batb":[[0,1.72,113.06],[1,1.7,113.62],[2,1.65,26.91]],"ltp":1.78,"tv":148.01,"id":12982356},{"batb":[[0,4.7,27.83],[1,4.6,54.42],[2,1.01,0.51]],"ltp":0.0,"tv":0.0,"id":12982355},{"batb":[[0,11.5,29.38],[1,11,29.56],[2,8.2,9.21]],"ltp":11.0,"tv":22.68,"id":13015345},{"batb":[[0,6.6,28.83],[1,6.4,38.51],[2,5.9,18.18]],"ltp":0.0,"tv":0.0,"id":13015344}]}]}
{"op":"mcm","clk":"1006401982","pt":1580648222029,"mc":[{"id":"1.168224553","rc":[{"batb":[[0,1.65,26.91],[1,1.01,0.51],[2,1.65,0]],"ltp":1.78,"tv":148.01,"id":12982356},{"batb":[[0,4.6,16.13],[1,1.01,0.51],[2,1.01,0]],"ltp":0.0,"tv":0.0,"id":12982355},{"batb":[[0,8.2,9.21],[1,1.01,0.51],[2,8.2,0]],"ltp":11.0,"tv":22.68,"id":13015345},{"batb":[[0,6.4,38.51],[1,5.9,18.18],[2,1.01,0.51]],"ltp":0.0,"tv":0.0,"id":13015344}]}]}
{"op":"mcm","clk":"1006402473","pt":1580648225328,"mc":[{"id":"1.168224553","rc":[{"batb":[[1,4.5,55.34],[2,4.4,41.98]],"ltp":0.0,"tv":0.0,"id":12982355},{"batb":[[0,9.4,21.36],[1,9.2,17.98],[2,8.2,9.21]],"ltp":11.0,"tv":22.68,"id":13015345},{"batb":[[1,6.2,41.18],[2,5.9,18.18]],"ltp":0.0,"tv":0.0,"id":13015344}]}]}
{"op":"mcm","clk":"1006402965","pt":1580648228347,"mc":[{"id":"1.168224553","rc":[{"batb":[[0,1.84,18.49],[1,1.82,62.56],[2,1.8,93.55]],"batl":[[1,2.18,26.12]],"ltp":1.78,"tv":148.01,"id":12982356},{"batb":[[2,4.4,59.92]],"batl":[[0,5.3,15.42],[1,5.5,14.24],[2,5.7,13.22]],"ltp":0.0,"tv":0.0,"id":12982355},{"batl":[[0,9.8,8.81],[1,13.5,12.43],[2,17.5,7.55]],"ltp":11.0,"tv":22.68,"id":13015345},{"batl":[[0,7.2,16.76],[1,7.4,15.82]],"ltp":0.0,"tv":0.0,"id":13015344}]}]}
{"op":"mcm","clk":"1006403132","pt":1580648229346,"mc":[{"id":"1.168224553","rc":[{"batl":[[0,1.93,60.19]],"ltp":1.78,"tv":148.01,"id":12982356},{"batb":[[2,4.4,71.68]],"batl":[[0,5.2,9.24],[1,5.3,15.42],[2,5.5,14.24]],"ltp":0.0,"tv":0.0,"id":12982355},{"batb":[[0,9.4,25.56]],"batl":[[2,17.5,0]],"ltp":11.0,"tv":22.68,"id":13015345},{"batl":[[0,6.8,6.72],[1,7.2,16.76]],"ltp":0.0,"tv":0.0,"id":13015344}]}]}
{"op":"mcm","clk":"1006403336","pt":1580648230836,"mc":[{"id":"1.168224553","rc":[{"batl":[[1,12,3.36],[2,13.5,12.43]],"ltp":11.0,"tv":22.68,"id":13015345}]}]}
{"op":"mcm","clk":"1006404831","pt":1580648240949,"mc":[{"id":"1.168224553","rc":[{"batb":[[0,1.78,53.77],[1,1.73,22.58],[2,1.01,0.51]],"batl":[[0,1.93,42.01]],"ltp":1.78,"tv":148.01,"id":12982356},{"batb":[[0,4.4,29.7],[1,1.01,0.51],[2,4.4,0]],"batl":[[1,5.5,14.24],[2,5.5,0]],"ltp":0.0,"tv":0.0,"id":12982355},{"batb":[[0,9.4,4.2],[1,6,18.1],[2,1.01,0.51]],"batl":[[0,12,3.36],[1,13.5,12.43],[2,13.5,0]],"ltp":11.0,"tv":22.68,"id":13015345},{"batb":[[0,6.2,41.18],[1,5.8,19.04],[2,5.7,8.4]],"ltp":0.0,"tv":0.0,"id":13015344}]}]}
{"op":"mcm","clk":"1006404991","pt":1580648242165,"mc":[{"id":"1.168224553","rc":[{"batb":[[0,1.73,22.58],[1,1.01,0.51],[2,1.01,0]],"batl":[[0,2.18,26.12],[1,2.18,0]],"ltp":1.78,"tv":148.01,"id":12982356},{"batb":[[0,4.4,17.94]],"batl":[[0,5.5,14.24],[1,5.5,0]],"ltp":0.0,"tv":0.0,"id":12982355},{"batb":[[0,6,18.1],[1,1.01,0.51],[2,1.01,0]],"batl":[[0,13.5,12.43],[1,13.5,0]],"ltp":11.0,"tv":22.68,"id":13015345},{"batb":[[2,1.01,0.51]],"batl":[[0,7.2,16.76],[1,7.2,0]],"ltp":0.0,"tv":0.0,"id":13015344}]}]}
{"op":"mcm","clk":"1006405212","pt":1580648243551,"mc":[{"id":"1.168224553","rc":[{"batb":[[1,1.71,115.17],[2,1.69,115.99]],"ltp":1.78,"tv":148.01,"id":12982356},{"batb":[[1,4.3,47.22],[2,4.2,47.06]],"ltp":0.0,"tv":0.0,"id":12982355},{"batb":[[0,6.8,22.19],[1,6.6,36.65],[2,6,18.1]],"ltp":11.0,"tv":22.68,"id":13015345},{"batb":[[0,6.2,48.09],[1,6,44.23],[2,5.8,19.04]],"ltp":0.0,"tv":0.0,"id":13015344}]}]}
{"op":"mcm","clk":"1006405580","pt":1580648246261,"mc":[{"id":"1.168224553","rc":[{"batb":[[1,1.01,0.51],[2,4.2,0]],"ltp":0.0,"tv":0.0,"id":12982355},{"batb":[[0,6,18.1],[1,1.01,0.51],[2,6,0]],"ltp":11.0,"tv":22.68,"id":13015345},{"batb":[[0,5.8,19.04],[1,1.01,0.51],[2,5.8,0]],"ltp":0.0,"tv":0.0,"id":13015344}]}]}
{"op":"mcm","clk":"1006405988","pt":1580648249286,"mc":[{"id":"1.168224553","rc":[{"batb":[[0,4.7,31.44],[1,4.6,38.2],[2,4.4,17.94]],"ltp":0.0,"tv":0.0,"id":12982355},{"batb":[[0,12,26.81],[1,11.5,27.07],[2,6,18.1]],"ltp":11.0,"tv":22.68,"id":13015345},{"batb":[[0,6.6,26.19],[1,6.4,38.81],[2,5.8,19.04]],"ltp":0.0,"tv":0.0,"id":13015344}]}]}
{"op":"mcm","clk":"1006406113","pt":1580648250099,"mc":[{"id":"1.168224553","rc":[{"batl":[[0,1.81,22.19],[1,1.95,17.7]],"ltp":1.78,"tv":148.01,"id":12982356},{"batb":[[0,4.8,14.87],[1,4.7,31.44],[2,4.6,54.41]],"batl":[[1,5.7,13.45]],"ltp":0.0,"tv":0.0,"id":12982355},{"batb":[[2,10,13.61]],"batl":[[1,17,8.03]],"ltp":11.0,"tv":22.68,"id":13015345},{"batb":[[2,5.9,18.41]],"batl":[[0,7.2,16.13]],"ltp":0.0,"tv":0.0,"id":13015344}]}]}
{"op":"mcm","clk":"1006406273","pt":1580648251153,"mc":[{"id":"1.168224553","rc":[{"batb":[[2,1.7,59.65]],"batl":[[1,1.85,42.01],[2,1.95,17.7]],"ltp":1.78,"tv":148.01,"id":12982356},{"batb":[[2,4.6,65.33]],"batl":[[0,5.3,9.24],[1,5.5,14.24],[2,5.7,13.45]],"ltp":0.0,"tv":0.0,"id":12982355},{"batb":[[0,12,30.17]],"ltp":11.0,"tv":22.68,"id":13015345},{"batl":[[0,7,6.72],[1,7.2,16.13]],"ltp":0.0,"tv":0.0,"id":13015344}]}]}
{"op":"mcm","clk":"1006406698","pt":1580648253965,"mc":[{"id":"1.168224553","rc":[{"batb":[[1,1.66,26.12],[2,1.01,0.51]],"ltp":1.78,"tv":148.01,"id":12982356},{"batb":[[2,4.6,54.41]],"ltp":0.0,"tv":0.0,"id":12982355}]}]}
{"op":"mcm","clk":"1006406970","pt":1580648255889,"mc":[{"id":"1.168224553","rc":[{"batb":[[1,4.7,23.3]],"ltp":0.0,"tv":0.0,"id":12982355},{"batb":[[1,10,13.61],[2,8,9.76]],"ltp":11.0,"tv":22.68,"id":13015345}]}]}
{"op":"mcm","clk":"1006407142","pt":1580648256956,"mc":[{"id":"1.168224553","rc":[{"batb":[[1,1.71,58.81],[2,1.66,26.12]],"ltp":1.78,"tv":148.01,"id":12982356}]}]}
{"op":"mcm","clk":"1006407467","pt":1580648258898,"mc":[{"id":"1.168224553","rc":[{"batb":[[1,1.71,131.54],[2,1.69,115.89]],"ltp":1.78,"tv":148.01,"id":12982356},{"batb":[[0,12.5,11.02],[1,12,30.17],[2,10,13.61]],"ltp":11.0,"tv":22.68,"id":13015345},{"batb":[[0,6.6,46.62]],"ltp":0.0,"tv":0.0,"id":13015344}]}]}
{"op":"mcm","clk":"1006408390","pt":1580648265465,"mc":[{"id":"1.168224553","rc":[{"batb":[[0,1.71,58.81],[1,1.66,26.12],[2,1.01,0.51]],"batl":[[0,1.85,42.01],[1,1.95,17.7],[2,1.95,0]],"ltp":1.78,"tv":148.01,"id":12982356},{"batb":[[0,4.6,16.21],[1,4.5,11.76],[2,1.01,0.51]],"batl":[[1,5.7,13.45],[2,5.7,0]],"ltp":0.0,"tv":0.0,"id":12982355},{"batb":[[0,12,3.36],[1,8,9.76],[2,1.01,0.51]],"batl":[[0,17,8.03],[1,17,0]],"ltp":11.0,"tv":22.68,"id":13015345},{"batb":[[0,6.4,38.81],[1,5.9,18.41],[2,5.8,8.4]],"ltp":0.0,"tv":0.0,"id":13015344}]}]}
{"op":"mcm","clk":"1006408517","pt":1580648266413,"mc":[{"id":"1.168224553","rc":[{"batb":[[0,1.66,26.12],[1,1.01,0.51],[2,1.01,0]],"batl":[[0,1.95,17.7],[1,1.95,0]],"ltp":1.78,"tv":148.01,"id":12982356},{"batb":[[1,1.01,0.51],[2,1.01,0]],"batl":[[0,5.7,13.45],[1,5.7,0]],"ltp":0.0,"tv":0.0,"id":12982355},{"batb":[[0,8,9.76],[1,1.01,0.51],[2,1.01,0]],"ltp":11.0,"tv":22.68,"id":13015345},{"batb":[[2,1.01,0.51]],"batl":[[0,7.2,16.13],[1,7.2,0]],"ltp":0.0,"tv":0.0,"id":13015344}]}]}
{"op":"mcm","clk":"1006408766","pt":1580648268375,"mc":[{"id":"1.168224553","rc":[{"batb":[[0,1.65,105.22],[1,1.64,64.89],[2,1.01,0.51]],"batl":[[0,1.93,18.18]],"ltp":1.78,"tv":148.01,"id":12982356},{"batb":[[1,4.5,38.62],[2,4.4,42.11]],"batl":[[0,5.6,13.61]],"ltp":0.0,"tv":0.0,"id":12982355},{"batb":[[0,9.4,14.24],[1,9.2,18.37],[2,8.2,9.28]],"batl":[[0,17.5,7.63]],"ltp":11.0,"tv":22.68,"id":13015345},{"batb":[[0,6.4,52.91],[1,6.2,41.5],[2,6,17.47]],"batl":[[0,7.4,15.26]],"ltp":0.0,"tv":0.0,"id":13015344}]}]}
{"op":"mcm","clk":"1006408859","pt":1580648269069,"mc":[{"id":"1.168224553","rc":[{"batb":[[0,1.65,26.75],[1,1.01,0.51],[2,1.01,0]],"ltp":1.78,"tv":148.01,"id":12982356},{"batb":[[2,1.01,0.51]],"ltp":0.0,"tv":0.0,"id":12982355},{"batb":[[0,8.2,9.28],[1,1.01,0.51],[2,8.2,0]],"ltp":11.0,"tv":22.68,"id":13015345},{"batb":[[0,6.4,38.99],[1,6,17.47],[2,1.01,0.51]],"ltp":0.0,"tv":0.0,"id":13015344}]}]}
{"op":"mcm","clk":"1006409227","pt":1580648272096,"mc":[{"id":"1.168224553","rc":[{"batb":[[0,1.73,81.46],[1,1.71,111.29],[2,1.65,26.75]],"ltp":1.78,"tv":148.01,"id":12982356},{"batb":[[0,4.6,65.54]],"ltp":0.0,"tv":0.0,"id":12982355},{"batb":[[0,11.5,24.96],[1,11,30.24],[2,8.2,9.28]],"ltp":11.0,"tv":22.68,"id":13015345},{"batb":[[0,6.6,39.74],[1,6.4,38.99],[2,6,17.47]],"ltp":0.0,"tv":0.0,"id":13015344}]}]}
{"op":"mcm","clk":"1006409402","pt":1580648273483,"mc":[{"id":"1.168224553","rc":[{"batb":[[0,1.65,26.75],[1,1.01,0.51],[2,1.65,0]],"ltp":1.78,"tv":148.01,"id":12982356},{"batb":[[0,4.6,16.21]],"ltp":0.0,"tv":0.0,"id":12982355},{"batb":[[0,8.2,9.28],[1,1.01,0.51],[2,8.2,0]],"ltp":11.0,"tv":22.68,"id":13015345},{"batb":[[0,6.4,38.99],[1,6,17.47],[2,1.01,0.51]],"ltp":0.0,"tv":0.0,"id":13015344}]}]}
{"op":"mcm","clk":"1006409778","pt":1580648276381,"mc":[{"id":"1.168224553","rc":[{"batb":[[0,1.65,104.87],[1,1.64,64.89],[2,1.01,0.51]],"ltp":1.78,"tv":148.01,"id":12982356},{"batb":[[2,4.4,42.11]],"ltp":0.0,"tv":0.0,"id":12982355},{"batb":[[0,9.4,14.41],[1,9.2,18.37],[2,8.2,9.28]],"ltp":11.0,"tv":22.68,"id":13015345},{"batb":[[0,6.4,52.94],[1,6.2,41.5],[2,6,17.47]],"ltp":0.0,"tv":0.0,"id":13015344}]}]}
{"op":"mcm","clk":"1006409885","pt":1580648277290,"mc":[{"id":"1.168224553","rc":[{"batb":[[0,1.65,26.75],[1,1.01,0.51],[2,1.01,0]],"ltp":1.78,"tv":148.01,"id":12982356}]}]}
{"op":"mcm","clk":"1006410123","pt":1580648279303,"mc":[{"id":"1.168224553","rc":[{"batb":[[0,1.81,51.25],[1,1.65,26.75],[2,1.01,0.51]],"batl":[[1,1.96,42.01]],"ltp":1.78,"tv":148.01,"id":12982356},{"batb":[[2,4.4,53.87]],"batl":[[0,5.2,9.24],[1,5.6,13.61]],"ltp":0.0,"tv":0.0,"id":12982355},{"batb":[[0,9.2,23.41],[1,8.2,9.28],[2,1.01,0.51]],"batl":[[0,12,3.36],[1,17.5,7.63]],"ltp":11.0,"tv":22.68,"id":13015345},{"batb":[[0,6.4,44.71]],"batl":[[0,6.8,6.72],[1,7.4,15.26]],"ltp":0.0,"tv":0.0,"id":13015344}]}]}
{"op":"mcm","clk":"1006410231","pt":1580648280106,"mc":[{"id":"1.168224553","rc":[{"batb":[[0,1.84,18.49],[1,1.81,51.25],[2,1.73,22.74]],"batl":[[2,2.18,25.89]],"ltp":1.78,"tv":148.01,"id":12982356},{"batl":[[1,5.3,15.82],[2,5.5,14.48]],"ltp":0.0,"tv":0.0,"id":12982355},{"batb":[[2,6,18.18]],"batl":[[0,9.8,8.89],[1,12,3.36],[2,13,12.75]],"ltp":11.0,"tv":22.68,"id":13015345},{"batb":[[2,5.9,18.18]],"ltp":0.0,"tv":0.0,"id":13015344}]}]}
{"op":"mcm","clk":"1006410676","pt":1580648283410,"mc":[{"id":"1.168224553","rc":[{"batb":[[1,1.83,61.29],[2,1.81,143.17]],"ltp":1.78,"tv":148.01,"id":12982356},{"batb":[[0,9.2,32.84],[1,9,18.89],[2,8.2,9.28]],"ltp":11.0,"tv":22.68,"id":13015345}]}]}
{"op":"mcm","clk":"1006411850","pt":1580648292318,"mc":[{"id":"1.168224553","rc":[{"batb":[[0,1.81,51.25],[1,1.73,22.74],[2,1.01,0.51]],"batl":[[0,1.96,42.01],[1,2.18,25.89],[2,2.18,0]],"ltp":1.78,"tv":148.01,"id":12982356},{"batb":[[0,4.4,11.76],[1,4.3,18.88],[2,1.01,0.51]],"batl":[[1,5.5,14.48],[2,5.5,0]],"ltp":0.0,"tv":0.0,"id":12982355},{"batb":[[0,9.2,5.04],[1,6,18.18],[2,1.01,0.51]],"batl":[[0,12,3.36],[1,13,12.75],[2,13,0]],"ltp":11.0,"tv":22.68,"id":13015345},{"batb":[[0,6.2,41.5],[1,5.9,18.18],[2,5.6,8.4]],"ltp":0.0,"tv":0.0,"id":13015344}]}]}
{"op":"mcm","clk":"1006412110","pt":1580648294228,"mc":[{"id":"1.168224553","rc":[{"batb":[[0,1.73,22.74],[1,1.01,0.51],[2,1.01,0]],"batl":[[0,2.18,25.89],[1,2.18,0]],"ltp":1.78,"tv":148.01,"id":12982356},{"batb":[[0,4.3,18.88],[1,1.01,0.51],[2,1.01,0]],"batl":[[0,5.5,14.48],[1,5.5,0]],"ltp":0.0,"tv":0.0,"id":12982355},{"batb":[[0,6,18.18],[1,1.01,0.51],[2,1.01,0]],"batl":[[0,13,12.75],[1,13,0]],"ltp":11.0,"tv":22.68,"id":13015345},{"batb":[[2,1.01,0.51]],"batl":[[0,7.4,15.26],[1,7.4,0]],"ltp":0.0,"tv":0.0,"id":13015344}]}]}
{"op":"mcm","clk":"1006412245","pt":1580648295119,"mc":[{"id":"1.168224553","rc":[{"batb":[[1,1.72,101.65],[2,1.7,113.66]],"ltp":1.78,"tv":148.01,"id":12982356},{"batb":[[0,4.3,54.02],[1,4.2,47.2],[2,1.01,0.51]],"ltp":0.0,"tv":0.0,"id":12982355},{"batb":[[0,6.6,45.85],[1,6.4,38.91],[2,6,18.18]],"ltp":11.0,"tv":22.68,"id":13015345},{"batb":[[0,6.2,50.43],[1,6,44.55],[2,5.9,18.18]],"ltp":0.0,"tv":0.0,"id":13015344}]}]}
{"op":"mcm","clk":"1006412839","pt":1580648299316,"mc":[{"id":"1.168224553","rc":[{"batb":[[0,4.3,18.88],[1,1.01,0.51],[2,1.01,0]],"ltp":0.0,"tv":0.0,"id":12982355},{"batb":[[0,6,18.18],[1,1.01,0.51],[2,6,0]],"ltp":11.0,"tv":22.68,"id":13015345},{"batb":[[0,5.9,18.18],[1,1.01,0.51],[2,5.9,0]],"ltp":0.0,"tv":0.0,"id":13015344}]}]}
{"op":"mcm","clk":"1006413235","pt":1580648302330,"mc":[{"id":"1.168224553","rc":[{"batl":[[0,1.81,22.35],[1,1.95,17.55]],"ltp":1.78,"tv":148.01,"id":12982356},{"batb":[[0,4.8,15.11],[1,4.6,74.52],[2,4.5,39.67]],"batl":[[1,5.6,13.77]],"ltp":0.0,"tv":0.0,"id":12982355},{"batb":[[0,12,17.79],[1,11.5,27.68],[2,10,14.01]],"batl":[[1,16.5,8.1]],"ltp":11.0,"tv":22.68,"id":13015345},{"batb":[[0,6.6,26.62],[1,6.4,39.13],[2,6,18.1]],"ltp":0.0,"tv":0.0,"id":13015344}]}]}
{"op":"mcm","clk":"1006413324","pt":1580648303132,"mc":[{"id":"1.168224553","rc":[{"batb":[[1,1.72,159.62]],"batl":[[1,1.87,42.01],[2,1.95,17.55]],"ltp":1.78,"tv":148.01,"id":12982356},{"batb":[[2,4.5,51.43]],"batl":[[0,5.3,9.24],[1,5.5,14.48],[2,5.6,13.77]],"ltp":0.0,"tv":0.0,"id":12982355},{"batb":[[1,11.5,31.04]],"ltp":11.0,"tv":22.68,"id":13015345},{"batl":[[0,6.8,6.72],[1,7.4,15.26]],"ltp":0.0,"tv":0.0,"id":13015344}]}]}
{"op":"mcm","clk":"1006415016","pt":1580648316471,"mc":[{"id":"1.168224553","rc":[{"batb":[[0,1.66,26.12],[1,1.01,0.51],[2,1.7,0]],"batl":[[0,1.95,17.55],[1,1.87,0],[2,1.95,0]],"ltp":1.78,"tv":148.01,"id":12982356},{"batb":[[0,4.6,16.68],[1,4.5,39.67],[2,1.01,0.51]],"batl":[[0,5.6,13.77],[1,5.5,0],[2,5.6,0]],"ltp":0.0,"tv":0.0,"id":12982355},{"batb":[[0,8,9.91],[1,1.01,0.51],[2,10,0]],"batl":[[0,16.5,8.1],[1,16.5,0]],"ltp":11.0,"tv":22.68,"id":13015345},{"batb":[[0,6.4,39.13],[1,6,18.1],[2,1.01,0.51]],"batl":[[0,7.4,15.26],[1,7.4,0]],"ltp":0.0,"tv":0.0,"id":13015344}]}]}
{"op":"mcm","clk":"1006415301","pt":1580648318678,"mc":[{"id":"1.168224553","rc":[{"batb":[[0,1.66,122.9],[1,1.65,63.54],[2,1.01,0.51]],"ltp":1.78,"tv":148.01,"id":12982356},{"batb":[[2,4.4,42.25]],"ltp":0.0,"tv":0.0,"id":12982355},{"batb":[[0,9,27.57],[1,8.8,19.82],[2,8,9.91]],"ltp":11.0,"tv":22.68,"id":13015345},{"batb":[[1,6.2,41.78],[2,6,18.1]],"ltp":0.0,"tv":0.0,"id":13015344}]}]}
{"op":"mcm","clk":"1006417663","pt":1580648337864,"mc":[{"id":"1.168224553","rc":[{"batb":[[0,1.66,26.12],[1,1.01,0.51],[2,1.01,0]],"ltp":1.78,"tv":148.01,"id":12982356}]}]}
{"op":"mcm","clk":"1006418083","pt":1580648341417,"mc":[{"id":"1.168224553","rc":[{"batb":[[0,1.84,82.57],[1,1.82,90.3],[2,1.66,26.12]],"ltp":1.78,"tv":148.01,"id":12982356},{"batb":[[2,4.4,54.01]],"batl":[[0,5.1,10.08],[1,5.6,13.77]],"ltp":0.0,"tv":0.0,"id":12982355},{"batb":[[0,9.2,5.04],[1,9,27.57],[2,8.8,19.82]],"batl":[[0,11.5,3.36],[1,16.5,8.1]],"ltp":11.0,"tv":22.68,"id":13015345}]}]}
{"op":"mcm","clk":"1006418230","pt":1580648342290,"mc":[{"id":"1.168224553","rc":[{"batb":[[0,1.86,17.78],[1,1.84,82.57],[2,1.82,140.71]],"batl":[[1,1.98,42.01],[2,2.2,25.18]],"ltp":1.78,"tv":148.01,"id":12982356},{"batl":[[1,5.2,15.89],[2,5.4,14.95]],"ltp":0.0,"tv":0.0,"id":12982355},{"batl":[[0,9.6,9.36],[1,11.5,3.36],[2,13,13.22]],"ltp":11.0,"tv":22.68,"id":13015345},{"batb":[[2,5.9,18.57]],"batl":[[0,6.6,6.72],[1,7.2,16.29]],"ltp":0.0,"tv":0.0,"id":13015344}]}]}
{"op":"mcm","clk":"1006418953","pt":1580648348227,"mc":[{"id":"1.168224553","rc":[{"batb":[[1,1.82,50.41],[2,1.75,21.95]],"ltp":1.78,"tv":148.01,"id":12982356},{"batb":[[1,9,21.6]],"ltp":11.0,"tv":22.68,"id":13015345},{"batb":[[0,6.4,25.36]],"ltp":0.0,"tv":0.0,"id":13015344}]}]}
{"op":"mcm","clk":"1006419320","pt":1580648351389,"mc":[{"id":"1.168224553","rc":[{"batb":[[1,1.85,56.49],[2,1.83,88.7]],"ltp":1.78,"tv":148.01,"id":12982356}]}]}
{"op":"mcm","clk":"1006419943","pt":1580648356428,"mc":[{"id":"1.168224553","rc":[{"batb":[[0,1.82,50.41],[1,1.75,21.95],[2,1.01,0.51]],"batl":[[0,1.98,42.01],[1,2.2,25.18],[2,2.2,0]],"ltp":1.78,"tv":148.01,"id":12982356},{"batb":[[0,4.4,11.76],[1,4.3,18.65],[2,1.01,0.51]],"batl":[[1,5.4,14.95],[2,5.4,0]],"ltp":0.0,"tv":0.0,"id":12982355},{"batb":[[1,5.9,19.28],[2,1.01,0.51]],"batl":[[0,11.5,3.36],[1,13,13.22],[2,13,0]],"ltp":11.0,"tv":22.68,"id":13015345},{"batb":[[0,6.2,31.92],[1,5.9,18.57],[2,5.6,8.4]],"ltp":0.0,"tv":0.0,"id":13015344}]}]}
{"op":"mcm","clk":"1006420188","pt":1580648358145,"mc":[{"id":"1.168224553","rc":[{"batb":[[0,1.75,21.95],[1,1.01,0.51],[2,1.01,0]],"batl":[[0,2.2,25.18],[1,2.2,0]],"ltp":1.78,"tv":148.01,"id":12982356},{"batb":[[0,4.3,18.65],[1,1.01,0.51],[2,1.01,0]],"batl":[[0,5.4,14.95],[1,5.4,0]],"ltp":0.0,"tv":0.0,"id":12982355},{"batb":[[0,5.9,19.28],[1,1.01,0.51],[2,1.01,0]],"batl":[[0,13,13.22],[1,13,0]],"ltp":11.0,"tv":22.68,"id":13015345},{"batb":[[2,1.01,0.51]],"batl":[[0,7.2,16.29],[1,7.2,0]],"ltp":0.0,"tv":0.0,"id":13015344}]}]}
{"op":"mcm","clk":"1006420348","pt":1580648359429,"mc":[{"id":"1.168224553","rc":[{"batb":[[1,1.74,100.15],[2,1.72,109.09]],"ltp":1.78,"tv":148.01,"id":12982356},{"batb":[[0,4.3,54.83],[1,4.2,47.29],[2,1.01,0.51]],"ltp":0.0,"tv":0.0,"id":12982355},{"batb":[[0,6.4,52.69],[1,6.2,41.29],[2,5.9,19.28]],"ltp":11.0,"tv":22.68,"id":13015345},{"batb":[[1,6,44.78],[2,5.9,18.57]],"ltp":0.0,"tv":0.0,"id":13015344}]}]}
{"op":"mcm","clk":"1006420437","pt":1580648360325,"mc":[{"id":"1.168224553","rc":[{"batb":[[0,1.74,22.03],[1,1.01,0.51],[2,1.72,0]],"ltp":1.78,"tv":148.01,"id":12982356},{"batb":[[1,1.01,0.51],[2,1.01,0]],"ltp":0.0,"tv":0.0,"id":12982355},{"batb":[[0,5.9,19.12],[1,1.01,0.51],[2,5.9,0]],"batl":[[0,13,13.06]],"ltp":11.0,"tv":22.68,"id":13015345},{"batb":[[1,5.9,18.41],[2,1.01,0.51]],"batl":[[0,7.2,16.13]],"ltp":0.0,"tv":0.0,"id":13015344}]}]}
{"op":"mcm","clk":"1006420691","pt":1580648362406,"mc":[{"id":"1.168224553","rc":[{"batb":[[0,1.88,92.64],[1,1.86,84.19],[2,1.74,22.03]],"ltp":1.78,"tv":148.01,"id":12982356},{"batb":[[0,4.4,65.3],[1,4.3,54.83],[2,1.01,0.51]],"ltp":0.0,"tv":0.0,"id":12982355},{"batb":[[0,8.4,18.52],[1,8.2,23.1],[2,5.9,19.12]],"ltp":11.0,"tv":22.68,"id":13015345},{"batb":[[0,6.4,17.56],[1,6.2,41.99],[2,5.9,18.41]],"ltp":0.0,"tv":0.0,"id":13015344}]}]}
{"op":"mcm","clk":"1006420772","pt":1580648363112,"mc":[{"id":"1.168224553","rc":[{"batb":[[0,1.74,22.03],[1,1.01,0.51],[2,1.74,0]],"ltp":1.78,"tv":148.01,"id":12982356},{"batb":[[0,4.3,54.83],[1,1.01,0.51],[2,1.01,0]],"ltp":0.0,"tv":0.0,"id":12982355},{"batb":[[0,5.9,19.12],[1,1.01,0.51],[2,5.9,0]],"ltp":11.0,"tv":22.68,"id":13015345},{"batb":[[0,6.2,31.92],[1,5.9,18.41],[2,1.01,0.51]],"ltp":0.0,"tv":0.0,"id":13015344}]}]}
{"op":"mcm","clk":"1006421250","pt":1580648366089,"mc":[{"id":"1.168224553","rc":[{"batb":[[0,1.74,100.15],[1,1.72,109.09],[2,1.01,0.51]],"ltp":1.78,"tv":148.01,"id":12982356},{"batb":[[1,4.2,47.29],[2,1.01,0.51]],"ltp":0.0,"tv":0.0,"id":12982355},{"batb":[[0,6.4,52.69],[1,6.2,41.29],[2,5.9,19.12]],"ltp":11.0,"tv":22.68,"id":13015345},{"batb":[[1,6,44.78],[2,5.9,18.41]],"ltp":0.0,"tv":0.0,"id":13015344}]}]}
{"op":"mcm","clk":"1006421570","pt":1580648369106,"mc":[{"id":"1.168224553","rc":[{"batb":[[0,1.74,22.03],[1,1.01,0.51],[2,1.01,0]],"ltp":1.78,"tv":148.01,"id":12982356}]}]}
{"op":"mcm","clk":"1006421961","pt":1580648372135,"mc":[{"id":"1.168224553","rc":[{"batb":[[0,2.06,59.14],[1,2.04,63.21],[2,1.74,22.03]],"ltp":1.78,"tv":148.01,"id":12982356}]}]}
{"op":"mcm","clk":"1006422108","pt":1580648373433,"mc":[{"id":"1.168224553","rc":[{"batb":[[0,2.06,85.11],[2,2.02,41.17]],"batl":[[0,2.2,59.63],[1,2.64,15.19]],"ltp":1.78,"tv":148.01,"id":12982356},{"batb":[[1,4.2,59.89],[2,4,22.42]],"batl":[[0,4.9,10.08],[1,5,17.86],[2,5.2,16.13]],"ltp":0.0,"tv":0.0,"id":12982355},{"batb":[[0,6.6,6.72],[1,6.4,52.69],[2,6.2,41.29]],"batl":[[0,7,17.78],[1,8.2,5.04],[2,9.4,9.68]],"ltp":11.0,"tv":22.68,"id":13015345},{"batl":[[0,6.4,7.56],[1,7.2,16.13]],"ltp":0.0,"tv":0.0,"id":13015344}]}]}
{"op":"mcm","clk":"1006423609","pt":1580648384333,"mc":[{"id":"1.168224553","rc":[{"batb":[[0,2.02,41.17],[1,1.87,17.62],[2,1.01,0.51]],"batl":[[0,2.2,34.45]],"ltp":1.78,"tv":148.01,"id":12982356},{"batb":[[0,4.2,12.6],[1,4,22.42],[2,1.01,0.51]],"batl":[[1,5.2,16.13],[2,5.2,0]],"ltp":0.0,"tv":0.0,"id":12982355},{"batb":[[1,4.3,19.43],[2,1.01,0.51]],"batl":[[0,8.2,5.04],[1,9.4,9.68],[2,9.4,0]],"ltp":11.0,"tv":22.68,"id":13015345},{"batb":[[0,6,35.13],[1,5.8,19.12],[2,5.5,9.24]],"ltp":0.0,"tv":0.0,"id":13015344}]}]}
{"op":"mcm","clk":"1006423837","pt":1580648386253,"mc":[{"id":"1.168224553","rc":[{"batb":[[0,1.87,17.62],[1,1.01,0.51],[2,1.01,0]],"batl":[[0,2.64,15.19],[1,2.64,0]],"ltp":1.78,"tv":148.01,"id":12982356},{"batb":[[0,4,22.42],[1,1.01,0.51],[2,1.01,0]],"batl":[[0,5.2,16.13],[1,5.2,0]],"ltp":0.0,"tv":0.0,"id":12982355},{"batb":[[0,4.3,19.43],[1,1.01,0.51],[2,1.01,0]],"batl":[[0,9.4,9.68],[1,9.4,0]],"ltp":11.0,"tv":22.68,"id":13015345},{"batb":[[2,1.01,0.51]],"batl":[[0,7.2,16.13],[1,7.2,0]],"ltp":0.0,"tv":0.0,"id":13015344}]}]}
{"op":"mcm","clk":"1006423992","pt":1580648387457,"mc":[{"id":"1.168224553","rc":[{"batb":[[1,1.86,73.79],[2,1.84,87.16]],"ltp":1.78,"tv":148.01,"id":12982356},{"batb":[[0,4,66.34],[1,3.95,27.65],[2,1.01,0.51]],"ltp":0.0,"tv":0.0,"id":12982355},{"batb":[[0,4.6,29.38],[1,4.5,43.5],[2,4.4,19.28]],"ltp":11.0,"tv":22.68,"id":13015345},{"batb":[[1,5.9,23.6],[2,5.8,19.12]],"ltp":0.0,"tv":0.0,"id":13015344}]}]}
{"op":"mcm","clk":"1006424429","pt":1580648390533,"mc":[{"id":"1.168224553","rc":[{"batb":[[1,1.01,0.51],[2,1.84,0]],"ltp":1.78,"tv":148.01,"id":12982356},{"batb":[[0,4,22.42],[1,1.01,0.51],[2,1.01,0]],"ltp":0.0,"tv":0.0,"id":12982355},{"batb":[[0,4.4,19.28],[1,1.01,0.51],[2,4.4,0]],"ltp":11.0,"tv":22.68,"id":13015345},{"batb":[[0,5.8,19.12],[1,1.01,0.51],[2,5.8,0]],"ltp":0.0,"tv":0.0,"id":13015344}]}]}
{"op":"mcm","clk":"1006424941","pt":1580648394433,"mc":[{"id":"1.168224553","rc":[{"batb":[[1,1.86,73.79],[2,1.84,87.16]],"batl":[[0,1.96,17.39],[1,2.2,24.78]],"ltp":1.78,"tv":148.01,"id":12982356},{"batb":[[0,4.5,51.61],[1,4.4,42.37],[2,4.3,18.96]],"batl":[[1,5.4,14.87]],"ltp":0.0,"tv":0.0,"id":12982355},{"batb":[[0,8.8,23.39],[1,8.6,20.77],[2,7.8,10.15]],"batl":[[1,12.5,13.61]],"ltp":11.0,"tv":22.68,"id":13015345},{"batb":[[0,6.2,57.57],[1,6,44.01],[2,5.9,18.41]],"ltp":0.0,"tv":0.0,"id":13015344}]}]}
{"op":"mcm","clk":"1006425060","pt":1580648395423,"mc":[{"id":"1.168224553","rc":[{"batb":[[1,4.4,54.13]],"ltp":0.0,"tv":0.0,"id":12982355},{"batb":[[0,8.8,28.43]],"ltp":11.0,"tv":22.68,"id":13015345}]}]}
{"op":"mcm","clk":"1006425184","pt":1580648396440,"mc":[{"id":"1.168224553","rc":[{"batb":[[1,1.75,21.79],[2,1.01,0.51]],"ltp":1.78,"tv":148.01,"id":12982356},{"batb":[[0,8.8,5.04]],"ltp":11.0,"tv":22.68,"id":13015345},{"batb":[[0,6.2,39.73]],"ltp":0.0,"tv":0.0,"id":13015344}]}]}
{"op":"mcm","clk":"1006425265","pt":1580648397032,"mc":[{"id":"1.168224553","rc":[{"batb":[[1,1.85,48.73],[2,1.75,21.79]],"batl":[[1,2,42.01],[2,2.2,24.78]],"ltp":1.78,"tv":148.01,"id":12982356},{"batl":[[0,5.1,10.08],[1,5.2,16.13],[2,5.4,14.87]],"ltp":0.0,"tv":0.0,"id":12982355},{"batl":[[1,11.5,3.36],[2,12.5,13.61]],"ltp":11.0,"tv":22.68,"id":13015345},{"batl":[[0,6.6,6.72],[1,7.2,16.13]],"ltp":0.0,"tv":0.0,"id":13015344}]}]}
{"op":"mcm","clk":"1006425516","pt":1580648399421,"mc":[{"id":"1.168224553","rc":[{"batb":[[0,1.87,84.68],[1,1.85,134.41]],"ltp":1.78,"tv":148.01,"id":12982356},{"batb":[[0,4.5,60.4]],"ltp":0.0,"tv":0.0,"id":12982355},{"batb":[[1,8.6,32.44],[2,8.4,21.41]],"ltp":11.0,"tv":22.68,"id":13015345}]}]}
{"op":"mcm","clk":"1006430002","pt":1580648431091,"mc":[{"id":"1.168224553","rc":[{"batb":[[0,1.87,17.62],[1,1.85,48.73]],"ltp":1.78,"tv":148.01,"id":12982356},{"batb":[[0,4.5,16.92],[1,4.4,11.76]],"ltp":0.0,"tv":0.0,"id":12982355},{"batb":[[1,7.8,10.15],[2,5.9,19.59]],"ltp":11.0,"tv":22.68,"id":13015345},{"batb":[[0,6,44.01],[1,5.9,18.41],[2,5.5,9.24]],"ltp":0.0,"tv":0.0,"id":13015344}]}]}
{"op":"mcm","clk":"1006430329","pt":1580648433806,"mc":[{"id":"1.168224553","rc":[{"batb":[[2,1.76,77.84]],"ltp":1.78,"tv":148.01,"id":12982356},{"batb":[[2,4.3,64.73]],"ltp":0.0,"tv":0.0,"id":12982355},{"batb":[[2,6.2,52.4]],"ltp":11.0,"tv":22.68,"id":13015345},{"batb":[[1,5.9,41.51]],"ltp":0.0,"tv":0.0,"id":13015344}]}]}
{"op":"mcm","clk":"1006430790","pt":1580648437386,"mc":[{"id":"1.168224553","rc":[{"batb":[[0,1.85,48.73],[1,1.76,77.84],[2,1.75,21.79]],"batl":[[0,2,42.01],[1,2.2,24.78],[2,2.2,0]],"ltp":1.78,"tv":148.01,"id":12982356},{"batb":[[0,4.4,11.76],[1,4.3,64.73],[2,4.2,47.36]],"batl":[[1,5.4,14.87],[2,5.4,0]],"ltp":0.0,"tv":0.0,"id":12982355},{"batb":[[1,6.2,52.4],[2,6,43.8]],"batl":[[0,11.5,3.36],[1,12.5,13.61],[2,12.5,0]],"ltp":11.0,"tv":22.68,"id":13015345}]}]}
{"op":"mcm","clk":"1006430886","pt":1580648438238,"mc":[{"id":"1.168224553","rc":[{"batb":[[0,1.76,77.84],[1,1.75,21.79],[2,1.74,104.91]],"batl":[[0,2.2,24.78],[1,2.2,0]],"ltp":1.78,"tv":148.01,"id":12982356},{"batb":[[0,4.3,64.73],[1,4.2,47.36],[2,1.01,0.51]],"batl":[[0,5.4,14.87],[1,5.4,0]],"ltp":0.0,"tv":0.0,"id":12982355},{"batb":[[0,6.2,52.4],[1,6,43.8],[2,5.9,19.59]],"batl":[[0,12.5,13.61],[1,12.5,0]],"ltp":11.0,"tv":22.68,"id":13015345},{"batb":[[2,1.01,0.51]],"batl":[[0,7.2,16.13],[1,7.2,0]],"ltp":0.0,"tv":0.0,"id":13015344}]}]}
{"op":"mcm","clk":"1006431105","pt":1580648439911,"mc":[{"id":"1.168224553","rc":[{"batb":[[0,1.76,99.32],[1,1.74,104.91],[2,1.01,0.51]],"batl":[[0,2.22,24.39]],"ltp":1.78,"tv":148.01,"id":12982356},{"batb":[[0,4.3,64.5]],"batl":[[0,5.4,14.71]],"ltp":0.0,"tv":0.0,"id":12982355},{"batb":[[2,5.8,20.14]],"ltp":11.0,"tv":22.68,"id":13015345},{"batb":[[1,5.9,23.1],[2,5.8,18.96]],"ltp":0.0,"tv":0.0,"id":13015344}]}]}
{"op":"mcm","clk":"1006431883","pt":1580648446545,"mc":[{"id":"1.168224553","rc":[{"batb":[[0,1.76,21.48],[1,1.01,0.51],[2,1.01,0]],"ltp":1.78,"tv":148.01,"id":12982356},{"batb":[[0,4.3,18.73],[1,1.01,0.51],[2,1.01,0]],"ltp":0.0,"tv":0.0,"id":12982355},{"batb":[[0,5.8,20.14],[1,1.01,0.51],[2,5.8,0]],"ltp":11.0,"tv":22.68,"id":13015345},{"batb":[[1,5.8,18.96],[2,1.01,0.51]],"ltp":0.0,"tv":0.0,"id":13015344}]}]}
{"op":"mcm","clk":"1006432352","pt":1580648450458,"mc":[{"id":"1.168224553","rc":[{"batb":[[0,1.76,99.39],[1,1.74,104.91],[2,1.69,24.71]],"batl":[[0,1.84,21.09],[1,1.98,16.68]],"ltp":1.78,"tv":148.01,"id":12982356},{"batb":[[0,4.7,15.34],[1,4.6,57.89],[2,4.5,56.91]],"batl":[[1,5.6,13.93]],"ltp":0.0,"tv":0.0,"id":12982355},{"batb":[[0,11,31.07],[1,10.5,31.83],[2,9.6,15.42]],"batl":[[1,16,8.97]],"ltp":11.0,"tv":22.68,"id":13015345},{"batb":[[0,6.2,54.84],[1,6,44.01],[2,5.9,18.41]],"ltp":0.0,"tv":0.0,"id":13015344}]}]}
{"op":"mcm","clk":"1006432486","pt":1580648451434,"mc":[{"id":"1.168224553","rc":[{"batb":[[1,1.75,55.45],[2,1.74,104.91]],"batl":[[1,1.91,42.01],[2,1.98,16.68]],"ltp":1.78,"tv":148.01,"id":12982356},{"batb":[[2,4.5,68.67]],"batl":[[0,5.3,9.24],[1,5.4,14.71],[2,5.6,13.93]],"ltp":0.0,"tv":0.0,"id":12982355},{"batb":[[0,11,35.27]],"ltp":11.0,"tv":22.68,"id":13015345},{"batl":[[0,6.6,6.72],[1,7.2,16.13]],"ltp":0.0,"tv":0.0,"id":13015344}]}]}
{"op":"mcm","clk":"1006433514","pt":1580648458370,"mc":[{"id":"1.168224553","rc":[{"batb":[[0,1.76,21.48],[2,1.69,24.71]],"ltp":1.78,"tv":148.01,"id":12982356},{"batb":[[1,4.5,28.68],[2,1.01,0.51]],"ltp":0.0,"tv":0.0,"id":12982355},{"batb":[[0,11,4.2],[1,9.6,15.42],[2,7.6,10.86]],"ltp":11.0,"tv":22.68,"id":13015345},{"batb":[[0,5.9,18.41],[1,5.5,9.24],[2,1.01,0.51]],"ltp":0.0,"tv":0.0,"id":13015344}]}]}
{"op":"mcm","clk":"1006433580","pt":1580648458984,"mc":[{"id":"1.168224553","rc":[{"batb":[[0,1.75,55.45],[1,1.69,24.71],[2,1.01,0.51]],"batl":[[0,1.91,42.01],[1,1.98,16.68],[2,1.98,0]],"ltp":1.78,"tv":148.01,"id":12982356},{"batb":[[0,4.5,28.68],[1,1.01,0.51],[2,1.01,0]],"batl":[[1,5.6,13.93],[2,5.6,0]],"ltp":0.0,"tv":0.0,"id":12982355},{"batb":[[1,7.6,10.86],[2,1.01,0.51]],"batl":[[0,16,8.97],[1,16,0]],"ltp":11.0,"tv":22.68,"id":13015345}]}]}
{"op":"mcm","clk":"1006433762","pt":1580648460462,"mc":[{"id":"1.168224553","rc":[{"batb":[[0,1.69,24.71],[1,1.01,0.51],[2,1.01,0]],"batl":[[0,1.98,16.68],[1,1.98,0]],"ltp":1.78,"tv":148.01,"id":12982356},{"batb":[[0,4.5,16.92]],"batl":[[0,5.6,13.93],[1,5.6,0]],"ltp":0.0,"tv":0.0,"id":12982355},{"batb":[[0,7.6,10.86],[1,1.01,0.51],[2,1.01,0]],"ltp":11.0,"tv":22.68,"id":13015345},{"batb":[[1,1.01,0.51],[2,1.01,0]],"batl":[[0,7.2,16.13],[1,7.2,0]],"ltp":0.0,"tv":0.0,"id":13015344}]}]}
{"op":"mcm","clk":"1006434028","pt":1580648462458,"mc":[{"id":"1.168224553","rc":[{"batb":[[0,1.69,124.7],[1,1.67,121.06],[2,1.01,0.51]],"ltp":1.78,"tv":148.01,"id":12982356},{"batb":[[0,4.5,56.83],[1,4.4,42.5],[2,1.01,0.51]],"ltp":0.0,"tv":0.0,"id":12982355},{"batb":[[0,8.4,32.3],[1,8.2,22.49],[2,7.6,10.86]],"ltp":11.0,"tv":22.68,"id":13015345},{"batb":[[0,6.2,25.44],[1,6,44.29],[2,5.9,18.41]],"ltp":0.0,"tv":0.0,"id":13015344}]}]}
{"op":"mcm","clk":"1006434484","pt":1580648465273,"mc":[{"id":"1.168224553","rc":[{"batb":[[0,4.5,16.92],[1,1.01,0.51],[2,1.01,0]],"ltp":0.0,"tv":0.0,"id":12982355},{"batb":[[0,7.6,10.86],[1,1.01,0.51],[2,7.6,0]],"ltp":11.0,"tv":22.68,"id":13015345},{"batb":[[1,5.9,18.41],[2,1.01,0.51]],"ltp":0.0,"tv":0.0,"id":13015344}]}]}
{"op":"mcm","clk":"1006434899","pt":1580648468445,"mc":[{"id":"1.168224553","rc":[{"batb":[[0,4.7,53.7],[1,4.6,38.04],[2,4.5,16.92]],"ltp":0.0,"tv":0.0,"id":12982355},{"batb":[[0,14,9.61],[1,13.5,19.68],[2,7.6,10.86]],"ltp":11.0,"tv":22.68,"id":13015345},{"batb":[[0,6.4,30.23],[1,6.2,41.02],[2,5.9,18.41]],"ltp":0.0,"tv":0.0,"id":13015344}]}]}
{"op":"mcm","clk":"1006435025","pt":1580648469457,"mc":[{"id":"1.168224553","rc":[{"batb":[[0,1.69,185.19],[2,1.62,28.48]],"batl":[[0,1.77,24.23],[1,1.82,21.87],[2,1.83,42.01]],"ltp":1.78,"tv":148.01,"id":12982356},{"batb":[[0,4.8,14.56],[1,4.7,68.96],[2,4.6,48.96]],"batl":[[0,5.4,9.24],[1,5.6,13.93],[2,5.7,13.14]],"ltp":0.0,"tv":0.0,"id":12982355},{"batb":[[2,13,3.36]],"batl":[[1,20,5.67]],"ltp":11.0,"tv":22.68,"id":13015345},{"batb":[[2,6,17.7]],"batl":[[0,6.8,6.72],[1,7.2,16.13],[2,7.4,15.58]],"ltp":0.0,"tv":0.0,"id":13015344}]}]}
{"op":"mcm","clk":"1006438068","pt":1580648492988,"mc":[{"id":"1.168224553","rc":[{"batb":[[0,1.69,60.49],[1,1.62,28.48],[2,1.01,0.51]],"batl":[[0,1.82,21.87],[1,1.83,42.01],[2,1.83,0]],"ltp":1.78,"tv":148.01,"id":12982356},{"batb":[[0,4.7,40.31],[1,4.6,48.96],[2,1.01,0.51]],"batl":[[1,5.7,13.14],[2,5.7,0]],"ltp":0.0,"tv":0.0,"id":12982355},{"batb":[[0,13,3.36],[1,10.5,13.14],[2,1.01,0.51]],"batl":[[0,20,5.67],[1,20,0]],"ltp":11.0,"tv":22.68,"id":13015345},{"batb":[[0,6.2,41.02],[1,5.9,18.41],[2,5.7,8.4]],"batl":[[1,7.4,15.58],[2,7.4,0]],"ltp":0.0,"tv":0.0,"id":13015344}]}]}
{"op":"mcm","clk":"1006438209","pt":1580648494267,"mc":[{"id":"1.168224553","rc":[{"batb":[[0,1.62,28.48],[1,1.01,0.51],[2,1.01,0]],"batl":[[1,1.83,0]],"ltp":1.78,"tv":148.01,"id":12982356},{"batb":[[1,4.6,38.04]],"batl":[[0,5.7,13.14],[1,5.7,0]],"ltp":0.0,"tv":0.0,"id":12982355},{"batb":[[0,10.5,13.14],[1,1.01,0.51],[2,1.01,0]],"ltp":11.0,"tv":22.68,"id":13015345},{"batb":[[2,1.01,0.51]],"batl":[[0,7.4,15.58],[1,7.4,0]],"ltp":0.0,"tv":0.0,"id":13015344}]}]}
{"op":"mcm","clk":"1006438336","pt":1580648495263,"mc":[{"id":"1.168224553","rc":[{"batb":[[0,1.63,101.42],[1,1.62,96.42],[2,1.01,0.51]],"ltp":1.78,"tv":148.01,"id":12982356},{"batb":[[0,12,26.29],[1,11.5,26.75],[2,10.5,13.14]],"ltp":11.0,"tv":22.68,"id":13015345},{"batb":[[0,6.2,49.6],[1,6,43.56],[2,5.9,18.41]],"ltp":0.0,"tv":0.0,"id":13015344}]}]}
{"op":"mcm","clk":"1006439461","pt":1580648504908,"mc":[{"id":"1.168224553","rc":[{"batb":[[0,1.62,28.48],[1,1.01,0.51],[2,1.01,0]],"ltp":1.78,"tv":148.01,"id":12982356}]}]}
{"op":"mcm","clk":"1006439857","pt":1580648507891,"mc":[{"id":"1.168224553","rc":[{"batb":[[0,1.74,72.51],[1,1.72,109.06],[2,1.62,28.48]],"ltp":1.78,"tv":148.01,"id":12982356}]}]}
{"op":"mcm","clk":"1006440094","pt":1580648509382,"mc":[{"id":"1.168224553","rc":[{"batb":[[0,1.74,94.78],[1,1.72,167.03],[2,1.68,25.26]],"batl":[[1,1.86,42.01],[2,1.88,19.67]],"ltp":1.78,"tv":148.01,"id":12982356},{"batb":[[1,4.6,54.25],[2,4.5,11.76]],"batl":[[0,5.3,9.24],[1,5.5,14.63],[2,5.6,13.93]],"ltp":0.0,"tv":0.0,"id":12982355},{"batb":[[0,12,29.65]],"batl":[[0,13.5,11.96],[1,16,8.5]],"ltp":11.0,"tv":22.68,"id":13015345},{"batl":[[0,6.6,6.72],[1,7.2,16.29]],"ltp":0.0,"tv":0.0,"id":13015344}]}]}
{"op":"mcm","clk":"1006441100","pt":1580648516331,"mc":[{"id":"1.168224553","rc":[{"batb":[[0,1.68,25.26],[1,1.01,0.51],[2,1.68,0]],"batl":[[0,1.88,19.67],[1,1.86,0],[2,1.88,0]],"ltp":1.78,"tv":148.01,"id":12982356},{"batb":[[0,4.6,54.25],[1,1.01,0.51],[2,4.5,0]],"batl":[[0,5.6,13.93],[1,5.5,0],[2,5.6,0]],"ltp":0.0,"tv":0.0,"id":12982355},{"batb":[[0,9.4,16.37],[1,1.01,0.51],[2,10.5,0]],"batl":[[0,16,8.5],[1,16,0]],"ltp":11.0,"tv":22.68,"id":13015345},{"batb":[[0,6.2,27.23],[2,5.8,19.2]],"batl":[[0,7.2,16.29],[1,7.2,0]],"ltp":0.0,"tv":0.0,"id":13015344}]}]}
{"op":"mcm","clk":"1006441538","pt":1580648519200,"mc":[{"id":"1.168224553","rc":[{"batb":[[0,1.68,126.43],[1,1.67,60.87],[2,1.01,0.51]],"ltp":1.78,"tv":148.01,"id":12982356},{"batb":[[1,4.5,40.29],[2,1.01,0.51]],"ltp":0.0,"tv":0.0,"id":12982355},{"batb":[[0,11,14.98],[1,10.5,32.62],[2,9.4,16.37]],"ltp":11.0,"tv":22.68,"id":13015345}]}]}
{"op":"mcm","clk":"1006441661","pt":1580648520110,"mc":[{"id":"1.168224553","rc":[{"batb":[[0,1.68,25.26],[1,1.01,0.51],[2,1.01,0]],"ltp":1.78,"tv":148.01,"id":12982356},{"batb":[[1,1.01,0.51],[2,1.01,0]],"ltp":0.0,"tv":0.0,"id":12982355},{"batb":[[0,9.4,16.37],[1,1.01,0.51],[2,9.4,0]],"ltp":11.0,"tv":22.68,"id":13015345}]}]}
{"op":"mcm","clk":"1006442228","pt":1580648524107,"mc":[{"id":"1.168224553","rc":[{"batb":[[0,1.73,75.76],[1,1.71,111.27],[2,1.68,25.26]],"ltp":1.78,"tv":148.01,"id":12982356},{"batb":[[0,4.7,31.23],[1,4.6,54.25],[2,1.01,0.51]],"ltp":0.0,"tv":0.0,"id":12982355},{"batb":[[0,12.5,14.46],[1,12,24.73],[2,9.4,16.37]],"ltp":11.0,"tv":22.68,"id":13015345},{"batb":[[0,6.2,55.11]],"ltp":0.0,"tv":0.0,"id":13015344}]}]}
{"op":"mcm","clk":"1006442399","pt":1580648525322,"mc":[{"id":"1.168224553","rc":[{"batb":[[0,1.68,25.26],[1,1.01,0.51],[2,1.68,0]],"ltp":1.78,"tv":148.01,"id":12982356},{"batb":[[0,4.6,54.25],[1,1.01,0.51],[2,1.01,0]],"ltp":0.0,"tv":0.0,"id":12982355},{"batb":[[0,9.4,16.37],[1,1.01,0.51],[2,9.4,0]],"ltp":11.0,"tv":22.68,"id":13015345},{"batb":[[0,6.2,27.23]],"ltp":0.0,"tv":0.0,"id":13015344}]}]}
{"op":"mcm","clk":"1006442811","pt":1580648528343,"mc":[{"id":"1.168224553","rc":[{"batb":[[0,1.68,126.43],[1,1.67,60.87],[2,1.01,0.51]],"ltp":1.78,"tv":148.01,"id":12982356},{"batb":[[1,4.5,40.29],[2,1.01,0.51]],"ltp":0.0,"tv":0.0,"id":12982355},{"batb":[[0,11,14.98],[1,10.5,32.62],[2,9.4,16.37]],"ltp":11.0,"tv":22.68,"id":13015345}]}]}
{"op":"mcm","clk":"1006444555","pt":1580648541150,"mc":[{"id":"1.168224553","rc":[{"batb":[[0,4.6,16.21],[1,1.01,0.51],[2,1.01,0]],"ltp":0.0,"tv":0.0,"id":12982355},{"batb":[[0,9.4,16.37],[1,1.01,0.51],[2,9.4,0]],"ltp":11.0,"tv":22.68,"id":13015345},{"batb":[[1,5.8,19.2],[2,1.01,0.51]],"ltp":0.0,"tv":0.0,"id":13015344}]}]}
{"op":"mcm","clk":"1006444981","pt":1580648544452,"mc":[{"id":"1.168224553","rc":[{"batb":[[0,4.8,23.02],[1,4.7,36.69],[2,4.6,16.21]],"ltp":0.0,"tv":0.0,"id":12982355},{"batb":[[0,14,23.33],[1,13.5,19.07],[2,9.4,16.37]],"ltp":11.0,"tv":22.68,"id":13015345},{"batb":[[0,6.4,38.11],[1,6.2,40.81],[2,5.8,19.2]],"ltp":0.0,"tv":0.0,"id":13015344}]}]}
{"op":"mcm","clk":"1006445072","pt":1580648545252,"mc":[{"id":"1.168224553","rc":[{"batb":[[0,1.68,187.76],[2,1.6,29.98]],"batl":[[0,1.76,24.71],[1,1.82,64.12]],"ltp":1.78,"tv":148.01,"id":12982356},{"batb":[[0,4.9,14.48],[1,4.8,23.02],[2,4.7,51.95]],"batl":[[0,5.4,9.24],[1,5.6,13.93],[2,5.8,12.83]],"ltp":0.0,"tv":0.0,"id":12982355},{"batb":[[1,13.5,22.43],[2,12,9.21]],"batl":[[1,22,4.8]],"ltp":11.0,"tv":22.68,"id":13015345},{"batb":[[2,6,18.02]],"batl":[[0,6.8,6.72],[1,7.4,15.26]],"ltp":0.0,"tv":0.0,"id":13015344}]}]}
{"op":"mcm","clk":"1006448614","pt":1580648572277,"mc":[{"id":"1.168224553","rc":[{"batb":[[0,1.6,29.98],[1,1.01,0.51],[2,1.6,0]],"batl":[[0,1.82,22.11],[1,1.82,0]],"ltp":1.78,"tv":148.01,"id":12982356},{"batb":[[0,4.7,42.59],[1,1.01,0.51],[2,4.7,0]],"batl":[[0,5.8,12.83],[1,5.6,0],[2,5.8,0]],"ltp":0.0,"tv":0.0,"id":12982355},{"batb":[[0,10.5,12.83],[1,1.01,0.51],[2,12,0]],"batl":[[0,22,4.8],[1,22,0]],"ltp":11.0,"tv":22.68,"id":13015345},{"batb":[[0,6.2,40.81],[1,6,18.02],[2,1.01,0.51]],"batl":[[0,7.4,15.26],[1,7.4,0]],"ltp":0.0,"tv":0.0,"id":13015344}]}]}
{"op":"mcm","clk":"1006449041","pt":1580648575467,"mc":[{"id":"1.168224553","rc":[{"batb":[[0,1.61,118.16],[1,1.6,101.18],[2,1.01,0.51]],"ltp":1.78,"tv":148.01,"id":12982356},{"batb":[[1,4.6,38.47],[2,1.01,0.51]],"ltp":0.0,"tv":0.0,"id":12982355},{"batb":[[0,12,25.69],[1,11.5,26.57],[2,10.5,12.83]],"ltp":11.0,"tv":22.68,"id":13015345},{"batb":[[0,6.2,56.62],[1,6,61.37]],"ltp":0.0,"tv":0.0,"id":13015344}]}]}
{"op":"mcm","clk":"1006450250","pt":1580648584384,"mc":[{"id":"1.168224553","rc":[{"batb":[[0,1.6,29.98],[1,1.01,0.51],[2,1.01,0]],"ltp":1.78,"tv":148.01,"id":12982356},{"batb":[[0,4.7,15.26],[1,1.01,0.51],[2,1.01,0]],"ltp":0.0,"tv":0.0,"id":12982355},{"batb":[[0,10.5,12.83],[1,1.01,0.51],[2,10.5,0]],"ltp":11.0,"tv":22.68,"id":13015345},{"batb":[[0,6,18.02],[1,1.01,0.51],[2,1.01,0]],"ltp":0.0,"tv":0.0,"id":13015344}]}]}
{"op":"mcm","clk":"1006450635","pt":1580648587422,"mc":[{"id":"1.168224553","rc":[{"batb":[[0,1.62,67.22],[1,1.61,118.16],[2,1.6,101.18]],"batl":[[0,1.74,42.01],[1,1.82,22.11]],"ltp":1.78,"tv":148.01,"id":12982356},{"batb":[[0,4.9,33.72],[1,4.8,34.8],[2,4.7,15.26]],"batl":[[0,5.4,9.24],[1,5.8,12.83]],"ltp":0.0,"tv":0.0,"id":12982355},{"batb":[[0,19,5.47],[1,18.5,10.32],[2,10.5,12.83]],"ltp":11.0,"tv":22.68,"id":13015345},{"batb":[[0,6.6,31.64],[1,6.4,38.23],[2,6,18.02]],"batl":[[0,7,6.72],[1,7.4,15.26]],"ltp":0.0,"tv":0.0,"id":13015344}]}]}
{"op":"mcm","clk":"1006450754","pt":1580648588297,"mc":[{"id":"1.168224553","rc":[{"batl":[[0,1.67,29.27],[1,1.74,67.35]],"ltp":1.78,"tv":148.01,"id":12982356},{"batb":[[0,5,13.38],[1,4.9,48.04],[2,4.8,34.8]],"batl":[[2,6,11.72]],"ltp":0.0,"tv":0.0,"id":12982355},{"batb":[[2,15.5,5.11]],"ltp":11.0,"tv":22.68,"id":13015345},{"batb":[[2,6.2,16.29]],"batl":[[2,7.8,14.24]],"ltp":0.0,"tv":0.0,"id":13015344}]}]}
{"op":"mcm","clk":"1006453034","pt":1580648606447,"mc":[{"id":"1.168224553","rc":[{"batb":[[0,1.52,36.12],[1,1.01,0.51],[2,1.6,0]],"batl":[[0,1.74,25.34],[1,1.74,0]],"ltp":1.78,"tv":148.01,"id":12982356},{"batb":[[0,4.9,14.32],[1,4.8,34.8],[2,1.01,0.51]],"batl":[[0,6,11.72],[1,5.8,0],[2,6,0]],"ltp":0.0,"tv":0.0,"id":12982355},{"batb":[[0,12.5,8.5],[1,1.01,0.51],[2,15.5,0]],"ltp":11.0,"tv":22.68,"id":13015345},{"batb":[[0,6.4,38.23],[1,6,17.31],[2,1.01,0.51]],"batl":[[0,7.8,14.24],[1,7.4,0],[2,7.8,0]],"ltp":0.0,"tv":0.0,"id":13015344}]}]}
{"op":"mcm","clk":"1006453364","pt":1580648609041,"mc":[{"id":"1.168224553","rc":[{"batb":[[0,1.54,104.46],[1,1.53,84.46],[2,1.52,36.12]],"ltp":1.78,"tv":148.01,"id":12982356},{"batb":[[2,4.7,36.58]],"ltp":0.0,"tv":0.0,"id":12982355},{"batb":[[0,14.5,22.23],[1,14,17.71],[2,12.5,8.5]],"ltp":11.0,"tv":22.68,"id":13015345},{"batb":[[0,6.4,45.59],[1,6.2,40.61],[2,6,17.31]],"ltp":0.0,"tv":0.0,"id":13015344}]}]}
{"op":"mcm","clk":"1006453541","pt":1580648610350,"mc":[{"id":"1.168224553","rc":[{"batb":[[0,1.52,36.12],[1,1.01,0.51],[2,1.52,0]],"ltp":1.78,"tv":148.01,"id":12982356},{"batb":[[2,1.01,0.51]],"ltp":0.0,"tv":0.0,"id":12982355},{"batb":[[0,12.5,8.5],[1,1.01,0.51],[2,12.5,0]],"ltp":11.0,"tv":22.68,"id":13015345},{"batb":[[0,6.4,38.23],[1,6,17.31],[2,1.01,0.51]],"ltp":0.0,"tv":0.0,"id":13015344}]}]}
{"op":"mcm","clk":"1006453962","pt":1580648613433,"mc":[{"id":"1.168224553","rc":[{"batb":[[0,1.6,82.74],[1,1.59,72.76],[2,1.52,36.12]],"ltp":1.78,"tv":148.01,"id":12982356},{"batb":[[0,4.9,58.87]],"ltp":0.0,"tv":0.0,"id":12982355},{"batb":[[0,20,14.68],[1,19.5,9.04],[2,12.5,8.5]],"ltp":11.0,"tv":22.68,"id":13015345},{"batb":[[0,6.6,38.57],[1,6.4,38.23],[2,6,17.31]],"ltp":0.0,"tv":0.0,"id":13015344}]}]}
{"op":"mcm","clk":"1006454162","pt":1580648614899,"mc":[{"id":"1.168224553","rc":[{"batb":[[0,1.52,36.12],[1,1.01,0.51],[2,1.52,0]],"ltp":1.78,"tv":148.01,"id":12982356},{"batb":[[0,4.9,14.32]],"ltp":0.0,"tv":0.0,"id":12982355},{"batb":[[0,12.5,8.5],[1,1.01,0.51],[2,12.5,0]],"ltp":11.0,"tv":22.68,"id":13015345},{"batb":[[0,6.4,38.23],[1,6,17.31],[2,1.01,0.51]],"ltp":0.0,"tv":0.0,"id":13015344}]}]}
{"op":"mcm","clk":"1006454586","pt":1580648617725,"mc":[{"id":"1.168224553","rc":[{"batb":[[0,1.54,104.46],[1,1.53,84.46],[2,1.52,36.12]],"ltp":1.78,"tv":148.01,"id":12982356},{"batb":[[2,4.7,36.58]],"ltp":0.0,"tv":0.0,"id":12982355},{"batb":[[0,14.5,22.23],[1,14,17.71],[2,12.5,8.5]],"ltp":11.0,"tv":22.68,"id":13015345},{"batb":[[0,6.4,45.59],[1,6.2,40.61],[2,6,17.31]],"ltp":0.0,"tv":0.0,"id":13015344}]}]}
{"op":"mcm","clk":"1006456004","pt":1580648628464,"mc":[{"id":"1.168224553","rc":[{"batb":[[1,1.01,0.51],[2,4.7,0]],"ltp":0.0,"tv":0.0,"id":12982355},{"batb":[[0,12.5,8.5],[1,1.01,0.51],[2,12.5,0]],"ltp":11.0,"tv":22.68,"id":13015345},{"batb":[[0,6,17.31],[1,1.01,0.51],[2,6,0]],"ltp":0.0,"tv":0.0,"id":13015344}]}]}
{"op":"mcm","clk":"1006456349","pt":1580648631266,"mc":[{"id":"1.168224553","rc":[{"batb":[[0,5.1,21.54],[1,5,31.9],[2,4.9,14.32]],"ltp":0.0,"tv":0.0,"id":12982355},{"batb":[[0,30,6.46],[1,29,8.06],[2,12.5,8.5]],"ltp":11.0,"tv":22.68,"id":13015345},{"batb":[[0,6.8,29.51],[1,6.6,35.81],[2,6,17.31]],"ltp":0.0,"tv":0.0,"id":13015344}]}]}
{"op":"mcm","clk":"1006456451","pt":1580648632076,"mc":[{"id":"1.168224553","rc":[{"batl":[[0,1.59,35.25],[1,1.65,30.84]],"ltp":1.78,"tv":148.01,"id":12982356},{"batb":[[0,5.3,12.2],[1,5.1,34.6],[2,5,31.9]],"batl":[[1,6.4,10.62]],"ltp":0.0,"tv":0.0,"id":12982355},{"batb":[[2,23,3.54]],"ltp":11.0,"tv":22.68,"id":13015345},{"batb":[[2,6.4,15.19]],"batl":[[1,8,13.14]],"ltp":0.0,"tv":0.0,"id":13015344}]}]}
{"op":"mcm","clk":"1006456601","pt":1580648633261,"mc":[{"id":"1.168224553","rc":[{"batb":[[0,1.56,74.78],[1,1.54,104.46],[2,1.53,84.46]],"batl":[[2,1.67,42.01]],"ltp":1.78,"tv":148.01,"id":12982356},{"batl":[[0,5.5,9.24],[1,6,11.72],[2,6.4,10.62]],"ltp":0.0,"tv":0.0,"id":12982355},{"batl":[[0,7.2,6.72],[1,7.8,14.24],[2,8,13.14]],"ltp":0.0,"tv":0.0,"id":13015344}]}]}
{"op":"mcm","clk":"1006458602","pt":1580648648710,"mc":[{"id":"1.168224553","rc":[{"batb":[[1,1.45,43.04],[2,1.01,0.51]],"batl":[[0,1.65,30.84],[1,1.67,42.01],[2,1.67,0]],"ltp":1.78,"tv":148.01,"id":12982356},{"batb":[[0,5.1,13.06],[1,4.7,10.92],[2,1.01,0.51]],"batl":[[1,6.4,10.62],[2,6.4,0]],"ltp":0.0,"tv":0.0,"id":12982355},{"batb":[[0,17,8.1],[1,1.01,0.51],[2,23,0]],"ltp":11.0,"tv":22.68,"id":13015345},{"batb":[[0,6.6,35.81],[1,6.2,16.13],[2,6,8.4]],"batl":[[1,8,13.14],[2,8,0]],"ltp":0.0,"tv":0.0,"id":13015344}]}]}
{"op":"mcm","clk":"1006458820","pt":1580648650324,"mc":[{"id":"1.168224553","rc":[{"batb":[[0,1.45,43.04],[1,1.01,0.51],[2,1.01,0]],"batl":[[1,1.67,0]],"ltp":1.78,"tv":148.01,"id":12982356},{"batb":[[1,1.01,0.51],[2,1.01,0]],"batl":[[0,6.4,10.62],[1,6.4,0]],"ltp":0.0,"tv":0.0,"id":12982355},{"batb":[[2,1.01,0.51]],"batl":[[0,8,13.14],[1,8,0]],"ltp":0.0,"tv":0.0,"id":13015344}]}]}
{"op":"mcm","clk":"1006458988","pt":1580648651392,"mc":[{"id":"1.168224553","rc":[{"batb":[[0,1.48,114.52],[1,1.47,99.35],[2,1.45,43.04]],"ltp":1.78,"tv":148.01,"id":12982356},{"batb":[[1,4.9,50.11],[2,4.8,34.54]],"ltp":0.0,"tv":0.0,"id":12982355},{"batb":[[0,22,5.67],[1,21,15.55],[2,17,8.1]],"ltp":11.0,"tv":22.68,"id":13015345},{"batb":[[1,6.4,38.03],[2,6.2,16.13]],"ltp":0.0,"tv":0.0,"id":13015344}]}]}
{"op":"mcm","clk":"1006459073","pt":1580648651938,"mc":[{"id":"1.168224553","rc":[{"batb":[[0,1.45,43.04],[1,1.01,0.51],[2,1.45,0]],"ltp":1.78,"tv":148.01,"id":12982356},{"batb":[[1,1.01,0.51],[2,4.8,0]],"ltp":0.0,"tv":0.0,"id":12982355},{"batb":[[0,17,8.1],[1,1.01,0.51],[2,17,0]],"ltp":11.0,"tv":22.68,"id":13015345},{"batb":[[1,6.2,16.13],[2,1.01,0.51]],"ltp":0.0,"tv":0.0,"id":13015344}]}]}
{"op":"mcm","clk":"1006459716","pt":1580648656291,"mc":[{"id":"1.168224553","rc":[{"batb":[[0,1.53,85.85],[1,1.52,86.58],[2,1.45,43.04]],"ltp":1.78,"tv":148.01,"id":12982356},{"batb":[[0,5.1,44.68],[1,5,31.75],[2,1.01,0.51]],"ltp":0.0,"tv":0.0,"id":12982355},{"batb":[[0,32,15.16],[1,30,6.34],[2,17,8.1]],"ltp":11.0,"tv":22.68,"id":13015345},{"batb":[[0,6.8,36.6],[1,6.6,35.81],[2,6.2,16.13]],"ltp":0.0,"tv":0.0,"id":13015344}]}]}
{"op":"mcm","clk":"1006459975","pt":1580648657935,"mc":[{"id":"1.168224553","rc":[{"batb":[[0,1.45,43.04],[1,1.01,0.51],[2,1.45,0]],"ltp":1.78,"tv":148.01,"id":12982356},{"batb":[[0,5.1,13.06],[1,1.01,0.51],[2,1.01,0]],"ltp":0.0,"tv":0.0,"id":12982355},{"batb":[[0,17,8.1],[1,1.01,0.51],[2,17,0]],"ltp":11.0,"tv":22.68,"id":13015345},{"batb":[[0,6.6,35.81],[1,6.2,16.13],[2,1.01,0.51]],"ltp":0.0,"tv":0.0,"id":13015344}]}]}
{"op":"mcm","clk":"1006460381","pt":1580648660919,"mc":[{"id":"1.168224553","rc":[{"batb":[[0,1.48,114.52],[1,1.47,99.35],[2,1.45,43.04]],"ltp":1.78,"tv":148.01,"id":12982356},{"batb":[[1,4.9,50.11],[2,4.8,34.54]],"ltp":0.0,"tv":0.0,"id":12982355},{"batb":[[0,22,5.67],[1,21,15.55],[2,17,8.1]],"ltp":11.0,"tv":22.68,"id":13015345},{"batb":[[1,6.4,38.03],[2,6.2,16.13]],"ltp":0.0,"tv":0.0,"id":13015344}]}]}
{"op":"mcm","clk":"1006462350","pt":1580648675433,"mc":[{"id":"1.168224553","rc":[{"batb":[[1,1.01,0.51],[2,4.8,0]],"ltp":0.0,"tv":0.0,"id":12982355},{"batb":[[0,17,8.1],[1,1.01,0.51],[2,17,0]],"ltp":11.0,"tv":22.68,"id":13015345},{"batb":[[0,6.2,16.13],[1,1.01,0.51],[2,6.2,0]],"ltp":0.0,"tv":0.0,"id":13015344}]}]}
{"op":"mcm","clk":"1006462753","pt":1580648678247,"mc":[{"id":"1.168224553","rc":[{"batb":[[0,5.2,40.97],[1,5.1,43.27],[2,1.01,0.51]],"ltp":0.0,"tv":0.0,"id":12982355},{"batb":[[0,60,5.14],[1,55,6.68],[2,17,8.1]],"ltp":11.0,"tv":22.68,"id":13015345},{"batb":[[0,7,30.43],[1,6.8,33.55],[2,6.2,16.13]],"ltp":0.0,"tv":0.0,"id":13015344}]}]}
{"op":"mcm","clk":"1006462857","pt":1580648679219,"mc":[{"id":"1.168224553","rc":[{"batb":[[0,1.48,201.9]],"batl":[[0,1.52,41.86],[1,1.57,36.59],[2,1.58,42.01]],"ltp":1.78,"tv":148.01,"id":12982356},{"batb":[[0,5.5,11.09],[1,5.3,12.04],[2,5.2,40.97]],"batl":[[0,5.7,8.4],[1,6.4,10.62],[2,6.6,20.3]],"ltp":0.0,"tv":0.0,"id":12982355},{"batb":[[2,26,4.19]],"ltp":11.0,"tv":22.68,"id":13015345},{"batb":[[2,6.6,13.93]],"batl":[[0,7.8,5.88],[1,8,13.14],[2,8.2,12.43]],"ltp":0.0,"tv":0.0,"id":13015344}]}]}
{"op":"mcm","clk":"1006467502","pt":1580648713308,"mc":[{"id":"1.168224553","rc":[{"trd":[[1.48,4.24]],"batb":[[0,1.48,199.78]],"ltp":1.48,"tv":152.25,"id":12982356}],"tv":174.93}]}
{"op":"mcm","clk":"1006476109","pt":1580648775055,"mc":[{"id":"1.168224553","rc":[{"batb":[[0,1.48,87.38],[1,1.43,46.58],[2,1.01,0.51]],"batl":[[0,1.57,36.59],[1,1.58,42.01],[2,1.58,0]],"ltp":1.48,"tv":152.25,"id":12982356},{"batb":[[0,5.3,12.04],[1,5.1,30.21],[2,4.8,10.92]],"batl":[[1,6.6,20.3],[2,6.6,0]],"ltp":0.0,"tv":0.0,"id":12982355},{"batb":[[0,26,4.19],[1,1.01,0.51],[2,26,0]],"ltp":11.0,"tv":22.68,"id":13015345},{"batb":[[0,6.8,33.55],[1,6.4,22.83],[2,1.01,0.51]],"batl":[[1,8.2,12.43],[2,8.2,0]],"ltp":0.0,"tv":0.0,"id":13015344}]}]}
{"op":"mcm","clk":"1006476294","pt":1580648776387,"mc":[{"id":"1.168224553","rc":[{"batb":[[0,1.43,46.58],[1,1.01,0.51],[2,1.01,0]],"batl":[[1,1.58,0]],"ltp":1.48,"tv":152.25,"id":12982356},{"batb":[[2,1.01,0.51]],"batl":[[0,6.6,20.3],[1,6.6,0]],"ltp":0.0,"tv":0.0,"id":12982355},{"batb":[[1,6.4,15.26]],"batl":[[0,8.2,12.43],[1,8.2,0]],"ltp":0.0,"tv":0.0,"id":13015344}]}]}
{"op":"mcm","clk":"1006476560","pt":1580648778265,"mc":[{"id":"1.168224553","rc":[{"batb":[[0,1.46,97.48],[1,1.45,105.26],[2,1.42,46.89]],"ltp":1.48,"tv":152.25,"id":12982356},{"batb":[[2,5,31.71]],"ltp":0.0,"tv":0.0,"id":12982355},{"batb":[[0,40,2.99],[1,38,9.29],[2,27,3.43]],"ltp":11.0,"tv":22.68,"id":13015345},{"batb":[[1,6.6,35.9],[2,6.4,15.26]],"ltp":0.0,"tv":0.0,"id":13015344}]}]}
{"op":"mcm","clk":"1006476976","pt":1580648781279,"mc":[{"id":"1.168224553","rc":[{"batb":[[1,1.01,0.51],[2,5,0]],"ltp":0.0,"tv":0.0,"id":12982355},{"batb":[[0,27,3.43],[1,1.01,0.51],[2,27,0]],"ltp":11.0,"tv":22.68,"id":13015345},{"batb":[[0,6.4,15.26],[1,1.01,0.51],[2,6.4,0]],"ltp":0.0,"tv":0.0,"id":13015344}]}]}
{"op":"mcm","clk":"1006477459","pt":1580648784386,"mc":[{"id":"1.168224553","rc":[{"batb":[[0,5.3,43.51],[1,5.2,29.03],[2,1.01,0.51]],"ltp":0.0,"tv":0.0,"id":12982355},{"batb":[[0,85,5.26],[1,80,2.85],[2,27,3.43]],"ltp":11.0,"tv":22.68,"id":13015345},{"batb":[[0,7.2,23.37],[1,7,31.77],[2,6.4,15.26]],"ltp":0.0,"tv":0.0,"id":13015344}]}]}
{"op":"mcm","clk":"1006477587","pt":1580648785299,"mc":[{"id":"1.168224553","rc":[{"batb":[[0,1.47,89.06],[1,1.46,97.48],[2,1.45,105.26]],"batl":[[0,1.49,45.56],[1,1.54,40.13],[2,1.56,42.01]],"ltp":1.48,"tv":152.25,"id":12982356},{"batb":[[0,5.6,10.54],[1,5.4,11.49],[2,5.3,31.47]],"batl":[[0,5.8,8.4],[1,6.6,20.3],[2,6.8,19.2]],"ltp":0.0,"tv":0.0,"id":12982355},{"batb":[[2,1.01,0.51]],"ltp":11.0,"tv":22.68,"id":13015345},{"batb":[[2,6.8,13.22]],"batl":[[0,8,5.88],[1,8.2,12.43],[2,8.4,11.8]],"ltp":0.0,"tv":0.0,"id":13015344}]}]}
{"op":"mcm","clk":"1006477633","pt":1580648785582,"mc":[{"id":"1.168224553","rc":[{"batl":[[0,6.6,20.3],[1,6.8,19.2],[2,6.8,0]],"ltp":0.0,"tv":0.0,"id":12982355}]}]}
{"op":"mcm","clk":"1006477896","pt":1580648787391,"mc":[{"id":"1.168224553","rc":[{"batl":[[0,5.7,8.4],[1,6.6,20.3],[2,6.8,19.2]],"ltp":0.0,"tv":0.0,"id":12982355}]}]}
{"op":"mcm","clk":"1006478485","pt":1580648790976,"mc":[{"id":"1.168224553","rc":[{"batb":[[1,1.4,49.96],[2,1.01,0.51]],"batl":[[0,1.54,40.13],[1,1.56,42.01],[2,1.56,0]],"ltp":1.48,"tv":152.25,"id":12982356},{"batb":[[0,5.4,11.49],[1,5.2,29.03],[2,4.9,10.08]],"batl":[[1,6.8,19.2],[2,6.8,0]],"ltp":0.0,"tv":0.0,"id":12982355},{"batb":[[0,1.01,0.51],[1,80,0],[2,1.01,0]],"ltp":11.0,"tv":22.68,"id":13015345},{"batb":[[0,7,16.51],[1,6.4,22.28],[2,1.01,0.51]],"batl":[[1,8.4,11.8],[2,8.4,0]],"ltp":0.0,"tv":0.0,"id":13015344}]}]}
{"op":"mcm","clk":"1006478682","pt":1580648792304,"mc":[{"id":"1.168224553","rc":[{"batb":[[0,1.4,49.96],[1,1.01,0.51],[2,1.01,0]],"batl":[[1,1.56,0]],"ltp":1.48,"tv":152.25,"id":12982356},{"batb":[[2,1.01,0.51]],"batl":[[0,6.8,19.2],[1,6.8,0]],"ltp":0.0,"tv":0.0,"id":12982355},{"batb":[[1,6.4,14.71]],"batl":[[0,8.4,11.8],[1,8.4,0]],"ltp":0.0,"tv":0.0,"id":13015344}]}]}
{"op":"mcm","clk":"1006478975","pt":1580648794292,"mc":[{"id":"1.168224553","rc":[{"batb":[[0,1.44,127.32],[1,1.43,112.02],[2,1.4,49.96]],"ltp":1.48,"tv":152.25,"id":12982356},{"batb":[[2,5.1,30.43]],"ltp":0.0,"tv":0.0,"id":12982355},{"batb":[[0,55,4.33],[1,50,8.75],[2,1.01,0.51]],"ltp":11.0,"tv":22.68,"id":13015345},{"batb":[[1,6.8,33.99],[2,6.4,14.71]],"ltp":0.0,"tv":0.0,"id":13015344}]}]}
{"op":"mcm","clk":"1006479475","pt":1580648797422,"mc":[{"id":"1.168224553","rc":[{"batb":[[1,1.01,0.51],[2,5.1,0]],"ltp":0.0,"tv":0.0,"id":12982355},{"batb":[[0,1.01,0.51],[1,50,0],[2,1.01,0]],"ltp":11.0,"tv":22.68,"id":13015345},{"batb":[[0,6.4,14.71],[1,1.01,0.51],[2,6.4,0]],"ltp":0.0,"tv":0.0,"id":13015344}]}]}
{"op":"mcm","clk":"1006479813","pt":1580648799904,"mc":[{"id":"1.168224553","rc":[{"batb":[[0,5.4,33.83],[1,5.3,27.95],[2,1.01,0.51]],"ltp":0.0,"tv":0.0,"id":12982355},{"batb":[[0,7.4,13.92],[1,7.2,30.11],[2,6.4,14.71]],"ltp":0.0,"tv":0.0,"id":13015344}]}]}
{"op":"mcm","clk":"1006480014","pt":1580648801300,"mc":[{"id":"1.168224553","rc":[{"batb":[[0,1.45,93.26],[1,1.44,127.32],[2,1.43,112.02]],"batl":[[0,1.47,48.47],[1,1.51,43.59],[2,1.54,42.01]],"ltp":1.48,"tv":152.25,"id":12982356},{"batb":[[0,5.5,10.94],[1,5.4,22.34],[2,5.3,27.95]],"batl":[[0,5.8,8.4],[1,6.8,18.33]],"ltp":0.0,"tv":0.0,"id":12982355},{"batb":[[2,7,12.51]],"batl":[[0,8.2,5.04],[1,8.4,11.8],[2,8.8,11.17]],"ltp":0.0,"tv":0.0,"id":13015344}]}]}
{"op":"mcm","clk":"1006481755","pt":1580648812934,"mc":[{"id":"1.168224553","rc":[{"batb":[[1,1.43,87.21],[2,1.38,53.03]],"batl":[[0,1.51,43.59],[1,1.54,42.01],[2,1.54,0]],"ltp":1.48,"tv":152.25,"id":12982356},{"batb":[[1,4.9,10.08],[2,1.01,0.51]],"ltp":0.0,"tv":0.0,"id":12982355},{"batb":[[0,6.6,20.73],[1,1.01,0.51],[2,7,0]],"batl":[[1,8.8,11.17],[2,8.8,0]],"ltp":0.0,"tv":0.0,"id":13015344}]}]}
{"op":"mcm","clk":"1006481950","pt":1580648814352,"mc":[{"id":"1.168224553","rc":[{"batb":[[0,1.43,87.21],[1,1.38,53.03],[2,1.01,0.51]],"batl":[[1,1.54,0]],"ltp":1.48,"tv":152.25,"id":12982356},{"batb":[[1,1.01,0.51],[2,1.01,0]],"batl":[[0,6.8,18.33],[1,6.8,0]],"ltp":0.0,"tv":0.0,"id":12982355},{"batb":[[0,6.6,14.01]],"batl":[[0,8.8,11.17],[1,8.8,0]],"ltp":0.0,"tv":0.0,"id":13015344}]}]}
{"op":"mcm","clk":"1006482210","pt":1580648816231,"mc":[{"id":"1.168224553","rc":[{"batb":[[1,1.42,115.18],[2,1.38,53.03]],"ltp":1.48,"tv":152.25,"id":12982356},{"batb":[[1,5.2,48.43],[2,5.1,30.08]],"ltp":0.0,"tv":0.0,"id":12982355},{"batb":[[0,85,2.67],[1,80,5.04],[2,1.01,0.51]],"ltp":11.0,"tv":22.68,"id":13015345},{"batb":[[0,7,37.14],[1,6.8,33.48],[2,6.6,14.01]],"ltp":0.0,"tv":0.0,"id":13015344}]}]}
{"op":"mcm","clk":"1006482573","pt":1580648818107,"mc":[{"id":"1.168224553","rc":[{"batb":[[0,1.38,53.03],[1,1.01,0.51],[2,1.38,0]],"ltp":1.48,"tv":152.25,"id":12982356}]}]}
{"op":"mcm","clk":"1006483111","pt":1580648821346,"mc":[{"id":"1.168224553","rc":[{"batb":[[0,1.47,173.32],[1,1.46,102.14],[2,1.44,44.85]],"batl":[[1,1.55,38.63],[2,1.56,42.01]],"ltp":1.48,"tv":152.25,"id":12982356},{"batb":[[1,5.3,11.8],[2,5.2,48.43]],"batl":[[0,5.7,8.4],[1,6.4,10.54],[2,6.6,20.3]],"ltp":0.0,"tv":0.0,"id":12982355},{"batl":[[0,7.8,5.88],[1,8,13.14],[2,8.4,12.2]],"ltp":0.0,"tv":0.0,"id":13015344}]}]}
{"op":"mcm","clk":"1006484322","pt":1580648828838,"mc":[{"id":"1.168224553","rc":[{"batb":[[0,7,44.03]],"ltp":0.0,"tv":0.0,"id":13015344}]}]}
{"op":"mcm","clk":"1006485201","pt":1580648834435,"mc":[{"id":"1.168224553","rc":[{"batb":[[0,1.41,48.55],[1,1.01,0.51],[2,1.44,0]],"batl":[[0,1.55,38.63],[1,1.55,0],[2,1.56,0]],"ltp":1.48,"tv":152.25,"id":12982356},{"batb":[[0,5.3,11.8],[1,5.1,30.08],[2,1.01,0.51]],"batl":[[0,6.6,20.3],[1,6.4,0],[2,6.6,0]],"ltp":0.0,"tv":0.0,"id":12982355},{"batb":[[0,1.01,0.51],[1,80,0],[2,1.01,0]],"ltp":11.0,"tv":22.68,"id":13015345},{"batb":[[0,6.8,33.48],[1,6.4,15.5],[2,1.01,0.51]],"batl":[[0,8.4,12.2],[1,8,0],[2,8.4,0]],"ltp":0.0,"tv":0.0,"id":13015344}]}]}
{"op":"mcm","clk":"1006485635","pt":1580648837477,"mc":[{"id":"1.168224553","rc":[{"batb":[[0,1.45,72.11],[1,1.44,108.31],[2,1.41,48.55]],"ltp":1.48,"tv":152.25,"id":12982356},{"batb":[[1,1.01,0.51],[2,1.01,0]],"ltp":0.0,"tv":0.0,"id":12982355},{"batb":[[0,6.4,15.5],[1,1.01,0.51],[2,1.01,0]],"ltp":0.0,"tv":0.0,"id":13015344}]}]}
{"op":"mcm","clk":"1006486023","pt":1580648840363,"mc":[{"id":"1.168224553","rc":[{"batb":[[0,5.3,49.88],[1,5.2,28.91],[2,1.01,0.51]],"ltp":0.0,"tv":0.0,"id":12982355},{"batb":[[0,7.2,33.07],[1,7,31.69],[2,6.4,15.5]],"ltp":0.0,"tv":0.0,"id":13015344}]}]}
{"op":"mcm","clk":"1006486182","pt":1580648841476,"mc":[{"id":"1.168224553","rc":[{"batb":[[0,1.46,90.74],[1,1.45,72.11],[2,1.44,108.31]],"batl":[[0,1.48,47.13],[1,1.51,42.72],[2,1.55,42.01]],"ltp":1.48,"tv":152.25,"id":12982356},{"batb":[[0,5.6,10.54],[1,5.5,11.09],[2,5.3,38.08]],"batl":[[0,5.8,8.4],[1,6.6,20.3],[2,6.8,18.96]],"ltp":0.0,"tv":0.0,"id":12982355},{"batb":[[2,6.8,12.98]],"batl":[[0,8,5.88],[1,8.4,11.8]],"ltp":0.0,"tv":0.0,"id":13015344}]}]}
{"op":"mcm","clk":"1006487259","pt":1580648849285,"mc":[{"id":"1.168224553","rc":[{"batb":[[1,1.39,51.22],[2,1.01,0.51]],"batl":[[0,1.51,42.72],[1,1.55,42.01],[2,1.55,0]],"ltp":1.48,"tv":152.25,"id":12982356},{"batb":[[0,5.5,11.09],[1,5.2,28.91],[2,4.9,10.08]],"batl":[[1,6.8,18.96],[2,6.8,0]],"ltp":0.0,"tv":0.0,"id":12982355},{"batb":[[0,7,25.45],[1,6.6,6.72],[2,6.4,14.71]],"ltp":0.0,"tv":0.0,"id":13015344}]}]}
{"op":"mcm","clk":"1006487411","pt":1580648850290,"mc":[{"id":"1.168224553","rc":[{"batb":[[0,1.39,51.22],[1,1.01,0.51],[2,1.01,0]],"batl":[[1,1.55,0]],"ltp":1.48,"tv":152.25,"id":12982356},{"batb":[[2,1.01,0.51]],"batl":[[0,6.8,18.96],[1,6.8,0]],"ltp":0.0,"tv":0.0,"id":12982355},{"batb":[[1,6.4,14.71],[2,1.01,0.51]],"batl":[[0,8.4,11.8],[1,8.4,0]],"ltp":0.0,"tv":0.0,"id":13015344}]}]}
{"op":"mcm","clk":"1006487689","pt":1580648852095,"mc":[{"id":"1.168224553","rc":[{"batb":[[0,1.43,142.54],[1,1.42,115.76],[2,1.39,51.22]],"ltp":1.48,"tv":152.25,"id":12982356},{"batb":[[1,5.2,36.19],[2,5.1,30.24]],"ltp":0.0,"tv":0.0,"id":12982355},{"batb":[[0,90,3.33],[1,85,4.42],[2,1.01,0.51]],"ltp":11.0,"tv":22.68,"id":13015345},{"batb":[[1,6.8,33.93],[2,6.4,14.71]],"ltp":0.0,"tv":0.0,"id":13015344}]}]}
{"op":"mcm","clk":"1006488295","pt":1580648856403,"mc":[{"id":"1.168224553","rc":[{"batl":[[0,1.46,37.68],[1,1.51,42.72]],"ltp":1.48,"tv":152.25,"id":12982356}]}]}
{"op":"mcm","clk":"1006488422","pt":1580648857216,"mc":[{"id":"1.168224553","rc":[{"batb":[[1,1.01,0.51],[2,5.1,0]],"ltp":0.0,"tv":0.0,"id":12982355},{"batb":[[0,1.01,0.51],[1,85,0],[2,1.01,0]],"ltp":11.0,"tv":22.68,"id":13015345},{"batb":[[0,6.4,14.71],[1,1.01,0.51],[2,6.4,0]],"ltp":0.0,"tv":0.0,"id":13015344}]}]}
{"op":"mcm","clk":"1006488932","pt":1580648860379,"mc":[{"id":"1.168224553","rc":[{"batb":[[1,5.4,27.08],[2,5.3,27.85]],"ltp":0.0,"tv":0.0,"id":12982355},{"batb":[[0,7.4,23.97],[1,7.2,30.03],[2,6.4,14.71]],"ltp":0.0,"tv":0.0,"id":13015344}]}]}
{"op":"mcm","clk":"1006489072","pt":1580648861298,"mc":[{"id":"1.168224553","rc":[{"batb":[[0,1.44,94.94],[1,1.43,142.54],[2,1.42,115.76]],"batl":[[0,1.46,87.41],[1,1.48,46.89],[2,1.52,42.01]],"ltp":1.48,"tv":152.25,"id":12982356},{"batb":[[0,5.7,20.38],[1,5.6,10.7],[2,5.4,27.08]],"batl":[[0,5.9,8.4],[1,6.8,18.96],[2,7,17.55]],"ltp":0.0,"tv":0.0,"id":12982355},{"batb":[[2,7,12.51]],"batl":[[0,8.2,5.04],[1,8.4,11.8],[2,9,10.62]],"ltp":0.0,"tv":0.0,"id":13015344}]}]}
{"op":"mcm","clk":"1006489637","pt":1580648865393,"mc":[{"id":"1.168224553","rc":[{"batl":[[0,1.46,49.73]],"ltp":1.48,"tv":152.25,"id":12982356}]}]}
{"op":"mcm","clk":"1006490084","pt":1580648868395,"mc":[{"id":"1.168224553","rc":[{"trd":[[1.44,75.37]],"batb":[[0,1.44,57.26]],"ltp":1.44,"tv":227.61,"id":12982356}],"tv":250.3}]}
{"op":"mcm","clk":"1006490498","pt":1580648871400,"mc":[{"id":"1.168224553","rc":[{"batb":[[0,1.44,94.23]],"ltp":1.44,"tv":227.61,"id":12982356},{"trd":[[8.2,4.54]],"batl":[[0,8.2,2.77]],"ltp":8.2,"tv":4.54,"id":13015344}],"tv":254.84}]}
{"op":"mcm","clk":"1006492226","pt":1580648883146,"mc":[{"id":"1.168224553","rc":[{"batb":[[1,1.37,55.94],[2,1.01,0.51]],"batl":[[0,1.48,46.89],[1,1.52,42.01],[2,1.52,0]],"ltp":1.44,"tv":227.61,"id":12982356},{"batb":[[0,5.6,10.7],[1,5.3,27.85],[2,4.9,10.08]],"batl":[[1,7,17.55],[2,7,0]],"ltp":0.0,"tv":0.0,"id":12982355},{"batb":[[0,7.2,24.15],[1,6.8,20.02],[2,1.01,0.51]],"batl":[[1,9,10.62],[2,9,0]],"ltp":8.2,"tv":4.54,"id":13015344}]}]}
{"op":"mcm","clk":"1006492390","pt":1580648884329,"mc":[{"id":"1.168224553","rc":[{"batb":[[0,1.37,55.94],[1,1.01,0.51],[2,1.01,0]],"batl":[[1,1.52,0]],"ltp":1.44,"tv":227.61,"id":12982356},{"batb":[[2,1.01,0.51]],"batl":[[0,7,17.55],[1,7,0]],"ltp":0.0,"tv":0.0,"id":12982355},{"batb":[[1,6.8,13.3]],"batl":[[0,9,10.62],[1,9,0]],"ltp":8.2,"tv":4.54,"id":13015344}]}]}
{"op":"mcm","clk":"1006492683","pt":1580648886323,"mc":[{"id":"1.168224553","rc":[{"batb":[[0,1.37,54.92]],"batl":[[0,1.49,45.95]],"ltp":1.44,"tv":227.61,"id":12982356},{"batb":[[0,5.6,10.54]],"batl":[[0,7,17.39]],"ltp":0.0,"tv":0.0,"id":12982355},{"batb":[[1,6.6,14.16]],"batl":[[0,8.6,11.25]],"ltp":8.2,"tv":4.54,"id":13015344}]}]}
{"op":"mcm","clk":"1006493268","pt":1580648890259,"mc":[{"id":"1.168224553","rc":[{"batb":[[0,1.43,96.4],[1,1.42,115.35],[2,1.37,54.92]],"ltp":1.44,"tv":227.61,"id":12982356},{"batb":[[1,5.4,33.75],[2,5.3,27.85]],"ltp":0.0,"tv":0.0,"id":12982355},{"batb":[[0,7.4,31.99],[1,7.2,29.84],[2,6.6,14.16]],"ltp":8.2,"tv":4.54,"id":13015344}]}]}
{"op":"mcm","clk":"1006493472","pt":1580648891360,"mc":[{"id":"1.168224553","rc":[{"batb":[[0,1.37,54.92],[1,1.01,0.51],[2,1.37,0]],"ltp":1.44,"tv":227.61,"id":12982356},{"batb":[[1,5.3,27.85],[2,1.01,0.51]],"ltp":0.0,"tv":0.0,"id":12982355},{"batb":[[0,7.2,24.15],[1,6.6,14.16],[2,1.01,0.51]],"ltp":8.2,"tv":4.54,"id":13015344}]}]}
{"op":"mcm","clk":"1006493978","pt":1580648894819,"mc":[{"id":"1.168224553","rc":[{"batb":[[0,1.41,143.64],[1,1.4,123.4],[2,1.37,54.92]],"ltp":1.44,"tv":227.61,"id":12982356},{"batb":[[2,5.2,29.03]],"ltp":0.0,"tv":0.0,"id":12982355},{"batb":[[1,7,31.9],[2,6.6,14.16]],"ltp":8.2,"tv":4.54,"id":13015344}]}]}
{"op":"mcm","clk":"1006494270","pt":1580648897042,"mc":[{"id":"1.168224553","rc":[{"batb":[[1,1.01,0.51],[2,5.2,0]],"ltp":0.0,"tv":0.0,"id":12982355},{"batb":[[0,6.6,14.16],[1,1.01,0.51],[2,6.6,0]],"ltp":8.2,"tv":4.54,"id":13015344}]}]}
{"op":"mcm","clk":"1006494798","pt":1580648900444,"mc":[{"id":"1.168224553","rc":[{"batb":[[1,5.5,33.2],[2,5.4,26.61]],"ltp":0.0,"tv":0.0,"id":12982355},{"batb":[[0,7.6,34.99],[1,7.4,28.06],[2,6.6,14.16]],"ltp":8.2,"tv":4.54,"id":13015344}]}]}
{"op":"mcm","clk":"1006494899","pt":1580648901362,"mc":[{"id":"1.168224553","rc":[{"batb":[[0,1.42,99.98],[1,1.41,143.64],[2,1.4,123.4]],"batl":[[0,1.44,53.19],[1,1.46,49.65],[2,1.51,42.01]],"ltp":1.44,"tv":227.61,"id":12982356},{"trd":[[5.9,16.8]],"batb":[[0,5.9,10.17],[1,5.7,19.67],[2,5.5,33.2]],"batl":[[1,7.4,15.89]],"ltp":5.9,"tv":16.8,"id":12982355},{"batb":[[2,7.2,11.88]],"batl":[[0,8.6,16.29],[1,9.2,9.84]],"ltp":8.2,"tv":4.54,"id":13015344}],"tv":271.64}]}
{"op":"mcm","clk":"1006495235","pt":1580648904025,"mc":[{"id":"1.168224553","rc":[{"batl":[[0,6,8.4],[1,7,17.39],[2,7.4,15.89]],"ltp":5.9,"tv":16.8,"id":12982355}]}]}
{"op":"mcm","clk":"1006495322","pt":1580648904656,"mc":[{"id":"1.168224553","rc":[{"trd":[[5.9,33.61]],"batb":[[0,5.9,1.76]],"ltp":5.9,"tv":33.6,"id":12982355}],"tv":288.45}]}
{"op":"mcm","clk":"1006496182","pt":1580648910960,"mc":[{"id":"1.168224553","rc":[{"batb":[[1,1.34,60.82],[2,1.01,0.51]],"batl":[[0,1.46,49.65],[1,1.51,42.01],[2,1.51,0]],"ltp":1.44,"tv":227.61,"id":12982356},{"batb":[[0,5.7,19.67],[1,5.4,26.61],[2,5,10.08]],"batl":[[1,7.4,15.89],[2,7.4,0]],"ltp":5.9,"tv":33.6,"id":12982355},{"batb":[[0,7.4,28.06],[1,7,6.72],[2,6.8,13.06]],"batl":[[0,8.6,5.04]],"ltp":8.2,"tv":4.54,"id":13015344}]}]}
{"op":"mcm","clk":"1006496405","pt":1580648912447,"mc":[{"id":"1.168224553","rc":[{"batb":[[0,1.34,60.82],[1,1.01,0.51],[2,1.01,0]],"batl":[[1,1.51,0]],"ltp":1.44,"tv":227.61,"id":12982356},{"batb":[[2,1.01,0.51]],"batl":[[0,7.4,15.89],[1,7.4,0]],"ltp":5.9,"tv":33.6,"id":12982355},{"batb":[[1,6.8,13.06],[2,1.01,0.51]],"batl":[[0,9.2,9.84],[1,9.2,0]],"ltp":8.2,"tv":4.54,"id":13015344}]}]}
{"op":"mcm","clk":"1006496660","pt":1580648914274,"mc":[{"id":"1.168224553","rc":[{"batb":[[0,1.39,148.1],[1,1.38,131.87],[2,1.36,59.4]],"batl":[[0,1.47,48.47]],"ltp":1.44,"tv":227.61,"id":12982356},{"batb":[[0,5.5,10.46],[1,5.4,34.11],[2,5.3,27.76]],"ltp":5.9,"tv":33.6,"id":12982355},{"batb":[[1,7.2,29.84],[2,6.8,12.9]],"ltp":8.2,"tv":4.54,"id":13015344}]}]}
{"op":"mcm","clk":"1006496740","pt":1580648914875,"mc":[{"id":"1.168224553","rc":[{"batb":[[0,1.36,59.4],[1,1.01,0.51],[2,1.36,0]],"ltp":1.44,"tv":227.61,"id":12982356},{"batb":[[1,5.4,26.61],[2,1.01,0.51]],"ltp":5.9,"tv":33.6,"id":12982355},{"batb":[[1,6.8,12.9],[2,1.01,0.51]],"ltp":8.2,"tv":4.54,"id":13015344}]}]}
{"op":"mcm","clk":"1006497168","pt":1580648918278,"mc":[{"id":"1.168224553","rc":[{"batb":[[0,1.41,102.97],[1,1.4,122.93],[2,1.36,59.4]],"ltp":1.44,"tv":227.61,"id":12982356},{"batb":[[0,5.5,51.58]],"ltp":5.9,"tv":33.6,"id":12982355},{"batb":[[0,7.6,38.87],[1,7.4,28.06],[2,6.8,12.9]],"ltp":8.2,"tv":4.54,"id":13015344}]}]}
{"op":"mcm","clk":"1006497396","pt":1580648919899,"mc":[{"id":"1.168224553","rc":[{"batb":[[0,1.36,59.4],[1,1.01,0.51],[2,1.36,0]],"ltp":1.44,"tv":227.61,"id":12982356},{"batb":[[0,5.5,10.46]],"ltp":5.9,"tv":33.6,"id":12982355},{"batb":[[0,7.4,28.06],[1,6.8,12.9],[2,1.01,0.51]],"ltp":8.2,"tv":4.54,"id":13015344}]}]}
{"op":"mcm","clk":"1006497788","pt":1580648922785,"mc":[{"id":"1.168224553","rc":[{"batb":[[0,1.39,148.1],[1,1.38,131.87],[2,1.36,59.4]],"ltp":1.44,"tv":227.61,"id":12982356},{"batb":[[1,5.4,34.11],[2,5.3,27.76]],"ltp":5.9,"tv":33.6,"id":12982355},{"batb":[[1,7.2,29.84],[2,6.8,12.9]],"ltp":8.2,"tv":4.54,"id":13015344}]}]}
{"op":"mcm","clk":"1006498757","pt":1580648929475,"mc":[{"id":"1.168224553","rc":[{"batb":[[0,1.36,59.4],[1,1.01,0.51],[2,1.36,0]],"ltp":1.44,"tv":227.61,"id":12982356}]}]}
{"op":"mcm","clk":"1006499155","pt":1580648932382,"mc":[{"id":"1.168224553","rc":[{"batb":[[0,1.43,109.16],[1,1.42,115.4],[2,1.36,59.4]],"ltp":1.44,"tv":227.61,"id":12982356}]}]}
{"op":"mcm","clk":"1006499299","pt":1580648933381,"mc":[{"id":"1.168224553","rc":[{"batb":[[0,1.43,206.62],[2,1.41,49.96]],"batl":[[1,1.5,45.16],[2,1.51,42.01]],"ltp":1.44,"tv":227.61,"id":12982356},{"batb":[[1,5.4,45.13]],"batl":[[0,6,8.4],[1,6.6,19.43],[2,6.8,18.41]],"ltp":5.9,"tv":33.6,"id":12982355},{"batb":[[2,6.8,19.63]],"batl":[[0,8.4,17.24],[1,8.8,10.94]],"ltp":8.2,"tv":4.54,"id":13015344}]}]}
{"op":"mcm","clk":"1006501435","pt":1580648948438,"mc":[{"id":"1.168224553","rc":[{"batb":[[0,1.38,54.13],[1,1.01,0.51],[2,1.41,0]],"batl":[[0,1.5,45.16],[1,1.5,0],[2,1.51,0]],"ltp":1.44,"tv":227.61,"id":12982356},{"batb":[[0,5.4,11.02],[1,5.3,27.76],[2,1.01,0.51]],"batl":[[0,6.8,18.41],[1,6.6,0],[2,6.8,0]],"ltp":5.9,"tv":33.6,"id":12982355},{"batb":[[0,7.2,29.84],[1,6.6,14.01],[2,1.01,0.51]],"batl":[[0,8.8,10.94],[1,8.8,0]],"ltp":8.2,"tv":4.54,"id":13015344}]}]}
{"op":"mcm","clk":"1006501795","pt":1580648951229,"mc":[{"id":"1.168224553","rc":[{"batb":[[0,1.41,95.28],[1,1.4,122.86],[2,1.39,53.58]],"batl":[[0,1.5,44.69]],"ltp":1.44,"tv":227.61,"id":12982356},{"batb":[[1,5.3,35.85],[2,5.2,28.96]],"ltp":5.9,"tv":33.6,"id":12982355},{"batb":[[0,160,3.04],[1,1.01,0.51]],"ltp":11.0,"tv":22.68,"id":13015345},{"batb":[[1,7,31.73],[2,6.4,14.48]],"batl":[[0,8.6,11.33]],"ltp":8.2,"tv":4.54,"id":13015344}]}]}
{"op":"mcm","clk":"1006502159","pt":1580648953841,"mc":[{"id":"1.168224553","rc":[{"batb":[[0,1.39,53.58],[1,1.01,0.51],[2,1.39,0]],"ltp":1.44,"tv":227.61,"id":12982356},{"batb":[[1,5.3,27.76],[2,1.01,0.51]],"ltp":5.9,"tv":33.6,"id":12982355},{"batb":[[0,1.01,0.51],[1,1.01,0]],"ltp":11.0,"tv":22.68,"id":13015345},{"batb":[[1,6.4,14.48],[2,1.01,0.51]],"ltp":8.2,"tv":4.54,"id":13015344}]}]}
{"op":"mcm","clk":"1006502646","pt":1580648957408,"mc":[{"id":"1.168224553","rc":[{"batb":[[0,1.45,71.44],[1,1.44,154.18],[2,1.43,97.46]],"batl":[[1,1.52,84.1]],"ltp":1.44,"tv":227.61,"id":12982356},{"batb":[[1,5.3,47.34],[2,5.2,28.96]],"batl":[[0,5.9,8.4],[1,6.6,19.43],[2,6.8,18.41]],"ltp":5.9,"tv":33.6,"id":12982355},{"batb":[[0,160,3.04],[1,1.01,0.51]],"ltp":11.0,"tv":22.68,"id":13015345},{"batb":[[1,7,31.73],[2,6.8,6.72]],"batl":[[0,7.8,13.61],[1,8.2,17.47],[2,8.6,11.33]],"ltp":8.2,"tv":4.54,"id":13015344}]}]}
{"op":"mcm","clk":"1006502679","pt":1580648957622,"mc":[{"id":"1.168224553","rc":[{"batl":[[2,6.8,0]],"ltp":5.9,"tv":33.6,"id":12982355},{"batl":[[2,8.6,0]],"ltp":8.2,"tv":4.54,"id":13015344}]}]}
{"op":"mcm","clk":"1006503499","pt":1580648963415,"mc":[{"id":"1.168224553","rc":[{"batb":[[0,1.43,97.46],[1,1.41,49.73],[2,1.01,0.51]],"batl":[[0,1.52,84.1],[1,1.52,0]],"ltp":1.44,"tv":227.61,"id":12982356},{"batb":[[0,5.3,11.49],[1,5.2,28.96],[2,5,10.08]],"ltp":5.9,"tv":33.6,"id":12982355},{"batb":[[0,1.01,0.51],[1,1.01,0]],"ltp":11.0,"tv":22.68,"id":13015345},{"batb":[[0,7,31.73],[1,6.8,6.72],[2,6.2,15.74]],"batl":[[0,8.2,17.47],[1,8.2,0]],"ltp":8.2,"tv":4.54,"id":13015344}]}]}
{"op":"mcm","clk":"1006503630","pt":1580648964314,"mc":[{"id":"1.168224553","rc":[{"batb":[[0,1.41,49.73],[1,1.01,0.51],[2,1.01,0]],"batl":[[0,1.52,42.09]],"ltp":1.44,"tv":227.61,"id":12982356},{"batb":[[2,1.01,0.51]],"batl":[[0,6.6,19.43],[1,6.6,0]],"ltp":5.9,"tv":33.6,"id":12982355},{"batb":[[1,6.2,15.74],[2,1.01,0.51]],"batl":[[0,8.2,12.43]],"ltp":8.2,"tv":4.54,"id":13015344}]}]}
{"op":"mcm","clk":"1006503890","pt":1580648966232,"mc":[{"id":"1.168224553","rc":[{"batb":[[0,1.42,177.92],[1,1.41,169.47],[2,1.01,0.51]],"ltp":1.44,"tv":227.61,"id":12982356},{"batb":[[1,5.2,40.77],[2,5.1,30.18]],"ltp":5.9,"tv":33.6,"id":12982355},{"batb":[[0,140,2.45],[1,130,2.55],[2,1.01,0.51]],"ltp":11.0,"tv":22.68,"id":13015345},{"batb":[[1,6.8,33.73],[2,6.2,15.74]],"ltp":8.2,"tv":4.54,"id":13015344}]}]}
{"op":"mcm","clk":"1006504001","pt":1580648967016,"mc":[{"id":"1.168224553","rc":[{"batb":[[0,1.41,49.73],[1,1.01,0.51],[2,1.01,0]],"ltp":1.44,"tv":227.61,"id":12982356},{"batb":[[1,5.2,28.96],[2,1.01,0.51]],"ltp":5.9,"tv":33.6,"id":12982355},{"batb":[[0,1.01,0.51],[1,130,0],[2,1.01,0]],"ltp":11.0,"tv":22.68,"id":13015345},{"batb":[[1,6.2,15.74],[2,1.01,0.51]],"ltp":8.2,"tv":4.54,"id":13015344}]}]}
{"op":"mcm","clk":"1006504460","pt":1580648970420,"mc":[{"id":"1.168224553","rc":[{"batb":[[0,1.44,134.27],[1,1.43,112.1],[2,1.41,49.73]],"ltp":1.44,"tv":227.61,"id":12982356},{"batb":[[0,5.3,54.02]],"ltp":5.9,"tv":33.6,"id":12982355},{"batb":[[0,170,2.45],[1,1.01,0.51]],"ltp":11.0,"tv":22.68,"id":13015345},{"batb":[[0,7.2,34.88],[1,7,31.73],[2,6.2,15.74]],"ltp":8.2,"tv":4.54,"id":13015344}]}]}
{"op":"mcm","clk":"1006504597","pt":1580648971444,"mc":[{"id":"1.168224553","rc":[{"batb":[[0,1.41,49.73],[1,1.01,0.51],[2,1.41,0]],"ltp":1.44,"tv":227.61,"id":12982356},{"batb":[[0,5.3,11.49]],"ltp":5.9,"tv":33.6,"id":12982355},{"batb":[[0,1.01,0.51],[1,1.01,0]],"ltp":11.0,"tv":22.68,"id":13015345},{"batb":[[0,7,31.73],[1,6.2,15.74],[2,1.01,0.51]],"ltp":8.2,"tv":4.54,"id":13015344}]}]}
{"op":"mcm","clk":"1006504992","pt":1580648974351,"mc":[{"id":"1.168224553","rc":[{"batb":[[0,1.42,177.92],[1,1.41,169.47],[2,1.01,0.51]],"ltp":1.44,"tv":227.61,"id":12982356},{"batb":[[1,5.2,40.77],[2,5.1,30.18]],"ltp":5.9,"tv":33.6,"id":12982355},{"batb":[[0,140,2.45],[1,130,2.55],[2,1.01,0.51]],"ltp":11.0,"tv":22.68,"id":13015345},{"batb":[[1,6.8,33.73],[2,6.2,15.74]],"ltp":8.2,"tv":4.54,"id":13015344}]}]}
{"op":"mcm","clk":"1006505142","pt":1580648975484,"mc":[{"id":"1.168224553","rc":[{"batb":[[1,1.01,0.51],[2,5.1,0]],"ltp":5.9,"tv":33.6,"id":12982355},{"batb":[[0,1.01,0.51],[1,130,0],[2,1.01,0]],"ltp":11.0,"tv":22.68,"id":13015345},{"batb":[[0,6.2,15.74],[1,1.01,0.51],[2,6.2,0]],"ltp":8.2,"tv":4.54,"id":13015344}]}]}
{"op":"mcm","clk":"1006505545","pt":1580648978332,"mc":[{"id":"1.168224553","rc":[{"batb":[[0,5.4,40.73],[1,5.3,39.15],[2,1.01,0.51]],"ltp":5.9,"tv":33.6,"id":12982355},{"batb":[[0,7.4,36.39],[1,7.2,29.63],[2,6.2,15.74]],"ltp":8.2,"tv":4.54,"id":13015344}]}]}
{"op":"mcm","clk":"1006505675","pt":1580648979347,"mc":[{"id":"1.168224553","rc":[{"batb":[[0,1.42,277.9],[2,1.38,54.84]],"batl":[[0,1.47,48.23],[1,1.5,44.93],[2,1.51,42.01]],"ltp":1.44,"tv":227.61,"id":12982356},{"batb":[[0,5.5,10.46],[1,5.4,51.67],[2,5.3,27.66]],"batl":[[0,6,8.4],[1,6.6,19.43],[2,6.8,18.02]],"ltp":5.9,"tv":33.6,"id":12982355},{"batb":[[2,7,6.72]],"batl":[[1,8.4,5.04],[2,8.8,11.02]],"ltp":8.2,"tv":4.54,"id":13015344}]}]}
{"op":"mcm","clk":"1006507467","pt":1580648992351,"mc":[{"id":"1.168224553","rc":[{"batb":[[0,1.38,54.84],[1,1.01,0.51],[2,1.38,0]],"batl":[[0,1.5,44.93],[1,1.5,0],[2,1.51,0]],"ltp":1.44,"tv":227.61,"id":12982356},{"batb":[[0,5.4,10.94],[1,5.3,27.66],[2,1.01,0.51]],"batl":[[0,6.8,18.02],[1,6.6,0],[2,6.8,0]],"ltp":5.9,"tv":33.6,"id":12982355},{"batb":[[0,7.2,29.63],[1,6.6,14.24],[2,1.01,0.51]],"batl":[[0,8.8,11.02],[1,8.4,0],[2,8.8,0]],"ltp":8.2,"tv":4.54,"id":13015344}]}]}
{"op":"mcm","clk":"1006507908","pt":1580648995405,"mc":[{"id":"1.168224553","rc":[{"batb":[[0,1.4,144.7],[1,1.39,127.47],[2,1.38,54.84]],"ltp":1.44,"tv":227.61,"id":12982356},{"batb":[[1,5.3,40.12],[2,5.2,28.89]],"ltp":5.9,"tv":33.6,"id":12982355},{"batb":[[0,160,2.03],[1,150,2.33],[2,1.01,0.51]],"ltp":11.0,"tv":22.68,"id":13015345},{"batb":[[1,7,31.56],[2,6.6,14.24]],"ltp":8.2,"tv":4.54,"id":13015344}]}]}
{"op":"mcm","clk":"1006508022","pt":1580648996171,"mc":[{"id":"1.168224553","rc":[{"batb":[[0,1.38,54.84],[1,1.01,0.51],[2,1.38,0]],"ltp":1.44,"tv":227.61,"id":12982356},{"batb":[[1,1.01,0.51],[2,5.2,0]],"ltp":5.9,"tv":33.6,"id":12982355},{"batb":[[0,1.01,0.51],[1,150,0],[2,1.01,0]],"ltp":11.0,"tv":22.68,"id":13015345},{"batb":[[0,6.6,14.24],[1,1.01,0.51],[2,6.6,0]],"ltp":8.2,"tv":4.54,"id":13015344}]}]}
{"op":"mcm","clk":"1006508494","pt":1580648999382,"mc":[{"id":"1.168224553","rc":[{"batb":[[0,1.42,123.35],[1,1.41,119.23],[2,1.38,54.84]],"ltp":1.44,"tv":227.61,"id":12982356},{"batb":[[0,5.5,21.13],[1,5.4,37.75],[2,1.01,0.51]],"ltp":5.9,"tv":33.6,"id":12982355},{"batb":[[0,7.6,16.21],[1,7.4,28.38],[2,6.6,14.24]],"ltp":8.2,"tv":4.54,"id":13015344}]}]}
{"op":"mcm","clk":"1006508892","pt":1580649002390,"mc":[{"id":"1.168224553","rc":[{"batb":[[0,1.38,54.84],[1,1.01,0.51],[2,1.38,0]],"ltp":1.44,"tv":227.61,"id":12982356},{"batb":[[0,5.4,10.94],[1,1.01,0.51],[2,1.01,0]],"ltp":5.9,"tv":33.6,"id":12982355},{"batb":[[0,6.6,14.24],[1,1.01,0.51],[2,6.6,0]],"ltp":8.2,"tv":4.54,"id":13015344}]}]}
{"op":"mcm","clk":"1006509217","pt":1580649004695,"mc":[{"id":"1.168224553","rc":[{"batb":[[0,1.4,144.7],[1,1.39,127.47],[2,1.38,54.84]],"ltp":1.44,"tv":227.61,"id":12982356},{"batb":[[1,5.3,40.12],[2,5.2,28.89]],"ltp":5.9,"tv":33.6,"id":12982355},{"batb":[[0,160,2.03],[1,150,2.33],[2,1.01,0.51]],"ltp":11.0,"tv":22.68,"id":13015345},{"batb":[[0,7.2,34],[1,7,31.56],[2,6.6,14.24]],"ltp":8.2,"tv":4.54,"id":13015344}]}]}
{"op":"mcm","clk":"1006510016","pt":1580649010417,"mc":[{"id":"1.168224553","rc":[{"batb":[[0,1.38,54.84],[1,1.01,0.51],[2,1.38,0]],"ltp":1.44,"tv":227.61,"id":12982356}]}]}
{"op":"mcm","clk":"1006510461","pt":1580649013302,"mc":[{"id":"1.168224553","rc":[{"batb":[[0,1.44,152.48],[1,1.43,209.71],[2,1.38,54.84]],"batl":[[1,1.51,42.01]],"ltp":1.44,"tv":227.61,"id":12982356},{"batl":[[0,6,8.4],[1,6.8,18.02]],"ltp":5.9,"tv":33.6,"id":12982355},{"batb":[[2,6.8,6.72]],"batl":[[0,8.4,5.04],[1,8.8,11.02]],"ltp":8.2,"tv":4.54,"id":13015344}]}]}
{"op":"mcm","clk":"1006510559","pt":1580649014003,"mc":[{"id":"1.168224553","rc":[{"batb":[[1,1.43,255.9],[2,1.41,49.65]],"batl":[[2,1.52,42.33]],"ltp":1.44,"tv":227.61,"id":12982356},{"batb":[[1,5.3,51.61]],"batl":[[1,6.6,19.59]],"ltp":5.9,"tv":33.6,"id":12982355},{"batl":[[0,8,13.45],[1,8.2,12.35],[2,8.4,5.04]],"ltp":8.2,"tv":4.54,"id":13015344}]}]}
{"op":"mcm","clk":"1006512907","pt":1580649029329,"mc":[{"id":"1.168224553","rc":[{"batb":[[0,1.43,97.46],[1,1.41,49.65],[2,1.01,0.51]],"batl":[[0,1.51,42.01],[1,1.52,42.33],[2,1.52,0]],"ltp":1.44,"tv":227.61,"id":12982356},{"batb":[[0,5.3,11.49],[1,5.2,28.89],[2,5,10.08]],"ltp":5.9,"tv":33.6,"id":12982355},{"batb":[[0,1.01,0.51],[1,150,0],[2,1.01,0]],"ltp":11.0,"tv":22.68,"id":13015345},{"batb":[[0,7,31.56],[1,6.8,6.72],[2,6.4,15.42]],"batl":[[0,8.2,12.35],[1,8.4,5.04],[2,8.4,0]],"ltp":8.2,"tv":4.54,"id":13015344}]}]}
{"op":"mcm","clk":"1006513083","pt":1580649030349,"mc":[{"id":"1.168224553","rc":[{"batb":[[0,1.41,49.65],[1,1.01,0.51],[2,1.01,0]],"batl":[[0,1.52,42.33],[1,1.52,0]],"ltp":1.44,"tv":227.61,"id":12982356},{"batb":[[2,1.01,0.51]],"batl":[[0,6.6,19.59],[1,6.6,0]],"ltp":5.9,"tv":33.6,"id":12982355},{"batb":[[1,6.4,15.42],[2,1.01,0.51]],"batl":[[1,8.4,0]],"ltp":8.2,"tv":4.54,"id":13015344}]}]}
{"op":"mcm","clk":"1006513443","pt":1580649032417,"mc":[{"id":"1.168224553","rc":[{"batb":[[0,1.42,146.95],[1,1.41,169.11],[2,1.01,0.51]],"ltp":1.44,"tv":227.61,"id":12982356},{"batb":[[1,5.2,44.79],[2,5.1,30.13]],"ltp":5.9,"tv":33.6,"id":12982355},{"batb":[[0,130,4.09],[1,1.01,0.51]],"ltp":11.0,"tv":22.68,"id":13015345},{"batb":[[0,7,36.66],[1,6.8,33.55],[2,6.4,15.42]],"ltp":8.2,"tv":4.54,"id":13015344}]}]}
{"op":"mcm","clk":"1006513493","pt":1580649032749,"mc":[{"id":"1.168224553","rc":[{"batb":[[0,1.41,49.65],[1,1.01,0.51],[2,1.01,0]],"ltp":1.44,"tv":227.61,"id":12982356},{"batb":[[1,5.2,28.89],[2,1.01,0.51]],"ltp":5.9,"tv":33.6,"id":12982355},{"batb":[[0,1.01,0.51],[1,1.01,0]],"ltp":11.0,"tv":22.68,"id":13015345},{"batb":[[0,7,31.56],[1,6.4,15.42],[2,1.01,0.51]],"ltp":8.2,"tv":4.54,"id":13015344}]}]}
{"op":"mcm","clk":"1006514872","pt":1580649041347,"mc":[{"id":"1.168224553","rc":[{"batb":[[0,1.42,146.95],[1,1.41,169.11],[2,1.01,0.51]],"ltp":1.44,"tv":227.61,"id":12982356},{"batb":[[1,1.01,0.51],[2,1.01,0]],"ltp":5.9,"tv":33.6,"id":12982355},{"batb":[[0,6.4,15.42],[1,1.01,0.51],[2,1.01,0]],"ltp":8.2,"tv":4.54,"id":13015344}]}]}
{"op":"mcm","clk":"1006515353","pt":1580649044349,"mc":[{"id":"1.168224553","rc":[{"batb":[[2,1.38,54.53]],"batl":[[0,1.47,48.15],[1,1.5,44.93]],"ltp":1.44,"tv":227.61,"id":12982356},{"batb":[[0,5.5,10.54],[1,5.4,56.18],[2,5.3,27.59]],"batl":[[1,6.8,18.1]],"ltp":5.9,"tv":33.6,"id":12982355},{"batb":[[0,7.6,13.69],[1,7.4,28.44],[2,6.8,13.14]],"batl":[[1,8.6,11.17]],"ltp":8.2,"tv":4.54,"id":13015344}]}]}
{"op":"mcm","clk":"1006515506","pt":1580649045333,"mc":[{"id":"1.168224553","rc":[{"batb":[[0,1.42,246.93]],"batl":[[1,1.5,86.94]],"ltp":1.44,"tv":227.61,"id":12982356},{"batl":[[0,6,8.4],[1,6.6,19.59],[2,6.8,18.1]],"ltp":5.9,"tv":33.6,"id":12982355},{"batb":[[2,7,6.72]],"batl":[[1,8.4,5.04],[2,8.6,11.17]],"ltp":8.2,"tv":4.54,"id":13015344}]}]}
{"op":"mcm","clk":"1006516933","pt":1580649055459,"mc":[{"id":"1.168224553","rc":[{"batb":[[0,1.42,99.98],[1,1.38,54.53],[2,1.01,0.51]],"batl":[[0,1.5,86.94],[1,1.5,0]],"ltp":1.44,"tv":227.61,"id":12982356},{"batb":[[0,5.4,10.94],[1,5.3,27.59],[2,5.1,10.08]],"batl":[[1,6.8,18.1],[2,6.8,0]],"ltp":5.9,"tv":33.6,"id":12982355},{"batb":[[0,7,6.72],[1,6.6,14.32],[2,1.01,0.51]],"batl":[[0,8.4,5.04],[1,8.6,11.17],[2,8.6,0]],"ltp":8.2,"tv":4.54,"id":13015344}]}]}
{"op":"mcm","clk":"1006517074","pt":1580649056473,"mc":[{"id":"1.168224553","rc":[{"batb":[[0,1.38,54.53],[1,1.01,0.51],[2,1.01,0]],"batl":[[0,1.5,44.93]],"ltp":1.44,"tv":227.61,"id":12982356},{"batb":[[2,1.01,0.51]],"batl":[[0,6.8,18.1],[1,6.8,0]],"ltp":5.9,"tv":33.6,"id":12982355},{"batb":[[0,6.6,14.32],[1,1.01,0.51],[2,1.01,0]],"batl":[[0,8.6,11.17],[1,8.6,0]],"ltp":8.2,"tv":4.54,"id":13015344}]}]}
{"op":"mcm","clk":"1006517359","pt":1580649058358,"mc":[{"id":"1.168224553","rc":[{"batb":[[0,1.4,113.36],[1,1.39,127.15],[2,1.38,54.53]],"ltp":1.44,"tv":227.61,"id":12982356},{"batb":[[1,5.3,44.51],[2,5.2,28.83]],"ltp":5.9,"tv":33.6,"id":12982355},{"batb":[[0,160,2.43],[1,1.01,0.51]],"ltp":11.0,"tv":22.68,"id":13015345},{"batb":[[0,7.2,40.12],[1,7,31.42],[2,6.6,14.32]],"ltp":8.2,"tv":4.54,"id":13015344}]}]}
{"op":"mcm","clk":"1006517499","pt":1580649059384,"mc":[{"id":"1.168224553","rc":[{"batb":[[0,1.38,54.53],[1,1.01,0.51],[2,1.38,0]],"ltp":1.44,"tv":227.61,"id":12982356},{"batb":[[1,1.01,0.51],[2,5.2,0]],"ltp":5.9,"tv":33.6,"id":12982355},{"batb":[[0,1.01,0.51],[1,1.01,0]],"ltp":11.0,"tv":22.68,"id":13015345},{"batb":[[0,6.6,14.32],[1,1.01,0.51],[2,6.6,0]],"ltp":8.2,"tv":4.54,"id":13015344}]}]}
{"op":"mcm","clk":"1006517985","pt":1580649062475,"mc":[{"id":"1.168224553","rc":[{"batb":[[0,1.42,92.66],[1,1.41,118.95],[2,1.38,54.53]],"ltp":1.44,"tv":227.61,"id":12982356},{"batb":[[0,5.5,25.63],[1,5.4,37.68],[2,1.01,0.51]],"ltp":5.9,"tv":33.6,"id":12982355},{"batb":[[0,7.6,22.28],[1,7.4,28.25],[2,6.6,14.32]],"ltp":8.2,"tv":4.54,"id":13015344}]}]}
{"op":"mcm","clk":"1006518326","pt":1580649064481,"mc":[{"id":"1.168224553","rc":[{"batb":[[0,1.38,54.53],[1,1.01,0.51],[2,1.38,0]],"ltp":1.44,"tv":227.61,"id":12982356},{"batb":[[0,5.4,10.94],[1,1.01,0.51],[2,1.01,0]],"ltp":5.9,"tv":33.6,"id":12982355},{"batb":[[0,6.6,14.32],[1,1.01,0.51],[2,6.6,0]],"ltp":8.2,"tv":4.54,"id":13015344}]}]}
{"op":"mcm","clk":"1006518757","pt":1580649067361,"mc":[{"id":"1.168224553","rc":[{"batb":[[0,1.4,113.36],[1,1.39,127.15],[2,1.38,54.53]],"ltp":1.44,"tv":227.61,"id":12982356},{"batb":[[1,5.3,44.51],[2,5.2,28.83]],"ltp":5.9,"tv":33.6,"id":12982355},{"batb":[[0,160,2.43],[1,1.01,0.51]],"ltp":11.0,"tv":22.68,"id":13015345},{"batb":[[0,7.2,40.12],[1,7,31.42],[2,6.6,14.32]],"ltp":8.2,"tv":4.54,"id":13015344}]}]}
{"op":"mcm","clk":"1006519838","pt":1580649074373,"mc":[{"id":"1.168224553","rc":[{"batb":[[1,1.01,0.51],[2,5.2,0]],"ltp":5.9,"tv":33.6,"id":12982355},{"batb":[[0,1.01,0.51],[1,1.01,0]],"ltp":11.0,"tv":22.68,"id":13015345},{"batb":[[0,6.6,14.32],[1,1.01,0.51],[2,6.6,0]],"ltp":8.2,"tv":4.54,"id":13015344}]}]}
{"op":"mcm","clk":"1006520266","pt":1580649077390,"mc":[{"id":"1.168224553","rc":[{"batb":[[0,1.41,101.66],[1,1.4,113.36],[2,1.39,127.15]],"batl":[[0,1.44,52.8],[1,1.47,48.15],[2,1.49,42.01]],"ltp":1.44,"tv":227.61,"id":12982356},{"batb":[[0,5.7,19.36],[1,5.6,29.83],[2,5.5,36.06]],"batl":[[0,6,8.4],[1,6.8,18.1],[2,7.2,16.21]],"ltp":5.9,"tv":33.6,"id":12982355},{"batb":[[0,7.8,29.28],[1,7.6,26.52],[2,7.2,18.45]],"batl":[[1,8.8,5.04],[2,9.4,9.52]],"ltp":8.2,"tv":4.54,"id":13015344}]}]}
{"op":"mcm","clk":"1006522856","pt":1580649095323,"mc":[{"id":"1.168224553","rc":[{"batb":[[1,1.38,54.53],[2,1.34,61.77]],"ltp":1.44,"tv":227.61,"id":12982356},{"batb":[[1,5.5,36.06],[2,5.1,10.08]],"ltp":5.9,"tv":33.6,"id":12982355},{"batb":[[0,7.6,18.31],[1,7.2,18.45],[2,6.8,13.22]],"ltp":8.2,"tv":4.54,"id":13015344}]}]}
{"op":"mcm","clk":"1006522894","pt":1580649095614,"mc":[{"id":"1.168224553","rc":[{"batb":[[1,1.34,61.77],[2,1.01,0.51]],"batl":[[0,1.47,48.15],[1,1.49,42.01],[2,1.49,0]],"ltp":1.44,"tv":227.61,"id":12982356},{"batb":[[0,5.5,36.06],[1,5.1,10.08],[2,1.01,0.51]],"batl":[[1,7.2,16.21],[2,7.2,0]],"ltp":5.9,"tv":33.6,"id":12982355},{"batb":[[1,7.2,6.72]],"batl":[[0,8.8,5.04],[1,9.4,9.52],[2,9.4,0]],"ltp":8.2,"tv":4.54,"id":13015344}]}]}
{"op":"mcm","clk":"1006523170","pt":1580649097321,"mc":[{"id":"1.168224553","rc":[{"batb":[[0,1.34,61.77],[1,1.01,0.51],[2,1.01,0]],"batl":[[1,1.49,0]],"ltp":1.44,"tv":227.61,"id":12982356},{"batb":[[1,1.01,0.51],[2,1.01,0]],"batl":[[0,7.2,16.21],[1,7.2,0]],"ltp":5.9,"tv":33.6,"id":12982355},{"batb":[[1,6.8,13.22],[2,1.01,0.51]],"batl":[[0,9.4,9.52],[1,9.4,0]],"ltp":8.2,"tv":4.54,"id":13015344}]}]}
{"op":"mcm","clk":"1006523377","pt":1580649098401,"mc":[{"id":"1.168224553","rc":[{"batb":[[0,1.37,171.34],[1,1.36,141.4],[2,1.34,61.77]],"ltp":1.44,"tv":227.61,"id":12982356},{"batb":[[1,5.4,26.8],[2,1.01,0.51]],"ltp":5.9,"tv":33.6,"id":12982355},{"batb":[[1,7.4,28.33],[2,6.8,13.22]],"ltp":8.2,"tv":4.54,"id":13015344}]}]}
