{"op":"mcm","clk":"1001179394","pt":1580585281138,"mc":[{"id":"1.168224555","marketDefinition":{"bspMarket":false,"turnInPlayEnabled":true,"persistenceEnabled":true,"marketBaseRate":5.0,"eventId":"29681742","eventTypeId":"2","numberOfWinners":1,"bettingType":"ODDS","marketType":"SET_WINNER","marketTime":"2020-02-02T09:00:00.000Z","suspendTime":"2020-02-02T09:00:00.000Z","bspReconciled":false,"complete":true,"inPlay":false,"crossMatching":false,"runnersVoidable":false,"numberOfActiveRunners":2,"betDelay":0,"status":"OPEN","runners":[{"status":"ACTIVE","sortPriority":1,"id":7414058,"name":"Damir Dzumhur"},{"status":"ACTIVE","sortPriority":2,"id":7287690,"name":"Quentin Halys"}],"regulators":["MR_INT"],"countryCode":"FR","discountAllowed":false,"timezone":"UTC","openDate":"2020-02-02T09:00:00.000Z","version":3147098920,"name":"Set 2 Winner","eventName":"Dzumhur v Halys"},"rc":[{"batb":[[0,1.01,20]],"ltp":0.0,"tv":0.0,"id":7287690},{"batb":[[0,1.01,20]],"ltp":0.0,"tv":0.0,"id":7414058}]}]}
{"op":"mcm","clk":"1001179667","pt":1580585282545,"mc":[{"id":"1.168224555","marketDefinition":{"bspMarket":false,"turnInPlayEnabled":true,"persistenceEnabled":true,"marketBaseRate":5.0,"eventId":"29681742","eventTypeId":"2","numberOfWinners":1,"bettingType":"ODDS","marketType":"SET_WINNER","marketTime":"2020-02-02T09:00:00.000Z","suspendTime":"2020-02-02T09:00:00.000Z","bspReconciled":false,"complete":true,"inPlay":false,"crossMatching":false,"runnersVoidable":false,"numberOfActiveRunners":2,"betDelay":0,"status":"OPEN","runners":[{"status":"ACTIVE","sortPriority":1,"id":7414058,"name":"Damir Dzumhur"},{"status":"ACTIVE","sortPriority":2,"id":7287690,"name":"Quentin Halys"}],"regulators":["MR_INT"],"countryCode":"FR","discountAllowed":false,"timezone":"UTC","openDate":"2020-02-02T09:00:00.000Z","version":3147098920,"name":"Set 2 Winner","eventName":"Dzumhur v Halys"}}]}
{"op":"mcm","clk":"1001179866","pt":1580585283504,"mc":[{"id":"1.168224555","marketDefinition":{"bspMarket":false,"turnInPlayEnabled":true,"persistenceEnabled":true,"marketBaseRate":5.0,"eventId":"29681742","eventTypeId":"2","numberOfWinners":1,"bettingType":"ODDS","marketType":"SET_WINNER","marketTime":"2020-02-02T09:00:00.000Z","suspendTime":"2020-02-02T09:00:00.000Z","bspReconciled":false,"complete":true,"inPlay":false,"crossMatching":false,"runnersVoidable":false,"numberOfActiveRunners":2,"betDelay":0,"status":"OPEN","runners":[{"status":"ACTIVE","sortPriority":1,"id":7414058,"name":"Damir Dzumhur"},{"status":"ACTIVE","sortPriority":2,"id":7287690,"name":"Quentin Halys"}],"regulators":["MR_INT"],"countryCode":"FR","discountAllowed":true,"timezone":"UTC","openDate":"2020-02-02T09:00:00.000Z","version":3147098920,"name":"Set 2 Winner","eventName":"Dzumhur v Halys"}}]}
{"op":"mcm","clk":"1001205068","pt":1580585420100,"mc":[{"id":"1.168224555","rc":[{"batb":[[0,1.01,15]],"ltp":0.0,"tv":0.0,"id":7287690},{"batb":[[0,1.01,15]],"ltp":0.0,"tv":0.0,"id":7414058}]}]}
{"op":"mcm","clk":"1001222203","pt":1580585513427,"mc":[{"id":"1.168224555","marketDefinition":{"bspMarket":false,"turnInPlayEnabled":true,"persistenceEnabled":true,"marketBaseRate":5.0,"eventId":"29681742","eventTypeId":"2","numberOfWinners":1,"bettingType":"ODDS","marketType":"SET_WINNER","marketTime":"2020-02-02T13:30:00.000Z","suspendTime":"2020-02-02T13:30:00.000Z","bspReconciled":false,"complete":true,"inPlay":false,"crossMatching":false,"runnersVoidable":false,"numberOfActiveRunners":2,"betDelay":0,"status":"OPEN","runners":[{"status":"ACTIVE","sortPriority":1,"id":7414058,"name":"Damir Dzumhur"},{"status":"ACTIVE","sortPriority":2,"id":7287690,"name":"Quentin Halys"}],"regulators":["MR_INT"],"countryCode":"FR","discountAllowed":true,"timezone":"UTC","openDate":"2020-02-02T09:00:00.000Z","version":3147124723,"name":"Set 2 Winner","eventName":"Dzumhur v Halys"}}]}
{"op":"mcm","clk":"1001222802","pt":1580585516439,"mc":[{"id":"1.168224555","marketDefinition":{"bspMarket":false,"turnInPlayEnabled":true,"persistenceEnabled":true,"marketBaseRate":5.0,"eventId":"29681742","eventTypeId":"2","numberOfWinners":1,"bettingType":"ODDS","marketType":"SET_WINNER","marketTime":"2020-02-02T13:30:00.000Z","suspendTime":"2020-02-02T13:30:00.000Z","bspReconciled":false,"complete":true,"inPlay":false,"crossMatching":false,"runnersVoidable":false,"numberOfActiveRunners":2,"betDelay":0,"status":"OPEN","runners":[{"status":"ACTIVE","sortPriority":1,"id":7414058,"name":"Damir Dzumhur"},{"status":"ACTIVE","sortPriority":2,"id":7287690,"name":"Quentin Halys"}],"regulators":["MR_INT"],"countryCode":"FR","discountAllowed":true,"timezone":"UTC","openDate":"2020-02-02T13:30:00.000Z","version":3147124723,"name":"Set 2 Winner","eventName":"Dzumhur v Halys"}}]}
{"op":"mcm","clk":"1003032822","pt":1580602188482,"mc":[{"id":"1.168224555","rc":[{"batb":[[0,1.01,15.51]],"ltp":0.0,"tv":0.0,"id":7287690},{"batb":[[0,1.01,15.51]],"ltp":0.0,"tv":0.0,"id":7414058}]}]}
{"op":"mcm","clk":"1003160539","pt":1580603728152,"mc":[{"id":"1.168224555","rc":[{"batb":[[0,1.01,16.01]],"ltp":0.0,"tv":0.0,"id":7287690},{"batb":[[0,1.01,16.01]],"ltp":0.0,"tv":0.0,"id":7414058}]}]}
{"op":"mcm","clk":"1004691847","pt":1580635314870,"mc":[{"id":"1.168224555","marketDefinition":{"bspMarket":false,"turnInPlayEnabled":true,"persistenceEnabled":true,"marketBaseRate":5.0,"eventId":"29681742","eventTypeId":"2","numberOfWinners":1,"bettingType":"ODDS","marketType":"SET_WINNER","marketTime":"2020-02-02T13:19:00.000Z","suspendTime":"2020-02-02T13:19:00.000Z","bspReconciled":false,"complete":true,"inPlay":false,"crossMatching":false,"runnersVoidable":false,"numberOfActiveRunners":2,"betDelay":0,"status":"OPEN","runners":[{"status":"ACTIVE","sortPriority":1,"id":7414058,"name":"Damir Dzumhur"},{"status":"ACTIVE","sortPriority":2,"id":7287690,"name":"Quentin Halys"}],"regulators":["MR_INT"],"countryCode":"FR","discountAllowed":true,"timezone":"UTC","openDate":"2020-02-02T13:30:00.000Z","version":3148342680,"name":"Set 2 Winner","eventName":"Dzumhur v Halys"}}]}
{"op":"mcm","clk":"1004692024","pt":1580635317913,"mc":[{"id":"1.168224555","marketDefinition":{"bspMarket":false,"turnInPlayEnabled":true,"persistenceEnabled":true,"marketBaseRate":5.0,"eventId":"29681742","eventTypeId":"2","numberOfWinners":1,"bettingType":"ODDS","marketType":"SET_WINNER","marketTime":"2020-02-02T13:19:00.000Z","suspendTime":"2020-02-02T13:19:00.000Z","bspReconciled":false,"complete":true,"inPlay":false,"crossMatching":false,"runnersVoidable":false,"numberOfActiveRunners":2,"betDelay":0,"status":"OPEN","runners":[{"status":"ACTIVE","sortPriority":1,"id":7414058,"name":"Damir Dzumhur"},{"status":"ACTIVE","sortPriority":2,"id":7287690,"name":"Quentin Halys"}],"regulators":["MR_INT"],"countryCode":"FR","discountAllowed":true,"timezone":"UTC","openDate":"2020-02-02T13:19:00.000Z","version":3148342680,"name":"Set 2 Winner","eventName":"Dzumhur v Halys"}}]}
{"op":"mcm","clk":"1005237073","pt":1580641614817,"mc":[{"id":"1.168224555","marketDefinition":{"bspMarket":false,"turnInPlayEnabled":true,"persistenceEnabled":true,"marketBaseRate":5.0,"eventId":"29681742","eventTypeId":"2","numberOfWinners":1,"bettingType":"ODDS","marketType":"SET_WINNER","marketTime":"2020-02-02T13:10:00.000Z","suspendTime":"2020-02-02T13:10:00.000Z","bspReconciled":false,"complete":true,"inPlay":false,"crossMatching":false,"runnersVoidable":false,"numberOfActiveRunners":2,"betDelay":0,"status":"OPEN","runners":[{"status":"ACTIVE","sortPriority":1,"id":7414058,"name":"Damir Dzumhur"},{"status":"ACTIVE","sortPriority":2,"id":7287690,"name":"Quentin Halys"}],"regulators":["MR_INT"],"countryCode":"FR","discountAllowed":true,"timezone":"UTC","openDate":"2020-02-02T13:19:00.000Z","version":3148499229,"name":"Set 2 Winner","eventName":"Dzumhur v Halys"}}]}
{"op":"mcm","clk":"1005237509","pt":1580641616832,"mc":[{"id":"1.168224555","marketDefinition":{"bspMarket":false,"turnInPlayEnabled":true,"persistenceEnabled":true,"marketBaseRate":5.0,"eventId":"29681742","eventTypeId":"2","numberOfWinners":1,"bettingType":"ODDS","marketType":"SET_WINNER","marketTime":"2020-02-02T13:10:00.000Z","suspendTime":"2020-02-02T13:10:00.000Z","bspReconciled":false,"complete":true,"inPlay":false,"crossMatching":false,"runnersVoidable":false,"numberOfActiveRunners":2,"betDelay":0,"status":"OPEN","runners":[{"status":"ACTIVE","sortPriority":1,"id":7414058,"name":"Damir Dzumhur"},{"status":"ACTIVE","sortPriority":2,"id":7287690,"name":"Quentin Halys"}],"regulators":["MR_INT"],"countryCode":"FR","discountAllowed":true,"timezone":"UTC","openDate":"2020-02-02T13:10:00.000Z","version":3148499229,"name":"Set 2 Winner","eventName":"Dzumhur v Halys"}}]}
{"op":"mcm","clk":"1005295374","pt":1580641914620,"mc":[{"id":"1.168224555","marketDefinition":{"bspMarket":false,"turnInPlayEnabled":true,"persistenceEnabled":true,"marketBaseRate":5.0,"eventId":"29681742","eventTypeId":"2","numberOfWinners":1,"bettingType":"ODDS","marketType":"SET_WINNER","marketTime":"2020-02-02T13:08:00.000Z","suspendTime":"2020-02-02T13:08:00.000Z","bspReconciled":false,"complete":true,"inPlay":false,"crossMatching":false,"runnersVoidable":false,"numberOfActiveRunners":2,"betDelay":0,"status":"OPEN","runners":[{"status":"ACTIVE","sortPriority":1,"id":7414058,"name":"Damir Dzumhur"},{"status":"ACTIVE","sortPriority":2,"id":7287690,"name":"Quentin Halys"}],"regulators":["MR_INT"],"countryCode":"FR","discountAllowed":true,"timezone":"UTC","openDate":"2020-02-02T13:10:00.000Z","version":3148508354,"name":"Set 2 Winner","eventName":"Dzumhur v Halys"}}]}
{"op":"mcm","clk":"1005295947","pt":1580641917627,"mc":[{"id":"1.168224555","marketDefinition":{"bspMarket":false,"turnInPlayEnabled":true,"persistenceEnabled":true,"marketBaseRate":5.0,"eventId":"29681742","eventTypeId":"2","numberOfWinners":1,"bettingType":"ODDS","marketType":"SET_WINNER","marketTime":"2020-02-02T13:08:00.000Z","suspendTime":"2020-02-02T13:08:00.000Z","bspReconciled":false,"complete":true,"inPlay":false,"crossMatching":false,"runnersVoidable":false,"numberOfActiveRunners":2,"betDelay":0,"status":"OPEN","runners":[{"status":"ACTIVE","sortPriority":1,"id":7414058,"name":"Damir Dzumhur"},{"status":"ACTIVE","sortPriority":2,"id":7287690,"name":"Quentin Halys"}],"regulators":["MR_INT"],"countryCode":"FR","discountAllowed":true,"timezone":"UTC","openDate":"2020-02-02T13:08:00.000Z","version":3148508354,"name":"Set 2 Winner","eventName":"Dzumhur v Halys"}}]}
{"op":"mcm","clk":"1006121905","pt":1580646610461,"mc":[{"id":"1.168224555","rc":[{"batb":[[0,2.34,17.62],[1,1.01,16.01]],"ltp":0.0,"tv":0.0,"id":7287690},{"batb":[[0,1.65,26.59],[1,1.01,16.01]],"ltp":0.0,"tv":0.0,"id":7414058}]}]}
{"op":"mcm","clk":"1006123236","pt":1580646618283,"mc":[{"id":"1.168224555","rc":[{"batb":[[0,2.36,17.62],[1,2.34,17.62],[2,1.01,16.01]],"ltp":0.0,"tv":0.0,"id":7287690}]}]}
{"op":"mcm","clk":"1006123335","pt":1580646618882,"mc":[{"id":"1.168224555","rc":[{"batb":[[1,1.01,16.01],[2,1.01,0]],"ltp":0.0,"tv":0.0,"id":7287690}]}]}
{"op":"mcm","clk":"1006126042","pt":1580646634123,"mc":[{"id":"1.168224555","rc":[{"batb":[[0,1.64,26.67]],"ltp":0.0,"tv":0.0,"id":7414058}]}]}
{"op":"mcm","clk":"1006140282","pt":1580646714573,"mc":[{"id":"1.168224555","marketDefinition":{"bspMarket":false,"turnInPlayEnabled":true,"persistenceEnabled":true,"marketBaseRate":5.0,"eventId":"29681742","eventTypeId":"2","numberOfWinners":1,"bettingType":"ODDS","marketType":"SET_WINNER","marketTime":"2020-02-02T12:28:00.000Z","suspendTime":"2020-02-02T12:28:00.000Z","bspReconciled":false,"complete":true,"inPlay":false,"crossMatching":false,"runnersVoidable":false,"numberOfActiveRunners":2,"betDelay":0,"status":"OPEN","runners":[{"status":"ACTIVE","sortPriority":1,"id":7414058,"name":"Damir Dzumhur"},{"status":"ACTIVE","sortPriority":2,"id":7287690,"name":"Quentin Halys"}],"regulators":["MR_INT"],"countryCode":"FR","discountAllowed":true,"timezone":"UTC","openDate":"2020-02-02T13:08:00.000Z","version":3148727323,"name":"Set 2 Winner","eventName":"Dzumhur v Halys"}}]}
{"op":"mcm","clk":"1006141082","pt":1580646718562,"mc":[{"id":"1.168224555","marketDefinition":{"bspMarket":false,"turnInPlayEnabled":true,"persistenceEnabled":true,"marketBaseRate":5.0,"eventId":"29681742","eventTypeId":"2","numberOfWinners":1,"bettingType":"ODDS","marketType":"SET_WINNER","marketTime":"2020-02-02T12:28:00.000Z","suspendTime":"2020-02-02T12:28:00.000Z","bspReconciled":false,"complete":true,"inPlay":false,"crossMatching":false,"runnersVoidable":false,"numberOfActiveRunners":2,"betDelay":0,"status":"OPEN","runners":[{"status":"ACTIVE","sortPriority":1,"id":7414058,"name":"Damir Dzumhur"},{"status":"ACTIVE","sortPriority":2,"id":7287690,"name":"Quentin Halys"}],"regulators":["MR_INT"],"countryCode":"FR","discountAllowed":true,"timezone":"UTC","openDate":"2020-02-02T12:28:00.000Z","version":3148727323,"name":"Set 2 Winner","eventName":"Dzumhur v Halys"}}]}
{"op":"mcm","clk":"1006185677","pt":1580646959872,"mc":[{"id":"1.168224555","rc":[{"batb":[[0,2.36,47.87]],"batl":[[0,2.68,24.37]],"ltp":0.0,"tv":0.0,"id":7287690},{"batb":[[1,1.6,69.74],[2,1.01,16.01]],"batl":[[0,1.74,42.01]],"ltp":0.0,"tv":0.0,"id":7414058}]}]}
{"op":"mcm","clk":"1006188182","pt":1580646973322,"mc":[{"id":"1.168224555","marketDefinition":{"bspMarket":false,"turnInPlayEnabled":true,"persistenceEnabled":true,"marketBaseRate":5.0,"eventId":"29681742","eventTypeId":"2","numberOfWinners":1,"bettingType":"ODDS","marketType":"SET_WINNER","marketTime":"2020-02-02T12:28:00.000Z","suspendTime":"2020-02-02T12:28:00.000Z","bspReconciled":false,"complete":true,"inPlay":false,"crossMatching":true,"runnersVoidable":false,"numberOfActiveRunners":2,"betDelay":0,"status":"OPEN","runners":[{"status":"ACTIVE","sortPriority":1,"id":7414058,"name":"Damir Dzumhur"},{"status":"ACTIVE","sortPriority":2,"id":7287690,"name":"Quentin Halys"}],"regulators":["MR_INT"],"countryCode":"FR","discountAllowed":true,"timezone":"UTC","openDate":"2020-02-02T12:28:00.000Z","version":3148727323,"name":"Set 2 Winner","eventName":"Dzumhur v Halys"}}]}
{"op":"mcm","clk":"1006209388","pt":1580647080161,"mc":[{"id":"1.168224555","rc":[{"batb":[[0,2.36,47.71]],"ltp":0.0,"tv":0.0,"id":7287690}]}]}
{"op":"mcm","clk":"1006238006","pt":1580647222420,"mc":[{"id":"1.168224555","rc":[{"batb":[[0,2.36,30.25]],"ltp":0.0,"tv":0.0,"id":7287690},{"batb":[[0,1.6,69.74],[1,1.01,16.01],[2,1.01,0]],"ltp":0.0,"tv":0.0,"id":7414058}]}]}
{"op":"mcm","clk":"1006238227","pt":1580647223354,"mc":[{"id":"1.168224555","marketDefinition":{"bspMarket":false,"turnInPlayEnabled":true,"persistenceEnabled":true,"marketBaseRate":5.0,"eventId":"29681742","eventTypeId":"2","numberOfWinners":1,"bettingType":"ODDS","marketType":"SET_WINNER","marketTime":"2020-02-02T12:28:00.000Z","suspendTime":"2020-02-02T12:28:00.000Z","bspReconciled":false,"complete":true,"inPlay":true,"crossMatching":true,"runnersVoidable":false,"numberOfActiveRunners":2,"betDelay":3,"status":"OPEN","runners":[{"status":"ACTIVE","sortPriority":1,"id":7414058,"name":"Damir Dzumhur"},{"status":"ACTIVE","sortPriority":2,"id":7287690,"name":"Quentin Halys"}],"regulators":["MR_INT"],"countryCode":"FR","discountAllowed":true,"timezone":"UTC","openDate":"2020-02-02T12:28:00.000Z","version":3148750677,"name":"Set 2 Winner","eventName":"Dzumhur v Halys"},"rc":[{"batb":[[0,1.01,15.51],[1,1.01,0]],"ltp":0.0,"tv":0.0,"id":7287690},{"batb":[[0,1.01,15.51],[1,1.01,0]],"ltp":0.0,"tv":0.0,"id":7414058}]}]}
{"op":"mcm","clk":"1006242151","pt":1580647242255,"mc":[{"id":"1.168224555","rc":[{"batb":[[0,2.44,15.97],[1,2.38,17.07],[2,1.01,15.51]],"ltp":0.0,"tv":0.0,"id":7287690},{"batb":[[0,1.61,29.03],[1,1.57,31.79],[2,1.01,15.51]],"ltp":0.0,"tv":0.0,"id":7414058}]}]}
{"op":"mcm","clk":"1006242283","pt":1580647242859,"mc":[{"id":"1.168224555","rc":[{"batb":[[1,2.4,29.41],[2,2.38,17.07]],"batl":[[0,2.74,23.53]],"ltp":0.0,"tv":0.0,"id":7287690},{"batb":[[1,1.57,104.88]],"batl":[[0,1.72,42.01]],"ltp":0.0,"tv":0.0,"id":7414058}]}]}
{"op":"mcm","clk":"1006244583","pt":1580647254072,"mc":[{"id":"1.168224555","rc":[{"batb":[[0,2.4,29.41],[1,2.38,17.07],[2,1.01,15.51]],"ltp":0.0,"tv":0.0,"id":7287690},{"batb":[[0,1.57,104.88],[1,1.01,15.51],[2,1.01,0]],"ltp":0.0,"tv":0.0,"id":7414058}]}]}
{"op":"mcm","clk":"1006244898","pt":1580647255465,"mc":[{"id":"1.168224555","rc":[{"batb":[[0,2.38,17.07],[1,1.01,15.51],[2,1.01,0]],"ltp":0.0,"tv":0.0,"id":7287690},{"batb":[[0,1.57,31.79]],"ltp":0.0,"tv":0.0,"id":7414058}]}]}
{"op":"mcm","clk":"1006246975","pt":1580647265477,"mc":[{"id":"1.168224555","rc":[{"batb":[[1,2.32,18.33],[2,1.01,15.51]],"ltp":0.0,"tv":0.0,"id":7287690},{"batb":[[0,1.63,27.3],[1,1.59,29.82],[2,1.57,31.79]],"ltp":0.0,"tv":0.0,"id":7414058}]}]}
{"op":"mcm","clk":"1006247008","pt":1580647265724,"mc":[{"id":"1.168224555","rc":[{"batb":[[2,1.01,15.51]],"ltp":0.0,"tv":0.0,"id":7414058}]}]}
{"op":"mcm","clk":"1006247191","pt":1580647266491,"mc":[{"id":"1.168224555","rc":[{"batb":[[1,2.36,30.25],[2,2.32,18.33]],"batl":[[0,2.72,24.37]],"ltp":0.0,"tv":0.0,"id":7287690},{"batb":[[2,1.58,72.26]],"batl":[[0,1.73,42.01]],"ltp":0.0,"tv":0.0,"id":7414058}]}]}
{"op":"mcm","clk":"1006249257","pt":1580647276463,"mc":[{"id":"1.168224555","rc":[{"batb":[[0,2.36,30.25],[1,2.32,18.33],[2,1.01,15.51]],"ltp":0.0,"tv":0.0,"id":7287690},{"batb":[[0,1.59,29.82],[1,1.58,72.26],[2,1.01,15.51]],"ltp":0.0,"tv":0.0,"id":7414058}]}]}
{"op":"mcm","clk":"1006249476","pt":1580647277484,"mc":[{"id":"1.168224555","rc":[{"batb":[[0,2.32,18.33],[1,1.01,15.51],[2,1.01,0]],"ltp":0.0,"tv":0.0,"id":7287690},{"batb":[[1,1.01,15.51],[2,1.01,0]],"ltp":0.0,"tv":0.0,"id":7414058}]}]}
{"op":"mcm","clk":"1006250849","pt":1580647284409,"mc":[{"id":"1.168224555","rc":[{"batb":[[1,2.26,19.43],[2,1.01,15.51]],"ltp":0.0,"tv":0.0,"id":7287690},{"batb":[[0,1.66,25.73],[1,1.62,28.09],[2,1.01,15.51]],"ltp":0.0,"tv":0.0,"id":7414058}]}]}
{"op":"mcm","clk":"1006251042","pt":1580647285396,"mc":[{"id":"1.168224555","rc":[{"batb":[[0,2.34,31.09],[1,2.32,18.33],[2,2.26,19.43]],"batl":[[0,2.68,24.37]],"ltp":0.0,"tv":0.0,"id":7287690},{"batb":[[2,1.6,69.74]],"batl":[[0,1.75,42.01]],"ltp":0.0,"tv":0.0,"id":7414058}]}]}
{"op":"mcm","clk":"1006253134","pt":1580647295627,"mc":[{"id":"1.168224555","rc":[{"batb":[[0,2.26,19.43],[1,1.01,15.51],[2,2.26,0]],"ltp":0.0,"tv":0.0,"id":7287690},{"batb":[[0,1.62,28.09],[1,1.01,15.51],[2,1.6,0]],"ltp":0.0,"tv":0.0,"id":7414058}]}]}
{"op":"mcm","clk":"1006256974","pt":1580647315408,"mc":[{"id":"1.168224555","rc":[{"batb":[[1,2.24,20.38],[2,1.01,15.51]],"ltp":0.0,"tv":0.0,"id":7287690},{"batb":[[0,1.69,24.39],[1,1.65,26.12],[2,1.62,28.09]],"ltp":0.0,"tv":0.0,"id":7414058}]}]}
{"op":"mcm","clk":"1006257175","pt":1580647316480,"mc":[{"id":"1.168224555","rc":[{"batb":[[0,2.3,31.93],[1,2.26,19.43],[2,2.24,20.38]],"batl":[[0,2.64,25.21]],"ltp":0.0,"tv":0.0,"id":7287690},{"batb":[[2,1.62,67.22]],"batl":[[0,1.77,42.01]],"ltp":0.0,"tv":0.0,"id":7414058}]}]}
{"op":"mcm","clk":"1006259182","pt":1580647326924,"mc":[{"id":"1.168224555","rc":[{"batb":[[1,2.24,20.38],[2,1.01,15.51]],"ltp":0.0,"tv":0.0,"id":7287690},{"batb":[[0,1.65,26.12],[1,1.62,67.22],[2,1.01,15.51]],"ltp":0.0,"tv":0.0,"id":7414058}]}]}
{"op":"mcm","clk":"1006259368","pt":1580647327824,"mc":[{"id":"1.168224555","rc":[{"batb":[[0,2.24,20.38],[1,1.01,15.51],[2,1.01,0]],"ltp":0.0,"tv":0.0,"id":7287690},{"batb":[[1,1.01,15.51],[2,1.01,0]],"ltp":0.0,"tv":0.0,"id":7414058}]}]}
{"op":"mcm","clk":"1006262232","pt":1580647342431,"mc":[{"id":"1.168224555","rc":[{"batb":[[0,2.34,17.94],[1,2.28,18.96],[2,1.01,15.51]],"ltp":0.0,"tv":0.0,"id":7287690},{"batb":[[1,1.61,28.48],[2,1.01,15.51]],"ltp":0.0,"tv":0.0,"id":7414058}]}]}
{"op":"mcm","clk":"1006262289","pt":1580647342714,"mc":[{"id":"1.168224555","rc":[{"batb":[[0,2.36,30.25],[1,2.34,17.94],[2,2.28,18.96]],"batl":[[0,2.7,24.37]],"ltp":0.0,"tv":0.0,"id":7287690},{"batb":[[2,1.6,69.74]],"batl":[[0,1.74,42.01]],"ltp":0.0,"tv":0.0,"id":7414058}]}]}
{"op":"mcm","clk":"1006264929","pt":1580647356143,"mc":[{"id":"1.168224555","rc":[{"batb":[[1,2.28,18.96],[2,1.01,15.51]],"ltp":0.0,"tv":0.0,"id":7287690},{"batb":[[0,1.61,28.48],[1,1.6,69.74],[2,1.01,15.51]],"ltp":0.0,"tv":0.0,"id":7414058}]}]}
{"op":"mcm","clk":"1006265210","pt":1580647357578,"mc":[{"id":"1.168224555","rc":[{"batb":[[0,2.28,18.96],[1,1.01,15.51],[2,1.01,0]],"ltp":0.0,"tv":0.0,"id":7287690},{"batb":[[1,1.01,15.51],[2,1.01,0]],"ltp":0.0,"tv":0.0,"id":7414058}]}]}
{"op":"mcm","clk":"1006266931","pt":1580647366353,"mc":[{"id":"1.168224555","rc":[{"batb":[[1,2.22,20.93],[2,1.01,15.51]],"ltp":0.0,"tv":0.0,"id":7287690},{"batb":[[0,1.68,24.94],[1,1.65,26.28],[2,1.01,15.51]],"ltp":0.0,"tv":0.0,"id":7414058}]}]}
{"op":"mcm","clk":"1006266950","pt":1580647366493,"mc":[{"id":"1.168224555","rc":[{"batb":[[0,2.3,31.93],[1,2.28,18.96],[2,2.22,20.93]],"batl":[[0,2.62,25.21]],"ltp":0.0,"tv":0.0,"id":7287690},{"batb":[[2,1.62,67.22]],"batl":[[0,1.77,42.01]],"ltp":0.0,"tv":0.0,"id":7414058}]}]}
{"op":"mcm","clk":"1006270141","pt":1580647382394,"mc":[{"id":"1.168224555","rc":[{"batb":[[0,2.3,50.89],[1,2.22,20.93],[2,1.01,15.51]],"ltp":0.0,"tv":0.0,"id":7287690}]}]}
{"op":"mcm","clk":"1006275128","pt":1580647407624,"mc":[{"id":"1.168224555","rc":[{"batb":[[0,2.22,20.93],[1,1.01,15.51],[2,1.01,0]],"ltp":0.0,"tv":0.0,"id":7287690},{"batb":[[0,1.65,26.28],[1,1.01,15.51],[2,1.62,0]],"ltp":0.0,"tv":0.0,"id":7414058}]}]}
{"op":"mcm","clk":"1006275707","pt":1580647410447,"mc":[{"id":"1.168224555","rc":[{"batb":[[1,1.64,26.67],[2,1.01,15.51]],"ltp":0.0,"tv":0.0,"id":7414058}]}]}
{"op":"mcm","clk":"1006275739","pt":1580647410663,"mc":[{"id":"1.168224555","rc":[{"batb":[[0,2.22,20.61]],"ltp":0.0,"tv":0.0,"id":7287690},{"batb":[[0,1.64,26.67],[1,1.01,15.51],[2,1.01,0]],"ltp":0.0,"tv":0.0,"id":7414058}]}]}
{"op":"mcm","clk":"1006278476","pt":1580647424441,"mc":[{"id":"1.168224555","rc":[{"batb":[[0,2.36,17.62],[1,2.28,19.36],[2,2.22,20.61]],"ltp":0.0,"tv":0.0,"id":7287690},{"batb":[[1,1.63,27.7],[2,1.01,15.51]],"ltp":0.0,"tv":0.0,"id":7414058}]}]}
{"op":"mcm","clk":"1006278596","pt":1580647425053,"mc":[{"id":"1.168224555","rc":[{"batb":[[1,2.32,31.09],[2,2.28,19.36]],"batl":[[0,2.66,25.21]],"ltp":0.0,"tv":0.0,"id":7287690},{"batb":[[2,1.61,68.06]],"batl":[[0,1.75,42.01]],"ltp":0.0,"tv":0.0,"id":7414058}]}]}
{"op":"mcm","clk":"1006280209","pt":1580647433879,"mc":[{"id":"1.168224555","rc":[{"batb":[[0,2.32,31.09],[1,2.28,19.36],[2,1.01,15.51]],"ltp":0.0,"tv":0.0,"id":7287690},{"batb":[[0,1.63,27.7],[1,1.61,68.06],[2,1.01,15.51]],"ltp":0.0,"tv":0.0,"id":7414058}]}]}
{"op":"mcm","clk":"1006280546","pt":1580647435684,"mc":[{"id":"1.168224555","rc":[{"batb":[[0,2.28,19.36],[1,1.01,15.51],[2,1.01,0]],"ltp":0.0,"tv":0.0,"id":7287690},{"batb":[[1,1.01,15.51],[2,1.01,0]],"ltp":0.0,"tv":0.0,"id":7414058}]}]}
{"op":"mcm","clk":"1006282177","pt":1580647444308,"mc":[{"id":"1.168224555","rc":[{"batl":[[0,3.15,200.42]],"ltp":0.0,"tv":0.0,"id":7287690},{"batl":[[0,2.22,329.01]],"ltp":0.0,"tv":0.0,"id":7414058}]}]}
{"op":"mcm","clk":"1006283960","pt":1580647453271,"mc":[{"id":"1.168224555","rc":[{"batb":[[0,2.38,16.84],[1,2.32,18.33],[2,2.28,19.36]],"ltp":0.0,"tv":0.0,"id":7287690},{"batb":[[1,1.61,28.72],[2,1.01,15.51]],"ltp":0.0,"tv":0.0,"id":7414058}]}]}
{"op":"mcm","clk":"1006284186","pt":1580647454486,"mc":[{"id":"1.168224555","rc":[{"batb":[[2,1.01,15.51]],"ltp":0.0,"tv":0.0,"id":7287690}]}]}
{"op":"mcm","clk":"1006284345","pt":1580647455383,"mc":[{"id":"1.168224555","rc":[{"batb":[[1,2.36,30.25],[2,2.32,18.33]],"batl":[[0,2.7,24.37],[1,3.15,200.42]],"ltp":0.0,"tv":0.0,"id":7287690},{"batb":[[2,1.6,69.74]],"batl":[[0,1.74,42.01],[1,2.22,329.01]],"ltp":0.0,"tv":0.0,"id":7414058}]}]}
{"op":"mcm","clk":"1006285576","pt":1580647462114,"mc":[{"id":"1.168224555","rc":[{"batb":[[0,2.36,30.25],[1,2.32,18.33],[2,1.01,15.51]],"ltp":0.0,"tv":0.0,"id":7287690},{"batb":[[0,1.61,28.72],[1,1.6,69.74],[2,1.01,15.51]],"ltp":0.0,"tv":0.0,"id":7414058}]}]}
{"op":"mcm","clk":"1006285870","pt":1580647463615,"mc":[{"id":"1.168224555","rc":[{"batb":[[0,2.32,18.33],[1,1.01,15.51],[2,1.01,0]],"batl":[[0,3.15,200.42],[1,3.15,0]],"ltp":0.0,"tv":0.0,"id":7287690},{"batb":[[1,1.01,15.51],[2,1.01,0]],"batl":[[0,2.22,329.01],[1,2.22,0]],"ltp":0.0,"tv":0.0,"id":7414058}]}]}
{"op":"mcm","clk":"1006289225","pt":1580647480321,"mc":[{"id":"1.168224555","rc":[{"batb":[[0,2.42,16.13],[1,2.36,17.23],[2,2.32,173.89]],"ltp":0.0,"tv":0.0,"id":7287690},{"batb":[[1,1.59,29.9],[2,1.01,15.51]],"ltp":0.0,"tv":0.0,"id":7414058}]}]}
{"op":"mcm","clk":"1006289436","pt":1580647481434,"mc":[{"id":"1.168224555","rc":[{"batb":[[1,2.38,30.25],[2,2.36,17.23]],"batl":[[0,2.74,23.53],[1,3.15,200.42]],"ltp":0.0,"tv":0.0,"id":7287690},{"batb":[[2,1.58,72.26]],"batl":[[0,1.72,42.01]],"ltp":0.0,"tv":0.0,"id":7414058}]}]}
{"op":"mcm","clk":"1006289448","pt":1580647481535,"mc":[{"id":"1.168224555","rc":[{"batl":[[1,2.1,363.31]],"ltp":0.0,"tv":0.0,"id":7414058}]}]}
{"op":"mcm","clk":"1006291457","pt":1580647492082,"mc":[{"id":"1.168224555","rc":[{"batb":[[0,2.38,30.25],[1,2.36,17.23],[2,1.01,15.51]],"ltp":0.0,"tv":0.0,"id":7287690},{"batb":[[0,1.59,29.9],[1,1.58,72.26],[2,1.01,15.51]],"ltp":0.0,"tv":0.0,"id":7414058}]}]}
{"op":"mcm","clk":"1006291755","pt":1580647493670,"mc":[{"id":"1.168224555","rc":[{"batb":[[0,2.36,17.23],[1,1.01,15.51],[2,1.01,0]],"batl":[[0,3.15,200.42],[1,3.15,0]],"ltp":0.0,"tv":0.0,"id":7287690},{"batb":[[1,1.01,15.51],[2,1.01,0]],"batl":[[0,2.1,363.31],[1,2.1,0]],"ltp":0.0,"tv":0.0,"id":7414058}]}]}
{"op":"mcm","clk":"1006294526","pt":1580647507412,"mc":[{"id":"1.168224555","rc":[{"batb":[[1,2.32,31.09],[2,2.3,18.8]],"batl":[[0,2.66,25.21],[1,3.15,200.42]],"ltp":0.0,"tv":0.0,"id":7287690},{"batb":[[0,1.64,27.07],[1,1.62,28.01],[2,1.61,68.06]],"batl":[[0,1.75,42.01],[1,2.1,363.31]],"ltp":0.0,"tv":0.0,"id":7414058}]}]}
{"op":"mcm","clk":"1006296748","pt":1580647519003,"mc":[{"id":"1.168224555","rc":[{"batb":[[0,2.32,31.09],[1,2.3,18.8],[2,1.01,15.51]],"ltp":0.0,"tv":0.0,"id":7287690},{"batb":[[0,1.62,28.01],[1,1.61,68.06],[2,1.01,15.51]],"ltp":0.0,"tv":0.0,"id":7414058}]}]}
{"op":"mcm","clk":"1006296899","pt":1580647519692,"mc":[{"id":"1.168224555","rc":[{"batb":[[0,2.3,18.8],[1,1.01,15.51],[2,1.01,0]],"batl":[[0,3.15,200.42],[1,3.15,0]],"ltp":0.0,"tv":0.0,"id":7287690},{"batb":[[1,1.01,15.51],[2,1.01,0]],"batl":[[0,2.1,363.31],[1,2.1,0]],"ltp":0.0,"tv":0.0,"id":7414058}]}]}
{"op":"mcm","clk":"1006299094","pt":1580647531136,"mc":[{"id":"1.168224555","rc":[{"batb":[[1,2.28,32.77],[2,2.22,20.61]],"batl":[[0,2.6,26.05],[1,3.15,200.42]],"ltp":0.0,"tv":0.0,"id":7287690},{"batb":[[0,1.67,25.1],[1,1.65,26.59],[2,1.64,65.54]],"batl":[[0,1.79,42.01],[1,2.1,363.31]],"ltp":0.0,"tv":0.0,"id":7414058}]}]}
{"op":"mcm","clk":"1006301070","pt":1580647542227,"mc":[{"id":"1.168224555","rc":[{"batb":[[0,2.28,32.77],[1,2.22,20.61],[2,1.01,15.51]],"ltp":0.0,"tv":0.0,"id":7287690},{"batb":[[0,1.65,26.59],[1,1.64,65.54],[2,1.01,15.51]],"ltp":0.0,"tv":0.0,"id":7414058}]}]}
{"op":"mcm","clk":"1006301350","pt":1580647543724,"mc":[{"id":"1.168224555","rc":[{"batb":[[0,2.22,20.61],[1,1.01,15.51],[2,1.01,0]],"batl":[[0,3.15,200.42],[1,3.15,0]],"ltp":0.0,"tv":0.0,"id":7287690},{"batb":[[1,1.01,15.51],[2,1.01,0]],"batl":[[0,2.1,363.31],[1,2.1,0]],"ltp":0.0,"tv":0.0,"id":7414058}]}]}
{"op":"mcm","clk":"1006305545","pt":1580647567360,"mc":[{"id":"1.168224555","rc":[{"batb":[[0,2.24,33.61],[1,2.22,20.61],[2,2.14,23.21]],"batl":[[0,2.54,26.89]],"ltp":0.0,"tv":0.0,"id":7287690},{"batb":[[0,1.71,23.05],[1,1.69,24.39],[2,1.66,63.01]],"batl":[[0,1.81,42.01]],"ltp":0.0,"tv":0.0,"id":7414058}]}]}
{"op":"mcm","clk":"1006305733","pt":1580647568465,"mc":[{"id":"1.168224555","rc":[{"batl":[[1,3,213.45]],"ltp":0.0,"tv":0.0,"id":7287690},{"batl":[[1,2.3,309.75]],"ltp":0.0,"tv":0.0,"id":7414058}]}]}
{"op":"mcm","clk":"1006307551","pt":1580647579784,"mc":[{"id":"1.168224555","rc":[{"batb":[[0,2.14,23.21],[1,1.01,15.51],[2,2.14,0]],"batl":[[0,3,213.45],[1,3,0]],"ltp":0.0,"tv":0.0,"id":7287690},{"batb":[[0,1.69,24.39],[1,1.01,15.51],[2,1.66,0]],"batl":[[0,2.3,309.75],[1,2.3,0]],"ltp":0.0,"tv":0.0,"id":7414058}]}]}
{"op":"mcm","clk":"1006310253","pt":1580647596215,"mc":[{"id":"1.168224555","rc":[{"batb":[[0,2.28,19.36],[1,2.2,21.01],[2,1.01,15.51]],"ltp":0.0,"tv":0.0,"id":7287690},{"batb":[[1,1.66,25.81],[2,1.01,15.51]],"ltp":0.0,"tv":0.0,"id":7414058}]}]}
{"op":"mcm","clk":"1006310506","pt":1580647597476,"mc":[{"id":"1.168224555","rc":[{"batb":[[1,2.26,32.77],[2,2.2,21.01]],"batl":[[0,2.56,26.89],[1,3,213.45]],"ltp":0.0,"tv":0.0,"id":7287690},{"batb":[[2,1.65,63.85]],"batl":[[0,1.8,42.01],[1,2.3,309.75]],"ltp":0.0,"tv":0.0,"id":7414058}]}]}
{"op":"mcm","clk":"1006312668","pt":1580647611222,"mc":[{"id":"1.168224555","rc":[{"batb":[[0,2.26,32.77],[1,2.2,21.01],[2,1.01,15.51]],"ltp":0.0,"tv":0.0,"id":7287690},{"batb":[[0,1.66,25.81],[1,1.65,63.85],[2,1.01,15.51]],"ltp":0.0,"tv":0.0,"id":7414058}]}]}
{"op":"mcm","clk":"1006312765","pt":1580647611817,"mc":[{"id":"1.168224555","rc":[{"batb":[[0,2.2,21.01],[1,1.01,15.51],[2,1.01,0]],"batl":[[0,3,213.45],[1,3,0]],"ltp":0.0,"tv":0.0,"id":7287690},{"batb":[[1,1.01,15.51],[2,1.01,0]],"batl":[[0,2.3,309.75],[1,2.3,0]],"ltp":0.0,"tv":0.0,"id":7414058}]}]}
{"op":"mcm","clk":"1006313112","pt":1580647614212,"mc":[{"id":"1.168224555","rc":[{"batb":[[0,2.22,20.69],[1,2.2,21.01],[2,1.01,15.51]],"ltp":0.0,"tv":0.0,"id":7287690},{"batb":[[1,1.65,26.12],[2,1.01,15.51]],"ltp":0.0,"tv":0.0,"id":7414058}]}]}
{"op":"mcm","clk":"1006313164","pt":1580647614533,"mc":[{"id":"1.168224555","rc":[{"batb":[[1,1.01,15.51],[2,1.01,0]],"ltp":0.0,"tv":0.0,"id":7287690},{"batb":[[0,1.65,26.12],[1,1.01,15.51],[2,1.01,0]],"ltp":0.0,"tv":0.0,"id":7414058}]}]}
{"op":"mcm","clk":"1006314485","pt":1580647623167,"mc":[{"id":"1.168224555","rc":[{"batb":[[0,2.34,18.02],[1,2.3,31.93],[2,2.28,19.04]],"batl":[[0,2.62,25.21],[1,3,213.45]],"ltp":0.0,"tv":0.0,"id":7287690},{"batb":[[1,1.63,66.38],[2,1.61,28.72]],"batl":[[0,1.77,42.01],[1,2.3,309.75]],"ltp":0.0,"tv":0.0,"id":7414058}]}]}
{"op":"mcm","clk":"1006317516","pt":1580647640348,"mc":[{"id":"1.168224555","rc":[{"batb":[[0,2.3,31.93],[1,2.28,19.04],[2,1.01,15.51]],"ltp":0.0,"tv":0.0,"id":7287690},{"batb":[[0,1.63,66.38],[1,1.61,28.72],[2,1.01,15.51]],"ltp":0.0,"tv":0.0,"id":7414058}]}]}
{"op":"mcm","clk":"1006317760","pt":1580647641862,"mc":[{"id":"1.168224555","rc":[{"batb":[[0,2.28,19.04],[1,1.01,15.51],[2,1.01,0]],"batl":[[0,3,213.45],[1,3,0]],"ltp":0.0,"tv":0.0,"id":7287690},{"batb":[[0,1.61,28.72],[1,1.01,15.51],[2,1.01,0]],"batl":[[0,2.3,309.75],[1,2.3,0]],"ltp":0.0,"tv":0.0,"id":7414058}]}]}
{"op":"mcm","clk":"1006320501","pt":1580647659283,"mc":[{"id":"1.168224555","rc":[{"batb":[[0,2.42,16.13],[1,2.36,47.71],[2,1.01,15.51]],"batl":[[0,2.7,24.37],[1,3,213.45]],"ltp":0.0,"tv":0.0,"id":7287690},{"batb":[[1,1.6,69.74],[2,1.57,31.39]],"batl":[[0,1.74,42.01]],"ltp":0.0,"tv":0.0,"id":7414058}]}]}
{"op":"mcm","clk":"1006320815","pt":1580647661286,"mc":[{"id":"1.168224555","rc":[{"batl":[[1,2.16,342.82]],"ltp":0.0,"tv":0.0,"id":7414058}]}]}
{"op":"mcm","clk":"1006323089","pt":1580647675892,"mc":[{"id":"1.168224555","rc":[{"batb":[[0,2.36,17.47],[1,1.01,15.51],[2,1.01,0]],"batl":[[0,3,213.45],[1,3,0]],"ltp":0.0,"tv":0.0,"id":7287690},{"batb":[[0,1.57,31.39],[1,1.01,15.51],[2,1.57,0]],"batl":[[0,2.16,342.82],[1,2.16,0]],"ltp":0.0,"tv":0.0,"id":7414058}]}]}
{"op":"mcm","clk":"1006325821","pt":1580647693418,"mc":[{"id":"1.168224555","rc":[{"batb":[[0,2.52,14.56],[1,2.46,15.66],[2,2.42,29.41]],"batl":[[0,2.76,23.53]],"ltp":0.0,"tv":0.0,"id":7287690},{"batb":[[0,1.57,104.49],[1,1.53,34.46],[2,1.01,15.51]],"batl":[[0,1.71,42.01],[1,2.16,342.82]],"ltp":0.0,"tv":0.0,"id":7414058}]}]}
{"op":"mcm","clk":"1006325987","pt":1580647694435,"mc":[{"id":"1.168224555","rc":[{"batl":[[1,3.45,180.4]],"ltp":0.0,"tv":0.0,"id":7287690}]}]}
{"op":"mcm","clk":"1006328058","pt":1580647707847,"mc":[{"id":"1.168224555","rc":[{"batb":[[0,2.46,15.66],[1,1.01,15.51],[2,2.42,0]],"batl":[[0,3.45,180.4],[1,3.45,0]],"ltp":0.0,"tv":0.0,"id":7287690},{"batb":[[0,1.53,34.46],[1,1.01,15.51],[2,1.01,0]],"batl":[[0,2.16,342.82],[1,2.16,0]],"ltp":0.0,"tv":0.0,"id":7414058}]}]}
{"op":"mcm","clk":"1006329507","pt":1580647717473,"mc":[{"id":"1.168224555","rc":[{"batb":[[1,2.4,29.41],[2,2.38,17]],"ltp":0.0,"tv":0.0,"id":7287690},{"batb":[[0,1.6,29.43],[1,1.58,72.26],[2,1.56,32.34]],"batl":[[0,1.72,42.01],[1,2.16,342.82]],"ltp":0.0,"tv":0.0,"id":7414058}]}]}
{"op":"mcm","clk":"1006329957","pt":1580647720363,"mc":[{"id":"1.168224555","rc":[{"batl":[[0,2.72,24.37],[1,3.3,191.92]],"ltp":0.0,"tv":0.0,"id":7287690}]}]}
{"op":"mcm","clk":"1006332201","pt":1580647735467,"mc":[{"id":"1.168224555","rc":[{"batb":[[0,2.4,29.41],[1,2.38,17],[2,1.01,15.51]],"ltp":0.0,"tv":0.0,"id":7287690},{"batb":[[0,1.58,72.26],[1,1.56,32.34],[2,1.01,15.51]],"ltp":0.0,"tv":0.0,"id":7414058}]}]}
{"op":"mcm","clk":"1006332252","pt":1580647735885,"mc":[{"id":"1.168224555","rc":[{"batb":[[0,2.38,17],[1,1.01,15.51],[2,1.01,0]],"batl":[[0,3.3,191.92],[1,3.3,0]],"ltp":0.0,"tv":0.0,"id":7287690},{"batb":[[0,1.56,32.34],[1,1.01,15.51],[2,1.01,0]],"batl":[[0,2.16,342.82],[1,2.16,0]],"ltp":0.0,"tv":0.0,"id":7414058}]}]}
{"op":"mcm","clk":"1006338561","pt":1580647777440,"mc":[{"id":"1.168224555","rc":[{"batb":[[1,2.36,30.25],[2,2.32,18.33]],"batl":[[0,2.7,24.37],[1,3.3,191.92]],"ltp":0.0,"tv":0.0,"id":7287690},{"batb":[[0,1.63,27.54],[1,1.59,101.03],[2,1.01,15.51]],"batl":[[0,1.74,42.01],[1,2.16,342.82]],"ltp":0.0,"tv":0.0,"id":7414058}]}]}
{"op":"mcm","clk":"1006341568","pt":1580647796410,"mc":[{"id":"1.168224555","rc":[{"batb":[[0,2.36,30.25],[1,2.32,18.33],[2,1.01,15.51]],"ltp":0.0,"tv":0.0,"id":7287690},{"batb":[[0,1.59,101.03],[1,1.01,15.51],[2,1.01,0]],"ltp":0.0,"tv":0.0,"id":7414058}]}]}
{"op":"mcm","clk":"1006341862","pt":1580647798292,"mc":[{"id":"1.168224555","rc":[{"batb":[[0,2.32,18.33],[1,1.01,15.51],[2,1.01,0]],"batl":[[0,3.3,191.92],[1,3.3,0]],"ltp":0.0,"tv":0.0,"id":7287690},{"batb":[[0,1.59,30.45]],"batl":[[0,2.16,342.82],[1,2.16,0]],"ltp":0.0,"tv":0.0,"id":7414058}]}]}
{"op":"mcm","clk":"1006342031","pt":1580647799414,"mc":[{"id":"1.168224555","rc":[{"batb":[[1,1.58,30.45],[2,1.01,15.51]],"ltp":0.0,"tv":0.0,"id":7414058}]}]}
{"op":"mcm","clk":"1006342063","pt":1580647799659,"mc":[{"id":"1.168224555","rc":[{"batb":[[0,1.58,30.45],[1,1.01,15.51],[2,1.01,0]],"ltp":0.0,"tv":0.0,"id":7414058}]}]}
{"op":"mcm","clk":"1006343720","pt":1580647809461,"mc":[{"id":"1.168224555","rc":[{"batb":[[0,2.32,49.42],[1,2.26,19.67],[2,1.01,15.51]],"batl":[[0,2.66,25.21],[1,3.3,191.92]],"ltp":0.0,"tv":0.0,"id":7287690},{"batb":[[0,1.66,25.65],[1,1.62,28.01],[2,1.61,68.06]],"batl":[[0,1.76,42.01],[1,2.16,342.82]],"ltp":0.0,"tv":0.0,"id":7414058}]}]}
{"op":"mcm","clk":"1006346246","pt":1580647825182,"mc":[{"id":"1.168224555","rc":[{"batb":[[0,2.32,31.09]],"ltp":0.0,"tv":0.0,"id":7287690},{"batb":[[0,1.62,28.01],[1,1.61,68.06],[2,1.01,15.51]],"ltp":0.0,"tv":0.0,"id":7414058}]}]}
{"op":"mcm","clk":"1006346345","pt":1580647825933,"mc":[{"id":"1.168224555","rc":[{"batb":[[0,2.26,19.67],[1,1.01,15.51],[2,1.01,0]],"batl":[[0,3.3,191.92],[1,3.3,0]],"ltp":0.0,"tv":0.0,"id":7287690},{"batb":[[1,1.01,15.51],[2,1.01,0]],"batl":[[0,2.16,342.82],[1,2.16,0]],"ltp":0.0,"tv":0.0,"id":7414058}]}]}
{"op":"mcm","clk":"1006346663","pt":1580647828113,"mc":[{"id":"1.168224555","rc":[{"batb":[[0,2.24,19.99]],"ltp":0.0,"tv":0.0,"id":7287690},{"batb":[[0,1.63,27.62]],"ltp":0.0,"tv":0.0,"id":7414058}]}]}
{"op":"mcm","clk":"1006348658","pt":1580647842410,"mc":[{"id":"1.168224555","rc":[{"batb":[[0,2.26,92.48],[1,2.24,19.99],[2,1.01,15.51]],"ltp":0.0,"tv":0.0,"id":7287690}]}]}
{"op":"mcm","clk":"1006348773","pt":1580647843307,"mc":[{"id":"1.168224555","rc":[{"batb":[[0,2.38,16.92],[1,2.36,30.25],[2,2.32,18.41]],"batl":[[0,2.7,24.37],[1,3.3,191.92]],"ltp":0.0,"tv":0.0,"id":7287690},{"batb":[[1,1.59,70.58],[2,1.58,30.69]],"batl":[[0,1.73,42.01],[1,2.16,342.82]],"ltp":0.0,"tv":0.0,"id":7414058}]}]}
{"op":"mcm","clk":"1006350705","pt":1580647856449,"mc":[{"id":"1.168224555","rc":[{"batb":[[0,2.36,30.25],[1,2.32,18.41],[2,1.01,15.51]],"ltp":0.0,"tv":0.0,"id":7287690},{"batb":[[0,1.59,70.58],[1,1.58,30.69],[2,1.01,15.51]],"ltp":0.0,"tv":0.0,"id":7414058}]}]}
{"op":"mcm","clk":"1006350936","pt":1580647857942,"mc":[{"id":"1.168224555","rc":[{"batb":[[0,2.32,18.41],[1,1.01,15.51],[2,1.01,0]],"batl":[[0,3.3,191.92],[1,3.3,0]],"ltp":0.0,"tv":0.0,"id":7287690},{"batb":[[0,1.58,30.69],[1,1.01,15.51],[2,1.01,0]],"batl":[[0,2.16,342.82],[1,2.16,0]],"ltp":0.0,"tv":0.0,"id":7414058}]}]}
{"op":"mcm","clk":"1006353516","pt":1580647874482,"mc":[{"id":"1.168224555","rc":[{"batb":[[0,2.5,14.95],[1,2.4,16.6],[2,2.34,172.22]],"ltp":0.0,"tv":0.0,"id":7287690},{"batb":[[1,1.53,34.7],[2,1.01,15.51]],"ltp":0.0,"tv":0.0,"id":7414058}]}]}
{"op":"mcm","clk":"1006353617","pt":1580647875171,"mc":[{"id":"1.168224555","rc":[{"batb":[[1,2.42,29.41],[2,2.4,16.6]],"batl":[[0,2.76,23.53],[1,3.3,191.92]],"ltp":0.0,"tv":0.0,"id":7287690},{"batb":[[1,1.57,73.1],[2,1.53,34.7]],"batl":[[0,1.71,42.01],[1,2.16,342.82]],"ltp":0.0,"tv":0.0,"id":7414058}]}]}
{"op":"mcm","clk":"1006355512","pt":1580647887907,"mc":[{"id":"1.168224555","rc":[{"batb":[[0,2.4,16.6],[1,1.01,15.51],[2,2.4,0]],"batl":[[0,3.3,191.92],[1,3.3,0]],"ltp":0.0,"tv":0.0,"id":7287690},{"batb":[[0,1.53,34.7],[1,1.01,15.51],[2,1.53,0]],"batl":[[0,2.16,342.82],[1,2.16,0]],"ltp":0.0,"tv":0.0,"id":7414058}]}]}
{"op":"mcm","clk":"1006356620","pt":1580647895458,"mc":[{"id":"1.168224555","rc":[{"batb":[[0,2.4,46.01],[1,2.34,17.86],[2,1.01,15.51]],"batl":[[0,2.74,23.53],[1,3.3,191.92]],"ltp":0.0,"tv":0.0,"id":7287690},{"batb":[[0,1.62,28.09],[1,1.58,72.26],[2,1.57,31.24]],"batl":[[0,1.72,42.01],[1,2.16,342.82]],"ltp":0.0,"tv":0.0,"id":7414058}]}]}
{"op":"mcm","clk":"1006358540","pt":1580647909963,"mc":[{"id":"1.168224555","rc":[{"batb":[[0,2.34,17.86],[1,1.01,15.51],[2,1.01,0]],"batl":[[0,3.3,191.92],[1,3.3,0]],"ltp":0.0,"tv":0.0,"id":7287690},{"batb":[[0,1.57,31.24],[1,1.01,15.51],[2,1.57,0]],"batl":[[0,2.16,342.82],[1,2.16,0]],"ltp":0.0,"tv":0.0,"id":7414058}]}]}
{"op":"mcm","clk":"1006361463","pt":1580647931092,"mc":[{"id":"1.168224555","rc":[{"batb":[[0,2.44,28.57],[1,2.34,17.86],[2,1.01,15.51]],"batl":[[0,2.8,22.69],[1,3.3,191.92]],"ltp":0.0,"tv":0.0,"id":7287690},{"batb":[[1,1.56,74.78],[2,1.01,15.51]],"batl":[[0,1.7,42.01],[1,2.16,342.82]],"ltp":0.0,"tv":0.0,"id":7414058}]}]}
{"op":"mcm","clk":"1006361560","pt":1580647931882,"mc":[{"id":"1.168224555","rc":[{"batb":[[0,2.52,14.63],[1,2.44,28.57],[2,2.42,16.37]],"ltp":0.0,"tv":0.0,"id":7287690},{"batb":[[2,1.53,34.93]],"ltp":0.0,"tv":0.0,"id":7414058}]}]}
{"op":"mcm","clk":"1006363560","pt":1580647947438,"mc":[{"id":"1.168224555","rc":[{"batb":[[0,2.44,28.57],[1,2.42,16.37],[2,1.01,15.51]],"ltp":0.0,"tv":0.0,"id":7287690},{"batb":[[0,1.56,74.78],[1,1.53,34.93],[2,1.01,15.51]],"ltp":0.0,"tv":0.0,"id":7414058}]}]}
{"op":"mcm","clk":"1006363675","pt":1580647948108,"mc":[{"id":"1.168224555","rc":[{"batb":[[0,2.42,16.37],[1,1.01,15.51],[2,1.01,0]],"batl":[[0,3.3,191.92],[1,3.3,0]],"ltp":0.0,"tv":0.0,"id":7287690},{"batb":[[0,1.53,34.93],[1,1.01,15.51],[2,1.01,0]],"batl":[[0,2.16,342.82],[1,2.16,0]],"ltp":0.0,"tv":0.0,"id":7414058}]}]}
{"op":"mcm","clk":"1006363976","pt":1580647950357,"mc":[{"id":"1.168224555","rc":[{"batb":[[0,2.44,16.05],[1,2.42,16.37],[2,1.01,15.51]],"ltp":0.0,"tv":0.0,"id":7287690},{"batb":[[1,1.52,35.49],[2,1.01,15.51]],"ltp":0.0,"tv":0.0,"id":7414058}]}]}
{"op":"mcm","clk":"1006364128","pt":1580647951342,"mc":[{"id":"1.168224555","rc":[{"batb":[[1,1.01,15.51],[2,1.01,0]],"ltp":0.0,"tv":0.0,"id":7287690},{"batb":[[0,1.52,35.49],[1,1.01,15.51],[2,1.01,0]],"ltp":0.0,"tv":0.0,"id":7414058}]}]}
{"op":"mcm","clk":"1006366216","pt":1580647967247,"mc":[{"id":"1.168224555","rc":[{"batb":[[0,2.66,12.59],[1,2.6,26.05],[2,2.56,13.93]],"batl":[[0,3,21]],"ltp":0.0,"tv":0.0,"id":7287690},{"batb":[[1,1.5,121.55],[2,1.01,15.51]],"batl":[[0,1.62,42.01]],"ltp":0.0,"tv":0.0,"id":7414058}]}]}
{"op":"mcm","clk":"1006366488","pt":1580647969363,"mc":[{"id":"1.168224555","rc":[{"batl":[[1,3.65,170.41]],"ltp":0.0,"tv":0.0,"id":7287690},{"batl":[[1,2.04,383.01]],"ltp":0.0,"tv":0.0,"id":7414058}]}]}
{"op":"mcm","clk":"1006367229","pt":1580647975050,"mc":[{"id":"1.168224555","rc":[{"batb":[[0,2.68,12.51],[2,2.58,13.77]],"ltp":0.0,"tv":0.0,"id":7287690}]}]}
{"op":"mcm","clk":"1006367853","pt":1580647979960,"mc":[{"id":"1.168224555","rc":[{"batb":[[0,2.68,12.35],[2,2.58,13.61]],"ltp":0.0,"tv":0.0,"id":7287690}]}]}
{"op":"mcm","clk":"1006380231","pt":1580648064780,"mc":[{"id":"1.168224555","rc":[{"batb":[[0,2.6,26.05],[1,2.58,13.61],[2,1.01,15.51]],"ltp":0.0,"tv":0.0,"id":7287690},{"batb":[[0,1.5,121.55],[1,1.01,15.51],[2,1.01,0]],"ltp":0.0,"tv":0.0,"id":7414058}]}]}
{"op":"mcm","clk":"1006380383","pt":1580648065990,"mc":[{"id":"1.168224555","rc":[{"batb":[[0,2.58,13.61],[1,1.01,15.51],[2,1.01,0]],"batl":[[0,3.65,170.41],[1,3.65,0]],"ltp":0.0,"tv":0.0,"id":7287690},{"batb":[[0,1.5,37.53]],"batl":[[0,2.04,383.01],[1,2.04,0]],"ltp":0.0,"tv":0.0,"id":7414058}]}]}
{"op":"mcm","clk":"1006380585","pt":1580648067478,"mc":[{"id":"1.168224555","rc":[{"batb":[[0,2.62,13.22],[1,2.58,13.61],[2,1.01,15.51]],"ltp":0.0,"tv":0.0,"id":7287690},{"batb":[[1,1.49,38.87],[2,1.01,15.51]],"ltp":0.0,"tv":0.0,"id":7414058}]}]}
{"op":"mcm","clk":"1006380716","pt":1580648068388,"mc":[{"id":"1.168224555","rc":[{"batb":[[1,1.01,15.51],[2,1.01,0]],"ltp":0.0,"tv":0.0,"id":7287690},{"batb":[[0,1.49,38.87],[1,1.01,15.51],[2,1.01,0]],"ltp":0.0,"tv":0.0,"id":7414058}]}]}
{"op":"mcm","clk":"1006382012","pt":1580648077887,"mc":[{"id":"1.168224555","rc":[{"batb":[[0,2.78,11.25],[1,2.68,12.35],[2,1.01,15.51]],"ltp":0.0,"tv":0.0,"id":7287690},{"batb":[[1,1.47,40.84],[2,1.01,15.51]],"ltp":0.0,"tv":0.0,"id":7414058}]}]}
{"op":"mcm","clk":"1006382162","pt":1580648078873,"mc":[{"id":"1.168224555","rc":[{"batb":[[2,2.66,25.21]],"batl":[[0,3.05,20.16],[1,3.65,170.41]],"ltp":0.0,"tv":0.0,"id":7287690},{"batb":[[0,1.49,124.57]],"batl":[[0,1.61,42.01],[1,2.04,383.01]],"ltp":0.0,"tv":0.0,"id":7414058}]}]}
{"op":"mcm","clk":"1006383847","pt":1580648090308,"mc":[{"id":"1.168224555","rc":[{"batb":[[0,2.68,12.35],[1,1.01,15.51],[2,2.66,0]],"batl":[[0,3.65,170.41],[1,3.65,0]],"ltp":0.0,"tv":0.0,"id":7287690},{"batb":[[0,1.47,40.52],[1,1.01,15.51],[2,1.01,0]],"batl":[[0,2.04,383.01],[1,2.04,0]],"ltp":0.0,"tv":0.0,"id":7414058}]}]}
{"op":"mcm","clk":"1006386428","pt":1580648107235,"mc":[{"id":"1.168224555","rc":[{"batb":[[0,2.84,10.7],[1,2.74,11.64],[2,2.7,24.37]],"batl":[[0,3.1,19.32],[1,3.65,170.41]],"ltp":0.0,"tv":0.0,"id":7287690},{"batb":[[0,1.48,87.38],[1,1.47,40.52],[2,1.46,42.41]],"batl":[[0,1.6,42.01],[1,2.04,383.01]],"ltp":0.0,"tv":0.0,"id":7414058}]}]}
{"op":"mcm","clk":"1006388325","pt":1580648120231,"mc":[{"id":"1.168224555","rc":[{"batb":[[0,2.74,11.64],[1,1.01,15.51],[2,2.7,0]],"batl":[[0,3.65,170.41],[1,3.65,0]],"ltp":0.0,"tv":0.0,"id":7287690},{"batb":[[0,1.46,42.41],[1,1.01,15.51],[2,1.46,0]],"batl":[[0,2.04,383.01],[1,2.04,0]],"ltp":0.0,"tv":0.0,"id":7414058}]}]}
{"op":"mcm","clk":"1006390098","pt":1580648132486,"mc":[{"id":"1.168224555","rc":[{"batb":[[1,2.64,12.9],[2,1.01,15.51]],"ltp":0.0,"tv":0.0,"id":7287690},{"batb":[[0,1.5,37.92],[1,1.48,39.81],[2,1.46,42.41]],"ltp":0.0,"tv":0.0,"id":7414058}]}]}
{"op":"mcm","clk":"1006390228","pt":1580648133282,"mc":[{"id":"1.168224555","rc":[{"batl":[[0,3,21],[1,3.65,170.41]],"ltp":0.0,"tv":0.0,"id":7287690},{"batb":[[2,1.01,15.51]],"batl":[[0,1.62,42.01],[1,2.04,383.01]],"ltp":0.0,"tv":0.0,"id":7414058}]}]}
{"op":"mcm","clk":"1006390392","pt":1580648134360,"mc":[{"id":"1.168224555","rc":[{"batb":[[2,2.62,25.21]],"ltp":0.0,"tv":0.0,"id":7287690},{"batb":[[0,1.5,121.94]],"ltp":0.0,"tv":0.0,"id":7414058}]}]}
{"op":"mcm","clk":"1006391986","pt":1580648146993,"mc":[{"id":"1.168224555","rc":[{"batb":[[0,2.64,12.9],[1,2.62,25.21],[2,1.01,15.51]],"ltp":0.0,"tv":0.0,"id":7287690},{"batb":[[0,1.5,84.02]],"ltp":0.0,"tv":0.0,"id":7414058}]}]}
{"op":"mcm","clk":"1006392129","pt":1580648148105,"mc":[{"id":"1.168224555","rc":[{"batb":[[1,1.01,15.51],[2,1.01,0]],"batl":[[0,3.65,170.41],[1,3.65,0]],"ltp":0.0,"tv":0.0,"id":7287690},{"batb":[[0,1.48,39.81],[1,1.01,15.51],[2,1.01,0]],"batl":[[0,2.04,383.01],[1,2.04,0]],"ltp":0.0,"tv":0.0,"id":7414058}]}]}
{"op":"mcm","clk":"1006395518","pt":1580648174350,"mc":[{"id":"1.168224555","rc":[{"batb":[[0,2.82,10.94],[1,2.7,12.12],[2,2.66,443.28]],"ltp":0.0,"tv":0.0,"id":7287690},{"batb":[[1,1.46,41.39],[2,1.01,15.51]],"ltp":0.0,"tv":0.0,"id":7414058}]}]}
{"op":"mcm","clk":"1006395645","pt":1580648175448,"mc":[{"id":"1.168224555","rc":[{"batb":[[2,2.66,25.21]],"batl":[[0,3.05,20.16],[1,3.65,170.41]],"ltp":0.0,"tv":0.0,"id":7287690},{"batb":[[0,1.49,85.7],[1,1.48,39.81],[2,1.46,41.39]],"batl":[[0,1.61,42.01],[1,2.04,383.01]],"ltp":0.0,"tv":0.0,"id":7414058}]}]}
{"op":"mcm","clk":"1006397819","pt":1580648191986,"mc":[{"id":"1.168224555","rc":[{"batb":[[0,2.7,12.12],[1,1.01,15.51],[2,2.66,0]],"batl":[[0,3.65,170.41],[1,3.65,0]],"ltp":0.0,"tv":0.0,"id":7287690},{"batb":[[0,1.46,41.39],[1,1.01,15.51],[2,1.46,0]],"batl":[[0,2.04,383.01],[1,2.04,0]],"ltp":0.0,"tv":0.0,"id":7414058}]}]}
{"op":"mcm","clk":"1006399179","pt":1580648202094,"mc":[{"id":"1.168224555","rc":[{"batb":[[1,2.6,13.3],[2,1.01,15.51]],"ltp":0.0,"tv":0.0,"id":7287690},{"batb":[[0,1.51,36.74],[1,1.49,38.79],[2,1.01,15.51]],"ltp":0.0,"tv":0.0,"id":7414058}]}]}
{"op":"mcm","clk":"1006399292","pt":1580648203010,"mc":[{"id":"1.168224555","rc":[{"batb":[[1,2.6,39.34]],"batl":[[0,2.96,21],[1,3.65,170.41]],"ltp":0.0,"tv":0.0,"id":7287690},{"batb":[[0,1.51,119.08]],"batl":[[0,1.64,42.01],[1,2.04,383.01]],"ltp":0.0,"tv":0.0,"id":7414058}]}]}
{"op":"mcm","clk":"1006400757","pt":1580648213300,"mc":[{"id":"1.168224555","rc":[{"batb":[[0,2.6,39.34],[1,1.01,15.51],[2,1.01,0]],"ltp":0.0,"tv":0.0,"id":7287690},{"batb":[[0,1.51,82.34]],"ltp":0.0,"tv":0.0,"id":7414058}]}]}
{"op":"mcm","clk":"1006400859","pt":1580648214121,"mc":[{"id":"1.168224555","rc":[{"batb":[[0,2.6,13.3]],"batl":[[0,3.65,170.41],[1,3.65,0]],"ltp":0.0,"tv":0.0,"id":7287690},{"batb":[[0,1.49,38.79],[1,1.01,15.51],[2,1.01,0]],"batl":[[0,2.04,383.01],[1,2.04,0]],"ltp":0.0,"tv":0.0,"id":7414058}]}]}
{"op":"mcm","clk":"1006402965","pt":1580648228347,"mc":[{"id":"1.168224555","rc":[{"batb":[[1,2.5,14.87],[2,1.01,15.51]],"ltp":0.0,"tv":0.0,"id":7287690},{"batb":[[0,1.54,33.83],[1,1.52,36.04],[2,1.49,38.79]],"ltp":0.0,"tv":0.0,"id":7414058}]}]}
{"op":"mcm","clk":"1006403132","pt":1580648229346,"mc":[{"id":"1.168224555","rc":[{"batb":[[1,2.54,26.89],[2,2.5,14.87]],"batl":[[0,2.9,21.85]],"ltp":0.0,"tv":0.0,"id":7287690},{"batb":[[1,1.53,78.98],[2,1.52,36.04]],"batl":[[0,1.66,42.01],[1,2.04,383.01]],"ltp":0.0,"tv":0.0,"id":7414058}]}]}
{"op":"mcm","clk":"1006403264","pt":1580648230353,"mc":[{"id":"1.168224555","rc":[{"batl":[[1,3.45,180.4]],"ltp":0.0,"tv":0.0,"id":7287690}]}]}
{"op":"mcm","clk":"1006404831","pt":1580648240949,"mc":[{"id":"1.168224555","rc":[{"batb":[[0,2.54,26.89],[1,2.5,14.87],[2,1.01,15.51]],"ltp":0.0,"tv":0.0,"id":7287690},{"batb":[[0,1.53,78.98],[1,1.52,36.04],[2,1.01,15.51]],"ltp":0.0,"tv":0.0,"id":7414058}]}]}
{"op":"mcm","clk":"1006404991","pt":1580648242165,"mc":[{"id":"1.168224555","rc":[{"batb":[[0,2.5,14.87],[1,1.01,15.51],[2,1.01,0]],"batl":[[0,3.45,180.4],[1,3.45,0]],"ltp":0.0,"tv":0.0,"id":7287690},{"batb":[[0,1.52,36.04],[1,1.01,15.51],[2,1.01,0]],"batl":[[0,2.04,383.01],[1,2.04,0]],"ltp":0.0,"tv":0.0,"id":7414058}]}]}
{"op":"mcm","clk":"1006406113","pt":1580648250099,"mc":[{"id":"1.168224555","rc":[{"batb":[[0,2.68,12.35],[1,2.58,13.69],[2,1.01,15.51]],"ltp":0.0,"tv":0.0,"id":7287690},{"batb":[[1,1.5,37.85],[2,1.01,15.51]],"ltp":0.0,"tv":0.0,"id":7414058}]}]}
{"op":"mcm","clk":"1006406273","pt":1580648251153,"mc":[{"id":"1.168224555","rc":[{"batb":[[2,2.56,26.89]],"batl":[[0,2.92,21.85],[1,3.45,180.4]],"ltp":0.0,"tv":0.0,"id":7287690},{"batb":[[0,1.52,116.7]],"batl":[[0,1.65,42.01],[1,2.04,383.01]],"ltp":0.0,"tv":0.0,"id":7414058}]}]}
{"op":"mcm","clk":"1006408390","pt":1580648265465,"mc":[{"id":"1.168224555","rc":[{"batb":[[0,2.58,13.69],[1,2.56,26.89],[2,1.01,15.51]],"ltp":0.0,"tv":0.0,"id":7287690},{"batb":[[0,1.52,80.66]],"ltp":0.0,"tv":0.0,"id":7414058}]}]}
{"op":"mcm","clk":"1006408517","pt":1580648266413,"mc":[{"id":"1.168224555","rc":[{"batb":[[1,1.01,15.51],[2,1.01,0]],"batl":[[0,3.45,180.4],[1,3.45,0]],"ltp":0.0,"tv":0.0,"id":7287690},{"batb":[[0,1.5,37.85],[1,1.01,15.51],[2,1.01,0]],"batl":[[0,2.04,383.01],[1,2.04,0]],"ltp":0.0,"tv":0.0,"id":7414058}]}]}
{"op":"mcm","clk":"1006408766","pt":1580648268375,"mc":[{"id":"1.168224555","rc":[{"batb":[[0,2.62,13.22]],"ltp":0.0,"tv":0.0,"id":7287690},{"batb":[[0,1.49,38.71]],"ltp":0.0,"tv":0.0,"id":7414058}]}]}
{"op":"mcm","clk":"1006410123","pt":1580648279303,"mc":[{"id":"1.168224555","rc":[{"batb":[[1,2.5,27.73],[2,1.01,15.51]],"batl":[[0,2.86,21.85],[1,3.45,180.4]],"ltp":0.0,"tv":0.0,"id":7287690},{"batb":[[0,1.54,77.3],[1,1.49,38.71],[2,1.01,15.51]],"batl":[[0,1.68,42.01],[1,2.04,383.01]],"ltp":0.0,"tv":0.0,"id":7414058}]}]}
{"op":"mcm","clk":"1006410231","pt":1580648280106,"mc":[{"id":"1.168224555","rc":[{"batb":[[1,2.5,42.6]],"ltp":0.0,"tv":0.0,"id":7287690},{"batb":[[0,1.54,111.29],[1,1.51,36.27]],"ltp":0.0,"tv":0.0,"id":7414058}]}]}
{"op":"mcm","clk":"1006411850","pt":1580648292318,"mc":[{"id":"1.168224555","rc":[{"batb":[[0,2.5,42.6],[1,1.01,15.51],[2,1.01,0]],"ltp":0.0,"tv":0.0,"id":7287690},{"batb":[[0,1.54,77.3]],"ltp":0.0,"tv":0.0,"id":7414058}]}]}
{"op":"mcm","clk":"1006412110","pt":1580648294228,"mc":[{"id":"1.168224555","rc":[{"batb":[[0,2.5,14.87]],"batl":[[0,3.45,180.4],[1,3.45,0]],"ltp":0.0,"tv":0.0,"id":7287690},{"batb":[[0,1.51,36.27],[1,1.01,15.51],[2,1.01,0]],"batl":[[0,2.04,383.01],[1,2.04,0]],"ltp":0.0,"tv":0.0,"id":7414058}]}]}
{"op":"mcm","clk":"1006413235","pt":1580648302330,"mc":[{"id":"1.168224555","rc":[{"batb":[[0,2.68,12.27],[1,2.58,13.61],[2,1.01,15.51]],"ltp":0.0,"tv":0.0,"id":7287690},{"batb":[[1,1.49,38.16],[2,1.01,15.51]],"ltp":0.0,"tv":0.0,"id":7414058}]}]}
{"op":"mcm","clk":"1006413324","pt":1580648303132,"mc":[{"id":"1.168224555","rc":[{"batb":[[2,2.54,26.89]],"batl":[[0,2.88,21.85],[1,3.45,180.4]],"ltp":0.0,"tv":0.0,"id":7287690},{"batb":[[0,1.53,78.98],[1,1.51,36.27],[2,1.49,38.16]],"batl":[[0,1.66,42.01],[1,2.04,383.01]],"ltp":0.0,"tv":0.0,"id":7414058}]}]}
{"op":"mcm","clk":"1006415016","pt":1580648316471,"mc":[{"id":"1.168224555","rc":[{"batb":[[0,2.58,13.61],[1,1.01,15.51],[2,2.54,0]],"batl":[[0,3.45,180.4],[1,3.45,0]],"ltp":0.0,"tv":0.0,"id":7287690},{"batb":[[0,1.49,38.16],[1,1.01,15.51],[2,1.49,0]],"batl":[[0,2.04,383.01],[1,2.04,0]],"ltp":0.0,"tv":0.0,"id":7414058}]}]}
{"op":"mcm","clk":"1006418083","pt":1580648341417,"mc":[{"id":"1.168224555","rc":[{"batl":[[0,1.68,42.01],[1,2.04,383.01]],"ltp":0.0,"tv":0.0,"id":7414058}]}]}
{"op":"mcm","clk":"1006418230","pt":1580648342290,"mc":[{"id":"1.168224555","rc":[{"batb":[[1,2.48,42.91],[2,1.01,15.51]],"batl":[[0,2.82,22.69]],"ltp":0.0,"tv":0.0,"id":7287690},{"batb":[[0,1.55,108.82],[1,1.52,35.49],[2,1.01,15.51]],"ltp":0.0,"tv":0.0,"id":7414058}]}]}
{"op":"mcm","clk":"1006418340","pt":1580648343088,"mc":[{"id":"1.168224555","rc":[{"batl":[[1,3.3,191.92]],"ltp":0.0,"tv":0.0,"id":7287690}]}]}
{"op":"mcm","clk":"1006419943","pt":1580648356428,"mc":[{"id":"1.168224555","rc":[{"batb":[[0,2.48,42.91],[1,1.01,15.51],[2,1.01,0]],"ltp":0.0,"tv":0.0,"id":7287690},{"batb":[[0,1.55,75.62]],"ltp":0.0,"tv":0.0,"id":7414058}]}]}
{"op":"mcm","clk":"1006420188","pt":1580648358145,"mc":[{"id":"1.168224555","rc":[{"batb":[[0,2.48,15.19]],"batl":[[0,3.3,191.92],[1,3.3,0]],"ltp":0.0,"tv":0.0,"id":7287690},{"batb":[[0,1.52,35.49],[1,1.01,15.51],[2,1.01,0]],"batl":[[0,2.04,383.01],[1,2.04,0]],"ltp":0.0,"tv":0.0,"id":7414058}]}]}
{"op":"mcm","clk":"1006422108","pt":1580648373433,"mc":[{"id":"1.168224555","rc":[{"batb":[[1,2.42,29.41],[2,2.36,17.31]],"batl":[[0,2.76,23.53],[1,3.3,191.92]],"ltp":0.0,"tv":0.0,"id":7287690},{"batb":[[0,1.59,30.45],[1,1.57,73.1],[2,1.55,32.89]],"batl":[[0,1.71,42.01],[1,2.04,383.01]],"ltp":0.0,"tv":0.0,"id":7414058}]}]}
{"op":"mcm","clk":"1006423609","pt":1580648384333,"mc":[{"id":"1.168224555","rc":[{"batb":[[0,2.42,29.41],[1,2.36,17.31],[2,1.01,15.51]],"ltp":0.0,"tv":0.0,"id":7287690},{"batb":[[0,1.57,73.1],[1,1.55,32.89],[2,1.01,15.51]],"ltp":0.0,"tv":0.0,"id":7414058}]}]}
{"op":"mcm","clk":"1006423837","pt":1580648386253,"mc":[{"id":"1.168224555","rc":[{"batb":[[0,2.36,17.31],[1,1.01,15.51],[2,1.01,0]],"batl":[[0,3.3,191.92],[1,3.3,0]],"ltp":0.0,"tv":0.0,"id":7287690},{"batb":[[0,1.55,32.89],[1,1.01,15.51],[2,1.01,0]],"batl":[[0,2.04,383.01],[1,2.04,0]],"ltp":0.0,"tv":0.0,"id":7414058}]}]}
{"op":"mcm","clk":"1006424941","pt":1580648394433,"mc":[{"id":"1.168224555","rc":[{"batb":[[0,2.58,13.77],[1,2.48,15.19],[2,1.01,15.51]],"ltp":0.0,"tv":0.0,"id":7287690},{"batb":[[1,1.52,35.33],[2,1.01,15.51]],"ltp":0.0,"tv":0.0,"id":7414058}]}]}
{"op":"mcm","clk":"1006425060","pt":1580648395423,"mc":[{"id":"1.168224555","rc":[{"batb":[[2,2.44,28.57]],"batl":[[0,2.78,23.53],[1,3.3,191.92]],"ltp":0.0,"tv":0.0,"id":7287690},{"batb":[[0,1.56,74.78],[1,1.55,32.89],[2,1.52,35.33]],"batl":[[0,1.7,42.01],[1,2.04,383.01]],"ltp":0.0,"tv":0.0,"id":7414058}]}]}
{"op":"mcm","clk":"1006430790","pt":1580648437386,"mc":[{"id":"1.168224555","rc":[{"batb":[[0,2.48,15.19],[1,2.44,28.57],[2,1.01,15.51]],"ltp":0.0,"tv":0.0,"id":7287690},{"batb":[[1,1.52,35.33],[2,1.01,15.51]],"ltp":0.0,"tv":0.0,"id":7414058}]}]}
{"op":"mcm","clk":"1006430886","pt":1580648438238,"mc":[{"id":"1.168224555","rc":[{"batb":[[1,1.01,15.51],[2,1.01,0]],"batl":[[0,3.3,191.92],[1,3.3,0]],"ltp":0.0,"tv":0.0,"id":7287690},{"batb":[[0,1.52,35.33],[1,1.01,15.51],[2,1.01,0]],"batl":[[0,2.04,383.01],[1,2.04,0]],"ltp":0.0,"tv":0.0,"id":7414058}]}]}
{"op":"mcm","clk":"1006431105","pt":1580648439911,"mc":[{"id":"1.168224555","rc":[{"batb":[[0,2.46,15.5]],"ltp":0.0,"tv":0.0,"id":7287690},{"batb":[[0,1.53,34.86]],"ltp":0.0,"tv":0.0,"id":7414058}]}]}
{"op":"mcm","clk":"1006432352","pt":1580648450458,"mc":[{"id":"1.168224555","rc":[{"batb":[[0,2.64,12.9],[1,2.56,14.08],[2,1.01,15.51]],"ltp":0.0,"tv":0.0,"id":7287690},{"batb":[[1,1.51,36.43],[2,1.01,15.51]],"ltp":0.0,"tv":0.0,"id":7414058}]}]}
{"op":"mcm","clk":"1006432486","pt":1580648451434,"mc":[{"id":"1.168224555","rc":[{"batb":[[2,2.48,27.73]],"batl":[[0,2.82,22.69],[1,3.3,191.92]],"ltp":0.0,"tv":0.0,"id":7287690},{"batb":[[0,1.55,75.62],[1,1.53,34.86],[2,1.51,36.43]],"batl":[[0,1.69,42.01],[1,2.04,383.01]],"ltp":0.0,"tv":0.0,"id":7414058}]}]}
{"op":"mcm","clk":"1006433580","pt":1580648458984,"mc":[{"id":"1.168224555","rc":[{"batb":[[0,2.56,14.08],[1,2.48,27.73],[2,1.01,15.51]],"ltp":0.0,"tv":0.0,"id":7287690},{"batb":[[1,1.51,36.43],[2,1.01,15.51]],"ltp":0.0,"tv":0.0,"id":7414058}]}]}
{"op":"mcm","clk":"1006433762","pt":1580648460462,"mc":[{"id":"1.168224555","rc":[{"batb":[[1,1.01,15.51],[2,1.01,0]],"batl":[[0,3.3,191.92],[1,3.3,0]],"ltp":0.0,"tv":0.0,"id":7287690},{"batb":[[0,1.51,36.43],[1,1.01,15.51],[2,1.01,0]],"batl":[[0,2.04,383.01],[1,2.04,0]],"ltp":0.0,"tv":0.0,"id":7414058}]}]}
{"op":"mcm","clk":"1006435025","pt":1580648469457,"mc":[{"id":"1.168224555","rc":[{"batb":[[0,2.7,12.2],[1,2.64,12.98],[2,2.52,26.89]],"batl":[[0,2.88,21.85],[1,3.3,191.92]],"ltp":0.0,"tv":0.0,"id":7287690},{"batb":[[0,1.53,78.98],[1,1.51,36.43],[2,1.48,39.18]],"batl":[[0,1.67,42.01],[1,2.04,383.01]],"ltp":0.0,"tv":0.0,"id":7414058}]}]}
{"op":"mcm","clk":"1006438068","pt":1580648492988,"mc":[{"id":"1.168224555","rc":[{"batb":[[0,2.64,12.98],[1,2.52,26.89],[2,1.01,15.51]],"ltp":0.0,"tv":0.0,"id":7287690},{"batb":[[1,1.48,39.18],[2,1.01,15.51]],"ltp":0.0,"tv":0.0,"id":7414058}]}]}
{"op":"mcm","clk":"1006438209","pt":1580648494267,"mc":[{"id":"1.168224555","rc":[{"batb":[[1,1.01,15.51],[2,1.01,0]],"batl":[[0,3.3,191.92],[1,3.3,0]],"ltp":0.0,"tv":0.0,"id":7287690},{"batb":[[0,1.48,39.18],[1,1.01,15.51],[2,1.01,0]],"batl":[[0,2.04,383.01],[1,2.04,0]],"ltp":0.0,"tv":0.0,"id":7414058}]}]}
{"op":"mcm","clk":"1006440094","pt":1580648509382,"mc":[{"id":"1.168224555","rc":[{"batb":[[1,2.56,13.93],[2,2.5,27.73]],"batl":[[0,2.86,21.85],[1,3.3,191.92]],"ltp":0.0,"tv":0.0,"id":7287690},{"batb":[[0,1.54,77.3],[1,1.53,34.62],[2,1.51,36.82]],"batl":[[0,1.68,42.01],[1,2.04,383.01]],"ltp":0.0,"tv":0.0,"id":7414058}]}]}
{"op":"mcm","clk":"1006441100","pt":1580648516331,"mc":[{"id":"1.168224555","rc":[{"batb":[[0,2.56,13.93],[1,1.01,15.51],[2,2.5,0]],"batl":[[0,3.3,191.92],[1,3.3,0]],"ltp":0.0,"tv":0.0,"id":7287690},{"batb":[[0,1.51,36.82],[1,1.01,15.51],[2,1.51,0]],"batl":[[0,2.04,383.01],[1,2.04,0]],"ltp":0.0,"tv":0.0,"id":7414058}]}]}
{"op":"mcm","clk":"1006445072","pt":1580648545252,"mc":[{"id":"1.168224555","rc":[{"batb":[[0,2.7,12.04],[1,2.66,12.75],[2,2.56,26.89]],"batl":[[0,2.92,21.85]],"ltp":0.0,"tv":0.0,"id":7287690},{"batb":[[0,1.52,80.66],[1,1.51,36.82],[2,1.48,40.13]],"batl":[[0,1.66,42.01],[1,2.04,383.01]],"ltp":0.0,"tv":0.0,"id":7414058}]}]}
{"op":"mcm","clk":"1006445330","pt":1580648547270,"mc":[{"id":"1.168224555","rc":[{"batl":[[1,3.65,170.41]],"ltp":0.0,"tv":0.0,"id":7287690}]}]}
{"op":"mcm","clk":"1006448614","pt":1580648572277,"mc":[{"id":"1.168224555","rc":[{"batb":[[0,2.66,12.75],[1,1.01,15.51],[2,2.56,0]],"batl":[[0,3.65,170.41],[1,3.65,0]],"ltp":0.0,"tv":0.0,"id":7287690},{"batb":[[0,1.48,40.13],[1,1.01,15.51],[2,1.48,0]],"batl":[[0,2.04,383.01],[1,2.04,0]],"ltp":0.0,"tv":0.0,"id":7414058}]}]}
{"op":"mcm","clk":"1006450635","pt":1580648587422,"mc":[{"id":"1.168224555","rc":[{"batb":[[1,2.6,26.05],[2,1.01,15.51]],"batl":[[0,2.98,21],[1,3.65,170.41]],"ltp":0.0,"tv":0.0,"id":7287690},{"batb":[[0,1.51,82.34],[1,1.48,40.13],[2,1.01,15.51]],"batl":[[0,1.64,42.01],[1,2.04,383.01]],"ltp":0.0,"tv":0.0,"id":7414058}]}]}
{"op":"mcm","clk":"1006450754","pt":1580648588297,"mc":[{"id":"1.168224555","rc":[{"batb":[[0,2.82,10.86],[1,2.72,11.8],[2,2.6,26.05]],"ltp":0.0,"tv":0.0,"id":7287690},{"batb":[[2,1.44,43.75]],"ltp":0.0,"tv":0.0,"id":7414058}]}]}
{"op":"mcm","clk":"1006453034","pt":1580648606447,"mc":[{"id":"1.168224555","rc":[{"batb":[[0,2.72,11.8],[1,1.01,15.51],[2,2.6,0]],"batl":[[0,3.65,170.41],[1,3.65,0]],"ltp":0.0,"tv":0.0,"id":7287690},{"batb":[[0,1.44,43.75],[1,1.01,15.51],[2,1.44,0]],"batl":[[0,2.04,383.01],[1,2.04,0]],"ltp":0.0,"tv":0.0,"id":7414058}]}]}
{"op":"mcm","clk":"1006456451","pt":1580648632076,"mc":[{"id":"1.168224555","rc":[{"batb":[[0,2.92,24.63],[1,2.84,10.7],[2,1.01,15.51]],"ltp":0.0,"tv":0.0,"id":7287690},{"batb":[[1,1.41,47.92],[2,1.01,15.51]],"ltp":0.0,"tv":0.0,"id":7414058}]}]}
{"op":"mcm","clk":"1006456601","pt":1580648633261,"mc":[{"id":"1.168224555","rc":[{"batb":[[2,2.64,25.21]],"batl":[[0,3,21],[1,3.65,170.41]],"ltp":0.0,"tv":0.0,"id":7287690},{"batb":[[0,1.49,85.7],[1,1.44,43.75],[2,1.41,47.92]],"batl":[[0,1.62,42.01],[1,2.04,383.01]],"ltp":0.0,"tv":0.0,"id":7414058}]}]}
{"op":"mcm","clk":"1006458602","pt":1580648648710,"mc":[{"id":"1.168224555","rc":[{"batb":[[0,2.84,10.7],[1,2.64,25.21],[2,1.01,15.51]],"ltp":0.0,"tv":0.0,"id":7287690},{"batb":[[1,1.41,47.92],[2,1.01,15.51]],"ltp":0.0,"tv":0.0,"id":7414058}]}]}
{"op":"mcm","clk":"1006458820","pt":1580648650324,"mc":[{"id":"1.168224555","rc":[{"batb":[[1,1.01,15.51],[2,1.01,0]],"batl":[[0,3.65,170.41],[1,3.65,0]],"ltp":0.0,"tv":0.0,"id":7287690},{"batb":[[0,1.41,47.92],[1,1.01,15.51],[2,1.01,0]],"batl":[[0,2.04,383.01],[1,2.04,0]],"ltp":0.0,"tv":0.0,"id":7414058}]}]}
{"op":"mcm","clk":"1006462857","pt":1580648679219,"mc":[{"id":"1.168224555","rc":[{"batb":[[0,3.05,21.95],[1,2.94,24.47],[2,2.78,23.53]],"batl":[[0,3.2,18.48]],"ltp":0.0,"tv":0.0,"id":7287690},{"batb":[[0,1.45,93.26],[1,1.41,47.92],[2,1.4,50.12]],"batl":[[0,1.57,42.01]],"ltp":0.0,"tv":0.0,"id":7414058}]}]}
{"op":"mcm","clk":"1006463261","pt":1580648682399,"mc":[{"id":"1.168224555","rc":[{"batl":[[1,4.2,148.03]],"ltp":0.0,"tv":0.0,"id":7287690},{"batl":[[1,1.89,435.28]],"ltp":0.0,"tv":0.0,"id":7414058}]}]}
{"op":"mcm","clk":"1006476109","pt":1580648775055,"mc":[{"id":"1.168224555","rc":[{"batb":[[0,2.94,24.47],[1,2.78,23.53],[2,1.01,15.51]],"ltp":0.0,"tv":0.0,"id":7287690},{"batb":[[1,1.4,50.12],[2,1.01,15.51]],"ltp":0.0,"tv":0.0,"id":7414058}]}]}
{"op":"mcm","clk":"1006476294","pt":1580648776387,"mc":[{"id":"1.168224555","rc":[{"batb":[[1,1.01,15.51],[2,1.01,0]],"batl":[[0,4.2,148.03],[1,4.2,0]],"ltp":0.0,"tv":0.0,"id":7287690},{"batb":[[0,1.4,50.12],[1,1.01,15.51],[2,1.01,0]],"batl":[[0,1.89,435.28],[1,1.89,0]],"ltp":0.0,"tv":0.0,"id":7414058}]}]}
{"op":"mcm","clk":"1006477587","pt":1580648785299,"mc":[{"id":"1.168224555","rc":[{"batb":[[0,3.1,20.61],[1,3,23.05],[2,2.8,22.69]],"batl":[[0,3.2,18.48],[1,4.2,148.03]],"ltp":0.0,"tv":0.0,"id":7287690},{"batb":[[0,1.45,93.26],[1,1.4,50.12],[2,1.39,52.32]],"batl":[[0,1.56,42.01],[1,1.89,435.28]],"ltp":0.0,"tv":0.0,"id":7414058}]}]}
{"op":"mcm","clk":"1006478485","pt":1580648790976,"mc":[{"id":"1.168224555","rc":[{"batb":[[0,3,23.05],[1,2.8,22.69],[2,1.01,15.51]],"ltp":0.0,"tv":0.0,"id":7287690},{"batb":[[1,1.39,52.32],[2,1.01,15.51]],"ltp":0.0,"tv":0.0,"id":7414058}]}]}
{"op":"mcm","clk":"1006478682","pt":1580648792304,"mc":[{"id":"1.168224555","rc":[{"batb":[[1,1.01,15.51],[2,1.01,0]],"batl":[[0,4.2,148.03],[1,4.2,0]],"ltp":0.0,"tv":0.0,"id":7287690},{"batb":[[0,1.39,52.32],[1,1.01,15.51],[2,1.01,0]],"batl":[[0,1.89,435.28],[1,1.89,0]],"ltp":0.0,"tv":0.0,"id":7414058}]}]}
{"op":"mcm","clk":"1006480014","pt":1580648801300,"mc":[{"id":"1.168224555","rc":[{"batb":[[0,3.2,19.51],[1,3.05,21.79],[2,2.84,22.69]],"batl":[[0,3.25,18.48],[1,4.2,148.03]],"ltp":0.0,"tv":0.0,"id":7287690},{"batb":[[0,1.44,94.94],[1,1.39,52.32],[2,1.37,54.76]],"batl":[[0,1.55,42.01],[1,1.89,435.28]],"ltp":0.0,"tv":0.0,"id":7414058}]}]}
{"op":"mcm","clk":"1006481755","pt":1580648812934,"mc":[{"id":"1.168224555","rc":[{"batb":[[0,3.05,21.79],[1,2.84,22.69],[2,1.01,15.51]],"ltp":0.0,"tv":0.0,"id":7287690},{"batb":[[1,1.37,54.76],[2,1.01,15.51]],"ltp":0.0,"tv":0.0,"id":7414058}]}]}
{"op":"mcm","clk":"1006481950","pt":1580648814352,"mc":[{"id":"1.168224555","rc":[{"batb":[[1,1.01,15.51],[2,1.01,0]],"batl":[[0,4.2,148.03],[1,4.2,0]],"ltp":0.0,"tv":0.0,"id":7287690},{"batb":[[0,1.37,54.76],[1,1.01,15.51],[2,1.01,0]],"batl":[[0,1.89,435.28],[1,1.89,0]],"ltp":0.0,"tv":0.0,"id":7414058}]}]}
{"op":"mcm","clk":"1006483111","pt":1580648821346,"mc":[{"id":"1.168224555","rc":[{"batb":[[1,2.94,24.16],[2,2.78,23.53]],"batl":[[0,3.2,18.48],[1,4.2,148.03]],"ltp":0.0,"tv":0.0,"id":7287690},{"batb":[[0,1.45,93.26],[1,1.41,48.15],[2,1.4,50.75]],"batl":[[0,1.57,42.01],[1,1.89,435.28]],"ltp":0.0,"tv":0.0,"id":7414058}]}]}
{"op":"mcm","clk":"1006485201","pt":1580648834435,"mc":[{"id":"1.168224555","rc":[{"batb":[[0,2.94,24.16],[1,1.01,15.51],[2,2.78,0]],"batl":[[0,4.2,148.03],[1,4.2,0]],"ltp":0.0,"tv":0.0,"id":7287690},{"batb":[[0,1.4,50.75],[1,1.01,15.51],[2,1.4,0]],"batl":[[0,1.89,435.28],[1,1.89,0]],"ltp":0.0,"tv":0.0,"id":7414058}]}]}
{"op":"mcm","clk":"1006486182","pt":1580648841476,"mc":[{"id":"1.168224555","rc":[{"batb":[[0,3.15,20.38],[1,3,22.58],[2,2.82,22.69]],"batl":[[0,3.25,18.48],[1,4.2,148.03]],"ltp":0.0,"tv":0.0,"id":7287690},{"batb":[[0,1.45,93.26],[1,1.4,50.75],[2,1.38,52.72]],"batl":[[0,1.56,42.01],[1,1.89,435.28]],"ltp":0.0,"tv":0.0,"id":7414058}]}]}
{"op":"mcm","clk":"1006487259","pt":1580648849285,"mc":[{"id":"1.168224555","rc":[{"batb":[[0,3,22.58],[1,2.82,22.69],[2,1.01,15.51]],"ltp":0.0,"tv":0.0,"id":7287690},{"batb":[[1,1.38,52.72],[2,1.01,15.51]],"ltp":0.0,"tv":0.0,"id":7414058}]}]}
{"op":"mcm","clk":"1006487411","pt":1580648850290,"mc":[{"id":"1.168224555","rc":[{"batb":[[1,1.01,15.51],[2,1.01,0]],"batl":[[0,4.2,148.03],[1,4.2,0]],"ltp":0.0,"tv":0.0,"id":7287690},{"batb":[[0,1.38,52.72],[1,1.01,15.51],[2,1.01,0]],"batl":[[0,1.89,435.28],[1,1.89,0]],"ltp":0.0,"tv":0.0,"id":7414058}]}]}
{"op":"mcm","clk":"1006489072","pt":1580648861298,"mc":[{"id":"1.168224555","rc":[{"batb":[[0,3.2,19.36],[1,3.1,20.77],[2,2.88,21.85]],"batl":[[0,3.3,17.64],[1,4.2,148.03]],"ltp":0.0,"tv":0.0,"id":7287690},{"batb":[[0,1.43,97.46],[1,1.38,52.72],[2,1.36,57.2]],"batl":[[0,1.54,42.01],[1,1.89,435.28]],"ltp":0.0,"tv":0.0,"id":7414058}]}]}
{"op":"mcm","clk":"1006492226","pt":1580648883146,"mc":[{"id":"1.168224555","rc":[{"batb":[[0,3.1,20.77],[1,2.88,21.85],[2,1.01,15.51]],"ltp":0.0,"tv":0.0,"id":7287690},{"batb":[[1,1.36,57.2],[2,1.01,15.51]],"ltp":0.0,"tv":0.0,"id":7414058}]}]}
{"op":"mcm","clk":"1006492390","pt":1580648884329,"mc":[{"id":"1.168224555","rc":[{"batb":[[1,1.01,15.51],[2,1.01,0]],"batl":[[0,4.2,148.03],[1,4.2,0]],"ltp":0.0,"tv":0.0,"id":7287690},{"batb":[[0,1.36,57.2],[1,1.01,15.51],[2,1.01,0]],"batl":[[0,1.89,435.28],[1,1.89,0]],"ltp":0.0,"tv":0.0,"id":7414058}]}]}
{"op":"mcm","clk":"1006492683","pt":1580648886323,"mc":[{"id":"1.168224555","rc":[{"batb":[[0,1.37,56.1]],"ltp":0.0,"tv":0.0,"id":7414058}]}]}
{"op":"mcm","clk":"1006494899","pt":1580648901362,"mc":[{"id":"1.168224555","rc":[{"batb":[[0,3.3,17.86],[1,3.2,19.43],[2,2.94,21]],"batl":[[0,3.4,16.8],[1,4.2,148.03]],"ltp":0.0,"tv":0.0,"id":7287690},{"batb":[[0,1.42,99.98],[1,1.37,56.1],[2,1.34,61.61]],"batl":[[0,1.53,42.01],[1,1.89,435.28]],"ltp":0.0,"tv":0.0,"id":7414058}]}]}
{"op":"mcm","clk":"1006494981","pt":1580648901949,"mc":[{"id":"1.168224555","rc":[{"batl":[[0,1.89,435.28],[1,1.89,0]],"ltp":0.0,"tv":0.0,"id":7414058}]}]}
{"op":"mcm","clk":"1006495235","pt":1580648904025,"mc":[{"id":"1.168224555","rc":[{"batl":[[0,1.52,42.01],[1,1.89,435.28]],"ltp":0.0,"tv":0.0,"id":7414058}]}]}
{"op":"mcm","clk":"1006496182","pt":1580648910960,"mc":[{"id":"1.168224555","rc":[{"batb":[[0,3.2,19.43],[1,2.94,21],[2,1.01,15.51]],"ltp":0.0,"tv":0.0,"id":7287690},{"batb":[[1,1.34,61.61],[2,1.01,15.51]],"ltp":0.0,"tv":0.0,"id":7414058}]}]}
{"op":"mcm","clk":"1006496405","pt":1580648912447,"mc":[{"id":"1.168224555","rc":[{"batb":[[1,1.01,15.51],[2,1.01,0]],"batl":[[0,4.2,148.03],[1,4.2,0]],"ltp":0.0,"tv":0.0,"id":7287690},{"batb":[[0,1.34,61.61],[1,1.01,15.51],[2,1.01,0]],"batl":[[0,1.89,435.28],[1,1.89,0]],"ltp":0.0,"tv":0.0,"id":7414058}]}]}
{"op":"mcm","clk":"1006496660","pt":1580648914274,"mc":[{"id":"1.168224555","rc":[{"batb":[[0,3.15,19.99]],"ltp":0.0,"tv":0.0,"id":7287690},{"batb":[[0,1.35,60.19]],"ltp":0.0,"tv":0.0,"id":7414058}]}]}
{"op":"mcm","clk":"1006499299","pt":1580648933381,"mc":[{"id":"1.168224555","rc":[{"batb":[[1,3.05,21.79],[2,2.92,21.85]],"batl":[[0,3.35,17.64],[1,4.2,148.03]],"ltp":0.0,"tv":0.0,"id":7287690},{"batb":[[0,1.42,99.98],[1,1.39,51.46],[2,1.37,55.16]],"batl":[[0,1.53,42.01],[1,1.89,435.28]],"ltp":0.0,"tv":0.0,"id":7414058}]}]}
{"op":"mcm","clk":"1006501435","pt":1580648948438,"mc":[{"id":"1.168224555","rc":[{"batb":[[0,3.05,21.79],[1,1.01,15.51],[2,2.92,0]],"batl":[[0,4.2,148.03],[1,4.2,0]],"ltp":0.0,"tv":0.0,"id":7287690},{"batb":[[0,1.37,54.61],[1,1.01,15.51],[2,1.37,0]],"batl":[[0,1.89,435.28],[1,1.89,0]],"ltp":0.0,"tv":0.0,"id":7414058}]}]}
{"op":"mcm","clk":"1006502646","pt":1580648957408,"mc":[{"id":"1.168224555","rc":[{"batb":[[1,2.98,23.6],[2,2.9,21.85]],"batl":[[0,3.35,17.64],[1,4.2,148.03]],"ltp":0.0,"tv":0.0,"id":7287690},{"batb":[[0,1.43,97.46],[1,1.42,47.68],[2,1.39,51.14]],"batl":[[0,1.53,42.01],[1,1.89,435.28]],"ltp":0.0,"tv":0.0,"id":7414058}]}]}
{"op":"mcm","clk":"1006503499","pt":1580648963415,"mc":[{"id":"1.168224555","rc":[{"batb":[[0,2.98,23.6],[1,2.9,21.85],[2,1.01,15.51]],"ltp":0.0,"tv":0.0,"id":7287690},{"batb":[[1,1.39,51.14],[2,1.01,15.51]],"ltp":0.0,"tv":0.0,"id":7414058}]}]}
{"op":"mcm","clk":"1006503630","pt":1580648964314,"mc":[{"id":"1.168224555","rc":[{"batb":[[1,1.01,15.51],[2,1.01,0]],"batl":[[0,4.2,148.03],[1,4.2,0]],"ltp":0.0,"tv":0.0,"id":7287690},{"batb":[[0,1.39,51.14],[1,1.01,15.51],[2,1.01,0]],"batl":[[0,1.89,435.28],[1,1.89,0]],"ltp":0.0,"tv":0.0,"id":7414058}]}]}
{"op":"mcm","clk":"1006505675","pt":1580648979347,"mc":[{"id":"1.168224555","rc":[{"batb":[[0,3.15,20.14],[1,3.05,21.87],[2,2.94,21]],"batl":[[0,3.4,16.8],[1,4.2,148.03]],"ltp":0.0,"tv":0.0,"id":7287690},{"batb":[[0,1.42,99.98],[1,1.39,51.14],[2,1.37,55.71]],"batl":[[0,1.52,42.01],[1,1.89,435.28]],"ltp":0.0,"tv":0.0,"id":7414058}]}]}
{"op":"mcm","clk":"1006507467","pt":1580648992351,"mc":[{"id":"1.168224555","rc":[{"batb":[[0,3.05,21.87],[1,1.01,15.51],[2,2.94,0]],"batl":[[0,4.2,148.03],[1,4.2,0]],"ltp":0.0,"tv":0.0,"id":7287690},{"batb":[[0,1.37,55.71],[1,1.01,15.51],[2,1.37,0]],"batl":[[0,1.89,435.28],[1,1.89,0]],"ltp":0.0,"tv":0.0,"id":7414058}]}]}
{"op":"mcm","clk":"1006510461","pt":1580649013302,"mc":[{"id":"1.168224555","rc":[{"batb":[[1,2.92,21.85],[2,1.01,15.51]],"batl":[[0,3.35,17.64],[1,4.2,148.03]],"ltp":0.0,"tv":0.0,"id":7287690},{"batb":[[0,1.42,99.98],[1,1.37,55.71],[2,1.01,15.51]],"batl":[[0,1.53,42.01],[1,1.89,435.28]],"ltp":0.0,"tv":0.0,"id":7414058}]}]}
{"op":"mcm","clk":"1006510559","pt":1580649014003,"mc":[{"id":"1.168224555","rc":[{"batb":[[1,2.98,23.37],[2,2.92,21.85]],"ltp":0.0,"tv":0.0,"id":7287690},{"batb":[[1,1.41,48],[2,1.39,51.06]],"ltp":0.0,"tv":0.0,"id":7414058}]}]}
{"op":"mcm","clk":"1006512907","pt":1580649029329,"mc":[{"id":"1.168224555","rc":[{"batb":[[0,2.98,23.37],[1,2.92,21.85],[2,1.01,15.51]],"ltp":0.0,"tv":0.0,"id":7287690},{"batb":[[1,1.39,51.06],[2,1.01,15.51]],"ltp":0.0,"tv":0.0,"id":7414058}]}]}
{"op":"mcm","clk":"1006513083","pt":1580649030349,"mc":[{"id":"1.168224555","rc":[{"batb":[[1,1.01,15.51],[2,1.01,0]],"batl":[[0,4.2,148.03],[1,4.2,0]],"ltp":0.0,"tv":0.0,"id":7287690},{"batb":[[0,1.39,51.06],[1,1.01,15.51],[2,1.01,0]],"batl":[[0,1.89,435.28],[1,1.89,0]],"ltp":0.0,"tv":0.0,"id":7414058}]}]}
{"op":"mcm","clk":"1006515353","pt":1580649044349,"mc":[{"id":"1.168224555","rc":[{"batb":[[0,3.15,20.22],[1,3.05,21.87],[2,1.01,15.51]],"ltp":0.0,"tv":0.0,"id":7287690},{"batb":[[1,1.37,55.39],[2,1.01,15.51]],"ltp":0.0,"tv":0.0,"id":7414058}]}]}
{"op":"mcm","clk":"1006515506","pt":1580649045333,"mc":[{"id":"1.168224555","rc":[{"batb":[[2,2.96,21]],"batl":[[0,3.4,16.8],[1,4.2,148.03]],"ltp":0.0,"tv":0.0,"id":7287690},{"batb":[[0,1.41,101.66],[1,1.39,51.06],[2,1.37,55.39]],"batl":[[0,1.52,42.01],[1,1.89,435.28]],"ltp":0.0,"tv":0.0,"id":7414058}]}]}
{"op":"mcm","clk":"1006516933","pt":1580649055459,"mc":[{"id":"1.168224555","rc":[{"batb":[[0,3.05,21.87],[1,2.96,21],[2,1.01,15.51]],"ltp":0.0,"tv":0.0,"id":7287690},{"batb":[[1,1.37,55.39],[2,1.01,15.51]],"ltp":0.0,"tv":0.0,"id":7414058}]}]}
{"op":"mcm","clk":"1006517074","pt":1580649056473,"mc":[{"id":"1.168224555","rc":[{"batb":[[1,1.01,15.51],[2,1.01,0]],"batl":[[0,4.2,148.03],[1,4.2,0]],"ltp":0.0,"tv":0.0,"id":7287690},{"batb":[[0,1.37,55.39],[1,1.01,15.51],[2,1.01,0]],"batl":[[0,1.89,435.28],[1,1.89,0]],"ltp":0.0,"tv":0.0,"id":7414058}]}]}
{"op":"mcm","clk":"1006520266","pt":1580649077390,"mc":[{"id":"1.168224555","rc":[{"batb":[[0,3.3,18.1],[1,3.15,20.22],[2,3.05,21.87]],"batl":[[0,3.45,16.8]],"ltp":0.0,"tv":0.0,"id":7287690},{"batb":[[0,1.41,101.66],[1,1.37,55.39],[2,1.34,61.77]],"batl":[[0,1.51,42.01]],"ltp":0.0,"tv":0.0,"id":7414058}]}]}
{"op":"mcm","clk":"1006520370","pt":1580649078124,"mc":[{"id":"1.168224555","rc":[{"batb":[[2,3,21]],"ltp":0.0,"tv":0.0,"id":7287690}]}]}
{"op":"mcm","clk":"1006520636","pt":1580649080077,"mc":[{"id":"1.168224555","rc":[{"batl":[[1,4.9,126.27]],"ltp":0.0,"tv":0.0,"id":7287690},{"batl":[[1,1.77,500.61]],"ltp":0.0,"tv":0.0,"id":7414058}]}]}
{"op":"mcm","clk":"1006522894","pt":1580649095614,"mc":[{"id":"1.168224555","rc":[{"batb":[[0,3.15,20.22],[1,3,21],[2,1.01,15.51]],"ltp":0.0,"tv":0.0,"id":7287690},{"batb":[[1,1.34,61.77],[2,1.01,15.51]],"ltp":0.0,"tv":0.0,"id":7414058}]}]}
{"op":"mcm","clk":"1006523170","pt":1580649097321,"mc":[{"id":"1.168224555","rc":[{"batb":[[1,1.01,15.51],[2,1.01,0]],"batl":[[0,4.9,126.27],[1,4.9,0]],"ltp":0.0,"tv":0.0,"id":7287690},{"batb":[[0,1.34,61.77],[1,1.01,15.51],[2,1.01,0]],"batl":[[0,1.77,500.61],[1,1.77,0]],"ltp":0.0,"tv":0.0,"id":7414058}]}]}
{"op":"mcm","clk":"1006527096","pt":1580649121347,"mc":[{"id":"1.168224555","rc":[{"batb":[[1,3.05,21.95],[2,2.98,21]],"batl":[[0,3.45,16.8]],"ltp":0.0,"tv":0.0,"id":7287690},{"batb":[[0,1.41,101.66],[1,1.39,50.99],[2,1.37,55.23]],"batl":[[0,1.52,42.01],[1,1.77,500.61]],"ltp":0.0,"tv":0.0,"id":7414058}]}]}
{"op":"mcm","clk":"1006527482","pt":1580649123555,"mc":[{"id":"1.168224555","rc":[{"batl":[[1,4.6,136.05]],"ltp":0.0,"tv":0.0,"id":7287690}]}]}
{"op":"mcm","clk":"1006529944","pt":1580649137378,"mc":[{"id":"1.168224555","rc":[{"batb":[[0,3.05,21.95],[1,2.98,21],[2,1.01,15.51]],"ltp":0.0,"tv":0.0,"id":7287690},{"batb":[[1,1.37,55.23],[2,1.01,15.51]],"ltp":0.0,"tv":0.0,"id":7414058}]}]}
{"op":"mcm","clk":"1006530095","pt":1580649138462,"mc":[{"id":"1.168224555","rc":[{"batb":[[1,1.01,15.51],[2,1.01,0]],"batl":[[0,4.6,136.05],[1,4.6,0]],"ltp":0.0,"tv":0.0,"id":7287690},{"batb":[[0,1.37,55.23],[1,1.01,15.51],[2,1.01,0]],"batl":[[0,1.77,500.61],[1,1.77,0]],"ltp":0.0,"tv":0.0,"id":7414058}]}]}
{"op":"mcm","clk":"1006532716","pt":1580649157376,"mc":[{"id":"1.168224555","rc":[{"batb":[[1,2.98,23.6],[2,2.94,21]],"batl":[[0,3.4,16.8],[1,4.6,136.05]],"ltp":0.0,"tv":0.0,"id":7287690},{"batb":[[0,1.42,47.84],[1,1.41,101.66],[2,1.4,50.67]],"batl":[[0,1.52,42.01],[1,1.77,500.61]],"ltp":0.0,"tv":0.0,"id":7414058}]}]}
{"op":"mcm","clk":"1006534273","pt":1580649168422,"mc":[{"id":"1.168224555","rc":[{"batb":[[0,2.98,23.6],[1,1.01,15.51],[2,2.94,0]],"batl":[[0,4.6,136.05],[1,4.6,0]],"ltp":0.0,"tv":0.0,"id":7287690},{"batb":[[0,1.4,50.67],[1,1.01,15.51],[2,1.4,0]],"batl":[[0,1.77,500.61],[1,1.77,0]],"ltp":0.0,"tv":0.0,"id":7414058}]}]}
{"op":"mcm","clk":"1006538761","pt":1580649198429,"mc":[{"id":"1.168224555","rc":[{"batb":[[0,3.15,20.38],[1,3.05,22.19],[2,3,449.77]],"ltp":0.0,"tv":0.0,"id":7287690},{"batb":[[1,1.37,54.92],[2,1.01,15.51]],"ltp":0.0,"tv":0.0,"id":7414058}]}]}
{"op":"mcm","clk":"1006538930","pt":1580649199486,"mc":[{"id":"1.168224555","rc":[{"batb":[[2,2.98,21]],"batl":[[0,3.45,16.8],[1,4.6,136.05]],"ltp":0.0,"tv":0.0,"id":7287690},{"batb":[[0,1.41,101.66],[1,1.4,50.67],[2,1.37,54.92]],"batl":[[0,1.51,42.01],[1,1.77,500.61]],"ltp":0.0,"tv":0.0,"id":7414058}]}]}
{"op":"mcm","clk":"1006541544","pt":1580649216460,"mc":[{"id":"1.168224555","rc":[{"batb":[[0,3.05,22.19],[1,1.01,15.51],[2,2.98,0]],"batl":[[0,4.6,136.05],[1,4.6,0]],"ltp":0.0,"tv":0.0,"id":7287690},{"batb":[[0,1.37,54.92],[1,1.01,15.51],[2,1.37,0]],"batl":[[0,1.77,500.61],[1,1.77,0]],"ltp":0.0,"tv":0.0,"id":7414058}]}]}
{"op":"mcm","clk":"1006543770","pt":1580649230447,"mc":[{"id":"1.168224555","rc":[{"batb":[[1,2.98,23.68],[2,1.01,15.51]],"ltp":0.0,"tv":0.0,"id":7287690},{"batb":[[0,1.42,47.52],[1,1.39,51.06],[2,1.37,54.92]],"ltp":0.0,"tv":0.0,"id":7414058}]}]}
{"op":"mcm","clk":"1006543932","pt":1580649231475,"mc":[{"id":"1.168224555","rc":[{"batb":[[2,2.96,21]],"batl":[[0,3.4,16.8],[1,4.6,136.05]],"ltp":0.0,"tv":0.0,"id":7287690},{"batb":[[1,1.41,101.66],[2,1.39,51.06]],"batl":[[0,1.52,42.01],[1,1.77,500.61]],"ltp":0.0,"tv":0.0,"id":7414058}]}]}
{"op":"mcm","clk":"1006544372","pt":1580649234382,"mc":[{"id":"1.168224555","rc":[{"batl":[[2,1000,0.02]],"ltp":0.0,"tv":0.0,"id":7414058}]}]}
{"op":"mcm","clk":"1006544429","pt":1580649234661,"mc":[{"id":"1.168224555","rc":[{"batl":[[2,1000,0]],"ltp":0.0,"tv":0.0,"id":7414058}]}]}
{"op":"mcm","clk":"1006544942","pt":1580649237768,"mc":[{"id":"1.168224555","rc":[{"trd":[[1.42,0.03]],"batb":[[0,1.42,47.51]],"ltp":1.42,"tv":0.03,"id":7414058}],"tv":0.03}]}
{"op":"mcm","clk":"1006545762","pt":1580649242487,"mc":[{"id":"1.168224555","rc":[{"batb":[[0,2.98,23.68],[1,1.01,15.51],[2,2.96,0]],"batl":[[0,4.6,136.05],[1,4.6,0]],"ltp":0.0,"tv":0.0,"id":7287690},{"batb":[[0,1.39,51.06],[1,1.01,15.51],[2,1.39,0]],"batl":[[0,1.77,500.61],[1,1.77,0]],"ltp":1.42,"tv":0.03,"id":7414058}]}]}
{"op":"mcm","clk":"1006548038","pt":1580649256389,"mc":[{"id":"1.168224555","rc":[{"batb":[[1,2.86,10.46],[2,1.01,15.51]],"ltp":0.0,"tv":0.0,"id":7287690},{"batb":[[0,1.43,45.16],[1,1.41,47.84],[2,1.39,51.06]],"ltp":1.42,"tv":0.03,"id":7414058}]}]}
{"op":"mcm","clk":"1006548206","pt":1580649257406,"mc":[{"id":"1.168224555","rc":[{"batb":[[1,2.92,21.85],[2,2.86,10.46]],"batl":[[0,3.35,17.64]],"ltp":0.0,"tv":0.0,"id":7287690},{"batb":[[1,1.42,99.98],[2,1.41,47.84]],"batl":[[0,1.53,42.01],[1,1.77,500.61]],"ltp":1.42,"tv":0.03,"id":7414058}]}]}
{"op":"mcm","clk":"1006548474","pt":1580649259108,"mc":[{"id":"1.168224555","rc":[{"batl":[[1,4.2,148.03]],"ltp":0.0,"tv":0.0,"id":7287690}]}]}
{"op":"mcm","clk":"1006553571","pt":1580649291358,"mc":[{"id":"1.168224555","rc":[{"batb":[[1,1.42,100]],"ltp":1.42,"tv":0.03,"id":7414058}]}]}
{"op":"mcm","clk":"1006560599","pt":1580649338921,"mc":[{"id":"1.168224555","rc":[{"trd":[[2.98,19.6]],"batb":[[0,2.98,13.88]],"ltp":2.98,"tv":19.6,"id":7287690}],"tv":19.63}]}
{"op":"mcm","clk":"1006561799","pt":1580649347404,"mc":[{"id":"1.168224555","rc":[{"batb":[[0,2.92,21.85],[1,2.86,10.46],[2,1.01,15.51]],"ltp":2.98,"tv":19.6,"id":7287690},{"batb":[[0,1.42,100],[1,1.41,47.84],[2,1.01,15.51]],"ltp":1.42,"tv":0.03,"id":7414058}]}]}
{"op":"mcm","clk":"1006562062","pt":1580649349424,"mc":[{"id":"1.168224555","rc":[{"batb":[[0,2.86,10.46],[1,1.01,15.51],[2,1.01,0]],"batl":[[0,4.2,148.03],[1,4.2,0]],"ltp":2.98,"tv":19.6,"id":7287690},{"batb":[[0,1.41,47.85],[1,1.01,15.51],[2,1.01,0]],"batl":[[0,1.77,500.61],[1,1.77,0]],"ltp":1.42,"tv":0.03,"id":7414058}]}]}
{"op":"mcm","clk":"1006562171","pt":1580649350221,"mc":[{"id":"1.168224555","rc":[{"batb":[[0,2.84,10.62]],"ltp":2.98,"tv":19.6,"id":7287690},{"batb":[[0,1.01,15.52],[1,1.01,0]],"ltp":1.42,"tv":0.03,"id":7414058}]}]}
{"op":"mcm","clk":"1006564068","pt":1580649361842,"mc":[{"id":"1.168224555","rc":[{"batb":[[0,3.05,22.35],[1,2.96,21],[2,2.9,25.1]],"batl":[[0,3.4,16.8],[1,4.2,148.03]],"ltp":2.98,"tv":19.6,"id":7287690},{"batb":[[0,1.43,47.29],[1,1.42,100],[2,1.41,49.88]],"batl":[[0,1.52,42.01],[1,1.77,500.61]],"ltp":1.42,"tv":0.03,"id":7414058}]}]}
{"op":"mcm","clk":"1006566299","pt":1580649375372,"mc":[{"id":"1.168224555","rc":[{"batb":[[0,2.9,25.1],[1,1.01,15.51],[2,2.9,0]],"batl":[[0,4.2,148.03],[1,4.2,0]],"ltp":2.98,"tv":19.6,"id":7287690},{"batb":[[0,1.41,49.9],[1,1.01,15.51],[2,1.41,0]],"batl":[[0,1.77,500.61],[1,1.77,0]],"ltp":1.42,"tv":0.03,"id":7414058}]}]}
{"op":"mcm","clk":"1006569052","pt":1580649392892,"mc":[{"id":"1.168224555","rc":[{"batb":[[1,2.78,11.17],[2,1.01,15.51]],"ltp":2.98,"tv":19.6,"id":7287690},{"batb":[[0,1.46,43.12],[1,1.44,45.64],[2,1.01,15.52]],"ltp":1.42,"tv":0.03,"id":7414058}]}]}
{"op":"mcm","clk":"1006569182","pt":1580649393796,"mc":[{"id":"1.168224555","rc":[{"batb":[[1,2.88,21.85],[2,2.78,11.17]],"batl":[[0,3.3,17.64],[1,4.2,148.03]],"ltp":2.98,"tv":19.6,"id":7287690},{"batb":[[2,1.43,97.46]],"batl":[[0,1.54,42.01],[1,1.77,500.61]],"ltp":1.42,"tv":0.03,"id":7414058}]}]}
{"op":"mcm","clk":"1006570751","pt":1580649404376,"mc":[{"id":"1.168224555","rc":[{"batb":[[0,2.88,21.85],[1,2.78,11.17],[2,1.01,15.51]],"ltp":2.98,"tv":19.6,"id":7287690},{"batb":[[0,1.44,45.64],[1,1.43,97.46],[2,1.01,15.52]],"ltp":1.42,"tv":0.03,"id":7414058}]}]}
{"op":"mcm","clk":"1006570818","pt":1580649404918,"mc":[{"id":"1.168224555","rc":[{"batb":[[0,2.78,11.17],[1,1.01,15.51],[2,1.01,0]],"batl":[[0,4.2,148.03],[1,4.2,0]],"ltp":2.98,"tv":19.6,"id":7287690},{"batb":[[1,1.01,15.52],[2,1.01,0]],"batl":[[0,1.77,500.61],[1,1.77,0]],"ltp":1.42,"tv":0.03,"id":7414058}]}]}
{"op":"mcm","clk":"1006573504","pt":1580649423233,"mc":[{"id":"1.168224555","rc":[{"batb":[[1,2.66,12.51],[2,1.01,15.51]],"ltp":2.98,"tv":19.6,"id":7287690},{"batb":[[0,1.49,39.18],[1,1.47,41.94],[2,1.01,15.52]],"ltp":1.42,"tv":0.03,"id":7414058}]}]}
{"op":"mcm","clk":"1006573633","pt":1580649424132,"mc":[{"id":"1.168224555","rc":[{"batb":[[0,2.8,22.69],[1,2.78,11.17],[2,2.66,12.51]],"batl":[[0,3.25,18.48],[1,4.2,148.03]],"ltp":2.98,"tv":19.6,"id":7287690},{"batl":[[0,1.55,42.01],[1,1.77,500.61]],"ltp":1.42,"tv":0.03,"id":7414058}]}]}
{"op":"mcm","clk":"1006573837","pt":1580649425429,"mc":[{"id":"1.168224555","rc":[{"batb":[[2,1.45,93.26]],"ltp":1.42,"tv":0.03,"id":7414058}]}]}
{"op":"mcm","clk":"1006575205","pt":1580649434838,"mc":[{"id":"1.168224555","rc":[{"batb":[[0,2.66,12.51],[1,1.01,15.51],[2,2.66,0]],"batl":[[0,4.2,148.03],[1,4.2,0]],"ltp":2.98,"tv":19.6,"id":7287690},{"batb":[[0,1.47,41.94],[1,1.01,15.52],[2,1.45,0]],"batl":[[0,1.77,500.61],[1,1.77,0]],"ltp":1.42,"tv":0.03,"id":7414058}]}]}
{"op":"mcm","clk":"1006576380","pt":1580649444044,"mc":[{"id":"1.168224555","rc":[{"batb":[[0,2.86,10.39],[1,2.8,22.69],[2,2.72,11.8]],"batl":[[0,3.25,18.48],[1,4.2,148.03]],"ltp":2.98,"tv":19.6,"id":7287690},{"batb":[[1,1.45,44.14],[2,1.44,94.94]],"batl":[[0,1.55,42.01],[1,1.77,500.61]],"ltp":1.42,"tv":0.03,"id":7414058}]}]}
{"op":"mcm","clk":"1006578625","pt":1580649459469,"mc":[{"id":"1.168224555","rc":[{"batb":[[0,2.8,22.69],[1,2.72,11.8],[2,1.01,15.51]],"ltp":2.98,"tv":19.6,"id":7287690},{"batb":[[0,1.45,44.14],[1,1.44,94.94],[2,1.01,15.52]],"ltp":1.42,"tv":0.03,"id":7414058}]}]}
{"op":"mcm","clk":"1006578864","pt":1580649461270,"mc":[{"id":"1.168224555","rc":[{"batb":[[0,2.72,11.8],[1,1.01,15.51],[2,1.01,0]],"batl":[[0,4.2,148.03],[1,4.2,0]],"ltp":2.98,"tv":19.6,"id":7287690},{"batb":[[1,1.01,15.52],[2,1.01,0]],"batl":[[0,1.77,500.61],[1,1.77,0]],"ltp":1.42,"tv":0.03,"id":7414058}]}]}
{"op":"mcm","clk":"1006581007","pt":1580649477084,"mc":[{"id":"1.168224555","rc":[{"batb":[[0,2.94,24.31],[1,2.82,10.86],[2,1.01,15.51]],"ltp":2.98,"tv":19.6,"id":7287690},{"batb":[[1,1.43,46.5],[2,1.01,15.52]],"ltp":1.42,"tv":0.03,"id":7414058}]}]}
{"op":"mcm","clk":"1006581213","pt":1580649478475,"mc":[{"id":"1.168224555","rc":[{"batb":[[1,2.84,22.69],[2,2.82,10.86]],"batl":[[0,3.3,17.64],[1,4.2,148.03]],"ltp":2.98,"tv":19.6,"id":7287690},{"batb":[[1,1.43,143.96]],"batl":[[0,1.54,42.01],[1,1.77,500.61]],"ltp":1.42,"tv":0.03,"id":7414058}]}]}
{"op":"mcm","clk":"1006583634","pt":1580649494823,"mc":[{"id":"1.168224555","rc":[{"batb":[[0,2.82,10.86],[1,1.01,15.51],[2,2.82,0]],"batl":[[0,4.2,148.03],[1,4.2,0]],"ltp":2.98,"tv":19.6,"id":7287690},{"batb":[[0,1.43,46.5],[1,1.01,15.52],[2,1.01,0]],"batl":[[0,1.77,500.61],[1,1.77,0]],"ltp":1.42,"tv":0.03,"id":7414058}]}]}
{"op":"mcm","clk":"1006584089","pt":1580649498218,"mc":[{"id":"1.168224555","rc":[{"batb":[[0,2.84,10.62]],"ltp":2.98,"tv":19.6,"id":7287690}]}]}
{"op":"mcm","clk":"1006586444","pt":1580649515315,"mc":[{"id":"1.168224555","rc":[{"batb":[[0,1.43,234.7],[1,1.42,219.44],[2,1.01,15.51]],"batl":[[0,1.47,164.12],[1,1.48,180.64],[2,1.77,500.61]],"ltp":1.42,"tv":0.03,"id":7414058}]}]}
{"op":"mcm","clk":"1006586559","pt":1580649516235,"mc":[{"id":"1.168224555","rc":[{"batb":[[0,3.05,22.35],[1,2.9,21.85],[2,2.76,11.49]],"batl":[[0,3.35,17.64],[1,4.2,148.03]],"ltp":2.98,"tv":19.6,"id":7287690},{"batb":[[0,1.43,332.16],[2,1.34,63.02]],"batl":[[2,1.53,42.01]],"ltp":1.42,"tv":0.03,"id":7414058}]}]}
{"op":"mcm","clk":"1006591934","pt":1580649553463,"mc":[{"id":"1.168224555","rc":[{"batb":[[1,2.76,11.49],[2,1.01,15.51]],"batl":[[0,4.2,148.03],[1,4.2,0]],"ltp":2.98,"tv":19.6,"id":7287690},{"batb":[[0,1.43,197.15]],"batl":[[2,1.77,500.61]],"ltp":1.42,"tv":0.03,"id":7414058}]}]}
{"op":"mcm","clk":"1006592407","pt":1580649556434,"mc":[{"id":"1.168224555","rc":[{"batb":[[1,2.96,21],[2,2.76,11.49]],"batl":[[0,3.4,16.8],[1,4.2,148.03]],"ltp":2.98,"tv":19.6,"id":7287690},{"batb":[[1,1.42,319.42]],"batl":[[0,1.47,200.65],[2,1.51,42.01]],"ltp":1.42,"tv":0.03,"id":7414058}]}]}
{"op":"mcm","clk":"1006592513","pt":1580649557088,"mc":[{"id":"1.168224555","rc":[{"batb":[[0,3.05,21.56],[2,2.8,11.09]],"ltp":2.98,"tv":19.6,"id":7287690},{"batb":[[0,1.42,368.04],[1,1.33,64.83],[2,1.01,15.51]],"ltp":1.42,"tv":0.03,"id":7414058}]}]}
{"op":"mcm","clk":"1006592892","pt":1580649559551,"mc":[{"id":"1.168224555","rc":[{"batb":[[0,1.42,500.69],[1,1.41,228.49],[2,1.33,64.83]],"ltp":1.42,"tv":0.03,"id":7414058}]}]}
{"op":"mcm","clk":"1006595747","pt":1580649579170,"mc":[{"id":"1.168224555","rc":[{"batb":[[0,1.42,368.07],[1,1.33,64.83],[2,1.01,15.51]],"batl":[[0,1.47,175.59]],"ltp":1.42,"tv":0.03,"id":7414058}]}]}
{"op":"mcm","clk":"1006596170","pt":1580649582098,"mc":[{"id":"1.168224555","rc":[{"batb":[[0,1.43,176.52],[1,1.42,368.07],[2,1.33,64.83]],"ltp":1.42,"tv":0.03,"id":7414058}]}]}
{"op":"mcm","clk":"1006602952","pt":1580649630133,"mc":[{"id":"1.168224555","rc":[{"batb":[[0,2.96,21],[1,2.8,11.09],[2,1.01,15.51]],"ltp":2.98,"tv":19.6,"id":7287690},{"batb":[[0,1.42,100],[1,1.33,64.83],[2,1.01,15.51]],"batl":[[0,1.51,42.01],[1,1.77,500.61],[2,1.51,0]],"ltp":1.42,"tv":0.03,"id":7414058}]}]}
{"op":"mcm","clk":"1006603055","pt":1580649630840,"mc":[{"id":"1.168224555","rc":[{"batb":[[0,2.8,11.09],[1,1.01,15.51],[2,1.01,0]],"batl":[[0,4.2,148.03],[1,4.2,0]],"ltp":2.98,"tv":19.6,"id":7287690},{"batb":[[0,1.33,64.85],[1,1.01,15.51],[2,1.01,0]],"batl":[[0,1.77,500.61],[1,1.77,0]],"ltp":1.42,"tv":0.03,"id":7414058}]}]}
{"op":"mcm","clk":"1006603836","pt":1580649636448,"mc":[{"id":"1.168224555","rc":[{"batb":[[0,1.41,209.02],[1,1.4,234.48],[2,1.33,64.83]],"batl":[[0,1.45,187.26],[1,1.46,191.12],[2,1.77,500.61]],"ltp":1.42,"tv":0.03,"id":7414058}]}]}
{"op":"mcm","clk":"1006604072","pt":1580649637946,"mc":[{"id":"1.168224555","rc":[{"batb":[[0,1.33,64.85],[1,1.01,15.51],[2,1.33,0]],"batl":[[0,1.77,500.61],[1,1.46,0],[2,1.77,0]],"ltp":1.42,"tv":0.03,"id":7414058}]}]}
{"op":"mcm","clk":"1006604504","pt":1580649640973,"mc":[{"id":"1.168224555","rc":[{"batb":[[0,1.34,322.99],[1,1.33,366.9],[2,1.01,15.51]],"batl":[[0,1.55,230.46],[1,1.56,146.87],[2,1.77,500.61]],"ltp":1.42,"tv":0.03,"id":7414058}]}]}
{"op":"mcm","clk":"1006605246","pt":1580649646373,"mc":[{"id":"1.168224555","rc":[{"batl":[[0,1.77,500.61],[1,1.56,0],[2,1.77,0]],"ltp":1.42,"tv":0.03,"id":7414058}]}]}
{"op":"mcm","clk":"1006605681","pt":1580649649459,"mc":[{"id":"1.168224555","rc":[{"trd":[[1.42,0.07]],"batb":[[0,1.34,322.97]],"batl":[[0,1.38,269.8],[1,1.39,235.66],[2,1.77,500.61]],"ltp":1.42,"tv":0.06,"id":7414058}],"tv":19.66}]}
{"op":"mcm","clk":"1006605785","pt":1580649650206,"mc":[{"id":"1.168224555","rc":[{"batb":[[0,3.6,14.63],[1,3.3,17.64],[2,3.1,20.69]],"batl":[[0,3.9,14.28]],"ltp":2.98,"tv":19.6,"id":7287690},{"batb":[[0,1.35,119.31],[1,1.34,322.97],[2,1.33,366.9]],"batl":[[2,1.44,42.01]],"ltp":1.42,"tv":0.06,"id":7414058}]}]}
{"op":"mcm","clk":"1006606091","pt":1580649652482,"mc":[{"id":"1.168224555","rc":[{"batl":[[1,5.3,118.79]],"ltp":2.98,"tv":19.6,"id":7287690}]}]}
{"op":"mcm","clk":"1006607346","pt":1580649661412,"mc":[{"id":"1.168224555","rc":[{"batb":[[1,1.33,64.83],[2,1.25,91.35]],"batl":[[0,1.44,42.01],[1,1.77,500.61],[2,1.44,0]],"ltp":1.42,"tv":0.06,"id":7414058}]}]}
{"op":"mcm","clk":"1006607508","pt":1580649662387,"mc":[{"id":"1.168224555","rc":[{"batb":[[0,3.3,17.64],[1,3.1,20.69],[2,1.01,15.51]],"ltp":2.98,"tv":19.6,"id":7287690},{"batb":[[1,1.25,91.35],[2,1.01,15.51]],"ltp":1.42,"tv":0.06,"id":7414058}]}]}
{"op":"mcm","clk":"1006607587","pt":1580649662919,"mc":[{"id":"1.168224555","rc":[{"batb":[[0,3.1,20.69],[1,1.01,15.51],[2,1.01,0]],"batl":[[0,5.3,118.79],[1,5.3,0]],"ltp":2.98,"tv":19.6,"id":7287690},{"batb":[[0,1.25,91.35],[1,1.01,15.51],[2,1.01,0]],"batl":[[0,1.77,500.61],[1,1.77,0]],"ltp":1.42,"tv":0.06,"id":7414058}]}]}
{"op":"mcm","clk":"1006607819","pt":1580649664421,"mc":[{"id":"1.168224555","rc":[{"batb":[[0,1.26,197.14],[1,1.25,515.48],[2,1.01,15.51]],"batl":[[0,1.46,252.85],[1,1.47,185.29],[2,1.77,500.61]],"ltp":1.42,"tv":0.06,"id":7414058}]}]}
{"op":"mcm","clk":"1006608124","pt":1580649666396,"mc":[{"id":"1.168224555","rc":[{"batb":[[0,1.25,91.35],[1,1.01,15.51],[2,1.01,0]],"batl":[[0,1.77,500.61],[1,1.47,0],[2,1.77,0]],"ltp":1.42,"tv":0.06,"id":7414058}]}]}
{"op":"mcm","clk":"1006608547","pt":1580649669299,"mc":[{"id":"1.168224555","rc":[{"batb":[[0,1.32,401.69],[1,1.31,328.19],[2,1.25,91.35]],"batl":[[0,1.36,267.76],[1,1.37,251.98],[2,1.77,500.61]],"ltp":1.42,"tv":0.06,"id":7414058}]}]}
{"op":"mcm","clk":"1006608838","pt":1580649671321,"mc":[{"id":"1.168224555","rc":[{"batb":[[0,1.25,91.35],[1,1.01,15.51],[2,1.25,0]],"batl":[[0,1.77,500.61],[1,1.37,0],[2,1.77,0]],"ltp":1.42,"tv":0.06,"id":7414058}]}]}
{"op":"mcm","clk":"1006609239","pt":1580649674224,"mc":[{"id":"1.168224555","rc":[{"batb":[[0,1.26,205.25],[1,1.25,515.5],[2,1.01,15.51]],"batl":[[0,1.46,245.9],[1,1.47,185.28],[2,1.77,500.61]],"ltp":1.42,"tv":0.06,"id":7414058}]}]}
{"op":"mcm","clk":"1006612861","pt":1580649698160,"mc":[{"id":"1.168224555","rc":[{"batb":[[0,1.25,91.35],[1,1.01,15.51],[2,1.01,0]],"ltp":1.42,"tv":0.06,"id":7414058}]}]}
{"op":"mcm","clk":"1006613336","pt":1580649701375,"mc":[{"id":"1.168224555","rc":[{"batb":[[1,2.78,11.33],[2,1.01,15.51]],"ltp":2.98,"tv":19.6,"id":7287690},{"batb":[[0,1.41,399.83],[1,1.4,235.74],[2,1.31,69.87]],"ltp":1.42,"tv":0.06,"id":7414058}]}]}
{"op":"mcm","clk":"1006613412","pt":1580649701856,"mc":[{"id":"1.168224555","rc":[{"batb":[[1,3,21],[2,2.78,11.33]],"batl":[[0,3.5,16.8]],"ltp":2.98,"tv":19.6,"id":7287690},{"batb":[[1,1.4,340.76]],"batl":[[2,1.51,42.01]],"ltp":1.42,"tv":0.06,"id":7414058}]}]}
{"op":"mcm","clk":"1006613804","pt":1580649704161,"mc":[{"id":"1.168224555","rc":[{"batl":[[1,4.6,136.05]],"ltp":2.98,"tv":19.6,"id":7287690}]}]}
{"op":"mcm","clk":"1006615929","pt":1580649719390,"mc":[{"id":"1.168224555","rc":[{"batb":[[0,1.41,49.88],[1,1.4,105.02]],"batl":[[0,1.51,42.01],[1,1.77,500.61],[2,1.51,0]],"ltp":1.42,"tv":0.06,"id":7414058}]}]}
{"op":"mcm","clk":"1006616031","pt":1580649720024,"mc":[{"id":"1.168224555","rc":[{"batb":[[0,3,21],[1,2.78,11.33],[2,1.01,15.51]],"ltp":2.98,"tv":19.6,"id":7287690},{"batb":[[0,1.4,105.02],[1,1.31,69.87],[2,1.01,15.51]],"ltp":1.42,"tv":0.06,"id":7414058}]}]}
{"op":"mcm","clk":"1006616165","pt":1580649720886,"mc":[{"id":"1.168224555","rc":[{"batb":[[0,2.78,11.33],[1,1.01,15.51],[2,1.01,0]],"batl":[[0,4.6,136.05],[1,4.6,0]],"ltp":2.98,"tv":19.6,"id":7287690},{"batb":[[0,1.31,69.87],[1,1.01,15.51],[2,1.01,0]],"batl":[[0,1.77,500.61],[1,1.77,0]],"ltp":1.42,"tv":0.06,"id":7414058}]}]}
{"op":"mcm","clk":"1006616385","pt":1580649722385,"mc":[{"id":"1.168224555","rc":[{"batb":[[0,1.32,206.31],[1,1.31,394.95],[2,1.01,15.51]],"batl":[[0,1.55,218.25],[1,1.56,146.89],[2,1.77,500.61]],"ltp":1.42,"tv":0.06,"id":7414058}]}]}
{"op":"mcm","clk":"1006616815","pt":1580649725112,"mc":[{"id":"1.168224555","rc":[{"batb":[[0,1.31,69.87],[1,1.01,15.51],[2,1.01,0]],"batl":[[0,1.77,500.61],[1,1.56,0],[2,1.77,0]],"ltp":1.42,"tv":0.06,"id":7414058}]}]}
{"op":"mcm","clk":"1006617317","pt":1580649728430,"mc":[{"id":"1.168224555","rc":[{"batb":[[1,2.54,14.4],[2,1.01,15.51]],"ltp":2.98,"tv":19.6,"id":7287690},{"batb":[[0,1.5,206.86],[1,1.49,178.61],[2,1.4,51.93]],"batl":[[0,1.55,218.25],[1,1.56,146.89]],"ltp":1.42,"tv":0.06,"id":7414058}]}]}
{"op":"mcm","clk":"1006617538","pt":1580649729831,"mc":[{"id":"1.168224555","rc":[{"batb":[[1,2.76,23.53],[2,2.54,14.4]],"batl":[[0,3.15,19.32]],"ltp":2.98,"tv":19.6,"id":7287690},{"batb":[[2,1.46,90.74]],"batl":[[2,1.58,42.01]],"ltp":1.42,"tv":0.06,"id":7414058}]}]}
{"op":"mcm","clk":"1006617650","pt":1580649730729,"mc":[{"id":"1.168224555","rc":[{"batl":[[1,3.9,158.24]],"ltp":2.98,"tv":19.6,"id":7287690}]}]}
{"op":"mcm","clk":"1006619239","pt":1580649742150,"mc":[{"id":"1.168224555","rc":[{"batb":[[0,2.76,23.53],[1,2.54,14.4],[2,1.01,15.51]],"ltp":2.98,"tv":19.6,"id":7287690},{"batb":[[0,1.46,90.74],[1,1.4,51.93],[2,1.01,15.51]],"batl":[[0,1.58,42.01],[1,1.95,409.86],[2,1.58,0]],"ltp":1.42,"tv":0.06,"id":7414058}]}]}
{"op":"mcm","clk":"1006619327","pt":1580649742855,"mc":[{"id":"1.168224555","rc":[{"batb":[[0,2.54,14.4],[1,1.01,15.51],[2,1.01,0]],"batl":[[0,3.9,158.24],[1,3.9,0]],"ltp":2.98,"tv":19.6,"id":7287690},{"batb":[[0,1.4,51.93],[1,1.01,15.51],[2,1.01,0]],"batl":[[0,1.95,409.86],[1,1.95,0]],"ltp":1.42,"tv":0.06,"id":7414058}]}]}
{"op":"mcm","clk":"1006619957","pt":1580649748319,"mc":[{"id":"1.168224555","rc":[{"batb":[[0,1.48,170.56],[1,1.47,188.96],[2,1.4,51.93]],"batl":[[0,1.53,252.73],[1,1.54,154.07],[2,1.95,409.86]],"ltp":1.42,"tv":0.06,"id":7414058}]}]}
{"op":"mcm","clk":"1006620427","pt":1580649752334,"mc":[{"id":"1.168224555","rc":[{"batb":[[0,1.4,51.93],[1,1.01,15.51],[2,1.4,0]],"batl":[[0,1.95,409.86],[1,1.54,0],[2,1.95,0]],"ltp":1.42,"tv":0.06,"id":7414058}]}]}
{"op":"mcm","clk":"1006620766","pt":1580649755267,"mc":[{"id":"1.168224555","rc":[{"batb":[[0,1.4,357.76],[1,1.39,243.26],[2,1.01,15.51]],"batl":[[0,1.63,135.69],[1,1.64,122.68],[2,1.95,409.86]],"ltp":1.42,"tv":0.06,"id":7414058}]}]}
{"op":"mcm","clk":"1006621294","pt":1580649759367,"mc":[{"id":"1.168224555","rc":[{"batb":[[0,1.4,51.93],[1,1.01,15.51],[2,1.01,0]],"ltp":1.42,"tv":0.06,"id":7414058}]}]}
{"op":"mcm","clk":"1006621695","pt":1580649762330,"mc":[{"id":"1.168224555","rc":[{"batb":[[0,1.58,129.98],[1,1.57,144.98],[2,1.4,51.93]],"ltp":1.42,"tv":0.06,"id":7414058}]}]}
{"op":"mcm","clk":"1006621840","pt":1580649763335,"mc":[{"id":"1.168224555","rc":[{"batb":[[1,2.38,16.92],[2,1.01,15.51]],"ltp":2.98,"tv":19.6,"id":7287690},{"batb":[[0,1.58,161.77],[2,1.51,37.85]],"ltp":1.42,"tv":0.06,"id":7414058}]}]}
{"op":"mcm","clk":"1006621935","pt":1580649764030,"mc":[{"id":"1.168224555","rc":[{"batb":[[0,2.56,26.89],[1,2.54,14.4],[2,2.38,16.92]],"batl":[[0,2.94,21]],"ltp":2.98,"tv":19.6,"id":7287690},{"batb":[[2,1.51,120.19]],"batl":[[1,1.64,164.69]],"ltp":1.42,"tv":0.06,"id":7414058}]}]}
{"op":"mcm","clk":"1006622208","pt":1580649766173,"mc":[{"id":"1.168224555","rc":[{"batl":[[1,3.45,180.4]],"ltp":2.98,"tv":19.6,"id":7287690}]}]}
{"op":"mcm","clk":"1006623839","pt":1580649778482,"mc":[{"id":"1.168224555","rc":[{"batb":[[1,2.38,16.92],[2,1.01,15.51]],"ltp":2.98,"tv":19.6,"id":7287690},{"batb":[[0,1.51,120.19],[1,1.01,15.51],[2,1.51,0]],"batl":[[0,1.64,42.01],[1,1.95,409.86],[2,1.95,0]],"ltp":1.42,"tv":0.06,"id":7414058}]}]}
{"op":"mcm","clk":"1006623943","pt":1580649779166,"mc":[{"id":"1.168224555","rc":[{"batb":[[0,2.38,16.92],[1,1.01,15.51],[2,1.01,0]],"batl":[[0,3.45,180.4],[1,3.45,0]],"ltp":2.98,"tv":19.6,"id":7287690},{"batb":[[0,1.51,37.85]],"batl":[[0,1.95,409.86],[1,1.95,0]],"ltp":1.42,"tv":0.06,"id":7414058}]}]}
{"op":"mcm","clk":"1006624241","pt":1580649781387,"mc":[{"id":"1.168224555","rc":[{"batb":[[0,1.51,249.63],[1,1.5,174.01],[2,1.01,15.51]],"batl":[[0,1.69,185.01],[1,1.71,213.26],[2,1.95,409.86]],"ltp":1.42,"tv":0.06,"id":7414058}]}]}
{"op":"mcm","clk":"1006624508","pt":1580649783302,"mc":[{"id":"1.168224555","rc":[{"batl":[[0,2.58,22.45],[1,3.45,180.4]],"ltp":2.98,"tv":19.6,"id":7287690}]}]}
{"op":"mcm","clk":"1006624829","pt":1580649785389,"mc":[{"id":"1.168224555","rc":[{"batb":[[0,1.51,37.85],[1,1.01,15.51],[2,1.01,0]],"batl":[[0,1.95,409.86],[1,1.71,0],[2,1.95,0]],"ltp":1.42,"tv":0.06,"id":7414058}]}]}
{"op":"mcm","clk":"1006625294","pt":1580649788410,"mc":[{"id":"1.168224555","rc":[{"trd":[[2.58,22.45]],"batl":[[0,3.45,180.4],[1,3.45,0]],"ltp":2.58,"tv":42.04,"id":7287690},{"trd":[[1.63,35.55]],"batb":[[0,1.56,227.26],[1,1.55,152.76],[2,1.51,37.85]],"batl":[[0,1.62,161.87],[1,1.63,125.16],[2,1.95,409.86]],"ltp":1.63,"tv":35.61,"id":7414058}],"tv":77.66}]}
{"op":"mcm","clk":"1006625843","pt":1580649792292,"mc":[{"id":"1.168224555","rc":[{"batb":[[0,1.51,37.85],[1,1.01,15.51],[2,1.51,0]],"batl":[[0,1.95,409.86],[1,1.63,0],[2,1.95,0]],"ltp":1.63,"tv":35.61,"id":7414058}]}]}
{"op":"mcm","clk":"1006626259","pt":1580649795178,"mc":[{"id":"1.168224555","rc":[{"batb":[[0,1.51,271.06],[1,1.5,174.03],[2,1.01,15.51]],"batl":[[0,1.69,165.89],[1,1.71,213.25],[2,1.95,409.86]],"ltp":1.63,"tv":35.61,"id":7414058}]}]}
{"op":"mcm","clk":"1006626511","pt":1580649797096,"mc":[{"id":"1.168224555","rc":[{"batl":[[0,1.95,409.86],[1,1.71,0],[2,1.95,0]],"ltp":1.63,"tv":35.61,"id":7414058}]}]}
{"op":"mcm","clk":"1006626974","pt":1580649800409,"mc":[{"id":"1.168224555","rc":[{"batl":[[0,1.56,139.24],[1,1.57,143.69],[2,1.95,409.86]],"ltp":1.63,"tv":35.61,"id":7414058}]}]}
{"op":"mcm","clk":"1006627075","pt":1580649801004,"mc":[{"id":"1.168224555","rc":[{"batb":[[0,2.74,11.64],[1,2.46,15.42],[2,1.01,15.51]],"ltp":2.58,"tv":42.04,"id":7287690},{"batb":[[2,1.39,52.64]],"ltp":1.63,"tv":35.61,"id":7414058}]}]}
{"op":"mcm","clk":"1006627296","pt":1580649802441,"mc":[{"id":"1.168224555","rc":[{"batb":[[1,2.68,24.37],[2,2.46,15.42]],"batl":[[0,3.1,19.32],[1,3.9,158.24]],"ltp":2.58,"tv":42.04,"id":7287690},{"batb":[[2,1.48,87.38]],"batl":[[2,1.59,42.01]],"ltp":1.63,"tv":35.61,"id":7414058}]}]}
{"op":"mcm","clk":"1006629830","pt":1580649820134,"mc":[{"id":"1.168224555","rc":[{"batb":[[0,2.68,24.37],[1,2.46,15.42],[2,1.01,15.51]],"ltp":2.58,"tv":42.04,"id":7287690},{"batb":[[0,1.48,87.38],[1,1.39,52.64],[2,1.01,15.51]],"batl":[[0,1.59,42.01],[1,1.95,409.86],[2,1.59,0]],"ltp":1.63,"tv":35.61,"id":7414058}]}]}
{"op":"mcm","clk":"1006629963","pt":1580649820952,"mc":[{"id":"1.168224555","rc":[{"batb":[[0,2.46,15.42],[1,1.01,15.51],[2,1.01,0]],"batl":[[0,3.9,158.24],[1,3.9,0]],"ltp":2.58,"tv":42.04,"id":7287690},{"batb":[[0,1.39,52.64],[1,1.01,15.51],[2,1.01,0]],"batl":[[0,1.95,409.86],[1,1.95,0]],"ltp":1.63,"tv":35.61,"id":7414058}]}]}
{"op":"mcm","clk":"1006630357","pt":1580649823349,"mc":[{"id":"1.168224555","rc":[{"batb":[[0,1.4,234.58],[1,1.39,295],[2,1.01,15.51]],"batl":[[0,1.67,209.65],[1,1.69,221.7],[2,1.95,409.86]],"ltp":1.63,"tv":35.61,"id":7414058}]}]}
{"op":"mcm","clk":"1006630752","pt":1580649825961,"mc":[{"id":"1.168224555","rc":[{"batl":[[0,1.95,409.86],[1,1.69,0],[2,1.95,0]],"ltp":1.63,"tv":35.61,"id":7414058}]}]}
{"op":"mcm","clk":"1006631260","pt":1580649829461,"mc":[{"id":"1.168224555","rc":[{"batb":[[0,3.2,19.43],[1,2.76,11.33],[2,2.46,15.42]],"ltp":2.58,"tv":42.04,"id":7287690},{"batb":[[2,1.27,81.36]],"batl":[[0,1.44,184.93],[1,1.45,196.49]],"ltp":1.63,"tv":35.61,"id":7414058}]}]}
{"op":"mcm","clk":"1006631387","pt":1580649830272,"mc":[{"id":"1.168224555","rc":[{"batb":[[1,3.05,20.16],[2,2.76,11.33]],"batl":[[0,3.55,15.96]],"ltp":2.58,"tv":42.04,"id":7287690},{"batb":[[1,1.39,402.54]],"batl":[[2,1.49,42.01]],"ltp":1.63,"tv":35.61,"id":7414058}]}]}
{"op":"mcm","clk":"1006631666","pt":1580649832039,"mc":[{"id":"1.168224555","rc":[{"batl":[[1,4.6,136.05]],"ltp":2.58,"tv":42.04,"id":7287690}]}]}
{"op":"mcm","clk":"1006633398","pt":1580649843526,"mc":[{"id":"1.168224555","rc":[{"batb":[[0,1.4,203.43]],"ltp":1.63,"tv":35.61,"id":7414058}]}]}
{"op":"mcm","clk":"1006633671","pt":1580649845393,"mc":[{"id":"1.168224555","rc":[{"trd":[[1.4,336.08]],"batb":[[0,1.4,35.39]],"ltp":1.4,"tv":371.69,"id":7414058}],"tv":413.74}]}
{"op":"mcm","clk":"1006633822","pt":1580649846457,"mc":[{"id":"1.168224555","rc":[{"batl":[[0,1.44,215.19]],"ltp":1.4,"tv":371.69,"id":7414058}]}]}
{"op":"mcm","clk":"1006633925","pt":1580649847149,"mc":[{"id":"1.168224555","rc":[{"batb":[[0,3.05,20.16],[1,2.76,11.33],[2,1.01,15.51]],"ltp":2.58,"tv":42.04,"id":7287690},{"batb":[[0,1.39,107.54],[1,1.27,81.36],[2,1.01,15.51]],"batl":[[0,1.49,42.01],[1,1.82,469.11],[2,1.49,0]],"ltp":1.4,"tv":371.69,"id":7414058}]}]}
{"op":"mcm","clk":"1006634201","pt":1580649848980,"mc":[{"id":"1.168224555","rc":[{"batb":[[0,2.76,11.33],[1,1.01,15.51],[2,1.01,0]],"batl":[[0,4.6,136.05],[1,4.6,0]],"ltp":2.58,"tv":42.04,"id":7287690},{"batb":[[0,1.27,81.36],[1,1.01,15.51],[2,1.01,0]],"batl":[[0,1.82,469.11],[1,1.82,0]],"ltp":1.4,"tv":371.69,"id":7414058}]}]}
{"op":"mcm","clk":"1006634331","pt":1580649849884,"mc":[{"id":"1.168224555","rc":[{"batb":[[0,1.28,162.92],[1,1.27,467.96],[2,1.01,15.51]],"batl":[[0,1.55,139.6],[1,1.56,147.69],[2,1.82,469.11]],"ltp":1.4,"tv":371.69,"id":7414058}]}]}
{"op":"mcm","clk":"1006634409","pt":1580649850489,"mc":[{"id":"1.168224555","rc":[{"batb":[[0,1.27,81.36],[1,1.01,15.51],[2,1.01,0]],"batl":[[0,1.82,469.11],[1,1.56,0],[2,1.82,0]],"ltp":1.4,"tv":371.69,"id":7414058}]}]}
{"op":"mcm","clk":"1006634819","pt":1580649853486,"mc":[{"id":"1.168224555","rc":[{"batb":[[0,1.37,253.16],[1,1.36,270.15],[2,1.27,81.36]],"batl":[[0,1.41,247.01],[1,1.42,215.21],[2,1.82,469.11]],"ltp":1.4,"tv":371.69,"id":7414058}]}]}
{"op":"mcm","clk":"1006635201","pt":1580649855976,"mc":[{"id":"1.168224555","rc":[{"batb":[[0,1.27,81.36],[1,1.01,15.51],[2,1.27,0]],"batl":[[0,1.82,469.11],[1,1.42,0],[2,1.82,0]],"ltp":1.4,"tv":371.69,"id":7414058}]}]}
{"op":"mcm","clk":"1006635640","pt":1580649859031,"mc":[{"id":"1.168224555","rc":[{"batb":[[0,1.28,162.92],[1,1.27,467.96],[2,1.01,15.51]],"batl":[[0,1.55,139.6],[1,1.56,147.69],[2,1.82,469.11]],"ltp":1.4,"tv":371.69,"id":7414058}]}]}
{"op":"mcm","clk":"1006635722","pt":1580649859593,"mc":[{"id":"1.168224555","rc":[{"batl":[[0,1.82,469.11],[1,1.56,0],[2,1.82,0]],"ltp":1.4,"tv":371.69,"id":7414058}]}]}
{"op":"mcm","clk":"1006636216","pt":1580649863302,"mc":[{"id":"1.168224555","rc":[{"batb":[[0,4,21.64],[1,3.2,19.2],[2,1.01,15.51]],"ltp":2.58,"tv":42.04,"id":7287690},{"batb":[[2,1.15,154.06]],"batl":[[0,1.31,360.33],[1,1.32,301.72]],"ltp":1.4,"tv":371.69,"id":7414058}]}]}
{"op":"mcm","clk":"1006636303","pt":1580649863894,"mc":[{"id":"1.168224555","rc":[{"batb":[[1,3.8,14.28],[2,3.2,19.2]],"batl":[[0,4.5,11.76]],"ltp":2.58,"tv":42.04,"id":7287690},{"batb":[[0,1.28,312.47]],"batl":[[2,1.36,42.01]],"ltp":1.4,"tv":371.69,"id":7414058}]}]}
{"op":"mcm","clk":"1006636437","pt":1580649864915,"mc":[{"id":"1.168224555","rc":[{"batl":[[1,6,106.18]],"ltp":2.58,"tv":42.04,"id":7287690}]}]}
{"op":"mcm","clk":"1006637522","pt":1580649872279,"mc":[{"id":"1.168224555","rc":[{"batb":[[0,1.28,149.55]],"ltp":1.4,"tv":371.69,"id":7414058}]}]}
{"op":"mcm","clk":"1006637839","pt":1580649874486,"mc":[{"id":"1.168224555","rc":[{"batb":[[1,1.27,579.38],[2,1.26,412.98]],"batl":[[0,1.31,411.61]],"ltp":1.4,"tv":371.69,"id":7414058}]}]}
{"op":"mcm","clk":"1006638654","pt":1580649879898,"mc":[{"id":"1.168224555","rc":[{"batb":[[0,3.8,14.28],[1,3.2,19.2],[2,1.01,15.51]],"ltp":2.58,"tv":42.04,"id":7287690},{"batb":[[1,1.15,154.06],[2,1.01,15.51]],"batl":[[0,1.36,42.01],[1,1.66,579.81],[2,1.36,0]],"ltp":1.4,"tv":371.69,"id":7414058}]}]}
{"op":"mcm","clk":"1006638793","pt":1580649880923,"mc":[{"id":"1.168224555","rc":[{"batb":[[0,3.2,19.2],[1,1.01,15.51],[2,1.01,0]],"batl":[[0,6,106.18],[1,6,0]],"ltp":2.58,"tv":42.04,"id":7287690},{"batb":[[0,1.15,154.06],[1,1.01,15.51],[2,1.01,0]],"batl":[[0,1.66,579.81],[1,1.66,0]],"ltp":1.4,"tv":371.69,"id":7414058}]}]}
{"op":"mcm","clk":"1006639563","pt":1580649885712,"mc":[{"id":"1.168224555","rc":[{"batb":[[0,1.25,235.27],[1,1.24,449.43],[2,1.15,154.06]],"batl":[[0,1.28,423.7],[1,1.29,340.32],[2,1.66,579.81]],"ltp":1.4,"tv":371.69,"id":7414058}]}]}
{"op":"mcm","clk":"1006639904","pt":1580649888046,"mc":[{"id":"1.168224555","rc":[{"batb":[[0,1.15,154.06],[1,1.01,15.51],[2,1.15,0]],"batl":[[0,1.66,579.81],[1,1.29,0],[2,1.66,0]],"ltp":1.4,"tv":371.69,"id":7414058}]}]}
{"op":"mcm","clk":"1006640365","pt":1580649891042,"mc":[{"id":"1.168224555","rc":[{"batb":[[0,1.15,722.71],[1,1.14,552.53],[2,1.01,15.51]],"batl":[[0,1.43,181.78],[1,1.44,203.69],[2,1.66,579.81]],"ltp":1.4,"tv":371.69,"id":7414058}]}]}
{"op":"mcm","clk":"1006640702","pt":1580649893317,"mc":[{"id":"1.168224555","rc":[{"batl":[[0,1.66,579.81],[1,1.44,0],[2,1.66,0]],"ltp":1.4,"tv":371.69,"id":7414058}]}]}
{"op":"mcm","clk":"1006641180","pt":1580649896451,"mc":[{"id":"1.168224555","rc":[{"batl":[[0,1.17,313.11],[1,1.18,602.86]],"ltp":1.4,"tv":371.69,"id":7414058}]}]}
{"op":"mcm","clk":"1006641265","pt":1580649897052,"mc":[{"id":"1.168224555","rc":[{"batb":[[0,6,16.76],[1,4.9,13.69],[2,1.01,15.51]],"ltp":2.58,"tv":42.04,"id":7287690},{"batb":[[2,1.12,191.35]],"ltp":1.4,"tv":371.69,"id":7414058}]}]}
{"op":"mcm","clk":"1006641616","pt":1580649899237,"mc":[{"id":"1.168224555","rc":[{"batb":[[0,6.4,7.56],[1,6,16.76],[2,4.9,13.69]],"batl":[[0,7.8,5.88],[1,9.8,75.27]],"ltp":2.58,"tv":42.04,"id":7287690},{"batb":[[1,1.14,720.57]],"batl":[[2,1.19,79.87]],"ltp":1.4,"tv":371.69,"id":7414058}]}]}
{"op":"mcm","clk":"1006641752","pt":1580649900138,"mc":[{"id":"1.168224555","rc":[{"batl":[[2,1.19,42.01]],"ltp":1.4,"tv":371.69,"id":7414058}]}]}
{"op":"mcm","clk":"1006643201","pt":1580649909367,"mc":[{"id":"1.168224555","rc":[{"batb":[[1,6.2,16.13],[2,6,16.76]],"ltp":2.58,"tv":42.04,"id":7287690}]}]}
{"op":"mcm","clk":"1006643325","pt":1580649910074,"mc":[{"id":"1.168224555","rc":[{"batb":[[2,5,13.22]],"ltp":2.58,"tv":42.04,"id":7287690}]}]}
{"op":"mcm","clk":"1006645449","pt":1580649924388,"mc":[{"id":"1.168224555","rc":[{"batb":[[1,1.14,658.44]],"batl":[[0,1.17,252.81]],"ltp":1.4,"tv":371.69,"id":7414058}]}]}
{"op":"mcm","clk":"1006645883","pt":1580649927418,"mc":[{"id":"1.168224555","rc":[{"batb":[[0,1.15,784.29]],"ltp":1.4,"tv":371.69,"id":7414058}]}]}
{"op":"mcm","clk":"1006646776","pt":1580649933519,"mc":[{"id":"1.168224555","rc":[{"batb":[[0,1.15,154.06],[1,1.14,168.04]],"batl":[[0,1.19,42.01],[1,1.49,761.67],[2,1.19,0]],"ltp":1.4,"tv":371.69,"id":7414058}]}]}
{"op":"mcm","clk":"1006647189","pt":1580649936408,"mc":[{"id":"1.168224555","rc":[{"batb":[[2,1.13,240.54]],"batl":[[1,1.23,519.21],[2,1.24,424.23]],"ltp":1.4,"tv":371.69,"id":7414058}]}]}
{"op":"mcm","clk":"1006648574","pt":1580649946420,"mc":[{"id":"1.168224555","rc":[{"batb":[[1,5,13.22],[2,1.01,15.51]],"ltp":2.58,"tv":42.04,"id":7287690},{"batb":[[0,1.14,168.04],[1,1.13,240.54],[2,1.12,1094.93]],"ltp":1.4,"tv":371.69,"id":7414058}]}]}
{"op":"mcm","clk":"1006648669","pt":1580649947002,"mc":[{"id":"1.168224555","rc":[{"batb":[[0,5,13.22],[1,1.01,15.51],[2,1.01,0]],"batl":[[0,9.8,75.27],[1,9.8,0]],"ltp":2.58,"tv":42.04,"id":7287690},{"batb":[[0,1.13,240.54],[1,1.12,1094.93],[2,1.01,15.51]],"batl":[[0,1.23,519.21],[1,1.24,424.23],[2,1.49,761.67]],"ltp":1.4,"tv":371.69,"id":7414058}]}]}
{"op":"mcm","clk":"1006649357","pt":1580649951881,"mc":[{"id":"1.168224555","rc":[{"batl":[[0,1.49,761.67],[1,1.24,0],[2,1.49,0]],"ltp":1.4,"tv":371.69,"id":7414058}]}]}
{"op":"mcm","clk":"1006649710","pt":1580649954392,"mc":[{"id":"1.168224555","rc":[{"batl":[[0,1.15,810.86],[1,1.16,302.88],[2,1.49,761.67]],"ltp":1.4,"tv":371.69,"id":7414058}]}]}
{"op":"mcm","clk":"1006649866","pt":1580649955402,"mc":[{"id":"1.168224555","rc":[{"batb":[[0,7.2,11.41],[1,5.8,18.65],[2,1.01,15.51]],"ltp":2.58,"tv":42.04,"id":7287690},{"batb":[[2,1.1,236.44]],"ltp":1.4,"tv":371.69,"id":7414058}]}]}
{"op":"mcm","clk":"1006649949","pt":1580649955925,"mc":[{"id":"1.168224555","rc":[{"batb":[[0,7.2,18.13]],"batl":[[0,9.2,5.04]],"ltp":2.58,"tv":42.04,"id":7287690},{"batb":[[1,1.12,1262.97]],"batl":[[1,1.16,344.89]],"ltp":1.4,"tv":371.69,"id":7414058}]}]}
{"op":"mcm","clk":"1006650083","pt":1580649956828,"mc":[{"id":"1.168224555","rc":[{"batl":[[1,12.5,65.97]],"ltp":2.58,"tv":42.04,"id":7287690}]}]}
{"op":"mcm","clk":"1006652399","pt":1580649972148,"mc":[{"id":"1.168224555","rc":[{"batb":[[0,7.2,6.72]],"ltp":2.58,"tv":42.04,"id":7287690},{"batb":[[0,1.12,168.04],[1,1.1,236.44],[2,1.01,15.51]],"batl":[[0,1.16,42.01],[1,1.49,761.67],[2,1.49,0]],"ltp":1.4,"tv":371.69,"id":7414058}]}]}
{"op":"mcm","clk":"1006652531","pt":1580649973003,"mc":[{"id":"1.168224555","rc":[{"batb":[[0,5.8,18.65],[1,1.01,15.51],[2,1.01,0]],"batl":[[0,12.5,65.97],[1,12.5,0]],"ltp":2.58,"tv":42.04,"id":7287690},{"batb":[[0,1.1,236.44],[1,1.01,15.51],[2,1.01,0]],"batl":[[0,1.49,761.67],[1,1.49,0]],"ltp":1.4,"tv":371.69,"id":7414058}]}]}
{"op":"mcm","clk":"1006652914","pt":1580649975449,"mc":[{"id":"1.168224555","rc":[{"batb":[[0,1.11,465.29],[1,1.1,934.03],[2,1.01,15.51]],"batl":[[0,1.19,713.68],[1,1.2,362.12],[2,1.49,761.67]],"ltp":1.4,"tv":371.69,"id":7414058}]}]}
{"op":"mcm","clk":"1006653027","pt":1580649976115,"mc":[{"id":"1.168224555","rc":[{"batl":[[0,1.49,761.67],[1,1.2,0],[2,1.49,0]],"ltp":1.4,"tv":371.69,"id":7414058}]}]}
{"op":"mcm","clk":"1006653553","pt":1580649979448,"mc":[{"id":"1.168224555","rc":[{"batl":[[0,1.13,891.38],[1,1.14,242.6]],"ltp":1.4,"tv":371.69,"id":7414058}]}]}
{"op":"mcm","clk":"1006653694","pt":1580649980352,"mc":[{"id":"1.168224555","rc":[{"batb":[[0,8.2,8.34],[1,7.8,5.88],[2,7,12.35]],"batl":[[0,10.5,4.2],[1,12.5,65.97]],"ltp":2.58,"tv":42.04,"id":7287690},{"batb":[[2,1.09,270.51]],"ltp":1.4,"tv":371.69,"id":7414058}]}]}
{"op":"mcm","clk":"1006653984","pt":1580649982325,"mc":[{"id":"1.168224555","rc":[{"batl":[[2,1.43,872.38]],"ltp":1.4,"tv":371.69,"id":7414058}]}]}
{"op":"mcm","clk":"1006654288","pt":1580649984438,"mc":[{"id":"1.168224555","rc":[{"batb":[[0,1.1,591.91],[1,1.09,270.51],[2,1.01,15.51]],"batl":[[0,1.43,872.38],[1,1.14,0],[2,1.43,0]],"ltp":1.4,"tv":371.69,"id":7414058}]}]}
{"op":"mcm","clk":"1006654382","pt":1580649985031,"mc":[{"id":"1.168224555","rc":[{"batb":[[0,7,12.35],[1,1.01,15.51],[2,7,0]],"batl":[[0,12.5,65.97],[1,12.5,0]],"ltp":2.58,"tv":42.04,"id":7287690},{"batb":[[0,1.1,355.47]],"ltp":1.4,"tv":371.69,"id":7414058}]}]}
{"op":"mcm","clk":"1006654730","pt":1580649987469,"mc":[{"id":"1.168224555","rc":[{"batb":[[1,1.09,1089.6]],"batl":[[0,1.15,485.36],[1,1.16,625.56],[2,1.43,872.38]],"ltp":1.4,"tv":371.69,"id":7414058}]}]}
{"op":"mcm","clk":"1006655999","pt":1580649995549,"mc":[{"id":"1.168224555","rc":[{"batl":[[0,1.43,872.38],[1,1.16,0],[2,1.43,0]],"ltp":1.4,"tv":371.69,"id":7414058}]}]}
{"op":"mcm","clk":"1006656573","pt":1580649999259,"mc":[{"id":"1.168224555","rc":[{"batb":[[0,9,6.85],[1,8,8.73],[2,1.01,15.51]],"ltp":2.58,"tv":42.04,"id":7287690},{"batb":[[2,1.08,297.18]],"batl":[[0,1.11,205.71],[1,1.12,942.39],[2,1.43,872.38]],"ltp":1.4,"tv":371.69,"id":7414058}]}]}
{"op":"mcm","clk":"1006656695","pt":1580650000055,"mc":[{"id":"1.168224555","rc":[{"batb":[[1,8.4,5.04],[2,8,8.73]],"batl":[[0,11,4.2]],"ltp":2.58,"tv":42.04,"id":7287690},{"batl":[[2,1.13,42.01]],"ltp":1.4,"tv":371.69,"id":7414058}]}]}
{"op":"mcm","clk":"1006656992","pt":1580650002168,"mc":[{"id":"1.168224555","rc":[{"batl":[[1,17,57.33]],"ltp":2.58,"tv":42.04,"id":7287690}]}]}
{"op":"mcm","clk":"1006657996","pt":1580650009401,"mc":[{"id":"1.168224555","rc":[{"batb":[[0,1.09,1089.6],[1,1.08,297.18],[2,1.01,15.51]],"batl":[[0,1.13,42.01],[1,1.43,872.38],[2,1.13,0]],"ltp":1.4,"tv":371.69,"id":7414058}]}]}
{"op":"mcm","clk":"1006658099","pt":1580650010081,"mc":[{"id":"1.168224555","rc":[{"batb":[[0,8.4,5.04],[1,8,8.73],[2,1.01,15.51]],"ltp":2.58,"tv":42.04,"id":7287690},{"batb":[[0,1.09,819.09]],"ltp":1.4,"tv":371.69,"id":7414058}]}]}
{"op":"mcm","clk":"1006658241","pt":1580650011102,"mc":[{"id":"1.168224555","rc":[{"batb":[[0,8,8.73],[1,1.01,15.51],[2,1.01,0]],"batl":[[0,17,57.33],[1,17,0]],"ltp":2.58,"tv":42.04,"id":7287690},{"batl":[[0,1.43,872.38],[1,1.43,0]],"ltp":1.4,"tv":371.69,"id":7414058}]}]}
{"op":"mcm","clk":"1006658443","pt":1580650012459,"mc":[{"id":"1.168224555","rc":[{"batb":[[0,1.09,977.39],[1,1.08,499.46]],"batl":[[0,1.13,892.46],[1,1.14,241.53],[2,1.43,872.38]],"ltp":1.4,"tv":371.69,"id":7414058}]}]}
{"op":"mcm","clk":"1006658457","pt":1580650012568,"mc":[{"id":"1.168224555","rc":[{"batb":[[0,1.09,544.53],[1,1.08,297.18]],"batl":[[0,1.13,215.5],[1,1.43,872.38],[2,1.43,0]],"ltp":1.4,"tv":371.69,"id":7414058}]}]}
{"op":"mcm","clk":"1006659246","pt":1580650018094,"mc":[{"id":"1.168224555","rc":[{"batl":[[0,1.1,3.3],[1,1.13,215.5],[2,1.43,872.38]],"ltp":1.4,"tv":371.69,"id":7414058}]}]}
{"op":"mcm","clk":"1006659423","pt":1580650019377,"mc":[{"id":"1.168224555","rc":[{"batb":[[0,1.09,977.39],[1,1.08,499.46]],"batl":[[1,1.13,892.46],[2,1.14,241.53]],"ltp":1.4,"tv":371.69,"id":7414058}]}]}
{"op":"mcm","clk":"1006659715","pt":1580650021299,"mc":[{"id":"1.168224555","rc":[{"batl":[[0,1.13,892.46],[1,1.14,241.53],[2,1.43,872.38]],"ltp":1.4,"tv":371.69,"id":7414058}]}]}
{"op":"mcm","clk":"1006659789","pt":1580650021683,"mc":[{"id":"1.168224555","rc":[{"batl":[[0,1.43,872.38],[1,1.14,0],[2,1.43,0]],"ltp":1.4,"tv":371.69,"id":7414058}]}]}
{"op":"mcm","clk":"1006660237","pt":1580650024396,"mc":[{"id":"1.168224555","rc":[{"trd":[[1.09,6.6]],"batb":[[0,1.09,974.09]],"ltp":1.09,"tv":378.29,"id":7414058}],"tv":420.34}]}
{"op":"mcm","clk":"1006660366","pt":1580650025293,"mc":[{"id":"1.168224555","rc":[{"batb":[[0,9.6,14.63],[1,8.4,7.79],[2,8,8.73]],"ltp":2.58,"tv":42.04,"id":7287690},{"batb":[[2,1.06,394.75]],"batl":[[0,1.11,848.39],[1,1.12,305.07],[2,1.43,872.38]],"ltp":1.09,"tv":378.29,"id":7414058}]}]}
{"op":"mcm","clk":"1006660478","pt":1580650026107,"mc":[{"id":"1.168224555","rc":[{"batb":[[1,9,5.04],[2,8.4,7.79]],"batl":[[0,12,3.36],[1,17,57.33]],"ltp":2.58,"tv":42.04,"id":7287690},{"batb":[[0,1.09,1142.13]],"ltp":1.09,"tv":378.29,"id":7414058}]}]}
{"op":"mcm","clk":"1006663088","pt":1580650045211,"mc":[{"id":"1.168224555","rc":[{"batb":[[0,8.4,7.79],[1,1.01,15.51],[2,8.4,0]],"batl":[[0,17,57.33],[1,17,0]],"ltp":2.58,"tv":42.04,"id":7287690},{"trd":[[1.09,12.66]],"batb":[[0,1.06,394.75],[1,1.01,15.51],[2,1.06,0]],"batl":[[0,1.43,872.38],[1,1.12,0],[2,1.43,0]],"ltp":1.09,"tv":384.35,"id":7414058}],"tv":426.4}]}
{"op":"mcm","clk":"1006663262","pt":1580650046507,"mc":[{"id":"1.168224555","rc":[{"batb":[[0,1.11,3.79],[1,1.06,394.75],[2,1.01,15.51]],"ltp":1.09,"tv":384.35,"id":7414058}]}]}
{"op":"mcm","clk":"1006663460","pt":1580650048031,"mc":[{"id":"1.168224555","rc":[{"batl":[[0,1.13,826.05],[1,1.14,306.98],[2,1.43,872.38]],"ltp":1.09,"tv":384.35,"id":7414058}]}]}
{"op":"mcm","clk":"1006663928","pt":1580650051117,"mc":[{"id":"1.168224555","rc":[{"batb":[[0,1.11,543.58],[1,1.1,622.02],[2,1.06,394.75]],"ltp":1.09,"tv":384.35,"id":7414058}]}]}
{"op":"mcm","clk":"1006664078","pt":1580650052149,"mc":[{"id":"1.168224555","rc":[{"batb":[[0,8.4,12.83],[1,7.4,10.39],[2,1.01,15.51]],"batl":[[0,10.5,4.2]],"ltp":2.58,"tv":42.04,"id":7287690},{"batb":[[1,1.1,868.69],[2,1.08,306.47]],"batl":[[1,1.14,348.99]],"ltp":1.09,"tv":384.35,"id":7414058}]}]}
{"op":"mcm","clk":"1006664462","pt":1580650054740,"mc":[{"id":"1.168224555","rc":[{"batl":[[1,14,62.58]],"ltp":2.58,"tv":42.04,"id":7287690}]}]}
{"op":"mcm","clk":"1006665141","pt":1580650059328,"mc":[{"id":"1.168224555","rc":[{"batb":[[0,7.4,10.39],[1,1.01,15.51],[2,1.01,0]],"batl":[[0,14,62.58],[1,14,0]],"ltp":2.58,"tv":42.04,"id":7287690},{"batb":[[0,1.11,3.79],[1,1.08,306.47],[2,1.01,15.51]],"batl":[[0,1.14,175.02],[1,1.43,872.38],[2,1.43,0]],"ltp":1.09,"tv":384.35,"id":7414058}]}]}
{"op":"mcm","clk":"1006665476","pt":1580650061841,"mc":[{"id":"1.168224555","rc":[{"batb":[[1,1.09,644.04],[2,1.08,844.8]],"batl":[[1,1.15,746.26],[2,1.43,872.38]],"ltp":1.09,"tv":384.35,"id":7414058}]}]}
{"op":"mcm","clk":"1006665851","pt":1580650064530,"mc":[{"id":"1.168224555","rc":[{"batb":[[1,1.08,306.47],[2,1.01,15.51]],"ltp":1.09,"tv":384.35,"id":7414058}]}]}
{"op":"mcm","clk":"1006666415","pt":1580650068338,"mc":[{"id":"1.168224555","rc":[{"batb":[[0,7.6,5.88],[1,7.4,10.39],[2,7,12.43]],"batl":[[0,10,4.2]],"ltp":2.58,"tv":42.04,"id":7287690},{"batb":[[0,1.12,1319.65],[1,1.11,171.83],[2,1.1,243.13]],"batl":[[1,1.15,788.27]],"ltp":1.09,"tv":384.35,"id":7414058}]}]}
{"op":"mcm","clk":"1006666748","pt":1580650070645,"mc":[{"id":"1.168224555","rc":[{"batl":[[1,12.5,65.97]],"ltp":2.58,"tv":42.04,"id":7287690}]}]}
{"op":"mcm","clk":"1006667278","pt":1580650074361,"mc":[{"id":"1.168224555","rc":[{"batb":[[1,7,12.43],[2,1.01,15.51]],"ltp":2.58,"tv":42.04,"id":7287690},{"batb":[[0,1.11,171.83],[1,1.1,243.13],[2,1.01,15.51]],"batl":[[0,1.15,42.01],[1,1.43,872.38],[2,1.43,0]],"ltp":1.09,"tv":384.35,"id":7414058}]}]}
{"op":"mcm","clk":"1006667377","pt":1580650075161,"mc":[{"id":"1.168224555","rc":[{"batb":[[0,7,12.43],[1,1.01,15.51],[2,1.01,0]],"batl":[[0,12.5,65.97],[1,12.5,0]],"ltp":2.58,"tv":42.04,"id":7287690},{"batb":[[0,1.11,3.79]],"batl":[[0,1.43,872.38],[1,1.43,0]],"ltp":1.09,"tv":384.35,"id":7414058}]}]}
{"op":"mcm","clk":"1006667700","pt":1580650077437,"mc":[{"id":"1.168224555","rc":[{"batb":[[0,1.11,600.88],[1,1.1,807.33]],"batl":[[0,1.16,637.51],[1,1.17,464.86],[2,1.43,872.38]],"ltp":1.09,"tv":384.35,"id":7414058}]}]}
{"op":"mcm","clk":"1006667750","pt":1580650077861,"mc":[{"id":"1.168224555","rc":[{"batb":[[0,1.11,597.09]],"ltp":1.09,"tv":384.35,"id":7414058}]}]}
{"op":"mcm","clk":"1006667969","pt":1580650079475,"mc":[{"id":"1.168224555","rc":[{"batb":[[0,1.1,243.13],[1,1.01,15.51],[2,1.01,0]],"batl":[[0,1.43,872.38],[1,1.17,0],[2,1.43,0]],"ltp":1.09,"tv":384.35,"id":7414058}]}]}
{"op":"mcm","clk":"1006668516","pt":1580650083272,"mc":[{"id":"1.168224555","rc":[{"batb":[[1,6.6,13.85],[2,1.01,15.51]],"ltp":2.58,"tv":42.04,"id":7287690},{"batb":[[0,1.14,310.72],[1,1.13,1007.89],[2,1.12,201.9]],"batl":[[0,1.16,637.51],[1,1.17,464.86],[2,1.43,872.38]],"ltp":1.09,"tv":384.35,"id":7414058}]}]}
{"op":"mcm","clk":"1006668632","pt":1580650084048,"mc":[{"id":"1.168224555","rc":[{"batb":[[0,7.4,5.88],[1,7,12.43],[2,6.6,13.85]],"batl":[[0,9.4,4.2]],"ltp":2.58,"tv":42.04,"id":7287690},{"batb":[[2,1.12,369.94]],"batl":[[0,1.16,679.52]],"ltp":1.09,"tv":384.35,"id":7414058}]}]}
{"op":"mcm","clk":"1006668756","pt":1580650084961,"mc":[{"id":"1.168224555","rc":[{"batl":[[1,11.5,70.11]],"ltp":2.58,"tv":42.04,"id":7287690}]}]}
{"op":"mcm","clk":"1006669501","pt":1580650090172,"mc":[{"id":"1.168224555","rc":[{"batb":[[1,6.6,13.85],[2,1.01,15.51]],"ltp":2.58,"tv":42.04,"id":7287690},{"batb":[[0,1.13,390.04],[1,1.12,369.94],[2,1.01,15.51]],"batl":[[0,1.16,42.01]],"ltp":1.09,"tv":384.35,"id":7414058}]}]}
{"op":"mcm","clk":"1006669650","pt":1580650091148,"mc":[{"id":"1.168224555","rc":[{"batb":[[0,6.6,13.85],[1,1.01,15.51],[2,1.01,0]],"batl":[[0,11.5,70.11],[1,11.5,0]],"ltp":2.58,"tv":42.04,"id":7287690},{"batb":[[1,1.12,201.9]],"batl":[[0,1.17,464.86],[1,1.43,872.38],[2,1.43,0]],"ltp":1.09,"tv":384.35,"id":7414058}]}]}
{"op":"mcm","clk":"1006669932","pt":1580650092751,"mc":[{"id":"1.168224555","rc":[{"batb":[[1,1.12,954.27]],"batl":[[0,1.17,751.09],[1,1.18,342.9],[2,1.43,872.38]],"ltp":1.09,"tv":384.35,"id":7414058}]}]}
{"op":"mcm","clk":"1006670582","pt":1580650097272,"mc":[{"id":"1.168224555","rc":[{"batb":[[0,1.13,214.97],[1,1.12,201.9]],"ltp":1.09,"tv":384.35,"id":7414058}]}]}
{"op":"mcm","clk":"1006671017","pt":1580650100297,"mc":[{"id":"1.168224555","rc":[{"batb":[[0,1.14,912.7],[1,1.13,214.97],[2,1.12,201.9]],"ltp":1.09,"tv":384.35,"id":7414058}]}]}
{"op":"mcm","clk":"1006671185","pt":1580650101393,"mc":[{"id":"1.168224555","rc":[{"batb":[[1,5.1,12.59],[2,1.01,15.51]],"ltp":2.58,"tv":42.04,"id":7287690},{"batb":[[0,1.14,1012.14],[2,1.11,216.53]],"batl":[[0,1.17,650.57],[1,1.43,872.38],[2,1.43,0]],"ltp":1.09,"tv":384.35,"id":7414058}]}]}
{"op":"mcm","clk":"1006671353","pt":1580650102381,"mc":[{"id":"1.168224555","rc":[{"batb":[[0,7.2,6.72],[1,6.6,13.85],[2,5.1,12.59]],"batl":[[0,9.2,5.04],[1,11.5,70.11]],"ltp":2.58,"tv":42.04,"id":7287690},{"batb":[[2,1.12,168.04]],"batl":[[0,1.16,42.01],[1,1.17,650.57],[2,1.43,872.38]],"ltp":1.09,"tv":384.35,"id":7414058}]}]}
{"op":"mcm","clk":"1006671555","pt":1580650103807,"mc":[{"id":"1.168224555","rc":[{"batb":[[1,1.13,289.28]],"batl":[[0,1.16,215.64]],"ltp":1.09,"tv":384.35,"id":7414058}]}]}
{"op":"mcm","clk":"1006675794","pt":1580650135856,"mc":[{"id":"1.168224555","rc":[{"trd":[[1.16,7.58]],"batl":[[0,1.16,211.85]],"ltp":1.16,"tv":391.93,"id":7414058}],"tv":433.98}]}
{"op":"mcm","clk":"1006676204","pt":1580650139132,"mc":[{"id":"1.168224555","rc":[{"batl":[[0,1.16,215.21]],"ltp":1.16,"tv":391.93,"id":7414058}]}]}
{"op":"mcm","clk":"1006678219","pt":1580650152937,"mc":[{"id":"1.168224555","rc":[{"batb":[[0,1.14,954.06]],"ltp":1.16,"tv":391.93,"id":7414058}]}]}
{"op":"mcm","clk":"1006678598","pt":1580650155975,"mc":[{"id":"1.168224555","rc":[{"batb":[[1,1.13,347.88]],"batl":[[0,1.16,272.17]],"ltp":1.16,"tv":391.93,"id":7414058}]}]}
{"op":"mcm","clk":"1006682156","pt":1580650183373,"mc":[{"id":"1.168224555","rc":[{"batb":[[0,1.14,920.33]],"ltp":1.16,"tv":391.93,"id":7414058}]}]}
{"op":"mcm","clk":"1006682547","pt":1580650186400,"mc":[{"id":"1.168224555","rc":[{"batb":[[1,1.13,381.9]],"batl":[[0,1.16,305.24]],"ltp":1.16,"tv":391.93,"id":7414058}]}]}
{"op":"mcm","clk":"1006683105","pt":1580650190385,"mc":[{"id":"1.168224555","rc":[{"batb":[[0,1.14,173.1],[1,1.12,168.04],[2,1.11,216.53]],"batl":[[0,1.16,41.58],[1,1.43,872.38],[2,1.43,0]],"ltp":1.16,"tv":391.93,"id":7414058}]}]}
{"op":"mcm","clk":"1006683235","pt":1580650191200,"mc":[{"id":"1.168224555","rc":[{"batb":[[0,5.1,12.59],[1,1.01,15.51],[2,5.1,0]],"batl":[[0,11.5,70.11],[1,11.5,0]],"ltp":2.58,"tv":42.04,"id":7287690},{"batb":[[0,1.11,216.53],[1,1.01,15.51],[2,1.11,0]],"batl":[[0,1.43,872.38],[1,1.43,0]],"ltp":1.16,"tv":391.93,"id":7414058}]}]}
{"op":"mcm","clk":"1006683522","pt":1580650193292,"mc":[{"id":"1.168224555","rc":[{"batb":[[0,1.12,258.84],[1,1.11,1111.57],[2,1.01,15.51]],"batl":[[0,1.22,319.41],[1,1.23,455.87],[2,1.43,872.38]],"ltp":1.16,"tv":391.93,"id":7414058}]}]}
{"op":"mcm","clk":"1006683620","pt":1580650193812,"mc":[{"id":"1.168224555","rc":[{"batb":[[0,1.11,216.53],[1,1.01,15.51],[2,1.01,0]],"batl":[[0,1.43,872.38],[1,1.23,0],[2,1.43,0]],"ltp":1.16,"tv":391.93,"id":7414058}]}]}
{"op":"mcm","clk":"1006684289","pt":1580650197415,"mc":[{"id":"1.168224555","rc":[{"batb":[[0,1.15,726.11],[1,1.14,393.3],[2,1.11,216.53]],"batl":[[0,1.17,181.3],[1,1.18,612.43],[2,1.43,872.38]],"ltp":1.16,"tv":391.93,"id":7414058}]}]}
{"op":"mcm","clk":"1006684314","pt":1580650197629,"mc":[{"id":"1.168224555","rc":[{"batb":[[0,1.11,216.53],[1,1.01,15.51],[2,1.11,0]],"batl":[[0,1.43,872.38],[1,1.18,0],[2,1.43,0]],"ltp":1.16,"tv":391.93,"id":7414058}]}]}
{"op":"mcm","clk":"1006684475","pt":1580650198815,"mc":[{"id":"1.168224555","rc":[{"batl":[[0,9.8,75.27]],"ltp":2.58,"tv":42.04,"id":7287690}]}]}
{"op":"mcm","clk":"1006684730","pt":1580650200647,"mc":[{"id":"1.168224555","rc":[{"batb":[[0,1.12,258.84],[1,1.11,1111.57],[2,1.01,15.51]],"batl":[[0,1.22,319.41],[1,1.23,455.87],[2,1.43,872.38]],"ltp":1.16,"tv":391.93,"id":7414058}]}]}
{"op":"mcm","clk":"1006685213","pt":1580650203216,"mc":[{"id":"1.168224555","rc":[{"batb":[[0,1.11,216.53],[1,1.01,15.51],[2,1.01,0]],"batl":[[0,1.43,872.38],[1,1.23,0],[2,1.43,0]],"ltp":1.16,"tv":391.93,"id":7414058}]}]}
{"op":"mcm","clk":"1006685812","pt":1580650206320,"mc":[{"id":"1.168224555","rc":[{"batb":[[0,1.12,258.84],[1,1.11,1111.57],[2,1.01,15.51]],"batl":[[0,1.14,939.08],[1,1.15,185.08],[2,1.43,872.38]],"ltp":1.16,"tv":391.93,"id":7414058}]}]}
{"op":"mcm","clk":"1006685939","pt":1580650207115,"mc":[{"id":"1.168224555","rc":[{"batb":[[0,7.8,9.6],[1,6,16.92],[2,1.01,15.51]],"ltp":2.58,"tv":42.04,"id":7287690},{"batb":[[2,1.09,265.55]],"ltp":1.16,"tv":391.93,"id":7414058}]}]}
{"op":"mcm","clk":"1006686126","pt":1580650208142,"mc":[{"id":"1.168224555","rc":[{"batb":[[0,8.2,5.04],[1,7.8,9.6],[2,6,16.92]],"batl":[[0,10.5,4.2]],"ltp":2.58,"tv":42.04,"id":7287690},{"batb":[[2,1.1,168.04]],"batl":[[0,1.14,981.09]],"ltp":1.16,"tv":391.93,"id":7414058}]}]}
{"op":"mcm","clk":"1006686234","pt":1580650208835,"mc":[{"id":"1.168224555","rc":[{"batl":[[1,14,62.58]],"ltp":2.58,"tv":42.04,"id":7287690}]}]}
{"op":"mcm","clk":"1006688166","pt":1580650222156,"mc":[{"id":"1.168224555","rc":[{"batb":[[1,6,16.92],[2,1.01,15.51]],"ltp":2.58,"tv":42.04,"id":7287690},{"batb":[[0,1.1,168.04],[1,1.09,265.55],[2,1.01,15.51]],"batl":[[0,1.14,42.01],[1,1.43,872.38],[2,1.43,0]],"ltp":1.16,"tv":391.93,"id":7414058}]}]}
{"op":"mcm","clk":"1006688303","pt":1580650223158,"mc":[{"id":"1.168224555","rc":[{"batb":[[0,6,16.92],[1,1.01,15.51],[2,1.01,0]],"batl":[[0,14,62.58],[1,14,0]],"ltp":2.58,"tv":42.04,"id":7287690},{"batb":[[0,1.09,265.55],[1,1.01,15.51],[2,1.01,0]],"batl":[[0,1.43,872.38],[1,1.43,0]],"ltp":1.16,"tv":391.93,"id":7414058}]}]}
{"op":"mcm","clk":"1006688425","pt":1580650224337,"mc":[{"id":"1.168224555","rc":[{"batb":[[0,1.1,475.5],[1,1.09,963.11],[2,1.01,15.51]],"batl":[[0,1.18,668.83],[1,1.19,415.28],[2,1.43,872.38]],"ltp":1.16,"tv":391.93,"id":7414058}]}]}
{"op":"mcm","clk":"1006689762","pt":1580650234848,"mc":[{"id":"1.168224555","rc":[{"batl":[[0,1.43,872.38],[1,1.19,0],[2,1.43,0]],"ltp":1.16,"tv":391.93,"id":7414058}]}]}
{"op":"mcm","clk":"1006690080","pt":1580650237469,"mc":[{"id":"1.168224555","rc":[{"batl":[[0,1.12,1079.52],[1,1.43,872.38]],"ltp":1.16,"tv":391.93,"id":7414058}]}]}
{"op":"mcm","clk":"1006690204","pt":1580650238455,"mc":[{"id":"1.168224555","rc":[{"batb":[[0,9.2,5.04],[1,8.8,7.08],[2,7.4,10.78]],"batl":[[0,12.5,3.36]],"ltp":2.58,"tv":42.04,"id":7287690},{"batb":[[2,1.08,308.35]],"batl":[[0,1.12,1121.53]],"ltp":1.16,"tv":391.93,"id":7414058}]}]}
{"op":"mcm","clk":"1006690478","pt":1580650240365,"mc":[{"id":"1.168224555","rc":[{"batl":[[1,17,57.33]],"ltp":2.58,"tv":42.04,"id":7287690}]}]}
{"op":"mcm","clk":"1006692861","pt":1580650258426,"mc":[{"id":"1.168224555","rc":[{"batb":[[0,1.09,630.55],[1,1.08,308.35],[2,1.01,15.51]],"batl":[[0,1.12,42.01]],"ltp":1.16,"tv":391.93,"id":7414058}]}]}
{"op":"mcm","clk":"1006692984","pt":1580650259201,"mc":[{"id":"1.168224555","rc":[{"batb":[[0,7.4,10.78],[1,1.01,15.51],[2,7.4,0]],"batl":[[0,17,57.33],[1,17,0]],"ltp":2.58,"tv":42.04,"id":7287690},{"batb":[[0,1.09,365]],"batl":[[0,1.43,872.38],[1,1.43,0]],"ltp":1.16,"tv":391.93,"id":7414058}]}]}
{"op":"mcm","clk":"1006693265","pt":1580650261289,"mc":[{"id":"1.168224555","rc":[{"batb":[[1,1.08,1128.3]],"batl":[[0,1.14,561.86],[1,1.15,559.02],[2,1.43,872.38]],"ltp":1.16,"tv":391.93,"id":7414058}]}]}
{"op":"mcm","clk":"1006693733","pt":1580650264188,"mc":[{"id":"1.168224555","rc":[{"batl":[[0,1.43,872.38],[1,1.15,0],[2,1.43,0]],"ltp":1.16,"tv":391.93,"id":7414058}]}]}
{"op":"mcm","clk":"1006694183","pt":1580650267395,"mc":[{"id":"1.168224555","rc":[{"batl":[[0,1.1,331.19],[1,1.11,828.01],[2,1.43,872.38]],"ltp":1.16,"tv":391.93,"id":7414058}]}]}
{"op":"mcm","clk":"1006694286","pt":1580650268097,"mc":[{"id":"1.168224555","rc":[{"batb":[[0,10,4.2],[1,9.8,13.69],[2,8.8,7.32]],"batl":[[0,13.5,3.36]],"ltp":2.58,"tv":42.04,"id":7287690},{"batb":[[1,1.08,1296.34],[2,1.07,338.8]],"batl":[[1,1.11,870.02]],"ltp":1.16,"tv":391.93,"id":7414058}]}]}
{"op":"mcm","clk":"1006694637","pt":1580650270704,"mc":[{"id":"1.168224555","rc":[{"batl":[[1,21,53.48]],"ltp":2.58,"tv":42.04,"id":7287690}]}]}
{"op":"mcm","clk":"1006695439","pt":1580650276314,"mc":[{"id":"1.168224555","rc":[{"batb":[[1,8.8,7.32],[2,1.01,15.51]],"ltp":2.58,"tv":42.04,"id":7287690},{"batb":[[0,1.08,987.99],[1,1.07,338.8],[2,1.01,15.51]],"batl":[[0,1.11,42.01],[1,1.43,872.38],[2,1.43,0]],"ltp":1.16,"tv":391.93,"id":7414058}]}]}
{"op":"mcm","clk":"1006695599","pt":1580650277311,"mc":[{"id":"1.168224555","rc":[{"batb":[[0,8.8,7.32],[1,1.01,15.51],[2,1.01,0]],"batl":[[0,21,53.48],[1,21,0]],"ltp":2.58,"tv":42.04,"id":7287690},{"batb":[[0,1.08,819.95]],"batl":[[0,1.43,872.38],[1,1.43,0]],"ltp":1.16,"tv":391.93,"id":7414058}]}]}
{"op":"mcm","clk":"1006695930","pt":1580650279108,"mc":[{"id":"1.168224555","rc":[{"batb":[[0,1.08,519.44]],"batl":[[0,1.09,8.4],[1,1.43,872.38]],"ltp":1.16,"tv":391.93,"id":7414058}]}]}
{"op":"mcm","clk":"1006696472","pt":1580650282236,"mc":[{"id":"1.168224555","rc":[{"trd":[[1.09,29.46]],"batb":[[0,1.09,654.36],[1,1.08,519.44],[2,1.07,338.8]],"batl":[[0,1.11,1134.86]],"ltp":1.09,"tv":408.73,"id":7414058}],"tv":450.78}]}
{"op":"mcm","clk":"1006696591","pt":1580650283142,"mc":[{"id":"1.168224555","rc":[{"batb":[[0,1.08,519.44],[1,1.07,338.8],[2,1.01,15.51]],"batl":[[0,1.43,872.38],[1,1.43,0]],"ltp":1.09,"tv":408.73,"id":7414058}]}]}
{"op":"mcm","clk":"1006696931","pt":1580650285424,"mc":[{"id":"1.168224555","rc":[{"batb":[[0,1.08,557.31]],"ltp":1.09,"tv":408.73,"id":7414058}]}]}
{"op":"mcm","clk":"1006697041","pt":1580650286127,"mc":[{"id":"1.168224555","rc":[{"batb":[[0,1.08,1109.34]],"batl":[[0,1.12,1140.98],[1,1.43,872.38]],"ltp":1.09,"tv":408.73,"id":7414058}]}]}
{"op":"mcm","clk":"1006697280","pt":1580650287517,"mc":[{"id":"1.168224555","rc":[{"batb":[[0,1.07,338.8],[1,1.01,15.51],[2,1.01,0]],"ltp":1.09,"tv":408.73,"id":7414058}]}]}
{"op":"mcm","clk":"1006697764","pt":1580650290431,"mc":[{"id":"1.168224555","rc":[{"batb":[[0,1.1,410.16],[1,1.09,763.5],[2,1.07,338.8]],"ltp":1.09,"tv":408.73,"id":7414058}]}]}
{"op":"mcm","clk":"1006697927","pt":1580650291430,"mc":[{"id":"1.168224555","rc":[{"batb":[[1,7.2,11.17],[2,1.01,15.51]],"ltp":2.58,"tv":42.04,"id":7287690},{"batb":[[1,1.09,1019.29],[2,1.08,299.46]],"ltp":1.09,"tv":408.73,"id":7414058}]}]}
{"op":"mcm","clk":"1006698053","pt":1580650292243,"mc":[{"id":"1.168224555","rc":[{"batb":[[0,9.2,5.04],[1,8.8,7.32],[2,7.2,11.17]],"batl":[[0,12.5,3.36]],"ltp":2.58,"tv":42.04,"id":7287690},{"batl":[[0,1.12,1182.99]],"ltp":1.09,"tv":408.73,"id":7414058}]}]}
{"op":"mcm","clk":"1006698198","pt":1580650293042,"mc":[{"id":"1.168224555","rc":[{"batl":[[1,17,57.33]],"ltp":2.58,"tv":42.04,"id":7287690}]}]}
{"op":"mcm","clk":"1006699545","pt":1580650301479,"mc":[{"id":"1.168224555","rc":[{"batb":[[0,1.09,599.87],[1,1.08,299.46],[2,1.01,15.51]],"batl":[[0,1.12,42.01]],"ltp":1.09,"tv":408.73,"id":7414058}]}]}
{"op":"mcm","clk":"1006699655","pt":1580650302173,"mc":[{"id":"1.168224555","rc":[{"batb":[[1,7.2,11.17],[2,1.01,15.51]],"ltp":2.58,"tv":42.04,"id":7287690},{"batb":[[0,1.09,344.08]],"ltp":1.09,"tv":408.73,"id":7414058}]}]}
{"op":"mcm","clk":"1006699836","pt":1580650303257,"mc":[{"id":"1.168224555","rc":[{"batb":[[0,7.2,11.17],[1,1.01,15.51],[2,1.01,0]],"batl":[[0,17,57.33],[1,17,0]],"ltp":2.58,"tv":42.04,"id":7287690},{"batl":[[0,1.43,872.38],[1,1.43,0]],"ltp":1.09,"tv":408.73,"id":7414058}]}]}
{"op":"mcm","clk":"1006699997","pt":1580650304437,"mc":[{"id":"1.168224555","rc":[{"batb":[[1,1.08,1140.52]],"batl":[[0,1.14,711.27],[1,1.15,410.91],[2,1.43,872.38]],"ltp":1.09,"tv":408.73,"id":7414058}]}]}
{"op":"mcm","clk":"1006700690","pt":1580650309044,"mc":[{"id":"1.168224555","rc":[{"batl":[[0,1.43,872.38],[1,1.15,0],[2,1.43,0]],"ltp":1.09,"tv":408.73,"id":7414058}]}]}
{"op":"mcm","clk":"1006701185","pt":1580650312268,"mc":[{"id":"1.168224555","rc":[{"batb":[[0,10.5,4.2],[1,7.2,11.17],[2,1.01,15.51]],"ltp":2.58,"tv":42.04,"id":7287690},{"batl":[[0,1.1,353.9],[1,1.11,847.43],[2,1.43,872.38]],"ltp":1.09,"tv":408.73,"id":7414058}]}]}
{"op":"mcm","clk":"1006701320","pt":1580650313228,"mc":[{"id":"1.168224555","rc":[{"batb":[[1,9.6,14.4],[2,8.6,7.63]],"ltp":2.58,"tv":42.04,"id":7287690},{"batb":[[2,1.06,403.01]],"ltp":1.09,"tv":408.73,"id":7414058}]}]}
{"op":"mcm","clk":"1006701481","pt":1580650314240,"mc":[{"id":"1.168224555","rc":[{"batl":[[0,21,53.48]],"ltp":2.58,"tv":42.04,"id":7287690}]}]}
{"op":"mcm","clk":"1006702770","pt":1580650323445,"mc":[{"id":"1.168224555","rc":[{"trd":[[1.1,7.58]],"batl":[[0,1.1,350.11]],"ltp":1.1,"tv":416.3,"id":7414058}],"tv":458.35}]}
{"op":"mcm","clk":"1006704122","pt":1580650333374,"mc":[{"id":"1.168224555","rc":[{"batb":[[0,8.6,7.63],[1,1.01,15.51],[2,8.6,0]],"ltp":2.58,"tv":42.04,"id":7287690},{"batb":[[0,1.06,403.01],[1,1.01,15.51],[2,1.06,0]],"batl":[[0,1.43,872.38],[1,1.11,0],[2,1.43,0]],"ltp":1.1,"tv":416.3,"id":7414058}]}]}
{"op":"mcm","clk":"1006704561","pt":1580650336168,"mc":[{"id":"1.168224555","rc":[{"batb":[[0,1.07,243.76],[1,1.06,1367.62],[2,1.01,15.51]],"batl":[[0,1.12,547.14],[1,1.13,593.38],[2,1.43,872.38]],"ltp":1.1,"tv":416.3,"id":7414058}]}]}
{"op":"mcm","clk":"1006704620","pt":1580650336555,"mc":[{"id":"1.168224555","rc":[{"batb":[[0,1.06,403.01],[1,1.01,15.51],[2,1.01,0]],"ltp":1.1,"tv":416.3,"id":7414058}]}]}
{"op":"mcm","clk":"1006705039","pt":1580650339466,"mc":[{"id":"1.168224555","rc":[{"batb":[[0,1.1,1108.48],[1,1.06,403.01],[2,1.01,15.51]],"ltp":1.1,"tv":416.3,"id":7414058}]}]}
{"op":"mcm","clk":"1006705167","pt":1580650340371,"mc":[{"id":"1.168224555","rc":[{"batb":[[0,9.2,5.04],[1,8.6,7.63],[2,7.6,9.84]],"batl":[[0,12.5,3.36]],"ltp":2.58,"tv":42.04,"id":7287690},{"batb":[[1,1.09,249.58],[2,1.07,314.1]],"batl":[[0,1.12,589.15]],"ltp":1.1,"tv":416.3,"id":7414058}]}]}
{"op":"mcm","clk":"1006705475","pt":1580650342452,"mc":[{"id":"1.168224555","rc":[{"batl":[[1,17,57.33]],"ltp":2.58,"tv":42.04,"id":7287690}]}]}
{"op":"mcm","clk":"1006706299","pt":1580650348172,"mc":[{"id":"1.168224555","rc":[{"batb":[[1,7.6,9.84],[2,1.01,15.51]],"ltp":2.58,"tv":42.04,"id":7287690},{"batb":[[0,1.07,314.1],[1,1.01,15.51],[2,1.07,0]],"batl":[[0,1.12,42.01],[1,1.43,872.38],[2,1.43,0]],"ltp":1.1,"tv":416.3,"id":7414058}]}]}
{"op":"mcm","clk":"1006706431","pt":1580650349294,"mc":[{"id":"1.168224555","rc":[{"batb":[[0,7.6,9.84],[1,1.01,15.51],[2,1.01,0]],"batl":[[0,17,57.33],[1,17,0]],"ltp":2.58,"tv":42.04,"id":7287690},{"batl":[[0,1.43,872.38],[1,1.43,0]],"ltp":1.1,"tv":416.3,"id":7414058}]}]}
{"op":"mcm","clk":"1006707086","pt":1580650354058,"mc":[{"id":"1.168224555","rc":[{"batb":[[0,1.1,628.91],[1,1.09,542.68],[2,1.07,314.1]],"batl":[[0,1.12,954.46],[1,1.13,189.66],[2,1.43,872.38]],"ltp":1.1,"tv":416.3,"id":7414058}]}]}
{"op":"mcm","clk":"1006707335","pt":1580650355786,"mc":[{"id":"1.168224555","rc":[{"batb":[[0,1.07,314.1],[1,1.01,15.51],[2,1.07,0]],"batl":[[0,1.43,872.38],[1,1.13,0],[2,1.43,0]],"ltp":1.1,"tv":416.3,"id":7414058}]}]}
{"op":"mcm","clk":"1006707772","pt":1580650358692,"mc":[{"id":"1.168224555","rc":[{"batb":[[0,1.08,1188.26],[1,1.07,314.1],[2,1.01,15.51]],"batl":[[0,1.14,833.91],[1,1.15,289.26],[2,1.43,872.38]],"ltp":1.1,"tv":416.3,"id":7414058}]}]}
{"op":"mcm","clk":"1006708026","pt":1580650359781,"mc":[{"id":"1.168224555","rc":[{"batl":[[0,1.43,872.38],[1,1.15,0],[2,1.43,0]],"ltp":1.1,"tv":416.3,"id":7414058}]}]}
{"op":"mcm","clk":"1006708621","pt":1580650363412,"mc":[{"id":"1.168224555","rc":[{"batb":[[0,10,13.3],[1,8.6,7.55],[2,7.6,9.84]],"ltp":2.58,"tv":42.04,"id":7287690},{"batb":[[2,1.05,451.4]],"batl":[[0,1.1,707.48],[1,1.11,455.04],[2,1.43,872.38]],"ltp":1.1,"tv":416.3,"id":7414058}]}]}
{"op":"mcm","clk":"1006708740","pt":1580650364201,"mc":[{"id":"1.168224555","rc":[{"batb":[[0,10.5,4.2],[1,10,13.3],[2,8.6,7.55]],"ltp":2.58,"tv":42.04,"id":7287690}]}]}
{"op":"mcm","clk":"1006708973","pt":1580650365711,"mc":[{"id":"1.168224555","rc":[{"batl":[[0,21,53.48]],"ltp":2.58,"tv":42.04,"id":7287690}]}]}
{"op":"mcm","clk":"1006710543","pt":1580650376227,"mc":[{"id":"1.168224555","rc":[{"batb":[[1,8.6,7.55],[2,1.01,15.51]],"ltp":2.58,"tv":42.04,"id":7287690},{"batb":[[0,1.05,451.4],[1,1.01,15.51],[2,1.05,0]],"batl":[[0,1.43,872.38],[1,1.11,0],[2,1.43,0]],"ltp":1.1,"tv":416.3,"id":7414058}]}]}
{"op":"mcm","clk":"1006710715","pt":1580650377221,"mc":[{"id":"1.168224555","rc":[{"batb":[[0,8.6,7.55],[1,1.01,15.51],[2,1.01,0]],"ltp":2.58,"tv":42.04,"id":7287690}]}]}
{"op":"mcm","clk":"1006710985","pt":1580650379181,"mc":[{"id":"1.168224555","rc":[{"batb":[[0,1.06,1038.97],[1,1.05,451.4],[2,1.01,15.51]],"batl":[[0,1.12,520.1],[1,1.13,620.18],[2,1.43,872.38]],"ltp":1.1,"tv":416.3,"id":7414058}]}]}
{"op":"mcm","clk":"1006711766","pt":1580650384614,"mc":[{"id":"1.168224555","rc":[{"batl":[[0,1.43,872.38],[1,1.13,0],[2,1.43,0]],"ltp":1.1,"tv":416.3,"id":7414058}]}]}
{"op":"mcm","clk":"1006712308","pt":1580650388411,"mc":[{"id":"1.168224555","rc":[{"batb":[[0,13,10.52],[1,10,12.59],[2,1.01,15.51]],"ltp":2.58,"tv":42.04,"id":7287690},{"batb":[[2,1.02,819.47]],"batl":[[0,1.07,342.1],[1,1.08,891.33]],"ltp":1.1,"tv":416.3,"id":7414058}]}]}
{"op":"mcm","clk":"1006712634","pt":1580650391012,"mc":[{"id":"1.168224555","rc":[{"batl":[[0,30,47.16]],"ltp":2.58,"tv":42.04,"id":7287690},{"batl":[[2,1.35,1057.18]],"ltp":1.1,"tv":416.3,"id":7414058}]}]}
{"op":"mcm","clk":"1006714733","pt":1580650407264,"mc":[{"id":"1.168224555","rc":[{"batb":[[0,10,12.59],[1,1.01,15.51],[2,1.01,0]],"ltp":2.58,"tv":42.04,"id":7287690},{"batb":[[0,1.02,819.47],[1,1.01,15.51],[2,1.02,0]],"batl":[[0,1.35,1057.18],[1,1.08,0],[2,1.35,0]],"ltp":1.1,"tv":416.3,"id":7414058}]}]}
{"op":"mcm","clk":"1006715523","pt":1580650413443,"mc":[{"id":"1.168224555","rc":[{"batb":[[0,1.05,1222.21],[1,1.02,819.47],[2,1.01,15.51]],"batl":[[0,1.07,1199.36],[1,1.35,1057.18]],"ltp":1.1,"tv":416.3,"id":7414058}]}]}
{"op":"mcm","clk":"1006715915","pt":1580650415688,"mc":[{"id":"1.168224555","rc":[{"batb":[[0,1.02,819.47],[1,1.01,15.51],[2,1.01,0]],"batl":[[0,1.35,1057.18],[1,1.35,0]],"ltp":1.1,"tv":416.3,"id":7414058}]}]}
{"op":"mcm","clk":"1006716376","pt":1580650418674,"mc":[{"id":"1.168224555","rc":[{"batb":[[0,1.03,1245.94],[1,1.02,819.47],[2,1.01,15.51]],"batl":[[0,1.1,1046.94]],"ltp":1.1,"tv":416.3,"id":7414058}]}]}
{"op":"mcm","clk":"1006717833","pt":1580650428666,"mc":[{"id":"1.168224555","rc":[{"batb":[[0,1.02,819.47],[1,1.01,15.51],[2,1.01,0]],"ltp":1.1,"tv":416.3,"id":7414058}]}]}
{"op":"mcm","clk":"1006718402","pt":1580650432390,"mc":[{"id":"1.168224555","rc":[{"batb":[[0,11,4.2],[1,10,12.59],[2,8.4,7.95]],"ltp":2.58,"tv":42.04,"id":7287690},{"batb":[[0,1.08,1095.69],[1,1.07,323.85],[2,1.04,548.33]],"batl":[[0,1.1,1088.95]],"ltp":1.1,"tv":416.3,"id":7414058}]}]}
{"op":"mcm","clk":"1006718693","pt":1580650434465,"mc":[{"id":"1.168224555","rc":[{"batl":[[0,21,53.48]],"ltp":2.58,"tv":42.04,"id":7287690},{"batl":[[1,1.38,972.97]],"ltp":1.1,"tv":416.3,"id":7414058}]}]}
{"op":"mcm","clk":"1006720821","pt":1580650449292,"mc":[{"id":"1.168224555","rc":[{"batb":[[0,8.4,7.95],[1,1.01,15.51],[2,8.4,0]],"ltp":2.58,"tv":42.04,"id":7287690},{"batb":[[0,1.04,548.33],[1,1.01,15.51],[2,1.04,0]],"batl":[[0,1.38,972.97],[1,1.38,0]],"ltp":1.1,"tv":416.3,"id":7414058}]}]}
{"op":"mcm","clk":"1006721222","pt":1580650452095,"mc":[{"id":"1.168224555","rc":[{"batb":[[0,1.05,1222.21],[1,1.04,548.33],[2,1.01,15.51]],"batl":[[0,1.13,1032.97],[1,1.38,972.97]],"ltp":1.1,"tv":416.3,"id":7414058}]}]}
{"op":"mcm","clk":"1006722182","pt":1580650459137,"mc":[{"id":"1.168224555","rc":[{"batl":[[0,1.38,972.97],[1,1.38,0]],"ltp":1.1,"tv":416.3,"id":7414058}]}]}
{"op":"mcm","clk":"1006722608","pt":1580650462238,"mc":[{"id":"1.168224555","rc":[{"batl":[[0,1.06,477.57],[1,1.07,726.25],[2,1.38,972.97]],"ltp":1.1,"tv":416.3,"id":7414058}]}]}
{"op":"mcm","clk":"1006722709","pt":1580650462888,"mc":[{"id":"1.168224555","rc":[{"batb":[[0,15,5.11],[1,10,12.43],[2,1.01,15.51]],"ltp":2.58,"tv":42.04,"id":7287690},{"batl":[[1,1.07,768.26]],"ltp":1.1,"tv":416.3,"id":7414058}]}]}
{"op":"mcm","clk":"1006722995","pt":1580650465015,"mc":[{"id":"1.168224555","rc":[{"batl":[[0,42,43.68]],"ltp":2.58,"tv":42.04,"id":7287690}]}]}
{"op":"mcm","clk":"1006725335","pt":1580650481397,"mc":[{"id":"1.168224555","rc":[{"batb":[[0,10,12.43],[1,1.01,15.51],[2,1.01,0]],"ltp":2.58,"tv":42.04,"id":7287690},{"batb":[[0,1.01,15.51],[1,1.04,0],[2,1.01,0]],"batl":[[0,1.38,972.97],[1,1.07,0],[2,1.38,0]],"ltp":1.1,"tv":416.3,"id":7414058}]}]}
{"op":"mcm","clk":"1006726121","pt":1580650487149,"mc":[{"id":"1.168224555","rc":[{"batb":[[0,1.04,1233.96],[1,1.01,15.51]],"batl":[[0,1.06,1210.68]],"ltp":1.1,"tv":416.3,"id":7414058}]}]}
{"op":"mcm","clk":"1006726382","pt":1580650489054,"mc":[{"id":"1.168224555","rc":[{"batb":[[0,1.01,15.51],[1,1.01,0]],"ltp":1.1,"tv":416.3,"id":7414058}]}]}
{"op":"mcm","clk":"1006726763","pt":1580650491944,"mc":[{"id":"1.168224555","rc":[{"batb":[[0,1.01,1286.12]],"batl":[[0,1.1,1093.48]],"ltp":1.1,"tv":416.3,"id":7414058}]}]}
{"op":"mcm","clk":"1006727735","pt":1580650499262,"mc":[{"id":"1.168224555","rc":[{"batl":[[0,1.02,1258.15]],"ltp":1.1,"tv":416.3,"id":7414058}]}]}
{"op":"mcm","clk":"1006727866","pt":1580650500340,"mc":[{"id":"1.168224555","rc":[{"batb":[[0,23,5.82]],"ltp":2.58,"tv":42.04,"id":7287690}]}]}
{"op":"mcm","clk":"1006727967","pt":1580650501173,"mc":[{"id":"1.168224555","rc":[{"batl":[[1,1.29,1276.55]],"ltp":1.1,"tv":416.3,"id":7414058}]}]}
{"op":"mcm","clk":"1006735836","pt":1580650555651,"mc":[{"id":"1.168224555","rc":[{"trd":[[1.02,30.28]],"batl":[[0,1.02,1243.01]],"ltp":1.02,"tv":446.59,"id":7414058}],"tv":488.64}]}
{"op":"mcm","clk":"1006740762","pt":1580650590174,"mc":[{"id":"1.168224555","rc":[{"batl":[[0,1.29,1276.55],[1,1.29,0]],"ltp":1.02,"tv":446.59,"id":7414058}]}]}
{"op":"mcm","clk":"1006741196","pt":1580650593073,"mc":[{"id":"1.168224555","rc":[{"batl":[[0,1.04,1233.96],[1,1.29,1276.55]],"ltp":1.02,"tv":446.59,"id":7414058}]}]}
{"op":"mcm","clk":"1006741857","pt":1580650597390,"mc":[{"id":"1.168224555","rc":[{"batb":[[0,1.01,15.51]],"ltp":1.02,"tv":446.59,"id":7414058}]}]}
{"op":"mcm","clk":"1006742329","pt":1580650600473,"mc":[{"id":"1.168224555","rc":[{"batb":[[0,1.02,1258.15],[1,1.01,15.51]],"batl":[[0,1.04,1023.8]],"ltp":1.02,"tv":446.59,"id":7414058}]}]}
{"op":"mcm","clk":"1006742411","pt":1580650601077,"mc":[{"id":"1.168224555","rc":[{"batb":[[1,16,4.33],[2,1.01,15.51]],"ltp":2.58,"tv":42.04,"id":7287690}]}]}
{"op":"mcm","clk":"1006742586","pt":1580650602277,"mc":[{"id":"1.168224555","rc":[{"batb":[[0,1.02,1426.19]],"ltp":1.02,"tv":446.59,"id":7414058}]}]}
{"op":"mcm","clk":"1006742712","pt":1580650603285,"mc":[{"id":"1.168224555","rc":[{"batl":[[0,160,37.1]],"ltp":2.58,"tv":42.04,"id":7287690}]}]}
{"op":"mcm","clk":"1006742780","pt":1580650603878,"mc":[{"id":"1.168224555","rc":[{"batl":[[0,1.03,212.19],[1,1.04,1023.8],[2,1.29,1276.55]],"ltp":1.02,"tv":446.59,"id":7414058}]}]}
{"op":"mcm","clk":"1006743728","pt":1580650610381,"mc":[{"id":"1.168224555","rc":[{"batb":[[0,16,4.33],[1,1.01,15.51],[2,1.01,0]],"ltp":2.58,"tv":42.04,"id":7287690},{"batb":[[0,1.02,168.04]],"batl":[[0,1.29,1276.55],[1,1.04,0],[2,1.29,0]],"ltp":1.02,"tv":446.59,"id":7414058}]}]}
{"op":"mcm","clk":"1006743835","pt":1580650611289,"mc":[{"id":"1.168224555","rc":[{"batb":[[0,1.01,15.51],[1,1.01,0]],"ltp":1.02,"tv":446.59,"id":7414058}]}]}
{"op":"mcm","clk":"1006744118","pt":1580650613311,"mc":[{"id":"1.168224555","rc":[{"batb":[[0,1.01,1286.12]],"batl":[[0,1.05,570.54],[1,1.06,645.52],[2,1.29,1276.55]],"ltp":1.02,"tv":446.59,"id":7414058}]}]}
{"op":"mcm","clk":"1006744695","pt":1580650617673,"mc":[{"id":"1.168224555","rc":[{"batb":[[0,1.01,15.51]],"ltp":1.02,"tv":446.59,"id":7414058}]}]}
{"op":"mcm","clk":"1006745219","pt":1580650621316,"mc":[{"id":"1.168224555","rc":[{"batb":[[1,11.5,9.44],[2,1.01,15.51]],"ltp":2.58,"tv":42.04,"id":7287690},{"batb":[[0,1.04,1233.96],[1,1.03,600.26],[2,1.02,868.02]],"ltp":1.02,"tv":446.59,"id":7414058}]}]}
{"op":"mcm","clk":"1006745364","pt":1580650622310,"mc":[{"id":"1.168224555","rc":[{"batl":[[0,1.05,612.55]],"ltp":1.02,"tv":446.59,"id":7414058}]}]}
{"op":"mcm","clk":"1006745686","pt":1580650624418,"mc":[{"id":"1.168224555","rc":[{"batl":[[0,42,43.68]],"ltp":2.58,"tv":42.04,"id":7287690}]}]}
{"op":"mcm","clk":"1006746558","pt":1580650630439,"mc":[{"id":"1.168224555","rc":[{"batb":[[0,11.5,9.44],[1,1.01,15.51],[2,1.01,0]],"ltp":2.58,"tv":42.04,"id":7287690},{"batb":[[0,1.02,868.02],[1,1.01,15.51],[2,1.02,0]],"batl":[[0,1.05,42.01],[1,1.29,1276.55],[2,1.29,0]],"ltp":1.02,"tv":446.59,"id":7414058}]}]}
{"op":"mcm","clk":"1006746709","pt":1580650631318,"mc":[{"id":"1.168224555","rc":[{"batl":[[0,1.29,1276.55],[1,1.29,0]],"ltp":1.02,"tv":446.59,"id":7414058}]}]}
{"op":"mcm","clk":"1006747402","pt":1580650636054,"mc":[{"id":"1.168224555","rc":[{"batb":[[0,1.04,1233.96],[1,1.02,868.02],[2,1.01,15.51]],"batl":[[0,1.06,1210.68],[1,1.29,1276.55]],"ltp":1.02,"tv":446.59,"id":7414058}]}]}
{"op":"mcm","clk":"1006747500","pt":1580650636752,"mc":[{"id":"1.168224555","rc":[{"batb":[[0,1.02,868.02],[1,1.01,15.51],[2,1.01,0]],"batl":[[0,1.29,1276.55],[1,1.29,0]],"ltp":1.02,"tv":446.59,"id":7414058}]}]}
{"op":"mcm","clk":"1006747924","pt":1580650639639,"mc":[{"id":"1.168224555","rc":[{"batb":[[0,1.03,1245.94],[1,1.02,868.02],[2,1.01,15.51]],"batl":[[0,1.08,1188.26],[1,1.29,1276.55]],"ltp":1.02,"tv":446.59,"id":7414058}]}]}
{"op":"mcm","clk":"1006749504","pt":1580650650364,"mc":[{"id":"1.168224555","rc":[{"batb":[[0,1.02,868.02],[1,1.01,15.51],[2,1.01,0]],"batl":[[0,1.29,1276.55],[1,1.29,0]],"ltp":1.02,"tv":446.59,"id":7414058}]}]}
{"op":"mcm","clk":"1006749990","pt":1580650653471,"mc":[{"id":"1.168224555","rc":[{"batb":[[0,1.03,1245.94],[1,1.02,868.02],[2,1.01,15.51]],"batl":[[0,1.04,1233.96],[1,1.29,1276.55]],"ltp":1.02,"tv":446.59,"id":7414058}]}]}
{"op":"mcm","clk":"1006750135","pt":1580650654484,"mc":[{"id":"1.168224555","rc":[{"batb":[[0,20,4.8],[1,13.5,6.61],[2,11.5,9.44]],"ltp":2.58,"tv":42.04,"id":7287690}]}]}
{"op":"mcm","clk":"1006750168","pt":1580650654666,"mc":[{"id":"1.168224555","rc":[{"batb":[[2,1.01,15.51]],"ltp":2.58,"tv":42.04,"id":7287690},{"batl":[[0,1.04,1275.97]],"ltp":1.02,"tv":446.59,"id":7414058}]}]}
{"op":"mcm","clk":"1006750479","pt":1580650656870,"mc":[{"id":"1.168224555","rc":[{"batl":[[0,95,38.77]],"ltp":2.58,"tv":42.04,"id":7287690}]}]}
{"op":"mcm","clk":"1006752486","pt":1580650670215,"mc":[{"id":"1.168224555","rc":[{"batb":[[0,13.5,6.61],[1,1.01,15.51],[2,1.01,0]],"ltp":2.58,"tv":42.04,"id":7287690},{"batb":[[0,1.01,15.51],[1,1.02,0],[2,1.01,0]],"batl":[[0,1.04,42.01]],"ltp":1.02,"tv":446.59,"id":7414058}]}]}
{"op":"mcm","clk":"1006752652","pt":1580650671288,"mc":[{"id":"1.168224555","rc":[{"batl":[[0,1.29,1276.55],[1,1.29,0]],"ltp":1.02,"tv":446.59,"id":7414058}]}]}
{"op":"mcm","clk":"1006753194","pt":1580650674970,"mc":[{"id":"1.168224555","rc":[{"batb":[[0,1.03,1245.94],[1,1.01,15.51]],"batl":[[0,1.05,1222.21],[1,1.29,1276.55]],"ltp":1.02,"tv":446.59,"id":7414058}]}]}
{"op":"mcm","clk":"1006753440","pt":1580650676481,"mc":[{"id":"1.168224555","rc":[{"batb":[[0,1.01,15.51],[1,1.01,0]],"batl":[[0,1.29,1276.55],[1,1.29,0]],"ltp":1.02,"tv":446.59,"id":7414058}]}]}
{"op":"mcm","clk":"1006753635","pt":1580650677990,"mc":[{"id":"1.168224555","rc":[{"batl":[[0,65,40.67]],"ltp":2.58,"tv":42.04,"id":7287690}]}]}
{"op":"mcm","clk":"1006753870","pt":1580650679497,"mc":[{"id":"1.168224555","rc":[{"batb":[[0,1.02,1258.15],[1,1.01,15.51]],"batl":[[0,1.07,1199.36],[1,1.29,1276.55]],"ltp":1.02,"tv":446.59,"id":7414058}]}]}
{"op":"mcm","clk":"1006754698","pt":1580650685112,"mc":[{"id":"1.168224555","rc":[{"trd":[[1.02,38.69]],"batb":[[0,1.02,1253.95]],"ltp":1.02,"tv":454.99,"id":7414058}],"tv":497.04}]}
{"op":"mcm","clk":"1006756044","pt":1580650694232,"mc":[{"id":"1.168224555","rc":[{"batl":[[0,1.29,1276.55],[1,1.29,0]],"ltp":1.02,"tv":454.99,"id":7414058}]}]}
{"op":"mcm","clk":"1006756506","pt":1580650697451,"mc":[{"id":"1.168224555","rc":[{"batl":[[0,1.03,1245.94],[1,1.29,1276.55]],"ltp":1.02,"tv":454.99,"id":7414058}]}]}
{"op":"mcm","clk":"1006756632","pt":1580650698316,"mc":[{"id":"1.168224555","rc":[{"batb":[[0,28,2.5],[1,17,7.79],[2,1.01,15.51]],"ltp":2.58,"tv":42.04,"id":7287690}]}]}
{"op":"mcm","clk":"1006756912","pt":1580650700249,"mc":[{"id":"1.168224555","rc":[{"batl":[[0,520,35.52]],"ltp":2.58,"tv":42.04,"id":7287690}]}]}
{"op":"mcm","clk":"1006759010","pt":1580650715034,"mc":[{"id":"1.168224555","rc":[{"batb":[[0,17,7.79],[1,1.01,15.51],[2,1.01,0]],"ltp":2.58,"tv":42.04,"id":7287690},{"batb":[[0,1.01,15.51],[1,1.01,0]],"batl":[[0,1.29,1276.55],[1,1.29,0]],"ltp":1.02,"tv":454.99,"id":7414058}]}]}
{"op":"mcm","clk":"1006759409","pt":1580650717664,"mc":[{"id":"1.168224555","rc":[{"batb":[[0,1.01,1286.12]],"batl":[[0,1.05,1176.82]],"ltp":1.02,"tv":454.99,"id":7414058}]}]}
{"op":"mcm","clk":"1006759673","pt":1580650719455,"mc":[{"id":"1.168224555","rc":[{"batb":[[0,1.01,15.51]],"ltp":1.02,"tv":454.99,"id":7414058}]}]}
{"op":"mcm","clk":"1006760128","pt":1580650722487,"mc":[{"id":"1.168224555","rc":[{"batb":[[0,1.02,1258.15],[1,1.01,15.51]],"batl":[[0,1.03,1070.32]],"ltp":1.02,"tv":454.99,"id":7414058}]}]}
{"op":"mcm","clk":"1006760453","pt":1580650724654,"mc":[{"id":"1.168224555","rc":[{"batl":[[0,160,37.1]],"ltp":2.58,"tv":42.04,"id":7287690},{"batb":[[0,1.01,15.51],[1,1.01,0]],"batl":[[0,1.3,1224.86]],"ltp":1.02,"tv":454.99,"id":7414058}]}]}
{"op":"mcm","clk":"1006760884","pt":1580650727669,"mc":[{"id":"1.168224555","rc":[{"batb":[[0,1.01,1286.12]],"batl":[[0,1.05,1176.29]],"ltp":1.02,"tv":454.99,"id":7414058}]}]}
{"op":"mcm","clk":"1006761617","pt":1580650732408,"mc":[{"id":"1.168224555","rc":[{"batl":[[0,1.02,1258.15]],"ltp":1.02,"tv":454.99,"id":7414058}]}]}
{"op":"mcm","clk":"1006761696","pt":1580650732890,"mc":[{"id":"1.168224555","rc":[{"batb":[[0,26,3.58]],"ltp":2.58,"tv":42.04,"id":7287690}]}]}
{"op":"mcm","clk":"1006762171","pt":1580650735797,"mc":[{"id":"1.168224555","rc":[{"batl":[[1,1.28,1326.22]],"ltp":1.02,"tv":454.99,"id":7414058}]}]}
{"op":"mcm","clk":"1006763507","pt":1580650743886,"mc":[{"id":"1.168224555","rc":[{"batb":[[0,1.01,15.51]],"batl":[[0,1.28,1326.22],[1,1.28,0]],"ltp":1.02,"tv":454.99,"id":7414058}]}]}
{"op":"mcm","clk":"1006763876","pt":1580650746200,"mc":[{"id":"1.168224555","rc":[{"trd":[[1.01,31.02]],"batl":[[0,1.01,984.49]],"ltp":1.01,"tv":486.01,"id":7414058}],"tv":528.06}]}
{"op":"mcm","clk":"1006764527","pt":1580650750454,"mc":[{"id":"1.168224555","rc":[{"batb":[[0,1.01,1270.61]],"batl":[[0,1.02,1258.15]],"ltp":1.01,"tv":486.01,"id":7414058}]}]}
{"op":"mcm","clk":"1006765045","pt":1580650753933,"mc":[{"id":"1.168224555","rc":[{"batl":[[1,1.29,1298.72]],"ltp":1.01,"tv":486.01,"id":7414058}]}]}
{"op":"mcm","clk":"1006765613","pt":1580650758025,"mc":[{"id":"1.168224555","rc":[{"batl":[[0,1.29,1298.72],[1,1.29,0]],"ltp":1.01,"tv":486.01,"id":7414058}]}]}
{"op":"mcm","clk":"1006765969","pt":1580650760513,"mc":[{"id":"1.168224555","rc":[{"batl":[[0,1.03,1245.94],[1,1.29,1298.72]],"ltp":1.01,"tv":486.01,"id":7414058}]}]}
{"op":"mcm","clk":"1006767585","pt":1580650770938,"mc":[{"id":"1.168224555","rc":[{"batl":[[1,1.29,0]],"ltp":1.01,"tv":486.01,"id":7414058}]}]}
{"op":"mcm","clk":"1006769263","pt":1580650781851,"mc":[{"id":"1.168224555","rc":[{"batb":[[0,1.01,15.51],[1,1.01,0]],"ltp":2.58,"tv":42.04,"id":7287690}]}]}
{"op":"mcm","clk":"1006769652","pt":1580650784340,"mc":[{"id":"1.168224555","rc":[{"batl":[[0,1.01,1270.52]],"ltp":1.01,"tv":486.01,"id":7414058}]}]}
{"op":"mcm","clk":"1006769917","pt":1580650786365,"mc":[{"id":"1.168224555","rc":[{"batl":[[0,1.01,1312.53]],"ltp":1.01,"tv":486.01,"id":7414058}]}]}
{"op":"mcm","clk":"1006770021","pt":1580650787057,"mc":[{"id":"1.168224555","rc":[{"batl":[[1,1.27,1384.57]],"ltp":1.01,"tv":486.01,"id":7414058}]}]}
{"op":"mcm","clk":"1006773335","pt":1580650809377,"mc":[{"id":"1.168224555","rc":[{"batl":[[0,1.01,1270.52]],"ltp":1.01,"tv":486.01,"id":7414058}]}]}
{"op":"mcm","clk":"1006774985","pt":1580650820281,"mc":[{"id":"1.168224555","rc":[{"batl":[[0,1.01,1312.53]],"ltp":1.01,"tv":486.01,"id":7414058}]}]}
{"op":"mcm","clk":"1006776978","pt":1580650833387,"mc":[{"id":"1.168224555","rc":[{"batl":[[0,1.01,1270.52]],"ltp":1.01,"tv":486.01,"id":7414058}]}]}
{"op":"mcm","clk":"1006777408","pt":1580650836503,"mc":[{"id":"1.168224555","rc":[{"batl":[[0,1.01,1287.32]],"ltp":1.01,"tv":486.01,"id":7414058}]}]}
{"op":"mcm","clk":"1006778308","pt":1580650842281,"mc":[{"id":"1.168224555","rc":[{"batl":[[0,1.01,1329.33]],"ltp":1.01,"tv":486.01,"id":7414058}]}]}
{"op":"mcm","clk":"1006779870","pt":1580650853245,"mc":[{"id":"1.168224555","rc":[{"batl":[[0,1.01,812.36]],"ltp":1.01,"tv":486.01,"id":7414058}]}]}
{"op":"mcm","clk":"1006780213","pt":1580650855401,"mc":[{"id":"1.168224555","rc":[{"batl":[[0,1.01,770.35]],"ltp":1.01,"tv":486.01,"id":7414058}]}]}
{"op":"mcm","clk":"1006780328","pt":1580650856214,"mc":[{"id":"1.168224555","rc":[{"batl":[[1,1.02,511.9],[2,1.27,1384.57]],"ltp":1.01,"tv":486.01,"id":7414058}]}]}
{"op":"mcm","clk":"1006782351","pt":1580650869539,"mc":[{"id":"1.168224555","rc":[{"batl":[[0,1.01,16.8]],"ltp":1.01,"tv":486.01,"id":7414058}]}]}
{"op":"mcm","clk":"1006782803","pt":1580650872575,"mc":[{"id":"1.168224555","rc":[{"batl":[[1,1.02,1258.07]],"ltp":1.01,"tv":486.01,"id":7414058}]}]}
{"op":"mcm","clk":"1006799019","pt":1580650975211,"mc":[{"id":"1.168224555","rc":[{"batl":[[1,1.02,747.69]],"ltp":1.01,"tv":486.01,"id":7414058}]}]}
{"op":"mcm","clk":"1006799521","pt":1580650978174,"mc":[{"id":"1.168224555","rc":[{"batl":[[2,1.03,505.41]],"ltp":1.01,"tv":486.01,"id":7414058}]}]}
{"op":"mcm","clk":"1006801568","pt":1580650991400,"mc":[{"id":"1.168224555","rc":[{"trd":[[1.01,64.62]],"batb":[[0,1.01,1270.52]],"batl":[[0,1.02,747.69],[1,1.03,505.41],[2,1.03,0]],"ltp":1.01,"tv":519.61,"id":7414058}],"tv":561.66}]}
{"op":"mcm","clk":"1006801722","pt":1580650992416,"mc":[{"id":"1.168224555","rc":[{"batb":[[0,21,4.04],[1,1.01,15.51]],"ltp":2.58,"tv":42.04,"id":7287690},{"batb":[[0,1.01,1269.68]],"batl":[[0,1.02,789.7]],"ltp":1.01,"tv":519.61,"id":7414058}]}]}
{"op":"mcm","clk":"1006801791","pt":1580650992709,"mc":[{"id":"1.168224555","rc":[{"batb":[[0,1.01,1253.72]],"ltp":1.01,"tv":519.61,"id":7414058}]}]}
{"op":"mcm","clk":"1006802027","pt":1580650994100,"mc":[{"id":"1.168224555","rc":[{"batl":[[2,1.29,1298.72]],"ltp":1.01,"tv":519.61,"id":7414058}]}]}
{"op":"mcm","clk":"1006802117","pt":1580650994606,"mc":[{"id":"1.168224555","rc":[{"batb":[[0,1.01,1421.76]],"ltp":1.01,"tv":519.61,"id":7414058}]}]}
{"op":"mcm","clk":"1006803324","pt":1580651001895,"mc":[{"id":"1.168224555","rc":[{"batl":[[0,1.02,42.01],[1,1.29,1298.72],[2,1.29,0]],"ltp":1.01,"tv":519.61,"id":7414058}]}]}
{"op":"mcm","clk":"1006803607","pt":1580651003404,"mc":[{"id":"1.168224555","rc":[{"batb":[[0,1.01,1253.72]],"batl":[[0,1.29,1298.72],[1,1.29,0]],"ltp":1.01,"tv":519.61,"id":7414058}]}]}
{"op":"mcm","clk":"1006803805","pt":1580651004923,"mc":[{"id":"1.168224555","rc":[{"batl":[[0,1.04,1233.87],[1,1.29,1298.72]],"ltp":1.01,"tv":519.61,"id":7414058}]}]}
{"op":"mcm","clk":"1006805149","pt":1580651013326,"mc":[{"id":"1.168224555","rc":[{"batb":[[1,15,5.11],[2,1.01,15.51]],"ltp":2.58,"tv":42.04,"id":7287690},{"trd":[[1.02,287.91],[1.03,750.78]],"batb":[[0,1.02,1517.26]],"ltp":1.02,"tv":1519.61,"id":7414058}],"tv":1561.66}]}
{"op":"mcm","clk":"1006805311","pt":1580651014417,"mc":[{"id":"1.168224555","rc":[{"batl":[[0,160,37.1]],"ltp":2.58,"tv":42.04,"id":7287690},{"batl":[[0,1.03,42.01],[1,1.04,1233.87],[2,1.29,1298.72]],"ltp":1.02,"tv":1519.61,"id":7414058}]}]}
{"op":"mcm","clk":"1006805421","pt":1580651015140,"mc":[{"id":"1.168224555","rc":[{"batl":[[0,1.04,1233.87],[1,1.29,1298.72],[2,1.29,0]],"ltp":1.02,"tv":1519.61,"id":7414058}]}]}
{"op":"mcm","clk":"1006805648","pt":1580651016448,"mc":[{"id":"1.168224555","rc":[{"trd":[[1.03,834.8]],"batb":[[0,1.03,150.28],[1,1.02,1988.25]],"ltp":1.03,"tv":1603.63,"id":7414058}],"tv":1645.68}]}
{"op":"mcm","clk":"1006805668","pt":1580651016546,"mc":[{"id":"1.168224555","rc":[{"batb":[[0,1.02,1988.25],[1,1.02,0]],"ltp":1.03,"tv":1603.63,"id":7414058}]}]}
{"op":"mcm","clk":"1006805883","pt":1580651017960,"mc":[{"id":"1.168224555","rc":[{"batb":[[0,1.02,2182.43]],"ltp":1.03,"tv":1603.63,"id":7414058}]}]}
{"op":"mcm","clk":"1006806175","pt":1580651019731,"mc":[{"id":"1.168224555","rc":[{"batl":[[0,1.03,42.01],[1,1.04,1233.87],[2,1.29,1298.72]],"ltp":1.03,"tv":1603.63,"id":7414058}]}]}
{"op":"mcm","clk":"1006807513","pt":1580651027970,"mc":[{"id":"1.168224555","rc":[{"batb":[[0,15,5.11],[1,1.01,15.51],[2,1.01,0]],"ltp":2.58,"tv":42.04,"id":7287690},{"batb":[[0,1.02,1104.16]],"batl":[[1,1.29,1298.72],[2,1.29,0]],"ltp":1.03,"tv":1603.63,"id":7414058}]}]}
{"op":"mcm","clk":"1006807755","pt":1580651029550,"mc":[{"id":"1.168224555","rc":[{"batl":[[0,1.29,1298.72],[1,1.29,0]],"ltp":1.03,"tv":1603.63,"id":7414058}]}]}
{"op":"mcm","clk":"1006807913","pt":1580651030534,"mc":[{"id":"1.168224555","rc":[{"batl":[[0,1.05,293.41],[1,1.06,919.94],[2,1.29,1298.72]],"ltp":1.03,"tv":1603.63,"id":7414058}]}]}
{"op":"mcm","clk":"1006808115","pt":1580651031957,"mc":[{"id":"1.168224555","rc":[{"batl":[[0,1.29,1298.72],[1,1.06,0],[2,1.29,0]],"ltp":1.03,"tv":1603.63,"id":7414058}]}]}
{"op":"mcm","clk":"1006808341","pt":1580651033265,"mc":[{"id":"1.168224555","rc":[{"batl":[[1,1000,0.02]],"ltp":1.03,"tv":1603.63,"id":7414058}]}]}
{"op":"mcm","clk":"1006808426","pt":1580651033749,"mc":[{"id":"1.168224555","rc":[{"batl":[[1,1000,0]],"ltp":1.03,"tv":1603.63,"id":7414058}]}]}
{"op":"mcm","clk":"1006808682","pt":1580651035259,"mc":[{"id":"1.168224555","rc":[{"batl":[[0,1.03,1245.85],[1,1.29,1298.72]],"ltp":1.03,"tv":1603.63,"id":7414058}]}]}
{"op":"mcm","clk":"1006808846","pt":1580651036264,"mc":[{"id":"1.168224555","rc":[{"batb":[[0,28,2.69],[1,17.5,7.08],[2,1.01,15.51]],"ltp":2.58,"tv":42.04,"id":7287690}]}]}
{"op":"mcm","clk":"1006808941","pt":1580651036848,"mc":[{"id":"1.168224555","rc":[{"trd":[[1.02,287.94]],"batb":[[0,1.02,1104.14]],"ltp":1.02,"tv":1603.67,"id":7414058}],"tv":1645.72}]}
{"op":"mcm","clk":"1006811364","pt":1580651052334,"mc":[{"id":"1.168224555","rc":[{"batb":[[0,17.5,7.08],[1,1.01,15.51],[2,1.01,0]],"ltp":2.58,"tv":42.04,"id":7287690},{"batl":[[0,1.29,1298.72],[1,1.29,0]],"ltp":1.02,"tv":1603.67,"id":7414058}]}]}
{"op":"mcm","clk":"1006811741","pt":1580651054818,"mc":[{"id":"1.168224555","rc":[{"batb":[[0,1.01,1270.52]],"batl":[[0,1.05,1222.12],[1,1.29,1298.72]],"ltp":1.02,"tv":1603.67,"id":7414058}]}]}
{"op":"mcm","clk":"1006811907","pt":1580651055942,"mc":[{"id":"1.168224555","rc":[{"batl":[[0,1.29,1298.72],[1,1.29,0]],"ltp":1.02,"tv":1603.67,"id":7414058}]}]}
{"op":"mcm","clk":"1006812458","pt":1580651059420,"mc":[{"id":"1.168224555","rc":[{"batl":[[0,1.02,1258.07],[1,1.29,1298.72]],"ltp":1.02,"tv":1603.67,"id":7414058}]}]}
{"op":"mcm","clk":"1006812513","pt":1580651059743,"mc":[{"id":"1.168224555","rc":[{"batb":[[0,23,3.15]],"ltp":2.58,"tv":42.04,"id":7287690}]}]}
{"op":"mcm","clk":"1006814665","pt":1580651074455,"mc":[{"id":"1.168224555","rc":[{"batl":[[0,1.29,1298.72],[1,1.29,0]],"ltp":1.02,"tv":1603.67,"id":7414058}]}]}
{"op":"mcm","clk":"1006815063","pt":1580651077361,"mc":[{"id":"1.168224555","rc":[{"batl":[[0,1.04,1233.87]],"ltp":1.02,"tv":1603.67,"id":7414058}]}]}
{"op":"mcm","clk":"1006816266","pt":1580651085472,"mc":[{"id":"1.168224555","rc":[{"batb":[[0,1.02,1258.07]],"ltp":1.02,"tv":1603.67,"id":7414058}]}]}
{"op":"mcm","clk":"1006816427","pt":1580651086484,"mc":[{"id":"1.168224555","rc":[{"batb":[[1,13,7.08],[2,1.01,15.51]],"ltp":2.58,"tv":42.04,"id":7287690},{"batb":[[0,1.02,2268.19]],"batl":[[0,1.03,42.01],[1,1.04,1233.87]],"ltp":1.02,"tv":1603.67,"id":7414058}]}]}
{"op":"mcm","clk":"1006816630","pt":1580651087887,"mc":[{"id":"1.168224555","rc":[{"batl":[[0,160,37.1]],"ltp":2.58,"tv":42.04,"id":7287690},{"batl":[[2,1.3,1224.86]],"ltp":1.02,"tv":1603.67,"id":7414058}]}]}
{"op":"mcm","clk":"1006817002","pt":1580651090373,"mc":[{"id":"1.168224555","rc":[{"batb":[[1,1.01,3.04]],"ltp":1.02,"tv":1603.67,"id":7414058}]}]}
{"op":"mcm","clk":"1006817113","pt":1580651091085,"mc":[{"id":"1.168224555","rc":[{"batb":[[1,1.01,0]],"ltp":1.02,"tv":1603.67,"id":7414058}]}]}
{"op":"mcm","clk":"1006817542","pt":1580651094296,"mc":[{"id":"1.168224555","rc":[{"batb":[[0,1.02,2268.2]],"ltp":1.02,"tv":1603.67,"id":7414058}]}]}
{"op":"mcm","clk":"1006818193","pt":1580651098390,"mc":[{"id":"1.168224555","rc":[{"batb":[[0,13,7.08],[1,1.01,15.51],[2,1.01,0]],"ltp":2.58,"tv":42.04,"id":7287690},{"batb":[[0,1.02,0.02]],"batl":[[1,1.3,1224.86],[2,1.3,0]],"ltp":1.02,"tv":1603.67,"id":7414058}]}]}
{"op":"mcm","clk":"1006818294","pt":1580651099076,"mc":[{"id":"1.168224555","rc":[{"batl":[[1,1.3,0]],"ltp":1.02,"tv":1603.67,"id":7414058}]}]}
{"op":"mcm","clk":"1006818613","pt":1580651101011,"mc":[{"id":"1.168224555","rc":[{"batb":[[0,1.01,1270.54]],"batl":[[0,1.07,1199.28]],"ltp":1.02,"tv":1603.67,"id":7414058}]}]}
{"op":"mcm","clk":"1006819837","pt":1580651107296,"mc":[{"id":"1.168224555","rc":[{"batb":[[0,30,2.44],[1,22,3.75],[2,13,7.08]],"ltp":2.58,"tv":42.04,"id":7287690},{"trd":[[1.02,287.98]],"batb":[[0,1.01,1270.52]],"batl":[[0,1.02,1258.05]],"ltp":1.02,"tv":1603.7,"id":7414058}],"tv":1645.75}]}
{"op":"mcm","clk":"1006819880","pt":1580651107513,"mc":[{"id":"1.168224555","rc":[{"batb":[[2,1.01,15.51]],"ltp":2.58,"tv":42.04,"id":7287690}]}]}
{"op":"mcm","clk":"1006820150","pt":1580651109010,"mc":[{"id":"1.168224555","rc":[{"batl":[[1,1.28,1326.22]],"ltp":1.02,"tv":1603.7,"id":7414058}]}]}
{"op":"mcm","clk":"1006822616","pt":1580651125029,"mc":[{"id":"1.168224555","rc":[{"batb":[[0,22,3.75],[1,1.01,15.51],[2,1.01,0]],"ltp":2.58,"tv":42.04,"id":7287690},{"batl":[[0,1.28,1326.22],[1,1.28,0]],"ltp":1.02,"tv":1603.7,"id":7414058}]}]}
{"op":"mcm","clk":"1006823000","pt":1580651127440,"mc":[{"id":"1.168224555","rc":[{"batl":[[0,1.04,1233.87]],"ltp":1.02,"tv":1603.7,"id":7414058}]}]}
{"op":"mcm","clk":"1006823479","pt":1580651130362,"mc":[{"id":"1.168224555","rc":[{"batb":[[0,1.01,1270.52]],"batl":[[0,1.02,1258.07]],"ltp":1.02,"tv":1603.7,"id":7414058}]}]}
{"op":"mcm","clk":"1006823952","pt":1580651133168,"mc":[{"id":"1.168224555","rc":[{"batl":[[0,1.29,1298.72]],"ltp":1.02,"tv":1603.7,"id":7414058}]}]}
{"op":"mcm","clk":"1006824235","pt":1580651134826,"mc":[{"id":"1.168224555","rc":[{"batl":[[0,1.04,1233.87]],"ltp":1.02,"tv":1603.7,"id":7414058}]}]}
{"op":"mcm","clk":"1006825990","pt":1580651145464,"mc":[{"id":"1.168224555","rc":[{"batb":[[0,30,2.68],[1,22,3.75],[2,1.01,15.51]],"ltp":2.58,"tv":42.04,"id":7287690},{"batl":[[0,1.01,1270.52]],"ltp":1.02,"tv":1603.7,"id":7414058}]}]}
{"op":"mcm","clk":"1006826136","pt":1580651146377,"mc":[{"id":"1.168224555","rc":[{"batb":[[1,1.01,15.51],[2,1.01,0]],"ltp":2.58,"tv":42.04,"id":7287690},{"batl":[[1,1.27,1384.57]],"ltp":1.02,"tv":1603.7,"id":7414058}]}]}
{"op":"mcm","clk":"1006828689","pt":1580651163271,"mc":[{"id":"1.168224555","rc":[{"batl":[[0,1.27,1384.57],[1,1.27,0]],"ltp":1.02,"tv":1603.7,"id":7414058}]}]}
{"op":"mcm","clk":"1006829521","pt":1580651169188,"mc":[{"id":"1.168224555","rc":[{"batl":[[0,1.01,1270.52]],"ltp":1.02,"tv":1603.7,"id":7414058}]}]}
{"op":"mcm","clk":"1006830347","pt":1580651174390,"mc":[{"id":"1.168224555","rc":[{"batl":[[0,1.02,1258.07]],"ltp":1.02,"tv":1603.7,"id":7414058}]}]}
{"op":"mcm","clk":"1006830909","pt":1580651178132,"mc":[{"id":"1.168224555","rc":[{"batb":[[0,1.01,15.51],[1,1.01,0]],"ltp":2.58,"tv":42.04,"id":7287690}]}]}
{"op":"mcm","clk":"1006831126","pt":1580651179149,"mc":[{"id":"1.168224555","marketDefinition":{"bspMarket":false,"turnInPlayEnabled":true,"persistenceEnabled":true,"marketBaseRate":5.0,"eventId":"29681742","eventTypeId":"2","numberOfWinners":1,"bettingType":"ODDS","marketType":"SET_WINNER","marketTime":"2020-02-02T12:28:00.000Z","suspendTime":"2020-02-02T12:28:00.000Z","bspReconciled":false,"complete":true,"inPlay":true,"crossMatching":true,"runnersVoidable":false,"numberOfActiveRunners":2,"betDelay":3,"status":"SUSPENDED","runners":[{"status":"ACTIVE","sortPriority":1,"id":7414058,"name":"Damir Dzumhur"},{"status":"ACTIVE","sortPriority":2,"id":7287690,"name":"Quentin Halys"}],"regulators":["MR_INT"],"countryCode":"FR","discountAllowed":true,"timezone":"UTC","openDate":"2020-02-02T12:28:00.000Z","version":3148983378,"name":"Set 2 Winner","eventName":"Dzumhur v Halys"}}]}
{"op":"mcm","clk":"1006836065","pt":1580651211815,"mc":[{"id":"1.168224555","tv":0.0}]}
{"op":"mcm","clk":"1006836202","pt":1580651212715,"mc":[{"id":"1.168224555","marketDefinition":{"bspMarket":false,"turnInPlayEnabled":true,"persistenceEnabled":true,"marketBaseRate":5.0,"eventId":"29681742","eventTypeId":"2","numberOfWinners":1,"bettingType":"ODDS","marketType":"SET_WINNER","marketTime":"2020-02-02T12:28:00.000Z","suspendTime":"2020-02-02T12:28:00.000Z","bspReconciled":false,"complete":true,"inPlay":true,"crossMatching":false,"runnersVoidable":false,"numberOfActiveRunners":0,"betDelay":3,"status":"CLOSED","settledTime":"2020-02-02T13:46:49.000Z","runners":[{"status":"WINNER","sortPriority":1,"id":7414058,"name":"Damir Dzumhur"},{"status":"LOSER","sortPriority":2,"id":7287690,"name":"Quentin Halys"}],"regulators":["MR_INT"],"countryCode":"FR","discountAllowed":true,"timezone":"UTC","openDate":"2020-02-02T12:28:00.000Z","version":3148985699,"name":"Set 2 Winner","eventName":"Dzumhur v Halys"}}]}
