{"op":"mcm","clk":"1001179394","pt":1580585281138,"mc":[{"id":"1.168224554","marketDefinition":{"bspMarket":false,"turnInPlayEnabled":true,"persistenceEnabled":true,"marketBaseRate":5.0,"eventId":"29681742","eventTypeId":"2","numberOfWinners":1,"bettingType":"ODDS","marketType":"SET_WINNER","marketTime":"2020-02-02T09:00:00.000Z","suspendTime":"2020-02-02T09:00:00.000Z","bspReconciled":false,"complete":true,"inPlay":false,"crossMatching":false,"runnersVoidable":false,"numberOfActiveRunners":2,"betDelay":0,"status":"OPEN","runners":[{"status":"ACTIVE","sortPriority":1,"id":7414058,"name":"Damir Dzumhur"},{"status":"ACTIVE","sortPriority":2,"id":7287690,"name":"Quentin Halys"}],"regulators":["MR_INT"],"countryCode":"FR","discountAllowed":false,"timezone":"UTC","openDate":"2020-02-02T09:00:00.000Z","version":3147098916,"name":"Set 1 Winner","eventName":"Dzumhur v Halys"},"rc":[{"batb":[[0,1.01,20]],"ltp":0.0,"tv":0.0,"id":7287690},{"batb":[[0,1.01,20]],"ltp":0.0,"tv":0.0,"id":7414058}]}]}
{"op":"mcm","clk":"1001179667","pt":1580585282545,"mc":[{"id":"1.168224554","marketDefinition":{"bspMarket":false,"turnInPlayEnabled":true,"persistenceEnabled":true,"marketBaseRate":5.0,"eventId":"29681742","eventTypeId":"2","numberOfWinners":1,"bettingType":"ODDS","marketType":"SET_WINNER","marketTime":"2020-02-02T09:00:00.000Z","suspendTime":"2020-02-02T09:00:00.000Z","bspReconciled":false,"complete":true,"inPlay":false,"crossMatching":false,"runnersVoidable":false,"numberOfActiveRunners":2,"betDelay":0,"status":"OPEN","runners":[{"status":"ACTIVE","sortPriority":1,"id":7414058,"name":"Damir Dzumhur"},{"status":"ACTIVE","sortPriority":2,"id":7287690,"name":"Quentin Halys"}],"regulators":["MR_INT"],"countryCode":"FR","discountAllowed":false,"timezone":"UTC","openDate":"2020-02-02T09:00:00.000Z","version":3147098916,"name":"Set 1 Winner","eventName":"Dzumhur v Halys"}}]}
{"op":"mcm","clk":"1001179866","pt":1580585283504,"mc":[{"id":"1.168224554","marketDefinition":{"bspMarket":false,"turnInPlayEnabled":true,"persistenceEnabled":true,"marketBaseRate":5.0,"eventId":"29681742","eventTypeId":"2","numberOfWinners":1,"bettingType":"ODDS","marketType":"SET_WINNER","marketTime":"2020-02-02T09:00:00.000Z","suspendTime":"2020-02-02T09:00:00.000Z","bspReconciled":false,"complete":true,"inPlay":false,"crossMatching":false,"runnersVoidable":false,"numberOfActiveRunners":2,"betDelay":0,"status":"OPEN","runners":[{"status":"ACTIVE","sortPriority":1,"id":7414058,"name":"Damir Dzumhur"},{"status":"ACTIVE","sortPriority":2,"id":7287690,"name":"Quentin Halys"}],"regulators":["MR_INT"],"countryCode":"FR","discountAllowed":true,"timezone":"UTC","openDate":"2020-02-02T09:00:00.000Z","version":3147098916,"name":"Set 1 Winner","eventName":"Dzumhur v Halys"}}]}
{"op":"mcm","clk":"1001205068","pt":1580585420100,"mc":[{"id":"1.168224554","rc":[{"batb":[[0,1.01,15]],"ltp":0.0,"tv":0.0,"id":7287690},{"batb":[[0,1.01,15]],"ltp":0.0,"tv":0.0,"id":7414058}]}]}
{"op":"mcm","clk":"1001222203","pt":1580585513427,"mc":[{"id":"1.168224554","marketDefinition":{"bspMarket":false,"turnInPlayEnabled":true,"persistenceEnabled":true,"marketBaseRate":5.0,"eventId":"29681742","eventTypeId":"2","numberOfWinners":1,"bettingType":"ODDS","marketType":"SET_WINNER","marketTime":"2020-02-02T13:30:00.000Z","suspendTime":"2020-02-02T13:30:00.000Z","bspReconciled":false,"complete":true,"inPlay":false,"crossMatching":false,"runnersVoidable":false,"numberOfActiveRunners":2,"betDelay":0,"status":"OPEN","runners":[{"status":"ACTIVE","sortPriority":1,"id":7414058,"name":"Damir Dzumhur"},{"status":"ACTIVE","sortPriority":2,"id":7287690,"name":"Quentin Halys"}],"regulators":["MR_INT"],"countryCode":"FR","discountAllowed":true,"timezone":"UTC","openDate":"2020-02-02T09:00:00.000Z","version":3147124721,"name":"Set 1 Winner","eventName":"Dzumhur v Halys"}}]}
{"op":"mcm","clk":"1001222802","pt":1580585516439,"mc":[{"id":"1.168224554","marketDefinition":{"bspMarket":false,"turnInPlayEnabled":true,"persistenceEnabled":true,"marketBaseRate":5.0,"eventId":"29681742","eventTypeId":"2","numberOfWinners":1,"bettingType":"ODDS","marketType":"SET_WINNER","marketTime":"2020-02-02T13:30:00.000Z","suspendTime":"2020-02-02T13:30:00.000Z","bspReconciled":false,"complete":true,"inPlay":false,"crossMatching":false,"runnersVoidable":false,"numberOfActiveRunners":2,"betDelay":0,"status":"OPEN","runners":[{"status":"ACTIVE","sortPriority":1,"id":7414058,"name":"Damir Dzumhur"},{"status":"ACTIVE","sortPriority":2,"id":7287690,"name":"Quentin Halys"}],"regulators":["MR_INT"],"countryCode":"FR","discountAllowed":true,"timezone":"UTC","openDate":"2020-02-02T13:30:00.000Z","version":3147124721,"name":"Set 1 Winner","eventName":"Dzumhur v Halys"}}]}
{"op":"mcm","clk":"1003032925","pt":1580602189574,"mc":[{"id":"1.168224554","rc":[{"batb":[[0,1.01,15.51]],"ltp":0.0,"tv":0.0,"id":7287690},{"batb":[[0,1.01,15.51]],"ltp":0.0,"tv":0.0,"id":7414058}]}]}
{"op":"mcm","clk":"1003160622","pt":1580603729139,"mc":[{"id":"1.168224554","rc":[{"batb":[[0,1.01,16.01]],"ltp":0.0,"tv":0.0,"id":7287690},{"batb":[[0,1.01,16.01]],"ltp":0.0,"tv":0.0,"id":7414058}]}]}
{"op":"mcm","clk":"1004691847","pt":1580635314870,"mc":[{"id":"1.168224554","marketDefinition":{"bspMarket":false,"turnInPlayEnabled":true,"persistenceEnabled":true,"marketBaseRate":5.0,"eventId":"29681742","eventTypeId":"2","numberOfWinners":1,"bettingType":"ODDS","marketType":"SET_WINNER","marketTime":"2020-02-02T13:19:00.000Z","suspendTime":"2020-02-02T13:19:00.000Z","bspReconciled":false,"complete":true,"inPlay":false,"crossMatching":false,"runnersVoidable":false,"numberOfActiveRunners":2,"betDelay":0,"status":"OPEN","runners":[{"status":"ACTIVE","sortPriority":1,"id":7414058,"name":"Damir Dzumhur"},{"status":"ACTIVE","sortPriority":2,"id":7287690,"name":"Quentin Halys"}],"regulators":["MR_INT"],"countryCode":"FR","discountAllowed":true,"timezone":"UTC","openDate":"2020-02-02T13:30:00.000Z","version":3148342678,"name":"Set 1 Winner","eventName":"Dzumhur v Halys"}}]}
{"op":"mcm","clk":"1004692024","pt":1580635317913,"mc":[{"id":"1.168224554","marketDefinition":{"bspMarket":false,"turnInPlayEnabled":true,"persistenceEnabled":true,"marketBaseRate":5.0,"eventId":"29681742","eventTypeId":"2","numberOfWinners":1,"bettingType":"ODDS","marketType":"SET_WINNER","marketTime":"2020-02-02T13:19:00.000Z","suspendTime":"2020-02-02T13:19:00.000Z","bspReconciled":false,"complete":true,"inPlay":false,"crossMatching":false,"runnersVoidable":false,"numberOfActiveRunners":2,"betDelay":0,"status":"OPEN","runners":[{"status":"ACTIVE","sortPriority":1,"id":7414058,"name":"Damir Dzumhur"},{"status":"ACTIVE","sortPriority":2,"id":7287690,"name":"Quentin Halys"}],"regulators":["MR_INT"],"countryCode":"FR","discountAllowed":true,"timezone":"UTC","openDate":"2020-02-02T13:19:00.000Z","version":3148342678,"name":"Set 1 Winner","eventName":"Dzumhur v Halys"}}]}
{"op":"mcm","clk":"1005237073","pt":1580641614817,"mc":[{"id":"1.168224554","marketDefinition":{"bspMarket":false,"turnInPlayEnabled":true,"persistenceEnabled":true,"marketBaseRate":5.0,"eventId":"29681742","eventTypeId":"2","numberOfWinners":1,"bettingType":"ODDS","marketType":"SET_WINNER","marketTime":"2020-02-02T13:10:00.000Z","suspendTime":"2020-02-02T13:10:00.000Z","bspReconciled":false,"complete":true,"inPlay":false,"crossMatching":false,"runnersVoidable":false,"numberOfActiveRunners":2,"betDelay":0,"status":"OPEN","runners":[{"status":"ACTIVE","sortPriority":1,"id":7414058,"name":"Damir Dzumhur"},{"status":"ACTIVE","sortPriority":2,"id":7287690,"name":"Quentin Halys"}],"regulators":["MR_INT"],"countryCode":"FR","discountAllowed":true,"timezone":"UTC","openDate":"2020-02-02T13:19:00.000Z","version":3148499227,"name":"Set 1 Winner","eventName":"Dzumhur v Halys"}}]}
{"op":"mcm","clk":"1005237509","pt":1580641616832,"mc":[{"id":"1.168224554","marketDefinition":{"bspMarket":false,"turnInPlayEnabled":true,"persistenceEnabled":true,"marketBaseRate":5.0,"eventId":"29681742","eventTypeId":"2","numberOfWinners":1,"bettingType":"ODDS","marketType":"SET_WINNER","marketTime":"2020-02-02T13:10:00.000Z","suspendTime":"2020-02-02T13:10:00.000Z","bspReconciled":false,"complete":true,"inPlay":false,"crossMatching":false,"runnersVoidable":false,"numberOfActiveRunners":2,"betDelay":0,"status":"OPEN","runners":[{"status":"ACTIVE","sortPriority":1,"id":7414058,"name":"Damir Dzumhur"},{"status":"ACTIVE","sortPriority":2,"id":7287690,"name":"Quentin Halys"}],"regulators":["MR_INT"],"countryCode":"FR","discountAllowed":true,"timezone":"UTC","openDate":"2020-02-02T13:10:00.000Z","version":3148499227,"name":"Set 1 Winner","eventName":"Dzumhur v Halys"}}]}
{"op":"mcm","clk":"1005295374","pt":1580641914620,"mc":[{"id":"1.168224554","marketDefinition":{"bspMarket":false,"turnInPlayEnabled":true,"persistenceEnabled":true,"marketBaseRate":5.0,"eventId":"29681742","eventTypeId":"2","numberOfWinners":1,"bettingType":"ODDS","marketType":"SET_WINNER","marketTime":"2020-02-02T13:08:00.000Z","suspendTime":"2020-02-02T13:08:00.000Z","bspReconciled":false,"complete":true,"inPlay":false,"crossMatching":false,"runnersVoidable":false,"numberOfActiveRunners":2,"betDelay":0,"status":"OPEN","runners":[{"status":"ACTIVE","sortPriority":1,"id":7414058,"name":"Damir Dzumhur"},{"status":"ACTIVE","sortPriority":2,"id":7287690,"name":"Quentin Halys"}],"regulators":["MR_INT"],"countryCode":"FR","discountAllowed":true,"timezone":"UTC","openDate":"2020-02-02T13:10:00.000Z","version":3148508352,"name":"Set 1 Winner","eventName":"Dzumhur v Halys"}}]}
{"op":"mcm","clk":"1005295947","pt":1580641917627,"mc":[{"id":"1.168224554","marketDefinition":{"bspMarket":false,"turnInPlayEnabled":true,"persistenceEnabled":true,"marketBaseRate":5.0,"eventId":"29681742","eventTypeId":"2","numberOfWinners":1,"bettingType":"ODDS","marketType":"SET_WINNER","marketTime":"2020-02-02T13:08:00.000Z","suspendTime":"2020-02-02T13:08:00.000Z","bspReconciled":false,"complete":true,"inPlay":false,"crossMatching":false,"runnersVoidable":false,"numberOfActiveRunners":2,"betDelay":0,"status":"OPEN","runners":[{"status":"ACTIVE","sortPriority":1,"id":7414058,"name":"Damir Dzumhur"},{"status":"ACTIVE","sortPriority":2,"id":7287690,"name":"Quentin Halys"}],"regulators":["MR_INT"],"countryCode":"FR","discountAllowed":true,"timezone":"UTC","openDate":"2020-02-02T13:08:00.000Z","version":3148508352,"name":"Set 1 Winner","eventName":"Dzumhur v Halys"}}]}
{"op":"mcm","clk":"1006121905","pt":1580646610461,"mc":[{"id":"1.168224554","rc":[{"batb":[[0,2.36,17.39],[1,1.01,16.01]],"ltp":0.0,"tv":0.0,"id":7287690},{"batb":[[0,1.64,26.99],[1,1.01,16.01]],"ltp":0.0,"tv":0.0,"id":7414058}]}]}
{"op":"mcm","clk":"1006140282","pt":1580646714573,"mc":[{"id":"1.168224554","marketDefinition":{"bspMarket":false,"turnInPlayEnabled":true,"persistenceEnabled":true,"marketBaseRate":5.0,"eventId":"29681742","eventTypeId":"2","numberOfWinners":1,"bettingType":"ODDS","marketType":"SET_WINNER","marketTime":"2020-02-02T12:28:00.000Z","suspendTime":"2020-02-02T12:28:00.000Z","bspReconciled":false,"complete":true,"inPlay":false,"crossMatching":false,"runnersVoidable":false,"numberOfActiveRunners":2,"betDelay":0,"status":"OPEN","runners":[{"status":"ACTIVE","sortPriority":1,"id":7414058,"name":"Damir Dzumhur"},{"status":"ACTIVE","sortPriority":2,"id":7287690,"name":"Quentin Halys"}],"regulators":["MR_INT"],"countryCode":"FR","discountAllowed":true,"timezone":"UTC","openDate":"2020-02-02T13:08:00.000Z","version":3148727321,"name":"Set 1 Winner","eventName":"Dzumhur v Halys"}}]}
{"op":"mcm","clk":"1006141082","pt":1580646718562,"mc":[{"id":"1.168224554","marketDefinition":{"bspMarket":false,"turnInPlayEnabled":true,"persistenceEnabled":true,"marketBaseRate":5.0,"eventId":"29681742","eventTypeId":"2","numberOfWinners":1,"bettingType":"ODDS","marketType":"SET_WINNER","marketTime":"2020-02-02T12:28:00.000Z","suspendTime":"2020-02-02T12:28:00.000Z","bspReconciled":false,"complete":true,"inPlay":false,"crossMatching":false,"runnersVoidable":false,"numberOfActiveRunners":2,"betDelay":0,"status":"OPEN","runners":[{"status":"ACTIVE","sortPriority":1,"id":7414058,"name":"Damir Dzumhur"},{"status":"ACTIVE","sortPriority":2,"id":7287690,"name":"Quentin Halys"}],"regulators":["MR_INT"],"countryCode":"FR","discountAllowed":true,"timezone":"UTC","openDate":"2020-02-02T12:28:00.000Z","version":3148727321,"name":"Set 1 Winner","eventName":"Dzumhur v Halys"}}]}
{"op":"mcm","clk":"1006185677","pt":1580646959872,"mc":[{"id":"1.168224554","rc":[{"batb":[[0,2.36,47.64]],"batl":[[0,2.68,24.37]],"ltp":0.0,"tv":0.0,"id":7287690},{"batb":[[1,1.6,69.74],[2,1.01,16.01]],"batl":[[0,1.74,42.01]],"ltp":0.0,"tv":0.0,"id":7414058}]}]}
{"op":"mcm","clk":"1006188182","pt":1580646973322,"mc":[{"id":"1.168224554","marketDefinition":{"bspMarket":false,"turnInPlayEnabled":true,"persistenceEnabled":true,"marketBaseRate":5.0,"eventId":"29681742","eventTypeId":"2","numberOfWinners":1,"bettingType":"ODDS","marketType":"SET_WINNER","marketTime":"2020-02-02T12:28:00.000Z","suspendTime":"2020-02-02T12:28:00.000Z","bspReconciled":false,"complete":true,"inPlay":false,"crossMatching":true,"runnersVoidable":false,"numberOfActiveRunners":2,"betDelay":0,"status":"OPEN","runners":[{"status":"ACTIVE","sortPriority":1,"id":7414058,"name":"Damir Dzumhur"},{"status":"ACTIVE","sortPriority":2,"id":7287690,"name":"Quentin Halys"}],"regulators":["MR_INT"],"countryCode":"FR","discountAllowed":true,"timezone":"UTC","openDate":"2020-02-02T12:28:00.000Z","version":3148727321,"name":"Set 1 Winner","eventName":"Dzumhur v Halys"},"rc":[{"batl":[[0,2.46,67.66],[1,2.68,24.37]],"ltp":0.0,"tv":0.0,"id":7287690}]}]}
{"op":"mcm","clk":"1006209388","pt":1580647080161,"mc":[{"id":"1.168224554","rc":[{"batb":[[0,2.38,17.15],[1,2.36,30.25],[2,1.01,16.01]],"ltp":0.0,"tv":0.0,"id":7287690}]}]}
{"op":"mcm","clk":"1006218743","pt":1580647127417,"mc":[{"id":"1.168224554","rc":[{"batl":[[0,2.68,24.37],[1,2.68,0]],"ltp":0.0,"tv":0.0,"id":7287690}]}]}
{"op":"mcm","clk":"1006218763","pt":1580647127522,"mc":[{"id":"1.168224554","rc":[{"batl":[[0,2.54,67.66],[1,2.68,24.37]],"ltp":0.0,"tv":0.0,"id":7287690}]}]}
{"op":"mcm","clk":"1006238006","pt":1580647222420,"mc":[{"id":"1.168224554","rc":[{"batb":[[0,2.36,30.25],[1,1.01,16.01],[2,1.01,0]],"ltp":0.0,"tv":0.0,"id":7287690},{"batb":[[0,1.6,69.74],[1,1.01,16.01],[2,1.01,0]],"ltp":0.0,"tv":0.0,"id":7414058}]}]}
{"op":"mcm","clk":"1006238227","pt":1580647223354,"mc":[{"id":"1.168224554","marketDefinition":{"bspMarket":false,"turnInPlayEnabled":true,"persistenceEnabled":true,"marketBaseRate":5.0,"eventId":"29681742","eventTypeId":"2","numberOfWinners":1,"bettingType":"ODDS","marketType":"SET_WINNER","marketTime":"2020-02-02T12:28:00.000Z","suspendTime":"2020-02-02T12:28:00.000Z","bspReconciled":false,"complete":true,"inPlay":true,"crossMatching":true,"runnersVoidable":false,"numberOfActiveRunners":2,"betDelay":3,"status":"OPEN","runners":[{"status":"ACTIVE","sortPriority":1,"id":7414058,"name":"Damir Dzumhur"},{"status":"ACTIVE","sortPriority":2,"id":7287690,"name":"Quentin Halys"}],"regulators":["MR_INT"],"countryCode":"FR","discountAllowed":true,"timezone":"UTC","openDate":"2020-02-02T12:28:00.000Z","version":3148750631,"name":"Set 1 Winner","eventName":"Dzumhur v Halys"},"rc":[{"batb":[[0,1.01,15.51],[1,1.01,0]],"batl":[[1,2.68,0]],"ltp":0.0,"tv":0.0,"id":7287690},{"batb":[[0,1.01,15.51],[1,1.01,0]],"ltp":0.0,"tv":0.0,"id":7414058}]}]}
{"op":"mcm","clk":"1006238854","pt":1580647226334,"mc":[{"id":"1.168224554","rc":[{"batb":[[0,1.01,17.19]],"ltp":0.0,"tv":0.0,"id":7414058}]}]}
{"op":"mcm","clk":"1006238977","pt":1580647226945,"mc":[{"id":"1.168224554","rc":[{"batb":[[0,1.01,15.51]],"ltp":0.0,"tv":0.0,"id":7414058}]}]}
{"op":"mcm","clk":"1006239219","pt":1580647228230,"mc":[{"id":"1.168224554","rc":[{"batb":[[0,1.63,124.41],[1,1.62,127.99],[2,1.01,15.51]],"batl":[[0,1.69,190.28],[1,1.71,211.64]],"ltp":0.0,"tv":0.0,"id":7414058}]}]}
{"op":"mcm","clk":"1006239481","pt":1580647229431,"mc":[{"id":"1.168224554","rc":[{"batb":[[0,1.01,17.19]],"ltp":0.0,"tv":0.0,"id":7287690}]}]}
{"op":"mcm","clk":"1006239610","pt":1580647230022,"mc":[{"id":"1.168224554","rc":[{"batb":[[0,1.01,15.51]],"ltp":0.0,"tv":0.0,"id":7287690},{"batb":[[0,1.65,1.53],[1,1.63,124.41],[2,1.62,127.99]],"ltp":0.0,"tv":0.0,"id":7414058}]}]}
{"op":"mcm","clk":"1006239793","pt":1580647230838,"mc":[{"id":"1.168224554","rc":[{"batb":[[1,1.01,15.51],[2,1.62,0]],"ltp":0.0,"tv":0.0,"id":7414058}]}]}
{"op":"mcm","clk":"1006240224","pt":1580647232915,"mc":[{"id":"1.168224554","rc":[{"batb":[[0,2.38,1.06],[1,1.01,15.51]],"ltp":0.0,"tv":0.0,"id":7287690}]}]}
{"op":"mcm","clk":"1006240435","pt":1580647233944,"mc":[{"id":"1.168224554","rc":[{"batb":[[1,1.53,146.5],[2,1.52,163.19]],"batl":[[0,1.82,139.42],[1,1.84,166.92]],"ltp":0.0,"tv":0.0,"id":7414058}]}]}
{"op":"mcm","clk":"1006241965","pt":1580647241472,"mc":[{"id":"1.168224554","rc":[{"trd":[[2.54,67.66]],"ltp":2.54,"tv":67.66,"id":7287690},{"trd":[[1.64,104.9],[1.65,3.06]],"batb":[[0,1.53,146.5],[1,1.52,163.19],[2,1.01,15.51]],"batl":[[0,1.58,77.05],[1,1.59,135.73]],"ltp":1.64,"tv":107.95,"id":7414058}],"tv":175.62}]}
{"op":"mcm","clk":"1006242151","pt":1580647242255,"mc":[{"id":"1.168224554","rc":[{"batb":[[0,2.7,12.04],[1,2.42,16.13],[2,2.38,1.06]],"ltp":2.54,"tv":67.66,"id":7287690},{"batb":[[2,1.51,36.9]],"ltp":1.64,"tv":107.95,"id":7414058}]}]}
{"op":"mcm","clk":"1006242562","pt":1580647244143,"mc":[{"id":"1.168224554","rc":[{"batl":[[2,1.63,37.86]],"ltp":1.64,"tv":107.95,"id":7414058}]}]}
{"op":"mcm","clk":"1006242761","pt":1580647244950,"mc":[{"id":"1.168224554","rc":[{"batb":[[1,2.62,25.21],[2,2.42,16.13]],"batl":[[0,3,21]],"ltp":2.54,"tv":67.66,"id":7287690},{"batb":[[0,1.53,188.36]],"batl":[[0,1.58,143.07],[2,1.61,42.01]],"ltp":1.64,"tv":107.95,"id":7414058}]}]}
{"op":"mcm","clk":"1006244583","pt":1580647254072,"mc":[{"id":"1.168224554","rc":[{"batb":[[0,2.62,25.21],[1,2.42,16.13],[2,2.38,1.06]],"ltp":2.54,"tv":67.66,"id":7287690},{"batb":[[0,1.49,85.7],[1,1.38,53.27],[2,1.01,15.51]],"batl":[[0,1.61,42.01],[1,1.59,0],[2,1.61,0]],"ltp":1.64,"tv":107.95,"id":7414058}]}]}
{"op":"mcm","clk":"1006244898","pt":1580647255465,"mc":[{"id":"1.168224554","rc":[{"batb":[[0,2.42,16.13],[1,2.38,1.06],[2,1.01,15.51]],"ltp":2.54,"tv":67.66,"id":7287690},{"batb":[[0,1.38,53.27],[1,1.01,15.51],[2,1.01,0]],"ltp":1.64,"tv":107.95,"id":7414058}]}]}
{"op":"mcm","clk":"1006245219","pt":1580647256962,"mc":[{"id":"1.168224554","rc":[{"batb":[[0,1.4,223.56],[1,1.39,239.37],[2,1.38,53.27]],"batl":[[0,1.69,116.3],[1,1.71,211.86]],"ltp":1.64,"tv":107.95,"id":7414058}]}]}
{"op":"mcm","clk":"1006246225","pt":1580647261857,"mc":[{"id":"1.168224554","rc":[{"batb":[[0,1.38,53.27],[1,1.01,15.51],[2,1.38,0]],"ltp":1.64,"tv":107.95,"id":7414058}]}]}
{"op":"mcm","clk":"1006246975","pt":1580647265477,"mc":[{"id":"1.168224554","rc":[{"batb":[[2,2.2,21.09]],"ltp":2.54,"tv":67.66,"id":7287690},{"batb":[[0,1.63,201.9],[1,1.62,128.14],[2,1.61,28.72]],"ltp":1.64,"tv":107.95,"id":7414058}]}]}
{"op":"mcm","clk":"1006247191","pt":1580647266491,"mc":[{"id":"1.168224554","rc":[{"batb":[[0,2.42,45.54]],"batl":[[0,2.76,23.53]],"ltp":2.54,"tv":67.66,"id":7287690},{"batl":[[1,1.7,42.01],[2,1.71,211.86]],"ltp":1.64,"tv":107.95,"id":7414058}]}]}
{"op":"mcm","clk":"1006249257","pt":1580647276463,"mc":[{"id":"1.168224554","rc":[{"batb":[[0,2.42,29.41]],"ltp":2.54,"tv":67.66,"id":7287690},{"batb":[[0,1.57,73.1],[1,1.47,40.76],[2,1.01,15.51]],"batl":[[0,1.7,42.01],[1,1.7,0],[2,1.71,0]],"ltp":1.64,"tv":107.95,"id":7414058}]}]}
{"op":"mcm","clk":"1006249476","pt":1580647277484,"mc":[{"id":"1.168224554","rc":[{"batb":[[0,2.38,1.06],[1,2.2,21.09],[2,1.01,15.51]],"ltp":2.54,"tv":67.66,"id":7287690},{"batb":[[0,1.47,40.76],[1,1.01,15.51],[2,1.01,0]],"ltp":1.64,"tv":107.95,"id":7414058}]}]}
{"op":"mcm","clk":"1006249829","pt":1580647279298,"mc":[{"id":"1.168224554","rc":[{"batb":[[0,1.49,157.15],[1,1.48,181.64],[2,1.47,40.76]],"batl":[[0,1.82,162.34],[1,1.84,166.73]],"ltp":1.64,"tv":107.95,"id":7414058}]}]}
{"op":"mcm","clk":"1006250022","pt":1580647280204,"mc":[{"id":"1.168224554","rc":[{"batb":[[0,1.47,40.76],[1,1.01,15.51],[2,1.47,0]],"ltp":1.64,"tv":107.95,"id":7414058}]}]}
{"op":"mcm","clk":"1006250849","pt":1580647284409,"mc":[{"id":"1.168224554","rc":[{"trd":[[2.38,1.06]],"batb":[[0,2.2,21.09],[1,2.04,26.04]],"ltp":2.38,"tv":68.72,"id":7287690},{"trd":[[1.73,1.46]],"batb":[[0,1.75,116.48],[1,1.73,201.69],[2,1.72,22.66]],"ltp":1.73,"tv":109.41,"id":7414058}],"tv":178.14}]}
{"op":"mcm","clk":"1006251042","pt":1580647285396,"mc":[{"id":"1.168224554","rc":[{"batb":[[0,2.24,33.61],[1,2.2,21.09],[2,2.04,26.04]],"batl":[[0,2.52,26.89]],"ltp":2.38,"tv":68.72,"id":7287690},{"batl":[[0,1.82,204.35]],"ltp":1.73,"tv":109.41,"id":7414058}]}]}
{"op":"mcm","clk":"1006253134","pt":1580647295627,"mc":[{"id":"1.168224554","rc":[{"batb":[[0,2.04,26.04],[1,1.01,15.51],[2,2.04,0]],"ltp":2.38,"tv":68.72,"id":7287690},{"batb":[[0,1.58,30.61],[1,1.01,15.51],[2,1.72,0]],"ltp":1.73,"tv":109.41,"id":7414058}]}]}
{"op":"mcm","clk":"1006254224","pt":1580647301206,"mc":[{"id":"1.168224554","rc":[{"batb":[[0,1.72,125.13],[1,1.7,214.19],[2,1.58,30.61]],"batl":[[0,1.79,185.37],[1,1.81,175.57]],"ltp":1.73,"tv":109.41,"id":7414058}]}]}
{"op":"mcm","clk":"1006254732","pt":1580647304017,"mc":[{"id":"1.168224554","rc":[{"batb":[[0,1.58,30.61],[1,1.01,15.51],[2,1.58,0]],"ltp":1.73,"tv":109.41,"id":7414058}]}]}
{"op":"mcm","clk":"1006255296","pt":1580647306895,"mc":[{"id":"1.168224554","rc":[{"batb":[[0,1.61,155.09],[1,1.6,133.97],[2,1.58,30.61]],"batl":[[0,1.93,125.57],[1,1.95,139.49]],"ltp":1.73,"tv":109.41,"id":7414058}]}]}
{"op":"mcm","clk":"1006256256","pt":1580647311776,"mc":[{"id":"1.168224554","rc":[{"batb":[[0,1.58,30.61],[1,1.01,15.51],[2,1.58,0]],"ltp":1.73,"tv":109.41,"id":7414058}]}]}
{"op":"mcm","clk":"1006256974","pt":1580647315408,"mc":[{"id":"1.168224554","rc":[{"batb":[[1,1.97,29.66],[2,1.01,15.51]],"ltp":2.38,"tv":68.72,"id":7287690},{"batb":[[0,1.85,145.63],[1,1.83,186.02],[2,1.73,22.42]],"ltp":1.73,"tv":109.41,"id":7414058}]}]}
{"op":"mcm","clk":"1006257175","pt":1580647316480,"mc":[{"id":"1.168224554","rc":[{"batb":[[0,2.1,37.81],[1,2.04,26.04],[2,1.97,29.66]],"batl":[[0,2.38,30.25]],"ltp":2.38,"tv":68.72,"id":7287690},{"batb":[[2,1.73,79.56]],"batl":[[0,1.91,42.01],[1,1.93,125.57],[2,1.95,139.49]],"ltp":1.73,"tv":109.41,"id":7414058}]}]}
{"op":"mcm","clk":"1006259182","pt":1580647326924,"mc":[{"id":"1.168224554","rc":[{"batb":[[1,1.97,29.66],[2,1.01,15.51]],"ltp":2.38,"tv":68.72,"id":7287690},{"batb":[[0,1.73,79.56],[1,1.01,15.51],[2,1.73,0]],"batl":[[1,1.93,0],[2,1.95,0]],"ltp":1.73,"tv":109.41,"id":7414058}]}]}
{"op":"mcm","clk":"1006259368","pt":1580647327824,"mc":[{"id":"1.168224554","rc":[{"batb":[[0,1.97,29.66],[1,1.01,15.51],[2,1.01,0]],"ltp":2.38,"tv":68.72,"id":7287690},{"batb":[[0,1.73,22.42]],"ltp":1.73,"tv":109.41,"id":7414058}]}]}
{"op":"mcm","clk":"1006260475","pt":1580647333410,"mc":[{"id":"1.168224554","rc":[{"batb":[[0,1.83,153.99],[1,1.81,173.57],[2,1.73,22.42]],"batl":[[0,1.91,134.29],[1,1.93,143.9]],"ltp":1.73,"tv":109.41,"id":7414058}]}]}
{"op":"mcm","clk":"1006261033","pt":1580647336217,"mc":[{"id":"1.168224554","rc":[{"batb":[[0,1.73,22.42],[1,1.01,15.51],[2,1.73,0]],"ltp":1.73,"tv":109.41,"id":7414058}]}]}
{"op":"mcm","clk":"1006261759","pt":1580647339927,"mc":[{"id":"1.168224554","rc":[{"batb":[[0,1.76,132.65],[1,1.74,197.84],[2,1.73,22.42]],"ltp":1.73,"tv":109.41,"id":7414058}]}]}
{"op":"mcm","clk":"1006262232","pt":1580647342431,"mc":[{"id":"1.168224554","rc":[{"batb":[[0,2.2,21.32],[1,2.02,27.22],[2,1.01,15.51]],"ltp":2.38,"tv":68.72,"id":7287690},{"batl":[[0,1.83,139.01],[1,1.85,163.97]],"ltp":1.73,"tv":109.41,"id":7414058}]}]}
{"op":"mcm","clk":"1006262289","pt":1580647342714,"mc":[{"id":"1.168224554","rc":[{"batb":[[0,2.22,33.61],[1,2.2,21.32],[2,2.02,27.22]],"batl":[[0,2.52,26.89]],"ltp":2.38,"tv":68.72,"id":7287690},{"batl":[[0,1.83,181.02]],"ltp":1.73,"tv":109.41,"id":7414058}]}]}
{"op":"mcm","clk":"1006264929","pt":1580647356143,"mc":[{"id":"1.168224554","rc":[{"batb":[[1,2.02,27.22],[2,1.01,15.51]],"ltp":2.38,"tv":68.72,"id":7287690},{"batb":[[0,1.67,62.17],[1,1.57,31.55],[2,1.01,15.51]],"batl":[[0,1.83,42.01],[1,1.85,0]],"ltp":1.73,"tv":109.41,"id":7414058}]}]}
{"op":"mcm","clk":"1006265210","pt":1580647357578,"mc":[{"id":"1.168224554","rc":[{"batb":[[0,2.02,27.22],[1,1.01,15.51],[2,1.01,0]],"ltp":2.38,"tv":68.72,"id":7287690},{"batb":[[0,1.57,31.55],[1,1.01,15.51],[2,1.01,0]],"ltp":1.73,"tv":109.41,"id":7414058}]}]}
{"op":"mcm","clk":"1006265465","pt":1580647358964,"mc":[{"id":"1.168224554","rc":[{"batb":[[0,1.6,161.99],[1,1.59,137.16],[2,1.57,31.55]],"batl":[[0,1.97,158.99],[1,1.99,131.24]],"ltp":1.73,"tv":109.41,"id":7414058}]}]}
{"op":"mcm","clk":"1006266158","pt":1580647362462,"mc":[{"id":"1.168224554","rc":[{"batb":[[0,1.57,31.55],[1,1.01,15.51],[2,1.57,0]],"ltp":1.73,"tv":109.41,"id":7414058}]}]}
{"op":"mcm","clk":"1006266734","pt":1580647365477,"mc":[{"id":"1.168224554","rc":[{"batb":[[0,1.88,156.24],[1,1.86,158.93],[2,1.57,31.55]],"ltp":1.73,"tv":109.41,"id":7414058}]}]}
{"op":"mcm","clk":"1006266931","pt":1580647366353,"mc":[{"id":"1.168224554","rc":[{"batb":[[1,1.82,18.88],[2,1.01,15.51]],"ltp":2.38,"tv":68.72,"id":7287690},{"batb":[[1,1.86,176.71],[2,1.74,21.79]],"ltp":1.73,"tv":109.41,"id":7414058}]}]}
{"op":"mcm","clk":"1006266950","pt":1580647366493,"mc":[{"id":"1.168224554","rc":[{"batb":[[0,2.06,39.49],[1,2.02,27.22],[2,1.82,18.88]],"batl":[[0,2.32,31.09]],"ltp":2.38,"tv":68.72,"id":7287690},{"batb":[[2,1.76,54.61]],"batl":[[0,1.95,42.01],[1,1.97,158.99],[2,1.99,131.24]],"ltp":1.73,"tv":109.41,"id":7414058}]}]}
{"op":"mcm","clk":"1006272703","pt":1580647395629,"mc":[{"id":"1.168224554","rc":[{"batb":[[0,1.86,17.78],[1,1.76,54.61],[2,1.74,21.79]],"batl":[[1,1.97,0],[2,1.99,0]],"ltp":1.73,"tv":109.41,"id":7414058}]}]}
{"op":"mcm","clk":"1006273264","pt":1580647398505,"mc":[{"id":"1.168224554","rc":[{"batb":[[0,1.87,180.43],[1,1.86,17.78],[2,1.85,161.79]],"batl":[[1,1.96,144.86],[2,1.98,133.29]],"ltp":1.73,"tv":109.41,"id":7414058}]}]}
{"op":"mcm","clk":"1006274128","pt":1580647402745,"mc":[{"id":"1.168224554","rc":[{"batb":[[0,1.86,17.78],[1,1.76,54.61],[2,1.74,21.79]],"batl":[[1,1.96,0],[2,1.98,0]],"ltp":1.73,"tv":109.41,"id":7414058}]}]}
{"op":"mcm","clk":"1006274727","pt":1580647405622,"mc":[{"id":"1.168224554","rc":[{"batb":[[1,1.77,138.2],[2,1.76,54.61]],"batl":[[1,2.2,144.46],[2,2.22,95.89]],"ltp":1.73,"tv":109.41,"id":7414058}]}]}
{"op":"mcm","clk":"1006275128","pt":1580647407624,"mc":[{"id":"1.168224554","rc":[{"batb":[[0,1.82,18.88],[1,1.01,15.51],[2,1.82,0]],"ltp":2.38,"tv":68.72,"id":7287690},{"batb":[[0,1.77,138.2],[1,1.75,194.19],[2,1.74,21.79]],"batl":[[0,2.2,144.46],[1,2.22,95.89],[2,2.22,0]],"ltp":1.73,"tv":109.41,"id":7414058}]}]}
{"op":"mcm","clk":"1006275707","pt":1580647410447,"mc":[{"id":"1.168224554","rc":[{"batb":[[0,1.83,18.65],[1,1.82,18.88],[2,1.01,15.51]],"ltp":2.38,"tv":68.72,"id":7287690},{"batb":[[0,1.74,21.79],[1,1.01,15.51],[2,1.74,0]],"ltp":1.73,"tv":109.41,"id":7414058}]}]}
{"op":"mcm","clk":"1006275739","pt":1580647410663,"mc":[{"id":"1.168224554","rc":[{"batb":[[1,1.01,15.51],[2,1.01,0]],"ltp":2.38,"tv":68.72,"id":7287690}]}]}
{"op":"mcm","clk":"1006277031","pt":1580647417031,"mc":[{"id":"1.168224554","rc":[{"batb":[[0,1.77,138.2],[1,1.75,194.19],[2,1.74,21.79]],"batl":[[0,2.2,144.46],[1,2.22,95.89]],"ltp":1.73,"tv":109.41,"id":7414058}]}]}
{"op":"mcm","clk":"1006278476","pt":1580647424441,"mc":[{"id":"1.168224554","rc":[{"batb":[[0,2.18,21.64],[1,1.98,29.19],[2,1.83,18.65]],"ltp":2.38,"tv":68.72,"id":7287690},{"batl":[[0,1.84,125.08],[1,1.86,161.38]],"ltp":1.73,"tv":109.41,"id":7414058}]}]}
{"op":"mcm","clk":"1006278596","pt":1580647425053,"mc":[{"id":"1.168224554","rc":[{"batb":[[0,2.18,56.93],[2,1.01,15.51]],"batl":[[0,2.46,28.57]],"ltp":2.38,"tv":68.72,"id":7287690},{"batl":[[1,1.86,203.39]],"ltp":1.73,"tv":109.41,"id":7414058}]}]}
{"op":"mcm","clk":"1006280209","pt":1580647433879,"mc":[{"id":"1.168224554","rc":[{"batb":[[0,2.18,35.29]],"ltp":2.38,"tv":68.72,"id":7287690},{"batb":[[0,1.69,60.49],[1,1.66,25.65],[2,1.01,15.51]],"batl":[[0,1.86,42.01],[1,1.86,0]],"ltp":1.73,"tv":109.41,"id":7414058}]}]}
{"op":"mcm","clk":"1006280546","pt":1580647435684,"mc":[{"id":"1.168224554","rc":[{"batb":[[0,1.98,29.19],[1,1.01,15.51],[2,1.01,0]],"ltp":2.38,"tv":68.72,"id":7287690},{"batb":[[0,1.66,25.65],[1,1.01,15.51],[2,1.01,0]],"ltp":1.73,"tv":109.41,"id":7414058}]}]}
{"op":"mcm","clk":"1006281145","pt":1580647438966,"mc":[{"id":"1.168224554","rc":[{"batb":[[0,1.8,116.58],[1,1.78,183.41],[2,1.66,25.65]],"batl":[[0,1.87,120.12],[1,1.89,153.56]],"ltp":1.73,"tv":109.41,"id":7414058}]}]}
{"op":"mcm","clk":"1006281909","pt":1580647443012,"mc":[{"id":"1.168224554","rc":[{"batb":[[0,1.66,25.65],[1,1.01,15.51],[2,1.66,0]],"ltp":1.73,"tv":109.41,"id":7414058}]}]}
{"op":"mcm","clk":"1006282526","pt":1580647445867,"mc":[{"id":"1.168224554","rc":[{"batb":[[0,1.69,198.52],[1,1.67,228.5],[2,1.66,25.65]],"batl":[[0,2,97.68],[1,2.02,125.63]],"ltp":1.73,"tv":109.41,"id":7414058}]}]}
{"op":"mcm","clk":"1006283960","pt":1580647453271,"mc":[{"id":"1.168224554","rc":[{"batb":[[0,2.32,18.41],[1,2.14,22.82],[2,1.98,29.19]],"ltp":2.38,"tv":68.72,"id":7287690},{"batl":[[0,1.76,149.55],[1,1.78,185.57]],"ltp":1.73,"tv":109.41,"id":7414058}]}]}
{"op":"mcm","clk":"1006284186","pt":1580647454486,"mc":[{"id":"1.168224554","rc":[{"batb":[[2,1.01,15.51]],"ltp":2.38,"tv":68.72,"id":7287690}]}]}
{"op":"mcm","clk":"1006284345","pt":1580647455383,"mc":[{"id":"1.168224554","rc":[{"batb":[[1,2.26,32.77],[2,2.14,22.82]],"batl":[[0,2.58,26.05]],"ltp":2.38,"tv":68.72,"id":7287690},{"batl":[[2,1.79,42.01]],"ltp":1.73,"tv":109.41,"id":7414058}]}]}
{"op":"mcm","clk":"1006285576","pt":1580647462114,"mc":[{"id":"1.168224554","rc":[{"batb":[[0,2.26,32.77],[1,2.14,22.82],[2,1.82,401.24]],"ltp":2.38,"tv":68.72,"id":7287690},{"batb":[[0,1.64,65.54],[1,1.61,28.88],[2,1.46,435.7]],"batl":[[0,1.79,42.01],[1,1.78,0],[2,1.79,0]],"ltp":1.73,"tv":109.41,"id":7414058}]}]}
{"op":"mcm","clk":"1006285870","pt":1580647463615,"mc":[{"id":"1.168224554","rc":[{"batb":[[0,2.14,22.82],[1,1.82,401.24],[2,1.01,15.51]],"ltp":2.38,"tv":68.72,"id":7287690},{"batb":[[0,1.61,28.88],[1,1.46,435.7],[2,1.01,15.51]],"ltp":1.73,"tv":109.41,"id":7414058}]}]}
{"op":"mcm","clk":"1006286566","pt":1580647467311,"mc":[{"id":"1.168224554","rc":[{"batb":[[0,1.71,167.24],[1,1.69,218.98],[2,1.61,28.88]],"batl":[[0,1.78,156.64],[1,1.8,178.97]],"ltp":1.73,"tv":109.41,"id":7414058}]}]}
{"op":"mcm","clk":"1006287129","pt":1580647469833,"mc":[{"id":"1.168224554","rc":[{"batb":[[0,1.61,28.88],[1,1.46,435.7],[2,1.01,15.51]],"ltp":1.73,"tv":109.41,"id":7414058}]}]}
{"op":"mcm","clk":"1006287699","pt":1580647472716,"mc":[{"id":"1.168224554","rc":[{"batb":[[0,1.65,132.86],[1,1.64,122.45],[2,1.61,28.88]],"batl":[[0,1.86,157.32],[1,1.88,156.02]],"ltp":1.73,"tv":109.41,"id":7414058}]}]}
{"op":"mcm","clk":"1006288830","pt":1580647478330,"mc":[{"id":"1.168224554","rc":[{"batb":[[1,1.01,15.51],[2,1.01,0]],"ltp":2.38,"tv":68.72,"id":7287690}]}]}
{"op":"mcm","clk":"1006289035","pt":1580647479450,"mc":[{"id":"1.168224554","rc":[{"batb":[[0,2.16,445.78],[1,2.14,22.82],[2,1.01,15.51]],"ltp":2.38,"tv":68.72,"id":7287690},{"batl":[[0,1.71,157.33],[1,1.73,203.74]],"ltp":1.73,"tv":109.41,"id":7414058}]}]}
{"op":"mcm","clk":"1006289225","pt":1580647480321,"mc":[{"id":"1.168224554","rc":[{"batb":[[0,2.44,15.97],[1,2.3,18.65]],"ltp":2.38,"tv":68.72,"id":7287690}]}]}
{"op":"mcm","clk":"1006289436","pt":1580647481434,"mc":[{"id":"1.168224554","rc":[{"batb":[[1,2.34,31.09],[2,2.3,18.65]],"batl":[[0,2.68,24.37]],"ltp":2.38,"tv":68.72,"id":7287690},{"batl":[[2,1.75,42.01]],"ltp":1.73,"tv":109.41,"id":7414058}]}]}
{"op":"mcm","clk":"1006291457","pt":1580647492082,"mc":[{"id":"1.168224554","rc":[{"batb":[[0,2.34,31.09],[1,2.3,18.65],[2,1.92,394.91]],"ltp":2.38,"tv":68.72,"id":7287690},{"batb":[[0,1.6,69.74],[1,1.58,30.84],[2,1.46,435.7]],"batl":[[0,1.75,42.01],[1,1.73,0],[2,1.75,0]],"ltp":1.73,"tv":109.41,"id":7414058}]}]}
{"op":"mcm","clk":"1006291755","pt":1580647493670,"mc":[{"id":"1.168224554","rc":[{"batb":[[0,2.3,18.65],[1,1.92,394.91],[2,1.01,15.51]],"ltp":2.38,"tv":68.72,"id":7287690},{"batb":[[0,1.58,30.84],[1,1.46,435.7],[2,1.01,15.51]],"ltp":1.73,"tv":109.41,"id":7414058}]}]}
{"op":"mcm","clk":"1006292163","pt":1580647495796,"mc":[{"id":"1.168224554","rc":[{"batb":[[0,1.62,215.76],[1,1.61,131.26],[2,1.58,30.84]],"batl":[[0,1.76,152.6],[1,1.78,185.55]],"ltp":1.73,"tv":109.41,"id":7414058}]}]}
{"op":"mcm","clk":"1006293728","pt":1580647503462,"mc":[{"id":"1.168224554","rc":[{"batb":[[0,1.58,30.84],[1,1.46,435.7],[2,1.01,15.51]],"ltp":1.73,"tv":109.41,"id":7414058}]}]}
{"op":"mcm","clk":"1006294335","pt":1580647506382,"mc":[{"id":"1.168224554","rc":[{"batb":[[0,1.69,195.27],[1,1.67,228.47],[2,1.58,30.84]],"ltp":1.73,"tv":109.41,"id":7414058}]}]}
{"op":"mcm","clk":"1006294526","pt":1580647507412,"mc":[{"id":"1.168224554","rc":[{"batb":[[1,2.26,32.77],[2,2.14,23.21]],"batl":[[0,2.58,26.05]],"ltp":2.38,"tv":68.72,"id":7287690},{"batb":[[1,1.67,253.81],[2,1.64,65.54]],"batl":[[2,1.79,42.01]],"ltp":1.73,"tv":109.41,"id":7414058}]}]}
{"op":"mcm","clk":"1006296748","pt":1580647519003,"mc":[{"id":"1.168224554","rc":[{"batb":[[0,2.26,32.77],[1,2.14,23.21],[2,1.92,394.91]],"ltp":2.38,"tv":68.72,"id":7287690},{"batb":[[0,1.64,65.54],[1,1.62,28.33],[2,1.46,435.7]],"batl":[[0,1.79,42.01],[1,1.78,0],[2,1.79,0]],"ltp":1.73,"tv":109.41,"id":7414058}]}]}
{"op":"mcm","clk":"1006296899","pt":1580647519692,"mc":[{"id":"1.168224554","rc":[{"batb":[[0,2.14,23.21],[1,1.92,394.91],[2,1.01,15.51]],"ltp":2.38,"tv":68.72,"id":7287690},{"batb":[[0,1.62,28.33],[1,1.46,435.7],[2,1.01,15.51]],"ltp":1.73,"tv":109.41,"id":7414058}]}]}
{"op":"mcm","clk":"1006297285","pt":1580647521681,"mc":[{"id":"1.168224554","rc":[{"batb":[[0,1.65,153.44],[1,1.64,122.52],[2,1.62,28.33]],"batl":[[0,1.85,127.15],[1,1.87,158.7]],"ltp":1.73,"tv":109.41,"id":7414058}]}]}
{"op":"mcm","clk":"1006298382","pt":1580647527332,"mc":[{"id":"1.168224554","rc":[{"batb":[[0,1.62,28.33],[1,1.46,435.7],[2,1.01,15.51]],"ltp":1.73,"tv":109.41,"id":7414058}]}]}
{"op":"mcm","clk":"1006298580","pt":1580647528317,"mc":[{"id":"1.168224554","rc":[{"batb":[[1,1.01,15.51],[2,1.01,0]],"ltp":2.38,"tv":68.72,"id":7287690},{"batb":[[1,1.01,15.51],[2,1.01,0]],"ltp":1.73,"tv":109.41,"id":7414058}]}]}
{"op":"mcm","clk":"1006298979","pt":1580647530390,"mc":[{"id":"1.168224554","rc":[{"batb":[[0,1.78,126.82],[1,1.76,190.48],[2,1.62,28.33]],"ltp":1.73,"tv":109.41,"id":7414058}]}]}
{"op":"mcm","clk":"1006299094","pt":1580647531136,"mc":[{"id":"1.168224554","rc":[{"batb":[[0,2.14,59.34],[1,1.89,16.76],[2,1.01,15.51]],"batl":[[0,2.42,29.41]],"ltp":2.38,"tv":68.72,"id":7287690},{"batb":[[1,1.77,20.77],[2,1.76,190.48]],"batl":[[1,1.86,42.01],[2,1.87,158.7]],"ltp":1.73,"tv":109.41,"id":7414058}]}]}
{"op":"mcm","clk":"1006299259","pt":1580647532097,"mc":[{"id":"1.168224554","rc":[{"batb":[[2,1.74,404.28]],"ltp":2.38,"tv":68.72,"id":7287690}]}]}
{"op":"mcm","clk":"1006301070","pt":1580647542227,"mc":[{"id":"1.168224554","rc":[{"batb":[[0,2.14,36.13]],"ltp":2.38,"tv":68.72,"id":7287690},{"batb":[[0,1.71,58.81],[1,1.66,25.73],[2,1.52,425.49]],"batl":[[0,1.86,42.01],[1,1.86,0],[2,1.87,0]],"ltp":1.73,"tv":109.41,"id":7414058}]}]}
{"op":"mcm","clk":"1006301350","pt":1580647543724,"mc":[{"id":"1.168224554","rc":[{"batb":[[0,1.89,16.76],[1,1.74,404.28],[2,1.01,15.51]],"ltp":2.38,"tv":68.72,"id":7287690},{"batb":[[0,1.66,25.73],[1,1.52,425.49],[2,1.01,15.51]],"ltp":1.73,"tv":109.41,"id":7414058}]}]}
{"op":"mcm","clk":"1006302217","pt":1580647548254,"mc":[{"id":"1.168224554","rc":[{"batb":[[0,1.82,107.11],[1,1.8,176.75],[2,1.66,25.73]],"batl":[[0,1.89,113.41],[1,1.91,148.67]],"ltp":1.73,"tv":109.41,"id":7414058}]}]}
{"op":"mcm","clk":"1006302937","pt":1580647552151,"mc":[{"id":"1.168224554","rc":[{"batb":[[0,1.66,25.73],[1,1.52,425.49],[2,1.01,15.51]],"ltp":1.73,"tv":109.41,"id":7414058}]}]}
{"op":"mcm","clk":"1006303492","pt":1580647555160,"mc":[{"id":"1.168224554","rc":[{"batb":[[0,1.67,220.47],[1,1.66,143.22],[2,1.52,425.49]],"batl":[[0,2.08,127.92],[1,2.1,112.2]],"ltp":1.73,"tv":109.41,"id":7414058}]}]}
{"op":"mcm","clk":"1006304848","pt":1580647563363,"mc":[{"id":"1.168224554","rc":[{"batb":[[0,1.66,25.73],[1,1.52,425.49],[2,1.01,15.51]],"ltp":1.73,"tv":109.41,"id":7414058}]}]}
{"op":"mcm","clk":"1006305045","pt":1580647564543,"mc":[{"id":"1.168224554","rc":[{"batb":[[1,1.01,15.51],[2,1.01,0]],"ltp":2.38,"tv":68.72,"id":7287690},{"batb":[[1,1.01,15.51],[2,1.01,0]],"ltp":1.73,"tv":109.41,"id":7414058}]}]}
{"op":"mcm","clk":"1006305340","pt":1580647566242,"mc":[{"id":"1.168224554","rc":[{"batb":[[0,1.93,108.66],[1,1.91,146.14],[2,1.89,16.76]],"batl":[[0,2.02,165.12],[1,2.04,122.03]],"ltp":2.38,"tv":68.72,"id":7287690}]}]}
{"op":"mcm","clk":"1006305545","pt":1580647567360,"mc":[{"id":"1.168224554","rc":[{"batb":[[0,1.94,44.53],[1,1.93,108.66],[2,1.91,146.14]],"batl":[[2,2.16,36.13]],"ltp":2.38,"tv":68.72,"id":7287690},{"batb":[[0,1.98,28.95],[1,1.85,48.73],[2,1.79,19.91]],"batl":[[0,2.06,39.49]],"ltp":1.73,"tv":109.41,"id":7414058}]}]}
{"op":"mcm","clk":"1006307508","pt":1580647579461,"mc":[{"id":"1.168224554","rc":[{"batb":[[1,1.89,16.76],[2,1.62,27.85]],"batl":[[0,2.16,36.13],[1,2.04,0],[2,2.16,0]],"ltp":2.38,"tv":68.72,"id":7287690}]}]}
{"op":"mcm","clk":"1006307551","pt":1580647579784,"mc":[{"id":"1.168224554","rc":[{"batb":[[0,1.62,27.85],[1,1.58,416.47],[2,1.01,15.51]],"ltp":2.38,"tv":68.72,"id":7287690},{"batb":[[0,1.79,19.91],[1,1.67,409.76],[2,1.01,15.51]],"ltp":1.73,"tv":109.41,"id":7414058}]}]}
{"op":"mcm","clk":"1006308011","pt":1580647582477,"mc":[{"id":"1.168224554","rc":[{"batb":[[0,1.64,164.78],[1,1.63,125.24],[2,1.62,27.85]],"batl":[[0,2.26,95.04],[1,2.28,89.03]],"ltp":2.38,"tv":68.72,"id":7287690}]}]}
{"op":"mcm","clk":"1006308079","pt":1580647582880,"mc":[{"id":"1.168224554","rc":[{"batb":[[0,1.62,27.85],[1,1.58,416.47],[2,1.01,15.51]],"ltp":2.38,"tv":68.72,"id":7287690}]}]}
{"op":"mcm","clk":"1006308486","pt":1580647585489,"mc":[{"id":"1.168224554","rc":[{"batb":[[0,1.86,150.19],[1,1.84,164.6],[2,1.62,27.85]],"batl":[[0,1.94,113.46],[1,1.96,137.42]],"ltp":2.38,"tv":68.72,"id":7287690}]}]}
{"op":"mcm","clk":"1006308961","pt":1580647588257,"mc":[{"id":"1.168224554","rc":[{"batb":[[0,1.62,27.85],[1,1.58,416.47],[2,1.01,15.51]],"ltp":2.38,"tv":68.72,"id":7287690}]}]}
{"op":"mcm","clk":"1006309433","pt":1580647591191,"mc":[{"id":"1.168224554","rc":[{"batb":[[0,1.64,164.78],[1,1.63,125.24],[2,1.62,27.85]],"batl":[[0,2.26,95.04],[1,2.28,89.03]],"ltp":2.38,"tv":68.72,"id":7287690}]}]}
{"op":"mcm","clk":"1006309588","pt":1580647592157,"mc":[{"id":"1.168224554","rc":[{"batb":[[0,1.62,27.85],[1,1.58,416.47],[2,1.01,15.51]],"ltp":2.38,"tv":68.72,"id":7287690}]}]}
{"op":"mcm","clk":"1006309889","pt":1580647593986,"mc":[{"id":"1.168224554","rc":[{"batb":[[1,1.01,15.51],[2,1.01,0]],"ltp":2.38,"tv":68.72,"id":7287690},{"batb":[[1,1.01,15.51],[2,1.01,0]],"ltp":1.73,"tv":109.41,"id":7414058}]}]}
{"op":"mcm","clk":"1006310059","pt":1580647595089,"mc":[{"id":"1.168224554","rc":[{"batb":[[0,1.79,173.09],[1,1.77,186.98],[2,1.01,15.51]],"batl":[[0,1.87,171.95],[1,1.89,153.46]],"ltp":1.73,"tv":109.41,"id":7414058}]}]}
{"op":"mcm","clk":"1006310253","pt":1580647596215,"mc":[{"id":"1.168224554","rc":[{"batb":[[0,2.1,24.23],[1,1.88,17.07],[2,1.01,15.51]],"ltp":2.38,"tv":68.72,"id":7287690},{"batb":[[2,1.68,24.78]],"ltp":1.73,"tv":109.41,"id":7414058}]}]}
{"op":"mcm","clk":"1006310506","pt":1580647597476,"mc":[{"id":"1.168224554","rc":[{"batb":[[0,2.12,36.97],[1,2.1,24.23],[2,1.88,17.07]],"batl":[[0,2.4,29.41]],"ltp":2.38,"tv":68.72,"id":7287690},{"batb":[[2,1.72,57.97]],"batl":[[1,1.89,195.47]],"ltp":1.73,"tv":109.41,"id":7414058}]}]}
{"op":"mcm","clk":"1006312668","pt":1580647611222,"mc":[{"id":"1.168224554","rc":[{"batb":[[1,1.88,17.07],[2,1.7,409.32]],"ltp":2.38,"tv":68.72,"id":7287690},{"batb":[[0,1.72,57.97],[1,1.68,24.78],[2,1.55,420.5]],"batl":[[0,1.89,42.01],[1,1.89,0]],"ltp":1.73,"tv":109.41,"id":7414058}]}]}
{"op":"mcm","clk":"1006312765","pt":1580647611817,"mc":[{"id":"1.168224554","rc":[{"batb":[[0,1.88,17.07],[1,1.7,409.32],[2,1.01,15.51]],"ltp":2.38,"tv":68.72,"id":7287690},{"batb":[[0,1.68,24.78],[1,1.55,420.5],[2,1.01,15.51]],"ltp":1.73,"tv":109.41,"id":7414058}]}]}
{"op":"mcm","clk":"1006313112","pt":1580647614212,"mc":[{"id":"1.168224554","rc":[{"batb":[[0,1.89,16.84],[1,1.88,17.07],[2,1.7,409.32]],"ltp":2.38,"tv":68.72,"id":7287690},{"batb":[[0,1.68,243.41],[1,1.67,25.02],[2,1.66,233.53]],"batl":[[0,2.1,133],[1,2.12,109.2]],"ltp":1.73,"tv":109.41,"id":7414058}]}]}
{"op":"mcm","clk":"1006313164","pt":1580647614533,"mc":[{"id":"1.168224554","rc":[{"batb":[[1,1.7,409.32],[2,1.01,15.51]],"ltp":2.38,"tv":68.72,"id":7287690},{"batb":[[0,1.68,218.63]],"ltp":1.73,"tv":109.41,"id":7414058}]}]}
{"op":"mcm","clk":"1006314038","pt":1580647619925,"mc":[{"id":"1.168224554","rc":[{"batb":[[1,1.01,15.51],[2,1.01,0]],"ltp":2.38,"tv":68.72,"id":7287690}]}]}
{"op":"mcm","clk":"1006314224","pt":1580647621037,"mc":[{"id":"1.168224554","rc":[{"batl":[[0,1.75,142.41],[1,1.77,189.04]],"ltp":1.73,"tv":109.41,"id":7414058}]}]}
{"op":"mcm","clk":"1006314485","pt":1580647623167,"mc":[{"id":"1.168224554","rc":[{"batb":[[0,2.3,18.88],[1,2.28,32.77],[2,2.12,23.84]],"batl":[[0,2.58,26.05]],"ltp":2.38,"tv":68.72,"id":7287690},{"batl":[[2,1.79,42.01]],"ltp":1.73,"tv":109.41,"id":7414058}]}]}
{"op":"mcm","clk":"1006317516","pt":1580647640348,"mc":[{"id":"1.168224554","rc":[{"batb":[[0,2.28,32.77],[1,2.12,23.84],[2,1.82,401.24]],"ltp":2.38,"tv":68.72,"id":7287690},{"batb":[[0,1.64,65.54],[1,1.53,34.62],[2,1.46,435.7]],"batl":[[0,1.79,42.01],[1,1.77,0],[2,1.79,0]],"ltp":1.73,"tv":109.41,"id":7414058}]}]}
{"op":"mcm","clk":"1006317760","pt":1580647641862,"mc":[{"id":"1.168224554","rc":[{"batb":[[0,2.12,23.84],[1,1.82,401.24],[2,1.01,15.51]],"ltp":2.38,"tv":68.72,"id":7287690},{"batb":[[0,1.53,34.62],[1,1.46,435.7],[2,1.01,15.51]],"ltp":1.73,"tv":109.41,"id":7414058}]}]}
{"op":"mcm","clk":"1006317965","pt":1580647643174,"mc":[{"id":"1.168224554","rc":[{"batb":[[0,1.54,247.96],[1,1.53,194.29],[2,1.46,435.7]],"batl":[[0,1.87,160.06],[1,1.89,153.46]],"ltp":1.73,"tv":109.41,"id":7414058}]}]}
{"op":"mcm","clk":"1006318108","pt":1580647644172,"mc":[{"id":"1.168224554","rc":[{"batb":[[0,1.53,34.62],[1,1.46,435.7],[2,1.01,15.51]],"ltp":1.73,"tv":109.41,"id":7414058}]}]}
{"op":"mcm","clk":"1006318628","pt":1580647647459,"mc":[{"id":"1.168224554","rc":[{"batb":[[0,1.65,220.25],[1,1.64,122.75],[2,1.53,34.62]],"batl":[[0,1.72,179.11],[1,1.74,199.83]],"ltp":1.73,"tv":109.41,"id":7414058}]}]}
{"op":"mcm","clk":"1006318877","pt":1580647648976,"mc":[{"id":"1.168224554","rc":[{"batb":[[0,1.53,34.62],[1,1.46,435.7],[2,1.01,15.51]],"ltp":1.73,"tv":109.41,"id":7414058}]}]}
{"op":"mcm","clk":"1006319363","pt":1580647651970,"mc":[{"id":"1.168224554","rc":[{"batb":[[0,1.54,255.72],[1,1.53,194.31],[2,1.46,435.7]],"batl":[[0,1.87,153.67],[1,1.89,153.46]],"ltp":1.73,"tv":109.41,"id":7414058}]}]}
{"op":"mcm","clk":"1006320155","pt":1580647657146,"mc":[{"id":"1.168224554","rc":[{"batb":[[1,1.01,15.51],[2,1.01,0]],"ltp":2.38,"tv":68.72,"id":7287690},{"batb":[[2,1.01,15.51]],"ltp":1.73,"tv":109.41,"id":7414058}]}]}
{"op":"mcm","clk":"1006320302","pt":1580647658064,"mc":[{"id":"1.168224554","rc":[{"batl":[[0,1.6,198.8],[1,1.61,129.73]],"ltp":1.73,"tv":109.41,"id":7414058}]}]}
{"op":"mcm","clk":"1006320501","pt":1580647659283,"mc":[{"id":"1.168224554","rc":[{"batb":[[0,2.64,12.98],[1,2.58,26.05],[2,2.36,17.62]],"batl":[[0,2.98,21]],"ltp":2.38,"tv":68.72,"id":7287690},{"batb":[[2,1.51,82.34]],"batl":[[2,1.64,42.01]],"ltp":1.73,"tv":109.41,"id":7414058}]}]}
{"op":"mcm","clk":"1006322592","pt":1580647672478,"mc":[{"id":"1.168224554","rc":[{"trd":[[1.54,46.94]],"batb":[[0,1.54,232.25]],"ltp":1.54,"tv":156.36,"id":7414058}],"tv":225.08}]}
{"op":"mcm","clk":"1006323004","pt":1580647675298,"mc":[{"id":"1.168224554","rc":[{"batb":[[0,1.53,34.62],[1,1.51,82.34],[2,1.39,51.62]],"batl":[[0,1.64,42.01],[1,1.61,0],[2,1.64,0]],"ltp":1.54,"tv":156.36,"id":7414058}]}]}
{"op":"mcm","clk":"1006323089","pt":1580647675892,"mc":[{"id":"1.168224554","rc":[{"batb":[[0,2.36,17.62],[1,1.97,394.86],[2,1.01,15.51]],"ltp":2.38,"tv":68.72,"id":7287690},{"batb":[[0,1.39,51.62],[1,1.38,448.45],[2,1.01,15.51]],"ltp":1.54,"tv":156.36,"id":7414058}]}]}
{"op":"mcm","clk":"1006323643","pt":1580647679419,"mc":[{"id":"1.168224554","rc":[{"batb":[[0,1.4,237.15],[1,1.39,291.81],[2,1.38,448.45]],"batl":[[0,1.72,137.76],[1,1.74,200.05]],"ltp":1.54,"tv":156.36,"id":7414058}]}]}
{"op":"mcm","clk":"1006325466","pt":1580647691122,"mc":[{"id":"1.168224554","rc":[{"batb":[[1,1.01,15.51],[2,1.01,0]],"ltp":2.38,"tv":68.72,"id":7287690},{"batb":[[2,1.01,15.51]],"ltp":1.54,"tv":156.36,"id":7414058}]}]}
{"op":"mcm","clk":"1006325655","pt":1580647692444,"mc":[{"id":"1.168224554","rc":[{"batb":[[0,2.46,457.01],[1,2.36,17.62],[2,1.01,15.51]],"ltp":2.38,"tv":68.72,"id":7287690},{"batl":[[0,1.44,175.29],[1,1.45,194.65]],"ltp":1.54,"tv":156.36,"id":7414058}]}]}
{"op":"mcm","clk":"1006325821","pt":1580647693418,"mc":[{"id":"1.168224554","rc":[{"batb":[[0,3.15,19.91],[1,3.1,19.32],[2,2.78,11.17]],"batl":[[0,3.65,15.12]],"ltp":2.38,"tv":68.72,"id":7287690},{"batb":[[2,1.38,110.07]],"ltp":1.54,"tv":156.36,"id":7414058}]}]}
{"op":"mcm","clk":"1006325987","pt":1580647694435,"mc":[{"id":"1.168224554","rc":[{"batl":[[2,1.47,42.01]],"ltp":1.54,"tv":156.36,"id":7414058}]}]}
{"op":"mcm","clk":"1006328058","pt":1580647707847,"mc":[{"id":"1.168224554","rc":[{"batb":[[0,2.78,11.17],[1,2.3,385.09],[2,1.01,15.51]],"ltp":2.38,"tv":68.72,"id":7287690},{"batb":[[0,1.27,80.41],[1,1.25,505.09],[2,1.01,15.51]],"ltp":1.54,"tv":156.36,"id":7414058}]}]}
{"op":"mcm","clk":"1006328610","pt":1580647711434,"mc":[{"id":"1.168224554","rc":[{"batb":[[0,1.28,308.74],[1,1.27,463.78],[2,1.25,505.09]],"batl":[[0,1.55,226.59],[1,1.56,145.54]],"ltp":1.54,"tv":156.36,"id":7414058}]}]}
{"op":"mcm","clk":"1006328941","pt":1580647713739,"mc":[{"id":"1.168224554","rc":[{"batb":[[0,1.27,80.41],[1,1.25,505.09],[2,1.01,15.51]],"ltp":1.54,"tv":156.36,"id":7414058}]}]}
{"op":"mcm","clk":"1006329352","pt":1580647716381,"mc":[{"id":"1.168224554","rc":[{"batb":[[1,1.01,15.51],[2,1.01,0]],"ltp":2.38,"tv":68.72,"id":7287690},{"batb":[[1,1.01,15.51],[2,1.01,0]],"ltp":1.54,"tv":156.36,"id":7414058}]}]}
{"op":"mcm","clk":"1006329507","pt":1580647717473,"mc":[{"id":"1.168224554","rc":[{"batb":[[1,2.76,23.53],[2,2.42,16.37]],"batl":[[0,3.15,19.32]],"ltp":2.38,"tv":68.72,"id":7287690},{"batb":[[0,1.5,152.89],[1,1.49,177.04],[2,1.48,39.26]],"batl":[[0,1.55,226.59],[1,1.56,145.54],[2,1.57,42.01]],"ltp":1.54,"tv":156.36,"id":7414058}]}]}
{"op":"mcm","clk":"1006332201","pt":1580647735467,"mc":[{"id":"1.168224554","rc":[{"batb":[[0,2.76,23.53],[1,2.42,16.37],[2,2.04,394.09]],"ltp":2.38,"tv":68.72,"id":7287690},{"batb":[[0,1.46,90.74],[1,1.34,465.43],[2,1.33,64.6]],"batl":[[0,1.57,42.01],[1,1.56,0],[2,1.57,0]],"ltp":1.54,"tv":156.36,"id":7414058}]}]}
{"op":"mcm","clk":"1006332252","pt":1580647735885,"mc":[{"id":"1.168224554","rc":[{"batb":[[0,2.42,16.37],[1,2.04,394.09],[2,1.01,15.51]],"ltp":2.38,"tv":68.72,"id":7287690},{"batb":[[0,1.34,465.43],[1,1.33,64.6],[2,1.01,15.51]],"ltp":1.54,"tv":156.36,"id":7414058}]}]}
{"op":"mcm","clk":"1006332624","pt":1580647738407,"mc":[{"id":"1.168224554","rc":[{"batb":[[1,1.33,454.03],[2,1.32,311.6]],"batl":[[0,1.7,220.02],[1,1.72,207.49]],"ltp":1.54,"tv":156.36,"id":7414058}]}]}
{"op":"mcm","clk":"1006332718","pt":1580647738995,"mc":[{"id":"1.168224554","rc":[{"batb":[[1,1.33,64.6],[2,1.01,15.51]],"ltp":1.54,"tv":156.36,"id":7414058}]}]}
{"op":"mcm","clk":"1006333218","pt":1580647742591,"mc":[{"id":"1.168224554","rc":[{"batb":[[0,1.46,239.15],[1,1.45,199.06],[2,1.34,465.43]],"batl":[[0,1.51,221.74],[1,1.52,160.7]],"ltp":1.54,"tv":156.36,"id":7414058}]}]}
{"op":"mcm","clk":"1006333468","pt":1580647744179,"mc":[{"id":"1.168224554","rc":[{"batb":[[0,1.34,465.43],[1,1.33,64.6],[2,1.01,15.51]],"ltp":1.54,"tv":156.36,"id":7414058}]}]}
{"op":"mcm","clk":"1006333944","pt":1580647747197,"mc":[{"id":"1.168224554","rc":[{"batb":[[1,1.33,454.03],[2,1.32,311.6]],"batl":[[0,1.7,220.02],[1,1.72,207.49]],"ltp":1.54,"tv":156.36,"id":7414058}]}]}
{"op":"mcm","clk":"1006338001","pt":1580647773653,"mc":[{"id":"1.168224554","rc":[{"batb":[[1,1.33,64.6],[2,1.01,15.51]],"ltp":1.54,"tv":156.36,"id":7414058}]}]}
{"op":"mcm","clk":"1006338256","pt":1580647775427,"mc":[{"id":"1.168224554","rc":[{"batb":[[1,1.01,15.51],[2,1.01,0]],"ltp":2.38,"tv":68.72,"id":7287690},{"batb":[[0,1.33,64.6],[1,1.01,15.51],[2,1.01,0]],"ltp":1.54,"tv":156.36,"id":7414058}]}]}
{"op":"mcm","clk":"1006338561","pt":1580647777440,"mc":[{"id":"1.168224554","rc":[{"batb":[[0,2.42,45.77],[1,2.12,23.84],[2,1.01,15.51]],"ltp":2.38,"tv":68.72,"id":7287690},{"batb":[[0,1.63,206.35],[1,1.62,156.73],[2,1.42,46.97]],"batl":[[0,1.7,262.03]],"ltp":1.54,"tv":156.36,"id":7414058}]}]}
{"op":"mcm","clk":"1006338723","pt":1580647778479,"mc":[{"id":"1.168224554","rc":[{"batl":[[0,2.76,23.53]],"ltp":2.38,"tv":68.72,"id":7287690},{"batb":[[2,1.57,73.1]],"ltp":1.54,"tv":156.36,"id":7414058}]}]}
{"op":"mcm","clk":"1006338833","pt":1580647779133,"mc":[{"id":"1.168224554","rc":[{"batb":[[2,1.86,398.62]],"ltp":2.38,"tv":68.72,"id":7287690}]}]}
{"op":"mcm","clk":"1006339007","pt":1580647780154,"mc":[{"id":"1.168224554","rc":[{"batl":[[0,1.7,42.01],[1,1.72,0]],"ltp":1.54,"tv":156.36,"id":7414058}]}]}
{"op":"mcm","clk":"1006339494","pt":1580647783162,"mc":[{"id":"1.168224554","rc":[{"batl":[[0,1.69,116.02],[1,1.7,42.01],[2,1.71,212.19]],"ltp":1.54,"tv":156.36,"id":7414058}]}]}
{"op":"mcm","clk":"1006340195","pt":1580647787713,"mc":[{"id":"1.168224554","rc":[{"batb":[[0,1.63,184.04]],"ltp":1.54,"tv":156.36,"id":7414058}]}]}
{"op":"mcm","clk":"1006341568","pt":1580647796410,"mc":[{"id":"1.168224554","rc":[{"batb":[[0,2.42,29.41]],"ltp":2.38,"tv":68.72,"id":7287690},{"batb":[[0,1.57,73.1],[1,1.44,436.18],[2,1.42,46.97]],"batl":[[0,1.7,42.01],[1,1.7,0],[2,1.71,0]],"ltp":1.54,"tv":156.36,"id":7414058}]}]}
{"op":"mcm","clk":"1006341862","pt":1580647798292,"mc":[{"id":"1.168224554","rc":[{"batb":[[0,2.12,23.84],[1,1.86,398.62],[2,1.01,15.51]],"ltp":2.38,"tv":68.72,"id":7287690},{"batb":[[0,1.44,436.18],[1,1.42,46.97],[2,1.01,15.51]],"ltp":1.54,"tv":156.36,"id":7414058}]}]}
{"op":"mcm","clk":"1006342031","pt":1580647799414,"mc":[{"id":"1.168224554","rc":[{"batb":[[1,1.43,220.8],[2,1.42,265.05]],"batl":[[0,1.88,166.53],[1,1.9,151.05]],"ltp":1.54,"tv":156.36,"id":7414058}]}]}
{"op":"mcm","clk":"1006342425","pt":1580647801583,"mc":[{"id":"1.168224554","rc":[{"batl":[[0,1.63,2.65],[1,1.88,166.53],[2,1.9,151.05]],"ltp":1.54,"tv":156.36,"id":7414058}]}]}
{"op":"mcm","clk":"1006342845","pt":1580647803953,"mc":[{"id":"1.168224554","rc":[{"batl":[[0,1.88,166.53],[1,1.9,151.05],[2,1.9,0]],"ltp":1.54,"tv":156.36,"id":7414058}]}]}
{"op":"mcm","clk":"1006343120","pt":1580647805812,"mc":[{"id":"1.168224554","rc":[{"batb":[[1,1.42,46.97],[2,1.01,15.51]],"ltp":1.54,"tv":156.36,"id":7414058}]}]}
{"op":"mcm","clk":"1006343263","pt":1580647806658,"mc":[{"id":"1.168224554","rc":[{"batb":[[1,1.01,15.51],[2,1.01,0]],"ltp":2.38,"tv":68.72,"id":7287690},{"batb":[[0,1.42,46.97],[1,1.01,15.51],[2,1.01,0]],"ltp":1.54,"tv":156.36,"id":7414058}]}]}
{"op":"mcm","clk":"1006343720","pt":1580647809461,"mc":[{"id":"1.168224554","rc":[{"batb":[[0,2.14,36.13],[1,2.12,23.84],[2,1.94,15.42]],"batl":[[0,2.42,29.41]],"ltp":2.38,"tv":68.72,"id":7287690},{"batb":[[0,1.8,149.05],[1,1.78,203.76],[2,1.7,59.65]],"batl":[[0,1.88,208.54]],"ltp":1.54,"tv":156.36,"id":7414058}]}]}
{"op":"mcm","clk":"1006344667","pt":1580647815380,"mc":[{"id":"1.168224554","rc":[{"trd":[[1.8,5.3]],"batb":[[0,1.8,146.4]],"ltp":1.8,"tv":161.66,"id":7414058}],"tv":230.38}]}
{"op":"mcm","clk":"1006346246","pt":1580647825182,"mc":[{"id":"1.168224554","rc":[{"batb":[[1,1.94,15.42],[2,1.7,409.32]],"ltp":2.38,"tv":68.72,"id":7287690},{"batb":[[0,1.7,59.65],[1,1.61,28.64],[2,1.55,420.5]],"batl":[[0,1.88,42.01],[1,1.9,0]],"ltp":1.8,"tv":161.66,"id":7414058}]}]}
{"op":"mcm","clk":"1006346345","pt":1580647825933,"mc":[{"id":"1.168224554","rc":[{"batb":[[0,1.94,15.42],[1,1.7,409.32],[2,1.01,15.51]],"ltp":2.38,"tv":68.72,"id":7287690},{"batb":[[0,1.61,28.64],[1,1.55,420.5],[2,1.01,15.51]],"ltp":1.8,"tv":161.66,"id":7414058}]}]}
{"op":"mcm","clk":"1006346663","pt":1580647828113,"mc":[{"id":"1.168224554","rc":[{"batb":[[0,1.62,208.36],[1,1.61,159.98],[2,1.55,420.5]],"batl":[[0,2.04,186.08],[1,2.06,118.68]],"ltp":1.8,"tv":161.66,"id":7414058}]}]}
{"op":"mcm","clk":"1006348381","pt":1580647840222,"mc":[{"id":"1.168224554","rc":[{"batb":[[1,1.01,15.51],[2,1.01,0]],"ltp":2.38,"tv":68.72,"id":7287690},{"batb":[[2,1.01,15.51]],"ltp":1.8,"tv":161.66,"id":7414058}]}]}
{"op":"mcm","clk":"1006348658","pt":1580647842410,"mc":[{"id":"1.168224554","rc":[{"batl":[[0,1.68,123.92],[1,1.7,216.46]],"ltp":1.8,"tv":161.66,"id":7414058}]}]}
{"op":"mcm","clk":"1006348773","pt":1580647843307,"mc":[{"id":"1.168224554","rc":[{"batb":[[0,2.42,45.62],[1,2.12,23.29],[2,1.01,15.51]],"batl":[[0,2.76,23.53]],"ltp":2.38,"tv":68.72,"id":7287690},{"batb":[[2,1.57,73.1]],"batl":[[2,1.71,42.01]],"ltp":1.8,"tv":161.66,"id":7414058}]}]}
{"op":"mcm","clk":"1006348834","pt":1580647843732,"mc":[{"id":"1.168224554","rc":[{"batb":[[2,1.86,398.62]],"ltp":2.38,"tv":68.72,"id":7287690}]}]}
{"op":"mcm","clk":"1006350705","pt":1580647856449,"mc":[{"id":"1.168224554","rc":[{"batb":[[0,2.42,29.41]],"ltp":2.38,"tv":68.72,"id":7287690},{"batb":[[1,1.61,131.34]],"ltp":1.8,"tv":161.66,"id":7414058}]}]}
{"op":"mcm","clk":"1006350751","pt":1580647856755,"mc":[{"id":"1.168224554","rc":[{"batb":[[0,1.57,73.1],[1,1.44,436.18],[2,1.42,47.84]],"batl":[[0,1.71,42.01],[1,1.7,0],[2,1.71,0]],"ltp":1.8,"tv":161.66,"id":7414058}]}]}
{"op":"mcm","clk":"1006350936","pt":1580647857942,"mc":[{"id":"1.168224554","rc":[{"batb":[[0,2.12,23.29],[1,1.86,398.62],[2,1.01,15.51]],"ltp":2.38,"tv":68.72,"id":7287690},{"batb":[[0,1.44,436.18],[1,1.42,47.84],[2,1.01,15.51]],"ltp":1.8,"tv":161.66,"id":7414058}]}]}
{"op":"mcm","clk":"1006351160","pt":1580647859562,"mc":[{"id":"1.168224554","rc":[{"batb":[[1,1.42,366.35],[2,1.41,225.92]],"batl":[[0,1.87,170.23],[1,1.89,153.5]],"ltp":1.8,"tv":161.66,"id":7414058}]}]}
{"op":"mcm","clk":"1006351406","pt":1580647861239,"mc":[{"id":"1.168224554","rc":[{"batb":[[1,1.42,47.84],[2,1.01,15.51]],"ltp":1.8,"tv":161.66,"id":7414058}]}]}
{"op":"mcm","clk":"1006351878","pt":1580647864263,"mc":[{"id":"1.168224554","rc":[{"batb":[[0,1.58,160.79],[1,1.57,144.15],[2,1.44,436.18]],"batl":[[0,1.64,223.94],[1,1.65,118.92]],"ltp":1.8,"tv":161.66,"id":7414058}]}]}
{"op":"mcm","clk":"1006352286","pt":1580647866934,"mc":[{"id":"1.168224554","rc":[{"batb":[[0,1.44,436.18],[1,1.42,47.84],[2,1.01,15.51]],"ltp":1.8,"tv":161.66,"id":7414058}]}]}
{"op":"mcm","clk":"1006352806","pt":1580647869986,"mc":[{"id":"1.168224554","rc":[{"batb":[[1,1.42,366.35],[2,1.41,225.92]],"batl":[[0,1.87,170.23],[1,1.89,153.5]],"ltp":1.8,"tv":161.66,"id":7414058}]}]}
{"op":"mcm","clk":"1006353118","pt":1580647871982,"mc":[{"id":"1.168224554","rc":[{"batb":[[1,1.01,15.51],[2,1.01,0]],"ltp":2.38,"tv":68.72,"id":7287690},{"batb":[[0,1.42,366.35],[1,1.41,225.92],[2,1.01,15.51]],"ltp":1.8,"tv":161.66,"id":7414058}]}]}
{"op":"mcm","clk":"1006353516","pt":1580647874482,"mc":[{"id":"1.168224554","rc":[{"batb":[[0,3.05,22.03],[1,2.46,15.66],[2,1.01,15.51]],"ltp":2.38,"tv":68.72,"id":7287690},{"batb":[[2,1.22,102.68]],"batl":[[0,1.47,240.72],[1,1.48,178.52]],"ltp":1.8,"tv":161.66,"id":7414058}]}]}
{"op":"mcm","clk":"1006353617","pt":1580647875171,"mc":[{"id":"1.168224554","rc":[{"batl":[[0,3.55,15.96]],"ltp":2.38,"tv":68.72,"id":7287690}]}]}
{"op":"mcm","clk":"1006353784","pt":1580647876090,"mc":[{"id":"1.168224554","rc":[{"batb":[[2,2.22,384.52]],"ltp":2.38,"tv":68.72,"id":7287690},{"batb":[[2,1.39,107.54]],"ltp":1.8,"tv":161.66,"id":7414058}]}]}
{"op":"mcm","clk":"1006355512","pt":1580647887907,"mc":[{"id":"1.168224554","rc":[{"batb":[[0,2.46,15.66],[1,2.22,384.52],[2,1.01,15.51]],"ltp":2.38,"tv":68.72,"id":7287690},{"batb":[[0,1.28,485.89],[1,1.22,102.68],[2,1.01,15.51]],"ltp":1.8,"tv":161.66,"id":7414058}]}]}
{"op":"mcm","clk":"1006356035","pt":1580647891470,"mc":[{"id":"1.168224554","rc":[{"batl":[[0,1.67,115.64],[1,1.69,220.91]],"ltp":1.8,"tv":161.66,"id":7414058}]}]}
{"op":"mcm","clk":"1006356275","pt":1580647893163,"mc":[{"id":"1.168224554","rc":[{"batb":[[1,1.01,15.51],[2,1.01,0]],"ltp":2.38,"tv":68.72,"id":7287690},{"batb":[[0,1.22,102.68],[1,1.01,15.51],[2,1.01,0]],"ltp":1.8,"tv":161.66,"id":7414058}]}]}
{"op":"mcm","clk":"1006356620","pt":1580647895458,"mc":[{"id":"1.168224554","rc":[{"batb":[[0,2.46,44.22],[1,2.14,22.82],[2,1.01,15.51]],"batl":[[0,2.8,22.69]],"ltp":2.38,"tv":68.72,"id":7287690},{"batb":[[0,1.61,230.94],[1,1.6,163.93],[2,1.41,49.02]],"ltp":1.8,"tv":161.66,"id":7414058}]}]}
{"op":"mcm","clk":"1006356862","pt":1580647897296,"mc":[{"id":"1.168224554","rc":[{"batb":[[2,1.92,394.91]],"ltp":2.38,"tv":68.72,"id":7287690},{"batb":[[2,1.56,74.78]],"batl":[[1,1.69,262.92]],"ltp":1.8,"tv":161.66,"id":7414058}]}]}
{"op":"mcm","clk":"1006358540","pt":1580647909963,"mc":[{"id":"1.168224554","rc":[{"batb":[[0,2.14,22.82],[1,1.92,394.91],[2,1.01,15.51]],"ltp":2.38,"tv":68.72,"id":7287690},{"batb":[[0,1.41,49.02],[1,1.4,451],[2,1.01,15.51]],"ltp":1.8,"tv":161.66,"id":7414058}]}]}
{"op":"mcm","clk":"1006359558","pt":1580647916441,"mc":[{"id":"1.168224554","rc":[{"batb":[[0,1.57,195.48],[1,1.56,147.87],[2,1.41,49.02]],"batl":[[0,1.63,206.44],[1,1.64,121.55]],"ltp":1.8,"tv":161.66,"id":7414058}]}]}
{"op":"mcm","clk":"1006359935","pt":1580647919369,"mc":[{"id":"1.168224554","rc":[{"batb":[[0,1.41,49.02],[1,1.4,451],[2,1.01,15.51]],"ltp":1.8,"tv":161.66,"id":7414058}]}]}
{"op":"mcm","clk":"1006360319","pt":1580647922382,"mc":[{"id":"1.168224554","rc":[{"batb":[[0,1.42,195.93],[1,1.41,273.77],[2,1.4,451]],"batl":[[0,1.86,175.32],[1,1.88,156.02]],"ltp":1.8,"tv":161.66,"id":7414058}]}]}
{"op":"mcm","clk":"1006360526","pt":1580647923917,"mc":[{"id":"1.168224554","rc":[{"batl":[[0,1.61,25.97],[1,1.86,175.32],[2,1.88,156.02]],"ltp":1.8,"tv":161.66,"id":7414058}]}]}
{"op":"mcm","clk":"1006361062","pt":1580647927977,"mc":[{"id":"1.168224554","rc":[{"batb":[[0,1.41,49.02],[1,1.4,451],[2,1.01,15.51]],"batl":[[1,1.86,0],[2,1.88,0]],"ltp":1.8,"tv":161.66,"id":7414058}]}]}
{"op":"mcm","clk":"1006361232","pt":1580647929406,"mc":[{"id":"1.168224554","rc":[{"batb":[[1,1.01,15.51],[2,1.01,0]],"ltp":2.38,"tv":68.72,"id":7287690},{"batb":[[1,1.01,15.51],[2,1.01,0]],"ltp":1.8,"tv":161.66,"id":7414058}]}]}
{"op":"mcm","clk":"1006361463","pt":1580647931092,"mc":[{"id":"1.168224554","rc":[{"batl":[[0,3.6,15.96]],"ltp":2.38,"tv":68.72,"id":7287690},{"batb":[[0,1.42,195.93],[1,1.41,273.77],[2,1.39,107.54]],"batl":[[0,1.46,171.17],[1,1.47,184.06],[2,1.61,25.97]],"ltp":1.8,"tv":161.66,"id":7414058}]}]}
{"op":"mcm","clk":"1006361560","pt":1580647931882,"mc":[{"id":"1.168224554","rc":[{"batb":[[0,3.1,21.32],[1,3.05,20.16],[2,2.48,15.34]],"ltp":2.38,"tv":68.72,"id":7287690},{"batl":[[2,1.49,42.01]],"ltp":1.8,"tv":161.66,"id":7414058}]}]}
{"op":"mcm","clk":"1006363560","pt":1580647947438,"mc":[{"id":"1.168224554","rc":[{"batb":[[0,3.05,20.16],[1,2.48,15.34],[2,2.22,384.52]],"ltp":2.38,"tv":68.72,"id":7287690},{"batb":[[0,1.39,107.54],[1,1.28,485.89],[2,1.22,104.73]],"batl":[[0,1.49,42.01],[1,1.61,25.97],[2,1.49,0]],"ltp":1.8,"tv":161.66,"id":7414058}]}]}
{"op":"mcm","clk":"1006363675","pt":1580647948108,"mc":[{"id":"1.168224554","rc":[{"batb":[[0,2.48,15.34],[1,2.22,384.52],[2,1.01,15.51]],"ltp":2.38,"tv":68.72,"id":7287690},{"batb":[[0,1.28,485.89],[1,1.22,104.73],[2,1.01,15.51]],"batl":[[0,1.61,25.97],[1,1.61,0]],"ltp":1.8,"tv":161.66,"id":7414058}]}]}
{"op":"mcm","clk":"1006363976","pt":1580647950357,"mc":[{"id":"1.168224554","rc":[{"batb":[[0,2.5,15.03],[1,2.48,15.34],[2,2.22,384.52]],"ltp":2.38,"tv":68.72,"id":7287690},{"batb":[[2,1.21,727]],"batl":[[1,1.67,216.55],[2,1.69,220.31]],"ltp":1.8,"tv":161.66,"id":7414058}]}]}
{"op":"mcm","clk":"1006364128","pt":1580647951342,"mc":[{"id":"1.168224554","rc":[{"batb":[[1,2.22,384.52],[2,1.01,15.51]],"ltp":2.38,"tv":68.72,"id":7287690},{"batb":[[1,1.21,106.3],[2,1.01,15.51]],"batl":[[1,1.67,0],[2,1.69,0]],"ltp":1.8,"tv":161.66,"id":7414058}]}]}
{"op":"mcm","clk":"1006364523","pt":1580647954212,"mc":[{"id":"1.168224554","rc":[{"batb":[[0,1.37,309.46],[1,1.36,267.37],[2,1.28,485.89]],"batl":[[0,1.41,183.02],[1,1.42,212.86],[2,1.61,25.97]],"ltp":1.8,"tv":161.66,"id":7414058}]}]}
{"op":"mcm","clk":"1006364805","pt":1580647956455,"mc":[{"id":"1.168224554","rc":[{"batb":[[0,1.28,485.89],[1,1.21,106.3],[2,1.01,15.51]],"batl":[[0,1.61,25.97],[1,1.42,0],[2,1.61,0]],"ltp":1.8,"tv":161.66,"id":7414058}]}]}
{"op":"mcm","clk":"1006365181","pt":1580647959430,"mc":[{"id":"1.168224554","rc":[{"batb":[[1,1.21,727],[2,1.2,442.22]],"batl":[[1,1.67,216.55],[2,1.69,220.31]],"ltp":1.8,"tv":161.66,"id":7414058}]}]}
{"op":"mcm","clk":"1006365706","pt":1580647963374,"mc":[{"id":"1.168224554","rc":[{"batl":[[1,1.67,0],[2,1.69,0]],"ltp":1.8,"tv":161.66,"id":7414058}]}]}
{"op":"mcm","clk":"1006366077","pt":1580647966240,"mc":[{"id":"1.168224554","rc":[{"batb":[[1,1.01,15.51],[2,1.01,0]],"ltp":2.38,"tv":68.72,"id":7287690},{"batb":[[0,1.21,727],[1,1.2,442.22],[2,1.01,15.51]],"batl":[[0,1.24,276.66],[1,1.25,402.13],[2,1.61,25.97]],"ltp":1.8,"tv":161.66,"id":7414058}]}]}
{"op":"mcm","clk":"1006366216","pt":1580647967247,"mc":[{"id":"1.168224554","rc":[{"batb":[[0,4.8,14.63],[1,3.85,24.71],[2,1.01,15.51]],"ltp":2.38,"tv":68.72,"id":7287690},{"batb":[[2,1.17,304.95]],"ltp":1.8,"tv":161.66,"id":7414058}]}]}
{"op":"mcm","clk":"1006366488","pt":1580647969363,"mc":[{"id":"1.168224554","rc":[{"batb":[[0,5.5,9.24],[1,4.8,14.63],[2,3.85,24.71]],"batl":[[0,6.8,6.72]],"ltp":2.38,"tv":68.72,"id":7287690},{"batl":[[0,1.22,42.01],[1,1.24,276.66],[2,1.25,402.13]],"ltp":1.8,"tv":161.66,"id":7414058}]}]}
{"op":"mcm","clk":"1006366801","pt":1580647971856,"mc":[{"id":"1.168224554","rc":[{"batb":[[1,4.8,14.4],[2,3.85,24.39]],"ltp":2.38,"tv":68.72,"id":7287690}]}]}
{"op":"mcm","clk":"1006368278","pt":1580647982950,"mc":[{"id":"1.168224554","rc":[{"batb":[[1,4.9,14.08],[2,3.9,23.92]],"ltp":2.38,"tv":68.72,"id":7287690}]}]}
{"op":"mcm","clk":"1006373525","pt":1580648018307,"mc":[{"id":"1.168224554","rc":[{"batb":[[0,1.21,672.79]],"ltp":1.8,"tv":161.66,"id":7414058}]}]}
{"op":"mcm","clk":"1006373984","pt":1580648021205,"mc":[{"id":"1.168224554","rc":[{"batb":[[1,1.2,498.87]],"batl":[[1,1.24,329.44]],"ltp":1.8,"tv":161.66,"id":7414058}]}]}
{"op":"mcm","clk":"1006375678","pt":1580648032470,"mc":[{"id":"1.168224554","rc":[{"batb":[[0,1.21,643.56]],"ltp":1.8,"tv":161.66,"id":7414058}]}]}
{"op":"mcm","clk":"1006376097","pt":1580648035257,"mc":[{"id":"1.168224554","rc":[{"batb":[[1,1.2,528.34]],"batl":[[1,1.24,357.95]],"ltp":1.8,"tv":161.66,"id":7414058}]}]}
{"op":"mcm","clk":"1006376384","pt":1580648037436,"mc":[{"id":"1.168224554","rc":[{"batb":[[0,1.21,594.66]],"ltp":1.8,"tv":161.66,"id":7414058}]}]}
{"op":"mcm","clk":"1006376813","pt":1580648040334,"mc":[{"id":"1.168224554","rc":[{"batb":[[1,1.2,560.53]],"batl":[[1,1.24,405.65]],"ltp":1.8,"tv":161.66,"id":7414058}]}]}
{"op":"mcm","clk":"1006377307","pt":1580648043723,"mc":[{"id":"1.168224554","rc":[{"batb":[[0,1.21,476.84]],"ltp":1.8,"tv":161.66,"id":7414058}]}]}
{"op":"mcm","clk":"1006377722","pt":1580648046730,"mc":[{"id":"1.168224554","rc":[{"batl":[[1,1.24,520.7]],"ltp":1.8,"tv":161.66,"id":7414058}]}]}
{"op":"mcm","clk":"1006378105","pt":1580648049450,"mc":[{"id":"1.168224554","rc":[{"batb":[[0,1.21,403.36]],"batl":[[1,1.24,433.6],[2,1.25,0]],"ltp":1.8,"tv":161.66,"id":7414058}]}]}
{"op":"mcm","clk":"1006378507","pt":1580648052458,"mc":[{"id":"1.168224554","rc":[{"batl":[[1,1.23,160.06],[2,1.24,433.6]],"ltp":1.8,"tv":161.66,"id":7414058}]}]}
{"op":"mcm","clk":"1006380166","pt":1580648064261,"mc":[{"id":"1.168224554","rc":[{"batb":[[0,1.21,106.3],[1,1.17,304.95],[2,1.14,627.92]],"batl":[[1,1.23,0],[2,1.24,0]],"ltp":1.8,"tv":161.66,"id":7414058}]}]}
{"op":"mcm","clk":"1006380231","pt":1580648064780,"mc":[{"id":"1.168224554","rc":[{"batb":[[1,3.9,23.92],[2,2.8,375.33]],"ltp":2.38,"tv":68.72,"id":7287690},{"batb":[[0,1.17,304.95],[1,1.14,627.92],[2,1.01,15.51]],"ltp":1.8,"tv":161.66,"id":7414058}]}]}
{"op":"mcm","clk":"1006380383","pt":1580648065990,"mc":[{"id":"1.168224554","rc":[{"batb":[[0,3.9,23.92],[1,2.8,375.33],[2,1.01,15.51]],"ltp":2.38,"tv":68.72,"id":7287690},{"batb":[[0,1.17,136.91]],"ltp":1.8,"tv":161.66,"id":7414058}]}]}
{"op":"mcm","clk":"1006380585","pt":1580648067478,"mc":[{"id":"1.168224554","rc":[{"batb":[[0,3.95,23.29],[1,3.9,23.92],[2,2.8,375.33]],"ltp":2.38,"tv":68.72,"id":7287690},{"batb":[[1,1.16,142.73],[2,1.14,627.92]],"ltp":1.8,"tv":161.66,"id":7414058}]}]}
{"op":"mcm","clk":"1006380716","pt":1580648068388,"mc":[{"id":"1.168224554","rc":[{"batb":[[1,2.8,375.33],[2,1.01,15.51]],"ltp":2.38,"tv":68.72,"id":7287690},{"batb":[[0,1.16,142.73],[1,1.14,627.92],[2,1.01,15.51]],"ltp":1.8,"tv":161.66,"id":7414058}]}]}
{"op":"mcm","clk":"1006380799","pt":1580648068974,"mc":[{"id":"1.168224554","rc":[{"batb":[[1,1.01,15.51],[2,1.01,0]],"ltp":1.8,"tv":161.66,"id":7414058}]}]}
{"op":"mcm","clk":"1006380973","pt":1580648070388,"mc":[{"id":"1.168224554","rc":[{"batb":[[0,1.22,204.18],[1,1.21,534.35],[2,1.16,142.73]],"batl":[[0,1.24,216.04],[1,1.25,418.36]],"ltp":1.8,"tv":161.66,"id":7414058}]}]}
{"op":"mcm","clk":"1006381189","pt":1580648071798,"mc":[{"id":"1.168224554","rc":[{"batb":[[0,1.16,142.73],[1,1.01,15.51],[2,1.16,0]],"ltp":1.8,"tv":161.66,"id":7414058}]}]}
{"op":"mcm","clk":"1006381316","pt":1580648072685,"mc":[{"id":"1.168224554","rc":[{"batb":[[0,1.16,718.86]],"ltp":1.8,"tv":161.66,"id":7414058}]}]}
{"op":"mcm","clk":"1006381620","pt":1580648075178,"mc":[{"id":"1.168224554","rc":[{"batb":[[0,1.17,247.53],[1,1.16,1455.13],[2,1.01,15.51]],"ltp":1.8,"tv":161.66,"id":7414058}]}]}
{"op":"mcm","clk":"1006381718","pt":1580648075993,"mc":[{"id":"1.168224554","rc":[{"batb":[[1,1.01,15.51],[2,1.01,0]],"ltp":2.38,"tv":68.72,"id":7287690},{"batb":[[1,1.16,879]],"ltp":1.8,"tv":161.66,"id":7414058}]}]}
{"op":"mcm","clk":"1006381893","pt":1580648077088,"mc":[{"id":"1.168224554","rc":[{"batl":[[0,1.19,456.47],[1,1.2,536.34]],"ltp":1.8,"tv":161.66,"id":7414058}]}]}
{"op":"mcm","clk":"1006382012","pt":1580648077887,"mc":[{"id":"1.168224554","rc":[{"batb":[[0,5.8,18.88],[1,4.7,15.58],[2,1.01,15.51]],"ltp":2.38,"tv":68.72,"id":7287690},{"batb":[[2,1.13,176.09]],"ltp":1.8,"tv":161.66,"id":7414058}]}]}
{"op":"mcm","clk":"1006382162","pt":1580648078873,"mc":[{"id":"1.168224554","rc":[{"batb":[[0,6.4,7.56],[1,5.8,18.88],[2,4.7,15.58]],"batl":[[0,8,5.88]],"ltp":2.38,"tv":68.72,"id":7287690},{"batb":[[2,1.14,168.04]],"batl":[[0,1.19,498.48]],"ltp":1.8,"tv":161.66,"id":7414058}]}]}
{"op":"mcm","clk":"1006382911","pt":1580648083922,"mc":[{"id":"1.168224554","rc":[{"trd":[[1.17,6.06]],"batb":[[0,1.17,244.5]],"ltp":1.17,"tv":167.72,"id":7414058}],"tv":236.44}]}
{"op":"mcm","clk":"1006383104","pt":1580648085209,"mc":[{"id":"1.168224554","rc":[{"trd":[[1.17,12.06]],"batb":[[0,1.17,241.5]],"ltp":1.17,"tv":173.72,"id":7414058}],"tv":242.44}]}
{"op":"mcm","clk":"1006383847","pt":1580648090308,"mc":[{"id":"1.168224554","rc":[{"batb":[[0,4.7,15.58],[1,3,380.84],[2,1.01,15.51]],"ltp":2.38,"tv":68.72,"id":7287690},{"batb":[[0,1.13,176.09],[1,1.11,684.32],[2,1.01,15.51]],"ltp":1.17,"tv":173.72,"id":7414058}]}]}
{"op":"mcm","clk":"1006384313","pt":1580648093397,"mc":[{"id":"1.168224554","rc":[{"batb":[[0,1.14,606.62],[1,1.13,700.46],[2,1.11,684.32]],"batl":[[0,1.24,171.09],[1,1.25,419.34]],"ltp":1.17,"tv":173.72,"id":7414058}]}]}
{"op":"mcm","clk":"1006384583","pt":1580648095102,"mc":[{"id":"1.168224554","rc":[{"batb":[[0,1.13,176.09],[1,1.01,15.51],[2,1.11,0]],"ltp":1.17,"tv":173.72,"id":7414058}]}]}
{"op":"mcm","clk":"1006385118","pt":1580648099015,"mc":[{"id":"1.168224554","rc":[{"batb":[[0,1.13,806.06]],"ltp":1.17,"tv":173.72,"id":7414058}]}]}
{"op":"mcm","clk":"1006385459","pt":1580648101137,"mc":[{"id":"1.168224554","rc":[{"batb":[[0,1.14,606.62],[1,1.13,1330.43],[2,1.01,15.51]],"batl":[[0,1.24,171.09],[1,1.25,419.34]],"ltp":1.17,"tv":173.72,"id":7414058}]}]}
{"op":"mcm","clk":"1006386144","pt":1580648105416,"mc":[{"id":"1.168224554","rc":[{"batb":[[1,1.13,700.46]],"ltp":1.17,"tv":173.72,"id":7414058}]}]}
{"op":"mcm","clk":"1006386292","pt":1580648106351,"mc":[{"id":"1.168224554","rc":[{"batl":[[0,1.16,397.13],[1,1.17,648.81]],"ltp":1.17,"tv":173.72,"id":7414058}]}]}
{"op":"mcm","clk":"1006386428","pt":1580648107235,"mc":[{"id":"1.168224554","rc":[{"batb":[[0,7,6.72],[1,6.6,13.45],[2,5.6,20.22]],"batl":[[0,9.2,5.04]],"ltp":2.38,"tv":68.72,"id":7287690},{"batb":[[2,1.12,168.04]],"batl":[[0,1.16,439.14]],"ltp":1.17,"tv":173.72,"id":7414058}]}]}
{"op":"mcm","clk":"1006388325","pt":1580648120231,"mc":[{"id":"1.168224554","rc":[{"batb":[[0,5.6,20.22],[1,3,380.84],[2,1.01,15.51]],"ltp":2.38,"tv":68.72,"id":7287690},{"batb":[[0,1.11,206.93],[1,1.09,779.05],[2,1.01,15.51]],"ltp":1.17,"tv":173.72,"id":7414058}]}]}
{"op":"mcm","clk":"1006388697","pt":1580648122853,"mc":[{"id":"1.168224554","rc":[{"batb":[[0,1.12,1099.74],[1,1.11,206.93],[2,1.09,779.05]],"batl":[[0,1.19,181.49],[1,1.2,545.54]],"ltp":1.17,"tv":173.72,"id":7414058}]}]}
{"op":"mcm","clk":"1006389579","pt":1580648129187,"mc":[{"id":"1.168224554","rc":[{"batb":[[0,1.11,206.93],[1,1.09,779.05],[2,1.01,15.51]],"ltp":1.17,"tv":173.72,"id":7414058}]}]}
{"op":"mcm","clk":"1006389762","pt":1580648130254,"mc":[{"id":"1.168224554","rc":[{"batb":[[1,1.01,15.51],[2,1.01,0]],"ltp":1.17,"tv":173.72,"id":7414058}]}]}
{"op":"mcm","clk":"1006390098","pt":1580648132486,"mc":[{"id":"1.168224554","rc":[{"batb":[[1,4.4,17.7],[2,3,380.84]],"ltp":2.38,"tv":68.72,"id":7287690},{"batb":[[0,1.17,686.13],[1,1.16,553.02],[2,1.13,175.15]],"ltp":1.17,"tv":173.72,"id":7414058}]}]}
{"op":"mcm","clk":"1006390228","pt":1580648133282,"mc":[{"id":"1.168224554","rc":[{"batb":[[0,6.2,7.56],[1,5.6,20.22],[2,4.4,17.7]],"batl":[[0,7.8,5.88]],"ltp":2.38,"tv":68.72,"id":7287690},{"batl":[[0,1.19,223.5]],"ltp":1.17,"tv":173.72,"id":7414058}]}]}
{"op":"mcm","clk":"1006391986","pt":1580648146993,"mc":[{"id":"1.168224554","rc":[{"batb":[[1,4.4,17.7],[2,3,380.84]],"ltp":2.38,"tv":68.72,"id":7287690},{"batb":[[0,1.13,175.15],[1,1.11,684.32],[2,1.01,15.51]],"batl":[[0,1.19,42.01],[1,1.2,0]],"ltp":1.17,"tv":173.72,"id":7414058}]}]}
{"op":"mcm","clk":"1006392129","pt":1580648148105,"mc":[{"id":"1.168224554","rc":[{"batb":[[0,4.4,17.7],[1,3,380.84],[2,1.01,15.51]],"ltp":2.38,"tv":68.72,"id":7287690}]}]}
{"op":"mcm","clk":"1006392568","pt":1580648151434,"mc":[{"id":"1.168224554","rc":[{"batb":[[1,1.01,15.51],[2,1.01,0]],"ltp":1.17,"tv":173.72,"id":7414058}]}]}
{"op":"mcm","clk":"1006392789","pt":1580648153083,"mc":[{"id":"1.168224554","rc":[{"batb":[[0,1.18,639.6],[1,1.17,452.44],[2,1.13,175.15]],"batl":[[0,1.21,548.45],[1,1.22,477.02]],"ltp":1.17,"tv":173.72,"id":7414058}]}]}
{"op":"mcm","clk":"1006393039","pt":1580648155387,"mc":[{"id":"1.168224554","rc":[{"batb":[[2,1.13,805.12]],"ltp":1.17,"tv":173.72,"id":7414058}]}]}
{"op":"mcm","clk":"1006393081","pt":1580648155804,"mc":[{"id":"1.168224554","rc":[{"batb":[[0,1.13,805.12],[1,1.01,15.51],[2,1.13,0]],"ltp":1.17,"tv":173.72,"id":7414058}]}]}
{"op":"mcm","clk":"1006393465","pt":1580648158690,"mc":[{"id":"1.168224554","rc":[{"batb":[[0,1.14,472.58],[1,1.13,1464.72],[2,1.01,15.51]],"batl":[[0,1.26,289.92],[1,1.27,379.67]],"ltp":1.17,"tv":173.72,"id":7414058}]}]}
{"op":"mcm","clk":"1006395100","pt":1580648170828,"mc":[{"id":"1.168224554","rc":[{"batb":[[0,1.13,805.12],[1,1.01,15.51],[2,1.01,0]],"ltp":1.17,"tv":173.72,"id":7414058}]}]}
{"op":"mcm","clk":"1006395292","pt":1580648172414,"mc":[{"id":"1.168224554","rc":[{"batb":[[0,1.13,175.15]],"ltp":1.17,"tv":173.72,"id":7414058}]}]}
{"op":"mcm","clk":"1006395518","pt":1580648174350,"mc":[{"id":"1.168224554","rc":[{"batb":[[0,6.6,13.61],[1,5.6,20.06],[2,4.4,17.7]],"ltp":2.38,"tv":68.72,"id":7287690},{"batb":[[0,1.14,472.58],[1,1.13,834.75],[2,1.11,205.75]],"batl":[[0,1.16,516.8],[1,1.17,585.13]],"ltp":1.17,"tv":173.72,"id":7414058}]}]}
{"op":"mcm","clk":"1006395645","pt":1580648175448,"mc":[{"id":"1.168224554","rc":[{"batb":[[0,7.2,6.72],[1,6.6,13.61],[2,5.6,20.06]],"batl":[[0,9.2,5.04]],"ltp":2.38,"tv":68.72,"id":7287690},{"batb":[[2,1.12,168.04]],"batl":[[0,1.16,558.81]],"ltp":1.17,"tv":173.72,"id":7414058}]}]}
{"op":"mcm","clk":"1006395711","pt":1580648175956,"mc":[{"id":"1.168224554","rc":[{"batb":[[1,1.13,649.36]],"batl":[[0,1.16,378.96]],"ltp":1.17,"tv":173.72,"id":7414058}]}]}
{"op":"mcm","clk":"1006395969","pt":1580648177876,"mc":[{"id":"1.168224554","rc":[{"trd":[[1.14,4]],"batb":[[0,1.14,470.58]],"ltp":1.14,"tv":177.72,"id":7414058}],"tv":246.44}]}
{"op":"mcm","clk":"1006396092","pt":1580648178881,"mc":[{"id":"1.168224554","rc":[{"batb":[[0,1.14,654.35]],"batl":[[1,1.17,643.99]],"ltp":1.14,"tv":177.72,"id":7414058}]}]}
{"op":"mcm","clk":"1006396559","pt":1580648182277,"mc":[{"id":"1.168224554","rc":[{"batb":[[0,1.14,587.94]],"ltp":1.14,"tv":177.72,"id":7414058}]}]}
{"op":"mcm","clk":"1006396738","pt":1580648183477,"mc":[{"id":"1.168224554","rc":[{"trd":[[1.14,604]],"batb":[[0,1.14,287.94]],"batl":[[1,1.17,589.7]],"ltp":1.14,"tv":777.72,"id":7414058}],"tv":846.44}]}
{"op":"mcm","clk":"1006396954","pt":1580648185395,"mc":[{"id":"1.168224554","rc":[{"batb":[[1,1.13,718.37]],"batl":[[0,1.16,446.14]],"ltp":1.14,"tv":777.72,"id":7414058}]}]}
{"op":"mcm","clk":"1006397078","pt":1580648186379,"mc":[{"id":"1.168224554","rc":[{"batb":[[0,1.14,477.99],[1,1.13,829.29]],"batl":[[0,1.16,554.2]],"ltp":1.14,"tv":777.72,"id":7414058}]}]}
{"op":"mcm","clk":"1006397739","pt":1580648191307,"mc":[{"id":"1.168224554","rc":[{"batb":[[1,5.6,20.06],[2,3,380.84]],"ltp":2.38,"tv":68.72,"id":7287690},{"batb":[[0,1.12,168.04],[1,1.11,205.75],[2,1.09,779.05]],"batl":[[0,1.16,42.01],[1,1.17,0]],"ltp":1.14,"tv":777.72,"id":7414058}]}]}
{"op":"mcm","clk":"1006397819","pt":1580648191986,"mc":[{"id":"1.168224554","rc":[{"batb":[[0,5.6,20.06],[1,3,380.84],[2,1.01,15.51]],"ltp":2.38,"tv":68.72,"id":7287690},{"batb":[[0,1.11,205.75],[1,1.09,779.05],[2,1.01,15.51]],"ltp":1.14,"tv":777.72,"id":7414058}]}]}
{"op":"mcm","clk":"1006398115","pt":1580648194189,"mc":[{"id":"1.168224554","rc":[{"batb":[[0,1.12,1014.53],[1,1.11,205.75],[2,1.09,779.05]],"batl":[[0,1.19,378.37],[1,1.2,539.06]],"ltp":1.14,"tv":777.72,"id":7414058}]}]}
{"op":"mcm","clk":"1006398654","pt":1580648198294,"mc":[{"id":"1.168224554","rc":[{"batb":[[0,1.11,205.75],[1,1.09,779.05],[2,1.01,15.51]],"ltp":1.14,"tv":777.72,"id":7414058}]}]}
{"op":"mcm","clk":"1006398861","pt":1580648199816,"mc":[{"id":"1.168224554","rc":[{"batb":[[1,1.01,15.51],[2,1.01,0]],"ltp":1.14,"tv":777.72,"id":7414058}]}]}
{"op":"mcm","clk":"1006399067","pt":1580648201211,"mc":[{"id":"1.168224554","rc":[{"batb":[[0,1.17,333.45],[1,1.16,740.04],[2,1.11,205.75]],"ltp":1.14,"tv":777.72,"id":7414058}]}]}
{"op":"mcm","clk":"1006399179","pt":1580648202094,"mc":[{"id":"1.168224554","rc":[{"batb":[[1,4.3,18.88],[2,3,380.84]],"ltp":2.38,"tv":68.72,"id":7287690},{"batb":[[0,1.17,471.3],[2,1.13,185.14]],"ltp":1.14,"tv":777.72,"id":7414058}]}]}
{"op":"mcm","clk":"1006399292","pt":1580648203010,"mc":[{"id":"1.168224554","rc":[{"batb":[[0,6.2,7.56],[1,5.6,20.06],[2,4.3,18.88]],"batl":[[0,8,5.88]],"ltp":2.38,"tv":68.72,"id":7287690},{"batl":[[0,1.19,420.38]],"ltp":1.14,"tv":777.72,"id":7414058}]}]}
{"op":"mcm","clk":"1006400757","pt":1580648213300,"mc":[{"id":"1.168224554","rc":[{"batb":[[1,4.3,18.88],[2,3,380.84]],"ltp":2.38,"tv":68.72,"id":7287690},{"batb":[[0,1.13,185.14],[1,1.11,684.32],[2,1.01,15.51]],"batl":[[0,1.19,42.01],[1,1.2,0]],"ltp":1.14,"tv":777.72,"id":7414058}]}]}
{"op":"mcm","clk":"1006400859","pt":1580648214121,"mc":[{"id":"1.168224554","rc":[{"batb":[[0,4.3,18.88],[1,3,380.84],[2,1.01,15.51]],"ltp":2.38,"tv":68.72,"id":7287690}]}]}
{"op":"mcm","clk":"1006401335","pt":1580648217727,"mc":[{"id":"1.168224554","rc":[{"batb":[[1,1.01,15.51],[2,1.01,0]],"ltp":1.14,"tv":777.72,"id":7414058}]}]}
{"op":"mcm","clk":"1006401592","pt":1580648220329,"mc":[{"id":"1.168224554","rc":[{"batb":[[0,1.18,551.01],[1,1.17,541.79],[2,1.13,185.14]],"batl":[[0,1.21,626.91],[1,1.22,430.76]],"ltp":1.14,"tv":777.72,"id":7414058}]}]}
{"op":"mcm","clk":"1006401860","pt":1580648221219,"mc":[{"id":"1.168224554","rc":[{"batb":[[2,1.13,815.11]],"ltp":1.14,"tv":777.72,"id":7414058}]}]}
{"op":"mcm","clk":"1006401982","pt":1580648222029,"mc":[{"id":"1.168224554","rc":[{"batb":[[0,1.13,815.11],[1,1.01,15.51],[2,1.13,0]],"ltp":1.14,"tv":777.72,"id":7414058}]}]}
{"op":"mcm","clk":"1006402473","pt":1580648225328,"mc":[{"id":"1.168224554","rc":[{"batl":[[0,1.27,411.49],[1,1.28,361.29]],"ltp":1.14,"tv":777.72,"id":7414058}]}]}
{"op":"mcm","clk":"1006402799","pt":1580648227342,"mc":[{"id":"1.168224554","rc":[{"batb":[[0,1.13,185.14]],"ltp":1.14,"tv":777.72,"id":7414058}]}]}
{"op":"mcm","clk":"1006402965","pt":1580648228347,"mc":[{"id":"1.168224554","rc":[{"batb":[[1,3.2,19.59],[2,3,380.84]],"ltp":2.38,"tv":68.72,"id":7287690},{"batb":[[0,1.25,89.3],[1,1.24,323.52],[2,1.23,482.75]],"ltp":1.14,"tv":777.72,"id":7414058}]}]}
{"op":"mcm","clk":"1006403132","pt":1580648229346,"mc":[{"id":"1.168224554","rc":[{"batb":[[0,4.9,10.08],[1,4.3,18.88],[2,3.2,19.59]],"batl":[[0,6,8.4]],"ltp":2.38,"tv":68.72,"id":7287690},{"batl":[[0,1.26,42.01],[1,1.27,411.49],[2,1.28,361.29]],"ltp":1.14,"tv":777.72,"id":7414058}]}]}
{"op":"mcm","clk":"1006404831","pt":1580648240949,"mc":[{"id":"1.168224554","rc":[{"batb":[[1,3.2,19.59],[2,3,380.84]],"ltp":2.38,"tv":68.72,"id":7287690},{"batb":[[0,1.2,168.04],[1,1.18,549.72],[2,1.17,132.03]],"batl":[[1,1.27,0],[2,1.28,0]],"ltp":1.14,"tv":777.72,"id":7414058}]}]}
{"op":"mcm","clk":"1006404991","pt":1580648242165,"mc":[{"id":"1.168224554","rc":[{"batb":[[0,3.2,19.59],[1,3,380.84],[2,1.01,15.51]],"ltp":2.38,"tv":68.72,"id":7287690},{"batb":[[0,1.18,549.72],[1,1.17,132.03],[2,1.01,15.51]],"ltp":1.14,"tv":777.72,"id":7414058}]}]}
{"op":"mcm","clk":"1006405212","pt":1580648243551,"mc":[{"id":"1.168224554","rc":[{"batb":[[1,1.17,740.64],[2,1.16,493.11]],"batl":[[0,1.41,145.67],[1,1.42,220.35]],"ltp":1.14,"tv":777.72,"id":7414058}]}]}
{"op":"mcm","clk":"1006405988","pt":1580648249286,"mc":[{"id":"1.168224554","rc":[{"batb":[[0,1.17,740.64],[1,1.16,493.11],[2,1.01,15.51]],"batl":[[0,1.2,676.01],[1,1.21,390.81]],"ltp":1.14,"tv":777.72,"id":7414058}]}]}
{"op":"mcm","clk":"1006406113","pt":1580648250099,"mc":[{"id":"1.168224554","rc":[{"batb":[[0,5.5,10.46],[1,4.2,19.83],[2,3,380.84]],"ltp":2.38,"tv":68.72,"id":7287690},{"batb":[[2,1.13,179.79]],"ltp":1.14,"tv":777.72,"id":7414058}]}]}
{"op":"mcm","clk":"1006406273","pt":1580648251153,"mc":[{"id":"1.168224554","rc":[{"batb":[[0,6.2,7.56],[1,5.5,10.46],[2,4.2,19.83]],"batl":[[0,7.8,5.88]],"ltp":2.38,"tv":68.72,"id":7287690},{"batl":[[0,1.19,42.01],[1,1.2,676.01],[2,1.21,390.81]],"ltp":1.14,"tv":777.72,"id":7414058}]}]}
{"op":"mcm","clk":"1006406467","pt":1580648252479,"mc":[{"id":"1.168224554","rc":[{"batb":[[2,1.13,809.76]],"ltp":1.14,"tv":777.72,"id":7414058}]}]}
{"op":"mcm","clk":"1006406698","pt":1580648253965,"mc":[{"id":"1.168224554","rc":[{"trd":[[6,1.03],[6.2,23.19]],"batb":[[0,5.5,10.46],[1,4.2,19.83],[2,3,380.84]],"ltp":6.0,"tv":92.94,"id":7287690},{"trd":[[1.19,42.01],[1.2,5.15]],"batl":[[0,1.2,670.86],[1,1.21,390.81],[2,1.21,0]],"ltp":1.2,"tv":824.88,"id":7414058}],"tv":917.82}]}
{"op":"mcm","clk":"1006406970","pt":1580648255889,"mc":[{"id":"1.168224554","rc":[{"batb":[[0,1.17,605.02]],"batl":[[0,1.2,548.12],[1,1.21,0]],"ltp":1.2,"tv":824.88,"id":7414058}]}]}
{"op":"mcm","clk":"1006407142","pt":1580648256956,"mc":[{"id":"1.168224554","rc":[{"batb":[[0,6,8.4],[1,5.5,10.46],[2,4.2,19.83]],"batl":[[0,7.4,5.88]],"ltp":6.0,"tv":92.94,"id":7287690},{"batb":[[2,1.15,168.04]],"batl":[[0,1.2,590.13]],"ltp":1.2,"tv":824.88,"id":7414058}]}]}
{"op":"mcm","clk":"1006407467","pt":1580648258898,"mc":[{"id":"1.168224554","rc":[{"batb":[[1,1.16,629.91]],"batl":[[0,1.19,262.25],[1,1.2,590.13]],"ltp":1.2,"tv":824.88,"id":7414058}]}]}
{"op":"mcm","clk":"1006407831","pt":1580648261559,"mc":[{"id":"1.168224554","rc":[{"trd":[[1.19,46.01]],"batl":[[0,1.19,260.25]],"ltp":1.19,"tv":828.88,"id":7414058}],"tv":921.82}]}
{"op":"mcm","clk":"1006408390","pt":1580648265465,"mc":[{"id":"1.168224554","rc":[{"batb":[[1,4.2,19.83],[2,3,380.84]],"ltp":6.0,"tv":92.94,"id":7287690},{"batb":[[0,1.15,168.04],[1,1.13,809.76],[2,1.01,15.51]],"batl":[[0,1.2,42.01],[1,1.2,0]],"ltp":1.19,"tv":828.88,"id":7414058}]}]}
{"op":"mcm","clk":"1006408517","pt":1580648266413,"mc":[{"id":"1.168224554","rc":[{"batb":[[0,4.2,19.83],[1,3,380.84],[2,1.01,15.51]],"ltp":6.0,"tv":92.94,"id":7287690},{"batb":[[0,1.13,809.76],[1,1.01,15.51],[2,1.01,0]],"ltp":1.19,"tv":828.88,"id":7414058}]}]}
{"op":"mcm","clk":"1006408766","pt":1580648268375,"mc":[{"id":"1.168224554","rc":[{"batb":[[0,4.3,19.2]],"ltp":6.0,"tv":92.94,"id":7287690},{"batb":[[0,1.13,1605.76],[1,1.12,343.4],[2,1.01,15.51]],"batl":[[0,1.27,288.27],[1,1.28,366.59]],"ltp":1.19,"tv":828.88,"id":7414058}]}]}
{"op":"mcm","clk":"1006408859","pt":1580648269069,"mc":[{"id":"1.168224554","rc":[{"batb":[[0,1.13,809.76],[1,1.01,15.51],[2,1.01,0]],"ltp":1.19,"tv":828.88,"id":7414058}]}]}
{"op":"mcm","clk":"1006409227","pt":1580648272096,"mc":[{"id":"1.168224554","rc":[{"trd":[[1.18,16.8]],"batb":[[0,1.18,683.86],[1,1.17,399.34],[2,1.13,809.76]],"batl":[[0,1.21,517.02],[1,1.22,482.61]],"ltp":1.18,"tv":845.68,"id":7414058}],"tv":938.62}]}
{"op":"mcm","clk":"1006409402","pt":1580648273483,"mc":[{"id":"1.168224554","rc":[{"batb":[[0,1.13,809.76],[1,1.01,15.51],[2,1.13,0]],"ltp":1.18,"tv":845.68,"id":7414058}]}]}
{"op":"mcm","clk":"1006409624","pt":1580648274985,"mc":[{"id":"1.168224554","rc":[{"batl":[[0,1.17,7.44]],"ltp":1.18,"tv":845.68,"id":7414058}]}]}
{"op":"mcm","clk":"1006409778","pt":1580648276381,"mc":[{"id":"1.168224554","rc":[{"batb":[[0,1.13,1602.53],[1,1.12,346.66],[2,1.01,15.51]],"batl":[[1,1.27,291.13],[2,1.28,366.59]],"ltp":1.18,"tv":845.68,"id":7414058}]}]}
{"op":"mcm","clk":"1006409885","pt":1580648277290,"mc":[{"id":"1.168224554","rc":[{"batb":[[0,1.13,809.76],[1,1.01,15.51],[2,1.01,0]],"ltp":1.18,"tv":845.68,"id":7414058}]}]}
{"op":"mcm","clk":"1006409938","pt":1580648277811,"mc":[{"id":"1.168224554","rc":[{"batb":[[0,1.13,179.79]],"ltp":1.18,"tv":845.68,"id":7414058}]}]}
{"op":"mcm","clk":"1006410123","pt":1580648279303,"mc":[{"id":"1.168224554","rc":[{"batb":[[0,4.7,10.92],[1,4.3,19.2],[2,3,380.84]],"ltp":6.0,"tv":92.94,"id":7287690},{"trd":[[1.17,26.93]],"batb":[[0,1.24,458.06],[1,1.23,489.81],[2,1.17,6.72]],"batl":[[0,1.27,282.38],[1,1.28,366.59],[2,1.28,0]],"ltp":1.17,"tv":860.56,"id":7414058}],"tv":953.5}]}
{"op":"mcm","clk":"1006410231","pt":1580648280106,"mc":[{"id":"1.168224554","rc":[{"batb":[[2,3.15,19.91]],"batl":[[0,5.3,6.06]],"ltp":6.0,"tv":92.94,"id":7287690},{"batb":[[0,1.25,88.28],[1,1.24,458.06],[2,1.23,489.81]],"ltp":1.17,"tv":860.56,"id":7414058}]}]}
{"op":"mcm","clk":"1006410372","pt":1580648281334,"mc":[{"id":"1.168224554","rc":[{"batl":[[0,1000,3.36]],"ltp":6.0,"tv":92.94,"id":7287690}]}]}
{"op":"mcm","clk":"1006410521","pt":1580648282405,"mc":[{"id":"1.168224554","rc":[{"batl":[[0,5.6,8.4]],"ltp":6.0,"tv":92.94,"id":7287690}]}]}
{"op":"mcm","clk":"1006410676","pt":1580648283410,"mc":[{"id":"1.168224554","rc":[{"batb":[[1,1.24,515.12]],"ltp":1.17,"tv":860.56,"id":7414058}]}]}
{"op":"mcm","clk":"1006411850","pt":1580648292318,"mc":[{"id":"1.168224554","rc":[{"batb":[[1,3.15,19.91],[2,3,380.84]],"ltp":6.0,"tv":92.94,"id":7287690},{"batb":[[0,1.21,168.04],[1,1.18,680.18],[2,1.01,15.51]],"batl":[[0,1.27,42.01],[1,1.28,0]],"ltp":1.17,"tv":860.56,"id":7414058}]}]}
{"op":"mcm","clk":"1006412110","pt":1580648294228,"mc":[{"id":"1.168224554","rc":[{"batb":[[0,3.15,19.91],[1,3,380.84],[2,1.01,15.51]],"ltp":6.0,"tv":92.94,"id":7287690},{"batb":[[0,1.18,680.18],[1,1.01,15.51],[2,1.01,0]],"ltp":1.17,"tv":860.56,"id":7414058}]}]}
{"op":"mcm","clk":"1006412245","pt":1580648295119,"mc":[{"id":"1.168224554","rc":[{"batb":[[1,1.17,808.52],[2,1.16,291.48]],"batl":[[0,1.42,238.3],[1,1.43,213.85]],"ltp":1.17,"tv":860.56,"id":7414058}]}]}
{"op":"mcm","clk":"1006412929","pt":1580648299939,"mc":[{"id":"1.168224554","rc":[{"batb":[[0,1.18,130.45]],"ltp":1.17,"tv":860.56,"id":7414058}]}]}
{"op":"mcm","clk":"1006413235","pt":1580648302330,"mc":[{"id":"1.168224554","rc":[{"batb":[[0,5.5,10.7],[1,4.2,20.3],[2,3,380.84]],"ltp":6.0,"tv":92.94,"id":7287690},{"batl":[[0,1.2,510.98],[1,1.21,508.54]],"ltp":1.17,"tv":860.56,"id":7414058}]}]}
{"op":"mcm","clk":"1006413324","pt":1580648303132,"mc":[{"id":"1.168224554","rc":[{"batl":[[0,7.2,6.72]],"ltp":6.0,"tv":92.94,"id":7287690}]}]}
{"op":"mcm","clk":"1006415016","pt":1580648316471,"mc":[{"id":"1.168224554","rc":[{"batb":[[0,4.2,20.3],[1,3,380.84],[2,1.01,15.51]],"ltp":6.0,"tv":92.94,"id":7287690},{"batb":[[0,1.13,807.16],[1,1.01,15.51],[2,1.16,0]],"ltp":1.17,"tv":860.56,"id":7414058}]}]}
{"op":"mcm","clk":"1006415301","pt":1580648318678,"mc":[{"id":"1.168224554","rc":[{"batb":[[0,1.14,182.93],[1,1.13,1742.62],[2,1.01,15.51]],"batl":[[0,1.28,376.48],[1,1.29,348.75]],"ltp":1.17,"tv":860.56,"id":7414058}]}]}
{"op":"mcm","clk":"1006417663","pt":1580648337864,"mc":[{"id":"1.168224554","rc":[{"batb":[[0,1.13,807.16],[1,1.01,15.51],[2,1.01,0]],"ltp":1.17,"tv":860.56,"id":7414058}]}]}
{"op":"mcm","clk":"1006417809","pt":1580648339176,"mc":[{"id":"1.168224554","rc":[{"batb":[[1,1.01,15.51],[2,1.01,0]],"ltp":6.0,"tv":92.94,"id":7287690},{"batb":[[0,1.13,177.19]],"ltp":1.17,"tv":860.56,"id":7414058}]}]}
{"op":"mcm","clk":"1006418083","pt":1580648341417,"mc":[{"id":"1.168224554","rc":[{"batb":[[0,4.7,10.92],[1,4.2,20.3],[2,1.01,15.51]],"ltp":6.0,"tv":92.94,"id":7287690},{"batb":[[0,1.25,312.82],[1,1.24,460.53],[2,1.21,168.04]],"batl":[[0,1.27,42.01],[1,1.28,376.48],[2,1.29,348.75]],"ltp":1.17,"tv":860.56,"id":7414058}]}]}
{"op":"mcm","clk":"1006418230","pt":1580648342290,"mc":[{"id":"1.168224554","rc":[{"batb":[[2,3.1,20.77]],"batl":[[0,5.5,9.24]],"ltp":6.0,"tv":92.94,"id":7287690},{"batb":[[0,1.26,85.06],[1,1.25,312.82],[2,1.24,460.53]],"ltp":1.17,"tv":860.56,"id":7414058}]}]}
{"op":"mcm","clk":"1006418953","pt":1580648348227,"mc":[{"id":"1.168224554","rc":[{"batl":[[1,1.28,322.38]],"ltp":1.17,"tv":860.56,"id":7414058}]}]}
{"op":"mcm","clk":"1006419320","pt":1580648351389,"mc":[{"id":"1.168224554","rc":[{"batb":[[1,1.25,368.38]],"ltp":1.17,"tv":860.56,"id":7414058}]}]}
{"op":"mcm","clk":"1006419943","pt":1580648356428,"mc":[{"id":"1.168224554","rc":[{"batb":[[1,3.1,20.77],[2,2.52,381.46]],"ltp":6.0,"tv":92.94,"id":7287690},{"batb":[[0,1.21,168.04],[1,1.2,530.86],[2,1.18,126.44]],"batl":[[1,1.28,0],[2,1.29,0]],"ltp":1.17,"tv":860.56,"id":7414058}]}]}
{"op":"mcm","clk":"1006420188","pt":1580648358145,"mc":[{"id":"1.168224554","rc":[{"batb":[[0,3.1,20.77],[1,2.52,381.46],[2,1.01,15.51]],"ltp":6.0,"tv":92.94,"id":7287690},{"batb":[[0,1.2,530.86],[1,1.18,126.44],[2,1.01,15.51]],"ltp":1.17,"tv":860.56,"id":7414058}]}]}
{"op":"mcm","clk":"1006420348","pt":1580648359429,"mc":[{"id":"1.168224554","rc":[{"batb":[[1,1.18,576.69],[2,1.17,643.42]],"batl":[[0,1.43,211.18],[1,1.44,207.27]],"ltp":1.17,"tv":860.56,"id":7414058}]}]}
{"op":"mcm","clk":"1006420437","pt":1580648360325,"mc":[{"id":"1.168224554","rc":[{"batb":[[1,1.18,126.44],[2,1.01,15.51]],"ltp":1.17,"tv":860.56,"id":7414058}]}]}
{"op":"mcm","clk":"1006420691","pt":1580648362406,"mc":[{"id":"1.168224554","rc":[{"batb":[[0,1.28,169.99],[1,1.27,394.69],[2,1.2,530.86]],"batl":[[0,1.31,374.51],[1,1.32,308.07]],"ltp":1.17,"tv":860.56,"id":7414058}]}]}
{"op":"mcm","clk":"1006420772","pt":1580648363112,"mc":[{"id":"1.168224554","rc":[{"batb":[[0,1.2,530.86],[1,1.18,126.44],[2,1.01,15.51]],"ltp":1.17,"tv":860.56,"id":7414058}]}]}
{"op":"mcm","clk":"1006421250","pt":1580648366089,"mc":[{"id":"1.168224554","rc":[{"batb":[[1,1.18,576.69],[2,1.17,643.42]],"batl":[[0,1.43,211.18],[1,1.44,207.27]],"ltp":1.17,"tv":860.56,"id":7414058}]}]}
{"op":"mcm","clk":"1006421570","pt":1580648369106,"mc":[{"id":"1.168224554","rc":[{"batb":[[1,1.18,126.44],[2,1.01,15.51]],"ltp":1.17,"tv":860.56,"id":7414058}]}]}
{"op":"mcm","clk":"1006421685","pt":1580648370214,"mc":[{"id":"1.168224554","rc":[{"batb":[[1,1.01,15.51],[2,1.01,0]],"ltp":6.0,"tv":92.94,"id":7287690},{"batb":[[0,1.18,126.44],[1,1.01,15.51],[2,1.01,0]],"ltp":1.17,"tv":860.56,"id":7414058}]}]}
{"op":"mcm","clk":"1006421961","pt":1580648372135,"mc":[{"id":"1.168224554","rc":[{"batb":[[0,1.39,255.15],[1,1.38,257.05],[2,1.18,126.44]],"ltp":1.17,"tv":860.56,"id":7414058}]}]}
{"op":"mcm","clk":"1006422108","pt":1580648373433,"mc":[{"id":"1.168224554","rc":[{"batb":[[0,3.35,17.64],[1,3.1,20.77],[2,2.26,19.43]],"ltp":6.0,"tv":92.94,"id":7287690},{"batb":[[0,1.4,50.12],[1,1.39,255.15],[2,1.38,257.05]],"batl":[[0,1.42,42.01],[1,1.43,211.18],[2,1.44,207.27]],"ltp":1.17,"tv":860.56,"id":7414058}]}]}
{"op":"mcm","clk":"1006423609","pt":1580648384333,"mc":[{"id":"1.168224554","rc":[{"batb":[[1,2.26,19.43],[2,2.22,384.52]],"ltp":6.0,"tv":92.94,"id":7287690},{"batb":[[0,1.28,485.89],[1,1.26,83.87],[2,1.01,15.51]],"batl":[[1,1.43,0],[2,1.44,0]],"ltp":1.17,"tv":860.56,"id":7414058}]}]}
{"op":"mcm","clk":"1006423837","pt":1580648386253,"mc":[{"id":"1.168224554","rc":[{"batb":[[0,2.26,19.43],[1,2.22,384.52],[2,1.01,15.51]],"ltp":6.0,"tv":92.94,"id":7287690}]}]}
{"op":"mcm","clk":"1006423992","pt":1580648387457,"mc":[{"id":"1.168224554","rc":[{"batb":[[0,2.28,19.36]],"ltp":6.0,"tv":92.94,"id":7287690},{"batb":[[1,1.26,249.85],[2,1.25,433.7]],"batl":[[0,1.75,125.27],[1,1.77,194.22]],"ltp":1.17,"tv":860.56,"id":7414058}]}]}
{"op":"mcm","clk":"1006424429","pt":1580648390533,"mc":[{"id":"1.168224554","rc":[{"batb":[[1,1.26,83.87],[2,1.01,15.51]],"ltp":1.17,"tv":860.56,"id":7414058}]}]}
{"op":"mcm","clk":"1006424688","pt":1580648392383,"mc":[{"id":"1.168224554","rc":[{"batb":[[1,1.01,15.51],[2,1.01,0]],"ltp":6.0,"tv":92.94,"id":7287690},{"batb":[[0,1.26,83.87],[1,1.01,15.51],[2,1.01,0]],"ltp":1.17,"tv":860.56,"id":7414058}]}]}
{"op":"mcm","clk":"1006424941","pt":1580648394433,"mc":[{"id":"1.168224554","rc":[{"batb":[[0,4.1,20.61],[1,3.1,21.32],[2,1.01,15.51]],"ltp":6.0,"tv":92.94,"id":7287690},{"batb":[[0,1.26,249.85],[1,1.25,433.7],[2,1.18,124.63]],"batl":[[0,1.29,461.12],[1,1.3,332.01]],"ltp":1.17,"tv":860.56,"id":7414058}]}]}
{"op":"mcm","clk":"1006425060","pt":1580648395423,"mc":[{"id":"1.168224554","rc":[{"batl":[[0,5.4,9.24]],"ltp":6.0,"tv":92.94,"id":7287690},{"batb":[[2,1.22,168.04]],"ltp":1.17,"tv":860.56,"id":7414058}]}]}
{"op":"mcm","clk":"1006425184","pt":1580648396440,"mc":[{"id":"1.168224554","rc":[{"batb":[[0,4.6,10.92],[1,4.1,20.61],[2,3.1,21.32]],"ltp":6.0,"tv":92.94,"id":7287690},{"batl":[[0,1.28,42.01],[1,1.29,354.57],[2,1.3,332.01]],"ltp":1.17,"tv":860.56,"id":7414058}]}]}
{"op":"mcm","clk":"1006425516","pt":1580648399421,"mc":[{"id":"1.168224554","rc":[{"batb":[[0,1.26,359.25]],"ltp":1.17,"tv":860.56,"id":7414058}]}]}
{"op":"mcm","clk":"1006430002","pt":1580648431091,"mc":[{"id":"1.168224554","rc":[{"batb":[[0,1.26,83.87],[1,1.22,168.04],[2,1.2,530.86]],"batl":[[1,1.29,0],[2,1.3,0]],"ltp":1.17,"tv":860.56,"id":7414058}]}]}
{"op":"mcm","clk":"1006430329","pt":1580648433806,"mc":[{"id":"1.168224554","rc":[{"batl":[[1,1.45,332.77],[2,1.46,193.45]],"ltp":1.17,"tv":860.56,"id":7414058}]}]}
{"op":"mcm","clk":"1006430790","pt":1580648437386,"mc":[{"id":"1.168224554","rc":[{"batb":[[1,3.1,21.32],[2,2.52,381.46]],"ltp":6.0,"tv":92.94,"id":7287690},{"batb":[[0,1.22,168.04],[1,1.2,530.86],[2,1.19,196.9]],"ltp":1.17,"tv":860.56,"id":7414058}]}]}
{"op":"mcm","clk":"1006430886","pt":1580648438238,"mc":[{"id":"1.168224554","rc":[{"batb":[[0,3.1,21.32],[1,2.52,381.46],[2,1.01,15.51]],"ltp":6.0,"tv":92.94,"id":7287690},{"batb":[[0,1.2,530.86],[1,1.19,196.9],[2,1.18,762.51]],"batl":[[0,1.45,332.77],[1,1.46,193.45],[2,1.46,0]],"ltp":1.17,"tv":860.56,"id":7414058}]}]}
{"op":"mcm","clk":"1006431105","pt":1580648439911,"mc":[{"id":"1.168224554","rc":[{"batb":[[0,3.05,21.72]],"ltp":6.0,"tv":92.94,"id":7287690},{"batb":[[1,1.19,319.96],[2,1.18,637.88]],"ltp":1.17,"tv":860.56,"id":7414058}]}]}
{"op":"mcm","clk":"1006431570","pt":1580648443714,"mc":[{"id":"1.168224554","rc":[{"trd":[[1.45,2.52]],"batl":[[0,1.45,331.51]],"ltp":1.45,"tv":863.08,"id":7414058}],"tv":956.02}]}
{"op":"mcm","clk":"1006431883","pt":1580648446545,"mc":[{"id":"1.168224554","rc":[{"batb":[[1,1.19,123.06],[2,1.01,15.51]],"ltp":1.45,"tv":863.08,"id":7414058}]}]}
{"op":"mcm","clk":"1006432216","pt":1580648449441,"mc":[{"id":"1.168224554","rc":[{"batb":[[1,1.01,15.51],[2,1.01,0]],"ltp":6.0,"tv":92.94,"id":7287690},{"batb":[[0,1.19,123.06],[1,1.01,15.51],[2,1.01,0]],"ltp":1.45,"tv":863.08,"id":7414058}]}]}
{"op":"mcm","clk":"1006432352","pt":1580648450458,"mc":[{"id":"1.168224554","rc":[{"batb":[[0,5.3,11.72],[1,4,22.11],[2,1.01,15.51]],"ltp":6.0,"tv":92.94,"id":7287690},{"batb":[[0,1.19,320.53],[1,1.18,637.89],[2,1.14,167.28]],"batl":[[0,1.21,368.13],[1,1.22,480.35]],"ltp":1.45,"tv":863.08,"id":7414058}]}]}
{"op":"mcm","clk":"1006432486","pt":1580648451434,"mc":[{"id":"1.168224554","rc":[{"batb":[[0,5.8,8.4],[1,5.3,11.72],[2,4,22.11]],"batl":[[0,7,6.72]],"ltp":6.0,"tv":92.94,"id":7287690},{"batb":[[2,1.16,168.04]],"batl":[[0,1.21,410.14]],"ltp":1.45,"tv":863.08,"id":7414058}]}]}
{"op":"mcm","clk":"1006433514","pt":1580648458370,"mc":[{"id":"1.168224554","rc":[{"batb":[[0,1.19,123.06],[1,1.16,168.04],[2,1.14,167.28]],"batl":[[0,1.21,42.01],[1,1.22,0]],"ltp":1.45,"tv":863.08,"id":7414058}]}]}
{"op":"mcm","clk":"1006433580","pt":1580648458984,"mc":[{"id":"1.168224554","rc":[{"batb":[[1,4,22.11],[2,2.9,375.84]],"ltp":6.0,"tv":92.94,"id":7287690},{"batb":[[0,1.16,168.04],[1,1.14,167.28],[2,1.13,629.97]],"ltp":1.45,"tv":863.08,"id":7414058}]}]}
{"op":"mcm","clk":"1006433762","pt":1580648460462,"mc":[{"id":"1.168224554","rc":[{"batb":[[0,4,22.11],[1,2.9,375.84],[2,1.01,15.51]],"ltp":6.0,"tv":92.94,"id":7287690},{"batb":[[0,1.14,167.28],[1,1.13,629.97],[2,1.01,15.51]],"ltp":1.45,"tv":863.08,"id":7414058}]}]}
{"op":"mcm","clk":"1006434028","pt":1580648462458,"mc":[{"id":"1.168224554","rc":[{"batb":[[0,1.14,1047.8],[1,1.13,878.02]],"batl":[[0,1.3,448.16],[1,1.31,316.88]],"ltp":1.45,"tv":863.08,"id":7414058}]}]}
{"op":"mcm","clk":"1006434205","pt":1580648463658,"mc":[{"id":"1.168224554","rc":[{"batb":[[0,1.21,7.57],[1,1.14,1047.8],[2,1.13,878.02]],"ltp":1.45,"tv":863.08,"id":7414058}]}]}
{"op":"mcm","clk":"1006434607","pt":1580648466246,"mc":[{"id":"1.168224554","rc":[{"batb":[[0,1.14,1047.8],[1,1.13,878.02],[2,1.01,15.51]],"ltp":1.45,"tv":863.08,"id":7414058}]}]}
{"op":"mcm","clk":"1006434718","pt":1580648467163,"mc":[{"id":"1.168224554","rc":[{"batb":[[1,1.01,15.51],[2,1.01,0]],"ltp":6.0,"tv":92.94,"id":7287690},{"batb":[[1,1.13,248.05]],"ltp":1.45,"tv":863.08,"id":7414058}]}]}
{"op":"mcm","clk":"1006434899","pt":1580648468445,"mc":[{"id":"1.168224554","rc":[{"batl":[[0,1.17,801.93],[1,1.18,292.55]],"ltp":1.45,"tv":863.08,"id":7414058}]}]}
{"op":"mcm","clk":"1006435025","pt":1580648469457,"mc":[{"id":"1.168224554","rc":[{"batb":[[0,6.4,14.63],[1,5.7,19.83],[2,1.01,15.51]],"batl":[[0,8.6,5.04]],"ltp":6.0,"tv":92.94,"id":7287690},{"batb":[[1,1.13,416.09],[2,1.11,222.98]],"ltp":1.45,"tv":863.08,"id":7414058}]}]}
{"op":"mcm","clk":"1006435142","pt":1580648470377,"mc":[{"id":"1.168224554","rc":[{"batb":[[0,7,6.72],[1,6.4,14.63],[2,5.7,19.83]],"ltp":6.0,"tv":92.94,"id":7287690},{"batl":[[0,1.17,843.94]],"ltp":1.45,"tv":863.08,"id":7414058}]}]}
{"op":"mcm","clk":"1006438068","pt":1580648492988,"mc":[{"id":"1.168224554","rc":[{"batb":[[1,5.7,19.83],[2,3.15,373.59]],"ltp":6.0,"tv":92.94,"id":7287690},{"trd":[[1.14,608]],"batb":[[0,1.13,168.04],[1,1.11,222.98],[2,1.09,779.05]],"batl":[[0,1.17,42.01],[1,1.18,0]],"ltp":1.14,"tv":867.08,"id":7414058}],"tv":960.02}]}
{"op":"mcm","clk":"1006438209","pt":1580648494267,"mc":[{"id":"1.168224554","rc":[{"batb":[[0,5.7,19.83],[1,3.15,373.59],[2,1.01,15.51]],"ltp":6.0,"tv":92.94,"id":7287690},{"batb":[[0,1.11,222.98],[1,1.09,779.05],[2,1.01,15.51]],"ltp":1.14,"tv":867.08,"id":7414058}]}]}
{"op":"mcm","clk":"1006438336","pt":1580648495263,"mc":[{"id":"1.168224554","rc":[{"batb":[[0,1.11,1076],[1,1.1,306.01],[2,1.09,779.05]],"batl":[[0,1.19,384.03],[1,1.2,536.11]],"ltp":1.14,"tv":867.08,"id":7414058}]}]}
{"op":"mcm","clk":"1006439461","pt":1580648504908,"mc":[{"id":"1.168224554","rc":[{"batb":[[0,1.11,222.98],[1,1.09,779.05],[2,1.01,15.51]],"ltp":1.14,"tv":867.08,"id":7414058}]}]}
{"op":"mcm","clk":"1006439700","pt":1580648506818,"mc":[{"id":"1.168224554","rc":[{"batb":[[1,1.01,15.51],[2,1.01,0]],"ltp":1.14,"tv":867.08,"id":7414058}]}]}
{"op":"mcm","clk":"1006439857","pt":1580648507891,"mc":[{"id":"1.168224554","rc":[{"batb":[[0,1.17,321.07],[1,1.16,736.05],[2,1.11,222.98]],"ltp":1.14,"tv":867.08,"id":7414058}]}]}
{"op":"mcm","clk":"1006440094","pt":1580648509382,"mc":[{"id":"1.168224554","rc":[{"batb":[[0,6.4,7.56],[1,5.7,19.83],[2,5.2,12.2]],"batl":[[0,7.8,5.88]],"ltp":6.0,"tv":92.94,"id":7287690},{"batb":[[0,1.17,459.79],[2,1.14,173.57]],"batl":[[0,1.19,426.04]],"ltp":1.14,"tv":867.08,"id":7414058}]}]}
{"op":"mcm","clk":"1006440942","pt":1580648515217,"mc":[{"id":"1.168224554","rc":[{"trd":[[1.19,616.01]],"batl":[[0,1.19,141.04]],"ltp":1.19,"tv":1437.08,"id":7414058}],"tv":1530.02}]}
{"op":"mcm","clk":"1006441100","pt":1580648516331,"mc":[{"id":"1.168224554","rc":[{"batb":[[0,5.2,12.2],[1,3.15,373.59],[2,1.01,15.51]],"ltp":6.0,"tv":92.94,"id":7287690},{"batb":[[0,1.14,173.57],[1,1.13,629.97],[2,1.01,15.51]],"ltp":1.19,"tv":1437.08,"id":7414058}]}]}
{"op":"mcm","clk":"1006441538","pt":1580648519200,"mc":[{"id":"1.168224554","rc":[{"batb":[[0,1.14,721.14],[1,1.13,1213.36]],"batl":[[0,1.22,599.22],[1,1.23,446.19]],"ltp":1.19,"tv":1437.08,"id":7414058}]}]}
{"op":"mcm","clk":"1006441661","pt":1580648520110,"mc":[{"id":"1.168224554","rc":[{"batb":[[0,1.14,173.57],[1,1.13,629.97]],"ltp":1.19,"tv":1437.08,"id":7414058}]}]}
{"op":"mcm","clk":"1006441757","pt":1580648520636,"mc":[{"id":"1.168224554","rc":[{"trd":[[5.2,0.46]],"batb":[[0,5.2,11.74]],"ltp":5.2,"tv":93.4,"id":7287690},{"trd":[[1.24,1.93]],"ltp":1.24,"tv":1439.01,"id":7414058}],"tv":1532.41}]}
{"op":"mcm","clk":"1006441959","pt":1580648522144,"mc":[{"id":"1.168224554","rc":[{"batb":[[1,1.01,15.51],[2,1.01,0]],"ltp":1.24,"tv":1439.01,"id":7414058}]}]}
{"op":"mcm","clk":"1006442228","pt":1580648524107,"mc":[{"id":"1.168224554","rc":[{"batb":[[0,1.16,737.3],[1,1.15,372.34],[2,1.14,173.57]],"batl":[[0,1.19,651.83],[1,1.2,423.15]],"ltp":1.24,"tv":1439.01,"id":7414058}]}]}
{"op":"mcm","clk":"1006442399","pt":1580648525322,"mc":[{"id":"1.168224554","rc":[{"trd":[[1.19,616.63]],"batb":[[0,1.14,173.57],[1,1.01,15.51],[2,1.14,0]],"ltp":1.19,"tv":1439.63,"id":7414058}],"tv":1533.03}]}
{"op":"mcm","clk":"1006442502","pt":1580648526054,"mc":[{"id":"1.168224554","rc":[{"batb":[[1,1.11,684.32],[2,1.01,15.51]],"ltp":1.19,"tv":1439.63,"id":7414058}]}]}
{"op":"mcm","clk":"1006442811","pt":1580648528343,"mc":[{"id":"1.168224554","rc":[{"batb":[[0,1.14,721.14],[1,1.13,583.39],[2,1.11,684.32]],"batl":[[0,1.22,599.22],[1,1.23,446.19]],"ltp":1.19,"tv":1439.63,"id":7414058}]}]}
{"op":"mcm","clk":"1006443174","pt":1580648530839,"mc":[{"id":"1.168224554","rc":[{"trd":[[1.22,0.12]],"batl":[[0,1.22,599.16]],"ltp":1.22,"tv":1439.75,"id":7414058}],"tv":1533.15}]}
{"op":"mcm","clk":"1006444812","pt":1580648543169,"mc":[{"id":"1.168224554","rc":[{"batb":[[2,1.01,15.51]],"ltp":1.22,"tv":1439.75,"id":7414058}]}]}
{"op":"mcm","clk":"1006444981","pt":1580648544452,"mc":[{"id":"1.168224554","rc":[{"batl":[[0,1.16,433.94],[1,1.17,639.82]],"ltp":1.22,"tv":1439.75,"id":7414058}]}]}
{"op":"mcm","clk":"1006445072","pt":1580648545252,"mc":[{"id":"1.168224554","rc":[{"batb":[[0,7.2,6.72],[1,6.6,13.85],[2,5.7,19.67]],"batl":[[0,9,5.04]],"ltp":5.2,"tv":93.4,"id":7287690},{"batb":[[0,1.14,720.98],[2,1.09,248.63]],"batl":[[0,1.16,475.95]],"ltp":1.22,"tv":1439.75,"id":7414058}]}]}
{"op":"mcm","clk":"1006445330","pt":1580648547270,"mc":[{"id":"1.168224554","rc":[{"batb":[[2,1.09,1027.69]],"ltp":1.22,"tv":1439.75,"id":7414058}]}]}
{"op":"mcm","clk":"1006448614","pt":1580648572277,"mc":[{"id":"1.168224554","rc":[{"batb":[[0,5.7,19.67],[1,3.15,373.59],[2,1.01,15.51]],"ltp":5.2,"tv":93.4,"id":7287690},{"batb":[[0,1.09,1027.69],[1,1.01,15.51],[2,1.09,0]],"ltp":1.22,"tv":1439.75,"id":7414058}]}]}
{"op":"mcm","clk":"1006449041","pt":1580648575467,"mc":[{"id":"1.168224554","rc":[{"batb":[[0,1.1,940.09],[1,1.09,1256.46],[2,1.01,15.51]],"batl":[[0,1.19,315.91],[1,1.2,534.8]],"ltp":1.22,"tv":1439.75,"id":7414058}]}]}
{"op":"mcm","clk":"1006450250","pt":1580648584384,"mc":[{"id":"1.168224554","rc":[{"batb":[[0,1.09,1027.69],[1,1.01,15.51],[2,1.01,0]],"ltp":1.22,"tv":1439.75,"id":7414058}]}]}
{"op":"mcm","clk":"1006450366","pt":1580648585282,"mc":[{"id":"1.168224554","rc":[{"batb":[[1,1.01,15.51],[2,1.01,0]],"ltp":5.2,"tv":93.4,"id":7287690},{"batb":[[0,1.09,248.63]],"ltp":1.22,"tv":1439.75,"id":7414058}]}]}
{"op":"mcm","clk":"1006450635","pt":1580648587422,"mc":[{"id":"1.168224554","rc":[{"batl":[[0,11.5,3.36]],"ltp":5.2,"tv":93.4,"id":7287690},{"batb":[[0,1.1,940.09],[1,1.09,477.4],[2,1.01,15.51]],"batl":[[0,1.12,672.96],[1,1.13,468.8]],"ltp":1.22,"tv":1439.75,"id":7414058}]}]}
{"op":"mcm","clk":"1006450754","pt":1580648588297,"mc":[{"id":"1.168224554","rc":[{"batb":[[0,8.6,7.63],[1,6.8,12.9],[2,1.01,15.51]],"ltp":5.2,"tv":93.4,"id":7287690},{"batb":[[2,1.05,428.11]],"ltp":1.22,"tv":1439.75,"id":7414058}]}]}
{"op":"mcm","clk":"1006450827","pt":1580648588716,"mc":[{"id":"1.168224554","rc":[{"batb":[[2,3.5,371.08]],"ltp":5.2,"tv":93.4,"id":7287690},{"batb":[[2,1.06,955.61]],"ltp":1.22,"tv":1439.75,"id":7414058}]}]}
{"op":"mcm","clk":"1006452520","pt":1580648602206,"mc":[{"id":"1.168224554","rc":[{"batb":[[0,8.8,5.04],[1,8.6,7.63],[2,6.8,12.9]],"ltp":5.2,"tv":93.4,"id":7287690}]}]}
{"op":"mcm","clk":"1006453034","pt":1580648606447,"mc":[{"id":"1.168224554","rc":[{"batb":[[0,6.8,12.9],[1,3.5,371.08],[2,1.01,15.51]],"ltp":5.2,"tv":93.4,"id":7287690},{"batb":[[0,1.06,955.61],[1,1.05,428.11],[2,1.01,15.51]],"ltp":1.22,"tv":1439.75,"id":7414058}]}]}
{"op":"mcm","clk":"1006453364","pt":1580648609041,"mc":[{"id":"1.168224554","rc":[{"batb":[[0,1.06,1914.24],[1,1.05,682.69]],"batl":[[0,1.16,818.19],[1,1.17,285.77]],"ltp":1.22,"tv":1439.75,"id":7414058}]}]}
{"op":"mcm","clk":"1006453541","pt":1580648610350,"mc":[{"id":"1.168224554","rc":[{"batb":[[0,1.06,955.61],[1,1.05,428.11]],"ltp":1.22,"tv":1439.75,"id":7414058}]}]}
{"op":"mcm","clk":"1006453962","pt":1580648613433,"mc":[{"id":"1.168224554","rc":[{"batb":[[0,1.09,1177.49],[1,1.06,955.61],[2,1.05,428.11]],"batl":[[0,1.11,673.65],[1,1.12,478.32]],"ltp":1.22,"tv":1439.75,"id":7414058}]}]}
{"op":"mcm","clk":"1006454162","pt":1580648614899,"mc":[{"id":"1.168224554","rc":[{"batb":[[0,1.06,955.61],[1,1.05,428.11],[2,1.01,15.51]],"ltp":1.22,"tv":1439.75,"id":7414058}]}]}
{"op":"mcm","clk":"1006454586","pt":1580648617725,"mc":[{"id":"1.168224554","rc":[{"batb":[[0,1.06,1914.24],[1,1.05,682.69]],"batl":[[0,1.16,818.19],[1,1.17,285.77]],"ltp":1.22,"tv":1439.75,"id":7414058}]}]}
{"op":"mcm","clk":"1006456118","pt":1580648629464,"mc":[{"id":"1.168224554","rc":[{"batb":[[0,1.06,958.63]],"ltp":1.22,"tv":1439.75,"id":7414058}]}]}
{"op":"mcm","clk":"1006456349","pt":1580648631266,"mc":[{"id":"1.168224554","rc":[{"batl":[[0,1.07,395.07],[1,1.08,796.98]],"ltp":1.22,"tv":1439.75,"id":7414058}]}]}
{"op":"mcm","clk":"1006456451","pt":1580648632076,"mc":[{"id":"1.168224554","rc":[{"batb":[[0,12.5,7.79],[1,9.6,14.79],[2,3.5,371.08]],"ltp":5.2,"tv":93.4,"id":7287690},{"batb":[[2,1.02,889.89]],"ltp":1.22,"tv":1439.75,"id":7414058}]}]}
{"op":"mcm","clk":"1006456601","pt":1580648633261,"mc":[{"id":"1.168224554","rc":[{"batb":[[0,13.5,3.36],[1,12.5,7.79],[2,9.6,14.79]],"ltp":5.2,"tv":93.4,"id":7287690},{"batb":[[2,1.03,1571.88]],"batl":[[1,1.08,838.99]],"ltp":1.22,"tv":1439.75,"id":7414058}]}]}
{"op":"mcm","clk":"1006458602","pt":1580648648710,"mc":[{"id":"1.168224554","rc":[{"batb":[[1,9.6,14.79],[2,3.5,371.08]],"ltp":5.2,"tv":93.4,"id":7287690},{"batb":[[0,1.03,1571.88],[1,1.02,889.89],[2,1.01,15.51]],"batl":[[0,1.08,42.01],[1,1.08,0]],"ltp":1.22,"tv":1439.75,"id":7414058}]}]}
{"op":"mcm","clk":"1006458820","pt":1580648650324,"mc":[{"id":"1.168224554","rc":[{"batb":[[0,9.6,14.79],[1,3.5,371.08],[2,1.01,15.51]],"ltp":5.2,"tv":93.4,"id":7287690}]}]}
{"op":"mcm","clk":"1006458988","pt":1580648651392,"mc":[{"id":"1.168224554","rc":[{"batb":[[1,1.01,15.51],[2,1.01,0]],"ltp":5.2,"tv":93.4,"id":7287690},{"batb":[[0,1.03,193.62],[1,1.02,1952.67]],"batl":[[0,1.1,486.43],[1,1.11,674.22]],"ltp":1.22,"tv":1439.75,"id":7414058}]}]}
{"op":"mcm","clk":"1006459073","pt":1580648651938,"mc":[{"id":"1.168224554","rc":[{"batb":[[0,1.02,889.89],[1,1.01,15.51],[2,1.01,0]],"ltp":1.22,"tv":1439.75,"id":7414058}]}]}
{"op":"mcm","clk":"1006459716","pt":1580648656291,"mc":[{"id":"1.168224554","rc":[{"batb":[[0,1.05,1222.35],[1,1.02,889.89],[2,1.01,15.51]],"batl":[[0,1.07,1199.5]],"ltp":1.22,"tv":1439.75,"id":7414058}]}]}
{"op":"mcm","clk":"1006459975","pt":1580648657935,"mc":[{"id":"1.168224554","rc":[{"batb":[[0,1.02,889.89],[1,1.01,15.51],[2,1.01,0]],"ltp":1.22,"tv":1439.75,"id":7414058}]}]}
{"op":"mcm","clk":"1006460381","pt":1580648660919,"mc":[{"id":"1.168224554","rc":[{"batb":[[0,1.03,193.62],[1,1.02,1952.67],[2,1.01,15.51]],"batl":[[0,1.1,486.43],[1,1.11,674.22]],"ltp":1.22,"tv":1439.75,"id":7414058}]}]}
{"op":"mcm","clk":"1006462753","pt":1580648678247,"mc":[{"id":"1.168224554","rc":[{"batl":[[0,1.04,1234.93]],"ltp":1.22,"tv":1439.75,"id":7414058}]}]}
{"op":"mcm","clk":"1006462857","pt":1580648679219,"mc":[{"id":"1.168224554","rc":[{"batb":[[0,21,4.34],[1,15,5.27],[2,1.01,15.51]],"ltp":5.2,"tv":93.4,"id":7287690},{"batb":[[1,1.02,2120.71]],"ltp":1.22,"tv":1439.75,"id":7414058}]}]}
{"op":"mcm","clk":"1006463123","pt":1580648681340,"mc":[{"id":"1.168224554","rc":[{"batb":[[2,4.2,372.95]],"ltp":5.2,"tv":93.4,"id":7287690},{"batb":[[2,1.01,3892.94]],"ltp":1.22,"tv":1439.75,"id":7414058}]}]}
{"op":"mcm","clk":"1006465271","pt":1580648697162,"mc":[{"id":"1.168224554","rc":[{"batb":[[0,1.02,2120.71],[1,1.01,3892.94],[2,1.01,0]],"ltp":1.22,"tv":1439.75,"id":7414058}]}]}
{"op":"mcm","clk":"1006465672","pt":1580648700244,"mc":[{"id":"1.168224554","rc":[{"batb":[[0,1.02,2317.08]],"ltp":1.22,"tv":1439.75,"id":7414058}]}]}
{"op":"mcm","clk":"1006470261","pt":1580648733317,"mc":[{"id":"1.168224554","rc":[{"trd":[[1.04,6]],"batl":[[0,1.04,1231.93]],"ltp":1.04,"tv":1445.75,"id":7414058}],"tv":1539.15}]}
{"op":"mcm","clk":"1006473856","pt":1580648759258,"mc":[{"id":"1.168224554","rc":[{"trd":[[1.02,400.01]],"batb":[[0,1.02,2117.07]],"ltp":1.02,"tv":1845.76,"id":7414058}],"tv":1939.16}]}
{"op":"mcm","clk":"1006476109","pt":1580648775055,"mc":[{"id":"1.168224554","rc":[{"batb":[[0,15,5.27],[1,4.2,372.95],[2,1.01,15.51]],"ltp":5.2,"tv":93.4,"id":7287690},{"batb":[[0,1.02,755.55]],"ltp":1.02,"tv":1845.76,"id":7414058}]}]}
{"op":"mcm","clk":"1006476294","pt":1580648776387,"mc":[{"id":"1.168224554","rc":[{"batb":[[0,1.02,587.51]],"ltp":1.02,"tv":1845.76,"id":7414058}]}]}
{"op":"mcm","clk":"1006476560","pt":1580648778265,"mc":[{"id":"1.168224554","rc":[{"batb":[[0,16.5,4.64]],"ltp":5.2,"tv":93.4,"id":7287690},{"batb":[[1,1.01,4571.22]],"batl":[[0,1.06,1211.64]],"ltp":1.02,"tv":1845.76,"id":7414058}]}]}
{"op":"mcm","clk":"1006477273","pt":1580648783200,"mc":[{"id":"1.168224554","rc":[{"batb":[[1,1.01,693.79]],"ltp":1.02,"tv":1845.76,"id":7414058}]}]}
{"op":"mcm","clk":"1006477459","pt":1580648784386,"mc":[{"id":"1.168224554","rc":[{"batl":[[0,1.03,1246.92]],"ltp":1.02,"tv":1845.76,"id":7414058}]}]}
{"op":"mcm","clk":"1006477587","pt":1580648785299,"mc":[{"id":"1.168224554","rc":[{"batb":[[0,21,4.71]],"ltp":5.2,"tv":93.4,"id":7287690}]}]}
{"op":"mcm","clk":"1006477896","pt":1580648787391,"mc":[{"id":"1.168224554","rc":[{"batl":[[0,520,35.52]],"ltp":5.2,"tv":93.4,"id":7287690}]}]}
{"op":"mcm","clk":"1006478485","pt":1580648790976,"mc":[{"id":"1.168224554","rc":[{"batb":[[0,1.01,693.79],[1,1.01,0]],"ltp":1.02,"tv":1845.76,"id":7414058}]}]}
{"op":"mcm","clk":"1006478975","pt":1580648794292,"mc":[{"id":"1.168224554","rc":[{"batb":[[0,1.01,1287.13]],"batl":[[0,1.04,1234.93]],"ltp":1.02,"tv":1845.76,"id":7414058}]}]}
{"op":"mcm","clk":"1006479597","pt":1580648798295,"mc":[{"id":"1.168224554","rc":[{"batb":[[0,4.2,372.95],[1,1.01,15.51],[2,1.01,0]],"ltp":5.2,"tv":93.4,"id":7287690}]}]}
{"op":"mcm","clk":"1006479813","pt":1580648799904,"mc":[{"id":"1.168224554","rc":[{"batl":[[0,1.02,1259.15]],"ltp":1.02,"tv":1845.76,"id":7414058}]}]}
{"op":"mcm","clk":"1006481454","pt":1580648811120,"mc":[{"id":"1.168224554","rc":[{"trd":[[1.02,430.3]],"batl":[[0,1.02,1244.01]],"ltp":1.02,"tv":1876.04,"id":7414058}],"tv":1969.45}]}
{"op":"mcm","clk":"1006481673","pt":1580648812409,"mc":[{"id":"1.168224554","rc":[{"trd":[[1.01,104]],"batb":[[0,1.01,1235.13]],"ltp":1.01,"tv":1980.04,"id":7414058}],"tv":2073.44}]}
{"op":"mcm","clk":"1006482210","pt":1580648816231,"mc":[{"id":"1.168224554","rc":[{"batl":[[0,1.03,1246.92]],"ltp":1.01,"tv":1980.04,"id":7414058}]}]}
{"op":"mcm","clk":"1006483111","pt":1580648821346,"mc":[{"id":"1.168224554","rc":[{"batb":[[0,20,5.51],[1,4.2,372.95],[2,1.01,15.51]],"ltp":5.2,"tv":93.4,"id":7287690},{"batb":[[0,1.02,1020.43],[1,1.01,241.08]],"ltp":1.01,"tv":1980.04,"id":7414058}]}]}
{"op":"mcm","clk":"1006483289","pt":1580648822424,"mc":[{"id":"1.168224554","rc":[{"batl":[[0,520,35.52]],"ltp":5.2,"tv":93.4,"id":7287690}]}]}
{"op":"mcm","clk":"1006483848","pt":1580648825937,"mc":[{"id":"1.168224554","rc":[{"batb":[[0,1.02,966.8]],"ltp":1.01,"tv":1980.04,"id":7414058}]}]}
{"op":"mcm","clk":"1006484322","pt":1580648828838,"mc":[{"id":"1.168224554","rc":[{"batb":[[1,1.01,295.23]],"ltp":1.01,"tv":1980.04,"id":7414058}]}]}
{"op":"mcm","clk":"1006485201","pt":1580648834435,"mc":[{"id":"1.168224554","rc":[{"batb":[[0,1.01,295.23],[1,1.01,0]],"ltp":1.01,"tv":1980.04,"id":7414058}]}]}
{"op":"mcm","clk":"1006485635","pt":1580648837477,"mc":[{"id":"1.168224554","rc":[{"batb":[[0,1.01,1271.62]],"ltp":1.01,"tv":1980.04,"id":7414058}]}]}
{"op":"mcm","clk":"1006485772","pt":1580648838453,"mc":[{"id":"1.168224554","rc":[{"batb":[[0,4.2,372.95],[1,1.01,15.51],[2,1.01,0]],"ltp":5.2,"tv":93.4,"id":7287690}]}]}
{"op":"mcm","clk":"1006486023","pt":1580648840363,"mc":[{"id":"1.168224554","rc":[{"batl":[[0,1.02,1259.15]],"ltp":1.01,"tv":1980.04,"id":7414058}]}]}
{"op":"mcm","clk":"1006487689","pt":1580648852095,"mc":[{"id":"1.168224554","rc":[{"batl":[[0,1.03,1246.92]],"ltp":1.01,"tv":1980.04,"id":7414058}]}]}
{"op":"mcm","clk":"1006488932","pt":1580648860379,"mc":[{"id":"1.168224554","rc":[{"batl":[[0,1.01,655.12],[1,1.02,610.35]],"ltp":1.01,"tv":1980.04,"id":7414058}]}]}
{"op":"mcm","clk":"1006490286","pt":1580648869901,"mc":[{"id":"1.168224554","rc":[{"batl":[[0,1.01,755.12]],"ltp":1.01,"tv":1980.04,"id":7414058}]}]}
{"op":"mcm","clk":"1006492226","pt":1580648883146,"mc":[{"id":"1.168224554","rc":[{"batl":[[0,1.01,100]],"ltp":1.01,"tv":1980.04,"id":7414058}]}]}
{"op":"mcm","clk":"1006492683","pt":1580648886323,"mc":[{"id":"1.168224554","rc":[{"batl":[[1,1.02,0]],"ltp":1.01,"tv":1980.04,"id":7414058}]}]}
{"op":"mcm","clk":"1006493268","pt":1580648890259,"mc":[{"id":"1.168224554","rc":[{"batl":[[0,1.01,1371.52]],"ltp":1.01,"tv":1980.04,"id":7414058}]}]}
{"op":"mcm","clk":"1006493472","pt":1580648891360,"mc":[{"id":"1.168224554","rc":[{"batl":[[0,1.01,100]],"ltp":1.01,"tv":1980.04,"id":7414058}]}]}
{"op":"mcm","clk":"1006493978","pt":1580648894819,"mc":[{"id":"1.168224554","rc":[{"batl":[[1,1.02,1259.05]],"ltp":1.01,"tv":1980.04,"id":7414058}]}]}
{"op":"mcm","clk":"1006494270","pt":1580648897042,"mc":[{"id":"1.168224554","rc":[{"batl":[[1,1.02,0]],"ltp":1.01,"tv":1980.04,"id":7414058}]}]}
{"op":"mcm","clk":"1006494798","pt":1580648900444,"mc":[{"id":"1.168224554","rc":[{"batl":[[0,1.01,1371.52]],"ltp":1.01,"tv":1980.04,"id":7414058}]}]}
{"op":"mcm","clk":"1006494899","pt":1580648901362,"mc":[{"id":"1.168224554","rc":[{"batl":[[0,1.01,1413.53]],"ltp":1.01,"tv":1980.04,"id":7414058}]}]}
{"op":"mcm","clk":"1006496182","pt":1580648910960,"mc":[{"id":"1.168224554","rc":[{"batl":[[0,1.01,1172.92]],"ltp":1.01,"tv":1980.04,"id":7414058}]}]}
{"op":"mcm","clk":"1006496405","pt":1580648912447,"mc":[{"id":"1.168224554","rc":[{"batb":[[0,1.01,15.51],[1,1.01,0]],"ltp":5.2,"tv":93.4,"id":7287690},{"batl":[[0,1.01,1130.91]],"ltp":1.01,"tv":1980.04,"id":7414058}]}]}
{"op":"mcm","clk":"1006496660","pt":1580648914274,"mc":[{"id":"1.168224554","rc":[{"batl":[[1,1.02,238.24]],"ltp":1.01,"tv":1980.04,"id":7414058}]}]}
{"op":"mcm","clk":"1006496740","pt":1580648914875,"mc":[{"id":"1.168224554","rc":[{"batl":[[1,1.02,0]],"ltp":1.01,"tv":1980.04,"id":7414058}]}]}
{"op":"mcm","clk":"1006497168","pt":1580648918278,"mc":[{"id":"1.168224554","rc":[{"batl":[[0,1.01,1371.52]],"ltp":1.01,"tv":1980.04,"id":7414058}]}]}
{"op":"mcm","clk":"1006497308","pt":1580648919300,"mc":[{"id":"1.168224554","rc":[{"batb":[[0,4.7,374.21],[1,1.01,15.51]],"ltp":5.2,"tv":93.4,"id":7287690}]}]}
{"op":"mcm","clk":"1006497396","pt":1580648919899,"mc":[{"id":"1.168224554","rc":[{"batl":[[0,1.01,1130.91]],"ltp":1.01,"tv":1980.04,"id":7414058}]}]}
{"op":"mcm","clk":"1006497599","pt":1580648921396,"mc":[{"id":"1.168224554","rc":[{"batb":[[0,1.01,15.51],[1,1.01,0]],"ltp":5.2,"tv":93.4,"id":7287690}]}]}
{"op":"mcm","clk":"1006497788","pt":1580648922785,"mc":[{"id":"1.168224554","rc":[{"batl":[[1,1.02,238.24]],"ltp":1.01,"tv":1980.04,"id":7414058}]}]}
{"op":"mcm","clk":"1006499375","pt":1580648934008,"mc":[{"id":"1.168224554","rc":[{"batb":[[0,4.6,373.8],[1,1.01,15.51]],"ltp":5.2,"tv":93.4,"id":7287690}]}]}
{"op":"mcm","clk":"1006501435","pt":1580648948438,"mc":[{"id":"1.168224554","rc":[{"batl":[[0,1.01,100]],"ltp":1.01,"tv":1980.04,"id":7414058}]}]}
{"op":"mcm","clk":"1006501795","pt":1580648951229,"mc":[{"id":"1.168224554","rc":[{"batl":[[1,1.02,1259.05]],"ltp":1.01,"tv":1980.04,"id":7414058}]}]}
{"op":"mcm","clk":"1006502159","pt":1580648953841,"mc":[{"id":"1.168224554","rc":[{"batl":[[1,1.02,238.24]],"ltp":1.01,"tv":1980.04,"id":7414058}]}]}
{"op":"mcm","clk":"1006502646","pt":1580648957408,"mc":[{"id":"1.168224554","rc":[{"trd":[[1.01,304]],"batb":[[0,1.01,1171.52]],"batl":[[0,1.02,1259.05],[1,1.02,0]],"ltp":1.01,"tv":2180.04,"id":7414058}],"tv":2273.44}]}
{"op":"mcm","clk":"1006503002","pt":1580648960036,"mc":[{"id":"1.168224554","rc":[{"batb":[[0,1.01,1250.14]],"ltp":1.01,"tv":2180.04,"id":7414058}]}]}
{"op":"mcm","clk":"1006504460","pt":1580648970420,"mc":[{"id":"1.168224554","rc":[{"batb":[[0,1.01,574.15]],"ltp":1.01,"tv":2180.04,"id":7414058}]}]}
{"op":"mcm","clk":"1006505545","pt":1580648978332,"mc":[{"id":"1.168224554","rc":[{"batl":[[0,1.01,1271.52]],"ltp":1.01,"tv":2180.04,"id":7414058}]}]}
{"op":"mcm","clk":"1006507714","pt":1580648993945,"mc":[{"id":"1.168224554","rc":[{"batb":[[0,1.01,15.51],[1,1.01,0]],"ltp":5.2,"tv":93.4,"id":7287690}]}]}
{"op":"mcm","clk":"1006507908","pt":1580648995405,"mc":[{"id":"1.168224554","rc":[{"batl":[[0,1.02,1259.05]],"ltp":1.01,"tv":2180.04,"id":7414058}]}]}
{"op":"mcm","clk":"1006508494","pt":1580648999382,"mc":[{"id":"1.168224554","rc":[{"batl":[[0,1.01,1271.52]],"ltp":1.01,"tv":2180.04,"id":7414058}]}]}
{"op":"mcm","clk":"1006508736","pt":1580649001302,"mc":[{"id":"1.168224554","rc":[{"batb":[[0,4.7,367.67],[1,1.01,15.51]],"ltp":5.2,"tv":93.4,"id":7287690}]}]}
{"op":"mcm","clk":"1006508944","pt":1580649002770,"mc":[{"id":"1.168224554","rc":[{"batb":[[0,1.01,15.51],[1,1.01,0]],"ltp":5.2,"tv":93.4,"id":7287690}]}]}
{"op":"mcm","clk":"1006509217","pt":1580649004695,"mc":[{"id":"1.168224554","rc":[{"batl":[[0,1.02,1259.05]],"ltp":1.01,"tv":2180.04,"id":7414058}]}]}
{"op":"mcm","clk":"1006510461","pt":1580649013302,"mc":[{"id":"1.168224554","rc":[{"batb":[[0,1.01,1271.52]],"ltp":1.01,"tv":2180.04,"id":7414058}]}]}
{"op":"mcm","clk":"1006510802","pt":1580649015721,"mc":[{"id":"1.168224554","rc":[{"batb":[[0,4.6,368.39],[1,1.01,15.51]],"ltp":5.2,"tv":93.4,"id":7287690}]}]}
{"op":"mcm","clk":"1006515353","pt":1580649044349,"mc":[{"id":"1.168224554","rc":[{"batl":[[0,1.01,1271.52]],"ltp":1.01,"tv":2180.04,"id":7414058}]}]}
{"op":"mcm","clk":"1006517185","pt":1580649057179,"mc":[{"id":"1.168224554","rc":[{"batb":[[0,1.01,15.51],[1,1.01,0]],"ltp":5.2,"tv":93.4,"id":7287690}]}]}
{"op":"mcm","clk":"1006517359","pt":1580649058358,"mc":[{"id":"1.168224554","rc":[{"batl":[[0,1.02,1259.05]],"ltp":1.01,"tv":2180.04,"id":7414058}]}]}
{"op":"mcm","clk":"1006517985","pt":1580649062475,"mc":[{"id":"1.168224554","rc":[{"batl":[[0,1.01,1271.52]],"ltp":1.01,"tv":2180.04,"id":7414058}]}]}
{"op":"mcm","clk":"1006518757","pt":1580649067361,"mc":[{"id":"1.168224554","rc":[{"batl":[[0,1.02,1259.05]],"ltp":1.01,"tv":2180.04,"id":7414058}]}]}
{"op":"mcm","clk":"1006520266","pt":1580649077390,"mc":[{"id":"1.168224554","rc":[{"batl":[[0,1.01,1271.52]],"ltp":1.01,"tv":2180.04,"id":7414058}]}]}
{"op":"mcm","clk":"1006520552","pt":1580649079477,"mc":[{"id":"1.168224554","rc":[{"batb":[[0,4.7,374.21],[1,1.01,15.51]],"ltp":5.2,"tv":93.4,"id":7287690}]}]}
{"op":"mcm","clk":"1006523170","pt":1580649097321,"mc":[{"id":"1.168224554","rc":[{"batb":[[0,1.01,15.51],[1,1.01,0]],"ltp":5.2,"tv":93.4,"id":7287690}]}]}
{"op":"mcm","clk":"1006524271","pt":1580649104304,"mc":[{"id":"1.168224554","rc":[{"batb":[[0,4.8,367.63],[1,1.01,15.51]],"ltp":5.2,"tv":93.4,"id":7287690}]}]}
{"op":"mcm","clk":"1006524569","pt":1580649106328,"mc":[{"id":"1.168224554","rc":[{"batb":[[0,1.01,15.51],[1,1.01,0]],"ltp":5.2,"tv":93.4,"id":7287690}]}]}
{"op":"mcm","clk":"1006527288","pt":1580649122464,"mc":[{"id":"1.168224554","rc":[{"batb":[[0,4.7,367.67],[1,1.01,15.51]],"ltp":5.2,"tv":93.4,"id":7287690}]}]}
{"op":"mcm","clk":"1006530342","pt":1580649140359,"mc":[{"id":"1.168224554","rc":[{"batb":[[0,1.01,15.51],[1,1.01,0]],"ltp":5.2,"tv":93.4,"id":7287690},{"batl":[[0,1.02,1259.05]],"ltp":1.01,"tv":2180.04,"id":7414058}]}]}
{"op":"mcm","clk":"1006532579","pt":1580649156285,"mc":[{"id":"1.168224554","rc":[{"batb":[[0,1.01,1271.52]],"ltp":1.01,"tv":2180.04,"id":7414058}]}]}
{"op":"mcm","clk":"1006532779","pt":1580649157793,"mc":[{"id":"1.168224554","rc":[{"batb":[[0,4.6,368.39],[1,1.01,15.51]],"ltp":5.2,"tv":93.4,"id":7287690}]}]}
{"op":"mcm","clk":"1006535332","pt":1580649175410,"mc":[{"id":"1.168224554","rc":[{"batb":[[0,1.01,711.53]],"ltp":1.01,"tv":2180.04,"id":7414058}]}]}
{"op":"mcm","clk":"1006536596","pt":1580649184093,"mc":[{"id":"1.168224554","rc":[{"batl":[[0,1.01,500],[1,1.02,1259.05]],"ltp":1.01,"tv":2180.04,"id":7414058}]}]}
{"op":"mcm","clk":"1006538340","pt":1580649195230,"mc":[{"id":"1.168224554","rc":[{"batl":[[1,1.02,0]],"ltp":1.01,"tv":2180.04,"id":7414058}]}]}
{"op":"mcm","clk":"1006538761","pt":1580649198429,"mc":[{"id":"1.168224554","rc":[{"batl":[[0,1.01,1771.52]],"ltp":1.01,"tv":2180.04,"id":7414058}]}]}
{"op":"mcm","clk":"1006541544","pt":1580649216460,"mc":[{"id":"1.168224554","rc":[{"batl":[[0,1.01,500]],"ltp":1.01,"tv":2180.04,"id":7414058}]}]}
{"op":"mcm","clk":"1006541609","pt":1580649216887,"mc":[{"id":"1.168224554","rc":[{"batb":[[0,1.01,15.51],[1,1.01,0]],"ltp":5.2,"tv":93.4,"id":7287690}]}]}
{"op":"mcm","clk":"1006541883","pt":1580649218456,"mc":[{"id":"1.168224554","rc":[{"batl":[[1,1.02,1259.05]],"ltp":1.01,"tv":2180.04,"id":7414058}]}]}
{"op":"mcm","clk":"1006543770","pt":1580649230447,"mc":[{"id":"1.168224554","rc":[{"trd":[[1.01,1304]],"batb":[[0,1.01,754.51]],"batl":[[0,1.02,1259.05],[1,1.02,0]],"ltp":1.01,"tv":3180.04,"id":7414058}],"tv":3273.44}]}
{"op":"mcm","clk":"1006544073","pt":1580649232347,"mc":[{"id":"1.168224554","rc":[{"batb":[[0,4.6,368.39],[1,1.01,15.51]],"ltp":5.2,"tv":93.4,"id":7287690}]}]}
{"op":"mcm","clk":"1006544186","pt":1580649233168,"mc":[{"id":"1.168224554","rc":[{"batb":[[0,1.01,1071.28]],"ltp":1.01,"tv":3180.04,"id":7414058}]}]}
{"op":"mcm","clk":"1006546956","pt":1580649249895,"mc":[{"id":"1.168224554","rc":[{"batl":[[0,1.01,50],[1,1.02,1259.05]],"ltp":1.01,"tv":3180.04,"id":7414058}]}]}
{"op":"mcm","clk":"1006548038","pt":1580649256389,"mc":[{"id":"1.168224554","rc":[{"batb":[[0,27,3.52],[1,4.6,368.39],[2,1.01,15.51]],"ltp":5.2,"tv":93.4,"id":7287690},{"trd":[[1.01,1404]],"batb":[[0,1.01,1221.52]],"batl":[[0,1.02,1259.05],[1,1.02,0]],"ltp":1.01,"tv":3280.04,"id":7414058}],"tv":3373.44}]}
{"op":"mcm","clk":"1006548474","pt":1580649259108,"mc":[{"id":"1.168224554","rc":[{"batb":[[0,1.01,1271.52]],"ltp":1.01,"tv":3280.04,"id":7414058}]}]}
{"op":"mcm","clk":"1006550609","pt":1580649273108,"mc":[{"id":"1.168224554","rc":[{"trd":[[1.01,3404]],"batb":[[0,1.01,271.52]],"ltp":1.01,"tv":5280.04,"id":7414058}],"tv":5373.44}]}
{"op":"mcm","clk":"1006551145","pt":1580649276631,"mc":[{"id":"1.168224554","rc":[{"batb":[[0,1.01,1271.52]],"ltp":1.01,"tv":5280.04,"id":7414058}]}]}
{"op":"mcm","clk":"1006552731","pt":1580649286139,"mc":[{"id":"1.168224554","rc":[{"batl":[[1,1000,3.04]],"ltp":1.01,"tv":5280.04,"id":7414058}]}]}
{"op":"mcm","clk":"1006552867","pt":1580649286959,"mc":[{"id":"1.168224554","rc":[{"batl":[[1,1000,0]],"ltp":1.01,"tv":5280.04,"id":7414058}]}]}
{"op":"mcm","clk":"1006553356","pt":1580649290079,"mc":[{"id":"1.168224554","rc":[{"trd":[[1.01,3404.03]],"batb":[[0,1.01,1271.5]],"ltp":1.01,"tv":5280.08,"id":7414058}],"tv":5373.48}]}
{"op":"mcm","clk":"1006561219","pt":1580649343332,"mc":[{"id":"1.168224554","rc":[{"batb":[[0,1.01,1271.52]],"ltp":1.01,"tv":5280.08,"id":7414058}]}]}
{"op":"mcm","clk":"1006561799","pt":1580649347404,"mc":[{"id":"1.168224554","rc":[{"batb":[[0,1.01,0.02]],"ltp":1.01,"tv":5280.08,"id":7414058}]}]}
{"op":"mcm","clk":"1006562062","pt":1580649349424,"mc":[{"id":"1.168224554","rc":[{"batb":[[1,1.01,15.51],[2,1.01,0]],"ltp":5.2,"tv":93.4,"id":7287690}]}]}
{"op":"mcm","clk":"1006562745","pt":1580649353216,"mc":[{"id":"1.168224554","rc":[{"batb":[[0,1.01,1271.54]],"batl":[[0,1.02,1259.05]],"ltp":1.01,"tv":5280.08,"id":7414058}]}]}
{"op":"mcm","clk":"1006562956","pt":1580649354436,"mc":[{"id":"1.168224554","rc":[{"batb":[[0,1.01,0.02]],"ltp":1.01,"tv":5280.08,"id":7414058}]}]}
{"op":"mcm","clk":"1006562974","pt":1580649354543,"mc":[{"id":"1.168224554","rc":[{"batb":[[1,4.5,371.06],[2,1.01,15.51]],"ltp":5.2,"tv":93.4,"id":7287690}]}]}
{"op":"mcm","clk":"1006563371","pt":1580649357342,"mc":[{"id":"1.168224554","rc":[{"batb":[[1,1.01,15.51],[2,1.01,0]],"ltp":5.2,"tv":93.4,"id":7287690},{"batl":[[0,1.03,1246.83]],"ltp":1.01,"tv":5280.08,"id":7414058}]}]}
{"op":"mcm","clk":"1006563946","pt":1580649361026,"mc":[{"id":"1.168224554","rc":[{"trd":[[1.01,3404.07]],"batl":[[0,1.01,1271.5]],"ltp":1.01,"tv":5280.11,"id":7414058}],"tv":5373.52}]}
{"op":"mcm","clk":"1006564068","pt":1580649361842,"mc":[{"id":"1.168224554","rc":[{"batb":[[0,30,2.95]],"ltp":5.2,"tv":93.4,"id":7287690}]}]}
{"op":"mcm","clk":"1006564428","pt":1580649364450,"mc":[{"id":"1.168224554","rc":[{"batb":[[1,4.7,367.67],[2,1.01,15.51]],"ltp":5.2,"tv":93.4,"id":7287690},{"batl":[[0,1.01,1313.51]],"ltp":1.01,"tv":5280.11,"id":7414058}]}]}
{"op":"mcm","clk":"1006566478","pt":1580649376572,"mc":[{"id":"1.168224554","rc":[{"batb":[[1,1.01,15.51],[2,1.01,0]],"ltp":5.2,"tv":93.4,"id":7287690}]}]}
{"op":"mcm","clk":"1006567324","pt":1580649381153,"mc":[{"id":"1.168224554","rc":[{"batl":[[0,1.01,1271.52]],"ltp":1.01,"tv":5280.11,"id":7414058}]}]}
{"op":"mcm","clk":"1006567585","pt":1580649383183,"mc":[{"id":"1.168224554","rc":[{"batb":[[1,4.6,373.8],[2,1.01,15.51]],"ltp":5.2,"tv":93.4,"id":7287690}]}]}
{"op":"mcm","clk":"1006567788","pt":1580649384569,"mc":[{"id":"1.168224554","rc":[{"batb":[[1,1.01,15.51],[2,1.01,0]],"ltp":5.2,"tv":93.4,"id":7287690}]}]}
{"op":"mcm","clk":"1006568081","pt":1580649386378,"mc":[{"id":"1.168224554","rc":[{"batl":[[0,1.02,1259.05]],"ltp":1.01,"tv":5280.11,"id":7414058}]}]}
{"op":"mcm","clk":"1006568936","pt":1580649392095,"mc":[{"id":"1.168224554","rc":[{"batb":[[0,1.01,1271.52]],"ltp":1.01,"tv":5280.11,"id":7414058}]}]}
{"op":"mcm","clk":"1006569052","pt":1580649392892,"mc":[{"id":"1.168224554","rc":[{"batb":[[1,23,3.27],[2,4.5,371.06]],"ltp":5.2,"tv":93.4,"id":7287690}]}]}
{"op":"mcm","clk":"1006570751","pt":1580649404376,"mc":[{"id":"1.168224554","rc":[{"batb":[[0,23,3.27],[1,4.5,371.06],[2,1.01,15.51]],"ltp":5.2,"tv":93.4,"id":7287690}]}]}
{"op":"mcm","clk":"1006570818","pt":1580649404918,"mc":[{"id":"1.168224554","rc":[{"batb":[[1,1.01,15.51],[2,1.01,0]],"ltp":5.2,"tv":93.4,"id":7287690}]}]}
{"op":"mcm","clk":"1006571105","pt":1580649407064,"mc":[{"id":"1.168224554","rc":[{"batl":[[0,1.03,322.24],[1,1.04,915.69]],"ltp":1.01,"tv":5280.11,"id":7414058}]}]}
{"op":"mcm","clk":"1006571840","pt":1580649412407,"mc":[{"id":"1.168224554","rc":[{"batb":[[0,1.01,1271.52]],"batl":[[0,1.02,1259.05]],"ltp":1.01,"tv":5280.11,"id":7414058}]}]}
{"op":"mcm","clk":"1006573033","pt":1580649420446,"mc":[{"id":"1.168224554","rc":[{"batl":[[0,1.03,322.24],[1,1.04,915.69]],"ltp":1.01,"tv":5280.11,"id":7414058}]}]}
{"op":"mcm","clk":"1006573339","pt":1580649422420,"mc":[{"id":"1.168224554","rc":[{"batb":[[0,1.02,1259.05]],"ltp":1.01,"tv":5280.11,"id":7414058}]}]}
{"op":"mcm","clk":"1006573504","pt":1580649423233,"mc":[{"id":"1.168224554","rc":[{"batb":[[1,15.5,5.19],[2,1.01,15.51]],"ltp":5.2,"tv":93.4,"id":7287690},{"batb":[[0,1.02,2246.59]],"ltp":1.01,"tv":5280.11,"id":7414058}]}]}
{"op":"mcm","clk":"1006573633","pt":1580649424132,"mc":[{"id":"1.168224554","rc":[{"batb":[[2,4.3,371.85]],"batl":[[0,160,37.09]],"ltp":5.2,"tv":93.4,"id":7287690},{"batl":[[0,1.03,364.25]],"ltp":1.01,"tv":5280.11,"id":7414058}]}]}
{"op":"mcm","clk":"1006575146","pt":1580649434408,"mc":[{"id":"1.168224554","rc":[{"batb":[[0,15.5,5.19],[1,4.3,371.85],[2,1.01,15.51]],"ltp":5.2,"tv":93.4,"id":7287690},{"batl":[[0,1.03,42.01],[1,1.04,0]],"ltp":1.01,"tv":5280.11,"id":7414058}]}]}
{"op":"mcm","clk":"1006575547","pt":1580649437419,"mc":[{"id":"1.168224554","rc":[{"batb":[[0,1.01,1271.52]],"batl":[[0,1.06,1211.54]],"ltp":1.01,"tv":5280.11,"id":7414058}]}]}
{"op":"mcm","clk":"1006576268","pt":1580649443128,"mc":[{"id":"1.168224554","rc":[{"batl":[[0,1.02,1259.05]],"ltp":1.01,"tv":5280.11,"id":7414058}]}]}
{"op":"mcm","clk":"1006576380","pt":1580649444044,"mc":[{"id":"1.168224554","rc":[{"batb":[[0,20,5.82]],"ltp":5.2,"tv":93.4,"id":7287690},{"batb":[[0,1.01,1439.56]],"batl":[[0,1.02,1301.06]],"ltp":1.01,"tv":5280.11,"id":7414058}]}]}
{"op":"mcm","clk":"1006578625","pt":1580649459469,"mc":[{"id":"1.168224554","rc":[{"batb":[[0,1.01,168.04]],"batl":[[0,1.02,42.01]],"ltp":1.01,"tv":5280.11,"id":7414058}]}]}
{"op":"mcm","clk":"1006578864","pt":1580649461270,"mc":[{"id":"1.168224554","rc":[{"batb":[[1,1.01,15.51],[2,1.01,0]],"ltp":5.2,"tv":93.4,"id":7287690}]}]}
{"op":"mcm","clk":"1006579006","pt":1580649462560,"mc":[{"id":"1.168224554","rc":[{"batl":[[0,1.04,881],[1,1.05,350.47]],"ltp":1.01,"tv":5280.11,"id":7414058}]}]}
{"op":"mcm","clk":"1006580599","pt":1580649473766,"mc":[{"id":"1.168224554","rc":[{"batb":[[0,1.01,15.51],[1,1.01,0]],"ltp":5.2,"tv":93.4,"id":7287690}]}]}
{"op":"mcm","clk":"1006580864","pt":1580649476005,"mc":[{"id":"1.168224554","rc":[{"batl":[[0,1.01,1271.52]],"ltp":1.01,"tv":5280.11,"id":7414058}]}]}
{"op":"mcm","clk":"1006581213","pt":1580649478475,"mc":[{"id":"1.168224554","rc":[{"batb":[[0,4.7,374.68],[1,1.01,15.51]],"ltp":5.2,"tv":93.4,"id":7287690}]}]}
{"op":"mcm","clk":"1006583856","pt":1580649496529,"mc":[{"id":"1.168224554","rc":[{"batb":[[0,1.01,15.51],[1,1.01,0]],"ltp":5.2,"tv":93.4,"id":7287690}]}]}
{"op":"mcm","clk":"1006584531","pt":1580649501405,"mc":[{"id":"1.168224554","rc":[{"batl":[[0,1.01,1271.52]],"ltp":1.01,"tv":5280.11,"id":7414058}]}]}
{"op":"mcm","clk":"1006584918","pt":1580649504312,"mc":[{"id":"1.168224554","rc":[{"batb":[[0,4.7,368.17],[1,1.01,15.51]],"ltp":5.2,"tv":93.4,"id":7287690}]}]}
{"op":"mcm","clk":"1006585315","pt":1580649507214,"mc":[{"id":"1.168224554","rc":[{"batb":[[0,1.01,15.51],[1,1.01,0]],"ltp":5.2,"tv":93.4,"id":7287690},{"batl":[[0,1.02,1259.05]],"ltp":1.01,"tv":5280.11,"id":7414058}]}]}
{"op":"mcm","clk":"1006586188","pt":1580649513413,"mc":[{"id":"1.168224554","marketDefinition":{"bspMarket":false,"turnInPlayEnabled":true,"persistenceEnabled":true,"marketBaseRate":5.0,"eventId":"29681742","eventTypeId":"2","numberOfWinners":1,"bettingType":"ODDS","marketType":"SET_WINNER","marketTime":"2020-02-02T12:28:00.000Z","suspendTime":"2020-02-02T12:28:00.000Z","bspReconciled":false,"complete":true,"inPlay":true,"crossMatching":true,"runnersVoidable":false,"numberOfActiveRunners":2,"betDelay":3,"status":"SUSPENDED","runners":[{"status":"ACTIVE","sortPriority":1,"id":7414058,"name":"Damir Dzumhur"},{"status":"ACTIVE","sortPriority":2,"id":7287690,"name":"Quentin Halys"}],"regulators":["MR_INT"],"countryCode":"FR","discountAllowed":true,"timezone":"UTC","openDate":"2020-02-02T12:28:00.000Z","version":3148899076,"name":"Set 1 Winner","eventName":"Dzumhur v Halys"}}]}
{"op":"mcm","clk":"1006590802","pt":1580649546267,"mc":[{"id":"1.168224554","tv":0.0}]}
{"op":"mcm","clk":"1006590989","pt":1580649547493,"mc":[{"id":"1.168224554","marketDefinition":{"bspMarket":false,"turnInPlayEnabled":true,"persistenceEnabled":true,"marketBaseRate":5.0,"eventId":"29681742","eventTypeId":"2","numberOfWinners":1,"bettingType":"ODDS","marketType":"SET_WINNER","marketTime":"2020-02-02T12:28:00.000Z","suspendTime":"2020-02-02T12:28:00.000Z","bspReconciled":false,"complete":true,"inPlay":true,"crossMatching":false,"runnersVoidable":false,"numberOfActiveRunners":0,"betDelay":3,"status":"CLOSED","settledTime":"2020-02-02T13:19:05.000Z","runners":[{"status":"WINNER","sortPriority":1,"id":7414058,"name":"Damir Dzumhur"},{"status":"LOSER","sortPriority":2,"id":7287690,"name":"Quentin Halys"}],"regulators":["MR_INT"],"countryCode":"FR","discountAllowed":true,"timezone":"UTC","openDate":"2020-02-02T12:28:00.000Z","version":3148899627,"name":"Set 1 Winner","eventName":"Dzumhur v Halys"}}]}
