{"op":"mcm","clk":"1001179394","pt":1580585281138,"mc":[{"id":"1.168224552","marketDefinition":{"bspMarket":false,"turnInPlayEnabled":true,"persistenceEnabled":true,"marketBaseRate":5.0,"eventId":"29681742","eventTypeId":"2","numberOfWinners":1,"bettingType":"ODDS","marketType":"MATCH_ODDS","marketTime":"2020-02-02T09:00:00.000Z","suspendTime":"2020-02-02T09:00:00.000Z","bspReconciled":false,"complete":true,"inPlay":false,"crossMatching":false,"runnersVoidable":false,"numberOfActiveRunners":2,"betDelay":0,"status":"OPEN","runners":[{"status":"ACTIVE","sortPriority":1,"id":7414058,"name":"Damir Dzumhur"},{"status":"ACTIVE","sortPriority":2,"id":7287690,"name":"Quentin Halys"}],"regulators":["MR_INT"],"countryCode":"FR","discountAllowed":false,"timezone":"UTC","openDate":"2020-02-02T09:00:00.000Z","version":3147098922,"name":"Match Odds","eventName":"Dzumhur v Halys"},"rc":[{"batb":[[0,1.02,3786.16],[1,1.01,4069.07]],"ltp":0.0,"tv":0.0,"id":7287690},{"batb":[[0,1.05,152.2],[1,1.04,168.86],[2,1.03,190.07]],"ltp":0.0,"tv":0.0,"id":7414058}]}]}
{"op":"mcm","clk":"1001179667","pt":1580585282545,"mc":[{"id":"1.168224552","marketDefinition":{"bspMarket":false,"turnInPlayEnabled":true,"persistenceEnabled":true,"marketBaseRate":5.0,"eventId":"29681742","eventTypeId":"2","numberOfWinners":1,"bettingType":"ODDS","marketType":"MATCH_ODDS","marketTime":"2020-02-02T09:00:00.000Z","suspendTime":"2020-02-02T09:00:00.000Z","bspReconciled":false,"complete":true,"inPlay":false,"crossMatching":false,"runnersVoidable":false,"numberOfActiveRunners":2,"betDelay":0,"status":"OPEN","runners":[{"status":"ACTIVE","sortPriority":1,"id":7414058,"name":"Damir Dzumhur"},{"status":"ACTIVE","sortPriority":2,"id":7287690,"name":"Quentin Halys"}],"regulators":["MR_INT"],"countryCode":"FR","discountAllowed":false,"timezone":"UTC","openDate":"2020-02-02T09:00:00.000Z","version":3147098922,"name":"Match Odds","eventName":"Dzumhur v Halys"}}]}
{"op":"mcm","clk":"1001179866","pt":1580585283504,"mc":[{"id":"1.168224552","marketDefinition":{"bspMarket":false,"turnInPlayEnabled":true,"persistenceEnabled":true,"marketBaseRate":5.0,"eventId":"29681742","eventTypeId":"2","numberOfWinners":1,"bettingType":"ODDS","marketType":"MATCH_ODDS","marketTime":"2020-02-02T09:00:00.000Z","suspendTime":"2020-02-02T09:00:00.000Z","bspReconciled":false,"complete":true,"inPlay":false,"crossMatching":false,"runnersVoidable":false,"numberOfActiveRunners":2,"betDelay":0,"status":"OPEN","runners":[{"status":"ACTIVE","sortPriority":1,"id":7414058,"name":"Damir Dzumhur"},{"status":"ACTIVE","sortPriority":2,"id":7287690,"name":"Quentin Halys"}],"regulators":["MR_INT"],"countryCode":"FR","discountAllowed":true,"timezone":"UTC","openDate":"2020-02-02T09:00:00.000Z","version":3147098922,"name":"Match Odds","eventName":"Dzumhur v Halys"}}]}
{"op":"mcm","clk":"1001197212","pt":1580585379432,"mc":[{"id":"1.168224552","rc":[{"batb":[[1,1.01,4369.07]],"ltp":0.0,"tv":0.0,"id":7287690}]}]}
{"op":"mcm","clk":"1001198012","pt":1580585383645,"mc":[{"id":"1.168224552","rc":[{"batb":[[1,1.01,4069.07]],"ltp":0.0,"tv":0.0,"id":7287690}]}]}
{"op":"mcm","clk":"1001204976","pt":1580585419389,"mc":[{"id":"1.168224552","rc":[{"batb":[[1,1.01,4059.07]],"ltp":0.0,"tv":0.0,"id":7287690}]}]}
{"op":"mcm","clk":"1001222203","pt":1580585513427,"mc":[{"id":"1.168224552","marketDefinition":{"bspMarket":false,"turnInPlayEnabled":true,"persistenceEnabled":true,"marketBaseRate":5.0,"eventId":"29681742","eventTypeId":"2","numberOfWinners":1,"bettingType":"ODDS","marketType":"MATCH_ODDS","marketTime":"2020-02-02T13:30:00.000Z","suspendTime":"2020-02-02T13:30:00.000Z","bspReconciled":false,"complete":true,"inPlay":false,"crossMatching":false,"runnersVoidable":false,"numberOfActiveRunners":2,"betDelay":0,"status":"OPEN","runners":[{"status":"ACTIVE","sortPriority":1,"id":7414058,"name":"Damir Dzumhur"},{"status":"ACTIVE","sortPriority":2,"id":7287690,"name":"Quentin Halys"}],"regulators":["MR_INT"],"countryCode":"FR","discountAllowed":true,"timezone":"UTC","openDate":"2020-02-02T09:00:00.000Z","version":3147124717,"name":"Match Odds","eventName":"Dzumhur v Halys"}}]}
{"op":"mcm","clk":"1001222802","pt":1580585516439,"mc":[{"id":"1.168224552","marketDefinition":{"bspMarket":false,"turnInPlayEnabled":true,"persistenceEnabled":true,"marketBaseRate":5.0,"eventId":"29681742","eventTypeId":"2","numberOfWinners":1,"bettingType":"ODDS","marketType":"MATCH_ODDS","marketTime":"2020-02-02T13:30:00.000Z","suspendTime":"2020-02-02T13:30:00.000Z","bspReconciled":false,"complete":true,"inPlay":false,"crossMatching":false,"runnersVoidable":false,"numberOfActiveRunners":2,"betDelay":0,"status":"OPEN","runners":[{"status":"ACTIVE","sortPriority":1,"id":7414058,"name":"Damir Dzumhur"},{"status":"ACTIVE","sortPriority":2,"id":7287690,"name":"Quentin Halys"}],"regulators":["MR_INT"],"countryCode":"FR","discountAllowed":true,"timezone":"UTC","openDate":"2020-02-02T13:30:00.000Z","version":3147124717,"name":"Match Odds","eventName":"Dzumhur v Halys"}}]}
{"op":"mcm","clk":"1001227866","pt":1580585543305,"mc":[{"id":"1.168224552","rc":[{"batb":[[0,1.03,100.96],[1,1.02,3786.16],[2,1.01,4059.07]],"ltp":0.0,"tv":0.0,"id":7287690},{"batb":[[0,1.06,50.48],[1,1.05,152.2],[2,1.04,168.86]],"ltp":0.0,"tv":0.0,"id":7414058}]}]}
{"op":"mcm","clk":"1001229255","pt":1580585550619,"mc":[{"id":"1.168224552","marketDefinition":{"bspMarket":false,"turnInPlayEnabled":true,"persistenceEnabled":true,"marketBaseRate":5.0,"eventId":"29681742","eventTypeId":"2","numberOfWinners":1,"bettingType":"ODDS","marketType":"MATCH_ODDS","marketTime":"2020-02-02T13:30:00.000Z","suspendTime":"2020-02-02T13:30:00.000Z","bspReconciled":false,"complete":true,"inPlay":false,"crossMatching":true,"runnersVoidable":false,"numberOfActiveRunners":2,"betDelay":0,"status":"OPEN","runners":[{"status":"ACTIVE","sortPriority":1,"id":7414058,"name":"Damir Dzumhur"},{"status":"ACTIVE","sortPriority":2,"id":7287690,"name":"Quentin Halys"}],"regulators":["MR_INT"],"countryCode":"FR","discountAllowed":true,"timezone":"UTC","openDate":"2020-02-02T13:30:00.000Z","version":3147124717,"name":"Match Odds","eventName":"Dzumhur v Halys"}}]}
{"op":"mcm","clk":"1001249024","pt":1580585649425,"mc":[{"id":"1.168224552","rc":[{"batb":[[2,1.01,4122.68]],"ltp":0.0,"tv":0.0,"id":7287690}]}]}
{"op":"mcm","clk":"1001278702","pt":1580585799764,"mc":[{"id":"1.168224552","rc":[{"batl":[[0,48,31.05]],"ltp":0.0,"tv":0.0,"id":7287690},{"batl":[[0,48,31.05]],"ltp":0.0,"tv":0.0,"id":7414058}]}]}
{"op":"mcm","clk":"1001382490","pt":1580586339370,"mc":[{"id":"1.168224552","rc":[{"batb":[[1,1.02,3811.36]],"ltp":0.0,"tv":0.0,"id":7287690}]}]}
{"op":"mcm","clk":"1001382542","pt":1580586339593,"mc":[{"id":"1.168224552","rc":[{"batb":[[0,1.03,109.36]],"ltp":0.0,"tv":0.0,"id":7287690}]}]}
{"op":"mcm","clk":"1001665625","pt":1580587947377,"mc":[{"id":"1.168224552","rc":[{"batl":[[1,990,2.2]],"ltp":0.0,"tv":0.0,"id":7287690},{"batl":[[1,990,2.2]],"ltp":0.0,"tv":0.0,"id":7414058}]}]}
{"op":"mcm","clk":"1001966094","pt":1580589614563,"mc":[{"id":"1.168224552","rc":[{"batb":[[1,1.02,25.21],[2,1.01,336.52]],"ltp":0.0,"tv":0.0,"id":7287690}]}]}
{"op":"mcm","clk":"1002985284","pt":1580601560420,"mc":[{"id":"1.168224552","rc":[{"batb":[[2,1.01,339.12]],"batl":[[2,1000,0.02]],"ltp":0.0,"tv":0.0,"id":7287690},{"batl":[[2,1000,0.02]],"ltp":0.0,"tv":0.0,"id":7414058}]}]}
{"op":"mcm","clk":"1002985307","pt":1580601560730,"mc":[{"id":"1.168224552","rc":[{"batb":[[0,1.03,109.96],[2,1.01,338.52]],"ltp":0.0,"tv":0.0,"id":7287690},{"batb":[[0,1.06,50.58],[2,1.04,169.36]],"ltp":0.0,"tv":0.0,"id":7414058}]}]}
{"op":"mcm","clk":"1002990392","pt":1580601630306,"mc":[{"id":"1.168224552","rc":[{"batb":[[2,1.01,340.52]],"ltp":0.0,"tv":0.0,"id":7287690}]}]}
{"op":"mcm","clk":"1002990438","pt":1580601630930,"mc":[{"id":"1.168224552","rc":[{"batb":[[0,1.03,110.06],[2,1.01,338.52]],"ltp":0.0,"tv":0.0,"id":7287690},{"batb":[[0,1.06,50.68]],"ltp":0.0,"tv":0.0,"id":7414058}]}]}
{"op":"mcm","clk":"1003032822","pt":1580602188482,"mc":[{"id":"1.168224552","rc":[{"batb":[[2,1.01,341.06]],"ltp":0.0,"tv":0.0,"id":7287690}]}]}
{"op":"mcm","clk":"1003032913","pt":1580602189468,"mc":[{"id":"1.168224552","rc":[{"batb":[[2,1.01,338.52]],"ltp":0.0,"tv":0.0,"id":7287690}]}]}
{"op":"mcm","clk":"1003032925","pt":1580602189574,"mc":[{"id":"1.168224552","rc":[{"batb":[[2,1.01,339.03]],"ltp":0.0,"tv":0.0,"id":7287690}]}]}
{"op":"mcm","clk":"1003160539","pt":1580603728152,"mc":[{"id":"1.168224552","rc":[{"batb":[[2,1.01,341.56]],"ltp":0.0,"tv":0.0,"id":7287690}]}]}
{"op":"mcm","clk":"1003160622","pt":1580603729139,"mc":[{"id":"1.168224552","rc":[{"batb":[[2,1.01,339.54]],"ltp":0.0,"tv":0.0,"id":7287690}]}]}
{"op":"mcm","clk":"1003881053","pt":1580615093035,"mc":[{"id":"1.168224552","rc":[{"batl":[[0,990,2.2],[1,1000,0.02],[2,1000,0]],"ltp":0.0,"tv":0.0,"id":7287690},{"batl":[[0,990,2.2],[1,1000,0.02],[2,1000,0]],"ltp":0.0,"tv":0.0,"id":7414058}]}]}
{"op":"mcm","clk":"1003929621","pt":1580616435420,"mc":[{"id":"1.168224552","rc":[{"batl":[[0,95,15.9],[1,990,2.2],[2,1000,0.02]],"ltp":0.0,"tv":0.0,"id":7287690},{"batl":[[0,95,15.9],[1,990,2.2],[2,1000,0.02]],"ltp":0.0,"tv":0.0,"id":7414058}]}]}
{"op":"mcm","clk":"1003933623","pt":1580616532391,"mc":[{"id":"1.168224552","rc":[{"batb":[[0,1.13,75.82],[1,1.03,109.96],[2,1.02,25.21]],"ltp":0.0,"tv":0.0,"id":7287690},{"batb":[[0,1.13,75.82],[1,1.06,50.58],[2,1.05,152.2]],"ltp":0.0,"tv":0.0,"id":7414058}]}]}
{"op":"mcm","clk":"1004050260","pt":1580618996590,"mc":[{"id":"1.168224552","rc":[{"batl":[[0,1.65,25.33],[1,95,15.9],[2,990,2.2]],"ltp":0.0,"tv":0.0,"id":7414058}]}]}
{"op":"mcm","clk":"1004345690","pt":1580627600290,"mc":[{"id":"1.168224552","rc":[{"batb":[[0,1.14,15.22],[1,1.13,75.72],[2,1.03,109.96]],"batl":[[0,15.5,3.36],[1,95,15.9],[2,990,2.2]],"ltp":0.0,"tv":0.0,"id":7287690},{"batb":[[0,1.14,15.22],[1,1.13,75.72],[2,1.06,50.58]],"ltp":0.0,"tv":0.0,"id":7414058}]}]}
{"op":"mcm","clk":"1004359865","pt":1580627950910,"mc":[{"id":"1.168224552","rc":[{"batb":[[0,1.15,2.37],[1,1.14,15.12],[2,1.13,75.72]],"ltp":0.0,"tv":0.0,"id":7414058}]}]}
{"op":"mcm","clk":"1004360108","pt":1580627956622,"mc":[{"id":"1.168224552","rc":[{"batb":[[0,1.16,2.37]],"ltp":0.0,"tv":0.0,"id":7414058}]}]}
{"op":"mcm","clk":"1004360311","pt":1580627961734,"mc":[{"id":"1.168224552","rc":[{"batb":[[0,1.17,2.37]],"ltp":0.0,"tv":0.0,"id":7414058}]}]}
{"op":"mcm","clk":"1004360506","pt":1580627966289,"mc":[{"id":"1.168224552","rc":[{"batb":[[0,1.18,2.37]],"ltp":0.0,"tv":0.0,"id":7414058}]}]}
{"op":"mcm","clk":"1004360563","pt":1580627967721,"mc":[{"id":"1.168224552","rc":[{"batb":[[1,1.13,75.72],[2,1.06,50.58]],"ltp":0.0,"tv":0.0,"id":7414058}]}]}
{"op":"mcm","clk":"1004360733","pt":1580627971890,"mc":[{"id":"1.168224552","rc":[{"batb":[[0,1.19,2.37]],"ltp":0.0,"tv":0.0,"id":7414058}]}]}
{"op":"mcm","clk":"1004361232","pt":1580627984952,"mc":[{"id":"1.168224552","rc":[{"batb":[[0,1.2,2.37]],"ltp":0.0,"tv":0.0,"id":7414058}]}]}
{"op":"mcm","clk":"1004361766","pt":1580627996369,"mc":[{"id":"1.168224552","rc":[{"batb":[[0,1.21,2.27],[1,1.13,75.82]],"ltp":0.0,"tv":0.0,"id":7414058}]}]}
{"op":"mcm","clk":"1004361970","pt":1580628000841,"mc":[{"id":"1.168224552","rc":[{"batb":[[0,1.22,2.27]],"ltp":0.0,"tv":0.0,"id":7414058}]}]}
{"op":"mcm","clk":"1004362308","pt":1580628008146,"mc":[{"id":"1.168224552","rc":[{"batb":[[0,1.23,2.27]],"ltp":0.0,"tv":0.0,"id":7414058}]}]}
{"op":"mcm","clk":"1004362575","pt":1580628013453,"mc":[{"id":"1.168224552","rc":[{"batb":[[0,1.24,2.27]],"ltp":0.0,"tv":0.0,"id":7414058}]}]}
{"op":"mcm","clk":"1004362865","pt":1580628018274,"mc":[{"id":"1.168224552","rc":[{"batb":[[0,1.25,2.27]],"ltp":0.0,"tv":0.0,"id":7414058}]}]}
{"op":"mcm","clk":"1004363356","pt":1580628027101,"mc":[{"id":"1.168224552","rc":[{"batb":[[0,1.26,2.27]],"ltp":0.0,"tv":0.0,"id":7414058}]}]}
{"op":"mcm","clk":"1004363603","pt":1580628032801,"mc":[{"id":"1.168224552","rc":[{"batb":[[0,1.27,2.27]],"ltp":0.0,"tv":0.0,"id":7414058}]}]}
{"op":"mcm","clk":"1004363817","pt":1580628037885,"mc":[{"id":"1.168224552","rc":[{"batb":[[0,1.28,2.27]],"ltp":0.0,"tv":0.0,"id":7414058}]}]}
{"op":"mcm","clk":"1004364074","pt":1580628043731,"mc":[{"id":"1.168224552","rc":[{"batb":[[0,1.29,2.27]],"ltp":0.0,"tv":0.0,"id":7414058}]}]}
{"op":"mcm","clk":"1004364337","pt":1580628051425,"mc":[{"id":"1.168224552","rc":[{"batb":[[0,1.3,2.27]],"ltp":0.0,"tv":0.0,"id":7414058}]}]}
{"op":"mcm","clk":"1004365468","pt":1580628074164,"mc":[{"id":"1.168224552","rc":[{"batb":[[0,1.13,75.82],[1,1.06,50.58],[2,1.05,152.2]],"ltp":0.0,"tv":0.0,"id":7414058}]}]}
{"op":"mcm","clk":"1004365852","pt":1580628082872,"mc":[{"id":"1.168224552","rc":[{"batb":[[0,1.14,15.22],[1,1.13,75.72],[2,1.06,50.58]],"ltp":0.0,"tv":0.0,"id":7414058}]}]}
{"op":"mcm","clk":"1004366079","pt":1580628088877,"mc":[{"id":"1.168224552","rc":[{"batl":[[0,1.64,2.27],[1,1.65,25.33],[2,95,15.9]],"ltp":0.0,"tv":0.0,"id":7414058}]}]}
{"op":"mcm","clk":"1004366623","pt":1580628094789,"mc":[{"id":"1.168224552","rc":[{"batl":[[0,1.63,2.27]],"ltp":0.0,"tv":0.0,"id":7414058}]}]}
{"op":"mcm","clk":"1004366827","pt":1580628099203,"mc":[{"id":"1.168224552","rc":[{"batl":[[0,1.62,2.27]],"ltp":0.0,"tv":0.0,"id":7414058}]}]}
{"op":"mcm","clk":"1004367011","pt":1580628103977,"mc":[{"id":"1.168224552","rc":[{"batl":[[0,1.61,2.27]],"ltp":0.0,"tv":0.0,"id":7414058}]}]}
{"op":"mcm","clk":"1004367386","pt":1580628112092,"mc":[{"id":"1.168224552","rc":[{"batl":[[0,1.6,2.27]],"ltp":0.0,"tv":0.0,"id":7414058}]}]}
{"op":"mcm","clk":"1004367642","pt":1580628116416,"mc":[{"id":"1.168224552","rc":[{"batl":[[0,1.65,25.33],[1,95,15.9],[2,990,2.2]],"ltp":0.0,"tv":0.0,"id":7414058}]}]}
{"op":"mcm","clk":"1004367648","pt":1580628116518,"mc":[{"id":"1.168224552","rc":[{"batl":[[0,1.59,2.27],[1,1.65,25.33],[2,95,15.9]],"ltp":0.0,"tv":0.0,"id":7414058}]}]}
{"op":"mcm","clk":"1004370352","pt":1580628179797,"mc":[{"id":"1.168224552","rc":[{"batl":[[0,1.65,25.33],[1,95,15.9],[2,990,2.2]],"ltp":0.0,"tv":0.0,"id":7414058}]}]}
{"op":"mcm","clk":"1004371731","pt":1580628210609,"mc":[{"id":"1.168224552","rc":[{"batb":[[0,1.41,60.67],[1,1.14,15.22],[2,1.13,75.72]],"ltp":0.0,"tv":0.0,"id":7414058}]}]}
{"op":"mcm","clk":"1004371783","pt":1580628211742,"mc":[{"id":"1.168224552","rc":[{"batb":[[0,1.15,75.82],[1,1.14,15.12]],"ltp":0.0,"tv":0.0,"id":7287690},{"batb":[[1,1.15,75.82],[2,1.14,15.12]],"ltp":0.0,"tv":0.0,"id":7414058}]}]}
{"op":"mcm","clk":"1004372001","pt":1580628217447,"mc":[{"id":"1.168224552","rc":[{"batl":[[0,1.64,52.18],[1,1.65,25.33],[2,95,15.9]],"ltp":0.0,"tv":0.0,"id":7414058}]}]}
{"op":"mcm","clk":"1004372127","pt":1580628220337,"mc":[{"id":"1.168224552","rc":[{"batb":[[0,1.15,75.82],[1,1.14,15.12],[2,1.06,50.58]],"ltp":0.0,"tv":0.0,"id":7414058}]}]}
{"op":"mcm","clk":"1004372671","pt":1580628233065,"mc":[{"id":"1.168224552","rc":[{"batb":[[0,2.4,37.86],[1,1.15,75.82],[2,1.14,15.12]],"ltp":0.0,"tv":0.0,"id":7287690},{"batb":[[0,1.4,72.11],[1,1.39,65.12],[2,1.15,75.82]],"ltp":0.0,"tv":0.0,"id":7414058}]}]}
{"op":"mcm","clk":"1004373620","pt":1580628266632,"mc":[{"id":"1.168224552","rc":[{"batb":[[2,1.03,109.96]],"ltp":0.0,"tv":0.0,"id":7287690}]}]}
{"op":"mcm","clk":"1004375698","pt":1580628330481,"mc":[{"id":"1.168224552","rc":[{"batb":[[0,2.46,37.86]],"ltp":0.0,"tv":0.0,"id":7287690}]}]}
{"op":"mcm","clk":"1004377325","pt":1580628367437,"mc":[{"id":"1.168224552","rc":[{"batb":[[0,1.15,75.82],[1,1.03,109.96],[2,1.02,25.21]],"ltp":0.0,"tv":0.0,"id":7287690}]}]}
{"op":"mcm","clk":"1004377333","pt":1580628367539,"mc":[{"id":"1.168224552","rc":[{"batb":[[0,2.4,37.86],[1,1.15,75.82],[2,1.03,109.96]],"ltp":0.0,"tv":0.0,"id":7287690}]}]}
{"op":"mcm","clk":"1004381156","pt":1580628456958,"mc":[{"id":"1.168224552","rc":[{"batb":[[0,2.46,37.86]],"ltp":0.0,"tv":0.0,"id":7287690}]}]}
{"op":"mcm","clk":"1004385571","pt":1580628574157,"mc":[{"id":"1.168224552","rc":[{"batb":[[0,2.5,37.86]],"ltp":0.0,"tv":0.0,"id":7287690}]}]}
{"op":"mcm","clk":"1004390233","pt":1580628687030,"mc":[{"id":"1.168224552","rc":[{"batb":[[0,1.39,65.12],[1,1.15,75.82],[2,1.06,50.58]],"batl":[[0,1.65,25.33],[1,95,15.9],[2,990,2.2]],"ltp":0.0,"tv":0.0,"id":7414058}]}]}
{"op":"mcm","clk":"1004392749","pt":1580628747605,"mc":[{"id":"1.168224552","rc":[{"batb":[[0,1.42,69.94],[1,1.39,65.12],[2,1.15,75.82]],"batl":[[0,1.62,52.25],[1,1.65,25.33],[2,95,15.9]],"ltp":0.0,"tv":0.0,"id":7414058}]}]}
{"op":"mcm","clk":"1004392941","pt":1580628752136,"mc":[{"id":"1.168224552","rc":[{"batb":[[0,1.15,75.82],[1,1.03,109.96],[2,1.02,25.21]],"ltp":0.0,"tv":0.0,"id":7287690},{"batb":[[0,1.42,135.06],[1,1.15,75.82],[2,1.06,50.58]],"ltp":0.0,"tv":0.0,"id":7414058}]}]}
{"op":"mcm","clk":"1004393187","pt":1580628757032,"mc":[{"id":"1.168224552","rc":[{"batb":[[0,2.5,36.35],[1,1.15,75.82],[2,1.03,109.96]],"ltp":0.0,"tv":0.0,"id":7287690},{"batb":[[0,1.42,69.94],[1,1.41,65.12],[2,1.15,75.82]],"ltp":0.0,"tv":0.0,"id":7414058}]}]}
{"op":"mcm","clk":"1004394041","pt":1580628777336,"mc":[{"id":"1.168224552","rc":[{"batb":[[0,2.42,36.35]],"ltp":0.0,"tv":0.0,"id":7287690}]}]}
{"op":"mcm","clk":"1004395860","pt":1580628820837,"mc":[{"id":"1.168224552","rc":[{"batb":[[0,2.5,36.35]],"ltp":0.0,"tv":0.0,"id":7287690}]}]}
{"op":"mcm","clk":"1004396790","pt":1580628846247,"mc":[{"id":"1.168224552","rc":[{"batb":[[0,2.46,36.35]],"ltp":0.0,"tv":0.0,"id":7287690}]}]}
{"op":"mcm","clk":"1004406141","pt":1580629100733,"mc":[{"id":"1.168224552","rc":[{"batb":[[0,2.52,36.35]],"ltp":0.0,"tv":0.0,"id":7287690}]}]}
{"op":"mcm","clk":"1004424333","pt":1580629541481,"mc":[{"id":"1.168224552","rc":[{"batb":[[0,1.15,75.82],[1,1.03,109.96],[2,1.02,25.21]],"ltp":0.0,"tv":0.0,"id":7287690}]}]}
{"op":"mcm","clk":"1004424340","pt":1580629541581,"mc":[{"id":"1.168224552","rc":[{"batb":[[0,2.46,36.35],[1,1.15,75.82],[2,1.03,109.96]],"ltp":0.0,"tv":0.0,"id":7287690}]}]}
{"op":"mcm","clk":"1004426772","pt":1580629595640,"mc":[{"id":"1.168224552","rc":[{"batb":[[0,1.41,65.12],[1,1.15,75.82],[2,1.06,50.58]],"ltp":0.0,"tv":0.0,"id":7414058}]}]}
{"op":"mcm","clk":"1004427018","pt":1580629600467,"mc":[{"id":"1.168224552","rc":[{"batb":[[0,1.15,75.82],[1,1.03,109.96],[2,1.02,25.21]],"ltp":0.0,"tv":0.0,"id":7287690},{"batb":[[0,1.15,75.82],[1,1.06,50.58],[2,1.05,152.2]],"ltp":0.0,"tv":0.0,"id":7414058}]}]}
{"op":"mcm","clk":"1004427022","pt":1580629600569,"mc":[{"id":"1.168224552","rc":[{"batb":[[0,2.5,36.35],[1,1.15,75.82],[2,1.03,109.96]],"ltp":0.0,"tv":0.0,"id":7287690}]}]}
{"op":"mcm","clk":"1004427378","pt":1580629608888,"mc":[{"id":"1.168224552","rc":[{"batb":[[0,2.58,36.35]],"ltp":0.0,"tv":0.0,"id":7287690},{"batb":[[0,1.39,65.12],[1,1.15,75.82],[2,1.06,50.58]],"ltp":0.0,"tv":0.0,"id":7414058}]}]}
{"op":"mcm","clk":"1004429626","pt":1580629659280,"mc":[{"id":"1.168224552","rc":[{"batb":[[0,2.6,36.35]],"ltp":0.0,"tv":0.0,"id":7287690}]}]}
{"op":"mcm","clk":"1004461370","pt":1580630361464,"mc":[{"id":"1.168224552","rc":[{"trd":[[1.39,4]],"batb":[[0,1.39,63.12]],"ltp":1.39,"tv":3.99,"id":7414058}],"tv":3.99}]}
{"op":"mcm","clk":"1004461384","pt":1580630361671,"mc":[{"id":"1.168224552","rc":[{"batb":[[0,1.4,73.21],[1,1.39,63.12],[2,1.15,75.82]],"ltp":1.39,"tv":3.99,"id":7414058}]}]}
{"op":"mcm","clk":"1004461832","pt":1580630370379,"mc":[{"id":"1.168224552","rc":[{"batl":[[0,1.57,57.22]],"ltp":1.39,"tv":3.99,"id":7414058}]}]}
{"op":"mcm","clk":"1004462030","pt":1580630375390,"mc":[{"id":"1.168224552","rc":[{"batl":[[0,1.57,55.22]],"ltp":1.39,"tv":3.99,"id":7414058}]}]}
{"op":"mcm","clk":"1004462043","pt":1580630375699,"mc":[{"id":"1.168224552","rc":[{"batl":[[0,1.52,2]],"ltp":1.39,"tv":3.99,"id":7414058}]}]}
{"op":"mcm","clk":"1004467077","pt":1580630470227,"mc":[{"id":"1.168224552","rc":[{"batb":[[0,2.64,36.35]],"ltp":0.0,"tv":0.0,"id":7287690}]}]}
{"op":"mcm","clk":"1004478529","pt":1580630721334,"mc":[{"id":"1.168224552","rc":[{"batl":[[0,1.45,2.52],[1,1.52,2],[2,1.65,25.33]],"ltp":1.39,"tv":3.99,"id":7414058}]}]}
{"op":"mcm","clk":"1004478547","pt":1580630721848,"mc":[{"id":"1.168224552","rc":[{"trd":[[1.45,4.82]],"batl":[[0,1.52,2.11],[1,1.65,25.33],[2,95,15.9]],"ltp":1.45,"tv":8.82,"id":7414058}],"tv":8.82}]}
{"op":"mcm","clk":"1004478900","pt":1580630730147,"mc":[{"id":"1.168224552","rc":[{"batb":[[0,1.39,63.12],[1,1.15,75.82],[2,1.06,50.58]],"ltp":1.45,"tv":8.82,"id":7414058}]}]}
{"op":"mcm","clk":"1004481005","pt":1580630778469,"mc":[{"id":"1.168224552","rc":[{"trd":[[1.39,15.76]],"batb":[[0,1.39,57.24]],"ltp":1.39,"tv":20.58,"id":7414058}],"tv":20.58}]}
{"op":"mcm","clk":"1004482057","pt":1580630803392,"mc":[{"id":"1.168224552","rc":[{"batl":[[0,1.56,7.68]],"ltp":1.39,"tv":20.58,"id":7414058}]}]}
{"op":"mcm","clk":"1004482100","pt":1580630804485,"mc":[{"id":"1.168224552","rc":[{"batb":[[0,1.4,73.21],[1,1.39,57.24],[2,1.15,75.82]],"ltp":1.39,"tv":20.58,"id":7414058}]}]}
{"op":"mcm","clk":"1004482129","pt":1580630805473,"mc":[{"id":"1.168224552","rc":[{"batl":[[0,1.65,25.43],[1,95,15.9],[2,990,2.2]],"ltp":1.39,"tv":20.58,"id":7414058}]}]}
{"op":"mcm","clk":"1004482132","pt":1580630805575,"mc":[{"id":"1.168224552","rc":[{"batl":[[0,1.52,7.68],[1,1.65,25.33],[2,95,15.9]],"ltp":1.39,"tv":20.58,"id":7414058}]}]}
{"op":"mcm","clk":"1004509430","pt":1580631435295,"mc":[{"id":"1.168224552","rc":[{"batl":[[0,1.51,7.68]],"ltp":1.39,"tv":20.58,"id":7414058}]}]}
{"op":"mcm","clk":"1004524381","pt":1580631776806,"mc":[{"id":"1.168224552","rc":[{"batl":[[2,3,42.01]],"ltp":1.39,"tv":20.58,"id":7414058}]}]}
{"op":"mcm","clk":"1004526292","pt":1580631828054,"mc":[{"id":"1.168224552","rc":[{"batb":[[0,1.4,109.76]],"ltp":1.39,"tv":20.58,"id":7414058}]}]}
{"op":"mcm","clk":"1004533478","pt":1580631970405,"mc":[{"id":"1.168224552","rc":[{"batb":[[1,1.21,37.86],[2,1.15,75.82]],"ltp":0.0,"tv":0.0,"id":7287690},{"batb":[[2,1.21,37.86]],"ltp":1.39,"tv":20.58,"id":7414058}]}]}
{"op":"mcm","clk":"1004533511","pt":1580631971229,"mc":[{"id":"1.168224552","rc":[{"batb":[[1,1.31,37.86],[2,1.21,37.86]],"ltp":0.0,"tv":0.0,"id":7287690}]}]}
{"op":"mcm","clk":"1004533527","pt":1580631971542,"mc":[{"id":"1.168224552","rc":[{"batb":[[1,1.41,37.86],[2,1.31,37.86]],"ltp":0.0,"tv":0.0,"id":7287690}]}]}
{"op":"mcm","clk":"1004533629","pt":1580631973404,"mc":[{"id":"1.168224552","rc":[{"batb":[[1,1.71,37.86],[2,1.61,37.86]],"ltp":0.0,"tv":0.0,"id":7287690}]}]}
{"op":"mcm","clk":"1004533691","pt":1580631974434,"mc":[{"id":"1.168224552","rc":[{"batb":[[1,1.81,37.86],[2,1.71,37.86]],"ltp":0.0,"tv":0.0,"id":7287690}]}]}
{"op":"mcm","clk":"1004533762","pt":1580631975566,"mc":[{"id":"1.168224552","rc":[{"batb":[[1,2.22,37.86],[2,2,37.86]],"ltp":0.0,"tv":0.0,"id":7287690}]}]}
{"op":"mcm","clk":"1004575470","pt":1580632932079,"mc":[{"id":"1.168224552","rc":[{"batl":[[0,1.45,2.64],[1,1.51,7.57],[2,1.65,25.33]],"ltp":1.39,"tv":20.58,"id":7414058}]}]}
{"op":"mcm","clk":"1004584488","pt":1580633111876,"mc":[{"id":"1.168224552","rc":[{"batl":[[1,1.5,7.57]],"ltp":1.39,"tv":20.58,"id":7414058}]}]}
{"op":"mcm","clk":"1004594444","pt":1580633336558,"mc":[{"id":"1.168224552","rc":[{"batb":[[0,1.39,57.24],[1,1.21,37.86],[2,1.15,75.82]],"ltp":1.39,"tv":20.58,"id":7414058}]}]}
{"op":"mcm","clk":"1004594597","pt":1580633339947,"mc":[{"id":"1.168224552","rc":[{"batb":[[0,1.39,170.56]],"ltp":1.39,"tv":20.58,"id":7414058}]}]}
{"op":"mcm","clk":"1004601493","pt":1580633487541,"mc":[{"id":"1.168224552","rc":[{"batb":[[1,2.52,18.93],[2,2.22,37.86]],"ltp":0.0,"tv":0.0,"id":7287690},{"batb":[[1,1.34,84.63],[2,1.21,37.86]],"ltp":1.39,"tv":20.58,"id":7414058}]}]}
{"op":"mcm","clk":"1004611345","pt":1580633717309,"mc":[{"id":"1.168224552","rc":[{"batb":[[1,2.5,19.18]],"ltp":0.0,"tv":0.0,"id":7287690},{"batb":[[1,1.35,82.21]],"ltp":1.39,"tv":20.58,"id":7414058}]}]}
{"op":"mcm","clk":"1004626679","pt":1580634004856,"mc":[{"id":"1.168224552","rc":[{"batb":[[1,2.5,57.04]],"ltp":0.0,"tv":0.0,"id":7287690}]}]}
{"op":"mcm","clk":"1004630850","pt":1580634069721,"mc":[{"id":"1.168224552","rc":[{"batb":[[0,2.7,36.35]],"ltp":0.0,"tv":0.0,"id":7287690},{"batb":[[0,1.39,113.32],[1,1.37,57.24],[2,1.35,82.21]],"ltp":1.39,"tv":20.58,"id":7414058}]}]}
{"op":"mcm","clk":"1004631875","pt":1580634086388,"mc":[{"id":"1.168224552","rc":[{"trd":[[1.45,10.11]],"batl":[[0,1.5,7.57],[1,1.65,25.33],[2,3,42.01]],"ltp":1.45,"tv":25.87,"id":7414058}],"tv":25.87}]}
{"op":"mcm","clk":"1004631916","pt":1580634086855,"mc":[{"id":"1.168224552","rc":[{"batb":[[0,3.05,19.53],[1,2.7,36.35],[2,2.5,57.04]],"ltp":0.0,"tv":0.0,"id":7287690},{"batb":[[0,1.42,89.84],[1,1.39,113.32],[2,1.37,57.24]],"ltp":1.45,"tv":25.87,"id":7414058}]}]}
{"op":"mcm","clk":"1004642391","pt":1580634310460,"mc":[{"id":"1.168224552","rc":[{"batb":[[1,1.37,57.24],[2,1.35,82.21]],"ltp":1.45,"tv":25.87,"id":7414058}]}]}
{"op":"mcm","clk":"1004660589","pt":1580634702666,"mc":[{"id":"1.168224552","rc":[{"batl":[[0,1.5,9.84]],"ltp":1.45,"tv":25.87,"id":7414058}]}]}
{"op":"mcm","clk":"1004670760","pt":1580634897343,"mc":[{"id":"1.168224552","rc":[{"batb":[[2,2.5,37.86]],"ltp":0.0,"tv":0.0,"id":7287690},{"batb":[[2,1.31,37.86]],"ltp":1.45,"tv":25.87,"id":7414058}]}]}
{"op":"mcm","clk":"1004670793","pt":1580634898013,"mc":[{"id":"1.168224552","rc":[{"batb":[[2,2.52,18.93]],"ltp":0.0,"tv":0.0,"id":7287690},{"batb":[[2,1.34,84.63]],"ltp":1.45,"tv":25.87,"id":7414058}]}]}
{"op":"mcm","clk":"1004691847","pt":1580635314870,"mc":[{"id":"1.168224552","marketDefinition":{"bspMarket":false,"turnInPlayEnabled":true,"persistenceEnabled":true,"marketBaseRate":5.0,"eventId":"29681742","eventTypeId":"2","numberOfWinners":1,"bettingType":"ODDS","marketType":"MATCH_ODDS","marketTime":"2020-02-02T13:19:00.000Z","suspendTime":"2020-02-02T13:19:00.000Z","bspReconciled":false,"complete":true,"inPlay":false,"crossMatching":true,"runnersVoidable":false,"numberOfActiveRunners":2,"betDelay":0,"status":"OPEN","runners":[{"status":"ACTIVE","sortPriority":1,"id":7414058,"name":"Damir Dzumhur"},{"status":"ACTIVE","sortPriority":2,"id":7287690,"name":"Quentin Halys"}],"regulators":["MR_INT"],"countryCode":"FR","discountAllowed":true,"timezone":"UTC","openDate":"2020-02-02T13:30:00.000Z","version":3148342674,"name":"Match Odds","eventName":"Dzumhur v Halys"}}]}
{"op":"mcm","clk":"1004692024","pt":1580635317913,"mc":[{"id":"1.168224552","marketDefinition":{"bspMarket":false,"turnInPlayEnabled":true,"persistenceEnabled":true,"marketBaseRate":5.0,"eventId":"29681742","eventTypeId":"2","numberOfWinners":1,"bettingType":"ODDS","marketType":"MATCH_ODDS","marketTime":"2020-02-02T13:19:00.000Z","suspendTime":"2020-02-02T13:19:00.000Z","bspReconciled":false,"complete":true,"inPlay":false,"crossMatching":true,"runnersVoidable":false,"numberOfActiveRunners":2,"betDelay":0,"status":"OPEN","runners":[{"status":"ACTIVE","sortPriority":1,"id":7414058,"name":"Damir Dzumhur"},{"status":"ACTIVE","sortPriority":2,"id":7287690,"name":"Quentin Halys"}],"regulators":["MR_INT"],"countryCode":"FR","discountAllowed":true,"timezone":"UTC","openDate":"2020-02-02T13:19:00.000Z","version":3148342674,"name":"Match Odds","eventName":"Dzumhur v Halys"}}]}
{"op":"mcm","clk":"1004693844","pt":1580635368678,"mc":[{"id":"1.168224552","rc":[{"batb":[[1,2.7,77.52]],"ltp":0.0,"tv":0.0,"id":7287690}]}]}
{"op":"mcm","clk":"1004695217","pt":1580635407764,"mc":[{"id":"1.168224552","rc":[{"batb":[[1,2.7,41.17]],"ltp":0.0,"tv":0.0,"id":7287690},{"batb":[[1,1.34,84.63],[2,1.31,37.86]],"batl":[[0,1.5,2.27]],"ltp":1.45,"tv":25.87,"id":7414058}]}]}
{"op":"mcm","clk":"1004695319","pt":1580635409872,"mc":[{"id":"1.168224552","rc":[{"batb":[[0,2.94,43.33]],"ltp":0.0,"tv":0.0,"id":7287690}]}]}
{"op":"mcm","clk":"1004695417","pt":1580635412034,"mc":[{"id":"1.168224552","rc":[{"batl":[[1,1.54,7.57],[2,1.65,25.33]],"ltp":1.45,"tv":25.87,"id":7414058}]}]}
{"op":"mcm","clk":"1004695506","pt":1580635414143,"mc":[{"id":"1.168224552","rc":[{"batl":[[0,1.5,9.84],[1,1.65,25.33],[2,3,42.01]],"ltp":1.45,"tv":25.87,"id":7414058}]}]}
{"op":"mcm","clk":"1004698126","pt":1580635477333,"mc":[{"id":"1.168224552","rc":[{"batb":[[2,2.52,24.91]],"ltp":0.0,"tv":0.0,"id":7287690},{"batb":[[1,1.34,111.36]],"ltp":1.45,"tv":25.87,"id":7414058}]}]}
{"op":"mcm","clk":"1004699205","pt":1580635500898,"mc":[{"id":"1.168224552","rc":[{"batb":[[1,2.52,24.91],[2,2.5,37.86]],"ltp":0.0,"tv":0.0,"id":7287690}]}]}
{"op":"mcm","clk":"1004700948","pt":1580635542443,"mc":[{"id":"1.168224552","rc":[{"batb":[[0,2.52,24.91],[1,2.5,37.86],[2,2.22,37.86]],"ltp":0.0,"tv":0.0,"id":7287690}]}]}
{"op":"mcm","clk":"1004700952","pt":1580635542546,"mc":[{"id":"1.168224552","rc":[{"batb":[[0,3.05,19.53],[1,2.52,24.91],[2,2.5,37.86]],"ltp":0.0,"tv":0.0,"id":7287690}]}]}
{"op":"mcm","clk":"1004718293","pt":1580635951349,"mc":[{"id":"1.168224552","rc":[{"trd":[[3.05,16.8]],"batb":[[0,2.9,44.14]],"ltp":3.05,"tv":16.8,"id":7287690},{"batb":[[0,1.43,86.43]],"ltp":1.45,"tv":25.87,"id":7414058}],"tv":42.67}]}
{"op":"mcm","clk":"1004719089","pt":1580635968575,"mc":[{"id":"1.168224552","rc":[{"trd":[[1.5,3.7]],"batl":[[0,1.5,8]],"ltp":1.5,"tv":29.57,"id":7414058}],"tv":46.37}]}
{"op":"mcm","clk":"1004719318","pt":1580635973266,"mc":[{"id":"1.168224552","rc":[{"batb":[[0,1.43,86.51]],"ltp":1.5,"tv":29.57,"id":7414058}]}]}
{"op":"mcm","clk":"1004731743","pt":1580636272741,"mc":[{"id":"1.168224552","rc":[{"batb":[[0,2.9,44.22]],"ltp":3.05,"tv":16.8,"id":7287690}]}]}
{"op":"mcm","clk":"1004737885","pt":1580636403743,"mc":[{"id":"1.168224552","rc":[{"trd":[[1.43,3.84],[1.44,0.16]],"batb":[[0,1.43,84.51]],"ltp":1.43,"tv":33.57,"id":7414058}],"tv":50.37}]}
{"op":"mcm","clk":"1004738140","pt":1580636409764,"mc":[{"id":"1.168224552","rc":[{"batl":[[2,2.02,74.21]],"ltp":1.43,"tv":33.57,"id":7414058}]}]}
{"op":"mcm","clk":"1004763818","pt":1580636929691,"mc":[{"id":"1.168224552","rc":[{"batl":[[0,5.7,153.72],[1,15.5,3.36],[2,95,15.9]],"ltp":3.05,"tv":16.8,"id":7287690},{"batl":[[2,1.99,153.72]],"ltp":1.43,"tv":33.57,"id":7414058}]}]}
{"op":"mcm","clk":"1004764261","pt":1580636937787,"mc":[{"id":"1.168224552","rc":[{"batl":[[1,95,15.9],[2,990,2.2]],"ltp":3.05,"tv":16.8,"id":7287690}]}]}
{"op":"mcm","clk":"1004774157","pt":1580637118776,"mc":[{"id":"1.168224552","rc":[{"batl":[[0,1.49,7.57],[1,1.5,8],[2,1.65,25.33]],"ltp":1.43,"tv":33.57,"id":7414058}]}]}
{"op":"mcm","clk":"1004774315","pt":1580637121802,"mc":[{"id":"1.168224552","rc":[{"batl":[[0,1.5,8],[1,1.65,25.33],[2,1.99,153.72]],"ltp":1.43,"tv":33.57,"id":7414058}]}]}
{"op":"mcm","clk":"1004779273","pt":1580637210979,"mc":[{"id":"1.168224552","rc":[{"trd":[[3,3.92],[3.05,16.96]],"batb":[[0,2.9,44.14]],"ltp":3.0,"tv":20.87,"id":7287690},{"trd":[[1.5,11.54]],"batl":[[0,1.65,25.48],[1,1.99,153.72],[2,2.02,74.21]],"ltp":1.5,"tv":41.41,"id":7414058}],"tv":62.29}]}
{"op":"mcm","clk":"1004779377","pt":1580637213350,"mc":[{"id":"1.168224552","rc":[{"batb":[[1,2.5,37.86],[2,2.46,25.94]],"ltp":3.0,"tv":20.87,"id":7287690},{"batb":[[1,1.36,105.17]],"ltp":1.5,"tv":41.41,"id":7414058}]}]}
{"op":"mcm","clk":"1004779394","pt":1580637213662,"mc":[{"id":"1.168224552","rc":[{"batl":[[0,1.5,7.72],[1,1.65,25.33],[2,1.99,153.72]],"ltp":1.5,"tv":41.41,"id":7414058}]}]}
{"op":"mcm","clk":"1004779946","pt":1580637225400,"mc":[{"id":"1.168224552","rc":[{"batl":[[0,1.5,7.57],[1,1.65,25.48]],"ltp":1.5,"tv":41.41,"id":7414058}]}]}
{"op":"mcm","clk":"1004785446","pt":1580637338511,"mc":[{"id":"1.168224552","rc":[{"batl":[[0,1.5,15.14]],"ltp":1.5,"tv":41.41,"id":7414058}]}]}
{"op":"mcm","clk":"1004785544","pt":1580637341075,"mc":[{"id":"1.168224552","rc":[{"batl":[[0,1.5,7.57]],"ltp":1.5,"tv":41.41,"id":7414058}]}]}
{"op":"mcm","clk":"1004803408","pt":1580637634469,"mc":[{"id":"1.168224552","rc":[{"batb":[[2,2.48,25.58]],"ltp":3.0,"tv":20.87,"id":7287690},{"batb":[[1,1.35,108.18]],"ltp":1.5,"tv":41.41,"id":7414058}]}]}
{"op":"mcm","clk":"1004813349","pt":1580637762914,"mc":[{"id":"1.168224552","rc":[{"batb":[[1,2.66,34.08],[2,2.5,37.86]],"ltp":3.0,"tv":20.87,"id":7287690},{"batb":[[1,1.38,65.88],[2,1.35,108.18]],"ltp":1.5,"tv":41.41,"id":7414058}]}]}
{"op":"mcm","clk":"1004817063","pt":1580637816375,"mc":[{"id":"1.168224552","rc":[{"batl":[[2,1.98,15.14]],"ltp":1.5,"tv":41.41,"id":7414058}]}]}
{"op":"mcm","clk":"1004821925","pt":1580637894945,"mc":[{"id":"1.168224552","rc":[{"batb":[[0,1.44,128.67],[1,1.43,84.51],[2,1.38,65.88]],"ltp":1.5,"tv":41.41,"id":7414058}]}]}
{"op":"mcm","clk":"1004822022","pt":1580637896451,"mc":[{"id":"1.168224552","rc":[{"batb":[[1,1.38,65.88],[2,1.31,37.86]],"ltp":1.5,"tv":41.41,"id":7414058}]}]}
{"op":"mcm","clk":"1004822051","pt":1580637896917,"mc":[{"id":"1.168224552","rc":[{"batb":[[0,1.45,44.3],[1,1.44,128.67],[2,1.41,92.34]],"ltp":1.5,"tv":41.41,"id":7414058}]}]}
{"op":"mcm","clk":"1004822202","pt":1580637899361,"mc":[{"id":"1.168224552","rc":[{"batb":[[1,2.5,37.86],[2,2.28,29.58]],"ltp":3.0,"tv":20.87,"id":7287690}]}]}
{"op":"mcm","clk":"1004822288","pt":1580637900354,"mc":[{"id":"1.168224552","rc":[{"trd":[[1.45,27.8]],"batb":[[0,1.45,35.45],[2,1.43,65.88]],"ltp":1.45,"tv":59.1,"id":7414058}],"tv":79.98}]}
{"op":"mcm","clk":"1004822458","pt":1580637902445,"mc":[{"id":"1.168224552","rc":[{"batb":[[0,2.92,44.63]],"ltp":3.0,"tv":20.87,"id":7287690}]}]}
{"op":"mcm","clk":"1004823187","pt":1580637912463,"mc":[{"id":"1.168224552","rc":[{"batb":[[2,2.44,37.1]],"ltp":3.0,"tv":20.87,"id":7287690},{"batb":[[0,1.46,126.88],[1,1.45,35.45],[2,1.42,65.88]],"ltp":1.45,"tv":59.1,"id":7414058}]}]}
{"op":"mcm","clk":"1004824451","pt":1580637930994,"mc":[{"id":"1.168224552","rc":[{"batl":[[0,1.52,7.57]],"ltp":1.45,"tv":59.1,"id":7414058}]}]}
{"op":"mcm","clk":"1004826400","pt":1580637964655,"mc":[{"id":"1.168224552","rc":[{"batb":[[0,1.45,35.45],[1,1.42,65.88],[2,1.41,92.34]],"ltp":1.45,"tv":59.1,"id":7414058}]}]}
{"op":"mcm","clk":"1004830590","pt":1580638030382,"mc":[{"id":"1.168224552","rc":[{"batb":[[0,2.92,21.99]],"ltp":3.0,"tv":20.87,"id":7287690}]}]}
{"op":"mcm","clk":"1004830607","pt":1580638030653,"mc":[{"id":"1.168224552","rc":[{"batb":[[0,2.94,22.64],[1,2.92,21.99],[2,2.5,37.86]],"ltp":3.0,"tv":20.87,"id":7287690},{"batb":[[0,1.43,75.68]],"ltp":1.45,"tv":59.1,"id":7414058}]}]}
{"op":"mcm","clk":"1004834408","pt":1580638087444,"mc":[{"id":"1.168224552","rc":[{"batb":[[1,1.41,92.34],[2,1.31,37.86]],"ltp":1.45,"tv":59.1,"id":7414058}]}]}
{"op":"mcm","clk":"1004834414","pt":1580638087549,"mc":[{"id":"1.168224552","rc":[{"batb":[[0,1.43,141.56]],"ltp":1.45,"tv":59.1,"id":7414058}]}]}
{"op":"mcm","clk":"1004839709","pt":1580638165684,"mc":[{"id":"1.168224552","rc":[{"batl":[[0,3.1,15.74],[1,5.7,153.72],[2,95,15.9]],"ltp":3.0,"tv":20.87,"id":7287690}]}]}
{"op":"mcm","clk":"1004840135","pt":1580638171659,"mc":[{"id":"1.168224552","rc":[{"batb":[[2,2.5,74.97]],"ltp":3.0,"tv":20.87,"id":7287690},{"batb":[[0,1.45,65.88],[1,1.43,75.68],[2,1.41,92.34]],"batl":[[0,1.52,7.72],[1,1.65,25.33]],"ltp":1.45,"tv":59.1,"id":7414058}]}]}
{"op":"mcm","clk":"1004841051","pt":1580638184074,"mc":[{"id":"1.168224552","rc":[{"batb":[[2,2.5,37.86]],"ltp":3.0,"tv":20.87,"id":7287690},{"batb":[[0,1.44,65.88]],"batl":[[0,1.52,7.57],[1,1.65,25.48]],"ltp":1.45,"tv":59.1,"id":7414058}]}]}
{"op":"mcm","clk":"1004843104","pt":1580638212442,"mc":[{"id":"1.168224552","rc":[{"trd":[[2.94,45.29]],"batb":[[0,2.5,37.86],[1,2.46,37.1],[2,2.28,29.58]],"ltp":2.94,"tv":66.16,"id":7287690},{"trd":[[1.52,12.06]],"batb":[[1,1.41,92.34],[2,1.31,37.86]],"batl":[[0,1.52,1.54]],"ltp":1.52,"tv":71.16,"id":7414058}],"tv":137.32}]}
{"op":"mcm","clk":"1004843146","pt":1580638213110,"mc":[{"id":"1.168224552","rc":[{"batb":[[0,2.82,46.51],[1,2.5,37.86],[2,2.46,37.1]],"ltp":2.94,"tv":66.16,"id":7287690},{"trd":[[1.51,12.14]],"batb":[[0,1.48,24.86],[1,1.44,65.88],[2,1.41,130.21]],"ltp":1.51,"tv":83.29,"id":7414058}],"tv":149.46}]}
{"op":"mcm","clk":"1004846381","pt":1580638261191,"mc":[{"id":"1.168224552","rc":[{"batb":[[2,1.41,92.34]],"ltp":1.51,"tv":83.29,"id":7414058}]}]}
{"op":"mcm","clk":"1004846463","pt":1580638262284,"mc":[{"id":"1.168224552","rc":[{"trd":[[2.82,6.4],[2.92,0.8]],"batb":[[0,2.82,43.31]],"ltp":2.82,"tv":73.36,"id":7287690},{"trd":[[1.52,13.6]],"batl":[[0,1.65,25.48],[1,1.98,15.14],[2,1.99,153.72]],"ltp":1.52,"tv":84.84,"id":7414058}],"tv":158.2}]}
{"op":"mcm","clk":"1004846514","pt":1580638263022,"mc":[{"id":"1.168224552","rc":[{"trd":[[2.92,29.2]],"batb":[[0,2.8,48.54]],"batl":[[0,2.92,27.81],[1,3.1,15.74],[2,5.7,153.72]],"ltp":2.92,"tv":101.76,"id":7287690},{"batb":[[0,1.48,30.93]],"ltp":1.52,"tv":84.84,"id":7414058}],"tv":186.6}]}
{"op":"mcm","clk":"1004846629","pt":1580638264489,"mc":[{"id":"1.168224552","rc":[{"batb":[[0,1.51,1.55],[1,1.48,30.93],[2,1.44,65.88]],"ltp":1.52,"tv":84.84,"id":7414058}]}]}
{"op":"mcm","clk":"1004847544","pt":1580638277325,"mc":[{"id":"1.168224552","rc":[{"batl":[[0,3.1,15.74],[1,5.7,153.72],[2,95,15.9]],"ltp":2.92,"tv":101.76,"id":7287690},{"batb":[[0,1.48,30.93],[1,1.44,65.88],[2,1.41,130.21]],"ltp":1.52,"tv":84.84,"id":7414058}]}]}
{"op":"mcm","clk":"1004847673","pt":1580638279426,"mc":[{"id":"1.168224552","rc":[{"batl":[[0,1.55,7.57],[1,1.65,25.48],[2,1.98,15.14]],"ltp":1.52,"tv":84.84,"id":7414058}]}]}
{"op":"mcm","clk":"1004847681","pt":1580638279630,"mc":[{"id":"1.168224552","rc":[{"trd":[[1.53,3.08]],"ltp":1.53,"tv":87.91,"id":7414058}],"tv":189.68}]}
{"op":"mcm","clk":"1004847908","pt":1580638282437,"mc":[{"id":"1.168224552","rc":[{"batl":[[0,1.53,7.57],[1,1.55,7.57],[2,1.65,25.48]],"ltp":1.53,"tv":87.91,"id":7414058}]}]}
{"op":"mcm","clk":"1004848121","pt":1580638285125,"mc":[{"id":"1.168224552","rc":[{"batl":[[1,1.65,25.48],[2,1.98,15.14]],"ltp":1.53,"tv":87.91,"id":7414058}]}]}
{"op":"mcm","clk":"1004858680","pt":1580638419484,"mc":[{"id":"1.168224552","rc":[{"batb":[[0,2.5,37.86],[1,2.46,37.1],[2,2.28,29.58]],"ltp":2.92,"tv":101.76,"id":7287690}]}]}
{"op":"mcm","clk":"1004858747","pt":1580638420386,"mc":[{"id":"1.168224552","rc":[{"batb":[[0,2.9,23.98],[1,2.5,37.86],[2,2.46,37.1]],"ltp":2.92,"tv":101.76,"id":7287690},{"trd":[[1.53,15.2]],"batl":[[0,1.53,1.51]],"ltp":1.53,"tv":100.03,"id":7414058}],"tv":201.8}]}
{"op":"mcm","clk":"1004858792","pt":1580638421119,"mc":[{"id":"1.168224552","rc":[{"trd":[[1.52,25.8]],"ltp":1.52,"tv":112.23,"id":7414058}],"tv":213.99}]}
{"op":"mcm","clk":"1004869552","pt":1580638550472,"mc":[{"id":"1.168224552","rc":[{"batb":[[0,2.5,37.86],[1,2.46,37.1],[2,2.28,29.58]],"ltp":2.92,"tv":101.76,"id":7287690}]}]}
{"op":"mcm","clk":"1004869585","pt":1580638550737,"mc":[{"id":"1.168224552","rc":[{"batb":[[0,2.8,48.54],[1,2.5,37.86],[2,2.46,37.1]],"ltp":2.92,"tv":101.76,"id":7287690}]}]}
{"op":"mcm","clk":"1004870163","pt":1580638559157,"mc":[{"id":"1.168224552","rc":[{"trd":[[2.8,10.4],[2.88,0.8]],"batb":[[0,2.78,48.72]],"ltp":2.8,"tv":112.96,"id":7287690},{"trd":[[1.53,16.71]],"batb":[[0,1.48,40.7]],"batl":[[0,1.65,25.48],[1,1.98,15.14],[2,1.99,153.72]],"ltp":1.53,"tv":113.74,"id":7414058}],"tv":226.71}]}
{"op":"mcm","clk":"1004870271","pt":1580638560673,"mc":[{"id":"1.168224552","rc":[{"batb":[[0,1.52,1.52],[1,1.48,40.7],[2,1.44,65.88]],"ltp":1.53,"tv":113.74,"id":7414058}]}]}
{"op":"mcm","clk":"1004895122","pt":1580638871345,"mc":[{"id":"1.168224552","rc":[{"trd":[[2.78,12]],"batb":[[0,2.76,48.23]],"ltp":2.78,"tv":124.96,"id":7287690},{"batb":[[1,1.48,51.87]],"ltp":1.53,"tv":113.74,"id":7414058}],"tv":238.71}]}
{"op":"mcm","clk":"1004924139","pt":1580639169210,"mc":[{"id":"1.168224552","rc":[{"trd":[[2.76,14]],"batb":[[0,2.76,41.23]],"ltp":2.76,"tv":138.96,"id":7287690}],"tv":252.71}]}
{"op":"mcm","clk":"1004924217","pt":1580639169896,"mc":[{"id":"1.168224552","rc":[{"batb":[[0,2.74,46.85]],"ltp":2.76,"tv":138.96,"id":7287690},{"batb":[[1,1.48,64.78]],"ltp":1.53,"tv":113.74,"id":7414058}]}]}
{"op":"mcm","clk":"1004932294","pt":1580639241265,"mc":[{"id":"1.168224552","rc":[{"trd":[[2.74,14]],"batb":[[0,2.74,39.85]],"ltp":2.74,"tv":152.96,"id":7287690}],"tv":266.7}]}
{"op":"mcm","clk":"1004932386","pt":1580639241954,"mc":[{"id":"1.168224552","rc":[{"batb":[[0,2.72,45.56]],"ltp":2.74,"tv":152.96,"id":7287690},{"batb":[[1,1.48,77.55]],"ltp":1.53,"tv":113.74,"id":7414058}]}]}
{"op":"mcm","clk":"1004943039","pt":1580639345396,"mc":[{"id":"1.168224552","rc":[{"trd":[[1.58,12.3]],"batl":[[0,1.58,1.42],[1,1.65,25.48],[2,1.98,15.14]],"ltp":1.58,"tv":126.04,"id":7414058}],"tv":279.0}]}
{"op":"mcm","clk":"1004943147","pt":1580639346288,"mc":[{"id":"1.168224552","rc":[{"batb":[[1,2.46,37.1],[2,2.28,37.27]],"ltp":2.74,"tv":152.96,"id":7287690},{"trd":[[1.57,12.38]],"ltp":1.57,"tv":138.42,"id":7414058}],"tv":291.38}]}
{"op":"mcm","clk":"1004943275","pt":1580639347721,"mc":[{"id":"1.168224552","rc":[{"batl":[[0,1.58,9]],"ltp":1.57,"tv":138.42,"id":7414058}]}]}
{"op":"mcm","clk":"1004946249","pt":1580639377440,"mc":[{"id":"1.168224552","rc":[{"trd":[[1.58,28.14]],"batl":[[0,1.58,1.08]],"ltp":1.58,"tv":154.26,"id":7414058}],"tv":307.22}]}
{"op":"mcm","clk":"1004948056","pt":1580639396188,"mc":[{"id":"1.168224552","rc":[{"batb":[[0,1.48,77.55],[1,1.44,65.88],[2,1.41,154.22]],"batl":[[0,1.65,25.48],[1,1.98,15.14],[2,1.99,153.72]],"ltp":1.58,"tv":154.26,"id":7414058}]}]}
{"op":"mcm","clk":"1004948149","pt":1580639397349,"mc":[{"id":"1.168224552","rc":[{"batl":[[0,1.57,7.57],[1,1.65,25.48],[2,1.98,15.14]],"ltp":1.58,"tv":154.26,"id":7414058}]}]}
{"op":"mcm","clk":"1004948170","pt":1580639397661,"mc":[{"id":"1.168224552","rc":[{"batb":[[0,1.52,9.76],[1,1.48,77.55],[2,1.44,65.88]],"ltp":1.58,"tv":154.26,"id":7414058}]}]}
{"op":"mcm","clk":"1004948324","pt":1580639399380,"mc":[{"id":"1.168224552","rc":[{"batl":[[0,1.58,7.57]],"ltp":1.58,"tv":154.26,"id":7414058}]}]}
{"op":"mcm","clk":"1004949474","pt":1580639408395,"mc":[{"id":"1.168224552","rc":[{"trd":[[1.58,40.46]],"batl":[[0,1.58,1.57],[1,1.65,25.33]],"ltp":1.58,"tv":166.57,"id":7414058}],"tv":319.54}]}
{"op":"mcm","clk":"1004949554","pt":1580639409272,"mc":[{"id":"1.168224552","rc":[{"trd":[[1.57,24.76]],"ltp":1.57,"tv":178.96,"id":7414058}],"tv":331.92}]}
{"op":"mcm","clk":"1004949821","pt":1580639411786,"mc":[{"id":"1.168224552","rc":[{"batl":[[0,1.58,16.71]],"ltp":1.57,"tv":178.96,"id":7414058}]}]}
{"op":"mcm","clk":"1004950399","pt":1580639416482,"mc":[{"id":"1.168224552","rc":[{"batl":[[0,1.58,24.28]],"ltp":1.57,"tv":178.96,"id":7414058}]}]}
{"op":"mcm","clk":"1004950602","pt":1580639418702,"mc":[{"id":"1.168224552","rc":[{"batb":[[0,1.53,9.76]],"ltp":1.57,"tv":178.96,"id":7414058}]}]}
{"op":"mcm","clk":"1004950776","pt":1580639420482,"mc":[{"id":"1.168224552","rc":[{"batb":[[0,1.48,77.55],[1,1.44,65.88],[2,1.41,154.22]],"ltp":1.57,"tv":178.96,"id":7414058}]}]}
{"op":"mcm","clk":"1004950788","pt":1580639420588,"mc":[{"id":"1.168224552","rc":[{"batb":[[0,1.54,9.76],[1,1.48,77.55],[2,1.44,65.88]],"ltp":1.57,"tv":178.96,"id":7414058}]}]}
{"op":"mcm","clk":"1004951067","pt":1580639423394,"mc":[{"id":"1.168224552","rc":[{"batb":[[0,1.55,9.76]],"ltp":1.57,"tv":178.96,"id":7414058}]}]}
{"op":"mcm","clk":"1004951074","pt":1580639423500,"mc":[{"id":"1.168224552","rc":[{"trd":[[1.55,6.26]],"batb":[[0,1.55,6.63]],"ltp":1.55,"tv":185.22,"id":7414058}],"tv":338.18}]}
{"op":"mcm","clk":"1004951390","pt":1580639427105,"mc":[{"id":"1.168224552","rc":[{"batb":[[0,1.56,6.63]],"ltp":1.55,"tv":185.22,"id":7414058}]}]}
{"op":"mcm","clk":"1004951590","pt":1580639429190,"mc":[{"id":"1.168224552","rc":[{"batb":[[0,1.55,6.63]],"ltp":1.55,"tv":185.22,"id":7414058}]}]}
{"op":"mcm","clk":"1004951670","pt":1580639430020,"mc":[{"id":"1.168224552","rc":[{"batl":[[0,1.65,25.48],[1,1.98,15.14],[2,1.99,153.72]],"ltp":1.55,"tv":185.22,"id":7414058}]}]}
{"op":"mcm","clk":"1004951891","pt":1580639432327,"mc":[{"id":"1.168224552","rc":[{"batb":[[0,1.48,77.55],[1,1.44,65.88],[2,1.41,154.22]],"ltp":1.55,"tv":185.22,"id":7414058}]}]}
{"op":"mcm","clk":"1004951992","pt":1580639433421,"mc":[{"id":"1.168224552","rc":[{"batb":[[0,1.53,6.53],[1,1.48,77.55],[2,1.44,65.88]],"batl":[[0,1.58,7.72],[1,1.65,25.33],[2,1.98,15.14]],"ltp":1.55,"tv":185.22,"id":7414058}]}]}
{"op":"mcm","clk":"1004955034","pt":1580639463442,"mc":[{"id":"1.168224552","rc":[{"trd":[[2.74,34]],"batb":[[0,2.74,35.56],[1,2.72,45.56],[2,2.46,37.1]],"ltp":2.74,"tv":172.96,"id":7287690},{"batb":[[1,1.48,155.11]],"ltp":1.55,"tv":185.22,"id":7414058}],"tv":358.18}]}
{"op":"mcm","clk":"1004955089","pt":1580639463968,"mc":[{"id":"1.168224552","rc":[{"batb":[[1,1.48,173.32]],"ltp":1.55,"tv":185.22,"id":7414058}]}]}
{"op":"mcm","clk":"1004957651","pt":1580639489936,"mc":[{"id":"1.168224552","rc":[{"batl":[[0,1.58,15.3]],"ltp":1.55,"tv":185.22,"id":7414058}]}]}
{"op":"mcm","clk":"1004961851","pt":1580639530181,"mc":[{"id":"1.168224552","rc":[{"trd":[[2.74,54]],"batb":[[0,2.74,25.56]],"ltp":2.74,"tv":192.95,"id":7287690},{"batb":[[1,1.49,155.91]],"ltp":1.55,"tv":185.22,"id":7414058}],"tv":378.18}]}
{"op":"mcm","clk":"1004981958","pt":1580639742879,"mc":[{"id":"1.168224552","rc":[{"batl":[[0,1.57,7.57],[1,1.58,15.3],[2,1.65,25.33]],"ltp":1.55,"tv":185.22,"id":7414058}]}]}
{"op":"mcm","clk":"1004982105","pt":1580639744358,"mc":[{"id":"1.168224552","rc":[{"trd":[[1.57,37.14]],"batb":[[0,1.56,6.22],[1,1.53,6.53],[2,1.49,155.91]],"batl":[[0,1.57,1.39]],"ltp":1.57,"tv":197.59,"id":7414058}],"tv":390.55}]}
{"op":"mcm","clk":"1004982308","pt":1580639746278,"mc":[{"id":"1.168224552","rc":[{"batl":[[0,1.58,15.3],[1,1.65,25.33],[2,1.98,15.14]],"ltp":1.57,"tv":197.59,"id":7414058}]}]}
{"op":"mcm","clk":"1004982665","pt":1580639750004,"mc":[{"id":"1.168224552","rc":[{"batl":[[0,1.65,25.48],[1,1.98,15.14],[2,1.99,153.72]],"ltp":1.57,"tv":197.59,"id":7414058}]}]}
{"op":"mcm","clk":"1004982908","pt":1580639752298,"mc":[{"id":"1.168224552","rc":[{"batb":[[0,1.57,6.22]],"ltp":1.57,"tv":197.59,"id":7414058}]}]}
{"op":"mcm","clk":"1004983167","pt":1580639755006,"mc":[{"id":"1.168224552","rc":[{"batb":[[0,1.54,6.22]],"ltp":1.57,"tv":197.59,"id":7414058}]}]}
{"op":"mcm","clk":"1004983272","pt":1580639756202,"mc":[{"id":"1.168224552","rc":[{"batb":[[0,1.49,155.91],[1,1.44,65.88],[2,1.41,154.22]],"ltp":1.57,"tv":197.59,"id":7414058}]}]}
{"op":"mcm","clk":"1004983396","pt":1580639757405,"mc":[{"id":"1.168224552","rc":[{"batb":[[0,1.53,12.88],[1,1.49,155.91],[2,1.44,65.88]],"ltp":1.57,"tv":197.59,"id":7414058}]}]}
{"op":"mcm","clk":"1004990241","pt":1580639828978,"mc":[{"id":"1.168224552","rc":[{"batb":[[0,2.68,94.12],[1,2.46,37.1],[2,2.28,37.27]],"ltp":2.74,"tv":192.95,"id":7287690}]}]}
{"op":"mcm","clk":"1004990700","pt":1580639833114,"mc":[{"id":"1.168224552","rc":[{"batl":[[0,1.59,7.72],[1,1.65,25.33],[2,1.98,15.14]],"ltp":1.57,"tv":197.59,"id":7414058}]}]}
{"op":"mcm","clk":"1004998913","pt":1580639919879,"mc":[{"id":"1.168224552","rc":[{"batb":[[0,1.55,12.88]],"ltp":1.57,"tv":197.59,"id":7414058}]}]}
{"op":"mcm","clk":"1004999033","pt":1580639920979,"mc":[{"id":"1.168224552","rc":[{"trd":[[1.58,40.76],[1.59,12.12]],"batl":[[0,1.59,1.51]],"ltp":1.59,"tv":210.01,"id":7414058}],"tv":402.97}]}
{"op":"mcm","clk":"1004999143","pt":1580639922075,"mc":[{"id":"1.168224552","rc":[{"batb":[[0,1.58,6.1]],"ltp":1.59,"tv":210.01,"id":7414058}]}]}
{"op":"mcm","clk":"1004999432","pt":1580639924854,"mc":[{"id":"1.168224552","rc":[{"batb":[[0,1.57,6.1]],"ltp":1.59,"tv":210.01,"id":7414058}]}]}
{"op":"mcm","clk":"1004999705","pt":1580639927783,"mc":[{"id":"1.168224552","rc":[{"batb":[[0,1.49,155.91],[1,1.44,65.88],[2,1.41,154.22]],"batl":[[0,1.65,25.33],[1,1.98,15.14],[2,1.99,153.72]],"ltp":1.59,"tv":210.01,"id":7414058}]}]}
{"op":"mcm","clk":"1004999821","pt":1580639929091,"mc":[{"id":"1.168224552","rc":[{"batb":[[0,1.53,19.17],[1,1.49,155.91],[2,1.44,65.88]],"ltp":1.59,"tv":210.01,"id":7414058}]}]}
{"op":"mcm","clk":"1005040271","pt":1580640287349,"mc":[{"id":"1.168224552","rc":[{"trd":[[2.68,22]],"batb":[[0,2.68,83.12]],"ltp":2.68,"tv":214.95,"id":7287690}],"tv":424.97}]}
{"op":"mcm","clk":"1005040330","pt":1580640287871,"mc":[{"id":"1.168224552","rc":[{"batb":[[0,2.66,95.09]],"ltp":2.68,"tv":214.95,"id":7287690},{"batb":[[1,1.49,175.37]],"ltp":1.59,"tv":210.01,"id":7414058}]}]}
{"op":"mcm","clk":"1005045425","pt":1580640322409,"mc":[{"id":"1.168224552","rc":[{"trd":[[2.66,22]],"batb":[[0,2.66,84.1]],"ltp":2.66,"tv":236.95,"id":7287690},{"batb":[[0,1.57,7.57],[1,1.53,19.17],[2,1.49,175.37]],"ltp":1.59,"tv":210.01,"id":7414058}],"tv":446.97}]}
{"op":"mcm","clk":"1005045563","pt":1580640323407,"mc":[{"id":"1.168224552","rc":[{"trd":[[1.57,52.28]],"batb":[[0,1.53,19.17],[1,1.49,175.37],[2,1.44,65.88]],"ltp":1.57,"tv":225.15,"id":7414058}],"tv":462.11}]}
{"op":"mcm","clk":"1005045695","pt":1580640324301,"mc":[{"id":"1.168224552","rc":[{"batb":[[0,2.64,91.93]],"ltp":2.66,"tv":236.95,"id":7287690},{"batb":[[0,1.5,167.77],[1,1.44,65.88],[2,1.41,154.22]],"batl":[[0,1.58,7.53],[1,1.65,25.33],[2,1.98,15.14]],"ltp":1.57,"tv":225.15,"id":7414058}]}]}
{"op":"mcm","clk":"1005046468","pt":1580640329813,"mc":[{"id":"1.168224552","rc":[{"batb":[[0,1.55,7.57],[1,1.5,167.77],[2,1.44,65.88]],"ltp":1.57,"tv":225.15,"id":7414058}]}]}
{"op":"mcm","clk":"1005047163","pt":1580640334834,"mc":[{"id":"1.168224552","rc":[{"batl":[[0,1.59,7.53]],"ltp":1.57,"tv":225.15,"id":7414058}]}]}
{"op":"mcm","clk":"1005047411","pt":1580640336832,"mc":[{"id":"1.168224552","rc":[{"batb":[[0,1.57,7.57],[1,1.55,7.57],[2,1.5,167.77]],"ltp":1.57,"tv":225.15,"id":7414058}]}]}
{"op":"mcm","clk":"1005047623","pt":1580640338495,"mc":[{"id":"1.168224552","rc":[{"batb":[[1,1.5,167.77],[2,1.44,65.88]],"ltp":1.57,"tv":225.15,"id":7414058}]}]}
{"op":"mcm","clk":"1005048289","pt":1580640343315,"mc":[{"id":"1.168224552","rc":[{"batb":[[0,1.5,167.77],[1,1.44,65.88],[2,1.41,154.22]],"batl":[[0,1.59,7.57]],"ltp":1.57,"tv":225.15,"id":7414058}]}]}
{"op":"mcm","clk":"1005048323","pt":1580640343646,"mc":[{"id":"1.168224552","rc":[{"batb":[[0,1.53,11.4],[1,1.5,167.77],[2,1.44,65.88]],"ltp":1.57,"tv":225.15,"id":7414058}]}]}
{"op":"mcm","clk":"1005055953","pt":1580640401422,"mc":[{"id":"1.168224552","rc":[{"batb":[[2,2.22,37.86]],"ltp":2.66,"tv":236.95,"id":7287690}]}]}
{"op":"mcm","clk":"1005056043","pt":1580640402191,"mc":[{"id":"1.168224552","rc":[{"batb":[[2,2.3,36.7]],"ltp":2.66,"tv":236.95,"id":7287690}]}]}
{"op":"mcm","clk":"1005056164","pt":1580640403086,"mc":[{"id":"1.168224552","rc":[{"trd":[[1.59,24.64]],"batb":[[0,1.58,6.3],[1,1.53,11.4],[2,1.5,167.77]],"batl":[[0,1.59,1.31]],"ltp":1.59,"tv":237.68,"id":7414058}],"tv":474.63}]}
{"op":"mcm","clk":"1005056959","pt":1580640408916,"mc":[{"id":"1.168224552","rc":[{"batb":[[0,1.57,6.3]],"ltp":1.59,"tv":237.68,"id":7414058}]}]}
{"op":"mcm","clk":"1005066276","pt":1580640484474,"mc":[{"id":"1.168224552","rc":[{"trd":[[1.57,64.88]],"batb":[[0,1.53,11.4],[1,1.5,167.77],[2,1.44,65.88]],"ltp":1.57,"tv":250.28,"id":7414058}],"tv":487.23}]}
{"op":"mcm","clk":"1005066332","pt":1580640484888,"mc":[{"id":"1.168224552","rc":[{"batb":[[0,2.62,100.42]],"ltp":2.66,"tv":236.95,"id":7287690},{"batb":[[1,1.5,174.25]],"ltp":1.57,"tv":250.28,"id":7414058}]}]}
{"op":"mcm","clk":"1005066506","pt":1580640486291,"mc":[{"id":"1.168224552","rc":[{"trd":[[2.68,22.78]],"ltp":2.68,"tv":237.73,"id":7287690},{"trd":[[1.59,25.95]],"batl":[[0,1.65,25.33],[1,1.98,15.14],[2,1.99,153.72]],"ltp":1.59,"tv":251.59,"id":7414058}],"tv":489.32}]}
{"op":"mcm","clk":"1005066688","pt":1580640487813,"mc":[{"id":"1.168224552","rc":[{"batb":[[0,1.58,1.32],[1,1.53,11.4],[2,1.5,174.25]],"ltp":1.59,"tv":251.59,"id":7414058}]}]}
{"op":"mcm","clk":"1005067214","pt":1580640492094,"mc":[{"id":"1.168224552","rc":[{"batb":[[0,1.5,174.25],[1,1.44,65.88],[2,1.41,37.86]],"ltp":1.59,"tv":251.59,"id":7414058}]}]}
{"op":"mcm","clk":"1005067343","pt":1580640493195,"mc":[{"id":"1.168224552","rc":[{"batb":[[0,1.57,11.15],[1,1.5,174.25],[2,1.44,65.88]],"ltp":1.59,"tv":251.59,"id":7414058}]}]}
{"op":"mcm","clk":"1005067499","pt":1580640494490,"mc":[{"id":"1.168224552","rc":[{"batl":[[0,1.61,7.57],[1,1.65,25.33],[2,1.98,15.14]],"ltp":1.59,"tv":251.59,"id":7414058}]}]}
{"op":"mcm","clk":"1005082486","pt":1580640611380,"mc":[{"id":"1.168224552","rc":[{"batb":[[2,2.32,36.14]],"ltp":2.68,"tv":237.73,"id":7287690},{"trd":[[1.61,12.56]],"batb":[[0,1.6,6.32],[1,1.57,11.15],[2,1.5,174.25]],"batl":[[0,1.61,1.29]],"ltp":1.61,"tv":264.14,"id":7414058}],"tv":501.88}]}
{"op":"mcm","clk":"1005082605","pt":1580640612267,"mc":[{"id":"1.168224552","rc":[{"trd":[[1.6,12.22]],"batb":[[0,1.57,11.36],[1,1.5,174.25],[2,1.44,65.88]],"ltp":1.6,"tv":276.37,"id":7414058}],"tv":514.1}]}
{"op":"mcm","clk":"1005082890","pt":1580640614363,"mc":[{"id":"1.168224552","rc":[{"batl":[[0,1.61,8.87]],"ltp":1.6,"tv":276.37,"id":7414058}]}]}
{"op":"mcm","clk":"1005082918","pt":1580640614571,"mc":[{"id":"1.168224552","rc":[{"batl":[[0,1.61,16.44]],"ltp":1.6,"tv":276.37,"id":7414058}]}]}
{"op":"mcm","clk":"1005084393","pt":1580640625299,"mc":[{"id":"1.168224552","rc":[{"batb":[[0,2.62,87.2]],"ltp":2.68,"tv":237.73,"id":7287690},{"trd":[[1.57,87.19],[1.6,12.63]],"batb":[[0,1.5,174.25],[1,1.44,65.88],[2,1.41,37.86]],"ltp":1.57,"tv":299.08,"id":7414058}],"tv":536.82}]}
{"op":"mcm","clk":"1005084439","pt":1580640625709,"mc":[{"id":"1.168224552","rc":[{"batb":[[0,2.64,6.62],[1,2.62,87.2],[2,2.46,37.1]],"ltp":2.68,"tv":237.73,"id":7287690},{"batb":[[0,1.51,152.19]],"ltp":1.57,"tv":299.08,"id":7414058}]}]}
{"op":"mcm","clk":"1005084885","pt":1580640628998,"mc":[{"id":"1.168224552","rc":[{"batl":[[0,1.65,25.33],[1,1.98,15.14],[2,1.99,153.72]],"ltp":1.57,"tv":299.08,"id":7414058}]}]}
{"op":"mcm","clk":"1005085051","pt":1580640630100,"mc":[{"id":"1.168224552","rc":[{"batl":[[0,1.61,15.14],[1,1.65,25.33],[2,1.98,15.14]],"ltp":1.57,"tv":299.08,"id":7414058}]}]}
{"op":"mcm","clk":"1005085239","pt":1580640631422,"mc":[{"id":"1.168224552","rc":[{"batb":[[0,1.57,1.33],[1,1.51,152.19],[2,1.44,65.88]],"ltp":1.57,"tv":299.08,"id":7414058}]}]}
{"op":"mcm","clk":"1005087973","pt":1580640652855,"mc":[{"id":"1.168224552","rc":[{"trd":[[1.6,25.18]],"batl":[[0,1.6,1.29],[1,1.61,15.14],[2,1.65,25.33]],"ltp":1.6,"tv":311.64,"id":7414058}],"tv":549.38}]}
{"op":"mcm","clk":"1005088072","pt":1580640653746,"mc":[{"id":"1.168224552","rc":[{"batb":[[0,1.59,6.32],[1,1.57,1.33],[2,1.51,152.19]],"ltp":1.6,"tv":311.64,"id":7414058}]}]}
{"op":"mcm","clk":"1005088349","pt":1580640656033,"mc":[{"id":"1.168224552","rc":[{"trd":[[1.59,38.51]],"batb":[[0,1.57,1.36],[1,1.51,152.19],[2,1.44,65.88]],"batl":[[0,1.61,15.14],[1,1.65,25.33],[2,1.98,15.14]],"ltp":1.59,"tv":324.2,"id":7414058}],"tv":561.93}]}
{"op":"mcm","clk":"1005088583","pt":1580640658123,"mc":[{"id":"1.168224552","rc":[{"batl":[[0,1.6,15.14],[1,1.61,15.14],[2,1.65,25.33]],"ltp":1.59,"tv":324.2,"id":7414058}]}]}
{"op":"mcm","clk":"1005089421","pt":1580640665137,"mc":[{"id":"1.168224552","rc":[{"batl":[[0,1.61,15.14],[1,1.65,25.33],[2,1.98,15.14]],"ltp":1.59,"tv":324.2,"id":7414058}]}]}
{"op":"mcm","clk":"1005090174","pt":1580640670975,"mc":[{"id":"1.168224552","rc":[{"batl":[[0,1.61,22.72]],"ltp":1.59,"tv":324.2,"id":7414058}]}]}
{"op":"mcm","clk":"1005090422","pt":1580640673393,"mc":[{"id":"1.168224552","rc":[{"batb":[[0,1.51,152.19],[1,1.44,65.88],[2,1.41,37.86]],"batl":[[0,1.65,25.33],[1,1.98,15.14],[2,1.99,153.72]],"ltp":1.59,"tv":324.2,"id":7414058}]}]}
{"op":"mcm","clk":"1005090523","pt":1580640674070,"mc":[{"id":"1.168224552","rc":[{"batl":[[0,1.6,7.57],[1,1.65,25.33],[2,1.98,15.14]],"ltp":1.59,"tv":324.2,"id":7414058}]}]}
{"op":"mcm","clk":"1005090777","pt":1580640676042,"mc":[{"id":"1.168224552","rc":[{"batb":[[0,1.57,1.37],[1,1.51,152.19],[2,1.44,65.88]],"ltp":1.59,"tv":324.2,"id":7414058}]}]}
{"op":"mcm","clk":"1005092066","pt":1580640686878,"mc":[{"id":"1.168224552","rc":[{"trd":[[1.6,52.14]],"batl":[[0,1.6,1.67]],"ltp":1.6,"tv":351.16,"id":7414058}],"tv":588.89}]}
{"op":"mcm","clk":"1005092133","pt":1580640687504,"mc":[{"id":"1.168224552","rc":[{"batb":[[0,1.59,13.56],[1,1.57,1.37],[2,1.51,152.19]],"ltp":1.6,"tv":351.16,"id":7414058}]}]}
{"op":"mcm","clk":"1005097747","pt":1580640735935,"mc":[{"id":"1.168224552","rc":[{"trd":[[2.64,10.78]],"batb":[[0,2.64,1.23]],"ltp":2.64,"tv":248.52,"id":7287690},{"batl":[[0,1.65,25.33],[1,1.98,15.14],[2,1.99,153.72]],"ltp":1.6,"tv":351.16,"id":7414058}],"tv":599.68}]}
{"op":"mcm","clk":"1005097877","pt":1580640737122,"mc":[{"id":"1.168224552","rc":[{"trd":[[1.59,65.63]],"batb":[[0,1.57,1.37],[1,1.51,152.19],[2,1.44,65.88]],"ltp":1.59,"tv":378.28,"id":7414058}],"tv":626.8}]}
{"op":"mcm","clk":"1005097970","pt":1580640737950,"mc":[{"id":"1.168224552","rc":[{"batb":[[0,2.6,92.88],[1,2.46,37.1],[2,2.32,36.14]],"ltp":2.64,"tv":248.52,"id":7287690},{"batb":[[1,1.51,175.5]],"ltp":1.59,"tv":378.28,"id":7414058}]}]}
{"op":"mcm","clk":"1005098129","pt":1580640739367,"mc":[{"id":"1.168224552","rc":[{"batb":[[0,2.6,170.72]],"ltp":2.64,"tv":248.52,"id":7287690},{"batl":[[0,1.6,15.14],[1,1.65,25.33],[2,1.98,15.14]],"ltp":1.59,"tv":378.28,"id":7414058}]}]}
{"op":"mcm","clk":"1005098211","pt":1580640740143,"mc":[{"id":"1.168224552","rc":[{"batb":[[0,2.6,92.88]],"ltp":2.64,"tv":248.52,"id":7287690},{"batl":[[1,1.61,7.57],[2,1.65,25.33]],"ltp":1.59,"tv":378.28,"id":7414058}]}]}
{"op":"mcm","clk":"1005098431","pt":1580640742334,"mc":[{"id":"1.168224552","rc":[{"batb":[[0,1.51,175.5],[1,1.44,65.88],[2,1.41,37.86]],"batl":[[0,1.65,25.33],[1,1.98,15.14],[2,1.99,153.72]],"ltp":1.59,"tv":378.28,"id":7414058}]}]}
{"op":"mcm","clk":"1005098766","pt":1580640745248,"mc":[{"id":"1.168224552","rc":[{"batb":[[0,2.6,170.72]],"ltp":2.64,"tv":248.52,"id":7287690},{"batb":[[0,1.57,1.37],[1,1.51,175.5],[2,1.44,65.88]],"ltp":1.59,"tv":378.28,"id":7414058}]}]}
{"op":"mcm","clk":"1005100662","pt":1580640761164,"mc":[{"id":"1.168224552","rc":[{"batb":[[0,2.6,92.88]],"ltp":2.64,"tv":248.52,"id":7287690},{"batl":[[0,1.61,15.14],[1,1.65,25.33],[2,1.98,15.14]],"ltp":1.59,"tv":378.28,"id":7414058}]}]}
{"op":"mcm","clk":"1005100900","pt":1580640763156,"mc":[{"id":"1.168224552","rc":[{"batl":[[1,1.62,7.57],[2,1.65,25.33]],"ltp":1.59,"tv":378.28,"id":7414058}]}]}
{"op":"mcm","clk":"1005101057","pt":1580640764364,"mc":[{"id":"1.168224552","rc":[{"trd":[[1.61,39.54]],"batl":[[0,1.6,7.57],[1,1.61,1.65],[2,1.62,7.57]],"ltp":1.61,"tv":405.26,"id":7414058}],"tv":653.78}]}
{"op":"mcm","clk":"1005101186","pt":1580640765362,"mc":[{"id":"1.168224552","rc":[{"trd":[[1.6,63.66]],"batb":[[0,1.59,7.87],[1,1.57,1.37],[2,1.51,175.5]],"batl":[[0,1.61,1.65],[1,1.62,7.57],[2,1.65,25.33]],"ltp":1.6,"tv":416.78,"id":7414058}],"tv":665.3}]}
{"op":"mcm","clk":"1005101306","pt":1580640766388,"mc":[{"id":"1.168224552","rc":[{"trd":[[1.59,80.47],[1.6,64.16]],"batb":[[0,1.57,1.57],[1,1.51,175.5],[2,1.44,65.88]],"ltp":1.59,"tv":432.12,"id":7414058}],"tv":680.64}]}
{"op":"mcm","clk":"1005101468","pt":1580640767379,"mc":[{"id":"1.168224552","rc":[{"batl":[[0,1.61,9.22]],"ltp":1.59,"tv":432.12,"id":7414058}]}]}
{"op":"mcm","clk":"1005101523","pt":1580640767800,"mc":[{"id":"1.168224552","rc":[{"batl":[[0,1.61,16.8]],"ltp":1.59,"tv":432.12,"id":7414058}]}]}
{"op":"mcm","clk":"1005102284","pt":1580640774484,"mc":[{"id":"1.168224552","rc":[{"batl":[[0,1.61,24.37]],"ltp":1.59,"tv":432.12,"id":7414058}]}]}
{"op":"mcm","clk":"1005102462","pt":1580640776208,"mc":[{"id":"1.168224552","rc":[{"batl":[[0,1.62,7.57],[1,1.65,25.33],[2,1.98,15.14]],"ltp":1.59,"tv":432.12,"id":7414058}]}]}
{"op":"mcm","clk":"1005102522","pt":1580640776679,"mc":[{"id":"1.168224552","rc":[{"batl":[[0,1.61,7.57],[1,1.62,7.57],[2,1.65,25.33]],"ltp":1.59,"tv":432.12,"id":7414058}]}]}
{"op":"mcm","clk":"1005102781","pt":1580640778812,"mc":[{"id":"1.168224552","rc":[{"batb":[[0,1.51,175.5],[1,1.44,65.88],[2,1.41,37.86]],"batl":[[0,1.65,25.33],[1,1.98,15.14],[2,1.99,153.72]],"ltp":1.59,"tv":432.12,"id":7414058}]}]}
{"op":"mcm","clk":"1005102923","pt":1580640780008,"mc":[{"id":"1.168224552","rc":[{"batl":[[0,1.61,7.57],[1,1.65,25.33],[2,1.98,15.14]],"ltp":1.59,"tv":432.12,"id":7414058}]}]}
{"op":"mcm","clk":"1005103104","pt":1580640781587,"mc":[{"id":"1.168224552","rc":[{"batb":[[0,1.59,1.55],[1,1.51,175.5],[2,1.44,65.88]],"ltp":1.59,"tv":432.12,"id":7414058}]}]}
{"op":"mcm","clk":"1005103890","pt":1580640788109,"mc":[{"id":"1.168224552","rc":[{"batl":[[0,1.61,15.14]],"ltp":1.59,"tv":432.12,"id":7414058}]}]}
{"op":"mcm","clk":"1005104126","pt":1580640790187,"mc":[{"id":"1.168224552","rc":[{"batl":[[0,1.6,7.57],[1,1.61,15.14],[2,1.65,25.33]],"ltp":1.59,"tv":432.12,"id":7414058}]}]}
{"op":"mcm","clk":"1005104210","pt":1580640791020,"mc":[{"id":"1.168224552","rc":[{"trd":[[1.6,76.76]],"batl":[[0,1.6,1.27]],"ltp":1.6,"tv":444.72,"id":7414058}],"tv":693.24}]}
{"op":"mcm","clk":"1005104493","pt":1580640793610,"mc":[{"id":"1.168224552","rc":[{"batb":[[0,1.59,9.12]],"ltp":1.6,"tv":444.72,"id":7414058}]}]}
{"op":"mcm","clk":"1005104784","pt":1580640795897,"mc":[{"id":"1.168224552","rc":[{"batb":[[0,1.51,175.5],[1,1.44,65.88],[2,1.41,37.86]],"ltp":1.6,"tv":444.72,"id":7414058}]}]}
{"op":"mcm","clk":"1005104905","pt":1580640797039,"mc":[{"id":"1.168224552","rc":[{"batl":[[0,1.65,25.33],[1,1.98,15.14],[2,1.99,153.72]],"ltp":1.6,"tv":444.72,"id":7414058}]}]}
{"op":"mcm","clk":"1005105059","pt":1580640798337,"mc":[{"id":"1.168224552","rc":[{"batb":[[0,1.59,7.89],[1,1.51,175.5],[2,1.44,65.88]],"batl":[[0,1.61,7.57],[1,1.65,25.33],[2,1.98,15.14]],"ltp":1.6,"tv":444.72,"id":7414058}]}]}
{"op":"mcm","clk":"1005106158","pt":1580640808255,"mc":[{"id":"1.168224552","rc":[{"batl":[[0,1.61,15.14]],"ltp":1.6,"tv":444.72,"id":7414058}]}]}
{"op":"mcm","clk":"1005107047","pt":1580640816126,"mc":[{"id":"1.168224552","rc":[{"batl":[[0,1.61,7.57]],"ltp":1.6,"tv":444.72,"id":7414058}]}]}
{"op":"mcm","clk":"1005107433","pt":1580640819462,"mc":[{"id":"1.168224552","rc":[{"batb":[[0,1.51,175.5],[1,1.44,65.88],[2,1.41,37.86]],"ltp":1.6,"tv":444.72,"id":7414058}]}]}
{"op":"mcm","clk":"1005107503","pt":1580640820032,"mc":[{"id":"1.168224552","rc":[{"trd":[[1.61,52.14]],"batb":[[0,1.57,7.89],[1,1.51,175.5],[2,1.44,65.88]],"batl":[[0,1.61,1.27]],"ltp":1.61,"tv":457.32,"id":7414058}],"tv":705.84}]}
{"op":"mcm","clk":"1005107672","pt":1580640821331,"mc":[{"id":"1.168224552","rc":[{"trd":[[1.6,88.98]],"batb":[[0,1.57,8.12]],"ltp":1.6,"tv":469.54,"id":7414058}],"tv":718.06}]}
{"op":"mcm","clk":"1005107756","pt":1580640821965,"mc":[{"id":"1.168224552","rc":[{"batb":[[0,2.6,170.72]],"ltp":2.64,"tv":248.52,"id":7287690}]}]}
{"op":"mcm","clk":"1005108008","pt":1580640823739,"mc":[{"id":"1.168224552","rc":[{"batl":[[0,1.61,7.57]],"ltp":1.6,"tv":469.54,"id":7414058}]}]}
{"op":"mcm","clk":"1005109095","pt":1580640832654,"mc":[{"id":"1.168224552","rc":[{"batb":[[0,2.6,92.88]],"ltp":2.64,"tv":248.52,"id":7287690},{"batl":[[0,1.61,15.14]],"ltp":1.6,"tv":469.54,"id":7414058}]}]}
{"op":"mcm","clk":"1005111386","pt":1580640852085,"mc":[{"id":"1.168224552","rc":[{"trd":[[1.61,91.79]],"batl":[[0,1.61,2.89]],"ltp":1.61,"tv":509.19,"id":7414058}],"tv":757.71}]}
{"op":"mcm","clk":"1005111485","pt":1580640852814,"mc":[{"id":"1.168224552","rc":[{"batb":[[0,1.6,20.17],[1,1.57,7.89],[2,1.51,175.5]],"ltp":1.61,"tv":509.19,"id":7414058}]}]}
{"op":"mcm","clk":"1005111578","pt":1580640853702,"mc":[{"id":"1.168224552","rc":[{"trd":[[1.6,128.89]],"batb":[[0,1.57,8.11],[1,1.51,175.5],[2,1.44,65.88]],"ltp":1.6,"tv":549.1,"id":7414058}],"tv":797.62}]}
{"op":"mcm","clk":"1005111843","pt":1580640855794,"mc":[{"id":"1.168224552","rc":[{"batl":[[0,1.61,10.46]],"ltp":1.6,"tv":549.1,"id":7414058}]}]}
{"op":"mcm","clk":"1005112866","pt":1580640864507,"mc":[{"id":"1.168224552","rc":[{"batl":[[2,1.8,495.23]],"ltp":1.6,"tv":549.1,"id":7414058}]}]}
{"op":"mcm","clk":"1005113520","pt":1580640869882,"mc":[{"id":"1.168224552","rc":[{"batb":[[0,1.6,5.22],[1,1.57,7.89],[2,1.51,175.5]],"ltp":1.6,"tv":549.1,"id":7414058}]}]}
{"op":"mcm","clk":"1005115071","pt":1580640883036,"mc":[{"id":"1.168224552","rc":[{"batl":[[0,1.65,25.33],[1,1.8,495.23],[2,1.9,757.23]],"ltp":1.6,"tv":549.1,"id":7414058}]}]}
{"op":"mcm","clk":"1005115307","pt":1580640885115,"mc":[{"id":"1.168224552","rc":[{"batb":[[0,1.6,5],[1,1.51,175.5],[2,1.44,65.88]],"ltp":1.6,"tv":549.1,"id":7414058}]}]}
{"op":"mcm","clk":"1005115432","pt":1580640886217,"mc":[{"id":"1.168224552","rc":[{"batb":[[0,1.6,13.06]],"ltp":1.6,"tv":549.1,"id":7414058}]}]}
{"op":"mcm","clk":"1005115626","pt":1580640887736,"mc":[{"id":"1.168224552","rc":[{"batl":[[0,1.62,7.57],[1,1.65,25.33],[2,1.8,495.23]],"ltp":1.6,"tv":549.1,"id":7414058}]}]}
{"op":"mcm","clk":"1005115921","pt":1580640890228,"mc":[{"id":"1.168224552","rc":[{"trd":[[1.6,155.02]],"batb":[[0,1.51,175.5],[1,1.44,65.88],[2,1.41,37.86]],"ltp":1.6,"tv":575.23,"id":7414058}],"tv":823.75}]}
{"op":"mcm","clk":"1005116009","pt":1580640891055,"mc":[{"id":"1.168224552","rc":[{"batb":[[0,2.6,85.06]],"ltp":2.64,"tv":248.52,"id":7287690},{"batb":[[0,1.52,156.2]],"ltp":1.6,"tv":575.23,"id":7414058}]}]}
{"op":"mcm","clk":"1005116182","pt":1580640892360,"mc":[{"id":"1.168224552","rc":[{"batl":[[0,1.61,7.57],[1,1.62,7.57],[2,1.65,25.33]],"ltp":1.6,"tv":575.23,"id":7414058}]}]}
{"op":"mcm","clk":"1005116255","pt":1580640892837,"mc":[{"id":"1.168224552","rc":[{"batl":[[0,1.61,22.72]],"ltp":1.6,"tv":575.23,"id":7414058}]}]}
{"op":"mcm","clk":"1005116679","pt":1580640896453,"mc":[{"id":"1.168224552","rc":[{"batl":[[0,1.6,7.57],[1,1.61,22.72],[2,1.62,7.57]],"ltp":1.6,"tv":575.23,"id":7414058}]}]}
{"op":"mcm","clk":"1005116796","pt":1580640897334,"mc":[{"id":"1.168224552","rc":[{"batl":[[1,1.62,7.57],[2,1.65,25.33]],"ltp":1.6,"tv":575.23,"id":7414058}]}]}
{"op":"mcm","clk":"1005116921","pt":1580640898627,"mc":[{"id":"1.168224552","rc":[{"batl":[[0,1.6,15.14]],"ltp":1.6,"tv":575.23,"id":7414058}]}]}
{"op":"mcm","clk":"1005117152","pt":1580640900447,"mc":[{"id":"1.168224552","rc":[{"batl":[[1,1.62,12.51]],"ltp":1.6,"tv":575.23,"id":7414058}]}]}
{"op":"mcm","clk":"1005117267","pt":1580640901486,"mc":[{"id":"1.168224552","rc":[{"batl":[[0,1.61,15.14]],"ltp":1.6,"tv":575.23,"id":7414058}]}]}
{"op":"mcm","clk":"1005122926","pt":1580640946221,"mc":[{"id":"1.168224552","rc":[{"batb":[[2,2.22,37.86]],"ltp":2.64,"tv":248.52,"id":7287690},{"trd":[[1.61,118.85]],"batl":[[0,1.61,1.61]],"ltp":1.61,"tv":602.29,"id":7414058}],"tv":850.81}]}
{"op":"mcm","clk":"1005122959","pt":1580640946491,"mc":[{"id":"1.168224552","rc":[{"batb":[[2,2.38,62]],"ltp":2.64,"tv":248.52,"id":7287690},{"batb":[[2,1.41,246.56]],"ltp":1.61,"tv":602.29,"id":7414058}]}]}
{"op":"mcm","clk":"1005123525","pt":1580640951362,"mc":[{"id":"1.168224552","rc":[{"batl":[[0,1.61,9.19]],"ltp":1.61,"tv":602.29,"id":7414058}]}]}
{"op":"mcm","clk":"1005123547","pt":1580640951524,"mc":[{"id":"1.168224552","rc":[{"batl":[[0,1.61,16.76]],"ltp":1.61,"tv":602.29,"id":7414058}]}]}
{"op":"mcm","clk":"1005124281","pt":1580640957508,"mc":[{"id":"1.168224552","rc":[{"batl":[[0,1.62,4.94],[1,1.65,25.33],[2,1.8,495.23]],"ltp":1.61,"tv":602.29,"id":7414058}]}]}
{"op":"mcm","clk":"1005124498","pt":1580640959110,"mc":[{"id":"1.168224552","rc":[{"batb":[[0,1.57,13.88],[1,1.52,156.2],[2,1.44,65.88]],"batl":[[0,1.61,7.57],[1,1.62,4.94],[2,1.65,25.33]],"ltp":1.61,"tv":602.29,"id":7414058}]}]}
{"op":"mcm","clk":"1005124610","pt":1580640960046,"mc":[{"id":"1.168224552","rc":[{"batl":[[0,1.61,15.14]],"ltp":1.61,"tv":602.29,"id":7414058}]}]}
{"op":"mcm","clk":"1005125233","pt":1580640964838,"mc":[{"id":"1.168224552","rc":[{"batb":[[0,1.52,156.2],[1,1.44,65.88],[2,1.41,246.56]],"batl":[[0,1.62,4.94],[1,1.65,25.33],[2,1.8,495.23]],"ltp":1.61,"tv":602.29,"id":7414058}]}]}
{"op":"mcm","clk":"1005125391","pt":1580640965934,"mc":[{"id":"1.168224552","rc":[{"batb":[[0,1.6,13.62],[1,1.52,156.2],[2,1.44,65.88]],"ltp":1.61,"tv":602.29,"id":7414058}]}]}
{"op":"mcm","clk":"1005132309","pt":1580641022202,"mc":[{"id":"1.168224552","rc":[{"trd":[[1.6,182.26]],"batb":[[0,1.52,156.2],[1,1.44,65.88],[2,1.41,246.56]],"ltp":1.6,"tv":629.53,"id":7414058}],"tv":878.05}]}
{"op":"mcm","clk":"1005132592","pt":1580641024419,"mc":[{"id":"1.168224552","rc":[{"batb":[[0,2.56,102.34]],"ltp":2.64,"tv":248.52,"id":7287690},{"batb":[[0,1.52,170.29]],"ltp":1.6,"tv":629.53,"id":7414058}]}]}
{"op":"mcm","clk":"1005132620","pt":1580641024629,"mc":[{"id":"1.168224552","rc":[{"batb":[[0,2.56,85.81]],"ltp":2.64,"tv":248.52,"id":7287690}]}]}
{"op":"mcm","clk":"1005132908","pt":1580641026295,"mc":[{"id":"1.168224552","rc":[{"batl":[[0,1.61,7.57],[1,1.62,4.94],[2,1.65,25.33]],"ltp":1.6,"tv":629.53,"id":7414058}]}]}
{"op":"mcm","clk":"1005132948","pt":1580641026502,"mc":[{"id":"1.168224552","rc":[{"batl":[[0,1.61,15.14]],"ltp":1.6,"tv":629.53,"id":7414058}]}]}
{"op":"mcm","clk":"1005141282","pt":1580641091487,"mc":[{"id":"1.168224552","rc":[{"trd":[[1.61,145.97]],"batl":[[0,1.61,1.58]],"ltp":1.61,"tv":656.65,"id":7414058}],"tv":905.17}]}
{"op":"mcm","clk":"1005141409","pt":1580641092323,"mc":[{"id":"1.168224552","rc":[{"batb":[[0,1.6,13.65],[1,1.52,170.29],[2,1.44,65.88]],"ltp":1.61,"tv":656.65,"id":7414058}]}]}
{"op":"mcm","clk":"1005141967","pt":1580641097119,"mc":[{"id":"1.168224552","rc":[{"batb":[[1,1.53,2.27],[2,1.52,170.29]],"ltp":1.61,"tv":656.65,"id":7414058}]}]}
{"op":"mcm","clk":"1005145648","pt":1580641125341,"mc":[{"id":"1.168224552","rc":[{"batl":[[0,1.62,4.94],[1,1.65,25.33],[2,1.8,495.23]],"ltp":1.61,"tv":656.65,"id":7414058}]}]}
{"op":"mcm","clk":"1005148664","pt":1580641146974,"mc":[{"id":"1.168224552","rc":[{"batb":[[0,1.59,13.65]],"ltp":1.61,"tv":656.65,"id":7414058}]}]}
{"op":"mcm","clk":"1005149034","pt":1580641149485,"mc":[{"id":"1.168224552","rc":[{"batb":[[0,1.53,2.27],[1,1.52,170.29],[2,1.44,65.88]],"ltp":1.61,"tv":656.65,"id":7414058}]}]}
{"op":"mcm","clk":"1005149046","pt":1580641149619,"mc":[{"id":"1.168224552","rc":[{"batb":[[0,1.58,13.65],[1,1.53,2.27],[2,1.52,170.29]],"ltp":1.61,"tv":656.65,"id":7414058}]}]}
{"op":"mcm","clk":"1005150149","pt":1580641158181,"mc":[{"id":"1.168224552","rc":[{"batb":[[0,2.56,102.34]],"ltp":2.64,"tv":248.52,"id":7287690}]}]}
{"op":"mcm","clk":"1005167307","pt":1580641262472,"mc":[{"id":"1.168224552","rc":[{"batb":[[1,2.38,62],[2,2.22,37.86]],"ltp":2.64,"tv":248.52,"id":7287690}]}]}
{"op":"mcm","clk":"1005167326","pt":1580641262576,"mc":[{"id":"1.168224552","rc":[{"batb":[[1,2.5,37.1],[2,2.38,62]],"ltp":2.64,"tv":248.52,"id":7287690}]}]}
{"op":"mcm","clk":"1005186256","pt":1580641367176,"mc":[{"id":"1.168224552","rc":[{"batb":[[0,1.53,2.27],[1,1.52,170.29],[2,1.43,65.88]],"ltp":1.61,"tv":656.65,"id":7414058}]}]}
{"op":"mcm","clk":"1005186463","pt":1580641368303,"mc":[{"id":"1.168224552","rc":[{"batb":[[0,1.6,13.65],[1,1.53,2.27],[2,1.52,170.29]],"ltp":1.61,"tv":656.65,"id":7414058}]}]}
{"op":"mcm","clk":"1005190388","pt":1580641388427,"mc":[{"id":"1.168224552","rc":[{"batb":[[1,1.52,170.29],[2,1.43,65.88]],"ltp":1.61,"tv":656.65,"id":7414058}]}]}
{"op":"mcm","clk":"1005198032","pt":1580641425250,"mc":[{"id":"1.168224552","rc":[{"batb":[[0,1.57,13.65]],"ltp":1.61,"tv":656.65,"id":7414058}]}]}
{"op":"mcm","clk":"1005198436","pt":1580641427054,"mc":[{"id":"1.168224552","rc":[{"batb":[[0,1.52,170.29],[1,1.43,65.88],[2,1.41,246.56]],"ltp":1.61,"tv":656.65,"id":7414058}]}]}
{"op":"mcm","clk":"1005198678","pt":1580641428245,"mc":[{"id":"1.168224552","rc":[{"batb":[[0,1.57,13.9],[1,1.52,170.29],[2,1.43,65.88]],"ltp":1.61,"tv":656.65,"id":7414058}]}]}
{"op":"mcm","clk":"1005237073","pt":1580641614817,"mc":[{"id":"1.168224552","marketDefinition":{"bspMarket":false,"turnInPlayEnabled":true,"persistenceEnabled":true,"marketBaseRate":5.0,"eventId":"29681742","eventTypeId":"2","numberOfWinners":1,"bettingType":"ODDS","marketType":"MATCH_ODDS","marketTime":"2020-02-02T13:10:00.000Z","suspendTime":"2020-02-02T13:10:00.000Z","bspReconciled":false,"complete":true,"inPlay":false,"crossMatching":true,"runnersVoidable":false,"numberOfActiveRunners":2,"betDelay":0,"status":"OPEN","runners":[{"status":"ACTIVE","sortPriority":1,"id":7414058,"name":"Damir Dzumhur"},{"status":"ACTIVE","sortPriority":2,"id":7287690,"name":"Quentin Halys"}],"regulators":["MR_INT"],"countryCode":"FR","discountAllowed":true,"timezone":"UTC","openDate":"2020-02-02T13:19:00.000Z","version":3148499223,"name":"Match Odds","eventName":"Dzumhur v Halys"}}]}
{"op":"mcm","clk":"1005237509","pt":1580641616832,"mc":[{"id":"1.168224552","marketDefinition":{"bspMarket":false,"turnInPlayEnabled":true,"persistenceEnabled":true,"marketBaseRate":5.0,"eventId":"29681742","eventTypeId":"2","numberOfWinners":1,"bettingType":"ODDS","marketType":"MATCH_ODDS","marketTime":"2020-02-02T13:10:00.000Z","suspendTime":"2020-02-02T13:10:00.000Z","bspReconciled":false,"complete":true,"inPlay":false,"crossMatching":true,"runnersVoidable":false,"numberOfActiveRunners":2,"betDelay":0,"status":"OPEN","runners":[{"status":"ACTIVE","sortPriority":1,"id":7414058,"name":"Damir Dzumhur"},{"status":"ACTIVE","sortPriority":2,"id":7287690,"name":"Quentin Halys"}],"regulators":["MR_INT"],"countryCode":"FR","discountAllowed":true,"timezone":"UTC","openDate":"2020-02-02T13:10:00.000Z","version":3148499223,"name":"Match Odds","eventName":"Dzumhur v Halys"}}]}
{"op":"mcm","clk":"1005250101","pt":1580641678824,"mc":[{"id":"1.168224552","rc":[{"batb":[[1,2.38,62],[2,2.22,37.86]],"ltp":2.64,"tv":248.52,"id":7287690},{"batb":[[2,1.41,246.56]],"ltp":1.61,"tv":656.65,"id":7414058}]}]}
{"op":"mcm","clk":"1005251511","pt":1580641686038,"mc":[{"id":"1.168224552","rc":[{"batb":[[1,2.5,36.35],[2,2.38,62]],"ltp":2.64,"tv":248.52,"id":7287690},{"batb":[[2,1.43,37.86]],"ltp":1.61,"tv":656.65,"id":7414058}]}]}
{"op":"mcm","clk":"1005273347","pt":1580641797956,"mc":[{"id":"1.168224552","rc":[{"batb":[[1,2.48,36.35]],"ltp":2.64,"tv":248.52,"id":7287690}]}]}
{"op":"mcm","clk":"1005277645","pt":1580641821016,"mc":[{"id":"1.168224552","rc":[{"batl":[[0,1.6,2.03],[1,1.62,4.94],[2,1.65,25.33]],"ltp":1.61,"tv":656.65,"id":7414058}]}]}
{"op":"mcm","clk":"1005281115","pt":1580641840040,"mc":[{"id":"1.168224552","rc":[{"batb":[[2,1.43,63.61]],"ltp":1.61,"tv":656.65,"id":7414058}]}]}
{"op":"mcm","clk":"1005295374","pt":1580641914620,"mc":[{"id":"1.168224552","marketDefinition":{"bspMarket":false,"turnInPlayEnabled":true,"persistenceEnabled":true,"marketBaseRate":5.0,"eventId":"29681742","eventTypeId":"2","numberOfWinners":1,"bettingType":"ODDS","marketType":"MATCH_ODDS","marketTime":"2020-02-02T13:08:00.000Z","suspendTime":"2020-02-02T13:08:00.000Z","bspReconciled":false,"complete":true,"inPlay":false,"crossMatching":true,"runnersVoidable":false,"numberOfActiveRunners":2,"betDelay":0,"status":"OPEN","runners":[{"status":"ACTIVE","sortPriority":1,"id":7414058,"name":"Damir Dzumhur"},{"status":"ACTIVE","sortPriority":2,"id":7287690,"name":"Quentin Halys"}],"regulators":["MR_INT"],"countryCode":"FR","discountAllowed":true,"timezone":"UTC","openDate":"2020-02-02T13:10:00.000Z","version":3148508348,"name":"Match Odds","eventName":"Dzumhur v Halys"}}]}
{"op":"mcm","clk":"1005295947","pt":1580641917627,"mc":[{"id":"1.168224552","marketDefinition":{"bspMarket":false,"turnInPlayEnabled":true,"persistenceEnabled":true,"marketBaseRate":5.0,"eventId":"29681742","eventTypeId":"2","numberOfWinners":1,"bettingType":"ODDS","marketType":"MATCH_ODDS","marketTime":"2020-02-02T13:08:00.000Z","suspendTime":"2020-02-02T13:08:00.000Z","bspReconciled":false,"complete":true,"inPlay":false,"crossMatching":true,"runnersVoidable":false,"numberOfActiveRunners":2,"betDelay":0,"status":"OPEN","runners":[{"status":"ACTIVE","sortPriority":1,"id":7414058,"name":"Damir Dzumhur"},{"status":"ACTIVE","sortPriority":2,"id":7287690,"name":"Quentin Halys"}],"regulators":["MR_INT"],"countryCode":"FR","discountAllowed":true,"timezone":"UTC","openDate":"2020-02-02T13:08:00.000Z","version":3148508348,"name":"Match Odds","eventName":"Dzumhur v Halys"}}]}
{"op":"mcm","clk":"1005307189","pt":1580641983443,"mc":[{"id":"1.168224552","rc":[{"batb":[[1,2.38,62],[2,2.22,37.86]],"ltp":2.64,"tv":248.52,"id":7287690},{"batb":[[2,1.41,246.56]],"ltp":1.61,"tv":656.65,"id":7414058}]}]}
{"op":"mcm","clk":"1005308808","pt":1580641992125,"mc":[{"id":"1.168224552","rc":[{"batb":[[1,2.48,36.35],[2,2.38,62]],"ltp":2.64,"tv":248.52,"id":7287690},{"batb":[[2,1.43,37.86]],"ltp":1.61,"tv":656.65,"id":7414058}]}]}
{"op":"mcm","clk":"1005346312","pt":1580642200713,"mc":[{"id":"1.168224552","rc":[{"batb":[[2,1.43,63.61]],"ltp":1.61,"tv":656.65,"id":7414058}]}]}
{"op":"mcm","clk":"1005389931","pt":1580642432818,"mc":[{"id":"1.168224552","rc":[{"batl":[[1,5.5,153.72]],"ltp":2.64,"tv":248.52,"id":7287690}]}]}
{"op":"mcm","clk":"1005397295","pt":1580642473289,"mc":[{"id":"1.168224552","rc":[{"batl":[[1,1.61,7.57],[2,1.62,4.94]],"ltp":1.61,"tv":656.65,"id":7414058}]}]}
{"op":"mcm","clk":"1005397350","pt":1580642473606,"mc":[{"id":"1.168224552","rc":[{"batl":[[1,1.61,15.14]],"ltp":1.61,"tv":656.65,"id":7414058}]}]}
{"op":"mcm","clk":"1005397948","pt":1580642476801,"mc":[{"id":"1.168224552","rc":[{"batb":[[0,1.52,170.29],[1,1.43,63.61],[2,1.41,246.56]],"batl":[[1,1.62,4.94],[2,1.65,25.33]],"ltp":1.61,"tv":656.65,"id":7414058}]}]}
{"op":"mcm","clk":"1005398155","pt":1580642478021,"mc":[{"id":"1.168224552","rc":[{"batb":[[0,1.57,13.9],[1,1.52,170.29],[2,1.43,63.61]],"batl":[[1,1.61,15.14],[2,1.62,4.94]],"ltp":1.61,"tv":656.65,"id":7414058}]}]}
{"op":"mcm","clk":"1005401860","pt":1580642499454,"mc":[{"id":"1.168224552","rc":[{"batb":[[0,2.64,52.64]],"ltp":2.64,"tv":248.52,"id":7287690}]}]}
{"op":"mcm","clk":"1005411114","pt":1580642549410,"mc":[{"id":"1.168224552","rc":[{"batb":[[0,1.52,170.29],[1,1.43,63.61],[2,1.41,246.56]],"ltp":1.61,"tv":656.65,"id":7414058}]}]}
{"op":"mcm","clk":"1005411307","pt":1580642550429,"mc":[{"id":"1.168224552","rc":[{"trd":[[2.64,48.34],[2.66,23.22]],"batb":[[0,2.54,94.38]],"ltp":2.64,"tv":287.29,"id":7287690},{"trd":[[1.6,184.29]],"batb":[[0,1.56,13.9],[1,1.53,170.16],[2,1.43,63.61]],"batl":[[0,1.61,15.14],[1,1.62,4.94],[2,1.65,25.33]],"ltp":1.6,"tv":658.68,"id":7414058}],"tv":945.98}]}
{"op":"mcm","clk":"1005411635","pt":1580642552154,"mc":[{"id":"1.168224552","rc":[{"batb":[[0,1.57,13.9]],"ltp":1.6,"tv":658.68,"id":7414058}]}]}
{"op":"mcm","clk":"1005412296","pt":1580642555447,"mc":[{"id":"1.168224552","rc":[{"batb":[[0,1.53,170.16],[1,1.43,63.61],[2,1.41,246.56]],"ltp":1.6,"tv":658.68,"id":7414058}]}]}
{"op":"mcm","clk":"1005412315","pt":1580642555551,"mc":[{"id":"1.168224552","rc":[{"batb":[[0,1.58,13.9],[1,1.53,170.16],[2,1.43,63.61]],"ltp":1.6,"tv":658.68,"id":7414058}]}]}
{"op":"mcm","clk":"1005412757","pt":1580642557840,"mc":[{"id":"1.168224552","rc":[{"batb":[[0,1.59,13.9]],"ltp":1.6,"tv":658.68,"id":7414058}]}]}
{"op":"mcm","clk":"1005413314","pt":1580642560839,"mc":[{"id":"1.168224552","rc":[{"batb":[[0,1.57,13.9]],"ltp":1.6,"tv":658.68,"id":7414058}]}]}
{"op":"mcm","clk":"1005413572","pt":1580642562277,"mc":[{"id":"1.168224552","rc":[{"batl":[[0,1.61,7.57]],"ltp":1.6,"tv":658.68,"id":7414058}]}]}
{"op":"mcm","clk":"1005441295","pt":1580642705046,"mc":[{"id":"1.168224552","rc":[{"trd":[[1.57,114.56]],"batb":[[0,1.53,170.37],[1,1.43,63.61],[2,1.41,246.56]],"ltp":1.57,"tv":686.05,"id":7414058}],"tv":973.35}]}
{"op":"mcm","clk":"1005441472","pt":1580642706056,"mc":[{"id":"1.168224552","rc":[{"trd":[[1.61,158.91]],"batl":[[0,1.61,1.11]],"ltp":1.61,"tv":698.98,"id":7414058}],"tv":986.28}]}
{"op":"mcm","clk":"1005441608","pt":1580642706685,"mc":[{"id":"1.168224552","rc":[{"batb":[[0,1.6,6.5],[1,1.53,170.37],[2,1.43,63.61]],"ltp":1.61,"tv":698.98,"id":7414058}]}]}
{"op":"mcm","clk":"1005442083","pt":1580642709094,"mc":[{"id":"1.168224552","rc":[{"batb":[[0,1.53,170.16],[1,1.43,63.61],[2,1.41,246.56]],"batl":[[0,1.62,4.94],[1,1.65,25.33],[2,1.8,495.99]],"ltp":1.61,"tv":698.98,"id":7414058}]}]}
{"op":"mcm","clk":"1005442347","pt":1580642710474,"mc":[{"id":"1.168224552","rc":[{"batb":[[0,1.57,6.85],[1,1.53,170.16],[2,1.43,63.61]],"batl":[[0,1.61,15.14],[1,1.62,4.94],[2,1.65,25.33]],"ltp":1.61,"tv":698.98,"id":7414058}]}]}
{"op":"mcm","clk":"1005453360","pt":1580642770274,"mc":[{"id":"1.168224552","rc":[{"batb":[[2,2.22,37.86]],"ltp":2.64,"tv":287.29,"id":7287690},{"trd":[[1.61,186.69]],"batl":[[0,1.61,1.25]],"ltp":1.61,"tv":726.77,"id":7414058}],"tv":1014.07}]}
{"op":"mcm","clk":"1005453466","pt":1580642770877,"mc":[{"id":"1.168224552","rc":[{"batb":[[2,2.46,80.91]],"ltp":2.64,"tv":287.29,"id":7287690},{"batb":[[0,1.6,13.98],[1,1.57,6.85],[2,1.53,170.16]],"ltp":1.61,"tv":726.77,"id":7414058}]}]}
{"op":"mcm","clk":"1005466708","pt":1580642838804,"mc":[{"id":"1.168224552","rc":[{"batb":[[0,1.58,13.98]],"ltp":1.61,"tv":726.77,"id":7414058}]}]}
{"op":"mcm","clk":"1005467113","pt":1580642841307,"mc":[{"id":"1.168224552","rc":[{"batb":[[0,1.6,6.85],[1,1.58,13.98]],"ltp":1.61,"tv":726.77,"id":7414058}]}]}
{"op":"mcm","clk":"1005467713","pt":1580642844631,"mc":[{"id":"1.168224552","rc":[{"batb":[[1,1.57,13.98]],"ltp":1.61,"tv":726.77,"id":7414058}]}]}
{"op":"mcm","clk":"1005477554","pt":1580642898361,"mc":[{"id":"1.168224552","rc":[{"trd":[[1.6,197.98]],"batb":[[0,1.57,13.98],[1,1.53,170.16],[2,1.43,338.32]],"ltp":1.6,"tv":740.46,"id":7414058}],"tv":1027.76}]}
{"op":"mcm","clk":"1005477908","pt":1580642900306,"mc":[{"id":"1.168224552","rc":[{"batb":[[0,2.54,88.01]],"ltp":2.64,"tv":287.29,"id":7287690},{"batb":[[1,1.53,177.19]],"ltp":1.6,"tv":740.46,"id":7414058}]}]}
{"op":"mcm","clk":"1005482224","pt":1580642925485,"mc":[{"id":"1.168224552","rc":[{"batb":[[0,1.6,7.57],[1,1.57,13.98],[2,1.53,177.19]],"ltp":1.6,"tv":740.46,"id":7414058}]}]}
{"op":"mcm","clk":"1005482472","pt":1580642926946,"mc":[{"id":"1.168224552","rc":[{"batb":[[1,1.53,177.19],[2,1.43,338.32]],"ltp":1.6,"tv":740.46,"id":7414058}]}]}
{"op":"mcm","clk":"1005482835","pt":1580642928843,"mc":[{"id":"1.168224552","rc":[{"batb":[[1,1.57,7.57],[2,1.53,177.19]],"ltp":1.6,"tv":740.46,"id":7414058}]}]}
{"op":"mcm","clk":"1005483060","pt":1580642930191,"mc":[{"id":"1.168224552","rc":[{"batb":[[0,1.57,7.57],[1,1.53,177.19],[2,1.43,338.32]],"ltp":1.6,"tv":740.46,"id":7414058}]}]}
{"op":"mcm","clk":"1005483635","pt":1580642933447,"mc":[{"id":"1.168224552","rc":[{"batb":[[0,1.53,177.19],[1,1.43,338.32],[2,1.41,37.86]],"batl":[[0,1.62,4.94],[1,1.65,25.33],[2,1.8,495.99]],"ltp":1.6,"tv":740.46,"id":7414058}]}]}
{"op":"mcm","clk":"1005483817","pt":1580642934629,"mc":[{"id":"1.168224552","rc":[{"batb":[[0,1.57,14.11],[1,1.53,177.19],[2,1.43,338.32]],"batl":[[0,1.61,7.57],[1,1.62,4.94],[2,1.65,25.33]],"ltp":1.6,"tv":740.46,"id":7414058}]}]}
{"op":"mcm","clk":"1005501269","pt":1580643028467,"mc":[{"id":"1.168224552","rc":[{"batb":[[0,2.54,89.93]],"ltp":2.64,"tv":287.29,"id":7287690}]}]}
{"op":"mcm","clk":"1005501626","pt":1580643030234,"mc":[{"id":"1.168224552","rc":[{"trd":[[1.61,199.69]],"batb":[[0,1.6,6.53],[1,1.57,14.11],[2,1.53,177.19]],"batl":[[0,1.61,1.08]],"ltp":1.61,"tv":753.46,"id":7414058}],"tv":1040.76}]}
{"op":"mcm","clk":"1005525276","pt":1580643159337,"mc":[{"id":"1.168224552","rc":[{"batb":[[0,2.54,85.68]],"ltp":2.64,"tv":287.29,"id":7287690},{"trd":[[1.6,211.05]],"batb":[[0,1.57,14.11],[1,1.54,152.64],[2,1.43,338.32]],"ltp":1.6,"tv":766.53,"id":7414058}],"tv":1053.83}]}
{"op":"mcm","clk":"1005532954","pt":1580643197878,"mc":[{"id":"1.168224552","rc":[{"batl":[[0,1.61,16.22]],"ltp":1.6,"tv":766.53,"id":7414058}]}]}
{"op":"mcm","clk":"1005533153","pt":1580643198795,"mc":[{"id":"1.168224552","rc":[{"trd":[[1.61,214.58]],"batl":[[0,1.61,8.78]],"ltp":1.61,"tv":781.42,"id":7414058}],"tv":1068.72}]}
{"op":"mcm","clk":"1005533506","pt":1580643200409,"mc":[{"id":"1.168224552","rc":[{"batb":[[0,1.6,6.41],[1,1.57,14.11],[2,1.54,152.64]],"ltp":1.61,"tv":781.42,"id":7414058}]}]}
{"op":"mcm","clk":"1005533772","pt":1580643201815,"mc":[{"id":"1.168224552","rc":[{"batb":[[0,1.6,7.49]],"ltp":1.61,"tv":781.42,"id":7414058}]}]}
{"op":"mcm","clk":"1005547224","pt":1580643269474,"mc":[{"id":"1.168224552","rc":[{"batb":[[0,2.54,79]],"ltp":2.64,"tv":287.29,"id":7287690},{"trd":[[1.6,226.03]],"batb":[[0,1.57,14.11],[1,1.54,152.64],[2,1.43,338.32]],"ltp":1.6,"tv":796.4,"id":7414058}],"tv":1083.7}]}
{"op":"mcm","clk":"1005547305","pt":1580643269886,"mc":[{"id":"1.168224552","rc":[{"trd":[[1.61,229.48]],"batb":[[1,1.54,160.28]],"batl":[[0,1.61,1.33]],"ltp":1.61,"tv":811.3,"id":7414058}],"tv":1098.6}]}
{"op":"mcm","clk":"1005547566","pt":1580643271389,"mc":[{"id":"1.168224552","rc":[{"batb":[[0,1.6,6.29],[1,1.57,14.11],[2,1.54,160.28]],"ltp":1.61,"tv":811.3,"id":7414058}]}]}
{"op":"mcm","clk":"1005547705","pt":1580643272190,"mc":[{"id":"1.168224552","rc":[{"batb":[[0,1.6,7.5]],"ltp":1.61,"tv":811.3,"id":7414058}]}]}
{"op":"mcm","clk":"1005552699","pt":1580643298114,"mc":[{"id":"1.168224552","rc":[{"batb":[[0,2.54,80.83]],"ltp":2.64,"tv":287.29,"id":7287690}]}]}
{"op":"mcm","clk":"1005629606","pt":1580643673051,"mc":[{"id":"1.168224552","rc":[{"batb":[[0,2.56,2.08],[1,2.54,82.95],[2,2.48,36.35]],"batl":[[0,2.72,2.16],[1,2.74,2.13],[2,3.1,15.74]],"ltp":2.64,"tv":287.29,"id":7287690},{"batb":[[1,1.58,2.06],[2,1.57,16.17]],"batl":[[2,1.64,2.18]],"ltp":1.61,"tv":811.3,"id":7414058}]}]}
{"op":"mcm","clk":"1005632448","pt":1580643687262,"mc":[{"id":"1.168224552","rc":[{"batb":[[0,2.58,58.05],[1,2.56,2.08],[2,2.54,2.12]],"ltp":2.64,"tv":287.29,"id":7287690}]}]}
{"op":"mcm","clk":"1005632561","pt":1580643687898,"mc":[{"id":"1.168224552","rc":[{"batb":[[2,2.54,2]],"batl":[[1,2.74,2.25]],"ltp":2.64,"tv":287.29,"id":7287690},{"batb":[[2,1.57,16.15]],"ltp":1.61,"tv":811.3,"id":7414058}]}]}
{"op":"mcm","clk":"1005650752","pt":1580643779287,"mc":[{"id":"1.168224552","rc":[{"batb":[[2,2.54,2.12]],"batl":[[1,2.74,2.05]],"ltp":2.64,"tv":287.29,"id":7287690},{"trd":[[1.6,229.39]],"batb":[[0,1.6,5.82],[2,1.57,16.17]],"ltp":1.6,"tv":814.66,"id":7414058}],"tv":1101.96}]}
{"op":"mcm","clk":"1005656368","pt":1580643808013,"mc":[{"id":"1.168224552","rc":[{"batb":[[2,2.54,2.02]],"batl":[[1,2.74,2.17]],"ltp":2.64,"tv":287.29,"id":7287690},{"batb":[[0,1.6,13.39]],"ltp":1.6,"tv":814.66,"id":7414058}]}]}
{"op":"mcm","clk":"1005656613","pt":1580643809344,"mc":[{"id":"1.168224552","rc":[{"batb":[[2,1.57,2.06]],"ltp":1.6,"tv":814.66,"id":7414058}]}]}
{"op":"mcm","clk":"1005665234","pt":1580643856483,"mc":[{"id":"1.168224552","rc":[{"batb":[[0,1.58,2.06],[1,1.57,2.06],[2,1.54,160.28]],"ltp":1.6,"tv":814.66,"id":7414058}]}]}
{"op":"mcm","clk":"1005665421","pt":1580643857481,"mc":[{"id":"1.168224552","rc":[{"batb":[[2,2.54,2.12]],"batl":[[0,2.74,2.01],[1,2.76,2.02]],"ltp":2.64,"tv":287.29,"id":7287690},{"batb":[[0,1.59,13.39],[2,1.56,2.06]],"ltp":1.6,"tv":814.66,"id":7414058}]}]}
{"op":"mcm","clk":"1005666379","pt":1580643863014,"mc":[{"id":"1.168224552","rc":[{"batl":[[0,2.72,2.16],[1,2.74,2.01],[2,2.76,2.02]],"ltp":2.64,"tv":287.29,"id":7287690},{"batb":[[0,1.6,13.39],[1,1.58,2.06],[2,1.57,2.06]],"ltp":1.6,"tv":814.66,"id":7414058}]}]}
{"op":"mcm","clk":"1005682776","pt":1580643950428,"mc":[{"id":"1.168224552","rc":[{"trd":[[1.6,256.15]],"batb":[[0,1.58,2.06],[1,1.57,2.06],[2,1.56,2.06]],"batl":[[0,1.6,6.89],[1,1.61,1.33],[2,1.62,4.94]],"ltp":1.6,"tv":841.42,"id":7414058}],"tv":1128.72}]}
{"op":"mcm","clk":"1005682949","pt":1580643951445,"mc":[{"id":"1.168224552","rc":[{"batb":[[0,2.62,2.04],[1,2.6,2.04],[2,2.58,58.05]],"batl":[[0,2.76,2.01],[1,2.78,2.25],[2,3.1,15.74]],"ltp":2.64,"tv":287.29,"id":7287690},{"batb":[[0,1.56,2.06],[1,1.55,2.08],[2,1.54,160.28]],"batl":[[1,1.61,8.85],[2,1.62,7.19]],"ltp":1.6,"tv":841.42,"id":7414058}]}]}
{"op":"mcm","clk":"1005683127","pt":1580643952309,"mc":[{"id":"1.168224552","rc":[{"batl":[[0,2.84,2.03],[1,2.86,2.03]],"ltp":2.64,"tv":287.29,"id":7287690},{"batb":[[0,1.54,160.28],[1,1.53,2.16],[2,1.52,2.06]],"ltp":1.6,"tv":841.42,"id":7414058}]}]}
{"op":"mcm","clk":"1005683306","pt":1580643953207,"mc":[{"id":"1.168224552","rc":[{"batl":[[0,2.92,2.06],[1,2.94,2.08]],"ltp":2.64,"tv":287.29,"id":7287690},{"batb":[[1,1.52,2.06],[2,1.51,2.08]],"ltp":1.6,"tv":841.42,"id":7414058}]}]}
{"op":"mcm","clk":"1005683509","pt":1580643954396,"mc":[{"id":"1.168224552","rc":[{"batb":[[2,2.54,80.82]],"batl":[[0,2.9,2.05],[1,2.96,2.12],[2,2.98,2.07]],"ltp":2.64,"tv":287.29,"id":7287690}]}]}
{"op":"mcm","clk":"1005683524","pt":1580643954548,"mc":[{"id":"1.168224552","rc":[{"batl":[[1,2.92,2.06],[2,2.96,2.12]],"ltp":2.64,"tv":287.29,"id":7287690}]}]}
{"op":"mcm","clk":"1005686074","pt":1580643968433,"mc":[{"id":"1.168224552","rc":[{"batb":[[0,2.68,74.1],[1,2.64,2.07],[2,2.48,36.35]],"batl":[[0,2.94,2.08],[1,2.96,2.12],[2,3.1,15.74]],"ltp":2.64,"tv":287.29,"id":7287690},{"batb":[[0,1.49,157.29],[1,1.48,2.01],[2,1.47,2.01]],"batl":[[0,1.59,45.89],[1,1.6,6.89],[2,1.61,10.99]],"ltp":1.6,"tv":841.42,"id":7414058}]}]}
{"op":"mcm","clk":"1005686274","pt":1580643969396,"mc":[{"id":"1.168224552","rc":[{"batb":[[2,2.62,2.04]],"batl":[[0,3.1,15.74],[1,3.15,2.1],[2,3.2,2.03]],"ltp":2.64,"tv":287.29,"id":7287690},{"batb":[[1,1.47,2.01],[2,1.46,2.01]],"batl":[[2,1.61,10.86]],"ltp":1.6,"tv":841.42,"id":7414058}]}]}
{"op":"mcm","clk":"1005696586","pt":1580644031426,"mc":[{"id":"1.168224552","rc":[{"trd":[[1.59,165.17]],"batl":[[0,1.59,3.54],[2,1.61,2.01]],"ltp":1.59,"tv":926.12,"id":7414058}],"tv":1213.42}]}
{"op":"mcm","clk":"1005696754","pt":1580644032487,"mc":[{"id":"1.168224552","rc":[{"batl":[[0,3.05,2.1],[1,3.1,17.79]],"ltp":2.64,"tv":287.29,"id":7287690},{"batb":[[0,1.51,6.66],[1,1.49,159.3],[2,1.48,2.01]],"batl":[[0,1.6,6.89],[1,1.62,7.11],[2,1.63,2.04]],"ltp":1.59,"tv":926.12,"id":7414058}]}]}
{"op":"mcm","clk":"1005701762","pt":1580644063434,"mc":[{"id":"1.168224552","rc":[{"trd":[[2.68,58.42],[2.72,1.16],[2.74,59.19],[2.76,18.06],[2.8,14.22]],"batb":[[0,2.68,56.28],[1,2.48,36.35],[2,2.46,80.91]],"batl":[[2,5.5,153.72]],"ltp":2.68,"tv":337.16,"id":7287690},{"trd":[[1.55,13.15],[1.57,116.57],[1.58,42.76]],"batl":[[0,1.62,4.94],[1,1.64,2.04],[2,1.65,25.33]],"ltp":1.58,"tv":937.02,"id":7414058}],"tv":1274.19}]}
{"op":"mcm","clk":"1005701957","pt":1580644064447,"mc":[{"id":"1.168224552","rc":[{"batb":[[0,2.64,57.65]],"batl":[[0,2.98,3.25],[1,3,2.65],[2,3.05,2.1]],"ltp":2.68,"tv":337.16,"id":7287690},{"batb":[[0,1.52,87.88],[1,1.51,6.66],[2,1.5,2.62]],"batl":[[1,1.65,25.33],[2,1.8,495.99]],"ltp":1.58,"tv":937.02,"id":7414058}]}]}
{"op":"mcm","clk":"1005702046","pt":1580644064932,"mc":[{"id":"1.168224552","rc":[{"batl":[[2,3.1,17.79]],"ltp":2.68,"tv":337.16,"id":7287690}]}]}
{"op":"mcm","clk":"1005702150","pt":1580644065622,"mc":[{"id":"1.168224552","rc":[{"batb":[[1,1.5,2.62],[2,1.49,2.58]],"ltp":1.58,"tv":937.02,"id":7414058}]}]}
{"op":"mcm","clk":"1005702417","pt":1580644067458,"mc":[{"id":"1.168224552","rc":[{"batl":[[0,2.84,3.03],[1,2.86,2.75],[2,2.98,3.25]],"ltp":2.68,"tv":337.16,"id":7287690},{"trd":[[1.56,12.89]],"batb":[[0,1.52,90.37],[1,1.51,2.99],[2,1.5,2.62]],"ltp":1.56,"tv":949.91,"id":7414058}],"tv":1287.08}]}
{"op":"mcm","clk":"1005702551","pt":1580644068428,"mc":[{"id":"1.168224552","rc":[{"batl":[[0,2.92,3.06],[1,2.94,2.91]],"ltp":2.68,"tv":337.16,"id":7287690},{"batb":[[0,1.52,87.88]],"ltp":1.56,"tv":949.91,"id":7414058}]}]}
{"op":"mcm","clk":"1005702652","pt":1580644069161,"mc":[{"id":"1.168224552","rc":[{"batl":[[0,2.98,2.75],[1,3,2.65],[2,3.05,2.9]],"ltp":2.68,"tv":337.16,"id":7287690},{"batb":[[1,1.5,2.62],[2,1.49,2.58]],"batl":[[0,1.6,7.57],[1,1.62,4.94],[2,1.65,25.33]],"ltp":1.56,"tv":949.91,"id":7414058}]}]}
{"op":"mcm","clk":"1005702748","pt":1580644069860,"mc":[{"id":"1.168224552","rc":[{"batl":[[0,1.6,15.14]],"ltp":1.56,"tv":949.91,"id":7414058}]}]}
{"op":"mcm","clk":"1005705262","pt":1580644086485,"mc":[{"id":"1.168224552","rc":[{"batb":[[0,2.68,56.28]],"ltp":2.68,"tv":337.16,"id":7287690},{"batb":[[0,1.51,120.53]],"ltp":1.56,"tv":949.91,"id":7414058}]}]}
{"op":"mcm","clk":"1005705371","pt":1580644087254,"mc":[{"id":"1.168224552","rc":[{"batl":[[0,3.05,2.9],[1,3.1,18.49],[2,3.15,2.7]],"ltp":2.68,"tv":337.16,"id":7287690},{"batb":[[1,1.49,2.58],[2,1.48,2.76]],"ltp":1.56,"tv":949.91,"id":7414058}]}]}
{"op":"mcm","clk":"1005705414","pt":1580644087561,"mc":[{"id":"1.168224552","rc":[{"trd":[[1.6,284.39]],"batl":[[0,1.6,1.02]],"ltp":1.6,"tv":978.15,"id":7414058}],"tv":1315.32}]}
{"op":"mcm","clk":"1005707618","pt":1580644102482,"mc":[{"id":"1.168224552","rc":[{"batl":[[1,3.1,15.74],[2,5.5,153.72]],"ltp":2.68,"tv":337.16,"id":7287690},{"batb":[[2,1.43,338.32]],"batl":[[0,1.6,8.59]],"ltp":1.6,"tv":978.15,"id":7414058}]}]}
{"op":"mcm","clk":"1005707643","pt":1580644102700,"mc":[{"id":"1.168224552","rc":[{"batl":[[1,3.1,18.69]],"ltp":2.68,"tv":337.16,"id":7287690},{"batb":[[2,1.48,2.76]],"ltp":1.6,"tv":978.15,"id":7414058}]}]}
{"op":"mcm","clk":"1005708012","pt":1580644105392,"mc":[{"id":"1.168224552","rc":[{"batl":[[0,1.62,4.94],[1,1.65,25.33],[2,1.8,495.99]],"ltp":1.6,"tv":978.15,"id":7414058}]}]}
{"op":"mcm","clk":"1005708291","pt":1580644107286,"mc":[{"id":"1.168224552","rc":[{"batl":[[0,2.84,3.03],[1,2.86,2.75],[2,3.1,18.69]],"ltp":2.68,"tv":337.16,"id":7287690},{"trd":[[1.56,30.99]],"batb":[[0,1.56,5.44],[1,1.54,3.12],[2,1.53,2.99]],"ltp":1.56,"tv":996.25,"id":7414058}],"tv":1333.42}]}
{"op":"mcm","clk":"1005708513","pt":1580644108959,"mc":[{"id":"1.168224552","rc":[{"batl":[[2,3.1,15.74]],"ltp":2.68,"tv":337.16,"id":7287690},{"batl":[[0,1.59,15.14],[1,1.62,4.94],[2,1.65,25.33]],"ltp":1.56,"tv":996.25,"id":7414058}]}]}
{"op":"mcm","clk":"1005708716","pt":1580644110375,"mc":[{"id":"1.168224552","rc":[{"batl":[[0,2.78,2.75],[1,2.8,2.87],[2,2.84,3.03]],"ltp":2.68,"tv":337.16,"id":7287690},{"trd":[[1.59,178.35]],"batb":[[0,1.58,6.63],[1,1.56,8.27],[2,1.55,2.79]],"batl":[[0,1.59,8.56]],"ltp":1.59,"tv":1009.43,"id":7414058}],"tv":1346.6}]}
{"op":"mcm","clk":"1005708893","pt":1580644111785,"mc":[{"id":"1.168224552","rc":[{"batl":[[0,1.62,4.94],[1,1.65,25.33],[2,1.8,495.99]],"ltp":1.59,"tv":1009.43,"id":7414058}]}]}
{"op":"mcm","clk":"1005709118","pt":1580644113468,"mc":[{"id":"1.168224552","rc":[{"batl":[[0,1.61,7.57],[1,1.62,4.94],[2,1.65,25.33]],"ltp":1.59,"tv":1009.43,"id":7414058}]}]}
{"op":"mcm","clk":"1005709130","pt":1580644113575,"mc":[{"id":"1.168224552","rc":[{"batl":[[2,3.1,15.74]],"ltp":2.68,"tv":337.16,"id":7287690}]}]}
{"op":"mcm","clk":"1005709492","pt":1580644116315,"mc":[{"id":"1.168224552","rc":[{"batb":[[0,1.56,2.83],[1,1.55,2.79],[2,1.51,120.53]],"batl":[[0,1.62,4.94],[1,1.65,25.33],[2,1.8,495.99]],"ltp":1.59,"tv":1009.43,"id":7414058}]}]}
{"op":"mcm","clk":"1005709635","pt":1580644117410,"mc":[{"id":"1.168224552","rc":[{"batl":[[0,2.86,2.75],[1,2.9,2.85],[2,2.92,2.81]],"ltp":2.68,"tv":337.16,"id":7287690},{"batb":[[0,1.56,5.44],[1,1.52,2.49],[2,1.51,123.01]],"ltp":1.59,"tv":1009.43,"id":7414058}]}]}
{"op":"mcm","clk":"1005709683","pt":1580644117723,"mc":[{"id":"1.168224552","rc":[{"batl":[[0,2.84,3.03],[1,2.86,2.89],[2,2.9,2.85]],"ltp":2.68,"tv":337.16,"id":7287690},{"batb":[[1,1.54,3.12],[2,1.53,2.99]],"ltp":1.59,"tv":1009.43,"id":7414058}]}]}
{"op":"mcm","clk":"1005723223","pt":1580644217421,"mc":[{"id":"1.168224552","rc":[{"trd":[[1.56,41.86]],"batb":[[0,1.54,3.12],[1,1.53,2.99],[2,1.52,2.49]],"ltp":1.56,"tv":1020.3,"id":7414058}],"tv":1357.47}]}
{"op":"mcm","clk":"1005723391","pt":1580644218409,"mc":[{"id":"1.168224552","rc":[{"batb":[[0,2.64,54.33]],"batl":[[0,2.92,2.81],[1,2.94,3.08],[2,3.1,15.74]],"ltp":2.68,"tv":337.16,"id":7287690},{"batb":[[0,1.51,2.99],[1,1.5,162.68],[2,1.43,338.32]],"ltp":1.56,"tv":1020.3,"id":7414058}]}]}
{"op":"mcm","clk":"1005723574","pt":1580644219452,"mc":[{"id":"1.168224552","rc":[{"batl":[[0,3.05,2.7],[1,3.1,18.29],[2,5.5,153.72]],"ltp":2.68,"tv":337.16,"id":7287690},{"batb":[[0,1.5,159.72],[1,1.48,2.76],[2,1.47,2.84]],"ltp":1.56,"tv":1020.3,"id":7414058}]}]}
{"op":"mcm","clk":"1005723745","pt":1580644220448,"mc":[{"id":"1.168224552","rc":[{"batl":[[0,3.1,18.29],[1,3.15,2.9]],"ltp":2.68,"tv":337.16,"id":7287690},{"batl":[[0,1.6,7.57],[1,1.62,4.94],[2,1.65,25.33]],"ltp":1.56,"tv":1020.3,"id":7414058}]}]}
{"op":"mcm","clk":"1005723791","pt":1580644220720,"mc":[{"id":"1.168224552","rc":[{"batl":[[0,1.6,22.72]],"ltp":1.56,"tv":1020.3,"id":7414058}]}]}
{"op":"mcm","clk":"1005724485","pt":1580644224936,"mc":[{"id":"1.168224552","rc":[{"batl":[[0,1.62,4.94],[1,1.65,25.33],[2,1.8,495.99]],"ltp":1.56,"tv":1020.3,"id":7414058}]}]}
{"op":"mcm","clk":"1005724727","pt":1580644226472,"mc":[{"id":"1.168224552","rc":[{"batl":[[1,5.5,153.72],[2,95,15.9]],"ltp":2.68,"tv":337.16,"id":7287690},{"batb":[[0,1.55,6.76],[1,1.5,159.72],[2,1.48,2.76]],"batl":[[0,1.6,15.14],[1,1.62,4.94],[2,1.65,25.33]],"ltp":1.56,"tv":1020.3,"id":7414058}]}]}
{"op":"mcm","clk":"1005724767","pt":1580644226736,"mc":[{"id":"1.168224552","rc":[{"batl":[[0,2.86,2.75],[1,2.88,2.79],[2,3.1,15.74]],"ltp":2.68,"tv":337.16,"id":7287690},{"batb":[[1,1.53,2.82],[2,1.52,2.99]],"ltp":1.56,"tv":1020.3,"id":7414058}]}]}
{"op":"mcm","clk":"1005725740","pt":1580644233417,"mc":[{"id":"1.168224552","rc":[{"batl":[[1,3.1,15.74],[2,5.5,153.72]],"ltp":2.68,"tv":337.16,"id":7287690},{"batb":[[0,1.56,6.76],[1,1.51,2.99],[2,1.5,162.5]],"ltp":1.56,"tv":1020.3,"id":7414058}]}]}
{"op":"mcm","clk":"1005725796","pt":1580644233832,"mc":[{"id":"1.168224552","rc":[{"batl":[[0,2.84,2.53],[1,2.86,2.75],[2,3.1,15.74]],"ltp":2.68,"tv":337.16,"id":7287690},{"batb":[[1,1.54,2.62],[2,1.53,2.99]],"ltp":1.56,"tv":1020.3,"id":7414058}]}]}
{"op":"mcm","clk":"1005726034","pt":1580644235460,"mc":[{"id":"1.168224552","rc":[{"batb":[[0,1.54,2.62],[1,1.52,2.99],[2,1.51,2.99]],"batl":[[0,1.62,4.94],[1,1.65,25.33],[2,1.8,495.99]],"ltp":1.56,"tv":1020.3,"id":7414058}]}]}
{"op":"mcm","clk":"1005726149","pt":1580644236355,"mc":[{"id":"1.168224552","rc":[{"batl":[[0,2.96,2.87],[1,2.98,2.75]],"ltp":2.68,"tv":337.16,"id":7287690},{"batb":[[0,1.5,162.5],[1,1.49,2.52],[2,1.43,338.32]],"batl":[[0,1.6,15.14],[1,1.62,4.94],[2,1.65,25.33]],"ltp":1.56,"tv":1020.3,"id":7414058}]}]}
{"op":"mcm","clk":"1005726213","pt":1580644236729,"mc":[{"id":"1.168224552","rc":[{"batl":[[0,2.84,3.03],[1,2.86,3.25],[2,3,2.55]],"ltp":2.68,"tv":337.16,"id":7287690},{"batb":[[0,1.56,6.72],[1,1.54,3.12],[2,1.53,2.65]],"ltp":1.56,"tv":1020.3,"id":7414058}]}]}
{"op":"mcm","clk":"1005733806","pt":1580644290413,"mc":[{"id":"1.168224552","rc":[{"batl":[[1,2.86,2.75],[2,3.1,15.74]],"ltp":2.68,"tv":337.16,"id":7287690},{"trd":[[1.6,312.71]],"batl":[[0,1.62,5.92],[1,1.65,25.33],[2,1.8,495.99]],"ltp":1.6,"tv":1048.62,"id":7414058}],"tv":1385.79}]}
{"op":"mcm","clk":"1005736033","pt":1580644306427,"mc":[{"id":"1.168224552","rc":[{"batl":[[0,2.92,3.06],[1,2.94,2.75]],"ltp":2.68,"tv":337.16,"id":7287690},{"batb":[[0,1.5,162.62],[1,1.49,3.01],[2,1.43,338.32]],"batl":[[0,1.62,4.94]],"ltp":1.6,"tv":1048.62,"id":7414058}]}]}
{"op":"mcm","clk":"1005736178","pt":1580644307424,"mc":[{"id":"1.168224552","rc":[{"batl":[[0,3.1,15.74],[1,3.2,2.58],[2,3.25,2.54]],"ltp":2.68,"tv":337.16,"id":7287690},{"batb":[[0,1.56,6.72],[1,1.54,3.12],[2,1.53,2.65]],"batl":[[0,1.6,7.57],[1,1.62,4.94],[2,1.65,25.33]],"ltp":1.6,"tv":1048.62,"id":7414058}]}]}
{"op":"mcm","clk":"1005736195","pt":1580644307527,"mc":[{"id":"1.168224552","rc":[{"batl":[[0,2.84,3.03],[1,2.86,2.75],[2,3.1,15.74]],"ltp":2.68,"tv":337.16,"id":7287690}]}]}
{"op":"mcm","clk":"1005741800","pt":1580644349474,"mc":[{"id":"1.168224552","rc":[{"batl":[[0,2.88,2.79],[1,2.9,2.85]],"ltp":2.68,"tv":337.16,"id":7287690},{"trd":[[1.56,55.29]],"batb":[[0,1.52,2.49],[1,1.51,2.99],[2,1.5,159.72]],"ltp":1.56,"tv":1062.05,"id":7414058}],"tv":1399.22}]}
{"op":"mcm","clk":"1005741910","pt":1580644350372,"mc":[{"id":"1.168224552","rc":[{"batb":[[0,2.68,49.03]],"batl":[[0,3,2.57],[1,3.05,3.1]],"ltp":2.68,"tv":337.16,"id":7287690},{"trd":[[1.6,325.93]],"batb":[[0,1.5,169.09],[1,1.49,3.01],[2,1.43,338.32]],"batl":[[0,1.62,5.9],[1,1.65,25.33],[2,1.8,495.99]],"ltp":1.6,"tv":1075.27,"id":7414058}],"tv":1412.44}]}
{"op":"mcm","clk":"1005741987","pt":1580644350891,"mc":[{"id":"1.168224552","rc":[{"batl":[[0,2.74,2.75],[1,2.76,3.02],[2,3.1,18.69]],"ltp":2.68,"tv":337.16,"id":7287690},{"batb":[[0,1.59,6.65],[1,1.57,2.92],[2,1.56,2.58]],"ltp":1.6,"tv":1075.27,"id":7414058}]}]}
{"op":"mcm","clk":"1005742404","pt":1580644354486,"mc":[{"id":"1.168224552","rc":[{"batl":[[0,2.82,2.75],[1,2.84,3.03]],"ltp":2.68,"tv":337.16,"id":7287690},{"batb":[[0,1.54,2.49],[1,1.53,2.65],[2,1.5,166.59]],"ltp":1.6,"tv":1075.27,"id":7414058}]}]}
{"op":"mcm","clk":"1005742519","pt":1580644355414,"mc":[{"id":"1.168224552","rc":[{"batl":[[0,2.94,2.58],[1,2.96,2.62]],"ltp":2.68,"tv":337.16,"id":7287690},{"batb":[[0,1.51,2.99],[1,1.5,169.49],[2,1.48,2.51]],"ltp":1.6,"tv":1075.27,"id":7414058}]}]}
{"op":"mcm","clk":"1005742658","pt":1580644356412,"mc":[{"id":"1.168224552","rc":[{"batl":[[0,3.1,18.69],[1,3.15,2.5],[2,5.5,153.72]],"ltp":2.68,"tv":337.16,"id":7287690},{"batb":[[0,1.5,166.59],[1,1.48,2.51],[2,1.47,2.84]],"batl":[[0,1.61,7.57],[1,1.62,4.94],[2,1.65,25.33]],"ltp":1.6,"tv":1075.27,"id":7414058}]}]}
{"op":"mcm","clk":"1005742770","pt":1580644357405,"mc":[{"id":"1.168224552","rc":[{"batl":[[0,2.84,2.78],[1,2.86,2.75],[2,3.1,15.74]],"ltp":2.68,"tv":337.16,"id":7287690},{"batb":[[0,1.56,21.3],[1,1.54,3.12],[2,1.53,2.82]],"batl":[[0,1.61,15.14]],"ltp":1.6,"tv":1075.27,"id":7414058}]}]}
{"op":"mcm","clk":"1005758568","pt":1580644481466,"mc":[{"id":"1.168224552","rc":[{"trd":[[2.68,124.42]],"batb":[[0,2.64,37.25]],"batl":[[0,2.88,2.79],[1,2.9,2.75]],"ltp":2.68,"tv":403.17,"id":7287690},{"trd":[[1.56,97.89]],"batb":[[0,1.52,2.74],[1,1.51,157.59],[2,1.43,338.32]],"ltp":1.56,"tv":1117.87,"id":7414058}],"tv":1521.04}]}
{"op":"mcm","clk":"1005758668","pt":1580644482150,"mc":[{"id":"1.168224552","rc":[{"batl":[[0,2.86,2.89],[1,2.88,2.79],[2,2.96,2.87]],"ltp":2.68,"tv":403.17,"id":7287690},{"batb":[[0,1.55,85.68],[1,1.53,2.82],[2,1.52,2.49]],"ltp":1.56,"tv":1117.87,"id":7414058}]}]}
{"op":"mcm","clk":"1005759198","pt":1580644486385,"mc":[{"id":"1.168224552","rc":[{"batl":[[0,1.6,22.72],[1,1.61,15.14],[2,1.62,4.94]],"ltp":1.56,"tv":1117.87,"id":7414058}]}]}
{"op":"mcm","clk":"1005762940","pt":1580644515413,"mc":[{"id":"1.168224552","rc":[{"batl":[[0,1.6,30.29]],"ltp":1.56,"tv":1117.87,"id":7414058}]}]}
{"op":"mcm","clk":"1005763050","pt":1580644516206,"mc":[{"id":"1.168224552","rc":[{"batl":[[1,2.88,3.04],[2,3.1,15.74]],"ltp":2.68,"tv":403.17,"id":7287690},{"trd":[[1.6,382.74]],"batb":[[2,1.52,2.99]],"batl":[[0,1.6,1.89]],"ltp":1.6,"tv":1174.67,"id":7414058}],"tv":1577.85}]}
{"op":"mcm","clk":"1005763188","pt":1580644517323,"mc":[{"id":"1.168224552","rc":[{"batl":[[0,2.74,2.75],[1,2.76,3.02],[2,2.88,3.04]],"ltp":2.68,"tv":403.17,"id":7287690},{"batb":[[0,1.59,5.72],[1,1.57,2.64],[2,1.56,2.58]],"ltp":1.6,"tv":1174.67,"id":7414058}]}]}
{"op":"mcm","clk":"1005763497","pt":1580644519438,"mc":[{"id":"1.168224552","rc":[{"batb":[[0,1.55,88.67],[1,1.54,2.62],[2,1.52,2.99]],"ltp":1.6,"tv":1174.67,"id":7414058}]}]}
{"op":"mcm","clk":"1005763601","pt":1580644520376,"mc":[{"id":"1.168224552","rc":[{"batl":[[0,2.86,2.75],[1,2.88,3.04],[2,3.1,15.74]],"ltp":2.68,"tv":403.17,"id":7287690},{"batb":[[0,1.55,85.68],[1,1.53,2.99]],"ltp":1.6,"tv":1174.67,"id":7414058}]}]}
{"op":"mcm","clk":"1005763663","pt":1580644520849,"mc":[{"id":"1.168224552","rc":[{"batl":[[1,2.88,2.79],[2,2.9,2.65]],"ltp":2.68,"tv":403.17,"id":7287690}]}]}
{"op":"mcm","clk":"1005763991","pt":1580644523424,"mc":[{"id":"1.168224552","rc":[{"batb":[[2,1.43,338.32]],"batl":[[0,1.6,9.46]],"ltp":1.6,"tv":1174.67,"id":7414058}]}]}
{"op":"mcm","clk":"1005764019","pt":1580644523631,"mc":[{"id":"1.168224552","rc":[{"batb":[[2,1.52,2.74]],"batl":[[0,1.6,17.03]],"ltp":1.6,"tv":1174.67,"id":7414058}]}]}
{"op":"mcm","clk":"1005764257","pt":1580644525625,"mc":[{"id":"1.168224552","rc":[{"batl":[[0,1.62,4.94],[1,1.65,25.33],[2,1.8,495.99]],"ltp":1.6,"tv":1174.67,"id":7414058}]}]}
{"op":"mcm","clk":"1005764489","pt":1580644527444,"mc":[{"id":"1.168224552","rc":[{"batl":[[0,2.84,3.03],[1,2.86,2.75],[2,3.1,15.74]],"ltp":2.68,"tv":403.17,"id":7287690},{"batb":[[0,1.56,29.13],[1,1.55,85.68],[2,1.54,2.49]],"ltp":1.6,"tv":1174.67,"id":7414058}]}]}
{"op":"mcm","clk":"1005772939","pt":1580644591332,"mc":[{"id":"1.168224552","rc":[{"batb":[[0,1.57,135.27],[1,1.56,29.13],[2,1.55,85.68]],"batl":[[0,1.61,131.91],[1,1.62,4.94],[2,1.65,25.33]],"ltp":1.6,"tv":1174.67,"id":7414058}]}]}
{"op":"mcm","clk":"1005773081","pt":1580644592345,"mc":[{"id":"1.168224552","rc":[{"trd":[[2.64,116.35]],"batb":[[0,2.64,3.25]],"batl":[[0,2.8,2.87],[1,2.82,2.75]],"ltp":2.64,"tv":471.17,"id":7287690},{"batb":[[2,1.55,88.67]],"ltp":1.6,"tv":1174.67,"id":7414058}],"tv":1645.85}]}
{"op":"mcm","clk":"1005773235","pt":1580644593404,"mc":[{"id":"1.168224552","rc":[{"batb":[[0,2.48,36.35],[1,2.46,80.91],[2,2.22,37.86]],"batl":[[0,2.78,2.84],[1,2.8,2.87],[2,2.82,2.75]],"ltp":2.64,"tv":471.17,"id":7287690},{"batb":[[0,1.58,56.36],[1,1.57,135.27],[2,1.56,31.96]],"ltp":1.6,"tv":1174.67,"id":7414058}]}]}
{"op":"mcm","clk":"1005773264","pt":1580644593614,"mc":[{"id":"1.168224552","rc":[{"batb":[[0,1.58,56.34]],"ltp":1.6,"tv":1174.67,"id":7414058}]}]}
{"op":"mcm","clk":"1005773582","pt":1580644596023,"mc":[{"id":"1.168224552","rc":[{"batb":[[1,2.22,37.86],[2,2,37.86]],"ltp":2.64,"tv":471.17,"id":7287690}]}]}
{"op":"mcm","clk":"1005773652","pt":1580644596607,"mc":[{"id":"1.168224552","rc":[{"batb":[[1,2.46,123.44],[2,2.22,37.86]],"ltp":2.64,"tv":471.17,"id":7287690}]}]}
{"op":"mcm","clk":"1005780329","pt":1580644648482,"mc":[{"id":"1.168224552","rc":[{"batl":[[1,3.1,15.74],[2,5.5,153.72]],"ltp":2.64,"tv":471.17,"id":7287690},{"trd":[[1.61,349.48]],"batb":[[2,1.56,2.83]],"batl":[[0,1.61,71.91]],"ltp":1.61,"tv":1294.67,"id":7414058}],"tv":1765.85}]}
{"op":"mcm","clk":"1005780461","pt":1580644649426,"mc":[{"id":"1.168224552","rc":[{"batl":[[0,2.74,2.98],[1,2.76,3.02],[2,2.78,2.84]],"ltp":2.64,"tv":471.17,"id":7287690},{"batb":[[0,1.59,28.59],[1,1.58,56.34],[2,1.57,137.98]],"ltp":1.61,"tv":1294.67,"id":7414058}]}]}
{"op":"mcm","clk":"1005780534","pt":1580644649897,"mc":[{"id":"1.168224552","rc":[{"batl":[[2,2.8,2.72]],"ltp":2.64,"tv":471.17,"id":7287690}]}]}
{"op":"mcm","clk":"1005787500","pt":1580644703438,"mc":[{"id":"1.168224552","rc":[{"trd":[[1.61,477.48]],"batb":[[0,1.58,56.34],[1,1.57,135.27],[2,1.56,2.58]],"batl":[[0,1.61,7.91]],"ltp":1.61,"tv":1422.67,"id":7414058}],"tv":1893.84}]}
{"op":"mcm","clk":"1005787625","pt":1580644704272,"mc":[{"id":"1.168224552","rc":[{"batl":[[0,2.78,2.84],[1,2.8,2.82],[2,2.82,2.75]],"ltp":2.64,"tv":471.17,"id":7287690},{"batb":[[0,1.58,84.93]],"ltp":1.61,"tv":1422.67,"id":7414058}]}]}
{"op":"mcm","clk":"1005787758","pt":1580644705429,"mc":[{"id":"1.168224552","rc":[{"batb":[[0,1.58,56.34]],"ltp":1.61,"tv":1422.67,"id":7414058}]}]}
{"op":"mcm","clk":"1005787844","pt":1580644706161,"mc":[{"id":"1.168224552","rc":[{"batl":[[0,2.74,2.98],[1,2.76,2.52],[2,2.78,2.84]],"ltp":2.64,"tv":471.17,"id":7287690},{"batb":[[0,1.59,28.59],[1,1.58,56.34],[2,1.57,138.05]],"ltp":1.61,"tv":1422.67,"id":7414058}]}]}
{"op":"mcm","clk":"1005849574","pt":1580645097159,"mc":[{"id":"1.168224552","rc":[{"trd":[[2.7,7.29]],"batl":[[1,2.76,2.77],[2,3.1,15.74]],"ltp":2.7,"tv":478.46,"id":7287690},{"trd":[[1.59,190.73],[1.61,490.82]],"batb":[[0,1.59,16.2]],"batl":[[0,1.61,1.24]],"ltp":1.61,"tv":1448.39,"id":7414058}],"tv":1926.86}]}
{"op":"mcm","clk":"1005850856","pt":1580645103461,"mc":[{"id":"1.168224552","rc":[{"batl":[[0,2.78,2.75],[1,2.8,2.87]],"ltp":2.7,"tv":478.46,"id":7287690},{"batb":[[0,1.58,56.34],[1,1.57,135.27],[2,1.56,2.58]],"ltp":1.61,"tv":1448.39,"id":7414058}]}]}
{"op":"mcm","clk":"1005851039","pt":1580645104375,"mc":[{"id":"1.168224552","rc":[{"batl":[[0,2.78,2.93],[2,2.82,2.75]],"ltp":2.7,"tv":478.46,"id":7287690},{"batb":[[0,1.59,16.2],[1,1.58,56.34],[2,1.57,135.27]],"ltp":1.61,"tv":1448.39,"id":7414058}]}]}
{"op":"mcm","clk":"1005851135","pt":1580645104858,"mc":[{"id":"1.168224552","rc":[{"batl":[[0,2.74,2.75],[1,2.76,2.77],[2,2.78,2.93]],"ltp":2.7,"tv":478.46,"id":7287690},{"batb":[[2,1.57,138.19]],"ltp":1.61,"tv":1448.39,"id":7414058}]}]}
{"op":"mcm","clk":"1005857526","pt":1580645137322,"mc":[{"id":"1.168224552","rc":[{"trd":[[1.59,222.85]],"batb":[[0,1.58,56.49],[1,1.57,138.19],[2,1.56,2.58]],"ltp":1.59,"tv":1480.51,"id":7414058}],"tv":1958.98}]}
{"op":"mcm","clk":"1005857656","pt":1580645137904,"mc":[{"id":"1.168224552","rc":[{"batl":[[0,2.78,2.93],[1,2.8,2.67],[2,3.1,15.74]],"ltp":2.7,"tv":478.46,"id":7287690},{"batb":[[1,1.57,135.27]],"ltp":1.59,"tv":1480.51,"id":7414058}]}]}
{"op":"mcm","clk":"1005858222","pt":1580645140948,"mc":[{"id":"1.168224552","rc":[{"batl":[[0,1.6,15.14],[1,1.61,1.24],[2,1.62,4.94]],"ltp":1.59,"tv":1480.51,"id":7414058}]}]}
{"op":"mcm","clk":"1005879091","pt":1580645247409,"mc":[{"id":"1.168224552","rc":[{"trd":[[1.6,411.38]],"batl":[[0,1.61,2.07],[1,1.62,4.94],[2,1.65,25.33]],"ltp":1.6,"tv":1509.15,"id":7414058}],"tv":1987.62}]}
{"op":"mcm","clk":"1005879287","pt":1580645248378,"mc":[{"id":"1.168224552","rc":[{"batl":[[0,2.74,2.98],[1,2.76,2.77],[2,2.78,2.93]],"ltp":2.7,"tv":478.46,"id":7287690},{"batb":[[0,1.59,14.55],[1,1.58,56.34],[2,1.57,138.26]],"ltp":1.6,"tv":1509.15,"id":7414058}]}]}
{"op":"mcm","clk":"1005879363","pt":1580645248793,"mc":[{"id":"1.168224552","rc":[{"batl":[[2,2.8,2.67]],"ltp":2.7,"tv":478.46,"id":7287690}]}]}
{"op":"mcm","clk":"1005885905","pt":1580645282341,"mc":[{"id":"1.168224552","rc":[{"batb":[[1,2.22,37.86],[2,2,37.86]],"batl":[[1,2.76,3.52],[2,3.1,15.74]],"ltp":2.7,"tv":478.46,"id":7287690}]}]}
{"op":"mcm","clk":"1005886486","pt":1580645285350,"mc":[{"id":"1.168224552","rc":[{"batb":[[0,2.48,53.38]],"ltp":2.7,"tv":478.46,"id":7287690}]}]}
{"op":"mcm","clk":"1005888452","pt":1580645295361,"mc":[{"id":"1.168224552","rc":[{"batb":[[0,2.48,17.03]],"ltp":2.7,"tv":478.46,"id":7287690}]}]}
{"op":"mcm","clk":"1005888587","pt":1580645295903,"mc":[{"id":"1.168224552","rc":[{"batl":[[1,2.76,3.77]],"ltp":2.7,"tv":478.46,"id":7287690}]}]}
{"op":"mcm","clk":"1005932605","pt":1580645527969,"mc":[{"id":"1.168224552","rc":[{"batb":[[0,2.66,2.53],[1,2.48,17.03],[2,2.22,37.86]],"ltp":2.7,"tv":478.46,"id":7287690}]}]}
{"op":"mcm","clk":"1005932715","pt":1580645528651,"mc":[{"id":"1.168224552","rc":[{"batl":[[1,2.76,3.52]],"ltp":2.7,"tv":478.46,"id":7287690}]}]}
{"op":"mcm","clk":"1005994089","pt":1580645876012,"mc":[{"id":"1.168224552","rc":[{"batl":[[1,2.76,3.77]],"ltp":2.7,"tv":478.46,"id":7287690}]}]}
{"op":"mcm","clk":"1006008417","pt":1580645958346,"mc":[{"id":"1.168224552","rc":[{"batb":[[0,1.58,56.34],[1,1.57,138.26],[2,1.56,2.08]],"batl":[[0,1.61,1.24]],"ltp":1.6,"tv":1509.15,"id":7414058}]}]}
{"op":"mcm","clk":"1006008579","pt":1580645959199,"mc":[{"id":"1.168224552","rc":[{"batl":[[0,2.78,3.43],[1,2.8,3.57],[2,2.82,4.25]],"ltp":2.7,"tv":478.46,"id":7287690},{"batb":[[1,1.57,135.27]],"ltp":1.6,"tv":1509.15,"id":7414058}]}]}
{"op":"mcm","clk":"1006008725","pt":1580645960094,"mc":[{"id":"1.168224552","rc":[{"batl":[[0,2.74,3.48],[1,2.76,4.02],[2,2.78,3.43]],"ltp":2.7,"tv":478.46,"id":7287690},{"batb":[[0,1.59,14.55],[1,1.58,56.34],[2,1.57,137.31]],"ltp":1.6,"tv":1509.15,"id":7414058}]}]}
{"op":"mcm","clk":"1006033097","pt":1580646098808,"mc":[{"id":"1.168224552","rc":[{"batl":[[1,2.76,3.77],[2,3.1,15.74]],"ltp":2.7,"tv":478.46,"id":7287690}]}]}
{"op":"mcm","clk":"1006042368","pt":1580646150150,"mc":[{"id":"1.168224552","rc":[{"batl":[[1,2.76,3.52]],"ltp":2.7,"tv":478.46,"id":7287690},{"trd":[[1.59,232.94]],"batb":[[0,1.59,9.51]],"ltp":1.59,"tv":1519.24,"id":7414058}],"tv":1997.7}]}
{"op":"mcm","clk":"1006066770","pt":1580646291371,"mc":[{"id":"1.168224552","rc":[{"batl":[[1,3.1,15.74],[2,5.5,153.72]],"ltp":2.7,"tv":478.46,"id":7287690},{"trd":[[1.59,251.96]],"batb":[[0,1.58,56.34],[1,1.57,135.27],[2,1.56,2.08]],"ltp":1.59,"tv":1538.26,"id":7414058}],"tv":2016.72}]}
{"op":"mcm","clk":"1006066957","pt":1580646292371,"mc":[{"id":"1.168224552","rc":[{"batl":[[0,2.8,3.37],[1,2.82,3.75],[2,2.84,3.78]],"ltp":2.7,"tv":478.46,"id":7287690},{"trd":[[1.57,251],[1.58,155.44]],"batb":[[0,1.57,68.06],[1,1.55,48.02],[2,1.54,2.12]],"ltp":1.57,"tv":1785.38,"id":7414058}],"tv":2263.84}]}
{"op":"mcm","clk":"1006067185","pt":1580646293476,"mc":[{"id":"1.168224552","rc":[{"batb":[[1,2.56,3.99],[2,2.5,16.8]],"batl":[[0,2.84,3.78],[1,2.86,3.89],[2,3.1,15.74]],"ltp":2.7,"tv":478.46,"id":7287690},{"trd":[[1.57,387.11]],"batb":[[0,1.56,56.71],[1,1.55,45.83]],"ltp":1.57,"tv":1921.49,"id":7414058}],"tv":2399.95}]}
{"op":"mcm","clk":"1006067356","pt":1580646294371,"mc":[{"id":"1.168224552","rc":[{"batl":[[1,2.86,3.82],[2,2.88,3.54]],"ltp":2.7,"tv":478.46,"id":7287690},{"batb":[[0,1.57,4.5],[1,1.56,56.71],[2,1.55,2.04]],"batl":[[0,1.61,4.24]],"ltp":1.57,"tv":1921.49,"id":7414058}]}]}
{"op":"mcm","clk":"1006067387","pt":1580646294590,"mc":[{"id":"1.168224552","rc":[{"batb":[[2,2.52,16.59]],"batl":[[0,2.8,3.87],[1,2.82,4.25],[2,2.84,3.78]],"ltp":2.7,"tv":478.46,"id":7287690}]}]}
{"op":"mcm","clk":"1006081240","pt":1580646375209,"mc":[{"id":"1.168224552","rc":[{"batb":[[0,2.68,297.36],[1,2.66,2.53],[2,2.56,3.99]],"batl":[[1,2.82,3.75],[2,3.1,15.74]],"ltp":2.7,"tv":478.46,"id":7287690},{"batb":[[1,1.56,32.62]],"ltp":1.57,"tv":1921.49,"id":7414058}]}]}
{"op":"mcm","clk":"1006081318","pt":1580646375617,"mc":[{"id":"1.168224552","rc":[{"batb":[[2,2.6,15.75]],"ltp":2.7,"tv":478.46,"id":7287690}]}]}
{"op":"mcm","clk":"1006081614","pt":1580646377200,"mc":[{"id":"1.168224552","rc":[{"batb":[[1,1.55,64.01],[2,1.54,2.02]],"ltp":1.57,"tv":1921.49,"id":7414058}]}]}
{"op":"mcm","clk":"1006081890","pt":1580646378612,"mc":[{"id":"1.168224552","rc":[{"batb":[[2,2.62,15.56]],"ltp":2.7,"tv":478.46,"id":7287690}]}]}
{"op":"mcm","clk":"1006104507","pt":1580646511247,"mc":[{"id":"1.168224552","rc":[{"trd":[[2.68,219.1],[2.7,14.61]],"batb":[[0,2.66,2.53],[1,2.62,15.56],[2,2.6,15.75]],"batl":[[1,2.82,4.25]],"ltp":2.68,"tv":580.46,"id":7287690},{"batb":[[1,1.55,2.04],[2,1.54,2]],"ltp":1.57,"tv":1921.49,"id":7414058}],"tv":2501.96}]}
{"op":"mcm","clk":"1006104620","pt":1580646511827,"mc":[{"id":"1.168224552","rc":[{"batb":[[1,2.52,16.59],[2,2.5,16.8]],"ltp":2.68,"tv":580.46,"id":7287690}]}]}
{"op":"mcm","clk":"1006120259","pt":1580646602412,"mc":[{"id":"1.168224552","rc":[{"batl":[[1,3.1,15.74],[2,5.5,153.72]],"ltp":2.68,"tv":580.46,"id":7287690},{"batb":[[0,1.57,13.27],[2,1.52,210.02]],"ltp":1.57,"tv":1921.49,"id":7414058}]}]}
{"op":"mcm","clk":"1006120338","pt":1580646602680,"mc":[{"id":"1.168224552","rc":[{"batl":[[1,2.82,4.25],[2,3.1,15.74]],"ltp":2.68,"tv":580.46,"id":7287690},{"batb":[[2,1.54,48.8]],"ltp":1.57,"tv":1921.49,"id":7414058}]}]}
{"op":"mcm","clk":"1006121662","pt":1580646609181,"mc":[{"id":"1.168224552","rc":[{"batl":[[1,2.82,3.75]],"ltp":2.68,"tv":580.46,"id":7287690},{"batb":[[2,1.54,2.06]],"ltp":1.57,"tv":1921.49,"id":7414058}]}]}
{"op":"mcm","clk":"1006121905","pt":1580646610461,"mc":[{"id":"1.168224552","rc":[{"batb":[[1,2.52,75.36]],"batl":[[0,2.78,3.75],[1,2.8,3.87],[2,2.82,3.75]],"ltp":2.68,"tv":580.46,"id":7287690},{"batb":[[0,1.58,124.63],[1,1.57,13.27],[2,1.56,2.08]],"ltp":1.57,"tv":1921.49,"id":7414058}]}]}
{"op":"mcm","clk":"1006121979","pt":1580646610887,"mc":[{"id":"1.168224552","rc":[{"batb":[[1,2.52,58.78],[2,2.48,17.03]],"batl":[[1,2.8,3.57]],"ltp":2.68,"tv":580.46,"id":7287690}]}]}
{"op":"mcm","clk":"1006123236","pt":1580646618283,"mc":[{"id":"1.168224552","rc":[{"batb":[[1,2.52,58.62]],"ltp":2.68,"tv":580.46,"id":7287690}]}]}
{"op":"mcm","clk":"1006123335","pt":1580646618882,"mc":[{"id":"1.168224552","rc":[{"batl":[[1,2.8,3.67],[2,3.1,15.74]],"ltp":2.68,"tv":580.46,"id":7287690}]}]}
{"op":"mcm","clk":"1006124466","pt":1580646625278,"mc":[{"id":"1.168224552","rc":[{"batl":[[1,3.1,15.74],[2,5.5,153.72]],"ltp":2.68,"tv":580.46,"id":7287690}]}]}
{"op":"mcm","clk":"1006124507","pt":1580646625490,"mc":[{"id":"1.168224552","rc":[{"batl":[[1,2.8,3.52],[2,3.1,15.74]],"ltp":2.68,"tv":580.46,"id":7287690}]}]}
{"op":"mcm","clk":"1006125935","pt":1580646633407,"mc":[{"id":"1.168224552","rc":[{"trd":[[2.74,61.99]],"batl":[[1,3.1,15.74],[2,5.5,153.72]],"ltp":2.74,"tv":583.26,"id":7287690},{"trd":[[1.58,160.3]],"batb":[[0,1.58,119.78]],"ltp":1.58,"tv":1926.34,"id":7414058}],"tv":2509.61}]}
{"op":"mcm","clk":"1006126042","pt":1580646634123,"mc":[{"id":"1.168224552","rc":[{"batl":[[1,2.8,3.27],[2,3.1,15.74]],"ltp":2.74,"tv":583.26,"id":7287690}]}]}
{"op":"mcm","clk":"1006127581","pt":1580646643007,"mc":[{"id":"1.168224552","rc":[{"batl":[[1,2.8,3.67]],"ltp":2.74,"tv":583.26,"id":7287690}]}]}
{"op":"mcm","clk":"1006128631","pt":1580646648819,"mc":[{"id":"1.168224552","rc":[{"batl":[[1,2.8,3.92]],"ltp":2.74,"tv":583.26,"id":7287690},{"batb":[[2,1.56,41.01]],"ltp":1.58,"tv":1926.34,"id":7414058}]}]}
{"op":"mcm","clk":"1006133560","pt":1580646677281,"mc":[{"id":"1.168224552","rc":[{"batl":[[0,1.6,40],[1,1.61,4.24],[2,1.62,4.94]],"ltp":1.58,"tv":1926.34,"id":7414058}]}]}
{"op":"mcm","clk":"1006133708","pt":1580646678080,"mc":[{"id":"1.168224552","rc":[{"batb":[[1,2.58,15.96],[2,2.52,58.62]],"batl":[[1,2.8,3.62]],"ltp":2.74,"tv":583.26,"id":7287690},{"trd":[[1.6,489.04]],"batl":[[0,1.6,1.17]],"ltp":1.6,"tv":2004.0,"id":7414058}],"tv":2587.27}]}
{"op":"mcm","clk":"1006133840","pt":1580646678666,"mc":[{"id":"1.168224552","rc":[{"batb":[[1,2.52,58.62],[2,2.48,17.03]],"ltp":2.74,"tv":583.26,"id":7287690}]}]}
{"op":"mcm","clk":"1006140282","pt":1580646714573,"mc":[{"id":"1.168224552","marketDefinition":{"bspMarket":false,"turnInPlayEnabled":true,"persistenceEnabled":true,"marketBaseRate":5.0,"eventId":"29681742","eventTypeId":"2","numberOfWinners":1,"bettingType":"ODDS","marketType":"MATCH_ODDS","marketTime":"2020-02-02T12:28:00.000Z","suspendTime":"2020-02-02T12:28:00.000Z","bspReconciled":false,"complete":true,"inPlay":false,"crossMatching":true,"runnersVoidable":false,"numberOfActiveRunners":2,"betDelay":0,"status":"OPEN","runners":[{"status":"ACTIVE","sortPriority":1,"id":7414058,"name":"Damir Dzumhur"},{"status":"ACTIVE","sortPriority":2,"id":7287690,"name":"Quentin Halys"}],"regulators":["MR_INT"],"countryCode":"FR","discountAllowed":true,"timezone":"UTC","openDate":"2020-02-02T13:08:00.000Z","version":3148727317,"name":"Match Odds","eventName":"Dzumhur v Halys"}}]}
{"op":"mcm","clk":"1006141082","pt":1580646718562,"mc":[{"id":"1.168224552","marketDefinition":{"bspMarket":false,"turnInPlayEnabled":true,"persistenceEnabled":true,"marketBaseRate":5.0,"eventId":"29681742","eventTypeId":"2","numberOfWinners":1,"bettingType":"ODDS","marketType":"MATCH_ODDS","marketTime":"2020-02-02T12:28:00.000Z","suspendTime":"2020-02-02T12:28:00.000Z","bspReconciled":false,"complete":true,"inPlay":false,"crossMatching":true,"runnersVoidable":false,"numberOfActiveRunners":2,"betDelay":0,"status":"OPEN","runners":[{"status":"ACTIVE","sortPriority":1,"id":7414058,"name":"Damir Dzumhur"},{"status":"ACTIVE","sortPriority":2,"id":7287690,"name":"Quentin Halys"}],"regulators":["MR_INT"],"countryCode":"FR","discountAllowed":true,"timezone":"UTC","openDate":"2020-02-02T12:28:00.000Z","version":3148727317,"name":"Match Odds","eventName":"Dzumhur v Halys"}}]}
{"op":"mcm","clk":"1006151401","pt":1580646778159,"mc":[{"id":"1.168224552","rc":[{"batl":[[0,3.1,15.74],[1,5.5,153.72],[2,95,15.9]],"ltp":2.74,"tv":583.26,"id":7287690},{"batb":[[2,1.55,68.31]],"ltp":1.6,"tv":2004.0,"id":7414058}]}]}
{"op":"mcm","clk":"1006160577","pt":1580646829460,"mc":[{"id":"1.168224552","rc":[{"batb":[[1,2.54,58.54]],"ltp":2.74,"tv":583.26,"id":7287690},{"trd":[[1.58,162.55]],"batb":[[0,1.58,118.65]],"ltp":1.58,"tv":2006.25,"id":7414058}],"tv":2589.52}]}
{"op":"mcm","clk":"1006160620","pt":1580646829733,"mc":[{"id":"1.168224552","rc":[{"batb":[[2,2.5,16.8]],"ltp":2.74,"tv":583.26,"id":7287690}]}]}
{"op":"mcm","clk":"1006162335","pt":1580646839426,"mc":[{"id":"1.168224552","rc":[{"batb":[[1,2.54,58.38]],"ltp":2.74,"tv":583.26,"id":7287690}]}]}
{"op":"mcm","clk":"1006167542","pt":1580646866865,"mc":[{"id":"1.168224552","rc":[{"trd":[[2.66,28.99]],"batb":[[0,2.54,58.38],[1,2.5,16.8],[2,2.48,17.03]],"batl":[[0,2.66,34.35],[1,3.1,15.74],[2,5.5,153.72]],"ltp":2.66,"tv":589.04,"id":7287690},{"trd":[[1.6,490.21]],"batl":[[0,1.61,4.24],[1,1.62,4.94],[2,1.65,25.33]],"ltp":1.6,"tv":2007.42,"id":7414058}],"tv":2596.46}]}
{"op":"mcm","clk":"1006167726","pt":1580646867775,"mc":[{"id":"1.168224552","rc":[{"batb":[[1,2.48,17.03],[2,2.22,37.86]],"ltp":2.66,"tv":589.04,"id":7287690}]}]}
{"op":"mcm","clk":"1006167949","pt":1580646868786,"mc":[{"id":"1.168224552","rc":[{"batb":[[2,1.55,114.14]],"ltp":1.6,"tv":2007.42,"id":7414058}]}]}
{"op":"mcm","clk":"1006183163","pt":1580646947074,"mc":[{"id":"1.168224552","rc":[{"trd":[[2.66,91.87]],"batl":[[0,2.66,2.91]],"ltp":2.66,"tv":651.91,"id":7287690}],"tv":2659.34}]}
{"op":"mcm","clk":"1006183309","pt":1580646947767,"mc":[{"id":"1.168224552","rc":[{"batb":[[1,2.5,16.8],[2,2.48,17.03]],"ltp":2.66,"tv":651.91,"id":7287690}]}]}
{"op":"mcm","clk":"1006184182","pt":1580646952277,"mc":[{"id":"1.168224552","rc":[{"trd":[[2.66,94.78]],"batl":[[0,3.1,15.74],[1,5.5,153.72],[2,95,15.9]],"ltp":2.66,"tv":654.82,"id":7287690},{"trd":[[1.6,495.05]],"batl":[[0,1.61,4.47]],"ltp":1.6,"tv":2012.26,"id":7414058}],"tv":2667.09}]}
{"op":"mcm","clk":"1006185677","pt":1580646959872,"mc":[{"id":"1.168224552","rc":[{"batb":[[0,2.54,85.27]],"batl":[[0,2.9,21.85],[1,3.1,15.74],[2,5.5,153.72]],"ltp":2.66,"tv":654.82,"id":7287690},{"batl":[[2,1.65,67.34]],"ltp":1.6,"tv":2012.26,"id":7414058}]}]}
{"op":"mcm","clk":"1006193269","pt":1580647000085,"mc":[{"id":"1.168224552","rc":[{"batl":[[0,1.61,4.24]],"ltp":1.6,"tv":2012.26,"id":7414058}]}]}
{"op":"mcm","clk":"1006209234","pt":1580647079361,"mc":[{"id":"1.168224552","rc":[{"trd":[[1.58,272.55]],"batb":[[0,1.58,63.65]],"ltp":1.58,"tv":2122.27,"id":7414058}],"tv":2777.09}]}
{"op":"mcm","clk":"1006209388","pt":1580647080161,"mc":[{"id":"1.168224552","rc":[{"batb":[[0,2.54,84.64]],"ltp":2.66,"tv":654.82,"id":7287690},{"batb":[[0,1.57,139.87],[1,1.55,114.14],[2,1.54,46.68]],"ltp":1.58,"tv":2122.27,"id":7414058}]}]}
{"op":"mcm","clk":"1006217311","pt":1580647120306,"mc":[{"id":"1.168224552","rc":[{"trd":[[1.61,670.82]],"batl":[[0,1.61,402.15]],"ltp":1.61,"tv":2302.27,"id":7414058}],"tv":2957.1}]}
{"op":"mcm","clk":"1006217411","pt":1580647120798,"mc":[{"id":"1.168224552","rc":[{"batb":[[0,2.56,16.16],[1,2.54,84.64],[2,2.5,16.8]],"ltp":2.66,"tv":654.82,"id":7287690},{"batb":[[1,1.55,68.31],[2,1.53,126.53]],"batl":[[0,1.62,4.94],[1,1.65,67.34],[2,1.8,495.99]],"ltp":1.61,"tv":2302.27,"id":7414058}]}]}
{"op":"mcm","clk":"1006217607","pt":1580647121778,"mc":[{"id":"1.168224552","rc":[{"batb":[[0,2.54,84.64],[1,2.5,16.8],[2,2.48,17.03]],"ltp":2.66,"tv":654.82,"id":7287690},{"batb":[[1,1.55,114.14]],"ltp":1.61,"tv":2302.27,"id":7414058}]}]}
{"op":"mcm","clk":"1006238006","pt":1580647222420,"mc":[{"id":"1.168224552","rc":[{"batb":[[0,2.54,26.89]],"ltp":2.66,"tv":654.82,"id":7287690},{"batb":[[0,1.57,13.27]],"ltp":1.61,"tv":2302.27,"id":7414058}]}]}
{"op":"mcm","clk":"1006238227","pt":1580647223354,"mc":[{"id":"1.168224552","marketDefinition":{"bspMarket":false,"turnInPlayEnabled":true,"persistenceEnabled":true,"marketBaseRate":5.0,"eventId":"29681742","eventTypeId":"2","numberOfWinners":1,"bettingType":"ODDS","marketType":"MATCH_ODDS","marketTime":"2020-02-02T12:28:00.000Z","suspendTime":"2020-02-02T12:28:00.000Z","bspReconciled":false,"complete":true,"inPlay":true,"crossMatching":true,"runnersVoidable":false,"numberOfActiveRunners":2,"betDelay":3,"status":"OPEN","runners":[{"status":"ACTIVE","sortPriority":1,"id":7414058,"name":"Damir Dzumhur"},{"status":"ACTIVE","sortPriority":2,"id":7287690,"name":"Quentin Halys"}],"regulators":["MR_INT"],"countryCode":"FR","discountAllowed":true,"timezone":"UTC","openDate":"2020-02-02T12:28:00.000Z","version":3148750549,"name":"Match Odds","eventName":"Dzumhur v Halys"},"rc":[{"batb":[[0,1.11,37.97],[1,1.03,9],[2,1.02,25.41]],"batl":[[0,1000,0.02],[1,3.1,0],[2,5.5,0]],"ltp":2.66,"tv":654.82,"id":7287690},{"batb":[[0,1.11,37.97],[1,1.05,152.3],[2,1.04,169.36]],"batl":[[1,3,42.77],[2,1000,0.02]],"ltp":1.61,"tv":2302.27,"id":7414058}]}]}
{"op":"mcm","clk":"1006239219","pt":1580647228230,"mc":[{"id":"1.168224552","rc":[{"batb":[[0,1.56,254.18],[1,1.55,227.78],[2,1.11,37.97]],"batl":[[0,1.61,371.49],[1,1.62,196.39],[2,3,42.77]],"ltp":1.61,"tv":2302.27,"id":7414058}]}]}
{"op":"mcm","clk":"1006239793","pt":1580647230838,"mc":[{"id":"1.168224552","rc":[{"batb":[[0,1.8,75.72],[1,1.11,37.97],[2,1.03,9]],"ltp":2.66,"tv":654.82,"id":7287690},{"batb":[[0,1.11,37.97],[1,1.05,152.3],[2,1.04,169.36]],"batl":[[0,1.62,4.94],[1,3,42.77],[2,1000,0.02]],"ltp":1.61,"tv":2302.27,"id":7414058}]}]}
{"op":"mcm","clk":"1006240435","pt":1580647233944,"mc":[{"id":"1.168224552","rc":[{"batb":[[2,1.03,387.62]],"ltp":2.66,"tv":654.82,"id":7287690},{"batb":[[0,1.5,437.69],[1,1.49,267.53],[2,1.11,37.97]],"batl":[[1,1.67,230.88],[2,1.69,333.22]],"ltp":1.61,"tv":2302.27,"id":7414058}]}]}
{"op":"mcm","clk":"1006241131","pt":1580647237244,"mc":[{"id":"1.168224552","rc":[{"batb":[[1,1.26,3.38],[2,1.11,37.96]],"ltp":2.66,"tv":654.82,"id":7287690}]}]}
{"op":"mcm","clk":"1006241361","pt":1580647238431,"mc":[{"id":"1.168224552","rc":[{"batl":[[1,3,42.77],[2,1000,0.02]],"ltp":1.61,"tv":2302.27,"id":7414058}]}]}
{"op":"mcm","clk":"1006241965","pt":1580647241472,"mc":[{"id":"1.168224552","rc":[{"batl":[[0,3.15,318],[1,1000,0.02]],"ltp":2.66,"tv":654.82,"id":7287690},{"batl":[[0,1.54,721],[1,1.55,342.97],[2,1.56,219.89]],"ltp":1.61,"tv":2302.27,"id":7414058}]}]}
{"op":"mcm","clk":"1006242151","pt":1580647242255,"mc":[{"id":"1.168224552","rc":[{"batb":[[0,2.82,46.66],[1,2.62,55.86],[2,1.8,75.72]],"ltp":2.66,"tv":654.82,"id":7287690},{"batb":[[0,1.5,410.01],[1,1.43,187.04],[2,1.11,37.96]],"batl":[[1,1.55,306.35]],"ltp":1.61,"tv":2302.27,"id":7414058}]}]}
{"op":"mcm","clk":"1006242283","pt":1580647242859,"mc":[{"id":"1.168224552","rc":[{"batb":[[1,2.7,24.37],[2,2.62,55.86]],"batl":[[0,3.15,337.32]],"ltp":2.66,"tv":654.82,"id":7287690},{"batb":[[1,1.47,89.07],[2,1.43,187.03]],"ltp":1.61,"tv":2302.27,"id":7414058}]}]}
{"op":"mcm","clk":"1006242761","pt":1580647244950,"mc":[{"id":"1.168224552","rc":[{"batb":[[0,1.51,215.47],[1,1.5,410.01],[2,1.47,89.07]],"ltp":1.61,"tv":2302.27,"id":7414058}]}]}
{"op":"mcm","clk":"1006243382","pt":1580647248144,"mc":[{"id":"1.168224552","rc":[{"trd":[[1.51,57.57]],"batb":[[0,1.51,192.75],[2,1.48,494.04]],"ltp":1.51,"tv":2347.71,"id":7414058}],"tv":3002.53}]}
{"op":"mcm","clk":"1006244583","pt":1580647254072,"mc":[{"id":"1.168224552","rc":[{"batb":[[0,2.7,24.37],[1,2.62,55.86],[2,1.8,75.72]],"batl":[[0,3.15,19.32]],"ltp":2.66,"tv":654.82,"id":7287690},{"batb":[[0,1.48,494.04],[1,1.47,89.06],[2,1.46,510.84]],"batl":[[0,1.57,480.59],[1,1.58,42.01],[2,1.59,497.4]],"ltp":1.51,"tv":2347.71,"id":7414058}]}]}
{"op":"mcm","clk":"1006244898","pt":1580647255465,"mc":[{"id":"1.168224552","rc":[{"batb":[[0,2.62,55.86],[1,1.8,75.72],[2,1.6,75.72]],"batl":[[0,1000,0.02],[1,1000,0]],"ltp":2.66,"tv":654.82,"id":7287690},{"batb":[[1,1.46,510.84],[2,1.43,187.03]],"batl":[[1,1.59,497.4],[2,1.61,4.97]],"ltp":1.51,"tv":2347.71,"id":7414058}]}]}
{"op":"mcm","clk":"1006245219","pt":1580647256962,"mc":[{"id":"1.168224552","rc":[{"batb":[[2,1.7,75.72]],"ltp":2.66,"tv":654.82,"id":7287690},{"batb":[[2,1.43,616.9]],"batl":[[2,1.61,345.32]],"ltp":1.51,"tv":2347.71,"id":7414058}]}]}
{"op":"mcm","clk":"1006246225","pt":1580647261857,"mc":[{"id":"1.168224552","rc":[{"batb":[[2,1.43,187.03]],"batl":[[0,1.61,345.32],[1,1.62,191.47],[2,3,42.77]],"ltp":1.51,"tv":2347.71,"id":7414058}]}]}
{"op":"mcm","clk":"1006246975","pt":1580647265477,"mc":[{"id":"1.168224552","rc":[{"batb":[[1,2.46,65.15],[2,1.8,75.72]],"batl":[[0,2.92,319],[1,1000,0.02]],"ltp":2.66,"tv":654.82,"id":7287690},{"batb":[[0,1.56,416.68],[1,1.55,227.82],[2,1.48,653.38]],"batl":[[0,1.6,645],[1,1.61,345.32],[2,1.62,191.47]],"ltp":1.51,"tv":2347.71,"id":7414058}]}]}
{"op":"mcm","clk":"1006247191","pt":1580647266491,"mc":[{"id":"1.168224552","rc":[{"batb":[[1,2.6,26.05],[2,2.46,65.15]],"batl":[[1,2.98,21],[2,1000,0.02]],"ltp":2.66,"tv":654.82,"id":7287690},{"batb":[[2,1.51,82.34]],"ltp":1.51,"tv":2347.71,"id":7414058}]}]}
{"op":"mcm","clk":"1006248176","pt":1580647271375,"mc":[{"id":"1.168224552","rc":[{"batb":[[2,1.54,494.03]],"ltp":1.51,"tv":2347.71,"id":7414058}]}]}
{"op":"mcm","clk":"1006249257","pt":1580647276463,"mc":[{"id":"1.168224552","rc":[{"batb":[[0,2.6,26.05],[1,2.46,65.15],[2,1.8,75.72]],"batl":[[0,2.98,21],[1,1000,0.02],[2,1000,0]],"ltp":2.66,"tv":654.82,"id":7287690},{"batb":[[0,1.54,494.03],[1,1.52,510.84],[2,1.51,82.34]],"batl":[[0,1.61,4.97],[1,1.63,522.6],[2,1.65,497.4]],"ltp":1.51,"tv":2347.71,"id":7414058}]}]}
{"op":"mcm","clk":"1006249476","pt":1580647277484,"mc":[{"id":"1.168224552","rc":[{"batb":[[0,2.46,65.15],[1,1.8,75.72],[2,1.7,75.72]],"batl":[[0,1000,0.02],[1,1000,0]],"ltp":2.66,"tv":654.82,"id":7287690},{"batb":[[2,1.48,159.34]],"batl":[[1,1.63,480.59]],"ltp":1.51,"tv":2347.71,"id":7414058}]}]}
{"op":"mcm","clk":"1006249616","pt":1580647278164,"mc":[{"id":"1.168224552","rc":[{"batl":[[0,1.63,480.59],[1,1.65,497.4],[2,3,42.77]],"ltp":1.51,"tv":2347.71,"id":7414058}]}]}
{"op":"mcm","clk":"1006249829","pt":1580647279298,"mc":[{"id":"1.168224552","rc":[{"batb":[[2,1.48,549.11]],"batl":[[2,1.67,312.22]],"ltp":1.51,"tv":2347.71,"id":7414058}]}]}
{"op":"mcm","clk":"1006250022","pt":1580647280204,"mc":[{"id":"1.168224552","rc":[{"batb":[[2,1.48,159.34]],"batl":[[0,1.67,312.22],[1,1.69,332.5],[2,3,42.01]],"ltp":1.51,"tv":2347.71,"id":7414058}]}]}
{"op":"mcm","clk":"1006250403","pt":1580647282207,"mc":[{"id":"1.168224552","rc":[{"trd":[[1.54,10.6]],"batb":[[0,1.54,488.73]],"batl":[[0,1.6,2],[1,1.67,312.22],[2,1.69,332.5]],"ltp":1.54,"tv":2358.31,"id":7414058}],"tv":3013.14}]}
{"op":"mcm","clk":"1006250623","pt":1580647283198,"mc":[{"id":"1.168224552","rc":[{"trd":[[2.66,95.98]],"batl":[[0,2.74,384],[1,1000,0.02]],"ltp":2.66,"tv":656.02,"id":7287690},{"trd":[[1.6,497.05]],"batb":[[0,1.62,1388.89],[1,1.54,488.73],[2,1.52,510.84]],"batl":[[0,1.66,523.76],[1,1.67,1658.77]],"ltp":1.6,"tv":2360.31,"id":7414058}],"tv":3016.34}]}
{"op":"mcm","clk":"1006250849","pt":1580647284409,"mc":[{"id":"1.168224552","rc":[{"batb":[[1,2.34,74.75],[2,1.8,75.72]],"ltp":2.66,"tv":656.02,"id":7287690},{"batb":[[0,1.62,1700.52],[1,1.61,197.13],[2,1.54,625.64]],"ltp":1.6,"tv":2360.31,"id":7414058}]}]}
{"op":"mcm","clk":"1006251042","pt":1580647285396,"mc":[{"id":"1.168224552","rc":[{"batb":[[0,2.46,93.72]],"batl":[[1,2.82,22.69],[2,1000,0.02]],"ltp":2.66,"tv":656.02,"id":7287690},{"batb":[[2,1.6,2]],"batl":[[2,1.68,42.01]],"ltp":1.6,"tv":2360.31,"id":7414058}]}]}
{"op":"mcm","clk":"1006251059","pt":1580647285492,"mc":[{"id":"1.168224552","rc":[{"batb":[[2,1.56,74.78]],"ltp":1.6,"tv":2360.31,"id":7414058}]}]}
{"op":"mcm","clk":"1006251794","pt":1580647289004,"mc":[{"id":"1.168224552","rc":[{"batb":[[2,1.6,494.03]],"ltp":1.6,"tv":2360.31,"id":7414058}]}]}
{"op":"mcm","clk":"1006252227","pt":1580647291122,"mc":[{"id":"1.168224552","rc":[{"trd":[[1.62,10.08]],"batb":[[0,1.62,1695.48]],"ltp":1.62,"tv":2370.39,"id":7414058}],"tv":3026.42}]}
{"op":"mcm","clk":"1006253059","pt":1580647295204,"mc":[{"id":"1.168224552","rc":[{"batl":[[0,2.82,22.69],[1,1000,0.02],[2,1000,0]],"ltp":2.66,"tv":656.02,"id":7287690},{"batb":[[0,1.62,311.63]],"batl":[[0,1.67,312.22],[1,1.68,42.01],[2,1.69,813.09]],"ltp":1.62,"tv":2370.39,"id":7414058}]}]}
{"op":"mcm","clk":"1006253134","pt":1580647295627,"mc":[{"id":"1.168224552","rc":[{"batb":[[0,2.34,74.75],[1,1.8,75.72],[2,1.7,75.72]],"batl":[[0,1000,0.02],[1,1000,0]],"ltp":2.66,"tv":656.02,"id":7287690},{"batb":[[0,1.6,494.03],[1,1.59,494.03],[2,1.58,510.84]],"batl":[[0,1.69,481.35],[1,1.7,480.59],[2,1.71,497.4]],"ltp":1.62,"tv":2370.39,"id":7414058}]}]}
{"op":"mcm","clk":"1006254224","pt":1580647301206,"mc":[{"id":"1.168224552","rc":[{"batb":[[0,1.6,803.04],[1,1.59,700.93]],"batl":[[0,1.65,240.24],[1,1.66,176.82],[2,1.69,480.59]],"ltp":1.62,"tv":2370.39,"id":7414058}]}]}
{"op":"mcm","clk":"1006254732","pt":1580647304017,"mc":[{"id":"1.168224552","rc":[{"batb":[[0,1.6,494.03],[1,1.59,494.03]],"batl":[[0,1.69,481.35],[1,1.7,480.59],[2,1.71,497.4]],"ltp":1.62,"tv":2370.39,"id":7414058}]}]}
{"op":"mcm","clk":"1006256256","pt":1580647311776,"mc":[{"id":"1.168224552","rc":[{"batl":[[0,1.72,245.2],[1,1.74,301.76],[2,3,42.01]],"ltp":1.62,"tv":2370.39,"id":7414058}]}]}
{"op":"mcm","clk":"1006256758","pt":1580647314388,"mc":[{"id":"1.168224552","rc":[{"batl":[[0,2.52,2426],[1,2.6,413],[2,2.7,5.4]],"ltp":2.66,"tv":656.02,"id":7287690},{"trd":[[1.66,1.52]],"batb":[[0,1.66,1111.27],[1,1.6,494.03],[2,1.59,494.03]],"batl":[[0,1.72,790.44]],"ltp":1.66,"tv":2371.91,"id":7414058}],"tv":3027.93}]}
{"op":"mcm","clk":"1006256974","pt":1580647315408,"mc":[{"id":"1.168224552","rc":[{"batb":[[1,2.26,81.59],[2,1.8,75.72]],"batl":[[0,2.6,413],[1,1000,0.02],[2,2.7,0]],"ltp":2.66,"tv":656.02,"id":7287690},{"batb":[[0,1.68,101.03],[1,1.67,187.2],[2,1.66,287.69]],"ltp":1.66,"tv":2371.91,"id":7414058}]}]}
{"op":"mcm","clk":"1006257175","pt":1580647316480,"mc":[{"id":"1.168224552","rc":[{"batb":[[0,2.36,30.25],[1,2.34,74.75],[2,2.26,81.59]],"batl":[[1,2.7,24.37],[2,1000,0.02]],"ltp":2.66,"tv":656.02,"id":7287690},{"batl":[[0,1.72,832.45]],"ltp":1.66,"tv":2371.91,"id":7414058}]}]}
{"op":"mcm","clk":"1006259182","pt":1580647326924,"mc":[{"id":"1.168224552","rc":[{"batb":[[1,2.26,81.59],[2,1.7,75.72]],"batl":[[0,2.7,24.37],[1,1000,0.02],[2,1000,0]],"ltp":2.66,"tv":656.02,"id":7287690},{"batb":[[0,1.62,114.56],[1,1.6,69.74],[2,1.25,378.63]],"batl":[[0,1.72,42.01],[1,3,42.01],[2,1000,0.02]],"ltp":1.66,"tv":2371.91,"id":7414058}]}]}
{"op":"mcm","clk":"1006259368","pt":1580647327824,"mc":[{"id":"1.168224552","rc":[{"batb":[[0,2.26,81.59],[1,1.7,75.72],[2,1.6,75.72]],"batl":[[0,1000,0.02],[1,1000,0]],"ltp":2.66,"tv":656.02,"id":7287690},{"batb":[[1,1.3,113.59],[2,1.25,378.62]],"batl":[[0,3,42.01],[1,1000,0.02],[2,1000,0]],"ltp":1.66,"tv":2371.91,"id":7414058}]}]}
{"op":"mcm","clk":"1006260475","pt":1580647333410,"mc":[{"id":"1.168224552","rc":[{"batb":[[0,1.66,189.31],[1,1.65,180.33],[2,1.62,114.56]],"batl":[[0,1.71,256.71],[1,1.73,307.54],[2,3,42.01]],"ltp":1.66,"tv":2371.91,"id":7414058}]}]}
{"op":"mcm","clk":"1006261033","pt":1580647336217,"mc":[{"id":"1.168224552","rc":[{"batb":[[0,1.62,114.56],[1,1.3,113.59],[2,1.25,378.62]],"batl":[[0,3,42.01],[1,1000,0.02],[2,3,0]],"ltp":1.66,"tv":2371.91,"id":7414058}]}]}
{"op":"mcm","clk":"1006261759","pt":1580647339927,"mc":[{"id":"1.168224552","rc":[{"batb":[[0,1.62,335.8],[1,1.61,197.21],[2,1.3,113.59]],"ltp":1.66,"tv":2371.91,"id":7414058}]}]}
{"op":"mcm","clk":"1006262044","pt":1580647341469,"mc":[{"id":"1.168224552","rc":[{"batb":[[0,2.48,742.17],[1,2.26,81.59],[2,1.7,75.72]],"batl":[[0,2.76,360],[1,1000,0.02]],"ltp":2.66,"tv":656.02,"id":7287690},{"batl":[[0,1.65,503],[1,1.66,3721.2],[2,1.72,8.58]],"ltp":1.66,"tv":2371.91,"id":7414058}]}]}
{"op":"mcm","clk":"1006262232","pt":1580647342431,"mc":[{"id":"1.168224552","rc":[{"batb":[[0,2.48,138.98],[1,2.34,75.14]],"ltp":2.66,"tv":656.02,"id":7287690},{"batb":[[2,1.53,139.9]],"batl":[[1,1.67,288.83],[2,1.69,332.65]],"ltp":1.66,"tv":2371.91,"id":7414058}]}]}
{"op":"mcm","clk":"1006262289","pt":1580647342714,"mc":[{"id":"1.168224552","rc":[{"batb":[[1,2.46,28.57],[2,2.34,75.14]],"batl":[[1,2.84,22.69],[2,1000,0.02]],"ltp":2.66,"tv":656.02,"id":7287690},{"batb":[[2,1.55,75.62]],"batl":[[2,1.68,42.01]],"ltp":1.66,"tv":2371.91,"id":7414058}]}]}
{"op":"mcm","clk":"1006263210","pt":1580647347643,"mc":[{"id":"1.168224552","rc":[{"batb":[[2,1.6,494.03]],"batl":[[2,1.68,522.6]],"ltp":1.66,"tv":2371.91,"id":7414058}]}]}
{"op":"mcm","clk":"1006263851","pt":1580647350756,"mc":[{"id":"1.168224552","rc":[{"trd":[[1.62,10.57]],"batb":[[0,1.62,335.55]],"ltp":1.62,"tv":2372.4,"id":7414058}],"tv":3028.43}]}
{"op":"mcm","clk":"1006264929","pt":1580647356143,"mc":[{"id":"1.168224552","rc":[{"batb":[[0,2.46,28.57],[1,2.34,75.14],[2,1.8,75.72]],"batl":[[0,2.84,22.69],[1,1000,0.02],[2,1000,0]],"ltp":2.66,"tv":656.02,"id":7287690},{"batb":[[0,1.6,494.03],[1,1.59,494.03],[2,1.58,510.84]],"batl":[[0,1.68,522.6],[1,1.69,480.59],[2,1.7,497.4]],"ltp":1.62,"tv":2372.4,"id":7414058}]}]}
{"op":"mcm","clk":"1006265210","pt":1580647357578,"mc":[{"id":"1.168224552","rc":[{"batb":[[0,2.34,75.14],[1,1.8,75.72],[2,1.7,75.72]],"batl":[[0,1000,0.02],[1,1000,0]],"ltp":2.66,"tv":656.02,"id":7287690},{"batl":[[0,1.68,480.59]],"ltp":1.62,"tv":2372.4,"id":7414058}]}]}
{"op":"mcm","clk":"1006266182","pt":1580647362563,"mc":[{"id":"1.168224552","rc":[{"batl":[[0,1.73,256.75],[1,1.75,296.02],[2,3,42.01]],"ltp":1.62,"tv":2372.4,"id":7414058}]}]}
{"op":"mcm","clk":"1006266734","pt":1580647365477,"mc":[{"id":"1.168224552","rc":[{"batl":[[0,2.5,85.18],[1,2.6,356],[2,1000,0.02]],"ltp":2.66,"tv":656.02,"id":7287690},{"batb":[[0,1.67,333.63],[1,1.66,176.9],[2,1.62,125.74]],"batl":[[0,1.72,631],[1,1.73,256.75],[2,1.75,296.02]],"ltp":1.62,"tv":2372.4,"id":7414058}]}]}
{"op":"mcm","clk":"1006266931","pt":1580647366353,"mc":[{"id":"1.168224552","rc":[{"batb":[[1,2.16,92.69]],"ltp":2.66,"tv":656.02,"id":7287690},{"batb":[[0,1.68,100.56],[1,1.67,333.63],[2,1.66,176.9]],"ltp":1.62,"tv":2372.4,"id":7414058}]}]}
{"op":"mcm","clk":"1006266950","pt":1580647366493,"mc":[{"id":"1.168224552","rc":[{"batb":[[0,2.34,106.23]],"batl":[[2,2.66,25.21]],"ltp":2.66,"tv":656.02,"id":7287690},{"batl":[[2,1.75,338.03]],"ltp":1.62,"tv":2372.4,"id":7414058}]}]}
{"op":"mcm","clk":"1006267268","pt":1580647367980,"mc":[{"id":"1.168224552","rc":[{"trd":[[1.68,3.36]],"batb":[[0,1.68,98.87]],"ltp":1.68,"tv":2375.76,"id":7414058}],"tv":3031.79}]}
{"op":"mcm","clk":"1006267900","pt":1580647371068,"mc":[{"id":"1.168224552","rc":[{"batb":[[1,2.16,92.53]],"ltp":2.66,"tv":656.02,"id":7287690}]}]}
{"op":"mcm","clk":"1006268460","pt":1580647373884,"mc":[{"id":"1.168224552","rc":[{"trd":[[1.68,23.63]],"batb":[[0,1.68,88.73]],"ltp":1.68,"tv":2396.03,"id":7414058}],"tv":3052.06}]}
{"op":"mcm","clk":"1006269515","pt":1580647379375,"mc":[{"id":"1.168224552","rc":[{"trd":[[1.68,27.63]],"batb":[[0,1.68,86.73]],"ltp":1.68,"tv":2400.03,"id":7414058}],"tv":3056.06}]}
{"op":"mcm","clk":"1006269673","pt":1580647380059,"mc":[{"id":"1.168224552","rc":[{"trd":[[1.68,31.63]],"batb":[[0,1.68,84.73]],"ltp":1.68,"tv":2404.03,"id":7414058}],"tv":3060.06}]}
{"op":"mcm","clk":"1006270141","pt":1580647382394,"mc":[{"id":"1.168224552","rc":[{"batb":[[0,2.34,105.99],[1,2.18,92.37]],"ltp":2.66,"tv":656.02,"id":7287690}]}]}
{"op":"mcm","clk":"1006272606","pt":1580647395098,"mc":[{"id":"1.168224552","rc":[{"trd":[[1.67,587.78],[1.68,201.09]],"batb":[[0,1.67,39.74],[1,1.66,176.9],[2,1.62,239.36]],"ltp":1.67,"tv":3161.27,"id":7414058}],"tv":3817.3}]}
{"op":"mcm","clk":"1006272703","pt":1580647395629,"mc":[{"id":"1.168224552","rc":[{"batb":[[0,1.66,176.9],[1,1.62,239.36],[2,1.61,68.06]],"batl":[[1,1.75,42.01],[2,3,42.01]],"ltp":1.67,"tv":3161.27,"id":7414058}]}]}
{"op":"mcm","clk":"1006273264","pt":1580647398505,"mc":[{"id":"1.168224552","rc":[{"batb":[[0,1.66,349.19],[1,1.65,181.26],[2,1.62,239.36]],"batl":[[0,1.72,892.83],[1,1.74,302.49],[2,1.75,42.01]],"ltp":1.67,"tv":3161.27,"id":7414058}]}]}
{"op":"mcm","clk":"1006274128","pt":1580647402745,"mc":[{"id":"1.168224552","rc":[{"batb":[[0,1.62,239.36],[1,1.61,68.06],[2,1.3,113.59]],"batl":[[0,1.72,631],[1,1.75,42.01],[2,3,42.01]],"ltp":1.67,"tv":3161.27,"id":7414058}]}]}
{"op":"mcm","clk":"1006274727","pt":1580647405622,"mc":[{"id":"1.168224552","rc":[{"batb":[[0,1.62,426],[1,1.61,265.69]],"batl":[[2,1.82,256.84]],"ltp":1.67,"tv":3161.27,"id":7414058}]}]}
{"op":"mcm","clk":"1006275038","pt":1580647407239,"mc":[{"id":"1.168224552","rc":[{"batl":[[0,2.66,25.21],[1,1000,0.02],[2,2.66,0]],"ltp":2.66,"tv":656.02,"id":7287690},{"batb":[[0,1.62,300.26]],"batl":[[0,1.75,42.01],[1,1.82,256.84],[2,1.84,252.31]],"ltp":1.67,"tv":3161.27,"id":7414058}]}]}
{"op":"mcm","clk":"1006275128","pt":1580647407624,"mc":[{"id":"1.168224552","rc":[{"batb":[[0,2.18,92.37],[1,1.7,75.72],[2,1.6,75.72]],"batl":[[0,1000,0.02],[1,1000,0]],"ltp":2.66,"tv":656.02,"id":7287690},{"batb":[[1,1.61,197.63]],"batl":[[0,1.82,256.84],[1,1.84,252.31],[2,3,42.01]],"ltp":1.67,"tv":3161.27,"id":7414058}]}]}
{"op":"mcm","clk":"1006275707","pt":1580647410447,"mc":[{"id":"1.168224552","rc":[{"batb":[[0,2.2,90.56],[1,2.18,92.37],[2,1.7,75.72]],"ltp":2.66,"tv":656.02,"id":7287690},{"batb":[[0,1.62,113.62],[1,1.61,115.98]],"batl":[[0,3,42.01],[1,1000,0.02],[2,3,0]],"ltp":1.67,"tv":3161.27,"id":7414058}]}]}
{"op":"mcm","clk":"1006275739","pt":1580647410663,"mc":[{"id":"1.168224552","rc":[{"batb":[[1,1.7,75.72],[2,1.6,75.72]],"ltp":2.66,"tv":656.02,"id":7287690},{"batb":[[0,1.61,115.98],[1,1.3,113.59],[2,1.25,378.62]],"ltp":1.67,"tv":3161.27,"id":7414058}]}]}
{"op":"mcm","clk":"1006277031","pt":1580647417031,"mc":[{"id":"1.168224552","rc":[{"batb":[[0,1.62,186.64],[1,1.61,313.61],[2,1.3,113.59]],"batl":[[0,1.82,256.84],[1,1.84,252.31],[2,3,42.01]],"ltp":1.67,"tv":3161.27,"id":7414058}]}]}
{"op":"mcm","clk":"1006277824","pt":1580647421035,"mc":[{"id":"1.168224552","rc":[{"batl":[[0,3,42.01],[1,1000,0.02],[2,3,0]],"ltp":1.67,"tv":3161.27,"id":7414058}]}]}
{"op":"mcm","clk":"1006278476","pt":1580647424441,"mc":[{"id":"1.168224552","rc":[{"batb":[[0,2.5,63.89],[1,2.42,74.87],[2,2.34,77.58]],"batl":[[0,2.74,340],[1,1000,0.02]],"ltp":2.66,"tv":656.02,"id":7287690},{"batb":[[2,1.57,126.6]],"batl":[[0,1.66,593],[1,1.67,324.4],[2,1.69,461.32]],"ltp":1.67,"tv":3161.27,"id":7414058}]}]}
{"op":"mcm","clk":"1006278596","pt":1580647425053,"mc":[{"id":"1.168224552","rc":[{"batb":[[1,2.42,104.28]],"batl":[[1,2.78,23.53],[2,1000,0.02]],"ltp":2.66,"tv":656.02,"id":7287690},{"batb":[[2,1.57,199.7]],"ltp":1.67,"tv":3161.27,"id":7414058}]}]}
{"op":"mcm","clk":"1006279493","pt":1580647430062,"mc":[{"id":"1.168224552","rc":[{"batb":[[2,1.58,494.03]],"batl":[[2,1.69,941.91]],"ltp":1.67,"tv":3161.27,"id":7414058}]}]}
{"op":"mcm","clk":"1006280209","pt":1580647433879,"mc":[{"id":"1.168224552","rc":[{"batb":[[0,2.42,29.41],[1,2.34,77.58],[2,1.7,75.72]],"batl":[[0,2.78,23.53],[1,1000,0.02],[2,1000,0]],"ltp":2.66,"tv":656.02,"id":7287690},{"batb":[[0,1.58,494.03],[1,1.57,199.7],[2,1.56,510.84]],"batl":[[0,1.69,480.59],[1,1.71,539.41],[2,3,42.01]],"ltp":1.67,"tv":3161.27,"id":7414058}]}]}
{"op":"mcm","clk":"1006280546","pt":1580647435684,"mc":[{"id":"1.168224552","rc":[{"batb":[[0,2.34,77.58],[1,1.7,75.72],[2,1.6,75.72]],"batl":[[0,1000,0.02],[1,1000,0]],"ltp":2.66,"tv":656.02,"id":7287690},{"batb":[[1,1.57,126.6]],"batl":[[1,1.71,497.4]],"ltp":1.67,"tv":3161.27,"id":7414058}]}]}
{"op":"mcm","clk":"1006281145","pt":1580647438966,"mc":[{"id":"1.168224552","rc":[{"batb":[[0,1.63,255.02],[1,1.62,193.42],[2,1.58,494.03]],"batl":[[0,1.68,242.48],[1,1.69,480.59],[2,1.7,327.24]],"ltp":1.67,"tv":3161.27,"id":7414058}]}]}
{"op":"mcm","clk":"1006281909","pt":1580647443012,"mc":[{"id":"1.168224552","rc":[{"batb":[[0,1.58,494.03],[1,1.57,126.6],[2,1.56,510.84]],"batl":[[0,1.69,480.59],[1,1.71,497.4],[2,3,42.01]],"ltp":1.67,"tv":3161.27,"id":7414058}]}]}
{"op":"mcm","clk":"1006282526","pt":1580647445867,"mc":[{"id":"1.168224552","rc":[{"batb":[[0,1.58,730.32],[1,1.57,343.93]],"batl":[[2,1.74,211.64]],"ltp":1.67,"tv":3161.27,"id":7414058}]}]}
{"op":"mcm","clk":"1006283241","pt":1580647449686,"mc":[{"id":"1.168224552","rc":[{"batb":[[0,1.58,236.29],[2,1.3,113.59]],"batl":[[2,3,42.01]],"ltp":1.67,"tv":3161.27,"id":7414058}]}]}
{"op":"mcm","clk":"1006283784","pt":1580647452375,"mc":[{"id":"1.168224552","rc":[{"batb":[[0,2.64,774.22],[1,2.34,77.58],[2,1.7,75.72]],"batl":[[0,2.86,293],[1,1000,0.02]],"ltp":2.66,"tv":656.02,"id":7287690},{"batl":[[0,1.62,715],[1,1.64,3788],[2,1.65,1306.92]],"ltp":1.67,"tv":3161.27,"id":7414058}]}]}
{"op":"mcm","clk":"1006283960","pt":1580647453271,"mc":[{"id":"1.168224552","rc":[{"batb":[[0,2.64,77.42],[1,2.6,57.67],[2,2.46,67.43]],"ltp":2.66,"tv":656.02,"id":7287690},{"batb":[[2,1.54,136.75]],"batl":[[1,1.63,350.14],[2,1.64,183.87]],"ltp":1.67,"tv":3161.27,"id":7414058}]}]}
{"op":"mcm","clk":"1006284345","pt":1580647455383,"mc":[{"id":"1.168224552","rc":[{"batb":[[1,2.6,60.35],[2,2.5,27.73]],"batl":[[1,2.88,21.85],[2,1000,0.02]],"ltp":2.66,"tv":656.02,"id":7287690},{"batb":[[2,1.56,2.7]],"ltp":1.67,"tv":3161.27,"id":7414058}]}]}
{"op":"mcm","clk":"1006284523","pt":1580647456396,"mc":[{"id":"1.168224552","rc":[{"batb":[[1,2.6,57.67]],"ltp":2.66,"tv":656.02,"id":7287690}]}]}
{"op":"mcm","clk":"1006285576","pt":1580647462114,"mc":[{"id":"1.168224552","rc":[{"batb":[[0,2.5,27.73],[1,2.46,67.12],[2,1.8,75.72]],"batl":[[0,2.88,21.85],[1,1000,0.02],[2,1000,0]],"ltp":2.66,"tv":656.02,"id":7287690},{"batb":[[0,1.56,2.7],[1,1.54,214.05],[2,1.38,448.46]],"batl":[[0,1.67,42.01],[1,2.04,383.01],[2,3,42.01]],"ltp":1.67,"tv":3161.27,"id":7414058}]}]}
{"op":"mcm","clk":"1006285870","pt":1580647463615,"mc":[{"id":"1.168224552","rc":[{"batb":[[0,2.46,67.12],[1,1.8,75.72],[2,1.7,75.72]],"batl":[[0,1000,0.02],[1,1000,0]],"ltp":2.66,"tv":656.02,"id":7287690},{"batb":[[1,1.54,136.75]],"batl":[[0,2.04,383.01],[1,3,42.01],[2,1000,0.02]],"ltp":1.67,"tv":3161.27,"id":7414058}]}]}
{"op":"mcm","clk":"1006286566","pt":1580647467311,"mc":[{"id":"1.168224552","rc":[{"batb":[[0,1.59,225.87],[1,1.58,212.12],[2,1.56,2.7]],"batl":[[0,1.64,340.69],[1,1.65,180],[2,2.04,383.01]],"ltp":1.67,"tv":3161.27,"id":7414058}]}]}
{"op":"mcm","clk":"1006287129","pt":1580647469833,"mc":[{"id":"1.168224552","rc":[{"batb":[[0,1.56,2.7],[1,1.54,136.75],[2,1.38,448.46]],"batl":[[0,2.04,383.01],[1,3,42.01],[2,1000,0.02]],"ltp":1.67,"tv":3161.27,"id":7414058}]}]}
{"op":"mcm","clk":"1006287699","pt":1580647472716,"mc":[{"id":"1.168224552","rc":[{"batb":[[1,1.55,336.48],[2,1.54,371.32]],"batl":[[0,1.68,294.57],[1,1.7,326.94],[2,2.04,383.01]],"ltp":1.67,"tv":3161.27,"id":7414058}]}]}
{"op":"mcm","clk":"1006288382","pt":1580647476067,"mc":[{"id":"1.168224552","rc":[{"batl":[[0,2.04,383.01],[1,3,42.01],[2,1000,0.02]],"ltp":1.67,"tv":3161.27,"id":7414058}]}]}
{"op":"mcm","clk":"1006288830","pt":1580647478330,"mc":[{"id":"1.168224552","rc":[{"batb":[[0,1.55,336.48],[1,1.54,371.32],[2,1.38,448.46]],"ltp":1.67,"tv":3161.27,"id":7414058}]}]}
{"op":"mcm","clk":"1006289035","pt":1580647479450,"mc":[{"id":"1.168224552","rc":[{"batb":[[0,2.7,80.68],[1,2.58,2.56],[2,2.46,67.12]],"batl":[[0,2.98,345],[1,1000,0.02]],"ltp":2.66,"tv":656.02,"id":7287690},{"batl":[[0,1.58,542],[1,1.6,441.42],[2,1.61,196.51]],"ltp":1.67,"tv":3161.27,"id":7414058}]}]}
{"op":"mcm","clk":"1006289225","pt":1580647480321,"mc":[{"id":"1.168224552","rc":[{"batb":[[0,2.7,133.16],[1,2.58,61.97],[2,1.8,75.72]],"ltp":2.66,"tv":656.02,"id":7287690},{"batb":[[2,1.52,144.77]],"ltp":1.67,"tv":3161.27,"id":7414058}]}]}
{"op":"mcm","clk":"1006289436","pt":1580647481434,"mc":[{"id":"1.168224552","rc":[{"batb":[[2,2.56,26.89]],"batl":[[0,2.96,21],[1,2.98,345],[2,1000,0.02]],"ltp":2.66,"tv":656.02,"id":7287690},{"batb":[[2,1.52,225.43]],"ltp":1.67,"tv":3161.27,"id":7414058}]}]}
{"op":"mcm","clk":"1006290225","pt":1580647485455,"mc":[{"id":"1.168224552","rc":[{"batb":[[2,1.52,719.47]],"batl":[[2,1.61,677.1]],"ltp":1.67,"tv":3161.27,"id":7414058}]}]}
{"op":"mcm","clk":"1006291457","pt":1580647492082,"mc":[{"id":"1.168224552","rc":[{"batb":[[0,2.58,61.97],[1,2.56,26.89],[2,1.8,75.72]],"batl":[[1,1000,0.02],[2,1000,0]],"ltp":2.66,"tv":656.02,"id":7287690},{"batb":[[0,1.52,719.47],[1,1.5,510.84],[2,1.38,448.46]],"batl":[[0,1.61,480.59],[1,1.63,497.4],[2,1.64,42.01]],"ltp":1.67,"tv":3161.27,"id":7414058}]}]}
{"op":"mcm","clk":"1006291755","pt":1580647493670,"mc":[{"id":"1.168224552","rc":[{"batb":[[1,1.8,75.72],[2,1.7,75.72]],"batl":[[0,1000,0.02],[1,1000,0]],"ltp":2.66,"tv":656.02,"id":7287690},{"batb":[[0,1.52,638.81]],"batl":[[2,2.04,383.01]],"ltp":1.67,"tv":3161.27,"id":7414058}]}]}
{"op":"mcm","clk":"1006292163","pt":1580647495796,"mc":[{"id":"1.168224552","rc":[{"batb":[[0,1.54,195.48],[1,1.53,239.89],[2,1.52,638.81]],"batl":[[1,1.63,755.15],[2,1.64,184.2]],"ltp":1.67,"tv":3161.27,"id":7414058}]}]}
{"op":"mcm","clk":"1006293728","pt":1580647503462,"mc":[{"id":"1.168224552","rc":[{"batb":[[0,1.52,638.81],[1,1.5,510.84],[2,1.38,448.46]],"ltp":1.67,"tv":3161.27,"id":7414058}]}]}
{"op":"mcm","clk":"1006293937","pt":1580647504382,"mc":[{"id":"1.168224552","rc":[{"batb":[[0,2.58,59.4]],"ltp":2.66,"tv":656.02,"id":7287690},{"batl":[[0,1.63,257.75],[1,1.64,184.2],[2,2.04,383.01]],"ltp":1.67,"tv":3161.27,"id":7414058}]}]}
{"op":"mcm","clk":"1006294335","pt":1580647506382,"mc":[{"id":"1.168224552","rc":[{"batl":[[0,2.68,74.49],[1,2.82,336],[2,1000,0.02]],"ltp":2.66,"tv":656.02,"id":7287690},{"batb":[[0,1.58,333.49],[1,1.57,217.74],[2,1.55,132.13]],"batl":[[0,1.63,821.75]],"ltp":1.67,"tv":3161.27,"id":7414058}]}]}
{"op":"mcm","clk":"1006294526","pt":1580647507412,"mc":[{"id":"1.168224552","rc":[{"batb":[[1,2.5,27.73],[2,2.44,68.93]],"batl":[[2,2.84,22.69]],"ltp":2.66,"tv":656.02,"id":7287690},{"batb":[[0,1.58,457.02],[2,1.55,341.82]],"batl":[[2,1.68,42.01]],"ltp":1.67,"tv":3161.27,"id":7414058}]}]}
{"op":"mcm","clk":"1006294575","pt":1580647507582,"mc":[{"id":"1.168224552","rc":[{"batb":[[0,1.58,459.56]],"ltp":1.67,"tv":3161.27,"id":7414058}]}]}
{"op":"mcm","clk":"1006296653","pt":1580647518418,"mc":[{"id":"1.168224552","rc":[{"batl":[[1,2.84,22.69],[2,1000,0.02]],"ltp":2.66,"tv":656.02,"id":7287690},{"batl":[[0,1.63,257.75]],"ltp":1.67,"tv":3161.27,"id":7414058}]}]}
{"op":"mcm","clk":"1006296748","pt":1580647519003,"mc":[{"id":"1.168224552","rc":[{"batb":[[0,2.5,27.73],[1,2.44,68.93],[2,1.8,75.72]],"batl":[[0,2.84,22.69],[1,1000,0.02],[2,1000,0]],"ltp":2.66,"tv":656.02,"id":7287690},{"batb":[[0,1.58,2.54],[1,1.55,209.69],[2,1.38,448.46]],"batl":[[0,1.68,42.01],[1,2.04,383.01],[2,3,42.01]],"ltp":1.67,"tv":3161.27,"id":7414058}]}]}
{"op":"mcm","clk":"1006296899","pt":1580647519692,"mc":[{"id":"1.168224552","rc":[{"batb":[[0,2.44,68.93],[1,1.8,75.72],[2,1.7,75.72]],"batl":[[0,1000,0.02],[1,1000,0]],"ltp":2.66,"tv":656.02,"id":7287690},{"batb":[[1,1.55,134.07]],"batl":[[0,2.04,383.01],[1,3,42.01],[2,1000,0.02]],"ltp":1.67,"tv":3161.27,"id":7414058}]}]}
{"op":"mcm","clk":"1006297285","pt":1580647521681,"mc":[{"id":"1.168224552","rc":[{"batb":[[1,1.56,221.08],[2,1.55,362.26]],"batl":[[0,1.68,245.5],[1,1.7,327.22],[2,2.04,383.01]],"ltp":1.67,"tv":3161.27,"id":7414058}]}]}
{"op":"mcm","clk":"1006298382","pt":1580647527332,"mc":[{"id":"1.168224552","rc":[{"batb":[[1,1.55,134.07],[2,1.38,448.46]],"ltp":1.67,"tv":3161.27,"id":7414058}]}]}
{"op":"mcm","clk":"1006298580","pt":1580647528317,"mc":[{"id":"1.168224552","rc":[{"trd":[[1.58,273.04]],"batb":[[0,1.58,2.29],[2,1.25,378.63]],"ltp":1.58,"tv":3161.76,"id":7414058}],"tv":3817.79}]}
{"op":"mcm","clk":"1006298979","pt":1580647530390,"mc":[{"id":"1.168224552","rc":[{"batl":[[0,2.56,106.54],[1,2.64,307],[2,1000,0.02]],"ltp":2.66,"tv":656.02,"id":7287690},{"batb":[[0,1.63,251.85],[1,1.62,312.51],[2,1.58,194.35]],"batl":[[1,1.7,980.22]],"ltp":1.58,"tv":3161.76,"id":7414058}]}]}
{"op":"mcm","clk":"1006299094","pt":1580647531136,"mc":[{"id":"1.168224552","rc":[{"batb":[[1,2.38,30.25],[2,2.24,86.47]],"batl":[[2,2.7,24.37]],"ltp":2.66,"tv":656.02,"id":7287690},{"batb":[[0,1.64,108.5],[1,1.63,251.85],[2,1.62,312.51]],"batl":[[2,1.74,42.01]],"ltp":1.58,"tv":3161.76,"id":7414058}]}]}
{"op":"mcm","clk":"1006299259","pt":1580647532097,"mc":[{"id":"1.168224552","rc":[{"batb":[[1,2.42,2.67],[2,2.38,30.25]],"ltp":2.66,"tv":656.02,"id":7287690}]}]}
{"op":"mcm","clk":"1006300079","pt":1580647536713,"mc":[{"id":"1.168224552","rc":[{"batl":[[0,1.67,250.8],[1,1.68,245.5],[2,1.7,980.22]],"ltp":1.58,"tv":3161.76,"id":7414058}]}]}
{"op":"mcm","clk":"1006301070","pt":1580647542227,"mc":[{"id":"1.168224552","rc":[{"batb":[[0,2.42,2.67],[1,2.38,30.25],[2,2.24,86.47]],"batl":[[0,2.7,24.37],[1,1000,0.02],[2,2.7,0]],"ltp":2.66,"tv":656.02,"id":7287690},{"batb":[[0,1.6,563.77],[1,1.58,634.68],[2,1.44,436.19]],"batl":[[1,1.71,480.59],[2,1.73,497.4]],"ltp":1.58,"tv":3161.76,"id":7414058}]}]}
{"op":"mcm","clk":"1006301350","pt":1580647543724,"mc":[{"id":"1.168224552","rc":[{"batb":[[1,2.24,86.47],[2,1.8,75.72]],"batl":[[0,1000,0.02],[1,1000,0]],"ltp":2.66,"tv":656.02,"id":7287690},{"batb":[[0,1.6,494.03]],"ltp":1.58,"tv":3161.76,"id":7414058}]}]}
{"op":"mcm","clk":"1006302217","pt":1580647548254,"mc":[{"id":"1.168224552","rc":[{"batb":[[0,1.65,209.84],[1,1.64,184.85],[2,1.6,494.03]],"batl":[[1,1.7,254.13],[2,1.71,480.59]],"ltp":1.58,"tv":3161.76,"id":7414058}]}]}
{"op":"mcm","clk":"1006302937","pt":1580647552151,"mc":[{"id":"1.168224552","rc":[{"batb":[[0,1.6,494.03],[1,1.58,634.68],[2,1.44,436.19]],"batl":[[1,1.71,480.59],[2,1.73,497.4]],"ltp":1.58,"tv":3161.76,"id":7414058}]}]}
{"op":"mcm","clk":"1006303492","pt":1580647555160,"mc":[{"id":"1.168224552","rc":[{"batb":[[1,1.58,888.63],[2,1.57,217.4]],"ltp":1.58,"tv":3161.76,"id":7414058}]}]}
{"op":"mcm","clk":"1006304143","pt":1580647559146,"mc":[{"id":"1.168224552","rc":[{"batb":[[0,2.24,86.47],[1,1.8,75.72],[2,1.7,75.72]],"ltp":2.66,"tv":656.02,"id":7287690}]}]}
{"op":"mcm","clk":"1006304848","pt":1580647563363,"mc":[{"id":"1.168224552","rc":[{"batb":[[1,1.58,634.68],[2,1.44,436.19]],"batl":[[1,1.78,216.25],[2,1.8,270.82]],"ltp":1.58,"tv":3161.76,"id":7414058}]}]}
{"op":"mcm","clk":"1006304932","pt":1580647563850,"mc":[{"id":"1.168224552","rc":[{"trd":[[2.48,2]],"ltp":2.48,"tv":658.02,"id":7287690},{"trd":[[1.67,590.75]],"batl":[[0,1.78,216.25],[1,1.8,270.82],[2,2.04,383.01]],"ltp":1.67,"tv":3164.72,"id":7414058}],"tv":3822.75}]}
{"op":"mcm","clk":"1006305045","pt":1580647564543,"mc":[{"id":"1.168224552","rc":[{"batb":[[2,1.25,378.63]],"batl":[[2,3,42.01]],"ltp":1.67,"tv":3164.72,"id":7414058}]}]}
{"op":"mcm","clk":"1006305340","pt":1580647566242,"mc":[{"id":"1.168224552","rc":[{"batb":[[1,1.7,75.72],[2,1.6,75.72]],"batl":[[0,2.42,417],[1,1000,0.02]],"ltp":2.48,"tv":658.02,"id":7287690},{"batb":[[0,1.74,259.84],[1,1.72,295.97],[2,1.71,202.87]],"batl":[[2,1.81,545]],"ltp":1.67,"tv":3164.72,"id":7414058}]}]}
{"op":"mcm","clk":"1006305545","pt":1580647567360,"mc":[{"id":"1.168224552","rc":[{"batb":[[0,2.26,2.6],[1,2.24,86.47],[2,2.22,33.61]],"batl":[[1,2.5,27.73],[2,1000,0.02]],"ltp":2.48,"tv":658.02,"id":7287690},{"batb":[[0,1.74,348.28]],"ltp":1.67,"tv":3164.72,"id":7414058}]}]}
{"op":"mcm","clk":"1006305853","pt":1580647569188,"mc":[{"id":"1.168224552","rc":[{"trd":[[1.74,3.36]],"batb":[[0,1.74,346.6]],"ltp":1.74,"tv":3168.08,"id":7414058}],"tv":3826.11}]}
{"op":"mcm","clk":"1006306377","pt":1580647574218,"mc":[{"id":"1.168224552","rc":[{"batl":[[0,1.77,218.23],[1,1.78,216.25],[2,1.8,270.82]],"ltp":1.74,"tv":3168.08,"id":7414058}]}]}
{"op":"mcm","clk":"1006307145","pt":1580647577051,"mc":[{"id":"1.168224552","rc":[{"trd":[[1.74,57.4]],"batb":[[0,1.74,319.58]],"ltp":1.74,"tv":3222.13,"id":7414058}],"tv":3880.15}]}
{"op":"mcm","clk":"1006307508","pt":1580647579461,"mc":[{"id":"1.168224552","rc":[{"batl":[[0,2.5,27.73],[1,1000,0.02],[2,1000,0]],"ltp":2.48,"tv":658.02,"id":7287690},{"batb":[[0,1.74,88.44],[1,1.7,494.03],[2,1.68,510.84]],"batl":[[1,1.81,480.59],[2,1.82,42.01]],"ltp":1.74,"tv":3222.13,"id":7414058}]}]}
{"op":"mcm","clk":"1006307551","pt":1580647579784,"mc":[{"id":"1.168224552","rc":[{"batb":[[1,2.02,116.69],[2,1.7,75.72]],"batl":[[0,1000,0.02],[1,1000,0]],"ltp":2.48,"tv":658.02,"id":7287690},{"batb":[[0,1.7,494.03],[1,1.68,510.84],[2,1.66,104.73]],"batl":[[2,1.83,497.4]],"ltp":1.74,"tv":3222.13,"id":7414058}]}]}
{"op":"mcm","clk":"1006308079","pt":1580647582880,"mc":[{"id":"1.168224552","rc":[{"trd":[[2.28,88.22]],"ltp":2.28,"tv":746.24,"id":7287690},{"trd":[[1.77,113.64]],"batl":[[0,1.77,104.6]],"ltp":1.77,"tv":3335.76,"id":7414058}],"tv":4082.01}]}
{"op":"mcm","clk":"1006308486","pt":1580647585489,"mc":[{"id":"1.168224552","rc":[{"batb":[[0,1.75,284.78],[1,1.73,305],[2,1.7,494.03]],"batl":[[1,1.81,666.06],[2,1.83,754.31]],"ltp":1.77,"tv":3335.76,"id":7414058}]}]}
{"op":"mcm","clk":"1006308961","pt":1580647588257,"mc":[{"id":"1.168224552","rc":[{"batb":[[0,1.7,494.03],[1,1.68,510.84],[2,1.66,104.73]],"batl":[[1,1.81,480.59],[2,1.83,497.4]],"ltp":1.77,"tv":3335.76,"id":7414058}]}]}
{"op":"mcm","clk":"1006309221","pt":1580647589965,"mc":[{"id":"1.168224552","rc":[{"batl":[[0,1.74,189.31],[1,1.77,104.6],[2,1.81,480.59]],"ltp":1.77,"tv":3335.76,"id":7414058}]}]}
{"op":"mcm","clk":"1006309665","pt":1580647592586,"mc":[{"id":"1.168224552","rc":[{"batb":[[0,1.66,104.73],[1,1.64,243.92],[2,1.63,189.1]],"ltp":1.77,"tv":3335.76,"id":7414058}]}]}
{"op":"mcm","clk":"1006309889","pt":1580647593986,"mc":[{"id":"1.168224552","rc":[{"batb":[[0,2.02,116.69],[1,1.7,75.72],[2,1.6,75.72]],"ltp":2.28,"tv":746.24,"id":7287690}]}]}
{"op":"mcm","clk":"1006310059","pt":1580647595089,"mc":[{"id":"1.168224552","rc":[{"batl":[[0,2.6,352],[1,1000,0.02]],"ltp":2.28,"tv":746.24,"id":7287690},{"batl":[[0,1.67,256.42],[1,1.69,237.01],[2,1.71,442.63]],"ltp":1.77,"tv":3335.76,"id":7414058}]}]}
{"op":"mcm","clk":"1006310253","pt":1580647596215,"mc":[{"id":"1.168224552","rc":[{"batb":[[0,2.4,71.68],[1,2.22,88.44],[2,1.7,75.72]],"ltp":2.28,"tv":746.24,"id":7287690}]}]}
{"op":"mcm","clk":"1006310506","pt":1580647597476,"mc":[{"id":"1.168224552","rc":[{"batb":[[1,2.36,2.6],[2,2.32,31.09]],"batl":[[1,2.66,25.21],[2,1000,0.02]],"ltp":2.28,"tv":746.24,"id":7287690}]}]}
{"op":"mcm","clk":"1006311486","pt":1580647603611,"mc":[{"id":"1.168224552","rc":[{"trd":[[1.66,210.96]],"batb":[[0,1.64,243.92],[1,1.63,189.1],[2,1.61,68.06]],"batl":[[0,1.66,22.58],[1,1.67,256.42],[2,1.69,237.01]],"ltp":1.66,"tv":3545.21,"id":7414058}],"tv":4291.46}]}
{"op":"mcm","clk":"1006312069","pt":1580647607399,"mc":[{"id":"1.168224552","rc":[{"batl":[[0,1.66,42.58]],"ltp":1.66,"tv":3545.21,"id":7414058}]}]}
{"op":"mcm","clk":"1006312668","pt":1580647611222,"mc":[{"id":"1.168224552","rc":[{"batb":[[0,2.36,2.6],[1,2.32,31.09],[2,2.22,88.44]],"batl":[[0,2.66,25.21],[1,1000,0.02],[2,1000,0]],"ltp":2.28,"tv":746.24,"id":7287690},{"batb":[[0,1.61,68.06],[1,1.6,119.52],[2,1.52,425.49]],"batl":[[1,1.74,42.01],[2,1.75,3.54]],"ltp":1.66,"tv":3545.21,"id":7414058}]}]}
{"op":"mcm","clk":"1006312765","pt":1580647611817,"mc":[{"id":"1.168224552","rc":[{"batb":[[1,2.22,88.44],[2,1.7,75.72]],"batl":[[0,1000,0.02],[1,1000,0]],"ltp":2.28,"tv":746.24,"id":7287690},{"batb":[[0,1.6,119.52],[1,1.52,425.49],[2,1.3,113.59]],"batl":[[1,1.75,3.54],[2,2.22,329.01]],"ltp":1.66,"tv":3545.21,"id":7414058}]}]}
{"op":"mcm","clk":"1006313112","pt":1580647614212,"mc":[{"id":"1.168224552","rc":[{"batb":[[1,2.24,86.47],[2,2.22,88.44]],"ltp":2.28,"tv":746.24,"id":7287690},{"batb":[[1,1.59,339.64],[2,1.58,212.09]],"batl":[[2,1.79,185.82]],"ltp":1.66,"tv":3545.21,"id":7414058}]}]}
{"op":"mcm","clk":"1006313164","pt":1580647614533,"mc":[{"id":"1.168224552","rc":[{"batb":[[2,1.7,75.72]],"ltp":2.28,"tv":746.24,"id":7287690},{"batb":[[0,1.59,339.64],[1,1.58,212.09],[2,1.52,425.49]],"ltp":1.66,"tv":3545.21,"id":7414058}]}]}
{"op":"mcm","clk":"1006313499","pt":1580647616493,"mc":[{"id":"1.168224552","rc":[{"batb":[[2,1.55,152.76]],"ltp":1.66,"tv":3545.21,"id":7414058}]}]}
{"op":"mcm","clk":"1006313747","pt":1580647618099,"mc":[{"id":"1.168224552","rc":[{"batl":[[2,2.22,329.01]],"ltp":1.66,"tv":3545.21,"id":7414058}]}]}
{"op":"mcm","clk":"1006314038","pt":1580647619925,"mc":[{"id":"1.168224552","rc":[{"batb":[[2,1.3,113.59]],"batl":[[2,3,42.01]],"ltp":1.66,"tv":3545.21,"id":7414058}]}]}
{"op":"mcm","clk":"1006314224","pt":1580647621037,"mc":[{"id":"1.168224552","rc":[{"batl":[[0,2.74,321],[1,1000,0.02]],"ltp":2.28,"tv":746.24,"id":7287690},{"batl":[[0,1.64,473.87],[1,1.65,311.31],[2,1.66,666.58]],"ltp":1.66,"tv":3545.21,"id":7414058}]}]}
{"op":"mcm","clk":"1006314485","pt":1580647623167,"mc":[{"id":"1.168224552","rc":[{"batb":[[0,2.56,60.35],[1,2.44,28.57],[2,2.42,69.71]],"batl":[[1,2.8,22.69],[2,1000,0.02]],"ltp":2.28,"tv":746.24,"id":7287690},{"batb":[[2,1.56,74.78]],"batl":[[2,1.66,646.58]],"ltp":1.66,"tv":3545.21,"id":7414058}]}]}
{"op":"mcm","clk":"1006314912","pt":1580647625032,"mc":[{"id":"1.168224552","rc":[{"trd":[[1.59,291.96]],"batb":[[0,1.59,319.64]],"ltp":1.59,"tv":3585.21,"id":7414058}],"tv":4331.46}]}
{"op":"mcm","clk":"1006315101","pt":1580647626030,"mc":[{"id":"1.168224552","rc":[{"batb":[[0,1.6,112.02],[1,1.59,319.64],[2,1.58,212.09]],"ltp":1.59,"tv":3585.21,"id":7414058}]}]}
{"op":"mcm","clk":"1006316276","pt":1580647632970,"mc":[{"id":"1.168224552","rc":[{"trd":[[1.6,572.77]],"batb":[[0,1.6,74.16]],"ltp":1.6,"tv":3660.93,"id":7414058}],"tv":4407.18}]}
{"op":"mcm","clk":"1006317516","pt":1580647640348,"mc":[{"id":"1.168224552","rc":[{"batb":[[0,2.44,28.57],[1,2.42,69.71],[2,1.8,75.72]],"batl":[[0,2.8,22.69],[1,1000,0.02],[2,1000,0]],"ltp":2.28,"tv":746.24,"id":7287690},{"batb":[[1,1.56,74.78],[2,1.51,148.16]],"batl":[[0,1.66,22.58],[1,1.68,42.01],[2,1.75,3.54]],"ltp":1.6,"tv":3660.93,"id":7414058}]}]}
{"op":"mcm","clk":"1006317760","pt":1580647641862,"mc":[{"id":"1.168224552","rc":[{"batb":[[0,2.42,69.71],[1,1.8,75.72],[2,1.7,75.72]],"batl":[[0,1000,0.02],[1,1000,0]],"ltp":2.28,"tv":746.24,"id":7287690},{"batb":[[1,1.51,148.16],[2,1.4,451.01]],"batl":[[1,1.75,3.54],[2,2.1,363.31]],"ltp":1.6,"tv":3660.93,"id":7414058}]}]}
{"op":"mcm","clk":"1006317965","pt":1580647643174,"mc":[{"id":"1.168224552","rc":[{"batb":[[1,1.51,515.83],[2,1.5,260.81]],"batl":[[1,1.69,231.4],[2,1.71,320.83]],"ltp":1.6,"tv":3660.93,"id":7414058}]}]}
{"op":"mcm","clk":"1006318108","pt":1580647644172,"mc":[{"id":"1.168224552","rc":[{"batl":[[0,2.56,126.48],[1,1000,0.02]],"ltp":2.28,"tv":746.24,"id":7287690},{"batb":[[1,1.51,148.16],[2,1.4,451.01]],"batl":[[1,1.75,3.54],[2,2.1,363.31]],"ltp":1.6,"tv":3660.93,"id":7414058}]}]}
{"op":"mcm","clk":"1006318198","pt":1580647644760,"mc":[{"id":"1.168224552","rc":[{"batl":[[0,1000,0.02],[1,1000,0]],"ltp":2.28,"tv":746.24,"id":7287690}]}]}
{"op":"mcm","clk":"1006318628","pt":1580647647459,"mc":[{"id":"1.168224552","rc":[{"trd":[[2.6,48.46]],"ltp":2.6,"tv":794.71,"id":7287690},{"trd":[[1.62,88.35]],"batb":[[0,1.57,309.55],[1,1.56,223.08],[2,1.51,148.16]],"batl":[[0,1.62,223.21],[1,1.63,188.14],[2,1.66,22.58]],"ltp":1.62,"tv":3738.71,"id":7414058}],"tv":4533.42}]}
{"op":"mcm","clk":"1006318877","pt":1580647648976,"mc":[{"id":"1.168224552","rc":[{"batb":[[0,1.51,148.16],[1,1.4,451.01],[2,1.25,378.62]],"batl":[[0,1.66,22.58],[1,1.75,3.54],[2,2.1,363.31]],"ltp":1.62,"tv":3738.71,"id":7414058}]}]}
{"op":"mcm","clk":"1006319217","pt":1580647651163,"mc":[{"id":"1.168224552","rc":[{"batb":[[0,1.59,71.2],[1,1.57,31.15],[2,1.51,148.16]],"batl":[[0,1.62,47.66],[1,1.66,22.58],[2,1.75,3.54]],"ltp":1.62,"tv":3738.71,"id":7414058}]}]}
{"op":"mcm","clk":"1006319363","pt":1580647651970,"mc":[{"id":"1.168224552","rc":[{"batb":[[1,1.51,547.77],[2,1.5,260.84]],"batl":[[0,1.66,22.58],[1,1.69,202.02],[2,1.71,320.83]],"ltp":1.62,"tv":3738.71,"id":7414058}]}]}
{"op":"mcm","clk":"1006319828","pt":1580647655160,"mc":[{"id":"1.168224552","rc":[{"batl":[[1,1.75,3.54],[2,2.1,363.31]],"ltp":1.62,"tv":3738.71,"id":7414058}]}]}
{"op":"mcm","clk":"1006319944","pt":1580647655862,"mc":[{"id":"1.168224552","rc":[{"batb":[[0,1.51,547.77],[1,1.5,260.84],[2,1.4,451.01]],"ltp":1.62,"tv":3738.71,"id":7414058}]}]}
{"op":"mcm","clk":"1006320155","pt":1580647657146,"mc":[{"id":"1.168224552","rc":[{"batb":[[2,1.25,378.63]],"batl":[[2,3,42.01]],"ltp":1.62,"tv":3738.71,"id":7414058}]}]}
{"op":"mcm","clk":"1006320302","pt":1580647658064,"mc":[{"id":"1.168224552","rc":[{"batb":[[0,2.72,78.15],[1,2.42,69.71],[2,1.8,75.72]],"batl":[[0,3.05,382],[1,1000,0.02]],"ltp":2.6,"tv":794.71,"id":7287690},{"batl":[[0,1.56,484.96],[1,1.57,932.31],[2,1.66,22.58]],"ltp":1.62,"tv":3738.71,"id":7414058}]}]}
{"op":"mcm","clk":"1006320501","pt":1580647659283,"mc":[{"id":"1.168224552","rc":[{"batb":[[0,2.8,47.84],[1,2.72,78.15],[2,2.64,25.21]],"batl":[[0,3.05,402.16]],"ltp":2.6,"tv":794.71,"id":7287690},{"batb":[[2,1.49,85.7]],"batl":[[2,1.6,42.01]],"ltp":1.62,"tv":3738.71,"id":7414058}]}]}
{"op":"mcm","clk":"1006320582","pt":1580647659763,"mc":[{"id":"1.168224552","rc":[{"batb":[[1,2.78,2.56],[2,2.72,78.15]],"ltp":2.6,"tv":794.71,"id":7287690}]}]}
{"op":"mcm","clk":"1006320815","pt":1580647661286,"mc":[{"id":"1.168224552","rc":[{"batb":[[0,1.52,80.78],[1,1.51,547.77],[2,1.5,260.84]],"ltp":1.62,"tv":3738.71,"id":7414058}]}]}
{"op":"mcm","clk":"1006321133","pt":1580647663275,"mc":[{"id":"1.168224552","rc":[{"trd":[[1.56,101.63]],"batl":[[0,1.56,483.09],[2,1.6,109.23]],"ltp":1.56,"tv":3742.45,"id":7414058}],"tv":4537.17}]}
{"op":"mcm","clk":"1006321340","pt":1580647664581,"mc":[{"id":"1.168224552","rc":[{"batb":[[2,1.5,754.87]],"batl":[[2,1.59,480.59]],"ltp":1.56,"tv":3742.45,"id":7414058}]}]}
{"op":"mcm","clk":"1006321758","pt":1580647667474,"mc":[{"id":"1.168224552","rc":[{"batb":[[0,1.51,547.77],[1,1.5,754.87],[2,1.49,85.7]],"ltp":1.56,"tv":3742.45,"id":7414058}]}]}
{"op":"mcm","clk":"1006322359","pt":1580647671090,"mc":[{"id":"1.168224552","rc":[{"batb":[[0,1.52,403.93],[1,1.51,547.77],[2,1.5,754.87]],"ltp":1.56,"tv":3742.45,"id":7414058}]}]}
{"op":"mcm","clk":"1006323004","pt":1580647675298,"mc":[{"id":"1.168224552","rc":[{"batl":[[0,3.05,20.16]],"ltp":2.6,"tv":794.71,"id":7287690},{"batb":[[1,1.51,148.16],[2,1.5,494.03]],"batl":[[0,1.56,127.75],[1,1.59,480.59],[2,1.6,42.01]],"ltp":1.56,"tv":3742.45,"id":7414058}]}]}
{"op":"mcm","clk":"1006323089","pt":1580647675892,"mc":[{"id":"1.168224552","rc":[{"batb":[[0,2.78,2.56],[1,2.62,57.52],[2,1.8,75.72]],"batl":[[0,1000,0.02],[1,1000,0]],"ltp":2.6,"tv":794.71,"id":7287690},{"batb":[[1,1.5,494.03],[2,1.48,510.85]],"batl":[[0,1.59,480.59],[1,1.61,497.4],[2,1.66,22.58]],"ltp":1.56,"tv":3742.45,"id":7414058}]}]}
{"op":"mcm","clk":"1006323643","pt":1580647679419,"mc":[{"id":"1.168224552","rc":[{"batl":[[2,1.62,274.65]],"ltp":1.56,"tv":3742.45,"id":7414058}]}]}
{"op":"mcm","clk":"1006324077","pt":1580647682324,"mc":[{"id":"1.168224552","rc":[{"batb":[[0,1.52,404.18]],"ltp":1.56,"tv":3742.45,"id":7414058}]}]}
{"op":"mcm","clk":"1006324875","pt":1580647687328,"mc":[{"id":"1.168224552","rc":[{"batb":[[0,2.62,57.52],[1,1.8,75.72],[2,1.7,75.72]],"ltp":2.6,"tv":794.71,"id":7287690}]}]}
{"op":"mcm","clk":"1006325158","pt":1580647689023,"mc":[{"id":"1.168224552","rc":[{"trd":[[1.52,26.65],[1.56,102.13]],"batb":[[0,1.52,403.5],[1,1.43,630.1],[2,1.42,329.69]],"batl":[[2,1.66,22.58]],"ltp":1.52,"tv":3743.8,"id":7414058}],"tv":4538.51}]}
{"op":"mcm","clk":"1006325285","pt":1580647689943,"mc":[{"id":"1.168224552","rc":[{"batb":[[0,1.43,630.1],[1,1.42,329.69],[2,1.34,465.43]],"ltp":1.52,"tv":3743.8,"id":7414058}]}]}
{"op":"mcm","clk":"1006325466","pt":1580647691122,"mc":[{"id":"1.168224552","rc":[{"batb":[[2,1.25,378.62]],"ltp":1.52,"tv":3743.8,"id":7414058}]}]}
{"op":"mcm","clk":"1006325655","pt":1580647692444,"mc":[{"id":"1.168224552","rc":[{"batb":[[0,3.2,234.37],[1,2.62,57.52],[2,1.8,75.72]],"batl":[[0,3.45,261],[1,1000,0.02]],"ltp":2.6,"tv":794.71,"id":7287690},{"trd":[[1.48,0.02]],"batb":[[0,1.43,630.09],[2,1.2,284.06]],"batl":[[0,1.47,952.77],[1,1.48,524.71],[2,1.59,480.59]],"ltp":1.48,"tv":3743.82,"id":7414058}],"tv":4538.53}]}
{"op":"mcm","clk":"1006325821","pt":1580647693418,"mc":[{"id":"1.168224552","rc":[{"batb":[[1,3.1,91.59],[2,3,2.63]],"ltp":2.6,"tv":794.71,"id":7287690},{"batb":[[0,1.44,2.68],[1,1.43,630.09],[2,1.42,329.69]],"batl":[[2,1.51,300.11]],"ltp":1.48,"tv":3743.82,"id":7414058}]}]}
{"op":"mcm","clk":"1006325987","pt":1580647694435,"mc":[{"id":"1.168224552","rc":[{"batl":[[0,3.4,16.8],[1,3.45,261],[2,1000,0.02]],"ltp":2.6,"tv":794.71,"id":7287690},{"batl":[[2,1.51,262.25]],"ltp":1.48,"tv":3743.82,"id":7414058}]}]}
{"op":"mcm","clk":"1006326135","pt":1580647695256,"mc":[{"id":"1.168224552","rc":[{"batl":[[2,1.52,42.01]],"ltp":1.48,"tv":3743.82,"id":7414058}]}]}
{"op":"mcm","clk":"1006326217","pt":1580647695820,"mc":[{"id":"1.168224552","rc":[{"batb":[[0,1.45,20.53],[1,1.44,2.68],[2,1.43,630.09]],"ltp":1.48,"tv":3743.82,"id":7414058}]}]}
{"op":"mcm","clk":"1006326587","pt":1580647698140,"mc":[{"id":"1.168224552","rc":[{"batl":[[2,1.49,480.59]],"ltp":1.48,"tv":3743.82,"id":7414058}]}]}
{"op":"mcm","clk":"1006327181","pt":1580647702028,"mc":[{"id":"1.168224552","rc":[{"trd":[[3.2,12.33]],"batb":[[0,3.2,222.04]],"ltp":3.2,"tv":807.04,"id":7287690},{"trd":[[1.46,27.02]],"ltp":1.46,"tv":3770.84,"id":7414058}],"tv":4577.89}]}
{"op":"mcm","clk":"1006327944","pt":1580647707143,"mc":[{"id":"1.168224552","rc":[{"batl":[[1,1000,0.02],[2,1000,0]],"ltp":3.2,"tv":807.04,"id":7287690},{"batl":[[0,1.47,297.77]],"ltp":1.46,"tv":3770.84,"id":7414058}]}]}
{"op":"mcm","clk":"1006328058","pt":1580647707847,"mc":[{"id":"1.168224552","rc":[{"batb":[[0,3,2.63],[1,2.9,43.9],[2,1.8,75.72]],"batl":[[0,1000,0.02],[1,1000,0]],"ltp":3.2,"tv":807.04,"id":7287690},{"batb":[[2,1.41,494.03]],"batl":[[0,1.49,480.59],[1,1.51,497.4],[2,1.6,1.68]],"ltp":1.46,"tv":3770.84,"id":7414058}]}]}
{"op":"mcm","clk":"1006328610","pt":1580647711434,"mc":[{"id":"1.168224552","rc":[{"batb":[[0,1.46,20],[1,1.45,20.53],[2,1.44,2.68]],"batl":[[2,1.53,310.14]],"ltp":1.46,"tv":3770.84,"id":7414058}]}]}
{"op":"mcm","clk":"1006328728","pt":1580647712367,"mc":[{"id":"1.168224552","rc":[{"trd":[[1.45,68.86],[1.46,67.02]],"batb":[[0,1.44,2.68],[1,1.41,494.03],[2,1.39,510.84]],"batl":[[0,1.45,9.47],[1,1.49,480.59],[2,1.51,497.4]],"ltp":1.45,"tv":3851.91,"id":7414058}],"tv":4658.95}]}
{"op":"mcm","clk":"1006328941","pt":1580647713739,"mc":[{"id":"1.168224552","rc":[{"batb":[[0,2.9,43.9],[1,1.8,75.72],[2,1.7,75.72]],"ltp":3.2,"tv":807.04,"id":7287690},{"batl":[[1,1.6,1.68],[2,1.71,2]],"ltp":1.45,"tv":3851.91,"id":7414058}]}]}
{"op":"mcm","clk":"1006329177","pt":1580647715153,"mc":[{"id":"1.168224552","rc":[{"batl":[[0,1.45,13.92]],"ltp":1.45,"tv":3851.91,"id":7414058}]}]}
{"op":"mcm","clk":"1006329352","pt":1580647716381,"mc":[{"id":"1.168224552","rc":[{"trd":[[3.2,14.35]],"batl":[[0,3,2106.98],[1,3.1,1209.68],[2,3.2,1007.26]],"ltp":3.2,"tv":809.06,"id":7287690},{"trd":[[1.45,92.25]],"batl":[[0,1.53,548]],"ltp":1.45,"tv":3875.3,"id":7414058}],"tv":4684.36}]}
{"op":"mcm","clk":"1006329507","pt":1580647717473,"mc":[{"id":"1.168224552","rc":[{"batb":[[1,2.66,54.84],[2,1.8,75.72]],"batl":[[0,3.1,120.97],[1,3.2,489.95],[2,1000,0.02]],"ltp":3.2,"tv":809.06,"id":7287690},{"batb":[[0,1.49,261.76],[1,1.48,433.78],[2,1.44,2.68]],"batl":[[0,1.53,858.14],[1,1.54,231.89],[2,1.6,1.68]],"ltp":1.45,"tv":3875.3,"id":7414058}]}]}
{"op":"mcm","clk":"1006329634","pt":1580647718250,"mc":[{"id":"1.168224552","rc":[{"batb":[[0,1.5,72.26],[1,1.49,261.76],[2,1.48,433.78]],"ltp":1.45,"tv":3875.3,"id":7414058}]}]}
{"op":"mcm","clk":"1006329729","pt":1580647718875,"mc":[{"id":"1.168224552","rc":[{"batb":[[1,2.78,23.53],[2,2.66,54.84]],"ltp":3.2,"tv":809.06,"id":7287690},{"batb":[[0,1.49,261.76],[1,1.48,433.78],[2,1.44,2.68]],"ltp":1.45,"tv":3875.3,"id":7414058}]}]}
{"op":"mcm","clk":"1006329957","pt":1580647720363,"mc":[{"id":"1.168224552","rc":[{"batl":[[1,3.2,508.43]],"ltp":3.2,"tv":809.06,"id":7287690},{"batb":[[2,1.46,90.74]],"batl":[[2,1.57,42.01]],"ltp":1.45,"tv":3875.3,"id":7414058}]}]}
{"op":"mcm","clk":"1006330965","pt":1580647726883,"mc":[{"id":"1.168224552","rc":[{"batl":[[0,1.52,69.48],[1,1.53,858.14],[2,1.54,231.89]],"ltp":1.45,"tv":3875.3,"id":7414058}]}]}
{"op":"mcm","clk":"1006331340","pt":1580647729478,"mc":[{"id":"1.168224552","rc":[{"trd":[[1.52,60.26]],"batl":[[0,1.52,52.67]],"ltp":1.52,"tv":3908.91,"id":7414058}],"tv":4717.97}]}
{"op":"mcm","clk":"1006332201","pt":1580647735467,"mc":[{"id":"1.168224552","rc":[{"batb":[[0,2.78,23.53],[1,2.66,54.84],[2,1.8,75.72]],"batl":[[1,3.2,75.43]],"ltp":3.2,"tv":809.06,"id":7287690},{"batb":[[0,1.46,90.74],[1,1.39,208.19],[2,1.34,465.43]],"batl":[[1,1.57,42.01],[2,1.6,1.68]],"ltp":1.52,"tv":3908.91,"id":7414058}]}]}
{"op":"mcm","clk":"1006332252","pt":1580647735885,"mc":[{"id":"1.168224552","rc":[{"batb":[[0,2.66,54.84],[1,1.8,75.72],[2,1.7,75.72]],"batl":[[0,1000,0.02],[1,3.2,0],[2,1000,0]],"ltp":3.2,"tv":809.06,"id":7287690},{"batb":[[0,1.39,208.19],[1,1.34,465.43],[2,1.2,284.06]],"batl":[[1,1.6,1.68],[2,1.71,2]],"ltp":1.52,"tv":3908.91,"id":7414058}]}]}
{"op":"mcm","clk":"1006332624","pt":1580647738407,"mc":[{"id":"1.168224552","rc":[{"batb":[[0,1.39,772.51],[1,1.38,377.04],[2,1.34,465.43]],"batl":[[1,1.6,191.41],[2,1.61,197.05]],"ltp":1.52,"tv":3908.91,"id":7414058}]}]}
{"op":"mcm","clk":"1006332718","pt":1580647738995,"mc":[{"id":"1.168224552","rc":[{"batb":[[0,1.39,208.19],[1,1.34,465.43],[2,1.2,284.06]],"batl":[[1,1.6,1.68],[2,1.71,2]],"ltp":1.52,"tv":3908.91,"id":7414058}]}]}
{"op":"mcm","clk":"1006333218","pt":1580647742591,"mc":[{"id":"1.168224552","rc":[{"batb":[[0,1.47,281.43],[1,1.46,291.01],[2,1.39,208.19]],"batl":[[0,1.51,339.89],[1,1.52,296.4],[2,1.6,1.68]],"ltp":1.52,"tv":3908.91,"id":7414058}]}]}
{"op":"mcm","clk":"1006333468","pt":1580647744179,"mc":[{"id":"1.168224552","rc":[{"batb":[[0,1.39,208.19],[1,1.34,465.43],[2,1.2,284.06]],"batl":[[0,1.52,52.67],[1,1.6,1.68],[2,1.71,2]],"ltp":1.52,"tv":3908.91,"id":7414058}]}]}
{"op":"mcm","clk":"1006333944","pt":1580647747197,"mc":[{"id":"1.168224552","rc":[{"batb":[[0,1.39,772.51],[1,1.38,377.04],[2,1.34,465.43]],"batl":[[1,1.6,191.41],[2,1.61,197.05]],"ltp":1.52,"tv":3908.91,"id":7414058}]}]}
{"op":"mcm","clk":"1006338001","pt":1580647773653,"mc":[{"id":"1.168224552","rc":[{"batb":[[0,1.39,208.19],[1,1.34,465.43],[2,1.2,284.06]],"ltp":1.52,"tv":3908.91,"id":7414058}]}]}
{"op":"mcm","clk":"1006338256","pt":1580647775427,"mc":[{"id":"1.168224552","rc":[{"batb":[[1,1.2,284.06],[2,1.15,378.62]],"batl":[[0,1.6,191.41],[1,1.61,197.05],[2,1.71,2]],"ltp":1.52,"tv":3908.91,"id":7414058}]}]}
{"op":"mcm","clk":"1006338398","pt":1580647776432,"mc":[{"id":"1.168224552","rc":[{"batl":[[0,2.8,118.66],[1,2.88,325],[2,1000,0.02]],"ltp":3.2,"tv":809.06,"id":7287690},{"batb":[[0,1.54,133.21],[1,1.39,208.19],[2,1.2,284.06]],"batl":[[1,1.61,773.05]],"ltp":1.52,"tv":3908.91,"id":7414058}]}]}
{"op":"mcm","clk":"1006338561","pt":1580647777440,"mc":[{"id":"1.168224552","rc":[{"batb":[[1,2.44,68.37],[2,1.8,75.72]],"ltp":3.2,"tv":809.06,"id":7287690},{"batb":[[0,1.56,374.22],[1,1.55,228.29],[2,1.54,133.21]],"batl":[[0,1.6,189.73]],"ltp":1.52,"tv":3908.91,"id":7414058}]}]}
{"op":"mcm","clk":"1006338723","pt":1580647778479,"mc":[{"id":"1.168224552","rc":[{"batb":[[0,2.66,57.4],[1,2.58,26.05],[2,2.44,68.37]],"batl":[[2,2.96,21]],"ltp":3.2,"tv":809.06,"id":7287690},{"batb":[[2,1.54,135.87]],"batl":[[2,1.63,42.01]],"ltp":1.52,"tv":3908.91,"id":7414058}]}]}
{"op":"mcm","clk":"1006339007","pt":1580647780154,"mc":[{"id":"1.168224552","rc":[{"trd":[[1.56,132.53]],"batb":[[0,1.56,359.01]],"ltp":1.56,"tv":3939.31,"id":7414058}],"tv":4748.38}]}
{"op":"mcm","clk":"1006339650","pt":1580647784122,"mc":[{"id":"1.168224552","rc":[{"batb":[[0,1.56,434.02]],"ltp":1.56,"tv":3939.31,"id":7414058}]}]}
{"op":"mcm","clk":"1006340000","pt":1580647786192,"mc":[{"id":"1.168224552","rc":[{"trd":[[1.56,132.69]],"batb":[[0,1.56,433.94]],"ltp":1.56,"tv":3939.47,"id":7414058}],"tv":4748.53}]}
{"op":"mcm","clk":"1006340142","pt":1580647787295,"mc":[{"id":"1.168224552","rc":[{"trd":[[1.56,323.92]],"batb":[[0,1.56,338.32]],"ltp":1.56,"tv":4130.71,"id":7414058}],"tv":4939.77}]}
{"op":"mcm","clk":"1006340195","pt":1580647787713,"mc":[{"id":"1.168224552","rc":[{"batb":[[0,1.56,207.2]],"ltp":1.56,"tv":4130.71,"id":7414058}]}]}
{"op":"mcm","clk":"1006340316","pt":1580647788505,"mc":[{"id":"1.168224552","rc":[{"trd":[[1.56,327.92]],"batb":[[0,1.56,205.2]],"ltp":1.56,"tv":4134.71,"id":7414058}],"tv":4943.77}]}
{"op":"mcm","clk":"1006340622","pt":1580647790404,"mc":[{"id":"1.168224552","rc":[{"batb":[[0,1.56,130.19]],"batl":[[0,1.6,238.73]],"ltp":1.56,"tv":4134.71,"id":7414058}]}]}
{"op":"mcm","clk":"1006340646","pt":1580647790575,"mc":[{"id":"1.168224552","rc":[{"batb":[[1,1.55,410.25],[2,1.54,371.1]],"ltp":1.56,"tv":4134.71,"id":7414058}]}]}
{"op":"mcm","clk":"1006341568","pt":1580647796410,"mc":[{"id":"1.168224552","rc":[{"batb":[[0,2.66,2.56]],"batl":[[0,2.96,21],[1,1000,0.02],[2,2.96,0]],"ltp":3.2,"tv":809.06,"id":7287690},{"batb":[[0,1.54,2.66],[1,1.51,82.34],[2,1.45,176.09]],"batl":[[0,1.63,42.01],[1,1.71,2],[2,1.75,3.54]],"ltp":1.56,"tv":4134.71,"id":7414058}]}]}
{"op":"mcm","clk":"1006341862","pt":1580647798292,"mc":[{"id":"1.168224552","rc":[{"batb":[[1,2.44,68.37],[2,1.8,75.72]],"batl":[[0,1000,0.02],[1,1000,0]],"ltp":3.2,"tv":809.06,"id":7287690},{"trd":[[1.54,13.96]],"batb":[[0,1.45,177.08],[1,1.38,448.45],[2,1.25,378.62]],"batl":[[0,1.71,2],[1,1.75,3.54],[2,2.04,383.01]],"ltp":1.54,"tv":4138.06,"id":7414058}],"tv":4947.13}]}
{"op":"mcm","clk":"1006342031","pt":1580647799414,"mc":[{"id":"1.168224552","rc":[{"batb":[[0,1.57,73.69],[1,1.45,503.96],[2,1.44,309.54]],"batl":[[0,1.69,316.81],[1,1.71,322.65],[2,1.75,3.54]],"ltp":1.54,"tv":4138.06,"id":7414058}]}]}
{"op":"mcm","clk":"1006342063","pt":1580647799659,"mc":[{"id":"1.168224552","rc":[{"batb":[[0,1.45,503.96],[1,1.44,309.54],[2,1.38,448.45]],"ltp":1.54,"tv":4138.06,"id":7414058}]}]}
{"op":"mcm","clk":"1006342727","pt":1580647803274,"mc":[{"id":"1.168224552","rc":[{"batb":[[0,1.55,76.37],[1,1.45,503.96],[2,1.44,309.54]],"ltp":1.54,"tv":4138.06,"id":7414058}]}]}
{"op":"mcm","clk":"1006343070","pt":1580647805480,"mc":[{"id":"1.168224552","rc":[{"batb":[[0,2.44,68.37],[1,1.8,75.72],[2,1.7,75.72]],"ltp":3.2,"tv":809.06,"id":7287690},{"batb":[[1,1.45,502.97]],"ltp":1.54,"tv":4138.06,"id":7414058}]}]}
{"op":"mcm","clk":"1006343120","pt":1580647805812,"mc":[{"id":"1.168224552","rc":[{"batb":[[1,1.45,176.09],[2,1.38,448.45]],"ltp":1.54,"tv":4138.06,"id":7414058}]}]}
{"op":"mcm","clk":"1006343263","pt":1580647806658,"mc":[{"id":"1.168224552","rc":[{"batb":[[2,1.25,378.62]],"ltp":1.54,"tv":4138.06,"id":7414058}]}]}
{"op":"mcm","clk":"1006343566","pt":1580647808462,"mc":[{"id":"1.168224552","rc":[{"batl":[[0,2.64,344],[1,1000,0.02]],"ltp":3.2,"tv":809.06,"id":7287690},{"batb":[[0,1.64,1371.95],[1,1.55,76.37],[2,1.45,176.09]],"batl":[[0,1.69,1648.17],[1,1.7,597],[2,1.71,322.65]],"ltp":1.54,"tv":4138.06,"id":7414058}]}]}
{"op":"mcm","clk":"1006343720","pt":1580647809461,"mc":[{"id":"1.168224552","rc":[{"batb":[[1,2.42,29.41],[2,2.32,79.94]],"batl":[[1,2.74,23.53],[2,1000,0.02]],"ltp":3.2,"tv":809.06,"id":7287690},{"batb":[[0,1.64,1481.24],[1,1.63,351.19],[2,1.62,193.89]],"batl":[[1,1.7,639.01]],"ltp":1.54,"tv":4138.06,"id":7414058}]}]}
{"op":"mcm","clk":"1006343816","pt":1580647810152,"mc":[{"id":"1.168224552","rc":[{"batb":[[0,1.66,63.64],[1,1.64,1481.24],[2,1.63,351.19]],"ltp":1.54,"tv":4138.06,"id":7414058}]}]}
{"op":"mcm","clk":"1006343919","pt":1580647810891,"mc":[{"id":"1.168224552","rc":[{"batb":[[0,2.5,2.66],[1,2.44,68.37],[2,2.42,29.41]],"ltp":3.2,"tv":809.06,"id":7287690},{"batb":[[0,1.64,1481.24],[1,1.63,351.19],[2,1.62,193.89]],"ltp":1.54,"tv":4138.06,"id":7414058}]}]}
{"op":"mcm","clk":"1006344667","pt":1580647815380,"mc":[{"id":"1.168224552","rc":[{"batb":[[0,1.65,323.15],[1,1.64,1481.24],[2,1.63,351.19]],"batl":[[2,1.71,803.24]],"ltp":1.54,"tv":4138.06,"id":7414058}]}]}
{"op":"mcm","clk":"1006345323","pt":1580647819294,"mc":[{"id":"1.168224552","rc":[{"trd":[[2.44,192.19],[2.5,5.33]],"batb":[[0,2.42,29.41],[1,2.32,79.94],[2,1.8,75.72]],"ltp":2.44,"tv":1006.58,"id":7287690},{"trd":[[1.69,80.06]],"batb":[[2,1.63,188.99]],"batl":[[0,1.69,1568.11]],"ltp":1.69,"tv":4218.12,"id":7414058}],"tv":5224.71}]}
{"op":"mcm","clk":"1006345818","pt":1580647822186,"mc":[{"id":"1.168224552","rc":[{"trd":[[1.65,43.74]],"batb":[[0,1.65,301.28],[1,1.64,1687.1]],"batl":[[0,1.69,1604.86]],"ltp":1.65,"tv":4261.86,"id":7414058}],"tv":5268.45}]}
{"op":"mcm","clk":"1006346246","pt":1580647825182,"mc":[{"id":"1.168224552","rc":[{"batl":[[0,2.74,23.53],[1,1000,0.02],[2,1000,0]],"ltp":2.44,"tv":1006.58,"id":7287690},{"batb":[[1,1.61,494.03],[2,1.59,510.84]],"batl":[[0,1.7,42.01],[1,1.71,482.59],[2,1.73,497.4]],"ltp":1.65,"tv":4261.86,"id":7414058}]}]}
{"op":"mcm","clk":"1006346345","pt":1580647825933,"mc":[{"id":"1.168224552","rc":[{"batb":[[0,2.32,79.94],[1,1.8,75.72],[2,1.7,75.72]],"batl":[[0,1000,0.02],[1,1000,0]],"ltp":2.44,"tv":1006.58,"id":7287690},{"batl":[[0,1.71,482.59],[1,1.73,497.4],[2,1.75,3.54]],"ltp":1.65,"tv":4261.86,"id":7414058}]}]}
{"op":"mcm","clk":"1006346663","pt":1580647828113,"mc":[{"id":"1.168224552","rc":[{"batb":[[0,2.3,81.67]],"ltp":2.44,"tv":1006.58,"id":7287690},{"batb":[[0,1.67,313.5],[1,1.65,301.28],[2,1.61,494.03]],"ltp":1.65,"tv":4261.86,"id":7414058}]}]}
{"op":"mcm","clk":"1006347774","pt":1580647835928,"mc":[{"id":"1.168224552","rc":[{"trd":[[2.4,21]],"ltp":2.4,"tv":1027.58,"id":7287690},{"trd":[[1.71,29.47]],"batl":[[0,1.71,453.12]],"ltp":1.71,"tv":4291.34,"id":7414058}],"tv":5318.92}]}
{"op":"mcm","clk":"1006348233","pt":1580647839205,"mc":[{"id":"1.168224552","rc":[{"trd":[[1.67,591.08]],"batb":[[0,1.65,301.28],[1,1.56,132.19],[2,1.55,279.99]],"ltp":1.67,"tv":4291.67,"id":7414058}],"tv":5319.26}]}
{"op":"mcm","clk":"1006348381","pt":1580647840222,"mc":[{"id":"1.168224552","rc":[{"batb":[[0,1.56,132.19],[1,1.55,279.99],[2,1.54,234.41]],"ltp":1.67,"tv":4291.67,"id":7414058}]}]}
{"op":"mcm","clk":"1006348523","pt":1580647841406,"mc":[{"id":"1.168224552","rc":[{"batl":[[0,2.92,301],[1,1000,0.02]],"ltp":2.4,"tv":1027.58,"id":7287690},{"batl":[[0,1.58,359.85],[1,1.6,677],[2,1.62,217.74]],"ltp":1.67,"tv":4291.67,"id":7414058}]}]}
{"op":"mcm","clk":"1006348658","pt":1580647842410,"mc":[{"id":"1.168224552","rc":[{"batl":[[1,1.6,1048.94],[2,1.61,196.37]],"ltp":1.67,"tv":4291.67,"id":7414058}]}]}
{"op":"mcm","clk":"1006348773","pt":1580647843307,"mc":[{"id":"1.168224552","rc":[{"batb":[[0,2.66,54.84],[1,2.46,67.67],[2,1.8,75.72]],"batl":[[1,2.98,21],[2,1000,0.02]],"ltp":2.4,"tv":1027.58,"id":7287690}]}]}
{"op":"mcm","clk":"1006349412","pt":1580647847348,"mc":[{"id":"1.168224552","rc":[{"batl":[[1,1000,0.02],[2,1000,0]],"ltp":2.4,"tv":1027.58,"id":7287690}]}]}
{"op":"mcm","clk":"1006349508","pt":1580647848028,"mc":[{"id":"1.168224552","rc":[{"trd":[[1.58,316.5]],"batb":[[2,1.54,728.44]],"batl":[[0,1.58,338.12],[2,1.61,676.96]],"ltp":1.58,"tv":4335.13,"id":7414058}],"tv":5362.71}]}
{"op":"mcm","clk":"1006349853","pt":1580647850344,"mc":[{"id":"1.168224552","rc":[{"batl":[[1,2.96,21],[2,1000,0.02]],"ltp":2.4,"tv":1027.58,"id":7287690},{"trd":[[1.58,375.96]],"batl":[[0,1.58,308.39]],"ltp":1.58,"tv":4394.59,"id":7414058}],"tv":5422.18}]}
{"op":"mcm","clk":"1006349937","pt":1580647850820,"mc":[{"id":"1.168224552","rc":[{"batb":[[1,2.58,26.05],[2,2.46,67.67]],"ltp":2.4,"tv":1027.58,"id":7287690}]}]}
{"op":"mcm","clk":"1006350705","pt":1580647856449,"mc":[{"id":"1.168224552","rc":[{"batb":[[0,2.58,26.05],[1,2.46,67.67],[2,1.8,75.72]],"batl":[[0,2.96,21],[1,1000,0.02],[2,1000,0]],"ltp":2.4,"tv":1027.58,"id":7287690},{"trd":[[1.56,360.88]],"batb":[[0,1.55,279.99],[1,1.54,728.44],[2,1.52,510.84]],"batl":[[1,1.6,371.94]],"ltp":1.56,"tv":4427.55,"id":7414058}],"tv":5455.13}]}
{"op":"mcm","clk":"1006350751","pt":1580647856755,"mc":[{"id":"1.168224552","rc":[{"batb":[[0,1.54,494.03],[1,1.52,510.84],[2,1.51,82.34]],"batl":[[0,1.61,480.59],[1,1.62,42.01],[2,1.63,497.4]],"ltp":1.56,"tv":4427.55,"id":7414058}]}]}
{"op":"mcm","clk":"1006350936","pt":1580647857942,"mc":[{"id":"1.168224552","rc":[{"batb":[[0,2.46,67.67],[1,1.8,75.72],[2,1.7,75.72]],"batl":[[0,1000,0.02],[1,1000,0]],"ltp":2.4,"tv":1027.58,"id":7287690},{"batb":[[2,1.45,175.93]],"batl":[[1,1.63,497.4],[2,1.7,12.11]],"ltp":1.56,"tv":4427.55,"id":7414058}]}]}
{"op":"mcm","clk":"1006351160","pt":1580647859562,"mc":[{"id":"1.168224552","rc":[{"batl":[[2,1.68,259.95]],"ltp":1.56,"tv":4427.55,"id":7414058}]}]}
{"op":"mcm","clk":"1006351406","pt":1580647861239,"mc":[{"id":"1.168224552","rc":[{"batl":[[2,1.7,12.11]],"ltp":1.56,"tv":4427.55,"id":7414058}]}]}
{"op":"mcm","clk":"1006351878","pt":1580647864263,"mc":[{"id":"1.168224552","rc":[{"batb":[[1,1.53,235.68],[2,1.52,757.41]],"batl":[[0,1.57,250.82],[1,1.58,210.95],[2,1.61,480.59]],"ltp":1.56,"tv":4427.55,"id":7414058}]}]}
{"op":"mcm","clk":"1006352286","pt":1580647866934,"mc":[{"id":"1.168224552","rc":[{"batb":[[1,1.52,510.84],[2,1.45,175.93]],"batl":[[0,1.61,480.59],[1,1.63,497.4],[2,1.7,12.11]],"ltp":1.56,"tv":4427.55,"id":7414058}]}]}
{"op":"mcm","clk":"1006352806","pt":1580647869986,"mc":[{"id":"1.168224552","rc":[{"batl":[[2,1.68,259.95]],"ltp":1.56,"tv":4427.55,"id":7414058}]}]}
{"op":"mcm","clk":"1006352954","pt":1580647870869,"mc":[{"id":"1.168224552","rc":[{"batb":[[0,1.45,175.93],[1,1.44,498.86],[2,1.43,320.24]],"batl":[[2,1.7,12.11]],"ltp":1.56,"tv":4427.55,"id":7414058}]}]}
{"op":"mcm","clk":"1006353313","pt":1580647873274,"mc":[{"id":"1.168224552","rc":[{"batl":[[0,3.45,393],[1,1000,0.02]],"ltp":2.4,"tv":1027.58,"id":7287690},{"batb":[[1,1.44,2061.36]],"batl":[[0,1.48,2214.27],[1,1.61,480.59],[2,1.63,497.4]],"ltp":1.56,"tv":4427.55,"id":7414058}]}]}
{"op":"mcm","clk":"1006353516","pt":1580647874482,"mc":[{"id":"1.168224552","rc":[{"batb":[[0,3,97.57],[1,2.7,52.72],[2,1.8,75.72]],"ltp":2.4,"tv":1027.58,"id":7287690},{"batl":[[0,1.48,2431.46],[1,1.49,264.78],[2,1.61,480.59]],"ltp":1.56,"tv":4427.55,"id":7414058}]}]}
{"op":"mcm","clk":"1006353617","pt":1580647875171,"mc":[{"id":"1.168224552","rc":[{"batl":[[0,3.35,17.64],[1,3.45,393],[2,1000,0.02]],"ltp":2.4,"tv":1027.58,"id":7287690}]}]}
{"op":"mcm","clk":"1006353784","pt":1580647876090,"mc":[{"id":"1.168224552","rc":[{"batb":[[1,2.9,21.85],[2,2.7,52.72]],"ltp":2.4,"tv":1027.58,"id":7287690},{"batl":[[2,1.53,42.01]],"ltp":1.56,"tv":4427.55,"id":7414058}]}]}
{"op":"mcm","clk":"1006354053","pt":1580647877794,"mc":[{"id":"1.168224552","rc":[{"trd":[[3.05,116.96]],"ltp":3.05,"tv":1127.58,"id":7287690},{"trd":[[1.48,206.1]],"batl":[[0,1.48,2225.38]],"ltp":1.48,"tv":4633.63,"id":7414058}],"tv":5761.21}]}
{"op":"mcm","clk":"1006354641","pt":1580647881886,"mc":[{"id":"1.168224552","rc":[{"trd":[[1.48,206.44]],"batl":[[0,1.48,2225.21]],"ltp":1.48,"tv":4633.97,"id":7414058}],"tv":5761.55}]}
{"op":"mcm","clk":"1006355421","pt":1580647887280,"mc":[{"id":"1.168224552","rc":[{"batl":[[1,1000,0.02],[2,1000,0]],"ltp":3.05,"tv":1127.58,"id":7287690},{"batb":[[1,1.44,2101.45]],"batl":[[0,1.48,1737.46]],"ltp":1.48,"tv":4633.97,"id":7414058}]}]}
{"op":"mcm","clk":"1006355512","pt":1580647887907,"mc":[{"id":"1.168224552","rc":[{"batb":[[0,2.7,52.72],[1,1.8,75.72],[2,1.7,75.72]],"batl":[[0,1000,0.02],[1,1000,0]],"ltp":3.05,"tv":1127.58,"id":7287690},{"batb":[[0,1.44,40.09],[1,1.33,259.73],[2,1.31,477.51]],"batl":[[0,1.7,12.11],[1,1.75,3.54],[2,1.89,435.28]],"ltp":1.48,"tv":4633.97,"id":7414058}]}]}
{"op":"mcm","clk":"1006355732","pt":1580647889282,"mc":[{"id":"1.168224552","rc":[{"trd":[[1.44,80.34]],"batb":[[0,1.33,259.73],[1,1.31,477.51],[2,1.2,284.06]],"batl":[[0,1.44,1.5],[1,1.45,25],[2,1.7,12.11]],"ltp":1.44,"tv":4714.15,"id":7414058}],"tv":5841.74}]}
{"op":"mcm","clk":"1006356035","pt":1580647891470,"mc":[{"id":"1.168224552","rc":[{"batl":[[2,1.59,322.7]],"ltp":1.44,"tv":4714.15,"id":7414058}]}]}
{"op":"mcm","clk":"1006356275","pt":1580647893163,"mc":[{"id":"1.168224552","rc":[{"batb":[[1,1.2,284.06],[2,1.15,378.62]],"ltp":1.44,"tv":4714.15,"id":7414058}]}]}
{"op":"mcm","clk":"1006356447","pt":1580647894394,"mc":[{"id":"1.168224552","rc":[{"trd":[[3.2,19.5],[3.25,0.66]],"batl":[[0,2.78,265.14],[1,2.94,303],[2,1000,0.02]],"ltp":3.2,"tv":1133.39,"id":7287690},{"trd":[[1.44,81.84],[1.45,103.61]],"batb":[[0,1.53,245.1],[1,1.33,259.73],[2,1.2,284.06]],"batl":[[0,1.59,897.7],[1,1.6,201.09],[2,1.7,12.11]],"ltp":1.45,"tv":4727.01,"id":7414058}],"tv":5860.4}]}
{"op":"mcm","clk":"1006356620","pt":1580647895458,"mc":[{"id":"1.168224552","rc":[{"batb":[[1,2.48,66.25],[2,1.8,75.72]],"ltp":3.2,"tv":1133.39,"id":7287690},{"batb":[[0,1.54,492.7],[1,1.53,485.97],[2,1.44,180.26]],"ltp":1.45,"tv":4727.01,"id":7414058}]}]}
{"op":"mcm","clk":"1006356703","pt":1580647896083,"mc":[{"id":"1.168224552","rc":[{"batb":[[2,1.5,17.16]],"ltp":1.45,"tv":4727.01,"id":7414058}]}]}
{"op":"mcm","clk":"1006356862","pt":1580647897296,"mc":[{"id":"1.168224552","rc":[{"batb":[[1,2.64,25.21],[2,2.48,66.25]],"batl":[[2,3.05,84.02]],"ltp":3.2,"tv":1133.39,"id":7287690},{"batl":[[2,1.61,42.01]],"ltp":1.45,"tv":4727.01,"id":7414058}]}]}
{"op":"mcm","clk":"1006356913","pt":1580647897717,"mc":[{"id":"1.168224552","rc":[{"batl":[[2,3,21]],"ltp":3.2,"tv":1133.39,"id":7287690}]}]}
{"op":"mcm","clk":"1006357094","pt":1580647899310,"mc":[{"id":"1.168224552","rc":[{"batb":[[2,1.49,85.7]],"ltp":1.45,"tv":4727.01,"id":7414058}]}]}
{"op":"mcm","clk":"1006357520","pt":1580647902750,"mc":[{"id":"1.168224552","rc":[{"batb":[[0,1.55,305.52],[1,1.54,492.7],[2,1.53,485.97]],"ltp":1.45,"tv":4727.01,"id":7414058}]}]}
{"op":"mcm","clk":"1006357741","pt":1580647904554,"mc":[{"id":"1.168224552","rc":[{"trd":[[2.78,12.69]],"batl":[[0,2.78,264.45]],"ltp":2.78,"tv":1134.08,"id":7287690},{"trd":[[1.56,362.11]],"ltp":1.56,"tv":4728.24,"id":7414058}],"tv":5862.32}]}
{"op":"mcm","clk":"1006357952","pt":1580647905839,"mc":[{"id":"1.168224552","rc":[{"batb":[[0,1.56,5]],"ltp":1.56,"tv":4728.24,"id":7414058}]}]}
{"op":"mcm","clk":"1006358287","pt":1580647908034,"mc":[{"id":"1.168224552","rc":[{"trd":[[2.78,21.11]],"batl":[[0,2.78,256.03]],"ltp":2.78,"tv":1142.5,"id":7287690},{"trd":[[1.56,387.11]],"batb":[[0,1.54,492.7],[1,1.53,485.97],[2,1.49,85.7]],"ltp":1.56,"tv":4753.24,"id":7414058}],"tv":5895.74}]}
{"op":"mcm","clk":"1006358443","pt":1580647909257,"mc":[{"id":"1.168224552","rc":[{"batl":[[1,3,21],[2,1000,0.02]],"ltp":2.78,"tv":1142.5,"id":7287690},{"batl":[[0,1.59,322.7]],"ltp":1.56,"tv":4753.24,"id":7414058}]}]}
{"op":"mcm","clk":"1006358540","pt":1580647909963,"mc":[{"id":"1.168224552","rc":[{"trd":[[2.78,22.05]],"batb":[[0,2.48,66.25],[1,1.8,75.72],[2,1.7,75.72]],"batl":[[0,1000,0.02],[1,3,0],[2,1000,0]],"ltp":2.78,"tv":1143.44,"id":7287690},{"trd":[[1.56,388.79]],"batb":[[0,1.54,311.18],[1,1.44,180.26],[2,1.38,448.45]],"batl":[[0,1.7,12.11],[1,1.75,3.54],[2,1.89,435.28]],"ltp":1.56,"tv":4754.92,"id":7414058}],"tv":5898.36}]}
{"op":"mcm","clk":"1006359558","pt":1580647916441,"mc":[{"id":"1.168224552","rc":[{"batb":[[1,1.52,323.92],[2,1.51,253.65]],"batl":[[0,1.56,186.45],[1,1.57,216.31],[2,1.7,12.11]],"ltp":1.56,"tv":4754.92,"id":7414058}]}]}
{"op":"mcm","clk":"1006359935","pt":1580647919369,"mc":[{"id":"1.168224552","rc":[{"batb":[[0,1.44,180.26],[1,1.38,448.45],[2,1.25,378.62]],"batl":[[0,1.7,12.11],[1,1.75,3.54],[2,1.89,435.28]],"ltp":1.56,"tv":4754.92,"id":7414058}]}]}
{"op":"mcm","clk":"1006360319","pt":1580647922382,"mc":[{"id":"1.168224552","rc":[{"batb":[[0,1.53,317.05],[1,1.44,511.88],[2,1.43,318.82]],"batl":[[0,1.67,225.28],[1,1.69,334.05],[2,1.7,12.11]],"ltp":1.56,"tv":4754.92,"id":7414058}]}]}
{"op":"mcm","clk":"1006360656","pt":1580647924916,"mc":[{"id":"1.168224552","rc":[{"batl":[[0,1.54,2],[1,1.67,225.28],[2,1.69,334.05]],"ltp":1.56,"tv":4754.92,"id":7414058}]}]}
{"op":"mcm","clk":"1006360857","pt":1580647926461,"mc":[{"id":"1.168224552","rc":[{"batb":[[0,1.44,511.88],[1,1.43,318.82],[2,1.38,448.45]],"ltp":1.56,"tv":4754.92,"id":7414058}]}]}
{"op":"mcm","clk":"1006361062","pt":1580647927977,"mc":[{"id":"1.168224552","rc":[{"batb":[[0,1.44,180.26],[1,1.38,448.45],[2,1.25,378.62]],"batl":[[1,1.7,12.11],[2,1.75,3.54]],"ltp":1.56,"tv":4754.92,"id":7414058}]}]}
{"op":"mcm","clk":"1006361232","pt":1580647929406,"mc":[{"id":"1.168224552","rc":[{"batb":[[1,1.25,378.62],[2,1.2,284.06]],"ltp":1.56,"tv":4754.92,"id":7414058}]}]}
{"op":"mcm","clk":"1006361368","pt":1580647930399,"mc":[{"id":"1.168224552","rc":[{"batl":[[0,3.45,326],[1,1000,0.02]],"ltp":2.78,"tv":1143.44,"id":7287690},{"batl":[[0,1.47,1644.39],[1,1.48,5233.6],[2,1.5,1537.69]],"ltp":1.56,"tv":4754.92,"id":7414058}]}]}
{"op":"mcm","clk":"1006361463","pt":1580647931092,"mc":[{"id":"1.168224552","rc":[{"batb":[[0,2.94,21],[1,2.48,66.25],[2,1.8,75.72]],"batl":[[0,3.45,342.8]],"ltp":2.78,"tv":1143.44,"id":7287690},{"batb":[[0,1.44,511.88],[1,1.43,318.82],[2,1.41,101.66]],"batl":[[0,1.47,164.44],[1,1.48,1216.79],[2,1.49,263.63]],"ltp":1.56,"tv":4754.92,"id":7414058}]}]}
{"op":"mcm","clk":"1006361560","pt":1580647931882,"mc":[{"id":"1.168224552","rc":[{"batb":[[0,3.05,94.97],[1,2.94,21],[2,2.72,52.17]],"ltp":2.78,"tv":1143.44,"id":7287690}]}]}
{"op":"mcm","clk":"1006362589","pt":1580647940072,"mc":[{"id":"1.168224552","rc":[{"trd":[[1.44,170.27]],"batb":[[0,1.44,467.65]],"ltp":1.44,"tv":4843.35,"id":7414058}],"tv":5986.79}]}
{"op":"mcm","clk":"1006362739","pt":1580647941348,"mc":[{"id":"1.168224552","rc":[{"batl":[[1,4.5,2.01],[2,1000,0.02]],"ltp":2.78,"tv":1143.44,"id":7287690},{"batl":[[0,1.45,12.11],[1,1.47,164.44],[2,1.48,1216.79]],"ltp":1.44,"tv":4843.35,"id":7414058}]}]}
{"op":"mcm","clk":"1006362992","pt":1580647943235,"mc":[{"id":"1.168224552","rc":[{"trd":[[1.44,370.27]],"batb":[[0,1.44,367.65]],"ltp":1.44,"tv":5043.36,"id":7414058}],"tv":6186.8}]}
{"op":"mcm","clk":"1006363152","pt":1580647944398,"mc":[{"id":"1.168224552","rc":[{"batl":[[2,4.6,2]],"ltp":2.78,"tv":1143.44,"id":7287690}]}]}
{"op":"mcm","clk":"1006363241","pt":1580647945098,"mc":[{"id":"1.168224552","rc":[{"trd":[[1.44,458.7],[1.45,127.83]],"batb":[[0,1.45,7.89],[1,1.44,323.42],[2,1.43,318.82]],"batl":[[0,1.47,164.44],[1,1.48,1216.79],[2,1.49,263.63]],"ltp":1.45,"tv":5156.0,"id":7414058}],"tv":6299.44}]}
{"op":"mcm","clk":"1006363420","pt":1580647946464,"mc":[{"id":"1.168224552","rc":[{"batl":[[0,3.2,2],[1,3.45,16.8],[2,4.5,2.01]],"ltp":2.78,"tv":1143.44,"id":7287690},{"batl":[[1,1.48,374.79]],"ltp":1.45,"tv":5156.0,"id":7414058}]}]}
{"op":"mcm","clk":"1006363560","pt":1580647947438,"mc":[{"id":"1.168224552","rc":[{"batb":[[0,2.94,21],[1,2.72,52.17],[2,2,75.72]],"batl":[[0,3.45,16.8],[1,4.5,2.01],[2,1000,0.02]],"ltp":2.78,"tv":1143.44,"id":7287690},{"batb":[[1,1.41,101.66],[2,1.33,262.4]],"batl":[[0,1.52,42.01],[1,1.53,5.24],[2,1.62,25.25]],"ltp":1.45,"tv":5156.0,"id":7414058}]}]}
{"op":"mcm","clk":"1006363675","pt":1580647948108,"mc":[{"id":"1.168224552","rc":[{"batb":[[0,2.72,52.17],[1,2.58,3.56]],"batl":[[0,4.5,2.01],[1,1000,0.02],[2,1000,0]],"ltp":2.78,"tv":1143.44,"id":7287690},{"batb":[[1,1.33,262.4],[2,1.28,547.55]],"batl":[[0,1.53,5.24],[1,1.62,25.25],[2,1.63,26.5]],"ltp":1.45,"tv":5156.0,"id":7414058}]}]}
{"op":"mcm","clk":"1006363868","pt":1580647949450,"mc":[{"id":"1.168224552","rc":[{"batb":[[1,2.6,3.29],[2,2.58,3.56]],"ltp":2.78,"tv":1143.44,"id":7287690},{"batb":[[0,1.33,262.4],[1,1.29,56.81]],"ltp":1.45,"tv":5156.0,"id":7414058}]}]}
{"op":"mcm","clk":"1006363976","pt":1580647950357,"mc":[{"id":"1.168224552","rc":[{"batb":[[0,2.74,50.36],[1,2.72,52.17],[2,2.6,3.29]],"batl":[[1,4.6,2],[2,1000,0.02]],"ltp":2.78,"tv":1143.44,"id":7287690},{"batb":[[1,1.32,692.94],[2,1.31,486.31]],"batl":[[1,1.58,267.63],[2,1.59,206.02]],"ltp":1.45,"tv":5156.0,"id":7414058}]}]}
{"op":"mcm","clk":"1006364128","pt":1580647951342,"mc":[{"id":"1.168224552","rc":[{"batb":[[1,2.72,3.59]],"ltp":2.78,"tv":1143.44,"id":7287690},{"batb":[[0,1.32,269.64],[1,1.29,56.81],[2,1.28,547.55]],"batl":[[1,1.58,29.75],[2,1.62,25.25]],"ltp":1.45,"tv":5156.0,"id":7414058}]}]}
{"op":"mcm","clk":"1006364188","pt":1580647951825,"mc":[{"id":"1.168224552","rc":[{"batb":[[1,2.6,3.29],[2,2.58,3.56]],"ltp":2.78,"tv":1143.44,"id":7287690},{"batl":[[0,1.44,30.97],[1,1.53,5.24]],"ltp":1.45,"tv":5156.0,"id":7414058}]}]}
{"op":"mcm","clk":"1006364394","pt":1580647953316,"mc":[{"id":"1.168224552","rc":[{"batl":[[1,1.62,25.25],[2,1.63,26.5]],"ltp":1.45,"tv":5156.0,"id":7414058}]}]}
{"op":"mcm","clk":"1006364523","pt":1580647954212,"mc":[{"id":"1.168224552","rc":[{"batb":[[0,1.41,493.22],[1,1.4,352.19],[2,1.32,269.64]],"batl":[[1,1.45,318.34],[2,1.46,286.99]],"ltp":1.45,"tv":5156.0,"id":7414058}]}]}
{"op":"mcm","clk":"1006364583","pt":1580647954743,"mc":[{"id":"1.168224552","rc":[{"batb":[[1,2.72,3.09],[2,2.6,3.29]],"ltp":2.78,"tv":1143.44,"id":7287690}]}]}
{"op":"mcm","clk":"1006364805","pt":1580647956455,"mc":[{"id":"1.168224552","rc":[{"trd":[[1.41,10.48]],"batb":[[0,1.32,269.64],[1,1.29,56.81],[2,1.28,547.55]],"batl":[[0,1.58,34.75],[1,1.62,25.25],[2,1.63,26.5]],"ltp":1.41,"tv":5166.48,"id":7414058}],"tv":6309.92}]}
{"op":"mcm","clk":"1006364835","pt":1580647956626,"mc":[{"id":"1.168224552","rc":[{"batb":[[1,2.6,3.29],[2,2.58,3.56]],"ltp":2.78,"tv":1143.44,"id":7287690},{"batl":[[0,1.62,25.25],[1,1.63,26.5],[2,1.75,3.54]],"ltp":1.41,"tv":5166.48,"id":7414058}]}]}
{"op":"mcm","clk":"1006365181","pt":1580647959430,"mc":[{"id":"1.168224552","rc":[{"batb":[[0,1.32,692.94],[1,1.31,486.31],[2,1.29,56.81]],"batl":[[0,1.58,267.63],[1,1.59,206.02],[2,1.62,25.25]],"ltp":1.41,"tv":5166.48,"id":7414058}]}]}
{"op":"mcm","clk":"1006365242","pt":1580647959849,"mc":[{"id":"1.168224552","rc":[{"batb":[[1,2.72,3.34],[2,2.6,3.29]],"ltp":2.78,"tv":1143.44,"id":7287690},{"batl":[[0,1.58,297.38]],"ltp":1.41,"tv":5166.48,"id":7414058}]}]}
{"op":"mcm","clk":"1006365706","pt":1580647963374,"mc":[{"id":"1.168224552","rc":[{"batb":[[1,2.6,3.29],[2,2.58,3.56]],"ltp":2.78,"tv":1143.44,"id":7287690},{"batl":[[0,1.62,25.25],[1,1.63,26.5],[2,1.75,3.54]],"ltp":1.41,"tv":5166.48,"id":7414058}]}]}
{"op":"mcm","clk":"1006366077","pt":1580647966240,"mc":[{"id":"1.168224552","rc":[{"batb":[[0,3.7,101.35],[1,2.74,50.36],[2,2.6,3.29]],"batl":[[0,4.5,303.01]],"ltp":2.78,"tv":1143.44,"id":7287690},{"batl":[[0,1.34,834],[1,1.35,394.22],[2,1.36,533.2]],"ltp":1.41,"tv":5166.48,"id":7414058}]}]}
{"op":"mcm","clk":"1006366216","pt":1580647967247,"mc":[{"id":"1.168224552","rc":[{"batb":[[0,3.9,14.28],[1,3.8,55.63],[2,3.7,101.35]],"ltp":2.78,"tv":1143.44,"id":7287690},{"batb":[[2,1.29,362.41]],"batl":[[0,1.34,876.01]],"ltp":1.41,"tv":5166.48,"id":7414058}]}]}
{"op":"mcm","clk":"1006366372","pt":1580647968459,"mc":[{"id":"1.168224552","rc":[{"trd":[[1.32,6.06],[1.34,5.1]],"batb":[[0,1.32,689.91]],"batl":[[0,1.34,873.46],[2,1.36,766.58]],"ltp":1.32,"tv":5177.64,"id":7414058}],"tv":6321.08}]}
{"op":"mcm","clk":"1006366488","pt":1580647969363,"mc":[{"id":"1.168224552","rc":[{"batl":[[2,4.7,10.92]],"ltp":2.78,"tv":1143.44,"id":7287690},{"trd":[[1.34,113.6]],"batl":[[0,1.34,819.21],[2,1.36,533.2]],"ltp":1.34,"tv":5286.14,"id":7414058}],"tv":6429.58}]}
{"op":"mcm","clk":"1006366724","pt":1580647971283,"mc":[{"id":"1.168224552","rc":[{"batl":[[0,1.33,254.6],[1,1.34,819.21],[2,1.35,394.22]],"ltp":1.34,"tv":5286.14,"id":7414058}]}]}
{"op":"mcm","clk":"1006367229","pt":1580647975050,"mc":[{"id":"1.168224552","rc":[{"batb":[[1,3.85,55]],"ltp":2.78,"tv":1143.44,"id":7287690},{"trd":[[1.32,6.8]],"batb":[[0,1.32,689.54]],"ltp":1.32,"tv":5286.87,"id":7414058}],"tv":6430.32}]}
{"op":"mcm","clk":"1006367330","pt":1580647975941,"mc":[{"id":"1.168224552","rc":[{"trd":[[1.32,68.74]],"batb":[[0,1.32,658.57]],"ltp":1.32,"tv":5348.82,"id":7414058}],"tv":6492.26}]}
{"op":"mcm","clk":"1006367853","pt":1580647979960,"mc":[{"id":"1.168224552","rc":[{"trd":[[1.33,177.38]],"batl":[[0,1.33,165.91]],"ltp":1.33,"tv":5526.2,"id":7414058}],"tv":6669.64}]}
{"op":"mcm","clk":"1006368278","pt":1580647982950,"mc":[{"id":"1.168224552","rc":[{"batb":[[1,3.85,54.05]],"ltp":2.78,"tv":1143.44,"id":7287690},{"batb":[[0,1.32,423.3],[1,1.31,761.46],[2,1.29,56.81]],"ltp":1.33,"tv":5526.2,"id":7414058}]}]}
{"op":"mcm","clk":"1006368912","pt":1580647987000,"mc":[{"id":"1.168224552","rc":[{"trd":[[1.33,178.18]],"batl":[[0,1.33,165.52]],"ltp":1.33,"tv":5526.99,"id":7414058}],"tv":6670.44}]}
{"op":"mcm","clk":"1006370335","pt":1580647996089,"mc":[{"id":"1.168224552","rc":[{"trd":[[1.32,80.74]],"batb":[[0,1.32,417.3]],"ltp":1.32,"tv":5538.99,"id":7414058}],"tv":6682.44}]}
{"op":"mcm","clk":"1006371568","pt":1580648004710,"mc":[{"id":"1.168224552","rc":[{"trd":[[1.32,88.32]],"batb":[[0,1.32,413.51]],"ltp":1.32,"tv":5546.57,"id":7414058}],"tv":6690.01}]}
{"op":"mcm","clk":"1006371897","pt":1580648007241,"mc":[{"id":"1.168224552","rc":[{"trd":[[1.32,148.32]],"batb":[[0,1.32,383.51]],"ltp":1.32,"tv":5606.57,"id":7414058}],"tv":6750.01}]}
{"op":"mcm","clk":"1006372371","pt":1580648010585,"mc":[{"id":"1.168224552","rc":[{"batl":[[2,1.35,428.45]],"ltp":1.32,"tv":5606.57,"id":7414058}]}]}
{"op":"mcm","clk":"1006372737","pt":1580648013010,"mc":[{"id":"1.168224552","rc":[{"batb":[[0,1.32,388.51]],"ltp":1.32,"tv":5606.57,"id":7414058}]}]}
{"op":"mcm","clk":"1006373202","pt":1580648016110,"mc":[{"id":"1.168224552","rc":[{"batb":[[0,1.32,383.51]],"ltp":1.32,"tv":5606.57,"id":7414058}]}]}
{"op":"mcm","clk":"1006373387","pt":1580648017402,"mc":[{"id":"1.168224552","rc":[{"batl":[[1,1.34,777.2]],"ltp":1.32,"tv":5606.57,"id":7414058}]}]}
{"op":"mcm","clk":"1006373525","pt":1580648018307,"mc":[{"id":"1.168224552","rc":[{"trd":[[1.32,448.32],[1.33,188.17]],"batb":[[0,1.32,233.51]],"batl":[[0,1.33,160.52]],"ltp":1.33,"tv":5916.57,"id":7414058}],"tv":7060.01}]}
