{"op":"mcm","clk":"998154875","pt":1580585274635,"mc":[{"id":"1.168224467","marketDefinition":{"bspMarket":false,"turnInPlayEnabled":true,"persistenceEnabled":true,"marketBaseRate":5.0,"eventId":"29681747","eventTypeId":"2","numberOfWinners":1,"bettingType":"ODDS","marketType":"SET_BETTING","marketTime":"2020-02-02T09:00:00.000Z","suspendTime":"2020-02-02T09:00:00.000Z","bspReconciled":false,"complete":true,"inPlay":false,"crossMatching":false,"runnersVoidable":false,"numberOfActiveRunners":4,"betDelay":0,"status":"OPEN","runners":[{"status":"ACTIVE","sortPriority":1,"id":13117353,"name":"Moriya 2-0"},{"status":"ACTIVE","sortPriority":2,"id":13117354,"name":"Moriya 2-1"},{"status":"ACTIVE","sortPriority":3,"id":16604346,"name":"Petrovic 2-0"},{"status":"ACTIVE","sortPriority":4,"id":16604347,"name":"Petrovic 2-1"}],"regulators":["MR_INT"],"countryCode":"FR","discountAllowed":false,"timezone":"UTC","openDate":"2020-02-02T09:00:00.000Z","version":3147098673,"name":"Set Betting","eventName":"Moriya v Petrovic"}}]}
{"op":"mcm","clk":"998155189","pt":1580585276473,"mc":[{"id":"1.168224467","marketDefinition":{"bspMarket":false,"turnInPlayEnabled":true,"persistenceEnabled":true,"marketBaseRate":5.0,"eventId":"29681747","eventTypeId":"2","numberOfWinners":1,"bettingType":"ODDS","marketType":"SET_BETTING","marketTime":"2020-02-02T09:00:00.000Z","suspendTime":"2020-02-02T09:00:00.000Z","bspReconciled":false,"complete":true,"inPlay":false,"crossMatching":false,"runnersVoidable":false,"numberOfActiveRunners":4,"betDelay":0,"status":"OPEN","runners":[{"status":"ACTIVE","sortPriority":1,"id":13117353,"name":"Moriya 2-0"},{"status":"ACTIVE","sortPriority":2,"id":13117354,"name":"Moriya 2-1"},{"status":"ACTIVE","sortPriority":3,"id":16604346,"name":"Petrovic 2-0"},{"status":"ACTIVE","sortPriority":4,"id":16604347,"name":"Petrovic 2-1"}],"regulators":["MR_INT"],"countryCode":"FR","discountAllowed":true,"timezone":"UTC","openDate":"2020-02-02T09:00:00.000Z","version":3147098673,"name":"Set Betting","eventName":"Moriya v Petrovic"}}]}
{"op":"mcm","clk":"998196782","pt":1580585516475,"mc":[{"id":"1.168224467","marketDefinition":{"bspMarket":false,"turnInPlayEnabled":true,"persistenceEnabled":true,"marketBaseRate":5.0,"eventId":"29681747","eventTypeId":"2","numberOfWinners":1,"bettingType":"ODDS","marketType":"SET_BETTING","marketTime":"2020-02-02T15:30:00.000Z","suspendTime":"2020-02-02T15:30:00.000Z","bspReconciled":false,"complete":true,"inPlay":false,"crossMatching":false,"runnersVoidable":false,"numberOfActiveRunners":4,"betDelay":0,"status":"OPEN","runners":[{"status":"ACTIVE","sortPriority":1,"id":13117353,"name":"Moriya 2-0"},{"status":"ACTIVE","sortPriority":2,"id":13117354,"name":"Moriya 2-1"},{"status":"ACTIVE","sortPriority":3,"id":16604346,"name":"Petrovic 2-0"},{"status":"ACTIVE","sortPriority":4,"id":16604347,"name":"Petrovic 2-1"}],"regulators":["MR_INT"],"countryCode":"FR","discountAllowed":true,"timezone":"UTC","openDate":"2020-02-02T09:00:00.000Z","version":3147125083,"name":"Set Betting","eventName":"Moriya v Petrovic"}}]}
{"op":"mcm","clk":"998197430","pt":1580585519449,"mc":[{"id":"1.168224467","marketDefinition":{"bspMarket":false,"turnInPlayEnabled":true,"persistenceEnabled":true,"marketBaseRate":5.0,"eventId":"29681747","eventTypeId":"2","numberOfWinners":1,"bettingType":"ODDS","marketType":"SET_BETTING","marketTime":"2020-02-02T15:30:00.000Z","suspendTime":"2020-02-02T15:30:00.000Z","bspReconciled":false,"complete":true,"inPlay":false,"crossMatching":false,"runnersVoidable":false,"numberOfActiveRunners":4,"betDelay":0,"status":"OPEN","runners":[{"status":"ACTIVE","sortPriority":1,"id":13117353,"name":"Moriya 2-0"},{"status":"ACTIVE","sortPriority":2,"id":13117354,"name":"Moriya 2-1"},{"status":"ACTIVE","sortPriority":3,"id":16604346,"name":"Petrovic 2-0"},{"status":"ACTIVE","sortPriority":4,"id":16604347,"name":"Petrovic 2-1"}],"regulators":["MR_INT"],"countryCode":"FR","discountAllowed":true,"timezone":"UTC","openDate":"2020-02-02T15:30:00.000Z","version":3147125083,"name":"Set Betting","eventName":"Moriya v Petrovic"}}]}
{"op":"mcm","clk":"998566472","pt":1580587950066,"mc":[{"id":"1.168224467","rc":[{"batb":[[0,1.02,2]],"ltp":0.0,"tv":0.0,"id":13117353},{"batb":[[0,1.02,2]],"ltp":0.0,"tv":0.0,"id":16604347},{"batb":[[0,1.02,2]],"ltp":0.0,"tv":0.0,"id":16604346},{"batb":[[0,1.02,2]],"ltp":0.0,"tv":0.0,"id":13117354}]}]}
{"op":"mcm","clk":"999887616","pt":1580602192189,"mc":[{"id":"1.168224467","rc":[{"batb":[[1,1.01,2.53]],"ltp":0.0,"tv":0.0,"id":13117353},{"batb":[[1,1.01,2.53]],"ltp":0.0,"tv":0.0,"id":16604347},{"batb":[[1,1.01,2.53]],"ltp":0.0,"tv":0.0,"id":16604346},{"batb":[[1,1.01,2.53]],"ltp":0.0,"tv":0.0,"id":13117354}]}]}
{"op":"mcm","clk":"999887684","pt":1580602193223,"mc":[{"id":"1.168224467","rc":[{"batb":[[1,1.01,0.51]],"ltp":0.0,"tv":0.0,"id":13117353},{"batb":[[1,1.01,0.51]],"ltp":0.0,"tv":0.0,"id":16604347},{"batb":[[1,1.01,0.51]],"ltp":0.0,"tv":0.0,"id":16604346},{"batb":[[1,1.01,0.51]],"ltp":0.0,"tv":0.0,"id":13117354}]}]}
{"op":"mcm","clk":"999983612","pt":1580603732198,"mc":[{"id":"1.168224467","rc":[{"batb":[[1,1.01,3.04]],"ltp":0.0,"tv":0.0,"id":13117353},{"batb":[[1,1.01,3.04]],"ltp":0.0,"tv":0.0,"id":16604347},{"batb":[[1,1.01,3.04]],"ltp":0.0,"tv":0.0,"id":16604346},{"batb":[[1,1.01,3.04]],"ltp":0.0,"tv":0.0,"id":13117354}]}]}
{"op":"mcm","clk":"999983644","pt":1580603733234,"mc":[{"id":"1.168224467","rc":[{"batb":[[1,1.01,1.01]],"ltp":0.0,"tv":0.0,"id":13117353},{"batb":[[1,1.01,1.01]],"ltp":0.0,"tv":0.0,"id":16604347},{"batb":[[1,1.01,1.01]],"ltp":0.0,"tv":0.0,"id":16604346},{"batb":[[1,1.01,1.01]],"ltp":0.0,"tv":0.0,"id":13117354}]}]}
{"op":"mcm","clk":"1001172948","pt":1580630119142,"mc":[{"id":"1.168224467","rc":[{"batb":[[0,2.5,30.29],[1,1.02,2],[2,1.01,1.01]],"ltp":0.0,"tv":0.0,"id":13117353}]}]}
{"op":"mcm","clk":"1001222284","pt":1580631092558,"mc":[{"id":"1.168224467","rc":[{"batb":[[0,2.5,30.29],[1,1.02,2],[2,1.01,1.01]],"ltp":0.0,"tv":0.0,"id":16604346}]}]}
{"op":"mcm","clk":"1001227553","pt":1580631214312,"mc":[{"id":"1.168224467","rc":[{"batb":[[0,1.02,2],[1,1.01,1.01],[2,1.01,0]],"ltp":0.0,"tv":0.0,"id":13117353}]}]}
{"op":"mcm","clk":"1001426382","pt":1580635616377,"mc":[{"id":"1.168224467","marketDefinition":{"bspMarket":false,"turnInPlayEnabled":true,"persistenceEnabled":true,"marketBaseRate":5.0,"eventId":"29681747","eventTypeId":"2","numberOfWinners":1,"bettingType":"ODDS","marketType":"SET_BETTING","marketTime":"2020-02-02T15:24:00.000Z","suspendTime":"2020-02-02T15:24:00.000Z","bspReconciled":false,"complete":true,"inPlay":false,"crossMatching":false,"runnersVoidable":false,"numberOfActiveRunners":4,"betDelay":0,"status":"OPEN","runners":[{"status":"ACTIVE","sortPriority":1,"id":13117353,"name":"Moriya 2-0"},{"status":"ACTIVE","sortPriority":2,"id":13117354,"name":"Moriya 2-1"},{"status":"ACTIVE","sortPriority":3,"id":16604346,"name":"Petrovic 2-0"},{"status":"ACTIVE","sortPriority":4,"id":16604347,"name":"Petrovic 2-1"}],"regulators":["MR_INT"],"countryCode":"FR","discountAllowed":true,"timezone":"UTC","openDate":"2020-02-02T15:30:00.000Z","version":3148345725,"name":"Set Betting","eventName":"Moriya v Petrovic"}}]}
{"op":"mcm","clk":"1001426714","pt":1580635619343,"mc":[{"id":"1.168224467","marketDefinition":{"bspMarket":false,"turnInPlayEnabled":true,"persistenceEnabled":true,"marketBaseRate":5.0,"eventId":"29681747","eventTypeId":"2","numberOfWinners":1,"bettingType":"ODDS","marketType":"SET_BETTING","marketTime":"2020-02-02T15:24:00.000Z","suspendTime":"2020-02-02T15:24:00.000Z","bspReconciled":false,"complete":true,"inPlay":false,"crossMatching":false,"runnersVoidable":false,"numberOfActiveRunners":4,"betDelay":0,"status":"OPEN","runners":[{"status":"ACTIVE","sortPriority":1,"id":13117353,"name":"Moriya 2-0"},{"status":"ACTIVE","sortPriority":2,"id":13117354,"name":"Moriya 2-1"},{"status":"ACTIVE","sortPriority":3,"id":16604346,"name":"Petrovic 2-0"},{"status":"ACTIVE","sortPriority":4,"id":16604347,"name":"Petrovic 2-1"}],"regulators":["MR_INT"],"countryCode":"FR","discountAllowed":true,"timezone":"UTC","openDate":"2020-02-02T15:24:00.000Z","version":3148345725,"name":"Set Betting","eventName":"Moriya v Petrovic"}}]}
{"op":"mcm","clk":"1001816331","pt":1580640414463,"mc":[{"id":"1.168224467","marketDefinition":{"bspMarket":false,"turnInPlayEnabled":true,"persistenceEnabled":true,"marketBaseRate":5.0,"eventId":"29681747","eventTypeId":"2","numberOfWinners":1,"bettingType":"ODDS","marketType":"SET_BETTING","marketTime":"2020-02-02T14:51:00.000Z","suspendTime":"2020-02-02T14:51:00.000Z","bspReconciled":false,"complete":true,"inPlay":false,"crossMatching":false,"runnersVoidable":false,"numberOfActiveRunners":4,"betDelay":0,"status":"OPEN","runners":[{"status":"ACTIVE","sortPriority":1,"id":13117353,"name":"Moriya 2-0"},{"status":"ACTIVE","sortPriority":2,"id":13117354,"name":"Moriya 2-1"},{"status":"ACTIVE","sortPriority":3,"id":16604346,"name":"Petrovic 2-0"},{"status":"ACTIVE","sortPriority":4,"id":16604347,"name":"Petrovic 2-1"}],"regulators":["MR_INT"],"countryCode":"FR","discountAllowed":true,"timezone":"UTC","openDate":"2020-02-02T15:24:00.000Z","version":3148438367,"name":"Set Betting","eventName":"Moriya v Petrovic"}}]}
{"op":"mcm","clk":"1001817051","pt":1580640420518,"mc":[{"id":"1.168224467","marketDefinition":{"bspMarket":false,"turnInPlayEnabled":true,"persistenceEnabled":true,"marketBaseRate":5.0,"eventId":"29681747","eventTypeId":"2","numberOfWinners":1,"bettingType":"ODDS","marketType":"SET_BETTING","marketTime":"2020-02-02T14:51:00.000Z","suspendTime":"2020-02-02T14:51:00.000Z","bspReconciled":false,"complete":true,"inPlay":false,"crossMatching":false,"runnersVoidable":false,"numberOfActiveRunners":4,"betDelay":0,"status":"OPEN","runners":[{"status":"ACTIVE","sortPriority":1,"id":13117353,"name":"Moriya 2-0"},{"status":"ACTIVE","sortPriority":2,"id":13117354,"name":"Moriya 2-1"},{"status":"ACTIVE","sortPriority":3,"id":16604346,"name":"Petrovic 2-0"},{"status":"ACTIVE","sortPriority":4,"id":16604347,"name":"Petrovic 2-1"}],"regulators":["MR_INT"],"countryCode":"FR","discountAllowed":true,"timezone":"UTC","openDate":"2020-02-02T14:51:00.000Z","version":3148438367,"name":"Set Betting","eventName":"Moriya v Petrovic"}}]}
{"op":"mcm","clk":"1001853042","pt":1580640715174,"mc":[{"id":"1.168224467","marketDefinition":{"bspMarket":false,"turnInPlayEnabled":true,"persistenceEnabled":true,"marketBaseRate":5.0,"eventId":"29681747","eventTypeId":"2","numberOfWinners":1,"bettingType":"ODDS","marketType":"SET_BETTING","marketTime":"2020-02-02T14:48:00.000Z","suspendTime":"2020-02-02T14:48:00.000Z","bspReconciled":false,"complete":true,"inPlay":false,"crossMatching":false,"runnersVoidable":false,"numberOfActiveRunners":4,"betDelay":0,"status":"OPEN","runners":[{"status":"ACTIVE","sortPriority":1,"id":13117353,"name":"Moriya 2-0"},{"status":"ACTIVE","sortPriority":2,"id":13117354,"name":"Moriya 2-1"},{"status":"ACTIVE","sortPriority":3,"id":16604346,"name":"Petrovic 2-0"},{"status":"ACTIVE","sortPriority":4,"id":16604347,"name":"Petrovic 2-1"}],"regulators":["MR_INT"],"countryCode":"FR","discountAllowed":true,"timezone":"UTC","openDate":"2020-02-02T14:51:00.000Z","version":3148443823,"name":"Set Betting","eventName":"Moriya v Petrovic"}}]}
{"op":"mcm","clk":"1001853415","pt":1580640718147,"mc":[{"id":"1.168224467","marketDefinition":{"bspMarket":false,"turnInPlayEnabled":true,"persistenceEnabled":true,"marketBaseRate":5.0,"eventId":"29681747","eventTypeId":"2","numberOfWinners":1,"bettingType":"ODDS","marketType":"SET_BETTING","marketTime":"2020-02-02T14:48:00.000Z","suspendTime":"2020-02-02T14:48:00.000Z","bspReconciled":false,"complete":true,"inPlay":false,"crossMatching":false,"runnersVoidable":false,"numberOfActiveRunners":4,"betDelay":0,"status":"OPEN","runners":[{"status":"ACTIVE","sortPriority":1,"id":13117353,"name":"Moriya 2-0"},{"status":"ACTIVE","sortPriority":2,"id":13117354,"name":"Moriya 2-1"},{"status":"ACTIVE","sortPriority":3,"id":16604346,"name":"Petrovic 2-0"},{"status":"ACTIVE","sortPriority":4,"id":16604347,"name":"Petrovic 2-1"}],"regulators":["MR_INT"],"countryCode":"FR","discountAllowed":true,"timezone":"UTC","openDate":"2020-02-02T14:48:00.000Z","version":3148443823,"name":"Set Betting","eventName":"Moriya v Petrovic"}}]}
{"op":"mcm","clk":"1002658314","pt":1580645699609,"mc":[{"id":"1.168224467","rc":[{"batb":[[0,1.02,2],[1,1.01,1.01],[2,1.01,0]],"ltp":0.0,"tv":0.0,"id":16604346}]}]}
{"op":"mcm","clk":"1002676122","pt":1580645813890,"mc":[{"id":"1.168224467","marketDefinition":{"bspMarket":false,"turnInPlayEnabled":true,"persistenceEnabled":true,"marketBaseRate":5.0,"eventId":"29681747","eventTypeId":"2","numberOfWinners":1,"bettingType":"ODDS","marketType":"SET_BETTING","marketTime":"2020-02-02T14:16:00.000Z","suspendTime":"2020-02-02T14:16:00.000Z","bspReconciled":false,"complete":true,"inPlay":false,"crossMatching":false,"runnersVoidable":false,"numberOfActiveRunners":4,"betDelay":0,"status":"OPEN","runners":[{"status":"ACTIVE","sortPriority":1,"id":13117353,"name":"Moriya 2-0"},{"status":"ACTIVE","sortPriority":2,"id":13117354,"name":"Moriya 2-1"},{"status":"ACTIVE","sortPriority":3,"id":16604346,"name":"Petrovic 2-0"},{"status":"ACTIVE","sortPriority":4,"id":16604347,"name":"Petrovic 2-1"}],"regulators":["MR_INT"],"countryCode":"FR","discountAllowed":true,"timezone":"UTC","openDate":"2020-02-02T14:48:00.000Z","version":3148684763,"name":"Set Betting","eventName":"Moriya v Petrovic"}}]}
{"op":"mcm","clk":"1002676782","pt":1580645817903,"mc":[{"id":"1.168224467","marketDefinition":{"bspMarket":false,"turnInPlayEnabled":true,"persistenceEnabled":true,"marketBaseRate":5.0,"eventId":"29681747","eventTypeId":"2","numberOfWinners":1,"bettingType":"ODDS","marketType":"SET_BETTING","marketTime":"2020-02-02T14:16:00.000Z","suspendTime":"2020-02-02T14:16:00.000Z","bspReconciled":false,"complete":true,"inPlay":false,"crossMatching":false,"runnersVoidable":false,"numberOfActiveRunners":4,"betDelay":0,"status":"OPEN","runners":[{"status":"ACTIVE","sortPriority":1,"id":13117353,"name":"Moriya 2-0"},{"status":"ACTIVE","sortPriority":2,"id":13117354,"name":"Moriya 2-1"},{"status":"ACTIVE","sortPriority":3,"id":16604346,"name":"Petrovic 2-0"},{"status":"ACTIVE","sortPriority":4,"id":16604347,"name":"Petrovic 2-1"}],"regulators":["MR_INT"],"countryCode":"FR","discountAllowed":true,"timezone":"UTC","openDate":"2020-02-02T14:16:00.000Z","version":3148684763,"name":"Set Betting","eventName":"Moriya v Petrovic"}}]}
{"op":"mcm","clk":"1003808359","pt":1580652114770,"mc":[{"id":"1.168224467","marketDefinition":{"bspMarket":false,"turnInPlayEnabled":true,"persistenceEnabled":true,"marketBaseRate":5.0,"eventId":"29681747","eventTypeId":"2","numberOfWinners":1,"bettingType":"ODDS","marketType":"SET_BETTING","marketTime":"2020-02-02T14:06:00.000Z","suspendTime":"2020-02-02T14:06:00.000Z","bspReconciled":false,"complete":true,"inPlay":false,"crossMatching":false,"runnersVoidable":false,"numberOfActiveRunners":4,"betDelay":0,"status":"OPEN","runners":[{"status":"ACTIVE","sortPriority":1,"id":13117353,"name":"Moriya 2-0"},{"status":"ACTIVE","sortPriority":2,"id":13117354,"name":"Moriya 2-1"},{"status":"ACTIVE","sortPriority":3,"id":16604346,"name":"Petrovic 2-0"},{"status":"ACTIVE","sortPriority":4,"id":16604347,"name":"Petrovic 2-1"}],"regulators":["MR_INT"],"countryCode":"FR","discountAllowed":true,"timezone":"UTC","openDate":"2020-02-02T14:16:00.000Z","version":3149081984,"name":"Set Betting","eventName":"Moriya v Petrovic"}}]}
{"op":"mcm","clk":"1003809195","pt":1580652118802,"mc":[{"id":"1.168224467","marketDefinition":{"bspMarket":false,"turnInPlayEnabled":true,"persistenceEnabled":true,"marketBaseRate":5.0,"eventId":"29681747","eventTypeId":"2","numberOfWinners":1,"bettingType":"ODDS","marketType":"SET_BETTING","marketTime":"2020-02-02T14:06:00.000Z","suspendTime":"2020-02-02T14:06:00.000Z","bspReconciled":false,"complete":true,"inPlay":false,"crossMatching":false,"runnersVoidable":false,"numberOfActiveRunners":4,"betDelay":0,"status":"OPEN","runners":[{"status":"ACTIVE","sortPriority":1,"id":13117353,"name":"Moriya 2-0"},{"status":"ACTIVE","sortPriority":2,"id":13117354,"name":"Moriya 2-1"},{"status":"ACTIVE","sortPriority":3,"id":16604346,"name":"Petrovic 2-0"},{"status":"ACTIVE","sortPriority":4,"id":16604347,"name":"Petrovic 2-1"}],"regulators":["MR_INT"],"countryCode":"FR","discountAllowed":true,"timezone":"UTC","openDate":"2020-02-02T14:06:00.000Z","version":3149081984,"name":"Set Betting","eventName":"Moriya v Petrovic"}}]}
{"op":"mcm","clk":"1003845478","pt":1580652277851,"mc":[{"id":"1.168224467","rc":[{"batb":[[0,3.15,20.14],[1,1.02,2],[2,1.01,1.01]],"batl":[[0,3.55,19.43]],"ltp":0.0,"tv":0.0,"id":13117353},{"batb":[[0,4.6,15.74],[1,1.02,2],[2,1.01,1.01]],"batl":[[0,5.4,15.03]],"ltp":0.0,"tv":0.0,"id":16604347},{"batb":[[0,3.15,20.14],[1,1.02,2],[2,1.01,1.01]],"batl":[[0,3.55,19.43]],"ltp":0.0,"tv":0.0,"id":16604346},{"batb":[[0,4.6,15.74],[1,1.02,2],[2,1.01,1.01]],"batl":[[0,5.4,15.03]],"ltp":0.0,"tv":0.0,"id":13117354}]}]}
{"op":"mcm","clk":"1003845870","pt":1580652279451,"mc":[{"id":"1.168224467","rc":[{"batb":[[1,2.02,16.74],[2,1.02,2]],"ltp":0.0,"tv":0.0,"id":13117353},{"batb":[[1,2.38,15.96],[2,1.02,2]],"ltp":0.0,"tv":0.0,"id":16604347},{"batb":[[1,1.8,18.58],[2,1.02,2]],"ltp":0.0,"tv":0.0,"id":16604346},{"batb":[[1,2.08,18.56],[2,1.02,2]],"ltp":0.0,"tv":0.0,"id":13117354}]}]}
{"op":"mcm","clk":"1003847364","pt":1580652285911,"mc":[{"id":"1.168224467","marketDefinition":{"bspMarket":false,"turnInPlayEnabled":true,"persistenceEnabled":true,"marketBaseRate":5.0,"eventId":"29681747","eventTypeId":"2","numberOfWinners":1,"bettingType":"ODDS","marketType":"SET_BETTING","marketTime":"2020-02-02T14:06:00.000Z","suspendTime":"2020-02-02T14:06:00.000Z","bspReconciled":false,"complete":true,"inPlay":false,"crossMatching":true,"runnersVoidable":false,"numberOfActiveRunners":4,"betDelay":0,"status":"OPEN","runners":[{"status":"ACTIVE","sortPriority":1,"id":13117353,"name":"Moriya 2-0"},{"status":"ACTIVE","sortPriority":2,"id":13117354,"name":"Moriya 2-1"},{"status":"ACTIVE","sortPriority":3,"id":16604346,"name":"Petrovic 2-0"},{"status":"ACTIVE","sortPriority":4,"id":16604347,"name":"Petrovic 2-1"}],"regulators":["MR_INT"],"countryCode":"FR","discountAllowed":true,"timezone":"UTC","openDate":"2020-02-02T14:06:00.000Z","version":3149081984,"name":"Set Betting","eventName":"Moriya v Petrovic"}}]}
{"op":"mcm","clk":"1003878607","pt":1580652413628,"mc":[{"id":"1.168224467","marketDefinition":{"bspMarket":false,"turnInPlayEnabled":true,"persistenceEnabled":true,"marketBaseRate":5.0,"eventId":"29681747","eventTypeId":"2","numberOfWinners":1,"bettingType":"ODDS","marketType":"SET_BETTING","marketTime":"2020-02-02T14:03:00.000Z","suspendTime":"2020-02-02T14:03:00.000Z","bspReconciled":false,"complete":true,"inPlay":false,"crossMatching":true,"runnersVoidable":false,"numberOfActiveRunners":4,"betDelay":0,"status":"OPEN","runners":[{"status":"ACTIVE","sortPriority":1,"id":13117353,"name":"Moriya 2-0"},{"status":"ACTIVE","sortPriority":2,"id":13117354,"name":"Moriya 2-1"},{"status":"ACTIVE","sortPriority":3,"id":16604346,"name":"Petrovic 2-0"},{"status":"ACTIVE","sortPriority":4,"id":16604347,"name":"Petrovic 2-1"}],"regulators":["MR_INT"],"countryCode":"FR","discountAllowed":true,"timezone":"UTC","openDate":"2020-02-02T14:06:00.000Z","version":3149117369,"name":"Set Betting","eventName":"Moriya v Petrovic"}}]}
{"op":"mcm","clk":"1003878930","pt":1580652414770,"mc":[{"id":"1.168224467","rc":[{"batb":[[1,1.02,2],[2,1.01,1.01]],"ltp":0.0,"tv":0.0,"id":13117353},{"batb":[[1,1.02,2],[2,1.01,1.01]],"ltp":0.0,"tv":0.0,"id":16604347},{"batb":[[1,1.02,2],[2,1.01,1.01]],"ltp":0.0,"tv":0.0,"id":16604346},{"batb":[[1,1.02,2],[2,1.01,1.01]],"ltp":0.0,"tv":0.0,"id":13117354}]}]}
{"op":"mcm","clk":"1003879387","pt":1580652416642,"mc":[{"id":"1.168224467","marketDefinition":{"bspMarket":false,"turnInPlayEnabled":true,"persistenceEnabled":true,"marketBaseRate":5.0,"eventId":"29681747","eventTypeId":"2","numberOfWinners":1,"bettingType":"ODDS","marketType":"SET_BETTING","marketTime":"2020-02-02T14:03:00.000Z","suspendTime":"2020-02-02T14:03:00.000Z","bspReconciled":false,"complete":true,"inPlay":false,"crossMatching":true,"runnersVoidable":false,"numberOfActiveRunners":4,"betDelay":0,"status":"OPEN","runners":[{"status":"ACTIVE","sortPriority":1,"id":13117353,"name":"Moriya 2-0"},{"status":"ACTIVE","sortPriority":2,"id":13117354,"name":"Moriya 2-1"},{"status":"ACTIVE","sortPriority":3,"id":16604346,"name":"Petrovic 2-0"},{"status":"ACTIVE","sortPriority":4,"id":16604347,"name":"Petrovic 2-1"}],"regulators":["MR_INT"],"countryCode":"FR","discountAllowed":true,"timezone":"UTC","openDate":"2020-02-02T14:03:00.000Z","version":3149117369,"name":"Set Betting","eventName":"Moriya v Petrovic"}}]}
{"op":"mcm","clk":"1003930605","pt":1580652610576,"mc":[{"id":"1.168224467","rc":[{"batb":[[0,3.15,39.47]],"batl":[[1,3.65,15.12]],"ltp":0.0,"tv":0.0,"id":13117353},{"batb":[[1,4.5,11.76],[2,1.02,2]],"batl":[[0,5.4,24.27]],"ltp":0.0,"tv":0.0,"id":16604347},{"batb":[[1,3.05,20.16],[2,1.02,2]],"batl":[[0,3.55,35.4]],"ltp":0.0,"tv":0.0,"id":16604346},{"batb":[[0,4.6,26.66]],"batl":[[1,5.5,9.24]],"ltp":0.0,"tv":0.0,"id":13117354}]}]}
{"op":"mcm","clk":"1003995124","pt":1580652868100,"mc":[{"id":"1.168224467","rc":[{"batb":[[0,3.15,19.32]],"batl":[[0,3.65,15.12],[1,3.65,0]],"ltp":0.0,"tv":0.0,"id":13117353},{"batb":[[0,4.5,11.76],[1,1.02,2],[2,1.01,1.01]],"batl":[[0,5.4,9.24]],"ltp":0.0,"tv":0.0,"id":16604347},{"batb":[[0,3.05,20.16],[1,1.02,2],[2,1.01,1.01]],"batl":[[0,3.55,15.96]],"ltp":0.0,"tv":0.0,"id":16604346},{"batb":[[0,4.6,10.92]],"batl":[[0,5.5,9.24],[1,5.5,0]],"ltp":0.0,"tv":0.0,"id":13117354}]}]}
{"op":"mcm","clk":"1003995312","pt":1580652868929,"mc":[{"id":"1.168224467","marketDefinition":{"bspMarket":false,"turnInPlayEnabled":true,"persistenceEnabled":true,"marketBaseRate":5.0,"eventId":"29681747","eventTypeId":"2","numberOfWinners":1,"bettingType":"ODDS","marketType":"SET_BETTING","marketTime":"2020-02-02T14:03:00.000Z","suspendTime":"2020-02-02T14:03:00.000Z","bspReconciled":false,"complete":true,"inPlay":true,"crossMatching":true,"runnersVoidable":false,"numberOfActiveRunners":4,"betDelay":3,"status":"OPEN","runners":[{"status":"ACTIVE","sortPriority":1,"id":13117353,"name":"Moriya 2-0"},{"status":"ACTIVE","sortPriority":2,"id":13117354,"name":"Moriya 2-1"},{"status":"ACTIVE","sortPriority":3,"id":16604346,"name":"Petrovic 2-0"},{"status":"ACTIVE","sortPriority":4,"id":16604347,"name":"Petrovic 2-1"}],"regulators":["MR_INT"],"countryCode":"FR","discountAllowed":true,"timezone":"UTC","openDate":"2020-02-02T14:03:00.000Z","version":3149153469,"name":"Set Betting","eventName":"Moriya v Petrovic"},"rc":[{"batb":[[0,1.01,0.51],[1,1.02,0],[2,1.01,0]],"ltp":0.0,"tv":0.0,"id":13117353},{"batb":[[0,1.01,0.51],[1,1.02,0],[2,1.01,0]],"ltp":0.0,"tv":0.0,"id":16604347},{"batb":[[0,1.01,0.51],[1,1.02,0],[2,1.01,0]],"ltp":0.0,"tv":0.0,"id":16604346},{"batb":[[0,1.01,0.51],[1,1.02,0],[2,1.01,0]],"ltp":0.0,"tv":0.0,"id":13117354}]}]}
{"op":"mcm","clk":"1003996528","pt":1580652874416,"mc":[{"id":"1.168224467","rc":[{"batb":[[0,3.05,25.53],[1,3,27.2],[2,1.01,0.51]],"ltp":0.0,"tv":0.0,"id":13117353},{"batb":[[0,4.8,11.75],[1,4.7,18.53],[2,1.01,0.51]],"ltp":0.0,"tv":0.0,"id":16604347},{"batb":[[0,2.86,29.6],[1,2.82,25.53],[2,1.01,0.51]],"ltp":0.0,"tv":0.0,"id":16604346},{"batb":[[0,4.9,10.89],[1,4.8,17.68],[2,1.01,0.51]],"ltp":0.0,"tv":0.0,"id":13117354}]}]}
{"op":"mcm","clk":"1003998571","pt":1580652883113,"mc":[{"id":"1.168224467","rc":[{"batb":[[0,1.01,0.51],[1,2.82,0],[2,1.01,0]],"ltp":0.0,"tv":0.0,"id":16604346}]}]}
{"op":"mcm","clk":"1003999222","pt":1580652885932,"mc":[{"id":"1.168224467","rc":[{"batb":[[0,3.4,22.99],[1,3.35,20.69],[2,1.01,0.51]],"ltp":0.0,"tv":0.0,"id":16604346}]}]}
{"op":"mcm","clk":"1003999414","pt":1580652886808,"mc":[{"id":"1.168224467","rc":[{"batb":[[2,2.96,23.92]],"batl":[[0,3.3,22.98],[1,3.65,18.1]],"ltp":0.0,"tv":0.0,"id":13117353},{"batb":[[2,4.6,16.21]],"batl":[[0,5.4,15.11],[1,5.5,14.79]],"ltp":0.0,"tv":0.0,"id":16604347},{"batb":[[0,3.4,39.91],[2,3.1,21.4]],"batl":[[0,3.8,16.37],[1,4.1,14.08]],"ltp":0.0,"tv":0.0,"id":16604346},{"batb":[[2,4.6,15.74]],"batl":[[0,5.4,14.79]],"ltp":0.0,"tv":0.0,"id":13117354}]}]}
{"op":"mcm","clk":"1003999649","pt":1580652887845,"mc":[{"id":"1.168224467","rc":[{"batb":[[1,3,48.2]],"batl":[[1,3.5,16.8],[2,3.65,18.1]],"ltp":0.0,"tv":0.0,"id":13117353},{"batl":[[0,5.4,24.35]],"ltp":0.0,"tv":0.0,"id":16604347},{"batb":[[2,3.2,18.48]],"batl":[[0,3.8,30.65]],"ltp":0.0,"tv":0.0,"id":16604346},{"batl":[[1,5.5,9.24]],"ltp":0.0,"tv":0.0,"id":13117354}]}]}
{"op":"mcm","clk":"1004001743","pt":1580652897034,"mc":[{"id":"1.168224467","rc":[{"batb":[[0,4.7,18.53],[1,4.6,16.21],[2,4.5,11.76]],"ltp":0.0,"tv":0.0,"id":16604347}]}]}
{"op":"mcm","clk":"1004002205","pt":1580652899144,"mc":[{"id":"1.168224467","rc":[{"batb":[[0,2.84,10.7],[1,1.01,0.51],[2,2.96,0]],"batl":[[0,3.65,18.1],[1,3.5,0],[2,3.65,0]],"ltp":0.0,"tv":0.0,"id":13117353},{"batb":[[2,1.01,0.51]],"batl":[[0,5.5,14.79],[1,5.5,0]],"ltp":0.0,"tv":0.0,"id":16604347},{"batb":[[0,3.1,21.4],[1,1.01,0.51],[2,3.2,0]],"batl":[[0,4.1,14.08],[1,4.1,0]],"ltp":0.0,"tv":0.0,"id":16604346},{"batl":[[1,5.5,0]],"ltp":0.0,"tv":0.0,"id":13117354}]}]}
{"op":"mcm","clk":"1004002410","pt":1580652899961,"mc":[{"id":"1.168224467","rc":[{"batb":[[0,4.7,28.45],[1,4.6,35.37]],"ltp":0.0,"tv":0.0,"id":16604347}]}]}
{"op":"mcm","clk":"1004002767","pt":1580652901545,"mc":[{"id":"1.168224467","rc":[{"batb":[[0,2.92,24.88],[1,2.88,24.25],[2,2.84,10.7]],"ltp":0.0,"tv":0.0,"id":13117353},{"batb":[[0,3.1,41.85],[1,3.05,26.1],[2,1.01,0.51]],"ltp":0.0,"tv":0.0,"id":16604346}]}]}
{"op":"mcm","clk":"1004005663","pt":1580652914435,"mc":[{"id":"1.168224467","rc":[{"batb":[[0,3.1,21.4],[1,1.01,0.51],[2,1.01,0]],"ltp":0.0,"tv":0.0,"id":16604346}]}]}
{"op":"mcm","clk":"1004006235","pt":1580652917326,"mc":[{"id":"1.168224467","rc":[{"batb":[[0,3.6,17.21],[1,3.55,17.99],[2,3.1,21.4]],"ltp":0.0,"tv":0.0,"id":16604346}]}]}
{"op":"mcm","clk":"1004006474","pt":1580652918339,"mc":[{"id":"1.168224467","rc":[{"batb":[[2,2.86,21.85]],"batl":[[0,3.1,10.46],[1,3.35,39.52]],"ltp":0.0,"tv":0.0,"id":13117353},{"batb":[[2,4.5,11.76]],"batl":[[0,5.3,15.34],[1,5.5,9.24]],"ltp":0.0,"tv":0.0,"id":16604347},{"batb":[[0,3.6,31.77],[2,3.35,35.27]],"batl":[[0,4,13.44],[1,4.1,14.08],[2,4.3,24.63]],"ltp":0.0,"tv":0.0,"id":16604346},{"batb":[[2,4.7,15.5]],"batl":[[0,5.4,9.24],[1,5.5,14.71]],"ltp":0.0,"tv":0.0,"id":13117354}]}]}
{"op":"mcm","clk":"1004008663","pt":1580652928350,"mc":[{"id":"1.168224467","rc":[{"batb":[[0,2.86,21.85],[1,2.72,11.88],[2,1.01,0.51]],"batl":[[0,3.35,39.52],[1,3.35,0]],"ltp":0.0,"tv":0.0,"id":13117353},{"batb":[[0,3.35,35.27],[1,1.01,0.51],[2,3.35,0]],"batl":[[1,4.3,24.63],[2,4.3,0]],"ltp":0.0,"tv":0.0,"id":16604346}]}]}
{"op":"mcm","clk":"1004008778","pt":1580652928853,"mc":[{"id":"1.168224467","rc":[{"batb":[[0,2.72,11.88],[1,1.01,0.51],[2,1.01,0]],"batl":[[0,3.35,21.87]],"ltp":0.0,"tv":0.0,"id":13117353},{"batb":[[2,1.01,0.51]],"batl":[[1,5.5,0]],"ltp":0.0,"tv":0.0,"id":16604347},{"batb":[[0,3.35,17.62]],"batl":[[0,4.3,24.63],[1,4.3,0]],"ltp":0.0,"tv":0.0,"id":16604346},{"batl":[[0,5.5,14.71],[1,5.5,0]],"ltp":0.0,"tv":0.0,"id":13117354}]}]}
{"op":"mcm","clk":"1004008970","pt":1580652929738,"mc":[{"id":"1.168224467","rc":[{"batb":[[0,4.9,14.56]],"ltp":0.0,"tv":0.0,"id":13117354}]}]}
{"op":"mcm","clk":"1004009306","pt":1580652931266,"mc":[{"id":"1.168224467","rc":[{"batb":[[0,2.84,18.66],[1,2.8,26.12],[2,2.72,11.88]],"ltp":0.0,"tv":0.0,"id":13117353},{"batb":[[0,3.35,35.72],[1,3.3,21.47],[2,1.01,0.51]],"ltp":0.0,"tv":0.0,"id":16604346}]}]}
{"op":"mcm","clk":"1004009478","pt":1580652931996,"mc":[{"id":"1.168224467","rc":[{"batb":[[0,3.35,18.1],[1,3.3,39.17]],"ltp":0.0,"tv":0.0,"id":16604346}]}]}
{"op":"mcm","clk":"1004010101","pt":1580652934707,"mc":[{"id":"1.168224467","rc":[{"batb":[[0,3.3,17.7],[1,1.01,0.51],[2,1.01,0]],"ltp":0.0,"tv":0.0,"id":16604346}]}]}
{"op":"mcm","clk":"1004010942","pt":1580652938298,"mc":[{"id":"1.168224467","rc":[{"batb":[[2,2.78,23.53]],"batl":[[0,2.98,11.64],[1,3.15,25.57],[2,3.2,18.48]],"ltp":0.0,"tv":0.0,"id":13117353},{"batb":[[1,4.6,46.29]],"batl":[[1,5.5,9.24]],"ltp":0.0,"tv":0.0,"id":16604347},{"batb":[[0,3.75,29.37],[1,3.7,16.29],[2,3.55,15.03]],"batl":[[0,4.1,13.44],[1,4.3,24.63],[2,4.5,22.82]],"ltp":0.0,"tv":0.0,"id":16604346},{"batl":[[0,5.4,9.24],[1,5.5,14.71]],"ltp":0.0,"tv":0.0,"id":13117354}]}]}
{"op":"mcm","clk":"1004013959","pt":1580652952893,"mc":[{"id":"1.168224467","rc":[{"batb":[[0,2.78,23.53],[1,2.66,12.67],[2,1.01,0.51]],"batl":[[0,3.15,25.57],[1,3.2,18.48],[2,3.2,0]],"ltp":0.0,"tv":0.0,"id":13117353},{"batb":[[0,4.7,22.62]],"ltp":0.0,"tv":0.0,"id":16604347},{"batb":[[0,3.55,15.03],[1,3.5,16.8],[2,1.01,0.51]],"batl":[[1,4.5,22.82],[2,4.5,0]],"ltp":0.0,"tv":0.0,"id":16604346},{"batb":[[2,4.7,15.34]],"batl":[[1,5.5,14.56]],"ltp":0.0,"tv":0.0,"id":13117354}]}]}
{"op":"mcm","clk":"1004014456","pt":1580652955300,"mc":[{"id":"1.168224467","rc":[{"batb":[[0,2.66,12.67],[1,1.01,0.51],[2,1.01,0]],"batl":[[1,3.2,0]],"ltp":0.0,"tv":0.0,"id":13117353},{"batb":[[1,4.6,35.37]],"batl":[[1,5.5,0]],"ltp":0.0,"tv":0.0,"id":16604347},{"batb":[[1,1.01,0.51],[2,1.01,0]],"batl":[[0,4.5,22.82],[1,4.5,0]],"ltp":0.0,"tv":0.0,"id":16604346},{"batl":[[0,5.5,14.56],[1,5.5,0]],"ltp":0.0,"tv":0.0,"id":13117354}]}]}
{"op":"mcm","clk":"1004014609","pt":1580652956004,"mc":[{"id":"1.168224467","rc":[{"batb":[[0,2.78,20.43],[1,2.74,27.61],[2,2.66,12.67]],"ltp":0.0,"tv":0.0,"id":13117353},{"batb":[[0,3.55,40.51],[1,3.5,18.54],[2,1.01,0.51]],"ltp":0.0,"tv":0.0,"id":16604346}]}]}
{"op":"mcm","clk":"1004016287","pt":1580652964100,"mc":[{"id":"1.168224467","rc":[{"batb":[[0,2.66,12.67],[1,1.01,0.51],[2,2.66,0]],"ltp":0.0,"tv":0.0,"id":13117353}]}]}
{"op":"mcm","clk":"1004017005","pt":1580652967282,"mc":[{"id":"1.168224467","rc":[{"batb":[[0,2.94,26.11],[1,2.9,23.83],[2,2.86,10.39]],"batl":[[1,3.4,21.17]],"ltp":0.0,"tv":0.0,"id":13117353},{"batb":[[2,3.25,18.41]],"batl":[[0,4,14.63],[1,4.2,12.98],[2,4.5,22.82]],"ltp":0.0,"tv":0.0,"id":16604346}]}]}
{"op":"mcm","clk":"1004017211","pt":1580652968291,"mc":[{"id":"1.168224467","rc":[{"batb":[[1,2.92,21.85],[2,2.9,23.83]],"batl":[[1,3.35,17.64],[2,3.4,21.17]],"ltp":0.0,"tv":0.0,"id":13117353},{"batb":[[2,4.5,11.76]],"batl":[[1,5.4,9.24]],"ltp":0.0,"tv":0.0,"id":16604347},{"batb":[[2,3.35,17.64]],"batl":[[0,3.95,13.44],[1,4,14.63],[2,4.2,12.98]],"ltp":0.0,"tv":0.0,"id":16604346},{"batl":[[0,5.5,23.8]],"ltp":0.0,"tv":0.0,"id":13117354}]}]}
{"op":"mcm","clk":"1004020624","pt":1580652983734,"mc":[{"id":"1.168224467","rc":[{"batb":[[0,2.92,21.85],[1,2.76,11.41],[2,1.01,0.51]],"batl":[[0,3.35,17.64],[1,3.4,21.17],[2,3.4,0]],"ltp":0.0,"tv":0.0,"id":13117353},{"batb":[[0,3.35,17.64],[1,3.25,18.41],[2,1.01,0.51]],"batl":[[1,4.2,12.98],[2,4.2,0]],"ltp":0.0,"tv":0.0,"id":16604346}]}]}
{"op":"mcm","clk":"1004020868","pt":1580652984837,"mc":[{"id":"1.168224467","rc":[{"batb":[[0,2.76,11.41],[1,1.01,0.51],[2,1.01,0]],"batl":[[0,3.4,21.17],[1,3.4,0]],"ltp":0.0,"tv":0.0,"id":13117353},{"batb":[[2,1.01,0.51]],"batl":[[1,5.4,0]],"ltp":0.0,"tv":0.0,"id":16604347},{"batb":[[0,3.25,18.41],[1,1.01,0.51],[2,1.01,0]],"batl":[[0,4.2,12.98],[1,4.2,0]],"ltp":0.0,"tv":0.0,"id":16604346},{"batl":[[0,5.5,14.56]],"ltp":0.0,"tv":0.0,"id":13117354}]}]}
{"op":"mcm","clk":"1004021210","pt":1580652986525,"mc":[{"id":"1.168224467","rc":[{"batb":[[0,2.86,18.84],[1,2.82,25.64],[2,2.76,11.41]],"ltp":0.0,"tv":0.0,"id":13117353},{"batb":[[0,3.3,35.11],[1,3.25,40.56],[2,1.01,0.51]],"ltp":0.0,"tv":0.0,"id":16604346}]}]}
{"op":"mcm","clk":"1004021771","pt":1580652989251,"mc":[{"id":"1.168224467","rc":[{"batb":[[0,2.76,11.41],[1,1.01,0.51],[2,2.76,0]],"ltp":0.0,"tv":0.0,"id":13117353},{"batb":[[0,3.25,18.41],[1,1.01,0.51],[2,1.01,0]],"ltp":0.0,"tv":0.0,"id":16604346}]}]}
{"op":"mcm","clk":"1004022916","pt":1580652994361,"mc":[{"id":"1.168224467","rc":[{"batb":[[0,2.86,18.84],[1,2.82,25.64],[2,2.76,11.41]],"ltp":0.0,"tv":0.0,"id":13117353},{"batb":[[0,3.3,35.11],[1,3.25,40.56],[2,1.01,0.51]],"ltp":0.0,"tv":0.0,"id":16604346}]}]}
{"op":"mcm","clk":"1004024700","pt":1580653002881,"mc":[{"id":"1.168224467","rc":[{"batb":[[0,3.25,18.41],[1,1.01,0.51],[2,1.01,0]],"ltp":0.0,"tv":0.0,"id":16604346}]}]}
{"op":"mcm","clk":"1004025405","pt":1580653006239,"mc":[{"id":"1.168224467","rc":[{"batb":[[0,3.7,23.6],[1,3.65,16.77],[2,3.25,18.41]],"ltp":0.0,"tv":0.0,"id":16604346}]}]}
{"op":"mcm","clk":"1004025508","pt":1580653006784,"mc":[{"id":"1.168224467","rc":[{"batl":[[0,3.05,11.17],[1,3.25,23.76]],"ltp":0.0,"tv":0.0,"id":13117353},{"batb":[[1,4.6,19.16],[2,4.5,16.44]],"ltp":0.0,"tv":0.0,"id":16604347},{"batb":[[0,3.75,13.38],[1,3.7,23.6],[2,3.65,16.77]],"batl":[[1,4.9,18.8]],"ltp":0.0,"tv":0.0,"id":16604346},{"batb":[[2,4.6,15.66]],"batl":[[0,5.5,14.24]],"ltp":0.0,"tv":0.0,"id":13117354}]}]}
{"op":"mcm","clk":"1004025720","pt":1580653007778,"mc":[{"id":"1.168224467","rc":[{"batb":[[2,2.76,34.93]],"batl":[[1,3.2,18.48],[2,3.25,23.76]],"ltp":0.0,"tv":0.0,"id":13117353},{"batb":[[2,4.5,28.21]],"batl":[[1,5.4,9.24]],"ltp":0.0,"tv":0.0,"id":16604347},{"batl":[[0,4.2,25.59]],"ltp":0.0,"tv":0.0,"id":16604346},{"batl":[[0,5.4,9.24],[1,5.5,14.24]],"ltp":0.0,"tv":0.0,"id":13117354}]}]}
{"op":"mcm","clk":"1004032856","pt":1580653042973,"mc":[{"id":"1.168224467","rc":[{"batb":[[0,2.76,34.93],[1,2.52,14.56],[2,1.01,0.51]],"ltp":0.0,"tv":0.0,"id":13117353},{"batb":[[1,3.5,16.8],[2,3.45,15.89]],"ltp":0.0,"tv":0.0,"id":16604346}]}]}
{"op":"mcm","clk":"1004033067","pt":1580653044170,"mc":[{"id":"1.168224467","rc":[{"batb":[[0,2.76,23.53]],"batl":[[0,3.2,18.48],[1,3.25,23.76],[2,3.25,0]],"ltp":0.0,"tv":0.0,"id":13117353},{"batb":[[0,3.5,16.8],[1,3.45,15.89],[2,1.01,0.51]],"batl":[[0,4.2,12.6]],"ltp":0.0,"tv":0.0,"id":16604346}]}]}
{"op":"mcm","clk":"1004033195","pt":1580653044936,"mc":[{"id":"1.168224467","rc":[{"batb":[[0,2.52,14.56],[1,1.01,0.51],[2,1.01,0]],"batl":[[0,3.25,23.76],[1,3.25,0]],"ltp":0.0,"tv":0.0,"id":13117353},{"batb":[[2,4.5,16.44]],"batl":[[1,5.4,0]],"ltp":0.0,"tv":0.0,"id":16604347},{"batb":[[0,3.45,15.89],[1,1.01,0.51],[2,1.01,0]],"batl":[[0,4.9,18.8],[1,4.9,0]],"ltp":0.0,"tv":0.0,"id":16604346},{"batl":[[0,5.5,14.24],[1,5.5,0]],"ltp":0.0,"tv":0.0,"id":13117354}]}]}
{"op":"mcm","clk":"1004033385","pt":1580653045976,"mc":[{"id":"1.168224467","rc":[{"batb":[[0,2.58,35.37],[1,2.54,33.61],[2,2.52,14.56]],"ltp":0.0,"tv":0.0,"id":13117353},{"batb":[[0,3.45,40.35],[1,3.4,19.91],[2,1.01,0.51]],"ltp":0.0,"tv":0.0,"id":16604346}]}]}
{"op":"mcm","clk":"1004034153","pt":1580653049899,"mc":[{"id":"1.168224467","rc":[{"batb":[[0,2.52,14.56],[1,1.01,0.51],[2,2.52,0]],"ltp":0.0,"tv":0.0,"id":13117353}]}]}
{"op":"mcm","clk":"1004034768","pt":1580653053200,"mc":[{"id":"1.168224467","rc":[{"batb":[[0,3,38.08],[1,2.96,22.52],[2,2.52,14.56]],"ltp":0.0,"tv":0.0,"id":13117353}]}]}
{"op":"mcm","clk":"1004034904","pt":1580653053905,"mc":[{"id":"1.168224467","rc":[{"batb":[[2,2.92,24.71]],"batl":[[1,3.4,16.8],[2,3.45,20.46]],"ltp":0.0,"tv":0.0,"id":13117353},{"batb":[[1,4.6,35.53],[2,4.5,11.76]],"batl":[[1,5.4,9.24]],"ltp":0.0,"tv":0.0,"id":16604347},{"batb":[[2,3.35,17.64]],"batl":[[0,3.9,15.42],[1,3.95,13.44],[2,4.4,23.6]],"ltp":0.0,"tv":0.0,"id":16604346},{"batl":[[0,5.4,9.24],[1,5.5,14.24]],"ltp":0.0,"tv":0.0,"id":13117354}]}]}
{"op":"mcm","clk":"1004036734","pt":1580653062941,"mc":[{"id":"1.168224467","rc":[{"batb":[[0,2.7,12.2],[1,1.01,0.51],[2,2.92,0]],"batl":[[0,3.45,20.46],[1,3.4,0],[2,3.45,0]],"ltp":0.0,"tv":0.0,"id":13117353},{"batb":[[2,1.01,0.51]],"batl":[[1,5.4,0]],"ltp":0.0,"tv":0.0,"id":16604347},{"batb":[[0,3.25,18.65],[1,1.01,0.51],[2,3.35,0]],"batl":[[0,4.4,23.6],[1,3.95,0],[2,4.4,0]],"ltp":0.0,"tv":0.0,"id":16604346},{"batb":[[0,4.9,10.89]],"batl":[[0,5.5,14.24],[1,5.5,0]],"ltp":0.0,"tv":0.0,"id":13117354}]}]}
{"op":"mcm","clk":"1004038454","pt":1580653072314,"mc":[{"id":"1.168224467","rc":[{"batb":[[0,2.78,25.91],[1,2.74,27.57],[2,2.7,12.2]],"ltp":0.0,"tv":0.0,"id":13117353},{"batb":[[0,3.25,53.59],[1,3.2,23.02],[2,1.01,0.51]],"ltp":0.0,"tv":0.0,"id":16604346}]}]}
{"op":"mcm","clk":"1004039393","pt":1580653077124,"mc":[{"id":"1.168224467","rc":[{"batb":[[0,3.25,18.65],[1,1.01,0.51],[2,1.01,0]],"ltp":0.0,"tv":0.0,"id":16604346}]}]}
{"op":"mcm","clk":"1004039962","pt":1580653080031,"mc":[{"id":"1.168224467","rc":[{"batb":[[0,3.85,14.34],[1,3.8,15.31],[2,3.25,18.65]],"ltp":0.0,"tv":0.0,"id":16604346},{"batb":[[0,4.9,14.81]],"ltp":0.0,"tv":0.0,"id":13117354}]}]}
{"op":"mcm","clk":"1004040101","pt":1580653080758,"mc":[{"id":"1.168224467","rc":[{"batl":[[0,2.94,11.96],[1,3.2,24.47]],"ltp":0.0,"tv":0.0,"id":13117353},{"batb":[[1,4.6,19.16],[2,4.5,16.6]],"ltp":0.0,"tv":0.0,"id":16604347},{"batb":[[0,3.85,39.28],[2,3.5,15.42]],"batl":[[1,5.2,16.21]],"ltp":0.0,"tv":0.0,"id":16604346},{"batb":[[2,4.7,15.58]],"batl":[[1,5.6,14.16]],"ltp":0.0,"tv":0.0,"id":13117354}]}]}
{"op":"mcm","clk":"1004040304","pt":1580653081741,"mc":[{"id":"1.168224467","rc":[{"batb":[[1,2.74,51.1]],"batl":[[1,3.15,19.32],[2,3.2,24.47]],"ltp":0.0,"tv":0.0,"id":13117353},{"batb":[[1,4.6,30.08]],"batl":[[1,5.5,9.24]],"ltp":0.0,"tv":0.0,"id":16604347},{"batb":[[2,3.65,15.12]],"batl":[[0,4.3,12.6],[1,4.4,23.6],[2,5.2,16.21]],"ltp":0.0,"tv":0.0,"id":16604346},{"batl":[[0,5.4,9.24],[1,5.5,14.24],[2,5.6,14.16]],"ltp":0.0,"tv":0.0,"id":13117354}]}]}
{"op":"mcm","clk":"1004042518","pt":1580653092874,"mc":[{"id":"1.168224467","rc":[{"batb":[[0,2.44,15.97],[1,1.01,0.51],[2,2.7,0]],"batl":[[0,3.2,24.47],[1,3.15,0],[2,3.2,0]],"ltp":0.0,"tv":0.0,"id":13117353},{"batb":[[1,4.6,19.16]],"batl":[[1,5.5,0]],"ltp":0.0,"tv":0.0,"id":16604347},{"batb":[[0,3.5,15.42],[1,1.01,0.51],[2,3.65,0]],"batl":[[0,5.2,16.21],[1,4.4,0],[2,5.2,0]],"ltp":0.0,"tv":0.0,"id":16604346},{"batb":[[0,4.8,17.68],[1,4.7,15.58],[2,1.01,0.51]],"batl":[[0,5.6,14.16],[1,5.5,0],[2,5.6,0]],"ltp":0.0,"tv":0.0,"id":13117354}]}]}
{"op":"mcm","clk":"1004043031","pt":1580653095799,"mc":[{"id":"1.168224467","rc":[{"batb":[[0,2.48,36.24],[1,2.44,53.43],[2,1.01,0.51]],"ltp":0.0,"tv":0.0,"id":13117353},{"batb":[[0,3.5,40.56],[1,3.45,19.21],[2,1.01,0.51]],"ltp":0.0,"tv":0.0,"id":16604346},{"batb":[[0,4.8,28.25],[1,4.7,33.88]],"ltp":0.0,"tv":0.0,"id":13117354}]}]}
{"op":"mcm","clk":"1004044100","pt":1580653101368,"mc":[{"id":"1.168224467","rc":[{"batb":[[0,2.44,15.97],[1,1.01,0.51],[2,1.01,0]],"ltp":0.0,"tv":0.0,"id":13117353}]}]}
{"op":"mcm","clk":"1004044717","pt":1580653104372,"mc":[{"id":"1.168224467","rc":[{"batb":[[0,2.98,26.93],[1,2.94,22.99],[2,2.44,15.97]],"ltp":0.0,"tv":0.0,"id":13117353}]}]}
{"op":"mcm","clk":"1004044861","pt":1580653105190,"mc":[{"id":"1.168224467","rc":[{"batb":[[2,2.88,25.49]],"batl":[[1,3.4,21.01]],"ltp":0.0,"tv":0.0,"id":13117353},{"batb":[[1,4.6,35.53],[2,1.01,0.51]],"ltp":0.0,"tv":0.0,"id":16604347},{"batb":[[2,3.3,18.18]],"batl":[[0,3.95,14.95],[1,4.6,21.72]],"ltp":0.0,"tv":0.0,"id":16604346},{"batb":[[1,4.7,18.3],[2,4.6,15.74]],"batl":[[0,5.5,14.48]],"ltp":0.0,"tv":0.0,"id":13117354}]}]}
{"op":"mcm","clk":"1004044969","pt":1580653105769,"mc":[{"id":"1.168224467","rc":[{"batl":[[1,3.3,17.64],[2,3.4,21.01]],"ltp":0.0,"tv":0.0,"id":13117353},{"batb":[[1,4.6,46.45]],"batl":[[1,5.5,9.24]],"ltp":0.0,"tv":0.0,"id":16604347},{"batb":[[2,3.4,16.8]],"batl":[[1,4,13.44],[2,4.6,21.72]],"ltp":0.0,"tv":0.0,"id":16604346},{"batl":[[0,5.4,9.24],[1,5.5,14.48]],"ltp":0.0,"tv":0.0,"id":13117354}]}]}
{"op":"mcm","clk":"1004046455","pt":1580653113776,"mc":[{"id":"1.168224467","rc":[{"batb":[[0,2.86,21.85],[1,2.62,13.06],[2,1.01,0.51]],"batl":[[0,3.3,17.64],[1,3.4,21.01],[2,3.4,0]],"ltp":0.0,"tv":0.0,"id":13117353},{"batb":[[0,3.4,16.8],[1,3.3,18.18],[2,1.01,0.51]],"batl":[[0,4,13.44],[1,4.6,21.72],[2,4.6,0]],"ltp":0.0,"tv":0.0,"id":16604346}]}]}
{"op":"mcm","clk":"1004046677","pt":1580653114897,"mc":[{"id":"1.168224467","rc":[{"batb":[[0,2.62,13.06],[1,1.01,0.51],[2,1.01,0]],"batl":[[0,3.4,21.01],[1,3.4,0]],"ltp":0.0,"tv":0.0,"id":13117353},{"batb":[[1,4.6,35.53]],"batl":[[1,5.5,0]],"ltp":0.0,"tv":0.0,"id":16604347},{"batb":[[0,3.3,18.18],[1,1.01,0.51],[2,1.01,0]],"batl":[[0,4.6,21.72],[1,4.6,0]],"ltp":0.0,"tv":0.0,"id":16604346},{"batl":[[0,5.5,14.48],[1,5.5,0]],"ltp":0.0,"tv":0.0,"id":13117354}]}]}
{"op":"mcm","clk":"1004047010","pt":1580653116683,"mc":[{"id":"1.168224467","rc":[{"batb":[[0,2.72,21.11],[1,2.68,29.24],[2,2.62,13.06]],"ltp":0.0,"tv":0.0,"id":13117353},{"batb":[[0,3.3,38.32],[1,3.25,22.28],[2,1.01,0.51]],"ltp":0.0,"tv":0.0,"id":16604346}]}]}
{"op":"mcm","clk":"1004050377","pt":1580653134116,"mc":[{"id":"1.168224467","rc":[{"batb":[[0,2.62,13.06],[1,1.01,0.51],[2,2.62,0]],"ltp":0.0,"tv":0.0,"id":13117353}]}]}
{"op":"mcm","clk":"1004050940","pt":1580653136954,"mc":[{"id":"1.168224467","rc":[{"batb":[[0,3.15,31.05],[1,3.1,25.03],[2,2.62,13.06]],"ltp":0.0,"tv":0.0,"id":13117353}]}]}
{"op":"mcm","clk":"1004051171","pt":1580653138154,"mc":[{"id":"1.168224467","rc":[{"batb":[[2,3.05,21.87]],"batl":[[1,3.5,16.8],[2,3.6,18.8]],"ltp":0.0,"tv":0.0,"id":13117353},{"batb":[[1,4.6,35.37],[2,4.5,11.76]],"batl":[[1,5.4,9.24]],"ltp":0.0,"tv":0.0,"id":16604347},{"batb":[[1,3.25,40.76],[2,3.15,20.46]],"batl":[[0,3.7,17.55],[1,3.8,14.28],[2,4,14.4]],"ltp":0.0,"tv":0.0,"id":16604346},{"batl":[[0,5.4,24.27]],"ltp":0.0,"tv":0.0,"id":13117354}]}]}
{"op":"mcm","clk":"1004052754","pt":1580653146047,"mc":[{"id":"1.168224467","rc":[{"batb":[[0,3,21],[1,2.86,10.39],[2,1.01,0.51]],"batl":[[0,3.5,16.8],[1,3.6,18.8],[2,3.6,0]],"ltp":0.0,"tv":0.0,"id":13117353},{"batb":[[0,3.25,18.48],[1,3.15,20.46],[2,1.01,0.51]],"batl":[[0,3.8,14.28],[1,4,14.4],[2,4,0]],"ltp":0.0,"tv":0.0,"id":16604346}]}]}
{"op":"mcm","clk":"1004052929","pt":1580653146959,"mc":[{"id":"1.168224467","rc":[{"batb":[[0,2.86,10.39],[1,1.01,0.51],[2,1.01,0]],"batl":[[0,3.6,18.8],[1,3.6,0]],"ltp":0.0,"tv":0.0,"id":13117353},{"batb":[[2,1.01,0.51]],"batl":[[1,5.4,0]],"ltp":0.0,"tv":0.0,"id":16604347},{"batb":[[0,3.15,20.46],[1,1.01,0.51],[2,1.01,0]],"batl":[[0,4,14.4],[1,4,0]],"ltp":0.0,"tv":0.0,"id":16604346},{"batl":[[0,5.4,15.03]],"ltp":0.0,"tv":0.0,"id":13117354}]}]}
{"op":"mcm","clk":"1004053330","pt":1580653148988,"mc":[{"id":"1.168224467","rc":[{"batb":[[0,2.98,21.06],[1,2.94,23.04],[2,2.86,10.39]],"ltp":0.0,"tv":0.0,"id":13117353},{"batb":[[0,3.15,58.85],[1,3.1,24.89],[2,1.01,0.51]],"ltp":0.0,"tv":0.0,"id":16604346}]}]}
{"op":"mcm","clk":"1004054119","pt":1580653152786,"mc":[{"id":"1.168224467","rc":[{"batb":[[0,2.86,10.39],[1,1.01,0.51],[2,2.86,0]],"ltp":0.0,"tv":0.0,"id":13117353},{"batb":[[0,3.15,20.46],[1,1.01,0.51],[2,1.01,0]],"ltp":0.0,"tv":0.0,"id":16604346}]}]}
{"op":"mcm","clk":"1004054712","pt":1580653155894,"mc":[{"id":"1.168224467","rc":[{"batb":[[0,4.7,26.91]],"ltp":0.0,"tv":0.0,"id":16604347}]}]}
{"op":"mcm","clk":"1004054993","pt":1580653157353,"mc":[{"id":"1.168224467","rc":[{"batb":[[0,2.98,21.06],[1,2.94,23.04],[2,2.86,10.39]],"ltp":0.0,"tv":0.0,"id":13117353},{"batb":[[0,3.15,58.85],[1,3.1,24.89],[2,1.01,0.51]],"ltp":0.0,"tv":0.0,"id":16604346}]}]}
{"op":"mcm","clk":"1004056731","pt":1580653166301,"mc":[{"id":"1.168224467","rc":[{"batb":[[0,4.7,18.53],[1,4.6,16.21]],"ltp":0.0,"tv":0.0,"id":16604347},{"batb":[[0,3.15,20.46],[1,1.01,0.51],[2,1.01,0]],"ltp":0.0,"tv":0.0,"id":16604346}]}]}
{"op":"mcm","clk":"1004057326","pt":1580653169305,"mc":[{"id":"1.168224467","rc":[{"batb":[[0,4.8,11.44],[1,4.7,18.53],[2,4.6,16.21]],"ltp":0.0,"tv":0.0,"id":16604347},{"batb":[[0,3.5,29.44],[1,3.45,19.17],[2,3.15,20.46]],"ltp":0.0,"tv":0.0,"id":16604346}]}]}
{"op":"mcm","clk":"1004057545","pt":1580653170330,"mc":[{"id":"1.168224467","rc":[{"batb":[[2,2.88,21.85]],"batl":[[0,3.15,25.57],[1,3.3,17.64],[2,3.4,21.17]],"ltp":0.0,"tv":0.0,"id":13117353},{"batb":[[2,4.6,27.13]],"batl":[[0,5.4,15.26],[1,5.5,9.24]],"ltp":0.0,"tv":0.0,"id":16604347},{"batb":[[0,3.55,14.87],[1,3.5,29.44],[2,3.45,35.97]],"batl":[[0,4,27.84],[1,4.7,20.77]],"ltp":0.0,"tv":0.0,"id":16604346},{"batl":[[0,5.3,9.24],[1,5.4,15.03],[2,5.5,14.4]],"ltp":0.0,"tv":0.0,"id":13117354}]}]}
{"op":"mcm","clk":"1004059761","pt":1580653181437,"mc":[{"id":"1.168224467","rc":[{"batb":[[0,2.88,21.85],[1,2.86,10.39],[2,2.58,13.53]],"ltp":0.0,"tv":0.0,"id":13117353},{"batb":[[1,3.45,16.8],[2,3.3,17.94]],"ltp":0.0,"tv":0.0,"id":16604346},{"batb":[[0,4.8,21.63]],"ltp":0.0,"tv":0.0,"id":13117354}]}]}
{"op":"mcm","clk":"1004059778","pt":1580653181543,"mc":[{"id":"1.168224467","rc":[{"batb":[[1,2.58,13.53],[2,1.01,0.51]],"batl":[[0,3.3,17.64],[1,3.4,21.17],[2,3.4,0]],"ltp":0.0,"tv":0.0,"id":13117353},{"batb":[[0,3.45,16.8],[1,3.3,17.94],[2,1.01,0.51]],"batl":[[0,4,13.44]],"ltp":0.0,"tv":0.0,"id":16604346},{"batl":[[1,5.5,14.4],[2,5.5,0]],"ltp":0.0,"tv":0.0,"id":13117354}]}]}
{"op":"mcm","clk":"1004060069","pt":1580653182904,"mc":[{"id":"1.168224467","rc":[{"batb":[[0,2.58,13.53],[1,1.01,0.51],[2,1.01,0]],"batl":[[0,3.4,21.17],[1,3.4,0]],"ltp":0.0,"tv":0.0,"id":13117353},{"batb":[[2,4.6,16.21]],"batl":[[1,5.5,0]],"ltp":0.0,"tv":0.0,"id":16604347},{"batb":[[0,3.3,17.94],[1,1.01,0.51],[2,1.01,0]],"batl":[[0,4.7,20.77],[1,4.7,0]],"ltp":0.0,"tv":0.0,"id":16604346},{"batl":[[0,5.5,14.4],[1,5.5,0]],"ltp":0.0,"tv":0.0,"id":13117354}]}]}
{"op":"mcm","clk":"1004060348","pt":1580653184396,"mc":[{"id":"1.168224467","rc":[{"batb":[[0,2.68,23.93],[1,2.64,30.4],[2,2.58,13.53]],"ltp":0.0,"tv":0.0,"id":13117353},{"batb":[[1,3.25,37.29],[2,3.2,23]],"ltp":0.0,"tv":0.0,"id":16604346}]}]}
{"op":"mcm","clk":"1004061649","pt":1580653190812,"mc":[{"id":"1.168224467","rc":[{"batb":[[0,2.58,13.53],[1,1.01,0.51],[2,2.58,0]],"ltp":0.0,"tv":0.0,"id":13117353}]}]}
{"op":"mcm","clk":"1004062224","pt":1580653193912,"mc":[{"id":"1.168224467","rc":[{"batb":[[0,3.15,36.87],[1,3.1,24.97],[2,2.58,13.53]],"ltp":0.0,"tv":0.0,"id":13117353}]}]}
{"op":"mcm","clk":"1004062469","pt":1580653195204,"mc":[{"id":"1.168224467","rc":[{"batb":[[2,3.05,21.95]],"batl":[[1,3.9,15.42]],"ltp":0.0,"tv":0.0,"id":13117353},{"batl":[[0,3.7,17.39],[1,4,14.63]],"ltp":0.0,"tv":0.0,"id":16604346},{"batb":[[2,4.5,16.44]],"batl":[[0,5.4,15.11]],"ltp":0.0,"tv":0.0,"id":13117354}]}]}
{"op":"mcm","clk":"1004062600","pt":1580653195835,"mc":[{"id":"1.168224467","rc":[{"batb":[[2,3.05,42.12]],"batl":[[1,3.55,15.96],[2,3.9,15.42]],"ltp":0.0,"tv":0.0,"id":13117353},{"batl":[[0,5.4,24.51]],"ltp":0.0,"tv":0.0,"id":16604347},{"batb":[[2,3.2,41.48]],"batl":[[1,3.75,15.12],[2,4,14.63]],"ltp":0.0,"tv":0.0,"id":16604346},{"batl":[[0,5.4,24.35]],"ltp":0.0,"tv":0.0,"id":13117354}]}]}
{"op":"mcm","clk":"1004067331","pt":1580653219143,"mc":[{"id":"1.168224467","rc":[{"batb":[[0,3.05,20.16],[1,2.88,10.31],[2,1.01,0.51]],"batl":[[0,3.55,15.96],[1,3.9,15.42],[2,3.9,0]],"ltp":0.0,"tv":0.0,"id":13117353},{"batb":[[0,4.7,18.53],[1,4.6,16.21],[2,4.5,11.76]],"ltp":0.0,"tv":0.0,"id":16604347},{"batb":[[0,3.2,18.48],[1,2.94,24.16],[2,1.01,0.51]],"batl":[[0,3.75,15.12],[1,4,14.63],[2,4,0]],"ltp":0.0,"tv":0.0,"id":16604346}]}]}
{"op":"mcm","clk":"1004067685","pt":1580653220850,"mc":[{"id":"1.168224467","rc":[{"batb":[[0,2.88,10.31],[1,1.01,0.51],[2,1.01,0]],"batl":[[0,3.9,15.42],[1,3.9,0]],"ltp":0.0,"tv":0.0,"id":13117353},{"batb":[[2,1.01,0.51]],"batl":[[0,5.4,15.26]],"ltp":0.0,"tv":0.0,"id":16604347},{"batb":[[0,2.94,24.16],[1,1.01,0.51],[2,1.01,0]],"batl":[[0,4,14.63],[1,4,0]],"ltp":0.0,"tv":0.0,"id":16604346},{"batl":[[0,5.4,15.11]],"ltp":0.0,"tv":0.0,"id":13117354}]}]}
{"op":"mcm","clk":"1004067908","pt":1580653221968,"mc":[{"id":"1.168224467","rc":[{"batb":[[0,2.98,25.93],[1,2.94,23],[2,2.88,10.31]],"ltp":0.0,"tv":0.0,"id":13117353},{"batb":[[0,4.7,28.12],[1,4.6,35.37]],"ltp":0.0,"tv":0.0,"id":16604347},{"batb":[[1,2.92,28.89],[2,2.88,24.16]],"ltp":0.0,"tv":0.0,"id":16604346}]}]}
{"op":"mcm","clk":"1004070589","pt":1580653235192,"mc":[{"id":"1.168224467","rc":[{"batb":[[1,1.01,0.51],[2,2.88,0]],"ltp":0.0,"tv":0.0,"id":16604346}]}]}
{"op":"mcm","clk":"1004071232","pt":1580653238202,"mc":[{"id":"1.168224467","rc":[{"batb":[[0,3.5,30.02],[1,3.45,19.17],[2,2.94,24.16]],"ltp":0.0,"tv":0.0,"id":16604346}]}]}
{"op":"mcm","clk":"1004071465","pt":1580653239269,"mc":[{"id":"1.168224467","rc":[{"batl":[[0,3.2,24.63],[1,3.55,19.43],[2,3.9,15.42]],"ltp":0.0,"tv":0.0,"id":13117353},{"batl":[[0,5.3,15.42],[1,5.4,15.26]],"ltp":0.0,"tv":0.0,"id":16604347},{"batb":[[0,3.55,15.11],[1,3.5,30.02],[2,3.45,19.17]],"batl":[[1,4.3,24.71]],"ltp":0.0,"tv":0.0,"id":16604346},{"batb":[[2,4.6,16.13]],"ltp":0.0,"tv":0.0,"id":13117354}]}]}
{"op":"mcm","clk":"1004071661","pt":1580653240192,"mc":[{"id":"1.168224467","rc":[{"batb":[[1,2.94,44]],"batl":[[1,3.4,16.8],[2,3.55,19.43]],"ltp":0.0,"tv":0.0,"id":13117353},{"batb":[[2,4.5,11.76]],"batl":[[1,5.4,9.24]],"ltp":0.0,"tv":0.0,"id":16604347},{"batl":[[0,4,28.08]],"ltp":0.0,"tv":0.0,"id":16604346},{"batl":[[0,5.4,14.95]],"ltp":0.0,"tv":0.0,"id":13117354}]}]}
{"op":"mcm","clk":"1004071860","pt":1580653241173,"mc":[{"id":"1.168224467","rc":[{"batl":[[0,5.3,9.24],[1,5.4,14.95]],"ltp":0.0,"tv":0.0,"id":13117354}]}]}
{"op":"mcm","clk":"1004074276","pt":1580653253015,"mc":[{"id":"1.168224467","rc":[{"batb":[[0,2.74,11.64],[1,1.01,0.51],[2,2.88,0]],"batl":[[0,3.55,19.43],[1,3.4,0],[2,3.55,0]],"ltp":0.0,"tv":0.0,"id":13117353},{"batb":[[2,1.01,0.51]],"batl":[[1,5.4,0]],"ltp":0.0,"tv":0.0,"id":16604347},{"batb":[[0,3.2,19.59],[1,1.01,0.51],[2,3.45,0]],"batl":[[0,4.3,24.71],[1,4.3,0]],"ltp":0.0,"tv":0.0,"id":16604346},{"batl":[[0,5.4,14.95],[1,5.4,0]],"ltp":0.0,"tv":0.0,"id":13117354}]}]}
{"op":"mcm","clk":"1004075020","pt":1580653256095,"mc":[{"id":"1.168224467","rc":[{"batb":[[0,2.84,27.61],[1,2.8,26.05],[2,2.74,11.64]],"batl":[[0,3.55,19.28]],"ltp":0.0,"tv":0.0,"id":13117353},{"batb":[[1,4.6,19.16],[2,4.5,16.52]],"ltp":0.0,"tv":0.0,"id":16604347},{"batb":[[0,3.2,35.83],[1,3.15,24.11],[2,1.01,0.51]],"ltp":0.0,"tv":0.0,"id":16604346},{"batb":[[2,4.6,15.97]],"ltp":0.0,"tv":0.0,"id":13117354}]}]}
{"op":"mcm","clk":"1004076699","pt":1580653263892,"mc":[{"id":"1.168224467","rc":[{"batb":[[0,3.2,19.59],[1,1.01,0.51],[2,1.01,0]],"ltp":0.0,"tv":0.0,"id":16604346}]}]}
{"op":"mcm","clk":"1004077370","pt":1580653267122,"mc":[{"id":"1.168224467","rc":[{"batb":[[0,3.75,16.78],[1,3.7,16.29],[2,3.2,19.59]],"ltp":0.0,"tv":0.0,"id":16604346}]}]}
{"op":"mcm","clk":"1004077625","pt":1580653268396,"mc":[{"id":"1.168224467","rc":[{"batb":[[2,2.78,23.53]],"batl":[[0,3,11.33],[1,3.25,41.85]],"ltp":0.0,"tv":0.0,"id":13117353},{"batb":[[2,4.5,28.29]],"ltp":0.0,"tv":0.0,"id":16604347},{"batb":[[0,3.75,30],[2,3.55,15.96]],"batl":[[0,4.2,12.6],[1,4.3,24.71],[2,4.6,21.79]],"ltp":0.0,"tv":0.0,"id":16604346},{"batb":[[1,4.7,33.88],[2,4.4,11.76]],"batl":[[0,5.3,9.24],[1,5.4,14.79]],"ltp":0.0,"tv":0.0,"id":13117354}]}]}
{"op":"mcm","clk":"1004077962","pt":1580653270124,"mc":[{"id":"1.168224467","rc":[{"batl":[[1,5.5,9.24]],"ltp":0.0,"tv":0.0,"id":16604347}]}]}
{"op":"mcm","clk":"1004079240","pt":1580653276140,"mc":[{"id":"1.168224467","rc":[{"batb":[[0,2.78,23.53],[1,2.64,12.83],[2,1.01,0.51]],"batl":[[0,3.25,41.85],[1,3.25,0]],"ltp":0.0,"tv":0.0,"id":13117353},{"batb":[[0,3.55,15.96],[1,3.45,16.13],[2,1.01,0.51]],"batl":[[1,4.6,21.79],[2,4.6,0]],"ltp":0.0,"tv":0.0,"id":16604346}]}]}
{"op":"mcm","clk":"1004079403","pt":1580653276944,"mc":[{"id":"1.168224467","rc":[{"batb":[[0,2.64,12.83],[1,1.01,0.51],[2,1.01,0]],"batl":[[0,3.25,23.37]],"ltp":0.0,"tv":0.0,"id":13117353},{"batb":[[2,4.5,16.52]],"batl":[[1,5.5,0]],"ltp":0.0,"tv":0.0,"id":16604347},{"batb":[[0,3.45,16.13],[1,1.01,0.51],[2,1.01,0]],"batl":[[0,4.6,21.79],[1,4.6,0]],"ltp":0.0,"tv":0.0,"id":16604346},{"batb":[[2,1.01,0.51]],"batl":[[0,5.4,14.79],[1,5.4,0]],"ltp":0.0,"tv":0.0,"id":13117354}]}]}
{"op":"mcm","clk":"1004079865","pt":1580653278868,"mc":[{"id":"1.168224467","rc":[{"batb":[[0,2.76,20.7],[1,2.72,28.13],[2,2.64,12.83]],"ltp":0.0,"tv":0.0,"id":13117353},{"batb":[[0,3.45,43.33],[1,3.4,19.89],[2,1.01,0.51]],"ltp":0.0,"tv":0.0,"id":16604346}]}]}
{"op":"mcm","clk":"1004082695","pt":1580653292066,"mc":[{"id":"1.168224467","rc":[{"batb":[[0,4.7,18.53],[1,4.5,16.52],[2,1.01,0.51]],"ltp":0.0,"tv":0.0,"id":16604347},{"batb":[[0,3.45,16.13],[1,1.01,0.51],[2,1.01,0]],"ltp":0.0,"tv":0.0,"id":16604346}]}]}
{"op":"mcm","clk":"1004083389","pt":1580653295447,"mc":[{"id":"1.168224467","rc":[{"batb":[[0,4.8,10.95],[1,4.7,18.53],[2,4.5,16.52]],"ltp":0.0,"tv":0.0,"id":16604347},{"batb":[[0,3.9,21.26],[1,3.85,14.78],[2,3.45,16.13]],"ltp":0.0,"tv":0.0,"id":16604346}]}]}
{"op":"mcm","clk":"1004083480","pt":1580653295975,"mc":[{"id":"1.168224467","rc":[{"batb":[[2,2.7,24.37]],"batl":[[0,2.88,12.59],[1,3.05,11.02],[2,3.1,19.32]],"ltp":0.0,"tv":0.0,"id":13117353},{"batb":[[2,4.6,10.92]],"batl":[[1,5.5,9.24]],"ltp":0.0,"tv":0.0,"id":16604347},{"batb":[[0,3.95,23.05],[1,3.9,21.26],[2,3.85,14.78]],"batl":[[0,4.4,11.76],[1,4.6,21.79],[2,4.7,20.14]],"ltp":0.0,"tv":0.0,"id":16604346},{"batb":[[2,4.4,11.76]],"batl":[[0,5.3,9.24],[1,5.4,14.79]],"ltp":0.0,"tv":0.0,"id":13117354}]}]}
{"op":"mcm","clk":"1004086591","pt":1580653311402,"mc":[{"id":"1.168224467","rc":[{"batb":[[0,2.7,24.37],[1,2.58,13.61],[2,1.01,0.51]],"batl":[[0,3.05,11.02],[1,3.1,19.32],[2,3.1,0]],"ltp":0.0,"tv":0.0,"id":13117353},{"batb":[[0,4.7,18.53],[1,4.6,10.92],[2,4.5,16.52]],"ltp":0.0,"tv":0.0,"id":16604347},{"batb":[[0,3.7,28.58],[1,1.01,0.51],[2,3.85,0]],"batl":[[1,4.7,20.14],[2,4.7,0]],"ltp":0.0,"tv":0.0,"id":16604346}]}]}
{"op":"mcm","clk":"1004086938","pt":1580653313190,"mc":[{"id":"1.168224467","rc":[{"batb":[[0,2.58,13.61],[1,1.01,0.51],[2,1.01,0]],"batl":[[1,3.1,0]],"ltp":0.0,"tv":0.0,"id":13117353},{"batb":[[1,4.5,16.52],[2,1.01,0.51]],"batl":[[1,5.5,0]],"ltp":0.0,"tv":0.0,"id":16604347},{"batb":[[0,3.7,13.45]],"batl":[[0,4.7,20.14],[1,4.7,0]],"ltp":0.0,"tv":0.0,"id":16604346},{"batb":[[2,1.01,0.51]],"batl":[[0,5.4,14.79],[1,5.4,0]],"ltp":0.0,"tv":0.0,"id":13117354}]}]}
{"op":"mcm","clk":"1004087137","pt":1580653314191,"mc":[{"id":"1.168224467","rc":[{"batb":[[0,2.7,25.18],[1,2.66,29.79],[2,2.58,13.61]],"ltp":0.0,"tv":0.0,"id":13117353},{"batb":[[0,4.7,23.06],[1,4.6,19.25],[2,4.5,16.52]],"ltp":0.0,"tv":0.0,"id":16604347},{"batb":[[0,3.7,37.9],[1,3.65,16.77],[2,1.01,0.51]],"ltp":0.0,"tv":0.0,"id":16604346}]}]}
{"op":"mcm","clk":"1004088084","pt":1580653318877,"mc":[{"id":"1.168224467","rc":[{"batb":[[0,4.7,18.53],[1,4.5,16.52],[2,1.01,0.51]],"ltp":0.0,"tv":0.0,"id":16604347},{"batb":[[0,3.7,13.45],[1,1.01,0.51],[2,1.01,0]],"ltp":0.0,"tv":0.0,"id":16604346}]}]}
{"op":"mcm","clk":"1004088775","pt":1580653322396,"mc":[{"id":"1.168224467","rc":[{"batb":[[2,2.62,25.21]],"batl":[[0,2.98,21],[1,3.05,11.02]],"ltp":0.0,"tv":0.0,"id":13117353},{"batb":[[0,4.8,14.63],[1,4.7,29.45],[2,4.5,16.52]],"batl":[[1,5.6,8.4]],"ltp":0.0,"tv":0.0,"id":16604347},{"batb":[[0,4,22.55],[1,3.95,13.9],[2,3.9,14.28]],"batl":[[0,4.6,10.92],[1,4.7,20.14]],"ltp":0.0,"tv":0.0,"id":16604346},{"batb":[[2,4.3,12.6]],"batl":[[0,5.2,9.24],[1,5.4,14.79]],"ltp":0.0,"tv":0.0,"id":13117354}]}]}
{"op":"mcm","clk":"1004088895","pt":1580653322987,"mc":[{"id":"1.168224467","rc":[{"batl":[[0,2.8,13.38],[1,2.98,21],[2,3,11.41]],"ltp":0.0,"tv":0.0,"id":13117353},{"batb":[[2,4.6,16.37]],"batl":[[0,5.4,15.19]],"ltp":0.0,"tv":0.0,"id":16604347},{"batb":[[0,4.1,21.24],[1,4,22.55],[2,3.95,13.9]],"batl":[[2,5.6,14.01]],"ltp":0.0,"tv":0.0,"id":16604346},{"batb":[[1,4.7,18.3],[2,4.6,15.82]],"batl":[[1,5.5,14.32]],"ltp":0.0,"tv":0.0,"id":13117354}]}]}
{"op":"mcm","clk":"1004103616","pt":1580653398231,"mc":[{"id":"1.168224467","rc":[{"batb":[[0,2.62,25.21],[1,2.34,17.78],[2,1.01,0.51]],"batl":[[0,2.98,21],[1,3,11.41],[2,3,0]],"ltp":0.0,"tv":0.0,"id":13117353},{"batb":[[0,3.9,14.28],[1,3.75,12.98],[2,1.01,0.51]],"batl":[[1,5.6,14.01],[2,5.6,0]],"ltp":0.0,"tv":0.0,"id":16604346},{"batb":[[0,4.8,17.68]],"ltp":0.0,"tv":0.0,"id":13117354}]}]}
{"op":"mcm","clk":"1004103788","pt":1580653399176,"mc":[{"id":"1.168224467","rc":[{"batb":[[0,2.34,17.78],[1,1.01,0.51],[2,1.01,0]],"batl":[[0,3,11.41],[1,3,0]],"ltp":0.0,"tv":0.0,"id":13117353},{"batb":[[1,4.7,18.53]],"batl":[[1,5.6,0]],"ltp":0.0,"tv":0.0,"id":16604347},{"batb":[[0,3.75,12.98],[1,1.01,0.51],[2,1.01,0]],"batl":[[0,5.6,14.01],[1,5.6,0]],"ltp":0.0,"tv":0.0,"id":16604346},{"batl":[[0,5.5,14.32],[1,5.5,0]],"ltp":0.0,"tv":0.0,"id":13117354}]}]}
{"op":"mcm","clk":"1004104115","pt":1580653401042,"mc":[{"id":"1.168224467","rc":[{"batb":[[0,2.44,35.48],[1,2.4,39.18],[2,2.34,17.78]],"ltp":0.0,"tv":0.0,"id":13117353},{"batb":[[1,3.7,24.33],[2,3.65,16.77]],"ltp":0.0,"tv":0.0,"id":16604346}]}]}
{"op":"mcm","clk":"1004104622","pt":1580653403920,"mc":[{"id":"1.168224467","rc":[{"batb":[[0,2.34,17.78],[1,1.01,0.51],[2,2.34,0]],"ltp":0.0,"tv":0.0,"id":13117353},{"batb":[[1,1.01,0.51],[2,3.65,0]],"ltp":0.0,"tv":0.0,"id":16604346}]}]}
{"op":"mcm","clk":"1004105723","pt":1580653409358,"mc":[{"id":"1.168224467","rc":[{"batb":[[0,2.44,35.48],[1,2.4,39.18],[2,2.34,17.78]],"ltp":0.0,"tv":0.0,"id":13117353},{"batb":[[1,3.7,24.33],[2,3.65,16.77]],"ltp":0.0,"tv":0.0,"id":16604346}]}]}
{"op":"mcm","clk":"1004108448","pt":1580653423577,"mc":[{"id":"1.168224467","rc":[{"batb":[[0,2.34,17.78],[1,1.01,0.51],[2,2.34,0]],"ltp":0.0,"tv":0.0,"id":13117353}]}]}
{"op":"mcm","clk":"1004109205","pt":1580653427449,"mc":[{"id":"1.168224467","rc":[{"batb":[[0,2.86,29.83],[1,2.82,25.56],[2,2.74,11.57]],"batl":[[1,3.2,24.55]],"ltp":0.0,"tv":0.0,"id":13117353},{"batl":[[0,4.3,24.47],[1,5,18.18]],"ltp":0.0,"tv":0.0,"id":16604346},{"batl":[[0,5.4,14.95]],"ltp":0.0,"tv":0.0,"id":13117354}]}]}
{"op":"mcm","clk":"1004109320","pt":1580653428198,"mc":[{"id":"1.168224467","rc":[{"batb":[[2,2.74,35.09]],"batl":[[1,3.15,19.32],[2,3.2,24.55]],"ltp":0.0,"tv":0.0,"id":13117353},{"batb":[[2,4.6,27.29]],"batl":[[1,5.6,8.4]],"ltp":0.0,"tv":0.0,"id":16604347},{"batb":[[1,3.7,39.45]],"batl":[[0,4.3,37.07]],"ltp":0.0,"tv":0.0,"id":16604346},{"batl":[[0,5.2,9.24],[1,5.4,14.95]],"ltp":0.0,"tv":0.0,"id":13117354}]}]}
{"op":"mcm","clk":"1004110974","pt":1580653436386,"mc":[{"id":"1.168224467","rc":[{"batb":[[0,2.74,23.53],[1,2.5,14.79],[2,1.01,0.51]],"batl":[[0,3.15,19.32],[1,3.2,24.55],[2,3.2,0]],"ltp":0.0,"tv":0.0,"id":13117353},{"batb":[[0,4.7,18.53],[1,4.6,27.29],[2,1.01,0.51]],"ltp":0.0,"tv":0.0,"id":16604347},{"batb":[[0,3.7,15.12],[1,3.55,14.95],[2,1.01,0.51]],"batl":[[0,4.3,12.6]],"ltp":0.0,"tv":0.0,"id":16604346},{"batb":[[0,4.8,13.21]],"ltp":0.0,"tv":0.0,"id":13117354}]}]}
{"op":"mcm","clk":"1004111133","pt":1580653437180,"mc":[{"id":"1.168224467","rc":[{"batb":[[0,2.5,14.79],[1,1.01,0.51],[2,1.01,0]],"batl":[[0,3.2,24.55],[1,3.2,0]],"ltp":0.0,"tv":0.0,"id":13117353},{"batb":[[1,4.6,16.37]],"batl":[[1,5.6,0]],"ltp":0.0,"tv":0.0,"id":16604347},{"batb":[[0,3.55,14.95],[1,1.01,0.51],[2,1.01,0]],"batl":[[0,5,18.18],[1,5,0]],"ltp":0.0,"tv":0.0,"id":16604346},{"batl":[[0,5.4,14.95],[1,5.4,0]],"ltp":0.0,"tv":0.0,"id":13117354}]}]}
{"op":"mcm","clk":"1004111516","pt":1580653439112,"mc":[{"id":"1.168224467","rc":[{"batb":[[0,2.64,20.67],[1,2.6,31.66],[2,2.5,14.79]],"ltp":0.0,"tv":0.0,"id":13117353},{"batb":[[0,4.7,28.17],[1,4.6,35.53]],"ltp":0.0,"tv":0.0,"id":16604347},{"batb":[[1,3.5,21.94],[2,3.45,19.24]],"ltp":0.0,"tv":0.0,"id":16604346}]}]}
{"op":"mcm","clk":"1004112797","pt":1580653445367,"mc":[{"id":"1.168224467","rc":[{"batb":[[0,2.5,14.79],[1,1.01,0.51],[2,2.5,0]],"ltp":0.0,"tv":0.0,"id":13117353}]}]}
{"op":"mcm","clk":"1004113431","pt":1580653448345,"mc":[{"id":"1.168224467","rc":[{"batb":[[0,3,34.67],[1,2.96,22.54],[2,2.5,14.79]],"ltp":0.0,"tv":0.0,"id":13117353}]}]}
{"op":"mcm","clk":"1004113636","pt":1580653449340,"mc":[{"id":"1.168224467","rc":[{"batb":[[2,2.88,25.57]],"batl":[[1,3.35,22.11]],"ltp":0.0,"tv":0.0,"id":13117353},{"batb":[[1,4.6,19.16],[2,4.5,16.52]],"ltp":0.0,"tv":0.0,"id":16604347},{"batl":[[0,4,14.48],[1,4.5,22.98]],"ltp":0.0,"tv":0.0,"id":16604346}]}]}
{"op":"mcm","clk":"1004113809","pt":1580653450213,"mc":[{"id":"1.168224467","rc":[{"batl":[[1,3.3,17.64],[2,3.35,22.11]],"ltp":0.0,"tv":0.0,"id":13117353},{"batb":[[1,4.6,30.08]],"batl":[[1,5.5,9.24]],"ltp":0.0,"tv":0.0,"id":16604347},{"batb":[[2,3.45,36.04]],"batl":[[1,4.1,13.44],[2,4.5,22.98]],"ltp":0.0,"tv":0.0,"id":16604346},{"batl":[[0,5.2,9.24],[1,5.4,14.95]],"ltp":0.0,"tv":0.0,"id":13117354}]}]}
{"op":"mcm","clk":"1004115386","pt":1580653457839,"mc":[{"id":"1.168224467","rc":[{"batb":[[0,2.86,21.85],[1,2.7,12.27],[2,1.01,0.51]],"batl":[[0,3.3,17.64],[1,3.35,22.11],[2,3.35,0]],"ltp":0.0,"tv":0.0,"id":13117353},{"batb":[[0,3.45,16.8],[1,3.4,16.6],[2,1.01,0.51]],"batl":[[0,4.1,13.44],[1,4.5,22.98],[2,4.5,0]],"ltp":0.0,"tv":0.0,"id":16604346}]}]}
{"op":"mcm","clk":"1004115695","pt":1580653459251,"mc":[{"id":"1.168224467","rc":[{"batb":[[0,2.7,12.27],[1,1.01,0.51],[2,1.01,0]],"batl":[[0,3.35,22.11],[1,3.35,0]],"ltp":0.0,"tv":0.0,"id":13117353},{"batb":[[1,4.6,19.16]],"batl":[[1,5.5,0]],"ltp":0.0,"tv":0.0,"id":16604347},{"batb":[[0,3.4,16.6],[1,1.01,0.51],[2,1.01,0]],"batl":[[0,4.5,22.98],[1,4.5,0]],"ltp":0.0,"tv":0.0,"id":16604346},{"batl":[[0,5.4,14.95],[1,5.4,0]],"ltp":0.0,"tv":0.0,"id":13117354}]}]}
{"op":"mcm","clk":"1004116009","pt":1580653460649,"mc":[{"id":"1.168224467","rc":[{"batb":[[0,2.82,30.32],[1,2.78,26.51],[2,2.7,12.27]],"ltp":0.0,"tv":0.0,"id":13117353},{"batb":[[1,3.35,29.13],[2,3.3,21.38]],"ltp":0.0,"tv":0.0,"id":16604346}]}]}
{"op":"mcm","clk":"1004118128","pt":1580653470780,"mc":[{"id":"1.168224467","rc":[{"batb":[[0,2.7,12.27],[1,1.01,0.51],[2,2.7,0]],"ltp":0.0,"tv":0.0,"id":13117353}]}]}
{"op":"mcm","clk":"1004118651","pt":1580653473384,"mc":[{"id":"1.168224467","rc":[{"batb":[[0,4.7,21.22]],"ltp":0.0,"tv":0.0,"id":16604347},{"batb":[[0,3.3,21.38],[1,1.01,0.51],[2,3.3,0]],"ltp":0.0,"tv":0.0,"id":16604346},{"batb":[[0,4.7,18.3],[1,4.6,15.82],[2,1.01,0.51]],"ltp":0.0,"tv":0.0,"id":13117354}]}]}
{"op":"mcm","clk":"1004119081","pt":1580653475287,"mc":[{"id":"1.168224467","rc":[{"batb":[[0,3,22.98],[1,2.86,10.46],[2,1.01,0.51]],"batl":[[0,3.45,20.3]],"ltp":0.0,"tv":0.0,"id":13117353},{"batl":[[0,5.3,15.5]],"ltp":0.0,"tv":0.0,"id":16604347},{"batb":[[0,3.3,39.56]],"batl":[[0,3.85,16.05],[1,4.1,13.77]],"ltp":0.0,"tv":0.0,"id":16604346},{"batl":[[0,5.3,15.5]],"ltp":0.0,"tv":0.0,"id":13117354}]}]}
{"op":"mcm","clk":"1004119189","pt":1580653475776,"mc":[{"id":"1.168224467","rc":[{"batb":[[0,3,23.92],[1,2.96,22.62],[2,2.86,10.46]],"ltp":0.0,"tv":0.0,"id":13117353},{"batb":[[1,3.25,22.31],[2,1.01,0.51]],"batl":[[0,4.1,13.77],[1,4.1,0]],"ltp":0.0,"tv":0.0,"id":16604346},{"batb":[[0,4.7,29.04],[1,4.6,35.03]],"ltp":0.0,"tv":0.0,"id":13117354}]}]}
{"op":"mcm","clk":"1004120367","pt":1580653481127,"mc":[{"id":"1.168224467","rc":[{"batb":[[0,4.7,18.53],[1,4.5,16.52],[2,1.01,0.51]],"ltp":0.0,"tv":0.0,"id":16604347},{"batb":[[0,3.3,18.18],[1,1.01,0.51],[2,1.01,0]],"ltp":0.0,"tv":0.0,"id":16604346}]}]}
{"op":"mcm","clk":"1004121024","pt":1580653484275,"mc":[{"id":"1.168224467","rc":[{"batb":[[2,2.86,32.31]],"batl":[[0,3.15,10.31],[1,3.3,40.38],[2,3.45,20.3]],"ltp":0.0,"tv":0.0,"id":13117353},{"batb":[[0,4.8,13.29],[1,4.7,18.53],[2,4.6,27.29]],"batl":[[1,5.4,15.26],[2,5.5,9.24]],"ltp":0.0,"tv":0.0,"id":16604347},{"batb":[[0,3.65,14.24],[1,3.5,47.76],[2,3.45,35.21]],"batl":[[0,4.1,27.21],[1,4.5,22.5]],"ltp":0.0,"tv":0.0,"id":16604346},{"batb":[[2,4.5,16.44]],"batl":[[0,5.1,10.08],[1,5.3,15.5],[2,5.4,15.19]],"ltp":0.0,"tv":0.0,"id":13117354}]}]}
{"op":"mcm","clk":"1004121068","pt":1580653484480,"mc":[{"id":"1.168224467","rc":[{"batl":[[2,3.45,0]],"ltp":0.0,"tv":0.0,"id":13117353},{"batl":[[0,5.4,15.26],[1,5.4,0],[2,5.5,0]],"ltp":0.0,"tv":0.0,"id":16604347},{"batl":[[0,4.1,13.77]],"ltp":0.0,"tv":0.0,"id":16604346},{"batb":[[1,4.6,19.21]],"batl":[[1,5.4,15.19],[2,5.4,0]],"ltp":0.0,"tv":0.0,"id":13117354}]}]}
{"op":"mcm","clk":"1004121547","pt":1580653486795,"mc":[{"id":"1.168224467","rc":[{"batl":[[1,5.6,8.4]],"ltp":0.0,"tv":0.0,"id":16604347},{"batl":[[1,4.2,12.6],[2,4.5,22.5]],"ltp":0.0,"tv":0.0,"id":16604346}]}]}
{"op":"mcm","clk":"1004123525","pt":1580653496188,"mc":[{"id":"1.168224467","rc":[{"batb":[[0,2.86,21.85],[1,2.66,12.51],[2,1.01,0.51]],"batl":[[0,3.3,40.38],[1,3.3,0]],"ltp":0.0,"tv":0.0,"id":13117353},{"batb":[[0,4.7,18.53],[1,4.6,27.29],[2,1.01,0.51]],"ltp":0.0,"tv":0.0,"id":16604347},{"batb":[[0,3.5,16.8],[1,3.45,16.05],[2,1.01,0.51]],"batl":[[0,4.2,12.6],[1,4.5,22.5],[2,4.5,0]],"ltp":0.0,"tv":0.0,"id":16604346}]}]}
{"op":"mcm","clk":"1004123742","pt":1580653497213,"mc":[{"id":"1.168224467","rc":[{"batb":[[0,2.66,12.51],[1,1.01,0.51],[2,1.01,0]],"batl":[[0,3.3,22.74]],"ltp":0.0,"tv":0.0,"id":13117353},{"batb":[[1,4.6,16.37]],"batl":[[1,5.6,0]],"ltp":0.0,"tv":0.0,"id":16604347},{"batb":[[0,3.45,16.05],[1,1.01,0.51],[2,1.01,0]],"batl":[[0,4.5,22.5],[1,4.5,0]],"ltp":0.0,"tv":0.0,"id":16604346},{"batl":[[0,5.4,15.19],[1,5.4,0]],"ltp":0.0,"tv":0.0,"id":13117354}]}]}
{"op":"mcm","clk":"1004124167","pt":1580653499103,"mc":[{"id":"1.168224467","rc":[{"batb":[[0,2.82,25.17],[1,2.78,26.56],[2,2.66,12.51]],"ltp":0.0,"tv":0.0,"id":13117353},{"batb":[[0,4.7,28.42],[1,4.6,35.53]],"ltp":0.0,"tv":0.0,"id":16604347},{"batb":[[1,3.4,19.81],[2,3.35,20.68]],"ltp":0.0,"tv":0.0,"id":16604346}]}]}
{"op":"mcm","clk":"1004124926","pt":1580653502695,"mc":[{"id":"1.168224467","rc":[{"batb":[[0,4.7,18.53],[1,4.6,16.37]],"ltp":0.0,"tv":0.0,"id":16604347},{"batb":[[1,1.01,0.51],[2,3.35,0]],"ltp":0.0,"tv":0.0,"id":16604346},{"batb":[[0,4.7,18.56],[1,4.5,16.44],[2,1.01,0.51]],"ltp":0.0,"tv":0.0,"id":13117354}]}]}
{"op":"mcm","clk":"1004125750","pt":1580653506310,"mc":[{"id":"1.168224467","rc":[{"batb":[[2,2.72,24.37]],"batl":[[0,2.9,12.27],[1,3.1,19.32],[2,3.15,10.31]],"ltp":0.0,"tv":0.0,"id":13117353},{"batb":[[0,4.8,19.88],[1,4.7,29.45],[2,4.6,16.37]],"batl":[[1,5.7,8.4]],"ltp":0.0,"tv":0.0,"id":16604347},{"batb":[[0,3.9,23.76],[1,3.8,15.09],[2,3.75,30.91]],"batl":[[0,4.5,34.27],[1,5.3,15.42]],"ltp":0.0,"tv":0.0,"id":16604346},{"batb":[[0,4.8,12.09],[1,4.7,18.56],[2,4.6,15.89]],"batl":[[0,5.1,10.08],[1,5.4,15.19],[2,5.5,14.71]],"ltp":0.0,"tv":0.0,"id":13117354}]}]}
{"op":"mcm","clk":"1004125917","pt":1580653507015,"mc":[{"id":"1.168224467","rc":[{"batb":[[2,4.6,15.97]],"batl":[[0,5.4,14.87]],"ltp":0.0,"tv":0.0,"id":16604347}]}]}
{"op":"mcm","clk":"1004128245","pt":1580653517441,"mc":[{"id":"1.168224467","rc":[{"batb":[[0,2.4,16.76],[1,1.01,0.51],[2,2.72,0]],"batl":[[0,3.15,10.31],[1,3.1,0],[2,3.15,0]],"ltp":0.0,"tv":0.0,"id":13117353},{"batb":[[1,4.7,18.53]],"batl":[[1,5.7,0]],"ltp":0.0,"tv":0.0,"id":16604347},{"batb":[[0,3.65,14.24],[1,1.01,0.51],[2,3.75,0]],"batl":[[0,5.3,15.42],[1,5.3,0]],"ltp":0.0,"tv":0.0,"id":16604346},{"batb":[[0,4.7,18.56],[1,4.5,16.44],[2,1.01,0.51]],"batl":[[0,5.5,14.71],[1,5.4,0],[2,5.5,0]],"ltp":0.0,"tv":0.0,"id":13117354}]}]}
{"op":"mcm","clk":"1004128885","pt":1580653520239,"mc":[{"id":"1.168224467","rc":[{"batb":[[0,2.54,21.99],[1,2.5,35.16],[2,2.4,16.76]],"batl":[[1,3.2,25.02]],"ltp":0.0,"tv":0.0,"id":13117353},{"batb":[[1,3.6,14.56],[2,3.5,23.96]],"ltp":0.0,"tv":0.0,"id":16604346},{"batb":[[0,4.7,24.39],[1,4.6,19.29],[2,4.5,16.44]],"ltp":0.0,"tv":0.0,"id":13117354}]}]}
{"op":"mcm","clk":"1004128939","pt":1580653520455,"mc":[{"id":"1.168224467","rc":[{"batb":[[2,2.4,16.52]],"batl":[[0,3.2,25.02],[1,3.2,0]],"ltp":0.0,"tv":0.0,"id":13117353},{"batb":[[0,3.6,14.56],[1,3.5,23.96],[2,3.45,19.21]],"ltp":0.0,"tv":0.0,"id":16604346},{"batb":[[2,1.01,0.51]],"batl":[[0,5.5,14.48]],"ltp":0.0,"tv":0.0,"id":13117354}]}]}
{"op":"mcm","clk":"1004130774","pt":1580653528650,"mc":[{"id":"1.168224467","rc":[{"batb":[[1,1.01,0.51],[2,3.45,0]],"ltp":0.0,"tv":0.0,"id":16604346},{"batb":[[0,4.7,18.56],[1,1.01,0.51],[2,1.01,0]],"ltp":0.0,"tv":0.0,"id":13117354}]}]}
{"op":"mcm","clk":"1004131658","pt":1580653532449,"mc":[{"id":"1.168224467","rc":[{"batb":[[2,2.48,27.73]],"batl":[[0,2.62,16.13],[1,2.84,22.69],[2,2.88,12.51]],"ltp":0.0,"tv":0.0,"id":13117353},{"batb":[[0,4.8,35.29]],"batl":[[1,5.7,8.4]],"ltp":0.0,"tv":0.0,"id":16604347},{"batb":[[0,4.5,16.44],[1,4.4,16.77],[2,4.3,22.59]],"batl":[[0,5.1,10.08],[1,5.3,15.42],[2,7.2,16.76]],"ltp":0.0,"tv":0.0,"id":16604346},{"batb":[[0,4.8,23.53],[1,4.7,33.67],[2,4.6,15.82]],"batl":[[0,5.1,10.08],[1,5.5,14.48],[2,5.7,13.45]],"ltp":0.0,"tv":0.0,"id":13117354}]}]}
{"op":"mcm","clk":"1004134246","pt":1580653544173,"mc":[{"id":"1.168224467","rc":[{"batb":[[0,2.48,27.73],[1,2.12,23.84],[2,1.01,0.51]],"batl":[[0,2.84,22.69],[1,2.88,12.51],[2,2.88,0]],"ltp":0.0,"tv":0.0,"id":13117353},{"batb":[[0,4.2,12.6],[1,3.95,23.13],[2,1.01,0.51]],"batl":[[1,7.2,16.76],[2,7.2,0]],"ltp":0.0,"tv":0.0,"id":16604346},{"batb":[[0,4.8,11.49],[1,4.7,18.56]],"batl":[[1,5.7,13.45],[2,5.7,0]],"ltp":0.0,"tv":0.0,"id":13117354}]}]}
{"op":"mcm","clk":"1004134492","pt":1580653545288,"mc":[{"id":"1.168224467","rc":[{"batb":[[0,2.12,23.84],[1,1.01,0.51],[2,1.01,0]],"batl":[[0,2.88,12.51],[1,2.88,0]],"ltp":0.0,"tv":0.0,"id":13117353},{"batb":[[0,4.8,24.37]],"batl":[[1,5.7,0]],"ltp":0.0,"tv":0.0,"id":16604347},{"batb":[[0,3.95,23.13],[1,1.01,0.51],[2,1.01,0]],"batl":[[0,7.2,16.76],[1,7.2,0]],"ltp":0.0,"tv":0.0,"id":16604346},{"batl":[[0,5.7,13.45],[1,5.7,0]],"ltp":0.0,"tv":0.0,"id":13117354}]}]}
{"op":"mcm","clk":"1004135035","pt":1580653547573,"mc":[{"id":"1.168224467","rc":[{"batb":[[0,2.2,31.34],[1,2.18,25.92],[2,2.12,23.84]],"ltp":0.0,"tv":0.0,"id":13117353},{"batb":[[1,3.85,14.32],[2,3.8,15.3]],"ltp":0.0,"tv":0.0,"id":16604346}]}]}
{"op":"mcm","clk":"1004138237","pt":1580653562394,"mc":[{"id":"1.168224467","rc":[{"batb":[[0,2.12,23.84],[1,1.01,0.51],[2,2.12,0]],"ltp":0.0,"tv":0.0,"id":13117353}]}]}
{"op":"mcm","clk":"1004138963","pt":1580653565422,"mc":[{"id":"1.168224467","rc":[{"batb":[[0,2.8,18.26],[1,2.76,27.12],[2,2.12,23.84]],"ltp":0.0,"tv":0.0,"id":13117353}]}]}
{"op":"mcm","clk":"1004139200","pt":1580653566440,"mc":[{"id":"1.168224467","rc":[{"batb":[[2,2.66,25.21]],"batl":[[1,3.05,20.16],[2,3.1,10.54]],"ltp":0.0,"tv":0.0,"id":13117353},{"batb":[[0,4.8,35.29]],"batl":[[1,5.7,8.4]],"ltp":0.0,"tv":0.0,"id":16604347},{"batb":[[1,3.85,28.6]],"batl":[[0,4.6,32.87],[1,5.4,15.11]],"ltp":0.0,"tv":0.0,"id":16604346},{"batl":[[0,5,10.08],[1,5.4,15.11],[2,5.6,14.16]],"ltp":0.0,"tv":0.0,"id":13117354}]}]}
{"op":"mcm","clk":"1004141594","pt":1580653577365,"mc":[{"id":"1.168224467","rc":[{"batb":[[0,2.66,25.21],[1,2.64,12.75],[2,2.38,17.15]],"ltp":0.0,"tv":0.0,"id":13117353},{"batb":[[0,4.8,31.04]],"ltp":0.0,"tv":0.0,"id":16604347},{"batb":[[1,3.85,14.28],[2,3.65,13.85]],"ltp":0.0,"tv":0.0,"id":16604346},{"batb":[[0,4.7,18.56],[1,4.6,15.82],[2,4.2,12.6]],"ltp":0.0,"tv":0.0,"id":13117354}]}]}
{"op":"mcm","clk":"1004141712","pt":1580653577969,"mc":[{"id":"1.168224467","rc":[{"batb":[[1,2.38,17.15],[2,1.01,0.51]],"batl":[[0,3.05,20.16],[1,3.1,10.54],[2,3.1,0]],"ltp":0.0,"tv":0.0,"id":13117353},{"batb":[[0,3.85,14.28],[1,3.65,13.85],[2,1.01,0.51]],"batl":[[0,4.6,10.92]],"ltp":0.0,"tv":0.0,"id":16604346},{"batl":[[1,5.6,14.16],[2,5.6,0]],"ltp":0.0,"tv":0.0,"id":13117354}]}]}
{"op":"mcm","clk":"1004142008","pt":1580653579371,"mc":[{"id":"1.168224467","rc":[{"batb":[[0,2.38,17.15],[1,1.01,0.51],[2,1.01,0]],"batl":[[0,3.1,10.54],[1,3.1,0]],"ltp":0.0,"tv":0.0,"id":13117353},{"batb":[[0,4.8,20.12]],"batl":[[1,5.7,0]],"ltp":0.0,"tv":0.0,"id":16604347},{"batb":[[0,3.65,13.85],[1,1.01,0.51],[2,1.01,0]],"batl":[[0,5.4,15.11],[1,5.4,0]],"ltp":0.0,"tv":0.0,"id":16604346},{"batb":[[2,1.01,0.51]],"batl":[[0,5.6,14.16],[1,5.6,0]],"ltp":0.0,"tv":0.0,"id":13117354}]}]}
{"op":"mcm","clk":"1004142239","pt":1580653580367,"mc":[{"id":"1.168224467","rc":[{"batb":[[0,2.5,34.31],[1,2.46,36.65],[2,2.38,17.15]],"ltp":0.0,"tv":0.0,"id":13117353},{"batb":[[1,3.55,19.37],[2,3.5,18.59]],"ltp":0.0,"tv":0.0,"id":16604346},{"batb":[[0,4.7,23.19],[1,4.6,35.13]],"ltp":0.0,"tv":0.0,"id":13117354}]}]}
{"op":"mcm","clk":"1004142632","pt":1580653582059,"mc":[{"id":"1.168224467","rc":[{"batb":[[0,2.38,17.15],[1,1.01,0.51],[2,2.38,0]],"ltp":0.0,"tv":0.0,"id":13117353},{"batb":[[1,1.01,0.51],[2,3.5,0]],"ltp":0.0,"tv":0.0,"id":16604346},{"batb":[[0,4.7,18.56],[1,4.6,15.82]],"ltp":0.0,"tv":0.0,"id":13117354}]}]}
{"op":"mcm","clk":"1004143262","pt":1580653585062,"mc":[{"id":"1.168224467","rc":[{"batb":[[0,2.72,31.64],[1,2.68,29.18],[2,2.38,17.15]],"ltp":0.0,"tv":0.0,"id":13117353},{"batb":[[0,4.8,24.17]],"ltp":0.0,"tv":0.0,"id":16604347},{"batb":[[0,3.95,17.22],[1,3.9,14.36],[2,3.65,13.85]],"ltp":0.0,"tv":0.0,"id":16604346},{"batb":[[0,4.8,13.95],[1,4.7,18.56],[2,4.6,15.82]],"ltp":0.0,"tv":0.0,"id":13117354}]}]}
{"op":"mcm","clk":"1004143508","pt":1580653586174,"mc":[{"id":"1.168224467","rc":[{"batb":[[0,2.38,17.15],[1,1.01,0.51],[2,2.38,0]],"ltp":0.0,"tv":0.0,"id":13117353},{"batb":[[0,4.8,20.12]],"ltp":0.0,"tv":0.0,"id":16604347},{"batb":[[0,3.65,13.85],[1,1.01,0.51],[2,3.65,0]],"ltp":0.0,"tv":0.0,"id":16604346},{"batb":[[0,4.7,18.56],[1,4.6,15.82],[2,1.01,0.51]],"ltp":0.0,"tv":0.0,"id":13117354}]}]}
{"op":"mcm","clk":"1004144180","pt":1580653589168,"mc":[{"id":"1.168224467","rc":[{"batb":[[0,2.5,34.31],[1,2.46,36.65],[2,2.38,17.15]],"ltp":0.0,"tv":0.0,"id":13117353},{"batb":[[1,3.55,19.37],[2,3.5,18.59]],"ltp":0.0,"tv":0.0,"id":16604346},{"batb":[[0,4.7,23.19],[1,4.6,35.13]],"ltp":0.0,"tv":0.0,"id":13117354}]}]}
{"op":"mcm","clk":"1004144700","pt":1580653591475,"mc":[{"id":"1.168224467","rc":[{"batb":[[0,4.8,19.88],[1,4.6,15.97],[2,1.01,0.51]],"ltp":0.0,"tv":0.0,"id":16604347},{"batb":[[1,1.01,0.51],[2,3.5,0]],"ltp":0.0,"tv":0.0,"id":16604346},{"batb":[[0,4.7,18.56],[1,4.6,15.82]],"ltp":0.0,"tv":0.0,"id":13117354}]}]}
{"op":"mcm","clk":"1004145580","pt":1580653595399,"mc":[{"id":"1.168224467","rc":[{"batl":[[0,2.58,16.76],[1,2.82,13.14],[2,3.1,10.54]],"ltp":0.0,"tv":0.0,"id":13117353},{"batb":[[0,4.9,10.43],[1,4.8,19.88],[2,4.6,15.97]],"ltp":0.0,"tv":0.0,"id":16604347},{"batb":[[0,4.6,15.82],[1,4.4,30.39],[2,4.3,22.34]],"batl":[[1,7.4,16.05]],"ltp":0.0,"tv":0.0,"id":16604346},{"batb":[[0,4.8,38.6],[1,4.7,34.06],[2,4.6,15.82]],"batl":[[1,5.7,13.3]],"ltp":0.0,"tv":0.0,"id":13117354}]}]}
{"op":"mcm","clk":"1004145771","pt":1580653596281,"mc":[{"id":"1.168224467","rc":[{"batb":[[1,2.46,65.22]],"batl":[[1,2.8,22.69],[2,2.82,13.14]],"ltp":0.0,"tv":0.0,"id":13117353},{"batb":[[1,4.8,30.8]],"batl":[[1,5.8,8.4]],"ltp":0.0,"tv":0.0,"id":16604347},{"batb":[[2,4.3,34.94]],"batl":[[0,5.2,9.24],[1,5.4,15.11],[2,7.4,16.05]],"ltp":0.0,"tv":0.0,"id":16604346},{"batb":[[2,4.3,12.6]],"batl":[[0,5.1,10.08],[1,5.6,14.16],[2,5.7,13.3]],"ltp":0.0,"tv":0.0,"id":13117354}]}]}
{"op":"mcm","clk":"1004147723","pt":1580653606320,"mc":[{"id":"1.168224467","rc":[{"batb":[[0,2.46,28.57],[1,2.38,17.15],[2,2.1,24.47]],"ltp":0.0,"tv":0.0,"id":13117353},{"batb":[[0,4.8,30.8],[1,4.6,15.97],[2,1.01,0.51]],"ltp":0.0,"tv":0.0,"id":16604347},{"batb":[[1,4.3,12.6],[2,4,22.19]],"ltp":0.0,"tv":0.0,"id":16604346},{"batb":[[0,4.8,25.81]],"ltp":0.0,"tv":0.0,"id":13117354}]}]}
{"op":"mcm","clk":"1004147928","pt":1580653607394,"mc":[{"id":"1.168224467","rc":[{"batb":[[0,2.1,24.47],[1,1.01,0.51],[2,2.1,0]],"batl":[[0,2.82,13.14],[1,2.8,0],[2,2.82,0]],"ltp":0.0,"tv":0.0,"id":13117353},{"batb":[[0,4.8,19.88]],"batl":[[1,5.8,0]],"ltp":0.0,"tv":0.0,"id":16604347},{"batb":[[0,4,22.19],[1,1.01,0.51],[2,4,0]],"batl":[[0,7.4,16.05],[1,5.4,0],[2,7.4,0]],"ltp":0.0,"tv":0.0,"id":16604346},{"batb":[[0,4.8,11.02],[2,1.01,0.51]],"batl":[[0,5.7,13.3],[1,5.6,0],[2,5.7,0]],"ltp":0.0,"tv":0.0,"id":13117354}]}]}
{"op":"mcm","clk":"1004148312","pt":1580653609399,"mc":[{"id":"1.168224467","rc":[{"batb":[[0,2.18,30.78],[1,2.16,26.62],[2,2.1,24.47]],"ltp":0.0,"tv":0.0,"id":13117353},{"batb":[[0,4.8,26.39],[1,4.7,18.27],[2,4.6,15.97]],"ltp":0.0,"tv":0.0,"id":16604347},{"batb":[[1,3.9,14.27],[2,3.85,14.83]],"ltp":0.0,"tv":0.0,"id":16604346}]}]}
{"op":"mcm","clk":"1004148750","pt":1580653611795,"mc":[{"id":"1.168224467","rc":[{"batb":[[0,2.1,24.47],[1,1.01,0.51],[2,2.1,0]],"ltp":0.0,"tv":0.0,"id":13117353},{"batb":[[0,4.8,19.88],[1,4.6,15.97],[2,1.01,0.51]],"ltp":0.0,"tv":0.0,"id":16604347},{"batb":[[1,1.01,0.51],[2,3.85,0]],"ltp":0.0,"tv":0.0,"id":16604346},{"batb":[[1,4.7,33.8]],"ltp":0.0,"tv":0.0,"id":13117354}]}]}
{"op":"mcm","clk":"1004149286","pt":1580653614721,"mc":[{"id":"1.168224467","rc":[{"batb":[[0,2.44,22.61],[1,2.4,39.27],[2,2.1,24.47]],"ltp":0.0,"tv":0.0,"id":13117353},{"batb":[[0,4.9,11.06],[1,4.8,19.88],[2,4.6,15.97]],"ltp":0.0,"tv":0.0,"id":16604347},{"batb":[[0,4.7,14.8],[1,4.6,19.36],[2,4,22.19]],"ltp":0.0,"tv":0.0,"id":16604346},{"batb":[[0,4.8,28.05]],"ltp":0.0,"tv":0.0,"id":13117354}]}]}
{"op":"mcm","clk":"1004149486","pt":1580653615704,"mc":[{"id":"1.168224467","rc":[{"batb":[[0,4.8,17.73],[1,4.7,15.5]],"ltp":0.0,"tv":0.0,"id":13117354}]}]}
{"op":"mcm","clk":"1004149694","pt":1580653616685,"mc":[{"id":"1.168224467","rc":[{"batb":[[0,2.1,24.47],[1,1.01,0.51],[2,2.1,0]],"ltp":0.0,"tv":0.0,"id":13117353},{"batb":[[0,4.8,19.88],[1,4.6,15.97],[2,1.01,0.51]],"ltp":0.0,"tv":0.0,"id":16604347},{"batb":[[0,4,22.19],[1,1.01,0.51],[2,4,0]],"ltp":0.0,"tv":0.0,"id":16604346},{"batb":[[0,4.8,11.37]],"ltp":0.0,"tv":0.0,"id":13117354}]}]}
{"op":"mcm","clk":"1004150405","pt":1580653620302,"mc":[{"id":"1.168224467","rc":[{"batb":[[0,2.18,31.68],[1,2.16,26.62],[2,2.1,24.47]],"ltp":0.0,"tv":0.0,"id":13117353},{"batb":[[0,4.8,25.95],[1,4.7,18.27],[2,4.6,15.97]],"ltp":0.0,"tv":0.0,"id":16604347},{"batb":[[1,3.9,13.7],[2,3.85,14.83]],"ltp":0.0,"tv":0.0,"id":16604346},{"batb":[[1,4.7,34.07]],"ltp":0.0,"tv":0.0,"id":13117354}]}]}
{"op":"mcm","clk":"1004150508","pt":1580653620825,"mc":[{"id":"1.168224467","rc":[{"batb":[[0,4.8,19.88],[1,4.6,15.97],[2,1.01,0.51]],"ltp":0.0,"tv":0.0,"id":16604347},{"batb":[[1,1.01,0.51],[2,3.85,0]],"ltp":0.0,"tv":0.0,"id":16604346},{"batb":[[0,4.7,15.5],[1,1.01,0.51],[2,1.01,0]],"ltp":0.0,"tv":0.0,"id":13117354}]}]}
{"op":"mcm","clk":"1004151222","pt":1580653624404,"mc":[{"id":"1.168224467","rc":[{"batb":[[0,2.18,66.97]],"batl":[[0,2.26,23.84],[1,2.46,28.57],[2,2.54,17.31]],"ltp":0.0,"tv":0.0,"id":13117353},{"batb":[[0,4.9,13.09],[1,4.8,30.8],[2,4.6,15.82]],"batl":[[1,5.8,8.4]],"ltp":0.0,"tv":0.0,"id":16604347},{"batb":[[0,6,17.15],[1,5.9,15.91],[2,5.8,11.45]],"batl":[[0,6.6,6.72],[1,7.4,16.05],[2,14.5,10.54]],"ltp":0.0,"tv":0.0,"id":16604346},{"batb":[[0,5,10.14],[1,4.9,30.77],[2,4.8,14.79]],"batl":[[0,5.3,9.24],[1,5.7,13.3],[2,6,11.96]],"ltp":0.0,"tv":0.0,"id":13117354}]}]}
{"op":"mcm","clk":"1004153172","pt":1580653634330,"mc":[{"id":"1.168224467","rc":[{"batb":[[0,4.9,30.77],[1,4.8,14.79],[2,4.4,11.76]],"ltp":0.0,"tv":0.0,"id":13117354}]}]}
{"op":"mcm","clk":"1004153751","pt":1580653637356,"mc":[{"id":"1.168224467","rc":[{"batb":[[0,4.9,41.02],[1,4.8,32.25]],"ltp":0.0,"tv":0.0,"id":13117354}]}]}
{"op":"mcm","clk":"1004154599","pt":1580653641360,"mc":[{"id":"1.168224467","rc":[{"batb":[[0,2.18,35.29],[1,2.1,24.47],[2,1.8,19.75]],"ltp":0.0,"tv":0.0,"id":13117353},{"batb":[[1,5.4,9.24],[2,4.7,15.19]],"ltp":0.0,"tv":0.0,"id":16604346},{"batb":[[0,4.9,13.85]],"ltp":0.0,"tv":0.0,"id":13117354}]}]}
{"op":"mcm","clk":"1004154656","pt":1580653641678,"mc":[{"id":"1.168224467","rc":[{"batb":[[1,1.8,19.75],[2,1.01,0.51]],"batl":[[0,2.46,28.57],[1,2.54,17.31],[2,2.54,0]],"ltp":0.0,"tv":0.0,"id":13117353},{"batb":[[0,5.4,9.24],[1,4.7,15.19],[2,1.01,0.51]],"batl":[[1,14.5,10.54],[2,14.5,0]],"ltp":0.0,"tv":0.0,"id":16604346},{"batb":[[0,4.8,32.25],[1,4.4,11.76],[2,1.01,0.51]],"batl":[[1,6,11.96],[2,6,0]],"ltp":0.0,"tv":0.0,"id":13117354}]}]}
{"op":"mcm","clk":"1004154984","pt":1580653643363,"mc":[{"id":"1.168224467","rc":[{"batb":[[0,1.8,19.75],[1,1.01,0.51],[2,1.01,0]],"batl":[[0,2.54,17.31],[1,2.54,0]],"ltp":0.0,"tv":0.0,"id":13117353},{"batb":[[1,4.8,19.88]],"batl":[[1,5.8,0]],"ltp":0.0,"tv":0.0,"id":16604347},{"batb":[[0,4.7,15.19],[1,1.01,0.51],[2,1.01,0]],"batl":[[0,14.5,10.54],[1,14.5,0]],"ltp":0.0,"tv":0.0,"id":16604346},{"batb":[[1,1.01,0.51],[2,1.01,0]],"batl":[[0,6,11.96],[1,6,0]],"ltp":0.0,"tv":0.0,"id":13117354}]}]}
{"op":"mcm","clk":"1004155155","pt":1580653644262,"mc":[{"id":"1.168224467","rc":[{"batb":[[0,1.82,43.06],[1,1.8,66.36],[2,1.01,0.51]],"ltp":0.0,"tv":0.0,"id":13117353},{"batb":[[1,4.5,21.07],[2,4.4,21.33]],"ltp":0.0,"tv":0.0,"id":16604346},{"batb":[[0,4.8,39.09],[1,4.7,18.37],[2,1.01,0.51]],"ltp":0.0,"tv":0.0,"id":13117354}]}]}
{"op":"mcm","clk":"1004156483","pt":1580653650389,"mc":[{"id":"1.168224467","rc":[{"batb":[[0,1.8,19.75],[1,1.01,0.51],[2,1.01,0]],"ltp":0.0,"tv":0.0,"id":13117353}]}]}
{"op":"mcm","clk":"1004157076","pt":1580653653381,"mc":[{"id":"1.168224467","rc":[{"batb":[[0,2.48,31.27],[1,2.44,37.5],[2,1.8,19.75]],"ltp":0.0,"tv":0.0,"id":13117353}]}]}
{"op":"mcm","clk":"1004157260","pt":1580653654269,"mc":[{"id":"1.168224467","rc":[{"batb":[[2,2.4,29.41]],"batl":[[1,2.72,24.37],[2,2.8,13.53]],"ltp":0.0,"tv":0.0,"id":13117353},{"batb":[[0,4.9,23.17]],"batl":[[1,5.9,8.4]],"ltp":0.0,"tv":0.0,"id":16604347},{"batb":[[2,4.4,33.09]],"batl":[[0,5.3,9.24],[1,5.5,14.56],[2,7.4,15.42]],"ltp":0.0,"tv":0.0,"id":16604346},{"batb":[[1,4.7,33.87],[2,4.2,12.6]],"batl":[[0,5.1,10.08],[1,5.6,14.16],[2,5.7,13.3]],"ltp":0.0,"tv":0.0,"id":13117354}]}]}
{"op":"mcm","clk":"1004159029","pt":1580653663301,"mc":[{"id":"1.168224467","rc":[{"batb":[[0,2.08,25.02],[1,1.01,0.51],[2,2.4,0]],"batl":[[0,2.8,13.53],[1,2.72,0],[2,2.8,0]],"ltp":0.0,"tv":0.0,"id":13117353},{"batb":[[0,4.9,13.09]],"batl":[[1,5.9,0]],"ltp":0.0,"tv":0.0,"id":16604347},{"batb":[[0,4.1,21.48],[1,1.01,0.51],[2,4.4,0]],"batl":[[0,7.4,15.42],[1,5.5,0],[2,7.4,0]],"ltp":0.0,"tv":0.0,"id":16604346},{"batb":[[0,4.8,10.83],[2,1.01,0.51]],"batl":[[0,5.7,13.3],[1,5.6,0],[2,5.7,0]],"ltp":0.0,"tv":0.0,"id":13117354}]}]}
{"op":"mcm","clk":"1004159540","pt":1580653665793,"mc":[{"id":"1.168224467","rc":[{"batb":[[0,2.16,34.18],[1,2.14,27.34],[2,2.08,25.02]],"ltp":0.0,"tv":0.0,"id":13117353},{"batb":[[1,3.9,27.18],[2,3.85,14.71]],"ltp":0.0,"tv":0.0,"id":16604346}]}]}
{"op":"mcm","clk":"1004160149","pt":1580653668679,"mc":[{"id":"1.168224467","rc":[{"batb":[[0,2.08,25.02],[1,1.01,0.51],[2,2.08,0]],"ltp":0.0,"tv":0.0,"id":13117353},{"batb":[[1,1.01,0.51],[2,3.85,0]],"ltp":0.0,"tv":0.0,"id":16604346}]}]}
{"op":"mcm","clk":"1004160890","pt":1580653672405,"mc":[{"id":"1.168224467","rc":[{"batb":[[0,2.74,20.46],[1,2.7,28.7],[2,2.58,39.82]],"batl":[[1,2.96,21],[2,3.05,11.09]],"ltp":0.0,"tv":0.0,"id":13117353},{"batb":[[0,4.9,23.17]],"batl":[[1,5.9,8.4]],"ltp":0.0,"tv":0.0,"id":16604347},{"batb":[[1,4,13.44],[2,3.9,27.18]],"batl":[[0,4.7,31.3],[1,5.6,14.16],[2,7.4,15.42]],"ltp":0.0,"tv":0.0,"id":16604346},{"batb":[[2,4.6,16.21]],"batl":[[0,5,10.08],[1,5.4,14.87],[2,5.6,14.08]],"ltp":0.0,"tv":0.0,"id":13117354}]}]}
{"op":"mcm","clk":"1004161051","pt":1580653673224,"mc":[{"id":"1.168224467","rc":[{"batb":[[2,2.58,13.77]],"batl":[[1,3.05,11.09],[2,3.05,0]],"ltp":0.0,"tv":0.0,"id":13117353},{"batb":[[0,4.9,13.09]],"ltp":0.0,"tv":0.0,"id":16604347},{"batb":[[1,3.9,27.18],[2,3.85,14.71]],"batl":[[2,7.4,0]],"ltp":0.0,"tv":0.0,"id":16604346}]}]}
{"op":"mcm","clk":"1004161399","pt":1580653675029,"mc":[{"id":"1.168224467","rc":[{"batb":[[2,2.6,26.05]],"ltp":0.0,"tv":0.0,"id":13117353},{"batb":[[1,4.8,30.8]],"ltp":0.0,"tv":0.0,"id":16604347},{"batb":[[1,3.95,13.44],[2,3.9,27.18]],"ltp":0.0,"tv":0.0,"id":16604346}]}]}
{"op":"mcm","clk":"1004161541","pt":1580653675629,"mc":[{"id":"1.168224467","rc":[{"batl":[[1,2.98,21],[2,3.05,11.09]],"ltp":0.0,"tv":0.0,"id":13117353}]}]}
{"op":"mcm","clk":"1004162236","pt":1580653678908,"mc":[{"id":"1.168224467","rc":[{"batb":[[0,2.6,26.05],[1,2.58,13.77],[2,2.32,18.1]],"ltp":0.0,"tv":0.0,"id":13117353},{"batb":[[2,3.9,14.4]],"ltp":0.0,"tv":0.0,"id":16604346},{"batb":[[0,4.7,33.87],[1,4.6,16.21],[2,4.2,12.6]],"ltp":0.0,"tv":0.0,"id":13117354}]}]}
{"op":"mcm","clk":"1004162914","pt":1580653682135,"mc":[{"id":"1.168224467","rc":[{"batb":[[0,2.72,23.9],[1,2.68,29.16],[2,2.6,26.05]],"ltp":0.0,"tv":0.0,"id":13117353},{"batb":[[0,4.9,17.37]],"ltp":0.0,"tv":0.0,"id":16604347},{"batb":[[1,3.95,34.16]],"ltp":0.0,"tv":0.0,"id":16604346},{"batb":[[0,4.7,40.06],[1,4.6,35.42]],"ltp":0.0,"tv":0.0,"id":13117354}]}]}
{"op":"mcm","clk":"1004163173","pt":1580653683348,"mc":[{"id":"1.168224467","rc":[{"batb":[[0,2.32,18.1],[1,1.01,0.51],[2,2.6,0]],"batl":[[0,3.05,11.09],[1,2.98,0],[2,3.05,0]],"ltp":0.0,"tv":0.0,"id":13117353},{"batb":[[0,4.9,13.35],[1,4.8,19.88]],"batl":[[1,5.9,0]],"ltp":0.0,"tv":0.0,"id":16604347},{"batb":[[0,3.75,13.14],[1,1.01,0.51],[2,3.9,0]],"batl":[[0,5.6,14.16],[1,5.6,0]],"ltp":0.0,"tv":0.0,"id":16604346},{"batb":[[0,4.7,18.37],[2,1.01,0.51]],"batl":[[0,5.6,14.08],[1,5.4,0],[2,5.6,0]],"ltp":0.0,"tv":0.0,"id":13117354}]}]}
{"op":"mcm","clk":"1004163855","pt":1580653686396,"mc":[{"id":"1.168224467","rc":[{"batb":[[0,2.44,34.06],[1,2.4,39.13],[2,2.34,17.7]],"batl":[[0,3.05,10.86]],"ltp":0.0,"tv":0.0,"id":13117353},{"batb":[[0,3.7,13.45],[1,3.65,19.45],[2,3.6,17.44]],"batl":[[0,5.5,14.48]],"ltp":0.0,"tv":0.0,"id":16604346},{"batb":[[1,4.6,35.1]],"batl":[[0,5.6,13.85]],"ltp":0.0,"tv":0.0,"id":13117354}]}]}
{"op":"mcm","clk":"1004164407","pt":1580653689247,"mc":[{"id":"1.168224467","rc":[{"batb":[[0,2.34,17.7],[1,1.01,0.51],[2,2.34,0]],"ltp":0.0,"tv":0.0,"id":13117353}]}]}
{"op":"mcm","clk":"1004165147","pt":1580653692322,"mc":[{"id":"1.168224467","rc":[{"batb":[[0,2.9,29.43],[1,2.86,24.61],[2,2.76,23.53]],"batl":[[1,3.2,18.48]],"ltp":0.0,"tv":0.0,"id":13117353},{"batb":[[1,4.8,30.8]],"batl":[[1,5.8,8.4]],"ltp":0.0,"tv":0.0,"id":16604347},{"batb":[[1,3.65,34.57]],"batl":[[0,4.3,12.6],[1,5.5,14.48]],"ltp":0.0,"tv":0.0,"id":16604346},{"batb":[[2,4.1,13.44]],"batl":[[0,5,10.08],[1,5.6,13.85]],"ltp":0.0,"tv":0.0,"id":13117354}]}]}
{"op":"mcm","clk":"1004165249","pt":1580653692819,"mc":[{"id":"1.168224467","rc":[{"batb":[[2,2.8,11.09]],"batl":[[2,3.55,19.43]],"ltp":0.0,"tv":0.0,"id":13117353},{"batb":[[2,4.5,16.52]],"batl":[[0,5.3,15.5]],"ltp":0.0,"tv":0.0,"id":16604347},{"batl":[[0,4.2,13.06],[1,4.3,12.6],[2,4.6,21.32]],"ltp":0.0,"tv":0.0,"id":16604346},{"batb":[[2,1.01,0.51]],"batl":[[1,5.4,14.79]],"ltp":0.0,"tv":0.0,"id":13117354}]}]}
{"op":"mcm","clk":"1004165727","pt":1580653695116,"mc":[{"id":"1.168224467","rc":[{"batb":[[2,4.2,12.6]],"ltp":0.0,"tv":0.0,"id":13117354}]}]}
{"op":"mcm","clk":"1004166295","pt":1580653697943,"mc":[{"id":"1.168224467","rc":[{"batb":[[0,4.7,13.61]],"ltp":0.0,"tv":0.0,"id":13117354}]}]}
{"op":"mcm","clk":"1004170389","pt":1580653719279,"mc":[{"id":"1.168224467","rc":[{"batb":[[0,2.8,11.09],[1,2.78,23.53],[2,2.62,13.14]],"ltp":0.0,"tv":0.0,"id":13117353},{"batb":[[0,4.9,13.09]],"ltp":0.0,"tv":0.0,"id":16604347},{"batb":[[1,3.65,15.12],[2,3.25,18.96]],"ltp":0.0,"tv":0.0,"id":16604346},{"batb":[[0,4.6,35.1],[1,4.2,12.6],[2,1.01,0.51]],"ltp":0.0,"tv":0.0,"id":13117354}]}]}
{"op":"mcm","clk":"1004170536","pt":1580653719992,"mc":[{"id":"1.168224467","rc":[{"batb":[[0,2.62,13.14],[1,1.01,0.51],[2,2.62,0]],"batl":[[0,3.55,19.43],[1,3.2,0],[2,3.55,0]],"ltp":0.0,"tv":0.0,"id":13117353},{"batb":[[1,4.8,19.88]],"batl":[[1,5.8,0]],"ltp":0.0,"tv":0.0,"id":16604347},{"batb":[[0,3.25,18.96],[1,1.01,0.51],[2,3.25,0]],"batl":[[0,4.6,21.32],[1,4.3,0],[2,4.6,0]],"ltp":0.0,"tv":0.0,"id":16604346},{"batb":[[1,1.01,0.51],[2,1.01,0]],"batl":[[0,5.4,14.79],[1,5.4,0]],"ltp":0.0,"tv":0.0,"id":13117354}]}]}
{"op":"mcm","clk":"1004170973","pt":1580653722275,"mc":[{"id":"1.168224467","rc":[{"batb":[[0,2.72,28.7],[1,2.68,29.12],[2,2.62,13.14]],"ltp":0.0,"tv":0.0,"id":13117353},{"batb":[[1,3.2,25.02],[2,3.15,24.12]],"ltp":0.0,"tv":0.0,"id":16604346},{"batb":[[1,4.5,20.16],[2,1.01,0.51]],"ltp":0.0,"tv":0.0,"id":13117354}]}]}
{"op":"mcm","clk":"1004171148","pt":1580653723298,"mc":[{"id":"1.168224467","rc":[{"batb":[[2,2.64,12.9]],"batl":[[0,3.5,19.51]],"ltp":0.0,"tv":0.0,"id":13117353},{"batb":[[0,3.25,18.8]],"ltp":0.0,"tv":0.0,"id":16604346},{"batb":[[0,4.6,19.21],[1,4.5,36.68]],"ltp":0.0,"tv":0.0,"id":13117354}]}]}
{"op":"mcm","clk":"1004174383","pt":1580653739603,"mc":[{"id":"1.168224467","rc":[{"batb":[[1,1.01,0.51],[2,3.15,0]],"ltp":0.0,"tv":0.0,"id":16604346},{"batb":[[1,4.5,16.52]],"ltp":0.0,"tv":0.0,"id":13117354}]}]}
{"op":"mcm","clk":"1004175171","pt":1580653743217,"mc":[{"id":"1.168224467","rc":[{"batl":[[0,2.88,12.67],[1,3.2,24.31],[2,3.5,19.51]],"ltp":0.0,"tv":0.0,"id":13117353},{"batb":[[0,4.9,17.84]],"batl":[[1,5.4,15.26]],"ltp":0.0,"tv":0.0,"id":16604347},{"batb":[[0,4,22.58],[1,3.95,21.9],[2,3.9,14.44]],"batl":[[1,5,18.1]],"ltp":0.0,"tv":0.0,"id":16604346},{"batb":[[0,4.7,19.31],[1,4.6,35.34],[2,4.5,16.52]],"ltp":0.0,"tv":0.0,"id":13117354}]}]}
{"op":"mcm","clk":"1004175442","pt":1580653744415,"mc":[{"id":"1.168224467","rc":[{"batb":[[1,2.68,53.49]],"batl":[[1,3.05,20.16],[2,3.2,24.31]],"ltp":0.0,"tv":0.0,"id":13117353},{"batb":[[1,4.8,30.8]],"batl":[[0,5.4,15.26],[1,5.7,8.4]],"ltp":0.0,"tv":0.0,"id":16604347},{"batl":[[0,4.6,32.25]],"ltp":0.0,"tv":0.0,"id":16604346},{"batb":[[2,4.2,12.6]],"batl":[[0,5,10.08],[1,5.4,14.79]],"ltp":0.0,"tv":0.0,"id":13117354}]}]}
{"op":"mcm","clk":"1004176981","pt":1580653751243,"mc":[{"id":"1.168224467","rc":[{"batb":[[0,2.68,24.37],[1,2.5,14.79],[2,1.01,0.51]],"batl":[[0,3.05,20.16],[1,3.2,24.31],[2,3.2,0]],"ltp":0.0,"tv":0.0,"id":13117353},{"batb":[[0,4.9,13.09]],"ltp":0.0,"tv":0.0,"id":16604347},{"batb":[[0,3.85,14.28],[1,3.55,14.87],[2,1.01,0.51]],"batl":[[0,4.6,10.92]],"ltp":0.0,"tv":0.0,"id":16604346},{"batb":[[0,4.7,12.09]],"ltp":0.0,"tv":0.0,"id":13117354}]}]}
{"op":"mcm","clk":"1004177096","pt":1580653751728,"mc":[{"id":"1.168224467","rc":[{"batb":[[0,2.5,14.79],[1,1.01,0.51],[2,1.01,0]],"batl":[[0,3.2,24.31],[1,3.2,0]],"ltp":0.0,"tv":0.0,"id":13117353},{"batb":[[1,4.8,19.88]],"batl":[[1,5.7,0]],"ltp":0.0,"tv":0.0,"id":16604347},{"batb":[[0,3.55,14.87],[1,1.01,0.51],[2,1.01,0]],"batl":[[0,5,18.1],[1,5,0]],"ltp":0.0,"tv":0.0,"id":16604346},{"batb":[[2,1.01,0.51]],"batl":[[0,5.4,14.79],[1,5.4,0]],"ltp":0.0,"tv":0.0,"id":13117354}]}]}
{"op":"mcm","clk":"1004177579","pt":1580653754138,"mc":[{"id":"1.168224467","rc":[{"batb":[[0,2.6,26.56],[1,2.56,32.9],[2,2.5,14.79]],"ltp":0.0,"tv":0.0,"id":13117353},{"batb":[[1,3.5,31.85],[2,3.45,19.25]],"ltp":0.0,"tv":0.0,"id":16604346}]}]}
{"op":"mcm","clk":"1004179315","pt":1580653761929,"mc":[{"id":"1.168224467","rc":[{"batb":[[1,1.01,0.51],[2,3.45,0]],"ltp":0.0,"tv":0.0,"id":16604346}]}]}
{"op":"mcm","clk":"1004179997","pt":1580653765326,"mc":[{"id":"1.168224467","rc":[{"batl":[[0,2.72,14.48],[1,2.94,11.96],[2,3.2,24.31]],"ltp":0.0,"tv":0.0,"id":13117353},{"batb":[[0,4.9,20.83]],"ltp":0.0,"tv":0.0,"id":16604347},{"batb":[[0,4.3,18.96],[1,4.2,25.63],[2,4.1,25.32]],"batl":[[1,5.3,15.58]],"ltp":0.0,"tv":0.0,"id":16604346},{"batb":[[0,4.7,38.8]],"batl":[[1,5.5,14.4]],"ltp":0.0,"tv":0.0,"id":13117354}]}]}
{"op":"mcm","clk":"1004180222","pt":1580653766347,"mc":[{"id":"1.168224467","rc":[{"batb":[[1,2.56,59.79]],"batl":[[1,2.94,32.96],[2,3.2,0]],"ltp":0.0,"tv":0.0,"id":13117353},{"batb":[[1,4.8,30.8]],"batl":[[0,5.4,15.11],[1,5.8,8.4]],"ltp":0.0,"tv":0.0,"id":16604347},{"batb":[[2,4.1,38.76]],"batl":[[0,4.9,10.08],[1,5,18.1],[2,5.3,15.58]],"ltp":0.0,"tv":0.0,"id":16604346},{"batb":[[1,4.6,19.21],[2,4.2,12.6]],"batl":[[0,5,10.08]],"ltp":0.0,"tv":0.0,"id":13117354}]}]}
{"op":"mcm","clk":"1004182872","pt":1580653779400,"mc":[{"id":"1.168224467","rc":[{"batb":[[0,2.56,26.89],[1,2.5,14.79],[2,2.4,16.52]],"ltp":0.0,"tv":0.0,"id":13117353},{"batb":[[0,4.9,13.09]],"ltp":0.0,"tv":0.0,"id":16604347},{"batb":[[1,4.1,13.44],[2,3.9,24.23]],"ltp":0.0,"tv":0.0,"id":16604346}]}]}
{"op":"mcm","clk":"1004182906","pt":1580653779599,"mc":[{"id":"1.168224467","rc":[{"batb":[[0,2.4,16.52],[1,1.01,0.51],[2,2.4,0]],"batl":[[0,2.94,11.96],[1,2.94,0]],"ltp":0.0,"tv":0.0,"id":13117353},{"batb":[[1,4.8,19.88]],"batl":[[1,5.8,0]],"ltp":0.0,"tv":0.0,"id":16604347},{"batb":[[0,3.9,24.23],[1,1.01,0.51],[2,3.9,0]],"batl":[[0,5.3,15.58],[1,5,0],[2,5.3,0]],"ltp":0.0,"tv":0.0,"id":16604346},{"batb":[[2,1.01,0.51]],"batl":[[0,5.5,14.4],[1,5.5,0]],"ltp":0.0,"tv":0.0,"id":13117354}]}]}
{"op":"mcm","clk":"1004183552","pt":1580653782391,"mc":[{"id":"1.168224467","rc":[{"batb":[[0,2.52,27.17],[1,2.48,35.83],[2,2.4,16.52]],"ltp":0.0,"tv":0.0,"id":13117353},{"batb":[[0,3.9,37.71],[1,3.85,14.96],[2,1.01,0.51]],"ltp":0.0,"tv":0.0,"id":16604346}]}]}
{"op":"mcm","clk":"1004183936","pt":1580653784430,"mc":[{"id":"1.168224467","rc":[{"batb":[[0,2.4,16.52],[1,1.01,0.51],[2,2.4,0]],"ltp":0.0,"tv":0.0,"id":13117353},{"batb":[[0,3.9,24.23],[1,1.01,0.51],[2,1.01,0]],"ltp":0.0,"tv":0.0,"id":16604346}]}]}
{"op":"mcm","clk":"1004184514","pt":1580653787427,"mc":[{"id":"1.168224467","rc":[{"batb":[[0,2.64,20.38],[1,2.6,31.61],[2,2.4,16.52]],"ltp":0.0,"tv":0.0,"id":13117353},{"batb":[[0,4.9,19.17]],"ltp":0.0,"tv":0.0,"id":16604347},{"batb":[[0,4.1,32.86],[1,4,26.7],[2,3.9,24.23]],"ltp":0.0,"tv":0.0,"id":16604346}]}]}
{"op":"mcm","clk":"1004185646","pt":1580653793563,"mc":[{"id":"1.168224467","rc":[{"batb":[[0,2.4,16.52],[1,1.01,0.51],[2,2.4,0]],"ltp":0.0,"tv":0.0,"id":13117353},{"batb":[[0,4.9,13.09]],"ltp":0.0,"tv":0.0,"id":16604347},{"batb":[[0,3.9,24.23],[1,1.01,0.51],[2,3.9,0]],"ltp":0.0,"tv":0.0,"id":16604346}]}]}
{"op":"mcm","clk":"1004186204","pt":1580653796407,"mc":[{"id":"1.168224467","rc":[{"batb":[[0,2.52,27.17],[1,2.48,35.83],[2,2.4,16.52]],"ltp":0.0,"tv":0.0,"id":13117353},{"batb":[[0,3.9,37.71],[1,3.85,14.96],[2,1.01,0.51]],"ltp":0.0,"tv":0.0,"id":16604346}]}]}
{"op":"mcm","clk":"1004186701","pt":1580653798943,"mc":[{"id":"1.168224467","rc":[{"batb":[[0,2.4,16.52],[1,1.01,0.51],[2,2.4,0]],"ltp":0.0,"tv":0.0,"id":13117353}]}]}
{"op":"mcm","clk":"1004187426","pt":1580653802448,"mc":[{"id":"1.168224467","rc":[{"batb":[[0,2.78,18.9],[1,2.74,27.54],[2,2.68,24.37]],"batl":[[1,3.1,19.32]],"ltp":0.0,"tv":0.0,"id":13117353},{"batb":[[2,4.7,10.92]],"batl":[[1,5.7,8.4]],"ltp":0.0,"tv":0.0,"id":16604347},{"batb":[[1,3.85,29.24]],"batl":[[0,4.5,11.76],[1,5.3,15.58]],"ltp":0.0,"tv":0.0,"id":16604346},{"batb":[[2,4.2,12.6]],"batl":[[0,5,10.08],[1,5.5,14.4]],"ltp":0.0,"tv":0.0,"id":13117354}]}]}
{"op":"mcm","clk":"1004187514","pt":1580653802865,"mc":[{"id":"1.168224467","rc":[{"batb":[[2,2.7,12.2]],"batl":[[2,3.35,22.03]],"ltp":0.0,"tv":0.0,"id":13117353},{"batl":[[0,5.3,15.74]],"ltp":0.0,"tv":0.0,"id":16604347},{"batb":[[2,3.4,16.68]],"batl":[[0,4.5,34.66],[1,4.9,18.65]],"ltp":0.0,"tv":0.0,"id":16604346},{"batb":[[0,4.7,23.22],[1,4.6,35.42]],"batl":[[1,5.4,14.87],[2,5.5,14.4]],"ltp":0.0,"tv":0.0,"id":13117354}]}]}
{"op":"mcm","clk":"1004191074","pt":1580653821378,"mc":[{"id":"1.168224467","rc":[{"batb":[[0,2.7,12.2],[1,2.68,24.37],[2,2.54,14.4]],"ltp":0.0,"tv":0.0,"id":13117353},{"batb":[[0,4.7,10.92],[1,4.5,16.52],[2,1.01,0.51]],"ltp":0.0,"tv":0.0,"id":16604347},{"batb":[[0,3.9,24.23],[1,3.85,14.28]],"ltp":0.0,"tv":0.0,"id":16604346},{"batb":[[0,4.6,16.21],[1,4.2,12.6],[2,1.01,0.51]],"ltp":0.0,"tv":0.0,"id":13117354}]}]}
{"op":"mcm","clk":"1004191161","pt":1580653821866,"mc":[{"id":"1.168224467","rc":[{"batb":[[0,2.54,14.4],[1,1.01,0.51],[2,2.54,0]],"batl":[[0,3.35,22.03],[1,3.1,0],[2,3.35,0]],"ltp":0.0,"tv":0.0,"id":13117353},{"batb":[[0,4.5,16.52],[1,1.01,0.51],[2,1.01,0]],"batl":[[1,5.7,0]],"ltp":0.0,"tv":0.0,"id":16604347},{"batb":[[0,3.4,16.68],[1,1.01,0.51],[2,3.4,0]],"batl":[[0,4.9,18.65],[1,4.9,0]],"ltp":0.0,"tv":0.0,"id":16604346},{"batb":[[1,1.01,0.51],[2,1.01,0]],"batl":[[0,5.5,14.4],[1,5.4,0],[2,5.5,0]],"ltp":0.0,"tv":0.0,"id":13117354}]}]}
{"op":"mcm","clk":"1004191600","pt":1580653824362,"mc":[{"id":"1.168224467","rc":[{"batb":[[0,2.62,25.08],[1,2.58,32.24],[2,2.54,14.4]],"ltp":0.0,"tv":0.0,"id":13117353},{"batb":[[0,4.8,26.52],[1,4.7,18.4],[2,4.5,16.52]],"ltp":0.0,"tv":0.0,"id":16604347},{"batb":[[0,3.4,37.89],[1,3.35,20.78],[2,1.01,0.51]],"ltp":0.0,"tv":0.0,"id":16604346},{"batb":[[0,4.6,46.53],[1,4.5,20.05],[2,1.01,0.51]],"ltp":0.0,"tv":0.0,"id":13117354}]}]}
{"op":"mcm","clk":"1004191723","pt":1580653825045,"mc":[{"id":"1.168224467","rc":[{"batb":[[2,2.52,14.56]],"ltp":0.0,"tv":0.0,"id":13117353},{"batl":[[0,5.3,15.58]],"ltp":0.0,"tv":0.0,"id":16604347},{"batb":[[0,3.4,37.73]],"batl":[[0,4.9,18.41]],"ltp":0.0,"tv":0.0,"id":16604346}]}]}
{"op":"mcm","clk":"1004192029","pt":1580653826677,"mc":[{"id":"1.168224467","rc":[{"batb":[[0,2.52,14.56],[1,1.01,0.51],[2,2.52,0]],"ltp":0.0,"tv":0.0,"id":13117353},{"batb":[[0,4.8,17.79],[1,4.5,16.52],[2,1.01,0.51]],"ltp":0.0,"tv":0.0,"id":16604347},{"batb":[[0,3.4,16.52],[1,1.01,0.51],[2,1.01,0]],"ltp":0.0,"tv":0.0,"id":16604346},{"batb":[[0,4.6,35.49],[1,1.01,0.51],[2,1.01,0]],"ltp":0.0,"tv":0.0,"id":13117354}]}]}
{"op":"mcm","clk":"1004192632","pt":1580653830153,"mc":[{"id":"1.168224467","rc":[{"batb":[[0,4.9,11.81],[1,4.8,17.79],[2,4.5,16.52]],"ltp":0.0,"tv":0.0,"id":16604347},{"batb":[[0,3.75,15.94],[1,3.4,16.52],[2,1.01,0.51]],"ltp":0.0,"tv":0.0,"id":16604346},{"batb":[[0,4.7,18.25],[1,4.6,35.49],[2,1.01,0.51]],"ltp":0.0,"tv":0.0,"id":13117354}]}]}
{"op":"mcm","clk":"1004193189","pt":1580653833282,"mc":[{"id":"1.168224467","rc":[{"batb":[[0,3.4,16.52],[1,1.01,0.51],[2,1.01,0]],"ltp":0.0,"tv":0.0,"id":16604346},{"batb":[[0,4.6,35.49],[1,1.01,0.51],[2,1.01,0]],"ltp":0.0,"tv":0.0,"id":13117354}]}]}
{"op":"mcm","clk":"1004193578","pt":1580653835581,"mc":[{"id":"1.168224467","rc":[{"batb":[[0,2.62,21.56],[1,2.58,32.23],[2,2.52,14.56]],"ltp":0.0,"tv":0.0,"id":13117353},{"batb":[[0,3.4,40.66],[1,3.35,20.78],[2,1.01,0.51]],"ltp":0.0,"tv":0.0,"id":16604346},{"batb":[[0,4.6,44.75],[1,4.5,20.06],[2,1.01,0.51]],"ltp":0.0,"tv":0.0,"id":13117354}]}]}
{"op":"mcm","clk":"1004193937","pt":1580653837673,"mc":[{"id":"1.168224467","rc":[{"batb":[[0,2.52,14.56],[1,1.01,0.51],[2,2.52,0]],"ltp":0.0,"tv":0.0,"id":13117353}]}]}
{"op":"mcm","clk":"1004194453","pt":1580653840411,"mc":[{"id":"1.168224467","rc":[{"batb":[[0,3.1,25.33],[1,3.05,25.99],[2,2.52,14.56]],"ltp":0.0,"tv":0.0,"id":13117353}]}]}
{"op":"mcm","clk":"1004194630","pt":1580653841270,"mc":[{"id":"1.168224467","rc":[{"batb":[[2,3,23.21]],"batl":[[1,4.3,25.49]],"ltp":0.0,"tv":0.0,"id":13117353},{"batb":[[2,2.86,10.54]],"batl":[[0,3.85,15.89],[1,4.5,22.74],[2,4.9,18.41]],"ltp":0.0,"tv":0.0,"id":16604346},{"batb":[[2,4.4,17.7]],"batl":[[0,5.3,15.66],[1,5.4,15.19],[2,5.5,14.4]],"ltp":0.0,"tv":0.0,"id":13117354}]}]}
{"op":"mcm","clk":"1004194817","pt":1580653842419,"mc":[{"id":"1.168224467","rc":[{"batl":[[1,3.45,16.8],[2,4.3,25.49]],"ltp":0.0,"tv":0.0,"id":13117353},{"batb":[[2,4.7,10.92]],"batl":[[1,5.6,8.4]],"ltp":0.0,"tv":0.0,"id":16604347},{"batb":[[0,3.4,57.47]],"batl":[[1,4,13.44],[2,4.5,22.74]],"ltp":0.0,"tv":0.0,"id":16604346},{"batb":[[0,4.6,28.54]],"batl":[[0,5,10.08],[1,5.3,15.66],[2,5.4,15.19]],"ltp":0.0,"tv":0.0,"id":13117354}]}]}
{"op":"mcm","clk":"1004197974","pt":1580653859037,"mc":[{"id":"1.168224467","rc":[{"batb":[[0,2.96,21],[1,2.72,11.96],[2,1.01,0.51]],"batl":[[0,3.45,16.8],[1,4.3,25.49],[2,4.3,0]],"ltp":0.0,"tv":0.0,"id":13117353},{"batb":[[0,4.8,17.79],[1,4.7,10.92],[2,4.5,16.52]],"ltp":0.0,"tv":0.0,"id":16604347},{"batb":[[0,3.4,16.8],[1,2.86,10.54],[2,1.01,0.51]],"batl":[[0,4,13.44],[1,4.5,22.74],[2,4.5,0]],"ltp":0.0,"tv":0.0,"id":16604346},{"batb":[[0,4.5,20.06],[1,4.4,17.7],[2,4.2,12.6]],"batl":[[1,5.4,15.19],[2,5.4,0]],"ltp":0.0,"tv":0.0,"id":13117354}]}]}
{"op":"mcm","clk":"1004198069","pt":1580653859527,"mc":[{"id":"1.168224467","rc":[{"batb":[[0,2.72,11.96],[1,1.01,0.51],[2,1.01,0]],"batl":[[0,4.3,25.49],[1,4.3,0]],"ltp":0.0,"tv":0.0,"id":13117353},{"batb":[[1,4.5,16.52],[2,1.01,0.51]],"batl":[[1,5.6,0]],"ltp":0.0,"tv":0.0,"id":16604347},{"batb":[[0,2.86,10.54],[1,1.01,0.51],[2,1.01,0]],"batl":[[0,4.5,22.74],[1,4.5,0]],"ltp":0.0,"tv":0.0,"id":16604346},{"batb":[[2,1.01,0.51]],"batl":[[0,5.4,15.19],[1,5.4,0]],"ltp":0.0,"tv":0.0,"id":13117354}]}]}
{"op":"mcm","clk":"1004198392","pt":1580653861446,"mc":[{"id":"1.168224467","rc":[{"batb":[[0,2.78,22.48],[1,2.74,27.5],[2,2.72,11.96]],"ltp":0.0,"tv":0.0,"id":13117353},{"batb":[[0,4.8,27.25],[1,4.7,18.45],[2,4.5,16.52]],"ltp":0.0,"tv":0.0,"id":16604347},{"batb":[[1,2.8,23.34],[2,2.76,27.06]],"ltp":0.0,"tv":0.0,"id":16604346},{"batb":[[0,4.5,25.97],[1,4.4,38.81]],"ltp":0.0,"tv":0.0,"id":13117354}]}]}
{"op":"mcm","clk":"1004198499","pt":1580653862057,"mc":[{"id":"1.168224467","rc":[{"batb":[[2,2.7,12.12]],"batl":[[0,4.2,12.9]],"ltp":0.0,"tv":0.0,"id":13117353},{"batl":[[0,5.4,15.34]],"ltp":0.0,"tv":0.0,"id":16604347},{"batb":[[0,2.86,10.39]],"batl":[[0,4.5,22.42]],"ltp":0.0,"tv":0.0,"id":16604346}]}]}
{"op":"mcm","clk":"1004200656","pt":1580653873461,"mc":[{"id":"1.168224467","rc":[{"batb":[[0,2.7,12.12],[1,1.01,0.51],[2,2.7,0]],"ltp":0.0,"tv":0.0,"id":13117353},{"batb":[[0,4.8,17.79],[1,4.5,16.52],[2,1.01,0.51]],"ltp":0.0,"tv":0.0,"id":16604347}]}]}
{"op":"mcm","clk":"1004201330","pt":1580653876438,"mc":[{"id":"1.168224467","rc":[{"batb":[[0,3.95,19.26],[1,3.9,14.28],[2,3.65,15.12]],"batl":[[1,4.3,12.6]],"ltp":0.0,"tv":0.0,"id":13117353},{"batb":[[0,4.9,12.49],[1,4.8,17.79],[2,4.7,10.92]],"batl":[[1,5.6,8.4]],"ltp":0.0,"tv":0.0,"id":16604347},{"batb":[[0,2.88,21.85],[1,2.86,10.39],[2,2.8,23.34]],"batl":[[0,3.35,17.64],[1,4.5,22.42]],"ltp":0.0,"tv":0.0,"id":16604346},{"batb":[[2,4,13.44]],"batl":[[0,4.8,10.92],[1,5.4,15.19]],"ltp":0.0,"tv":0.0,"id":13117354}]}]}
{"op":"mcm","clk":"1004201523","pt":1580653877362,"mc":[{"id":"1.168224467","rc":[{"batb":[[2,3.75,13.3]],"batl":[[2,7.2,16.37]],"ltp":0.0,"tv":0.0,"id":13117353},{"batb":[[2,4.5,16.52]],"batl":[[0,5.4,15.03]],"ltp":0.0,"tv":0.0,"id":16604347},{"batl":[[0,3.15,25.49],[1,3.35,17.64],[2,3.75,16.6]],"ltp":0.0,"tv":0.0,"id":16604346},{"batb":[[2,4.2,20.22]],"batl":[[1,5.1,17.07],[2,5.3,15.82]],"ltp":0.0,"tv":0.0,"id":13117354}]}]}
{"op":"mcm","clk":"1004202102","pt":1580653880276,"mc":[{"id":"1.168224467","rc":[{"batb":[[2,4.6,10.92]],"ltp":0.0,"tv":0.0,"id":16604347}]}]}
{"op":"mcm","clk":"1004205486","pt":1580653896211,"mc":[{"id":"1.168224467","rc":[{"batb":[[0,3.9,14.28],[1,3.75,13.3],[2,3.65,15.12]],"ltp":0.0,"tv":0.0,"id":13117353},{"batb":[[2,2.26,19.51]],"ltp":0.0,"tv":0.0,"id":16604346},{"batb":[[0,4.5,20.33]],"ltp":0.0,"tv":0.0,"id":13117354}]}]}
{"op":"mcm","clk":"1004205865","pt":1580653898096,"mc":[{"id":"1.168224467","rc":[{"batb":[[0,3.65,15.12],[1,3.05,22.03],[2,1.01,0.51]],"batl":[[0,4.3,12.6],[1,7.2,16.37],[2,7.2,0]],"ltp":0.0,"tv":0.0,"id":13117353},{"batb":[[1,2.26,19.51],[2,1.01,0.51]],"batl":[[0,3.35,17.64],[1,3.75,16.6],[2,3.75,0]],"ltp":0.0,"tv":0.0,"id":16604346},{"batb":[[0,4.2,20.22],[1,4,13.44],[2,1.01,0.51]],"batl":[[1,5.3,15.82],[2,5.3,0]],"ltp":0.0,"tv":0.0,"id":13117354}]}]}
{"op":"mcm","clk":"1004206305","pt":1580653900195,"mc":[{"id":"1.168224467","rc":[{"batb":[[0,3.05,22.03],[1,1.01,0.51],[2,1.01,0]],"batl":[[0,7.2,16.37],[1,7.2,0]],"ltp":0.0,"tv":0.0,"id":13117353},{"batb":[[2,4.5,16.52]],"batl":[[1,5.6,0]],"ltp":0.0,"tv":0.0,"id":16604347},{"batb":[[0,2.26,19.51],[1,1.01,0.51],[2,1.01,0]],"batl":[[0,3.75,16.6],[1,3.75,0]],"ltp":0.0,"tv":0.0,"id":16604346},{"batb":[[1,1.01,0.51],[2,1.01,0]],"batl":[[0,5.3,15.82],[1,5.3,0]],"ltp":0.0,"tv":0.0,"id":13117354}]}]}
{"op":"mcm","clk":"1004206364","pt":1580653900495,"mc":[{"id":"1.168224467","rc":[{"batb":[[0,3.15,17.8],[1,3.1,24.93],[2,3.05,22.03]],"ltp":0.0,"tv":0.0,"id":13117353},{"batb":[[1,2.18,40.09],[2,2.16,26.75]],"ltp":0.0,"tv":0.0,"id":16604346},{"batb":[[0,4.3,18.53],[1,4.2,43.89],[2,1.01,0.51]],"ltp":0.0,"tv":0.0,"id":13117354}]}]}
{"op":"mcm","clk":"1004207022","pt":1580653903621,"mc":[{"id":"1.168224467","rc":[{"batb":[[1,1.01,0.51],[2,2.16,0]],"ltp":0.0,"tv":0.0,"id":16604346},{"batb":[[0,4.2,20.22],[1,1.01,0.51],[2,1.01,0]],"ltp":0.0,"tv":0.0,"id":13117354}]}]}
{"op":"mcm","clk":"1004207773","pt":1580653907286,"mc":[{"id":"1.168224467","rc":[{"batl":[[0,3.4,21.17],[1,4.4,24.31],[2,7.2,16.37]],"ltp":0.0,"tv":0.0,"id":13117353},{"batl":[[0,5.3,15.42],[1,5.4,15.03]],"ltp":0.0,"tv":0.0,"id":16604347},{"batb":[[0,3.35,45.46],[1,3.3,21.59],[2,2.82,10.94]],"batl":[[1,4.4,23.84]],"ltp":0.0,"tv":0.0,"id":16604346},{"batb":[[0,4.6,26.31],[1,4.5,36.52],[2,4.4,17.62]],"batl":[[1,5.4,15.19]],"ltp":0.0,"tv":0.0,"id":13117354}]}]}
{"op":"mcm","clk":"1004207985","pt":1580653908409,"mc":[{"id":"1.168224467","rc":[{"batb":[[2,3.05,42.2]],"batl":[[1,3.55,15.96],[2,4.4,24.31]],"ltp":0.0,"tv":0.0,"id":13117353},{"batb":[[2,4.6,10.92]],"batl":[[1,5.5,9.24]],"ltp":0.0,"tv":0.0,"id":16604347},{"batb":[[0,3.35,63.11]],"batl":[[1,3.9,14.28],[2,4.4,23.84]],"ltp":0.0,"tv":0.0,"id":16604346},{"batl":[[0,5.1,10.08],[1,5.3,15.82],[2,5.4,15.19]],"ltp":0.0,"tv":0.0,"id":13117354}]}]}
{"op":"mcm","clk":"1004209904","pt":1580653918406,"mc":[{"id":"1.168224467","rc":[{"batb":[[0,3.05,20.16],[1,2.74,11.57],[2,1.01,0.51]],"batl":[[0,3.55,15.96],[1,4.4,24.31],[2,4.4,0]],"ltp":0.0,"tv":0.0,"id":13117353},{"batb":[[0,3.35,17.64],[1,2.82,10.94],[2,1.01,0.51]],"batl":[[0,3.9,14.28],[1,4.4,23.84],[2,4.4,0]],"ltp":0.0,"tv":0.0,"id":16604346},{"batb":[[0,4.5,20],[1,4.4,17.62],[2,4.2,12.6]],"batl":[[1,5.4,15.19],[2,5.4,0]],"ltp":0.0,"tv":0.0,"id":13117354}]}]}
{"op":"mcm","clk":"1004210127","pt":1580653919528,"mc":[{"id":"1.168224467","rc":[{"batb":[[0,2.74,11.57],[1,1.01,0.51],[2,1.01,0]],"batl":[[0,4.4,24.31],[1,4.4,0]],"ltp":0.0,"tv":0.0,"id":13117353},{"batb":[[2,4.5,16.52]],"batl":[[1,5.5,0]],"ltp":0.0,"tv":0.0,"id":16604347},{"batb":[[0,2.82,10.94],[1,1.01,0.51],[2,1.01,0]],"batl":[[0,4.4,23.84],[1,4.4,0]],"ltp":0.0,"tv":0.0,"id":16604346},{"batb":[[2,1.01,0.51]],"batl":[[0,5.4,15.19],[1,5.4,0]],"ltp":0.0,"tv":0.0,"id":13117354}]}]}
{"op":"mcm","clk":"1004210611","pt":1580653922014,"mc":[{"id":"1.168224467","rc":[{"batb":[[0,2.8,25.15],[1,2.76,26.86],[2,2.74,11.57]],"batl":[[0,4.3,24.71]],"ltp":0.0,"tv":0.0,"id":13117353},{"batl":[[0,5.4,15.26]],"ltp":0.0,"tv":0.0,"id":16604347},{"batb":[[0,2.82,10.78],[1,2.78,18.98],[2,2.74,27.69]],"batl":[[0,4.4,23.45]],"ltp":0.0,"tv":0.0,"id":16604346},{"batb":[[0,4.5,24.18],[1,4.4,38.65]],"ltp":0.0,"tv":0.0,"id":13117354}]}]}
{"op":"mcm","clk":"1004211877","pt":1580653927917,"mc":[{"id":"1.168224467","rc":[{"batb":[[0,2.74,11.57],[1,1.01,0.51],[2,2.74,0]],"ltp":0.0,"tv":0.0,"id":13117353}]}]}
{"op":"mcm","clk":"1004212494","pt":1580653931123,"mc":[{"id":"1.168224467","rc":[{"batb":[[0,4,18.04],[1,3.95,13.8],[2,2.74,11.57]],"ltp":0.0,"tv":0.0,"id":13117353},{"batb":[[0,4.9,16.39]],"ltp":0.0,"tv":0.0,"id":16604347}]}]}
{"op":"mcm","clk":"1004212745","pt":1580653932423,"mc":[{"id":"1.168224467","rc":[{"batb":[[2,3.75,13.06]],"batl":[[1,4.4,11.76],[2,7.4,15.42]],"ltp":0.0,"tv":0.0,"id":13117353},{"batb":[[2,4.6,26.89]],"batl":[[0,5.4,14.87],[1,5.5,9.24]],"ltp":0.0,"tv":0.0,"id":16604347},{"batb":[[0,2.82,33.46]],"batl":[[0,3.1,10.54],[1,3.3,17.64],[2,3.75,17.07]],"ltp":0.0,"tv":0.0,"id":16604346},{"batb":[[2,4.2,20.3]],"batl":[[0,4.9,10.08],[1,5.1,17.07],[2,5.3,15.74]],"ltp":0.0,"tv":0.0,"id":13117354}]}]}
{"op":"mcm","clk":"1004215289","pt":1580653946351,"mc":[{"id":"1.168224467","rc":[{"batb":[[0,3.75,13.06],[1,3.7,15.12],[2,3.1,21.4]],"ltp":0.0,"tv":0.0,"id":13117353},{"batb":[[0,4.8,17.79],[1,4.6,26.89],[2,4.5,16.52]],"ltp":0.0,"tv":0.0,"id":16604347},{"batb":[[1,2.24,20.22],[2,1.01,0.51]],"ltp":0.0,"tv":0.0,"id":16604346},{"batb":[[0,4.4,17.62],[1,4.2,20.3],[2,4,13.44]],"ltp":0.0,"tv":0.0,"id":13117354}]}]}
{"op":"mcm","clk":"1004215421","pt":1580653947127,"mc":[{"id":"1.168224467","rc":[{"batb":[[0,3.7,15.12],[1,3.1,21.4],[2,1.01,0.51]],"batl":[[0,4.4,11.76],[1,7.4,15.42],[2,7.4,0]],"ltp":0.0,"tv":0.0,"id":13117353},{"batb":[[1,4.6,10.92]],"ltp":0.0,"tv":0.0,"id":16604347},{"batb":[[0,2.82,22.69]],"batl":[[0,3.3,17.64],[1,3.75,17.07],[2,3.75,0]],"ltp":0.0,"tv":0.0,"id":16604346},{"batb":[[0,4.2,20.3],[1,4,13.44],[2,1.01,0.51]],"batl":[[1,5.3,15.74],[2,5.3,0]],"ltp":0.0,"tv":0.0,"id":13117354}]}]}
{"op":"mcm","clk":"1004215517","pt":1580653947534,"mc":[{"id":"1.168224467","rc":[{"batb":[[0,3.1,21.4],[1,1.01,0.51],[2,1.01,0]],"batl":[[0,7.4,15.42],[1,7.4,0]],"ltp":0.0,"tv":0.0,"id":13117353},{"batb":[[1,4.5,16.52],[2,1.01,0.51]],"batl":[[1,5.5,0]],"ltp":0.0,"tv":0.0,"id":16604347},{"batb":[[0,2.24,20.22],[1,1.01,0.51],[2,1.01,0]],"batl":[[0,3.75,17.07],[1,3.75,0]],"ltp":0.0,"tv":0.0,"id":16604346},{"batb":[[1,1.01,0.51],[2,1.01,0]],"batl":[[0,5.3,15.74],[1,5.3,0]],"ltp":0.0,"tv":0.0,"id":13117354}]}]}
{"op":"mcm","clk":"1004215843","pt":1580653949365,"mc":[{"id":"1.168224467","rc":[{"batb":[[0,3.2,17.17],[1,3.15,23.95],[2,3.1,21.4]],"ltp":0.0,"tv":0.0,"id":13117353},{"batb":[[0,4.8,28.33],[1,4.7,18.49],[2,4.5,16.52]],"ltp":0.0,"tv":0.0,"id":16604347},{"batb":[[1,2.16,39.37],[2,2.14,27.5]],"ltp":0.0,"tv":0.0,"id":16604346},{"batb":[[0,4.3,26.47],[1,4.2,43.82],[2,1.01,0.51]],"ltp":0.0,"tv":0.0,"id":13117354}]}]}
{"op":"mcm","clk":"1004215995","pt":1580653950246,"mc":[{"id":"1.168224467","rc":[{"batb":[[2,3.1,21.24]],"ltp":0.0,"tv":0.0,"id":13117353},{"batb":[[2,4.6,16.44]],"ltp":0.0,"tv":0.0,"id":16604347},{"batb":[[1,4.2,43.27]],"batl":[[0,5.2,16.21]],"ltp":0.0,"tv":0.0,"id":13117354}]}]}
{"op":"mcm","clk":"1004217386","pt":1580653957979,"mc":[{"id":"1.168224467","rc":[{"batb":[[1,1.01,0.51],[2,2.14,0]],"ltp":0.0,"tv":0.0,"id":16604346},{"batb":[[0,4.2,19.75],[1,1.01,0.51],[2,1.01,0]],"ltp":0.0,"tv":0.0,"id":13117354}]}]}
{"op":"mcm","clk":"1004217986","pt":1580653961252,"mc":[{"id":"1.168224467","rc":[{"batb":[[0,3.15,23.95],[1,3.1,21.24],[2,1.01,0.51]],"ltp":0.0,"tv":0.0,"id":13117353},{"batb":[[0,4.8,17.9],[1,4.6,16.44],[2,1.01,0.51]],"ltp":0.0,"tv":0.0,"id":16604347},{"batb":[[0,3.3,26.85],[1,3.25,22.44],[2,2.24,20.22]],"ltp":0.0,"tv":0.0,"id":16604346},{"batb":[[0,4.6,22.97],[1,4.5,19.95],[2,4.2,19.75]],"ltp":0.0,"tv":0.0,"id":13117354}]}]}
{"op":"mcm","clk":"1004218215","pt":1580653962449,"mc":[{"id":"1.168224467","rc":[{"batb":[[1,3.1,40.57],[2,2.8,11.09]],"batl":[[0,3.45,20.46],[1,3.6,15.96],[2,4.4,23.29]],"ltp":0.0,"tv":0.0,"id":13117353},{"batb":[[1,4.5,28.29]],"batl":[[0,5.4,24.11]],"ltp":0.0,"tv":0.0,"id":16604347},{"batb":[[0,3.35,17.62],[1,3.3,44.49],[2,3.25,22.44]],"batl":[[1,3.85,14.28],[2,4.3,25.34]],"ltp":0.0,"tv":0.0,"id":16604346},{"batb":[[1,4.5,36.95],[2,4.4,17.7]],"batl":[[0,5.1,10.08],[1,5.2,16.21],[2,5.3,15.58]],"ltp":0.0,"tv":0.0,"id":13117354}]}]}
{"op":"mcm","clk":"1004218546","pt":1580653964262,"mc":[{"id":"1.168224467","rc":[{"batb":[[0,3.15,32.63],[1,3.1,65.26]],"ltp":0.0,"tv":0.0,"id":13117353},{"batb":[[0,4.9,15.45],[1,4.8,17.9],[2,4.5,28.29]],"ltp":0.0,"tv":0.0,"id":16604347},{"batb":[[1,3.3,53.28]],"ltp":0.0,"tv":0.0,"id":16604346}]}]}
{"op":"mcm","clk":"1004221057","pt":1580653978213,"mc":[{"id":"1.168224467","rc":[{"batb":[[0,3.1,19.32],[1,2.8,11.09],[2,1.01,0.51]],"batl":[[0,3.6,15.96],[1,4.4,23.29],[2,4.4,0]],"ltp":0.0,"tv":0.0,"id":13117353},{"batb":[[0,3.3,17.64],[1,2.78,11.33],[2,1.01,0.51]],"batl":[[0,3.85,14.28],[1,4.3,25.34],[2,4.3,0]],"ltp":0.0,"tv":0.0,"id":16604346},{"batb":[[0,4.5,19.95],[1,4.4,17.7],[2,4.2,12.6]],"batl":[[1,5.3,15.58],[2,5.3,0]],"ltp":0.0,"tv":0.0,"id":13117354}]}]}
{"op":"mcm","clk":"1004221359","pt":1580653979623,"mc":[{"id":"1.168224467","rc":[{"batb":[[0,2.8,11.09],[1,1.01,0.51],[2,1.01,0]],"batl":[[0,4.4,23.29],[1,4.4,0]],"ltp":0.0,"tv":0.0,"id":13117353},{"batb":[[2,4.5,16.52]],"batl":[[0,5.4,14.87]],"ltp":0.0,"tv":0.0,"id":16604347},{"batb":[[0,2.78,11.33],[1,1.01,0.51],[2,1.01,0]],"batl":[[0,4.3,25.34],[1,4.3,0]],"ltp":0.0,"tv":0.0,"id":16604346},{"batb":[[2,1.01,0.51]],"batl":[[0,5.3,15.58],[1,5.3,0]],"ltp":0.0,"tv":0.0,"id":13117354}]}]}
{"op":"mcm","clk":"1004221696","pt":1580653981196,"mc":[{"id":"1.168224467","rc":[{"batb":[[0,2.82,27.83],[1,2.78,37.51],[2,1.01,0.51]],"ltp":0.0,"tv":0.0,"id":13117353},{"batb":[[2,4.6,16.29]],"ltp":0.0,"tv":0.0,"id":16604347},{"batb":[[0,2.8,11.17],[1,2.74,28.99],[2,2.7,28.79]],"batl":[[0,4.3,24.55]],"ltp":0.0,"tv":0.0,"id":16604346},{"batb":[[1,4.4,38.66]],"ltp":0.0,"tv":0.0,"id":13117354}]}]}
{"op":"mcm","clk":"1004222201","pt":1580653983802,"mc":[{"id":"1.168224467","rc":[{"batb":[[0,2.78,11.25],[1,1.01,0.51],[2,1.01,0]],"ltp":0.0,"tv":0.0,"id":13117353},{"batb":[[1,1.01,0.51],[2,2.7,0]],"ltp":0.0,"tv":0.0,"id":16604346},{"batb":[[0,4.4,17.7],[1,1.01,0.51],[2,1.01,0]],"ltp":0.0,"tv":0.0,"id":13117354}]}]}
{"op":"mcm","clk":"1004222805","pt":1580653986780,"mc":[{"id":"1.168224467","rc":[{"batb":[[0,2.82,27.83],[1,2.78,37.51],[2,1.01,0.51]],"ltp":0.0,"tv":0.0,"id":13117353},{"batb":[[0,3.8,18.06],[1,3.75,16.03],[2,2.8,11.17]],"ltp":0.0,"tv":0.0,"id":16604346},{"batb":[[0,4.7,15.14],[1,4.6,19.12],[2,4.4,17.7]],"ltp":0.0,"tv":0.0,"id":13117354}]}]}
{"op":"mcm","clk":"1004223109","pt":1580653988419,"mc":[{"id":"1.168224467","rc":[{"batb":[[1,2.78,61.04],[2,2.58,13.61]],"batl":[[0,3.05,11.09],[1,3.25,18.48],[2,3.5,19.83]],"ltp":0.0,"tv":0.0,"id":13117353},{"batl":[[0,5.3,15.42],[1,5.4,9.24]],"ltp":0.0,"tv":0.0,"id":16604347},{"batb":[[1,3.75,29.01],[2,3.65,15.12]],"batl":[[0,4.3,37.15],[1,4.8,19.28]],"ltp":0.0,"tv":0.0,"id":16604346},{"batb":[[2,4.5,16.76]],"batl":[[0,5.2,9.24],[1,5.3,15.58]],"ltp":0.0,"tv":0.0,"id":13117354}]}]}
{"op":"mcm","clk":"1004225332","pt":1580653999400,"mc":[{"id":"1.168224467","rc":[{"batb":[[0,2.78,23.53],[1,2.58,13.61],[2,1.01,0.51]],"batl":[[0,3.25,18.48],[1,3.5,19.83],[2,3.5,0]],"ltp":0.0,"tv":0.0,"id":13117353},{"batb":[[0,3.65,15.12],[1,3.25,18.65],[2,1.01,0.51]],"batl":[[0,4.3,12.6]],"ltp":0.0,"tv":0.0,"id":16604346},{"batb":[[0,4.6,19.12],[1,4.5,16.76],[2,4.3,12.6]],"ltp":0.0,"tv":0.0,"id":13117354}]}]}
{"op":"mcm","clk":"1004225349","pt":1580653999533,"mc":[{"id":"1.168224467","rc":[{"batb":[[0,2.58,13.61],[1,1.01,0.51],[2,1.01,0]],"batl":[[0,3.5,19.83],[1,3.5,0]],"ltp":0.0,"tv":0.0,"id":13117353},{"batl":[[1,5.4,0]],"ltp":0.0,"tv":0.0,"id":16604347},{"batb":[[0,3.25,18.65],[1,1.01,0.51],[2,1.01,0]],"batl":[[0,4.8,19.28],[1,4.8,0]],"ltp":0.0,"tv":0.0,"id":16604346},{"batb":[[2,1.01,0.51]],"batl":[[0,5.3,15.58],[1,5.3,0]],"ltp":0.0,"tv":0.0,"id":13117354}]}]}
{"op":"mcm","clk":"1004225871","pt":1580654002212,"mc":[{"id":"1.168224467","rc":[{"batb":[[0,2.64,29.89],[1,2.6,31.25],[2,2.58,13.61]],"ltp":0.0,"tv":0.0,"id":13117353},{"batb":[[0,3.25,51.57],[1,3.2,23.34],[2,1.01,0.51]],"ltp":0.0,"tv":0.0,"id":16604346},{"batb":[[0,4.6,25.87],[1,4.5,36.66]],"ltp":0.0,"tv":0.0,"id":13117354}]}]}
{"op":"mcm","clk":"1004226915","pt":1580654007619,"mc":[{"id":"1.168224467","rc":[{"batb":[[0,2.58,13.61],[1,1.01,0.51],[2,2.58,0]],"ltp":0.0,"tv":0.0,"id":13117353}]}]}
{"op":"mcm","clk":"1004227631","pt":1580654011329,"mc":[{"id":"1.168224467","rc":[{"batb":[[0,3.2,33.63],[1,3.15,44.25],[2,2.84,10.7]],"batl":[[1,4.5,22.27]],"ltp":0.0,"tv":0.0,"id":13117353},{"batl":[[1,5.4,15.11]],"ltp":0.0,"tv":0.0,"id":16604347},{"batb":[[2,2.74,11.72]],"batl":[[0,3.65,18.02],[1,4.2,13.22],[2,4.8,19.28]],"ltp":0.0,"tv":0.0,"id":16604346},{"batb":[[2,4.4,17.86]],"ltp":0.0,"tv":0.0,"id":13117354}]}]}
{"op":"mcm","clk":"1004227689","pt":1580654011637,"mc":[{"id":"1.168224467","rc":[{"batb":[[2,4.5,16.6]],"batl":[[0,5.4,15.11],[1,5.4,0]],"ltp":0.0,"tv":0.0,"id":16604347},{"batl":[[2,4.8,0]],"ltp":0.0,"tv":0.0,"id":16604346}]}]}
{"op":"mcm","clk":"1004228016","pt":1580654013237,"mc":[{"id":"1.168224467","rc":[{"batb":[[2,3.1,19.32]],"batl":[[1,3.65,15.12],[2,4.5,22.27]],"ltp":0.0,"tv":0.0,"id":13117353},{"batb":[[2,4.5,28.36]],"batl":[[0,5.4,24.35]],"ltp":0.0,"tv":0.0,"id":16604347},{"batb":[[0,3.25,70.05]],"batl":[[1,3.8,14.28],[2,4.2,13.22]],"ltp":0.0,"tv":0.0,"id":16604346},{"batl":[[0,5.1,10.08],[1,5.3,15.58]],"ltp":0.0,"tv":0.0,"id":13117354}]}]}
{"op":"mcm","clk":"1004231435","pt":1580654029877,"mc":[{"id":"1.168224467","rc":[{"batb":[[0,3.1,19.32],[1,2.84,10.7],[2,1.01,0.51]],"batl":[[0,3.65,15.12],[1,4.5,22.27],[2,4.5,0]],"ltp":0.0,"tv":0.0,"id":13117353},{"batb":[[0,4.8,17.9],[1,4.5,28.36],[2,1.01,0.51]],"ltp":0.0,"tv":0.0,"id":16604347},{"batb":[[0,3.25,18.48],[1,2.74,11.72],[2,1.01,0.51]],"batl":[[0,3.8,14.28],[1,4.2,13.22],[2,4.2,0]],"ltp":0.0,"tv":0.0,"id":16604346},{"batb":[[0,4.5,19.9],[1,4.4,17.86],[2,4.3,12.6]],"ltp":0.0,"tv":0.0,"id":13117354}]}]}
{"op":"mcm","clk":"1004231791","pt":1580654031559,"mc":[{"id":"1.168224467","rc":[{"batb":[[0,2.84,10.7],[1,1.01,0.51],[2,1.01,0]],"batl":[[0,4.5,22.27],[1,4.5,0]],"ltp":0.0,"tv":0.0,"id":13117353},{"batb":[[1,4.5,16.6]],"batl":[[0,5.4,15.11]],"ltp":0.0,"tv":0.0,"id":16604347},{"batb":[[0,2.74,11.72],[1,1.01,0.51],[2,1.01,0]],"batl":[[0,4.2,13.22],[1,4.2,0]],"ltp":0.0,"tv":0.0,"id":16604346},{"batb":[[2,1.01,0.51]],"batl":[[0,5.3,15.58],[1,5.3,0]],"ltp":0.0,"tv":0.0,"id":13117354}]}]}
{"op":"mcm","clk":"1004232143","pt":1580654033255,"mc":[{"id":"1.168224467","rc":[{"batb":[[0,2.86,22.95],[1,2.84,10.7],[2,2.82,25.3]],"ltp":0.0,"tv":0.0,"id":13117353},{"batb":[[0,4.9,12.02],[1,4.8,17.9],[2,4.5,16.6]],"ltp":0.0,"tv":0.0,"id":16604347},{"batb":[[1,2.72,19.75],[2,2.68,29.46]],"ltp":0.0,"tv":0.0,"id":16604346},{"batb":[[0,4.5,24.57],[1,4.4,38.74]],"ltp":0.0,"tv":0.0,"id":13117354}]}]}
{"op":"mcm","clk":"1004233371","pt":1580654039170,"mc":[{"id":"1.168224467","rc":[{"batb":[[0,2.84,10.7],[1,1.01,0.51],[2,2.82,0]],"ltp":0.0,"tv":0.0,"id":13117353}]}]}
{"op":"mcm","clk":"1004234035","pt":1580654042372,"mc":[{"id":"1.168224467","rc":[{"batb":[[0,4.1,19.81],[1,4,26.26],[2,2.84,10.7]],"ltp":0.0,"tv":0.0,"id":13117353},{"batb":[[0,4.9,21.62]],"ltp":0.0,"tv":0.0,"id":16604347}]}]}
{"op":"mcm","clk":"1004234249","pt":1580654043251,"mc":[{"id":"1.168224467","rc":[{"batb":[[2,3.95,23.45]],"batl":[[1,4.6,10.92],[2,7.8,14.48]],"ltp":0.0,"tv":0.0,"id":13117353},{"batb":[[2,4.6,15.82]],"batl":[[0,5.4,24.35],[1,5.5,14.63]],"ltp":0.0,"tv":0.0,"id":16604347},{"batb":[[0,2.74,35.25]],"batl":[[0,2.98,11.57],[1,3.2,18.48],[2,3.6,18.73]],"ltp":0.0,"tv":0.0,"id":16604346},{"batb":[[2,4.3,19.2]],"batl":[[0,5,10.08],[1,5.1,17],[2,5.2,16.13]],"ltp":0.0,"tv":0.0,"id":13117354}]}]}
{"op":"mcm","clk":"1004238053","pt":1580654061407,"mc":[{"id":"1.168224467","rc":[{"batb":[[0,3.85,14.28],[1,3.2,19.28],[2,1.01,0.51]],"batl":[[0,4.6,10.92],[1,7.8,14.48],[2,7.8,0]],"ltp":0.0,"tv":0.0,"id":13117353},{"batb":[[0,4.9,13.1],[2,4.5,28.36]],"batl":[[0,5.4,9.24]],"ltp":0.0,"tv":0.0,"id":16604347},{"batb":[[0,2.74,23.53],[1,2.18,21.64],[2,1.01,0.51]],"batl":[[0,3.2,18.48],[1,3.6,18.73],[2,3.6,0]],"ltp":0.0,"tv":0.0,"id":16604346},{"batb":[[0,4.3,19.2],[1,4.1,13.44],[2,1.01,0.51]],"batl":[[1,5.2,16.13],[2,5.2,0]],"ltp":0.0,"tv":0.0,"id":13117354}]}]}
{"op":"mcm","clk":"1004238126","pt":1580654061785,"mc":[{"id":"1.168224467","rc":[{"batb":[[0,3.2,19.28],[1,1.01,0.51],[2,1.01,0]],"batl":[[0,7.8,14.48],[1,7.8,0]],"ltp":0.0,"tv":0.0,"id":13117353},{"batb":[[2,4.5,16.6]],"batl":[[0,5.5,14.63],[1,5.5,0]],"ltp":0.0,"tv":0.0,"id":16604347},{"batb":[[0,2.18,21.64],[1,1.01,0.51],[2,1.01,0]],"batl":[[0,3.6,18.73],[1,3.6,0]],"ltp":0.0,"tv":0.0,"id":16604346},{"batb":[[1,1.01,0.51],[2,1.01,0]],"batl":[[0,5.2,16.13],[1,5.2,0]],"ltp":0.0,"tv":0.0,"id":13117354}]}]}
{"op":"mcm","clk":"1004238470","pt":1580654063508,"mc":[{"id":"1.168224467","rc":[{"batb":[[0,3.25,28.37],[1,3.2,42.08],[2,1.01,0.51]],"ltp":0.0,"tv":0.0,"id":13117353},{"batb":[[1,2.14,27.39],[2,2.12,28.38]],"ltp":0.0,"tv":0.0,"id":16604346},{"batb":[[0,4.3,51.94],[1,4.2,23.27],[2,1.01,0.51]],"ltp":0.0,"tv":0.0,"id":13117354}]}]}
{"op":"mcm","clk":"1004238997","pt":1580654066088,"mc":[{"id":"1.168224467","rc":[{"batb":[[0,3.2,19.28],[1,1.01,0.51],[2,1.01,0]],"ltp":0.0,"tv":0.0,"id":13117353},{"batb":[[1,4.8,17.79]],"ltp":0.0,"tv":0.0,"id":16604347},{"batb":[[1,1.01,0.51],[2,2.12,0]],"ltp":0.0,"tv":0.0,"id":16604346},{"batb":[[0,4.3,19.2],[1,1.01,0.51],[2,1.01,0]],"ltp":0.0,"tv":0.0,"id":13117354}]}]}
{"op":"mcm","clk":"1004240500","pt":1580654073793,"mc":[{"id":"1.168224467","rc":[{"batb":[[0,3.25,29.46],[1,3.2,42.08],[2,1.01,0.51]],"ltp":0.0,"tv":0.0,"id":13117353},{"batb":[[1,2.14,26.05],[2,2.12,28.38]],"ltp":0.0,"tv":0.0,"id":16604346},{"batb":[[0,4.3,51.9],[1,4.2,23.27],[2,1.01,0.51]],"ltp":0.0,"tv":0.0,"id":13117354}]}]}
{"op":"mcm","clk":"1004244611","pt":1580654093444,"mc":[{"id":"1.168224467","rc":[{"batb":[[0,3.2,19.28],[1,1.01,0.51],[2,1.01,0]],"ltp":0.0,"tv":0.0,"id":13117353},{"batb":[[1,4.5,16.6],[2,1.01,0.51]],"ltp":0.0,"tv":0.0,"id":16604347}]}]}
{"op":"mcm","clk":"1004245242","pt":1580654096428,"mc":[{"id":"1.168224467","rc":[{"batb":[[0,7.2,25.71],[1,7,14.46],[2,3.2,19.28]],"batl":[[1,9.2,5.04]],"ltp":0.0,"tv":0.0,"id":13117353},{"batb":[[0,5,19.2],[1,4.9,16.95],[2,4.5,28.36]],"batl":[[0,5.5,23.88]],"ltp":0.0,"tv":0.0,"id":16604347},{"batb":[[2,2.12,65.35]],"batl":[[0,2.36,30.25],[1,3.6,18.73]],"ltp":0.0,"tv":0.0,"id":16604346},{"batb":[[2,4.1,13.44]],"batl":[[0,4.9,10.08],[1,5.2,16.13]],"ltp":0.0,"tv":0.0,"id":13117354}]}]}
{"op":"mcm","clk":"1004245491","pt":1580654097434,"mc":[{"id":"1.168224467","rc":[{"batb":[[2,6.2,15.34]],"batl":[[2,9.4,9.52]],"ltp":0.0,"tv":0.0,"id":13117353},{"batb":[[2,4.6,15.66]],"batl":[[0,5.5,23.56]],"ltp":0.0,"tv":0.0,"id":16604347},{"batl":[[0,2.36,51.33],[1,2.6,16.13]],"ltp":0.0,"tv":0.0,"id":16604346},{"batb":[[0,4.3,32.7],[1,4.2,42.7]],"batl":[[1,5,18.1]],"ltp":0.0,"tv":0.0,"id":13117354}]}]}
{"op":"mcm","clk":"1004247157","pt":1580654105369,"mc":[{"id":"1.168224467","rc":[{"batb":[[2,6.4,14.79]],"batl":[[0,7.8,13.93],[2,9.6,9.21]],"ltp":0.0,"tv":0.0,"id":13117353},{"batl":[[0,2.34,21.4],[1,2.36,30.25],[2,2.6,16.13]],"ltp":0.0,"tv":0.0,"id":16604346}]}]}
{"op":"mcm","clk":"1004247575","pt":1580654107347,"mc":[{"id":"1.168224467","rc":[{"batb":[[2,1.01,0.51]],"batl":[[0,5,18.1],[1,5,0]],"ltp":0.0,"tv":0.0,"id":13117354}]}]}
{"op":"mcm","clk":"1004248226","pt":1580654110239,"mc":[{"id":"1.168224467","rc":[{"batb":[[2,4,13.44]],"batl":[[0,4.8,10.92],[1,5,18.1]],"ltp":0.0,"tv":0.0,"id":13117354}]}]}
{"op":"mcm","clk":"1004248394","pt":1580654111069,"mc":[{"id":"1.168224467","rc":[{"batb":[[2,1.01,0.51]],"ltp":0.0,"tv":0.0,"id":13117354}]}]}
{"op":"mcm","clk":"1004249019","pt":1580654113847,"mc":[{"id":"1.168224467","rc":[{"batb":[[2,4.1,13.44]],"ltp":0.0,"tv":0.0,"id":13117354}]}]}
{"op":"mcm","clk":"1004249472","pt":1580654116059,"mc":[{"id":"1.168224467","rc":[{"batb":[[2,1.01,0.51]],"ltp":0.0,"tv":0.0,"id":13117354}]}]}
{"op":"mcm","clk":"1004250127","pt":1580654118950,"mc":[{"id":"1.168224467","rc":[{"batb":[[2,4,13.44]],"ltp":0.0,"tv":0.0,"id":13117354}]}]}
{"op":"mcm","clk":"1004267396","pt":1580654202783,"mc":[{"id":"1.168224467","rc":[{"batb":[[0,7.2,6.72],[1,5.1,12.67],[2,1.01,0.51]],"batl":[[0,9.2,5.04],[1,9.6,9.21],[2,9.6,0]],"ltp":0.0,"tv":0.0,"id":13117353},{"batb":[[0,2.12,36.97],[1,2.06,25.57],[2,1.01,0.51]],"batl":[[0,2.36,30.25],[1,2.6,16.13],[2,2.6,0]],"ltp":0.0,"tv":0.0,"id":16604346},{"batb":[[0,4.3,28.25]],"ltp":0.0,"tv":0.0,"id":13117354}]}]}
{"op":"mcm","clk":"1004267626","pt":1580654203824,"mc":[{"id":"1.168224467","rc":[{"batb":[[0,5.1,12.67],[1,1.01,0.51],[2,1.01,0]],"batl":[[0,9.6,9.21],[1,9.6,0]],"ltp":0.0,"tv":0.0,"id":13117353},{"batl":[[0,5.5,14.32]],"ltp":0.0,"tv":0.0,"id":16604347},{"batb":[[0,2.06,25.57],[1,1.01,0.51],[2,1.01,0]],"batl":[[0,2.6,16.13],[1,2.6,0]],"ltp":0.0,"tv":0.0,"id":16604346},{"batb":[[2,1.01,0.51]],"batl":[[0,5,18.1],[1,5,0]],"ltp":0.0,"tv":0.0,"id":13117354}]}]}
{"op":"mcm","clk":"1004268025","pt":1580654205636,"mc":[{"id":"1.168224467","rc":[{"batb":[[0,5.6,14.94],[1,5.5,12.6],[2,5.1,12.67]],"ltp":0.0,"tv":0.0,"id":13117353},{"batb":[[1,2.04,32.91],[2,2.02,32.41]],"ltp":0.0,"tv":0.0,"id":16604346}]}]}
{"op":"mcm","clk":"1004269278","pt":1580654211428,"mc":[{"id":"1.168224467","rc":[{"batb":[[1,1.01,0.51],[2,2.02,0]],"ltp":0.0,"tv":0.0,"id":16604346}]}]}
{"op":"mcm","clk":"1004269916","pt":1580654214320,"mc":[{"id":"1.168224467","rc":[{"batb":[[0,2.34,30.63],[1,2.32,21.76],[2,2.06,25.57]],"ltp":0.0,"tv":0.0,"id":16604346}]}]}
{"op":"mcm","clk":"1004270176","pt":1580654215408,"mc":[{"id":"1.168224467","rc":[{"batb":[[0,5.7,8.4],[1,5.6,14.94],[2,5.5,12.6]],"batl":[[0,6,12.2],[1,7.2,6.72],[2,7.4,15.42]],"ltp":0.0,"tv":0.0,"id":13117353},{"batl":[[0,5.5,23.56]],"ltp":0.0,"tv":0.0,"id":16604347},{"batb":[[0,2.4,16.76],[1,2.34,30.63],[2,2.32,21.76]],"batl":[[0,2.58,26.05],[1,2.6,16.13],[2,2.98,11.57]],"ltp":0.0,"tv":0.0,"id":16604346},{"batb":[[2,4,13.44]],"batl":[[0,4.8,10.92],[1,5,18.1]],"ltp":0.0,"tv":0.0,"id":13117354}]}]}
{"op":"mcm","clk":"1004270200","pt":1580654215520,"mc":[{"id":"1.168224467","rc":[{"batl":[[1,5,17.86]],"ltp":0.0,"tv":0.0,"id":13117354}]}]}
{"op":"mcm","clk":"1004272420","pt":1580654225948,"mc":[{"id":"1.168224467","rc":[{"batb":[[0,4,22.42],[1,1.01,0.51],[2,5.5,0]],"batl":[[0,7.4,15.42],[1,7.2,0],[2,7.4,0]],"ltp":0.0,"tv":0.0,"id":13117353},{"batb":[[0,5,12.99]],"batl":[[0,5.5,14.32]],"ltp":0.0,"tv":0.0,"id":16604347},{"batb":[[0,2.22,20.69],[1,1.01,0.51],[2,2.32,0]],"batl":[[0,2.98,11.57],[1,2.6,0],[2,2.98,0]],"ltp":0.0,"tv":0.0,"id":16604346},{"batb":[[2,1.01,0.51]],"batl":[[0,5,17.86],[1,5,0]],"ltp":0.0,"tv":0.0,"id":13117354}]}]}
{"op":"mcm","clk":"1004272985","pt":1580654228862,"mc":[{"id":"1.168224467","rc":[{"batb":[[0,4.3,11.67],[1,4.2,23.41],[2,4,21.64]],"batl":[[0,7.6,14.87]],"ltp":0.0,"tv":0.0,"id":13117353},{"batb":[[0,2.2,21.01],[1,2.18,39.24],[2,2.16,26.62]],"batl":[[0,2.94,11.88]],"ltp":0.0,"tv":0.0,"id":16604346}]}]}
{"op":"mcm","clk":"1004273667","pt":1580654232316,"mc":[{"id":"1.168224467","rc":[{"batb":[[1,1.01,0.51],[2,2.16,0]],"ltp":0.0,"tv":0.0,"id":16604346},{"batb":[[0,4.3,21.94],[1,4.2,19.43]],"ltp":0.0,"tv":0.0,"id":13117354}]}]}
{"op":"mcm","clk":"1004274313","pt":1580654235369,"mc":[{"id":"1.168224467","rc":[{"batb":[[0,2.66,32.59],[1,2.62,31.1],[2,2.2,21.01]],"ltp":0.0,"tv":0.0,"id":16604346},{"batb":[[0,4.4,22.75],[1,4.3,21.94],[2,4.2,19.43]],"ltp":0.0,"tv":0.0,"id":13117354}]}]}
{"op":"mcm","clk":"1004274541","pt":1580654236414,"mc":[{"id":"1.168224467","rc":[{"batl":[[0,4.7,20.54],[1,5.6,14.08],[2,7.6,14.87]],"ltp":0.0,"tv":0.0,"id":13117353},{"batl":[[0,5.4,15.03],[1,5.5,14.32]],"ltp":0.0,"tv":0.0,"id":16604347},{"batb":[[0,2.7,12.12],[1,2.66,32.59],[2,2.62,31.1]],"batl":[[1,3.5,19.83]],"ltp":0.0,"tv":0.0,"id":16604346},{"batb":[[1,4.3,40.9]],"batl":[[1,5.1,16.92]],"ltp":0.0,"tv":0.0,"id":13117354}]}]}
{"op":"mcm","clk":"1004274625","pt":1580654236855,"mc":[{"id":"1.168224467","rc":[{"batl":[[2,7.6,0]],"ltp":0.0,"tv":0.0,"id":13117353},{"batl":[[0,5.4,24.27],[1,5.5,0]],"ltp":0.0,"tv":0.0,"id":16604347},{"batl":[[0,2.92,21.85],[1,2.94,11.88],[2,3.5,19.83]],"ltp":0.0,"tv":0.0,"id":16604346},{"batb":[[2,1.01,0.51]],"batl":[[0,4.9,10.08]],"ltp":0.0,"tv":0.0,"id":13117354}]}]}
{"op":"mcm","clk":"1004275093","pt":1580654239263,"mc":[{"id":"1.168224467","rc":[{"batl":[[1,5.4,9.24],[2,5.6,14.08]],"ltp":0.0,"tv":0.0,"id":13117353}]}]}
{"op":"mcm","clk":"1004275217","pt":1580654239862,"mc":[{"id":"1.168224467","rc":[{"batb":[[0,4.4,11.76],[1,4.3,11.67],[2,4.2,23.41]],"ltp":0.0,"tv":0.0,"id":13117353},{"batb":[[2,4,13.44]],"ltp":0.0,"tv":0.0,"id":13117354}]}]}
{"op":"mcm","clk":"1004276561","pt":1580654246040,"mc":[{"id":"1.168224467","rc":[{"batb":[[0,3.3,17.94],[1,1.01,0.51],[2,4.2,0]],"batl":[[0,5.6,14.08],[1,5.4,0],[2,5.6,0]],"ltp":0.0,"tv":0.0,"id":13117353},{"batl":[[0,5.4,15.03]],"ltp":0.0,"tv":0.0,"id":16604347},{"batb":[[0,2.46,15.5],[1,1.01,0.51],[2,2.62,0]],"batl":[[0,3.5,19.83],[1,2.94,0],[2,3.5,0]],"ltp":0.0,"tv":0.0,"id":16604346},{"batb":[[0,4.3,40.9],[1,1.01,0.51],[2,4,0]],"batl":[[0,5.1,16.92],[1,5.1,0]],"ltp":0.0,"tv":0.0,"id":13117354}]}]}
{"op":"mcm","clk":"1004277175","pt":1580654249065,"mc":[{"id":"1.168224467","rc":[{"batb":[[0,3.35,32.52],[1,3.3,38.85],[2,1.01,0.51]],"ltp":0.0,"tv":0.0,"id":13117353},{"batb":[[1,2.44,31.5],[2,2.4,39.32]],"ltp":0.0,"tv":0.0,"id":16604346},{"batb":[[0,4.3,52.36],[1,4.2,22.99],[2,1.01,0.51]],"ltp":0.0,"tv":0.0,"id":13117354}]}]}
{"op":"mcm","clk":"1004277828","pt":1580654252186,"mc":[{"id":"1.168224467","rc":[{"batb":[[0,3.3,17.94],[1,1.01,0.51],[2,1.01,0]],"ltp":0.0,"tv":0.0,"id":13117353}]}]}
{"op":"mcm","clk":"1004278545","pt":1580654255380,"mc":[{"id":"1.168224467","rc":[{"batb":[[0,5.1,14.26],[1,5,15.64],[2,3.3,17.94]],"ltp":0.0,"tv":0.0,"id":13117353}]}]}
{"op":"mcm","clk":"1004278612","pt":1580654255677,"mc":[{"id":"1.168224467","rc":[{"batb":[[2,4.8,14.63]],"batl":[[1,7.2,16.68]],"ltp":0.0,"tv":0.0,"id":13117353},{"batl":[[0,5.4,14.87]],"ltp":0.0,"tv":0.0,"id":16604347},{"batl":[[0,2.68,15.19],[1,3.2,24.47]],"ltp":0.0,"tv":0.0,"id":16604346},{"batb":[[1,4.2,42.82]],"batl":[[0,5,18.02],[1,5.1,16.92]],"ltp":0.0,"tv":0.0,"id":13117354}]}]}
{"op":"mcm","clk":"1004278919","pt":1580654257193,"mc":[{"id":"1.168224467","rc":[{"batb":[[0,5.1,24.34]],"batl":[[1,6.4,7.56],[2,7.2,16.68]],"ltp":0.0,"tv":0.0,"id":13117353},{"batl":[[1,5.5,9.24]],"ltp":0.0,"tv":0.0,"id":16604347},{"batb":[[2,2.4,68.73]],"batl":[[1,2.74,23.53],[2,3.2,24.47]],"ltp":0.0,"tv":0.0,"id":16604346},{"batb":[[2,4,13.44]],"batl":[[0,4.8,10.92],[1,5,18.02],[2,5.1,16.92]],"ltp":0.0,"tv":0.0,"id":13117354}]}]}
{"op":"mcm","clk":"1004280817","pt":1580654266178,"mc":[{"id":"1.168224467","rc":[{"batb":[[0,5.1,10.08],[1,3.65,13.85],[2,1.01,0.51]],"batl":[[0,6.4,7.56],[1,7.2,16.68],[2,7.2,0]],"ltp":0.0,"tv":0.0,"id":13117353},{"batb":[[0,2.4,29.41],[1,2.26,19.75],[2,1.01,0.51]],"batl":[[0,2.74,23.53],[1,3.2,24.47],[2,3.2,0]],"ltp":0.0,"tv":0.0,"id":16604346},{"batb":[[0,4.3,21.94]],"batl":[[1,5.1,16.92],[2,5.1,0]],"ltp":0.0,"tv":0.0,"id":13117354}]}]}
{"op":"mcm","clk":"1004281265","pt":1580654268372,"mc":[{"id":"1.168224467","rc":[{"batb":[[0,3.65,13.85],[1,1.01,0.51],[2,1.01,0]],"batl":[[0,7.2,16.68],[1,7.2,0]],"ltp":0.0,"tv":0.0,"id":13117353},{"batl":[[1,5.5,0]],"ltp":0.0,"tv":0.0,"id":16604347},{"batb":[[0,2.26,19.75],[1,1.01,0.51],[2,1.01,0]],"batl":[[0,3.2,24.47],[1,3.2,0]],"ltp":0.0,"tv":0.0,"id":16604346},{"batb":[[2,1.01,0.51]],"batl":[[0,5.1,16.92],[1,5.1,0]],"ltp":0.0,"tv":0.0,"id":13117354}]}]}
{"op":"mcm","clk":"1004281587","pt":1580654270000,"mc":[{"id":"1.168224467","rc":[{"batb":[[1,4.2,19.83]],"ltp":0.0,"tv":0.0,"id":13117354}]}]}
{"op":"mcm","clk":"1004282165","pt":1580654272804,"mc":[{"id":"1.168224467","rc":[{"batb":[[0,4.7,24.43],[1,4.6,18.73],[2,3.65,13.85]],"ltp":0.0,"tv":0.0,"id":13117353},{"batb":[[0,2.52,32.99],[1,2.48,35.99],[2,2.26,19.75]],"ltp":0.0,"tv":0.0,"id":16604346},{"batb":[[0,4.4,14.07],[1,4.3,21.94],[2,4.2,19.83]],"ltp":0.0,"tv":0.0,"id":13117354}]}]}
{"op":"mcm","clk":"1004282625","pt":1580654275107,"mc":[{"id":"1.168224467","rc":[{"batb":[[0,3.65,13.85],[1,1.01,0.51],[2,3.65,0]],"ltp":0.0,"tv":0.0,"id":13117353},{"batb":[[0,2.26,19.75],[1,1.01,0.51],[2,2.26,0]],"ltp":0.0,"tv":0.0,"id":16604346},{"batb":[[0,4.3,21.94],[1,4.2,19.83],[2,1.01,0.51]],"ltp":0.0,"tv":0.0,"id":13117354}]}]}
{"op":"mcm","clk":"1004283276","pt":1580654278079,"mc":[{"id":"1.168224467","rc":[{"batb":[[0,3.75,17.93],[1,3.7,15.92],[2,3.65,13.85]],"ltp":0.0,"tv":0.0,"id":13117353},{"batb":[[1,2.24,26.54],[2,2.22,24.64]],"ltp":0.0,"tv":0.0,"id":16604346},{"batb":[[1,4.2,43.05]],"ltp":0.0,"tv":0.0,"id":13117354}]}]}
{"op":"mcm","clk":"1004284298","pt":1580654283137,"mc":[{"id":"1.168224467","rc":[{"batb":[[0,3.65,13.85],[1,1.01,0.51],[2,3.65,0]],"ltp":0.0,"tv":0.0,"id":13117353}]}]}
{"op":"mcm","clk":"1004285022","pt":1580654286448,"mc":[{"id":"1.168224467","rc":[{"batb":[[0,6.4,17.98],[1,6.2,18.85],[2,5.9,17.86]],"batl":[[1,9.8,8.89]],"ltp":0.0,"tv":0.0,"id":13117353},{"batb":[[0,5,17.22]],"batl":[[1,5.5,14.56]],"ltp":0.0,"tv":0.0,"id":16604347},{"batl":[[0,2.44,19.28],[1,2.84,12.9],[2,3.2,24.47]],"ltp":0.0,"tv":0.0,"id":16604346},{"batl":[[0,4.9,18.88],[1,5,17.94],[2,5.1,16.92]],"ltp":0.0,"tv":0.0,"id":13117354}]}]}
{"op":"mcm","clk":"1004285180","pt":1580654287141,"mc":[{"id":"1.168224467","rc":[{"batb":[[0,6.4,25.54]],"batl":[[1,8,5.88],[2,9.8,8.89]],"ltp":0.0,"tv":0.0,"id":13117353},{"batb":[[2,4.6,26.58]],"batl":[[0,5.5,23.8],[1,5.5,0]],"ltp":0.0,"tv":0.0,"id":16604347},{"batb":[[1,2.24,60.15]],"batl":[[1,2.52,26.89],[2,2.84,12.9]],"ltp":0.0,"tv":0.0,"id":16604346},{"batb":[[2,3.95,13.44]],"batl":[[0,4.7,10.92],[1,4.9,18.88],[2,5,17.94]],"ltp":0.0,"tv":0.0,"id":13117354}]}]}
{"op":"mcm","clk":"1004287668","pt":1580654299430,"mc":[{"id":"1.168224467","rc":[{"batb":[[0,6.4,7.56],[1,5.9,17.86],[2,4.3,19.04]],"ltp":0.0,"tv":0.0,"id":13117353},{"batb":[[0,5,12.99]],"ltp":0.0,"tv":0.0,"id":16604347},{"batb":[[1,2.24,33.61],[2,2.08,25.18]],"ltp":0.0,"tv":0.0,"id":16604346},{"batb":[[0,4.2,43.05],[1,3.95,13.44],[2,1.01,0.51]],"ltp":0.0,"tv":0.0,"id":13117354}]}]}
{"op":"mcm","clk":"1004287850","pt":1580654300251,"mc":[{"id":"1.168224467","rc":[{"batb":[[0,4.3,19.04],[1,1.01,0.51],[2,4.3,0]],"batl":[[0,9.8,8.89],[1,8,0],[2,9.8,0]],"ltp":0.0,"tv":0.0,"id":13117353},{"batb":[[2,4.6,15.66]],"batl":[[0,5.5,14.56]],"ltp":0.0,"tv":0.0,"id":16604347},{"batb":[[0,2.08,25.18],[1,1.01,0.51],[2,2.08,0]],"batl":[[0,2.84,12.9],[1,2.52,0],[2,2.84,0]],"ltp":0.0,"tv":0.0,"id":16604346},{"batb":[[1,1.01,0.51],[2,1.01,0]],"batl":[[0,5,17.94],[1,4.9,0],[2,5,0]],"ltp":0.0,"tv":0.0,"id":13117354}]}]}
{"op":"mcm","clk":"1004288454","pt":1580654303445,"mc":[{"id":"1.168224467","rc":[{"batb":[[0,4.4,32.29],[1,4.3,40.83],[2,1.01,0.51]],"ltp":0.0,"tv":0.0,"id":13117353},{"batb":[[1,2.06,41.34],[2,2.04,31.47]],"ltp":0.0,"tv":0.0,"id":16604346},{"batb":[[0,4.2,50.16],[1,4.1,24.34],[2,1.01,0.51]],"ltp":0.0,"tv":0.0,"id":13117354}]}]}
{"op":"mcm","clk":"1004288643","pt":1580654304344,"mc":[{"id":"1.168224467","rc":[{"batb":[[0,4.3,19.04],[1,1.01,0.51],[2,1.01,0]],"ltp":0.0,"tv":0.0,"id":13117353}]}]}
{"op":"mcm","clk":"1004289190","pt":1580654307157,"mc":[{"id":"1.168224467","rc":[{"batb":[[0,8.8,6.7],[1,8.6,9.44],[2,4.3,19.04]],"ltp":0.0,"tv":0.0,"id":13117353},{"batb":[[0,5,20.21]],"ltp":0.0,"tv":0.0,"id":16604347}]}]}
{"op":"mcm","clk":"1004289315","pt":1580654307862,"mc":[{"id":"1.168224467","rc":[{"batb":[[2,7.8,9.36]],"batl":[[1,13.5,12.2]],"ltp":0.0,"tv":0.0,"id":13117353},{"batb":[[2,4.7,15.5]],"ltp":0.0,"tv":0.0,"id":16604347},{"batl":[[0,2.24,24.55],[1,2.46,18.8]],"ltp":0.0,"tv":0.0,"id":16604346},{"batb":[[0,4.2,30.33],[1,4.1,45.19]],"batl":[[0,4.9,19.04]],"ltp":0.0,"tv":0.0,"id":13117354}]}]}
{"op":"mcm","clk":"1004289479","pt":1580654308712,"mc":[{"id":"1.168224467","rc":[{"batb":[[2,8.2,5.04]],"ltp":0.0,"tv":0.0,"id":13117353},{"batl":[[0,5.5,23.8]],"ltp":0.0,"tv":0.0,"id":16604347},{"batb":[[0,2.08,63.83]],"batl":[[1,2.34,31.09],[2,2.46,18.8]],"ltp":0.0,"tv":0.0,"id":16604346},{"batb":[[2,3.85,14.28]],"batl":[[0,4.6,10.92],[1,4.9,19.04]],"ltp":0.0,"tv":0.0,"id":13117354}]}]}
{"op":"mcm","clk":"1004290948","pt":1580654316073,"mc":[{"id":"1.168224467","rc":[{"batb":[[0,5.8,18.65],[1,1.01,0.51],[2,8.2,0]],"batl":[[0,13.5,12.2],[1,13.5,0]],"ltp":0.0,"tv":0.0,"id":13117353},{"batl":[[0,5.5,14.56]],"ltp":0.0,"tv":0.0,"id":16604347},{"batb":[[0,1.97,29.35],[1,1.01,0.51],[2,2.04,0]],"batl":[[0,2.46,18.8],[1,2.34,0],[2,2.46,0]],"ltp":0.0,"tv":0.0,"id":16604346},{"batb":[[2,1.01,0.51]],"batl":[[0,4.9,19.04],[1,4.9,0]],"ltp":0.0,"tv":0.0,"id":13117354}]}]}
{"op":"mcm","clk":"1004291417","pt":1580654318529,"mc":[{"id":"1.168224467","rc":[{"batb":[[0,6.2,22.29],[1,6,20.15],[2,5.8,18.65]],"ltp":0.0,"tv":0.0,"id":13117353},{"batb":[[0,1.97,61.78],[1,1.95,36.12],[2,1.01,0.51]],"ltp":0.0,"tv":0.0,"id":16604346}]}]}
{"op":"mcm","clk":"1004291760","pt":1580654320365,"mc":[{"id":"1.168224467","rc":[{"batb":[[0,5.8,18.65],[1,1.01,0.51],[2,5.8,0]],"ltp":0.0,"tv":0.0,"id":13117353}]}]}
{"op":"mcm","clk":"1004292306","pt":1580654323078,"mc":[{"id":"1.168224467","rc":[{"batb":[[0,11,13.05],[1,10.5,14.69],[2,5.8,18.65]],"ltp":0.0,"tv":0.0,"id":13117353}]}]}
{"op":"mcm","clk":"1004292419","pt":1580654323680,"mc":[{"id":"1.168224467","rc":[{"batb":[[2,10,13.38]],"batl":[[1,17,7.87]],"ltp":0.0,"tv":0.0,"id":13117353},{"batl":[[0,5.6,14.01]],"ltp":0.0,"tv":0.0,"id":16604347},{"batb":[[2,1.88,17.15]],"batl":[[0,2.12,28.56],[1,2.18,26.04]],"ltp":0.0,"tv":0.0,"id":16604346},{"batl":[[0,4.8,19.83],[1,4.9,18.57]],"ltp":0.0,"tv":0.0,"id":13117354}]}]}
{"op":"mcm","clk":"1004292573","pt":1580654324548,"mc":[{"id":"1.168224467","rc":[{"batb":[[1,10.5,18.89]],"ltp":0.0,"tv":0.0,"id":13117353},{"batl":[[0,5.5,9.24],[1,5.6,14.01]],"ltp":0.0,"tv":0.0,"id":16604347},{"batb":[[0,1.97,104.63]],"batl":[[2,2.22,33.61]],"ltp":0.0,"tv":0.0,"id":16604346},{"batb":[[2,3.9,14.28]],"batl":[[0,4.6,10.92],[1,4.8,19.83],[2,4.9,18.57]],"ltp":0.0,"tv":0.0,"id":13117354}]}]}
{"op":"mcm","clk":"1004297959","pt":1580654351899,"mc":[{"id":"1.168224467","rc":[{"batb":[[0,8.8,7.08],[1,1.01,0.51],[2,10,0]],"batl":[[0,17,7.87],[1,17,0]],"ltp":0.0,"tv":0.0,"id":13117353},{"batl":[[0,5.6,14.01],[1,5.6,0]],"ltp":0.0,"tv":0.0,"id":16604347},{"batb":[[0,1.88,17.15],[1,1.01,0.51],[2,1.88,0]],"batl":[[0,2.18,26.04],[1,2.18,0],[2,2.22,0]],"ltp":0.0,"tv":0.0,"id":16604346},{"batb":[[0,4.2,16.02],[2,1.01,0.51]],"batl":[[0,4.9,18.57],[1,4.8,0],[2,4.9,0]],"ltp":0.0,"tv":0.0,"id":13117354}]}]}
{"op":"mcm","clk":"1004298666","pt":1580654355229,"mc":[{"id":"1.168224467","rc":[{"batb":[[0,10,8.54],[1,9.8,7.09],[2,8.8,7.08]],"ltp":0.0,"tv":0.0,"id":13117353},{"batb":[[0,1.88,64.04],[1,1.86,41.82],[2,1.01,0.51]],"ltp":0.0,"tv":0.0,"id":16604346}]}]}
{"op":"mcm","clk":"1004300447","pt":1580654363647,"mc":[{"id":"1.168224467","rc":[{"batb":[[0,1.88,17.15],[1,1.01,0.51],[2,1.01,0]],"ltp":0.0,"tv":0.0,"id":16604346}]}]}
{"op":"mcm","clk":"1004301070","pt":1580654366655,"mc":[{"id":"1.168224467","rc":[{"batb":[[0,2.02,39.01],[1,2,33.41],[2,1.88,17.15]],"ltp":0.0,"tv":0.0,"id":16604346}]}]}
{"op":"mcm","clk":"1004301307","pt":1580654367838,"mc":[{"id":"1.168224467","rc":[{"batl":[[0,11.5,15.97],[1,14,11.33]],"ltp":0.0,"tv":0.0,"id":13117353},{"batb":[[2,4.6,15.89]],"batl":[[0,5.5,14.32]],"ltp":0.0,"tv":0.0,"id":16604347},{"batb":[[0,2.04,26.75],[1,2.02,39.01],[2,2,33.41]],"batl":[[1,2.26,23.84]],"ltp":0.0,"tv":0.0,"id":16604346},{"batb":[[2,4,21.87]],"batl":[[0,4.8,19.2]],"ltp":0.0,"tv":0.0,"id":13117354}]}]}
{"op":"mcm","clk":"1004301621","pt":1580654369430,"mc":[{"id":"1.168224467","rc":[{"batb":[[2,9.6,4.2]],"batl":[[1,12.5,3.36],[2,14,11.33]],"ltp":0.0,"tv":0.0,"id":13117353},{"batb":[[2,4.6,26.82]],"batl":[[1,5.6,8.4]],"ltp":0.0,"tv":0.0,"id":16604347},{"batb":[[1,2.02,80.18]],"batl":[[1,2.26,56.61]],"ltp":0.0,"tv":0.0,"id":16604346},{"batl":[[0,4.5,11.76],[1,4.8,19.2]],"ltp":0.0,"tv":0.0,"id":13117354}]}]}
{"op":"mcm","clk":"1004304082","pt":1580654381158,"mc":[{"id":"1.168224467","rc":[{"batb":[[0,9.6,4.2],[1,8.8,7.08],[2,8.2,8.34]],"ltp":0.0,"tv":0.0,"id":13117353},{"batb":[[0,5,15.15]],"ltp":0.0,"tv":0.0,"id":16604347},{"batb":[[1,2.02,41.17],[2,1.94,15.42]],"ltp":0.0,"tv":0.0,"id":16604346},{"batb":[[0,4.1,45.19],[1,4,21.87],[2,3.85,14.28]],"ltp":0.0,"tv":0.0,"id":13117354}]}]}
{"op":"mcm","clk":"1004304291","pt":1580654382143,"mc":[{"id":"1.168224467","rc":[{"batb":[[0,8.2,8.34],[1,1.01,0.51],[2,8.2,0]],"batl":[[0,14,11.33],[1,12.5,0],[2,14,0]],"ltp":0.0,"tv":0.0,"id":13117353},{"batb":[[2,4.6,15.89]],"batl":[[1,5.6,0]],"ltp":0.0,"tv":0.0,"id":16604347},{"batb":[[0,1.94,15.42],[1,1.01,0.51],[2,1.94,0]],"batl":[[0,2.26,23.84],[1,2.26,0]],"ltp":0.0,"tv":0.0,"id":16604346},{"batb":[[0,4.1,24.34],[2,1.01,0.51]],"batl":[[0,4.8,19.2],[1,4.8,0]],"ltp":0.0,"tv":0.0,"id":13117354}]}]}
{"op":"mcm","clk":"1004304759","pt":1580654384385,"mc":[{"id":"1.168224467","rc":[{"batb":[[0,9.2,8.92],[1,9,8.49],[2,8.2,8.34]],"ltp":0.0,"tv":0.0,"id":13117353},{"batb":[[0,1.95,29.71],[1,1.94,15.42],[2,1.93,37.24]],"ltp":0.0,"tv":0.0,"id":16604346},{"batb":[[1,4,47.68]],"ltp":0.0,"tv":0.0,"id":13117354}]}]}
{"op":"mcm","clk":"1004305131","pt":1580654386397,"mc":[{"id":"1.168224467","rc":[{"batb":[[0,8.2,8.34],[1,1.01,0.51],[2,8.2,0]],"ltp":0.0,"tv":0.0,"id":13117353},{"batb":[[0,1.94,15.42],[1,1.01,0.51],[2,1.93,0]],"ltp":0.0,"tv":0.0,"id":16604346},{"batb":[[1,4,21.87]],"ltp":0.0,"tv":0.0,"id":13117354}]}]}
{"op":"mcm","clk":"1004305801","pt":1580654389360,"mc":[{"id":"1.168224467","rc":[{"batb":[[0,10,17.84],[1,9.8,6.91],[2,8.2,8.34]],"ltp":0.0,"tv":0.0,"id":13117353},{"batb":[[0,5,20.2]],"ltp":0.0,"tv":0.0,"id":16604347},{"batb":[[0,2,49.32],[1,1.98,34.44],[2,1.94,15.42]],"ltp":0.0,"tv":0.0,"id":16604346},{"batb":[[0,4.2,17.72],[1,4.1,24.34],[2,4,21.87]],"ltp":0.0,"tv":0.0,"id":13117354}]}]}
{"op":"mcm","clk":"1004306378","pt":1580654392376,"mc":[{"id":"1.168224467","rc":[{"batb":[[0,8.2,8.34],[1,1.01,0.51],[2,8.2,0]],"ltp":0.0,"tv":0.0,"id":13117353},{"batb":[[0,5,15.15]],"ltp":0.0,"tv":0.0,"id":16604347},{"batb":[[0,1.94,15.42],[1,1.01,0.51],[2,1.94,0]],"ltp":0.0,"tv":0.0,"id":16604346},{"batb":[[0,4.1,24.34],[1,4,21.87],[2,1.01,0.51]],"ltp":0.0,"tv":0.0,"id":13117354}]}]}
{"op":"mcm","clk":"1004306948","pt":1580654395399,"mc":[{"id":"1.168224467","rc":[{"batb":[[0,9.2,8.92],[1,9,8.49],[2,8.2,8.34]],"ltp":0.0,"tv":0.0,"id":13117353},{"batb":[[0,1.95,29.71],[1,1.94,15.42],[2,1.93,37.24]],"ltp":0.0,"tv":0.0,"id":16604346},{"batb":[[1,4,47.68]],"ltp":0.0,"tv":0.0,"id":13117354}]}]}
{"op":"mcm","clk":"1004310087","pt":1580654410478,"mc":[{"id":"1.168224467","rc":[{"batl":[[0,4.4,6.82],[1,4.8,19.2]],"ltp":0.0,"tv":0.0,"id":13117354}]}]}
{"op":"mcm","clk":"1004310535","pt":1580654412792,"mc":[{"id":"1.168224467","rc":[{"batb":[[0,1.94,15.42],[1,1.01,0.51],[2,1.93,0]],"ltp":0.0,"tv":0.0,"id":16604346}]}]}
{"op":"mcm","clk":"1004311190","pt":1580654415824,"mc":[{"id":"1.168224467","rc":[{"batb":[[0,2.08,24.22],[1,2.06,30.6],[2,1.94,15.42]],"ltp":0.0,"tv":0.0,"id":16604346}]}]}
{"op":"mcm","clk":"1004311452","pt":1580654416987,"mc":[{"id":"1.168224467","rc":[{"batl":[[0,10.5,7.95],[1,12,15.26]],"ltp":0.0,"tv":0.0,"id":13117353},{"batb":[[0,2.1,24.47],[1,2.08,24.22],[2,2.06,30.6]],"batl":[[1,2.32,22.27]],"ltp":0.0,"tv":0.0,"id":16604346},{"batl":[[1,4.7,20.77],[2,4.8,19.2]],"ltp":0.0,"tv":0.0,"id":13117354}]}]}
{"op":"mcm","clk":"1004311834","pt":1580654418832,"mc":[{"id":"1.168224467","rc":[{"batb":[[1,9,13.53]],"batl":[[1,12,18.63]],"ltp":0.0,"tv":0.0,"id":13117353},{"batb":[[2,4.6,26.82]],"batl":[[0,5.5,23.56]],"ltp":0.0,"tv":0.0,"id":16604347},{"batb":[[2,2.06,70.09]],"batl":[[1,2.3,31.93],[2,2.32,22.27]],"ltp":0.0,"tv":0.0,"id":16604346},{"batb":[[2,3.75,15.12]],"batl":[[1,4.5,11.76],[2,4.7,20.77]],"ltp":0.0,"tv":0.0,"id":13117354}]}]}
{"op":"mcm","clk":"1004314721","pt":1580654433351,"mc":[{"id":"1.168224467","rc":[{"batb":[[0,9,5.04],[1,7.8,9.36],[2,1.01,0.51]],"batl":[[0,12,18.63],[1,12,0]],"ltp":0.0,"tv":0.0,"id":13117353},{"batb":[[0,5,12.99]],"ltp":0.0,"tv":0.0,"id":16604347},{"batb":[[0,2.06,39.49],[1,2,27.62],[2,1.01,0.51]],"batl":[[0,2.3,31.93],[1,2.32,22.27],[2,2.32,0]],"ltp":0.0,"tv":0.0,"id":16604346},{"batb":[[0,4.1,15.5]],"batl":[[2,4.8,19.2]],"ltp":0.0,"tv":0.0,"id":13117354}]}]}
{"op":"mcm","clk":"1004314824","pt":1580654433846,"mc":[{"id":"1.168224467","rc":[{"batb":[[0,7.8,9.36],[1,1.01,0.51],[2,1.01,0]],"batl":[[0,12,15.26]],"ltp":0.0,"tv":0.0,"id":13117353},{"batb":[[2,4.6,15.89]],"batl":[[0,5.5,14.32]],"ltp":0.0,"tv":0.0,"id":16604347},{"batb":[[0,2,27.62],[1,1.01,0.51],[2,1.01,0]],"batl":[[0,2.32,22.27],[1,2.32,0]],"ltp":0.0,"tv":0.0,"id":16604346},{"batb":[[2,1.01,0.51]],"batl":[[1,4.8,19.2],[2,4.8,0]],"ltp":0.0,"tv":0.0,"id":13117354}]}]}
{"op":"mcm","clk":"1004315337","pt":1580654436329,"mc":[{"id":"1.168224467","rc":[{"batb":[[0,8.8,5.8],[1,8.6,9.42],[2,7.8,9.36]],"ltp":0.0,"tv":0.0,"id":13117353},{"batb":[[0,2,74.83],[1,1.98,34.44],[2,1.01,0.51]],"ltp":0.0,"tv":0.0,"id":16604346}]}]}
{"op":"mcm","clk":"1004315769","pt":1580654438257,"mc":[{"id":"1.168224467","rc":[{"batb":[[0,2,27.62],[1,1.01,0.51],[2,1.01,0]],"ltp":0.0,"tv":0.0,"id":16604346}]}]}
{"op":"mcm","clk":"1004316413","pt":1580654441352,"mc":[{"id":"1.168224467","rc":[{"batb":[[0,2.12,25.33],[1,2.1,28.92],[2,2,27.62]],"ltp":0.0,"tv":0.0,"id":16604346}]}]}
{"op":"mcm","clk":"1004316563","pt":1580654442071,"mc":[{"id":"1.168224467","rc":[{"batl":[[0,9.8,8.97],[1,10.5,7.79]],"ltp":0.0,"tv":0.0,"id":13117353},{"batl":[[0,5.4,14.95]],"ltp":0.0,"tv":0.0,"id":16604347},{"batb":[[0,2.14,22.82],[1,2.12,25.33],[2,2.1,28.92]],"batl":[[1,2.36,21.01]],"ltp":0.0,"tv":0.0,"id":16604346},{"batb":[[2,3.95,23.53]],"batl":[[1,4.6,21.56],[2,4.7,20.3]],"ltp":0.0,"tv":0.0,"id":13117354}]}]}
{"op":"mcm","clk":"1004316775","pt":1580654443032,"mc":[{"id":"1.168224467","rc":[{"batb":[[1,8.6,14.46]],"batl":[[2,11,4.2]],"ltp":0.0,"tv":0.0,"id":13117353},{"batb":[[2,4.6,26.82]],"batl":[[1,5.5,9.24]],"ltp":0.0,"tv":0.0,"id":16604347},{"batb":[[2,2.1,66.73]],"batl":[[1,2.34,31.09],[2,2.36,21.01]],"ltp":0.0,"tv":0.0,"id":16604346},{"batl":[[0,4.4,18.58]],"ltp":0.0,"tv":0.0,"id":13117354}]}]}
{"op":"mcm","clk":"1004319360","pt":1580654455118,"mc":[{"id":"1.168224467","rc":[{"batb":[[0,8.6,5.04],[1,7.4,10.31],[2,1.01,0.51]],"batl":[[0,10.5,7.79],[1,11,4.2],[2,11,0]],"ltp":0.0,"tv":0.0,"id":13117353},{"batb":[[0,4.9,16.95],[1,4.6,26.82],[2,1.01,0.51]],"ltp":0.0,"tv":0.0,"id":16604347},{"batb":[[0,2.1,37.81],[1,2.08,25.18],[2,1.01,0.51]],"batl":[[0,2.34,31.09],[1,2.36,21.01],[2,2.36,0]],"ltp":0.0,"tv":0.0,"id":16604346},{"batb":[[0,4,25.81],[1,3.95,23.53],[2,3.7,15.12]],"batl":[[1,4.7,20.3],[2,4.7,0]],"ltp":0.0,"tv":0.0,"id":13117354}]}]}
{"op":"mcm","clk":"1004319617","pt":1580654456239,"mc":[{"id":"1.168224467","rc":[{"batb":[[0,7.4,10.31],[1,1.01,0.51],[2,1.01,0]],"batl":[[1,11,0]],"ltp":0.0,"tv":0.0,"id":13117353},{"batb":[[1,4.6,15.89]],"batl":[[1,5.5,0]],"ltp":0.0,"tv":0.0,"id":16604347},{"batb":[[0,2.08,25.18],[1,1.01,0.51],[2,1.01,0]],"batl":[[0,2.36,21.01],[1,2.36,0]],"ltp":0.0,"tv":0.0,"id":16604346},{"batb":[[2,1.01,0.51]],"batl":[[0,4.4,6.82]],"ltp":0.0,"tv":0.0,"id":13117354}]}]}
{"op":"mcm","clk":"1004319998","pt":1580654458135,"mc":[{"id":"1.168224467","rc":[{"batb":[[0,8.4,13.74],[1,8.2,10.25],[2,7.4,10.31]],"ltp":0.0,"tv":0.0,"id":13117353},{"batb":[[0,4.9,26.49],[1,4.8,17.68],[2,4.6,15.89]],"ltp":0.0,"tv":0.0,"id":16604347},{"batb":[[1,2.06,34.56],[2,2.04,31.49]],"ltp":0.0,"tv":0.0,"id":16604346},{"batb":[[1,3.95,36.98]],"ltp":0.0,"tv":0.0,"id":13117354}]}]}
{"op":"mcm","clk":"1004320311","pt":1580654459733,"mc":[{"id":"1.168224467","rc":[{"batb":[[1,1.01,0.51],[2,2.04,0]],"ltp":0.0,"tv":0.0,"id":16604346}]}]}
{"op":"mcm","clk":"1004321091","pt":1580654463329,"mc":[{"id":"1.168224467","rc":[{"batb":[[0,8.4,9.96],[1,7.4,10.31],[2,5.5,10.54]],"batl":[[0,9.4,9.84],[1,10.5,7.79],[2,13,13.53]],"ltp":0.0,"tv":0.0,"id":13117353},{"batl":[[0,5.3,15.42],[1,5.4,14.95]],"ltp":0.0,"tv":0.0,"id":16604347},{"batb":[[0,2.18,21.56],[1,2.14,28.33],[2,2.12,28.11]],"batl":[[1,2.64,15.58]],"ltp":0.0,"tv":0.0,"id":16604346},{"batb":[[2,3.9,24.31]],"batl":[[1,4.6,21.87],[2,4.7,20.3]],"ltp":0.0,"tv":0.0,"id":13117354}]}]}
{"op":"mcm","clk":"1004321137","pt":1580654463544,"mc":[{"id":"1.168224467","rc":[{"batl":[[1,13,13.53],[2,13,0]],"ltp":0.0,"tv":0.0,"id":13117353},{"batl":[[1,5.4,0]],"ltp":0.0,"tv":0.0,"id":16604347},{"batb":[[1,3.95,13.45]],"batl":[[2,4.7,0]],"ltp":0.0,"tv":0.0,"id":13117354}]}]}
{"op":"mcm","clk":"1004321358","pt":1580654464633,"mc":[{"id":"1.168224467","rc":[{"batb":[[1,8.2,5.04],[2,7.4,10.31]],"batl":[[1,10.5,4.2],[2,13,13.53]],"ltp":0.0,"tv":0.0,"id":13117353},{"batb":[[2,4.6,26.82]],"batl":[[1,5.5,9.24]],"ltp":0.0,"tv":0.0,"id":16604347},{"batb":[[1,2.16,36.13],[2,2.14,28.33]],"batl":[[1,2.4,29.41],[2,2.64,15.58]],"ltp":0.0,"tv":0.0,"id":16604346},{"batl":[[0,4.2,12.6],[1,4.4,6.82],[2,4.6,21.87]],"ltp":0.0,"tv":0.0,"id":13117354}]}]}
{"op":"mcm","clk":"1004321668","pt":1580654466157,"mc":[{"id":"1.168224467","rc":[{"batb":[[0,8.6,12.32],[1,8.4,9.96],[2,8.2,5.04]],"ltp":0.0,"tv":0.0,"id":13117353},{"batl":[[1,4.6,21.87],[2,4.6,0]],"ltp":0.0,"tv":0.0,"id":13117354}]}]}
{"op":"mcm","clk":"1004321718","pt":1580654466473,"mc":[{"id":"1.168224467","rc":[{"batb":[[0,8.6,9.67],[1,8.2,5.04],[2,7.4,10.31]],"ltp":0.0,"tv":0.0,"id":13117353},{"batb":[[2,2.12,28.11]],"ltp":0.0,"tv":0.0,"id":16604346}]}]}
{"op":"mcm","clk":"1004322474","pt":1580654469734,"mc":[{"id":"1.168224467","rc":[{"batb":[[0,8.8,7.95],[1,8.6,9.67],[2,8.2,5.04]],"ltp":0.0,"tv":0.0,"id":13117353},{"batb":[[2,2.12,49]],"ltp":0.0,"tv":0.0,"id":16604346}]}]}
{"op":"mcm","clk":"1004322914","pt":1580654471751,"mc":[{"id":"1.168224467","rc":[{"batl":[[0,9.6,9.13],[2,13.5,12.51]],"ltp":0.0,"tv":0.0,"id":13117353},{"batl":[[0,2.34,21.48],[2,2.62,16.05]],"ltp":0.0,"tv":0.0,"id":16604346},{"batb":[[2,3.9,23.6]],"batl":[[1,4.5,22.03]],"ltp":0.0,"tv":0.0,"id":13117354}]}]}
{"op":"mcm","clk":"1004323208","pt":1580654473148,"mc":[{"id":"1.168224467","rc":[{"batb":[[0,8.8,11.35]],"ltp":0.0,"tv":0.0,"id":13117353}]}]}
{"op":"mcm","clk":"1004324606","pt":1580654479682,"mc":[{"id":"1.168224467","rc":[{"batl":[[0,10,8.42],[2,14,11.57]],"ltp":0.0,"tv":0.0,"id":13117353},{"batb":[[0,2.16,58.71],[1,2.12,49],[2,2.1,28.88]],"batl":[[0,2.32,22.03],[2,2.58,16.52]],"ltp":0.0,"tv":0.0,"id":16604346}]}]}
{"op":"mcm","clk":"1004336469","pt":1580654535889,"mc":[{"id":"1.168224467","rc":[{"batb":[[1,8.2,5.04],[2,8,8.81]],"ltp":0.0,"tv":0.0,"id":13117353},{"batb":[[1,2.12,30.11]],"ltp":0.0,"tv":0.0,"id":16604346}]}]}
{"op":"mcm","clk":"1004337225","pt":1580654539306,"mc":[{"id":"1.168224467","rc":[{"batb":[[0,9,11.77],[1,8.8,11.35],[2,8.2,5.04]],"ltp":0.0,"tv":0.0,"id":13117353}]}]}
{"op":"mcm","clk":"1004337320","pt":1580654539752,"mc":[{"id":"1.168224467","rc":[{"batb":[[0,8.2,5.04],[1,5.8,18.57],[2,1.01,0.51]],"batl":[[0,10.5,4.2],[1,14,11.57],[2,14,0]],"ltp":0.0,"tv":0.0,"id":13117353},{"batb":[[0,2.16,36.13],[1,2.04,26.2],[2,1.01,0.51]],"batl":[[0,2.4,29.41],[1,2.58,16.52],[2,2.58,0]],"ltp":0.0,"tv":0.0,"id":16604346},{"batb":[[0,4,20.38],[2,3.85,24.39]],"ltp":0.0,"tv":0.0,"id":13117354}]}]}
{"op":"mcm","clk":"1004337793","pt":1580654541690,"mc":[{"id":"1.168224467","rc":[{"batb":[[0,5.8,18.57],[1,1.01,0.51],[2,1.01,0]],"batl":[[0,14,11.57],[1,14,0]],"ltp":0.0,"tv":0.0,"id":13117353},{"batb":[[2,4.6,15.89]],"batl":[[1,5.5,0]],"ltp":0.0,"tv":0.0,"id":16604347},{"batb":[[0,2.04,26.2],[1,1.01,0.51],[2,1.01,0]],"batl":[[0,2.58,16.52],[1,2.58,0]],"ltp":0.0,"tv":0.0,"id":16604346},{"batl":[[0,4.5,22.03],[1,4.5,0]],"ltp":0.0,"tv":0.0,"id":13117354}]}]}
{"op":"mcm","clk":"1004338089","pt":1580654542928,"mc":[{"id":"1.168224467","rc":[{"batb":[[0,6.4,9.63],[1,6.2,20.09],[2,6,17.55]],"batl":[[0,14.5,10.94]],"ltp":0.0,"tv":0.0,"id":13117353},{"batb":[[1,2.02,28.33],[2,2,33.34]],"batl":[[0,2.56,16.92]],"ltp":0.0,"tv":0.0,"id":16604346}]}]}
{"op":"mcm","clk":"1004340469","pt":1580654553520,"mc":[{"id":"1.168224467","rc":[{"batb":[[0,6,17.55],[1,1.01,0.51],[2,6,0]],"ltp":0.0,"tv":0.0,"id":13117353}]}]}
{"op":"mcm","clk":"1004341304","pt":1580654557340,"mc":[{"id":"1.168224467","rc":[{"batb":[[0,11.5,17.03],[1,11,12.56],[2,10.5,16.08]],"batl":[[1,19,6.29]],"ltp":0.0,"tv":0.0,"id":13117353},{"batb":[[2,4.6,26.82]],"batl":[[1,5.4,15.19],[2,5.5,9.24]],"ltp":0.0,"tv":0.0,"id":16604347},{"batb":[[0,2.06,39.49],[1,2.04,26.2],[2,2.02,28.33]],"batl":[[0,2.2,25.81],[1,2.3,31.93],[2,2.38,20.77]],"ltp":0.0,"tv":0.0,"id":16604346},{"batl":[[0,4.2,12.6],[1,4.4,23.21],[2,4.5,22.03]],"ltp":0.0,"tv":0.0,"id":13117354}]}]}
{"op":"mcm","clk":"1004341451","pt":1580654557943,"mc":[{"id":"1.168224467","rc":[{"batl":[[0,5.4,15.19],[1,5.5,9.24],[2,5.5,0]],"ltp":0.0,"tv":0.0,"id":16604347},{"batl":[[2,4.5,0]],"ltp":0.0,"tv":0.0,"id":13117354}]}]}
{"op":"mcm","clk":"1004343349","pt":1580654566367,"mc":[{"id":"1.168224467","rc":[{"batb":[[0,10.5,16.08],[1,7.6,9.76],[2,1.01,0.51]],"ltp":0.0,"tv":0.0,"id":13117353},{"batb":[[2,1.96,30.14]],"ltp":0.0,"tv":0.0,"id":16604346}]}]}
{"op":"mcm","clk":"1004343424","pt":1580654566630,"mc":[{"id":"1.168224467","rc":[{"batb":[[0,10.5,4.2]],"batl":[[0,19,6.29],[1,19,0]],"ltp":0.0,"tv":0.0,"id":13117353},{"batb":[[1,1.96,30.14],[2,1.01,0.51]],"batl":[[0,2.3,31.93],[1,2.38,20.77],[2,2.38,0]],"ltp":0.0,"tv":0.0,"id":16604346}]}]}
{"op":"mcm","clk":"1004343687","pt":1580654567744,"mc":[{"id":"1.168224467","rc":[{"batb":[[0,7.6,9.76],[1,1.01,0.51],[2,1.01,0]],"ltp":0.0,"tv":0.0,"id":13117353},{"batb":[[2,4.6,15.89]],"batl":[[1,5.5,0]],"ltp":0.0,"tv":0.0,"id":16604347},{"batb":[[0,1.96,30.14],[1,1.01,0.51],[2,1.01,0]],"batl":[[0,2.38,20.77],[1,2.38,0]],"ltp":0.0,"tv":0.0,"id":16604346},{"batl":[[0,4.4,23.21],[1,4.4,0]],"ltp":0.0,"tv":0.0,"id":13117354}]}]}
{"op":"mcm","clk":"1004344057","pt":1580654569375,"mc":[{"id":"1.168224467","rc":[{"batb":[[0,8.4,7.01],[1,8.2,11.03],[2,7.6,9.76]],"ltp":0.0,"tv":0.0,"id":13117353},{"batb":[[1,1.94,39.68],[2,1.92,37.73]],"ltp":0.0,"tv":0.0,"id":16604346}]}]}
{"op":"mcm","clk":"1004344542","pt":1580654571422,"mc":[{"id":"1.168224467","rc":[{"batb":[[0,7.6,9.76],[1,1.01,0.51],[2,7.6,0]],"ltp":0.0,"tv":0.0,"id":13117353}]}]}
{"op":"mcm","clk":"1004345216","pt":1580654574448,"mc":[{"id":"1.168224467","rc":[{"batb":[[0,15.5,4.61],[1,15,7.64],[2,7.6,9.76]],"ltp":0.0,"tv":0.0,"id":13117353}]}]}
{"op":"mcm","clk":"1004345419","pt":1580654575259,"mc":[{"id":"1.168224467","rc":[{"batb":[[2,13.5,6.69]],"batl":[[1,26,7.55]],"ltp":0.0,"tv":0.0,"id":13117353},{"batb":[[2,4.6,10.92]],"batl":[[1,5.5,9.24]],"ltp":0.0,"tv":0.0,"id":16604347},{"batb":[[0,1.98,42.85],[1,1.96,30.14],[2,1.94,39.68]],"batl":[[0,2.1,29.27],[1,2.22,33.61],[2,2.24,24.63]],"ltp":0.0,"tv":0.0,"id":16604346},{"batl":[[0,4.2,12.6],[1,4.5,22.58]],"ltp":0.0,"tv":0.0,"id":13117354}]}]}
{"op":"mcm","clk":"1004347590","pt":1580654584183,"mc":[{"id":"1.168224467","rc":[{"batb":[[0,13,3.36],[1,10,12.67],[2,1.01,0.51]],"batl":[[0,26,7.55],[1,26,0]],"ltp":0.0,"tv":0.0,"id":13117353},{"batb":[[0,4.9,22.25]],"ltp":0.0,"tv":0.0,"id":16604347},{"batb":[[1,1.9,16.52],[2,1.01,0.51]],"batl":[[0,2.22,33.61],[1,2.24,24.63],[2,2.24,0]],"ltp":0.0,"tv":0.0,"id":16604346},{"batb":[[0,3.95,13.45],[1,3.8,25.34],[2,3.6,15.96]],"ltp":0.0,"tv":0.0,"id":13117354}]}]}
{"op":"mcm","clk":"1004347976","pt":1580654585752,"mc":[{"id":"1.168224467","rc":[{"batb":[[0,10,12.67],[1,1.01,0.51],[2,1.01,0]],"ltp":0.0,"tv":0.0,"id":13117353},{"batb":[[2,4.5,16.52]],"batl":[[1,5.5,0]],"ltp":0.0,"tv":0.0,"id":16604347},{"batb":[[0,1.9,16.52],[1,1.01,0.51],[2,1.01,0]],"batl":[[0,2.24,24.63],[1,2.24,0]],"ltp":0.0,"tv":0.0,"id":16604346},{"batb":[[2,1.01,0.51]],"batl":[[0,4.5,22.58],[1,4.5,0]],"ltp":0.0,"tv":0.0,"id":13117354}]}]}
{"op":"mcm","clk":"1004348355","pt":1580654587445,"mc":[{"id":"1.168224467","rc":[{"batb":[[0,3.95,13.48]],"ltp":0.0,"tv":0.0,"id":13117354}]}]}
{"op":"mcm","clk":"1004349314","pt":1580654591866,"mc":[{"id":"1.168224467","rc":[{"batb":[[0,14.5,5.21],[1,14,8.79],[2,10,12.67]],"ltp":0.0,"tv":0.0,"id":13117353},{"batb":[[0,1.96,37.07],[1,1.94,36.55],[2,1.9,16.52]],"ltp":0.0,"tv":0.0,"id":16604346},{"batb":[[0,4,17.71],[1,3.95,13.48],[2,3.8,25.34]],"ltp":0.0,"tv":0.0,"id":13117354}]}]}
{"op":"mcm","clk":"1004349572","pt":1580654592950,"mc":[{"id":"1.168224467","rc":[{"batb":[[0,10,12.67],[1,1.01,0.51],[2,10,0]],"ltp":0.0,"tv":0.0,"id":13117353},{"batb":[[0,1.9,16.52],[1,1.01,0.51],[2,1.9,0]],"ltp":0.0,"tv":0.0,"id":16604346},{"batb":[[0,3.95,13.48],[1,3.8,25.34],[2,1.01,0.51]],"ltp":0.0,"tv":0.0,"id":13117354}]}]}
{"op":"mcm","clk":"1004350204","pt":1580654595730,"mc":[{"id":"1.168224467","rc":[{"batb":[[0,11.5,8.22],[1,11,14.35],[2,10,12.67]],"ltp":0.0,"tv":0.0,"id":13117353},{"batb":[[1,1.89,42.8],[2,1.87,40.96]],"ltp":0.0,"tv":0.0,"id":16604346},{"batb":[[0,3.95,21.5],[1,3.9,13.91],[2,3.8,25.34]],"ltp":0.0,"tv":0.0,"id":13117354}]}]}
{"op":"mcm","clk":"1004351803","pt":1580654602878,"mc":[{"id":"1.168224467","rc":[{"batb":[[0,10,12.67],[1,1.01,0.51],[2,10,0]],"ltp":0.0,"tv":0.0,"id":13117353},{"batb":[[0,4.9,17.04],[1,4.5,16.52],[2,1.01,0.51]],"ltp":0.0,"tv":0.0,"id":16604347},{"batb":[[0,3.95,13.45],[1,3.8,25.34],[2,1.01,0.51]],"ltp":0.0,"tv":0.0,"id":13117354}]}]}
{"op":"mcm","clk":"1004352579","pt":1580654606301,"mc":[{"id":"1.168224467","rc":[{"batb":[[0,19,3.49],[1,18.5,4.99],[2,16.5,4.17]],"batl":[[1,30,5.82]],"ltp":0.0,"tv":0.0,"id":13117353},{"batb":[[0,5,10.52],[1,4.9,17.04],[2,4.6,16.21]],"ltp":0.0,"tv":0.0,"id":16604347},{"batl":[[0,2.02,16.29],[1,2.12,28.33],[2,2.24,24.63]],"ltp":0.0,"tv":0.0,"id":16604346},{"batb":[[0,4,26.82],[1,3.95,13.45],[2,3.9,23.84]],"batl":[[1,4.6,21.87]],"ltp":0.0,"tv":0.0,"id":13117354}]}]}
{"op":"mcm","clk":"1004352689","pt":1580654606790,"mc":[{"id":"1.168224467","rc":[{"batb":[[2,4.6,27.13]],"batl":[[0,5.4,14.87],[1,5.5,9.24]],"ltp":0.0,"tv":0.0,"id":16604347},{"batb":[[0,1.93,44.53],[1,1.9,16.52],[2,1.89,42.8]],"batl":[[2,2.16,36.13]],"ltp":0.0,"tv":0.0,"id":16604346},{"batl":[[0,4.2,12.6],[1,4.5,22.58],[2,4.6,21.87]],"ltp":0.0,"tv":0.0,"id":13117354}]}]}
{"op":"mcm","clk":"1004355108","pt":1580654617168,"mc":[{"id":"1.168224467","rc":[{"batb":[[0,14,6.22],[1,1.01,0.51],[2,16.5,0]],"batl":[[0,30,5.82],[1,30,0]],"ltp":0.0,"tv":0.0,"id":13117353},{"batb":[[0,4.9,17.04],[1,4.6,27.13],[2,1.01,0.51]],"ltp":0.0,"tv":0.0,"id":16604347},{"batb":[[1,1.86,17.62],[2,1.01,0.51]],"batl":[[0,2.12,28.33],[1,2.16,36.13],[2,2.16,0]],"ltp":0.0,"tv":0.0,"id":16604346},{"batb":[[0,3.95,13.45],[1,3.75,13.06],[2,3.6,15.96]],"batl":[[1,4.6,21.87],[2,4.6,0]],"ltp":0.0,"tv":0.0,"id":13117354}]}]}
{"op":"mcm","clk":"1004355328","pt":1580654618188,"mc":[{"id":"1.168224467","rc":[{"batb":[[1,4.6,16.21]],"batl":[[1,5.5,0]],"ltp":0.0,"tv":0.0,"id":16604347},{"batb":[[0,1.86,17.62],[1,1.01,0.51],[2,1.01,0]],"batl":[[1,2.16,0]],"ltp":0.0,"tv":0.0,"id":16604346},{"batb":[[2,1.01,0.51]],"batl":[[0,4.6,21.87],[1,4.6,0]],"ltp":0.0,"tv":0.0,"id":13117354}]}]}
{"op":"mcm","clk":"1004355747","pt":1580654620240,"mc":[{"id":"1.168224467","rc":[{"batb":[[0,16,4.47],[1,15.5,7.14],[2,14,6.22]],"ltp":0.0,"tv":0.0,"id":13117353},{"batb":[[0,4.9,22.76],[1,4.8,17.68],[2,4.6,16.21]],"ltp":0.0,"tv":0.0,"id":16604347},{"batb":[[0,1.86,62.87],[1,1.84,43.11],[2,1.01,0.51]],"ltp":0.0,"tv":0.0,"id":16604346},{"batb":[[1,3.9,13.92],[2,3.75,13.06]],"ltp":0.0,"tv":0.0,"id":13117354}]}]}
{"op":"mcm","clk":"1004356756","pt":1580654624690,"mc":[{"id":"1.168224467","rc":[{"batb":[[0,14,6.22],[1,1.01,0.51],[2,14,0]],"ltp":0.0,"tv":0.0,"id":13117353},{"batb":[[0,4.9,17.04],[1,4.6,16.21],[2,1.01,0.51]],"ltp":0.0,"tv":0.0,"id":16604347},{"batb":[[0,3.75,13.06],[1,1.01,0.51],[2,3.75,0]],"ltp":0.0,"tv":0.0,"id":13117354}]}]}
{"op":"mcm","clk":"1004357579","pt":1580654628373,"mc":[{"id":"1.168224467","rc":[{"batb":[[0,21,3.12],[1,20,8.31],[2,18.5,6.37]],"ltp":0.0,"tv":0.0,"id":13117353},{"batb":[[0,5,13.66],[1,4.9,17.04],[2,4.6,16.21]],"batl":[[1,5.5,14.48]],"ltp":0.0,"tv":0.0,"id":16604347},{"batb":[[2,1.79,20.06]],"batl":[[0,1.98,17.39],[1,2.04,16.05],[2,2.12,28.33]],"ltp":0.0,"tv":0.0,"id":16604346},{"batb":[[0,4.1,12.58],[1,4,25.93],[2,3.95,23.13]],"batl":[[1,4.7,20.06]],"ltp":0.0,"tv":0.0,"id":13117354}]}]}
{"op":"mcm","clk":"1004357649","pt":1580654628690,"mc":[{"id":"1.168224467","rc":[{"batb":[[2,4.6,26.97]],"batl":[[0,5.5,23.72],[1,5.5,0]],"ltp":0.0,"tv":0.0,"id":16604347},{"batb":[[0,1.88,47.05],[1,1.86,62.87],[2,1.84,43.11]],"batl":[[2,2.08,38.65]],"ltp":0.0,"tv":0.0,"id":16604346},{"batl":[[0,4.4,11.76],[1,4.6,21.87],[2,4.7,20.06]],"ltp":0.0,"tv":0.0,"id":13117354}]}]}
{"op":"mcm","clk":"1004364638","pt":1580654660405,"mc":[{"id":"1.168224467","rc":[{"batb":[[0,18.5,6.37],[1,16.5,4.09],[2,1.01,0.51]],"ltp":0.0,"tv":0.0,"id":13117353},{"batb":[[0,4.9,17.04],[1,4.6,26.97],[2,1.01,0.51]],"ltp":0.0,"tv":0.0,"id":16604347},{"batb":[[1,1.86,17.62],[2,1.79,20.06]],"ltp":0.0,"tv":0.0,"id":16604346},{"batb":[[0,4,21.34],[1,3.95,23.13],[2,3.9,24.23]],"ltp":0.0,"tv":0.0,"id":13117354}]}]}
{"op":"mcm","clk":"1004364864","pt":1580654661435,"mc":[{"id":"1.168224467","rc":[{"batb":[[0,16.5,4.09],[1,1.01,0.51],[2,1.01,0]],"ltp":0.0,"tv":0.0,"id":13117353},{"batb":[[1,1.79,20.06],[2,1.01,0.51]],"batl":[[0,2.04,16.05],[1,2.08,38.65],[2,2.08,0]],"ltp":0.0,"tv":0.0,"id":16604346},{"batb":[[1,3.9,24.23],[2,3.7,15.12]],"batl":[[1,4.7,20.06],[2,4.7,0]],"ltp":0.0,"tv":0.0,"id":13117354}]}]}
{"op":"mcm","clk":"1004364958","pt":1580654661873,"mc":[{"id":"1.168224467","rc":[{"batb":[[1,4.6,16.05]],"batl":[[0,5.5,14.48]],"ltp":0.0,"tv":0.0,"id":16604347},{"batb":[[0,1.79,20.06],[1,1.01,0.51],[2,1.01,0]],"batl":[[1,2.08,0]],"ltp":0.0,"tv":0.0,"id":16604346},{"batb":[[2,1.01,0.51]],"batl":[[0,4.7,20.06],[1,4.7,0]],"ltp":0.0,"tv":0.0,"id":13117354}]}]}
{"op":"mcm","clk":"1004365264","pt":1580654663270,"mc":[{"id":"1.168224467","rc":[{"batb":[[0,18.5,5.6],[1,18,5.22],[2,16.5,4.09]],"ltp":0.0,"tv":0.0,"id":13117353},{"batb":[[0,4.9,23.4],[1,4.8,17.66],[2,4.6,16.05]],"ltp":0.0,"tv":0.0,"id":16604347},{"batb":[[0,1.8,33.44],[1,1.79,20.06],[2,1.78,47.97]],"ltp":0.0,"tv":0.0,"id":16604346},{"batb":[[1,3.95,13.45],[2,3.9,24.23]],"ltp":0.0,"tv":0.0,"id":13117354}]}]}
{"op":"mcm","clk":"1004365421","pt":1580654664014,"mc":[{"id":"1.168224467","rc":[{"batb":[[2,3.85,24.47]],"ltp":0.0,"tv":0.0,"id":13117354}]}]}
{"op":"mcm","clk":"1004365825","pt":1580654665899,"mc":[{"id":"1.168224467","rc":[{"batb":[[0,16.5,4.09],[1,1.01,0.51],[2,16.5,0]],"ltp":0.0,"tv":0.0,"id":13117353},{"batb":[[0,4.9,16.95],[1,4.6,16.05],[2,1.01,0.51]],"ltp":0.0,"tv":0.0,"id":16604347},{"batb":[[0,1.79,20.06],[1,1.01,0.51],[2,1.78,0]],"ltp":0.0,"tv":0.0,"id":16604346},{"batb":[[1,3.85,24.47],[2,1.01,0.51]],"ltp":0.0,"tv":0.0,"id":13117354}]}]}
{"op":"mcm","clk":"1004366524","pt":1580654669121,"mc":[{"id":"1.168224467","rc":[{"batb":[[0,22,2.49],[1,21,7.56],[2,16.5,4.09]],"ltp":0.0,"tv":0.0,"id":13117353},{"batb":[[0,5,16.26],[1,4.9,16.95],[2,4.6,16.05]],"ltp":0.0,"tv":0.0,"id":16604347},{"batb":[[0,1.85,37.86],[1,1.83,43.87],[2,1.79,20.06]],"ltp":0.0,"tv":0.0,"id":16604346},{"batb":[[0,4.1,18.57],[1,4,25.81],[2,3.85,24.47]],"ltp":0.0,"tv":0.0,"id":13117354}]}]}
{"op":"mcm","clk":"1004366960","pt":1580654671182,"mc":[{"id":"1.168224467","rc":[{"batb":[[0,16.5,4.09],[1,1.01,0.51],[2,16.5,0]],"ltp":0.0,"tv":0.0,"id":13117353},{"batb":[[0,4.9,16.95],[1,4.6,16.05],[2,1.01,0.51]],"ltp":0.0,"tv":0.0,"id":16604347},{"batb":[[0,1.79,20.06],[1,1.01,0.51],[2,1.79,0]],"ltp":0.0,"tv":0.0,"id":16604346},{"batb":[[0,4,21.34],[1,3.85,24.47],[2,1.01,0.51]],"ltp":0.0,"tv":0.0,"id":13117354}]}]}
{"op":"mcm","clk":"1004367626","pt":1580654674185,"mc":[{"id":"1.168224467","rc":[{"batb":[[0,18.5,5.45],[1,18,5.22],[2,16.5,4.09]],"ltp":0.0,"tv":0.0,"id":13117353},{"batb":[[0,4.9,23.68],[1,4.8,17.66],[2,4.6,16.05]],"ltp":0.0,"tv":0.0,"id":16604347},{"batb":[[0,1.8,34.66],[1,1.79,20.06],[2,1.78,47.97]],"ltp":0.0,"tv":0.0,"id":16604346},{"batb":[[1,3.95,13.45],[2,3.85,24.47]],"ltp":0.0,"tv":0.0,"id":13117354}]}]}
{"op":"mcm","clk":"1004370240","pt":1580654686212,"mc":[{"id":"1.168224467","rc":[{"batb":[[0,1.79,20.06],[1,1.01,0.51],[2,1.78,0]],"ltp":0.0,"tv":0.0,"id":16604346}]}]}
{"op":"mcm","clk":"1004370891","pt":1580654689191,"mc":[{"id":"1.168224467","rc":[{"batb":[[0,1.91,26.26],[1,1.89,39.6],[2,1.79,20.06]],"ltp":0.0,"tv":0.0,"id":16604346}]}]}
{"op":"mcm","clk":"1004371077","pt":1580654690090,"mc":[{"id":"1.168224467","rc":[{"batl":[[0,26,7.47]],"ltp":0.0,"tv":0.0,"id":13117353},{"batl":[[0,5.4,15.26],[1,5.5,14.48]],"ltp":0.0,"tv":0.0,"id":16604347},{"batb":[[0,1.91,42.55],[2,1.84,18.33]],"batl":[[1,2.1,29.58]],"ltp":0.0,"tv":0.0,"id":16604346},{"batl":[[0,4.4,23.13],[1,4.6,21.56]],"ltp":0.0,"tv":0.0,"id":13117354}]}]}
{"op":"mcm","clk":"1004371283","pt":1580654690982,"mc":[{"id":"1.168224467","rc":[{"batb":[[2,4.6,26.97]],"batl":[[1,5.5,23.72]],"ltp":0.0,"tv":0.0,"id":16604347},{"batb":[[0,1.91,16.29],[1,1.84,18.33],[2,1.01,0.51]],"ltp":0.0,"tv":0.0,"id":16604346},{"batl":[[0,4.3,12.6],[1,4.4,23.13],[2,4.6,21.56]],"ltp":0.0,"tv":0.0,"id":13117354}]}]}
{"op":"mcm","clk":"1004371559","pt":1580654692313,"mc":[{"id":"1.168224467","rc":[{"batb":[[0,1.92,45.37],[1,1.91,16.29],[2,1.84,18.33]],"batl":[[2,2.14,36.13]],"ltp":0.0,"tv":0.0,"id":16604346}]}]}
{"op":"mcm","clk":"1004371794","pt":1580654693504,"mc":[{"id":"1.168224467","rc":[{"batb":[[2,1.9,45.77]],"ltp":0.0,"tv":0.0,"id":16604346}]}]}
{"op":"mcm","clk":"1004373799","pt":1580654702810,"mc":[{"id":"1.168224467","rc":[{"batb":[[0,15.5,4.72],[1,1.01,0.51],[2,16.5,0]],"ltp":0.0,"tv":0.0,"id":13117353},{"batb":[[0,4.9,17.09]],"batl":[[0,5.5,23.72],[1,5.5,0]],"ltp":0.0,"tv":0.0,"id":16604347},{"batb":[[1,1.84,18.33],[2,1.01,0.51]],"batl":[[0,2.1,29.58],[1,2.14,36.13],[2,2.14,0]],"ltp":0.0,"tv":0.0,"id":16604346},{"batb":[[0,3.95,13.45],[1,3.8,12.9],[2,3.65,15.12]],"batl":[[1,4.6,21.56],[2,4.6,0]],"ltp":0.0,"tv":0.0,"id":13117354}]}]}
{"op":"mcm","clk":"1004374020","pt":1580654703844,"mc":[{"id":"1.168224467","rc":[{"batb":[[2,4.6,16.05]],"batl":[[0,5.5,14.48]],"ltp":0.0,"tv":0.0,"id":16604347},{"batb":[[0,1.84,18.33],[1,1.01,0.51],[2,1.01,0]],"batl":[[1,2.14,0]],"ltp":0.0,"tv":0.0,"id":16604346},{"batb":[[2,1.01,0.51]],"batl":[[0,4.6,21.56],[1,4.6,0]],"ltp":0.0,"tv":0.0,"id":13117354}]}]}
{"op":"mcm","clk":"1004374397","pt":1580654705440,"mc":[{"id":"1.168224467","rc":[{"batb":[[0,17,6.5],[1,16.5,6.22],[2,15.5,4.72]],"ltp":0.0,"tv":0.0,"id":13117353},{"batb":[[0,1.84,62.07],[1,1.82,44.67],[2,1.01,0.51]],"ltp":0.0,"tv":0.0,"id":16604346},{"batb":[[1,3.9,13.91],[2,3.8,12.9]],"ltp":0.0,"tv":0.0,"id":13117354}]}]}
{"op":"mcm","clk":"1004375158","pt":1580654708438,"mc":[{"id":"1.168224467","rc":[{"batb":[[0,15.5,4.72],[1,1.01,0.51],[2,15.5,0]],"ltp":0.0,"tv":0.0,"id":13117353},{"batb":[[0,1.84,18.33],[1,1.01,0.51],[2,1.01,0]],"ltp":0.0,"tv":0.0,"id":16604346},{"batb":[[1,3.8,12.9],[2,1.01,0.51]],"ltp":0.0,"tv":0.0,"id":13117354}]}]}
{"op":"mcm","clk":"1004375854","pt":1580654711432,"mc":[{"id":"1.168224467","rc":[{"batb":[[0,19,6.18],[1,18.5,4.92],[2,15.5,4.72]],"ltp":0.0,"tv":0.0,"id":13117353},{"batb":[[0,4.9,26.02]],"ltp":0.0,"tv":0.0,"id":16604347},{"batb":[[0,1.89,40.76],[1,1.87,40.96],[2,1.84,18.33]],"ltp":0.0,"tv":0.0,"id":16604346},{"batb":[[0,4,26.61],[1,3.95,13.45],[2,3.8,12.9]],"ltp":0.0,"tv":0.0,"id":13117354}]}]}
{"op":"mcm","clk":"1004376902","pt":1580654716161,"mc":[{"id":"1.168224467","rc":[{"batb":[[0,15.5,4.72],[1,1.01,0.51],[2,15.5,0]],"ltp":0.0,"tv":0.0,"id":13117353},{"batb":[[0,4.9,17.09]],"ltp":0.0,"tv":0.0,"id":16604347},{"batb":[[0,1.84,18.33],[1,1.01,0.51],[2,1.84,0]],"ltp":0.0,"tv":0.0,"id":16604346},{"batb":[[0,3.95,13.45],[1,3.8,12.9],[2,1.01,0.51]],"ltp":0.0,"tv":0.0,"id":13117354}]}]}
{"op":"mcm","clk":"1004377556","pt":1580654719115,"mc":[{"id":"1.168224467","rc":[{"batb":[[0,17,6.5],[1,16.5,6.22],[2,15.5,4.72]],"ltp":0.0,"tv":0.0,"id":13117353},{"batb":[[0,1.84,62.07],[1,1.82,44.67],[2,1.01,0.51]],"ltp":0.0,"tv":0.0,"id":16604346},{"batb":[[1,3.9,13.91],[2,3.8,12.9]],"ltp":0.0,"tv":0.0,"id":13117354}]}]}
{"op":"mcm","clk":"1004377781","pt":1580654720136,"mc":[{"id":"1.168224467","rc":[{"batb":[[0,1.84,18.33],[1,1.01,0.51],[2,1.01,0]],"ltp":0.0,"tv":0.0,"id":16604346}]}]}
{"op":"mcm","clk":"1004378437","pt":1580654723146,"mc":[{"id":"1.168224467","rc":[{"batb":[[0,1.94,38.68],[1,1.92,37.72],[2,1.84,18.33]],"ltp":0.0,"tv":0.0,"id":16604346}]}]}
{"op":"mcm","clk":"1004378683","pt":1580654724348,"mc":[{"id":"1.168224467","rc":[{"batl":[[0,23,4.48],[1,27,7.08]],"ltp":0.0,"tv":0.0,"id":13117353},{"batl":[[0,5.3,15.66],[1,5.4,14.95],[2,5.5,14.48]],"ltp":0.0,"tv":0.0,"id":16604347},{"batb":[[0,1.95,30.53],[1,1.94,38.68],[2,1.92,37.72]],"batl":[[1,2.14,27.7]],"ltp":0.0,"tv":0.0,"id":16604346},{"batl":[[0,4.3,24.39],[1,4.5,22.35],[2,4.6,21.56]],"ltp":0.0,"tv":0.0,"id":13117354}]}]}
{"op":"mcm","clk":"1004378769","pt":1580654724769,"mc":[{"id":"1.168224467","rc":[{"batb":[[2,4.6,26.97]],"batl":[[2,5.5,9.24]],"ltp":0.0,"tv":0.0,"id":16604347},{"batb":[[0,1.95,74.22]],"batl":[[2,2.16,36.13]],"ltp":0.0,"tv":0.0,"id":16604346},{"batl":[[0,4.2,12.6],[1,4.3,24.39],[2,4.5,22.35]],"ltp":0.0,"tv":0.0,"id":13117354}]}]}
{"op":"mcm","clk":"1004380980","pt":1580654735065,"mc":[{"id":"1.168224467","rc":[{"batb":[[0,14.5,5.35],[1,1.01,0.51],[2,15.5,0]],"batl":[[0,27,7.08],[1,27,0]],"ltp":0.0,"tv":0.0,"id":13117353},{"batb":[[0,4.9,12.02],[2,4.6,10.92]],"batl":[[0,5.4,14.95],[1,5.5,9.24],[2,5.5,0]],"ltp":0.0,"tv":0.0,"id":16604347},{"batb":[[0,1.95,43.69],[1,1.88,17],[2,1.01,0.51]],"batl":[[0,2.14,27.7],[1,2.16,36.13],[2,2.16,0]],"ltp":0.0,"tv":0.0,"id":16604346},{"batb":[[0,3.9,13.91],[1,3.7,13.38],[2,3.6,15.96]],"batl":[[1,4.5,22.35],[2,4.5,0]],"ltp":0.0,"tv":0.0,"id":13117354}]}]}
{"op":"mcm","clk":"1004381122","pt":1580654735784,"mc":[{"id":"1.168224467","rc":[{"batb":[[2,4.5,16.84]],"batl":[[1,5.5,0]],"ltp":0.0,"tv":0.0,"id":16604347},{"batb":[[0,1.88,17],[1,1.01,0.51],[2,1.01,0]],"batl":[[1,2.16,0]],"ltp":0.0,"tv":0.0,"id":16604346},{"batb":[[2,1.01,0.51]],"batl":[[0,4.5,22.35],[1,4.5,0]],"ltp":0.0,"tv":0.0,"id":13117354}]}]}
{"op":"mcm","clk":"1004381670","pt":1580654738289,"mc":[{"id":"1.168224467","rc":[{"batb":[[0,16,8.9],[1,15.5,7.01],[2,14.5,5.35]],"ltp":0.0,"tv":0.0,"id":13117353},{"batb":[[0,1.89,30.39],[1,1.88,17],[2,1.87,40.96]],"ltp":0.0,"tv":0.0,"id":16604346},{"batb":[[1,3.85,14.38],[2,3.7,13.38]],"ltp":0.0,"tv":0.0,"id":13117354}]}]}
{"op":"mcm","clk":"1004382021","pt":1580654740175,"mc":[{"id":"1.168224467","rc":[{"batb":[[0,14.5,5.35],[1,1.01,0.51],[2,14.5,0]],"ltp":0.0,"tv":0.0,"id":13117353},{"batb":[[0,1.88,17],[1,1.01,0.51],[2,1.87,0]],"ltp":0.0,"tv":0.0,"id":16604346},{"batb":[[1,3.7,13.38],[2,1.01,0.51]],"ltp":0.0,"tv":0.0,"id":13117354}]}]}
{"op":"mcm","clk":"1004382716","pt":1580654743380,"mc":[{"id":"1.168224467","rc":[{"batb":[[0,17.5,4.34],[1,17,5.91],[2,14.5,5.35]],"ltp":0.0,"tv":0.0,"id":13117353},{"batb":[[0,4.9,19.12]],"ltp":0.0,"tv":0.0,"id":16604347},{"batb":[[0,1.93,36.66],[1,1.91,38.33],[2,1.88,17]],"ltp":0.0,"tv":0.0,"id":16604346},{"batb":[[0,3.95,23.05],[1,3.9,13.91],[2,3.7,13.38]],"ltp":0.0,"tv":0.0,"id":13117354}]}]}
{"op":"mcm","clk":"1004383378","pt":1580654746656,"mc":[{"id":"1.168224467","rc":[{"batb":[[0,14.5,5.35],[1,1.01,0.51],[2,14.5,0]],"ltp":0.0,"tv":0.0,"id":13117353},{"batb":[[0,4.9,12.02]],"ltp":0.0,"tv":0.0,"id":16604347},{"batb":[[0,1.88,17],[1,1.01,0.51],[2,1.88,0]],"ltp":0.0,"tv":0.0,"id":16604346},{"batb":[[0,3.9,13.91],[1,3.7,13.38],[2,1.01,0.51]],"ltp":0.0,"tv":0.0,"id":13117354}]}]}
{"op":"mcm","clk":"1004384049","pt":1580654749579,"mc":[{"id":"1.168224467","rc":[{"batb":[[0,16,8.9],[1,15.5,7.01],[2,14.5,5.35]],"ltp":0.0,"tv":0.0,"id":13117353},{"batb":[[0,1.89,30.39],[1,1.88,17],[2,1.87,40.96]],"ltp":0.0,"tv":0.0,"id":16604346},{"batb":[[1,3.85,14.38],[2,3.7,13.38]],"ltp":0.0,"tv":0.0,"id":13117354}]}]}
{"op":"mcm","clk":"1004385490","pt":1580654756305,"mc":[{"id":"1.168224467","rc":[{"batb":[[0,14.5,5.35],[1,1.01,0.51],[2,14.5,0]],"ltp":0.0,"tv":0.0,"id":13117353},{"batb":[[1,4.5,16.84],[2,1.01,0.51]],"ltp":0.0,"tv":0.0,"id":16604347},{"batb":[[0,3.7,13.38],[1,1.01,0.51],[2,3.7,0]],"ltp":0.0,"tv":0.0,"id":13117354}]}]}
{"op":"mcm","clk":"1004386073","pt":1580654758900,"mc":[{"id":"1.168224467","rc":[{"batb":[[0,19,3.54],[1,18.5,4.98],[2,14.5,5.35]],"ltp":0.0,"tv":0.0,"id":13117353},{"batb":[[0,5,10.11],[1,4.9,17.06],[2,4.5,16.84]],"ltp":0.0,"tv":0.0,"id":16604347},{"batb":[[0,4,34.59],[1,3.95,13.33],[2,3.7,13.38]],"ltp":0.0,"tv":0.0,"id":13117354}]}]}
{"op":"mcm","clk":"1004386301","pt":1580654759916,"mc":[{"id":"1.168224467","rc":[{"batb":[[2,17,7.79]],"ltp":0.0,"tv":0.0,"id":13117353},{"batb":[[2,4.6,16.21]],"batl":[[1,5.5,14.4]],"ltp":0.0,"tv":0.0,"id":16604347},{"batl":[[0,2,16.68],[1,2.06,15.5]],"ltp":0.0,"tv":0.0,"id":16604346},{"batb":[[2,3.9,23.6]],"batl":[[1,4.7,20.06]],"ltp":0.0,"tv":0.0,"id":13117354}]}]}
{"op":"mcm","clk":"1004386494","pt":1580654760823,"mc":[{"id":"1.168224467","rc":[{"batl":[[0,5.4,24.19]],"ltp":0.0,"tv":0.0,"id":16604347},{"batb":[[0,1.9,46.21],[1,1.89,30.39],[2,1.88,17]],"batl":[[2,2.1,37.81]],"ltp":0.0,"tv":0.0,"id":16604346},{"batl":[[0,4.4,11.76],[1,4.5,22.35],[2,4.7,20.06]],"ltp":0.0,"tv":0.0,"id":13117354}]}]}
{"op":"mcm","clk":"1004389660","pt":1580654775415,"mc":[{"id":"1.168224467","rc":[{"batb":[[0,17,7.79],[1,15.5,4.72],[2,1.01,0.51]],"ltp":0.0,"tv":0.0,"id":13117353},{"batb":[[0,4.9,17.06],[1,4.6,16.21],[2,4.5,11.76]],"ltp":0.0,"tv":0.0,"id":16604347},{"batb":[[1,1.88,17],[2,1.8,19.59]],"ltp":0.0,"tv":0.0,"id":16604346},{"batb":[[0,4,17.04]],"ltp":0.0,"tv":0.0,"id":13117354}]}]}
{"op":"mcm","clk":"1004389727","pt":1580654775737,"mc":[{"id":"1.168224467","rc":[{"batb":[[0,15.5,4.72],[1,1.01,0.51],[2,1.01,0]],"ltp":0.0,"tv":0.0,"id":13117353},{"batb":[[2,1.01,0.51]],"batl":[[0,5.5,14.4],[1,5.5,0]],"ltp":0.0,"tv":0.0,"id":16604347},{"batb":[[0,1.8,19.59],[1,1.01,0.51],[2,1.8,0]],"batl":[[0,2.06,15.5],[1,2.06,0],[2,2.1,0]],"ltp":0.0,"tv":0.0,"id":16604346},{"batb":[[2,3.85,24.47]],"batl":[[0,4.7,20.06],[1,4.5,0],[2,4.7,0]],"ltp":0.0,"tv":0.0,"id":13117354}]}]}
{"op":"mcm","clk":"1004390492","pt":1580654779205,"mc":[{"id":"1.168224467","rc":[{"batb":[[0,17,6.33],[1,16.5,6.22],[2,15.5,4.72]],"ltp":0.0,"tv":0.0,"id":13117353},{"batb":[[1,4.8,17.73],[2,4.6,16.21]],"ltp":0.0,"tv":0.0,"id":16604347},{"batb":[[0,1.82,40.52],[1,1.8,65.88],[2,1.01,0.51]],"ltp":0.0,"tv":0.0,"id":16604346}]}]}
{"op":"mcm","clk":"1004391197","pt":1580654782344,"mc":[{"id":"1.168224467","rc":[{"batb":[[0,1.8,19.59],[1,1.01,0.51],[2,1.01,0]],"ltp":0.0,"tv":0.0,"id":16604346}]}]}
{"op":"mcm","clk":"1004391817","pt":1580654785004,"mc":[{"id":"1.168224467","rc":[{"batb":[[0,1.93,30.41],[1,1.91,38.34],[2,1.8,19.59]],"ltp":0.0,"tv":0.0,"id":16604346}]}]}
{"op":"mcm","clk":"1004392049","pt":1580654786073,"mc":[{"id":"1.168224467","rc":[{"batl":[[0,23,4.48],[1,27,7]],"ltp":0.0,"tv":0.0,"id":13117353},{"batl":[[0,5.4,14.79]],"ltp":0.0,"tv":0.0,"id":16604347},{"batb":[[0,1.93,46.15],[2,1.86,17.78]],"batl":[[1,2.12,28.72]],"ltp":0.0,"tv":0.0,"id":16604346},{"batl":[[0,4.4,23.13],[1,4.6,20.93]],"ltp":0.0,"tv":0.0,"id":13117354}]}]}
{"op":"mcm","clk":"1004392189","pt":1580654786770,"mc":[{"id":"1.168224467","rc":[{"batl":[[1,5.5,9.24]],"ltp":0.0,"tv":0.0,"id":16604347},{"batb":[[0,1.93,90.68]],"batl":[[2,2.14,36.13]],"ltp":0.0,"tv":0.0,"id":16604346},{"batl":[[0,4.3,12.6],[1,4.4,23.13],[2,4.6,20.93]],"ltp":0.0,"tv":0.0,"id":13117354}]}]}
{"op":"mcm","clk":"1004394430","pt":1580654797317,"mc":[{"id":"1.168224467","rc":[{"batb":[[0,15,5.35],[1,1.01,0.51],[2,15.5,0]],"batl":[[0,27,7],[1,27,0]],"ltp":0.0,"tv":0.0,"id":13117353},{"batb":[[2,4.5,28.36]],"ltp":0.0,"tv":0.0,"id":16604347},{"batb":[[0,1.93,44.53],[1,1.86,17.78],[2,1.01,0.51]],"batl":[[0,2.12,28.72],[1,2.14,36.13],[2,2.14,0]],"ltp":0.0,"tv":0.0,"id":16604346},{"batb":[[0,3.75,13.06],[1,3.65,15.12],[2,1.01,0.51]],"batl":[[1,4.6,20.93],[2,4.6,0]],"ltp":0.0,"tv":0.0,"id":13117354}]}]}
{"op":"mcm","clk":"1004394534","pt":1580654797795,"mc":[{"id":"1.168224467","rc":[{"batb":[[2,4.5,16.6]],"batl":[[1,5.5,0]],"ltp":0.0,"tv":0.0,"id":16604347},{"batb":[[0,1.86,17.78],[1,1.01,0.51],[2,1.01,0]],"batl":[[1,2.14,0]],"ltp":0.0,"tv":0.0,"id":16604346},{"batb":[[1,1.01,0.51],[2,1.01,0]],"batl":[[0,4.6,20.93],[1,4.6,0]],"ltp":0.0,"tv":0.0,"id":13117354}]}]}
{"op":"mcm","clk":"1004395101","pt":1580654800374,"mc":[{"id":"1.168224467","rc":[{"batb":[[0,16,9.78],[1,15.5,6.98],[2,15,5.35]],"ltp":0.0,"tv":0.0,"id":13117353},{"batb":[[0,1.87,45.9],[1,1.86,17.78],[2,1.85,42.42]],"ltp":0.0,"tv":0.0,"id":16604346},{"batb":[[0,3.9,26.73],[1,3.85,14.25],[2,3.75,13.06]],"ltp":0.0,"tv":0.0,"id":13117354}]}]}
{"op":"mcm","clk":"1004395905","pt":1580654804206,"mc":[{"id":"1.168224467","rc":[{"batb":[[0,1.86,17.78],[1,1.01,0.51],[2,1.85,0]],"ltp":0.0,"tv":0.0,"id":16604346}]}]}
{"op":"mcm","clk":"1004396453","pt":1580654807090,"mc":[{"id":"1.168224467","rc":[{"batb":[[0,1.96,31.35],[1,1.94,36.54],[2,1.86,17.78]],"ltp":0.0,"tv":0.0,"id":16604346}]}]}
{"op":"mcm","clk":"1004396666","pt":1580654808118,"mc":[{"id":"1.168224467","rc":[{"batl":[[0,22,5.04]],"ltp":0.0,"tv":0.0,"id":13117353},{"batl":[[0,5.3,15.66]],"ltp":0.0,"tv":0.0,"id":16604347},{"batb":[[0,1.97,29.51],[1,1.96,31.35],[2,1.94,36.54]],"batl":[[1,2.34,21.72]],"ltp":0.0,"tv":0.0,"id":16604346},{"batl":[[0,4.3,24.31]],"ltp":0.0,"tv":0.0,"id":13117354}]}]}
{"op":"mcm","clk":"1004396794","pt":1580654808710,"mc":[{"id":"1.168224467","rc":[{"batb":[[2,4.6,10.92]],"batl":[[1,5.5,9.24]],"ltp":0.0,"tv":0.0,"id":16604347},{"batb":[[0,1.98,42.85],[1,1.97,29.51],[2,1.96,31.35]],"batl":[[1,2.2,34.45],[2,2.34,21.72]],"ltp":0.0,"tv":0.0,"id":16604346},{"batl":[[0,4.2,12.6],[1,4.3,24.31]],"ltp":0.0,"tv":0.0,"id":13117354}]}]}
{"op":"mcm","clk":"1004411205","pt":1580654885420,"mc":[{"id":"1.168224467","rc":[{"batb":[[0,15,5.35],[1,8.6,7.4],[2,1.01,0.51]],"ltp":0.0,"tv":0.0,"id":13117353},{"batb":[[0,4.9,12.06]],"ltp":0.0,"tv":0.0,"id":16604347},{"batb":[[2,1.88,17.15]],"ltp":0.0,"tv":0.0,"id":16604346},{"batb":[[0,3.9,21.81]],"ltp":0.0,"tv":0.0,"id":13117354}]}]}
{"op":"mcm","clk":"1004411268","pt":1580654885743,"mc":[{"id":"1.168224467","rc":[{"batb":[[0,8.6,7.4],[1,1.01,0.51],[2,1.01,0]],"ltp":0.0,"tv":0.0,"id":13117353},{"batb":[[2,4.5,16.6]],"batl":[[1,5.5,0]],"ltp":0.0,"tv":0.0,"id":16604347},{"batb":[[0,1.88,17.15],[1,1.01,0.51],[2,1.88,0]],"batl":[[0,2.34,21.72],[1,2.2,0],[2,2.34,0]],"ltp":0.0,"tv":0.0,"id":16604346},{"batl":[[0,4.3,24.31],[1,4.3,0]],"ltp":0.0,"tv":0.0,"id":13117354}]}]}
{"op":"mcm","clk":"1004411727","pt":1580654888346,"mc":[{"id":"1.168224467","rc":[{"batb":[[0,9,7.03],[1,8.8,9.49],[2,8.6,7.4]],"ltp":0.0,"tv":0.0,"id":13117353},{"batb":[[1,1.87,27.62],[2,1.85,42.3]],"ltp":0.0,"tv":0.0,"id":16604346}]}]}
{"op":"mcm","clk":"1004412005","pt":1580654889808,"mc":[{"id":"1.168224467","rc":[{"batb":[[0,8.6,7.4],[1,1.01,0.51],[2,8.6,0]],"ltp":0.0,"tv":0.0,"id":13117353}]}]}
{"op":"mcm","clk":"1004412546","pt":1580654892741,"mc":[{"id":"1.168224467","rc":[{"batb":[[0,29,4.69],[1,28,4.14],[2,8.6,7.4]],"ltp":0.0,"tv":0.0,"id":13117353},{"batb":[[0,4.9,15.84]],"ltp":0.0,"tv":0.0,"id":16604347}]}]}
{"op":"mcm","clk":"1004412753","pt":1580654893843,"mc":[{"id":"1.168224467","rc":[{"batb":[[2,24,5.22]],"ltp":0.0,"tv":0.0,"id":13117353},{"batl":[[0,2,16.92],[1,2.18,26.36]],"ltp":0.0,"tv":0.0,"id":16604346},{"batl":[[0,4.4,24.23]],"ltp":0.0,"tv":0.0,"id":13117354}]}]}
{"op":"mcm","clk":"1004412920","pt":1580654894743,"mc":[{"id":"1.168224467","rc":[{"batb":[[2,4.5,28.36]],"batl":[[1,5.4,9.24]],"ltp":0.0,"tv":0.0,"id":16604347},{"batb":[[0,1.89,47.05],[1,1.88,17.15],[2,1.87,27.62]],"batl":[[1,2.1,37.81],[2,2.18,26.36]],"ltp":0.0,"tv":0.0,"id":16604346},{"batl":[[0,4.1,13.44],[1,4.4,24.23]],"ltp":0.0,"tv":0.0,"id":13117354}]}]}
{"op":"mcm","clk":"1004414510","pt":1580654903325,"mc":[{"id":"1.168224467","rc":[{"batb":[[0,24,5.22],[1,13,7.24],[2,1.01,0.51]],"ltp":0.0,"tv":0.0,"id":13117353},{"batb":[[0,4.9,12.02]],"ltp":0.0,"tv":0.0,"id":16604347},{"batb":[[2,1.81,19.36]],"ltp":0.0,"tv":0.0,"id":16604346},{"batb":[[0,3.9,17.01]],"ltp":0.0,"tv":0.0,"id":13117354}]}]}
{"op":"mcm","clk":"1004414620","pt":1580654903858,"mc":[{"id":"1.168224467","rc":[{"batb":[[0,13,7.24],[1,1.01,0.51],[2,1.01,0]],"ltp":0.0,"tv":0.0,"id":13117353},{"batb":[[2,4.5,16.6]],"batl":[[1,5.4,0]],"ltp":0.0,"tv":0.0,"id":16604347},{"batb":[[0,1.81,19.36],[1,1.01,0.51],[2,1.81,0]],"batl":[[0,2.18,26.36],[1,2.1,0],[2,2.18,0]],"ltp":0.0,"tv":0.0,"id":16604346},{"batl":[[0,4.4,24.23],[1,4.4,0]],"ltp":0.0,"tv":0.0,"id":13117354}]}]}
{"op":"mcm","clk":"1004415035","pt":1580654906337,"mc":[{"id":"1.168224467","rc":[{"batb":[[0,14,8.15],[1,13.5,9.36],[2,13,7.24]],"ltp":0.0,"tv":0.0,"id":13117353},{"batb":[[1,1.8,36.75],[2,1.78,47.87]],"ltp":0.0,"tv":0.0,"id":16604346}]}]}
{"op":"mcm","clk":"1004415201","pt":1580654907148,"mc":[{"id":"1.168224467","rc":[{"batb":[[0,13,7.24],[1,1.01,0.51],[2,13,0]],"ltp":0.0,"tv":0.0,"id":13117353}]}]}
{"op":"mcm","clk":"1004415758","pt":1580654910267,"mc":[{"id":"1.168224467","rc":[{"batb":[[0,4.9,18.31]],"ltp":0.0,"tv":0.0,"id":16604347},{"batb":[[0,3.9,24.08]],"ltp":0.0,"tv":0.0,"id":13117354}]}]}
{"op":"mcm","clk":"1004415943","pt":1580654911357,"mc":[{"id":"1.168224467","rc":[{"batb":[[0,23,3.08]],"ltp":0.0,"tv":0.0,"id":13117353},{"batb":[[2,4.5,28.36]],"batl":[[0,5.4,24.35]],"ltp":0.0,"tv":0.0,"id":16604347},{"batb":[[0,1.83,50.41],[1,1.81,19.36],[2,1.8,36.75]],"batl":[[0,1.92,19.04],[1,2.02,41.17],[2,2.04,15.97]],"ltp":0.0,"tv":0.0,"id":16604346},{"batb":[[2,3.8,25.65]],"batl":[[0,4.1,13.44],[1,4.4,23.29]],"ltp":0.0,"tv":0.0,"id":13117354}]}]}
{"op":"mcm","clk":"1004416301","pt":1580654913446,"mc":[{"id":"1.168224467","rc":[{"batb":[[0,65,4.46],[1,23,3.08],[2,1.01,0.51]],"ltp":0.0,"tv":0.0,"id":13117353}]}]}
{"op":"mcm","clk":"1004417325","pt":1580654919364,"mc":[{"id":"1.168224467","rc":[{"batl":[[0,4.4,23.29],[1,4.4,0]],"ltp":0.0,"tv":0.0,"id":13117354}]}]}
{"op":"mcm","clk":"1004417428","pt":1580654920045,"mc":[{"id":"1.168224467","rc":[{"batb":[[0,23,3.08],[1,1.01,0.51],[2,1.01,0]],"ltp":0.0,"tv":0.0,"id":13117353},{"batb":[[0,4.9,12.15]],"ltp":0.0,"tv":0.0,"id":16604347},{"batb":[[1,1.75,21.32],[2,1.01,0.51]],"batl":[[0,2.02,41.17],[1,2.04,15.97],[2,2.04,0]],"ltp":0.0,"tv":0.0,"id":16604346},{"batb":[[0,3.85,14.25],[1,3.7,13.61],[2,1.01,0.51]],"ltp":0.0,"tv":0.0,"id":13117354}]}]}
{"op":"mcm","clk":"1004417799","pt":1580654922370,"mc":[{"id":"1.168224467","rc":[{"batb":[[2,4.5,16.6]],"batl":[[0,5.4,15.11]],"ltp":0.0,"tv":0.0,"id":16604347},{"batb":[[0,1.75,21.32],[1,1.01,0.51],[2,1.01,0]],"batl":[[0,2.04,15.97],[1,2.04,0]],"ltp":0.0,"tv":0.0,"id":16604346}]}]}
{"op":"mcm","clk":"1004417935","pt":1580654923154,"mc":[{"id":"1.168224467","rc":[{"batb":[[0,28,4.43],[1,27,4.46],[2,23,3.08]],"ltp":0.0,"tv":0.0,"id":13117353},{"batb":[[0,1.76,32.95],[1,1.75,21.32],[2,1.74,51.55]],"ltp":0.0,"tv":0.0,"id":16604346},{"batb":[[1,3.8,14.75],[2,3.7,13.61]],"ltp":0.0,"tv":0.0,"id":13117354}]}]}
{"op":"mcm","clk":"1004418147","pt":1580654924594,"mc":[{"id":"1.168224467","rc":[{"batb":[[0,23,3.08],[1,1.01,0.51],[2,23,0]],"ltp":0.0,"tv":0.0,"id":13117353},{"batb":[[0,1.75,21.32],[1,1.01,0.51],[2,1.74,0]],"ltp":0.0,"tv":0.0,"id":16604346},{"batb":[[1,3.7,13.61],[2,1.01,0.51]],"ltp":0.0,"tv":0.0,"id":13117354}]}]}
{"op":"mcm","clk":"1004418727","pt":1580654928085,"mc":[{"id":"1.168224467","rc":[{"batb":[[0,50,6.35],[1,23,3.08],[2,1.01,0.51]],"ltp":0.0,"tv":0.0,"id":13117353},{"batb":[[0,4.9,13.56]],"ltp":0.0,"tv":0.0,"id":16604347},{"batb":[[0,3.9,18.27]],"ltp":0.0,"tv":0.0,"id":13117354}]}]}
{"op":"mcm","clk":"1004418911","pt":1580654929276,"mc":[{"id":"1.168224467","rc":[{"batb":[[0,23,3.08],[1,1.01,0.51],[2,1.01,0]],"ltp":0.0,"tv":0.0,"id":13117353},{"batb":[[0,4.8,17.73],[1,4.5,16.6],[2,1.01,0.51]],"ltp":0.0,"tv":0.0,"id":16604347}]}]}
{"op":"mcm","clk":"1004419397","pt":1580654932362,"mc":[{"id":"1.168224467","rc":[{"batb":[[0,28,5.91],[1,27,4.47],[2,23,3.08]],"ltp":0.0,"tv":0.0,"id":13117353},{"batb":[[0,4.8,25.97],[1,4.7,18.41],[2,4.5,16.6]],"ltp":0.0,"tv":0.0,"id":16604347},{"batb":[[0,1.75,61.48],[1,1.73,52.67],[2,1.01,0.51]],"ltp":0.0,"tv":0.0,"id":16604346},{"batb":[[1,3.85,14.43],[2,3.7,13.61]],"ltp":0.0,"tv":0.0,"id":13117354}]}]}
{"op":"mcm","clk":"1004419932","pt":1580654936087,"mc":[{"id":"1.168224467","rc":[{"batb":[[0,23,3.08],[1,1.01,0.51],[2,23,0]],"ltp":0.0,"tv":0.0,"id":13117353},{"batb":[[0,4.8,17.73],[1,4.5,16.6],[2,1.01,0.51]],"ltp":0.0,"tv":0.0,"id":16604347},{"batb":[[0,3.7,13.61],[1,1.01,0.51],[2,3.7,0]],"ltp":0.0,"tv":0.0,"id":13117354}]}]}
{"op":"mcm","clk":"1004420499","pt":1580654939281,"mc":[{"id":"1.168224467","rc":[{"batb":[[0,4.9,18.72],[1,4.8,17.73],[2,4.5,16.6]],"ltp":0.0,"tv":0.0,"id":16604347},{"batb":[[0,4,18.96],[1,3.95,13.51],[2,3.7,13.61]],"ltp":0.0,"tv":0.0,"id":13117354}]}]}
{"op":"mcm","clk":"1004420592","pt":1580654939911,"mc":[{"id":"1.168224467","rc":[{"batb":[[0,1.01,0.51],[1,1.01,0]],"ltp":0.0,"tv":0.0,"id":13117353},{"batb":[[2,4.6,15.82]],"batl":[[0,5.4,14.79]],"ltp":0.0,"tv":0.0,"id":16604347},{"batb":[[2,1.72,22.66]],"batl":[[0,1.86,21.01],[1,1.94,18.25]],"ltp":0.0,"tv":0.0,"id":16604346},{"batb":[[2,3.85,24.63]],"batl":[[1,4.5,22.27]],"ltp":0.0,"tv":0.0,"id":13117354}]}]}
{"op":"mcm","clk":"1004420808","pt":1580654941205,"mc":[{"id":"1.168224467","rc":[{"batl":[[0,5.4,24.03]],"ltp":0.0,"tv":0.0,"id":16604347},{"batb":[[0,1.77,53.77],[1,1.75,61.48],[2,1.73,52.67]],"batl":[[2,1.97,42.01]],"ltp":0.0,"tv":0.0,"id":16604346},{"batl":[[0,4.3,12.6],[1,4.4,23.29],[2,4.5,22.27]],"ltp":0.0,"tv":0.0,"id":13117354}]}]}
{"op":"mcm","clk":"1004422048","pt":1580654948291,"mc":[{"id":"1.168224467","rc":[{"batb":[[0,4.8,17.73],[1,4.6,15.82],[2,4.5,28.36]],"ltp":0.0,"tv":0.0,"id":16604347},{"batb":[[1,1.75,21.32],[2,1.72,22.66]],"ltp":0.0,"tv":0.0,"id":16604346},{"batb":[[0,3.85,24.63],[1,3.7,13.61],[2,3.6,15.96]],"ltp":0.0,"tv":0.0,"id":13117354}]}]}
{"op":"mcm","clk":"1004422073","pt":1580654948508,"mc":[{"id":"1.168224467","rc":[{"batb":[[1,4.5,28.36],[2,1.01,0.51]],"ltp":0.0,"tv":0.0,"id":16604347},{"batb":[[1,1.72,22.66],[2,1.01,0.51]],"batl":[[0,1.94,18.25],[1,1.97,42.01],[2,1.97,0]],"ltp":0.0,"tv":0.0,"id":16604346},{"batb":[[0,3.7,13.61],[1,3.6,15.96],[2,1.01,0.51]],"batl":[[1,4.5,22.27],[2,4.5,0]],"ltp":0.0,"tv":0.0,"id":13117354}]}]}
{"op":"mcm","clk":"1004422371","pt":1580654950313,"mc":[{"id":"1.168224467","rc":[{"batb":[[1,4.5,16.6]],"batl":[[0,5.4,14.79]],"ltp":0.0,"tv":0.0,"id":16604347},{"batb":[[0,1.72,22.66],[1,1.01,0.51],[2,1.01,0]],"batl":[[1,1.97,0]],"ltp":0.0,"tv":0.0,"id":16604346},{"batb":[[1,1.01,0.51],[2,1.01,0]],"batl":[[0,4.5,22.27],[1,4.5,0]],"ltp":0.0,"tv":0.0,"id":13117354}]}]}
{"op":"mcm","clk":"1004422551","pt":1580654951411,"mc":[{"id":"1.168224467","rc":[{"batb":[[0,4.8,27.88],[1,4.7,18.33],[2,4.5,16.6]],"ltp":0.0,"tv":0.0,"id":16604347},{"batb":[[0,1.72,78.59],[1,1.7,56.67],[2,1.01,0.51]],"ltp":0.0,"tv":0.0,"id":16604346},{"batb":[[0,3.9,13.14],[1,3.85,14.42],[2,3.7,13.61]],"ltp":0.0,"tv":0.0,"id":13117354}]}]}
{"op":"mcm","clk":"1004422902","pt":1580654953726,"mc":[{"id":"1.168224467","rc":[{"batb":[[0,4.8,17.73],[1,4.5,16.6],[2,1.01,0.51]],"ltp":0.0,"tv":0.0,"id":16604347},{"batb":[[0,1.72,22.66],[1,1.01,0.51],[2,1.01,0]],"ltp":0.0,"tv":0.0,"id":16604346},{"batb":[[1,3.7,13.61],[2,1.01,0.51]],"ltp":0.0,"tv":0.0,"id":13117354}]}]}
{"op":"mcm","clk":"1004423341","pt":1580654956907,"mc":[{"id":"1.168224467","rc":[{"batb":[[0,4.9,16.93],[1,4.8,17.73],[2,4.5,16.6]],"ltp":0.0,"tv":0.0,"id":16604347},{"batb":[[0,1.76,39.81],[1,1.74,51.65],[2,1.72,22.66]],"ltp":0.0,"tv":0.0,"id":16604346},{"batb":[[0,3.95,26.06],[1,3.9,13.14],[2,3.7,13.61]],"ltp":0.0,"tv":0.0,"id":13117354}]}]}
{"op":"mcm","clk":"1004423928","pt":1580654961089,"mc":[{"id":"1.168224467","rc":[{"batb":[[0,4.8,17.73],[1,4.5,16.6],[2,1.01,0.51]],"ltp":0.0,"tv":0.0,"id":16604347},{"batb":[[0,1.72,22.66],[1,1.01,0.51],[2,1.72,0]],"ltp":0.0,"tv":0.0,"id":16604346},{"batb":[[0,3.9,13.14],[1,3.7,13.61],[2,1.01,0.51]],"ltp":0.0,"tv":0.0,"id":13117354}]}]}
{"op":"mcm","clk":"1004424420","pt":1580654964342,"mc":[{"id":"1.168224467","rc":[{"batb":[[0,4.8,27.88],[1,4.7,18.33],[2,4.5,16.6]],"ltp":0.0,"tv":0.0,"id":16604347},{"batb":[[1,3.85,14.42],[2,3.7,13.61]],"ltp":0.0,"tv":0.0,"id":13117354}]}]}
{"op":"mcm","clk":"1004424852","pt":1580654967234,"mc":[{"id":"1.168224467","rc":[{"batb":[[0,1.8,41.46],[1,1.78,47.9],[2,1.72,22.66]],"ltp":0.0,"tv":0.0,"id":16604346}]}]}
{"op":"mcm","clk":"1004424979","pt":1580654968035,"mc":[{"id":"1.168224467","rc":[{"batb":[[0,26,3.75],[1,1.01,0.51]],"ltp":0.0,"tv":0.0,"id":13117353},{"batl":[[0,5.3,15.42]],"ltp":0.0,"tv":0.0,"id":16604347},{"batb":[[0,1.83,18.57],[1,1.8,41.46],[2,1.78,68.44]],"batl":[[1,2.06,15.42]],"ltp":0.0,"tv":0.0,"id":16604346},{"batl":[[0,4.2,13.14],[1,4.3,25.49]],"ltp":0.0,"tv":0.0,"id":13117354}]}]}
{"op":"mcm","clk":"1004425160","pt":1580654969138,"mc":[{"id":"1.168224467","rc":[{"batb":[[2,4.5,28.36]],"batl":[[1,5.4,9.24]],"ltp":0.0,"tv":0.0,"id":16604347}]}]}
{"op":"mcm","clk":"1004425329","pt":1580654970322,"mc":[{"id":"1.168224467","rc":[{"batb":[[1,1.82,50.41],[2,1.8,41.46]],"batl":[[1,2.02,41.17],[2,2.06,15.42]],"ltp":0.0,"tv":0.0,"id":16604346},{"batl":[[0,4.1,13.44],[1,4.2,13.14],[2,4.3,25.49]],"ltp":0.0,"tv":0.0,"id":13117354}]}]}
{"op":"mcm","clk":"1004426906","pt":1580654980326,"mc":[{"id":"1.168224467","rc":[{"batb":[[0,4.8,21.41]],"ltp":0.0,"tv":0.0,"id":16604347},{"batb":[[2,1.78,20.54]],"ltp":0.0,"tv":0.0,"id":16604346},{"batb":[[0,3.7,13.61],[1,3.6,14.71],[2,3.5,16.8]],"ltp":0.0,"tv":0.0,"id":13117354}]}]}
{"op":"mcm","clk":"1004427048","pt":1580654981316,"mc":[{"id":"1.168224467","rc":[{"batb":[[0,1.82,50.41],[1,1.78,20.54],[2,1.01,0.51]],"batl":[[0,2.02,41.17],[1,2.06,15.42],[2,2.06,0]],"ltp":0.0,"tv":0.0,"id":16604346},{"batb":[[0,3.6,14.71],[1,3.5,16.8],[2,1.01,0.51]],"batl":[[1,4.3,25.49],[2,4.3,0]],"ltp":0.0,"tv":0.0,"id":13117354}]}]}
{"op":"mcm","clk":"1004427127","pt":1580654981845,"mc":[{"id":"1.168224467","rc":[{"batb":[[2,4.5,16.6]],"batl":[[1,5.4,0]],"ltp":0.0,"tv":0.0,"id":16604347},{"batb":[[0,1.78,20.54],[1,1.01,0.51],[2,1.01,0]],"batl":[[0,2.06,15.42],[1,2.06,0]],"ltp":0.0,"tv":0.0,"id":16604346},{"batb":[[1,1.01,0.51],[2,1.01,0]],"batl":[[0,4.3,25.49],[1,4.3,0]],"ltp":0.0,"tv":0.0,"id":13117354}]}]}
{"op":"mcm","clk":"1004427341","pt":1580654983328,"mc":[{"id":"1.168224467","rc":[{"batb":[[0,32,7.87],[1,30,2.74],[2,26,3.75]],"ltp":0.0,"tv":0.0,"id":13117353},{"batb":[[1,1.76,39.57],[2,1.74,52.27]],"ltp":0.0,"tv":0.0,"id":16604346},{"batb":[[0,3.8,21.41],[1,3.75,15.31],[2,3.6,14.71]],"ltp":0.0,"tv":0.0,"id":13117354}]}]}
{"op":"mcm","clk":"1004427783","pt":1580654986264,"mc":[{"id":"1.168224467","rc":[{"batb":[[0,26,3.75],[1,1.01,0.51],[2,26,0]],"ltp":0.0,"tv":0.0,"id":13117353},{"batb":[[0,4.8,17.73],[1,4.5,16.6],[2,1.01,0.51]],"ltp":0.0,"tv":0.0,"id":16604347},{"batb":[[0,3.6,14.71],[1,1.01,0.51],[2,3.6,0]],"ltp":0.0,"tv":0.0,"id":13117354}]}]}
{"op":"mcm","clk":"1004428177","pt":1580654988766,"mc":[{"id":"1.168224467","rc":[{"batb":[[0,4.9,13.65],[1,4.8,17.73],[2,4.5,28.36]],"batl":[[1,5.4,9.24]],"ltp":0.0,"tv":0.0,"id":16604347},{"batb":[[0,1.78,74.31]],"batl":[[0,1.96,42.01],[1,2.06,15.42]],"ltp":0.0,"tv":0.0,"id":16604346},{"batb":[[0,3.9,24.49],[1,3.85,14.31],[2,3.6,14.71]],"batl":[[0,4.1,13.44],[1,4.3,25.49]],"ltp":0.0,"tv":0.0,"id":13117354}]}]}
{"op":"mcm","clk":"1004428367","pt":1580654989877,"mc":[{"id":"1.168224467","rc":[{"batb":[[0,1.01,0.51],[1,1.01,0]],"ltp":0.0,"tv":0.0,"id":13117353},{"batb":[[2,4.6,16.13]],"batl":[[2,6,11.96]],"ltp":0.0,"tv":0.0,"id":16604347},{"batl":[[0,1.88,20.14],[1,1.96,42.01],[2,2,16.76]],"ltp":0.0,"tv":0.0,"id":16604346},{"batb":[[2,3.75,13.14]],"batl":[[2,4.9,18.73]],"ltp":0.0,"tv":0.0,"id":13117354}]}]}
{"op":"mcm","clk":"1004429782","pt":1580654998743,"mc":[{"id":"1.168224467","rc":[{"batb":[[1,1.76,28.36]],"ltp":0.0,"tv":0.0,"id":16604346},{"batb":[[0,3.9,14],[1,3.75,13.14],[2,3.55,15.96]],"ltp":0.0,"tv":0.0,"id":13117354}]}]}
{"op":"mcm","clk":"1004430204","pt":1580655001494,"mc":[{"id":"1.168224467","rc":[{"batb":[[0,3.95,18.82],[1,3.9,14],[2,3.75,13.14]],"ltp":0.0,"tv":0.0,"id":13117354}]}]}
{"op":"mcm","clk":"1004432918","pt":1580655020496,"mc":[{"id":"1.168224467","rc":[{"batb":[[0,3.9,14],[1,3.75,13.14],[2,3.55,15.96]],"ltp":0.0,"tv":0.0,"id":13117354}]}]}
{"op":"mcm","clk":"1004433313","pt":1580655023387,"mc":[{"id":"1.168224467","rc":[{"batb":[[1,1.76,40.3]],"ltp":0.0,"tv":0.0,"id":16604346},{"batb":[[0,3.9,23.53],[1,3.85,14.31],[2,3.75,13.14]],"ltp":0.0,"tv":0.0,"id":13117354}]}]}
{"op":"mcm","clk":"1004434612","pt":1580655032740,"mc":[{"id":"1.168224467","rc":[{"batb":[[1,1.62,28.01],[2,1.01,0.51]],"ltp":0.0,"tv":0.0,"id":16604346},{"batb":[[0,3.85,14.31],[1,3.75,13.14],[2,3.55,15.96]],"ltp":0.0,"tv":0.0,"id":13117354}]}]}
{"op":"mcm","clk":"1004435061","pt":1580655035896,"mc":[{"id":"1.168224467","rc":[{"batb":[[0,4.9,18.1]],"ltp":0.0,"tv":0.0,"id":16604347},{"batb":[[1,1.77,35.99],[2,1.75,50.55]],"ltp":0.0,"tv":0.0,"id":16604346},{"batb":[[1,3.8,14.63],[2,3.75,13.14]],"ltp":0.0,"tv":0.0,"id":13117354}]}]}
{"op":"mcm","clk":"1004443060","pt":1580655087163,"mc":[{"id":"1.168224467","rc":[{"batb":[[1,1.62,28.01],[2,1.01,0.51]],"ltp":0.0,"tv":0.0,"id":16604346},{"batb":[[0,3.75,13.14],[1,3.55,15.96],[2,3.5,15.42]],"ltp":0.0,"tv":0.0,"id":13117354}]}]}
{"op":"mcm","clk":"1004443228","pt":1580655088385,"mc":[{"id":"1.168224467","rc":[{"batb":[[0,18,15.96],[1,1.01,0.51]],"ltp":0.0,"tv":0.0,"id":13117353}]}]}
{"op":"mcm","clk":"1004443568","pt":1580655090448,"mc":[{"id":"1.168224467","rc":[{"batb":[[0,4.9,24.34]],"ltp":0.0,"tv":0.0,"id":16604347},{"batb":[[0,1.78,115.31],[1,1.76,49.49],[2,1.62,28.01]],"ltp":0.0,"tv":0.0,"id":16604346},{"batb":[[0,3.75,40.88],[1,3.7,15.31],[2,3.55,15.96]],"ltp":0.0,"tv":0.0,"id":13117354}]}]}
{"op":"mcm","clk":"1004445123","pt":1580655101187,"mc":[{"id":"1.168224467","rc":[{"batb":[[0,3.75,36.14]],"ltp":0.0,"tv":0.0,"id":13117354}]}]}
{"op":"mcm","clk":"1004446626","pt":1580655111436,"mc":[{"id":"1.168224467","rc":[{"batb":[[0,4.6,16.13],[1,4.5,11.76],[2,4.3,18.96]],"ltp":0.0,"tv":0.0,"id":16604347},{"batb":[[0,1.78,74.31],[1,1.62,28.01],[2,1.01,0.51]],"ltp":0.0,"tv":0.0,"id":16604346},{"batb":[[0,3.75,13.14],[1,3.55,15.96],[2,3.5,15.42]],"ltp":0.0,"tv":0.0,"id":13117354}]}]}
{"op":"mcm","clk":"1004446704","pt":1580655111916,"mc":[{"id":"1.168224467","rc":[{"batb":[[0,4.3,18.96],[1,1.01,0.51],[2,4.3,0]],"batl":[[0,6,11.96],[1,5.4,0],[2,6,0]],"ltp":0.0,"tv":0.0,"id":16604347},{"batb":[[0,1.62,28.01],[1,1.01,0.51],[2,1.01,0]],"batl":[[0,2,16.76],[1,1.96,0],[2,2,0]],"ltp":0.0,"tv":0.0,"id":16604346},{"batb":[[0,3.5,15.42],[1,1.01,0.51],[2,3.5,0]],"batl":[[0,4.9,18.73],[1,4.3,0],[2,4.9,0]],"ltp":0.0,"tv":0.0,"id":13117354}]}]}
{"op":"mcm","clk":"1004447116","pt":1580655114323,"mc":[{"id":"1.168224467","rc":[{"batb":[[0,4.6,27.5],[1,4.5,20.45],[2,4.3,18.96]],"ltp":0.0,"tv":0.0,"id":16604347},{"batb":[[0,1.63,35.92],[1,1.62,61.13],[2,1.01,0.51]],"ltp":0.0,"tv":0.0,"id":16604346},{"batb":[[0,3.5,42.41],[1,3.45,18.13],[2,1.01,0.51]],"ltp":0.0,"tv":0.0,"id":13117354}]}]}
{"op":"mcm","clk":"1004447222","pt":1580655115150,"mc":[{"id":"1.168224467","rc":[{"batb":[[2,4.3,18.73]],"batl":[[0,6,11.8]],"ltp":0.0,"tv":0.0,"id":16604347},{"batb":[[0,1.63,63.54],[1,1.62,33.12]],"batl":[[0,2.02,16.52]],"ltp":0.0,"tv":0.0,"id":16604346},{"batl":[[0,4.8,19.28]],"ltp":0.0,"tv":0.0,"id":13117354}]}]}
{"op":"mcm","clk":"1004447345","pt":1580655115809,"mc":[{"id":"1.168224467","rc":[{"batb":[[0,1.63,27.62],[1,1.01,0.51],[2,1.01,0]],"ltp":0.0,"tv":0.0,"id":16604346}]}]}
{"op":"mcm","clk":"1004447851","pt":1580655118884,"mc":[{"id":"1.168224467","rc":[{"batb":[[0,1.89,30.28],[1,1.87,40.63],[2,1.63,27.62]],"ltp":0.0,"tv":0.0,"id":16604346}]}]}
{"op":"mcm","clk":"1004447982","pt":1580655119830,"mc":[{"id":"1.168224467","rc":[{"batl":[[0,5,17.86],[1,5.4,14.79]],"ltp":0.0,"tv":0.0,"id":16604347},{"batb":[[0,1.89,47.04],[2,1.74,21.79]],"batl":[[1,2.12,28.09]],"ltp":0.0,"tv":0.0,"id":16604346},{"batb":[[2,3.3,17.86]],"batl":[[0,3.9,15.34],[1,4.4,23.6]],"ltp":0.0,"tv":0.0,"id":13117354}]}]}
{"op":"mcm","clk":"1004448131","pt":1580655120805,"mc":[{"id":"1.168224467","rc":[{"batl":[[1,5.1,10.08],[2,5.4,14.79]],"ltp":0.0,"tv":0.0,"id":16604347},{"batb":[[1,1.87,88.52]],"batl":[[1,2.06,39.49],[2,2.12,28.09]],"ltp":0.0,"tv":0.0,"id":16604346},{"batb":[[2,3.35,17.64]],"batl":[[1,3.95,13.44],[2,4.4,23.6]],"ltp":0.0,"tv":0.0,"id":13117354}]}]}
{"op":"mcm","clk":"1004450037","pt":1580655132721,"mc":[{"id":"1.168224467","rc":[{"batb":[[0,4.2,12.6],[1,4.1,21.17],[2,1.01,0.51]],"batl":[[0,5.1,10.08],[1,5.4,14.79],[2,5.4,0]],"ltp":0.0,"tv":0.0,"id":16604347},{"batb":[[0,1.87,47.89],[1,1.74,21.79],[2,1.01,0.51]],"batl":[[0,2.06,39.49],[1,2.12,28.09],[2,2.12,0]],"ltp":0.0,"tv":0.0,"id":16604346},{"batb":[[0,3.35,17.64],[1,3.3,17.86],[2,1.01,0.51]],"batl":[[0,3.95,13.44],[1,4.4,23.6],[2,4.4,0]],"ltp":0.0,"tv":0.0,"id":13117354}]}]}
{"op":"mcm","clk":"1004450195","pt":1580655133841,"mc":[{"id":"1.168224467","rc":[{"batb":[[0,4.1,21.17],[1,1.01,0.51],[2,1.01,0]],"batl":[[0,5.4,14.79],[1,5.4,0]],"ltp":0.0,"tv":0.0,"id":16604347},{"batb":[[0,1.74,21.79],[1,1.01,0.51],[2,1.01,0]],"batl":[[0,2.12,28.09],[1,2.12,0]],"ltp":0.0,"tv":0.0,"id":16604346},{"batb":[[0,3.3,17.86],[1,1.01,0.51],[2,1.01,0]],"batl":[[0,4.4,23.6],[1,4.4,0]],"ltp":0.0,"tv":0.0,"id":13117354}]}]}
{"op":"mcm","clk":"1004450434","pt":1580655135430,"mc":[{"id":"1.168224467","rc":[{"batb":[[0,4.4,28.39],[1,4.3,22.69],[2,4.1,21.17]],"ltp":0.0,"tv":0.0,"id":16604347},{"batb":[[0,1.74,73.9],[1,1.72,53.49],[2,1.01,0.51]],"ltp":0.0,"tv":0.0,"id":16604346},{"batb":[[0,3.35,18.37],[1,3.3,38.19],[2,1.01,0.51]],"ltp":0.0,"tv":0.0,"id":13117354}]}]}
{"op":"mcm","clk":"1004451005","pt":1580655139352,"mc":[{"id":"1.168224467","rc":[{"batb":[[0,4.1,21.17],[1,1.01,0.51],[2,4.1,0]],"ltp":0.0,"tv":0.0,"id":16604347},{"batb":[[0,1.74,21.79],[1,1.01,0.51],[2,1.01,0]],"ltp":0.0,"tv":0.0,"id":16604346},{"batb":[[0,3.3,17.86],[1,1.01,0.51],[2,1.01,0]],"ltp":0.0,"tv":0.0,"id":13117354}]}]}
{"op":"mcm","clk":"1004451302","pt":1580655141447,"mc":[{"id":"1.168224467","rc":[{"batb":[[0,4.7,22.39],[1,4.6,19.53],[2,4.1,21.17]],"ltp":0.0,"tv":0.0,"id":16604347},{"batb":[[0,1.86,30.21],[1,1.84,42.77],[2,1.74,21.79]],"ltp":0.0,"tv":0.0,"id":16604346},{"batb":[[0,3.6,15.04],[1,3.55,17.02],[2,3.3,17.86]],"ltp":0.0,"tv":0.0,"id":13117354}]}]}
{"op":"mcm","clk":"1004451653","pt":1580655143436,"mc":[{"id":"1.168224467","rc":[{"batb":[[0,4.1,21.17],[1,1.01,0.51],[2,4.1,0]],"ltp":0.0,"tv":0.0,"id":16604347},{"batb":[[0,1.74,21.79],[1,1.01,0.51],[2,1.74,0]],"ltp":0.0,"tv":0.0,"id":16604346},{"batb":[[0,3.3,17.86],[1,1.01,0.51],[2,3.3,0]],"ltp":0.0,"tv":0.0,"id":13117354}]}]}
{"op":"mcm","clk":"1004452092","pt":1580655146320,"mc":[{"id":"1.168224467","rc":[{"batb":[[0,4.4,28.39],[1,4.3,22.69],[2,4.1,21.17]],"ltp":0.0,"tv":0.0,"id":16604347},{"batb":[[0,1.74,73.9],[1,1.72,53.49],[2,1.01,0.51]],"ltp":0.0,"tv":0.0,"id":16604346},{"batb":[[0,3.35,18.37],[1,3.3,38.19],[2,1.01,0.51]],"ltp":0.0,"tv":0.0,"id":13117354}]}]}
{"op":"mcm","clk":"1004452221","pt":1580655147240,"mc":[{"id":"1.168224467","rc":[{"batb":[[0,1.75,29.37],[1,1.74,21.79],[2,1.73,52.33]],"ltp":0.0,"tv":0.0,"id":16604346}]}]}
{"op":"mcm","clk":"1004453089","pt":1580655153291,"mc":[{"id":"1.168224467","rc":[{"batb":[[0,1.74,21.79],[1,1.01,0.51],[2,1.73,0]],"ltp":0.0,"tv":0.0,"id":16604346}]}]}
{"op":"mcm","clk":"1004453522","pt":1580655156255,"mc":[{"id":"1.168224467","rc":[{"batl":[[0,5,17.55],[1,5.4,14.79]],"ltp":0.0,"tv":0.0,"id":16604347},{"batb":[[0,1.98,62.22],[1,1.96,35.12],[2,1.86,17.62]],"batl":[[1,2.2,25.49]],"ltp":0.0,"tv":0.0,"id":16604346},{"batb":[[2,3.15,19.91]],"batl":[[0,3.7,17.31],[1,4,14.48],[2,4.4,23.6]],"ltp":0.0,"tv":0.0,"id":13117354}]}]}
{"op":"mcm","clk":"1004453660","pt":1580655157059,"mc":[{"id":"1.168224467","rc":[{"batb":[[2,4.1,34.61]],"batl":[[0,4.9,10.08],[1,5,17.55]],"ltp":0.0,"tv":0.0,"id":16604347},{"batb":[[2,1.94,44.53]],"batl":[[1,2.16,36.13],[2,2.2,25.49]],"ltp":0.0,"tv":0.0,"id":16604346},{"batb":[[2,3.2,18.48]],"batl":[[1,3.75,15.12],[2,4,14.48]],"ltp":0.0,"tv":0.0,"id":13117354}]}]}
{"op":"mcm","clk":"1004455352","pt":1580655169289,"mc":[{"id":"1.168224467","rc":[{"batb":[[0,4.3,22.69],[1,4.1,13.44],[2,4,21.95]],"ltp":0.0,"tv":0.0,"id":16604347},{"batb":[[0,1.94,44.53],[1,1.86,17.62],[2,1.01,0.51]],"batl":[[0,2.16,36.13],[1,2.2,25.49],[2,2.2,0]],"ltp":0.0,"tv":0.0,"id":16604346},{"batb":[[0,3.2,18.48],[1,3.15,19.91],[2,1.01,0.51]],"batl":[[0,3.75,15.12],[1,4,14.48],[2,4,0]],"ltp":0.0,"tv":0.0,"id":13117354}]}]}
{"op":"mcm","clk":"1004455466","pt":1580655170063,"mc":[{"id":"1.168224467","rc":[{"batb":[[1,4,21.95],[2,1.01,0.51]],"batl":[[0,5,17.55],[1,5,0]],"ltp":0.0,"tv":0.0,"id":16604347},{"batb":[[0,1.86,17.62],[1,1.01,0.51],[2,1.01,0]],"batl":[[0,2.2,25.49],[1,2.2,0]],"ltp":0.0,"tv":0.0,"id":16604346},{"batb":[[0,3.15,19.91],[1,1.01,0.51],[2,1.01,0]],"batl":[[0,4,14.48],[1,4,0]],"ltp":0.0,"tv":0.0,"id":13117354}]}]}
{"op":"mcm","clk":"1004455689","pt":1580655171962,"mc":[{"id":"1.168224467","rc":[{"batb":[[1,4.2,24],[2,4,21.95]],"ltp":0.0,"tv":0.0,"id":16604347},{"batb":[[0,1.87,34.9],[1,1.86,17.62],[2,1.85,42.05]],"ltp":0.0,"tv":0.0,"id":16604346},{"batb":[[0,3.2,30.9],[1,3.15,42.59],[2,1.01,0.51]],"ltp":0.0,"tv":0.0,"id":13117354}]}]}
