{"op":"mcm","clk":"998154875","pt":1580585274635,"mc":[{"id":"1.168224477","marketDefinition":{"bspMarket":false,"turnInPlayEnabled":true,"persistenceEnabled":true,"marketBaseRate":5.0,"eventId":"29681747","eventTypeId":"2","numberOfWinners":1,"bettingType":"ODDS","marketType":"SET_WINNER","marketTime":"2020-02-02T09:00:00.000Z","suspendTime":"2020-02-02T09:00:00.000Z","bspReconciled":false,"complete":true,"inPlay":false,"crossMatching":false,"runnersVoidable":false,"numberOfActiveRunners":2,"betDelay":0,"status":"OPEN","runners":[{"status":"ACTIVE","sortPriority":1,"id":5858055,"name":"Hiroki Moriya"},{"status":"ACTIVE","sortPriority":2,"id":7444998,"name":"Danilo Petrovic"}],"regulators":["MR_INT"],"countryCode":"FR","discountAllowed":false,"timezone":"UTC","openDate":"2020-02-02T09:00:00.000Z","version":3147098670,"name":"Set 2 Winner","eventName":"Moriya v Petrovic"},"rc":[{"batb":[[0,1.01,20]],"ltp":0.0,"tv":0.0,"id":5858055},{"batb":[[0,1.01,20]],"ltp":0.0,"tv":0.0,"id":7444998}]}]}
{"op":"mcm","clk":"998155189","pt":1580585276473,"mc":[{"id":"1.168224477","marketDefinition":{"bspMarket":false,"turnInPlayEnabled":true,"persistenceEnabled":true,"marketBaseRate":5.0,"eventId":"29681747","eventTypeId":"2","numberOfWinners":1,"bettingType":"ODDS","marketType":"SET_WINNER","marketTime":"2020-02-02T09:00:00.000Z","suspendTime":"2020-02-02T09:00:00.000Z","bspReconciled":false,"complete":true,"inPlay":false,"crossMatching":false,"runnersVoidable":false,"numberOfActiveRunners":2,"betDelay":0,"status":"OPEN","runners":[{"status":"ACTIVE","sortPriority":1,"id":5858055,"name":"Hiroki Moriya"},{"status":"ACTIVE","sortPriority":2,"id":7444998,"name":"Danilo Petrovic"}],"regulators":["MR_INT"],"countryCode":"FR","discountAllowed":true,"timezone":"UTC","openDate":"2020-02-02T09:00:00.000Z","version":3147098670,"name":"Set 2 Winner","eventName":"Moriya v Petrovic"}}]}
{"op":"mcm","clk":"998178965","pt":1580585419340,"mc":[{"id":"1.168224477","rc":[{"batb":[[0,1.01,15]],"ltp":0.0,"tv":0.0,"id":5858055},{"batb":[[0,1.01,15]],"ltp":0.0,"tv":0.0,"id":7444998}]}]}
{"op":"mcm","clk":"998196782","pt":1580585516475,"mc":[{"id":"1.168224477","marketDefinition":{"bspMarket":false,"turnInPlayEnabled":true,"persistenceEnabled":true,"marketBaseRate":5.0,"eventId":"29681747","eventTypeId":"2","numberOfWinners":1,"bettingType":"ODDS","marketType":"SET_WINNER","marketTime":"2020-02-02T15:30:00.000Z","suspendTime":"2020-02-02T15:30:00.000Z","bspReconciled":false,"complete":true,"inPlay":false,"crossMatching":false,"runnersVoidable":false,"numberOfActiveRunners":2,"betDelay":0,"status":"OPEN","runners":[{"status":"ACTIVE","sortPriority":1,"id":5858055,"name":"Hiroki Moriya"},{"status":"ACTIVE","sortPriority":2,"id":7444998,"name":"Danilo Petrovic"}],"regulators":["MR_INT"],"countryCode":"FR","discountAllowed":true,"timezone":"UTC","openDate":"2020-02-02T09:00:00.000Z","version":3147125087,"name":"Set 2 Winner","eventName":"Moriya v Petrovic"}}]}
{"op":"mcm","clk":"998197430","pt":1580585519449,"mc":[{"id":"1.168224477","marketDefinition":{"bspMarket":false,"turnInPlayEnabled":true,"persistenceEnabled":true,"marketBaseRate":5.0,"eventId":"29681747","eventTypeId":"2","numberOfWinners":1,"bettingType":"ODDS","marketType":"SET_WINNER","marketTime":"2020-02-02T15:30:00.000Z","suspendTime":"2020-02-02T15:30:00.000Z","bspReconciled":false,"complete":true,"inPlay":false,"crossMatching":false,"runnersVoidable":false,"numberOfActiveRunners":2,"betDelay":0,"status":"OPEN","runners":[{"status":"ACTIVE","sortPriority":1,"id":5858055,"name":"Hiroki Moriya"},{"status":"ACTIVE","sortPriority":2,"id":7444998,"name":"Danilo Petrovic"}],"regulators":["MR_INT"],"countryCode":"FR","discountAllowed":true,"timezone":"UTC","openDate":"2020-02-02T15:30:00.000Z","version":3147125087,"name":"Set 2 Winner","eventName":"Moriya v Petrovic"}}]}
{"op":"mcm","clk":"999887684","pt":1580602193223,"mc":[{"id":"1.168224477","rc":[{"batb":[[0,1.01,15.51]],"ltp":0.0,"tv":0.0,"id":5858055},{"batb":[[0,1.01,15.51]],"ltp":0.0,"tv":0.0,"id":7444998}]}]}
{"op":"mcm","clk":"999983612","pt":1580603732198,"mc":[{"id":"1.168224477","rc":[{"batb":[[0,1.01,18.04]],"ltp":0.0,"tv":0.0,"id":5858055},{"batb":[[0,1.01,18.04]],"ltp":0.0,"tv":0.0,"id":7444998}]}]}
{"op":"mcm","clk":"999983644","pt":1580603733234,"mc":[{"id":"1.168224477","rc":[{"batb":[[0,1.01,16.01]],"ltp":0.0,"tv":0.0,"id":5858055},{"batb":[[0,1.01,16.01]],"ltp":0.0,"tv":0.0,"id":7444998}]}]}
{"op":"mcm","clk":"1001426382","pt":1580635616377,"mc":[{"id":"1.168224477","marketDefinition":{"bspMarket":false,"turnInPlayEnabled":true,"persistenceEnabled":true,"marketBaseRate":5.0,"eventId":"29681747","eventTypeId":"2","numberOfWinners":1,"bettingType":"ODDS","marketType":"SET_WINNER","marketTime":"2020-02-02T15:24:00.000Z","suspendTime":"2020-02-02T15:24:00.000Z","bspReconciled":false,"complete":true,"inPlay":false,"crossMatching":false,"runnersVoidable":false,"numberOfActiveRunners":2,"betDelay":0,"status":"OPEN","runners":[{"status":"ACTIVE","sortPriority":1,"id":5858055,"name":"Hiroki Moriya"},{"status":"ACTIVE","sortPriority":2,"id":7444998,"name":"Danilo Petrovic"}],"regulators":["MR_INT"],"countryCode":"FR","discountAllowed":true,"timezone":"UTC","openDate":"2020-02-02T15:30:00.000Z","version":3148345729,"name":"Set 2 Winner","eventName":"Moriya v Petrovic"}}]}
{"op":"mcm","clk":"1001426714","pt":1580635619343,"mc":[{"id":"1.168224477","marketDefinition":{"bspMarket":false,"turnInPlayEnabled":true,"persistenceEnabled":true,"marketBaseRate":5.0,"eventId":"29681747","eventTypeId":"2","numberOfWinners":1,"bettingType":"ODDS","marketType":"SET_WINNER","marketTime":"2020-02-02T15:24:00.000Z","suspendTime":"2020-02-02T15:24:00.000Z","bspReconciled":false,"complete":true,"inPlay":false,"crossMatching":false,"runnersVoidable":false,"numberOfActiveRunners":2,"betDelay":0,"status":"OPEN","runners":[{"status":"ACTIVE","sortPriority":1,"id":5858055,"name":"Hiroki Moriya"},{"status":"ACTIVE","sortPriority":2,"id":7444998,"name":"Danilo Petrovic"}],"regulators":["MR_INT"],"countryCode":"FR","discountAllowed":true,"timezone":"UTC","openDate":"2020-02-02T15:24:00.000Z","version":3148345729,"name":"Set 2 Winner","eventName":"Moriya v Petrovic"}}]}
{"op":"mcm","clk":"1001816331","pt":1580640414463,"mc":[{"id":"1.168224477","marketDefinition":{"bspMarket":false,"turnInPlayEnabled":true,"persistenceEnabled":true,"marketBaseRate":5.0,"eventId":"29681747","eventTypeId":"2","numberOfWinners":1,"bettingType":"ODDS","marketType":"SET_WINNER","marketTime":"2020-02-02T14:51:00.000Z","suspendTime":"2020-02-02T14:51:00.000Z","bspReconciled":false,"complete":true,"inPlay":false,"crossMatching":false,"runnersVoidable":false,"numberOfActiveRunners":2,"betDelay":0,"status":"OPEN","runners":[{"status":"ACTIVE","sortPriority":1,"id":5858055,"name":"Hiroki Moriya"},{"status":"ACTIVE","sortPriority":2,"id":7444998,"name":"Danilo Petrovic"}],"regulators":["MR_INT"],"countryCode":"FR","discountAllowed":true,"timezone":"UTC","openDate":"2020-02-02T15:24:00.000Z","version":3148438375,"name":"Set 2 Winner","eventName":"Moriya v Petrovic"}}]}
{"op":"mcm","clk":"1001817051","pt":1580640420518,"mc":[{"id":"1.168224477","marketDefinition":{"bspMarket":false,"turnInPlayEnabled":true,"persistenceEnabled":true,"marketBaseRate":5.0,"eventId":"29681747","eventTypeId":"2","numberOfWinners":1,"bettingType":"ODDS","marketType":"SET_WINNER","marketTime":"2020-02-02T14:51:00.000Z","suspendTime":"2020-02-02T14:51:00.000Z","bspReconciled":false,"complete":true,"inPlay":false,"crossMatching":false,"runnersVoidable":false,"numberOfActiveRunners":2,"betDelay":0,"status":"OPEN","runners":[{"status":"ACTIVE","sortPriority":1,"id":5858055,"name":"Hiroki Moriya"},{"status":"ACTIVE","sortPriority":2,"id":7444998,"name":"Danilo Petrovic"}],"regulators":["MR_INT"],"countryCode":"FR","discountAllowed":true,"timezone":"UTC","openDate":"2020-02-02T14:51:00.000Z","version":3148438375,"name":"Set 2 Winner","eventName":"Moriya v Petrovic"}}]}
{"op":"mcm","clk":"1001853042","pt":1580640715174,"mc":[{"id":"1.168224477","marketDefinition":{"bspMarket":false,"turnInPlayEnabled":true,"persistenceEnabled":true,"marketBaseRate":5.0,"eventId":"29681747","eventTypeId":"2","numberOfWinners":1,"bettingType":"ODDS","marketType":"SET_WINNER","marketTime":"2020-02-02T14:48:00.000Z","suspendTime":"2020-02-02T14:48:00.000Z","bspReconciled":false,"complete":true,"inPlay":false,"crossMatching":false,"runnersVoidable":false,"numberOfActiveRunners":2,"betDelay":0,"status":"OPEN","runners":[{"status":"ACTIVE","sortPriority":1,"id":5858055,"name":"Hiroki Moriya"},{"status":"ACTIVE","sortPriority":2,"id":7444998,"name":"Danilo Petrovic"}],"regulators":["MR_INT"],"countryCode":"FR","discountAllowed":true,"timezone":"UTC","openDate":"2020-02-02T14:51:00.000Z","version":3148443827,"name":"Set 2 Winner","eventName":"Moriya v Petrovic"}}]}
{"op":"mcm","clk":"1001853415","pt":1580640718147,"mc":[{"id":"1.168224477","marketDefinition":{"bspMarket":false,"turnInPlayEnabled":true,"persistenceEnabled":true,"marketBaseRate":5.0,"eventId":"29681747","eventTypeId":"2","numberOfWinners":1,"bettingType":"ODDS","marketType":"SET_WINNER","marketTime":"2020-02-02T14:48:00.000Z","suspendTime":"2020-02-02T14:48:00.000Z","bspReconciled":false,"complete":true,"inPlay":false,"crossMatching":false,"runnersVoidable":false,"numberOfActiveRunners":2,"betDelay":0,"status":"OPEN","runners":[{"status":"ACTIVE","sortPriority":1,"id":5858055,"name":"Hiroki Moriya"},{"status":"ACTIVE","sortPriority":2,"id":7444998,"name":"Danilo Petrovic"}],"regulators":["MR_INT"],"countryCode":"FR","discountAllowed":true,"timezone":"UTC","openDate":"2020-02-02T14:48:00.000Z","version":3148443827,"name":"Set 2 Winner","eventName":"Moriya v Petrovic"}}]}
{"op":"mcm","clk":"1002676122","pt":1580645813890,"mc":[{"id":"1.168224477","marketDefinition":{"bspMarket":false,"turnInPlayEnabled":true,"persistenceEnabled":true,"marketBaseRate":5.0,"eventId":"29681747","eventTypeId":"2","numberOfWinners":1,"bettingType":"ODDS","marketType":"SET_WINNER","marketTime":"2020-02-02T14:16:00.000Z","suspendTime":"2020-02-02T14:16:00.000Z","bspReconciled":false,"complete":true,"inPlay":false,"crossMatching":false,"runnersVoidable":false,"numberOfActiveRunners":2,"betDelay":0,"status":"OPEN","runners":[{"status":"ACTIVE","sortPriority":1,"id":5858055,"name":"Hiroki Moriya"},{"status":"ACTIVE","sortPriority":2,"id":7444998,"name":"Danilo Petrovic"}],"regulators":["MR_INT"],"countryCode":"FR","discountAllowed":true,"timezone":"UTC","openDate":"2020-02-02T14:48:00.000Z","version":3148684767,"name":"Set 2 Winner","eventName":"Moriya v Petrovic"}}]}
{"op":"mcm","clk":"1002676782","pt":1580645817903,"mc":[{"id":"1.168224477","marketDefinition":{"bspMarket":false,"turnInPlayEnabled":true,"persistenceEnabled":true,"marketBaseRate":5.0,"eventId":"29681747","eventTypeId":"2","numberOfWinners":1,"bettingType":"ODDS","marketType":"SET_WINNER","marketTime":"2020-02-02T14:16:00.000Z","suspendTime":"2020-02-02T14:16:00.000Z","bspReconciled":false,"complete":true,"inPlay":false,"crossMatching":false,"runnersVoidable":false,"numberOfActiveRunners":2,"betDelay":0,"status":"OPEN","runners":[{"status":"ACTIVE","sortPriority":1,"id":5858055,"name":"Hiroki Moriya"},{"status":"ACTIVE","sortPriority":2,"id":7444998,"name":"Danilo Petrovic"}],"regulators":["MR_INT"],"countryCode":"FR","discountAllowed":true,"timezone":"UTC","openDate":"2020-02-02T14:16:00.000Z","version":3148684767,"name":"Set 2 Winner","eventName":"Moriya v Petrovic"}}]}
{"op":"mcm","clk":"1003808359","pt":1580652114770,"mc":[{"id":"1.168224477","marketDefinition":{"bspMarket":false,"turnInPlayEnabled":true,"persistenceEnabled":true,"marketBaseRate":5.0,"eventId":"29681747","eventTypeId":"2","numberOfWinners":1,"bettingType":"ODDS","marketType":"SET_WINNER","marketTime":"2020-02-02T14:06:00.000Z","suspendTime":"2020-02-02T14:06:00.000Z","bspReconciled":false,"complete":true,"inPlay":false,"crossMatching":false,"runnersVoidable":false,"numberOfActiveRunners":2,"betDelay":0,"status":"OPEN","runners":[{"status":"ACTIVE","sortPriority":1,"id":5858055,"name":"Hiroki Moriya"},{"status":"ACTIVE","sortPriority":2,"id":7444998,"name":"Danilo Petrovic"}],"regulators":["MR_INT"],"countryCode":"FR","discountAllowed":true,"timezone":"UTC","openDate":"2020-02-02T14:16:00.000Z","version":3149081988,"name":"Set 2 Winner","eventName":"Moriya v Petrovic"}}]}
{"op":"mcm","clk":"1003809195","pt":1580652118802,"mc":[{"id":"1.168224477","marketDefinition":{"bspMarket":false,"turnInPlayEnabled":true,"persistenceEnabled":true,"marketBaseRate":5.0,"eventId":"29681747","eventTypeId":"2","numberOfWinners":1,"bettingType":"ODDS","marketType":"SET_WINNER","marketTime":"2020-02-02T14:06:00.000Z","suspendTime":"2020-02-02T14:06:00.000Z","bspReconciled":false,"complete":true,"inPlay":false,"crossMatching":false,"runnersVoidable":false,"numberOfActiveRunners":2,"betDelay":0,"status":"OPEN","runners":[{"status":"ACTIVE","sortPriority":1,"id":5858055,"name":"Hiroki Moriya"},{"status":"ACTIVE","sortPriority":2,"id":7444998,"name":"Danilo Petrovic"}],"regulators":["MR_INT"],"countryCode":"FR","discountAllowed":true,"timezone":"UTC","openDate":"2020-02-02T14:06:00.000Z","version":3149081988,"name":"Set 2 Winner","eventName":"Moriya v Petrovic"}}]}
{"op":"mcm","clk":"1003845478","pt":1580652277851,"mc":[{"id":"1.168224477","rc":[{"batb":[[0,1.93,15.66],[1,1.01,16.01]],"ltp":0.0,"tv":0.0,"id":5858055},{"batb":[[0,1.93,15.66],[1,1.01,16.01]],"ltp":0.0,"tv":0.0,"id":7444998}]}]}
{"op":"mcm","clk":"1003878607","pt":1580652413628,"mc":[{"id":"1.168224477","marketDefinition":{"bspMarket":false,"turnInPlayEnabled":true,"persistenceEnabled":true,"marketBaseRate":5.0,"eventId":"29681747","eventTypeId":"2","numberOfWinners":1,"bettingType":"ODDS","marketType":"SET_WINNER","marketTime":"2020-02-02T14:03:00.000Z","suspendTime":"2020-02-02T14:03:00.000Z","bspReconciled":false,"complete":true,"inPlay":false,"crossMatching":false,"runnersVoidable":false,"numberOfActiveRunners":2,"betDelay":0,"status":"OPEN","runners":[{"status":"ACTIVE","sortPriority":1,"id":5858055,"name":"Hiroki Moriya"},{"status":"ACTIVE","sortPriority":2,"id":7444998,"name":"Danilo Petrovic"}],"regulators":["MR_INT"],"countryCode":"FR","discountAllowed":true,"timezone":"UTC","openDate":"2020-02-02T14:06:00.000Z","version":3149117373,"name":"Set 2 Winner","eventName":"Moriya v Petrovic"}}]}
{"op":"mcm","clk":"1003879387","pt":1580652416642,"mc":[{"id":"1.168224477","marketDefinition":{"bspMarket":false,"turnInPlayEnabled":true,"persistenceEnabled":true,"marketBaseRate":5.0,"eventId":"29681747","eventTypeId":"2","numberOfWinners":1,"bettingType":"ODDS","marketType":"SET_WINNER","marketTime":"2020-02-02T14:03:00.000Z","suspendTime":"2020-02-02T14:03:00.000Z","bspReconciled":false,"complete":true,"inPlay":false,"crossMatching":false,"runnersVoidable":false,"numberOfActiveRunners":2,"betDelay":0,"status":"OPEN","runners":[{"status":"ACTIVE","sortPriority":1,"id":5858055,"name":"Hiroki Moriya"},{"status":"ACTIVE","sortPriority":2,"id":7444998,"name":"Danilo Petrovic"}],"regulators":["MR_INT"],"countryCode":"FR","discountAllowed":true,"timezone":"UTC","openDate":"2020-02-02T14:03:00.000Z","version":3149117373,"name":"Set 2 Winner","eventName":"Moriya v Petrovic"}}]}
{"op":"mcm","clk":"1003930605","pt":1580652610576,"mc":[{"id":"1.168224477","rc":[{"batb":[[0,1.93,60.19]],"batl":[[0,2.14,36.13]],"ltp":0.0,"tv":0.0,"id":5858055},{"batb":[[1,1.89,47.05],[2,1.01,16.01]],"batl":[[0,2.1,37.81]],"ltp":0.0,"tv":0.0,"id":7444998}]}]}
{"op":"mcm","clk":"1003932093","pt":1580652616504,"mc":[{"id":"1.168224477","marketDefinition":{"bspMarket":false,"turnInPlayEnabled":true,"persistenceEnabled":true,"marketBaseRate":5.0,"eventId":"29681747","eventTypeId":"2","numberOfWinners":1,"bettingType":"ODDS","marketType":"SET_WINNER","marketTime":"2020-02-02T14:03:00.000Z","suspendTime":"2020-02-02T14:03:00.000Z","bspReconciled":false,"complete":true,"inPlay":false,"crossMatching":true,"runnersVoidable":false,"numberOfActiveRunners":2,"betDelay":0,"status":"OPEN","runners":[{"status":"ACTIVE","sortPriority":1,"id":5858055,"name":"Hiroki Moriya"},{"status":"ACTIVE","sortPriority":2,"id":7444998,"name":"Danilo Petrovic"}],"regulators":["MR_INT"],"countryCode":"FR","discountAllowed":true,"timezone":"UTC","openDate":"2020-02-02T14:03:00.000Z","version":3149117373,"name":"Set 2 Winner","eventName":"Moriya v Petrovic"}}]}
{"op":"mcm","clk":"1003936137","pt":1580652632284,"mc":[{"id":"1.168224477","rc":[{"batb":[[0,1.94,2],[1,1.93,60.19],[2,1.01,16.01]],"ltp":0.0,"tv":0.0,"id":5858055},{"batb":[[0,1.94,2],[1,1.93,15.66],[2,1.89,47.05]],"ltp":0.0,"tv":0.0,"id":7444998}]}]}
{"op":"mcm","clk":"1003995124","pt":1580652868100,"mc":[{"id":"1.168224477","rc":[{"batb":[[1,1.93,44.53]],"ltp":0.0,"tv":0.0,"id":5858055},{"batb":[[1,1.89,47.05],[2,1.01,16.01]],"ltp":0.0,"tv":0.0,"id":7444998}]}]}
{"op":"mcm","clk":"1003995312","pt":1580652868929,"mc":[{"id":"1.168224477","marketDefinition":{"bspMarket":false,"turnInPlayEnabled":true,"persistenceEnabled":true,"marketBaseRate":5.0,"eventId":"29681747","eventTypeId":"2","numberOfWinners":1,"bettingType":"ODDS","marketType":"SET_WINNER","marketTime":"2020-02-02T14:03:00.000Z","suspendTime":"2020-02-02T14:03:00.000Z","bspReconciled":false,"complete":true,"inPlay":true,"crossMatching":true,"runnersVoidable":false,"numberOfActiveRunners":2,"betDelay":3,"status":"OPEN","runners":[{"status":"ACTIVE","sortPriority":1,"id":5858055,"name":"Hiroki Moriya"},{"status":"ACTIVE","sortPriority":2,"id":7444998,"name":"Danilo Petrovic"}],"regulators":["MR_INT"],"countryCode":"FR","discountAllowed":true,"timezone":"UTC","openDate":"2020-02-02T14:03:00.000Z","version":3149153557,"name":"Set 2 Winner","eventName":"Moriya v Petrovic"},"rc":[{"batb":[[0,1.01,15.51],[1,1.93,0],[2,1.01,0]],"ltp":0.0,"tv":0.0,"id":5858055},{"batb":[[0,1.01,15.51],[1,1.89,0],[2,1.01,0]],"ltp":0.0,"tv":0.0,"id":7444998}]}]}
{"op":"mcm","clk":"1003999414","pt":1580652886808,"mc":[{"id":"1.168224477","rc":[{"batb":[[0,1.91,16.37],[1,1.88,17.07],[2,1.01,15.51]],"ltp":0.0,"tv":0.0,"id":5858055},{"batb":[[0,1.97,29.66],[1,1.92,15.89],[2,1.01,15.51]],"ltp":0.0,"tv":0.0,"id":7444998}]}]}
{"op":"mcm","clk":"1003999649","pt":1580652887845,"mc":[{"id":"1.168224477","rc":[{"batb":[[1,1.89,47.05],[2,1.88,17.07]],"batl":[[0,2.1,37.81]],"ltp":0.0,"tv":0.0,"id":5858055},{"batb":[[2,1.9,46.21]],"batl":[[0,2.12,36.97]],"ltp":0.0,"tv":0.0,"id":7444998}]}]}
{"op":"mcm","clk":"1004002205","pt":1580652899144,"mc":[{"id":"1.168224477","rc":[{"batb":[[0,1.88,17.07],[1,1.01,15.51],[2,1.88,0]],"ltp":0.0,"tv":0.0,"id":5858055},{"batb":[[0,1.92,15.89],[1,1.01,15.51],[2,1.9,0]],"ltp":0.0,"tv":0.0,"id":7444998}]}]}
{"op":"mcm","clk":"1004006474","pt":1580652918339,"mc":[{"id":"1.168224477","rc":[{"batb":[[1,1.87,47.89],[2,1.85,17.86]],"batl":[[0,2.08,38.65]],"ltp":0.0,"tv":0.0,"id":5858055},{"batb":[[0,2,28.4],[1,1.95,30.53],[2,1.92,45.37]],"batl":[[0,2.16,36.13]],"ltp":0.0,"tv":0.0,"id":7444998}]}]}
{"op":"mcm","clk":"1004008663","pt":1580652928350,"mc":[{"id":"1.168224477","rc":[{"batb":[[0,1.87,47.89],[1,1.85,17.86],[2,1.01,15.51]],"ltp":0.0,"tv":0.0,"id":5858055},{"batb":[[0,1.95,30.53],[1,1.92,45.37],[2,1.01,15.51]],"ltp":0.0,"tv":0.0,"id":7444998}]}]}
{"op":"mcm","clk":"1004008778","pt":1580652928853,"mc":[{"id":"1.168224477","rc":[{"batb":[[0,1.85,17.86],[1,1.01,15.51],[2,1.01,0]],"ltp":0.0,"tv":0.0,"id":5858055},{"batb":[[1,1.01,15.51],[2,1.01,0]],"ltp":0.0,"tv":0.0,"id":7444998}]}]}
{"op":"mcm","clk":"1004010942","pt":1580652938298,"mc":[{"id":"1.168224477","rc":[{"batb":[[1,1.84,49.57],[2,1.83,18.57]],"batl":[[0,2.06,39.49]],"ltp":0.0,"tv":0.0,"id":5858055},{"batb":[[0,2.02,27.15],[1,1.98,28.95],[2,1.95,74.22]],"batl":[[0,2.18,35.29]],"ltp":0.0,"tv":0.0,"id":7444998}]}]}
{"op":"mcm","clk":"1004011011","pt":1580652938639,"mc":[{"id":"1.168224477","rc":[{"batb":[[2,1.95,43.69]],"ltp":0.0,"tv":0.0,"id":7444998}]}]}
{"op":"mcm","clk":"1004013959","pt":1580652952893,"mc":[{"id":"1.168224477","rc":[{"batb":[[0,1.84,49.57],[1,1.83,18.57],[2,1.01,15.51]],"ltp":0.0,"tv":0.0,"id":5858055},{"batb":[[0,1.98,28.95],[1,1.95,43.69],[2,1.01,15.51]],"ltp":0.0,"tv":0.0,"id":7444998}]}]}
{"op":"mcm","clk":"1004014456","pt":1580652955300,"mc":[{"id":"1.168224477","rc":[{"batb":[[0,1.83,18.57],[1,1.01,15.51],[2,1.01,0]],"ltp":0.0,"tv":0.0,"id":5858055},{"batb":[[1,1.01,15.51],[2,1.01,0]],"ltp":0.0,"tv":0.0,"id":7444998}]}]}
{"op":"mcm","clk":"1004017005","pt":1580652967282,"mc":[{"id":"1.168224477","rc":[{"batb":[[0,1.89,16.68],[1,1.87,17.23],[2,1.83,18.57]],"ltp":0.0,"tv":0.0,"id":5858055},{"batb":[[1,1.94,15.58],[2,1.01,15.51]],"ltp":0.0,"tv":0.0,"id":7444998}]}]}
{"op":"mcm","clk":"1004017211","pt":1580652968291,"mc":[{"id":"1.168224477","rc":[{"batb":[[2,1.84,244.47]],"batl":[[0,2.1,37.81]],"ltp":0.0,"tv":0.0,"id":5858055},{"batb":[[2,1.92,45.37]],"batl":[[0,2.12,36.97]],"ltp":0.0,"tv":0.0,"id":7444998}]}]}
{"op":"mcm","clk":"1004017369","pt":1580652969195,"mc":[{"id":"1.168224477","rc":[{"batb":[[0,1.89,63.73],[2,1.01,15.51]],"ltp":0.0,"tv":0.0,"id":5858055}]}]}
{"op":"mcm","clk":"1004020624","pt":1580652983734,"mc":[{"id":"1.168224477","rc":[{"batb":[[0,1.89,47.05]],"ltp":0.0,"tv":0.0,"id":5858055},{"batb":[[0,1.94,15.58],[1,1.92,45.37],[2,1.01,15.51]],"ltp":0.0,"tv":0.0,"id":7444998}]}]}
{"op":"mcm","clk":"1004020868","pt":1580652984837,"mc":[{"id":"1.168224477","rc":[{"batb":[[0,1.87,17.23],[1,1.01,15.51],[2,1.01,0]],"ltp":0.0,"tv":0.0,"id":5858055},{"batb":[[1,1.01,15.51],[2,1.01,0]],"ltp":0.0,"tv":0.0,"id":7444998}]}]}
{"op":"mcm","clk":"1004025508","pt":1580653006784,"mc":[{"id":"1.168224477","rc":[{"batb":[[1,1.83,18.65],[2,1.01,15.51]],"ltp":0.0,"tv":0.0,"id":5858055},{"batb":[[0,2,28.09],[1,1.97,29.35],[2,1.01,15.51]],"ltp":0.0,"tv":0.0,"id":7444998}]}]}
{"op":"mcm","clk":"1004025720","pt":1580653007778,"mc":[{"id":"1.168224477","rc":[{"batb":[[1,1.85,48.73],[2,1.83,18.65]],"batl":[[0,2.06,39.49]],"ltp":0.0,"tv":0.0,"id":5858055},{"batb":[[2,1.96,43.69]],"batl":[[0,2.18,35.29]],"ltp":0.0,"tv":0.0,"id":7444998}]}]}
{"op":"mcm","clk":"1004033067","pt":1580653044170,"mc":[{"id":"1.168224477","rc":[{"batb":[[0,1.85,48.73],[1,1.83,18.65],[2,1.01,15.51]],"ltp":0.0,"tv":0.0,"id":5858055},{"batb":[[0,1.97,29.35],[1,1.96,43.69],[2,1.01,15.51]],"ltp":0.0,"tv":0.0,"id":7444998}]}]}
{"op":"mcm","clk":"1004033195","pt":1580653044936,"mc":[{"id":"1.168224477","rc":[{"batb":[[0,1.83,18.65],[1,1.01,15.51],[2,1.01,0]],"ltp":0.0,"tv":0.0,"id":5858055},{"batb":[[1,1.01,15.51],[2,1.01,0]],"ltp":0.0,"tv":0.0,"id":7444998}]}]}
{"op":"mcm","clk":"1004034904","pt":1580653053905,"mc":[{"id":"1.168224477","rc":[{"batb":[[0,1.9,16.52],[1,1.88,47.05],[2,1.85,17.86]],"batl":[[0,2.08,38.65]],"ltp":0.0,"tv":0.0,"id":5858055},{"batb":[[1,1.94,60.03],[2,1.01,15.51]],"batl":[[0,2.14,36.13]],"ltp":0.0,"tv":0.0,"id":7444998}]}]}
{"op":"mcm","clk":"1004036734","pt":1580653062941,"mc":[{"id":"1.168224477","rc":[{"batb":[[0,1.85,17.86],[1,1.01,15.51],[2,1.85,0]],"ltp":0.0,"tv":0.0,"id":5858055},{"batb":[[0,1.94,15.5],[1,1.01,15.51],[2,1.01,0]],"ltp":0.0,"tv":0.0,"id":7444998}]}]}
{"op":"mcm","clk":"1004040101","pt":1580653080758,"mc":[{"id":"1.168224477","rc":[{"batb":[[1,1.81,19.2],[2,1.01,15.51]],"ltp":0.0,"tv":0.0,"id":5858055},{"batb":[[0,2.02,27.15],[1,1.99,28.88],[2,1.01,15.51]],"ltp":0.0,"tv":0.0,"id":7444998}]}]}
{"op":"mcm","clk":"1004040304","pt":1580653081741,"mc":[{"id":"1.168224477","rc":[{"batb":[[1,1.83,50.41],[2,1.81,19.2]],"batl":[[0,2.04,40.33]],"ltp":0.0,"tv":0.0,"id":5858055},{"batb":[[2,1.98,42.85]],"batl":[[0,2.2,34.45]],"ltp":0.0,"tv":0.0,"id":7444998}]}]}
{"op":"mcm","clk":"1004040804","pt":1580653084255,"mc":[{"id":"1.168224477","rc":[{"batl":[[1,2.52,270.1]],"ltp":0.0,"tv":0.0,"id":5858055},{"batl":[[1,2.7,245.56]],"ltp":0.0,"tv":0.0,"id":7444998}]}]}
{"op":"mcm","clk":"1004042518","pt":1580653092874,"mc":[{"id":"1.168224477","rc":[{"batb":[[0,1.81,19.2],[1,1.01,15.51],[2,1.81,0]],"batl":[[0,2.52,270.1],[1,2.52,0]],"ltp":0.0,"tv":0.0,"id":5858055},{"batb":[[0,1.99,28.88],[1,1.01,15.51],[2,1.98,0]],"batl":[[0,2.7,245.56],[1,2.7,0]],"ltp":0.0,"tv":0.0,"id":7444998}]}]}
{"op":"mcm","clk":"1004044861","pt":1580653105190,"mc":[{"id":"1.168224477","rc":[{"batb":[[0,1.89,16.76],[1,1.84,18.25],[2,1.01,15.51]],"ltp":0.0,"tv":0.0,"id":5858055},{"batb":[[1,1.95,30.29],[2,1.01,15.51]],"ltp":0.0,"tv":0.0,"id":7444998}]}]}
{"op":"mcm","clk":"1004044969","pt":1580653105769,"mc":[{"id":"1.168224477","rc":[{"batb":[[1,1.85,48.73],[2,1.84,18.25]],"batl":[[0,2.06,39.49],[1,2.52,270.1]],"ltp":0.0,"tv":0.0,"id":5858055},{"batb":[[1,1.96,43.69],[2,1.95,30.29]],"batl":[[0,2.18,35.29],[1,2.7,245.56]],"ltp":0.0,"tv":0.0,"id":7444998}]}]}
{"op":"mcm","clk":"1004046455","pt":1580653113776,"mc":[{"id":"1.168224477","rc":[{"batb":[[0,1.85,48.73],[1,1.84,18.25],[2,1.01,15.51]],"ltp":0.0,"tv":0.0,"id":5858055},{"batb":[[0,1.96,43.69],[1,1.95,30.29],[2,1.01,15.51]],"ltp":0.0,"tv":0.0,"id":7444998}]}]}
{"op":"mcm","clk":"1004046677","pt":1580653114897,"mc":[{"id":"1.168224477","rc":[{"batb":[[0,1.84,18.25],[1,1.01,15.51],[2,1.01,0]],"batl":[[0,2.52,270.1],[1,2.52,0]],"ltp":0.0,"tv":0.0,"id":5858055},{"batb":[[0,1.95,30.29],[1,1.01,15.51],[2,1.01,0]],"batl":[[0,2.7,245.56],[1,2.7,0]],"ltp":0.0,"tv":0.0,"id":7444998}]}]}
{"op":"mcm","clk":"1004051171","pt":1580653138154,"mc":[{"id":"1.168224477","rc":[{"batb":[[0,1.92,16.05],[1,1.88,47.05],[2,1.87,17.31]],"batl":[[0,2.08,38.65],[1,2.52,270.1]],"ltp":0.0,"tv":0.0,"id":5858055},{"batb":[[1,1.93,60.35],[2,1.01,15.51]],"batl":[[0,2.14,36.13],[1,2.7,245.56]],"ltp":0.0,"tv":0.0,"id":7444998}]}]}
{"op":"mcm","clk":"1004052754","pt":1580653146047,"mc":[{"id":"1.168224477","rc":[{"batb":[[0,1.88,47.05],[1,1.87,17.31],[2,1.01,15.51]],"ltp":0.0,"tv":0.0,"id":5858055},{"batb":[[0,1.93,60.35],[1,1.01,15.51],[2,1.01,0]],"ltp":0.0,"tv":0.0,"id":7444998}]}]}
{"op":"mcm","clk":"1004052929","pt":1580653146959,"mc":[{"id":"1.168224477","rc":[{"batb":[[0,1.87,17.31],[1,1.01,15.51],[2,1.01,0]],"batl":[[0,2.52,270.1],[1,2.52,0]],"ltp":0.0,"tv":0.0,"id":5858055},{"batb":[[0,1.93,15.82]],"batl":[[0,2.7,245.56],[1,2.7,0]],"ltp":0.0,"tv":0.0,"id":7444998}]}]}
{"op":"mcm","clk":"1004057545","pt":1580653170330,"mc":[{"id":"1.168224477","rc":[{"batb":[[1,1.83,69.06],[2,1.01,15.51]],"batl":[[0,2.04,40.33],[1,2.52,270.1]],"ltp":0.0,"tv":0.0,"id":5858055},{"batb":[[0,2,27.93],[1,1.98,72.2],[2,1.01,15.51]],"batl":[[0,2.2,34.45],[1,2.7,245.56]],"ltp":0.0,"tv":0.0,"id":7444998}]}]}
{"op":"mcm","clk":"1004059778","pt":1580653181543,"mc":[{"id":"1.168224477","rc":[{"batb":[[0,1.83,69.06],[1,1.01,15.51],[2,1.01,0]],"ltp":0.0,"tv":0.0,"id":5858055},{"batb":[[0,1.98,72.2],[1,1.01,15.51],[2,1.01,0]],"ltp":0.0,"tv":0.0,"id":7444998}]}]}
{"op":"mcm","clk":"1004060069","pt":1580653182904,"mc":[{"id":"1.168224477","rc":[{"batb":[[0,1.83,18.65]],"batl":[[0,2.52,270.1],[1,2.52,0]],"ltp":0.0,"tv":0.0,"id":5858055},{"batb":[[0,1.98,29.35]],"batl":[[0,2.7,245.56],[1,2.7,0]],"ltp":0.0,"tv":0.0,"id":7444998}]}]}
{"op":"mcm","clk":"1004062469","pt":1580653195204,"mc":[{"id":"1.168224477","rc":[{"batb":[[0,1.9,16.52],[1,1.88,17.15],[2,1.01,15.51]],"ltp":0.0,"tv":0.0,"id":5858055},{"batb":[[1,1.92,16.13],[2,1.01,15.51]],"ltp":0.0,"tv":0.0,"id":7444998}]}]}
{"op":"mcm","clk":"1004062600","pt":1580653195835,"mc":[{"id":"1.168224477","rc":[{"batb":[[1,1.89,47.05],[2,1.88,17.15]],"batl":[[0,2.08,38.65],[1,2.52,270.1]],"ltp":0.0,"tv":0.0,"id":5858055},{"batb":[[1,1.94,44.53],[2,1.92,16.13]],"batl":[[0,2.14,36.13],[1,2.7,245.56]],"ltp":0.0,"tv":0.0,"id":7444998}]}]}
{"op":"mcm","clk":"1004067331","pt":1580653219143,"mc":[{"id":"1.168224477","rc":[{"batb":[[0,1.89,47.05],[1,1.88,17.15],[2,1.01,15.51]],"ltp":0.0,"tv":0.0,"id":5858055},{"batb":[[0,1.94,44.53],[1,1.92,16.13],[2,1.01,15.51]],"ltp":0.0,"tv":0.0,"id":7444998}]}]}
{"op":"mcm","clk":"1004067685","pt":1580653220850,"mc":[{"id":"1.168224477","rc":[{"batb":[[0,1.88,17.15],[1,1.01,15.51],[2,1.01,0]],"batl":[[0,2.52,270.1],[1,2.52,0]],"ltp":0.0,"tv":0.0,"id":5858055},{"batb":[[0,1.92,16.13],[1,1.01,15.51],[2,1.01,0]],"batl":[[0,2.7,245.56],[1,2.7,0]],"ltp":0.0,"tv":0.0,"id":7444998}]}]}
{"op":"mcm","clk":"1004071465","pt":1580653239269,"mc":[{"id":"1.168224477","rc":[{"batb":[[1,1.85,18.02],[2,1.01,15.51]],"ltp":0.0,"tv":0.0,"id":5858055},{"batb":[[0,2,28.33],[1,1.95,30.69],[2,1.01,15.51]],"ltp":0.0,"tv":0.0,"id":7444998}]}]}
{"op":"mcm","clk":"1004071661","pt":1580653240192,"mc":[{"id":"1.168224477","rc":[{"batl":[[0,2.06,39.49],[1,2.52,270.1]],"ltp":0.0,"tv":0.0,"id":5858055},{"batb":[[1,1.96,43.69],[2,1.95,30.69]],"batl":[[0,2.18,35.29],[1,2.7,245.56]],"ltp":0.0,"tv":0.0,"id":7444998}]}]}
{"op":"mcm","clk":"1004071860","pt":1580653241173,"mc":[{"id":"1.168224477","rc":[{"batb":[[1,1.86,48.73],[2,1.85,18.02]],"ltp":0.0,"tv":0.0,"id":5858055}]}]}
{"op":"mcm","clk":"1004074276","pt":1580653253015,"mc":[{"id":"1.168224477","rc":[{"batb":[[0,1.85,18.02],[1,1.01,15.51],[2,1.85,0]],"batl":[[0,2.52,270.1],[1,2.52,0]],"ltp":0.0,"tv":0.0,"id":5858055},{"batb":[[0,1.95,30.69],[1,1.01,15.51],[2,1.95,0]],"batl":[[0,2.7,245.56],[1,2.7,0]],"ltp":0.0,"tv":0.0,"id":7444998}]}]}
{"op":"mcm","clk":"1004075020","pt":1580653256095,"mc":[{"id":"1.168224477","rc":[{"batb":[[1,1.94,15.42],[2,1.01,15.51]],"ltp":0.0,"tv":0.0,"id":7444998}]}]}
{"op":"mcm","clk":"1004075048","pt":1580653256458,"mc":[{"id":"1.168224477","rc":[{"batb":[[0,1.94,15.42],[1,1.01,15.51],[2,1.01,0]],"ltp":0.0,"tv":0.0,"id":7444998}]}]}
{"op":"mcm","clk":"1004077625","pt":1580653268396,"mc":[{"id":"1.168224477","rc":[{"batb":[[1,1.84,49.57],[2,1.83,18.73]],"batl":[[0,2.04,40.33]],"ltp":0.0,"tv":0.0,"id":5858055},{"batb":[[0,2.02,26.99],[1,1.98,72.12],[2,1.01,15.51]],"batl":[[0,2.2,34.45],[1,2.7,245.56]],"ltp":0.0,"tv":0.0,"id":7444998}]}]}
{"op":"mcm","clk":"1004077962","pt":1580653270124,"mc":[{"id":"1.168224477","rc":[{"batl":[[1,2.4,289.78]],"ltp":0.0,"tv":0.0,"id":5858055}]}]}
{"op":"mcm","clk":"1004079240","pt":1580653276140,"mc":[{"id":"1.168224477","rc":[{"batb":[[0,1.84,49.57],[1,1.83,18.73],[2,1.01,15.51]],"ltp":0.0,"tv":0.0,"id":5858055},{"batb":[[0,1.98,72.12],[1,1.01,15.51],[2,1.01,0]],"ltp":0.0,"tv":0.0,"id":7444998}]}]}
{"op":"mcm","clk":"1004079403","pt":1580653276944,"mc":[{"id":"1.168224477","rc":[{"batb":[[0,1.83,18.73],[1,1.01,15.51],[2,1.01,0]],"batl":[[0,2.4,289.78],[1,2.4,0]],"ltp":0.0,"tv":0.0,"id":5858055},{"batb":[[0,1.98,29.27]],"batl":[[0,2.7,245.56],[1,2.7,0]],"ltp":0.0,"tv":0.0,"id":7444998}]}]}
{"op":"mcm","clk":"1004083480","pt":1580653295975,"mc":[{"id":"1.168224477","rc":[{"batb":[[1,1.82,50.41],[2,1.81,19.43]],"batl":[[0,2,42.01],[1,2.4,289.78]],"ltp":0.0,"tv":0.0,"id":5858055},{"batb":[[0,2.06,25.81],[1,2,69.86],[2,1.01,15.51]],"batl":[[0,2.24,33.61],[1,2.7,245.56]],"ltp":0.0,"tv":0.0,"id":7444998}]}]}
{"op":"mcm","clk":"1004086591","pt":1580653311402,"mc":[{"id":"1.168224477","rc":[{"batb":[[0,1.82,50.41],[1,1.81,19.43],[2,1.01,15.51]],"ltp":0.0,"tv":0.0,"id":5858055},{"batb":[[0,2,69.86],[1,1.01,15.51],[2,1.01,0]],"ltp":0.0,"tv":0.0,"id":7444998}]}]}
{"op":"mcm","clk":"1004086938","pt":1580653313190,"mc":[{"id":"1.168224477","rc":[{"batb":[[0,1.81,19.43],[1,1.01,15.51],[2,1.01,0]],"batl":[[0,2.4,289.78],[1,2.4,0]],"ltp":0.0,"tv":0.0,"id":5858055},{"batb":[[0,2,27.85]],"batl":[[0,2.7,245.56],[1,2.7,0]],"ltp":0.0,"tv":0.0,"id":7444998}]}]}
{"op":"mcm","clk":"1004088775","pt":1580653322396,"mc":[{"id":"1.168224477","rc":[{"batb":[[1,1.78,53.77],[2,1.01,15.51]],"batl":[[0,1.97,42.01],[1,2.4,289.78]],"ltp":0.0,"tv":0.0,"id":5858055},{"batb":[[0,2.06,39.49],[1,2,27.85],[2,1.01,15.51]],"batl":[[0,2.3,31.93],[1,2.7,245.56]],"ltp":0.0,"tv":0.0,"id":7444998}]}]}
{"op":"mcm","clk":"1004088895","pt":1580653322987,"mc":[{"id":"1.168224477","rc":[{"batb":[[2,1.75,21.4]],"ltp":0.0,"tv":0.0,"id":5858055},{"batb":[[0,2.08,24.86],[1,2.06,39.49],[2,2.04,26.12]],"ltp":0.0,"tv":0.0,"id":7444998}]}]}
{"op":"mcm","clk":"1004103616","pt":1580653398231,"mc":[{"id":"1.168224477","rc":[{"batb":[[0,1.78,53.77],[1,1.75,21.4],[2,1.01,15.51]],"ltp":0.0,"tv":0.0,"id":5858055},{"batb":[[0,2.06,39.49],[1,2.04,26.12],[2,1.01,15.51]],"ltp":0.0,"tv":0.0,"id":7444998}]}]}
{"op":"mcm","clk":"1004103788","pt":1580653399176,"mc":[{"id":"1.168224477","rc":[{"batb":[[0,1.75,21.4],[1,1.01,15.51],[2,1.01,0]],"batl":[[0,2.4,289.78],[1,2.4,0]],"ltp":0.0,"tv":0.0,"id":5858055},{"batb":[[0,2.04,26.12],[1,1.01,15.51],[2,1.01,0]],"batl":[[0,2.7,245.56],[1,2.7,0]],"ltp":0.0,"tv":0.0,"id":7444998}]}]}
{"op":"mcm","clk":"1004109205","pt":1580653427449,"mc":[{"id":"1.168224477","rc":[{"batb":[[0,1.83,18.49],[1,1.78,20.3],[2,1.76,270.48]],"ltp":0.0,"tv":0.0,"id":5858055},{"batb":[[1,2.02,27.54],[2,1.01,15.51]],"ltp":0.0,"tv":0.0,"id":7444998}]}]}
{"op":"mcm","clk":"1004109320","pt":1580653428198,"mc":[{"id":"1.168224477","rc":[{"batb":[[1,1.79,52.93],[2,1.78,20.3]],"batl":[[0,1.99,42.01],[1,2.4,289.78]],"ltp":0.0,"tv":0.0,"id":5858055},{"batb":[[1,2.02,68.71]],"batl":[[0,2.26,32.77],[1,2.7,245.56]],"ltp":0.0,"tv":0.0,"id":7444998}]}]}
{"op":"mcm","clk":"1004110974","pt":1580653436386,"mc":[{"id":"1.168224477","rc":[{"batb":[[0,1.79,52.93],[1,1.78,20.3],[2,1.01,15.51]],"ltp":0.0,"tv":0.0,"id":5858055},{"batb":[[0,2.02,68.71],[1,1.01,15.51],[2,1.01,0]],"ltp":0.0,"tv":0.0,"id":7444998}]}]}
{"op":"mcm","clk":"1004111133","pt":1580653437180,"mc":[{"id":"1.168224477","rc":[{"batb":[[0,1.78,20.3],[1,1.01,15.51],[2,1.01,0]],"batl":[[0,2.4,289.78],[1,2.4,0]],"ltp":0.0,"tv":0.0,"id":5858055},{"batb":[[0,2.02,27.54]],"batl":[[0,2.7,245.56],[1,2.7,0]],"ltp":0.0,"tv":0.0,"id":7444998}]}]}
{"op":"mcm","clk":"1004113636","pt":1580653449340,"mc":[{"id":"1.168224477","rc":[{"batb":[[0,1.86,17.62],[1,1.81,19.2],[2,1.01,15.51]],"ltp":0.0,"tv":0.0,"id":5858055},{"batb":[[1,1.99,28.64],[2,1.01,15.51]],"ltp":0.0,"tv":0.0,"id":7444998}]}]}
{"op":"mcm","clk":"1004113809","pt":1580653450213,"mc":[{"id":"1.168224477","rc":[{"batb":[[1,1.82,50.41],[2,1.81,19.2]],"batl":[[0,2.02,41.17],[1,2.4,289.78]],"ltp":0.0,"tv":0.0,"id":5858055},{"batb":[[1,2,42.01],[2,1.99,28.64]],"batl":[[0,2.24,33.61],[1,2.7,245.56]],"ltp":0.0,"tv":0.0,"id":7444998}]}]}
{"op":"mcm","clk":"1004115386","pt":1580653457839,"mc":[{"id":"1.168224477","rc":[{"batb":[[0,1.82,50.41],[1,1.81,19.2],[2,1.01,15.51]],"ltp":0.0,"tv":0.0,"id":5858055},{"batb":[[0,2,42.01],[1,1.99,28.64],[2,1.01,15.51]],"ltp":0.0,"tv":0.0,"id":7444998}]}]}
{"op":"mcm","clk":"1004115695","pt":1580653459251,"mc":[{"id":"1.168224477","rc":[{"batb":[[0,1.81,19.2],[1,1.01,15.51],[2,1.01,0]],"batl":[[0,2.4,289.78],[1,2.4,0]],"ltp":0.0,"tv":0.0,"id":5858055},{"batb":[[0,1.99,28.64],[1,1.01,15.51],[2,1.01,0]],"batl":[[0,2.7,245.56],[1,2.7,0]],"ltp":0.0,"tv":0.0,"id":7444998}]}]}
{"op":"mcm","clk":"1004118651","pt":1580653473384,"mc":[{"id":"1.168224477","rc":[{"batb":[[0,1.01,15.51],[1,1.01,0]],"ltp":0.0,"tv":0.0,"id":7444998}]}]}
{"op":"mcm","clk":"1004119081","pt":1580653475287,"mc":[{"id":"1.168224477","rc":[{"batb":[[0,1.88,16.92],[1,1.84,18.18],[2,1.01,15.51]],"ltp":0.0,"tv":0.0,"id":5858055},{"batb":[[0,1.96,30.21],[1,1.01,15.51]],"ltp":0.0,"tv":0.0,"id":7444998}]}]}
{"op":"mcm","clk":"1004119189","pt":1580653475776,"mc":[{"id":"1.168224477","rc":[{"batb":[[0,1.84,18.18],[1,1.01,15.51],[2,1.01,0]],"ltp":0.0,"tv":0.0,"id":5858055}]}]}
{"op":"mcm","clk":"1004121024","pt":1580653484275,"mc":[{"id":"1.168224477","rc":[{"batb":[[1,1.8,71.68],[2,1.01,15.51]],"batl":[[0,2,42.01],[1,2.4,289.78]],"ltp":0.0,"tv":0.0,"id":5858055},{"batb":[[0,2.04,26.67],[1,2,69.94],[2,1.96,30.21]],"batl":[[0,2.24,33.61],[1,2.7,245.56]],"ltp":0.0,"tv":0.0,"id":7444998}]}]}
{"op":"mcm","clk":"1004121068","pt":1580653484480,"mc":[{"id":"1.168224477","rc":[{"batl":[[0,2.4,289.78],[1,2.4,0]],"ltp":0.0,"tv":0.0,"id":5858055},{"batb":[[1,2,27.93],[2,1.01,15.51]],"ltp":0.0,"tv":0.0,"id":7444998}]}]}
{"op":"mcm","clk":"1004121547","pt":1580653486795,"mc":[{"id":"1.168224477","rc":[{"batl":[[0,1.99,42.01],[1,2.4,289.78]],"ltp":0.0,"tv":0.0,"id":5858055},{"batb":[[1,2.02,41.17],[2,2,27.93]],"ltp":0.0,"tv":0.0,"id":7444998}]}]}
{"op":"mcm","clk":"1004123525","pt":1580653496188,"mc":[{"id":"1.168224477","rc":[{"batb":[[0,1.8,71.68],[1,1.01,15.51],[2,1.01,0]],"ltp":0.0,"tv":0.0,"id":5858055},{"batb":[[0,2.02,41.17],[1,2,27.93],[2,1.01,15.51]],"ltp":0.0,"tv":0.0,"id":7444998}]}]}
{"op":"mcm","clk":"1004123742","pt":1580653497213,"mc":[{"id":"1.168224477","rc":[{"batb":[[0,1.8,19.59]],"batl":[[0,2.4,289.78],[1,2.4,0]],"ltp":0.0,"tv":0.0,"id":5858055},{"batb":[[0,2,27.93],[1,1.01,15.51],[2,1.01,0]],"batl":[[0,2.7,245.56],[1,2.7,0]],"ltp":0.0,"tv":0.0,"id":7444998}]}]}
{"op":"mcm","clk":"1004125750","pt":1580653506310,"mc":[{"id":"1.168224477","rc":[{"batb":[[1,1.77,53.77],[2,1.75,21.72]],"batl":[[0,1.95,42.01]],"ltp":0.0,"tv":0.0,"id":5858055},{"batb":[[0,2.08,24.63],[1,2.06,65.45],[2,2,27.93]],"batl":[[0,2.32,31.09]],"ltp":0.0,"tv":0.0,"id":7444998}]}]}
{"op":"mcm","clk":"1004125917","pt":1580653507015,"mc":[{"id":"1.168224477","rc":[{"batb":[[2,1.01,15.51]],"ltp":0.0,"tv":0.0,"id":7444998}]}]}
{"op":"mcm","clk":"1004126129","pt":1580653508000,"mc":[{"id":"1.168224477","rc":[{"batl":[[1,2.3,309.75]],"ltp":0.0,"tv":0.0,"id":5858055},{"batl":[[1,3,213.45]],"ltp":0.0,"tv":0.0,"id":7444998}]}]}
{"op":"mcm","clk":"1004128245","pt":1580653517441,"mc":[{"id":"1.168224477","rc":[{"batb":[[0,1.75,21.72],[1,1.01,15.51],[2,1.75,0]],"batl":[[0,2.3,309.75],[1,2.3,0]],"ltp":0.0,"tv":0.0,"id":5858055},{"batb":[[0,2.06,25.97],[1,1.01,15.51],[2,1.01,0]],"batl":[[0,3,213.45],[1,3,0]],"ltp":0.0,"tv":0.0,"id":7444998}]}]}
{"op":"mcm","clk":"1004128885","pt":1580653520239,"mc":[{"id":"1.168224477","rc":[{"batb":[[1,2.04,26.36],[2,1.01,15.51]],"ltp":0.0,"tv":0.0,"id":7444998}]}]}
{"op":"mcm","clk":"1004128939","pt":1580653520455,"mc":[{"id":"1.168224477","rc":[{"batb":[[0,1.75,21.4]],"ltp":0.0,"tv":0.0,"id":5858055},{"batb":[[0,2.04,26.36],[1,1.01,15.51],[2,1.01,0]],"ltp":0.0,"tv":0.0,"id":7444998}]}]}
{"op":"mcm","clk":"1004131658","pt":1580653532449,"mc":[{"id":"1.168224477","rc":[{"batb":[[1,1.74,56.29],[2,1.7,23.68]],"batl":[[0,1.91,42.01],[1,2.3,309.75]],"ltp":0.0,"tv":0.0,"id":5858055},{"batb":[[0,2.16,22.42],[1,2.1,62.12],[2,2.04,26.36]],"batl":[[0,2.38,30.25],[1,3,213.45]],"ltp":0.0,"tv":0.0,"id":7444998}]}]}
{"op":"mcm","clk":"1004131771","pt":1580653532935,"mc":[{"id":"1.168224477","rc":[{"batb":[[2,1.01,15.51]],"ltp":0.0,"tv":0.0,"id":7444998}]}]}
{"op":"mcm","clk":"1004134246","pt":1580653544173,"mc":[{"id":"1.168224477","rc":[{"batb":[[0,1.74,56.29],[1,1.7,23.68],[2,1.01,15.51]],"ltp":0.0,"tv":0.0,"id":5858055},{"batb":[[0,2.1,62.12],[1,1.01,15.51],[2,1.01,0]],"ltp":0.0,"tv":0.0,"id":7444998}]}]}
{"op":"mcm","clk":"1004134492","pt":1580653545288,"mc":[{"id":"1.168224477","rc":[{"batb":[[0,1.7,23.68],[1,1.01,15.51],[2,1.01,0]],"batl":[[0,2.3,309.75],[1,2.3,0]],"ltp":0.0,"tv":0.0,"id":5858055},{"batb":[[0,2.1,24.31]],"batl":[[0,3,213.45],[1,3,0]],"ltp":0.0,"tv":0.0,"id":7444998}]}]}
{"op":"mcm","clk":"1004139200","pt":1580653566440,"mc":[{"id":"1.168224477","rc":[{"batb":[[0,1.79,19.83],[1,1.74,78.17],[2,1.01,15.51]],"batl":[[0,1.93,42.01],[1,2.3,309.75]],"ltp":0.0,"tv":0.0,"id":5858055},{"batb":[[1,2.08,38.65],[2,2.06,25.57]],"batl":[[0,2.34,31.09],[1,3,213.45]],"ltp":0.0,"tv":0.0,"id":7444998}]}]}
{"op":"mcm","clk":"1004141712","pt":1580653577969,"mc":[{"id":"1.168224477","rc":[{"batb":[[0,1.74,78.17],[1,1.01,15.51],[2,1.01,0]],"ltp":0.0,"tv":0.0,"id":5858055},{"batb":[[0,2.08,38.65],[1,2.06,25.57],[2,1.01,15.51]],"ltp":0.0,"tv":0.0,"id":7444998}]}]}
{"op":"mcm","clk":"1004142008","pt":1580653579371,"mc":[{"id":"1.168224477","rc":[{"batb":[[0,1.74,21.87]],"batl":[[0,2.3,309.75],[1,2.3,0]],"ltp":0.0,"tv":0.0,"id":5858055},{"batb":[[0,2.06,25.57],[1,1.01,15.51],[2,1.01,0]],"batl":[[0,3,213.45],[1,3,0]],"ltp":0.0,"tv":0.0,"id":7444998}]}]}
{"op":"mcm","clk":"1004145580","pt":1580653595399,"mc":[{"id":"1.168224477","rc":[{"batb":[[1,1.69,24.16],[2,1.01,15.51]],"ltp":0.0,"tv":0.0,"id":5858055},{"batb":[[0,2.18,21.87],[1,2.12,23.53],[2,2.06,25.57]],"ltp":0.0,"tv":0.0,"id":7444998}]}]}
{"op":"mcm","clk":"1004145771","pt":1580653596281,"mc":[{"id":"1.168224477","rc":[{"batb":[[1,1.72,57.97],[2,1.69,24.16]],"batl":[[0,1.89,42.01],[1,2.3,309.75]],"ltp":0.0,"tv":0.0,"id":5858055},{"batb":[[1,2.12,60.49],[2,1.01,15.51]],"batl":[[0,2.4,29.41],[1,3,213.45]],"ltp":0.0,"tv":0.0,"id":7444998}]}]}
{"op":"mcm","clk":"1004147928","pt":1580653607394,"mc":[{"id":"1.168224477","rc":[{"batb":[[0,1.69,24.16],[1,1.01,15.51],[2,1.69,0]],"batl":[[0,2.3,309.75],[1,2.3,0]],"ltp":0.0,"tv":0.0,"id":5858055},{"batb":[[0,2.12,23.53],[1,1.01,15.51],[2,1.01,0]],"batl":[[0,3,213.45],[1,3,0]],"ltp":0.0,"tv":0.0,"id":7444998}]}]}
{"op":"mcm","clk":"1004151222","pt":1580653624404,"mc":[{"id":"1.168224477","rc":[{"batb":[[0,1.69,84.65],[1,1.63,27.62],[2,1.01,15.51]],"batl":[[0,1.86,42.01]],"ltp":0.0,"tv":0.0,"id":5858055},{"batb":[[0,2.26,19.59],[1,2.2,21.48],[2,2.18,35.29]],"batl":[[0,2.46,28.57],[1,3,213.45]],"ltp":0.0,"tv":0.0,"id":7444998}]}]}
{"op":"mcm","clk":"1004151511","pt":1580653625936,"mc":[{"id":"1.168224477","rc":[{"batl":[[1,2.16,342.82]],"ltp":0.0,"tv":0.0,"id":5858055}]}]}
{"op":"mcm","clk":"1004154656","pt":1580653641678,"mc":[{"id":"1.168224477","rc":[{"batb":[[0,1.69,60.49]],"ltp":0.0,"tv":0.0,"id":5858055},{"batb":[[0,2.2,21.48],[1,2.18,35.29],[2,1.01,15.51]],"ltp":0.0,"tv":0.0,"id":7444998}]}]}
{"op":"mcm","clk":"1004154984","pt":1580653643363,"mc":[{"id":"1.168224477","rc":[{"batb":[[0,1.63,27.62],[1,1.01,15.51],[2,1.01,0]],"batl":[[0,2.16,342.82],[1,2.16,0]],"ltp":0.0,"tv":0.0,"id":5858055},{"batb":[[1,1.01,15.51],[2,1.01,0]],"batl":[[0,3,213.45],[1,3,0]],"ltp":0.0,"tv":0.0,"id":7444998}]}]}
{"op":"mcm","clk":"1004157260","pt":1580653654269,"mc":[{"id":"1.168224477","rc":[{"batb":[[0,1.73,22.27],[1,1.7,59.65],[2,1.68,24.55]],"batl":[[0,1.88,42.01],[1,2.16,342.82]],"ltp":0.0,"tv":0.0,"id":5858055},{"batb":[[1,2.16,36.13],[2,2.12,23.29]],"batl":[[0,2.42,29.41],[1,3,213.45]],"ltp":0.0,"tv":0.0,"id":7444998}]}]}
{"op":"mcm","clk":"1004159029","pt":1580653663301,"mc":[{"id":"1.168224477","rc":[{"batb":[[0,1.68,24.55],[1,1.01,15.51],[2,1.68,0]],"batl":[[0,2.16,342.82],[1,2.16,0]],"ltp":0.0,"tv":0.0,"id":5858055},{"batb":[[0,2.12,23.29],[1,1.01,15.51],[2,2.12,0]],"batl":[[0,3,213.45],[1,3,0]],"ltp":0.0,"tv":0.0,"id":7444998}]}]}
{"op":"mcm","clk":"1004160890","pt":1580653672405,"mc":[{"id":"1.168224477","rc":[{"batb":[[0,1.77,20.61],[1,1.73,22.5],[2,1.72,57.97]],"batl":[[0,1.9,42.01],[1,2.16,342.82]],"ltp":0.0,"tv":0.0,"id":5858055},{"batb":[[0,2.14,36.13],[1,2.12,23.29],[2,2.08,24.78]],"batl":[[0,2.4,29.41],[1,3,213.45]],"ltp":0.0,"tv":0.0,"id":7444998}]}]}
{"op":"mcm","clk":"1004161051","pt":1580653673224,"mc":[{"id":"1.168224477","rc":[{"batb":[[0,2.12,23.29],[1,2.08,24.78],[2,1.01,15.51]],"batl":[[0,3,213.45],[1,3,0]],"ltp":0.0,"tv":0.0,"id":7444998}]}]}
{"op":"mcm","clk":"1004161399","pt":1580653675029,"mc":[{"id":"1.168224477","rc":[{"batb":[[0,2.12,60.26]],"batl":[[0,2.38,30.25],[1,3,213.45]],"ltp":0.0,"tv":0.0,"id":7444998}]}]}
{"op":"mcm","clk":"1004163173","pt":1580653683348,"mc":[{"id":"1.168224477","rc":[{"batb":[[0,1.73,22.5],[1,1.01,15.51],[2,1.72,0]],"batl":[[0,2.16,342.82],[1,2.16,0]],"ltp":0.0,"tv":0.0,"id":5858055},{"batb":[[0,2.08,24.78],[1,1.01,15.51],[2,1.01,0]],"batl":[[0,3,213.45],[1,3,0]],"ltp":0.0,"tv":0.0,"id":7444998}]}]}
{"op":"mcm","clk":"1004163855","pt":1580653686396,"mc":[{"id":"1.168224477","rc":[{"batb":[[0,1.74,22.11]],"ltp":0.0,"tv":0.0,"id":5858055}]}]}
{"op":"mcm","clk":"1004165147","pt":1580653692322,"mc":[{"id":"1.168224477","rc":[{"batb":[[0,1.76,54.61],[1,1.74,22.11],[2,1.01,15.51]],"batl":[[0,1.94,42.01],[1,2.16,342.82]],"ltp":0.0,"tv":0.0,"id":5858055},{"batb":[[0,2.08,63.43]],"batl":[[0,2.34,31.09],[1,3,213.45]],"ltp":0.0,"tv":0.0,"id":7444998}]}]}
{"op":"mcm","clk":"1004165249","pt":1580653692819,"mc":[{"id":"1.168224477","rc":[{"batb":[[0,1.82,19.12],[1,1.79,20.14],[2,1.76,54.61]],"ltp":0.0,"tv":0.0,"id":5858055},{"batb":[[1,2,28.01],[2,1.01,15.51]],"batl":[[0,3,213.45],[1,3,0]],"ltp":0.0,"tv":0.0,"id":7444998}]}]}
{"op":"mcm","clk":"1004165727","pt":1580653695116,"mc":[{"id":"1.168224477","rc":[{"batl":[[0,2.32,31.09],[1,3,213.45]],"ltp":0.0,"tv":0.0,"id":7444998}]}]}
{"op":"mcm","clk":"1004170536","pt":1580653719992,"mc":[{"id":"1.168224477","rc":[{"batb":[[0,1.79,20.14],[1,1.01,15.51],[2,1.76,0]],"batl":[[0,2.16,342.82],[1,2.16,0]],"ltp":0.0,"tv":0.0,"id":5858055},{"batb":[[0,2,27.77],[1,1.01,15.51],[2,1.01,0]],"batl":[[0,3,213.45],[1,3,0]],"ltp":0.0,"tv":0.0,"id":7444998}]}]}
{"op":"mcm","clk":"1004175171","pt":1580653743217,"mc":[{"id":"1.168224477","rc":[{"batb":[[1,1.76,21.17],[2,1.01,15.51]],"ltp":0.0,"tv":0.0,"id":5858055},{"batb":[[0,2.1,24],[1,2.04,26.28],[2,2,27.77]],"ltp":0.0,"tv":0.0,"id":7444998}]}]}
{"op":"mcm","clk":"1004175442","pt":1580653744415,"mc":[{"id":"1.168224477","rc":[{"batb":[[2,1.75,55.45]],"batl":[[0,1.92,42.01],[1,2.16,342.82]],"ltp":0.0,"tv":0.0,"id":5858055},{"batb":[[1,2.08,38.65],[2,2.04,26.28]],"batl":[[0,2.36,30.25],[1,3,213.45]],"ltp":0.0,"tv":0.0,"id":7444998}]}]}
{"op":"mcm","clk":"1004176981","pt":1580653751243,"mc":[{"id":"1.168224477","rc":[{"batb":[[0,1.76,21.17],[1,1.75,55.45],[2,1.01,15.51]],"ltp":0.0,"tv":0.0,"id":5858055},{"batb":[[0,2.08,38.65],[1,2.04,26.28],[2,1.01,15.51]],"ltp":0.0,"tv":0.0,"id":7444998}]}]}
{"op":"mcm","clk":"1004177096","pt":1580653751728,"mc":[{"id":"1.168224477","rc":[{"batb":[[1,1.01,15.51],[2,1.01,0]],"batl":[[0,2.16,342.82],[1,2.16,0]],"ltp":0.0,"tv":0.0,"id":5858055},{"batb":[[0,2.04,26.28],[1,1.01,15.51],[2,1.01,0]],"batl":[[0,3,213.45],[1,3,0]],"ltp":0.0,"tv":0.0,"id":7444998}]}]}
{"op":"mcm","clk":"1004179997","pt":1580653765326,"mc":[{"id":"1.168224477","rc":[{"batb":[[1,1.73,22.27],[2,1.01,15.51]],"ltp":0.0,"tv":0.0,"id":5858055},{"batb":[[0,2.16,22.66],[1,2.08,24.94],[2,2.06,220.24]],"ltp":0.0,"tv":0.0,"id":7444998}]}]}
{"op":"mcm","clk":"1004180222","pt":1580653766347,"mc":[{"id":"1.168224477","rc":[{"batb":[[2,1.01,15.51]],"ltp":0.0,"tv":0.0,"id":7444998}]}]}
{"op":"mcm","clk":"1004180290","pt":1580653766627,"mc":[{"id":"1.168224477","rc":[{"batb":[[1,1.73,79.4]],"batl":[[0,1.9,42.01],[1,2.16,342.82]],"ltp":0.0,"tv":0.0,"id":5858055},{"batb":[[1,2.1,37.81],[2,2.08,24.94]],"batl":[[0,2.38,30.25],[1,3,213.45]],"ltp":0.0,"tv":0.0,"id":7444998}]}]}
{"op":"mcm","clk":"1004182906","pt":1580653779599,"mc":[{"id":"1.168224477","rc":[{"batb":[[0,1.73,22.27],[1,1.01,15.51],[2,1.01,0]],"batl":[[0,2.16,342.82],[1,2.16,0]],"ltp":0.0,"tv":0.0,"id":5858055},{"batb":[[0,2.08,24.94],[1,1.01,15.51],[2,2.08,0]],"batl":[[0,3,213.45],[1,3,0]],"ltp":0.0,"tv":0.0,"id":7444998}]}]}
{"op":"mcm","clk":"1004187426","pt":1580653802448,"mc":[{"id":"1.168224477","rc":[{"batb":[[0,1.76,54.61],[1,1.73,22.27],[2,1.01,15.51]],"batl":[[0,1.94,42.01]],"ltp":0.0,"tv":0.0,"id":5858055},{"batb":[[1,2.06,39.49],[2,1.01,15.51]],"batl":[[0,2.32,31.09]],"ltp":0.0,"tv":0.0,"id":7444998}]}]}
{"op":"mcm","clk":"1004187514","pt":1580653802865,"mc":[{"id":"1.168224477","rc":[{"batb":[[0,1.81,19.36],[1,1.78,20.38],[2,1.76,54.61]],"ltp":0.0,"tv":0.0,"id":5858055},{"batb":[[2,2,27.62]],"ltp":0.0,"tv":0.0,"id":7444998}]}]}
{"op":"mcm","clk":"1004187803","pt":1580653804125,"mc":[{"id":"1.168224477","rc":[{"batl":[[1,2.4,289.78]],"ltp":0.0,"tv":0.0,"id":5858055},{"batl":[[1,2.84,228.62]],"ltp":0.0,"tv":0.0,"id":7444998}]}]}
{"op":"mcm","clk":"1004191161","pt":1580653821866,"mc":[{"id":"1.168224477","rc":[{"batb":[[0,1.78,20.38],[1,1.01,15.51],[2,1.76,0]],"batl":[[0,2.4,289.78],[1,2.4,0]],"ltp":0.0,"tv":0.0,"id":5858055},{"batb":[[0,2,27.62],[1,1.01,15.51],[2,2,0]],"batl":[[0,2.84,228.62],[1,2.84,0]],"ltp":0.0,"tv":0.0,"id":7444998}]}]}
{"op":"mcm","clk":"1004191723","pt":1580653825045,"mc":[{"id":"1.168224477","rc":[{"batb":[[0,1.77,20.61]],"ltp":0.0,"tv":0.0,"id":5858055},{"batb":[[0,2.02,27.38]],"ltp":0.0,"tv":0.0,"id":7444998}]}]}
{"op":"mcm","clk":"1004194630","pt":1580653841270,"mc":[{"id":"1.168224477","rc":[{"batb":[[0,1.86,17.7],[1,1.82,18.88],[2,1.78,327.16]],"ltp":0.0,"tv":0.0,"id":5858055},{"batb":[[1,1.94,15.42],[2,1.01,15.51]],"ltp":0.0,"tv":0.0,"id":7444998}]}]}
{"op":"mcm","clk":"1004194817","pt":1580653842419,"mc":[{"id":"1.168224477","rc":[{"batb":[[2,1.01,15.51]],"ltp":0.0,"tv":0.0,"id":5858055}]}]}
{"op":"mcm","clk":"1004195000","pt":1580653843435,"mc":[{"id":"1.168224477","rc":[{"batb":[[2,1.8,52.09]],"batl":[[0,1.98,42.01],[1,2.4,289.78]],"ltp":0.0,"tv":0.0,"id":5858055},{"batb":[[0,2.02,68.55]],"batl":[[0,2.28,32.77],[1,2.7,245.56]],"ltp":0.0,"tv":0.0,"id":7444998}]}]}
{"op":"mcm","clk":"1004197974","pt":1580653859037,"mc":[{"id":"1.168224477","rc":[{"batb":[[0,1.82,18.88],[1,1.8,52.09],[2,1.01,15.51]],"ltp":0.0,"tv":0.0,"id":5858055},{"batb":[[0,2.02,41.17]],"ltp":0.0,"tv":0.0,"id":7444998}]}]}
{"op":"mcm","clk":"1004198069","pt":1580653859527,"mc":[{"id":"1.168224477","rc":[{"batb":[[1,1.01,15.51],[2,1.01,0]],"batl":[[0,2.4,289.78],[1,2.4,0]],"ltp":0.0,"tv":0.0,"id":5858055},{"batb":[[0,1.94,15.42],[1,1.01,15.51],[2,1.01,0]],"batl":[[0,2.7,245.56],[1,2.7,0]],"ltp":0.0,"tv":0.0,"id":7444998}]}]}
{"op":"mcm","clk":"1004198499","pt":1580653862057,"mc":[{"id":"1.168224477","rc":[{"batb":[[0,1.95,30.53]],"ltp":0.0,"tv":0.0,"id":7444998}]}]}
{"op":"mcm","clk":"1004201330","pt":1580653876438,"mc":[{"id":"1.168224477","rc":[{"batb":[[0,1.83,50.41],[1,1.82,18.88],[2,1.01,15.51]],"batl":[[0,2.02,41.17],[1,2.4,289.78]],"ltp":0.0,"tv":0.0,"id":5858055},{"batb":[[0,1.97,42.85],[1,1.95,30.53],[2,1.01,15.51]],"batl":[[0,2.22,33.61],[1,2.7,245.56]],"ltp":0.0,"tv":0.0,"id":7444998}]}]}
{"op":"mcm","clk":"1004201523","pt":1580653877362,"mc":[{"id":"1.168224477","rc":[{"batb":[[0,1.92,15.89],[1,1.88,17.15],[2,1.83,271.15]],"ltp":0.0,"tv":0.0,"id":5858055},{"batb":[[2,1.88,17.23]],"ltp":0.0,"tv":0.0,"id":7444998}]}]}
{"op":"mcm","clk":"1004201544","pt":1580653877457,"mc":[{"id":"1.168224477","rc":[{"batb":[[2,1.83,50.41]],"ltp":0.0,"tv":0.0,"id":5858055}]}]}
{"op":"mcm","clk":"1004205710","pt":1580653897296,"mc":[{"id":"1.168224477","rc":[{"batl":[[0,2.7,245.56],[1,2.7,0]],"ltp":0.0,"tv":0.0,"id":7444998}]}]}
{"op":"mcm","clk":"1004205865","pt":1580653898096,"mc":[{"id":"1.168224477","rc":[{"batb":[[0,1.88,17.15],[1,1.83,50.41],[2,1.01,15.51]],"ltp":0.0,"tv":0.0,"id":5858055},{"batb":[[1,1.88,17.23],[2,1.01,15.51]],"ltp":0.0,"tv":0.0,"id":7444998}]}]}
{"op":"mcm","clk":"1004206305","pt":1580653900195,"mc":[{"id":"1.168224477","rc":[{"batb":[[1,1.01,15.51],[2,1.01,0]],"batl":[[0,2.4,289.78],[1,2.4,0]],"ltp":0.0,"tv":0.0,"id":5858055},{"batb":[[0,1.88,17.23],[1,1.01,15.51],[2,1.01,0]],"batl":[[0,2.2,34.45],[1,2.7,245.56]],"ltp":0.0,"tv":0.0,"id":7444998}]}]}
{"op":"mcm","clk":"1004206364","pt":1580653900495,"mc":[{"id":"1.168224477","rc":[{"batl":[[0,2.7,245.56],[1,2.7,0]],"ltp":0.0,"tv":0.0,"id":7444998}]}]}
{"op":"mcm","clk":"1004207773","pt":1580653907286,"mc":[{"id":"1.168224477","rc":[{"batb":[[1,1.83,18.49],[2,1.01,15.51]],"ltp":0.0,"tv":0.0,"id":5858055},{"batb":[[0,2,28.25],[1,1.94,15.58],[2,1.88,17.23]],"ltp":0.0,"tv":0.0,"id":7444998}]}]}
{"op":"mcm","clk":"1004207985","pt":1580653908409,"mc":[{"id":"1.168224477","rc":[{"batb":[[2,1.01,15.51]],"ltp":0.0,"tv":0.0,"id":7444998}]}]}
{"op":"mcm","clk":"1004208113","pt":1580653909007,"mc":[{"id":"1.168224477","rc":[{"batb":[[2,1.82,50.41]],"batl":[[0,2,42.01],[1,2.4,289.78]],"ltp":0.0,"tv":0.0,"id":5858055},{"batb":[[1,1.99,42.01],[2,1.94,15.58]],"batl":[[0,2.24,33.61],[1,2.7,245.56]],"ltp":0.0,"tv":0.0,"id":7444998}]}]}
{"op":"mcm","clk":"1004209904","pt":1580653918406,"mc":[{"id":"1.168224477","rc":[{"batb":[[0,1.83,18.49],[1,1.82,50.41],[2,1.01,15.51]],"ltp":0.0,"tv":0.0,"id":5858055},{"batb":[[0,1.99,42.01],[1,1.94,15.58],[2,1.01,15.51]],"ltp":0.0,"tv":0.0,"id":7444998}]}]}
{"op":"mcm","clk":"1004210127","pt":1580653919528,"mc":[{"id":"1.168224477","rc":[{"batb":[[1,1.01,15.51],[2,1.01,0]],"batl":[[0,2.4,289.78],[1,2.4,0]],"ltp":0.0,"tv":0.0,"id":5858055},{"batb":[[0,1.94,15.58],[1,1.01,15.51],[2,1.01,0]],"batl":[[0,2.7,245.56],[1,2.7,0]],"ltp":0.0,"tv":0.0,"id":7444998}]}]}
{"op":"mcm","clk":"1004212745","pt":1580653932423,"mc":[{"id":"1.168224477","rc":[{"batb":[[0,1.93,15.66],[1,1.88,17.07],[2,1.01,15.51]],"ltp":0.0,"tv":0.0,"id":5858055},{"batb":[[1,1.85,17.86],[2,1.01,15.51]],"ltp":0.0,"tv":0.0,"id":7444998}]}]}
{"op":"mcm","clk":"1004212913","pt":1580653933335,"mc":[{"id":"1.168224477","rc":[{"batb":[[2,1.86,48.73]],"batl":[[0,2.06,39.49],[1,2.4,289.78]],"ltp":0.0,"tv":0.0,"id":5858055},{"batb":[[0,1.95,43.69],[1,1.94,15.58],[2,1.85,17.86]],"batl":[[0,2.18,35.29],[1,2.7,245.56]],"ltp":0.0,"tv":0.0,"id":7444998}]}]}
{"op":"mcm","clk":"1004215421","pt":1580653947127,"mc":[{"id":"1.168224477","rc":[{"batb":[[0,1.88,17.07],[1,1.86,48.73],[2,1.01,15.51]],"ltp":0.0,"tv":0.0,"id":5858055},{"batb":[[1,1.85,17.86],[2,1.01,15.51]],"ltp":0.0,"tv":0.0,"id":7444998}]}]}
{"op":"mcm","clk":"1004215517","pt":1580653947534,"mc":[{"id":"1.168224477","rc":[{"batb":[[1,1.01,15.51],[2,1.01,0]],"batl":[[0,2.4,289.78],[1,2.4,0]],"ltp":0.0,"tv":0.0,"id":5858055},{"batb":[[0,1.85,17.86],[1,1.01,15.51],[2,1.01,0]],"batl":[[0,2.7,245.56],[1,2.7,0]],"ltp":0.0,"tv":0.0,"id":7444998}]}]}
{"op":"mcm","clk":"1004215995","pt":1580653950246,"mc":[{"id":"1.168224477","rc":[{"batb":[[0,1.89,16.92]],"ltp":0.0,"tv":0.0,"id":5858055},{"batb":[[0,1.86,17.78]],"ltp":0.0,"tv":0.0,"id":7444998}]}]}
{"op":"mcm","clk":"1004218215","pt":1580653962449,"mc":[{"id":"1.168224477","rc":[{"batb":[[1,1.85,18.02],[2,1.84,49.57]],"batl":[[0,2.02,41.17],[1,2.4,289.78]],"ltp":0.0,"tv":0.0,"id":5858055},{"batb":[[0,1.99,28.72],[1,1.97,42.85],[2,1.92,15.97]],"batl":[[0,2.22,33.61],[1,2.7,245.56]],"ltp":0.0,"tv":0.0,"id":7444998}]}]}
{"op":"mcm","clk":"1004221057","pt":1580653978213,"mc":[{"id":"1.168224477","rc":[{"batb":[[0,1.85,18.02],[1,1.84,49.57],[2,1.01,15.51]],"ltp":0.0,"tv":0.0,"id":5858055},{"batb":[[0,1.97,42.85],[1,1.92,15.97],[2,1.01,15.51]],"ltp":0.0,"tv":0.0,"id":7444998}]}]}
{"op":"mcm","clk":"1004221359","pt":1580653979623,"mc":[{"id":"1.168224477","rc":[{"batb":[[1,1.01,15.51],[2,1.01,0]],"batl":[[0,2.4,289.78],[1,2.4,0]],"ltp":0.0,"tv":0.0,"id":5858055},{"batb":[[0,1.92,15.97],[1,1.01,15.51],[2,1.01,0]],"batl":[[0,2.7,245.56],[1,2.7,0]],"ltp":0.0,"tv":0.0,"id":7444998}]}]}
{"op":"mcm","clk":"1004221696","pt":1580653981196,"mc":[{"id":"1.168224477","rc":[{"batb":[[0,1.84,18.18]],"ltp":0.0,"tv":0.0,"id":5858055},{"batb":[[0,1.93,15.82]],"ltp":0.0,"tv":0.0,"id":7444998}]}]}
{"op":"mcm","clk":"1004223109","pt":1580653988419,"mc":[{"id":"1.168224477","rc":[{"batb":[[1,1.81,19.43],[2,1.01,15.51]],"ltp":0.0,"tv":0.0,"id":5858055},{"batb":[[0,2.04,26.59],[1,1.97,29.43],[2,1.01,15.51]],"ltp":0.0,"tv":0.0,"id":7444998}]}]}
{"op":"mcm","clk":"1004223129","pt":1580653988506,"mc":[{"id":"1.168224477","rc":[{"batb":[[1,1.82,50.41],[2,1.81,19.43]],"batl":[[0,2,42.01],[1,2.4,289.78]],"ltp":0.0,"tv":0.0,"id":5858055},{"batb":[[1,1.99,42.01],[2,1.97,29.43]],"batl":[[0,2.24,33.61],[1,2.7,245.56]],"ltp":0.0,"tv":0.0,"id":7444998}]}]}
{"op":"mcm","clk":"1004225332","pt":1580653999400,"mc":[{"id":"1.168224477","rc":[{"batb":[[0,1.82,50.41],[1,1.81,19.43],[2,1.01,15.51]],"ltp":0.0,"tv":0.0,"id":5858055},{"batb":[[0,1.99,42.01],[1,1.97,29.43],[2,1.01,15.51]],"ltp":0.0,"tv":0.0,"id":7444998}]}]}
{"op":"mcm","clk":"1004225349","pt":1580653999533,"mc":[{"id":"1.168224477","rc":[{"batb":[[0,1.81,19.43],[1,1.01,15.51],[2,1.01,0]],"batl":[[0,2.4,289.78],[1,2.4,0]],"ltp":0.0,"tv":0.0,"id":5858055},{"batb":[[0,1.97,29.43],[1,1.01,15.51],[2,1.01,0]],"batl":[[0,2.7,245.56],[1,2.7,0]],"ltp":0.0,"tv":0.0,"id":7444998}]}]}
{"op":"mcm","clk":"1004227631","pt":1580654011329,"mc":[{"id":"1.168224477","rc":[{"batb":[[0,1.9,16.52],[1,1.86,17.62],[2,1.81,242.72]],"ltp":0.0,"tv":0.0,"id":5858055},{"batb":[[1,1.91,16.29],[2,1.01,15.51]],"ltp":0.0,"tv":0.0,"id":7444998}]}]}
{"op":"mcm","clk":"1004227689","pt":1580654011637,"mc":[{"id":"1.168224477","rc":[{"batb":[[2,1.01,15.51]],"ltp":0.0,"tv":0.0,"id":5858055}]}]}
{"op":"mcm","clk":"1004228016","pt":1580654013237,"mc":[{"id":"1.168224477","rc":[{"batb":[[1,1.86,66.36]],"batl":[[0,2.04,40.33],[1,2.4,289.78]],"ltp":0.0,"tv":0.0,"id":5858055},{"batb":[[1,1.95,43.69],[2,1.91,16.29]],"batl":[[0,2.18,35.29],[1,2.7,245.56]],"ltp":0.0,"tv":0.0,"id":7444998}]}]}
{"op":"mcm","clk":"1004231435","pt":1580654029877,"mc":[{"id":"1.168224477","rc":[{"batb":[[0,1.86,66.36],[1,1.01,15.51],[2,1.01,0]],"ltp":0.0,"tv":0.0,"id":5858055},{"batb":[[0,1.95,43.69],[1,1.91,16.29],[2,1.01,15.51]],"ltp":0.0,"tv":0.0,"id":7444998}]}]}
{"op":"mcm","clk":"1004231791","pt":1580654031559,"mc":[{"id":"1.168224477","rc":[{"batb":[[0,1.86,17.62]],"batl":[[0,2.4,289.78],[1,2.4,0]],"ltp":0.0,"tv":0.0,"id":5858055},{"batb":[[0,1.91,16.29],[1,1.01,15.51],[2,1.01,0]],"batl":[[0,2.7,245.56],[1,2.7,0]],"ltp":0.0,"tv":0.0,"id":7444998}]}]}
{"op":"mcm","clk":"1004234249","pt":1580654043251,"mc":[{"id":"1.168224477","rc":[{"batb":[[0,1.97,29.66],[1,1.92,15.97],[2,1.9,46.21]],"batl":[[0,2.1,37.81],[1,2.4,289.78]],"ltp":0.0,"tv":0.0,"id":5858055},{"batb":[[0,1.91,61.66],[1,1.82,18.8],[2,1.01,15.51]],"batl":[[0,2.14,36.13],[1,2.7,245.56]],"ltp":0.0,"tv":0.0,"id":7444998}]}]}
{"op":"mcm","clk":"1004238053","pt":1580654061407,"mc":[{"id":"1.168224477","rc":[{"batb":[[0,1.92,15.97],[1,1.9,46.21],[2,1.01,15.51]],"ltp":0.0,"tv":0.0,"id":5858055},{"batb":[[0,1.91,45.37]],"ltp":0.0,"tv":0.0,"id":7444998}]}]}
{"op":"mcm","clk":"1004238126","pt":1580654061785,"mc":[{"id":"1.168224477","rc":[{"batb":[[1,1.01,15.51],[2,1.01,0]],"batl":[[0,2.4,289.78],[1,2.4,0]],"ltp":0.0,"tv":0.0,"id":5858055},{"batb":[[0,1.82,18.8],[1,1.01,15.51],[2,1.01,0]],"batl":[[0,2.7,245.56],[1,2.7,0]],"ltp":0.0,"tv":0.0,"id":7444998}]}]}
{"op":"mcm","clk":"1004245491","pt":1580654097434,"mc":[{"id":"1.168224477","rc":[{"batb":[[0,2.06,25.65],[1,2.02,41.17],[2,2,28.25]],"batl":[[0,2.26,32.77]],"ltp":0.0,"tv":0.0,"id":5858055},{"batb":[[1,1.81,51.25],[2,1.78,20.22]],"batl":[[0,1.99,42.01]],"ltp":0.0,"tv":0.0,"id":7444998}]}]}
{"op":"mcm","clk":"1004246106","pt":1580654100267,"mc":[{"id":"1.168224477","rc":[{"batl":[[1,2.7,245.56]],"ltp":0.0,"tv":0.0,"id":5858055},{"batl":[[1,2.52,270.1]],"ltp":0.0,"tv":0.0,"id":7444998}]}]}
{"op":"mcm","clk":"1004246526","pt":1580654102234,"mc":[{"id":"1.168224477","rc":[{"batb":[[2,2,28.09]],"ltp":0.0,"tv":0.0,"id":5858055}]}]}
{"op":"mcm","clk":"1004267396","pt":1580654202783,"mc":[{"id":"1.168224477","rc":[{"batb":[[0,2.02,41.17],[1,2,28.09],[2,1.01,15.51]],"ltp":0.0,"tv":0.0,"id":5858055},{"batb":[[0,1.81,51.25],[1,1.78,20.22],[2,1.01,15.51]],"ltp":0.0,"tv":0.0,"id":7444998}]}]}
{"op":"mcm","clk":"1004267626","pt":1580654203824,"mc":[{"id":"1.168224477","rc":[{"batb":[[0,2,28.09],[1,1.01,15.51],[2,1.01,0]],"batl":[[0,2.7,245.56],[1,2.7,0]],"ltp":0.0,"tv":0.0,"id":5858055},{"batb":[[0,1.78,20.22],[1,1.01,15.51],[2,1.01,0]],"batl":[[0,2.52,270.1],[1,2.52,0]],"ltp":0.0,"tv":0.0,"id":7444998}]}]}
{"op":"mcm","clk":"1004270176","pt":1580654215408,"mc":[{"id":"1.168224477","rc":[{"batb":[[1,1.98,42.85],[2,1.94,15.58]],"batl":[[0,2.2,34.45],[1,2.7,245.56]],"ltp":0.0,"tv":0.0,"id":5858055},{"batb":[[0,1.87,17.23],[1,1.84,67.98],[2,1.78,20.22]],"batl":[[0,2.04,40.33],[1,2.52,270.1]],"ltp":0.0,"tv":0.0,"id":7444998}]}]}
{"op":"mcm","clk":"1004270200","pt":1580654215520,"mc":[{"id":"1.168224477","rc":[{"batb":[[2,1.01,15.51]],"ltp":0.0,"tv":0.0,"id":7444998}]}]}
{"op":"mcm","clk":"1004272420","pt":1580654225948,"mc":[{"id":"1.168224477","rc":[{"batb":[[0,1.94,15.58],[1,1.01,15.51],[2,1.94,0]],"batl":[[0,2.7,245.56],[1,2.7,0]],"ltp":0.0,"tv":0.0,"id":5858055},{"batb":[[0,1.84,18.41],[1,1.01,15.51],[2,1.01,0]],"batl":[[0,2.52,270.1],[1,2.52,0]],"ltp":0.0,"tv":0.0,"id":7444998}]}]}
{"op":"mcm","clk":"1004272985","pt":1580654228862,"mc":[{"id":"1.168224477","rc":[{"batb":[[0,1.83,18.49]],"ltp":0.0,"tv":0.0,"id":7444998}]}]}
{"op":"mcm","clk":"1004274541","pt":1580654236414,"mc":[{"id":"1.168224477","rc":[{"batb":[[1,1.88,17.23],[2,1.01,15.51]],"ltp":0.0,"tv":0.0,"id":5858055},{"batb":[[0,1.93,15.66],[1,1.89,16.92],[2,1.84,245.72]],"ltp":0.0,"tv":0.0,"id":7444998}]}]}
{"op":"mcm","clk":"1004274625","pt":1580654236855,"mc":[{"id":"1.168224477","rc":[{"batb":[[2,1.88,47.05]],"batl":[[0,2.08,38.65],[1,2.52,270.1]],"ltp":0.0,"tv":0.0,"id":7444998}]}]}
{"op":"mcm","clk":"1004275093","pt":1580654239263,"mc":[{"id":"1.168224477","rc":[{"batl":[[0,2.14,36.13],[1,2.7,245.56]],"ltp":0.0,"tv":0.0,"id":5858055}]}]}
{"op":"mcm","clk":"1004275217","pt":1580654239862,"mc":[{"id":"1.168224477","rc":[{"batb":[[1,1.93,44.53],[2,1.88,17.23]],"ltp":0.0,"tv":0.0,"id":5858055}]}]}
{"op":"mcm","clk":"1004276561","pt":1580654246040,"mc":[{"id":"1.168224477","rc":[{"batb":[[0,1.88,17.23],[1,1.01,15.51],[2,1.88,0]],"batl":[[0,2.7,245.56],[1,2.7,0]],"ltp":0.0,"tv":0.0,"id":5858055},{"batb":[[0,1.89,16.92],[1,1.01,15.51],[2,1.88,0]],"batl":[[0,2.52,270.1],[1,2.52,0]],"ltp":0.0,"tv":0.0,"id":7444998}]}]}
{"op":"mcm","clk":"1004278545","pt":1580654255380,"mc":[{"id":"1.168224477","rc":[{"batb":[[0,1.99,28.72],[1,1.92,15.97],[2,1.88,17.23]],"ltp":0.0,"tv":0.0,"id":5858055},{"batb":[[1,1.85,17.94],[2,1.01,15.51]],"ltp":0.0,"tv":0.0,"id":7444998}]}]}
{"op":"mcm","clk":"1004278612","pt":1580654255677,"mc":[{"id":"1.168224477","rc":[{"batb":[[2,1.01,15.51]],"ltp":0.0,"tv":0.0,"id":5858055}]}]}
{"op":"mcm","clk":"1004278919","pt":1580654257193,"mc":[{"id":"1.168224477","rc":[{"batb":[[1,1.95,43.69],[2,1.92,15.97]],"batl":[[0,2.16,36.13],[1,2.7,245.56]],"ltp":0.0,"tv":0.0,"id":5858055},{"batb":[[1,1.87,47.89],[2,1.85,17.94]],"batl":[[0,2.08,38.65],[1,2.52,270.1]],"ltp":0.0,"tv":0.0,"id":7444998}]}]}
{"op":"mcm","clk":"1004280817","pt":1580654266178,"mc":[{"id":"1.168224477","rc":[{"batb":[[0,1.95,43.69],[1,1.92,15.97],[2,1.01,15.51]],"ltp":0.0,"tv":0.0,"id":5858055},{"batb":[[0,1.87,47.89],[1,1.85,17.94],[2,1.01,15.51]],"ltp":0.0,"tv":0.0,"id":7444998}]}]}
{"op":"mcm","clk":"1004281265","pt":1580654268372,"mc":[{"id":"1.168224477","rc":[{"batb":[[0,1.92,15.97],[1,1.01,15.51],[2,1.01,0]],"batl":[[0,2.7,245.56],[1,2.7,0]],"ltp":0.0,"tv":0.0,"id":5858055},{"batb":[[0,1.85,17.94],[1,1.01,15.51],[2,1.01,0]],"batl":[[0,2.52,270.1],[1,2.52,0]],"ltp":0.0,"tv":0.0,"id":7444998}]}]}
{"op":"mcm","clk":"1004285022","pt":1580654286448,"mc":[{"id":"1.168224477","rc":[{"batb":[[0,2.02,26.91],[1,1.95,30.29],[2,1.92,15.97]],"ltp":0.0,"tv":0.0,"id":5858055},{"batb":[[1,1.81,19.36],[2,1.01,15.51]],"ltp":0.0,"tv":0.0,"id":7444998}]}]}
{"op":"mcm","clk":"1004285180","pt":1580654287141,"mc":[{"id":"1.168224477","rc":[{"batb":[[1,1.96,43.69],[2,1.95,30.29]],"batl":[[0,2.18,35.29],[1,2.7,245.56]],"ltp":0.0,"tv":0.0,"id":5858055},{"batb":[[0,1.85,66.67]],"batl":[[0,2.04,40.33],[1,2.52,270.1]],"ltp":0.0,"tv":0.0,"id":7444998}]}]}
{"op":"mcm","clk":"1004287850","pt":1580654300251,"mc":[{"id":"1.168224477","rc":[{"batb":[[0,1.95,30.29],[1,1.01,15.51],[2,1.95,0]],"batl":[[0,2.7,245.56],[1,2.7,0]],"ltp":0.0,"tv":0.0,"id":5858055},{"batb":[[0,1.81,19.36],[1,1.01,15.51],[2,1.01,0]],"batl":[[0,2.52,270.1],[1,2.52,0]],"ltp":0.0,"tv":0.0,"id":7444998}]}]}
{"op":"mcm","clk":"1004289315","pt":1580654307862,"mc":[{"id":"1.168224477","rc":[{"batb":[[0,2.08,24.94],[1,2.02,27.38],[2,1.01,15.51]],"ltp":0.0,"tv":0.0,"id":5858055},{"batb":[[1,1.78,20.38],[2,1.01,15.51]],"ltp":0.0,"tv":0.0,"id":7444998}]}]}
{"op":"mcm","clk":"1004289479","pt":1580654308712,"mc":[{"id":"1.168224477","rc":[{"batb":[[2,1.99,42.01]],"batl":[[0,2.22,33.61],[1,2.7,245.56]],"ltp":0.0,"tv":0.0,"id":5858055},{"batb":[[0,1.82,50.41],[1,1.81,19.36],[2,1.78,20.38]],"batl":[[0,2.02,41.17],[1,2.52,270.1]],"ltp":0.0,"tv":0.0,"id":7444998}]}]}
{"op":"mcm","clk":"1004290948","pt":1580654316073,"mc":[{"id":"1.168224477","rc":[{"batb":[[0,2.02,27.38],[1,1.01,15.51],[2,1.99,0]],"batl":[[0,2.7,245.56],[1,2.7,0]],"ltp":0.0,"tv":0.0,"id":5858055},{"batb":[[0,1.78,20.38],[1,1.01,15.51],[2,1.78,0]],"batl":[[0,2.52,270.1],[1,2.52,0]],"ltp":0.0,"tv":0.0,"id":7444998}]}]}
{"op":"mcm","clk":"1004292419","pt":1580654323680,"mc":[{"id":"1.168224477","rc":[{"batb":[[0,2.12,23.6],[1,2.08,25.02],[2,1.01,15.51]],"ltp":0.0,"tv":0.0,"id":5858055},{"batb":[[1,1.73,22.42],[2,1.01,15.51]],"ltp":0.0,"tv":0.0,"id":7444998}]}]}
{"op":"mcm","clk":"1004292573","pt":1580654324548,"mc":[{"id":"1.168224477","rc":[{"batb":[[2,2.02,41.17]],"batl":[[0,2.26,32.77],[1,2.7,245.56]],"ltp":0.0,"tv":0.0,"id":5858055},{"batb":[[0,1.79,52.93],[1,1.78,20.38],[2,1.73,22.42]],"batl":[[0,1.99,42.01]],"ltp":0.0,"tv":0.0,"id":7444998}]}]}
{"op":"mcm","clk":"1004292842","pt":1580654325962,"mc":[{"id":"1.168224477","rc":[{"batl":[[1,2.4,289.78]],"ltp":0.0,"tv":0.0,"id":7444998}]}]}
{"op":"mcm","clk":"1004297959","pt":1580654351899,"mc":[{"id":"1.168224477","rc":[{"batb":[[0,2.08,25.02],[1,1.01,15.51],[2,2.02,0]],"batl":[[0,2.7,245.56],[1,2.7,0]],"ltp":0.0,"tv":0.0,"id":5858055},{"batb":[[0,1.73,22.42],[1,1.01,15.51],[2,1.73,0]],"batl":[[0,2.4,289.78],[1,2.4,0]],"ltp":0.0,"tv":0.0,"id":7444998}]}]}
{"op":"mcm","clk":"1004301307","pt":1580654367838,"mc":[{"id":"1.168224477","rc":[{"batb":[[1,2.04,26.44],[2,1.01,15.51]],"ltp":0.0,"tv":0.0,"id":5858055},{"batb":[[0,1.81,19.28],[1,1.76,21.17],[2,1.01,15.51]],"ltp":0.0,"tv":0.0,"id":7444998}]}]}
{"op":"mcm","clk":"1004301621","pt":1580654369430,"mc":[{"id":"1.168224477","rc":[{"batb":[[2,2,42.01]],"batl":[[0,2.24,33.61],[1,2.7,245.56]],"ltp":0.0,"tv":0.0,"id":5858055},{"batb":[[0,1.81,70.53]],"batl":[[0,2,42.01],[1,2.4,289.78]],"ltp":0.0,"tv":0.0,"id":7444998}]}]}
{"op":"mcm","clk":"1004304291","pt":1580654382143,"mc":[{"id":"1.168224477","rc":[{"batb":[[0,2.04,26.44],[1,1.01,15.51],[2,2,0]],"batl":[[0,2.7,245.56],[1,2.7,0]],"ltp":0.0,"tv":0.0,"id":5858055},{"batb":[[0,1.76,21.17],[1,1.01,15.51],[2,1.01,0]],"batl":[[0,2.4,289.78],[1,2.4,0]],"ltp":0.0,"tv":0.0,"id":7444998}]}]}
{"op":"mcm","clk":"1004311452","pt":1580654416987,"mc":[{"id":"1.168224477","rc":[{"batb":[[1,2,27.77],[2,1.01,15.51]],"ltp":0.0,"tv":0.0,"id":5858055},{"batb":[[0,1.84,18.33],[1,1.79,19.91],[2,1.01,15.51]],"ltp":0.0,"tv":0.0,"id":7444998}]}]}
{"op":"mcm","clk":"1004311834","pt":1580654418832,"mc":[{"id":"1.168224477","rc":[{"batb":[[2,1.99,42.01]],"batl":[[0,2.2,34.45],[1,2.7,245.56]],"ltp":0.0,"tv":0.0,"id":5858055},{"batb":[[1,1.83,50.41],[2,1.79,19.91]],"batl":[[0,2.04,40.33],[1,2.4,289.78]],"ltp":0.0,"tv":0.0,"id":7444998}]}]}
{"op":"mcm","clk":"1004314721","pt":1580654433351,"mc":[{"id":"1.168224477","rc":[{"batb":[[0,2,27.77],[1,1.99,42.01],[2,1.01,15.51]],"ltp":0.0,"tv":0.0,"id":5858055},{"batb":[[0,1.83,50.41],[1,1.79,19.91],[2,1.01,15.51]],"ltp":0.0,"tv":0.0,"id":7444998}]}]}
{"op":"mcm","clk":"1004314824","pt":1580654433846,"mc":[{"id":"1.168224477","rc":[{"batb":[[1,1.01,15.51],[2,1.01,0]],"batl":[[0,2.7,245.56],[1,2.7,0]],"ltp":0.0,"tv":0.0,"id":5858055},{"batb":[[0,1.79,19.91],[1,1.01,15.51],[2,1.01,0]],"batl":[[0,2.4,289.78],[1,2.4,0]],"ltp":0.0,"tv":0.0,"id":7444998}]}]}
{"op":"mcm","clk":"1004316563","pt":1580654442071,"mc":[{"id":"1.168224477","rc":[{"batb":[[1,1.98,29.11],[2,1.01,15.51]],"ltp":0.0,"tv":0.0,"id":5858055},{"batb":[[0,1.87,17.47],[1,1.82,18.88],[2,1.01,15.51]],"ltp":0.0,"tv":0.0,"id":7444998}]}]}
{"op":"mcm","clk":"1004316775","pt":1580654443032,"mc":[{"id":"1.168224477","rc":[{"batb":[[2,1.96,43.69]],"batl":[[0,2.18,35.29],[1,2.7,245.56]],"ltp":0.0,"tv":0.0,"id":5858055},{"batb":[[1,1.85,48.73],[2,1.82,18.88]],"batl":[[0,2.06,39.49],[1,2.4,289.78]],"ltp":0.0,"tv":0.0,"id":7444998}]}]}
{"op":"mcm","clk":"1004319360","pt":1580654455118,"mc":[{"id":"1.168224477","rc":[{"batb":[[0,1.98,29.11],[1,1.96,43.69],[2,1.01,15.51]],"ltp":0.0,"tv":0.0,"id":5858055},{"batb":[[0,1.85,48.73],[1,1.82,18.88],[2,1.01,15.51]],"ltp":0.0,"tv":0.0,"id":7444998}]}]}
{"op":"mcm","clk":"1004319617","pt":1580654456239,"mc":[{"id":"1.168224477","rc":[{"batb":[[1,1.01,15.51],[2,1.01,0]],"batl":[[0,2.7,245.56],[1,2.7,0]],"ltp":0.0,"tv":0.0,"id":5858055},{"batb":[[0,1.82,18.88],[1,1.01,15.51],[2,1.01,0]],"batl":[[0,2.4,289.78],[1,2.4,0]],"ltp":0.0,"tv":0.0,"id":7444998}]}]}
{"op":"mcm","clk":"1004321091","pt":1580654463329,"mc":[{"id":"1.168224477","rc":[{"batb":[[1,1.92,16.05],[2,1.01,15.51]],"ltp":0.0,"tv":0.0,"id":5858055},{"batb":[[0,1.9,16.68],[1,1.86,17.55],[2,1.82,18.88]],"ltp":0.0,"tv":0.0,"id":7444998}]}]}
{"op":"mcm","clk":"1004321137","pt":1580654463544,"mc":[{"id":"1.168224477","rc":[{"batb":[[2,1.01,15.51]],"ltp":0.0,"tv":0.0,"id":7444998}]}]}
{"op":"mcm","clk":"1004321358","pt":1580654464633,"mc":[{"id":"1.168224477","rc":[{"batb":[[1,1.92,61.42]],"batl":[[0,2.12,36.97],[1,2.7,245.56]],"ltp":0.0,"tv":0.0,"id":5858055},{"batb":[[1,1.89,47.05],[2,1.86,17.55]],"batl":[[0,2.1,37.81],[1,2.4,289.78]],"ltp":0.0,"tv":0.0,"id":7444998}]}]}
{"op":"mcm","clk":"1004322914","pt":1580654471751,"mc":[{"id":"1.168224477","rc":[{"batb":[[0,1.98,28.95],[1,1.92,61.26]],"ltp":0.0,"tv":0.0,"id":5858055},{"batb":[[0,1.89,63.81],[1,1.86,17.55],[2,1.01,15.51]],"ltp":0.0,"tv":0.0,"id":7444998}]}]}
{"op":"mcm","clk":"1004324606","pt":1580654479682,"mc":[{"id":"1.168224477","rc":[{"batb":[[0,1.99,28.72],[1,1.93,15.82],[2,1.92,45.37]],"ltp":0.0,"tv":0.0,"id":5858055}]}]}
{"op":"mcm","clk":"1004337320","pt":1580654539752,"mc":[{"id":"1.168224477","rc":[{"batb":[[0,1.93,15.82],[1,1.92,45.37],[2,1.01,15.51]],"ltp":0.0,"tv":0.0,"id":5858055},{"batb":[[0,1.89,47.05]],"ltp":0.0,"tv":0.0,"id":7444998}]}]}
{"op":"mcm","clk":"1004337793","pt":1580654541690,"mc":[{"id":"1.168224477","rc":[{"batb":[[1,1.01,15.51],[2,1.01,0]],"batl":[[0,2.7,245.56],[1,2.7,0]],"ltp":0.0,"tv":0.0,"id":5858055},{"batb":[[0,1.86,17.55],[1,1.01,15.51],[2,1.01,0]],"batl":[[0,2.4,289.78],[1,2.4,0]],"ltp":0.0,"tv":0.0,"id":7444998}]}]}
{"op":"mcm","clk":"1004341304","pt":1580654557340,"mc":[{"id":"1.168224477","rc":[{"batb":[[0,2.02,27.22],[1,1.96,223.78],[2,1.95,43.69]],"batl":[[0,2.16,36.13],[1,2.7,245.56]],"ltp":0.0,"tv":0.0,"id":5858055},{"batb":[[0,1.86,66.28],[1,1.83,18.73],[2,1.01,15.51]],"batl":[[0,2.08,38.65],[1,2.4,289.78]],"ltp":0.0,"tv":0.0,"id":7444998}]}]}
{"op":"mcm","clk":"1004341451","pt":1580654557943,"mc":[{"id":"1.168224477","rc":[{"batb":[[1,1.96,29.9]],"ltp":0.0,"tv":0.0,"id":5858055}]}]}
{"op":"mcm","clk":"1004343424","pt":1580654566630,"mc":[{"id":"1.168224477","rc":[{"batb":[[0,1.96,29.9],[1,1.95,43.69],[2,1.01,15.51]],"ltp":0.0,"tv":0.0,"id":5858055},{"batb":[[0,1.86,48.73]],"ltp":0.0,"tv":0.0,"id":7444998}]}]}
{"op":"mcm","clk":"1004343687","pt":1580654567744,"mc":[{"id":"1.168224477","rc":[{"batb":[[1,1.01,15.51],[2,1.01,0]],"batl":[[0,2.7,245.56],[1,2.7,0]],"ltp":0.0,"tv":0.0,"id":5858055},{"batb":[[0,1.83,18.73],[1,1.01,15.51],[2,1.01,0]],"batl":[[0,2.4,289.78],[1,2.4,0]],"ltp":0.0,"tv":0.0,"id":7444998}]}]}
{"op":"mcm","clk":"1004345419","pt":1580654575259,"mc":[{"id":"1.168224477","rc":[{"batb":[[0,2.06,25.73],[1,2,28.25],[2,1.97,42.85]],"batl":[[0,2.18,35.29],[1,2.7,245.56]],"ltp":0.0,"tv":0.0,"id":5858055},{"batb":[[0,1.84,49.57],[1,1.83,18.73],[2,1.79,19.83]],"batl":[[0,2.04,40.33],[1,2.4,289.78]],"ltp":0.0,"tv":0.0,"id":7444998}]}]}
{"op":"mcm","clk":"1004347590","pt":1580654584183,"mc":[{"id":"1.168224477","rc":[{"batb":[[0,2,28.25],[1,1.97,42.85],[2,1.01,15.51]],"ltp":0.0,"tv":0.0,"id":5858055},{"batb":[[1,1.79,19.83],[2,1.01,15.51]],"ltp":0.0,"tv":0.0,"id":7444998}]}]}
{"op":"mcm","clk":"1004347976","pt":1580654585752,"mc":[{"id":"1.168224477","rc":[{"batb":[[1,1.01,15.51],[2,1.01,0]],"batl":[[0,2.7,245.56],[1,2.7,0]],"ltp":0.0,"tv":0.0,"id":5858055},{"batb":[[0,1.79,19.83],[1,1.01,15.51],[2,1.01,0]],"batl":[[0,2.4,289.78],[1,2.4,0]],"ltp":0.0,"tv":0.0,"id":7444998}]}]}
{"op":"mcm","clk":"1004352579","pt":1580654606301,"mc":[{"id":"1.168224477","rc":[{"batb":[[0,2.1,24.31],[1,2.02,26.83],[2,2,28.25]],"ltp":0.0,"tv":0.0,"id":5858055},{"batb":[[1,1.77,20.77],[2,1.01,15.51]],"ltp":0.0,"tv":0.0,"id":7444998}]}]}
{"op":"mcm","clk":"1004352689","pt":1580654606790,"mc":[{"id":"1.168224477","rc":[{"batb":[[2,2,42.01]],"batl":[[0,2.22,33.61],[1,2.7,245.56]],"ltp":0.0,"tv":0.0,"id":5858055},{"batb":[[0,1.82,50.41],[1,1.79,19.83],[2,1.77,20.77]],"batl":[[0,2.02,41.17],[1,2.4,289.78]],"ltp":0.0,"tv":0.0,"id":7444998}]}]}
{"op":"mcm","clk":"1004355108","pt":1580654617168,"mc":[{"id":"1.168224477","rc":[{"batb":[[0,2.02,26.83],[1,2,42.01],[2,1.01,15.51]],"ltp":0.0,"tv":0.0,"id":5858055},{"batb":[[1,1.77,20.77],[2,1.01,15.51]],"ltp":0.0,"tv":0.0,"id":7444998}]}]}
{"op":"mcm","clk":"1004355328","pt":1580654618188,"mc":[{"id":"1.168224477","rc":[{"batb":[[1,1.01,15.51],[2,1.01,0]],"batl":[[0,2.7,245.56],[1,2.7,0]],"ltp":0.0,"tv":0.0,"id":5858055},{"batb":[[0,1.77,20.77],[1,1.01,15.51],[2,1.01,0]],"batl":[[0,2.4,289.78],[1,2.4,0]],"ltp":0.0,"tv":0.0,"id":7444998}]}]}
{"op":"mcm","clk":"1004357579","pt":1580654628373,"mc":[{"id":"1.168224477","rc":[{"batb":[[0,2.14,23.13],[1,2.1,24.55],[2,2.02,26.83]],"ltp":0.0,"tv":0.0,"id":5858055},{"batb":[[1,1.72,22.82],[2,1.01,15.51]],"ltp":0.0,"tv":0.0,"id":7444998}]}]}
{"op":"mcm","clk":"1004357649","pt":1580654628690,"mc":[{"id":"1.168224477","rc":[{"batb":[[2,2.04,40.33]],"batl":[[0,2.28,32.77],[1,2.7,245.56]],"ltp":0.0,"tv":0.0,"id":5858055},{"batb":[[0,1.78,53.77],[1,1.77,20.77],[2,1.72,22.82]],"batl":[[0,1.98,42.01],[1,2.4,289.78]],"ltp":0.0,"tv":0.0,"id":7444998}]}]}
{"op":"mcm","clk":"1004364864","pt":1580654661435,"mc":[{"id":"1.168224477","rc":[{"batb":[[0,2.1,24.55],[1,2.04,40.33],[2,1.01,15.51]],"ltp":0.0,"tv":0.0,"id":5858055},{"batb":[[1,1.72,22.82],[2,1.01,15.51]],"ltp":0.0,"tv":0.0,"id":7444998}]}]}
{"op":"mcm","clk":"1004364958","pt":1580654661873,"mc":[{"id":"1.168224477","rc":[{"batb":[[1,1.01,15.51],[2,1.01,0]],"batl":[[0,2.7,245.56],[1,2.7,0]],"ltp":0.0,"tv":0.0,"id":5858055},{"batb":[[0,1.72,22.82],[1,1.01,15.51],[2,1.01,0]],"batl":[[0,2.4,289.78],[1,2.4,0]],"ltp":0.0,"tv":0.0,"id":7444998}]}]}
{"op":"mcm","clk":"1004365421","pt":1580654664014,"mc":[{"id":"1.168224477","rc":[{"batb":[[0,2.08,24.71]],"ltp":0.0,"tv":0.0,"id":5858055}]}]}
{"op":"mcm","clk":"1004371077","pt":1580654690090,"mc":[{"id":"1.168224477","rc":[{"batb":[[1,2.04,26.2],[2,1.01,15.51]],"ltp":0.0,"tv":0.0,"id":5858055},{"batb":[[0,1.8,19.51],[1,1.75,21.48],[2,1.01,15.51]],"ltp":0.0,"tv":0.0,"id":7444998}]}]}
{"op":"mcm","clk":"1004371283","pt":1580654690982,"mc":[{"id":"1.168224477","rc":[{"batl":[[0,2.24,33.61],[1,2.7,245.56]],"ltp":0.0,"tv":0.0,"id":5858055},{"batb":[[0,1.8,71.61]],"batl":[[0,2,42.01],[1,2.4,289.78]],"ltp":0.0,"tv":0.0,"id":7444998}]}]}
{"op":"mcm","clk":"1004371559","pt":1580654692313,"mc":[{"id":"1.168224477","rc":[{"batb":[[2,2,42.01]],"ltp":0.0,"tv":0.0,"id":5858055}]}]}
{"op":"mcm","clk":"1004373799","pt":1580654702810,"mc":[{"id":"1.168224477","rc":[{"batb":[[0,2.04,26.2],[1,2,42.01],[2,1.01,15.51]],"ltp":0.0,"tv":0.0,"id":5858055},{"batb":[[0,1.8,52.09]],"ltp":0.0,"tv":0.0,"id":7444998}]}]}
{"op":"mcm","clk":"1004374020","pt":1580654703844,"mc":[{"id":"1.168224477","rc":[{"batb":[[1,1.01,15.51],[2,1.01,0]],"batl":[[0,2.7,245.56],[1,2.7,0]],"ltp":0.0,"tv":0.0,"id":5858055},{"batb":[[0,1.75,21.48],[1,1.01,15.51],[2,1.01,0]],"batl":[[0,2.4,289.78],[1,2.4,0]],"ltp":0.0,"tv":0.0,"id":7444998}]}]}
{"op":"mcm","clk":"1004378683","pt":1580654724348,"mc":[{"id":"1.168224477","rc":[{"batb":[[1,2,27.77],[2,1.01,15.51]],"ltp":0.0,"tv":0.0,"id":5858055},{"batb":[[0,1.83,18.49],[1,1.78,20.38],[2,1.75,21.48]],"ltp":0.0,"tv":0.0,"id":7444998}]}]}
{"op":"mcm","clk":"1004378769","pt":1580654724769,"mc":[{"id":"1.168224477","rc":[{"batb":[[2,1.99,42.01]],"batl":[[0,2.22,33.61],[1,2.7,245.56]],"ltp":0.0,"tv":0.0,"id":5858055},{"batb":[[1,1.82,50.41],[2,1.78,20.38]],"batl":[[0,2.02,41.17],[1,2.4,289.78]],"ltp":0.0,"tv":0.0,"id":7444998}]}]}
{"op":"mcm","clk":"1004380980","pt":1580654735065,"mc":[{"id":"1.168224477","rc":[{"batb":[[0,2,27.77],[1,1.99,42.01],[2,1.01,15.51]],"ltp":0.0,"tv":0.0,"id":5858055},{"batb":[[0,1.82,50.41],[1,1.78,20.38],[2,1.01,15.51]],"ltp":0.0,"tv":0.0,"id":7444998}]}]}
{"op":"mcm","clk":"1004381122","pt":1580654735784,"mc":[{"id":"1.168224477","rc":[{"batb":[[1,1.01,15.51],[2,1.01,0]],"batl":[[0,2.7,245.56],[1,2.7,0]],"ltp":0.0,"tv":0.0,"id":5858055},{"batb":[[0,1.78,20.38],[1,1.01,15.51],[2,1.01,0]],"batl":[[0,2.4,289.78],[1,2.4,0]],"ltp":0.0,"tv":0.0,"id":7444998}]}]}
{"op":"mcm","clk":"1004386301","pt":1580654759916,"mc":[{"id":"1.168224477","rc":[{"batb":[[0,2.12,23.68],[1,2.08,25.02],[2,1.01,15.51]],"ltp":0.0,"tv":0.0,"id":5858055},{"batb":[[1,1.72,22.82],[2,1.01,15.51]],"ltp":0.0,"tv":0.0,"id":7444998}]}]}
{"op":"mcm","clk":"1004386494","pt":1580654760823,"mc":[{"id":"1.168224477","rc":[{"batb":[[2,2.04,40.33]],"batl":[[0,2.26,32.77],[1,2.7,245.56]],"ltp":0.0,"tv":0.0,"id":5858055},{"batb":[[0,1.79,52.93],[1,1.78,20.38],[2,1.72,22.82]],"batl":[[0,1.98,42.01],[1,2.4,289.78]],"ltp":0.0,"tv":0.0,"id":7444998}]}]}
{"op":"mcm","clk":"1004389727","pt":1580654775737,"mc":[{"id":"1.168224477","rc":[{"batb":[[0,2.08,25.02],[1,1.01,15.51],[2,2.04,0]],"batl":[[0,2.7,245.56],[1,2.7,0]],"ltp":0.0,"tv":0.0,"id":5858055},{"batb":[[0,1.72,22.82],[1,1.01,15.51],[2,1.72,0]],"batl":[[0,2.4,289.78],[1,2.4,0]],"ltp":0.0,"tv":0.0,"id":7444998}]}]}
{"op":"mcm","clk":"1004392049","pt":1580654786073,"mc":[{"id":"1.168224477","rc":[{"batb":[[1,2.04,26.67],[2,1.01,15.51]],"ltp":0.0,"tv":0.0,"id":5858055},{"batb":[[0,1.81,19.28],[1,1.75,21.4],[2,1.01,15.51]],"ltp":0.0,"tv":0.0,"id":7444998}]}]}
{"op":"mcm","clk":"1004392189","pt":1580654786770,"mc":[{"id":"1.168224477","rc":[{"batb":[[2,2,42.01]],"batl":[[0,2.24,33.61],[1,2.7,245.56]],"ltp":0.0,"tv":0.0,"id":5858055},{"batb":[[1,1.8,52.09],[2,1.75,21.4]],"batl":[[0,2,42.01],[1,2.4,289.78]],"ltp":0.0,"tv":0.0,"id":7444998}]}]}
{"op":"mcm","clk":"1004394430","pt":1580654797317,"mc":[{"id":"1.168224477","rc":[{"batb":[[0,2.04,26.67],[1,2,42.01],[2,1.01,15.51]],"ltp":0.0,"tv":0.0,"id":5858055},{"batb":[[0,1.8,52.09],[1,1.75,21.4],[2,1.01,15.51]],"ltp":0.0,"tv":0.0,"id":7444998}]}]}
{"op":"mcm","clk":"1004394534","pt":1580654797795,"mc":[{"id":"1.168224477","rc":[{"batb":[[1,1.01,15.51],[2,1.01,0]],"batl":[[0,2.7,245.56],[1,2.7,0]],"ltp":0.0,"tv":0.0,"id":5858055},{"batb":[[0,1.75,21.4],[1,1.01,15.51],[2,1.01,0]],"batl":[[0,2.4,289.78],[1,2.4,0]],"ltp":0.0,"tv":0.0,"id":7444998}]}]}
{"op":"mcm","clk":"1004396666","pt":1580654808118,"mc":[{"id":"1.168224477","rc":[{"batb":[[1,1.97,29.43],[2,1.01,15.51]],"ltp":0.0,"tv":0.0,"id":5858055},{"batb":[[0,1.85,18.1],[1,1.81,19.28],[2,1.01,15.51]],"ltp":0.0,"tv":0.0,"id":7444998}]}]}
{"op":"mcm","clk":"1004396794","pt":1580654808710,"mc":[{"id":"1.168224477","rc":[{"batb":[[1,1.97,72.28]],"batl":[[0,2.18,35.29],[1,2.7,245.56]],"ltp":0.0,"tv":0.0,"id":5858055},{"batb":[[1,1.84,49.57],[2,1.81,19.28]],"batl":[[0,2.04,40.33],[1,2.4,289.78]],"ltp":0.0,"tv":0.0,"id":7444998}]}]}
{"op":"mcm","clk":"1004411268","pt":1580654885743,"mc":[{"id":"1.168224477","rc":[{"batb":[[0,1.97,29.43],[1,1.01,15.51],[2,1.01,0]],"batl":[[0,2.7,245.56],[1,2.7,0]],"ltp":0.0,"tv":0.0,"id":5858055},{"batb":[[0,1.81,19.28],[1,1.01,15.51],[2,1.81,0]],"batl":[[0,2.4,289.78],[1,2.4,0]],"ltp":0.0,"tv":0.0,"id":7444998}]}]}
{"op":"mcm","clk":"1004412753","pt":1580654893843,"mc":[{"id":"1.168224477","rc":[{"batb":[[0,2.08,25.02],[1,2,28.17],[2,1.01,15.51]],"ltp":0.0,"tv":0.0,"id":5858055},{"batb":[[1,1.78,20.38],[2,1.01,15.51]],"ltp":0.0,"tv":0.0,"id":7444998}]}]}
{"op":"mcm","clk":"1004412920","pt":1580654894743,"mc":[{"id":"1.168224477","rc":[{"batb":[[2,1.99,42.01]],"batl":[[0,2.22,33.61],[1,2.7,245.56]],"ltp":0.0,"tv":0.0,"id":5858055},{"batb":[[0,1.82,50.41],[1,1.81,19.28],[2,1.78,20.38]],"batl":[[0,2.02,41.17],[1,2.4,289.78]],"ltp":0.0,"tv":0.0,"id":7444998}]}]}
{"op":"mcm","clk":"1004414620","pt":1580654903858,"mc":[{"id":"1.168224477","rc":[{"batb":[[0,2,28.17],[1,1.01,15.51],[2,1.99,0]],"batl":[[0,2.7,245.56],[1,2.7,0]],"ltp":0.0,"tv":0.0,"id":5858055},{"batb":[[0,1.78,20.38],[1,1.01,15.51],[2,1.78,0]],"batl":[[0,2.4,289.78],[1,2.4,0]],"ltp":0.0,"tv":0.0,"id":7444998}]}]}
{"op":"mcm","clk":"1004415943","pt":1580654911357,"mc":[{"id":"1.168224477","rc":[{"batb":[[0,2.12,23.6],[1,2.04,26.36],[2,2.02,41.17]],"batl":[[0,2.24,33.61],[1,2.7,245.56]],"ltp":0.0,"tv":0.0,"id":5858055},{"batb":[[0,1.8,52.09],[1,1.78,20.38],[2,1.75,21.64]],"batl":[[0,2,42.01],[1,2.4,289.78]],"ltp":0.0,"tv":0.0,"id":7444998}]}]}
{"op":"mcm","clk":"1004417325","pt":1580654919364,"mc":[{"id":"1.168224477","rc":[{"batl":[[0,2.7,245.56],[1,2.7,0]],"ltp":0.0,"tv":0.0,"id":5858055},{"batl":[[0,2.4,289.78],[1,2.4,0]],"ltp":0.0,"tv":0.0,"id":7444998}]}]}
{"op":"mcm","clk":"1004417428","pt":1580654920045,"mc":[{"id":"1.168224477","rc":[{"batb":[[0,2.04,26.36],[1,2.02,41.17],[2,1.01,15.51]],"ltp":0.0,"tv":0.0,"id":5858055},{"batb":[[1,1.75,21.64],[2,1.01,15.51]],"ltp":0.0,"tv":0.0,"id":7444998}]}]}
{"op":"mcm","clk":"1004417799","pt":1580654922370,"mc":[{"id":"1.168224477","rc":[{"batb":[[1,1.01,15.51],[2,1.01,0]],"ltp":0.0,"tv":0.0,"id":5858055},{"batb":[[0,1.75,21.64],[1,1.01,15.51],[2,1.01,0]],"ltp":0.0,"tv":0.0,"id":7444998}]}]}
{"op":"mcm","clk":"1004420499","pt":1580654939281,"mc":[{"id":"1.168224477","rc":[{"batb":[[0,2.06,144.91],[1,2.04,26.36],[2,1.01,15.51]],"ltp":0.0,"tv":0.0,"id":5858055}]}]}
{"op":"mcm","clk":"1004420592","pt":1580654939911,"mc":[{"id":"1.168224477","rc":[{"batb":[[0,2.16,22.11],[1,2.08,25.02]],"ltp":0.0,"tv":0.0,"id":5858055},{"batb":[[1,1.72,22.66],[2,1.01,15.51]],"ltp":0.0,"tv":0.0,"id":7444998}]}]}
{"op":"mcm","clk":"1004420808","pt":1580654941205,"mc":[{"id":"1.168224477","rc":[{"batb":[[2,2.06,39.49]],"batl":[[0,2.3,31.93],[1,2.7,245.56]],"ltp":0.0,"tv":0.0,"id":5858055},{"batb":[[0,1.77,53.77],[1,1.75,21.64],[2,1.72,22.66]],"batl":[[0,1.96,42.01],[1,2.4,289.78]],"ltp":0.0,"tv":0.0,"id":7444998}]}]}
{"op":"mcm","clk":"1004422073","pt":1580654948508,"mc":[{"id":"1.168224477","rc":[{"batb":[[0,2.08,25.02],[1,2.06,39.49],[2,1.01,15.51]],"ltp":0.0,"tv":0.0,"id":5858055},{"batb":[[1,1.72,22.66],[2,1.01,15.51]],"ltp":0.0,"tv":0.0,"id":7444998}]}]}
{"op":"mcm","clk":"1004422371","pt":1580654950313,"mc":[{"id":"1.168224477","rc":[{"batb":[[1,1.01,15.51],[2,1.01,0]],"batl":[[0,2.7,245.56],[1,2.7,0]],"ltp":0.0,"tv":0.0,"id":5858055},{"batb":[[0,1.72,22.66],[1,1.01,15.51],[2,1.01,0]],"batl":[[0,2.4,289.78],[1,2.4,0]],"ltp":0.0,"tv":0.0,"id":7444998}]}]}
{"op":"mcm","clk":"1004424979","pt":1580654968035,"mc":[{"id":"1.168224477","rc":[{"batb":[[1,2,27.85],[2,1.01,15.51]],"ltp":0.0,"tv":0.0,"id":5858055},{"batb":[[0,1.81,19.28],[1,1.78,20.54],[2,1.01,15.51]],"ltp":0.0,"tv":0.0,"id":7444998}]}]}
{"op":"mcm","clk":"1004425160","pt":1580654969138,"mc":[{"id":"1.168224477","rc":[{"batb":[[1,2.02,41.17],[2,2,27.85]],"ltp":0.0,"tv":0.0,"id":5858055},{"batl":[[0,1.99,42.01],[1,2.4,289.78]],"ltp":0.0,"tv":0.0,"id":7444998}]}]}
{"op":"mcm","clk":"1004425329","pt":1580654970322,"mc":[{"id":"1.168224477","rc":[{"batl":[[0,2.24,33.61],[1,2.7,245.56]],"ltp":0.0,"tv":0.0,"id":5858055},{"batb":[[1,1.8,52.09],[2,1.78,20.54]],"ltp":0.0,"tv":0.0,"id":7444998}]}]}
{"op":"mcm","clk":"1004427048","pt":1580654981316,"mc":[{"id":"1.168224477","rc":[{"batb":[[0,2.02,41.17],[1,2,27.85],[2,1.01,15.51]],"ltp":0.0,"tv":0.0,"id":5858055},{"batb":[[0,1.8,52.09],[1,1.78,20.54],[2,1.01,15.51]],"ltp":0.0,"tv":0.0,"id":7444998}]}]}
{"op":"mcm","clk":"1004427127","pt":1580654981845,"mc":[{"id":"1.168224477","rc":[{"batb":[[0,2,27.85],[1,1.01,15.51],[2,1.01,0]],"batl":[[0,2.7,245.56],[1,2.7,0]],"ltp":0.0,"tv":0.0,"id":5858055},{"batb":[[0,1.78,20.54],[1,1.01,15.51],[2,1.01,0]],"batl":[[0,2.4,289.78],[1,2.4,0]],"ltp":0.0,"tv":0.0,"id":7444998}]}]}
{"op":"mcm","clk":"1004428177","pt":1580654988766,"mc":[{"id":"1.168224477","rc":[{"batb":[[0,2.04,40.33],[1,2,27.85],[2,1.01,15.51]],"batl":[[0,2.28,32.77],[1,2.7,245.56]],"ltp":0.0,"tv":0.0,"id":5858055},{"batb":[[0,1.78,74.31],[1,1.76,73.27],[2,1.74,98.07]],"batl":[[0,1.83,63.94],[1,1.85,81.26],[2,1.98,42.01]],"ltp":0.0,"tv":0.0,"id":7444998}]}]}
{"op":"mcm","clk":"1004428367","pt":1580654989877,"mc":[{"id":"1.168224477","rc":[{"batb":[[0,2.12,23.45],[1,2.04,40.33],[2,1.99,28.56]],"ltp":0.0,"tv":0.0,"id":5858055}]}]}
{"op":"mcm","clk":"1004429782","pt":1580654998743,"mc":[{"id":"1.168224477","rc":[{"batb":[[1,1.62,28.01],[2,1.01,15.51]],"ltp":0.0,"tv":0.0,"id":7444998}]}]}
{"op":"mcm","clk":"1004430204","pt":1580655001494,"mc":[{"id":"1.168224477","rc":[{"batb":[[1,1.75,101.96],[2,1.73,100.18]],"batl":[[0,1.83,83.2]],"ltp":0.0,"tv":0.0,"id":7444998}]}]}
{"op":"mcm","clk":"1004431253","pt":1580655008388,"mc":[{"id":"1.168224477","rc":[{"batb":[[1,1.62,28.01],[2,1.01,15.51]],"ltp":0.0,"tv":0.0,"id":7444998}]}]}
{"op":"mcm","clk":"1004431583","pt":1580655010877,"mc":[{"id":"1.168224477","rc":[{"batb":[[1,1.76,56.35],[2,1.74,98.07]],"ltp":0.0,"tv":0.0,"id":7444998}]}]}
{"op":"mcm","clk":"1004432918","pt":1580655020496,"mc":[{"id":"1.168224477","rc":[{"batl":[[0,1.83,63.94]],"ltp":0.0,"tv":0.0,"id":7444998}]}]}
{"op":"mcm","clk":"1004433313","pt":1580655023387,"mc":[{"id":"1.168224477","rc":[{"batb":[[1,1.76,75.54]],"ltp":0.0,"tv":0.0,"id":7444998}]}]}
{"op":"mcm","clk":"1004434612","pt":1580655032740,"mc":[{"id":"1.168224477","rc":[{"batb":[[1,1.62,28.01],[2,1.01,15.51]],"batl":[[0,1.98,42.01],[1,2.4,289.78],[2,1.98,0]],"ltp":0.0,"tv":0.0,"id":7444998}]}]}
{"op":"mcm","clk":"1004435061","pt":1580655035896,"mc":[{"id":"1.168224477","rc":[{"batb":[[1,1.77,66.41],[2,1.75,96.08]],"ltp":0.0,"tv":0.0,"id":7444998}]}]}
{"op":"mcm","clk":"1004435523","pt":1580655038841,"mc":[{"id":"1.168224477","rc":[{"batb":[[1,1.77,83.08]],"batl":[[0,1.85,89.76],[1,1.87,78.39],[2,1.98,42.01]],"ltp":0.0,"tv":0.0,"id":7444998}]}]}
{"op":"mcm","clk":"1004443060","pt":1580655087163,"mc":[{"id":"1.168224477","rc":[{"batb":[[1,1.62,28.01],[2,1.01,15.51]],"batl":[[0,1.85,53.6]],"ltp":0.0,"tv":0.0,"id":7444998}]}]}
{"op":"mcm","clk":"1004443568","pt":1580655090448,"mc":[{"id":"1.168224477","rc":[{"batb":[[0,1.78,148.34],[1,1.76,94.15],[2,1.62,28.01]],"batl":[[0,1.98,42.01],[1,2.4,289.78],[2,1.98,0]],"ltp":0.0,"tv":0.0,"id":7444998}]}]}
{"op":"mcm","clk":"1004443967","pt":1580655093256,"mc":[{"id":"1.168224477","rc":[{"batb":[[0,1.78,158.28]],"batl":[[0,1.86,83.48],[1,1.88,77.01],[2,1.98,42.01]],"ltp":0.0,"tv":0.0,"id":7444998}]}]}
{"op":"mcm","clk":"1004446626","pt":1580655111436,"mc":[{"id":"1.168224477","rc":[{"batb":[[0,1.78,74.31],[1,1.62,28.01],[2,1.01,15.51]],"batl":[[0,1.98,42.01],[1,2.4,289.78],[2,1.98,0]],"ltp":0.0,"tv":0.0,"id":7444998}]}]}
{"op":"mcm","clk":"1004446704","pt":1580655111916,"mc":[{"id":"1.168224477","rc":[{"batb":[[0,1.99,28.56],[1,1.01,15.51],[2,1.99,0]],"batl":[[0,2.7,245.56],[1,2.7,0]],"ltp":0.0,"tv":0.0,"id":5858055},{"batb":[[0,1.62,28.01],[1,1.01,15.51],[2,1.01,0]],"batl":[[0,2.4,289.78],[1,2.4,0]],"ltp":0.0,"tv":0.0,"id":7444998}]}]}
{"op":"mcm","clk":"1004447116","pt":1580655114323,"mc":[{"id":"1.168224477","rc":[{"batb":[[0,1.63,63.54],[1,1.62,91.05],[2,1.01,15.51]],"batl":[[0,1.97,66.69],[1,1.99,64.94],[2,2.4,289.78]],"ltp":0.0,"tv":0.0,"id":7444998}]}]}
{"op":"mcm","clk":"1004447222","pt":1580655115150,"mc":[{"id":"1.168224477","rc":[{"batb":[[0,1.98,28.95]],"ltp":0.0,"tv":0.0,"id":5858055},{"batb":[[0,1.63,91.16],[1,1.62,63.04]],"ltp":0.0,"tv":0.0,"id":7444998}]}]}
{"op":"mcm","clk":"1004447345","pt":1580655115809,"mc":[{"id":"1.168224477","rc":[{"batb":[[0,1.63,27.62],[1,1.01,15.51],[2,1.01,0]],"ltp":0.0,"tv":0.0,"id":7444998}]}]}
{"op":"mcm","clk":"1004447851","pt":1580655118884,"mc":[{"id":"1.168224477","rc":[{"batb":[[0,1.89,53.44],[1,1.87,77.32],[2,1.63,27.62]],"ltp":0.0,"tv":0.0,"id":7444998}]}]}
{"op":"mcm","clk":"1004447982","pt":1580655119830,"mc":[{"id":"1.168224477","rc":[{"batb":[[1,1.89,16.76],[2,1.01,15.51]],"ltp":0.0,"tv":0.0,"id":5858055},{"batb":[[0,1.89,70.2],[2,1.74,21.79]],"ltp":0.0,"tv":0.0,"id":7444998}]}]}
{"op":"mcm","clk":"1004448131","pt":1580655120805,"mc":[{"id":"1.168224477","rc":[{"batb":[[1,1.94,44.53],[2,1.89,16.76]],"batl":[[0,2.14,36.13],[1,2.7,245.56]],"ltp":0.0,"tv":0.0,"id":5858055},{"batb":[[1,1.87,125.21]],"batl":[[2,2.06,39.49]],"ltp":0.0,"tv":0.0,"id":7444998}]}]}
{"op":"mcm","clk":"1004450037","pt":1580655132721,"mc":[{"id":"1.168224477","rc":[{"batb":[[0,1.94,44.53],[1,1.89,16.76],[2,1.01,15.51]],"ltp":0.0,"tv":0.0,"id":5858055},{"batb":[[0,1.87,47.89],[1,1.74,21.79],[2,1.01,15.51]],"batl":[[0,2.06,39.49],[1,2.4,289.78],[2,2.06,0]],"ltp":0.0,"tv":0.0,"id":7444998}]}]}
{"op":"mcm","clk":"1004450195","pt":1580655133841,"mc":[{"id":"1.168224477","rc":[{"batb":[[0,1.89,16.76],[1,1.01,15.51],[2,1.01,0]],"batl":[[0,2.7,245.56],[1,2.7,0]],"ltp":0.0,"tv":0.0,"id":5858055},{"batb":[[0,1.74,21.79],[1,1.01,15.51],[2,1.01,0]],"batl":[[0,2.4,289.78],[1,2.4,0]],"ltp":0.0,"tv":0.0,"id":7444998}]}]}
{"op":"mcm","clk":"1004450434","pt":1580655135430,"mc":[{"id":"1.168224477","rc":[{"batb":[[0,1.74,116.42],[1,1.72,101.77],[2,1.01,15.51]],"batl":[[0,2.08,94.74],[1,2.1,55.57],[2,2.4,289.78]],"ltp":0.0,"tv":0.0,"id":7444998}]}]}
{"op":"mcm","clk":"1004451005","pt":1580655139352,"mc":[{"id":"1.168224477","rc":[{"batb":[[0,1.74,21.79],[1,1.01,15.51],[2,1.01,0]],"batl":[[0,2.4,289.78],[1,2.1,0],[2,2.4,0]],"ltp":0.0,"tv":0.0,"id":7444998}]}]}
{"op":"mcm","clk":"1004451302","pt":1580655141447,"mc":[{"id":"1.168224477","rc":[{"batb":[[0,1.86,53.24],[1,1.84,81.39],[2,1.74,21.79]],"batl":[[0,1.94,77.96],[1,1.96,67.92],[2,2.4,289.78]],"ltp":0.0,"tv":0.0,"id":7444998}]}]}
{"op":"mcm","clk":"1004451653","pt":1580655143436,"mc":[{"id":"1.168224477","rc":[{"batb":[[0,1.74,21.79],[1,1.01,15.51],[2,1.74,0]],"batl":[[0,2.4,289.78],[1,1.96,0],[2,2.4,0]],"ltp":0.0,"tv":0.0,"id":7444998}]}]}
{"op":"mcm","clk":"1004452092","pt":1580655146320,"mc":[{"id":"1.168224477","rc":[{"batb":[[0,1.74,116.42],[1,1.72,101.77],[2,1.01,15.51]],"batl":[[0,2.08,94.74],[1,2.1,55.57],[2,2.4,289.78]],"ltp":0.0,"tv":0.0,"id":7444998}]}]}
{"op":"mcm","clk":"1004453089","pt":1580655153291,"mc":[{"id":"1.168224477","rc":[{"batb":[[0,1.74,21.79],[1,1.01,15.51],[2,1.01,0]],"batl":[[0,2.4,289.78],[1,2.1,0],[2,2.4,0]],"ltp":0.0,"tv":0.0,"id":7444998}]}]}
{"op":"mcm","clk":"1004453522","pt":1580655156255,"mc":[{"id":"1.168224477","rc":[{"batb":[[0,1.93,82.26],[1,1.91,72.38],[2,1.89,16.76]],"batl":[[0,2.02,56.64],[1,2.04,60.47]],"ltp":0.0,"tv":0.0,"id":5858055},{"batb":[[0,1.98,28.95],[1,1.86,17.62],[2,1.74,21.79]],"ltp":0.0,"tv":0.0,"id":7444998}]}]}
{"op":"mcm","clk":"1004453660","pt":1580655157059,"mc":[{"id":"1.168224477","rc":[{"batb":[[2,1.01,15.51]],"batl":[[0,2.16,36.13]],"ltp":0.0,"tv":0.0,"id":7444998}]}]}
{"op":"mcm","clk":"1004453985","pt":1580655159501,"mc":[{"id":"1.168224477","rc":[{"batl":[[2,2.5,274.54]],"ltp":0.0,"tv":0.0,"id":5858055},{"batl":[[1,2.72,241.55]],"ltp":0.0,"tv":0.0,"id":7444998}]}]}
{"op":"mcm","clk":"1004455139","pt":1580655167553,"mc":[{"id":"1.168224477","rc":[{"batl":[[2,2.06,39.49]],"ltp":0.0,"tv":0.0,"id":5858055},{"batb":[[1,1.94,44.53],[2,1.86,17.62]],"ltp":0.0,"tv":0.0,"id":7444998}]}]}
{"op":"mcm","clk":"1004455352","pt":1580655169289,"mc":[{"id":"1.168224477","rc":[{"batb":[[0,1.85,48.73],[1,1.83,18.49],[2,1.01,15.51]],"batl":[[0,2.06,39.49],[1,2.5,274.54],[2,2.06,0]],"ltp":0.0,"tv":0.0,"id":5858055},{"batb":[[0,1.94,44.53],[1,1.86,17.62],[2,1.01,15.51]],"ltp":0.0,"tv":0.0,"id":7444998}]}]}
{"op":"mcm","clk":"1004455466","pt":1580655170063,"mc":[{"id":"1.168224477","rc":[{"batb":[[0,1.83,18.49],[1,1.01,15.51],[2,1.01,0]],"batl":[[0,2.5,274.54],[1,2.5,0]],"ltp":0.0,"tv":0.0,"id":5858055},{"batb":[[0,1.86,17.62],[1,1.01,15.51],[2,1.01,0]],"batl":[[0,2.72,241.55],[1,2.72,0]],"ltp":0.0,"tv":0.0,"id":7444998}]}]}
{"op":"mcm","clk":"1004455689","pt":1580655171962,"mc":[{"id":"1.168224477","rc":[{"batb":[[0,1.87,87.91],[1,1.85,80.19],[2,1.83,18.49]],"batl":[[0,2.16,80.6],[1,2.18,49.93],[2,2.5,274.54]],"ltp":0.0,"tv":0.0,"id":5858055}]}]}
{"op":"mcm","clk":"1004457011","pt":1580655181090,"mc":[{"id":"1.168224477","rc":[{"batb":[[0,1.83,18.49],[1,1.01,15.51],[2,1.83,0]],"batl":[[0,2.5,274.54],[1,2.18,0],[2,2.5,0]],"ltp":0.0,"tv":0.0,"id":5858055}]}]}
{"op":"mcm","clk":"1004457527","pt":1580655184444,"mc":[{"id":"1.168224477","rc":[{"batl":[[0,1.96,59.68],[1,1.98,66.1],[2,2.5,274.54]],"ltp":0.0,"tv":0.0,"id":5858055}]}]}
{"op":"mcm","clk":"1004457605","pt":1580655184822,"mc":[{"id":"1.168224477","rc":[{"batb":[[1,1.82,50.41],[2,1.79,19.99]],"batl":[[2,2,42.01]],"ltp":0.0,"tv":0.0,"id":5858055},{"batb":[[0,2.04,26.2],[1,1.99,42.01],[2,1.96,30.14]],"batl":[[0,2.24,33.61],[1,2.72,241.55]],"ltp":0.0,"tv":0.0,"id":7444998}]}]}
{"op":"mcm","clk":"1004457992","pt":1580655187253,"mc":[{"id":"1.168224477","rc":[{"batb":[[0,1.88,65.17],[1,1.86,78.78],[2,1.83,18.49]],"ltp":0.0,"tv":0.0,"id":5858055}]}]}
{"op":"mcm","clk":"1004459677","pt":1580655198695,"mc":[{"id":"1.168224477","rc":[{"batb":[[0,1.82,50.41],[1,1.79,19.99],[2,1.01,15.51]],"batl":[[0,2,42.01],[1,2.5,274.54],[2,2,0]],"ltp":0.0,"tv":0.0,"id":5858055},{"batb":[[0,1.99,42.01],[1,1.96,30.14],[2,1.01,15.51]],"ltp":0.0,"tv":0.0,"id":7444998}]}]}
{"op":"mcm","clk":"1004459837","pt":1580655199762,"mc":[{"id":"1.168224477","rc":[{"batb":[[0,1.79,19.99],[1,1.01,15.51],[2,1.01,0]],"batl":[[0,2.5,274.54],[1,2.5,0]],"ltp":0.0,"tv":0.0,"id":5858055},{"batb":[[0,1.96,30.14],[1,1.01,15.51],[2,1.01,0]],"batl":[[0,2.72,241.55],[1,2.72,0]],"ltp":0.0,"tv":0.0,"id":7444998}]}]}
{"op":"mcm","clk":"1004460044","pt":1580655201336,"mc":[{"id":"1.168224477","rc":[{"batb":[[0,1.85,54.55],[1,1.83,83.02],[2,1.79,19.99]],"batl":[[0,2.04,88.28],[1,2.06,58.79],[2,2.5,274.54]],"ltp":0.0,"tv":0.0,"id":5858055}]}]}
{"op":"mcm","clk":"1004460353","pt":1580655203355,"mc":[{"id":"1.168224477","rc":[{"batl":[[0,2.5,274.54],[1,2.06,0],[2,2.5,0]],"ltp":0.0,"tv":0.0,"id":5858055}]}]}
{"op":"mcm","clk":"1004460768","pt":1580655206375,"mc":[{"id":"1.168224477","rc":[{"batl":[[0,1.93,81.46],[1,1.95,69.21]],"ltp":0.0,"tv":0.0,"id":5858055}]}]}
{"op":"mcm","clk":"1004460889","pt":1580655207182,"mc":[{"id":"1.168224477","rc":[{"batl":[[0,1.93,64.68],[2,1.96,42.01]],"ltp":0.0,"tv":0.0,"id":5858055},{"batb":[[0,2.1,24.16],[1,2.04,40.33],[2,1.98,29.03]],"batl":[[0,2.3,31.93],[1,2.72,241.55]],"ltp":0.0,"tv":0.0,"id":7444998}]}]}
{"op":"mcm","clk":"1004461286","pt":1580655210075,"mc":[{"id":"1.168224477","rc":[{"batb":[[0,1.85,72.1]],"ltp":0.0,"tv":0.0,"id":5858055}]}]}
{"op":"mcm","clk":"1004461580","pt":1580655212164,"mc":[{"id":"1.168224477","rc":[{"batb":[[2,1.79,19.83]],"ltp":0.0,"tv":0.0,"id":5858055}]}]}
{"op":"mcm","clk":"1004464237","pt":1580655231399,"mc":[{"id":"1.168224477","rc":[{"trd":[[2.1,6.06]],"batb":[[0,2.1,21.13]],"ltp":2.1,"tv":6.05,"id":7444998}],"tv":6.05}]}
{"op":"mcm","clk":"1004465928","pt":1580655243383,"mc":[{"id":"1.168224477","rc":[{"batb":[[0,1.79,19.83],[1,1.78,53.77],[2,1.63,27.46]],"batl":[[0,1.96,42.01],[1,2.36,299.17],[2,1.96,0]],"ltp":0.0,"tv":0.0,"id":5858055}]}]}
{"op":"mcm","clk":"1004466397","pt":1580655246419,"mc":[{"id":"1.168224477","rc":[{"batb":[[2,1.68,83.1]],"batl":[[1,2.04,46.39],[2,2.06,58.75]],"ltp":0.0,"tv":0.0,"id":5858055}]}]}
{"op":"mcm","clk":"1004466502","pt":1580655247097,"mc":[{"id":"1.168224477","rc":[{"batb":[[0,1.8,258.33],[1,1.79,19.83],[2,1.78,53.77]],"ltp":0.0,"tv":0.0,"id":5858055}]}]}
{"op":"mcm","clk":"1004467129","pt":1580655251850,"mc":[{"id":"1.168224477","rc":[{"batb":[[0,1.68,83.1],[1,1.67,57.06],[2,1.63,27.46]],"batl":[[0,2.04,46.39],[1,2.06,58.75],[2,2.36,299.17]],"ltp":0.0,"tv":0.0,"id":5858055},{"batb":[[0,1.98,29.03],[1,1.01,15.51],[2,1.98,0]],"batl":[[0,2.72,241.55],[1,2.72,0]],"ltp":2.1,"tv":6.05,"id":7444998}]}]}
{"op":"mcm","clk":"1004467574","pt":1580655254801,"mc":[{"id":"1.168224477","rc":[{"batb":[[2,1.64,27.38]],"ltp":0.0,"tv":0.0,"id":5858055}]}]}
{"op":"mcm","clk":"1004468687","pt":1580655262125,"mc":[{"id":"1.168224477","rc":[{"batb":[[0,1.64,27.38],[1,1.01,15.51],[2,1.64,0]],"ltp":0.0,"tv":0.0,"id":5858055}]}]}
{"op":"mcm","clk":"1004469248","pt":1580655265363,"mc":[{"id":"1.168224477","rc":[{"batb":[[0,1.96,50.97],[1,1.94,68.93],[2,1.64,27.38]],"ltp":0.0,"tv":0.0,"id":5858055}]}]}
{"op":"mcm","clk":"1004469434","pt":1580655266221,"mc":[{"id":"1.168224477","rc":[{"batb":[[2,1.91,16.52]],"ltp":0.0,"tv":0.0,"id":5858055},{"batb":[[1,1.9,16.6],[2,1.01,15.51]],"ltp":2.1,"tv":6.05,"id":7444998}]}]}
{"op":"mcm","clk":"1004469538","pt":1580655266859,"mc":[{"id":"1.168224477","rc":[{"batl":[[1,2.06,98.24]],"ltp":0.0,"tv":0.0,"id":5858055},{"batb":[[1,1.96,43.69],[2,1.9,16.6]],"batl":[[0,2.18,35.29],[1,2.72,241.55]],"ltp":2.1,"tv":6.05,"id":7444998}]}]}
{"op":"mcm","clk":"1004471017","pt":1580655276086,"mc":[{"id":"1.168224477","rc":[{"batb":[[0,1.75,21.72],[1,1.01,15.51],[2,1.91,0]],"batl":[[0,2.36,299.17],[1,2.06,0],[2,2.36,0]],"ltp":0.0,"tv":0.0,"id":5858055},{"batb":[[0,1.9,16.6],[1,1.01,15.51],[2,1.9,0]],"batl":[[0,2.72,241.55],[1,2.72,0]],"ltp":2.1,"tv":6.05,"id":7444998}]}]}
{"op":"mcm","clk":"1004471472","pt":1580655278897,"mc":[{"id":"1.168224477","rc":[{"batb":[[0,1.8,90.43],[1,1.78,91.03],[2,1.75,21.72]],"batl":[[0,2.14,55.67],[1,2.16,51.23],[2,2.36,299.17]],"ltp":0.0,"tv":0.0,"id":5858055}]}]}
{"op":"mcm","clk":"1004472130","pt":1580655282946,"mc":[{"id":"1.168224477","rc":[{"batb":[[0,1.75,21.72],[1,1.01,15.51],[2,1.75,0]],"batl":[[0,2.36,299.17],[1,2.16,0],[2,2.36,0]],"ltp":0.0,"tv":0.0,"id":5858055}]}]}
{"op":"mcm","clk":"1004472785","pt":1580655286346,"mc":[{"id":"1.168224477","rc":[{"batb":[[0,1.98,29.19],[1,1.86,17.7],[2,1.01,15.51]],"ltp":0.0,"tv":0.0,"id":5858055},{"batb":[[1,1.88,52.56],[2,1.86,78.64]],"batl":[[0,1.96,71.13],[1,1.98,65.93]],"ltp":2.1,"tv":6.05,"id":7444998}]}]}
{"op":"mcm","clk":"1004472851","pt":1580655286781,"mc":[{"id":"1.168224477","rc":[{"batb":[[1,1.93,44.53],[2,1.86,17.7]],"batl":[[0,2.14,36.13]],"ltp":0.0,"tv":0.0,"id":5858055},{"batb":[[1,1.88,99.61]],"batl":[[2,2.08,38.65]],"ltp":2.1,"tv":6.05,"id":7444998}]}]}
{"op":"mcm","clk":"1004473301","pt":1580655289477,"mc":[{"id":"1.168224477","rc":[{"batl":[[1,2.6,257.57]],"ltp":0.0,"tv":0.0,"id":5858055}]}]}
{"op":"mcm","clk":"1004474265","pt":1580655295255,"mc":[{"id":"1.168224477","rc":[{"batb":[[0,1.93,44.53],[1,1.86,17.7],[2,1.01,15.51]],"ltp":0.0,"tv":0.0,"id":5858055},{"batb":[[0,1.88,47.05],[1,1.84,18.41],[2,1.01,15.51]],"batl":[[0,2.08,38.65],[1,2.6,257.57],[2,2.08,0]],"ltp":2.1,"tv":6.05,"id":7444998}]}]}
{"op":"mcm","clk":"1004474341","pt":1580655295795,"mc":[{"id":"1.168224477","rc":[{"batb":[[0,1.86,17.7],[1,1.01,15.51],[2,1.01,0]],"batl":[[0,2.6,257.57],[1,2.6,0]],"ltp":0.0,"tv":0.0,"id":5858055},{"batb":[[0,1.84,18.41],[1,1.01,15.51],[2,1.01,0]],"batl":[[0,2.6,257.57],[1,2.6,0]],"ltp":2.1,"tv":6.05,"id":7444998}]}]}
{"op":"mcm","clk":"1004474721","pt":1580655298384,"mc":[{"id":"1.168224477","rc":[{"batb":[[1,1.83,55.04],[2,1.81,85.84]],"batl":[[0,2.08,74.25],[1,2.1,55.56],[2,2.6,257.57]],"ltp":2.1,"tv":6.05,"id":7444998}]}]}
{"op":"mcm","clk":"1004474784","pt":1580655298716,"mc":[{"id":"1.168224477","rc":[{"batb":[[1,1.01,15.51],[2,1.81,0]],"batl":[[0,2.6,257.57],[1,2.1,0],[2,2.6,0]],"ltp":2.1,"tv":6.05,"id":7444998}]}]}
{"op":"mcm","clk":"1004475274","pt":1580655301986,"mc":[{"id":"1.168224477","rc":[{"batb":[[0,1.88,76.03],[1,1.84,18.41],[2,1.01,15.51]],"ltp":2.1,"tv":6.05,"id":7444998}]}]}
{"op":"mcm","clk":"1004475542","pt":1580655303374,"mc":[{"id":"1.168224477","rc":[{"batb":[[0,1.84,18.41],[1,1.01,15.51],[2,1.01,0]],"ltp":2.1,"tv":6.05,"id":7444998}]}]}
{"op":"mcm","clk":"1004476029","pt":1580655306379,"mc":[{"id":"1.168224477","rc":[{"batb":[[1,1.81,87.87],[2,1.79,89.2]],"batl":[[0,2.06,65.34],[1,2.08,57.15],[2,2.6,257.57]],"ltp":2.1,"tv":6.05,"id":7444998}]}]}
{"op":"mcm","clk":"1004476036","pt":1580655306489,"mc":[{"id":"1.168224477","rc":[{"batb":[[1,1.81,77.32]],"ltp":2.1,"tv":6.05,"id":7444998}]}]}
{"op":"mcm","clk":"1004476391","pt":1580655308409,"mc":[{"id":"1.168224477","rc":[{"batl":[[0,2.06,74.8]],"ltp":2.1,"tv":6.05,"id":7444998}]}]}
{"op":"mcm","clk":"1004476745","pt":1580655310382,"mc":[{"id":"1.168224477","rc":[{"batl":[[0,2.6,257.57],[1,2.08,0],[2,2.6,0]],"ltp":2.1,"tv":6.05,"id":7444998}]}]}
{"op":"mcm","clk":"1004477209","pt":1580655313207,"mc":[{"id":"1.168224477","rc":[{"batl":[[0,1.89,76.4],[1,1.91,73.57]],"ltp":2.1,"tv":6.05,"id":7444998}]}]}
{"op":"mcm","clk":"1004477323","pt":1580655313907,"mc":[{"id":"1.168224477","rc":[{"batb":[[0,2.04,26.28],[1,1.96,30.14],[2,1.01,15.51]],"ltp":0.0,"tv":0.0,"id":5858055},{"batb":[[2,1.79,109.03]],"ltp":2.1,"tv":6.05,"id":7444998}]}]}
{"op":"mcm","clk":"1004477479","pt":1580655314809,"mc":[{"id":"1.168224477","rc":[{"batb":[[1,1.97,42.85],[2,1.96,30.14]],"batl":[[0,2.2,34.45],[1,2.6,257.57]],"ltp":0.0,"tv":0.0,"id":5858055},{"batb":[[1,1.82,50.41],[2,1.81,77.32]],"batl":[[2,2.02,41.17]],"ltp":2.1,"tv":6.05,"id":7444998}]}]}
{"op":"mcm","clk":"1004479544","pt":1580655327355,"mc":[{"id":"1.168224477","rc":[{"batb":[[0,1.97,42.85],[1,1.96,30.14],[2,1.01,15.51]],"ltp":0.0,"tv":0.0,"id":5858055},{"batb":[[0,1.82,50.41],[1,1.79,19.83],[2,1.01,15.51]],"batl":[[0,2.02,41.17],[1,2.5,274.54],[2,2.02,0]],"ltp":2.1,"tv":6.05,"id":7444998}]}]}
{"op":"mcm","clk":"1004479683","pt":1580655328350,"mc":[{"id":"1.168224477","rc":[{"batb":[[0,1.96,30.14],[1,1.01,15.51],[2,1.01,0]],"batl":[[0,2.6,257.57],[1,2.6,0]],"ltp":0.0,"tv":0.0,"id":5858055},{"batb":[[0,1.79,19.83],[1,1.01,15.51],[2,1.01,0]],"batl":[[0,2.5,274.54],[1,2.5,0]],"ltp":2.1,"tv":6.05,"id":7444998}]}]}
{"op":"mcm","clk":"1004479996","pt":1580655330298,"mc":[{"id":"1.168224477","rc":[{"batb":[[1,1.78,96.91],[2,1.76,94.41]],"batl":[[0,1.95,65.92],[1,1.97,67.02],[2,2.5,274.54]],"ltp":2.1,"tv":6.05,"id":7444998}]}]}
{"op":"mcm","clk":"1004480123","pt":1580655330958,"mc":[{"id":"1.168224477","rc":[{"batb":[[1,1.01,15.51],[2,1.76,0]],"batl":[[0,2.5,274.54],[1,1.97,0],[2,2.5,0]],"ltp":2.1,"tv":6.05,"id":7444998}]}]}
{"op":"mcm","clk":"1004480646","pt":1580655334245,"mc":[{"id":"1.168224477","rc":[{"batb":[[0,1.82,80.58],[1,1.8,87.59],[2,1.79,19.83]],"batl":[[0,1.9,68.87],[1,1.92,72.42],[2,2.5,274.54]],"ltp":2.1,"tv":6.05,"id":7444998}]}]}
{"op":"mcm","clk":"1004480856","pt":1580655335419,"mc":[{"id":"1.168224477","rc":[{"batb":[[0,1.79,19.83],[1,1.01,15.51],[2,1.79,0]],"batl":[[0,2.5,274.54],[1,1.92,0],[2,2.5,0]],"ltp":2.1,"tv":6.05,"id":7444998}]}]}
{"op":"mcm","clk":"1004481306","pt":1580655338428,"mc":[{"id":"1.168224477","rc":[{"batb":[[1,1.78,95.98],[2,1.76,94.41]],"batl":[[0,1.95,66.77],[1,1.97,67.03],[2,2.5,274.54]],"ltp":2.1,"tv":6.05,"id":7444998}]}]}
{"op":"mcm","clk":"1004481599","pt":1580655340342,"mc":[{"id":"1.168224477","rc":[{"batl":[[0,2.5,274.54],[1,1.97,0],[2,2.5,0]],"ltp":2.1,"tv":6.05,"id":7444998}]}]}
{"op":"mcm","clk":"1004482029","pt":1580655343350,"mc":[{"id":"1.168224477","rc":[{"batl":[[0,1.86,72.88],[1,1.88,77.24],[2,2.5,274.54]],"ltp":2.1,"tv":6.05,"id":7444998}]}]}
{"op":"mcm","clk":"1004482163","pt":1580655344145,"mc":[{"id":"1.168224477","rc":[{"batb":[[0,2.1,24.31],[1,1.97,29.51],[2,1.01,15.51]],"ltp":0.0,"tv":0.0,"id":5858055}]}]}
{"op":"mcm","clk":"1004482251","pt":1580655344767,"mc":[{"id":"1.168224477","rc":[{"batb":[[1,2.02,41.17],[2,1.97,29.51]],"batl":[[0,2.26,32.77],[1,2.6,257.57]],"ltp":0.0,"tv":0.0,"id":5858055},{"batb":[[0,1.79,72.76]],"batl":[[2,1.99,42.01]],"ltp":2.1,"tv":6.05,"id":7444998}]}]}
{"op":"mcm","clk":"1004485962","pt":1580655369302,"mc":[{"id":"1.168224477","rc":[{"batb":[[1,1.63,27.77],[2,1.01,15.51]],"batl":[[0,1.86,57.95]],"ltp":2.1,"tv":6.05,"id":7444998}]}]}
{"op":"mcm","clk":"1004486278","pt":1580655371396,"mc":[{"id":"1.168224477","rc":[{"batl":[[0,1.99,42.01],[1,2.5,274.54],[2,1.99,0]],"ltp":2.1,"tv":6.05,"id":7444998}]}]}
{"op":"mcm","clk":"1004486435","pt":1580655372409,"mc":[{"id":"1.168224477","rc":[{"batb":[[0,1.97,29.51],[1,1.01,15.51],[2,1.97,0]],"batl":[[0,2.6,257.57],[1,2.6,0]],"ltp":0.0,"tv":0.0,"id":5858055},{"batb":[[0,1.63,27.77],[1,1.01,15.51],[2,1.01,0]],"batl":[[0,2.5,274.54],[1,2.5,0]],"ltp":2.1,"tv":6.05,"id":7444998}]}]}
{"op":"mcm","clk":"1004486727","pt":1580655374315,"mc":[{"id":"1.168224477","rc":[{"batb":[[1,1.62,106.08],[2,1.61,64.85]],"batl":[[0,1.98,70.13],[1,2,64.08],[2,2.5,274.54]],"ltp":2.1,"tv":6.05,"id":7444998}]}]}
{"op":"mcm","clk":"1004487782","pt":1580655381432,"mc":[{"id":"1.168224477","rc":[{"batb":[[1,1.01,15.51],[2,1.61,0]],"ltp":2.1,"tv":6.05,"id":7444998}]}]}
{"op":"mcm","clk":"1004488041","pt":1580655383100,"mc":[{"id":"1.168224477","rc":[{"batl":[[0,1.98,56.17]],"ltp":2.1,"tv":6.05,"id":7444998}]}]}
{"op":"mcm","clk":"1004488226","pt":1580655384414,"mc":[{"id":"1.168224477","rc":[{"batb":[[0,1.89,84.39],[1,1.87,77.45],[2,1.63,27.77]],"ltp":2.1,"tv":6.05,"id":7444998}]}]}
{"op":"mcm","clk":"1004488369","pt":1580655385329,"mc":[{"id":"1.168224477","rc":[{"batb":[[1,1.93,44.53],[2,1.89,16.92]],"batl":[[0,2.14,36.13]],"ltp":0.0,"tv":0.0,"id":5858055},{"batb":[[0,1.9,16.44],[1,1.87,47.89],[2,1.74,21.79]],"batl":[[2,2.08,38.65]],"ltp":2.1,"tv":6.05,"id":7444998}]}]}
{"op":"mcm","clk":"1004488534","pt":1580655386416,"mc":[{"id":"1.168224477","rc":[{"batb":[[0,1.9,77.51],[1,1.88,76.12],[2,1.87,47.89]],"ltp":2.1,"tv":6.05,"id":7444998}]}]}
{"op":"mcm","clk":"1004488645","pt":1580655387243,"mc":[{"id":"1.168224477","rc":[{"batl":[[1,2.5,274.54]],"ltp":0.0,"tv":0.0,"id":5858055}]}]}
{"op":"mcm","clk":"1004489239","pt":1580655391351,"mc":[{"id":"1.168224477","rc":[{"batl":[[0,2.08,38.65],[1,2.5,274.54],[2,2.08,0]],"ltp":2.1,"tv":6.05,"id":7444998}]}]}
{"op":"mcm","clk":"1004489622","pt":1580655393818,"mc":[{"id":"1.168224477","rc":[{"batb":[[0,1.9,92.12]],"batl":[[0,1.99,74.33],[1,2.02,93.77],[2,2.08,38.65]],"ltp":2.1,"tv":6.05,"id":7444998}]}]}
{"op":"mcm","clk":"1004490380","pt":1580655399055,"mc":[{"id":"1.168224477","rc":[{"batb":[[0,1.93,44.53],[1,1.89,16.92],[2,1.01,15.51]],"ltp":0.0,"tv":0.0,"id":5858055},{"batb":[[0,1.87,47.89],[1,1.74,21.79],[2,1.01,15.51]],"batl":[[0,2.08,38.65],[1,2.5,274.54],[2,2.08,0]],"ltp":2.1,"tv":6.05,"id":7444998}]}]}
{"op":"mcm","clk":"1004490505","pt":1580655399928,"mc":[{"id":"1.168224477","rc":[{"batb":[[0,1.89,16.92],[1,1.01,15.51],[2,1.01,0]],"batl":[[0,2.5,274.54],[1,2.5,0]],"ltp":0.0,"tv":0.0,"id":5858055},{"batb":[[0,1.74,21.79],[1,1.01,15.51],[2,1.01,0]],"batl":[[0,2.5,274.54],[1,2.5,0]],"ltp":2.1,"tv":6.05,"id":7444998}]}]}
{"op":"mcm","clk":"1004490802","pt":1580655402134,"mc":[{"id":"1.168224477","rc":[{"batb":[[0,1.75,86.8],[1,1.74,21.79],[2,1.73,99.91]],"batl":[[0,2.1,96.84],[1,2.12,54.14],[2,2.5,274.54]],"ltp":2.1,"tv":6.05,"id":7444998}]}]}
{"op":"mcm","clk":"1004491144","pt":1580655404160,"mc":[{"id":"1.168224477","rc":[{"batb":[[0,1.74,21.79],[1,1.01,15.51],[2,1.73,0]],"batl":[[0,2.5,274.54],[1,2.12,0],[2,2.5,0]],"ltp":2.1,"tv":6.05,"id":7444998}]}]}
{"op":"mcm","clk":"1004491546","pt":1580655406957,"mc":[{"id":"1.168224477","rc":[{"batb":[[0,1.92,66.35],[1,1.9,73.66],[2,1.89,16.92]],"batl":[[0,2.02,106.41],[1,2.04,60.53],[2,2.5,274.54]],"ltp":0.0,"tv":0.0,"id":5858055}]}]}
{"op":"mcm","clk":"1004491657","pt":1580655407638,"mc":[{"id":"1.168224477","rc":[{"batb":[[0,1.99,28.72],[1,1.86,17.62],[2,1.01,15.51]],"ltp":2.1,"tv":6.05,"id":7444998}]}]}
{"op":"mcm","clk":"1004491832","pt":1580655408830,"mc":[{"id":"1.168224477","rc":[{"batl":[[1,2.04,100.86]],"ltp":0.0,"tv":0.0,"id":5858055},{"batb":[[1,1.95,43.69],[2,1.86,17.62]],"batl":[[0,2.18,35.29]],"ltp":2.1,"tv":6.05,"id":7444998}]}]}
{"op":"mcm","clk":"1004492102","pt":1580655410580,"mc":[{"id":"1.168224477","rc":[{"batl":[[1,2.82,231.28]],"ltp":2.1,"tv":6.05,"id":7444998}]}]}
{"op":"mcm","clk":"1004493277","pt":1580655418349,"mc":[{"id":"1.168224477","rc":[{"batb":[[0,1.86,48.73],[1,1.83,18.8],[2,1.01,15.51]],"batl":[[0,2.04,40.33],[1,2.5,274.54],[2,2.5,0]],"ltp":0.0,"tv":0.0,"id":5858055},{"batb":[[0,1.95,43.69],[1,1.86,17.62],[2,1.01,15.51]],"ltp":2.1,"tv":6.05,"id":7444998}]}]}
{"op":"mcm","clk":"1004493509","pt":1580655420007,"mc":[{"id":"1.168224477","rc":[{"batb":[[0,1.83,18.8],[1,1.01,15.51],[2,1.01,0]],"batl":[[0,2.5,274.54],[1,2.5,0]],"ltp":0.0,"tv":0.0,"id":5858055},{"batb":[[0,1.86,17.62],[1,1.01,15.51],[2,1.01,0]],"batl":[[0,2.82,231.28],[1,2.82,0]],"ltp":2.1,"tv":6.05,"id":7444998}]}]}
{"op":"mcm","clk":"1004493669","pt":1580655421058,"mc":[{"id":"1.168224477","rc":[{"batb":[[0,1.86,80.49],[1,1.84,81.65],[2,1.83,18.8]],"batl":[[0,2.14,72.4],[1,2.16,51.3],[2,2.5,274.54]],"ltp":0.0,"tv":0.0,"id":5858055}]}]}
{"op":"mcm","clk":"1004494076","pt":1580655423871,"mc":[{"id":"1.168224477","rc":[{"batb":[[0,1.83,18.8],[1,1.01,15.51],[2,1.83,0]],"batl":[[0,2.5,274.54],[1,2.16,0],[2,2.5,0]],"ltp":0.0,"tv":0.0,"id":5858055}]}]}
{"op":"mcm","clk":"1004494567","pt":1580655427362,"mc":[{"id":"1.168224477","rc":[{"batb":[[0,1.94,74.07],[1,1.92,71.26],[2,1.83,18.8]],"batl":[[0,2.04,90.82],[1,2.06,58.82],[2,2.5,274.54]],"ltp":0.0,"tv":0.0,"id":5858055}]}]}
{"op":"mcm","clk":"1004494957","pt":1580655429959,"mc":[{"id":"1.168224477","rc":[{"batb":[[0,1.83,18.8],[1,1.01,15.51],[2,1.83,0]],"batl":[[0,2.5,274.54],[1,2.06,0],[2,2.5,0]],"ltp":0.0,"tv":0.0,"id":5858055}]}]}
{"op":"mcm","clk":"1004495358","pt":1580655432960,"mc":[{"id":"1.168224477","rc":[{"batb":[[0,1.86,80.49],[1,1.84,81.65],[2,1.83,18.8]],"batl":[[0,2.14,72.4],[1,2.16,51.3],[2,2.5,274.54]],"ltp":0.0,"tv":0.0,"id":5858055}]}]}
{"op":"mcm","clk":"1004495707","pt":1580655435379,"mc":[{"id":"1.168224477","rc":[{"batb":[[0,1.83,18.8],[1,1.01,15.51],[2,1.83,0]],"batl":[[0,2.5,274.54],[1,2.16,0],[2,2.5,0]],"ltp":0.0,"tv":0.0,"id":5858055}]}]}
{"op":"mcm","clk":"1004496134","pt":1580655438359,"mc":[{"id":"1.168224477","rc":[{"batb":[[0,2.02,27.54],[1,1.91,16.44],[2,1.83,18.8]],"ltp":0.0,"tv":0.0,"id":5858055},{"batb":[[0,1.88,71.59],[1,1.86,96.37],[2,1.69,24.31]],"batl":[[0,1.96,53.26],[1,1.98,66.02]],"ltp":2.1,"tv":6.05,"id":7444998}]}]}
{"op":"mcm","clk":"1004496275","pt":1580655439258,"mc":[{"id":"1.168224477","rc":[{"batb":[[1,1.92,45.37],[2,1.91,16.44]],"batl":[[0,2.16,36.13],[1,2.5,274.54]],"ltp":0.0,"tv":0.0,"id":5858055},{"batb":[[1,1.86,145.11]],"batl":[[2,2.08,38.65]],"ltp":2.1,"tv":6.05,"id":7444998}]}]}
{"op":"mcm","clk":"1004496308","pt":1580655439456,"mc":[{"id":"1.168224477","rc":[{"batb":[[1,1.91,16.44],[2,1.01,15.51]],"ltp":0.0,"tv":0.0,"id":5858055}]}]}
{"op":"mcm","clk":"1004496509","pt":1580655440871,"mc":[{"id":"1.168224477","rc":[{"batb":[[1,1.93,44.53],[2,1.91,16.44]],"ltp":0.0,"tv":0.0,"id":5858055}]}]}
{"op":"mcm","clk":"1004498348","pt":1580655453299,"mc":[{"id":"1.168224477","rc":[{"batb":[[0,1.93,44.53],[1,1.91,16.44],[2,1.01,15.51]],"ltp":0.0,"tv":0.0,"id":5858055},{"batb":[[0,1.86,48.73],[1,1.69,24.31],[2,1.01,15.51]],"batl":[[0,2.08,38.65],[1,2.6,257.57],[2,2.08,0]],"ltp":2.1,"tv":6.05,"id":7444998}]}]}
{"op":"mcm","clk":"1004498439","pt":1580655453878,"mc":[{"id":"1.168224477","rc":[{"batb":[[0,1.91,16.44],[1,1.01,15.51],[2,1.01,0]],"batl":[[0,2.5,274.54],[1,2.5,0]],"ltp":0.0,"tv":0.0,"id":5858055},{"batb":[[0,1.69,24.31],[1,1.01,15.51],[2,1.01,0]],"batl":[[0,2.6,257.57],[1,2.6,0]],"ltp":2.1,"tv":6.05,"id":7444998}]}]}
{"op":"mcm","clk":"1004498691","pt":1580655455581,"mc":[{"id":"1.168224477","rc":[{"batb":[[0,1.71,73.97],[1,1.69,132.5],[2,1.01,15.51]],"batl":[[0,2.08,52.77],[1,2.1,55.62],[2,2.6,257.57]],"ltp":2.1,"tv":6.05,"id":7444998}]}]}
{"op":"mcm","clk":"1004500294","pt":1580655466299,"mc":[{"id":"1.168224477","rc":[{"batl":[[0,2.6,257.57],[1,2.1,0],[2,2.6,0]],"ltp":2.1,"tv":6.05,"id":7444998}]}]}
{"op":"mcm","clk":"1004500801","pt":1580655469424,"mc":[{"id":"1.168224477","rc":[{"batl":[[0,1.78,86.83],[1,1.8,88.39]],"ltp":2.1,"tv":6.05,"id":7444998}]}]}
{"op":"mcm","clk":"1004500886","pt":1580655469903,"mc":[{"id":"1.168224477","rc":[{"batb":[[0,2.28,19.43],[1,2.02,26.99],[2,1.01,15.51]],"ltp":0.0,"tv":0.0,"id":5858055},{"batb":[[2,1.45,42.65]],"ltp":2.1,"tv":6.05,"id":7444998}]}]}
{"op":"mcm","clk":"1004501096","pt":1580655471198,"mc":[{"id":"1.168224477","rc":[{"batb":[[1,2.12,36.97],[2,2.02,26.99]],"batl":[[0,2.4,29.41]],"ltp":0.0,"tv":0.0,"id":5858055},{"batb":[[0,1.72,57.97],[1,1.71,73.97],[2,1.69,132.5]],"ltp":2.1,"tv":6.05,"id":7444998}]}]}
{"op":"mcm","clk":"1004501261","pt":1580655472309,"mc":[{"id":"1.168224477","rc":[{"batl":[[1,2.92,221.26]],"ltp":0.0,"tv":0.0,"id":5858055},{"batl":[[2,1.89,42.01]],"ltp":2.1,"tv":6.05,"id":7444998}]}]}
{"op":"mcm","clk":"1004503530","pt":1580655486388,"mc":[{"id":"1.168224477","rc":[{"batb":[[1,1.69,24.31],[2,1.45,42.65]],"batl":[[0,1.89,42.01],[1,2.36,299.17],[2,1.89,0]],"ltp":2.1,"tv":6.05,"id":7444998}]}]}
{"op":"mcm","clk":"1004503622","pt":1580655486974,"mc":[{"id":"1.168224477","rc":[{"batb":[[0,2.12,36.97],[1,2.02,26.99],[2,1.01,15.51]],"ltp":0.0,"tv":0.0,"id":5858055},{"batb":[[1,1.45,42.65],[2,1.01,15.51]],"ltp":2.1,"tv":6.05,"id":7444998}]}]}
{"op":"mcm","clk":"1004503773","pt":1580655487881,"mc":[{"id":"1.168224477","rc":[{"batb":[[0,2.02,26.99],[1,1.01,15.51],[2,1.01,0]],"batl":[[0,2.92,221.26],[1,2.92,0]],"ltp":0.0,"tv":0.0,"id":5858055},{"batb":[[0,1.45,42.65],[1,1.01,15.51],[2,1.01,0]],"batl":[[0,2.36,299.17],[1,2.36,0]],"ltp":2.1,"tv":6.05,"id":7444998}]}]}
{"op":"mcm","clk":"1004504016","pt":1580655489383,"mc":[{"id":"1.168224477","rc":[{"batb":[[0,1.47,91.38],[1,1.46,94.85],[2,1.45,42.65]],"batl":[[0,1.97,72.83],[1,1.99,65.03],[2,2.36,299.17]],"ltp":2.1,"tv":6.05,"id":7444998}]}]}
{"op":"mcm","clk":"1004505684","pt":1580655499161,"mc":[{"id":"1.168224477","rc":[{"batb":[[0,1.45,42.65],[1,1.01,15.51],[2,1.45,0]],"ltp":2.1,"tv":6.05,"id":7444998}]}]}
{"op":"mcm","clk":"1004505941","pt":1580655500762,"mc":[{"id":"1.168224477","rc":[{"batl":[[2,2.36,0]],"ltp":2.1,"tv":6.05,"id":7444998}]}]}
{"op":"mcm","clk":"1004506141","pt":1580655501956,"mc":[{"id":"1.168224477","rc":[{"batb":[[0,1.88,85.88],[1,1.86,78.79],[2,1.45,42.65]],"ltp":2.1,"tv":6.05,"id":7444998}]}]}
{"op":"mcm","clk":"1004506308","pt":1580655502910,"mc":[{"id":"1.168224477","rc":[{"batb":[[1,1.94,44.53],[2,1.91,16.6]],"batl":[[0,2.16,36.13]],"ltp":0.0,"tv":0.0,"id":5858055},{"batb":[[1,1.86,127.52],[2,1.85,17.86]],"batl":[[2,2.06,39.49]],"ltp":2.1,"tv":6.05,"id":7444998}]}]}
{"op":"mcm","clk":"1004506552","pt":1580655504364,"mc":[{"id":"1.168224477","rc":[{"batl":[[1,2.6,257.57]],"ltp":0.0,"tv":0.0,"id":5858055}]}]}
{"op":"mcm","clk":"1004509513","pt":1580655522328,"mc":[{"id":"1.168224477","rc":[{"batb":[[0,1.94,44.53],[1,1.91,16.6],[2,1.01,15.51]],"ltp":0.0,"tv":0.0,"id":5858055},{"batb":[[0,1.86,48.73],[1,1.66,25.57],[2,1.01,15.51]],"batl":[[0,2.06,39.49],[1,2.6,257.57],[2,2.06,0]],"ltp":2.1,"tv":6.05,"id":7444998}]}]}
{"op":"mcm","clk":"1004509777","pt":1580655523927,"mc":[{"id":"1.168224477","rc":[{"batb":[[0,1.91,16.6],[1,1.01,15.51],[2,1.01,0]],"batl":[[0,2.6,257.57],[1,2.6,0]],"ltp":0.0,"tv":0.0,"id":5858055},{"batb":[[0,1.66,25.57],[1,1.01,15.51],[2,1.01,0]],"batl":[[0,2.6,257.57],[1,2.6,0]],"ltp":2.1,"tv":6.05,"id":7444998}]}]}
{"op":"mcm","clk":"1004509945","pt":1580655525060,"mc":[{"id":"1.168224477","rc":[{"batb":[[0,1.69,99.26],[1,1.67,112.93],[2,1.66,25.57]],"batl":[[0,2.1,50.28],[1,2.12,54.14],[2,2.6,257.57]],"ltp":2.1,"tv":6.05,"id":7444998}]}]}
{"op":"mcm","clk":"1004510629","pt":1580655529397,"mc":[{"id":"1.168224477","rc":[{"batl":[[0,2.6,257.57],[1,2.12,0],[2,2.6,0]],"ltp":2.1,"tv":6.05,"id":7444998}]}]}
{"op":"mcm","clk":"1004510974","pt":1580655531422,"mc":[{"id":"1.168224477","rc":[{"batl":[[0,1.76,74.53],[1,1.78,91.67]],"ltp":2.1,"tv":6.05,"id":7444998}]}]}
{"op":"mcm","clk":"1004511082","pt":1580655532122,"mc":[{"id":"1.168224477","rc":[{"batb":[[0,2.32,18.41],[1,2.08,25.34],[2,1.01,15.51]],"ltp":0.0,"tv":0.0,"id":5858055}]}]}
{"op":"mcm","clk":"1004511194","pt":1580655532914,"mc":[{"id":"1.168224477","rc":[{"batb":[[1,2.14,36.13],[2,2.08,25.34]],"batl":[[0,2.42,29.41]],"ltp":0.0,"tv":0.0,"id":5858055},{"batb":[[0,1.7,59.65],[1,1.69,99.26],[2,1.67,112.93]],"batl":[[2,1.88,42.01]],"ltp":2.1,"tv":6.05,"id":7444998}]}]}
{"op":"mcm","clk":"1004511326","pt":1580655533710,"mc":[{"id":"1.168224477","rc":[{"batl":[[1,2.92,221.26]],"ltp":0.0,"tv":0.0,"id":5858055}]}]}
{"op":"mcm","clk":"1004511941","pt":1580655537224,"mc":[{"id":"1.168224477","rc":[{"trd":[[2.32,18.41]],"batb":[[0,2.14,36.13],[1,2.08,25.34],[2,1.01,15.51]],"ltp":2.32,"tv":18.41,"id":5858055},{"trd":[[1.76,173.33]],"batb":[[1,1.66,25.57],[2,1.44,44.77]],"batl":[[0,1.88,42.01],[1,2.36,299.17],[2,1.88,0]],"ltp":1.76,"tv":179.38,"id":7444998}],"tv":197.79}]}
{"op":"mcm","clk":"1004512474","pt":1580655540122,"mc":[{"id":"1.168224477","rc":[{"batb":[[0,1.7,132.56],[1,1.68,110.32],[2,1.66,25.57]],"batl":[[0,1.77,93.4],[1,1.79,89.84],[2,1.88,42.01]],"ltp":1.76,"tv":179.38,"id":7444998}]}]}
{"op":"mcm","clk":"1004515058","pt":1580655555046,"mc":[{"id":"1.168224477","rc":[{"batb":[[0,1.7,59.65],[1,1.44,44.77],[2,1.01,15.51]],"batl":[[0,1.88,42.01],[1,2.36,299.17],[2,1.88,0]],"ltp":1.76,"tv":179.38,"id":7444998}]}]}
{"op":"mcm","clk":"1004515223","pt":1580655555945,"mc":[{"id":"1.168224477","rc":[{"batb":[[0,2.08,25.34],[1,1.01,15.51],[2,1.01,0]],"batl":[[0,2.92,221.26],[1,2.92,0]],"ltp":2.32,"tv":18.41,"id":5858055},{"batb":[[0,1.44,44.77],[1,1.01,15.51],[2,1.01,0]],"batl":[[0,2.36,299.17],[1,2.36,0]],"ltp":1.76,"tv":179.38,"id":7444998}]}]}
{"op":"mcm","clk":"1004515572","pt":1580655557973,"mc":[{"id":"1.168224477","rc":[{"batb":[[0,2.06,25.89]],"ltp":2.32,"tv":18.41,"id":5858055},{"batb":[[0,1.46,166.6],[1,1.45,97.72],[2,1.01,15.51]],"batl":[[0,1.96,79.7],[1,1.98,65.95],[2,2.36,299.17]],"ltp":1.76,"tv":179.38,"id":7444998}]}]}
{"op":"mcm","clk":"1004516234","pt":1580655561836,"mc":[{"id":"1.168224477","rc":[{"batb":[[0,1.46,43.9],[1,1.01,15.51],[2,1.01,0]],"ltp":1.76,"tv":179.38,"id":7444998}]}]}
{"op":"mcm","clk":"1004516605","pt":1580655564243,"mc":[{"id":"1.168224477","rc":[{"batl":[[2,2.36,0]],"ltp":1.76,"tv":179.38,"id":7444998}]}]}
{"op":"mcm","clk":"1004516780","pt":1580655565376,"mc":[{"id":"1.168224477","rc":[{"batb":[[1,1.96,43.69],[2,1.93,15.82]],"batl":[[0,2.18,35.29]],"ltp":2.32,"tv":18.41,"id":5858055},{"batb":[[0,1.87,82.83],[1,1.86,18.65],[2,1.85,128.83]],"batl":[[2,2.04,40.33]],"ltp":1.76,"tv":179.38,"id":7444998}]}]}
{"op":"mcm","clk":"1004517257","pt":1580655567882,"mc":[{"id":"1.168224477","rc":[{"batl":[[1,2.6,257.57]],"ltp":2.32,"tv":18.41,"id":5858055}]}]}
{"op":"mcm","clk":"1004519303","pt":1580655580378,"mc":[{"id":"1.168224477","rc":[{"batb":[[0,1.86,18.65],[1,1.85,48.73],[2,1.67,26.67]],"batl":[[0,2.04,40.33],[1,2.6,257.57],[2,2.04,0]],"ltp":1.76,"tv":179.38,"id":7444998}]}]}
{"op":"mcm","clk":"1004519461","pt":1580655581389,"mc":[{"id":"1.168224477","rc":[{"batb":[[0,1.96,43.69],[1,1.93,15.82],[2,1.01,15.51]],"ltp":2.32,"tv":18.41,"id":5858055},{"batb":[[0,1.85,48.73],[1,1.67,26.67],[2,1.01,15.51]],"ltp":1.76,"tv":179.38,"id":7444998}]}]}
{"op":"mcm","clk":"1004519534","pt":1580655581866,"mc":[{"id":"1.168224477","rc":[{"batb":[[0,1.93,15.82],[1,1.01,15.51],[2,1.01,0]],"batl":[[0,2.6,257.57],[1,2.6,0]],"ltp":2.32,"tv":18.41,"id":5858055},{"batb":[[0,1.67,26.67],[1,1.01,15.51],[2,1.01,0]],"batl":[[0,2.6,257.57],[1,2.6,0]],"ltp":1.76,"tv":179.38,"id":7444998}]}]}
{"op":"mcm","clk":"1004519775","pt":1580655583285,"mc":[{"id":"1.168224477","rc":[{"batb":[[0,1.68,102.11],[1,1.67,83.42],[2,1.01,15.51]],"batl":[[0,2.1,80.38],[1,2.12,54.12],[2,2.6,257.57]],"ltp":1.76,"tv":179.38,"id":7444998}]}]}
{"op":"mcm","clk":"1004519991","pt":1580655584368,"mc":[{"id":"1.168224477","rc":[{"batb":[[0,1.67,26.67],[1,1.01,15.51],[2,1.01,0]],"batl":[[0,2.6,257.57],[1,2.12,0],[2,2.6,0]],"ltp":1.76,"tv":179.38,"id":7444998}]}]}
{"op":"mcm","clk":"1004520553","pt":1580655587286,"mc":[{"id":"1.168224477","rc":[{"batb":[[0,1.83,80.81],[1,1.81,85.93],[2,1.67,26.67]],"batl":[[0,1.91,63.98],[1,1.93,71.2]],"ltp":1.76,"tv":179.38,"id":7444998}]}]}
{"op":"mcm","clk":"1004520858","pt":1580655588993,"mc":[{"id":"1.168224477","rc":[{"batl":[[2,2.5,274.54]],"ltp":1.76,"tv":179.38,"id":7444998}]}]}
{"op":"mcm","clk":"1004521238","pt":1580655591080,"mc":[{"id":"1.168224477","rc":[{"batb":[[0,1.67,26.67],[1,1.01,15.51],[2,1.67,0]],"batl":[[0,2.5,274.54],[1,1.93,0],[2,2.5,0]],"ltp":1.76,"tv":179.38,"id":7444998}]}]}
{"op":"mcm","clk":"1004521851","pt":1580655594290,"mc":[{"id":"1.168224477","rc":[{"batb":[[0,1.68,102.11],[1,1.67,83.42],[2,1.01,15.51]],"batl":[[0,2.1,80.38],[1,2.12,54.12],[2,2.5,274.54]],"ltp":1.76,"tv":179.38,"id":7444998}]}]}
{"op":"mcm","clk":"1004522531","pt":1580655598287,"mc":[{"id":"1.168224477","rc":[{"batb":[[0,1.67,26.67],[1,1.01,15.51],[2,1.01,0]],"batl":[[0,2.5,274.54],[1,2.12,0],[2,2.5,0]],"ltp":1.76,"tv":179.38,"id":7444998}]}]}
{"op":"mcm","clk":"1004523139","pt":1580655601401,"mc":[{"id":"1.168224477","rc":[{"batb":[[1,1.91,85.07],[2,1.89,74.89]],"batl":[[0,2,61.69],[1,2.02,62.29],[2,2.6,257.57]],"ltp":2.32,"tv":18.41,"id":5858055}]}]}
{"op":"mcm","clk":"1004523351","pt":1580655602433,"mc":[{"id":"1.168224477","rc":[{"batl":[[2,2.6,0]],"ltp":2.32,"tv":18.41,"id":5858055},{"batb":[[0,1.97,30.69],[1,1.89,17.94],[2,1.88,235.96]],"ltp":1.76,"tv":179.38,"id":7444998}]}]}
{"op":"mcm","clk":"1004523524","pt":1580655603230,"mc":[{"id":"1.168224477","rc":[{"batl":[[0,2.2,34.45],[1,2.5,274.54]],"ltp":1.76,"tv":179.38,"id":7444998}]}]}
{"op":"mcm","clk":"1004523776","pt":1580655604320,"mc":[{"id":"1.168224477","rc":[{"batl":[[1,2.02,103.46]],"ltp":2.32,"tv":18.41,"id":5858055},{"batb":[[0,1.97,73.54]],"ltp":1.76,"tv":179.38,"id":7444998}]}]}
{"op":"mcm","clk":"1004523935","pt":1580655605115,"mc":[{"id":"1.168224477","rc":[{"batl":[[2,2.5,274.54]],"ltp":2.32,"tv":18.41,"id":5858055}]}]}
{"op":"mcm","clk":"1004524576","pt":1580655608414,"mc":[{"id":"1.168224477","rc":[{"batb":[[1,1.84,49.57],[2,1.72,23.05]],"ltp":2.32,"tv":18.41,"id":5858055}]}]}
{"op":"mcm","clk":"1004525157","pt":1580655611426,"mc":[{"id":"1.168224477","rc":[{"batb":[[1,1.92,49.87],[2,1.9,73.65]],"ltp":2.32,"tv":18.41,"id":5858055}]}]}
{"op":"mcm","clk":"1004526937","pt":1580655622335,"mc":[{"id":"1.168224477","rc":[{"batl":[[0,2.02,103.46],[1,2.5,274.54],[2,2.5,0]],"ltp":2.32,"tv":18.41,"id":5858055}]}]}
{"op":"mcm","clk":"1004527432","pt":1580655625231,"mc":[{"id":"1.168224477","rc":[{"batb":[[1,1.92,65.23]],"batl":[[0,2.02,148.57],[1,2.04,60.52],[2,2.5,274.54]],"ltp":2.32,"tv":18.41,"id":5858055}]}]}
{"op":"mcm","clk":"1004527813","pt":1580655627511,"mc":[{"id":"1.168224477","rc":[{"batb":[[2,1.01,15.51]],"ltp":1.76,"tv":179.38,"id":7444998}]}]}
{"op":"mcm","clk":"1004535534","pt":1580655672143,"mc":[{"id":"1.168224477","rc":[{"trd":[[1.93,0.03]],"batb":[[0,1.93,15.8]],"ltp":1.93,"tv":18.44,"id":5858055}],"tv":197.82}]}
{"op":"mcm","clk":"1004537794","pt":1580655683382,"mc":[{"id":"1.168224477","rc":[{"batb":[[1,1.84,49.57],[2,1.72,23.05]],"batl":[[0,2.02,41.17],[1,2.5,274.54],[2,2.5,0]],"ltp":1.93,"tv":18.44,"id":5858055}]}]}
{"op":"mcm","clk":"1004537912","pt":1580655683965,"mc":[{"id":"1.168224477","rc":[{"batb":[[0,1.72,23.05],[1,1.01,15.51],[2,1.72,0]],"batl":[[0,2.5,274.54],[1,2.5,0]],"ltp":1.93,"tv":18.44,"id":5858055},{"batb":[[0,1.89,17.94],[1,1.01,15.51],[2,1.01,0]],"batl":[[0,2.5,274.54],[1,2.5,0]],"ltp":1.76,"tv":179.38,"id":7444998}]}]}
{"op":"mcm","clk":"1004538332","pt":1580655686338,"mc":[{"id":"1.168224477","rc":[{"batb":[[0,1.72,127.05],[1,1.7,106.63],[2,1.01,15.51]],"batl":[[0,2.14,69.87],[1,2.16,51.3],[2,2.5,274.54]],"ltp":1.93,"tv":18.44,"id":5858055}]}]}
{"op":"mcm","clk":"1004540775","pt":1580655698871,"mc":[{"id":"1.168224477","rc":[{"batb":[[0,1.72,23.05],[1,1.01,15.51],[2,1.01,0]],"batl":[[0,2.5,274.54],[1,2.16,0],[2,2.5,0]],"ltp":1.93,"tv":18.44,"id":5858055}]}]}
{"op":"mcm","clk":"1004541309","pt":1580655701868,"mc":[{"id":"1.168224477","rc":[{"batb":[[1,1.88,68.71],[2,1.86,78.74]],"batl":[[0,1.96,55.95],[1,1.98,66.01],[2,2.5,274.54]],"ltp":1.76,"tv":179.38,"id":7444998}]}]}
{"op":"mcm","clk":"1004541499","pt":1580655702910,"mc":[{"id":"1.168224477","rc":[{"batb":[[0,2.02,27.07],[1,1.92,45.37],[2,1.85,18.02]],"batl":[[0,2.14,36.13],[1,2.5,274.54]],"ltp":1.93,"tv":18.44,"id":5858055},{"batb":[[0,1.89,64.99]],"batl":[[2,2.08,38.65]],"ltp":1.76,"tv":179.38,"id":7444998}]}]}
{"op":"mcm","clk":"1004542867","pt":1580655710391,"mc":[{"id":"1.168224477","rc":[{"batb":[[1,1.81,20.54],[2,1.01,15.51]],"batl":[[0,2.08,38.65],[1,2.5,274.54],[2,2.08,0]],"ltp":1.76,"tv":179.38,"id":7444998}]}]}
{"op":"mcm","clk":"1004542993","pt":1580655711086,"mc":[{"id":"1.168224477","rc":[{"batb":[[0,1.92,45.37],[1,1.85,18.02],[2,1.01,15.51]],"ltp":1.93,"tv":18.44,"id":5858055},{"batb":[[0,1.89,47.05]],"ltp":1.76,"tv":179.38,"id":7444998}]}]}
{"op":"mcm","clk":"1004543168","pt":1580655712115,"mc":[{"id":"1.168224477","rc":[{"batb":[[0,1.85,18.02],[1,1.01,15.51],[2,1.01,0]],"batl":[[0,2.5,274.54],[1,2.5,0]],"ltp":1.93,"tv":18.44,"id":5858055},{"batb":[[0,1.81,20.54],[1,1.01,15.51],[2,1.01,0]],"batl":[[0,2.5,274.54],[1,2.5,0]],"ltp":1.76,"tv":179.38,"id":7444998}]}]}
{"op":"mcm","clk":"1004543378","pt":1580655713200,"mc":[{"id":"1.168224477","rc":[{"batb":[[1,1.8,90.45],[2,1.78,90.85]],"batl":[[0,2.16,70.81],[1,2.18,50.04],[2,2.5,274.54]],"ltp":1.76,"tv":179.38,"id":7444998}]}]}
{"op":"mcm","clk":"1004544015","pt":1580655716894,"mc":[{"id":"1.168224477","rc":[{"batb":[[1,1.01,15.51],[2,1.78,0]],"batl":[[0,2.5,274.54],[1,2.18,0],[2,2.5,0]],"ltp":1.76,"tv":179.38,"id":7444998}]}]}
{"op":"mcm","clk":"1004544707","pt":1580655720234,"mc":[{"id":"1.168224477","rc":[{"batb":[[0,1.87,50.56],[1,1.85,98.21],[2,1.01,15.51]],"batl":[[0,1.95,77.5],[1,1.97,67.14],[2,2.5,274.54]],"ltp":1.93,"tv":18.44,"id":5858055}]}]}
{"op":"mcm","clk":"1004544921","pt":1580655721298,"mc":[{"id":"1.168224477","rc":[{"batb":[[2,1.8,52.09]],"batl":[[2,1.98,42.01]],"ltp":1.93,"tv":18.44,"id":5858055},{"batb":[[0,2.06,26.91],[1,2.02,41.17],[2,1.93,16.76]],"batl":[[0,2.28,32.77]],"ltp":1.76,"tv":179.38,"id":7444998}]}]}
{"op":"mcm","clk":"1004545286","pt":1580655723314,"mc":[{"id":"1.168224477","rc":[{"batl":[[1,2.82,231.28]],"ltp":1.76,"tv":179.38,"id":7444998}]}]}
{"op":"mcm","clk":"1004546835","pt":1580655731411,"mc":[{"id":"1.168224477","rc":[{"batb":[[0,1.85,18.02],[1,1.8,52.09],[2,1.63,27.62]],"batl":[[0,1.98,42.01],[1,2.5,274.54],[2,1.98,0]],"ltp":1.93,"tv":18.44,"id":5858055}]}]}
{"op":"mcm","clk":"1004546951","pt":1580655732049,"mc":[{"id":"1.168224477","rc":[{"batb":[[0,1.63,27.62],[1,1.01,15.51],[2,1.63,0]],"batl":[[0,2.5,274.54],[1,2.5,0]],"ltp":1.93,"tv":18.44,"id":5858055},{"batb":[[0,1.93,16.76],[1,1.01,15.51],[2,1.93,0]],"batl":[[0,2.82,231.28],[1,2.82,0]],"ltp":1.76,"tv":179.38,"id":7444998}]}]}
{"op":"mcm","clk":"1004547328","pt":1580655734223,"mc":[{"id":"1.168224477","rc":[{"batb":[[0,1.64,65.87],[1,1.63,89.87],[2,1.01,15.51]],"batl":[[0,2.1,50.01],[1,2.12,54.09],[2,2.5,274.54]],"ltp":1.93,"tv":18.44,"id":5858055}]}]}
{"op":"mcm","clk":"1004547678","pt":1580655736253,"mc":[{"id":"1.168224477","rc":[{"batb":[[0,1.63,27.62],[1,1.01,15.51],[2,1.01,0]],"batl":[[0,2.5,274.54],[1,2.12,0],[2,2.5,0]],"ltp":1.93,"tv":18.44,"id":5858055}]}]}
{"op":"mcm","clk":"1004548178","pt":1580655739017,"mc":[{"id":"1.168224477","rc":[{"batb":[[0,1.81,91.89],[1,1.79,89.4],[2,1.63,27.62]],"batl":[[0,1.89,63.26],[1,1.91,73.79]],"ltp":1.93,"tv":18.44,"id":5858055}]}]}
{"op":"mcm","clk":"1004548650","pt":1580655741654,"mc":[{"id":"1.168224477","rc":[{"batl":[[2,2.36,299.17]],"ltp":1.93,"tv":18.44,"id":5858055}]}]}
{"op":"mcm","clk":"1004549020","pt":1580655743639,"mc":[{"id":"1.168224477","rc":[{"batb":[[0,1.63,27.62],[1,1.01,15.51],[2,1.63,0]],"batl":[[0,2.36,299.17],[1,1.91,0],[2,2.36,0]],"ltp":1.93,"tv":18.44,"id":5858055}]}]}
{"op":"mcm","clk":"1004549575","pt":1580655746526,"mc":[{"id":"1.168224477","rc":[{"batb":[[0,1.64,68.57],[1,1.63,89.87],[2,1.01,15.51]],"batl":[[0,2.1,47.94],[1,2.12,54.09],[2,2.36,299.17]],"ltp":1.93,"tv":18.44,"id":5858055}]}]}
{"op":"mcm","clk":"1004550247","pt":1580655749976,"mc":[{"id":"1.168224477","rc":[{"batb":[[0,1.63,27.62],[1,1.01,15.51],[2,1.01,0]],"batl":[[0,2.36,299.17],[1,2.12,0],[2,2.36,0]],"ltp":1.93,"tv":18.44,"id":5858055}]}]}
{"op":"mcm","clk":"1004550983","pt":1580655753264,"mc":[{"id":"1.168224477","rc":[{"batb":[[0,1.9,46.21],[1,1.63,27.62],[2,1.01,15.51]],"batl":[[0,2.1,37.81]],"ltp":1.93,"tv":18.44,"id":5858055},{"batb":[[1,1.91,49.37],[2,1.9,46.21]],"batl":[[0,1.99,63.86],[1,2.02,93.77],[2,2.1,37.81]],"ltp":1.76,"tv":179.38,"id":7444998}]}]}
{"op":"mcm","clk":"1004551077","pt":1580655753759,"mc":[{"id":"1.168224477","rc":[{"batb":[[0,1.98,28.88],[1,1.9,46.21],[2,1.78,20.3]],"ltp":1.93,"tv":18.44,"id":5858055}]}]}
{"op":"mcm","clk":"1004551700","pt":1580655756677,"mc":[{"id":"1.168224477","rc":[{"batl":[[1,2.6,257.57]],"ltp":1.93,"tv":18.44,"id":5858055}]}]}
{"op":"mcm","clk":"1004553390","pt":1580655764362,"mc":[{"id":"1.168224477","rc":[{"batb":[[0,1.78,20.3],[1,1.01,15.51],[2,1.78,0]],"batl":[[0,2.6,257.57],[1,2.6,0]],"ltp":1.93,"tv":18.44,"id":5858055},{"batb":[[0,1.82,20.06],[1,1.01,15.51],[2,1.9,0]],"batl":[[0,2.6,257.57],[1,2.02,0],[2,2.1,0]],"ltp":1.76,"tv":179.38,"id":7444998}]}]}
{"op":"mcm","clk":"1004553906","pt":1580655766886,"mc":[{"id":"1.168224477","rc":[{"batb":[[1,1.81,71.99],[2,1.79,89.13]],"batl":[[0,2.24,71.06],[1,2.26,45.29],[2,2.6,257.57]],"ltp":1.76,"tv":179.38,"id":7444998}]}]}
{"op":"mcm","clk":"1004554964","pt":1580655772283,"mc":[{"id":"1.168224477","rc":[{"batb":[[0,1.78,20.32]],"ltp":1.93,"tv":18.44,"id":5858055}]}]}
{"op":"mcm","clk":"1004555587","pt":1580655775285,"mc":[{"id":"1.168224477","rc":[{"batb":[[1,1.01,15.51],[2,1.79,0]],"batl":[[0,2.6,257.57],[1,2.26,0],[2,2.6,0]],"ltp":1.76,"tv":179.38,"id":7444998}]}]}
{"op":"mcm","clk":"1004556113","pt":1580655777982,"mc":[{"id":"1.168224477","rc":[{"trd":[[1.93,0.07]],"batb":[[0,1.81,72.44],[1,1.79,89.36],[2,1.78,20.3]],"batl":[[0,1.89,81.71],[1,1.91,73.76]],"ltp":1.93,"tv":18.47,"id":5858055}],"tv":197.86}]}
{"op":"mcm","clk":"1004556329","pt":1580655779107,"mc":[{"id":"1.168224477","rc":[{"batb":[[0,2.16,23.76],[1,1.94,16.37],[2,1.01,15.51]],"batl":[[0,2.34,31.09]],"ltp":1.76,"tv":179.38,"id":7444998}]}]}
{"op":"mcm","clk":"1004556812","pt":1580655781284,"mc":[{"id":"1.168224477","rc":[{"batl":[[2,1.93,42.01]],"ltp":1.93,"tv":18.47,"id":5858055},{"batb":[[1,2.08,38.65],[2,1.94,16.37]],"ltp":1.76,"tv":179.38,"id":7444998}]}]}
{"op":"mcm","clk":"1004556906","pt":1580655781703,"mc":[{"id":"1.168224477","rc":[{"batl":[[1,2.92,221.26]],"ltp":1.76,"tv":179.38,"id":7444998}]}]}
{"op":"mcm","clk":"1004560469","pt":1580655799213,"mc":[{"id":"1.168224477","rc":[{"batb":[[0,1.76,54.61],[1,1.51,36.74],[2,1.01,15.51]],"batl":[[0,1.93,42.01],[1,2.36,299.17],[2,1.93,0]],"ltp":1.93,"tv":18.47,"id":5858055},{"batb":[[0,2.08,38.65],[1,1.94,16.37],[2,1.01,15.51]],"ltp":1.76,"tv":179.38,"id":7444998}]}]}
{"op":"mcm","clk":"1004560660","pt":1580655800139,"mc":[{"id":"1.168224477","rc":[{"batb":[[0,1.51,36.74],[1,1.01,15.51],[2,1.01,0]],"batl":[[0,2.36,299.17],[1,2.36,0]],"ltp":1.93,"tv":18.47,"id":5858055},{"batb":[[0,1.94,16.37],[1,1.01,15.51],[2,1.01,0]],"batl":[[0,2.92,221.26],[1,2.92,0]],"ltp":1.76,"tv":179.38,"id":7444998}]}]}
{"op":"mcm","clk":"1004560962","pt":1580655801665,"mc":[{"id":"1.168224477","rc":[{"batb":[[0,1.52,126.37],[1,1.51,120.49],[2,1.01,15.51]],"batl":[[0,2.1,52.81],[1,2.12,54.09],[2,2.36,299.17]],"ltp":1.93,"tv":18.47,"id":5858055}]}]}
{"op":"mcm","clk":"1004562594","pt":1580655809180,"mc":[{"id":"1.168224477","rc":[{"batl":[[0,2.36,299.17],[1,2.12,0],[2,2.36,0]],"ltp":1.93,"tv":18.47,"id":5858055}]}]}
{"op":"mcm","clk":"1004563095","pt":1580655811411,"mc":[{"id":"1.168224477","rc":[{"batl":[[0,1.58,121.46],[1,1.59,67.51]],"ltp":1.93,"tv":18.47,"id":5858055}]}]}
{"op":"mcm","clk":"1004563288","pt":1580655812282,"mc":[{"id":"1.168224477","rc":[{"batb":[[2,1.2,113.85]],"ltp":1.93,"tv":18.47,"id":5858055},{"batb":[[0,2.76,12.12],[1,2.2,22.27],[2,1.01,15.51]],"ltp":1.76,"tv":179.38,"id":7444998}]}]}
{"op":"mcm","clk":"1004563456","pt":1580655813100,"mc":[{"id":"1.168224477","rc":[{"batb":[[1,1.51,202.83]],"batl":[[2,1.63,42.01]],"ltp":1.93,"tv":18.47,"id":5858055},{"batb":[[1,2.58,26.05],[2,2.2,22.27]],"batl":[[0,2.96,21]],"ltp":1.76,"tv":179.38,"id":7444998}]}]}
{"op":"mcm","clk":"1004563731","pt":1580655814295,"mc":[{"id":"1.168224477","rc":[{"batl":[[1,3.9,158.24]],"ltp":1.76,"tv":179.38,"id":7444998}]}]}
{"op":"mcm","clk":"1004564999","pt":1580655820176,"mc":[{"id":"1.168224477","rc":[{"batl":[[1,3.9,0]],"ltp":1.76,"tv":179.38,"id":7444998}]}]}
{"op":"mcm","clk":"1004565881","pt":1580655824300,"mc":[{"id":"1.168224477","rc":[{"batl":[[1,3.65,170.41]],"ltp":1.76,"tv":179.38,"id":7444998}]}]}
{"op":"mcm","clk":"1004566117","pt":1580655825324,"mc":[{"id":"1.168224477","rc":[{"batb":[[1,1.51,120.49]],"ltp":1.93,"tv":18.47,"id":5858055},{"batb":[[1,2.2,22.27],[2,1.01,15.51]],"ltp":1.76,"tv":179.38,"id":7444998}]}]}
{"op":"mcm","clk":"1004566827","pt":1580655828332,"mc":[{"id":"1.168224477","rc":[{"batb":[[2,1.5,84.02]],"ltp":1.93,"tv":18.47,"id":5858055},{"batb":[[1,2.6,26.05],[2,2.2,22.27]],"ltp":1.76,"tv":179.38,"id":7444998}]}]}
{"op":"mcm","clk":"1004567520","pt":1580655831448,"mc":[{"id":"1.168224477","rc":[{"batb":[[0,1.5,84.02],[1,1.2,113.85],[2,1.01,15.51]],"batl":[[0,1.63,42.01],[1,1.95,409.86],[2,1.63,0]],"ltp":1.93,"tv":18.47,"id":5858055},{"batb":[[0,2.6,26.05],[1,2.2,22.11],[2,1.01,15.51]],"ltp":1.76,"tv":179.38,"id":7444998}]}]}
{"op":"mcm","clk":"1004567683","pt":1580655832140,"mc":[{"id":"1.168224477","rc":[{"batb":[[0,1.2,113.85],[1,1.01,15.51],[2,1.01,0]],"batl":[[0,1.95,409.86],[1,1.95,0]],"ltp":1.93,"tv":18.47,"id":5858055},{"batb":[[0,2.2,22.11],[1,1.01,15.51],[2,1.01,0]],"batl":[[0,3.65,170.41],[1,3.65,0]],"ltp":1.76,"tv":179.38,"id":7444998}]}]}
{"op":"mcm","clk":"1004568170","pt":1580655834410,"mc":[{"id":"1.168224477","rc":[{"batb":[[0,1.2,241.05],[1,1.19,291.18],[2,1.01,15.51]],"batl":[[0,1.87,88.29],[1,1.89,76.18]],"ltp":1.93,"tv":18.47,"id":5858055}]}]}
{"op":"mcm","clk":"1004571098","pt":1580655847834,"mc":[{"id":"1.168224477","rc":[{"batb":[[0,1.2,113.85],[1,1.01,15.51],[2,1.01,0]],"ltp":1.93,"tv":18.47,"id":5858055}]}]}
{"op":"mcm","clk":"1004571844","pt":1580655851420,"mc":[{"id":"1.168224477","rc":[{"batb":[[0,1.44,152.82],[1,1.43,105.58],[2,1.2,113.85]],"batl":[[0,1.49,104.74],[1,1.5,84.4]],"ltp":1.93,"tv":18.47,"id":5858055}]}]}
{"op":"mcm","clk":"1004572088","pt":1580655852620,"mc":[{"id":"1.168224477","rc":[{"batl":[[2,1.89,435.28]],"ltp":1.93,"tv":18.47,"id":5858055},{"batl":[[0,4.2,148.03]],"ltp":1.76,"tv":179.38,"id":7444998}]}]}
{"op":"mcm","clk":"1004572290","pt":1580655853642,"mc":[{"id":"1.168224477","rc":[{"batb":[[0,1.2,113.85],[1,1.01,15.51],[2,1.2,0]],"batl":[[0,1.89,435.28],[1,1.5,0],[2,1.89,0]],"ltp":1.93,"tv":18.47,"id":5858055}]}]}
{"op":"mcm","clk":"1004572853","pt":1580655856553,"mc":[{"id":"1.168224477","rc":[{"batb":[[0,1.2,241.05],[1,1.19,291.18],[2,1.01,15.51]],"batl":[[0,1.87,88.29],[1,1.89,76.18]],"ltp":1.93,"tv":18.47,"id":5858055}]}]}
{"op":"mcm","clk":"1004574896","pt":1580655866448,"mc":[{"id":"1.168224477","rc":[{"batb":[[0,1.2,113.85],[1,1.01,15.51],[2,1.01,0]],"ltp":1.93,"tv":18.47,"id":5858055}]}]}
{"op":"mcm","clk":"1004575456","pt":1580655869153,"mc":[{"id":"1.168224477","rc":[{"batb":[[0,1.79,75.41],[1,1.77,92.78],[2,1.2,113.85]],"ltp":1.93,"tv":18.47,"id":5858055}]}]}
{"op":"mcm","clk":"1004575666","pt":1580655870161,"mc":[{"id":"1.168224477","rc":[{"batb":[[2,1.75,21.64]],"ltp":1.93,"tv":18.47,"id":5858055},{"batb":[[1,1.98,15.42],[2,1.01,15.51]],"ltp":1.76,"tv":179.38,"id":7444998}]}]}
{"op":"mcm","clk":"1004575838","pt":1580655871044,"mc":[{"id":"1.168224477","rc":[{"batl":[[1,1.89,118.19],[2,2.42,286.52]],"ltp":1.93,"tv":18.47,"id":5858055},{"batb":[[1,2.12,36.97],[2,1.98,15.42]],"batl":[[0,2.82,231.28]],"ltp":1.76,"tv":179.38,"id":7444998}]}]}
{"op":"mcm","clk":"1004578358","pt":1580655883393,"mc":[{"id":"1.168224477","rc":[{"batb":[[0,1.49,38.16],[1,1.01,15.51],[2,1.75,0]],"batl":[[0,1.89,42.01],[1,2.42,286.52],[2,2.42,0]],"ltp":1.93,"tv":18.47,"id":5858055},{"batb":[[0,2.12,36.97],[1,1.98,15.42],[2,1.01,15.51]],"ltp":1.76,"tv":179.38,"id":7444998}]}]}
{"op":"mcm","clk":"1004578566","pt":1580655884373,"mc":[{"id":"1.168224477","rc":[{"batl":[[0,2.42,286.52],[1,2.42,0]],"ltp":1.93,"tv":18.47,"id":5858055},{"batb":[[0,1.98,15.42],[1,1.01,15.51],[2,1.01,0]],"ltp":1.76,"tv":179.38,"id":7444998}]}]}
{"op":"mcm","clk":"1004578967","pt":1580655886260,"mc":[{"id":"1.168224477","rc":[{"batb":[[0,1.51,106.45],[1,1.5,85.92],[2,1.49,38.16]],"batl":[[0,2.08,64.36],[1,2.1,55.59],[2,2.42,286.52]],"ltp":1.93,"tv":18.47,"id":5858055}]}]}
{"op":"mcm","clk":"1004580976","pt":1580655895275,"mc":[{"id":"1.168224477","rc":[{"batl":[[0,2.42,286.52],[1,2.1,0],[2,2.42,0]],"ltp":1.93,"tv":18.47,"id":5858055}]}]}
{"op":"mcm","clk":"1004581651","pt":1580655898292,"mc":[{"id":"1.168224477","rc":[{"batl":[[0,1.56,79.25],[1,1.57,70.94]],"ltp":1.93,"tv":18.47,"id":5858055}]}]}
{"op":"mcm","clk":"1004581880","pt":1580655899390,"mc":[{"id":"1.168224477","rc":[{"batb":[[1,1.5,169.94]],"batl":[[2,1.62,42.01]],"ltp":1.93,"tv":18.47,"id":5858055},{"batb":[[0,2.82,11.57],[1,2.62,25.21],[2,2.6,26.05]],"batl":[[0,2.98,21],[1,3,21]],"ltp":1.76,"tv":179.38,"id":7444998}]}]}
{"op":"mcm","clk":"1004581913","pt":1580655899494,"mc":[{"id":"1.168224477","rc":[{"batb":[[2,2.24,21.32]],"batl":[[0,3,21],[1,3,0]],"ltp":1.76,"tv":179.38,"id":7444998}]}]}
{"op":"mcm","clk":"1004582410","pt":1580655901891,"mc":[{"id":"1.168224477","rc":[{"batl":[[1,3.65,170.41]],"ltp":1.76,"tv":179.38,"id":7444998}]}]}
{"op":"mcm","clk":"1004585495","pt":1580655917097,"mc":[{"id":"1.168224477","rc":[{"batb":[[0,1.5,84.02],[1,1.49,38.16],[2,1.2,116.84]],"batl":[[0,1.62,42.01],[1,2.04,383.01],[2,1.62,0]],"ltp":1.93,"tv":18.47,"id":5858055}]}]}
{"op":"mcm","clk":"1004585746","pt":1580655918246,"mc":[{"id":"1.168224477","rc":[{"batb":[[0,1.2,116.84],[1,1.01,15.51],[2,1.2,0]],"batl":[[0,2.04,383.01],[1,2.04,0]],"ltp":1.93,"tv":18.47,"id":5858055},{"batb":[[0,2.24,21.32],[1,1.01,15.51],[2,2.24,0]],"batl":[[0,3.65,170.41],[1,3.65,0]],"ltp":1.76,"tv":179.38,"id":7444998}]}]}
{"op":"mcm","clk":"1004586142","pt":1580655920225,"mc":[{"id":"1.168224477","rc":[{"batb":[[1,1.19,334.88],[2,1.18,193.81]],"batl":[[0,1.85,91.27],[1,1.87,78.73]],"ltp":1.93,"tv":18.47,"id":5858055}]}]}
{"op":"mcm","clk":"1004586248","pt":1580655920715,"mc":[{"id":"1.168224477","rc":[{"batb":[[1,1.01,15.51],[2,1.18,0]],"ltp":1.93,"tv":18.47,"id":5858055}]}]}
{"op":"mcm","clk":"1004586992","pt":1580655924247,"mc":[{"id":"1.168224477","rc":[{"batb":[[0,1.43,156.19],[1,1.42,108.94],[2,1.2,116.84]],"batl":[[0,1.48,113.45],[1,1.49,86.62]],"ltp":1.93,"tv":18.47,"id":5858055}]}]}
{"op":"mcm","clk":"1004587385","pt":1580655926146,"mc":[{"id":"1.168224477","rc":[{"batl":[[2,1.89,435.28]],"ltp":1.93,"tv":18.47,"id":5858055},{"batl":[[0,4.2,148.03]],"ltp":1.76,"tv":179.38,"id":7444998}]}]}
{"op":"mcm","clk":"1004587461","pt":1580655926530,"mc":[{"id":"1.168224477","rc":[{"batb":[[0,1.2,116.84],[1,1.01,15.51],[2,1.2,0]],"batl":[[0,1.89,435.28],[1,1.49,0],[2,1.89,0]],"ltp":1.93,"tv":18.47,"id":5858055}]}]}
{"op":"mcm","clk":"1004588097","pt":1580655929595,"mc":[{"id":"1.168224477","rc":[{"batb":[[1,1.19,334.88],[2,1.18,193.81]],"batl":[[0,1.85,91.27],[1,1.87,78.73]],"ltp":1.93,"tv":18.47,"id":5858055}]}]}
{"op":"mcm","clk":"1004594121","pt":1580655959392,"mc":[{"id":"1.168224477","rc":[{"batb":[[1,1.01,15.51],[2,1.18,0]],"ltp":1.93,"tv":18.47,"id":5858055}]}]}
{"op":"mcm","clk":"1004594733","pt":1580655962362,"mc":[{"id":"1.168224477","rc":[{"batb":[[0,1.77,82.79],[1,1.75,96.41],[2,1.2,116.84]],"ltp":1.93,"tv":18.47,"id":5858055}]}]}
{"op":"mcm","clk":"1004594940","pt":1580655963341,"mc":[{"id":"1.168224477","rc":[{"batb":[[2,1.73,22.42]],"batl":[[2,1.88,42.01]],"ltp":1.93,"tv":18.47,"id":5858055},{"batb":[[1,2.14,36.13],[2,1.99,29.74]],"ltp":1.76,"tv":179.38,"id":7444998}]}]}
{"op":"mcm","clk":"1004595301","pt":1580655964858,"mc":[{"id":"1.168224477","rc":[{"batl":[[0,2.82,231.28]],"ltp":1.76,"tv":179.38,"id":7444998}]}]}
{"op":"mcm","clk":"1004599801","pt":1580655987373,"mc":[{"id":"1.168224477","rc":[{"batb":[[0,1.73,22.42],[1,1.47,40.6],[2,1.01,15.51]],"batl":[[0,1.88,42.01],[1,2.42,286.52],[2,1.88,0]],"ltp":1.93,"tv":18.47,"id":5858055}]}]}
{"op":"mcm","clk":"1004599956","pt":1580655988196,"mc":[{"id":"1.168224477","rc":[{"batb":[[0,1.47,40.6],[1,1.01,15.51],[2,1.01,0]],"batl":[[0,2.42,286.52],[1,2.42,0]],"ltp":1.93,"tv":18.47,"id":5858055},{"batb":[[0,1.99,29.74],[1,1.01,15.51],[2,1.99,0]],"ltp":1.76,"tv":179.38,"id":7444998}]}]}
{"op":"mcm","clk":"1004600420","pt":1580655990383,"mc":[{"id":"1.168224477","rc":[{"batb":[[0,1.5,90.98],[1,1.49,88.21],[2,1.47,40.6]],"batl":[[0,2.06,73.22],[1,2.08,57.15],[2,2.42,286.52]],"ltp":1.93,"tv":18.47,"id":5858055}]}]}
{"op":"mcm","clk":"1004600829","pt":1580655992447,"mc":[{"id":"1.168224477","rc":[{"batb":[[0,1.47,40.6],[1,1.01,15.51],[2,1.47,0]],"batl":[[0,2.42,286.52],[1,2.08,0],[2,2.42,0]],"ltp":1.93,"tv":18.47,"id":5858055}]}]}
{"op":"mcm","clk":"1004601376","pt":1580655995181,"mc":[{"id":"1.168224477","rc":[{"batb":[[0,1.71,74.32],[1,1.69,108.72],[2,1.47,40.6]],"batl":[[0,1.78,88.76],[1,1.8,88.89]],"ltp":1.93,"tv":18.47,"id":5858055}]}]}
{"op":"mcm","clk":"1004601771","pt":1580655997193,"mc":[{"id":"1.168224477","rc":[{"batb":[[0,1.47,40.6],[1,1.01,15.51],[2,1.47,0]],"ltp":1.93,"tv":18.47,"id":5858055}]}]}
{"op":"mcm","clk":"1004601969","pt":1580655998182,"mc":[{"id":"1.168224477","rc":[{"batl":[[0,2.3,309.75]],"ltp":1.93,"tv":18.47,"id":5858055}]}]}
{"op":"mcm","clk":"1004602387","pt":1580656000101,"mc":[{"id":"1.168224477","rc":[{"batb":[[0,1.5,90.98],[1,1.49,88.21],[2,1.47,40.6]],"batl":[[0,2.06,73.22],[1,2.08,57.15],[2,2.3,309.75]],"ltp":1.93,"tv":18.47,"id":5858055}]}]}
{"op":"mcm","clk":"1004604026","pt":1580656007438,"mc":[{"id":"1.168224477","rc":[{"batb":[[0,1.47,40.6],[1,1.01,15.51],[2,1.47,0]],"batl":[[0,2.3,309.75],[1,2.08,0],[2,2.3,0]],"ltp":1.93,"tv":18.47,"id":5858055}]}]}
{"op":"mcm","clk":"1004604734","pt":1580656010399,"mc":[{"id":"1.168224477","rc":[{"batb":[[1,1.95,54.61],[2,1.93,70.1]],"batl":[[0,2.04,75.85],[1,2.06,58.75]],"ltp":1.76,"tv":179.38,"id":7444998}]}]}
{"op":"mcm","clk":"1004604891","pt":1580656011139,"mc":[{"id":"1.168224477","rc":[{"batb":[[0,1.91,16.29],[1,1.87,47.89],[2,1.7,23.92]],"batl":[[0,2.08,38.65]],"ltp":1.93,"tv":18.47,"id":5858055},{"batb":[[2,1.94,44.53]],"batl":[[2,2.14,36.13]],"ltp":1.76,"tv":179.38,"id":7444998}]}]}
{"op":"mcm","clk":"1004605556","pt":1580656014309,"mc":[{"id":"1.168224477","rc":[{"batl":[[1,2.72,241.55]],"ltp":1.93,"tv":18.47,"id":5858055}]}]}
{"op":"mcm","clk":"1004607580","pt":1580656023404,"mc":[{"id":"1.168224477","rc":[{"batb":[[1,1.94,44.53],[2,1.88,18.02]],"batl":[[0,2.14,36.13],[1,2.5,274.54],[2,2.14,0]],"ltp":1.76,"tv":179.38,"id":7444998}]}]}
{"op":"mcm","clk":"1004607759","pt":1580656024129,"mc":[{"id":"1.168224477","rc":[{"batb":[[0,1.7,23.92],[1,1.01,15.51],[2,1.7,0]],"batl":[[0,2.72,241.55],[1,2.72,0]],"ltp":1.93,"tv":18.47,"id":5858055},{"batb":[[0,1.88,18.02],[1,1.01,15.51],[2,1.88,0]],"batl":[[0,2.5,274.54],[1,2.5,0]],"ltp":1.76,"tv":179.38,"id":7444998}]}]}
{"op":"mcm","clk":"1004608228","pt":1580656026130,"mc":[{"id":"1.168224477","rc":[{"batb":[[1,1.83,79.95],[2,1.81,85.94]],"batl":[[0,2.34,81.27],[1,2.36,40.28],[2,2.5,274.54]],"ltp":1.76,"tv":179.38,"id":7444998}]}]}
{"op":"mcm","clk":"1004609185","pt":1580656030437,"mc":[{"id":"1.168224477","rc":[{"batb":[[1,1.01,15.51],[2,1.81,0]],"batl":[[0,2.5,274.54],[1,2.36,0],[2,2.5,0]],"ltp":1.76,"tv":179.38,"id":7444998}]}]}
{"op":"mcm","clk":"1004609688","pt":1580656033440,"mc":[{"id":"1.168224477","rc":[{"batb":[[0,1.75,90.4],[1,1.73,100.28],[2,1.7,83.57]],"ltp":1.93,"tv":18.47,"id":5858055},{"batl":[[0,2.4,29.41]],"ltp":1.76,"tv":179.38,"id":7444998}]}]}
{"op":"mcm","clk":"1004609807","pt":1580656033761,"mc":[{"id":"1.168224477","rc":[{"batl":[[0,1.88,42.01]],"ltp":1.93,"tv":18.47,"id":5858055},{"batb":[[0,2.3,19.83],[1,2.14,36.13],[2,2.02,28.25]],"ltp":1.76,"tv":179.38,"id":7444998}]}]}
{"op":"mcm","clk":"1004610316","pt":1580656036367,"mc":[{"id":"1.168224477","rc":[{"batb":[[0,1.75,100.93]],"batl":[[0,1.83,84.63],[1,1.85,81.42],[2,1.88,42.01]],"ltp":1.93,"tv":18.47,"id":5858055},{"batl":[[1,2.92,221.26]],"ltp":1.76,"tv":179.38,"id":7444998}]}]}
{"op":"mcm","clk":"1004613761","pt":1580656054169,"mc":[{"id":"1.168224477","rc":[{"batb":[[0,1.45,42.57],[1,1.01,15.51],[2,1.7,0]],"batl":[[0,2.36,299.17],[1,1.85,0],[2,1.88,0]],"ltp":1.93,"tv":18.47,"id":5858055},{"batb":[[0,2.02,28.25],[1,1.01,15.51],[2,2.02,0]],"batl":[[0,2.92,221.26],[1,2.92,0]],"ltp":1.76,"tv":179.38,"id":7444998}]}]}
{"op":"mcm","clk":"1004614181","pt":1580656056403,"mc":[{"id":"1.168224477","rc":[{"batb":[[0,1.49,86.49],[1,1.48,90.61],[2,1.45,42.57]],"batl":[[0,2.04,74.06],[1,2.06,58.77],[2,2.36,299.17]],"ltp":1.93,"tv":18.47,"id":5858055}]}]}
{"op":"mcm","clk":"1004619520","pt":1580656083987,"mc":[{"id":"1.168224477","rc":[{"batb":[[0,1.45,42.57],[1,1.01,15.51],[2,1.45,0]],"ltp":1.93,"tv":18.47,"id":5858055}]}]}
{"op":"mcm","clk":"1004619992","pt":1580656086432,"mc":[{"id":"1.168224477","rc":[{"batl":[[2,2.36,0]],"ltp":1.93,"tv":18.47,"id":5858055}]}]}
{"op":"mcm","clk":"1004620141","pt":1580656087312,"mc":[{"id":"1.168224477","rc":[{"batb":[[0,1.95,56.48],[1,1.93,70.07],[2,1.88,17.15]],"batl":[[1,2.06,98.26]],"ltp":1.93,"tv":18.47,"id":5858055},{"batb":[[1,1.95,43.69],[2,1.91,17.15]],"batl":[[0,2.16,36.13]],"ltp":1.76,"tv":179.38,"id":7444998}]}]}
{"op":"mcm","clk":"1004620472","pt":1580656089114,"mc":[{"id":"1.168224477","rc":[{"batl":[[2,2.6,257.57]],"ltp":1.93,"tv":18.47,"id":5858055},{"batl":[[1,2.6,257.57]],"ltp":1.76,"tv":179.38,"id":7444998}]}]}
{"op":"mcm","clk":"1004622682","pt":1580656100422,"mc":[{"id":"1.168224477","rc":[{"batb":[[0,1.85,48.73],[1,1.67,25.18],[2,1.01,15.51]],"batl":[[0,2.06,39.49],[1,2.6,257.57],[2,2.6,0]],"ltp":1.93,"tv":18.47,"id":5858055},{"batb":[[0,1.95,43.69],[1,1.91,17.15],[2,1.01,15.51]],"ltp":1.76,"tv":179.38,"id":7444998}]}]}
{"op":"mcm","clk":"1004622985","pt":1580656102323,"mc":[{"id":"1.168224477","rc":[{"batb":[[0,1.67,25.18],[1,1.01,15.51],[2,1.01,0]],"batl":[[0,2.6,257.57],[1,2.6,0]],"ltp":1.93,"tv":18.47,"id":5858055},{"batb":[[0,1.91,17.15],[1,1.01,15.51],[2,1.01,0]],"batl":[[0,2.6,257.57],[1,2.6,0]],"ltp":1.76,"tv":179.38,"id":7444998}]}]}
{"op":"mcm","clk":"1004623178","pt":1580656103266,"mc":[{"id":"1.168224477","rc":[{"batb":[[0,1.74,63.68],[1,1.72,102.18],[2,1.67,25.18]],"batl":[[0,2.18,54.11],[1,2.2,48.65],[2,2.6,257.57]],"ltp":1.93,"tv":18.47,"id":5858055}]}]}
{"op":"mcm","clk":"1004623687","pt":1580656105764,"mc":[{"id":"1.168224477","rc":[{"batb":[[0,1.67,25.18],[1,1.01,15.51],[2,1.67,0]],"batl":[[0,2.6,257.57],[1,2.2,0],[2,2.6,0]],"ltp":1.93,"tv":18.47,"id":5858055}]}]}
{"op":"mcm","clk":"1004624315","pt":1580656109178,"mc":[{"id":"1.168224477","rc":[{"batb":[[0,1.74,63.68],[1,1.72,102.18],[2,1.7,59.65]],"batl":[[0,1.81,83.19],[1,1.83,84.27]],"ltp":1.93,"tv":18.47,"id":5858055},{"batl":[[0,2.44,28.57]],"ltp":1.76,"tv":179.38,"id":7444998}]}]}
{"op":"mcm","clk":"1004624421","pt":1580656109669,"mc":[{"id":"1.168224477","rc":[{"batl":[[2,1.86,42.01]],"ltp":1.93,"tv":18.47,"id":5858055},{"batb":[[0,2.34,18.73],[1,2.16,36.13],[2,2.06,26.59]],"ltp":1.76,"tv":179.38,"id":7444998}]}]}
{"op":"mcm","clk":"1004624738","pt":1580656111367,"mc":[{"id":"1.168224477","rc":[{"batl":[[1,2.92,221.26]],"ltp":1.76,"tv":179.38,"id":7444998}]}]}
{"op":"mcm","clk":"1004628079","pt":1580656129408,"mc":[{"id":"1.168224477","rc":[{"batb":[[0,1.7,59.65],[1,1.67,25.18],[2,1.44,44.93]],"batl":[[0,1.86,42.01],[1,2.36,299.17],[2,1.86,0]],"ltp":1.93,"tv":18.47,"id":5858055}]}]}
{"op":"mcm","clk":"1004628258","pt":1580656130233,"mc":[{"id":"1.168224477","rc":[{"batb":[[0,1.44,44.93],[1,1.01,15.51],[2,1.44,0]],"batl":[[0,2.36,299.17],[1,2.36,0]],"ltp":1.93,"tv":18.47,"id":5858055},{"batb":[[0,2.06,26.59],[1,1.01,15.51],[2,2.06,0]],"batl":[[0,2.92,221.26],[1,2.92,0]],"ltp":1.76,"tv":179.38,"id":7444998}]}]}
{"op":"mcm","clk":"1004628626","pt":1580656132410,"mc":[{"id":"1.168224477","rc":[{"batb":[[0,1.48,77.02],[1,1.47,93.14],[2,1.44,44.93]],"batl":[[0,2.02,78.96],[1,2.04,60.47],[2,2.36,299.17]],"ltp":1.93,"tv":18.47,"id":5858055}]}]}
{"op":"mcm","clk":"1004629858","pt":1580656139242,"mc":[{"id":"1.168224477","rc":[{"batb":[[0,1.44,44.93],[1,1.01,15.51],[2,1.44,0]],"ltp":1.93,"tv":18.47,"id":5858055}]}]}
{"op":"mcm","clk":"1004630259","pt":1580656141348,"mc":[{"id":"1.168224477","rc":[{"batl":[[2,2.36,0]],"ltp":1.93,"tv":18.47,"id":5858055}]}]}
{"op":"mcm","clk":"1004630449","pt":1580656142338,"mc":[{"id":"1.168224477","rc":[{"batb":[[0,1.93,58.84],[1,1.91,72.4],[2,1.84,18.18]],"ltp":1.93,"tv":18.47,"id":5858055},{"batb":[[1,1.94,16.37],[2,1.01,15.51]],"ltp":1.76,"tv":179.38,"id":7444998}]}]}
{"op":"mcm","clk":"1004630594","pt":1580656143159,"mc":[{"id":"1.168224477","rc":[{"batb":[[2,1.84,67.75]],"batl":[[1,2.04,100.8]],"ltp":1.93,"tv":18.47,"id":5858055},{"batb":[[1,1.97,42.85],[2,1.94,16.37]],"batl":[[0,2.18,35.29]],"ltp":1.76,"tv":179.38,"id":7444998}]}]}
{"op":"mcm","clk":"1004630852","pt":1580656144445,"mc":[{"id":"1.168224477","rc":[{"batl":[[2,2.6,257.57]],"ltp":1.93,"tv":18.47,"id":5858055},{"batl":[[1,2.6,257.57]],"ltp":1.76,"tv":179.38,"id":7444998}]}]}
{"op":"mcm","clk":"1004632792","pt":1580656154363,"mc":[{"id":"1.168224477","rc":[{"batb":[[0,1.65,26.52],[1,1.01,15.51],[2,1.84,0]],"batl":[[0,2.6,257.57],[1,2.04,0],[2,2.6,0]],"ltp":1.93,"tv":18.47,"id":5858055},{"batb":[[0,1.94,16.37],[1,1.01,15.51],[2,1.94,0]],"batl":[[0,2.6,257.57],[1,2.6,0]],"ltp":1.76,"tv":179.38,"id":7444998}]}]}
{"op":"mcm","clk":"1004633332","pt":1580656157361,"mc":[{"id":"1.168224477","rc":[{"batb":[[0,1.72,83.02],[1,1.7,106.47],[2,1.65,26.52]],"batl":[[0,2.16,57.53],[1,2.18,49.92],[2,2.6,257.57]],"ltp":1.93,"tv":18.47,"id":5858055}]}]}
{"op":"mcm","clk":"1004637262","pt":1580656178417,"mc":[{"id":"1.168224477","rc":[{"batl":[[0,2.6,257.57],[1,2.18,0],[2,2.6,0]],"ltp":1.93,"tv":18.47,"id":5858055}]}]}
{"op":"mcm","clk":"1004637852","pt":1580656181414,"mc":[{"id":"1.168224477","rc":[{"batb":[[2,1.69,60.49]],"batl":[[0,1.79,74.96],[1,1.81,87.3]],"ltp":1.93,"tv":18.47,"id":5858055},{"batb":[[0,2.38,17.94],[1,2.1,25.57],[2,1.94,16.37]],"batl":[[0,2.48,27.73]],"ltp":1.76,"tv":179.38,"id":7444998}]}]}
{"op":"mcm","clk":"1004637909","pt":1580656181699,"mc":[{"id":"1.168224477","rc":[{"batl":[[2,1.85,42.01]],"ltp":1.93,"tv":18.47,"id":5858055},{"batb":[[1,2.18,35.29],[2,2.1,25.57]],"ltp":1.76,"tv":179.38,"id":7444998}]}]}
{"op":"mcm","clk":"1004638305","pt":1580656183702,"mc":[{"id":"1.168224477","rc":[{"batl":[[1,3,213.45]],"ltp":1.76,"tv":179.38,"id":7444998}]}]}
{"op":"mcm","clk":"1004639327","pt":1580656189119,"mc":[{"id":"1.168224477","rc":[{"trd":[[1.72,9.4]],"batb":[[0,1.72,78.32]],"ltp":1.72,"tv":27.88,"id":5858055}],"tv":207.26}]}
{"op":"mcm","clk":"1004642107","pt":1580656203415,"mc":[{"id":"1.168224477","rc":[{"batb":[[0,1.69,60.49],[1,1.43,46.26],[2,1.01,15.51]],"batl":[[0,1.85,42.01],[1,2.3,309.75],[2,1.85,0]],"ltp":1.72,"tv":27.88,"id":5858055},{"batb":[[0,2.18,35.29],[1,2.1,25.57],[2,1.01,15.51]],"ltp":1.76,"tv":179.38,"id":7444998}]}]}
{"op":"mcm","clk":"1004642301","pt":1580656204344,"mc":[{"id":"1.168224477","rc":[{"batb":[[0,1.43,46.26],[1,1.01,15.51],[2,1.01,0]],"batl":[[0,2.3,309.75],[1,2.3,0]],"ltp":1.72,"tv":27.88,"id":5858055},{"batb":[[0,2.1,25.57],[1,1.01,15.51],[2,1.01,0]],"batl":[[0,3,213.45],[1,3,0]],"ltp":1.76,"tv":179.38,"id":7444998}]}]}
{"op":"mcm","clk":"1004642701","pt":1580656206138,"mc":[{"id":"1.168224477","rc":[{"batb":[[0,1.47,74.08],[1,1.46,95.82],[2,1.43,46.26]],"batl":[[0,1.99,47.92],[1,2.02,93.84],[2,2.3,309.75]],"ltp":1.72,"tv":27.88,"id":5858055}]}]}
{"op":"mcm","clk":"1004642936","pt":1580656207226,"mc":[{"id":"1.168224477","rc":[{"batb":[[0,1.43,46.26],[1,1.01,15.51],[2,1.43,0]],"batl":[[0,2.3,309.75],[1,2.02,0],[2,2.3,0]],"ltp":1.72,"tv":27.88,"id":5858055}]}]}
{"op":"mcm","clk":"1004643545","pt":1580656210356,"mc":[{"id":"1.168224477","rc":[{"batb":[[0,1.66,102.42],[1,1.65,59.59],[2,1.43,46.26]],"batl":[[0,1.73,91.62],[1,1.75,97.39],[2,2.3,309.75]],"ltp":1.72,"tv":27.88,"id":5858055}]}]}
{"op":"mcm","clk":"1004644038","pt":1580656213027,"mc":[{"id":"1.168224477","rc":[{"batb":[[0,1.43,46.26],[1,1.01,15.51],[2,1.43,0]],"batl":[[0,2.3,309.75],[1,1.75,0],[2,2.3,0]],"ltp":1.72,"tv":27.88,"id":5858055}]}]}
{"op":"mcm","clk":"1004644598","pt":1580656215949,"mc":[{"id":"1.168224477","rc":[{"batb":[[0,1.47,74.08],[1,1.46,95.82],[2,1.43,46.26]],"batl":[[0,1.99,47.92],[1,2.02,93.84],[2,2.3,309.75]],"ltp":1.72,"tv":27.88,"id":5858055}]}]}
{"op":"mcm","clk":"1004651226","pt":1580656250701,"mc":[{"id":"1.168224477","rc":[{"trd":[[1.5,2.27]],"ltp":1.5,"tv":30.15,"id":5858055},{"trd":[[3,1.13]],"batl":[[0,3,212.32]],"ltp":3.0,"tv":180.52,"id":7444998}],"tv":210.67}]}
{"op":"mcm","clk":"1004658072","pt":1580656285106,"mc":[{"id":"1.168224477","rc":[{"batl":[[0,2.3,309.75],[1,2.02,0],[2,2.3,0]],"ltp":1.5,"tv":30.15,"id":5858055}]}]}
{"op":"mcm","clk":"1004658673","pt":1580656288384,"mc":[{"id":"1.168224477","rc":[{"batl":[[0,1.52,80.26]],"ltp":1.5,"tv":30.15,"id":5858055}]}]}
{"op":"mcm","clk":"1004658816","pt":1580656289191,"mc":[{"id":"1.168224477","rc":[{"batb":[[1,1.46,186.56]],"batl":[[1,1.58,42.01]],"ltp":1.5,"tv":30.15,"id":5858055},{"batb":[[0,3.05,22.98],[1,2.74,23.53],[2,2.44,17]],"batl":[[0,3.15,19.32]],"ltp":3.0,"tv":180.52,"id":7444998}]}]}
{"op":"mcm","clk":"1004659207","pt":1580656291186,"mc":[{"id":"1.168224477","rc":[{"batb":[[0,1.47,86.04]],"batl":[[0,1.52,134.02],[1,1.53,77.77],[2,1.58,42.01]],"ltp":1.5,"tv":30.15,"id":5858055},{"batl":[[1,3.9,157.36]],"ltp":3.0,"tv":180.52,"id":7444998}]}]}
{"op":"mcm","clk":"1004662974","pt":1580656310409,"mc":[{"id":"1.168224477","rc":[{"batb":[[0,1.18,131.79],[1,1.01,15.51],[2,1.43,0]],"batl":[[0,1.95,411.6],[1,1.53,0],[2,1.58,0]],"ltp":1.5,"tv":30.15,"id":5858055},{"batb":[[0,2.44,17],[1,1.01,15.51],[2,2.44,0]],"batl":[[0,3.9,157.36],[1,3.9,0]],"ltp":3.0,"tv":180.52,"id":7444998}]}]}
{"op":"mcm","clk":"1004663572","pt":1580656313438,"mc":[{"id":"1.168224477","rc":[{"batb":[[0,1.18,489.31],[1,1.17,174.86],[2,1.01,15.51]],"batl":[[0,1.78,86.82],[1,1.8,88.76]],"ltp":1.5,"tv":30.15,"id":5858055},{"batb":[[0,2.42,17.07]],"ltp":3.0,"tv":180.52,"id":7444998}]}]}
{"op":"mcm","clk":"1004666145","pt":1580656325430,"mc":[{"id":"1.168224477","rc":[{"batb":[[0,1.18,131.16],[1,1.01,15.51],[2,1.01,0]],"ltp":1.5,"tv":30.15,"id":5858055}]}]}
{"op":"mcm","clk":"1004666756","pt":1580656328358,"mc":[{"id":"1.168224477","rc":[{"trd":[[1.71,24.16]],"batb":[[0,1.71,51.68],[1,1.69,108.56],[2,1.18,131.16]],"ltp":1.71,"tv":54.31,"id":5858055},{"trd":[[2.42,17.07]],"batb":[[0,1.01,15.51],[1,1.01,0]],"ltp":2.42,"tv":197.59,"id":7444998}],"tv":251.9}]}
{"op":"mcm","clk":"1004666958","pt":1580656329354,"mc":[{"id":"1.168224477","rc":[{"batb":[[2,1.66,63.01]],"batl":[[2,1.82,42.01]],"ltp":1.71,"tv":54.31,"id":5858055},{"batb":[[0,2.22,33.61],[1,2.12,24.63],[2,1.01,15.51]],"batl":[[0,2.5,27.73]],"ltp":2.42,"tv":197.59,"id":7444998}]}]}
{"op":"mcm","clk":"1004667333","pt":1580656331266,"mc":[{"id":"1.168224477","rc":[{"batl":[[1,3,212.32]],"ltp":2.42,"tv":197.59,"id":7444998}]}]}
{"op":"mcm","clk":"1004667556","pt":1580656332373,"mc":[{"id":"1.168224477","rc":[{"batb":[[0,1.71,71.08]],"ltp":1.71,"tv":54.31,"id":5858055}]}]}
{"op":"mcm","clk":"1004670325","pt":1580656346275,"mc":[{"id":"1.168224477","rc":[{"batb":[[0,1.41,48],[1,1.01,15.51],[2,1.66,0]],"batl":[[0,2.3,311.23],[1,1.8,0],[2,1.82,0]],"ltp":1.71,"tv":54.31,"id":5858055},{"batb":[[0,2.12,24.63],[1,1.01,15.51],[2,1.01,0]],"batl":[[0,3,212.32],[1,3,0]],"ltp":2.42,"tv":197.59,"id":7444998}]}]}
{"op":"mcm","clk":"1004670890","pt":1580656349105,"mc":[{"id":"1.168224477","rc":[{"batb":[[0,1.42,46.89]],"ltp":1.71,"tv":54.31,"id":5858055},{"batb":[[0,2.08,25.34]],"ltp":2.42,"tv":197.59,"id":7444998}]}]}
{"op":"mcm","clk":"1004671296","pt":1580656351194,"mc":[{"id":"1.168224477","rc":[{"batb":[[0,1.65,92.95],[1,1.64,60.85],[2,1.42,46.89]],"batl":[[0,1.71,55.85],[1,1.73,101.28],[2,2.3,311.23]],"ltp":1.71,"tv":54.31,"id":5858055}]}]}
{"op":"mcm","clk":"1004672302","pt":1580656356191,"mc":[{"id":"1.168224477","rc":[{"batb":[[0,1.42,46.89],[1,1.01,15.51],[2,1.42,0]],"batl":[[0,2.3,311.23],[1,1.73,0],[2,2.3,0]],"ltp":1.71,"tv":54.31,"id":5858055}]}]}
{"op":"mcm","clk":"1004672945","pt":1580656359418,"mc":[{"id":"1.168224477","rc":[{"batb":[[0,1.46,91.08],[1,1.45,98.71],[2,1.42,46.89]],"ltp":1.71,"tv":54.31,"id":5858055}]}]}
{"op":"mcm","clk":"1004673449","pt":1580656361998,"mc":[{"id":"1.168224477","rc":[{"batl":[[0,1.51,139.42],[1,1.52,79.73]],"ltp":1.71,"tv":54.31,"id":5858055}]}]}
{"op":"mcm","clk":"1004673717","pt":1580656363411,"mc":[{"id":"1.168224477","rc":[{"batb":[[1,1.45,191.97]],"ltp":1.71,"tv":54.31,"id":5858055},{"batl":[[0,3.2,18.48]],"ltp":2.42,"tv":197.59,"id":7444998}]}]}
{"op":"mcm","clk":"1004673824","pt":1580656363896,"mc":[{"id":"1.168224477","rc":[{"batb":[[0,3,22.58],[1,2.4,16.92],[2,1.01,15.51]],"ltp":2.42,"tv":197.59,"id":7444998}]}]}
{"op":"mcm","clk":"1004674067","pt":1580656365209,"mc":[{"id":"1.168224477","rc":[{"batl":[[2,1.57,42.01]],"ltp":1.71,"tv":54.31,"id":5858055},{"batb":[[1,2.76,23.53],[2,2.4,16.92]],"batl":[[1,3.9,157.36]],"ltp":2.42,"tv":197.59,"id":7444998}]}]}
{"op":"mcm","clk":"1004676428","pt":1580656377739,"mc":[{"id":"1.168224477","rc":[{"batl":[[2,1.95,411.6]],"ltp":1.71,"tv":54.31,"id":5858055},{"batb":[[1,2.4,16.92],[2,1.01,15.51]],"ltp":2.42,"tv":197.59,"id":7444998}]}]}
{"op":"mcm","clk":"1004677024","pt":1580656381021,"mc":[{"id":"1.168224477","rc":[{"batl":[[2,1.56,42.01]],"ltp":1.71,"tv":54.31,"id":5858055},{"batb":[[1,2.78,23.53],[2,2.4,16.92]],"ltp":2.42,"tv":197.59,"id":7444998}]}]}
{"op":"mcm","clk":"1004677607","pt":1580656384258,"mc":[{"id":"1.168224477","rc":[{"batb":[[0,1.17,132.42],[1,1.01,15.51],[2,1.42,0]],"batl":[[0,1.95,411.6],[1,1.52,0],[2,1.56,0]],"ltp":1.71,"tv":54.31,"id":5858055},{"batb":[[0,2.4,16.76],[1,1.01,15.51],[2,2.4,0]],"batl":[[0,3.9,157.36],[1,3.9,0]],"ltp":2.42,"tv":197.59,"id":7444998}]}]}
{"op":"mcm","clk":"1004678230","pt":1580656387449,"mc":[{"id":"1.168224477","rc":[{"batb":[[0,1.18,277.09],[1,1.17,389.03],[2,1.01,15.51]],"batl":[[0,1.76,69.53],[1,1.78,92.1]],"ltp":1.71,"tv":54.31,"id":5858055}]}]}
{"op":"mcm","clk":"1004680384","pt":1580656398352,"mc":[{"id":"1.168224477","rc":[{"batl":[[0,1.21,286.68],[1,1.22,228.47]],"ltp":1.71,"tv":54.31,"id":5858055}]}]}
{"op":"mcm","clk":"1004680556","pt":1580656399260,"mc":[{"id":"1.168224477","rc":[{"batb":[[2,1.16,168.04]],"batl":[[0,1.21,328.69]],"ltp":1.71,"tv":54.31,"id":5858055},{"batb":[[0,5.6,18.95],[1,4.2,19.59],[2,1.01,15.51]],"batl":[[0,7,6.72]],"ltp":2.42,"tv":197.59,"id":7444998}]}]}
{"op":"mcm","clk":"1004680787","pt":1580656400344,"mc":[{"id":"1.168224477","rc":[{"batl":[[2,1.53,716.32]],"ltp":1.71,"tv":54.31,"id":5858055},{"batl":[[1,8.6,81.49]],"ltp":2.42,"tv":197.59,"id":7444998}]}]}
{"op":"mcm","clk":"1004685102","pt":1580656422395,"mc":[{"id":"1.168224477","rc":[{"batb":[[0,1.18,201.54]],"batl":[[0,1.21,291.23],[1,1.53,716.32],[2,1.53,0]],"ltp":1.71,"tv":54.31,"id":5858055}]}]}
{"op":"mcm","clk":"1004685713","pt":1580656425230,"mc":[{"id":"1.168224477","rc":[{"batb":[[1,1.17,464.88]],"batl":[[0,1.2,112.01],[1,1.21,291.23],[2,1.53,716.32]],"ltp":1.71,"tv":54.31,"id":5858055}]}]}
{"op":"mcm","clk":"1004686906","pt":1580656431385,"mc":[{"id":"1.168224477","rc":[{"batb":[[0,1.16,168.04],[1,1.13,174.67],[2,1.01,15.51]],"batl":[[0,1.21,42.01],[1,1.53,716.32],[2,1.53,0]],"ltp":1.71,"tv":54.31,"id":5858055},{"batb":[[0,5.6,8.4]],"ltp":2.42,"tv":197.59,"id":7444998}]}]}
{"op":"mcm","clk":"1004687081","pt":1580656432298,"mc":[{"id":"1.168224477","rc":[{"batb":[[0,1.13,174.67],[1,1.01,15.51],[2,1.01,0]],"batl":[[0,1.53,716.32],[1,1.53,0]],"ltp":1.71,"tv":54.31,"id":5858055},{"batb":[[0,4.2,19.59],[1,1.01,15.51],[2,1.01,0]],"batl":[[0,8.6,81.49],[1,8.6,0]],"ltp":2.42,"tv":197.59,"id":7444998}]}]}
{"op":"mcm","clk":"1004687522","pt":1580656434394,"mc":[{"id":"1.168224477","rc":[{"batb":[[0,1.14,338.09],[1,1.13,388.27],[2,1.01,15.51]],"batl":[[0,1.29,175.74],[1,1.3,161.41],[2,1.53,716.32]],"ltp":1.71,"tv":54.31,"id":5858055},{"batb":[[0,4.3,19.2],[1,4.2,19.59],[2,1.01,15.51]],"ltp":2.42,"tv":197.59,"id":7444998}]}]}
{"op":"mcm","clk":"1004687588","pt":1580656434714,"mc":[{"id":"1.168224477","rc":[{"batb":[[1,1.01,15.51],[2,1.01,0]],"ltp":2.42,"tv":197.59,"id":7444998}]}]}
{"op":"mcm","clk":"1004688359","pt":1580656438306,"mc":[{"id":"1.168224477","rc":[{"batb":[[0,1.13,174.67],[1,1.01,15.51],[2,1.01,0]],"batl":[[0,1.53,716.32],[1,1.3,0],[2,1.53,0]],"ltp":1.71,"tv":54.31,"id":5858055}]}]}
{"op":"mcm","clk":"1004689013","pt":1580656441327,"mc":[{"id":"1.168224477","rc":[{"batb":[[0,1.19,335.78],[1,1.18,192.54],[2,1.13,174.67]],"batl":[[0,1.22,199.08],[1,1.23,221.5]],"ltp":1.71,"tv":54.31,"id":5858055}]}]}
{"op":"mcm","clk":"1004689241","pt":1580656442202,"mc":[{"id":"1.168224477","rc":[{"batb":[[0,1.13,174.67],[1,1.01,15.51],[2,1.13,0]],"ltp":1.71,"tv":54.31,"id":5858055}]}]}
{"op":"mcm","clk":"1004689921","pt":1580656445408,"mc":[{"id":"1.168224477","rc":[{"batb":[[0,1.14,338.09],[1,1.13,388.27],[2,1.01,15.51]],"batl":[[0,1.29,175.74],[1,1.3,161.41]],"ltp":1.71,"tv":54.31,"id":5858055},{"batl":[[0,7.8,87.46]],"ltp":2.42,"tv":197.59,"id":7444998}]}]}
{"op":"mcm","clk":"1004691352","pt":1580656452420,"mc":[{"id":"1.168224477","rc":[{"batb":[[2,1.1,230.07]],"batl":[[0,1.16,152.2],[1,1.17,316.52]],"ltp":1.71,"tv":54.31,"id":5858055},{"batb":[[0,6.8,13.38],[1,5.2,12.12],[2,4.3,19.2]],"ltp":2.42,"tv":197.59,"id":7444998}]}]}
{"op":"mcm","clk":"1004691512","pt":1580656453239,"mc":[{"id":"1.168224477","rc":[{"batb":[[1,1.13,556.31]],"ltp":1.71,"tv":54.31,"id":5858055},{"batb":[[2,1.01,15.51]],"batl":[[0,8.4,5.04]],"ltp":2.42,"tv":197.59,"id":7444998}]}]}
{"op":"mcm","clk":"1004691840","pt":1580656454718,"mc":[{"id":"1.168224477","rc":[{"batl":[[1,11.5,69.8]],"ltp":2.42,"tv":197.59,"id":7444998}]}]}
{"op":"mcm","clk":"1004692140","pt":1580656456236,"mc":[{"id":"1.168224477","rc":[{"batl":[[2,1.47,805.53]],"ltp":1.71,"tv":54.31,"id":5858055}]}]}
{"op":"mcm","clk":"1004693777","pt":1580656464263,"mc":[{"id":"1.168224477","rc":[{"trd":[[1.14,24.58]],"batb":[[0,1.14,325.8]],"ltp":1.14,"tv":78.89,"id":5858055}],"tv":276.48}]}
{"op":"mcm","clk":"1004696906","pt":1580656479363,"mc":[{"id":"1.168224477","rc":[{"batb":[[0,1.13,342.71],[1,1.1,230.07],[2,1.01,15.51]],"batl":[[0,1.47,805.53],[1,1.17,0],[2,1.47,0]],"ltp":1.14,"tv":78.89,"id":5858055}]}]}
{"op":"mcm","clk":"1004697105","pt":1580656480313,"mc":[{"id":"1.168224477","rc":[{"batb":[[0,1.1,230.07],[1,1.01,15.51],[2,1.01,0]],"ltp":1.14,"tv":78.89,"id":5858055},{"batb":[[0,5.2,12.12],[1,1.01,15.51],[2,1.01,0]],"batl":[[0,11.5,69.8],[1,11.5,0]],"ltp":2.42,"tv":197.59,"id":7444998}]}]}
{"op":"mcm","clk":"1004697512","pt":1580656482316,"mc":[{"id":"1.168224477","rc":[{"batb":[[0,1.11,564.68],[1,1.1,230.07],[2,1.01,15.51]],"batl":[[0,1.22,148.76],[1,1.23,223.03],[2,1.47,805.53]],"ltp":1.14,"tv":78.89,"id":5858055}]}]}
{"op":"mcm","clk":"1004697946","pt":1580656484310,"mc":[{"id":"1.168224477","rc":[{"batb":[[0,1.1,230.07],[1,1.01,15.51],[2,1.01,0]],"batl":[[0,1.47,805.53],[1,1.23,0],[2,1.47,0]],"ltp":1.14,"tv":78.89,"id":5858055}]}]}
{"op":"mcm","clk":"1004698614","pt":1580656487414,"mc":[{"id":"1.168224477","rc":[{"batb":[[0,1.15,332.45],[1,1.14,214.45],[2,1.1,230.07]],"batl":[[0,1.17,108.56],[1,1.18,298.35],[2,1.47,805.53]],"ltp":1.14,"tv":78.89,"id":5858055}]}]}
{"op":"mcm","clk":"1004699341","pt":1580656490401,"mc":[{"id":"1.168224477","rc":[{"batl":[[0,9.8,74.92]],"ltp":2.42,"tv":197.59,"id":7444998}]}]}
{"op":"mcm","clk":"1004699995","pt":1580656493442,"mc":[{"id":"1.168224477","rc":[{"batb":[[0,1.1,230.07],[1,1.01,15.51],[2,1.1,0]],"batl":[[0,1.47,805.53],[1,1.18,0],[2,1.47,0]],"ltp":1.14,"tv":78.89,"id":5858055}]}]}
{"op":"mcm","clk":"1004700627","pt":1580656496120,"mc":[{"id":"1.168224477","rc":[{"batb":[[0,1.11,564.68],[1,1.1,230.07],[2,1.01,15.51]],"batl":[[0,1.22,148.76],[1,1.23,223.03],[2,1.47,805.53]],"ltp":1.14,"tv":78.89,"id":5858055}]}]}
{"op":"mcm","clk":"1004700877","pt":1580656497308,"mc":[{"id":"1.168224477","rc":[{"batl":[[0,1.47,805.53],[1,1.23,0],[2,1.47,0]],"ltp":1.14,"tv":78.89,"id":5858055}]}]}
{"op":"mcm","clk":"1004701561","pt":1580656500320,"mc":[{"id":"1.168224477","rc":[{"batb":[[2,1.09,274.36]],"batl":[[0,1.13,116.28],[1,1.14,396.44],[2,1.47,805.53]],"ltp":1.14,"tv":78.89,"id":5858055},{"batb":[[0,8.2,8.73],[1,6.4,14.48],[2,5.2,12.12]],"ltp":2.42,"tv":197.59,"id":7444998}]}]}
{"op":"mcm","clk":"1004701756","pt":1580656501262,"mc":[{"id":"1.168224477","rc":[{"batb":[[0,1.11,732.72]],"batl":[[2,1.15,42.01]],"ltp":1.14,"tv":78.89,"id":5858055},{"batb":[[1,7.6,5.88],[2,6.4,14.48]],"batl":[[0,9.8,4.2]],"ltp":2.42,"tv":197.59,"id":7444998}]}]}
{"op":"mcm","clk":"1004701992","pt":1580656502324,"mc":[{"id":"1.168224477","rc":[{"batl":[[1,12.5,65.69]],"ltp":2.42,"tv":197.59,"id":7444998}]}]}
{"op":"mcm","clk":"1004704240","pt":1580656512370,"mc":[{"id":"1.168224477","rc":[{"batb":[[0,1.11,168.04]],"batl":[[0,1.15,42.01],[1,1.47,805.53],[2,1.15,0]],"ltp":1.14,"tv":78.89,"id":5858055}]}]}
{"op":"mcm","clk":"1004704323","pt":1580656512757,"mc":[{"id":"1.168224477","rc":[{"batb":[[1,1.09,274.36],[2,1.01,15.51]],"ltp":1.14,"tv":78.89,"id":5858055},{"batb":[[0,7.6,5.88],[1,6.4,14.48],[2,1.01,15.51]],"ltp":2.42,"tv":197.59,"id":7444998}]}]}
{"op":"mcm","clk":"1004704652","pt":1580656514281,"mc":[{"id":"1.168224477","rc":[{"batb":[[0,1.09,274.36],[1,1.01,15.51],[2,1.01,0]],"batl":[[0,1.47,805.53],[1,1.47,0]],"ltp":1.14,"tv":78.89,"id":5858055},{"batb":[[0,6.4,14.48],[1,1.01,15.51],[2,1.01,0]],"batl":[[0,12.5,65.69],[1,12.5,0]],"ltp":2.42,"tv":197.59,"id":7444998}]}]}
{"op":"mcm","clk":"1004704869","pt":1580656515287,"mc":[{"id":"1.168224477","rc":[{"batb":[[0,1.1,339.44],[1,1.09,506.84],[2,1.01,15.51]],"batl":[[0,1.17,271.09],[1,1.18,262.38],[2,1.47,805.53]],"ltp":1.14,"tv":78.89,"id":5858055}]}]}
{"op":"mcm","clk":"1004705327","pt":1580656517256,"mc":[{"id":"1.168224477","rc":[{"batb":[[0,1.09,274.36],[1,1.01,15.51],[2,1.01,0]],"ltp":1.14,"tv":78.89,"id":5858055}]}]}
{"op":"mcm","clk":"1004706007","pt":1580656520277,"mc":[{"id":"1.168224477","rc":[{"batb":[[0,1.15,150.63],[1,1.14,397.86],[2,1.09,274.36]],"ltp":1.14,"tv":78.89,"id":5858055}]}]}
{"op":"mcm","clk":"1004706286","pt":1580656521328,"mc":[{"id":"1.168224477","rc":[{"batb":[[1,1.14,566.4],[2,1.1,224.95]],"batl":[[1,1.18,304.39]],"ltp":1.14,"tv":78.89,"id":5858055},{"batb":[[0,6.6,6.72],[1,6.4,14.48],[2,4.8,14.56]],"batl":[[0,8.4,5.04]],"ltp":2.42,"tv":197.59,"id":7444998}]}]}
{"op":"mcm","clk":"1004706877","pt":1580656524150,"mc":[{"id":"1.168224477","rc":[{"batl":[[1,9.8,74.92]],"ltp":2.42,"tv":197.59,"id":7444998}]}]}
{"op":"mcm","clk":"1004709537","pt":1580656535410,"mc":[{"id":"1.168224477","rc":[{"batb":[[0,1.14,168.54],[1,1.1,224.95],[2,1.01,15.51]],"batl":[[0,1.18,42.01],[1,1.47,805.53],[2,1.47,0]],"ltp":1.14,"tv":78.89,"id":5858055}]}]}
{"op":"mcm","clk":"1004709799","pt":1580656536370,"mc":[{"id":"1.168224477","rc":[{"batb":[[0,1.1,224.95],[1,1.01,15.51],[2,1.01,0]],"batl":[[0,1.47,805.53],[1,1.47,0]],"ltp":1.14,"tv":78.89,"id":5858055},{"batb":[[0,4.8,14.56],[1,1.01,15.51],[2,4.8,0]],"batl":[[0,9.8,74.92],[1,9.8,0]],"ltp":2.42,"tv":197.59,"id":7444998}]}]}
{"op":"mcm","clk":"1004710206","pt":1580656538294,"mc":[{"id":"1.168224477","rc":[{"batb":[[0,1.11,557.11],[1,1.1,224.95],[2,1.01,15.51]],"batl":[[0,1.24,119.37],[1,1.25,202.46],[2,1.47,805.53]],"ltp":1.14,"tv":78.89,"id":5858055}]}]}
{"op":"mcm","clk":"1004710347","pt":1580656538886,"mc":[{"id":"1.168224477","rc":[{"batb":[[0,1.1,224.95],[1,1.01,15.51],[2,1.01,0]],"batl":[[0,1.47,805.53],[1,1.25,0],[2,1.47,0]],"ltp":1.14,"tv":78.89,"id":5858055}]}]}
{"op":"mcm","clk":"1004710994","pt":1580656541781,"mc":[{"id":"1.168224477","rc":[{"batb":[[0,1.16,251.6],[1,1.15,291.24],[2,1.1,224.95]],"batl":[[0,1.18,137.64],[1,1.19,278.9],[2,1.47,805.53]],"ltp":1.14,"tv":78.89,"id":5858055}]}]}
{"op":"mcm","clk":"1004712257","pt":1580656547605,"mc":[{"id":"1.168224477","rc":[{"batb":[[0,1.1,224.95],[1,1.01,15.51],[2,1.1,0]],"batl":[[0,1.47,805.53],[1,1.19,0],[2,1.47,0]],"ltp":1.14,"tv":78.89,"id":5858055}]}]}
{"op":"mcm","clk":"1004712936","pt":1580656550512,"mc":[{"id":"1.168224477","rc":[{"batb":[[0,1.11,557.11],[1,1.1,224.95],[2,1.01,15.51]],"batl":[[0,1.24,119.37],[1,1.25,202.46],[2,1.47,805.53]],"ltp":1.14,"tv":78.89,"id":5858055}]}]}
{"op":"mcm","clk":"1004716377","pt":1580656566417,"mc":[{"id":"1.168224477","rc":[{"batb":[[0,1.1,224.95],[1,1.01,15.51],[2,1.01,0]],"ltp":1.14,"tv":78.89,"id":5858055}]}]}
{"op":"mcm","clk":"1004717044","pt":1580656569308,"mc":[{"id":"1.168224477","rc":[{"batb":[[0,1.22,81.55],[1,1.21,365.07],[2,1.19,168.04]],"batl":[[0,1.24,161.38]],"ltp":1.14,"tv":78.89,"id":5858055},{"batb":[[0,5.1,10.08],[1,4.8,14.56],[2,3.35,17.7]],"batl":[[0,6.2,7.56]],"ltp":2.42,"tv":197.59,"id":7444998}]}]}
{"op":"mcm","clk":"1004717221","pt":1580656570149,"mc":[{"id":"1.168224477","rc":[{"batl":[[0,1.24,119.37]],"ltp":1.14,"tv":78.89,"id":5858055}]}]}
{"op":"mcm","clk":"1004717650","pt":1580656572236,"mc":[{"id":"1.168224477","rc":[{"batl":[[1,1.25,244.47]],"ltp":1.14,"tv":78.89,"id":5858055},{"batl":[[1,7.2,91.7]],"ltp":2.42,"tv":197.59,"id":7444998}]}]}
{"op":"mcm","clk":"1004720732","pt":1580656586262,"mc":[{"id":"1.168224477","rc":[{"batb":[[0,1.21,106.46],[1,1.19,168.04],[2,1.14,167.36]],"batl":[[0,1.25,42.01],[1,1.47,805.53],[2,1.47,0]],"ltp":1.14,"tv":78.89,"id":5858055}]}]}
{"op":"mcm","clk":"1004720826","pt":1580656586749,"mc":[{"id":"1.168224477","rc":[{"batb":[[0,1.19,168.04],[1,1.14,167.36],[2,1.01,15.51]],"ltp":1.14,"tv":78.89,"id":5858055},{"batb":[[1,3.35,17.7],[2,1.01,15.51]],"ltp":2.42,"tv":197.59,"id":7444998}]}]}
{"op":"mcm","clk":"1004721368","pt":1580656589279,"mc":[{"id":"1.168224477","rc":[{"batb":[[0,1.14,611.93],[1,1.13,106.17]],"batl":[[0,1.41,86.89],[1,1.42,106.68],[2,1.47,805.53]],"ltp":1.14,"tv":78.89,"id":5858055},{"batb":[[0,3.35,17.7],[1,1.01,15.51],[2,1.01,0]],"batl":[[0,7.2,91.7],[1,7.2,0]],"ltp":2.42,"tv":197.59,"id":7444998}]}]}
{"op":"mcm","clk":"1004722192","pt":1580656593402,"mc":[{"id":"1.168224477","rc":[{"batl":[[0,1.47,805.53],[1,1.42,0],[2,1.47,0]],"ltp":1.14,"tv":78.89,"id":5858055}]}]}
{"op":"mcm","clk":"1004722832","pt":1580656596388,"mc":[{"id":"1.168224477","rc":[{"batl":[[0,1.17,376.85],[1,1.18,157.51],[2,1.47,805.53]],"ltp":1.14,"tv":78.89,"id":5858055}]}]}
{"op":"mcm","clk":"1004723044","pt":1580656597373,"mc":[{"id":"1.168224477","rc":[{"batb":[[2,1.1,241.16]],"ltp":1.14,"tv":78.89,"id":5858055},{"batb":[[0,6.4,14.63],[1,4.7,15.66],[2,3.35,17.7]],"ltp":2.42,"tv":197.59,"id":7444998}]}]}
{"op":"mcm","clk":"1004723071","pt":1580656597485,"mc":[{"id":"1.168224477","rc":[{"batb":[[1,1.13,274.21]],"batl":[[0,1.17,418.86]],"ltp":1.14,"tv":78.89,"id":5858055},{"batb":[[0,6.8,6.72],[1,6.4,14.63],[2,4.7,15.66]],"batl":[[0,8.6,5.04]],"ltp":2.42,"tv":197.59,"id":7444998}]}]}
{"op":"mcm","clk":"1004723401","pt":1580656599196,"mc":[{"id":"1.168224477","rc":[{"batl":[[1,11.5,69.8]],"ltp":2.42,"tv":197.59,"id":7444998}]}]}
{"op":"mcm","clk":"1004726295","pt":1580656612422,"mc":[{"id":"1.168224477","rc":[{"batb":[[0,1.14,167.36],[1,1.13,168.04]],"batl":[[0,1.17,42.01],[1,1.47,805.53],[2,1.47,0]],"ltp":1.14,"tv":78.89,"id":5858055}]}]}
{"op":"mcm","clk":"1004726429","pt":1580656612997,"mc":[{"id":"1.168224477","rc":[{"batb":[[0,1.13,168.04],[1,1.1,241.16],[2,1.01,15.51]],"ltp":1.14,"tv":78.89,"id":5858055},{"batb":[[1,4.7,15.66],[2,1.01,15.51]],"ltp":2.42,"tv":197.59,"id":7444998}]}]}
{"op":"mcm","clk":"1004726736","pt":1580656614408,"mc":[{"id":"1.168224477","rc":[{"batb":[[0,1.1,241.16],[1,1.01,15.51],[2,1.01,0]],"batl":[[0,1.47,805.53],[1,1.47,0]],"ltp":1.14,"tv":78.89,"id":5858055},{"batb":[[0,4.7,15.66],[1,1.01,15.51],[2,1.01,0]],"batl":[[0,11.5,69.8],[1,11.5,0]],"ltp":2.42,"tv":197.59,"id":7444998}]}]}
{"op":"mcm","clk":"1004726906","pt":1580656615276,"mc":[{"id":"1.168224477","rc":[{"batb":[[0,1.11,109.53],[1,1.1,700.44],[2,1.01,15.51]],"batl":[[0,1.25,151.63],[1,1.26,192.43],[2,1.47,805.53]],"ltp":1.14,"tv":78.89,"id":5858055}]}]}
{"op":"mcm","clk":"1004727684","pt":1580656618985,"mc":[{"id":"1.168224477","rc":[{"batl":[[0,1.47,805.53],[1,1.26,0],[2,1.47,0]],"ltp":1.14,"tv":78.89,"id":5858055}]}]}
{"op":"mcm","clk":"1004728485","pt":1580656622418,"mc":[{"id":"1.168224477","rc":[{"batl":[[0,1.12,115.19],[1,1.13,430.17],[2,1.47,805.53]],"ltp":1.14,"tv":78.89,"id":5858055}]}]}
{"op":"mcm","clk":"1004728691","pt":1580656623392,"mc":[{"id":"1.168224477","rc":[{"batb":[[2,1.07,321.57]],"batl":[[1,1.13,472.18]],"ltp":1.14,"tv":78.89,"id":5858055},{"batb":[[0,8.4,13.07],[1,7.6,10.31],[2,1.01,15.51]],"batl":[[0,11,4.2]],"ltp":2.42,"tv":197.59,"id":7444998}]}]}
{"op":"mcm","clk":"1004728769","pt":1580656623721,"mc":[{"id":"1.168224477","rc":[{"batb":[[0,8.4,8.03]],"ltp":2.42,"tv":197.59,"id":7444998}]}]}
{"op":"mcm","clk":"1004729149","pt":1580656625409,"mc":[{"id":"1.168224477","rc":[{"batb":[[0,8.6,5.04],[1,8.4,8.03],[2,7.6,10.31]],"batl":[[0,11.5,3.36]],"ltp":2.42,"tv":197.59,"id":7444998}]}]}
{"op":"mcm","clk":"1004729225","pt":1580656625746,"mc":[{"id":"1.168224477","rc":[{"batl":[[1,14,62.33]],"ltp":2.42,"tv":197.59,"id":7444998}]}]}
{"op":"mcm","clk":"1004732480","pt":1580656640834,"mc":[{"id":"1.168224477","rc":[{"trd":[[1.11,50.42]],"batb":[[0,1.11,84.32]],"ltp":1.11,"tv":129.31,"id":5858055}],"tv":326.9}]}
{"op":"mcm","clk":"1004733189","pt":1580656644247,"mc":[{"id":"1.168224477","rc":[{"batb":[[0,1.11,102.7]],"ltp":1.11,"tv":129.31,"id":5858055}]}]}
{"op":"mcm","clk":"1004734186","pt":1580656648934,"mc":[{"id":"1.168224477","rc":[{"trd":[[1.12,15.14]],"batl":[[0,1.12,107.62]],"ltp":1.12,"tv":144.45,"id":5858055}],"tv":342.04}]}
{"op":"mcm","clk":"1004742427","pt":1580656685202,"mc":[{"id":"1.168224477","rc":[{"batb":[[1,1.1,672.86]],"batl":[[0,1.12,88.17]],"ltp":1.12,"tv":144.45,"id":5858055}]}]}
{"op":"mcm","clk":"1004743148","pt":1580656688123,"mc":[{"id":"1.168224477","rc":[{"batb":[[0,1.11,136.84],[1,1.1,650.76]],"batl":[[0,1.13,472.18],[1,1.47,805.53],[2,1.47,0]],"ltp":1.12,"tv":144.45,"id":5858055}]}]}
{"op":"mcm","clk":"1004743924","pt":1580656691439,"mc":[{"id":"1.168224477","rc":[{"batb":[[0,1.11,158.74]],"batl":[[0,1.13,538.2]],"ltp":1.12,"tv":144.45,"id":5858055}]}]}
{"op":"mcm","clk":"1004746679","pt":1580656704154,"mc":[{"id":"1.168224477","rc":[{"batb":[[0,1.07,321.57],[1,1.01,15.51],[2,1.07,0]],"batl":[[0,1.13,42.01]],"ltp":1.12,"tv":144.45,"id":5858055},{"batb":[[1,7.6,10.31],[2,1.01,15.51]],"ltp":2.42,"tv":197.59,"id":7444998}]}]}
{"op":"mcm","clk":"1004746799","pt":1580656704744,"mc":[{"id":"1.168224477","rc":[{"batl":[[0,1.47,805.53],[1,1.47,0]],"ltp":1.12,"tv":144.45,"id":5858055},{"batb":[[0,7.6,10.31],[1,1.01,15.51],[2,1.01,0]],"batl":[[0,14,62.33],[1,14,0]],"ltp":2.42,"tv":197.59,"id":7444998}]}]}
{"op":"mcm","clk":"1004747209","pt":1580656706620,"mc":[{"id":"1.168224477","rc":[{"batb":[[0,1.08,580.34],[1,1.07,321.57],[2,1.01,15.51]],"batl":[[0,1.14,244.14],[1,1.15,303],[2,1.47,805.53]],"ltp":1.12,"tv":144.45,"id":5858055}]}]}
{"op":"mcm","clk":"1004747429","pt":1580656707850,"mc":[{"id":"1.168224477","rc":[{"batb":[[0,1.07,321.57],[1,1.01,15.51],[2,1.01,0]],"ltp":1.12,"tv":144.45,"id":5858055}]}]}
{"op":"mcm","clk":"1004748090","pt":1580656711011,"mc":[{"id":"1.168224477","rc":[{"batb":[[0,1.12,364.48],[1,1.11,196.89],[2,1.07,321.57]],"ltp":1.12,"tv":144.45,"id":5858055}]}]}
{"op":"mcm","clk":"1004748235","pt":1580656711716,"mc":[{"id":"1.168224477","rc":[{"batb":[[1,1.11,404.61],[2,1.09,257.6]],"ltp":1.12,"tv":144.45,"id":5858055},{"batb":[[0,7.8,5.88],[1,7.6,10.31],[2,7,12.43]],"batl":[[0,10.5,4.2]],"ltp":2.42,"tv":197.59,"id":7444998}]}]}
{"op":"mcm","clk":"1004748772","pt":1580656714363,"mc":[{"id":"1.168224477","rc":[{"batl":[[1,12.5,65.69]],"ltp":2.42,"tv":197.59,"id":7444998}]}]}
{"op":"mcm","clk":"1004750288","pt":1580656721194,"mc":[{"id":"1.168224477","rc":[{"batb":[[0,1.09,257.6],[1,1.01,15.51],[2,1.09,0]],"batl":[[0,1.15,139.03],[1,1.47,805.53],[2,1.47,0]],"ltp":1.12,"tv":144.45,"id":5858055},{"batb":[[0,7,12.43],[1,1.01,15.51],[2,7,0]],"batl":[[0,12.5,65.69],[1,12.5,0]],"ltp":2.42,"tv":197.59,"id":7444998}]}]}
{"op":"mcm","clk":"1004750767","pt":1580656723398,"mc":[{"id":"1.168224477","rc":[{"batb":[[0,1.1,459.21],[1,1.09,369.19],[2,1.01,15.51]],"batl":[[1,1.16,337.31],[2,1.47,805.53]],"ltp":1.12,"tv":144.45,"id":5858055}]}]}
{"op":"mcm","clk":"1004750966","pt":1580656724322,"mc":[{"id":"1.168224477","rc":[{"batb":[[0,1.09,257.6],[1,1.01,15.51],[2,1.01,0]],"batl":[[1,1.47,805.53],[2,1.47,0]],"ltp":1.12,"tv":144.45,"id":5858055}]}]}
{"op":"mcm","clk":"1004751389","pt":1580656726405,"mc":[{"id":"1.168224477","rc":[{"batb":[[0,1.12,170.6],[1,1.11,392.52],[2,1.09,257.6]],"batl":[[0,1.14,413.38],[1,1.15,139.03],[2,1.47,805.53]],"ltp":1.12,"tv":144.45,"id":5858055}]}]}
{"op":"mcm","clk":"1004751970","pt":1580656729020,"mc":[{"id":"1.168224477","rc":[{"batb":[[0,1.09,257.6],[1,1.01,15.51],[2,1.09,0]],"batl":[[0,1.15,139.03],[1,1.47,805.53],[2,1.47,0]],"ltp":1.12,"tv":144.45,"id":5858055}]}]}
{"op":"mcm","clk":"1004752665","pt":1580656732237,"mc":[{"id":"1.168224477","rc":[{"batb":[[0,1.1,459.46],[1,1.09,368.94],[2,1.01,15.51]],"batl":[[0,1.47,805.53],[1,1.47,0]],"ltp":1.12,"tv":144.45,"id":5858055}]}]}
{"op":"mcm","clk":"1004753301","pt":1580656735350,"mc":[{"id":"1.168224477","rc":[{"batl":[[0,1.12,325.92],[1,1.13,231.62],[2,1.47,805.53]],"ltp":1.12,"tv":144.45,"id":5858055}]}]}
{"op":"mcm","clk":"1004753468","pt":1580656736053,"mc":[{"id":"1.168224477","rc":[{"batb":[[1,1.09,536.98],[2,1.06,368.7]],"ltp":1.12,"tv":144.45,"id":5858055},{"batb":[[0,8.8,12.28],[1,7.6,10.07],[2,1.01,15.51]],"batl":[[0,11.5,3.36],[1,12.5,65.69]],"ltp":2.42,"tv":197.59,"id":7444998}]}]}
{"op":"mcm","clk":"1004756124","pt":1580656748346,"mc":[{"id":"1.168224477","rc":[{"batb":[[0,1.09,168.04],[1,1.06,367.29],[2,1.01,15.51]],"batl":[[0,1.47,805.53],[1,1.13,0],[2,1.47,0]],"ltp":1.12,"tv":144.45,"id":5858055},{"batb":[[0,8.8,5.04]],"ltp":2.42,"tv":197.59,"id":7444998}]}]}
{"op":"mcm","clk":"1004756218","pt":1580656748769,"mc":[{"id":"1.168224477","rc":[{"batb":[[0,1.06,367.29],[1,1.01,15.51],[2,1.01,0]],"ltp":1.12,"tv":144.45,"id":5858055},{"batb":[[0,7.6,10.07],[1,1.01,15.51],[2,1.01,0]],"batl":[[0,12.5,65.69],[1,12.5,0]],"ltp":2.42,"tv":197.59,"id":7444998}]}]}
{"op":"mcm","clk":"1004756757","pt":1580656751328,"mc":[{"id":"1.168224477","rc":[{"batl":[[0,1.14,324.24],[1,1.15,223.59],[2,1.47,805.53]],"ltp":1.12,"tv":144.45,"id":5858055}]}]}
{"op":"mcm","clk":"1004757396","pt":1580656754341,"mc":[{"id":"1.168224477","rc":[{"batb":[[0,1.12,272.66],[1,1.11,499.61],[2,1.09,271.61]],"ltp":1.12,"tv":144.45,"id":5858055},{"batb":[[1,6.8,12.59],[2,1.01,15.51]],"ltp":2.42,"tv":197.59,"id":7444998}]}]}
{"op":"mcm","clk":"1004757695","pt":1580656755763,"mc":[{"id":"1.168224477","rc":[{"batl":[[0,1.14,366.25]],"ltp":1.12,"tv":144.45,"id":5858055},{"batb":[[0,8,5.88],[1,7.6,10.07],[2,6.8,12.59]],"batl":[[0,10.5,4.2],[1,12.5,65.69]],"ltp":2.42,"tv":197.59,"id":7444998}]}]}
{"op":"mcm","clk":"1004759110","pt":1580656762429,"mc":[{"id":"1.168224477","rc":[{"batb":[[0,1.09,271.61],[1,1.01,15.51],[2,1.09,0]],"batl":[[0,1.14,42.01],[1,1.15,126.05]],"ltp":1.12,"tv":144.45,"id":5858055},{"batb":[[1,6.8,12.59],[2,1.01,15.51]],"ltp":2.42,"tv":197.59,"id":7444998}]}]}
{"op":"mcm","clk":"1004759181","pt":1580656762762,"mc":[{"id":"1.168224477","rc":[{"batl":[[0,1.15,126.05],[1,1.47,805.53],[2,1.47,0]],"ltp":1.12,"tv":144.45,"id":5858055},{"batb":[[0,6.8,12.59],[1,1.01,15.51],[2,1.01,0]],"batl":[[0,12.5,65.69],[1,12.5,0]],"ltp":2.42,"tv":197.59,"id":7444998}]}]}
{"op":"mcm","clk":"1004759760","pt":1580656765448,"mc":[{"id":"1.168224477","rc":[{"batb":[[0,1.1,148.53],[1,1.09,696.73],[2,1.01,15.51]],"batl":[[1,1.16,337.89],[2,1.47,805.53]],"ltp":1.12,"tv":144.45,"id":5858055}]}]}
{"op":"mcm","clk":"1004759848","pt":1580656765871,"mc":[{"id":"1.168224477","rc":[{"batb":[[0,1.09,271.61],[1,1.01,15.51],[2,1.01,0]],"ltp":1.12,"tv":144.45,"id":5858055}]}]}
{"op":"mcm","clk":"1004760537","pt":1580656769045,"mc":[{"id":"1.168224477","rc":[{"batb":[[0,1.13,425.35],[1,1.12,130.46],[2,1.09,271.61]],"ltp":1.12,"tv":144.45,"id":5858055}]}]}
{"op":"mcm","clk":"1004760839","pt":1580656770370,"mc":[{"id":"1.168224477","rc":[{"batb":[[0,1.13,609.07],[2,1.11,210.95]],"ltp":1.12,"tv":144.45,"id":5858055},{"batb":[[0,7.4,5.88],[1,6.8,12.59],[2,6.6,14.4]],"batl":[[0,9.8,4.2]],"ltp":2.42,"tv":197.59,"id":7444998}]}]}
{"op":"mcm","clk":"1004761148","pt":1580656771982,"mc":[{"id":"1.168224477","rc":[{"batl":[[1,11.5,69.8]],"ltp":2.42,"tv":197.59,"id":7444998}]}]}
{"op":"mcm","clk":"1004761428","pt":1580656773256,"mc":[{"id":"1.168224477","rc":[{"batl":[[0,11.5,69.8],[1,11.5,0]],"ltp":2.42,"tv":197.59,"id":7444998}]}]}
{"op":"mcm","clk":"1004762123","pt":1580656776252,"mc":[{"id":"1.168224477","rc":[{"batl":[[0,9.6,4.2],[1,11.5,69.8]],"ltp":2.42,"tv":197.59,"id":7444998}]}]}
{"op":"mcm","clk":"1004762565","pt":1580656778348,"mc":[{"id":"1.168224477","rc":[{"batb":[[0,1.12,130.46],[1,1.11,210.95],[2,1.01,15.51]],"batl":[[0,1.16,195.03],[1,1.47,805.53],[2,1.47,0]],"ltp":1.12,"tv":144.45,"id":5858055},{"batb":[[1,6.6,14.4],[2,1.01,15.51]],"ltp":2.42,"tv":197.59,"id":7444998}]}]}
{"op":"mcm","clk":"1004762655","pt":1580656778769,"mc":[{"id":"1.168224477","rc":[{"batb":[[0,6.6,14.4],[1,1.01,15.51],[2,1.01,0]],"batl":[[0,11.5,69.8],[1,11.5,0]],"ltp":2.42,"tv":197.59,"id":7444998}]}]}
{"op":"mcm","clk":"1004763239","pt":1580656781361,"mc":[{"id":"1.168224477","rc":[{"batb":[[0,1.12,324.22],[1,1.11,448.46]],"batl":[[1,1.17,312.43],[2,1.47,805.53]],"ltp":1.12,"tv":144.45,"id":5858055}]}]}
{"op":"mcm","clk":"1004763424","pt":1580656782180,"mc":[{"id":"1.168224477","rc":[{"batb":[[0,1.11,210.95],[1,1.01,15.51],[2,1.01,0]],"ltp":1.12,"tv":144.45,"id":5858055}]}]}
{"op":"mcm","clk":"1004764106","pt":1580656785356,"mc":[{"id":"1.168224477","rc":[{"batb":[[0,1.14,284.64],[1,1.13,267.5],[2,1.11,210.95]],"ltp":1.12,"tv":144.45,"id":5858055}]}]}
{"op":"mcm","clk":"1004764320","pt":1580656786246,"mc":[{"id":"1.168224477","rc":[{"batb":[[0,1.14,454.28],[2,1.12,168.04]],"batl":[[0,1.16,237.04]],"ltp":1.12,"tv":144.45,"id":5858055},{"batb":[[0,7,6.72],[1,6.6,14.4],[2,4.6,15.97]],"batl":[[0,9.2,5.04],[1,11.5,69.8]],"ltp":2.42,"tv":197.59,"id":7444998}]}]}
{"op":"mcm","clk":"1004769777","pt":1580656811011,"mc":[{"id":"1.168224477","rc":[{"trd":[[1.14,36.7]],"batb":[[0,1.14,448.22]],"ltp":1.14,"tv":156.57,"id":5858055}],"tv":354.16}]}
{"op":"mcm","clk":"1004769985","pt":1580656811916,"mc":[{"id":"1.168224477","rc":[{"batb":[[0,1.14,426.12]],"ltp":1.14,"tv":156.57,"id":5858055}]}]}
{"op":"mcm","clk":"1004770776","pt":1580656815413,"mc":[{"id":"1.168224477","rc":[{"batb":[[1,1.13,295.91]],"batl":[[0,1.16,264.75]],"ltp":1.14,"tv":156.57,"id":5858055}]}]}
{"op":"mcm","clk":"1004772372","pt":1580656822336,"mc":[{"id":"1.168224477","rc":[{"batb":[[0,1.14,169.64],[1,1.12,168.04],[2,1.1,245.8]],"batl":[[0,1.16,42.01],[1,1.47,805.53],[2,1.47,0]],"ltp":1.14,"tv":156.57,"id":5858055}]}]}
{"op":"mcm","clk":"1004772932","pt":1580656825117,"mc":[{"id":"1.168224477","rc":[{"batb":[[2,1.1,638.29]],"batl":[[1,1.25,193.4],[2,1.26,190.93]],"ltp":1.14,"tv":156.57,"id":5858055}]}]}
{"op":"mcm","clk":"1004776160","pt":1580656840078,"mc":[{"id":"1.168224477","rc":[{"batb":[[0,1.12,168.04],[1,1.1,638.29],[2,1.09,178.92]],"ltp":1.14,"tv":156.57,"id":5858055},{"batb":[[1,4.6,15.97],[2,1.01,15.51]],"ltp":2.42,"tv":197.59,"id":7444998}]}]}
{"op":"mcm","clk":"1004776408","pt":1580656841147,"mc":[{"id":"1.168224477","rc":[{"batb":[[0,1.1,638.29],[1,1.09,178.92],[2,1.01,15.51]],"batl":[[0,1.25,193.4],[1,1.26,190.93],[2,1.47,805.53]],"ltp":1.14,"tv":156.57,"id":5858055},{"batb":[[0,4.6,15.97],[1,1.01,15.51],[2,1.01,0]],"batl":[[0,11.5,69.8],[1,11.5,0]],"ltp":2.42,"tv":197.59,"id":7444998}]}]}
{"op":"mcm","clk":"1004776938","pt":1580656843441,"mc":[{"id":"1.168224477","rc":[{"batb":[[0,1.1,392.49],[1,1.09,427.95]],"batl":[[0,1.47,805.53],[1,1.26,0],[2,1.47,0]],"ltp":1.14,"tv":156.57,"id":5858055},{"batb":[[0,4.7,15.66]],"ltp":2.42,"tv":197.59,"id":7444998}]}]}
{"op":"mcm","clk":"1004777833","pt":1580656847132,"mc":[{"id":"1.168224477","rc":[{"batb":[[2,1.06,356.04]],"batl":[[0,1.12,386.63],[1,1.13,171.45]],"ltp":1.14,"tv":156.57,"id":5858055},{"batb":[[0,8.6,7.63],[1,6,17.07],[2,1.01,15.51]],"ltp":2.42,"tv":197.59,"id":7444998}]}]}
{"op":"mcm","clk":"1004777968","pt":1580656847753,"mc":[{"id":"1.168224477","rc":[{"batb":[[1,1.09,595.99]],"ltp":1.14,"tv":156.57,"id":5858055},{"batl":[[0,12,3.36]],"ltp":2.42,"tv":197.59,"id":7444998}]}]}
{"op":"mcm","clk":"1004778400","pt":1580656849649,"mc":[{"id":"1.168224477","rc":[{"batl":[[2,1.4,930.11]],"ltp":1.14,"tv":156.57,"id":5858055},{"batl":[[1,17,57.12]],"ltp":2.42,"tv":197.59,"id":7444998}]}]}
{"op":"mcm","clk":"1004780143","pt":1580656857302,"mc":[{"id":"1.168224477","rc":[{"batb":[[0,1.09,417.07],[1,1.06,356.04],[2,1.01,15.51]],"batl":[[0,1.4,930.11],[1,1.13,0],[2,1.4,0]],"ltp":1.14,"tv":156.57,"id":5858055}]}]}
{"op":"mcm","clk":"1004780407","pt":1580656858388,"mc":[{"id":"1.168224477","rc":[{"batb":[[0,1.09,168.04]],"ltp":1.14,"tv":156.57,"id":5858055},{"batb":[[0,6,17.07],[1,1.01,15.51],[2,1.01,0]],"ltp":2.42,"tv":197.59,"id":7444998}]}]}
{"op":"mcm","clk":"1004780488","pt":1580656858771,"mc":[{"id":"1.168224477","rc":[{"batb":[[0,1.06,356.04],[1,1.01,15.51],[2,1.01,0]],"ltp":1.14,"tv":156.57,"id":5858055},{"batl":[[0,17,57.12],[1,17,0]],"ltp":2.42,"tv":197.59,"id":7444998}]}]}
{"op":"mcm","clk":"1004780860","pt":1580656860399,"mc":[{"id":"1.168224477","rc":[{"batb":[[0,1.07,585.77],[1,1.06,356.04],[2,1.01,15.51]],"batl":[[0,1.18,271.71],[1,1.19,257.27],[2,1.4,930.11]],"ltp":1.14,"tv":156.57,"id":5858055}]}]}
{"op":"mcm","clk":"1004781349","pt":1580656862296,"mc":[{"id":"1.168224477","rc":[{"batb":[[0,1.06,356.04],[1,1.01,15.51],[2,1.01,0]],"batl":[[0,1.4,930.11],[1,1.19,0],[2,1.4,0]],"ltp":1.14,"tv":156.57,"id":5858055}]}]}
{"op":"mcm","clk":"1004782092","pt":1580656865309,"mc":[{"id":"1.168224477","rc":[{"batb":[[0,1.11,394.23],[1,1.1,171.97],[2,1.06,356.04]],"batl":[[0,1.13,296.61],[1,1.14,255.78],[2,1.4,930.11]],"ltp":1.14,"tv":156.57,"id":5858055}]}]}
{"op":"mcm","clk":"1004782800","pt":1580656868308,"mc":[{"id":"1.168224477","rc":[{"batb":[[0,1.06,356.04],[1,1.01,15.51],[2,1.06,0]],"batl":[[0,1.4,930.11],[1,1.14,0],[2,1.4,0]],"ltp":1.14,"tv":156.57,"id":5858055}]}]}
{"op":"mcm","clk":"1004783025","pt":1580656869193,"mc":[{"id":"1.168224477","rc":[{"batl":[[0,14,62.33]],"ltp":2.42,"tv":197.59,"id":7444998}]}]}
{"op":"mcm","clk":"1004783548","pt":1580656871432,"mc":[{"id":"1.168224477","rc":[{"batb":[[0,1.07,585.77],[1,1.06,356.04],[2,1.01,15.51]],"batl":[[0,1.18,272.98],[1,1.19,256.01],[2,1.4,930.11]],"ltp":1.14,"tv":156.57,"id":5858055}]}]}
{"op":"mcm","clk":"1004783921","pt":1580656872927,"mc":[{"id":"1.168224477","rc":[{"batb":[[0,1.06,356.04],[1,1.01,15.51],[2,1.01,0]],"ltp":1.14,"tv":156.57,"id":5858055}]}]}
{"op":"mcm","clk":"1004784654","pt":1580656876118,"mc":[{"id":"1.168224477","rc":[{"batb":[[0,1.16,100.36],[1,1.15,382.57],[2,1.06,356.04]],"ltp":1.14,"tv":156.57,"id":5858055}]}]}
{"op":"mcm","clk":"1004784874","pt":1580656877131,"mc":[{"id":"1.168224477","rc":[{"batb":[[1,1.15,534.58],[2,1.1,237.78]],"ltp":1.14,"tv":156.57,"id":5858055},{"batb":[[1,4.1,21.4],[2,1.01,15.51]],"ltp":2.42,"tv":197.59,"id":7444998}]}]}
{"op":"mcm","clk":"1004785036","pt":1580656877834,"mc":[{"id":"1.168224477","rc":[{"batl":[[0,1.18,314.99]],"ltp":1.14,"tv":156.57,"id":5858055},{"batb":[[0,6.6,6.72],[1,6,17.07],[2,4.1,21.4]],"batl":[[0,8.4,5.04]],"ltp":2.42,"tv":197.59,"id":7444998}]}]}
{"op":"mcm","clk":"1004785241","pt":1580656878709,"mc":[{"id":"1.168224477","rc":[{"batl":[[1,9.8,74.92]],"ltp":2.42,"tv":197.59,"id":7444998}]}]}
{"op":"mcm","clk":"1004788587","pt":1580656893342,"mc":[{"id":"1.168224477","rc":[{"batb":[[0,1.1,237.78],[1,1.01,15.51],[2,1.1,0]],"batl":[[0,1.18,42.01],[1,1.4,930.11],[2,1.4,0]],"ltp":1.14,"tv":156.57,"id":5858055},{"batb":[[1,4.1,21.4],[2,1.01,15.51]],"ltp":2.42,"tv":197.59,"id":7444998}]}]}
{"op":"mcm","clk":"1004789017","pt":1580656895255,"mc":[{"id":"1.168224477","rc":[{"batl":[[0,1.4,930.11],[1,1.4,0]],"ltp":1.14,"tv":156.57,"id":5858055},{"trd":[[6.6,6]],"batb":[[0,4.1,21.4],[1,1.01,15.51],[2,1.01,0]],"batl":[[0,9.8,74.92],[1,9.8,0]],"ltp":6.6,"tv":203.59,"id":7444998}],"tv":360.16}]}
{"op":"mcm","clk":"1004789231","pt":1580656896187,"mc":[{"id":"1.168224477","rc":[{"batb":[[0,1.1,807.57]],"batl":[[0,1.3,199.42],[1,1.31,154.17],[2,1.4,930.11]],"ltp":1.14,"tv":156.57,"id":5858055}]}]}
{"op":"mcm","clk":"1004790880","pt":1580656903147,"mc":[{"id":"1.168224477","rc":[{"batl":[[0,1.4,930.11],[1,1.31,0],[2,1.4,0]],"ltp":1.14,"tv":156.57,"id":5858055}]}]}
{"op":"mcm","clk":"1004791625","pt":1580656906442,"mc":[{"id":"1.168224477","rc":[{"batl":[[0,1.12,196.64],[1,1.13,359.76],[2,1.4,930.11]],"ltp":1.14,"tv":156.57,"id":5858055}]}]}
{"op":"mcm","clk":"1004791818","pt":1580656907281,"mc":[{"id":"1.168224477","rc":[{"batb":[[1,1.06,370.2],[2,1.01,15.51]],"ltp":1.14,"tv":156.57,"id":5858055},{"batb":[[0,8.4,8.18],[1,5.6,10.54],[2,1.01,15.51]],"ltp":6.6,"tv":203.59,"id":7444998}]}]}
{"op":"mcm","clk":"1004791953","pt":1580656907869,"mc":[{"id":"1.168224477","rc":[{"batb":[[1,1.09,168.04],[2,1.06,370.2]],"ltp":1.14,"tv":156.57,"id":5858055},{"batb":[[0,8.8,5.04],[1,8.4,8.18],[2,5.6,10.54]],"batl":[[0,11.5,3.36]],"ltp":6.6,"tv":203.59,"id":7444998}]}]}
{"op":"mcm","clk":"1004792276","pt":1580656909264,"mc":[{"id":"1.168224477","rc":[{"batl":[[1,14,62.33]],"ltp":6.6,"tv":203.59,"id":7444998}]}]}
{"op":"mcm","clk":"1004795289","pt":1580656923287,"mc":[{"id":"1.168224477","rc":[{"batb":[[0,1.09,168.04],[1,1.06,370.2],[2,1.01,15.51]],"batl":[[0,1.4,930.11],[1,1.13,0],[2,1.4,0]],"ltp":1.14,"tv":156.57,"id":5858055},{"batb":[[1,5.6,10.31],[2,1.01,15.51]],"ltp":6.6,"tv":203.59,"id":7444998}]}]}
{"op":"mcm","clk":"1004795661","pt":1580656924914,"mc":[{"id":"1.168224477","rc":[{"batb":[[0,1.06,370.2],[1,1.01,15.51],[2,1.01,0]],"ltp":1.14,"tv":156.57,"id":5858055},{"batb":[[0,5.6,10.31],[1,1.01,15.51],[2,1.01,0]],"batl":[[0,14,62.33],[1,14,0]],"ltp":6.6,"tv":203.59,"id":7444998}]}]}
{"op":"mcm","clk":"1004795944","pt":1580656926191,"mc":[{"id":"1.168224477","rc":[{"batb":[[0,1.07,540.45],[1,1.06,370.2],[2,1.01,15.51]],"batl":[[0,1.2,264.81],[1,1.21,243.59],[2,1.4,930.11]],"ltp":1.14,"tv":156.57,"id":5858055}]}]}
{"op":"mcm","clk":"1004796676","pt":1580656929435,"mc":[{"id":"1.168224477","rc":[{"batb":[[0,1.06,370.2],[1,1.01,15.51],[2,1.01,0]],"batl":[[0,1.4,930.11],[1,1.21,0],[2,1.4,0]],"ltp":1.14,"tv":156.57,"id":5858055}]}]}
{"op":"mcm","clk":"1004797341","pt":1580656932423,"mc":[{"id":"1.168224477","rc":[{"batb":[[0,1.12,184.21],[1,1.11,378.78],[2,1.06,370.2]],"batl":[[0,1.14,404.77],[1,1.15,143.76],[2,1.4,930.11]],"ltp":1.14,"tv":156.57,"id":5858055}]}]}
{"op":"mcm","clk":"1004797517","pt":1580656933311,"mc":[{"id":"1.168224477","rc":[{"batb":[[0,1.06,370.2],[1,1.01,15.51],[2,1.06,0]],"batl":[[0,1.4,930.11],[1,1.15,0],[2,1.4,0]],"ltp":1.14,"tv":156.57,"id":5858055}]}]}
{"op":"mcm","clk":"1004798131","pt":1580656936241,"mc":[{"id":"1.168224477","rc":[{"batb":[[0,1.07,539.15],[1,1.06,370.2],[2,1.01,15.51]],"batl":[[0,1.2,265.94],[1,1.21,243.6],[2,1.4,930.11]],"ltp":1.14,"tv":156.57,"id":5858055}]}]}
{"op":"mcm","clk":"1004798210","pt":1580656936608,"mc":[{"id":"1.168224477","rc":[{"batb":[[0,1.06,370.2],[1,1.01,15.51],[2,1.01,0]],"ltp":1.14,"tv":156.57,"id":5858055}]}]}
{"op":"mcm","clk":"1004798939","pt":1580656940327,"mc":[{"id":"1.168224477","rc":[{"batb":[[0,1.17,495.63],[1,1.16,176.52],[2,1.09,251.7]],"ltp":1.14,"tv":156.57,"id":5858055},{"batb":[[0,6.2,7.56],[1,5.6,10.31],[2,3.5,15.5]],"ltp":6.6,"tv":203.59,"id":7444998}]}]}
{"op":"mcm","clk":"1004798965","pt":1580656940453,"mc":[{"id":"1.168224477","rc":[{"batb":[[2,1.15,168.04]],"ltp":1.14,"tv":156.57,"id":5858055},{"batl":[[0,7.6,5.88]],"ltp":6.6,"tv":203.59,"id":7444998}]}]}
{"op":"mcm","clk":"1004799383","pt":1580656942522,"mc":[{"id":"1.168224477","rc":[{"batl":[[1,8.6,81.49]],"ltp":6.6,"tv":203.59,"id":7444998}]}]}
{"op":"mcm","clk":"1004802069","pt":1580656956149,"mc":[{"id":"1.168224477","rc":[{"batb":[[0,1.15,168.04],[1,1.09,251.7],[2,1.01,15.51]],"batl":[[0,1.4,930.11],[1,1.21,0],[2,1.4,0]],"ltp":1.14,"tv":156.57,"id":5858055},{"batb":[[1,3.5,15.5],[2,1.01,15.51]],"ltp":6.6,"tv":203.59,"id":7444998}]}]}
{"op":"mcm","clk":"1004802206","pt":1580656956842,"mc":[{"id":"1.168224477","rc":[{"batb":[[0,1.09,249.19],[1,1.01,15.51],[2,1.01,0]],"ltp":1.14,"tv":156.57,"id":5858055},{"batb":[[0,3.5,15.5],[1,1.01,15.51],[2,1.01,0]],"batl":[[0,8.6,81.49],[1,8.6,0]],"ltp":6.6,"tv":203.59,"id":7444998}]}]}
{"op":"mcm","clk":"1004802738","pt":1580656959447,"mc":[{"id":"1.168224477","rc":[{"batb":[[0,1.1,308.5],[1,1.09,512.88],[2,1.01,15.51]],"batl":[[0,1.38,154.24],[1,1.39,116.33],[2,1.4,930.11]],"ltp":1.14,"tv":156.57,"id":5858055}]}]}
{"op":"mcm","clk":"1004802965","pt":1580656960472,"mc":[{"id":"1.168224477","rc":[{"batb":[[0,1.09,249.19],[1,1.01,15.51],[2,1.01,0]],"batl":[[0,1.4,930.11],[1,1.39,0],[2,1.4,0]],"ltp":1.14,"tv":156.57,"id":5858055}]}]}
{"op":"mcm","clk":"1004803658","pt":1580656963905,"mc":[{"id":"1.168224477","rc":[{"batb":[[0,1.2,300.58],[1,1.19,223.59],[2,1.09,249.19]],"batl":[[0,1.23,189.59],[1,1.24,210.29]],"ltp":1.14,"tv":156.57,"id":5858055}]}]}
{"op":"mcm","clk":"1004804129","pt":1580656966086,"mc":[{"id":"1.168224477","rc":[{"batb":[[0,1.09,249.19],[1,1.01,15.51],[2,1.09,0]],"ltp":1.14,"tv":156.57,"id":5858055}]}]}
{"op":"mcm","clk":"1004804445","pt":1580656967782,"mc":[{"id":"1.168224477","rc":[{"batl":[[0,1.56,677.77]],"ltp":1.14,"tv":156.57,"id":5858055},{"batl":[[0,7.8,87.46]],"ltp":6.6,"tv":203.59,"id":7444998}]}]}
{"op":"mcm","clk":"1004804726","pt":1580656969083,"mc":[{"id":"1.168224477","rc":[{"batb":[[0,1.1,305.89],[1,1.09,515.5],[2,1.01,15.51]],"batl":[[0,1.38,156.29],[1,1.39,116.34],[2,1.56,677.77]],"ltp":1.14,"tv":156.57,"id":5858055}]}]}
{"op":"mcm","clk":"1004805991","pt":1580656975215,"mc":[{"id":"1.168224477","rc":[{"batb":[[0,1.09,249.19],[1,1.01,15.51],[2,1.01,0]],"ltp":1.14,"tv":156.57,"id":5858055}]}]}
{"op":"mcm","clk":"1004806238","pt":1580656976405,"mc":[{"id":"1.168224477","rc":[{"batl":[[2,1.56,0]],"ltp":1.14,"tv":156.57,"id":5858055}]}]}
{"op":"mcm","clk":"1004806609","pt":1580656978258,"mc":[{"id":"1.168224477","rc":[{"batb":[[0,1.34,138.3],[1,1.33,149.14],[2,1.09,249.19]],"ltp":1.14,"tv":156.57,"id":5858055}]}]}
{"op":"mcm","clk":"1004806771","pt":1580656979019,"mc":[{"id":"1.168224477","rc":[{"batb":[[0,1.34,200.3],[2,1.18,128.33]],"ltp":1.14,"tv":156.57,"id":5858055},{"batb":[[1,2.2,21.09],[2,1.01,15.51]],"ltp":6.6,"tv":203.59,"id":7444998}]}]}
{"op":"mcm","clk":"1004806968","pt":1580656979931,"mc":[{"id":"1.168224477","rc":[{"batb":[[2,1.29,144.51]],"batl":[[0,1.36,42.01],[1,1.38,156.29],[2,1.39,116.34]],"ltp":1.14,"tv":156.57,"id":5858055},{"batb":[[0,3.75,15.12],[1,3.5,15.5],[2,2.2,21.09]],"batl":[[0,4.4,11.76],[1,5.3,118.13]],"ltp":6.6,"tv":203.59,"id":7444998}]}]}
{"op":"mcm","clk":"1004808800","pt":1580656988466,"mc":[{"id":"1.168224477","rc":[{"batl":[[0,1.38,156.29],[1,1.39,116.34],[2,1.73,529.53]],"ltp":1.14,"tv":156.57,"id":5858055}]}]}
{"op":"mcm","clk":"1004809411","pt":1580656991435,"mc":[{"id":"1.168224477","rc":[{"batl":[[0,1.37,42.01],[1,1.38,156.29],[2,1.39,116.34]],"ltp":1.14,"tv":156.57,"id":5858055}]}]}
{"op":"mcm","clk":"1004811017","pt":1580656999148,"mc":[{"id":"1.168224477","rc":[{"batb":[[0,1.18,128.33],[1,1.01,15.51],[2,1.29,0]],"batl":[[0,1.73,529.53],[1,1.38,0],[2,1.39,0]],"ltp":1.14,"tv":156.57,"id":5858055},{"batb":[[0,2.2,21.09],[1,1.01,15.51],[2,2.2,0]],"batl":[[0,5.3,118.13],[1,5.3,0]],"ltp":6.6,"tv":203.59,"id":7444998}]}]}
{"op":"mcm","clk":"1004811515","pt":1580657001447,"mc":[{"id":"1.168224477","rc":[{"batb":[[0,1.18,341.16],[1,1.17,321.04],[2,1.01,15.51]],"batl":[[0,1.85,84.96],[1,1.87,78.94]],"ltp":1.14,"tv":156.57,"id":5858055}]}]}
{"op":"mcm","clk":"1004811655","pt":1580657002047,"mc":[{"id":"1.168224477","rc":[{"batb":[[0,1.18,128.33],[1,1.01,15.51],[2,1.01,0]],"ltp":1.14,"tv":156.57,"id":5858055}]}]}
{"op":"mcm","clk":"1004811934","pt":1580657003483,"mc":[{"id":"1.168224477","rc":[{"batl":[[0,3.75,3]],"ltp":6.6,"tv":203.59,"id":7444998}]}]}
{"op":"mcm","clk":"1004812265","pt":1580657005055,"mc":[{"id":"1.168224477","rc":[{"batb":[[0,1.41,102.68],[1,1.4,115.92],[2,1.18,128.33]],"batl":[[0,1.45,95.95],[1,1.46,94.48]],"ltp":1.14,"tv":156.57,"id":5858055}]}]}
{"op":"mcm","clk":"1004812659","pt":1580657007045,"mc":[{"id":"1.168224477","rc":[{"batl":[[2,1.82,470.97]],"ltp":1.14,"tv":156.57,"id":5858055},{"batl":[[0,4.6,135.29]],"ltp":6.6,"tv":203.59,"id":7444998}]}]}
{"op":"mcm","clk":"1004812906","pt":1580657008392,"mc":[{"id":"1.168224477","rc":[{"batb":[[0,1.18,128.33],[1,1.01,15.51],[2,1.18,0]],"batl":[[0,1.82,470.97],[1,1.46,0],[2,1.82,0]],"ltp":1.14,"tv":156.57,"id":5858055}]}]}
{"op":"mcm","clk":"1004813467","pt":1580657011269,"mc":[{"id":"1.168224477","rc":[{"batb":[[0,1.18,339.79],[1,1.17,322.43],[2,1.01,15.51]],"batl":[[0,1.85,85.84],[1,1.87,78.95]],"ltp":1.14,"tv":156.57,"id":5858055}]}]}
{"op":"mcm","clk":"1004813902","pt":1580657013287,"mc":[{"id":"1.168224477","rc":[{"batb":[[0,1.18,128.33],[1,1.01,15.51],[2,1.01,0]],"ltp":1.14,"tv":156.57,"id":5858055}]}]}
{"op":"mcm","clk":"1004814540","pt":1580657016390,"mc":[{"id":"1.168224477","rc":[{"batb":[[0,1.77,89.49],[1,1.75,96.6],[2,1.18,128.33]],"ltp":1.14,"tv":156.57,"id":5858055}]}]}
{"op":"mcm","clk":"1004814722","pt":1580657017276,"mc":[{"id":"1.168224477","rc":[{"batb":[[2,1.73,22.66]],"ltp":1.14,"tv":156.57,"id":5858055},{"batb":[[1,2,27.77],[2,1.01,15.51]],"ltp":6.6,"tv":203.59,"id":7444998}]}]}
{"op":"mcm","clk":"1004814916","pt":1580657018180,"mc":[{"id":"1.168224477","rc":[{"batl":[[1,1.87,120.96],[2,2.36,300.61]],"ltp":1.14,"tv":156.57,"id":5858055},{"batb":[[1,2.14,36.13],[2,2,27.77]],"batl":[[0,2.4,29.41],[1,2.92,220.09]],"ltp":6.6,"tv":203.59,"id":7444998}]}]}
{"op":"mcm","clk":"1004817198","pt":1580657029004,"mc":[{"id":"1.168224477","rc":[{"trd":[[2.2,12]],"batb":[[0,2.2,15.09]],"ltp":2.2,"tv":215.59,"id":7444998}],"tv":372.16}]}
{"op":"mcm","clk":"1004817875","pt":1580657032315,"mc":[{"id":"1.168224477","rc":[{"batb":[[2,1.74,22.5]],"ltp":1.14,"tv":156.57,"id":5858055}]}]}
{"op":"mcm","clk":"1004818919","pt":1580657037216,"mc":[{"id":"1.168224477","rc":[{"batb":[[2,1.74,22.35]],"ltp":1.14,"tv":156.57,"id":5858055}]}]}
{"op":"mcm","clk":"1004821307","pt":1580657048302,"mc":[{"id":"1.168224477","rc":[{"batb":[[1,1.75,118.87]],"ltp":1.14,"tv":156.57,"id":5858055}]}]}
{"op":"mcm","clk":"1004821371","pt":1580657048615,"mc":[{"id":"1.168224477","rc":[{"batb":[[2,1.71,58.81]],"ltp":1.14,"tv":156.57,"id":5858055}]}]}
{"op":"mcm","clk":"1004831315","pt":1580657096315,"mc":[{"id":"1.168224477","rc":[{"batb":[[0,1.71,58.81],[1,1.54,34.78],[2,1.01,15.51]],"batl":[[0,1.87,42.01],[1,2.36,300.61],[2,2.36,0]],"ltp":1.14,"tv":156.57,"id":5858055},{"batb":[[0,2.14,36.13],[1,2,27.77],[2,1.01,15.51]],"ltp":2.2,"tv":215.59,"id":7444998}]}]}
{"op":"mcm","clk":"1004831464","pt":1580657097033,"mc":[{"id":"1.168224477","rc":[{"batb":[[0,1.54,34.78],[1,1.01,15.51],[2,1.01,0]],"batl":[[0,2.36,300.61],[1,2.36,0]],"ltp":1.14,"tv":156.57,"id":5858055},{"batb":[[0,2,27.77],[1,1.01,15.51],[2,1.01,0]],"batl":[[0,2.92,220.09],[1,2.92,0]],"ltp":2.2,"tv":215.59,"id":7444998}]}]}
{"op":"mcm","clk":"1004831873","pt":1580657099089,"mc":[{"id":"1.168224477","rc":[{"batb":[[0,1.57,106.84],[1,1.56,73.62],[2,1.54,34.78]],"batl":[[0,2,54.7],[1,2.02,62.37],[2,2.36,300.61]],"ltp":1.14,"tv":156.57,"id":5858055}]}]}
